{"op":"mcm","clk":"4214193908","pt":1631522345145,"mc":[{"id":"1.187605875","marketDefinition":{"bspMarket":false,"turnInPlayEnabled":true,"persistenceEnabled":true,"marketBaseRate":5.0,"eventId":"30896916","eventTypeId":"2","numberOfWinners":1,"bettingType":"ODDS","marketType":"MATCH_ODDS","marketTime":"2021-09-13T13:30:00.000Z","suspendTime":"2021-09-13T13:30:00.000Z","bspReconciled":false,"complete":true,"inPlay":false,"crossMatching":false,"runnersVoidable":false,"numberOfActiveRunners":2,"betDelay":0,"status":"OPEN","runners":[{"status":"ACTIVE","sortPriority":1,"id":11214864,"name":"A Pisareva"},{"status":"ACTIVE","sortPriority":2,"id":40752182,"name":"S Motlagh"}],"regulators":["MR_INT"],"discountAllowed":false,"timezone":"Europe/London","openDate":"2021-09-13T16:30:00.000Z","version":4030218034,"name":"Match Odds","eventName":"A Pisareva v S Motlagh"}}]}
{"op":"mcm","clk":"4214194070","pt":1631522348146,"mc":[{"id":"1.187605875","marketDefinition":{"bspMarket":false,"turnInPlayEnabled":true,"persistenceEnabled":true,"marketBaseRate":5.0,"eventId":"30896916","eventTypeId":"2","numberOfWinners":1,"bettingType":"ODDS","marketType":"MATCH_ODDS","marketTime":"2021-09-13T13:30:00.000Z","suspendTime":"2021-09-13T13:30:00.000Z","bspReconciled":false,"complete":true,"inPlay":false,"crossMatching":false,"runnersVoidable":false,"numberOfActiveRunners":2,"betDelay":0,"status":"OPEN","runners":[{"status":"ACTIVE","sortPriority":1,"id":11214864,"name":"A Pisareva"},{"status":"ACTIVE","sortPriority":2,"id":40752182,"name":"S Motlagh"}],"regulators":["MR_INT"],"discountAllowed":true,"timezone":"Europe/London","openDate":"2021-09-13T16:30:00.000Z","version":4030218034,"name":"Match Odds","eventName":"A Pisareva v S Motlagh"}}]}
{"op":"mcm","clk":"4214197199","pt":1631522408063,"mc":[{"id":"1.187605875","rc":[{"batb":[[0,1.01,25]],"ltp":0.0,"tv":0.0,"id":40752182},{"batb":[[0,1.01,25]],"ltp":0.0,"tv":0.0,"id":11214864}]}]}
{"op":"mcm","clk":"4214310750","pt":1631524359892,"mc":[{"id":"1.187605875","rc":[{"batl":[[0,990,2.2]],"ltp":0.0,"tv":0.0,"id":40752182},{"batl":[[0,990,2.2]],"ltp":0.0,"tv":0.0,"id":11214864}]}]}
{"op":"mcm","clk":"4214681599","pt":1631529131746,"mc":[{"id":"1.187605875","rc":[{"batl":[[0,1.72,2.66],[1,990,2.2]],"ltp":0.0,"tv":0.0,"id":11214864}]}]}
{"op":"mcm","clk":"4214682259","pt":1631529142542,"mc":[{"id":"1.187605875","rc":[{"batb":[[0,1.04,42.62],[1,1.01,25]],"ltp":0.0,"tv":0.0,"id":11214864}]}]}
{"op":"mcm","clk":"4214955315","pt":1631532931893,"mc":[{"id":"1.187605875","rc":[{"batb":[[0,1.05,874.55],[1,1.01,25]],"ltp":0.0,"tv":0.0,"id":40752182},{"batb":[[0,1.05,874.55],[1,1.04,42.53],[2,1.01,25]],"batl":[[0,1.72,2.66]],"ltp":0.0,"tv":0.0,"id":11214864}]}]}
{"op":"mcm","clk":"4214957143","pt":1631532958272,"mc":[{"id":"1.187605875","marketDefinition":{"bspMarket":false,"turnInPlayEnabled":true,"persistenceEnabled":true,"marketBaseRate":5.0,"eventId":"30896916","eventTypeId":"2","numberOfWinners":1,"bettingType":"ODDS","marketType":"MATCH_ODDS","marketTime":"2021-09-13T13:30:00.000Z","suspendTime":"2021-09-13T13:30:00.000Z","bspReconciled":false,"complete":true,"inPlay":false,"crossMatching":true,"runnersVoidable":false,"numberOfActiveRunners":2,"betDelay":0,"status":"OPEN","runners":[{"status":"ACTIVE","sortPriority":1,"id":11214864,"name":"A Pisareva"},{"status":"ACTIVE","sortPriority":2,"id":40752182,"name":"S Motlagh"}],"regulators":["MR_INT"],"discountAllowed":true,"timezone":"Europe/London","openDate":"2021-09-13T16:30:00.000Z","version":4030218034,"name":"Match Odds","eventName":"A Pisareva v S Motlagh"}}]}
{"op":"mcm","clk":"4215327368","pt":1631537851148,"mc":[{"id":"1.187605875","rc":[{"batb":[[0,1.13,72.32],[1,1.05,874.55],[2,1.04,42.53]],"ltp":0.0,"tv":0.0,"id":11214864}]}]}
{"op":"mcm","clk":"4215328109","pt":1631537863455,"mc":[{"id":"1.187605875","rc":[{"batb":[[0,2.4,21.7],[1,1.05,874.55],[2,1.01,25]],"ltp":0.0,"tv":0.0,"id":40752182}]}]}
{"op":"mcm","clk":"4215328408","pt":1631537868048,"mc":[{"id":"1.187605875","rc":[{"batb":[[0,2.44,21.7]],"ltp":0.0,"tv":0.0,"id":40752182}]}]}
{"op":"mcm","clk":"4215329442","pt":1631537883722,"mc":[{"id":"1.187605875","rc":[{"batb":[[1,1.01,25],[2,1.01,0]],"ltp":0.0,"tv":0.0,"id":40752182}]}]}
{"op":"mcm","clk":"4215329857","pt":1631537890631,"mc":[{"id":"1.187605875","rc":[{"batl":[[0,1.68,43.73],[1,1.72,2.66],[2,990,2.2]],"ltp":0.0,"tv":0.0,"id":11214864}]}]}
{"op":"mcm","clk":"4215417120","pt":1631539025591,"mc":[{"id":"1.187605875","rc":[{"batb":[[0,1.01,25],[1,1.01,0]],"ltp":0.0,"tv":0.0,"id":40752182},{"batb":[[0,1.05,873.97],[1,1.04,42.58],[2,1.01,25]],"batl":[[0,1.68,43.7],[1,1.72,2.66]],"ltp":0.0,"tv":0.0,"id":11214864}]}]}
{"op":"mcm","clk":"4215724187","pt":1631543529360,"mc":[{"id":"1.187605875","marketDefinition":{"bspMarket":false,"turnInPlayEnabled":true,"persistenceEnabled":true,"marketBaseRate":5.0,"eventId":"30896916","eventTypeId":"2","numberOfWinners":1,"bettingType":"ODDS","marketType":"MATCH_ODDS","marketTime":"2021-09-13T14:30:00.000Z","suspendTime":"2021-09-13T14:30:00.000Z","bspReconciled":false,"complete":true,"inPlay":false,"crossMatching":true,"runnersVoidable":false,"numberOfActiveRunners":2,"betDelay":0,"status":"OPEN","runners":[{"status":"ACTIVE","sortPriority":1,"id":11214864,"name":"A Pisareva"},{"status":"ACTIVE","sortPriority":2,"id":40752182,"name":"S Motlagh"}],"regulators":["MR_INT"],"discountAllowed":true,"timezone":"Europe/London","openDate":"2021-09-13T16:30:00.000Z","version":4030780469,"name":"Match Odds","eventName":"A Pisareva v S Motlagh"}}]}
{"op":"mcm","clk":"4215724391","pt":1631543531373,"mc":[{"id":"1.187605875","marketDefinition":{"bspMarket":false,"turnInPlayEnabled":true,"persistenceEnabled":true,"marketBaseRate":5.0,"eventId":"30896916","eventTypeId":"2","numberOfWinners":1,"bettingType":"ODDS","marketType":"MATCH_ODDS","marketTime":"2021-09-13T14:30:00.000Z","suspendTime":"2021-09-13T14:30:00.000Z","bspReconciled":false,"complete":true,"inPlay":false,"crossMatching":true,"runnersVoidable":false,"numberOfActiveRunners":2,"betDelay":0,"status":"OPEN","runners":[{"status":"ACTIVE","sortPriority":1,"id":11214864,"name":"A Pisareva"},{"status":"ACTIVE","sortPriority":2,"id":40752182,"name":"S Motlagh"}],"regulators":["MR_INT"],"countryCode":"US","discountAllowed":true,"timezone":"UTC","openDate":"2021-09-13T14:30:00.000Z","version":4030780469,"name":"Match Odds","eventName":"Al Pisareva v Motlagh"}}]}
{"op":"mcm","clk":"4215736999","pt":1631543671979,"mc":[{"id":"1.187605875","rc":[{"batl":[[2,1.8,264.01]],"ltp":0.0,"tv":0.0,"id":11214864}]}]}
{"op":"mcm","clk":"4215737369","pt":1631543675999,"mc":[{"id":"1.187605875","rc":[{"batl":[[1,1.7,236.76],[2,1.72,2.66]],"ltp":0.0,"tv":0.0,"id":11214864}]}]}
{"op":"mcm","clk":"4215744277","pt":1631543757612,"mc":[{"id":"1.187605875","marketDefinition":{"bspMarket":false,"turnInPlayEnabled":true,"persistenceEnabled":true,"marketBaseRate":5.0,"eventId":"30896916","eventTypeId":"2","numberOfWinners":1,"bettingType":"ODDS","marketType":"MATCH_ODDS","marketTime":"2021-09-13T14:30:00.000Z","suspendTime":"2021-09-13T14:30:00.000Z","bspReconciled":false,"complete":true,"inPlay":true,"crossMatching":true,"runnersVoidable":false,"numberOfActiveRunners":2,"betDelay":3,"status":"OPEN","runners":[{"status":"ACTIVE","sortPriority":1,"id":11214864,"name":"A Pisareva"},{"status":"ACTIVE","sortPriority":2,"id":40752182,"name":"S Motlagh"}],"regulators":["MR_INT"],"countryCode":"US","discountAllowed":true,"timezone":"UTC","openDate":"2021-09-13T14:30:00.000Z","version":4030783221,"name":"Match Odds","eventName":"Al Pisareva v Motlagh"},"rc":[{"batb":[[0,1.01,25],[1,1.04,0],[2,1.01,0]],"batl":[[0,1.7,236.76],[1,1.8,264.01],[2,1.72,0]],"ltp":0.0,"tv":0.0,"id":11214864}]}]}
{"op":"mcm","clk":"4215745831","pt":1631543775260,"mc":[{"id":"1.187605875","rc":[{"batl":[[0,1.68,5.96],[1,1.7,236.76],[2,1.8,264.01]],"ltp":0.0,"tv":0.0,"id":11214864}]}]}
{"op":"mcm","clk":"4215752131","pt":1631543843410,"mc":[{"id":"1.187605875","rc":[{"batl":[[0,4,5.16],[1,4.1,48.01]],"ltp":0.0,"tv":0.0,"id":40752182},{"batl":[[0,1.35,14.85],[1,1.36,124.15],[2,1.68,5.96]],"ltp":0.0,"tv":0.0,"id":11214864}]}]}
{"op":"mcm","clk":"4215753262","pt":1631543856723,"mc":[{"id":"1.187605875","rc":[{"batl":[[0,1.68,5.96],[1,1.7,236.76],[2,1.8,264.01]],"ltp":0.0,"tv":0.0,"id":11214864}]}]}
{"op":"mcm","clk":"4215753937","pt":1631543865049,"mc":[{"id":"1.187605875","rc":[{"batb":[[0,4.1,54.51],[1,1.01,25]],"batl":[[0,4.7,78.37]],"ltp":0.0,"tv":0.0,"id":40752182},{"batb":[[0,1.29,20.59],[1,1.01,25]],"batl":[[0,1.31,22.12],[1,1.68,5.96],[2,1.7,236.76]],"ltp":0.0,"tv":0.0,"id":11214864}]}]}
{"op":"mcm","clk":"4215754897","pt":1631543875877,"mc":[{"id":"1.187605875","rc":[{"batb":[[0,1.01,25],[1,1.01,0]],"ltp":0.0,"tv":0.0,"id":40752182},{"batb":[[0,1.01,25],[1,1.01,0]],"batl":[[0,1.68,5.96],[1,1.7,236.76],[2,1.8,264.01]],"ltp":0.0,"tv":0.0,"id":11214864}]}]}
{"op":"mcm","clk":"4215757754","pt":1631543906600,"mc":[{"id":"1.187605875","rc":[{"batb":[[0,4.8,4.28],[1,1.01,25]],"batl":[[0,5,4.44],[1,5.3,63.75]],"ltp":0.0,"tv":0.0,"id":40752182},{"batl":[[0,1.28,210.11],[1,1.68,5.96],[2,1.7,236.76]],"ltp":0.0,"tv":0.0,"id":11214864}]}]}
{"op":"mcm","clk":"4215759421","pt":1631543925514,"mc":[{"id":"1.187605875","rc":[{"batb":[[0,1.01,25],[1,1.01,0]],"ltp":0.0,"tv":0.0,"id":40752182},{"batl":[[0,1.68,5.96],[1,1.7,236.76],[2,1.8,264.01]],"ltp":0.0,"tv":0.0,"id":11214864}]}]}
{"op":"mcm","clk":"4215759859","pt":1631543930533,"mc":[{"id":"1.187605875","rc":[{"batb":[[0,1.6,766.48],[1,1.01,25]],"ltp":0.0,"tv":0.0,"id":40752182}]}]}
{"op":"mcm","clk":"4215760456","pt":1631543937122,"mc":[{"id":"1.187605875","rc":[{"batb":[[0,1.61,16.18],[1,1.6,766.48],[2,1.01,25]],"ltp":0.0,"tv":0.0,"id":40752182}]}]}
{"op":"mcm","clk":"4215761018","pt":1631543943746,"mc":[{"id":"1.187605875","rc":[{"batl":[[0,5.7,3.51],[1,6,21.68]],"ltp":0.0,"tv":0.0,"id":40752182},{"batb":[[0,1.2,108.4],[1,1.01,25]],"batl":[[0,1.23,36.03],[1,1.24,247.23],[2,1.68,5.96]],"ltp":0.0,"tv":0.0,"id":11214864}]}]}
{"op":"mcm","clk":"4215761415","pt":1631543948031,"mc":[{"id":"1.187605875","rc":[{"trd":[[1.23,72.06]],"batb":[[0,1.23,144.59],[1,1.22,192.32],[2,1.2,108.4]],"batl":[[0,1.24,247.23],[1,1.26,176.19],[2,1.27,142.01]],"ltp":1.23,"tv":72.06,"id":11214864}],"tv":72.06}]}
{"op":"mcm","clk":"4215761684","pt":1631543951280,"mc":[{"id":"1.187605875","rc":[{"batb":[[0,1.23,156.53]],"batl":[[1,1.26,199.73]],"ltp":1.23,"tv":72.06,"id":11214864}]}]}
{"op":"mcm","clk":"4215761863","pt":1631543952947,"mc":[{"id":"1.187605875","rc":[{"batb":[[0,1.01,25],[1,1.22,0],[2,1.2,0]],"batl":[[0,1.68,5.96],[1,1.7,236.76],[2,1.8,264.01]],"ltp":1.23,"tv":72.06,"id":11214864}]}]}
{"op":"mcm","clk":"4215762446","pt":1631543958626,"mc":[{"id":"1.187605875","rc":[{"batb":[[0,1.22,239.02],[1,1.21,173.34],[2,1.01,25]],"batl":[[0,1.25,148.24],[1,1.26,149.81],[2,1.68,5.96]],"ltp":1.23,"tv":72.06,"id":11214864}]}]}
{"op":"mcm","clk":"4215763092","pt":1631543965745,"mc":[{"id":"1.187605875","rc":[{"batb":[[0,1.01,25],[1,1.21,0],[2,1.01,0]],"batl":[[0,1.68,5.96],[1,1.7,236.76],[2,1.8,264.01]],"ltp":1.23,"tv":72.06,"id":11214864}]}]}
{"op":"mcm","clk":"4215763345","pt":1631543968735,"mc":[{"id":"1.187605875","rc":[{"batb":[[0,1.2,188.25],[1,1.19,229.75],[2,1.01,25]],"batl":[[0,1.29,133.92],[1,1.3,126.31],[2,1.68,5.96]],"ltp":1.23,"tv":72.06,"id":11214864}]}]}
{"op":"mcm","clk":"4215764474","pt":1631543981375,"mc":[{"id":"1.187605875","rc":[{"batl":[[0,1.68,5.96],[1,1.7,236.76],[2,1.8,264.01]],"ltp":1.23,"tv":72.06,"id":11214864}]}]}
{"op":"mcm","clk":"4215764721","pt":1631543984094,"mc":[{"id":"1.187605875","rc":[{"batl":[[0,6.2,5.65],[1,6.8,48.8]],"ltp":0.0,"tv":0.0,"id":40752182},{"batl":[[0,1.21,29.54],[1,1.24,757.25],[2,1.68,5.96]],"ltp":1.23,"tv":72.06,"id":11214864}]}]}
{"op":"mcm","clk":"4215764743","pt":1631543984358,"mc":[{"id":"1.187605875","rc":[{"batl":[[1,1.22,71.73],[2,1.23,175.41]],"ltp":1.23,"tv":72.06,"id":11214864}]}]}
{"op":"mcm","clk":"4215765078","pt":1631543988185,"mc":[{"id":"1.187605875","rc":[{"trd":[[1.2,44.72]],"batb":[[0,1.2,165.89]],"ltp":1.2,"tv":116.78,"id":11214864}],"tv":116.78}]}
{"op":"mcm","clk":"4215765376","pt":1631543991486,"mc":[{"id":"1.187605875","rc":[{"batb":[[0,1.2,173.3]],"batl":[[1,1.22,86.44]],"ltp":1.2,"tv":116.78,"id":11214864}]}]}
{"op":"mcm","clk":"4215768066","pt":1631544021638,"mc":[{"id":"1.187605875","rc":[{"batb":[[0,1.01,25],[1,1.19,0],[2,1.01,0]],"batl":[[1,1.24,757.25],[2,1.68,5.96]],"ltp":1.2,"tv":116.78,"id":11214864}]}]}
{"op":"mcm","clk":"4215768328","pt":1631544024551,"mc":[{"id":"1.187605875","rc":[{"batb":[[0,1.18,139.31],[1,1.17,260.11],[2,1.01,25]],"batl":[[2,1.26,154.03]],"ltp":1.2,"tv":116.78,"id":11214864}]}]}
{"op":"mcm","clk":"4215770759","pt":1631544051873,"mc":[{"id":"1.187605875","rc":[{"batl":[[0,1.26,154.03],[1,1.27,143.39],[2,1.68,5.96]],"ltp":1.2,"tv":116.78,"id":11214864}]}]}
{"op":"mcm","clk":"4215771979","pt":1631544066595,"mc":[{"id":"1.187605875","rc":[{"batb":[[0,1.01,25],[1,1.17,0],[2,1.01,0]],"ltp":1.2,"tv":116.78,"id":11214864}]}]}
{"op":"mcm","clk":"4215772263","pt":1631544069580,"mc":[{"id":"1.187605875","rc":[{"batl":[[0,5.5,7.78],[1,6,30.1]],"ltp":0.0,"tv":0.0,"id":40752182},{"batb":[[0,1.23,208.13],[1,1.22,194.17],[2,1.2,150.52]],"batl":[[0,1.24,199.63],[1,1.26,154.03],[2,1.27,143.39]],"ltp":1.2,"tv":116.78,"id":11214864}]}]}
{"op":"mcm","clk":"4215773744","pt":1631544085818,"mc":[{"id":"1.187605875","rc":[{"batb":[[0,1.16,583.98],[1,1.01,25],[2,1.2,0]],"batl":[[0,1.58,659.44],[1,1.68,5.96],[2,1.7,236.76]],"ltp":1.2,"tv":116.78,"id":11214864}]}]}
{"op":"mcm","clk":"4215774244","pt":1631544092130,"mc":[{"id":"1.187605875","rc":[{"batb":[[0,1.24,163.23],[1,1.23,182.94],[2,1.16,583.98]],"batl":[[0,1.27,173.56],[1,1.28,136.83],[2,1.58,659.44]],"ltp":1.2,"tv":116.78,"id":11214864}]}]}
{"op":"mcm","clk":"4215774579","pt":1631544096637,"mc":[{"id":"1.187605875","rc":[{"batb":[[0,1.16,583.98],[1,1.01,25],[2,1.16,0]],"batl":[[0,1.58,659.44],[1,1.68,5.96],[2,1.7,236.76]],"ltp":1.2,"tv":116.78,"id":11214864}]}]}
{"op":"mcm","clk":"4215774820","pt":1631544099519,"mc":[{"id":"1.187605875","rc":[{"batb":[[0,1.21,73.9],[1,1.2,213.14],[2,1.16,583.98]],"batl":[[0,1.3,99.68],[1,1.31,122.22],[2,1.58,659.44]],"ltp":1.2,"tv":116.78,"id":11214864}]}]}
{"op":"mcm","clk":"4215775121","pt":1631544102751,"mc":[{"id":"1.187605875","rc":[{"batb":[[0,1.16,583.98],[1,1.01,25],[2,1.16,0]],"ltp":1.2,"tv":116.78,"id":11214864}]}]}
{"op":"mcm","clk":"4215775312","pt":1631544104833,"mc":[{"id":"1.187605875","rc":[{"batb":[[0,1.01,25],[1,1.01,0]],"ltp":1.2,"tv":116.78,"id":11214864}]}]}
{"op":"mcm","clk":"4215775392","pt":1631544105753,"mc":[{"id":"1.187605875","rc":[{"batl":[[0,4.8,6.91]],"ltp":0.0,"tv":0.0,"id":40752182},{"batb":[[0,1.27,184.44],[1,1.26,158.18],[2,1.24,189.88]],"batl":[[0,1.28,181.47],[1,1.3,99.68],[2,1.31,122.22]],"ltp":1.2,"tv":116.78,"id":11214864}]}]}
{"op":"mcm","clk":"4215777744","pt":1631544130379,"mc":[{"id":"1.187605875","rc":[{"batb":[[2,1.18,557.21]],"batl":[[0,1.3,99.68],[1,1.31,122.22],[2,1.58,659.44]],"ltp":1.2,"tv":116.78,"id":11214864}]}]}
{"op":"mcm","clk":"4215777858","pt":1631544131581,"mc":[{"id":"1.187605875","rc":[{"batb":[[0,1.18,557.21],[1,1.01,25],[2,1.18,0]],"batl":[[0,1.58,659.44],[1,1.68,5.96],[2,1.7,236.76]],"ltp":1.2,"tv":116.78,"id":11214864}]}]}
{"op":"mcm","clk":"4215778109","pt":1631544134598,"mc":[{"id":"1.187605875","rc":[{"batb":[[0,1.24,202.02],[1,1.23,183.94],[2,1.18,557.21]],"batl":[[0,1.35,139.82],[1,1.36,100.97],[2,1.58,659.44]],"ltp":1.2,"tv":116.78,"id":11214864}]}]}
{"op":"mcm","clk":"4215778257","pt":1631544136679,"mc":[{"id":"1.187605875","rc":[{"batb":[[0,1.18,557.21],[1,1.01,25],[2,1.18,0]],"ltp":1.2,"tv":116.78,"id":11214864}]}]}
{"op":"mcm","clk":"4215778359","pt":1631544138394,"mc":[{"id":"1.187605875","rc":[{"batb":[[0,1.01,25],[1,1.01,0]],"ltp":1.2,"tv":116.78,"id":11214864}]}]}
{"op":"mcm","clk":"4215778468","pt":1631544139700,"mc":[{"id":"1.187605875","rc":[{"batb":[[0,4.1,56.11],[1,1.61,16.18],[2,1.6,766.48]],"batl":[[0,4.7,79.34]],"ltp":0.0,"tv":0.0,"id":40752182},{"batb":[[0,1.32,68.41],[1,1.31,138],[2,1.01,25]],"ltp":1.2,"tv":116.78,"id":11214864}]}]}
{"op":"mcm","clk":"4215778644","pt":1631544142192,"mc":[{"id":"1.187605875","rc":[{"batb":[[2,1.2,538.09]],"ltp":1.2,"tv":116.78,"id":11214864}]}]}
{"op":"mcm","clk":"4215779645","pt":1631544154591,"mc":[{"id":"1.187605875","rc":[{"batb":[[0,1.61,16.18],[1,1.6,766.48],[2,1.01,25]],"ltp":0.0,"tv":0.0,"id":40752182},{"batb":[[0,1.2,538.09],[1,1.01,25],[2,1.2,0]],"batl":[[0,1.58,659.44],[1,1.68,5.96],[2,1.7,236.76]],"ltp":1.2,"tv":116.78,"id":11214864}]}]}
{"op":"mcm","clk":"4215780144","pt":1631544160022,"mc":[{"id":"1.187605875","rc":[{"batl":[[0,4.5,4]],"ltp":0.0,"tv":0.0,"id":40752182}]}]}
{"op":"mcm","clk":"4215780167","pt":1631544160297,"mc":[{"id":"1.187605875","rc":[{"batb":[[0,1.32,149.81],[1,1.31,126.69],[2,1.2,538.09]],"batl":[[0,1.35,63.69],[1,1.36,102.01],[2,1.58,659.44]],"ltp":1.2,"tv":116.78,"id":11214864}]}]}
{"op":"mcm","clk":"4215780399","pt":1631544163113,"mc":[{"id":"1.187605875","rc":[{"batb":[[0,1.2,538.09],[1,1.01,25],[2,1.2,0]],"batl":[[0,1.58,659.44],[1,1.36,0],[2,1.58,0]],"ltp":1.2,"tv":116.78,"id":11214864}]}]}
{"op":"mcm","clk":"4215780636","pt":1631544166022,"mc":[{"id":"1.187605875","rc":[{"batb":[[0,1.29,131.78],[1,1.28,143.43],[2,1.2,538.09]],"batl":[[0,1.38,70.37],[1,1.39,92.11],[2,1.58,659.44]],"ltp":1.2,"tv":116.78,"id":11214864}]}]}
{"op":"mcm","clk":"4215780825","pt":1631544168947,"mc":[{"id":"1.187605875","rc":[{"batl":[[0,1.58,659.44],[1,1.39,0],[2,1.58,0]],"ltp":1.2,"tv":116.78,"id":11214864}]}]}
{"op":"mcm","clk":"4215781065","pt":1631544171928,"mc":[{"id":"1.187605875","rc":[{"batb":[[0,4.4,49.53],[1,1.61,16.18],[2,1.6,766.48]],"batl":[[0,5,33.1]],"ltp":0.0,"tv":0.0,"id":40752182},{"batb":[[1,1.28,164.13],[2,1.25,132.41]],"batl":[[0,1.3,22.4],[1,1.32,118.32],[2,1.33,112.86]],"ltp":1.2,"tv":116.78,"id":11214864}]}]}
{"op":"mcm","clk":"4215782890","pt":1631544194996,"mc":[{"id":"1.187605875","rc":[{"batb":[[0,1.61,16.18],[1,1.6,766.48],[2,1.01,25]],"ltp":0.0,"tv":0.0,"id":40752182},{"batb":[[1,1.28,143.43],[2,1.2,538.09]],"batl":[[0,1.32,118.32],[1,1.33,112.86],[2,1.58,659.44]],"ltp":1.2,"tv":116.78,"id":11214864}]}]}
{"op":"mcm","clk":"4215782904","pt":1631544195309,"mc":[{"id":"1.187605875","rc":[{"batb":[[0,1.2,538.09],[1,1.01,25],[2,1.2,0]],"batl":[[0,1.58,659.44],[1,1.33,0],[2,1.58,0]],"ltp":1.2,"tv":116.78,"id":11214864}]}]}
{"op":"mcm","clk":"4215783461","pt":1631544201914,"mc":[{"id":"1.187605875","rc":[{"batb":[[0,1.3,114.34],[1,1.29,137.03],[2,1.2,538.09]],"batl":[[0,1.33,121.1],[1,1.34,108.72],[2,1.58,659.44]],"ltp":1.2,"tv":116.78,"id":11214864}]}]}
{"op":"mcm","clk":"4215783989","pt":1631544208818,"mc":[{"id":"1.187605875","rc":[{"batb":[[0,1.2,538.09],[1,1.01,25],[2,1.2,0]],"batl":[[0,1.58,659.44],[1,1.34,0],[2,1.58,0]],"ltp":1.2,"tv":116.78,"id":11214864}]}]}
{"op":"mcm","clk":"4215784226","pt":1631544211734,"mc":[{"id":"1.187605875","rc":[{"batb":[[0,1.26,101.24],[1,1.25,164.01],[2,1.2,538.09]],"batl":[[0,1.37,121.31],[1,1.38,94.56],[2,1.58,659.44]],"ltp":1.2,"tv":116.78,"id":11214864}]}]}
{"op":"mcm","clk":"4215784814","pt":1631544219137,"mc":[{"id":"1.187605875","rc":[{"batl":[[0,1.58,659.44],[1,1.38,0],[2,1.58,0]],"ltp":1.2,"tv":116.78,"id":11214864}]}]}
{"op":"mcm","clk":"4215784921","pt":1631544220454,"mc":[{"id":"1.187605875","rc":[{"batb":[[2,1.01,25]],"ltp":1.2,"tv":116.78,"id":11214864}]}]}
{"op":"mcm","clk":"4215785069","pt":1631544222034,"mc":[{"id":"1.187605875","rc":[{"batb":[[0,4.8,56.38],[1,1.61,16.18],[2,1.6,766.48]],"batl":[[0,5,4.04],[1,5.5,54.05]],"ltp":0.0,"tv":0.0,"id":40752182},{"batl":[[0,1.28,59.94],[1,1.29,133.38],[2,1.58,659.44]],"ltp":1.2,"tv":116.78,"id":11214864}]}]}
{"op":"mcm","clk":"4215785191","pt":1631544223958,"mc":[{"id":"1.187605875","rc":[{"batb":[[2,1.16,583.98]],"ltp":1.2,"tv":116.78,"id":11214864}]}]}
{"op":"mcm","clk":"4215786988","pt":1631544246899,"mc":[{"id":"1.187605875","rc":[{"batb":[[0,1.61,16.18],[1,1.6,766.48],[2,1.01,25]],"ltp":0.0,"tv":0.0,"id":40752182},{"batb":[[0,1.16,583.98],[1,1.01,25],[2,1.16,0]],"batl":[[0,1.58,659.44],[1,1.29,0],[2,1.58,0]],"ltp":1.2,"tv":116.78,"id":11214864}]}]}
{"op":"mcm","clk":"4215787219","pt":1631544249772,"mc":[{"id":"1.187605875","rc":[{"batb":[[0,1.21,235.85],[1,1.2,179.97],[2,1.16,583.98]],"batl":[[0,1.35,66.45],[1,1.36,101.98],[2,1.58,659.44]],"ltp":1.2,"tv":116.78,"id":11214864}]}]}
{"op":"mcm","clk":"4215788039","pt":1631544260292,"mc":[{"id":"1.187605875","rc":[{"batb":[[0,1.16,583.98],[1,1.01,25],[2,1.16,0]],"ltp":1.2,"tv":116.78,"id":11214864}]}]}
{"op":"mcm","clk":"4215788171","pt":1631544262003,"mc":[{"id":"1.187605875","rc":[{"batb":[[0,1.01,25],[1,1.01,0]],"ltp":1.2,"tv":116.78,"id":11214864}]}]}
{"op":"mcm","clk":"4215788267","pt":1631544262999,"mc":[{"id":"1.187605875","rc":[{"batl":[[0,4.7,76.51]],"ltp":0.0,"tv":0.0,"id":40752182},{"batb":[[0,1.31,14.36],[1,1.01,25]],"batl":[[0,1.33,238.78],[1,1.35,66.45],[2,1.36,101.98]],"ltp":1.2,"tv":116.78,"id":11214864}]}]}
{"op":"mcm","clk":"4215788282","pt":1631544263207,"mc":[{"id":"1.187605875","rc":[{"batb":[[0,1.32,146.85],[1,1.31,141],[2,1.01,25]],"ltp":1.2,"tv":116.78,"id":11214864}]}]}
{"op":"mcm","clk":"4215788529","pt":1631544266293,"mc":[{"id":"1.187605875","rc":[{"batb":[[2,1.18,557.21]],"ltp":1.2,"tv":116.78,"id":11214864}]}]}
{"op":"mcm","clk":"4215790508","pt":1631544293830,"mc":[{"id":"1.187605875","rc":[{"batb":[[0,1.18,557.21],[1,1.01,25],[2,1.18,0]],"batl":[[0,1.58,659.44],[1,1.35,0],[2,1.36,0]],"ltp":1.2,"tv":116.78,"id":11214864}]}]}
{"op":"mcm","clk":"4215790722","pt":1631544296741,"mc":[{"id":"1.187605875","rc":[{"batb":[[0,1.28,117.83],[1,1.27,149.69],[2,1.18,557.21]],"batl":[[0,1.4,57.84],[1,1.41,86.55],[2,1.58,659.44]],"ltp":1.2,"tv":116.78,"id":11214864}]}]}
{"op":"mcm","clk":"4215790796","pt":1631544297836,"mc":[{"id":"1.187605875","rc":[{"batb":[[0,1.18,557.21],[1,1.01,25],[2,1.18,0]],"ltp":1.2,"tv":116.78,"id":11214864}]}]}
{"op":"mcm","clk":"4215790839","pt":1631544298453,"mc":[{"id":"1.187605875","rc":[{"batb":[[0,1.01,25],[1,1.01,0]],"ltp":1.2,"tv":116.78,"id":11214864}]}]}
{"op":"mcm","clk":"4215791027","pt":1631544301064,"mc":[{"id":"1.187605875","rc":[{"batb":[[0,3.7,3.97],[1,1.61,16.18],[2,1.6,766.48]],"batl":[[0,3.85,7.59]],"ltp":0.0,"tv":0.0,"id":40752182},{"trd":[[1.37,208.04]],"batb":[[0,1.36,104.27],[1,1.32,171.24],[2,1.01,25]],"batl":[[0,1.37,49.06],[1,1.4,57.84],[2,1.41,86.55]],"ltp":1.37,"tv":324.82,"id":11214864}],"tv":324.82}]}
{"op":"mcm","clk":"4215791179","pt":1631544302652,"mc":[{"id":"1.187605875","rc":[{"batb":[[2,1.2,538.09]],"ltp":1.37,"tv":324.82,"id":11214864}]}]}
{"op":"mcm","clk":"4215791329","pt":1631544304163,"mc":[{"id":"1.187605875","rc":[{"batb":[[0,1.36,139.03],[1,1.35,109.42],[2,1.32,171.24]],"batl":[[1,1.4,125.91]],"ltp":1.37,"tv":324.82,"id":11214864}]}]}
{"op":"mcm","clk":"4215791945","pt":1631544311675,"mc":[{"id":"1.187605875","rc":[{"batb":[[0,1.61,16.18],[1,1.6,766.48],[2,1.01,7]],"ltp":0.0,"tv":0.0,"id":40752182},{"batb":[[0,1.2,538.09],[1,1.01,7],[2,1.32,0]],"batl":[[0,1.58,659.44],[1,1.4,0],[2,1.41,0]],"ltp":1.37,"tv":324.82,"id":11214864}]}]}
{"op":"mcm","clk":"4215792196","pt":1631544314553,"mc":[{"id":"1.187605875","rc":[{"batb":[[0,1.32,69.08],[1,1.31,126.48],[2,1.2,538.09]],"batl":[[0,1.45,87.04],[1,1.46,74.92],[2,1.58,659.44]],"ltp":1.37,"tv":324.82,"id":11214864}]}]}
{"op":"mcm","clk":"4215792508","pt":1631544318170,"mc":[{"id":"1.187605875","rc":[{"batb":[[0,1.2,538.09],[1,1.01,7],[2,1.2,0]],"ltp":1.37,"tv":324.82,"id":11214864}]}]}
{"op":"mcm","clk":"4215792632","pt":1631544319667,"mc":[{"id":"1.187605875","rc":[{"batb":[[0,1.01,7],[1,1.01,0]],"ltp":1.37,"tv":324.82,"id":11214864}]}]}
{"op":"mcm","clk":"4215792738","pt":1631544321071,"mc":[{"id":"1.187605875","rc":[{"batb":[[0,3.35,6.4],[1,3.3,67.52],[2,1.61,16.18]],"batl":[[0,3.5,4.11],[1,3.7,79.3]],"ltp":0.0,"tv":0.0,"id":40752182},{"batb":[[0,1.41,125.58],[1,1.4,102.2],[2,1.01,7]],"ltp":1.37,"tv":324.82,"id":11214864}]}]}
{"op":"mcm","clk":"4215792948","pt":1631544323974,"mc":[{"id":"1.187605875","rc":[{"batb":[[2,1.23,523.51]],"ltp":1.37,"tv":324.82,"id":11214864}]}]}
{"op":"mcm","clk":"4215793999","pt":1631544338886,"mc":[{"id":"1.187605875","rc":[{"batb":[[0,1.61,16.18],[1,1.6,766.48],[2,1.01,7]],"ltp":0.0,"tv":0.0,"id":40752182},{"batb":[[0,1.23,523.51],[1,1.01,7],[2,1.23,0]],"batl":[[0,1.58,659.44],[1,1.46,0],[2,1.58,0]],"ltp":1.37,"tv":324.82,"id":11214864}]}]}
{"op":"mcm","clk":"4215794220","pt":1631544341791,"mc":[{"id":"1.187605875","rc":[{"batb":[[0,1.37,85.16],[1,1.36,104.89],[2,1.23,523.51]],"batl":[[0,1.5,83.39],[1,1.51,65.41],[2,1.58,659.44]],"ltp":1.37,"tv":324.82,"id":11214864}]}]}
{"op":"mcm","clk":"4215794260","pt":1631544342310,"mc":[{"id":"1.187605875","rc":[{"batb":[[0,1.23,523.51],[1,1.01,7],[2,1.23,0]],"batl":[[0,1.58,659.44],[1,1.51,0],[2,1.58,0]],"ltp":1.37,"tv":324.82,"id":11214864}]}]}
{"op":"mcm","clk":"4215794471","pt":1631544345185,"mc":[{"id":"1.187605875","rc":[{"batb":[[0,1.4,134.82],[1,1.39,95.11],[2,1.23,523.51]],"batl":[[0,1.44,87.61],[1,1.45,77.1],[2,1.58,659.44]],"ltp":1.37,"tv":324.82,"id":11214864}]}]}
{"op":"mcm","clk":"4215794809","pt":1631544349111,"mc":[{"id":"1.187605875","rc":[{"batb":[[0,1.01,7],[1,1.6,0],[2,1.01,0]],"ltp":0.0,"tv":0.0,"id":40752182},{"batb":[[0,1.23,523.51],[1,1.01,7],[2,1.23,0]],"batl":[[0,1.58,659.44],[1,1.45,0],[2,1.58,0]],"ltp":1.37,"tv":324.82,"id":11214864}]}]}
{"op":"mcm","clk":"4215795039","pt":1631544351981,"mc":[{"id":"1.187605875","rc":[{"batb":[[0,1.37,85.16],[1,1.36,104.89],[2,1.23,523.51]],"batl":[[0,1.5,83.39],[1,1.51,65.41],[2,1.58,659.44]],"ltp":1.37,"tv":324.82,"id":11214864}]}]}
{"op":"mcm","clk":"4215795068","pt":1631544352252,"mc":[{"id":"1.187605875","rc":[{"batb":[[0,1.41,16.18],[1,1.4,766.48],[2,1.01,7]],"ltp":0.0,"tv":0.0,"id":40752182}]}]}
{"op":"mcm","clk":"4215796067","pt":1631544364505,"mc":[{"id":"1.187605875","rc":[{"batl":[[0,1.58,659.44],[1,1.51,0],[2,1.58,0]],"ltp":1.37,"tv":324.82,"id":11214864}]}]}
{"op":"mcm","clk":"4215796213","pt":1631544366283,"mc":[{"id":"1.187605875","rc":[{"batb":[[2,1.01,7]],"ltp":1.37,"tv":324.82,"id":11214864}]}]}
{"op":"mcm","clk":"4215796312","pt":1631544367485,"mc":[{"id":"1.187605875","rc":[{"batb":[[0,3.6,54.78],[1,1.41,16.18],[2,1.4,766.48]],"batl":[[0,4,58.94]],"ltp":0.0,"tv":0.0,"id":40752182},{"batb":[[1,1.36,118.97]],"batl":[[0,1.38,17.77],[1,1.4,77.99],[2,1.41,87.07]],"ltp":1.37,"tv":324.82,"id":11214864}]}]}
{"op":"mcm","clk":"4215796565","pt":1631544370505,"mc":[{"id":"1.187605875","rc":[{"batb":[[2,1.2,538.09]],"ltp":1.37,"tv":324.82,"id":11214864}]}]}
{"op":"mcm","clk":"4215798369","pt":1631544391738,"mc":[{"id":"1.187605875","rc":[{"batb":[[0,1.41,16.18],[1,1.4,766.48],[2,1.01,7]],"ltp":0.0,"tv":0.0,"id":40752182},{"batb":[[0,1.2,538.09],[1,1.01,7],[2,1.2,0]],"batl":[[0,1.58,659.44],[1,1.4,0],[2,1.41,0]],"ltp":1.37,"tv":324.82,"id":11214864}]}]}
{"op":"mcm","clk":"4215798585","pt":1631544394605,"mc":[{"id":"1.187605875","rc":[{"batb":[[0,1.31,183.18],[1,1.3,133.68],[2,1.2,538.09]],"batl":[[0,1.46,64.58],[1,1.47,73.02],[2,1.58,659.44]],"ltp":1.37,"tv":324.82,"id":11214864}]}]}
{"op":"mcm","clk":"4215798963","pt":1631544399515,"mc":[{"id":"1.187605875","rc":[{"batl":[[0,1.58,659.44],[1,1.47,0],[2,1.58,0]],"ltp":1.37,"tv":324.82,"id":11214864}]}]}
{"op":"mcm","clk":"4215799210","pt":1631544402441,"mc":[{"id":"1.187605875","rc":[{"batb":[[0,4,54.73],[1,1.41,16.18],[2,1.4,766.48]],"batl":[[0,4.5,51.68]],"ltp":0.0,"tv":0.0,"id":40752182},{"batb":[[0,1.31,196.73]],"batl":[[0,1.33,24.43],[1,1.35,153.97],[2,1.36,101.72]],"ltp":1.37,"tv":324.82,"id":11214864}]}]}
{"op":"mcm","clk":"4215800924","pt":1631544423247,"mc":[{"id":"1.187605875","rc":[{"batb":[[0,1.41,16.18],[1,1.4,766.48],[2,1.01,7]],"ltp":0.0,"tv":0.0,"id":40752182},{"batb":[[0,1.2,538.09],[1,1.01,7],[2,1.2,0]],"batl":[[0,1.58,659.44],[1,1.35,0],[2,1.36,0]],"ltp":1.37,"tv":324.82,"id":11214864}]}]}
{"op":"mcm","clk":"4215801163","pt":1631544426265,"mc":[{"id":"1.187605875","rc":[{"batb":[[0,1.26,94.48],[1,1.25,165.4],[2,1.2,538.09]],"batl":[[0,1.42,136.75],[1,1.43,81.32],[2,1.58,659.44]],"ltp":1.37,"tv":324.82,"id":11214864}]}]}
{"op":"mcm","clk":"4215801641","pt":1631544432590,"mc":[{"id":"1.187605875","rc":[{"batb":[[0,1.2,538.09],[1,1.01,7],[2,1.2,0]],"ltp":1.37,"tv":324.82,"id":11214864}]}]}
{"op":"mcm","clk":"4215801738","pt":1631544434157,"mc":[{"id":"1.187605875","rc":[{"batb":[[0,1.01,7],[1,1.01,0]],"ltp":1.37,"tv":324.82,"id":11214864}]}]}
{"op":"mcm","clk":"4215801833","pt":1631544435550,"mc":[{"id":"1.187605875","rc":[{"batb":[[0,3.5,31.73],[1,1.41,16.18],[2,1.4,766.48]],"batl":[[0,3.7,5.44]],"ltp":0.0,"tv":0.0,"id":40752182},{"batb":[[0,1.38,103.49],[1,1.37,101.48],[2,1.34,195.69]],"batl":[[0,1.39,15.57],[1,1.4,79.33],[2,1.42,136.75]],"ltp":1.37,"tv":324.82,"id":11214864}]}]}
{"op":"mcm","clk":"4215802754","pt":1631544447912,"mc":[{"id":"1.187605875","rc":[{"batb":[[0,1.41,16.18],[1,1.4,766.48],[2,1.01,7]],"ltp":0.0,"tv":0.0,"id":40752182},{"batb":[[2,1.22,530.12]],"batl":[[0,1.42,136.75],[1,1.43,81.32],[2,1.58,659.44]],"ltp":1.37,"tv":324.82,"id":11214864}]}]}
{"op":"mcm","clk":"4215802774","pt":1631544448181,"mc":[{"id":"1.187605875","rc":[{"batb":[[0,1.22,530.12],[1,1.01,7],[2,1.22,0]],"batl":[[0,1.58,659.44],[1,1.43,0],[2,1.58,0]],"ltp":1.37,"tv":324.82,"id":11214864}]}]}
{"op":"mcm","clk":"4215803036","pt":1631544451096,"mc":[{"id":"1.187605875","rc":[{"batb":[[0,1.31,181.16],[1,1.3,133.64],[2,1.22,530.12]],"batl":[[0,1.49,70.55],[1,1.5,67.26],[2,1.58,659.44]],"ltp":1.37,"tv":324.82,"id":11214864}]}]}
{"op":"mcm","clk":"4215803211","pt":1631544452825,"mc":[{"id":"1.187605875","rc":[{"batb":[[0,1.22,530.12],[1,1.01,7],[2,1.22,0]],"batl":[[0,1.58,659.44],[1,1.5,0],[2,1.58,0]],"ltp":1.37,"tv":324.82,"id":11214864}]}]}
{"op":"mcm","clk":"4215803457","pt":1631544455690,"mc":[{"id":"1.187605875","rc":[{"batb":[[0,1.37,69.35],[1,1.36,104.7],[2,1.22,530.12]],"batl":[[0,1.4,92.93],[1,1.41,86.92],[2,1.58,659.44]],"ltp":1.37,"tv":324.82,"id":11214864}]}]}
{"op":"mcm","clk":"4215803692","pt":1631544458820,"mc":[{"id":"1.187605875","rc":[{"batb":[[0,1.22,530.12],[1,1.01,7],[2,1.22,0]],"batl":[[0,1.58,659.44],[1,1.41,0],[2,1.58,0]],"ltp":1.37,"tv":324.82,"id":11214864}]}]}
{"op":"mcm","clk":"4215803947","pt":1631544461725,"mc":[{"id":"1.187605875","rc":[{"batb":[[0,1.31,181.16],[1,1.3,133.64],[2,1.22,530.12]],"batl":[[0,1.49,70.55],[1,1.5,67.26],[2,1.58,659.44]],"ltp":1.37,"tv":324.82,"id":11214864}]}]}
{"op":"mcm","clk":"4215813800","pt":1631544485553,"mc":[{"id":"1.187605875","rc":[{"batl":[[0,1.58,659.44],[1,1.5,0],[2,1.58,0]],"ltp":1.37,"tv":324.82,"id":11214864}]}]}
{"op":"mcm","clk":"4215813930","pt":1631544486862,"mc":[{"id":"1.187605875","rc":[{"batb":[[2,1.01,7]],"ltp":1.37,"tv":324.82,"id":11214864}]}]}
{"op":"mcm","clk":"4215814080","pt":1631544488545,"mc":[{"id":"1.187605875","rc":[{"batl":[[0,4.5,49.64]],"ltp":0.0,"tv":0.0,"id":40752182},{"batb":[[0,1.31,195.1]],"batl":[[0,1.33,24.06],[1,1.34,223.53],[2,1.35,155.81]],"ltp":1.37,"tv":324.82,"id":11214864}]}]}
{"op":"mcm","clk":"4215814267","pt":1631544490778,"mc":[{"id":"1.187605875","rc":[{"batb":[[2,1.18,557.21]],"ltp":1.37,"tv":324.82,"id":11214864}]}]}
{"op":"mcm","clk":"4215815279","pt":1631544502781,"mc":[{"id":"1.187605875","rc":[{"batb":[[0,1.8,11.95],[1,1.41,16.18],[2,1.4,766.48]],"ltp":0.0,"tv":0.0,"id":40752182}]}]}
{"op":"mcm","clk":"4215816199","pt":1631544513594,"mc":[{"id":"1.187605875","rc":[{"batb":[[0,1.18,557.21],[1,1.03,497.67],[2,1.01,479.65]],"batl":[[0,1.58,659.44],[1,44,7.23],[2,1.35,0]],"ltp":1.37,"tv":324.82,"id":11214864}]}]}
{"op":"mcm","clk":"4215816551","pt":1631544517098,"mc":[{"id":"1.187605875","rc":[{"batb":[[0,1.26,92.24],[1,1.25,165.35],[2,1.18,557.21]],"batl":[[0,1.41,54.26],[1,1.42,84.65],[2,1.58,659.44]],"ltp":1.37,"tv":324.82,"id":11214864}]}]}
{"op":"mcm","clk":"4215816807","pt":1631544519686,"mc":[{"id":"1.187605875","rc":[{"batb":[[0,2,11.95],[1,1.8,11.95],[2,1.41,16.18]],"ltp":0.0,"tv":0.0,"id":40752182}]}]}
{"op":"mcm","clk":"4215816979","pt":1631544521723,"mc":[{"id":"1.187605875","rc":[{"batb":[[0,1.18,557.21],[1,1.05,477.76],[2,1.03,497.67]],"ltp":1.37,"tv":324.82,"id":11214864}]}]}
{"op":"mcm","clk":"4215817074","pt":1631544522873,"mc":[{"id":"1.187605875","rc":[{"batb":[[0,1.05,477.76],[1,1.03,497.67],[2,1.01,479.65]],"ltp":1.37,"tv":324.82,"id":11214864}]}]}
{"op":"mcm","clk":"4215817125","pt":1631544523398,"mc":[{"id":"1.187605875","rc":[{"batb":[[0,3.5,31.81],[1,2,11.95],[2,1.8,11.95]],"batl":[[0,3.7,5.43]],"ltp":0.0,"tv":0.0,"id":40752182},{"batb":[[0,1.34,195.68],[1,1.05,477.76],[2,1.03,497.67]],"batl":[[0,1.39,15.6],[1,1.4,79.52],[2,1.41,54.26]],"ltp":1.37,"tv":324.82,"id":11214864}]}]}
{"op":"mcm","clk":"4215817269","pt":1631544525112,"mc":[{"id":"1.187605875","rc":[{"batb":[[0,1.38,101.56],[1,1.37,101.46],[2,1.34,195.68]],"ltp":1.37,"tv":324.82,"id":11214864}]}]}
{"op":"mcm","clk":"4215818505","pt":1631544542129,"mc":[{"id":"1.187605875","rc":[{"batb":[[0,2,11.95],[1,1.8,11.95],[2,1.41,16.18]],"ltp":0.0,"tv":0.0,"id":40752182},{"batb":[[0,1.22,530.12],[1,1.05,477.76],[2,1.03,497.67]],"batl":[[0,1.58,659.44],[1,44,7.23],[2,820,0.14]],"ltp":1.37,"tv":324.82,"id":11214864}]}]}
{"op":"mcm","clk":"4215818542","pt":1631544542542,"mc":[{"id":"1.187605875","rc":[{"batl":[[2,810,0.07]],"ltp":1.37,"tv":324.82,"id":11214864}]}]}
{"op":"mcm","clk":"4215818727","pt":1631544545045,"mc":[{"id":"1.187605875","rc":[{"batb":[[0,1.31,179.08],[1,1.3,133.6],[2,1.22,530.12]],"batl":[[0,1.49,72.38],[1,1.5,67.24],[2,1.58,659.44]],"ltp":1.37,"tv":324.82,"id":11214864}]}]}
{"op":"mcm","clk":"4215819030","pt":1631544549427,"mc":[{"id":"1.187605875","rc":[{"batl":[[0,1.58,659.44],[1,44,7.23],[2,810,0.07]],"ltp":1.37,"tv":324.82,"id":11214864}]}]}
{"op":"mcm","clk":"4215819112","pt":1631544550720,"mc":[{"id":"1.187605875","rc":[{"batb":[[2,1.05,477.76]],"ltp":1.37,"tv":324.82,"id":11214864}]}]}
{"op":"mcm","clk":"4215819207","pt":1631544552121,"mc":[{"id":"1.187605875","rc":[{"batl":[[0,4.5,50.19]],"ltp":0.0,"tv":0.0,"id":40752182},{"batb":[[0,1.31,193.3]],"batl":[[0,1.33,23.8],[1,1.34,222.1],[2,1.58,659.44]],"ltp":1.37,"tv":324.82,"id":11214864}]}]}
{"op":"mcm","clk":"4215819227","pt":1631544552432,"mc":[{"id":"1.187605875","rc":[{"batl":[[2,1.35,157.71]],"ltp":1.37,"tv":324.82,"id":11214864}]}]}
{"op":"mcm","clk":"4215819403","pt":1631544554420,"mc":[{"id":"1.187605875","rc":[{"batb":[[2,1.18,557.21]],"ltp":1.37,"tv":324.82,"id":11214864}]}]}
{"op":"mcm","clk":"4215819486","pt":1631544555452,"mc":[{"id":"1.187605875","rc":[{"batb":[[0,2.2,42.64],[1,2,11.95],[2,1.8,11.95]],"ltp":0.0,"tv":0.0,"id":40752182}]}]}
{"op":"mcm","clk":"4215820315","pt":1631544564974,"mc":[{"id":"1.187605875","rc":[{"batb":[[0,1.31,179.08]],"batl":[[0,1.35,157.71],[1,1.36,101.68],[2,1.58,659.44]],"ltp":1.37,"tv":324.82,"id":11214864}]}]}
{"op":"mcm","clk":"4215820351","pt":1631544565240,"mc":[{"id":"1.187605875","rc":[{"batb":[[0,1.18,557.21],[1,1.05,477.76],[2,1.03,497.67]],"batl":[[0,1.58,659.44],[1,44,7.23],[2,810,0.07]],"ltp":1.37,"tv":324.82,"id":11214864}]}]}
{"op":"mcm","clk":"4215820565","pt":1631544568248,"mc":[{"id":"1.187605875","rc":[{"batb":[[0,1.26,89.95],[1,1.25,165.3],[2,1.18,557.21]],"batl":[[0,1.41,56.13],[1,1.42,84.63],[2,1.58,659.44]],"ltp":1.37,"tv":324.82,"id":11214864}]}]}
{"op":"mcm","clk":"4215821804","pt":1631544582476,"mc":[{"id":"1.187605875","rc":[{"batb":[[0,1.18,557.21],[1,1.05,477.76],[2,1.03,497.67]],"ltp":1.37,"tv":324.82,"id":11214864}]}]}
{"op":"mcm","clk":"4215821941","pt":1631544584199,"mc":[{"id":"1.187605875","rc":[{"batb":[[0,1.05,477.76],[1,1.03,497.67],[2,1.01,479.65]],"ltp":1.37,"tv":324.82,"id":11214864}]}]}
{"op":"mcm","clk":"4215822058","pt":1631544585511,"mc":[{"id":"1.187605875","rc":[{"batb":[[0,3.5,31.87],[1,2.2,42.64],[2,2,11.95]],"batl":[[0,3.7,5.41]],"ltp":0.0,"tv":0.0,"id":40752182},{"batb":[[0,1.38,99.59],[1,1.37,101.42],[2,1.34,195.61]],"batl":[[0,1.39,15.63],[1,1.4,79.68],[2,1.41,56.13]],"ltp":1.37,"tv":324.82,"id":11214864}]}]}
{"op":"mcm","clk":"4215823978","pt":1631544608817,"mc":[{"id":"1.187605875","rc":[{"batb":[[0,2.2,42.64],[1,2,11.95],[2,1.8,11.95]],"ltp":0.0,"tv":0.0,"id":40752182},{"batb":[[0,1.22,530.12],[1,1.05,477.76],[2,1.03,497.67]],"batl":[[0,1.58,659.44],[1,44,7.23],[2,810,0.07]],"ltp":1.37,"tv":324.82,"id":11214864}]}]}
{"op":"mcm","clk":"4215824222","pt":1631544611829,"mc":[{"id":"1.187605875","rc":[{"batb":[[0,1.31,176.94],[1,1.3,133.58],[2,1.22,530.12]],"batl":[[0,1.49,74.26],[1,1.5,67.22],[2,1.58,659.44]],"ltp":1.37,"tv":324.82,"id":11214864}]}]}
{"op":"mcm","clk":"4215824293","pt":1631544612622,"mc":[{"id":"1.187605875","rc":[{"batb":[[0,1.22,530.12],[1,1.05,477.76],[2,1.03,497.67]],"batl":[[0,1.58,659.44],[1,44,7.23],[2,810,0.07]],"ltp":1.37,"tv":324.82,"id":11214864}]}]}
{"op":"mcm","clk":"4215824560","pt":1631544615538,"mc":[{"id":"1.187605875","rc":[{"batb":[[0,1.37,65.43],[1,1.36,104.64],[2,1.22,530.12]],"batl":[[0,1.4,96.64],[1,1.41,86.88],[2,1.58,659.44]],"ltp":1.37,"tv":324.82,"id":11214864}]}]}
{"op":"mcm","clk":"4215824881","pt":1631544619029,"mc":[{"id":"1.187605875","rc":[{"batb":[[0,1.22,530.12],[1,1.05,477.76],[2,1.03,497.67]],"batl":[[0,1.58,659.44],[1,44,7.23],[2,810,0.07]],"ltp":1.37,"tv":324.82,"id":11214864}]}]}
{"op":"mcm","clk":"4215825142","pt":1631544621939,"mc":[{"id":"1.187605875","rc":[{"batb":[[0,1.31,176.94],[1,1.3,133.58],[2,1.22,530.12]],"batl":[[0,1.49,74.26],[1,1.5,67.22],[2,1.58,659.44]],"ltp":1.37,"tv":324.82,"id":11214864}]}]}
{"op":"mcm","clk":"4215825830","pt":1631544629936,"mc":[{"id":"1.187605875","rc":[{"batb":[[0,1.22,530.12],[1,1.05,477.76],[2,1.03,497.67]],"ltp":1.37,"tv":324.82,"id":11214864}]}]}
{"op":"mcm","clk":"4215826088","pt":1631544632935,"mc":[{"id":"1.187605875","rc":[{"batb":[[0,2,11.95],[1,1.8,11.95],[2,1.6,99.53]],"batl":[[0,3.5,42.35]],"ltp":0.0,"tv":0.0,"id":40752182},{"batb":[[0,1.45,104.68],[1,1.44,92.32],[2,1.4,105.88]],"batl":[[0,1.46,13.43],[1,1.47,135.5],[2,1.49,74.26]],"ltp":1.37,"tv":324.82,"id":11214864}]}]}
{"op":"mcm","clk":"4215826340","pt":1631544635957,"mc":[{"id":"1.187605875","rc":[{"batb":[[2,1.7,17.06]],"ltp":0.0,"tv":0.0,"id":40752182}]}]}
{"op":"mcm","clk":"4215827540","pt":1631544650070,"mc":[{"id":"1.187605875","rc":[{"trd":[[1.45,42.61]],"batb":[[0,1.45,83.36]],"ltp":1.45,"tv":367.43,"id":11214864}],"tv":367.43}]}
{"op":"mcm","clk":"4215827696","pt":1631544651955,"mc":[{"id":"1.187605875","rc":[{"trd":[[1.45,98.86]],"batb":[[0,1.45,55.22]],"ltp":1.45,"tv":423.67,"id":11214864}],"tv":423.67}]}
{"op":"mcm","clk":"4215827799","pt":1631544653088,"mc":[{"id":"1.187605875","rc":[{"batb":[[0,1.45,62.29]],"batl":[[2,1.49,88.13]],"ltp":1.45,"tv":423.67,"id":11214864}]}]}
{"op":"mcm","clk":"4215827994","pt":1631544655585,"mc":[{"id":"1.187605875","rc":[{"trd":[[1.45,132.94]],"batb":[[0,1.45,54.57]],"batl":[[2,1.49,106.44]],"ltp":1.45,"tv":457.75,"id":11214864}],"tv":457.75}]}
{"op":"mcm","clk":"4215828102","pt":1631544657090,"mc":[{"id":"1.187605875","rc":[{"trd":[[1.45,201.11]],"batb":[[0,1.45,20.46]],"ltp":1.45,"tv":525.93,"id":11214864}],"tv":525.93}]}
{"op":"mcm","clk":"4215828163","pt":1631544657875,"mc":[{"id":"1.187605875","rc":[{"trd":[[1.45,242]],"batb":[[0,1.44,92.32],[1,1.4,105.88],[2,1.22,530.12]],"batl":[[0,1.45,22.15],[1,1.46,13.43],[2,1.47,135.5]],"ltp":1.45,"tv":566.82,"id":11214864}],"tv":566.82}]}
{"op":"mcm","clk":"4215828246","pt":1631544659068,"mc":[{"id":"1.187605875","rc":[{"trd":[[1.45,253.3]],"batl":[[0,1.45,15.64]],"ltp":1.45,"tv":578.12,"id":11214864}],"tv":578.12}]}
{"op":"mcm","clk":"4215828261","pt":1631544659279,"mc":[{"id":"1.187605875","rc":[{"batl":[[0,1.46,13.43],[1,1.47,135.5],[2,1.49,74.26]],"ltp":1.45,"tv":578.12,"id":11214864}]}]}
{"op":"mcm","clk":"4215828356","pt":1631544660589,"mc":[{"id":"1.187605875","rc":[{"batb":[[0,1.44,116.24],[1,1.43,84.09],[2,1.4,105.88]],"batl":[[2,1.48,84.04]],"ltp":1.45,"tv":578.12,"id":11214864}]}]}
{"op":"mcm","clk":"4215834526","pt":1631544743967,"mc":[{"id":"1.187605875","rc":[{"batb":[[0,1.44,104.85],[2,1.22,530.12]],"batl":[[0,1.48,84.04],[1,1.49,74.26],[2,1.58,659.44]],"ltp":1.45,"tv":578.12,"id":11214864}]}]}
{"op":"mcm","clk":"4215834538","pt":1631544744175,"mc":[{"id":"1.187605875","rc":[{"batb":[[0,1.22,530.12],[1,1.05,477.76],[2,1.03,497.67]],"batl":[[0,1.58,659.44],[1,44,7.23],[2,810,0.07]],"ltp":1.45,"tv":578.12,"id":11214864}]}]}
{"op":"mcm","clk":"4215834768","pt":1631544747188,"mc":[{"id":"1.187605875","rc":[{"batb":[[0,1.39,87.26],[1,1.38,98.75],[2,1.22,530.12]],"batl":[[0,1.56,81.84],[1,1.57,56.8],[2,1.58,659.44]],"ltp":1.45,"tv":578.12,"id":11214864}]}]}
{"op":"mcm","clk":"4215835335","pt":1631544754904,"mc":[{"id":"1.187605875","rc":[{"batl":[[0,1.58,659.44],[1,44,7.23],[2,810,0.07]],"ltp":1.45,"tv":578.12,"id":11214864}]}]}
{"op":"mcm","clk":"4215835568","pt":1631544757902,"mc":[{"id":"1.187605875","rc":[{"batb":[[0,3.4,68.07],[1,2,11.95],[2,1.8,11.95]],"batl":[[0,3.6,6.82]],"ltp":0.0,"tv":0.0,"id":40752182},{"batb":[[2,1.36,156.48]],"batl":[[0,1.41,19.26],[1,1.42,62.5],[2,1.43,82.81]],"ltp":1.45,"tv":578.12,"id":11214864}]}]}
{"op":"mcm","clk":"4215836737","pt":1631544776013,"mc":[{"id":"1.187605875","rc":[{"batb":[[0,2,11.95],[1,1.8,11.95],[2,1.7,17.06]],"ltp":0.0,"tv":0.0,"id":40752182},{"batb":[[2,1.22,530.12]],"batl":[[0,1.42,62.5],[1,1.43,82.81],[2,1.58,659.44]],"ltp":1.45,"tv":578.12,"id":11214864}]}]}
{"op":"mcm","clk":"4215836752","pt":1631544776225,"mc":[{"id":"1.187605875","rc":[{"batb":[[0,1.22,530.12],[1,1.05,477.76],[2,1.03,497.67]],"batl":[[0,1.58,659.44],[1,44,7.23],[2,810,0.07]],"ltp":1.45,"tv":578.12,"id":11214864}]}]}
{"op":"mcm","clk":"4215836931","pt":1631544779227,"mc":[{"id":"1.187605875","rc":[{"batb":[[0,1.35,59.9],[1,1.34,113.56],[2,1.22,530.12]],"batl":[[0,1.49,84.59],[1,1.5,67.74],[2,1.58,659.44]],"ltp":1.45,"tv":578.12,"id":11214864}]}]}
{"op":"mcm","clk":"4215837342","pt":1631544783848,"mc":[{"id":"1.187605875","rc":[{"batb":[[0,1.22,530.12],[1,1.05,477.76],[2,1.03,497.67]],"ltp":1.45,"tv":578.12,"id":11214864}]}]}
{"op":"mcm","clk":"4215837444","pt":1631544785551,"mc":[{"id":"1.187605875","rc":[{"batb":[[0,1.05,477.76],[1,1.03,497.67],[2,1.01,479.65]],"batl":[[2,44,7.23]],"ltp":1.45,"tv":578.12,"id":11214864}]}]}
{"op":"mcm","clk":"4215837533","pt":1631544786859,"mc":[{"id":"1.187605875","rc":[{"batl":[[0,3.4,59.17]],"ltp":0.0,"tv":0.0,"id":40752182},{"batb":[[0,1.45,106.28],[1,1.44,81.52],[2,1.05,477.76]],"batl":[[0,1.47,14.13],[1,1.48,143.96],[2,1.49,84.59]],"ltp":1.45,"tv":578.12,"id":11214864}]}]}
{"op":"mcm","clk":"4215837808","pt":1631544789938,"mc":[{"id":"1.187605875","rc":[{"batb":[[2,1.25,511.97]],"ltp":1.45,"tv":578.12,"id":11214864}]}]}
{"op":"mcm","clk":"4215839522","pt":1631544815852,"mc":[{"id":"1.187605875","rc":[{"batb":[[0,1.45,96.33]],"batl":[[0,1.49,84.59],[1,1.5,67.74],[2,1.77,507.43]],"ltp":1.45,"tv":578.12,"id":11214864}]}]}
{"op":"mcm","clk":"4215839540","pt":1631544816163,"mc":[{"id":"1.187605875","rc":[{"batb":[[0,1.25,511.97],[1,1.05,477.76],[2,1.03,497.67]],"batl":[[0,1.77,507.43],[1,44,7.23],[2,810,0.07]],"ltp":1.45,"tv":578.12,"id":11214864}]}]}
{"op":"mcm","clk":"4215839738","pt":1631544819078,"mc":[{"id":"1.187605875","rc":[{"batb":[[0,1.39,101.29],[1,1.38,98.9],[2,1.25,511.97]],"batl":[[0,1.58,61.73],[1,1.59,54.28],[2,1.77,507.43]],"ltp":1.45,"tv":578.12,"id":11214864}]}]}
{"op":"mcm","clk":"4215839803","pt":1631544819761,"mc":[{"id":"1.187605875","rc":[{"batb":[[0,1.25,511.97],[1,1.05,477.76],[2,1.03,497.67]],"batl":[[0,1.77,507.43],[1,44,7.23],[2,810,0.07]],"ltp":1.45,"tv":578.12,"id":11214864}]}]}
{"op":"mcm","clk":"4215839944","pt":1631544821279,"mc":[{"id":"1.187605875","rc":[{"batl":[[2,810,0]],"ltp":1.45,"tv":578.12,"id":11214864}]}]}
{"op":"mcm","clk":"4215840050","pt":1631544822747,"mc":[{"id":"1.187605875","rc":[{"batb":[[0,1.47,67.04],[1,1.46,76.62],[2,1.25,511.97]],"batl":[[0,1.51,98.19],[1,1.52,64.2],[2,1.77,507.43]],"ltp":1.45,"tv":578.12,"id":11214864}]}]}
{"op":"mcm","clk":"4215840424","pt":1631544828495,"mc":[{"id":"1.187605875","rc":[{"batb":[[0,1.25,511.97],[1,1.05,477.76],[2,1.03,497.67]],"batl":[[0,1.77,507.43],[1,44,7.23],[2,1.77,0]],"ltp":1.45,"tv":578.12,"id":11214864}]}]}
{"op":"mcm","clk":"4215840629","pt":1631544831352,"mc":[{"id":"1.187605875","rc":[{"batb":[[0,1.39,101.29],[1,1.38,98.9],[2,1.25,511.97]],"batl":[[0,1.58,61.73],[1,1.59,54.28],[2,1.77,507.43]],"ltp":1.45,"tv":578.12,"id":11214864}]}]}
{"op":"mcm","clk":"4215841402","pt":1631544843396,"mc":[{"id":"1.187605875","rc":[{"batl":[[0,1.77,507.43],[1,44,7.23],[2,1.77,0]],"ltp":1.45,"tv":578.12,"id":11214864}]}]}
{"op":"mcm","clk":"4215841592","pt":1631544846092,"mc":[{"id":"1.187605875","rc":[{"batb":[[0,3.4,59.52],[1,2,11.95],[2,1.8,11.95]],"ltp":0.0,"tv":0.0,"id":40752182},{"batb":[[0,1.39,113.57],[2,1.36,169.55]],"batl":[[0,1.41,16.56]],"ltp":1.45,"tv":578.12,"id":11214864}]}]}
{"op":"mcm","clk":"4215841608","pt":1631544846301,"mc":[{"id":"1.187605875","rc":[{"batl":[[1,1.43,131.77],[2,1.44,79.75]],"ltp":1.45,"tv":578.12,"id":11214864}]}]}
{"op":"mcm","clk":"4215842131","pt":1631544853595,"mc":[{"id":"1.187605875","rc":[{"trd":[[3.6,43.79]],"ltp":3.6,"tv":43.79,"id":40752182},{"trd":[[1.39,113.55]],"batb":[[0,1.38,98.92],[1,1.36,169.55],[2,1.2,538.09]],"ltp":1.39,"tv":691.67,"id":11214864}],"tv":735.46}]}
{"op":"mcm","clk":"4215842172","pt":1631544854446,"mc":[{"id":"1.187605875","rc":[{"batl":[[1,1.43,82.96],[2,1.66,587.71]],"ltp":1.39,"tv":691.67,"id":11214864}]}]}
{"op":"mcm","clk":"4215842373","pt":1631544857122,"mc":[{"id":"1.187605875","rc":[{"batb":[[0,1.38,132.77],[1,1.37,103.46],[2,1.36,169.55]],"batl":[[1,1.42,115.43],[2,1.43,82.96]],"ltp":1.39,"tv":691.67,"id":11214864}]}]}
{"op":"mcm","clk":"4215842777","pt":1631544863834,"mc":[{"id":"1.187605875","rc":[{"batb":[[0,1.38,132.75]],"batl":[[0,1.42,115.43],[1,1.43,82.96],[2,1.66,587.71]],"ltp":1.39,"tv":691.67,"id":11214864}]}]}
{"op":"mcm","clk":"4215842973","pt":1631544866736,"mc":[{"id":"1.187605875","rc":[{"batb":[[0,1.38,148.24]],"batl":[[0,1.4,7.34],[1,1.42,115.43],[2,1.43,82.96]],"ltp":1.39,"tv":691.67,"id":11214864}]}]}
{"op":"mcm","clk":"4215843115","pt":1631544868912,"mc":[{"id":"1.187605875","rc":[{"batb":[[0,2,11.95],[1,1.8,11.95],[2,1.7,17.06]],"ltp":3.6,"tv":43.79,"id":40752182},{"batb":[[0,1.2,538.09],[1,1.05,477.76],[2,1.03,497.67]],"batl":[[0,1.66,587.71],[1,44,7.23],[2,1.43,0]],"ltp":1.39,"tv":691.67,"id":11214864}]}]}
{"op":"mcm","clk":"4215843342","pt":1631544872604,"mc":[{"id":"1.187605875","rc":[{"batb":[[0,1.05,477.76],[1,1.03,497.67],[2,1.01,479.65]],"ltp":1.39,"tv":691.67,"id":11214864}]}]}
{"op":"mcm","clk":"4215843456","pt":1631544874318,"mc":[{"id":"1.187605875","rc":[{"batb":[[0,1.4,63.91],[1,1.39,95.91],[2,1.05,477.76]],"batl":[[0,1.43,79.14],[1,1.44,80.83],[2,1.66,587.71]],"ltp":1.39,"tv":691.67,"id":11214864}]}]}
{"op":"mcm","clk":"4215843614","pt":1631544876648,"mc":[{"id":"1.187605875","rc":[{"batb":[[2,1.22,530.12]],"ltp":1.39,"tv":691.67,"id":11214864}]}]}
{"op":"mcm","clk":"4215843948","pt":1631544881726,"mc":[{"id":"1.187605875","rc":[{"batb":[[0,1.22,530.12],[1,1.05,477.76],[2,1.03,497.67]],"batl":[[0,1.66,587.71],[1,44,7.23],[2,1.66,0]],"ltp":1.39,"tv":691.67,"id":11214864}]}]}
{"op":"mcm","clk":"4215844200","pt":1631544885258,"mc":[{"id":"1.187605875","rc":[{"batb":[[0,1.34,57.82],[1,1.33,118.84],[2,1.22,530.12]],"batl":[[0,1.49,77.03],[1,1.5,68.27],[2,1.66,587.71]],"ltp":1.39,"tv":691.67,"id":11214864}]}]}
{"op":"mcm","clk":"4215845450","pt":1631544903779,"mc":[{"id":"1.187605875","rc":[{"batl":[[0,1.66,587.71],[1,44,7.23],[2,1.66,0]],"ltp":1.39,"tv":691.67,"id":11214864}]}]}
{"op":"mcm","clk":"4215845545","pt":1631544904978,"mc":[{"id":"1.187605875","rc":[{"batb":[[2,1.05,477.76]],"ltp":1.39,"tv":691.67,"id":11214864}]}]}
{"op":"mcm","clk":"4215845671","pt":1631544906800,"mc":[{"id":"1.187605875","rc":[{"batl":[[0,4,5.35],[1,4.2,67.74]],"ltp":3.6,"tv":43.79,"id":40752182},{"batl":[[0,1.35,13.69],[1,1.37,136.89],[2,1.38,97.03]],"ltp":1.39,"tv":691.67,"id":11214864}]}]}
{"op":"mcm","clk":"4215845854","pt":1631544909106,"mc":[{"id":"1.187605875","rc":[{"batb":[[2,1.18,557.21]],"ltp":1.39,"tv":691.67,"id":11214864}]}]}
{"op":"mcm","clk":"4215845915","pt":1631544909765,"mc":[{"id":"1.187605875","rc":[{"batb":[[0,2.2,42.64],[1,2,11.95],[2,1.8,11.95]],"ltp":3.6,"tv":43.79,"id":40752182}]}]}
{"op":"mcm","clk":"4215847631","pt":1631544935428,"mc":[{"id":"1.187605875","rc":[{"batb":[[0,1.18,557.21],[1,1.11,271.45],[2,1.1,298.6]],"batl":[[0,1.66,587.71],[1,44,7.23],[2,1.38,0]],"ltp":1.39,"tv":691.67,"id":11214864}]}]}
{"op":"mcm","clk":"4215847831","pt":1631544938511,"mc":[{"id":"1.187605875","rc":[{"batb":[[0,1.3,190.18],[1,1.29,142.07],[2,1.18,557.21]],"batl":[[0,1.41,74.92],[1,1.42,85.92],[2,1.66,587.71]],"ltp":1.39,"tv":691.67,"id":11214864}]}]}
{"op":"mcm","clk":"4215848102","pt":1631544942520,"mc":[{"id":"1.187605875","rc":[{"batl":[[0,1.66,587.71],[1,44,7.23],[2,1.66,0]],"ltp":1.39,"tv":691.67,"id":11214864}]}]}
{"op":"mcm","clk":"4215848294","pt":1631544945110,"mc":[{"id":"1.187605875","rc":[{"batl":[[0,4.3,5.21]],"ltp":3.6,"tv":43.79,"id":40752182},{"batb":[[1,1.29,296.92]],"batl":[[0,1.32,16.71],[1,1.33,132.02],[2,44,7.23]],"ltp":1.39,"tv":691.67,"id":11214864}]}]}
{"op":"mcm","clk":"4215848306","pt":1631544945317,"mc":[{"id":"1.187605875","rc":[{"batl":[[1,1.33,192.49],[2,1.34,112.78]],"ltp":1.39,"tv":691.67,"id":11214864}]}]}
{"op":"mcm","clk":"4215849606","pt":1631544963960,"mc":[{"id":"1.187605875","rc":[{"batb":[[1,1.29,142.07]],"batl":[[0,1.33,60.47],[1,1.34,112.78],[2,1.58,659.44]],"ltp":1.39,"tv":691.67,"id":11214864}]}]}
{"op":"mcm","clk":"4215849639","pt":1631544964280,"mc":[{"id":"1.187605875","rc":[{"batb":[[0,1.18,557.21],[1,1.15,358.31],[2,1.11,271.45]],"batl":[[0,1.58,659.44],[1,44,7.23],[2,1.58,0]],"ltp":1.39,"tv":691.67,"id":11214864}]}]}
{"op":"mcm","clk":"4215849851","pt":1631544967201,"mc":[{"id":"1.187605875","rc":[{"batb":[[0,1.26,135.23],[1,1.25,169.52],[2,1.18,557.21]],"batl":[[0,1.39,143.84],[1,1.4,90.79],[2,1.58,659.44]],"ltp":1.39,"tv":691.67,"id":11214864}]}]}
{"op":"mcm","clk":"4215850215","pt":1631544971690,"mc":[{"id":"1.187605875","rc":[{"batl":[[0,1.58,659.44],[1,44,7.23],[2,1.58,0]],"ltp":1.39,"tv":691.67,"id":11214864}]}]}
{"op":"mcm","clk":"4215850294","pt":1631544972687,"mc":[{"id":"1.187605875","rc":[{"batb":[[2,1.15,358.31]],"ltp":1.39,"tv":691.67,"id":11214864}]}]}
{"op":"mcm","clk":"4215850400","pt":1631544973991,"mc":[{"id":"1.187605875","rc":[{"batl":[[0,5.1,54.51]],"ltp":3.6,"tv":43.79,"id":40752182},{"batb":[[0,1.26,153.77]],"batl":[[0,1.28,28.72],[1,1.29,906.42],[2,1.33,13.1]],"ltp":1.39,"tv":691.67,"id":11214864}]}]}
{"op":"mcm","clk":"4215850446","pt":1631544974563,"mc":[{"id":"1.187605875","rc":[{"batl":[[1,1.29,374.04],[2,1.3,129.8]],"ltp":1.39,"tv":691.67,"id":11214864}]}]}
{"op":"mcm","clk":"4215851567","pt":1631544988888,"mc":[{"id":"1.187605875","rc":[{"batb":[[0,1.15,358.31],[1,1.14,618.77],[2,1.11,271.45]],"batl":[[0,1.58,659.44],[1,44,7.23],[2,1.3,0]],"ltp":1.39,"tv":691.67,"id":11214864}]}]}
{"op":"mcm","clk":"4215852002","pt":1631544994985,"mc":[{"id":"1.187605875","rc":[{"batb":[[0,1.25,166.45],[1,1.24,178.9],[2,1.15,358.31]],"batl":[[0,1.28,164.17],[1,1.29,135.5],[2,1.58,659.44]],"ltp":1.39,"tv":691.67,"id":11214864}]}]}
{"op":"mcm","clk":"4215852247","pt":1631544998326,"mc":[{"id":"1.187605875","rc":[{"batb":[[0,1.15,358.31],[1,1.14,618.77],[2,1.11,271.45]],"batl":[[0,1.58,659.44],[1,44,7.23],[2,1.58,0]],"ltp":1.39,"tv":691.67,"id":11214864}]}]}
{"op":"mcm","clk":"4215852521","pt":1631545001298,"mc":[{"id":"1.187605875","rc":[{"batb":[[0,1.22,139.16],[1,1.21,209.35],[2,1.15,358.31]],"batl":[[0,1.33,72.29],[1,1.34,112.61],[2,1.58,659.44]],"ltp":1.39,"tv":691.67,"id":11214864}]}]}
{"op":"mcm","clk":"4215853657","pt":1631545016316,"mc":[{"id":"1.187605875","rc":[{"batl":[[0,1.58,659.44],[1,44,7.23],[2,1.58,0]],"ltp":1.39,"tv":691.67,"id":11214864}]}]}
{"op":"mcm","clk":"4215853803","pt":1631545018136,"mc":[{"id":"1.187605875","rc":[{"batl":[[0,44,7.23],[1,44,0]],"ltp":1.39,"tv":691.67,"id":11214864}]}]}
{"op":"mcm","clk":"4215853886","pt":1631545019020,"mc":[{"id":"1.187605875","rc":[{"batb":[[0,5,30.44],[1,2.2,42.64],[2,2,11.95]],"batl":[[0,5.5,3.8],[1,6,39.02]],"ltp":3.6,"tv":43.79,"id":40752182},{"batb":[[2,1.2,195.1]],"batl":[[0,1.24,33.28],[1,1.25,892.68],[2,1.28,14.33]],"ltp":1.39,"tv":691.67,"id":11214864}]}]}
{"op":"mcm","clk":"4215853916","pt":1631545019329,"mc":[{"id":"1.187605875","rc":[{"batl":[[0,1.24,125.19],[1,1.25,285.67],[2,44,7.23]],"ltp":1.39,"tv":691.67,"id":11214864}]}]}
{"op":"mcm","clk":"4215854260","pt":1631545022543,"mc":[{"id":"1.187605875","rc":[{"batb":[[1,3,5.97],[2,2.2,42.64]],"ltp":3.6,"tv":43.79,"id":40752182},{"batl":[[2,1.51,751.18]],"ltp":1.39,"tv":691.67,"id":11214864}]}]}
{"op":"mcm","clk":"4215855465","pt":1631545034482,"mc":[{"id":"1.187605875","rc":[{"batl":[[2,44,7.23]],"ltp":1.39,"tv":691.67,"id":11214864}]}]}
{"op":"mcm","clk":"4215855782","pt":1631545037968,"mc":[{"id":"1.187605875","rc":[{"batb":[[2,2.6,3.73]],"ltp":3.6,"tv":43.79,"id":40752182},{"batl":[[2,8.8,7.23]],"ltp":1.39,"tv":691.67,"id":11214864}]}]}
{"op":"mcm","clk":"4215856031","pt":1631545040839,"mc":[{"id":"1.187605875","rc":[{"batb":[[0,3,5.97],[1,2.6,3.73],[2,2.2,42.64]],"ltp":3.6,"tv":43.79,"id":40752182},{"batb":[[0,1.05,477.76],[1,1.03,497.67],[2,1.01,479.65]],"batl":[[0,8.8,7.23],[1,44,7.23],[2,50,7.23]],"ltp":1.39,"tv":691.67,"id":11214864}]}]}
{"op":"mcm","clk":"4215856266","pt":1631545044065,"mc":[{"id":"1.187605875","rc":[{"batb":[[0,1.19,120.82],[1,1.18,250.49],[2,1.05,477.76]],"batl":[[0,1.28,128.7],[1,1.29,136.18],[2,8.8,7.23]],"ltp":1.39,"tv":691.67,"id":11214864}]}]}
{"op":"mcm","clk":"4215856306","pt":1631545044481,"mc":[{"id":"1.187605875","rc":[{"batb":[[0,1.05,477.76],[1,1.03,497.67],[2,1.01,479.65]],"batl":[[0,8.8,7.23],[1,44,7.23],[2,50,7.23]],"ltp":1.39,"tv":691.67,"id":11214864}]}]}
{"op":"mcm","clk":"4215856580","pt":1631545047760,"mc":[{"id":"1.187605875","rc":[{"batb":[[0,1.21,217.67],[1,1.2,198.3],[2,1.05,477.76]],"batl":[[0,1.24,210.58],[1,1.25,161.06],[2,8.8,7.23]],"ltp":1.39,"tv":691.67,"id":11214864}]}]}
{"op":"mcm","clk":"4215856841","pt":1631545051095,"mc":[{"id":"1.187605875","rc":[{"batb":[[0,1.05,477.76],[1,1.03,497.67],[2,1.01,479.65]],"batl":[[0,8.8,7.23],[1,44,7.23],[2,50,7.23]],"ltp":1.39,"tv":691.67,"id":11214864}]}]}
{"op":"mcm","clk":"4215857079","pt":1631545053962,"mc":[{"id":"1.187605875","rc":[{"batb":[[0,1.19,120.82],[1,1.18,250.49],[2,1.05,477.76]],"batl":[[0,1.28,128.7],[1,1.29,136.18],[2,8.8,7.23]],"ltp":1.39,"tv":691.67,"id":11214864}]}]}
{"op":"mcm","clk":"4215857188","pt":1631545055372,"mc":[{"id":"1.187605875","rc":[{"batl":[[0,8.8,7.23],[1,44,7.23],[2,50,7.23]],"ltp":1.39,"tv":691.67,"id":11214864}]}]}
{"op":"mcm","clk":"4215857393","pt":1631545058071,"mc":[{"id":"1.187605875","rc":[{"batb":[[0,5.7,41.25],[1,3,5.97],[2,2.6,3.73]],"ltp":3.6,"tv":43.79,"id":40752182},{"batb":[[1,1.18,466.69]],"batl":[[0,1.21,1713.97],[1,8.8,7.23],[2,44,7.23]],"ltp":1.39,"tv":691.67,"id":11214864}]}]}
{"op":"mcm","clk":"4215857446","pt":1631545058687,"mc":[{"id":"1.187605875","rc":[{"batl":[[0,1.21,347.27],[1,1.22,188.69],[2,8.8,7.23]],"ltp":1.39,"tv":691.67,"id":11214864}]}]}
{"op":"mcm","clk":"4215858279","pt":1631545070100,"mc":[{"id":"1.187605875","rc":[{"batl":[[0,1.21,212.18]],"ltp":1.39,"tv":691.67,"id":11214864}]}]}
{"op":"mcm","clk":"4215858684","pt":1631545075822,"mc":[{"id":"1.187605875","rc":[{"batb":[[0,3,5.97],[1,2.6,3.73],[2,2.2,42.64]],"ltp":3.6,"tv":43.79,"id":40752182},{"batb":[[0,1.05,477.76],[1,1.03,497.67],[2,1.01,479.65]],"batl":[[0,8.8,7.23],[1,44,7.23],[2,50,7.23]],"ltp":1.39,"tv":691.67,"id":11214864}]}]}
{"op":"mcm","clk":"4215858911","pt":1631545078899,"mc":[{"id":"1.187605875","rc":[{"batb":[[0,1.17,147.62],[1,1.05,477.76],[2,1.03,497.67]],"ltp":1.39,"tv":691.67,"id":11214864}]}]}
{"op":"mcm","clk":"4215859155","pt":1631545081731,"mc":[{"id":"1.187605875","rc":[{"batb":[[0,1.18,278.5],[1,1.17,147.62],[2,1.05,477.76]],"batl":[[0,1.21,252.32],[1,1.22,160.68],[2,8.8,7.23]],"ltp":1.39,"tv":691.67,"id":11214864}]}]}
{"op":"mcm","clk":"4215859576","pt":1631545086723,"mc":[{"id":"1.187605875","rc":[{"batb":[[0,1.17,147.62],[1,1.05,477.76],[2,1.03,497.67]],"batl":[[0,8.8,7.23],[1,44,7.23],[2,50,7.23]],"ltp":1.39,"tv":691.67,"id":11214864}]}]}
{"op":"mcm","clk":"4215859827","pt":1631545089723,"mc":[{"id":"1.187605875","rc":[{"batb":[[0,1.17,154.68],[1,1.16,276.18],[2,1.05,477.76]],"batl":[[0,1.23,116.36],[1,1.24,171.54],[2,8.8,7.23]],"ltp":1.39,"tv":691.67,"id":11214864}]}]}
{"op":"mcm","clk":"4215860227","pt":1631545094633,"mc":[{"id":"1.187605875","rc":[{"batl":[[0,8.8,7.23],[1,44,7.23],[2,50,7.23]],"ltp":1.39,"tv":691.67,"id":11214864}]}]}
{"op":"mcm","clk":"4215860438","pt":1631545097648,"mc":[{"id":"1.187605875","rc":[{"batb":[[0,6.4,5.2],[1,6.2,41.19],[2,3,5.97]],"batl":[[0,6.8,3.62],[1,7.2,42.63]],"ltp":3.6,"tv":43.79,"id":40752182},{"batb":[[2,1.03,497.67]],"batl":[[0,1.19,193.52],[1,1.2,210.29],[2,8.8,7.23]],"ltp":1.39,"tv":691.67,"id":11214864}]}]}
{"op":"mcm","clk":"4215860666","pt":1631545100744,"mc":[{"id":"1.187605875","rc":[{"batl":[[2,3.8,27.46]],"ltp":1.39,"tv":691.67,"id":11214864}]}]}
{"op":"mcm","clk":"4215861309","pt":1631545109355,"mc":[{"id":"1.187605875","rc":[{"batl":[[0,1.19,190.64]],"ltp":1.39,"tv":691.67,"id":11214864}]}]}
{"op":"mcm","clk":"4215868361","pt":1631545204084,"mc":[{"id":"1.187605875","rc":[{"trd":[[3.6,43.84]],"batb":[[0,3,5.96],[1,2.6,3.73],[2,2.2,42.6]],"ltp":3.6,"tv":43.84,"id":40752182},{"trd":[[1.45,253.45]],"batb":[[2,1.03,497.16]],"batl":[[2,3.8,27.43]],"ltp":1.39,"tv":691.82,"id":11214864}],"tv":735.66}]}
{"op":"mcm","clk":"4215868387","pt":1631545204299,"mc":[{"id":"1.187605875","rc":[{"batb":[[0,1.03,497.16],[1,1.01,479.17],[2,1.03,0]],"batl":[[0,3.8,27.43],[1,8.8,7.22],[2,44,7.22]],"ltp":1.39,"tv":691.82,"id":11214864}]}]}
{"op":"mcm","clk":"4215868810","pt":1631545208103,"mc":[{"id":"1.187605875","rc":[{"batl":[[0,8,7.03],[1,8.6,64.79]],"ltp":3.6,"tv":43.84,"id":40752182},{"batb":[[0,1.15,89.51],[1,1.14,333.15],[2,1.03,497.16]],"batl":[[0,1.16,31.6],[1,1.17,306.33],[2,3.8,27.43]],"ltp":1.39,"tv":691.82,"id":11214864}]}]}
{"op":"mcm","clk":"4215868821","pt":1631545208211,"mc":[{"id":"1.187605875","rc":[{"batl":[[1,1.17,621.15],[2,1.18,112.71]],"ltp":1.39,"tv":691.82,"id":11214864}]}]}
{"op":"mcm","clk":"4215869003","pt":1631545210006,"mc":[{"id":"1.187605875","rc":[{"batb":[[2,1.06,950.7]],"ltp":1.39,"tv":691.82,"id":11214864}]}]}
{"op":"mcm","clk":"4215870673","pt":1631545229922,"mc":[{"id":"1.187605875","rc":[{"batb":[[0,1.06,950.7],[1,1.03,497.16],[2,1.01,479.17]],"batl":[[0,1.39,17.9],[1,1.4,954.47],[2,3.8,27.43]],"ltp":1.39,"tv":691.82,"id":11214864}]}]}
{"op":"mcm","clk":"4215870894","pt":1631545232839,"mc":[{"id":"1.187605875","rc":[{"batb":[[0,1.13,153.51],[1,1.12,292.75],[2,1.06,950.7]],"batl":[[0,1.2,272.6],[1,1.21,143.98],[2,1.39,17.9]],"ltp":1.39,"tv":691.82,"id":11214864}]}]}
{"op":"mcm","clk":"4215871303","pt":1631545239025,"mc":[{"id":"1.187605875","rc":[{"batl":[[0,1.39,17.9],[1,1.4,954.47],[2,3.8,27.43]],"ltp":1.39,"tv":691.82,"id":11214864}]}]}
{"op":"mcm","clk":"4215871409","pt":1631545240523,"mc":[{"id":"1.187605875","rc":[{"batb":[[2,1.03,497.16]],"ltp":1.39,"tv":691.82,"id":11214864}]}]}
{"op":"mcm","clk":"4215871518","pt":1631545242122,"mc":[{"id":"1.187605875","rc":[{"batl":[[0,9.2,7.35]],"ltp":3.6,"tv":43.84,"id":40752182},{"batb":[[1,1.12,538.88],[2,1.01,479.17]],"batl":[[0,1.14,40],[1,1.15,728.51],[2,1.16,93.97]],"ltp":1.39,"tv":691.82,"id":11214864}]}]}
{"op":"mcm","clk":"4215871672","pt":1631545244417,"mc":[{"id":"1.187605875","rc":[{"batb":[[2,1.05,1085.45]],"ltp":1.39,"tv":691.82,"id":11214864}]}]}
{"op":"mcm","clk":"4215872443","pt":1631545254006,"mc":[{"id":"1.187605875","rc":[{"batb":[[0,1.05,1085.45],[1,1.01,479.17],[2,1.05,0]],"batl":[[0,1.39,17.9],[1,1.4,954.47],[2,3.8,27.43]],"ltp":1.39,"tv":691.82,"id":11214864}]}]}
{"op":"mcm","clk":"4215872655","pt":1631545256864,"mc":[{"id":"1.187605875","rc":[{"batb":[[0,1.11,451.66],[1,1.05,1085.45],[2,1.01,479.17]],"batl":[[0,1.17,258.98],[1,1.18,168.08],[2,1.39,17.9]],"ltp":1.39,"tv":691.82,"id":11214864}]}]}
{"op":"mcm","clk":"4215873268","pt":1631545264702,"mc":[{"id":"1.187605875","rc":[{"batb":[[0,1.05,1085.45],[1,1.01,479.17],[2,1.01,0]],"ltp":1.39,"tv":691.82,"id":11214864}]}]}
{"op":"mcm","clk":"4215873418","pt":1631545266785,"mc":[{"id":"1.187605875","rc":[{"batb":[[0,1.01,479.17],[1,1.01,0]],"ltp":1.39,"tv":691.82,"id":11214864}]}]}
{"op":"mcm","clk":"4215873493","pt":1631545267720,"mc":[{"id":"1.187605875","rc":[{"batl":[[0,8,7.46]],"ltp":3.6,"tv":43.84,"id":40752182},{"batb":[[0,1.15,151.65],[1,1.14,513.43],[2,1.01,479.17]],"batl":[[0,1.16,28.89],[1,1.17,552.58],[2,1.18,168.08]],"ltp":1.39,"tv":691.82,"id":11214864}]}]}
{"op":"mcm","clk":"4215873734","pt":1631545270786,"mc":[{"id":"1.187605875","rc":[{"batb":[[2,1.06,1008.65]],"ltp":1.39,"tv":691.82,"id":11214864}]}]}
{"op":"mcm","clk":"4215874470","pt":1631545280903,"mc":[{"id":"1.187605875","rc":[{"batb":[[0,1.06,1008.65],[1,1.01,479.17],[2,1.06,0]],"batl":[[0,1.39,17.9],[1,1.4,954.47],[2,3.8,27.43]],"ltp":1.39,"tv":691.82,"id":11214864}]}]}
{"op":"mcm","clk":"4215874955","pt":1631545287634,"mc":[{"id":"1.187605875","rc":[{"batb":[[0,1.15,343.1],[1,1.14,93.66],[2,1.06,1008.65]],"batl":[[0,1.17,86.92],[1,1.18,241.76],[2,1.39,17.9]],"ltp":1.39,"tv":691.82,"id":11214864}]}]}
{"op":"mcm","clk":"4215875396","pt":1631545294039,"mc":[{"id":"1.187605875","rc":[{"batb":[[0,1.06,1008.65],[1,1.01,479.17],[2,1.06,0]],"batl":[[0,1.39,17.9],[1,1.4,954.47],[2,3.8,27.43]],"ltp":1.39,"tv":691.82,"id":11214864}]}]}
{"op":"mcm","clk":"4215875614","pt":1631545297050,"mc":[{"id":"1.187605875","rc":[{"batb":[[0,1.13,124.59],[1,1.12,321.93],[2,1.06,1008.65]],"batl":[[0,1.2,134.81],[1,1.21,200.47],[2,1.39,17.9]],"ltp":1.39,"tv":691.82,"id":11214864}]}]}
{"op":"mcm","clk":"4215876416","pt":1631545306740,"mc":[{"id":"1.187605875","rc":[{"batb":[[0,1.06,1008.65],[1,1.01,479.17],[2,1.06,0]],"ltp":1.39,"tv":691.82,"id":11214864}]}]}
{"op":"mcm","clk":"4215876509","pt":1631545308243,"mc":[{"id":"1.187605875","rc":[{"batb":[[0,1.01,479.17],[1,1.01,0]],"ltp":1.39,"tv":691.82,"id":11214864}]}]}
{"op":"mcm","clk":"4215876586","pt":1631545309646,"mc":[{"id":"1.187605875","rc":[{"batb":[[0,6.2,4.31],[1,3,5.96],[2,2.6,3.73]],"batl":[[0,7.2,71.39]],"ltp":3.6,"tv":43.84,"id":40752182},{"batb":[[0,1.18,208.72],[1,1.17,241.13],[2,1.01,479.17]],"batl":[[1,1.21,551.05]],"ltp":1.39,"tv":691.82,"id":11214864}]}]}
{"op":"mcm","clk":"4215876750","pt":1631545311935,"mc":[{"id":"1.187605875","rc":[{"batb":[[2,1.08,812.84]],"ltp":1.39,"tv":691.82,"id":11214864}]}]}
{"op":"mcm","clk":"4215878447","pt":1631545334103,"mc":[{"id":"1.187605875","rc":[{"batb":[[0,3,5.96],[1,2.6,3.73],[2,2.2,42.6]],"ltp":3.6,"tv":43.84,"id":40752182},{"batb":[[0,1.08,812.84],[1,1.03,497.12],[2,1.01,479.17]],"batl":[[0,1.39,17.9],[1,1.4,954.47],[2,3.8,27.43]],"ltp":1.39,"tv":691.82,"id":11214864}]}]}
{"op":"mcm","clk":"4215878660","pt":1631545336875,"mc":[{"id":"1.187605875","rc":[{"batb":[[0,1.15,103.21],[1,1.14,333.85],[2,1.08,812.84]],"batl":[[0,1.26,213.97],[1,1.27,146.81],[2,1.39,17.9]],"ltp":1.39,"tv":691.82,"id":11214864}]}]}
{"op":"mcm","clk":"4215879954","pt":1631545351923,"mc":[{"id":"1.187605875","rc":[{"batl":[[0,1.39,17.9],[1,1.4,954.47],[2,3.8,27.43]],"ltp":1.39,"tv":691.82,"id":11214864}]}]}
{"op":"mcm","clk":"4215880095","pt":1631545353707,"mc":[{"id":"1.187605875","rc":[{"batb":[[2,1.03,497.12]],"ltp":1.39,"tv":691.82,"id":11214864}]}]}
{"op":"mcm","clk":"4215880203","pt":1631545354912,"mc":[{"id":"1.187605875","rc":[{"batl":[[0,8,5.46],[1,8.6,52.36]],"ltp":3.6,"tv":43.84,"id":40752182},{"batl":[[0,1.16,41.57],[1,1.17,646.65],[2,1.18,124.92]],"ltp":1.39,"tv":691.82,"id":11214864}]}]}
{"op":"mcm","clk":"4215880385","pt":1631545357208,"mc":[{"id":"1.187605875","rc":[{"batb":[[2,1.06,950.7]],"ltp":1.39,"tv":691.82,"id":11214864}]}]}
{"op":"mcm","clk":"4215881896","pt":1631545375446,"mc":[{"id":"1.187605875","rc":[{"batb":[[0,1.06,950.7],[1,1.03,497.12],[2,1.01,479.17]],"batl":[[0,1.39,17.9],[1,1.4,954.47],[2,3.8,27.43]],"ltp":1.39,"tv":691.82,"id":11214864}]}]}
{"op":"mcm","clk":"4215882238","pt":1631545379936,"mc":[{"id":"1.187605875","rc":[{"batb":[[0,1.03,497.12],[1,1.01,479.17],[2,1.01,0]],"ltp":1.39,"tv":691.82,"id":11214864}]}]}
{"op":"mcm","clk":"4215882369","pt":1631545381560,"mc":[{"id":"1.187605875","rc":[{"batb":[[0,1.15,328.22],[1,1.14,108.68],[2,1.03,497.12]],"batl":[[0,1.17,100.3],[1,1.18,241.23],[2,1.39,17.9]],"ltp":1.39,"tv":691.82,"id":11214864}]}]}
{"op":"mcm","clk":"4215882523","pt":1631545383462,"mc":[{"id":"1.187605875","rc":[{"batb":[[2,1.06,1008.65]],"ltp":1.39,"tv":691.82,"id":11214864}]}]}
{"op":"mcm","clk":"4215882977","pt":1631545388602,"mc":[{"id":"1.187605875","rc":[{"batb":[[0,1.06,1008.65],[1,1.03,497.12],[2,1.01,479.17]],"batl":[[0,1.39,17.9],[1,1.4,954.47],[2,3.8,27.43]],"ltp":1.39,"tv":691.82,"id":11214864}]}]}
{"op":"mcm","clk":"4215883219","pt":1631545391621,"mc":[{"id":"1.187605875","rc":[{"batb":[[0,1.12,289.86],[1,1.11,159.19],[2,1.06,1008.65]],"batl":[[0,1.21,244.5],[1,1.22,168.44],[2,1.39,17.9]],"ltp":1.39,"tv":691.82,"id":11214864}]}]}
{"op":"mcm","clk":"4215884177","pt":1631545403711,"mc":[{"id":"1.187605875","rc":[{"batl":[[0,1.39,17.9],[1,1.4,954.47],[2,3.8,27.43]],"ltp":1.39,"tv":691.82,"id":11214864}]}]}
{"op":"mcm","clk":"4215884451","pt":1631545407008,"mc":[{"id":"1.187605875","rc":[{"batl":[[0,10,30.05]],"ltp":3.6,"tv":43.84,"id":40752182},{"batb":[[0,1.12,311.79],[2,1.01,479.17]],"batl":[[0,1.13,35.37],[1,1.14,845.79],[2,1.15,164.92]],"ltp":1.39,"tv":691.82,"id":11214864}]}]}
{"op":"mcm","clk":"4215884653","pt":1631545409609,"mc":[{"id":"1.187605875","rc":[{"batb":[[2,1.04,1300.13]],"ltp":1.39,"tv":691.82,"id":11214864}]}]}
{"op":"mcm","clk":"4215885322","pt":1631545418536,"mc":[{"id":"1.187605875","rc":[{"batl":[[1,1.14,635.19]],"ltp":1.39,"tv":691.82,"id":11214864}]}]}
{"op":"mcm","clk":"4215887215","pt":1631545443789,"mc":[{"id":"1.187605875","rc":[{"batb":[[0,1.12,21.93],[1,1.04,1300.13],[2,1.01,479.17]],"batl":[[1,1.14,361.78],[2,1.39,17.9]],"ltp":1.39,"tv":691.82,"id":11214864}]}]}
{"op":"mcm","clk":"4215887452","pt":1631545446794,"mc":[{"id":"1.187605875","rc":[{"batb":[[1,1.1,455.77],[2,1.04,1300.13]],"batl":[[2,1.16,278.98]],"ltp":1.39,"tv":691.82,"id":11214864}]}]}
{"op":"mcm","clk":"4215889811","pt":1631545477232,"mc":[{"id":"1.187605875","rc":[{"batb":[[0,1.1,455.77],[1,1.04,1300.13],[2,1.01,479.17]],"batl":[[0,1.16,278.98],[1,1.17,151.9],[2,1.39,17.9]],"ltp":1.39,"tv":691.82,"id":11214864}]}]}
{"op":"mcm","clk":"4215890339","pt":1631545483947,"mc":[{"id":"1.187605875","rc":[{"batl":[[0,1.39,17.9],[1,1.4,954.47],[2,3.8,27.43]],"ltp":1.39,"tv":691.82,"id":11214864}]}]}
{"op":"mcm","clk":"4215890575","pt":1631545486966,"mc":[{"id":"1.187605875","rc":[{"batl":[[0,11,5.56],[1,12,53.77]],"ltp":3.6,"tv":43.84,"id":40752182},{"batl":[[0,1.12,508.6],[1,1.13,256.72],[2,1.39,17.9]],"ltp":1.39,"tv":691.82,"id":11214864}]}]}
{"op":"mcm","clk":"4215891276","pt":1631545497045,"mc":[{"id":"1.187605875","rc":[{"batb":[[0,1.04,1300.13],[1,1.01,479.17],[2,1.01,0]],"batl":[[0,1.39,17.9],[1,1.4,954.47],[2,3.8,27.43]],"ltp":1.39,"tv":691.82,"id":11214864}]}]}
{"op":"mcm","clk":"4215891494","pt":1631545499948,"mc":[{"id":"1.187605875","rc":[{"batb":[[0,1.09,371.69],[1,1.08,89.07],[2,1.04,1300.13]],"batl":[[0,1.14,249.57],[1,1.15,188.55],[2,1.39,17.9]],"ltp":1.39,"tv":691.82,"id":11214864}]}]}
{"op":"mcm","clk":"4215891734","pt":1631545502738,"mc":[{"id":"1.187605875","rc":[{"batb":[[0,1.04,1300.13],[1,1.01,479.17],[2,1.04,0]],"ltp":1.39,"tv":691.82,"id":11214864}]}]}
{"op":"mcm","clk":"4215892029","pt":1631545505977,"mc":[{"id":"1.187605875","rc":[{"batl":[[0,10,35.65]],"ltp":3.6,"tv":43.84,"id":40752182},{"batb":[[0,1.12,532.78],[1,1.11,131.64],[2,1.04,1300.13]],"batl":[[0,1.13,31.54],[1,1.14,609.66],[2,1.15,188.55]],"ltp":1.39,"tv":691.82,"id":11214864}]}]}
{"op":"mcm","clk":"4215892863","pt":1631545517085,"mc":[{"id":"1.187605875","rc":[{"batb":[[0,1.04,1300.13],[1,1.01,479.17],[2,1.04,0]],"batl":[[0,1.39,17.9],[1,1.4,954.47],[2,3.8,27.43]],"ltp":1.39,"tv":691.82,"id":11214864}]}]}
{"op":"mcm","clk":"4215893076","pt":1631545520002,"mc":[{"id":"1.187605875","rc":[{"batb":[[0,1.1,455.77],[1,1.04,1300.13],[2,1.01,479.17]],"batl":[[0,1.16,195],[1,1.17,235.16],[2,1.39,17.9]],"ltp":1.39,"tv":691.82,"id":11214864}]}]}
{"op":"mcm","clk":"4215893329","pt":1631545523597,"mc":[{"id":"1.187605875","rc":[{"batb":[[0,1.04,1300.13],[1,1.01,479.17],[2,1.01,0]],"ltp":1.39,"tv":691.82,"id":11214864}]}]}
{"op":"mcm","clk":"4215893482","pt":1631545525626,"mc":[{"id":"1.187605875","rc":[{"batb":[[0,1.01,479.17],[1,1.01,0]],"ltp":1.39,"tv":691.82,"id":11214864}]}]}
{"op":"mcm","clk":"4215893534","pt":1631545526404,"mc":[{"id":"1.187605875","rc":[{"batl":[[0,8.6,33.05]],"ltp":3.6,"tv":43.84,"id":40752182},{"batb":[[0,1.14,293.11],[1,1.13,173.93],[2,1.01,479.17]],"batl":[[0,1.15,23.3],[1,1.16,469.02],[2,1.17,235.16]],"ltp":1.39,"tv":691.82,"id":11214864}]}]}
{"op":"mcm","clk":"4215893766","pt":1631545529732,"mc":[{"id":"1.187605875","rc":[{"batb":[[2,1.06,950.7]],"ltp":1.39,"tv":691.82,"id":11214864}]}]}
{"op":"mcm","clk":"4215895016","pt":1631545548750,"mc":[{"id":"1.187605875","rc":[{"batb":[[0,1.06,950.7],[1,1.01,479.17],[2,1.06,0]],"batl":[[0,1.39,17.9],[1,1.4,954.47],[2,3.8,27.43]],"ltp":1.39,"tv":691.82,"id":11214864}]}]}
{"op":"mcm","clk":"4215895281","pt":1631545552815,"mc":[{"id":"1.187605875","rc":[{"batb":[[0,1.01,479.17],[1,1.01,0]],"ltp":1.39,"tv":691.82,"id":11214864}]}]}
{"op":"mcm","clk":"4215895378","pt":1631545554533,"mc":[{"id":"1.187605875","rc":[{"batb":[[0,1.14,136.79],[1,1.13,305.66],[2,1.01,479.17]],"batl":[[0,1.16,311.38],[1,1.17,119.77],[2,1.39,17.9]],"ltp":1.39,"tv":691.82,"id":11214864}]}]}
{"op":"mcm","clk":"4215895533","pt":1631545556835,"mc":[{"id":"1.187605875","rc":[{"batb":[[2,1.05,1085.45]],"ltp":1.39,"tv":691.82,"id":11214864}]}]}
{"op":"mcm","clk":"4215895815","pt":1631545561534,"mc":[{"id":"1.187605875","rc":[{"batb":[[0,1.05,1085.45],[1,1.01,479.17],[2,1.05,0]],"batl":[[0,1.39,17.9],[1,1.4,954.47],[2,3.8,27.43]],"ltp":1.39,"tv":691.82,"id":11214864}]}]}
{"op":"mcm","clk":"4215895990","pt":1631545564470,"mc":[{"id":"1.187605875","rc":[{"batb":[[0,1.12,334.75],[1,1.11,113.9],[2,1.05,1085.45]],"batl":[[0,1.18,121.66],[1,1.19,225.81],[2,1.39,17.9]],"ltp":1.39,"tv":691.82,"id":11214864}]}]}
{"op":"mcm","clk":"4215896554","pt":1631545572692,"mc":[{"id":"1.187605875","rc":[{"batb":[[0,1.05,1085.45],[1,1.01,479.17],[2,1.05,0]],"ltp":1.39,"tv":691.82,"id":11214864}]}]}
{"op":"mcm","clk":"4215896639","pt":1631545573879,"mc":[{"id":"1.187605875","rc":[{"batb":[[0,1.01,479.17],[1,1.01,0]],"ltp":1.39,"tv":691.82,"id":11214864}]}]}
{"op":"mcm","clk":"4215896707","pt":1631545574763,"mc":[{"id":"1.187605875","rc":[{"batb":[[0,6.4,51.33],[1,3,5.96],[2,2.6,3.73]],"batl":[[0,7.2,4.58],[1,7.6,41.95]],"ltp":3.6,"tv":43.84,"id":40752182}]}]}
{"op":"mcm","clk":"4215896743","pt":1631545575287,"mc":[{"id":"1.187605875","rc":[{"batb":[[0,1.16,265.12],[1,1.15,168.52],[2,1.01,479.17]],"ltp":1.39,"tv":691.82,"id":11214864}]}]}
{"op":"mcm","clk":"4215896923","pt":1631545577969,"mc":[{"id":"1.187605875","rc":[{"batb":[[2,1.06,1008.65]],"ltp":1.39,"tv":691.82,"id":11214864}]}]}
{"op":"mcm","clk":"4215897638","pt":1631545588996,"mc":[{"id":"1.187605875","rc":[{"batb":[[0,3,5.96],[1,2.6,3.73],[2,2.2,42.6]],"ltp":3.6,"tv":43.84,"id":40752182}]}]}
{"op":"mcm","clk":"4215897651","pt":1631545589309,"mc":[{"id":"1.187605875","rc":[{"batb":[[0,1.15,81.5],[1,1.06,1008.65],[2,1.01,479.17]],"batl":[[0,1.39,17.9],[1,1.4,954.47],[2,3.8,27.43]],"ltp":1.39,"tv":691.82,"id":11214864}]}]}
{"op":"mcm","clk":"4215898031","pt":1631545594985,"mc":[{"id":"1.187605875","rc":[{"batb":[[0,1.16,169.7],[1,1.15,264.77],[2,1.06,1008.65]],"batl":[[0,1.18,208.02],[1,1.19,215.02],[2,1.39,17.9]],"ltp":1.39,"tv":691.82,"id":11214864}]}]}
{"op":"mcm","clk":"4215898426","pt":1631545600026,"mc":[{"id":"1.187605875","rc":[{"batb":[[0,1.15,81.5],[1,1.06,1008.65],[2,1.01,479.17]],"batl":[[0,1.39,17.9],[1,1.4,954.47],[2,3.8,27.43]],"ltp":1.39,"tv":691.82,"id":11214864}]}]}
{"op":"mcm","clk":"4215898621","pt":1631545602886,"mc":[{"id":"1.187605875","rc":[{"batb":[[1,1.14,332.75],[2,1.06,1008.65]],"batl":[[0,1.2,147.85],[1,1.21,200.06],[2,1.39,17.9]],"ltp":1.39,"tv":691.82,"id":11214864}]}]}
{"op":"mcm","clk":"4215899782","pt":1631545619807,"mc":[{"id":"1.187605875","rc":[{"batb":[[0,1.06,1008.65],[1,1.01,479.17],[2,1.06,0]],"ltp":1.39,"tv":691.82,"id":11214864}]}]}
{"op":"mcm","clk":"4215900004","pt":1631545622761,"mc":[{"id":"1.187605875","rc":[{"batl":[[0,6.8,35.83]],"ltp":3.6,"tv":43.84,"id":40752182},{"batb":[[0,1.18,200.34],[1,1.17,255.48],[2,1.06,1008.65]],"batl":[[1,1.21,542.63]],"ltp":1.39,"tv":691.82,"id":11214864}]}]}
{"op":"mcm","clk":"4215907086","pt":1631545727020,"mc":[{"id":"1.187605875","rc":[{"trd":[[1.18,380.26]],"batb":[[0,1.17,255.48],[1,1.06,1008.65],[2,1.03,497.12]],"batl":[[1,1.21,505.12]],"ltp":1.18,"tv":1072.08,"id":11214864}],"tv":1115.92}]}
{"op":"mcm","clk":"4215907247","pt":1631545729967,"mc":[{"id":"1.187605875","rc":[{"batb":[[0,1.17,334.17],[1,1.16,95.14],[2,1.06,1008.65]],"batl":[[0,1.2,253.88]],"ltp":1.18,"tv":1072.08,"id":11214864}]}]}
{"op":"mcm","clk":"4215907697","pt":1631545737071,"mc":[{"id":"1.187605875","rc":[{"batb":[[0,1.06,1008.65],[1,1.03,497.12],[2,1.01,479.17]],"batl":[[0,1.39,17.9],[1,1.4,954.47],[2,3.8,27.43]],"ltp":1.18,"tv":1072.08,"id":11214864}]}]}
{"op":"mcm","clk":"4215907836","pt":1631545740066,"mc":[{"id":"1.187605875","rc":[{"batb":[[0,1.15,171.19],[1,1.14,267.08],[2,1.06,1008.65]],"batl":[[0,1.24,156.78],[1,1.25,165.08],[2,1.39,17.9]],"ltp":1.18,"tv":1072.08,"id":11214864}]}]}
{"op":"mcm","clk":"4215907979","pt":1631545742672,"mc":[{"id":"1.187605875","rc":[{"batl":[[0,1.39,17.9],[1,1.4,954.47],[2,3.8,27.43]],"ltp":1.18,"tv":1072.08,"id":11214864}]}]}
{"op":"mcm","clk":"4215908115","pt":1631545744600,"mc":[{"id":"1.187605875","rc":[{"batb":[[2,1.03,497.12]],"ltp":1.18,"tv":1072.08,"id":11214864}]}]}
{"op":"mcm","clk":"4215908203","pt":1631545745680,"mc":[{"id":"1.187605875","rc":[{"batl":[[0,8,49.6]],"ltp":3.6,"tv":43.84,"id":40752182},{"batl":[[0,1.16,32.38],[1,1.17,250.41],[2,1.18,176.58]],"ltp":1.18,"tv":1072.08,"id":11214864}]}]}
{"op":"mcm","clk":"4215908390","pt":1631545748175,"mc":[{"id":"1.187605875","rc":[{"batb":[[2,1.06,950.7]],"ltp":1.18,"tv":1072.08,"id":11214864}]}]}
{"op":"mcm","clk":"4215909280","pt":1631545760875,"mc":[{"id":"1.187605875","rc":[{"batb":[[0,1.06,950.7],[1,1.03,497.12],[2,1.01,479.17]],"batl":[[0,1.39,17.9],[1,1.4,954.47],[2,3.8,27.43]],"ltp":1.18,"tv":1072.08,"id":11214864}]}]}
{"op":"mcm","clk":"4215909696","pt":1631545766726,"mc":[{"id":"1.187605875","rc":[{"batb":[[0,1.15,371.4],[1,1.06,950.7],[2,1.03,497.12]],"batl":[[0,1.17,70.42],[1,1.18,246.55],[2,1.39,17.9]],"ltp":1.18,"tv":1072.08,"id":11214864}]}]}
{"op":"mcm","clk":"4215910227","pt":1631545773841,"mc":[{"id":"1.187605875","rc":[{"batb":[[0,1.06,950.7],[1,1.03,497.12],[2,1.01,479.17]],"batl":[[0,1.39,17.9],[1,1.4,954.47],[2,3.8,27.43]],"ltp":1.18,"tv":1072.08,"id":11214864}]}]}
{"op":"mcm","clk":"4215910448","pt":1631545776700,"mc":[{"id":"1.187605875","rc":[{"batb":[[0,1.13,143.74],[1,1.12,302.61],[2,1.06,950.7]],"batl":[[0,1.2,102.69],[1,1.21,204.85],[2,1.39,17.9]],"ltp":1.18,"tv":1072.08,"id":11214864}]}]}
{"op":"mcm","clk":"4215910876","pt":1631545782730,"mc":[{"id":"1.187605875","rc":[{"batl":[[0,1.39,17.9],[1,1.4,954.47],[2,3.8,27.43]],"ltp":1.18,"tv":1072.08,"id":11214864}]}]}
{"op":"mcm","clk":"4215910971","pt":1631545784069,"mc":[{"id":"1.187605875","rc":[{"batb":[[2,1.03,497.12]],"ltp":1.18,"tv":1072.08,"id":11214864}]}]}
{"op":"mcm","clk":"4215911099","pt":1631545785751,"mc":[{"id":"1.187605875","rc":[{"batl":[[0,9.2,42.51]],"ltp":3.6,"tv":43.84,"id":40752182},{"batb":[[2,1.01,479.17]],"batl":[[0,1.14,50.35],[1,1.15,631.22],[2,1.16,74.86]],"ltp":1.18,"tv":1072.08,"id":11214864}]}]}
{"op":"mcm","clk":"4215911279","pt":1631545788450,"mc":[{"id":"1.187605875","rc":[{"batb":[[2,1.04,1300.13]],"ltp":1.18,"tv":1072.08,"id":11214864}]}]}
{"op":"mcm","clk":"4215912355","pt":1631545804049,"mc":[{"id":"1.187605875","rc":[{"batl":[[0,1.15,360.44],[1,1.16,74.86],[2,1.39,17.9]],"ltp":1.18,"tv":1072.08,"id":11214864}]}]}
{"op":"mcm","clk":"4215912382","pt":1631545804456,"mc":[{"id":"1.187605875","rc":[{"batb":[[0,1.04,1300.13],[1,1.01,479.17],[2,1.04,0]],"batl":[[0,1.39,17.9],[1,1.4,954.47],[2,3.8,27.43]],"ltp":1.18,"tv":1072.08,"id":11214864}]}]}
{"op":"mcm","clk":"4215912885","pt":1631545810854,"mc":[{"id":"1.187605875","rc":[{"batb":[[0,1.13,310.68],[1,1.12,134.18],[2,1.04,1300.13]],"batl":[[0,1.15,212.98],[1,1.16,221.05],[2,1.39,17.9]],"ltp":1.18,"tv":1072.08,"id":11214864}]}]}
{"op":"mcm","clk":"4215913140","pt":1631545814960,"mc":[{"id":"1.187605875","rc":[{"batb":[[0,1.04,1300.13],[1,1.01,479.17],[2,1.04,0]],"batl":[[0,1.39,17.9],[1,1.4,954.47],[2,3.8,27.43]],"ltp":1.18,"tv":1072.08,"id":11214864}]}]}
{"op":"mcm","clk":"4215913381","pt":1631545817865,"mc":[{"id":"1.187605875","rc":[{"batb":[[0,1.11,392.67],[1,1.04,1300.13],[2,1.01,479.17]],"batl":[[0,1.17,196.56],[1,1.18,229.97],[2,1.39,17.9]],"ltp":1.18,"tv":1072.08,"id":11214864}]}]}
{"op":"mcm","clk":"4215913541","pt":1631545820147,"mc":[{"id":"1.187605875","rc":[{"batb":[[0,1.04,1300.13],[1,1.01,479.17],[2,1.01,0]],"ltp":1.18,"tv":1072.08,"id":11214864}]}]}
{"op":"mcm","clk":"4215913762","pt":1631545822946,"mc":[{"id":"1.187605875","rc":[{"batl":[[0,8,46.02]],"ltp":3.6,"tv":43.84,"id":40752182},{"batb":[[0,1.15,17.48]],"batl":[[0,1.16,28.99],[1,1.17,196.56],[2,1.18,577.3]],"ltp":1.18,"tv":1072.08,"id":11214864}]}]}
{"op":"mcm","clk":"4215913773","pt":1631545823154,"mc":[{"id":"1.187605875","rc":[{"batb":[[0,1.15,248.56],[1,1.14,206.67],[2,1.01,479.17]],"ltp":1.18,"tv":1072.08,"id":11214864}]}]}
{"op":"mcm","clk":"4215914008","pt":1631545826774,"mc":[{"id":"1.187605875","rc":[{"batb":[[2,1.06,950.7]],"ltp":1.18,"tv":1072.08,"id":11214864}]}]}
{"op":"mcm","clk":"4215915109","pt":1631545843067,"mc":[{"id":"1.187605875","rc":[{"batb":[[0,1.15,231.08]],"batl":[[0,1.17,196.56],[1,1.18,229.97],[2,1.39,17.9]],"ltp":1.18,"tv":1072.08,"id":11214864}]}]}
{"op":"mcm","clk":"4215915120","pt":1631545843275,"mc":[{"id":"1.187605875","rc":[{"batb":[[0,1.06,950.7],[1,1.01,479.17],[2,1.06,0]],"batl":[[0,1.39,17.9],[1,1.4,954.47],[2,3.8,27.43]],"ltp":1.18,"tv":1072.08,"id":11214864}]}]}
{"op":"mcm","clk":"4215915338","pt":1631545846296,"mc":[{"id":"1.187605875","rc":[{"batb":[[0,1.13,88.7],[1,1.12,358.14],[2,1.06,950.7]],"batl":[[0,1.21,153.28],[1,1.22,192.4],[2,1.39,17.9]],"ltp":1.18,"tv":1072.08,"id":11214864}]}]}
{"op":"mcm","clk":"4215915959","pt":1631545856098,"mc":[{"id":"1.187605875","rc":[{"batl":[[0,1.39,17.9],[1,1.4,954.47],[2,3.8,27.43]],"ltp":1.18,"tv":1072.08,"id":11214864}]}]}
{"op":"mcm","clk":"4215916106","pt":1631545857973,"mc":[{"id":"1.187605875","rc":[{"batb":[[2,1.01,479.17]],"ltp":1.18,"tv":1072.08,"id":11214864}]}]}
{"op":"mcm","clk":"4215916186","pt":1631545859021,"mc":[{"id":"1.187605875","rc":[{"batl":[[0,9.2,4.61]],"ltp":3.6,"tv":43.84,"id":40752182},{"batb":[[1,1.12,637.09]],"batl":[[0,1.14,107.88],[1,1.15,637.1],[2,1.39,17.9]],"ltp":1.18,"tv":1072.08,"id":11214864}]}]}
{"op":"mcm","clk":"4215916412","pt":1631545862103,"mc":[{"id":"1.187605875","rc":[{"batb":[[2,1.04,1300.13]],"ltp":1.18,"tv":1072.08,"id":11214864}]}]}
{"op":"mcm","clk":"4215917145","pt":1631545872036,"mc":[{"id":"1.187605875","rc":[{"batb":[[1,1.12,358.14]],"batl":[[1,1.15,302.12]],"ltp":1.18,"tv":1072.08,"id":11214864}]}]}
{"op":"mcm","clk":"4215917179","pt":1631545872409,"mc":[{"id":"1.187605875","rc":[{"batb":[[0,1.04,1300.13],[1,1.01,479.17],[2,1.04,0]],"batl":[[0,1.39,17.9],[1,1.4,954.47],[2,3.8,27.43]],"ltp":1.18,"tv":1072.08,"id":11214864}]}]}
{"op":"mcm","clk":"4215917399","pt":1631545875312,"mc":[{"id":"1.187605875","rc":[{"batb":[[0,1.11,318],[1,1.1,134.87],[2,1.04,1300.13]],"batl":[[0,1.17,259.36],[1,1.18,167.71],[2,1.39,17.9]],"ltp":1.18,"tv":1072.08,"id":11214864}]}]}
{"op":"mcm","clk":"4215918678","pt":1631545896041,"mc":[{"id":"1.187605875","rc":[{"batl":[[0,1.39,17.9],[1,1.4,954.47],[2,3.8,27.43]],"ltp":1.18,"tv":1072.08,"id":11214864}]}]}
{"op":"mcm","clk":"4215918883","pt":1631545898941,"mc":[{"id":"1.187605875","rc":[{"batl":[[0,11,29.04]],"ltp":3.6,"tv":43.84,"id":40752182},{"batb":[[0,1.11,339.76],[1,1.1,425.24]],"batl":[[0,1.12,42.76],[1,1.13,600.63],[2,1.14,119.61]],"ltp":1.18,"tv":1072.08,"id":11214864}]}]}
{"op":"mcm","clk":"4215920726","pt":1631545921679,"mc":[{"id":"1.187605875","rc":[{"batb":[[0,1.1,120.26],[1,1.04,1300.13],[2,1.01,479.17]],"batl":[[0,1.14,103.37],[1,1.39,17.9],[2,1.4,954.47]],"ltp":1.18,"tv":1072.08,"id":11214864}]}]}
{"op":"mcm","clk":"4215920960","pt":1631545924477,"mc":[{"id":"1.187605875","rc":[{"batb":[[1,1.09,338.58],[2,1.04,1300.13]],"batl":[[1,1.15,302.35],[2,1.39,17.9]],"ltp":1.18,"tv":1072.08,"id":11214864}]}]}
{"op":"mcm","clk":"4215921568","pt":1631545931094,"mc":[{"id":"1.187605875","rc":[{"batl":[[0,1.39,17.9],[1,1.4,954.47],[2,3.8,27.43]],"ltp":1.18,"tv":1072.08,"id":11214864}]}]}
{"op":"mcm","clk":"4215921637","pt":1631545932083,"mc":[{"id":"1.187605875","rc":[{"batb":[[2,1.01,479.17]],"ltp":1.18,"tv":1072.08,"id":11214864}]}]}
{"op":"mcm","clk":"4215921805","pt":1631545933996,"mc":[{"id":"1.187605875","rc":[{"batl":[[0,12,42.2]],"ltp":3.6,"tv":43.84,"id":40752182},{"batl":[[0,1.11,257.7],[1,1.12,750.49],[2,1.39,17.9]],"ltp":1.18,"tv":1072.08,"id":11214864}]}]}
{"op":"mcm","clk":"4215921950","pt":1631545935685,"mc":[{"id":"1.187605875","rc":[{"batb":[[2,1.03,1558.63]],"ltp":1.18,"tv":1072.08,"id":11214864}]}]}
{"op":"mcm","clk":"4215922623","pt":1631545944524,"mc":[{"id":"1.187605875","rc":[{"batb":[[0,1.03,1558.63],[1,1.01,479.17],[2,1.03,0]],"batl":[[0,1.39,17.9],[1,1.4,954.47],[2,3.8,27.43]],"ltp":1.18,"tv":1072.08,"id":11214864}]}]}
{"op":"mcm","clk":"4215923055","pt":1631545950945,"mc":[{"id":"1.187605875","rc":[{"batb":[[0,1.09,459.95],[1,1.03,1558.63],[2,1.01,479.17]],"batl":[[0,1.11,308.78],[1,1.12,141.6],[2,1.39,17.9]],"ltp":1.18,"tv":1072.08,"id":11214864}]}]}
{"op":"mcm","clk":"4215923323","pt":1631545954650,"mc":[{"id":"1.187605875","rc":[{"batb":[[0,1.03,1558.63],[1,1.01,479.17],[2,1.01,0]],"batl":[[0,1.39,17.9],[1,1.4,954.47],[2,3.8,27.43]],"ltp":1.18,"tv":1072.08,"id":11214864}]}]}
{"op":"mcm","clk":"4215923517","pt":1631545957619,"mc":[{"id":"1.187605875","rc":[{"batb":[[0,1.08,464.21],[1,1.03,1558.63],[2,1.01,479.17]],"batl":[[0,1.13,324.99],[1,1.14,117.63],[2,1.39,17.9]],"ltp":1.18,"tv":1072.08,"id":11214864}]}]}
{"op":"mcm","clk":"4215924311","pt":1631545968673,"mc":[{"id":"1.187605875","rc":[{"batb":[[0,1.03,1558.63],[1,1.01,479.17],[2,1.01,0]],"ltp":1.18,"tv":1072.08,"id":11214864}]}]}
{"op":"mcm","clk":"4215924457","pt":1631545970591,"mc":[{"id":"1.187605875","rc":[{"batb":[[0,1.01,479.17],[1,1.01,0]],"ltp":1.18,"tv":1072.08,"id":11214864}]}]}
{"op":"mcm","clk":"4215924534","pt":1631545971580,"mc":[{"id":"1.187605875","rc":[{"batl":[[0,11,29.46]],"ltp":3.6,"tv":43.84,"id":40752182},{"batb":[[0,1.11,338.96],[1,1.1,431.83],[2,1.01,479.17]],"batl":[[0,1.12,41.36],[1,1.13,593.61],[2,1.14,117.63]],"ltp":1.18,"tv":1072.08,"id":11214864}]}]}
{"op":"mcm","clk":"4215924708","pt":1631545974181,"mc":[{"id":"1.187605875","rc":[{"batb":[[2,1.04,1252.86]],"ltp":1.18,"tv":1072.08,"id":11214864}]}]}
{"op":"mcm","clk":"4215925896","pt":1631545989537,"mc":[{"id":"1.187605875","rc":[{"batb":[[0,1.04,1252.86],[1,1.01,479.17],[2,1.04,0]],"batl":[[0,1.39,17.9],[1,1.4,954.47],[2,3.8,27.43]],"ltp":1.18,"tv":1072.08,"id":11214864}]}]}
{"op":"mcm","clk":"4215926176","pt":1631545992542,"mc":[{"id":"1.187605875","rc":[{"batb":[[0,1.09,459.95],[1,1.04,1252.86],[2,1.01,479.17]],"batl":[[0,1.15,348.98],[1,1.16,86.22],[2,1.39,17.9]],"ltp":1.18,"tv":1072.08,"id":11214864}]}]}
{"op":"mcm","clk":"4215926327","pt":1631545994523,"mc":[{"id":"1.187605875","rc":[{"batb":[[0,1.04,1252.86],[1,1.01,479.17],[2,1.01,0]],"ltp":1.18,"tv":1072.08,"id":11214864}]}]}
{"op":"mcm","clk":"4215926449","pt":1631545996046,"mc":[{"id":"1.187605875","rc":[{"batb":[[0,1.01,479.17],[1,1.01,0]],"ltp":1.18,"tv":1072.08,"id":11214864}]}]}
{"op":"mcm","clk":"4215926582","pt":1631545997432,"mc":[{"id":"1.187605875","rc":[{"batl":[[0,9.2,44.74]],"ltp":3.6,"tv":43.84,"id":40752182},{"batb":[[0,1.13,156.72],[1,1.12,289.51],[2,1.01,479.17]],"batl":[[0,1.14,49.22],[1,1.15,621.24],[2,1.16,86.22]],"ltp":1.18,"tv":1072.08,"id":11214864}]}]}
{"op":"mcm","clk":"4215926794","pt":1631545999435,"mc":[{"id":"1.187605875","rc":[{"batb":[[2,1.04,1300.13]],"ltp":1.18,"tv":1072.08,"id":11214864}]}]}
{"op":"mcm","clk":"4215928250","pt":1631546016585,"mc":[{"id":"1.187605875","rc":[{"batb":[[0,1.04,1300.13],[1,1.01,479.17],[2,1.04,0]],"batl":[[0,1.16,86.22],[1,1.39,17.9],[2,1.4,954.47]],"ltp":1.18,"tv":1072.08,"id":11214864}]}]}
{"op":"mcm","clk":"4215928487","pt":1631546019581,"mc":[{"id":"1.187605875","rc":[{"batb":[[0,1.11,304.93],[1,1.1,148.07],[2,1.04,1300.13]],"batl":[[1,1.17,262.47],[2,1.39,17.9]],"ltp":1.18,"tv":1072.08,"id":11214864}]}]}
{"op":"mcm","clk":"4215928810","pt":1631546023499,"mc":[{"id":"1.187605875","rc":[{"batl":[[0,1.39,17.9],[1,1.4,954.47],[2,3.8,27.43]],"ltp":1.18,"tv":1072.08,"id":11214864}]}]}
{"op":"mcm","clk":"4215929039","pt":1631546026365,"mc":[{"id":"1.187605875","rc":[{"batl":[[0,11,29.73]],"ltp":3.6,"tv":43.84,"id":40752182},{"batb":[[0,1.11,329.85],[1,1.1,445.35]],"batl":[[0,1.12,39.84],[1,1.13,589.88],[2,1.14,108.43]],"ltp":1.18,"tv":1072.08,"id":11214864}]}]}
{"op":"mcm","clk":"4215930626","pt":1631546037827,"mc":[{"id":"1.187605875","rc":[{"batb":[[0,1.04,1300.13],[1,1.01,479.17],[2,1.04,0]],"batl":[[0,1.39,17.9],[1,1.4,954.47],[2,3.8,27.43]],"ltp":1.18,"tv":1072.08,"id":11214864}]}]}
{"op":"mcm","clk":"4215930975","pt":1631546040824,"mc":[{"id":"1.187605875","rc":[{"batb":[[0,1.09,387.72],[1,1.08,72.89],[2,1.04,1300.13]],"batl":[[0,1.15,241.35],[1,1.16,192.92],[2,1.39,17.9]],"ltp":1.18,"tv":1072.08,"id":11214864}]}]}
{"op":"mcm","clk":"4215931050","pt":1631546041663,"mc":[{"id":"1.187605875","rc":[{"batb":[[0,1.04,1300.13],[1,1.01,479.17],[2,1.04,0]],"batl":[[0,1.39,17.9],[1,1.4,954.47],[2,3.8,27.43]],"ltp":1.18,"tv":1072.08,"id":11214864}]}]}
{"op":"mcm","clk":"4215931171","pt":1631546042832,"mc":[{"id":"1.187605875","rc":[{"batb":[[0,1.01,479.17],[1,1.01,0]],"ltp":1.18,"tv":1072.08,"id":11214864}]}]}
{"op":"mcm","clk":"4215931334","pt":1631546044668,"mc":[{"id":"1.187605875","rc":[{"batb":[[0,1.11,128.12],[1,1.1,326.48],[2,1.01,479.17]],"batl":[[0,1.12,134.53],[1,1.13,310.33],[2,1.39,17.9]],"ltp":1.18,"tv":1072.08,"id":11214864}]}]}
{"op":"mcm","clk":"4215931591","pt":1631546047151,"mc":[{"id":"1.187605875","rc":[{"batb":[[2,1.03,1558.63]],"ltp":1.18,"tv":1072.08,"id":11214864}]}]}
{"op":"mcm","clk":"4215931919","pt":1631546049486,"mc":[{"id":"1.187605875","rc":[{"batb":[[0,1.03,1558.63],[1,1.01,479.17],[2,1.03,0]],"batl":[[0,1.39,17.9],[1,1.4,954.47],[2,3.8,27.43]],"ltp":1.18,"tv":1072.08,"id":11214864}]}]}
{"op":"mcm","clk":"4215932236","pt":1631546052347,"mc":[{"id":"1.187605875","rc":[{"batb":[[0,1.09,387.72],[1,1.08,72.89],[2,1.03,1558.63]],"batl":[[0,1.15,241.35],[1,1.16,192.92],[2,1.39,17.9]],"ltp":1.18,"tv":1072.08,"id":11214864}]}]}
{"op":"mcm","clk":"4215932655","pt":1631546057083,"mc":[{"id":"1.187605875","rc":[{"batl":[[0,1.39,17.9],[1,1.4,954.47],[2,3.8,27.43]],"ltp":1.18,"tv":1072.08,"id":11214864}]}]}
{"op":"mcm","clk":"4215933293","pt":1631546060089,"mc":[{"id":"1.187605875","rc":[{"batl":[[0,13.5,32.03]],"ltp":3.6,"tv":43.84,"id":40752182},{"batb":[[1,1.08,473.27],[2,1.01,7]],"batl":[[0,1.1,19.36],[1,1.11,716.43],[2,1.39,17.9]],"ltp":1.18,"tv":1072.08,"id":11214864}]}]}
{"op":"mcm","clk":"4215934472","pt":1631546062979,"mc":[{"id":"1.187605875","rc":[{"batl":[[2,1.25,14.92]],"ltp":1.18,"tv":1072.08,"id":11214864}]}]}
{"op":"mcm","clk":"4215934526","pt":1631546063499,"mc":[{"id":"1.187605875","rc":[{"batb":[[2,1.02,2179.83]],"ltp":1.18,"tv":1072.08,"id":11214864}]}]}
{"op":"mcm","clk":"4215935871","pt":1631546078807,"mc":[{"id":"1.187605875","rc":[{"batb":[[0,1.02,2179.83],[1,1.01,7],[2,1.02,0]],"batl":[[0,1.25,14.92],[1,1.33,1138.02],[2,1.39,17.9]],"ltp":1.18,"tv":1072.08,"id":11214864}]}]}
{"op":"mcm","clk":"4215936095","pt":1631546081807,"mc":[{"id":"1.187605875","rc":[{"batb":[[0,1.07,468.55],[1,1.02,2179.83],[2,1.01,7]],"batl":[[0,1.13,316.85],[1,1.14,125.7],[2,1.25,14.92]],"ltp":1.18,"tv":1072.08,"id":11214864}]}]}
{"op":"mcm","clk":"4215936128","pt":1631546082214,"mc":[{"id":"1.187605875","rc":[{"batb":[[0,1.02,2179.83],[1,1.01,7],[2,1.01,0]],"batl":[[0,1.25,14.92],[1,1.33,1138.02],[2,1.39,17.9]],"ltp":1.18,"tv":1072.08,"id":11214864}]}]}
{"op":"mcm","clk":"4215936318","pt":1631546085095,"mc":[{"id":"1.187605875","rc":[{"batb":[[0,1.09,177.37],[1,1.08,285.19],[2,1.02,2179.83]],"batl":[[0,1.1,180.18],[1,1.11,273.1],[2,1.25,14.92]],"ltp":1.18,"tv":1072.08,"id":11214864}]}]}
{"op":"mcm","clk":"4215936444","pt":1631546087219,"mc":[{"id":"1.187605875","rc":[{"batb":[[0,1.02,2179.83],[1,1.01,7],[2,1.02,0]],"batl":[[0,1.25,14.92],[1,1.33,1138.02],[2,1.39,17.9]],"ltp":1.18,"tv":1072.08,"id":11214864}]}]}
{"op":"mcm","clk":"4215936625","pt":1631546090105,"mc":[{"id":"1.187605875","rc":[{"batb":[[0,1.07,468.55],[1,1.02,2179.83],[2,1.01,7]],"batl":[[0,1.13,316.85],[1,1.14,125.7],[2,1.25,14.92]],"ltp":1.18,"tv":1072.08,"id":11214864}]}]}
{"op":"mcm","clk":"4215936865","pt":1631546093219,"mc":[{"id":"1.187605875","rc":[{"batb":[[0,1.02,2179.83],[1,1.01,7],[2,1.01,0]],"ltp":1.18,"tv":1072.08,"id":11214864}]}]}
{"op":"mcm","clk":"4215936974","pt":1631546094714,"mc":[{"id":"1.187605875","rc":[{"batb":[[0,1.01,7],[1,1.01,0]],"ltp":1.18,"tv":1072.08,"id":11214864}]}]}
{"op":"mcm","clk":"4215937086","pt":1631546096127,"mc":[{"id":"1.187605875","rc":[{"batl":[[0,11,29.57]],"ltp":3.6,"tv":43.84,"id":40752182},{"batb":[[0,1.11,351.49],[1,1.1,423.35],[2,1.01,7]],"batl":[[0,1.12,38.49],[1,1.13,554.4],[2,1.14,125.7]],"ltp":1.18,"tv":1072.08,"id":11214864}]}]}
{"op":"mcm","clk":"4215937290","pt":1631546098904,"mc":[{"id":"1.187605875","rc":[{"batb":[[2,1.04,1252.86]],"ltp":1.18,"tv":1072.08,"id":11214864}]}]}
{"op":"mcm","clk":"4215938385","pt":1631546111743,"mc":[{"id":"1.187605875","rc":[{"batb":[[0,1.11,325.11],[1,1.1,127.69]],"batl":[[0,1.13,316.85],[1,1.14,125.7],[2,1.25,14.92]],"ltp":1.18,"tv":1072.08,"id":11214864}]}]}
{"op":"mcm","clk":"4215938428","pt":1631546112327,"mc":[{"id":"1.187605875","rc":[{"batb":[[0,1.04,1252.86],[1,1.01,7],[2,1.04,0]],"batl":[[0,1.25,14.92],[1,1.33,1138.02],[2,1.39,17.9]],"ltp":1.18,"tv":1072.08,"id":11214864}]}]}
{"op":"mcm","clk":"4215938667","pt":1631546115259,"mc":[{"id":"1.187605875","rc":[{"batb":[[0,1.09,408.57],[1,1.04,1252.86],[2,1.01,7]],"batl":[[0,1.15,225.14],[1,1.16,208.99],[2,1.25,14.92]],"ltp":1.18,"tv":1072.08,"id":11214864}]}]}
{"op":"mcm","clk":"4215939849","pt":1631546131703,"mc":[{"id":"1.187605875","rc":[{"batl":[[2,1.2,8.47]],"ltp":1.18,"tv":1072.08,"id":11214864}]}]}
{"op":"mcm","clk":"4215940422","pt":1631546139627,"mc":[{"id":"1.187605875","rc":[{"batl":[[0,1.2,8.47],[1,1.25,14.92],[2,1.33,1138.02]],"ltp":1.18,"tv":1072.08,"id":11214864}]}]}
{"op":"mcm","clk":"4215940513","pt":1631546140835,"mc":[{"id":"1.187605875","rc":[{"batb":[[1,1.01,7],[2,1.01,0]],"ltp":1.18,"tv":1072.08,"id":11214864}]}]}
{"op":"mcm","clk":"4215940651","pt":1631546142815,"mc":[{"id":"1.187605875","rc":[{"batl":[[0,13.5,32.55]],"ltp":3.6,"tv":43.84,"id":40752182},{"batb":[[1,1.08,406.85],[2,1.01,7]],"batl":[[0,1.1,18.48],[1,1.11,910.66],[2,1.2,8.47]],"ltp":1.18,"tv":1072.08,"id":11214864}]}]}
{"op":"mcm","clk":"4215940799","pt":1631546144542,"mc":[{"id":"1.187605875","rc":[{"batb":[[2,1.02,2179.83]],"ltp":1.18,"tv":1072.08,"id":11214864}]}]}
{"op":"mcm","clk":"4215941685","pt":1631546150743,"mc":[{"id":"1.187605875","rc":[{"batl":[[2,1.25,14.92]],"ltp":1.18,"tv":1072.08,"id":11214864}]}]}
{"op":"mcm","clk":"4215942211","pt":1631546154351,"mc":[{"id":"1.187605875","rc":[{"batl":[[1,1.11,689.25]],"ltp":1.18,"tv":1072.08,"id":11214864}]}]}
{"op":"mcm","clk":"4215943435","pt":1631546163878,"mc":[{"id":"1.187605875","rc":[{"trd":[[1.09,16.94]],"batb":[[0,1.09,400.1]],"ltp":1.09,"tv":1089.02,"id":11214864}],"tv":1132.86}]}
{"op":"mcm","clk":"4215944897","pt":1631546178602,"mc":[{"id":"1.187605875","rc":[{"batb":[[0,1.02,2179.83],[1,1.01,7],[2,1.02,0]],"batl":[[0,1.25,14.92],[1,1.33,1138.02],[2,1.39,17.9]],"ltp":1.09,"tv":1089.02,"id":11214864}]}]}
{"op":"mcm","clk":"4215945204","pt":1631546181610,"mc":[{"id":"1.187605875","rc":[{"batb":[[0,1.07,468.55],[1,1.02,2179.83],[2,1.01,7]],"batl":[[0,1.13,305.38],[1,1.14,137.07],[2,1.25,14.92]],"ltp":1.09,"tv":1089.02,"id":11214864}]}]}
{"op":"mcm","clk":"4215946282","pt":1631546191701,"mc":[{"id":"1.187605875","rc":[{"batb":[[0,1.03,8.47]],"ltp":1.09,"tv":1089.02,"id":11214864}]}]}
{"op":"mcm","clk":"4215946380","pt":1631546192800,"mc":[{"id":"1.187605875","rc":[{"batb":[[1,1.01,7],[2,1.01,0]],"ltp":1.09,"tv":1089.02,"id":11214864}]}]}
{"op":"mcm","clk":"4215946567","pt":1631546194682,"mc":[{"id":"1.187605875","rc":[{"batl":[[0,11,30.02]],"ltp":3.6,"tv":43.84,"id":40752182},{"batb":[[0,1.11,605.91],[1,1.1,413.65],[2,1.03,8.47]],"batl":[[0,1.12,37.23],[1,1.13,535.89],[2,1.14,137.07]],"ltp":1.09,"tv":1089.02,"id":11214864}]}]}
{"op":"mcm","clk":"4215946726","pt":1631546196442,"mc":[{"id":"1.187605875","rc":[{"batb":[[2,1.04,1252.86]],"ltp":1.09,"tv":1089.02,"id":11214864}]}]}
{"op":"mcm","clk":"4215947759","pt":1631546206218,"mc":[{"id":"1.187605875","rc":[{"batb":[[0,1.11,366.94]],"ltp":1.09,"tv":1089.02,"id":11214864}]}]}
{"op":"mcm","clk":"4215948188","pt":1631546210424,"mc":[{"id":"1.187605875","rc":[{"batb":[[0,1.04,1252.86],[1,1.03,8.47],[2,1.01,7]],"batl":[[0,1.25,14.92],[1,1.33,1138.02],[2,1.39,17.9]],"ltp":1.09,"tv":1089.02,"id":11214864}]}]}
{"op":"mcm","clk":"4215948441","pt":1631546213380,"mc":[{"id":"1.187605875","rc":[{"batb":[[0,1.09,423.17],[1,1.04,1252.86],[2,1.03,8.47]],"batl":[[0,1.15,214.71],[1,1.16,219.34],[2,1.25,14.92]],"ltp":1.09,"tv":1089.02,"id":11214864}]}]}
{"op":"mcm","clk":"4215948990","pt":1631546218448,"mc":[{"id":"1.187605875","rc":[{"batl":[[0,1.25,14.92],[1,1.33,1138.02],[2,1.39,17.9]],"ltp":1.09,"tv":1089.02,"id":11214864}]}]}
{"op":"mcm","clk":"4215949205","pt":1631546220445,"mc":[{"id":"1.187605875","rc":[{"batb":[[1,1.03,8.47],[2,1.01,7]],"ltp":1.09,"tv":1089.02,"id":11214864}]}]}
{"op":"mcm","clk":"4215949323","pt":1631546221813,"mc":[{"id":"1.187605875","rc":[{"batl":[[0,12,3.44],[1,13.5,33.09]],"ltp":3.6,"tv":43.84,"id":40752182},{"batb":[[1,1.08,413.67],[2,1.03,8.47]],"batl":[[0,1.1,17.56],[1,1.11,889.11],[2,1.25,14.92]],"ltp":1.09,"tv":1089.02,"id":11214864}]}]}
{"op":"mcm","clk":"4215950532","pt":1631546233230,"mc":[{"id":"1.187605875","rc":[{"batl":[[1,1.11,667.75]],"ltp":1.09,"tv":1089.02,"id":11214864}]}]}
{"op":"mcm","clk":"4215951010","pt":1631546236975,"mc":[{"id":"1.187605875","rc":[{"batb":[[1,1.03,8.47],[2,1.02,2179.83]],"batl":[[0,1.11,396.52],[1,1.25,14.92],[2,1.33,1138.02]],"ltp":1.09,"tv":1089.02,"id":11214864}]}]}
{"op":"mcm","clk":"4215951026","pt":1631546237184,"mc":[{"id":"1.187605875","rc":[{"batb":[[0,1.03,8.47],[1,1.02,2179.83],[2,1.01,7]],"batl":[[0,1.25,14.92],[1,1.33,1138.02],[2,1.39,17.9]],"ltp":1.09,"tv":1089.02,"id":11214864}]}]}
{"op":"mcm","clk":"4215951292","pt":1631546240154,"mc":[{"id":"1.187605875","rc":[{"batb":[[0,1.07,468.55],[1,1.03,8.47],[2,1.02,2179.83]],"batl":[[0,1.13,288.93],[1,1.14,153.38],[2,1.25,14.92]],"ltp":1.09,"tv":1089.02,"id":11214864}]}]}
{"op":"mcm","clk":"4215952146","pt":1631546247758,"mc":[{"id":"1.187605875","rc":[{"batl":[[0,1.25,14.92],[1,1.33,1138.02],[2,1.39,17.9]],"ltp":1.09,"tv":1089.02,"id":11214864}]}]}
{"op":"mcm","clk":"4215952283","pt":1631546249191,"mc":[{"id":"1.187605875","rc":[{"batb":[[2,1.01,7]],"ltp":1.09,"tv":1089.02,"id":11214864}]}]}
{"op":"mcm","clk":"4215952422","pt":1631546250666,"mc":[{"id":"1.187605875","rc":[{"batb":[[0,12,25.25],[1,3,5.96],[2,2.6,3.73]],"batl":[[0,15,33.95]],"ltp":3.6,"tv":43.84,"id":40752182},{"batl":[[0,1.09,784.67],[1,1.25,14.92],[2,1.33,1138.02]],"ltp":1.09,"tv":1089.02,"id":11214864}]}]}
{"op":"mcm","clk":"4215952705","pt":1631546253396,"mc":[{"id":"1.187605875","rc":[{"batb":[[2,1.01,4165.03]],"batl":[[1,1.23,29.82],[2,1.25,14.92]],"ltp":1.09,"tv":1089.02,"id":11214864}]}]}
{"op":"mcm","clk":"4215952835","pt":1631546254695,"mc":[{"id":"1.187605875","rc":[{"trd":[[1.09,56.94]],"batl":[[0,1.09,764.67]],"ltp":1.09,"tv":1129.02,"id":11214864}],"tv":1172.86}]}
{"op":"mcm","clk":"4215953469","pt":1631546260382,"mc":[{"id":"1.187605875","rc":[{"batb":[[1,1.41,16.2],[2,1.4,767.39]],"batl":[[1,990,0.01]],"ltp":3.6,"tv":43.84,"id":40752182}]}]}
{"op":"mcm","clk":"4215953642","pt":1631546262200,"mc":[{"id":"1.187605875","rc":[{"batl":[[0,1.09,559.09]],"ltp":1.09,"tv":1129.02,"id":11214864}]}]}
{"op":"mcm","clk":"4215954718","pt":1631546272614,"mc":[{"id":"1.187605875","rc":[{"batb":[[2,1.01,4167.03]],"ltp":1.09,"tv":1129.02,"id":11214864}]}]}
{"op":"mcm","clk":"4215955875","pt":1631546283540,"mc":[{"id":"1.187605875","rc":[{"trd":[[1.09,60.94]],"batl":[[0,1.09,557.09]],"ltp":1.09,"tv":1133.02,"id":11214864}],"tv":1176.86}]}
{"op":"mcm","clk":"4215956956","pt":1631546293741,"mc":[{"id":"1.187605875","rc":[{"batl":[[0,15,28.45]],"ltp":3.6,"tv":43.84,"id":40752182},{"batl":[[0,1.09,459.95]],"ltp":1.09,"tv":1133.02,"id":11214864}]}]}
{"op":"mcm","clk":"4215957264","pt":1631546296624,"mc":[{"id":"1.187605875","rc":[{"batl":[[0,15,34.1]],"ltp":3.6,"tv":43.84,"id":40752182},{"batl":[[0,1.09,557.09]],"ltp":1.09,"tv":1133.02,"id":11214864}]}]}
{"op":"mcm","clk":"4215957974","pt":1631546303648,"mc":[{"id":"1.187605875","rc":[{"trd":[[1.09,77.88]],"batl":[[0,1.09,548.62]],"ltp":1.09,"tv":1149.96,"id":11214864}],"tv":1193.8}]}
{"op":"mcm","clk":"4215958307","pt":1631546307148,"mc":[{"id":"1.187605875","rc":[{"batl":[[0,1.09,557.09]],"ltp":1.09,"tv":1149.96,"id":11214864}]}]}
{"op":"mcm","clk":"4215960638","pt":1631546331283,"mc":[{"id":"1.187605875","rc":[{"batl":[[0,1.08,28.14],[1,1.09,557.09],[2,1.23,29.82]],"ltp":1.09,"tv":1149.96,"id":11214864}]}]}
{"op":"mcm","clk":"4215960958","pt":1631546334607,"mc":[{"id":"1.187605875","rc":[{"batl":[[2,1.21,14.92]],"ltp":1.09,"tv":1149.96,"id":11214864}]}]}
{"op":"mcm","clk":"4215966174","pt":1631546391078,"mc":[{"id":"1.187605875","rc":[{"batb":[[0,1.41,16.2],[1,1.4,767.39],[2,1.01,7]],"batl":[[0,990,0.01],[1,990,0]],"ltp":3.6,"tv":43.84,"id":40752182},{"batb":[[0,1.03,8.47],[1,1.01,4167.03],[2,1.01,0]],"batl":[[1,1.21,14.92],[2,1.23,29.82]],"ltp":1.09,"tv":1149.96,"id":11214864}]}]}
{"op":"mcm","clk":"4215966424","pt":1631546393984,"mc":[{"id":"1.187605875","rc":[{"batb":[[0,1.06,472.97],[1,1.03,8.47],[2,1.01,4167.03]],"batl":[[1,1.1,129.55],[2,1.11,323.28]],"ltp":1.09,"tv":1149.96,"id":11214864}]}]}
{"op":"mcm","clk":"4215966471","pt":1631546394610,"mc":[{"id":"1.187605875","rc":[{"batb":[[0,1.03,8.47],[1,1.01,4167.03],[2,1.01,0]],"batl":[[1,1.21,14.92],[2,1.23,29.82]],"ltp":1.09,"tv":1149.96,"id":11214864}]}]}
{"op":"mcm","clk":"4215966697","pt":1631546396890,"mc":[{"id":"1.187605875","rc":[{"batb":[[0,1.07,468.55],[1,1.03,8.47],[2,1.01,4167.03]],"batl":[[1,1.09,373.68],[2,1.21,14.92]],"ltp":1.09,"tv":1149.96,"id":11214864}]}]}
{"op":"mcm","clk":"4215966723","pt":1631546397203,"mc":[{"id":"1.187605875","rc":[{"batl":[[2,1.1,85.49]],"ltp":1.09,"tv":1149.96,"id":11214864}]}]}
{"op":"mcm","clk":"4215967183","pt":1631546402628,"mc":[{"id":"1.187605875","rc":[{"batb":[[0,1.03,8.47],[1,1.01,4167.03],[2,1.01,0]],"batl":[[1,1.1,85.49],[2,1.21,14.92]],"ltp":1.09,"tv":1149.96,"id":11214864}]}]}
{"op":"mcm","clk":"4215967479","pt":1631546405607,"mc":[{"id":"1.187605875","rc":[{"batb":[[0,1.06,472.97],[1,1.03,8.47],[2,1.01,4167.03]],"batl":[[1,1.1,129.55],[2,1.11,323.28]],"ltp":1.09,"tv":1149.96,"id":11214864}]}]}
{"op":"mcm","clk":"4215967589","pt":1631546406609,"mc":[{"id":"1.187605875","rc":[{"batb":[[0,1.03,8.47],[1,1.01,4167.03],[2,1.01,0]],"ltp":1.09,"tv":1149.96,"id":11214864}]}]}
{"op":"mcm","clk":"4215967727","pt":1631546408030,"mc":[{"id":"1.187605875","rc":[{"batb":[[1,1.01,9]],"ltp":1.09,"tv":1149.96,"id":11214864}]}]}
{"op":"mcm","clk":"4215967952","pt":1631546409951,"mc":[{"id":"1.187605875","rc":[{"trd":[[13.5,2.25]],"batl":[[0,12,1.19],[1,15,103.59],[2,990,0.01]],"ltp":13.5,"tv":46.09,"id":40752182},{"trd":[[1.08,28.14]],"batb":[[0,1.09,233.07],[1,1.08,228.97],[2,1.03,8.47]],"batl":[[0,1.1,147.02],[1,1.11,604.83],[2,1.21,14.92]],"ltp":1.08,"tv":1178.09,"id":11214864}],"tv":1224.19}]}
{"op":"mcm","clk":"4215968910","pt":1631546419532,"mc":[{"id":"1.187605875","rc":[{"batl":[[0,15,103.59],[1,990,0.01],[2,990,0]],"ltp":13.5,"tv":46.09,"id":40752182},{"batl":[[0,1.1,129.55]],"ltp":1.08,"tv":1178.09,"id":11214864}]}]}
{"op":"mcm","clk":"4215969254","pt":1631546422534,"mc":[{"id":"1.187605875","rc":[{"batl":[[0,13.5,4.76],[1,15,103.59],[2,990,0.01]],"ltp":13.5,"tv":46.09,"id":40752182},{"batb":[[1,1.08,288.46]],"batl":[[0,1.1,160.84]],"ltp":1.08,"tv":1178.09,"id":11214864}]}]}
{"op":"mcm","clk":"4215969964","pt":1631546429455,"mc":[{"id":"1.187605875","rc":[{"batl":[[0,990,0.01],[1,15,0],[2,990,0]],"ltp":13.5,"tv":46.09,"id":40752182},{"batb":[[0,1.03,8.47],[1,1.02,2179.83],[2,1.01,9]],"batl":[[0,1.21,14.92],[1,1.23,29.82],[2,1.25,14.92]],"ltp":1.08,"tv":1178.09,"id":11214864}]}]}
{"op":"mcm","clk":"4215970181","pt":1631546432448,"mc":[{"id":"1.187605875","rc":[{"batb":[[0,1.07,468.55],[1,1.03,8.47],[2,1.02,2179.83]],"batl":[[0,1.13,372.81],[1,1.14,70.23],[2,1.21,14.92]],"ltp":1.08,"tv":1178.09,"id":11214864}]}]}
{"op":"mcm","clk":"4215970592","pt":1631546436653,"mc":[{"id":"1.187605875","rc":[{"batl":[[0,1.21,14.92],[1,1.23,29.82],[2,1.25,14.92]],"ltp":1.08,"tv":1178.09,"id":11214864}]}]}
{"op":"mcm","clk":"4215970805","pt":1631546438670,"mc":[{"id":"1.187605875","rc":[{"batb":[[2,1.01,9]],"ltp":1.08,"tv":1178.09,"id":11214864}]}]}
{"op":"mcm","clk":"4215970894","pt":1631546439558,"mc":[{"id":"1.187605875","rc":[{"batb":[[0,11,28.06],[1,1.41,16.2],[2,1.4,767.39]],"batl":[[0,15,45.27],[1,990,0.01]],"ltp":13.5,"tv":46.09,"id":40752182},{"batl":[[0,1.09,494.33],[1,1.1,350.61],[2,1.21,14.92]],"ltp":1.08,"tv":1178.09,"id":11214864}]}]}
{"op":"mcm","clk":"4215971160","pt":1631546442739,"mc":[{"id":"1.187605875","rc":[{"batb":[[2,1.01,4167.03]],"ltp":1.08,"tv":1178.09,"id":11214864}]}]}
{"op":"mcm","clk":"4215971609","pt":1631546447352,"mc":[{"id":"1.187605875","rc":[{"batb":[[0,1.41,16.2],[1,1.4,767.39],[2,1.01,7]],"batl":[[0,990,0.01],[1,990,0]],"ltp":13.5,"tv":46.09,"id":40752182},{"batb":[[0,1.03,8.47],[1,1.01,4167.03],[2,1.01,0]],"batl":[[0,1.21,14.92],[1,1.23,29.82],[2,1.25,14.92]],"ltp":1.08,"tv":1178.09,"id":11214864}]}]}
{"op":"mcm","clk":"4215971975","pt":1631546450412,"mc":[{"id":"1.187605875","rc":[{"batb":[[0,1.06,472.97],[1,1.03,8.47],[2,1.01,4167.03]],"batl":[[0,1.11,273.37],[1,1.12,176.7],[2,1.21,14.92]],"ltp":1.08,"tv":1178.09,"id":11214864}]}]}
{"op":"mcm","clk":"4215972768","pt":1631546457006,"mc":[{"id":"1.187605875","rc":[{"batl":[[0,1.21,14.92],[1,1.23,29.82],[2,1.25,14.92]],"ltp":1.08,"tv":1178.09,"id":11214864}]}]}
{"op":"mcm","clk":"4215972886","pt":1631546458104,"mc":[{"id":"1.187605875","rc":[{"batb":[[2,1.01,9]],"ltp":1.08,"tv":1178.09,"id":11214864}]}]}
{"op":"mcm","clk":"4215973094","pt":1631546459891,"mc":[{"id":"1.187605875","rc":[{"batb":[[0,13.5,15.57],[1,1.41,16.2],[2,1.4,767.39]],"batl":[[0,17.5,30.63],[1,990,0.01]],"ltp":13.5,"tv":46.09,"id":40752182},{"batl":[[0,1.07,56.93],[1,1.08,658.79],[2,1.21,14.92]],"ltp":1.08,"tv":1178.09,"id":11214864}]}]}
{"op":"mcm","clk":"4215973292","pt":1631546462209,"mc":[{"id":"1.187605875","rc":[{"batb":[[2,1.01,3979.74]],"ltp":1.08,"tv":1178.09,"id":11214864}]}]}
{"op":"mcm","clk":"4215974376","pt":1631546473396,"mc":[{"id":"1.187605875","rc":[{"batb":[[0,1.41,16.2],[1,1.4,767.39],[2,1.01,7]],"batl":[[0,990,0.01],[1,990,0]],"ltp":13.5,"tv":46.09,"id":40752182},{"batb":[[0,1.03,8.47],[1,1.01,3979.74],[2,1.01,0]],"batl":[[0,1.21,14.92],[1,1.23,29.82],[2,1.25,14.92]],"ltp":1.08,"tv":1178.09,"id":11214864}]}]}
{"op":"mcm","clk":"4215974663","pt":1631546476428,"mc":[{"id":"1.187605875","rc":[{"batb":[[0,1.05,477.47],[1,1.03,8.47],[2,1.01,3979.74]],"batl":[[0,1.09,202.91],[1,1.1,254.7],[2,1.21,14.92]],"ltp":1.08,"tv":1178.09,"id":11214864}]}]}
{"op":"mcm","clk":"4215975523","pt":1631546484223,"mc":[{"id":"1.187605875","rc":[{"batb":[[0,1.03,8.47],[1,1.01,3979.74],[2,1.01,0]],"ltp":1.08,"tv":1178.09,"id":11214864}]}]}
{"op":"mcm","clk":"4215975800","pt":1631546487036,"mc":[{"id":"1.187605875","rc":[{"batb":[[0,11,21.75],[1,1.41,16.2],[2,1.4,767.39]],"batl":[[0,15,56.78],[1,990,0.01]],"ltp":13.5,"tv":46.09,"id":40752182},{"batb":[[1,1.01,9]],"batl":[[0,1.09,287.36],[1,1.1,472.22]],"ltp":1.08,"tv":1178.09,"id":11214864}]}]}
{"op":"mcm","clk":"4215975820","pt":1631546487244,"mc":[{"id":"1.187605875","rc":[{"batb":[[0,1.08,220.48],[1,1.07,246.01],[2,1.03,8.47]],"ltp":1.08,"tv":1178.09,"id":11214864}]}]}
{"op":"mcm","clk":"4215977693","pt":1631546505943,"mc":[{"id":"1.187605875","rc":[{"batb":[[0,1.41,16.2],[1,1.4,767.39],[2,1.01,7]],"batl":[[0,990,0.01],[1,990,0]],"ltp":13.5,"tv":46.09,"id":40752182},{"batl":[[0,1.09,202.91],[1,1.1,254.7]],"ltp":1.08,"tv":1178.09,"id":11214864}]}]}
{"op":"mcm","clk":"4215977719","pt":1631546506150,"mc":[{"id":"1.187605875","rc":[{"batb":[[0,1.03,8.47],[1,1.01,4167.03],[2,1.03,0]],"batl":[[0,1.21,14.92],[1,1.23,29.82],[2,1.25,14.92]],"ltp":1.08,"tv":1178.09,"id":11214864}]}]}
{"op":"mcm","clk":"4215978020","pt":1631546509159,"mc":[{"id":"1.187605875","rc":[{"batb":[[0,1.06,472.97],[1,1.03,8.47],[2,1.01,4167.03]],"batl":[[0,1.12,265.49],[1,1.13,180.53],[2,1.21,14.92]],"ltp":1.08,"tv":1178.09,"id":11214864}]}]}
{"op":"mcm","clk":"4215978404","pt":1631546512884,"mc":[{"id":"1.187605875","rc":[{"batl":[[0,1.21,14.92],[1,1.23,29.82],[2,1.25,14.92]],"ltp":1.08,"tv":1178.09,"id":11214864}]}]}
{"op":"mcm","clk":"4215978527","pt":1631546513970,"mc":[{"id":"1.187605875","rc":[{"batb":[[2,1.01,9]],"ltp":1.08,"tv":1178.09,"id":11214864}]}]}
{"op":"mcm","clk":"4215978724","pt":1631546515860,"mc":[{"id":"1.187605875","rc":[{"batb":[[0,13.5,18.16],[1,1.41,16.2],[2,1.4,767.39]],"ltp":13.5,"tv":46.09,"id":40752182},{"batb":[[0,1.06,846]],"batl":[[0,1.07,142.79],[1,1.08,621],[2,1.21,14.92]],"ltp":1.08,"tv":1178.09,"id":11214864}]}]}
{"op":"mcm","clk":"4215978942","pt":1631546517891,"mc":[{"id":"1.187605875","rc":[{"batb":[[2,1.01,3979.74]],"ltp":1.08,"tv":1178.09,"id":11214864}]}]}
{"op":"mcm","clk":"4215979528","pt":1631546523664,"mc":[{"id":"1.187605875","rc":[{"batb":[[0,1.41,16.2],[1,1.4,767.39],[2,1.01,7]],"ltp":13.5,"tv":46.09,"id":40752182},{"batb":[[0,1.03,8.47],[1,1.01,3979.74],[2,1.01,0]],"batl":[[0,1.21,14.92],[1,1.23,29.82],[2,1.25,14.92]],"ltp":1.08,"tv":1178.09,"id":11214864}]}]}
{"op":"mcm","clk":"4215979813","pt":1631546526704,"mc":[{"id":"1.187605875","rc":[{"batb":[[0,1.05,425.78],[1,1.03,8.47],[2,1.01,3979.74]],"batl":[[0,1.09,74.02],[1,1.1,382.42],[2,1.21,14.92]],"ltp":1.08,"tv":1178.09,"id":11214864}]}]}
{"op":"mcm","clk":"4215980695","pt":1631546535507,"mc":[{"id":"1.187605875","rc":[{"batl":[[0,1.21,14.92],[1,1.23,29.82],[2,1.25,14.92]],"ltp":1.08,"tv":1178.09,"id":11214864}]}]}
{"op":"mcm","clk":"4215980874","pt":1631546537290,"mc":[{"id":"1.187605875","rc":[{"batb":[[2,1.01,9]],"ltp":1.08,"tv":1178.09,"id":11214864}]}]}
{"op":"mcm","clk":"4215980985","pt":1631546538493,"mc":[{"id":"1.187605875","rc":[{"batl":[[0,26,33.17],[1,990,0.01]],"ltp":13.5,"tv":46.09,"id":40752182},{"batb":[[1,1.04,829.19],[2,1.03,8.47]],"batl":[[0,1.06,460.31],[1,1.07,907.61],[2,1.21,14.92]],"ltp":1.08,"tv":1178.09,"id":11214864}]}]}
{"op":"mcm","clk":"4215981266","pt":1631546541213,"mc":[{"id":"1.187605875","rc":[{"batl":[[1,170,37.53],[2,990,0.01]],"ltp":13.5,"tv":46.09,"id":40752182}]}]}
{"op":"mcm","clk":"4215984798","pt":1631546575566,"mc":[{"id":"1.187605875","rc":[{"batb":[[0,1.04,829.19],[1,1.03,8.47],[2,1.01,9]],"batl":[[0,1.06,116.87]],"ltp":1.08,"tv":1178.09,"id":11214864}]}]}
{"op":"mcm","clk":"4215985169","pt":1631546578875,"mc":[{"id":"1.187605875","rc":[{"batb":[[0,1.04,1311.26]],"batl":[[1,1.07,939.13],[2,1.08,305.84]],"ltp":1.08,"tv":1178.09,"id":11214864}]}]}
{"op":"mcm","clk":"4215985843","pt":1631546585758,"mc":[{"id":"1.187605875","rc":[{"batb":[[1,1.01,9],[2,1.01,0]],"ltp":1.08,"tv":1178.09,"id":11214864}]}]}
{"op":"mcm","clk":"4215990368","pt":1631546633724,"mc":[{"id":"1.187605875","rc":[{"batl":[[0,170,37.53],[1,990,0.01],[2,990,0]],"ltp":13.5,"tv":46.09,"id":40752182},{"batb":[[0,1.04,482.07]],"batl":[[0,1.07,159.84],[1,1.08,305.84],[2,1.21,14.92]],"ltp":1.08,"tv":1178.09,"id":11214864}]}]}
{"op":"mcm","clk":"4215990733","pt":1631546637141,"mc":[{"id":"1.187605875","rc":[{"batb":[[0,1.04,267.58]],"batl":[[0,1.21,14.92],[1,1.23,29.82],[2,1.25,14.92]],"ltp":1.08,"tv":1178.09,"id":11214864}]}]}
{"op":"mcm","clk":"4215990983","pt":1631546640058,"mc":[{"id":"1.187605875","rc":[{"batb":[[0,1.05,212.44],[1,1.04,267.58],[2,1.01,9]],"batl":[[0,1.06,472.97],[1,1.21,14.92],[2,1.23,29.82]],"ltp":1.08,"tv":1178.09,"id":11214864}]}]}
{"op":"mcm","clk":"4215991537","pt":1631546647067,"mc":[{"id":"1.187605875","rc":[{"batb":[[0,1.04,267.58],[1,1.01,9],[2,1.01,0]],"batl":[[0,1.21,14.92],[1,1.23,29.82],[2,1.25,14.92]],"ltp":1.08,"tv":1178.09,"id":11214864}]}]}
{"op":"mcm","clk":"4215991761","pt":1631546650077,"mc":[{"id":"1.187605875","rc":[{"batb":[[0,1.04,482.07]],"batl":[[0,1.07,159.84],[1,1.08,305.84],[2,1.21,14.92]],"ltp":1.08,"tv":1178.09,"id":11214864}]}]}
{"op":"mcm","clk":"4215992131","pt":1631546655248,"mc":[{"id":"1.187605875","rc":[{"batb":[[0,1.01,9],[1,1.01,0]],"ltp":1.08,"tv":1178.09,"id":11214864}]}]}
{"op":"mcm","clk":"4215992215","pt":1631546656283,"mc":[{"id":"1.187605875","rc":[{"batl":[[0,990,0.01],[1,990,0]],"ltp":13.5,"tv":46.09,"id":40752182}]}]}
{"op":"mcm","clk":"4215992359","pt":1631546658075,"mc":[{"id":"1.187605875","rc":[{"batb":[[0,13.5,22.64],[1,1.41,16.2],[2,1.4,767.39]],"batl":[[0,17.5,89.76],[1,21,31.54],[2,990,0.01]],"ltp":13.5,"tv":46.09,"id":40752182},{"batb":[[0,1.06,31.74],[1,1.05,630.9],[2,1.01,9]],"batl":[[0,1.07,248.6],[1,1.08,588.82]],"ltp":1.08,"tv":1178.09,"id":11214864}]}]}
{"op":"mcm","clk":"4215992377","pt":1631546658286,"mc":[{"id":"1.187605875","rc":[{"batl":[[0,21,31.54],[1,990,0.01],[2,990,0]],"ltp":13.5,"tv":46.09,"id":40752182},{"batb":[[0,1.06,504.71]],"ltp":1.08,"tv":1178.09,"id":11214864}]}]}
{"op":"mcm","clk":"4215992553","pt":1631546660648,"mc":[{"id":"1.187605875","rc":[{"batb":[[2,1.01,3979.74]],"ltp":1.08,"tv":1178.09,"id":11214864}]}]}
{"op":"mcm","clk":"4215994049","pt":1631546679798,"mc":[{"id":"1.187605875","rc":[{"batb":[[0,1.41,16.2],[1,1.4,767.39],[2,1.01,7]],"batl":[[0,990,0.01],[1,990,0]],"ltp":13.5,"tv":46.09,"id":40752182},{"batb":[[0,1.01,3979.74],[1,1.05,0],[2,1.01,0]],"batl":[[0,1.21,14.92],[1,1.23,29.82],[2,1.25,14.92]],"ltp":1.08,"tv":1178.09,"id":11214864}]}]}
{"op":"mcm","clk":"4215994273","pt":1631546682716,"mc":[{"id":"1.187605875","rc":[{"batb":[[0,1.05,441.59],[1,1.01,3979.74]],"batl":[[0,1.09,459.95],[1,1.21,14.92],[2,1.23,29.82]],"ltp":1.08,"tv":1178.09,"id":11214864}]}]}
{"op":"mcm","clk":"4215994720","pt":1631546689012,"mc":[{"id":"1.187605875","rc":[{"batl":[[0,1.21,14.92],[1,1.23,29.82],[2,1.25,14.92]],"ltp":1.08,"tv":1178.09,"id":11214864}]}]}
{"op":"mcm","clk":"4215994861","pt":1631546691103,"mc":[{"id":"1.187605875","rc":[{"batb":[[1,1.01,9]],"ltp":1.08,"tv":1178.09,"id":11214864}]}]}
{"op":"mcm","clk":"4215994926","pt":1631546691932,"mc":[{"id":"1.187605875","rc":[{"batl":[[0,26,33.41],[1,990,0.01]],"ltp":13.5,"tv":46.09,"id":40752182},{"batb":[[1,1.04,835.2],[2,1.01,9]],"batl":[[0,1.06,447.03],[1,1.07,3830.86],[2,1.21,14.92]],"ltp":1.08,"tv":1178.09,"id":11214864}]}]}
{"op":"mcm","clk":"4215994952","pt":1631546692305,"mc":[{"id":"1.187605875","rc":[{"batl":[[1,1.07,1163.14]],"ltp":1.08,"tv":1178.09,"id":11214864}]}]}
{"op":"mcm","clk":"4215995171","pt":1631546695024,"mc":[{"id":"1.187605875","rc":[{"batl":[[1,170,37.53],[2,990,0.01]],"ltp":13.5,"tv":46.09,"id":40752182}]}]}
{"op":"mcm","clk":"4215995686","pt":1631546701929,"mc":[{"id":"1.187605875","rc":[{"batl":[[0,170,37.53],[1,990,0.01],[2,990,0]],"ltp":13.5,"tv":46.09,"id":40752182},{"batb":[[0,1.01,9],[1,1.04,0],[2,1.01,0]],"batl":[[0,1.21,14.92],[1,1.23,29.82],[2,1.25,14.92]],"ltp":1.08,"tv":1178.09,"id":11214864}]}]}
{"op":"mcm","clk":"4215995946","pt":1631546704927,"mc":[{"id":"1.187605875","rc":[{"batb":[[0,1.04,337.29],[1,1.03,146.18],[2,1.01,9]],"batl":[[0,1.08,464.21],[1,1.21,14.92],[2,1.23,29.82]],"ltp":1.08,"tv":1178.09,"id":11214864}]}]}
{"op":"mcm","clk":"4215996863","pt":1631546714954,"mc":[{"id":"1.187605875","rc":[{"batb":[[0,1.01,9],[1,1.03,0],[2,1.01,0]],"ltp":1.08,"tv":1178.09,"id":11214864}]}]}
{"op":"mcm","clk":"4215996980","pt":1631546716427,"mc":[{"id":"1.187605875","rc":[{"batl":[[0,990,0.01],[1,990,0]],"ltp":13.5,"tv":46.09,"id":40752182}]}]}
{"op":"mcm","clk":"4215997078","pt":1631546717837,"mc":[{"id":"1.187605875","rc":[{"batb":[[0,13.5,18.5],[1,1.41,16.2],[2,1.4,767.39]],"batl":[[0,17.5,20.83],[1,990,0.01]],"ltp":13.5,"tv":46.09,"id":40752182},{"batb":[[0,1.06,3523.64],[1,1.01,9]],"batl":[[0,1.07,71.18],[1,1.08,695.43],[2,1.21,14.92]],"ltp":1.08,"tv":1178.09,"id":11214864}]}]}
{"op":"mcm","clk":"4215997099","pt":1631546718146,"mc":[{"id":"1.187605875","rc":[{"batb":[[0,1.06,719.53]],"ltp":1.08,"tv":1178.09,"id":11214864}]}]}
{"op":"mcm","clk":"4215997310","pt":1631546720355,"mc":[{"id":"1.187605875","rc":[{"batb":[[1,1.01,3979.74]],"ltp":1.08,"tv":1178.09,"id":11214864}]}]}
{"op":"mcm","clk":"4215998084","pt":1631546729666,"mc":[{"id":"1.187605875","rc":[{"batb":[[0,1.06,472.97]],"ltp":1.08,"tv":1178.09,"id":11214864}]}]}
{"op":"mcm","clk":"4215998884","pt":1631546739069,"mc":[{"id":"1.187605875","rc":[{"batb":[[0,1.41,16.2],[1,1.4,767.39],[2,1.01,7]],"batl":[[0,990,0.01],[1,990,0]],"ltp":13.5,"tv":46.09,"id":40752182},{"batb":[[0,1.01,3979.74],[1,1.01,0]],"batl":[[0,1.21,14.92],[1,1.23,29.82],[2,1.25,14.92]],"ltp":1.08,"tv":1178.09,"id":11214864}]}]}
{"op":"mcm","clk":"4215999090","pt":1631546741997,"mc":[{"id":"1.187605875","rc":[{"batb":[[0,1.05,457.26],[1,1.01,3979.74]],"batl":[[0,1.09,323.34],[1,1.1,135.36],[2,1.21,14.92]],"ltp":1.08,"tv":1178.09,"id":11214864}]}]}
{"op":"mcm","clk":"4215999455","pt":1631546746987,"mc":[{"id":"1.187605875","rc":[{"batb":[[0,1.01,3979.74],[1,1.01,0]],"ltp":1.08,"tv":1178.09,"id":11214864}]}]}
{"op":"mcm","clk":"4215999614","pt":1631546748867,"mc":[{"id":"1.187605875","rc":[{"batb":[[0,1.01,9]],"ltp":1.08,"tv":1178.09,"id":11214864}]}]}
{"op":"mcm","clk":"4215999716","pt":1631546750058,"mc":[{"id":"1.187605875","rc":[{"batb":[[0,11,30.17],[1,1.41,16.2],[2,1.4,767.39]],"batl":[[0,15,39.82],[1,990,0.01]],"ltp":13.5,"tv":46.09,"id":40752182},{"trd":[[1.08,55.56]],"batb":[[0,1.08,72.64],[1,1.07,381.39],[2,1.01,9]],"batl":[[1,1.1,428.1]],"ltp":1.08,"tv":1205.51,"id":11214864}],"tv":1251.61}]}
{"op":"mcm","clk":"4215999908","pt":1631546753068,"mc":[{"id":"1.187605875","rc":[{"batb":[[1,1.07,390.63],[2,1.01,4167.03]],"batl":[[0,1.09,332.43]],"ltp":1.08,"tv":1205.51,"id":11214864}]}]}
{"op":"mcm","clk":"4216000415","pt":1631546759993,"mc":[{"id":"1.187605875","rc":[{"batl":[[0,15,35.16]],"ltp":13.5,"tv":46.09,"id":40752182}]}]}
{"op":"mcm","clk":"4216000626","pt":1631546762964,"mc":[{"id":"1.187605875","rc":[{"batl":[[0,15,40.81]],"ltp":13.5,"tv":46.09,"id":40752182},{"batl":[[0,1.09,432.1]],"ltp":1.08,"tv":1205.51,"id":11214864}]}]}
{"op":"mcm","clk":"4216001588","pt":1631546776090,"mc":[{"id":"1.187605875","rc":[{"batb":[[0,1.41,16.2],[1,1.4,767.39],[2,1.01,7]],"batl":[[0,990,0.01],[1,990,0]],"ltp":13.5,"tv":46.09,"id":40752182},{"batl":[[0,1.09,332.43],[1,1.1,126.36]],"ltp":1.08,"tv":1205.51,"id":11214864}]}]}
{"op":"mcm","clk":"4216001597","pt":1631546776191,"mc":[{"id":"1.187605875","rc":[{"batb":[[0,1.01,4167.03],[1,1.07,0],[2,1.01,0]],"batl":[[0,1.1,126.36],[1,1.21,14.92],[2,1.23,29.82]],"ltp":1.08,"tv":1205.51,"id":11214864}]}]}
{"op":"mcm","clk":"4216001850","pt":1631546779732,"mc":[{"id":"1.187605875","rc":[{"batl":[[0,1.21,14.92],[1,1.23,29.82],[2,1.25,14.92]],"ltp":1.08,"tv":1205.51,"id":11214864}]}]}
{"op":"mcm","clk":"4216002073","pt":1631546782689,"mc":[{"id":"1.187605875","rc":[{"batb":[[0,1.07,468.55],[1,1.01,4167.03]],"batl":[[0,1.09,455.33],[1,1.21,14.92],[2,1.23,29.82]],"ltp":1.08,"tv":1205.51,"id":11214864}]}]}
{"op":"mcm","clk":"4216002250","pt":1631546785028,"mc":[{"id":"1.187605875","rc":[{"batb":[[0,1.01,4167.03],[1,1.01,0]],"batl":[[0,1.21,14.92],[1,1.23,29.82],[2,1.25,14.92]],"ltp":1.08,"tv":1205.51,"id":11214864}]}]}
{"op":"mcm","clk":"4216002452","pt":1631546787940,"mc":[{"id":"1.187605875","rc":[{"batb":[[0,1.06,472.97],[1,1.01,4167.03]],"batl":[[0,1.1,208.25],[1,1.11,245.29],[2,1.21,14.92]],"ltp":1.08,"tv":1205.51,"id":11214864}]}]}
{"op":"mcm","clk":"4216002519","pt":1631546788720,"mc":[{"id":"1.187605875","rc":[{"batb":[[1,1.01,9]],"ltp":1.08,"tv":1205.51,"id":11214864}]}]}
{"op":"mcm","clk":"4216002860","pt":1631546793834,"mc":[{"id":"1.187605875","rc":[{"batl":[[0,1.21,14.92],[1,1.23,29.82],[2,1.25,14.92]],"ltp":1.08,"tv":1205.51,"id":11214864}]}]}
{"op":"mcm","clk":"4216003078","pt":1631546797123,"mc":[{"id":"1.187605875","rc":[{"batl":[[0,17.5,42.68],[1,990,0.01]],"ltp":13.5,"tv":46.09,"id":40752182},{"batl":[[0,1.08,573.99],[1,1.09,762.37],[2,1.21,14.92]],"ltp":1.08,"tv":1205.51,"id":11214864}]}]}
{"op":"mcm","clk":"4216003850","pt":1631546808567,"mc":[{"id":"1.187605875","rc":[{"batl":[[0,1.08,448.9]],"ltp":1.08,"tv":1205.51,"id":11214864}]}]}
{"op":"mcm","clk":"4216004682","pt":1631546818697,"mc":[{"id":"1.187605875","rc":[{"batl":[[0,990,0.01],[1,990,0]],"ltp":13.5,"tv":46.09,"id":40752182},{"batb":[[0,1.01,9],[1,1.01,0]],"batl":[[0,1.21,14.92],[1,1.23,29.82],[2,1.25,14.92]],"ltp":1.08,"tv":1205.51,"id":11214864}]}]}
{"op":"mcm","clk":"4216005129","pt":1631546824602,"mc":[{"id":"1.187605875","rc":[{"batb":[[0,1.06,472.97],[1,1.01,9]],"batl":[[0,1.08,464.21],[1,1.21,14.92],[2,1.23,29.82]],"ltp":1.08,"tv":1205.51,"id":11214864}]}]}
{"op":"mcm","clk":"4216005677","pt":1631546832100,"mc":[{"id":"1.187605875","rc":[{"batb":[[0,1.01,9],[1,1.01,0]],"batl":[[0,1.21,14.92],[1,1.23,29.82],[2,1.25,14.92]],"ltp":1.08,"tv":1205.51,"id":11214864}]}]}
{"op":"mcm","clk":"4216005938","pt":1631546834990,"mc":[{"id":"1.187605875","rc":[{"batb":[[0,1.05,473.44],[1,1.01,9]],"batl":[[0,1.1,450.03],[1,1.21,14.92],[2,1.23,29.82]],"ltp":1.08,"tv":1205.51,"id":11214864}]}]}
{"op":"mcm","clk":"4216006915","pt":1631546849218,"mc":[{"id":"1.187605875","rc":[{"batl":[[0,1.21,14.92],[1,1.23,29.82],[2,1.25,14.92]],"ltp":1.08,"tv":1205.51,"id":11214864}]}]}
{"op":"mcm","clk":"4216007114","pt":1631546852126,"mc":[{"id":"1.187605875","rc":[{"batl":[[0,26,28.04],[1,990,0.01]],"ltp":13.5,"tv":46.09,"id":40752182},{"batb":[[1,1.04,701.09],[2,1.01,9]],"batl":[[0,1.06,407.08],[1,1.07,3766.99],[2,1.21,14.92]],"ltp":1.08,"tv":1205.51,"id":11214864}]}]}
{"op":"mcm","clk":"4216007143","pt":1631546852494,"mc":[{"id":"1.187605875","rc":[{"batl":[[1,1.07,1156.82]],"ltp":1.08,"tv":1205.51,"id":11214864}]}]}
{"op":"mcm","clk":"4216007887","pt":1631546864016,"mc":[{"id":"1.187605875","rc":[{"batl":[[0,990,0.01],[1,990,0]],"ltp":13.5,"tv":46.09,"id":40752182},{"batb":[[1,1.01,9],[2,1.01,0]],"batl":[[0,1.06,304.67],[1,1.07,166.73]],"ltp":1.08,"tv":1205.51,"id":11214864}]}]}
{"op":"mcm","clk":"4216007900","pt":1631546864218,"mc":[{"id":"1.187605875","rc":[{"batb":[[0,1.01,9],[1,1.01,0]],"batl":[[0,1.21,14.92],[1,1.23,29.82],[2,1.25,14.92]],"ltp":1.08,"tv":1205.51,"id":11214864}]}]}
{"op":"mcm","clk":"4216008079","pt":1631546867136,"mc":[{"id":"1.187605875","rc":[{"batb":[[0,1.03,486.75],[1,1.01,9]],"batl":[[0,1.08,420.02],[1,1.21,14.92],[2,1.23,29.82]],"ltp":1.08,"tv":1205.51,"id":11214864}]}]}
{"op":"mcm","clk":"4216008096","pt":1631546867348,"mc":[{"id":"1.187605875","rc":[{"batb":[[0,1.01,9],[1,1.01,0]],"batl":[[0,1.21,14.92],[1,1.23,29.82],[2,1.25,14.92]],"ltp":1.08,"tv":1205.51,"id":11214864}]}]}
{"op":"mcm","clk":"4216008310","pt":1631546870162,"mc":[{"id":"1.187605875","rc":[{"batb":[[0,1.05,169.76],[1,1.04,310.67],[2,1.01,9]],"batl":[[0,1.06,472.97],[1,1.21,14.92],[2,1.23,29.82]],"ltp":1.08,"tv":1205.51,"id":11214864}]}]}
{"op":"mcm","clk":"4216008819","pt":1631546877367,"mc":[{"id":"1.187605875","rc":[{"batb":[[0,1.01,9],[1,1.04,0],[2,1.01,0]],"batl":[[0,1.21,14.92],[1,1.23,29.82],[2,1.25,14.92]],"ltp":1.08,"tv":1205.51,"id":11214864}]}]}
{"op":"mcm","clk":"4216008947","pt":1631546880231,"mc":[{"id":"1.187605875","rc":[{"batb":[[0,1.03,486.75],[1,1.01,9]],"batl":[[0,1.08,420.02],[1,1.21,14.92],[2,1.23,29.82]],"ltp":1.08,"tv":1205.51,"id":11214864}]}]}
{"op":"mcm","clk":"4216010962","pt":1631546910550,"mc":[{"id":"1.187605875","rc":[{"batb":[[0,1.01,9],[1,1.01,0]],"ltp":1.08,"tv":1205.51,"id":11214864}]}]}
{"op":"mcm","clk":"4216011148","pt":1631546913449,"mc":[{"id":"1.187605875","rc":[{"batl":[[0,17.5,40.51],[1,990,0.01]],"ltp":13.5,"tv":46.09,"id":40752182},{"batb":[[0,1.06,472.97],[1,1.01,9]],"batl":[[1,1.09,728.29],[2,1.21,14.92]],"ltp":1.08,"tv":1205.51,"id":11214864}]}]}
{"op":"mcm","clk":"4216013240","pt":1631546946407,"mc":[{"id":"1.187605875","rc":[{"batl":[[0,990,0.01],[1,990,0]],"ltp":13.5,"tv":46.09,"id":40752182},{"batb":[[0,1.01,9],[1,1.01,0]],"batl":[[0,1.21,14.92],[1,1.23,29.82],[2,1.25,14.92]],"ltp":1.08,"tv":1205.51,"id":11214864}]}]}
{"op":"mcm","clk":"4216013438","pt":1631546949409,"mc":[{"id":"1.187605875","rc":[{"batb":[[0,1.05,477.47],[1,1.01,9]],"batl":[[0,1.1,425.31],[1,1.21,14.92],[2,1.23,29.82]],"ltp":1.08,"tv":1205.51,"id":11214864}]}]}
{"op":"mcm","clk":"4216013641","pt":1631546953035,"mc":[{"id":"1.187605875","rc":[{"batl":[[0,1.21,14.92],[1,1.23,29.82],[2,1.25,14.92]],"ltp":1.08,"tv":1205.51,"id":11214864}]}]}
{"op":"mcm","clk":"4216013818","pt":1631546955944,"mc":[{"id":"1.187605875","rc":[{"batl":[[0,26,27.97],[1,990,0.01]],"ltp":13.5,"tv":46.09,"id":40752182},{"batb":[[1,1.04,699.19],[2,1.01,9]],"batl":[[0,1.06,375.42],[1,1.07,960.37],[2,1.21,14.92]],"ltp":1.08,"tv":1205.51,"id":11214864}]}]}
{"op":"mcm","clk":"4216013989","pt":1631546958436,"mc":[{"id":"1.187605875","rc":[{"batl":[[1,170,37.53],[2,990,0.01]],"ltp":13.5,"tv":46.09,"id":40752182}]}]}
{"op":"mcm","clk":"4216014128","pt":1631546960053,"mc":[{"id":"1.187605875","rc":[{"batl":[[1,990,0.01],[2,990,0]],"ltp":13.5,"tv":46.09,"id":40752182}]}]}
{"op":"mcm","clk":"4216014973","pt":1631546974070,"mc":[{"id":"1.187605875","rc":[{"batl":[[0,990,0.01],[1,990,0]],"ltp":13.5,"tv":46.09,"id":40752182},{"batb":[[1,1.01,9],[2,1.01,0]],"batl":[[0,1.06,272.67],[1,1.07,198.42]],"ltp":1.08,"tv":1205.51,"id":11214864}]}]}
{"op":"mcm","clk":"4216014983","pt":1631546974230,"mc":[{"id":"1.187605875","rc":[{"batb":[[0,1.01,9],[1,1.01,0]],"batl":[[0,1.21,14.92],[1,1.23,29.82],[2,1.25,14.92]],"ltp":1.08,"tv":1205.51,"id":11214864}]}]}
{"op":"mcm","clk":"4216015144","pt":1631546977139,"mc":[{"id":"1.187605875","rc":[{"batb":[[0,1.03,486.75],[1,1.01,9]],"batl":[[0,1.08,391.95],[1,1.09,71.6],[2,1.21,14.92]],"ltp":1.08,"tv":1205.51,"id":11214864}]}]}
{"op":"mcm","clk":"4216015338","pt":1631546980062,"mc":[{"id":"1.187605875","rc":[{"batb":[[0,1.01,9],[1,1.01,0]],"ltp":1.08,"tv":1205.51,"id":11214864}]}]}
{"op":"mcm","clk":"4216015517","pt":1631546983074,"mc":[{"id":"1.187605875","rc":[{"batl":[[0,17.5,40.13],[1,990,0.01]],"ltp":13.5,"tv":46.09,"id":40752182},{"batb":[[0,1.07,95.81],[1,1.06,376.25],[2,1.01,9]],"batl":[[1,1.09,804.09]],"ltp":1.08,"tv":1205.51,"id":11214864}]}]}
{"op":"mcm","clk":"4216016708","pt":1631547000990,"mc":[{"id":"1.187605875","rc":[{"batl":[[0,990,0.01],[1,990,0]],"ltp":13.5,"tv":46.09,"id":40752182},{"batb":[[0,1.01,9],[1,1.06,0],[2,1.01,0]],"batl":[[0,1.21,14.92],[1,1.23,29.82],[2,1.25,14.92]],"ltp":1.08,"tv":1205.51,"id":11214864}]}]}
{"op":"mcm","clk":"4216016942","pt":1631547003872,"mc":[{"id":"1.187605875","rc":[{"batb":[[0,1.05,477.47],[1,1.01,9]],"batl":[[0,1.1,401.25],[1,1.21,14.92],[2,1.23,29.82]],"ltp":1.08,"tv":1205.51,"id":11214864}]}]}
{"op":"mcm","clk":"4216016984","pt":1631547004511,"mc":[{"id":"1.187605875","rc":[{"batb":[[0,1.01,9],[1,1.01,0]],"batl":[[0,1.21,14.92],[1,1.23,29.82],[2,1.25,14.92]],"ltp":1.08,"tv":1205.51,"id":11214864}]}]}
{"op":"mcm","clk":"4216017234","pt":1631547007387,"mc":[{"id":"1.187605875","rc":[{"batb":[[0,1.06,472.97],[1,1.01,9]],"batl":[[0,1.08,464.21],[1,1.21,14.92],[2,1.23,29.82]],"ltp":1.08,"tv":1205.51,"id":11214864}]}]}
{"op":"mcm","clk":"4216017624","pt":1631547011718,"mc":[{"id":"1.187605875","rc":[{"batb":[[0,1.01,9],[1,1.01,0]],"batl":[[0,1.21,14.92],[1,1.23,29.82],[2,1.25,14.92]],"ltp":1.08,"tv":1205.51,"id":11214864}]}]}
{"op":"mcm","clk":"4216017831","pt":1631547014685,"mc":[{"id":"1.187605875","rc":[{"batb":[[0,1.05,477.47],[1,1.01,9]],"batl":[[0,1.1,401.25],[1,1.21,14.92],[2,1.23,29.82]],"ltp":1.08,"tv":1205.51,"id":11214864}]}]}
{"op":"mcm","clk":"4216018133","pt":1631547019920,"mc":[{"id":"1.187605875","rc":[{"batl":[[0,1.21,14.92],[1,1.23,29.82],[2,1.25,14.92]],"ltp":1.08,"tv":1205.51,"id":11214864}]}]}
{"op":"mcm","clk":"4216018302","pt":1631547022891,"mc":[{"id":"1.187605875","rc":[{"batl":[[0,26,28.18],[1,990,0.01]],"ltp":13.5,"tv":46.09,"id":40752182},{"batb":[[1,1.04,704.46],[2,1.01,9]],"batl":[[0,1.06,343.26],[1,1.07,986.3],[2,1.21,14.92]],"ltp":1.08,"tv":1205.51,"id":11214864}]}]}
{"op":"mcm","clk":"4216019437","pt":1631547040385,"mc":[{"id":"1.187605875","rc":[{"batl":[[0,990,0.01],[1,990,0]],"ltp":13.5,"tv":46.09,"id":40752182},{"batb":[[0,1.01,9],[1,1.04,0],[2,1.01,0]],"batl":[[0,1.21,14.92],[1,1.23,29.82],[2,1.25,14.92]],"ltp":1.08,"tv":1205.51,"id":11214864}]}]}
{"op":"mcm","clk":"4216019587","pt":1631547043350,"mc":[{"id":"1.187605875","rc":[{"batb":[[0,1.04,74.72],[1,1.03,411.29],[2,1.01,9]],"batl":[[0,1.08,364.66],[1,1.09,98.64],[2,1.21,14.92]],"ltp":1.08,"tv":1205.51,"id":11214864}]}]}
{"op":"mcm","clk":"4216020454","pt":1631547056373,"mc":[{"id":"1.187605875","rc":[{"batb":[[0,1.01,9],[1,1.03,0],[2,1.01,0]],"ltp":1.08,"tv":1205.51,"id":11214864}]}]}
{"op":"mcm","clk":"4216020622","pt":1631547059377,"mc":[{"id":"1.187605875","rc":[{"batl":[[0,17.5,40.53],[1,990,0.01]],"ltp":13.5,"tv":46.09,"id":40752182},{"batb":[[0,1.07,126.68],[1,1.06,345.08],[2,1.01,9]],"batl":[[1,1.09,827.22]],"ltp":1.08,"tv":1205.51,"id":11214864}]}]}
{"op":"mcm","clk":"4216021728","pt":1631547075066,"mc":[{"id":"1.187605875","rc":[{"batl":[[0,990,0.01],[1,990,0]],"ltp":13.5,"tv":46.09,"id":40752182},{"batb":[[0,1.01,9],[1,1.06,0],[2,1.01,0]],"batl":[[0,1.21,14.92],[1,1.23,29.82],[2,1.25,14.92]],"ltp":1.08,"tv":1205.51,"id":11214864}]}]}
{"op":"mcm","clk":"4216021975","pt":1631547077936,"mc":[{"id":"1.187605875","rc":[{"batb":[[0,1.05,477.47],[1,1.01,9]],"batl":[[0,1.1,377.85],[1,1.11,77.21],[2,1.21,14.92]],"ltp":1.08,"tv":1205.51,"id":11214864}]}]}
{"op":"mcm","clk":"4216021991","pt":1631547078198,"mc":[{"id":"1.187605875","rc":[{"batb":[[0,1.01,9],[1,1.01,0]],"batl":[[0,1.21,14.92],[1,1.23,29.82],[2,1.25,14.92]],"ltp":1.08,"tv":1205.51,"id":11214864}]}]}
{"op":"mcm","clk":"4216022239","pt":1631547081215,"mc":[{"id":"1.187605875","rc":[{"batb":[[0,1.06,472.97],[1,1.01,9]],"batl":[[0,1.08,464.21],[1,1.21,14.92],[2,1.23,29.82]],"ltp":1.08,"tv":1205.51,"id":11214864}]}]}
{"op":"mcm","clk":"4216022678","pt":1631547087561,"mc":[{"id":"1.187605875","rc":[{"batb":[[0,1.01,9],[1,1.01,0]],"batl":[[0,1.21,14.92],[1,1.23,29.82],[2,1.25,14.92]],"ltp":1.08,"tv":1205.51,"id":11214864}]}]}
{"op":"mcm","clk":"4216022905","pt":1631547090528,"mc":[{"id":"1.187605875","rc":[{"batb":[[0,1.05,477.47],[1,1.01,9]],"batl":[[0,1.1,377.85],[1,1.11,77.21],[2,1.21,14.92]],"ltp":1.08,"tv":1205.51,"id":11214864}]}]}
{"op":"mcm","clk":"4216024098","pt":1631547109942,"mc":[{"id":"1.187605875","rc":[{"batb":[[0,1.01,9],[1,1.01,0]],"ltp":1.08,"tv":1205.51,"id":11214864}]}]}
{"op":"mcm","clk":"4216024311","pt":1631547112954,"mc":[{"id":"1.187605875","rc":[{"batb":[[0,11,13.66],[1,1.41,16.2],[2,1.4,767.39]],"batl":[[0,13.5,16.61],[1,990,0.01]],"ltp":13.5,"tv":46.09,"id":40752182},{"batb":[[0,1.08,621.92],[1,1.01,9]],"batl":[[0,1.09,42.64],[1,1.1,514.47],[2,1.11,77.21]],"ltp":1.08,"tv":1205.51,"id":11214864}]}]}
{"op":"mcm","clk":"4216024413","pt":1631547114457,"mc":[{"id":"1.187605875","rc":[{"batb":[[1,1.02,2179.83],[2,1.01,9]],"ltp":1.08,"tv":1205.51,"id":11214864}]}]}
{"op":"mcm","clk":"4216026718","pt":1631547150096,"mc":[{"id":"1.187605875","rc":[{"batb":[[0,1.08,157.71]],"batl":[[1,1.1,136.62],[2,1.21,14.92]],"ltp":1.08,"tv":1205.51,"id":11214864}]}]}
{"op":"mcm","clk":"4216026812","pt":1631547151555,"mc":[{"id":"1.187605875","rc":[{"batb":[[0,1.41,16.2],[1,1.4,767.39],[2,1.01,7]],"batl":[[0,990,0.01],[1,990,0]],"ltp":13.5,"tv":46.09,"id":40752182},{"batb":[[0,1.02,2179.83],[1,1.01,9],[2,1.01,0]],"batl":[[0,1.21,14.92],[1,1.23,29.82],[2,1.25,14.92]],"ltp":1.08,"tv":1205.51,"id":11214864}]}]}
{"op":"mcm","clk":"4216026876","pt":1631547152953,"mc":[{"id":"1.187605875","rc":[{"batb":[[0,1.07,453.52],[1,1.02,2179.83],[2,1.01,9]],"batl":[[0,1.12,250.69],[1,1.13,195.2],[2,1.21,14.92]],"ltp":1.08,"tv":1205.51,"id":11214864}]}]}
{"op":"mcm","clk":"4216026968","pt":1631547154464,"mc":[{"id":"1.187605875","rc":[{"batb":[[0,1.02,2179.83],[1,1.01,9],[2,1.01,0]],"batl":[[0,1.21,14.92],[1,1.23,29.82],[2,1.25,14.92]],"ltp":1.08,"tv":1205.51,"id":11214864}]}]}
{"op":"mcm","clk":"4216027154","pt":1631547157476,"mc":[{"id":"1.187605875","rc":[{"batb":[[0,1.09,185.87],[1,1.08,276.61],[2,1.02,2179.83]],"batl":[[0,1.1,173.2],[1,1.11,280.02],[2,1.21,14.92]],"ltp":1.08,"tv":1205.51,"id":11214864}]}]}
{"op":"mcm","clk":"4216027609","pt":1631547164598,"mc":[{"id":"1.187605875","rc":[{"batb":[[0,1.02,2179.83],[1,1.01,9],[2,1.02,0]],"batl":[[0,1.21,14.92],[1,1.23,29.82],[2,1.25,14.92]],"ltp":1.08,"tv":1205.51,"id":11214864}]}]}
{"op":"mcm","clk":"4216027799","pt":1631547167611,"mc":[{"id":"1.187605875","rc":[{"batb":[[0,1.07,453.52],[1,1.02,2179.83],[2,1.01,9]],"batl":[[0,1.12,250.69],[1,1.13,195.2],[2,1.21,14.92]],"ltp":1.08,"tv":1205.51,"id":11214864}]}]}
{"op":"mcm","clk":"4216028354","pt":1631547175525,"mc":[{"id":"1.187605875","rc":[{"batl":[[0,1.21,14.92],[1,1.23,29.82],[2,1.25,14.92]],"ltp":1.08,"tv":1205.51,"id":11214864}]}]}
{"op":"mcm","clk":"4216028533","pt":1631547177728,"mc":[{"id":"1.187605875","rc":[{"batb":[[1,1.01,9],[2,1.01,0]],"ltp":1.08,"tv":1205.51,"id":11214864}]}]}
{"op":"mcm","clk":"4216028601","pt":1631547178512,"mc":[{"id":"1.187605875","rc":[{"batl":[[0,17.5,64.37],[1,990,0.01]],"ltp":13.5,"tv":46.09,"id":40752182},{"batl":[[0,1.08,114.48],[1,1.09,912.05],[2,1.21,14.92]],"ltp":1.08,"tv":1205.51,"id":11214864}]}]}
{"op":"mcm","clk":"4216028803","pt":1631547181243,"mc":[{"id":"1.187605875","rc":[{"batb":[[1,1.01,4167.03]],"ltp":1.08,"tv":1205.51,"id":11214864}]}]}
{"op":"mcm","clk":"4216029473","pt":1631547190722,"mc":[{"id":"1.187605875","rc":[{"batl":[[0,990,0.01],[1,990,0]],"ltp":13.5,"tv":46.09,"id":40752182},{"batb":[[0,1.01,4167.03],[1,1.01,0]],"batl":[[0,1.21,14.92],[1,1.23,29.82],[2,1.25,14.92]],"ltp":1.08,"tv":1205.51,"id":11214864}]}]}
{"op":"mcm","clk":"4216029679","pt":1631547193721,"mc":[{"id":"1.187605875","rc":[{"batb":[[0,1.06,472.97],[1,1.01,4167.03]],"batl":[[0,1.1,182.46],[1,1.11,270.85],[2,1.21,14.92]],"ltp":1.08,"tv":1205.51,"id":11214864}]}]}
{"op":"mcm","clk":"4216030285","pt":1631547199725,"mc":[{"id":"1.187605875","rc":[{"batl":[[0,1.21,14.92],[1,1.23,29.82],[2,1.25,14.92]],"ltp":1.08,"tv":1205.51,"id":11214864}]}]}
{"op":"mcm","clk":"4216030540","pt":1631547202764,"mc":[{"id":"1.187605875","rc":[{"batb":[[0,13.5,27.5],[1,1.41,16.2],[2,1.4,767.39]],"batl":[[0,21,32.17],[1,990,0.01]],"ltp":13.5,"tv":46.09,"id":40752182},{"batb":[[1,1.05,643.5],[2,1.01,9]],"batl":[[0,1.07,230.26],[1,1.08,674.92],[2,1.21,14.92]],"ltp":1.08,"tv":1205.51,"id":11214864}]}]}
{"op":"mcm","clk":"4216030853","pt":1631547206649,"mc":[{"id":"1.187605875","rc":[{"batb":[[2,1.01,3979.74]],"ltp":1.08,"tv":1205.51,"id":11214864}]}]}
{"op":"mcm","clk":"4216032035","pt":1631547220780,"mc":[{"id":"1.187605875","rc":[{"batb":[[0,1.41,16.2],[1,1.4,767.39],[2,1.01,7]],"batl":[[0,990,0.01],[1,990,0]],"ltp":13.5,"tv":46.09,"id":40752182},{"batb":[[0,1.01,3979.74],[1,1.05,0],[2,1.01,0]],"batl":[[0,1.21,14.92],[1,1.23,29.82],[2,1.25,14.92]],"ltp":1.08,"tv":1205.51,"id":11214864}]}]}
{"op":"mcm","clk":"4216032293","pt":1631547223767,"mc":[{"id":"1.187605875","rc":[{"batb":[[0,1.05,477.47],[1,1.01,3979.74]],"batl":[[0,1.09,459.95],[1,1.21,14.92],[2,1.23,29.82]],"ltp":1.08,"tv":1205.51,"id":11214864}]}]}
{"op":"mcm","clk":"4216032913","pt":1631547231498,"mc":[{"id":"1.187605875","rc":[{"batl":[[0,1.21,14.92],[1,1.23,29.82],[2,1.25,14.92]],"ltp":1.08,"tv":1205.51,"id":11214864}]}]}
{"op":"mcm","clk":"4216033111","pt":1631547233700,"mc":[{"id":"1.187605875","rc":[{"batb":[[1,1.01,9]],"ltp":1.08,"tv":1205.51,"id":11214864}]}]}
{"op":"mcm","clk":"4216033173","pt":1631547234495,"mc":[{"id":"1.187605875","rc":[{"batl":[[0,21,14.27],[1,990,0.01]],"ltp":13.5,"tv":46.09,"id":40752182},{"batb":[[0,1.05,693.17]],"batl":[[0,1.06,76.34],[1,1.07,1134.4],[2,1.21,14.92]],"ltp":1.08,"tv":1205.51,"id":11214864}]}]}
{"op":"mcm","clk":"4216033419","pt":1631547237907,"mc":[{"id":"1.187605875","rc":[{"batl":[[1,170,37.53],[2,990,0.01]],"ltp":13.5,"tv":46.09,"id":40752182}]}]}
{"op":"mcm","clk":"4216033896","pt":1631547244096,"mc":[{"id":"1.187605875","rc":[{"trd":[[1.05,663.56]],"batb":[[0,1.05,361.39]],"ltp":1.05,"tv":1869.07,"id":11214864}],"tv":1915.17}]}
{"op":"mcm","clk":"4216033919","pt":1631547244511,"mc":[{"id":"1.187605875","rc":[{"batl":[[1,1.07,979.49]],"ltp":1.05,"tv":1869.07,"id":11214864}]}]}
{"op":"mcm","clk":"4216034164","pt":1631547247683,"mc":[{"id":"1.187605875","rc":[{"batb":[[0,1.05,693.17]],"batl":[[0,1.06,232.7]],"ltp":1.05,"tv":1869.07,"id":11214864}]}]}
{"op":"mcm","clk":"4216034562","pt":1631547252996,"mc":[{"id":"1.187605875","rc":[{"batl":[[0,170,37.53],[1,990,0.01],[2,990,0]],"ltp":13.5,"tv":46.09,"id":40752182},{"batb":[[0,1.05,205.51]],"batl":[[0,1.07,313.64],[1,1.21,14.92],[2,1.23,29.82]],"ltp":1.05,"tv":1869.07,"id":11214864}]}]}
{"op":"mcm","clk":"4216034784","pt":1631547256042,"mc":[{"id":"1.187605875","rc":[{"batb":[[1,1.04,274.57],[2,1.01,9]],"batl":[[0,1.07,364.12],[1,1.08,103.46],[2,1.21,14.92]],"ltp":1.05,"tv":1869.07,"id":11214864}]}]}
{"op":"mcm","clk":"4216034799","pt":1631547256191,"mc":[{"id":"1.187605875","rc":[{"batb":[[1,1.01,9],[2,1.01,0]],"batl":[[1,1.21,14.92],[2,1.23,29.82]],"ltp":1.05,"tv":1869.07,"id":11214864}]}]}
{"op":"mcm","clk":"4216034980","pt":1631547258999,"mc":[{"id":"1.187605875","rc":[{"batb":[[0,1.05,477.47]],"batl":[[0,1.07,468.55]],"ltp":1.05,"tv":1869.07,"id":11214864}]}]}
{"op":"mcm","clk":"4216035472","pt":1631547265433,"mc":[{"id":"1.187605875","rc":[{"batb":[[0,1.05,205.51]],"batl":[[0,1.07,364.12]],"ltp":1.05,"tv":1869.07,"id":11214864}]}]}
{"op":"mcm","clk":"4216035704","pt":1631547268420,"mc":[{"id":"1.187605875","rc":[{"batb":[[1,1.04,274.57],[2,1.01,9]],"batl":[[1,1.08,103.46],[2,1.21,14.92]],"ltp":1.05,"tv":1869.07,"id":11214864}]}]}
{"op":"mcm","clk":"4216036296","pt":1631547276943,"mc":[{"id":"1.187605875","rc":[{"batl":[[0,1.21,14.92],[1,1.23,29.82],[2,1.25,14.92]],"ltp":1.05,"tv":1869.07,"id":11214864}]}]}
{"op":"mcm","clk":"4216036523","pt":1631547279785,"mc":[{"id":"1.187605875","rc":[{"batl":[[0,26,29.34],[1,170,37.53],[2,990,0.01]],"ltp":13.5,"tv":46.09,"id":40752182},{"batb":[[1,1.04,1008]],"batl":[[0,1.06,961.65],[1,1.21,14.92],[2,1.23,29.82]],"ltp":1.05,"tv":1869.07,"id":11214864}]}]}
{"op":"mcm","clk":"4216036849","pt":1631547284087,"mc":[{"id":"1.187605875","rc":[{"batl":[[1,990,0.01],[2,990,0]],"ltp":13.5,"tv":46.09,"id":40752182}]}]}
{"op":"mcm","clk":"4216044560","pt":1631547386909,"mc":[{"id":"1.187605875","rc":[{"batl":[[0,990,0.01],[1,990,0]],"ltp":13.5,"tv":46.09,"id":40752182},{"batb":[[1,1.04,274.57]],"batl":[[0,1.06,472.97]],"ltp":1.05,"tv":1869.07,"id":11214864}]}]}
{"op":"mcm","clk":"4216044608","pt":1631547387488,"mc":[{"id":"1.187605875","rc":[{"batb":[[0,1.04,157.61],[1,1.01,9],[2,1.01,0]],"batl":[[0,1.21,14.92],[1,1.23,29.82],[2,1.25,14.92]],"ltp":1.05,"tv":1869.07,"id":11214864}]}]}
{"op":"mcm","clk":"4216044865","pt":1631547390508,"mc":[{"id":"1.187605875","rc":[{"batb":[[1,1.03,327.6],[2,1.01,9]],"batl":[[0,1.07,343.65],[1,1.08,123.74],[2,1.21,14.92]],"ltp":1.05,"tv":1869.07,"id":11214864}]}]}
{"op":"mcm","clk":"4216045123","pt":1631547393997,"mc":[{"id":"1.187605875","rc":[{"batl":[[0,1.21,14.92],[1,1.23,29.82],[2,1.25,14.92]],"ltp":1.05,"tv":1869.07,"id":11214864}]}]}
{"op":"mcm","clk":"4216045374","pt":1631547397018,"mc":[{"id":"1.187605875","rc":[{"batb":[[0,21,16.73],[1,1.41,16.2],[2,1.4,767.39]],"batl":[[0,34,51.28],[1,990,0.01]],"ltp":13.5,"tv":46.09,"id":40752182},{"batl":[[0,1.05,812.02],[1,1.21,14.92],[2,1.23,29.82]],"ltp":1.05,"tv":1869.07,"id":11214864}]}]}
{"op":"mcm","clk":"4216046484","pt":1631547411538,"mc":[{"id":"1.187605875","rc":[{"batb":[[0,1.41,16.2],[1,1.4,767.39],[2,1.01,7]],"batl":[[0,990,0.01],[1,990,0]],"ltp":13.5,"tv":46.09,"id":40752182},{"batb":[[0,1.03,248.88],[1,1.01,9],[2,1.01,0]],"batl":[[0,1.21,14.92],[1,1.23,29.82],[2,1.25,14.92]],"ltp":1.05,"tv":1869.07,"id":11214864}]}]}
{"op":"mcm","clk":"4216046708","pt":1631547414541,"mc":[{"id":"1.187605875","rc":[{"batb":[[1,1.02,240.19],[2,1.01,9]],"batl":[[0,1.06,472.97],[1,1.21,14.92],[2,1.23,29.82]],"ltp":1.05,"tv":1869.07,"id":11214864}]}]}
{"op":"mcm","clk":"4216046776","pt":1631547415544,"mc":[{"id":"1.187605875","rc":[{"batb":[[1,1.01,9],[2,1.01,0]],"batl":[[0,1.21,14.92],[1,1.23,29.82],[2,1.25,14.92]],"ltp":1.05,"tv":1869.07,"id":11214864}]}]}
{"op":"mcm","clk":"4216047010","pt":1631547418512,"mc":[{"id":"1.187605875","rc":[{"batb":[[0,1.03,486.75]],"batl":[[0,1.05,477.47],[1,1.21,14.92],[2,1.23,29.82]],"ltp":1.05,"tv":1869.07,"id":11214864}]}]}
{"op":"mcm","clk":"4216047199","pt":1631547421064,"mc":[{"id":"1.187605875","rc":[{"batb":[[0,1.03,248.88]],"batl":[[0,1.21,14.92],[1,1.23,29.82],[2,1.25,14.92]],"ltp":1.05,"tv":1869.07,"id":11214864}]}]}
{"op":"mcm","clk":"4216047482","pt":1631547424039,"mc":[{"id":"1.187605875","rc":[{"batb":[[1,1.02,240.19],[2,1.01,9]],"batl":[[0,1.06,472.97],[1,1.21,14.92],[2,1.23,29.82]],"ltp":1.05,"tv":1869.07,"id":11214864}]}]}
{"op":"mcm","clk":"4216048024","pt":1631547429272,"mc":[{"id":"1.187605875","rc":[{"batl":[[0,1.21,14.92],[1,1.23,29.82],[2,1.25,14.92]],"ltp":1.05,"tv":1869.07,"id":11214864}]}]}
{"op":"mcm","clk":"4216048275","pt":1631547431935,"mc":[{"id":"1.187605875","rc":[{"batb":[[0,26,17.27],[1,1.41,16.2],[2,1.4,767.39]],"batl":[[0,50,53.45],[1,990,0.01]],"ltp":13.5,"tv":46.09,"id":40752182},{"batl":[[0,1.04,431.65],[1,1.21,14.92],[2,1.23,29.82]],"ltp":1.05,"tv":1869.07,"id":11214864}]}]}
{"op":"mcm","clk":"4216048317","pt":1631547432246,"mc":[{"id":"1.187605875","rc":[{"batl":[[0,1.04,913.72]],"ltp":1.05,"tv":1869.07,"id":11214864}]}]}
{"op":"mcm","clk":"4216049684","pt":1631547448594,"mc":[{"id":"1.187605875","rc":[{"batb":[[0,1.41,16.2],[1,1.4,767.39],[2,1.01,7]],"batl":[[0,990,0.01],[1,990,0]],"ltp":13.5,"tv":46.09,"id":40752182},{"batb":[[0,1.02,240.19],[1,1.01,9],[2,1.01,0]],"batl":[[0,1.21,14.92],[1,1.23,29.82],[2,1.25,14.92]],"ltp":1.05,"tv":1869.07,"id":11214864}]}]}
{"op":"mcm","clk":"4216049910","pt":1631547451640,"mc":[{"id":"1.187605875","rc":[{"batb":[[0,1.02,491.52]],"batl":[[0,1.05,477.47],[1,1.21,14.92],[2,1.23,29.82]],"ltp":1.05,"tv":1869.07,"id":11214864}]}]}
{"op":"mcm","clk":"4216050047","pt":1631547453002,"mc":[{"id":"1.187605875","rc":[{"batb":[[0,1.01,9],[1,1.01,0]],"ltp":1.05,"tv":1869.07,"id":11214864}]}]}
{"op":"mcm","clk":"4216050293","pt":1631547455901,"mc":[{"id":"1.187605875","rc":[{"batb":[[0,21,16.88],[1,1.41,16.2],[2,1.4,767.39]],"batl":[[0,34,43],[1,990,0.01]],"ltp":13.5,"tv":46.09,"id":40752182},{"batb":[[0,1.03,486.75],[1,1.01,9]],"batl":[[0,1.04,17.27],[1,1.05,815.08],[2,1.21,14.92]],"ltp":1.05,"tv":1869.07,"id":11214864}]}]}
{"op":"mcm","clk":"4216051151","pt":1631547465580,"mc":[{"id":"1.187605875","rc":[{"batb":[[0,1.41,16.2],[1,1.4,767.39],[2,1.01,7]],"batl":[[0,990,0.01],[1,990,0]],"ltp":13.5,"tv":46.09,"id":40752182},{"batb":[[0,1.01,9],[1,1.01,0]],"batl":[[0,1.21,14.92],[1,1.23,29.82],[2,1.25,14.92]],"ltp":1.05,"tv":1869.07,"id":11214864}]}]}
{"op":"mcm","clk":"4216051643","pt":1631547471398,"mc":[{"id":"1.187605875","rc":[{"batb":[[0,1.03,486.75],[1,1.01,9]],"batl":[[0,1.04,183.04],[1,1.05,296.17],[2,1.21,14.92]],"ltp":1.05,"tv":1869.07,"id":11214864}]}]}
{"op":"mcm","clk":"4216052010","pt":1631547475522,"mc":[{"id":"1.187605875","rc":[{"batb":[[0,1.01,9],[1,1.01,0]],"batl":[[0,1.21,14.92],[1,1.23,29.82],[2,1.25,14.92]],"ltp":1.05,"tv":1869.07,"id":11214864}]}]}
{"op":"mcm","clk":"4216052274","pt":1631547478500,"mc":[{"id":"1.187605875","rc":[{"batb":[[0,1.02,491.52],[1,1.01,9]],"batl":[[0,1.06,472.97],[1,1.21,14.92],[2,1.23,29.82]],"ltp":1.05,"tv":1869.07,"id":11214864}]}]}
{"op":"mcm","clk":"4216052601","pt":1631547482440,"mc":[{"id":"1.187605875","rc":[{"batb":[[0,1.01,9],[1,1.01,0]],"ltp":1.05,"tv":1869.07,"id":11214864}]}]}
{"op":"mcm","clk":"4216052845","pt":1631547485318,"mc":[{"id":"1.187605875","rc":[{"batb":[[0,17.5,21.31],[1,1.41,16.2],[2,1.4,767.39]],"batl":[[0,26,27.32],[1,990,0.01]],"ltp":13.5,"tv":46.09,"id":40752182},{"batb":[[0,1.05,213.45],[1,1.04,949.7],[2,1.01,9]],"batl":[[0,1.06,604.92]],"ltp":1.05,"tv":1869.07,"id":11214864}]}]}
{"op":"mcm","clk":"4216052979","pt":1631547486726,"mc":[{"id":"1.187605875","rc":[{"batl":[[1,170,37.53],[2,990,0.01]],"ltp":13.5,"tv":46.09,"id":40752182}]}]}
{"op":"mcm","clk":"4216053931","pt":1631547499435,"mc":[{"id":"1.187605875","rc":[{"batb":[[0,1.41,16.2],[1,1.4,767.39],[2,1.01,7]],"batl":[[0,170,37.53],[1,990,0.01],[2,990,0]],"ltp":13.5,"tv":46.09,"id":40752182},{"batb":[[0,1.01,9],[1,1.04,0],[2,1.01,0]],"batl":[[0,1.21,14.92],[1,1.23,29.82],[2,1.25,14.92]],"ltp":1.05,"tv":1869.07,"id":11214864}]}]}
{"op":"mcm","clk":"4216054204","pt":1631547502445,"mc":[{"id":"1.187605875","rc":[{"batb":[[0,1.03,486.75],[1,1.01,9]],"batl":[[0,1.08,464.21],[1,1.21,14.92],[2,1.23,29.82]],"ltp":1.05,"tv":1869.07,"id":11214864}]}]}
{"op":"mcm","clk":"4216054997","pt":1631547511555,"mc":[{"id":"1.187605875","rc":[{"batb":[[0,1.01,9],[1,1.01,0]],"ltp":1.05,"tv":1869.07,"id":11214864}]}]}
{"op":"mcm","clk":"4216055122","pt":1631547513070,"mc":[{"id":"1.187605875","rc":[{"batl":[[0,990,0.01],[1,990,0]],"ltp":13.5,"tv":46.09,"id":40752182}]}]}
{"op":"mcm","clk":"4216055233","pt":1631547514477,"mc":[{"id":"1.187605875","rc":[{"batb":[[0,13.5,14.17],[1,1.41,16.2],[2,1.4,767.39]],"batl":[[0,17.5,30.66],[1,990,0.01]],"ltp":13.5,"tv":46.09,"id":40752182},{"batb":[[0,1.06,472.97],[1,1.01,9]],"batl":[[0,1.07,41.06],[1,1.08,641.32],[2,1.21,14.92]],"ltp":1.05,"tv":1869.07,"id":11214864}]}]}
{"op":"mcm","clk":"4216055438","pt":1631547517054,"mc":[{"id":"1.187605875","rc":[{"batb":[[1,1.01,3979.74]],"ltp":1.05,"tv":1869.07,"id":11214864}]}]}
{"op":"mcm","clk":"4216056615","pt":1631547532403,"mc":[{"id":"1.187605875","rc":[{"batb":[[0,1.41,16.2],[1,1.4,767.39],[2,1.01,7]],"batl":[[0,990,0.01],[1,990,0]],"ltp":13.5,"tv":46.09,"id":40752182},{"batb":[[0,1.01,3979.74],[1,1.01,0]],"batl":[[0,1.21,14.92],[1,1.23,29.82],[2,1.25,14.92]],"ltp":1.05,"tv":1869.07,"id":11214864}]}]}
{"op":"mcm","clk":"4216056871","pt":1631547535398,"mc":[{"id":"1.187605875","rc":[{"batb":[[0,1.05,240.85],[1,1.04,238.89],[2,1.01,3979.74]],"batl":[[0,1.09,126.5],[1,1.1,330.41],[2,1.21,14.92]],"ltp":1.05,"tv":1869.07,"id":11214864}]}]}
{"op":"mcm","clk":"4216057311","pt":1631547540792,"mc":[{"id":"1.187605875","rc":[{"batl":[[0,1.21,14.92],[1,1.23,29.82],[2,1.25,14.92]],"ltp":1.05,"tv":1869.07,"id":11214864}]}]}
{"op":"mcm","clk":"4216057578","pt":1631547543815,"mc":[{"id":"1.187605875","rc":[{"batb":[[0,17.5,20.32],[1,1.41,16.2],[2,1.4,767.39]],"batl":[[0,26,26.99],[1,990,0.01]],"ltp":13.5,"tv":46.09,"id":40752182},{"batb":[[1,1.04,913.83],[2,1.01,9]],"batl":[[0,1.06,604.56],[1,1.21,14.92],[2,1.23,29.82]],"ltp":1.05,"tv":1869.07,"id":11214864}]}]}
{"op":"mcm","clk":"4216057899","pt":1631547547320,"mc":[{"id":"1.187605875","rc":[{"batl":[[1,170,37.53],[2,990,0.01]],"ltp":13.5,"tv":46.09,"id":40752182}]}]}
{"op":"mcm","clk":"4216058585","pt":1631547556028,"mc":[{"id":"1.187605875","rc":[{"batb":[[0,1.41,16.2],[1,1.4,767.39],[2,1.01,7]],"batl":[[0,170,37.53],[1,990,0.01],[2,990,0]],"ltp":13.5,"tv":46.09,"id":40752182},{"batb":[[0,1.01,9],[1,1.04,0],[2,1.01,0]],"batl":[[0,1.21,14.92],[1,1.23,29.82],[2,1.25,14.92]],"ltp":1.05,"tv":1869.07,"id":11214864}]}]}
{"op":"mcm","clk":"4216059015","pt":1631547560676,"mc":[{"id":"1.187605875","rc":[{"batl":[[0,990,0.01],[1,990,0]],"ltp":13.5,"tv":46.09,"id":40752182}]}]}
{"op":"mcm","clk":"4216059121","pt":1631547562115,"mc":[{"id":"1.187605875","rc":[{"batb":[[0,1.04,482.07],[1,1.01,9]],"batl":[[0,1.06,472.97],[1,1.21,14.92],[2,1.23,29.82]],"ltp":1.05,"tv":1869.07,"id":11214864}]}]}
{"op":"mcm","clk":"4216059400","pt":1631547565002,"mc":[{"id":"1.187605875","rc":[{"batb":[[0,1.01,9],[1,1.01,0]],"batl":[[0,1.21,14.92],[1,1.23,29.82],[2,1.25,14.92]],"ltp":1.05,"tv":1869.07,"id":11214864}]}]}
{"op":"mcm","clk":"4216059632","pt":1631547567970,"mc":[{"id":"1.187605875","rc":[{"batb":[[0,1.03,486.75],[1,1.01,9]],"batl":[[0,1.08,464.21],[1,1.21,14.92],[2,1.23,29.82]],"ltp":1.05,"tv":1869.07,"id":11214864}]}]}
{"op":"mcm","clk":"4216061305","pt":1631547587422,"mc":[{"id":"1.187605875","rc":[{"batl":[[0,1.21,14.92],[1,1.23,29.82],[2,1.25,14.92]],"ltp":1.05,"tv":1869.07,"id":11214864}]}]}
{"op":"mcm","clk":"4216061547","pt":1631547590393,"mc":[{"id":"1.187605875","rc":[{"batb":[[0,21,22.4],[1,1.41,16.2],[2,1.4,767.39]],"batl":[[0,34,23.75],[1,990,0.01]],"ltp":13.5,"tv":46.09,"id":40752182},{"batl":[[0,1.04,311.24],[1,1.05,669.99],[2,1.21,14.92]],"ltp":1.05,"tv":1869.07,"id":11214864}]}]}
{"op":"mcm","clk":"4216062544","pt":1631547602303,"mc":[{"id":"1.187605875","rc":[{"batl":[[1,1.05,665.35]],"ltp":1.05,"tv":1869.07,"id":11214864}]}]}
{"op":"mcm","clk":"4216063145","pt":1631547609013,"mc":[{"id":"1.187605875","rc":[{"batb":[[0,1.41,16.2],[1,1.4,767.39],[2,1.01,7]],"batl":[[0,990,0.01],[1,990,0]],"ltp":13.5,"tv":46.09,"id":40752182},{"batl":[[0,1.04,262.61],[1,1.05,217.36]],"ltp":1.05,"tv":1869.07,"id":11214864}]}]}
{"op":"mcm","clk":"4216063161","pt":1631547609228,"mc":[{"id":"1.187605875","rc":[{"batb":[[0,1.01,9],[1,1.01,0]],"batl":[[0,1.21,14.92],[1,1.23,29.82],[2,1.25,14.92]],"ltp":1.05,"tv":1869.07,"id":11214864}]}]}
{"op":"mcm","clk":"4216063397","pt":1631547612219,"mc":[{"id":"1.187605875","rc":[{"batb":[[0,1.02,425.03],[1,1.01,9]],"batl":[[0,1.06,472.97],[1,1.21,14.92],[2,1.23,29.82]],"ltp":1.05,"tv":1869.07,"id":11214864}]}]}
{"op":"mcm","clk":"4216063982","pt":1631547619330,"mc":[{"id":"1.187605875","rc":[{"batb":[[0,1.01,9],[1,1.01,0]],"ltp":1.05,"tv":1869.07,"id":11214864}]}]}
{"op":"mcm","clk":"4216064215","pt":1631547622350,"mc":[{"id":"1.187605875","rc":[{"batl":[[0,26,26.81],[1,990,0.01]],"ltp":13.5,"tv":46.09,"id":40752182},{"batb":[[0,1.05,281.28],[1,1.04,868.24],[2,1.01,9]],"batl":[[0,1.06,604.06],[1,1.07,895.98],[2,1.21,14.92]],"ltp":1.05,"tv":1869.07,"id":11214864}]}]}
{"op":"mcm","clk":"4216064349","pt":1631547624238,"mc":[{"id":"1.187605875","rc":[{"batl":[[1,170,37.53],[2,990,0.01]],"ltp":13.5,"tv":46.09,"id":40752182}]}]}
{"op":"mcm","clk":"4216065801","pt":1631547643645,"mc":[{"id":"1.187605875","rc":[{"batl":[[0,170,37.53],[1,990,0.01],[2,990,0]],"ltp":13.5,"tv":46.09,"id":40752182},{"batb":[[0,1.01,9],[1,1.04,0],[2,1.01,0]],"batl":[[0,1.21,14.92],[1,1.23,29.82],[2,1.25,14.92]],"ltp":1.05,"tv":1869.07,"id":11214864}]}]}
{"op":"mcm","clk":"4216066256","pt":1631547649879,"mc":[{"id":"1.187605875","rc":[{"batb":[[0,1.04,482.07],[1,1.01,9]],"batl":[[0,1.06,472.97],[1,1.21,14.92],[2,1.23,29.82]],"ltp":1.05,"tv":1869.07,"id":11214864}]}]}
{"op":"mcm","clk":"4216066740","pt":1631547654436,"mc":[{"id":"1.187605875","rc":[{"batb":[[0,1.01,9],[1,1.01,0]],"batl":[[0,1.21,14.92],[1,1.23,29.82],[2,1.25,14.92]],"ltp":1.05,"tv":1869.07,"id":11214864}]}]}
{"op":"mcm","clk":"4216067198","pt":1631547657312,"mc":[{"id":"1.187605875","rc":[{"batb":[[0,1.03,486.75],[1,1.01,9]],"batl":[[0,1.08,464.21],[1,1.21,14.92],[2,1.23,29.82]],"ltp":1.05,"tv":1869.07,"id":11214864}]}]}
{"op":"mcm","clk":"4216067764","pt":1631547663012,"mc":[{"id":"1.187605875","rc":[{"batb":[[0,1.01,9],[1,1.01,0]],"ltp":1.05,"tv":1869.07,"id":11214864}]}]}
{"op":"mcm","clk":"4216067908","pt":1631547664546,"mc":[{"id":"1.187605875","rc":[{"batl":[[0,990,0.01],[1,990,0]],"ltp":13.5,"tv":46.09,"id":40752182}]}]}
{"op":"mcm","clk":"4216068073","pt":1631547666015,"mc":[{"id":"1.187605875","rc":[{"batb":[[0,13.5,14.07],[1,1.41,16.2],[2,1.4,767.39]],"batl":[[0,17.5,30.9],[1,990,0.01]],"ltp":13.5,"tv":46.09,"id":40752182},{"batb":[[0,1.06,472.97],[1,1.01,9]],"batl":[[0,1.07,40.58],[1,1.08,640.07],[2,1.21,14.92]],"ltp":1.05,"tv":1869.07,"id":11214864}]}]}
{"op":"mcm","clk":"4216068380","pt":1631547668747,"mc":[{"id":"1.187605875","rc":[{"batb":[[1,1.01,3979.74]],"ltp":1.05,"tv":1869.07,"id":11214864}]}]}
{"op":"mcm","clk":"4216070833","pt":1631547686466,"mc":[{"id":"1.187605875","rc":[{"batb":[[0,1.41,16.2],[1,1.4,767.39],[2,1.01,7]],"batl":[[0,990,0.01],[1,990,0]],"ltp":13.5,"tv":46.09,"id":40752182},{"batb":[[0,1.01,3979.74],[1,1.01,0]],"batl":[[0,1.21,14.92],[1,1.23,29.82],[2,1.25,14.92]],"ltp":1.05,"tv":1869.07,"id":11214864}]}]}
{"op":"mcm","clk":"4216071057","pt":1631547689378,"mc":[{"id":"1.187605875","rc":[{"batb":[[0,1.05,307.13],[1,1.04,171.98],[2,1.01,3979.74]],"batl":[[0,1.09,76.09],[1,1.1,380.37],[2,1.21,14.92]],"ltp":1.05,"tv":1869.07,"id":11214864}]}]}
{"op":"mcm","clk":"4216071286","pt":1631547692338,"mc":[{"id":"1.187605875","rc":[{"batb":[[0,1.01,3979.74],[1,1.04,0],[2,1.01,0]],"ltp":1.05,"tv":1869.07,"id":11214864}]}]}
{"op":"mcm","clk":"4216071394","pt":1631547693950,"mc":[{"id":"1.187605875","rc":[{"batb":[[0,1.01,9]],"ltp":1.05,"tv":1869.07,"id":11214864}]}]}
{"op":"mcm","clk":"4216071486","pt":1631547695048,"mc":[{"id":"1.187605875","rc":[{"batb":[[0,11,17.42],[1,1.41,16.2],[2,1.4,767.39]],"batl":[[0,15,56.66],[1,990,0.01]],"ltp":13.5,"tv":46.09,"id":40752182},{"batl":[[0,1.09,132.45],[1,1.1,554.59]],"ltp":1.05,"tv":1869.07,"id":11214864}]}]}
{"op":"mcm","clk":"4216071499","pt":1631547695248,"mc":[{"id":"1.187605875","rc":[{"batb":[[0,1.08,385.46],[1,1.07,79.48],[2,1.01,9]],"ltp":1.05,"tv":1869.07,"id":11214864}]}]}
{"op":"mcm","clk":"4216071685","pt":1631547697950,"mc":[{"id":"1.187605875","rc":[{"batb":[[2,1.02,2179.83]],"ltp":1.05,"tv":1869.07,"id":11214864}]}]}
{"op":"mcm","clk":"4216073887","pt":1631547729024,"mc":[{"id":"1.187605875","rc":[{"batb":[[0,1.41,16.2],[1,1.4,767.39],[2,1.01,7]],"batl":[[0,990,0.01],[1,990,0]],"ltp":13.5,"tv":46.09,"id":40752182},{"batb":[[0,1.07,79.48],[1,1.02,2179.83],[2,1.01,9]],"batl":[[0,1.21,14.92],[1,1.23,29.82],[2,1.25,14.92]],"ltp":1.05,"tv":1869.07,"id":11214864}]}]}
{"op":"mcm","clk":"4216074069","pt":1631547732031,"mc":[{"id":"1.187605875","rc":[{"batb":[[0,1.07,218.47],[1,1.06,252.44],[2,1.02,2179.83]],"batl":[[0,1.12,355.6],[1,1.13,91.21],[2,1.21,14.92]],"ltp":1.05,"tv":1869.07,"id":11214864}]}]}
{"op":"mcm","clk":"4216074453","pt":1631547737330,"mc":[{"id":"1.187605875","rc":[{"batl":[[0,1.21,14.92],[1,1.23,29.82],[2,1.25,14.92]],"ltp":1.05,"tv":1869.07,"id":11214864}]}]}
{"op":"mcm","clk":"4216074566","pt":1631547738892,"mc":[{"id":"1.187605875","rc":[{"batb":[[2,1.01,9]],"ltp":1.05,"tv":1869.07,"id":11214864}]}]}
{"op":"mcm","clk":"4216074645","pt":1631547740127,"mc":[{"id":"1.187605875","rc":[{"batb":[[0,13.5,3.9],[1,1.41,16.2],[2,1.4,767.39]],"batl":[[0,17.5,53.29],[1,990,0.01]],"ltp":13.5,"tv":46.09,"id":40752182},{"batl":[[0,1.08,48.72],[1,1.09,634.98],[2,1.21,14.92]],"ltp":1.05,"tv":1869.07,"id":11214864}]}]}
{"op":"mcm","clk":"4216074657","pt":1631547740335,"mc":[{"id":"1.187605875","rc":[{"batl":[[0,1.08,355.86],[1,1.09,790.6]],"ltp":1.05,"tv":1869.07,"id":11214864}]}]}
{"op":"mcm","clk":"4216074822","pt":1631547742619,"mc":[{"id":"1.187605875","rc":[{"batb":[[2,1.01,4167.03]],"ltp":1.05,"tv":1869.07,"id":11214864}]}]}
{"op":"mcm","clk":"4216075513","pt":1631547752422,"mc":[{"id":"1.187605875","rc":[{"batb":[[0,1.41,16.2],[1,1.4,767.39],[2,1.01,7]],"batl":[[0,990,0.01],[1,990,0]],"ltp":13.5,"tv":46.09,"id":40752182},{"batb":[[0,1.06,245.14],[1,1.01,4167.03],[2,1.01,0]],"batl":[[0,1.21,14.92],[1,1.23,29.82],[2,1.25,14.92]],"ltp":1.05,"tv":1869.07,"id":11214864}]}]}
{"op":"mcm","clk":"4216075734","pt":1631547755428,"mc":[{"id":"1.187605875","rc":[{"batb":[[1,1.05,230],[2,1.01,4167.03]],"batl":[[0,1.1,340.6],[1,1.11,114.12],[2,1.21,14.92]],"ltp":1.05,"tv":1869.07,"id":11214864}]}]}
{"op":"mcm","clk":"4216076498","pt":1631547767754,"mc":[{"id":"1.187605875","rc":[{"batb":[[0,1.01,4167.03],[1,1.05,0],[2,1.01,0]],"ltp":1.05,"tv":1869.07,"id":11214864}]}]}
{"op":"mcm","clk":"4216076712","pt":1631547770764,"mc":[{"id":"1.187605875","rc":[{"batl":[[0,13.5,21.48],[1,990,0.01]],"ltp":13.5,"tv":46.09,"id":40752182},{"batb":[[0,1.08,667.91],[1,1.01,9]],"batl":[[0,1.09,29.25],[1,1.1,340.6],[2,1.11,704.51]],"ltp":1.05,"tv":1869.07,"id":11214864}]}]}
{"op":"mcm","clk":"4216076938","pt":1631547773878,"mc":[{"id":"1.187605875","rc":[{"batb":[[1,1.02,2179.83],[2,1.01,9]],"ltp":1.05,"tv":1869.07,"id":11214864}]}]}
{"op":"mcm","clk":"4216078251","pt":1631547791377,"mc":[{"id":"1.187605875","rc":[{"batl":[[0,990,0.01],[1,990,0]],"ltp":13.5,"tv":46.09,"id":40752182},{"batb":[[0,1.02,2179.83],[1,1.01,9],[2,1.01,0]],"batl":[[0,1.21,14.92],[1,1.23,29.82],[2,1.25,14.92]],"ltp":1.05,"tv":1869.07,"id":11214864}]}]}
{"op":"mcm","clk":"4216078436","pt":1631547794306,"mc":[{"id":"1.187605875","rc":[{"batb":[[0,1.07,336.99],[1,1.06,132.8],[2,1.02,2179.83]],"batl":[[0,1.13,353.74],[1,1.14,89.14],[2,1.21,14.92]],"ltp":1.05,"tv":1869.07,"id":11214864}]}]}
{"op":"mcm","clk":"4216080427","pt":1631547823812,"mc":[{"id":"1.187605875","rc":[{"batl":[[0,1.21,14.92],[1,1.23,29.82],[2,1.25,14.92]],"ltp":1.05,"tv":1869.07,"id":11214864}]}]}
{"op":"mcm","clk":"4216080615","pt":1631547826839,"mc":[{"id":"1.187605875","rc":[{"batb":[[0,13.5,3.72],[1,1.41,16.2],[2,1.4,767.39]],"batl":[[0,17.5,54.8],[1,990,0.01]],"ltp":13.5,"tv":46.09,"id":40752182},{"batb":[[2,1.01,9]],"batl":[[0,1.08,2480.97],[1,1.09,859.78],[2,1.21,14.92]],"ltp":1.05,"tv":1869.07,"id":11214864}]}]}
{"op":"mcm","clk":"4216080639","pt":1631547827214,"mc":[{"id":"1.187605875","rc":[{"batl":[[0,1.08,429.26]],"ltp":1.05,"tv":1869.07,"id":11214864}]}]}
{"op":"mcm","clk":"4216081318","pt":1631547838723,"mc":[{"id":"1.187605875","rc":[{"batl":[[0,1.08,248.85]],"ltp":1.05,"tv":1869.07,"id":11214864}]}]}
{"op":"mcm","clk":"4216083703","pt":1631547863995,"mc":[{"id":"1.187605875","rc":[{"batb":[[0,1.06,132.8],[1,1.01,9],[2,1.01,0]],"batl":[[0,1.08,46.52],[1,1.09,600.3]],"ltp":1.05,"tv":1869.07,"id":11214864}]}]}
{"op":"mcm","clk":"4216084018","pt":1631547866866,"mc":[{"id":"1.187605875","rc":[{"batb":[[0,1.06,220.88],[1,1.05,254.48],[2,1.01,9]],"batl":[[2,1.1,106.88]],"ltp":1.05,"tv":1869.07,"id":11214864}]}]}
{"op":"mcm","clk":"4216084092","pt":1631547867699,"mc":[{"id":"1.187605875","rc":[{"batb":[[0,1.41,16.2],[1,1.4,767.39],[2,1.01,7]],"batl":[[0,990,0.01],[1,990,0]],"ltp":13.5,"tv":46.09,"id":40752182},{"batl":[[0,1.1,106.88],[1,1.11,345.74],[2,1.21,14.92]],"ltp":1.05,"tv":1869.07,"id":11214864}]}]}
{"op":"mcm","clk":"4216084809","pt":1631547874312,"mc":[{"id":"1.187605875","rc":[{"batl":[[0,1.21,14.92],[1,1.23,29.82],[2,1.25,14.92]],"ltp":1.05,"tv":1869.07,"id":11214864}]}]}
{"op":"mcm","clk":"4216085070","pt":1631547877078,"mc":[{"id":"1.187605875","rc":[{"batl":[[0,1.09,9.64],[1,1.21,14.92],[2,1.23,29.82]],"ltp":1.05,"tv":1869.07,"id":11214864}]}]}
{"op":"mcm","clk":"4216085106","pt":1631547877397,"mc":[{"id":"1.187605875","rc":[{"batl":[[0,21,25.63],[1,990,0.01]],"ltp":13.5,"tv":46.09,"id":40752182},{"batb":[[1,1.05,635.9]],"batl":[[0,1.07,773.41]],"ltp":1.05,"tv":1869.07,"id":11214864}]}]}
{"op":"mcm","clk":"4216085262","pt":1631547878981,"mc":[{"id":"1.187605875","rc":[{"batb":[[2,1.01,3979.74]],"ltp":1.05,"tv":1869.07,"id":11214864}]}]}
{"op":"mcm","clk":"4216085968","pt":1631547887030,"mc":[{"id":"1.187605875","rc":[{"batl":[[0,21,19.07]],"ltp":13.5,"tv":46.09,"id":40752182}]}]}
{"op":"mcm","clk":"4216085976","pt":1631547887148,"mc":[{"id":"1.187605875","rc":[{"batl":[[0,990,0.01],[1,990,0]],"ltp":13.5,"tv":46.09,"id":40752182},{"batb":[[0,1.05,254.48],[1,1.01,3979.74],[2,1.01,0]],"batl":[[0,1.21,14.92],[1,1.23,29.82],[2,1.25,14.92]],"ltp":1.05,"tv":1869.07,"id":11214864}]}]}
{"op":"mcm","clk":"4216086204","pt":1631547890042,"mc":[{"id":"1.187605875","rc":[{"batb":[[0,1.05,477.47]],"batl":[[0,1.08,235.33],[1,1.09,226.78],[2,1.21,14.92]],"ltp":1.05,"tv":1869.07,"id":11214864}]}]}
{"op":"mcm","clk":"4216086242","pt":1631547890426,"mc":[{"id":"1.187605875","rc":[{"batb":[[0,1.01,3979.74],[1,1.01,0]],"batl":[[1,1.21,14.92],[2,1.23,29.82]],"ltp":1.05,"tv":1869.07,"id":11214864}]}]}
{"op":"mcm","clk":"4216086508","pt":1631547893413,"mc":[{"id":"1.187605875","rc":[{"batb":[[0,1.06,420.63],[1,1.01,3979.74]],"batl":[[0,1.07,236.76],[1,1.08,235.33],[2,1.21,14.92]],"ltp":1.05,"tv":1869.07,"id":11214864}]}]}
{"op":"mcm","clk":"4216086904","pt":1631547897021,"mc":[{"id":"1.187605875","rc":[{"batb":[[0,1.01,3979.74],[1,1.01,0]],"batl":[[0,1.08,235.33],[1,1.21,14.92],[2,1.23,29.82]],"ltp":1.05,"tv":1869.07,"id":11214864}]}]}
{"op":"mcm","clk":"4216087148","pt":1631547899959,"mc":[{"id":"1.187605875","rc":[{"batb":[[0,1.05,477.47],[1,1.01,3979.74]],"batl":[[1,1.09,226.78],[2,1.21,14.92]],"ltp":1.05,"tv":1869.07,"id":11214864}]}]}
{"op":"mcm","clk":"4216087897","pt":1631547907746,"mc":[{"id":"1.187605875","rc":[{"batl":[[0,1.21,14.92],[1,1.23,29.82],[2,1.25,14.92]],"ltp":1.05,"tv":1869.07,"id":11214864}]}]}
{"op":"mcm","clk":"4216088249","pt":1631547911044,"mc":[{"id":"1.187605875","rc":[{"batb":[[0,17.5,18.72],[1,1.41,16.2],[2,1.4,767.39]],"batl":[[0,26,31.29],[1,990,0.01]],"ltp":13.5,"tv":46.09,"id":40752182},{"batb":[[1,1.04,782.16],[2,1.01,9]],"batl":[[0,1.06,386.26],[1,1.07,438.7],[2,1.21,14.92]],"ltp":1.05,"tv":1869.07,"id":11214864}]}]}
{"op":"mcm","clk":"4216088579","pt":1631547914562,"mc":[{"id":"1.187605875","rc":[{"batl":[[1,170,37.53],[2,990,0.01]],"ltp":13.5,"tv":46.09,"id":40752182}]}]}
{"op":"mcm","clk":"4216089346","pt":1631547922581,"mc":[{"id":"1.187605875","rc":[{"batl":[[1,1.07,203.02]],"ltp":1.05,"tv":1869.07,"id":11214864}]}]}
{"op":"mcm","clk":"4216096914","pt":1631547995972,"mc":[{"id":"1.187605875","rc":[{"batl":[[1,990,0.01],[2,990,0]],"ltp":13.5,"tv":46.09,"id":40752182}]}]}
{"op":"mcm","clk":"4216099346","pt":1631548023136,"mc":[{"id":"1.187605875","rc":[{"batb":[[0,1.41,16.2],[1,1.4,767.39],[2,1.01,7]],"batl":[[0,990,0.01],[1,990,0]],"ltp":13.5,"tv":46.09,"id":40752182},{"batb":[[0,1.01,9],[1,1.04,0],[2,1.01,0]],"batl":[[0,1.21,14.92],[1,1.23,29.82],[2,1.25,14.92]],"ltp":1.05,"tv":1869.07,"id":11214864}]}]}
{"op":"mcm","clk":"4216099604","pt":1631548026124,"mc":[{"id":"1.187605875","rc":[{"batb":[[0,1.04,349.19],[1,1.03,134.16],[2,1.01,9]],"batl":[[0,1.08,464.21],[1,1.21,14.92],[2,1.23,29.82]],"ltp":1.05,"tv":1869.07,"id":11214864}]}]}
{"op":"mcm","clk":"4216100415","pt":1631548035130,"mc":[{"id":"1.187605875","rc":[{"batl":[[0,1.21,14.92],[1,1.23,29.82],[2,1.25,14.92]],"ltp":1.05,"tv":1869.07,"id":11214864}]}]}
{"op":"mcm","clk":"4216100671","pt":1631548038060,"mc":[{"id":"1.187605875","rc":[{"batb":[[0,21,17.14],[1,1.41,16.2],[2,1.4,767.39]],"batl":[[0,34,49.75],[1,990,0.01]],"ltp":13.5,"tv":46.09,"id":40752182},{"batl":[[0,1.05,342.71],[1,1.21,14.92],[2,1.23,29.82]],"ltp":1.05,"tv":1869.07,"id":11214864}]}]}
{"op":"mcm","clk":"4216100684","pt":1631548038165,"mc":[{"id":"1.187605875","rc":[{"batl":[[0,1.05,820.18]],"ltp":1.05,"tv":1869.07,"id":11214864}]}]}
{"op":"mcm","clk":"4216101067","pt":1631548042355,"mc":[{"id":"1.187605875","rc":[{"batl":[[1,340,36.42],[2,990,0.01]],"ltp":13.5,"tv":46.09,"id":40752182}]}]}
{"op":"mcm","clk":"4216101537","pt":1631548046937,"mc":[{"id":"1.187605875","rc":[{"batb":[[0,1.41,16.2],[1,1.4,767.39],[2,1.01,7]],"batl":[[0,340,36.42],[1,990,0.01],[2,990,0]],"ltp":13.5,"tv":46.09,"id":40752182},{"batb":[[0,1.03,134.16],[1,1.01,9],[2,1.01,0]],"batl":[[0,1.21,14.92],[1,1.23,29.82],[2,1.25,14.92]],"ltp":1.05,"tv":1869.07,"id":11214864}]}]}
{"op":"mcm","clk":"4216101816","pt":1631548049828,"mc":[{"id":"1.187605875","rc":[{"batb":[[0,1.03,169.11],[1,1.02,320.75],[2,1.01,9]],"batl":[[0,1.06,299.79],[1,1.07,171.55],[2,1.21,14.92]],"ltp":1.05,"tv":1869.07,"id":11214864}]}]}
{"op":"mcm","clk":"4216102654","pt":1631548059650,"mc":[{"id":"1.187605875","rc":[{"batl":[[0,1.21,14.92],[1,1.23,29.82],[2,1.25,14.92]],"ltp":1.05,"tv":1869.07,"id":11214864}]}]}
{"op":"mcm","clk":"4216102832","pt":1631548061790,"mc":[{"id":"1.187605875","rc":[{"batl":[[0,990,0.01],[1,990,0]],"ltp":13.5,"tv":46.09,"id":40752182}]}]}
{"op":"mcm","clk":"4216102902","pt":1631548062578,"mc":[{"id":"1.187605875","rc":[{"batb":[[0,26,21.4],[1,1.41,16.2],[2,1.4,767.39]],"batl":[[0,50,44.81],[1,990,0.01]],"ltp":13.5,"tv":46.09,"id":40752182},{"batl":[[0,1.04,1017.06],[1,1.21,14.92],[2,1.23,29.82]],"ltp":1.05,"tv":1869.07,"id":11214864}]}]}
{"op":"mcm","clk":"4216104007","pt":1631548076000,"mc":[{"id":"1.187605875","rc":[{"batb":[[0,1.41,16.2],[1,1.4,767.39],[2,1.01,7]],"batl":[[0,990,0.01],[1,990,0]],"ltp":13.5,"tv":46.09,"id":40752182},{"batb":[[0,1.02,320.75],[1,1.01,9],[2,1.01,0]],"batl":[[0,1.21,14.92],[1,1.23,29.82],[2,1.25,14.92]],"ltp":1.05,"tv":1869.07,"id":11214864}]}]}
{"op":"mcm","clk":"4216104295","pt":1631548079015,"mc":[{"id":"1.187605875","rc":[{"batb":[[0,1.02,491.52]],"batl":[[0,1.05,477.47],[1,1.21,14.92],[2,1.23,29.82]],"ltp":1.05,"tv":1869.07,"id":11214864}]}]}
{"op":"mcm","clk":"4216104321","pt":1631548079287,"mc":[{"id":"1.187605875","rc":[{"batl":[[0,1.21,14.92],[1,1.23,29.82],[2,1.25,14.92]],"ltp":1.05,"tv":1869.07,"id":11214864}]}]}
{"op":"mcm","clk":"4216104576","pt":1631548082268,"mc":[{"id":"1.187605875","rc":[{"batl":[[0,1.04,482.07],[1,1.21,14.92],[2,1.23,29.82]],"ltp":1.05,"tv":1869.07,"id":11214864}]}]}
{"op":"mcm","clk":"4216104929","pt":1631548086310,"mc":[{"id":"1.187605875","rc":[{"batl":[[0,1.21,14.92],[1,1.23,29.82],[2,1.25,14.92]],"ltp":1.05,"tv":1869.07,"id":11214864}]}]}
{"op":"mcm","clk":"4216105237","pt":1631548089301,"mc":[{"id":"1.187605875","rc":[{"batl":[[0,1.05,477.47],[1,1.21,14.92],[2,1.23,29.82]],"ltp":1.05,"tv":1869.07,"id":11214864}]}]}
{"op":"mcm","clk":"4216105619","pt":1631548094001,"mc":[{"id":"1.187605875","rc":[{"batl":[[0,1.21,14.92],[1,1.23,29.82],[2,1.25,14.92]],"ltp":1.05,"tv":1869.07,"id":11214864}]}]}
{"op":"mcm","clk":"4216105858","pt":1631548097009,"mc":[{"id":"1.187605875","rc":[{"batl":[[0,100,57.64],[1,990,0.01]],"ltp":13.5,"tv":46.09,"id":40752182},{"batl":[[0,1.03,1635.01],[1,1.21,14.92],[2,1.23,29.82]],"ltp":1.05,"tv":1869.07,"id":11214864}]}]}
{"op":"mcm","clk":"4216107042","pt":1631548109824,"mc":[{"id":"1.187605875","rc":[{"batl":[[0,990,0.01],[1,990,0]],"ltp":13.5,"tv":46.09,"id":40752182},{"batb":[[0,1.01,9],[1,1.01,0]],"batl":[[0,1.03,341.31]],"ltp":1.05,"tv":1869.07,"id":11214864}]}]}
{"op":"mcm","clk":"4216107344","pt":1631548112730,"mc":[{"id":"1.187605875","rc":[{"batb":[[0,1.01,505.39]],"batl":[[1,1.04,144.03],[2,1.21,14.92]],"ltp":1.05,"tv":1869.07,"id":11214864}]}]}
{"op":"mcm","clk":"4216107872","pt":1631548118398,"mc":[{"id":"1.187605875","rc":[{"batl":[[2,1.2,767.39]],"ltp":1.05,"tv":1869.07,"id":11214864}]}]}
{"op":"mcm","clk":"4216108065","pt":1631548121015,"mc":[{"id":"1.187605875","rc":[{"batl":[[2,1.18,10.23]],"ltp":1.05,"tv":1869.07,"id":11214864}]}]}
{"op":"mcm","clk":"4216108362","pt":1631548125114,"mc":[{"id":"1.187605875","rc":[{"trd":[[1.01,272.85]],"batb":[[0,1.01,368.97]],"batl":[[1,1.18,10.23],[2,1.2,767.39]],"ltp":1.01,"tv":2141.92,"id":11214864}],"tv":2188.01}]}
{"op":"mcm","clk":"4216108587","pt":1631548128153,"mc":[{"id":"1.187605875","rc":[{"batb":[[0,1.01,496.39]],"batl":[[0,1.03,424.73]],"ltp":1.01,"tv":2141.92,"id":11214864}]}]}
{"op":"mcm","clk":"4216108735","pt":1631548130069,"mc":[{"id":"1.187605875","rc":[{"batl":[[0,1.18,10.23],[1,1.2,767.39],[2,1.21,14.92]],"ltp":1.01,"tv":2141.92,"id":11214864}]}]}
{"op":"mcm","clk":"4216108975","pt":1631548132964,"mc":[{"id":"1.187605875","rc":[{"batl":[[0,100,34.73],[1,990,0.01]],"ltp":13.5,"tv":46.09,"id":40752182},{"batl":[[0,1.02,630.84],[1,1.03,895.98],[2,1.18,10.23]],"ltp":1.01,"tv":2141.92,"id":11214864}]}]}
{"op":"mcm","clk":"4216111583","pt":1631548160665,"mc":[{"id":"1.187605875","rc":[{"batl":[[0,990,0.01],[1,990,0]],"ltp":13.5,"tv":46.09,"id":40752182},{"batl":[[0,1.18,10.23],[1,1.2,767.39],[2,1.21,14.92]],"ltp":1.01,"tv":2141.92,"id":11214864}]}]}
{"op":"mcm","clk":"4216111908","pt":1631548163672,"mc":[{"id":"1.187605875","rc":[{"batl":[[0,1.03,486.75],[1,1.18,10.23],[2,1.2,767.39]],"ltp":1.01,"tv":2141.92,"id":11214864}]}]}
{"op":"mcm","clk":"4216112177","pt":1631548166813,"mc":[{"id":"1.187605875","rc":[{"batl":[[0,1.18,10.23],[1,1.2,767.39],[2,1.21,14.92]],"ltp":1.01,"tv":2141.92,"id":11214864}]}]}
{"op":"mcm","clk":"4216112426","pt":1631548169708,"mc":[{"id":"1.187605875","rc":[{"batb":[[0,1.01,1070.91]],"batl":[[0,1.02,1731.95],[1,1.18,10.23],[2,1.2,767.39]],"ltp":1.01,"tv":2141.92,"id":11214864}]}]}
{"op":"mcm","clk":"4216113078","pt":1631548178126,"mc":[{"id":"1.187605875","rc":[{"trd":[[1.01,276.26]],"batb":[[0,1.01,1069.2]],"ltp":1.01,"tv":2145.34,"id":11214864}],"tv":2191.43}]}
{"op":"mcm","clk":"4216113853","pt":1631548186345,"mc":[{"id":"1.187605875","rc":[{"batl":[[0,1.02,491.52]],"ltp":1.01,"tv":2145.34,"id":11214864}]}]}
{"op":"mcm","clk":"4216114612","pt":1631548193872,"mc":[{"id":"1.187605875","rc":[{"batl":[[0,1.18,10.23],[1,1.2,767.39],[2,1.21,14.92]],"ltp":1.01,"tv":2145.34,"id":11214864}]}]}
{"op":"mcm","clk":"4216114904","pt":1631548196884,"mc":[{"id":"1.187605875","rc":[{"batl":[[0,190,10.13],[1,990,0.01]],"ltp":13.5,"tv":46.09,"id":40752182},{"batl":[[0,1.01,669.06],[1,1.02,895.98],[2,1.18,10.23]],"ltp":1.01,"tv":2145.34,"id":11214864}]}]}
{"op":"mcm","clk":"4216117378","pt":1631548221990,"mc":[{"id":"1.187605875","rc":[{"batl":[[0,990,0.01],[1,990,0]],"ltp":13.5,"tv":46.09,"id":40752182},{"batl":[[0,1.01,496.39],[1,1.18,10.23],[2,1.2,767.39]],"ltp":1.01,"tv":2145.34,"id":11214864}]}]}
{"op":"mcm","clk":"4216117399","pt":1631548222198,"mc":[{"id":"1.187605875","rc":[{"batl":[[0,1.18,10.23],[1,1.2,767.39],[2,1.21,14.92]],"ltp":1.01,"tv":2145.34,"id":11214864}]}]}
{"op":"mcm","clk":"4216117710","pt":1631548225085,"mc":[{"id":"1.187605875","rc":[{"batl":[[0,1.02,491.52],[1,1.18,10.23],[2,1.2,767.39]],"ltp":1.01,"tv":2145.34,"id":11214864}]}]}
{"op":"mcm","clk":"4216117732","pt":1631548225291,"mc":[{"id":"1.187605875","rc":[{"batl":[[0,1.02,271.69]],"ltp":1.01,"tv":2145.34,"id":11214864}]}]}
{"op":"mcm","clk":"4216117994","pt":1631548227813,"mc":[{"id":"1.187605875","rc":[{"batl":[[0,1.01,222],[1,1.02,271.69],[2,1.18,10.23]],"ltp":1.01,"tv":2145.34,"id":11214864}]}]}
{"op":"mcm","clk":"4216118658","pt":1631548234798,"mc":[{"id":"1.187605875","rc":[{"batl":[[0,1.02,271.69],[1,1.18,10.23],[2,1.2,767.39]],"ltp":1.01,"tv":2145.34,"id":11214864}]}]}
{"op":"mcm","clk":"4216118978","pt":1631548237792,"mc":[{"id":"1.187605875","rc":[{"batl":[[0,1.02,491.52]],"ltp":1.01,"tv":2145.34,"id":11214864}]}]}
{"op":"mcm","clk":"4216119484","pt":1631548243188,"mc":[{"id":"1.187605875","rc":[{"batl":[[0,1.18,10.23],[1,1.2,767.39],[2,1.21,14.92]],"ltp":1.01,"tv":2145.34,"id":11214864}]}]}
{"op":"mcm","clk":"4216119659","pt":1631548245291,"mc":[{"id":"1.187605875","rc":[{"batl":[[0,290,7.95],[1,990,0.01]],"ltp":13.5,"tv":46.09,"id":40752182},{"batl":[[0,1.01,895.98],[1,1.18,10.23],[2,1.2,767.39]],"ltp":1.01,"tv":2145.34,"id":11214864}]}]}
{"op":"mcm","clk":"4216119776","pt":1631548246179,"mc":[{"id":"1.187605875","rc":[{"batl":[[0,1.01,1392.37]],"ltp":1.01,"tv":2145.34,"id":11214864}]}]}
{"op":"mcm","clk":"4216121148","pt":1631548260110,"mc":[{"id":"1.187605875","rc":[{"batl":[[0,990,0.01],[1,990,0]],"ltp":13.5,"tv":46.09,"id":40752182},{"batl":[[0,1.01,496.39]],"ltp":1.01,"tv":2145.34,"id":11214864}]}]}
{"op":"mcm","clk":"4216122605","pt":1631548276414,"mc":[{"id":"1.187605875","rc":[{"batb":[[0,140,6.45],[1,1.41,16.2],[2,1.4,767.39]],"ltp":13.5,"tv":46.09,"id":40752182}]}]}
{"op":"mcm","clk":"4216131708","pt":1631548375547,"mc":[{"id":"1.187605875","rc":[{"batb":[[0,1.41,16.2],[1,1.4,767.39],[2,1.01,7]],"ltp":13.5,"tv":46.09,"id":40752182}]}]}
{"op":"mcm","clk":"4216132529","pt":1631548384465,"mc":[{"id":"1.187605875","rc":[{"batl":[[0,290,11.92],[1,990,0.01]],"ltp":13.5,"tv":46.09,"id":40752182},{"batl":[[0,1.01,1392.37]],"ltp":1.01,"tv":2145.34,"id":11214864}]}]}
{"op":"mcm","clk":"4216133408","pt":1631548393651,"mc":[{"id":"1.187605875","rc":[{"batl":[[0,990,0.01],[1,990,0]],"ltp":13.5,"tv":46.09,"id":40752182},{"batl":[[0,1.01,496.39]],"ltp":1.01,"tv":2145.34,"id":11214864}]}]}
{"op":"mcm","clk":"4216135410","pt":1631548414917,"mc":[{"id":"1.187605875","rc":[{"batl":[[0,1.01,513.44]],"ltp":1.01,"tv":2145.34,"id":11214864}]}]}
{"op":"mcm","clk":"4216135674","pt":1631548417782,"mc":[{"id":"1.187605875","rc":[{"batb":[[0,140,6.45],[1,1.41,16.2],[2,1.4,767.39]],"batl":[[0,490,10.33],[1,990,0.01]],"ltp":13.5,"tv":46.09,"id":40752182}]}]}
{"op":"mcm","clk":"4216136467","pt":1631548426602,"mc":[{"id":"1.187605875","rc":[{"batb":[[0,1.41,16.2],[1,1.4,767.39],[2,1.01,7]],"batl":[[0,990,0.01],[1,990,0]],"ltp":13.5,"tv":46.09,"id":40752182}]}]}
{"op":"mcm","clk":"4216138080","pt":1631548445461,"mc":[{"id":"1.187605875","rc":[{"batb":[[0,190,4.74],[1,1.41,16.2],[2,1.4,767.39]],"batl":[[0,990,6.36]],"ltp":13.5,"tv":46.09,"id":40752182}]}]}
{"op":"mcm","clk":"4216140080","pt":1631548465044,"mc":[{"id":"1.187605875","rc":[{"batb":[[0,1.41,16.2],[1,1.4,767.39],[2,1.01,7]],"batl":[[0,990,0.01]],"ltp":13.5,"tv":46.09,"id":40752182}]}]}
{"op":"mcm","clk":"4216145340","pt":1631548522817,"mc":[{"id":"1.187605875","rc":[{"batb":[[0,190,4.74],[1,1.41,16.2],[2,1.4,767.39]],"batl":[[0,990,3.94]],"ltp":13.5,"tv":46.09,"id":40752182}]}]}
{"op":"mcm","clk":"4216146397","pt":1631548535673,"mc":[{"id":"1.187605875","rc":[{"batb":[[0,1.41,16.2],[1,1.4,767.39],[2,1.01,7]],"batl":[[0,990,0.01]],"ltp":13.5,"tv":46.09,"id":40752182}]}]}
{"op":"mcm","clk":"4216148205","pt":1631548556907,"mc":[{"id":"1.187605875","rc":[{"batl":[[0,1.01,17.05]],"ltp":1.01,"tv":2145.34,"id":11214864}]}]}
{"op":"mcm","clk":"4216148337","pt":1631548558470,"mc":[{"id":"1.187605875","marketDefinition":{"bspMarket":false,"turnInPlayEnabled":true,"persistenceEnabled":true,"marketBaseRate":5.0,"eventId":"30896916","eventTypeId":"2","numberOfWinners":1,"bettingType":"ODDS","marketType":"MATCH_ODDS","marketTime":"2021-09-13T14:30:00.000Z","suspendTime":"2021-09-13T14:30:00.000Z","bspReconciled":false,"complete":true,"inPlay":true,"crossMatching":true,"runnersVoidable":false,"numberOfActiveRunners":2,"betDelay":3,"status":"SUSPENDED","runners":[{"status":"ACTIVE","sortPriority":1,"id":11214864,"name":"A Pisareva"},{"status":"ACTIVE","sortPriority":2,"id":40752182,"name":"S Motlagh"}],"regulators":["MR_INT"],"countryCode":"US","discountAllowed":true,"timezone":"UTC","openDate":"2021-09-13T14:30:00.000Z","version":4030860977,"name":"Match Odds","eventName":"Al Pisareva v Motlagh"}}]}
{"op":"mcm","clk":"4216148835","pt":1631548563707,"mc":[{"id":"1.187605875","rc":[{"batb":[[0,1.01,7],[1,1.4,0],[2,1.01,0]],"ltp":13.5,"tv":46.09,"id":40752182}]}]}
{"op":"mcm","clk":"4216151661","pt":1631548595568,"mc":[{"id":"1.187605875","tv":0.0}]}
{"op":"mcm","clk":"4216151723","pt":1631548596427,"mc":[{"id":"1.187605875","marketDefinition":{"bspMarket":false,"turnInPlayEnabled":true,"persistenceEnabled":true,"marketBaseRate":5.0,"eventId":"30896916","eventTypeId":"2","numberOfWinners":1,"bettingType":"ODDS","marketType":"MATCH_ODDS","marketTime":"2021-09-13T14:30:00.000Z","suspendTime":"2021-09-13T14:30:00.000Z","bspReconciled":false,"complete":true,"inPlay":true,"crossMatching":false,"runnersVoidable":false,"numberOfActiveRunners":0,"betDelay":3,"status":"CLOSED","settledTime":"2021-09-13T15:56:34.000Z","runners":[{"status":"WINNER","sortPriority":1,"id":11214864,"name":"A Pisareva"},{"status":"LOSER","sortPriority":2,"id":40752182,"name":"S Motlagh"}],"regulators":["MR_INT"],"countryCode":"US","discountAllowed":true,"timezone":"UTC","openDate":"2021-09-13T14:30:00.000Z","version":4030861181,"name":"Match Odds","eventName":"Al Pisareva v Motlagh"}}]}
