{"op":"mcm","clk":"4222180501","pt":1631441187451,"mc":[{"id":"1.187552453","marketDefinition":{"bspMarket":false,"turnInPlayEnabled":true,"persistenceEnabled":true,"marketBaseRate":5.0,"eventId":"30895271","eventTypeId":"2","numberOfWinners":1,"bettingType":"ODDS","marketType":"MATCH_ODDS","marketTime":"2021-09-12T15:00:00.000Z","suspendTime":"2021-09-12T15:00:00.000Z","bspReconciled":false,"complete":true,"inPlay":false,"crossMatching":false,"runnersVoidable":false,"numberOfActiveRunners":2,"betDelay":0,"status":"OPEN","runners":[{"status":"ACTIVE","sortPriority":1,"id":9183341,"name":"E Silva"},{"status":"ACTIVE","sortPriority":2,"id":25079846,"name":"U Nebelska"}],"regulators":["MR_INT"],"countryCode":"GB","discountAllowed":true,"timezone":"GMT","openDate":"2021-09-12T15:00:00.000Z","version":4027702524,"name":"Match Odds","eventName":"E Silva v U Nebelska"},"rc":[{"batb":[[0,1.01,25]],"ltp":0.0,"tv":0.0,"id":9183341},{"batb":[[0,1.01,25]],"ltp":0.0,"tv":0.0,"id":25079846}]}]}
{"op":"mcm","clk":"4222240434","pt":1631441549261,"mc":[{"id":"1.187552453","rc":[{"batl":[[0,990,2.2]],"ltp":0.0,"tv":0.0,"id":9183341},{"batl":[[0,990,2.2]],"ltp":0.0,"tv":0.0,"id":25079846}]}]}
{"op":"mcm","clk":"4222268573","pt":1631441707572,"mc":[{"id":"1.187552453","rc":[{"batb":[[0,1.01,7]],"ltp":0.0,"tv":0.0,"id":9183341},{"batb":[[0,1.01,7]],"ltp":0.0,"tv":0.0,"id":25079846}]}]}
{"op":"mcm","clk":"4222513003","pt":1631443054400,"mc":[{"id":"1.187552453","rc":[{"batb":[[0,1.02,500],[1,1.01,7]],"ltp":0.0,"tv":0.0,"id":9183341},{"batb":[[0,12,10],[1,1.01,7]],"ltp":0.0,"tv":0.0,"id":25079846}]}]}
{"op":"mcm","clk":"4222513296","pt":1631443056238,"mc":[{"id":"1.187552453","marketDefinition":{"bspMarket":false,"turnInPlayEnabled":true,"persistenceEnabled":true,"marketBaseRate":5.0,"eventId":"30895271","eventTypeId":"2","numberOfWinners":1,"bettingType":"ODDS","marketType":"MATCH_ODDS","marketTime":"2021-09-12T15:00:00.000Z","suspendTime":"2021-09-12T15:00:00.000Z","bspReconciled":false,"complete":true,"inPlay":false,"crossMatching":true,"runnersVoidable":false,"numberOfActiveRunners":2,"betDelay":0,"status":"OPEN","runners":[{"status":"ACTIVE","sortPriority":1,"id":9183341,"name":"E Silva"},{"status":"ACTIVE","sortPriority":2,"id":25079846,"name":"U Nebelska"}],"regulators":["MR_INT"],"countryCode":"GB","discountAllowed":true,"timezone":"GMT","openDate":"2021-09-12T15:00:00.000Z","version":4027702524,"name":"Match Odds","eventName":"E Silva v U Nebelska"}}]}
{"op":"mcm","clk":"4222742284","pt":1631444490025,"mc":[{"id":"1.187552453","rc":[{"batb":[[1,1.01,12]],"ltp":0.0,"tv":0.0,"id":9183341},{"batb":[[1,1.01,12]],"ltp":0.0,"tv":0.0,"id":25079846}]}]}
{"op":"mcm","clk":"4222998123","pt":1631445811714,"mc":[{"id":"1.187552453","rc":[{"batb":[[0,1.02,608.45]],"ltp":0.0,"tv":0.0,"id":9183341},{"batb":[[1,1.02,108.45],[2,1.01,12]],"ltp":0.0,"tv":0.0,"id":25079846}]}]}
{"op":"mcm","clk":"4223334415","pt":1631447543368,"mc":[{"id":"1.187552453","rc":[{"batl":[[0,1.21,80],[1,990,2.2]],"ltp":0.0,"tv":0.0,"id":9183341}]}]}
{"op":"mcm","clk":"4223445592","pt":1631448195672,"mc":[{"id":"1.187552453","rc":[{"batl":[[0,1.09,43.98],[1,1.21,80],[2,990,2.2]],"ltp":0.0,"tv":0.0,"id":9183341}]}]}
{"op":"mcm","clk":"4223541898","pt":1631448707175,"mc":[{"id":"1.187552453","rc":[{"trd":[[1.02,909.82]],"batb":[[0,1.02,153.54]],"ltp":1.02,"tv":909.81,"id":9183341}],"tv":909.81}]}
{"op":"mcm","clk":"4223542419","pt":1631448710196,"mc":[{"id":"1.187552453","rc":[{"batb":[[0,1.02,108.45]],"ltp":1.02,"tv":909.81,"id":9183341}]}]}
{"op":"mcm","clk":"4223543741","pt":1631448717419,"mc":[{"id":"1.187552453","rc":[{"trd":[[1.03,249.38]],"batb":[[0,1.03,236.82],[1,1.02,108.45],[2,1.01,12]],"ltp":1.03,"tv":1159.2,"id":9183341}],"tv":1159.2}]}
{"op":"mcm","clk":"4223543779","pt":1631448717605,"mc":[{"id":"1.187552453","rc":[{"batb":[[0,1.05,2.89],[1,1.04,2.89],[2,1.03,236.82]],"ltp":1.03,"tv":1159.2,"id":9183341}]}]}
{"op":"mcm","clk":"4223544026","pt":1631448718922,"mc":[{"id":"1.187552453","rc":[{"batb":[[0,1.04,2.89],[1,1.03,236.82],[2,1.02,108.45]],"ltp":1.03,"tv":1159.2,"id":9183341}]}]}
{"op":"mcm","clk":"4223544427","pt":1631448721016,"mc":[{"id":"1.187552453","rc":[{"batb":[[1,1.02,108.45],[2,1.01,12]],"ltp":1.03,"tv":1159.2,"id":9183341}]}]}
{"op":"mcm","clk":"4223544873","pt":1631448723410,"mc":[{"id":"1.187552453","rc":[{"batb":[[1,1.01,12],[2,1.01,0]],"ltp":1.03,"tv":1159.2,"id":9183341}]}]}
{"op":"mcm","clk":"4223544890","pt":1631448723504,"mc":[{"id":"1.187552453","rc":[{"batb":[[1,1.01,120.45]],"ltp":1.03,"tv":1159.2,"id":9183341}]}]}
{"op":"mcm","clk":"4223546037","pt":1631448730005,"mc":[{"id":"1.187552453","rc":[{"batl":[[0,1.08,118.92],[1,1.09,43.98],[2,1.21,80]],"ltp":1.03,"tv":1159.2,"id":9183341}]}]}
{"op":"mcm","clk":"4223546671","pt":1631448733544,"mc":[{"id":"1.187552453","rc":[{"batl":[[0,1.05,105.52],[1,1.08,118.92],[2,1.09,43.98]],"ltp":1.03,"tv":1159.2,"id":9183341}]}]}
{"op":"mcm","clk":"4223569355","pt":1631448848694,"mc":[{"id":"1.187552453","rc":[{"batl":[[0,190,48.37],[1,990,2.2]],"ltp":0.0,"tv":0.0,"id":25079846}]}]}
{"op":"mcm","clk":"4223584168","pt":1631448921844,"mc":[{"id":"1.187552453","rc":[{"batb":[[1,1.01,3536.63]],"ltp":1.03,"tv":1159.2,"id":9183341}]}]}
{"op":"mcm","clk":"4223585602","pt":1631448929265,"mc":[{"id":"1.187552453","rc":[{"trd":[[1.04,5.79]],"batb":[[0,1.01,3536.63],[1,1.01,0]],"batl":[[0,1.05,106.04]],"ltp":1.04,"tv":1164.98,"id":9183341}],"tv":1164.98}]}
{"op":"mcm","clk":"4223586532","pt":1631448934256,"mc":[{"id":"1.187552453","rc":[{"batl":[[0,1.05,105.52]],"ltp":1.04,"tv":1164.98,"id":9183341}]}]}
{"op":"mcm","clk":"4223588600","pt":1631448945171,"mc":[{"id":"1.187552453","rc":[{"batb":[[0,1.02,5.12],[1,1.01,3536.63]],"ltp":1.04,"tv":1164.98,"id":9183341}]}]}
{"op":"mcm","clk":"4223608339","pt":1631449048339,"mc":[{"id":"1.187552453","rc":[{"batb":[[0,1.02,9.36]],"batl":[[0,1.04,3.13],[1,1.05,105.52],[2,1.08,118.92]],"ltp":1.04,"tv":1164.98,"id":9183341}]}]}
{"op":"mcm","clk":"4223676850","pt":1631449453453,"mc":[{"id":"1.187552453","rc":[{"batl":[[1,1.08,118.92],[2,1.09,43.98]],"ltp":1.04,"tv":1164.98,"id":9183341}]}]}
{"op":"mcm","clk":"4223676866","pt":1631449453555,"mc":[{"id":"1.187552453","rc":[{"batl":[[0,1.04,108.65]],"ltp":1.04,"tv":1164.98,"id":9183341}]}]}
{"op":"mcm","clk":"4223787969","pt":1631450103938,"mc":[{"id":"1.187552453","rc":[{"batb":[[0,1.02,4.24]],"ltp":1.04,"tv":1164.98,"id":9183341}]}]}
{"op":"mcm","clk":"4223842700","pt":1631450392880,"mc":[{"id":"1.187552453","rc":[{"batb":[[1,1.01,120.45]],"ltp":1.04,"tv":1164.98,"id":9183341}]}]}
{"op":"mcm","clk":"4224086213","pt":1631451677560,"mc":[{"id":"1.187552453","rc":[{"batl":[[2,1000,0.01]],"ltp":0.0,"tv":0.0,"id":25079846}]}]}
{"op":"mcm","clk":"4224372944","pt":1631452990040,"mc":[{"id":"1.187552453","rc":[{"batb":[[1,1.01,3536.63]],"ltp":1.04,"tv":1164.98,"id":9183341}]}]}
{"op":"mcm","clk":"4224422012","pt":1631453233040,"mc":[{"id":"1.187552453","rc":[{"batl":[[1,1.07,43.98],[2,1.08,118.92]],"ltp":1.04,"tv":1164.98,"id":9183341}]}]}
{"op":"mcm","clk":"4224819799","pt":1631455393947,"mc":[{"id":"1.187552453","rc":[{"trd":[[1.02,918.3]],"batb":[[0,1.01,3536.63],[1,1.01,0]],"batl":[[0,1.02,5913.62],[1,1.04,108.65],[2,1.07,43.98]],"ltp":1.02,"tv":1173.46,"id":9183341}],"tv":1173.46}]}
{"op":"mcm","clk":"4224982060","pt":1631456208378,"mc":[{"id":"1.187552453","rc":[{"trd":[[1.02,958.78]],"batl":[[0,1.02,5893.38]],"ltp":1.02,"tv":1213.94,"id":9183341}],"tv":1213.94}]}
{"op":"mcm","clk":"4225019061","pt":1631456340652,"mc":[{"id":"1.187552453","rc":[{"batb":[[0,1.01,4390.67]],"ltp":1.02,"tv":1213.94,"id":9183341}]}]}
{"op":"mcm","clk":"4225059535","pt":1631456543623,"mc":[{"id":"1.187552453","rc":[{"batb":[[0,55,7.6],[1,12,10],[2,1.02,108.45]],"ltp":0.0,"tv":0.0,"id":25079846}]}]}
{"op":"mcm","clk":"4225353709","pt":1631458010726,"mc":[{"id":"1.187552453","rc":[{"batb":[[0,1.01,4402.16]],"batl":[[1,1.04,120.14]],"ltp":1.02,"tv":1213.94,"id":9183341}]}]}
{"op":"mcm","clk":"4225388648","pt":1631458208994,"mc":[{"id":"1.187552453","rc":[{"batb":[[1,15.5,10.34],[2,12,10]],"ltp":0.0,"tv":0.0,"id":25079846}]}]}
{"op":"mcm","clk":"4225388806","pt":1631458209875,"mc":[{"id":"1.187552453","rc":[{"batl":[[0,1.04,120.14],[1,1.07,43.98],[2,1.08,118.92]],"ltp":1.02,"tv":1213.94,"id":9183341}]}]}
{"op":"mcm","clk":"4225389047","pt":1631458211090,"mc":[{"id":"1.187552453","rc":[{"trd":[[1.01,8804.54]],"batl":[[0,1.01,1490.99],[1,1.04,120.14],[2,1.07,43.98]],"ltp":1.01,"tv":10018.49,"id":9183341}],"tv":10018.49}]}
{"op":"mcm","clk":"4225414462","pt":1631458356860,"mc":[{"id":"1.187552453","rc":[{"batl":[[1,1.03,4184.82],[2,1.04,120.14]],"ltp":1.01,"tv":10018.49,"id":9183341}]}]}
{"op":"mcm","clk":"4225462998","pt":1631458636562,"mc":[{"id":"1.187552453","rc":[{"batl":[[1,1.04,120.14],[2,1.07,54.77]],"ltp":1.01,"tv":10018.49,"id":9183341}]}]}
{"op":"mcm","clk":"4225465608","pt":1631458651429,"mc":[{"id":"1.187552453","rc":[{"batl":[[1,1.02,2135.11],[2,1.04,120.14]],"ltp":1.01,"tv":10018.49,"id":9183341}]}]}
{"op":"mcm","clk":"4225468945","pt":1631458670859,"mc":[{"id":"1.187552453","rc":[{"batl":[[2,1.03,1964.3]],"ltp":1.01,"tv":10018.49,"id":9183341}]}]}
{"op":"mcm","clk":"4225503211","pt":1631458867084,"mc":[{"id":"1.187552453","marketDefinition":{"bspMarket":false,"turnInPlayEnabled":true,"persistenceEnabled":true,"marketBaseRate":5.0,"eventId":"30895271","eventTypeId":"2","numberOfWinners":1,"bettingType":"ODDS","marketType":"MATCH_ODDS","marketTime":"2021-09-12T15:00:00.000Z","suspendTime":"2021-09-12T15:00:00.000Z","bspReconciled":false,"complete":true,"inPlay":true,"crossMatching":true,"runnersVoidable":false,"numberOfActiveRunners":2,"betDelay":5,"status":"OPEN","runners":[{"status":"ACTIVE","sortPriority":1,"id":9183341,"name":"E Silva"},{"status":"ACTIVE","sortPriority":2,"id":25079846,"name":"U Nebelska"}],"regulators":["MR_INT"],"countryCode":"GB","discountAllowed":true,"timezone":"GMT","openDate":"2021-09-12T15:00:00.000Z","version":4028769862,"name":"Match Odds","eventName":"E Silva v U Nebelska"},"rc":[{"batl":[[0,1.02,2135.11],[1,1.03,1964.3],[2,1.07,10.8]],"ltp":1.01,"tv":10018.49,"id":9183341},{"batb":[[0,1.01,12],[1,15.5,0],[2,12,0]],"ltp":0.0,"tv":0.0,"id":25079846}]}]}
{"op":"mcm","clk":"4225527223","pt":1631458989002,"mc":[{"id":"1.187552453","rc":[{"batl":[[1,1.07,10.8],[2,1.21,80]],"ltp":1.01,"tv":10018.49,"id":9183341}]}]}
{"op":"mcm","clk":"4225530347","pt":1631459005404,"mc":[{"id":"1.187552453","rc":[{"batb":[[0,75,17.08],[1,1.01,12]],"ltp":0.0,"tv":0.0,"id":25079846}]}]}
{"op":"mcm","clk":"4225559219","pt":1631459152344,"mc":[{"id":"1.187552453","rc":[{"batl":[[0,1.07,10.8],[1,1.21,80],[2,1.21,0]],"ltp":1.01,"tv":10018.49,"id":9183341},{"batb":[[0,1.01,12],[1,1.01,0]],"ltp":0.0,"tv":0.0,"id":25079846}]}]}
{"op":"mcm","clk":"4225566566","pt":1631459189499,"mc":[{"id":"1.187552453","rc":[{"batl":[[0,1.05,854.04],[1,1.07,10.8],[2,1.21,80]],"ltp":1.01,"tv":10018.49,"id":9183341}]}]}
{"op":"mcm","clk":"4225594424","pt":1631459333211,"mc":[{"id":"1.187552453","rc":[{"batl":[[0,1.02,427.02],[1,1.05,854.04],[2,1.07,10.8]],"ltp":1.01,"tv":10018.49,"id":9183341}]}]}
{"op":"mcm","clk":"4225595468","pt":1631459338518,"mc":[{"id":"1.187552453","rc":[{"batb":[[0,32,7.08],[1,1.01,12]],"ltp":0.0,"tv":0.0,"id":25079846}]}]}
{"op":"mcm","clk":"4225596392","pt":1631459343324,"mc":[{"id":"1.187552453","rc":[{"batb":[[0,1.01,12],[1,1.01,0]],"ltp":0.0,"tv":0.0,"id":25079846}]}]}
{"op":"mcm","clk":"4225597490","pt":1631459348412,"mc":[{"id":"1.187552453","rc":[{"batb":[[0,55,7.08],[1,1.01,12]],"ltp":0.0,"tv":0.0,"id":25079846}]}]}
{"op":"mcm","clk":"4225601693","pt":1631459370152,"mc":[{"id":"1.187552453","rc":[{"batb":[[0,65,17.08],[1,55,7.08],[2,1.01,12]],"ltp":0.0,"tv":0.0,"id":25079846}]}]}
{"op":"mcm","clk":"4225631355","pt":1631459523833,"mc":[{"id":"1.187552453","rc":[{"batb":[[0,55,7.08],[1,1.01,12],[2,1.01,0]],"ltp":0.0,"tv":0.0,"id":25079846}]}]}
{"op":"mcm","clk":"4225632408","pt":1631459528935,"mc":[{"id":"1.187552453","rc":[{"batb":[[0,75,17.08],[1,55,7.08],[2,1.01,12]],"ltp":0.0,"tv":0.0,"id":25079846}]}]}
{"op":"mcm","clk":"4225733206","pt":1631460015577,"mc":[{"id":"1.187552453","rc":[{"batb":[[0,55,7.08],[1,1.01,12],[2,1.01,0]],"ltp":0.0,"tv":0.0,"id":25079846}]}]}
{"op":"mcm","clk":"4225734294","pt":1631460020697,"mc":[{"id":"1.187552453","rc":[{"batb":[[0,80,17.08],[1,55,7.08],[2,1.01,12]],"ltp":0.0,"tv":0.0,"id":25079846}]}]}
{"op":"mcm","clk":"4225852649","pt":1631460695074,"mc":[{"id":"1.187552453","rc":[{"batb":[[0,55,7.08],[1,1.01,12],[2,1.01,0]],"ltp":0.0,"tv":0.0,"id":25079846}]}]}
{"op":"mcm","clk":"4225853690","pt":1631460700196,"mc":[{"id":"1.187552453","rc":[{"batb":[[0,65,17.08],[1,55,7.08],[2,1.01,12]],"ltp":0.0,"tv":0.0,"id":25079846}]}]}
{"op":"mcm","clk":"4225882882","pt":1631460865179,"mc":[{"id":"1.187552453","rc":[{"batb":[[0,55,7.08],[1,1.01,12],[2,1.01,0]],"ltp":0.0,"tv":0.0,"id":25079846}]}]}
{"op":"mcm","clk":"4226017728","pt":1631461608146,"mc":[{"id":"1.187552453","rc":[{"batb":[[0,80,4.27],[1,55,7.08],[2,1.01,12]],"ltp":0.0,"tv":0.0,"id":25079846}]}]}
{"op":"mcm","clk":"4226050894","pt":1631461745028,"mc":[{"id":"1.187552453","rc":[{"batb":[[0,55,7.08],[1,1.01,12],[2,1.01,0]],"ltp":0.0,"tv":0.0,"id":25079846}]}]}
{"op":"mcm","clk":"4226164682","pt":1631462427541,"mc":[{"id":"1.187552453","rc":[{"batb":[[0,75,17.08],[1,55,7.08],[2,1.01,12]],"ltp":0.0,"tv":0.0,"id":25079846}]}]}
{"op":"mcm","clk":"4226205841","pt":1631462646529,"mc":[{"id":"1.187552453","marketDefinition":{"bspMarket":false,"turnInPlayEnabled":true,"persistenceEnabled":true,"marketBaseRate":5.0,"eventId":"30895271","eventTypeId":"2","numberOfWinners":1,"bettingType":"ODDS","marketType":"MATCH_ODDS","marketTime":"2021-09-12T16:04:06.000Z","suspendTime":"2021-09-12T16:04:06.000Z","bspReconciled":false,"complete":true,"inPlay":true,"crossMatching":true,"runnersVoidable":false,"numberOfActiveRunners":2,"betDelay":5,"status":"OPEN","runners":[{"status":"ACTIVE","sortPriority":1,"id":9183341,"name":"E Silva"},{"status":"ACTIVE","sortPriority":2,"id":25079846,"name":"U Nebelska"}],"regulators":["MR_INT"],"countryCode":"GB","discountAllowed":true,"timezone":"GMT","openDate":"2021-09-12T15:00:00.000Z","version":4029032357,"name":"Match Odds","eventName":"E Silva v U Nebelska"}}]}
{"op":"mcm","clk":"4226206176","pt":1631462648540,"mc":[{"id":"1.187552453","marketDefinition":{"bspMarket":false,"turnInPlayEnabled":true,"persistenceEnabled":true,"marketBaseRate":5.0,"eventId":"30895271","eventTypeId":"2","numberOfWinners":1,"bettingType":"ODDS","marketType":"MATCH_ODDS","marketTime":"2021-09-12T16:04:06.000Z","suspendTime":"2021-09-12T16:04:06.000Z","bspReconciled":false,"complete":true,"inPlay":true,"crossMatching":true,"runnersVoidable":false,"numberOfActiveRunners":2,"betDelay":5,"status":"OPEN","runners":[{"status":"ACTIVE","sortPriority":1,"id":9183341,"name":"E Silva"},{"status":"ACTIVE","sortPriority":2,"id":25079846,"name":"U Nebelska"}],"regulators":["MR_INT"],"countryCode":"GB","discountAllowed":true,"timezone":"GMT","openDate":"2021-09-12T16:04:06.000Z","version":4029032357,"name":"Match Odds","eventName":"E Silva v U Nebelska"}}]}
{"op":"mcm","clk":"4226212230","pt":1631462683062,"mc":[{"id":"1.187552453","rc":[{"batl":[[0,1000,3.42]],"ltp":0.0,"tv":0.0,"id":25079846}]}]}
{"op":"mcm","clk":"4226212449","pt":1631462684253,"mc":[{"id":"1.187552453","rc":[{"batl":[[0,1000,1.71]],"ltp":0.0,"tv":0.0,"id":25079846}]}]}
{"op":"mcm","clk":"4226213432","pt":1631462689567,"mc":[{"id":"1.187552453","rc":[{"trd":[[75,3.42]],"batb":[[0,75,15.37]],"ltp":75.0,"tv":3.41,"id":25079846}],"tv":10021.9}]}
{"op":"mcm","clk":"4226221430","pt":1631462733604,"mc":[{"id":"1.187552453","rc":[{"batl":[[0,1000,3.42]],"ltp":75.0,"tv":3.41,"id":25079846}]}]}
{"op":"mcm","clk":"4226222680","pt":1631462740534,"mc":[{"id":"1.187552453","rc":[{"trd":[[75,6.83]],"batb":[[0,75,13.66]],"ltp":75.0,"tv":6.83,"id":25079846}],"tv":10025.32}]}
{"op":"mcm","clk":"4226250241","pt":1631462873032,"mc":[{"id":"1.187552453","rc":[{"batl":[[0,1000,3.42]],"ltp":75.0,"tv":6.83,"id":25079846}]}]}
{"op":"mcm","clk":"4226250746","pt":1631462876147,"mc":[{"id":"1.187552453","rc":[{"batl":[[1,1.07,10.8],[2,1.1,854.04]],"ltp":1.01,"tv":10018.49,"id":9183341},{"batb":[[0,55,7.08],[1,1.01,12],[2,1.01,0]],"ltp":75.0,"tv":6.83,"id":25079846}]}]}
{"op":"mcm","clk":"4226251389","pt":1631462879764,"mc":[{"id":"1.187552453","rc":[{"batl":[[0,75,1.14]],"ltp":75.0,"tv":6.83,"id":25079846}]}]}
{"op":"mcm","clk":"4226251643","pt":1631462881256,"mc":[{"id":"1.187552453","rc":[{"batl":[[1,1.03,854.04],[2,1.07,10.8]],"ltp":1.01,"tv":10018.49,"id":9183341},{"batb":[[0,85,13.66],[1,55,7.08],[2,1.01,12]],"ltp":75.0,"tv":6.83,"id":25079846}]}]}
{"op":"mcm","clk":"4226282109","pt":1631463036425,"mc":[{"id":"1.187552453","rc":[{"batb":[[0,55,7.08],[1,1.01,12],[2,1.01,0]],"ltp":75.0,"tv":6.83,"id":25079846}]}]}
{"op":"mcm","clk":"4226283195","pt":1631463041513,"mc":[{"id":"1.187552453","rc":[{"batb":[[0,75,13.66],[1,55,7.08],[2,1.01,12]],"ltp":75.0,"tv":6.83,"id":25079846}]}]}
{"op":"mcm","clk":"4226302832","pt":1631463143818,"mc":[{"id":"1.187552453","rc":[{"batb":[[0,1.01,2.89]],"ltp":1.01,"tv":10018.49,"id":9183341}]}]}
{"op":"mcm","clk":"4226314188","pt":1631463203515,"mc":[{"id":"1.187552453","rc":[{"trd":[[1.02,964.56]],"batl":[[0,1.02,424.13]],"ltp":1.02,"tv":10024.27,"id":9183341}],"tv":10031.11}]}
{"op":"mcm","clk":"4226323665","pt":1631463253501,"mc":[{"id":"1.187552453","rc":[{"batb":[[0,55,7.08],[1,1.01,12],[2,1.01,0]],"ltp":75.0,"tv":6.83,"id":25079846}]}]}
{"op":"mcm","clk":"4226324575","pt":1631463258621,"mc":[{"id":"1.187552453","rc":[{"batb":[[0,85,13.66],[1,55,7.08],[2,1.01,12]],"ltp":75.0,"tv":6.83,"id":25079846}]}]}
{"op":"mcm","clk":"4226373486","pt":1631463512774,"mc":[{"id":"1.187552453","rc":[{"batl":[[0,1000,3.42]],"ltp":75.0,"tv":6.83,"id":25079846}]}]}
{"op":"mcm","clk":"4226374786","pt":1631463519372,"mc":[{"id":"1.187552453","rc":[{"trd":[[85,3.01]],"batb":[[0,85,12.16]],"ltp":85.0,"tv":9.83,"id":25079846}],"tv":10034.11}]}
{"op":"mcm","clk":"4226378951","pt":1631463540101,"mc":[{"id":"1.187552453","rc":[{"trd":[[1.02,1306.18]],"batl":[[0,1.02,253.32]],"ltp":1.02,"tv":10365.89,"id":9183341}],"tv":10375.73}]}
{"op":"mcm","clk":"4226379521","pt":1631463543307,"mc":[{"id":"1.187552453","rc":[{"batl":[[0,1000,3.42]],"ltp":85.0,"tv":9.83,"id":25079846}]}]}
{"op":"mcm","clk":"4226380873","pt":1631463550020,"mc":[{"id":"1.187552453","rc":[{"trd":[[85,5.02]],"batb":[[0,85,11.15]],"ltp":85.0,"tv":11.85,"id":25079846}],"tv":10377.74}]}
{"op":"mcm","clk":"4226383725","pt":1631463565413,"mc":[{"id":"1.187552453","rc":[{"batb":[[0,55,7.08],[1,1.01,12],[2,1.01,0]],"ltp":85.0,"tv":11.85,"id":25079846}]}]}
{"op":"mcm","clk":"4226384353","pt":1631463568808,"mc":[{"id":"1.187552453","rc":[{"batl":[[0,85,2.64]],"ltp":85.0,"tv":11.85,"id":25079846}]}]}
{"op":"mcm","clk":"4226384658","pt":1631463570528,"mc":[{"id":"1.187552453","rc":[{"batb":[[0,75,11.15],[1,55,7.08],[2,1.01,12]],"ltp":85.0,"tv":11.85,"id":25079846}]}]}
{"op":"mcm","clk":"4226386725","pt":1631463580870,"mc":[{"id":"1.187552453","rc":[{"trd":[[75,12.11]],"batb":[[0,75,8.51]],"ltp":75.0,"tv":17.13,"id":25079846}],"tv":10383.02}]}
{"op":"mcm","clk":"4226397137","pt":1631463636629,"mc":[{"id":"1.187552453","rc":[{"batb":[[0,55,7.08],[1,1.01,12],[2,1.01,0]],"ltp":75.0,"tv":17.13,"id":25079846}]}]}
{"op":"mcm","clk":"4226398034","pt":1631463641722,"mc":[{"id":"1.187552453","rc":[{"batb":[[0,85,8.51],[1,55,7.08],[2,1.01,12]],"ltp":75.0,"tv":17.13,"id":25079846}]}]}
{"op":"mcm","clk":"4226409968","pt":1631463708088,"mc":[{"id":"1.187552453","rc":[{"trd":[[1.02,1406.18]],"batl":[[0,1.02,203.31]],"ltp":1.02,"tv":10465.89,"id":9183341}],"tv":10483.03}]}
{"op":"mcm","clk":"4226412975","pt":1631463725792,"mc":[{"id":"1.187552453","rc":[{"batl":[[0,1000,3.42]],"ltp":75.0,"tv":17.13,"id":25079846}]}]}
{"op":"mcm","clk":"4226414128","pt":1631463732114,"mc":[{"id":"1.187552453","rc":[{"trd":[[85,9.04]],"batb":[[0,85,6.51]],"ltp":85.0,"tv":21.14,"id":25079846}],"tv":10487.04}]}
{"op":"mcm","clk":"4226421579","pt":1631463782959,"mc":[{"id":"1.187552453","rc":[{"batb":[[0,55,7.08],[1,1.01,12],[2,1.01,0]],"ltp":85.0,"tv":21.14,"id":25079846}]}]}
{"op":"mcm","clk":"4226422285","pt":1631463787980,"mc":[{"id":"1.187552453","rc":[{"batb":[[0,70,6.51],[1,55,7.08],[2,1.01,12]],"ltp":85.0,"tv":21.14,"id":25079846}]}]}
{"op":"mcm","clk":"4226426737","pt":1631463817390,"mc":[{"id":"1.187552453","rc":[{"batl":[[0,1000,1.22]],"ltp":85.0,"tv":21.14,"id":25079846}]}]}
{"op":"mcm","clk":"4226427538","pt":1631463822708,"mc":[{"id":"1.187552453","rc":[{"trd":[[70,2.44]],"batb":[[0,70,5.29]],"ltp":70.0,"tv":23.58,"id":25079846}],"tv":10489.48}]}
{"op":"mcm","clk":"4226431455","pt":1631463847670,"mc":[{"id":"1.187552453","rc":[{"batl":[[0,1000,3.42]],"ltp":70.0,"tv":23.58,"id":25079846}]}]}
{"op":"mcm","clk":"4226432378","pt":1631463853991,"mc":[{"id":"1.187552453","rc":[{"trd":[[70,4.89]],"batb":[[0,70,4.07]],"ltp":70.0,"tv":26.03,"id":25079846}],"tv":10491.93}]}
{"op":"mcm","clk":"4226432533","pt":1631463855107,"mc":[{"id":"1.187552453","rc":[{"batb":[[2,1.02,14.46]],"ltp":70.0,"tv":26.03,"id":25079846}]}]}
{"op":"mcm","clk":"4226434056","pt":1631463864328,"mc":[{"id":"1.187552453","rc":[{"batb":[[1,1.02,14.46],[2,1.01,12]],"ltp":70.0,"tv":26.03,"id":25079846}]}]}
{"op":"mcm","clk":"4226436627","pt":1631463879610,"mc":[{"id":"1.187552453","rc":[{"batl":[[0,1000,3.42]],"ltp":70.0,"tv":26.03,"id":25079846}]}]}
{"op":"mcm","clk":"4226437639","pt":1631463885893,"mc":[{"id":"1.187552453","rc":[{"trd":[[70,7.33]],"batb":[[0,70,2.84]],"ltp":70.0,"tv":28.47,"id":25079846}],"tv":10494.37}]}
{"op":"mcm","clk":"4226441281","pt":1631463910156,"mc":[{"id":"1.187552453","rc":[{"batl":[[0,1000,3.42]],"ltp":70.0,"tv":28.47,"id":25079846}]}]}
{"op":"mcm","clk":"4226442231","pt":1631463916466,"mc":[{"id":"1.187552453","rc":[{"trd":[[70,9.77]],"batb":[[0,70,1.62]],"ltp":70.0,"tv":30.91,"id":25079846}],"tv":10496.81}]}
{"op":"mcm","clk":"4226445234","pt":1631463936901,"mc":[{"id":"1.187552453","rc":[{"batb":[[0,1.02,14.46],[1,1.01,12],[2,1.01,0]],"ltp":70.0,"tv":30.91,"id":25079846}]}]}
{"op":"mcm","clk":"4226446572","pt":1631463945803,"mc":[{"id":"1.187552453","rc":[{"batl":[[1,1.07,10.8],[2,1.1,854.04]],"ltp":1.02,"tv":10465.89,"id":9183341}]}]}
{"op":"mcm","clk":"4226447327","pt":1631463950900,"mc":[{"id":"1.187552453","rc":[{"batl":[[0,1.02,1057.36]],"ltp":1.02,"tv":10465.89,"id":9183341}]}]}
{"op":"mcm","clk":"4226449736","pt":1631463966903,"mc":[{"id":"1.187552453","rc":[{"batl":[[2,1.2,200.82]],"ltp":1.02,"tv":10465.89,"id":9183341}]}]}
{"op":"mcm","clk":"4226452751","pt":1631463987362,"mc":[{"id":"1.187552453","rc":[{"batb":[[0,70,8.54],[1,1.02,14.46],[2,1.01,12]],"ltp":70.0,"tv":30.91,"id":25079846}]}]}
{"op":"mcm","clk":"4226465338","pt":1631464072504,"mc":[{"id":"1.187552453","rc":[{"batb":[[0,1.02,14.46],[1,1.01,12],[2,1.01,0]],"ltp":70.0,"tv":30.91,"id":25079846}]}]}
{"op":"mcm","clk":"4226466068","pt":1631464077591,"mc":[{"id":"1.187552453","rc":[{"batb":[[0,85,8.54],[1,1.02,14.46],[2,1.01,12]],"ltp":70.0,"tv":30.91,"id":25079846}]}]}
{"op":"mcm","clk":"4226470488","pt":1631464107830,"mc":[{"id":"1.187552453","rc":[{"batl":[[2,1.19,436.42]],"ltp":1.02,"tv":10465.89,"id":9183341}]}]}
{"op":"mcm","clk":"4226475019","pt":1631464139770,"mc":[{"id":"1.187552453","rc":[{"batl":[[0,1.01,837.38],[1,1.02,1057.36],[2,1.07,10.8]],"ltp":1.02,"tv":10465.89,"id":9183341}]}]}
{"op":"mcm","clk":"4226488288","pt":1631464231270,"mc":[{"id":"1.187552453","rc":[{"trd":[[1.01,8807.96]],"batl":[[0,1.01,835.67]],"ltp":1.01,"tv":10469.31,"id":9183341}],"tv":10500.23}]}
{"op":"mcm","clk":"4226492790","pt":1631464263230,"mc":[{"id":"1.187552453","rc":[{"trd":[[1.01,8811.38]],"batl":[[0,1.01,833.96]],"ltp":1.01,"tv":10472.73,"id":9183341}],"tv":10503.64}]}
{"op":"mcm","clk":"4226508149","pt":1631464370948,"mc":[{"id":"1.187552453","rc":[{"batl":[[0,1000,3.42]],"ltp":70.0,"tv":30.91,"id":25079846}]}]}
{"op":"mcm","clk":"4226508671","pt":1631464374854,"mc":[{"id":"1.187552453","rc":[{"trd":[[1.01,8814.79]],"batl":[[0,1.01,832.26]],"ltp":1.01,"tv":10476.14,"id":9183341}],"tv":10507.06}]}
{"op":"mcm","clk":"4226508985","pt":1631464377462,"mc":[{"id":"1.187552453","rc":[{"trd":[[1.01,8983.91]],"batl":[[0,1.01,663.14]],"ltp":1.01,"tv":10645.26,"id":9183341},{"trd":[[100,1.71]],"ltp":100.0,"tv":32.62,"id":25079846}],"tv":10677.89}]}
{"op":"mcm","clk":"4226512731","pt":1631464404889,"mc":[{"id":"1.187552453","rc":[{"batl":[[0,1000,3.42]],"ltp":100.0,"tv":32.62,"id":25079846}]}]}
{"op":"mcm","clk":"4226513764","pt":1631464412201,"mc":[{"id":"1.187552453","rc":[{"trd":[[1.01,9153.03]],"batl":[[0,1.01,494.02]],"ltp":1.01,"tv":10814.38,"id":9183341},{"trd":[[100,3.42]],"ltp":100.0,"tv":34.33,"id":25079846}],"tv":10848.71}]}
{"op":"mcm","clk":"4226516139","pt":1631464429014,"mc":[{"id":"1.187552453","rc":[{"batl":[[1,1.07,10.8],[2,1.19,436.42]],"ltp":1.01,"tv":10814.38,"id":9183341},{"batb":[[0,1.02,14.46],[1,1.01,12],[2,1.01,0]],"ltp":100.0,"tv":34.33,"id":25079846}]}]}
{"op":"mcm","clk":"4226524186","pt":1631464481237,"mc":[{"id":"1.187552453","rc":[{"batl":[[1,1.05,2265.78],[2,1.07,10.8]],"ltp":1.01,"tv":10814.38,"id":9183341}]}]}
{"op":"mcm","clk":"4226528020","pt":1631464506213,"mc":[{"id":"1.187552453","rc":[{"batl":[[0,1.01,1091.85]],"ltp":1.01,"tv":10814.38,"id":9183341}]}]}
{"op":"mcm","clk":"4226546139","pt":1631464623210,"mc":[{"id":"1.187552453","rc":[{"batl":[[0,1.01,494.02],[1,1.07,10.8],[2,1.19,436.42]],"ltp":1.01,"tv":10814.38,"id":9183341}]}]}
{"op":"mcm","clk":"4226556830","pt":1631464693405,"mc":[{"id":"1.187552453","rc":[{"batb":[[0,150,12.81],[1,1.02,14.46],[2,1.01,12]],"ltp":100.0,"tv":34.33,"id":25079846}]}]}
{"op":"mcm","clk":"4226561788","pt":1631464726243,"mc":[{"id":"1.187552453","rc":[{"batl":[[0,1.01,921.04]],"ltp":1.01,"tv":10814.38,"id":9183341}]}]}
{"op":"mcm","clk":"4226575220","pt":1631464813586,"mc":[{"id":"1.187552453","rc":[{"batl":[[0,1.01,494.02]],"ltp":1.01,"tv":10814.38,"id":9183341}]}]}
{"op":"mcm","clk":"4226575958","pt":1631464818798,"mc":[{"id":"1.187552453","rc":[{"batb":[[0,1.02,14.46],[1,1.01,12],[2,1.01,0]],"ltp":100.0,"tv":34.33,"id":25079846}]}]}
{"op":"mcm","clk":"4226576729","pt":1631464823868,"mc":[{"id":"1.187552453","rc":[{"batb":[[0,170,12.81],[1,1.02,14.46],[2,1.01,12]],"ltp":100.0,"tv":34.33,"id":25079846}]}]}
{"op":"mcm","clk":"4226585955","pt":1631464887966,"mc":[{"id":"1.187552453","rc":[{"batb":[[0,1.02,14.46],[1,1.01,12],[2,1.01,0]],"ltp":100.0,"tv":34.33,"id":25079846}]}]}
{"op":"mcm","clk":"4226586706","pt":1631464893022,"mc":[{"id":"1.187552453","rc":[{"batb":[[0,200,12.81],[1,1.02,14.46],[2,1.01,12]],"ltp":100.0,"tv":34.33,"id":25079846}]}]}
{"op":"mcm","clk":"4226594421","pt":1631464948006,"mc":[{"id":"1.187552453","rc":[{"batb":[[0,1.02,14.46],[1,1.01,12],[2,1.01,0]],"ltp":100.0,"tv":34.33,"id":25079846}]}]}
{"op":"mcm","clk":"4226595962","pt":1631464958979,"mc":[{"id":"1.187552453","rc":[{"batl":[[0,1.01,694.02]],"ltp":1.01,"tv":10814.38,"id":9183341}]}]}
{"op":"mcm","clk":"4226597083","pt":1631464967741,"mc":[{"id":"1.187552453","rc":[{"batb":[[0,300,9.39],[1,1.02,14.46],[2,1.01,12]],"ltp":100.0,"tv":34.33,"id":25079846}]}]}
{"op":"mcm","clk":"4226600821","pt":1631464995858,"mc":[{"id":"1.187552453","rc":[{"batl":[[0,1.01,887.51]],"ltp":1.01,"tv":10814.38,"id":9183341}]}]}
{"op":"mcm","clk":"4226611768","pt":1631465069115,"mc":[{"id":"1.187552453","rc":[{"batb":[[0,1.02,14.46],[1,1.01,12],[2,1.01,0]],"ltp":100.0,"tv":34.33,"id":25079846}]}]}
{"op":"mcm","clk":"4226612530","pt":1631465074245,"mc":[{"id":"1.187552453","rc":[{"batb":[[0,200,9.39],[1,1.02,14.46],[2,1.01,12]],"ltp":100.0,"tv":34.33,"id":25079846}]}]}
{"op":"mcm","clk":"4226627257","pt":1631465171043,"mc":[{"id":"1.187552453","rc":[{"batb":[[0,1.02,14.46],[1,1.01,12],[2,1.01,0]],"ltp":100.0,"tv":34.33,"id":25079846}]}]}
{"op":"mcm","clk":"4226628023","pt":1631465176174,"mc":[{"id":"1.187552453","rc":[{"batb":[[0,300,9.39],[1,1.02,14.46],[2,1.01,12]],"ltp":100.0,"tv":34.33,"id":25079846}]}]}
{"op":"mcm","clk":"4226690382","pt":1631465623725,"mc":[{"id":"1.187552453","marketDefinition":{"bspMarket":false,"turnInPlayEnabled":true,"persistenceEnabled":true,"marketBaseRate":5.0,"eventId":"30895271","eventTypeId":"2","numberOfWinners":1,"bettingType":"ODDS","marketType":"MATCH_ODDS","marketTime":"2021-09-12T16:04:06.000Z","suspendTime":"2021-09-12T16:04:06.000Z","bspReconciled":false,"complete":true,"inPlay":true,"crossMatching":true,"runnersVoidable":false,"numberOfActiveRunners":2,"betDelay":5,"status":"SUSPENDED","runners":[{"status":"ACTIVE","sortPriority":1,"id":9183341,"name":"E Silva"},{"status":"ACTIVE","sortPriority":2,"id":25079846,"name":"U Nebelska"}],"regulators":["MR_INT"],"countryCode":"GB","discountAllowed":true,"timezone":"GMT","openDate":"2021-09-12T16:04:06.000Z","version":4029180477,"name":"Match Odds","eventName":"E Silva v U Nebelska"}}]}
{"op":"mcm","clk":"4226691127","pt":1631465629739,"mc":[{"id":"1.187552453","tv":0.0}]}
{"op":"mcm","clk":"4226691249","pt":1631465630761,"mc":[{"id":"1.187552453","marketDefinition":{"bspMarket":false,"turnInPlayEnabled":true,"persistenceEnabled":true,"marketBaseRate":5.0,"eventId":"30895271","eventTypeId":"2","numberOfWinners":1,"bettingType":"ODDS","marketType":"MATCH_ODDS","marketTime":"2021-09-12T16:04:06.000Z","suspendTime":"2021-09-12T16:04:06.000Z","bspReconciled":false,"complete":true,"inPlay":true,"crossMatching":false,"runnersVoidable":false,"numberOfActiveRunners":0,"betDelay":5,"status":"CLOSED","settledTime":"2021-09-12T16:53:46.000Z","runners":[{"status":"WINNER","sortPriority":1,"id":9183341,"name":"E Silva"},{"status":"LOSER","sortPriority":2,"id":25079846,"name":"U Nebelska"}],"regulators":["MR_INT"],"countryCode":"GB","discountAllowed":true,"timezone":"GMT","openDate":"2021-09-12T16:04:06.000Z","version":4029181247,"name":"Match Odds","eventName":"E Silva v U Nebelska"}}]}
