{"op":"mcm","clk":"4231810496","pt":1631548262215,"mc":[{"id":"1.187560634","rc":[{"trd":[[1.71,91]],"batl":[[0,1.71,3.15]],"ltp":1.71,"tv":3734.51,"id":12343905}],"tv":7688.84}]}
{"op":"mcm","clk":"4231810820","pt":1631548265834,"mc":[{"id":"1.187560634","rc":[{"trd":[[1.71,97.29]],"batb":[[0,1.71,21.85],[1,1.7,9.98],[2,1.69,101.46]],"batl":[[0,1.75,115.7],[1,1.76,10.29],[2,1.77,110.97]],"ltp":1.71,"tv":3740.8,"id":12343905}],"tv":7695.14}]}
{"op":"mcm","clk":"4231810925","pt":1631548267133,"mc":[{"id":"1.187560634","rc":[{"batl":[[0,2.4,5.63],[1,2.42,55.45],[2,3.15,193.68]],"ltp":2.4,"tv":3954.33,"id":9629296}]}]}
{"op":"mcm","clk":"4231811024","pt":1631548268128,"mc":[{"id":"1.187560634","rc":[{"batb":[[0,2.18,34.56],[1,2.1,7.14],[2,2.02,43.03]],"ltp":2.4,"tv":3954.33,"id":9629296},{"batb":[[1,1.69,101.46],[2,1.67,181.45]],"ltp":1.71,"tv":3740.8,"id":12343905}]}]}
{"op":"mcm","clk":"4231811301","pt":1631548271638,"mc":[{"id":"1.187560634","rc":[{"batb":[[0,2.36,10.31],[1,2.18,34.56],[2,2.1,7.14]],"batl":[[0,2.42,55.45],[1,3.15,193.68],[2,3.25,4.8]],"ltp":2.4,"tv":3954.33,"id":9629296},{"batb":[[1,1.7,9.98],[2,1.69,101.46]],"ltp":1.71,"tv":3740.8,"id":12343905}]}]}
{"op":"mcm","clk":"4231811343","pt":1631548272052,"mc":[{"id":"1.187560634","rc":[{"batb":[[0,1.7,9.98],[1,1.69,101.46],[2,1.67,181.45]],"ltp":1.71,"tv":3740.8,"id":12343905}]}]}
{"op":"mcm","clk":"4231811554","pt":1631548274762,"mc":[{"id":"1.187560634","rc":[{"trd":[[2.36,11.26]],"batb":[[0,2.36,4.68]],"ltp":2.36,"tv":3965.59,"id":9629296}],"tv":7706.4}]}
{"op":"mcm","clk":"4231812459","pt":1631548284946,"mc":[{"id":"1.187560634","rc":[{"batb":[[0,2.18,34.56],[1,2.1,7.14],[2,2.02,43.03]],"ltp":2.36,"tv":3965.59,"id":9629296},{"batb":[[0,1.69,101.46],[1,1.67,181.45],[2,1.66,8.98]],"ltp":1.71,"tv":3740.8,"id":12343905}]}]}
{"op":"mcm","clk":"4231812702","pt":1631548288146,"mc":[{"id":"1.187560634","rc":[{"batb":[[0,2.2,13.96],[1,2.18,34.56],[2,2.1,7.14]],"batl":[[0,2.42,65.87]],"ltp":2.36,"tv":3965.59,"id":9629296},{"batl":[[0,1.74,9.41],[1,1.75,115.7],[2,1.76,10.29]],"ltp":1.71,"tv":3740.8,"id":12343905}]}]}
{"op":"mcm","clk":"4231813231","pt":1631548295646,"mc":[{"id":"1.187560634","rc":[{"batb":[[0,2.3,6.56],[1,2.2,13.96],[2,2.18,34.56]],"ltp":2.36,"tv":3965.59,"id":9629296}]}]}
{"op":"mcm","clk":"4231813245","pt":1631548295759,"mc":[{"id":"1.187560634","rc":[{"batb":[[1,2.18,34.56],[2,2.1,7.14]],"ltp":2.36,"tv":3965.59,"id":9629296}]}]}
{"op":"mcm","clk":"4231814603","pt":1631548317667,"mc":[{"id":"1.187560634","rc":[{"batb":[[1,2.1,7.14],[2,2.02,43.03]],"batl":[[0,3.15,193.68],[1,3.25,4.8],[2,3.25,0]],"ltp":2.36,"tv":3965.59,"id":9629296},{"batb":[[0,1.53,54.61],[1,1.3,198.87],[2,1.2,447.45]],"batl":[[0,1.76,1.71],[1,1.9,26.15],[2,3,5.2]],"ltp":1.71,"tv":3740.8,"id":12343905}]}]}
{"op":"mcm","clk":"4231814624","pt":1631548317929,"mc":[{"id":"1.187560634","rc":[{"batb":[[1,2.02,43.03],[2,1.95,28.88]],"ltp":2.36,"tv":3965.59,"id":9629296},{"batl":[[1,3,5.2],[2,3,0]],"ltp":1.71,"tv":3740.8,"id":12343905}]}]}
{"op":"mcm","clk":"4231814770","pt":1631548319660,"mc":[{"id":"1.187560634","rc":[{"batb":[[1,2.16,7.78],[2,2.12,7.79]],"batl":[[0,2.74,4.48],[1,2.9,4.25],[2,3.15,193.68]],"ltp":2.36,"tv":3965.59,"id":9629296},{"batb":[[0,1.58,38.56],[1,1.53,106.94],[2,1.3,198.87]],"batl":[[0,1.7,3.61],[1,1.76,1.71],[2,1.85,30.5]],"ltp":1.71,"tv":3740.8,"id":12343905}]}]}
{"op":"mcm","clk":"4231814827","pt":1631548320645,"mc":[{"id":"1.187560634","rc":[{"batb":[[1,2.12,7.79],[2,2.02,43.03]],"batl":[[0,2.9,4.25],[1,3.15,193.68],[2,3.25,4.8]],"ltp":2.36,"tv":3965.59,"id":9629296},{"batb":[[0,1.55,139.52],[1,1.54,84.11],[2,1.53,106.94]],"batl":[[2,1.86,77.45]],"ltp":1.71,"tv":3740.8,"id":12343905}]}]}
{"op":"mcm","clk":"4231815758","pt":1631548333286,"mc":[{"id":"1.187560634","rc":[{"batl":[[0,1.76,1.71],[1,1.86,77.45],[2,1.88,84.51]],"ltp":1.71,"tv":3740.8,"id":12343905}]}]}
{"op":"mcm","clk":"4231815953","pt":1631548336370,"mc":[{"id":"1.187560634","rc":[{"batl":[[0,1.75,3.61],[1,1.76,1.71],[2,1.86,77.45]],"ltp":1.71,"tv":3740.8,"id":12343905}]}]}
{"op":"mcm","clk":"4231816099","pt":1631548338706,"mc":[{"id":"1.187560634","rc":[{"batb":[[0,1.53,106.94],[1,1.3,198.87],[2,1.2,447.45]],"batl":[[2,1.89,24.5]],"ltp":1.71,"tv":3740.8,"id":12343905}]}]}
{"op":"mcm","clk":"4231816269","pt":1631548341588,"mc":[{"id":"1.187560634","rc":[{"batb":[[0,1.66,107.97],[1,1.65,64.87],[2,1.53,106.94]],"batl":[[0,1.72,110.44],[1,1.74,108.28],[2,1.75,3.61]],"ltp":1.71,"tv":3740.8,"id":12343905}]}]}
{"op":"mcm","clk":"4231816465","pt":1631548344415,"mc":[{"id":"1.187560634","rc":[{"batb":[[1,2.16,6.78],[2,2.12,7.79]],"batl":[[0,2.74,4.98],[1,2.9,4.25],[2,3.15,193.68]],"ltp":2.36,"tv":3965.59,"id":9629296},{"batb":[[0,1.58,40.06],[1,1.53,106.94],[2,1.3,198.87]],"batl":[[0,1.75,3.61],[1,1.76,1.71],[2,1.85,28.7]],"ltp":1.71,"tv":3740.8,"id":12343905}]}]}
{"op":"mcm","clk":"4231816493","pt":1631548344886,"mc":[{"id":"1.187560634","rc":[{"batb":[[1,2.12,7.79],[2,2.02,43.03]],"batl":[[0,2.9,4.25],[1,3.15,193.68],[2,3.25,4.8]],"ltp":2.36,"tv":3965.59,"id":9629296},{"batb":[[0,1.53,106.94],[1,1.3,198.87],[2,1.2,447.45]],"batl":[[2,1.89,24.5]],"ltp":1.71,"tv":3740.8,"id":12343905}]}]}
{"op":"mcm","clk":"4231816594","pt":1631548346712,"mc":[{"id":"1.187560634","rc":[{"batb":[[0,1.55,139.52],[1,1.54,84.11],[2,1.53,106.94]],"batl":[[2,1.86,77.45]],"ltp":1.71,"tv":3740.8,"id":12343905}]}]}
{"op":"mcm","clk":"4231816736","pt":1631548348493,"mc":[{"id":"1.187560634","rc":[{"batb":[[0,1.53,106.94],[1,1.3,198.87],[2,1.2,447.45]],"ltp":1.71,"tv":3740.8,"id":12343905}]}]}
{"op":"mcm","clk":"4231816782","pt":1631548349115,"mc":[{"id":"1.187560634","rc":[{"batl":[[1,3.25,4.8],[2,3.25,0]],"ltp":2.36,"tv":3965.59,"id":9629296}]}]}
{"op":"mcm","clk":"4231816962","pt":1631548351415,"mc":[{"id":"1.187560634","rc":[{"trd":[[2.3,21.36],[2.32,29.3]],"batb":[[0,2.12,7.79],[1,2.02,43.03],[2,1.95,28.88]],"batl":[[0,2.24,6.44],[1,2.26,42.84],[2,2.28,111.23]],"ltp":2.3,"tv":3982.72,"id":9629296},{"trd":[[1.75,271.03],[1.76,65.7]],"batb":[[0,1.8,79.32],[1,1.78,99.16],[2,1.53,106.94]],"batl":[[0,1.86,98.51],[1,1.88,84.51],[2,1.89,126.78]],"ltp":1.76,"tv":3746.12,"id":12343905}],"tv":7728.85}]}
{"op":"mcm","clk":"4231817012","pt":1631548352204,"mc":[{"id":"1.187560634","rc":[{"batb":[[2,1.77,32.63]],"batl":[[1,1.88,100.47],[2,1.89,134.76]],"ltp":1.76,"tv":3746.12,"id":12343905}]}]}
{"op":"mcm","clk":"4231817263","pt":1631548356015,"mc":[{"id":"1.187560634","rc":[{"trd":[[2.16,40.53]],"ltp":2.16,"tv":3988.94,"id":9629296},{"trd":[[1.86,189.76]],"batl":[[0,1.86,91.29]],"ltp":1.86,"tv":3753.34,"id":12343905}],"tv":7742.29}]}
{"op":"mcm","clk":"4231817405","pt":1631548357805,"mc":[{"id":"1.187560634","rc":[{"batb":[[1,2.08,7.81],[2,2.04,7.37]],"ltp":2.16,"tv":3988.94,"id":9629296}]}]}
{"op":"mcm","clk":"4231817799","pt":1631548362634,"mc":[{"id":"1.187560634","rc":[{"batb":[[0,1.95,28.88],[1,1.92,51.17],[2,1.82,424.02]],"batl":[[0,2.46,6.25],[1,3,216.62],[2,3.25,4.8]],"ltp":2.16,"tv":3988.94,"id":9629296},{"batb":[[0,1.69,38.21],[1,1.64,42.86],[2,1.3,198.87]],"batl":[[0,1.95,24.3],[1,3,5.2],[2,1.89,0]],"ltp":1.86,"tv":3753.34,"id":12343905}]}]}
{"op":"mcm","clk":"4231818022","pt":1631548365622,"mc":[{"id":"1.187560634","rc":[{"batb":[[0,2.08,9.06],[1,2.04,8.12],[2,1.95,28.88]],"batl":[[0,2.38,6.25],[1,2.46,6.25],[2,3,216.62]],"ltp":2.16,"tv":3988.94,"id":9629296},{"batb":[[0,1.73,33.13],[1,1.69,38.21],[2,1.64,42.86]],"batl":[[0,1.92,25.56],[1,1.95,24.3],[2,3,5.2]],"ltp":1.86,"tv":3753.34,"id":12343905}]}]}
{"op":"mcm","clk":"4231818058","pt":1631548366136,"mc":[{"id":"1.187560634","rc":[{"batb":[[0,2.04,8.12],[1,1.95,28.88],[2,1.92,51.17]],"batl":[[0,2.46,6.25],[1,3,216.62],[2,3.25,4.8]],"ltp":2.16,"tv":3988.94,"id":9629296},{"batb":[[0,1.69,38.21],[1,1.64,42.86],[2,1.3,198.87]],"batl":[[0,1.8,4]],"ltp":1.86,"tv":3753.34,"id":12343905}]}]}
{"op":"mcm","clk":"4231818148","pt":1631548367535,"mc":[{"id":"1.187560634","rc":[{"batb":[[0,1.77,80.12],[1,1.75,104.98],[2,1.69,38.21]],"batl":[[0,1.83,78.61],[1,1.85,88.87],[2,1.95,24.3]],"ltp":1.86,"tv":3753.34,"id":12343905}]}]}
{"op":"mcm","clk":"4231818272","pt":1631548369216,"mc":[{"id":"1.187560634","rc":[{"batl":[[0,2.38,5.75],[1,2.46,6.25],[2,3,216.62]],"ltp":2.16,"tv":3988.94,"id":9629296},{"batb":[[2,1.73,33.13]],"ltp":1.86,"tv":3753.34,"id":12343905}]}]}
{"op":"mcm","clk":"4231818367","pt":1631548370410,"mc":[{"id":"1.187560634","rc":[{"batl":[[0,2.46,6.25],[1,3,216.62],[2,3.25,4.8]],"ltp":2.16,"tv":3988.94,"id":9629296},{"batb":[[0,1.69,38.21],[1,1.64,42.86],[2,1.3,198.87]],"batl":[[0,1.95,24.3],[1,3,5.2],[2,1.95,0]],"ltp":1.86,"tv":3753.34,"id":12343905}]}]}
{"op":"mcm","clk":"4231818578","pt":1631548373625,"mc":[{"id":"1.187560634","rc":[{"batl":[[0,2.38,6.25],[1,2.46,6.25],[2,3,216.62]],"ltp":2.16,"tv":3988.94,"id":9629296},{"batb":[[0,1.73,30.13],[1,1.69,38.21],[2,1.66,110.75]],"batl":[[1,1.97,81.92],[2,1.99,71.03]],"ltp":1.86,"tv":3753.34,"id":12343905}]}]}
{"op":"mcm","clk":"4231818596","pt":1631548373932,"mc":[{"id":"1.187560634","rc":[{"batl":[[0,2.46,6.25],[1,3,216.62],[2,3.25,4.8]],"ltp":2.16,"tv":3988.94,"id":9629296},{"batb":[[0,1.69,38.21],[1,1.66,110.75],[2,1.65,64.87]],"ltp":1.86,"tv":3753.34,"id":12343905}]}]}
{"op":"mcm","clk":"4231818688","pt":1631548375549,"mc":[{"id":"1.187560634","rc":[{"batb":[[1,1.64,42.86],[2,1.3,198.87]],"ltp":1.86,"tv":3753.34,"id":12343905}]}]}
{"op":"mcm","clk":"4231818732","pt":1631548376437,"mc":[{"id":"1.187560634","rc":[{"batl":[[1,3.25,4.8],[2,3.25,0]],"ltp":2.16,"tv":3988.94,"id":9629296}]}]}
{"op":"mcm","clk":"4231818863","pt":1631548378659,"mc":[{"id":"1.187560634","rc":[{"batb":[[0,2.08,8.02],[1,2.04,8.12],[2,1.95,28.88]],"batl":[[0,2.12,23.77],[1,2.14,7.08],[2,2.16,112.81]],"ltp":2.16,"tv":3988.94,"id":9629296},{"batb":[[0,1.91,104.72],[1,1.9,75.28],[2,1.88,83.04]],"batl":[[2,1.98,90.31]],"ltp":1.86,"tv":3753.34,"id":12343905}]}]}
{"op":"mcm","clk":"4231818931","pt":1631548379552,"mc":[{"id":"1.187560634","rc":[{"batb":[[2,2,15]],"ltp":2.16,"tv":3988.94,"id":9629296}]}]}
{"op":"mcm","clk":"4231819216","pt":1631548383481,"mc":[{"id":"1.187560634","rc":[{"trd":[[2.08,82.34]],"batb":[[0,2.04,8.12],[1,2,15],[2,1.99,7.5]],"ltp":2.08,"tv":4004.98,"id":9629296}],"tv":7758.33}]}
{"op":"mcm","clk":"4231819409","pt":1631548386447,"mc":[{"id":"1.187560634","rc":[{"batb":[[1,2.02,8.74],[2,2,36.35]],"ltp":2.08,"tv":4004.98,"id":9629296},{"batl":[[1,1.97,105.75]],"ltp":1.86,"tv":3753.34,"id":12343905}]}]}
{"op":"mcm","clk":"4231819509","pt":1631548388165,"mc":[{"id":"1.187560634","rc":[{"trd":[[1.91,4.92]],"batb":[[0,1.91,102.26]],"ltp":1.91,"tv":3758.26,"id":12343905}],"tv":7763.25}]}
{"op":"mcm","clk":"4231819877","pt":1631548393392,"mc":[{"id":"1.187560634","rc":[{"batb":[[0,1.95,28.88],[1,1.85,29.19],[2,1.82,424.02]],"batl":[[0,2.82,234.71],[1,3.25,4.8],[2,2.16,0]],"ltp":2.08,"tv":4004.98,"id":9629296},{"batb":[[0,1.79,34.31],[1,1.76,33.55],[2,1.3,198.87]],"batl":[[0,2.02,8.75],[1,3,5.2],[2,1.98,0]],"ltp":1.91,"tv":3758.26,"id":12343905}]}]}
{"op":"mcm","clk":"4231820120","pt":1631548396604,"mc":[{"id":"1.187560634","rc":[{"batb":[[0,1.99,24.51],[1,1.95,28.88],[2,1.85,29.19]],"batl":[[0,2.28,6.34],[1,2.82,234.71],[2,3.25,4.8]],"ltp":2.08,"tv":4004.98,"id":9629296}]}]}
{"op":"mcm","clk":"4231820235","pt":1631548398160,"mc":[{"id":"1.187560634","rc":[{"batb":[[0,1.87,91.71],[1,1.85,87.45],[2,1.79,34.31]],"batl":[[0,1.94,67.15],[1,1.96,74.36],[2,2.02,8.75]],"ltp":1.91,"tv":3758.26,"id":12343905}]}]}
{"op":"mcm","clk":"4231820325","pt":1631548399557,"mc":[{"id":"1.187560634","rc":[{"batl":[[0,2.1,21.25],[1,2.28,6.34],[2,2.82,234.71]],"ltp":2.08,"tv":4004.98,"id":9629296},{"batb":[[0,1.9,18.86],[1,1.87,91.71],[2,1.85,87.45]],"batl":[[1,1.95,20.3],[2,1.96,74.36]],"ltp":1.91,"tv":3758.26,"id":12343905}]}]}
{"op":"mcm","clk":"4231820402","pt":1631548400594,"mc":[{"id":"1.187560634","rc":[{"batb":[[0,2,25.16],[1,1.99,24.51],[2,1.95,28.88]],"batl":[[0,2.22,6.25]],"ltp":2.08,"tv":4004.98,"id":9629296},{"batb":[[0,1.87,91.71],[1,1.85,87.45],[2,1.83,35.03]],"batl":[[1,1.96,74.36],[2,1.99,27.5]],"ltp":1.91,"tv":3758.26,"id":12343905}]}]}
{"op":"mcm","clk":"4231820431","pt":1631548401011,"mc":[{"id":"1.187560634","rc":[{"batb":[[0,1.99,24.51],[1,1.95,28.88],[2,1.85,29.19]],"batl":[[0,2.28,6.34],[1,2.82,234.71],[2,3.25,4.8]],"ltp":2.08,"tv":4004.98,"id":9629296},{"batb":[[2,1.79,34.31]],"batl":[[2,2.02,8.75]],"ltp":1.91,"tv":3758.26,"id":12343905}]}]}
{"op":"mcm","clk":"4231820605","pt":1631548403200,"mc":[{"id":"1.187560634","rc":[{"batl":[[0,1.94,68.05]],"ltp":1.91,"tv":3758.26,"id":12343905}]}]}
{"op":"mcm","clk":"4231820703","pt":1631548404503,"mc":[{"id":"1.187560634","rc":[{"batb":[[0,1.79,34.31],[1,1.76,33.55],[2,1.3,198.87]],"batl":[[0,2.02,9.65],[1,3,5.2],[2,2.02,0]],"ltp":1.91,"tv":3758.26,"id":12343905}]}]}
{"op":"mcm","clk":"4231820862","pt":1631548406483,"mc":[{"id":"1.187560634","rc":[{"batb":[[2,1.4,149.15]],"ltp":1.91,"tv":3758.26,"id":12343905}]}]}
{"op":"mcm","clk":"4231820921","pt":1631548407210,"mc":[{"id":"1.187560634","rc":[{"batb":[[1,1.78,100.83],[2,1.76,136.59]],"batl":[[1,2.06,92.31],[2,2.08,62.36]],"ltp":1.91,"tv":3758.26,"id":12343905}]}]}
{"op":"mcm","clk":"4231820972","pt":1631548407989,"mc":[{"id":"1.187560634","rc":[{"batl":[[1,3,5.2],[2,2.08,0]],"ltp":1.91,"tv":3758.26,"id":12343905}]}]}
{"op":"mcm","clk":"4231821136","pt":1631548410589,"mc":[{"id":"1.187560634","rc":[{"batb":[[0,2.2,6.18],[1,2.18,41.28],[2,2.16,20.64]],"batl":[[0,2.24,6.15],[1,2.28,6.34],[2,2.82,234.71]],"ltp":2.08,"tv":4004.98,"id":9629296},{"batb":[[2,1.76,274.82]],"batl":[[0,1.96,350.05],[1,2.02,8.75],[2,3,5.2]],"ltp":1.91,"tv":3758.26,"id":12343905}]}]}
{"op":"mcm","clk":"4231821237","pt":1631548411589,"mc":[{"id":"1.187560634","rc":[{"batb":[[1,2.18,13.76],[2,2.16,6.88]],"ltp":2.08,"tv":4004.98,"id":9629296},{"batb":[[2,1.76,291.86]],"batl":[[0,1.85,98.31],[1,1.87,85.88],[2,1.96,350.05]],"ltp":1.91,"tv":3758.26,"id":12343905}]}]}
{"op":"mcm","clk":"4231821605","pt":1631548416485,"mc":[{"id":"1.187560634","rc":[{"batl":[[2,1.96,349.15]],"ltp":1.91,"tv":3758.26,"id":12343905}]}]}
{"op":"mcm","clk":"4231821685","pt":1631548417627,"mc":[{"id":"1.187560634","rc":[{"batl":[[2,2.44,5.58]],"ltp":2.08,"tv":4004.98,"id":9629296},{"batl":[[2,1.94,26.75]],"ltp":1.91,"tv":3758.26,"id":12343905}]}]}
{"op":"mcm","clk":"4231821701","pt":1631548417830,"mc":[{"id":"1.187560634","rc":[{"trd":[[2.2,364.66]],"batb":[[0,2.2,4.01]],"ltp":2.2,"tv":4009.32,"id":9629296}],"tv":7767.58}]}
{"op":"mcm","clk":"4231821907","pt":1631548420431,"mc":[{"id":"1.187560634","rc":[{"batb":[[0,2.02,8.74],[1,1.95,28.88],[2,1.91,51.59]],"batl":[[0,2.52,5.51],[1,2.82,234.71],[2,3.25,4.8]],"ltp":2.2,"tv":4009.32,"id":9629296},{"batb":[[0,1.66,32.28],[1,1.61,45.55],[2,1.4,149.15]],"batl":[[0,1.98,29.25],[1,3,5.2],[2,1.94,0]],"ltp":1.91,"tv":3758.26,"id":12343905}]}]}
{"op":"mcm","clk":"4231822185","pt":1631548423621,"mc":[{"id":"1.187560634","rc":[{"batb":[[0,2.06,9.58],[1,2.02,8.74],[2,1.95,28.88]],"batl":[[0,2.44,5.58],[1,2.52,5.51],[2,2.82,234.71]],"ltp":2.2,"tv":4009.32,"id":9629296},{"batb":[[0,1.7,37.72],[1,1.66,32.28],[2,1.63,115.42]],"batl":[[0,1.94,23.75],[1,1.97,79.18],[2,1.98,29.25]],"ltp":1.91,"tv":3758.26,"id":12343905}]}]}
{"op":"mcm","clk":"4231822202","pt":1631548423833,"mc":[{"id":"1.187560634","rc":[{"batb":[[0,2.02,8.74],[1,1.95,28.88],[2,1.91,51.59]],"batl":[[0,2.52,5.51],[1,2.82,234.71],[2,3.25,4.8]],"ltp":2.2,"tv":4009.32,"id":9629296},{"batb":[[0,1.66,32.28],[1,1.63,115.42],[2,1.62,69.35]],"batl":[[0,1.97,79.18],[1,1.98,29.25],[2,1.99,71.03]],"ltp":1.91,"tv":3758.26,"id":12343905}]}]}
{"op":"mcm","clk":"4231822743","pt":1631548430450,"mc":[{"id":"1.187560634","rc":[{"batb":[[0,2.06,8.58],[1,2.02,8.74],[2,1.95,28.88]],"batl":[[0,2.44,6.33],[1,2.52,5.51],[2,2.82,234.71]],"ltp":2.2,"tv":4009.32,"id":9629296},{"batb":[[0,1.7,33.92],[1,1.66,32.28],[2,1.63,115.42]],"batl":[[0,1.94,25.25],[1,1.97,79.18],[2,1.98,29.25]],"ltp":1.91,"tv":3758.26,"id":12343905}]}]}
{"op":"mcm","clk":"4231822768","pt":1631548430726,"mc":[{"id":"1.187560634","rc":[{"batb":[[0,2.02,8.74],[1,1.95,28.88],[2,1.91,51.59]],"batl":[[0,2.52,5.51],[1,2.82,234.71],[2,3.25,4.8]],"ltp":2.2,"tv":4009.32,"id":9629296},{"batb":[[0,1.66,32.28],[1,1.63,115.42],[2,1.62,69.35]],"batl":[[0,1.97,79.18],[1,1.98,29.25],[2,1.99,71.03]],"ltp":1.91,"tv":3758.26,"id":12343905}]}]}
{"op":"mcm","clk":"4231823003","pt":1631548434119,"mc":[{"id":"1.187560634","rc":[{"batb":[[1,1.61,45.55],[2,1.4,149.15]],"batl":[[0,1.98,29.25],[1,3,5.2],[2,1.99,0]],"ltp":1.91,"tv":3758.26,"id":12343905}]}]}
{"op":"mcm","clk":"4231823086","pt":1631548435451,"mc":[{"id":"1.187560634","rc":[{"batl":[[1,3.25,4.8],[2,3.25,0]],"ltp":2.2,"tv":4009.32,"id":9629296}]}]}
{"op":"mcm","clk":"4231823255","pt":1631548437656,"mc":[{"id":"1.187560634","rc":[{"batl":[[0,2.44,6.33],[1,2.52,5.51],[2,3.25,4.8]],"ltp":2.2,"tv":4009.32,"id":9629296},{"batb":[[0,1.75,91.68],[1,1.73,109.19],[2,1.7,36.22]],"batl":[[0,1.81,76.67],[1,1.83,91.99],[2,1.98,29.25]],"ltp":1.91,"tv":3758.26,"id":12343905}]}]}
{"op":"mcm","clk":"4231823284","pt":1631548438064,"mc":[{"id":"1.187560634","rc":[{"batl":[[0,2.52,5.51],[1,3.25,4.8],[2,3.25,0]],"ltp":2.2,"tv":4009.32,"id":9629296},{"batb":[[0,1.66,32.28],[1,1.61,45.55],[2,1.4,149.15]],"batl":[[0,1.98,29.25],[1,3,5.2],[2,1.98,0]],"ltp":1.91,"tv":3758.26,"id":12343905}]}]}
{"op":"mcm","clk":"4231823469","pt":1631548440242,"mc":[{"id":"1.187560634","rc":[{"batl":[[1,3.15,203.39],[2,3.25,4.8]],"ltp":2.2,"tv":4009.32,"id":9629296}]}]}
{"op":"mcm","clk":"4231823582","pt":1631548441553,"mc":[{"id":"1.187560634","rc":[{"batb":[[1,1.63,115.42],[2,1.62,69.35]],"ltp":1.91,"tv":3758.26,"id":12343905}]}]}
{"op":"mcm","clk":"4231823695","pt":1631548443268,"mc":[{"id":"1.187560634","rc":[{"batl":[[0,2.5,6.78],[1,2.52,5.51],[2,2.6,89.01]],"ltp":2.2,"tv":4009.32,"id":9629296},{"batl":[[0,1.68,64.24],[1,1.69,71],[2,1.7,184.38]],"ltp":1.91,"tv":3758.26,"id":12343905}]}]}
{"op":"mcm","clk":"4231823761","pt":1631548444364,"mc":[{"id":"1.187560634","rc":[{"batb":[[0,2.3,29.95],[1,2.04,42.44],[2,2.02,8.74]],"ltp":2.2,"tv":4009.32,"id":9629296}]}]}
{"op":"mcm","clk":"4231824276","pt":1631548450562,"mc":[{"id":"1.187560634","rc":[{"batb":[[1,2.14,7.32],[2,2.06,8.08]],"ltp":2.2,"tv":4009.32,"id":9629296}]}]}
{"op":"mcm","clk":"4231825027","pt":1631548457667,"mc":[{"id":"1.187560634","rc":[{"trd":[[1.68,128.48]],"batb":[[0,1.68,80.76],[1,1.66,32.28],[2,1.63,67.6]],"batl":[[0,1.69,71],[1,1.7,67.04],[2,1.71,26.47]],"ltp":1.68,"tv":3886.74,"id":12343905}],"tv":7896.06}]}
{"op":"mcm","clk":"4231825136","pt":1631548458661,"mc":[{"id":"1.187560634","rc":[{"batb":[[0,2.04,42.44],[1,1.95,28.88],[2,1.92,400.77]],"batl":[[0,3.15,203.39],[1,3.25,8.38],[2,3.65,3.1]],"ltp":2.2,"tv":4009.32,"id":9629296},{"batb":[[1,1.6,5.47],[2,1.45,59.41]],"batl":[[0,1.93,28.5],[1,3,5.2],[2,1.71,0]],"ltp":1.68,"tv":3886.74,"id":12343905}]}]}
{"op":"mcm","clk":"4231825336","pt":1631548460862,"mc":[{"id":"1.187560634","rc":[{"batb":[[0,1.68,55.76]],"ltp":1.68,"tv":3886.74,"id":12343905}]}]}
{"op":"mcm","clk":"4231825450","pt":1631548461965,"mc":[{"id":"1.187560634","rc":[{"batb":[[0,2.06,8.58],[1,2.04,42.44],[2,1.95,28.88]],"batl":[[0,3.25,8.38],[1,3.65,3.1],[2,3.75,3.26]],"ltp":2.2,"tv":4009.32,"id":9629296}]}]}
{"op":"mcm","clk":"4231825599","pt":1631548463583,"mc":[{"id":"1.187560634","rc":[{"trd":[[1.68,240]],"batb":[[0,1.6,81.28],[1,1.59,74.04]],"batl":[[0,1.65,64.27],[1,1.66,63.03],[2,1.93,28.5]],"ltp":1.68,"tv":3998.26,"id":12343905}],"tv":8007.58}]}
{"op":"mcm","clk":"4231825852","pt":1631548466290,"mc":[{"id":"1.187560634","rc":[{"batl":[[1,3.65,176.04]],"ltp":2.2,"tv":4009.32,"id":9629296},{"batb":[[0,1.6,5.47],[1,1.45,59.41],[2,1.43,72.81]],"batl":[[0,1.93,28.5],[1,3,5.2],[2,1.93,0]],"ltp":1.68,"tv":3998.26,"id":12343905}]}]}
{"op":"mcm","clk":"4231826104","pt":1631548469463,"mc":[{"id":"1.187560634","rc":[{"batb":[[1,1.45,218.35],[2,1.44,110.49]],"ltp":1.68,"tv":3998.26,"id":12343905}]}]}
{"op":"mcm","clk":"4231826149","pt":1631548470184,"mc":[{"id":"1.187560634","rc":[{"batb":[[2,1.98,14.44]],"ltp":2.2,"tv":4009.32,"id":9629296}]}]}
{"op":"mcm","clk":"4231826179","pt":1631548470706,"mc":[{"id":"1.187560634","rc":[{"batl":[[1,3.65,3.1]],"ltp":2.2,"tv":4009.32,"id":9629296}]}]}
{"op":"mcm","clk":"4231826327","pt":1631548472481,"mc":[{"id":"1.187560634","rc":[{"batb":[[0,2.96,9.44],[1,2.9,72.41],[2,2.88,15.52]],"ltp":2.2,"tv":4009.32,"id":9629296},{"trd":[[1.6,10.94]],"batb":[[0,1.48,16.05],[2,1.44,342.99]],"batl":[[0,1.49,84.35],[1,1.5,91.76],[2,1.54,185.18]],"ltp":1.6,"tv":4009.2,"id":12343905}],"tv":8018.52}]}
{"op":"mcm","clk":"4231826410","pt":1631548473490,"mc":[{"id":"1.187560634","rc":[{"batl":[[0,3.15,4.76],[1,3.2,2.38],[2,3.25,7.18]],"ltp":2.2,"tv":4009.32,"id":9629296},{"batb":[[1,1.45,158.94]],"ltp":1.6,"tv":4009.2,"id":12343905}]}]}
{"op":"mcm","clk":"4231826540","pt":1631548475301,"mc":[{"id":"1.187560634","rc":[{"batb":[[1,2.9,51.72],[2,2.88,5.18]],"batl":[[0,3.15,9.52],[1,3.2,4.76],[2,3.25,9.56]],"ltp":2.2,"tv":4009.32,"id":9629296}]}]}
{"op":"mcm","clk":"4231826986","pt":1631548480600,"mc":[{"id":"1.187560634","rc":[{"trd":[[1.49,100]],"batb":[[1,1.45,106.43],[2,1.44,232.5]],"batl":[[0,1.5,91.76],[1,1.54,185.18],[2,1.72,32.16]],"ltp":1.49,"tv":4109.2,"id":12343905}],"tv":8118.52}]}
{"op":"mcm","clk":"4231827131","pt":1631548482494,"mc":[{"id":"1.187560634","rc":[{"batb":[[0,1.48,16.07]],"ltp":1.49,"tv":4109.2,"id":12343905}]}]}
{"op":"mcm","clk":"4231827238","pt":1631548483593,"mc":[{"id":"1.187560634","rc":[{"trd":[[1.5,3.02]],"batb":[[1,1.46,80.36],[2,1.45,106.43]],"batl":[[0,1.5,146.61],[1,1.51,88.77],[2,1.54,185.18]],"ltp":1.5,"tv":4112.22,"id":12343905}],"tv":8121.54}]}
{"op":"mcm","clk":"4231827321","pt":1631548484527,"mc":[{"id":"1.187560634","rc":[{"trd":[[3,2.73]],"batb":[[0,2.32,29.19],[1,2.26,6.98],[2,2.24,6.77]],"batl":[[0,3.25,4.8],[1,4.6,138.07],[2,5.2,2.08]],"ltp":3.0,"tv":4012.05,"id":9629296},{"trd":[[1.5,8.48]],"batb":[[0,1.24,245.16],[1,1.16,151.28],[2,1.1,2]],"batl":[[0,1.79,32.5],[1,1.8,32.87],[2,1.93,28.5]],"ltp":1.5,"tv":4117.68,"id":12343905}],"tv":8129.73}]}
{"op":"mcm","clk":"4231827592","pt":1631548487411,"mc":[{"id":"1.187560634","rc":[{"batb":[[0,1.26,176.56],[1,1.25,225.33],[2,1.24,245.14]],"batl":[[0,1.69,113.41],[1,1.71,114.17],[2,1.79,32.5]],"ltp":1.5,"tv":4117.68,"id":12343905}]}]}
{"op":"mcm","clk":"4231827669","pt":1631548488407,"mc":[{"id":"1.187560634","rc":[{"batb":[[0,2.38,5.67],[1,2.32,29.19],[2,2.26,6.98]],"ltp":3.0,"tv":4012.05,"id":9629296},{"batb":[[0,1.26,176.61]],"batl":[[2,1.72,33.16]],"ltp":1.5,"tv":4117.68,"id":12343905}]}]}
{"op":"mcm","clk":"4231827771","pt":1631548489815,"mc":[{"id":"1.187560634","rc":[{"batb":[[0,1.26,177.51]],"ltp":1.5,"tv":4117.68,"id":12343905}]}]}
{"op":"mcm","clk":"4231827919","pt":1631548491999,"mc":[{"id":"1.187560634","rc":[{"batb":[[0,2.32,29.19],[1,2.26,6.98],[2,2.24,6.77]],"ltp":3.0,"tv":4012.05,"id":9629296},{"batb":[[0,1.24,246.12],[1,1.16,151.28],[2,1.1,2]],"batl":[[0,1.79,32.5],[1,1.8,32.87],[2,1.93,28.5]],"ltp":1.5,"tv":4117.68,"id":12343905}]}]}
{"op":"mcm","clk":"4231828004","pt":1631548492930,"mc":[{"id":"1.187560634","rc":[{"batb":[[0,1.24,245.22]],"ltp":1.5,"tv":4117.68,"id":12343905}]}]}
{"op":"mcm","clk":"4231828209","pt":1631548495395,"mc":[{"id":"1.187560634","rc":[{"batb":[[0,2.38,6.46],[1,2.32,29.19],[2,2.26,6.98]],"ltp":3.0,"tv":4012.05,"id":9629296},{"trd":[[1.49,100.15]],"batb":[[0,1.41,162.69],[1,1.4,124.91],[2,1.24,245.14]],"batl":[[0,1.45,123.57],[1,1.46,101.77],[2,1.72,31.66]],"ltp":1.49,"tv":4117.83,"id":12343905}],"tv":8129.89}]}
{"op":"mcm","clk":"4231828442","pt":1631548498412,"mc":[{"id":"1.187560634","rc":[{"batb":[[0,1.24,245.14],[1,1.16,151.28],[2,1.1,2]],"batl":[[0,1.72,31.66],[1,1.79,32.5],[2,1.8,32.87]],"ltp":1.49,"tv":4117.83,"id":12343905}]}]}
{"op":"mcm","clk":"4231828459","pt":1631548498721,"mc":[{"id":"1.187560634","rc":[{"batb":[[0,2.32,29.19],[1,2.26,6.98],[2,2.24,6.77]],"ltp":3.0,"tv":4012.05,"id":9629296},{"batl":[[0,1.79,32.5],[1,1.8,32.87],[2,1.93,28.5]],"ltp":1.49,"tv":4117.83,"id":12343905}]}]}
{"op":"mcm","clk":"4231828672","pt":1631548501514,"mc":[{"id":"1.187560634","rc":[{"batl":[[0,1.69,113.37],[1,1.71,114.17],[2,1.79,32.5]],"ltp":1.49,"tv":4117.83,"id":12343905}]}]}
{"op":"mcm","clk":"4231828714","pt":1631548502034,"mc":[{"id":"1.187560634","rc":[{"batb":[[0,2.38,5.46],[1,2.32,29.19],[2,2.26,6.98]],"ltp":3.0,"tv":4012.05,"id":9629296},{"batl":[[2,1.72,38.41]],"ltp":1.49,"tv":4117.83,"id":12343905}]}]}
{"op":"mcm","clk":"4231828786","pt":1631548503141,"mc":[{"id":"1.187560634","rc":[{"batl":[[1,5.2,2.08],[2,7.4,2]],"ltp":3.0,"tv":4012.05,"id":9629296}]}]}
{"op":"mcm","clk":"4231828868","pt":1631548504337,"mc":[{"id":"1.187560634","rc":[{"batb":[[0,2.38,62.6],[1,2.36,200.96],[2,2.34,55.46]],"batl":[[0,2.54,2.88],[1,2.56,12.67],[2,2.62,52.3]],"ltp":3.0,"tv":4012.05,"id":9629296},{"batb":[[0,1.65,13.13],[1,1.64,204.95],[2,1.63,124.08]],"batl":[[0,1.68,10.26],[1,1.69,113.37],[2,1.71,114.17]],"ltp":1.49,"tv":4117.83,"id":12343905}]}]}
{"op":"mcm","clk":"4231829308","pt":1631548510656,"mc":[{"id":"1.187560634","rc":[{"batb":[[0,2.38,34.03],[1,2.36,27.73],[2,2.34,27.73]],"batl":[[1,2.62,26.15],[2,2.66,25.38]],"ltp":3.0,"tv":4012.05,"id":9629296},{"batb":[[1,1.63,124.08],[2,1.62,69.05]],"batl":[[0,1.69,113.37],[1,1.71,114.17],[2,1.72,38.41]],"ltp":1.49,"tv":4117.83,"id":12343905}]}]}
{"op":"mcm","clk":"4231829353","pt":1631548511232,"mc":[{"id":"1.187560634","rc":[{"batb":[[0,2.08,7.06],[1,2.04,41.6],[2,1.98,14.44]],"batl":[[0,3.25,4.8],[1,3.65,172.94],[2,3.75,3.26]],"ltp":3.0,"tv":4012.05,"id":9629296},{"batb":[[0,1.42,74.15],[1,1.37,66.77],[2,1.24,98.27]],"batl":[[0,1.91,28.5],[1,3,5.2],[2,880,0.01]],"ltp":1.49,"tv":4117.83,"id":12343905}]}]}
{"op":"mcm","clk":"4231829648","pt":1631548514536,"mc":[{"id":"1.187560634","rc":[{"batl":[[1,3.3,3.75],[2,3.65,172.94]],"ltp":3.0,"tv":4012.05,"id":9629296},{"batb":[[0,1.45,92.19],[1,1.44,167.11],[2,1.42,74.15]],"batl":[[0,1.85,28.3],[1,1.86,97.29],[2,1.88,84.15]],"ltp":1.49,"tv":4117.83,"id":12343905}]}]}
{"op":"mcm","clk":"4231829736","pt":1631548515665,"mc":[{"id":"1.187560634","rc":[{"batl":[[1,3.65,172.94],[2,3.75,3.26]],"ltp":3.0,"tv":4012.05,"id":9629296},{"batb":[[0,1.68,25],[1,1.45,92.19],[2,1.44,109.69]],"batl":[[0,1.86,97.29],[1,1.88,84.15],[2,1.91,28.5]],"ltp":1.49,"tv":4117.83,"id":12343905}]}]}
{"op":"mcm","clk":"4231829753","pt":1631548515834,"mc":[{"id":"1.187560634","rc":[{"trd":[[1.68,240.04]],"batb":[[0,1.68,24.98]],"ltp":1.68,"tv":4117.87,"id":12343905}],"tv":8129.92}]}
{"op":"mcm","clk":"4231829880","pt":1631548517626,"mc":[{"id":"1.187560634","rc":[{"batb":[[0,2.16,7.28],[1,2.08,7.06],[2,2.04,41.6]],"ltp":3.0,"tv":4012.05,"id":9629296},{"batb":[[0,1.45,92.19],[1,1.44,109.69],[2,1.42,74.15]],"ltp":1.68,"tv":4117.87,"id":12343905}]}]}
{"op":"mcm","clk":"4231829927","pt":1631548518248,"mc":[{"id":"1.187560634","rc":[{"batb":[[0,2.08,7.06],[1,2.04,41.6],[2,1.98,14.44]],"ltp":3.0,"tv":4012.05,"id":9629296}]}]}
{"op":"mcm","clk":"4231830147","pt":1631548521570,"mc":[{"id":"1.187560634","rc":[{"batl":[[1,3.3,4.05],[2,3.65,172.94]],"ltp":3.0,"tv":4012.05,"id":9629296},{"batb":[[1,1.44,164.36]],"batl":[[0,1.85,28.7],[1,1.86,97.29],[2,1.88,84.15]],"ltp":1.68,"tv":4117.87,"id":12343905}]}]}
{"op":"mcm","clk":"4231830164","pt":1631548521834,"mc":[{"id":"1.187560634","rc":[{"batl":[[1,3.65,172.94],[2,3.75,3.26]],"ltp":3.0,"tv":4012.05,"id":9629296},{"batb":[[1,1.44,109.69]],"batl":[[0,1.86,97.29],[1,1.88,84.15],[2,1.91,28.5]],"ltp":1.68,"tv":4117.87,"id":12343905}]}]}
{"op":"mcm","clk":"4231830360","pt":1631548524553,"mc":[{"id":"1.187560634","rc":[{"batb":[[0,2.16,7.28],[1,2.08,7.06],[2,2.04,41.6]],"ltp":3.0,"tv":4012.05,"id":9629296}]}]}
{"op":"mcm","clk":"4231830413","pt":1631548525355,"mc":[{"id":"1.187560634","rc":[{"batb":[[0,2.08,7.06],[1,2.04,41.6],[2,1.98,14.44]],"ltp":3.0,"tv":4012.05,"id":9629296}]}]}
{"op":"mcm","clk":"4231830502","pt":1631548526761,"mc":[{"id":"1.187560634","rc":[{"batb":[[0,1.42,74.15],[1,1.37,66.77],[2,1.24,98.27]],"ltp":1.68,"tv":4117.87,"id":12343905}]}]}
{"op":"mcm","clk":"4231830655","pt":1631548528578,"mc":[{"id":"1.187560634","rc":[{"batl":[[1,3.3,3.35]],"ltp":3.0,"tv":4012.05,"id":9629296},{"batb":[[0,1.44,50.92],[1,1.42,74.15],[2,1.37,66.77]],"batl":[[0,1.85,28.7],[1,1.86,97.29],[2,1.88,84.15]],"ltp":1.68,"tv":4117.87,"id":12343905}]}]}
{"op":"mcm","clk":"4231830731","pt":1631548529673,"mc":[{"id":"1.187560634","rc":[{"batb":[[0,2.16,96.11],[1,2.08,7.06],[2,2.04,41.6]],"batl":[[0,2.26,3.25],[1,2.28,78.46],[2,2.3,1131.75]],"ltp":3.0,"tv":4012.05,"id":9629296},{"batb":[[0,1.82,109.9],[1,1.8,11.58],[2,1.74,144.38]],"batl":[[0,1.83,11.86]],"ltp":1.68,"tv":4117.87,"id":12343905}]}]}
{"op":"mcm","clk":"4231830818","pt":1631548530664,"mc":[{"id":"1.187560634","rc":[{"batl":[[1,2.28,25.82],[2,2.3,6.58]],"ltp":3.0,"tv":4012.05,"id":9629296},{"batb":[[2,1.79,95.5]],"batl":[[2,1.87,80.2]],"ltp":1.68,"tv":4117.87,"id":12343905}]}]}
{"op":"mcm","clk":"4231830919","pt":1631548531667,"mc":[{"id":"1.187560634","rc":[{"batl":[[2,1.87,16.04]],"ltp":1.68,"tv":4117.87,"id":12343905}]}]}
{"op":"mcm","clk":"4231831268","pt":1631548536462,"mc":[{"id":"1.187560634","rc":[{"batb":[[2,2.06,8.08]],"ltp":3.0,"tv":4012.05,"id":9629296}]}]}
{"op":"mcm","clk":"4231831389","pt":1631548538292,"mc":[{"id":"1.187560634","rc":[{"trd":[[1.82,62.51]],"batb":[[0,1.82,109.88]],"ltp":1.82,"tv":4117.91,"id":12343905}],"tv":8129.96}]}
{"op":"mcm","clk":"4231831910","pt":1631548546474,"mc":[{"id":"1.187560634","rc":[{"batl":[[1,1.87,16.04],[2,1.88,8.02]],"ltp":1.82,"tv":4117.91,"id":12343905}]}]}
{"op":"mcm","clk":"4231832143","pt":1631548549500,"mc":[{"id":"1.187560634","rc":[{"batl":[[1,1.85,57.54],[2,1.87,101.68]],"ltp":1.82,"tv":4117.91,"id":12343905}]}]}
{"op":"mcm","clk":"4231832293","pt":1631548551418,"mc":[{"id":"1.187560634","rc":[{"batb":[[0,1.98,14.44],[1,1.97,400.72],[2,1.95,28.88]],"batl":[[0,2.6,5.11],[1,3.15,203.39],[2,3.25,4.8]],"ltp":3.0,"tv":4012.05,"id":9629296},{"batb":[[0,1.63,37.23],[1,1.6,47.22],[2,1.37,66.77]],"batl":[[0,1.98,26.25],[1,3,5.2],[2,880,0.01]],"ltp":1.82,"tv":4117.91,"id":12343905}]}]}
{"op":"mcm","clk":"4231832530","pt":1631548554608,"mc":[{"id":"1.187560634","rc":[{"batb":[[0,2.06,9.08],[1,2.02,8.74],[2,1.98,14.44]],"batl":[[0,2.48,5.49],[1,2.6,5.11],[2,3.15,203.39]],"ltp":3.0,"tv":4012.05,"id":9629296},{"batb":[[0,1.68,35.86],[1,1.63,37.23],[2,1.62,96.09]],"batl":[[0,1.94,28.75],[1,1.98,26.25],[2,2,65.4]],"ltp":1.82,"tv":4117.91,"id":12343905}]}]}
{"op":"mcm","clk":"4231832554","pt":1631548554923,"mc":[{"id":"1.187560634","rc":[{"batb":[[0,2.02,8.74],[1,1.98,14.44],[2,1.97,400.72]],"batl":[[0,2.6,5.11],[1,3.15,203.39],[2,3.25,4.8]],"ltp":3.0,"tv":4012.05,"id":9629296},{"batb":[[0,1.63,37.23],[1,1.62,96.09],[2,1.61,70.54]],"batl":[[0,1.98,26.25],[1,2,65.4],[2,2.02,67.76]],"ltp":1.82,"tv":4117.91,"id":12343905}]}]}
{"op":"mcm","clk":"4231833045","pt":1631548561410,"mc":[{"id":"1.187560634","rc":[{"batb":[[0,2.06,7.58],[1,2.02,8.74],[2,1.98,14.44]],"ltp":3.0,"tv":4012.05,"id":9629296},{"batl":[[0,1.94,26.75],[1,1.98,26.25],[2,3,5.2]],"ltp":1.82,"tv":4117.91,"id":12343905}]}]}
{"op":"mcm","clk":"4231833103","pt":1631548562025,"mc":[{"id":"1.187560634","rc":[{"batb":[[0,2.02,8.74],[1,1.98,14.44],[2,1.97,400.72]],"ltp":3.0,"tv":4012.05,"id":9629296},{"batl":[[0,1.98,26.25],[1,3,5.2],[2,880,0.01]],"ltp":1.82,"tv":4117.91,"id":12343905}]}]}
{"op":"mcm","clk":"4231833172","pt":1631548562821,"mc":[{"id":"1.187560634","rc":[{"batl":[[1,3.25,4.8],[2,3.75,3.26]],"ltp":3.0,"tv":4012.05,"id":9629296}]}]}
{"op":"mcm","clk":"4231833288","pt":1631548564322,"mc":[{"id":"1.187560634","rc":[{"batb":[[0,2.5,7.4],[1,2.02,8.74],[2,1.98,14.44]],"batl":[[0,2.56,5.64],[1,2.6,5.11],[2,2.72,139.39]],"ltp":3.0,"tv":4012.05,"id":9629296},{"batl":[[0,1.67,158.96],[1,1.69,172.25],[2,1.7,164.13]],"ltp":1.82,"tv":4117.91,"id":12343905}]}]}
{"op":"mcm","clk":"4231833377","pt":1631548565426,"mc":[{"id":"1.187560634","rc":[{"batb":[[1,2.34,28.77],[2,2.06,40.85]],"batl":[[2,2.62,11.44]],"ltp":3.0,"tv":4012.05,"id":9629296},{"batl":[[1,1.69,136.75],[2,1.7,146.38]],"ltp":1.82,"tv":4117.91,"id":12343905}]}]}
{"op":"mcm","clk":"4231833898","pt":1631548572225,"mc":[{"id":"1.187560634","rc":[{"batb":[[2,2.2,6.77]],"ltp":3.0,"tv":4012.05,"id":9629296},{"trd":[[1.67,52.8]],"batl":[[0,1.67,133.96]],"ltp":1.67,"tv":4167.91,"id":12343905}],"tv":8179.96}]}
{"op":"mcm","clk":"4231834088","pt":1631548574624,"mc":[{"id":"1.187560634","rc":[{"batb":[[0,2.34,28.77],[1,2.2,6.77],[2,2.14,7.82]],"batl":[[0,2.6,5.11],[1,3.25,4.8],[2,3.35,3.3]],"ltp":3.0,"tv":4012.05,"id":9629296},{"batl":[[0,1.67,87.1],[1,1.69,118.99],[2,1.82,30.25]],"ltp":1.67,"tv":4167.91,"id":12343905}]}]}
{"op":"mcm","clk":"4231834128","pt":1631548575141,"mc":[{"id":"1.187560634","rc":[{"batb":[[0,2.14,7.82],[1,2.06,40.85],[2,2,5]],"batl":[[0,3.25,4.8],[1,3.65,172.94],[2,3.75,3.26]],"ltp":3.0,"tv":4012.05,"id":9629296},{"batb":[[0,1.41,76],[1,1.37,66.77],[2,1.36,62.68]],"batl":[[0,1.87,28.5],[1,3,5.2],[2,880,0.01]],"ltp":1.67,"tv":4167.91,"id":12343905}]}]}
{"op":"mcm","clk":"4231834181","pt":1631548575935,"mc":[{"id":"1.187560634","rc":[{"batl":[[0,3.25,4.82]],"ltp":3.0,"tv":4012.05,"id":9629296}]}]}
{"op":"mcm","clk":"4231834401","pt":1631548578545,"mc":[{"id":"1.187560634","rc":[{"batl":[[1,3.35,3.9],[2,3.65,172.94]],"ltp":3.0,"tv":4012.05,"id":9629296},{"batb":[[0,1.44,93.46],[1,1.43,175.48],[2,1.41,76]],"batl":[[0,1.84,89.36],[1,1.86,87.02],[2,1.87,28.5]],"ltp":1.67,"tv":4167.91,"id":12343905}]}]}
{"op":"mcm","clk":"4231834571","pt":1631548580646,"mc":[{"id":"1.187560634","rc":[{"batl":[[0,3.25,4.8]],"ltp":3.0,"tv":4012.05,"id":9629296},{"batl":[[0,1.87,28.5],[1,3,5.2],[2,880,0.01]],"ltp":1.67,"tv":4167.91,"id":12343905}]}]}
{"op":"mcm","clk":"4231834675","pt":1631548582054,"mc":[{"id":"1.187560634","rc":[{"batl":[[2,3.75,3.26]],"ltp":3.0,"tv":4012.05,"id":9629296}]}]}
{"op":"mcm","clk":"4231834767","pt":1631548583159,"mc":[{"id":"1.187560634","rc":[{"batb":[[0,3.05,8.37],[1,2.98,10.06],[2,2.96,5.04]],"batl":[[0,3.15,4.7],[1,3.25,4.8],[2,3.35,90.19]],"ltp":3.0,"tv":4012.05,"id":9629296},{"batl":[[0,1.48,155.23],[1,1.49,227.69],[2,1.52,201.65]],"ltp":1.67,"tv":4167.91,"id":12343905}]}]}
{"op":"mcm","clk":"4231834869","pt":1631548584154,"mc":[{"id":"1.187560634","rc":[{"batl":[[1,3.25,14.04],[2,3.3,4.62]],"ltp":3.0,"tv":4012.05,"id":9629296}]}]}
{"op":"mcm","clk":"4231834966","pt":1631548585256,"mc":[{"id":"1.187560634","rc":[{"trd":[[3.05,1.56]],"batb":[[0,3.05,7.59]],"ltp":3.05,"tv":4013.61,"id":9629296}],"tv":8181.53}]}
{"op":"mcm","clk":"4231835494","pt":1631548591793,"mc":[{"id":"1.187560634","rc":[{"trd":[[3.05,1.6]],"batb":[[0,3.05,7.57]],"ltp":3.05,"tv":4013.65,"id":9629296}],"tv":8181.57}]}
{"op":"mcm","clk":"4231835698","pt":1631548594670,"mc":[{"id":"1.187560634","rc":[{"batb":[[0,2.86,41.1],[1,2.48,6.51],[2,2.36,6.68]],"batl":[[0,3.25,4.8],[1,3.35,3.9],[2,3.75,3.26]],"ltp":3.05,"tv":4013.65,"id":9629296},{"batl":[[1,1.49,93.47],[2,1.67,39.5]],"ltp":1.67,"tv":4167.91,"id":12343905}]}]}
{"op":"mcm","clk":"4231835730","pt":1631548595089,"mc":[{"id":"1.187560634","rc":[{"batb":[[0,2.36,6.68],[1,2.34,28.44],[2,2.22,390.22]],"batl":[[1,4.6,138.07],[2,5.4,2.04]],"ltp":3.05,"tv":4013.65,"id":9629296},{"batb":[[0,1.23,279.53],[1,1.16,151.28],[2,1.15,147.63]],"batl":[[0,1.73,35.5],[1,1.87,28.5],[2,3,5.2]],"ltp":1.67,"tv":4167.91,"id":12343905}]}]}
{"op":"mcm","clk":"4231835944","pt":1631548598274,"mc":[{"id":"1.187560634","rc":[{"batb":[[0,2.48,5.76],[1,2.36,6.68],[2,2.34,28.44]],"ltp":3.05,"tv":4013.65,"id":9629296},{"batb":[[0,1.25,192.26],[1,1.24,237.09],[2,1.23,279.53]],"batl":[[0,1.66,106.44],[1,1.67,38.5],[2,1.68,121.33]],"ltp":1.67,"tv":4167.91,"id":12343905}]}]}
{"op":"mcm","clk":"4231836185","pt":1631548601469,"mc":[{"id":"1.187560634","rc":[{"batb":[[0,1.23,279.53],[1,1.16,151.28],[2,1.15,147.63]],"ltp":1.67,"tv":4167.91,"id":12343905}]}]}
{"op":"mcm","clk":"4231836250","pt":1631548602399,"mc":[{"id":"1.187560634","rc":[{"batl":[[1,5.4,2.04],[2,7.4,2]],"ltp":3.05,"tv":4013.65,"id":9629296}]}]}
{"op":"mcm","clk":"4231836401","pt":1631548604586,"mc":[{"id":"1.187560634","rc":[{"batb":[[1,2.46,55.28],[2,2.44,53.66]],"batl":[[0,2.7,50.74],[1,2.74,49.26],[2,2.76,49.26]],"ltp":3.05,"tv":4013.65,"id":9629296},{"batb":[[0,1.61,301.25],[1,1.6,72.14],[2,1.23,279.53]],"ltp":1.67,"tv":4167.91,"id":12343905}]}]}
{"op":"mcm","clk":"4231836448","pt":1631548605412,"mc":[{"id":"1.187560634","rc":[{"batb":[[2,1.59,47.73]],"ltp":1.67,"tv":4167.91,"id":12343905}]}]}
{"op":"mcm","clk":"4231836563","pt":1631548607201,"mc":[{"id":"1.187560634","rc":[{"batl":[[0,2.6,8.19],[1,2.7,50.74],[2,2.74,49.26]],"ltp":3.05,"tv":4013.65,"id":9629296},{"batl":[[0,1.66,121.2]],"ltp":1.67,"tv":4167.91,"id":12343905}]}]}
{"op":"mcm","clk":"4231836902","pt":1631548611632,"mc":[{"id":"1.187560634","rc":[{"batb":[[0,2.14,7.82],[1,2.08,39.93],[2,2,5]],"batl":[[0,3.25,4.8],[1,3.65,172.94],[2,3.9,2.95]],"ltp":3.05,"tv":4013.65,"id":9629296},{"batb":[[0,1.41,76.58],[1,1.35,69.87],[2,1.23,128.63]],"batl":[[0,1.87,28.5],[1,3,5.2],[2,880,0.01]],"ltp":1.67,"tv":4167.91,"id":12343905}]}]}
{"op":"mcm","clk":"4231837033","pt":1631548613518,"mc":[{"id":"1.187560634","rc":[{"batb":[[0,2.14,7.84]],"ltp":3.05,"tv":4013.65,"id":9629296}]}]}
{"op":"mcm","clk":"4231837108","pt":1631548614534,"mc":[{"id":"1.187560634","rc":[{"batl":[[1,3.4,3.24],[2,3.65,172.94]],"ltp":3.05,"tv":4013.65,"id":9629296},{"batb":[[0,1.43,111.78],[1,1.42,174.21],[2,1.41,76.58]],"batl":[[0,1.82,68.32],[1,1.84,90.11],[2,1.87,28.5]],"ltp":1.67,"tv":4167.91,"id":12343905}]}]}
{"op":"mcm","clk":"4231837501","pt":1631548620336,"mc":[{"id":"1.187560634","rc":[{"batl":[[1,3.65,172.94],[2,3.9,2.95]],"ltp":3.05,"tv":4013.65,"id":9629296},{"batb":[[0,1.41,76.58],[1,1.35,69.87],[2,1.23,128.63]],"ltp":1.67,"tv":4167.91,"id":12343905}]}]}
{"op":"mcm","clk":"4231837592","pt":1631548621637,"mc":[{"id":"1.187560634","rc":[{"batl":[[1,3.9,2.95],[2,5.4,2.04]],"ltp":3.05,"tv":4013.65,"id":9629296}]}]}
{"op":"mcm","clk":"4231837715","pt":1631548623415,"mc":[{"id":"1.187560634","rc":[{"trd":[[2.24,22.31],[2.64,0.04]],"batb":[[0,2.14,7.82]],"batl":[[0,2.24,17.86],[1,2.4,93.15],[2,3.25,4.8]],"ltp":2.24,"tv":4023.78,"id":9629296},{"trd":[[1.8,185.43]],"batb":[[0,1.76,105.99],[1,1.75,85.72],[2,1.74,149.57]],"batl":[[1,1.83,121.35],[2,1.84,90.11]],"ltp":1.8,"tv":4180.47,"id":12343905}],"tv":8204.26}]}
{"op":"mcm","clk":"4231837783","pt":1631548624552,"mc":[{"id":"1.187560634","rc":[{"batb":[[0,2.22,14.44],[1,2.14,7.82],[2,2.08,39.93]],"ltp":2.24,"tv":4023.78,"id":9629296},{"batb":[[1,1.75,51.43],[2,1.74,167.49]],"batl":[[2,1.84,106.41]],"ltp":1.8,"tv":4180.47,"id":12343905}]}]}
{"op":"mcm","clk":"4231837833","pt":1631548625335,"mc":[{"id":"1.187560634","rc":[{"batl":[[2,3.15,203.39]],"ltp":2.24,"tv":4023.78,"id":9629296}]}]}
{"op":"mcm","clk":"4231838134","pt":1631548629617,"mc":[{"id":"1.187560634","rc":[{"batl":[[2,2.54,5.75]],"ltp":2.24,"tv":4023.78,"id":9629296}]}]}
{"op":"mcm","clk":"4231838388","pt":1631548633148,"mc":[{"id":"1.187560634","rc":[{"batb":[[0,1.76,94.49]],"ltp":1.8,"tv":4180.47,"id":12343905}]}]}
{"op":"mcm","clk":"4231838515","pt":1631548634667,"mc":[{"id":"1.187560634","rc":[{"batl":[[0,2.54,5.75],[1,2.68,4.89],[2,3.15,203.39]],"ltp":2.24,"tv":4023.78,"id":9629296},{"batb":[[0,1.74,35.06],[1,1.65,39.93],[2,1.6,42.04]],"batl":[[0,1.87,28.5],[1,1.93,24.5],[2,1.97,23.5]],"ltp":1.8,"tv":4180.47,"id":12343905}]}]}
{"op":"mcm","clk":"4231838564","pt":1631548635237,"mc":[{"id":"1.187560634","rc":[{"batb":[[1,2,5],[2,1.97,400.72]],"batl":[[0,2.68,4.89],[1,3.15,203.39],[2,3.25,4.8]],"ltp":2.24,"tv":4023.78,"id":9629296},{"batb":[[0,1.6,42.04],[1,1.58,48.73],[2,1.35,69.87]],"batl":[[0,1.97,23.5],[1,3,5.2],[2,880,0.01]],"ltp":1.8,"tv":4180.47,"id":12343905}]}]}
{"op":"mcm","clk":"4231838636","pt":1631548636136,"mc":[{"id":"1.187560634","rc":[{"batl":[[0,1.8,9.02],[1,1.97,23.5],[2,3,5.2]],"ltp":1.8,"tv":4180.47,"id":12343905}]}]}
{"op":"mcm","clk":"4231838749","pt":1631548637642,"mc":[{"id":"1.187560634","rc":[{"batb":[[0,1.6,107.33],[1,1.59,73.77],[2,1.58,48.73]],"batl":[[1,1.97,105.69],[2,1.99,70.84]],"ltp":1.8,"tv":4180.47,"id":12343905}]}]}
{"op":"mcm","clk":"4231838809","pt":1631548638534,"mc":[{"id":"1.187560634","rc":[{"batb":[[1,2.02,8.74],[2,2,5]],"batl":[[0,2.54,6.25],[1,2.68,4.89],[2,3.15,203.39]],"ltp":2.24,"tv":4023.78,"id":9629296},{"batb":[[0,1.65,38.73],[1,1.6,42.04]],"batl":[[1,1.97,23.5],[2,3,5.2]],"ltp":1.8,"tv":4180.47,"id":12343905}]}]}
{"op":"mcm","clk":"4231838882","pt":1631548639670,"mc":[{"id":"1.187560634","rc":[{"batl":[[0,2.3,19.35]],"ltp":2.24,"tv":4023.78,"id":9629296},{"batb":[[0,1.76,18.98],[1,1.73,64.07],[2,1.71,113.11]],"batl":[[0,1.78,63.05],[1,1.8,105.68],[2,1.82,19.75]],"ltp":1.8,"tv":4180.47,"id":12343905}]}]}
{"op":"mcm","clk":"4231838892","pt":1631548639731,"mc":[{"id":"1.187560634","rc":[{"batl":[[0,2.68,4.89],[1,3.15,203.39],[2,3.25,4.8]],"ltp":2.24,"tv":4023.78,"id":9629296},{"batb":[[0,1.73,64.07],[1,1.71,113.11],[2,1.6,42.04]],"batl":[[2,1.97,23.5]],"ltp":1.8,"tv":4180.47,"id":12343905}]}]}
{"op":"mcm","clk":"4231839026","pt":1631548641657,"mc":[{"id":"1.187560634","rc":[{"batl":[[2,1.93,26.5]],"ltp":1.8,"tv":4180.47,"id":12343905}]}]}
{"op":"mcm","clk":"4231839099","pt":1631548642650,"mc":[{"id":"1.187560634","rc":[{"batb":[[0,1.6,42.04],[1,1.58,48.73],[2,1.35,69.87]],"batl":[[0,1.8,9.02],[1,1.97,23.5],[2,3,5.2]],"ltp":1.8,"tv":4180.47,"id":12343905}]}]}
{"op":"mcm","clk":"4231839393","pt":1631548646248,"mc":[{"id":"1.187560634","rc":[{"batb":[[0,1.6,108.96],[1,1.59,73.77],[2,1.58,48.73]],"batl":[[0,1.97,104.26],[1,1.99,70.83]],"ltp":1.8,"tv":4180.47,"id":12343905}]}]}
{"op":"mcm","clk":"4231840329","pt":1631548659664,"mc":[{"id":"1.187560634","rc":[{"batb":[[0,2.02,8.74],[1,2,5],[2,1.97,400.72]],"batl":[[0,2.54,5.75],[1,2.68,4.89],[2,3.15,203.39]],"ltp":2.24,"tv":4023.78,"id":9629296},{"batb":[[0,1.65,38.33],[1,1.6,108.96],[2,1.59,73.77]],"batl":[[0,1.93,26.5],[1,1.97,23.5]],"ltp":1.8,"tv":4180.47,"id":12343905}]}]}
{"op":"mcm","clk":"4231840358","pt":1631548660076,"mc":[{"id":"1.187560634","rc":[{"batl":[[0,2.68,4.89],[1,3.25,4.8],[2,3.9,2.95]],"ltp":2.24,"tv":4023.78,"id":9629296},{"batb":[[0,1.6,108.96],[1,1.59,73.77],[2,1.58,48.73]],"batl":[[0,1.97,23.5],[1,3,5.2],[2,880,0.01]],"ltp":1.8,"tv":4180.47,"id":12343905}]}]}
{"op":"mcm","clk":"4231840472","pt":1631548661590,"mc":[{"id":"1.187560634","rc":[{"batl":[[0,2.6,10.26],[1,2.68,4.89],[2,2.78,124.33]],"ltp":2.24,"tv":4023.78,"id":9629296},{"batl":[[0,1.64,1891.56],[1,1.65,121.22],[2,1.66,11.46]],"ltp":1.8,"tv":4180.47,"id":12343905}]}]}
{"op":"mcm","clk":"4231840558","pt":1631548662576,"mc":[{"id":"1.187560634","rc":[{"batb":[[0,1.61,93.16],[1,1.6,155.54],[2,1.59,120.35]],"batl":[[0,1.64,63.44],[1,1.65,185.57]],"ltp":1.8,"tv":4180.47,"id":12343905}]}]}
{"op":"mcm","clk":"4231840596","pt":1631548663090,"mc":[{"id":"1.187560634","rc":[{"batb":[[0,2.36,27.68],[1,2.08,39.34],[2,2.02,8.74]],"ltp":2.24,"tv":4023.78,"id":9629296},{"batb":[[0,1.61,18.64],[1,1.6,118.28],[2,1.59,83.09]],"ltp":1.8,"tv":4180.47,"id":12343905}]}]}
{"op":"mcm","clk":"4231840936","pt":1631548668405,"mc":[{"id":"1.187560634","rc":[{"batb":[[1,2.24,6.27],[2,2.16,7.28]],"ltp":2.24,"tv":4023.78,"id":9629296}]}]}
{"op":"mcm","clk":"4231841205","pt":1631548672591,"mc":[{"id":"1.187560634","rc":[{"batb":[[0,2.16,7.28],[1,2.08,39.34],[2,2,5]],"batl":[[0,3.25,4.8],[1,3.9,163.54],[2,5.4,2.04]],"ltp":2.24,"tv":4023.78,"id":9629296},{"batb":[[0,1.41,77.84],[1,1.35,69.87],[2,1.23,128.63]],"batl":[[0,1.86,27.75],[1,3,5.2],[2,880,0.01]],"ltp":1.8,"tv":4180.47,"id":12343905}]}]}
{"op":"mcm","clk":"4231841397","pt":1631548675539,"mc":[{"id":"1.187560634","rc":[{"batb":[[0,2.24,6.77],[1,2.16,7.28],[2,2.08,39.34]],"ltp":2.24,"tv":4023.78,"id":9629296},{"batb":[[0,1.42,129.43],[1,1.41,198.51],[2,1.35,69.87]],"batl":[[0,1.8,31.87],[1,1.81,93.01],[2,1.83,91.6]],"ltp":1.8,"tv":4180.47,"id":12343905}]}]}
{"op":"mcm","clk":"4231841433","pt":1631548676162,"mc":[{"id":"1.187560634","rc":[{"batb":[[0,2.16,7.28],[1,2.08,39.34],[2,2,5]],"ltp":2.24,"tv":4023.78,"id":9629296},{"batl":[[0,1.81,93.01],[1,1.83,91.6],[2,1.86,27.75]],"ltp":1.8,"tv":4180.47,"id":12343905}]}]}
{"op":"mcm","clk":"4231841554","pt":1631548677775,"mc":[{"id":"1.187560634","rc":[{"batb":[[0,1.41,77.84],[1,1.35,69.87],[2,1.23,128.63]],"ltp":1.8,"tv":4180.47,"id":12343905}]}]}
{"op":"mcm","clk":"4231841687","pt":1631548679350,"mc":[{"id":"1.187560634","rc":[{"batl":[[0,2.56,9.02],[1,3.25,4.8],[2,3.4,3.54]],"ltp":2.24,"tv":4023.78,"id":9629296},{"batb":[[0,1.42,57.94],[1,1.41,77.84],[2,1.35,69.87]],"ltp":1.8,"tv":4180.47,"id":12343905}]}]}
{"op":"mcm","clk":"4231841773","pt":1631548680666,"mc":[{"id":"1.187560634","rc":[{"batl":[[0,2.26,88.5],[1,2.32,3.11],[2,2.36,1286.22]],"ltp":2.24,"tv":4023.78,"id":9629296},{"batb":[[0,1.76,26.97],[1,1.74,86.2],[2,1.73,43.1]],"batl":[[0,1.8,9.13],[1,1.81,93.01],[2,1.83,267.64]],"ltp":1.8,"tv":4180.47,"id":12343905}]}]}
{"op":"mcm","clk":"4231841865","pt":1631548681672,"mc":[{"id":"1.187560634","rc":[{"batl":[[2,2.56,9.02]],"ltp":2.24,"tv":4023.78,"id":9629296},{"batb":[[1,1.75,73.5],[2,1.74,17.24]],"batl":[[2,1.83,349.6]],"ltp":1.8,"tv":4180.47,"id":12343905}]}]}
{"op":"mcm","clk":"4231841911","pt":1631548682254,"mc":[{"id":"1.187560634","rc":[{"batl":[[2,1.83,284.04]],"ltp":1.8,"tv":4180.47,"id":12343905}]}]}
{"op":"mcm","clk":"4231842076","pt":1631548684045,"mc":[{"id":"1.187560634","rc":[{"batl":[[2,3.25,4.8]],"ltp":2.24,"tv":4023.78,"id":9629296}]}]}
{"op":"mcm","clk":"4231842188","pt":1631548685571,"mc":[{"id":"1.187560634","rc":[{"trd":[[2.24,27.92]],"ltp":2.24,"tv":4029.39,"id":9629296},{"trd":[[1.8,192.41]],"batl":[[0,1.8,2.15]],"ltp":1.8,"tv":4187.45,"id":12343905}],"tv":8216.85}]}
{"op":"mcm","clk":"4231842328","pt":1631548687363,"mc":[{"id":"1.187560634","rc":[{"batb":[[1,2.08,46.65],[2,2.04,8.62]],"batl":[[2,2.58,5.75]],"ltp":2.24,"tv":4029.39,"id":9629296}]}]}
{"op":"mcm","clk":"4231842585","pt":1631548690879,"mc":[{"id":"1.187560634","rc":[{"trd":[[2.26,42.12]],"batl":[[0,2.26,86.92]],"ltp":2.26,"tv":4030.97,"id":9629296},{"trd":[[1.79,48.13]],"ltp":1.79,"tv":4189.45,"id":12343905}],"tv":8220.43}]}
{"op":"mcm","clk":"4231842910","pt":1631548695750,"mc":[{"id":"1.187560634","rc":[{"batb":[[0,1.76,11.98]],"batl":[[0,1.81,93.01],[1,1.83,284.04],[2,1.84,8.2]],"ltp":1.79,"tv":4189.45,"id":12343905}]}]}
{"op":"mcm","clk":"4231843007","pt":1631548697060,"mc":[{"id":"1.187560634","rc":[{"trd":[[2.26,49.26]],"batl":[[0,2.26,79.78]],"ltp":2.26,"tv":4038.11,"id":9629296},{"trd":[[1.79,57.15]],"ltp":1.79,"tv":4198.47,"id":12343905}],"tv":8236.59}]}
{"op":"mcm","clk":"4231843124","pt":1631548698676,"mc":[{"id":"1.187560634","rc":[{"trd":[[2.26,49.32]],"batb":[[0,2,5],[1,1.97,400.72],[2,1.95,28.88]],"batl":[[0,2.28,6.97],[1,2.7,5.05],[2,3.25,4.8]],"ltp":2.26,"tv":4038.17,"id":9629296},{"trd":[[1.79,57.23]],"batb":[[0,1.59,46.11],[1,1.57,49.74],[2,1.35,69.87]],"batl":[[0,1.83,18.83],[1,1.96,26.62],[2,3,5.2]],"ltp":1.79,"tv":4198.55,"id":12343905}],"tv":8236.73}]}
{"op":"mcm","clk":"4231843183","pt":1631548699562,"mc":[{"id":"1.187560634","rc":[{"batb":[[0,2.06,7.58],[1,2.02,8.24],[2,2,5]],"batl":[[0,2.7,5.05],[1,2.74,4.48]],"ltp":2.26,"tv":4038.17,"id":9629296},{"batb":[[1,1.58,45.06],[2,1.57,49.74]],"batl":[[0,1.93,26.5],[2,1.97,22.83]],"ltp":1.79,"tv":4198.55,"id":12343905}]}]}
{"op":"mcm","clk":"4231843200","pt":1631548699773,"mc":[{"id":"1.187560634","rc":[{"batb":[[0,2.02,8.24],[1,2,5],[2,1.97,400.72]],"ltp":2.26,"tv":4038.17,"id":9629296},{"batl":[[0,1.96,26.62],[1,1.97,22.83],[2,3,5.2]],"ltp":1.79,"tv":4198.55,"id":12343905}]}]}
{"op":"mcm","clk":"4231843347","pt":1631548701653,"mc":[{"id":"1.187560634","rc":[{"batb":[[0,2.04,7.87],[1,2.02,8.24],[2,2,5]],"batl":[[0,2.58,5.75],[1,2.7,5.05],[2,2.74,4.48]],"ltp":2.26,"tv":4038.17,"id":9629296},{"batb":[[0,1.64,38.57],[1,1.59,46.11],[2,1.58,174.69]],"batl":[[0,1.95,68.92],[1,1.96,26.62],[2,1.97,95.85]],"ltp":1.79,"tv":4198.55,"id":12343905}]}]}
{"op":"mcm","clk":"4231843373","pt":1631548701966,"mc":[{"id":"1.187560634","rc":[{"batl":[[0,2.7,5.05],[1,2.74,4.48],[2,3.25,4.8]],"ltp":2.26,"tv":4038.17,"id":9629296},{"batb":[[0,1.59,46.11],[1,1.58,174.69],[2,1.57,127.39]],"ltp":1.79,"tv":4198.55,"id":12343905}]}]}
{"op":"mcm","clk":"4231843743","pt":1631548708598,"mc":[{"id":"1.187560634","rc":[{"batb":[[0,2.08,8.06],[1,2.04,7.87],[2,2.02,8.24]],"batl":[[0,2.58,5.44],[1,2.7,5.05],[2,2.74,4.48]],"ltp":2.26,"tv":4038.17,"id":9629296},{"batb":[[0,1.64,39.07],[1,1.59,46.11],[2,1.58,174.69]],"batl":[[0,1.92,26.06],[1,1.95,68.92],[2,1.96,26.62]],"ltp":1.79,"tv":4198.55,"id":12343905}]}]}
{"op":"mcm","clk":"4231843761","pt":1631548708863,"mc":[{"id":"1.187560634","rc":[{"batb":[[0,2.04,7.87],[1,2.02,8.24],[2,2,5]],"batl":[[0,2.7,5.05],[1,2.74,4.48],[2,3.25,4.8]],"ltp":2.26,"tv":4038.17,"id":9629296},{"batb":[[0,1.59,46.11],[1,1.58,174.69],[2,1.57,127.39]],"batl":[[0,1.95,68.92],[1,1.96,26.62],[2,1.97,95.85]],"ltp":1.79,"tv":4198.55,"id":12343905}]}]}
{"op":"mcm","clk":"4231844134","pt":1631548715586,"mc":[{"id":"1.187560634","rc":[{"batb":[[0,2.08,8.06],[1,2.04,7.87],[2,2.02,8.24]],"ltp":2.26,"tv":4038.17,"id":9629296},{"batl":[[0,1.92,30.06],[1,1.95,68.92],[2,1.96,26.62]],"ltp":1.79,"tv":4198.55,"id":12343905}]}]}
{"op":"mcm","clk":"4231844171","pt":1631548715897,"mc":[{"id":"1.187560634","rc":[{"batb":[[0,2.04,7.87],[1,2.02,8.24],[2,2,5]],"ltp":2.26,"tv":4038.17,"id":9629296},{"batl":[[0,1.95,68.92],[1,1.96,26.62],[2,1.97,95.85]],"ltp":1.79,"tv":4198.55,"id":12343905}]}]}
{"op":"mcm","clk":"4231844580","pt":1631548722576,"mc":[{"id":"1.187560634","rc":[{"batb":[[0,2.08,7.06],[1,2.04,7.87],[2,2.02,8.24]],"batl":[[0,2.58,5.94],[1,2.7,5.05],[2,2.74,4.48]],"ltp":2.26,"tv":4038.17,"id":9629296},{"batb":[[0,1.64,42.82],[1,1.59,46.11],[2,1.58,174.69]],"batl":[[0,1.92,28.06],[1,1.95,68.92],[2,1.96,26.62]],"ltp":1.79,"tv":4198.55,"id":12343905}]}]}
{"op":"mcm","clk":"4231844623","pt":1631548723304,"mc":[{"id":"1.187560634","rc":[{"batb":[[0,2.04,7.87],[1,2.02,8.24],[2,2,5]],"batl":[[0,2.7,5.05],[1,2.74,4.48],[2,3.25,4.8]],"ltp":2.26,"tv":4038.17,"id":9629296},{"batb":[[0,1.59,46.11],[1,1.58,174.69],[2,1.57,127.39]],"batl":[[0,1.96,26.62],[1,1.97,22.83],[2,3,5.2]],"ltp":1.79,"tv":4198.55,"id":12343905}]}]}
{"op":"mcm","clk":"4231844749","pt":1631548725599,"mc":[{"id":"1.187560634","rc":[{"batb":[[0,1.59,46.56]],"ltp":1.79,"tv":4198.55,"id":12343905}]}]}
{"op":"mcm","clk":"4231844788","pt":1631548726223,"mc":[{"id":"1.187560634","rc":[{"batl":[[0,2.6,8.75],[1,2.7,5.05],[2,2.74,4.48]],"ltp":2.26,"tv":4038.17,"id":9629296},{"batl":[[0,1.63,81.29],[1,1.64,187.63],[2,1.66,13.76]],"ltp":1.79,"tv":4198.55,"id":12343905}]}]}
{"op":"mcm","clk":"4231844860","pt":1631548727210,"mc":[{"id":"1.187560634","rc":[{"batb":[[0,2.38,27.09],[1,2.1,38.5],[2,2.04,7.87]],"ltp":2.26,"tv":4038.17,"id":9629296},{"batb":[[0,1.6,19.21],[1,1.59,55.49],[2,1.58,184.07]],"ltp":1.79,"tv":4198.55,"id":12343905}]}]}
{"op":"mcm","clk":"4231845194","pt":1631548732430,"mc":[{"id":"1.187560634","rc":[{"batb":[[1,2.24,5.77],[2,2.16,7.53]],"ltp":2.26,"tv":4038.17,"id":9629296}]}]}
{"op":"mcm","clk":"4231845268","pt":1631548733626,"mc":[{"id":"1.187560634","rc":[{"batb":[[0,1.6,18.76]],"ltp":1.79,"tv":4198.55,"id":12343905}]}]}
{"op":"mcm","clk":"4231845433","pt":1631548736349,"mc":[{"id":"1.187560634","rc":[{"trd":[[2.58,7.12]],"ltp":2.58,"tv":4045.29,"id":9629296},{"trd":[[1.63,11.27]],"batl":[[0,1.63,70.02]],"ltp":1.63,"tv":4209.82,"id":12343905}],"tv":8255.12}]}
{"op":"mcm","clk":"4231845994","pt":1631548745635,"mc":[{"id":"1.187560634","rc":[{"trd":[[2.58,16.14]],"ltp":2.58,"tv":4054.31,"id":9629296},{"trd":[[1.63,25.55]],"batl":[[0,1.63,55.74]],"ltp":1.63,"tv":4224.1,"id":12343905}],"tv":8278.42}]}
{"op":"mcm","clk":"4231846014","pt":1631548746052,"mc":[{"id":"1.187560634","rc":[{"batb":[[2,1.58,129.93]],"ltp":1.63,"tv":4224.1,"id":12343905}]}]}
{"op":"mcm","clk":"4231846147","pt":1631548748626,"mc":[{"id":"1.187560634","rc":[{"batb":[[0,2.16,7.53],[1,2.1,38.5],[2,2,5]],"batl":[[0,3.25,4.8],[1,3.4,3.64],[2,3.9,2.95]],"ltp":2.58,"tv":4054.31,"id":9629296},{"batb":[[0,1.42,64.44],[1,1.4,79.1],[2,1.35,69.87]],"batl":[[0,1.86,26.25],[1,3,5.2],[2,880,0.01]],"ltp":1.63,"tv":4224.1,"id":12343905}]}]}
{"op":"mcm","clk":"4231846305","pt":1631548751468,"mc":[{"id":"1.187560634","rc":[{"batb":[[1,1.41,168.35],[2,1.4,203.98]],"batl":[[0,1.8,103.81],[1,1.82,93.11],[2,1.86,26.25]],"ltp":1.63,"tv":4224.1,"id":12343905}]}]}
{"op":"mcm","clk":"4231846623","pt":1631548756235,"mc":[{"id":"1.187560634","rc":[{"batl":[[0,1.58,2],[1,1.8,103.81],[2,1.82,93.11]],"ltp":1.63,"tv":4224.1,"id":12343905}]}]}
{"op":"mcm","clk":"4231846812","pt":1631548759144,"mc":[{"id":"1.187560634","rc":[{"batl":[[0,1.8,103.81],[1,1.82,93.11],[2,1.86,26.25]],"ltp":1.63,"tv":4224.1,"id":12343905}]}]}
{"op":"mcm","clk":"4231846867","pt":1631548760036,"mc":[{"id":"1.187560634","rc":[{"batb":[[1,1.4,79.1],[2,1.35,69.87]],"ltp":1.63,"tv":4224.1,"id":12343905}]}]}
{"op":"mcm","clk":"4231847081","pt":1631548763072,"mc":[{"id":"1.187560634","rc":[{"batl":[[0,2.28,52.63],[1,2.32,3.11],[2,2.36,38.14]],"ltp":2.58,"tv":4054.31,"id":9629296},{"batb":[[0,1.76,24.7],[1,1.74,66.98],[2,1.72,110.83]],"batl":[[0,1.8,246.18]],"ltp":1.63,"tv":4224.1,"id":12343905}]}]}
{"op":"mcm","clk":"4231847165","pt":1631548764171,"mc":[{"id":"1.187560634","rc":[{"batb":[[0,2.22,13.52],[1,2.2,6.76],[2,2.18,6.76]],"batl":[[2,2.36,12.72]],"ltp":2.58,"tv":4054.31,"id":9629296},{"batb":[[2,1.72,147.15]],"ltp":1.63,"tv":4224.1,"id":12343905}]}]}
{"op":"mcm","clk":"4231847792","pt":1631548774679,"mc":[{"id":"1.187560634","rc":[{"trd":[[2.28,30.89]],"batl":[[0,2.28,32.78]],"ltp":2.28,"tv":4074.16,"id":9629296},{"trd":[[1.78,65.93]],"ltp":1.78,"tv":4249.53,"id":12343905}],"tv":8323.7}]}
{"op":"mcm","clk":"4231847905","pt":1631548776656,"mc":[{"id":"1.187560634","rc":[{"batb":[[0,2.22,6.76],[1,2.2,3.38],[2,2.18,3.38]],"batl":[[0,2.28,8.77],[2,2.36,6.36]],"ltp":2.28,"tv":4074.16,"id":9629296},{"batb":[[0,1.76,11.98]],"batl":[[0,1.8,103.81]],"ltp":1.78,"tv":4249.53,"id":12343905}]}]}
{"op":"mcm","clk":"4231847965","pt":1631548777558,"mc":[{"id":"1.187560634","rc":[{"batb":[[0,2,5],[1,1.95,77.95],[2,1.6,99.43]],"batl":[[0,2.68,5.64],[1,3.25,4.8],[2,3.4,3.64]],"ltp":2.28,"tv":4074.16,"id":9629296},{"batb":[[0,1.6,45.84],[1,1.57,50.5],[2,1.42,64.44]],"batl":[[0,1.95,27.3],[1,3,5.2],[2,880,0.01]],"ltp":1.78,"tv":4249.53,"id":12343905}]}]}
{"op":"mcm","clk":"4231848021","pt":1631548778491,"mc":[{"id":"1.187560634","rc":[{"trd":[[1.6,16.94]],"batb":[[0,1.6,42.84]],"ltp":1.6,"tv":4255.53,"id":12343905}],"tv":8329.7}]}
{"op":"mcm","clk":"4231848082","pt":1631548779278,"mc":[{"id":"1.187560634","rc":[{"batl":[[0,1.95,27.39]],"ltp":1.6,"tv":4255.53,"id":12343905}]}]}
{"op":"mcm","clk":"4231848159","pt":1631548780592,"mc":[{"id":"1.187560634","rc":[{"batb":[[0,2.04,9.37],[1,2,5],[2,1.95,77.95]],"ltp":2.28,"tv":4074.16,"id":9629296},{"batb":[[1,1.57,187.29],[2,1.56,79.53]],"batl":[[0,1.94,79.35],[1,1.95,27.3],[2,1.96,74.11]],"ltp":1.6,"tv":4255.53,"id":12343905}]}]}
{"op":"mcm","clk":"4231848292","pt":1631548782589,"mc":[{"id":"1.187560634","rc":[{"trd":[[1.78,66.11]],"batb":[[0,1.8,149.91],[1,1.6,42.84],[2,1.57,187.29]],"batl":[[0,1.94,79.26]],"ltp":1.78,"tv":4255.71,"id":12343905}],"tv":8329.88}]}
{"op":"mcm","clk":"4231848413","pt":1631548784469,"mc":[{"id":"1.187560634","rc":[{"batl":[[0,2.54,5.25],[1,2.68,5.64],[2,3.25,4.8]],"ltp":2.28,"tv":4074.16,"id":9629296},{"batb":[[1,1.65,38.53],[2,1.6,42.84]],"ltp":1.78,"tv":4255.71,"id":12343905}]}]}
{"op":"mcm","clk":"4231848517","pt":1631548786191,"mc":[{"id":"1.187560634","rc":[{"batl":[[0,2.68,5.64],[1,3.25,4.8],[2,3.4,3.64]],"ltp":2.28,"tv":4074.16,"id":9629296},{"batb":[[0,1.6,42.84],[1,1.57,50.5],[2,1.42,64.44]],"ltp":1.78,"tv":4255.71,"id":12343905}]}]}
{"op":"mcm","clk":"4231848673","pt":1631548788592,"mc":[{"id":"1.187560634","rc":[{"batl":[[0,2.12,2.96],[1,2.16,12.92],[2,2.28,116.76]],"ltp":2.28,"tv":4074.16,"id":9629296},{"batb":[[0,1.91,104.72],[1,1.9,9.36],[2,1.88,79.8]],"batl":[[0,1.92,167.82],[1,1.94,79.26],[2,1.95,27.3]],"ltp":1.78,"tv":4255.71,"id":12343905}]}]}
{"op":"mcm","clk":"4231848745","pt":1631548789596,"mc":[{"id":"1.187560634","rc":[{"batb":[[2,1.88,15.96]],"ltp":1.78,"tv":4255.71,"id":12343905}]}]}
{"op":"mcm","clk":"4231849129","pt":1631548795200,"mc":[{"id":"1.187560634","rc":[{"batl":[[2,2.26,7.75]],"ltp":2.28,"tv":4074.16,"id":9629296}]}]}
{"op":"mcm","clk":"4231849400","pt":1631548799106,"mc":[{"id":"1.187560634","rc":[{"batb":[[2,1.95,49.07]],"ltp":2.28,"tv":4074.16,"id":9629296}]}]}
{"op":"mcm","clk":"4231849637","pt":1631548801548,"mc":[{"id":"1.187560634","rc":[{"trd":[[1.91,9.7]],"batb":[[0,1.91,102.33]],"ltp":1.91,"tv":4260.49,"id":12343905}],"tv":8334.65}]}
{"op":"mcm","clk":"4231849700","pt":1631548802199,"mc":[{"id":"1.187560634","rc":[{"trd":[[1.91,107.49]],"batb":[[0,1.91,53.43]],"ltp":1.91,"tv":4358.29,"id":12343905}],"tv":8432.45}]}
{"op":"mcm","clk":"4231849829","pt":1631548803701,"mc":[{"id":"1.187560634","rc":[{"trd":[[1.91,214.35]],"batb":[[0,1.9,9.36],[1,1.88,15.96],[2,1.87,86.16]],"batl":[[0,1.91,66.57],[1,1.92,167.82],[2,1.94,79.26]],"ltp":1.91,"tv":4465.15,"id":12343905}],"tv":8539.31}]}
{"op":"mcm","clk":"4231850116","pt":1631548807440,"mc":[{"id":"1.187560634","rc":[{"batl":[[0,1.92,167.82],[1,1.94,79.26],[2,1.95,27.3]],"ltp":1.91,"tv":4465.15,"id":12343905}]}]}
{"op":"mcm","clk":"4231850581","pt":1631548813952,"mc":[{"id":"1.187560634","rc":[{"trd":[[1.9,18.72]],"batb":[[0,1.88,15.96],[1,1.87,86.16],[2,1.86,7.98]],"batl":[[0,1.9,50.64],[1,1.92,167.82],[2,1.94,79.26]],"ltp":1.9,"tv":4483.87,"id":12343905}],"tv":8558.03}]}
{"op":"mcm","clk":"4231850756","pt":1631548816316,"mc":[{"id":"1.187560634","rc":[{"batl":[[0,1.9,51.09]],"ltp":1.9,"tv":4483.87,"id":12343905}]}]}
{"op":"mcm","clk":"4231850844","pt":1631548817518,"mc":[{"id":"1.187560634","rc":[{"batl":[[0,1.9,51.86]],"ltp":1.9,"tv":4483.87,"id":12343905}]}]}
{"op":"mcm","clk":"4231850892","pt":1631548818358,"mc":[{"id":"1.187560634","rc":[{"trd":[[2.1,50.5]],"ltp":2.1,"tv":4081.34,"id":9629296},{"trd":[[1.9,26.66]],"batl":[[0,1.9,43.92]],"ltp":1.9,"tv":4491.81,"id":12343905}],"tv":8573.15}]}
{"op":"mcm","clk":"4231851044","pt":1631548820659,"mc":[{"id":"1.187560634","rc":[{"batb":[[0,2,5],[1,1.95,49.07],[2,1.9,27.06]],"batl":[[0,2.26,7.75],[1,2.32,6.86],[2,2.68,5.64]],"ltp":2.1,"tv":4081.34,"id":9629296},{"batb":[[0,1.85,28.77],[1,1.8,28.83],[2,1.76,35.98]],"batl":[[1,2.12,7.96],[2,2.14,8.75]],"ltp":1.9,"tv":4491.81,"id":12343905}]}]}
{"op":"mcm","clk":"4231851103","pt":1631548821545,"mc":[{"id":"1.187560634","rc":[{"batb":[[1,1.9,27.06],[2,1.88,25.96]],"batl":[[0,2.32,6.86],[1,3.25,4.8],[2,3.4,3.64]],"ltp":2.1,"tv":4081.34,"id":9629296},{"batb":[[0,1.76,35.98],[1,1.74,34.73],[2,1.42,64.44]],"ltp":1.9,"tv":4491.81,"id":12343905}]}]}
{"op":"mcm","clk":"4231851224","pt":1631548823533,"mc":[{"id":"1.187560634","rc":[{"batb":[[0,1.76,124.02],[1,1.74,141.36]],"ltp":1.9,"tv":4491.81,"id":12343905}]}]}
{"op":"mcm","clk":"4231851342","pt":1631548825043,"mc":[{"id":"1.187560634","rc":[{"batb":[[1,1.74,141.19]],"ltp":1.9,"tv":4491.81,"id":12343905}]}]}
{"op":"mcm","clk":"4231851557","pt":1631548828450,"mc":[{"id":"1.187560634","rc":[{"batb":[[0,2.24,7.83],[1,2,5],[2,1.9,27.06]],"batl":[[1,2.42,74.96],[2,3.25,4.8]],"ltp":2.1,"tv":4081.34,"id":9629296},{"trd":[[1.8,246.97]],"batb":[[0,1.76,142.16]],"batl":[[0,1.8,87.96],[1,1.82,74.3],[2,1.83,16.4]],"ltp":1.8,"tv":4546.37,"id":12343905}],"tv":8627.71}]}
{"op":"mcm","clk":"4231851623","pt":1631548829340,"mc":[{"id":"1.187560634","rc":[{"batb":[[1,2.06,40.51],[2,2,5]],"ltp":2.1,"tv":4081.34,"id":9629296},{"batb":[[1,1.74,158.43],[2,1.73,8.62]],"ltp":1.8,"tv":4546.37,"id":12343905}]}]}
{"op":"mcm","clk":"4231851806","pt":1631548832270,"mc":[{"id":"1.187560634","rc":[{"trd":[[2.2,386.15],[2.24,114.26]],"batb":[[0,2.06,40.51],[1,2,5],[2,1.91,52.09]],"ltp":2.2,"tv":4189.17,"id":9629296},{"trd":[[1.8,334.93],[1.82,88.49]],"batl":[[0,1.82,48.32],[1,1.83,16.4],[2,1.84,98.22]],"ltp":1.82,"tv":4660.31,"id":12343905}],"tv":8849.48}]}
{"op":"mcm","clk":"4231851865","pt":1631548833163,"mc":[{"id":"1.187560634","rc":[{"batb":[[0,1.8,10.66],[1,1.76,142.16],[2,1.74,158.43]],"ltp":1.82,"tv":4660.31,"id":12343905}]}]}
{"op":"mcm","clk":"4231852008","pt":1631548835256,"mc":[{"id":"1.187560634","rc":[{"batb":[[0,2.06,48.59],[1,2.02,8.74],[2,2,5]],"batl":[[1,2.42,80.21],[2,2.48,5.49]],"ltp":2.2,"tv":4189.17,"id":9629296}]}]}
{"op":"mcm","clk":"4231852040","pt":1631548835774,"mc":[{"id":"1.187560634","rc":[{"batb":[[1,1.76,157.02]],"batl":[[0,1.82,59.95]],"ltp":1.82,"tv":4660.31,"id":12343905}]}]}
{"op":"mcm","clk":"4231852148","pt":1631548837185,"mc":[{"id":"1.187560634","rc":[{"batb":[[1,2.04,7.87],[2,2.02,8.74]],"batl":[[1,2.38,5.75],[2,2.42,80.21]],"ltp":2.2,"tv":4189.17,"id":9629296},{"batb":[[0,1.76,157.02],[1,1.74,158.43],[2,1.73,38.75]],"ltp":1.82,"tv":4660.31,"id":12343905}]}]}
{"op":"mcm","clk":"4231852352","pt":1631548840379,"mc":[{"id":"1.187560634","rc":[{"trd":[[1.82,109.81]],"batl":[[0,1.8,60],[2,1.84,8.2]],"ltp":1.82,"tv":4681.63,"id":12343905}],"tv":8870.8}]}
{"op":"mcm","clk":"4231852403","pt":1631548841615,"mc":[{"id":"1.187560634","rc":[{"batb":[[0,2.06,60.17]],"ltp":2.2,"tv":4189.17,"id":9629296}]}]}
{"op":"mcm","clk":"4231852501","pt":1631548842479,"mc":[{"id":"1.187560634","rc":[{"batb":[[0,1.76,138.88]],"ltp":1.82,"tv":4681.63,"id":12343905}]}]}
{"op":"mcm","clk":"4231852562","pt":1631548843269,"mc":[{"id":"1.187560634","rc":[{"batl":[[1,1.83,115.72]],"ltp":1.82,"tv":4681.63,"id":12343905}]}]}
{"op":"mcm","clk":"4231852714","pt":1631548845370,"mc":[{"id":"1.187560634","rc":[{"batl":[[0,2.28,11.59],[1,2.32,6.86],[2,2.38,5.75]],"ltp":2.2,"tv":4189.17,"id":9629296},{"batl":[[1,1.83,128.78]],"ltp":1.82,"tv":4681.63,"id":12343905}]}]}
{"op":"mcm","clk":"4231852906","pt":1631548848659,"mc":[{"id":"1.187560634","rc":[{"batb":[[0,2.06,48.59]],"batl":[[0,2.32,6.86],[1,2.38,5.75],[2,2.42,5.25]],"ltp":2.2,"tv":4189.17,"id":9629296},{"batb":[[1,1.74,141.19],[2,1.73,30.13]],"batl":[[1,1.83,99.32],[2,1.85,88.38]],"ltp":1.82,"tv":4681.63,"id":12343905}]}]}
{"op":"mcm","clk":"4231852973","pt":1631548849560,"mc":[{"id":"1.187560634","rc":[{"batb":[[0,2.02,8.74],[1,2,5],[2,1.91,52.09]],"batl":[[0,2.4,5.14],[1,2.46,6.25],[2,3.25,4.8]],"ltp":2.2,"tv":4189.17,"id":9629296},{"batb":[[0,1.77,150.07],[1,1.72,37.09],[2,1.69,34.21]],"batl":[[1,1.98,26.02],[2,3,5.2]],"ltp":1.82,"tv":4681.63,"id":12343905}]}]}
{"op":"mcm","clk":"4231853036","pt":1631548850474,"mc":[{"id":"1.187560634","rc":[{"batl":[[0,2.46,6.25],[1,3.25,4.8],[2,3.25,0]],"ltp":2.2,"tv":4189.17,"id":9629296},{"batb":[[1,1.69,34.21],[2,1.66,40.93]],"batl":[[0,1.98,26.02],[1,3,5.2],[2,880,0.01]],"ltp":1.82,"tv":4681.63,"id":12343905}]}]}
{"op":"mcm","clk":"4231853115","pt":1631548851668,"mc":[{"id":"1.187560634","rc":[{"batb":[[2,1.68,114.75]],"batl":[[0,1.98,84.46],[1,2,69.75],[2,3,5.2]],"ltp":1.82,"tv":4681.63,"id":12343905}]}]}
{"op":"mcm","clk":"4231853172","pt":1631548852462,"mc":[{"id":"1.187560634","rc":[{"batl":[[0,2.42,6.75],[1,2.46,6.25],[2,2.48,5.74]],"ltp":2.2,"tv":4189.17,"id":9629296},{"batb":[[1,1.71,34.19],[2,1.69,34.21]],"ltp":1.82,"tv":4681.63,"id":12343905}]}]}
{"op":"mcm","clk":"4231853478","pt":1631548856661,"mc":[{"id":"1.187560634","rc":[{"batl":[[0,1.98,26.02],[1,3,5.2],[2,3,0]],"ltp":1.82,"tv":4681.63,"id":12343905}]}]}
{"op":"mcm","clk":"4231853518","pt":1631548857392,"mc":[{"id":"1.187560634","rc":[{"batb":[[0,1.71,34.19],[1,1.69,34.21],[2,1.68,150.36]],"ltp":1.82,"tv":4681.63,"id":12343905}]}]}
{"op":"mcm","clk":"4231853543","pt":1631548857707,"mc":[{"id":"1.187560634","rc":[{"batl":[[0,2.46,6.25],[1,2.48,5.74],[2,3.25,4.8]],"ltp":2.2,"tv":4189.17,"id":9629296},{"batb":[[0,1.69,34.21],[1,1.68,150.36],[2,1.66,166.43]],"ltp":1.82,"tv":4681.63,"id":12343905}]}]}
{"op":"mcm","clk":"4231853663","pt":1631548859603,"mc":[{"id":"1.187560634","rc":[{"batb":[[0,2.34,15.54],[1,2.32,106.02],[2,2.3,6.4]],"batl":[[0,2.4,7.42],[1,2.46,6.25],[2,2.48,5.74]],"ltp":2.2,"tv":4189.17,"id":9629296},{"batb":[[2,1.66,297.75]],"batl":[[0,1.74,10.25],[1,1.83,383.28],[2,1.98,26.02]],"ltp":1.82,"tv":4681.63,"id":12343905}]}]}
{"op":"mcm","clk":"4231853726","pt":1631548860502,"mc":[{"id":"1.187560634","rc":[{"batl":[[0,1.74,100.01],[1,1.76,103.71],[2,1.83,383.28]],"ltp":1.82,"tv":4681.63,"id":12343905}]}]}
{"op":"mcm","clk":"4231854065","pt":1631548864487,"mc":[{"id":"1.187560634","rc":[{"batl":[[0,1.73,150.07],[1,1.74,100.01],[2,1.76,103.71]],"ltp":1.82,"tv":4681.63,"id":12343905}]}]}
{"op":"mcm","clk":"4231854164","pt":1631548865374,"mc":[{"id":"1.187560634","rc":[{"trd":[[2.4,21.99]],"batl":[[0,2.46,6.25],[1,2.48,5.74],[2,2.5,12]],"ltp":2.4,"tv":4196.59,"id":9629296},{"trd":[[1.71,107.7]],"batb":[[0,1.7,150.07],[1,1.69,34.21],[2,1.68,150.36]],"batl":[[0,1.71,20.8],[1,1.73,150.07],[2,1.74,100.01]],"ltp":1.71,"tv":4692.03,"id":12343905}],"tv":8888.62}]}
{"op":"mcm","clk":"4231854275","pt":1631548866583,"mc":[{"id":"1.187560634","rc":[{"batl":[[0,1.73,150.07],[1,1.74,100.01],[2,1.76,103.71]],"ltp":1.71,"tv":4692.03,"id":12343905}]}]}
{"op":"mcm","clk":"4231854395","pt":1631548868099,"mc":[{"id":"1.187560634","rc":[{"trd":[[1.7,289.39]],"batb":[[0,1.7,65.42]],"ltp":1.7,"tv":4861.38,"id":12343905}],"tv":9057.98}]}
{"op":"mcm","clk":"4231854600","pt":1631548871022,"mc":[{"id":"1.187560634","rc":[{"batl":[[2,2.5,17.39]],"ltp":2.4,"tv":4196.59,"id":9629296},{"trd":[[1.7,323.5]],"batb":[[0,1.7,48.36]],"ltp":1.7,"tv":4895.49,"id":12343905}],"tv":9092.08}]}
{"op":"mcm","clk":"4231854923","pt":1631548875416,"mc":[{"id":"1.187560634","rc":[{"trd":[[2.36,11.36]],"batb":[[1,2.32,92.6]],"ltp":2.36,"tv":4196.69,"id":9629296},{"trd":[[1.73,0.14]],"batl":[[0,1.73,149.93]],"ltp":1.73,"tv":4895.63,"id":12343905}],"tv":9092.32}]}
{"op":"mcm","clk":"4231855146","pt":1631548878024,"mc":[{"id":"1.187560634","rc":[{"batb":[[0,2.36,10.24],[1,2.34,15.54],[2,2.32,92.6]],"ltp":2.36,"tv":4196.69,"id":9629296},{"trd":[[1.7,330.43]],"batb":[[0,1.7,54.84]],"ltp":1.7,"tv":4902.55,"id":12343905}],"tv":9099.25}]}
{"op":"mcm","clk":"4231855707","pt":1631548884029,"mc":[{"id":"1.187560634","rc":[{"trd":[[2.36,11.5]],"batb":[[0,2.36,10.17]],"ltp":2.36,"tv":4196.83,"id":9629296}],"tv":9099.39}]}
{"op":"mcm","clk":"4231856012","pt":1631548886519,"mc":[{"id":"1.187560634","rc":[{"batb":[[0,2.34,9.13],[1,2.32,46.3],[2,2.3,3.2]],"batl":[[2,2.5,11.39]],"ltp":2.36,"tv":4196.83,"id":9629296},{"batb":[[0,1.7,44.9]],"ltp":1.7,"tv":4902.55,"id":12343905}]}]}
{"op":"mcm","clk":"4231856090","pt":1631548887150,"mc":[{"id":"1.187560634","rc":[{"batb":[[0,2.24,7.02],[1,2.2,6.82],[2,2.18,7.86]],"batl":[[0,2.54,5.75],[1,3.25,4.8],[2,2.5,0]],"ltp":2.36,"tv":4196.83,"id":9629296},{"batb":[[1,1.65,37.93],[2,1.6,46.64]],"batl":[[1,1.8,28.37],[2,1.83,33.5]],"ltp":1.7,"tv":4902.55,"id":12343905}]}]}
{"op":"mcm","clk":"4231856396","pt":1631548890557,"mc":[{"id":"1.187560634","rc":[{"batb":[[2,1.63,103.86]],"ltp":1.7,"tv":4902.55,"id":12343905}]}]}
{"op":"mcm","clk":"4231856744","pt":1631548894621,"mc":[{"id":"1.187560634","rc":[{"batb":[[0,1.65,37.93],[1,1.63,103.86],[2,1.62,68.89]],"ltp":1.7,"tv":4902.55,"id":12343905}]}]}
{"op":"mcm","clk":"4231856878","pt":1631548896458,"mc":[{"id":"1.187560634","rc":[{"batb":[[0,2.46,48.78],[1,2.44,2.42],[2,2.24,7.02]],"ltp":2.36,"tv":4196.83,"id":9629296},{"batb":[[2,1.62,188.82]],"batl":[[0,1.68,73.26],[1,1.69,63.76],[2,1.7,263.14]],"ltp":1.7,"tv":4902.55,"id":12343905}]}]}
{"op":"mcm","clk":"4231856964","pt":1631548897659,"mc":[{"id":"1.187560634","rc":[{"batb":[[2,2.32,29.19]],"ltp":2.36,"tv":4196.83,"id":9629296},{"batb":[[2,1.62,207.34]],"batl":[[1,1.69,28.26],[2,1.7,245.39]],"ltp":1.7,"tv":4902.55,"id":12343905}]}]}
{"op":"mcm","clk":"4231857022","pt":1631548898557,"mc":[{"id":"1.187560634","rc":[{"batl":[[0,1.67,106.92],[1,1.68,73.26],[2,1.69,28.26]],"ltp":1.7,"tv":4902.55,"id":12343905}]}]}
{"op":"mcm","clk":"4231857070","pt":1631548899248,"mc":[{"id":"1.187560634","rc":[{"batl":[[1,2.56,12.74],[2,3.25,4.8]],"ltp":2.36,"tv":4196.83,"id":9629296},{"batl":[[1,1.68,83.28]],"ltp":1.7,"tv":4902.55,"id":12343905}]}]}
{"op":"mcm","clk":"4231857392","pt":1631548903158,"mc":[{"id":"1.187560634","rc":[{"batb":[[2,2.38,5.96]],"batl":[[2,2.58,5.25]],"ltp":2.36,"tv":4196.83,"id":9629296},{"batb":[[1,1.64,37.07],[2,1.63,143.09]],"ltp":1.7,"tv":4902.55,"id":12343905}]}]}
{"op":"mcm","clk":"4231858420","pt":1631548915581,"mc":[{"id":"1.187560634","rc":[{"batb":[[0,2.46,40.65]],"batl":[[1,2.58,5.25],[2,2.6,5.46]],"ltp":2.36,"tv":4196.83,"id":9629296},{"batl":[[1,1.68,73.26],[2,1.69,19.38]],"ltp":1.7,"tv":4902.55,"id":12343905}]}]}
{"op":"mcm","clk":"4231858450","pt":1631548915954,"mc":[{"id":"1.187560634","rc":[{"batb":[[0,2.38,5.96],[1,2.34,6.22],[2,2.24,7.02]],"batl":[[0,3.25,4.8],[1,2.58,0],[2,2.6,0]],"ltp":2.36,"tv":4196.83,"id":9629296},{"batb":[[0,1.63,39.23],[1,1.57,50.16],[2,1.3,199.24]],"batl":[[1,1.72,32.16],[2,1.73,149.93]],"ltp":1.7,"tv":4902.55,"id":12343905}]}]}
{"op":"mcm","clk":"4231858704","pt":1631548919454,"mc":[{"id":"1.187560634","rc":[{"batl":[[0,2.6,5.81],[1,3.25,4.8]],"ltp":2.36,"tv":4196.83,"id":9629296}]}]}
{"op":"mcm","clk":"4231858793","pt":1631548920665,"mc":[{"id":"1.187560634","rc":[{"batl":[[0,1.72,32.16],[1,1.73,149.93],[2,1.74,37.75]],"ltp":1.7,"tv":4902.55,"id":12343905}]}]}
{"op":"mcm","clk":"4231858858","pt":1631548921597,"mc":[{"id":"1.187560634","rc":[{"batb":[[0,2.34,6.22],[1,2.24,7.02],[2,2.2,40.79]],"batl":[[0,2.52,21.76],[1,2.6,5.81],[2,3.25,4.8]],"ltp":2.36,"tv":4196.83,"id":9629296},{"batb":[[0,1.66,21.28],[1,1.64,104.16],[2,1.63,106.59]],"batl":[[0,1.67,20.5],[1,1.69,67.29],[2,1.71,114.26]],"ltp":1.7,"tv":4902.55,"id":12343905}]}]}
{"op":"mcm","clk":"4231858875","pt":1631548921870,"mc":[{"id":"1.187560634","rc":[{"batl":[[0,2.6,5.81],[1,3.25,4.8],[2,3.25,0]],"ltp":2.36,"tv":4196.83,"id":9629296},{"batb":[[0,1.64,104.16],[1,1.63,106.59],[2,1.57,50.16]],"batl":[[0,1.69,67.29],[1,1.71,114.26],[2,1.73,149.93]],"ltp":1.7,"tv":4902.55,"id":12343905}]}]}
{"op":"mcm","clk":"4231859027","pt":1631548924070,"mc":[{"id":"1.187560634","rc":[{"batb":[[0,2.38,6.17],[1,2.34,6.22],[2,2.24,7.02]],"ltp":2.36,"tv":4196.83,"id":9629296},{"batl":[[2,1.72,30.66]],"ltp":1.7,"tv":4902.55,"id":12343905}]}]}
{"op":"mcm","clk":"4231859099","pt":1631548924994,"mc":[{"id":"1.187560634","rc":[{"batl":[[1,1.7,105.03],[2,1.71,114.26]],"ltp":1.7,"tv":4902.55,"id":12343905}]}]}
{"op":"mcm","clk":"4231859286","pt":1631548927188,"mc":[{"id":"1.187560634","rc":[{"batb":[[0,1.63,39.23],[1,1.57,50.16],[2,1.3,199.24]],"batl":[[0,1.7,105.03],[1,1.72,30.66],[2,1.73,149.93]],"ltp":1.7,"tv":4902.55,"id":12343905}]}]}
{"op":"mcm","clk":"4231859529","pt":1631548930100,"mc":[{"id":"1.187560634","rc":[{"batb":[[1,1.6,101.99],[2,1.59,73.83]],"ltp":1.7,"tv":4902.55,"id":12343905}]}]}
{"op":"mcm","clk":"4231859853","pt":1631548933585,"mc":[{"id":"1.187560634","rc":[{"batb":[[1,1.57,50.16],[2,1.3,199.24]],"ltp":1.7,"tv":4902.55,"id":12343905}]}]}
{"op":"mcm","clk":"4231859901","pt":1631548934299,"mc":[{"id":"1.187560634","rc":[{"batb":[[0,2.34,6.22],[1,2.24,7.02],[2,2.2,40.79]],"ltp":2.36,"tv":4196.83,"id":9629296},{"batl":[[0,1.73,149.93],[1,1.74,133.91],[2,1.76,103.71]],"ltp":1.7,"tv":4902.55,"id":12343905}]}]}
{"op":"mcm","clk":"4231859942","pt":1631548934917,"mc":[{"id":"1.187560634","rc":[{"batl":[[0,1.74,133.91],[1,1.76,103.71],[2,1.8,28.37]],"ltp":1.7,"tv":4902.55,"id":12343905}]}]}
{"op":"mcm","clk":"4231860054","pt":1631548936324,"mc":[{"id":"1.187560634","rc":[{"batb":[[0,2.36,9.1],[1,2.34,6.22],[2,2.32,101.69]],"batl":[[0,2.42,6.01],[1,2.5,77.29],[2,2.6,5.81]],"ltp":2.36,"tv":4196.83,"id":9629296},{"batb":[[0,1.68,125.97],[1,1.67,8.92],[2,1.66,254.89]],"ltp":1.7,"tv":4902.55,"id":12343905}]}]}
{"op":"mcm","clk":"4231860188","pt":1631548937617,"mc":[{"id":"1.187560634","rc":[{"batb":[[2,1.66,295.49]],"batl":[[1,1.76,120.75],[2,1.77,8.52]],"ltp":1.7,"tv":4902.55,"id":12343905}]}]}
{"op":"mcm","clk":"4231860391","pt":1631548940482,"mc":[{"id":"1.187560634","rc":[{"batl":[[0,1.73,103.21],[1,1.74,133.91],[2,1.76,120.75]],"ltp":1.7,"tv":4902.55,"id":12343905}]}]}
{"op":"mcm","clk":"4231860655","pt":1631548944220,"mc":[{"id":"1.187560634","rc":[{"trd":[[2.42,43.05]],"batl":[[0,2.5,77.29],[1,2.52,6.26],[2,2.58,4.94]],"ltp":2.42,"tv":4202.84,"id":9629296},{"trd":[[1.66,447.84],[1.67,70.64],[1.68,491.98],[1.7,338.99]],"batb":[[0,1.66,115.35],[1,1.64,37.32],[2,1.63,39.23]],"ltp":1.66,"tv":5627.73,"id":12343905}],"tv":9830.58}]}
{"op":"mcm","clk":"4231860741","pt":1631548945423,"mc":[{"id":"1.187560634","rc":[{"batl":[[2,1.76,17.04]],"ltp":1.66,"tv":5627.73,"id":12343905}]}]}
{"op":"mcm","clk":"4231860827","pt":1631548946413,"mc":[{"id":"1.187560634","rc":[{"batb":[[0,2.42,4],[1,2.36,9.1],[2,2.34,6.22]],"ltp":2.42,"tv":4202.84,"id":9629296}]}]}
{"op":"mcm","clk":"4231860986","pt":1631548948599,"mc":[{"id":"1.187560634","rc":[{"batb":[[0,1.66,154.32],[1,1.65,64.86],[2,1.64,37.32]],"batl":[[1,1.74,37.75]],"ltp":1.66,"tv":5627.73,"id":12343905}]}]}
{"op":"mcm","clk":"4231861010","pt":1631548948910,"mc":[{"id":"1.187560634","rc":[{"batb":[[0,1.66,145.3]],"ltp":1.66,"tv":5627.73,"id":12343905}]}]}
{"op":"mcm","clk":"4231861198","pt":1631548951424,"mc":[{"id":"1.187560634","rc":[{"batl":[[2,2.54,5.75]],"ltp":2.42,"tv":4202.84,"id":9629296},{"batb":[[1,1.65,105.99]],"batl":[[0,1.71,73.52],[1,1.73,213.9],[2,1.74,37.75]],"ltp":1.66,"tv":5627.73,"id":12343905}]}]}
{"op":"mcm","clk":"4231861300","pt":1631548952533,"mc":[{"id":"1.187560634","rc":[{"batb":[[0,1.66,163.51]],"batl":[[0,1.71,82.36]],"ltp":1.66,"tv":5627.73,"id":12343905}]}]}
{"op":"mcm","clk":"4231861348","pt":1631548953014,"mc":[{"id":"1.187560634","rc":[{"batl":[[0,1.7,105.03],[1,1.71,82.36],[2,1.73,213.9]],"ltp":1.66,"tv":5627.73,"id":12343905}]}]}
{"op":"mcm","clk":"4231861447","pt":1631548954346,"mc":[{"id":"1.187560634","rc":[{"batb":[[1,2.34,6.22],[2,2.32,101.69]],"ltp":2.42,"tv":4202.84,"id":9629296}]}]}
{"op":"mcm","clk":"4231861628","pt":1631548956610,"mc":[{"id":"1.187560634","rc":[{"batb":[[1,2.3,6.78],[2,2.28,6.66]],"batl":[[0,2.54,5.75],[1,2.58,4.94],[2,2.6,5.81]],"ltp":2.42,"tv":4202.84,"id":9629296},{"batb":[[0,1.66,40.6],[1,1.65,41.13]],"batl":[[1,1.73,103.21],[2,1.76,36.52]],"ltp":1.66,"tv":5627.73,"id":12343905}]}]}
{"op":"mcm","clk":"4231861726","pt":1631548957538,"mc":[{"id":"1.187560634","rc":[{"batl":[[0,2.6,5.81],[1,3.25,4.8],[2,2.6,0]],"ltp":2.42,"tv":4202.84,"id":9629296},{"batb":[[0,1.63,39.23],[1,1.61,45.46],[2,1.3,199.24]],"ltp":1.66,"tv":5627.73,"id":12343905}]}]}
{"op":"mcm","clk":"4231861904","pt":1631548959615,"mc":[{"id":"1.187560634","rc":[{"batb":[[1,1.61,131.99],[2,1.6,72.64]],"ltp":1.66,"tv":5627.73,"id":12343905}]}]}
{"op":"mcm","clk":"4231861984","pt":1631548960514,"mc":[{"id":"1.187560634","rc":[{"batb":[[1,1.61,86.53],[2,1.6,119.11]],"ltp":1.66,"tv":5627.73,"id":12343905}]}]}
{"op":"mcm","clk":"4231862185","pt":1631548962721,"mc":[{"id":"1.187560634","rc":[{"batb":[[0,2.3,6.78],[1,2.28,6.66],[2,2.26,5.98]],"ltp":2.42,"tv":4202.84,"id":9629296}]}]}
{"op":"mcm","clk":"4231862503","pt":1631548966274,"mc":[{"id":"1.187560634","rc":[{"batb":[[0,2.28,6.66],[1,2.26,5.98],[2,2.24,7.02]],"ltp":2.42,"tv":4202.84,"id":9629296},{"batb":[[1,1.6,46.47],[2,1.3,199.24]],"batl":[[2,1.77,150.07]],"ltp":1.66,"tv":5627.73,"id":12343905}]}]}
{"op":"mcm","clk":"4231862620","pt":1631548967533,"mc":[{"id":"1.187560634","rc":[{"batl":[[0,1.77,150.07],[1,1.78,35.25],[2,1.79,33.5]],"ltp":1.66,"tv":5627.73,"id":12343905}]}]}
{"op":"mcm","clk":"4231862766","pt":1631548969148,"mc":[{"id":"1.187560634","rc":[{"batl":[[0,2.36,63.56],[1,2.38,31.78],[2,2.4,31.78]],"ltp":2.42,"tv":4202.84,"id":9629296},{"batb":[[0,1.76,15.58],[1,1.75,22.86],[2,1.74,110.4]],"ltp":1.66,"tv":5627.73,"id":12343905}]}]}
{"op":"mcm","clk":"4231862872","pt":1631548970448,"mc":[{"id":"1.187560634","rc":[{"batl":[[0,2.36,38.14],[1,2.38,19.07],[2,2.4,19.07]],"ltp":2.42,"tv":4202.84,"id":9629296},{"batb":[[2,1.74,145.21]],"ltp":1.66,"tv":5627.73,"id":12343905}]}]}
{"op":"mcm","clk":"4231862954","pt":1631548971565,"mc":[{"id":"1.187560634","rc":[{"batl":[[0,1.78,35.25],[1,1.79,33.5],[2,1.8,101.2]],"ltp":1.66,"tv":5627.73,"id":12343905}]}]}
{"op":"mcm","clk":"4231862976","pt":1631548971835,"mc":[{"id":"1.187560634","rc":[{"batb":[[0,2.26,5.98],[1,2.22,13.52],[2,2.2,13.58]],"ltp":2.42,"tv":4202.84,"id":9629296},{"batl":[[0,1.79,33.5],[1,1.8,72.83],[2,1.82,93.88]],"ltp":1.66,"tv":5627.73,"id":12343905}]}]}
{"op":"mcm","clk":"4231863110","pt":1631548973665,"mc":[{"id":"1.187560634","rc":[{"trd":[[1.76,96.84]],"batb":[[0,1.75,22.86],[1,1.74,145.21],[2,1.72,111.7]],"batl":[[0,1.76,85.88],[1,1.79,33.5],[2,1.8,72.83]],"ltp":1.76,"tv":5658.88,"id":12343905}],"tv":9861.73}]}
{"op":"mcm","clk":"4231863390","pt":1631548977338,"mc":[{"id":"1.187560634","rc":[{"batb":[[0,2.32,3],[1,2.26,5.98],[2,2.22,13.52]],"ltp":2.42,"tv":4202.84,"id":9629296}]}]}
{"op":"mcm","clk":"4231863665","pt":1631548980568,"mc":[{"id":"1.187560634","rc":[{"batb":[[0,2.26,5.98],[1,2.22,13.52],[2,2.2,13.58]],"ltp":2.42,"tv":4202.84,"id":9629296}]}]}
{"op":"mcm","clk":"4231863824","pt":1631548982375,"mc":[{"id":"1.187560634","rc":[{"trd":[[1.75,274.31]],"batb":[[0,1.75,21.22]],"ltp":1.75,"tv":5662.16,"id":12343905}],"tv":9865.01}]}
{"op":"mcm","clk":"4231863919","pt":1631548983477,"mc":[{"id":"1.187560634","rc":[{"trd":[[2.34,3]],"ltp":2.34,"tv":4205.84,"id":9629296},{"trd":[[1.75,278.32]],"batb":[[0,1.75,17.21]],"ltp":1.75,"tv":5666.17,"id":12343905}],"tv":9872.02}]}
{"op":"mcm","clk":"4231863942","pt":1631548983784,"mc":[{"id":"1.187560634","rc":[{"batl":[[2,1.8,64.25]],"ltp":1.75,"tv":5666.17,"id":12343905}]}]}
{"op":"mcm","clk":"4231864186","pt":1631548986771,"mc":[{"id":"1.187560634","rc":[{"batb":[[1,1.74,158.07]],"batl":[[1,1.78,12.21],[2,1.79,33.5]],"ltp":1.75,"tv":5666.17,"id":12343905}]}]}
{"op":"mcm","clk":"4231864475","pt":1631548990477,"mc":[{"id":"1.187560634","rc":[{"trd":[[1.75,283.44]],"batb":[[0,1.75,14.65]],"ltp":1.75,"tv":5671.29,"id":12343905}],"tv":9877.14}]}
{"op":"mcm","clk":"4231864860","pt":1631548995269,"mc":[{"id":"1.187560634","rc":[{"trd":[[2.34,11.53]],"ltp":2.34,"tv":4214.37,"id":9629296},{"trd":[[1.75,300.39]],"batb":[[0,1.74,158.54],[1,1.72,111.7],[2,1.66,39.78]],"ltp":1.75,"tv":5688.24,"id":12343905}],"tv":9902.62}]}
{"op":"mcm","clk":"4231864940","pt":1631548996669,"mc":[{"id":"1.187560634","rc":[{"batb":[[0,2.02,8.24],[1,2,5],[2,1.87,27.85]],"batl":[[0,2.54,5.25],[1,2.6,5.81],[2,2.62,5.25]],"ltp":2.34,"tv":4214.37,"id":9629296},{"batb":[[0,1.65,41.93],[1,1.63,82.6],[2,1.62,39.54]],"batl":[[1,1.97,28.27],[2,3,5.2]],"ltp":1.75,"tv":5688.24,"id":12343905}]}]}
{"op":"mcm","clk":"4231864958","pt":1631548996876,"mc":[{"id":"1.187560634","rc":[{"batl":[[0,2.6,5.81],[1,2.62,5.25],[2,3.25,4.8]],"ltp":2.34,"tv":4214.37,"id":9629296},{"batb":[[0,1.63,82.6],[1,1.62,39.54],[2,1.3,199.24]],"ltp":1.75,"tv":5688.24,"id":12343905}]}]}
{"op":"mcm","clk":"4231865130","pt":1631548999471,"mc":[{"id":"1.187560634","rc":[{"batb":[[0,2.04,8.37],[1,2.02,8.24],[2,2,5]],"ltp":2.34,"tv":4214.37,"id":9629296},{"batb":[[0,1.64,89.57],[1,1.63,150.46],[2,1.62,39.54]],"batl":[[1,1.91,28.27],[2,1.96,28.37]],"ltp":1.75,"tv":5688.24,"id":12343905}]}]}
{"op":"mcm","clk":"4231865195","pt":1631549000202,"mc":[{"id":"1.187560634","rc":[{"batb":[[0,1.63,82.6],[1,1.62,39.54],[2,1.3,199.24]],"batl":[[0,1.96,29.14],[1,1.97,27.5],[2,3,5.2]],"ltp":1.75,"tv":5688.24,"id":12343905}]}]}
{"op":"mcm","clk":"4231865302","pt":1631549002071,"mc":[{"id":"1.187560634","rc":[{"batb":[[0,1.78,84.05],[1,1.76,103.26],[2,1.63,82.6]],"batl":[[0,1.84,71.21],[1,1.86,87.62],[2,1.96,29.14]],"ltp":1.75,"tv":5688.24,"id":12343905}]}]}
{"op":"mcm","clk":"4231865386","pt":1631549003574,"mc":[{"id":"1.187560634","rc":[{"batb":[[0,2.08,8.06],[1,2.04,8.37],[2,2.02,8.24]],"batl":[[0,2.52,4.76],[1,2.6,5.81],[2,2.62,5.25]],"ltp":2.34,"tv":4214.37,"id":9629296},{"batb":[[2,1.66,41.78]],"batl":[[0,1.82,83.05],[1,1.84,71.21],[2,1.86,87.62]],"ltp":1.75,"tv":5688.24,"id":12343905}]}]}
{"op":"mcm","clk":"4231865394","pt":1631549003680,"mc":[{"id":"1.187560634","rc":[{"batb":[[0,2.04,8.37],[1,2.02,8.24],[2,2,5]],"ltp":2.34,"tv":4214.37,"id":9629296}]}]}
{"op":"mcm","clk":"4231865721","pt":1631549008283,"mc":[{"id":"1.187560634","rc":[{"batl":[[0,2.6,5.81],[1,2.62,5.25],[2,3.25,4.8]],"ltp":2.34,"tv":4214.37,"id":9629296},{"batb":[[0,1.63,82.6],[1,1.62,39.54],[2,1.3,199.24]],"batl":[[1,1.96,29.14],[2,1.97,27.5]],"ltp":1.75,"tv":5688.24,"id":12343905}]}]}
{"op":"mcm","clk":"4231865907","pt":1631549010887,"mc":[{"id":"1.187560634","rc":[{"batb":[[0,1.64,89.57],[1,1.63,150.46],[2,1.62,39.54]],"ltp":1.75,"tv":5688.24,"id":12343905}]}]}
{"op":"mcm","clk":"4231866007","pt":1631549012601,"mc":[{"id":"1.187560634","rc":[{"batl":[[1,3,5.97],[2,1.97,0]],"ltp":1.75,"tv":5688.24,"id":12343905}]}]}
{"op":"mcm","clk":"4231866259","pt":1631549015581,"mc":[{"id":"1.187560634","rc":[{"batb":[[0,2.48,2.51],[1,2.34,85.48],[2,2.28,208.91]],"batl":[[0,2.56,115.14],[1,2.6,5.81],[2,2.62,5.25]],"ltp":2.34,"tv":4214.37,"id":9629296},{"batl":[[0,1.67,11.5],[1,1.68,98.86],[2,1.69,128.34]],"ltp":1.75,"tv":5688.24,"id":12343905}]}]}
{"op":"mcm","clk":"4231866335","pt":1631549016515,"mc":[{"id":"1.187560634","rc":[{"batb":[[1,2.34,51.29]],"ltp":2.34,"tv":4214.37,"id":9629296},{"batl":[[1,1.68,63.15],[2,1.69,110.48]],"ltp":1.75,"tv":5688.24,"id":12343905}]}]}
{"op":"mcm","clk":"4231866721","pt":1631549022079,"mc":[{"id":"1.187560634","rc":[{"trd":[[1.64,23.66]],"batb":[[0,1.64,77.74]],"batl":[[0,1.66,91.05],[1,1.67,11.5],[2,1.68,63.15]],"ltp":1.64,"tv":5711.9,"id":12343905}],"tv":9926.27}]}
{"op":"mcm","clk":"4231867375","pt":1631549030640,"mc":[{"id":"1.187560634","rc":[{"trd":[[1.66,456.37]],"batl":[[0,1.66,86.78]],"ltp":1.66,"tv":5720.43,"id":12343905}],"tv":9934.8}]}
{"op":"mcm","clk":"4231867431","pt":1631549031531,"mc":[{"id":"1.187560634","rc":[{"trd":[[2.5,0.06]],"ltp":2.5,"tv":4214.43,"id":9629296},{"trd":[[1.66,456.46]],"batl":[[0,1.66,86.69]],"ltp":1.66,"tv":5720.52,"id":12343905}],"tv":9934.96}]}
{"op":"mcm","clk":"4231867562","pt":1631549033625,"mc":[{"id":"1.187560634","rc":[{"trd":[[2.5,2.23]],"ltp":2.5,"tv":4216.6,"id":9629296},{"trd":[[1.66,579.69]],"batl":[[0,1.66,23.46]],"ltp":1.66,"tv":5843.75,"id":12343905}],"tv":10060.36}]}
{"op":"mcm","clk":"4231867756","pt":1631549036041,"mc":[{"id":"1.187560634","rc":[{"trd":[[1.66,591.63]],"batl":[[0,1.66,17.49]],"ltp":1.66,"tv":5855.69,"id":12343905}],"tv":10072.29}]}
{"op":"mcm","clk":"4231867842","pt":1631549037024,"mc":[{"id":"1.187560634","rc":[{"trd":[[1.66,626.62]],"batb":[[0,1.66,7.5],[1,1.64,77.74],[2,1.63,150.46]],"batl":[[0,1.67,11.5],[1,1.68,63.15],[2,1.69,110.48]],"ltp":1.66,"tv":5890.68,"id":12343905}],"tv":10107.28}]}
{"op":"mcm","clk":"4231867974","pt":1631549038540,"mc":[{"id":"1.187560634","rc":[{"batl":[[0,2.56,126.18]],"ltp":2.5,"tv":4216.6,"id":9629296}]}]}
{"op":"mcm","clk":"4231867989","pt":1631549038745,"mc":[{"id":"1.187560634","rc":[{"batl":[[0,2.56,115.14]],"ltp":2.5,"tv":4216.6,"id":9629296}]}]}
{"op":"mcm","clk":"4231868130","pt":1631549040412,"mc":[{"id":"1.187560634","rc":[{"batb":[[0,1.64,77.74],[1,1.63,150.46],[2,1.62,39.54]],"ltp":1.66,"tv":5890.68,"id":12343905}]}]}
{"op":"mcm","clk":"4231868274","pt":1631549042240,"mc":[{"id":"1.187560634","rc":[{"trd":[[2.48,5.34]],"batb":[[0,2.34,51.29],[1,2.28,208.91],[2,2.26,31.62]],"ltp":2.48,"tv":4221.94,"id":9629296},{"trd":[[1.67,71.12]],"batl":[[0,1.67,11.02]],"ltp":1.67,"tv":5891.16,"id":12343905}],"tv":10113.1}]}
{"op":"mcm","clk":"4231870015","pt":1631549063431,"mc":[{"id":"1.187560634","rc":[{"trd":[[2.48,7.05]],"ltp":2.48,"tv":4223.65,"id":9629296},{"trd":[[1.67,73.65]],"batl":[[0,1.67,8.49]],"ltp":1.67,"tv":5893.69,"id":12343905}],"tv":10117.34}]}
{"op":"mcm","clk":"4231872121","pt":1631549089501,"mc":[{"id":"1.187560634","rc":[{"trd":[[2.48,7.5]],"ltp":2.48,"tv":4224.1,"id":9629296},{"trd":[[1.67,74.32]],"batl":[[0,1.67,7.82]],"ltp":1.67,"tv":5894.36,"id":12343905}],"tv":10118.46}]}
{"op":"mcm","clk":"4231872288","pt":1631549091916,"mc":[{"id":"1.187560634","rc":[{"batb":[[0,1.63,82.6],[1,1.62,39.54],[2,1.61,18.64]],"batl":[[2,1.69,26.78]],"ltp":1.67,"tv":5894.36,"id":12343905}]}]}
{"op":"mcm","clk":"4231872548","pt":1631549095115,"mc":[{"id":"1.187560634","rc":[{"batb":[[0,1.64,83.01],[1,1.63,150.43],[2,1.62,39.54]],"batl":[[2,1.69,116.83]],"ltp":1.67,"tv":5894.36,"id":12343905}]}]}
{"op":"mcm","clk":"4231874057","pt":1631549107838,"mc":[{"id":"1.187560634","rc":[{"batb":[[0,2.34,58.01],[1,2.28,215.57]],"ltp":2.48,"tv":4224.1,"id":9629296}]}]}
{"op":"mcm","clk":"4231874233","pt":1631549109412,"mc":[{"id":"1.187560634","rc":[{"trd":[[2.48,9.66]],"ltp":2.48,"tv":4226.26,"id":9629296},{"trd":[[1.67,77.54]],"batl":[[0,1.67,4.6]],"ltp":1.67,"tv":5897.58,"id":12343905}],"tv":10123.84}]}
{"op":"mcm","clk":"4231874387","pt":1631549110630,"mc":[{"id":"1.187560634","rc":[{"batb":[[0,2.34,6.72],[1,2.26,31.62],[2,2.08,39.34]],"batl":[[0,2.94,4.25],[1,3.15,3.9],[2,3.25,4.8]],"ltp":2.48,"tv":4226.26,"id":9629296},{"batb":[[0,1.63,43.37],[1,1.52,48.99],[2,1.51,57.88]],"batl":[[0,1.74,30.75],[1,1.77,34.5],[2,3,5.97]],"ltp":1.67,"tv":5897.58,"id":12343905}]}]}
{"op":"mcm","clk":"4231874440","pt":1631549111102,"mc":[{"id":"1.187560634","rc":[{"batb":[[0,2.08,39.34],[1,2,5],[2,1.01,105.79]],"batl":[[0,3.15,3.9],[1,3.25,4.8],[2,990,0.01]],"ltp":2.48,"tv":4226.26,"id":9629296},{"batb":[[0,1.51,57.88],[1,1.47,52.67],[2,1.1,2]],"batl":[[0,1.77,34.5],[1,3,5.97],[2,990,0.01]],"ltp":1.67,"tv":5897.58,"id":12343905}]}]}
{"op":"mcm","clk":"4231874678","pt":1631549113612,"mc":[{"id":"1.187560634","rc":[{"batb":[[0,1.51,177.27],[1,1.5,93.34],[2,1.47,52.67]],"batl":[[1,1.8,105.13],[2,1.82,93.76]],"ltp":1.67,"tv":5897.58,"id":12343905}]}]}
{"op":"mcm","clk":"4231874748","pt":1631549114236,"mc":[{"id":"1.187560634","rc":[{"batb":[[0,2.28,6.16],[1,2.08,39.34],[2,2,5]],"ltp":2.48,"tv":4226.26,"id":9629296}]}]}
{"op":"mcm","clk":"4231874889","pt":1631549116120,"mc":[{"id":"1.187560634","rc":[{"batl":[[0,2.48,19.84],[1,3.15,3.9],[2,3.25,4.8]],"ltp":2.48,"tv":4226.26,"id":9629296},{"batl":[[1,3,5.97],[2,990,0.01]],"ltp":1.67,"tv":5897.58,"id":12343905}]}]}
{"op":"mcm","clk":"4231874999","pt":1631549117420,"mc":[{"id":"1.187560634","rc":[{"batb":[[0,2.34,5.72],[1,2.28,6.16],[2,2.08,39.34]],"batl":[[1,2.94,4.25],[2,3.15,3.9]],"ltp":2.48,"tv":4226.26,"id":9629296},{"batb":[[0,1.52,42.99],[1,1.51,177.27],[2,1.5,93.34]],"batl":[[0,1.74,31.25],[1,1.77,34.5],[2,3,5.97]],"ltp":1.67,"tv":5897.58,"id":12343905}]}]}
{"op":"mcm","clk":"4231875115","pt":1631549118627,"mc":[{"id":"1.187560634","rc":[{"trd":[[2.48,29.5]],"batb":[[0,2.78,2]],"batl":[[0,2.88,7.85],[1,2.92,93.26]],"ltp":2.48,"tv":4246.1,"id":9629296},{"trd":[[1.67,107]],"batb":[[0,1.51,177.27],[1,1.5,93.34],[2,1.47,52.67]],"batl":[[0,1.55,71.51],[1,1.56,323.07],[2,1.57,48.08]],"ltp":1.67,"tv":5927.04,"id":12343905}],"tv":10173.14}]}
{"op":"mcm","clk":"4231875184","pt":1631549119457,"mc":[{"id":"1.187560634","rc":[{"batb":[[1,2.54,22.65],[2,2.3,30.11]],"ltp":2.48,"tv":4246.1,"id":9629296},{"batb":[[1,1.5,193.34],[2,1.49,50]],"batl":[[1,1.56,246.15],[2,1.57,9.62]],"ltp":1.67,"tv":5927.04,"id":12343905}]}]}
{"op":"mcm","clk":"4231875206","pt":1631549119723,"mc":[{"id":"1.187560634","rc":[{"batb":[[1,1.5,113.34],[2,1.49,10]],"ltp":1.67,"tv":5927.04,"id":12343905}]}]}
{"op":"mcm","clk":"4231875709","pt":1631549125738,"mc":[{"id":"1.187560634","rc":[{"batb":[[1,2.56,5.83],[2,2.54,22.65]],"ltp":2.48,"tv":4246.1,"id":9629296}]}]}
{"op":"mcm","clk":"4231876153","pt":1631549129621,"mc":[{"id":"1.187560634","rc":[{"batb":[[0,2.3,30.11],[1,2,5],[2,1.01,105.79]],"batl":[[0,3.25,4.8],[1,3.6,3.11],[2,3.95,2.7]],"ltp":2.48,"tv":4246.1,"id":9629296},{"batb":[[0,1.55,60],[1,1.39,140.36],[2,1.34,81.22]],"batl":[[0,1.67,37.5],[1,3,5.97],[2,990,0.01]],"ltp":1.67,"tv":5927.04,"id":12343905}]}]}
{"op":"mcm","clk":"4231876622","pt":1631549132246,"mc":[{"id":"1.187560634","rc":[{"batb":[[2,1.38,205.21]],"batl":[[0,1.66,75.33],[1,1.67,99.59],[2,3,5.97]],"ltp":1.67,"tv":5927.04,"id":12343905}]}]}
{"op":"mcm","clk":"4231876698","pt":1631549133142,"mc":[{"id":"1.187560634","rc":[{"batb":[[0,2.48,5.26],[1,2.3,30.11],[2,2,5]],"ltp":2.48,"tv":4246.1,"id":9629296}]}]}
{"op":"mcm","clk":"4231876913","pt":1631549136365,"mc":[{"id":"1.187560634","rc":[{"batb":[[0,2.56,5.83],[1,2.48,5.26],[2,2.3,30.11]],"ltp":2.48,"tv":4246.1,"id":9629296},{"batb":[[0,1.39,140.36],[1,1.38,205.21],[2,1.37,139.45]],"batl":[[0,1.64,42.43],[1,1.66,75.33],[2,1.67,99.59]],"ltp":1.67,"tv":5927.04,"id":12343905}]}]}
{"op":"mcm","clk":"4231876994","pt":1631549137464,"mc":[{"id":"1.187560634","rc":[{"batb":[[0,2.48,5.26],[1,2.3,30.11],[2,2,5]],"ltp":2.48,"tv":4246.1,"id":9629296},{"batl":[[0,1.66,75.33],[1,1.67,99.59],[2,3,5.97]],"ltp":1.67,"tv":5927.04,"id":12343905}]}]}
{"op":"mcm","clk":"4231877174","pt":1631549140249,"mc":[{"id":"1.187560634","rc":[{"batl":[[0,1.66,84.71]],"ltp":1.67,"tv":5927.04,"id":12343905}]}]}
{"op":"mcm","clk":"4231877427","pt":1631549143482,"mc":[{"id":"1.187560634","rc":[{"batb":[[0,2.56,5.83],[1,2.48,5.26],[2,2.3,30.11]],"ltp":2.48,"tv":4246.1,"id":9629296},{"batl":[[0,1.64,38.18],[1,1.66,84.71],[2,1.67,99.59]],"ltp":1.67,"tv":5927.04,"id":12343905}]}]}
{"op":"mcm","clk":"4231877447","pt":1631549143750,"mc":[{"id":"1.187560634","rc":[{"batb":[[0,2.48,5.26],[1,2.3,30.11],[2,2,5]],"ltp":2.48,"tv":4246.1,"id":9629296},{"batl":[[0,1.66,84.71],[1,1.67,99.59],[2,3,5.97]],"ltp":1.67,"tv":5927.04,"id":12343905}]}]}
{"op":"mcm","clk":"4231877514","pt":1631549144791,"mc":[{"id":"1.187560634","rc":[{"batb":[[1,1.34,81.22],[2,1.1,2]],"ltp":1.67,"tv":5927.04,"id":12343905}]}]}
{"op":"mcm","clk":"4231877691","pt":1631549147586,"mc":[{"id":"1.187560634","rc":[{"batb":[[0,2.56,6.08],[1,2.48,5.26],[2,2.4,90.05]],"batl":[[0,2.6,8.04],[1,2.62,1176.96],[2,3.25,4.8]],"ltp":2.48,"tv":4246.1,"id":9629296},{"batb":[[0,1.62,131.61],[1,1.61,217.38],[2,1.6,46.58]],"batl":[[0,1.64,44.68],[1,1.66,99.76],[2,1.67,99.59]],"ltp":1.67,"tv":5927.04,"id":12343905}]}]}
{"op":"mcm","clk":"4231877773","pt":1631549148588,"mc":[{"id":"1.187560634","rc":[{"batb":[[0,2.48,5.26],[1,2.4,90.05],[2,2.3,30.11]],"batl":[[1,3.25,4.8],[2,3.6,3.11]],"ltp":2.48,"tv":4246.1,"id":9629296},{"batb":[[1,1.61,283.3],[2,1.6,100.68]],"batl":[[0,1.66,99.76],[1,1.67,99.59],[2,1.68,89.28]],"ltp":1.67,"tv":5927.04,"id":12343905}]}]}
{"op":"mcm","clk":"4231877799","pt":1631549148890,"mc":[{"id":"1.187560634","rc":[{"batb":[[1,1.61,246.04],[2,1.6,82.05]],"batl":[[2,1.68,17.86]],"ltp":1.67,"tv":5927.04,"id":12343905}]}]}
{"op":"mcm","clk":"4231878335","pt":1631549156411,"mc":[{"id":"1.187560634","rc":[{"batb":[[0,2.28,7.66],[1,2.1,38.58],[2,2,5]],"batl":[[0,3.25,4.8],[1,3.35,3.7],[2,990,0.01]],"ltp":2.48,"tv":4246.1,"id":9629296},{"batb":[[0,1.47,64.76],[1,1.43,57.43],[2,1.1,2]],"batl":[[0,1.77,35.5],[1,3,5.97],[2,990,0.01]],"ltp":1.67,"tv":5927.04,"id":12343905}]}]}
{"op":"mcm","clk":"4231878512","pt":1631549158985,"mc":[{"id":"1.187560634","rc":[{"batb":[[0,1.47,175.11],[1,1.46,104.33],[2,1.43,57.43]],"batl":[[1,1.78,70.36],[2,1.8,97.3]],"ltp":1.67,"tv":5927.04,"id":12343905}]}]}
{"op":"mcm","clk":"4231878697","pt":1631549161503,"mc":[{"id":"1.187560634","rc":[{"batl":[[1,3,5.97],[2,990,0.01]],"ltp":1.67,"tv":5927.04,"id":12343905}]}]}
{"op":"mcm","clk":"4231878927","pt":1631549164498,"mc":[{"id":"1.187560634","rc":[{"batb":[[0,2.92,2],[1,2.82,42.55],[2,2.28,7.66]],"batl":[[0,3.05,9.31],[1,3.25,4.8],[2,3.35,3.7]],"ltp":2.48,"tv":4246.1,"id":9629296},{"batb":[[0,1.48,178.38],[1,1.47,175.11],[2,1.46,104.33]],"batl":[[0,1.51,113.32],[1,1.52,110.7],[2,1.53,58.82]],"ltp":1.67,"tv":5927.04,"id":12343905}]}]}
{"op":"mcm","clk":"4231879007","pt":1631549165522,"mc":[{"id":"1.187560634","rc":[{"batb":[[2,2.68,19.8]],"ltp":2.48,"tv":4246.1,"id":9629296},{"batb":[[1,1.47,195.51],[2,1.46,114.53]],"batl":[[2,1.53,19.6]],"ltp":1.67,"tv":5927.04,"id":12343905}]}]}
{"op":"mcm","clk":"4231879273","pt":1631549169607,"mc":[{"id":"1.187560634","rc":[{"trd":[[1.51,36.22]],"batl":[[0,1.51,96.92]],"ltp":1.51,"tv":5959.84,"id":12343905}],"tv":10205.94}]}
{"op":"mcm","clk":"4231879460","pt":1631549172427,"mc":[{"id":"1.187560634","rc":[{"trd":[[2.96,1.62]],"ltp":2.96,"tv":4247.72,"id":9629296},{"trd":[[1.51,39.4]],"batl":[[0,1.51,93.74]],"ltp":1.51,"tv":5963.02,"id":12343905}],"tv":10210.74}]}
{"op":"mcm","clk":"4231879506","pt":1631549173102,"mc":[{"id":"1.187560634","rc":[{"batl":[[0,1.51,108.88]],"ltp":1.51,"tv":5963.02,"id":12343905}]}]}
{"op":"mcm","clk":"4231879657","pt":1631549175228,"mc":[{"id":"1.187560634","rc":[{"batb":[[0,2.48,5.26],[1,2.36,28.02],[2,2,5]],"batl":[[0,3.25,5.3],[1,4.8,2.27],[2,990,0.01]],"ltp":2.96,"tv":4247.72,"id":9629296},{"batb":[[0,1.33,99.31],[1,1.27,84.87],[2,1.1,2]],"batl":[[0,1.67,36.5],[1,3,5.97],[2,990,0.01]],"ltp":1.51,"tv":5963.02,"id":12343905}]}]}
{"op":"mcm","clk":"4231879940","pt":1631549178624,"mc":[{"id":"1.187560634","rc":[{"batl":[[1,4.1,2.85],[2,4.8,2.27]],"ltp":2.96,"tv":4247.72,"id":9629296},{"batb":[[0,1.33,299.4],[1,1.32,166.32],[2,1.27,84.87]],"batl":[[0,1.63,104.63],[1,1.64,66.36],[2,1.67,36.5]],"ltp":1.51,"tv":5963.02,"id":12343905}]}]}
{"op":"mcm","clk":"4231880615","pt":1631549185441,"mc":[{"id":"1.187560634","rc":[{"batb":[[0,2.58,5.56],[1,2.48,5.26],[2,2.36,28.02]],"ltp":2.96,"tv":4247.72,"id":9629296},{"batl":[[0,1.63,144.13]],"ltp":1.51,"tv":5963.02,"id":12343905}]}]}
{"op":"mcm","clk":"4231880649","pt":1631549185755,"mc":[{"id":"1.187560634","rc":[{"batb":[[0,2.48,5.26],[1,2.36,28.02],[2,2,5]],"ltp":2.96,"tv":4247.72,"id":9629296},{"batl":[[0,1.63,104.63]],"ltp":1.51,"tv":5963.02,"id":12343905}]}]}
{"op":"mcm","clk":"4231880761","pt":1631549186720,"mc":[{"id":"1.187560634","rc":[{"batl":[[0,1.67,36.5],[1,3,5.97],[2,990,0.01]],"ltp":1.51,"tv":5963.02,"id":12343905}]}]}
{"op":"mcm","clk":"4231881042","pt":1631549189662,"mc":[{"id":"1.187560634","rc":[{"trd":[[2.96,2.12],[3.25,27.94]],"batb":[[0,3.6,43.68],[1,3.55,20.84],[2,3.5,20.84]],"batl":[[0,3.85,7.45]],"ltp":3.25,"tv":4253.02,"id":9629296},{"trd":[[1.44,13.54],[1.51,40.38]],"batb":[[0,1.34,224.82],[1,1.33,299.4],[2,1.32,166.32]],"batl":[[0,1.36,150.83],[1,1.37,234.83],[2,1.38,7.25]],"ltp":1.44,"tv":5974.83,"id":12343905}],"tv":10227.85}]}
{"op":"mcm","clk":"4231881138","pt":1631549190630,"mc":[{"id":"1.187560634","rc":[{"batb":[[0,3.6,27.01],[1,3.55,12.5],[2,3.5,12.5]],"ltp":3.25,"tv":4253.02,"id":9629296},{"batb":[[0,1.34,336.76],[1,1.33,355.36],[2,1.32,222.28]],"ltp":1.44,"tv":5974.83,"id":12343905}]}]}
{"op":"mcm","clk":"4231881169","pt":1631549190947,"mc":[{"id":"1.187560634","rc":[{"batb":[[0,1.34,247.2],[1,1.33,310.6],[2,1.32,177.52]],"ltp":1.44,"tv":5974.83,"id":12343905}]}]}
{"op":"mcm","clk":"4231881314","pt":1631549192554,"mc":[{"id":"1.187560634","rc":[{"trd":[[1.36,73.08]],"batl":[[0,1.36,148.81]],"ltp":1.36,"tv":5978.87,"id":12343905}],"tv":10231.89}]}
{"op":"mcm","clk":"4231882071","pt":1631549201638,"mc":[{"id":"1.187560634","rc":[{"trd":[[3.85,2.09]],"batb":[[0,3.15,3.63],[1,3,5],[2,2.84,42.02]],"batl":[[0,5.4,2.04],[1,6.4,2],[2,990,0.01]],"ltp":3.85,"tv":4255.11,"id":9629296},{"trd":[[1.35,24.89]],"batb":[[0,1.23,260.88],[1,1.19,135.71],[2,1.1,2]],"batl":[[0,1.46,60.25],[1,1.5,48.83],[2,1.64,5.58]],"ltp":1.35,"tv":5984.83,"id":12343905}],"tv":10239.95}]}
{"op":"mcm","clk":"4231882081","pt":1631549201745,"mc":[{"id":"1.187560634","rc":[{"batb":[[0,3,5],[1,2.84,42.02],[2,2,5]],"batl":[[0,6.4,2],[1,990,0.01],[2,990,0]],"ltp":3.85,"tv":4255.11,"id":9629296},{"batb":[[0,1.23,153.25]],"batl":[[0,1.5,48.83],[1,1.64,5.58],[2,3,5.97]],"ltp":1.35,"tv":5984.83,"id":12343905}]}]}
{"op":"mcm","clk":"4231882300","pt":1631549204347,"mc":[{"id":"1.187560634","rc":[{"batb":[[0,1.23,282.43],[1,1.22,263.04],[2,1.19,135.71]],"batl":[[0,1.45,136.42],[1,1.46,102.64],[2,1.5,48.83]],"ltp":1.35,"tv":5984.83,"id":12343905}]}]}
{"op":"mcm","clk":"4231882340","pt":1631549204965,"mc":[{"id":"1.187560634","rc":[{"batb":[[0,3.15,4.23],[1,3,5],[2,2.84,42.02]],"batl":[[0,5.4,2.04],[1,6.4,2],[2,990,0.01]],"ltp":3.85,"tv":4255.11,"id":9629296},{"batb":[[0,1.23,389.06]],"batl":[[1,1.46,157.89]],"ltp":1.35,"tv":5984.83,"id":12343905}]}]}
{"op":"mcm","clk":"4231882705","pt":1631549209526,"mc":[{"id":"1.187560634","rc":[{"trd":[[1.23,3.26]],"batb":[[0,1.23,387.43]],"ltp":1.23,"tv":5988.09,"id":12343905}],"tv":10243.21}]}
{"op":"mcm","clk":"4231882789","pt":1631549210663,"mc":[{"id":"1.187560634","rc":[{"batl":[[0,6.4,2],[1,990,0.01],[2,990,0]],"ltp":3.85,"tv":4255.11,"id":9629296},{"batb":[[0,1.23,151.62],[1,1.19,135.71],[2,1.1,2]],"ltp":1.23,"tv":5988.09,"id":12343905}]}]}
{"op":"mcm","clk":"4231882977","pt":1631549213387,"mc":[{"id":"1.187560634","rc":[{"batb":[[2,2.96,106.45]],"batl":[[0,3.9,370.29],[1,6.4,2],[2,990,0.01]],"ltp":3.85,"tv":4255.11,"id":9629296},{"batb":[[0,1.41,353.43],[1,1.4,125.92],[2,1.39,97.14]],"batl":[[2,1.47,92.52]],"ltp":1.23,"tv":5988.09,"id":12343905}]}]}
{"op":"mcm","clk":"4231883044","pt":1631549214058,"mc":[{"id":"1.187560634","rc":[{"batb":[[0,1.42,74.65],[1,1.41,353.43],[2,1.4,125.92]],"ltp":1.23,"tv":5988.09,"id":12343905}]}]}
{"op":"mcm","clk":"4231883191","pt":1631549215861,"mc":[{"id":"1.187560634","rc":[{"batb":[[0,3.2,7.01],[1,3.15,4.23],[2,3,5]],"batl":[[0,3.3,4.71],[1,3.9,370.29],[2,6.4,2]],"ltp":3.85,"tv":4255.11,"id":9629296}]}]}
{"op":"mcm","clk":"4231883513","pt":1631549219891,"mc":[{"id":"1.187560634","rc":[{"batl":[[2,5.6,2.01]],"ltp":3.85,"tv":4255.11,"id":9629296}]}]}
{"op":"mcm","clk":"4231883863","pt":1631549224674,"mc":[{"id":"1.187560634","rc":[{"batb":[[0,2.84,42.02],[1,2.62,5.04],[2,2.5,5.94]],"batl":[[0,5.6,2.01],[1,6.4,2],[2,7.8,2]],"ltp":3.85,"tv":4255.11,"id":9629296},{"batb":[[1,1.24,144.78],[2,1.22,104.34]],"batl":[[0,1.61,37.5],[1,1.64,5.58],[2,1.66,41.25]],"ltp":1.23,"tv":5988.09,"id":12343905}]}]}
{"op":"mcm","clk":"4231883903","pt":1631549225185,"mc":[{"id":"1.187560634","rc":[{"batb":[[0,2.5,5.94],[1,2.36,27.68],[2,2,5]],"ltp":3.85,"tv":4255.11,"id":9629296},{"batb":[[0,1.24,144.78],[1,1.22,104.34],[2,1.19,135.71]],"batl":[[0,1.64,5.58],[1,1.66,41.25],[2,3,5.97]],"ltp":1.23,"tv":5988.09,"id":12343905}]}]}
{"op":"mcm","clk":"4231884155","pt":1631549227600,"mc":[{"id":"1.187560634","rc":[{"batl":[[0,3.2,1.71],[1,5.4,4.57],[2,5.6,2.01]],"ltp":3.85,"tv":4255.11,"id":9629296},{"batb":[[0,1.24,246.8],[1,1.23,248.74],[2,1.22,104.34]],"batl":[[0,1.62,109.03],[1,1.63,67.79],[2,1.64,5.58]],"ltp":1.23,"tv":5988.09,"id":12343905}]}]}
{"op":"mcm","clk":"4231884262","pt":1631549228384,"mc":[{"id":"1.187560634","rc":[{"batl":[[1,5.6,2.01],[2,6.4,2]],"ltp":3.85,"tv":4255.11,"id":9629296},{"batb":[[0,1.24,144.78],[1,1.22,104.34],[2,1.19,135.71]],"batl":[[0,1.64,5.58],[1,1.66,41.25],[2,3,5.97]],"ltp":1.23,"tv":5988.09,"id":12343905}]}]}
{"op":"mcm","clk":"4231884352","pt":1631549229487,"mc":[{"id":"1.187560634","rc":[{"trd":[[3.2,1.71]],"batl":[[0,5.6,2.01],[1,6.4,2],[2,7.8,2]],"ltp":3.2,"tv":4256.82,"id":9629296},{"trd":[[1.45,3.77]],"batl":[[0,1.44,385.31],[1,1.64,5.58],[2,1.66,41.25]],"ltp":1.45,"tv":5991.86,"id":12343905}],"tv":10248.68}]}
{"op":"mcm","clk":"4231884440","pt":1631549230281,"mc":[{"id":"1.187560634","rc":[{"batb":[[0,1.37,179],[1,1.36,144.3],[2,1.24,144.78]],"batl":[[0,1.41,166.11],[1,1.42,114.94],[2,1.64,5.58]],"ltp":1.45,"tv":5991.86,"id":12343905}]}]}
{"op":"mcm","clk":"4231884609","pt":1631549231682,"mc":[{"id":"1.187560634","rc":[{"batb":[[0,2.62,5.54],[1,2.5,5.94],[2,2.36,27.68]],"ltp":3.2,"tv":4256.82,"id":9629296},{"batl":[[2,1.61,45.5]],"ltp":1.45,"tv":5991.86,"id":12343905}]}]}
{"op":"mcm","clk":"4231884828","pt":1631549234600,"mc":[{"id":"1.187560634","rc":[{"batb":[[0,2.5,5.94],[1,2.36,27.68],[2,2,5]],"ltp":3.2,"tv":4256.82,"id":9629296},{"batb":[[0,1.24,144.78],[1,1.22,104.34],[2,1.19,135.71]],"batl":[[0,1.64,5.58],[1,1.66,41.25],[2,3,5.97]],"ltp":1.45,"tv":5991.86,"id":12343905}]}]}
{"op":"mcm","clk":"4231885056","pt":1631549237210,"mc":[{"id":"1.187560634","rc":[{"batb":[[0,1.24,246.8],[1,1.23,248.74],[2,1.22,104.34]],"batl":[[0,1.62,109.03],[1,1.63,67.79],[2,1.64,5.58]],"ltp":1.45,"tv":5991.86,"id":12343905}]}]}
{"op":"mcm","clk":"4231885734","pt":1631549243702,"mc":[{"id":"1.187560634","rc":[{"batb":[[0,1.24,144.78],[1,1.22,104.34],[2,1.19,135.71]],"ltp":1.45,"tv":5991.86,"id":12343905}]}]}
{"op":"mcm","clk":"4231885986","pt":1631549246620,"mc":[{"id":"1.187560634","rc":[{"batl":[[0,2.7,74.08],[1,2.72,9.07],[2,2.78,184.68]],"ltp":3.2,"tv":4256.82,"id":9629296},{"batl":[[0,1.62,127.38]],"ltp":1.45,"tv":5991.86,"id":12343905}]}]}
{"op":"mcm","clk":"4231886051","pt":1631549247407,"mc":[{"id":"1.187560634","rc":[{"batl":[[2,2.78,141.52]],"ltp":3.2,"tv":4256.82,"id":9629296},{"batb":[[0,1.57,112.28],[1,1.56,80.36],[2,1.24,144.78]],"batl":[[1,1.63,159.81],[2,1.64,51.58]],"ltp":1.45,"tv":5991.86,"id":12343905}]}]}
{"op":"mcm","clk":"4231886098","pt":1631549248028,"mc":[{"id":"1.187560634","rc":[{"batb":[[2,2.1,38.67]],"ltp":3.2,"tv":4256.82,"id":9629296},{"batb":[[0,1.58,48.73],[1,1.57,112.28],[2,1.56,80.36]],"batl":[[1,1.63,86.19],[2,1.64,14.78]],"ltp":1.45,"tv":5991.86,"id":12343905}]}]}
{"op":"mcm","clk":"4231886622","pt":1631549253989,"mc":[{"id":"1.187560634","rc":[{"batb":[[2,2.34,6.72]],"ltp":3.2,"tv":4256.82,"id":9629296}]}]}
{"op":"mcm","clk":"4231886923","pt":1631549257497,"mc":[{"id":"1.187560634","rc":[{"trd":[[1.62,13.81]],"batl":[[0,1.62,121.41]],"ltp":1.62,"tv":6003.8,"id":12343905}],"tv":10260.62}]}
{"op":"mcm","clk":"4231887839","pt":1631549267620,"mc":[{"id":"1.187560634","rc":[{"batb":[[0,2.36,27.68],[1,2.34,6.72],[2,2.26,6.48]],"batl":[[0,3.5,3.05],[1,4.1,3.05],[2,5.6,2.01]],"ltp":3.2,"tv":4256.82,"id":9629296},{"batl":[[0,1.62,103.06],[1,1.63,67.79],[2,1.64,5.58]],"ltp":1.62,"tv":6003.8,"id":12343905}]}]}
{"op":"mcm","clk":"4231887867","pt":1631549267933,"mc":[{"id":"1.187560634","rc":[{"batb":[[0,2.26,6.48],[1,2.1,38.67],[2,1.01,105.79]],"batl":[[0,4.1,3.05],[1,990,0.01],[2,5.6,0]],"ltp":3.2,"tv":4256.82,"id":9629296},{"batb":[[0,1.41,75.91],[1,1.33,75.53],[2,1.1,2]],"batl":[[0,1.64,5.58],[1,1.79,30.5],[2,3,5.97]],"ltp":1.62,"tv":6003.8,"id":12343905}]}]}
{"op":"mcm","clk":"4231888103","pt":1631549270653,"mc":[{"id":"1.187560634","rc":[{"batb":[[1,1.4,187.83],[2,1.39,130.46]],"batl":[[1,1.77,80.32],[2,1.79,130.02]],"ltp":1.62,"tv":6003.8,"id":12343905}]}]}
{"op":"mcm","clk":"4231888166","pt":1631549271449,"mc":[{"id":"1.187560634","rc":[{"batb":[[1,1.33,75.53],[2,1.1,2]],"batl":[[1,1.79,30.5],[2,3,5.97]],"ltp":1.62,"tv":6003.8,"id":12343905}]}]}
{"op":"mcm","clk":"4231888342","pt":1631549273641,"mc":[{"id":"1.187560634","rc":[{"batl":[[0,1.62,326.84],[1,1.64,5.58],[2,1.79,30.5]],"ltp":1.62,"tv":6003.8,"id":12343905}]}]}
{"op":"mcm","clk":"4231888420","pt":1631549274654,"mc":[{"id":"1.187560634","rc":[{"batb":[[0,1.53,149.77],[1,1.52,89.06],[2,1.41,75.91]],"batl":[[0,1.58,105.48],[1,1.59,74.11],[2,1.64,5.58]],"ltp":1.62,"tv":6003.8,"id":12343905}]}]}
{"op":"mcm","clk":"4231888427","pt":1631549274727,"mc":[{"id":"1.187560634","rc":[{"batb":[[0,2.34,6.72],[1,2.26,6.48],[2,2.1,38.67]],"batl":[[0,3.5,3.45],[1,4.1,3.05],[2,990,0.01]],"ltp":3.2,"tv":4256.82,"id":9629296}]}]}
{"op":"mcm","clk":"4231888531","pt":1631549276038,"mc":[{"id":"1.187560634","rc":[{"batb":[[0,2.26,6.48],[1,2.1,38.67],[2,1.01,105.79]],"batl":[[0,4.1,3.05],[1,990,0.01],[2,990,0]],"ltp":3.2,"tv":4256.82,"id":9629296},{"batb":[[0,1.41,75.91],[1,1.33,75.53],[2,1.1,2]],"batl":[[0,1.64,5.58],[1,1.79,30.5],[2,3,5.97]],"ltp":1.62,"tv":6003.8,"id":12343905}]}]}
{"op":"mcm","clk":"4231888798","pt":1631549279544,"mc":[{"id":"1.187560634","rc":[{"batb":[[1,1.4,187.83],[2,1.39,130.46]],"batl":[[1,1.77,80.32],[2,1.79,130.02]],"ltp":1.62,"tv":6003.8,"id":12343905}]}]}
{"op":"mcm","clk":"4231889053","pt":1631549282666,"mc":[{"id":"1.187560634","rc":[{"batl":[[1,1.79,30.5],[2,3,5.97]],"ltp":1.62,"tv":6003.8,"id":12343905}]}]}
{"op":"mcm","clk":"4231889188","pt":1631549284473,"mc":[{"id":"1.187560634","rc":[{"batb":[[0,2.34,6.72],[1,2.26,6.48],[2,2.1,38.67]],"batl":[[0,3.5,3.49],[1,4.1,3.05],[2,990,0.01]],"ltp":3.2,"tv":4256.82,"id":9629296},{"batb":[[1,1.4,260.84]],"batl":[[1,1.74,31.75],[2,1.79,30.5]],"ltp":1.62,"tv":6003.8,"id":12343905}]}]}
{"op":"mcm","clk":"4231889322","pt":1631549285662,"mc":[{"id":"1.187560634","rc":[{"batb":[[0,3.25,5.8],[1,3.2,2],[2,3.15,28.57]],"batl":[[0,3.35,5.48]],"ltp":3.2,"tv":4256.82,"id":9629296},{"batb":[[0,1.41,306.57],[1,1.4,187.83]],"batl":[[0,1.44,116.68],[1,1.45,195.43],[2,1.64,5.58]],"ltp":1.62,"tv":6003.8,"id":12343905}]}]}
{"op":"mcm","clk":"4231889393","pt":1631549286658,"mc":[{"id":"1.187560634","rc":[{"batb":[[0,1.41,327.85],[1,1.4,198.47],[2,1.39,141.1]],"ltp":1.62,"tv":6003.8,"id":12343905}]}]}
{"op":"mcm","clk":"4231889868","pt":1631549293432,"mc":[{"id":"1.187560634","rc":[{"batl":[[2,5.8,2.02]],"ltp":3.2,"tv":4256.82,"id":9629296},{"batl":[[2,1.6,40.31]],"ltp":1.62,"tv":6003.8,"id":12343905}]}]}
{"op":"mcm","clk":"4231890239","pt":1631549297940,"mc":[{"id":"1.187560634","rc":[{"trd":[[3.35,32.69]],"batl":[[0,3.35,2.95]],"ltp":3.35,"tv":4259.35,"id":9629296},{"trd":[[1.42,5.97]],"ltp":1.42,"tv":6009.76,"id":12343905}],"tv":10269.11}]}
{"op":"mcm","clk":"4231890347","pt":1631549299648,"mc":[{"id":"1.187560634","rc":[{"batb":[[0,3.2,2],[1,3.15,4.76],[2,3.1,2.38]],"batl":[[0,4.1,3.05],[1,5.8,2.02],[2,8.2,2]],"ltp":3.35,"tv":4259.35,"id":9629296},{"batb":[[0,1.41,86.55],[1,1.4,193.15],[2,1.39,135.78]],"batl":[[1,1.45,181.64]],"ltp":1.42,"tv":6009.76,"id":12343905}]}]}
{"op":"mcm","clk":"4231890389","pt":1631549300271,"mc":[{"id":"1.187560634","rc":[{"batb":[[0,2.52,5.99],[1,2.38,27.26],[2,1.01,105.79]],"batl":[[0,5.8,2.02],[1,8.2,2],[2,990,0.01]],"ltp":3.35,"tv":4259.35,"id":9629296},{"batb":[[0,1.24,145.2],[1,1.21,122.69],[2,1.14,169.32]],"batl":[[0,1.64,5.58],[1,1.65,36.5],[2,3,5.97]],"ltp":1.42,"tv":6009.76,"id":12343905}]}]}
{"op":"mcm","clk":"4231890622","pt":1631549303552,"mc":[{"id":"1.187560634","rc":[{"batb":[[1,1.23,259.48],[2,1.22,266.57]],"batl":[[0,1.61,115.71],[1,1.62,69.27],[2,1.64,5.58]],"ltp":1.42,"tv":6009.76,"id":12343905}]}]}
{"op":"mcm","clk":"4231890868","pt":1631549306882,"mc":[{"id":"1.187560634","rc":[{"batb":[[0,2.66,4.78],[1,2.52,5.99],[2,2.38,27.26]],"ltp":3.35,"tv":4259.35,"id":9629296},{"batl":[[0,1.6,45.21],[1,1.61,115.71],[2,1.62,69.27]],"ltp":1.42,"tv":6009.76,"id":12343905}]}]}
{"op":"mcm","clk":"4231891100","pt":1631549310171,"mc":[{"id":"1.187560634","rc":[{"batb":[[0,2.52,5.99],[1,2.38,27.26],[2,1.01,105.79]],"ltp":3.35,"tv":4259.35,"id":9629296},{"batl":[[0,1.61,115.71],[1,1.62,69.27],[2,1.64,5.58]],"ltp":1.42,"tv":6009.76,"id":12343905}]}]}
{"op":"mcm","clk":"4231891439","pt":1631549314699,"mc":[{"id":"1.187560634","rc":[{"batb":[[1,1.21,122.69],[2,1.14,169.32]],"ltp":1.42,"tv":6009.76,"id":12343905}]}]}
{"op":"mcm","clk":"4231891648","pt":1631549317571,"mc":[{"id":"1.187560634","rc":[{"batl":[[0,2.68,44.77],[1,2.78,10.83],[2,5.8,2.02]],"ltp":3.35,"tv":4259.35,"id":9629296},{"batb":[[0,1.56,113.17],[1,1.55,140.43],[2,1.54,29.03]],"batl":[[0,1.6,16.16],[1,1.61,115.71],[2,1.62,69.27]],"ltp":1.42,"tv":6009.76,"id":12343905}]}]}
{"op":"mcm","clk":"4231891721","pt":1631549318657,"mc":[{"id":"1.187560634","rc":[{"batb":[[0,2.62,11.44],[1,2.6,5.72],[2,2.58,5.72]],"ltp":3.35,"tv":4259.35,"id":9629296},{"batb":[[0,1.58,49.41],[1,1.56,113.17],[2,1.55,101.73]],"ltp":1.42,"tv":6009.76,"id":12343905}]}]}
{"op":"mcm","clk":"4231892153","pt":1631549324597,"mc":[{"id":"1.187560634","rc":[{"batb":[[0,2.52,5.99],[1,2.38,27.26],[2,2.12,37.91]],"batl":[[0,5.8,2.02],[1,8.2,2],[2,990,0.01]],"ltp":3.35,"tv":4259.35,"id":9629296},{"batb":[[2,1.55,82.37]],"batl":[[0,1.61,115.71],[1,1.62,69.27],[2,1.64,5.58]],"ltp":1.42,"tv":6009.76,"id":12343905}]}]}
{"op":"mcm","clk":"4231892235","pt":1631549325484,"mc":[{"id":"1.187560634","rc":[{"batb":[[0,2.36,6.43],[1,2.28,6.16]],"batl":[[0,3.6,3.11],[1,4.2,2.78]],"ltp":3.35,"tv":4259.35,"id":9629296},{"batb":[[0,1.41,77.42],[1,1.39,59.91],[2,1.32,69.89]],"batl":[[0,1.64,5.58],[1,1.73,33.5],[2,1.77,34.5]],"ltp":1.42,"tv":6009.76,"id":12343905}]}]}
{"op":"mcm","clk":"4231892257","pt":1631549325797,"mc":[{"id":"1.187560634","rc":[{"batb":[[0,2.28,6.16],[1,2.12,37.91],[2,1.01,105.79]],"batl":[[0,4.2,2.78],[1,990,0.01],[2,990,0]],"ltp":3.35,"tv":4259.35,"id":9629296},{"batb":[[1,1.32,69.89],[2,1.1,2]],"batl":[[1,1.77,34.5],[2,3,5.97]],"ltp":1.42,"tv":6009.76,"id":12343905}]}]}
{"op":"mcm","clk":"4231892447","pt":1631549328403,"mc":[{"id":"1.187560634","rc":[{"batb":[[0,1.6,7],[1,1.41,77.42],[2,1.32,69.89]],"ltp":1.42,"tv":6009.76,"id":12343905}]}]}
{"op":"mcm","clk":"4231892542","pt":1631549329706,"mc":[{"id":"1.187560634","rc":[{"batb":[[0,1.41,77.42],[1,1.32,69.89],[2,1.1,2]],"ltp":1.42,"tv":6009.76,"id":12343905}]}]}
{"op":"mcm","clk":"4231892688","pt":1631549331630,"mc":[{"id":"1.187560634","rc":[{"batb":[[0,1.52,154.16],[1,1.51,91.48],[2,1.41,77.42]],"batl":[[0,1.57,110.29],[1,1.58,75.83],[2,1.64,5.58]],"ltp":1.42,"tv":6009.76,"id":12343905}]}]}
{"op":"mcm","clk":"4231892778","pt":1631549332622,"mc":[{"id":"1.187560634","rc":[{"batb":[[0,1.41,77.42],[1,1.32,69.89],[2,1.1,2]],"batl":[[0,1.64,5.58],[1,1.77,34.5],[2,3,5.97]],"ltp":1.42,"tv":6009.76,"id":12343905}]}]}
{"op":"mcm","clk":"4231893030","pt":1631549335537,"mc":[{"id":"1.187560634","rc":[{"batb":[[1,1.4,95.04],[2,1.39,129.5]],"batl":[[1,1.76,96.61],[2,1.77,34.5]],"ltp":1.42,"tv":6009.76,"id":12343905}]}]}
{"op":"mcm","clk":"4231893284","pt":1631549338406,"mc":[{"id":"1.187560634","rc":[{"batl":[[0,1.77,34.5],[1,3,5.97],[2,990,0.01]],"ltp":1.42,"tv":6009.76,"id":12343905}]}]}
{"op":"mcm","clk":"4231893392","pt":1631549339500,"mc":[{"id":"1.187560634","rc":[{"batl":[[1,3,5.2]],"ltp":1.42,"tv":6009.76,"id":12343905}]}]}
{"op":"mcm","clk":"4231893530","pt":1631549341332,"mc":[{"id":"1.187560634","rc":[{"batb":[[0,3.3,7.12],[1,3.2,2],[2,3,57.34]],"batl":[[0,3.5,51.97],[1,4.2,2.78],[2,990,0.01]],"ltp":3.35,"tv":4259.35,"id":9629296},{"batb":[[0,1.41,96.55],[1,1.4,224.97]],"batl":[[0,1.43,95.02],[1,1.44,192.43],[2,1.45,6.9]],"ltp":1.42,"tv":6009.76,"id":12343905}]}]}
{"op":"mcm","clk":"4231893618","pt":1631549342533,"mc":[{"id":"1.187560634","rc":[{"batb":[[0,1.41,117.83],[1,1.4,235.61],[2,1.39,140.14]],"ltp":1.42,"tv":6009.76,"id":12343905}]}]}
{"op":"mcm","clk":"4231894068","pt":1631549347705,"mc":[{"id":"1.187560634","rc":[{"batl":[[2,5.8,2.02]],"ltp":3.35,"tv":4259.35,"id":9629296}]}]}
{"op":"mcm","clk":"4231894368","pt":1631549351117,"mc":[{"id":"1.187560634","rc":[{"trd":[[1.43,15.86]],"batl":[[0,1.43,88.02]],"ltp":1.43,"tv":6023.76,"id":12343905}],"tv":10283.11}]}
{"op":"mcm","clk":"4231894972","pt":1631549358065,"mc":[{"id":"1.187560634","rc":[{"trd":[[1.43,16.66]],"batl":[[0,1.43,87.62]],"ltp":1.43,"tv":6024.56,"id":12343905}],"tv":10283.91}]}
{"op":"mcm","clk":"4231895418","pt":1631549362555,"mc":[{"id":"1.187560634","rc":[{"batb":[[0,2.5,7.36],[1,2.38,26.93],[2,1.01,105.79]],"batl":[[0,5.8,2.02],[1,8.2,2],[2,990,0.01]],"ltp":3.35,"tv":4259.35,"id":9629296},{"batb":[[0,1.23,149.31],[1,1.21,116.69],[2,1.14,193.82]],"batl":[[0,1.66,38.25],[1,3,5.2],[2,990,0.01]],"ltp":1.43,"tv":6024.56,"id":12343905}]}]}
{"op":"mcm","clk":"4231895656","pt":1631549365158,"mc":[{"id":"1.187560634","rc":[{"batb":[[0,1.23,320.57],[1,1.22,264.03],[2,1.21,116.69]],"batl":[[0,1.6,118.44],[1,1.61,70.8],[2,1.66,38.25]],"ltp":1.43,"tv":6024.56,"id":12343905}]}]}
{"op":"mcm","clk":"4231895849","pt":1631549367666,"mc":[{"id":"1.187560634","rc":[{"batl":[[0,1.66,38.25],[1,3,5.2],[2,990,0.01]],"ltp":1.43,"tv":6024.56,"id":12343905}]}]}
{"op":"mcm","clk":"4231895919","pt":1631549368609,"mc":[{"id":"1.187560634","rc":[{"batl":[[0,8.2,2],[1,990,0.01],[2,990,0]],"ltp":3.35,"tv":4259.35,"id":9629296},{"batb":[[2,1.14,193.82]],"batl":[[0,3,5.2],[1,990,0.01],[2,990,0]],"ltp":1.43,"tv":6024.56,"id":12343905}]}]}
{"op":"mcm","clk":"4231896091","pt":1631549370672,"mc":[{"id":"1.187560634","rc":[{"batb":[[0,4.6,19.56],[1,4.5,36.44],[2,4.4,9.78]],"batl":[[0,5.5,101.44],[1,8.2,2],[2,990,0.01]],"ltp":3.35,"tv":4259.35,"id":9629296},{"batb":[[0,1.24,72.47],[1,1.23,320.57],[2,1.22,264.03]],"batl":[[0,1.25,106.77],[1,1.26,237.15],[2,1.36,43.45]],"ltp":1.43,"tv":6024.56,"id":12343905}]}]}
{"op":"mcm","clk":"4231896183","pt":1631549371676,"mc":[{"id":"1.187560634","rc":[{"batb":[[0,1.24,145.05],[1,1.23,356.86],[2,1.22,300.32]],"ltp":1.43,"tv":6024.56,"id":12343905}]}]}
{"op":"mcm","clk":"4231896192","pt":1631549371777,"mc":[{"id":"1.187560634","rc":[{"batb":[[0,4.6,6.52],[1,4.5,29.92],[2,4.4,3.26]],"ltp":3.35,"tv":4259.35,"id":9629296},{"batb":[[0,1.24,96.67],[1,1.23,332.67],[2,1.22,276.13]],"ltp":1.43,"tv":6024.56,"id":12343905}]}]}
{"op":"mcm","clk":"4231896335","pt":1631549373460,"mc":[{"id":"1.187560634","rc":[{"trd":[[1.25,5.72]],"batl":[[0,1.25,103.91]],"ltp":1.25,"tv":6030.28,"id":12343905}],"tv":10289.63}]}
{"op":"mcm","clk":"4231896859","pt":1631549380366,"mc":[{"id":"1.187560634","rc":[{"trd":[[1.25,120.09]],"batl":[[0,1.26,237.15],[1,1.36,43.45],[2,3,5.2]],"ltp":1.25,"tv":6144.65,"id":12343905}],"tv":10404.0}]}
{"op":"mcm","clk":"4231897003","pt":1631549382088,"mc":[{"id":"1.187560634","rc":[{"batl":[[2,2,1.39]],"ltp":1.25,"tv":6144.65,"id":12343905}]}]}
{"op":"mcm","clk":"4231897111","pt":1631549383394,"mc":[{"id":"1.187560634","rc":[{"trd":[[1.26,40]],"batb":[[0,1.24,96.92],[1,1.23,376.47]],"batl":[[0,1.26,278.3],[1,1.27,192.56],[2,1.36,43.45]],"ltp":1.26,"tv":6184.65,"id":12343905}],"tv":10444.0}]}
{"op":"mcm","clk":"4231897354","pt":1631549386211,"mc":[{"id":"1.187560634","rc":[{"batl":[[0,4.9,25.58],[1,5.5,101.44],[2,8.2,2]],"ltp":3.35,"tv":4259.35,"id":9629296},{"batb":[[0,1.25,160.25],[1,1.24,96.67],[2,1.23,376.47]],"ltp":1.26,"tv":6184.65,"id":12343905}]}]}
{"op":"mcm","clk":"4231897492","pt":1631549387987,"mc":[{"id":"1.187560634","rc":[{"batb":[[0,1.24,96.92],[1,1.23,376.47],[2,1.22,276.13]],"ltp":1.26,"tv":6184.65,"id":12343905}]}]}
{"op":"mcm","clk":"4231897879","pt":1631549392502,"mc":[{"id":"1.187560634","rc":[{"trd":[[4.9,1.04]],"batl":[[0,4.9,24.54]],"ltp":4.9,"tv":4260.39,"id":9629296},{"trd":[[1.25,124.67]],"batb":[[0,1.24,96.67]],"ltp":1.25,"tv":6189.23,"id":12343905}],"tv":10449.62}]}
{"op":"mcm","clk":"4231897924","pt":1631549393018,"mc":[{"id":"1.187560634","rc":[{"batl":[[0,5.5,101.44],[1,8.2,2],[2,990,0.01]],"ltp":4.9,"tv":4260.39,"id":9629296},{"batb":[[0,1.24,71.86]],"batl":[[0,1.26,267.43]],"ltp":1.25,"tv":6189.23,"id":12343905}]}]}
{"op":"mcm","clk":"4231898041","pt":1631549394529,"mc":[{"id":"1.187560634","rc":[{"trd":[[1.26,360]],"batb":[[2,1.22,256.5]],"batl":[[0,1.26,107.43]],"ltp":1.26,"tv":6509.23,"id":12343905}],"tv":10769.62}]}
{"op":"mcm","clk":"4231898211","pt":1631549396558,"mc":[{"id":"1.187560634","rc":[{"batb":[[0,4.8,4.99],[1,4.6,6.52],[2,4.5,29.92]],"batl":[[0,5,4.01],[1,5.5,101.44],[2,8.2,2]],"ltp":4.9,"tv":4260.39,"id":9629296},{"trd":[[1.26,367.06]],"batl":[[0,1.26,103.9]],"ltp":1.26,"tv":6516.29,"id":12343905}],"tv":10776.68}]}
{"op":"mcm","clk":"4231898286","pt":1631549397545,"mc":[{"id":"1.187560634","rc":[{"batb":[[1,1.23,473.37]],"batl":[[0,1.26,169.41]],"ltp":1.26,"tv":6516.29,"id":12343905}]}]}
{"op":"mcm","clk":"4231899092","pt":1631549406659,"mc":[{"id":"1.187560634","rc":[{"trd":[[4.7,0.02],[4.8,54.43]],"batb":[[0,4.6,6.52],[1,4.5,29.92],[2,4.4,3.26]],"ltp":4.7,"tv":4314.83,"id":9629296},{"trd":[[1.26,536.47],[1.27,0.06]],"batl":[[0,1.27,192.5],[1,1.36,43.45],[2,3,5.2]],"ltp":1.27,"tv":6685.76,"id":12343905}],"tv":11000.6}]}
{"op":"mcm","clk":"4231899138","pt":1631549407281,"mc":[{"id":"1.187560634","rc":[{"batb":[[1,1.23,402.46],[2,1.22,12.1]],"ltp":1.27,"tv":6685.76,"id":12343905}]}]}
{"op":"mcm","clk":"4231899451","pt":1631549410145,"mc":[{"id":"1.187560634","rc":[{"batb":[[0,1.26,16],[1,1.24,239.38],[2,1.23,402.46]],"batl":[[0,1.27,269.35],[1,1.28,180.21],[2,1.36,43.45]],"ltp":1.27,"tv":6685.76,"id":12343905}]}]}
{"op":"mcm","clk":"4231900126","pt":1631549417168,"mc":[{"id":"1.187560634","rc":[{"trd":[[4.7,35.83]],"batl":[[0,5.5,101.44],[1,8.2,2],[2,990,0.01]],"ltp":4.7,"tv":4350.64,"id":9629296},{"trd":[[1.27,132.66]],"batl":[[0,1.27,136.75]],"ltp":1.27,"tv":6818.36,"id":12343905}],"tv":11169.01}]}
{"op":"mcm","clk":"4231900437","pt":1631549420660,"mc":[{"id":"1.187560634","rc":[{"batl":[[0,5,4.4],[1,5.5,101.44],[2,8.2,2]],"ltp":4.7,"tv":4350.64,"id":9629296},{"batb":[[1,1.25,17.61],[2,1.24,314.45]],"batl":[[0,1.27,213]],"ltp":1.27,"tv":6818.36,"id":12343905}]}]}
{"op":"mcm","clk":"4231900971","pt":1631549427995,"mc":[{"id":"1.187560634","rc":[{"batb":[[0,1.26,1]],"ltp":1.27,"tv":6818.36,"id":12343905}]}]}
{"op":"mcm","clk":"4231901074","pt":1631549429190,"mc":[{"id":"1.187560634","rc":[{"batb":[[0,1.25,17.61],[1,1.24,314.45],[2,1.23,402.46]],"ltp":1.27,"tv":6818.36,"id":12343905}]}]}
{"op":"mcm","clk":"4231901193","pt":1631549431123,"mc":[{"id":"1.187560634","rc":[{"trd":[[1.27,162.66]],"batl":[[0,1.27,198]],"ltp":1.27,"tv":6848.36,"id":12343905}],"tv":11199.01}]}
{"op":"mcm","clk":"4231901661","pt":1631549437021,"mc":[{"id":"1.187560634","rc":[{"trd":[[1.27,164.66]],"batl":[[0,1.27,197]],"ltp":1.27,"tv":6850.36,"id":12343905}],"tv":11201.01}]}
{"op":"mcm","clk":"4231902027","pt":1631549441824,"mc":[{"id":"1.187560634","rc":[{"trd":[[4.7,36.22]],"ltp":4.7,"tv":4351.03,"id":9629296},{"trd":[[1.27,166.09]],"batl":[[0,1.27,195.57]],"ltp":1.27,"tv":6851.79,"id":12343905}],"tv":11202.82}]}
{"op":"mcm","clk":"4231902390","pt":1631549446522,"mc":[{"id":"1.187560634","rc":[{"trd":[[4.7,37.92]],"ltp":4.7,"tv":4352.73,"id":9629296},{"trd":[[1.27,178.74]],"batl":[[0,1.27,186.09]],"ltp":1.27,"tv":6864.44,"id":12343905}],"tv":11217.18}]}
{"op":"mcm","clk":"4231902623","pt":1631549449504,"mc":[{"id":"1.187560634","rc":[{"batb":[[1,1.24,326.11]],"ltp":1.27,"tv":6864.44,"id":12343905}]}]}
{"op":"mcm","clk":"4231902647","pt":1631549449816,"mc":[{"id":"1.187560634","rc":[{"batl":[[0,1.27,198.13]],"ltp":1.27,"tv":6864.44,"id":12343905}]}]}
{"op":"mcm","clk":"4231902922","pt":1631549453254,"mc":[{"id":"1.187560634","rc":[{"trd":[[1.27,188.74]],"batl":[[0,1.27,193.13]],"ltp":1.27,"tv":6874.44,"id":12343905}],"tv":11227.18}]}
{"op":"mcm","clk":"4231903436","pt":1631549460121,"mc":[{"id":"1.187560634","rc":[{"trd":[[1.27,208.74]],"batl":[[0,1.27,183.13]],"ltp":1.27,"tv":6894.44,"id":12343905}],"tv":11247.18}]}
{"op":"mcm","clk":"4231903739","pt":1631549463653,"mc":[{"id":"1.187560634","rc":[{"batb":[[1,1.24,338.18]],"ltp":1.27,"tv":6894.44,"id":12343905}]}]}
{"op":"mcm","clk":"4231905345","pt":1631549482148,"mc":[{"id":"1.187560634","rc":[{"trd":[[1.25,131.83]],"batb":[[0,1.25,14.03]],"ltp":1.25,"tv":6901.59,"id":12343905}],"tv":11254.33}]}
{"op":"mcm","clk":"4231906283","pt":1631549492406,"mc":[{"id":"1.187560634","rc":[{"batl":[[0,5.5,101.44],[1,8.2,2],[2,990,0.01]],"ltp":4.7,"tv":4352.73,"id":9629296},{"batb":[[0,1.24,338.18],[1,1.23,402.46],[2,1.22,12.1]],"batl":[[0,1.27,166.2]],"ltp":1.25,"tv":6901.59,"id":12343905}]}]}
{"op":"mcm","clk":"4231906521","pt":1631549495285,"mc":[{"id":"1.187560634","rc":[{"batl":[[0,5,3.96],[1,5.5,101.44],[2,8.2,2]],"ltp":4.7,"tv":4352.73,"id":9629296},{"batb":[[0,1.25,15.82],[1,1.24,338.18],[2,1.23,402.46]],"batl":[[0,1.27,186.65]],"ltp":1.25,"tv":6901.59,"id":12343905}]}]}
{"op":"mcm","clk":"4231908336","pt":1631549517247,"mc":[{"id":"1.187560634","rc":[{"batb":[[0,3.65,21.98],[1,1.01,105.79],[2,4.4,0]],"batl":[[0,990,0.01],[1,5.5,0],[2,8.2,0]],"ltp":4.7,"tv":4352.73,"id":9629296},{"batb":[[0,1.2,173.21],[1,1.1,2],[2,1.01,105.79]],"batl":[[0,1.9,1.39],[1,3,5.2],[2,8.8,7.22]],"ltp":1.25,"tv":6901.59,"id":12343905}]}]}
{"op":"mcm","clk":"4231908795","pt":1631549522746,"mc":[{"id":"1.187560634","rc":[{"batb":[[0,1.25,246.72],[1,1.24,228.69],[2,1.2,173.21]],"batl":[[0,1.28,165.29],[1,1.29,172.92],[2,1.9,1.39]],"ltp":1.25,"tv":6901.59,"id":12343905}]}]}
{"op":"mcm","clk":"4231909339","pt":1631549529143,"mc":[{"id":"1.187560634","rc":[{"batb":[[0,1.2,173.21],[1,1.1,2],[2,1.01,105.79]],"batl":[[0,1.9,1.39],[1,3,5.2],[2,8.8,7.22]],"ltp":1.25,"tv":6901.59,"id":12343905}]}]}
{"op":"mcm","clk":"4231909627","pt":1631549532054,"mc":[{"id":"1.187560634","rc":[{"batb":[[0,1.22,103.39],[1,1.21,263.63],[2,1.2,173.21]],"batl":[[0,1.32,115],[1,1.33,148.61],[2,1.9,1.39]],"ltp":1.25,"tv":6901.59,"id":12343905}]}]}
{"op":"mcm","clk":"4231910809","pt":1631549545977,"mc":[{"id":"1.187560634","rc":[{"batb":[[0,1.2,173.21],[1,1.1,2],[2,1.01,105.79]],"ltp":1.25,"tv":6901.59,"id":12343905}]}]}
{"op":"mcm","clk":"4231910991","pt":1631549548278,"mc":[{"id":"1.187560634","rc":[{"batl":[[0,1.31,300.14],[1,1.32,115],[2,1.33,148.61]],"ltp":1.25,"tv":6901.59,"id":12343905}]}]}
{"op":"mcm","clk":"4231911101","pt":1631549549381,"mc":[{"id":"1.187560634","rc":[{"batb":[[0,4,34],[1,3.95,33],[2,3.9,33]],"batl":[[0,4.3,3.9],[1,4.5,60.89],[2,990,0.01]],"ltp":4.7,"tv":4352.73,"id":9629296},{"batb":[[0,1.29,442.71],[1,1.28,295.26],[2,1.27,103.12]],"batl":[[0,1.32,137.02],[1,1.33,148.61],[2,1.34,226.55]],"ltp":1.25,"tv":6901.59,"id":12343905}]}]}
{"op":"mcm","clk":"4231911150","pt":1631549549960,"mc":[{"id":"1.187560634","rc":[{"batb":[[2,1.27,228.77]],"ltp":1.25,"tv":6901.59,"id":12343905}]}]}
{"op":"mcm","clk":"4231911633","pt":1631549555635,"mc":[{"id":"1.187560634","rc":[{"batl":[[2,4.9,2.25]],"ltp":4.7,"tv":4352.73,"id":9629296}]}]}
{"op":"mcm","clk":"4231912071","pt":1631549560907,"mc":[{"id":"1.187560634","rc":[{"batb":[[0,1.29,255.53]],"ltp":1.25,"tv":6901.59,"id":12343905}]}]}
{"op":"mcm","clk":"4231913155","pt":1631549573619,"mc":[{"id":"1.187560634","rc":[{"batb":[[0,3.65,21.98],[1,3.6,2.84],[2,3.4,3.56]],"batl":[[0,4.9,2.25],[1,5.2,2.13],[2,990,0.01]],"ltp":4.7,"tv":4352.73,"id":9629296},{"batb":[[1,1.28,189],[2,1.27,125.65]],"batl":[[0,1.32,115],[2,1.38,66.75]],"ltp":1.25,"tv":6901.59,"id":12343905}]}]}
{"op":"mcm","clk":"4231913187","pt":1631549574038,"mc":[{"id":"1.187560634","rc":[{"batb":[[0,3.4,3.56],[1,3.3,28.44],[2,1.01,105.79]],"ltp":4.7,"tv":4352.73,"id":9629296},{"batb":[[0,1.26,91.98],[1,1.24,264.9],[2,1.1,2]],"batl":[[0,1.41,60.5],[1,1.9,1.39],[2,3,5.2]],"ltp":1.25,"tv":6901.59,"id":12343905}]}]}
{"op":"mcm","clk":"4231913271","pt":1631549575131,"mc":[{"id":"1.187560634","rc":[{"batl":[[0,5.2,2.13],[1,990,0.01],[2,990,0]],"ltp":4.7,"tv":4352.73,"id":9629296},{"batb":[[0,1.24,264.9],[1,1.1,2],[2,1.01,105.79]],"ltp":1.25,"tv":6901.59,"id":12343905}]}]}
{"op":"mcm","clk":"4231913438","pt":1631549576961,"mc":[{"id":"1.187560634","rc":[{"batb":[[0,1.25,276.11],[1,1.24,494.32],[2,1.1,2]],"ltp":1.25,"tv":6901.59,"id":12343905}]}]}
{"op":"mcm","clk":"4231913669","pt":1631549579520,"mc":[{"id":"1.187560634","rc":[{"batb":[[0,4.5,44.44],[1,4.4,61.09],[2,4.3,3.4]],"batl":[[0,4.8,5.43],[1,5,30.17],[2,5.2,2.13]],"ltp":4.7,"tv":4352.73,"id":9629296},{"batb":[[0,1.25,444.07]],"batl":[[0,1.28,159.11],[1,1.29,173.47],[2,1.36,43.45]],"ltp":1.25,"tv":6901.59,"id":12343905}]}]}
{"op":"mcm","clk":"4231913758","pt":1631549580634,"mc":[{"id":"1.187560634","rc":[{"batl":[[1,5,36.17],[2,5.1,3]],"ltp":4.7,"tv":4352.73,"id":9629296},{"batb":[[2,1.2,172.62]],"ltp":1.25,"tv":6901.59,"id":12343905}]}]}
{"op":"mcm","clk":"4231914286","pt":1631549586165,"mc":[{"id":"1.187560634","rc":[{"trd":[[1.28,240]],"batb":[[0,1.25,381.36],[1,1.24,264.9],[2,1.23,108.63]],"batl":[[0,1.28,39.11],[2,1.33,77.5]],"ltp":1.28,"tv":7141.59,"id":12343905}],"tv":11494.33}]}
{"op":"mcm","clk":"4231914546","pt":1631549589156,"mc":[{"id":"1.187560634","rc":[{"batb":[[0,1.26,117.98],[1,1.25,381.36],[2,1.24,264.9]],"batl":[[0,1.28,83.55]],"ltp":1.28,"tv":7141.59,"id":12343905}]}]}
{"op":"mcm","clk":"4231915151","pt":1631549596660,"mc":[{"id":"1.187560634","rc":[{"batb":[[0,3.85,2.97],[1,3.6,22.9],[2,3.4,3.56]],"batl":[[0,5.4,2.04],[1,5.6,2.01],[2,990,0.01]],"ltp":4.7,"tv":4352.73,"id":9629296},{"batb":[[0,1.23,108.63],[1,1.22,107.34],[2,1.2,172.62]],"batl":[[0,1.35,68.1],[1,1.41,60.5],[2,1.9,1.39]],"ltp":1.28,"tv":7141.59,"id":12343905}]}]}
{"op":"mcm","clk":"4231915180","pt":1631549596972,"mc":[{"id":"1.187560634","rc":[{"batb":[[2,1.01,105.79]],"batl":[[1,990,0.01],[2,990,0]],"ltp":4.7,"tv":4352.73,"id":9629296},{"batb":[[1,1.2,172.62],[2,1.1,2]],"batl":[[1,1.9,1.39],[2,3,5.2]],"ltp":1.28,"tv":7141.59,"id":12343905}]}]}
{"op":"mcm","clk":"4231915374","pt":1631549599647,"mc":[{"id":"1.187560634","rc":[{"batl":[[0,5.2,2.03],[1,5.4,2.04],[2,990,0.01]],"ltp":4.7,"tv":4352.73,"id":9629296},{"batb":[[0,1.24,95.02],[1,1.23,108.63],[2,1.2,172.62]],"ltp":1.28,"tv":7141.59,"id":12343905}]}]}
{"op":"mcm","clk":"4231915416","pt":1631549600258,"mc":[{"id":"1.187560634","rc":[{"batl":[[0,5.4,2.04],[1,990,0.01],[2,990,0]],"ltp":4.7,"tv":4352.73,"id":9629296},{"batb":[[0,1.23,108.63],[1,1.2,172.62],[2,1.1,2]],"ltp":1.28,"tv":7141.59,"id":12343905}]}]}
{"op":"mcm","clk":"4231915528","pt":1631549601672,"mc":[{"id":"1.187560634","rc":[{"batl":[[0,4.9,20.65],[1,5.4,2.04],[2,990,0.01]],"ltp":4.7,"tv":4352.73,"id":9629296},{"batb":[[0,1.26,20.48],[1,1.23,108.63],[2,1.2,172.62]],"batl":[[0,1.28,21.84],[1,1.35,68.1],[2,1.9,1.39]],"ltp":1.28,"tv":7141.59,"id":12343905}]}]}
{"op":"mcm","clk":"4231915552","pt":1631549601883,"mc":[{"id":"1.187560634","rc":[{"batl":[[0,5.4,2.04],[1,990,0.01],[2,990,0]],"ltp":4.7,"tv":4352.73,"id":9629296},{"batb":[[0,1.27,147.41],[1,1.26,204.23],[2,1.23,108.63]],"batl":[[0,1.3,208.12],[1,1.31,157.7],[2,1.35,68.1]],"ltp":1.28,"tv":7141.59,"id":12343905}]}]}
{"op":"mcm","clk":"4231915698","pt":1631549603459,"mc":[{"id":"1.187560634","rc":[{"batb":[[0,4,2.68],[1,3.85,2.97],[2,3.6,22.9]],"batl":[[0,5.2,2.23],[1,5.4,2.04],[2,990,0.01]],"ltp":4.7,"tv":4352.73,"id":9629296},{"batb":[[2,1.24,117.52]],"batl":[[2,1.33,79.5]],"ltp":1.28,"tv":7141.59,"id":12343905}]}]}
{"op":"mcm","clk":"4231915757","pt":1631549604201,"mc":[{"id":"1.187560634","rc":[{"batl":[[2,1.32,300.14]],"ltp":1.28,"tv":7141.59,"id":12343905}]}]}
{"op":"mcm","clk":"4231916015","pt":1631549607268,"mc":[{"id":"1.187560634","rc":[{"batl":[[0,5.4,2.04],[1,990,0.01],[2,990,0]],"ltp":4.7,"tv":4352.73,"id":9629296},{"batb":[[0,1.23,108.63],[1,1.2,172.62],[2,1.1,2]],"batl":[[0,1.32,300.14],[1,1.33,79.5],[2,1.35,68.1]],"ltp":1.28,"tv":7141.59,"id":12343905}]}]}
{"op":"mcm","clk":"4231916263","pt":1631549610473,"mc":[{"id":"1.187560634","rc":[{"batl":[[0,5.2,2.03],[1,5.4,2.04],[2,990,0.01]],"ltp":4.7,"tv":4352.73,"id":9629296},{"batb":[[0,1.24,93.52],[1,1.23,108.63],[2,1.22,283.11]],"batl":[[2,1.35,223.13]],"ltp":1.28,"tv":7141.59,"id":12343905}]}]}
{"op":"mcm","clk":"4231916307","pt":1631549610981,"mc":[{"id":"1.187560634","rc":[{"batl":[[0,5.4,2.04],[1,990,0.01],[2,990,0]],"ltp":4.7,"tv":4352.73,"id":9629296},{"batb":[[0,1.23,108.63],[1,1.22,283.11],[2,1.21,267.47]],"batl":[[2,1.35,68.1]],"ltp":1.28,"tv":7141.59,"id":12343905}]}]}
{"op":"mcm","clk":"4231916608","pt":1631549614508,"mc":[{"id":"1.187560634","rc":[{"batb":[[0,5.1,26.66],[1,5,25.88],[2,4.9,25.88]],"batl":[[1,5.5,42.84],[2,5.9,23.04]],"ltp":4.7,"tv":4352.73,"id":9629296},{"batb":[[0,1.24,16.66],[1,1.23,108.63],[2,1.22,331.54]],"batl":[[0,1.25,357.48],[1,1.26,230.7],[2,1.29,623.38]],"ltp":1.28,"tv":7141.59,"id":12343905}]}]}
{"op":"mcm","clk":"4231917120","pt":1631549620285,"mc":[{"id":"1.187560634","rc":[{"batl":[[2,5.6,2.01]],"ltp":4.7,"tv":4352.73,"id":9629296},{"batb":[[2,1.22,448.88]],"batl":[[2,1.28,84.09]],"ltp":1.28,"tv":7141.59,"id":12343905}]}]}
{"op":"mcm","clk":"4231917548","pt":1631549625798,"mc":[{"id":"1.187560634","rc":[{"batl":[[0,1.25,211.3]],"ltp":1.28,"tv":7141.59,"id":12343905}]}]}
{"op":"mcm","clk":"4231918276","pt":1631549634416,"mc":[{"id":"1.187560634","rc":[{"batb":[[0,4.3,2.58],[1,3.95,35.82],[2,3.85,2.97]],"batl":[[0,5.8,2.02],[1,990,0.01],[2,5.6,0]],"ltp":4.7,"tv":4352.73,"id":9629296},{"batb":[[0,1.21,122.69],[1,1.18,196.87],[2,1.1,2]],"batl":[[0,1.3,80.65],[1,1.35,68.1],[2,1.9,1.39]],"ltp":1.28,"tv":7141.59,"id":12343905}]}]}
{"op":"mcm","clk":"4231918477","pt":1631549636619,"mc":[{"id":"1.187560634","rc":[{"batb":[[2,1.01,105.79]],"ltp":4.7,"tv":4352.73,"id":9629296},{"batl":[[1,1.9,1.39],[2,3,5.2]],"ltp":1.28,"tv":7141.59,"id":12343905}]}]}
{"op":"mcm","clk":"4231918595","pt":1631549637609,"mc":[{"id":"1.187560634","rc":[{"batb":[[0,4.5,2.58],[1,4.3,2.58],[2,3.95,35.82]],"batl":[[0,5.6,2.01],[1,5.8,2.02],[2,990,0.01]],"ltp":4.7,"tv":4352.73,"id":9629296},{"batb":[[0,1.22,104.34],[1,1.21,122.69],[2,1.2,161.08]],"batl":[[0,1.28,82.59],[1,1.3,80.65],[2,1.9,1.39]],"ltp":1.28,"tv":7141.59,"id":12343905}]}]}
{"op":"mcm","clk":"4231918616","pt":1631549637924,"mc":[{"id":"1.187560634","rc":[{"batb":[[0,4.3,2.58],[1,3.95,35.82],[2,1.01,105.79]],"batl":[[0,5.8,2.02],[1,990,0.01],[2,990,0]],"ltp":4.7,"tv":4352.73,"id":9629296},{"batb":[[0,1.21,122.69],[1,1.2,161.08],[2,1.19,296.4]],"batl":[[0,1.3,80.65],[1,1.9,1.39],[2,3,5.2]],"ltp":1.28,"tv":7141.59,"id":12343905}]}]}
{"op":"mcm","clk":"4231918737","pt":1631549639655,"mc":[{"id":"1.187560634","rc":[{"batb":[[0,5.3,56.42],[1,5.2,41.3],[2,5.1,2.84]],"batl":[[0,5.7,5.39],[1,5.8,2.02],[2,6,18.69]],"ltp":4.7,"tv":4352.73,"id":9629296},{"batb":[[1,1.2,254.51],[2,1.19,346.06]],"batl":[[0,1.22,163.07],[1,1.23,261.48],[2,1.3,126.1]],"ltp":1.28,"tv":7141.59,"id":12343905}]}]}
{"op":"mcm","clk":"4231919277","pt":1631549646036,"mc":[{"id":"1.187560634","rc":[{"batb":[[2,5.1,4.88]],"batl":[[2,6,20.7]],"ltp":4.7,"tv":4352.73,"id":9629296},{"batb":[[1,1.2,370.93],[2,1.19,462.77]],"batl":[[2,1.24,97.73]],"ltp":1.28,"tv":7141.59,"id":12343905}]}]}
{"op":"mcm","clk":"4231919555","pt":1631549649178,"mc":[{"id":"1.187560634","rc":[{"trd":[[1.21,43.64]],"batb":[[0,1.21,100.87]],"ltp":1.21,"tv":7185.23,"id":12343905}],"tv":11537.97}]}
{"op":"mcm","clk":"4231919894","pt":1631549652462,"mc":[{"id":"1.187560634","rc":[{"batb":[[0,5,2.05],[1,4.4,27.26],[2,1.01,105.79]],"batl":[[0,6.4,2],[1,990,0.01],[2,6,0]],"ltp":4.7,"tv":4352.73,"id":9629296},{"batb":[[0,1.19,116.71],[1,1.16,217.42],[2,1.1,2]],"batl":[[0,1.25,105.06],[1,1.9,1.39],[2,3,5.2]],"ltp":1.21,"tv":7185.23,"id":12343905}]}]}
{"op":"mcm","clk":"4231920197","pt":1631549655658,"mc":[{"id":"1.187560634","rc":[{"batb":[[1,1.18,314.77],[2,1.17,265.34]],"batl":[[0,1.25,291.15],[1,1.26,195.23],[2,1.9,1.39]],"ltp":1.21,"tv":7185.23,"id":12343905}]}]}
{"op":"mcm","clk":"4231920628","pt":1631549660265,"mc":[{"id":"1.187560634","rc":[{"batb":[[1,1.16,217.42],[2,1.1,2]],"ltp":1.21,"tv":7185.23,"id":12343905}]}]}
{"op":"mcm","clk":"4231920995","pt":1631549663664,"mc":[{"id":"1.187560634","rc":[{"batb":[[1,4.7,28.94],[2,4.6,28.1]],"batl":[[0,5.5,67.78],[1,5.6,24],[2,5.7,24]],"ltp":4.7,"tv":4352.73,"id":9629296},{"batb":[[0,1.24,15.35],[1,1.22,655.39],[2,1.21,249.86]],"batl":[[1,1.26,461.12],[2,1.32,44.76]],"ltp":1.21,"tv":7185.23,"id":12343905}]}]}
{"op":"mcm","clk":"4231921077","pt":1631549664499,"mc":[{"id":"1.187560634","rc":[{"batb":[[2,1.21,420.47]],"ltp":1.21,"tv":7185.23,"id":12343905}]}]}
{"op":"mcm","clk":"4231921546","pt":1631549669562,"mc":[{"id":"1.187560634","rc":[{"batb":[[2,1.21,535.16]],"batl":[[2,1.29,80.5]],"ltp":1.21,"tv":7185.23,"id":12343905}]}]}
{"op":"mcm","clk":"4231922003","pt":1631549675091,"mc":[{"id":"1.187560634","rc":[{"batb":[[1,1.22,359.53]],"ltp":1.21,"tv":7185.23,"id":12343905}]}]}
{"op":"mcm","clk":"4231922960","pt":1631549686128,"mc":[{"id":"1.187560634","rc":[{"trd":[[1.25,134.8]],"batl":[[0,1.25,289.66]],"ltp":1.25,"tv":7188.21,"id":12343905}],"tv":11540.95}]}
{"op":"mcm","clk":"4231923161","pt":1631549688401,"mc":[{"id":"1.187560634","rc":[{"batb":[[0,4.2,2.37],[1,3.9,37.07],[2,1.01,105.79]],"batl":[[0,6.4,2],[1,990,0.01],[2,5.7,0]],"ltp":4.7,"tv":4352.73,"id":9629296},{"batb":[[0,1.19,122.68],[1,1.18,201.65],[2,1.1,2]],"batl":[[0,1.31,76.5],[1,1.9,1.39],[2,3,5.2]],"ltp":1.25,"tv":7188.21,"id":12343905}]}]}
{"op":"mcm","clk":"4231923461","pt":1631549691616,"mc":[{"id":"1.187560634","rc":[{"batb":[[0,4.4,2.51],[1,4.2,2.37],[2,3.9,37.07]],"batl":[[0,5.8,2.02],[1,6.4,2],[2,990,0.01]],"ltp":4.7,"tv":4352.73,"id":9629296},{"batb":[[0,1.21,131.69],[1,1.19,471.76],[2,1.18,427.47]],"batl":[[0,1.29,84.5],[1,1.31,297],[2,1.32,151.51]],"ltp":1.25,"tv":7188.21,"id":12343905}]}]}
{"op":"mcm","clk":"4231923492","pt":1631549691937,"mc":[{"id":"1.187560634","rc":[{"batb":[[0,4.2,2.37],[1,3.9,37.07],[2,1.01,105.79]],"batl":[[0,6.4,2],[1,990,0.01],[2,990,0]],"ltp":4.7,"tv":4352.73,"id":9629296},{"batb":[[0,1.19,471.76],[1,1.18,427.47],[2,1.1,2]],"batl":[[0,1.31,297],[1,1.32,151.51],[2,1.9,1.39]],"ltp":1.25,"tv":7188.21,"id":12343905}]}]}
{"op":"mcm","clk":"4231923677","pt":1631549693627,"mc":[{"id":"1.187560634","rc":[{"batl":[[0,1.9,1.39],[1,3,5.2],[2,8.8,7.22]],"ltp":1.25,"tv":7188.21,"id":12343905}]}]}
{"op":"mcm","clk":"4231923974","pt":1631549696509,"mc":[{"id":"1.187560634","rc":[{"batb":[[0,5.5,30.43],[1,5.4,24],[2,5.3,24]],"batl":[[0,6.2,53.88],[1,6.4,2],[2,6.8,20]],"ltp":4.7,"tv":4352.73,"id":9629296},{"batb":[[0,1.21,22.26],[1,1.19,521.41],[2,1.18,427.47]],"batl":[[0,1.22,2625.98],[1,1.23,454.48],[2,1.29,45.81]],"ltp":1.25,"tv":7188.21,"id":12343905}]}]}
{"op":"mcm","clk":"4231924047","pt":1631549697351,"mc":[{"id":"1.187560634","rc":[{"batb":[[0,5.5,28.43]],"ltp":4.7,"tv":4352.73,"id":9629296},{"batl":[[0,1.22,449.57]],"ltp":1.25,"tv":7188.21,"id":12343905}]}]}
{"op":"mcm","clk":"4231925091","pt":1631549708214,"mc":[{"id":"1.187560634","rc":[{"batl":[[0,1.22,260.18]],"ltp":1.25,"tv":7188.21,"id":12343905}]}]}
{"op":"mcm","clk":"4231925247","pt":1631549709846,"mc":[{"id":"1.187560634","rc":[{"batb":[[1,1.19,515.45]],"ltp":1.25,"tv":7188.21,"id":12343905}]}]}
{"op":"mcm","clk":"4231925607","pt":1631549713065,"mc":[{"id":"1.187560634","rc":[{"batb":[[0,1.21,28.23]],"ltp":1.25,"tv":7188.21,"id":12343905}]}]}
{"op":"mcm","clk":"4231926241","pt":1631549719478,"mc":[{"id":"1.187560634","rc":[{"trd":[[5.5,78.43]],"batb":[[0,5.4,24],[1,5.3,24],[2,4.8,21.22]],"ltp":5.5,"tv":4431.16,"id":9629296},{"trd":[[1.22,97.24]],"batl":[[0,1.22,162.94]],"ltp":1.22,"tv":7285.45,"id":12343905}],"tv":11716.62}]}
{"op":"mcm","clk":"4231926275","pt":1631549719843,"mc":[{"id":"1.187560634","rc":[{"batb":[[1,1.19,459.07],[2,1.18,201.65]],"ltp":1.22,"tv":7285.45,"id":12343905}]}]}
{"op":"mcm","clk":"4231926561","pt":1631549722671,"mc":[{"id":"1.187560634","rc":[{"batl":[[0,6.2,58.26]],"ltp":5.5,"tv":4431.16,"id":9629296}]}]}
{"op":"mcm","clk":"4231926578","pt":1631549722776,"mc":[{"id":"1.187560634","rc":[{"batb":[[1,1.2,110.54],[2,1.19,459.07]],"batl":[[0,1.22,206.45]],"ltp":1.22,"tv":7285.45,"id":12343905}]}]}
{"op":"mcm","clk":"4231926936","pt":1631549726575,"mc":[{"id":"1.187560634","rc":[{"trd":[[1.22,100.48]],"batl":[[0,1.22,204.83]],"ltp":1.22,"tv":7288.69,"id":12343905}],"tv":11719.86}]}
{"op":"mcm","clk":"4231927216","pt":1631549729674,"mc":[{"id":"1.187560634","rc":[{"trd":[[1.21,43.8]],"batb":[[0,1.21,5.97]],"ltp":1.21,"tv":7288.85,"id":12343905}],"tv":11720.02}]}
{"op":"mcm","clk":"4231927454","pt":1631549732598,"mc":[{"id":"1.187560634","rc":[{"batl":[[0,5.7,6.36],[1,6.2,58.26],[2,6.4,2]],"ltp":5.5,"tv":4431.16,"id":9629296},{"batl":[[1,1.23,477.21]],"ltp":1.21,"tv":7288.85,"id":12343905}]}]}
{"op":"mcm","clk":"4231927528","pt":1631549733491,"mc":[{"id":"1.187560634","rc":[{"trd":[[5.5,78.58]],"ltp":5.5,"tv":4431.32,"id":9629296},{"trd":[[1.22,101.18]],"batb":[[1,1.19,116.71],[2,1.18,201.65]],"batl":[[0,1.23,253.85],[1,1.9,1.39],[2,3,5.2]],"ltp":1.22,"tv":7289.55,"id":12343905}],"tv":11720.87}]}
{"op":"mcm","clk":"4231927843","pt":1631549736378,"mc":[{"id":"1.187560634","rc":[{"batl":[[1,1.25,161.01],[2,1.26,194.5]],"ltp":1.22,"tv":7289.55,"id":12343905}]}]}
{"op":"mcm","clk":"4231928190","pt":1631549739888,"mc":[{"id":"1.187560634","rc":[{"batl":[[0,6.2,58.26],[1,6.4,2],[2,6.8,20]],"ltp":5.5,"tv":4431.32,"id":9629296},{"batl":[[0,1.23,231.12]],"ltp":1.22,"tv":7289.55,"id":12343905}]}]}
{"op":"mcm","clk":"4231928439","pt":1631549742918,"mc":[{"id":"1.187560634","rc":[{"batl":[[0,5.7,6.34],[1,6.2,58.26],[2,6.4,2]],"ltp":5.5,"tv":4431.32,"id":9629296},{"batl":[[0,1.23,253.93]],"ltp":1.22,"tv":7289.55,"id":12343905}]}]}
{"op":"mcm","clk":"4231929472","pt":1631549755453,"mc":[{"id":"1.187560634","rc":[{"trd":[[5.4,0.08]],"batb":[[0,5.4,23.96]],"ltp":5.4,"tv":4431.4,"id":9629296}],"tv":11720.95}]}
{"op":"mcm","clk":"4231929596","pt":1631549756753,"mc":[{"id":"1.187560634","rc":[{"batb":[[2,5,2]],"ltp":5.4,"tv":4431.4,"id":9629296},{"batl":[[1,1.25,257.79],[2,1.26,299.25]],"ltp":1.22,"tv":7289.55,"id":12343905}]}]}
{"op":"mcm","clk":"4231930134","pt":1631549762668,"mc":[{"id":"1.187560634","rc":[{"batb":[[0,5,2],[1,4.8,23.55],[2,4.4,26.93]],"batl":[[0,6.4,2],[1,7,2],[2,7.8,2]],"ltp":5.4,"tv":4431.4,"id":9629296},{"batl":[[0,1.25,257.79],[1,1.26,299.25],[2,1.9,1.39]],"ltp":1.22,"tv":7289.55,"id":12343905}]}]}
{"op":"mcm","clk":"4231930231","pt":1631549763662,"mc":[{"id":"1.187560634","rc":[{"batb":[[0,4.8,2.33],[1,4.4,26.93],[2,1.01,105.79]],"batl":[[0,7.8,2],[1,990,0.01],[2,7.8,0]],"ltp":5.4,"tv":4431.4,"id":9629296},{"batb":[[1,1.16,231.16],[2,1.15,527.99]],"batl":[[0,1.25,161.01]],"ltp":1.22,"tv":7289.55,"id":12343905}]}]}
{"op":"mcm","clk":"4231930496","pt":1631549766443,"mc":[{"id":"1.187560634","rc":[{"batb":[[1,1.15,168.23],[2,1.14,247.87]],"ltp":1.22,"tv":7289.55,"id":12343905}]}]}
{"op":"mcm","clk":"4231930687","pt":1631549768642,"mc":[{"id":"1.187560634","rc":[{"batl":[[0,5.1,3.99],[1,5.3,28.3],[2,5.4,14.16]],"ltp":5.4,"tv":4431.4,"id":9629296},{"batb":[[0,1.23,87.52],[1,1.22,451.83],[2,1.21,5.97]],"batl":[[1,1.26,575.64]],"ltp":1.22,"tv":7289.55,"id":12343905}]}]}
{"op":"mcm","clk":"4231930776","pt":1631549769638,"mc":[{"id":"1.187560634","rc":[{"batb":[[2,4.1,32.38]],"batl":[[1,5.3,5.66],[2,5.4,2.84]],"ltp":5.4,"tv":4431.4,"id":9629296},{"batb":[[2,1.21,226.84]],"batl":[[2,1.27,118.12]],"ltp":1.22,"tv":7289.55,"id":12343905}]}]}
{"op":"mcm","clk":"4231930791","pt":1631549769746,"mc":[{"id":"1.187560634","rc":[{"batl":[[2,1.27,23.62]],"ltp":1.22,"tv":7289.55,"id":12343905}]}]}
{"op":"mcm","clk":"4231931349","pt":1631549775717,"mc":[{"id":"1.187560634","rc":[{"batb":[[1,4.7,2.32],[2,4.5,2.58]],"ltp":5.4,"tv":4431.4,"id":9629296},{"batb":[[2,1.21,340.53]],"batl":[[2,1.27,106.12]],"ltp":1.22,"tv":7289.55,"id":12343905}]}]}
{"op":"mcm","clk":"4231931497","pt":1631549777495,"mc":[{"id":"1.187560634","rc":[{"batb":[[0,4.7,2.32],[1,4.5,2.58],[2,4.4,26.93]],"batl":[[0,5.8,2.02],[1,6.4,2],[2,7.8,2]],"ltp":5.4,"tv":4431.4,"id":9629296},{"batb":[[0,1.21,334.56],[1,1.19,137.71],[2,1.17,206.51]],"batl":[[0,1.27,82.5],[1,1.28,78.34],[2,1.32,44.76]],"ltp":1.22,"tv":7289.55,"id":12343905}]}]}
{"op":"mcm","clk":"4231931541","pt":1631549777919,"mc":[{"id":"1.187560634","rc":[{"batb":[[0,4.5,2.58],[1,4.1,32.38],[2,1.01,105.79]],"batl":[[0,6.4,2],[1,7.8,2],[2,990,0.01]],"ltp":5.4,"tv":4431.4,"id":9629296},{"batb":[[0,1.19,137.71],[1,1.17,206.51],[2,1.15,168.23]],"batl":[[0,1.28,78.34],[1,1.9,1.39],[2,3,5.2]],"ltp":1.22,"tv":7289.55,"id":12343905}]}]}
{"op":"mcm","clk":"4231931903","pt":1631549782420,"mc":[{"id":"1.187560634","rc":[{"batb":[[0,1.22,155.98],[1,1.21,261.89],[2,1.19,137.71]],"batl":[[0,1.24,117.47],[1,1.25,204.85],[2,1.28,78.34]],"ltp":1.22,"tv":7289.55,"id":12343905}]}]}
{"op":"mcm","clk":"4231932001","pt":1631549783621,"mc":[{"id":"1.187560634","rc":[{"batl":[[0,5.2,19.28],[1,6.4,2],[2,7.8,2]],"ltp":5.4,"tv":4431.4,"id":9629296},{"batb":[[0,1.23,18.76],[1,1.22,155.98],[2,1.21,261.89]],"batl":[[1,1.25,226.51]],"ltp":1.22,"tv":7289.55,"id":12343905}]}]}
{"op":"mcm","clk":"4231932085","pt":1631549784623,"mc":[{"id":"1.187560634","rc":[{"batb":[[0,4.7,2.32],[1,4.5,2.58],[2,4.1,32.38]],"batl":[[0,5.8,2.02]],"ltp":5.4,"tv":4431.4,"id":9629296},{"batb":[[0,1.22,155.98],[1,1.21,380.58],[2,1.19,137.71]],"batl":[[1,1.25,204.85],[2,1.27,93.5]],"ltp":1.22,"tv":7289.55,"id":12343905}]}]}
{"op":"mcm","clk":"4231932164","pt":1631549785405,"mc":[{"id":"1.187560634","rc":[{"batb":[[0,1.21,118.69],[1,1.19,137.71],[2,1.17,206.51]],"batl":[[0,1.27,93.5],[1,1.28,78.34],[2,1.9,1.39]],"ltp":1.22,"tv":7289.55,"id":12343905}]}]}
{"op":"mcm","clk":"4231932191","pt":1631549785713,"mc":[{"id":"1.187560634","rc":[{"batb":[[0,4.5,2.58],[1,4.1,32.38],[2,1.01,105.79]],"batl":[[0,6.4,2],[1,7.8,2],[2,990,0.01]],"ltp":5.4,"tv":4431.4,"id":9629296},{"batb":[[0,1.19,137.71],[1,1.17,206.51],[2,1.15,168.23]],"batl":[[0,1.28,78.34],[1,1.9,1.39],[2,3,5.2]],"ltp":1.22,"tv":7289.55,"id":12343905}]}]}
{"op":"mcm","clk":"4231932425","pt":1631549788316,"mc":[{"id":"1.187560634","rc":[{"batb":[[0,1.19,358.95],[1,1.18,315.73],[2,1.17,206.51]],"batl":[[0,1.28,243.12],[1,1.29,170.66],[2,1.9,1.39]],"ltp":1.22,"tv":7289.55,"id":12343905}]}]}
{"op":"mcm","clk":"4231932597","pt":1631549790717,"mc":[{"id":"1.187560634","rc":[{"batb":[[0,1.19,137.71],[1,1.17,206.51],[2,1.15,168.23]],"ltp":1.22,"tv":7289.55,"id":12343905}]}]}
{"op":"mcm","clk":"4231932721","pt":1631549792443,"mc":[{"id":"1.187560634","rc":[{"batb":[[0,4.7,2.32],[1,4.5,2.58],[2,4.1,32.38]],"batl":[[0,5.8,2.02],[1,6.4,2],[2,7.8,2]],"ltp":5.4,"tv":4431.4,"id":9629296},{"batb":[[0,1.21,110.69],[1,1.19,137.71],[2,1.17,206.51]],"batl":[[0,1.27,83.5],[1,1.28,243.12],[2,1.29,170.66]],"ltp":1.22,"tv":7289.55,"id":12343905}]}]}
{"op":"mcm","clk":"4231932825","pt":1631549793599,"mc":[{"id":"1.187560634","rc":[{"batb":[[0,4.5,9.4],[1,4.3,63.26],[2,4.2,61.4]],"batl":[[0,4.8,7.7],[1,5.1,43.85],[2,6.4,2]],"ltp":5.4,"tv":4431.4,"id":9629296},{"batb":[[0,1.25,3388.29],[1,1.24,219.36],[2,1.23,212.9]],"batl":[[0,1.28,412.77],[1,1.29,170.66],[2,1.9,1.39]],"ltp":1.22,"tv":7289.55,"id":12343905}]}]}
{"op":"mcm","clk":"4231932889","pt":1631549794535,"mc":[{"id":"1.187560634","rc":[{"batb":[[1,4.3,31.64],[2,4.2,30.7]],"ltp":5.4,"tv":4431.4,"id":9629296},{"batb":[[0,1.25,513.3],[1,1.24,387.4],[2,1.23,258.43]],"batl":[[2,1.35,43.77]],"ltp":1.22,"tv":7289.55,"id":12343905}]}]}
{"op":"mcm","clk":"4231933110","pt":1631549797520,"mc":[{"id":"1.187560634","rc":[{"trd":[[1.28,240.04]],"batl":[[0,1.28,412.75]],"ltp":1.28,"tv":7289.59,"id":12343905}],"tv":11720.99}]}
{"op":"mcm","clk":"4231933189","pt":1631549798612,"mc":[{"id":"1.187560634","rc":[{"batl":[[2,1.3,227.16]],"ltp":1.28,"tv":7289.59,"id":12343905}]}]}
{"op":"mcm","clk":"4231933200","pt":1631549798817,"mc":[{"id":"1.187560634","rc":[{"batl":[[2,1.35,43.77]],"ltp":1.28,"tv":7289.59,"id":12343905}]}]}
{"op":"mcm","clk":"4231933350","pt":1631549800750,"mc":[{"id":"1.187560634","rc":[{"batb":[[1,4.4,2.16],[2,4.3,34.42]],"batl":[[2,5.2,2.08]],"ltp":5.4,"tv":4431.4,"id":9629296},{"batb":[[1,1.24,496.67],[2,1.23,368.06]],"batl":[[1,1.29,258.16],[2,1.3,81.95]],"ltp":1.28,"tv":7289.59,"id":12343905}]}]}
{"op":"mcm","clk":"4231933570","pt":1631549803621,"mc":[{"id":"1.187560634","rc":[{"batb":[[0,4.4,2.16],[1,4.3,2.78],[2,4.1,32.38]],"batl":[[0,5.2,2.08],[1,5.4,2.04],[2,6.4,2]],"ltp":5.4,"tv":4431.4,"id":9629296},{"batb":[[0,1.24,161.24],[1,1.23,261.62],[2,1.2,175.14]],"batl":[[0,1.29,87.5],[1,1.3,81.95],[2,1.35,43.77]],"ltp":1.28,"tv":7289.59,"id":12343905}]}]}
{"op":"mcm","clk":"4231933590","pt":1631549803834,"mc":[{"id":"1.187560634","rc":[{"batb":[[0,4.3,2.78],[1,3.9,36.99],[2,1.01,105.79]],"batl":[[0,5.4,2.04],[1,6.4,2],[2,7.8,2]],"ltp":5.4,"tv":4431.4,"id":9629296},{"batb":[[0,1.24,4.31],[1,1.23,109.63]],"batl":[[0,1.3,81.95],[1,1.9,1.39],[2,3,5.2]],"ltp":1.28,"tv":7289.59,"id":12343905}]}]}
{"op":"mcm","clk":"4231933775","pt":1631549806643,"mc":[{"id":"1.187560634","rc":[{"batb":[[2,1.22,274.14]],"batl":[[0,1.3,178.91],[1,1.31,158.71],[2,1.9,1.39]],"ltp":1.28,"tv":7289.59,"id":12343905}]}]}
{"op":"mcm","clk":"4231934093","pt":1631549810633,"mc":[{"id":"1.187560634","rc":[{"batb":[[0,4.4,2.61],[1,4.3,2.78],[2,3.9,36.99]],"batl":[[0,5.2,2.03],[1,5.4,2.04],[2,6.4,2]],"ltp":5.4,"tv":4431.4,"id":9629296},{"batb":[[0,1.24,118.83]],"batl":[[0,1.29,86.5],[1,1.3,178.91],[2,1.31,158.71]],"ltp":1.28,"tv":7289.59,"id":12343905}]}]}
{"op":"mcm","clk":"4231934105","pt":1631549810838,"mc":[{"id":"1.187560634","rc":[{"batb":[[0,4.3,2.78],[1,3.9,36.99],[2,1.01,105.79]],"batl":[[0,5.4,2.04],[1,6.4,2],[2,7.8,2]],"ltp":5.4,"tv":4431.4,"id":9629296},{"batb":[[0,1.24,4.31]],"batl":[[0,1.3,178.91],[1,1.31,158.71],[2,1.9,1.39]],"ltp":1.28,"tv":7289.59,"id":12343905}]}]}
{"op":"mcm","clk":"4231934320","pt":1631549813672,"mc":[{"id":"1.187560634","rc":[{"batb":[[2,1.2,175.14]],"ltp":1.28,"tv":7289.59,"id":12343905}]}]}
{"op":"mcm","clk":"4231934408","pt":1631549814571,"mc":[{"id":"1.187560634","rc":[{"batb":[[0,4.4,2.36],[1,4.3,2.78],[2,3.9,36.99]],"batl":[[0,5.2,2.13],[1,5.4,2.04],[2,6.4,2]],"ltp":5.4,"tv":4431.4,"id":9629296},{"batb":[[0,1.24,95.83]],"batl":[[0,1.29,87.5],[1,1.3,178.91],[2,1.31,158.71]],"ltp":1.28,"tv":7289.59,"id":12343905}]}]}
{"op":"mcm","clk":"4231934425","pt":1631549814775,"mc":[{"id":"1.187560634","rc":[{"batb":[[0,4.3,2.78],[1,3.9,36.99],[2,1.01,105.79]],"batl":[[0,5.4,2.04],[1,6.4,2],[2,7.8,2]],"ltp":5.4,"tv":4431.4,"id":9629296},{"batb":[[0,1.24,4.31]],"batl":[[0,1.3,178.91],[1,1.31,158.71],[2,1.9,1.39]],"ltp":1.28,"tv":7289.59,"id":12343905}]}]}
{"op":"mcm","clk":"4231934564","pt":1631549816580,"mc":[{"id":"1.187560634","rc":[{"batb":[[0,4.3,8.06]],"batl":[[0,4.5,5.69],[1,4.7,74.48],[2,4.8,57.17]],"ltp":5.4,"tv":4431.4,"id":9629296},{"batb":[[0,1.27,264.66],[1,1.26,205.6],[2,1.23,109.63]],"batl":[[0,1.3,356.5]],"ltp":1.28,"tv":7289.59,"id":12343905}]}]}
{"op":"mcm","clk":"4231934643","pt":1631549817571,"mc":[{"id":"1.187560634","rc":[{"batb":[[2,3.75,40.68]],"batl":[[1,4.7,44.69],[2,4.8,50.79]],"ltp":5.4,"tv":4431.4,"id":9629296},{"batb":[[1,1.26,252.5],[2,1.25,138.65]],"batl":[[2,1.32,113.64]],"ltp":1.28,"tv":7289.59,"id":12343905}]}]}
{"op":"mcm","clk":"4231934665","pt":1631549817786,"mc":[{"id":"1.187560634","rc":[{"batl":[[1,4.7,31.92],[2,4.8,44.41]],"ltp":5.4,"tv":4431.4,"id":9629296},{"batl":[[2,1.32,22.72]],"ltp":1.28,"tv":7289.59,"id":12343905}]}]}
{"op":"mcm","clk":"4231934992","pt":1631549821624,"mc":[{"id":"1.187560634","rc":[{"trd":[[1.3,30]],"batl":[[0,1.3,341.5]],"ltp":1.3,"tv":7319.59,"id":12343905}],"tv":11750.99}]}
{"op":"mcm","clk":"4231935225","pt":1631549824505,"mc":[{"id":"1.187560634","rc":[{"batb":[[1,4.2,2.57],[2,3.9,36.99]],"ltp":5.4,"tv":4431.4,"id":9629296},{"trd":[[1.3,80]],"batb":[[1,1.26,351.48]],"batl":[[0,1.3,316.5],[1,1.31,241.21]],"ltp":1.3,"tv":7369.59,"id":12343905}],"tv":11800.99}]}
{"op":"mcm","clk":"4231936023","pt":1631549832293,"mc":[{"id":"1.187560634","rc":[{"batb":[[0,1.28,4.31],[1,1.27,264.66],[2,1.26,351.48]],"ltp":1.3,"tv":7369.59,"id":12343905}]}]}
{"op":"mcm","clk":"4231936211","pt":1631549834404,"mc":[{"id":"1.187560634","rc":[{"trd":[[4.3,7.8]],"batb":[[0,4.3,4.16]],"ltp":4.3,"tv":4439.2,"id":9629296},{"batb":[[2,1.26,304.58]],"ltp":1.3,"tv":7369.59,"id":12343905}],"tv":11808.79}]}
{"op":"mcm","clk":"4231936484","pt":1631549837827,"mc":[{"id":"1.187560634","rc":[{"batb":[[0,4.3,6.64]],"ltp":4.3,"tv":4439.2,"id":9629296}]}]}
{"op":"mcm","clk":"4231936588","pt":1631549839033,"mc":[{"id":"1.187560634","rc":[{"batb":[[1,1.26,98.98],[2,1.25,138.65]],"batl":[[0,1.3,219.54],[1,1.31,82.5]],"ltp":1.3,"tv":7369.59,"id":12343905}]}]}
{"op":"mcm","clk":"4231937000","pt":1631549843542,"mc":[{"id":"1.187560634","rc":[{"trd":[[1.3,80.04]],"batl":[[0,1.3,219.52]],"ltp":1.3,"tv":7369.63,"id":12343905}],"tv":11808.83}]}
{"op":"mcm","clk":"4231937126","pt":1631549844643,"mc":[{"id":"1.187560634","rc":[{"batb":[[0,4.3,2.48]],"batl":[[0,4.7,31.92],[1,4.8,44.41],[2,4.9,5.25]],"ltp":4.3,"tv":4439.2,"id":9629296}]}]}
{"op":"mcm","clk":"4231937393","pt":1631549847619,"mc":[{"id":"1.187560634","rc":[{"batb":[[0,4.3,6.64]],"ltp":4.3,"tv":4439.2,"id":9629296},{"batb":[[0,1.29,13.98],[1,1.28,4.31],[2,1.26,98.98]],"ltp":1.3,"tv":7369.63,"id":12343905}]}]}
{"op":"mcm","clk":"4231937541","pt":1631549849351,"mc":[{"id":"1.187560634","rc":[{"batb":[[0,3.9,36.99],[1,3.75,40.68],[2,1.01,105.79]],"batl":[[0,4.9,2.05],[1,5.4,2.04],[2,6.4,2]],"ltp":4.3,"tv":4439.2,"id":9629296},{"batb":[[0,1.28,4.31],[1,1.26,98.98],[2,1.25,138.65]],"batl":[[0,1.31,82.5],[1,1.9,1.39],[2,3,5.2]],"ltp":1.3,"tv":7369.63,"id":12343905}]}]}
{"op":"mcm","clk":"4231937591","pt":1631549849827,"mc":[{"id":"1.187560634","rc":[{"batb":[[0,3.75,40.68],[1,1.01,105.79],[2,1.01,0]],"ltp":4.3,"tv":4439.2,"id":9629296},{"batb":[[2,1.23,262.21]],"ltp":1.3,"tv":7369.63,"id":12343905}]}]}
{"op":"mcm","clk":"4231937853","pt":1631549852539,"mc":[{"id":"1.187560634","rc":[{"batb":[[0,4.3,2.58],[1,4.2,2.47],[2,3.75,40.68]],"ltp":4.3,"tv":4439.2,"id":9629296},{"batl":[[0,1.3,79.75],[1,1.31,82.5],[2,1.9,1.39]],"ltp":1.3,"tv":7369.63,"id":12343905}]}]}
{"op":"mcm","clk":"4231937876","pt":1631549852753,"mc":[{"id":"1.187560634","rc":[{"batb":[[0,4.2,2.47],[1,3.75,40.68],[2,1.01,105.79]],"ltp":4.3,"tv":4439.2,"id":9629296},{"batl":[[0,1.31,82.5],[1,1.9,1.39],[2,3,5.2]],"ltp":1.3,"tv":7369.63,"id":12343905}]}]}
{"op":"mcm","clk":"4231938381","pt":1631549858133,"mc":[{"id":"1.187560634","rc":[{"batl":[[0,4.3,3.63],[1,4.6,2],[2,4.7,61.1]],"ltp":4.3,"tv":4439.2,"id":9629296},{"batb":[[0,1.29,331.31],[1,1.28,234.57],[2,1.27,81.41]],"batl":[[0,1.31,235.89],[1,1.32,169.11],[2,1.33,146.21]],"ltp":1.3,"tv":7369.63,"id":12343905}]}]}
{"op":"mcm","clk":"4231938489","pt":1631549859270,"mc":[{"id":"1.187560634","rc":[{"batb":[[1,4,7.5],[2,3.95,3.76]],"ltp":4.3,"tv":4439.2,"id":9629296},{"batb":[[2,1.27,211]],"ltp":1.3,"tv":7369.63,"id":12343905}]}]}
{"op":"mcm","clk":"4231938736","pt":1631549861735,"mc":[{"id":"1.187560634","rc":[{"batb":[[1,1.28,230.26]],"ltp":1.3,"tv":7369.63,"id":12343905}]}]}
{"op":"mcm","clk":"4231939411","pt":1631549868948,"mc":[{"id":"1.187560634","rc":[{"trd":[[1.31,8.62]],"batl":[[0,1.31,231.58]],"ltp":1.31,"tv":7378.25,"id":12343905}],"tv":11817.45}]}
{"op":"mcm","clk":"4231939494","pt":1631549870053,"mc":[{"id":"1.187560634","rc":[{"trd":[[4.3,8.44]],"batl":[[0,4.3,2.99]],"ltp":4.3,"tv":4439.84,"id":9629296},{"trd":[[1.3,82.16]],"ltp":1.3,"tv":7380.36,"id":12343905}],"tv":11820.21}]}
{"op":"mcm","clk":"4231939671","pt":1631549872255,"mc":[{"id":"1.187560634","rc":[{"trd":[[4.2,0.38]],"batb":[[0,4.2,2.28]],"ltp":4.2,"tv":4440.21,"id":9629296}],"tv":11820.58}]}
{"op":"mcm","clk":"4231939754","pt":1631549873193,"mc":[{"id":"1.187560634","rc":[{"trd":[[4.2,2.18]],"batb":[[0,4.2,1.38]],"ltp":4.2,"tv":4442.01,"id":9629296}],"tv":11822.38}]}
{"op":"mcm","clk":"4231939887","pt":1631549874673,"mc":[{"id":"1.187560634","rc":[{"trd":[[4.3,11.43]],"batl":[[0,4.6,2],[1,4.7,61.1],[2,4.9,2.05]],"ltp":4.3,"tv":4445.0,"id":9629296},{"trd":[[1.29,406.56],[1.3,92.05]],"batb":[[0,1.29,128.03]],"ltp":1.29,"tv":7796.81,"id":12343905}],"tv":12241.82}]}
{"op":"mcm","clk":"4231940135","pt":1631549877660,"mc":[{"id":"1.187560634","rc":[{"batb":[[0,1.29,146.14]],"batl":[[1,1.32,191.01]],"ltp":1.29,"tv":7796.81,"id":12343905}]}]}
{"op":"mcm","clk":"4231940141","pt":1631549877764,"mc":[{"id":"1.187560634","rc":[{"batl":[[0,1.3,1.62],[1,1.31,231.58],[2,1.32,191.01]],"ltp":1.29,"tv":7796.81,"id":12343905}]}]}
{"op":"mcm","clk":"4231940344","pt":1631549880287,"mc":[{"id":"1.187560634","rc":[{"batl":[[2,1.32,169.23]],"ltp":1.29,"tv":7796.81,"id":12343905}]}]}
{"op":"mcm","clk":"4231940638","pt":1631549883276,"mc":[{"id":"1.187560634","rc":[{"batl":[[0,4.4,5.64],[1,4.6,2],[2,4.7,61.1]],"ltp":4.3,"tv":4445.0,"id":9629296},{"trd":[[1.3,92.17]],"batl":[[0,1.3,1.56],[1,1.31,245.83]],"ltp":1.3,"tv":7796.93,"id":12343905}],"tv":12241.94}]}
{"op":"mcm","clk":"4231940728","pt":1631549884269,"mc":[{"id":"1.187560634","rc":[{"batl":[[0,4.6,2],[1,4.7,61.1],[2,4.9,2.05]],"ltp":4.3,"tv":4445.0,"id":9629296},{"batl":[[1,1.31,231.58]],"ltp":1.3,"tv":7796.93,"id":12343905}]}]}
{"op":"mcm","clk":"4231941028","pt":1631549887619,"mc":[{"id":"1.187560634","rc":[{"batb":[[0,3.85,3.17],[1,3.75,3.07],[2,3.7,3.32]],"batl":[[0,4.9,2.05],[1,5.2,2.18],[2,5.4,2.04]],"ltp":4.3,"tv":4445.0,"id":9629296},{"batb":[[0,1.27,46.53],[1,1.26,98.98],[2,1.24,100.52]],"batl":[[1,1.35,70.5],[2,1.36,69.82]],"ltp":1.3,"tv":7796.93,"id":12343905}]}]}
{"op":"mcm","clk":"4231941060","pt":1631549887890,"mc":[{"id":"1.187560634","rc":[{"batb":[[0,3.7,3.32],[1,3.35,27.18],[2,1.01,105.79]],"batl":[[0,5.2,2.18],[1,6.4,2],[2,7.8,2]],"ltp":4.3,"tv":4445.0,"id":9629296},{"batb":[[0,1.24,100.52],[1,1.23,149.39],[2,1.19,137.71]],"batl":[[1,1.37,74.5],[2,1.9,1.39]],"ltp":1.3,"tv":7796.93,"id":12343905}]}]}
{"op":"mcm","clk":"4231941456","pt":1631549892503,"mc":[{"id":"1.187560634","rc":[{"batl":[[0,4.5,40.65],[1,5.2,2.18],[2,6.4,2]],"ltp":4.3,"tv":4445.0,"id":9629296},{"trd":[[1.3,95.29]],"batb":[[0,1.3,169.51],[1,1.29,219.45],[2,1.24,100.52]],"batl":[[0,1.31,43.5],[1,1.33,128.93],[2,1.34,141.62]],"ltp":1.3,"tv":7800.05,"id":12343905}],"tv":12245.06}]}
{"op":"mcm","clk":"4231941478","pt":1631549892820,"mc":[{"id":"1.187560634","rc":[{"batl":[[0,5.2,2.18],[1,6.4,2],[2,7.8,2]],"ltp":4.3,"tv":4445.0,"id":9629296},{"batb":[[1,1.29,178.64]],"batl":[[0,1.33,128.93],[1,1.34,141.62],[2,1.37,74.5]],"ltp":1.3,"tv":7800.05,"id":12343905}]}]}
{"op":"mcm","clk":"4231941623","pt":1631549894495,"mc":[{"id":"1.187560634","rc":[{"batb":[[0,3.85,2.97],[1,3.7,3.32],[2,3.35,27.18]],"batl":[[0,4.9,2.05],[1,5.2,2.18],[2,6.4,2]],"ltp":4.3,"tv":4445.0,"id":9629296},{"batb":[[2,1.26,106.48]],"batl":[[2,1.35,70.5]],"ltp":1.3,"tv":7800.05,"id":12343905}]}]}
{"op":"mcm","clk":"4231941900","pt":1631549897488,"mc":[{"id":"1.187560634","rc":[{"batb":[[0,1.26,106.48],[1,1.24,100.52],[2,1.23,149.39]],"batl":[[0,1.35,70.5],[1,1.37,74.5],[2,1.9,1.39]],"ltp":1.3,"tv":7800.05,"id":12343905}]}]}
{"op":"mcm","clk":"4231941917","pt":1631549897692,"mc":[{"id":"1.187560634","rc":[{"batb":[[0,3.7,3.32],[1,3.35,27.18],[2,1.01,105.79]],"batl":[[0,5.2,2.18],[1,6.4,2],[2,7.8,2]],"ltp":4.3,"tv":4445.0,"id":9629296},{"batb":[[0,1.24,100.52],[1,1.23,149.39],[2,1.19,137.71]],"batl":[[0,1.37,74.5],[1,1.9,1.39],[2,3,5.2]],"ltp":1.3,"tv":7800.05,"id":12343905}]}]}
{"op":"mcm","clk":"4231942185","pt":1631549900523,"mc":[{"id":"1.187560634","rc":[{"batb":[[0,1.26,91.69],[1,1.25,212],[2,1.24,100.52]],"batl":[[1,1.38,92.35],[2,1.39,119.88]],"ltp":1.3,"tv":7800.05,"id":12343905}]}]}
{"op":"mcm","clk":"4231942232","pt":1631549900996,"mc":[{"id":"1.187560634","rc":[{"batb":[[0,3.85,2.97],[1,3.7,3.32],[2,3.35,27.18]],"batl":[[0,4.9,2.15],[1,5.2,2.18],[2,6.4,2]],"ltp":4.3,"tv":4445.0,"id":9629296},{"batb":[[0,1.26,182.67]],"batl":[[0,1.35,76.3],[1,1.37,74.5],[2,1.38,92.35]],"ltp":1.3,"tv":7800.05,"id":12343905}]}]}
{"op":"mcm","clk":"4231942336","pt":1631549901986,"mc":[{"id":"1.187560634","rc":[{"batb":[[0,3.7,3.32],[1,3.35,27.18],[2,1.01,105.79]],"batl":[[0,5.2,2.18],[1,6.4,2],[2,7.8,2]],"ltp":4.3,"tv":4445.0,"id":9629296},{"batb":[[0,1.26,91.69]],"batl":[[0,1.37,74.5],[1,1.9,1.39],[2,3,5.2]],"ltp":1.3,"tv":7800.05,"id":12343905}]}]}
{"op":"mcm","clk":"4231942642","pt":1631549905123,"mc":[{"id":"1.187560634","rc":[{"batb":[[0,4.5,33.32],[1,4.4,16.66],[2,4.3,16.66]],"batl":[[0,4.8,4.53],[1,5.2,2.18],[2,6.4,2]],"ltp":4.3,"tv":4445.0,"id":9629296},{"batb":[[2,1.24,367.87]],"batl":[[0,1.28,313.22],[1,1.29,172.33],[2,1.3,30.76]],"ltp":1.3,"tv":7800.05,"id":12343905}]}]}
{"op":"mcm","clk":"4231942743","pt":1631549906135,"mc":[{"id":"1.187560634","rc":[{"batb":[[0,4.5,6.66],[1,4.4,3.34],[2,4.3,3.34]],"batl":[[1,5.1,5.88],[2,5.2,5.12]],"ltp":4.3,"tv":4445.0,"id":9629296}]}]}
{"op":"mcm","clk":"4231943398","pt":1631549912736,"mc":[{"id":"1.187560634","rc":[{"trd":[[1.28,242.18]],"batl":[[0,1.28,312.15]],"ltp":1.28,"tv":7802.19,"id":12343905}],"tv":12247.2}]}
{"op":"mcm","clk":"4231944237","pt":1631549922004,"mc":[{"id":"1.187560634","rc":[{"batb":[[2,1.24,320.21]],"ltp":1.28,"tv":7802.19,"id":12343905}]}]}
{"op":"mcm","clk":"4231944314","pt":1631549922837,"mc":[{"id":"1.187560634","rc":[{"batl":[[0,5.1,5.88],[1,5.2,5.12],[2,5.3,2.94]],"ltp":4.3,"tv":4445.0,"id":9629296},{"batl":[[0,1.28,290.25]],"ltp":1.28,"tv":7802.19,"id":12343905}]}]}
{"op":"mcm","clk":"4231944450","pt":1631549924510,"mc":[{"id":"1.187560634","rc":[{"batb":[[0,4,2.79],[1,3.65,21.89],[2,1.01,105.79]],"batl":[[0,5.4,2.04],[1,6.4,2],[2,7.8,2]],"ltp":4.3,"tv":4445.0,"id":9629296},{"batb":[[0,1.23,120.63],[1,1.21,168.85],[2,1.19,137.71]],"batl":[[0,1.33,70.5],[1,1.9,1.39],[2,3,5.2]],"ltp":1.28,"tv":7802.19,"id":12343905}]}]}
{"op":"mcm","clk":"4231944691","pt":1631549927536,"mc":[{"id":"1.187560634","rc":[{"batb":[[0,4.2,2.57],[1,4,2.79],[2,3.65,21.89]],"batl":[[0,5.2,2.03],[1,5.4,2.04],[2,6.4,2]],"ltp":4.3,"tv":4445.0,"id":9629296},{"batb":[[0,1.24,117.77],[1,1.23,120.63],[2,1.21,168.85]],"batl":[[0,1.31,77.5],[1,1.33,70.5],[2,1.9,1.39]],"ltp":1.28,"tv":7802.19,"id":12343905}]}]}
{"op":"mcm","clk":"4231944707","pt":1631549927748,"mc":[{"id":"1.187560634","rc":[{"batb":[[0,4,2.79],[1,3.65,21.89],[2,1.01,105.79]],"batl":[[0,5.4,2.04],[1,6.4,2],[2,7.8,2]],"ltp":4.3,"tv":4445.0,"id":9629296},{"batb":[[0,1.23,120.63],[1,1.21,168.85],[2,1.19,137.71]],"batl":[[0,1.33,70.5],[1,1.9,1.39],[2,3,5.2]],"ltp":1.28,"tv":7802.19,"id":12343905}]}]}
{"op":"mcm","clk":"4231944822","pt":1631549929217,"mc":[{"id":"1.187560634","rc":[{"batb":[[0,1.26,275.17],[1,1.25,216.35],[2,1.23,120.63]],"batl":[[0,1.29,110.3],[1,1.3,165.35],[2,1.33,70.5]],"ltp":1.28,"tv":7802.19,"id":12343905}]}]}
{"op":"mcm","clk":"4231944975","pt":1631549931041,"mc":[{"id":"1.187560634","rc":[{"batb":[[0,4.2,2.77],[1,4,2.79],[2,3.65,21.89]],"batl":[[0,5.2,2.08],[1,5.4,2.04],[2,6.4,2]],"ltp":4.3,"tv":4445.0,"id":9629296},{"batb":[[2,1.24,96.77]],"batl":[[2,1.31,87.5]],"ltp":1.28,"tv":7802.19,"id":12343905}]}]}
{"op":"mcm","clk":"4231945168","pt":1631549933533,"mc":[{"id":"1.187560634","rc":[{"batb":[[0,4,2.79],[1,3.65,21.89],[2,1.01,105.79]],"batl":[[0,5.4,2.04],[1,6.4,2],[2,7.8,2]],"ltp":4.3,"tv":4445.0,"id":9629296},{"batb":[[0,1.23,120.63],[1,1.21,168.85],[2,1.19,137.71]],"batl":[[0,1.33,70.5],[1,1.9,1.39],[2,3,5.2]],"ltp":1.28,"tv":7802.19,"id":12343905}]}]}
{"op":"mcm","clk":"4231945405","pt":1631549936141,"mc":[{"id":"1.187560634","rc":[{"batb":[[0,1.23,323.47],[1,1.22,249.95],[2,1.21,168.85]],"batl":[[0,1.33,168.02],[1,1.34,142.13],[2,1.9,1.39]],"ltp":1.28,"tv":7802.19,"id":12343905}]}]}
{"op":"mcm","clk":"4231945723","pt":1631549940466,"mc":[{"id":"1.187560634","rc":[{"batb":[[0,4.2,2.57],[1,4,2.79],[2,3.65,21.89]],"batl":[[0,5.2,2.08],[1,5.4,2.04],[2,6.4,2]],"ltp":4.3,"tv":4445.0,"id":9629296},{"batb":[[0,1.24,122.77],[1,1.23,120.63]],"batl":[[0,1.31,84.5],[1,1.33,168.02],[2,1.34,142.13]],"ltp":1.28,"tv":7802.19,"id":12343905}]}]}
{"op":"mcm","clk":"4231945745","pt":1631549940736,"mc":[{"id":"1.187560634","rc":[{"batb":[[0,4,2.79],[1,3.65,21.89],[2,1.01,105.79]],"batl":[[0,5.4,2.04],[1,6.4,2],[2,7.8,2]],"ltp":4.3,"tv":4445.0,"id":9629296},{"batb":[[0,1.23,120.63],[1,1.21,168.85],[2,1.19,137.71]],"batl":[[0,1.33,168.02],[1,1.34,142.13],[2,1.9,1.39]],"ltp":1.28,"tv":7802.19,"id":12343905}]}]}
{"op":"mcm","clk":"4231945917","pt":1631549942659,"mc":[{"id":"1.187560634","rc":[{"batb":[[0,4.1,4.75],[1,4,2.79],[2,3.65,21.89]],"batl":[[0,4.3,823.39],[1,4.4,34.1],[2,4.5,17.04]],"ltp":4.3,"tv":4445.0,"id":9629296},{"batb":[[0,1.26,520.31],[1,1.23,120.63],[2,1.21,168.85]],"batl":[[0,1.33,383.71]],"ltp":1.28,"tv":7802.19,"id":12343905}]}]}
{"op":"mcm","clk":"4231946015","pt":1631549943651,"mc":[{"id":"1.187560634","rc":[{"batb":[[2,3.95,37.96]],"batl":[[0,4.3,7.51],[1,4.4,6.82],[2,4.5,5.4]],"ltp":4.3,"tv":4445.0,"id":9629296},{"batb":[[0,1.3,204.92],[1,1.29,193.11],[2,1.28,169.13]],"batl":[[2,1.39,42.51]],"ltp":1.28,"tv":7802.19,"id":12343905}]}]}
{"op":"mcm","clk":"4231946040","pt":1631549943963,"mc":[{"id":"1.187560634","rc":[{"batb":[[2,3.95,7.6]],"ltp":4.3,"tv":4445.0,"id":9629296}]}]}
{"op":"mcm","clk":"4231946315","pt":1631549947653,"mc":[{"id":"1.187560634","rc":[{"batl":[[1,1.34,373.38]],"ltp":1.28,"tv":7802.19,"id":12343905}]}]}
{"op":"mcm","clk":"4231946331","pt":1631549947859,"mc":[{"id":"1.187560634","rc":[{"batl":[[1,1.34,142.13]],"ltp":1.28,"tv":7802.19,"id":12343905}]}]}
{"op":"mcm","clk":"4231946479","pt":1631549949852,"mc":[{"id":"1.187560634","rc":[{"batl":[[2,1.39,107.01]],"ltp":1.28,"tv":7802.19,"id":12343905}]}]}
{"op":"mcm","clk":"4231947317","pt":1631549959883,"mc":[{"id":"1.187560634","rc":[{"batb":[[2,1.28,122.97]],"batl":[[2,1.39,64.5]],"ltp":1.28,"tv":7802.19,"id":12343905}]}]}
{"op":"mcm","clk":"4231947474","pt":1631549961462,"mc":[{"id":"1.187560634","rc":[{"batb":[[0,3.35,3.47],[1,3.2,30.45],[2,1.01,105.79]],"batl":[[0,4.9,2.35],[1,5.2,2.08],[2,5.4,2.04]],"ltp":4.3,"tv":4445.0,"id":9629296},{"batb":[[0,1.26,106.48],[1,1.24,233.14],[2,1.23,120.63]],"batl":[[0,1.42,54.75],[1,1.9,1.39],[2,3,5.2]],"ltp":1.28,"tv":7802.19,"id":12343905}]}]}
{"op":"mcm","clk":"4231947500","pt":1631549961771,"mc":[{"id":"1.187560634","rc":[{"batl":[[0,5.2,2.08],[1,5.4,2.04],[2,6.4,2]],"ltp":4.3,"tv":4445.0,"id":9629296},{"batb":[[0,1.24,233.14],[1,1.23,120.63],[2,1.19,137.71]],"ltp":1.28,"tv":7802.19,"id":12343905}]}]}
{"op":"mcm","clk":"4231947733","pt":1631549964583,"mc":[{"id":"1.187560634","rc":[{"batb":[[0,3.55,3.39],[1,3.35,3.47],[2,3.2,30.45]],"ltp":4.3,"tv":4445.0,"id":9629296},{"batl":[[0,1.39,68.5],[1,1.42,54.75],[2,1.9,1.39]],"ltp":1.28,"tv":7802.19,"id":12343905}]}]}
{"op":"mcm","clk":"4231947809","pt":1631549965368,"mc":[{"id":"1.187560634","rc":[{"batb":[[0,3.35,3.47],[1,3.2,30.45],[2,1.01,105.79]],"ltp":4.3,"tv":4445.0,"id":9629296},{"batl":[[0,1.42,54.75],[1,1.9,1.39],[2,3,5.2]],"ltp":1.28,"tv":7802.19,"id":12343905}]}]}
{"op":"mcm","clk":"4231947931","pt":1631549966672,"mc":[{"id":"1.187560634","rc":[{"batl":[[0,4.3,20.65],[1,5.2,2.08],[2,5.4,2.04]],"ltp":4.3,"tv":4445.0,"id":9629296},{"batb":[[0,1.32,103.41],[1,1.31,184.21],[2,1.24,233.14]],"batl":[[0,1.33,20.5],[1,1.35,161.02],[2,1.36,131.51]],"ltp":1.28,"tv":7802.19,"id":12343905}]}]}
{"op":"mcm","clk":"4231947959","pt":1631549966989,"mc":[{"id":"1.187560634","rc":[{"batl":[[0,5.2,2.08],[1,5.4,2.04],[2,6.4,2]],"ltp":4.3,"tv":4445.0,"id":9629296},{"batb":[[1,1.31,163.42]],"batl":[[0,1.35,161.02],[1,1.36,131.51],[2,1.42,54.75]],"ltp":1.28,"tv":7802.19,"id":12343905}]}]}
{"op":"mcm","clk":"4231948066","pt":1631549968592,"mc":[{"id":"1.187560634","rc":[{"batb":[[0,3.55,3.39],[1,3.35,3.47],[2,3.2,30.45]],"batl":[[0,4.9,2.45],[1,5.2,2.08],[2,5.4,2.04]],"ltp":4.3,"tv":4445.0,"id":9629296},{"batb":[[2,1.26,95.48]],"batl":[[2,1.39,70.5]],"ltp":1.28,"tv":7802.19,"id":12343905}]}]}
{"op":"mcm","clk":"4231948305","pt":1631549971472,"mc":[{"id":"1.187560634","rc":[{"batb":[[0,3.35,3.47],[1,3.2,30.45],[2,1.01,105.79]],"batl":[[0,5.2,2.08],[1,5.4,2.04],[2,6.4,2]],"ltp":4.3,"tv":4445.0,"id":9629296},{"batb":[[0,1.24,233.14],[1,1.23,120.63],[2,1.19,137.71]],"batl":[[0,1.42,54.75],[1,1.9,1.39],[2,3,5.2]],"ltp":1.28,"tv":7802.19,"id":12343905}]}]}
{"op":"mcm","clk":"4231948532","pt":1631549974278,"mc":[{"id":"1.187560634","rc":[{"batb":[[0,1.26,214.79],[1,1.25,214.94],[2,1.24,233.14]],"batl":[[0,1.41,96.19],[1,1.42,163.87],[2,1.9,1.39]],"ltp":1.28,"tv":7802.19,"id":12343905}]}]}
{"op":"mcm","clk":"4231948581","pt":1631549974909,"mc":[{"id":"1.187560634","rc":[{"batl":[[0,4.9,2.15],[1,5.2,2.08],[2,5.4,2.04]],"ltp":4.3,"tv":4445.0,"id":9629296},{"batb":[[0,1.26,315.77]],"ltp":1.28,"tv":7802.19,"id":12343905}]}]}
{"op":"mcm","clk":"4231948769","pt":1631549977399,"mc":[{"id":"1.187560634","rc":[{"batl":[[0,5.2,2.08],[1,5.4,2.04],[2,6.4,2]],"ltp":4.3,"tv":4445.0,"id":9629296},{"batb":[[0,1.24,233.14],[1,1.23,120.63],[2,1.19,137.71]],"ltp":1.28,"tv":7802.19,"id":12343905}]}]}
{"op":"mcm","clk":"4231948983","pt":1631549980106,"mc":[{"id":"1.187560634","rc":[{"batb":[[0,3.5,36.07],[1,3.35,3.47],[2,3.2,30.45]],"batl":[[0,3.7,63.05],[1,3.8,9.9],[2,3.85,3.94]],"ltp":4.3,"tv":4445.0,"id":9629296},{"batb":[[0,1.38,95.44],[1,1.37,130.87],[2,1.36,13.18]],"batl":[[0,1.4,90.19],[1,1.41,96.19],[2,1.42,163.87]],"ltp":1.28,"tv":7802.19,"id":12343905}]}]}
{"op":"mcm","clk":"4231949064","pt":1631549981192,"mc":[{"id":"1.187560634","rc":[{"batb":[[1,3.45,8.7],[2,3.4,4.34]],"ltp":4.3,"tv":4445.0,"id":9629296}]}]}
{"op":"mcm","clk":"4231949349","pt":1631549984898,"mc":[{"id":"1.187560634","rc":[{"trd":[[3.5,20]],"batb":[[0,3.5,26.07]],"ltp":3.5,"tv":4465.0,"id":9629296}],"tv":12267.2}]}
{"op":"mcm","clk":"4231950021","pt":1631549992717,"mc":[{"id":"1.187560634","rc":[{"trd":[[1.38,84.78]],"batb":[[0,1.38,93.05]],"ltp":1.38,"tv":7806.97,"id":12343905}],"tv":12271.98}]}
{"op":"mcm","clk":"4231950215","pt":1631549994804,"mc":[{"id":"1.187560634","rc":[{"batl":[[0,3.7,54.06]],"ltp":3.5,"tv":4465.0,"id":9629296},{"batl":[[0,1.4,79.44]],"ltp":1.38,"tv":7806.97,"id":12343905}]}]}
{"op":"mcm","clk":"4231950430","pt":1631549997617,"mc":[{"id":"1.187560634","rc":[{"batb":[[0,1.37,130.87],[1,1.36,13.18],[2,1.34,300.6]],"ltp":1.38,"tv":7806.97,"id":12343905}]}]}
{"op":"mcm","clk":"4231950452","pt":1631549997824,"mc":[{"id":"1.187560634","rc":[{"batl":[[0,3.6,4.72],[1,3.7,54.06],[2,3.8,9.9]],"ltp":3.5,"tv":4465.0,"id":9629296},{"batl":[[0,1.4,84.82]],"ltp":1.38,"tv":7806.97,"id":12343905}]}]}
{"op":"mcm","clk":"4231950701","pt":1631550000522,"mc":[{"id":"1.187560634","rc":[{"batb":[[0,1.37,201.49],[1,1.36,150.38]],"batl":[[1,1.41,121.04]],"ltp":1.38,"tv":7806.97,"id":12343905}]}]}
{"op":"mcm","clk":"4231950928","pt":1631550002642,"mc":[{"id":"1.187560634","rc":[{"batb":[[0,3.2,30.45],[1,2.84,4.22],[2,2.78,17.78]],"batl":[[0,4.6,2.36],[1,5.2,2.08],[2,5.4,2.04]],"ltp":3.5,"tv":4465.0,"id":9629296},{"batb":[[0,1.34,95.62],[1,1.29,117.52],[2,1.28,83.66]],"batl":[[0,1.54,46.25],[1,1.9,1.39],[2,3,5.2]],"ltp":1.38,"tv":7806.97,"id":12343905}]}]}
{"op":"mcm","clk":"4231950954","pt":1631550002842,"mc":[{"id":"1.187560634","rc":[{"batb":[[0,2.84,4.22],[1,2.78,17.78],[2,1.01,105.79]],"ltp":3.5,"tv":4465.0,"id":9629296},{"batb":[[0,1.29,117.52],[1,1.28,83.66],[2,1.24,87.27]],"ltp":1.38,"tv":7806.97,"id":12343905}]}]}
{"op":"mcm","clk":"4231951195","pt":1631550005349,"mc":[{"id":"1.187560634","rc":[{"batb":[[0,1.31,229.63],[1,1.3,172.84],[2,1.29,117.52]],"batl":[[0,1.53,123.59],[1,1.54,125.04],[2,1.9,1.39]],"ltp":1.38,"tv":7806.97,"id":12343905}]}]}
{"op":"mcm","clk":"4231951278","pt":1631550006142,"mc":[{"id":"1.187560634","rc":[{"batb":[[1,2.8,17.53]],"batl":[[0,4.3,2.65],[1,4.6,2.36],[2,5.2,2.08]],"ltp":3.5,"tv":4465.0,"id":9629296},{"batb":[[0,1.31,315.42],[2,1.28,202.94]],"ltp":1.38,"tv":7806.97,"id":12343905}]}]}
{"op":"mcm","clk":"4231951510","pt":1631550008433,"mc":[{"id":"1.187560634","rc":[{"batl":[[0,1.54,46.25],[1,1.9,1.39],[2,3,5.2]],"ltp":1.38,"tv":7806.97,"id":12343905}]}]}
{"op":"mcm","clk":"4231951786","pt":1631550011558,"mc":[{"id":"1.187560634","rc":[{"batb":[[0,3.8,7.9],[1,3.75,3.94],[2,3.7,3.94]],"batl":[[0,4.1,6.17],[1,4.3,2.65],[2,4.6,2.36]],"ltp":3.5,"tv":4465.0,"id":9629296},{"batb":[[2,1.29,253.71]],"batl":[[0,1.34,13.26],[1,1.35,197.17],[2,1.36,131.34]],"ltp":1.38,"tv":7806.97,"id":12343905}]}]}
{"op":"mcm","clk":"4231951888","pt":1631550012657,"mc":[{"id":"1.187560634","rc":[{"batl":[[1,4.2,7.14],[2,4.3,6.23]],"ltp":3.5,"tv":4465.0,"id":9629296}]}]}
{"op":"mcm","clk":"4231952898","pt":1631550023322,"mc":[{"id":"1.187560634","rc":[{"batb":[[0,3.15,4.03],[1,3.05,34.31],[2,1.01,105.79]],"batl":[[0,5,2.12],[1,5.4,2.04],[2,6.4,2]],"ltp":3.5,"tv":4465.0,"id":9629296},{"batb":[[0,1.25,95.41],[1,1.24,147.29],[2,1.23,120.63]],"batl":[[0,1.46,53.25],[1,1.9,1.39],[2,3,5.2]],"ltp":1.38,"tv":7806.97,"id":12343905}]}]}
{"op":"mcm","clk":"4231953199","pt":1631550026616,"mc":[{"id":"1.187560634","rc":[{"batl":[[0,5,2.2]],"ltp":3.5,"tv":4465.0,"id":9629296},{"batb":[[0,1.26,181.98],[1,1.25,310.13],[2,1.24,147.29]],"ltp":1.38,"tv":7806.97,"id":12343905}]}]}
{"op":"mcm","clk":"4231953503","pt":1631550029301,"mc":[{"id":"1.187560634","rc":[{"trd":[[3.9,13.14]],"batb":[[0,4.5,58.25],[1,3.15,4.03],[2,3.05,34.31]],"batl":[[0,4.7,5.15],[1,5,2.12],[2,5.4,2.04]],"ltp":3.9,"tv":4465.08,"id":9629296},{"trd":[[1.34,26.7]],"batb":[[2,1.24,450.99]],"batl":[[0,1.29,197.21],[1,1.3,341.05],[2,1.31,11.54]],"ltp":1.34,"tv":7807.2,"id":12343905}],"tv":12272.29}]}
{"op":"mcm","clk":"4231953613","pt":1631550030293,"mc":[{"id":"1.187560634","rc":[{"batb":[[1,4,33.89],[2,3.55,23.4]],"ltp":3.9,"tv":4465.08,"id":9629296},{"batb":[[0,1.26,205.78],[1,1.25,322.03],[2,1.24,462.89]],"ltp":1.34,"tv":7807.2,"id":12343905}]}]}
{"op":"mcm","clk":"4231954120","pt":1631550035638,"mc":[{"id":"1.187560634","rc":[{"batb":[[1,4,36.93],[2,3.85,3.37]],"batl":[[2,5.2,2.08]],"ltp":3.9,"tv":4465.08,"id":9629296},{"batb":[[2,1.24,563.41]],"ltp":1.34,"tv":7807.2,"id":12343905}]}]}
{"op":"mcm","clk":"4231954614","pt":1631550041031,"mc":[{"id":"1.187560634","rc":[{"trd":[[1.29,456.56]],"batl":[[0,1.29,172.21]],"ltp":1.29,"tv":7857.2,"id":12343905}],"tv":12322.29}]}
{"op":"mcm","clk":"4231954939","pt":1631550044435,"mc":[{"id":"1.187560634","rc":[{"trd":[[4.7,38.07]],"batl":[[0,4.7,5]],"ltp":4.7,"tv":4465.23,"id":9629296},{"trd":[[1.27,209.29]],"batb":[[0,1.26,219.93]],"batl":[[0,1.29,183.4]],"ltp":1.27,"tv":7857.76,"id":12343905}],"tv":12323.0}]}
{"op":"mcm","clk":"4231955090","pt":1631550046523,"mc":[{"id":"1.187560634","rc":[{"batb":[[0,3.85,3.37],[1,3.55,23.4],[2,1.01,105.79]],"batl":[[0,5.6,2.01],[1,6.4,2],[2,7.8,2]],"ltp":4.7,"tv":4465.23,"id":9629296},{"batb":[[0,1.22,108.34],[1,1.2,172.46],[2,1.19,137.71]],"batl":[[0,1.35,68.9],[1,1.9,1.39],[2,3,5.2]],"ltp":1.27,"tv":7857.76,"id":12343905}]}]}
{"op":"mcm","clk":"4231955344","pt":1631550049541,"mc":[{"id":"1.187560634","rc":[{"batb":[[0,4,2.79],[1,3.85,3.37],[2,3.55,23.4]],"batl":[[0,5.2,2.03],[1,5.6,2.01],[2,6.4,2]],"ltp":4.7,"tv":4465.23,"id":9629296},{"batb":[[0,1.24,94.52],[1,1.23,99.72],[2,1.22,355.61]],"batl":[[0,1.33,64.5],[1,1.35,68.9],[2,1.36,196.98]],"ltp":1.27,"tv":7857.76,"id":12343905}]}]}
{"op":"mcm","clk":"4231955377","pt":1631550049858,"mc":[{"id":"1.187560634","rc":[{"batb":[[0,3.85,3.37],[1,3.55,23.4],[2,1.01,105.79]],"batl":[[0,5.6,2.01],[1,6.4,2],[2,7.8,2]],"ltp":4.7,"tv":4465.23,"id":9629296},{"batb":[[0,1.23,99.72],[1,1.22,355.61],[2,1.2,172.46]],"batl":[[0,1.35,68.9],[1,1.36,196.98],[2,1.37,126.76]],"ltp":1.27,"tv":7857.76,"id":12343905}]}]}
{"op":"mcm","clk":"4231955708","pt":1631550053430,"mc":[{"id":"1.187560634","rc":[{"batl":[[1,990,0.01],[2,7.8,0]],"ltp":4.7,"tv":4465.23,"id":9629296},{"batl":[[0,1.9,1.39],[1,3,5.2],[2,8.8,7.22]],"ltp":1.27,"tv":7857.76,"id":12343905}]}]}
{"op":"mcm","clk":"4231955977","pt":1631550056463,"mc":[{"id":"1.187560634","rc":[{"batb":[[0,4.8,25],[1,3.85,3.37],[2,3.55,23.4]],"batl":[[1,5.7,50.44],[2,990,0.01]],"ltp":4.7,"tv":4465.23,"id":9629296},{"batb":[[2,1.21,48.84]],"batl":[[0,1.25,151.3],[1,1.26,266.96],[2,1.27,35.71]],"ltp":1.27,"tv":7857.76,"id":12343905}]}]}
{"op":"mcm","clk":"4231956052","pt":1631550057348,"mc":[{"id":"1.187560634","rc":[{"batb":[[1,4.4,26.84],[2,4,33.55]],"batl":[[0,5.5,5.46],[1,5.6,4.73],[2,5.7,53.16]],"ltp":4.7,"tv":4465.23,"id":9629296}]}]}
{"op":"mcm","clk":"4231956204","pt":1631550059286,"mc":[{"id":"1.187560634","rc":[{"batl":[[0,5.3,7.73],[1,5.5,5.46],[2,5.6,4.73]],"ltp":4.7,"tv":4465.23,"id":9629296},{"batl":[[0,1.25,158.81]],"ltp":1.27,"tv":7857.76,"id":12343905}]}]}
{"op":"mcm","clk":"4231957776","pt":1631550077272,"mc":[{"id":"1.187560634","rc":[{"trd":[[1.25,135]],"batb":[[0,1.23,109.27]],"batl":[[0,1.25,158.71]],"ltp":1.25,"tv":7857.96,"id":12343905}],"tv":12323.2}]}
{"op":"mcm","clk":"4231958588","pt":1631550086220,"mc":[{"id":"1.187560634","rc":[{"trd":[[1.25,137]],"batl":[[0,1.25,157.71]],"ltp":1.25,"tv":7859.96,"id":12343905}],"tv":12325.2}]}
{"op":"mcm","clk":"4231959120","pt":1631550093213,"mc":[{"id":"1.187560634","rc":[{"trd":[[5.3,10]],"batl":[[0,5.3,2.73]],"ltp":5.3,"tv":4475.23,"id":9629296}],"tv":12335.2}]}
{"op":"mcm","clk":"4231960039","pt":1631550103329,"mc":[{"id":"1.187560634","rc":[{"batl":[[0,5.5,5.46],[1,5.6,4.73],[2,5.7,53.16]],"ltp":5.3,"tv":4475.23,"id":9629296},{"batl":[[0,1.25,150.2]],"ltp":1.25,"tv":7859.96,"id":12343905}]}]}
{"op":"mcm","clk":"4231960290","pt":1631550106306,"mc":[{"id":"1.187560634","rc":[{"batb":[[0,5.1,4.94],[1,4.8,25],[2,4.4,26.84]],"ltp":5.3,"tv":4475.23,"id":9629296},{"batb":[[0,1.23,128.65]],"ltp":1.25,"tv":7859.96,"id":12343905}]}]}
{"op":"mcm","clk":"4231963314","pt":1631550142050,"mc":[{"id":"1.187560634","rc":[{"trd":[[1.25,140.78]],"batl":[[0,1.25,148.31]],"ltp":1.25,"tv":7863.74,"id":12343905}],"tv":12338.98}]}
{"op":"mcm","clk":"4231963434","pt":1631550143355,"mc":[{"id":"1.187560634","rc":[{"batb":[[2,1.2,172.46]],"ltp":1.25,"tv":7863.74,"id":12343905}]}]}
{"op":"mcm","clk":"4231963740","pt":1631550146650,"mc":[{"id":"1.187560634","rc":[{"batb":[[2,4.5,2.58]],"ltp":5.3,"tv":4475.23,"id":9629296}]}]}
{"op":"mcm","clk":"4231964440","pt":1631550155373,"mc":[{"id":"1.187560634","rc":[{"batb":[[0,4.3,2.48],[1,4,33.55],[2,1.01,105.79]],"batl":[[0,6.4,2],[1,7,2],[2,990,0.01]],"ltp":5.3,"tv":4475.23,"id":9629296},{"batb":[[0,1.23,9.55],[1,1.19,125.71],[2,1.17,160.97]],"batl":[[0,1.3,83.75],[1,3,5.2],[2,8.8,7.22]],"ltp":1.25,"tv":7863.74,"id":12343905}]}]}
{"op":"mcm","clk":"4231964461","pt":1631550155683,"mc":[{"id":"1.187560634","rc":[{"batl":[[0,7,2],[1,990,0.01],[2,990,0]],"ltp":5.3,"tv":4475.23,"id":9629296},{"batb":[[1,1.17,160.97],[2,1.16,219.6]],"ltp":1.25,"tv":7863.74,"id":12343905}]}]}
{"op":"mcm","clk":"4231964682","pt":1631550158605,"mc":[{"id":"1.187560634","rc":[{"batb":[[0,4.5,2.64],[1,4.3,2.48],[2,4,33.55]],"ltp":5.3,"tv":4475.23,"id":9629296},{"batl":[[0,1.28,99.09],[1,1.3,83.75],[2,3,5.2]],"ltp":1.25,"tv":7863.74,"id":12343905}]}]}
{"op":"mcm","clk":"4231964736","pt":1631550159073,"mc":[{"id":"1.187560634","rc":[{"batb":[[0,4.3,2.48],[1,4,33.55],[2,1.01,105.79]],"ltp":5.3,"tv":4475.23,"id":9629296},{"batl":[[0,1.3,83.75],[1,3,5.2],[2,8.8,7.22]],"ltp":1.25,"tv":7863.74,"id":12343905}]}]}
{"op":"mcm","clk":"4231964857","pt":1631550160579,"mc":[{"id":"1.187560634","rc":[{"batl":[[0,5.4,38.54],[1,7,2],[2,990,0.01]],"ltp":5.3,"tv":4475.23,"id":9629296},{"batb":[[1,1.22,164.44],[2,1.21,261.8]],"batl":[[0,1.24,150.71],[1,1.25,246.9],[2,1.3,83.75]],"ltp":1.25,"tv":7863.74,"id":12343905}]}]}
{"op":"mcm","clk":"4231964882","pt":1631550160892,"mc":[{"id":"1.187560634","rc":[{"batl":[[0,7,2],[1,990,0.01],[2,990,0]],"ltp":5.3,"tv":4475.23,"id":9629296},{"batb":[[1,1.22,122.1]],"batl":[[1,1.25,204.8]],"ltp":1.25,"tv":7863.74,"id":12343905}]}]}
{"op":"mcm","clk":"4231964991","pt":1631550162295,"mc":[{"id":"1.187560634","rc":[{"batb":[[0,4.5,2.58],[1,4.3,2.48],[2,4,33.55]],"batl":[[0,6.4,2],[1,7,2],[2,990,0.01]],"ltp":5.3,"tv":4475.23,"id":9629296},{"batl":[[2,1.28,85.84]],"ltp":1.25,"tv":7863.74,"id":12343905}]}]}
{"op":"mcm","clk":"4231965190","pt":1631550164584,"mc":[{"id":"1.187560634","rc":[{"batb":[[1,1.19,145.71],[2,1.17,160.97]],"batl":[[0,1.28,85.84],[1,1.3,83.75],[2,3,5.2]],"ltp":1.25,"tv":7863.74,"id":12343905}]}]}
{"op":"mcm","clk":"4231965213","pt":1631550164894,"mc":[{"id":"1.187560634","rc":[{"batb":[[0,4.3,2.48],[1,4,33.55],[2,1.01,105.79]],"batl":[[0,7,2],[1,990,0.01],[2,990,0]],"ltp":5.3,"tv":4475.23,"id":9629296},{"batb":[[1,1.17,160.97],[2,1.16,219.6]],"batl":[[0,1.3,83.75],[1,3,5.2],[2,8.8,7.22]],"ltp":1.25,"tv":7863.74,"id":12343905}]}]}
{"op":"mcm","clk":"4231965459","pt":1631550167503,"mc":[{"id":"1.187560634","rc":[{"batb":[[1,1.18,272.29],[2,1.17,469.15]],"batl":[[0,1.29,213.33],[1,1.3,247.26],[2,3,5.2]],"ltp":1.25,"tv":7863.74,"id":12343905}]}]}
{"op":"mcm","clk":"4231965608","pt":1631550169695,"mc":[{"id":"1.187560634","rc":[{"batb":[[0,1.18,272.29],[1,1.17,469.15],[2,1.16,219.6]],"ltp":1.25,"tv":7863.74,"id":12343905}]}]}
{"op":"mcm","clk":"4231965917","pt":1631550173420,"mc":[{"id":"1.187560634","rc":[{"batb":[[1,1.01,105.79],[2,1.01,0]],"ltp":5.3,"tv":4475.23,"id":9629296},{"batb":[[0,1.17,160.97],[1,1.1,2],[2,1.01,105.79]],"ltp":1.25,"tv":7863.74,"id":12343905}]}]}
{"op":"mcm","clk":"4231966067","pt":1631550175195,"mc":[{"id":"1.187560634","rc":[{"batb":[[0,4.5,2.58],[1,4.3,2.48],[2,1.01,105.79]],"batl":[[0,6.4,2],[1,7,2],[2,990,0.01]],"ltp":5.3,"tv":4475.23,"id":9629296},{"batb":[[0,1.19,119.71],[1,1.17,160.97],[2,1.1,2]],"batl":[[0,1.28,77.84],[1,1.29,213.33],[2,1.3,247.26]],"ltp":1.25,"tv":7863.74,"id":12343905}]}]}
{"op":"mcm","clk":"4231966195","pt":1631550176603,"mc":[{"id":"1.187560634","rc":[{"batb":[[0,4.5,67.4],[1,4.3,34.12],[2,4.2,30.7]],"batl":[[0,4.9,2],[1,5,27.2],[2,5.1,26.4]],"ltp":5.3,"tv":4475.23,"id":9629296},{"batb":[[0,1.26,491.9],[1,1.25,213.91],[2,1.23,48.04]],"batl":[[0,1.28,29.82]],"ltp":1.25,"tv":7863.74,"id":12343905}]}]}
{"op":"mcm","clk":"4231966713","pt":1631550182700,"mc":[{"id":"1.187560634","rc":[{"batb":[[2,4.2,33.22]],"ltp":5.3,"tv":4475.23,"id":9629296},{"batb":[[2,1.24,108.02]],"ltp":1.25,"tv":7863.74,"id":12343905}]}]}
{"op":"mcm","clk":"4231967089","pt":1631550188113,"mc":[{"id":"1.187560634","rc":[{"batb":[[0,1.26,195.87]],"ltp":1.25,"tv":7863.74,"id":12343905}]}]}
{"op":"mcm","clk":"4231967341","pt":1631550191444,"mc":[{"id":"1.187560634","rc":[{"batb":[[0,4.2,2.52],[1,1.01,105.79],[2,4.2,0]],"batl":[[0,5.4,2.04],[1,990,0.01],[2,5.1,0]],"ltp":5.3,"tv":4475.23,"id":9629296},{"batb":[[0,1.23,103.63],[1,1.1,2],[2,1.01,105.79]],"batl":[[0,1.31,88.5],[1,3,5.2],[2,8.8,7.22]],"ltp":1.25,"tv":7863.74,"id":12343905}]}]}
{"op":"mcm","clk":"4231967606","pt":1631550194549,"mc":[{"id":"1.187560634","rc":[{"batb":[[0,4.3,2.48],[1,4.2,2.52],[2,1.01,105.79]],"batl":[[0,5.2,2.03],[1,5.4,2.04],[2,990,0.01]],"ltp":5.3,"tv":4475.23,"id":9629296},{"batb":[[0,1.24,119.77],[1,1.23,103.63],[2,1.22,126.74]],"batl":[[0,1.3,82.75],[1,1.31,88.5],[2,1.32,158.41]],"ltp":1.25,"tv":7863.74,"id":12343905}]}]}
{"op":"mcm","clk":"4231967633","pt":1631550194819,"mc":[{"id":"1.187560634","rc":[{"batb":[[0,4.2,2.52],[1,1.01,105.79],[2,1.01,0]],"batl":[[0,5.4,2.04],[1,990,0.01],[2,990,0]],"ltp":5.3,"tv":4475.23,"id":9629296},{"batb":[[0,1.23,103.63],[1,1.22,126.74],[2,1.21,261.95]],"batl":[[0,1.31,88.5],[1,1.32,158.41],[2,1.33,146.57]],"ltp":1.25,"tv":7863.74,"id":12343905}]}]}
{"op":"mcm","clk":"4231967742","pt":1631550195963,"mc":[{"id":"1.187560634","rc":[{"batb":[[1,1.1,2],[2,1.01,105.79]],"ltp":1.25,"tv":7863.74,"id":12343905}]}]}
{"op":"mcm","clk":"4231967981","pt":1631550198622,"mc":[{"id":"1.187560634","rc":[{"batb":[[0,4.3,5.39],[1,4.2,2.52],[2,4,68]],"batl":[[0,4.5,5.76],[1,4.7,43.02],[2,5.4,2.04]],"ltp":5.3,"tv":4475.23,"id":9629296},{"batb":[[0,1.29,2452.61],[1,1.28,212.5],[2,1.27,206.24]],"batl":[[0,1.31,268.14]],"ltp":1.25,"tv":7863.74,"id":12343905}]}]}
{"op":"mcm","clk":"4231968039","pt":1631550199246,"mc":[{"id":"1.187560634","rc":[{"batb":[[2,4,34]],"batl":[[0,4.5,7.76]],"ltp":5.3,"tv":4475.23,"id":9629296},{"batb":[[0,1.29,370.41],[1,1.28,292.67],[2,1.27,103.12]],"ltp":1.25,"tv":7863.74,"id":12343905}]}]}
{"op":"mcm","clk":"4231968385","pt":1631550203525,"mc":[{"id":"1.187560634","rc":[{"batl":[[1,1.32,385.12]],"ltp":1.25,"tv":7863.74,"id":12343905}]}]}
{"op":"mcm","clk":"4231968403","pt":1631550203732,"mc":[{"id":"1.187560634","rc":[{"batl":[[1,1.32,158.41]],"ltp":1.25,"tv":7863.74,"id":12343905}]}]}
{"op":"mcm","clk":"4231968527","pt":1631550205245,"mc":[{"id":"1.187560634","rc":[{"batb":[[2,4.1,2.64]],"batl":[[2,4.8,2.32]],"ltp":5.3,"tv":4475.23,"id":9629296},{"batb":[[2,1.27,197.99]],"batl":[[1,1.32,232.52]],"ltp":1.25,"tv":7863.74,"id":12343905}]}]}
{"op":"mcm","clk":"4231968929","pt":1631550210649,"mc":[{"id":"1.187560634","rc":[{"trd":[[1.29,458.56]],"batb":[[0,1.29,172.18]],"ltp":1.29,"tv":7865.74,"id":12343905}],"tv":12340.98}]}
{"op":"mcm","clk":"4231969062","pt":1631550212626,"mc":[{"id":"1.187560634","rc":[{"batb":[[0,1.01,105.79],[1,4.2,0],[2,4.1,0]],"batl":[[0,4.9,2.15],[1,990,0.01],[2,4.8,0]],"ltp":5.3,"tv":4475.23,"id":9629296},{"batb":[[0,1.3,3.36],[1,1.26,102.98],[2,1.1,2]],"batl":[[0,1.32,74.11],[1,3,5.2],[2,8.8,7.22]],"ltp":1.29,"tv":7865.74,"id":12343905}]}]}
{"op":"mcm","clk":"4231969288","pt":1631550215544,"mc":[{"id":"1.187560634","rc":[{"batb":[[0,4.1,3.04],[1,1.01,105.79]],"batl":[[0,4.8,2.02],[1,4.9,2.15],[2,990,0.01]],"ltp":5.3,"tv":4475.23,"id":9629296},{"batb":[[1,1.27,98.87],[2,1.26,102.98]],"ltp":1.29,"tv":7865.74,"id":12343905}]}]}
{"op":"mcm","clk":"4231969315","pt":1631550215854,"mc":[{"id":"1.187560634","rc":[{"batl":[[0,4.9,2.15],[1,990,0.01],[2,990,0]],"ltp":5.3,"tv":4475.23,"id":9629296},{"batb":[[1,1.26,102.98],[2,1.1,2]],"ltp":1.29,"tv":7865.74,"id":12343905}]}]}
{"op":"mcm","clk":"4231969505","pt":1631550218366,"mc":[{"id":"1.187560634","rc":[{"trd":[[1.3,102.01]],"batb":[[0,1.28,215.96],[1,1.27,196.05],[2,1.26,102.98]],"batl":[[0,1.31,123.66],[1,1.32,226.91],[2,3,5.2]],"ltp":1.3,"tv":7872.46,"id":12343905}],"tv":12347.7}]}
{"op":"mcm","clk":"4231969579","pt":1631550219090,"mc":[{"id":"1.187560634","rc":[{"batl":[[0,4.8,2.02],[1,4.9,2.15],[2,990,0.01]],"ltp":5.3,"tv":4475.23,"id":9629296},{"batb":[[1,1.27,277.92]],"ltp":1.3,"tv":7872.46,"id":12343905}]}]}
{"op":"mcm","clk":"4231969864","pt":1631550222571,"mc":[{"id":"1.187560634","rc":[{"batl":[[0,4.9,2.15],[1,990,0.01],[2,990,0]],"ltp":5.3,"tv":4475.23,"id":9629296},{"batb":[[0,1.26,102.98],[1,1.1,2],[2,1.01,105.79]],"batl":[[0,1.32,74.11],[1,3,5.2],[2,8.8,7.22]],"ltp":1.3,"tv":7872.46,"id":12343905}]}]}
{"op":"mcm","clk":"4231970092","pt":1631550225597,"mc":[{"id":"1.187560634","rc":[{"batl":[[0,4.8,2.32],[1,4.9,2.15],[2,990,0.01]],"ltp":5.3,"tv":4475.23,"id":9629296},{"batb":[[0,1.27,106.87],[1,1.26,102.98],[2,1.1,2]],"batl":[[1,1.35,205.7],[2,1.36,130.99]],"ltp":1.3,"tv":7872.46,"id":12343905}]}]}
{"op":"mcm","clk":"4231970156","pt":1631550226270,"mc":[{"id":"1.187560634","rc":[{"batl":[[0,4.9,2.15],[1,990,0.01],[2,990,0]],"ltp":5.3,"tv":4475.23,"id":9629296},{"batb":[[0,1.26,102.98],[1,1.1,2],[2,1.01,105.79]],"ltp":1.3,"tv":7872.46,"id":12343905}]}]}
{"op":"mcm","clk":"4231970306","pt":1631550228195,"mc":[{"id":"1.187560634","rc":[{"batb":[[0,4.1,7.64]],"batl":[[0,4.3,7.77],[1,4.4,2],[2,4.9,2.15]],"ltp":5.3,"tv":4475.23,"id":9629296},{"batb":[[0,1.31,323.03],[1,1.3,286.32],[2,1.29,256.99]],"batl":[[1,1.33,166.91],[2,1.35,205.7]],"ltp":1.3,"tv":7872.46,"id":12343905}]}]}
{"op":"mcm","clk":"4231970792","pt":1631550234493,"mc":[{"id":"1.187560634","rc":[{"batb":[[1,4,2.68],[2,3.9,3.26]],"batl":[[2,4.5,2.35]],"ltp":5.3,"tv":4475.23,"id":9629296},{"batb":[[2,1.29,334.8]],"batl":[[1,1.33,232.41],[2,1.34,72.25]],"ltp":1.3,"tv":7872.46,"id":12343905}]}]}
{"op":"mcm","clk":"4231971029","pt":1631550237507,"mc":[{"id":"1.187560634","rc":[{"batb":[[0,3.9,3.26],[1,3.6,22.4],[2,1.01,105.79]],"batl":[[0,4.5,2.35],[1,990,0.01],[2,4.5,0]],"ltp":5.3,"tv":4475.23,"id":9629296},{"batb":[[0,1.29,77.81],[1,1.24,144.36],[2,1.1,2]],"batl":[[0,1.34,72.25],[1,1.36,100.58],[2,1.66,2.88]],"ltp":1.3,"tv":7872.46,"id":12343905}]}]}
{"op":"mcm","clk":"4231971253","pt":1631550240416,"mc":[{"id":"1.187560634","rc":[{"batb":[[0,4,2.68],[1,3.9,3.26],[2,3.6,22.4]],"batl":[[0,4.4,2.04],[1,4.5,2.35],[2,990,0.01]],"ltp":5.3,"tv":4475.23,"id":9629296},{"batb":[[0,1.3,92.68],[1,1.29,225.77],[2,1.28,186.2]],"batl":[[0,1.33,80.5],[1,1.34,72.25],[2,1.36,100.58]],"ltp":1.3,"tv":7872.46,"id":12343905}]}]}
{"op":"mcm","clk":"4231971430","pt":1631550242609,"mc":[{"id":"1.187560634","rc":[{"batb":[[0,3.9,3.26],[1,3.6,22.4],[2,1.01,105.79]],"batl":[[0,4.5,2.35],[1,990,0.01],[2,990,0]],"ltp":5.3,"tv":4475.23,"id":9629296},{"batb":[[0,1.29,77.81],[1,1.24,144.36],[2,1.1,2]],"batl":[[0,1.34,72.25],[1,1.36,100.58],[2,1.37,128.07]],"ltp":1.3,"tv":7872.46,"id":12343905}]}]}
{"op":"mcm","clk":"4231971652","pt":1631550245358,"mc":[{"id":"1.187560634","rc":[{"batl":[[0,4.2,7.14],[1,4.3,96.36],[2,4.4,3.58]],"ltp":5.3,"tv":4475.23,"id":9629296},{"batb":[[0,1.33,153.45],[1,1.32,173.72],[2,1.31,13.08]],"batl":[[0,1.34,232.65]],"ltp":1.3,"tv":7872.46,"id":12343905}]}]}
{"op":"mcm","clk":"4231971755","pt":1631550246563,"mc":[{"id":"1.187560634","rc":[{"batb":[[1,3.8,7.9],[2,3.75,3.94]],"ltp":5.3,"tv":4475.23,"id":9629296}]}]}
{"op":"mcm","clk":"4231972574","pt":1631550256654,"mc":[{"id":"1.187560634","rc":[{"trd":[[1.32,34.32],[1.33,306.9]],"batb":[[0,1.32,156.56],[1,1.31,13.08],[2,1.29,123.62]],"ltp":1.32,"tv":8213.68,"id":12343905}],"tv":12688.92}]}
{"op":"mcm","clk":"4231972886","pt":1631550260461,"mc":[{"id":"1.187560634","rc":[{"batb":[[0,1.32,226.43],[1,1.31,180.15]],"batl":[[1,1.36,184.46]],"ltp":1.32,"tv":8213.68,"id":12343905}]}]}
{"op":"mcm","clk":"4231973480","pt":1631550266890,"mc":[{"id":"1.187560634","rc":[{"batl":[[0,1.34,210.52]],"ltp":1.32,"tv":8213.68,"id":12343905}]}]}
{"op":"mcm","clk":"4231973738","pt":1631550269780,"mc":[{"id":"1.187560634","rc":[{"batl":[[0,4.2,11.93]],"ltp":5.3,"tv":4475.23,"id":9629296},{"batl":[[0,1.33,19.34],[1,1.34,210.52],[2,1.36,184.46]],"ltp":1.32,"tv":8213.68,"id":12343905}]}]}
{"op":"mcm","clk":"4231974454","pt":1631550277479,"mc":[{"id":"1.187560634","rc":[{"trd":[[1.32,38.32]],"batb":[[0,1.32,224.43]],"ltp":1.32,"tv":8217.68,"id":12343905}],"tv":12692.92}]}
{"op":"mcm","clk":"4231974892","pt":1631550282609,"mc":[{"id":"1.187560634","rc":[{"batb":[[0,1.31,13.08],[1,1.29,77.81],[2,1.28,210.87]],"batl":[[2,1.39,71.5]],"ltp":1.32,"tv":8217.68,"id":12343905}]}]}
{"op":"mcm","clk":"4231975082","pt":1631550284596,"mc":[{"id":"1.187560634","rc":[{"batb":[[0,3.6,22.4],[1,3.2,30.7],[2,1.01,105.79]],"batl":[[0,4.9,2.45],[1,990,0.01],[2,4.4,0]],"ltp":5.3,"tv":4475.23,"id":9629296},{"batb":[[0,1.28,121.21],[1,1.26,86.98],[2,1.25,139.58]],"batl":[[0,1.66,2.88],[1,3,5.2],[2,8.8,7.22]],"ltp":1.32,"tv":8217.68,"id":12343905}]}]}
{"op":"mcm","clk":"4231975154","pt":1631550285380,"mc":[{"id":"1.187560634","rc":[{"batb":[[0,3.2,30.45],[1,1.01,105.79],[2,1.01,0]],"ltp":5.3,"tv":4475.23,"id":9629296},{"batb":[[0,1.29,87.15],[1,1.28,186.69],[2,1.26,86.98]],"batl":[[0,1.43,84.52],[1,1.44,103.93],[2,1.66,2.88]],"ltp":1.32,"tv":8217.68,"id":12343905}]}]}
{"op":"mcm","clk":"4231975351","pt":1631550287676,"mc":[{"id":"1.187560634","rc":[{"batb":[[0,3.35,3.87],[1,3.2,30.45],[2,1.01,105.79]],"ltp":5.3,"tv":4475.23,"id":9629296},{"batb":[[0,1.26,86.98],[1,1.25,139.58],[2,1.1,2]],"batl":[[0,1.42,60.25],[1,1.66,2.88],[2,3,5.2]],"ltp":1.32,"tv":8217.68,"id":12343905}]}]}
{"op":"mcm","clk":"4231975395","pt":1631550288299,"mc":[{"id":"1.187560634","rc":[{"batb":[[0,3.4,3.26],[1,3.35,3.87],[2,3.2,30.45]],"ltp":5.3,"tv":4475.23,"id":9629296},{"batl":[[0,1.41,57.5],[1,1.42,60.25],[2,1.66,2.88]],"ltp":1.32,"tv":8217.68,"id":12343905}]}]}
{"op":"mcm","clk":"4231975504","pt":1631550289602,"mc":[{"id":"1.187560634","rc":[{"batb":[[0,1.34,122.99],[1,1.33,152.99],[2,1.26,86.98]],"batl":[[0,1.37,119.49],[1,1.38,124.76],[2,1.41,57.5]],"ltp":1.32,"tv":8217.68,"id":12343905}]}]}
{"op":"mcm","clk":"4231975559","pt":1631550290178,"mc":[{"id":"1.187560634","rc":[{"trd":[[1.34,114.2]],"batb":[[0,1.34,79.24]],"ltp":1.34,"tv":8305.18,"id":12343905}],"tv":12780.42}]}
{"op":"mcm","clk":"4231975665","pt":1631550291381,"mc":[{"id":"1.187560634","rc":[{"batb":[[0,3.55,3.79],[1,3.4,3.26],[2,3.35,3.87]],"batl":[[0,4.6,2.46],[1,4.9,2.45],[2,990,0.01]],"ltp":5.3,"tv":4475.23,"id":9629296},{"batb":[[2,1.28,94.16]],"batl":[[2,1.39,54.5]],"ltp":1.34,"tv":8305.18,"id":12343905}]}]}
{"op":"mcm","clk":"4231975836","pt":1631550293203,"mc":[{"id":"1.187560634","rc":[{"batb":[[0,1.34,98.82]],"batl":[[0,1.37,143.16]],"ltp":1.34,"tv":8305.18,"id":12343905}]}]}
{"op":"mcm","clk":"4231975998","pt":1631550295398,"mc":[{"id":"1.187560634","rc":[{"trd":[[1.34,134]],"batb":[[0,1.34,88.92]],"ltp":1.34,"tv":8324.98,"id":12343905}],"tv":12800.22}]}
{"op":"mcm","clk":"4231976095","pt":1631550296601,"mc":[{"id":"1.187560634","rc":[{"batb":[[0,1.28,94.16],[1,1.26,86.98],[2,1.25,139.58]],"batl":[[0,1.39,54.5],[1,1.41,57.5],[2,1.42,60.25]],"ltp":1.34,"tv":8324.98,"id":12343905}]}]}
{"op":"mcm","clk":"4231976140","pt":1631550297222,"mc":[{"id":"1.187560634","rc":[{"batb":[[0,3.4,3.26],[1,3.35,3.87],[2,3.2,30.45]],"batl":[[0,4.9,2.45],[1,990,0.01],[2,990,0]],"ltp":5.3,"tv":4475.23,"id":9629296},{"batb":[[0,1.26,86.98],[1,1.25,139.58],[2,1.1,2]],"batl":[[0,1.41,57.5],[1,1.42,60.25],[2,1.66,2.88]],"ltp":1.34,"tv":8324.98,"id":12343905}]}]}
{"op":"mcm","clk":"4231976325","pt":1631550299508,"mc":[{"id":"1.187560634","rc":[{"batb":[[0,1.32,15],[1,1.28,243.48],[2,1.27,199.01]],"batl":[[2,1.43,112.4]],"ltp":1.34,"tv":8324.98,"id":12343905}]}]}
{"op":"mcm","clk":"4231976407","pt":1631550300394,"mc":[{"id":"1.187560634","rc":[{"batl":[[0,4.6,2.06],[1,4.9,2.45],[2,990,0.01]],"ltp":5.3,"tv":4475.23,"id":9629296},{"batb":[[1,1.28,337.89]],"ltp":1.34,"tv":8324.98,"id":12343905}]}]}
{"op":"mcm","clk":"4231976692","pt":1631550303599,"mc":[{"id":"1.187560634","rc":[{"batb":[[0,3.55,3.39],[1,3.4,3.26],[2,3.35,3.87]],"ltp":5.3,"tv":4475.23,"id":9629296},{"batl":[[0,1.39,70.5],[1,1.41,57.5],[2,1.42,60.25]],"ltp":1.34,"tv":8324.98,"id":12343905}]}]}
{"op":"mcm","clk":"4231976710","pt":1631550303818,"mc":[{"id":"1.187560634","rc":[{"batb":[[0,3.4,3.26],[1,3.35,3.87],[2,3.2,30.45]],"ltp":5.3,"tv":4475.23,"id":9629296},{"batl":[[0,1.41,57.5],[1,1.42,60.25],[2,1.43,112.4]],"ltp":1.34,"tv":8324.98,"id":12343905}]}]}
{"op":"mcm","clk":"4231976923","pt":1631550306435,"mc":[{"id":"1.187560634","rc":[{"trd":[[1.32,45.11]],"batb":[[0,1.32,11.6]],"ltp":1.32,"tv":8331.77,"id":12343905}],"tv":12807.01}]}
{"op":"mcm","clk":"4231977036","pt":1631550307428,"mc":[{"id":"1.187560634","rc":[{"batb":[[0,3.55,3.59],[1,3.4,3.26],[2,3.35,3.87]],"ltp":5.3,"tv":4475.23,"id":9629296},{"batl":[[0,1.39,63.5],[1,1.41,57.5],[2,1.42,60.25]],"ltp":1.32,"tv":8331.77,"id":12343905}]}]}
{"op":"mcm","clk":"4231977063","pt":1631550307743,"mc":[{"id":"1.187560634","rc":[{"batb":[[0,3.4,3.26],[1,3.35,3.87],[2,3.2,30.45]],"ltp":5.3,"tv":4475.23,"id":9629296},{"batl":[[0,1.41,57.5],[1,1.42,60.25],[2,1.43,112.4]],"ltp":1.32,"tv":8331.77,"id":12343905}]}]}
{"op":"mcm","clk":"4231977396","pt":1631550310942,"mc":[{"id":"1.187560634","rc":[{"batb":[[0,3.55,3.79],[1,3.4,3.26],[2,3.35,3.87]],"ltp":5.3,"tv":4475.23,"id":9629296},{"batl":[[0,1.39,69.5],[1,1.41,57.5],[2,1.42,60.25]],"ltp":1.32,"tv":8331.77,"id":12343905}]}]}
{"op":"mcm","clk":"4231977540","pt":1631550312425,"mc":[{"id":"1.187560634","rc":[{"batb":[[0,3.4,3.26],[1,3.35,3.87],[2,3.2,30.45]],"ltp":5.3,"tv":4475.23,"id":9629296},{"batl":[[0,1.41,57.5],[1,1.42,60.25],[2,1.66,2.88]],"ltp":1.32,"tv":8331.77,"id":12343905}]}]}
{"op":"mcm","clk":"4231977842","pt":1631550315508,"mc":[{"id":"1.187560634","rc":[{"batb":[[0,4.4,6.23],[1,4.3,20.93],[2,4.2,10.46]],"batl":[[1,4.7,9.44],[2,4.8,58.69]],"ltp":5.3,"tv":4475.23,"id":9629296},{"trd":[[1.32,68.31]],"batb":[[0,1.28,337.89],[1,1.27,199.01],[2,1.26,133.88]],"batl":[[0,1.31,104.56],[1,1.32,155.13],[2,1.33,531.59]],"ltp":1.32,"tv":8354.97,"id":12343905}],"tv":12830.21}]}
{"op":"mcm","clk":"4231977941","pt":1631550316555,"mc":[{"id":"1.187560634","rc":[{"batb":[[1,4.3,6.98],[2,4.2,3.48]],"batl":[[2,4.8,64.93]],"ltp":5.3,"tv":4475.23,"id":9629296}]}]}
{"op":"mcm","clk":"4231978435","pt":1631550322435,"mc":[{"id":"1.187560634","rc":[{"batl":[[2,1.33,597.09]],"ltp":1.32,"tv":8354.97,"id":12343905}]}]}
{"op":"mcm","clk":"4231979358","pt":1631550332658,"mc":[{"id":"1.187560634","rc":[{"batb":[[2,1.26,86.98]],"ltp":1.32,"tv":8354.97,"id":12343905}]}]}
{"op":"mcm","clk":"4231979923","pt":1631550338538,"mc":[{"id":"1.187560634","rc":[{"batb":[[0,4,2.79],[1,3.95,35.9],[2,3.85,3.17]],"batl":[[1,4.9,2.45],[2,5,2.12]],"ltp":5.3,"tv":4475.23,"id":9629296},{"batl":[[2,1.33,65.5]],"ltp":1.32,"tv":8354.97,"id":12343905}]}]}
{"op":"mcm","clk":"4231979997","pt":1631550339267,"mc":[{"id":"1.187560634","rc":[{"batb":[[0,3.85,3.17],[1,3.5,23.82],[2,1.01,105.79]],"batl":[[0,5,2.12],[1,990,0.01],[2,5,0]],"ltp":5.3,"tv":4475.23,"id":9629296},{"batb":[[0,1.25,98.57],[1,1.22,160.88],[2,1.1,2]],"batl":[[0,1.35,77.5],[1,1.66,2.88],[2,3,5.2]],"ltp":1.32,"tv":8354.97,"id":12343905}]}]}
{"op":"mcm","clk":"4231980466","pt":1631550344248,"mc":[{"id":"1.187560634","rc":[{"batb":[[0,1.29,245.02],[1,1.28,190.38],[2,1.25,98.57]],"batl":[[0,1.32,84.15],[1,1.33,149.71],[2,1.35,77.5]],"ltp":1.32,"tv":8354.97,"id":12343905}]}]}
{"op":"mcm","clk":"4231980606","pt":1631550345656,"mc":[{"id":"1.187560634","rc":[{"batb":[[0,4,2.79],[1,3.85,3.17],[2,3.5,23.82]],"batl":[[0,4.9,2.25],[1,5,2.12],[2,990,0.01]],"ltp":5.3,"tv":4475.23,"id":9629296},{"batb":[[2,1.26,98.48]],"batl":[[1,1.33,221.21]],"ltp":1.32,"tv":8354.97,"id":12343905}]}]}
{"op":"mcm","clk":"4231980670","pt":1631550346288,"mc":[{"id":"1.187560634","rc":[{"batb":[[0,3.85,3.17],[1,3.5,23.82],[2,1.01,105.79]],"ltp":5.3,"tv":4475.23,"id":9629296},{"batl":[[1,1.33,149.71]],"ltp":1.32,"tv":8354.97,"id":12343905}]}]}
{"op":"mcm","clk":"4231980878","pt":1631550348595,"mc":[{"id":"1.187560634","rc":[{"batl":[[0,5,2.12],[1,990,0.01],[2,990,0]],"ltp":5.3,"tv":4475.23,"id":9629296},{"batb":[[0,1.25,98.57],[1,1.22,160.88],[2,1.1,2]],"batl":[[0,1.35,77.5],[1,1.66,2.88],[2,3,5.2]],"ltp":1.32,"tv":8354.97,"id":12343905}]}]}
{"op":"mcm","clk":"4231981129","pt":1631550351062,"mc":[{"id":"1.187560634","rc":[{"batb":[[0,1.25,387],[1,1.24,230.59],[2,1.22,160.88]],"batl":[[1,1.37,119.79],[2,1.38,125.15]],"ltp":1.32,"tv":8354.97,"id":12343905}]}]}
{"op":"mcm","clk":"4231981610","pt":1631550356370,"mc":[{"id":"1.187560634","rc":[{"batb":[[0,4,2.79],[1,3.85,3.17],[2,3.5,23.82]],"ltp":5.3,"tv":4475.23,"id":9629296},{"batl":[[0,1.33,79.5],[1,1.35,77.5],[2,1.66,2.88]],"ltp":1.32,"tv":8354.97,"id":12343905}]}]}
{"op":"mcm","clk":"4231981650","pt":1631550356685,"mc":[{"id":"1.187560634","rc":[{"batb":[[0,3.85,3.17],[1,3.5,23.82],[2,1.01,105.79]],"ltp":5.3,"tv":4475.23,"id":9629296},{"batl":[[0,1.35,77.5],[1,1.66,2.88],[2,3,5.2]],"ltp":1.32,"tv":8354.97,"id":12343905}]}]}
{"op":"mcm","clk":"4231981931","pt":1631550359565,"mc":[{"id":"1.187560634","rc":[{"batb":[[0,4.5,30.22],[1,4.4,29.34],[2,4.3,29.34]],"batl":[[0,5,7.71],[1,5.3,25.66],[2,5.4,24.9]],"ltp":5.3,"tv":4475.23,"id":9629296},{"batb":[[1,1.24,442.08],[2,1.23,48.04]],"batl":[[0,1.27,29.05],[1,1.28,455.92],[2,1.29,174.38]],"ltp":1.32,"tv":8354.97,"id":12343905}]}]}
{"op":"mcm","clk":"4231982472","pt":1631550365580,"mc":[{"id":"1.187560634","rc":[{"batb":[[1,4.4,31.95],[2,4.3,31.72]],"batl":[[1,5.2,2.08],[2,5.3,25.66]],"ltp":5.3,"tv":4475.23,"id":9629296},{"batb":[[1,1.24,552.85],[2,1.23,163.67]],"batl":[[2,1.29,250.88]],"ltp":1.32,"tv":8354.97,"id":12343905}]}]}
{"op":"mcm","clk":"4231982907","pt":1631550370788,"mc":[{"id":"1.187560634","rc":[{"batl":[[1,1.28,331]],"ltp":1.32,"tv":8354.97,"id":12343905}]}]}
{"op":"mcm","clk":"4231983338","pt":1631550376106,"mc":[{"id":"1.187560634","rc":[{"batb":[[2,1.23,115.63]],"ltp":1.32,"tv":8354.97,"id":12343905}]}]}
{"op":"mcm","clk":"4231983578","pt":1631550379191,"mc":[{"id":"1.187560634","rc":[{"trd":[[1.25,143.76]],"batb":[[0,1.25,385.51]],"ltp":1.25,"tv":8357.95,"id":12343905}],"tv":12833.18}]}
{"op":"mcm","clk":"4231983710","pt":1631550380599,"mc":[{"id":"1.187560634","rc":[{"batb":[[0,4.3,2.38],[1,3.85,38],[2,1.01,105.79]],"batl":[[0,5.4,2.04],[1,990,0.01],[2,5.3,0]],"ltp":5.3,"tv":4475.23,"id":9629296},{"batb":[[0,1.24,89.38],[1,1.23,115.63],[2,1.2,178.58]],"batl":[[0,1.3,86.35],[1,1.66,2.88],[2,3,5.2]],"ltp":1.25,"tv":8357.95,"id":12343905}]}]}
{"op":"mcm","clk":"4231983902","pt":1631550383001,"mc":[{"id":"1.187560634","rc":[{"batb":[[1,1.23,352.99]],"batl":[[1,1.32,141.05],[2,1.33,148.78]],"ltp":1.25,"tv":8357.95,"id":12343905}]}]}
{"op":"mcm","clk":"4231983985","pt":1631550383937,"mc":[{"id":"1.187560634","rc":[{"batl":[[0,1.3,86.43],[1,1.66,2.88],[2,3,5.2]],"ltp":1.25,"tv":8357.95,"id":12343905}]}]}
{"op":"mcm","clk":"4231984262","pt":1631550387342,"mc":[{"id":"1.187560634","rc":[{"batb":[[0,4.9,18.36],[1,4.8,9.18],[2,4.7,9.18]],"batl":[[0,5.3,6.04],[1,5.4,2.04],[2,5.5,58.86]],"ltp":5.3,"tv":4475.23,"id":9629296},{"batb":[[2,1.21,48.84]],"batl":[[0,1.25,11.78],[1,1.26,577.86],[2,1.27,189.61]],"ltp":1.25,"tv":8357.95,"id":12343905}]}]}
{"op":"mcm","clk":"4231984354","pt":1631550388234,"mc":[{"id":"1.187560634","rc":[{"batb":[[0,4.9,6.12],[1,4.8,3.06],[2,4.7,3.06]],"batl":[[2,5.5,64.32]],"ltp":5.3,"tv":4475.23,"id":9629296}]}]}
{"op":"mcm","clk":"4231984834","pt":1631550393522,"mc":[{"id":"1.187560634","rc":[{"batb":[[1,4.8,5.19],[2,4.7,5.08]],"batl":[[0,5.2,2.03],[1,5.3,6.04],[2,5.4,2.04]],"ltp":5.3,"tv":4475.23,"id":9629296},{"batb":[[0,1.24,187.9]],"batl":[[1,1.26,661.61],[2,1.27,282.11]],"ltp":1.25,"tv":8357.95,"id":12343905}]}]}
{"op":"mcm","clk":"4231984864","pt":1631550393840,"mc":[{"id":"1.187560634","rc":[{"batb":[[1,4.8,3.06]],"ltp":5.3,"tv":4475.23,"id":9629296},{"batl":[[1,1.26,577.86]],"ltp":1.25,"tv":8357.95,"id":12343905}]}]}
{"op":"mcm","clk":"4231985175","pt":1631550397727,"mc":[{"id":"1.187560634","rc":[{"batb":[[1,4.8,5.29]],"ltp":5.3,"tv":4475.23,"id":9629296},{"batl":[[1,1.26,670.61]],"ltp":1.25,"tv":8357.95,"id":12343905}]}]}
{"op":"mcm","clk":"4231985269","pt":1631550398867,"mc":[{"id":"1.187560634","rc":[{"batl":[[1,1.26,522.8]],"ltp":1.25,"tv":8357.95,"id":12343905}]}]}
{"op":"mcm","clk":"4231985388","pt":1631550400549,"mc":[{"id":"1.187560634","rc":[{"batb":[[0,4.8,2.23],[1,4.7,2.02],[2,4.5,25.5]],"batl":[[1,5.4,2.04],[2,990,0.01]],"ltp":5.3,"tv":4475.23,"id":9629296},{"batl":[[0,1.26,240.58],[1,1.27,282.11],[2,1.3,86.35]],"ltp":1.25,"tv":8357.95,"id":12343905}]}]}
{"op":"mcm","clk":"4231985438","pt":1631550401171,"mc":[{"id":"1.187560634","rc":[{"batb":[[0,4.7,2.02],[1,4.2,30.53],[2,1.01,105.79]],"batl":[[0,5.4,2.04],[1,990,0.01],[2,990,0]],"ltp":5.3,"tv":4475.23,"id":9629296},{"batb":[[0,1.23,115.63],[1,1.19,190.74],[2,1.1,2]],"batl":[[0,1.27,92.58],[1,1.66,2.88],[2,3,5.2]],"ltp":1.25,"tv":8357.95,"id":12343905}]}]}
{"op":"mcm","clk":"4231985705","pt":1631550404570,"mc":[{"id":"1.187560634","rc":[{"batb":[[1,1.22,303.35],[2,1.21,257.68]],"batl":[[1,1.28,92.71],[2,1.29,175.13]],"ltp":1.25,"tv":8357.95,"id":12343905}]}]}
{"op":"mcm","clk":"4231985760","pt":1631550405046,"mc":[{"id":"1.187560634","rc":[{"batb":[[1,1.19,190.74],[2,1.1,2]],"ltp":1.25,"tv":8357.95,"id":12343905}]}]}
{"op":"mcm","clk":"4231985998","pt":1631550407461,"mc":[{"id":"1.187560634","rc":[{"batl":[[0,5.2,2.03],[1,5.4,2.04],[2,990,0.01]],"ltp":5.3,"tv":4475.23,"id":9629296},{"batb":[[0,1.24,103.27],[1,1.23,115.63],[2,1.19,190.74]],"ltp":1.25,"tv":8357.95,"id":12343905}]}]}
{"op":"mcm","clk":"4231986095","pt":1631550408665,"mc":[{"id":"1.187560634","rc":[{"trd":[[5,0.02]],"batb":[[2,3.8,38.75]],"batl":[[0,5,7.88],[1,5.1,44.65],[2,5.2,2.94]],"ltp":5.0,"tv":4475.25,"id":9629296},{"trd":[[1.25,143.84],[1.26,717.97]],"batb":[[0,1.25,228.38],[1,1.23,163.67],[2,1.22,158.11]],"batl":[[0,1.27,120.47],[1,1.28,296.97]],"ltp":1.26,"tv":8539.53,"id":12343905}],"tv":13014.78}]}
{"op":"mcm","clk":"4231986128","pt":1631550409078,"mc":[{"id":"1.187560634","rc":[{"batb":[[1,4.5,6.66],[2,4.4,3.34]],"ltp":5.0,"tv":4475.25,"id":9629296}]}]}
{"op":"mcm","clk":"4231986304","pt":1631550411176,"mc":[{"id":"1.187560634","rc":[{"batb":[[0,1.25,291.08],[1,1.24,231.56],[2,1.23,163.67]],"batl":[[1,1.28,346.39]],"ltp":1.26,"tv":8539.53,"id":12343905}]}]}
{"op":"mcm","clk":"4231986516","pt":1631550414382,"mc":[{"id":"1.187560634","rc":[{"batb":[[1,4.5,9.24],[2,4.4,5.9]],"batl":[[2,5.2,5.07]],"ltp":5.0,"tv":4475.25,"id":9629296},{"batb":[[1,1.24,334.58],[2,1.23,173.21]],"batl":[[1,1.28,440.98],[2,1.29,268.63]],"ltp":1.26,"tv":8539.53,"id":12343905}]}]}
{"op":"mcm","clk":"4231987349","pt":1631550424669,"mc":[{"id":"1.187560634","rc":[{"batb":[[0,4.4,2.56],[1,3.8,38.75],[2,1.01,105.79]],"batl":[[0,5.4,2.04],[1,990,0.01],[2,5.2,0]],"ltp":5.0,"tv":4475.25,"id":9629296},{"batb":[[0,1.23,125.18],[1,1.2,175.06],[2,1.1,2]],"batl":[[0,1.29,93.5],[1,1.66,2.88],[2,3,5.2]],"ltp":1.26,"tv":8539.53,"id":12343905}]}]}
{"op":"mcm","clk":"4231987626","pt":1631550427667,"mc":[{"id":"1.187560634","rc":[{"batb":[[0,4.5,2.58],[1,4.4,2.56],[2,3.8,38.75]],"ltp":5.0,"tv":4475.25,"id":9629296},{"batb":[[0,1.23,446.26],[1,1.22,235.2],[2,1.2,175.06]],"batl":[[0,1.28,83.09],[1,1.29,93.5],[2,1.32,179.32]],"ltp":1.26,"tv":8539.53,"id":12343905}]}]}
