{"op":"mcm","clk":"4232373729","pt":1631518765810,"mc":[{"id":"1.187595437","marketDefinition":{"bspMarket":false,"turnInPlayEnabled":true,"persistenceEnabled":true,"marketBaseRate":5.0,"eventId":"30898003","eventTypeId":"2","numberOfWinners":1,"bettingType":"ODDS","marketType":"MATCH_ODDS","marketTime":"2021-09-13T13:30:00.000Z","suspendTime":"2021-09-13T13:30:00.000Z","bspReconciled":false,"complete":true,"inPlay":false,"crossMatching":false,"runnersVoidable":false,"numberOfActiveRunners":2,"betDelay":0,"status":"OPEN","runners":[{"status":"ACTIVE","sortPriority":1,"id":9168659,"name":"T Lukas"},{"status":"ACTIVE","sortPriority":2,"id":9628279,"name":"Y Cavalle-Reimers"}],"regulators":["MR_INT"],"countryCode":"GB","discountAllowed":false,"timezone":"GMT","openDate":"2021-09-13T13:30:00.000Z","version":4030167324,"name":"Match Odds","eventName":"T Lukas v Y Cavalle-reimers"},"rc":[{"batb":[[0,1.01,25]],"ltp":0.0,"tv":0.0,"id":9628279},{"batb":[[0,1.01,25]],"ltp":0.0,"tv":0.0,"id":9168659}]}]}
{"op":"mcm","clk":"4232373856","pt":1631518767640,"mc":[{"id":"1.187595437","marketDefinition":{"bspMarket":false,"turnInPlayEnabled":true,"persistenceEnabled":true,"marketBaseRate":5.0,"eventId":"30898003","eventTypeId":"2","numberOfWinners":1,"bettingType":"ODDS","marketType":"MATCH_ODDS","marketTime":"2021-09-13T13:30:00.000Z","suspendTime":"2021-09-13T13:30:00.000Z","bspReconciled":false,"complete":true,"inPlay":false,"crossMatching":false,"runnersVoidable":false,"numberOfActiveRunners":2,"betDelay":0,"status":"OPEN","runners":[{"status":"ACTIVE","sortPriority":1,"id":9168659,"name":"T Lukas"},{"status":"ACTIVE","sortPriority":2,"id":9628279,"name":"Y Cavalle-Reimers"}],"regulators":["MR_INT"],"countryCode":"GB","discountAllowed":true,"timezone":"GMT","openDate":"2021-09-13T13:30:00.000Z","version":4030167324,"name":"Match Odds","eventName":"T Lukas v Y Cavalle-reimers"}}]}
{"op":"mcm","clk":"4232396412","pt":1631519123599,"mc":[{"id":"1.187595437","rc":[{"batb":[[0,1.01,7]],"ltp":0.0,"tv":0.0,"id":9628279},{"batb":[[0,1.01,7]],"ltp":0.0,"tv":0.0,"id":9168659}]}]}
{"op":"mcm","clk":"4232506411","pt":1631520745080,"mc":[{"id":"1.187595437","rc":[{"batl":[[0,990,2.2]],"ltp":0.0,"tv":0.0,"id":9628279},{"batl":[[0,990,2.2]],"ltp":0.0,"tv":0.0,"id":9168659}]}]}
{"op":"mcm","clk":"4232602591","pt":1631522338033,"mc":[{"id":"1.187595437","rc":[{"batl":[[0,1.94,2.66],[1,990,2.2]],"ltp":0.0,"tv":0.0,"id":9628279}]}]}
{"op":"mcm","clk":"4232602797","pt":1631522342921,"mc":[{"id":"1.187595437","rc":[{"batb":[[0,1.06,42.59],[1,1.01,7]],"ltp":0.0,"tv":0.0,"id":9628279}]}]}
{"op":"mcm","clk":"4232615265","pt":1631522568579,"mc":[{"id":"1.187595437","rc":[{"batb":[[0,1.44,71.19],[1,1.06,42.59],[2,1.01,7]],"ltp":0.0,"tv":0.0,"id":9628279},{"batb":[[0,2.62,19.33],[1,1.01,7]],"ltp":0.0,"tv":0.0,"id":9168659}]}]}
{"op":"mcm","clk":"4232616079","pt":1631522582278,"mc":[{"id":"1.187595437","marketDefinition":{"bspMarket":false,"turnInPlayEnabled":true,"persistenceEnabled":true,"marketBaseRate":5.0,"eventId":"30898003","eventTypeId":"2","numberOfWinners":1,"bettingType":"ODDS","marketType":"MATCH_ODDS","marketTime":"2021-09-13T13:30:00.000Z","suspendTime":"2021-09-13T13:30:00.000Z","bspReconciled":false,"complete":true,"inPlay":false,"crossMatching":true,"runnersVoidable":false,"numberOfActiveRunners":2,"betDelay":0,"status":"OPEN","runners":[{"status":"ACTIVE","sortPriority":1,"id":9168659,"name":"T Lukas"},{"status":"ACTIVE","sortPriority":2,"id":9628279,"name":"Y Cavalle-Reimers"}],"regulators":["MR_INT"],"countryCode":"GB","discountAllowed":true,"timezone":"GMT","openDate":"2021-09-13T13:30:00.000Z","version":4030167324,"name":"Match Odds","eventName":"T Lukas v Y Cavalle-reimers"}}]}
{"op":"mcm","clk":"4232729657","pt":1631524665804,"mc":[{"id":"1.187595437","rc":[{"batb":[[1,1.06,42.62]],"batl":[[0,1.94,2.66]],"ltp":0.0,"tv":0.0,"id":9628279}]}]}
{"op":"mcm","clk":"4233253444","pt":1631532601493,"mc":[{"id":"1.187595437","rc":[{"batb":[[0,1.44,94.92],[1,1.06,42.53]],"batl":[[0,1.94,2.66]],"ltp":0.0,"tv":0.0,"id":9628279},{"batb":[[0,2.62,25.78]],"ltp":0.0,"tv":0.0,"id":9168659}]}]}
{"op":"mcm","clk":"4233284671","pt":1631532965674,"mc":[{"id":"1.187595437","rc":[{"batb":[[1,1.07,612.18],[2,1.06,42.53]],"ltp":0.0,"tv":0.0,"id":9628279},{"batb":[[1,1.05,874.55],[2,1.01,7]],"ltp":0.0,"tv":0.0,"id":9168659}]}]}
{"op":"mcm","clk":"4233548367","pt":1631535873958,"mc":[{"id":"1.187595437","rc":[{"batl":[[0,1.61,100],[1,1.94,2.66],[2,990,2.2]],"ltp":0.0,"tv":0.0,"id":9628279}]}]}
{"op":"mcm","clk":"4233574408","pt":1631536200530,"mc":[{"id":"1.187595437","rc":[{"batb":[[0,1.45,28.39],[1,1.44,94.92],[2,1.07,612.18]],"ltp":0.0,"tv":0.0,"id":9628279},{"batb":[[0,2.64,7.79],[1,2.62,25.78],[2,1.05,874.55]],"ltp":0.0,"tv":0.0,"id":9168659}]}]}
{"op":"mcm","clk":"4233621189","pt":1631536720724,"mc":[{"id":"1.187595437","rc":[{"batb":[[2,1.01,7]],"ltp":0.0,"tv":0.0,"id":9168659}]}]}
{"op":"mcm","clk":"4233621703","pt":1631536726633,"mc":[{"id":"1.187595437","rc":[{"batl":[[2,2.2,43.73]],"ltp":0.0,"tv":0.0,"id":9628279}]}]}
{"op":"mcm","clk":"4233871795","pt":1631539569425,"mc":[{"id":"1.187595437","rc":[{"trd":[[1.45,0.2]],"batb":[[0,1.45,28.28],[2,1.07,611.78]],"batl":[[1,1.94,2.66],[2,2.2,43.7]],"ltp":1.45,"tv":0.2,"id":9628279},{"batb":[[0,2.64,7.79]],"ltp":0.0,"tv":0.0,"id":9168659}],"tv":0.2}]}
{"op":"mcm","clk":"4233876917","pt":1631539615744,"mc":[{"id":"1.187595437","marketDefinition":{"bspMarket":false,"turnInPlayEnabled":true,"persistenceEnabled":true,"marketBaseRate":5.0,"eventId":"30898003","eventTypeId":"2","numberOfWinners":1,"bettingType":"ODDS","marketType":"MATCH_ODDS","marketTime":"2021-09-13T13:40:00.000Z","suspendTime":"2021-09-13T13:40:00.000Z","bspReconciled":false,"complete":true,"inPlay":false,"crossMatching":true,"runnersVoidable":false,"numberOfActiveRunners":2,"betDelay":0,"status":"OPEN","runners":[{"status":"ACTIVE","sortPriority":1,"id":9168659,"name":"T Lukas"},{"status":"ACTIVE","sortPriority":2,"id":9628279,"name":"Y Cavalle-Reimers"}],"regulators":["MR_INT"],"countryCode":"GB","discountAllowed":true,"timezone":"GMT","openDate":"2021-09-13T13:30:00.000Z","version":4030708191,"name":"Match Odds","eventName":"T Lukas v Y Cavalle-reimers"}}]}
{"op":"mcm","clk":"4233877144","pt":1631539617753,"mc":[{"id":"1.187595437","marketDefinition":{"bspMarket":false,"turnInPlayEnabled":true,"persistenceEnabled":true,"marketBaseRate":5.0,"eventId":"30898003","eventTypeId":"2","numberOfWinners":1,"bettingType":"ODDS","marketType":"MATCH_ODDS","marketTime":"2021-09-13T13:40:00.000Z","suspendTime":"2021-09-13T13:40:00.000Z","bspReconciled":false,"complete":true,"inPlay":false,"crossMatching":true,"runnersVoidable":false,"numberOfActiveRunners":2,"betDelay":0,"status":"OPEN","runners":[{"status":"ACTIVE","sortPriority":1,"id":9168659,"name":"T Lukas"},{"status":"ACTIVE","sortPriority":2,"id":9628279,"name":"Y Cavalle-Reimers"}],"regulators":["MR_INT"],"countryCode":"GB","discountAllowed":true,"timezone":"GMT","openDate":"2021-09-13T13:40:00.000Z","version":4030708191,"name":"Match Odds","eventName":"T Lukas v Y Cavalle-reimers"}}]}
{"op":"mcm","clk":"4233938597","pt":1631540229192,"mc":[{"id":"1.187595437","marketDefinition":{"bspMarket":false,"turnInPlayEnabled":true,"persistenceEnabled":true,"marketBaseRate":5.0,"eventId":"30898003","eventTypeId":"2","numberOfWinners":1,"bettingType":"ODDS","marketType":"MATCH_ODDS","marketTime":"2021-09-13T13:50:00.000Z","suspendTime":"2021-09-13T13:50:00.000Z","bspReconciled":false,"complete":true,"inPlay":false,"crossMatching":true,"runnersVoidable":false,"numberOfActiveRunners":2,"betDelay":0,"status":"OPEN","runners":[{"status":"ACTIVE","sortPriority":1,"id":9168659,"name":"T Lukas"},{"status":"ACTIVE","sortPriority":2,"id":9628279,"name":"Y Cavalle-Reimers"}],"regulators":["MR_INT"],"countryCode":"GB","discountAllowed":true,"timezone":"GMT","openDate":"2021-09-13T13:40:00.000Z","version":4030721076,"name":"Match Odds","eventName":"T Lukas v Y Cavalle-reimers"}}]}
{"op":"mcm","clk":"4233938886","pt":1631540232209,"mc":[{"id":"1.187595437","marketDefinition":{"bspMarket":false,"turnInPlayEnabled":true,"persistenceEnabled":true,"marketBaseRate":5.0,"eventId":"30898003","eventTypeId":"2","numberOfWinners":1,"bettingType":"ODDS","marketType":"MATCH_ODDS","marketTime":"2021-09-13T13:50:00.000Z","suspendTime":"2021-09-13T13:50:00.000Z","bspReconciled":false,"complete":true,"inPlay":false,"crossMatching":true,"runnersVoidable":false,"numberOfActiveRunners":2,"betDelay":0,"status":"OPEN","runners":[{"status":"ACTIVE","sortPriority":1,"id":9168659,"name":"T Lukas"},{"status":"ACTIVE","sortPriority":2,"id":9628279,"name":"Y Cavalle-Reimers"}],"regulators":["MR_INT"],"countryCode":"GB","discountAllowed":true,"timezone":"GMT","openDate":"2021-09-13T13:50:00.000Z","version":4030721076,"name":"Match Odds","eventName":"T Lukas v Y Cavalle-reimers"}}]}
{"op":"mcm","clk":"4233943887","pt":1631540290526,"mc":[{"id":"1.187595437","marketDefinition":{"bspMarket":false,"turnInPlayEnabled":true,"persistenceEnabled":true,"marketBaseRate":5.0,"eventId":"30898003","eventTypeId":"2","numberOfWinners":1,"bettingType":"ODDS","marketType":"MATCH_ODDS","marketTime":"2021-09-13T13:45:00.000Z","suspendTime":"2021-09-13T13:45:00.000Z","bspReconciled":false,"complete":true,"inPlay":false,"crossMatching":true,"runnersVoidable":false,"numberOfActiveRunners":2,"betDelay":0,"status":"OPEN","runners":[{"status":"ACTIVE","sortPriority":1,"id":9168659,"name":"T Lukas"},{"status":"ACTIVE","sortPriority":2,"id":9628279,"name":"Y Cavalle-Reimers"}],"regulators":["MR_INT"],"countryCode":"GB","discountAllowed":true,"timezone":"GMT","openDate":"2021-09-13T13:50:00.000Z","version":4030721366,"name":"Match Odds","eventName":"T Lukas v Y Cavalle-reimers"}}]}
{"op":"mcm","clk":"4233944050","pt":1631540292538,"mc":[{"id":"1.187595437","marketDefinition":{"bspMarket":false,"turnInPlayEnabled":true,"persistenceEnabled":true,"marketBaseRate":5.0,"eventId":"30898003","eventTypeId":"2","numberOfWinners":1,"bettingType":"ODDS","marketType":"MATCH_ODDS","marketTime":"2021-09-13T13:45:00.000Z","suspendTime":"2021-09-13T13:45:00.000Z","bspReconciled":false,"complete":true,"inPlay":false,"crossMatching":true,"runnersVoidable":false,"numberOfActiveRunners":2,"betDelay":0,"status":"OPEN","runners":[{"status":"ACTIVE","sortPriority":1,"id":9168659,"name":"T Lukas"},{"status":"ACTIVE","sortPriority":2,"id":9628279,"name":"Y Cavalle-Reimers"}],"regulators":["MR_INT"],"countryCode":"GB","discountAllowed":true,"timezone":"GMT","openDate":"2021-09-13T13:45:00.000Z","version":4030721366,"name":"Match Odds","eventName":"T Lukas v Y Cavalle-reimers"}}]}
{"op":"mcm","clk":"4233949786","pt":1631540362214,"mc":[{"id":"1.187595437","rc":[{"trd":[[1.45,16.18]],"batb":[[0,1.45,20.29]],"ltp":1.45,"tv":16.17,"id":9628279}],"tv":16.17}]}
{"op":"mcm","clk":"4233973850","pt":1631540663744,"mc":[{"id":"1.187595437","rc":[{"batl":[[0,5.6,4.41],[1,990,2.2]],"ltp":0.0,"tv":0.0,"id":9168659}]}]}
{"op":"mcm","clk":"4233974214","pt":1631540667752,"mc":[{"id":"1.187595437","rc":[{"batb":[[2,1.06,42.58]],"ltp":1.45,"tv":16.17,"id":9628279}]}]}
{"op":"mcm","clk":"4233974641","pt":1631540672848,"mc":[{"id":"1.187595437","rc":[{"batb":[[2,1.22,194.02]],"ltp":1.45,"tv":16.17,"id":9628279}]}]}
{"op":"mcm","clk":"4233980151","pt":1631540744079,"mc":[{"id":"1.187595437","marketDefinition":{"bspMarket":false,"turnInPlayEnabled":true,"persistenceEnabled":true,"marketBaseRate":5.0,"eventId":"30898003","eventTypeId":"2","numberOfWinners":1,"bettingType":"ODDS","marketType":"MATCH_ODDS","marketTime":"2021-09-13T13:45:00.000Z","suspendTime":"2021-09-13T13:45:00.000Z","bspReconciled":false,"complete":true,"inPlay":true,"crossMatching":true,"runnersVoidable":false,"numberOfActiveRunners":2,"betDelay":5,"status":"OPEN","runners":[{"status":"ACTIVE","sortPriority":1,"id":9168659,"name":"T Lukas"},{"status":"ACTIVE","sortPriority":2,"id":9628279,"name":"Y Cavalle-Reimers"}],"regulators":["MR_INT"],"countryCode":"GB","discountAllowed":true,"timezone":"GMT","openDate":"2021-09-13T13:45:00.000Z","version":4030729056,"name":"Match Odds","eventName":"T Lukas v Y Cavalle-reimers"},"rc":[{"batb":[[0,1.01,7],[1,1.44,0],[2,1.22,0]],"batl":[[1,1.94,0],[2,2.2,0]],"ltp":1.45,"tv":16.17,"id":9628279},{"batb":[[0,1.01,7],[1,2.62,0],[2,1.01,0]],"ltp":0.0,"tv":0.0,"id":9168659}]}]}
{"op":"mcm","clk":"4233980565","pt":1631540749269,"mc":[{"id":"1.187595437","rc":[{"batb":[[0,1.42,71.42],[1,1.01,7]],"ltp":1.45,"tv":16.17,"id":9628279},{"batb":[[0,2.58,18.98],[1,1.01,7]],"ltp":0.0,"tv":0.0,"id":9168659}]}]}
{"op":"mcm","clk":"4234004785","pt":1631540965493,"mc":[{"id":"1.187595437","rc":[{"trd":[[1.42,3.4]],"batb":[[0,1.01,7],[1,1.01,0]],"ltp":1.42,"tv":19.57,"id":9628279}],"tv":19.57}]}
{"op":"mcm","clk":"4234005105","pt":1631540970408,"mc":[{"id":"1.187595437","rc":[{"batb":[[0,1.42,71.42],[1,1.01,7]],"ltp":1.42,"tv":19.57,"id":9628279}]}]}
{"op":"mcm","clk":"4234046457","pt":1631541565388,"mc":[{"id":"1.187595437","marketDefinition":{"bspMarket":false,"turnInPlayEnabled":true,"persistenceEnabled":true,"marketBaseRate":5.0,"eventId":"30898003","eventTypeId":"2","numberOfWinners":1,"bettingType":"ODDS","marketType":"MATCH_ODDS","marketTime":"2021-09-13T13:59:24.000Z","suspendTime":"2021-09-13T13:59:24.000Z","bspReconciled":false,"complete":true,"inPlay":true,"crossMatching":true,"runnersVoidable":false,"numberOfActiveRunners":2,"betDelay":5,"status":"OPEN","runners":[{"status":"ACTIVE","sortPriority":1,"id":9168659,"name":"T Lukas"},{"status":"ACTIVE","sortPriority":2,"id":9628279,"name":"Y Cavalle-Reimers"}],"regulators":["MR_INT"],"countryCode":"GB","discountAllowed":true,"timezone":"GMT","openDate":"2021-09-13T13:45:00.000Z","version":4030741197,"name":"Match Odds","eventName":"T Lukas v Y Cavalle-reimers"}}]}
{"op":"mcm","clk":"4234046642","pt":1631541568405,"mc":[{"id":"1.187595437","marketDefinition":{"bspMarket":false,"turnInPlayEnabled":true,"persistenceEnabled":true,"marketBaseRate":5.0,"eventId":"30898003","eventTypeId":"2","numberOfWinners":1,"bettingType":"ODDS","marketType":"MATCH_ODDS","marketTime":"2021-09-13T13:59:24.000Z","suspendTime":"2021-09-13T13:59:24.000Z","bspReconciled":false,"complete":true,"inPlay":true,"crossMatching":true,"runnersVoidable":false,"numberOfActiveRunners":2,"betDelay":5,"status":"OPEN","runners":[{"status":"ACTIVE","sortPriority":1,"id":9168659,"name":"T Lukas"},{"status":"ACTIVE","sortPriority":2,"id":9628279,"name":"Y Cavalle-Reimers"}],"regulators":["MR_INT"],"countryCode":"GB","discountAllowed":true,"timezone":"GMT","openDate":"2021-09-13T13:59:24.000Z","version":4030741197,"name":"Match Odds","eventName":"T Lukas v Y Cavalle-reimers"}}]}
{"op":"mcm","clk":"4234050914","pt":1631541621501,"mc":[{"id":"1.187595437","rc":[{"batb":[[0,1.01,7],[1,1.01,0]],"ltp":1.42,"tv":19.57,"id":9628279},{"batb":[[0,1.01,7],[1,1.01,0]],"ltp":0.0,"tv":0.0,"id":9168659}]}]}
{"op":"mcm","clk":"4234051300","pt":1631541626400,"mc":[{"id":"1.187595437","rc":[{"batb":[[0,1.48,62.5],[1,1.01,7]],"ltp":1.42,"tv":19.57,"id":9628279},{"batb":[[0,2.5,20],[1,1.01,7]],"ltp":0.0,"tv":0.0,"id":9168659}]}]}
{"op":"mcm","clk":"4234053646","pt":1631541658634,"mc":[{"id":"1.187595437","rc":[{"batb":[[0,1.01,7],[1,1.01,0]],"ltp":1.42,"tv":19.57,"id":9628279},{"batb":[[0,1.01,7],[1,1.01,0]],"ltp":0.0,"tv":0.0,"id":9168659}]}]}
{"op":"mcm","clk":"4234054096","pt":1631541663660,"mc":[{"id":"1.187595437","rc":[{"batb":[[0,1.55,54.54],[1,1.01,7]],"ltp":1.42,"tv":19.57,"id":9628279},{"batb":[[0,2.34,22.38],[1,1.01,7]],"ltp":0.0,"tv":0.0,"id":9168659}]}]}
{"op":"mcm","clk":"4234055990","pt":1631541686911,"mc":[{"id":"1.187595437","rc":[{"batb":[[0,1.01,7],[1,1.01,0]],"ltp":1.42,"tv":19.57,"id":9628279},{"batb":[[0,1.01,7],[1,1.01,0]],"ltp":0.0,"tv":0.0,"id":9168659}]}]}
{"op":"mcm","clk":"4234056398","pt":1631541691813,"mc":[{"id":"1.187595437","rc":[{"batb":[[0,1.48,62.5],[1,1.01,7]],"ltp":1.42,"tv":19.57,"id":9628279},{"batb":[[0,2.5,20],[1,1.01,7]],"ltp":0.0,"tv":0.0,"id":9168659}]}]}
{"op":"mcm","clk":"4234059494","pt":1631541728558,"mc":[{"id":"1.187595437","rc":[{"batb":[[0,1.01,7],[1,1.01,0]],"ltp":1.42,"tv":19.57,"id":9628279},{"batb":[[0,1.01,7],[1,1.01,0]],"ltp":0.0,"tv":0.0,"id":9168659}]}]}
{"op":"mcm","clk":"4234059952","pt":1631541733594,"mc":[{"id":"1.187595437","rc":[{"batb":[[0,1.55,54.54],[1,1.01,7]],"ltp":1.42,"tv":19.57,"id":9628279},{"batb":[[0,2.34,22.38],[1,1.01,7]],"ltp":0.0,"tv":0.0,"id":9168659}]}]}
{"op":"mcm","clk":"4234061360","pt":1631541750024,"mc":[{"id":"1.187595437","rc":[{"batb":[[0,1.01,7],[1,1.01,0]],"ltp":1.42,"tv":19.57,"id":9628279},{"batb":[[0,1.01,7],[1,1.01,0]],"ltp":0.0,"tv":0.0,"id":9168659}]}]}
{"op":"mcm","clk":"4234061790","pt":1631541754911,"mc":[{"id":"1.187595437","rc":[{"batb":[[0,1.51,58.82],[1,1.01,7]],"ltp":1.42,"tv":19.57,"id":9628279},{"batb":[[0,2.42,21.12],[1,1.01,7]],"ltp":0.0,"tv":0.0,"id":9168659}]}]}
{"op":"mcm","clk":"4234062379","pt":1631541762255,"mc":[{"id":"1.187595437","rc":[{"batb":[[0,1.01,7],[1,1.01,0]],"ltp":1.42,"tv":19.57,"id":9628279},{"batb":[[0,1.01,7],[1,1.01,0]],"ltp":0.0,"tv":0.0,"id":9168659}]}]}
{"op":"mcm","clk":"4234062811","pt":1631541767148,"mc":[{"id":"1.187595437","rc":[{"batb":[[0,2.16,25.86],[1,1.01,7]],"ltp":0.0,"tv":0.0,"id":9168659}]}]}
{"op":"mcm","clk":"4234069326","pt":1631541839167,"mc":[{"id":"1.187595437","rc":[{"batb":[[0,1.01,7],[1,1.01,0]],"ltp":0.0,"tv":0.0,"id":9168659}]}]}
{"op":"mcm","clk":"4234069786","pt":1631541843974,"mc":[{"id":"1.187595437","rc":[{"batb":[[0,1.55,54.54],[1,1.01,7]],"ltp":1.42,"tv":19.57,"id":9628279},{"batb":[[0,2.34,22.38],[1,1.01,7]],"ltp":0.0,"tv":0.0,"id":9168659}]}]}
{"op":"mcm","clk":"4234069922","pt":1631541845180,"mc":[{"id":"1.187595437","rc":[{"batb":[[1,1.92,400.29],[2,1.01,7]],"batl":[[0,3.45,182.86]],"ltp":0.0,"tv":0.0,"id":9168659}]}]}
{"op":"mcm","clk":"4234071945","pt":1631541866527,"mc":[{"id":"1.187595437","rc":[{"batb":[[0,1.01,7],[1,1.01,0]],"ltp":1.42,"tv":19.57,"id":9628279},{"batb":[[0,1.92,400.29],[1,1.01,7],[2,1.01,0]],"ltp":0.0,"tv":0.0,"id":9168659}]}]}
{"op":"mcm","clk":"4234072394","pt":1631541871428,"mc":[{"id":"1.187595437","rc":[{"batb":[[0,2.16,25.86],[1,1.92,400.29],[2,1.01,7]],"ltp":0.0,"tv":0.0,"id":9168659}]}]}
{"op":"mcm","clk":"4234072574","pt":1631541873249,"mc":[{"id":"1.187595437","rc":[{"batl":[[0,3.3,194.53]],"ltp":0.0,"tv":0.0,"id":9168659}]}]}
{"op":"mcm","clk":"4234075479","pt":1631541902992,"mc":[{"id":"1.187595437","rc":[{"batb":[[0,1.92,400.29],[1,1.01,7],[2,1.01,0]],"ltp":0.0,"tv":0.0,"id":9168659}]}]}
{"op":"mcm","clk":"4234075596","pt":1631541903886,"mc":[{"id":"1.187595437","rc":[{"batb":[[0,1.01,7],[1,1.01,0]],"ltp":0.0,"tv":0.0,"id":9168659}]}]}
{"op":"mcm","clk":"4234076114","pt":1631541907921,"mc":[{"id":"1.187595437","rc":[{"batb":[[0,2,30],[1,1.01,7]],"ltp":0.0,"tv":0.0,"id":9168659}]}]}
{"op":"mcm","clk":"4234076199","pt":1631541908706,"mc":[{"id":"1.187595437","rc":[{"trd":[[1.61,105.86]],"batl":[[0,1.61,47.04]],"ltp":1.61,"tv":125.43,"id":9628279}],"tv":125.43}]}
{"op":"mcm","clk":"4234076348","pt":1631541910013,"mc":[{"id":"1.187595437","rc":[{"batb":[[1,1.77,407.75],[2,1.01,7]],"batl":[[0,3,216.36]],"ltp":0.0,"tv":0.0,"id":9168659}]}]}
{"op":"mcm","clk":"4234076502","pt":1631541911474,"mc":[{"id":"1.187595437","rc":[{"trd":[[1.61,138.27]],"batl":[[0,1.61,30.82]],"ltp":1.61,"tv":157.85,"id":9628279}],"tv":157.85}]}
{"op":"mcm","clk":"4234076622","pt":1631541912617,"mc":[{"id":"1.187595437","rc":[{"trd":[[1.61,199.88]],"batb":[[0,1.61,120.14],[1,1.01,7]],"ltp":1.61,"tv":219.45,"id":9628279}],"tv":219.45}]}
{"op":"mcm","clk":"4234076726","pt":1631541913611,"mc":[{"id":"1.187595437","rc":[{"batb":[[0,1.61,143.24]],"ltp":1.61,"tv":219.45,"id":9628279}]}]}
{"op":"mcm","clk":"4234076816","pt":1631541914625,"mc":[{"id":"1.187595437","rc":[{"batb":[[0,1.61,33.5]],"ltp":1.61,"tv":219.45,"id":9628279},{"batl":[[0,2.62,29.65],[1,3,216.36]],"ltp":0.0,"tv":0.0,"id":9168659}]}]}
{"op":"mcm","clk":"4234076859","pt":1631541915000,"mc":[{"id":"1.187595437","rc":[{"batb":[[0,1.61,5.58]],"ltp":1.61,"tv":219.45,"id":9628279},{"batl":[[0,3,216.36],[1,3,0]],"ltp":0.0,"tv":0.0,"id":9168659}]}]}
{"op":"mcm","clk":"4234076973","pt":1631541916298,"mc":[{"id":"1.187595437","rc":[{"batb":[[0,1.61,52.49]],"ltp":1.61,"tv":219.45,"id":9628279}]}]}
{"op":"mcm","clk":"4234077034","pt":1631541916927,"mc":[{"id":"1.187595437","rc":[{"batb":[[0,1.73,41.09],[1,1.61,98.56],[2,1.01,7]],"ltp":1.61,"tv":219.45,"id":9628279}]}]}
{"op":"mcm","clk":"4234077135","pt":1631541917915,"mc":[{"id":"1.187595437","rc":[{"batb":[[1,1.61,5.58]],"ltp":1.61,"tv":219.45,"id":9628279}]}]}
{"op":"mcm","clk":"4234077288","pt":1631541919642,"mc":[{"id":"1.187595437","rc":[{"batb":[[1,1.01,7],[2,1.01,0]],"ltp":1.61,"tv":219.45,"id":9628279}]}]}
{"op":"mcm","clk":"4234077864","pt":1631541925633,"mc":[{"id":"1.187595437","rc":[{"batb":[[0,1.01,7],[1,1.01,0]],"ltp":1.61,"tv":219.45,"id":9628279},{"batb":[[0,1.77,407.75],[1,1.01,7],[2,1.01,0]],"ltp":0.0,"tv":0.0,"id":9168659}]}]}
{"op":"mcm","clk":"4234078291","pt":1631541930562,"mc":[{"id":"1.187595437","rc":[{"batb":[[0,1.78,38.46],[1,1.01,7]],"ltp":1.61,"tv":219.45,"id":9628279},{"batb":[[0,1.98,30.61],[1,1.77,407.75],[2,1.01,7]],"ltp":0.0,"tv":0.0,"id":9168659}]}]}
{"op":"mcm","clk":"4234079835","pt":1631541945870,"mc":[{"id":"1.187595437","rc":[{"batb":[[0,1.01,7],[1,1.01,0]],"ltp":1.61,"tv":219.45,"id":9628279},{"batb":[[0,1.77,407.75],[1,1.01,7],[2,1.01,0]],"ltp":0.0,"tv":0.0,"id":9168659}]}]}
{"op":"mcm","clk":"4234080339","pt":1631541950773,"mc":[{"id":"1.187595437","rc":[{"batb":[[0,1.65,46.15],[1,1.01,7]],"ltp":1.61,"tv":219.45,"id":9628279},{"batb":[[0,2.1,27.27],[1,1.77,407.75],[2,1.01,7]],"ltp":0.0,"tv":0.0,"id":9168659}]}]}
{"op":"mcm","clk":"4234082854","pt":1631541976631,"mc":[{"id":"1.187595437","rc":[{"batb":[[0,1.01,7],[1,1.01,0]],"ltp":1.61,"tv":219.45,"id":9628279},{"batb":[[0,1.77,407.75],[1,1.01,7],[2,1.01,0]],"ltp":0.0,"tv":0.0,"id":9168659}]}]}
{"op":"mcm","clk":"4234083351","pt":1631541981525,"mc":[{"id":"1.187595437","rc":[{"batb":[[0,1.78,38.46],[1,1.01,7]],"ltp":1.61,"tv":219.45,"id":9628279},{"batb":[[0,1.88,34.09],[1,1.77,407.75],[2,1.01,7]],"ltp":0.0,"tv":0.0,"id":9168659}]}]}
{"op":"mcm","clk":"4234087108","pt":1631542018992,"mc":[{"id":"1.187595437","rc":[{"batb":[[0,1.01,7],[1,1.01,0]],"ltp":1.61,"tv":219.45,"id":9628279}]}]}
{"op":"mcm","clk":"4234087590","pt":1631542023992,"mc":[{"id":"1.187595437","rc":[{"batb":[[0,1.85,35.29],[1,1.01,7]],"ltp":1.61,"tv":219.45,"id":9628279}]}]}
{"op":"mcm","clk":"4234088352","pt":1631542031290,"mc":[{"id":"1.187595437","rc":[{"batb":[[0,1.01,7],[1,1.01,0]],"ltp":1.61,"tv":219.45,"id":9628279},{"batb":[[0,1.77,407.75],[1,1.01,7],[2,1.01,0]],"ltp":0.0,"tv":0.0,"id":9168659}]}]}
{"op":"mcm","clk":"4234088875","pt":1631542036333,"mc":[{"id":"1.187595437","rc":[{"batb":[[0,1.65,46.15],[1,1.01,7]],"ltp":1.61,"tv":219.45,"id":9628279},{"batb":[[0,2.1,27.27],[1,1.77,407.75],[2,1.01,7]],"ltp":0.0,"tv":0.0,"id":9168659}]}]}
{"op":"mcm","clk":"4234091252","pt":1631542059767,"mc":[{"id":"1.187595437","rc":[{"batb":[[0,1.01,7],[1,1.01,0]],"ltp":1.61,"tv":219.45,"id":9628279},{"batb":[[0,1.77,407.75],[1,1.01,7],[2,1.01,0]],"ltp":0.0,"tv":0.0,"id":9168659}]}]}
{"op":"mcm","clk":"4234091744","pt":1631542064556,"mc":[{"id":"1.187595437","rc":[{"batb":[[0,1.85,35.29],[1,1.01,7]],"ltp":1.61,"tv":219.45,"id":9628279},{"batb":[[0,1.88,34.09],[1,1.77,407.75],[2,1.01,7]],"ltp":0.0,"tv":0.0,"id":9168659}]}]}
{"op":"mcm","clk":"4234093084","pt":1631542079077,"mc":[{"id":"1.187595437","rc":[{"batb":[[0,1.01,7],[1,1.01,0]],"ltp":1.61,"tv":219.45,"id":9628279},{"batb":[[0,1.77,407.75],[1,1.01,7],[2,1.01,0]],"ltp":0.0,"tv":0.0,"id":9168659}]}]}
{"op":"mcm","clk":"4234093531","pt":1631542084013,"mc":[{"id":"1.187595437","rc":[{"batb":[[0,2,30],[1,1.01,7]],"ltp":1.61,"tv":219.45,"id":9628279},{"batb":[[1,1.73,41.09],[2,1.01,7]],"ltp":0.0,"tv":0.0,"id":9168659}]}]}
{"op":"mcm","clk":"4234093724","pt":1631542086010,"mc":[{"id":"1.187595437","rc":[{"batl":[[0,2.72,244.84]],"ltp":0.0,"tv":0.0,"id":9168659}]}]}
{"op":"mcm","clk":"4234095105","pt":1631542099404,"mc":[{"id":"1.187595437","rc":[{"batb":[[0,1.01,7],[1,1.01,0]],"ltp":1.61,"tv":219.45,"id":9628279},{"batb":[[1,1.01,7],[2,1.01,0]],"ltp":0.0,"tv":0.0,"id":9168659}]}]}
{"op":"mcm","clk":"4234095583","pt":1631542104319,"mc":[{"id":"1.187595437","rc":[{"batb":[[0,1.88,34.09],[1,1.01,7]],"ltp":1.61,"tv":219.45,"id":9628279},{"batb":[[0,1.85,35.29],[1,1.77,407.75],[2,1.01,7]],"ltp":0.0,"tv":0.0,"id":9168659}]}]}
{"op":"mcm","clk":"4234097084","pt":1631542120178,"mc":[{"id":"1.187595437","rc":[{"batb":[[0,1.01,7],[1,1.01,0]],"ltp":1.61,"tv":219.45,"id":9628279},{"batb":[[0,1.77,407.75],[1,1.01,7],[2,1.01,0]],"ltp":0.0,"tv":0.0,"id":9168659}]}]}
{"op":"mcm","clk":"4234097153","pt":1631542121057,"mc":[{"id":"1.187595437","rc":[{"batb":[[0,1.01,7],[1,1.01,0]],"ltp":0.0,"tv":0.0,"id":9168659}]}]}
{"op":"mcm","clk":"4234097524","pt":1631542125049,"mc":[{"id":"1.187595437","rc":[{"batb":[[0,2.06,28.3],[1,1.01,7]],"ltp":1.61,"tv":219.45,"id":9628279},{"batb":[[0,1.71,42.25],[1,1.01,7]],"ltp":0.0,"tv":0.0,"id":9168659}]}]}
{"op":"mcm","clk":"4234097684","pt":1631542126685,"mc":[{"id":"1.187595437","rc":[{"batb":[[1,1.58,422.14],[2,1.01,7]],"batl":[[0,2.5,278.28]],"ltp":0.0,"tv":0.0,"id":9168659}]}]}
{"op":"mcm","clk":"4234099445","pt":1631542143495,"mc":[{"id":"1.187595437","rc":[{"batb":[[0,1.01,7],[1,1.01,0]],"ltp":1.61,"tv":219.45,"id":9628279},{"batb":[[0,1.58,422.14],[1,1.01,7],[2,1.01,0]],"ltp":0.0,"tv":0.0,"id":9168659}]}]}
{"op":"mcm","clk":"4234099985","pt":1631542148510,"mc":[{"id":"1.187595437","rc":[{"batb":[[0,2.16,25.86],[1,1.01,7]],"ltp":1.61,"tv":219.45,"id":9628279},{"batb":[[0,1.63,47.61],[1,1.58,422.14],[2,1.01,7]],"ltp":0.0,"tv":0.0,"id":9168659}]}]}
{"op":"mcm","clk":"4234103812","pt":1631542185874,"mc":[{"id":"1.187595437","rc":[{"batb":[[0,1.01,7],[1,1.01,0]],"ltp":1.61,"tv":219.45,"id":9628279},{"batb":[[0,1.58,422.14],[1,1.01,7],[2,1.01,0]],"ltp":0.0,"tv":0.0,"id":9168659}]}]}
{"op":"mcm","clk":"4234103957","pt":1631542187012,"mc":[{"id":"1.187595437","rc":[{"batb":[[0,1.87,2],[1,1.58,422.14],[2,1.01,7]],"ltp":0.0,"tv":0.0,"id":9168659}]}]}
{"op":"mcm","clk":"4234104356","pt":1631542191128,"mc":[{"id":"1.187595437","rc":[{"trd":[[2.16,1.73]],"ltp":2.16,"tv":221.18,"id":9628279},{"trd":[[1.87,2]],"batb":[[0,1.58,422.14],[1,1.55,54.54]],"ltp":1.87,"tv":2.0,"id":9168659}],"tv":223.18}]}
{"op":"mcm","clk":"4234104463","pt":1631542192361,"mc":[{"id":"1.187595437","rc":[{"batl":[[0,2.3,313.97]],"ltp":1.87,"tv":2.0,"id":9168659}]}]}
{"op":"mcm","clk":"4234104685","pt":1631542194557,"mc":[{"id":"1.187595437","rc":[{"batl":[[0,1.87,386.42],[1,2.3,313.97]],"ltp":1.87,"tv":2.0,"id":9168659}]}]}
{"op":"mcm","clk":"4234104745","pt":1631542195272,"mc":[{"id":"1.187595437","rc":[{"batl":[[0,2.3,313.97],[1,2.3,0]],"ltp":1.87,"tv":2.0,"id":9168659}]}]}
{"op":"mcm","clk":"4234104819","pt":1631542196053,"mc":[{"id":"1.187595437","rc":[{"batb":[[0,2.34,22.38],[1,1.01,7]],"ltp":2.16,"tv":221.18,"id":9628279}]}]}
{"op":"mcm","clk":"4234108202","pt":1631542230700,"mc":[{"id":"1.187595437","rc":[{"batb":[[0,1.61,28.45],[1,1.58,422.14],[2,1.55,54.54]],"ltp":1.87,"tv":2.0,"id":9168659}]}]}
{"op":"mcm","clk":"4234108613","pt":1631542235626,"mc":[{"id":"1.187595437","rc":[{"batb":[[0,1.01,7],[1,1.01,0]],"ltp":2.16,"tv":221.18,"id":9628279},{"batb":[[1,1.01,7],[2,1.55,0]],"ltp":1.87,"tv":2.0,"id":9168659}]}]}
{"op":"mcm","clk":"4234109035","pt":1631542240544,"mc":[{"id":"1.187595437","rc":[{"batb":[[0,2.42,21.12],[1,1.01,7]],"ltp":2.16,"tv":221.18,"id":9628279},{"batb":[[1,1.51,58.82],[2,1.01,7]],"ltp":1.87,"tv":2.0,"id":9168659}]}]}
{"op":"mcm","clk":"4234109179","pt":1631542241713,"mc":[{"id":"1.187595437","rc":[{"batb":[[2,1.46,441.64]],"ltp":1.87,"tv":2.0,"id":9168659}]}]}
{"op":"mcm","clk":"4234118351","pt":1631542333380,"mc":[{"id":"1.187595437","rc":[{"trd":[[2.42,6.92]],"batb":[[0,2.42,17.66]],"ltp":2.42,"tv":228.1,"id":9628279}],"tv":230.1}]}
{"op":"mcm","clk":"4234118388","pt":1631542333792,"mc":[{"id":"1.187595437","rc":[{"batb":[[0,1.01,7],[1,1.01,0]],"ltp":2.42,"tv":228.1,"id":9628279}]}]}
{"op":"mcm","clk":"4234118873","pt":1631542338685,"mc":[{"id":"1.187595437","rc":[{"batb":[[0,2.42,21.12],[1,1.01,7]],"ltp":2.42,"tv":228.1,"id":9628279}]}]}
{"op":"mcm","clk":"4234119458","pt":1631542344435,"mc":[{"id":"1.187595437","rc":[{"batb":[[0,1.01,7],[1,1.01,0]],"ltp":2.42,"tv":228.1,"id":9628279},{"batb":[[1,1.46,441.64],[2,1.01,7]],"ltp":1.87,"tv":2.0,"id":9168659}]}]}
{"op":"mcm","clk":"4234119960","pt":1631542349326,"mc":[{"id":"1.187595437","rc":[{"batb":[[0,2.5,20],[1,1.01,7]],"ltp":2.42,"tv":228.1,"id":9628279},{"batb":[[1,1.48,62.5],[2,1.46,441.64]],"ltp":1.87,"tv":2.0,"id":9168659}]}]}
{"op":"mcm","clk":"4234120174","pt":1631542351357,"mc":[{"id":"1.187595437","rc":[{"batl":[[0,2.16,347.49]],"ltp":1.87,"tv":2.0,"id":9168659}]}]}
{"op":"mcm","clk":"4234121876","pt":1631542368251,"mc":[{"id":"1.187595437","rc":[{"batb":[[0,1.01,7],[1,1.01,0]],"ltp":2.42,"tv":228.1,"id":9628279},{"batb":[[1,1.46,441.64],[2,1.01,7]],"ltp":1.87,"tv":2.0,"id":9168659}]}]}
{"op":"mcm","clk":"4234122380","pt":1631542373137,"mc":[{"id":"1.187595437","rc":[{"batb":[[0,2.42,21.12],[1,1.01,7]],"ltp":2.42,"tv":228.1,"id":9628279},{"batb":[[1,1.51,58.82],[2,1.46,441.64]],"ltp":1.87,"tv":2.0,"id":9168659}]}]}
{"op":"mcm","clk":"4234122442","pt":1631542373767,"mc":[{"id":"1.187595437","rc":[{"batb":[[0,1.51,58.82],[1,1.46,441.64],[2,1.01,7]],"ltp":1.87,"tv":2.0,"id":9168659}]}]}
{"op":"mcm","clk":"4234123760","pt":1631542387473,"mc":[{"id":"1.187595437","rc":[{"batb":[[0,1.01,7],[1,1.01,0]],"ltp":2.42,"tv":228.1,"id":9628279},{"batb":[[0,1.46,441.64],[1,1.01,7],[2,1.01,0]],"ltp":1.87,"tv":2.0,"id":9168659}]}]}
{"op":"mcm","clk":"4234124231","pt":1631542392398,"mc":[{"id":"1.187595437","rc":[{"batb":[[0,2.58,18.98],[1,1.01,7]],"ltp":2.42,"tv":228.1,"id":9628279},{"batb":[[1,1.45,66.66],[2,1.01,7]],"ltp":1.87,"tv":2.0,"id":9168659}]}]}
{"op":"mcm","clk":"4234127421","pt":1631542428547,"mc":[{"id":"1.187595437","rc":[{"batb":[[0,1.45,66.66],[1,1.01,7],[2,1.01,0]],"ltp":1.87,"tv":2.0,"id":9168659}]}]}
{"op":"mcm","clk":"4234127476","pt":1631542429128,"mc":[{"id":"1.187595437","rc":[{"batb":[[0,1.01,7],[1,1.01,0]],"ltp":2.42,"tv":228.1,"id":9628279},{"batb":[[0,1.01,7],[1,1.01,0]],"ltp":1.87,"tv":2.0,"id":9168659}]}]}
{"op":"mcm","clk":"4234127930","pt":1631542434246,"mc":[{"id":"1.187595437","rc":[{"batb":[[0,2.66,18.07],[1,1.01,7]],"ltp":2.42,"tv":228.1,"id":9628279},{"batb":[[0,1.42,71.42],[1,1.34,471.77],[2,1.01,7]],"batl":[[0,1.95,415.45]],"ltp":1.87,"tv":2.0,"id":9168659}]}]}
{"op":"mcm","clk":"4234129763","pt":1631542454693,"mc":[{"id":"1.187595437","rc":[{"batb":[[0,1.49,31.16],[1,1.42,71.42],[2,1.34,471.77]],"ltp":1.87,"tv":2.0,"id":9168659}]}]}
{"op":"mcm","clk":"4234131622","pt":1631542471348,"mc":[{"id":"1.187595437","rc":[{"batb":[[0,1.01,7],[1,1.01,0]],"ltp":2.42,"tv":228.1,"id":9628279},{"batb":[[1,1.34,471.77],[2,1.01,7]],"ltp":1.87,"tv":2.0,"id":9168659}]}]}
{"op":"mcm","clk":"4234131722","pt":1631542472138,"mc":[{"id":"1.187595437","rc":[{"batb":[[1,1.01,7],[2,1.01,0]],"ltp":1.87,"tv":2.0,"id":9168659}]}]}
{"op":"mcm","clk":"4234132140","pt":1631542476373,"mc":[{"id":"1.187595437","rc":[{"batb":[[0,2.58,18.98],[1,1.01,7]],"ltp":2.42,"tv":228.1,"id":9628279},{"batb":[[1,1.45,66.66],[2,1.01,7]],"ltp":1.87,"tv":2.0,"id":9168659}]}]}
{"op":"mcm","clk":"4234132328","pt":1631542477736,"mc":[{"id":"1.187595437","rc":[{"batb":[[2,1.38,454.56]],"ltp":1.87,"tv":2.0,"id":9168659}]}]}
{"op":"mcm","clk":"4234135484","pt":1631542506481,"mc":[{"id":"1.187595437","rc":[{"batb":[[0,1.01,7],[1,1.01,0]],"ltp":2.42,"tv":228.1,"id":9628279},{"batb":[[1,1.38,454.56],[2,1.01,7]],"ltp":1.87,"tv":2.0,"id":9168659}]}]}
{"op":"mcm","clk":"4234135646","pt":1631542507682,"mc":[{"id":"1.187595437","rc":[{"batb":[[1,1.01,7],[2,1.01,0]],"ltp":1.87,"tv":2.0,"id":9168659}]}]}
{"op":"mcm","clk":"4234136141","pt":1631542511389,"mc":[{"id":"1.187595437","rc":[{"batb":[[0,2.42,21.12],[1,1.01,7]],"ltp":2.42,"tv":228.1,"id":9628279},{"batb":[[0,1.51,58.82],[1,1.49,31.16],[2,1.01,7]],"ltp":1.87,"tv":2.0,"id":9168659}]}]}
{"op":"mcm","clk":"4234136429","pt":1631542514015,"mc":[{"id":"1.187595437","rc":[{"batb":[[2,1.44,442.12]],"batl":[[0,2.16,347.49]],"ltp":1.87,"tv":2.0,"id":9168659}]}]}
{"op":"mcm","clk":"4234138220","pt":1631542529406,"mc":[{"id":"1.187595437","rc":[{"batb":[[0,1.01,7],[1,1.01,0]],"ltp":2.42,"tv":228.1,"id":9628279}]}]}
{"op":"mcm","clk":"4234138731","pt":1631542534307,"mc":[{"id":"1.187595437","rc":[{"batb":[[0,2.5,20],[1,1.01,7]],"ltp":2.42,"tv":228.1,"id":9628279}]}]}
{"op":"mcm","clk":"4234140146","pt":1631542547337,"mc":[{"id":"1.187595437","rc":[{"batb":[[0,1.01,7],[1,1.01,0]],"ltp":2.42,"tv":228.1,"id":9628279},{"batb":[[0,1.49,31.16],[1,1.01,7],[2,1.44,0]],"ltp":1.87,"tv":2.0,"id":9168659}]}]}
{"op":"mcm","clk":"4234140556","pt":1631542552131,"mc":[{"id":"1.187595437","rc":[{"batb":[[0,2.58,18.98],[1,1.01,7]],"ltp":2.42,"tv":228.1,"id":9628279},{"batb":[[1,1.45,66.66],[2,1.01,7]],"ltp":1.87,"tv":2.0,"id":9168659}]}]}
{"op":"mcm","clk":"4234140707","pt":1631542553284,"mc":[{"id":"1.187595437","rc":[{"batb":[[2,1.38,454.56]],"batl":[[0,2.04,388.23]],"ltp":1.87,"tv":2.0,"id":9168659}]}]}
{"op":"mcm","clk":"4234142506","pt":1631542571793,"mc":[{"id":"1.187595437","rc":[{"batb":[[2,1.01,7]],"ltp":1.87,"tv":2.0,"id":9168659}]}]}
{"op":"mcm","clk":"4234143619","pt":1631542583277,"mc":[{"id":"1.187595437","rc":[{"batb":[[0,1.01,7],[1,1.01,0]],"ltp":2.42,"tv":228.1,"id":9628279},{"batb":[[1,1.01,7],[2,1.01,0]],"ltp":1.87,"tv":2.0,"id":9168659}]}]}
{"op":"mcm","clk":"4234143769","pt":1631542585091,"mc":[{"id":"1.187595437","rc":[{"batb":[[1,1.34,471.77],[2,1.01,7]],"batl":[[0,1.95,415.45]],"ltp":1.87,"tv":2.0,"id":9168659}]}]}
{"op":"mcm","clk":"4234143856","pt":1631542586025,"mc":[{"id":"1.187595437","rc":[{"batb":[[1,1.01,7],[2,1.01,0]],"ltp":1.87,"tv":2.0,"id":9168659}]}]}
{"op":"mcm","clk":"4234144056","pt":1631542588206,"mc":[{"id":"1.187595437","rc":[{"batb":[[0,2.84,16.3],[1,1.01,7]],"ltp":2.42,"tv":228.1,"id":9628279},{"batb":[[1,1.38,78.94],[2,1.01,7]],"ltp":1.87,"tv":2.0,"id":9168659}]}]}
{"op":"mcm","clk":"4234144647","pt":1631542594583,"mc":[{"id":"1.187595437","rc":[{"trd":[[3.05,3.8]],"ltp":3.05,"tv":231.9,"id":9628279},{"trd":[[1.49,54.54]],"batb":[[0,1.38,78.94],[1,1.01,7],[2,1.01,0]],"batl":[[0,1.49,126.93]],"ltp":1.49,"tv":56.54,"id":9168659}],"tv":288.44}]}
{"op":"mcm","clk":"4234147021","pt":1631542619433,"mc":[{"id":"1.187595437","rc":[{"batb":[[1,1.25,511.97],[2,1.01,7]],"batl":[[0,1.77,507.43]],"ltp":1.49,"tv":56.54,"id":9168659}]}]}
{"op":"mcm","clk":"4234149243","pt":1631542640323,"mc":[{"id":"1.187595437","rc":[{"batb":[[0,1.01,7],[1,1.01,0]],"ltp":3.05,"tv":231.9,"id":9628279},{"batb":[[0,1.25,511.97],[1,1.01,7],[2,1.01,0]],"ltp":1.49,"tv":56.54,"id":9168659}]}]}
{"op":"mcm","clk":"4234149300","pt":1631542640789,"mc":[{"id":"1.187595437","rc":[{"batb":[[0,1.01,7],[1,1.01,0]],"ltp":1.49,"tv":56.54,"id":9168659}]}]}
{"op":"mcm","clk":"4234149749","pt":1631542645218,"mc":[{"id":"1.187595437","rc":[{"batb":[[0,3,15],[1,1.01,7]],"ltp":3.05,"tv":231.9,"id":9628279},{"batb":[[0,1.34,88.23],[1,1.01,7]],"ltp":1.49,"tv":56.54,"id":9168659}]}]}
{"op":"mcm","clk":"4234149915","pt":1631542646793,"mc":[{"id":"1.187595437","rc":[{"batb":[[1,1.22,530.12],[2,1.01,7]],"ltp":1.49,"tv":56.54,"id":9168659}]}]}
{"op":"mcm","clk":"4234150928","pt":1631542656725,"mc":[{"id":"1.187595437","rc":[{"batl":[[0,1.66,587.71]],"ltp":1.49,"tv":56.54,"id":9168659}]}]}
{"op":"mcm","clk":"4234152600","pt":1631542673759,"mc":[{"id":"1.187595437","rc":[{"batb":[[0,1.01,7],[1,1.01,0]],"ltp":3.05,"tv":231.9,"id":9628279},{"batb":[[0,1.22,530.12],[1,1.01,7],[2,1.01,0]],"ltp":1.49,"tv":56.54,"id":9168659}]}]}
{"op":"mcm","clk":"4234153125","pt":1631542678745,"mc":[{"id":"1.187595437","rc":[{"batb":[[0,2.84,16.3],[1,1.01,7]],"ltp":3.05,"tv":231.9,"id":9628279},{"batb":[[0,1.38,78.94],[1,1.22,530.12],[2,1.01,7]],"ltp":1.49,"tv":56.54,"id":9168659}]}]}
{"op":"mcm","clk":"4234154399","pt":1631542692371,"mc":[{"id":"1.187595437","rc":[{"trd":[[1.38,23.74]],"batb":[[0,1.22,530.12],[1,1.01,7],[2,1.01,0]],"ltp":1.38,"tv":80.28,"id":9168659}],"tv":312.19}]}
{"op":"mcm","clk":"4234154857","pt":1631542697361,"mc":[{"id":"1.187595437","rc":[{"batb":[[0,1.38,78.94],[1,1.22,530.12],[2,1.01,7]],"ltp":1.38,"tv":80.28,"id":9168659}]}]}
{"op":"mcm","clk":"4234157246","pt":1631542726021,"mc":[{"id":"1.187595437","rc":[{"batb":[[1,1.01,7],[2,1.01,0]],"ltp":1.38,"tv":80.28,"id":9168659}]}]}
{"op":"mcm","clk":"4234157753","pt":1631542731741,"mc":[{"id":"1.187595437","rc":[{"batb":[[1,1.25,511.97],[2,1.01,7]],"ltp":1.38,"tv":80.28,"id":9168659}]}]}
{"op":"mcm","clk":"4234158035","pt":1631542735225,"mc":[{"id":"1.187595437","rc":[{"batb":[[1,1.01,7],[2,1.01,0]],"ltp":1.38,"tv":80.28,"id":9168659}]}]}
{"op":"mcm","clk":"4234158539","pt":1631542740945,"mc":[{"id":"1.187595437","rc":[{"batb":[[1,1.22,530.12],[2,1.01,7]],"ltp":1.38,"tv":80.28,"id":9168659}]}]}
{"op":"mcm","clk":"4234159994","pt":1631542757585,"mc":[{"id":"1.187595437","rc":[{"batb":[[1,1.01,7],[2,1.01,0]],"ltp":1.38,"tv":80.28,"id":9168659}]}]}
{"op":"mcm","clk":"4234160564","pt":1631542763105,"mc":[{"id":"1.187595437","rc":[{"batb":[[1,1.25,511.97],[2,1.01,7]],"ltp":1.38,"tv":80.28,"id":9168659}]}]}
{"op":"mcm","clk":"4234163008","pt":1631542789030,"mc":[{"id":"1.187595437","rc":[{"batb":[[1,1.01,7],[2,1.01,0]],"ltp":1.38,"tv":80.28,"id":9168659}]}]}
{"op":"mcm","clk":"4234163488","pt":1631542794467,"mc":[{"id":"1.187595437","rc":[{"batb":[[1,1.22,530.12],[2,1.01,7]],"ltp":1.38,"tv":80.28,"id":9168659}]}]}
{"op":"mcm","clk":"4234163928","pt":1631542799252,"mc":[{"id":"1.187595437","rc":[{"batb":[[1,1.01,7],[2,1.01,0]],"ltp":1.38,"tv":80.28,"id":9168659}]}]}
{"op":"mcm","clk":"4234164757","pt":1631542807979,"mc":[{"id":"1.187595437","rc":[{"batb":[[0,1.01,7],[1,1.01,0]],"ltp":3.05,"tv":231.9,"id":9628279},{"batb":[[0,1.01,7],[1,1.01,0]],"ltp":1.38,"tv":80.28,"id":9168659}]}]}
{"op":"mcm","clk":"4234165211","pt":1631542812857,"mc":[{"id":"1.187595437","rc":[{"batb":[[0,3,15],[1,1.01,7]],"ltp":3.05,"tv":231.9,"id":9628279},{"batb":[[0,1.34,88.23],[1,1.01,7]],"ltp":1.38,"tv":80.28,"id":9168659}]}]}
{"op":"mcm","clk":"4234169346","pt":1631542857732,"mc":[{"id":"1.187595437","rc":[{"batl":[[0,1.4,5]],"ltp":1.38,"tv":80.28,"id":9168659}]}]}
{"op":"mcm","clk":"4234169876","pt":1631542863267,"mc":[{"id":"1.187595437","rc":[{"trd":[[1.34,6.78]],"batb":[[0,1.01,7],[1,1.01,0]],"ltp":1.34,"tv":87.06,"id":9168659}],"tv":318.97}]}
{"op":"mcm","clk":"4234170340","pt":1631542868264,"mc":[{"id":"1.187595437","rc":[{"batb":[[0,1.34,88.23],[1,1.01,7]],"ltp":1.34,"tv":87.06,"id":9168659}]}]}
{"op":"mcm","clk":"4234174823","pt":1631542919135,"mc":[{"id":"1.187595437","rc":[{"batb":[[0,1.01,7],[1,1.01,0]],"ltp":3.05,"tv":231.9,"id":9628279},{"batb":[[0,1.01,7],[1,1.01,0]],"ltp":1.34,"tv":87.06,"id":9168659}]}]}
{"op":"mcm","clk":"4234175295","pt":1631542924068,"mc":[{"id":"1.187595437","rc":[{"batb":[[0,3.15,13.95],[1,1.01,7]],"ltp":3.05,"tv":231.9,"id":9628279},{"batb":[[0,1.31,96.77],[1,1.01,7]],"ltp":1.34,"tv":87.06,"id":9168659}]}]}
{"op":"mcm","clk":"4234177263","pt":1631542946493,"mc":[{"id":"1.187595437","rc":[{"batb":[[0,1.01,7],[1,1.01,0]],"ltp":3.05,"tv":231.9,"id":9628279},{"batb":[[0,1.01,7],[1,1.01,0]],"ltp":1.34,"tv":87.06,"id":9168659}]}]}
{"op":"mcm","clk":"4234177707","pt":1631542951387,"mc":[{"id":"1.187595437","rc":[{"batb":[[0,3,15],[1,1.01,7]],"ltp":3.05,"tv":231.9,"id":9628279},{"batb":[[0,1.34,88.23],[1,1.01,7]],"ltp":1.34,"tv":87.06,"id":9168659}]}]}
{"op":"mcm","clk":"4234180466","pt":1631542978417,"mc":[{"id":"1.187595437","rc":[{"batb":[[1,1.16,583.98],[2,1.01,7]],"batl":[[1,1.58,659.44]],"ltp":1.34,"tv":87.06,"id":9168659}]}]}
{"op":"mcm","clk":"4234180698","pt":1631542980628,"mc":[{"id":"1.187595437","rc":[{"trd":[[3.95,8.66]],"ltp":3.95,"tv":240.56,"id":9628279},{"trd":[[1.34,32.34]],"batb":[[0,1.34,62.67]],"ltp":1.34,"tv":112.62,"id":9168659}],"tv":353.19}]}
{"op":"mcm","clk":"4234180832","pt":1631542981630,"mc":[{"id":"1.187595437","rc":[{"trd":[[3.95,25.98]],"batb":[[0,3.95,73.61],[1,3,15],[2,1.01,7]],"ltp":3.95,"tv":257.89,"id":9628279},{"trd":[[1.34,83.46]],"batb":[[0,1.16,583.98],[1,1.01,7],[2,1.01,0]],"batl":[[0,1.34,68.13],[1,1.4,5],[2,1.58,659.44]],"ltp":1.34,"tv":163.74,"id":9168659}],"tv":421.63}]}
{"op":"mcm","clk":"4234180929","pt":1631542982469,"mc":[{"id":"1.187595437","rc":[{"batb":[[0,3.95,98.21]],"ltp":3.95,"tv":257.89,"id":9628279},{"batl":[[0,1.34,42.58]],"ltp":1.34,"tv":163.74,"id":9168659}]}]}
{"op":"mcm","clk":"4234181050","pt":1631542983568,"mc":[{"id":"1.187595437","rc":[{"batb":[[0,3.95,40.48]],"ltp":3.95,"tv":257.89,"id":9628279},{"batl":[[0,1.34,34.07]],"ltp":1.34,"tv":163.74,"id":9168659}]}]}
{"op":"mcm","clk":"4234181141","pt":1631542984463,"mc":[{"id":"1.187595437","rc":[{"batb":[[0,3.95,69.68]],"ltp":3.95,"tv":257.89,"id":9628279},{"batl":[[0,1.4,5],[1,1.58,659.44],[2,1.58,0]],"ltp":1.34,"tv":163.74,"id":9168659}]}]}
{"op":"mcm","clk":"4234181252","pt":1631542985565,"mc":[{"id":"1.187595437","rc":[{"batl":[[0,1.34,60],[1,1.4,5],[2,1.58,659.44]],"ltp":1.34,"tv":163.74,"id":9168659}]}]}
{"op":"mcm","clk":"4234181352","pt":1631542986559,"mc":[{"id":"1.187595437","rc":[{"batb":[[0,3.95,30.51]],"ltp":3.95,"tv":257.89,"id":9628279},{"trd":[[1.34,259.92]],"batl":[[0,1.34,1.77]],"ltp":1.34,"tv":340.2,"id":9168659}],"tv":598.09}]}
{"op":"mcm","clk":"4234181391","pt":1631542987077,"mc":[{"id":"1.187595437","rc":[{"batb":[[0,3.95,20.34]],"ltp":3.95,"tv":257.89,"id":9628279},{"batl":[[0,1.34,30]],"ltp":1.34,"tv":340.2,"id":9168659}]}]}
{"op":"mcm","clk":"4234181478","pt":1631542988171,"mc":[{"id":"1.187595437","rc":[{"batb":[[0,3,15],[1,1.01,7],[2,1.01,0]],"ltp":3.95,"tv":257.89,"id":9628279},{"batl":[[0,1.4,5],[1,1.58,659.44],[2,1.58,0]],"ltp":1.34,"tv":340.2,"id":9168659}]}]}
{"op":"mcm","clk":"4234186194","pt":1631543041317,"mc":[{"id":"1.187595437","rc":[{"batb":[[0,1.21,62.3],[1,1.16,583.98],[2,1.01,7]],"ltp":1.34,"tv":340.2,"id":9168659}]}]}
{"op":"mcm","clk":"4234186270","pt":1631543042256,"mc":[{"id":"1.187595437","rc":[{"batb":[[1,1.2,124.6],[2,1.16,583.98]],"ltp":1.34,"tv":340.2,"id":9168659}]}]}
{"op":"mcm","clk":"4234186459","pt":1631543044350,"mc":[{"id":"1.187595437","rc":[{"batb":[[0,1.2,124.6],[1,1.16,583.98],[2,1.01,7]],"batl":[[0,1.36,62.3],[1,1.4,5],[2,1.58,659.44]],"ltp":1.34,"tv":340.2,"id":9168659}]}]}
{"op":"mcm","clk":"4234190448","pt":1631543086999,"mc":[{"id":"1.187595437","rc":[{"batb":[[1,1.01,7],[2,1.01,0]],"ltp":1.34,"tv":340.2,"id":9168659}]}]}
{"op":"mcm","clk":"4234190913","pt":1631543092321,"mc":[{"id":"1.187595437","rc":[{"batl":[[0,1.4,5],[1,1.58,659.44],[2,1.58,0]],"ltp":1.34,"tv":340.2,"id":9168659}]}]}
{"op":"mcm","clk":"4234190960","pt":1631543092842,"mc":[{"id":"1.187595437","rc":[{"batb":[[1,1.18,557.21],[2,1.01,7]],"ltp":1.34,"tv":340.2,"id":9168659}]}]}
{"op":"mcm","clk":"4234191409","pt":1631543097910,"mc":[{"id":"1.187595437","rc":[{"batl":[[0,1.39,62.3],[1,1.4,5],[2,1.58,659.44]],"ltp":1.34,"tv":340.2,"id":9168659}]}]}
{"op":"mcm","clk":"4234191608","pt":1631543100135,"mc":[{"id":"1.187595437","rc":[{"batb":[[0,1.2,186.9]],"ltp":1.34,"tv":340.2,"id":9168659}]}]}
{"op":"mcm","clk":"4234194872","pt":1631543131809,"mc":[{"id":"1.187595437","rc":[{"batb":[[1,1.01,7],[2,1.01,0]],"ltp":1.34,"tv":340.2,"id":9168659}]}]}
{"op":"mcm","clk":"4234195393","pt":1631543137074,"mc":[{"id":"1.187595437","rc":[{"batb":[[0,1.2,724.99]],"ltp":1.34,"tv":340.2,"id":9168659}]}]}
{"op":"mcm","clk":"4234196263","pt":1631543145881,"mc":[{"id":"1.187595437","rc":[{"batl":[[0,1.4,5],[1,1.58,659.44],[2,1.58,0]],"ltp":1.34,"tv":340.2,"id":9168659}]}]}
{"op":"mcm","clk":"4234196811","pt":1631543152327,"mc":[{"id":"1.187595437","rc":[{"batl":[[1,1.5,62.3],[2,1.58,659.44]],"ltp":1.34,"tv":340.2,"id":9168659}]}]}
{"op":"mcm","clk":"4234199671","pt":1631543180781,"mc":[{"id":"1.187595437","rc":[{"batb":[[0,1.01,7],[1,1.01,0]],"ltp":3.95,"tv":257.89,"id":9628279}]}]}
{"op":"mcm","clk":"4234200128","pt":1631543185672,"mc":[{"id":"1.187595437","rc":[{"batb":[[0,3.15,13.95],[1,1.01,7]],"ltp":3.95,"tv":257.89,"id":9628279},{"batb":[[0,1.31,96.77],[1,1.2,724.99],[2,1.01,7]],"ltp":1.34,"tv":340.2,"id":9168659}]}]}
{"op":"mcm","clk":"4234201213","pt":1631543196993,"mc":[{"id":"1.187595437","rc":[{"batl":[[1,1.58,659.44],[2,1.58,0]],"ltp":1.34,"tv":340.2,"id":9168659}]}]}
{"op":"mcm","clk":"4234201852","pt":1631543204189,"mc":[{"id":"1.187595437","rc":[{"batl":[[0,1.4,67.3]],"ltp":1.34,"tv":340.2,"id":9168659}]}]}
{"op":"mcm","clk":"4234202521","pt":1631543211726,"mc":[{"id":"1.187595437","rc":[{"batb":[[1,1.2,186.9]],"ltp":1.34,"tv":340.2,"id":9168659}]}]}
{"op":"mcm","clk":"4234203028","pt":1631543217048,"mc":[{"id":"1.187595437","rc":[{"batb":[[1,1.01,7],[2,1.01,0]],"ltp":1.34,"tv":340.2,"id":9168659}]}]}
{"op":"mcm","clk":"4234203121","pt":1631543218035,"mc":[{"id":"1.187595437","rc":[{"batb":[[1,1.14,618.77],[2,1.01,7]],"ltp":1.34,"tv":340.2,"id":9168659}]}]}
{"op":"mcm","clk":"4234203604","pt":1631543223265,"mc":[{"id":"1.187595437","rc":[{"batb":[[1,1.16,186.9]],"ltp":1.34,"tv":340.2,"id":9168659}]}]}
{"op":"mcm","clk":"4234203650","pt":1631543223740,"mc":[{"id":"1.187595437","rc":[{"batb":[[1,1.16,249.2]],"ltp":1.34,"tv":340.2,"id":9168659}]}]}
{"op":"mcm","clk":"4234204167","pt":1631543229168,"mc":[{"id":"1.187595437","rc":[{"batb":[[1,1.16,833.18]],"ltp":1.34,"tv":340.2,"id":9168659}]}]}
{"op":"mcm","clk":"4234204226","pt":1631543229883,"mc":[{"id":"1.187595437","rc":[{"batb":[[1,1.16,249.2]],"ltp":1.34,"tv":340.2,"id":9168659}]}]}
{"op":"mcm","clk":"4234204664","pt":1631543235068,"mc":[{"id":"1.187595437","rc":[{"batb":[[0,1.01,7],[1,1.01,0]],"ltp":3.95,"tv":257.89,"id":9628279},{"batb":[[0,1.16,249.2],[1,1.01,7],[2,1.01,0]],"ltp":1.34,"tv":340.2,"id":9168659}]}]}
{"op":"mcm","clk":"4234205171","pt":1631543239972,"mc":[{"id":"1.187595437","rc":[{"batb":[[0,3.3,13.04],[1,1.01,7]],"ltp":3.95,"tv":257.89,"id":9628279},{"batb":[[0,1.28,107.14],[1,1.16,249.2],[2,1.01,7]],"ltp":1.34,"tv":340.2,"id":9168659}]}]}
{"op":"mcm","clk":"4234205530","pt":1631543243986,"mc":[{"id":"1.187595437","rc":[{"batb":[[0,1.01,7],[1,1.01,0]],"ltp":3.95,"tv":257.89,"id":9628279},{"batb":[[0,1.16,249.2],[1,1.01,7],[2,1.01,0]],"ltp":1.34,"tv":340.2,"id":9168659}]}]}
{"op":"mcm","clk":"4234205971","pt":1631543248904,"mc":[{"id":"1.187595437","rc":[{"batb":[[0,3.4,12.5],[1,1.01,7]],"ltp":3.95,"tv":257.89,"id":9628279},{"batb":[[0,1.27,111.11],[1,1.16,249.2],[2,1.01,7]],"ltp":1.34,"tv":340.2,"id":9168659}]}]}
{"op":"mcm","clk":"4234207828","pt":1631543270433,"mc":[{"id":"1.187595437","rc":[{"trd":[[3.5,10.22]],"ltp":3.5,"tv":268.11,"id":9628279},{"trd":[[1.4,25.58]],"batl":[[0,1.4,41.72]],"ltp":1.4,"tv":365.78,"id":9168659}],"tv":633.89}]}
{"op":"mcm","clk":"4234207847","pt":1631543270644,"mc":[{"id":"1.187595437","rc":[{"batl":[[1,1.58,0]],"ltp":1.4,"tv":365.78,"id":9168659}]}]}
{"op":"mcm","clk":"4234211545","pt":1631543311464,"mc":[{"id":"1.187595437","rc":[{"trd":[[1.27,2.76]],"batb":[[0,1.16,249.2],[1,1.01,7],[2,1.01,0]],"ltp":1.27,"tv":368.54,"id":9168659}],"tv":636.65}]}
{"op":"mcm","clk":"4234211992","pt":1631543316498,"mc":[{"id":"1.187595437","rc":[{"batb":[[0,1.27,111.11],[1,1.16,249.2],[2,1.01,7]],"ltp":1.27,"tv":368.54,"id":9168659}]}]}
{"op":"mcm","clk":"4234213524","pt":1631543333412,"mc":[{"id":"1.187595437","rc":[{"batb":[[0,1.01,7],[1,1.01,0]],"ltp":3.5,"tv":268.11,"id":9628279},{"batb":[[0,1.16,249.2],[1,1.01,7],[2,1.01,0]],"ltp":1.27,"tv":368.54,"id":9168659}]}]}
{"op":"mcm","clk":"4234213969","pt":1631543338435,"mc":[{"id":"1.187595437","rc":[{"batb":[[0,3.95,10.16],[1,1.01,7]],"ltp":3.5,"tv":268.11,"id":9628279},{"batb":[[0,1.2,150],[1,1.16,249.2],[2,1.01,7]],"ltp":1.27,"tv":368.54,"id":9168659}]}]}
{"op":"mcm","clk":"4234216519","pt":1631543367869,"mc":[{"id":"1.187595437","rc":[{"batb":[[0,1.01,7],[1,1.01,0]],"ltp":3.5,"tv":268.11,"id":9628279},{"batb":[[0,1.16,249.2],[1,1.01,7],[2,1.01,0]],"ltp":1.27,"tv":368.54,"id":9168659}]}]}
{"op":"mcm","clk":"4234216869","pt":1631543371257,"mc":[{"id":"1.187595437","rc":[{"batl":[[0,1.2,7.95],[1,1.4,41.72]],"ltp":1.27,"tv":368.54,"id":9168659}]}]}
{"op":"mcm","clk":"4234216998","pt":1631543373059,"mc":[{"id":"1.187595437","rc":[{"batb":[[0,3.4,12.5],[1,1.01,7]],"ltp":3.5,"tv":268.11,"id":9628279},{"trd":[[1.2,15.9]],"batl":[[0,1.4,41.72],[1,1.4,0]],"ltp":1.2,"tv":384.44,"id":9168659}],"tv":652.55}]}
{"op":"mcm","clk":"4234217439","pt":1631543377874,"mc":[{"id":"1.187595437","rc":[{"batb":[[0,1.27,111.11],[1,1.16,249.2],[2,1.01,7]],"ltp":1.2,"tv":384.44,"id":9168659}]}]}
{"op":"mcm","clk":"4234219276","pt":1631543398602,"mc":[{"id":"1.187595437","rc":[{"batb":[[0,1.01,7],[1,1.01,0]],"ltp":3.5,"tv":268.11,"id":9628279},{"batb":[[0,1.16,249.2],[1,1.01,7],[2,1.01,0]],"ltp":1.2,"tv":384.44,"id":9168659}]}]}
{"op":"mcm","clk":"4234219525","pt":1631543401731,"mc":[{"id":"1.187595437","rc":[{"batb":[[0,1.01,7],[1,1.01,0]],"ltp":1.2,"tv":384.44,"id":9168659}]}]}
{"op":"mcm","clk":"4234219662","pt":1631543403507,"mc":[{"id":"1.187595437","rc":[{"batb":[[0,3.95,10.16],[1,1.01,7]],"ltp":3.5,"tv":268.11,"id":9628279},{"batb":[[0,1.2,150],[1,1.01,7]],"ltp":1.2,"tv":384.44,"id":9168659}]}]}
{"op":"mcm","clk":"4234220178","pt":1631543408524,"mc":[{"id":"1.187595437","rc":[{"batb":[[0,1.22,50],[1,1.21,50],[2,1.2,150]],"ltp":1.2,"tv":384.44,"id":9168659}]}]}
{"op":"mcm","clk":"4234220288","pt":1631543409519,"mc":[{"id":"1.187595437","rc":[{"batb":[[0,1.22,250]],"ltp":1.2,"tv":384.44,"id":9168659}]}]}
{"op":"mcm","clk":"4234220340","pt":1631543410143,"mc":[{"id":"1.187595437","rc":[{"batb":[[0,1.21,50],[1,1.2,150],[2,1.01,7]],"ltp":1.2,"tv":384.44,"id":9168659}]}]}
{"op":"mcm","clk":"4234220409","pt":1631543410818,"mc":[{"id":"1.187595437","rc":[{"batb":[[0,1.2,150],[1,1.01,7],[2,1.01,0]],"ltp":1.2,"tv":384.44,"id":9168659}]}]}
{"op":"mcm","clk":"4234221133","pt":1631543418341,"mc":[{"id":"1.187595437","rc":[{"batb":[[1,1.16,200],[2,1.01,7]],"ltp":1.2,"tv":384.44,"id":9168659}]}]}
{"op":"mcm","clk":"4234221162","pt":1631543418652,"mc":[{"id":"1.187595437","rc":[{"batb":[[1,1.16,250]],"ltp":1.2,"tv":384.44,"id":9168659}]}]}
{"op":"mcm","clk":"4234222185","pt":1631543429305,"mc":[{"id":"1.187595437","rc":[{"batb":[[0,1.01,7],[1,1.01,0]],"ltp":3.5,"tv":268.11,"id":9628279},{"batb":[[0,1.16,250],[1,1.01,7],[2,1.01,0]],"ltp":1.2,"tv":384.44,"id":9168659}]}]}
{"op":"mcm","clk":"4234222777","pt":1631543434211,"mc":[{"id":"1.187595437","rc":[{"batb":[[0,4.3,10],[1,1.01,7]],"ltp":3.5,"tv":268.11,"id":9628279},{"batb":[[0,1.18,166.66],[1,1.16,250],[2,1.01,7]],"ltp":1.2,"tv":384.44,"id":9168659}]}]}
{"op":"mcm","clk":"4234224909","pt":1631543446423,"mc":[{"id":"1.187595437","rc":[{"batb":[[1,1.01,7],[2,1.01,0]],"ltp":1.2,"tv":384.44,"id":9168659}]}]}
{"op":"mcm","clk":"4234225903","pt":1631543453624,"mc":[{"id":"1.187595437","rc":[{"batb":[[1,1.14,100],[2,1.01,7]],"ltp":1.2,"tv":384.44,"id":9168659}]}]}
{"op":"mcm","clk":"4234225920","pt":1631543453727,"mc":[{"id":"1.187595437","rc":[{"batb":[[1,1.14,150]],"ltp":1.2,"tv":384.44,"id":9168659}]}]}
{"op":"mcm","clk":"4234226101","pt":1631543454720,"mc":[{"id":"1.187595437","rc":[{"batb":[[1,1.14,200]],"ltp":1.2,"tv":384.44,"id":9168659}]}]}
{"op":"mcm","clk":"4234227080","pt":1631543461770,"mc":[{"id":"1.187595437","rc":[{"batb":[[0,1.01,7],[1,1.01,0]],"ltp":3.5,"tv":268.11,"id":9628279},{"batb":[[0,1.14,200],[1,1.01,7],[2,1.01,0]],"ltp":1.2,"tv":384.44,"id":9168659}]}]}
{"op":"mcm","clk":"4234227708","pt":1631543467168,"mc":[{"id":"1.187595437","rc":[{"batb":[[0,3.95,10.16],[1,1.01,7]],"ltp":3.5,"tv":268.11,"id":9628279},{"batb":[[0,1.2,150]],"ltp":1.2,"tv":384.44,"id":9168659}]}]}
{"op":"mcm","clk":"4234227774","pt":1631543467675,"mc":[{"id":"1.187595437","rc":[{"batb":[[1,1.14,618.77],[2,1.01,7]],"batl":[[1,1.55,700.17]],"ltp":1.2,"tv":384.44,"id":9168659}]}]}
{"op":"mcm","clk":"4234228194","pt":1631543471253,"mc":[{"id":"1.187595437","rc":[{"batb":[[1,1.16,200],[2,1.14,618.77]],"ltp":1.2,"tv":384.44,"id":9168659}]}]}
{"op":"mcm","clk":"4234230914","pt":1631543492898,"mc":[{"id":"1.187595437","rc":[{"batb":[[0,1.01,7],[1,1.01,0]],"ltp":3.5,"tv":268.11,"id":9628279},{"batb":[[0,1.16,200],[1,1.01,7],[2,1.14,0]],"batl":[[1,1.55,0]],"ltp":1.2,"tv":384.44,"id":9168659}]}]}
{"op":"mcm","clk":"4234231449","pt":1631543496721,"mc":[{"id":"1.187595437","rc":[{"batb":[[0,1.01,7],[1,1.01,0]],"ltp":1.2,"tv":384.44,"id":9168659}]}]}
{"op":"mcm","clk":"4234231584","pt":1631543497824,"mc":[{"id":"1.187595437","rc":[{"batb":[[0,4.3,10],[1,1.01,7]],"ltp":3.5,"tv":268.11,"id":9628279},{"batb":[[0,1.18,166.66],[1,1.01,7]],"ltp":1.2,"tv":384.44,"id":9168659}]}]}
{"op":"mcm","clk":"4234231736","pt":1631543498876,"mc":[{"id":"1.187595437","rc":[{"batb":[[1,1.1,733.06],[2,1.01,7]],"batl":[[1,1.48,795.63]],"ltp":1.2,"tv":384.44,"id":9168659}]}]}
{"op":"mcm","clk":"4234232406","pt":1631543504209,"mc":[{"id":"1.187595437","rc":[{"batb":[[1,1.12,200],[2,1.1,733.06]],"batl":[[0,1.48,795.63],[1,1.48,0]],"ltp":1.2,"tv":384.44,"id":9168659}]}]}
{"op":"mcm","clk":"4234233520","pt":1631543511840,"mc":[{"id":"1.187595437","rc":[{"batl":[[0,1.3,41.72],[1,1.48,795.63]],"ltp":1.2,"tv":384.44,"id":9168659}]}]}
{"op":"mcm","clk":"4234240958","pt":1631543572126,"mc":[{"id":"1.187595437","rc":[{"batb":[[0,1.01,7],[1,1.01,0]],"ltp":3.5,"tv":268.11,"id":9628279},{"batb":[[0,1.12,200],[1,1.1,733.06],[2,1.01,7]],"ltp":1.2,"tv":384.44,"id":9168659}]}]}
{"op":"mcm","clk":"4234241123","pt":1631543573630,"mc":[{"id":"1.187595437","rc":[{"batb":[[1,1.01,7],[2,1.01,0]],"ltp":1.2,"tv":384.44,"id":9168659}]}]}
{"op":"mcm","clk":"4234241537","pt":1631543577116,"mc":[{"id":"1.187595437","rc":[{"batb":[[0,5.3,10],[1,1.01,7]],"ltp":3.5,"tv":268.11,"id":9628279},{"batb":[[0,1.12,249.99]],"ltp":1.2,"tv":384.44,"id":9168659}]}]}
{"op":"mcm","clk":"4234241796","pt":1631543579252,"mc":[{"id":"1.187595437","rc":[{"batb":[[1,1.08,811.87],[2,1.01,7]],"ltp":1.2,"tv":384.44,"id":9168659}]}]}
{"op":"mcm","clk":"4234242342","pt":1631543583631,"mc":[{"id":"1.187595437","rc":[{"batb":[[1,1.1,150],[2,1.08,811.87]],"ltp":1.2,"tv":384.44,"id":9168659}]}]}
{"op":"mcm","clk":"4234242359","pt":1631543583742,"mc":[{"id":"1.187595437","rc":[{"batb":[[1,1.1,200]],"ltp":1.2,"tv":384.44,"id":9168659}]}]}
{"op":"mcm","clk":"4234243978","pt":1631543595174,"mc":[{"id":"1.187595437","rc":[{"batb":[[0,1.01,7],[1,1.01,0]],"ltp":3.5,"tv":268.11,"id":9628279},{"batb":[[0,1.1,200],[1,1.08,811.87],[2,1.01,7]],"ltp":1.2,"tv":384.44,"id":9168659}]}]}
{"op":"mcm","clk":"4234244204","pt":1631543596861,"mc":[{"id":"1.187595437","rc":[{"batb":[[1,1.01,7],[2,1.01,0]],"batl":[[1,1.48,0]],"ltp":1.2,"tv":384.44,"id":9168659}]}]}
{"op":"mcm","clk":"4234244588","pt":1631543600138,"mc":[{"id":"1.187595437","rc":[{"batb":[[0,6,10],[1,1.01,7]],"ltp":3.5,"tv":268.11,"id":9628279},{"batb":[[1,1.08,374.99],[2,1.01,7]],"ltp":1.2,"tv":384.44,"id":9168659}]}]}
{"op":"mcm","clk":"4234244673","pt":1631543600768,"mc":[{"id":"1.187595437","rc":[{"batb":[[0,1.08,374.99],[1,1.01,7],[2,1.01,0]],"ltp":1.2,"tv":384.44,"id":9168659}]}]}
{"op":"mcm","clk":"4234244908","pt":1631543602666,"mc":[{"id":"1.187595437","rc":[{"batb":[[1,1.06,949.57],[2,1.01,7]],"batl":[[0,1.4,953.33]],"ltp":1.2,"tv":384.44,"id":9168659}]}]}
{"op":"mcm","clk":"4234245081","pt":1631543603985,"mc":[{"id":"1.187595437","rc":[{"batb":[[1,1.01,7],[2,1.01,0]],"ltp":1.2,"tv":384.44,"id":9168659}]}]}
{"op":"mcm","clk":"4234245802","pt":1631543608476,"mc":[{"id":"1.187595437","rc":[{"batb":[[1,1.07,100],[2,1.01,7]],"ltp":1.2,"tv":384.44,"id":9168659}]}]}
{"op":"mcm","clk":"4234245952","pt":1631543609580,"mc":[{"id":"1.187595437","rc":[{"batb":[[1,1.07,250],[2,1.05,1084.16]],"ltp":1.2,"tv":384.44,"id":9168659}]}]}
{"op":"mcm","clk":"4234245969","pt":1631543609685,"mc":[{"id":"1.187595437","rc":[{"batb":[[1,1.07,300]],"ltp":1.2,"tv":384.44,"id":9168659}]}]}
{"op":"mcm","clk":"4234246196","pt":1631543611163,"mc":[{"id":"1.187595437","rc":[{"batl":[[0,1.25,41.72],[1,1.4,953.33]],"ltp":1.2,"tv":384.44,"id":9168659}]}]}
{"op":"mcm","clk":"4234246561","pt":1631543613949,"mc":[{"id":"1.187595437","rc":[{"batb":[[2,1.01,7]],"ltp":1.2,"tv":384.44,"id":9168659}]}]}
{"op":"mcm","clk":"4234247317","pt":1631543619693,"mc":[{"id":"1.187595437","rc":[{"batb":[[2,1.06,949.57]],"ltp":1.2,"tv":384.44,"id":9168659}]}]}
{"op":"mcm","clk":"4234249039","pt":1631543633303,"mc":[{"id":"1.187595437","rc":[{"batb":[[0,1.01,7],[1,1.01,0]],"ltp":3.5,"tv":268.11,"id":9628279},{"batb":[[0,1.07,300],[1,1.01,7],[2,1.06,0]],"ltp":1.2,"tv":384.44,"id":9168659}]}]}
{"op":"mcm","clk":"4234249203","pt":1631543634769,"mc":[{"id":"1.187595437","rc":[{"batb":[[0,1.01,7],[1,1.01,0]],"ltp":1.2,"tv":384.44,"id":9168659}]}]}
{"op":"mcm","clk":"4234249577","pt":1631543638177,"mc":[{"id":"1.187595437","rc":[{"batb":[[0,7.6,10],[1,1.01,7]],"ltp":3.5,"tv":268.11,"id":9628279},{"batb":[[0,1.05,599.99],[1,1.01,7]],"ltp":1.2,"tv":384.44,"id":9168659}]}]}
{"op":"mcm","clk":"4234249667","pt":1631543638911,"mc":[{"id":"1.187595437","rc":[{"batb":[[1,1.04,1251.37],[2,1.01,7]],"ltp":1.2,"tv":384.44,"id":9168659}]}]}
{"op":"mcm","clk":"4234249914","pt":1631543640575,"mc":[{"id":"1.187595437","rc":[{"batb":[[0,1.05,649.99]],"ltp":1.2,"tv":384.44,"id":9168659}]}]}
{"op":"mcm","clk":"4234250051","pt":1631543641470,"mc":[{"id":"1.187595437","rc":[{"batb":[[0,1.05,799.99]],"ltp":1.2,"tv":384.44,"id":9168659}]}]}
{"op":"mcm","clk":"4234250086","pt":1631543641681,"mc":[{"id":"1.187595437","rc":[{"batb":[[0,1.05,849.99]],"ltp":1.2,"tv":384.44,"id":9168659}]}]}
{"op":"mcm","clk":"4234256327","pt":1631543694203,"mc":[{"id":"1.187595437","rc":[{"batb":[[0,1.01,7],[1,1.01,0]],"ltp":3.5,"tv":268.11,"id":9628279},{"batb":[[0,1.05,250]],"ltp":1.2,"tv":384.44,"id":9168659}]}]}
{"op":"mcm","clk":"4234256513","pt":1631543695802,"mc":[{"id":"1.187595437","rc":[{"batb":[[1,1.01,7],[2,1.01,0]],"ltp":1.2,"tv":384.44,"id":9168659}]}]}
{"op":"mcm","clk":"4234256945","pt":1631543699084,"mc":[{"id":"1.187595437","rc":[{"batb":[[0,6,10],[1,1.01,7]],"ltp":3.5,"tv":268.11,"id":9628279},{"batb":[[0,1.08,374.99],[1,1.05,250],[2,1.01,7]],"ltp":1.2,"tv":384.44,"id":9168659}]}]}
{"op":"mcm","clk":"4234257118","pt":1631543700610,"mc":[{"id":"1.187595437","rc":[{"trd":[[1.08,60]],"batb":[[0,1.08,344.99]],"ltp":1.08,"tv":444.44,"id":9168659}],"tv":712.55}]}
{"op":"mcm","clk":"4234257246","pt":1631543701403,"mc":[{"id":"1.187595437","rc":[{"batb":[[0,1.05,250],[1,1.04,1298.58]],"ltp":1.08,"tv":444.44,"id":9168659}]}]}
{"op":"mcm","clk":"4234257597","pt":1631543703992,"mc":[{"id":"1.187595437","rc":[{"batb":[[1,1.01,7],[2,1.01,0]],"ltp":1.08,"tv":444.44,"id":9168659}]}]}
{"op":"mcm","clk":"4234257828","pt":1631543705789,"mc":[{"id":"1.187595437","rc":[{"batb":[[0,1.08,374.99],[1,1.05,250],[2,1.01,7]],"ltp":1.08,"tv":444.44,"id":9168659}]}]}
{"op":"mcm","clk":"4234258405","pt":1631543710199,"mc":[{"id":"1.187595437","rc":[{"batb":[[1,1.06,949.57],[2,1.05,250]],"ltp":1.08,"tv":444.44,"id":9168659}]}]}
{"op":"mcm","clk":"4234258563","pt":1631543711503,"mc":[{"id":"1.187595437","rc":[{"batb":[[1,1.07,200],[2,1.06,949.57]],"ltp":1.08,"tv":444.44,"id":9168659}]}]}
{"op":"mcm","clk":"4234258615","pt":1631543711915,"mc":[{"id":"1.187595437","rc":[{"batb":[[1,1.07,300]],"ltp":1.08,"tv":444.44,"id":9168659}]}]}
{"op":"mcm","clk":"4234259889","pt":1631543722545,"mc":[{"id":"1.187595437","rc":[{"batb":[[0,1.01,7],[1,1.01,0]],"ltp":3.5,"tv":268.11,"id":9628279},{"batb":[[0,1.07,300],[1,1.06,949.57],[2,1.05,250]],"ltp":1.08,"tv":444.44,"id":9168659}]}]}
{"op":"mcm","clk":"4234259965","pt":1631543723130,"mc":[{"id":"1.187595437","rc":[{"batb":[[1,1.05,250],[2,1.01,7]],"ltp":1.08,"tv":444.44,"id":9168659}]}]}
{"op":"mcm","clk":"4234260233","pt":1631543725213,"mc":[{"id":"1.187595437","rc":[{"batb":[[0,1.01,7],[1,1.05,0],[2,1.01,0]],"batl":[[0,1.4,953.33],[1,1.4,0]],"ltp":1.08,"tv":444.44,"id":9168659}]}]}
{"op":"mcm","clk":"4234260514","pt":1631543727408,"mc":[{"id":"1.187595437","rc":[{"batb":[[0,7.6,10],[1,1.01,7]],"ltp":3.5,"tv":268.11,"id":9628279},{"batb":[[0,1.05,599.99],[1,1.01,7]],"ltp":1.08,"tv":444.44,"id":9168659}]}]}
{"op":"mcm","clk":"4234260773","pt":1631543729442,"mc":[{"id":"1.187595437","rc":[{"batb":[[1,1.03,1556.77],[2,1.01,7]],"ltp":1.08,"tv":444.44,"id":9168659}]}]}
{"op":"mcm","clk":"4234261141","pt":1631543732431,"mc":[{"id":"1.187595437","rc":[{"batb":[[1,1.04,50],[2,1.03,1556.77]],"ltp":1.08,"tv":444.44,"id":9168659}]}]}
{"op":"mcm","clk":"4234261222","pt":1631543733008,"mc":[{"id":"1.187595437","rc":[{"batb":[[1,1.04,200]],"ltp":1.08,"tv":444.44,"id":9168659}]}]}
{"op":"mcm","clk":"4234261396","pt":1631543734529,"mc":[{"id":"1.187595437","rc":[{"batb":[[2,1.03,1656.77]],"ltp":1.08,"tv":444.44,"id":9168659}]}]}
{"op":"mcm","clk":"4234261507","pt":1631543735423,"mc":[{"id":"1.187595437","rc":[{"batb":[[2,1.03,1706.77]],"ltp":1.08,"tv":444.44,"id":9168659}]}]}
{"op":"mcm","clk":"4234261744","pt":1631543737357,"mc":[{"id":"1.187595437","rc":[{"batl":[[0,1.15,41.72],[1,1.4,953.33]],"ltp":1.08,"tv":444.44,"id":9168659}]}]}
{"op":"mcm","clk":"4234262985","pt":1631543746833,"mc":[{"id":"1.187595437","rc":[{"batb":[[0,1.09,11.11],[1,1.05,599.99],[2,1.04,200]],"ltp":1.08,"tv":444.44,"id":9168659}]}]}
{"op":"mcm","clk":"4234264264","pt":1631543757569,"mc":[{"id":"1.187595437","rc":[{"batb":[[0,1.01,7],[1,1.01,0]],"ltp":3.5,"tv":268.11,"id":9628279},{"batb":[[1,1.04,200],[2,1.03,1706.77]],"ltp":1.08,"tv":444.44,"id":9168659}]}]}
{"op":"mcm","clk":"4234264947","pt":1631543762471,"mc":[{"id":"1.187595437","rc":[{"batb":[[0,8.6,10],[1,1.01,7]],"ltp":3.5,"tv":268.11,"id":9628279},{"batb":[[1,1.04,949.99]],"ltp":1.08,"tv":444.44,"id":9168659}]}]}
{"op":"mcm","clk":"4234265169","pt":1631543764158,"mc":[{"id":"1.187595437","rc":[{"batb":[[0,1.04,949.99],[1,1.03,1706.77],[2,1.02,100]],"ltp":1.08,"tv":444.44,"id":9168659}]}]}
{"op":"mcm","clk":"4234265625","pt":1631543767475,"mc":[{"id":"1.187595437","rc":[{"batb":[[1,1.03,150]],"batl":[[1,1.4,0]],"ltp":1.08,"tv":444.44,"id":9168659}]}]}
{"op":"mcm","clk":"4234266040","pt":1631543770585,"mc":[{"id":"1.187595437","rc":[{"batb":[[0,1.04,749.99]],"ltp":1.08,"tv":444.44,"id":9168659}]}]}
{"op":"mcm","clk":"4234266551","pt":1631543774160,"mc":[{"id":"1.187595437","rc":[{"batb":[[2,1.02,2277.23]],"batl":[[0,1.33,1136.66]],"ltp":1.08,"tv":444.44,"id":9168659}]}]}
{"op":"mcm","clk":"4234267008","pt":1631543777783,"mc":[{"id":"1.187595437","rc":[{"batl":[[0,1.13,41.72],[1,1.33,1136.66]],"ltp":1.08,"tv":444.44,"id":9168659}]}]}
{"op":"mcm","clk":"4234268882","pt":1631543792304,"mc":[{"id":"1.187595437","rc":[{"batb":[[0,1.01,7],[1,1.01,0]],"ltp":3.5,"tv":268.11,"id":9628279},{"batb":[[0,1.03,150],[1,1.02,2277.23],[2,1.01,307]],"ltp":1.08,"tv":444.44,"id":9168659}]}]}
{"op":"mcm","clk":"4234269081","pt":1631543793724,"mc":[{"id":"1.187595437","rc":[{"batb":[[1,1.02,100]],"ltp":1.08,"tv":444.44,"id":9168659}]}]}
{"op":"mcm","clk":"4234269538","pt":1631543797299,"mc":[{"id":"1.187595437","rc":[{"batb":[[0,7.6,10],[1,1.01,7]],"ltp":3.5,"tv":268.11,"id":9628279},{"batb":[[0,1.05,599.99],[1,1.03,150],[2,1.02,100]],"ltp":1.08,"tv":444.44,"id":9168659}]}]}
{"op":"mcm","clk":"4234269873","pt":1631543799830,"mc":[{"id":"1.187595437","rc":[{"batb":[[1,1.03,1706.77]],"ltp":1.08,"tv":444.44,"id":9168659}]}]}
{"op":"mcm","clk":"4234271720","pt":1631543813853,"mc":[{"id":"1.187595437","rc":[{"batb":[[0,1.01,7],[1,1.01,0]],"ltp":3.5,"tv":268.11,"id":9628279},{"batb":[[0,1.03,1706.77],[1,1.02,100],[2,1.01,307]],"ltp":1.08,"tv":444.44,"id":9168659}]}]}
{"op":"mcm","clk":"4234271848","pt":1631543814843,"mc":[{"id":"1.187595437","rc":[{"batb":[[0,1.03,150]],"ltp":1.08,"tv":444.44,"id":9168659}]}]}
{"op":"mcm","clk":"4234272395","pt":1631543818730,"mc":[{"id":"1.187595437","rc":[{"batb":[[0,8.6,10],[1,1.01,7]],"ltp":3.5,"tv":268.11,"id":9628279},{"batb":[[0,1.04,749.99],[1,1.03,150],[2,1.02,100]],"ltp":1.08,"tv":444.44,"id":9168659}]}]}
{"op":"mcm","clk":"4234272592","pt":1631543820251,"mc":[{"id":"1.187595437","rc":[{"batb":[[2,1.02,2277.23]],"ltp":1.08,"tv":444.44,"id":9168659}]}]}
{"op":"mcm","clk":"4234275207","pt":1631543842157,"mc":[{"id":"1.187595437","rc":[{"batb":[[2,1.02,100]],"ltp":1.08,"tv":444.44,"id":9168659}]}]}
{"op":"mcm","clk":"4234275878","pt":1631543848472,"mc":[{"id":"1.187595437","rc":[{"batb":[[1,1.03,1706.77]],"ltp":1.08,"tv":444.44,"id":9168659}]}]}
{"op":"mcm","clk":"4234277635","pt":1631543864321,"mc":[{"id":"1.187595437","rc":[{"batb":[[1,1.03,150]],"ltp":1.08,"tv":444.44,"id":9168659}]}]}
{"op":"mcm","clk":"4234277956","pt":1631543867204,"mc":[{"id":"1.187595437","rc":[{"batb":[[0,1.01,7],[1,1.01,0]],"ltp":3.5,"tv":268.11,"id":9628279},{"batb":[[0,1.03,150],[1,1.02,100],[2,1.01,307]],"ltp":1.08,"tv":444.44,"id":9168659}]}]}
{"op":"mcm","clk":"4234278580","pt":1631543872223,"mc":[{"id":"1.187595437","rc":[{"batb":[[0,7.6,10],[1,1.01,7]],"ltp":3.5,"tv":268.11,"id":9628279},{"batb":[[0,1.05,599.99],[1,1.03,150],[2,1.02,100]],"ltp":1.08,"tv":444.44,"id":9168659}]}]}
{"op":"mcm","clk":"4234280613","pt":1631543889085,"mc":[{"id":"1.187595437","rc":[{"batb":[[0,1.01,7],[1,1.01,0]],"ltp":3.5,"tv":268.11,"id":9628279},{"batb":[[0,1.03,150],[1,1.02,100],[2,1.01,307]],"ltp":1.08,"tv":444.44,"id":9168659}]}]}
{"op":"mcm","clk":"4234281188","pt":1631543894055,"mc":[{"id":"1.187595437","rc":[{"batb":[[0,7,10],[1,1.01,7]],"ltp":3.5,"tv":268.11,"id":9628279},{"batb":[[0,1.06,499.99],[1,1.03,150],[2,1.02,100]],"ltp":1.08,"tv":444.44,"id":9168659}]}]}
{"op":"mcm","clk":"4234281393","pt":1631543895852,"mc":[{"id":"1.187595437","rc":[{"batb":[[1,1.04,1251.37],[2,1.03,150]],"ltp":1.08,"tv":444.44,"id":9168659}]}]}
{"op":"mcm","clk":"4234281749","pt":1631543899001,"mc":[{"id":"1.187595437","rc":[{"batl":[[0,1.33,1136.66],[1,1.33,0]],"ltp":1.08,"tv":444.44,"id":9168659}]}]}
{"op":"mcm","clk":"4234282398","pt":1631543904174,"mc":[{"id":"1.187595437","rc":[{"batb":[[0,1.01,7],[1,1.01,0]],"ltp":3.5,"tv":268.11,"id":9628279},{"batb":[[0,1.04,1251.37],[1,1.03,150],[2,1.02,100]],"ltp":1.08,"tv":444.44,"id":9168659}]}]}
{"op":"mcm","clk":"4234282569","pt":1631543905489,"mc":[{"id":"1.187595437","rc":[{"batb":[[0,1.03,150],[1,1.02,100],[2,1.01,307]],"batl":[[0,1.16,41.72],[1,1.33,1136.66]],"ltp":1.08,"tv":444.44,"id":9168659}]}]}
{"op":"mcm","clk":"4234283019","pt":1631543909179,"mc":[{"id":"1.187595437","rc":[{"batb":[[0,8.6,10],[1,1.01,7]],"ltp":3.5,"tv":268.11,"id":9628279},{"batb":[[0,1.03,1149.99]],"ltp":1.08,"tv":444.44,"id":9168659}]}]}
{"op":"mcm","clk":"4234283222","pt":1631543910919,"mc":[{"id":"1.187595437","rc":[{"batb":[[1,1.02,2277.23]],"ltp":1.08,"tv":444.44,"id":9168659}]}]}
{"op":"mcm","clk":"4234285150","pt":1631543927712,"mc":[{"id":"1.187595437","rc":[{"batb":[[0,1.01,7],[1,1.01,0]],"ltp":3.5,"tv":268.11,"id":9628279},{"batb":[[0,1.03,150]],"ltp":1.08,"tv":444.44,"id":9168659}]}]}
{"op":"mcm","clk":"4234285313","pt":1631543928913,"mc":[{"id":"1.187595437","rc":[{"batb":[[1,1.02,100]],"ltp":1.08,"tv":444.44,"id":9168659}]}]}
{"op":"mcm","clk":"4234285737","pt":1631543932633,"mc":[{"id":"1.187595437","rc":[{"batb":[[0,11,10],[1,1.01,7]],"ltp":3.5,"tv":268.11,"id":9628279}]}]}
{"op":"mcm","clk":"4234286034","pt":1631543934932,"mc":[{"id":"1.187595437","rc":[{"trd":[[1.03,6]],"batb":[[0,1.03,147],[2,1.01,4273]],"ltp":1.03,"tv":450.44,"id":9168659}],"tv":718.55}]}
{"op":"mcm","clk":"4234286277","pt":1631543937129,"mc":[{"id":"1.187595437","rc":[{"batb":[[0,1.02,100],[1,1.01,4273],[2,1.01,0]],"ltp":1.03,"tv":450.44,"id":9168659}]}]}
{"op":"mcm","clk":"4234287053","pt":1631543943543,"mc":[{"id":"1.187595437","rc":[{"batb":[[0,1.02,250]],"ltp":1.03,"tv":450.44,"id":9168659}]}]}
{"op":"mcm","clk":"4234292909","pt":1631543996442,"mc":[{"id":"1.187595437","rc":[{"batl":[[0,1.33,1136.66],[1,1.33,0]],"ltp":1.03,"tv":450.44,"id":9168659}]}]}
{"op":"mcm","clk":"4234296450","pt":1631544032472,"mc":[{"id":"1.187595437","rc":[{"batb":[[0,1.02,550]],"ltp":1.03,"tv":450.44,"id":9168659}]}]}
{"op":"mcm","clk":"4234296472","pt":1631544032681,"mc":[{"id":"1.187595437","rc":[{"batb":[[0,1.02,600]],"ltp":1.03,"tv":450.44,"id":9168659}]}]}
{"op":"mcm","clk":"4234297018","pt":1631544037960,"mc":[{"id":"1.187595437","rc":[{"batb":[[1,1.01,307]],"ltp":1.03,"tv":450.44,"id":9168659}]}]}
{"op":"mcm","clk":"4234297620","pt":1631544044305,"mc":[{"id":"1.187595437","rc":[{"batl":[[0,170,37.48]],"ltp":3.5,"tv":268.11,"id":9628279}]}]}
{"op":"mcm","clk":"4234298059","pt":1631544048480,"mc":[{"id":"1.187595437","rc":[{"batb":[[0,1.01,7],[1,1.01,0]],"ltp":3.5,"tv":268.11,"id":9628279}]}]}
{"op":"mcm","clk":"4234298589","pt":1631544053397,"mc":[{"id":"1.187595437","rc":[{"batb":[[0,10,10],[1,1.01,7]],"ltp":3.5,"tv":268.11,"id":9628279},{"batb":[[0,1.02,2099.99]],"ltp":1.03,"tv":450.44,"id":9168659}]}]}
{"op":"mcm","clk":"4234298775","pt":1631544055011,"mc":[{"id":"1.187595437","rc":[{"batb":[[1,1.01,4460.07]],"ltp":1.03,"tv":450.44,"id":9168659}]}]}
{"op":"mcm","clk":"4234302565","pt":1631544091665,"mc":[{"id":"1.187595437","rc":[{"batb":[[0,1.01,7],[1,1.01,0]],"ltp":3.5,"tv":268.11,"id":9628279},{"batb":[[0,1.02,600]],"ltp":1.03,"tv":450.44,"id":9168659}]}]}
{"op":"mcm","clk":"4234302675","pt":1631544092657,"mc":[{"id":"1.187595437","rc":[{"batb":[[1,1.01,307]],"ltp":1.03,"tv":450.44,"id":9168659}]}]}
{"op":"mcm","clk":"4234303100","pt":1631544096682,"mc":[{"id":"1.187595437","rc":[{"batb":[[0,8.6,10],[1,1.01,7]],"ltp":3.5,"tv":268.11,"id":9628279},{"batb":[[0,1.04,749.99],[1,1.02,600],[2,1.01,307]],"ltp":1.03,"tv":450.44,"id":9168659}]}]}
{"op":"mcm","clk":"4234303331","pt":1631544098880,"mc":[{"id":"1.187595437","rc":[{"batb":[[1,1.02,2777.23]],"ltp":1.03,"tv":450.44,"id":9168659}]}]}
{"op":"mcm","clk":"4234305054","pt":1631544116908,"mc":[{"id":"1.187595437","rc":[{"batb":[[0,1.01,7],[1,1.01,0]],"ltp":3.5,"tv":268.11,"id":9628279},{"batb":[[0,1.02,2777.23],[1,1.01,307],[2,1.01,0]],"ltp":1.03,"tv":450.44,"id":9168659}]}]}
{"op":"mcm","clk":"4234305170","pt":1631544118167,"mc":[{"id":"1.187595437","rc":[{"batb":[[0,1.02,600]],"ltp":1.03,"tv":450.44,"id":9168659}]}]}
{"op":"mcm","clk":"4234305620","pt":1631544121881,"mc":[{"id":"1.187595437","rc":[{"batb":[[0,9.6,10],[1,1.01,7]],"ltp":3.5,"tv":268.11,"id":9628279},{"batb":[[0,1.03,999.99],[1,1.02,600],[2,1.01,307]],"ltp":1.03,"tv":450.44,"id":9168659}]}]}
{"op":"mcm","clk":"4234305884","pt":1631544124009,"mc":[{"id":"1.187595437","rc":[{"batb":[[2,1.01,4460.07]],"ltp":1.03,"tv":450.44,"id":9168659}]}]}
{"op":"mcm","clk":"4234309004","pt":1631544154424,"mc":[{"id":"1.187595437","rc":[{"batb":[[0,1.01,7],[1,1.01,0]],"ltp":3.5,"tv":268.11,"id":9628279},{"batb":[[0,1.02,600],[1,1.01,4460.07],[2,1.01,0]],"ltp":1.03,"tv":450.44,"id":9168659}]}]}
{"op":"mcm","clk":"4234309116","pt":1631544155523,"mc":[{"id":"1.187595437","rc":[{"batb":[[1,1.01,307]],"ltp":1.03,"tv":450.44,"id":9168659}]}]}
{"op":"mcm","clk":"4234309473","pt":1631544159305,"mc":[{"id":"1.187595437","rc":[{"batb":[[0,8,10],[1,1.01,7]],"ltp":3.5,"tv":268.11,"id":9628279},{"batb":[[0,1.04,749.99],[1,1.02,600],[2,1.01,307]],"ltp":1.03,"tv":450.44,"id":9168659}]}]}
{"op":"mcm","clk":"4234309675","pt":1631544161133,"mc":[{"id":"1.187595437","rc":[{"batb":[[1,1.02,2777.23]],"ltp":1.03,"tv":450.44,"id":9168659}]}]}
{"op":"mcm","clk":"4234312475","pt":1631544189772,"mc":[{"id":"1.187595437","rc":[{"batb":[[0,1.01,7],[1,1.01,0]],"ltp":3.5,"tv":268.11,"id":9628279},{"batb":[[0,1.02,2777.23],[1,1.01,307],[2,1.01,0]],"ltp":1.03,"tv":450.44,"id":9168659}]}]}
{"op":"mcm","clk":"4234312976","pt":1631544194684,"mc":[{"id":"1.187595437","rc":[{"batb":[[0,9.6,10],[1,1.01,7]],"ltp":3.5,"tv":268.11,"id":9628279},{"batb":[[0,1.03,999.99],[1,1.02,2777.23],[2,1.01,307]],"ltp":1.03,"tv":450.44,"id":9168659}]}]}
{"op":"mcm","clk":"4234318957","pt":1631544253270,"mc":[{"id":"1.187595437","rc":[{"batb":[[0,1.01,7],[1,1.01,0]],"ltp":3.5,"tv":268.11,"id":9628279},{"batb":[[0,1.02,2777.23],[1,1.01,307],[2,1.01,0]],"ltp":1.03,"tv":450.44,"id":9168659}]}]}
{"op":"mcm","clk":"4234319041","pt":1631544253948,"mc":[{"id":"1.187595437","rc":[{"batb":[[0,1.02,600]],"ltp":1.03,"tv":450.44,"id":9168659}]}]}
{"op":"mcm","clk":"4234320193","pt":1631544264357,"mc":[{"id":"1.187595437","rc":[{"batb":[[0,1.02,2777.23]],"ltp":1.03,"tv":450.44,"id":9168659}]}]}
{"op":"mcm","clk":"4234320272","pt":1631544264985,"mc":[{"id":"1.187595437","rc":[{"batb":[[0,1.02,600]],"ltp":1.03,"tv":450.44,"id":9168659}]}]}
{"op":"mcm","clk":"4234320594","pt":1631544268348,"mc":[{"id":"1.187595437","rc":[{"batb":[[0,12,10],[1,1.01,7]],"ltp":3.5,"tv":268.11,"id":9628279}]}]}
{"op":"mcm","clk":"4234320617","pt":1631544268654,"mc":[{"id":"1.187595437","rc":[{"batb":[[0,1.01,7],[1,1.01,0]],"ltp":3.5,"tv":268.11,"id":9628279}]}]}
{"op":"mcm","clk":"4234320784","pt":1631544270476,"mc":[{"id":"1.187595437","rc":[{"batb":[[0,1.03,999.99],[1,1.02,600],[2,1.01,307]],"ltp":1.03,"tv":450.44,"id":9168659}]}]}
{"op":"mcm","clk":"4234320812","pt":1631544270790,"mc":[{"id":"1.187595437","rc":[{"batb":[[0,1.02,600],[1,1.01,307],[2,1.01,0]],"ltp":1.03,"tv":450.44,"id":9168659}]}]}
{"op":"mcm","clk":"4234321113","pt":1631544273555,"mc":[{"id":"1.187595437","rc":[{"batb":[[0,9.6,10],[1,1.01,7]],"ltp":3.5,"tv":268.11,"id":9628279}]}]}
{"op":"mcm","clk":"4234321136","pt":1631544273862,"mc":[{"id":"1.187595437","rc":[{"batb":[[0,1.01,7],[1,1.01,0]],"ltp":3.5,"tv":268.11,"id":9628279}]}]}
{"op":"mcm","clk":"4234321364","pt":1631544276460,"mc":[{"id":"1.187595437","rc":[{"batb":[[1,1.01,4273]],"batl":[[0,1.31,1203.19]],"ltp":1.03,"tv":450.44,"id":9168659}]}]}
{"op":"mcm","clk":"4234321559","pt":1631544278791,"mc":[{"id":"1.187595437","rc":[{"batb":[[0,12,10],[1,1.01,7]],"ltp":3.5,"tv":268.11,"id":9628279}]}]}
{"op":"mcm","clk":"4234321697","pt":1631544280300,"mc":[{"id":"1.187595437","rc":[{"batb":[[0,1.01,7],[1,1.01,0]],"ltp":3.5,"tv":268.11,"id":9628279},{"batb":[[1,1.01,307]],"ltp":1.03,"tv":450.44,"id":9168659}]}]}
{"op":"mcm","clk":"4234322140","pt":1631544284582,"mc":[{"id":"1.187595437","rc":[{"batb":[[0,16,10],[1,1.01,7]],"ltp":3.5,"tv":268.11,"id":9628279}]}]}
{"op":"mcm","clk":"4234322345","pt":1631544286586,"mc":[{"id":"1.187595437","rc":[{"batl":[[0,340,36.37]],"ltp":3.5,"tv":268.11,"id":9628279}]}]}
{"op":"mcm","clk":"4234322833","pt":1631544291393,"mc":[{"id":"1.187595437","rc":[{"batb":[[0,1.01,7],[1,1.01,0]],"ltp":3.5,"tv":268.11,"id":9628279}]}]}
{"op":"mcm","clk":"4234323692","pt":1631544300394,"mc":[{"id":"1.187595437","rc":[{"batl":[[0,1.33,1136.66]],"ltp":1.03,"tv":450.44,"id":9168659}]}]}
{"op":"mcm","clk":"4234324339","pt":1631544306509,"mc":[{"id":"1.187595437","rc":[{"batb":[[0,9.6,10],[1,1.01,7]],"ltp":3.5,"tv":268.11,"id":9628279}]}]}
{"op":"mcm","clk":"4234324361","pt":1631544306716,"mc":[{"id":"1.187595437","rc":[{"batb":[[0,1.02,2777.23]],"ltp":1.03,"tv":450.44,"id":9168659}]}]}
{"op":"mcm","clk":"4234324519","pt":1631544308494,"mc":[{"id":"1.187595437","rc":[{"batb":[[0,1.01,7],[1,1.01,0]],"ltp":3.5,"tv":268.11,"id":9628279},{"batb":[[0,1.02,600]],"ltp":1.03,"tv":450.44,"id":9168659}]}]}
{"op":"mcm","clk":"4234324994","pt":1631544312924,"mc":[{"id":"1.187595437","rc":[{"batb":[[0,12,10],[1,1.01,7]],"ltp":3.5,"tv":268.11,"id":9628279}]}]}
{"op":"mcm","clk":"4234325219","pt":1631544314805,"mc":[{"id":"1.187595437","rc":[{"batb":[[1,1.01,4460.07]],"ltp":1.03,"tv":450.44,"id":9168659}]}]}
{"op":"mcm","clk":"4234326208","pt":1631544324920,"mc":[{"id":"1.187595437","rc":[{"batb":[[0,1.01,7],[1,1.01,0]],"ltp":3.5,"tv":268.11,"id":9628279}]}]}
{"op":"mcm","clk":"4234326295","pt":1631544325747,"mc":[{"id":"1.187595437","rc":[{"batb":[[1,1.01,307]],"ltp":1.03,"tv":450.44,"id":9168659}]}]}
{"op":"mcm","clk":"4234326755","pt":1631544329948,"mc":[{"id":"1.187595437","rc":[{"batb":[[0,14,10],[1,1.01,7]],"ltp":3.5,"tv":268.11,"id":9628279}]}]}
{"op":"mcm","clk":"4234326955","pt":1631544331823,"mc":[{"id":"1.187595437","rc":[{"batb":[[1,1.01,4273]],"ltp":1.03,"tv":450.44,"id":9168659}]}]}
{"op":"mcm","clk":"4234327456","pt":1631544335861,"mc":[{"id":"1.187595437","rc":[{"batb":[[1,1.01,307]],"ltp":1.03,"tv":450.44,"id":9168659}]}]}
{"op":"mcm","clk":"4234331233","pt":1631544370299,"mc":[{"id":"1.187595437","rc":[{"batb":[[0,1.01,7],[1,1.01,0]],"ltp":3.5,"tv":268.11,"id":9628279}]}]}
{"op":"mcm","clk":"4234331791","pt":1631544375268,"mc":[{"id":"1.187595437","rc":[{"batb":[[0,12,10],[1,1.01,7]],"ltp":3.5,"tv":268.11,"id":9628279}]}]}
{"op":"mcm","clk":"4234332272","pt":1631544379707,"mc":[{"id":"1.187595437","rc":[{"trd":[[1.02,14]],"batb":[[0,1.02,593]],"ltp":1.02,"tv":464.44,"id":9168659}],"tv":732.55}]}
{"op":"mcm","clk":"4234335436","pt":1631544407139,"mc":[{"id":"1.187595437","rc":[{"batb":[[0,1.01,7],[1,1.01,0]],"ltp":3.5,"tv":268.11,"id":9628279}]}]}
{"op":"mcm","clk":"4234336039","pt":1631544412148,"mc":[{"id":"1.187595437","rc":[{"batb":[[0,14,10],[1,1.01,7]],"ltp":3.5,"tv":268.11,"id":9628279}]}]}
{"op":"mcm","clk":"4234336413","pt":1631544415146,"mc":[{"id":"1.187595437","rc":[{"trd":[[1.02,214]],"batb":[[0,1.02,493]],"ltp":1.02,"tv":664.44,"id":9168659}],"tv":932.55}]}
{"op":"mcm","clk":"4234337213","pt":1631544422878,"mc":[{"id":"1.187595437","rc":[{"batb":[[0,1.01,307],[1,1.01,0]],"ltp":1.02,"tv":664.44,"id":9168659}]}]}
{"op":"mcm","clk":"4234337898","pt":1631544429454,"mc":[{"id":"1.187595437","rc":[{"batb":[[0,1.01,407]],"ltp":1.02,"tv":664.44,"id":9168659}]}]}
{"op":"mcm","clk":"4234337994","pt":1631544430361,"mc":[{"id":"1.187595437","rc":[{"batb":[[0,1.01,457]],"ltp":1.02,"tv":664.44,"id":9168659}]}]}
{"op":"mcm","clk":"4234338050","pt":1631544431040,"mc":[{"id":"1.187595437","rc":[{"batb":[[0,1.01,557]],"ltp":1.02,"tv":664.44,"id":9168659}]}]}
{"op":"mcm","clk":"4234345387","pt":1631544507256,"mc":[{"id":"1.187595437","rc":[{"batb":[[0,1.01,7],[1,1.01,0]],"ltp":3.5,"tv":268.11,"id":9628279}]}]}
{"op":"mcm","clk":"4234345877","pt":1631544512157,"mc":[{"id":"1.187595437","rc":[{"batb":[[0,16,10],[1,1.01,7]],"ltp":3.5,"tv":268.11,"id":9628279}]}]}
{"op":"mcm","clk":"4234347400","pt":1631544528484,"mc":[{"id":"1.187595437","rc":[{"batb":[[0,1.01,7],[1,1.01,0]],"ltp":3.5,"tv":268.11,"id":9628279}]}]}
{"op":"mcm","clk":"4234347759","pt":1631544533324,"mc":[{"id":"1.187595437","rc":[{"batb":[[0,19.5,10],[1,1.01,7]],"ltp":3.5,"tv":268.11,"id":9628279}]}]}
{"op":"mcm","clk":"4234347908","pt":1631544535197,"mc":[{"id":"1.187595437","rc":[{"batl":[[0,1.29,1287.28]],"ltp":1.02,"tv":664.44,"id":9168659}]}]}
{"op":"mcm","clk":"4234351033","pt":1631544571437,"mc":[{"id":"1.187595437","rc":[{"batb":[[0,1.01,7],[1,1.01,0]],"ltp":3.5,"tv":268.11,"id":9628279}]}]}
{"op":"mcm","clk":"4234351449","pt":1631544576363,"mc":[{"id":"1.187595437","rc":[{"batb":[[0,16,10],[1,1.01,7]],"ltp":3.5,"tv":268.11,"id":9628279}]}]}
{"op":"mcm","clk":"4234351562","pt":1631544577669,"mc":[{"id":"1.187595437","rc":[{"batl":[[0,340,36.37]],"ltp":3.5,"tv":268.11,"id":9628279}]}]}
{"op":"mcm","clk":"4234354299","pt":1631544609014,"mc":[{"id":"1.187595437","rc":[{"batb":[[0,1.01,7],[1,1.01,0]],"ltp":3.5,"tv":268.11,"id":9628279}]}]}
{"op":"mcm","clk":"4234354714","pt":1631544613927,"mc":[{"id":"1.187595437","rc":[{"batb":[[0,19.5,10],[1,1.01,7]],"ltp":3.5,"tv":268.11,"id":9628279}]}]}
{"op":"mcm","clk":"4234357048","pt":1631544642615,"mc":[{"id":"1.187595437","rc":[{"batb":[[0,1.01,7],[1,1.01,0]],"ltp":3.5,"tv":268.11,"id":9628279}]}]}
{"op":"mcm","clk":"4234357416","pt":1631544647516,"mc":[{"id":"1.187595437","rc":[{"batb":[[0,24,10],[1,1.01,7]],"ltp":3.5,"tv":268.11,"id":9628279},{"batb":[[0,1.01,7]],"ltp":1.02,"tv":664.44,"id":9168659}]}]}
{"op":"mcm","clk":"4234357497","pt":1631544648455,"mc":[{"id":"1.187595437","rc":[{"batl":[[0,1.28,1366.24]],"ltp":1.02,"tv":664.44,"id":9168659}]}]}
{"op":"mcm","clk":"4234358400","pt":1631544659276,"mc":[{"id":"1.187595437","rc":[{"batb":[[0,1.01,7],[1,1.01,0]],"ltp":3.5,"tv":268.11,"id":9628279}]}]}
{"op":"mcm","clk":"4234358829","pt":1631544664157,"mc":[{"id":"1.187595437","rc":[{"batb":[[0,19.5,10],[1,1.01,7]],"ltp":3.5,"tv":268.11,"id":9628279}]}]}
{"op":"mcm","clk":"4234359014","pt":1631544666485,"mc":[{"id":"1.187595437","rc":[{"batl":[[0,1.28,1326.95]],"ltp":1.02,"tv":664.44,"id":9168659}]}]}
{"op":"mcm","clk":"4234359953","pt":1631544678299,"mc":[{"id":"1.187595437","rc":[{"batb":[[0,1.01,7],[1,1.01,0]],"ltp":3.5,"tv":268.11,"id":9628279}]}]}
{"op":"mcm","clk":"4234360315","pt":1631544683073,"mc":[{"id":"1.187595437","rc":[{"batb":[[0,16,10],[1,1.01,7]],"ltp":3.5,"tv":268.11,"id":9628279}]}]}
{"op":"mcm","clk":"4234360429","pt":1631544684471,"mc":[{"id":"1.187595437","rc":[{"batl":[[0,1.3,1265.64]],"ltp":1.02,"tv":664.44,"id":9168659}]}]}
{"op":"mcm","clk":"4234360478","pt":1631544685194,"mc":[{"id":"1.187595437","rc":[{"batl":[[0,340,36.37]],"ltp":3.5,"tv":268.11,"id":9628279}]}]}
{"op":"mcm","clk":"4234362818","pt":1631544713000,"mc":[{"id":"1.187595437","rc":[{"batb":[[0,1.01,7],[1,1.01,0]],"ltp":3.5,"tv":268.11,"id":9628279}]}]}
{"op":"mcm","clk":"4234363265","pt":1631544718048,"mc":[{"id":"1.187595437","rc":[{"batb":[[0,12,10],[1,1.01,7]],"ltp":3.5,"tv":268.11,"id":9628279}]}]}
{"op":"mcm","clk":"4234363368","pt":1631544719140,"mc":[{"id":"1.187595437","rc":[{"batb":[[0,1.01,3973]],"batl":[[0,1.31,1203.19]],"ltp":1.02,"tv":664.44,"id":9168659}]}]}
{"op":"mcm","clk":"4234364517","pt":1631544732433,"mc":[{"id":"1.187595437","rc":[{"batb":[[0,1.02,600],[1,1.01,3973]],"ltp":1.02,"tv":664.44,"id":9168659}]}]}
{"op":"mcm","clk":"4234364553","pt":1631544732847,"mc":[{"id":"1.187595437","rc":[{"batb":[[0,1.02,1000]],"ltp":1.02,"tv":664.44,"id":9168659}]}]}
{"op":"mcm","clk":"4234365081","pt":1631544739555,"mc":[{"id":"1.187595437","rc":[{"batl":[[0,1.09,140],[1,1.31,1203.19]],"ltp":1.02,"tv":664.44,"id":9168659}]}]}
{"op":"mcm","clk":"4234365317","pt":1631544742565,"mc":[{"id":"1.187595437","rc":[{"batl":[[0,1.31,1203.19],[1,1.31,0]],"ltp":1.02,"tv":664.44,"id":9168659}]}]}
{"op":"mcm","clk":"4234365371","pt":1631544743129,"mc":[{"id":"1.187595437","rc":[{"batb":[[0,1.01,7],[1,1.01,0]],"ltp":3.5,"tv":268.11,"id":9628279}]}]}
{"op":"mcm","clk":"4234365429","pt":1631544743957,"mc":[{"id":"1.187595437","rc":[{"batb":[[1,1.01,7]],"ltp":1.02,"tv":664.44,"id":9168659}]}]}
{"op":"mcm","clk":"4234365834","pt":1631544748632,"mc":[{"id":"1.187595437","rc":[{"batb":[[0,16,10],[1,1.01,7]],"ltp":3.5,"tv":268.11,"id":9628279},{"batb":[[0,1.01,7],[1,1.01,0]],"ltp":1.02,"tv":664.44,"id":9168659}]}]}
{"op":"mcm","clk":"4234365897","pt":1631544749353,"mc":[{"id":"1.187595437","rc":[{"batl":[[0,170,37.48]],"ltp":3.5,"tv":268.11,"id":9628279}]}]}
{"op":"mcm","clk":"4234367561","pt":1631544770986,"mc":[{"id":"1.187595437","rc":[{"batb":[[0,1.01,7],[1,1.01,0]],"ltp":3.5,"tv":268.11,"id":9628279}]}]}
{"op":"mcm","clk":"4234367916","pt":1631544775907,"mc":[{"id":"1.187595437","rc":[{"batb":[[0,12,10],[1,1.01,7]],"ltp":3.5,"tv":268.11,"id":9628279}]}]}
{"op":"mcm","clk":"4234368136","pt":1631544778704,"mc":[{"id":"1.187595437","rc":[{"batb":[[0,1.01,3973]],"ltp":1.02,"tv":664.44,"id":9168659}]}]}
{"op":"mcm","clk":"4234370509","pt":1631544808038,"mc":[{"id":"1.187595437","rc":[{"batb":[[0,1.01,7],[1,1.01,0]],"ltp":3.5,"tv":268.11,"id":9628279}]}]}
{"op":"mcm","clk":"4234370553","pt":1631544808765,"mc":[{"id":"1.187595437","rc":[{"batb":[[0,1.01,7]],"ltp":1.02,"tv":664.44,"id":9168659}]}]}
{"op":"mcm","clk":"4234370876","pt":1631544813031,"mc":[{"id":"1.187595437","rc":[{"batb":[[0,16,10],[1,1.01,7]],"ltp":3.5,"tv":268.11,"id":9628279}]}]}
{"op":"mcm","clk":"4234371013","pt":1631544814853,"mc":[{"id":"1.187595437","rc":[{"batl":[[0,170,37.48]],"ltp":3.5,"tv":268.11,"id":9628279}]}]}
{"op":"mcm","clk":"4234372609","pt":1631544835993,"mc":[{"id":"1.187595437","rc":[{"batb":[[0,1.01,7],[1,1.01,0]],"ltp":3.5,"tv":268.11,"id":9628279}]}]}
{"op":"mcm","clk":"4234372959","pt":1631544840574,"mc":[{"id":"1.187595437","rc":[{"batb":[[0,19.5,10],[1,1.01,7]],"ltp":3.5,"tv":268.11,"id":9628279}]}]}
{"op":"mcm","clk":"4234375125","pt":1631544866993,"mc":[{"id":"1.187595437","rc":[{"batb":[[0,1.01,7],[1,1.01,0]],"ltp":3.5,"tv":268.11,"id":9628279}]}]}
{"op":"mcm","clk":"4234375532","pt":1631544871926,"mc":[{"id":"1.187595437","rc":[{"batb":[[0,24,10],[1,1.01,7]],"ltp":3.5,"tv":268.11,"id":9628279}]}]}
{"op":"mcm","clk":"4234376202","pt":1631544879840,"mc":[{"id":"1.187595437","rc":[{"batb":[[0,1.01,7],[1,1.01,0]],"ltp":3.5,"tv":268.11,"id":9628279}]}]}
{"op":"mcm","clk":"4234376694","pt":1631544885833,"mc":[{"id":"1.187595437","rc":[{"batl":[[0,1.27,1393.59]],"ltp":1.02,"tv":664.44,"id":9168659}]}]}
{"op":"mcm","clk":"4234377444","pt":1631544894729,"mc":[{"id":"1.187595437","rc":[{"trd":[[1.01,14]],"batl":[[0,1.01,22.46],[1,1.27,1393.59]],"ltp":1.01,"tv":678.44,"id":9168659}],"tv":946.55}]}
{"op":"mcm","clk":"4234379185","pt":1631544914974,"mc":[{"id":"1.187595437","rc":[{"batl":[[0,1.01,859.05]],"ltp":1.01,"tv":678.44,"id":9168659}]}]}
{"op":"mcm","clk":"4234380094","pt":1631544926463,"mc":[{"id":"1.187595437","rc":[{"batl":[[0,1.01,836.6]],"ltp":1.01,"tv":678.44,"id":9168659}]}]}
{"op":"mcm","clk":"4234380423","pt":1631544931407,"mc":[{"id":"1.187595437","rc":[{"batl":[[1,1.27,0]],"ltp":1.01,"tv":678.44,"id":9168659}]}]}
{"op":"mcm","clk":"4234381493","pt":1631544947090,"mc":[{"id":"1.187595437","rc":[{"batl":[[1,1.27,1412.67]],"ltp":1.01,"tv":678.44,"id":9168659}]}]}
{"op":"mcm","clk":"4234382211","pt":1631544956598,"mc":[{"id":"1.187595437","rc":[{"batl":[[1,1.27,0]],"ltp":1.01,"tv":678.44,"id":9168659}]}]}
{"op":"mcm","clk":"4234398863","pt":1631545191685,"mc":[{"id":"1.187595437","rc":[{"batl":[[1,1.27,1393.59]],"ltp":1.01,"tv":678.44,"id":9168659}]}]}
{"op":"mcm","clk":"4234400103","pt":1631545207317,"mc":[{"id":"1.187595437","rc":[{"trd":[[1.42,3.41],[1.45,16.19],[1.61,200],[2.42,6.93],[3.5,10.23],[3.95,26.01]],"ltp":3.5,"tv":268.29,"id":9628279},{"trd":[[1.01,14.02],[1.2,15.89],[1.27,2.77],[1.38,23.76],[1.49,54.51]],"batl":[[0,1.01,838.8],[1,1.27,0]],"ltp":1.01,"tv":678.43,"id":9168659}],"tv":946.73}]}
{"op":"mcm","clk":"4234401672","pt":1631545226226,"mc":[{"id":"1.187595437","rc":[{"batl":[[1,1.27,1414.36]],"ltp":1.01,"tv":678.43,"id":9168659}]}]}
{"op":"mcm","clk":"4234402698","pt":1631545239482,"mc":[{"id":"1.187595437","rc":[{"batl":[[1,1.27,0]],"ltp":1.01,"tv":678.43,"id":9168659}]}]}
{"op":"mcm","clk":"4234403897","pt":1631545253171,"mc":[{"id":"1.187595437","rc":[{"batl":[[1,1.27,1395.25]],"ltp":1.01,"tv":678.43,"id":9168659}]}]}
{"op":"mcm","clk":"4234405201","pt":1631545269799,"mc":[{"id":"1.187595437","rc":[{"batl":[[1,1.27,0]],"ltp":1.01,"tv":678.43,"id":9168659}]}]}
{"op":"mcm","clk":"4234406031","pt":1631545281582,"mc":[{"id":"1.187595437","rc":[{"batl":[[1,1.28,1367.87]],"ltp":1.01,"tv":678.43,"id":9168659}]}]}
{"op":"mcm","clk":"4234407540","pt":1631545299260,"mc":[{"id":"1.187595437","rc":[{"batl":[[1,1.28,0]],"ltp":1.01,"tv":678.43,"id":9168659}]}]}
{"op":"mcm","clk":"4234408199","pt":1631545305854,"mc":[{"id":"1.187595437","rc":[{"batl":[[1,1.28,1354.01]],"ltp":1.01,"tv":678.43,"id":9168659}]}]}
{"op":"mcm","clk":"4234408564","pt":1631545310218,"mc":[{"id":"1.187595437","rc":[{"batl":[[1,1.28,0]],"ltp":1.01,"tv":678.43,"id":9168659}]}]}
{"op":"mcm","clk":"4234409273","pt":1631545318863,"mc":[{"id":"1.187595437","rc":[{"batb":[[0,19.5,10],[1,1.01,7]],"ltp":3.5,"tv":268.29,"id":9628279},{"batl":[[1,1.28,1328.53]],"ltp":1.01,"tv":678.43,"id":9168659}]}]}
{"op":"mcm","clk":"4234410621","pt":1631545334269,"mc":[{"id":"1.187595437","rc":[{"trd":[[100,0.09]],"ltp":100.0,"tv":268.38,"id":9628279},{"trd":[[1.01,23.31]],"batl":[[0,1.01,829.51]],"ltp":1.01,"tv":687.73,"id":9168659}],"tv":956.11}]}
{"op":"mcm","clk":"4234419781","pt":1631545439439,"mc":[{"id":"1.187595437","rc":[{"batb":[[0,1.01,7],[1,1.01,0]],"ltp":100.0,"tv":268.38,"id":9628279}]}]}
{"op":"mcm","clk":"4234420256","pt":1631545444425,"mc":[{"id":"1.187595437","rc":[{"batb":[[0,16,10],[1,1.01,7]],"ltp":100.0,"tv":268.38,"id":9628279}]}]}
{"op":"mcm","clk":"4234422596","pt":1631545473168,"mc":[{"id":"1.187595437","rc":[{"batl":[[0,340,36.42]],"ltp":100.0,"tv":268.38,"id":9628279}]}]}
{"op":"mcm","clk":"4234428704","pt":1631545557044,"mc":[{"id":"1.187595437","rc":[{"batb":[[0,1.01,7],[1,1.01,0]],"ltp":100.0,"tv":268.38,"id":9628279}]}]}
{"op":"mcm","clk":"4234429104","pt":1631545561899,"mc":[{"id":"1.187595437","rc":[{"batb":[[0,19.5,10],[1,1.01,7]],"ltp":100.0,"tv":268.38,"id":9628279}]}]}
{"op":"mcm","clk":"4234430032","pt":1631545576060,"mc":[{"id":"1.187595437","rc":[{"batl":[[1,1.28,0]],"ltp":1.01,"tv":687.73,"id":9168659}]}]}
{"op":"mcm","clk":"4234430224","pt":1631545579674,"mc":[{"id":"1.187595437","rc":[{"batb":[[0,1.01,7],[1,1.01,0]],"ltp":100.0,"tv":268.38,"id":9628279}]}]}
{"op":"mcm","clk":"4234430666","pt":1631545586044,"mc":[{"id":"1.187595437","rc":[{"batl":[[1,1.27,1395.25]],"ltp":1.01,"tv":687.73,"id":9168659}]}]}
{"op":"mcm","clk":"4234431937","pt":1631545606310,"mc":[{"id":"1.187595437","rc":[{"batl":[[1,1.27,0]],"ltp":1.01,"tv":687.73,"id":9168659}]}]}
{"op":"mcm","clk":"4234433057","pt":1631545623229,"mc":[{"id":"1.187595437","rc":[{"batl":[[1,1.28,1354.01]],"ltp":1.01,"tv":687.73,"id":9168659}]}]}
{"op":"mcm","clk":"4234433889","pt":1631545635666,"mc":[{"id":"1.187595437","rc":[{"batl":[[1,1.28,0]],"ltp":1.01,"tv":687.73,"id":9168659}]}]}
{"op":"mcm","clk":"4234435590","pt":1631545661583,"mc":[{"id":"1.187595437","rc":[{"batl":[[1,1.29,1288.82]],"ltp":1.01,"tv":687.73,"id":9168659}]}]}
{"op":"mcm","clk":"4234436467","pt":1631545674290,"mc":[{"id":"1.187595437","rc":[{"batb":[[0,16,10],[1,1.01,7]],"ltp":100.0,"tv":268.38,"id":9628279}]}]}
{"op":"mcm","clk":"4234437567","pt":1631545691344,"mc":[{"id":"1.187595437","rc":[{"batb":[[0,1.01,7],[1,1.01,0]],"ltp":100.0,"tv":268.38,"id":9628279}]}]}
{"op":"mcm","clk":"4234437933","pt":1631545696352,"mc":[{"id":"1.187595437","rc":[{"batb":[[0,14,10],[1,1.01,7]],"ltp":100.0,"tv":268.38,"id":9628279}]}]}
{"op":"mcm","clk":"4234438017","pt":1631545697718,"mc":[{"id":"1.187595437","rc":[{"batl":[[0,340,36.42]],"ltp":100.0,"tv":268.38,"id":9628279}]}]}
{"op":"mcm","clk":"4234439006","pt":1631545710651,"mc":[{"id":"1.187595437","rc":[{"trd":[[1.01,32.59]],"batl":[[0,1.01,824.87]],"ltp":1.01,"tv":697.01,"id":9168659}],"tv":965.39}]}
{"op":"mcm","clk":"4234439952","pt":1631545724074,"mc":[{"id":"1.187595437","rc":[{"trd":[[1.01,1682.32]],"batl":[[0,1.29,1288.82],[1,1.29,0]],"ltp":1.01,"tv":2346.74,"id":9168659}],"tv":2615.12}]}
{"op":"mcm","clk":"4234440155","pt":1631545727589,"mc":[{"id":"1.187595437","rc":[{"batl":[[0,1000,3.41]],"ltp":100.0,"tv":268.38,"id":9628279}]}]}
{"op":"mcm","clk":"4234440598","pt":1631545734120,"mc":[{"id":"1.187595437","rc":[{"batb":[[0,1.01,7],[1,1.01,0]],"ltp":100.0,"tv":268.38,"id":9628279}]}]}
{"op":"mcm","clk":"4234440897","pt":1631545739026,"mc":[{"id":"1.187595437","rc":[{"batb":[[0,9.6,10],[1,1.01,7]],"ltp":100.0,"tv":268.38,"id":9628279},{"batb":[[0,1.03,999.99]],"ltp":1.01,"tv":2346.74,"id":9168659}]}]}
{"op":"mcm","clk":"4234440966","pt":1631545740114,"mc":[{"id":"1.187595437","rc":[{"batb":[[1,1.02,1252.25]],"batl":[[0,1.33,1756.38]],"ltp":1.01,"tv":2346.74,"id":9168659}]}]}
{"op":"mcm","clk":"4234441586","pt":1631545749215,"mc":[{"id":"1.187595437","rc":[{"batb":[[0,1.01,7],[1,1.01,0]],"ltp":100.0,"tv":268.38,"id":9628279}]}]}
{"op":"mcm","clk":"4234441771","pt":1631545751708,"mc":[{"id":"1.187595437","rc":[{"batb":[[1,1.02,0]],"ltp":1.01,"tv":2346.74,"id":9168659}]}]}
{"op":"mcm","clk":"4234441943","pt":1631545754230,"mc":[{"id":"1.187595437","rc":[{"batb":[[0,8.6,10],[1,1.01,7]],"ltp":100.0,"tv":268.38,"id":9628279}]}]}
{"op":"mcm","clk":"4234442094","pt":1631545756929,"mc":[{"id":"1.187595437","rc":[{"batb":[[0,1.03,1711.13]],"ltp":1.01,"tv":2346.74,"id":9168659}]}]}
{"op":"mcm","clk":"4234443167","pt":1631545773637,"mc":[{"id":"1.187595437","rc":[{"batb":[[0,1.01,7],[1,1.01,0]],"ltp":100.0,"tv":268.38,"id":9628279},{"batb":[[0,1.03,711.14]],"ltp":1.01,"tv":2346.74,"id":9168659}]}]}
{"op":"mcm","clk":"4234443504","pt":1631545778665,"mc":[{"id":"1.187595437","rc":[{"batb":[[0,12,10],[1,1.01,7]],"ltp":100.0,"tv":268.38,"id":9628279}]}]}
{"op":"mcm","clk":"4234443598","pt":1631545780240,"mc":[{"id":"1.187595437","rc":[{"batb":[[0,1.01,2978.25]],"ltp":1.01,"tv":2346.74,"id":9168659}]}]}
{"op":"mcm","clk":"4234445386","pt":1631545809397,"mc":[{"id":"1.187595437","rc":[{"batb":[[0,1.01,7],[1,1.01,0]],"ltp":100.0,"tv":268.38,"id":9628279}]}]}
{"op":"mcm","clk":"4234445731","pt":1631545814294,"mc":[{"id":"1.187595437","rc":[{"batb":[[0,8.6,10],[1,1.01,7]],"ltp":100.0,"tv":268.38,"id":9628279},{"batb":[[0,1.03,999.99]],"ltp":1.01,"tv":2346.74,"id":9168659}]}]}
{"op":"mcm","clk":"4234445809","pt":1631545815593,"mc":[{"id":"1.187595437","rc":[{"batb":[[0,1.03,1711.13]],"batl":[[0,1.35,1700.38]],"ltp":1.01,"tv":2346.74,"id":9168659}]}]}
{"op":"mcm","clk":"4234446601","pt":1631545829213,"mc":[{"id":"1.187595437","rc":[{"batb":[[0,1.03,711.14]],"ltp":1.01,"tv":2346.74,"id":9168659}]}]}
{"op":"mcm","clk":"4234446906","pt":1631545834205,"mc":[{"id":"1.187595437","rc":[{"batb":[[0,1.04,749.99],[1,1.03,711.14]],"ltp":1.01,"tv":2346.74,"id":9168659}]}]}
{"op":"mcm","clk":"4234447511","pt":1631545843743,"mc":[{"id":"1.187595437","rc":[{"batb":[[0,1.01,7],[1,1.01,0]],"ltp":100.0,"tv":268.38,"id":9628279},{"batb":[[0,1.03,711.14],[1,1.03,0]],"ltp":1.01,"tv":2346.74,"id":9168659}]}]}
{"op":"mcm","clk":"4234447833","pt":1631545848625,"mc":[{"id":"1.187595437","rc":[{"batb":[[0,7,10],[1,1.01,7]],"ltp":100.0,"tv":268.38,"id":9628279},{"batb":[[0,1.06,499.99]],"ltp":1.01,"tv":2346.74,"id":9168659}]}]}
{"op":"mcm","clk":"4234447947","pt":1631545850910,"mc":[{"id":"1.187595437","rc":[{"batb":[[1,1.05,260.11]],"ltp":1.01,"tv":2346.74,"id":9168659}]}]}
{"op":"mcm","clk":"4234448583","pt":1631545861533,"mc":[{"id":"1.187595437","rc":[{"trd":[[7,2.02]],"batb":[[0,7,8.99]],"ltp":7.0,"tv":270.4,"id":9628279}],"tv":2617.15}]}
{"op":"mcm","clk":"4234448606","pt":1631545861843,"mc":[{"id":"1.187595437","rc":[{"batb":[[0,1.01,7],[1,1.01,0]],"ltp":7.0,"tv":270.4,"id":9628279}]}]}
{"op":"mcm","clk":"4234448948","pt":1631545866738,"mc":[{"id":"1.187595437","rc":[{"batb":[[0,7,10],[1,1.01,7]],"ltp":7.0,"tv":270.4,"id":9628279}]}]}
{"op":"mcm","clk":"4234449046","pt":1631545868331,"mc":[{"id":"1.187595437","rc":[{"batb":[[0,1.01,7],[1,1.01,0]],"ltp":7.0,"tv":270.4,"id":9628279}]}]}
{"op":"mcm","clk":"4234449381","pt":1631545873342,"mc":[{"id":"1.187595437","rc":[{"batb":[[0,6,10],[1,1.01,7]],"ltp":7.0,"tv":270.4,"id":9628279},{"batb":[[0,1.08,374.99]],"ltp":1.01,"tv":2346.74,"id":9168659}]}]}
{"op":"mcm","clk":"4234449430","pt":1631545874271,"mc":[{"id":"1.187595437","rc":[{"batb":[[1,1.06,109.71]],"ltp":1.01,"tv":2346.74,"id":9168659}]}]}
{"op":"mcm","clk":"4234454019","pt":1631545939128,"mc":[{"id":"1.187595437","rc":[{"batb":[[1,1.06,0]],"ltp":1.01,"tv":2346.74,"id":9168659}]}]}
{"op":"mcm","clk":"4234454366","pt":1631545944834,"mc":[{"id":"1.187595437","rc":[{"batb":[[0,1.08,402.68]],"ltp":1.01,"tv":2346.74,"id":9168659}]}]}
{"op":"mcm","clk":"4234457293","pt":1631545992962,"mc":[{"id":"1.187595437","rc":[{"batb":[[0,1.01,7],[1,1.01,0]],"ltp":7.0,"tv":270.4,"id":9628279},{"batb":[[0,1.08,27.69]],"ltp":1.01,"tv":2346.74,"id":9168659}]}]}
{"op":"mcm","clk":"4234457604","pt":1631545997866,"mc":[{"id":"1.187595437","rc":[{"batb":[[0,7.6,10],[1,1.01,7]],"ltp":7.0,"tv":270.4,"id":9628279},{"batb":[[0,1.05,599.99]],"ltp":1.01,"tv":2346.74,"id":9168659}]}]}
{"op":"mcm","clk":"4234457720","pt":1631545999590,"mc":[{"id":"1.187595437","rc":[{"batb":[[0,1.05,860.1]],"ltp":1.01,"tv":2346.74,"id":9168659}]}]}
{"op":"mcm","clk":"4234459197","pt":1631546021515,"mc":[{"id":"1.187595437","rc":[{"batb":[[0,1.05,599.99]],"ltp":1.01,"tv":2346.74,"id":9168659}]}]}
{"op":"mcm","clk":"4234459567","pt":1631546027649,"mc":[{"id":"1.187595437","rc":[{"batb":[[0,1.01,7],[1,1.01,0]],"ltp":7.0,"tv":270.4,"id":9628279}]}]}
{"op":"mcm","clk":"4234460303","pt":1631546032581,"mc":[{"id":"1.187595437","rc":[{"batb":[[0,12,10],[1,1.01,7]],"ltp":7.0,"tv":270.4,"id":9628279}]}]}
{"op":"mcm","clk":"4234460549","pt":1631546034052,"mc":[{"id":"1.187595437","rc":[{"batb":[[0,1.02,1252.25]],"batl":[[0,1.33,1756.38]],"ltp":1.01,"tv":2346.74,"id":9168659}]}]}
{"op":"mcm","clk":"4234462931","pt":1631546055498,"mc":[{"id":"1.187595437","rc":[{"batb":[[0,1.01,7],[1,1.01,0]],"ltp":7.0,"tv":270.4,"id":9628279}]}]}
{"op":"mcm","clk":"4234463854","pt":1631546060407,"mc":[{"id":"1.187595437","rc":[{"batb":[[0,8,10],[1,1.01,7]],"ltp":7.0,"tv":270.4,"id":9628279},{"batb":[[0,1.04,749.99]],"ltp":1.01,"tv":2346.74,"id":9168659}]}]}
{"op":"mcm","clk":"4234464681","pt":1631546062406,"mc":[{"id":"1.187595437","rc":[{"batb":[[0,1.04,1188.27]],"batl":[[0,1.36,1645.42]],"ltp":1.01,"tv":2346.74,"id":9168659}]}]}
{"op":"mcm","clk":"4234465581","pt":1631546068471,"mc":[{"id":"1.187595437","rc":[{"batb":[[0,1.04,749.99]],"ltp":1.01,"tv":2346.74,"id":9168659}]}]}
{"op":"mcm","clk":"4234466379","pt":1631546080393,"mc":[{"id":"1.187595437","rc":[{"batb":[[0,1.01,7],[1,1.01,0]],"ltp":7.0,"tv":270.4,"id":9628279}]}]}
{"op":"mcm","clk":"4234466734","pt":1631546085410,"mc":[{"id":"1.187595437","rc":[{"batb":[[0,16,10],[1,1.01,7]],"ltp":7.0,"tv":270.4,"id":9628279}]}]}
{"op":"mcm","clk":"4234466854","pt":1631546087012,"mc":[{"id":"1.187595437","rc":[{"batl":[[0,170,32.52]],"ltp":7.0,"tv":270.4,"id":9628279},{"batl":[[0,1.3,1877.33]],"ltp":1.01,"tv":2346.74,"id":9168659}]}]}
{"op":"mcm","clk":"4234468228","pt":1631546109453,"mc":[{"id":"1.187595437","rc":[{"batb":[[0,1.01,7],[1,1.01,0]],"ltp":7.0,"tv":270.4,"id":9628279}]}]}
{"op":"mcm","clk":"4234470084","pt":1631546140134,"mc":[{"id":"1.187595437","marketDefinition":{"bspMarket":false,"turnInPlayEnabled":true,"persistenceEnabled":true,"marketBaseRate":5.0,"eventId":"30898003","eventTypeId":"2","numberOfWinners":1,"bettingType":"ODDS","marketType":"MATCH_ODDS","marketTime":"2021-09-13T13:59:24.000Z","suspendTime":"2021-09-13T13:59:24.000Z","bspReconciled":false,"complete":true,"inPlay":true,"crossMatching":true,"runnersVoidable":false,"numberOfActiveRunners":2,"betDelay":5,"status":"SUSPENDED","runners":[{"status":"ACTIVE","sortPriority":1,"id":9168659,"name":"T Lukas"},{"status":"ACTIVE","sortPriority":2,"id":9628279,"name":"Y Cavalle-Reimers"}],"regulators":["MR_INT"],"countryCode":"GB","discountAllowed":true,"timezone":"GMT","openDate":"2021-09-13T13:59:24.000Z","version":4030819538,"name":"Match Odds","eventName":"T Lukas v Y Cavalle-reimers"}}]}
{"op":"mcm","clk":"4234470582","pt":1631546145998,"mc":[{"id":"1.187595437","tv":0.0}]}
{"op":"mcm","clk":"4234470722","pt":1631546147196,"mc":[{"id":"1.187595437","marketDefinition":{"bspMarket":false,"turnInPlayEnabled":true,"persistenceEnabled":true,"marketBaseRate":5.0,"eventId":"30898003","eventTypeId":"2","numberOfWinners":1,"bettingType":"ODDS","marketType":"MATCH_ODDS","marketTime":"2021-09-13T13:59:24.000Z","suspendTime":"2021-09-13T13:59:24.000Z","bspReconciled":false,"complete":true,"inPlay":true,"crossMatching":false,"runnersVoidable":false,"numberOfActiveRunners":0,"betDelay":5,"status":"CLOSED","settledTime":"2021-09-13T15:15:42.000Z","runners":[{"status":"WINNER","sortPriority":1,"id":9168659,"name":"T Lukas"},{"status":"LOSER","sortPriority":2,"id":9628279,"name":"Y Cavalle-Reimers"}],"regulators":["MR_INT"],"countryCode":"GB","discountAllowed":true,"timezone":"GMT","openDate":"2021-09-13T13:59:24.000Z","version":4030819557,"name":"Match Odds","eventName":"T Lukas v Y Cavalle-reimers"}}]}
