{"op":"mcm","clk":"4226434656","pt":1631463867693,"mc":[{"id":"1.187557995","marketDefinition":{"bspMarket":false,"turnInPlayEnabled":true,"persistenceEnabled":true,"marketBaseRate":5.0,"eventId":"30896141","eventTypeId":"2","numberOfWinners":1,"bettingType":"ODDS","marketType":"MATCH_ODDS","marketTime":"2021-09-13T10:30:00.000Z","suspendTime":"2021-09-13T10:30:00.000Z","bspReconciled":false,"complete":true,"inPlay":false,"crossMatching":false,"runnersVoidable":false,"numberOfActiveRunners":2,"betDelay":0,"status":"OPEN","runners":[{"status":"ACTIVE","sortPriority":1,"id":9342449,"name":"Viktoria Kuzmova"},{"status":"ACTIVE","sortPriority":2,"id":9633869,"name":"Lucrezia Stefanini"}],"regulators":["MR_INT"],"discountAllowed":false,"timezone":"UTC","openDate":"2021-09-13T10:30:00.000Z","version":4029094371,"name":"Match Odds","eventName":"Kuzmova v Stefanini"}}]}
{"op":"mcm","clk":"4226434863","pt":1631463868724,"mc":[{"id":"1.187557995","marketDefinition":{"bspMarket":false,"turnInPlayEnabled":true,"persistenceEnabled":true,"marketBaseRate":5.0,"eventId":"30896141","eventTypeId":"2","numberOfWinners":1,"bettingType":"ODDS","marketType":"MATCH_ODDS","marketTime":"2021-09-13T10:30:00.000Z","suspendTime":"2021-09-13T10:30:00.000Z","bspReconciled":false,"complete":true,"inPlay":false,"crossMatching":false,"runnersVoidable":false,"numberOfActiveRunners":2,"betDelay":0,"status":"OPEN","runners":[{"status":"ACTIVE","sortPriority":1,"id":9342449,"name":"Viktoria Kuzmova"},{"status":"ACTIVE","sortPriority":2,"id":9633869,"name":"Lucrezia Stefanini"}],"regulators":["MR_INT"],"discountAllowed":true,"timezone":"UTC","openDate":"2021-09-13T10:30:00.000Z","version":4029094371,"name":"Match Odds","eventName":"Kuzmova v Stefanini"}}]}
{"op":"mcm","clk":"4226442748","pt":1631463920088,"mc":[{"id":"1.187557995","rc":[{"batb":[[0,1.01,25]],"ltp":0.0,"tv":0.0,"id":9342449},{"batb":[[0,1.01,25]],"ltp":0.0,"tv":0.0,"id":9633869}]}]}
{"op":"mcm","clk":"4226807560","pt":1631466477558,"mc":[{"id":"1.187557995","rc":[{"batb":[[0,1.64,49.9],[1,1.01,25]],"ltp":0.0,"tv":0.0,"id":9342449},{"batb":[[0,1.8,40.59],[1,1.01,25]],"ltp":0.0,"tv":0.0,"id":9633869}]}]}
{"op":"mcm","clk":"4226809963","pt":1631466492593,"mc":[{"id":"1.187557995","rc":[{"batb":[[0,1.01,25],[1,1.01,0]],"ltp":0.0,"tv":0.0,"id":9633869}]}]}
{"op":"mcm","clk":"4226809983","pt":1631466492811,"mc":[{"id":"1.187557995","rc":[{"batb":[[0,1.6,52.07],[1,1.01,25]],"ltp":0.0,"tv":0.0,"id":9633869}]}]}
{"op":"mcm","clk":"4226850609","pt":1631466736334,"mc":[{"id":"1.187557995","rc":[{"batl":[[0,990,2.2]],"ltp":0.0,"tv":0.0,"id":9342449},{"batl":[[0,990,2.2]],"ltp":0.0,"tv":0.0,"id":9633869}]}]}
{"op":"mcm","clk":"4226885817","pt":1631466942667,"mc":[{"id":"1.187557995","rc":[{"batb":[[1,1.01,118.94]],"ltp":0.0,"tv":0.0,"id":9342449}]}]}
{"op":"mcm","clk":"4226885857","pt":1631466942887,"mc":[{"id":"1.187557995","rc":[{"batb":[[1,1.01,118.94]],"ltp":0.0,"tv":0.0,"id":9633869}]}]}
{"op":"mcm","clk":"4226887045","pt":1631466949883,"mc":[{"id":"1.187557995","marketDefinition":{"bspMarket":false,"turnInPlayEnabled":true,"persistenceEnabled":true,"marketBaseRate":5.0,"eventId":"30896141","eventTypeId":"2","numberOfWinners":1,"bettingType":"ODDS","marketType":"MATCH_ODDS","marketTime":"2021-09-13T10:30:00.000Z","suspendTime":"2021-09-13T10:30:00.000Z","bspReconciled":false,"complete":true,"inPlay":false,"crossMatching":true,"runnersVoidable":false,"numberOfActiveRunners":2,"betDelay":0,"status":"OPEN","runners":[{"status":"ACTIVE","sortPriority":1,"id":9342449,"name":"Viktoria Kuzmova"},{"status":"ACTIVE","sortPriority":2,"id":9633869,"name":"Lucrezia Stefanini"}],"regulators":["MR_INT"],"discountAllowed":true,"timezone":"UTC","openDate":"2021-09-13T10:30:00.000Z","version":4029094371,"name":"Match Odds","eventName":"Kuzmova v Stefanini"}}]}
{"op":"mcm","clk":"4226927786","pt":1631467135236,"mc":[{"id":"1.187557995","rc":[{"batb":[[0,1.7,43.65]],"ltp":0.0,"tv":0.0,"id":9342449}]}]}
{"op":"mcm","clk":"4227090340","pt":1631468225024,"mc":[{"id":"1.187557995","rc":[{"batb":[[0,2.1,20.49]],"ltp":0.0,"tv":0.0,"id":9342449},{"batb":[[0,1.73,30.88],[1,1.6,52.07],[2,1.01,118.94]],"ltp":0.0,"tv":0.0,"id":9633869}]}]}
{"op":"mcm","clk":"4227092824","pt":1631468242641,"mc":[{"id":"1.187557995","rc":[{"batb":[[1,1.01,118.94],[2,1.01,0]],"ltp":0.0,"tv":0.0,"id":9633869}]}]}
{"op":"mcm","clk":"4227092838","pt":1631468242756,"mc":[{"id":"1.187557995","rc":[{"batb":[[0,2.12,37.98],[1,2.1,20.49],[2,1.01,118.94]],"ltp":0.0,"tv":0.0,"id":9342449}]}]}
{"op":"mcm","clk":"4227106624","pt":1631468336053,"mc":[{"id":"1.187557995","rc":[{"batb":[[0,2.2,18.78],[1,2.12,37.98]],"ltp":0.0,"tv":0.0,"id":9342449},{"batb":[[0,1.67,33.65]],"ltp":0.0,"tv":0.0,"id":9633869}]}]}
{"op":"mcm","clk":"4227134639","pt":1631468543013,"mc":[{"id":"1.187557995","rc":[{"batb":[[0,2.2,55.38],[1,1.01,118.94],[2,1.01,0]],"ltp":0.0,"tv":0.0,"id":9342449}]}]}
{"op":"mcm","clk":"4227158368","pt":1631468724100,"mc":[{"id":"1.187557995","rc":[{"batl":[[0,14.5,3.42],[1,990,2.2]],"ltp":0.0,"tv":0.0,"id":9342449},{"batl":[[0,10.5,3.42],[1,990,2.2]],"ltp":0.0,"tv":0.0,"id":9633869}]}]}
{"op":"mcm","clk":"4227248598","pt":1631469567474,"mc":[{"id":"1.187557995","rc":[{"batb":[[0,2.2,55.37]],"ltp":0.0,"tv":0.0,"id":9342449}]}]}
{"op":"mcm","clk":"4227251396","pt":1631469594633,"mc":[{"id":"1.187557995","rc":[{"batb":[[0,2.2,18.78]],"ltp":0.0,"tv":0.0,"id":9342449}]}]}
{"op":"mcm","clk":"4227335399","pt":1631470303504,"mc":[{"id":"1.187557995","rc":[{"batl":[[0,1.83,5],[1,10.5,3.42],[2,990,2.2]],"ltp":0.0,"tv":0.0,"id":9633869}]}]}
{"op":"mcm","clk":"4227341055","pt":1631470348518,"mc":[{"id":"1.187557995","rc":[{"batl":[[1,990,2.2],[2,990,0]],"ltp":0.0,"tv":0.0,"id":9633869}]}]}
{"op":"mcm","clk":"4227652494","pt":1631472854428,"mc":[{"id":"1.187557995","rc":[{"batb":[[1,1.01,591.8]],"ltp":0.0,"tv":0.0,"id":9342449},{"batb":[[1,1.01,591.8]],"ltp":0.0,"tv":0.0,"id":9633869}]}]}
{"op":"mcm","clk":"4227667330","pt":1631473004030,"mc":[{"id":"1.187557995","rc":[{"batl":[[0,990,2.2],[1,990,0]],"ltp":0.0,"tv":0.0,"id":9633869}]}]}
{"op":"mcm","clk":"4227671636","pt":1631473049925,"mc":[{"id":"1.187557995","rc":[{"batl":[[0,10.5,3.42],[1,990,2.2]],"ltp":0.0,"tv":0.0,"id":9633869}]}]}
{"op":"mcm","clk":"4227794323","pt":1631474228848,"mc":[{"id":"1.187557995","rc":[{"batb":[[1,1.36,10.04],[2,1.01,591.8]],"ltp":0.0,"tv":0.0,"id":9342449},{"batb":[[1,1.2,18.08],[2,1.01,591.8]],"ltp":0.0,"tv":0.0,"id":9633869}]}]}
{"op":"mcm","clk":"4227805722","pt":1631474352538,"mc":[{"id":"1.187557995","rc":[{"batl":[[0,2.48,3],[1,14.5,3.42],[2,990,2.2]],"ltp":0.0,"tv":0.0,"id":9342449},{"batb":[[0,1.68,5],[1,1.67,37.65],[2,1.2,18.08]],"ltp":0.0,"tv":0.0,"id":9633869}]}]}
{"op":"mcm","clk":"4227806469","pt":1631474360356,"mc":[{"id":"1.187557995","rc":[{"batl":[[1,990,2.2],[2,990,0]],"ltp":0.0,"tv":0.0,"id":9342449}]}]}
{"op":"mcm","clk":"4227914962","pt":1631475530968,"mc":[{"id":"1.187557995","rc":[{"batl":[[0,990,2.2],[1,990,0]],"ltp":0.0,"tv":0.0,"id":9342449},{"batb":[[0,1.67,33.65],[1,1.2,18.08],[2,1.01,591.8]],"ltp":0.0,"tv":0.0,"id":9633869}]}]}
{"op":"mcm","clk":"4227919238","pt":1631475573523,"mc":[{"id":"1.187557995","rc":[{"batl":[[0,14,3.42],[1,990,2.2]],"ltp":0.0,"tv":0.0,"id":9342449}]}]}
{"op":"mcm","clk":"4228043527","pt":1631477172252,"mc":[{"id":"1.187557995","rc":[{"batb":[[2,1.01,596.76]],"batl":[[0,14,3.42]],"ltp":0.0,"tv":0.0,"id":9342449},{"batb":[[2,1.01,596.76]],"batl":[[0,10.5,3.42]],"ltp":0.0,"tv":0.0,"id":9633869}]}]}
{"op":"mcm","clk":"4228113878","pt":1631477912943,"mc":[{"id":"1.187557995","rc":[{"batb":[[0,1.68,129.83],[1,1.67,33.65],[2,1.2,18.08]],"ltp":0.0,"tv":0.0,"id":9633869}]}]}
{"op":"mcm","clk":"4228119143","pt":1631477977921,"mc":[{"id":"1.187557995","rc":[{"batb":[[0,2,22.54]],"ltp":0.0,"tv":0.0,"id":9342449},{"batb":[[0,1.8,28.18],[1,1.68,129.83]],"ltp":0.0,"tv":0.0,"id":9633869}]}]}
{"op":"mcm","clk":"4228135927","pt":1631478213152,"mc":[{"id":"1.187557995","rc":[{"batb":[[0,1.81,110.47],[1,1.8,28.18]],"ltp":0.0,"tv":0.0,"id":9633869}]}]}
{"op":"mcm","clk":"4228373514","pt":1631482332267,"mc":[{"id":"1.187557995","rc":[{"batb":[[0,2.02,45.98],[1,2,22.54],[2,1.36,10.04]],"ltp":0.0,"tv":0.0,"id":9342449},{"batb":[[0,1.83,73.54],[1,1.81,110.47],[2,1.8,28.18]],"ltp":0.0,"tv":0.0,"id":9633869}]}]}
{"op":"mcm","clk":"4228373555","pt":1631482333352,"mc":[{"id":"1.187557995","rc":[{"batl":[[0,3,254.83],[1,14,3.42],[2,990,2.2]],"ltp":0.0,"tv":0.0,"id":9342449}]}]}
{"op":"mcm","clk":"4228374383","pt":1631482358852,"mc":[{"id":"1.187557995","rc":[{"batl":[[1,990,2.2],[2,990,0]],"ltp":0.0,"tv":0.0,"id":9342449}]}]}
{"op":"mcm","clk":"4228376319","pt":1631482413119,"mc":[{"id":"1.187557995","rc":[{"batb":[[1,1.8,28.18],[2,1.2,18.08]],"ltp":0.0,"tv":0.0,"id":9633869}]}]}
{"op":"mcm","clk":"4228427168","pt":1631483437351,"mc":[{"id":"1.187557995","rc":[{"batb":[[0,1.84,426.88],[1,1.83,73.54],[2,1.8,28.18]],"ltp":0.0,"tv":0.0,"id":9633869}]}]}
{"op":"mcm","clk":"4228427289","pt":1631483440138,"mc":[{"id":"1.187557995","rc":[{"batb":[[1,1.83,500.42]],"ltp":0.0,"tv":0.0,"id":9633869}]}]}
{"op":"mcm","clk":"4228427380","pt":1631483442342,"mc":[{"id":"1.187557995","rc":[{"batb":[[2,1.82,426.88]],"ltp":0.0,"tv":0.0,"id":9633869}]}]}
{"op":"mcm","clk":"4228430484","pt":1631483503385,"mc":[{"id":"1.187557995","rc":[{"batb":[[0,1.85,55.17],[1,1.84,426.88],[2,1.83,426.88]],"ltp":0.0,"tv":0.0,"id":9633869}]}]}
{"op":"mcm","clk":"4228556357","pt":1631485808439,"mc":[{"id":"1.187557995","rc":[{"batb":[[0,2.02,45.99],[2,1.36,10.04]],"ltp":0.0,"tv":0.0,"id":9342449},{"batb":[[0,1.85,60.6],[1,1.84,426.95],[2,1.83,426.95]],"ltp":0.0,"tv":0.0,"id":9633869}]}]}
{"op":"mcm","clk":"4228650745","pt":1631488665659,"mc":[{"id":"1.187557995","rc":[{"batb":[[0,2.02,45.98]],"ltp":0.0,"tv":0.0,"id":9342449},{"batb":[[0,1.85,60.59],[1,1.84,426.88],[2,1.83,426.88]],"ltp":0.0,"tv":0.0,"id":9633869}]}]}
{"op":"mcm","clk":"4228691978","pt":1631489476299,"mc":[{"id":"1.187557995","rc":[{"batl":[[0,2.6,293.89]],"ltp":0.0,"tv":0.0,"id":9342449}]}]}
{"op":"mcm","clk":"4228732634","pt":1631490582057,"mc":[{"id":"1.187557995","rc":[{"batl":[[0,2.58,110.89]],"ltp":0.0,"tv":0.0,"id":9342449}]}]}
{"op":"mcm","clk":"4228949963","pt":1631496757223,"mc":[{"id":"1.187557995","rc":[{"batb":[[0,2.02,45.96]],"batl":[[0,2.9,98.74]],"ltp":0.0,"tv":0.0,"id":9342449},{"batb":[[0,1.85,60.56],[1,1.84,426.66],[2,1.83,426.66]],"batl":[[0,10.5,3.41]],"ltp":0.0,"tv":0.0,"id":9633869}]}]}
{"op":"mcm","clk":"4228982097","pt":1631498007983,"mc":[{"id":"1.187557995","rc":[{"batl":[[0,2.1,7.98]],"ltp":0.0,"tv":0.0,"id":9342449}]}]}
{"op":"mcm","clk":"4229196220","pt":1631504865668,"mc":[{"id":"1.187557995","rc":[{"batb":[[0,2.02,45.95],[2,1.36,10.04]],"batl":[[0,2.1,7.98]],"ltp":0.0,"tv":0.0,"id":9342449},{"batb":[[0,1.85,60.55],[1,1.84,426.55],[2,1.83,426.55]],"ltp":0.0,"tv":0.0,"id":9633869}]}]}
{"op":"mcm","clk":"4229261810","pt":1631507401218,"mc":[{"id":"1.187557995","rc":[{"batb":[[1,2,33.81]],"ltp":0.0,"tv":0.0,"id":9342449}]}]}
{"op":"mcm","clk":"4229264613","pt":1631507667836,"mc":[{"id":"1.187557995","rc":[{"batb":[[0,1.86,391.6],[1,1.85,60.55],[2,1.84,426.55]],"ltp":0.0,"tv":0.0,"id":9633869}]}]}
{"op":"mcm","clk":"4229264656","pt":1631507672846,"mc":[{"id":"1.187557995","rc":[{"batb":[[1,1.85,55.13]],"ltp":0.0,"tv":0.0,"id":9633869}]}]}
{"op":"mcm","clk":"4229264714","pt":1631507679441,"mc":[{"id":"1.187557995","rc":[{"batb":[[0,1.86,396.98]],"ltp":0.0,"tv":0.0,"id":9633869}]}]}
{"op":"mcm","clk":"4229264872","pt":1631507693558,"mc":[{"id":"1.187557995","rc":[{"batb":[[0,1.87,37.56],[1,1.86,396.98]],"ltp":0.0,"tv":0.0,"id":9633869}]}]}
{"op":"mcm","clk":"4229264966","pt":1631507698991,"mc":[{"id":"1.187557995","rc":[{"batb":[[1,1.86,391.6]],"ltp":0.0,"tv":0.0,"id":9633869}]}]}
{"op":"mcm","clk":"4229265047","pt":1631507705599,"mc":[{"id":"1.187557995","rc":[{"batb":[[0,1.87,42.92]],"ltp":0.0,"tv":0.0,"id":9633869}]}]}
{"op":"mcm","clk":"4229265056","pt":1631507705911,"mc":[{"id":"1.187557995","rc":[{"batb":[[0,1.87,432.4],[1,1.84,426.55],[2,1.83,426.55]],"ltp":0.0,"tv":0.0,"id":9633869}]}]}
{"op":"mcm","clk":"4229274736","pt":1631508754900,"mc":[{"id":"1.187557995","rc":[{"batb":[[2,1.41,43.17]],"ltp":0.0,"tv":0.0,"id":9342449}]}]}
{"op":"mcm","clk":"4229275305","pt":1631508818383,"mc":[{"id":"1.187557995","rc":[{"batl":[[1,2.42,5.09],[2,990,2.2]],"ltp":0.0,"tv":0.0,"id":9342449},{"batl":[[0,2.2,6.02],[1,10.5,3.41],[2,990,2.2]],"ltp":0.0,"tv":0.0,"id":9633869}]}]}
{"op":"mcm","clk":"4229275676","pt":1631508858845,"mc":[{"id":"1.187557995","rc":[{"batl":[[1,990,2.2],[2,990,0]],"ltp":0.0,"tv":0.0,"id":9633869}]}]}
{"op":"mcm","clk":"4229275797","pt":1631508873628,"mc":[{"id":"1.187557995","rc":[{"batb":[[2,1.9,37.57]],"ltp":0.0,"tv":0.0,"id":9342449},{"batb":[[0,1.9,37.57],[1,1.87,432.4],[2,1.84,426.55]],"ltp":0.0,"tv":0.0,"id":9633869}]}]}
{"op":"mcm","clk":"4229275798","pt":1631508873731,"mc":[{"id":"1.187557995","rc":[{"batb":[[1,1.9,37.57],[2,1.41,43.17]],"ltp":0.0,"tv":0.0,"id":9342449}]}]}
{"op":"mcm","clk":"4229275834","pt":1631508877216,"mc":[{"id":"1.187557995","rc":[{"batb":[[1,1.87,427.04]],"ltp":0.0,"tv":0.0,"id":9633869}]}]}
{"op":"mcm","clk":"4229275902","pt":1631508884105,"mc":[{"id":"1.187557995","rc":[{"batb":[[0,1.9,420.83],[1,1.87,37.56]],"ltp":0.0,"tv":0.0,"id":9633869}]}]}
{"op":"mcm","clk":"4229276012","pt":1631508893545,"mc":[{"id":"1.187557995","rc":[{"batb":[[0,1.99,67.12],[1,1.9,567.68]],"ltp":0.0,"tv":0.0,"id":9342449},{"batb":[[1,1.85,55.13]],"ltp":0.0,"tv":0.0,"id":9633869}]}]}
{"op":"mcm","clk":"4229276015","pt":1631508893750,"mc":[{"id":"1.187557995","rc":[{"batb":[[1,1.9,37.57]],"ltp":0.0,"tv":0.0,"id":9342449}]}]}
{"op":"mcm","clk":"4229282045","pt":1631509400369,"mc":[{"id":"1.187557995","rc":[{"batb":[[0,1.99,67.13],[2,1.41,43.2]],"batl":[[0,2.1,7.97],[1,2.42,5.09]],"ltp":0.0,"tv":0.0,"id":9342449},{"batb":[[0,1.9,540.4],[1,1.85,55.13],[2,1.84,426.58]],"batl":[[0,2.2,6.03]],"ltp":0.0,"tv":0.0,"id":9633869}]}]}
{"op":"mcm","clk":"4229282918","pt":1631509458952,"mc":[{"id":"1.187557995","rc":[{"batl":[[0,2.04,8.1],[1,2.1,7.97],[2,2.42,5.09]],"ltp":0.0,"tv":0.0,"id":9342449}]}]}
{"op":"mcm","clk":"4229302808","pt":1631510408679,"mc":[{"id":"1.187557995","rc":[{"batl":[[1,29,48.39],[2,990,2.2]],"ltp":0.0,"tv":0.0,"id":9633869}]}]}
{"op":"mcm","clk":"4229309162","pt":1631510839681,"mc":[{"id":"1.187557995","rc":[{"batl":[[0,1.99,4.06],[1,2.2,6.03],[2,29,48.39]],"ltp":0.0,"tv":0.0,"id":9633869}]}]}
{"op":"mcm","clk":"4229316137","pt":1631511511448,"mc":[{"id":"1.187557995","rc":[{"batb":[[0,1.9,540.2]],"ltp":0.0,"tv":0.0,"id":9633869}]}]}
{"op":"mcm","clk":"4229327601","pt":1631512419582,"mc":[{"id":"1.187557995","rc":[{"batl":[[2,2.4,5.16]],"ltp":0.0,"tv":0.0,"id":9342449},{"batl":[[1,2.32,5.48]],"ltp":0.0,"tv":0.0,"id":9633869}]}]}
{"op":"mcm","clk":"4229335289","pt":1631512961092,"mc":[{"id":"1.187557995","rc":[{"batl":[[2,2.5,2.66]],"ltp":0.0,"tv":0.0,"id":9633869}]}]}
{"op":"mcm","clk":"4229343156","pt":1631513331228,"mc":[{"id":"1.187557995","rc":[{"batb":[[0,1.95,4.27],[1,1.9,42.83],[2,1.85,55.13]],"ltp":0.0,"tv":0.0,"id":9633869}]}]}
{"op":"mcm","clk":"4229371272","pt":1631514687655,"mc":[{"id":"1.187557995","rc":[{"batb":[[2,1.5,87.98]],"ltp":0.0,"tv":0.0,"id":9342449}]}]}
{"op":"mcm","clk":"4229420911","pt":1631516711135,"mc":[{"id":"1.187557995","rc":[{"batb":[[0,2,37.55],[1,1.99,67.14],[2,1.9,37.57]],"batl":[[1,2.1,7.99],[2,2.4,5.17]],"ltp":0.0,"tv":0.0,"id":9342449},{"batb":[[2,1.85,55.14]],"batl":[[0,1.99,4.07],[1,2,37.55],[2,2.32,5.49]],"ltp":0.0,"tv":0.0,"id":9633869}]}]}
{"op":"mcm","clk":"4229423204","pt":1631516763381,"mc":[{"id":"1.187557995","rc":[{"batb":[[0,2.02,45.96],[1,2,37.55]],"ltp":0.0,"tv":0.0,"id":9342449}]}]}
{"op":"mcm","clk":"4229442233","pt":1631517188674,"mc":[{"id":"1.187557995","rc":[{"trd":[[2.02,91.92]],"batb":[[0,2,37.55],[1,1.9,37.57],[2,1.5,88.09]],"ltp":2.02,"tv":91.91,"id":9342449},{"batb":[[0,1.96,462.12],[1,1.95,4.27],[2,1.9,42.83]],"ltp":0.0,"tv":0.0,"id":9633869}],"tv":91.91}]}
{"op":"mcm","clk":"4229442260","pt":1631517189187,"mc":[{"id":"1.187557995","rc":[{"batb":[[1,1.94,67.05],[2,1.9,37.57]],"batl":[[0,2.02,3],[1,2.04,8.1],[2,2.1,7.99]],"ltp":2.02,"tv":91.91,"id":9342449},{"trd":[[1.99,8]],"batb":[[0,1.98,4],[1,1.96,462.12],[2,1.95,4.27]],"batl":[[0,2,37.62],[1,2.32,5.49],[2,2.5,2.66]],"ltp":1.99,"tv":7.99,"id":9633869}],"tv":99.91}]}
{"op":"mcm","clk":"4229442496","pt":1631517193659,"mc":[{"id":"1.187557995","rc":[{"batl":[[0,2.04,8.1],[1,2.1,7.99],[2,2.4,5.17]],"ltp":2.02,"tv":91.91,"id":9342449},{"batb":[[1,1.97,5],[2,1.96,462.12]],"ltp":1.99,"tv":7.99,"id":9633869}]}]}
{"op":"mcm","clk":"4229442811","pt":1631517200192,"mc":[{"id":"1.187557995","rc":[{"batb":[[2,1.96,467.22]],"ltp":1.99,"tv":7.99,"id":9633869}]}]}
{"op":"mcm","clk":"4229443003","pt":1631517203756,"mc":[{"id":"1.187557995","rc":[{"batb":[[2,1.96,5.1]],"ltp":1.99,"tv":7.99,"id":9633869}]}]}
{"op":"mcm","clk":"4229444675","pt":1631517242620,"mc":[{"id":"1.187557995","rc":[{"batb":[[1,1.94,49.68]],"ltp":2.02,"tv":91.91,"id":9342449}]}]}
{"op":"mcm","clk":"4229444687","pt":1631517243030,"mc":[{"id":"1.187557995","rc":[{"batb":[[1,1.92,65.49]],"ltp":2.02,"tv":91.91,"id":9342449},{"batb":[[1,1.96,5.1],[2,1.95,4.27]],"ltp":1.99,"tv":7.99,"id":9633869}]}]}
{"op":"mcm","clk":"4229444792","pt":1631517245961,"mc":[{"id":"1.187557995","rc":[{"batb":[[1,1.95,4.27],[2,1.91,61.18]],"ltp":1.99,"tv":7.99,"id":9633869}]}]}
{"op":"mcm","clk":"4229446437","pt":1631517282988,"mc":[{"id":"1.187557995","rc":[{"batb":[[2,1.83,40.74]],"ltp":2.02,"tv":91.91,"id":9342449},{"batb":[[2,1.91,98.34]],"ltp":1.99,"tv":7.99,"id":9633869}]}]}
{"op":"mcm","clk":"4229471463","pt":1631517835851,"mc":[{"id":"1.187557995","rc":[{"trd":[[2,20]],"batb":[[0,2,27.55]],"ltp":2.0,"tv":111.91,"id":9342449}],"tv":119.91}]}
{"op":"mcm","clk":"4229509761","pt":1631518903514,"mc":[{"id":"1.187557995","rc":[{"batb":[[0,1.95,477.81],[1,1.91,98.34],[2,1.84,426.66]],"ltp":1.99,"tv":7.99,"id":9633869}]}]}
{"op":"mcm","clk":"4229509793","pt":1631518903877,"mc":[{"id":"1.187557995","rc":[{"batb":[[0,1.95,4.27]],"ltp":1.99,"tv":7.99,"id":9633869}]}]}
{"op":"mcm","clk":"4229510003","pt":1631518908812,"mc":[{"id":"1.187557995","rc":[{"batb":[[1,1.91,103.58]],"ltp":1.99,"tv":7.99,"id":9633869}]}]}
{"op":"mcm","clk":"4229521217","pt":1631519238145,"mc":[{"id":"1.187557995","rc":[{"batb":[[0,1.96,466.35],[1,1.95,4.27],[2,1.91,103.58]],"ltp":1.99,"tv":7.99,"id":9633869}]}]}
{"op":"mcm","clk":"4229521442","pt":1631519243645,"mc":[{"id":"1.187557995","rc":[{"batb":[[2,1.84,4]],"ltp":2.0,"tv":111.91,"id":9342449},{"batb":[[0,1.97,4],[1,1.96,470.35],[2,1.95,4.27]],"ltp":1.99,"tv":7.99,"id":9633869}]}]}
{"op":"mcm","clk":"4229521626","pt":1631519250075,"mc":[{"id":"1.187557995","rc":[{"batb":[[1,1.96,475.45]],"ltp":1.99,"tv":7.99,"id":9633869}]}]}
{"op":"mcm","clk":"4229522020","pt":1631519264479,"mc":[{"id":"1.187557995","rc":[{"batb":[[0,1.97,19.07],[1,1.96,5.1]],"ltp":1.99,"tv":7.99,"id":9633869}]}]}
{"op":"mcm","clk":"4229522163","pt":1631519269883,"mc":[{"id":"1.187557995","rc":[{"batb":[[1,1.95,4.27],[2,1.84,426.66]],"ltp":1.99,"tv":7.99,"id":9633869}]}]}
{"op":"mcm","clk":"4229525514","pt":1631519363933,"mc":[{"id":"1.187557995","rc":[{"batb":[[0,1.97,4],[2,1.91,61.18]],"ltp":1.99,"tv":7.99,"id":9633869}]}]}
{"op":"mcm","clk":"4229525664","pt":1631519368853,"mc":[{"id":"1.187557995","rc":[{"batb":[[2,1.91,98.34]],"ltp":1.99,"tv":7.99,"id":9633869}]}]}
{"op":"mcm","clk":"4229530820","pt":1631519530309,"mc":[{"id":"1.187557995","rc":[{"trd":[[2,20.2]],"batb":[[0,2,27.44]],"ltp":2.0,"tv":112.12,"id":9342449}],"tv":120.12}]}
{"op":"mcm","clk":"4229533631","pt":1631519620685,"mc":[{"id":"1.187557995","rc":[{"batl":[[2,29,48.45]],"ltp":2.0,"tv":112.12,"id":9342449}]}]}
{"op":"mcm","clk":"4229533650","pt":1631519621407,"mc":[{"id":"1.187557995","rc":[{"batl":[[2,2.4,5.17]],"ltp":2.0,"tv":112.12,"id":9342449},{"batl":[[1,2.34,5.4]],"ltp":1.99,"tv":7.99,"id":9633869}]}]}
{"op":"mcm","clk":"4229539844","pt":1631519799745,"mc":[{"id":"1.187557995","rc":[{"batb":[[0,1.97,465.58]],"ltp":1.99,"tv":7.99,"id":9633869}]}]}
{"op":"mcm","clk":"4229539974","pt":1631519803542,"mc":[{"id":"1.187557995","rc":[{"batb":[[2,1.83,40.74]],"batl":[[0,2.02,4],[1,2.04,8.1],[2,2.1,7.99]],"ltp":2.0,"tv":112.12,"id":9342449},{"batb":[[0,1.98,5],[1,1.97,470.66],[2,1.95,4.27]],"ltp":1.99,"tv":7.99,"id":9633869}]}]}
{"op":"mcm","clk":"4229540015","pt":1631519805026,"mc":[{"id":"1.187557995","rc":[{"batb":[[2,1.5,88.09]],"ltp":2.0,"tv":112.12,"id":9342449}]}]}
{"op":"mcm","clk":"4229555379","pt":1631520099999,"mc":[{"id":"1.187557995","rc":[{"batb":[[1,1.97,5.08]],"ltp":1.99,"tv":7.99,"id":9633869}]}]}
{"op":"mcm","clk":"4229555747","pt":1631520105980,"mc":[{"id":"1.187557995","rc":[{"batb":[[1,1.95,4.27],[2,1.91,61.18]],"ltp":1.99,"tv":7.99,"id":9633869}]}]}
{"op":"mcm","clk":"4229555918","pt":1631520109182,"mc":[{"id":"1.187557995","rc":[{"batb":[[2,1.83,40.74]],"ltp":2.0,"tv":112.12,"id":9342449},{"batb":[[2,1.91,98.34]],"ltp":1.99,"tv":7.99,"id":9633869}]}]}
{"op":"mcm","clk":"4229572460","pt":1631520387963,"mc":[{"id":"1.187557995","rc":[{"batb":[[2,1.83,37.74]],"ltp":2.0,"tv":112.12,"id":9342449},{"batb":[[2,1.91,95.6]],"ltp":1.99,"tv":7.99,"id":9633869}]}]}
{"op":"mcm","clk":"4229578538","pt":1631520492958,"mc":[{"id":"1.187557995","rc":[{"batb":[[0,2,44.39]],"ltp":2.0,"tv":112.12,"id":9342449}]}]}
{"op":"mcm","clk":"4229579134","pt":1631520505842,"mc":[{"id":"1.187557995","rc":[{"batl":[[0,2.02,54]],"ltp":2.0,"tv":112.12,"id":9342449}]}]}
{"op":"mcm","clk":"4229582336","pt":1631520572834,"mc":[{"id":"1.187557995","rc":[{"batb":[[0,1.98,431.66],[1,1.96,426.66],[2,1.95,4.27]],"ltp":1.99,"tv":7.99,"id":9633869}]}]}
{"op":"mcm","clk":"4229582396","pt":1631520574027,"mc":[{"id":"1.187557995","rc":[{"trd":[[2,70.42]],"batb":[[0,2,19.28]],"ltp":2.0,"tv":162.33,"id":9342449}],"tv":170.33}]}
{"op":"mcm","clk":"4229582489","pt":1631520575731,"mc":[{"id":"1.187557995","rc":[{"batb":[[2,1.5,88.09]],"ltp":2.0,"tv":162.33,"id":9342449}]}]}
{"op":"mcm","clk":"4229583131","pt":1631520587695,"mc":[{"id":"1.187557995","rc":[{"batl":[[1,2.04,619.51],[2,2.34,5.4]],"ltp":1.99,"tv":7.99,"id":9633869}]}]}
{"op":"mcm","clk":"4229583379","pt":1631520593310,"mc":[{"id":"1.187557995","rc":[{"batl":[[1,2.04,1477.94]],"ltp":1.99,"tv":7.99,"id":9633869}]}]}
{"op":"mcm","clk":"4229583517","pt":1631520596908,"mc":[{"id":"1.187557995","rc":[{"batl":[[1,2.04,619.51],[2,2.08,858.44]],"ltp":1.99,"tv":7.99,"id":9633869}]}]}
{"op":"mcm","clk":"4229586492","pt":1631520662973,"mc":[{"id":"1.187557995","rc":[{"batb":[[1,1.97,27.15]],"ltp":2.0,"tv":162.33,"id":9342449},{"batb":[[1,1.97,15.07],[2,1.96,426.66]],"ltp":1.99,"tv":7.99,"id":9633869}]}]}
{"op":"mcm","clk":"4229586702","pt":1631520666894,"mc":[{"id":"1.187557995","rc":[{"batb":[[0,1.98,436.72]],"ltp":1.99,"tv":7.99,"id":9633869}]}]}
{"op":"mcm","clk":"4229588694","pt":1631520715148,"mc":[{"id":"1.187557995","rc":[{"trd":[[2,87.49]],"batb":[[0,2,10.74]],"ltp":2.0,"tv":179.4,"id":9342449}],"tv":187.4}]}
{"op":"mcm","clk":"4229620160","pt":1631521211238,"mc":[{"id":"1.187557995","rc":[{"batb":[[2,1.5,127.11]],"ltp":2.0,"tv":179.4,"id":9342449}]}]}
{"op":"mcm","clk":"4229637965","pt":1631521538827,"mc":[{"id":"1.187557995","rc":[{"trd":[[2,146.57]],"batb":[[0,1.97,27.15],[1,1.5,127.11],[2,1.41,43.26]],"batl":[[0,2,1.66],[1,2.02,4],[2,2.04,8.1]],"ltp":2.0,"tv":238.48,"id":9342449},{"trd":[[1.99,8.07],[2,37.55]],"batl":[[0,2.04,619.51],[1,2.08,858.44],[2,2.34,5.4]],"ltp":2.0,"tv":45.61,"id":9633869}],"tv":284.1}]}
{"op":"mcm","clk":"4229638230","pt":1631521544062,"mc":[{"id":"1.187557995","rc":[{"batb":[[1,1.83,37.74],[2,1.5,127.11]],"ltp":2.0,"tv":238.48,"id":9342449}]}]}
{"op":"mcm","clk":"4229648709","pt":1631521750621,"mc":[{"id":"1.187557995","rc":[{"batb":[[0,1.98,38.4],[1,1.97,27.15],[2,1.83,37.74]],"ltp":2.0,"tv":238.48,"id":9342449},{"batl":[[0,2.02,38.4],[1,2.04,619.51],[2,2.08,858.44]],"ltp":2.0,"tv":45.61,"id":9633869}]}]}
{"op":"mcm","clk":"4229651181","pt":1631521802800,"mc":[{"id":"1.187557995","rc":[{"batb":[[2,1.83,50.32]],"ltp":2.0,"tv":238.48,"id":9342449}]}]}
{"op":"mcm","clk":"4229670538","pt":1631522255099,"mc":[{"id":"1.187557995","rc":[{"batl":[[0,2,9.76],[2,2.1,7.99]],"ltp":2.0,"tv":238.48,"id":9342449}]}]}
{"op":"mcm","clk":"4229689896","pt":1631522698270,"mc":[{"id":"1.187557995","rc":[{"trd":[[1.98,46.01]],"batb":[[0,1.98,15.39]],"ltp":1.98,"tv":284.49,"id":9342449}],"tv":330.1}]}
{"op":"mcm","clk":"4229691157","pt":1631522721709,"mc":[{"id":"1.187557995","rc":[{"trd":[[2,156.33]],"batl":[[0,2.02,4],[1,2.1,7.99],[2,2.4,5.17]],"ltp":2.0,"tv":294.25,"id":9342449},{"trd":[[2,47.31]],"batl":[[0,2,7.3],[1,2.02,38.4],[2,2.04,619.51]],"ltp":2.0,"tv":55.37,"id":9633869}],"tv":349.62}]}
{"op":"mcm","clk":"4229692266","pt":1631522745957,"mc":[{"id":"1.187557995","rc":[{"batb":[[0,1.98,40.99]],"ltp":2.0,"tv":294.25,"id":9342449}]}]}
{"op":"mcm","clk":"4229704245","pt":1631522973044,"mc":[{"id":"1.187557995","rc":[{"trd":[[2,61.91],[2.02,4.4]],"batl":[[0,2.02,36.2],[1,2.04,619.51],[2,2.08,858.44]],"ltp":2.02,"tv":74.38,"id":9633869}],"tv":368.63}]}
{"op":"mcm","clk":"4229717459","pt":1631523221471,"mc":[{"id":"1.187557995","rc":[{"batl":[[2,2.36,5.32]],"ltp":2.0,"tv":294.25,"id":9342449}]}]}
{"op":"mcm","clk":"4229724711","pt":1631523390817,"mc":[{"id":"1.187557995","rc":[{"batb":[[0,1.99,461.55],[1,1.98,436.72],[2,1.97,15.07]],"ltp":2.02,"tv":74.38,"id":9633869}]}]}
{"op":"mcm","clk":"4229724867","pt":1631523394718,"mc":[{"id":"1.187557995","rc":[{"trd":[[1.98,56.01]],"batb":[[0,1.98,35.99]],"ltp":1.98,"tv":304.25,"id":9342449},{"trd":[[2.02,12.4]],"batb":[[0,2,5],[1,1.99,461.55],[2,1.98,431.66]],"batl":[[0,2.02,32.2]],"ltp":2.02,"tv":82.38,"id":9633869}],"tv":386.63}]}
{"op":"mcm","clk":"4229724887","pt":1631523395285,"mc":[{"id":"1.187557995","rc":[{"batb":[[2,1.8,4]],"ltp":1.98,"tv":304.25,"id":9342449}]}]}
{"op":"mcm","clk":"4229725139","pt":1631523401198,"mc":[{"id":"1.187557995","rc":[{"batb":[[1,1.99,466.59]],"ltp":2.02,"tv":82.38,"id":9633869}]}]}
{"op":"mcm","clk":"4229726763","pt":1631523431353,"mc":[{"id":"1.187557995","rc":[{"batb":[[0,2,464.22],[1,1.99,5.04],[2,1.98,426.66]],"ltp":2.02,"tv":82.38,"id":9633869}]}]}
{"op":"mcm","clk":"4229726885","pt":1631523434438,"mc":[{"id":"1.187557995","rc":[{"batb":[[1,1.98,426.66],[2,1.97,15.07]],"ltp":2.02,"tv":82.38,"id":9633869}]}]}
{"op":"mcm","clk":"4229727191","pt":1631523441384,"mc":[{"id":"1.187557995","rc":[{"batb":[[0,2,469.22]],"ltp":2.02,"tv":82.38,"id":9633869}]}]}
{"op":"mcm","clk":"4229733040","pt":1631523586182,"mc":[{"id":"1.187557995","rc":[{"batb":[[0,2,10]],"ltp":2.02,"tv":82.38,"id":9633869}]}]}
{"op":"mcm","clk":"4229733241","pt":1631523592069,"mc":[{"id":"1.187557995","rc":[{"batl":[[0,2.1,7.99],[1,2.36,5.32],[2,29,48.45]],"ltp":1.98,"tv":304.25,"id":9342449},{"batb":[[0,1.98,426.66],[1,1.97,15.07],[2,1.96,426.66]],"ltp":2.02,"tv":82.38,"id":9633869}]}]}
{"op":"mcm","clk":"4229733292","pt":1631523593093,"mc":[{"id":"1.187557995","rc":[{"batb":[[2,1.8,56.2]],"ltp":1.98,"tv":304.25,"id":9342449},{"batb":[[0,2,41.76],[1,1.98,426.66],[2,1.97,15.07]],"ltp":2.02,"tv":82.38,"id":9633869}]}]}
{"op":"mcm","clk":"4229733568","pt":1631523598409,"mc":[{"id":"1.187557995","rc":[{"batb":[[0,2,46.76]],"ltp":2.02,"tv":82.38,"id":9633869}]}]}
{"op":"mcm","clk":"4229739657","pt":1631523720480,"mc":[{"id":"1.187557995","rc":[{"trd":[[1.98,56.01],[2,156.35],[2.02,91.93]],"batb":[[0,1.98,36],[1,1.97,27.16],[2,1.9,46.4]],"batl":[[0,2.1,7.99],[1,2.36,5.32],[2,29,48.42]],"ltp":1.98,"tv":304.28,"id":9342449},{"trd":[[1.99,8.07],[2,61.92],[2.02,12.4]],"batb":[[0,2,5],[1,1.98,426.73],[2,1.97,15.07]],"batl":[[0,2.02,32.2],[1,2.04,619.61],[2,2.08,858.58]],"ltp":2.02,"tv":82.39,"id":9633869}],"tv":386.67}]}
{"op":"mcm","clk":"4229740120","pt":1631523727061,"mc":[{"id":"1.187557995","rc":[{"batb":[[0,1.98,426.73],[1,1.97,15.07],[2,1.96,426.73]],"ltp":2.02,"tv":82.39,"id":9633869}]}]}
{"op":"mcm","clk":"4229743084","pt":1631523787098,"mc":[{"id":"1.187557995","rc":[{"batb":[[0,1.98,431.79]],"ltp":2.02,"tv":82.39,"id":9633869}]}]}
{"op":"mcm","clk":"4229746742","pt":1631523852228,"mc":[{"id":"1.187557995","rc":[{"batb":[[2,1.83,50.32]],"ltp":1.98,"tv":304.28,"id":9342449}]}]}
{"op":"mcm","clk":"4229750668","pt":1631523920826,"mc":[{"id":"1.187557995","rc":[{"batl":[[0,2.1,8.84]],"ltp":1.98,"tv":304.28,"id":9342449}]}]}
{"op":"mcm","clk":"4229770749","pt":1631524259664,"mc":[{"id":"1.187557995","rc":[{"batl":[[0,2,17.61],[1,2.1,8.84],[2,2.36,5.32]],"ltp":1.98,"tv":304.28,"id":9342449}]}]}
{"op":"mcm","clk":"4229771626","pt":1631524271882,"mc":[{"id":"1.187557995","rc":[{"batl":[[0,1.99,17.61]],"ltp":1.98,"tv":304.28,"id":9342449}]}]}
{"op":"mcm","clk":"4229780434","pt":1631524404281,"mc":[{"id":"1.187557995","rc":[{"batl":[[0,1.99,27.61]],"ltp":1.98,"tv":304.28,"id":9342449}]}]}
{"op":"mcm","clk":"4229780700","pt":1631524407838,"mc":[{"id":"1.187557995","rc":[{"batb":[[0,1.98,426.73]],"ltp":2.02,"tv":82.39,"id":9633869}]}]}
{"op":"mcm","clk":"4229781127","pt":1631524414402,"mc":[{"id":"1.187557995","rc":[{"batb":[[0,1.98,78.67]],"ltp":1.98,"tv":304.28,"id":9342449},{"batb":[[0,2,5],[1,1.98,426.73],[2,1.97,15.07]],"batl":[[0,2.02,74.87]],"ltp":2.02,"tv":82.39,"id":9633869}]}]}
{"op":"mcm","clk":"4229783684","pt":1631524453151,"mc":[{"id":"1.187557995","rc":[{"batl":[[2,29,48.42]],"ltp":1.98,"tv":304.28,"id":9342449}]}]}
{"op":"mcm","clk":"4229793904","pt":1631524637559,"mc":[{"id":"1.187557995","rc":[{"batl":[[1,2.04,4.3],[2,2.1,7.99]],"ltp":1.98,"tv":304.28,"id":9342449}]}]}
{"op":"mcm","clk":"4229835738","pt":1631525400458,"mc":[{"id":"1.187557995","rc":[{"batb":[[2,1.92,27.83]],"ltp":1.98,"tv":304.28,"id":9342449}]}]}
{"op":"mcm","clk":"4229842472","pt":1631525522505,"mc":[{"id":"1.187557995","rc":[{"batb":[[1,1.97,10.24]],"ltp":1.98,"tv":304.28,"id":9342449},{"batb":[[1,1.99,17.66],[2,1.98,426.73]],"ltp":2.02,"tv":82.39,"id":9633869}]}]}
{"op":"mcm","clk":"4229867652","pt":1631525874723,"mc":[{"id":"1.187557995","rc":[{"trd":[[2.02,17.73]],"batl":[[0,2.02,72.21]],"ltp":2.02,"tv":87.72,"id":9633869}],"tv":392.0}]}
{"op":"mcm","clk":"4229875094","pt":1631525988517,"mc":[{"id":"1.187557995","rc":[{"trd":[[1.98,91.22]],"batb":[[0,1.98,61.07]],"batl":[[0,1.99,10]],"ltp":1.98,"tv":339.49,"id":9342449}],"tv":427.21}]}
{"op":"mcm","clk":"4229875372","pt":1631525992908,"mc":[{"id":"1.187557995","rc":[{"batb":[[0,1.99,17.66],[1,1.98,426.73],[2,1.96,426.73]],"ltp":2.02,"tv":87.72,"id":9633869}]}]}
{"op":"mcm","clk":"4229875882","pt":1631525999856,"mc":[{"id":"1.187557995","rc":[{"batb":[[1,1.98,431.79]],"ltp":2.02,"tv":87.72,"id":9633869}]}]}
{"op":"mcm","clk":"4229890449","pt":1631526179797,"mc":[{"id":"1.187557995","rc":[{"trd":[[1.98,94.57]],"batb":[[0,1.98,59.39]],"ltp":1.98,"tv":342.83,"id":9342449}],"tv":430.55}]}
{"op":"mcm","clk":"4229894429","pt":1631526243225,"mc":[{"id":"1.187557995","rc":[{"trd":[[1.98,94.96]],"batb":[[0,1.98,59.2]],"ltp":1.98,"tv":343.23,"id":9342449}],"tv":430.95}]}
{"op":"mcm","clk":"4229966998","pt":1631527231469,"mc":[{"id":"1.187557995","rc":[{"trd":[[1.98,108.45]],"batb":[[0,1.98,52.45]],"ltp":1.98,"tv":356.71,"id":9342449}],"tv":444.43}]}
{"op":"mcm","clk":"4229969251","pt":1631527262484,"mc":[{"id":"1.187557995","rc":[{"batb":[[1,1.97,104.98]],"ltp":1.98,"tv":356.71,"id":9342449}]}]}
{"op":"mcm","clk":"4230017636","pt":1631527941578,"mc":[{"id":"1.187557995","rc":[{"trd":[[1.98,108.65]],"batb":[[0,1.98,52.35]],"ltp":1.98,"tv":356.92,"id":9342449}],"tv":444.64}]}
{"op":"mcm","clk":"4230041732","pt":1631528134733,"mc":[{"id":"1.187557995","rc":[{"batb":[[1,1.97,108.95]],"ltp":1.98,"tv":356.92,"id":9342449},{"batb":[[0,1.99,24.5]],"ltp":2.02,"tv":87.72,"id":9633869}]}]}
{"op":"mcm","clk":"4230042047","pt":1631528139813,"mc":[{"id":"1.187557995","rc":[{"batb":[[1,1.98,426.73]],"ltp":2.02,"tv":87.72,"id":9633869}]}]}
{"op":"mcm","clk":"4230042553","pt":1631528146453,"mc":[{"id":"1.187557995","rc":[{"batb":[[0,1.99,29.54]],"ltp":2.02,"tv":87.72,"id":9633869}]}]}
{"op":"mcm","clk":"4230049575","pt":1631528243627,"mc":[{"id":"1.187557995","rc":[{"trd":[[1.96,575.81],[1.97,217.91],[1.98,287.02],[1.99,20],[2.02,91.94]],"batb":[[0,1.92,27.83],[1,1.8,4],[2,1.5,88.04]],"batl":[[0,2.04,4.29],[1,2.1,7.99],[2,29,48.42]],"ltp":2.02,"tv":1349.03,"id":9342449},{"trd":[[2.02,89.94],[2.04,553.23]],"batl":[[0,2.04,66.38],[1,2.08,858.58],[2,2.5,2.66]],"ltp":2.04,"tv":713.16,"id":9633869}],"tv":2062.19}]}
{"op":"mcm","clk":"4230049608","pt":1631528244146,"mc":[{"id":"1.187557995","rc":[{"batb":[[0,1.93,44.42],[1,1.92,27.83],[2,1.8,4]],"ltp":2.02,"tv":1349.03,"id":9342449},{"batb":[[0,1.99,40.8]],"ltp":2.04,"tv":713.16,"id":9633869}]}]}
{"op":"mcm","clk":"4230049715","pt":1631528245748,"mc":[{"id":"1.187557995","rc":[{"batb":[[2,1.83,50.32]],"ltp":2.02,"tv":1349.03,"id":9342449}]}]}
{"op":"mcm","clk":"4230051818","pt":1631528279473,"mc":[{"id":"1.187557995","rc":[{"batl":[[0,1.98,426.73],[1,2.04,4.29],[2,2.1,7.99]],"ltp":2.02,"tv":1349.03,"id":9342449}]}]}
{"op":"mcm","clk":"4230051845","pt":1631528279986,"mc":[{"id":"1.187557995","rc":[{"batb":[[1,1.91,28.14]],"ltp":2.02,"tv":1349.03,"id":9342449},{"batb":[[2,1.96,453.4]],"ltp":2.04,"tv":713.16,"id":9633869}]}]}
{"op":"mcm","clk":"4230052011","pt":1631528282163,"mc":[{"id":"1.187557995","rc":[{"batb":[[0,1.94,162.93],[1,1.93,44.42],[2,1.91,28.14]],"ltp":2.02,"tv":1349.03,"id":9342449}]}]}
{"op":"mcm","clk":"4230057188","pt":1631528360650,"mc":[{"id":"1.187557995","rc":[{"batb":[[1,1.91,28.31],[2,1.83,50.32]],"ltp":2.02,"tv":1349.03,"id":9342449}]}]}
{"op":"mcm","clk":"4230057205","pt":1631528360962,"mc":[{"id":"1.187557995","rc":[{"batb":[[0,1.95,24.82],[1,1.94,162.93],[2,1.91,28.31]],"ltp":2.02,"tv":1349.03,"id":9342449}]}]}
{"op":"mcm","clk":"4230059159","pt":1631528397102,"mc":[{"id":"1.187557995","rc":[{"batl":[[1,2.04,15.77]],"ltp":2.02,"tv":1349.03,"id":9342449}]}]}
{"op":"mcm","clk":"4230060205","pt":1631528410220,"mc":[{"id":"1.187557995","rc":[{"batb":[[0,1.99,35.76]],"ltp":2.04,"tv":713.16,"id":9633869}]}]}
{"op":"mcm","clk":"4230060771","pt":1631528416813,"mc":[{"id":"1.187557995","rc":[{"batb":[[0,2.02,4.96],[1,1.99,35.76],[2,1.98,426.73]],"ltp":2.04,"tv":713.16,"id":9633869}]}]}
{"op":"mcm","clk":"4230081701","pt":1631528716753,"mc":[{"id":"1.187557995","rc":[{"trd":[[1.96,580.81]],"ltp":1.96,"tv":1354.03,"id":9342449},{"trd":[[2.04,558.04]],"batl":[[0,2.04,61.58]],"ltp":2.04,"tv":717.96,"id":9633869}],"tv":2071.99}]}
{"op":"mcm","clk":"4230082943","pt":1631528732647,"mc":[{"id":"1.187557995","rc":[{"trd":[[1.95,49.64],[1.96,644.9]],"batb":[[0,1.94,162.16],[1,1.91,28.14],[2,1.9,46.4]],"batl":[[0,1.95,118.63],[1,1.98,426.73],[2,2.04,15.77]],"ltp":1.95,"tv":1467.76,"id":9342449},{"trd":[[2.04,619.61]],"batl":[[0,2.08,858.58],[1,2.5,2.66],[2,29,48.42]],"ltp":2.04,"tv":779.54,"id":9633869}],"tv":2247.3}]}
{"op":"mcm","clk":"4230082991","pt":1631528733369,"mc":[{"id":"1.187557995","rc":[{"batb":[[1,1.93,25.56]],"ltp":1.95,"tv":1467.76,"id":9342449},{"batb":[[1,1.99,53.89]],"ltp":2.04,"tv":779.54,"id":9633869}]}]}
{"op":"mcm","clk":"4230083716","pt":1631528744850,"mc":[{"id":"1.187557995","rc":[{"batb":[[0,1.99,53.89],[1,1.98,426.73],[2,1.96,453.4]],"ltp":2.04,"tv":779.54,"id":9633869}]}]}
{"op":"mcm","clk":"4230084173","pt":1631528751572,"mc":[{"id":"1.187557995","rc":[{"batb":[[0,2.04,4.9],[1,1.99,53.89],[2,1.98,426.73]],"ltp":2.04,"tv":779.54,"id":9633869}]}]}
{"op":"mcm","clk":"4230084227","pt":1631528752387,"mc":[{"id":"1.187557995","rc":[{"batb":[[2,1.98,452.85]],"ltp":2.04,"tv":779.54,"id":9633869}]}]}
{"op":"mcm","clk":"4230097962","pt":1631528940154,"mc":[{"id":"1.187557995","rc":[{"batl":[[0,1.95,120.33]],"ltp":1.95,"tv":1467.76,"id":9342449}]}]}
{"op":"mcm","clk":"4230098959","pt":1631528953489,"mc":[{"id":"1.187557995","rc":[{"trd":[[1.95,290.3]],"batb":[[0,1.95,41.83],[2,1.9,74.85]],"batl":[[0,1.98,426.73],[1,2.04,15.77],[2,2.1,7.99]],"ltp":1.95,"tv":1708.42,"id":9342449},{"batb":[[2,1.98,426.73]],"ltp":2.04,"tv":779.54,"id":9633869}],"tv":2487.96}]}
{"op":"mcm","clk":"4230099260","pt":1631528957386,"mc":[{"id":"1.187557995","rc":[{"batb":[[0,1.99,53.89],[1,1.98,426.73],[2,1.96,453.4]],"ltp":2.04,"tv":779.54,"id":9633869}]}]}
{"op":"mcm","clk":"4230099404","pt":1631528959564,"mc":[{"id":"1.187557995","rc":[{"batb":[[0,1.94,41.83],[2,1.9,46.4]],"ltp":1.95,"tv":1708.42,"id":9342449}]}]}
{"op":"mcm","clk":"4230099743","pt":1631528964499,"mc":[{"id":"1.187557995","rc":[{"batb":[[0,2.02,4.96],[1,1.99,53.89],[2,1.98,426.73]],"ltp":2.04,"tv":779.54,"id":9633869}]}]}
{"op":"mcm","clk":"4230102071","pt":1631528996729,"mc":[{"id":"1.187557995","rc":[{"batl":[[0,1.98,428.73]],"ltp":1.95,"tv":1708.42,"id":9342449},{"batl":[[0,2.08,860.58]],"ltp":2.04,"tv":779.54,"id":9633869}]}]}
{"op":"mcm","clk":"4230103090","pt":1631529008527,"mc":[{"id":"1.187557995","rc":[{"batb":[[0,1.95,3.11],[1,1.94,41.83],[2,1.93,25.56]],"ltp":1.95,"tv":1708.42,"id":9342449}]}]}
{"op":"mcm","clk":"4230138674","pt":1631529450188,"mc":[{"id":"1.187557995","rc":[{"batb":[[1,1.93,25.56],[2,1.9,46.4]],"ltp":1.95,"tv":1708.42,"id":9342449}]}]}
{"op":"mcm","clk":"4230140643","pt":1631529477113,"mc":[{"id":"1.187557995","rc":[{"batl":[[1,2,170.69],[2,2.04,15.77]],"ltp":1.95,"tv":1708.42,"id":9342449},{"batb":[[1,2,170.69],[2,1.99,53.89]],"ltp":2.04,"tv":779.54,"id":9633869}]}]}
{"op":"mcm","clk":"4230147347","pt":1631529557635,"mc":[{"id":"1.187557995","marketDefinition":{"bspMarket":false,"turnInPlayEnabled":true,"persistenceEnabled":true,"marketBaseRate":5.0,"eventId":"30896141","eventTypeId":"2","numberOfWinners":1,"bettingType":"ODDS","marketType":"MATCH_ODDS","marketTime":"2021-09-13T10:50:00.000Z","suspendTime":"2021-09-13T10:50:00.000Z","bspReconciled":false,"complete":true,"inPlay":false,"crossMatching":true,"runnersVoidable":false,"numberOfActiveRunners":2,"betDelay":0,"status":"OPEN","runners":[{"status":"ACTIVE","sortPriority":1,"id":9342449,"name":"Viktoria Kuzmova"},{"status":"ACTIVE","sortPriority":2,"id":9633869,"name":"Lucrezia Stefanini"}],"regulators":["MR_INT"],"discountAllowed":true,"timezone":"UTC","openDate":"2021-09-13T10:30:00.000Z","version":4030549468,"name":"Match Odds","eventName":"Kuzmova v Stefanini"}}]}
{"op":"mcm","clk":"4230147406","pt":1631529558209,"mc":[{"id":"1.187557995","rc":[{"batl":[[0,1.98,430.79]],"ltp":1.95,"tv":1708.42,"id":9342449}]}]}
{"op":"mcm","clk":"4230147616","pt":1631529560620,"mc":[{"id":"1.187557995","marketDefinition":{"bspMarket":false,"turnInPlayEnabled":true,"persistenceEnabled":true,"marketBaseRate":5.0,"eventId":"30896141","eventTypeId":"2","numberOfWinners":1,"bettingType":"ODDS","marketType":"MATCH_ODDS","marketTime":"2021-09-13T10:50:00.000Z","suspendTime":"2021-09-13T10:50:00.000Z","bspReconciled":false,"complete":true,"inPlay":false,"crossMatching":true,"runnersVoidable":false,"numberOfActiveRunners":2,"betDelay":0,"status":"OPEN","runners":[{"status":"ACTIVE","sortPriority":1,"id":9342449,"name":"Viktoria Kuzmova"},{"status":"ACTIVE","sortPriority":2,"id":9633869,"name":"Lucrezia Stefanini"}],"regulators":["MR_INT"],"discountAllowed":true,"timezone":"UTC","openDate":"2021-09-13T10:50:00.000Z","version":4030549468,"name":"Match Odds","eventName":"Kuzmova v Stefanini"}}]}
{"op":"mcm","clk":"4230147671","pt":1631529561110,"mc":[{"id":"1.187557995","rc":[{"batb":[[0,2.02,30.04],[2,1.98,426.73]],"ltp":2.04,"tv":779.54,"id":9633869}]}]}
{"op":"mcm","clk":"4230166617","pt":1631529799986,"mc":[{"id":"1.187557995","rc":[{"batl":[[1,2,172.69]],"ltp":1.95,"tv":1708.42,"id":9342449}]}]}
{"op":"mcm","clk":"4230169372","pt":1631529833723,"mc":[{"id":"1.187557995","rc":[{"batl":[[2,2.04,12.32]],"ltp":1.95,"tv":1708.42,"id":9342449}]}]}
{"op":"mcm","clk":"4230169842","pt":1631529839620,"mc":[{"id":"1.187557995","rc":[{"batl":[[0,1.96,3.44],[1,1.98,430.79],[2,2,172.69]],"ltp":1.95,"tv":1708.42,"id":9342449}]}]}
{"op":"mcm","clk":"4230170248","pt":1631529844725,"mc":[{"id":"1.187557995","rc":[{"batb":[[1,1.93,95.35]],"ltp":1.95,"tv":1708.42,"id":9342449}]}]}
{"op":"mcm","clk":"4230195728","pt":1631530140217,"mc":[{"id":"1.187557995","rc":[{"batl":[[1,1.98,428.73]],"ltp":1.95,"tv":1708.42,"id":9342449}]}]}
{"op":"mcm","clk":"4230208504","pt":1631530291327,"mc":[{"id":"1.187557995","rc":[{"batl":[[0,1.98,428.73],[1,2,172.69],[2,2.04,12.32]],"ltp":1.95,"tv":1708.42,"id":9342449}]}]}
{"op":"mcm","clk":"4230208846","pt":1631530295683,"mc":[{"id":"1.187557995","rc":[{"trd":[[1.94,0.66],[1.95,296.52]],"batb":[[0,1.93,95.35],[1,1.9,46.4],[2,1.89,28.77]],"ltp":1.94,"tv":1715.3,"id":9342449}],"tv":2494.84}]}
{"op":"mcm","clk":"4230209027","pt":1631530298011,"mc":[{"id":"1.187557995","rc":[{"trd":[[1.95,372.98]],"ltp":1.95,"tv":1791.75,"id":9342449}],"tv":2571.3}]}
{"op":"mcm","clk":"4230209296","pt":1631530301120,"mc":[{"id":"1.187557995","rc":[{"batl":[[0,2.08,865.7]],"ltp":2.04,"tv":779.54,"id":9633869}]}]}
{"op":"mcm","clk":"4230209647","pt":1631530305216,"mc":[{"id":"1.187557995","rc":[{"batb":[[1,2,1103.52]],"ltp":2.04,"tv":779.54,"id":9633869}]}]}
{"op":"mcm","clk":"4230210982","pt":1631530320642,"mc":[{"id":"1.187557995","rc":[{"batl":[[0,1.97,3.16],[1,1.98,428.73],[2,2,172.69]],"ltp":1.95,"tv":1791.75,"id":9342449}]}]}
{"op":"mcm","clk":"4230221311","pt":1631530456619,"mc":[{"id":"1.187557995","marketDefinition":{"bspMarket":false,"turnInPlayEnabled":true,"persistenceEnabled":true,"marketBaseRate":5.0,"eventId":"30896141","eventTypeId":"2","numberOfWinners":1,"bettingType":"ODDS","marketType":"MATCH_ODDS","marketTime":"2021-09-13T11:00:00.000Z","suspendTime":"2021-09-13T11:00:00.000Z","bspReconciled":false,"complete":true,"inPlay":false,"crossMatching":true,"runnersVoidable":false,"numberOfActiveRunners":2,"betDelay":0,"status":"OPEN","runners":[{"status":"ACTIVE","sortPriority":1,"id":9342449,"name":"Viktoria Kuzmova"},{"status":"ACTIVE","sortPriority":2,"id":9633869,"name":"Lucrezia Stefanini"}],"regulators":["MR_INT"],"discountAllowed":true,"timezone":"UTC","openDate":"2021-09-13T10:50:00.000Z","version":4030564247,"name":"Match Odds","eventName":"Kuzmova v Stefanini"},"rc":[{"batl":[[0,1.97,5.63]],"ltp":1.95,"tv":1791.75,"id":9342449}]}]}
{"op":"mcm","clk":"4230221328","pt":1631530456826,"mc":[{"id":"1.187557995","rc":[{"batl":[[1,1.98,431.19]],"ltp":1.95,"tv":1791.75,"id":9342449}]}]}
{"op":"mcm","clk":"4230221537","pt":1631530459490,"mc":[{"id":"1.187557995","marketDefinition":{"bspMarket":false,"turnInPlayEnabled":true,"persistenceEnabled":true,"marketBaseRate":5.0,"eventId":"30896141","eventTypeId":"2","numberOfWinners":1,"bettingType":"ODDS","marketType":"MATCH_ODDS","marketTime":"2021-09-13T11:00:00.000Z","suspendTime":"2021-09-13T11:00:00.000Z","bspReconciled":false,"complete":true,"inPlay":false,"crossMatching":true,"runnersVoidable":false,"numberOfActiveRunners":2,"betDelay":0,"status":"OPEN","runners":[{"status":"ACTIVE","sortPriority":1,"id":9342449,"name":"Viktoria Kuzmova"},{"status":"ACTIVE","sortPriority":2,"id":9633869,"name":"Lucrezia Stefanini"}],"regulators":["MR_INT"],"discountAllowed":true,"timezone":"UTC","openDate":"2021-09-13T11:00:00.000Z","version":4030564247,"name":"Match Odds","eventName":"Kuzmova v Stefanini"}}]}
{"op":"mcm","clk":"4230228127","pt":1631530551506,"mc":[{"id":"1.187557995","rc":[{"trd":[[1.93,82.79]],"batb":[[0,1.93,53.96],[1,1.91,26.74],[2,1.9,46.4]],"ltp":1.93,"tv":1874.55,"id":9342449}],"tv":2654.09}]}
{"op":"mcm","clk":"4230242174","pt":1631530740298,"mc":[{"id":"1.187557995","rc":[{"batl":[[0,1.97,3.16],[1,1.98,428.73]],"ltp":1.93,"tv":1874.55,"id":9342449}]}]}
{"op":"mcm","clk":"4230242351","pt":1631530742077,"mc":[{"id":"1.187557995","rc":[{"trd":[[1.93,342.52]],"batb":[[0,1.91,26.74],[1,1.9,46.4],[2,1.89,28.77]],"batl":[[0,1.93,45.95],[1,1.97,3.16],[2,1.98,428.73]],"ltp":1.93,"tv":2134.27,"id":9342449}],"tv":2913.82}]}
{"op":"mcm","clk":"4230242403","pt":1631530742908,"mc":[{"id":"1.187557995","rc":[{"batb":[[2,1.88,2.66]],"ltp":1.93,"tv":2134.27,"id":9342449}]}]}
{"op":"mcm","clk":"4230243584","pt":1631530759639,"mc":[{"id":"1.187557995","marketDefinition":{"bspMarket":false,"turnInPlayEnabled":true,"persistenceEnabled":true,"marketBaseRate":5.0,"eventId":"30896141","eventTypeId":"2","numberOfWinners":1,"bettingType":"ODDS","marketType":"MATCH_ODDS","marketTime":"2021-09-13T11:20:00.000Z","suspendTime":"2021-09-13T11:20:00.000Z","bspReconciled":false,"complete":true,"inPlay":false,"crossMatching":true,"runnersVoidable":false,"numberOfActiveRunners":2,"betDelay":0,"status":"OPEN","runners":[{"status":"ACTIVE","sortPriority":1,"id":9342449,"name":"Viktoria Kuzmova"},{"status":"ACTIVE","sortPriority":2,"id":9633869,"name":"Lucrezia Stefanini"}],"regulators":["MR_INT"],"discountAllowed":true,"timezone":"UTC","openDate":"2021-09-13T11:00:00.000Z","version":4030568879,"name":"Match Odds","eventName":"Kuzmova v Stefanini"}}]}
{"op":"mcm","clk":"4230243796","pt":1631530762170,"mc":[{"id":"1.187557995","marketDefinition":{"bspMarket":false,"turnInPlayEnabled":true,"persistenceEnabled":true,"marketBaseRate":5.0,"eventId":"30896141","eventTypeId":"2","numberOfWinners":1,"bettingType":"ODDS","marketType":"MATCH_ODDS","marketTime":"2021-09-13T11:20:00.000Z","suspendTime":"2021-09-13T11:20:00.000Z","bspReconciled":false,"complete":true,"inPlay":false,"crossMatching":true,"runnersVoidable":false,"numberOfActiveRunners":2,"betDelay":0,"status":"OPEN","runners":[{"status":"ACTIVE","sortPriority":1,"id":9342449,"name":"Viktoria Kuzmova"},{"status":"ACTIVE","sortPriority":2,"id":9633869,"name":"Lucrezia Stefanini"}],"regulators":["MR_INT"],"discountAllowed":true,"timezone":"UTC","openDate":"2021-09-13T11:20:00.000Z","version":4030568879,"name":"Match Odds","eventName":"Kuzmova v Stefanini"}}]}
{"op":"mcm","clk":"4230281316","pt":1631531214443,"mc":[{"id":"1.187557995","rc":[{"trd":[[1.93,341.97],[1.95,372.26],[1.96,643.63],[1.97,217.48],[1.98,286.55],[1.99,19.98],[2,156.22],[2.02,91.84]],"batb":[[0,1.91,28.58],[2,1.88,2.66]],"batl":[[0,1.97,5.01],[1,1.98,429.74],[2,2,172.36]],"ltp":1.93,"tv":2130.58,"id":9342449},{"trd":[[1.99,8.06],[2,61.81],[2.02,89.78],[2.04,618.4]],"batb":[[0,2.02,29.99],[1,2,1101.36],[2,1.98,425.89]],"batl":[[0,2.08,864.01],[1,2.5,2.66],[2,29,48.37]],"ltp":2.04,"tv":778.05,"id":9633869}],"tv":2908.64}]}
{"op":"mcm","clk":"4230281389","pt":1631531215122,"mc":[{"id":"1.187557995","rc":[{"batb":[[2,1.89,28.71]],"ltp":1.93,"tv":2130.58,"id":9342449},{"batb":[[2,1.98,451.97]],"ltp":2.04,"tv":778.05,"id":9633869}]}]}
{"op":"mcm","clk":"4230282221","pt":1631531223382,"mc":[{"id":"1.187557995","rc":[{"trd":[[1.92,46.25]],"ltp":1.92,"tv":2176.83,"id":9342449},{"trd":[[2.08,42.69]],"batl":[[0,2.08,821.32]],"ltp":2.08,"tv":820.74,"id":9633869}],"tv":2997.58}]}
{"op":"mcm","clk":"4230299531","pt":1631531430677,"mc":[{"id":"1.187557995","rc":[{"batb":[[1,1.9,48.41]],"batl":[[0,1.94,3.41],[1,1.97,5.01],[2,1.98,429.74]],"ltp":1.92,"tv":2176.83,"id":9342449}]}]}
{"op":"mcm","clk":"4230299589","pt":1631531431399,"mc":[{"id":"1.187557995","rc":[{"batb":[[2,1.88,2.66]],"ltp":1.92,"tv":2176.83,"id":9342449}]}]}
{"op":"mcm","clk":"4230299793","pt":1631531434107,"mc":[{"id":"1.187557995","rc":[{"batb":[[1,1.9,46.4]],"batl":[[0,1.93,3.41]],"ltp":1.92,"tv":2176.83,"id":9342449}]}]}
{"op":"mcm","clk":"4230300076","pt":1631531437489,"mc":[{"id":"1.187557995","rc":[{"trd":[[1.92,49.65]],"batl":[[0,1.97,5.01],[1,1.98,429.74],[2,2,172.36]],"ltp":1.92,"tv":2180.24,"id":9342449},{"trd":[[2.08,45.83]],"batl":[[0,2.08,818.18]],"ltp":2.08,"tv":823.88,"id":9633869}],"tv":3004.13}]}
{"op":"mcm","clk":"4230300166","pt":1631531438318,"mc":[{"id":"1.187557995","rc":[{"batb":[[2,1.89,28.71]],"ltp":1.92,"tv":2180.24,"id":9342449}]}]}
{"op":"mcm","clk":"4230303218","pt":1631531475753,"mc":[{"id":"1.187557995","rc":[{"batl":[[0,2.06,16],[1,2.08,818.18],[2,2.5,2.66]],"ltp":2.08,"tv":823.88,"id":9633869}]}]}
{"op":"mcm","clk":"4230303933","pt":1631531484052,"mc":[{"id":"1.187557995","rc":[{"batb":[[1,1.9,48.46]],"batl":[[0,1.96,12],[1,1.97,5.01],[2,1.98,429.74]],"ltp":1.92,"tv":2180.24,"id":9342449}]}]}
{"op":"mcm","clk":"4230305114","pt":1631531499076,"mc":[{"id":"1.187557995","rc":[{"trd":[[1.96,644.05]],"batb":[[2,1.89,30.78]],"batl":[[0,1.96,11.79]],"ltp":1.96,"tv":2180.66,"id":9342449}],"tv":3004.55}]}
{"op":"mcm","clk":"4230306413","pt":1631531513586,"mc":[{"id":"1.187557995","rc":[{"trd":[[1.94,17.63]],"batl":[[0,1.95,5318.86],[1,1.96,14.9],[2,1.97,5.01]],"ltp":1.94,"tv":2197.63,"id":9342449},{"trd":[[2.06,15.98]],"batl":[[0,2.08,818.2],[1,2.44,7.23]],"ltp":2.06,"tv":839.86,"id":9633869}],"tv":3037.5}]}
{"op":"mcm","clk":"4230306477","pt":1631531514311,"mc":[{"id":"1.187557995","rc":[{"batb":[[2,1.89,2.07]],"ltp":1.94,"tv":2197.63,"id":9342449}]}]}
{"op":"mcm","clk":"4230306538","pt":1631531515091,"mc":[{"id":"1.187557995","rc":[{"trd":[[2.06,16.02],[2.08,291.7]],"batb":[[0,2.02,40.98],[1,2,1112.35]],"batl":[[0,2.08,695.25]],"ltp":2.08,"tv":1085.76,"id":9633869}],"tv":3283.4}]}
{"op":"mcm","clk":"4230312425","pt":1631531578416,"mc":[{"id":"1.187557995","rc":[{"trd":[[1.95,383.93]],"batl":[[0,1.95,5307.19]],"ltp":1.95,"tv":2209.3,"id":9342449},{"trd":[[2.04,629.55]],"batb":[[2,1.99,25.81]],"ltp":2.04,"tv":1096.92,"id":9633869}],"tv":3306.22}]}
{"op":"mcm","clk":"4230320028","pt":1631531668710,"mc":[{"id":"1.187557995","rc":[{"batb":[[2,1.89,74.87]],"ltp":1.95,"tv":2209.3,"id":9342449},{"batb":[[1,2,1232.94]],"ltp":2.04,"tv":1096.92,"id":9633869}]}]}
{"op":"mcm","clk":"4230323890","pt":1631531714567,"mc":[{"id":"1.187557995","rc":[{"trd":[[1.95,392.39]],"batl":[[0,1.95,5302.96]],"ltp":1.95,"tv":2217.76,"id":9342449}],"tv":3314.68}]}
{"op":"mcm","clk":"4230334032","pt":1631531846651,"mc":[{"id":"1.187557995","rc":[{"batb":[[0,1.93,113.3],[1,1.91,28.58],[2,1.9,48.46]],"ltp":1.95,"tv":2217.76,"id":9342449},{"batb":[[2,1.98,451.97]],"ltp":2.04,"tv":1096.92,"id":9633869}]}]}
{"op":"mcm","clk":"4230334107","pt":1631531847949,"mc":[{"id":"1.187557995","rc":[{"trd":[[1.95,399.16]],"batl":[[0,1.95,5299.57]],"ltp":1.95,"tv":2224.53,"id":9342449}],"tv":3321.45}]}
{"op":"mcm","clk":"4230334226","pt":1631531849459,"mc":[{"id":"1.187557995","rc":[{"trd":[[1.95,404.23]],"batl":[[0,1.95,5297.03]],"ltp":1.95,"tv":2229.6,"id":9342449}],"tv":3326.52}]}
{"op":"mcm","clk":"4230349401","pt":1631531940163,"mc":[{"id":"1.187557995","rc":[{"batb":[[1,1.91,26.69],[2,1.9,46.4]],"batl":[[0,1.95,5293.93],[1,1.96,11.79],[2,1.97,3.16]],"ltp":1.95,"tv":2229.6,"id":9342449},{"batb":[[0,2.02,29.99],[1,2,1221.95]],"ltp":2.04,"tv":1096.92,"id":9633869}]}]}
{"op":"mcm","clk":"4230350715","pt":1631531956605,"mc":[{"id":"1.187557995","marketDefinition":{"bspMarket":false,"turnInPlayEnabled":true,"persistenceEnabled":true,"marketBaseRate":5.0,"eventId":"30896141","eventTypeId":"2","numberOfWinners":1,"bettingType":"ODDS","marketType":"MATCH_ODDS","marketTime":"2021-09-13T11:25:00.000Z","suspendTime":"2021-09-13T11:25:00.000Z","bspReconciled":false,"complete":true,"inPlay":false,"crossMatching":true,"runnersVoidable":false,"numberOfActiveRunners":2,"betDelay":0,"status":"OPEN","runners":[{"status":"ACTIVE","sortPriority":1,"id":9342449,"name":"Viktoria Kuzmova"},{"status":"ACTIVE","sortPriority":2,"id":9633869,"name":"Lucrezia Stefanini"}],"regulators":["MR_INT"],"discountAllowed":true,"timezone":"UTC","openDate":"2021-09-13T11:20:00.000Z","version":4030582877,"name":"Match Odds","eventName":"Kuzmova v Stefanini"}}]}
{"op":"mcm","clk":"4230350761","pt":1631531957002,"mc":[{"id":"1.187557995","rc":[{"batl":[[0,1.95,5299.6],[1,1.96,17.46]],"ltp":1.95,"tv":2229.6,"id":9342449},{"batb":[[0,2.02,40.12],[1,2,1232.11]],"ltp":2.04,"tv":1096.92,"id":9633869}]}]}
{"op":"mcm","clk":"4230350962","pt":1631531959564,"mc":[{"id":"1.187557995","marketDefinition":{"bspMarket":false,"turnInPlayEnabled":true,"persistenceEnabled":true,"marketBaseRate":5.0,"eventId":"30896141","eventTypeId":"2","numberOfWinners":1,"bettingType":"ODDS","marketType":"MATCH_ODDS","marketTime":"2021-09-13T11:25:00.000Z","suspendTime":"2021-09-13T11:25:00.000Z","bspReconciled":false,"complete":true,"inPlay":false,"crossMatching":true,"runnersVoidable":false,"numberOfActiveRunners":2,"betDelay":0,"status":"OPEN","runners":[{"status":"ACTIVE","sortPriority":1,"id":9342449,"name":"Viktoria Kuzmova"},{"status":"ACTIVE","sortPriority":2,"id":9633869,"name":"Lucrezia Stefanini"}],"regulators":["MR_INT"],"discountAllowed":true,"timezone":"UTC","openDate":"2021-09-13T11:25:00.000Z","version":4030582877,"name":"Match Odds","eventName":"Kuzmova v Stefanini"}}]}
{"op":"mcm","clk":"4230351385","pt":1631531964501,"mc":[{"id":"1.187557995","rc":[{"batb":[[1,1.92,44.29],[2,1.91,26.69]],"ltp":1.95,"tv":2229.6,"id":9342449}]}]}
{"op":"mcm","clk":"4230353671","pt":1631531991908,"mc":[{"id":"1.187557995","rc":[{"batb":[[1,1.91,26.69],[2,1.9,46.4]],"ltp":1.95,"tv":2229.6,"id":9342449}]}]}
{"op":"mcm","clk":"4230362023","pt":1631532089357,"mc":[{"id":"1.187557995","rc":[{"batb":[[0,2.04,172.06],[1,2.02,40.12],[2,2,1232.11]],"ltp":2.04,"tv":1096.92,"id":9633869}]}]}
{"op":"mcm","clk":"4230362301","pt":1631532092861,"mc":[{"id":"1.187557995","rc":[{"batb":[[2,1.89,72.8]],"ltp":1.95,"tv":2229.6,"id":9342449}]}]}
{"op":"mcm","clk":"4230363362","pt":1631532104865,"mc":[{"id":"1.187557995","rc":[{"batb":[[1,1.9,37.82]],"ltp":1.95,"tv":2229.6,"id":9342449}]}]}
{"op":"mcm","clk":"4230368243","pt":1631532157394,"mc":[{"id":"1.187557995","rc":[{"trd":[[1.93,365.55]],"batb":[[0,1.93,101.51]],"batl":[[1,1.96,5.67],[2,1.97,8.68]],"ltp":1.93,"tv":2253.18,"id":9342449}],"tv":3350.1}]}
{"op":"mcm","clk":"4230375305","pt":1631532240229,"mc":[{"id":"1.187557995","rc":[{"batl":[[0,1.95,5293.93],[1,1.97,3.16],[2,1.98,427.89]],"ltp":1.93,"tv":2253.18,"id":9342449},{"batb":[[1,2.02,29.99],[2,2,1221.95]],"ltp":2.04,"tv":1096.92,"id":9633869}]}]}
{"op":"mcm","clk":"4230379099","pt":1631532289414,"mc":[{"id":"1.187557995","rc":[{"trd":[[2.08,387.38]],"batl":[[0,2.08,647.4]],"ltp":2.08,"tv":1192.6,"id":9633869}],"tv":3445.79}]}
{"op":"mcm","clk":"4230379942","pt":1631532300400,"mc":[{"id":"1.187557995","rc":[{"batb":[[1,1.89,72.8],[2,1.88,31.7]],"ltp":1.93,"tv":2253.18,"id":9342449},{"batb":[[1,2.02,4.96]],"ltp":2.08,"tv":1192.6,"id":9633869}]}]}
{"op":"mcm","clk":"4230384255","pt":1631532355243,"mc":[{"id":"1.187557995","rc":[{"batb":[[2,1.88,105.84]],"ltp":1.93,"tv":2253.18,"id":9342449},{"batb":[[1,2.02,123.28],[2,2,1101.36]],"ltp":2.08,"tv":1192.6,"id":9633869}]}]}
{"op":"mcm","clk":"4230384975","pt":1631532364937,"mc":[{"id":"1.187557995","rc":[{"batb":[[0,1.94,101.51]],"ltp":1.93,"tv":2253.18,"id":9342449}]}]}
{"op":"mcm","clk":"4230388111","pt":1631532407629,"mc":[{"id":"1.187557995","marketDefinition":{"bspMarket":false,"turnInPlayEnabled":true,"persistenceEnabled":true,"marketBaseRate":5.0,"eventId":"30896141","eventTypeId":"2","numberOfWinners":1,"bettingType":"ODDS","marketType":"MATCH_ODDS","marketTime":"2021-09-13T11:25:00.000Z","suspendTime":"2021-09-13T11:25:00.000Z","bspReconciled":false,"complete":true,"inPlay":false,"crossMatching":true,"runnersVoidable":false,"numberOfActiveRunners":2,"betDelay":0,"status":"OPEN","runners":[{"status":"ACTIVE","sortPriority":1,"id":9342449,"name":"Viktoria Kuzmova"},{"status":"ACTIVE","sortPriority":2,"id":9633869,"name":"Lucrezia Stefanini"}],"regulators":["MR_INT"],"discountAllowed":true,"timezone":"UTC","openDate":"2021-09-13T11:25:00.000Z","version":4030582877,"name":"Match Odds","eventName":"Kuzmova v Stefanini"},"rc":[{"batb":[[1,1.88,31.7],[2,1.86,29.71]],"ltp":1.93,"tv":2253.18,"id":9342449},{"batb":[[1,2.02,4.96]],"ltp":2.08,"tv":1192.6,"id":9633869}]}]}
{"op":"mcm","clk":"4230388125","pt":1631532407849,"mc":[{"id":"1.187557995","marketDefinition":{"bspMarket":false,"turnInPlayEnabled":true,"persistenceEnabled":true,"marketBaseRate":5.0,"eventId":"30896141","eventTypeId":"2","numberOfWinners":1,"bettingType":"ODDS","marketType":"MATCH_ODDS","marketTime":"2021-09-13T11:25:00.000Z","suspendTime":"2021-09-13T11:25:00.000Z","bspReconciled":false,"complete":true,"inPlay":true,"crossMatching":true,"runnersVoidable":false,"numberOfActiveRunners":2,"betDelay":3,"status":"OPEN","runners":[{"status":"ACTIVE","sortPriority":1,"id":9342449,"name":"Viktoria Kuzmova"},{"status":"ACTIVE","sortPriority":2,"id":9633869,"name":"Lucrezia Stefanini"}],"regulators":["MR_INT"],"discountAllowed":true,"timezone":"UTC","openDate":"2021-09-13T11:25:00.000Z","version":4030588606,"name":"Match Odds","eventName":"Kuzmova v Stefanini"},"rc":[{"batb":[[1,1.8,3.41],[2,1.29,3.45]],"batl":[[1,1.98,425.89],[2,2,2]],"ltp":1.93,"tv":2253.18,"id":9342449},{"batb":[[0,1.95,4.26],[1,1.9,11.71],[2,1.67,1.38]],"ltp":2.08,"tv":1192.6,"id":9633869}]}]}
{"op":"mcm","clk":"4230388988","pt":1631532417631,"mc":[{"id":"1.187557995","rc":[{"trd":[[1.94,220.65]],"batb":[[0,1.92,107.39]],"batl":[[0,1.94,16.58],[1,1.95,5399.66],[2,1.98,425.89]],"ltp":1.94,"tv":2456.2,"id":9342449}],"tv":3648.81}]}
{"op":"mcm","clk":"4230389009","pt":1631532417942,"mc":[{"id":"1.187557995","rc":[{"batb":[[0,1.8,3.41],[1,1.29,3.45],[2,1.2,2]],"batl":[[0,1.95,5293.93],[1,1.98,425.89],[2,2,2]],"ltp":1.94,"tv":2456.2,"id":9342449}]}]}
{"op":"mcm","clk":"4230389570","pt":1631532424457,"mc":[{"id":"1.187557995","rc":[{"trd":[[1.95,433.98]],"batl":[[0,1.95,5279.06]],"ltp":1.95,"tv":2485.95,"id":9342449}],"tv":3678.56}]}
{"op":"mcm","clk":"4230390929","pt":1631532441466,"mc":[{"id":"1.187557995","rc":[{"trd":[[1.95,3583.44]],"batl":[[0,1.95,2129.6]],"ltp":1.95,"tv":5635.41,"id":9342449},{"trd":[[2.04,3640.05]],"batl":[[0,2.1,13.62]],"ltp":2.04,"tv":4203.1,"id":9633869}],"tv":9838.52}]}
{"op":"mcm","clk":"4230391068","pt":1631532443396,"mc":[{"id":"1.187557995","rc":[{"trd":[[1.95,3843.02]],"batb":[[0,1.85,76.99],[1,1.8,3.41],[2,1.29,3.45]],"batl":[[0,1.95,1999.81]],"ltp":1.95,"tv":5894.99,"id":9342449},{"batb":[[1,1.93,67.7],[2,1.9,11.71]],"ltp":2.04,"tv":4203.1,"id":9633869}],"tv":10098.09}]}
{"op":"mcm","clk":"4230391170","pt":1631532444648,"mc":[{"id":"1.187557995","rc":[{"trd":[[1.95,7196.87]],"batl":[[0,1.95,184.47]],"ltp":1.95,"tv":9248.84,"id":9342449},{"trd":[[2.04,3904.67]],"ltp":2.04,"tv":4467.72,"id":9633869}],"tv":13716.57}]}
{"op":"mcm","clk":"4230391226","pt":1631532445381,"mc":[{"id":"1.187557995","rc":[{"trd":[[1.95,7229.83]],"batb":[[0,1.94,4],[1,1.85,76.99],[2,1.8,3.41]],"batl":[[0,1.95,165.9]],"ltp":1.95,"tv":9281.8,"id":9342449},{"trd":[[2.04,3908.67]],"ltp":2.04,"tv":4471.72,"id":9633869}],"tv":13753.53}]}
{"op":"mcm","clk":"4230391339","pt":1631532446596,"mc":[{"id":"1.187557995","rc":[{"trd":[[1.94,228.65]],"batb":[[0,1.86,110.85]],"batl":[[0,1.94,42.1],[1,1.95,165.9],[2,1.98,425.89]],"ltp":1.94,"tv":9289.8,"id":9342449}],"tv":13761.53}]}
{"op":"mcm","clk":"4230391414","pt":1631532447482,"mc":[{"id":"1.187557995","rc":[{"trd":[[1.94,270.75],[1.95,7240.66]],"batl":[[0,1.95,155.07],[1,1.98,425.89],[2,2,2]],"ltp":1.95,"tv":9342.73,"id":9342449},{"trd":[[2.04,3919.02],[2.06,55.67]],"ltp":2.04,"tv":4521.72,"id":9633869}],"tv":13864.46}]}
{"op":"mcm","clk":"4230391514","pt":1631532448576,"mc":[{"id":"1.187557995","rc":[{"trd":[[1.95,7395.73],[1.98,392.78]],"batl":[[0,1.98,319.67],[1,2,2],[2,2.1,7.97]],"ltp":1.98,"tv":9604.03,"id":9342449},{"trd":[[2.02,193.9],[2.04,4067.25]],"batb":[[2,1.91,157.49]],"ltp":2.02,"tv":4774.07,"id":9633869}],"tv":14378.1}]}
{"op":"mcm","clk":"4230391594","pt":1631532449567,"mc":[{"id":"1.187557995","rc":[{"batb":[[0,1.95,167.52],[1,1.86,110.85],[2,1.85,76.99]],"ltp":1.98,"tv":9604.03,"id":9342449}]}]}
{"op":"mcm","clk":"4230391609","pt":1631532449777,"mc":[{"id":"1.187557995","rc":[{"batb":[[0,1.95,283.54],[1,1.93,4],[2,1.86,110.85]],"ltp":1.98,"tv":9604.03,"id":9342449},{"batl":[[0,2.06,4]],"ltp":2.02,"tv":4774.07,"id":9633869}]}]}
{"op":"mcm","clk":"4230391777","pt":1631532451666,"mc":[{"id":"1.187557995","rc":[{"trd":[[1.98,654.85]],"batb":[[0,1.97,4],[1,1.95,227.58],[2,1.93,4]],"batl":[[0,1.98,61.59]],"ltp":1.98,"tv":9866.1,"id":9342449},{"trd":[[2.02,442.94]],"batb":[[0,1.98,170.61],[1,1.95,4.26],[2,1.93,230.03]],"ltp":2.02,"tv":5023.11,"id":9633869}],"tv":14889.22}]}
{"op":"mcm","clk":"4230391837","pt":1631532452291,"mc":[{"id":"1.187557995","rc":[{"batb":[[0,1.93,98.66],[1,1.86,110.85],[2,1.85,76.99]],"ltp":1.98,"tv":9866.1,"id":9342449}]}]}
{"op":"mcm","clk":"4230391878","pt":1631532452863,"mc":[{"id":"1.187557995","rc":[{"batb":[[0,1.94,97.99],[1,1.93,98.66],[2,1.86,110.85]],"ltp":1.98,"tv":9866.1,"id":9342449},{"batl":[[1,2.2,95.39]],"ltp":2.02,"tv":5023.11,"id":9633869}]}]}
{"op":"mcm","clk":"4230392034","pt":1631532454592,"mc":[{"id":"1.187557995","rc":[{"trd":[[1.98,716.44]],"batb":[[0,1.96,94.29],[1,1.95,95.87]],"batl":[[0,2,2],[1,2.1,7.97],[2,2.16,2]],"ltp":1.98,"tv":9927.69,"id":9342449},{"trd":[[2.02,503.31]],"batb":[[1,1.95,154.32]],"batl":[[0,2.02,48.23],[1,2.04,131.43],[2,2.06,4]],"ltp":2.02,"tv":5083.48,"id":9633869}],"tv":15011.18}]}
{"op":"mcm","clk":"4230392104","pt":1631532455479,"mc":[{"id":"1.187557995","rc":[{"batb":[[0,1.87,4],[1,1.86,115.85],[2,1.85,76.99]],"ltp":1.98,"tv":9927.69,"id":9342449},{"batb":[[1,1.95,4.26],[2,1.93,67.7]],"batl":[[0,2.04,131.43],[1,2.06,4],[2,2.16,92.12]],"ltp":2.02,"tv":5083.48,"id":9633869}]}]}
{"op":"mcm","clk":"4230392258","pt":1631532457572,"mc":[{"id":"1.187557995","rc":[{"batb":[[0,1.86,5],[1,1.85,76.99],[2,1.8,3.41]],"ltp":1.98,"tv":9927.69,"id":9342449},{"batb":[[2,1.9,11.71]],"ltp":2.02,"tv":5083.48,"id":9633869}]}]}
{"op":"mcm","clk":"4230392511","pt":1631532460621,"mc":[{"id":"1.187557995","rc":[{"batb":[[1,1.85,78.99],[2,1.84,79.25]],"batl":[[1,2.02,5],[2,2.1,7.97]],"ltp":1.98,"tv":9927.69,"id":9342449},{"batb":[[2,1.91,74.56]],"batl":[[0,2.16,148.33],[1,2.18,110.79]],"ltp":2.02,"tv":5083.48,"id":9633869}]}]}
{"op":"mcm","clk":"4230392596","pt":1631532461717,"mc":[{"id":"1.187557995","rc":[{"batl":[[0,2.18,2],[1,2.18,0]],"ltp":2.02,"tv":5083.48,"id":9633869}]}]}
{"op":"mcm","clk":"4230392650","pt":1631532462495,"mc":[{"id":"1.187557995","rc":[{"batb":[[0,1.84,79.25],[1,1.8,3.41],[2,1.29,3.45]],"ltp":1.98,"tv":9927.69,"id":9342449}]}]}
{"op":"mcm","clk":"4230392839","pt":1631532464693,"mc":[{"id":"1.187557995","rc":[{"batb":[[0,1.86,190.18],[1,1.84,256.76],[2,1.82,577.95]],"batl":[[0,1.93,134.37],[1,1.95,150.71],[2,1.96,975.78]],"ltp":1.98,"tv":9927.69,"id":9342449}]}]}
{"op":"mcm","clk":"4230392929","pt":1631532465681,"mc":[{"id":"1.187557995","rc":[{"batb":[[0,2.1,110.37],[1,1.99,65.86],[2,1.98,170.61]],"batl":[[0,2.18,11.17]],"ltp":2.02,"tv":5083.48,"id":9633869}]}]}
{"op":"mcm","clk":"4230393011","pt":1631532466677,"mc":[{"id":"1.187557995","rc":[{"trd":[[1.93,499.92]],"batl":[[0,1.95,150.71],[1,1.96,975.78],[2,1.97,947.06]],"ltp":1.93,"tv":10062.06,"id":9342449},{"trd":[[2.06,181.56],[2.1,220.75]],"batb":[[0,1.99,65.86],[1,1.98,170.61],[2,1.95,4.26]],"batl":[[0,2.06,18.45],[1,2.18,11.17]],"ltp":2.06,"tv":5430.13,"id":9633869}],"tv":15492.2}]}
{"op":"mcm","clk":"4230393074","pt":1631532467510,"mc":[{"id":"1.187557995","rc":[{"batb":[[0,1.84,84.25],[1,1.82,577.95],[2,1.81,560.96]],"batl":[[0,1.96,975.78],[1,1.97,947.06],[2,1.98,947.06]],"ltp":1.93,"tv":10062.06,"id":9342449},{"batb":[[0,2,2],[1,1.99,67.86],[2,1.98,170.61]],"batl":[[1,2.16,2],[2,2.18,11.17]],"ltp":2.06,"tv":5430.13,"id":9633869}]}]}
{"op":"mcm","clk":"4230393162","pt":1631532468605,"mc":[{"id":"1.187557995","rc":[{"batb":[[0,1.87,84.54],[1,1.84,84.25],[2,1.82,577.95]],"ltp":1.93,"tv":10062.06,"id":9342449}]}]}
{"op":"mcm","clk":"4230393247","pt":1631532469594,"mc":[{"id":"1.187557995","rc":[{"batl":[[0,2.16,2],[1,2.18,11.17],[2,2.18,0]],"ltp":2.06,"tv":5430.13,"id":9633869}]}]}
{"op":"mcm","clk":"4230393336","pt":1631532470478,"mc":[{"id":"1.187557995","rc":[{"batb":[[0,1.87,264.73],[1,1.85,265.22],[2,1.84,84.25]],"batl":[[0,1.94,135.96],[1,1.96,1124.13],[2,1.97,947.06]],"ltp":1.93,"tv":10062.06,"id":9342449},{"batb":[[0,2.06,141.03],[1,2,2],[2,1.99,67.86]],"ltp":2.06,"tv":5430.13,"id":9633869}]}]}
{"op":"mcm","clk":"4230393560","pt":1631532473181,"mc":[{"id":"1.187557995","rc":[{"batb":[[0,1.88,110.81],[1,1.87,264.73],[2,1.85,265.22]],"ltp":1.93,"tv":10062.06,"id":9342449}]}]}
{"op":"mcm","clk":"4230393706","pt":1631532474702,"mc":[{"id":"1.187557995","rc":[{"batb":[[0,1.83,1642],[1,1.8,3.41],[2,1.72,97.82]],"batl":[[0,2,2],[1,2.02,5],[2,2.1,7.97]],"ltp":1.93,"tv":10062.06,"id":9342449},{"batb":[[0,1.99,65.86],[1,1.98,170.61],[2,1.95,4.26]],"ltp":2.06,"tv":5430.13,"id":9633869}]}]}
{"op":"mcm","clk":"4230393743","pt":1631532475225,"mc":[{"id":"1.187557995","rc":[{"batb":[[0,1.8,3.41],[1,1.72,97.82],[2,1.29,3.45]],"ltp":1.93,"tv":10062.06,"id":9342449}]}]}
{"op":"mcm","clk":"4230393941","pt":1631532477715,"mc":[{"id":"1.187557995","rc":[{"batb":[[1,1.76,163.8],[2,1.74,309.07]],"batl":[[2,2.06,120.49]],"ltp":1.93,"tv":10062.06,"id":9342449},{"batb":[[0,1.98,170.61],[1,1.95,4.26],[2,1.94,67.11]],"ltp":2.06,"tv":5430.13,"id":9633869}]}]}
{"op":"mcm","clk":"4230394571","pt":1631532485202,"mc":[{"id":"1.187557995","rc":[{"batl":[[2,2.1,7.97]],"ltp":1.93,"tv":10062.06,"id":9342449}]}]}
{"op":"mcm","clk":"4230394869","pt":1631532488414,"mc":[{"id":"1.187557995","rc":[{"batl":[[0,1.81,14.69],[1,1.82,162.04],[2,1.84,1219.99]],"ltp":1.93,"tv":10062.06,"id":9342449},{"batl":[[0,2.38,441.96],[1,2.4,428.97],[2,2.42,428.97]],"ltp":2.06,"tv":5430.13,"id":9633869}]}]}
{"op":"mcm","clk":"4230394957","pt":1631532489506,"mc":[{"id":"1.187557995","rc":[{"batb":[[0,2.22,90.71],[1,2.06,110.96],[2,1.98,170.61]],"batl":[[0,2.32,8.62],[1,2.38,441.96],[2,2.4,428.97]],"ltp":2.06,"tv":5430.13,"id":9633869}]}]}
{"op":"mcm","clk":"4230395069","pt":1631532490913,"mc":[{"id":"1.187557995","rc":[{"batb":[[2,2.02,2]],"ltp":2.06,"tv":5430.13,"id":9633869}]}]}
{"op":"mcm","clk":"4230395195","pt":1631532492161,"mc":[{"id":"1.187557995","rc":[{"trd":[[1.8,4.65]],"batb":[[0,1.8,1.08],[1,1.78,109.65],[2,1.76,163.8]],"ltp":1.8,"tv":10066.71,"id":9342449}],"tv":15496.84}]}
{"op":"mcm","clk":"4230395581","pt":1631532496208,"mc":[{"id":"1.187557995","rc":[{"batb":[[1,1.79,97.59],[2,1.78,109.65]],"ltp":1.8,"tv":10066.71,"id":9342449}]}]}
{"op":"mcm","clk":"4230395815","pt":1631532498700,"mc":[{"id":"1.187557995","rc":[{"trd":[[1.81,29.37]],"batb":[[0,1.81,9.03],[1,1.8,1.08],[2,1.79,97.59]],"batl":[[0,1.82,162.04],[1,1.84,1219.99],[2,1.85,1008.82]],"ltp":1.81,"tv":10096.09,"id":9342449}],"tv":15526.22}]}
{"op":"mcm","clk":"4230395852","pt":1631532499013,"mc":[{"id":"1.187557995","rc":[{"batb":[[0,1.8,1.08],[1,1.79,97.59],[2,1.78,109.65]],"ltp":1.81,"tv":10096.09,"id":9342449}]}]}
{"op":"mcm","clk":"4230396057","pt":1631532501251,"mc":[{"id":"1.187557995","rc":[{"batl":[[0,1.81,108],[1,1.82,162.04],[2,1.84,1219.99]],"ltp":1.81,"tv":10096.09,"id":9342449}]}]}
{"op":"mcm","clk":"4230396120","pt":1631532501937,"mc":[{"id":"1.187557995","rc":[{"trd":[[1.8,21.69]],"batb":[[0,1.8,70.28],[1,1.76,163.8],[2,1.74,309.07]],"ltp":1.8,"tv":10113.13,"id":9342449}],"tv":15543.26}]}
{"op":"mcm","clk":"4230396370","pt":1631532504647,"mc":[{"id":"1.187557995","rc":[{"trd":[[2.22,48.5]],"batb":[[0,2.22,66.46]],"ltp":2.22,"tv":5478.63,"id":9633869}],"tv":15591.76}]}
{"op":"mcm","clk":"4230396463","pt":1631532505648,"mc":[{"id":"1.187557995","rc":[{"batb":[[0,1.77,76.32]],"batl":[[0,1.82,162.04],[1,1.84,180.59],[2,2,2]],"ltp":1.8,"tv":10113.13,"id":9342449}]}]}
{"op":"mcm","clk":"4230396491","pt":1631532506016,"mc":[{"id":"1.187557995","rc":[{"batb":[[0,1.62,121.25],[1,1.29,3.45],[2,1.2,2]],"batl":[[0,2,2],[1,2.02,5],[2,2.1,7.97]],"ltp":1.8,"tv":10113.13,"id":9342449},{"batb":[[0,2.06,110.96],[1,2.02,2],[2,1.98,170.61]],"ltp":2.22,"tv":5478.63,"id":9633869}]}]}
{"op":"mcm","clk":"4230396677","pt":1631532508452,"mc":[{"id":"1.187557995","rc":[{"batb":[[2,1.2,388.24]],"ltp":1.8,"tv":10113.13,"id":9342449}]}]}
{"op":"mcm","clk":"4230396759","pt":1631532509442,"mc":[{"id":"1.187557995","rc":[{"batb":[[0,1.63,5],[1,1.62,127.25],[2,1.29,3.45]],"batl":[[0,1.94,4],[1,2,2],[2,2.02,5]],"ltp":1.8,"tv":10113.13,"id":9342449},{"batb":[[0,2.06,114.96]],"batl":[[0,2.6,3]],"ltp":2.22,"tv":5478.63,"id":9633869}]}]}
{"op":"mcm","clk":"4230396822","pt":1631532510332,"mc":[{"id":"1.187557995","rc":[{"batb":[[0,1.81,14.87],[1,1.63,5],[2,1.62,127.25]],"ltp":1.8,"tv":10113.13,"id":9342449}]}]}
{"op":"mcm","clk":"4230396932","pt":1631532511518,"mc":[{"id":"1.187557995","rc":[{"batl":[[1,1.95,4],[2,2,2]],"ltp":1.8,"tv":10113.13,"id":9342449},{"batb":[[1,2.04,4],[2,2.02,2]],"batl":[[1,2.62,3]],"ltp":2.22,"tv":5478.63,"id":9633869}]}]}
{"op":"mcm","clk":"4230397018","pt":1631532512658,"mc":[{"id":"1.187557995","rc":[{"trd":[[1.81,59.12]],"batb":[[0,1.74,145.76],[1,1.72,222.36],[2,1.66,5]],"batl":[[0,1.8,183.42],[1,1.82,186.95],[2,1.93,5]],"ltp":1.81,"tv":10142.87,"id":9342449},{"batl":[[0,2.52,3],[1,2.6,3],[2,2.62,3]],"ltp":2.22,"tv":5478.63,"id":9633869}],"tv":15621.5}]}
{"op":"mcm","clk":"4230397106","pt":1631532513640,"mc":[{"id":"1.187557995","rc":[{"batb":[[0,1.66,5],[1,1.65,5],[2,1.63,5]],"batl":[[0,1.93,5],[1,1.94,4],[2,1.95,4]],"ltp":1.81,"tv":10142.87,"id":9342449}]}]}
{"op":"mcm","clk":"4230397414","pt":1631532517367,"mc":[{"id":"1.187557995","rc":[{"batb":[[0,1.66,139.21],[1,1.65,134.47]],"batl":[[0,1.93,117.35],[2,1.95,154.68]],"ltp":1.81,"tv":10142.87,"id":9342449}]}]}
{"op":"mcm","clk":"4230397471","pt":1631532517935,"mc":[{"id":"1.187557995","rc":[{"batb":[[0,1.66,5],[1,1.65,5]],"ltp":1.81,"tv":10142.87,"id":9342449}]}]}
{"op":"mcm","clk":"4230397652","pt":1631532520670,"mc":[{"id":"1.187557995","rc":[{"batb":[[0,1.86,1606.95],[1,1.84,2078.8],[2,1.83,2017.66]],"batl":[[0,1.93,112.35],[1,1.95,150.68],[2,1.96,1951.54]],"ltp":1.81,"tv":10142.87,"id":9342449},{"batb":[[0,2.06,110.96],[1,1.98,170.61],[2,1.95,4.26]],"batl":[[0,2.18,9.17],[1,2.52,3],[2,2.6,3]],"ltp":2.22,"tv":5478.63,"id":9633869}]}]}
{"op":"mcm","clk":"4230397727","pt":1631532521548,"mc":[{"id":"1.187557995","rc":[{"batb":[[0,1.87,126.11],[1,1.86,15.28],[2,1.85,252.76]],"batl":[[2,1.96,536.68]],"ltp":1.81,"tv":10142.87,"id":9342449}]}]}
{"op":"mcm","clk":"4230397890","pt":1631532523668,"mc":[{"id":"1.187557995","rc":[{"batb":[[1,2,4],[2,1.99,3]],"ltp":2.22,"tv":5478.63,"id":9633869}]}]}
{"op":"mcm","clk":"4230397972","pt":1631532524653,"mc":[{"id":"1.187557995","rc":[{"batb":[[0,1.88,80.76],[1,1.87,126.11],[2,1.86,15.28]],"ltp":1.81,"tv":10142.87,"id":9342449},{"batl":[[2,2.6,0]],"ltp":2.22,"tv":5478.63,"id":9633869}]}]}
{"op":"mcm","clk":"4230398070","pt":1631532525639,"mc":[{"id":"1.187557995","rc":[{"trd":[[1.87,52.3],[1.88,161.52]],"batb":[[0,1.87,99.96],[1,1.86,15.28],[2,1.85,252.76]],"ltp":1.87,"tv":10356.69,"id":9342449}],"tv":15835.32}]}
{"op":"mcm","clk":"4230398234","pt":1631532527661,"mc":[{"id":"1.187557995","rc":[{"batl":[[2,2.6,5.26]],"ltp":2.22,"tv":5478.63,"id":9633869}]}]}
{"op":"mcm","clk":"4230398290","pt":1631532528592,"mc":[{"id":"1.187557995","rc":[{"batb":[[0,1.88,75.1],[1,1.87,99.96],[2,1.86,15.28]],"batl":[[0,1.92,46.73],[1,1.93,112.35],[2,1.95,150.68]],"ltp":1.87,"tv":10356.69,"id":9342449}]}]}
{"op":"mcm","clk":"4230398305","pt":1631532528749,"mc":[{"id":"1.187557995","rc":[{"batl":[[1,1.93,126.35]],"ltp":1.87,"tv":10356.69,"id":9342449}]}]}
{"op":"mcm","clk":"4230398543","pt":1631532531590,"mc":[{"id":"1.187557995","rc":[{"trd":[[1.88,191.26]],"batb":[[0,1.88,60.23]],"ltp":1.88,"tv":10386.44,"id":9342449}],"tv":15865.07}]}
{"op":"mcm","clk":"4230398617","pt":1631532532469,"mc":[{"id":"1.187557995","rc":[{"batb":[[2,1.85,252.76]],"ltp":1.88,"tv":10386.44,"id":9342449}]}]}
{"op":"mcm","clk":"4230398734","pt":1631532534168,"mc":[{"id":"1.187557995","rc":[{"trd":[[1.87,73.02],[1.88,311.72]],"batb":[[0,1.87,89.6],[1,1.85,252.76],[2,1.84,1039.4]],"ltp":1.87,"tv":10527.62,"id":9342449}],"tv":16006.25}]}
{"op":"mcm","clk":"4230398778","pt":1631532534791,"mc":[{"id":"1.187557995","rc":[{"batb":[[0,1.85,78.41],[1,1.84,1039.4],[2,1.83,1008.82]],"ltp":1.87,"tv":10527.62,"id":9342449}]}]}
{"op":"mcm","clk":"4230398903","pt":1631532536599,"mc":[{"id":"1.187557995","rc":[{"batb":[[2,1.98,170.61]],"ltp":2.22,"tv":5478.63,"id":9633869}]}]}
{"op":"mcm","clk":"4230398978","pt":1631532537693,"mc":[{"id":"1.187557995","rc":[{"batb":[[0,1.86,192.7],[1,1.85,78.41],[2,1.84,177.5]],"batl":[[0,1.93,126.35],[1,1.95,150.68],[2,1.97,29.5]],"ltp":1.87,"tv":10527.62,"id":9342449},{"batl":[[0,2.52,3],[1,2.6,5.26],[2,2.62,4.75]],"ltp":2.22,"tv":5478.63,"id":9633869}]}]}
{"op":"mcm","clk":"4230399028","pt":1631532538260,"mc":[{"id":"1.187557995","rc":[{"batb":[[0,1.7,102.51],[1,1.66,5],[2,1.3,198.07]],"batl":[[0,2,7],[1,2.06,8.25],[2,2.1,7.97]],"ltp":1.87,"tv":10527.62,"id":9342449},{"batb":[[0,2,4],[1,1.98,170.61],[2,1.95,4.26]],"batl":[[1,2.62,4.75],[2,2.62,0]],"ltp":2.22,"tv":5478.63,"id":9633869}]}]}
{"op":"mcm","clk":"4230399128","pt":1631532539706,"mc":[{"id":"1.187557995","rc":[{"batb":[[1,1.99,4],[2,1.98,170.61]],"ltp":2.22,"tv":5478.63,"id":9633869}]}]}
{"op":"mcm","clk":"4230399214","pt":1631532540698,"mc":[{"id":"1.187557995","rc":[{"batb":[[0,1.73,143.61],[1,1.71,226.91],[2,1.7,102.51]],"batl":[[2,2.08,116.66]],"ltp":1.87,"tv":10527.62,"id":9342449}]}]}
{"op":"mcm","clk":"4230399276","pt":1631532541477,"mc":[{"id":"1.187557995","rc":[{"batb":[[2,1.7,107.51]],"batl":[[0,2,33.22]],"ltp":1.87,"tv":10527.62,"id":9342449},{"batl":[[0,2.44,4],[1,2.52,3],[2,2.62,4.75]],"ltp":2.22,"tv":5478.63,"id":9633869}]}]}
{"op":"mcm","clk":"4230399301","pt":1631532541788,"mc":[{"id":"1.187557995","rc":[{"batl":[[0,2,7]],"ltp":1.87,"tv":10527.62,"id":9342449}]}]}
{"op":"mcm","clk":"4230399466","pt":1631532543862,"mc":[{"id":"1.187557995","rc":[{"batl":[[0,1.85,70.59],[1,2,7],[2,2.06,8.25]],"ltp":1.87,"tv":10527.62,"id":9342449}]}]}
{"op":"mcm","clk":"4230399672","pt":1631532546607,"mc":[{"id":"1.187557995","rc":[{"batl":[[0,2,7],[1,2.06,8.25],[2,2.08,116.66]],"ltp":1.87,"tv":10527.62,"id":9342449},{"batb":[[0,2,28.54]],"ltp":2.22,"tv":5478.63,"id":9633869}]}]}
{"op":"mcm","clk":"4230399733","pt":1631532547593,"mc":[{"id":"1.187557995","rc":[{"batb":[[0,1.7,107.51],[1,1.69,5],[2,1.66,5]],"batl":[[2,2.1,12.93]],"ltp":1.87,"tv":10527.62,"id":9342449},{"batb":[[0,2,4]],"ltp":2.22,"tv":5478.63,"id":9633869}]}]}
{"op":"mcm","clk":"4230399819","pt":1631532548572,"mc":[{"id":"1.187557995","rc":[{"batb":[[0,1.85,17.68],[1,1.7,107.51],[2,1.69,5]],"batl":[[0,2,32.61]],"ltp":1.87,"tv":10527.62,"id":9342449}]}]}
{"op":"mcm","clk":"4230399906","pt":1631532549714,"mc":[{"id":"1.187557995","rc":[{"trd":[[2,174.22]],"batb":[[0,2,2330.72],[1,1.85,8.85],[2,1.7,107.51]],"batl":[[0,2.06,8.25],[1,2.1,12.93],[2,2.16,2]],"ltp":2.0,"tv":10545.62,"id":9342449},{"trd":[[2,65.81]],"batb":[[0,1.99,4],[1,1.98,170.61],[2,1.95,30.57]],"ltp":2.0,"tv":5482.63,"id":9633869}],"tv":16028.25}]}
{"op":"mcm","clk":"4230399983","pt":1631532550594,"mc":[{"id":"1.187557995","rc":[{"batb":[[0,1.99,961.06],[1,1.98,932.8],[2,1.97,932.8]],"ltp":2.0,"tv":10545.62,"id":9342449},{"batb":[[0,1.98,170.61],[1,1.95,30.57],[2,1.93,68.03]],"batl":[[0,1.99,106.11],[1,2.02,203.87],[2,2.06,9.71]],"ltp":2.0,"tv":5482.63,"id":9633869}]}]}
{"op":"mcm","clk":"4230400058","pt":1631532551681,"mc":[{"id":"1.187557995","rc":[{"batb":[[2,1.97,1062]],"batl":[[2,2.14,9.35]],"ltp":2.0,"tv":10545.62,"id":9342449}]}]}
{"op":"mcm","clk":"4230400194","pt":1631532553480,"mc":[{"id":"1.187557995","rc":[{"batb":[[0,2,4],[1,1.99,965.06],[2,1.98,932.8]],"ltp":2.0,"tv":10545.62,"id":9342449},{"batl":[[1,2,4],[2,2.02,203.87]],"ltp":2.0,"tv":5482.63,"id":9633869}]}]}
{"op":"mcm","clk":"4230400276","pt":1631532554620,"mc":[{"id":"1.187557995","rc":[{"batb":[[0,2,69.92]],"batl":[[0,2.06,72.25]],"ltp":2.0,"tv":10545.62,"id":9342449}]}]}
{"op":"mcm","clk":"4230400346","pt":1631532555609,"mc":[{"id":"1.187557995","rc":[{"trd":[[1.98,55.56]],"batb":[[0,1.98,142.84]],"ltp":1.98,"tv":5538.18,"id":9633869}],"tv":16083.8}]}
{"op":"mcm","clk":"4230400386","pt":1631532556124,"mc":[{"id":"1.187557995","rc":[{"batl":[[0,2.04,74.38],[1,2.06,72.25],[2,2.1,12.93]],"ltp":2.0,"tv":10545.62,"id":9342449},{"batb":[[2,1.94,36.69]],"ltp":1.98,"tv":5538.18,"id":9633869}]}]}
{"op":"mcm","clk":"4230400615","pt":1631532558714,"mc":[{"id":"1.187557995","rc":[{"batl":[[2,2.1,20.38]],"ltp":2.0,"tv":10545.62,"id":9342449},{"batb":[[1,1.95,68.12]],"ltp":1.98,"tv":5538.18,"id":9633869}]}]}
{"op":"mcm","clk":"4230400655","pt":1631532559152,"mc":[{"id":"1.187557995","marketDefinition":{"bspMarket":false,"turnInPlayEnabled":true,"persistenceEnabled":true,"marketBaseRate":5.0,"eventId":"30896141","eventTypeId":"2","numberOfWinners":1,"bettingType":"ODDS","marketType":"MATCH_ODDS","marketTime":"2021-09-13T11:30:00.000Z","suspendTime":"2021-09-13T11:30:00.000Z","bspReconciled":false,"complete":true,"inPlay":true,"crossMatching":true,"runnersVoidable":false,"numberOfActiveRunners":2,"betDelay":3,"status":"OPEN","runners":[{"status":"ACTIVE","sortPriority":1,"id":9342449,"name":"Viktoria Kuzmova"},{"status":"ACTIVE","sortPriority":2,"id":9633869,"name":"Lucrezia Stefanini"}],"regulators":["MR_INT"],"discountAllowed":true,"timezone":"UTC","openDate":"2021-09-13T11:25:00.000Z","version":4030590407,"name":"Match Odds","eventName":"Kuzmova v Stefanini"}}]}
{"op":"mcm","clk":"4230400785","pt":1631532560426,"mc":[{"id":"1.187557995","rc":[{"batb":[[0,1.84,26.22],[1,1.83,81],[2,1.77,33.37]],"batl":[[0,2.1,20.38],[1,2.16,9.72],[2,2.1,0]],"ltp":2.0,"tv":10545.62,"id":9342449},{"batb":[[0,1.98,313.84],[1,1.95,4.26],[2,1.91,28.39]],"batl":[[0,2.2,7.08],[1,2.3,6.45],[2,2.02,0]],"ltp":1.98,"tv":5538.18,"id":9633869}]}]}
{"op":"mcm","clk":"4230400867","pt":1631532561189,"mc":[{"id":"1.187557995","marketDefinition":{"bspMarket":false,"turnInPlayEnabled":true,"persistenceEnabled":true,"marketBaseRate":5.0,"eventId":"30896141","eventTypeId":"2","numberOfWinners":1,"bettingType":"ODDS","marketType":"MATCH_ODDS","marketTime":"2021-09-13T11:30:00.000Z","suspendTime":"2021-09-13T11:30:00.000Z","bspReconciled":false,"complete":true,"inPlay":true,"crossMatching":true,"runnersVoidable":false,"numberOfActiveRunners":2,"betDelay":3,"status":"OPEN","runners":[{"status":"ACTIVE","sortPriority":1,"id":9342449,"name":"Viktoria Kuzmova"},{"status":"ACTIVE","sortPriority":2,"id":9633869,"name":"Lucrezia Stefanini"}],"regulators":["MR_INT"],"discountAllowed":true,"timezone":"UTC","openDate":"2021-09-13T11:30:00.000Z","version":4030590407,"name":"Match Odds","eventName":"Kuzmova v Stefanini"},"rc":[{"batb":[[0,1.83,81],[1,1.77,33.37],[2,1.3,198.07]],"ltp":2.0,"tv":10545.62,"id":9342449},{"batb":[[0,1.99,14.87],[1,1.98,142.84],[2,1.95,4.26]],"batl":[[0,2.3,6.45],[1,2.3,0]],"ltp":1.98,"tv":5538.18,"id":9633869}]}]}
{"op":"mcm","clk":"4230401065","pt":1631532563638,"mc":[{"id":"1.187557995","rc":[{"batl":[[0,2,13.02],[1,2.1,20.38],[2,2.16,9.72]],"ltp":2.0,"tv":10545.62,"id":9342449},{"batl":[[0,2.16,115.13],[1,2.18,108.77],[2,2.2,4]],"ltp":1.98,"tv":5538.18,"id":9633869}]}]}
{"op":"mcm","clk":"4230401087","pt":1631532563998,"mc":[{"id":"1.187557995","rc":[{"batb":[[0,1.84,33.97],[1,1.83,85],[2,1.82,5]],"ltp":2.0,"tv":10545.62,"id":9342449},{"batl":[[2,2.2,10.03]],"ltp":1.98,"tv":5538.18,"id":9633869}]}]}
{"op":"mcm","clk":"4230401164","pt":1631532565295,"mc":[{"id":"1.187557995","rc":[{"batb":[[0,1.83,85],[1,1.82,5],[2,1.77,33.37]],"ltp":2.0,"tv":10545.62,"id":9342449},{"batl":[[0,2.2,4],[1,2.22,4],[2,2.3,6.45]],"ltp":1.98,"tv":5538.18,"id":9633869}]}]}
{"op":"mcm","clk":"4230401299","pt":1631532567424,"mc":[{"id":"1.187557995","rc":[{"trd":[[2,187.24]],"batl":[[0,2.1,12.93],[1,2.16,9.72],[2,2.16,0]],"ltp":2.0,"tv":10558.63,"id":9342449},{"trd":[[1.95,8.52],[1.98,341.23],[1.99,37.81],[2,78.83]],"batb":[[0,1.9,267.25],[1,1.87,34.27],[2,1.84,79.41]],"batl":[[2,2.3,0]],"ltp":1.95,"tv":5875.14,"id":9633869}],"tv":16433.78}]}
{"op":"mcm","clk":"4230401394","pt":1631532568716,"mc":[{"id":"1.187557995","rc":[{"trd":[[2.1,12.93]],"batb":[[0,2.06,110.21],[1,1.98,126.78],[2,1.83,85]],"batl":[[0,2.16,9.72],[1,2.26,8.85]],"ltp":2.1,"tv":10571.56,"id":9342449},{"trd":[[1.87,68.54],[1.9,548.8]],"batb":[[0,1.84,79.41],[1,1.81,126.14],[2,1.79,193.36]],"batl":[[0,1.87,118.76],[1,1.89,1176.9],[2,1.9,982.14]],"ltp":1.87,"tv":6492.48,"id":9633869}],"tv":17064.05}]}
{"op":"mcm","clk":"4230401422","pt":1631532569129,"mc":[{"id":"1.187557995","rc":[{"batb":[[2,1.83,4]],"ltp":2.1,"tv":10571.56,"id":9342449}]}]}
{"op":"mcm","clk":"4230401521","pt":1631532570628,"mc":[{"id":"1.187557995","rc":[{"batb":[[0,2.1,4],[1,2.08,4],[2,2.06,110.21]],"ltp":2.1,"tv":10571.56,"id":9342449},{"trd":[[1.87,171.28]],"batl":[[0,1.87,67.39],[2,1.9,986.14]],"ltp":1.87,"tv":6595.22,"id":9633869}],"tv":17166.79}]}
{"op":"mcm","clk":"4230401609","pt":1631532571616,"mc":[{"id":"1.187557995","rc":[{"trd":[[1.87,190.64]],"batb":[[1,1.81,164.01]],"batl":[[0,1.89,1011.9],[1,1.9,986.14],[2,1.91,986.14]],"ltp":1.87,"tv":6614.58,"id":9633869}],"tv":17186.15}]}
{"op":"mcm","clk":"4230401691","pt":1631532572713,"mc":[{"id":"1.187557995","rc":[{"batl":[[1,2.22,53.33],[2,2.26,8.85]],"ltp":2.1,"tv":10571.56,"id":9342449},{"batb":[[1,1.82,46.64],[2,1.81,164.01]],"batl":[[0,1.88,31.53],[1,1.89,1056.81],[2,1.9,986.14]],"ltp":1.87,"tv":6614.58,"id":9633869}]}]}
{"op":"mcm","clk":"4230401701","pt":1631532572930,"mc":[{"id":"1.187557995","rc":[{"batl":[[1,2.26,8.85],[2,2.26,0]],"ltp":2.1,"tv":10571.56,"id":9342449},{"batl":[[0,1.89,1056.81],[1,1.9,986.14],[2,1.91,986.14]],"ltp":1.87,"tv":6614.58,"id":9633869}]}]}
{"op":"mcm","clk":"4230401781","pt":1631532574125,"mc":[{"id":"1.187557995","rc":[{"batb":[[1,1.83,54.12],[2,1.82,46.64]],"batl":[[0,1.88,170.99],[1,1.89,1056.81],[2,1.9,1200.42]],"ltp":1.87,"tv":6614.58,"id":9633869}]}]}
{"op":"mcm","clk":"4230401870","pt":1631532575426,"mc":[{"id":"1.187557995","rc":[{"batl":[[2,1000,1]],"ltp":2.1,"tv":10571.56,"id":9342449}]}]}
{"op":"mcm","clk":"4230401947","pt":1631532576620,"mc":[{"id":"1.187557995","rc":[{"batb":[[1,2.08,111.03]],"batl":[[2,1000,0]],"ltp":2.1,"tv":10571.56,"id":9342449},{"batb":[[0,1.86,161],[1,1.84,79.41],[2,1.83,54.12]],"ltp":1.87,"tv":6614.58,"id":9633869}]}]}
{"op":"mcm","clk":"4230402003","pt":1631532577509,"mc":[{"id":"1.187557995","rc":[{"batl":[[0,2.16,7.72]],"ltp":2.1,"tv":10571.56,"id":9342449},{"batb":[[1,1.83,54.12],[2,1.82,128.31]],"ltp":1.87,"tv":6614.58,"id":9633869}]}]}
{"op":"mcm","clk":"4230402130","pt":1631532579211,"mc":[{"id":"1.187557995","rc":[{"batl":[[1,2.26,9.85]],"ltp":2.1,"tv":10571.56,"id":9342449},{"batb":[[1,1.84,68.22],[2,1.83,54.12]],"ltp":1.87,"tv":6614.58,"id":9633869}]}]}
{"op":"mcm","clk":"4230402227","pt":1631532580611,"mc":[{"id":"1.187557995","rc":[{"trd":[[2.12,2]],"ltp":2.12,"tv":10573.56,"id":9342449},{"trd":[[1.88,2.26]],"batl":[[0,1.88,168.73]],"ltp":1.88,"tv":6616.84,"id":9633869}],"tv":17190.41}]}
{"op":"mcm","clk":"4230402301","pt":1631532581646,"mc":[{"id":"1.187557995","rc":[{"trd":[[2.16,14.2]],"batl":[[0,2.26,10.47],[1,2.26,0]],"ltp":2.16,"tv":10587.76,"id":9342449}],"tv":17204.61}]}
{"op":"mcm","clk":"4230403384","pt":1631532596639,"mc":[{"id":"1.187557995","rc":[{"batb":[[1,2.08,107.03]],"ltp":2.16,"tv":10587.76,"id":9342449},{"trd":[[1.88,28.3]],"batl":[[0,1.88,155.71]],"ltp":1.88,"tv":6642.88,"id":9633869}],"tv":17230.64}]}
{"op":"mcm","clk":"4230403561","pt":1631532599656,"mc":[{"id":"1.187557995","rc":[{"batb":[[1,1.85,97.82],[2,1.84,68.22]],"ltp":1.88,"tv":6642.88,"id":9633869}]}]}
{"op":"mcm","clk":"4230404007","pt":1631532605448,"mc":[{"id":"1.187557995","rc":[{"batl":[[0,1.89,1056.81],[1,1.9,1038.26],[2,1.91,982.14]],"ltp":1.88,"tv":6642.88,"id":9633869}]}]}
{"op":"mcm","clk":"4230404066","pt":1631532606270,"mc":[{"id":"1.187557995","rc":[{"batb":[[0,1.88,5.86],[1,1.86,161],[2,1.85,97.82]],"ltp":1.88,"tv":6642.88,"id":9633869}]}]}
{"op":"mcm","clk":"4230404248","pt":1631532608652,"mc":[{"id":"1.187557995","rc":[{"batb":[[0,1.88,176.21],[1,1.86,314.39]],"ltp":1.88,"tv":6642.88,"id":9633869}]}]}
{"op":"mcm","clk":"4230404340","pt":1631532609648,"mc":[{"id":"1.187557995","rc":[{"trd":[[1.88,349.89]],"batb":[[0,1.88,15.42]],"ltp":1.88,"tv":6964.48,"id":9633869}],"tv":17552.24}]}
{"op":"mcm","clk":"4230404466","pt":1631532611153,"mc":[{"id":"1.187557995","rc":[{"batb":[[0,1.86,314.39],[1,1.85,97.82],[2,1.84,68.22]],"ltp":1.88,"tv":6964.48,"id":9633869}]}]}
{"op":"mcm","clk":"4230405803","pt":1631532628301,"mc":[{"id":"1.187557995","rc":[{"batl":[[1,2.3,5.95],[2,2.38,6.75]],"ltp":2.16,"tv":10587.76,"id":9342449}]}]}
{"op":"mcm","clk":"4230405908","pt":1631532629669,"mc":[{"id":"1.187557995","rc":[{"batl":[[0,2.26,1.62]],"ltp":2.16,"tv":10587.76,"id":9342449},{"batl":[[0,1.89,44.91],[1,1.9,56.12],[2,1.98,144.76]],"ltp":1.88,"tv":6964.48,"id":9633869}]}]}
{"op":"mcm","clk":"4230405940","pt":1631532630087,"mc":[{"id":"1.187557995","rc":[{"batb":[[0,2,151.02],[1,1.95,26.31],[2,1.82,4.2]],"batl":[[0,2.26,1],[1,2.38,6.75],[2,2.38,0]],"ltp":2.16,"tv":10587.76,"id":9342449},{"batb":[[0,1.86,161],[1,1.78,33.16],[2,1.73,34.13]],"batl":[[0,1.98,144.76],[1,2,163.27],[2,2.06,8.75]],"ltp":1.88,"tv":6964.48,"id":9633869}]}]}
{"op":"mcm","clk":"4230406064","pt":1631532631397,"mc":[{"id":"1.187557995","rc":[{"batb":[[0,1.73,34.13],[1,1.72,257.5],[2,1.7,229.54]],"ltp":1.88,"tv":6964.48,"id":9633869}]}]}
{"op":"mcm","clk":"4230406331","pt":1631532634590,"mc":[{"id":"1.187557995","rc":[{"batl":[[1,2.3,4],[2,2.38,6.75]],"ltp":2.16,"tv":10587.76,"id":9342449},{"batb":[[0,1.78,39.66],[1,1.77,5],[2,1.76,4]],"ltp":1.88,"tv":6964.48,"id":9633869}]}]}
{"op":"mcm","clk":"4230406357","pt":1631532634896,"mc":[{"id":"1.187557995","rc":[{"batb":[[0,1.78,5]],"ltp":1.88,"tv":6964.48,"id":9633869}]}]}
{"op":"mcm","clk":"4230406464","pt":1631532636406,"mc":[{"id":"1.187557995","rc":[{"batl":[[2,2.32,4]],"ltp":2.16,"tv":10587.76,"id":9342449}]}]}
{"op":"mcm","clk":"4230406549","pt":1631532637615,"mc":[{"id":"1.187557995","rc":[{"batl":[[1,2.3,9.95]],"ltp":2.16,"tv":10587.76,"id":9342449}]}]}
{"op":"mcm","clk":"4230406593","pt":1631532638089,"mc":[{"id":"1.187557995","rc":[{"batl":[[1,2.3,5.95],[2,2.38,6.75]],"ltp":2.16,"tv":10587.76,"id":9342449},{"batb":[[0,1.78,34.66],[1,1.75,5],[2,1.73,34.13]],"ltp":1.88,"tv":6964.48,"id":9633869}]}]}
{"op":"mcm","clk":"4230406836","pt":1631532640795,"mc":[{"id":"1.187557995","rc":[{"batb":[[0,2.04,4],[1,2.02,766.33],[2,2,151.02]],"ltp":2.16,"tv":10587.76,"id":9342449},{"batl":[[0,1.97,3],[1,1.98,144.76],[2,2,163.27]],"ltp":1.88,"tv":6964.48,"id":9633869}]}]}
{"op":"mcm","clk":"4230407105","pt":1631532644008,"mc":[{"id":"1.187557995","rc":[{"batb":[[0,2.06,4],[1,2.04,4],[2,2.02,766.33]],"ltp":2.16,"tv":10587.76,"id":9342449},{"batl":[[0,1.96,5],[1,1.97,3],[2,1.98,144.76]],"ltp":1.88,"tv":6964.48,"id":9633869}]}]}
{"op":"mcm","clk":"4230407329","pt":1631532647501,"mc":[{"id":"1.187557995","rc":[{"batb":[[0,2,151.02],[1,1.95,26.31],[2,1.82,4.2]],"batl":[[1,2.38,6.75],[2,2.38,0]],"ltp":2.16,"tv":10587.76,"id":9342449},{"batb":[[0,1.75,5],[1,1.73,34.13],[2,1.72,257.5]],"batl":[[0,1.98,144.76],[1,2,163.27],[2,2.06,8.75]],"ltp":1.88,"tv":6964.48,"id":9633869}]}]}
{"op":"mcm","clk":"4230407561","pt":1631532650407,"mc":[{"id":"1.187557995","rc":[{"batl":[[1,2.34,3],[2,2.38,6.75]],"ltp":2.16,"tv":10587.76,"id":9342449},{"batb":[[0,1.76,5],[1,1.75,5],[2,1.73,34.13]],"ltp":1.88,"tv":6964.48,"id":9633869}]}]}
{"op":"mcm","clk":"4230407876","pt":1631532653623,"mc":[{"id":"1.187557995","rc":[{"batl":[[1,2.3,10.35],[2,2.32,4]],"ltp":2.16,"tv":10587.76,"id":9342449},{"batb":[[0,1.78,36.66],[1,1.77,5],[2,1.76,5]],"ltp":1.88,"tv":6964.48,"id":9633869}]}]}
{"op":"mcm","clk":"4230407907","pt":1631532653989,"mc":[{"id":"1.187557995","rc":[{"batb":[[0,2,123.09]],"batl":[[1,2.3,4]],"ltp":2.16,"tv":10587.76,"id":9342449},{"batb":[[0,1.78,5]],"batl":[[0,2.06,8.75],[1,2.26,1],[2,2.06,0]],"ltp":1.88,"tv":6964.48,"id":9633869}]}]}
{"op":"mcm","clk":"4230408125","pt":1631532656695,"mc":[{"id":"1.187557995","rc":[{"batb":[[0,1.79,210.91],[1,1.78,5],[2,1.77,205.67]],"batl":[[0,1.86,172.59],[1,1.88,167.46],[2,2.06,8.75]],"ltp":1.88,"tv":6964.48,"id":9633869}]}]}
{"op":"mcm","clk":"4230408171","pt":1631532657314,"mc":[{"id":"1.187557995","rc":[{"batb":[[0,2,147.43]],"ltp":2.16,"tv":10587.76,"id":9342449},{"batb":[[1,1.78,35.66]],"batl":[[2,2,27.93]],"ltp":1.88,"tv":6964.48,"id":9633869}]}]}
{"op":"mcm","clk":"4230408330","pt":1631532659639,"mc":[{"id":"1.187557995","rc":[{"batb":[[0,1.78,35.66],[1,1.77,5],[2,1.76,5]],"batl":[[0,2,27.93],[1,2.06,8.75],[2,2.26,1]],"ltp":1.88,"tv":6964.48,"id":9633869}]}]}
{"op":"mcm","clk":"4230408409","pt":1631532660579,"mc":[{"id":"1.187557995","rc":[{"batb":[[0,2,123.09]],"batl":[[1,2.28,4],[2,2.3,10.15]],"ltp":2.16,"tv":10587.76,"id":9342449},{"batb":[[0,1.79,4],[1,1.78,5],[2,1.77,5]],"batl":[[0,2.06,8.75],[1,2.26,1],[2,2.26,0]],"ltp":1.88,"tv":6964.48,"id":9633869}]}]}
{"op":"mcm","clk":"4230408445","pt":1631532660848,"mc":[{"id":"1.187557995","rc":[{"batl":[[2,2.3,4]],"ltp":2.16,"tv":10587.76,"id":9342449}]}]}
{"op":"mcm","clk":"4230408614","pt":1631532662470,"mc":[{"id":"1.187557995","rc":[{"batl":[[0,1.98,144.76],[1,2,139.11],[2,2.06,8.75]],"ltp":1.88,"tv":6964.48,"id":9633869}]}]}
{"op":"mcm","clk":"4230408734","pt":1631532663680,"mc":[{"id":"1.187557995","rc":[{"batb":[[0,2,147.17]],"batl":[[0,2.28,4],[1,2.3,4],[2,2.32,4]],"ltp":2.16,"tv":10587.76,"id":9342449},{"batl":[[1,2,164.46]],"ltp":1.88,"tv":6964.48,"id":9633869}]}]}
{"op":"mcm","clk":"4230408988","pt":1631532666693,"mc":[{"id":"1.187557995","rc":[{"batb":[[1,1.78,40.16]],"ltp":1.88,"tv":6964.48,"id":9633869}]}]}
{"op":"mcm","clk":"4230409056","pt":1631532667569,"mc":[{"id":"1.187557995","rc":[{"batl":[[1,2.3,6.15],[2,2.38,6.75]],"ltp":2.16,"tv":10587.76,"id":9342449},{"batb":[[1,1.73,34.13],[2,1.72,257.5]],"ltp":1.88,"tv":6964.48,"id":9633869}]}]}
{"op":"mcm","clk":"4230409082","pt":1631532667879,"mc":[{"id":"1.187557995","rc":[{"batl":[[1,2.38,6.75],[2,2.38,0]],"ltp":2.16,"tv":10587.76,"id":9342449}]}]}
{"op":"mcm","clk":"4230409289","pt":1631532670467,"mc":[{"id":"1.187557995","rc":[{"batb":[[1,1.78,4],[2,1.73,34.13]],"ltp":1.88,"tv":6964.48,"id":9633869}]}]}
{"op":"mcm","clk":"4230409459","pt":1631532672598,"mc":[{"id":"1.187557995","rc":[{"trd":[[2.02,104.61]],"ltp":2.02,"tv":10600.54,"id":9342449},{"trd":[[1.98,354.26]],"batl":[[0,1.98,131.73]],"ltp":1.98,"tv":6977.51,"id":9633869}],"tv":17578.05}]}
{"op":"mcm","clk":"4230409549","pt":1631532673697,"mc":[{"id":"1.187557995","rc":[{"batb":[[1,1.78,36.16]],"ltp":1.98,"tv":6977.51,"id":9633869}]}]}
{"op":"mcm","clk":"4230409635","pt":1631532674681,"mc":[{"id":"1.187557995","rc":[{"batl":[[1,2.3,6.15],[2,2.38,6.75]],"ltp":2.02,"tv":10600.54,"id":9342449},{"batb":[[1,1.78,4]],"ltp":1.98,"tv":6977.51,"id":9633869}]}]}
{"op":"mcm","clk":"4230409664","pt":1631532674994,"mc":[{"id":"1.187557995","rc":[{"batl":[[1,2.38,6.75],[2,2.38,0]],"ltp":2.02,"tv":10600.54,"id":9342449}]}]}
{"op":"mcm","clk":"4230410050","pt":1631532679305,"mc":[{"id":"1.187557995","rc":[{"batl":[[2,2.06,0]],"ltp":1.98,"tv":6977.51,"id":9633869}]}]}
{"op":"mcm","clk":"4230410172","pt":1631532680604,"mc":[{"id":"1.187557995","rc":[{"batb":[[1,1.78,35.16]],"ltp":1.98,"tv":6977.51,"id":9633869}]}]}
{"op":"mcm","clk":"4230410275","pt":1631532681691,"mc":[{"id":"1.187557995","rc":[{"batl":[[1,2.3,6.35],[2,2.38,6.75]],"ltp":2.02,"tv":10600.54,"id":9342449},{"batb":[[1,1.78,4]],"ltp":1.98,"tv":6977.51,"id":9633869}]}]}
{"op":"mcm","clk":"4230410355","pt":1631532682678,"mc":[{"id":"1.187557995","rc":[{"batb":[[1,1.98,593.43],[2,1.97,296.72]],"batl":[[1,2.38,6.75],[2,2.38,0]],"ltp":2.02,"tv":10600.54,"id":9342449},{"batb":[[0,1.91,146.39],[1,1.9,71.38],[2,1.89,162.49]],"ltp":1.98,"tv":6977.51,"id":9633869}]}]}
{"op":"mcm","clk":"4230410398","pt":1631532683195,"mc":[{"id":"1.187557995","rc":[{"batb":[[1,1.98,148.36],[2,1.97,74.18]],"ltp":2.02,"tv":10600.54,"id":9342449},{"batl":[[2,2.04,9.8]],"ltp":1.98,"tv":6977.51,"id":9633869}]}]}
{"op":"mcm","clk":"4230410493","pt":1631532684290,"mc":[{"id":"1.187557995","rc":[{"batb":[[0,2.02,4],[1,2,152.17],[2,1.98,148.36]],"batl":[[0,2.26,3],[1,2.28,4],[2,2.38,6.75]],"ltp":2.02,"tv":10600.54,"id":9342449}]}]}
{"op":"mcm","clk":"4230410646","pt":1631532686103,"mc":[{"id":"1.187557995","rc":[{"batb":[[0,1.92,153.86],[1,1.91,146.39],[2,1.9,71.38]],"batl":[[0,1.97,54.82],[1,1.98,131.73],[2,2,164.46]],"ltp":1.98,"tv":6977.51,"id":9633869}]}]}
{"op":"mcm","clk":"4230410871","pt":1631532688991,"mc":[{"id":"1.187557995","rc":[{"batl":[[0,2.16,7.97],[1,2.22,6.75],[2,2.26,3]],"ltp":2.02,"tv":10600.54,"id":9342449}]}]}
{"op":"mcm","clk":"4230410945","pt":1631532690023,"mc":[{"id":"1.187557995","rc":[{"batl":[[0,1.96,30.27],[1,1.97,54.82],[2,1.98,131.73]],"ltp":1.98,"tv":6977.51,"id":9633869}]}]}
{"op":"mcm","clk":"4230411310","pt":1631532694423,"mc":[{"id":"1.187557995","rc":[{"batl":[[1,2.2,7.28],[2,2.22,6.75]],"ltp":2.02,"tv":10600.54,"id":9342449},{"batl":[[0,1.97,54.82],[1,1.98,131.73],[2,2,164.46]],"ltp":1.98,"tv":6977.51,"id":9633869}]}]}
{"op":"mcm","clk":"4230411617","pt":1631532698196,"mc":[{"id":"1.187557995","rc":[{"batb":[[1,2,147.17]],"ltp":2.02,"tv":10600.54,"id":9342449},{"trd":[[1.97,98.82]],"batl":[[0,1.98,131.73],[1,2,164.46],[2,2.04,17.43]],"ltp":1.97,"tv":7076.33,"id":9633869}],"tv":17676.87}]}
{"op":"mcm","clk":"4230411772","pt":1631532700427,"mc":[{"id":"1.187557995","rc":[{"batb":[[0,1.92,69.45],[1,1.91,32.39],[2,1.82,4.2]],"batl":[[0,2.26,3],[1,2.82,234.47],[2,2.22,0]],"ltp":2.02,"tv":10600.54,"id":9342449},{"batb":[[0,1.84,4],[1,1.83,34.03],[2,1.8,85.02]],"batl":[[0,2.1,7.65],[1,2,0],[2,2.04,0]],"ltp":1.97,"tv":7076.33,"id":9633869}]}]}
{"op":"mcm","clk":"4230412042","pt":1631532703649,"mc":[{"id":"1.187557995","rc":[{"batb":[[0,1.97,25.17],[1,1.92,72.45],[2,1.91,35.39]],"batl":[[0,2.16,7.97],[1,2.2,4],[2,2.22,10.25]],"ltp":2.02,"tv":10600.54,"id":9342449},{"batb":[[0,1.87,27.27],[1,1.84,4],[2,1.83,39.03]],"batl":[[0,2.04,7.63],[1,2.08,108.44],[2,2.1,132.45]],"ltp":1.97,"tv":7076.33,"id":9633869}]}]}
{"op":"mcm","clk":"4230412081","pt":1631532704109,"mc":[{"id":"1.187557995","rc":[{"batb":[[0,1.92,72.45],[1,1.91,35.39],[2,1.82,4.2]],"batl":[[0,2.2,4],[1,2.22,10.25],[2,2.26,3]],"ltp":2.02,"tv":10600.54,"id":9342449},{"batb":[[0,1.84,4],[1,1.83,39.03],[2,1.8,85.02]],"batl":[[0,2.1,11.65],[1,2.08,0],[2,2.1,0]],"ltp":1.97,"tv":7076.33,"id":9633869}]}]}
{"op":"mcm","clk":"4230412290","pt":1631532706648,"mc":[{"id":"1.187557995","rc":[{"batl":[[0,2,505.63],[1,2.08,4],[2,2.1,11.65]],"ltp":1.97,"tv":7076.33,"id":9633869}]}]}
{"op":"mcm","clk":"4230412335","pt":1631532707115,"mc":[{"id":"1.187557995","rc":[{"batb":[[0,1.97,27.17],[1,1.92,72.45],[2,1.91,35.39]],"batl":[[0,2.16,6.47],[1,2.2,4],[2,2.22,10.25]],"ltp":2.02,"tv":10600.54,"id":9342449},{"batb":[[0,1.89,138.06],[1,1.87,201.24],[2,1.84,4]],"batl":[[0,1.96,159.52],[1,1.98,143.26],[2,2.04,8.88]],"ltp":1.97,"tv":7076.33,"id":9633869}]}]}
{"op":"mcm","clk":"4230412789","pt":1631532712444,"mc":[{"id":"1.187557995","rc":[{"batb":[[0,1.92,72.45],[1,1.91,35.39],[2,1.82,4.2]],"batl":[[0,2.2,4],[1,2.22,10.25],[2,2.26,3]],"ltp":2.02,"tv":10600.54,"id":9342449},{"batb":[[0,1.84,4],[1,1.83,39.03],[2,1.8,85.02]],"batl":[[0,2.08,4],[1,2.1,11.65],[2,2.04,0]],"ltp":1.97,"tv":7076.33,"id":9633869}]}]}
{"op":"mcm","clk":"4230413031","pt":1631532715652,"mc":[{"id":"1.187557995","rc":[{"batb":[[0,1.97,26.17],[1,1.92,72.45],[2,1.91,32.39]],"batl":[[0,2.16,6.47],[1,2.2,4],[2,2.22,6.25]],"ltp":2.02,"tv":10600.54,"id":9342449},{"batb":[[0,1.87,29.27],[1,1.84,4],[2,1.83,34.03]],"batl":[[0,2.04,7.63],[1,2.08,112.44],[2,2.1,132.45]],"ltp":1.97,"tv":7076.33,"id":9633869}]}]}
{"op":"mcm","clk":"4230413061","pt":1631532716036,"mc":[{"id":"1.187557995","rc":[{"batb":[[0,1.92,72.45],[1,1.91,32.39],[2,1.82,4.2]],"batl":[[0,2.2,4],[1,2.82,234.47],[2,2.22,0]],"ltp":2.02,"tv":10600.54,"id":9342449},{"batb":[[0,1.84,4],[1,1.83,34.03],[2,1.8,85.02]],"batl":[[0,2.08,4],[1,2.1,11.65],[2,2.1,0]],"ltp":1.97,"tv":7076.33,"id":9633869}]}]}
{"op":"mcm","clk":"4230413258","pt":1631532718663,"mc":[{"id":"1.187557995","rc":[{"batb":[[1,1.91,35.39]],"ltp":2.02,"tv":10600.54,"id":9342449},{"batb":[[1,1.83,39.03]],"batl":[[1,2.1,7.65]],"ltp":1.97,"tv":7076.33,"id":9633869}]}]}
{"op":"mcm","clk":"4230413342","pt":1631532719541,"mc":[{"id":"1.187557995","rc":[{"batb":[[0,1.91,146.39],[1,1.89,162.49],[2,1.88,103.31]],"batl":[[0,1.98,137.56],[1,2,139.11],[2,2.08,4]],"ltp":1.97,"tv":7076.33,"id":9633869}]}]}
{"op":"mcm","clk":"4230413590","pt":1631532722654,"mc":[{"id":"1.187557995","rc":[{"batb":[[0,1.93,753.28],[1,1.92,72.45],[2,1.91,35.39]],"ltp":2.02,"tv":10600.54,"id":9342449},{"batb":[[0,1.92,89.64],[1,1.91,146.39],[2,1.89,162.49]],"ltp":1.97,"tv":7076.33,"id":9633869}]}]}
{"op":"mcm","clk":"4230413678","pt":1631532723642,"mc":[{"id":"1.187557995","rc":[{"batb":[[0,1.92,72.45],[1,1.91,35.39],[2,1.82,4.2]],"ltp":2.02,"tv":10600.54,"id":9342449},{"batb":[[0,1.84,4],[1,1.83,39.03],[2,1.8,85.02]],"batl":[[0,2.08,4],[1,2.1,7.65],[2,2.08,0]],"ltp":1.97,"tv":7076.33,"id":9633869}]}]}
{"op":"mcm","clk":"4230413893","pt":1631532726474,"mc":[{"id":"1.187557995","rc":[{"batb":[[2,1.81,138.78]],"batl":[[0,2.08,112.44],[1,2.1,128.45]],"ltp":1.97,"tv":7076.33,"id":9633869}]}]}
{"op":"mcm","clk":"4230414360","pt":1631532732365,"mc":[{"id":"1.187557995","rc":[{"batb":[[1,1.91,32.39]],"ltp":2.02,"tv":10600.54,"id":9342449},{"batb":[[1,1.83,34.03],[2,1.8,85.02]],"batl":[[0,2.06,321.11],[1,2.08,4],[2,2.1,7.65]],"ltp":1.97,"tv":7076.33,"id":9633869}]}]}
{"op":"mcm","clk":"4230414464","pt":1631532733655,"mc":[{"id":"1.187557995","rc":[{"batl":[[0,2.06,465.76]],"ltp":1.97,"tv":7076.33,"id":9633869}]}]}
{"op":"mcm","clk":"4230414522","pt":1631532734585,"mc":[{"id":"1.187557995","rc":[{"batl":[[0,2.08,4],[1,2.1,7.65],[2,2.1,0]],"ltp":1.97,"tv":7076.33,"id":9633869}]}]}
{"op":"mcm","clk":"4230414597","pt":1631532735672,"mc":[{"id":"1.187557995","rc":[{"batb":[[0,1.92,236.17],[1,1.91,37.39],[2,1.9,159.98]],"batl":[[0,1.99,114.91],[1,2.02,204.08],[2,2.08,9.62]],"ltp":2.02,"tv":10600.54,"id":9342449},{"batb":[[0,2,2094.68],[1,1.99,961.06],[2,1.98,932.8]],"batl":[[0,2.1,7.65],[1,2.1,0]],"ltp":1.97,"tv":7076.33,"id":9633869}]}]}
{"op":"mcm","clk":"4230414684","pt":1631532736661,"mc":[{"id":"1.187557995","rc":[{"batb":[[0,2,19.92]],"batl":[[1,2.12,9.43]],"ltp":1.97,"tv":7076.33,"id":9633869}]}]}
{"op":"mcm","clk":"4230415177","pt":1631532742668,"mc":[{"id":"1.187557995","rc":[{"batl":[[0,1.98,3.24],[1,1.99,114.91],[2,2.02,204.08]],"ltp":2.02,"tv":10600.54,"id":9342449}]}]}
{"op":"mcm","clk":"4230415261","pt":1631532743706,"mc":[{"id":"1.187557995","rc":[{"batb":[[1,1.91,77.79]],"batl":[[2,2,38.58]],"ltp":2.02,"tv":10600.54,"id":9342449}]}]}
{"op":"mcm","clk":"4230415508","pt":1631532746705,"mc":[{"id":"1.187557995","rc":[{"batb":[[0,1.92,277.45]],"batl":[[0,1.98,43.27]],"ltp":2.02,"tv":10600.54,"id":9342449}]}]}
{"op":"mcm","clk":"4230415586","pt":1631532747466,"mc":[{"id":"1.187557995","rc":[{"batb":[[1,1.91,72.79]],"ltp":2.02,"tv":10600.54,"id":9342449},{"batb":[[0,1.99,961.06],[1,1.98,932.8],[2,1.97,1059.16]],"ltp":1.97,"tv":7076.33,"id":9633869}]}]}
{"op":"mcm","clk":"4230415919","pt":1631532751707,"mc":[{"id":"1.187557995","rc":[{"batb":[[0,1.92,72.45],[1,1.91,32.39],[2,1.86,76.9]],"batl":[[0,1.97,8.52],[1,1.98,3.24],[2,2.18,4]],"ltp":2.02,"tv":10600.54,"id":9342449},{"batb":[[0,1.97,126.36],[1,1.89,72.47],[2,1.85,4]],"batl":[[1,2.12,0]],"ltp":1.97,"tv":7076.33,"id":9633869}]}]}
{"op":"mcm","clk":"4230415971","pt":1631532752179,"mc":[{"id":"1.187557995","rc":[{"batb":[[0,1.92,3],[1,1.86,76.9],[2,1.82,4.2]],"batl":[[0,1.96,8.52],[1,1.97,8.52],[2,1.98,3.24]],"ltp":2.02,"tv":10600.54,"id":9342449},{"batb":[[0,1.89,72.47],[1,1.85,4],[2,1.67,1.38]],"ltp":1.97,"tv":7076.33,"id":9633869}]}]}
{"op":"mcm","clk":"4230416180","pt":1631532754463,"mc":[{"id":"1.187557995","rc":[{"batb":[[1,1.91,4],[2,1.86,76.9]],"ltp":2.02,"tv":10600.54,"id":9342449},{"batl":[[0,2.1,3]],"ltp":1.97,"tv":7076.33,"id":9633869}]}]}
{"op":"mcm","clk":"4230416231","pt":1631532755085,"mc":[{"id":"1.187557995","rc":[{"batl":[[1,2.12,3]],"ltp":1.97,"tv":7076.33,"id":9633869}]}]}
{"op":"mcm","clk":"4230416433","pt":1631532757370,"mc":[{"id":"1.187557995","rc":[{"batl":[[0,1.98,3.24],[1,2.18,4],[2,2.82,234.47]],"ltp":2.02,"tv":10600.54,"id":9342449}]}]}
{"op":"mcm","clk":"4230416468","pt":1631532757783,"mc":[{"id":"1.187557995","rc":[{"batl":[[2,2.82,0]],"ltp":2.02,"tv":10600.54,"id":9342449}]}]}
{"op":"mcm","clk":"4230416634","pt":1631532759704,"mc":[{"id":"1.187557995","rc":[{"trd":[[1.92,55.65]],"batb":[[0,1.86,76.9],[1,1.85,154.02],[2,1.83,180.54]],"batl":[[0,1.92,190.83],[1,1.93,990.94],[2,1.94,1114.78]],"ltp":1.92,"tv":10606.54,"id":9342449}],"tv":17682.87}]}
{"op":"mcm","clk":"4230416685","pt":1631532760172,"mc":[{"id":"1.187557995","rc":[{"batb":[[0,2.04,113.97],[1,1.97,127.53],[2,1.85,4]],"batl":[[0,2.18,9.17]],"ltp":1.97,"tv":7076.33,"id":9633869}]}]}
{"op":"mcm","clk":"4230417004","pt":1631532763176,"mc":[{"id":"1.187557995","rc":[{"batb":[[0,1.86,118.23]],"batl":[[0,1.91,40.24],[1,1.92,190.83],[2,1.93,990.94]],"ltp":1.92,"tv":10606.54,"id":9342449}]}]}
{"op":"mcm","clk":"4230417851","pt":1631532771402,"mc":[{"id":"1.187557995","rc":[{"batb":[[0,1.82,82.43],[1,1.8,4.96],[2,1.58,422.21]],"batl":[[0,1.98,3.24],[1,2.18,4],[2,2.5,278.33]],"ltp":1.92,"tv":10606.54,"id":9342449},{"batb":[[0,1.97,127.53],[1,1.85,4],[2,1.67,1.38]],"ltp":1.97,"tv":7076.33,"id":9633869}]}]}
{"op":"mcm","clk":"4230417933","pt":1631532772233,"mc":[{"id":"1.187557995","rc":[{"batb":[[0,1.92,26.03],[1,1.82,82.43],[2,1.8,4.96]],"ltp":1.92,"tv":10606.54,"id":9342449}]}]}
{"op":"mcm","clk":"4230418144","pt":1631532774628,"mc":[{"id":"1.187557995","rc":[{"batb":[[1,1.86,4],[2,1.85,4]],"batl":[[0,1.98,151.25],[1,2,139.48],[2,2.18,4]],"ltp":1.92,"tv":10606.54,"id":9342449},{"batl":[[0,2.18,4],[1,2.22,3]],"ltp":1.97,"tv":7076.33,"id":9633869}]}]}
{"op":"mcm","clk":"4230418900","pt":1631532783526,"mc":[{"id":"1.187557995","rc":[{"batl":[[0,1.97,2.32],[1,1.98,151.25],[2,2,139.48]],"ltp":1.92,"tv":10606.54,"id":9342449}]}]}
{"op":"mcm","clk":"4230418989","pt":1631532784408,"mc":[{"id":"1.187557995","rc":[{"batb":[[1,1.91,136.56],[2,1.89,162.68]],"ltp":1.92,"tv":10606.54,"id":9342449},{"batb":[[0,1.99,961.06],[1,1.98,513.04],[2,1.97,640.57]],"batl":[[0,2.12,9.43],[1,2.18,4],[2,2.22,3]],"ltp":1.97,"tv":7076.33,"id":9633869}]}]}
{"op":"mcm","clk":"4230419048","pt":1631532785133,"mc":[{"id":"1.187557995","rc":[{"batb":[[0,1.93,68.87],[1,1.92,26.03],[2,1.91,136.56]],"ltp":1.92,"tv":10606.54,"id":9342449}]}]}
{"op":"mcm","clk":"4230419194","pt":1631532786750,"mc":[{"id":"1.187557995","rc":[{"batl":[[2,2.22,0]],"ltp":1.97,"tv":7076.33,"id":9633869}]}]}
{"op":"mcm","clk":"4230419494","pt":1631532790032,"mc":[{"id":"1.187557995","rc":[{"batb":[[0,1.93,134.78]],"batl":[[0,1.97,66.89]],"ltp":1.92,"tv":10606.54,"id":9342449}]}]}
{"op":"mcm","clk":"4230419611","pt":1631532791122,"mc":[{"id":"1.187557995","rc":[{"batb":[[2,1.97,665.74]],"batl":[[0,2.12,16.14],[1,2.16,87.33],[2,2.18,114.31]],"ltp":1.97,"tv":7076.33,"id":9633869}]}]}
{"op":"mcm","clk":"4230419694","pt":1631532792058,"mc":[{"id":"1.187557995","rc":[{"batb":[[0,2,95.9],[1,1.99,961.06],[2,1.98,513.04]],"ltp":1.97,"tv":7076.33,"id":9633869}]}]}
{"op":"mcm","clk":"4230419909","pt":1631532794644,"mc":[{"id":"1.187557995","rc":[{"batl":[[0,1.97,64.57]],"ltp":1.92,"tv":10606.54,"id":9342449},{"batb":[[0,1.99,961.06],[1,1.98,513.04],[2,1.97,665.74]],"ltp":1.97,"tv":7076.33,"id":9633869}]}]}
{"op":"mcm","clk":"4230419981","pt":1631532795635,"mc":[{"id":"1.187557995","rc":[{"batb":[[0,1.97,152.7],[1,1.95,113.36],[2,1.94,144.47]],"batl":[[0,2.12,6.71]],"ltp":1.97,"tv":7076.33,"id":9633869}]}]}
{"op":"mcm","clk":"4230420035","pt":1631532796163,"mc":[{"id":"1.187557995","rc":[{"batb":[[0,1.92,26.03],[1,1.87,186.47],[2,1.86,122.66]],"batl":[[0,1.98,3.24],[1,2.04,8.38],[2,2.06,113.49]],"ltp":1.92,"tv":10606.54,"id":9342449},{"batb":[[0,1.97,25.17]],"ltp":1.97,"tv":7076.33,"id":9633869}]}]}
{"op":"mcm","clk":"4230420202","pt":1631532798027,"mc":[{"id":"1.187557995","rc":[{"batb":[[1,1.9,28.36],[2,1.87,186.47]],"ltp":1.92,"tv":10606.54,"id":9342449}]}]}
{"op":"mcm","clk":"4230420668","pt":1631532803674,"mc":[{"id":"1.187557995","rc":[{"batb":[[0,1.93,115.52],[1,1.92,26.03],[2,1.91,157.34]],"batl":[[1,2,154.68],[2,2.02,135.38]],"ltp":1.92,"tv":10606.54,"id":9342449}]}]}
{"op":"mcm","clk":"4230421026","pt":1631532808437,"mc":[{"id":"1.187557995","rc":[{"batb":[[0,1.92,26.03],[1,1.9,28.36],[2,1.87,186.47]],"batl":[[1,2.06,113.49],[2,2.08,108.55]],"ltp":1.92,"tv":10606.54,"id":9342449},{"batb":[[0,1.95,113.36],[1,1.94,144.47],[2,1.93,179.78]],"ltp":1.97,"tv":7076.33,"id":9633869}]}]}
{"op":"mcm","clk":"4230421271","pt":1631532811651,"mc":[{"id":"1.187557995","rc":[{"batl":[[1,2.04,8.38],[2,2.06,113.49]],"ltp":1.92,"tv":10606.54,"id":9342449},{"batb":[[0,1.97,30.17],[1,1.95,113.36],[2,1.94,144.47]],"ltp":1.97,"tv":7076.33,"id":9633869}]}]}
{"op":"mcm","clk":"4230421288","pt":1631532811859,"mc":[{"id":"1.187557995","rc":[{"batl":[[1,2.06,113.49],[2,2.08,262.3]],"ltp":1.92,"tv":10606.54,"id":9342449},{"batb":[[0,1.95,113.36],[1,1.94,144.47],[2,1.93,179.78]],"ltp":1.97,"tv":7076.33,"id":9633869}]}]}
{"op":"mcm","clk":"4230421675","pt":1631532816694,"mc":[{"id":"1.187557995","rc":[{"batb":[[0,2.08,9.76],[1,1.95,113.36],[2,1.94,144.47]],"ltp":1.97,"tv":7076.33,"id":9633869}]}]}
{"op":"mcm","clk":"4230421828","pt":1631532818566,"mc":[{"id":"1.187557995","rc":[{"batl":[[1,2.04,8.88],[2,2.06,113.49]],"ltp":1.92,"tv":10606.54,"id":9342449},{"batb":[[1,1.97,27.17],[2,1.95,113.36]],"ltp":1.97,"tv":7076.33,"id":9633869}]}]}
{"op":"mcm","clk":"4230421872","pt":1631532819289,"mc":[{"id":"1.187557995","rc":[{"batb":[[2,1.87,75.98]],"batl":[[1,2.06,113.49],[2,2.08,108.55]],"ltp":1.92,"tv":10606.54,"id":9342449},{"batb":[[1,1.95,113.36],[2,1.94,144.47]],"batl":[[1,2.18,4],[2,2.18,0]],"ltp":1.97,"tv":7076.33,"id":9633869}]}]}
{"op":"mcm","clk":"4230421948","pt":1631532820278,"mc":[{"id":"1.187557995","rc":[{"trd":[[1.93,510.44],[1.98,722.92]],"batl":[[0,2.06,113.49],[1,2.08,108.55],[2,2.1,123.09]],"ltp":1.98,"tv":10623.54,"id":9342449},{"trd":[[2.08,397.14]],"batb":[[0,1.94,144.47],[1,1.93,179.78],[2,1.91,29.39]],"ltp":2.08,"tv":7086.09,"id":9633869}],"tv":17709.63}]}
{"op":"mcm","clk":"4230422139","pt":1631532822660,"mc":[{"id":"1.187557995","rc":[{"batb":[[0,1.99,982.57],[1,1.98,932.8],[2,1.97,932.8]],"batl":[[0,2.08,108.55],[1,2.1,123.09],[2,2.18,4]],"ltp":1.98,"tv":10623.54,"id":9342449},{"batb":[[1,1.93,314.08],[2,1.91,186.64]],"batl":[[0,2,135.94],[1,2.02,141.86],[2,2.06,9.71]],"ltp":2.08,"tv":7086.09,"id":9633869}]}]}
{"op":"mcm","clk":"4230422227","pt":1631532823591,"mc":[{"id":"1.187557995","rc":[{"batb":[[0,2.02,119.08],[1,1.99,982.57],[2,1.98,932.8]],"batl":[[2,2.14,9.35]],"ltp":1.98,"tv":10623.54,"id":9342449}]}]}
{"op":"mcm","clk":"4230422487","pt":1631532826457,"mc":[{"id":"1.187557995","rc":[{"batb":[[0,2.02,174.84],[1,2,5],[2,1.99,986.57]],"batl":[[0,2.06,54.67],[1,2.08,108.55],[2,2.1,123.09]],"ltp":1.98,"tv":10623.54,"id":9342449},{"batb":[[0,1.95,93.76],[1,1.94,144.47],[2,1.93,314.08]],"batl":[[0,2,138.94]],"ltp":2.08,"tv":7086.09,"id":9633869}]}]}
{"op":"mcm","clk":"4230422547","pt":1631532827186,"mc":[{"id":"1.187557995","rc":[{"batb":[[0,2.02,119.08]],"batl":[[0,2.08,108.55],[1,2.1,123.09],[2,2.14,9.35]],"ltp":1.98,"tv":10623.54,"id":9342449},{"batb":[[1,1.94,238.42]],"ltp":2.08,"tv":7086.09,"id":9633869}]}]}
{"op":"mcm","clk":"4230422733","pt":1631532829562,"mc":[{"id":"1.187557995","rc":[{"batl":[[0,2.08,109.55]],"ltp":1.98,"tv":10623.54,"id":9342449},{"batl":[[2,2.04,8.38]],"ltp":2.08,"tv":7086.09,"id":9633869}]}]}
{"op":"mcm","clk":"4230423080","pt":1631532834177,"mc":[{"id":"1.187557995","rc":[{"batb":[[0,1.95,96.08]],"ltp":2.08,"tv":7086.09,"id":9633869}]}]}
{"op":"mcm","clk":"4230423197","pt":1631532835574,"mc":[{"id":"1.187557995","rc":[{"batb":[[0,1.93,25.36],[1,1.92,95.99],[2,1.9,28.36]],"batl":[[0,2.08,1],[1,2.24,6.73],[2,2.72,244.88]],"ltp":1.98,"tv":10623.54,"id":9342449},{"batb":[[0,1.95,2.32],[1,1.81,31.29],[2,1.76,90.54]],"batl":[[0,2.08,8.69],[1,2.12,6.71],[2,2.18,4]],"ltp":2.08,"tv":7086.09,"id":9633869}]}]}
{"op":"mcm","clk":"4230423277","pt":1631532836410,"mc":[{"id":"1.187557995","rc":[{"batl":[[0,2.02,70.59],[1,2.08,1],[2,2.24,6.73]],"ltp":1.98,"tv":10623.54,"id":9342449}]}]}
{"op":"mcm","clk":"4230423469","pt":1631532838693,"mc":[{"id":"1.187557995","rc":[{"batl":[[2,2.18,7.75]],"ltp":1.98,"tv":10623.54,"id":9342449},{"batb":[[1,1.86,29.68],[2,1.81,31.29]],"batl":[[2,2.14,106.06]],"ltp":2.08,"tv":7086.09,"id":9633869}]}]}
{"op":"mcm","clk":"4230423510","pt":1631532839102,"mc":[{"id":"1.187557995","rc":[{"batb":[[0,1.93,27.36],[1,1.92,97.99]],"ltp":1.98,"tv":10623.54,"id":9342449},{"batb":[[0,1.86,29.68],[1,1.85,30.97]],"batl":[[0,2.08,11.69]],"ltp":2.08,"tv":7086.09,"id":9633869}]}]}
{"op":"mcm","clk":"4230423870","pt":1631532843693,"mc":[{"id":"1.187557995","rc":[{"batb":[[2,1.86,4]],"batl":[[0,2.08,1],[1,2.24,6.73],[2,2.72,244.88]],"ltp":1.98,"tv":10623.54,"id":9342449},{"batb":[[0,1.81,31.29],[1,1.79,188.82],[2,1.77,200.58]],"batl":[[1,2.14,106.06],[2,2.16,111.53]],"ltp":2.08,"tv":7086.09,"id":9633869}]}]}
{"op":"mcm","clk":"4230424468","pt":1631532850622,"mc":[{"id":"1.187557995","rc":[{"batb":[[1,1.92,95.99],[2,1.8,4.96]],"ltp":1.98,"tv":10623.54,"id":9342449}]}]}
{"op":"mcm","clk":"4230424790","pt":1631532854145,"mc":[{"id":"1.187557995","rc":[{"batb":[[1,1.92,98.99]],"ltp":1.98,"tv":10623.54,"id":9342449},{"batb":[[1,1.76,90.54],[2,1.67,1.38]],"batl":[[1,2.14,0],[2,2.16,0]],"ltp":2.08,"tv":7086.09,"id":9633869}]}]}
{"op":"mcm","clk":"4230425021","pt":1631532856647,"mc":[{"id":"1.187557995","rc":[{"batb":[[0,2.04,416.29],[1,1.81,31.29],[2,1.76,90.54]],"ltp":2.08,"tv":7086.09,"id":9633869}]}]}
{"op":"mcm","clk":"4230425101","pt":1631532857534,"mc":[{"id":"1.187557995","rc":[{"batb":[[0,1.93,25.36],[1,1.92,95.99],[2,1.87,182.37]],"batl":[[0,1.94,133.53],[1,1.96,1124.05],[2,1.97,947.06]],"ltp":1.98,"tv":10623.54,"id":9342449},{"batb":[[0,1.81,31.29],[1,1.76,90.54],[2,1.67,1.38]],"batl":[[0,2.08,8.69]],"ltp":2.08,"tv":7086.09,"id":9633869}]}]}
{"op":"mcm","clk":"4230425186","pt":1631532858326,"mc":[{"id":"1.187557995","rc":[{"batb":[[0,1.98,125.6],[1,1.89,72.89],[2,1.81,31.29]],"batl":[[1,2.16,9.26]],"ltp":2.08,"tv":7086.09,"id":9633869}]}]}
{"op":"mcm","clk":"4230425399","pt":1631532860657,"mc":[{"id":"1.187557995","rc":[{"batb":[[0,1.99,4],[1,1.98,130.6],[2,1.89,72.89]],"ltp":2.08,"tv":7086.09,"id":9633869}]}]}
{"op":"mcm","clk":"4230425450","pt":1631532861235,"mc":[{"id":"1.187557995","rc":[{"batb":[[0,1.99,77.35]],"ltp":2.08,"tv":7086.09,"id":9633869}]}]}
{"op":"mcm","clk":"4230425645","pt":1631532863661,"mc":[{"id":"1.187557995","rc":[{"batb":[[0,2,98.56],[1,1.99,77.35],[2,1.98,130.6]],"ltp":2.08,"tv":7086.09,"id":9633869}]}]}
{"op":"mcm","clk":"4230425682","pt":1631532864028,"mc":[{"id":"1.187557995","rc":[{"batb":[[1,1.99,100.86]],"batl":[[2,2.22,6.25]],"ltp":2.08,"tv":7086.09,"id":9633869}]}]}
{"op":"mcm","clk":"4230425872","pt":1631532866573,"mc":[{"id":"1.187557995","rc":[{"batb":[[0,2.02,58.79],[1,2,98.56],[2,1.99,100.86]],"ltp":2.08,"tv":7086.09,"id":9633869}]}]}
{"op":"mcm","clk":"4230426204","pt":1631532870470,"mc":[{"id":"1.187557995","rc":[{"trd":[[1.94,330.25]],"batb":[[2,1.84,571.67]],"batl":[[0,1.94,103.78]],"ltp":1.94,"tv":10683.03,"id":9342449}],"tv":17769.13}]}
{"op":"mcm","clk":"4230426373","pt":1631532872567,"mc":[{"id":"1.187557995","rc":[{"batl":[[0,1.94,247.78]],"ltp":1.94,"tv":10683.03,"id":9342449}]}]}
{"op":"mcm","clk":"4230426468","pt":1631532873561,"mc":[{"id":"1.187557995","rc":[{"trd":[[1.94,340.17]],"batb":[[1,1.92,151.95],[2,1.88,114.19]],"batl":[[0,1.94,256.13],[1,1.95,55.09],[2,1.96,1124.05]],"ltp":1.94,"tv":10692.95,"id":9342449}],"tv":17779.05}]}
{"op":"mcm","clk":"4230426851","pt":1631532877536,"mc":[{"id":"1.187557995","rc":[{"trd":[[1.93,532.12]],"batb":[[0,1.93,14.52]],"ltp":1.93,"tv":10714.64,"id":9342449}],"tv":17800.73}]}
{"op":"mcm","clk":"4230426921","pt":1631532878270,"mc":[{"id":"1.187557995","rc":[{"trd":[[1.92,72.69],[1.93,561.16]],"batb":[[0,1.92,143.43],[1,1.88,114.19],[2,1.86,171.24]],"batl":[[0,1.93,6.66],[1,1.94,256.13],[2,1.95,55.09]],"ltp":1.92,"tv":10760.71,"id":9342449}],"tv":17846.8}]}
{"op":"mcm","clk":"4230426973","pt":1631532878955,"mc":[{"id":"1.187557995","rc":[{"batl":[[1,1.94,320.98]],"ltp":1.92,"tv":10760.71,"id":9342449}]}]}
{"op":"mcm","clk":"4230427154","pt":1631532881246,"mc":[{"id":"1.187557995","rc":[{"batb":[[1,1.91,73.29],[2,1.88,114.19]],"ltp":1.92,"tv":10760.71,"id":9342449}]}]}
{"op":"mcm","clk":"4230427836","pt":1631532889678,"mc":[{"id":"1.187557995","rc":[{"batl":[[0,1.94,320.98],[1,1.95,55.09],[2,1.96,1124.05]],"ltp":1.92,"tv":10760.71,"id":9342449}]}]}
{"op":"mcm","clk":"4230427988","pt":1631532891361,"mc":[{"id":"1.187557995","rc":[{"batb":[[0,1.92,17.51],[1,1.79,221.72],[2,1.78,122.81]],"batl":[[0,1.94,144],[1,2.02,8.25],[2,2.04,82.23]],"ltp":1.92,"tv":10760.71,"id":9342449},{"batb":[[0,1.99,23.51],[1,1.96,84.01],[2,1.95,152.1]],"batl":[[0,2.08,1],[1,2.26,91.87],[2,2.28,122.56]],"ltp":2.08,"tv":7086.09,"id":9633869}]}]}
{"op":"mcm","clk":"4230428062","pt":1631532892399,"mc":[{"id":"1.187557995","rc":[{"batl":[[0,2.04,82.23],[1,2.06,110.06],[2,2.08,159.72]],"ltp":1.92,"tv":10760.71,"id":9342449},{"batb":[[0,1.96,84.01],[1,1.95,152.1],[2,1.94,165.48]],"ltp":2.08,"tv":7086.09,"id":9633869}]}]}
{"op":"mcm","clk":"4230428283","pt":1631532894654,"mc":[{"id":"1.187557995","rc":[{"batb":[[1,1.81,31.29],[2,1.79,221.72]],"batl":[[1,2.06,266.45],[2,2.08,283.89]],"ltp":1.92,"tv":10760.71,"id":9342449},{"batl":[[1,2.24,7.23],[2,2.26,91.87]],"ltp":2.08,"tv":7086.09,"id":9633869}]}]}
{"op":"mcm","clk":"4230428356","pt":1631532895578,"mc":[{"id":"1.187557995","rc":[{"batb":[[1,1.79,221.72],[2,1.78,122.81]],"batl":[[0,2.02,8.75],[1,2.04,86.23],[2,2.06,266.45]],"ltp":1.92,"tv":10760.71,"id":9342449},{"batb":[[0,1.99,27.51],[1,1.96,87.01],[2,1.95,156.1]],"batl":[[1,2.26,91.87],[2,2.28,122.56]],"ltp":2.08,"tv":7086.09,"id":9633869}]}]}
{"op":"mcm","clk":"4230428420","pt":1631532896269,"mc":[{"id":"1.187557995","rc":[{"batl":[[0,2.04,86.23],[1,2.06,110.06],[2,2.08,159.72]],"ltp":1.92,"tv":10760.71,"id":9342449},{"batb":[[0,1.96,87.01],[1,1.95,156.1],[2,1.94,165.48]],"ltp":2.08,"tv":7086.09,"id":9633869}]}]}
{"op":"mcm","clk":"4230428693","pt":1631532899337,"mc":[{"id":"1.187557995","rc":[{"trd":[[1.92,108.79]],"batb":[[0,1.85,180.56],[1,1.83,180.55],[2,1.79,221.72]],"batl":[[0,1.92,132.77],[1,1.94,152.98],[2,2.04,86.23]],"ltp":1.92,"tv":10796.81,"id":9342449},{"trd":[[2.08,398.14]],"batl":[[0,2.26,91.87],[1,2.28,122.56],[2,2.3,112.13]],"ltp":2.08,"tv":7087.09,"id":9633869}],"tv":17883.91}]}
{"op":"mcm","clk":"4230428812","pt":1631532900557,"mc":[{"id":"1.187557995","rc":[{"batl":[[2,2.02,52.08]],"ltp":1.92,"tv":10796.81,"id":9342449},{"batb":[[0,1.97,58.82],[1,1.96,87.01],[2,1.95,156.1]],"ltp":2.08,"tv":7087.09,"id":9633869}]}]}
{"op":"mcm","clk":"4230428984","pt":1631532902554,"mc":[{"id":"1.187557995","rc":[{"batb":[[0,1.86,35.19],[1,1.85,180.56],[2,1.83,180.55]],"batl":[[2,2.02,59.83]],"ltp":1.92,"tv":10796.81,"id":9342449},{"batb":[[0,1.99,28.51],[1,1.97,58.82],[2,1.96,87.01]],"batl":[[0,2.24,64.71],[1,2.26,91.87],[2,2.28,122.56]],"ltp":2.08,"tv":7087.09,"id":9633869}]}]}
{"op":"mcm","clk":"4230429073","pt":1631532903447,"mc":[{"id":"1.187557995","rc":[{"batb":[[1,1.96,87.01],[2,1.95,156.1]],"batl":[[0,2.24,6.98]],"ltp":2.08,"tv":7087.09,"id":9633869}]}]}
{"op":"mcm","clk":"4230429122","pt":1631532903967,"mc":[{"id":"1.187557995","rc":[{"batb":[[0,1.86,97.14]],"batl":[[0,1.91,94.6],[1,1.92,132.77],[2,1.94,152.98]],"ltp":1.92,"tv":10796.81,"id":9342449}]}]}
{"op":"mcm","clk":"4230429270","pt":1631532905639,"mc":[{"id":"1.187557995","rc":[{"batb":[[0,1.87,92.58],[1,1.86,97.14],[2,1.85,180.56]],"ltp":1.92,"tv":10796.81,"id":9342449}]}]}
{"op":"mcm","clk":"4230429357","pt":1631532906582,"mc":[{"id":"1.187557995","rc":[{"batb":[[0,1.79,221.72],[1,1.78,122.81],[2,1.77,170.11]],"batl":[[0,2.02,52.08],[1,2.04,86.23],[2,2.06,110.06]],"ltp":1.92,"tv":10796.81,"id":9342449},{"batb":[[0,2,58.82],[1,1.97,1.05],[2,1.96,87.01]],"batl":[[0,2.22,57.73]],"ltp":2.08,"tv":7087.09,"id":9633869}]}]}
{"op":"mcm","clk":"4230429426","pt":1631532907261,"mc":[{"id":"1.187557995","rc":[{"batl":[[0,2.04,86.23],[1,2.06,110.06],[2,2.08,159.72]],"ltp":1.92,"tv":10796.81,"id":9342449},{"batb":[[0,1.97,1.05],[1,1.96,87.01],[2,1.95,152.1]],"batl":[[0,2.26,91.87],[1,2.28,122.56],[2,2.3,112.13]],"ltp":2.08,"tv":7087.09,"id":9633869}]}]}
{"op":"mcm","clk":"4230429632","pt":1631532909666,"mc":[{"id":"1.187557995","rc":[{"batb":[[0,1.81,4],[1,1.8,5],[2,1.79,221.72]],"batl":[[1,2.06,256.88],[2,2.08,283.88]],"ltp":1.92,"tv":10796.81,"id":9342449}]}]}
{"op":"mcm","clk":"4230429697","pt":1631532910452,"mc":[{"id":"1.187557995","rc":[{"batb":[[2,1.79,225.72]],"ltp":1.92,"tv":10796.81,"id":9342449},{"batb":[[2,1.95,156.1]],"batl":[[0,2.26,94.87]],"ltp":2.08,"tv":7087.09,"id":9633869}]}]}
{"op":"mcm","clk":"4230430000","pt":1631532913652,"mc":[{"id":"1.187557995","rc":[{"batl":[[0,2.24,4],[1,2.26,94.87],[2,2.28,122.56]],"ltp":2.08,"tv":7087.09,"id":9633869}]}]}
{"op":"mcm","clk":"4230430191","pt":1631532915689,"mc":[{"id":"1.187557995","rc":[{"batl":[[0,2.04,4],[1,2.06,155.57],[2,2.08,132.35]],"ltp":1.92,"tv":10796.81,"id":9342449},{"batb":[[1,1.96,3],[2,1.95,32.51]],"ltp":2.08,"tv":7087.09,"id":9633869}]}]}
{"op":"mcm","clk":"4230430208","pt":1631532915850,"mc":[{"id":"1.187557995","rc":[{"batl":[[1,2.08,1],[2,2.5,278.33]],"ltp":1.92,"tv":10796.81,"id":9342449},{"batb":[[2,1.95,4]],"ltp":2.08,"tv":7087.09,"id":9633869}]}]}
{"op":"mcm","clk":"4230430324","pt":1631532917170,"mc":[{"id":"1.187557995","rc":[{"batb":[[0,1.79,221.72],[1,1.78,122.81],[2,1.77,313.13]],"batl":[[2,2.5,0]],"ltp":1.92,"tv":10796.81,"id":9342449},{"batl":[[0,2.26,91.87],[1,2.28,122.56],[2,2.3,112.13]],"ltp":2.08,"tv":7087.09,"id":9633869}]}]}
{"op":"mcm","clk":"4230430444","pt":1631532918573,"mc":[{"id":"1.187557995","rc":[{"batl":[[0,1.83,1770.21],[1,1.84,2078.8],[2,1.85,2017.66]],"ltp":1.92,"tv":10796.81,"id":9342449}]}]}
{"op":"mcm","clk":"4230430542","pt":1631532919566,"mc":[{"id":"1.187557995","rc":[{"batb":[[0,1.79,86.36]],"batl":[[0,1.83,189.42],[1,1.84,1039.4],[2,1.85,1186.23]],"ltp":1.92,"tv":10796.81,"id":9342449},{"batb":[[0,2.12,100.84],[1,2,887.49],[2,1.97,1.05]],"batl":[[0,2.28,122.56],[1,2.3,120.83],[2,2.32,7.11]],"ltp":2.08,"tv":7087.09,"id":9633869}]}]}
{"op":"mcm","clk":"4230430634","pt":1631532920557,"mc":[{"id":"1.187557995","rc":[{"batb":[[1,2,891.49],[2,1.99,4]],"ltp":2.08,"tv":7087.09,"id":9633869}]}]}
{"op":"mcm","clk":"4230430776","pt":1631532922174,"mc":[{"id":"1.187557995","rc":[{"batb":[[0,2.12,103.84],[1,2.1,4],[2,2,891.49]],"batl":[[0,2.28,145.15]],"ltp":2.08,"tv":7087.09,"id":9633869}]}]}
{"op":"mcm","clk":"4230430908","pt":1631532923577,"mc":[{"id":"1.187557995","rc":[{"batb":[[0,1.79,174.95]],"batl":[[0,1.83,276.08]],"ltp":1.92,"tv":10796.81,"id":9342449},{"batl":[[0,2.24,16.8],[1,2.28,145.15],[2,2.3,120.83]],"ltp":2.08,"tv":7087.09,"id":9633869}]}]}
{"op":"mcm","clk":"4230430924","pt":1631532923788,"mc":[{"id":"1.187557995","rc":[{"batb":[[0,2.14,30.08],[1,2.12,103.84],[2,2.1,4]],"batl":[[0,2.28,145.15],[1,2.3,120.83],[2,2.32,7.11]],"ltp":2.08,"tv":7087.09,"id":9633869}]}]}
{"op":"mcm","clk":"4230431487","pt":1631532930582,"mc":[{"id":"1.187557995","rc":[{"batl":[[0,1.83,259.38]],"ltp":1.92,"tv":10796.81,"id":9342449}]}]}
{"op":"mcm","clk":"4230431799","pt":1631532933670,"mc":[{"id":"1.187557995","rc":[{"batb":[[0,1.8,96.8],[1,1.79,174.95],[2,1.78,122.81]],"batl":[[0,1.82,95.73],[1,1.83,259.38],[2,1.84,1039.4]],"ltp":1.92,"tv":10796.81,"id":9342449}]}]}
{"op":"mcm","clk":"4230431821","pt":1631532933878,"mc":[{"id":"1.187557995","rc":[{"batb":[[2,2.08,103.36]],"ltp":2.08,"tv":7087.09,"id":9633869}]}]}
{"op":"mcm","clk":"4230432092","pt":1631532936693,"mc":[{"id":"1.187557995","rc":[{"batb":[[0,1.79,86.36],[1,1.78,122.81],[2,1.77,313.13]],"batl":[[0,1.83,172.72],[1,1.85,177.41],[2,1.92,119.8]],"ltp":1.92,"tv":10796.81,"id":9342449},{"batb":[[0,2.12,103.84],[1,2.08,103.36],[2,2.06,128.92]],"batl":[[0,2.28,122.56],[1,2.3,112.13]],"ltp":2.08,"tv":7087.09,"id":9633869}]}]}
{"op":"mcm","clk":"4230432142","pt":1631532937210,"mc":[{"id":"1.187557995","rc":[{"batb":[[0,1.68,118.71],[1,1.67,255.18],[2,1.66,174.27]],"batl":[[0,1.92,92.99],[1,1.93,106.01],[2,1.94,150.42]],"ltp":1.92,"tv":10796.81,"id":9342449},{"batb":[[0,2.08,95.8],[1,2.06,128.92],[2,2.04,124.08]],"batl":[[0,2.48,71.09],[1,2.5,87.93],[2,2.52,122.17]],"ltp":2.08,"tv":7087.09,"id":9633869}]}]}
{"op":"mcm","clk":"4230432454","pt":1631532940620,"mc":[{"id":"1.187557995","rc":[{"batb":[[0,1.69,5],[1,1.68,123.71],[2,1.67,260.18]],"batl":[[0,1.79,5.41],[1,1.92,92.99],[2,1.93,106.01]],"ltp":1.92,"tv":10796.81,"id":9342449},{"batl":[[0,2.46,3],[1,2.48,74.09],[2,2.5,87.93]],"ltp":2.08,"tv":7087.09,"id":9633869}]}]}
{"op":"mcm","clk":"4230432722","pt":1631532943431,"mc":[{"id":"1.187557995","rc":[{"trd":[[1.79,7.48]],"batl":[[0,1.79,1.67]],"ltp":1.79,"tv":10804.3,"id":9342449}],"tv":17891.39}]}
{"op":"mcm","clk":"4230432814","pt":1631532944320,"mc":[{"id":"1.187557995","rc":[{"batb":[[0,1.7,25],[1,1.69,5],[2,1.68,123.71]],"ltp":1.79,"tv":10804.3,"id":9342449},{"batb":[[0,2.1,59.72],[1,2.08,95.8],[2,2.06,128.92]],"batl":[[0,2.44,15],[1,2.46,3],[2,2.48,74.09]],"ltp":2.08,"tv":7087.09,"id":9633869}]}]}
{"op":"mcm","clk":"4230432879","pt":1631532945030,"mc":[{"id":"1.187557995","rc":[{"batb":[[0,1.75,131.57],[1,1.73,217.84],[2,1.69,5]],"batl":[[1,1.81,202.06],[2,1.83,183.63]],"ltp":1.79,"tv":10804.3,"id":9342449}]}]}
{"op":"mcm","clk":"4230433109","pt":1631532947639,"mc":[{"id":"1.187557995","rc":[{"batb":[[0,1.69,37.21],[1,1.68,123.71],[2,1.67,260.18]],"batl":[[1,1.92,92.99],[2,1.93,106.01]],"ltp":1.79,"tv":10804.3,"id":9342449},{"batb":[[0,2.08,95.8],[1,2.06,128.92],[2,2.04,124.08]],"batl":[[0,2.46,9.25],[1,2.48,74.09],[2,2.5,87.93]],"ltp":2.08,"tv":7087.09,"id":9633869}]}]}
{"op":"mcm","clk":"4230433182","pt":1631532948470,"mc":[{"id":"1.187557995","rc":[{"batb":[[0,1.69,5]],"ltp":1.79,"tv":10804.3,"id":9342449},{"batl":[[0,2.46,3]],"ltp":2.08,"tv":7087.09,"id":9633869}]}]}
{"op":"mcm","clk":"4230433381","pt":1631532950604,"mc":[{"id":"1.187557995","rc":[{"trd":[[1.79,33.89]],"batb":[[2,1.67,398.19]],"batl":[[0,1.97,25.83],[1,2,4],[2,2.08,1]],"ltp":1.79,"tv":10830.7,"id":9342449},{"batb":[[0,2.02,8.74],[1,2,120.25],[2,1.97,1.05]],"ltp":2.08,"tv":7087.09,"id":9633869}],"tv":17917.79}]}
{"op":"mcm","clk":"4230433522","pt":1631532952220,"mc":[{"id":"1.187557995","rc":[{"batb":[[1,1.68,118.71],[2,1.67,393.19]],"ltp":1.79,"tv":10830.7,"id":9342449},{"batl":[[1,2.48,71.09]],"ltp":2.08,"tv":7087.09,"id":9633869}]}]}
{"op":"mcm","clk":"4230433631","pt":1631532953431,"mc":[{"id":"1.187557995","rc":[{"batb":[[0,1.68,118.71],[1,1.67,393.19],[2,1.66,300.96]],"batl":[[0,1.72,173.43],[1,1.74,216.74],[2,1.75,1092.86]],"ltp":1.79,"tv":10830.7,"id":9342449},{"batl":[[0,2.48,71.09],[1,2.5,87.93],[2,2.52,122.17]],"ltp":2.08,"tv":7087.09,"id":9633869}]}]}
{"op":"mcm","clk":"4230433748","pt":1631532954615,"mc":[{"id":"1.187557995","rc":[{"batb":[[0,2.32,78.16],[1,2.18,93.97],[2,2.04,762.69]],"batl":[[0,2.46,8.13],[1,2.48,71.09],[2,2.5,87.93]],"ltp":2.08,"tv":7087.09,"id":9633869}]}]}
{"op":"mcm","clk":"4230433879","pt":1631532956337,"mc":[{"id":"1.187557995","rc":[{"batb":[[0,1.68,148.12]],"ltp":1.79,"tv":10830.7,"id":9342449},{"batl":[[1,2.48,93.56]],"ltp":2.08,"tv":7087.09,"id":9633869}]}]}
{"op":"mcm","clk":"4230434022","pt":1631532957668,"mc":[{"id":"1.187557995","rc":[{"batb":[[0,1.68,238.11]],"batl":[[0,1.72,261.33]],"ltp":1.79,"tv":10830.7,"id":9342449}]}]}
{"op":"mcm","clk":"4230434127","pt":1631532958561,"mc":[{"id":"1.187557995","rc":[{"batb":[[0,2.32,121.86]],"ltp":2.08,"tv":7087.09,"id":9633869}]}]}
{"op":"mcm","clk":"4230434330","pt":1631532960553,"mc":[{"id":"1.187557995","rc":[{"batb":[[1,2.24,109.71],[2,2.22,98.79]],"batl":[[0,2.4,5.03],[1,2.46,8.13],[2,2.48,93.56]],"ltp":2.08,"tv":7087.09,"id":9633869}]}]}
{"op":"mcm","clk":"4230434620","pt":1631532963542,"mc":[{"id":"1.187557995","rc":[{"batb":[[1,1.67,255.18],[2,1.66,174.27]],"batl":[[0,1.75,1092.86],[1,1.76,1060.72],[2,1.77,1060.72]],"ltp":1.79,"tv":10830.7,"id":9342449}]}]}
{"op":"mcm","clk":"4230434721","pt":1631532964542,"mc":[{"id":"1.187557995","rc":[{"batb":[[0,1.68,208.7]],"ltp":1.79,"tv":10830.7,"id":9342449},{"batb":[[0,2.32,78.16]],"batl":[[2,2.48,71.09]],"ltp":2.08,"tv":7087.09,"id":9633869}]}]}
{"op":"mcm","clk":"4230434896","pt":1631532966714,"mc":[{"id":"1.187557995","rc":[{"batb":[[0,1.69,141.3],[1,1.68,208.7],[2,1.67,255.18]],"batl":[[0,1.74,137.24],[1,1.75,1092.86],[2,1.76,1060.72]],"ltp":1.79,"tv":10830.7,"id":9342449}]}]}
{"op":"mcm","clk":"4230435007","pt":1631532968064,"mc":[{"id":"1.187557995","rc":[{"batb":[[2,1.67,393.19]],"batl":[[0,1.72,173.43],[1,1.74,353.98],[2,1.75,1092.86]],"ltp":1.79,"tv":10830.7,"id":9342449}]}]}
{"op":"mcm","clk":"4230435142","pt":1631532969627,"mc":[{"id":"1.187557995","rc":[{"batb":[[0,1.61,36.09],[1,1.59,148.84],[2,1.58,140.89]],"batl":[[0,1.8,109.53],[1,1.81,185.6],[2,1.82,165.13]],"ltp":1.79,"tv":10830.7,"id":9342449},{"batb":[[0,2.24,109.71],[1,2.22,98.79],[2,2.2,128.35]],"batl":[[1,2.64,5.68],[2,2.68,74.6]],"ltp":2.08,"tv":7087.09,"id":9633869}]}]}
{"op":"mcm","clk":"4230435414","pt":1631532972653,"mc":[{"id":"1.187557995","rc":[{"trd":[[1.71,7.07]],"batb":[[1,1.59,288.57],[2,1.58,292.89]],"batl":[[1,1.81,387.36]],"ltp":1.71,"tv":10837.77,"id":9342449},{"trd":[[2.4,5.03]],"batl":[[0,2.64,5.68],[1,2.68,74.6],[2,2.7,92.89]],"ltp":2.4,"tv":7092.12,"id":9633869}],"tv":17929.9}]}
{"op":"mcm","clk":"4230435445","pt":1631532973065,"mc":[{"id":"1.187557995","rc":[{"batb":[[0,1.59,288.57],[1,1.58,292.89],[2,1.57,345.12]],"ltp":1.71,"tv":10837.77,"id":9342449},{"batl":[[0,2.68,74.6],[1,2.7,92.89],[2,2.72,112.25]],"ltp":2.4,"tv":7092.12,"id":9633869}]}]}
{"op":"mcm","clk":"4230435655","pt":1631532975666,"mc":[{"id":"1.187557995","rc":[{"batb":[[0,1.61,5],[1,1.6,5],[2,1.59,288.57]],"ltp":1.71,"tv":10837.77,"id":9342449},{"batl":[[0,2.64,3],[1,2.68,74.6],[2,2.7,92.89]],"ltp":2.4,"tv":7092.12,"id":9633869}]}]}
{"op":"mcm","clk":"4230435733","pt":1631532976552,"mc":[{"id":"1.187557995","rc":[{"batb":[[0,1.62,5],[1,1.59,294.57],[2,1.58,297.89]],"ltp":1.71,"tv":10837.77,"id":9342449},{"batl":[[0,2.62,3],[1,2.68,77.6]],"ltp":2.4,"tv":7092.12,"id":9633869}]}]}
{"op":"mcm","clk":"4230436440","pt":1631532983557,"mc":[{"id":"1.187557995","rc":[{"batl":[[0,1.81,30.71],[1,1.85,27.5],[2,1.86,30.75]],"ltp":1.71,"tv":10837.77,"id":9342449},{"batb":[[0,2.22,6.84],[1,2.18,93.97],[2,2.16,8.03]],"ltp":2.4,"tv":7092.12,"id":9633869}]}]}
{"op":"mcm","clk":"4230436457","pt":1631532983765,"mc":[{"id":"1.187557995","rc":[{"batl":[[0,1.85,27.5],[1,1.86,30.75],[2,2.08,1]],"ltp":1.71,"tv":10837.77,"id":9342449},{"batb":[[0,2.18,93.97],[1,2.16,8.03],[2,1.97,1.05]],"ltp":2.4,"tv":7092.12,"id":9633869}]}]}
{"op":"mcm","clk":"4230436705","pt":1631532986681,"mc":[{"id":"1.187557995","rc":[{"batb":[[0,1.59,288.57],[1,1.58,297.89],[2,1.57,345.12]],"batl":[[0,1.63,135.15],[1,1.64,132.31],[2,1.73,11.56]],"ltp":1.71,"tv":10837.77,"id":9342449},{"batb":[[0,2.54,752.94],[1,2.52,730.82],[2,2.5,730.82]],"batl":[[0,2.68,74.6],[1,2.7,92.89],[2,2.72,112.25]],"ltp":2.4,"tv":7092.12,"id":9633869}]}]}
{"op":"mcm","clk":"4230436813","pt":1631532987686,"mc":[{"id":"1.187557995","rc":[{"batb":[[0,2.56,59.92],[1,2.54,752.94],[2,2.52,730.82]],"batl":[[0,2.64,7.58],[1,2.68,74.6],[2,2.7,92.89]],"ltp":2.4,"tv":7092.12,"id":9633869}]}]}
{"op":"mcm","clk":"4230436986","pt":1631532989457,"mc":[{"id":"1.187557995","rc":[{"batb":[[0,1.59,326.98]],"ltp":1.71,"tv":10837.77,"id":9342449},{"batl":[[1,2.68,94.14]],"ltp":2.4,"tv":7092.12,"id":9633869}]}]}
{"op":"mcm","clk":"4230437172","pt":1631532991554,"mc":[{"id":"1.187557995","rc":[{"batb":[[0,1.59,474.95]],"batl":[[0,1.63,279.49]],"ltp":1.71,"tv":10837.77,"id":9342449}]}]}
{"op":"mcm","clk":"4230437231","pt":1631532992179,"mc":[{"id":"1.187557995","rc":[{"batb":[[0,1.6,144.22],[1,1.59,474.95],[2,1.58,297.89]],"ltp":1.71,"tv":10837.77,"id":9342449}]}]}
{"op":"mcm","clk":"4230437349","pt":1631532993483,"mc":[{"id":"1.187557995","rc":[{"batl":[[2,1.68,180.04]],"ltp":1.71,"tv":10837.77,"id":9342449}]}]}
{"op":"mcm","clk":"4230437411","pt":1631532994059,"mc":[{"id":"1.187557995","rc":[{"batl":[[0,1.63,481.49]],"ltp":1.71,"tv":10837.77,"id":9342449}]}]}
{"op":"mcm","clk":"4230437520","pt":1631532995361,"mc":[{"id":"1.187557995","rc":[{"trd":[[1.6,50]],"batb":[[0,1.6,119.22]],"ltp":1.6,"tv":10887.77,"id":9342449}],"tv":17979.9}]}
{"op":"mcm","clk":"4230437621","pt":1631532996448,"mc":[{"id":"1.187557995","rc":[{"trd":[[1.59,301.24],[1.6,300.95]],"batb":[[0,1.59,324.33],[1,1.58,297.89],[2,1.57,345.12]],"batl":[[0,1.63,279.49]],"ltp":1.59,"tv":11439.96,"id":9342449},{"trd":[[2.64,7.58]],"batl":[[0,2.68,94.14],[1,2.7,92.89],[2,2.72,112.25]],"ltp":2.64,"tv":7099.7,"id":9633869}],"tv":18539.67}]}
{"op":"mcm","clk":"4230437791","pt":1631532998482,"mc":[{"id":"1.187557995","rc":[{"batl":[[0,1.6,33.19],[1,1.62,140.94],[2,1.63,279.49]],"ltp":1.59,"tv":11439.96,"id":9342449}]}]}
{"op":"mcm","clk":"4230437822","pt":1631532998853,"mc":[{"id":"1.187557995","rc":[{"batl":[[0,1.6,30.21],[2,1.63,429.4]],"ltp":1.59,"tv":11439.96,"id":9342449},{"batb":[[0,2.58,94.71],[1,2.56,59.92],[2,2.54,752.94]],"ltp":2.64,"tv":7099.7,"id":9633869}]}]}
{"op":"mcm","clk":"4230438046","pt":1631533001670,"mc":[{"id":"1.187557995","rc":[{"batl":[[1,1.61,131.57],[2,1.62,140.94]],"ltp":1.59,"tv":11439.96,"id":9342449},{"batl":[[0,2.68,19.54]],"ltp":2.64,"tv":7099.7,"id":9633869}]}]}
{"op":"mcm","clk":"4230438304","pt":1631533004685,"mc":[{"id":"1.187557995","rc":[{"batl":[[0,1.6,313.21],[2,1.62,320.67]],"ltp":1.59,"tv":11439.96,"id":9342449},{"batb":[[0,2.6,111.98],[1,2.58,94.71],[2,2.56,59.92]],"ltp":2.64,"tv":7099.7,"id":9633869}]}]}
{"op":"mcm","clk":"4230438449","pt":1631533006203,"mc":[{"id":"1.187557995","rc":[{"batl":[[0,1.6,283]],"ltp":1.59,"tv":11439.96,"id":9342449}]}]}
{"op":"mcm","clk":"4230438577","pt":1631533007403,"mc":[{"id":"1.187557995","rc":[{"batb":[[0,1.54,167.59],[1,1.53,133.25],[2,1.52,213.98]],"batl":[[1,1.68,180.04],[2,1.69,161.31]],"ltp":1.59,"tv":11439.96,"id":9342449},{"batb":[[0,2.46,91.23],[1,2.44,84.47],[2,2.42,187.64]],"batl":[[0,2.84,82.06],[1,2.86,101.94],[2,2.88,91.57]],"ltp":2.64,"tv":7099.7,"id":9633869}]}]}
{"op":"mcm","clk":"4230438680","pt":1631533008395,"mc":[{"id":"1.187557995","rc":[{"batl":[[0,1.68,138.9],[1,1.69,161.31],[2,1.7,164.72]],"ltp":1.59,"tv":11439.96,"id":9342449},{"batb":[[0,2.46,84.85]],"ltp":2.64,"tv":7099.7,"id":9633869}]}]}
{"op":"mcm","clk":"4230438994","pt":1631533011887,"mc":[{"id":"1.187557995","rc":[{"batb":[[0,1.6,2.32],[1,1.54,167.59],[2,1.53,133.25]],"ltp":1.59,"tv":11439.96,"id":9342449}]}]}
{"op":"mcm","clk":"4230439145","pt":1631533013503,"mc":[{"id":"1.187557995","rc":[{"batb":[[1,1.58,137.02],[2,1.57,155.71]],"batl":[[0,1.62,148.92],[1,1.63,135.2],[2,1.68,138.9]],"ltp":1.59,"tv":11439.96,"id":9342449}]}]}
{"op":"mcm","clk":"4230439239","pt":1631533014593,"mc":[{"id":"1.187557995","rc":[{"batl":[[2,1.67,51.14]],"ltp":1.59,"tv":11439.96,"id":9342449},{"batb":[[0,2.48,37.9],[1,2.46,84.85],[2,2.44,84.47]],"batl":[[0,2.82,39.76],[1,2.84,82.06],[2,2.86,101.94]],"ltp":2.64,"tv":7099.7,"id":9633869}]}]}
{"op":"mcm","clk":"4230439268","pt":1631533014903,"mc":[{"id":"1.187557995","rc":[{"batb":[[1,2.46,90.36]],"ltp":2.64,"tv":7099.7,"id":9633869}]}]}
{"op":"mcm","clk":"4230439445","pt":1631533016686,"mc":[{"id":"1.187557995","rc":[{"batb":[[1,1.54,167.59],[2,1.53,133.25]],"batl":[[0,1.68,138.9],[1,1.69,161.31],[2,1.7,164.72]],"ltp":1.59,"tv":11439.96,"id":9342449},{"batb":[[0,2.46,84.85],[1,2.44,84.47],[2,2.42,187.64]],"batl":[[0,2.84,82.06],[1,2.86,101.94],[2,2.88,91.57]],"ltp":2.64,"tv":7099.7,"id":9633869}]}]}
{"op":"mcm","clk":"4230439743","pt":1631533019717,"mc":[{"id":"1.187557995","rc":[{"batb":[[1,1.54,306.59],[2,1.53,305.42]],"batl":[[0,1.67,105.26],[1,1.69,224.81],[2,1.71,269.15]],"ltp":1.59,"tv":11439.96,"id":9342449},{"batb":[[0,2.42,69.62],[1,2.4,6.01],[2,2.38,6.96]],"ltp":2.64,"tv":7099.7,"id":9633869}]}]}
{"op":"mcm","clk":"4230439801","pt":1631533020400,"mc":[{"id":"1.187557995","rc":[{"batb":[[0,1.54,306.59],[1,1.53,305.42],[2,1.52,164.74]],"batl":[[0,1.59,21.1],[1,1.72,37.66],[2,1.84,4]],"ltp":1.59,"tv":11439.96,"id":9342449},{"batb":[[1,2.38,6.96],[2,1.97,1.05]],"ltp":2.64,"tv":7099.7,"id":9633869}]}]}
{"op":"mcm","clk":"4230440018","pt":1631533022630,"mc":[{"id":"1.187557995","rc":[{"batl":[[0,1.58,2867.41],[1,1.59,21.1],[2,1.6,2390.62]],"ltp":1.59,"tv":11439.96,"id":9342449}]}]}
{"op":"mcm","clk":"4230440142","pt":1631533023630,"mc":[{"id":"1.187557995","rc":[{"batl":[[0,1.58,223.44],[1,1.59,168.93],[2,1.6,1195.32]],"ltp":1.59,"tv":11439.96,"id":9342449},{"trd":[[2.76,14.5]],"batb":[[0,2.76,41.79],[1,2.52,63.01],[2,2.42,69.62]],"ltp":2.76,"tv":7114.2,"id":9633869}],"tv":18554.17}]}
{"op":"mcm","clk":"4230440245","pt":1631533024512,"mc":[{"id":"1.187557995","rc":[{"batb":[[0,1.54,163.41]],"ltp":1.59,"tv":11439.96,"id":9342449},{"batb":[[1,2.6,4],[2,2.58,4]],"batl":[[0,2.84,100.13],[1,2.86,96.69]],"ltp":2.76,"tv":7114.2,"id":9633869}]}]}
{"op":"mcm","clk":"4230440416","pt":1631533026136,"mc":[{"id":"1.187557995","rc":[{"batl":[[1,1.59,147.83]],"ltp":1.59,"tv":11439.96,"id":9342449}]}]}
{"op":"mcm","clk":"4230440603","pt":1631533027714,"mc":[{"id":"1.187557995","rc":[{"batb":[[1,1.53,433.77],[2,1.52,342.34]],"batl":[[0,1.57,111.96],[1,1.58,223.44],[2,1.59,147.83]],"ltp":1.59,"tv":11439.96,"id":9342449}]}]}
{"op":"mcm","clk":"4230440683","pt":1631533028499,"mc":[{"id":"1.187557995","rc":[{"batl":[[0,1.57,172.96]],"ltp":1.59,"tv":11439.96,"id":9342449}]}]}
{"op":"mcm","clk":"4230441082","pt":1631533032414,"mc":[{"id":"1.187557995","rc":[{"trd":[[1.57,65.24]],"batl":[[0,1.57,140.34]],"ltp":1.57,"tv":11505.21,"id":9342449}],"tv":18619.41}]}
{"op":"mcm","clk":"4230441175","pt":1631533033556,"mc":[{"id":"1.187557995","rc":[{"trd":[[1.57,95.24]],"batl":[[0,1.57,125.34]],"ltp":1.57,"tv":11535.21,"id":9342449}],"tv":18649.41}]}
{"op":"mcm","clk":"4230441279","pt":1631533034652,"mc":[{"id":"1.187557995","rc":[{"batl":[[1,1.58,196.39]],"ltp":1.57,"tv":11535.21,"id":9342449}]}]}
{"op":"mcm","clk":"4230441376","pt":1631533035643,"mc":[{"id":"1.187557995","rc":[{"batb":[[0,1.54,198.89]],"ltp":1.57,"tv":11535.21,"id":9342449}]}]}
{"op":"mcm","clk":"4230441510","pt":1631533037152,"mc":[{"id":"1.187557995","rc":[{"batb":[[0,1.55,50.45],[1,1.54,198.89],[2,1.53,433.77]],"ltp":1.57,"tv":11535.21,"id":9342449},{"batb":[[2,2.52,89.57]],"ltp":2.76,"tv":7114.2,"id":9633869}]}]}
{"op":"mcm","clk":"4230441795","pt":1631533040341,"mc":[{"id":"1.187557995","rc":[{"batb":[[2,2.58,3]],"ltp":2.76,"tv":7114.2,"id":9633869}]}]}
{"op":"mcm","clk":"4230442133","pt":1631533044665,"mc":[{"id":"1.187557995","rc":[{"trd":[[1.57,115.24]],"batl":[[0,1.57,115.34]],"ltp":1.57,"tv":11555.21,"id":9342449}],"tv":18669.41}]}
{"op":"mcm","clk":"4230442780","pt":1631533052696,"mc":[{"id":"1.187557995","rc":[{"batb":[[2,2.52,89.57]],"ltp":2.76,"tv":7114.2,"id":9633869}]}]}
{"op":"mcm","clk":"4230443043","pt":1631533055657,"mc":[{"id":"1.187557995","rc":[{"batb":[[2,2.58,3]],"ltp":2.76,"tv":7114.2,"id":9633869}]}]}
{"op":"mcm","clk":"4230443072","pt":1631533055963,"mc":[{"id":"1.187557995","rc":[{"trd":[[1.55,0.16]],"batb":[[0,1.55,50.37]],"ltp":1.55,"tv":11555.37,"id":9342449}],"tv":18669.57}]}
{"op":"mcm","clk":"4230443329","pt":1631533058771,"mc":[{"id":"1.187557995","rc":[{"trd":[[1.57,135.24]],"batl":[[0,1.57,105.34]],"ltp":1.57,"tv":11575.37,"id":9342449}],"tv":18689.57}]}
{"op":"mcm","clk":"4230444339","pt":1631533070581,"mc":[{"id":"1.187557995","rc":[{"trd":[[1.55,100.9]],"batb":[[0,1.54,163.41],[1,1.53,433.77],[2,1.52,342.34]],"batl":[[0,1.55,34.81],[1,1.57,105.34],[2,1.58,196.39]],"ltp":1.55,"tv":11676.1,"id":9342449},{"batb":[[2,2.52,89.57]],"ltp":2.76,"tv":7114.2,"id":9633869}],"tv":18790.31}]}
{"op":"mcm","clk":"4230444589","pt":1631533073392,"mc":[{"id":"1.187557995","rc":[{"batl":[[1,1.56,67.71],[2,1.57,105.34]],"ltp":1.55,"tv":11676.1,"id":9342449}]}]}
{"op":"mcm","clk":"4230444620","pt":1631533073805,"mc":[{"id":"1.187557995","rc":[{"batb":[[2,2.58,3]],"ltp":2.76,"tv":7114.2,"id":9633869}]}]}
{"op":"mcm","clk":"4230445025","pt":1631533078209,"mc":[{"id":"1.187557995","rc":[{"batl":[[2,1.57,44.34]],"ltp":1.55,"tv":11676.1,"id":9342449},{"batl":[[0,2.84,82.06]],"ltp":2.76,"tv":7114.2,"id":9633869}]}]}
{"op":"mcm","clk":"4230445314","pt":1631533081708,"mc":[{"id":"1.187557995","rc":[{"trd":[[1.54,1.2]],"batb":[[0,1.54,162.81]],"batl":[[0,1.55,487.81]],"ltp":1.54,"tv":11677.3,"id":9342449}],"tv":18791.5}]}
{"op":"mcm","clk":"4230445520","pt":1631533084510,"mc":[{"id":"1.187557995","rc":[{"trd":[[1.55,104.3]],"batb":[[0,1.54,37.44]],"batl":[[0,1.55,564.72]],"ltp":1.55,"tv":11680.7,"id":9342449},{"batl":[[0,2.86,96.69],[1,2.88,91.57],[2,2.94,357.79]],"ltp":2.76,"tv":7114.2,"id":9633869}],"tv":18794.91}]}
{"op":"mcm","clk":"4230445808","pt":1631533087686,"mc":[{"id":"1.187557995","rc":[{"batb":[[2,2.52,89.57]],"batl":[[0,2.86,116.3]],"ltp":2.76,"tv":7114.2,"id":9633869}]}]}
{"op":"mcm","clk":"4230445934","pt":1631533089089,"mc":[{"id":"1.187557995","rc":[{"batl":[[0,1.55,761.48]],"ltp":1.55,"tv":11680.7,"id":9342449},{"batb":[[0,2.8,108.92],[1,2.76,41.79],[2,2.6,4]],"ltp":2.76,"tv":7114.2,"id":9633869}]}]}
{"op":"mcm","clk":"4230446036","pt":1631533090331,"mc":[{"id":"1.187557995","rc":[{"batl":[[0,1.55,922.47]],"ltp":1.55,"tv":11680.7,"id":9342449},{"batb":[[0,2.8,198.03]],"ltp":2.76,"tv":7114.2,"id":9633869}]}]}
{"op":"mcm","clk":"4230446325","pt":1631533093511,"mc":[{"id":"1.187557995","rc":[{"batb":[[1,1.53,459.56]],"ltp":1.55,"tv":11680.7,"id":9342449}]}]}
{"op":"mcm","clk":"4230446801","pt":1631533095568,"mc":[{"id":"1.187557995","rc":[{"batb":[[0,2.8,108.92]],"ltp":2.76,"tv":7114.2,"id":9633869}]}]}
{"op":"mcm","clk":"4230448009","pt":1631533107926,"mc":[{"id":"1.187557995","rc":[{"trd":[[1.55,106.91]],"batl":[[0,1.55,921.17]],"ltp":1.55,"tv":11683.31,"id":9342449}],"tv":18797.52}]}
{"op":"mcm","clk":"4230448938","pt":1631533119255,"mc":[{"id":"1.187557995","rc":[{"batb":[[0,1.53,459.56],[1,1.52,342.34],[2,1.51,206.07]],"ltp":1.55,"tv":11683.31,"id":9342449},{"batl":[[0,2.86,96.69]],"ltp":2.76,"tv":7114.2,"id":9633869}]}]}
{"op":"mcm","clk":"4230449194","pt":1631533122212,"mc":[{"id":"1.187557995","rc":[{"batb":[[2,2.62,3]],"ltp":2.76,"tv":7114.2,"id":9633869}]}]}
{"op":"mcm","clk":"4230449599","pt":1631533127282,"mc":[{"id":"1.187557995","rc":[{"trd":[[1.55,147.18]],"batl":[[0,1.55,901.03]],"ltp":1.55,"tv":11723.58,"id":9342449}],"tv":18837.79}]}
{"op":"mcm","clk":"4230449994","pt":1631533132785,"mc":[{"id":"1.187557995","rc":[{"batb":[[0,1.53,502.23]],"ltp":1.55,"tv":11723.58,"id":9342449},{"batl":[[0,2.86,114.6]],"ltp":2.76,"tv":7114.2,"id":9633869}]}]}
{"op":"mcm","clk":"4230450702","pt":1631533142568,"mc":[{"id":"1.187557995","rc":[{"batb":[[0,1.53,459.56]],"ltp":1.55,"tv":11723.58,"id":9342449}]}]}
{"op":"mcm","clk":"4230450783","pt":1631533143715,"mc":[{"id":"1.187557995","rc":[{"batb":[[0,1.51,160.08],[1,1.5,44.62],[2,1.49,138.48]],"batl":[[0,1.55,464.67],[1,1.66,144.21],[2,1.67,153.17]],"ltp":1.55,"tv":11723.58,"id":9342449},{"batb":[[0,2.76,41.79],[1,2.52,89.57],[2,2.5,141.37]],"batl":[[0,3,4.32],[1,3.05,67.73],[2,3.1,78.99]],"ltp":2.76,"tv":7114.2,"id":9633869}]}]}
{"op":"mcm","clk":"4230450821","pt":1631533144208,"mc":[{"id":"1.187557995","rc":[{"batb":[[0,1.49,138.48],[1,1.48,241.8],[2,1.47,173.92]],"batl":[[0,1.55,11.67]],"ltp":1.55,"tv":11723.58,"id":9342449},{"batb":[[0,2.52,89.57],[1,2.5,141.37],[2,2.48,114.57]],"batl":[[0,3.05,67.73],[1,3.1,78.99],[2,3.15,102.21]],"ltp":2.76,"tv":7114.2,"id":9633869}]}]}
{"op":"mcm","clk":"4230450927","pt":1631533145710,"mc":[{"id":"1.187557995","rc":[{"batb":[[0,2.6,3],[1,2.52,89.57],[2,2.5,141.37]],"ltp":2.76,"tv":7114.2,"id":9633869}]}]}
{"op":"mcm","clk":"4230450992","pt":1631533146592,"mc":[{"id":"1.187557995","rc":[{"batb":[[1,1.48,383.99],[2,1.47,376.67]],"batl":[[1,1.66,277.17],[2,1.67,277.32]],"ltp":1.55,"tv":11723.58,"id":9342449},{"batb":[[0,2.52,89.57],[1,2.5,141.37],[2,2.48,114.57]],"ltp":2.76,"tv":7114.2,"id":9633869}]}]}
{"op":"mcm","clk":"4230451072","pt":1631533147682,"mc":[{"id":"1.187557995","rc":[{"batb":[[0,1.5,5],[1,1.49,145.48],[2,1.48,246.8]],"batl":[[0,1.55,11.75],[1,1.66,144.21],[2,1.67,153.17]],"ltp":1.55,"tv":11723.58,"id":9342449},{"batl":[[0,2.98,3],[1,3,3],[2,3.05,70.73]],"ltp":2.76,"tv":7114.2,"id":9633869}]}]}
{"op":"mcm","clk":"4230451386","pt":1631533151590,"mc":[{"id":"1.187557995","rc":[{"trd":[[1.53,0.16],[1.55,170.52]],"batb":[[0,1.55,199.81],[1,1.54,168.2],[2,1.5,53.7]],"batl":[[0,1.6,258.15],[1,1.61,141.01],[2,1.66,144.21]],"ltp":1.55,"tv":11747.08,"id":9342449},{"batb":[[0,2.54,41.94],[1,2.52,89.57],[2,2.5,141.37]],"batl":[[0,2.96,15],[1,2.98,3],[2,3,6.6]],"ltp":2.76,"tv":7114.2,"id":9633869}],"tv":18861.29}]}
{"op":"mcm","clk":"4230451538","pt":1631533153415,"mc":[{"id":"1.187557995","rc":[{"trd":[[1.55,364.52]],"batb":[[0,1.55,102.81]],"ltp":1.55,"tv":11941.08,"id":9342449},{"batb":[[0,2.52,89.57],[1,2.5,141.37],[2,2.48,114.57]],"batl":[[0,2.98,3],[1,3,6.6],[2,3.05,70.73]],"ltp":2.76,"tv":7114.2,"id":9633869}],"tv":19055.29}]}
{"op":"mcm","clk":"4230451647","pt":1631533154413,"mc":[{"id":"1.187557995","rc":[{"batb":[[0,1.56,187.63],[1,1.5,5],[2,1.49,145.48]],"batl":[[0,1.59,217.28],[1,1.66,144.21],[2,1.67,153.17]],"ltp":1.55,"tv":11941.08,"id":9342449},{"batl":[[1,3,3]],"ltp":2.76,"tv":7114.2,"id":9633869}]}]}
{"op":"mcm","clk":"4230451700","pt":1631533155021,"mc":[{"id":"1.187557995","rc":[{"batb":[[0,1.5,5],[1,1.49,145.48],[2,1.48,246.8]],"batl":[[0,1.66,144.21],[1,1.67,153.17],[2,1.68,170.78]],"ltp":1.55,"tv":11941.08,"id":9342449}]}]}
{"op":"mcm","clk":"4230451827","pt":1631533156583,"mc":[{"id":"1.187557995","rc":[{"batl":[[0,1.66,283.22],[1,1.67,277.33]],"ltp":1.55,"tv":11941.08,"id":9342449}]}]}
{"op":"mcm","clk":"4230451964","pt":1631533158194,"mc":[{"id":"1.187557995","rc":[{"batb":[[1,1.49,138.48]],"batl":[[0,1.66,333.2]],"ltp":1.55,"tv":11941.08,"id":9342449},{"batl":[[0,3.05,70.73],[1,3.1,78.99],[2,3.15,102.21]],"ltp":2.76,"tv":7114.2,"id":9633869}]}]}
{"op":"mcm","clk":"4230452072","pt":1631533159614,"mc":[{"id":"1.187557995","rc":[{"batb":[[1,1.48,55.76],[2,1.47,282.35]],"ltp":1.55,"tv":11941.08,"id":9342449},{"batl":[[0,3.05,3],[1,3.1,3.85],[2,3.15,0]],"ltp":2.76,"tv":7114.2,"id":9633869}]}]}
{"op":"mcm","clk":"4230452107","pt":1631533159924,"mc":[{"id":"1.187557995","rc":[{"batb":[[1,1.48,50.76],[2,1.46,184.85]],"ltp":1.55,"tv":11941.08,"id":9342449}]}]}
{"op":"mcm","clk":"4230452279","pt":1631533161399,"mc":[{"id":"1.187557995","rc":[{"batb":[[1,1.49,6],[2,1.48,50.76]],"ltp":1.55,"tv":11941.08,"id":9342449},{"batl":[[0,3,3],[1,3.05,3],[2,3.1,3.85]],"ltp":2.76,"tv":7114.2,"id":9633869}]}]}
{"op":"mcm","clk":"4230452395","pt":1631533162703,"mc":[{"id":"1.187557995","rc":[{"batb":[[0,1.61,194.78],[1,1.6,145.42],[2,1.59,10.11]],"ltp":1.55,"tv":11941.08,"id":9342449},{"batl":[[0,2.58,7.75],[1,2.68,713.62],[2,2.7,694.69]],"ltp":2.76,"tv":7114.2,"id":9633869}]}]}
{"op":"mcm","clk":"4230452517","pt":1631533163634,"mc":[{"id":"1.187557995","rc":[{"batb":[[1,1.6,274.96]],"ltp":1.55,"tv":11941.08,"id":9342449}]}]}
{"op":"mcm","clk":"4230452963","pt":1631533167527,"mc":[{"id":"1.187557995","rc":[{"batb":[[0,1.62,162.54],[1,1.61,194.78],[2,1.6,274.96]],"batl":[[0,1.65,196.55],[1,1.66,333.2],[2,1.67,277.33]],"ltp":1.55,"tv":11941.08,"id":9342449}]}]}
{"op":"mcm","clk":"4230453222","pt":1631533170025,"mc":[{"id":"1.187557995","rc":[{"batl":[[0,1.65,317.55]],"ltp":1.55,"tv":11941.08,"id":9342449}]}]}
{"op":"mcm","clk":"4230453449","pt":1631533172337,"mc":[{"id":"1.187557995","rc":[{"batb":[[0,1.62,194.02]],"ltp":1.55,"tv":11941.08,"id":9342449}]}]}
{"op":"mcm","clk":"4230453569","pt":1631533173639,"mc":[{"id":"1.187557995","rc":[{"batb":[[0,1.62,162.54],[1,1.57,47.57],[2,1.56,111.14]],"batl":[[1,1.75,32.46],[2,1.76,131.14]],"ltp":1.55,"tv":11941.08,"id":9342449},{"batb":[[0,2.32,7.39],[1,2.3,97.1],[2,2.28,185.85]],"batl":[[0,2.76,5.02],[1,2.78,65.69],[2,2.8,86.68]],"ltp":2.76,"tv":7114.2,"id":9633869}]}]}
{"op":"mcm","clk":"4230453640","pt":1631533174528,"mc":[{"id":"1.187557995","rc":[{"batb":[[0,1.56,111.14],[1,1.55,183.8],[2,1.54,178.49]],"batl":[[0,1.76,131.14],[1,1.77,159.1],[2,1.78,151.13]],"ltp":1.55,"tv":11941.08,"id":9342449},{"batb":[[0,2.3,97.1],[1,2.28,185.85],[2,2.26,106.75]],"batl":[[0,2.78,65.69],[1,2.8,86.68],[2,2.82,118.12]],"ltp":2.76,"tv":7114.2,"id":9633869}]}]}
{"op":"mcm","clk":"4230453816","pt":1631533176713,"mc":[{"id":"1.187557995","rc":[{"batb":[[2,1.54,367.07]],"batl":[[0,1.76,299.5],[2,1.78,352.48]],"ltp":1.55,"tv":11941.08,"id":9342449}]}]}
{"op":"mcm","clk":"4230453904","pt":1631533177708,"mc":[{"id":"1.187557995","rc":[{"batb":[[0,1.56,118.14],[1,1.55,189.8]],"batl":[[0,1.75,37.1],[1,1.76,304.5],[2,1.77,159.1]],"ltp":1.55,"tv":11941.08,"id":9342449},{"batb":[[0,2.32,9.14],[1,2.3,100.1],[2,2.28,189.85]],"batl":[[0,2.78,68.69]],"ltp":2.76,"tv":7114.2,"id":9633869}]}]}
{"op":"mcm","clk":"4230453933","pt":1631533178065,"mc":[{"id":"1.187557995","rc":[{"batb":[[2,1.54,178.49]],"batl":[[0,1.75,5],[1,1.76,136.14]],"ltp":1.55,"tv":11941.08,"id":9342449},{"batb":[[0,2.32,3]],"ltp":2.76,"tv":7114.2,"id":9633869}]}]}
{"op":"mcm","clk":"4230454139","pt":1631533180822,"mc":[{"id":"1.187557995","rc":[{"batb":[[0,1.61,194.78],[1,1.6,145.42],[2,1.56,118.14]],"batl":[[0,1.66,188.99],[1,1.67,124.19],[2,1.75,5]],"ltp":1.55,"tv":11941.08,"id":9342449}]}]}
{"op":"mcm","clk":"4230454410","pt":1631533184052,"mc":[{"id":"1.187557995","rc":[{"batb":[[0,1.62,89.73],[1,1.61,194.78],[2,1.6,145.42]],"batl":[[0,1.65,145.09],[1,1.66,188.99],[2,1.67,124.19]],"ltp":1.55,"tv":11941.08,"id":9342449}]}]}
{"op":"mcm","clk":"4230454759","pt":1631533188531,"mc":[{"id":"1.187557995","rc":[{"batb":[[0,1.56,118.14],[1,1.55,183.8],[2,1.54,178.49]],"batl":[[0,1.75,5],[1,1.76,136.14],[2,1.77,159.1]],"ltp":1.55,"tv":11941.08,"id":9342449}]}]}
{"op":"mcm","clk":"4230454880","pt":1631533190138,"mc":[{"id":"1.187557995","rc":[{"batl":[[1,1.76,131.14]],"ltp":1.55,"tv":11941.08,"id":9342449},{"batb":[[1,2.3,97.1],[2,2.28,185.85]],"ltp":2.76,"tv":7114.2,"id":9633869}]}]}
{"op":"mcm","clk":"4230455015","pt":1631533191647,"mc":[{"id":"1.187557995","rc":[{"batb":[[1,1.55,188.8],[2,1.54,367.07]],"batl":[[0,1.62,84.71],[1,1.75,5],[2,1.76,299.5]],"ltp":1.55,"tv":11941.08,"id":9342449}]}]}
{"op":"mcm","clk":"4230455133","pt":1631533193361,"mc":[{"id":"1.187557995","rc":[{"batb":[[1,2.3,100.1]],"ltp":2.76,"tv":7114.2,"id":9633869}]}]}
{"op":"mcm","clk":"4230455202","pt":1631533194377,"mc":[{"id":"1.187557995","rc":[{"batl":[[0,1.75,5],[1,1.76,299.5],[2,1.77,159.1]],"ltp":1.55,"tv":11941.08,"id":9342449}]}]}
{"op":"mcm","clk":"4230455448","pt":1631533197660,"mc":[{"id":"1.187557995","rc":[{"batl":[[1,1.8,29.17],[2,2.04,388.3]],"ltp":1.55,"tv":11941.08,"id":9342449},{"batb":[[1,2.3,3],[2,2.28,83.6]],"ltp":2.76,"tv":7114.2,"id":9633869}]}]}
{"op":"mcm","clk":"4230455592","pt":1631533199433,"mc":[{"id":"1.187557995","rc":[{"batb":[[0,1.56,111.14],[1,1.55,183.8]],"batl":[[2,2.08,1]],"ltp":1.55,"tv":11941.08,"id":9342449},{"batl":[[0,2.78,65.69]],"ltp":2.76,"tv":7114.2,"id":9633869}]}]}
{"op":"mcm","clk":"4230455674","pt":1631533200643,"mc":[{"id":"1.187557995","rc":[{"batb":[[0,1.54,367.07],[1,1.53,221.09],[2,1.52,154.39]],"batl":[[0,1.58,150.25],[1,1.59,148.33],[2,1.69,11.83]],"ltp":1.55,"tv":11941.08,"id":9342449},{"batb":[[0,2.7,174.08],[1,2.68,87.04],[2,2.66,87.04]],"batl":[[0,2.9,4.05],[1,2.94,683.04],[2,2.96,662.95]],"ltp":2.76,"tv":7114.2,"id":9633869}]}]}
{"op":"mcm","clk":"4230455755","pt":1631533201648,"mc":[{"id":"1.187557995","rc":[{"batb":[[0,2.7,226.21]],"batl":[[0,2.74,7.3],[1,2.9,4.05],[2,2.94,683.04]],"ltp":2.76,"tv":7114.2,"id":9633869}]}]}
{"op":"mcm","clk":"4230455824","pt":1631533202368,"mc":[{"id":"1.187557995","rc":[{"batb":[[0,1.54,372.07],[1,1.53,225.09]],"ltp":1.55,"tv":11941.08,"id":9342449}]}]}
{"op":"mcm","clk":"4230455908","pt":1631533203484,"mc":[{"id":"1.187557995","rc":[{"batb":[[0,1.55,31.36],[1,1.54,372.07],[2,1.53,225.09]],"batl":[[2,1.68,5]],"ltp":1.55,"tv":11941.08,"id":9342449},{"batl":[[1,2.88,20.25],[2,2.9,4.05]],"ltp":2.76,"tv":7114.2,"id":9633869}]}]}
{"op":"mcm","clk":"4230455943","pt":1631533203959,"mc":[{"id":"1.187557995","rc":[{"trd":[[1.57,137.41]],"ltp":1.57,"tv":11943.25,"id":9342449},{"trd":[[2.74,1.24]],"batl":[[0,2.74,6.06]],"ltp":2.74,"tv":7115.44,"id":9633869}],"tv":19058.7}]}
{"op":"mcm","clk":"4230456061","pt":1631533205462,"mc":[{"id":"1.187557995","rc":[{"trd":[[1.57,147.99]],"batb":[[0,1.55,103.21]],"batl":[[0,1.57,126.3],[1,1.58,150.25],[2,1.59,148.33]],"ltp":1.57,"tv":11953.83,"id":9342449},{"trd":[[2.74,7.3]],"batl":[[0,2.88,20.25],[1,2.9,4.05],[2,2.94,683.04]],"ltp":2.74,"tv":7121.5,"id":9633869}],"tv":19075.34}]}
{"op":"mcm","clk":"4230456135","pt":1631533206361,"mc":[{"id":"1.187557995","rc":[{"batl":[[1,1.58,435.69]],"ltp":1.57,"tv":11953.83,"id":9342449}]}]}
{"op":"mcm","clk":"4230456580","pt":1631533211980,"mc":[{"id":"1.187557995","rc":[{"trd":[[1.57,152.31]],"batl":[[0,1.57,124.14]],"ltp":1.57,"tv":11958.15,"id":9342449}],"tv":19079.65}]}
{"op":"mcm","clk":"4230456865","pt":1631533215266,"mc":[{"id":"1.187557995","rc":[{"trd":[[1.55,505.7]],"batb":[[0,1.55,32.62],[2,1.53,221.09]],"ltp":1.55,"tv":12099.33,"id":9342449}],"tv":19220.83}]}
{"op":"mcm","clk":"4230457154","pt":1631533218696,"mc":[{"id":"1.187557995","rc":[{"batb":[[1,1.54,193.58],[2,1.53,226.09]],"ltp":1.55,"tv":12099.33,"id":9342449},{"batb":[[0,2.7,52.13],[1,2.48,82.39],[2,2.46,85.36]],"batl":[[0,2.9,4.05],[1,3.05,60.22],[2,3.1,70.23]],"ltp":2.74,"tv":7121.5,"id":9633869}]}]}
{"op":"mcm","clk":"4230457206","pt":1631533219174,"mc":[{"id":"1.187557995","rc":[{"batb":[[0,1.49,162.54],[1,1.48,146.29],[2,1.47,221.26]],"batl":[[0,1.68,106.1],[1,1.69,154.56],[2,1.7,147.96]],"ltp":1.55,"tv":12099.33,"id":9342449},{"batb":[[0,2.48,82.39],[1,2.46,85.36],[2,2.44,201.5]],"batl":[[0,3.05,60.22],[1,3.1,70.23],[2,3.15,104.08]],"ltp":2.74,"tv":7121.5,"id":9633869}]}]}
{"op":"mcm","clk":"4230457454","pt":1631533222389,"mc":[{"id":"1.187557995","rc":[{"batb":[[0,1.49,168.54],[1,1.48,152.29],[2,1.47,470.75]],"batl":[[0,1.68,278.7],[2,1.7,382.98]],"ltp":1.55,"tv":12099.33,"id":9342449},{"batb":[[0,2.48,85.39],[1,2.46,88.36]],"batl":[[0,3.05,63.22]],"ltp":2.74,"tv":7121.5,"id":9633869}]}]}
{"op":"mcm","clk":"4230457708","pt":1631533226295,"mc":[{"id":"1.187557995","rc":[{"batl":[[0,1.68,5],[1,1.8,29.17],[2,2.08,1]],"ltp":1.55,"tv":12099.33,"id":9342449},{"batb":[[0,2.48,3],[1,2.46,3],[2,2.44,68.87]],"ltp":2.74,"tv":7121.5,"id":9633869}]}]}
{"op":"mcm","clk":"4230457808","pt":1631533227497,"mc":[{"id":"1.187557995","rc":[{"batb":[[0,1.48,146.29],[1,1.47,470.75],[2,1.46,392.15]],"ltp":1.55,"tv":12099.33,"id":9342449},{"batl":[[0,3.1,70.23],[1,3.15,104.08],[2,3.15,0]],"ltp":2.74,"tv":7121.5,"id":9633869}]}]}
{"op":"mcm","clk":"4230457964","pt":1631533229482,"mc":[{"id":"1.187557995","rc":[{"batb":[[0,1.47,470.75],[1,1.46,392.15],[2,1.29,3.45]],"batl":[[0,1.5,2.17],[1,1.51,202.87],[2,1.52,1434.06]],"ltp":1.55,"tv":12099.33,"id":9342449},{"batl":[[2,3.25,323.65]],"ltp":2.74,"tv":7121.5,"id":9633869}]}]}
{"op":"mcm","clk":"4230458021","pt":1631533230513,"mc":[{"id":"1.187557995","rc":[{"trd":[[1.5,2.17],[1.51,11.21]],"batb":[[2,1.41,213.22]],"batl":[[0,1.51,191.66],[1,1.52,1434.06],[2,1.53,1221.22]],"ltp":1.51,"tv":12112.71,"id":9342449},{"trd":[[2.96,5.72],[3,1.08]],"batb":[[0,2.92,107.61],[1,2.82,3],[2,2.8,4]],"ltp":2.96,"tv":7128.3,"id":9633869}],"tv":19241.01}]}
{"op":"mcm","clk":"4230458087","pt":1631533231506,"mc":[{"id":"1.187557995","rc":[{"batl":[[0,3.1,86.18]],"ltp":2.96,"tv":7128.3,"id":9633869}]}]}
{"op":"mcm","clk":"4230458219","pt":1631533233402,"mc":[{"id":"1.187557995","rc":[{"batb":[[0,1.47,506.23]],"batl":[[0,1.51,325.2]],"ltp":1.51,"tv":12112.71,"id":9342449}]}]}
{"op":"mcm","clk":"4230458444","pt":1631533236603,"mc":[{"id":"1.187557995","rc":[{"batb":[[0,1.48,35.82],[1,1.47,506.23],[2,1.46,392.15]],"batl":[[0,1.5,133.76],[1,1.51,325.2],[2,1.52,1434.06]],"ltp":1.51,"tv":12112.71,"id":9342449}]}]}
{"op":"mcm","clk":"4230458509","pt":1631533237483,"mc":[{"id":"1.187557995","rc":[{"batb":[[1,2.8,4],[2,2.74,87.96]],"ltp":2.96,"tv":7128.3,"id":9633869}]}]}
{"op":"mcm","clk":"4230458564","pt":1631533238315,"mc":[{"id":"1.187557995","rc":[{"batb":[[1,1.47,548.6]],"ltp":1.51,"tv":12112.71,"id":9342449}]}]}
{"op":"mcm","clk":"4230458707","pt":1631533240200,"mc":[{"id":"1.187557995","rc":[{"batb":[[0,1.43,171.77],[1,1.42,214],[2,1.41,401.42]],"batl":[[0,1.58,114.58],[1,1.59,170.32],[2,1.6,149.68]],"ltp":1.51,"tv":12112.71,"id":9342449},{"batb":[[0,2.74,87.96],[1,2.72,93.42],[2,2.7,93.72]],"batl":[[0,3.35,63.88],[1,3.4,68.79],[2,3.45,98.13]],"ltp":2.96,"tv":7128.3,"id":9633869}]}]}
{"op":"mcm","clk":"4230458816","pt":1631533241441,"mc":[{"id":"1.187557995","rc":[{"batb":[[0,1.43,234.2]],"batl":[[2,1.6,190.64]],"ltp":1.51,"tv":12112.71,"id":9342449},{"batl":[[0,3.35,67.38]],"ltp":2.96,"tv":7128.3,"id":9633869}]}]}
{"op":"mcm","clk":"4230458935","pt":1631533242692,"mc":[{"id":"1.187557995","rc":[{"batb":[[0,1.5,2],[1,1.43,234.2],[2,1.42,214]],"ltp":1.51,"tv":12112.71,"id":9342449}]}]}
{"op":"mcm","clk":"4230459004","pt":1631533243514,"mc":[{"id":"1.187557995","rc":[{"trd":[[1.5,6.17]],"batb":[[0,1.44,7],[1,1.43,242.2],[2,1.42,221]],"batl":[[1,1.59,334.22],[2,1.6,335.5]],"ltp":1.5,"tv":12116.71,"id":9342449},{"batl":[[0,3.35,70.38],[2,3.45,101.83]],"ltp":2.96,"tv":7128.3,"id":9633869}],"tv":19245.01}]}
{"op":"mcm","clk":"4230459101","pt":1631533244715,"mc":[{"id":"1.187557995","rc":[{"batb":[[0,1.45,7],[1,1.44,7],[2,1.43,242.2]],"batl":[[0,1.56,45.67],[1,1.58,114.58],[2,1.59,170.32]],"ltp":1.5,"tv":12116.71,"id":9342449},{"batb":[[0,2.78,4.66],[1,2.74,87.96],[2,2.72,93.42]],"batl":[[0,3.25,3],[1,3.35,70.38],[2,3.4,68.79]],"ltp":2.96,"tv":7128.3,"id":9633869}]}]}
{"op":"mcm","clk":"4230459135","pt":1631533245018,"mc":[{"id":"1.187557995","rc":[{"batl":[[0,1.58,114.58],[1,1.59,170.32],[2,1.6,190.64]],"ltp":1.5,"tv":12116.71,"id":9342449},{"batb":[[0,2.74,87.96],[1,2.72,93.42],[2,2.7,93.72]],"ltp":2.96,"tv":7128.3,"id":9633869}]}]}
{"op":"mcm","clk":"4230459289","pt":1631533246637,"mc":[{"id":"1.187557995","rc":[{"batl":[[1,3.3,3],[2,3.35,70.38]],"ltp":2.96,"tv":7128.3,"id":9633869}]}]}
{"op":"mcm","clk":"4230459366","pt":1631533247625,"mc":[{"id":"1.187557995","rc":[{"batb":[[0,1.49,142.41],[1,1.48,197.41],[2,1.46,35]],"batl":[[0,1.53,269.24],[1,1.54,166.72],[2,1.57,61.86]],"ltp":1.5,"tv":12116.71,"id":9342449},{"batb":[[0,2.76,34],[1,2.74,87.96],[2,2.72,93.42]],"batl":[[0,3.2,15],[1,3.25,3],[2,3.3,7.15]],"ltp":2.96,"tv":7128.3,"id":9633869}]}]}
{"op":"mcm","clk":"4230459452","pt":1631533248621,"mc":[{"id":"1.187557995","rc":[{"trd":[[1.53,4.5]],"batb":[[2,1.45,7]],"batl":[[0,1.53,267.07],[2,1.56,43.42]],"ltp":1.53,"tv":12121.05,"id":9342449},{"batb":[[0,2.78,5.16]],"ltp":2.96,"tv":7128.3,"id":9633869}],"tv":19249.35}]}
{"op":"mcm","clk":"4230459616","pt":1631533250644,"mc":[{"id":"1.187557995","rc":[{"batb":[[0,1.45,7],[1,1.44,7],[2,1.43,242.2]],"batl":[[0,1.58,114.58],[1,1.59,170.32],[2,1.6,190.64]],"ltp":1.53,"tv":12121.05,"id":9342449},{"batb":[[0,2.74,87.96],[1,2.72,93.42],[2,2.7,93.72]],"batl":[[0,3.25,3],[1,3.3,3],[2,3.35,70.38]],"ltp":2.96,"tv":7128.3,"id":9633869}]}]}
{"op":"mcm","clk":"4230459840","pt":1631533253230,"mc":[{"id":"1.187557995","rc":[{"batl":[[1,1.59,333.07],[2,1.6,335.5]],"ltp":1.53,"tv":12121.05,"id":9342449}]}]}
{"op":"mcm","clk":"4230460212","pt":1631533257539,"mc":[{"id":"1.187557995","rc":[{"batb":[[1,1.44,55.67],[2,1.43,234.2]],"batl":[[0,1.56,43.67],[1,1.58,114.58],[2,1.59,333.07]],"ltp":1.53,"tv":12121.05,"id":9342449},{"batb":[[0,2.78,5.16],[1,2.74,87.96],[2,2.72,93.42]],"batl":[[0,3.3,6.95],[1,3.35,67.38],[2,3.4,68.79]],"ltp":2.96,"tv":7128.3,"id":9633869}]}]}
{"op":"mcm","clk":"4230460228","pt":1631533257746,"mc":[{"id":"1.187557995","rc":[{"batb":[[1,1.43,234.2],[2,1.42,214]],"batl":[[0,1.58,114.58],[1,1.59,333.07],[2,1.6,335.5]],"ltp":1.53,"tv":12121.05,"id":9342449},{"batb":[[0,2.74,87.96],[1,2.72,93.42],[2,2.7,93.72]],"batl":[[0,3.3,3]],"ltp":2.96,"tv":7128.3,"id":9633869}]}]}
{"op":"mcm","clk":"4230460319","pt":1631533259043,"mc":[{"id":"1.187557995","rc":[{"batb":[[0,1.56,2.17],[1,1.45,7],[2,1.43,234.2]],"ltp":1.53,"tv":12121.05,"id":9342449}]}]}
{"op":"mcm","clk":"4230460508","pt":1631533261444,"mc":[{"id":"1.187557995","rc":[{"trd":[[1.56,4.34]],"batb":[[0,1.45,7],[1,1.44,6],[2,1.43,62.43]],"ltp":1.56,"tv":12125.39,"id":9342449},{"batl":[[0,3.25,3],[1,3.3,3],[2,3.35,3.5]],"ltp":2.96,"tv":7128.3,"id":9633869}],"tv":19253.69}]}
{"op":"mcm","clk":"4230460771","pt":1631533264567,"mc":[{"id":"1.187557995","rc":[{"batb":[[0,1.55,161.59],[1,1.54,179.83],[2,1.45,7]],"batl":[[0,1.58,4]],"ltp":1.56,"tv":12125.39,"id":9342449},{"trd":[[2.74,22]],"batb":[[0,2.74,3],[1,2.72,3]],"batl":[[0,2.86,2.25],[1,2.9,659.48],[2,2.92,640.08]],"ltp":2.74,"tv":7143.0,"id":9633869}],"tv":19268.39}]}
{"op":"mcm","clk":"4230460832","pt":1631533265348,"mc":[{"id":"1.187557995","rc":[{"batb":[[1,1.54,328.53],[2,1.46,184.1]],"batl":[[0,1.59,333.07],[1,1.6,335.5],[2,1.67,6]],"ltp":1.56,"tv":12125.39,"id":9342449},{"batb":[[0,2.7,93.72],[1,2.66,59.84],[2,2.64,398.44]],"ltp":2.74,"tv":7143.0,"id":9633869}]}]}
{"op":"mcm","clk":"4230460997","pt":1631533267352,"mc":[{"id":"1.187557995","rc":[{"batb":[[2,1.53,5]],"ltp":1.56,"tv":12125.39,"id":9342449},{"batl":[[0,2.84,3],[1,2.86,2.25],[2,2.88,3]],"ltp":2.74,"tv":7143.0,"id":9633869}]}]}
{"op":"mcm","clk":"4230461175","pt":1631533269680,"mc":[{"id":"1.187557995","rc":[{"batb":[[0,1.55,250.66]],"batl":[[0,1.59,470.99]],"ltp":1.56,"tv":12125.39,"id":9342449}]}]}
{"op":"mcm","clk":"4230461490","pt":1631533273158,"mc":[{"id":"1.187557995","rc":[{"trd":[[1.55,510.12]],"batb":[[0,1.55,248.45]],"ltp":1.55,"tv":12129.8,"id":9342449},{"batl":[[0,2.82,15],[1,2.84,3],[2,2.86,2.25]],"ltp":2.74,"tv":7143.0,"id":9633869}],"tv":19272.81}]}
{"op":"mcm","clk":"4230461686","pt":1631533275388,"mc":[{"id":"1.187557995","rc":[{"trd":[[1.59,327.27]],"batl":[[0,1.59,457.97]],"ltp":1.59,"tv":12155.83,"id":9342449}],"tv":19298.84}]}
{"op":"mcm","clk":"4230461975","pt":1631533278613,"mc":[{"id":"1.187557995","rc":[{"batb":[[0,1.56,44.6],[1,1.55,248.45],[2,1.54,328.53]],"ltp":1.59,"tv":12155.83,"id":9342449}]}]}
{"op":"mcm","clk":"4230462234","pt":1631533281532,"mc":[{"id":"1.187557995","rc":[{"batb":[[0,1.46,184.1],[1,1.43,62.43],[2,1.41,63.89]],"batl":[[0,1.78,30.75],[1,1.8,29.17],[2,2.08,1]],"ltp":1.59,"tv":12155.83,"id":9342449},{"batb":[[0,2.34,77.07],[1,2.28,6.66],[2,2.24,7.02]],"batl":[[0,3.35,3.5],[1,3.45,3.7],[2,2.86,0]],"ltp":2.74,"tv":7143.0,"id":9633869}]}]}
{"op":"mcm","clk":"4230462520","pt":1631533284701,"mc":[{"id":"1.187557995","rc":[{"batb":[[0,1.48,59.76],[1,1.47,5],[2,1.46,477.72]],"batl":[[0,1.71,36.81],[1,1.72,216.01],[2,1.74,216.97]],"ltp":1.59,"tv":12155.83,"id":9342449},{"batb":[[0,2.4,8.96],[1,2.38,4],[2,2.34,80.07]],"batl":[[0,3.1,6.75],[1,3.2,3],[2,3.35,3.5]],"ltp":2.74,"tv":7143.0,"id":9633869}]}]}
{"op":"mcm","clk":"4230462577","pt":1631533285324,"mc":[{"id":"1.187557995","rc":[{"batb":[[0,1.48,5],[2,1.46,191.1]],"batl":[[0,1.71,5],[1,1.72,5],[2,1.75,5]],"ltp":1.59,"tv":12155.83,"id":9342449},{"batb":[[0,2.4,3]],"batl":[[0,3.1,3]],"ltp":2.74,"tv":7143.0,"id":9633869}]}]}
{"op":"mcm","clk":"4230462770","pt":1631533287508,"mc":[{"id":"1.187557995","rc":[{"batb":[[2,2.36,4]],"ltp":2.74,"tv":7143.0,"id":9633869}]}]}
{"op":"mcm","clk":"4230462859","pt":1631533288547,"mc":[{"id":"1.187557995","rc":[{"trd":[[1.53,6.67]],"batb":[[0,1.57,187.87],[1,1.56,160.07],[2,1.48,52.51]],"batl":[[0,1.62,250.69],[1,1.63,135.1],[2,1.71,5]],"ltp":1.53,"tv":12158.0,"id":9342449},{"trd":[[2.86,1.16]],"batl":[[0,3.1,7.05]],"ltp":2.86,"tv":7144.16,"id":9633869}],"tv":19302.17}]}
{"op":"mcm","clk":"4230463031","pt":1631533290627,"mc":[{"id":"1.187557995","rc":[{"batb":[[2,1.49,25]],"batl":[[2,1.7,25]],"ltp":1.53,"tv":12158.0,"id":9342449},{"batb":[[0,2.42,15],[1,2.4,3],[2,2.38,4]],"batl":[[0,3.05,15],[1,3.1,7.05],[2,3.2,3]],"ltp":2.86,"tv":7144.16,"id":9633869}]}]}
{"op":"mcm","clk":"4230463055","pt":1631533290944,"mc":[{"id":"1.187557995","rc":[{"batb":[[2,1.48,52.51]],"ltp":1.53,"tv":12158.0,"id":9342449}]}]}
{"op":"mcm","clk":"4230463169","pt":1631533292352,"mc":[{"id":"1.187557995","rc":[{"batb":[[0,1.48,5],[1,1.47,5],[2,1.46,191.1]],"batl":[[0,1.71,5],[1,1.72,5],[2,1.75,5]],"ltp":1.53,"tv":12158.0,"id":9342449},{"batb":[[0,2.4,3],[1,2.38,4],[2,2.36,4]],"batl":[[0,3.1,3],[1,3.2,3],[2,3.35,3.5]],"ltp":2.86,"tv":7144.16,"id":9633869}]}]}
{"op":"mcm","clk":"4230463420","pt":1631533295628,"mc":[{"id":"1.187557995","rc":[{"batb":[[0,1.48,55.76],[2,1.46,477.72]],"batl":[[0,1.71,35.5],[1,1.72,216.01],[2,1.74,216.97]],"ltp":1.53,"tv":12158.0,"id":9342449},{"batb":[[0,2.4,8.06]],"batl":[[0,3.1,6.85]],"ltp":2.86,"tv":7144.16,"id":9633869}]}]}
{"op":"mcm","clk":"4230463449","pt":1631533295938,"mc":[{"id":"1.187557995","rc":[{"batb":[[0,1.48,5]],"batl":[[0,1.71,5]],"ltp":1.53,"tv":12158.0,"id":9342449},{"batb":[[0,2.4,3]],"batl":[[0,3.1,3]],"ltp":2.86,"tv":7144.16,"id":9633869}]}]}
{"op":"mcm","clk":"4230463700","pt":1631533299438,"mc":[{"id":"1.187557995","rc":[{"batb":[[1,1.46,470.72],[2,1.45,216.29]],"batl":[[1,1.72,211.01]],"ltp":1.53,"tv":12158.0,"id":9342449},{"batb":[[1,2.34,77.07],[2,2.28,6.66]],"batl":[[1,3.35,3.5],[2,3.45,3.7]],"ltp":2.86,"tv":7144.16,"id":9633869}]}]}
{"op":"mcm","clk":"4230463943","pt":1631533302635,"mc":[{"id":"1.187557995","rc":[{"batb":[[1,1.47,5],[2,1.46,470.72]],"batl":[[0,1.49,2.17],[1,1.71,5],[2,1.72,211.01]],"ltp":1.53,"tv":12158.0,"id":9342449},{"batb":[[1,2.38,3],[2,2.34,77.07]],"ltp":2.86,"tv":7144.16,"id":9633869}]}]}
{"op":"mcm","clk":"4230464065","pt":1631533304251,"mc":[{"id":"1.187557995","rc":[{"batl":[[0,1.71,5],[1,1.72,211.01],[2,1.74,216.97]],"ltp":1.53,"tv":12158.0,"id":9342449}]}]}
{"op":"mcm","clk":"4230464125","pt":1631533305136,"mc":[{"id":"1.187557995","rc":[{"batl":[[1,1.78,30.75],[2,1.8,29.17]],"ltp":1.53,"tv":12158.0,"id":9342449}]}]}
{"op":"mcm","clk":"4230464219","pt":1631533306234,"mc":[{"id":"1.187557995","rc":[{"batb":[[0,1.48,56.01]],"batl":[[0,1.71,40.5]],"ltp":1.53,"tv":12158.0,"id":9342449},{"batb":[[0,2.4,8.26]],"batl":[[0,3.1,6.75]],"ltp":2.86,"tv":7144.16,"id":9633869}]}]}
{"op":"mcm","clk":"4230464305","pt":1631533307270,"mc":[{"id":"1.187557995","rc":[{"batb":[[0,1.48,5]],"batl":[[0,1.71,5]],"ltp":1.53,"tv":12158.0,"id":9342449},{"batb":[[0,2.4,3]],"batl":[[0,3.1,3]],"ltp":2.86,"tv":7144.16,"id":9633869}]}]}
{"op":"mcm","clk":"4230464373","pt":1631533308058,"mc":[{"id":"1.187557995","rc":[{"batb":[[0,1.46,470.72],[1,1.45,216.29],[2,1.43,62.43]],"batl":[[0,1.5,187.79],[1,1.51,1447.1],[2,1.52,1229.32]],"ltp":1.53,"tv":12158.0,"id":9342449},{"batl":[[0,3.3,318.76],[1,3.35,312.87],[2,3.4,309.37]],"ltp":2.86,"tv":7144.16,"id":9633869}]}]}
{"op":"mcm","clk":"4230464477","pt":1631533309362,"mc":[{"id":"1.187557995","rc":[{"trd":[[1.5,19.59]],"batl":[[0,1.5,174.37]],"ltp":1.5,"tv":12171.42,"id":9342449},{"trd":[[3,7.79]],"batb":[[0,2.92,106.27],[1,2.62,56.4],[2,2.4,3]],"ltp":3.0,"tv":7150.87,"id":9633869}],"tv":19322.3}]}
{"op":"mcm","clk":"4230464628","pt":1631533311140,"mc":[{"id":"1.187557995","rc":[{"batb":[[0,1.46,518.01]],"ltp":1.5,"tv":12171.42,"id":9342449},{"batb":[[2,2.42,3]],"batl":[[0,3.25,31.48],[1,3.3,318.76],[2,3.35,312.87]],"ltp":3.0,"tv":7150.87,"id":9633869}]}]}
{"op":"mcm","clk":"4230464744","pt":1631533312546,"mc":[{"id":"1.187557995","rc":[{"batb":[[0,1.46,550.24]],"batl":[[0,1.5,306.35]],"ltp":1.5,"tv":12171.42,"id":9342449},{"batb":[[0,2.92,124.97]],"ltp":3.0,"tv":7150.87,"id":9633869}]}]}
{"op":"mcm","clk":"4230464902","pt":1631533314474,"mc":[{"id":"1.187557995","rc":[{"batb":[[1,2.8,4.93],[2,2.68,4.61]],"ltp":3.0,"tv":7150.87,"id":9633869}]}]}
{"op":"mcm","clk":"4230464941","pt":1631533314940,"mc":[{"id":"1.187557995","rc":[{"batb":[[2,2.72,70.62]],"ltp":3.0,"tv":7150.87,"id":9633869}]}]}
{"op":"mcm","clk":"4230465076","pt":1631533316454,"mc":[{"id":"1.187557995","rc":[{"trd":[[1.5,21.79]],"batl":[[0,1.5,304.15]],"ltp":1.5,"tv":12173.62,"id":9342449},{"trd":[[3,8.89]],"batb":[[2,2.78,5.16]],"ltp":3.0,"tv":7151.97,"id":9633869}],"tv":19325.6}]}
{"op":"mcm","clk":"4230465307","pt":1631533319048,"mc":[{"id":"1.187557995","rc":[{"batb":[[0,1.47,61.14],[1,1.46,550.24],[2,1.45,216.29]],"ltp":1.5,"tv":12173.62,"id":9342449}]}]}
{"op":"mcm","clk":"4230465655","pt":1631533322661,"mc":[{"id":"1.187557995","rc":[{"batl":[[0,1.49,153.56],[1,1.5,362.15],[2,1.51,1447.1]],"ltp":1.5,"tv":12173.62,"id":9342449}]}]}
{"op":"mcm","clk":"4230465996","pt":1631533326668,"mc":[{"id":"1.187557995","rc":[{"batb":[[1,1.46,502.95]],"batl":[[2,1.51,180.54]],"ltp":1.5,"tv":12173.62,"id":9342449},{"batb":[[0,2.92,106.27]],"batl":[[0,3.35,3.5],[1,3.45,75.7],[2,3.5,73.77]],"ltp":3.0,"tv":7151.97,"id":9633869}]}]}
{"op":"mcm","clk":"4230466066","pt":1631533327555,"mc":[{"id":"1.187557995","rc":[{"batb":[[0,1.41,167.01],[1,1.4,503.97],[2,1.39,253.93]],"batl":[[0,1.58,131.96],[1,1.59,171.06],[2,1.6,251.19]],"ltp":1.5,"tv":12173.62,"id":9342449},{"batb":[[0,2.72,70.62],[1,2.7,91.08],[2,2.68,123.07]],"batl":[[0,3.45,72],[1,3.5,73.77],[2,3.55,95.13]],"ltp":3.0,"tv":7151.97,"id":9633869}]}]}
{"op":"mcm","clk":"4230466132","pt":1631533328284,"mc":[{"id":"1.187557995","rc":[{"batl":[[0,1.47,57.85],[1,1.58,131.96],[2,1.59,171.06]],"ltp":1.5,"tv":12173.62,"id":9342449}]}]}
{"op":"mcm","clk":"4230466319","pt":1631533330687,"mc":[{"id":"1.187557995","rc":[{"batb":[[0,1.43,7],[1,1.42,7],[2,1.41,175.01]],"ltp":1.5,"tv":12173.62,"id":9342449},{"batl":[[0,3.35,3],[1,3.45,74],[2,3.5,73.77]],"ltp":3.0,"tv":7151.97,"id":9633869}]}]}
{"op":"mcm","clk":"4230466348","pt":1631533331002,"mc":[{"id":"1.187557995","rc":[{"batl":[[0,1.47,1.38]],"ltp":1.5,"tv":12173.62,"id":9342449}]}]}
{"op":"mcm","clk":"4230466421","pt":1631533331786,"mc":[{"id":"1.187557995","rc":[{"batb":[[1,1.42,507]],"ltp":1.5,"tv":12173.62,"id":9342449}]}]}
{"op":"mcm","clk":"4230466916","pt":1631533337674,"mc":[{"id":"1.187557995","rc":[{"trd":[[1.47,2.76]],"batb":[[0,1.43,7.79]],"batl":[[0,1.55,41.9]],"ltp":1.47,"tv":12176.38,"id":9342449},{"batb":[[0,2.8,5.18],[1,2.72,70.62],[2,2.7,91.08]],"ltp":3.0,"tv":7151.97,"id":9633869}],"tv":19328.36}]}
{"op":"mcm","clk":"4230466997","pt":1631533338563,"mc":[{"id":"1.187557995","rc":[{"trd":[[1.54,2.77]],"batb":[[0,1.48,230.22],[1,1.47,203.6],[2,1.43,7]],"batl":[[0,1.5,20.52],[1,1.52,202.76],[2,1.53,171.29]],"ltp":1.54,"tv":12177.96,"id":9342449},{"batb":[[0,3,20]],"batl":[[0,3.15,18.5],[1,3.35,3],[2,3.45,74]],"ltp":3.0,"tv":7151.97,"id":9633869}],"tv":19329.94}]}
{"op":"mcm","clk":"4230467035","pt":1631533338979,"mc":[{"id":"1.187557995","rc":[{"batl":[[0,1.52,202.76],[1,1.53,171.29],[2,1.58,131.96]],"ltp":1.54,"tv":12177.96,"id":9342449},{"batb":[[0,2.72,70.62],[1,2.7,91.08],[2,2.68,123.07]],"batl":[[0,3.35,3],[1,3.45,74],[2,3.5,73.77]],"ltp":3.0,"tv":7151.97,"id":9633869}]}]}
{"op":"mcm","clk":"4230467170","pt":1631533340592,"mc":[{"id":"1.187557995","rc":[{"batl":[[2,1.57,70.62]],"ltp":1.54,"tv":12177.96,"id":9342449},{"batb":[[0,2.74,43.56],[1,2.72,70.62],[2,2.7,91.08]],"batl":[[0,3.3,15],[1,3.35,3],[2,3.45,74]],"ltp":3.0,"tv":7151.97,"id":9633869}]}]}
{"op":"mcm","clk":"4230467243","pt":1631533341582,"mc":[{"id":"1.187557995","rc":[{"batb":[[2,1.43,62.43]],"batl":[[2,1.55,45.3]],"ltp":1.54,"tv":12177.96,"id":9342449},{"batb":[[0,2.8,4.93]],"batl":[[1,3.35,6.3]],"ltp":3.0,"tv":7151.97,"id":9633869}]}]}
{"op":"mcm","clk":"4230467422","pt":1631533343611,"mc":[{"id":"1.187557995","rc":[{"batb":[[0,1.49,77.76],[1,1.48,272.05],[2,1.47,203.6]],"batl":[[0,1.51,163.92],[1,1.52,202.76],[2,1.53,171.29]],"ltp":1.54,"tv":12177.96,"id":9342449},{"batl":[[2,3.45,72]],"ltp":3.0,"tv":7151.97,"id":9633869}]}]}
{"op":"mcm","clk":"4230467515","pt":1631533344706,"mc":[{"id":"1.187557995","rc":[{"batb":[[0,1.43,7],[1,1.42,500],[2,1.41,167.01]],"batl":[[0,1.58,131.96],[1,1.59,171.06],[2,1.6,251.19]],"ltp":1.54,"tv":12177.96,"id":9342449},{"batb":[[0,2.82,43.56]],"batl":[[0,3.35,3],[1,3.45,72],[2,3.5,73.77]],"ltp":3.0,"tv":7151.97,"id":9633869}]}]}
{"op":"mcm","clk":"4230467542","pt":1631533344968,"mc":[{"id":"1.187557995","rc":[{"batb":[[0,2.72,70.62],[1,2.7,91.08],[2,2.68,123.07]],"ltp":3.0,"tv":7151.97,"id":9633869}]}]}
{"op":"mcm","clk":"4230467673","pt":1631533346583,"mc":[{"id":"1.187557995","rc":[{"batl":[[0,1.51,74],[1,1.58,131.96],[2,1.59,171.06]],"ltp":1.54,"tv":12177.96,"id":9342449}]}]}
{"op":"mcm","clk":"4230467732","pt":1631533347412,"mc":[{"id":"1.187557995","rc":[{"batb":[[1,1.42,506]],"batl":[[0,1.58,131.96],[1,1.59,171.06],[2,1.6,460.06]],"ltp":1.54,"tv":12177.96,"id":9342449}]}]}
{"op":"mcm","clk":"4230467897","pt":1631533349593,"mc":[{"id":"1.187557995","rc":[{"batb":[[2,1.4,305.22]],"ltp":1.54,"tv":12177.96,"id":9342449},{"batl":[[1,3.5,3.03],[2,3.5,0]],"ltp":3.0,"tv":7151.97,"id":9633869}]}]}
{"op":"mcm","clk":"4230467962","pt":1631533350381,"mc":[{"id":"1.187557995","rc":[{"batb":[[0,1.54,2.17],[1,1.43,7],[2,1.42,506]],"ltp":1.54,"tv":12177.96,"id":9342449}]}]}
{"op":"mcm","clk":"4230468049","pt":1631533351484,"mc":[{"id":"1.187557995","rc":[{"batb":[[1,1.43,67.43],[2,1.42,6]],"batl":[[0,1.55,45.7],[1,1.58,131.96],[2,1.59,171.06]],"ltp":1.54,"tv":12177.96,"id":9342449},{"batb":[[0,2.8,4.33],[1,2.72,70.62],[2,2.7,91.08]],"batl":[[0,3.35,6.7]],"ltp":3.0,"tv":7151.97,"id":9633869}]}]}
{"op":"mcm","clk":"4230468167","pt":1631533352690,"mc":[{"id":"1.187557995","rc":[{"batb":[[0,1.55,290.61],[1,1.54,170.8],[2,1.53,12.33]],"batl":[[0,1.59,171.06],[1,1.6,473.08],[2,1.61,141.38]],"ltp":1.54,"tv":12177.96,"id":9342449},{"trd":[[2.72,14.7]],"batb":[[0,2.7,91.08],[1,2.68,123.07],[2,2.66,4.28]],"batl":[[0,2.86,668.7],[1,2.88,649.04],[2,2.9,651.09]],"ltp":2.72,"tv":7166.67,"id":9633869}],"tv":19344.64}]}
{"op":"mcm","clk":"4230468237","pt":1631533353526,"mc":[{"id":"1.187557995","rc":[{"batb":[[0,1.55,435.29],[1,1.54,168.63]],"ltp":1.54,"tv":12177.96,"id":9342449}]}]}
{"op":"mcm","clk":"4230468358","pt":1631533354679,"mc":[{"id":"1.187557995","rc":[{"batb":[[0,1.55,440.29],[1,1.54,174.63]],"ltp":1.54,"tv":12177.96,"id":9342449}]}]}
{"op":"mcm","clk":"4230468634","pt":1631533357706,"mc":[{"id":"1.187557995","rc":[{"batb":[[0,1.56,35.56],[1,1.55,501.5],[2,1.54,174.63]],"batl":[[0,1.59,317.23]],"ltp":1.54,"tv":12177.96,"id":9342449},{"batl":[[0,2.84,29.86],[1,2.86,668.7],[2,2.88,649.04]],"ltp":2.72,"tv":7166.67,"id":9633869}]}]}
{"op":"mcm","clk":"4230468793","pt":1631533359386,"mc":[{"id":"1.187557995","rc":[{"trd":[[1.56,8.5]],"batb":[[0,1.56,10.4]],"ltp":1.56,"tv":12182.12,"id":9342449}],"tv":19348.8}]}
{"op":"mcm","clk":"4230468923","pt":1631533360908,"mc":[{"id":"1.187557995","rc":[{"batb":[[0,1.57,20.89],[1,1.56,68.01],[2,1.55,501.5]],"ltp":1.56,"tv":12182.12,"id":9342449}]}]}
{"op":"mcm","clk":"4230469120","pt":1631533363327,"mc":[{"id":"1.187557995","rc":[{"batl":[[1,1.6,460.06]],"ltp":1.56,"tv":12182.12,"id":9342449}]}]}
{"op":"mcm","clk":"4230469201","pt":1631533364318,"mc":[{"id":"1.187557995","rc":[{"batb":[[2,1.55,475.42]],"ltp":1.56,"tv":12182.12,"id":9342449}]}]}
{"op":"mcm","clk":"4230469265","pt":1631533365207,"mc":[{"id":"1.187557995","rc":[{"trd":[[1.59,331.92]],"batl":[[0,1.59,314.91]],"ltp":1.59,"tv":12186.77,"id":9342449}],"tv":19353.44}]}
{"op":"mcm","clk":"4230469465","pt":1631533367615,"mc":[{"id":"1.187557995","rc":[{"batl":[[0,1.59,182.35],[1,1.6,253.93]],"ltp":1.59,"tv":12186.77,"id":9342449},{"batb":[[0,2.68,4.61],[1,2.66,4.28],[2,2.62,56.4]],"batl":[[1,2.9,2.05],[2,3.1,3.95]],"ltp":2.72,"tv":7166.67,"id":9633869}]}]}
{"op":"mcm","clk":"4230469537","pt":1631533368402,"mc":[{"id":"1.187557995","rc":[{"batb":[[0,1.47,179.66],[1,1.44,6],[2,1.43,53.43]],"batl":[[0,1.71,5],[1,1.79,29.5],[2,2.08,1]],"ltp":1.59,"tv":12186.77,"id":9342449},{"batb":[[0,2.32,79.58],[1,2.26,6.48],[2,1.97,1.05]],"batl":[[0,3.3,3],[1,3.35,3.5],[2,3.5,3.03]],"ltp":2.72,"tv":7166.67,"id":9633869}]}]}
{"op":"mcm","clk":"4230469810","pt":1631533371641,"mc":[{"id":"1.187557995","rc":[{"batb":[[0,1.48,49.01],[1,1.47,366.31],[2,1.46,215.24]],"batl":[[1,1.72,157.01],[2,1.74,217.26]],"ltp":1.59,"tv":12186.77,"id":9342449},{"batb":[[0,2.4,3],[1,2.38,8.96],[2,2.32,79.58]],"batl":[[0,3.1,7.25],[1,3.15,2],[2,3.3,3]],"ltp":2.72,"tv":7166.67,"id":9633869}]}]}
{"op":"mcm","clk":"4230469848","pt":1631533372015,"mc":[{"id":"1.187557995","rc":[{"batb":[[0,1.47,366.31],[1,1.46,215.24],[2,1.44,6]],"batl":[[1,1.72,123.1]],"ltp":1.59,"tv":12186.77,"id":9342449},{"batb":[[1,2.38,3]],"batl":[[0,3.1,3]],"ltp":2.72,"tv":7166.67,"id":9633869}]}]}
{"op":"mcm","clk":"4230470061","pt":1631533374517,"mc":[{"id":"1.187557995","rc":[{"batl":[[1,1.79,29.5],[2,2.08,1]],"ltp":1.59,"tv":12186.77,"id":9342449}]}]}
{"op":"mcm","clk":"4230470150","pt":1631533375612,"mc":[{"id":"1.187557995","rc":[{"batb":[[0,1.48,500],[1,1.47,366.31],[2,1.46,215.24]],"ltp":1.59,"tv":12186.77,"id":9342449}]}]}
{"op":"mcm","clk":"4230470207","pt":1631533376231,"mc":[{"id":"1.187557995","rc":[{"trd":[[1.48,4.34]],"batb":[[0,1.48,497.83]],"ltp":1.48,"tv":12191.11,"id":9342449}],"tv":19357.78}]}
{"op":"mcm","clk":"4230470329","pt":1631533377640,"mc":[{"id":"1.187557995","rc":[{"batb":[[1,1.47,361.31]],"batl":[[0,1.51,2411.06],[1,1.52,1433.58],[2,1.53,1221.22]],"ltp":1.48,"tv":12191.11,"id":9342449},{"batl":[[0,3.15,2],[1,3.25,588.46],[2,3.3,317.14]],"ltp":2.72,"tv":7166.67,"id":9633869}]}]}
{"op":"mcm","clk":"4230470401","pt":1631533378525,"mc":[{"id":"1.187557995","rc":[{"trd":[[1.51,24.46]],"batl":[[0,1.51,270.55]],"ltp":1.51,"tv":12204.36,"id":9342449},{"trd":[[2.96,12.48]],"batb":[[0,2.9,43.85],[1,2.58,58.49],[2,2.42,757.56]],"ltp":2.96,"tv":7173.43,"id":9633869}],"tv":19377.79}]}
{"op":"mcm","clk":"4230470622","pt":1631533381143,"mc":[{"id":"1.187557995","rc":[{"batb":[[2,2.4,3]],"batl":[[0,3.15,12]],"ltp":2.96,"tv":7173.43,"id":9633869}]}]}
{"op":"mcm","clk":"4230470826","pt":1631533383646,"mc":[{"id":"1.187557995","rc":[{"batl":[[0,1.51,397.45]],"ltp":1.51,"tv":12204.36,"id":9342449}]}]}
{"op":"mcm","clk":"4230470845","pt":1631533383853,"mc":[{"id":"1.187557995","rc":[{"batb":[[0,2.9,63.06]],"batl":[[2,3.3,314.14]],"ltp":2.96,"tv":7173.43,"id":9633869}]}]}
{"op":"mcm","clk":"4230471005","pt":1631533385566,"mc":[{"id":"1.187557995","rc":[{"trd":[[1.51,26.6]],"batl":[[0,1.51,449.31]],"ltp":1.51,"tv":12206.5,"id":9342449},{"trd":[[2.96,13.57]],"batb":[[1,2.74,4.79],[2,2.62,5.54]],"ltp":2.96,"tv":7174.53,"id":9633869}],"tv":19381.03}]}
{"op":"mcm","clk":"4230471063","pt":1631533386344,"mc":[{"id":"1.187557995","rc":[{"trd":[[1.48,104.34]],"batb":[[0,1.48,447.83]],"ltp":1.48,"tv":12306.5,"id":9342449}],"tv":19481.03}]}
{"op":"mcm","clk":"4230471171","pt":1631533387649,"mc":[{"id":"1.187557995","rc":[{"trd":[[1.48,1000]],"batb":[[0,1.47,361.31],[1,1.46,215.24],[2,1.43,53.43]],"batl":[[0,1.48,46.29],[1,1.51,449.31],[2,1.52,1433.58]],"ltp":1.48,"tv":13202.16,"id":9342449}],"tv":20376.69}]}
{"op":"mcm","clk":"4230471250","pt":1631533388636,"mc":[{"id":"1.187557995","rc":[{"trd":[[1.48,1092.58]],"batb":[[0,1.48,12.04],[1,1.47,361.31],[2,1.46,215.24]],"batl":[[0,1.51,395.31],[1,1.52,1433.58],[2,1.53,1221.22]],"ltp":1.48,"tv":13294.74,"id":9342449}],"tv":20469.27}]}
{"op":"mcm","clk":"4230471293","pt":1631533389256,"mc":[{"id":"1.187557995","rc":[{"batl":[[0,1.51,393.68]],"ltp":1.48,"tv":13294.74,"id":9342449}]}]}
{"op":"mcm","clk":"4230471466","pt":1631533391450,"mc":[{"id":"1.187557995","rc":[{"trd":[[1.48,1116.66]],"batb":[[0,1.47,458.88],[1,1.46,215.24],[2,1.43,53.43]],"batl":[[0,1.48,245.96],[1,1.49,151.8],[2,1.51,393.68]],"ltp":1.48,"tv":13318.82,"id":9342449},{"batb":[[1,2.84,4.47],[2,2.74,4.79]],"ltp":2.96,"tv":7174.53,"id":9633869}],"tv":20493.35}]}
{"op":"mcm","clk":"4230471492","pt":1631533391761,"mc":[{"id":"1.187557995","rc":[{"batl":[[2,1.5,150.28]],"ltp":1.48,"tv":13318.82,"id":9342449}]}]}
{"op":"mcm","clk":"4230471765","pt":1631533394576,"mc":[{"id":"1.187557995","rc":[{"batb":[[2,2.8,5.03]],"ltp":2.96,"tv":7174.53,"id":9633869}]}]}
{"op":"mcm","clk":"4230471879","pt":1631533395671,"mc":[{"id":"1.187557995","rc":[{"batb":[[0,1.42,66.94],[1,1.41,211.96],[2,1.4,62.46]],"batl":[[1,1.54,46.25],[2,1.55,39.1]],"ltp":1.48,"tv":13318.82,"id":9342449},{"batb":[[0,2.84,4.47],[1,2.8,5.03],[2,2.74,4.79]],"batl":[[0,3.4,3.39],[1,3.5,3.03],[2,3.6,3.26]],"ltp":2.96,"tv":7174.53,"id":9633869}]}]}
{"op":"mcm","clk":"4230471967","pt":1631533396474,"mc":[{"id":"1.187557995","rc":[{"batb":[[0,1.41,211.96],[1,1.4,62.46],[2,1.39,68.91]],"batl":[[0,1.57,45.5],[1,1.71,5],[2,1.79,29.5]],"ltp":1.48,"tv":13318.82,"id":9342449},{"batb":[[0,2.74,4.79],[1,2.58,58.49],[2,2.4,3]],"batl":[[0,3.5,3.03],[1,3.6,3.26],[2,3.65,2.9]],"ltp":2.96,"tv":7174.53,"id":9633869}]}]}
{"op":"mcm","clk":"4230472184","pt":1631533398454,"mc":[{"id":"1.187557995","rc":[{"batb":[[1,1.4,328.82],[2,1.39,330]],"batl":[[1,1.61,263.7],[2,1.62,138.04]],"ltp":1.48,"tv":13318.82,"id":9342449}]}]}
{"op":"mcm","clk":"4230472289","pt":1631533399652,"mc":[{"id":"1.187557995","rc":[{"batb":[[0,1.42,8],[1,1.41,218.96],[2,1.4,334.82]],"batl":[[0,1.57,51.5]],"ltp":1.48,"tv":13318.82,"id":9342449},{"batb":[[0,2.74,7.79],[1,2.72,3],[2,2.58,58.49]],"batl":[[0,3.4,3],[1,3.45,3],[2,3.5,3.03]],"ltp":2.96,"tv":7174.53,"id":9633869}]}]}
{"op":"mcm","clk":"4230472567","pt":1631533402264,"mc":[{"id":"1.187557995","rc":[{"batl":[[0,1.47,13.02],[1,1.57,51.5],[2,1.61,263.7]],"ltp":1.48,"tv":13318.82,"id":9342449}]}]}
{"op":"mcm","clk":"4230472708","pt":1631533403671,"mc":[{"id":"1.187557995","rc":[{"batl":[[1,1.57,6],[2,1.71,5]],"ltp":1.48,"tv":13318.82,"id":9342449}]}]}
{"op":"mcm","clk":"4230472913","pt":1631533405552,"mc":[{"id":"1.187557995","rc":[{"batb":[[0,1.41,211.96],[1,1.4,334.82],[2,1.39,330]],"ltp":1.48,"tv":13318.82,"id":9342449},{"batl":[[0,3.5,3.03],[1,3.6,3.26],[2,3.65,2.9]],"ltp":2.96,"tv":7174.53,"id":9633869}]}]}
{"op":"mcm","clk":"4230473003","pt":1631533406465,"mc":[{"id":"1.187557995","rc":[{"batl":[[0,1.44,340.26],[1,1.45,1530.75],[2,1.46,1280.16]],"ltp":1.48,"tv":13318.82,"id":9342449}]}]}
{"op":"mcm","clk":"4230473109","pt":1631533407496,"mc":[{"id":"1.187557995","rc":[{"trd":[[1.44,13.88]],"batl":[[0,1.44,326.38],[2,1.46,1334.1]],"ltp":1.44,"tv":13332.7,"id":9342449},{"trd":[[3.25,6.15]],"batb":[[0,3.15,88.7],[1,2.96,102.93],[2,2.8,604.88]],"ltp":3.25,"tv":7180.68,"id":9633869}],"tv":20513.38}]}
{"op":"mcm","clk":"4230473209","pt":1631533408551,"mc":[{"id":"1.187557995","rc":[{"batl":[[0,3.5,18.18]],"ltp":3.25,"tv":7180.68,"id":9633869}]}]}
{"op":"mcm","clk":"4230473258","pt":1631533409071,"mc":[{"id":"1.187557995","rc":[{"batl":[[1,1.45,1701.11]],"ltp":1.44,"tv":13332.7,"id":9342449},{"batl":[[0,3.5,3.03]],"ltp":3.25,"tv":7180.68,"id":9633869}]}]}
{"op":"mcm","clk":"4230473398","pt":1631533410585,"mc":[{"id":"1.187557995","rc":[{"batb":[[0,3.2,38.95],[1,3.15,88.7],[2,2.96,102.93]],"ltp":3.25,"tv":7180.68,"id":9633869}]}]}
{"op":"mcm","clk":"4230473511","pt":1631533411706,"mc":[{"id":"1.187557995","rc":[{"batl":[[0,1.44,483.44]],"ltp":1.44,"tv":13332.7,"id":9342449}]}]}
{"op":"mcm","clk":"4230473703","pt":1631533413683,"mc":[{"id":"1.187557995","rc":[{"batb":[[0,1.42,23.1],[1,1.41,211.96],[2,1.4,334.82]],"batl":[[0,1.43,517.48],[1,1.44,483.44],[2,1.45,1587.65]],"ltp":1.44,"tv":13332.7,"id":9342449},{"batb":[[0,3.2,20.52],[2,3.1,3.74]],"ltp":3.25,"tv":7180.68,"id":9633869}]}]}
{"op":"mcm","clk":"4230473877","pt":1631533415664,"mc":[{"id":"1.187557995","rc":[{"batb":[[1,3.15,92.73]],"ltp":3.25,"tv":7180.68,"id":9633869}]}]}
{"op":"mcm","clk":"4230473907","pt":1631533416082,"mc":[{"id":"1.187557995","rc":[{"batl":[[1,1.44,533.44]],"ltp":1.44,"tv":13332.7,"id":9342449}]}]}
{"op":"mcm","clk":"4230474018","pt":1631533417479,"mc":[{"id":"1.187557995","rc":[{"batl":[[0,1.43,683.91]],"ltp":1.44,"tv":13332.7,"id":9342449}]}]}
{"op":"mcm","clk":"4230474115","pt":1631533418572,"mc":[{"id":"1.187557995","rc":[{"trd":[[1.42,43.95]],"batb":[[0,1.42,1.12]],"batl":[[0,1.43,166.43]],"ltp":1.42,"tv":13376.65,"id":9342449}],"tv":20557.33}]}
{"op":"mcm","clk":"4230474159","pt":1631533419088,"mc":[{"id":"1.187557995","rc":[{"batl":[[1,1.44,483.44]],"ltp":1.42,"tv":13376.65,"id":9342449}]}]}
{"op":"mcm","clk":"4230474283","pt":1631533420490,"mc":[{"id":"1.187557995","rc":[{"trd":[[1.42,46.2]],"batb":[[0,1.41,211.96],[1,1.4,334.82],[2,1.39,330]],"batl":[[0,1.43,166.73]],"ltp":1.42,"tv":13378.89,"id":9342449}],"tv":20559.57}]}
{"op":"mcm","clk":"4230474509","pt":1631533422686,"mc":[{"id":"1.187557995","rc":[{"batl":[[0,1.42,521.43],[1,1.43,347.43],[2,1.44,483.44]],"ltp":1.42,"tv":13378.89,"id":9342449}]}]}
{"op":"mcm","clk":"4230474591","pt":1631533423617,"mc":[{"id":"1.187557995","rc":[{"trd":[[1.42,50.19]],"batl":[[0,1.42,519.43]],"ltp":1.42,"tv":13382.89,"id":9342449}],"tv":20563.57}]}
{"op":"mcm","clk":"4230474783","pt":1631533425597,"mc":[{"id":"1.187557995","rc":[{"batl":[[1,3.55,17.47],[2,3.6,3.26]],"ltp":3.25,"tv":7180.68,"id":9633869}]}]}
{"op":"mcm","clk":"4230474842","pt":1631533426323,"mc":[{"id":"1.187557995","rc":[{"batl":[[0,1.42,153.35],[2,1.44,539.77]],"ltp":1.42,"tv":13382.89,"id":9342449},{"batb":[[0,3.25,3.73],[1,3.2,20.52],[2,3.15,92.73]],"batl":[[1,3.6,3.26],[2,3.65,2.9]],"ltp":3.25,"tv":7180.68,"id":9633869}]}]}
{"op":"mcm","clk":"4230475111","pt":1631533429191,"mc":[{"id":"1.187557995","rc":[{"batl":[[0,1.43,347.43],[1,1.44,539.77],[2,1.45,1587.65]],"ltp":1.42,"tv":13382.89,"id":9342449},{"batl":[[0,3.5,20.5]],"ltp":3.25,"tv":7180.68,"id":9633869}]}]}
{"op":"mcm","clk":"4230475182","pt":1631533430126,"mc":[{"id":"1.187557995","rc":[{"trd":[[1.41,423.93]],"batb":[[0,1.4,334.82],[1,1.39,330],[2,1.38,828.69]],"batl":[[0,1.41,311.45],[1,1.43,347.43],[2,1.44,539.77]],"ltp":1.41,"tv":13806.82,"id":9342449}],"tv":20987.5}]}
{"op":"mcm","clk":"4230475479","pt":1631533433311,"mc":[{"id":"1.187557995","rc":[{"batb":[[0,1.4,378.49]],"batl":[[1,1.42,145.65],[2,1.43,347.43]],"ltp":1.41,"tv":13806.82,"id":9342449}]}]}
{"op":"mcm","clk":"4230476145","pt":1631533440608,"mc":[{"id":"1.187557995","rc":[{"trd":[[1.41,424.53]],"batl":[[0,1.41,311.15]],"ltp":1.41,"tv":13807.42,"id":9342449}],"tv":20988.1}]}
{"op":"mcm","clk":"4230476292","pt":1631533442443,"mc":[{"id":"1.187557995","rc":[{"batb":[[0,1.36,323.22],[1,1.34,542.57],[2,1.33,73.53]],"batl":[[1,1.43,181],[2,1.44,56.33]],"ltp":1.41,"tv":13807.42,"id":9342449},{"batb":[[1,3.2,3.42],[2,3.15,4.03]],"batl":[[0,3.8,3.32],[1,3.95,3.1],[2,4.1,2.55]],"ltp":3.25,"tv":7180.68,"id":9633869}]}]}
{"op":"mcm","clk":"4230476390","pt":1631533443640,"mc":[{"id":"1.187557995","rc":[{"batl":[[0,1.44,56.33],[1,1.45,56.9],[2,1.46,56.25]],"ltp":1.41,"tv":13807.42,"id":9342449}]}]}
{"op":"mcm","clk":"4230476413","pt":1631533443849,"mc":[{"id":"1.187557995","rc":[{"batl":[[0,1.46,56.25],[1,1.57,6],[2,1.95,415.52]],"ltp":1.41,"tv":13807.42,"id":9342449},{"batb":[[0,3.15,4.03],[1,2.96,102.93],[2,2.74,3]],"ltp":3.25,"tv":7180.68,"id":9633869}]}]}
{"op":"mcm","clk":"4230476591","pt":1631533445624,"mc":[{"id":"1.187557995","rc":[{"batb":[[0,1.36,80.93],[1,1.35,705.21],[2,1.34,856.54]],"batl":[[1,1.48,170.36],[2,1.49,323.87]],"ltp":1.41,"tv":13807.42,"id":9342449},{"batb":[[1,3.05,98.99]],"batl":[[0,3.8,5.32]],"ltp":3.25,"tv":7180.68,"id":9633869}]}]}
{"op":"mcm","clk":"4230476655","pt":1631533446347,"mc":[{"id":"1.187557995","rc":[{"batb":[[0,1.36,8]],"ltp":1.41,"tv":13807.42,"id":9342449},{"batl":[[0,3.8,2]],"ltp":3.25,"tv":7180.68,"id":9633869}]}]}
{"op":"mcm","clk":"4230476736","pt":1631533447238,"mc":[{"id":"1.187557995","rc":[{"batl":[[0,1.46,62.25]],"ltp":1.41,"tv":13807.42,"id":9342449},{"batb":[[0,3.15,7.03],[1,3.1,3],[2,3.05,98.99]],"ltp":3.25,"tv":7180.68,"id":9633869}]}]}
{"op":"mcm","clk":"4230476971","pt":1631533449525,"mc":[{"id":"1.187557995","rc":[{"batb":[[0,1.36,73.93]],"ltp":1.41,"tv":13807.42,"id":9342449},{"batl":[[0,3.8,4.67]],"ltp":3.25,"tv":7180.68,"id":9633869}]}]}
{"op":"mcm","clk":"4230477050","pt":1631533450461,"mc":[{"id":"1.187557995","rc":[{"batb":[[0,1.36,8]],"batl":[[0,1.44,61.08],[1,1.46,62.25],[2,1.48,170.36]],"ltp":1.41,"tv":13807.42,"id":9342449},{"batb":[[0,3.25,3.69],[1,3.15,7.03],[2,3.1,3]],"batl":[[0,3.8,2]],"ltp":3.25,"tv":7180.68,"id":9633869}]}]}
{"op":"mcm","clk":"4230477080","pt":1631533450727,"mc":[{"id":"1.187557995","rc":[{"batl":[[0,1.46,62.25],[1,1.48,170.36],[2,1.49,323.87]],"ltp":1.41,"tv":13807.42,"id":9342449},{"batb":[[0,3.15,7.03],[1,3.1,3],[2,3.05,98.99]],"ltp":3.25,"tv":7180.68,"id":9633869}]}]}
{"op":"mcm","clk":"4230477614","pt":1631533456349,"mc":[{"id":"1.187557995","rc":[{"batl":[[0,1.46,6],[2,1.57,6]],"ltp":1.41,"tv":13807.42,"id":9342449}]}]}
{"op":"mcm","clk":"4230477731","pt":1631533457454,"mc":[{"id":"1.187557995","rc":[{"batb":[[1,1.35,697.21]],"batl":[[0,1.44,64.33],[1,1.46,6],[2,1.48,170.36]],"ltp":1.41,"tv":13807.42,"id":9342449},{"batb":[[0,3.25,4.25],[1,3.15,7.03],[2,3.1,3]],"ltp":3.25,"tv":7180.68,"id":9633869}]}]}
{"op":"mcm","clk":"4230477813","pt":1631533458243,"mc":[{"id":"1.187557995","rc":[{"batb":[[0,1.35,697.21],[1,1.34,384.69],[2,1.33,243.89]],"batl":[[0,1.46,6],[1,1.48,170.36],[2,2.08,1]],"ltp":1.41,"tv":13807.42,"id":9342449},{"batb":[[0,3.15,7.03],[1,3.05,98.99],[2,2,11.88]],"ltp":3.25,"tv":7180.68,"id":9633869}]}]}
{"op":"mcm","clk":"4230477947","pt":1631533459646,"mc":[{"id":"1.187557995","rc":[{"batb":[[2,1.33,1034.77]],"batl":[[0,1.39,1705.78],[1,1.4,1582.27],[2,1.41,1335.42]],"ltp":1.41,"tv":13807.42,"id":9342449}]}]}
{"op":"mcm","clk":"4230478040","pt":1631533460587,"mc":[{"id":"1.187557995","rc":[{"batb":[[0,1.36,37.32],[1,1.35,704.21],[2,1.34,384.69]],"batl":[[2,1.41,1350.42]],"ltp":1.41,"tv":13807.42,"id":9342449},{"trd":[[3.6,11.6]],"batb":[[0,3.6,62.57],[1,3.4,6.25],[2,3.3,82.34]],"batl":[[2,4,8.66]],"ltp":3.6,"tv":7192.28,"id":9633869}],"tv":20999.7}]}
{"op":"mcm","clk":"4230478161","pt":1631533461575,"mc":[{"id":"1.187557995","rc":[{"batb":[[2,3.3,85.34]],"ltp":3.6,"tv":7192.28,"id":9633869}]}]}
{"op":"mcm","clk":"4230478373","pt":1631533463671,"mc":[{"id":"1.187557995","rc":[{"batl":[[0,1.38,149.09],[1,1.39,1705.78],[2,1.4,1582.27]],"ltp":1.41,"tv":13807.42,"id":9342449}]}]}
{"op":"mcm","clk":"4230478421","pt":1631533464191,"mc":[{"id":"1.187557995","rc":[{"trd":[[3.6,38.7]],"batb":[[0,3.6,49.02]],"ltp":3.6,"tv":7219.38,"id":9633869}],"tv":21026.8}]}
{"op":"mcm","clk":"4230478554","pt":1631533465491,"mc":[{"id":"1.187557995","rc":[{"batl":[[1,1.39,1766.78]],"ltp":1.41,"tv":13807.42,"id":9342449},{"batb":[[1,3.3,85.34],[2,3.25,2]],"ltp":3.6,"tv":7219.38,"id":9633869}]}]}
{"op":"mcm","clk":"4230478619","pt":1631533466066,"mc":[{"id":"1.187557995","rc":[{"batl":[[0,1.38,467]],"ltp":1.41,"tv":13807.42,"id":9342449},{"batb":[[1,3.4,3.36],[2,3.3,151.57]],"ltp":3.6,"tv":7219.38,"id":9633869}]}]}
{"op":"mcm","clk":"4230478719","pt":1631533467105,"mc":[{"id":"1.187557995","rc":[{"batl":[[2,1.4,1636.86]],"ltp":1.41,"tv":13807.42,"id":9342449},{"batb":[[1,3.5,4.08],[2,3.4,3.36]],"ltp":3.6,"tv":7219.38,"id":9633869}]}]}
{"op":"mcm","clk":"4230478850","pt":1631533468508,"mc":[{"id":"1.187557995","rc":[{"batb":[[0,1.36,101.18]],"batl":[[1,1.39,1705.78]],"ltp":1.41,"tv":13807.42,"id":9342449},{"batb":[[2,3.45,6.12]],"ltp":3.6,"tv":7219.38,"id":9633869}]}]}
{"op":"mcm","clk":"4230479002","pt":1631533470280,"mc":[{"id":"1.187557995","rc":[{"batl":[[0,3.8,12]],"ltp":3.6,"tv":7219.38,"id":9633869}]}]}
{"op":"mcm","clk":"4230479113","pt":1631533471480,"mc":[{"id":"1.187557995","rc":[{"batl":[[0,1.37,365],[1,1.38,467],[2,1.39,1705.78]],"ltp":1.41,"tv":13807.42,"id":9342449}]}]}
{"op":"mcm","clk":"4230479206","pt":1631533472377,"mc":[{"id":"1.187557995","rc":[{"batb":[[0,1.33,26.11],[1,1.32,278.05],[2,1.31,181.64]],"batl":[[1,1.38,317.91],[2,1.4,54.59]],"ltp":1.41,"tv":13807.42,"id":9342449},{"batb":[[0,3.5,4.08],[1,3.45,6.12],[2,3.4,3.36]],"batl":[[0,4,8.66],[1,4.1,48.15],[2,4.2,75.14]],"ltp":3.6,"tv":7219.38,"id":9633869}]}]}
{"op":"mcm","clk":"4230479306","pt":1631533473524,"mc":[{"id":"1.187557995","rc":[{"batb":[[0,1.32,278.05],[1,1.31,181.64],[2,1.3,594.33]],"batl":[[0,1.38,317.91],[1,1.4,54.59],[2,1.41,56.5]],"ltp":1.41,"tv":13807.42,"id":9342449},{"batb":[[1,3.4,3.36],[2,3.35,3.67]],"batl":[[0,4.1,48.15],[1,4.2,75.14],[2,4.3,76.81]],"ltp":3.6,"tv":7219.38,"id":9633869}]}]}
{"op":"mcm","clk":"4230479475","pt":1631533475573,"mc":[{"id":"1.187557995","rc":[{"batb":[[0,1.33,9],[1,1.32,285.05],[2,1.31,583.76]],"ltp":1.41,"tv":13807.42,"id":9342449},{"batl":[[0,4,2],[1,4.1,48.15],[2,4.2,75.14]],"ltp":3.6,"tv":7219.38,"id":9633869}]}]}
{"op":"mcm","clk":"4230479584","pt":1631533476968,"mc":[{"id":"1.187557995","rc":[{"batb":[[2,1.31,591.76]],"ltp":1.41,"tv":13807.42,"id":9342449},{"batl":[[1,4.1,51.15]],"ltp":3.6,"tv":7219.38,"id":9633869}]}]}
{"op":"mcm","clk":"4230479734","pt":1631533478679,"mc":[{"id":"1.187557995","rc":[{"batb":[[1,1.32,78.64],[2,1.31,8]],"ltp":1.41,"tv":13807.42,"id":9342449},{"batl":[[1,4.1,3],[2,4.2,2.83]],"ltp":3.6,"tv":7219.38,"id":9633869}]}]}
{"op":"mcm","clk":"4230479829","pt":1631533479709,"mc":[{"id":"1.187557995","rc":[{"trd":[[1.38,635.82],[1.4,119.38]],"batb":[[1,1.32,7]],"batl":[[0,1.42,60.75],[1,1.43,385.4],[2,1.44,393.18]],"ltp":1.4,"tv":14562.62,"id":9342449},{"trd":[[3.5,4.08]],"batb":[[0,3.35,3.67],[1,3.3,66.22],[2,3.25,175.11]],"batl":[[2,4.5,2.43]],"ltp":3.5,"tv":7223.46,"id":9633869}],"tv":21786.08}]}
{"op":"mcm","clk":"4230480010","pt":1631533481689,"mc":[{"id":"1.187557995","rc":[{"trd":[[1.42,56.04]],"batb":[[0,1.4,237.37],[1,1.39,274.65],[2,1.38,2078.81]],"batl":[[0,1.42,54.9]],"ltp":1.42,"tv":14568.47,"id":9342449},{"trd":[[3.35,9.82]],"batb":[[0,3.3,66.22],[1,3.25,175.11],[2,3.2,104.35]],"batl":[[0,3.6,2.01],[1,4,2],[2,4.1,3]],"ltp":3.35,"tv":7233.28,"id":9633869}],"tv":21801.75}]}
{"op":"mcm","clk":"4230480117","pt":1631533482685,"mc":[{"id":"1.187557995","rc":[{"batb":[[1,1.39,497.49],[2,1.38,1543.92]],"ltp":1.42,"tv":14568.47,"id":9342449}]}]}
{"op":"mcm","clk":"4230480201","pt":1631533483616,"mc":[{"id":"1.187557995","rc":[{"batl":[[1,3.7,9.12],[2,3.95,13]],"ltp":3.35,"tv":7233.28,"id":9633869}]}]}
{"op":"mcm","clk":"4230480317","pt":1631533484704,"mc":[{"id":"1.187557995","rc":[{"batb":[[1,1.39,503.49],[2,1.38,1439.36]],"ltp":1.42,"tv":14568.47,"id":9342449},{"batl":[[0,3.6,5.01],[2,3.95,3]],"ltp":3.35,"tv":7233.28,"id":9633869}]}]}
{"op":"mcm","clk":"4230480340","pt":1631533484912,"mc":[{"id":"1.187557995","rc":[{"batb":[[2,1.38,1392.88]],"batl":[[1,1.43,324.9]],"ltp":1.42,"tv":14568.47,"id":9342449},{"batb":[[0,3.3,62.84]],"batl":[[0,3.55,2],[1,3.6,5.01],[2,3.7,9.12]],"ltp":3.35,"tv":7233.28,"id":9633869}]}]}
{"op":"mcm","clk":"4230480537","pt":1631533486691,"mc":[{"id":"1.187557995","rc":[{"trd":[[1.42,77.98]],"batb":[[0,1.4,281.87]],"batl":[[0,1.42,223.88]],"ltp":1.42,"tv":14590.41,"id":9342449},{"trd":[[3.35,19.12]],"ltp":3.35,"tv":7242.58,"id":9633869}],"tv":21832.99}]}
{"op":"mcm","clk":"4230480611","pt":1631533487429,"mc":[{"id":"1.187557995","rc":[{"batb":[[0,1.4,326.87],[2,1.38,1417.21]],"batl":[[0,1.42,350.88]],"ltp":1.42,"tv":14590.41,"id":9342449},{"batl":[[2,3.95,3]],"ltp":3.35,"tv":7242.58,"id":9633869}]}]}
{"op":"mcm","clk":"4230480748","pt":1631533488627,"mc":[{"id":"1.187557995","rc":[{"batl":[[2,1.44,448.76]],"ltp":1.42,"tv":14590.41,"id":9342449},{"batb":[[1,3.25,178.84]],"batl":[[2,3.75,50.89]],"ltp":3.35,"tv":7242.58,"id":9633869}]}]}
{"op":"mcm","clk":"4230480944","pt":1631533490348,"mc":[{"id":"1.187557995","rc":[{"batl":[[0,3.5,10.05],[1,3.55,2],[2,3.6,5.01]],"ltp":3.35,"tv":7242.58,"id":9633869}]}]}
{"op":"mcm","clk":"4230481287","pt":1631533493643,"mc":[{"id":"1.187557995","rc":[{"batb":[[0,1.38,24.33],[1,1.36,183.85],[2,1.35,188.11]],"batl":[[0,1.42,127],[1,1.44,55.58],[2,1.46,56.25]],"ltp":1.42,"tv":14590.41,"id":9342449},{"batb":[[0,3.25,3.73],[1,3.15,10.8],[2,3.05,75.4]],"batl":[[0,3.65,9.21],[1,3.75,50.89],[2,3.8,59.63]],"ltp":3.35,"tv":7242.58,"id":9633869}]}]}
{"op":"mcm","clk":"4230481369","pt":1631533494471,"mc":[{"id":"1.187557995","rc":[{"batb":[[0,1.36,183.85],[1,1.35,188.11],[2,1.34,626.14]],"batl":[[0,1.4,705.88]],"ltp":1.42,"tv":14590.41,"id":9342449},{"batb":[[1,3.15,3.83]],"batl":[[0,3.75,50.89],[1,3.8,59.63],[2,3.85,81.54]],"ltp":3.35,"tv":7242.58,"id":9633869}]}]}
{"op":"mcm","clk":"4230481569","pt":1631533496443,"mc":[{"id":"1.187557995","rc":[{"batb":[[1,1.35,416.32],[2,1.34,937.4]],"ltp":1.42,"tv":14590.41,"id":9342449}]}]}
{"op":"mcm","clk":"4230481879","pt":1631533499548,"mc":[{"id":"1.187557995","rc":[{"batb":[[0,1.37,500],[1,1.36,183.85],[2,1.35,416.32]],"batl":[[0,1.46,56.25],[1,1.48,173.74],[2,1.49,403.01]],"ltp":1.42,"tv":14590.41,"id":9342449},{"batb":[[0,3.15,3.83],[1,3.05,75.4],[2,3,176.62]],"ltp":3.35,"tv":7242.58,"id":9633869}]}]}
{"op":"mcm","clk":"4230482013","pt":1631533501065,"mc":[{"id":"1.187557995","rc":[{"batb":[[2,1.35,188.11]],"batl":[[2,1.49,172.78]],"ltp":1.42,"tv":14590.41,"id":9342449}]}]}
{"op":"mcm","clk":"4230482159","pt":1631533502488,"mc":[{"id":"1.187557995","rc":[{"batl":[[0,1.44,7],[1,1.46,56.25],[2,1.48,173.74]],"ltp":1.42,"tv":14590.41,"id":9342449},{"batb":[[0,3.25,3],[1,3.2,3],[2,3.15,3.83]],"ltp":3.35,"tv":7242.58,"id":9633869}]}]}
{"op":"mcm","clk":"4230482238","pt":1631533503069,"mc":[{"id":"1.187557995","rc":[{"batl":[[1,1.45,7],[2,1.46,62.25]],"ltp":1.42,"tv":14590.41,"id":9342449},{"batb":[[2,3.15,5.83]],"ltp":3.35,"tv":7242.58,"id":9633869}]}]}
{"op":"mcm","clk":"4230482393","pt":1631533504484,"mc":[{"id":"1.187557995","rc":[{"batb":[[0,1.39,227.41],[1,1.38,269.63],[2,1.37,500]],"batl":[[0,1.42,178.32],[1,1.43,226.16],[2,1.44,7]],"ltp":1.42,"tv":14590.41,"id":9342449}]}]}
{"op":"mcm","clk":"4230482560","pt":1631533506268,"mc":[{"id":"1.187557995","rc":[{"batl":[[2,1.44,110.48]],"ltp":1.42,"tv":14590.41,"id":9342449},{"batb":[[0,3.3,15.15],[1,3.25,6.29],[2,3.2,3]],"batl":[[0,3.7,29.17],[1,3.75,50.89],[2,3.8,59.63]],"ltp":3.35,"tv":7242.58,"id":9633869}]}]}
{"op":"mcm","clk":"4230482616","pt":1631533506893,"mc":[{"id":"1.187557995","rc":[{"trd":[[1.42,99.07]],"batl":[[0,1.42,167.78]],"ltp":1.42,"tv":14611.49,"id":9342449}],"tv":21854.07}]}
{"op":"mcm","clk":"4230482808","pt":1631533508671,"mc":[{"id":"1.187557995","rc":[{"batb":[[0,1.37,500],[1,1.36,183.85],[2,1.35,188.11]],"batl":[[0,1.42,57],[1,1.44,67.33],[2,1.45,7]],"ltp":1.42,"tv":14611.49,"id":9342449},{"batb":[[0,3.25,6.29],[1,3.2,3],[2,3.15,5.83]],"batl":[[0,3.75,50.89],[1,3.8,59.63],[2,3.85,81.54]],"ltp":3.35,"tv":7242.58,"id":9633869}]}]}
{"op":"mcm","clk":"4230482893","pt":1631533509561,"mc":[{"id":"1.187557995","rc":[{"trd":[[1.37,739.74]],"batb":[[0,1.37,130.13]],"batl":[[0,1.44,7],[1,1.45,7],[2,1.46,62.25]],"ltp":1.37,"tv":15351.24,"id":9342449},{"batb":[[0,3.25,3]],"ltp":3.35,"tv":7242.58,"id":9633869}],"tv":22593.82}]}
{"op":"mcm","clk":"4230483098","pt":1631533511695,"mc":[{"id":"1.187557995","rc":[{"batb":[[2,1.35,422.47]],"ltp":1.37,"tv":15351.24,"id":9342449}]}]}
{"op":"mcm","clk":"4230483470","pt":1631533516069,"mc":[{"id":"1.187557995","rc":[{"batl":[[1,1.46,56.25],[2,1.48,173.74]],"ltp":1.37,"tv":15351.24,"id":9342449},{"batb":[[1,3.15,3.83],[2,3.05,75.4]],"ltp":3.35,"tv":7242.58,"id":9633869}]}]}
{"op":"mcm","clk":"4230483776","pt":1631533519297,"mc":[{"id":"1.187557995","rc":[{"batb":[[1,3.2,3],[2,3.15,3.83]],"ltp":3.35,"tv":7242.58,"id":9633869}]}]}
{"op":"mcm","clk":"4230483868","pt":1631533520201,"mc":[{"id":"1.187557995","rc":[{"batl":[[2,1.82,475.58]],"ltp":1.37,"tv":15351.24,"id":9342449}]}]}
{"op":"mcm","clk":"4230484009","pt":1631533521719,"mc":[{"id":"1.187557995","rc":[{"batl":[[0,3.8,59.63],[1,3.85,81.54],[2,3.95,2.9]],"ltp":3.35,"tv":7242.58,"id":9633869}]}]}
{"op":"mcm","clk":"4230484214","pt":1631533523709,"mc":[{"id":"1.187557995","rc":[{"batl":[[0,1.38,265.66],[1,1.39,1631.57],[2,1.4,1335.42]],"ltp":1.37,"tv":15351.24,"id":9342449},{"batb":[[0,3.65,65.27],[1,3.3,81.84],[2,3.25,575.1]],"ltp":3.35,"tv":7242.58,"id":9633869}]}]}
{"op":"mcm","clk":"4230484297","pt":1631533524605,"mc":[{"id":"1.187557995","rc":[{"batb":[[2,1.35,428.47]],"batl":[[2,1.4,1350.42]],"ltp":1.37,"tv":15351.24,"id":9342449},{"trd":[[3.65,11.42]],"batb":[[0,3.65,59.56],[1,3.45,6.12],[2,3.3,98.84]],"ltp":3.65,"tv":7254.0,"id":9633869}],"tv":22605.24}]}
{"op":"mcm","clk":"4230484461","pt":1631533526280,"mc":[{"id":"1.187557995","rc":[{"batb":[[0,1.35,428.47],[1,1.34,937.41],[2,1.33,790.88]],"ltp":1.37,"tv":15351.24,"id":9342449},{"batl":[[0,3.85,81.54],[1,3.95,2.9],[2,4.4,2.39]],"ltp":3.65,"tv":7254.0,"id":9633869}]}]}
{"op":"mcm","clk":"4230484561","pt":1631533527492,"mc":[{"id":"1.187557995","rc":[{"batl":[[0,1.38,428.15]],"ltp":1.37,"tv":15351.24,"id":9342449}]}]}
{"op":"mcm","clk":"4230484758","pt":1631533529513,"mc":[{"id":"1.187557995","rc":[{"batb":[[0,1.35,470.37]],"batl":[[0,1.38,521.15]],"ltp":1.37,"tv":15351.24,"id":9342449},{"batb":[[1,3.4,3.26],[2,3.3,102.52]],"batl":[[0,3.85,95.6],[2,4.1,8.51]],"ltp":3.65,"tv":7254.0,"id":9633869}]}]}
{"op":"mcm","clk":"4230484811","pt":1631533530089,"mc":[{"id":"1.187557995","rc":[{"batl":[[2,1.4,1411.36]],"ltp":1.37,"tv":15351.24,"id":9342449},{"batb":[[1,3.5,4.08],[2,3.4,3.26]],"ltp":3.65,"tv":7254.0,"id":9633869}]}]}
{"op":"mcm","clk":"4230485034","pt":1631533532402,"mc":[{"id":"1.187557995","rc":[{"batl":[[0,1.37,181.3],[1,1.38,428.15],[2,1.39,1631.57]],"ltp":1.37,"tv":15351.24,"id":9342449},{"batb":[[1,3.5,10.08]],"ltp":3.65,"tv":7254.0,"id":9633869}]}]}
{"op":"mcm","clk":"4230485337","pt":1631533535388,"mc":[{"id":"1.187557995","rc":[{"batl":[[0,1.37,482.3]],"ltp":1.37,"tv":15351.24,"id":9342449}]}]}
{"op":"mcm","clk":"4230485556","pt":1631533537687,"mc":[{"id":"1.187557995","rc":[{"batb":[[0,1.36,20.45],[1,1.35,470.37],[2,1.34,937.41]],"ltp":1.37,"tv":15351.24,"id":9342449}]}]}
{"op":"mcm","clk":"4230485635","pt":1631533538519,"mc":[{"id":"1.187557995","rc":[{"batb":[[1,1.35,509.63],[2,1.34,930.41]],"ltp":1.37,"tv":15351.24,"id":9342449}]}]}
{"op":"mcm","clk":"4230485731","pt":1631533539616,"mc":[{"id":"1.187557995","rc":[{"trd":[[1.35,1293.46],[1.36,40.9]],"batb":[[0,1.34,930.41],[1,1.33,790.88],[2,1.32,794.13]],"batl":[[0,1.35,254.54],[1,1.37,482.3],[2,1.38,428.15]],"ltp":1.35,"tv":16685.6,"id":9342449},{"trd":[[3.85,96.15]],"batl":[[0,3.95,2.9],[1,4.1,8.51],[2,4.4,2.39]],"ltp":3.85,"tv":7350.14,"id":9633869}],"tv":24035.75}]}
{"op":"mcm","clk":"4230485859","pt":1631533541127,"mc":[{"id":"1.187557995","rc":[{"batb":[[0,1.34,939.41]],"ltp":1.35,"tv":16685.6,"id":9342449}]}]}
{"op":"mcm","clk":"4230486029","pt":1631533542692,"mc":[{"id":"1.187557995","rc":[{"trd":[[1.35,1330.86]],"batl":[[0,1.35,235.84],[1,1.36,190.12],[2,1.37,482.3]],"ltp":1.35,"tv":16723.0,"id":9342449},{"batl":[[0,3.9,2],[1,3.95,2.9],[2,4.1,8.51]],"ltp":3.85,"tv":7350.14,"id":9633869}],"tv":24073.15}]}
{"op":"mcm","clk":"4230486108","pt":1631533543627,"mc":[{"id":"1.187557995","rc":[{"batb":[[0,1.34,1099.94],[1,1.33,1118.44]],"ltp":1.35,"tv":16723.0,"id":9342449},{"batb":[[1,3.6,3.24],[2,3.5,10.08]],"batl":[[0,3.9,16.5]],"ltp":3.85,"tv":7350.14,"id":9633869}]}]}
{"op":"mcm","clk":"4230486216","pt":1631533544620,"mc":[{"id":"1.187557995","rc":[{"batb":[[0,1.34,9],[1,1.32,26.51],[2,1.29,3.45]],"batl":[[1,1.37,301],[2,1.38,70.25]],"ltp":1.35,"tv":16723.0,"id":9342449},{"batb":[[0,3.6,3.24],[1,3.5,10.08],[2,3.4,3.26]],"batl":[[0,3.9,2],[1,4.1,8.51],[2,4.9,2.15]],"ltp":3.85,"tv":7350.14,"id":9633869}]}]}
