{"op":"mcm","clk":"4228706139","pt":1631463243457,"mc":[{"id":"1.187551081","rc":[{"batb":[[2,10,2]],"ltp":10.5,"tv":2011.46,"id":7445998},{"batb":[[2,1.05,1925.22]],"ltp":1.1,"tv":64373.42,"id":9629022}]}]}
{"op":"mcm","clk":"4228706513","pt":1631463245463,"mc":[{"id":"1.187551081","rc":[{"trd":[[12,123.7]],"batb":[[0,12,28.63]],"batl":[[0,13.5,52.09],[2,18,2]],"ltp":12.0,"tv":2031.46,"id":7445998},{"batb":[[2,1.06,431.08]],"ltp":1.1,"tv":64373.42,"id":9629022}],"tv":66404.89}]}
{"op":"mcm","clk":"4228706787","pt":1631463246387,"mc":[{"id":"1.187551081","rc":[{"batb":[[0,12,38.63]],"ltp":12.0,"tv":2031.46,"id":7445998},{"trd":[[1.09,1314.14]],"batl":[[0,1.09,701.17]],"ltp":1.09,"tv":64540.9,"id":9629022}],"tv":66572.36}]}
{"op":"mcm","clk":"4228707001","pt":1631463247566,"mc":[{"id":"1.187551081","rc":[{"trd":[[1.09,2462.59]],"batb":[[1,1.07,1079.24]],"batl":[[0,1.09,126.95]],"ltp":1.09,"tv":65689.35,"id":9629022}],"tv":67720.82}]}
{"op":"mcm","clk":"4228707220","pt":1631463248664,"mc":[{"id":"1.187551081","rc":[{"trd":[[12,142.48]],"batb":[[0,8,39.94],[1,7.6,3],[2,7.4,2]],"batl":[[0,20,2],[1,26,2],[2,990,0.01]],"ltp":12.0,"tv":2050.24,"id":7445998},{"batb":[[0,1.05,2470.11],[1,1.04,577.12],[2,1.03,843.51]],"batl":[[0,1.23,29.64],[1,1.25,14.81],[2,1.39,17.79]],"ltp":1.09,"tv":65689.35,"id":9629022}],"tv":67739.6}]}
{"op":"mcm","clk":"4228707549","pt":1631463250493,"mc":[{"id":"1.187551081","rc":[{"batb":[[0,1.08,116.48],[1,1.05,2470.11],[2,1.04,577.12]],"batl":[[0,1.1,190.45],[1,1.23,29.64],[2,1.25,14.81]],"ltp":1.09,"tv":65689.35,"id":9629022}]}]}
{"op":"mcm","clk":"4228707744","pt":1631463251496,"mc":[{"id":"1.187551081","rc":[{"batb":[[2,1.01,30]],"batl":[[0,16,10],[1,18,2],[2,20,2]],"ltp":12.0,"tv":2050.24,"id":7445998},{"batb":[[1,1.07,204.52],[2,1.06,41]],"batl":[[1,1.11,60],[2,1.15,16]],"ltp":1.09,"tv":65689.35,"id":9629022}]}]}
{"op":"mcm","clk":"4228707925","pt":1631463252575,"mc":[{"id":"1.187551081","rc":[{"batb":[[0,10,25],[1,8,39.94],[2,7.6,3]],"batl":[[0,14,131.36],[1,16,10],[2,18,4]],"ltp":12.0,"tv":2050.24,"id":7445998},{"batb":[[1,1.06,453.58],[2,1.05,2509.11]],"batl":[[1,1.15,16],[2,1.23,29.64]],"ltp":1.09,"tv":65689.35,"id":9629022}]}]}
{"op":"mcm","clk":"4228708045","pt":1631463253174,"mc":[{"id":"1.187551081","rc":[{"batb":[[0,8,39.94],[1,7.6,3],[2,1.01,30]],"batl":[[0,18,4],[1,20,2],[2,26,2]],"ltp":12.0,"tv":2050.24,"id":7445998},{"batb":[[0,1.09,331.25],[1,1.08,914.43],[2,1.06,453.58]],"batl":[[0,1.1,442.24],[1,1.11,776.74],[2,1.15,16]],"ltp":1.09,"tv":65689.35,"id":9629022}]}]}
{"op":"mcm","clk":"4228708347","pt":1631463254914,"mc":[{"id":"1.187551081","rc":[{"batb":[[1,1.08,1118.95]],"batl":[[0,1.1,505.22]],"ltp":1.09,"tv":65689.35,"id":9629022}]}]}
{"op":"mcm","clk":"4228708659","pt":1631463256661,"mc":[{"id":"1.187551081","rc":[{"batl":[[0,14.5,16.46],[1,18,4],[2,20,2]],"ltp":12.0,"tv":2050.24,"id":7445998},{"trd":[[1.1,2593.82]],"batb":[[0,1.06,453.58],[1,1.05,2509.11],[2,1.04,629.12]],"batl":[[0,1.15,16],[1,1.23,29.64],[2,1.25,14.81]],"ltp":1.1,"tv":65693.69,"id":9629022}],"tv":67743.94}]}
{"op":"mcm","clk":"4228709157","pt":1631463259578,"mc":[{"id":"1.187551081","rc":[{"batb":[[0,11,6.3],[1,8,39.94],[2,7.6,3]],"ltp":12.0,"tv":2050.24,"id":7445998},{"batb":[[0,1.06,1359.84],[1,1.05,2878.64]],"batl":[[0,1.13,331.98],[1,1.14,759.12],[2,1.15,16]],"ltp":1.1,"tv":65693.69,"id":9629022}]}]}
{"op":"mcm","clk":"4228709218","pt":1631463260008,"mc":[{"id":"1.187551081","rc":[{"batb":[[0,8,39.94],[1,7.6,3],[2,1.01,30]],"ltp":12.0,"tv":2050.24,"id":7445998}]}]}
{"op":"mcm","clk":"4228709359","pt":1631463260879,"mc":[{"id":"1.187551081","rc":[{"batb":[[0,1.09,120],[1,1.06,1359.84],[2,1.05,2878.64]],"ltp":1.1,"tv":65693.69,"id":9629022}]}]}
{"op":"mcm","clk":"4228709820","pt":1631463263518,"mc":[{"id":"1.187551081","rc":[{"batl":[[2,26,2]],"ltp":12.0,"tv":2050.24,"id":7445998},{"batb":[[1,1.08,154.57],[2,1.06,1359.84]],"ltp":1.1,"tv":65693.69,"id":9629022}]}]}
{"op":"mcm","clk":"4228709970","pt":1631463264339,"mc":[{"id":"1.187551081","rc":[{"batl":[[0,1.15,16],[1,1.23,29.64],[2,1.25,14.81]],"ltp":1.1,"tv":65693.69,"id":9629022}]}]}
{"op":"mcm","clk":"4228710200","pt":1631463265481,"mc":[{"id":"1.187551081","rc":[{"trd":[[14.5,19.22]],"batl":[[0,18,4],[1,26,2],[2,990,0.01]],"ltp":14.5,"tv":2066.7,"id":7445998},{"trd":[[1.07,2124.22],[1.08,445.66],[1.09,2702.59]],"batb":[[0,1.06,1359.84],[1,1.05,2839.64],[2,1.04,577.12]],"batl":[[0,1.07,6398.15],[1,1.15,16],[2,1.23,29.64]],"ltp":1.07,"tv":66465.89,"id":9629022}],"tv":68532.6}]}
{"op":"mcm","clk":"4228710242","pt":1631463265701,"mc":[{"id":"1.187551081","rc":[{"batl":[[0,18,2]],"ltp":14.5,"tv":2066.7,"id":7445998},{"batb":[[0,1.06,1318.84]],"batl":[[0,1.15,16],[1,1.23,29.64],[2,1.25,14.81]],"ltp":1.07,"tv":66465.89,"id":9629022}]}]}
{"op":"mcm","clk":"4228710595","pt":1631463267614,"mc":[{"id":"1.187551081","rc":[{"batb":[[0,9.4,26.6],[1,8,39.94],[2,7.6,3]],"ltp":14.5,"tv":2066.7,"id":7445998},{"batl":[[0,1.07,488.62],[1,1.08,764.65],[2,1.1,14.5]],"ltp":1.07,"tv":66465.89,"id":9629022}]}]}
{"op":"mcm","clk":"4228710752","pt":1631463268421,"mc":[{"id":"1.187551081","rc":[{"batb":[[0,13.5,30.23],[1,8.4,35.67]],"ltp":14.5,"tv":2066.7,"id":7445998},{"trd":[[1.07,2134.22]],"batl":[[0,1.07,483.62]],"ltp":1.07,"tv":66475.89,"id":9629022}],"tv":68542.6}]}
{"op":"mcm","clk":"4228710844","pt":1631463268895,"mc":[{"id":"1.187551081","rc":[{"batb":[[1,12.5,2],[2,12,2]],"ltp":14.5,"tv":2066.7,"id":7445998}]}]}
{"op":"mcm","clk":"4228711175","pt":1631463270482,"mc":[{"id":"1.187551081","rc":[{"batb":[[0,15.5,2],[1,15,2],[2,13.5,30.23]],"batl":[[0,18,37.77],[1,21,34.93],[2,26,2]],"ltp":14.5,"tv":2066.7,"id":7445998},{"batb":[[0,1.06,1907.43],[1,1.05,3538.25]],"ltp":1.07,"tv":66475.89,"id":9629022}]}]}
{"op":"mcm","clk":"4228711392","pt":1631463271514,"mc":[{"id":"1.187551081","rc":[{"batb":[[2,14,26.6]],"ltp":14.5,"tv":2066.7,"id":7445998},{"batb":[[0,1.06,2410.35]],"batl":[[0,1.07,590.78]],"ltp":1.07,"tv":66475.89,"id":9629022}]}]}
{"op":"mcm","clk":"4228711530","pt":1631463272212,"mc":[{"id":"1.187551081","rc":[{"batb":[[2,13.5,30.23]],"ltp":14.5,"tv":2066.7,"id":7445998}]}]}
{"op":"mcm","clk":"4228711798","pt":1631463273645,"mc":[{"id":"1.187551081","rc":[{"batb":[[0,16,2],[1,15.5,2],[2,15,2]],"ltp":14.5,"tv":2066.7,"id":7445998},{"batl":[[1,1.08,1258.29],[2,1.09,598.68]],"ltp":1.07,"tv":66475.89,"id":9629022}]}]}
{"op":"mcm","clk":"4228711850","pt":1631463273820,"mc":[{"id":"1.187551081","rc":[{"trd":[[1.07,2148.22]],"batl":[[0,1.07,583.78]],"ltp":1.07,"tv":66489.89,"id":9629022}],"tv":68556.6}]}
{"op":"mcm","clk":"4228712102","pt":1631463275238,"mc":[{"id":"1.187551081","rc":[{"batb":[[0,16,5.66]],"ltp":14.5,"tv":2066.7,"id":7445998}]}]}
{"op":"mcm","clk":"4228712912","pt":1631463279554,"mc":[{"id":"1.187551081","rc":[{"trd":[[16,8]],"batb":[[0,16,1.66]],"ltp":16.0,"tv":2074.7,"id":7445998}],"tv":68564.6}]}
{"op":"mcm","clk":"4228713141","pt":1631463280911,"mc":[{"id":"1.187551081","rc":[{"trd":[[1.07,2158.46]],"batl":[[0,1.07,578.66]],"ltp":1.07,"tv":66500.14,"id":9629022}],"tv":68574.85}]}
{"op":"mcm","clk":"4228713382","pt":1631463282246,"mc":[{"id":"1.187551081","rc":[{"trd":[[15.5,4],[16,11.32]],"batb":[[0,13.5,69.72],[1,12,54.38],[2,8.4,35.67]],"batl":[[0,18,38.11]],"ltp":15.5,"tv":2082.02,"id":7445998}],"tv":68582.17}]}
{"op":"mcm","clk":"4228713573","pt":1631463283363,"mc":[{"id":"1.187551081","rc":[{"batl":[[0,18,37.77]],"ltp":15.5,"tv":2082.02,"id":7445998}]}]}
{"op":"mcm","clk":"4228713954","pt":1631463285530,"mc":[{"id":"1.187551081","rc":[{"batb":[[0,15,2],[1,14,2],[2,13.5,2]],"batl":[[0,30,47.29],[1,36,2],[2,110,2]],"ltp":15.5,"tv":2082.02,"id":7445998},{"batb":[[0,1.03,1580.34],[1,1.02,5975.27],[2,1.01,3871.84]],"batl":[[0,1.19,14.82],[1,1.21,11.86],[2,1.23,29.64]],"ltp":1.07,"tv":66500.14,"id":9629022}]}]}
{"op":"mcm","clk":"4228714149","pt":1631463286599,"mc":[{"id":"1.187551081","rc":[{"batb":[[0,8.4,35.67],[1,3.85,374.05],[2,1.01,30]],"ltp":15.5,"tv":2082.02,"id":7445998}]}]}
{"op":"mcm","clk":"4228714189","pt":1631463286929,"mc":[{"id":"1.187551081","rc":[{"batb":[[1,1.01,30],[2,1.01,0]],"batl":[[0,36,2],[1,110,2],[2,990,0.01]],"ltp":15.5,"tv":2082.02,"id":7445998}]}]}
{"op":"mcm","clk":"4228714470","pt":1631463288596,"mc":[{"id":"1.187551081","rc":[{"batl":[[0,30,2],[1,36,2],[2,110,2]],"ltp":15.5,"tv":2082.02,"id":7445998}]}]}
{"op":"mcm","clk":"4228714519","pt":1631463288918,"mc":[{"id":"1.187551081","rc":[{"batb":[[0,8.4,37.67],[1,8.2,2],[2,1.01,30]],"ltp":15.5,"tv":2082.02,"id":7445998},{"batb":[[0,1.03,1625.34],[1,1.02,6021.27]],"batl":[[0,1.14,16],[1,1.19,14.82],[2,1.21,11.86]],"ltp":1.07,"tv":66500.14,"id":9629022}]}]}
{"op":"mcm","clk":"4228714858","pt":1631463290596,"mc":[{"id":"1.187551081","rc":[{"batl":[[1,36,4]],"ltp":15.5,"tv":2082.02,"id":7445998},{"batb":[[0,1.07,730.51],[1,1.06,534.91],[2,1.03,1625.34]],"batl":[[0,1.08,405.07],[1,1.09,835.94],[2,1.14,16]],"ltp":1.07,"tv":66500.14,"id":9629022}]}]}
{"op":"mcm","clk":"4228715211","pt":1631463292444,"mc":[{"id":"1.187551081","rc":[{"batb":[[0,11.5,21.74],[1,8.4,37.67],[2,8.2,2]],"batl":[[0,18.5,10],[1,30,2],[2,36,4]],"ltp":15.5,"tv":2082.02,"id":7445998},{"batb":[[2,1.05,238.1]],"ltp":1.07,"tv":66500.14,"id":9629022}]}]}
{"op":"mcm","clk":"4228715599","pt":1631463294599,"mc":[{"id":"1.187551081","rc":[{"batb":[[0,1.07,1267.73]],"ltp":1.07,"tv":66500.14,"id":9629022}]}]}
{"op":"mcm","clk":"4228715770","pt":1631463295631,"mc":[{"id":"1.187551081","rc":[{"batl":[[0,1.08,503.63]],"ltp":1.07,"tv":66500.14,"id":9629022}]}]}
{"op":"mcm","clk":"4228715901","pt":1631463296335,"mc":[{"id":"1.187551081","rc":[{"batb":[[0,8.4,37.67],[1,8.2,2],[2,1.01,30]],"batl":[[0,30,2],[1,36,4],[2,110,2]],"ltp":15.5,"tv":2082.02,"id":7445998},{"batb":[[0,1.03,1408.44],[1,1.02,6021.27],[2,1.01,3871.84]],"batl":[[0,1.14,16],[1,1.19,29.82],[2,1.21,11.86]],"ltp":1.07,"tv":66500.14,"id":9629022}]}]}
{"op":"mcm","clk":"4228716122","pt":1631463297506,"mc":[{"id":"1.187551081","rc":[{"batl":[[0,1.06,10],[1,1.14,16],[2,1.19,29.82]],"ltp":1.07,"tv":66500.14,"id":9629022}]}]}
{"op":"mcm","clk":"4228716258","pt":1631463298204,"mc":[{"id":"1.187551081","rc":[{"trd":[[1.06,87.92]],"batl":[[0,1.14,16],[1,1.19,29.82],[2,1.21,11.86]],"ltp":1.06,"tv":66504.48,"id":9629022}],"tv":68586.5}]}
{"op":"mcm","clk":"4228716515","pt":1631463299434,"mc":[{"id":"1.187551081","rc":[{"trd":[[1.06,97.92]],"batb":[[0,1.03,2717.81]],"batl":[[0,1.13,734.93],[1,1.14,470.54],[2,1.19,29.82]],"ltp":1.06,"tv":66514.48,"id":9629022}],"tv":68596.5}]}
{"op":"mcm","clk":"4228716866","pt":1631463301021,"mc":[{"id":"1.187551081","rc":[{"batb":[[1,1.01,30],[2,1.01,0]],"ltp":15.5,"tv":2082.02,"id":7445998},{"batb":[[1,1.02,5975.27]],"batl":[[2,1.17,29.64]],"ltp":1.06,"tv":66514.48,"id":9629022}]}]}
{"op":"mcm","clk":"4228717020","pt":1631463301818,"mc":[{"id":"1.187551081","rc":[{"batl":[[0,1.12,10],[1,1.13,734.93],[2,1.14,470.54]],"ltp":1.06,"tv":66514.48,"id":9629022}]}]}
{"op":"mcm","clk":"4228717518","pt":1631463304263,"mc":[{"id":"1.187551081","rc":[{"batl":[[1,36,2]],"ltp":15.5,"tv":2082.02,"id":7445998},{"batb":[[1,1.02,6059.27]],"batl":[[0,1.12,17]],"ltp":1.06,"tv":66514.48,"id":9629022}]}]}
{"op":"mcm","clk":"4228718131","pt":1631463307528,"mc":[{"id":"1.187551081","rc":[{"batl":[[0,1.12,27]],"ltp":1.06,"tv":66514.48,"id":9629022}]}]}
{"op":"mcm","clk":"4228719256","pt":1631463313523,"mc":[{"id":"1.187551081","rc":[{"batl":[[0,1.12,17]],"ltp":1.06,"tv":66514.48,"id":9629022}]}]}
{"op":"mcm","clk":"4228719851","pt":1631463317114,"mc":[{"id":"1.187551081","rc":[{"batb":[[1,1.02,5975.27]],"batl":[[0,1.12,7]],"ltp":1.06,"tv":66514.48,"id":9629022}]}]}
{"op":"mcm","clk":"4228719936","pt":1631463317746,"mc":[{"id":"1.187551081","rc":[{"batb":[[0,1.05,85.4],[1,1.03,2717.81],[2,1.02,5975.27]],"ltp":1.06,"tv":66514.48,"id":9629022}]}]}
{"op":"mcm","clk":"4228720392","pt":1631463320333,"mc":[{"id":"1.187551081","rc":[{"batb":[[2,1.02,5983.27]],"batl":[[1,1.14,16],[2,1.17,29.64]],"ltp":1.06,"tv":66514.48,"id":9629022}]}]}
{"op":"mcm","clk":"4228720779","pt":1631463322432,"mc":[{"id":"1.187551081","rc":[{"batl":[[0,36,2],[1,110,2],[2,990,0.01]],"ltp":15.5,"tv":2082.02,"id":7445998},{"trd":[[1.05,2848.85]],"batb":[[0,1.03,2672.81],[1,1.02,5983.27],[2,1.01,3871.84]],"ltp":1.05,"tv":66685.27,"id":9629022}],"tv":68767.3}]}
{"op":"mcm","clk":"4228720873","pt":1631463323020,"mc":[{"id":"1.187551081","rc":[{"batl":[[0,1.04,1296.79],[1,1.07,14.91],[2,1.09,7.32]],"ltp":1.05,"tv":66685.27,"id":9629022}]}]}
{"op":"mcm","clk":"4228721153","pt":1631463324424,"mc":[{"id":"1.187551081","rc":[{"batb":[[0,23,14.95],[1,13,31.9],[2,8.4,2]],"ltp":15.5,"tv":2082.02,"id":7445998},{"batl":[[0,1.04,1331.22]],"ltp":1.05,"tv":66685.27,"id":9629022}]}]}
{"op":"mcm","clk":"4228721394","pt":1631463325663,"mc":[{"id":"1.187551081","rc":[{"batb":[[0,26,9.62],[1,23,14.95],[2,22,2]],"batl":[[0,36,4.84],[2,160,37.59]],"ltp":15.5,"tv":2082.02,"id":7445998},{"batb":[[0,1.03,2724.32],[1,1.02,5224.12]],"batl":[[0,1.04,1592.17]],"ltp":1.05,"tv":66685.27,"id":9629022}]}]}
{"op":"mcm","clk":"4228721544","pt":1631463326477,"mc":[{"id":"1.187551081","rc":[{"batb":[[0,27,2],[1,26,2],[2,23,14.95]],"batl":[[0,36,2]],"ltp":15.5,"tv":2082.02,"id":7445998}]}]}
{"op":"mcm","clk":"4228721765","pt":1631463327544,"mc":[{"id":"1.187551081","rc":[{"batb":[[0,1.03,3229.02]],"ltp":1.05,"tv":66685.27,"id":9629022}]}]}
{"op":"mcm","clk":"4228721847","pt":1631463327967,"mc":[{"id":"1.187551081","rc":[{"batl":[[0,36,23.74],[1,55,23.62],[2,110,2]],"ltp":15.5,"tv":2082.02,"id":7445998},{"batb":[[0,1.03,3989.12],[1,1.02,6498.35]],"ltp":1.05,"tv":66685.27,"id":9629022}]}]}
{"op":"mcm","clk":"4228722143","pt":1631463329591,"mc":[{"id":"1.187551081","rc":[{"batb":[[0,28,9.62],[1,27,2],[2,26,2]],"batl":[[0,36,26.58]],"ltp":15.5,"tv":2082.02,"id":7445998},{"batl":[[1,1.07,21.91]],"ltp":1.05,"tv":66685.27,"id":9629022}]}]}
{"op":"mcm","clk":"4228722240","pt":1631463330074,"mc":[{"id":"1.187551081","rc":[{"trd":[[28,8]],"batb":[[0,27,2],[1,26,2],[2,23,14.95]],"ltp":28.0,"tv":2090.02,"id":7445998},{"batl":[[1,1.05,622.6],[2,1.06,694.34]],"ltp":1.05,"tv":66685.27,"id":9629022}],"tv":68775.3}]}
{"op":"mcm","clk":"4228722382","pt":1631463330884,"mc":[{"id":"1.187551081","rc":[{"batb":[[0,1.03,3555.31]],"ltp":1.05,"tv":66685.27,"id":9629022}]}]}
{"op":"mcm","clk":"4228722669","pt":1631463332451,"mc":[{"id":"1.187551081","rc":[{"trd":[[1.04,3785.01]],"batl":[[0,1.04,1587.17]],"ltp":1.04,"tv":66695.27,"id":9629022}],"tv":68785.3}]}
{"op":"mcm","clk":"4228722971","pt":1631463334068,"mc":[{"id":"1.187551081","rc":[{"trd":[[27,39.78]],"batb":[[0,26,2],[1,23,14.95],[2,22,2]],"batl":[[0,27,1],[1,36,26.58],[2,55,23.62]],"ltp":27.0,"tv":2094.02,"id":7445998}],"tv":68789.3}]}
{"op":"mcm","clk":"4228723579","pt":1631463337365,"mc":[{"id":"1.187551081","rc":[{"trd":[[27,41.78]],"batb":[[2,21,31.13]],"batl":[[0,36,26.58],[1,55,23.62],[2,110,2]],"ltp":27.0,"tv":2096.02,"id":7445998}],"tv":68791.3}]}
{"op":"mcm","clk":"4228723764","pt":1631463338389,"mc":[{"id":"1.187551081","rc":[{"batb":[[2,1.01,3293.43]],"ltp":1.04,"tv":66695.27,"id":9629022}]}]}
{"op":"mcm","clk":"4228723954","pt":1631463339362,"mc":[{"id":"1.187551081","rc":[{"trd":[[1.04,3812.57]],"batl":[[0,1.04,1573.39]],"ltp":1.04,"tv":66722.83,"id":9629022}],"tv":68818.86}]}
{"op":"mcm","clk":"4228724180","pt":1631463340372,"mc":[{"id":"1.187551081","rc":[{"batb":[[0,27,2],[1,26,2],[2,23,14.95]],"ltp":27.0,"tv":2096.02,"id":7445998}]}]}
{"op":"mcm","clk":"4228724434","pt":1631463341773,"mc":[{"id":"1.187551081","rc":[{"trd":[[1.04,3820.57]],"batl":[[0,1.04,1569.39]],"ltp":1.04,"tv":66730.83,"id":9629022}],"tv":68826.86}]}
{"op":"mcm","clk":"4228724677","pt":1631463343086,"mc":[{"id":"1.187551081","rc":[{"batb":[[0,1.03,3396.24]],"ltp":1.04,"tv":66730.83,"id":9629022}]}]}
{"op":"mcm","clk":"4228724979","pt":1631463344691,"mc":[{"id":"1.187551081","rc":[{"batb":[[0,28,8.23],[1,27,2],[2,26,2]],"ltp":27.0,"tv":2096.02,"id":7445998}]}]}
{"op":"mcm","clk":"4228725169","pt":1631463345778,"mc":[{"id":"1.187551081","rc":[{"trd":[[1.04,3822.51]],"batl":[[0,1.04,1568.42]],"ltp":1.04,"tv":66732.77,"id":9629022}],"tv":68828.79}]}
{"op":"mcm","clk":"4228725350","pt":1631463346790,"mc":[{"id":"1.187551081","rc":[{"trd":[[1.04,3842.51]],"batl":[[0,1.04,1558.42]],"ltp":1.04,"tv":66752.77,"id":9629022}],"tv":68848.79}]}
{"op":"mcm","clk":"4228725719","pt":1631463348368,"mc":[{"id":"1.187551081","rc":[{"trd":[[1.04,4306.23]],"batl":[[0,1.04,1326.56]],"ltp":1.04,"tv":67216.48,"id":9629022}],"tv":69312.51}]}
{"op":"mcm","clk":"4228726071","pt":1631463350412,"mc":[{"id":"1.187551081","rc":[{"trd":[[28,12]],"batb":[[0,27,2],[1,26,2],[2,23,14.95]],"ltp":28.0,"tv":2100.02,"id":7445998},{"batb":[[0,1.03,3362.51]],"batl":[[0,1.04,1360.31]],"ltp":1.04,"tv":67216.48,"id":9629022}],"tv":69316.51}]}
{"op":"mcm","clk":"4228726419","pt":1631463352024,"mc":[{"id":"1.187551081","rc":[{"batl":[[0,1.04,1491.36]],"ltp":1.04,"tv":67216.48,"id":9629022}]}]}
{"op":"mcm","clk":"4228726698","pt":1631463353531,"mc":[{"id":"1.187551081","rc":[{"batb":[[0,29,6.23],[1,27,2]],"ltp":28.0,"tv":2100.02,"id":7445998}]}]}
{"op":"mcm","clk":"4228726822","pt":1631463354286,"mc":[{"id":"1.187551081","rc":[{"batb":[[0,27,2],[1,23,14.95],[2,21,31.13]],"ltp":28.0,"tv":2100.02,"id":7445998},{"batl":[[0,1.04,1562.76]],"ltp":1.04,"tv":67216.48,"id":9629022}]}]}
{"op":"mcm","clk":"4228726900","pt":1631463354784,"mc":[{"id":"1.187551081","rc":[{"trd":[[1.04,4342.37]],"batl":[[0,1.04,1544.69]],"ltp":1.04,"tv":67252.62,"id":9629022}],"tv":69352.65}]}
{"op":"mcm","clk":"4228727151","pt":1631463356222,"mc":[{"id":"1.187551081","rc":[{"trd":[[1.03,19027.68]],"batb":[[0,1.03,3322.51]],"ltp":1.03,"tv":67332.62,"id":9629022}],"tv":69432.65}]}
{"op":"mcm","clk":"4228727241","pt":1631463356814,"mc":[{"id":"1.187551081","rc":[{"batb":[[0,28,6.23],[1,27,2],[2,23,14.95]],"ltp":28.0,"tv":2100.02,"id":7445998}]}]}
{"op":"mcm","clk":"4228727756","pt":1631463360021,"mc":[{"id":"1.187551081","rc":[{"batb":[[0,1.03,2013.14]],"batl":[[0,1.04,295.38]],"ltp":1.03,"tv":67332.62,"id":9629022}]}]}
{"op":"mcm","clk":"4228728267","pt":1631463362929,"mc":[{"id":"1.187551081","rc":[{"batb":[[2,1.01,4628.73]],"ltp":1.03,"tv":67332.62,"id":9629022}]}]}
{"op":"mcm","clk":"4228729108","pt":1631463367418,"mc":[{"id":"1.187551081","rc":[{"trd":[[1.03,19055.68]],"batb":[[0,1.03,1999.14]],"ltp":1.03,"tv":67360.62,"id":9629022}],"tv":69460.65}]}
{"op":"mcm","clk":"4228730245","pt":1631463373528,"mc":[{"id":"1.187551081","rc":[{"batb":[[0,13,31.9],[1,12,2],[2,9.2,2]],"batl":[[0,110,2],[1,160,37.59],[2,990,0.01]],"ltp":28.0,"tv":2100.02,"id":7445998},{"batb":[[0,1.01,4628.73],[1,1.02,0],[2,1.01,0]],"batl":[[0,1.08,1268.75],[1,1.09,315.5],[2,1.1,236.95]],"ltp":1.03,"tv":67360.62,"id":9629022}]}]}
{"op":"mcm","clk":"4228730590","pt":1631463375327,"mc":[{"id":"1.187551081","rc":[{"batl":[[1,990,0.01],[2,990,0]],"ltp":28.0,"tv":2100.02,"id":7445998}]}]}
{"op":"mcm","clk":"4228730772","pt":1631463376342,"mc":[{"id":"1.187551081","rc":[{"batb":[[0,14,27.97],[1,13,31.9],[2,12,2]],"ltp":28.0,"tv":2100.02,"id":7445998}]}]}
{"op":"mcm","clk":"4228730862","pt":1631463376869,"mc":[{"id":"1.187551081","rc":[{"batb":[[1,12,2],[2,9.2,2]],"ltp":28.0,"tv":2100.02,"id":7445998}]}]}
{"op":"mcm","clk":"4228731101","pt":1631463378138,"mc":[{"id":"1.187551081","rc":[{"batb":[[0,1.01,3293.43]],"batl":[[0,1.07,7],[1,1.08,20],[2,1.09,315.5]],"ltp":1.03,"tv":67360.62,"id":9629022}]}]}
{"op":"mcm","clk":"4228731725","pt":1631463381578,"mc":[{"id":"1.187551081","rc":[{"trd":[[1.04,4362.37]],"batb":[[0,1.04,225.27],[1,1.03,1071.82],[2,1.01,3293.43]],"batl":[[0,1.05,1284.44]],"ltp":1.04,"tv":67380.62,"id":9629022}],"tv":69480.65}]}
{"op":"mcm","clk":"4228731828","pt":1631463382166,"mc":[{"id":"1.187551081","rc":[{"batb":[[0,21,11.9],[1,14,27.97],[2,12,2]],"batl":[[0,34,7.19],[1,110,2],[2,990,0.01]],"ltp":28.0,"tv":2100.02,"id":7445998},{"batb":[[1,1.03,1314.54]],"batl":[[0,1.05,1319.44]],"ltp":1.04,"tv":67380.62,"id":9629022}]}]}
{"op":"mcm","clk":"4228732103","pt":1631463383588,"mc":[{"id":"1.187551081","rc":[{"batl":[[1,95,39.2],[2,110,2]],"ltp":28.0,"tv":2100.02,"id":7445998},{"batb":[[2,1.02,36.14]],"ltp":1.04,"tv":67380.62,"id":9629022}]}]}
{"op":"mcm","clk":"4228732682","pt":1631463386493,"mc":[{"id":"1.187551081","rc":[{"batb":[[0,14,27.97],[1,12,2],[2,9.2,2]],"batl":[[0,95,39.2],[1,110,2],[2,990,0.01]],"ltp":28.0,"tv":2100.02,"id":7445998},{"batb":[[0,1.02,36.14],[1,1.01,3293.43],[2,1.02,0]],"batl":[[0,1.08,20],[1,1.09,315.5],[2,1.1,236.95]],"ltp":1.04,"tv":67380.62,"id":9629022}]}]}
{"op":"mcm","clk":"4228733096","pt":1631463388605,"mc":[{"id":"1.187551081","rc":[{"batl":[[0,110,2],[1,990,0.01],[2,990,0]],"ltp":28.0,"tv":2100.02,"id":7445998},{"batl":[[0,1.08,27]],"ltp":1.04,"tv":67380.62,"id":9629022}]}]}
{"op":"mcm","clk":"4228733222","pt":1631463389197,"mc":[{"id":"1.187551081","rc":[{"batb":[[1,9.2,2],[2,1.01,30]],"ltp":28.0,"tv":2100.02,"id":7445998},{"batb":[[0,1.02,72.29],[1,1.01,4628.73]],"batl":[[0,1.04,50],[1,1.08,1275.75],[2,1.11,38.82]],"ltp":1.04,"tv":67380.62,"id":9629022}]}]}
{"op":"mcm","clk":"4228733869","pt":1631463392091,"mc":[{"id":"1.187551081","rc":[{"batb":[[1,12,2],[2,9.2,2]],"ltp":28.0,"tv":2100.02,"id":7445998},{"batl":[[2,1.09,252.5]],"ltp":1.04,"tv":67380.62,"id":9629022}]}]}
{"op":"mcm","clk":"4228734918","pt":1631463397216,"mc":[{"id":"1.187551081","rc":[{"batl":[[1,1.08,27]],"ltp":1.04,"tv":67380.62,"id":9629022}]}]}
{"op":"mcm","clk":"4228735245","pt":1631463398930,"mc":[{"id":"1.187551081","rc":[{"trd":[[1.02,2863.06]],"batb":[[0,1.01,4628.73],[1,1.01,0]],"ltp":1.02,"tv":67525.19,"id":9629022}],"tv":69625.22}]}
{"op":"mcm","clk":"4228735608","pt":1631463400602,"mc":[{"id":"1.187551081","rc":[{"batb":[[0,24,12.8],[1,14,27.97],[2,12,2]],"ltp":28.0,"tv":2100.02,"id":7445998},{"batl":[[0,1.02,1322.21],[1,1.04,50],[2,1.05,15.19]],"ltp":1.02,"tv":67525.19,"id":9629022}]}]}
{"op":"mcm","clk":"4228735635","pt":1631463400810,"mc":[{"id":"1.187551081","rc":[{"batb":[[1,12,2],[2,9.2,2]],"ltp":28.0,"tv":2100.02,"id":7445998}]}]}
{"op":"mcm","clk":"4228735940","pt":1631463402524,"mc":[{"id":"1.187551081","rc":[{"batb":[[0,60,4.17],[1,27,2],[2,26,2]],"batl":[[0,100,2.13],[1,110,2],[2,990,0.01]],"ltp":28.0,"tv":2100.02,"id":7445998},{"batb":[[0,1.01,5050.07]],"batl":[[0,1.02,1567.31],[1,1.03,80],[2,1.04,50]],"ltp":1.02,"tv":67525.19,"id":9629022}]}]}
{"op":"mcm","clk":"4228736324","pt":1631463404524,"mc":[{"id":"1.187551081","rc":[{"trd":[[1.01,700]],"batb":[[0,1.01,4950.07]],"ltp":1.01,"tv":67725.19,"id":9629022}],"tv":69825.22}]}
{"op":"mcm","clk":"4228736561","pt":1631463405618,"mc":[{"id":"1.187551081","rc":[{"trd":[[60,4]],"batb":[[0,60,2.17]],"ltp":60.0,"tv":2104.02,"id":7445998},{"batb":[[0,1.01,5750.07]],"ltp":1.01,"tv":67725.19,"id":9629022}],"tv":69829.22}]}
{"op":"mcm","clk":"4228736718","pt":1631463406438,"mc":[{"id":"1.187551081","rc":[{"batb":[[2,26,4]],"ltp":60.0,"tv":2104.02,"id":7445998},{"batl":[[2,1.04,630.88]],"ltp":1.01,"tv":67725.19,"id":9629022}]}]}
{"op":"mcm","clk":"4228737008","pt":1631463407855,"mc":[{"id":"1.187551081","rc":[{"trd":[[1.02,2869.24]],"batl":[[0,1.02,1564.22]],"ltp":1.02,"tv":67731.37,"id":9629022}],"tv":69835.4}]}
{"op":"mcm","clk":"4228737361","pt":1631463409624,"mc":[{"id":"1.187551081","rc":[{"trd":[[60,8.34]],"batb":[[0,27,2],[1,26,4],[2,24,12.8]],"ltp":60.0,"tv":2108.36,"id":7445998}],"tv":69839.74}]}
{"op":"mcm","clk":"4228737831","pt":1631463412047,"mc":[{"id":"1.187551081","rc":[{"trd":[[1.02,2889.24]],"batl":[[0,1.02,1554.22]],"ltp":1.02,"tv":67751.37,"id":9629022}],"tv":69859.74}]}
{"op":"mcm","clk":"4228738214","pt":1631463414040,"mc":[{"id":"1.187551081","rc":[{"batb":[[0,60,4.17],[1,27,2],[2,26,2]],"ltp":60.0,"tv":2108.36,"id":7445998},{"batb":[[0,1.01,5099.36]],"ltp":1.02,"tv":67751.37,"id":9629022}]}]}
{"op":"mcm","clk":"4228738572","pt":1631463415844,"mc":[{"id":"1.187551081","rc":[{"trd":[[1.02,2893.58]],"batl":[[0,1.02,1552.05]],"ltp":1.02,"tv":67755.71,"id":9629022}],"tv":69864.08}]}
{"op":"mcm","clk":"4228739105","pt":1631463418663,"mc":[{"id":"1.187551081","rc":[{"trd":[[60,16.68]],"batb":[[0,27,2],[1,26,2],[2,24,12.8]],"ltp":60.0,"tv":2116.7,"id":7445998}],"tv":69872.41}]}
{"op":"mcm","clk":"4228739296","pt":1631463419641,"mc":[{"id":"1.187551081","rc":[{"batb":[[0,24,12.53],[1,17.5,2],[2,12,2]],"batl":[[0,110,2],[1,990,0.01],[2,990,0]],"ltp":60.0,"tv":2116.7,"id":7445998},{"batb":[[0,1.01,2542.72]],"batl":[[0,1.04,50],[1,1.05,525.7],[2,1.06,379.25]],"ltp":1.02,"tv":67755.71,"id":9629022}]}]}
{"op":"mcm","clk":"4228739782","pt":1631463422257,"mc":[{"id":"1.187551081","rc":[{"batl":[[0,1.04,938.27],[1,1.05,930.32]],"ltp":1.02,"tv":67755.71,"id":9629022}]}]}
{"op":"mcm","clk":"4228740064","pt":1631463423662,"mc":[{"id":"1.187551081","rc":[{"batb":[[0,26,2],[1,24,14.53],[2,23,2]],"ltp":60.0,"tv":2116.7,"id":7445998},{"batb":[[0,1.01,2253.52]],"batl":[[0,1.04,1571.4]],"ltp":1.02,"tv":67755.71,"id":9629022}]}]}
{"op":"mcm","clk":"4228740164","pt":1631463424152,"mc":[{"id":"1.187551081","rc":[{"batb":[[0,24,14.53],[1,23,2],[2,17.5,2]],"batl":[[0,990,0.01],[1,990,0]],"ltp":60.0,"tv":2116.7,"id":7445998},{"batl":[[0,1.04,938.27],[1,1.05,404.62]],"ltp":1.02,"tv":67755.71,"id":9629022}]}]}
{"op":"mcm","clk":"4228740524","pt":1631463426076,"mc":[{"id":"1.187551081","rc":[{"batl":[[0,1.01,442],[1,1.04,938.27],[2,1.05,404.62]],"ltp":1.02,"tv":67755.71,"id":9629022}]}]}
{"op":"mcm","clk":"4228740833","pt":1631463427555,"mc":[{"id":"1.187551081","rc":[{"batl":[[1,1.04,50],[2,1.06,379.25]],"ltp":1.02,"tv":67755.71,"id":9629022}]}]}
{"op":"mcm","clk":"4228741395","pt":1631463430520,"mc":[{"id":"1.187551081","rc":[{"trd":[[100,4.46]],"ltp":100.0,"tv":2121.16,"id":7445998},{"trd":[[1.01,1142]],"batb":[[0,1.01,1335.3]],"batl":[[0,1.02,506.26],[1,1.03,808.03],[2,1.04,50]],"ltp":1.01,"tv":68197.71,"id":9629022}],"tv":70318.87}]}
{"op":"mcm","clk":"4228741789","pt":1631463432489,"mc":[{"id":"1.187551081","rc":[{"batb":[[0,1.01,1407.59]],"ltp":1.01,"tv":68197.71,"id":9629022}]}]}
{"op":"mcm","clk":"4228742016","pt":1631463433615,"mc":[{"id":"1.187551081","rc":[{"batb":[[0,26,2],[1,24,14.53],[2,23,4]],"ltp":100.0,"tv":2121.16,"id":7445998},{"batb":[[0,1.01,1335.3]],"batl":[[1,1.03,1050.75],[2,1.04,616.38]],"ltp":1.01,"tv":68197.71,"id":9629022}]}]}
{"op":"mcm","clk":"4228742219","pt":1631463434510,"mc":[{"id":"1.187551081","rc":[{"batb":[[2,23,2]],"ltp":100.0,"tv":2121.16,"id":7445998},{"trd":[[1.01,1146]],"batb":[[0,1.01,1333.3]],"batl":[[1,1.03,808.03]],"ltp":1.01,"tv":68201.71,"id":9629022}],"tv":70322.87}]}
{"op":"mcm","clk":"4228742356","pt":1631463435218,"mc":[{"id":"1.187551081","rc":[{"batb":[[0,1.01,2153.98]],"ltp":1.01,"tv":68201.71,"id":9629022}]}]}
{"op":"mcm","clk":"4228742819","pt":1631463437648,"mc":[{"id":"1.187551081","rc":[{"batl":[[0,1.04,616.38],[1,1.05,555.9],[2,1.06,379.25]],"ltp":1.01,"tv":68201.71,"id":9629022}]}]}
{"op":"mcm","clk":"4228742871","pt":1631463437906,"mc":[{"id":"1.187551081","rc":[{"batb":[[0,24,14.53],[1,17.5,2],[2,4.5,374.57]],"ltp":100.0,"tv":2121.16,"id":7445998},{"batl":[[0,1.04,50],[1,1.06,379.25],[2,1.08,20]],"ltp":1.01,"tv":68201.71,"id":9629022}]}]}
{"op":"mcm","clk":"4228743361","pt":1631463440424,"mc":[{"id":"1.187551081","rc":[{"batl":[[0,70,2.25],[1,990,0.01]],"ltp":100.0,"tv":2121.16,"id":7445998},{"batl":[[0,1.04,939.35],[1,1.05,403.55],[2,1.06,379.25]],"ltp":1.01,"tv":68201.71,"id":9629022}]}]}
{"op":"mcm","clk":"4228743515","pt":1631463441123,"mc":[{"id":"1.187551081","rc":[{"batb":[[1,23,2],[2,17.5,2]],"batl":[[0,990,0.01],[1,990,0]],"ltp":100.0,"tv":2121.16,"id":7445998},{"batb":[[0,1.02,36.8]],"batl":[[0,1.03,242.72],[1,1.04,939.35],[2,1.05,403.55]],"ltp":1.01,"tv":68201.71,"id":9629022}]}]}
{"op":"mcm","clk":"4228743960","pt":1631463443393,"mc":[{"id":"1.187551081","rc":[{"batl":[[0,1.04,939.35],[1,1.05,403.55],[2,1.06,379.25]],"ltp":1.01,"tv":68201.71,"id":9629022}]}]}
{"op":"mcm","clk":"4228744718","pt":1631463447418,"mc":[{"id":"1.187551081","rc":[{"batb":[[1,23,4],[2,20,2]],"ltp":100.0,"tv":2121.16,"id":7445998}]}]}
{"op":"mcm","clk":"4228744905","pt":1631463448316,"mc":[{"id":"1.187551081","rc":[{"batb":[[1,23,2],[2,17.5,2]],"ltp":100.0,"tv":2121.16,"id":7445998},{"trd":[[1.02,2967.18]],"ltp":1.02,"tv":68275.31,"id":9629022}],"tv":70396.47}]}
{"op":"mcm","clk":"4228745403","pt":1631463450642,"mc":[{"id":"1.187551081","rc":[{"batb":[[0,26,2],[1,24,14.53],[2,23,2]],"batl":[[0,34,84.71],[1,990,0.01]],"ltp":100.0,"tv":2121.16,"id":7445998},{"batl":[[0,1.04,1504.48],[1,1.05,885.85]],"ltp":1.02,"tv":68275.31,"id":9629022}]}]}
{"op":"mcm","clk":"4228745595","pt":1631463451544,"mc":[{"id":"1.187551081","rc":[{"batb":[[0,24,14.53],[1,23,2],[2,17.5,2]],"batl":[[0,36,2]],"ltp":100.0,"tv":2121.16,"id":7445998},{"batb":[[0,1.03,1357.2]],"ltp":1.02,"tv":68275.31,"id":9629022}]}]}
{"op":"mcm","clk":"4228745757","pt":1631463452441,"mc":[{"id":"1.187551081","rc":[{"batb":[[0,25,9.04],[1,24,14.53]],"batl":[[0,990,0.01],[1,990,0]],"ltp":100.0,"tv":2121.16,"id":7445998},{"batb":[[0,1.03,1309.37],[1,1.02,4307.4]],"batl":[[0,1.04,1669.31]],"ltp":1.02,"tv":68275.31,"id":9629022}]}]}
{"op":"mcm","clk":"4228745952","pt":1631463453518,"mc":[{"id":"1.187551081","rc":[{"batb":[[0,27,2],[1,26,2],[2,25,9.04]],"batl":[[0,32,2.6],[1,160,37.59],[2,990,0.01]],"ltp":100.0,"tv":2121.16,"id":7445998}]}]}
{"op":"mcm","clk":"4228746088","pt":1631463454242,"mc":[{"id":"1.187551081","rc":[{"batb":[[2,25,2]],"batl":[[0,160,37.59],[1,990,0.01],[2,990,0]],"ltp":100.0,"tv":2121.16,"id":7445998},{"batb":[[2,1.01,289.2]],"ltp":1.02,"tv":68275.31,"id":9629022}]}]}
{"op":"mcm","clk":"4228746357","pt":1631463455660,"mc":[{"id":"1.187551081","rc":[{"batb":[[0,1.03,1463.15],[1,1.02,4452]],"ltp":1.02,"tv":68275.31,"id":9629022}]}]}
{"op":"mcm","clk":"4228746512","pt":1631463456430,"mc":[{"id":"1.187551081","rc":[{"batb":[[0,1.03,2080.91]],"ltp":1.02,"tv":68275.31,"id":9629022}]}]}
{"op":"mcm","clk":"4228746675","pt":1631463457329,"mc":[{"id":"1.187551081","rc":[{"batb":[[0,28,2.66],[1,27,2],[2,26,2]],"batl":[[0,38,6.58],[1,160,37.59],[2,990,0.01]],"ltp":100.0,"tv":2121.16,"id":7445998},{"batb":[[1,1.02,4549],[2,1.01,760.4]],"ltp":1.02,"tv":68275.31,"id":9629022}]}]}
{"op":"mcm","clk":"4228746810","pt":1631463458131,"mc":[{"id":"1.187551081","rc":[{"batl":[[1,110,2],[2,160,37.59]],"ltp":100.0,"tv":2121.16,"id":7445998},{"batb":[[2,1.01,3608.77]],"ltp":1.02,"tv":68275.31,"id":9629022}]}]}
{"op":"mcm","clk":"4228746956","pt":1631463459055,"mc":[{"id":"1.187551081","rc":[{"batb":[[2,1.01,4476.38]],"ltp":1.02,"tv":68275.31,"id":9629022}]}]}
{"op":"mcm","clk":"4228747618","pt":1631463462450,"mc":[{"id":"1.187551081","rc":[{"batl":[[0,36,20.25],[1,55,20.3],[2,110,2]],"ltp":100.0,"tv":2121.16,"id":7445998},{"batb":[[0,1.03,2788.91],[1,1.02,5643.88]],"ltp":1.02,"tv":68275.31,"id":9629022}]}]}
{"op":"mcm","clk":"4228747831","pt":1631463463637,"mc":[{"id":"1.187551081","rc":[{"trd":[[28,17.32]],"batb":[[0,27,2],[1,26,2],[2,25,2]],"batl":[[0,28,1.34],[1,36,20.25],[2,55,20.3]],"ltp":28.0,"tv":2126.48,"id":7445998}],"tv":70401.79}]}
{"op":"mcm","clk":"4228747996","pt":1631463464567,"mc":[{"id":"1.187551081","rc":[{"batl":[[0,36,20.25],[1,55,20.3],[2,110,2]],"ltp":28.0,"tv":2126.48,"id":7445998}]}]}
{"op":"mcm","clk":"4228748281","pt":1631463466144,"mc":[{"id":"1.187551081","rc":[{"batb":[[1,25,2],[2,24,12.53]],"batl":[[0,34,6.58],[1,36,20.25],[2,55,20.3]],"ltp":28.0,"tv":2126.48,"id":7445998}]}]}
{"op":"mcm","clk":"4228748554","pt":1631463468219,"mc":[{"id":"1.187551081","rc":[{"batb":[[0,28,2.39],[1,27,2]],"ltp":28.0,"tv":2126.48,"id":7445998}]}]}
{"op":"mcm","clk":"4228748875","pt":1631463469563,"mc":[{"id":"1.187551081","rc":[{"batb":[[0,13.5,29.73],[1,12,2],[2,9.2,2]],"batl":[[0,110,2],[1,160,37.59],[2,990,0.01]],"ltp":28.0,"tv":2126.48,"id":7445998},{"batb":[[0,1.02,144.6],[1,1.01,4294.38],[2,1.01,0]],"batl":[[0,1.04,50],[1,1.08,20],[2,1.09,285.5]],"ltp":1.02,"tv":68275.31,"id":9629022}]}]}
{"op":"mcm","clk":"4228749067","pt":1631463470543,"mc":[{"id":"1.187551081","rc":[{"batl":[[1,990,0.01],[2,990,0]],"ltp":28.0,"tv":2126.48,"id":7445998}]}]}
{"op":"mcm","clk":"4228749438","pt":1631463472645,"mc":[{"id":"1.187551081","rc":[{"batb":[[1,1.01,5629.68]],"batl":[[1,1.08,1173.41]],"ltp":1.02,"tv":68275.31,"id":9629022}]}]}
{"op":"mcm","clk":"4228749887","pt":1631463475068,"mc":[{"id":"1.187551081","rc":[{"batl":[[1,1.07,92.96],[2,1.08,1173.41]],"ltp":1.02,"tv":68275.31,"id":9629022}]}]}
{"op":"mcm","clk":"4228752067","pt":1631463486972,"mc":[{"id":"1.187551081","rc":[{"batb":[[0,1.02,149.6]],"ltp":1.02,"tv":68275.31,"id":9629022}]}]}
{"op":"mcm","clk":"4228752420","pt":1631463488906,"mc":[{"id":"1.187551081","rc":[{"batb":[[1,9.2,2],[2,1.01,30]],"ltp":28.0,"tv":2126.48,"id":7445998},{"batb":[[1,1.01,4294.38]],"ltp":1.02,"tv":68275.31,"id":9629022}]}]}
{"op":"mcm","clk":"4228752599","pt":1631463489888,"mc":[{"id":"1.187551081","rc":[{"trd":[[1.04,4415.77]],"batl":[[0,1.04,23.3]],"ltp":1.04,"tv":68328.71,"id":9629022}],"tv":70455.19}]}
{"op":"mcm","clk":"4228752906","pt":1631463491623,"mc":[{"id":"1.187551081","rc":[{"trd":[[1.04,4462.37]],"batb":[[0,1.06,8389.06],[1,1.02,149.6],[2,1.01,4294.38]],"batl":[[0,1.07,92.96],[1,1.08,1173.41],[2,1.1,246.75]],"ltp":1.04,"tv":68375.31,"id":9629022}],"tv":70501.79}]}
{"op":"mcm","clk":"4228753099","pt":1631463492596,"mc":[{"id":"1.187551081","rc":[{"batb":[[2,8.4,34.58]],"ltp":28.0,"tv":2126.48,"id":7445998},{"batb":[[0,1.06,1339.08],[1,1.05,1945.24],[2,1.02,4287.66]],"batl":[[2,1.1,261.25]],"ltp":1.04,"tv":68375.31,"id":9629022}]}]}
{"op":"mcm","clk":"4228753233","pt":1631463493655,"mc":[{"id":"1.187551081","rc":[{"batl":[[0,26,2],[1,50,2],[2,110,2]],"ltp":28.0,"tv":2126.48,"id":7445998},{"batb":[[2,1.04,19]],"batl":[[0,1.08,1173.41],[1,1.1,261.25],[2,1.11,278.32]],"ltp":1.04,"tv":68375.31,"id":9629022}]}]}
{"op":"mcm","clk":"4228753453","pt":1631463494436,"mc":[{"id":"1.187551081","rc":[{"batl":[[1,30,47.29],[2,50,2]],"ltp":28.0,"tv":2126.48,"id":7445998}]}]}
{"op":"mcm","clk":"4228753546","pt":1631463494917,"mc":[{"id":"1.187551081","rc":[{"batb":[[0,14,5.8],[1,13.5,29.73],[2,9.2,2]],"batl":[[0,18.5,10],[1,26,2],[2,30,47.29]],"ltp":28.0,"tv":2126.48,"id":7445998},{"batb":[[0,1.06,1518.55]],"ltp":1.04,"tv":68375.31,"id":9629022}]}]}
{"op":"mcm","clk":"4228753868","pt":1631463496589,"mc":[{"id":"1.187551081","rc":[{"batb":[[0,14,7.8],[1,13.5,31.73]],"batl":[[1,22,32.69],[2,26,2]],"ltp":28.0,"tv":2126.48,"id":7445998},{"batb":[[0,1.06,2197.07]],"batl":[[0,1.07,171.02],[1,1.08,1293.39],[2,1.1,261.25]],"ltp":1.04,"tv":68375.31,"id":9629022}]}]}
{"op":"mcm","clk":"4228753906","pt":1631463496801,"mc":[{"id":"1.187551081","rc":[{"batl":[[1,26,2],[2,30,47.29]],"ltp":28.0,"tv":2126.48,"id":7445998},{"batl":[[0,1.07,26]],"ltp":1.04,"tv":68375.31,"id":9629022}]}]}
{"op":"mcm","clk":"4228754156","pt":1631463498194,"mc":[{"id":"1.187551081","rc":[{"batb":[[0,14.5,2],[1,14,7.8],[2,13.5,31.73]],"ltp":28.0,"tv":2126.48,"id":7445998}]}]}
{"op":"mcm","clk":"4228754537","pt":1631463500332,"mc":[{"id":"1.187551081","rc":[{"trd":[[1.07,2210.46]],"batb":[[0,1.07,88.85],[1,1.06,2197.07],[2,1.05,1945.24]],"batl":[[0,1.08,1293.39],[1,1.1,261.25],[2,1.11,278.32]],"ltp":1.07,"tv":68427.31,"id":9629022}],"tv":70553.79}]}
{"op":"mcm","clk":"4228754723","pt":1631463501320,"mc":[{"id":"1.187551081","rc":[{"batb":[[0,15,2],[1,14.5,2],[2,14,7.8]],"ltp":28.0,"tv":2126.48,"id":7445998},{"trd":[[1.07,2251.77]],"batb":[[0,1.07,68.19]],"ltp":1.07,"tv":68468.62,"id":9629022}],"tv":70595.1}]}
{"op":"mcm","clk":"4228754938","pt":1631463502485,"mc":[{"id":"1.187551081","rc":[{"batl":[[0,18,32.54],[1,21,38.47],[2,26,2]],"ltp":28.0,"tv":2126.48,"id":7445998},{"batb":[[1,1.06,2749.64],[2,1.05,2714.73]],"ltp":1.07,"tv":68468.62,"id":9629022}]}]}
{"op":"mcm","clk":"4228755153","pt":1631463503637,"mc":[{"id":"1.187551081","rc":[{"trd":[[1.07,2275.77]],"batb":[[0,1.07,56.19]],"ltp":1.07,"tv":68492.62,"id":9629022}],"tv":70619.11}]}
{"op":"mcm","clk":"4228755170","pt":1631463503734,"mc":[{"id":"1.187551081","rc":[{"batb":[[1,1.06,2682.88]],"ltp":1.07,"tv":68492.62,"id":9629022}]}]}
{"op":"mcm","clk":"4228755515","pt":1631463505436,"mc":[{"id":"1.187551081","rc":[{"trd":[[1.07,2322.57]],"batb":[[0,1.07,32.79]],"batl":[[0,1.08,1751.16],[1,1.09,560.25],[2,1.1,261.25]],"ltp":1.07,"tv":68539.42,"id":9629022}],"tv":70665.9}]}
{"op":"mcm","clk":"4228755595","pt":1631463505821,"mc":[{"id":"1.187551081","rc":[{"batl":[[0,17.5,10.31],[1,18,32.54],[2,21,38.47]],"ltp":28.0,"tv":2126.48,"id":7445998}]}]}
{"op":"mcm","clk":"4228756070","pt":1631463508239,"mc":[{"id":"1.187551081","rc":[{"batb":[[0,14,5.8],[1,13.5,66.35],[2,12,50.88]],"ltp":28.0,"tv":2126.48,"id":7445998}]}]}
{"op":"mcm","clk":"4228756689","pt":1631463511245,"mc":[{"id":"1.187551081","rc":[{"trd":[[1.06,97.94],[1.07,2388.15],[1.08,3435.97]],"batb":[[0,1.06,2178.65],[1,1.05,2714.73],[2,1.03,907.83]],"batl":[[0,1.08,256]],"ltp":1.06,"tv":71595.33,"id":9629022}],"tv":73721.81}]}
{"op":"mcm","clk":"4228757287","pt":1631463514053,"mc":[{"id":"1.187551081","rc":[{"batb":[[0,1.07,974.53],[1,1.06,2178.65],[2,1.05,2714.73]],"batl":[[0,1.08,784.12],[1,1.09,1274.27]],"ltp":1.06,"tv":71595.33,"id":9629022}]}]}
{"op":"mcm","clk":"4228757490","pt":1631463515041,"mc":[{"id":"1.187551081","rc":[{"batl":[[0,15,3.2],[1,17.5,10.31],[2,18,32.54]],"ltp":28.0,"tv":2126.48,"id":7445998},{"batl":[[0,1.08,892.1]],"ltp":1.06,"tv":71595.33,"id":9629022}]}]}
{"op":"mcm","clk":"4228757629","pt":1631463515748,"mc":[{"id":"1.187551081","rc":[{"batb":[[0,1.07,979.53]],"ltp":1.06,"tv":71595.33,"id":9629022}]}]}
{"op":"mcm","clk":"4228758005","pt":1631463517584,"mc":[{"id":"1.187551081","rc":[{"batb":[[0,8.4,34.58],[1,7.6,2],[2,6.2,2]],"batl":[[0,30,47.29],[1,36,2],[2,110,2]],"ltp":28.0,"tv":2126.48,"id":7445998},{"batb":[[0,1.07,5],[1,1.03,907.83],[2,1.02,5624.56]],"batl":[[0,1.11,38.82],[1,1.13,11.86],[2,1.15,192.92]],"ltp":1.06,"tv":71595.33,"id":9629022}]}]}
{"op":"mcm","clk":"4228758220","pt":1631463518658,"mc":[{"id":"1.187551081","rc":[{"batl":[[0,36,2],[1,110,2],[2,990,0.01]],"ltp":28.0,"tv":2126.48,"id":7445998}]}]}
{"op":"mcm","clk":"4228758297","pt":1631463519041,"mc":[{"id":"1.187551081","rc":[{"batl":[[0,110,2],[1,990,0.01],[2,990,0]],"ltp":28.0,"tv":2126.48,"id":7445998},{"batb":[[1,1.02,5624.56],[2,1.01,4294.38]],"ltp":1.06,"tv":71595.33,"id":9629022}]}]}
{"op":"mcm","clk":"4228758496","pt":1631463520063,"mc":[{"id":"1.187551081","rc":[{"batb":[[1,1.03,1309.37],[2,1.02,5624.56]],"batl":[[2,1.14,320.61]],"ltp":1.06,"tv":71595.33,"id":9629022}]}]}
{"op":"mcm","clk":"4228758926","pt":1631463522223,"mc":[{"id":"1.187551081","rc":[{"batl":[[0,36,2],[1,110,2],[2,990,0.01]],"ltp":28.0,"tv":2126.48,"id":7445998},{"batb":[[0,1.03,2138.2],[1,1.02,5624.56],[2,1.01,4294.38]],"ltp":1.06,"tv":71595.33,"id":9629022}]}]}
{"op":"mcm","clk":"4228759203","pt":1631463523657,"mc":[{"id":"1.187551081","rc":[{"batb":[[0,1.04,5],[1,1.03,2143.2],[2,1.02,5624.56]],"batl":[[0,1.07,5],[1,1.11,38.82],[2,1.13,11.86]],"ltp":1.06,"tv":71595.33,"id":9629022}]}]}
{"op":"mcm","clk":"4228759585","pt":1631463525447,"mc":[{"id":"1.187551081","rc":[{"batl":[[0,1.05,6204.54],[1,1.07,5],[2,1.11,38.82]],"ltp":1.06,"tv":71595.33,"id":9629022}]}]}
{"op":"mcm","clk":"4228759822","pt":1631463526783,"mc":[{"id":"1.187551081","rc":[{"batb":[[0,1.03,2143.2],[1,1.02,5624.56],[2,1.01,4294.38]],"ltp":1.06,"tv":71595.33,"id":9629022}]}]}
{"op":"mcm","clk":"4228760191","pt":1631463528558,"mc":[{"id":"1.187551081","rc":[{"trd":[[1.05,2858.85]],"batl":[[0,1.05,7483.98],[1,1.07,19.91],[2,1.09,7.32]],"ltp":1.05,"tv":71605.33,"id":9629022}],"tv":73731.81}]}
{"op":"mcm","clk":"4228760408","pt":1631463529533,"mc":[{"id":"1.187551081","rc":[{"batb":[[0,23,14.38],[1,13.5,30.73],[2,7.6,2]],"ltp":28.0,"tv":2126.48,"id":7445998},{"batl":[[0,1.05,1333.68]],"ltp":1.05,"tv":71605.33,"id":9629022}]}]}
{"op":"mcm","clk":"4228760605","pt":1631463530469,"mc":[{"id":"1.187551081","rc":[{"batl":[[0,34,6.75],[1,36,2],[2,110,2]],"ltp":28.0,"tv":2126.48,"id":7445998},{"batb":[[0,1.03,2375.19]],"batl":[[0,1.04,69.43],[1,1.05,1333.68],[2,1.07,19.91]],"ltp":1.05,"tv":71605.33,"id":9629022}]}]}
{"op":"mcm","clk":"4228760801","pt":1631463531466,"mc":[{"id":"1.187551081","rc":[{"batl":[[2,1.07,14.91]],"ltp":1.05,"tv":71605.33,"id":9629022}]}]}
{"op":"mcm","clk":"4228760976","pt":1631463532381,"mc":[{"id":"1.187551081","rc":[{"batl":[[1,36,25.79],[2,55,21.93]],"ltp":28.0,"tv":2126.48,"id":7445998},{"batb":[[0,1.03,3202.03],[1,1.02,6807.41]],"ltp":1.05,"tv":71605.33,"id":9629022}]}]}
{"op":"mcm","clk":"4228761182","pt":1631463533463,"mc":[{"id":"1.187551081","rc":[{"batb":[[0,24,11.36],[1,23,14.38],[2,13.5,30.73]],"ltp":28.0,"tv":2126.48,"id":7445998},{"batb":[[0,1.03,3650.77]],"ltp":1.05,"tv":71605.33,"id":9629022}]}]}
{"op":"mcm","clk":"4228761567","pt":1631463535450,"mc":[{"id":"1.187551081","rc":[{"batb":[[2,21,30.49]],"ltp":28.0,"tv":2126.48,"id":7445998},{"trd":[[1.04,4472.37]],"batl":[[0,1.04,61.14],[1,1.05,1943.47],[2,1.06,627.72]],"ltp":1.04,"tv":71615.33,"id":9629022}],"tv":73741.81}]}
{"op":"mcm","clk":"4228762516","pt":1631463540374,"mc":[{"id":"1.187551081","rc":[{"batl":[[0,1.04,97.29],[1,1.05,1894.23]],"ltp":1.04,"tv":71615.33,"id":9629022}]}]}
{"op":"mcm","clk":"4228763187","pt":1631463543583,"mc":[{"id":"1.187551081","rc":[{"batb":[[0,23,14.38],[1,21,30.49],[2,17.5,38.02]],"batl":[[0,36,25.79],[1,55,21.93],[2,110,2]],"ltp":28.0,"tv":2126.48,"id":7445998},{"batb":[[0,1.03,2109.41]],"batl":[[0,1.04,72.29],[1,1.05,609.79]],"ltp":1.04,"tv":71615.33,"id":9629022}]}]}
{"op":"mcm","clk":"4228763267","pt":1631463543992,"mc":[{"id":"1.187551081","rc":[{"batb":[[0,13.5,30.73],[1,11,2],[2,8.6,2]],"batl":[[0,110,2],[1,160,37.59],[2,990,0.01]],"ltp":28.0,"tv":2126.48,"id":7445998},{"batb":[[0,1.02,149.6],[1,1.01,4294.38],[2,1.01,0]],"batl":[[1,1.1,214.95],[2,1.11,235.32]],"ltp":1.04,"tv":71615.33,"id":9629022}]}]}
{"op":"mcm","clk":"4228763789","pt":1631463546589,"mc":[{"id":"1.187551081","rc":[{"trd":[[26,8.03]],"batl":[[1,990,0.01],[2,990,0]],"ltp":26.0,"tv":2128.96,"id":7445998},{"trd":[[1.04,4534.36]],"batl":[[0,1.04,10.29]],"ltp":1.04,"tv":71677.33,"id":9629022}],"tv":73806.29}]}
{"op":"mcm","clk":"4228764346","pt":1631463549421,"mc":[{"id":"1.187551081","rc":[{"trd":[[1.04,4554.94]],"batb":[[0,1.04,1288.5],[1,1.02,149.6],[2,1.01,4294.38]],"batl":[[0,1.05,500.26],[1,1.06,776.77],[2,1.1,214.95]],"ltp":1.04,"tv":71697.9,"id":9629022}],"tv":73826.87}]}
{"op":"mcm","clk":"4228764780","pt":1631463551593,"mc":[{"id":"1.187551081","rc":[{"batb":[[0,18.5,13.51],[1,13.5,30.73],[2,11,2]],"batl":[[0,29,8.32],[1,95,39.2],[2,110,2]],"ltp":26.0,"tv":2128.96,"id":7445998},{"batb":[[1,1.02,159.6]],"ltp":1.04,"tv":71697.9,"id":9629022}]}]}
{"op":"mcm","clk":"4228764915","pt":1631463552301,"mc":[{"id":"1.187551081","rc":[{"batl":[[0,1.05,624.19]],"ltp":1.04,"tv":71697.9,"id":9629022}]}]}
{"op":"mcm","clk":"4228765287","pt":1631463554123,"mc":[{"id":"1.187551081","rc":[{"batb":[[0,1.04,2200.02]],"ltp":1.04,"tv":71697.9,"id":9629022}]}]}
{"op":"mcm","clk":"4228765766","pt":1631463556619,"mc":[{"id":"1.187551081","rc":[{"batb":[[0,1.04,913.52]],"batl":[[0,1.1,214.95],[1,1.11,235.32],[2,1.12,195.71]],"ltp":1.04,"tv":71697.9,"id":9629022}]}]}
{"op":"mcm","clk":"4228765863","pt":1631463557106,"mc":[{"id":"1.187551081","rc":[{"batb":[[0,1.04,12]],"ltp":1.04,"tv":71697.9,"id":9629022}]}]}
{"op":"mcm","clk":"4228766271","pt":1631463559246,"mc":[{"id":"1.187551081","rc":[{"batb":[[2,1.01,5629.68]],"batl":[[0,1.08,261.56],[1,1.09,978.13],[2,1.1,214.95]],"ltp":1.04,"tv":71697.9,"id":9629022}]}]}
{"op":"mcm","clk":"4228766477","pt":1631463560355,"mc":[{"id":"1.187551081","rc":[{"batb":[[0,13.5,30.73],[1,11,2],[2,8.6,2]],"batl":[[0,95,39.2],[1,110,2],[2,990,0.01]],"ltp":26.0,"tv":2128.96,"id":7445998},{"batb":[[0,1.02,159.6],[1,1.01,5629.68],[2,1.01,0]],"ltp":1.04,"tv":71697.9,"id":9629022}]}]}
{"op":"mcm","clk":"4228766934","pt":1631463562631,"mc":[{"id":"1.187551081","rc":[{"batl":[[0,110,2],[1,990,0.01],[2,990,0]],"ltp":26.0,"tv":2128.96,"id":7445998}]}]}
{"op":"mcm","clk":"4228767678","pt":1631463566551,"mc":[{"id":"1.187551081","rc":[{"batb":[[0,1.02,3584.31]],"ltp":1.04,"tv":71697.9,"id":9629022}]}]}
{"op":"mcm","clk":"4228767933","pt":1631463567848,"mc":[{"id":"1.187551081","rc":[{"batb":[[0,1.02,3594.31]],"ltp":1.04,"tv":71697.9,"id":9629022}]}]}
{"op":"mcm","clk":"4228768845","pt":1631463572466,"mc":[{"id":"1.187551081","rc":[{"batl":[[0,1.1,214.95],[1,1.11,38.82],[2,1.13,11.86]],"ltp":1.04,"tv":71697.9,"id":9629022}]}]}
{"op":"mcm","clk":"4228768901","pt":1631463572756,"mc":[{"id":"1.187551081","rc":[{"batb":[[0,1.02,169.6]],"ltp":1.04,"tv":71697.9,"id":9629022}]}]}
{"op":"mcm","clk":"4228769248","pt":1631463574564,"mc":[{"id":"1.187551081","rc":[{"batb":[[0,1.02,25]],"ltp":1.04,"tv":71697.9,"id":9629022}]}]}
{"op":"mcm","clk":"4228769433","pt":1631463575451,"mc":[{"id":"1.187551081","rc":[{"trd":[[1.02,3017.18]],"batb":[[0,1.01,5629.68],[1,1.01,0]],"batl":[[0,1.02,1297.21],[1,1.03,61.98],[2,1.05,15.19]],"ltp":1.02,"tv":71747.9,"id":9629022}],"tv":73876.87}]}
{"op":"mcm","clk":"4228769623","pt":1631463576225,"mc":[{"id":"1.187551081","rc":[{"batb":[[0,23,15.31]],"ltp":26.0,"tv":2128.96,"id":7445998}]}]}
{"op":"mcm","clk":"4228770050","pt":1631463578543,"mc":[{"id":"1.187551081","rc":[{"batb":[[0,55,4.55],[1,23,15.31],[2,11,2]],"batl":[[0,90,2.78],[1,110,2],[2,990,0.01]],"ltp":26.0,"tv":2128.96,"id":7445998},{"trd":[[1.02,3230.68]],"batb":[[0,1.01,5877.2]],"batl":[[0,1.02,1460.56]],"ltp":1.02,"tv":71961.4,"id":9629022}],"tv":74090.37}]}
{"op":"mcm","clk":"4228770270","pt":1631463579647,"mc":[{"id":"1.187551081","rc":[{"batb":[[0,1.01,4431.19]],"ltp":1.02,"tv":71961.4,"id":9629022}]}]}
{"op":"mcm","clk":"4228770372","pt":1631463580145,"mc":[{"id":"1.187551081","rc":[{"batb":[[0,1.01,4946.13]],"ltp":1.02,"tv":71961.4,"id":9629022}]}]}
{"op":"mcm","clk":"4228770655","pt":1631463581475,"mc":[{"id":"1.187551081","rc":[{"batb":[[2,21,2]],"ltp":26.0,"tv":2128.96,"id":7445998},{"batl":[[2,1.05,525.09]],"ltp":1.02,"tv":71961.4,"id":9629022}]}]}
{"op":"mcm","clk":"4228770767","pt":1631463581960,"mc":[{"id":"1.187551081","rc":[{"batl":[[0,1.02,1567.31]],"ltp":1.02,"tv":71961.4,"id":9629022}]}]}
{"op":"mcm","clk":"4228771014","pt":1631463583143,"mc":[{"id":"1.187551081","rc":[{"trd":[[55,8]],"batb":[[0,23,15.86],[1,21,2],[2,15,2]],"ltp":55.0,"tv":2136.96,"id":7445998}],"tv":74098.37}]}
{"op":"mcm","clk":"4228771541","pt":1631463585974,"mc":[{"id":"1.187551081","rc":[{"trd":[[1.02,3250.68]],"batl":[[0,1.02,1557.31]],"ltp":1.02,"tv":71981.4,"id":9629022}],"tv":74118.37}]}
{"op":"mcm","clk":"4228771734","pt":1631463586879,"mc":[{"id":"1.187551081","rc":[{"batl":[[1,1.05,525.09],[2,1.06,370.25]],"ltp":1.02,"tv":71981.4,"id":9629022}]}]}
{"op":"mcm","clk":"4228772667","pt":1631463591552,"mc":[{"id":"1.187551081","rc":[{"trd":[[1.01,1346]],"batb":[[0,1.01,4846.13]],"ltp":1.01,"tv":72181.4,"id":9629022}],"tv":74318.37}]}
{"op":"mcm","clk":"4228773029","pt":1631463593455,"mc":[{"id":"1.187551081","rc":[{"trd":[[1.01,1656.88],[1.02,3255.02]],"batb":[[0,1.01,4690.69]],"batl":[[0,1.02,1555.14]],"ltp":1.02,"tv":72496.62,"id":9629022}],"tv":74633.58}]}
{"op":"mcm","clk":"4228773497","pt":1631463596085,"mc":[{"id":"1.187551081","rc":[{"batb":[[0,23,15.31]],"ltp":55.0,"tv":2136.96,"id":7445998}]}]}
{"op":"mcm","clk":"4228773854","pt":1631463598085,"mc":[{"id":"1.187551081","rc":[{"batl":[[1,1.04,5],[2,1.05,525.09]],"ltp":1.02,"tv":72496.62,"id":9629022}]}]}
{"op":"mcm","clk":"4228774242","pt":1631463600305,"mc":[{"id":"1.187551081","rc":[{"batb":[[0,50,5],[1,23,15.31],[2,21,2]],"ltp":55.0,"tv":2136.96,"id":7445998}]}]}
{"op":"mcm","clk":"4228774445","pt":1631463601293,"mc":[{"id":"1.187551081","rc":[{"batb":[[0,23,15.31],[1,15,2],[2,4.6,371.92]],"batl":[[0,990,0.01],[1,110,0],[2,990,0]],"ltp":55.0,"tv":2136.96,"id":7445998},{"batb":[[0,1.02,1.38]],"batl":[[0,1.04,5],[1,1.07,335.5],[2,1.11,58.22]],"ltp":1.02,"tv":72496.62,"id":9629022}]}]}
{"op":"mcm","clk":"4228774801","pt":1631463602941,"mc":[{"id":"1.187551081","rc":[{"batb":[[2,1.01,30]],"ltp":55.0,"tv":2136.96,"id":7445998}]}]}
{"op":"mcm","clk":"4228775100","pt":1631463604522,"mc":[{"id":"1.187551081","rc":[{"batb":[[1,21,2],[2,15,2]],"ltp":55.0,"tv":2136.96,"id":7445998},{"batl":[[1,1.05,1797.94],[2,1.06,415.75]],"ltp":1.02,"tv":72496.62,"id":9629022}]}]}
{"op":"mcm","clk":"4228775151","pt":1631463604797,"mc":[{"id":"1.187551081","rc":[{"batb":[[1,15,2],[2,1.01,30]],"ltp":55.0,"tv":2136.96,"id":7445998},{"batl":[[1,1.05,1284.44],[2,1.07,335.5]],"ltp":1.02,"tv":72496.62,"id":9629022}]}]}
{"op":"mcm","clk":"4228777513","pt":1631463617124,"mc":[{"id":"1.187551081","rc":[{"batl":[[1,1.07,335.5],[2,1.08,20]],"ltp":1.02,"tv":72496.62,"id":9629022}]}]}
{"op":"mcm","clk":"4228777808","pt":1631463618664,"mc":[{"id":"1.187551081","rc":[{"batb":[[0,20,2],[1,19.5,2],[2,15,2]],"ltp":55.0,"tv":2136.96,"id":7445998}]}]}
{"op":"mcm","clk":"4228777865","pt":1631463619018,"mc":[{"id":"1.187551081","rc":[{"batb":[[0,15,2],[1,1.01,30],[2,15,0]],"ltp":55.0,"tv":2136.96,"id":7445998},{"batl":[[1,1.05,464.5],[2,1.06,474.75]],"ltp":1.02,"tv":72496.62,"id":9629022}]}]}
{"op":"mcm","clk":"4228778465","pt":1631463621665,"mc":[{"id":"1.187551081","rc":[{"batb":[[0,1.01,30],[1,1.01,0]],"ltp":55.0,"tv":2136.96,"id":7445998},{"trd":[[1.02,3257.77]],"batl":[[0,1.01,4742.84],[1,1.04,5],[2,1.08,20]],"ltp":1.02,"tv":72499.37,"id":9629022}],"tv":74636.33}]}
{"op":"mcm","clk":"4228778856","pt":1631463623537,"mc":[{"id":"1.187551081","marketDefinition":{"bspMarket":false,"turnInPlayEnabled":true,"persistenceEnabled":true,"marketBaseRate":5.0,"eventId":"30895117","eventTypeId":"2","numberOfWinners":1,"bettingType":"ODDS","marketType":"MATCH_ODDS","marketTime":"2021-09-12T15:00:00.000Z","suspendTime":"2021-09-12T15:00:00.000Z","bspReconciled":false,"complete":true,"inPlay":true,"crossMatching":true,"runnersVoidable":false,"numberOfActiveRunners":2,"betDelay":3,"status":"SUSPENDED","runners":[{"status":"ACTIVE","sortPriority":1,"id":7445998,"name":"Ekaterina Yashina"},{"status":"ACTIVE","sortPriority":2,"id":9629022,"name":"Susan Bandecchi"}],"regulators":["MR_INT"],"discountAllowed":true,"timezone":"UTC","openDate":"2021-09-12T15:00:00.000Z","version":4029083011,"name":"Match Odds","eventName":"Eka Yashina v Bandecchi"}}]}
{"op":"mcm","clk":"4228779046","pt":1631463624607,"mc":[{"id":"1.187551081","rc":[{"batl":[[1,1.11,58.22],[2,990,0.01]],"ltp":1.02,"tv":72499.37,"id":9629022}]}]}
{"op":"mcm","clk":"4228787134","pt":1631463668535,"mc":[{"id":"1.187551081","tv":0.0}]}
{"op":"mcm","clk":"4228787387","pt":1631463669930,"mc":[{"id":"1.187551081","marketDefinition":{"bspMarket":false,"turnInPlayEnabled":true,"persistenceEnabled":true,"marketBaseRate":5.0,"eventId":"30895117","eventTypeId":"2","numberOfWinners":1,"bettingType":"ODDS","marketType":"MATCH_ODDS","marketTime":"2021-09-12T15:00:00.000Z","suspendTime":"2021-09-12T15:00:00.000Z","bspReconciled":false,"complete":true,"inPlay":true,"crossMatching":false,"runnersVoidable":false,"numberOfActiveRunners":0,"betDelay":3,"status":"CLOSED","settledTime":"2021-09-12T16:20:56.000Z","runners":[{"status":"LOSER","sortPriority":1,"id":7445998,"name":"Ekaterina Yashina"},{"status":"WINNER","sortPriority":2,"id":9629022,"name":"Susan Bandecchi"}],"regulators":["MR_INT"],"discountAllowed":true,"timezone":"UTC","openDate":"2021-09-12T15:00:00.000Z","version":4029086149,"name":"Match Odds","eventName":"Eka Yashina v Bandecchi"}}]}
