{"op":"mcm","clk":"4222353741","pt":1631442186603,"mc":[{"id":"1.187552834","marketDefinition":{"bspMarket":false,"turnInPlayEnabled":true,"persistenceEnabled":true,"marketBaseRate":5.0,"eventId":"30895331","eventTypeId":"2","numberOfWinners":1,"bettingType":"ODDS","marketType":"MATCH_ODDS","marketTime":"2021-09-12T10:30:00.000Z","suspendTime":"2021-09-12T10:30:00.000Z","bspReconciled":false,"complete":true,"inPlay":false,"crossMatching":false,"runnersVoidable":false,"numberOfActiveRunners":2,"betDelay":0,"status":"OPEN","runners":[{"status":"ACTIVE","sortPriority":1,"id":8679184,"name":"I Rosca"},{"status":"ACTIVE","sortPriority":2,"id":14039549,"name":"L Pulchartova"}],"regulators":["MR_INT"],"countryCode":"GB","discountAllowed":false,"timezone":"GMT","openDate":"2021-09-12T10:30:00.000Z","version":4027747949,"name":"Match Odds","eventName":"I Rosca v L Pulchartova"},"rc":[{"batb":[[0,1.01,25]],"ltp":0.0,"tv":0.0,"id":14039549},{"batb":[[0,1.01,25]],"ltp":0.0,"tv":0.0,"id":8679184}]}]}
{"op":"mcm","clk":"4222354007","pt":1631442188275,"mc":[{"id":"1.187552834","marketDefinition":{"bspMarket":false,"turnInPlayEnabled":true,"persistenceEnabled":true,"marketBaseRate":5.0,"eventId":"30895331","eventTypeId":"2","numberOfWinners":1,"bettingType":"ODDS","marketType":"MATCH_ODDS","marketTime":"2021-09-12T10:30:00.000Z","suspendTime":"2021-09-12T10:30:00.000Z","bspReconciled":false,"complete":true,"inPlay":false,"crossMatching":false,"runnersVoidable":false,"numberOfActiveRunners":2,"betDelay":0,"status":"OPEN","runners":[{"status":"ACTIVE","sortPriority":1,"id":8679184,"name":"I Rosca"},{"status":"ACTIVE","sortPriority":2,"id":14039549,"name":"L Pulchartova"}],"regulators":["MR_INT"],"countryCode":"GB","discountAllowed":true,"timezone":"GMT","openDate":"2021-09-12T10:30:00.000Z","version":4027747949,"name":"Match Odds","eventName":"I Rosca v L Pulchartova"}}]}
{"op":"mcm","clk":"4222432170","pt":1631442608180,"mc":[{"id":"1.187552834","rc":[{"batb":[[0,1.01,7]],"ltp":0.0,"tv":0.0,"id":14039549},{"batb":[[0,1.01,7]],"ltp":0.0,"tv":0.0,"id":8679184}]}]}
{"op":"mcm","clk":"4222444418","pt":1631442673034,"mc":[{"id":"1.187552834","marketDefinition":{"bspMarket":false,"turnInPlayEnabled":true,"persistenceEnabled":true,"marketBaseRate":5.0,"eventId":"30895331","eventTypeId":"2","numberOfWinners":1,"bettingType":"ODDS","marketType":"MATCH_ODDS","marketTime":"2021-09-12T10:30:00.000Z","suspendTime":"2021-09-12T10:30:00.000Z","bspReconciled":false,"complete":true,"inPlay":true,"crossMatching":false,"runnersVoidable":false,"numberOfActiveRunners":2,"betDelay":5,"status":"OPEN","runners":[{"status":"ACTIVE","sortPriority":1,"id":8679184,"name":"I Rosca"},{"status":"ACTIVE","sortPriority":2,"id":14039549,"name":"L Pulchartova"}],"regulators":["MR_INT"],"countryCode":"GB","discountAllowed":true,"timezone":"GMT","openDate":"2021-09-12T10:30:00.000Z","version":4027768250,"name":"Match Odds","eventName":"I Rosca v L Pulchartova"}}]}
{"op":"mcm","clk":"4222500601","pt":1631442983826,"mc":[{"id":"1.187552834","marketDefinition":{"bspMarket":false,"turnInPlayEnabled":true,"persistenceEnabled":true,"marketBaseRate":5.0,"eventId":"30895331","eventTypeId":"2","numberOfWinners":1,"bettingType":"ODDS","marketType":"MATCH_ODDS","marketTime":"2021-09-12T10:36:23.000Z","suspendTime":"2021-09-12T10:36:23.000Z","bspReconciled":false,"complete":true,"inPlay":true,"crossMatching":false,"runnersVoidable":false,"numberOfActiveRunners":2,"betDelay":5,"status":"OPEN","runners":[{"status":"ACTIVE","sortPriority":1,"id":8679184,"name":"I Rosca"},{"status":"ACTIVE","sortPriority":2,"id":14039549,"name":"L Pulchartova"}],"regulators":["MR_INT"],"countryCode":"GB","discountAllowed":true,"timezone":"GMT","openDate":"2021-09-12T10:30:00.000Z","version":4027777578,"name":"Match Odds","eventName":"I Rosca v L Pulchartova"}}]}
{"op":"mcm","clk":"4222501141","pt":1631442986877,"mc":[{"id":"1.187552834","marketDefinition":{"bspMarket":false,"turnInPlayEnabled":true,"persistenceEnabled":true,"marketBaseRate":5.0,"eventId":"30895331","eventTypeId":"2","numberOfWinners":1,"bettingType":"ODDS","marketType":"MATCH_ODDS","marketTime":"2021-09-12T10:36:23.000Z","suspendTime":"2021-09-12T10:36:23.000Z","bspReconciled":false,"complete":true,"inPlay":true,"crossMatching":false,"runnersVoidable":false,"numberOfActiveRunners":2,"betDelay":5,"status":"OPEN","runners":[{"status":"ACTIVE","sortPriority":1,"id":8679184,"name":"I Rosca"},{"status":"ACTIVE","sortPriority":2,"id":14039549,"name":"L Pulchartova"}],"regulators":["MR_INT"],"countryCode":"GB","discountAllowed":true,"timezone":"GMT","openDate":"2021-09-12T10:36:23.000Z","version":4027777578,"name":"Match Odds","eventName":"I Rosca v L Pulchartova"}}]}
{"op":"mcm","clk":"4222550312","pt":1631443275477,"mc":[{"id":"1.187552834","rc":[{"batb":[[0,1.16,585.63],[1,1.01,7]],"batl":[[0,1.58,661.3]],"ltp":0.0,"tv":0.0,"id":8679184}]}]}
{"op":"mcm","clk":"4222553036","pt":1631443291506,"mc":[{"id":"1.187552834","rc":[{"batb":[[0,1.01,7],[1,1.01,0]],"ltp":0.0,"tv":0.0,"id":8679184}]}]}
{"op":"mcm","clk":"4222554163","pt":1631443297841,"mc":[{"id":"1.187552834","rc":[{"batb":[[0,1.2,539.61],[1,1.01,7]],"ltp":0.0,"tv":0.0,"id":8679184}]}]}
{"op":"mcm","clk":"4222554313","pt":1631443298518,"mc":[{"id":"1.187552834","marketDefinition":{"bspMarket":false,"turnInPlayEnabled":true,"persistenceEnabled":true,"marketBaseRate":5.0,"eventId":"30895331","eventTypeId":"2","numberOfWinners":1,"bettingType":"ODDS","marketType":"MATCH_ODDS","marketTime":"2021-09-12T10:36:23.000Z","suspendTime":"2021-09-12T10:36:23.000Z","bspReconciled":false,"complete":true,"inPlay":true,"crossMatching":true,"runnersVoidable":false,"numberOfActiveRunners":2,"betDelay":5,"status":"OPEN","runners":[{"status":"ACTIVE","sortPriority":1,"id":8679184,"name":"I Rosca"},{"status":"ACTIVE","sortPriority":2,"id":14039549,"name":"L Pulchartova"}],"regulators":["MR_INT"],"countryCode":"GB","discountAllowed":true,"timezone":"GMT","openDate":"2021-09-12T10:36:23.000Z","version":4027777578,"name":"Match Odds","eventName":"I Rosca v L Pulchartova"}}]}
{"op":"mcm","clk":"4222557284","pt":1631443314991,"mc":[{"id":"1.187552834","rc":[{"batb":[[0,1.01,7],[1,1.01,0]],"ltp":0.0,"tv":0.0,"id":8679184}]}]}
{"op":"mcm","clk":"4222558506","pt":1631443321541,"mc":[{"id":"1.187552834","rc":[{"batb":[[0,1.22,531.62],[1,1.01,7]],"ltp":0.0,"tv":0.0,"id":8679184}]}]}
{"op":"mcm","clk":"4222583860","pt":1631443462672,"mc":[{"id":"1.187552834","rc":[{"batb":[[0,1.01,7],[1,1.01,0]],"ltp":0.0,"tv":0.0,"id":8679184}]}]}
{"op":"mcm","clk":"4222584999","pt":1631443468951,"mc":[{"id":"1.187552834","rc":[{"batb":[[0,1.18,558.78],[1,1.01,7]],"ltp":0.0,"tv":0.0,"id":8679184}]}]}
{"op":"mcm","clk":"4222587735","pt":1631443483887,"mc":[{"id":"1.187552834","rc":[{"batb":[[0,1.01,7],[1,1.01,0]],"ltp":0.0,"tv":0.0,"id":8679184}]}]}
{"op":"mcm","clk":"4222618119","pt":1631443661632,"mc":[{"id":"1.187552834","rc":[{"batb":[[0,1.16,585.63],[1,1.01,7]],"batl":[[0,1.58,661.3]],"ltp":0.0,"tv":0.0,"id":8679184}]}]}
{"op":"mcm","clk":"4222620638","pt":1631443677784,"mc":[{"id":"1.187552834","rc":[{"batb":[[0,1.01,7],[1,1.01,0]],"ltp":0.0,"tv":0.0,"id":8679184}]}]}
{"op":"mcm","clk":"4222621682","pt":1631443683976,"mc":[{"id":"1.187552834","rc":[{"batb":[[0,1.14,620.51],[1,1.01,7]],"ltp":0.0,"tv":0.0,"id":8679184}]}]}
{"op":"mcm","clk":"4222626751","pt":1631443716540,"mc":[{"id":"1.187552834","rc":[{"batb":[[0,1.01,7],[1,1.01,0]],"ltp":0.0,"tv":0.0,"id":8679184}]}]}
{"op":"mcm","clk":"4222627708","pt":1631443722527,"mc":[{"id":"1.187552834","rc":[{"batb":[[0,1.12,661.06],[1,1.01,7]],"batl":[[0,1.51,753.29]],"ltp":0.0,"tv":0.0,"id":8679184}]}]}
{"op":"mcm","clk":"4222632569","pt":1631443753359,"mc":[{"id":"1.187552834","rc":[{"batb":[[0,1.01,7],[1,1.01,0]],"ltp":0.0,"tv":0.0,"id":8679184}]}]}
{"op":"mcm","clk":"4222633409","pt":1631443758970,"mc":[{"id":"1.187552834","rc":[{"batb":[[0,1.14,620.51],[1,1.01,7]],"ltp":0.0,"tv":0.0,"id":8679184}]}]}
{"op":"mcm","clk":"4222634425","pt":1631443765585,"mc":[{"id":"1.187552834","rc":[{"batb":[[0,1.01,7],[1,1.01,0]],"ltp":0.0,"tv":0.0,"id":8679184}]}]}
{"op":"mcm","clk":"4222637908","pt":1631443789512,"mc":[{"id":"1.187552834","rc":[{"batb":[[0,1.1,735.13],[1,1.01,7]],"batl":[[0,1.48,797.87]],"ltp":0.0,"tv":0.0,"id":8679184}]}]}
{"op":"mcm","clk":"4222641686","pt":1631443815463,"mc":[{"id":"1.187552834","rc":[{"batb":[[0,1.01,7],[1,1.01,0]],"ltp":0.0,"tv":0.0,"id":8679184}]}]}
{"op":"mcm","clk":"4222642624","pt":1631443821783,"mc":[{"id":"1.187552834","rc":[{"batb":[[0,1.14,620.51],[1,1.01,7]],"ltp":0.0,"tv":0.0,"id":8679184}]}]}
{"op":"mcm","clk":"4222647776","pt":1631443857237,"mc":[{"id":"1.187552834","rc":[{"batb":[[0,1.01,7],[1,1.01,0]],"ltp":0.0,"tv":0.0,"id":8679184}]}]}
{"op":"mcm","clk":"4222648690","pt":1631443863433,"mc":[{"id":"1.187552834","rc":[{"batb":[[0,1.16,585.63],[1,1.01,7]],"ltp":0.0,"tv":0.0,"id":8679184}]}]}
{"op":"mcm","clk":"4222652867","pt":1631443893890,"mc":[{"id":"1.187552834","rc":[{"batb":[[0,1.01,7],[1,1.01,0]],"ltp":0.0,"tv":0.0,"id":8679184}]}]}
{"op":"mcm","clk":"4222653643","pt":1631443899991,"mc":[{"id":"1.187552834","rc":[{"batb":[[0,1.18,558.78],[1,1.01,7]],"ltp":0.0,"tv":0.0,"id":8679184}]}]}
{"op":"mcm","clk":"4222657993","pt":1631443932701,"mc":[{"id":"1.187552834","rc":[{"batb":[[0,1.01,7],[1,1.01,0]],"ltp":0.0,"tv":0.0,"id":8679184}]}]}
{"op":"mcm","clk":"4222658736","pt":1631443938414,"mc":[{"id":"1.187552834","rc":[{"batb":[[0,1.2,539.61],[1,1.01,7]],"batl":[[0,1.66,589.37]],"ltp":0.0,"tv":0.0,"id":8679184}]}]}
{"op":"mcm","clk":"4222668517","pt":1631444011226,"mc":[{"id":"1.187552834","rc":[{"batb":[[0,1.01,7],[1,1.01,0]],"ltp":0.0,"tv":0.0,"id":8679184}]}]}
{"op":"mcm","clk":"4222669353","pt":1631444017542,"mc":[{"id":"1.187552834","rc":[{"batb":[[0,1.16,585.63],[1,1.01,7]],"batl":[[0,1.58,661.3]],"ltp":0.0,"tv":0.0,"id":8679184}]}]}
{"op":"mcm","clk":"4222671490","pt":1631444032694,"mc":[{"id":"1.187552834","rc":[{"batb":[[0,1.01,7],[1,1.01,0]],"ltp":0.0,"tv":0.0,"id":8679184}]}]}
{"op":"mcm","clk":"4222672418","pt":1631444038994,"mc":[{"id":"1.187552834","rc":[{"batb":[[0,1.2,539.61],[1,1.01,7]],"ltp":0.0,"tv":0.0,"id":8679184}]}]}
{"op":"mcm","clk":"4222676354","pt":1631444065339,"mc":[{"id":"1.187552834","rc":[{"batb":[[0,1.01,7],[1,1.01,0]],"ltp":0.0,"tv":0.0,"id":8679184}]}]}
{"op":"mcm","clk":"4222677237","pt":1631444071425,"mc":[{"id":"1.187552834","rc":[{"batb":[[0,1.23,524.99],[1,1.01,7]],"ltp":0.0,"tv":0.0,"id":8679184}]}]}
{"op":"mcm","clk":"4222680060","pt":1631444090740,"mc":[{"id":"1.187552834","rc":[{"batb":[[0,1.01,7],[1,1.01,0]],"ltp":0.0,"tv":0.0,"id":8679184}]}]}
{"op":"mcm","clk":"4222681042","pt":1631444096767,"mc":[{"id":"1.187552834","rc":[{"batb":[[0,1.28,493.9],[1,1.01,7]],"batl":[[0,1.82,476.84]],"ltp":0.0,"tv":0.0,"id":8679184}]}]}
{"op":"mcm","clk":"4222687572","pt":1631444140640,"mc":[{"id":"1.187552834","rc":[{"batb":[[0,1.01,7],[1,1.01,0]],"ltp":0.0,"tv":0.0,"id":8679184}]}]}
{"op":"mcm","clk":"4222688350","pt":1631444146329,"mc":[{"id":"1.187552834","rc":[{"batb":[[0,1.23,524.99],[1,1.01,7]],"batl":[[0,1.73,536.26]],"ltp":0.0,"tv":0.0,"id":8679184}]}]}
{"op":"mcm","clk":"4222690537","pt":1631444162054,"mc":[{"id":"1.187552834","rc":[{"batb":[[0,1.01,7],[1,1.01,0]],"ltp":0.0,"tv":0.0,"id":8679184}]}]}
{"op":"mcm","clk":"4222691389","pt":1631444167655,"mc":[{"id":"1.187552834","rc":[{"batb":[[0,1.2,539.61],[1,1.01,7]],"batl":[[0,1.66,589.37]],"ltp":0.0,"tv":0.0,"id":8679184}]}]}
{"op":"mcm","clk":"4222694623","pt":1631444190485,"mc":[{"id":"1.187552834","rc":[{"batb":[[0,1.01,7],[1,1.01,0]],"ltp":0.0,"tv":0.0,"id":8679184}]}]}
{"op":"mcm","clk":"4222695412","pt":1631444195893,"mc":[{"id":"1.187552834","rc":[{"batb":[[0,1.16,585.63],[1,1.01,7]],"batl":[[0,1.58,661.3]],"ltp":0.0,"tv":0.0,"id":8679184}]}]}
{"op":"mcm","clk":"4222699713","pt":1631444226078,"mc":[{"id":"1.187552834","rc":[{"batb":[[0,1.01,7],[1,1.01,0]],"ltp":0.0,"tv":0.0,"id":8679184}]}]}
{"op":"mcm","clk":"4222700658","pt":1631444232338,"mc":[{"id":"1.187552834","rc":[{"batb":[[0,1.2,539.61],[1,1.01,7]],"ltp":0.0,"tv":0.0,"id":8679184}]}]}
{"op":"mcm","clk":"4222704051","pt":1631444255586,"mc":[{"id":"1.187552834","rc":[{"batb":[[0,1.01,7],[1,1.01,0]],"ltp":0.0,"tv":0.0,"id":8679184}]}]}
{"op":"mcm","clk":"4222704886","pt":1631444261593,"mc":[{"id":"1.187552834","rc":[{"batb":[[0,1.25,513.42],[1,1.01,7]],"batl":[[0,1.77,508.86]],"ltp":0.0,"tv":0.0,"id":8679184}]}]}
{"op":"mcm","clk":"4222707482","pt":1631444280968,"mc":[{"id":"1.187552834","rc":[{"batb":[[0,1.01,7],[1,1.01,0]],"ltp":0.0,"tv":0.0,"id":8679184}]}]}
{"op":"mcm","clk":"4222708432","pt":1631444287956,"mc":[{"id":"1.187552834","rc":[{"batb":[[0,1.2,539.61],[1,1.01,7]],"batl":[[0,1.66,589.37]],"ltp":0.0,"tv":0.0,"id":8679184}]}]}
{"op":"mcm","clk":"4222713603","pt":1631444324589,"mc":[{"id":"1.187552834","rc":[{"batb":[[0,1.01,7],[1,1.01,0]],"ltp":0.0,"tv":0.0,"id":8679184}]}]}
{"op":"mcm","clk":"4222714532","pt":1631444330322,"mc":[{"id":"1.187552834","rc":[{"batb":[[0,1.16,585.63],[1,1.01,7]],"batl":[[0,1.58,661.3]],"ltp":0.0,"tv":0.0,"id":8679184}]}]}
{"op":"mcm","clk":"4222717605","pt":1631444350920,"mc":[{"id":"1.187552834","rc":[{"batb":[[0,1.01,7],[1,1.01,0]],"ltp":0.0,"tv":0.0,"id":8679184}]}]}
{"op":"mcm","clk":"4222718477","pt":1631444356555,"mc":[{"id":"1.187552834","rc":[{"batb":[[0,1.12,661.06],[1,1.01,7]],"batl":[[0,1.51,753.29]],"ltp":0.0,"tv":0.0,"id":8679184}]}]}
{"op":"mcm","clk":"4222722611","pt":1631444379387,"mc":[{"id":"1.187552834","rc":[{"batb":[[0,1.01,7],[1,1.01,0]],"ltp":0.0,"tv":0.0,"id":8679184}]}]}
{"op":"mcm","clk":"4222723375","pt":1631444384787,"mc":[{"id":"1.187552834","rc":[{"batb":[[0,1.14,620.51],[1,1.01,7]],"ltp":0.0,"tv":0.0,"id":8679184}]}]}
{"op":"mcm","clk":"4222724347","pt":1631444391516,"mc":[{"id":"1.187552834","rc":[{"batb":[[0,1.01,7],[1,1.01,0]],"ltp":0.0,"tv":0.0,"id":8679184}]}]}
{"op":"mcm","clk":"4222725129","pt":1631444396894,"mc":[{"id":"1.187552834","rc":[{"batb":[[0,1.1,735.13],[1,1.01,7]],"ltp":0.0,"tv":0.0,"id":8679184}]}]}
{"op":"mcm","clk":"4222729576","pt":1631444421960,"mc":[{"id":"1.187552834","rc":[{"batb":[[0,1.01,7],[1,1.01,0]],"ltp":0.0,"tv":0.0,"id":8679184}]}]}
{"op":"mcm","clk":"4222730858","pt":1631444428450,"mc":[{"id":"1.187552834","rc":[{"batb":[[0,1.14,620.51],[1,1.01,7]],"ltp":0.0,"tv":0.0,"id":8679184}]}]}
{"op":"mcm","clk":"4222736619","pt":1631444458517,"mc":[{"id":"1.187552834","rc":[{"batb":[[0,1.01,7],[1,1.01,0]],"ltp":0.0,"tv":0.0,"id":8679184}]}]}
{"op":"mcm","clk":"4222737798","pt":1631444464813,"mc":[{"id":"1.187552834","rc":[{"batb":[[0,1.1,735.13],[1,1.01,7]],"ltp":0.0,"tv":0.0,"id":8679184}]}]}
{"op":"mcm","clk":"4222741209","pt":1631444483943,"mc":[{"id":"1.187552834","rc":[{"batb":[[0,1.01,7],[1,1.01,0]],"ltp":0.0,"tv":0.0,"id":8679184}]}]}
{"op":"mcm","clk":"4222742282","pt":1631444490025,"mc":[{"id":"1.187552834","rc":[{"batb":[[0,1.08,814.16],[1,1.01,7]],"batl":[[0,1.44,871.88]],"ltp":0.0,"tv":0.0,"id":8679184}]}]}
{"op":"mcm","clk":"4222743016","pt":1631444493960,"mc":[{"id":"1.187552834","rc":[{"batb":[[0,1.01,7],[1,1.01,0]],"ltp":0.0,"tv":0.0,"id":8679184}]}]}
{"op":"mcm","clk":"4222743293","pt":1631444495240,"mc":[{"id":"1.187552834","rc":[{"batb":[[0,1.01,12]],"ltp":0.0,"tv":0.0,"id":14039549},{"batb":[[0,1.01,12]],"ltp":0.0,"tv":0.0,"id":8679184}]}]}
{"op":"mcm","clk":"4222746063","pt":1631444511290,"mc":[{"id":"1.187552834","rc":[{"batb":[[0,1.06,1010.28],[1,1.01,12]],"batl":[[0,1.41,917.52]],"ltp":0.0,"tv":0.0,"id":8679184}]}]}
{"op":"mcm","clk":"4222761258","pt":1631444598587,"mc":[{"id":"1.187552834","rc":[{"batb":[[0,1.01,12],[1,1.01,0]],"ltp":0.0,"tv":0.0,"id":8679184}]}]}
{"op":"mcm","clk":"4222762291","pt":1631444604404,"mc":[{"id":"1.187552834","rc":[{"batb":[[0,1.06,952.24],[1,1.01,12]],"ltp":0.0,"tv":0.0,"id":8679184}]}]}
{"op":"mcm","clk":"4222765919","pt":1631444626050,"mc":[{"id":"1.187552834","rc":[{"batb":[[0,1.01,12],[1,1.01,0]],"ltp":0.0,"tv":0.0,"id":8679184}]}]}
{"op":"mcm","clk":"4222766995","pt":1631444631972,"mc":[{"id":"1.187552834","rc":[{"batb":[[0,1.05,1087.21],[1,1.01,12]],"ltp":0.0,"tv":0.0,"id":8679184}]}]}
{"op":"mcm","clk":"4222768646","pt":1631444641373,"mc":[{"id":"1.187552834","rc":[{"batb":[[0,1.01,12],[1,1.01,0]],"ltp":0.0,"tv":0.0,"id":8679184}]}]}
{"op":"mcm","clk":"4222769784","pt":1631444647148,"mc":[{"id":"1.187552834","rc":[{"batb":[[0,1.06,1010.28],[1,1.01,12]],"ltp":0.0,"tv":0.0,"id":8679184}]}]}
{"op":"mcm","clk":"4222772230","pt":1631444660591,"mc":[{"id":"1.187552834","rc":[{"batb":[[0,1.01,12],[1,1.01,0]],"ltp":0.0,"tv":0.0,"id":8679184}]}]}
{"op":"mcm","clk":"4222773411","pt":1631444666693,"mc":[{"id":"1.187552834","rc":[{"batb":[[0,1.09,765.47],[1,1.01,12]],"ltp":0.0,"tv":0.0,"id":8679184}]}]}
{"op":"mcm","clk":"4222778687","pt":1631444696211,"mc":[{"id":"1.187552834","rc":[{"batb":[[0,1.01,12],[1,1.01,0]],"ltp":0.0,"tv":0.0,"id":8679184}]}]}
{"op":"mcm","clk":"4222779739","pt":1631444701737,"mc":[{"id":"1.187552834","rc":[{"batb":[[0,1.06,1010.28],[1,1.01,12]],"ltp":0.0,"tv":0.0,"id":8679184}]}]}
{"op":"mcm","clk":"4222785493","pt":1631444731976,"mc":[{"id":"1.187552834","rc":[{"batb":[[0,1.01,12],[1,1.01,0]],"ltp":0.0,"tv":0.0,"id":8679184}]}]}
{"op":"mcm","clk":"4222786661","pt":1631444738290,"mc":[{"id":"1.187552834","rc":[{"batb":[[0,1.1,735.13],[1,1.01,12]],"ltp":0.0,"tv":0.0,"id":8679184}]}]}
{"op":"mcm","clk":"4222789643","pt":1631444754330,"mc":[{"id":"1.187552834","rc":[{"batb":[[0,1.01,12],[1,1.01,0]],"ltp":0.0,"tv":0.0,"id":8679184}]}]}
{"op":"mcm","clk":"4222790834","pt":1631444760547,"mc":[{"id":"1.187552834","rc":[{"batb":[[0,1.06,1010.28],[1,1.01,12]],"ltp":0.0,"tv":0.0,"id":8679184}]}]}
{"op":"mcm","clk":"4222796375","pt":1631444790077,"mc":[{"id":"1.187552834","rc":[{"batb":[[0,1.01,12],[1,1.01,0]],"ltp":0.0,"tv":0.0,"id":8679184}]}]}
{"op":"mcm","clk":"4222797567","pt":1631444796278,"mc":[{"id":"1.187552834","rc":[{"batb":[[0,1.05,1087.21],[1,1.01,12]],"ltp":0.0,"tv":0.0,"id":8679184}]}]}
{"op":"mcm","clk":"4222801032","pt":1631444814498,"mc":[{"id":"1.187552834","rc":[{"batb":[[0,1.01,12],[1,1.01,0]],"ltp":0.0,"tv":0.0,"id":8679184}]}]}
{"op":"mcm","clk":"4222802234","pt":1631444820507,"mc":[{"id":"1.187552834","rc":[{"batb":[[0,1.06,1010.28],[1,1.01,12]],"ltp":0.0,"tv":0.0,"id":8679184}]}]}
{"op":"mcm","clk":"4222804652","pt":1631444832800,"mc":[{"id":"1.187552834","rc":[{"batb":[[0,1.01,12],[1,1.01,0]],"ltp":0.0,"tv":0.0,"id":8679184}]}]}
{"op":"mcm","clk":"4222805842","pt":1631444839041,"mc":[{"id":"1.187552834","rc":[{"batb":[[0,1.1,735.13],[1,1.01,12]],"ltp":0.0,"tv":0.0,"id":8679184}]}]}
{"op":"mcm","clk":"4222813599","pt":1631444881481,"mc":[{"id":"1.187552834","rc":[{"batb":[[0,1.01,12],[1,1.01,0]],"ltp":0.0,"tv":0.0,"id":8679184}]}]}
{"op":"mcm","clk":"4222814770","pt":1631444887680,"mc":[{"id":"1.187552834","rc":[{"batb":[[0,1.06,1010.28],[1,1.01,12]],"ltp":0.0,"tv":0.0,"id":8679184}]}]}
{"op":"mcm","clk":"4222820522","pt":1631444918030,"mc":[{"id":"1.187552834","rc":[{"batb":[[0,1.01,12],[1,1.01,0]],"ltp":0.0,"tv":0.0,"id":8679184}]}]}
{"op":"mcm","clk":"4222821634","pt":1631444923926,"mc":[{"id":"1.187552834","rc":[{"batb":[[0,1.05,1087.21],[1,1.01,12]],"ltp":0.0,"tv":0.0,"id":8679184}]}]}
{"op":"mcm","clk":"4222826839","pt":1631444951594,"mc":[{"id":"1.187552834","rc":[{"batb":[[0,1.01,12],[1,1.01,0]],"ltp":0.0,"tv":0.0,"id":8679184}]}]}
{"op":"mcm","clk":"4222827902","pt":1631444957505,"mc":[{"id":"1.187552834","rc":[{"batb":[[0,1.03,1561.16],[1,1.01,12]],"batl":[[0,1.35,1090.71]],"ltp":0.0,"tv":0.0,"id":8679184}]}]}
{"op":"mcm","clk":"4222830702","pt":1631444973947,"mc":[{"id":"1.187552834","rc":[{"batb":[[0,1.01,12],[1,1.01,0]],"ltp":0.0,"tv":0.0,"id":8679184}]}]}
{"op":"mcm","clk":"4222838830","pt":1631445020062,"mc":[{"id":"1.187552834","rc":[{"batb":[[0,1.02,2183.36],[1,1.01,12]],"ltp":0.0,"tv":0.0,"id":8679184}]}]}
{"op":"mcm","clk":"4222842463","pt":1631445040023,"mc":[{"id":"1.187552834","rc":[{"batb":[[0,1.01,12],[1,1.01,0]],"ltp":0.0,"tv":0.0,"id":8679184}]}]}
{"op":"mcm","clk":"4222843600","pt":1631445046290,"mc":[{"id":"1.187552834","rc":[{"batb":[[0,1.01,4176.78]],"ltp":0.0,"tv":0.0,"id":8679184}]}]}
{"op":"mcm","clk":"4222849421","pt":1631445078601,"mc":[{"id":"1.187552834","rc":[{"batb":[[0,1.01,12]],"ltp":0.0,"tv":0.0,"id":8679184}]}]}
{"op":"mcm","clk":"4222850633","pt":1631445084790,"mc":[{"id":"1.187552834","rc":[{"batb":[[0,1.01,3989.18]],"ltp":0.0,"tv":0.0,"id":8679184}]}]}
{"op":"mcm","clk":"4222872645","pt":1631445202738,"mc":[{"id":"1.187552834","rc":[{"batb":[[0,1.01,12]],"ltp":0.0,"tv":0.0,"id":8679184}]}]}
{"op":"mcm","clk":"4222873615","pt":1631445208329,"mc":[{"id":"1.187552834","rc":[{"batb":[[0,1.02,2183.36],[1,1.01,12]],"ltp":0.0,"tv":0.0,"id":8679184}]}]}
{"op":"mcm","clk":"4222877699","pt":1631445231211,"mc":[{"id":"1.187552834","rc":[{"batb":[[0,1.01,12],[1,1.01,0]],"ltp":0.0,"tv":0.0,"id":8679184}]}]}
{"op":"mcm","clk":"4222878751","pt":1631445236868,"mc":[{"id":"1.187552834","rc":[{"batb":[[0,1.01,3989.18]],"ltp":0.0,"tv":0.0,"id":8679184}]}]}
{"op":"mcm","clk":"4222879250","pt":1631445239399,"mc":[{"id":"1.187552834","rc":[{"batb":[[0,1.01,12]],"ltp":0.0,"tv":0.0,"id":8679184}]}]}
{"op":"mcm","clk":"4222909552","pt":1631445399893,"mc":[{"id":"1.187552834","rc":[{"batl":[[0,1.28,1356.2]],"ltp":0.0,"tv":0.0,"id":8679184}]}]}
{"op":"mcm","clk":"4222989971","pt":1631445767320,"mc":[{"id":"1.187552834","rc":[{"batl":[[0,340,36.48]],"ltp":0.0,"tv":0.0,"id":14039549}]}]}
{"op":"mcm","clk":"4222998523","pt":1631445814006,"mc":[{"id":"1.187552834","rc":[{"batb":[[0,1.01,3989.18]],"ltp":0.0,"tv":0.0,"id":8679184}]}]}
{"op":"mcm","clk":"4222999047","pt":1631445817018,"mc":[{"id":"1.187552834","rc":[{"batl":[[1,11.5,8.68]],"ltp":0.0,"tv":0.0,"id":8679184}]}]}
{"op":"mcm","clk":"4223001522","pt":1631445830303,"mc":[{"id":"1.187552834","rc":[{"batb":[[0,1.01,12]],"ltp":0.0,"tv":0.0,"id":8679184}]}]}
{"op":"mcm","clk":"4223002576","pt":1631445836219,"mc":[{"id":"1.187552834","rc":[{"batl":[[0,170,37.59]],"ltp":0.0,"tv":0.0,"id":14039549}]}]}
{"op":"mcm","clk":"4223010249","pt":1631445876683,"mc":[{"id":"1.187552834","rc":[{"batb":[[0,1.01,3989.18]],"ltp":0.0,"tv":0.0,"id":8679184}]}]}
{"op":"mcm","clk":"4223013877","pt":1631445895194,"mc":[{"id":"1.187552834","rc":[{"batb":[[0,1.01,12]],"ltp":0.0,"tv":0.0,"id":8679184}]}]}
{"op":"mcm","clk":"4223019899","pt":1631445924151,"mc":[{"id":"1.187552834","rc":[{"batl":[[0,340,36.48]],"ltp":0.0,"tv":0.0,"id":14039549}]}]}
{"op":"mcm","clk":"4223066191","pt":1631446164738,"mc":[{"id":"1.187552834","rc":[{"batl":[[0,1.25,50.39],[1,1.28,1356.2],[2,11.5,8.68]],"ltp":0.0,"tv":0.0,"id":8679184}]}]}
{"op":"mcm","clk":"4223075299","pt":1631446208731,"mc":[{"id":"1.187552834","rc":[{"batl":[[0,1.28,1356.2],[1,11.5,8.68],[2,11.5,0]],"ltp":0.0,"tv":0.0,"id":8679184}]}]}
{"op":"mcm","clk":"4223077171","pt":1631446217130,"mc":[{"id":"1.187552834","rc":[{"batb":[[0,1.01,3989.18]],"ltp":0.0,"tv":0.0,"id":8679184}]}]}
{"op":"mcm","clk":"4223083015","pt":1631446246496,"mc":[{"id":"1.187552834","rc":[{"batb":[[0,1.01,12]],"ltp":0.0,"tv":0.0,"id":8679184}]}]}
{"op":"mcm","clk":"4223084187","pt":1631446252494,"mc":[{"id":"1.187552834","rc":[{"batb":[[0,1.01,4176.78]],"ltp":0.0,"tv":0.0,"id":8679184}]}]}
{"op":"mcm","clk":"4223086914","pt":1631446266780,"mc":[{"id":"1.187552834","rc":[{"batb":[[0,1.01,12]],"ltp":0.0,"tv":0.0,"id":8679184}]}]}
{"op":"mcm","clk":"4223088136","pt":1631446272711,"mc":[{"id":"1.187552834","rc":[{"batb":[[0,1.02,2183.36],[1,1.01,12]],"ltp":0.0,"tv":0.0,"id":8679184}]}]}
{"op":"mcm","clk":"4223091965","pt":1631446292064,"mc":[{"id":"1.187552834","rc":[{"batb":[[0,1.01,12],[1,1.01,0]],"ltp":0.0,"tv":0.0,"id":8679184}]}]}
{"op":"mcm","clk":"4223093248","pt":1631446298085,"mc":[{"id":"1.187552834","rc":[{"batb":[[0,1.01,3989.18]],"ltp":0.0,"tv":0.0,"id":8679184}]}]}
{"op":"mcm","clk":"4223099773","pt":1631446328482,"mc":[{"id":"1.187552834","rc":[{"batb":[[0,1.01,12]],"ltp":0.0,"tv":0.0,"id":8679184}]}]}
{"op":"mcm","clk":"4223100899","pt":1631446334396,"mc":[{"id":"1.187552834","rc":[{"batl":[[0,170,37.59]],"ltp":0.0,"tv":0.0,"id":14039549}]}]}
{"op":"mcm","clk":"4223128212","pt":1631446474405,"mc":[{"id":"1.187552834","rc":[{"trd":[[1.01,24]],"batl":[[0,1.01,5.08],[1,1.28,1356.2],[2,11.5,8.68]],"ltp":1.01,"tv":23.99,"id":8679184}],"tv":23.99}]}
{"op":"mcm","clk":"4223129046","pt":1631446478588,"mc":[{"id":"1.187552834","rc":[{"batl":[[1,11.5,8.68],[2,11.5,0]],"ltp":1.01,"tv":23.99,"id":8679184}]}]}
{"op":"mcm","clk":"4223132740","pt":1631446497796,"mc":[{"id":"1.187552834","rc":[{"batl":[[1,1.27,1397.51],[2,11.5,8.68]],"ltp":1.01,"tv":23.99,"id":8679184}]}]}
{"op":"mcm","clk":"4223134047","pt":1631446504935,"mc":[{"id":"1.187552834","rc":[{"batl":[[1,11.5,8.68],[2,11.5,0]],"ltp":1.01,"tv":23.99,"id":8679184}]}]}
{"op":"mcm","clk":"4223142849","pt":1631446548257,"mc":[{"id":"1.187552834","rc":[{"batl":[[1,1.28,1356.2],[2,11.5,8.68]],"ltp":1.01,"tv":23.99,"id":8679184}]}]}
{"op":"mcm","clk":"4223144870","pt":1631446558462,"mc":[{"id":"1.187552834","rc":[{"batl":[[1,11.5,8.68],[2,11.5,0]],"ltp":1.01,"tv":23.99,"id":8679184}]}]}
{"op":"mcm","clk":"4223146969","pt":1631446568400,"mc":[{"id":"1.187552834","rc":[{"batl":[[1,1.28,1370.09],[2,11.5,8.68]],"ltp":1.01,"tv":23.99,"id":8679184}]}]}
{"op":"mcm","clk":"4223147301","pt":1631446569585,"mc":[{"id":"1.187552834","rc":[{"batl":[[1,11.5,8.68],[2,11.5,0]],"ltp":1.01,"tv":23.99,"id":8679184}]}]}
{"op":"mcm","clk":"4223150107","pt":1631446583601,"mc":[{"id":"1.187552834","rc":[{"batl":[[1,1.27,1397.51],[2,11.5,8.68]],"ltp":1.01,"tv":23.99,"id":8679184}]}]}
{"op":"mcm","clk":"4223151120","pt":1631446588817,"mc":[{"id":"1.187552834","rc":[{"batl":[[1,11.5,8.68],[2,11.5,0]],"ltp":1.01,"tv":23.99,"id":8679184}]}]}
{"op":"mcm","clk":"4223153631","pt":1631446600644,"mc":[{"id":"1.187552834","rc":[{"batl":[[1,1.02,2.33],[2,11.5,8.68]],"ltp":1.01,"tv":23.99,"id":8679184}]}]}
{"op":"mcm","clk":"4223157381","pt":1631446618978,"mc":[{"id":"1.187552834","rc":[{"batl":[[2,1.28,1356.2]],"ltp":1.01,"tv":23.99,"id":8679184}]}]}
{"op":"mcm","clk":"4223158263","pt":1631446623246,"mc":[{"id":"1.187552834","rc":[{"batl":[[2,11.5,8.68]],"ltp":1.01,"tv":23.99,"id":8679184}]}]}
{"op":"mcm","clk":"4223160848","pt":1631446637091,"mc":[{"id":"1.187552834","rc":[{"batl":[[2,1.29,1290.91]],"ltp":1.01,"tv":23.99,"id":8679184}]}]}
{"op":"mcm","clk":"4223164640","pt":1631446656108,"mc":[{"id":"1.187552834","rc":[{"batl":[[1,1.29,1290.91],[2,11.5,8.68]],"ltp":1.01,"tv":23.99,"id":8679184}]}]}
{"op":"mcm","clk":"4223167353","pt":1631446670207,"mc":[{"id":"1.187552834","rc":[{"batl":[[0,340,36.48]],"ltp":0.0,"tv":0.0,"id":14039549}]}]}
{"op":"mcm","clk":"4223177789","pt":1631446726886,"mc":[{"id":"1.187552834","rc":[{"trd":[[1.01,34.16]],"batb":[[0,1.01,8.7]],"batl":[[0,1.29,1290.91],[1,11.5,8.68],[2,11.5,0]],"ltp":1.01,"tv":34.16,"id":8679184}],"tv":34.16}]}
{"op":"mcm","clk":"4223189960","pt":1631446793265,"mc":[{"id":"1.187552834","rc":[{"batl":[[0,1.28,80],[1,1.29,1290.91],[2,11.5,8.68]],"ltp":1.01,"tv":34.16,"id":8679184}]}]}
{"op":"mcm","clk":"4223189999","pt":1631446793474,"mc":[{"id":"1.187552834","rc":[{"batl":[[0,340,36.48]],"ltp":0.0,"tv":0.0,"id":14039549}]}]}
{"op":"mcm","clk":"4223195353","pt":1631446821008,"mc":[{"id":"1.187552834","rc":[{"batl":[[0,1.05,2.2],[1,1.28,80],[2,1.29,1290.91]],"ltp":1.01,"tv":34.16,"id":8679184}]}]}
{"op":"mcm","clk":"4223214419","pt":1631446914106,"mc":[{"id":"1.187552834","rc":[{"batl":[[2,11.5,8.68]],"ltp":1.01,"tv":34.16,"id":8679184}]}]}
{"op":"mcm","clk":"4223233349","pt":1631447008114,"mc":[{"id":"1.187552834","rc":[{"batl":[[0,1.28,80],[1,11.5,8.68],[2,11.5,0]],"ltp":1.01,"tv":34.16,"id":8679184}]}]}
{"op":"mcm","clk":"4223234260","pt":1631447013200,"mc":[{"id":"1.187552834","rc":[{"batl":[[0,1.02,2.2],[1,1.28,80],[2,11.5,8.68]],"ltp":1.01,"tv":34.16,"id":8679184}]}]}
{"op":"mcm","clk":"4223239881","pt":1631447043384,"mc":[{"id":"1.187552834","marketDefinition":{"bspMarket":false,"turnInPlayEnabled":true,"persistenceEnabled":true,"marketBaseRate":5.0,"eventId":"30895331","eventTypeId":"2","numberOfWinners":1,"bettingType":"ODDS","marketType":"MATCH_ODDS","marketTime":"2021-09-12T10:36:23.000Z","suspendTime":"2021-09-12T10:36:23.000Z","bspReconciled":false,"complete":true,"inPlay":true,"crossMatching":true,"runnersVoidable":false,"numberOfActiveRunners":2,"betDelay":5,"status":"SUSPENDED","runners":[{"status":"ACTIVE","sortPriority":1,"id":8679184,"name":"I Rosca"},{"status":"ACTIVE","sortPriority":2,"id":14039549,"name":"L Pulchartova"}],"regulators":["MR_INT"],"countryCode":"GB","discountAllowed":true,"timezone":"GMT","openDate":"2021-09-12T10:36:23.000Z","version":4027965816,"name":"Match Odds","eventName":"I Rosca v L Pulchartova"}}]}
{"op":"mcm","clk":"4223240305","pt":1631447045849,"mc":[{"id":"1.187552834","tv":0.0}]}
{"op":"mcm","clk":"4223240413","pt":1631447046398,"mc":[{"id":"1.187552834","marketDefinition":{"bspMarket":false,"turnInPlayEnabled":true,"persistenceEnabled":true,"marketBaseRate":5.0,"eventId":"30895331","eventTypeId":"2","numberOfWinners":1,"bettingType":"ODDS","marketType":"MATCH_ODDS","marketTime":"2021-09-12T10:36:23.000Z","suspendTime":"2021-09-12T10:36:23.000Z","bspReconciled":false,"complete":true,"inPlay":true,"crossMatching":false,"runnersVoidable":false,"numberOfActiveRunners":0,"betDelay":5,"status":"CLOSED","settledTime":"2021-09-12T11:44:04.000Z","runners":[{"status":"WINNER","sortPriority":1,"id":8679184,"name":"I Rosca"},{"status":"LOSER","sortPriority":2,"id":14039549,"name":"L Pulchartova"}],"regulators":["MR_INT"],"countryCode":"GB","discountAllowed":true,"timezone":"GMT","openDate":"2021-09-12T10:36:23.000Z","version":4027965826,"name":"Match Odds","eventName":"I Rosca v L Pulchartova"}}]}
