{"op":"mcm","clk":"4232958465","pt":1631528540989,"mc":[{"id":"1.187612427","marketDefinition":{"bspMarket":false,"turnInPlayEnabled":true,"persistenceEnabled":true,"marketBaseRate":5.0,"eventId":"30898447","eventTypeId":"2","numberOfWinners":1,"bettingType":"ODDS","marketType":"MATCH_ODDS","marketTime":"2021-09-13T16:00:00.000Z","suspendTime":"2021-09-13T16:00:00.000Z","bspReconciled":false,"complete":true,"inPlay":false,"crossMatching":false,"runnersVoidable":false,"numberOfActiveRunners":2,"betDelay":0,"status":"OPEN","runners":[{"status":"ACTIVE","sortPriority":1,"id":9627400,"name":"C Dinu"},{"status":"ACTIVE","sortPriority":2,"id":25977944,"name":"J Bouzas Maneiro"}],"regulators":["MR_INT"],"countryCode":"GB","discountAllowed":false,"timezone":"GMT","openDate":"2021-09-13T16:00:00.000Z","version":4030538065,"name":"Match Odds","eventName":"C Dinu v J Bouzas Maneiro"},"rc":[{"batb":[[0,1.01,25]],"ltp":0.0,"tv":0.0,"id":9627400},{"batb":[[0,1.01,25]],"ltp":0.0,"tv":0.0,"id":25977944}]}]}
{"op":"mcm","clk":"4232958560","pt":1631528542494,"mc":[{"id":"1.187612427","marketDefinition":{"bspMarket":false,"turnInPlayEnabled":true,"persistenceEnabled":true,"marketBaseRate":5.0,"eventId":"30898447","eventTypeId":"2","numberOfWinners":1,"bettingType":"ODDS","marketType":"MATCH_ODDS","marketTime":"2021-09-13T16:00:00.000Z","suspendTime":"2021-09-13T16:00:00.000Z","bspReconciled":false,"complete":true,"inPlay":false,"crossMatching":false,"runnersVoidable":false,"numberOfActiveRunners":2,"betDelay":0,"status":"OPEN","runners":[{"status":"ACTIVE","sortPriority":1,"id":9627400,"name":"C Dinu"},{"status":"ACTIVE","sortPriority":2,"id":25977944,"name":"J Bouzas Maneiro"}],"regulators":["MR_INT"],"countryCode":"GB","discountAllowed":true,"timezone":"GMT","openDate":"2021-09-13T16:00:00.000Z","version":4030538065,"name":"Match Odds","eventName":"C Dinu v J Bouzas Maneiro"}}]}
{"op":"mcm","clk":"4232983195","pt":1631528978896,"mc":[{"id":"1.187612427","rc":[{"batb":[[0,1.67,46.75],[1,1.01,25]],"ltp":0.0,"tv":0.0,"id":9627400},{"batb":[[0,2.1,28.47],[1,1.01,25]],"ltp":0.0,"tv":0.0,"id":25977944}]}]}
{"op":"mcm","clk":"4232983701","pt":1631528986804,"mc":[{"id":"1.187612427","marketDefinition":{"bspMarket":false,"turnInPlayEnabled":true,"persistenceEnabled":true,"marketBaseRate":5.0,"eventId":"30898447","eventTypeId":"2","numberOfWinners":1,"bettingType":"ODDS","marketType":"MATCH_ODDS","marketTime":"2021-09-13T16:00:00.000Z","suspendTime":"2021-09-13T16:00:00.000Z","bspReconciled":false,"complete":true,"inPlay":false,"crossMatching":true,"runnersVoidable":false,"numberOfActiveRunners":2,"betDelay":0,"status":"OPEN","runners":[{"status":"ACTIVE","sortPriority":1,"id":9627400,"name":"C Dinu"},{"status":"ACTIVE","sortPriority":2,"id":25977944,"name":"J Bouzas Maneiro"}],"regulators":["MR_INT"],"countryCode":"GB","discountAllowed":true,"timezone":"GMT","openDate":"2021-09-13T16:00:00.000Z","version":4030538065,"name":"Match Odds","eventName":"C Dinu v J Bouzas Maneiro"}}]}
{"op":"mcm","clk":"4232985169","pt":1631529007855,"mc":[{"id":"1.187612427","rc":[{"batb":[[1,1.01,7]],"ltp":0.0,"tv":0.0,"id":9627400},{"batb":[[1,1.01,7]],"ltp":0.0,"tv":0.0,"id":25977944}]}]}
{"op":"mcm","clk":"4233178245","pt":1631531563608,"mc":[{"id":"1.187612427","rc":[{"batl":[[0,990,2.2]],"ltp":0.0,"tv":0.0,"id":9627400},{"batl":[[0,990,2.2]],"ltp":0.0,"tv":0.0,"id":25977944}]}]}
{"op":"mcm","clk":"4233267137","pt":1631532769264,"mc":[{"id":"1.187612427","rc":[{"batb":[[0,1.62,50.52]],"ltp":0.0,"tv":0.0,"id":9627400},{"batb":[[0,2.2,26.1]],"ltp":0.0,"tv":0.0,"id":25977944}]}]}
{"op":"mcm","clk":"4233605127","pt":1631536543334,"mc":[{"id":"1.187612427","rc":[{"batb":[[0,1.65,1.39],[1,1.62,50.52],[2,1.01,7]],"ltp":0.0,"tv":0.0,"id":9627400}]}]}
{"op":"mcm","clk":"4233852603","pt":1631539389710,"mc":[{"id":"1.187612427","rc":[{"batb":[[0,1.65,1.4],[2,1.05,873.97]],"ltp":0.0,"tv":0.0,"id":9627400},{"batb":[[1,1.05,873.97],[2,1.01,7]],"ltp":0.0,"tv":0.0,"id":25977944}]}]}
{"op":"mcm","clk":"4233894474","pt":1631539789837,"mc":[{"id":"1.187612427","rc":[{"batb":[[1,1.57,54.95]],"ltp":0.0,"tv":0.0,"id":9627400},{"batb":[[0,2.24,25.26]],"ltp":0.0,"tv":0.0,"id":25977944}]}]}
{"op":"mcm","clk":"4234049167","pt":1631541601535,"mc":[{"id":"1.187612427","rc":[{"batb":[[1,1.57,73.27]],"ltp":0.0,"tv":0.0,"id":9627400},{"batb":[[0,2.24,33.68]],"ltp":0.0,"tv":0.0,"id":25977944}]}]}
{"op":"mcm","clk":"4234186670","pt":1631543046778,"mc":[{"id":"1.187612427","marketDefinition":{"bspMarket":false,"turnInPlayEnabled":true,"persistenceEnabled":true,"marketBaseRate":5.0,"eventId":"30898447","eventTypeId":"2","numberOfWinners":1,"bettingType":"ODDS","marketType":"MATCH_ODDS","marketTime":"2021-09-13T15:55:00.000Z","suspendTime":"2021-09-13T15:55:00.000Z","bspReconciled":false,"complete":true,"inPlay":false,"crossMatching":true,"runnersVoidable":false,"numberOfActiveRunners":2,"betDelay":0,"status":"OPEN","runners":[{"status":"ACTIVE","sortPriority":1,"id":9627400,"name":"C Dinu"},{"status":"ACTIVE","sortPriority":2,"id":25977944,"name":"J Bouzas Maneiro"}],"regulators":["MR_INT"],"countryCode":"GB","discountAllowed":true,"timezone":"GMT","openDate":"2021-09-13T16:00:00.000Z","version":4030767915,"name":"Match Odds","eventName":"C Dinu v J Bouzas Maneiro"}}]}
{"op":"mcm","clk":"4234186934","pt":1631543049791,"mc":[{"id":"1.187612427","marketDefinition":{"bspMarket":false,"turnInPlayEnabled":true,"persistenceEnabled":true,"marketBaseRate":5.0,"eventId":"30898447","eventTypeId":"2","numberOfWinners":1,"bettingType":"ODDS","marketType":"MATCH_ODDS","marketTime":"2021-09-13T15:55:00.000Z","suspendTime":"2021-09-13T15:55:00.000Z","bspReconciled":false,"complete":true,"inPlay":false,"crossMatching":true,"runnersVoidable":false,"numberOfActiveRunners":2,"betDelay":0,"status":"OPEN","runners":[{"status":"ACTIVE","sortPriority":1,"id":9627400,"name":"C Dinu"},{"status":"ACTIVE","sortPriority":2,"id":25977944,"name":"J Bouzas Maneiro"}],"regulators":["MR_INT"],"countryCode":"GB","discountAllowed":true,"timezone":"GMT","openDate":"2021-09-13T15:55:00.000Z","version":4030767915,"name":"Match Odds","eventName":"C Dinu v J Bouzas Maneiro"}}]}
{"op":"mcm","clk":"4234310050","pt":1631544164689,"mc":[{"id":"1.187612427","marketDefinition":{"bspMarket":false,"turnInPlayEnabled":true,"persistenceEnabled":true,"marketBaseRate":5.0,"eventId":"30898447","eventTypeId":"2","numberOfWinners":1,"bettingType":"ODDS","marketType":"MATCH_ODDS","marketTime":"2021-09-13T16:10:00.000Z","suspendTime":"2021-09-13T16:10:00.000Z","bspReconciled":false,"complete":true,"inPlay":false,"crossMatching":true,"runnersVoidable":false,"numberOfActiveRunners":2,"betDelay":0,"status":"OPEN","runners":[{"status":"ACTIVE","sortPriority":1,"id":9627400,"name":"C Dinu"},{"status":"ACTIVE","sortPriority":2,"id":25977944,"name":"J Bouzas Maneiro"}],"regulators":["MR_INT"],"countryCode":"GB","discountAllowed":true,"timezone":"GMT","openDate":"2021-09-13T15:55:00.000Z","version":4030787941,"name":"Match Odds","eventName":"C Dinu v J Bouzas Maneiro"}}]}
{"op":"mcm","clk":"4234310445","pt":1631544168709,"mc":[{"id":"1.187612427","marketDefinition":{"bspMarket":false,"turnInPlayEnabled":true,"persistenceEnabled":true,"marketBaseRate":5.0,"eventId":"30898447","eventTypeId":"2","numberOfWinners":1,"bettingType":"ODDS","marketType":"MATCH_ODDS","marketTime":"2021-09-13T16:10:00.000Z","suspendTime":"2021-09-13T16:10:00.000Z","bspReconciled":false,"complete":true,"inPlay":false,"crossMatching":true,"runnersVoidable":false,"numberOfActiveRunners":2,"betDelay":0,"status":"OPEN","runners":[{"status":"ACTIVE","sortPriority":1,"id":9627400,"name":"C Dinu"},{"status":"ACTIVE","sortPriority":2,"id":25977944,"name":"J Bouzas Maneiro"}],"regulators":["MR_INT"],"countryCode":"GB","discountAllowed":true,"timezone":"GMT","openDate":"2021-09-13T16:10:00.000Z","version":4030787941,"name":"Match Odds","eventName":"C Dinu v J Bouzas Maneiro"}}]}
{"op":"mcm","clk":"4234371224","pt":1631544818029,"mc":[{"id":"1.187612427","rc":[{"batl":[[0,2.34,2.66],[1,990,2.2]],"ltp":0.0,"tv":0.0,"id":9627400}]}]}
{"op":"mcm","clk":"4234371552","pt":1631544822169,"mc":[{"id":"1.187612427","rc":[{"batb":[[2,1.2,13.31]],"ltp":0.0,"tv":0.0,"id":9627400}]}]}
{"op":"mcm","clk":"4234389685","pt":1631545063694,"mc":[{"id":"1.187612427","rc":[{"batb":[[2,1.22,194.02]],"ltp":0.0,"tv":0.0,"id":9627400}]}]}
{"op":"mcm","clk":"4234444815","pt":1631545800564,"mc":[{"id":"1.187612427","rc":[{"batb":[[0,1.65,1.4],[1,1.58,22.05],[2,1.57,73.27]],"ltp":0.0,"tv":0.0,"id":9627400},{"batb":[[0,2.26,10.15],[1,2.24,33.68],[2,1.05,872.97]],"ltp":0.0,"tv":0.0,"id":25977944}]}]}
{"op":"mcm","clk":"4234519223","pt":1631546611755,"mc":[{"id":"1.187612427","rc":[{"batb":[[2,1.01,7]],"ltp":0.0,"tv":0.0,"id":25977944}]}]}
{"op":"mcm","clk":"4234520223","pt":1631546623852,"mc":[{"id":"1.187612427","rc":[{"batl":[[1,2.6,43.65],[2,990,2.2]],"ltp":0.0,"tv":0.0,"id":9627400}]}]}
{"op":"mcm","clk":"4234711691","pt":1631549082177,"mc":[{"id":"1.187612427","rc":[{"batb":[[2,1.01,12]],"ltp":0.0,"tv":0.0,"id":25977944}]}]}
{"op":"mcm","clk":"4234726951","pt":1631549234906,"mc":[{"id":"1.187612427","marketDefinition":{"bspMarket":false,"turnInPlayEnabled":true,"persistenceEnabled":true,"marketBaseRate":5.0,"eventId":"30898447","eventTypeId":"2","numberOfWinners":1,"bettingType":"ODDS","marketType":"MATCH_ODDS","marketTime":"2021-09-13T16:20:00.000Z","suspendTime":"2021-09-13T16:20:00.000Z","bspReconciled":false,"complete":true,"inPlay":false,"crossMatching":true,"runnersVoidable":false,"numberOfActiveRunners":2,"betDelay":0,"status":"OPEN","runners":[{"status":"ACTIVE","sortPriority":1,"id":9627400,"name":"C Dinu"},{"status":"ACTIVE","sortPriority":2,"id":25977944,"name":"J Bouzas Maneiro"}],"regulators":["MR_INT"],"countryCode":"GB","discountAllowed":true,"timezone":"GMT","openDate":"2021-09-13T16:10:00.000Z","version":4030878766,"name":"Match Odds","eventName":"C Dinu v J Bouzas Maneiro"}}]}
{"op":"mcm","clk":"4234727235","pt":1631549237922,"mc":[{"id":"1.187612427","marketDefinition":{"bspMarket":false,"turnInPlayEnabled":true,"persistenceEnabled":true,"marketBaseRate":5.0,"eventId":"30898447","eventTypeId":"2","numberOfWinners":1,"bettingType":"ODDS","marketType":"MATCH_ODDS","marketTime":"2021-09-13T16:20:00.000Z","suspendTime":"2021-09-13T16:20:00.000Z","bspReconciled":false,"complete":true,"inPlay":false,"crossMatching":true,"runnersVoidable":false,"numberOfActiveRunners":2,"betDelay":0,"status":"OPEN","runners":[{"status":"ACTIVE","sortPriority":1,"id":9627400,"name":"C Dinu"},{"status":"ACTIVE","sortPriority":2,"id":25977944,"name":"J Bouzas Maneiro"}],"regulators":["MR_INT"],"countryCode":"GB","discountAllowed":true,"timezone":"GMT","openDate":"2021-09-13T16:20:00.000Z","version":4030878766,"name":"Match Odds","eventName":"C Dinu v J Bouzas Maneiro"}}]}
{"op":"mcm","clk":"4234742550","pt":1631549399730,"mc":[{"id":"1.187612427","rc":[{"batl":[[0,2.34,3.19]],"ltp":0.0,"tv":0.0,"id":9627400}]}]}
{"op":"mcm","clk":"4234800699","pt":1631550042033,"mc":[{"id":"1.187612427","marketDefinition":{"bspMarket":false,"turnInPlayEnabled":true,"persistenceEnabled":true,"marketBaseRate":5.0,"eventId":"30898447","eventTypeId":"2","numberOfWinners":1,"bettingType":"ODDS","marketType":"MATCH_ODDS","marketTime":"2021-09-13T16:20:00.000Z","suspendTime":"2021-09-13T16:20:00.000Z","bspReconciled":false,"complete":true,"inPlay":true,"crossMatching":true,"runnersVoidable":false,"numberOfActiveRunners":2,"betDelay":5,"status":"OPEN","runners":[{"status":"ACTIVE","sortPriority":1,"id":9627400,"name":"C Dinu"},{"status":"ACTIVE","sortPriority":2,"id":25977944,"name":"J Bouzas Maneiro"}],"regulators":["MR_INT"],"countryCode":"GB","discountAllowed":true,"timezone":"GMT","openDate":"2021-09-13T16:20:00.000Z","version":4030901476,"name":"Match Odds","eventName":"C Dinu v J Bouzas Maneiro"},"rc":[{"batb":[[1,1.01,12],[2,1.57,0]],"batl":[[0,1.71,0.52],[1,2.6,0],[2,990,0]],"ltp":0.0,"tv":0.0,"id":9627400},{"batb":[[0,1.01,12],[1,2.24,0],[2,1.01,0]],"ltp":0.0,"tv":0.0,"id":25977944}]}]}
{"op":"mcm","clk":"4234801155","pt":1631550047298,"mc":[{"id":"1.187612427","rc":[{"batb":[[1,1.55,54.54],[2,1.01,12]],"ltp":0.0,"tv":0.0,"id":9627400},{"batb":[[0,2.2,24.99],[1,1.01,12]],"ltp":0.0,"tv":0.0,"id":25977944}]}]}
{"op":"mcm","clk":"4234810545","pt":1631550149484,"mc":[{"id":"1.187612427","rc":[{"batb":[[0,1.01,12],[1,1.01,0]],"ltp":0.0,"tv":0.0,"id":25977944}]}]}
{"op":"mcm","clk":"4234811006","pt":1631550154392,"mc":[{"id":"1.187612427","rc":[{"batb":[[0,2.16,25.86],[1,1.01,12]],"ltp":0.0,"tv":0.0,"id":25977944}]}]}
{"op":"mcm","clk":"4234842985","pt":1631550494800,"mc":[{"id":"1.187612427","marketDefinition":{"bspMarket":false,"turnInPlayEnabled":true,"persistenceEnabled":true,"marketBaseRate":5.0,"eventId":"30898447","eventTypeId":"2","numberOfWinners":1,"bettingType":"ODDS","marketType":"MATCH_ODDS","marketTime":"2021-09-13T16:28:14.000Z","suspendTime":"2021-09-13T16:28:14.000Z","bspReconciled":false,"complete":true,"inPlay":true,"crossMatching":true,"runnersVoidable":false,"numberOfActiveRunners":2,"betDelay":5,"status":"OPEN","runners":[{"status":"ACTIVE","sortPriority":1,"id":9627400,"name":"C Dinu"},{"status":"ACTIVE","sortPriority":2,"id":25977944,"name":"J Bouzas Maneiro"}],"regulators":["MR_INT"],"countryCode":"GB","discountAllowed":true,"timezone":"GMT","openDate":"2021-09-13T16:20:00.000Z","version":4030908682,"name":"Match Odds","eventName":"C Dinu v J Bouzas Maneiro"},"rc":[{"batb":[[1,1.01,12],[2,1.01,0]],"ltp":0.0,"tv":0.0,"id":9627400},{"batb":[[0,1.01,12],[1,1.01,0]],"ltp":0.0,"tv":0.0,"id":25977944}]}]}
{"op":"mcm","clk":"4234843180","pt":1631550496858,"mc":[{"id":"1.187612427","marketDefinition":{"bspMarket":false,"turnInPlayEnabled":true,"persistenceEnabled":true,"marketBaseRate":5.0,"eventId":"30898447","eventTypeId":"2","numberOfWinners":1,"bettingType":"ODDS","marketType":"MATCH_ODDS","marketTime":"2021-09-13T16:28:14.000Z","suspendTime":"2021-09-13T16:28:14.000Z","bspReconciled":false,"complete":true,"inPlay":true,"crossMatching":true,"runnersVoidable":false,"numberOfActiveRunners":2,"betDelay":5,"status":"OPEN","runners":[{"status":"ACTIVE","sortPriority":1,"id":9627400,"name":"C Dinu"},{"status":"ACTIVE","sortPriority":2,"id":25977944,"name":"J Bouzas Maneiro"}],"regulators":["MR_INT"],"countryCode":"GB","discountAllowed":true,"timezone":"GMT","openDate":"2021-09-13T16:28:14.000Z","version":4030908682,"name":"Match Odds","eventName":"C Dinu v J Bouzas Maneiro"}}]}
{"op":"mcm","clk":"4234843399","pt":1631550499554,"mc":[{"id":"1.187612427","rc":[{"batb":[[1,1.6,49.99],[2,1.01,12]],"ltp":0.0,"tv":0.0,"id":9627400},{"batb":[[0,2.2,24.99],[1,1.01,12]],"ltp":0.0,"tv":0.0,"id":25977944}]}]}
{"op":"mcm","clk":"4234845313","pt":1631550520301,"mc":[{"id":"1.187612427","rc":[{"batb":[[1,1.01,12],[2,1.01,0]],"ltp":0.0,"tv":0.0,"id":9627400},{"batb":[[0,1.01,12],[1,1.01,0]],"ltp":0.0,"tv":0.0,"id":25977944}]}]}
{"op":"mcm","clk":"4234845715","pt":1631550525270,"mc":[{"id":"1.187612427","rc":[{"batb":[[1,1.51,58.82],[2,1.01,12]],"ltp":0.0,"tv":0.0,"id":9627400},{"batb":[[0,2.42,21.12],[1,1.01,12]],"ltp":0.0,"tv":0.0,"id":25977944}]}]}
{"op":"mcm","clk":"4234847189","pt":1631550541733,"mc":[{"id":"1.187612427","rc":[{"batb":[[1,1.01,12],[2,1.01,0]],"ltp":0.0,"tv":0.0,"id":9627400},{"batb":[[0,1.01,12],[1,1.01,0]],"ltp":0.0,"tv":0.0,"id":25977944}]}]}
{"op":"mcm","clk":"4234847590","pt":1631550546815,"mc":[{"id":"1.187612427","rc":[{"trd":[[1.65,1.4]],"batb":[[0,1.45,66.66]],"ltp":1.65,"tv":1.4,"id":9627400},{"trd":[[2.54,0.91]],"ltp":2.54,"tv":0.91,"id":25977944}],"tv":2.31}]}
{"op":"mcm","clk":"4234848046","pt":1631550551728,"mc":[{"id":"1.187612427","rc":[{"batb":[[0,2.58,18.98],[1,1.01,12]],"ltp":2.54,"tv":0.91,"id":25977944}]}]}
{"op":"mcm","clk":"4234848560","pt":1631550556968,"mc":[{"id":"1.187612427","rc":[{"batb":[[0,1.01,12],[1,1.01,0]],"ltp":1.65,"tv":1.4,"id":9627400},{"batb":[[0,1.01,12],[1,1.01,0]],"ltp":2.54,"tv":0.91,"id":25977944}]}]}
{"op":"mcm","clk":"4234849048","pt":1631550561978,"mc":[{"id":"1.187612427","rc":[{"batb":[[0,1.51,58.82],[1,1.01,12]],"ltp":1.65,"tv":1.4,"id":9627400},{"batb":[[0,2.42,21.12],[1,1.01,12]],"ltp":2.54,"tv":0.91,"id":25977944}]}]}
{"op":"mcm","clk":"4234850764","pt":1631550580391,"mc":[{"id":"1.187612427","rc":[{"batb":[[0,1.01,12],[1,1.01,0]],"ltp":1.65,"tv":1.4,"id":9627400},{"batb":[[0,1.01,12],[1,1.01,0]],"ltp":2.54,"tv":0.91,"id":25977944}]}]}
{"op":"mcm","clk":"4234851262","pt":1631550585288,"mc":[{"id":"1.187612427","rc":[{"batb":[[0,1.45,66.66],[1,1.01,12]],"ltp":1.65,"tv":1.4,"id":9627400},{"batb":[[0,2.58,18.98],[1,1.01,12]],"ltp":2.54,"tv":0.91,"id":25977944}]}]}
{"op":"mcm","clk":"4234853355","pt":1631550604827,"mc":[{"id":"1.187612427","rc":[{"batb":[[0,1.01,12],[1,1.01,0]],"ltp":1.65,"tv":1.4,"id":9627400},{"batb":[[0,1.01,12],[1,1.01,0]],"ltp":2.54,"tv":0.91,"id":25977944}]}]}
{"op":"mcm","clk":"4234853923","pt":1631550609848,"mc":[{"id":"1.187612427","rc":[{"batb":[[0,1.38,78.94],[1,1.01,12]],"ltp":1.65,"tv":1.4,"id":9627400},{"batb":[[0,2.84,16.3],[1,1.01,12]],"ltp":2.54,"tv":0.91,"id":25977944}]}]}
{"op":"mcm","clk":"4234862968","pt":1631550698670,"mc":[{"id":"1.187612427","rc":[{"batb":[[0,1.01,12],[1,1.01,0]],"ltp":1.65,"tv":1.4,"id":9627400},{"batb":[[0,1.01,12],[1,1.01,0]],"ltp":2.54,"tv":0.91,"id":25977944}]}]}
{"op":"mcm","clk":"4234863421","pt":1631550703565,"mc":[{"id":"1.187612427","rc":[{"batb":[[0,1.34,88.23],[1,1.01,12]],"ltp":1.65,"tv":1.4,"id":9627400},{"batb":[[0,3,15],[1,1.01,12]],"ltp":2.54,"tv":0.91,"id":25977944}]}]}
{"op":"mcm","clk":"4234866193","pt":1631550729196,"mc":[{"id":"1.187612427","rc":[{"batb":[[0,1.01,12],[1,1.01,0]],"ltp":1.65,"tv":1.4,"id":9627400},{"batb":[[0,1.01,12],[1,1.01,0]],"ltp":2.54,"tv":0.91,"id":25977944}]}]}
{"op":"mcm","clk":"4234866629","pt":1631550734134,"mc":[{"id":"1.187612427","rc":[{"batb":[[0,1.28,107.14],[1,1.01,12]],"ltp":1.65,"tv":1.4,"id":9627400},{"batb":[[0,3.3,13.04],[1,1.01,12]],"ltp":2.54,"tv":0.91,"id":25977944}]}]}
{"op":"mcm","clk":"4234870211","pt":1631550768569,"mc":[{"id":"1.187612427","rc":[{"batb":[[0,1.01,12],[1,1.01,0]],"ltp":1.65,"tv":1.4,"id":9627400},{"batb":[[0,1.01,12],[1,1.01,0]],"ltp":2.54,"tv":0.91,"id":25977944}]}]}
{"op":"mcm","clk":"4234870678","pt":1631550773461,"mc":[{"id":"1.187612427","rc":[{"batb":[[0,1.27,111.11],[1,1.01,12]],"ltp":1.65,"tv":1.4,"id":9627400},{"batb":[[0,3.4,12.5],[1,1.01,12]],"ltp":2.54,"tv":0.91,"id":25977944}]}]}
{"op":"mcm","clk":"4234874053","pt":1631550807026,"mc":[{"id":"1.187612427","rc":[{"batb":[[0,1.01,12],[1,1.01,0]],"ltp":1.65,"tv":1.4,"id":9627400},{"batb":[[0,1.01,12],[1,1.01,0]],"ltp":2.54,"tv":0.91,"id":25977944}]}]}
{"op":"mcm","clk":"4234874577","pt":1631550812055,"mc":[{"id":"1.187612427","rc":[{"batb":[[0,1.31,96.77],[1,1.01,12]],"ltp":1.65,"tv":1.4,"id":9627400},{"batb":[[0,3.15,13.95],[1,1.01,12]],"ltp":2.54,"tv":0.91,"id":25977944}]}]}
{"op":"mcm","clk":"4234877165","pt":1631550837704,"mc":[{"id":"1.187612427","rc":[{"batb":[[0,1.01,12],[1,1.01,0]],"ltp":1.65,"tv":1.4,"id":9627400},{"batb":[[0,1.01,12],[1,1.01,0]],"ltp":2.54,"tv":0.91,"id":25977944}]}]}
{"op":"mcm","clk":"4234877672","pt":1631550842600,"mc":[{"id":"1.187612427","rc":[{"batb":[[0,1.27,111.11],[1,1.01,12]],"ltp":1.65,"tv":1.4,"id":9627400},{"batb":[[0,3.4,12.5],[1,1.01,12]],"ltp":2.54,"tv":0.91,"id":25977944}]}]}
{"op":"mcm","clk":"4234880804","pt":1631550872660,"mc":[{"id":"1.187612427","rc":[{"batb":[[0,1.01,12],[1,1.01,0]],"ltp":1.65,"tv":1.4,"id":9627400},{"batb":[[0,1.01,12],[1,1.01,0]],"ltp":2.54,"tv":0.91,"id":25977944}]}]}
{"op":"mcm","clk":"4234881277","pt":1631550877566,"mc":[{"id":"1.187612427","rc":[{"batb":[[0,1.31,96.77],[1,1.01,12]],"ltp":1.65,"tv":1.4,"id":9627400},{"batb":[[0,3.15,13.95],[1,1.01,12]],"ltp":2.54,"tv":0.91,"id":25977944}]}]}
{"op":"mcm","clk":"4234883618","pt":1631550900894,"mc":[{"id":"1.187612427","rc":[{"batb":[[0,1.01,12],[1,1.01,0]],"ltp":1.65,"tv":1.4,"id":9627400},{"batb":[[0,1.01,12],[1,1.01,0]],"ltp":2.54,"tv":0.91,"id":25977944}]}]}
{"op":"mcm","clk":"4234884088","pt":1631550905840,"mc":[{"id":"1.187612427","rc":[{"batb":[[0,1.34,88.23],[1,1.01,12]],"ltp":1.65,"tv":1.4,"id":9627400},{"batb":[[0,3,15],[1,1.01,12]],"ltp":2.54,"tv":0.91,"id":25977944}]}]}
{"op":"mcm","clk":"4234886107","pt":1631550925726,"mc":[{"id":"1.187612427","rc":[{"batb":[[0,1.01,12],[1,1.01,0]],"ltp":1.65,"tv":1.4,"id":9627400},{"batb":[[0,1.01,12],[1,1.01,0]],"ltp":2.54,"tv":0.91,"id":25977944}]}]}
{"op":"mcm","clk":"4234886644","pt":1631550930676,"mc":[{"id":"1.187612427","rc":[{"batb":[[0,1.38,78.94],[1,1.01,12]],"ltp":1.65,"tv":1.4,"id":9627400},{"batb":[[0,2.84,16.3],[1,1.01,12]],"ltp":2.54,"tv":0.91,"id":25977944}]}]}
{"op":"mcm","clk":"4234903300","pt":1631551094778,"mc":[{"id":"1.187612427","rc":[{"batb":[[0,1.01,12],[1,1.01,0]],"ltp":1.65,"tv":1.4,"id":9627400},{"batb":[[0,1.01,12],[1,1.01,0]],"ltp":2.54,"tv":0.91,"id":25977944}]}]}
{"op":"mcm","clk":"4234903749","pt":1631551099686,"mc":[{"id":"1.187612427","rc":[{"batb":[[0,1.34,88.23],[1,1.01,12]],"ltp":1.65,"tv":1.4,"id":9627400},{"batb":[[0,3,15],[1,1.01,12]],"ltp":2.54,"tv":0.91,"id":25977944}]}]}
{"op":"mcm","clk":"4234909780","pt":1631551158590,"mc":[{"id":"1.187612427","rc":[{"batb":[[0,1.01,12],[1,1.01,0]],"ltp":1.65,"tv":1.4,"id":9627400},{"batb":[[0,1.01,12],[1,1.01,0]],"ltp":2.54,"tv":0.91,"id":25977944}]}]}
{"op":"mcm","clk":"4234910354","pt":1631551163409,"mc":[{"id":"1.187612427","rc":[{"batb":[[0,1.31,96.77],[1,1.01,12]],"ltp":1.65,"tv":1.4,"id":9627400},{"batb":[[0,3.15,13.95],[1,1.01,12]],"ltp":2.54,"tv":0.91,"id":25977944}]}]}
{"op":"mcm","clk":"4234915435","pt":1631551209288,"mc":[{"id":"1.187612427","rc":[{"batb":[[0,1.01,12],[1,1.01,0]],"ltp":1.65,"tv":1.4,"id":9627400},{"batb":[[0,1.01,12],[1,1.01,0]],"ltp":2.54,"tv":0.91,"id":25977944}]}]}
{"op":"mcm","clk":"4234915973","pt":1631551214297,"mc":[{"id":"1.187612427","rc":[{"batb":[[0,1.28,107.14],[1,1.01,12]],"ltp":1.65,"tv":1.4,"id":9627400},{"batb":[[0,3.3,13.04],[1,1.01,12]],"ltp":2.54,"tv":0.91,"id":25977944}]}]}
{"op":"mcm","clk":"4234917965","pt":1631551232712,"mc":[{"id":"1.187612427","rc":[{"batb":[[0,1.01,12],[1,1.01,0]],"ltp":1.65,"tv":1.4,"id":9627400},{"batb":[[0,1.01,12],[1,1.01,0]],"ltp":2.54,"tv":0.91,"id":25977944}]}]}
{"op":"mcm","clk":"4234918457","pt":1631551237602,"mc":[{"id":"1.187612427","rc":[{"batb":[[0,1.27,111.11],[1,1.01,12]],"ltp":1.65,"tv":1.4,"id":9627400},{"batb":[[0,3.4,12.5],[1,1.01,12]],"ltp":2.54,"tv":0.91,"id":25977944}]}]}
{"op":"mcm","clk":"4234923858","pt":1631551291134,"mc":[{"id":"1.187612427","rc":[{"batb":[[0,1.01,12],[1,1.01,0]],"ltp":1.65,"tv":1.4,"id":9627400},{"batb":[[0,1.01,12],[1,1.01,0]],"ltp":2.54,"tv":0.91,"id":25977944}]}]}
{"op":"mcm","clk":"4234924385","pt":1631551296101,"mc":[{"id":"1.187612427","rc":[{"batb":[[0,1.28,107.14],[1,1.01,12]],"ltp":1.65,"tv":1.4,"id":9627400},{"batb":[[0,3.3,13.04],[1,1.01,12]],"ltp":2.54,"tv":0.91,"id":25977944}]}]}
{"op":"mcm","clk":"4234926359","pt":1631551317024,"mc":[{"id":"1.187612427","rc":[{"batb":[[0,1.01,12],[1,1.01,0]],"ltp":1.65,"tv":1.4,"id":9627400},{"batb":[[0,1.01,12],[1,1.01,0]],"ltp":2.54,"tv":0.91,"id":25977944}]}]}
{"op":"mcm","clk":"4234926783","pt":1631551322067,"mc":[{"id":"1.187612427","rc":[{"batb":[[0,1.31,96.77],[1,1.01,12]],"ltp":1.65,"tv":1.4,"id":9627400},{"batb":[[0,3.15,13.95],[1,1.01,12]],"ltp":2.54,"tv":0.91,"id":25977944}]}]}
{"op":"mcm","clk":"4234930695","pt":1631551363236,"mc":[{"id":"1.187612427","rc":[{"batb":[[0,1.01,12],[1,1.01,0]],"ltp":1.65,"tv":1.4,"id":9627400},{"batb":[[0,1.01,12],[1,1.01,0]],"ltp":2.54,"tv":0.91,"id":25977944}]}]}
{"op":"mcm","clk":"4234931160","pt":1631551368117,"mc":[{"id":"1.187612427","rc":[{"batb":[[0,1.28,107.14],[1,1.01,12]],"ltp":1.65,"tv":1.4,"id":9627400},{"batb":[[0,3.3,13.04],[1,1.01,12]],"ltp":2.54,"tv":0.91,"id":25977944}]}]}
{"op":"mcm","clk":"4234932069","pt":1631551377751,"mc":[{"id":"1.187612427","rc":[{"batb":[[0,1.01,12],[1,1.01,0]],"ltp":1.65,"tv":1.4,"id":9627400},{"batb":[[0,1.01,12],[1,1.01,0]],"ltp":2.54,"tv":0.91,"id":25977944}]}]}
{"op":"mcm","clk":"4234932578","pt":1631551382649,"mc":[{"id":"1.187612427","rc":[{"batb":[[0,1.34,88.23],[1,1.01,12]],"ltp":1.65,"tv":1.4,"id":9627400},{"batb":[[0,3,15],[1,1.01,12]],"ltp":2.54,"tv":0.91,"id":25977944}]}]}
{"op":"mcm","clk":"4234934507","pt":1631551401078,"mc":[{"id":"1.187612427","rc":[{"batb":[[0,1.01,12],[1,1.01,0]],"ltp":1.65,"tv":1.4,"id":9627400},{"batb":[[0,1.01,12],[1,1.01,0]],"ltp":2.54,"tv":0.91,"id":25977944}]}]}
{"op":"mcm","clk":"4234934988","pt":1631551405914,"mc":[{"id":"1.187612427","rc":[{"batb":[[0,1.38,78.94],[1,1.01,12]],"ltp":1.65,"tv":1.4,"id":9627400},{"batb":[[0,2.84,16.3],[1,1.01,12]],"ltp":2.54,"tv":0.91,"id":25977944}]}]}
{"op":"mcm","clk":"4234947838","pt":1631551522099,"mc":[{"id":"1.187612427","rc":[{"batb":[[0,1.01,12],[1,1.01,0]],"ltp":1.65,"tv":1.4,"id":9627400},{"batb":[[0,1.01,12],[1,1.01,0]],"ltp":2.54,"tv":0.91,"id":25977944}]}]}
{"op":"mcm","clk":"4234948401","pt":1631551527036,"mc":[{"id":"1.187612427","rc":[{"batb":[[0,1.34,88.23],[1,1.01,12]],"ltp":1.65,"tv":1.4,"id":9627400},{"batb":[[0,3,15],[1,1.01,12]],"ltp":2.54,"tv":0.91,"id":25977944}]}]}
{"op":"mcm","clk":"4234949877","pt":1631551540434,"mc":[{"id":"1.187612427","rc":[{"trd":[[1.34,3.42]],"batb":[[0,1.01,12],[1,1.01,0]],"ltp":1.34,"tv":4.81,"id":9627400}],"tv":5.72}]}
{"op":"mcm","clk":"4234950424","pt":1631551545333,"mc":[{"id":"1.187612427","rc":[{"batb":[[0,1.34,88.23],[1,1.01,12]],"ltp":1.34,"tv":4.81,"id":9627400}]}]}
{"op":"mcm","clk":"4234950531","pt":1631551546435,"mc":[{"id":"1.187612427","rc":[{"batb":[[0,1.01,12],[1,1.01,0]],"ltp":2.54,"tv":0.91,"id":25977944}]}]}
{"op":"mcm","clk":"4234951010","pt":1631551551355,"mc":[{"id":"1.187612427","rc":[{"batb":[[0,3.15,13.95],[1,1.01,12]],"ltp":2.54,"tv":0.91,"id":25977944}]}]}
{"op":"mcm","clk":"4234952836","pt":1631551570207,"mc":[{"id":"1.187612427","rc":[{"batb":[[0,1.01,12],[1,1.01,0]],"ltp":1.34,"tv":4.81,"id":9627400},{"batb":[[0,1.01,12],[1,1.01,0]],"ltp":2.54,"tv":0.91,"id":25977944}]}]}
{"op":"mcm","clk":"4234953321","pt":1631551575225,"mc":[{"id":"1.187612427","rc":[{"batb":[[0,1.38,78.94],[1,1.01,12]],"ltp":1.34,"tv":4.81,"id":9627400},{"batb":[[0,2.84,16.3],[1,1.01,12]],"ltp":2.54,"tv":0.91,"id":25977944}]}]}
{"op":"mcm","clk":"4234956131","pt":1631551602542,"mc":[{"id":"1.187612427","rc":[{"batb":[[0,1.01,12],[1,1.01,0]],"ltp":1.34,"tv":4.81,"id":9627400},{"batb":[[0,1.01,12],[1,1.01,0]],"ltp":2.54,"tv":0.91,"id":25977944}]}]}
{"op":"mcm","clk":"4234956646","pt":1631551607362,"mc":[{"id":"1.187612427","rc":[{"batb":[[0,1.34,88.23],[1,1.01,12]],"ltp":1.34,"tv":4.81,"id":9627400},{"batb":[[0,3,15],[1,1.01,12]],"ltp":2.54,"tv":0.91,"id":25977944}]}]}
{"op":"mcm","clk":"4234958184","pt":1631551622393,"mc":[{"id":"1.187612427","rc":[{"batb":[[0,1.01,12],[1,1.01,0]],"ltp":1.34,"tv":4.81,"id":9627400},{"batb":[[0,1.01,12],[1,1.01,0]],"ltp":2.54,"tv":0.91,"id":25977944}]}]}
{"op":"mcm","clk":"4234958733","pt":1631551627318,"mc":[{"id":"1.187612427","rc":[{"batb":[[0,1.27,111.11],[1,1.01,12]],"ltp":1.34,"tv":4.81,"id":9627400},{"batb":[[0,3.4,12.5],[1,1.01,12]],"ltp":2.54,"tv":0.91,"id":25977944}]}]}
{"op":"mcm","clk":"4234960477","pt":1631551643140,"mc":[{"id":"1.187612427","rc":[{"batb":[[0,1.01,12],[1,1.01,0]],"ltp":1.34,"tv":4.81,"id":9627400},{"batb":[[0,1.01,12],[1,1.01,0]],"ltp":2.54,"tv":0.91,"id":25977944}]}]}
{"op":"mcm","clk":"4234961006","pt":1631551648034,"mc":[{"id":"1.187612427","rc":[{"batb":[[0,1.23,130.43],[1,1.01,12]],"ltp":1.34,"tv":4.81,"id":9627400},{"batb":[[0,3.7,11.11],[1,1.01,12]],"ltp":2.54,"tv":0.91,"id":25977944}]}]}
{"op":"mcm","clk":"4234974362","pt":1631551692500,"mc":[{"id":"1.187612427","rc":[{"batb":[[0,1.01,12],[1,1.01,0]],"ltp":1.34,"tv":4.81,"id":9627400},{"batb":[[0,1.01,12],[1,1.01,0]],"ltp":2.54,"tv":0.91,"id":25977944}]}]}
{"op":"mcm","clk":"4234974896","pt":1631551697392,"mc":[{"id":"1.187612427","rc":[{"batb":[[0,1.27,111.11],[1,1.01,12]],"ltp":1.34,"tv":4.81,"id":9627400},{"batb":[[0,3.4,12.5],[1,1.01,12]],"ltp":2.54,"tv":0.91,"id":25977944}]}]}
{"op":"mcm","clk":"4234977182","pt":1631551719059,"mc":[{"id":"1.187612427","rc":[{"batb":[[0,1.01,12],[1,1.01,0]],"ltp":1.34,"tv":4.81,"id":9627400},{"batb":[[0,1.01,12],[1,1.01,0]],"ltp":2.54,"tv":0.91,"id":25977944}]}]}
{"op":"mcm","clk":"4234977624","pt":1631551724068,"mc":[{"id":"1.187612427","rc":[{"batb":[[0,1.28,107.14],[1,1.01,12]],"ltp":1.34,"tv":4.81,"id":9627400},{"batb":[[0,3.3,13.04],[1,1.01,12]],"ltp":2.54,"tv":0.91,"id":25977944}]}]}
{"op":"mcm","clk":"4234979940","pt":1631551747196,"mc":[{"id":"1.187612427","rc":[{"batb":[[0,1.01,12],[1,1.01,0]],"ltp":1.34,"tv":4.81,"id":9627400},{"batb":[[0,1.01,12],[1,1.01,0]],"ltp":2.54,"tv":0.91,"id":25977944}]}]}
{"op":"mcm","clk":"4234980538","pt":1631551752120,"mc":[{"id":"1.187612427","rc":[{"batb":[[0,1.27,111.11],[1,1.01,12]],"ltp":1.34,"tv":4.81,"id":9627400},{"batb":[[0,3.4,12.5],[1,1.01,12]],"ltp":2.54,"tv":0.91,"id":25977944}]}]}
{"op":"mcm","clk":"4234982358","pt":1631551769121,"mc":[{"id":"1.187612427","rc":[{"batb":[[0,1.01,12],[1,1.01,0]],"ltp":1.34,"tv":4.81,"id":9627400},{"batb":[[0,1.01,12],[1,1.01,0]],"ltp":2.54,"tv":0.91,"id":25977944}]}]}
{"op":"mcm","clk":"4234982877","pt":1631551774112,"mc":[{"id":"1.187612427","rc":[{"batb":[[0,1.23,130.43],[1,1.01,12]],"ltp":1.34,"tv":4.81,"id":9627400},{"batb":[[0,3.7,11.11],[1,1.01,12]],"ltp":2.54,"tv":0.91,"id":25977944}]}]}
{"op":"mcm","clk":"4234984374","pt":1631551789666,"mc":[{"id":"1.187612427","rc":[{"batb":[[0,1.01,12],[1,1.01,0]],"ltp":2.54,"tv":0.91,"id":25977944}]}]}
{"op":"mcm","clk":"4234984885","pt":1631551794529,"mc":[{"id":"1.187612427","rc":[{"batb":[[0,3.95,10.16],[1,1.01,12]],"ltp":2.54,"tv":0.91,"id":25977944}]}]}
{"op":"mcm","clk":"4234986694","pt":1631551812870,"mc":[{"id":"1.187612427","rc":[{"batb":[[0,1.01,12],[1,1.01,0]],"ltp":1.34,"tv":4.81,"id":9627400},{"batb":[[0,1.01,12],[1,1.01,0]],"ltp":2.54,"tv":0.91,"id":25977944}]}]}
{"op":"mcm","clk":"4234987138","pt":1631551817776,"mc":[{"id":"1.187612427","rc":[{"batb":[[0,1.18,166.66],[1,1.01,12]],"ltp":1.34,"tv":4.81,"id":9627400},{"batb":[[0,4.1,10],[1,1.01,12]],"ltp":2.54,"tv":0.91,"id":25977944}]}]}
{"op":"mcm","clk":"4234990619","pt":1631551853061,"mc":[{"id":"1.187612427","rc":[{"batb":[[0,1.01,12],[1,1.01,0]],"ltp":1.34,"tv":4.81,"id":9627400},{"batb":[[0,1.01,12],[1,1.01,0]],"ltp":2.54,"tv":0.91,"id":25977944}]}]}
{"op":"mcm","clk":"4234991050","pt":1631551857950,"mc":[{"id":"1.187612427","rc":[{"batb":[[0,1.15,200],[1,1.01,12]],"ltp":1.34,"tv":4.81,"id":9627400},{"batb":[[0,4.8,10],[1,1.01,12]],"ltp":2.54,"tv":0.91,"id":25977944}]}]}
{"op":"mcm","clk":"4234996150","pt":1631551909427,"mc":[{"id":"1.187612427","rc":[{"trd":[[1.15,4]],"batb":[[0,1.15,198]],"ltp":1.15,"tv":8.81,"id":9627400}],"tv":9.72}]}
{"op":"mcm","clk":"4234996169","pt":1631551909632,"mc":[{"id":"1.187612427","rc":[{"batb":[[0,1.01,12],[1,1.01,0]],"ltp":1.15,"tv":8.81,"id":9627400}]}]}
{"op":"mcm","clk":"4234996665","pt":1631551914646,"mc":[{"id":"1.187612427","rc":[{"batb":[[0,1.15,200],[1,1.01,12]],"ltp":1.15,"tv":8.81,"id":9627400}]}]}
{"op":"mcm","clk":"4235005031","pt":1631551998663,"mc":[{"id":"1.187612427","rc":[{"batb":[[0,1.01,12],[1,1.01,0]],"ltp":1.15,"tv":8.81,"id":9627400},{"batb":[[0,1.01,12],[1,1.01,0]],"ltp":2.54,"tv":0.91,"id":25977944}]}]}
{"op":"mcm","clk":"4235005485","pt":1631552003555,"mc":[{"id":"1.187612427","rc":[{"batb":[[0,1.12,249.99],[1,1.01,12]],"ltp":1.15,"tv":8.81,"id":9627400},{"batb":[[0,5.3,10],[1,1.01,12]],"ltp":2.54,"tv":0.91,"id":25977944}]}]}
{"op":"mcm","clk":"4235008284","pt":1631552032881,"mc":[{"id":"1.187612427","rc":[{"batb":[[0,1.01,12],[1,1.01,0]],"ltp":1.15,"tv":8.81,"id":9627400},{"batb":[[0,1.01,12],[1,1.01,0]],"ltp":2.54,"tv":0.91,"id":25977944}]}]}
{"op":"mcm","clk":"4235008712","pt":1631552037783,"mc":[{"id":"1.187612427","rc":[{"batb":[[0,1.15,200],[1,1.01,12]],"ltp":1.15,"tv":8.81,"id":9627400},{"batb":[[0,4.8,10],[1,1.01,12]],"ltp":2.54,"tv":0.91,"id":25977944}]}]}
{"op":"mcm","clk":"4235012243","pt":1631552071449,"mc":[{"id":"1.187612427","rc":[{"batb":[[0,1.01,12],[1,1.01,0]],"ltp":1.15,"tv":8.81,"id":9627400},{"batb":[[0,1.01,12],[1,1.01,0]],"ltp":2.54,"tv":0.91,"id":25977944}]}]}
{"op":"mcm","clk":"4235012760","pt":1631552076351,"mc":[{"id":"1.187612427","rc":[{"batb":[[0,1.18,166.66],[1,1.01,12]],"ltp":1.15,"tv":8.81,"id":9627400},{"batb":[[0,4.3,10],[1,1.01,12]],"ltp":2.54,"tv":0.91,"id":25977944}]}]}
{"op":"mcm","clk":"4235019586","pt":1631552142135,"mc":[{"id":"1.187612427","rc":[{"batb":[[0,1.01,12],[1,1.01,0]],"ltp":1.15,"tv":8.81,"id":9627400},{"batb":[[0,1.01,12],[1,1.01,0]],"ltp":2.54,"tv":0.91,"id":25977944}]}]}
{"op":"mcm","clk":"4235020054","pt":1631552147140,"mc":[{"id":"1.187612427","rc":[{"batb":[[0,1.2,150],[1,1.01,12]],"ltp":1.15,"tv":8.81,"id":9627400},{"batb":[[0,4,10],[1,1.01,12]],"ltp":2.54,"tv":0.91,"id":25977944}]}]}
{"op":"mcm","clk":"4235023310","pt":1631552177980,"mc":[{"id":"1.187612427","rc":[{"batb":[[0,1.01,12],[1,1.01,0]],"ltp":1.15,"tv":8.81,"id":9627400},{"batb":[[0,1.01,12],[1,1.01,0]],"ltp":2.54,"tv":0.91,"id":25977944}]}]}
{"op":"mcm","clk":"4235023785","pt":1631552182988,"mc":[{"id":"1.187612427","rc":[{"batb":[[0,1.23,130.43],[1,1.01,12]],"ltp":1.15,"tv":8.81,"id":9627400},{"batb":[[0,3.7,11.11],[1,1.01,12]],"ltp":2.54,"tv":0.91,"id":25977944}]}]}
{"op":"mcm","clk":"4235025329","pt":1631552199131,"mc":[{"id":"1.187612427","rc":[{"batb":[[0,1.01,12],[1,1.01,0]],"ltp":1.15,"tv":8.81,"id":9627400},{"batb":[[0,1.01,12],[1,1.01,0]],"ltp":2.54,"tv":0.91,"id":25977944}]}]}
{"op":"mcm","clk":"4235025827","pt":1631552204033,"mc":[{"id":"1.187612427","rc":[{"batb":[[0,1.2,150],[1,1.01,12]],"ltp":1.15,"tv":8.81,"id":9627400},{"batb":[[0,4,10],[1,1.01,12]],"ltp":2.54,"tv":0.91,"id":25977944}]}]}
{"op":"mcm","clk":"4235027922","pt":1631552223553,"mc":[{"id":"1.187612427","rc":[{"batb":[[0,1.01,12],[1,1.01,0]],"ltp":1.15,"tv":8.81,"id":9627400},{"batb":[[0,1.01,12],[1,1.01,0]],"ltp":2.54,"tv":0.91,"id":25977944}]}]}
{"op":"mcm","clk":"4235028487","pt":1631552228450,"mc":[{"id":"1.187612427","rc":[{"batb":[[0,1.23,130.43],[1,1.01,12]],"ltp":1.15,"tv":8.81,"id":9627400},{"batb":[[0,3.7,11.11],[1,1.01,12]],"ltp":2.54,"tv":0.91,"id":25977944}]}]}
{"op":"mcm","clk":"4235030102","pt":1631552245388,"mc":[{"id":"1.187612427","rc":[{"batb":[[0,1.01,12],[1,1.01,0]],"ltp":1.15,"tv":8.81,"id":9627400},{"batb":[[0,1.01,12],[1,1.01,0]],"ltp":2.54,"tv":0.91,"id":25977944}]}]}
{"op":"mcm","clk":"4235030610","pt":1631552250390,"mc":[{"id":"1.187612427","rc":[{"batb":[[0,1.27,111.11],[1,1.01,12]],"ltp":1.15,"tv":8.81,"id":9627400},{"batb":[[0,3.4,12.5],[1,1.01,12]],"ltp":2.54,"tv":0.91,"id":25977944}]}]}
{"op":"mcm","clk":"4235033659","pt":1631552279410,"mc":[{"id":"1.187612427","rc":[{"batb":[[0,1.01,12],[1,1.01,0]],"ltp":1.15,"tv":8.81,"id":9627400},{"batb":[[0,1.01,12],[1,1.01,0]],"ltp":2.54,"tv":0.91,"id":25977944}]}]}
{"op":"mcm","clk":"4235034209","pt":1631552284422,"mc":[{"id":"1.187612427","rc":[{"batb":[[0,1.23,130.43],[1,1.01,12]],"ltp":1.15,"tv":8.81,"id":9627400},{"batb":[[0,3.7,11.11],[1,1.01,12]],"ltp":2.54,"tv":0.91,"id":25977944}]}]}
{"op":"mcm","clk":"4235036338","pt":1631552303932,"mc":[{"id":"1.187612427","rc":[{"batb":[[0,1.01,12],[1,1.01,0]],"ltp":1.15,"tv":8.81,"id":9627400},{"batb":[[0,1.01,12],[1,1.01,0]],"ltp":2.54,"tv":0.91,"id":25977944}]}]}
{"op":"mcm","clk":"4235036929","pt":1631552308944,"mc":[{"id":"1.187612427","rc":[{"batb":[[0,1.28,107.14],[1,1.01,12]],"ltp":1.15,"tv":8.81,"id":9627400},{"batb":[[0,3.3,13.04],[1,1.01,12]],"ltp":2.54,"tv":0.91,"id":25977944}]}]}
{"op":"mcm","clk":"4235040833","pt":1631552340908,"mc":[{"id":"1.187612427","rc":[{"trd":[[1.28,17.97]],"batb":[[0,1.01,12],[1,1.01,0]],"ltp":1.28,"tv":26.78,"id":9627400},{"trd":[[4.6,5]],"ltp":4.6,"tv":5.91,"id":25977944}],"tv":32.69}]}
{"op":"mcm","clk":"4235041502","pt":1631552345806,"mc":[{"id":"1.187612427","rc":[{"batb":[[0,1.28,107.14],[1,1.01,12]],"ltp":1.28,"tv":26.78,"id":9627400}]}]}
{"op":"mcm","clk":"4235056009","pt":1631552456037,"mc":[{"id":"1.187612427","rc":[{"trd":[[1.34,3.42],[1.65,1.4]],"batb":[[0,1.01,12],[1,1.01,0]],"ltp":1.28,"tv":26.78,"id":9627400},{"batb":[[0,1.01,12],[1,1.01,0]],"ltp":4.6,"tv":5.91,"id":25977944}]}]}
{"op":"mcm","clk":"4235056712","pt":1631552461041,"mc":[{"id":"1.187612427","rc":[{"batb":[[0,1.38,78.94],[1,1.01,12]],"ltp":1.28,"tv":26.78,"id":9627400},{"batb":[[0,2.84,16.3],[1,1.01,12]],"ltp":4.6,"tv":5.91,"id":25977944}]}]}
{"op":"mcm","clk":"4235062099","pt":1631552497872,"mc":[{"id":"1.187612427","rc":[{"batb":[[0,1.01,12],[1,1.01,0]],"ltp":1.28,"tv":26.78,"id":9627400},{"batb":[[0,1.01,12],[1,1.01,0]],"ltp":4.6,"tv":5.91,"id":25977944}]}]}
{"op":"mcm","clk":"4235062821","pt":1631552502791,"mc":[{"id":"1.187612427","rc":[{"batb":[[0,1.48,62.5],[1,1.01,12]],"ltp":1.28,"tv":26.78,"id":9627400},{"batb":[[0,2.5,20],[1,1.01,12]],"ltp":4.6,"tv":5.91,"id":25977944}]}]}
{"op":"mcm","clk":"4235065948","pt":1631552523836,"mc":[{"id":"1.187612427","rc":[{"batb":[[0,1.01,12],[1,1.01,0]],"ltp":1.28,"tv":26.78,"id":9627400},{"batb":[[0,1.01,12],[1,1.01,0]],"ltp":4.6,"tv":5.91,"id":25977944}]}]}
{"op":"mcm","clk":"4235066683","pt":1631552528729,"mc":[{"id":"1.187612427","rc":[{"batb":[[0,1.6,49.99],[1,1.01,12]],"ltp":1.28,"tv":26.78,"id":9627400},{"batb":[[0,2.2,24.99],[1,1.01,12]],"ltp":4.6,"tv":5.91,"id":25977944}]}]}
{"op":"mcm","clk":"4235068506","pt":1631552542013,"mc":[{"id":"1.187612427","rc":[{"batb":[[0,1.01,12],[1,1.01,0]],"ltp":4.6,"tv":5.91,"id":25977944}]}]}
{"op":"mcm","clk":"4235069217","pt":1631552546950,"mc":[{"id":"1.187612427","rc":[{"batb":[[0,2.16,25.86],[1,1.01,12]],"ltp":4.6,"tv":5.91,"id":25977944}]}]}
{"op":"mcm","clk":"4235070789","pt":1631552558288,"mc":[{"id":"1.187612427","rc":[{"batb":[[0,1.01,12],[1,1.01,0]],"ltp":1.28,"tv":26.78,"id":9627400},{"batb":[[0,1.01,12],[1,1.01,0]],"ltp":4.6,"tv":5.91,"id":25977944}]}]}
{"op":"mcm","clk":"4235071491","pt":1631552563278,"mc":[{"id":"1.187612427","rc":[{"batb":[[0,1.51,58.82],[1,1.01,12]],"ltp":1.28,"tv":26.78,"id":9627400},{"batb":[[0,2.42,21.12],[1,1.01,12]],"ltp":4.6,"tv":5.91,"id":25977944}]}]}
{"op":"mcm","clk":"4235074467","pt":1631552584913,"mc":[{"id":"1.187612427","rc":[{"batb":[[0,1.01,12],[1,1.01,0]],"ltp":1.28,"tv":26.78,"id":9627400},{"batb":[[0,1.01,12],[1,1.01,0]],"ltp":4.6,"tv":5.91,"id":25977944}]}]}
{"op":"mcm","clk":"4235075156","pt":1631552589938,"mc":[{"id":"1.187612427","rc":[{"batb":[[0,1.65,46.15],[1,1.01,12]],"ltp":1.28,"tv":26.78,"id":9627400},{"batb":[[0,2.1,27.27],[1,1.01,12]],"ltp":4.6,"tv":5.91,"id":25977944}]}]}
{"op":"mcm","clk":"4235075446","pt":1631552591820,"mc":[{"id":"1.187612427","rc":[{"trd":[[1.65,1.62]],"batb":[[0,1.01,12],[1,1.01,0]],"ltp":1.65,"tv":27.0,"id":9627400}],"tv":32.91}]}
{"op":"mcm","clk":"4235076193","pt":1631552596870,"mc":[{"id":"1.187612427","rc":[{"batb":[[0,1.65,46.15],[1,1.01,12]],"ltp":1.65,"tv":27.0,"id":9627400}]}]}
{"op":"mcm","clk":"4235079677","pt":1631552621777,"mc":[{"id":"1.187612427","rc":[{"batb":[[0,1.01,12],[1,1.01,0]],"ltp":1.65,"tv":27.0,"id":9627400},{"batb":[[0,1.01,12],[1,1.01,0]],"ltp":4.6,"tv":5.91,"id":25977944}]}]}
{"op":"mcm","clk":"4235080352","pt":1631552626760,"mc":[{"id":"1.187612427","rc":[{"batb":[[0,1.55,54.54],[1,1.01,12]],"ltp":1.65,"tv":27.0,"id":9627400},{"batb":[[0,2.34,22.38],[1,1.01,12]],"ltp":4.6,"tv":5.91,"id":25977944}]}]}
{"op":"mcm","clk":"4235082557","pt":1631552640996,"mc":[{"id":"1.187612427","rc":[{"batb":[[0,1.01,12],[1,1.01,0]],"ltp":1.65,"tv":27.0,"id":9627400},{"batb":[[0,1.01,12],[1,1.01,0]],"ltp":4.6,"tv":5.91,"id":25977944}]}]}
{"op":"mcm","clk":"4235083254","pt":1631552645883,"mc":[{"id":"1.187612427","rc":[{"batb":[[0,1.51,58.82],[1,1.01,12]],"ltp":1.65,"tv":27.0,"id":9627400},{"batb":[[0,2.42,21.12],[1,1.01,12]],"ltp":4.6,"tv":5.91,"id":25977944}]}]}
{"op":"mcm","clk":"4235084866","pt":1631552657286,"mc":[{"id":"1.187612427","rc":[{"batb":[[0,1.01,12],[1,1.01,0]],"ltp":1.65,"tv":27.0,"id":9627400},{"batb":[[0,1.01,12],[1,1.01,0]],"ltp":4.6,"tv":5.91,"id":25977944}]}]}
{"op":"mcm","clk":"4235085617","pt":1631552662285,"mc":[{"id":"1.187612427","rc":[{"batb":[[0,1.42,71.42],[1,1.01,12]],"ltp":1.65,"tv":27.0,"id":9627400},{"batb":[[0,2.66,18.07],[1,1.01,12]],"ltp":4.6,"tv":5.91,"id":25977944}]}]}
{"op":"mcm","clk":"4235088100","pt":1631552678844,"mc":[{"id":"1.187612427","rc":[{"batb":[[0,1.01,12],[1,1.01,0]],"ltp":1.65,"tv":27.0,"id":9627400},{"batb":[[0,1.01,12],[1,1.01,0]],"ltp":4.6,"tv":5.91,"id":25977944}]}]}
{"op":"mcm","clk":"4235088835","pt":1631552683821,"mc":[{"id":"1.187612427","rc":[{"batb":[[0,1.51,58.82],[1,1.01,12]],"ltp":1.65,"tv":27.0,"id":9627400},{"batb":[[0,2.42,21.12],[1,1.01,12]],"ltp":4.6,"tv":5.91,"id":25977944}]}]}
{"op":"mcm","clk":"4235098205","pt":1631552745413,"mc":[{"id":"1.187612427","rc":[{"batb":[[0,1.01,12],[1,1.01,0]],"ltp":1.65,"tv":27.0,"id":9627400},{"batb":[[0,1.01,12],[1,1.01,0]],"ltp":4.6,"tv":5.91,"id":25977944}]}]}
{"op":"mcm","clk":"4235098968","pt":1631552750317,"mc":[{"id":"1.187612427","rc":[{"batb":[[0,1.63,47.61],[1,1.01,12]],"ltp":1.65,"tv":27.0,"id":9627400},{"batb":[[0,2.16,25.86],[1,1.01,12]],"ltp":4.6,"tv":5.91,"id":25977944}]}]}
{"op":"mcm","clk":"4235101311","pt":1631552765422,"mc":[{"id":"1.187612427","rc":[{"batb":[[0,1.01,12],[1,1.01,0]],"ltp":1.65,"tv":27.0,"id":9627400},{"batb":[[0,1.01,12],[1,1.01,0]],"ltp":4.6,"tv":5.91,"id":25977944}]}]}
{"op":"mcm","clk":"4235102098","pt":1631552770455,"mc":[{"id":"1.187612427","rc":[{"batb":[[0,1.48,62.5],[1,1.01,12]],"ltp":1.65,"tv":27.0,"id":9627400},{"batb":[[0,2.5,20],[1,1.01,12]],"ltp":4.6,"tv":5.91,"id":25977944}]}]}
{"op":"mcm","clk":"4235104557","pt":1631552785833,"mc":[{"id":"1.187612427","rc":[{"batb":[[0,1.01,12],[1,1.01,0]],"ltp":1.65,"tv":27.0,"id":9627400},{"batb":[[0,1.01,12],[1,1.01,0]],"ltp":4.6,"tv":5.91,"id":25977944}]}]}
{"op":"mcm","clk":"4235105399","pt":1631552790887,"mc":[{"id":"1.187612427","rc":[{"batb":[[0,1.34,88.23],[1,1.01,12]],"ltp":1.65,"tv":27.0,"id":9627400},{"batb":[[0,3,15],[1,1.01,12]],"ltp":4.6,"tv":5.91,"id":25977944}]}]}
{"op":"mcm","clk":"4235121207","pt":1631552889185,"mc":[{"id":"1.187612427","rc":[{"batb":[[0,1.01,12],[1,1.01,0]],"ltp":1.65,"tv":27.0,"id":9627400},{"batb":[[0,1.01,12],[1,1.01,0]],"ltp":4.6,"tv":5.91,"id":25977944}]}]}
{"op":"mcm","clk":"4235121965","pt":1631552894200,"mc":[{"id":"1.187612427","rc":[{"batb":[[0,1.27,111.11],[1,1.01,12]],"ltp":1.65,"tv":27.0,"id":9627400},{"batb":[[0,3.4,12.5],[1,1.01,12]],"ltp":4.6,"tv":5.91,"id":25977944}]}]}
{"op":"mcm","clk":"4235126543","pt":1631552924434,"mc":[{"id":"1.187612427","rc":[{"batb":[[0,1.01,12],[1,1.01,0]],"ltp":1.65,"tv":27.0,"id":9627400},{"batb":[[0,1.01,12],[1,1.01,0]],"ltp":4.6,"tv":5.91,"id":25977944}]}]}
{"op":"mcm","clk":"4235127302","pt":1631552929335,"mc":[{"id":"1.187612427","rc":[{"batb":[[0,1.2,150],[1,1.01,12]],"ltp":1.65,"tv":27.0,"id":9627400},{"batb":[[0,4,10],[1,1.01,12]],"ltp":4.6,"tv":5.91,"id":25977944}]}]}
{"op":"mcm","clk":"4235132967","pt":1631552967279,"mc":[{"id":"1.187612427","rc":[{"batb":[[0,1.01,12],[1,1.01,0]],"ltp":1.65,"tv":27.0,"id":9627400},{"batb":[[0,1.01,12],[1,1.01,0]],"ltp":4.6,"tv":5.91,"id":25977944}]}]}
{"op":"mcm","clk":"4235133700","pt":1631552972320,"mc":[{"id":"1.187612427","rc":[{"batb":[[0,1.27,111.11],[1,1.01,12]],"ltp":1.65,"tv":27.0,"id":9627400},{"batb":[[0,3.4,12.5],[1,1.01,12]],"ltp":4.6,"tv":5.91,"id":25977944}]}]}
{"op":"mcm","clk":"4235138444","pt":1631553005591,"mc":[{"id":"1.187612427","rc":[{"batb":[[0,1.01,12],[1,1.01,0]],"ltp":1.65,"tv":27.0,"id":9627400},{"batb":[[0,1.01,12],[1,1.01,0]],"ltp":4.6,"tv":5.91,"id":25977944}]}]}
{"op":"mcm","clk":"4235139247","pt":1631553010447,"mc":[{"id":"1.187612427","rc":[{"batb":[[0,1.34,88.23],[1,1.01,12]],"ltp":1.65,"tv":27.0,"id":9627400},{"batb":[[0,3,15],[1,1.01,12]],"ltp":4.6,"tv":5.91,"id":25977944}]}]}
{"op":"mcm","clk":"4235149114","pt":1631553076556,"mc":[{"id":"1.187612427","rc":[{"batb":[[0,1.01,12],[1,1.01,0]],"ltp":1.65,"tv":27.0,"id":9627400},{"batb":[[0,1.01,12],[1,1.01,0]],"ltp":4.6,"tv":5.91,"id":25977944}]}]}
{"op":"mcm","clk":"4235149881","pt":1631553081539,"mc":[{"id":"1.187612427","rc":[{"batb":[[0,1.48,62.5],[1,1.01,12]],"ltp":1.65,"tv":27.0,"id":9627400},{"batb":[[0,2.5,20],[1,1.01,12]],"ltp":4.6,"tv":5.91,"id":25977944}]}]}
{"op":"mcm","clk":"4235159143","pt":1631553142589,"mc":[{"id":"1.187612427","rc":[{"batb":[[0,1.01,12],[1,1.01,0]],"ltp":1.65,"tv":27.0,"id":9627400},{"batb":[[0,1.01,12],[1,1.01,0]],"ltp":4.6,"tv":5.91,"id":25977944}]}]}
{"op":"mcm","clk":"4235159897","pt":1631553147485,"mc":[{"id":"1.187612427","rc":[{"batb":[[0,1.34,88.23],[1,1.01,12]],"ltp":1.65,"tv":27.0,"id":9627400},{"batb":[[0,3,15],[1,1.01,12]],"ltp":4.6,"tv":5.91,"id":25977944}]}]}
{"op":"mcm","clk":"4235167937","pt":1631553203899,"mc":[{"id":"1.187612427","rc":[{"batb":[[0,1.01,12],[1,1.01,0]],"ltp":1.65,"tv":27.0,"id":9627400},{"batb":[[0,1.01,12],[1,1.01,0]],"ltp":4.6,"tv":5.91,"id":25977944}]}]}
{"op":"mcm","clk":"4235168692","pt":1631553208884,"mc":[{"id":"1.187612427","rc":[{"batb":[[0,1.27,111.11],[1,1.01,12]],"ltp":1.65,"tv":27.0,"id":9627400},{"batb":[[0,3.4,12.5],[1,1.01,12]],"ltp":4.6,"tv":5.91,"id":25977944}]}]}
{"op":"mcm","clk":"4235175504","pt":1631553255593,"mc":[{"id":"1.187612427","rc":[{"batb":[[0,1.01,12],[1,1.01,0]],"ltp":1.65,"tv":27.0,"id":9627400},{"batb":[[0,1.01,12],[1,1.01,0]],"ltp":4.6,"tv":5.91,"id":25977944}]}]}
{"op":"mcm","clk":"4235176295","pt":1631553260564,"mc":[{"id":"1.187612427","rc":[{"batb":[[0,1.34,88.23],[1,1.01,12]],"ltp":1.65,"tv":27.0,"id":9627400},{"batb":[[0,3,15],[1,1.01,12]],"ltp":4.6,"tv":5.91,"id":25977944}]}]}
{"op":"mcm","clk":"4235181640","pt":1631553297236,"mc":[{"id":"1.187612427","rc":[{"batb":[[0,1.01,12],[1,1.01,0]],"ltp":1.65,"tv":27.0,"id":9627400},{"batb":[[0,1.01,12],[1,1.01,0]],"ltp":4.6,"tv":5.91,"id":25977944}]}]}
{"op":"mcm","clk":"4235182406","pt":1631553302125,"mc":[{"id":"1.187612427","rc":[{"batb":[[0,1.27,111.11],[1,1.01,12]],"ltp":1.65,"tv":27.0,"id":9627400},{"batb":[[0,3.4,12.5],[1,1.01,12]],"ltp":4.6,"tv":5.91,"id":25977944}]}]}
{"op":"mcm","clk":"4235191305","pt":1631553361002,"mc":[{"id":"1.187612427","rc":[{"batb":[[0,1.01,12],[1,1.01,0]],"ltp":1.65,"tv":27.0,"id":9627400},{"batb":[[0,1.01,12],[1,1.01,0]],"ltp":4.6,"tv":5.91,"id":25977944}]}]}
{"op":"mcm","clk":"4235192168","pt":1631553366085,"mc":[{"id":"1.187612427","rc":[{"batb":[[0,1.34,88.23],[1,1.01,12]],"ltp":1.65,"tv":27.0,"id":9627400},{"batb":[[0,3,15],[1,1.01,12]],"ltp":4.6,"tv":5.91,"id":25977944}]}]}
{"op":"mcm","clk":"4235199626","pt":1631553413454,"mc":[{"id":"1.187612427","rc":[{"batb":[[0,1.01,12],[1,1.01,0]],"ltp":1.65,"tv":27.0,"id":9627400},{"batb":[[0,1.01,12],[1,1.01,0]],"ltp":4.6,"tv":5.91,"id":25977944}]}]}
{"op":"mcm","clk":"4235200430","pt":1631553418341,"mc":[{"id":"1.187612427","rc":[{"batb":[[0,1.27,111.11],[1,1.01,12]],"ltp":1.65,"tv":27.0,"id":9627400},{"batb":[[0,3.4,12.5],[1,1.01,12]],"ltp":4.6,"tv":5.91,"id":25977944}]}]}
{"op":"mcm","clk":"4235212087","pt":1631553496431,"mc":[{"id":"1.187612427","rc":[{"batb":[[0,1.01,12],[1,1.01,0]],"ltp":1.65,"tv":27.0,"id":9627400},{"batb":[[0,1.01,12],[1,1.01,0]],"ltp":4.6,"tv":5.91,"id":25977944}]}]}
{"op":"mcm","clk":"4235212831","pt":1631553501333,"mc":[{"id":"1.187612427","rc":[{"batb":[[0,1.34,88.23],[1,1.01,12]],"ltp":1.65,"tv":27.0,"id":9627400},{"batb":[[0,3,15],[1,1.01,12]],"ltp":4.6,"tv":5.91,"id":25977944}]}]}
{"op":"mcm","clk":"4235220230","pt":1631553555512,"mc":[{"id":"1.187612427","rc":[{"batb":[[0,1.01,12],[1,1.01,0]],"ltp":1.65,"tv":27.0,"id":9627400},{"batb":[[0,1.01,12],[1,1.01,0]],"ltp":4.6,"tv":5.91,"id":25977944}]}]}
{"op":"mcm","clk":"4235220905","pt":1631553560505,"mc":[{"id":"1.187612427","rc":[{"batb":[[0,1.27,111.11],[1,1.01,12]],"ltp":1.65,"tv":27.0,"id":9627400},{"batb":[[0,3.4,12.5],[1,1.01,12]],"ltp":4.6,"tv":5.91,"id":25977944}]}]}
{"op":"mcm","clk":"4235225664","pt":1631553595645,"mc":[{"id":"1.187612427","rc":[{"batb":[[0,1.01,12],[1,1.01,0]],"ltp":1.65,"tv":27.0,"id":9627400},{"batb":[[0,1.01,12],[1,1.01,0]],"ltp":4.6,"tv":5.91,"id":25977944}]}]}
{"op":"mcm","clk":"4235226336","pt":1631553600565,"mc":[{"id":"1.187612427","rc":[{"batb":[[0,1.18,166.66],[1,1.01,12]],"ltp":1.65,"tv":27.0,"id":9627400},{"batb":[[0,4.1,10],[1,1.01,12]],"ltp":4.6,"tv":5.91,"id":25977944}]}]}
{"op":"mcm","clk":"4235257671","pt":1631553816324,"mc":[{"id":"1.187612427","rc":[{"trd":[[1.18,6]],"batb":[[0,1.01,12],[1,1.01,0]],"ltp":1.18,"tv":33.0,"id":9627400}],"tv":38.91}]}
{"op":"mcm","clk":"4235258501","pt":1631553821352,"mc":[{"id":"1.187612427","rc":[{"batb":[[0,1.18,166.66],[1,1.01,12]],"ltp":1.18,"tv":33.0,"id":9627400}]}]}
{"op":"mcm","clk":"4235278281","pt":1631553954213,"mc":[{"id":"1.187612427","rc":[{"batb":[[0,1.01,12],[1,1.01,0]],"ltp":1.18,"tv":33.0,"id":9627400},{"batb":[[0,1.01,12],[1,1.01,0]],"ltp":4.6,"tv":5.91,"id":25977944}]}]}
{"op":"mcm","clk":"4235279069","pt":1631553959205,"mc":[{"id":"1.187612427","rc":[{"batb":[[0,1.2,150],[1,1.01,12]],"ltp":1.18,"tv":33.0,"id":9627400},{"batb":[[0,3.95,10.16],[1,1.01,12]],"ltp":4.6,"tv":5.91,"id":25977944}]}]}
{"op":"mcm","clk":"4235282352","pt":1631553982447,"mc":[{"id":"1.187612427","rc":[{"batb":[[0,1.01,12],[1,1.01,0]],"ltp":1.18,"tv":33.0,"id":9627400},{"batb":[[0,1.01,12],[1,1.01,0]],"ltp":4.6,"tv":5.91,"id":25977944}]}]}
{"op":"mcm","clk":"4235283022","pt":1631553987351,"mc":[{"id":"1.187612427","rc":[{"batb":[[0,1.18,166.66],[1,1.01,12]],"ltp":1.18,"tv":33.0,"id":9627400},{"batb":[[0,4.3,10],[1,1.01,12]],"ltp":4.6,"tv":5.91,"id":25977944}]}]}
{"op":"mcm","clk":"4235285035","pt":1631554002094,"mc":[{"id":"1.187612427","rc":[{"batb":[[0,1.01,12],[1,1.01,0]],"ltp":1.18,"tv":33.0,"id":9627400},{"batb":[[0,1.01,12],[1,1.01,0]],"ltp":4.6,"tv":5.91,"id":25977944}]}]}
{"op":"mcm","clk":"4235285749","pt":1631554006985,"mc":[{"id":"1.187612427","rc":[{"batb":[[0,1.15,200],[1,1.01,12]],"ltp":1.18,"tv":33.0,"id":9627400},{"batb":[[0,4.8,10],[1,1.01,12]],"ltp":4.6,"tv":5.91,"id":25977944}]}]}
{"op":"mcm","clk":"4235287439","pt":1631554018396,"mc":[{"id":"1.187612427","rc":[{"batb":[[0,1.01,12],[1,1.01,0]],"ltp":1.18,"tv":33.0,"id":9627400},{"batb":[[0,1.01,12],[1,1.01,0]],"ltp":4.6,"tv":5.91,"id":25977944}]}]}
{"op":"mcm","clk":"4235288182","pt":1631554023290,"mc":[{"id":"1.187612427","rc":[{"batb":[[0,1.18,166.66],[1,1.01,12]],"ltp":1.18,"tv":33.0,"id":9627400},{"batb":[[0,4.3,10],[1,1.01,12]],"ltp":4.6,"tv":5.91,"id":25977944}]}]}
{"op":"mcm","clk":"4235291367","pt":1631554045528,"mc":[{"id":"1.187612427","rc":[{"batb":[[0,1.01,12],[1,1.01,0]],"ltp":1.18,"tv":33.0,"id":9627400},{"batb":[[0,1.01,12],[1,1.01,0]],"ltp":4.6,"tv":5.91,"id":25977944}]}]}
{"op":"mcm","clk":"4235292061","pt":1631554050419,"mc":[{"id":"1.187612427","rc":[{"batb":[[0,1.2,150],[1,1.01,12]],"ltp":1.18,"tv":33.0,"id":9627400},{"batb":[[0,3.95,10.16],[1,1.01,12]],"ltp":4.6,"tv":5.91,"id":25977944}]}]}
{"op":"mcm","clk":"4235295691","pt":1631554076678,"mc":[{"id":"1.187612427","rc":[{"batb":[[0,1.01,12],[1,1.01,0]],"ltp":1.18,"tv":33.0,"id":9627400},{"batb":[[0,1.01,12],[1,1.01,0]],"ltp":4.6,"tv":5.91,"id":25977944}]}]}
{"op":"mcm","clk":"4235296369","pt":1631554081694,"mc":[{"id":"1.187612427","rc":[{"batb":[[0,1.18,166.66],[1,1.01,12]],"ltp":1.18,"tv":33.0,"id":9627400},{"batb":[[0,4.3,10],[1,1.01,12]],"ltp":4.6,"tv":5.91,"id":25977944}]}]}
{"op":"mcm","clk":"4235301762","pt":1631554119796,"mc":[{"id":"1.187612427","rc":[{"batb":[[0,1.01,12],[1,1.01,0]],"ltp":1.18,"tv":33.0,"id":9627400},{"batb":[[0,1.01,12],[1,1.01,0]],"ltp":4.6,"tv":5.91,"id":25977944}]}]}
{"op":"mcm","clk":"4235302400","pt":1631554124732,"mc":[{"id":"1.187612427","rc":[{"batb":[[0,1.2,150],[1,1.01,12]],"ltp":1.18,"tv":33.0,"id":9627400},{"batb":[[0,3.95,10.16],[1,1.01,12]],"ltp":4.6,"tv":5.91,"id":25977944}]}]}
{"op":"mcm","clk":"4235306251","pt":1631554153830,"mc":[{"id":"1.187612427","rc":[{"batb":[[0,1.01,12],[1,1.01,0]],"ltp":1.18,"tv":33.0,"id":9627400},{"batb":[[0,1.01,12],[1,1.01,0]],"ltp":4.6,"tv":5.91,"id":25977944}]}]}
{"op":"mcm","clk":"4235306950","pt":1631554158754,"mc":[{"id":"1.187612427","rc":[{"batb":[[0,1.18,166.66],[1,1.01,12]],"ltp":1.18,"tv":33.0,"id":9627400},{"batb":[[0,4.3,10],[1,1.01,12]],"ltp":4.6,"tv":5.91,"id":25977944}]}]}
{"op":"mcm","clk":"4235313342","pt":1631554203318,"mc":[{"id":"1.187612427","rc":[{"batb":[[0,1.01,12],[1,1.01,0]],"ltp":1.18,"tv":33.0,"id":9627400},{"batb":[[0,1.01,12],[1,1.01,0]],"ltp":4.6,"tv":5.91,"id":25977944}]}]}
{"op":"mcm","clk":"4235314102","pt":1631554208343,"mc":[{"id":"1.187612427","rc":[{"batb":[[0,1.12,249.99],[1,1.01,12]],"ltp":1.18,"tv":33.0,"id":9627400},{"batb":[[0,5.3,10],[1,1.01,12]],"ltp":4.6,"tv":5.91,"id":25977944}]}]}
{"op":"mcm","clk":"4235317675","pt":1631554231926,"mc":[{"id":"1.187612427","rc":[{"batb":[[0,1.01,12],[1,1.01,0]],"ltp":1.18,"tv":33.0,"id":9627400},{"batb":[[0,1.01,12],[1,1.01,0]],"ltp":4.6,"tv":5.91,"id":25977944}]}]}
{"op":"mcm","clk":"4235318384","pt":1631554236869,"mc":[{"id":"1.187612427","rc":[{"batb":[[0,1.11,272.72],[1,1.01,12]],"ltp":1.18,"tv":33.0,"id":9627400},{"batb":[[0,5.8,10],[1,1.01,12]],"ltp":4.6,"tv":5.91,"id":25977944}]}]}
{"op":"mcm","clk":"4235319260","pt":1631554243249,"mc":[{"id":"1.187612427","rc":[{"batb":[[0,1.01,12],[1,1.01,0]],"ltp":1.18,"tv":33.0,"id":9627400},{"batb":[[0,1.01,12],[1,1.01,0]],"ltp":4.6,"tv":5.91,"id":25977944}]}]}
{"op":"mcm","clk":"4235319957","pt":1631554248277,"mc":[{"id":"1.187612427","rc":[{"batb":[[0,1.18,166.66],[1,1.01,12]],"ltp":1.18,"tv":33.0,"id":9627400},{"batb":[[0,4.3,10],[1,1.01,12]],"ltp":4.6,"tv":5.91,"id":25977944}]}]}
{"op":"mcm","clk":"4235322946","pt":1631554267587,"mc":[{"id":"1.187612427","rc":[{"batb":[[0,1.01,12],[1,1.01,0]],"ltp":1.18,"tv":33.0,"id":9627400},{"batb":[[0,1.01,12],[1,1.01,0]],"ltp":4.6,"tv":5.91,"id":25977944}]}]}
{"op":"mcm","clk":"4235323593","pt":1631554272472,"mc":[{"id":"1.187612427","rc":[{"batb":[[0,1.15,200],[1,1.01,12]],"ltp":1.18,"tv":33.0,"id":9627400},{"batb":[[0,4.8,10],[1,1.01,12]],"ltp":4.6,"tv":5.91,"id":25977944}]}]}
{"op":"mcm","clk":"4235325490","pt":1631554285895,"mc":[{"id":"1.187612427","rc":[{"batb":[[0,1.01,12],[1,1.01,0]],"ltp":1.18,"tv":33.0,"id":9627400},{"batb":[[0,1.01,12],[1,1.01,0]],"ltp":4.6,"tv":5.91,"id":25977944}]}]}
{"op":"mcm","clk":"4235326272","pt":1631554290935,"mc":[{"id":"1.187612427","rc":[{"batb":[[0,1.12,249.99],[1,1.01,12]],"ltp":1.18,"tv":33.0,"id":9627400},{"batb":[[0,5.3,10],[1,1.01,12]],"ltp":4.6,"tv":5.91,"id":25977944}]}]}
{"op":"mcm","clk":"4235328461","pt":1631554305341,"mc":[{"id":"1.187612427","rc":[{"batb":[[0,1.01,12],[1,1.01,0]],"ltp":1.18,"tv":33.0,"id":9627400}]}]}
{"op":"mcm","clk":"4235329199","pt":1631554310329,"mc":[{"id":"1.187612427","rc":[{"batb":[[0,1.11,272.72],[1,1.01,12]],"ltp":1.18,"tv":33.0,"id":9627400}]}]}
{"op":"mcm","clk":"4235330073","pt":1631554316175,"mc":[{"id":"1.187612427","rc":[{"batb":[[0,1.01,12],[1,1.01,0]],"ltp":1.18,"tv":33.0,"id":9627400},{"batb":[[0,1.01,12],[1,1.01,0]],"ltp":4.6,"tv":5.91,"id":25977944}]}]}
{"op":"mcm","clk":"4235330834","pt":1631554321140,"mc":[{"id":"1.187612427","rc":[{"batb":[[0,1.08,374.99],[1,1.01,12]],"ltp":1.18,"tv":33.0,"id":9627400},{"batb":[[0,6,10],[1,1.01,12]],"ltp":4.6,"tv":5.91,"id":25977944}]}]}
{"op":"mcm","clk":"4235343129","pt":1631554402281,"mc":[{"id":"1.187612427","rc":[{"batb":[[0,1.01,12],[1,1.01,0]],"ltp":1.18,"tv":33.0,"id":9627400},{"batb":[[0,1.01,12],[1,1.01,0]],"ltp":4.6,"tv":5.91,"id":25977944}]}]}
{"op":"mcm","clk":"4235343869","pt":1631554407185,"mc":[{"id":"1.187612427","rc":[{"batb":[[0,1.05,599.99],[1,1.01,12]],"ltp":1.18,"tv":33.0,"id":9627400},{"batb":[[0,7.6,10],[1,1.01,12]],"ltp":4.6,"tv":5.91,"id":25977944}]}]}
{"op":"mcm","clk":"4235347147","pt":1631554429215,"mc":[{"id":"1.187612427","rc":[{"batb":[[0,1.01,12],[1,1.01,0]],"ltp":1.18,"tv":33.0,"id":9627400},{"batb":[[0,1.01,12],[1,1.01,0]],"ltp":4.6,"tv":5.91,"id":25977944}]}]}
{"op":"mcm","clk":"4235347863","pt":1631554434117,"mc":[{"id":"1.187612427","rc":[{"batb":[[0,1.08,374.99],[1,1.01,12]],"ltp":1.18,"tv":33.0,"id":9627400},{"batb":[[0,6,10],[1,1.01,12]],"ltp":4.6,"tv":5.91,"id":25977944}]}]}
{"op":"mcm","clk":"4235353457","pt":1631554469658,"mc":[{"id":"1.187612427","rc":[{"batb":[[0,1.01,12],[1,1.01,0]],"ltp":1.18,"tv":33.0,"id":9627400},{"batb":[[0,1.01,12],[1,1.01,0]],"ltp":4.6,"tv":5.91,"id":25977944}]}]}
{"op":"mcm","clk":"4235354191","pt":1631554474643,"mc":[{"id":"1.187612427","rc":[{"batb":[[0,1.05,599.99],[1,1.01,12]],"ltp":1.18,"tv":33.0,"id":9627400},{"batb":[[0,7.6,10],[1,1.01,12]],"ltp":4.6,"tv":5.91,"id":25977944}]}]}
{"op":"mcm","clk":"4235363583","pt":1631554534843,"mc":[{"id":"1.187612427","rc":[{"batb":[[0,1.01,12],[1,1.01,0]],"ltp":1.18,"tv":33.0,"id":9627400},{"batb":[[0,1.01,12],[1,1.01,0]],"ltp":4.6,"tv":5.91,"id":25977944}]}]}
{"op":"mcm","clk":"4235364450","pt":1631554539894,"mc":[{"id":"1.187612427","rc":[{"batb":[[0,1.08,374.99],[1,1.01,12]],"ltp":1.18,"tv":33.0,"id":9627400},{"batb":[[0,6,10],[1,1.01,12]],"ltp":4.6,"tv":5.91,"id":25977944}]}]}
{"op":"mcm","clk":"4235370054","pt":1631554575699,"mc":[{"id":"1.187612427","rc":[{"batb":[[0,1.01,12],[1,1.01,0]],"ltp":1.18,"tv":33.0,"id":9627400},{"batb":[[0,1.01,12],[1,1.01,0]],"ltp":4.6,"tv":5.91,"id":25977944}]}]}
{"op":"mcm","clk":"4235370808","pt":1631554580687,"mc":[{"id":"1.187612427","rc":[{"batb":[[0,1.05,599.99],[1,1.01,12]],"ltp":1.18,"tv":33.0,"id":9627400},{"batb":[[0,7.6,10],[1,1.01,12]],"ltp":4.6,"tv":5.91,"id":25977944}]}]}
{"op":"mcm","clk":"4235373145","pt":1631554597307,"mc":[{"id":"1.187612427","rc":[{"batb":[[0,1.07,84.27],[1,1.05,599.99],[2,1.01,12]],"ltp":1.18,"tv":33.0,"id":9627400}]}]}
{"op":"mcm","clk":"4235373282","pt":1631554598310,"mc":[{"id":"1.187612427","rc":[{"batb":[[1,1.06,56.18],[2,1.05,599.99]],"ltp":1.18,"tv":33.0,"id":9627400}]}]}
{"op":"mcm","clk":"4235373434","pt":1631554599485,"mc":[{"id":"1.187612427","rc":[{"batb":[[0,1.07,112.36],[1,1.06,168.54]],"ltp":1.18,"tv":33.0,"id":9627400}]}]}
{"op":"mcm","clk":"4235373536","pt":1631554600280,"mc":[{"id":"1.187612427","rc":[{"batb":[[1,1.06,252.81]],"ltp":1.18,"tv":33.0,"id":9627400}]}]}
{"op":"mcm","clk":"4235373670","pt":1631554601111,"mc":[{"id":"1.187612427","rc":[{"batb":[[1,1.06,337.08]],"ltp":1.18,"tv":33.0,"id":9627400}]}]}
{"op":"mcm","clk":"4235375921","pt":1631554616429,"mc":[{"id":"1.187612427","rc":[{"batb":[[2,1.01,12]],"ltp":1.18,"tv":33.0,"id":9627400},{"batb":[[0,1.01,12],[1,1.01,0]],"ltp":4.6,"tv":5.91,"id":25977944}]}]}
{"op":"mcm","clk":"4235376528","pt":1631554620344,"mc":[{"id":"1.187612427","rc":[{"batb":[[0,1.06,337.08],[1,1.01,12],[2,1.01,0]],"ltp":1.18,"tv":33.0,"id":9627400}]}]}
{"op":"mcm","clk":"4235376711","pt":1631554621405,"mc":[{"id":"1.187612427","rc":[{"batb":[[0,1.03,999.99]],"ltp":1.18,"tv":33.0,"id":9627400},{"batb":[[0,9.6,10],[1,1.01,12]],"ltp":4.6,"tv":5.91,"id":25977944}]}]}
{"op":"mcm","clk":"4235377609","pt":1631554627211,"mc":[{"id":"1.187612427","rc":[{"batb":[[0,1.05,112.36],[1,1.03,999.99],[2,1.01,12]],"ltp":1.18,"tv":33.0,"id":9627400}]}]}
{"op":"mcm","clk":"4235377759","pt":1631554628417,"mc":[{"id":"1.187612427","rc":[{"batb":[[0,1.05,224.72]],"ltp":1.18,"tv":33.0,"id":9627400}]}]}
{"op":"mcm","clk":"4235377920","pt":1631554629213,"mc":[{"id":"1.187612427","rc":[{"batb":[[0,1.05,365.17]],"ltp":1.18,"tv":33.0,"id":9627400}]}]}
{"op":"mcm","clk":"4235378008","pt":1631554629742,"mc":[{"id":"1.187612427","rc":[{"batb":[[0,1.05,393.26]],"ltp":1.18,"tv":33.0,"id":9627400}]}]}
{"op":"mcm","clk":"4235381665","pt":1631554655039,"mc":[{"id":"1.187612427","rc":[{"batb":[[1,1.01,12],[2,1.01,0]],"ltp":1.18,"tv":33.0,"id":9627400},{"batb":[[0,1.01,12],[1,1.01,0]],"ltp":4.6,"tv":5.91,"id":25977944}]}]}
{"op":"mcm","clk":"4235382376","pt":1631554659956,"mc":[{"id":"1.187612427","rc":[{"batb":[[0,1.05,993.25]],"ltp":1.18,"tv":33.0,"id":9627400},{"batb":[[0,7.6,10],[1,1.01,12]],"ltp":4.6,"tv":5.91,"id":25977944}]}]}
{"op":"mcm","clk":"4235384898","pt":1631554676266,"mc":[{"id":"1.187612427","rc":[{"batb":[[0,1.05,393.26]],"ltp":1.18,"tv":33.0,"id":9627400},{"batb":[[0,1.01,12],[1,1.01,0]],"ltp":4.6,"tv":5.91,"id":25977944}]}]}
{"op":"mcm","clk":"4235385636","pt":1631554681280,"mc":[{"id":"1.187612427","rc":[{"batb":[[1,1.03,999.99],[2,1.01,12]],"ltp":1.18,"tv":33.0,"id":9627400},{"batb":[[0,8.6,10],[1,1.01,12]],"ltp":4.6,"tv":5.91,"id":25977944}]}]}
{"op":"mcm","clk":"4235389258","pt":1631554704635,"mc":[{"id":"1.187612427","rc":[{"batb":[[1,1.01,12],[2,1.01,0]],"ltp":1.18,"tv":33.0,"id":9627400},{"batb":[[0,1.01,12],[1,1.01,0]],"ltp":4.6,"tv":5.91,"id":25977944}]}]}
{"op":"mcm","clk":"4235390139","pt":1631554709626,"mc":[{"id":"1.187612427","rc":[{"batb":[[0,1.05,993.25]],"ltp":1.18,"tv":33.0,"id":9627400},{"batb":[[0,7.6,10],[1,1.01,12]],"ltp":4.6,"tv":5.91,"id":25977944}]}]}
{"op":"mcm","clk":"4235394368","pt":1631554738770,"mc":[{"id":"1.187612427","rc":[{"batb":[[0,1.05,393.26]],"ltp":1.18,"tv":33.0,"id":9627400},{"batb":[[0,1.01,12],[1,1.01,0]],"ltp":4.6,"tv":5.91,"id":25977944}]}]}
{"op":"mcm","clk":"4235395121","pt":1631554743651,"mc":[{"id":"1.187612427","rc":[{"batb":[[0,1.06,499.99],[1,1.05,393.26],[2,1.01,12]],"ltp":1.18,"tv":33.0,"id":9627400},{"batb":[[0,7,10],[1,1.01,12]],"ltp":4.6,"tv":5.91,"id":25977944}]}]}
{"op":"mcm","clk":"4235396708","pt":1631554753684,"mc":[{"id":"1.187612427","rc":[{"batb":[[1,1.01,12],[2,1.01,0]],"ltp":1.18,"tv":33.0,"id":9627400}]}]}
{"op":"mcm","clk":"4235399024","pt":1631554769489,"mc":[{"id":"1.187612427","rc":[{"batb":[[0,1.01,12],[1,1.01,0]],"ltp":1.18,"tv":33.0,"id":9627400},{"batb":[[0,1.01,12],[1,1.01,0]],"ltp":4.6,"tv":5.91,"id":25977944}]}]}
{"op":"mcm","clk":"4235399778","pt":1631554774515,"mc":[{"id":"1.187612427","rc":[{"batb":[[0,1.08,374.99],[1,1.01,12]],"ltp":1.18,"tv":33.0,"id":9627400},{"batb":[[0,6,10],[1,1.01,12]],"ltp":4.6,"tv":5.91,"id":25977944}]}]}
{"op":"mcm","clk":"4235417435","pt":1631554890482,"mc":[{"id":"1.187612427","rc":[{"batb":[[0,1.01,12],[1,1.01,0]],"ltp":1.18,"tv":33.0,"id":9627400},{"batb":[[0,1.01,12],[1,1.01,0]],"ltp":4.6,"tv":5.91,"id":25977944}]}]}
{"op":"mcm","clk":"4235418109","pt":1631554895477,"mc":[{"id":"1.187612427","rc":[{"batb":[[0,1.05,599.99],[1,1.01,12]],"ltp":1.18,"tv":33.0,"id":9627400},{"batb":[[0,7.6,10],[1,1.01,12]],"ltp":4.6,"tv":5.91,"id":25977944}]}]}
{"op":"mcm","clk":"4235427216","pt":1631554959187,"mc":[{"id":"1.187612427","rc":[{"batb":[[0,1.01,12],[1,1.01,0]],"ltp":1.18,"tv":33.0,"id":9627400},{"batb":[[0,1.01,12],[1,1.01,0]],"ltp":4.6,"tv":5.91,"id":25977944}]}]}
{"op":"mcm","clk":"4235427901","pt":1631554964170,"mc":[{"id":"1.187612427","rc":[{"batb":[[0,1.08,374.99],[1,1.01,12]],"ltp":1.18,"tv":33.0,"id":9627400},{"batb":[[0,6,10],[1,1.01,12]],"ltp":4.6,"tv":5.91,"id":25977944}]}]}
{"op":"mcm","clk":"4235434315","pt":1631555006345,"mc":[{"id":"1.187612427","rc":[{"batb":[[0,1.01,12],[1,1.01,0]],"ltp":1.18,"tv":33.0,"id":9627400},{"batb":[[0,1.01,12],[1,1.01,0]],"ltp":4.6,"tv":5.91,"id":25977944}]}]}
{"op":"mcm","clk":"4235435062","pt":1631555011289,"mc":[{"id":"1.187612427","rc":[{"batb":[[0,1.05,599.99],[1,1.01,12]],"ltp":1.18,"tv":33.0,"id":9627400},{"batb":[[0,7.6,10],[1,1.01,12]],"ltp":4.6,"tv":5.91,"id":25977944}]}]}
{"op":"mcm","clk":"4235439593","pt":1631555040790,"mc":[{"id":"1.187612427","rc":[{"batb":[[0,1.01,12],[1,1.01,0]],"ltp":1.18,"tv":33.0,"id":9627400},{"batb":[[0,1.01,12],[1,1.01,0]],"ltp":4.6,"tv":5.91,"id":25977944}]}]}
{"op":"mcm","clk":"4235440333","pt":1631555045760,"mc":[{"id":"1.187612427","rc":[{"batb":[[0,1.04,749.99],[1,1.01,12]],"ltp":1.18,"tv":33.0,"id":9627400},{"batb":[[0,8.6,10],[1,1.01,12]],"ltp":4.6,"tv":5.91,"id":25977944}]}]}
{"op":"mcm","clk":"4235442909","pt":1631555062507,"mc":[{"id":"1.187612427","rc":[{"batb":[[0,1.01,12],[1,1.01,0]],"ltp":4.6,"tv":5.91,"id":25977944}]}]}
{"op":"mcm","clk":"4235443624","pt":1631555067423,"mc":[{"id":"1.187612427","rc":[{"batb":[[0,8,10],[1,1.01,12]],"ltp":4.6,"tv":5.91,"id":25977944}]}]}
{"op":"mcm","clk":"4235447539","pt":1631555092369,"mc":[{"id":"1.187612427","rc":[{"batb":[[0,1.01,12],[1,1.01,0]],"ltp":1.18,"tv":33.0,"id":9627400},{"batb":[[0,1.01,12],[1,1.01,0]],"ltp":4.6,"tv":5.91,"id":25977944}]}]}
{"op":"mcm","clk":"4235448281","pt":1631555097251,"mc":[{"id":"1.187612427","rc":[{"batb":[[0,1.05,599.99],[1,1.01,12]],"ltp":1.18,"tv":33.0,"id":9627400},{"batb":[[0,7.6,10],[1,1.01,12]],"ltp":4.6,"tv":5.91,"id":25977944}]}]}
{"op":"mcm","clk":"4235470843","pt":1631555248232,"mc":[{"id":"1.187612427","rc":[{"batb":[[0,1.01,12],[1,1.01,0]],"ltp":1.18,"tv":33.0,"id":9627400},{"batb":[[0,1.01,12],[1,1.01,0]],"ltp":4.6,"tv":5.91,"id":25977944}]}]}
{"op":"mcm","clk":"4235471622","pt":1631555253292,"mc":[{"id":"1.187612427","rc":[{"batb":[[0,1.08,374.99],[1,1.01,12]],"ltp":1.18,"tv":33.0,"id":9627400},{"batb":[[0,6,10],[1,1.01,12]],"ltp":4.6,"tv":5.91,"id":25977944}]}]}
{"op":"mcm","clk":"4235476046","pt":1631555284677,"mc":[{"id":"1.187612427","rc":[{"batb":[[0,1.01,12],[1,1.01,0]],"ltp":1.18,"tv":33.0,"id":9627400},{"batb":[[0,1.01,12],[1,1.01,0]],"ltp":4.6,"tv":5.91,"id":25977944}]}]}
{"op":"mcm","clk":"4235476789","pt":1631555289697,"mc":[{"id":"1.187612427","rc":[{"batb":[[0,1.05,599.99],[1,1.01,12]],"ltp":1.18,"tv":33.0,"id":9627400},{"batb":[[0,7.6,10],[1,1.01,12]],"ltp":4.6,"tv":5.91,"id":25977944}]}]}
{"op":"mcm","clk":"4235480162","pt":1631555314959,"mc":[{"id":"1.187612427","rc":[{"batb":[[0,1.01,12],[1,1.01,0]],"ltp":1.18,"tv":33.0,"id":9627400},{"batb":[[0,1.01,12],[1,1.01,0]],"ltp":4.6,"tv":5.91,"id":25977944}]}]}
{"op":"mcm","clk":"4235480783","pt":1631555319845,"mc":[{"id":"1.187612427","rc":[{"batb":[[0,1.03,999.99],[1,1.01,12]],"ltp":1.18,"tv":33.0,"id":9627400},{"batb":[[0,9.6,10],[1,1.01,12]],"ltp":4.6,"tv":5.91,"id":25977944}]}]}
{"op":"mcm","clk":"4235489691","pt":1631555390908,"mc":[{"id":"1.187612427","rc":[{"batb":[[0,1.01,12],[1,1.01,0]],"ltp":1.18,"tv":33.0,"id":9627400},{"batb":[[0,1.01,12],[1,1.01,0]],"ltp":4.6,"tv":5.91,"id":25977944}]}]}
{"op":"mcm","clk":"4235490303","pt":1631555395831,"mc":[{"id":"1.187612427","rc":[{"batb":[[0,11,10],[1,1.01,12]],"ltp":4.6,"tv":5.91,"id":25977944}]}]}
{"op":"mcm","clk":"4235499060","pt":1631555470224,"mc":[{"id":"1.187612427","rc":[{"batb":[[0,1.01,12],[1,1.01,0]],"ltp":4.6,"tv":5.91,"id":25977944}]}]}
{"op":"mcm","clk":"4235499557","pt":1631555475108,"mc":[{"id":"1.187612427","rc":[{"batb":[[0,14,10],[1,1.01,12]],"ltp":4.6,"tv":5.91,"id":25977944}]}]}
{"op":"mcm","clk":"4235504627","pt":1631555525721,"mc":[{"id":"1.187612427","rc":[{"batb":[[0,1.01,12],[1,1.01,0]],"ltp":4.6,"tv":5.91,"id":25977944}]}]}
{"op":"mcm","clk":"4235505202","pt":1631555530674,"mc":[{"id":"1.187612427","rc":[{"batb":[[0,12,10],[1,1.01,12]],"ltp":4.6,"tv":5.91,"id":25977944}]}]}
{"op":"mcm","clk":"4235507128","pt":1631555549019,"mc":[{"id":"1.187612427","rc":[{"batb":[[0,1.01,12],[1,1.01,0]],"ltp":4.6,"tv":5.91,"id":25977944}]}]}
{"op":"mcm","clk":"4235507587","pt":1631555553926,"mc":[{"id":"1.187612427","rc":[{"batb":[[0,16,10],[1,1.01,12]],"ltp":4.6,"tv":5.91,"id":25977944}]}]}
{"op":"mcm","clk":"4235513103","pt":1631555597669,"mc":[{"id":"1.187612427","rc":[{"batb":[[0,1.01,12],[1,1.01,0]],"ltp":4.6,"tv":5.91,"id":25977944}]}]}
{"op":"mcm","clk":"4235513723","pt":1631555602658,"mc":[{"id":"1.187612427","rc":[{"batb":[[0,12,10],[1,1.01,12]],"ltp":4.6,"tv":5.91,"id":25977944}]}]}
{"op":"mcm","clk":"4235518063","pt":1631555641345,"mc":[{"id":"1.187612427","rc":[{"batb":[[0,1.01,12],[1,1.01,0]],"ltp":4.6,"tv":5.91,"id":25977944}]}]}
{"op":"mcm","clk":"4235518590","pt":1631555646215,"mc":[{"id":"1.187612427","rc":[{"batb":[[0,19.5,10],[1,1.01,12]],"ltp":4.6,"tv":5.91,"id":25977944}]}]}
{"op":"mcm","clk":"4235521367","pt":1631555671254,"mc":[{"id":"1.187612427","rc":[{"trd":[[1.01,24]],"batl":[[0,1.01,93],[1,1.71,0.52]],"ltp":1.01,"tv":57.0,"id":9627400}],"tv":62.91}]}
{"op":"mcm","clk":"4235525995","pt":1631555710446,"mc":[{"id":"1.187612427","rc":[{"trd":[[1.01,210]],"batb":[[0,1.01,19.36]],"batl":[[0,1.71,0.52],[1,1.71,0]],"ltp":1.01,"tv":243.0,"id":9627400}],"tv":248.91}]}
{"op":"mcm","clk":"4235526052","pt":1631555710874,"mc":[{"id":"1.187612427","rc":[{"batb":[[0,1.01,47.45]],"ltp":1.01,"tv":243.0,"id":9627400}]}]}
{"op":"mcm","clk":"4235531064","pt":1631555751001,"mc":[{"id":"1.187612427","rc":[{"trd":[[1.01,234]],"batb":[[0,1.01,35.45]],"ltp":1.01,"tv":267.0,"id":9627400}],"tv":272.91}]}
{"op":"mcm","clk":"4235533152","pt":1631555769243,"mc":[{"id":"1.187612427","rc":[{"batb":[[0,1.01,175.9]],"ltp":1.01,"tv":267.0,"id":9627400}]}]}
{"op":"mcm","clk":"4235533237","pt":1631555770036,"mc":[{"id":"1.187612427","rc":[{"batb":[[0,1.01,316.35]],"ltp":1.01,"tv":267.0,"id":9627400}]}]}
{"op":"mcm","clk":"4235539470","pt":1631555826511,"mc":[{"id":"1.187612427","rc":[{"batb":[[0,1.01,12],[1,1.01,0]],"ltp":4.6,"tv":5.91,"id":25977944}]}]}
{"op":"mcm","clk":"4235540006","pt":1631555831523,"mc":[{"id":"1.187612427","rc":[{"batb":[[0,14,10],[1,1.01,12]],"ltp":4.6,"tv":5.91,"id":25977944}]}]}
{"op":"mcm","clk":"4235544567","pt":1631555871563,"mc":[{"id":"1.187612427","rc":[{"batb":[[0,1.01,12],[1,1.01,0]],"ltp":4.6,"tv":5.91,"id":25977944}]}]}
{"op":"mcm","clk":"4235545140","pt":1631555876444,"mc":[{"id":"1.187612427","rc":[{"batb":[[0,11,10],[1,1.01,12]],"ltp":4.6,"tv":5.91,"id":25977944}]}]}
{"op":"mcm","clk":"4235549714","pt":1631555916305,"mc":[{"id":"1.187612427","rc":[{"batb":[[0,1.01,12],[1,1.01,0]],"ltp":4.6,"tv":5.91,"id":25977944}]}]}
{"op":"mcm","clk":"4235550315","pt":1631555921339,"mc":[{"id":"1.187612427","rc":[{"batb":[[0,14,10],[1,1.01,12]],"ltp":4.6,"tv":5.91,"id":25977944}]}]}
{"op":"mcm","clk":"4235554031","pt":1631555950639,"mc":[{"id":"1.187612427","rc":[{"batb":[[0,1.01,12],[1,1.01,0]],"ltp":4.6,"tv":5.91,"id":25977944}]}]}
{"op":"mcm","clk":"4235554696","pt":1631555955652,"mc":[{"id":"1.187612427","rc":[{"batb":[[0,12,10],[1,1.01,12]],"ltp":4.6,"tv":5.91,"id":25977944}]}]}
{"op":"mcm","clk":"4235558081","pt":1631555982184,"mc":[{"id":"1.187612427","rc":[{"batb":[[0,1.01,12],[1,1.01,0]],"ltp":4.6,"tv":5.91,"id":25977944}]}]}
{"op":"mcm","clk":"4235558689","pt":1631555987102,"mc":[{"id":"1.187612427","rc":[{"batb":[[0,19.5,10],[1,1.01,12]],"ltp":4.6,"tv":5.91,"id":25977944}]}]}
{"op":"mcm","clk":"4235565632","pt":1631556037784,"mc":[{"id":"1.187612427","rc":[{"batb":[[0,1.01,12],[1,1.01,0]],"ltp":4.6,"tv":5.91,"id":25977944}]}]}
{"op":"mcm","clk":"4235566290","pt":1631556042725,"mc":[{"id":"1.187612427","rc":[{"batb":[[0,12,10],[1,1.01,12]],"ltp":4.6,"tv":5.91,"id":25977944}]}]}
{"op":"mcm","clk":"4235571466","pt":1631556080435,"mc":[{"id":"1.187612427","rc":[{"batb":[[0,1.01,12],[1,1.01,0]],"ltp":4.6,"tv":5.91,"id":25977944}]}]}
{"op":"mcm","clk":"4235572118","pt":1631556085367,"mc":[{"id":"1.187612427","rc":[{"batb":[[0,1.02,1499.99]],"ltp":1.01,"tv":267.0,"id":9627400},{"batb":[[0,10,10],[1,1.01,12]],"ltp":4.6,"tv":5.91,"id":25977944}]}]}
{"op":"mcm","clk":"4235574223","pt":1631556100268,"mc":[{"id":"1.187612427","rc":[{"batb":[[0,1.04,108.16],[1,1.02,1499.99]],"ltp":1.01,"tv":267.0,"id":9627400}]}]}
{"op":"mcm","clk":"4235574276","pt":1631556100640,"mc":[{"id":"1.187612427","rc":[{"batb":[[0,1.04,162.24]],"ltp":1.01,"tv":267.0,"id":9627400}]}]}
{"op":"mcm","clk":"4235575027","pt":1631556105944,"mc":[{"id":"1.187612427","rc":[{"batb":[[0,1.02,1499.99],[1,1.02,0]],"ltp":1.01,"tv":267.0,"id":9627400}]}]}
{"op":"mcm","clk":"4235579168","pt":1631556135624,"mc":[{"id":"1.187612427","rc":[{"batb":[[0,1.01,12],[1,1.01,0]],"ltp":4.6,"tv":5.91,"id":25977944}]}]}
{"op":"mcm","clk":"4235579925","pt":1631556140637,"mc":[{"id":"1.187612427","rc":[{"batb":[[0,1.04,749.99]],"ltp":1.01,"tv":267.0,"id":9627400},{"batb":[[0,8.6,10],[1,1.01,12]],"ltp":4.6,"tv":5.91,"id":25977944}]}]}
{"op":"mcm","clk":"4235583336","pt":1631556164219,"mc":[{"id":"1.187612427","rc":[{"batb":[[0,1.01,12],[1,1.01,0]],"ltp":4.6,"tv":5.91,"id":25977944}]}]}
{"op":"mcm","clk":"4235584090","pt":1631556169150,"mc":[{"id":"1.187612427","rc":[{"batb":[[0,1.02,1499.99]],"ltp":1.01,"tv":267.0,"id":9627400},{"batb":[[0,10,10],[1,1.01,12]],"ltp":4.6,"tv":5.91,"id":25977944}]}]}
{"op":"mcm","clk":"4235589965","pt":1631556209622,"mc":[{"id":"1.187612427","rc":[{"batb":[[0,1.01,12],[1,1.01,0]],"ltp":4.6,"tv":5.91,"id":25977944}]}]}
{"op":"mcm","clk":"4235590672","pt":1631556214525,"mc":[{"id":"1.187612427","rc":[{"batb":[[0,14,10],[1,1.01,12]],"ltp":4.6,"tv":5.91,"id":25977944}]}]}
{"op":"mcm","clk":"4235595558","pt":1631556248468,"mc":[{"id":"1.187612427","rc":[{"batb":[[0,1.01,12],[1,1.01,0]],"ltp":4.6,"tv":5.91,"id":25977944}]}]}
{"op":"mcm","clk":"4235596304","pt":1631556253473,"mc":[{"id":"1.187612427","rc":[{"batb":[[0,19.5,10],[1,1.01,12]],"ltp":4.6,"tv":5.91,"id":25977944}]}]}
{"op":"mcm","clk":"4235599614","pt":1631556274912,"mc":[{"id":"1.187612427","rc":[{"batb":[[0,1.01,12],[1,1.01,0]],"ltp":4.6,"tv":5.91,"id":25977944}]}]}
{"op":"mcm","clk":"4235600399","pt":1631556279902,"mc":[{"id":"1.187612427","rc":[{"batb":[[0,24,10],[1,1.01,12]],"ltp":4.6,"tv":5.91,"id":25977944}]}]}
{"op":"mcm","clk":"4235620744","pt":1631556408500,"mc":[{"id":"1.187612427","rc":[{"batb":[[0,1.01,12],[1,1.01,0]],"ltp":4.6,"tv":5.91,"id":25977944}]}]}
{"op":"mcm","clk":"4235666899","pt":1631556686104,"mc":[{"id":"1.187612427","marketDefinition":{"bspMarket":false,"turnInPlayEnabled":true,"persistenceEnabled":true,"marketBaseRate":5.0,"eventId":"30898447","eventTypeId":"2","numberOfWinners":1,"bettingType":"ODDS","marketType":"MATCH_ODDS","marketTime":"2021-09-13T16:28:14.000Z","suspendTime":"2021-09-13T16:28:14.000Z","bspReconciled":false,"complete":true,"inPlay":true,"crossMatching":true,"runnersVoidable":false,"numberOfActiveRunners":2,"betDelay":5,"status":"SUSPENDED","runners":[{"status":"ACTIVE","sortPriority":1,"id":9627400,"name":"C Dinu"},{"status":"ACTIVE","sortPriority":2,"id":25977944,"name":"J Bouzas Maneiro"}],"regulators":["MR_INT"],"countryCode":"GB","discountAllowed":true,"timezone":"GMT","openDate":"2021-09-13T16:28:14.000Z","version":4031160123,"name":"Match Odds","eventName":"C Dinu v J Bouzas Maneiro"}}]}
{"op":"mcm","clk":"4235667739","pt":1631556691050,"mc":[{"id":"1.187612427","tv":0.0}]}
{"op":"mcm","clk":"4235667928","pt":1631556692145,"mc":[{"id":"1.187612427","marketDefinition":{"bspMarket":false,"turnInPlayEnabled":true,"persistenceEnabled":true,"marketBaseRate":5.0,"eventId":"30898447","eventTypeId":"2","numberOfWinners":1,"bettingType":"ODDS","marketType":"MATCH_ODDS","marketTime":"2021-09-13T16:28:14.000Z","suspendTime":"2021-09-13T16:28:14.000Z","bspReconciled":false,"complete":true,"inPlay":true,"crossMatching":false,"runnersVoidable":false,"numberOfActiveRunners":0,"betDelay":5,"status":"CLOSED","settledTime":"2021-09-13T18:11:29.000Z","runners":[{"status":"WINNER","sortPriority":1,"id":9627400,"name":"C Dinu"},{"status":"LOSER","sortPriority":2,"id":25977944,"name":"J Bouzas Maneiro"}],"regulators":["MR_INT"],"countryCode":"GB","discountAllowed":true,"timezone":"GMT","openDate":"2021-09-13T16:28:14.000Z","version":4031160541,"name":"Match Odds","eventName":"C Dinu v J Bouzas Maneiro"}}]}
