{"op":"mcm","clk":"4228524379","pt":1631462218712,"mc":[{"id":"1.187557653","marketDefinition":{"bspMarket":false,"turnInPlayEnabled":true,"persistenceEnabled":true,"marketBaseRate":5.0,"eventId":"30896062","eventTypeId":"2","numberOfWinners":1,"bettingType":"ODDS","marketType":"MATCH_ODDS","marketTime":"2021-09-13T11:00:00.000Z","suspendTime":"2021-09-13T11:00:00.000Z","bspReconciled":false,"complete":true,"inPlay":false,"crossMatching":false,"runnersVoidable":false,"numberOfActiveRunners":2,"betDelay":0,"status":"OPEN","runners":[{"status":"ACTIVE","sortPriority":1,"id":9433864,"name":"Vitaliy Sachko"},{"status":"ACTIVE","sortPriority":2,"id":9632596,"name":"Bogdan Bobrov"}],"regulators":["MR_INT"],"countryCode":"PL","discountAllowed":false,"timezone":"UTC","openDate":"2021-09-13T09:00:00.000Z","version":4028987748,"name":"Match Odds","eventName":"Vi Sachko v Bobrov"},"rc":[{"batb":[[0,1.01,25]],"ltp":0.0,"tv":0.0,"id":9632596},{"batb":[[0,1.01,25]],"ltp":0.0,"tv":0.0,"id":9433864}]}]}
{"op":"mcm","clk":"4228524577","pt":1631462220320,"mc":[{"id":"1.187557653","marketDefinition":{"bspMarket":false,"turnInPlayEnabled":true,"persistenceEnabled":true,"marketBaseRate":5.0,"eventId":"30896062","eventTypeId":"2","numberOfWinners":1,"bettingType":"ODDS","marketType":"MATCH_ODDS","marketTime":"2021-09-13T11:00:00.000Z","suspendTime":"2021-09-13T11:00:00.000Z","bspReconciled":false,"complete":true,"inPlay":false,"crossMatching":false,"runnersVoidable":false,"numberOfActiveRunners":2,"betDelay":0,"status":"OPEN","runners":[{"status":"ACTIVE","sortPriority":1,"id":9433864,"name":"Vitaliy Sachko"},{"status":"ACTIVE","sortPriority":2,"id":9632596,"name":"Bogdan Bobrov"}],"regulators":["MR_INT"],"countryCode":"PL","discountAllowed":false,"timezone":"UTC","openDate":"2021-09-13T11:00:00.000Z","version":4028987748,"name":"Match Odds","eventName":"Vi Sachko v Bobrov"}}]}
{"op":"mcm","clk":"4228524724","pt":1631462221315,"mc":[{"id":"1.187557653","marketDefinition":{"bspMarket":false,"turnInPlayEnabled":true,"persistenceEnabled":true,"marketBaseRate":5.0,"eventId":"30896062","eventTypeId":"2","numberOfWinners":1,"bettingType":"ODDS","marketType":"MATCH_ODDS","marketTime":"2021-09-13T11:00:00.000Z","suspendTime":"2021-09-13T11:00:00.000Z","bspReconciled":false,"complete":true,"inPlay":false,"crossMatching":false,"runnersVoidable":false,"numberOfActiveRunners":2,"betDelay":0,"status":"OPEN","runners":[{"status":"ACTIVE","sortPriority":1,"id":9433864,"name":"Vitaliy Sachko"},{"status":"ACTIVE","sortPriority":2,"id":9632596,"name":"Bogdan Bobrov"}],"regulators":["MR_INT"],"countryCode":"PL","discountAllowed":true,"timezone":"UTC","openDate":"2021-09-13T11:00:00.000Z","version":4028987748,"name":"Match Odds","eventName":"Vi Sachko v Bobrov"}}]}
{"op":"mcm","clk":"4228551616","pt":1631462411270,"mc":[{"id":"1.187557653","rc":[{"batb":[[0,1.01,15]],"ltp":0.0,"tv":0.0,"id":9632596},{"batb":[[0,1.01,15]],"ltp":0.0,"tv":0.0,"id":9433864}]}]}
{"op":"mcm","clk":"4228686060","pt":1631463137864,"mc":[{"id":"1.187557653","rc":[{"batl":[[0,990,2.2]],"ltp":0.0,"tv":0.0,"id":9632596},{"batl":[[0,990,2.2]],"ltp":0.0,"tv":0.0,"id":9433864}]}]}
{"op":"mcm","clk":"4228724083","pt":1631463340038,"mc":[{"id":"1.187557653","rc":[{"batb":[[0,1.01,108.94]],"ltp":0.0,"tv":0.0,"id":9632596},{"batb":[[0,1.01,108.94]],"ltp":0.0,"tv":0.0,"id":9433864}]}]}
{"op":"mcm","clk":"4230220109","pt":1631472861866,"mc":[{"id":"1.187557653","rc":[{"batb":[[0,1.01,581.8]],"ltp":0.0,"tv":0.0,"id":9632596},{"batb":[[0,1.01,581.8]],"ltp":0.0,"tv":0.0,"id":9433864}]}]}
{"op":"mcm","clk":"4230220187","pt":1631472862500,"mc":[{"id":"1.187557653","rc":[{"batb":[[0,1.02,108.45],[1,1.01,581.8]],"ltp":0.0,"tv":0.0,"id":9632596},{"batb":[[0,1.02,108.45],[1,1.01,581.8]],"ltp":0.0,"tv":0.0,"id":9433864}]}]}
{"op":"mcm","clk":"4230223034","pt":1631472889686,"mc":[{"id":"1.187557653","marketDefinition":{"bspMarket":false,"turnInPlayEnabled":true,"persistenceEnabled":true,"marketBaseRate":5.0,"eventId":"30896062","eventTypeId":"2","numberOfWinners":1,"bettingType":"ODDS","marketType":"MATCH_ODDS","marketTime":"2021-09-13T11:00:00.000Z","suspendTime":"2021-09-13T11:00:00.000Z","bspReconciled":false,"complete":true,"inPlay":false,"crossMatching":true,"runnersVoidable":false,"numberOfActiveRunners":2,"betDelay":0,"status":"OPEN","runners":[{"status":"ACTIVE","sortPriority":1,"id":9433864,"name":"Vitaliy Sachko"},{"status":"ACTIVE","sortPriority":2,"id":9632596,"name":"Bogdan Bobrov"}],"regulators":["MR_INT"],"countryCode":"PL","discountAllowed":true,"timezone":"UTC","openDate":"2021-09-13T11:00:00.000Z","version":4028987748,"name":"Match Odds","eventName":"Vi Sachko v Bobrov"}}]}
{"op":"mcm","clk":"4230302284","pt":1631473688486,"mc":[{"id":"1.187557653","rc":[{"batl":[[0,3,21.35],[1,990,2.2]],"ltp":0.0,"tv":0.0,"id":9433864}]}]}
{"op":"mcm","clk":"4230304219","pt":1631473705478,"mc":[{"id":"1.187557653","rc":[{"batl":[[0,9,21.35],[1,990,2.2]],"ltp":0.0,"tv":0.0,"id":9632596}]}]}
{"op":"mcm","clk":"4230595227","pt":1631477175192,"mc":[{"id":"1.187557653","rc":[{"batb":[[1,1.01,586.76]],"batl":[[0,9,21.34]],"ltp":0.0,"tv":0.0,"id":9632596},{"batb":[[1,1.01,586.76]],"batl":[[0,3,21.34]],"ltp":0.0,"tv":0.0,"id":9433864}]}]}
{"op":"mcm","clk":"4230964571","pt":1631484954504,"mc":[{"id":"1.187557653","rc":[{"batb":[[0,1.5,6.68],[1,1.02,108.43],[2,1.01,586.68]],"batl":[[0,9,21.35]],"ltp":0.0,"tv":0.0,"id":9632596},{"batb":[[0,1.02,108.43],[1,1.01,586.68]],"batl":[[0,3,21.35]],"ltp":0.0,"tv":0.0,"id":9433864}]}]}
{"op":"mcm","clk":"4231091290","pt":1631487836891,"mc":[{"id":"1.187557653","rc":[{"batb":[[1,1.02,108.42],[2,1.01,586.63]],"batl":[[0,4,25],[1,9,21.34],[2,990,2.2]],"ltp":0.0,"tv":0.0,"id":9632596},{"batb":[[0,1.02,108.42],[1,1.01,586.63]],"batl":[[0,1.44,25],[1,3,21.34],[2,990,2.2]],"ltp":0.0,"tv":0.0,"id":9433864}]}]}
{"op":"mcm","clk":"4231146227","pt":1631488923701,"mc":[{"id":"1.187557653","rc":[{"batb":[[0,1.51,15.37],[1,1.5,6.68],[2,1.02,108.42]],"ltp":0.0,"tv":0.0,"id":9632596}]}]}
{"op":"mcm","clk":"4231163869","pt":1631489286228,"mc":[{"id":"1.187557653","rc":[{"batb":[[2,1.22,16.43]],"ltp":0.0,"tv":0.0,"id":9632596},{"batb":[[0,1.1,72.28],[1,1.02,108.42],[2,1.01,586.63]],"ltp":0.0,"tv":0.0,"id":9433864}]}]}
{"op":"mcm","clk":"4231163878","pt":1631489286433,"mc":[{"id":"1.187557653","rc":[{"batb":[[2,1.22,49.28]],"ltp":0.0,"tv":0.0,"id":9632596},{"batb":[[0,1.1,108.42]],"ltp":0.0,"tv":0.0,"id":9433864}]}]}
{"op":"mcm","clk":"4231593799","pt":1631497665833,"mc":[{"id":"1.187557653","rc":[{"batb":[[0,1.51,15.36],[2,1.22,49.28]],"batl":[[1,9,21.33]],"ltp":0.0,"tv":0.0,"id":9632596},{"batb":[[0,1.1,108.43],[1,1.02,108.43],[2,1.01,586.61]],"batl":[[1,3,21.33]],"ltp":0.0,"tv":0.0,"id":9433864}]}]}
{"op":"mcm","clk":"4231755679","pt":1631503065794,"mc":[{"id":"1.187557653","rc":[{"batb":[[0,1.51,15.36],[2,1.22,49.27]],"batl":[[1,9,21.33]],"ltp":0.0,"tv":0.0,"id":9632596},{"batb":[[0,1.1,108.41],[1,1.02,108.41],[2,1.01,586.49]],"batl":[[1,3,21.33]],"ltp":0.0,"tv":0.0,"id":9433864}]}]}
{"op":"mcm","clk":"4232017446","pt":1631510769922,"mc":[{"id":"1.187557653","rc":[{"batb":[[0,1.9,21.65],[1,1.51,15.36],[2,1.5,6.68]],"batl":[[1,9,21.33]],"ltp":0.0,"tv":0.0,"id":9632596},{"batb":[[0,1.13,136.27],[1,1.1,108.5],[2,1.02,108.5]],"batl":[[1,3,21.33]],"ltp":0.0,"tv":0.0,"id":9433864}]}]}
{"op":"mcm","clk":"4232018225","pt":1631510790227,"mc":[{"id":"1.187557653","rc":[{"batb":[[1,1.5,6.68],[2,1.22,49.32]],"ltp":0.0,"tv":0.0,"id":9632596}]}]}
{"op":"mcm","clk":"4232018496","pt":1631510797359,"mc":[{"id":"1.187557653","rc":[{"batb":[[1,1.22,49.32],[2,1.02,108.5]],"ltp":0.0,"tv":0.0,"id":9632596}]}]}
{"op":"mcm","clk":"4232018747","pt":1631510804190,"mc":[{"id":"1.187557653","rc":[{"batb":[[0,1.9,26.91]],"ltp":0.0,"tv":0.0,"id":9632596}]}]}
{"op":"mcm","clk":"4232020322","pt":1631510846986,"mc":[{"id":"1.187557653","rc":[{"batb":[[0,1.91,15.36],[1,1.9,26.91],[2,1.22,49.32]],"ltp":0.0,"tv":0.0,"id":9632596}]}]}
{"op":"mcm","clk":"4232040078","pt":1631511470723,"mc":[{"id":"1.187557653","rc":[{"batl":[[2,46,29.03]],"ltp":0.0,"tv":0.0,"id":9632596},{"batl":[[2,46,29.03]],"ltp":0.0,"tv":0.0,"id":9433864}]}]}
{"op":"mcm","clk":"4232061732","pt":1631512028974,"mc":[{"id":"1.187557653","rc":[{"batl":[[1,1.82,2.66],[2,3,21.33]],"ltp":0.0,"tv":0.0,"id":9433864}]}]}
{"op":"mcm","clk":"4232062262","pt":1631512040320,"mc":[{"id":"1.187557653","rc":[{"batb":[[2,1.05,42.5]],"ltp":0.0,"tv":0.0,"id":9433864}]}]}
{"op":"mcm","clk":"4232073926","pt":1631512357878,"mc":[{"id":"1.187557653","rc":[{"trd":[[1.4,4]],"batb":[[0,1.4,12.46],[1,1.13,136.27],[2,1.1,108.5]],"ltp":1.4,"tv":4.0,"id":9433864}],"tv":4.0}]}
{"op":"mcm","clk":"4232153388","pt":1631514017267,"mc":[{"id":"1.187557653","rc":[{"batl":[[1,4.5,2.07],[2,9,21.33]],"ltp":0.0,"tv":0.0,"id":9632596},{"batl":[[1,1.6,12.06],[2,1.82,2.66]],"ltp":1.4,"tv":4.0,"id":9433864}]}]}
{"op":"mcm","clk":"4232185662","pt":1631514820911,"mc":[{"id":"1.187557653","rc":[{"batb":[[1,1.2,219.96],[2,1.13,136.27]],"ltp":1.4,"tv":4.0,"id":9433864}]}]}
{"op":"mcm","clk":"4232299838","pt":1631517434492,"mc":[{"id":"1.187557653","rc":[{"batb":[[0,2.44,30.97],[1,1.91,15.36],[2,1.9,26.94]],"batl":[[1,4.5,2.07],[2,9,21.33]],"ltp":0.0,"tv":0.0,"id":9632596},{"trd":[[1.4,4.01]],"batb":[[0,1.4,12.48],[1,1.2,220.22],[2,1.13,136.46]],"batl":[[1,1.6,12.07],[2,1.82,2.66]],"ltp":1.4,"tv":4.0,"id":9433864}],"tv":4.0}]}
{"op":"mcm","clk":"4232300268","pt":1631517440982,"mc":[{"id":"1.187557653","rc":[{"batb":[[2,1.9,21.68]],"ltp":0.0,"tv":0.0,"id":9632596}]}]}
{"op":"mcm","clk":"4232300660","pt":1631517447583,"mc":[{"id":"1.187557653","rc":[{"batb":[[0,2.44,35.07]],"ltp":0.0,"tv":0.0,"id":9632596}]}]}
{"op":"mcm","clk":"4232302252","pt":1631517476925,"mc":[{"id":"1.187557653","rc":[{"batb":[[1,1.9,21.68],[2,1.22,49.38]],"ltp":0.0,"tv":0.0,"id":9632596}]}]}
{"op":"mcm","clk":"4232309660","pt":1631517617118,"mc":[{"id":"1.187557653","rc":[{"batl":[[1,1.82,2.66],[2,1.88,44.04]],"ltp":1.4,"tv":4.0,"id":9433864}]}]}
{"op":"mcm","clk":"4232309716","pt":1631517618200,"mc":[{"id":"1.187557653","rc":[{"batl":[[1,1.6,12.07],[2,1.82,2.66]],"ltp":1.4,"tv":4.0,"id":9433864}]}]}
{"op":"mcm","clk":"4232539097","pt":1631521219092,"mc":[{"id":"1.187557653","rc":[{"batl":[[1,9,21.33],[2,46,29.07]],"ltp":0.0,"tv":0.0,"id":9632596}]}]}
{"op":"mcm","clk":"4232539121","pt":1631521219400,"mc":[{"id":"1.187557653","rc":[{"batl":[[1,4.5,2.07],[2,9,21.33]],"ltp":0.0,"tv":0.0,"id":9632596}]}]}
{"op":"mcm","clk":"4232637919","pt":1631522994634,"mc":[{"id":"1.187557653","rc":[{"batb":[[1,1.13,136.46],[2,1.1,108.65]],"ltp":1.4,"tv":4.0,"id":9433864}]}]}
{"op":"mcm","clk":"4232657489","pt":1631523420646,"mc":[{"id":"1.187557653","marketDefinition":{"bspMarket":false,"turnInPlayEnabled":true,"persistenceEnabled":true,"marketBaseRate":5.0,"eventId":"30896062","eventTypeId":"2","numberOfWinners":1,"bettingType":"ODDS","marketType":"MATCH_ODDS","marketTime":"2021-09-13T10:56:00.000Z","suspendTime":"2021-09-13T10:56:00.000Z","bspReconciled":false,"complete":true,"inPlay":false,"crossMatching":true,"runnersVoidable":false,"numberOfActiveRunners":2,"betDelay":0,"status":"OPEN","runners":[{"status":"ACTIVE","sortPriority":1,"id":9433864,"name":"Vitaliy Sachko"},{"status":"ACTIVE","sortPriority":2,"id":9632596,"name":"Bogdan Bobrov"}],"regulators":["MR_INT"],"countryCode":"PL","discountAllowed":true,"timezone":"UTC","openDate":"2021-09-13T11:00:00.000Z","version":4030477382,"name":"Match Odds","eventName":"Vi Sachko v Bobrov"},"rc":[{"batb":[[1,1.9,43.44]],"ltp":0.0,"tv":0.0,"id":9632596},{"batb":[[1,1.2,97.91],[2,1.13,136.46]],"ltp":1.4,"tv":4.0,"id":9433864}]}]}
{"op":"mcm","clk":"4232657654","pt":1631523422610,"mc":[{"id":"1.187557653","marketDefinition":{"bspMarket":false,"turnInPlayEnabled":true,"persistenceEnabled":true,"marketBaseRate":5.0,"eventId":"30896062","eventTypeId":"2","numberOfWinners":1,"bettingType":"ODDS","marketType":"MATCH_ODDS","marketTime":"2021-09-13T10:56:00.000Z","suspendTime":"2021-09-13T10:56:00.000Z","bspReconciled":false,"complete":true,"inPlay":false,"crossMatching":true,"runnersVoidable":false,"numberOfActiveRunners":2,"betDelay":0,"status":"OPEN","runners":[{"status":"ACTIVE","sortPriority":1,"id":9433864,"name":"Vitaliy Sachko"},{"status":"ACTIVE","sortPriority":2,"id":9632596,"name":"Bogdan Bobrov"}],"regulators":["MR_INT"],"countryCode":"PL","discountAllowed":true,"timezone":"UTC","openDate":"2021-09-13T10:56:00.000Z","version":4030477382,"name":"Match Odds","eventName":"Vi Sachko v Bobrov"},"rc":[{"batb":[[0,2.44,4.1]],"ltp":0.0,"tv":0.0,"id":9632596}]}]}
{"op":"mcm","clk":"4232657943","pt":1631523431452,"mc":[{"id":"1.187557653","rc":[{"batb":[[0,2.46,40.98],[1,2.44,4.1],[2,1.9,43.44]],"ltp":0.0,"tv":0.0,"id":9632596}]}]}
{"op":"mcm","clk":"4232665156","pt":1631523626773,"mc":[{"id":"1.187557653","rc":[{"batb":[[1,1.9,43.41],[2,1.22,49.35]],"batl":[[1,4.5,2.07],[2,9,21.34]],"ltp":0.0,"tv":0.0,"id":9632596},{"trd":[[1.4,4]],"batb":[[0,1.4,12.47],[1,1.2,97.84],[2,1.13,136.36]],"batl":[[1,1.6,12.07],[2,1.82,2.66]],"ltp":1.4,"tv":4.0,"id":9433864}],"tv":4.0}]}
{"op":"mcm","clk":"4232665474","pt":1631523634158,"mc":[{"id":"1.187557653","rc":[{"batb":[[0,2.46,45.06]],"ltp":0.0,"tv":0.0,"id":9632596}]}]}
{"op":"mcm","clk":"4232683072","pt":1631523976988,"mc":[{"id":"1.187557653","rc":[{"batl":[[0,1.43,1.28],[1,1.44,25],[2,1.6,12.07]],"ltp":1.4,"tv":4.0,"id":9433864}]}]}
{"op":"mcm","clk":"4232707531","pt":1631524397977,"mc":[{"id":"1.187557653","rc":[{"batb":[[1,1.2,317.93]],"ltp":1.4,"tv":4.0,"id":9433864}]}]}
{"op":"mcm","clk":"4232709588","pt":1631524435159,"mc":[{"id":"1.187557653","rc":[{"batb":[[1,1.01,113.88],[2,1.22,0]],"batl":[[1,9,21.34],[2,46,29.05]],"ltp":0.0,"tv":0.0,"id":9632596},{"batb":[[1,1.2,220.09],[2,1.05,42.62]],"batl":[[2,1.82,2.66]],"ltp":1.4,"tv":4.0,"id":9433864}]}]}
{"op":"mcm","clk":"4232709614","pt":1631524435566,"mc":[{"id":"1.187557653","rc":[{"batl":[[2,1.59,60]],"ltp":1.4,"tv":4.0,"id":9433864}]}]}
{"op":"mcm","clk":"4232709923","pt":1631524440866,"mc":[{"id":"1.187557653","rc":[{"batb":[[0,2.46,40.98]],"ltp":0.0,"tv":0.0,"id":9632596}]}]}
{"op":"mcm","clk":"4232710311","pt":1631524447592,"mc":[{"id":"1.187557653","rc":[{"batb":[[0,2.68,3.74],[1,2.46,40.98],[2,1.01,113.88]],"ltp":0.0,"tv":0.0,"id":9632596}]}]}
{"op":"mcm","clk":"4232720473","pt":1631524631629,"mc":[{"id":"1.187557653","rc":[{"batb":[[0,2.7,53.31],[1,2.68,3.74]],"ltp":0.0,"tv":0.0,"id":9632596}]}]}
{"op":"mcm","clk":"4232720711","pt":1631524636314,"mc":[{"id":"1.187557653","rc":[{"batb":[[1,1.01,113.88],[2,1.01,0]],"ltp":0.0,"tv":0.0,"id":9632596}]}]}
{"op":"mcm","clk":"4232721057","pt":1631524642926,"mc":[{"id":"1.187557653","rc":[{"batb":[[0,2.7,57.01]],"ltp":0.0,"tv":0.0,"id":9632596}]}]}
{"op":"mcm","clk":"4232730428","pt":1631524668193,"mc":[{"id":"1.187557653","rc":[{"batl":[[1,1.44,28.44]],"ltp":1.4,"tv":4.0,"id":9433864}]}]}
{"op":"mcm","clk":"4232733367","pt":1631524720641,"mc":[{"id":"1.187557653","rc":[{"batl":[[1,1.44,36.98]],"ltp":1.4,"tv":4.0,"id":9433864}]}]}
{"op":"mcm","clk":"4232837207","pt":1631526548997,"mc":[{"id":"1.187557653","rc":[{"trd":[[1.4,28.95]],"batb":[[0,1.22,135.79]],"batl":[[0,1.4,187.53],[1,1.43,1.28],[2,1.44,36.98]],"ltp":1.4,"tv":28.94,"id":9433864}],"tv":28.94}]}
{"op":"mcm","clk":"4232837531","pt":1631526553947,"mc":[{"id":"1.187557653","rc":[{"batb":[[0,2.72,11.95],[1,2.7,57.01],[2,1.01,113.88]],"ltp":0.0,"tv":0.0,"id":9632596}]}]}
{"op":"mcm","clk":"4232848853","pt":1631526731548,"mc":[{"id":"1.187557653","rc":[{"batb":[[0,2.82,140.81],[1,2.72,11.95],[2,2.7,3.7]],"ltp":0.0,"tv":0.0,"id":9632596}]}]}
{"op":"mcm","clk":"4232849783","pt":1631526746786,"mc":[{"id":"1.187557653","rc":[{"batb":[[1,2.7,3.7],[2,1.01,113.88]],"ltp":0.0,"tv":0.0,"id":9632596}]}]}
{"op":"mcm","clk":"4232855748","pt":1631526843878,"mc":[{"id":"1.187557653","rc":[{"batb":[[0,2.84,10.24],[1,2.82,140.81],[2,2.7,3.7]],"ltp":0.0,"tv":0.0,"id":9632596}]}]}
{"op":"mcm","clk":"4232856024","pt":1631526848978,"mc":[{"id":"1.187557653","rc":[{"batb":[[0,1.2,220.09],[1,1.05,42.62],[2,1.01,113.88]],"ltp":1.4,"tv":28.94,"id":9433864}]}]}
{"op":"mcm","clk":"4232861738","pt":1631526960703,"mc":[{"id":"1.187557653","rc":[{"batb":[[0,3.45,5.22],[1,2.84,10.24]],"ltp":0.0,"tv":0.0,"id":9632596},{"batb":[[0,1.32,40.01],[1,1.2,220.09],[2,1.05,42.62]],"ltp":1.4,"tv":28.94,"id":9433864}]}]}
{"op":"mcm","clk":"4232862300","pt":1631526972334,"mc":[{"id":"1.187557653","rc":[{"batb":[[2,1.01,113.88]],"ltp":0.0,"tv":0.0,"id":9632596}]}]}
{"op":"mcm","clk":"4232862637","pt":1631526979056,"mc":[{"id":"1.187557653","rc":[{"batb":[[0,3.5,2.86],[1,3.45,5.22],[2,2.84,10.24]],"ltp":0.0,"tv":0.0,"id":9632596}]}]}
{"op":"mcm","clk":"4232865756","pt":1631527033214,"mc":[{"id":"1.187557653","rc":[{"batb":[[2,1.01,113.88]],"ltp":0.0,"tv":0.0,"id":9632596}]}]}
{"op":"mcm","clk":"4232866332","pt":1631527042035,"mc":[{"id":"1.187557653","rc":[{"trd":[[3.5,3.42]],"batb":[[0,3.5,1.15]],"ltp":3.5,"tv":3.41,"id":9632596}],"tv":32.36}]}
{"op":"mcm","clk":"4232866869","pt":1631527051244,"mc":[{"id":"1.187557653","rc":[{"batb":[[2,1.75,3.41]],"ltp":3.5,"tv":3.41,"id":9632596}]}]}
{"op":"mcm","clk":"4232869176","pt":1631527091460,"mc":[{"id":"1.187557653","rc":[{"batb":[[0,3.55,2.66],[1,3.5,1.15],[2,3.45,5.22]],"ltp":3.5,"tv":3.41,"id":9632596}]}]}
{"op":"mcm","clk":"4232883104","pt":1631527339853,"mc":[{"id":"1.187557653","rc":[{"batb":[[1,1.05,42.62],[2,1.01,113.88]],"ltp":1.4,"tv":28.94,"id":9433864}]}]}
{"op":"mcm","clk":"4232883583","pt":1631527348729,"mc":[{"id":"1.187557653","rc":[{"batb":[[1,1.14,308.12],[2,1.05,42.62]],"ltp":1.4,"tv":28.94,"id":9433864}]}]}
{"op":"mcm","clk":"4232910204","pt":1631527914608,"mc":[{"id":"1.187557653","rc":[{"batl":[[2,1.44,28.44]],"ltp":1.4,"tv":28.94,"id":9433864}]}]}
{"op":"mcm","clk":"4232960078","pt":1631528569513,"mc":[{"id":"1.187557653","rc":[{"batb":[[1,1.28,2.66],[2,1.14,308.12]],"ltp":1.4,"tv":28.94,"id":9433864}]}]}
{"op":"mcm","clk":"4233040486","pt":1631529849339,"mc":[{"id":"1.187557653","rc":[{"trd":[[1.4,39.6]],"batl":[[0,1.4,182.2]],"ltp":1.4,"tv":39.6,"id":9433864}],"tv":43.02}]}
{"op":"mcm","clk":"4233048070","pt":1631529961798,"mc":[{"id":"1.187557653","rc":[{"batb":[[2,1.27,555.56]],"ltp":1.4,"tv":39.6,"id":9433864}]}]}
{"op":"mcm","clk":"4233048650","pt":1631529969504,"mc":[{"id":"1.187557653","rc":[{"trd":[[4,0.4]],"batl":[[0,4,24.8]],"ltp":4.0,"tv":3.82,"id":9632596}],"tv":43.42}]}
{"op":"mcm","clk":"4233097997","pt":1631530553841,"mc":[{"id":"1.187557653","rc":[{"batl":[[0,4,26.8]],"ltp":4.0,"tv":3.82,"id":9632596},{"batl":[[0,1.4,184.2]],"ltp":1.4,"tv":39.6,"id":9433864}]}]}
{"op":"mcm","clk":"4233102761","pt":1631530617415,"mc":[{"id":"1.187557653","marketDefinition":{"bspMarket":false,"turnInPlayEnabled":true,"persistenceEnabled":true,"marketBaseRate":5.0,"eventId":"30896062","eventTypeId":"2","numberOfWinners":1,"bettingType":"ODDS","marketType":"MATCH_ODDS","marketTime":"2021-09-13T11:00:00.000Z","suspendTime":"2021-09-13T11:00:00.000Z","bspReconciled":false,"complete":true,"inPlay":false,"crossMatching":true,"runnersVoidable":false,"numberOfActiveRunners":2,"betDelay":0,"status":"OPEN","runners":[{"status":"ACTIVE","sortPriority":1,"id":9433864,"name":"Vitaliy Sachko"},{"status":"ACTIVE","sortPriority":2,"id":9632596,"name":"Bogdan Bobrov"}],"regulators":["MR_INT"],"countryCode":"PL","discountAllowed":true,"timezone":"UTC","openDate":"2021-09-13T10:56:00.000Z","version":4030566633,"name":"Match Odds","eventName":"Vi Sachko v Bobrov"}}]}
{"op":"mcm","clk":"4233105877","pt":1631530660642,"mc":[{"id":"1.187557653","marketDefinition":{"bspMarket":false,"turnInPlayEnabled":true,"persistenceEnabled":true,"marketBaseRate":5.0,"eventId":"30896062","eventTypeId":"2","numberOfWinners":1,"bettingType":"ODDS","marketType":"MATCH_ODDS","marketTime":"2021-09-13T11:00:00.000Z","suspendTime":"2021-09-13T11:00:00.000Z","bspReconciled":false,"complete":true,"inPlay":false,"crossMatching":true,"runnersVoidable":false,"numberOfActiveRunners":2,"betDelay":0,"status":"OPEN","runners":[{"status":"ACTIVE","sortPriority":1,"id":9433864,"name":"Vitaliy Sachko"},{"status":"ACTIVE","sortPriority":2,"id":9632596,"name":"Bogdan Bobrov"}],"regulators":["MR_INT"],"countryCode":"PL","discountAllowed":true,"timezone":"UTC","openDate":"2021-09-13T11:00:00.000Z","version":4030566633,"name":"Match Odds","eventName":"Vi Sachko v Bobrov"}}]}
{"op":"mcm","clk":"4233107558","pt":1631530683805,"mc":[{"id":"1.187557653","rc":[{"batb":[[0,1.29,409.32]],"batl":[[0,1.36,2.56],[1,1.4,184.2],[2,1.43,1.28]],"ltp":1.4,"tv":39.6,"id":9433864}]}]}
{"op":"mcm","clk":"4233107775","pt":1631530687186,"mc":[{"id":"1.187557653","rc":[{"batl":[[0,1.34,2.56]],"ltp":1.4,"tv":39.6,"id":9433864}]}]}
{"op":"mcm","clk":"4233108001","pt":1631530690929,"mc":[{"id":"1.187557653","rc":[{"trd":[[4,1.25]],"batl":[[0,4,25.95]],"ltp":4.0,"tv":4.67,"id":9632596},{"trd":[[1.33,2.56]],"batb":[[0,1.32,40.01],[1,1.29,44.14],[2,1.28,2.66]],"batl":[[0,1.4,184.2],[1,1.43,1.28],[2,1.44,28.44]],"ltp":1.33,"tv":42.16,"id":9433864}],"tv":46.83}]}
{"op":"mcm","clk":"4233117608","pt":1631530832271,"mc":[{"id":"1.187557653","rc":[{"trd":[[3.5,3.41]],"batb":[[0,3.55,2.66],[2,3.45,5.21]],"batl":[[1,9,21.29],[2,46,29.02]],"ltp":4.0,"tv":4.66,"id":9632596},{"trd":[[1.33,2.56],[1.4,39.58]],"batb":[[0,1.32,39.93],[1,1.31,108.28],[2,1.29,44.05]],"batl":[[1,1.43,1.28],[2,1.44,28.44]],"ltp":1.33,"tv":42.13,"id":9433864}],"tv":46.8}]}
{"op":"mcm","clk":"4233124146","pt":1631530917970,"mc":[{"id":"1.187557653","marketDefinition":{"bspMarket":false,"turnInPlayEnabled":true,"persistenceEnabled":true,"marketBaseRate":5.0,"eventId":"30896062","eventTypeId":"2","numberOfWinners":1,"bettingType":"ODDS","marketType":"MATCH_ODDS","marketTime":"2021-09-13T10:58:00.000Z","suspendTime":"2021-09-13T10:58:00.000Z","bspReconciled":false,"complete":true,"inPlay":false,"crossMatching":true,"runnersVoidable":false,"numberOfActiveRunners":2,"betDelay":0,"status":"OPEN","runners":[{"status":"ACTIVE","sortPriority":1,"id":9433864,"name":"Vitaliy Sachko"},{"status":"ACTIVE","sortPriority":2,"id":9632596,"name":"Bogdan Bobrov"}],"regulators":["MR_INT"],"countryCode":"PL","discountAllowed":true,"timezone":"UTC","openDate":"2021-09-13T11:00:00.000Z","version":4030572660,"name":"Match Odds","eventName":"Vi Sachko v Bobrov"}}]}
{"op":"mcm","clk":"4233124549","pt":1631530921994,"mc":[{"id":"1.187557653","marketDefinition":{"bspMarket":false,"turnInPlayEnabled":true,"persistenceEnabled":true,"marketBaseRate":5.0,"eventId":"30896062","eventTypeId":"2","numberOfWinners":1,"bettingType":"ODDS","marketType":"MATCH_ODDS","marketTime":"2021-09-13T10:58:00.000Z","suspendTime":"2021-09-13T10:58:00.000Z","bspReconciled":false,"complete":true,"inPlay":false,"crossMatching":true,"runnersVoidable":false,"numberOfActiveRunners":2,"betDelay":0,"status":"OPEN","runners":[{"status":"ACTIVE","sortPriority":1,"id":9433864,"name":"Vitaliy Sachko"},{"status":"ACTIVE","sortPriority":2,"id":9632596,"name":"Bogdan Bobrov"}],"regulators":["MR_INT"],"countryCode":"PL","discountAllowed":true,"timezone":"UTC","openDate":"2021-09-13T10:58:00.000Z","version":4030572660,"name":"Match Odds","eventName":"Vi Sachko v Bobrov"}}]}
{"op":"mcm","clk":"4233131544","pt":1631531003730,"mc":[{"id":"1.187557653","rc":[{"trd":[[3.55,5.11]],"batb":[[0,3.5,1.25],[1,3.45,5.21],[2,3.4,25.61]],"ltp":3.55,"tv":9.78,"id":9632596}],"tv":51.91}]}
{"op":"mcm","clk":"4233132589","pt":1631531016058,"mc":[{"id":"1.187557653","rc":[{"trd":[[3.5,9.57],[3.55,5.32]],"batb":[[0,3.45,5.21],[1,3.4,25.61],[2,3.3,2.66]],"ltp":3.5,"tv":16.14,"id":9632596},{"trd":[[1.4,49.23]],"batl":[[0,1.4,174.55]],"ltp":1.4,"tv":51.78,"id":9433864}],"tv":67.92}]}
{"op":"mcm","clk":"4233137190","pt":1631531067545,"mc":[{"id":"1.187557653","rc":[{"batb":[[1,1.31,107.28]],"ltp":1.4,"tv":51.78,"id":9433864}]}]}
{"op":"mcm","clk":"4233162395","pt":1631531353718,"mc":[{"id":"1.187557653","rc":[{"trd":[[4,2.91]],"batl":[[0,4,24.29]],"ltp":4.0,"tv":17.8,"id":9632596},{"trd":[[1.33,7.56]],"ltp":1.33,"tv":56.78,"id":9433864}],"tv":74.58}]}
{"op":"mcm","clk":"4233166872","pt":1631531410189,"mc":[{"id":"1.187557653","rc":[{"trd":[[4,27.2]],"batl":[[0,6,68.17]],"ltp":4.0,"tv":42.09,"id":9632596},{"trd":[[1.33,94.53]],"batl":[[0,1.33,92.54],[1,1.4,2],[2,1.43,1.28]],"ltp":1.33,"tv":143.75,"id":9433864}],"tv":185.84}]}
{"op":"mcm","clk":"4233166905","pt":1631531410498,"mc":[{"id":"1.187557653","rc":[{"batb":[[0,3.85,4.48],[1,3.45,5.21],[2,3.4,25.61]],"batl":[[0,5,97.7]],"ltp":4.0,"tv":42.09,"id":9632596},{"batb":[[0,1.31,107.28],[1,1.28,48.29],[2,1.27,555.56]],"ltp":1.33,"tv":143.75,"id":9433864}]}]}
{"op":"mcm","clk":"4233166987","pt":1631531411289,"mc":[{"id":"1.187557653","rc":[{"batb":[[1,1.28,2.66]],"ltp":1.33,"tv":143.75,"id":9433864}]}]}
{"op":"mcm","clk":"4233168431","pt":1631531431094,"mc":[{"id":"1.187557653","rc":[{"batb":[[2,3.3,2.66]],"ltp":4.0,"tv":42.09,"id":9632596},{"batb":[[0,1.28,2.66],[1,1.27,555.56],[2,1.14,307.83]],"ltp":1.33,"tv":143.75,"id":9433864}]}]}
{"op":"mcm","clk":"4233168493","pt":1631531431830,"mc":[{"id":"1.187557653","marketDefinition":{"bspMarket":false,"turnInPlayEnabled":true,"persistenceEnabled":true,"marketBaseRate":5.0,"eventId":"30896062","eventTypeId":"2","numberOfWinners":1,"bettingType":"ODDS","marketType":"MATCH_ODDS","marketTime":"2021-09-13T10:58:00.000Z","suspendTime":"2021-09-13T10:58:00.000Z","bspReconciled":false,"complete":true,"inPlay":true,"crossMatching":true,"runnersVoidable":false,"numberOfActiveRunners":2,"betDelay":3,"status":"OPEN","runners":[{"status":"ACTIVE","sortPriority":1,"id":9433864,"name":"Vitaliy Sachko"},{"status":"ACTIVE","sortPriority":2,"id":9632596,"name":"Bogdan Bobrov"}],"regulators":["MR_INT"],"countryCode":"PL","discountAllowed":true,"timezone":"UTC","openDate":"2021-09-13T10:58:00.000Z","version":4030578678,"name":"Match Odds","eventName":"Vi Sachko v Bobrov"},"rc":[{"batb":[[0,1.75,3.41],[1,1.6,766.61],[2,1.01,113.7]],"ltp":4.0,"tv":42.09,"id":9632596},{"batb":[[0,1.06,766.61],[1,1.01,113.7],[2,1.14,0]],"batl":[[1,1.5,60],[2,1.43,0]],"ltp":1.33,"tv":143.75,"id":9433864}]}]}
{"op":"mcm","clk":"4233169008","pt":1631531438941,"mc":[{"id":"1.187557653","rc":[{"batb":[[0,1.8,11.86],[1,1.75,3.41],[2,1.6,766.61]],"ltp":4.0,"tv":42.09,"id":9632596},{"batb":[[1,1.01,586.68]],"batl":[[2,44,7.23]],"ltp":1.33,"tv":143.75,"id":9433864}]}]}
{"op":"mcm","clk":"4233169453","pt":1631531445162,"mc":[{"id":"1.187557653","rc":[{"trd":[[4,57.97]],"batb":[[0,3.4,45.83],[1,1.8,11.86],[2,1.75,3.41]],"batl":[[0,3.7,46.09]],"ltp":4.0,"tv":72.86,"id":9632596},{"trd":[[1.33,187.07]],"batl":[[0,1.41,19.33]],"ltp":1.33,"tv":236.29,"id":9433864}],"tv":309.15}]}
{"op":"mcm","clk":"4233169533","pt":1631531446367,"mc":[{"id":"1.187557653","rc":[{"batb":[[1,3.1,32.97],[2,2.84,41.42]],"ltp":4.0,"tv":72.86,"id":9632596},{"batb":[[0,1.36,89.71],[1,1.32,104.35],[2,1.06,766.61]],"ltp":1.33,"tv":236.29,"id":9433864}]}]}
{"op":"mcm","clk":"4233170201","pt":1631531455284,"mc":[{"id":"1.187557653","rc":[{"batl":[[0,1.5,60],[1,44,7.23],[2,44,0]],"ltp":1.33,"tv":236.29,"id":9433864}]}]}
{"op":"mcm","clk":"4233170299","pt":1631531456789,"mc":[{"id":"1.187557653","rc":[{"trd":[[3.7,9.26]],"batl":[[0,3.7,36.83]],"ltp":3.7,"tv":82.12,"id":9632596},{"trd":[[1.37,25]],"ltp":1.37,"tv":261.29,"id":9433864}],"tv":343.41}]}
{"op":"mcm","clk":"4233170378","pt":1631531458163,"mc":[{"id":"1.187557653","rc":[{"batb":[[0,3.55,5.41],[1,3.4,45.83],[2,3.1,32.97]],"batl":[[0,3.7,44.75]],"ltp":3.7,"tv":82.12,"id":9632596}]}]}
{"op":"mcm","clk":"4233170431","pt":1631531458786,"mc":[{"id":"1.187557653","rc":[{"batb":[[2,1.11,269.5]],"ltp":1.37,"tv":261.29,"id":9433864}]}]}
{"op":"mcm","clk":"4233170697","pt":1631531462065,"mc":[{"id":"1.187557653","rc":[{"batb":[[2,1.17,313.89]],"ltp":1.37,"tv":261.29,"id":9433864}]}]}
{"op":"mcm","clk":"4233170912","pt":1631531464965,"mc":[{"id":"1.187557653","rc":[{"batb":[[0,2.84,41.42],[1,2,11.86],[2,1.8,11.86]],"ltp":3.7,"tv":82.12,"id":9632596},{"batb":[[0,1.32,104.35],[1,1.17,313.89],[2,1.11,269.5]],"ltp":1.37,"tv":261.29,"id":9433864}]}]}
{"op":"mcm","clk":"4233172248","pt":1631531482122,"mc":[{"id":"1.187557653","rc":[{"batb":[[0,3.5,83.89],[1,2.84,41.42],[2,2,11.86]],"batl":[[0,4,5.79],[1,4.1,51.59]],"ltp":3.7,"tv":82.12,"id":9632596},{"trd":[[1.32,15.88]],"batb":[[0,1.32,96.41]],"batl":[[0,1.35,13.52],[1,1.4,209.73],[2,1.5,60]],"ltp":1.32,"tv":277.17,"id":9433864}],"tv":359.29}]}
{"op":"mcm","clk":"4233172335","pt":1631531483222,"mc":[{"id":"1.187557653","rc":[{"batb":[[1,3.35,26.95],[2,3,35.15]],"ltp":3.7,"tv":82.12,"id":9632596},{"batb":[[1,1.28,121],[2,1.2,8.33]],"ltp":1.32,"tv":277.17,"id":9433864}]}]}
{"op":"mcm","clk":"4233173237","pt":1631531496218,"mc":[{"id":"1.187557653","rc":[{"batl":[[0,1.35,159.52]],"ltp":1.32,"tv":277.17,"id":9433864}]}]}
{"op":"mcm","clk":"4233173727","pt":1631531502662,"mc":[{"id":"1.187557653","rc":[{"batb":[[0,3,35.15],[1,2.2,42.67],[2,2,11.86]],"ltp":3.7,"tv":82.12,"id":9632596},{"batb":[[0,1.28,121],[1,1.17,313.89],[2,1.11,269.5]],"batl":[[0,1.35,146],[1,1.5,60],[2,44,7.23]],"ltp":1.32,"tv":277.17,"id":9433864}]}]}
{"op":"mcm","clk":"4233173813","pt":1631531503549,"mc":[{"id":"1.187557653","rc":[{"batl":[[0,1.5,60],[1,44,7.23],[2,44,0]],"ltp":1.32,"tv":277.17,"id":9433864}]}]}
{"op":"mcm","clk":"4233174701","pt":1631531514673,"mc":[{"id":"1.187557653","rc":[{"batb":[[0,3.4,6.63],[1,3,35.15],[2,2.2,42.67]],"batl":[[0,3.55,8.13],[1,4.7,6.38],[2,4.8,3.2]],"ltp":3.7,"tv":82.12,"id":9632596},{"batb":[[0,1.38,160.1],[1,1.28,121],[2,1.23,8.13]],"batl":[[0,1.44,145.22],[1,1.5,60],[2,44,7.23]],"ltp":1.32,"tv":277.17,"id":9433864}]}]}
{"op":"mcm","clk":"4233174790","pt":1631531515773,"mc":[{"id":"1.187557653","rc":[{"trd":[[3.55,8.33]],"batb":[[1,3.3,9.08],[2,3.25,4.54]],"batl":[[0,3.55,5.12]],"ltp":3.55,"tv":85.13,"id":9632596},{"trd":[[1.39,7.69]],"batb":[[0,1.38,245.71],[1,1.33,101.92]],"ltp":1.39,"tv":284.86,"id":9433864}],"tv":369.99}]}
{"op":"mcm","clk":"4233175317","pt":1631531522664,"mc":[{"id":"1.187557653","rc":[{"batl":[[0,1.41,72],[1,1.44,145.22],[2,1.5,60]],"ltp":1.39,"tv":284.86,"id":9433864}]}]}
{"op":"mcm","clk":"4233175549","pt":1631531525585,"mc":[{"id":"1.187557653","rc":[{"batb":[[0,3.3,9.08],[1,3.25,4.54],[2,3.2,4.54]],"batl":[[0,4.7,6.38],[1,4.8,3.2],[2,4.9,3.2]],"ltp":3.55,"tv":85.13,"id":9632596}]}]}
{"op":"mcm","clk":"4233175791","pt":1631531528976,"mc":[{"id":"1.187557653","rc":[{"batl":[[0,3.55,5.12],[1,4.7,6.38],[2,4.8,3.2]],"ltp":3.55,"tv":85.13,"id":9632596},{"batl":[[0,1.41,85.95]],"ltp":1.39,"tv":284.86,"id":9433864}]}]}
{"op":"mcm","clk":"4233176238","pt":1631531535267,"mc":[{"id":"1.187557653","rc":[{"batb":[[0,2.74,18.24],[1,2.2,42.67],[2,2,11.86]],"ltp":3.55,"tv":85.13,"id":9632596},{"batb":[[0,1.33,101.92],[1,1.17,313.89],[2,1.11,269.5]],"batl":[[0,1.41,72],[1,1.5,60],[2,44,7.23]],"ltp":1.39,"tv":284.86,"id":9433864}]}]}
{"op":"mcm","clk":"4233176252","pt":1631531535478,"mc":[{"id":"1.187557653","rc":[{"batl":[[0,1.5,60],[1,44,7.23],[2,44,0]],"ltp":1.39,"tv":284.86,"id":9433864}]}]}
{"op":"mcm","clk":"4233176678","pt":1631531541276,"mc":[{"id":"1.187557653","rc":[{"batb":[[0,3.65,8.22],[1,3.6,4.12],[2,3.55,4.12]],"batl":[[0,3.9,4.05],[1,4,57.56]],"ltp":3.55,"tv":85.13,"id":9632596},{"trd":[[1.33,202.81]],"batb":[[0,1.33,94.05]],"batl":[[0,1.36,15.32],[1,1.4,142.86],[2,1.5,60]],"ltp":1.33,"tv":300.6,"id":9433864}],"tv":385.73}]}
{"op":"mcm","clk":"4233176730","pt":1631531542033,"mc":[{"id":"1.187557653","rc":[{"batb":[[1,1.29,116.28],[2,1.28,181.15]],"ltp":1.33,"tv":300.6,"id":9433864}]}]}
{"op":"mcm","clk":"4233176751","pt":1631531542312,"mc":[{"id":"1.187557653","rc":[{"batb":[[1,1.29,23.26],[2,1.28,134.63]],"ltp":1.33,"tv":300.6,"id":9433864}]}]}
{"op":"mcm","clk":"4233177211","pt":1631531549211,"mc":[{"id":"1.187557653","rc":[{"batl":[[0,1.36,83.32]],"ltp":1.33,"tv":300.6,"id":9433864}]}]}
{"op":"mcm","clk":"4233177921","pt":1631531559185,"mc":[{"id":"1.187557653","rc":[{"batb":[[0,3.3,27.78],[1,2.94,38.07],[2,2.2,42.67]],"ltp":3.55,"tv":85.13,"id":9632596},{"batb":[[1,1.28,123.01],[2,1.17,313.89]],"batl":[[0,1.36,68],[1,1.5,60],[2,44,7.23]],"ltp":1.33,"tv":300.6,"id":9433864}]}]}
{"op":"mcm","clk":"4233177939","pt":1631531559499,"mc":[{"id":"1.187557653","rc":[{"batb":[[0,2.94,38.07],[1,2.2,42.67],[2,2,11.86]],"ltp":3.55,"tv":85.13,"id":9632596},{"batb":[[0,1.28,123.01],[1,1.17,313.89],[2,1.11,269.5]],"batl":[[0,1.5,60],[1,44,7.23],[2,44,0]],"ltp":1.33,"tv":300.6,"id":9433864}]}]}
{"op":"mcm","clk":"4233180083","pt":1631531590248,"mc":[{"id":"1.187557653","rc":[{"batb":[[0,4.2,4.23],[1,3.95,50.64],[2,2.94,38.07]],"ltp":3.55,"tv":85.13,"id":9632596},{"trd":[[1.28,16.12],[1.5,15]],"batb":[[0,1.3,13.12],[1,1.29,179.72],[2,1.28,114.95]],"batl":[[0,1.33,112.78],[1,1.34,258.12],[2,1.35,56.4]],"ltp":1.28,"tv":331.72,"id":9433864}],"tv":416.85}]}
{"op":"mcm","clk":"4233180158","pt":1631531591281,"mc":[{"id":"1.187557653","rc":[{"batb":[[1,3.95,30.38],[2,3.65,43.43]],"batl":[[0,4.5,19.99],[1,4.6,16.66],[2,4.7,16.66]],"ltp":3.55,"tv":85.13,"id":9632596},{"batl":[[0,1.33,22.56],[1,1.34,213],[2,1.35,11.28]],"ltp":1.28,"tv":331.72,"id":9433864}]}]}
{"op":"mcm","clk":"4233180185","pt":1631531591590,"mc":[{"id":"1.187557653","rc":[{"batl":[[0,4.5,6.66],[1,4.6,3.34],[2,4.7,3.34]],"ltp":3.55,"tv":85.13,"id":9632596}]}]}
{"op":"mcm","clk":"4233180733","pt":1631531598364,"mc":[{"id":"1.187557653","rc":[{"batl":[[0,1.32,86],[1,1.33,22.56],[2,1.34,213]],"ltp":1.28,"tv":331.72,"id":9433864}]}]}
{"op":"mcm","clk":"4233181652","pt":1631531609885,"mc":[{"id":"1.187557653","rc":[{"batb":[[0,3.25,28.7],[1,2.2,42.67],[2,2,11.86]],"ltp":3.55,"tv":85.13,"id":9632596},{"batb":[[0,1.24,143.68],[1,1.17,313.89],[2,1.11,269.5]],"batl":[[1,1.5,52.5],[2,44,7.23]],"ltp":1.28,"tv":331.72,"id":9433864}]}]}
{"op":"mcm","clk":"4233181704","pt":1631531610508,"mc":[{"id":"1.187557653","rc":[{"batl":[[0,1.5,52.5],[1,44,7.23],[2,44,0]],"ltp":1.28,"tv":331.72,"id":9433864}]}]}
{"op":"mcm","clk":"4233181947","pt":1631531613102,"mc":[{"id":"1.187557653","rc":[{"batb":[[0,3.3,28.62]],"ltp":3.55,"tv":85.13,"id":9632596}]}]}
{"op":"mcm","clk":"4233182211","pt":1631531617110,"mc":[{"id":"1.187557653","rc":[{"batb":[[0,4.5,6.81],[1,4.3,100.15],[2,3.3,28.62]],"batl":[[0,4.8,42.28]],"ltp":3.55,"tv":85.13,"id":9632596},{"trd":[[1.24,16.4]],"batb":[[0,1.27,13.74],[1,1.24,135.48],[2,1.17,313.89]],"batl":[[0,1.29,23.26],[1,1.3,11.62],[2,1.31,11.62]],"ltp":1.24,"tv":348.12,"id":9433864}],"tv":433.25}]}
{"op":"mcm","clk":"4233182255","pt":1631531617685,"mc":[{"id":"1.187557653","rc":[{"batb":[[2,4,34.81]],"batl":[[1,5,6],[2,5.1,3]],"ltp":3.55,"tv":85.13,"id":9632596},{"batb":[[2,1.21,168.28]],"ltp":1.24,"tv":348.12,"id":9433864}]}]}
{"op":"mcm","clk":"4233182883","pt":1631531625812,"mc":[{"id":"1.187557653","rc":[{"batb":[[2,4,34.64]],"ltp":3.55,"tv":85.13,"id":9632596},{"batl":[[0,1.29,94.26]],"ltp":1.24,"tv":348.12,"id":9433864}]}]}
{"op":"mcm","clk":"4233186585","pt":1631531675966,"mc":[{"id":"1.187557653","rc":[{"batb":[[0,3.7,42.59],[1,2.2,42.67],[2,2,11.86]],"ltp":3.55,"tv":85.13,"id":9632596},{"batb":[[0,1.21,168.28],[1,1.17,313.89],[2,1.11,269.5]],"batl":[[0,1.29,71],[1,1.5,52.5],[2,8.8,7.23]],"ltp":1.24,"tv":348.12,"id":9433864}]}]}
{"op":"mcm","clk":"4233186612","pt":1631531676481,"mc":[{"id":"1.187557653","rc":[{"batl":[[0,1.5,52.5],[1,8.8,7.23],[2,44,7.23]],"ltp":1.24,"tv":348.12,"id":9433864}]}]}
{"op":"mcm","clk":"4233190879","pt":1631531728156,"mc":[{"id":"1.187557653","rc":[{"batb":[[0,5.1,4.99],[1,4.8,54.41],[2,3.7,42.59]],"batl":[[0,5.5,48.54]],"ltp":3.55,"tv":85.13,"id":9632596},{"trd":[[1.23,16.66]],"batb":[[0,1.23,11.74],[1,1.21,168.28],[2,1.06,1260.69]],"ltp":1.23,"tv":364.78,"id":9433864}],"tv":449.91}]}
{"op":"mcm","clk":"4233190945","pt":1631531729040,"mc":[{"id":"1.187557653","rc":[{"batb":[[2,4.4,27.61]],"batl":[[1,5.6,5.36],[2,5.7,2.68]],"ltp":3.55,"tv":85.13,"id":9632596},{"batb":[[2,1.18,557.31]],"batl":[[1,1.62,622.88],[2,8.8,7.23]],"ltp":1.23,"tv":364.78,"id":9433864}]}]}
{"op":"mcm","clk":"4233191199","pt":1631531732123,"mc":[{"id":"1.187557653","rc":[{"batl":[[0,1.25,82],[1,1.5,52.5],[2,1.62,622.88]],"ltp":1.23,"tv":364.78,"id":9433864}]}]}
{"op":"mcm","clk":"4233191595","pt":1631531737860,"mc":[{"id":"1.187557653","rc":[{"batb":[[0,4.8,54.41],[1,4.4,27.61],[2,4,34.31]],"ltp":3.55,"tv":85.13,"id":9632596},{"batb":[[0,1.21,168.28],[1,1.18,557.31],[2,1.17,203.93]],"ltp":1.23,"tv":364.78,"id":9433864}]}]}
{"op":"mcm","clk":"4233191682","pt":1631531738849,"mc":[{"id":"1.187557653","rc":[{"batb":[[0,4,34.31],[1,3,5.94],[2,2.6,3.72]],"ltp":3.55,"tv":85.13,"id":9632596},{"batb":[[0,1.18,557.31],[1,1.17,203.93],[2,1.06,1260.69]],"batl":[[1,1.36,36.8],[2,1.5,52.5]],"ltp":1.23,"tv":364.78,"id":9433864}]}]}
{"op":"mcm","clk":"4233191746","pt":1631531739573,"mc":[{"id":"1.187557653","rc":[{"batl":[[0,1.36,36.8],[1,1.5,52.5],[2,1.62,622.88]],"ltp":1.23,"tv":364.78,"id":9433864}]}]}
{"op":"mcm","clk":"4233191984","pt":1631531742553,"mc":[{"id":"1.187557653","rc":[{"batb":[[0,1.17,203.93],[1,1.06,1260.69],[2,1.05,474.33]],"ltp":1.23,"tv":364.78,"id":9433864}]}]}
{"op":"mcm","clk":"4233192124","pt":1631531744164,"mc":[{"id":"1.187557653","rc":[{"batb":[[1,2.6,3.72],[2,2.2,42.67]],"batl":[[0,4.7,42.56],[1,5,6],[2,5.1,3]],"ltp":3.55,"tv":85.13,"id":9632596},{"batb":[[0,1.26,15.83],[1,1.17,203.93],[2,1.16,8.62]],"batl":[[0,1.28,33.83],[1,1.3,220.24],[2,1.36,36.8]],"ltp":1.23,"tv":364.78,"id":9433864}]}]}
{"op":"mcm","clk":"4233192206","pt":1631531745050,"mc":[{"id":"1.187557653","rc":[{"trd":[[4.7,2.22]],"batb":[[1,3.65,43.6],[2,2.6,3.72]],"batl":[[0,4.7,40.34]],"ltp":4.7,"tv":87.35,"id":9632596},{"trd":[[1.27,8.2]],"batb":[[1,1.24,145.35],[2,1.2,174.47]],"batl":[[1,1.29,23.26],[2,1.3,231.86]],"ltp":1.27,"tv":372.98,"id":9433864}],"tv":460.33}]}
{"op":"mcm","clk":"4233192288","pt":1631531746044,"mc":[{"id":"1.187557653","rc":[{"batb":[[2,1.2,712.66]],"ltp":1.27,"tv":372.98,"id":9433864}]}]}
{"op":"mcm","clk":"4233192747","pt":1631531752077,"mc":[{"id":"1.187557653","rc":[{"batb":[[0,4,366.49]],"ltp":4.7,"tv":87.35,"id":9632596},{"batl":[[0,1.28,134.83]],"ltp":1.27,"tv":372.98,"id":9433864}]}]}
{"op":"mcm","clk":"4233192925","pt":1631531754272,"mc":[{"id":"1.187557653","rc":[{"batb":[[0,3.65,43.6],[1,2.6,3.72],[2,2.2,42.67]],"ltp":4.7,"tv":87.35,"id":9632596},{"batb":[[0,1.2,712.66],[1,1.06,1260.69],[2,1.05,474.33]],"batl":[[0,1.28,101],[1,1.36,36.8],[2,1.5,52.5]],"ltp":1.27,"tv":372.98,"id":9433864}]}]}
{"op":"mcm","clk":"4233192952","pt":1631531754578,"mc":[{"id":"1.187557653","rc":[{"batl":[[0,1.36,36.8],[1,1.5,52.5],[2,1.62,622.88]],"ltp":1.27,"tv":372.98,"id":9433864}]}]}
{"op":"mcm","clk":"4233193568","pt":1631531762084,"mc":[{"id":"1.187557653","rc":[{"batb":[[0,5,30],[1,4.9,15],[2,4.8,15]],"batl":[[0,5.7,54.79]],"ltp":4.7,"tv":87.35,"id":9632596},{"trd":[[1.2,16.8]],"batb":[[0,1.2,704.26]],"batl":[[0,1.23,17.48],[1,1.26,315.34],[2,1.36,36.8]],"ltp":1.2,"tv":389.78,"id":9433864}],"tv":477.13}]}
{"op":"mcm","clk":"4233193665","pt":1631531763270,"mc":[{"id":"1.187557653","rc":[{"batb":[[0,5,6],[1,4.9,3],[2,4.8,3]],"batl":[[0,5.7,70.58],[1,5.8,7.9],[2,5.9,7.9]],"ltp":4.7,"tv":87.35,"id":9632596},{"batb":[[1,1.17,214.47],[2,1.13,8.85]],"ltp":1.2,"tv":389.78,"id":9433864}]}]}
{"op":"mcm","clk":"4233193756","pt":1631531764254,"mc":[{"id":"1.187557653","rc":[{"batl":[[0,5.7,60.05],[1,5.8,2.64],[2,5.9,2.64]],"ltp":4.7,"tv":87.35,"id":9632596}]}]}
{"op":"mcm","clk":"4233194263","pt":1631531770268,"mc":[{"id":"1.187557653","rc":[{"batl":[[0,1.23,609.48]],"ltp":1.2,"tv":389.78,"id":9433864}]}]}
{"op":"mcm","clk":"4233194334","pt":1631531771197,"mc":[{"id":"1.187557653","rc":[{"batb":[[0,4.5,26.19],[1,4,33.72],[2,2.6,3.72]],"ltp":4.7,"tv":87.35,"id":9632596},{"batb":[[2,1.06,1260.69]],"batl":[[0,1.23,592],[1,1.36,36.8],[2,1.5,52.5]],"ltp":1.2,"tv":389.78,"id":9433864}]}]}
{"op":"mcm","clk":"4233194362","pt":1631531771512,"mc":[{"id":"1.187557653","rc":[{"batb":[[0,4,33.72],[1,2.6,3.72],[2,2.2,42.67]],"ltp":4.7,"tv":87.35,"id":9632596},{"batb":[[0,1.2,538.19]],"batl":[[0,1.36,36.8],[1,1.5,52.5],[2,1.62,622.88]],"ltp":1.2,"tv":389.78,"id":9433864}]}]}
{"op":"mcm","clk":"4233194949","pt":1631531778590,"mc":[{"id":"1.187557653","rc":[{"batl":[[0,5,6.64],[1,5.1,66.05]],"ltp":4.7,"tv":87.35,"id":9632596},{"batb":[[0,1.26,158.74],[1,1.24,24.2],[2,1.23,12.1]],"batl":[[0,1.27,25.98],[1,1.29,178.75],[2,1.36,36.8]],"ltp":1.2,"tv":389.78,"id":9433864}]}]}
{"op":"mcm","clk":"4233195069","pt":1631531779685,"mc":[{"id":"1.187557653","rc":[{"batb":[[0,4.6,6.52],[1,4.5,3.26],[2,4.4,3.26]],"ltp":4.7,"tv":87.35,"id":9632596},{"trd":[[1.26,16.52]],"batb":[[0,1.26,150.48],[1,1.24,171.65]],"ltp":1.26,"tv":406.3,"id":9433864}],"tv":493.65}]}
{"op":"mcm","clk":"4233195713","pt":1631531787220,"mc":[{"id":"1.187557653","rc":[{"batl":[[0,1.36,36.8],[1,1.5,52.5],[2,1.62,622.88]],"ltp":1.26,"tv":406.3,"id":9433864}]}]}
{"op":"mcm","clk":"4233195754","pt":1631531787733,"mc":[{"id":"1.187557653","rc":[{"batb":[[0,3.65,22.34],[1,2.6,3.72],[2,2.2,42.67]],"ltp":4.7,"tv":87.35,"id":9632596},{"batb":[[0,1.2,538.19],[1,1.19,183.85],[2,1.06,1260.69]],"ltp":1.26,"tv":406.3,"id":9433864}]}]}
{"op":"mcm","clk":"4233196335","pt":1631531794245,"mc":[{"id":"1.187557653","rc":[{"batb":[[1,1.19,185.85]],"ltp":1.26,"tv":406.3,"id":9433864}]}]}
{"op":"mcm","clk":"4233196871","pt":1631531800636,"mc":[{"id":"1.187557653","rc":[{"batb":[[0,1.19,186.85],[1,1.06,1260.69],[2,1.05,474.33]],"ltp":1.26,"tv":406.3,"id":9433864}]}]}
{"op":"mcm","clk":"4233196993","pt":1631531802108,"mc":[{"id":"1.187557653","rc":[{"batl":[[0,4.4,50.83]],"ltp":4.7,"tv":87.35,"id":9632596},{"batb":[[0,1.29,198.5],[1,1.28,11.62],[2,1.27,11.62]],"batl":[[0,1.31,16.47],[1,1.34,200.87],[2,1.36,36.8]],"ltp":1.26,"tv":406.3,"id":9433864}]}]}
{"op":"mcm","clk":"4233197095","pt":1631531803197,"mc":[{"id":"1.187557653","rc":[{"batb":[[0,3.3,28.12]],"batl":[[0,4.4,45.46]],"ltp":4.7,"tv":87.35,"id":9632596},{"trd":[[1.29,16.12]],"batb":[[0,1.29,15.2]],"batl":[[0,1.33,22.56],[1,1.34,11.28],[2,1.35,11.28]],"ltp":1.29,"tv":422.42,"id":9433864}],"tv":509.77}]}
{"op":"mcm","clk":"4233197992","pt":1631531813539,"mc":[{"id":"1.187557653","rc":[{"batb":[[0,1.24,147.11],[1,1.23,523.6],[2,1.19,1]],"batl":[[0,1.36,36.8],[1,1.5,52.5],[2,1.62,622.88]],"ltp":1.29,"tv":422.42,"id":9433864}]}]}
{"op":"mcm","clk":"4233198180","pt":1631531816228,"mc":[{"id":"1.187557653","rc":[{"batl":[[0,1.33,51],[1,1.36,36.8],[2,1.5,52.5]],"ltp":1.29,"tv":422.42,"id":9433864}]}]}
{"op":"mcm","clk":"4233198187","pt":1631531816332,"mc":[{"id":"1.187557653","rc":[{"batl":[[0,1.36,36.8],[1,1.5,52.5],[2,1.62,622.88]],"ltp":1.29,"tv":422.42,"id":9433864}]}]}
{"op":"mcm","clk":"4233198397","pt":1631531818711,"mc":[{"id":"1.187557653","rc":[{"batl":[[0,1.5,52.5],[1,1.62,622.88],[2,8.8,7.23]],"ltp":1.29,"tv":422.42,"id":9433864}]}]}
{"op":"mcm","clk":"4233198670","pt":1631531821952,"mc":[{"id":"1.187557653","rc":[{"batl":[[0,1.43,36.8],[1,1.5,52.5],[2,1.62,622.88]],"ltp":1.29,"tv":422.42,"id":9433864}]}]}
{"op":"mcm","clk":"4233199682","pt":1631531834879,"mc":[{"id":"1.187557653","rc":[{"batb":[[1,1.19,1],[2,1.06,1260.69]],"ltp":1.29,"tv":422.42,"id":9433864}]}]}
{"op":"mcm","clk":"4233199804","pt":1631531836269,"mc":[{"id":"1.187557653","rc":[{"batb":[[0,4.8,4.98],[1,4.5,48.84],[2,3.3,28.12]],"batl":[[0,5,4.03],[1,5.1,48.4]],"ltp":4.7,"tv":87.35,"id":9632596},{"trd":[[1.24,32.92]],"batb":[[0,1.24,138.85]],"batl":[[0,1.27,3090.82],[1,1.28,117.2],[2,1.29,58.6]],"ltp":1.24,"tv":438.94,"id":9433864}],"tv":526.29}]}
{"op":"mcm","clk":"4233199873","pt":1631531837276,"mc":[{"id":"1.187557653","rc":[{"batl":[[1,5.1,77.8],[2,5.2,14.7]],"ltp":4.7,"tv":87.35,"id":9632596},{"batb":[[2,1.15,8.7]],"batl":[[0,1.27,94.49],[1,1.28,70.32],[2,1.29,35.16]],"ltp":1.24,"tv":438.94,"id":9433864}]}]}
{"op":"mcm","clk":"4233199911","pt":1631531837647,"mc":[{"id":"1.187557653","rc":[{"batb":[[2,4,33.72]],"batl":[[1,5.1,54.28],[2,5.2,2.94]],"ltp":4.7,"tv":87.35,"id":9632596},{"batb":[[1,1.19,185.77]],"batl":[[1,1.28,23.44],[2,1.29,11.72]],"ltp":1.24,"tv":438.94,"id":9433864}]}]}
{"op":"mcm","clk":"4233200032","pt":1631531839090,"mc":[{"id":"1.187557653","rc":[{"batb":[[1,1.2,538.19],[2,1.19,185.77]],"ltp":1.24,"tv":438.94,"id":9433864}]}]}
{"op":"mcm","clk":"4233200196","pt":1631531841267,"mc":[{"id":"1.187557653","rc":[{"trd":[[4.8,8.54]],"batb":[[0,4.5,49.55],[1,4,33.72],[2,3.65,22.43]],"batl":[[0,5,15.34]],"ltp":4.8,"tv":95.89,"id":9632596},{"batl":[[1,1.28,199.81]],"ltp":1.24,"tv":438.94,"id":9433864}],"tv":534.83}]}
{"op":"mcm","clk":"4233200214","pt":1631531841574,"mc":[{"id":"1.187557653","rc":[{"batl":[[0,5,4.03]],"ltp":4.8,"tv":95.89,"id":9632596},{"batl":[[0,1.27,149.49],[1,1.28,23.44]],"ltp":1.24,"tv":438.94,"id":9433864}]}]}
{"op":"mcm","clk":"4233200595","pt":1631531847065,"mc":[{"id":"1.187557653","rc":[{"batb":[[0,5,10],[1,3.65,22.43],[2,2.6,3.72]],"ltp":4.8,"tv":95.89,"id":9632596},{"batb":[[0,1.2,538.19],[1,1.19,185.77],[2,1.06,1260.69]],"batl":[[0,1.27,55],[1,1.43,36.8],[2,1.5,52.5]],"ltp":1.24,"tv":438.94,"id":9433864}]}]}
{"op":"mcm","clk":"4233200620","pt":1631531847476,"mc":[{"id":"1.187557653","rc":[{"batl":[[0,1.43,36.8],[1,1.5,52.5],[2,1.62,622.88]],"ltp":1.24,"tv":438.94,"id":9433864}]}]}
{"op":"mcm","clk":"4233200838","pt":1631531850285,"mc":[{"id":"1.187557653","rc":[{"batb":[[2,3,5.94]],"ltp":4.8,"tv":95.89,"id":9632596}]}]}
{"op":"mcm","clk":"4233201219","pt":1631531855175,"mc":[{"id":"1.187557653","rc":[{"trd":[[5,1.01]],"batb":[[0,3.65,22.43],[1,3,5.94],[2,2.6,3.72]],"ltp":5.0,"tv":96.9,"id":9632596},{"trd":[[1.25,4.05]],"ltp":1.25,"tv":442.99,"id":9433864}],"tv":539.89}]}
{"op":"mcm","clk":"4233201461","pt":1631531858288,"mc":[{"id":"1.187557653","rc":[{"trd":[[6,8.99]],"ltp":6.0,"tv":105.89,"id":9632596},{"trd":[[1.2,61.75]],"batb":[[0,1.2,493.24]],"ltp":1.2,"tv":487.94,"id":9433864}],"tv":593.83}]}
{"op":"mcm","clk":"4233202499","pt":1631531871192,"mc":[{"id":"1.187557653","rc":[{"batb":[[0,4.2,4.89],[1,4,61.33],[2,3.65,22.43]],"batl":[[0,4.4,7.06],[1,4.5,795.66],[2,4.7,42.56]],"ltp":6.0,"tv":105.89,"id":9632596},{"batb":[[0,1.28,117.2],[1,1.27,58.6],[2,1.26,58.6]],"ltp":1.2,"tv":487.94,"id":9433864}]}]}
{"op":"mcm","clk":"4233202590","pt":1631531872286,"mc":[{"id":"1.187557653","rc":[{"trd":[[4.4,2.36]],"batl":[[0,4.4,4.7],[1,4.7,8.52],[2,5,94.66]],"ltp":4.4,"tv":108.25,"id":9632596},{"trd":[[1.29,24.18]],"batb":[[0,1.28,238.12]],"batl":[[0,1.33,112.78],[1,1.34,56.4],[2,1.35,56.4]],"ltp":1.29,"tv":496.0,"id":9433864}],"tv":604.25}]}
{"op":"mcm","clk":"4233202597","pt":1631531872394,"mc":[{"id":"1.187557653","rc":[{"batb":[[0,1.28,191.24],[1,1.27,35.16],[2,1.26,35.16]],"batl":[[0,1.33,22.56],[1,1.34,11.28],[2,1.35,11.28]],"ltp":1.29,"tv":496.0,"id":9433864}]}]}
{"op":"mcm","clk":"4233202885","pt":1631531876111,"mc":[{"id":"1.187557653","rc":[{"batl":[[1,4.5,19.81],[2,4.7,8.52]],"ltp":4.4,"tv":108.25,"id":9632596},{"batl":[[0,1.32,147.67],[1,1.33,22.56],[2,1.34,11.28]],"ltp":1.29,"tv":496.0,"id":9433864}]}]}
{"op":"mcm","clk":"4233202898","pt":1631531876316,"mc":[{"id":"1.187557653","rc":[{"batl":[[1,4.7,8.52],[2,5,94.66]],"ltp":4.4,"tv":108.25,"id":9632596},{"batl":[[0,1.33,22.56],[1,1.34,11.28],[2,1.35,11.28]],"ltp":1.29,"tv":496.0,"id":9433864}]}]}
{"op":"mcm","clk":"4233203126","pt":1631531879311,"mc":[{"id":"1.187557653","rc":[{"batl":[[0,1.31,141],[1,1.33,22.56],[2,1.34,11.28]],"ltp":1.29,"tv":496.0,"id":9433864}]}]}
{"op":"mcm","clk":"4233203362","pt":1631531882529,"mc":[{"id":"1.187557653","rc":[{"batb":[[0,4,61.33],[1,3.65,22.43],[2,3.35,28.03]],"batl":[[0,4.7,8.52],[1,5,94.66],[2,5,0]],"ltp":4.4,"tv":108.25,"id":9632596}]}]}
{"op":"mcm","clk":"4233203456","pt":1631531883925,"mc":[{"id":"1.187557653","rc":[{"batb":[[0,3.35,28.03],[1,2.6,3.72],[2,2.2,42.67]],"ltp":4.4,"tv":108.25,"id":9632596},{"batb":[[0,1.23,627.02],[1,1.19,1],[2,1.06,1260.69]],"batl":[[0,1.29,4.05],[1,1.31,141],[2,1.43,36.8]],"ltp":1.29,"tv":496.0,"id":9433864}]}]}
{"op":"mcm","clk":"4233203571","pt":1631531885221,"mc":[{"id":"1.187557653","rc":[{"trd":[[4.4,3.55]],"batl":[[0,4.4,3.51]],"ltp":4.4,"tv":109.44,"id":9632596},{"trd":[[1.29,28.23]],"batl":[[0,1.31,18.45],[1,1.43,36.8],[2,1.5,52.5]],"ltp":1.29,"tv":500.04,"id":9433864}],"tv":609.49}]}
{"op":"mcm","clk":"4233203581","pt":1631531885436,"mc":[{"id":"1.187557653","rc":[{"batl":[[0,1.43,36.8],[1,1.5,52.5],[2,1.62,622.88]],"ltp":1.29,"tv":500.04,"id":9433864}]}]}
{"op":"mcm","clk":"4233203780","pt":1631531888028,"mc":[{"id":"1.187557653","rc":[{"batl":[[0,1.32,458.36],[1,1.43,36.8],[2,1.5,52.5]],"ltp":1.29,"tv":500.04,"id":9433864}]}]}
{"op":"mcm","clk":"4233203793","pt":1631531888334,"mc":[{"id":"1.187557653","rc":[{"batl":[[0,1.43,36.8],[1,1.5,52.5],[2,1.62,622.88]],"ltp":1.29,"tv":500.04,"id":9433864}]}]}
{"op":"mcm","clk":"4233204727","pt":1631531902862,"mc":[{"id":"1.187557653","rc":[{"batb":[[0,1.23,148.11]],"ltp":1.29,"tv":500.04,"id":9433864}]}]}
{"op":"mcm","clk":"4233204805","pt":1631531904267,"mc":[{"id":"1.187557653","rc":[{"batb":[[0,4.5,64.54],[1,3.35,28.03],[2,2.6,3.72]],"batl":[[0,5.1,6.68]],"ltp":4.4,"tv":109.44,"id":9632596},{"trd":[[1.23,33.18]],"batb":[[0,1.24,206.37],[1,1.23,139.85],[2,1.19,1]],"batl":[[0,1.26,175.41],[1,1.27,3067.6],[2,1.28,59.06]],"ltp":1.23,"tv":516.56,"id":9433864}],"tv":626.01}]}
{"op":"mcm","clk":"4233204866","pt":1631531905259,"mc":[{"id":"1.187557653","rc":[{"batb":[[1,1.23,261.81],[2,1.22,60.98]],"batl":[[0,1.26,111.91],[1,1.27,70.87],[2,1.28,35.44]],"ltp":1.23,"tv":516.56,"id":9433864}]}]}
{"op":"mcm","clk":"4233204897","pt":1631531905670,"mc":[{"id":"1.187557653","rc":[{"batb":[[1,4.1,33.39],[2,3.65,22.18]],"ltp":4.4,"tv":109.44,"id":9632596},{"batb":[[1,1.23,164.25],[2,1.22,12.2]],"ltp":1.23,"tv":516.56,"id":9433864}]}]}
{"op":"mcm","clk":"4233205146","pt":1631531909248,"mc":[{"id":"1.187557653","rc":[{"batl":[[0,5.1,26.07]],"ltp":4.4,"tv":109.44,"id":9632596},{"batl":[[2,1.28,227.05]],"ltp":1.23,"tv":516.56,"id":9433864}]}]}
{"op":"mcm","clk":"4233205164","pt":1631531909462,"mc":[{"id":"1.187557653","rc":[{"batl":[[0,5.1,6.68]],"ltp":4.4,"tv":109.44,"id":9632596},{"batl":[[2,1.28,35.44]],"ltp":1.23,"tv":516.56,"id":9433864}]}]}
{"op":"mcm","clk":"4233205255","pt":1631531910761,"mc":[{"id":"1.187557653","rc":[{"batb":[[0,4.5,151.68]],"ltp":4.4,"tv":109.44,"id":9632596}]}]}
{"op":"mcm","clk":"4233205832","pt":1631531920167,"mc":[{"id":"1.187557653","rc":[{"batb":[[0,4.1,33.39],[1,3.65,22.18],[2,2.6,3.72]],"ltp":4.4,"tv":109.44,"id":9632596},{"batb":[[0,1.23,139.85],[1,1.2,493.12],[2,1.19,188.11]],"batl":[[0,1.43,36.8],[1,1.5,52.5],[2,1.62,622.88]],"ltp":1.23,"tv":516.56,"id":9433864}]}]}
{"op":"mcm","clk":"4233205845","pt":1631531920374,"mc":[{"id":"1.187557653","rc":[{"batb":[[0,3.65,22.18],[1,2.6,3.72],[2,2.2,42.67]],"ltp":4.4,"tv":109.44,"id":9632596},{"batb":[[0,1.2,493.12],[1,1.19,188.11],[2,1.06,1260.69]],"ltp":1.23,"tv":516.56,"id":9433864}]}]}
{"op":"mcm","clk":"4233206047","pt":1631531923284,"mc":[{"id":"1.187557653","rc":[{"batb":[[0,3.7,22.09],[1,3.65,22.18],[2,2.6,3.72]],"ltp":4.4,"tv":109.44,"id":9632596}]}]}
{"op":"mcm","clk":"4233206077","pt":1631531923698,"mc":[{"id":"1.187557653","rc":[{"batb":[[1,2.6,3.72],[2,2.2,42.67]],"ltp":4.4,"tv":109.44,"id":9632596}]}]}
{"op":"mcm","clk":"4233207503","pt":1631531943604,"mc":[{"id":"1.187557653","rc":[{"batb":[[0,1.19,188.11],[1,1.06,1260.69],[2,1.05,474.33]],"ltp":1.23,"tv":516.56,"id":9433864}]}]}
{"op":"mcm","clk":"4233207577","pt":1631531944692,"mc":[{"id":"1.187557653","rc":[{"batb":[[0,4.3,5.4],[1,3.7,22.09],[2,2.6,3.72]],"batl":[[0,4.5,50.49],[1,4.7,6.38],[2,4.8,3.2]],"ltp":4.4,"tv":109.44,"id":9632596},{"batb":[[0,1.28,195.44],[1,1.19,188.11],[2,1.18,8.47]],"batl":[[0,1.33,204.21],[1,1.43,36.8],[2,1.5,52.5]],"ltp":1.23,"tv":516.56,"id":9433864}]}]}
{"op":"mcm","clk":"4233207680","pt":1631531945906,"mc":[{"id":"1.187557653","rc":[{"batb":[[2,3.35,27.87]],"ltp":4.4,"tv":109.44,"id":9632596},{"trd":[[1.28,32.24]],"batb":[[0,1.28,309.05],[1,1.23,149.96],[2,1.19,1]],"batl":[[0,1.32,22.72],[1,1.33,215.57],[2,1.34,11.36]],"ltp":1.28,"tv":532.68,"id":9433864}],"tv":642.13}]}
{"op":"mcm","clk":"4233207770","pt":1631531947197,"mc":[{"id":"1.187557653","rc":[{"batb":[[2,1.22,485.14]],"ltp":1.28,"tv":532.68,"id":9433864}]}]}
{"op":"mcm","clk":"4233208144","pt":1631531952609,"mc":[{"id":"1.187557653","rc":[{"batl":[[0,1.31,61],[1,1.32,22.72],[2,1.33,215.57]],"ltp":1.28,"tv":532.68,"id":9433864}]}]}
{"op":"mcm","clk":"4233209517","pt":1631531972241,"mc":[{"id":"1.187557653","rc":[{"batb":[[0,3.7,22.09],[1,3.35,27.87],[2,2.6,3.72]],"batl":[[0,4.5,44.44]],"ltp":4.4,"tv":109.44,"id":9632596},{"batb":[[0,1.28,121.67]],"batl":[[2,1.33,11.36]],"ltp":1.28,"tv":532.68,"id":9433864}]}]}
{"op":"mcm","clk":"4233209555","pt":1631531972763,"mc":[{"id":"1.187557653","rc":[{"batb":[[0,3.35,27.87],[1,2.6,3.72],[2,2.2,42.67]],"ltp":4.4,"tv":109.44,"id":9632596},{"batb":[[0,1.23,149.96],[1,1.22,485.14],[2,1.19,1]],"batl":[[1,1.43,36.8],[2,1.5,52.5]],"ltp":1.28,"tv":532.68,"id":9433864}]}]}
{"op":"mcm","clk":"4233209628","pt":1631531973649,"mc":[{"id":"1.187557653","rc":[{"batl":[[0,1.43,36.8],[1,1.5,52.5],[2,1.62,622.88]],"ltp":1.28,"tv":532.68,"id":9433864}]}]}
{"op":"mcm","clk":"4233209804","pt":1631531976159,"mc":[{"id":"1.187557653","rc":[{"batb":[[1,1.19,1],[2,1.06,1260.69]],"ltp":1.28,"tv":532.68,"id":9433864}]}]}
{"op":"mcm","clk":"4233209927","pt":1631531978036,"mc":[{"id":"1.187557653","rc":[{"batb":[[1,2.2,42.67],[2,2,11.86]],"batl":[[0,4.1,6.55],[1,4.2,81.54],[2,4.3,3.58]],"ltp":4.4,"tv":109.44,"id":9632596},{"batb":[[0,1.32,151.52],[1,1.23,149.96],[2,1.2,8.33]],"batl":[[0,1.34,13.61],[1,1.37,192.38],[2,1.43,36.8]],"ltp":1.28,"tv":532.68,"id":9433864}]}]}
{"op":"mcm","clk":"4233210016","pt":1631531979174,"mc":[{"id":"1.187557653","rc":[{"batb":[[0,3.8,7.9],[1,3.75,3.94],[2,3.7,3.94]],"ltp":4.4,"tv":109.44,"id":9632596},{"trd":[[1.33,218.69]],"batb":[[0,1.33,93.73],[1,1.32,151.52],[2,1.29,117.99]],"ltp":1.33,"tv":548.56,"id":9433864}],"tv":658.01}]}
{"op":"mcm","clk":"4233213535","pt":1631532025217,"mc":[{"id":"1.187557653","rc":[{"batb":[[0,3.8,3.95],[1,3.75,1.97],[2,3.7,1.97]],"batl":[[0,4.2,3.57],[1,4.3,1.79],[2,4.4,1.79]],"ltp":4.4,"tv":109.44,"id":9632596},{"batb":[[1,1.32,75.76]],"batl":[[0,1.43,36.8],[1,1.5,52.5],[2,1.62,622.88]],"ltp":1.33,"tv":548.56,"id":9433864}]}]}
{"op":"mcm","clk":"4233213572","pt":1631532025740,"mc":[{"id":"1.187557653","rc":[{"batb":[[0,3.05,35.31],[1,2.2,42.67],[2,2,11.86]],"ltp":4.4,"tv":109.44,"id":9632596},{"batb":[[0,1.29,117.99],[1,1.25,468.07],[2,1.19,1]],"ltp":1.33,"tv":548.56,"id":9433864}]}]}
{"op":"mcm","clk":"4233215249","pt":1631532049243,"mc":[{"id":"1.187557653","rc":[{"batb":[[1,1.19,1],[2,1.1,297.11]],"batl":[[2,8.8,7.23]],"ltp":1.33,"tv":548.56,"id":9433864}]}]}
{"op":"mcm","clk":"4233215369","pt":1631532051230,"mc":[{"id":"1.187557653","rc":[{"batl":[[0,3.65,24.66],[1,3.7,107.27],[2,3.75,12.34]],"ltp":4.4,"tv":109.44,"id":9632596},{"batb":[[0,1.38,14.85],[1,1.29,117.99],[2,1.23,8.13]],"batl":[[0,1.4,8.31],[1,1.43,192.04],[2,1.5,52.5]],"ltp":1.33,"tv":548.56,"id":9433864}]}]}
{"op":"mcm","clk":"4233215452","pt":1631532052220,"mc":[{"id":"1.187557653","rc":[{"batb":[[0,3.35,44.78],[1,3.3,22.4],[2,3.25,22.4]],"ltp":4.4,"tv":109.44,"id":9632596},{"trd":[[1.38,15.38]],"batb":[[0,1.38,92.18],[1,1.33,99.33]],"ltp":1.38,"tv":563.94,"id":9433864}],"tv":673.39}]}
{"op":"mcm","clk":"4233215461","pt":1631532052330,"mc":[{"id":"1.187557653","rc":[{"batb":[[0,3.35,8.96],[1,3.3,4.48],[2,3.25,4.48]],"batl":[[0,3.65,8.22],[1,3.7,99.05],[2,3.75,4.12]],"ltp":4.4,"tv":109.44,"id":9632596}]}]}
{"op":"mcm","clk":"4233215595","pt":1631532054051,"mc":[{"id":"1.187557653","rc":[{"batb":[[2,1.31,442.37]],"batl":[[1,1.43,155.24]],"ltp":1.38,"tv":563.94,"id":9433864}]}]}
{"op":"mcm","clk":"4233216266","pt":1631532062156,"mc":[{"id":"1.187557653","rc":[{"batb":[[0,1.38,85.02]],"batl":[[0,1.43,155.24],[1,1.5,52.5],[2,1.89,469.65]],"ltp":1.38,"tv":563.94,"id":9433864}]}]}
{"op":"mcm","clk":"4233216511","pt":1631532065276,"mc":[{"id":"1.187557653","rc":[{"batb":[[0,3.55,4.82],[1,3.35,8.96],[2,3.3,4.48]],"batl":[[1,3.7,107.74]],"ltp":4.4,"tv":109.44,"id":9632596},{"batl":[[0,1.43,423.07]],"ltp":1.38,"tv":563.94,"id":9433864}]}]}
{"op":"mcm","clk":"4233216524","pt":1631532065381,"mc":[{"id":"1.187557653","rc":[{"batl":[[0,1.43,155.24]],"ltp":1.38,"tv":563.94,"id":9433864}]}]}
{"op":"mcm","clk":"4233216928","pt":1631532070657,"mc":[{"id":"1.187557653","rc":[{"batb":[[0,2.8,18.58],[1,2.2,42.67],[2,2,11.86]],"ltp":4.4,"tv":109.44,"id":9632596},{"batb":[[0,1.33,99.33],[1,1.31,442.37],[2,1.19,1]],"batl":[[0,1.5,52.5],[1,1.89,469.65],[2,8.8,7.23]],"ltp":1.38,"tv":563.94,"id":9433864}]}]}
{"op":"mcm","clk":"4233217957","pt":1631532083668,"mc":[{"id":"1.187557653","rc":[{"batl":[[1,1.54,36.8],[2,1.89,469.65]],"ltp":1.38,"tv":563.94,"id":9433864}]}]}
{"op":"mcm","clk":"4233221316","pt":1631532127764,"mc":[{"id":"1.187557653","rc":[{"batb":[[1,1.19,1],[2,1.17,314.59]],"batl":[[1,1.89,469.65],[2,8.8,7.23]],"ltp":1.38,"tv":563.94,"id":9433864}]}]}
{"op":"mcm","clk":"4233221428","pt":1631532129068,"mc":[{"id":"1.187557653","rc":[{"batb":[[1,2,11.86],[2,1.8,11.86]],"batl":[[0,3.25,64.62],[1,3.3,13.85],[2,3.35,13.85]],"ltp":4.4,"tv":109.44,"id":9632596},{"batb":[[0,1.45,12.86],[1,1.33,99.33],[2,1.19,1]],"batl":[[0,1.47,12.64],[1,1.5,52.5],[2,1.52,177.39]],"ltp":1.38,"tv":563.94,"id":9433864}]}]}
{"op":"mcm","clk":"4233221514","pt":1631532130160,"mc":[{"id":"1.187557653","rc":[{"batb":[[0,3,10],[1,2.98,5],[2,2.96,5]],"batl":[[0,3.25,46.16],[1,3.3,4.62],[2,3.35,4.62]],"ltp":4.4,"tv":109.44,"id":9632596},{"trd":[[1.45,14.7]],"batb":[[0,1.45,73.46],[1,1.4,79.16]],"ltp":1.45,"tv":578.64,"id":9433864}],"tv":688.09}]}
{"op":"mcm","clk":"4233221680","pt":1631532132240,"mc":[{"id":"1.187557653","rc":[{"batb":[[2,1.34,431.32]],"ltp":1.45,"tv":578.64,"id":9433864}]}]}
{"op":"mcm","clk":"4233222268","pt":1631532139946,"mc":[{"id":"1.187557653","rc":[{"batb":[[0,1.45,67.95]],"batl":[[0,1.5,52.5],[1,1.52,177.39],[2,1.89,469.65]],"ltp":1.45,"tv":578.64,"id":9433864}]}]}
{"op":"mcm","clk":"4233222480","pt":1631532142852,"mc":[{"id":"1.187557653","rc":[{"batb":[[0,3.15,6.46],[1,3,10],[2,2.98,5]],"batl":[[0,3.25,51.93]],"ltp":4.4,"tv":109.44,"id":9632596}]}]}
{"op":"mcm","clk":"4233223343","pt":1631532154267,"mc":[{"id":"1.187557653","rc":[{"batb":[[0,2.54,23.93],[1,2,11.86],[2,1.8,11.86]],"ltp":4.4,"tv":109.44,"id":9632596},{"batb":[[0,1.4,79.16],[1,1.34,431.32],[2,1.19,1]],"batl":[[1,1.89,469.65],[2,8.8,7.23]],"ltp":1.45,"tv":578.64,"id":9433864}]}]}
{"op":"mcm","clk":"4233223675","pt":1631532158970,"mc":[{"id":"1.187557653","rc":[{"batb":[[1,1.19,1],[2,1.17,314.59]],"ltp":1.45,"tv":578.64,"id":9433864}]}]}
{"op":"mcm","clk":"4233223831","pt":1631532161100,"mc":[{"id":"1.187557653","rc":[{"batl":[[1,1.61,1762.11],[2,1.89,469.65]],"ltp":1.45,"tv":578.64,"id":9433864}]}]}
{"op":"mcm","clk":"4233223917","pt":1631532162811,"mc":[{"id":"1.187557653","rc":[{"batb":[[1,1.38,415.85],[2,1.19,1]],"ltp":1.45,"tv":578.64,"id":9433864}]}]}
{"op":"mcm","clk":"4233224135","pt":1631532167020,"mc":[{"id":"1.187557653","rc":[{"batl":[[1,1.89,469.65],[2,8.8,7.23]],"ltp":1.45,"tv":578.64,"id":9433864}]}]}
{"op":"mcm","clk":"4233224160","pt":1631532167695,"mc":[{"id":"1.187557653","rc":[{"batb":[[1,1.19,1],[2,1.17,314.59]],"batl":[[1,1.63,18.4],[2,1.89,469.65]],"ltp":1.45,"tv":578.64,"id":9433864}]}]}
{"op":"mcm","clk":"4233224231","pt":1631532169196,"mc":[{"id":"1.187557653","rc":[{"trd":[[4.1,2.44]],"batb":[[0,3.35,44.78],[1,3.3,22.4],[2,3.25,22.4]],"batl":[[0,3.55,75.83]],"ltp":4.1,"tv":111.88,"id":9632596},{"trd":[[1.32,23.46],[1.4,207.55]],"batb":[[0,1.19,1],[1,1.17,314.59],[2,1.1,297.11]],"batl":[[0,1.4,63.7],[1,1.41,10.93],[2,1.42,783.16]],"ltp":1.32,"tv":744.55,"id":9433864}],"tv":856.43}]}
{"op":"mcm","clk":"4233224306","pt":1631532170239,"mc":[{"id":"1.187557653","rc":[{"batb":[[0,3.35,26.87],[1,3.3,13.44],[2,3.25,13.44]],"batl":[[1,3.65,41.1],[2,3.7,20.56]],"ltp":4.1,"tv":111.88,"id":9632596},{"batb":[[0,1.34,96.32],[1,1.19,1],[2,1.17,314.59]],"batl":[[0,1.4,14.29],[2,1.47,261.31]],"ltp":1.32,"tv":744.55,"id":9433864}]}]}
{"op":"mcm","clk":"4233224362","pt":1631532170914,"mc":[{"id":"1.187557653","rc":[{"batb":[[0,3.35,8.96],[1,3.3,4.48],[2,3.25,4.48]],"batl":[[1,3.65,8.22],[2,3.7,4.12]],"ltp":4.1,"tv":111.88,"id":9632596},{"batb":[[1,1.31,442.37],[2,1.19,1]],"ltp":1.32,"tv":744.55,"id":9433864}]}]}
{"op":"mcm","clk":"4233224597","pt":1631532174233,"mc":[{"id":"1.187557653","rc":[{"trd":[[1.4,235.67]],"batl":[[0,1.41,11.16],[1,1.43,2.31]],"ltp":1.4,"tv":772.67,"id":9433864}],"tv":884.55}]}
{"op":"mcm","clk":"4233224604","pt":1631532174337,"mc":[{"id":"1.187557653","rc":[{"batl":[[1,1.47,261.31],[2,1.5,52.5]],"ltp":1.4,"tv":772.67,"id":9433864}]}]}
{"op":"mcm","clk":"4233225210","pt":1631532184828,"mc":[{"id":"1.187557653","rc":[{"trd":[[1.4,235.83]],"batl":[[0,1.41,11.08]],"ltp":1.4,"tv":772.83,"id":9433864}],"tv":884.71}]}
{"op":"mcm","clk":"4233225427","pt":1631532188147,"mc":[{"id":"1.187557653","rc":[{"trd":[[1.4,236.13],[1.41,21.48]],"batl":[[0,1.47,261.5],[1,1.5,52.5],[2,1.63,18.4]],"ltp":1.41,"tv":794.61,"id":9433864}],"tv":906.49}]}
{"op":"mcm","clk":"4233225512","pt":1631532189131,"mc":[{"id":"1.187557653","rc":[{"batb":[[0,2.96,38.74],[1,2.68,20.59],[2,2,11.86]],"ltp":4.1,"tv":111.88,"id":9632596},{"batl":[[0,1.5,52.5],[1,1.63,18.4],[2,1.89,469.65]],"ltp":1.41,"tv":794.61,"id":9433864}]}]}
{"op":"mcm","clk":"4233225541","pt":1631532189444,"mc":[{"id":"1.187557653","rc":[{"batb":[[0,2.68,20.59],[1,2,11.86],[2,1.8,11.86]],"ltp":4.1,"tv":111.88,"id":9632596}]}]}
{"op":"mcm","clk":"4233225666","pt":1631532191256,"mc":[{"id":"1.187557653","rc":[{"batl":[[0,1.46,1336.84],[1,1.5,52.5],[2,1.63,18.4]],"ltp":1.41,"tv":794.61,"id":9433864}]}]}
{"op":"mcm","clk":"4233225688","pt":1631532191570,"mc":[{"id":"1.187557653","rc":[{"batl":[[0,1.5,52.5],[1,1.63,18.4],[2,1.89,469.65]],"ltp":1.41,"tv":794.61,"id":9433864}]}]}
{"op":"mcm","clk":"4233225750","pt":1631532192860,"mc":[{"id":"1.187557653","rc":[{"batb":[[0,2.72,19.92]],"ltp":4.1,"tv":111.88,"id":9632596},{"batb":[[0,1.33,98.99]],"ltp":1.41,"tv":794.61,"id":9433864}]}]}
{"op":"mcm","clk":"4233226307","pt":1631532200950,"mc":[{"id":"1.187557653","rc":[{"batb":[[0,3.65,24.66],[1,3.6,45.68],[2,3.55,12.34]],"ltp":4.1,"tv":111.88,"id":9632596},{"trd":[[1.33,234.31]],"batb":[[0,1.34,187.61],[1,1.33,91.18],[2,1.31,442.37]],"ltp":1.33,"tv":810.23,"id":9433864}],"tv":922.11}]}
{"op":"mcm","clk":"4233226375","pt":1631532202098,"mc":[{"id":"1.187557653","rc":[{"batb":[[0,3.65,8.22],[1,3.6,37.46],[2,3.55,4.12]],"ltp":4.1,"tv":111.88,"id":9632596},{"batb":[[1,1.33,113.74],[2,1.32,11.28]],"ltp":1.33,"tv":810.23,"id":9433864}]}]}
{"op":"mcm","clk":"4233226522","pt":1631532203765,"mc":[{"id":"1.187557653","rc":[{"batb":[[0,3.75,4.49],[1,3.65,8.22],[2,3.6,37.46]],"ltp":4.1,"tv":111.88,"id":9632596},{"batb":[[0,1.35,11.79],[1,1.34,187.61],[2,1.33,113.74]],"ltp":1.33,"tv":810.23,"id":9433864}]}]}
{"op":"mcm","clk":"4233226846","pt":1631532208965,"mc":[{"id":"1.187557653","rc":[{"batl":[[0,14,199.35]],"ltp":4.1,"tv":111.88,"id":9632596}]}]}
{"op":"mcm","clk":"4233226925","pt":1631532210268,"mc":[{"id":"1.187557653","rc":[{"batl":[[0,1.46,908.73],[1,1.5,52.5],[2,1.63,18.4]],"ltp":1.33,"tv":810.23,"id":9433864}]}]}
{"op":"mcm","clk":"4233227033","pt":1631532211778,"mc":[{"id":"1.187557653","rc":[{"trd":[[3.75,4.32]],"batb":[[0,3.75,2.33]],"ltp":3.75,"tv":116.2,"id":9632596}],"tv":926.43}]}
{"op":"mcm","clk":"4233227673","pt":1631532221508,"mc":[{"id":"1.187557653","rc":[{"batb":[[0,2.92,41.34],[1,2,11.86],[2,1.8,11.86]],"ltp":3.75,"tv":116.2,"id":9632596},{"batb":[[0,1.31,442.37],[1,1.28,121.67],[2,1.19,1]],"batl":[[0,1.5,52.5],[1,1.63,18.4],[2,1.89,469.65]],"ltp":1.33,"tv":810.23,"id":9433864}]}]}
{"op":"mcm","clk":"4233228639","pt":1631532235377,"mc":[{"id":"1.187557653","rc":[{"batb":[[0,1.28,121.67],[1,1.19,1],[2,1.17,314.59]],"ltp":1.33,"tv":810.23,"id":9433864}]}]}
{"op":"mcm","clk":"4233228722","pt":1631532236681,"mc":[{"id":"1.187557653","rc":[{"batb":[[0,3,45.62],[1,2.92,41.34],[2,2,11.86]],"batl":[[0,3.35,8.96],[1,3.4,4.48],[2,3.45,4.48]],"ltp":3.75,"tv":116.2,"id":9632596},{"batb":[[0,1.44,10.51],[1,1.28,121.67],[2,1.19,1]],"batl":[[0,1.46,15.52],[1,1.5,143.75],[2,1.63,18.4]],"ltp":1.33,"tv":810.23,"id":9433864}]}]}
{"op":"mcm","clk":"4233228800","pt":1631532237822,"mc":[{"id":"1.187557653","rc":[{"batb":[[0,3.1,9.68],[1,3.05,4.84],[2,3,50.46]],"ltp":3.75,"tv":116.2,"id":9632596},{"trd":[[1.44,14.82]],"batb":[[0,1.44,3.1],[1,1.42,75.48],[2,1.34,96.99]],"ltp":1.44,"tv":825.05,"id":9433864}],"tv":941.25}]}
{"op":"mcm","clk":"4233228868","pt":1631532238920,"mc":[{"id":"1.187557653","rc":[{"batb":[[2,1.34,528.31]],"ltp":1.44,"tv":825.05,"id":9433864}]}]}
{"op":"mcm","clk":"4233229450","pt":1631532247804,"mc":[{"id":"1.187557653","rc":[{"batb":[[0,1.42,75.48],[1,1.34,528.31],[2,1.19,1]],"batl":[[0,1.5,143.75],[1,1.63,18.4],[2,1.89,469.65]],"ltp":1.44,"tv":825.05,"id":9433864}]}]}
{"op":"mcm","clk":"4233229646","pt":1631532251032,"mc":[{"id":"1.187557653","rc":[{"batb":[[0,3.2,7.27],[1,3.1,9.68],[2,3.05,4.84]],"ltp":3.75,"tv":116.2,"id":9632596},{"batb":[[0,1.43,16.96],[1,1.42,75.48],[2,1.34,528.31]],"ltp":1.44,"tv":825.05,"id":9433864}]}]}
{"op":"mcm","clk":"4233230059","pt":1631532257123,"mc":[{"id":"1.187557653","rc":[{"batl":[[0,1.5,207.63]],"ltp":1.44,"tv":825.05,"id":9433864}]}]}
{"op":"mcm","clk":"4233230354","pt":1631532261246,"mc":[{"id":"1.187557653","rc":[{"batb":[[0,3.1,9.68],[1,3.05,4.84],[2,3,4.84]],"ltp":3.75,"tv":116.2,"id":9632596},{"batb":[[0,1.42,75.48],[1,1.34,528.31],[2,1.19,1]],"batl":[[0,1.5,116.38],[1,1.89,469.65],[2,8.8,7.23]],"ltp":1.44,"tv":825.05,"id":9433864}]}]}
{"op":"mcm","clk":"4233230384","pt":1631532261713,"mc":[{"id":"1.187557653","rc":[{"batb":[[0,2.52,24.27],[1,2,11.86],[2,1.8,11.86]],"ltp":3.75,"tv":116.2,"id":9632596},{"batb":[[0,1.34,528.31],[1,1.19,1],[2,1.17,314.59]],"batl":[[0,1.5,52.5]],"ltp":1.44,"tv":825.05,"id":9433864}]}]}
{"op":"mcm","clk":"4233231119","pt":1631532274851,"mc":[{"id":"1.187557653","rc":[{"batb":[[0,1.34,96.99]],"ltp":1.44,"tv":825.05,"id":9433864}]}]}
{"op":"mcm","clk":"4233231175","pt":1631532275848,"mc":[{"id":"1.187557653","rc":[{"batl":[[0,3.85,8.13],[1,3.9,70.52]],"ltp":3.75,"tv":116.2,"id":9632596},{"trd":[[1.34,15.5]],"batb":[[0,1.34,89.24]],"batl":[[0,1.37,145.98],[1,1.38,26.81],[2,1.39,21.58]],"ltp":1.34,"tv":840.55,"id":9433864}],"tv":956.75}]}
{"op":"mcm","clk":"4233231255","pt":1631532276936,"mc":[{"id":"1.187557653","rc":[{"batb":[[0,3.3,29.71],[1,2.9,42.09],[2,2,11.86]],"ltp":3.75,"tv":116.2,"id":9632596},{"batb":[[0,1.34,111.62],[1,1.33,11.2],[2,1.32,11.2]],"ltp":1.34,"tv":840.55,"id":9433864}]}]}
{"op":"mcm","clk":"4233231555","pt":1631532282066,"mc":[{"id":"1.187557653","rc":[{"batb":[[0,3.35,926.94],[1,3.3,29.71],[2,2.9,42.09]],"ltp":3.75,"tv":116.2,"id":9632596}]}]}
{"op":"mcm","clk":"4233232510","pt":1631532299256,"mc":[{"id":"1.187557653","rc":[{"batb":[[0,2.9,42.09],[1,2,11.86],[2,1.8,11.86]],"ltp":3.75,"tv":116.2,"id":9632596},{"batb":[[0,1.29,118.74],[1,1.28,450.13],[2,1.19,1]],"batl":[[0,1.5,52.5],[1,1.8,18.4],[2,1.89,469.65]],"ltp":1.34,"tv":840.55,"id":9433864}]}]}
{"op":"mcm","clk":"4233232696","pt":1631532302266,"mc":[{"id":"1.187557653","rc":[{"batb":[[1,1.28,569.21]],"ltp":1.34,"tv":840.55,"id":9433864}]}]}
{"op":"mcm","clk":"4233232757","pt":1631532303199,"mc":[{"id":"1.187557653","rc":[{"batb":[[0,2.9,41.92]],"ltp":3.75,"tv":116.2,"id":9632596},{"batb":[[0,1.28,569.21],[1,1.19,1],[2,1.17,314.59]],"ltp":1.34,"tv":840.55,"id":9433864}]}]}
{"op":"mcm","clk":"4233233816","pt":1631532319581,"mc":[{"id":"1.187557653","rc":[{"batb":[[0,1.28,119.08]],"ltp":1.34,"tv":840.55,"id":9433864}]}]}
{"op":"mcm","clk":"4233233889","pt":1631532320921,"mc":[{"id":"1.187557653","rc":[{"batb":[[0,2.96,90],[1,2.9,41.92],[2,2,11.86]],"batl":[[0,3.3,60.6],[1,3.35,8.96],[2,3.4,4.48]],"ltp":3.75,"tv":116.2,"id":9632596},{"batb":[[0,1.44,16.15],[1,1.43,177.82],[2,1.28,119.08]],"batl":[[0,1.46,10.16],[1,1.5,52.5],[2,1.8,18.4]],"ltp":1.34,"tv":840.55,"id":9433864}]}]}
{"op":"mcm","clk":"4233233951","pt":1631532321918,"mc":[{"id":"1.187557653","rc":[{"batb":[[2,2.5,25.02]],"ltp":3.75,"tv":116.2,"id":9632596},{"trd":[[1.44,29.64]],"batb":[[0,1.44,8.74],[2,1.42,74.39]],"batl":[[1,1.48,20.28],[2,1.49,10.14]],"ltp":1.44,"tv":855.37,"id":9433864}],"tv":971.57}]}
{"op":"mcm","clk":"4233234404","pt":1631532328908,"mc":[{"id":"1.187557653","rc":[{"batb":[[0,2.98,134.1],[1,2.96,90],[2,2.9,41.92]],"ltp":3.75,"tv":116.2,"id":9632596}]}]}
{"op":"mcm","clk":"4233234594","pt":1631532332010,"mc":[{"id":"1.187557653","rc":[{"batb":[[0,2.96,90],[1,2.9,41.92],[2,2.5,25.02]],"ltp":3.75,"tv":116.2,"id":9632596},{"batb":[[0,1.43,177.82],[1,1.42,74.39],[2,1.35,94.64]],"batl":[[0,1.48,20.28],[1,1.49,10.14],[2,1.5,62.64]],"ltp":1.44,"tv":855.37,"id":9433864}]}]}
{"op":"mcm","clk":"4233234765","pt":1631532334607,"mc":[{"id":"1.187557653","rc":[{"batb":[[0,3.2,4.79],[1,2.96,90],[2,2.9,41.92]],"batl":[[0,3.3,67.54]],"ltp":3.75,"tv":116.2,"id":9632596}]}]}
{"op":"mcm","clk":"4233235437","pt":1631532346148,"mc":[{"id":"1.187557653","rc":[{"batb":[[0,2.5,25.02],[1,2,11.86],[2,1.8,11.86]],"ltp":3.75,"tv":116.2,"id":9632596},{"batb":[[0,1.35,94.64],[1,1.34,431.32],[2,1.31,3.23]],"batl":[[0,1.5,52.5],[1,1.8,18.4],[2,1.89,469.65]],"ltp":1.44,"tv":855.37,"id":9433864}]}]}
{"op":"mcm","clk":"4233235621","pt":1631532348947,"mc":[{"id":"1.187557653","rc":[{"batb":[[1,1.31,3.23],[2,1.19,1]],"ltp":1.44,"tv":855.37,"id":9433864}]}]}
{"op":"mcm","clk":"4233235917","pt":1631532353322,"mc":[{"id":"1.187557653","rc":[{"batb":[[0,1.38,415.85],[1,1.35,94.64],[2,1.31,3.23]],"ltp":1.44,"tv":855.37,"id":9433864}]}]}
{"op":"mcm","clk":"4233236521","pt":1631532362129,"mc":[{"id":"1.187557653","rc":[{"batb":[[0,1.35,94.64],[1,1.31,3.23],[2,1.19,1]],"batl":[[2,8.8,7.23]],"ltp":1.44,"tv":855.37,"id":9433864}]}]}
{"op":"mcm","clk":"4233236678","pt":1631532364266,"mc":[{"id":"1.187557653","rc":[{"trd":[[3,26.25]],"batl":[[0,2.72,6.19],[1,2.74,73],[2,2.76,1109.06]],"ltp":3.0,"tv":142.45,"id":9632596},{"trd":[[1.5,67.5]],"batl":[[0,1.62,23.44],[1,1.68,155.86],[2,1.8,18.4]],"ltp":1.5,"tv":907.87,"id":9433864}],"tv":1050.32}]}
{"op":"mcm","clk":"4233236745","pt":1631532365250,"mc":[{"id":"1.187557653","rc":[{"trd":[[2.72,3.95]],"batb":[[1,2.34,30.21]],"batl":[[0,2.72,2.24],[1,2.74,43.8],[2,2.78,32.38]],"ltp":2.72,"tv":146.4,"id":9632596},{"trd":[[1.58,6.8]],"batb":[[0,1.55,53.05],[1,1.47,64.69],[2,1.35,94.64]],"batl":[[1,1.63,92.02],[2,1.64,46]],"ltp":1.58,"tv":914.67,"id":9433864}],"tv":1061.07}]}
{"op":"mcm","clk":"4233236774","pt":1631532365667,"mc":[{"id":"1.187557653","rc":[{"batl":[[2,2.78,10.8]],"ltp":2.72,"tv":146.4,"id":9632596},{"batb":[[2,1.31,3.23]],"batl":[[1,1.63,18.4],[2,1.64,9.2]],"ltp":1.58,"tv":914.67,"id":9433864}]}]}
{"op":"mcm","clk":"4233236820","pt":1631532366345,"mc":[{"id":"1.187557653","rc":[{"batb":[[2,1.44,405.13]],"ltp":1.58,"tv":914.67,"id":9433864}]}]}
{"op":"mcm","clk":"4233236953","pt":1631532367956,"mc":[{"id":"1.187557653","rc":[{"batb":[[1,1.5,26.75],[2,1.47,64.69]],"ltp":1.58,"tv":914.67,"id":9433864}]}]}
{"op":"mcm","clk":"4233237049","pt":1631532369253,"mc":[{"id":"1.187557653","rc":[{"batl":[[2,2.76,27.23]],"ltp":2.72,"tv":146.4,"id":9632596},{"batl":[[0,1.61,63.46],[1,1.62,23.44],[2,1.63,18.4]],"ltp":1.58,"tv":914.67,"id":9433864}]}]}
{"op":"mcm","clk":"4233237057","pt":1631532369357,"mc":[{"id":"1.187557653","rc":[{"batl":[[2,2.78,10.8]],"ltp":2.72,"tv":146.4,"id":9632596},{"batb":[[1,1.47,64.69],[2,1.44,405.13]],"batl":[[0,1.62,23.44],[1,1.63,18.4],[2,1.64,9.2]],"ltp":1.58,"tv":914.67,"id":9433864}]}]}
{"op":"mcm","clk":"4233237514","pt":1631532375892,"mc":[{"id":"1.187557653","rc":[{"batl":[[0,2.74,43.8],[1,2.78,10.8],[2,2.8,5.4]],"ltp":2.72,"tv":146.4,"id":9632596},{"batl":[[0,1.63,18.4],[1,1.64,9.2],[2,1.65,9.2]],"ltp":1.58,"tv":914.67,"id":9433864}]}]}
{"op":"mcm","clk":"4233237675","pt":1631532378484,"mc":[{"id":"1.187557653","rc":[{"batl":[[1,2.78,23.64]],"ltp":2.72,"tv":146.4,"id":9632596},{"batl":[[0,1.6,13.04],[1,1.63,18.4],[2,1.64,9.2]],"ltp":1.58,"tv":914.67,"id":9433864}]}]}
{"op":"mcm","clk":"4233238123","pt":1631532384975,"mc":[{"id":"1.187557653","rc":[{"batb":[[0,2.52,60.4],[1,2.5,25.02],[2,2.34,30.21]],"ltp":2.72,"tv":146.4,"id":9632596}]}]}
{"op":"mcm","clk":"4233238643","pt":1631532393578,"mc":[{"id":"1.187557653","rc":[{"trd":[[2.74,5.73]],"batl":[[0,2.74,38.07]],"ltp":2.74,"tv":152.13,"id":9632596},{"trd":[[1.57,10]],"ltp":1.57,"tv":924.67,"id":9433864}],"tv":1076.8}]}
{"op":"mcm","clk":"4233241838","pt":1631532442044,"mc":[{"id":"1.187557653","rc":[{"batb":[[0,2.5,25.02],[1,2.34,30.21],[2,1.8,11.86]],"ltp":2.74,"tv":152.13,"id":9632596}]}]}
{"op":"mcm","clk":"4233242843","pt":1631532456885,"mc":[{"id":"1.187557653","rc":[{"batb":[[0,2.34,30.21],[1,1.8,11.86],[2,1.75,3.41]],"ltp":2.74,"tv":152.13,"id":9632596},{"batb":[[0,1.47,64.69],[1,1.44,405.13],[2,1.25,237.69]],"batl":[[0,1.8,18.4],[1,2.16,372.43],[2,8.8,7.23]],"ltp":1.57,"tv":924.67,"id":9433864}]}]}
{"op":"mcm","clk":"4233243732","pt":1631532469281,"mc":[{"id":"1.187557653","rc":[{"batb":[[1,2.32,116.59],[2,1.8,11.86]],"batl":[[0,2.58,77.52],[1,2.78,360.68],[2,3.35,2.99]],"ltp":2.74,"tv":152.13,"id":9632596},{"batb":[[0,1.63,92.02],[1,1.62,46],[2,1.61,46]],"ltp":1.57,"tv":924.67,"id":9433864}]}]}
{"op":"mcm","clk":"4233243825","pt":1631532470268,"mc":[{"id":"1.187557653","rc":[{"trd":[[2.56,4.24]],"batb":[[0,2.42,61.98],[1,2.4,30.98],[2,2.38,30.98]],"batl":[[0,2.56,5.38],[1,2.58,77.52],[2,2.78,360.68]],"ltp":2.56,"tv":156.37,"id":9632596},{"trd":[[1.64,6.62]],"batb":[[0,1.63,18.4],[1,1.62,9.2],[2,1.61,9.2]],"batl":[[0,1.68,15.39],[1,1.8,18.4],[2,2.16,372.43]],"ltp":1.64,"tv":931.29,"id":9433864}],"tv":1087.66}]}
{"op":"mcm","clk":"4233243866","pt":1631532470684,"mc":[{"id":"1.187557653","rc":[{"batb":[[0,2.42,12.4],[1,2.4,6.2],[2,2.38,6.2]],"ltp":2.56,"tv":156.37,"id":9632596},{"batb":[[1,1.62,54.14]],"ltp":1.64,"tv":931.29,"id":9433864}]}]}
{"op":"mcm","clk":"4233244099","pt":1631532474282,"mc":[{"id":"1.187557653","rc":[{"batl":[[1,2.58,107.18]],"ltp":2.56,"tv":156.37,"id":9632596},{"batl":[[0,1.68,76.53]],"ltp":1.64,"tv":931.29,"id":9433864}]}]}
{"op":"mcm","clk":"4233244111","pt":1631532474492,"mc":[{"id":"1.187557653","rc":[{"batl":[[1,2.58,77.52]],"ltp":2.56,"tv":156.37,"id":9632596},{"batl":[[0,1.68,15.39]],"ltp":1.64,"tv":931.29,"id":9433864}]}]}
{"op":"mcm","clk":"4233244424","pt":1631532479017,"mc":[{"id":"1.187557653","rc":[{"batb":[[0,2.34,30.21],[1,2.2,36.15],[2,1.8,11.86]],"ltp":2.56,"tv":156.37,"id":9632596},{"batb":[[0,1.62,44.94],[1,1.54,54.31],[2,1.5,397.3]],"batl":[[0,1.8,18.4],[1,2.16,372.43],[2,8.8,7.23]],"ltp":1.64,"tv":931.29,"id":9433864}]}]}
{"op":"mcm","clk":"4233244455","pt":1631532479431,"mc":[{"id":"1.187557653","rc":[{"batb":[[0,2.2,36.15],[1,1.8,11.86],[2,1.75,3.41]],"ltp":2.56,"tv":156.37,"id":9632596},{"batb":[[0,1.54,54.31],[1,1.5,397.3],[2,1.25,237.69]],"ltp":1.64,"tv":931.29,"id":9433864}]}]}
{"op":"mcm","clk":"4233245018","pt":1631532487222,"mc":[{"id":"1.187557653","rc":[{"batb":[[1,1.75,3.41],[2,1.7,16.97]],"batl":[[0,2.42,92.76],[1,2.6,385.59],[2,3.15,3.17]],"ltp":2.56,"tv":156.37,"id":9632596},{"batb":[[0,1.7,17.64],[1,1.69,8.82],[2,1.68,8.82]],"batl":[[0,1.74,10.3],[1,1.8,18.4],[2,1.83,109.06]],"ltp":1.64,"tv":931.29,"id":9433864}]}]}
{"op":"mcm","clk":"4233245085","pt":1631532488209,"mc":[{"id":"1.187557653","rc":[{"batb":[[1,2.08,42.51],[2,1.75,3.41]],"ltp":2.56,"tv":156.37,"id":9632596},{"trd":[[1.7,12.82]],"batb":[[0,1.7,11.23],[1,1.69,47.06]],"batl":[[1,1.78,84.28],[2,1.79,25.28]],"ltp":1.7,"tv":944.11,"id":9433864}],"tv":1100.48}]}
{"op":"mcm","clk":"4233245133","pt":1631532488939,"mc":[{"id":"1.187557653","rc":[{"batl":[[1,1.78,16.86],[2,1.79,8.42]],"ltp":1.7,"tv":944.11,"id":9433864}]}]}
{"op":"mcm","clk":"4233245572","pt":1631532495122,"mc":[{"id":"1.187557653","rc":[{"batb":[[0,2.22,806.78],[1,2.2,36.15],[2,2.08,42.51]],"ltp":2.56,"tv":156.37,"id":9632596}]}]}
{"op":"mcm","clk":"4233245654","pt":1631532496268,"mc":[{"id":"1.187557653","rc":[{"batb":[[0,2.2,36.15],[1,2.08,42.51],[2,1.75,3.41]],"ltp":2.56,"tv":156.37,"id":9632596},{"batb":[[0,1.69,38.24],[1,1.62,44.69],[2,1.5,397.3]],"batl":[[0,2.16,372.43],[1,810,0.07],[2,1.79,0]],"ltp":1.7,"tv":944.11,"id":9433864}]}]}
{"op":"mcm","clk":"4233245703","pt":1631532496739,"mc":[{"id":"1.187557653","rc":[{"batb":[[0,2.08,42.51],[1,1.75,3.41],[2,1.7,16.97]],"ltp":2.56,"tv":156.37,"id":9632596},{"batb":[[0,1.62,44.69],[1,1.5,397.3],[2,1.3,198.07]],"ltp":1.7,"tv":944.11,"id":9433864}]}]}
{"op":"mcm","clk":"4233245967","pt":1631532500293,"mc":[{"id":"1.187557653","rc":[{"batb":[[1,1.3,198.07],[2,1.25,237.69]],"batl":[[0,810,0.07],[1,810,0]],"ltp":1.7,"tv":944.11,"id":9433864}]}]}
{"op":"mcm","clk":"4233246120","pt":1631532502051,"mc":[{"id":"1.187557653","rc":[{"batb":[[0,2.24,8.4],[1,2.08,42.51],[2,1.75,3.41]],"batl":[[0,3,3.33]],"ltp":2.56,"tv":156.37,"id":9632596},{"batb":[[0,1.8,97.3],[1,1.77,113],[2,1.76,18.1]],"batl":[[0,1.92,155.88],[1,810,0.07]],"ltp":1.7,"tv":944.11,"id":9433864}]}]}
{"op":"mcm","clk":"4233246233","pt":1631532503254,"mc":[{"id":"1.187557653","rc":[{"batb":[[2,2,47.03]],"batl":[[1,3.4,518.76]],"ltp":2.56,"tv":156.37,"id":9632596},{"trd":[[1.8,12.5]],"batb":[[0,1.8,91.05],[1,1.77,100.6]],"batl":[[0,1.84,81.52],[1,1.85,40.76],[2,1.86,40.76]],"ltp":1.8,"tv":956.61,"id":9433864}],"tv":1112.98}]}
{"op":"mcm","clk":"4233246289","pt":1631532503951,"mc":[{"id":"1.187557653","rc":[{"batl":[[0,1.84,16.3],[1,1.85,8.16],[2,1.86,8.16]],"ltp":1.8,"tv":956.61,"id":9433864}]}]}
{"op":"mcm","clk":"4233246544","pt":1631532507273,"mc":[{"id":"1.187557653","rc":[{"batl":[[1,3.4,0]],"ltp":2.56,"tv":156.37,"id":9632596}]}]}
{"op":"mcm","clk":"4233246695","pt":1631532509285,"mc":[{"id":"1.187557653","rc":[{"batb":[[0,2,47.03],[1,1.75,3.41],[2,1.6,99.04]],"ltp":2.56,"tv":156.37,"id":9632596},{"batb":[[0,1.71,37.07],[1,1.55,392.04],[2,1.3,198.07]],"batl":[[0,1.9,36.8],[1,2.42,312.73],[2,810,0.07]],"ltp":1.8,"tv":956.61,"id":9433864}]}]}
{"op":"mcm","clk":"4233247290","pt":1631532517066,"mc":[{"id":"1.187557653","rc":[{"batl":[[0,1.8,5.7],[1,1.9,36.8],[2,2.42,312.73]],"ltp":1.8,"tv":956.61,"id":9433864}]}]}
{"op":"mcm","clk":"4233247720","pt":1631532522795,"mc":[{"id":"1.187557653","rc":[{"trd":[[2.3,52.16],[2.34,7.28]],"batb":[[0,2.3,65.23],[1,2.28,19.56],[2,2.26,19.56]],"batl":[[0,2.36,70.57],[1,2.42,10.49]],"ltp":2.3,"tv":215.81,"id":9632596},{"trd":[[1.71,12.74],[1.74,9.79]],"batb":[[0,1.71,30.7]],"batl":[[1,1.83,117.21],[2,1.9,36.8]],"ltp":1.74,"tv":979.14,"id":9433864}],"tv":1194.95}]}
{"op":"mcm","clk":"4233247807","pt":1631532523677,"mc":[{"id":"1.187557653","rc":[{"batb":[[0,2.3,50],[1,2.28,6.52],[2,2.26,6.52]],"batl":[[2,3.15,3.17]],"ltp":2.3,"tv":215.81,"id":9632596},{"batb":[[1,1.69,17.76],[2,1.68,8.88]],"ltp":1.74,"tv":979.14,"id":9433864}]}]}
{"op":"mcm","clk":"4233248198","pt":1631532528081,"mc":[{"id":"1.187557653","rc":[{"batl":[[0,1.83,117.21],[1,1.9,36.8],[2,2.42,312.73]],"ltp":1.74,"tv":979.14,"id":9433864}]}]}
{"op":"mcm","clk":"4233248236","pt":1631532528702,"mc":[{"id":"1.187557653","rc":[{"batl":[[2,1.98,36.8]],"ltp":1.74,"tv":979.14,"id":9433864}]}]}
{"op":"mcm","clk":"4233248423","pt":1631532531180,"mc":[{"id":"1.187557653","rc":[{"batl":[[0,1.83,231.63]],"ltp":1.74,"tv":979.14,"id":9433864}]}]}
{"op":"mcm","clk":"4233248539","pt":1631532532990,"mc":[{"id":"1.187557653","rc":[{"batl":[[1,3.15,3.17],[2,3.15,0]],"ltp":2.3,"tv":215.81,"id":9632596}]}]}
{"op":"mcm","clk":"4233248675","pt":1631532535204,"mc":[{"id":"1.187557653","rc":[{"batl":[[1,3.15,0]],"ltp":2.3,"tv":215.81,"id":9632596}]}]}
{"op":"mcm","clk":"4233248730","pt":1631532535987,"mc":[{"id":"1.187557653","rc":[{"batb":[[0,2.06,42.59],[1,1.75,3.41],[2,1.6,99.04]],"ltp":2.3,"tv":215.81,"id":9632596},{"batb":[[0,1.63,43.85],[1,1.55,392.04],[2,1.3,198.07]],"batl":[[0,1.9,36.8],[1,1.98,36.8],[2,2.42,312.73]],"ltp":1.74,"tv":979.14,"id":9433864}]}]}
{"op":"mcm","clk":"4233249627","pt":1631532547912,"mc":[{"id":"1.187557653","rc":[{"batl":[[0,2.28,23.49],[1,2.3,6.58],[2,2.32,6.58]],"ltp":2.3,"tv":215.81,"id":9632596},{"batb":[[0,1.72,402.74],[1,1.71,116.96],[2,1.63,43.85]],"batl":[[0,1.83,15.3],[1,1.89,82.07],[2,1.9,36.8]],"ltp":1.74,"tv":979.14,"id":9433864}]}]}
{"op":"mcm","clk":"4233249731","pt":1631532549199,"mc":[{"id":"1.187557653","rc":[{"trd":[[2.28,4.85]],"batb":[[1,1.94,52.13],[2,1.75,3.41]],"batl":[[0,2.28,18.64]],"ltp":2.28,"tv":220.66,"id":9632596},{"trd":[[1.78,6.21]],"batb":[[0,1.77,32.8],[1,1.72,402.74],[2,1.71,116.96]],"batl":[[1,1.87,16.04],[2,1.88,8.02]],"ltp":1.78,"tv":985.35,"id":9433864}],"tv":1206.01}]}
{"op":"mcm","clk":"4233250370","pt":1631532557738,"mc":[{"id":"1.187557653","rc":[{"trd":[[2.28,10.24]],"batl":[[0,2.28,13.25]],"ltp":2.28,"tv":226.05,"id":9632596},{"trd":[[1.78,13.11]],"ltp":1.78,"tv":992.25,"id":9433864}],"tv":1218.3}]}
{"op":"mcm","clk":"4233250495","pt":1631532559238,"mc":[{"id":"1.187557653","rc":[{"batb":[[0,2.1,1194.42],[1,2.06,42.59],[2,1.94,52.13]],"ltp":2.28,"tv":226.05,"id":9632596}]}]}
{"op":"mcm","clk":"4233250516","pt":1631532559441,"mc":[{"id":"1.187557653","rc":[{"batb":[[0,2.06,42.59],[1,1.94,52.13],[2,1.75,3.41]],"ltp":2.28,"tv":226.05,"id":9632596}]}]}
{"op":"mcm","clk":"4233250815","pt":1631532562563,"mc":[{"id":"1.187557653","rc":[{"batb":[[0,2.1,760.46],[1,2.06,42.59],[2,1.94,52.13]],"ltp":2.28,"tv":226.05,"id":9632596}]}]}
{"op":"mcm","clk":"4233251630","pt":1631532573970,"mc":[{"id":"1.187557653","rc":[{"batl":[[0,2.28,2.92]],"ltp":2.28,"tv":226.05,"id":9632596},{"batb":[[1,1.71,116.96],[2,1.7,37.49]],"batl":[[0,1.87,16.04],[1,1.88,8.02],[2,1.89,8.02]],"ltp":1.78,"tv":992.25,"id":9433864}]}]}
{"op":"mcm","clk":"4233251663","pt":1631532574447,"mc":[{"id":"1.187557653","rc":[{"batb":[[0,2.06,42.59],[1,1.94,52.13],[2,1.75,3.41]],"ltp":2.28,"tv":226.05,"id":9632596}]}]}
{"op":"mcm","clk":"4233252049","pt":1631532580460,"mc":[{"id":"1.187557653","rc":[{"batb":[[0,2.06,116.42]],"ltp":2.28,"tv":226.05,"id":9632596}]}]}
{"op":"mcm","clk":"4233252667","pt":1631532590251,"mc":[{"id":"1.187557653","rc":[{"batb":[[0,1.94,52.13],[1,1.75,3.41],[2,1.6,99.04]],"ltp":2.28,"tv":226.05,"id":9632596},{"batb":[[0,1.7,37.49],[1,1.3,198.07],[2,1.25,237.69]],"batl":[[0,1.9,36.8],[1,1.98,36.8],[2,810,0.07]],"ltp":1.78,"tv":992.25,"id":9433864}]}]}
{"op":"mcm","clk":"4233253108","pt":1631532597053,"mc":[{"id":"1.187557653","rc":[{"batb":[[1,1.58,388.69],[2,1.3,198.07]],"batl":[[2,2.5,299.95]],"ltp":1.78,"tv":992.25,"id":9433864}]}]}
{"op":"mcm","clk":"4233253988","pt":1631532607993,"mc":[{"id":"1.187557653","rc":[{"batb":[[1,1.3,198.07],[2,1.25,237.69]],"ltp":1.78,"tv":992.25,"id":9433864}]}]}
{"op":"mcm","clk":"4233254081","pt":1631532609216,"mc":[{"id":"1.187557653","rc":[{"batb":[[0,2.08,8.05],[1,1.94,52.13],[2,1.75,3.41]],"batl":[[0,2.12,102.34],[1,2.16,1394.34],[2,2.78,3.6]],"ltp":2.28,"tv":226.05,"id":9632596},{"trd":[[1.9,73.6]],"batb":[[0,1.9,42.16],[1,1.89,39.48],[2,1.88,39.48]],"batl":[[0,1.98,36.8],[1,2.02,103.06]],"ltp":1.9,"tv":1065.84,"id":9433864}],"tv":1291.9}]}
{"op":"mcm","clk":"4233254159","pt":1631532610211,"mc":[{"id":"1.187557653","rc":[{"batb":[[1,2,75],[2,1.99,37.5]],"batl":[[1,2.78,3.6],[2,3.85,71.26]],"ltp":2.28,"tv":226.05,"id":9632596},{"trd":[[1.9,85.58]],"batb":[[0,1.9,33.49],[1,1.89,23.69],[2,1.88,23.69]],"ltp":1.9,"tv":1077.82,"id":9433864}],"tv":1303.88}]}
{"op":"mcm","clk":"4233254212","pt":1631532610784,"mc":[{"id":"1.187557653","rc":[{"batb":[[1,2,15],[2,1.99,7.5]],"batl":[[2,3.85,0]],"ltp":2.28,"tv":226.05,"id":9632596},{"batb":[[0,1.9,1.91],[1,1.89,7.9],[2,1.88,34.85]],"batl":[[0,2.02,103.06],[1,2.5,299.95],[2,2.5,0]],"ltp":1.9,"tv":1077.82,"id":9433864}]}]}
{"op":"mcm","clk":"4233254483","pt":1631532614200,"mc":[{"id":"1.187557653","rc":[{"batl":[[1,2.18,34.08],[2,2.78,3.6]],"ltp":2.28,"tv":226.05,"id":9632596},{"batl":[[0,1.91,54.28],[1,2.02,103.06],[2,2.5,299.95]],"ltp":1.9,"tv":1077.82,"id":9433864}]}]}
{"op":"mcm","clk":"4233254499","pt":1631532614409,"mc":[{"id":"1.187557653","rc":[{"batl":[[1,2.78,3.6],[2,2.78,0]],"ltp":2.28,"tv":226.05,"id":9632596},{"batl":[[0,2.02,103.06],[1,2.5,299.95],[2,2.5,0]],"ltp":1.9,"tv":1077.82,"id":9433864}]}]}
{"op":"mcm","clk":"4233256097","pt":1631532634117,"mc":[{"id":"1.187557653","rc":[{"batb":[[0,1.82,31.88],[1,1.75,3.41],[2,1.5,106.96]],"ltp":2.28,"tv":226.05,"id":9632596},{"batb":[[0,1.79,31.63],[1,1.62,388.38],[2,1.4,148.56]],"batl":[[0,2.5,299.95],[1,2.5,0]],"ltp":1.9,"tv":1077.82,"id":9433864}]}]}
{"op":"mcm","clk":"4233256801","pt":1631532643642,"mc":[{"id":"1.187557653","rc":[{"batb":[[1,1.4,148.56],[2,1.3,198.07]],"ltp":1.9,"tv":1077.82,"id":9433864}]}]}
{"op":"mcm","clk":"4233256922","pt":1631532645148,"mc":[{"id":"1.187557653","rc":[{"batb":[[2,1.4,148.56]],"batl":[[0,1.95,20.52],[1,1.98,121.97],[2,1.99,75.38]],"ltp":2.28,"tv":226.05,"id":9632596},{"batl":[[0,2.06,6.58],[1,2.2,145.64],[2,2.5,299.95]],"ltp":1.9,"tv":1077.82,"id":9433864}]}]}
{"op":"mcm","clk":"4233257010","pt":1631532646140,"mc":[{"id":"1.187557653","rc":[{"trd":[[1.95,5.91]],"batb":[[0,1.89,15.88],[1,1.88,7.94],[2,1.87,7.94]],"batl":[[0,1.95,14.61],[2,1.99,15.08]],"ltp":1.95,"tv":231.96,"id":9632596},{"trd":[[2.04,5.65]],"batb":[[0,2,43.93],[1,1.9,51.88],[2,1.4,148.56]],"ltp":2.04,"tv":1083.47,"id":9433864}],"tv":1315.44}]}
{"op":"mcm","clk":"4233257100","pt":1631532647547,"mc":[{"id":"1.187557653","rc":[{"batb":[[2,1.67,383.76]],"ltp":2.04,"tv":1083.47,"id":9433864}]}]}
{"op":"mcm","clk":"4233257311","pt":1631532649832,"mc":[{"id":"1.187557653","rc":[{"trd":[[1.95,20.52]],"batl":[[0,1.98,121.97],[1,1.99,15.08],[2,2,7.54]],"ltp":1.95,"tv":246.57,"id":9632596},{"trd":[[2.04,19.62]],"ltp":2.04,"tv":1097.44,"id":9433864}],"tv":1344.02}]}
{"op":"mcm","clk":"4233258618","pt":1631532666171,"mc":[{"id":"1.187557653","rc":[{"batb":[[0,1.75,3.41],[1,1.71,38.91],[2,1.4,148.56]],"ltp":1.95,"tv":246.57,"id":9632596},{"batb":[[0,1.9,51.88],[1,1.67,383.76],[2,1.4,148.56]],"batl":[[0,2.5,299.95],[1,2.2,0],[2,2.5,0]],"ltp":2.04,"tv":1097.44,"id":9433864}]}]}
{"op":"mcm","clk":"4233259180","pt":1631532673170,"mc":[{"id":"1.187557653","rc":[{"batl":[[0,2.82,253.59]],"ltp":2.04,"tv":1097.44,"id":9433864}]}]}
{"op":"mcm","clk":"4233260575","pt":1631532690283,"mc":[{"id":"1.187557653","rc":[{"batb":[[0,1.95,102.56],[1,1.75,3.41],[2,1.71,38.91]],"ltp":1.95,"tv":246.57,"id":9632596},{"trd":[[1.9,97.28]],"batb":[[0,1.9,46.03]],"batl":[[0,1.97,1530.36],[1,1.99,75.38],[2,2,37.68]],"ltp":1.9,"tv":1109.14,"id":9433864}],"tv":1355.72}]}
{"op":"mcm","clk":"4233260603","pt":1631532690593,"mc":[{"id":"1.187557653","rc":[{"batb":[[0,2.04,6.94],[1,1.95,61.54],[2,1.75,3.41]],"batl":[[0,2.08,121.46]],"ltp":1.95,"tv":246.57,"id":9632596},{"batl":[[0,1.99,45.23],[1,2,22.61],[2,2.02,22.61]],"ltp":1.9,"tv":1109.14,"id":9433864}]}]}
{"op":"mcm","clk":"4233260721","pt":1631532691782,"mc":[{"id":"1.187557653","rc":[{"batb":[[2,1.92,27.11]],"batl":[[1,2.7,3.7]],"ltp":1.95,"tv":246.57,"id":9632596},{"batb":[[1,1.8,31.13],[2,1.67,383.76]],"ltp":1.9,"tv":1109.14,"id":9433864}]}]}
{"op":"mcm","clk":"4233261529","pt":1631532702710,"mc":[{"id":"1.187557653","rc":[{"batb":[[1,1.86,36.8],[2,1.8,31.13]],"ltp":1.9,"tv":1109.14,"id":9433864}]}]}
{"op":"mcm","clk":"4233262349","pt":1631532713270,"mc":[{"id":"1.187557653","rc":[{"batb":[[0,1.78,34.48],[1,1.75,3.41],[2,1.5,106.96]],"ltp":1.95,"tv":246.57,"id":9632596},{"batb":[[0,1.86,36.8],[1,1.8,31.13],[2,1.67,383.76]],"batl":[[0,2.6,281.81],[1,2,0],[2,2.02,0]],"ltp":1.9,"tv":1109.14,"id":9433864}]}]}
{"op":"mcm","clk":"4233262358","pt":1631532713323,"mc":[{"id":"1.187557653","rc":[{"batb":[[0,1.78,34.31]],"ltp":1.95,"tv":246.57,"id":9632596}]}]}
{"op":"mcm","clk":"4233263101","pt":1631532722139,"mc":[{"id":"1.187557653","rc":[{"batb":[[2,1.4,148.56]],"ltp":1.9,"tv":1109.14,"id":9433864}]}]}
{"op":"mcm","clk":"4233263349","pt":1631532725285,"mc":[{"id":"1.187557653","rc":[{"batl":[[0,3.6,332.39]],"ltp":1.9,"tv":1109.14,"id":9433864}]}]}
{"op":"mcm","clk":"4233263876","pt":1631532731956,"mc":[{"id":"1.187557653","rc":[{"batl":[[0,3.2,151.46]],"ltp":1.9,"tv":1109.14,"id":9433864}]}]}
{"op":"mcm","clk":"4233266161","pt":1631532759155,"mc":[{"id":"1.187557653","rc":[{"batb":[[0,1.8,109.2],[1,1.78,34.31],[2,1.75,3.41]],"batl":[[0,1.92,121.58],[1,2.44,4.1]],"ltp":1.95,"tv":246.57,"id":9632596},{"batl":[[0,2.16,16.75]],"ltp":1.9,"tv":1109.14,"id":9433864}]}]}
{"op":"mcm","clk":"4233266258","pt":1631532760234,"mc":[{"id":"1.187557653","rc":[{"trd":[[1.92,5.95]],"batb":[[0,1.84,81.52],[1,1.83,40.76],[2,1.82,40.76]],"batl":[[0,1.92,115.63]],"ltp":1.92,"tv":252.52,"id":9632596},{"trd":[[2.08,5.49]],"batb":[[0,2.06,40.59],[1,1.94,48.62],[2,1.86,36.8]],"ltp":2.08,"tv":1114.63,"id":9433864}],"tv":1367.16}]}
{"op":"mcm","clk":"4233266317","pt":1631532760838,"mc":[{"id":"1.187557653","rc":[{"batb":[[0,1.84,16.3],[1,1.83,8.16],[2,1.82,8.16]],"ltp":1.92,"tv":252.52,"id":9632596}]}]}
{"op":"mcm","clk":"4233266406","pt":1631532761621,"mc":[{"id":"1.187557653","rc":[{"batl":[[1,2.82,253.59]],"ltp":2.08,"tv":1114.63,"id":9433864}]}]}
{"op":"mcm","clk":"4233266618","pt":1631532764161,"mc":[{"id":"1.187557653","rc":[{"batl":[[0,2.44,4.1],[1,2.44,0]],"ltp":1.92,"tv":252.52,"id":9632596},{"batb":[[0,1.94,48.62],[1,1.86,36.8],[2,1.7,383.83]],"batl":[[0,2.82,253.59],[1,2.82,0]],"ltp":2.08,"tv":1114.63,"id":9433864}]}]}
{"op":"mcm","clk":"4233267202","pt":1631532770048,"mc":[{"id":"1.187557653","rc":[{"batl":[[0,2.34,135.13],[1,2.44,4.1]],"ltp":1.92,"tv":252.52,"id":9632596}]}]}
{"op":"mcm","clk":"4233267948","pt":1631532778367,"mc":[{"id":"1.187557653","rc":[{"batb":[[0,1.75,3.41],[1,1.67,42.43],[2,1.4,148.56]],"ltp":1.92,"tv":252.52,"id":9632596}]}]}
{"op":"mcm","clk":"4233268953","pt":1631532790187,"mc":[{"id":"1.187557653","rc":[{"batb":[[0,2,75],[1,1.99,37.5],[2,1.98,37.5]],"batl":[[0,2.02,115.71]],"ltp":1.92,"tv":252.52,"id":9632596},{"trd":[[1.94,11.42]],"batb":[[0,1.94,42.91]],"batl":[[0,2.02,8.1],[1,2.06,97.08],[2,2.12,98.14]],"ltp":1.94,"tv":1126.05,"id":9433864}],"tv":1378.58}]}
{"op":"mcm","clk":"4233269055","pt":1631532791283,"mc":[{"id":"1.187557653","rc":[{"batb":[[0,2,45],[1,1.99,22.5],[2,1.98,22.5]],"batl":[[1,2.12,14.16],[2,2.14,7.08]],"ltp":1.92,"tv":252.52,"id":9632596},{"batb":[[2,1.8,31.13]],"batl":[[1,2.06,58.25]],"ltp":1.94,"tv":1126.05,"id":9433864}]}]}
{"op":"mcm","clk":"4233270212","pt":1631532804094,"mc":[{"id":"1.187557653","rc":[{"batb":[[0,1.88,28.87],[1,1.75,3.41],[2,1.7,39.83]],"ltp":1.92,"tv":252.52,"id":9632596},{"batl":[[0,2.82,253.59],[1,2.06,0],[2,2.12,0]],"ltp":1.94,"tv":1126.05,"id":9433864}]}]}
{"op":"mcm","clk":"4233270237","pt":1631532804502,"mc":[{"id":"1.187557653","rc":[{"batb":[[0,1.75,3.41],[1,1.7,39.66],[2,1.5,106.96]],"ltp":1.92,"tv":252.52,"id":9632596},{"batb":[[0,1.86,36.8],[1,1.8,31.13],[2,1.7,383.83]],"ltp":1.94,"tv":1126.05,"id":9433864}]}]}
{"op":"mcm","clk":"4233270362","pt":1631532805903,"mc":[{"id":"1.187557653","rc":[{"batb":[[0,2,36.8],[1,1.86,36.8],[2,1.8,31.13]],"ltp":1.94,"tv":1126.05,"id":9433864}]}]}
{"op":"mcm","clk":"4233270719","pt":1631532809891,"mc":[{"id":"1.187557653","rc":[{"batb":[[0,1.86,36.8],[1,1.8,31.13],[2,1.4,148.56]],"ltp":1.94,"tv":1126.05,"id":9433864}]}]}
{"op":"mcm","clk":"4233270941","pt":1631532811910,"mc":[{"id":"1.187557653","rc":[{"batb":[[2,1.4,148.56]],"batl":[[0,1.83,144.76],[1,1.84,81.52],[2,1.85,40.76]],"ltp":1.92,"tv":252.52,"id":9632596},{"batl":[[0,2.28,9.89],[1,2.42,103.06],[2,2.82,253.59]],"ltp":1.94,"tv":1126.05,"id":9433864}]}]}
{"op":"mcm","clk":"4233271063","pt":1631532813214,"mc":[{"id":"1.187557653","rc":[{"trd":[[1.83,6.19]],"batb":[[0,1.75,20.55],[1,1.74,8.58],[2,1.73,8.58]],"batl":[[0,1.83,138.57],[1,1.84,16.3],[2,1.85,8.16]],"ltp":1.83,"tv":258.71,"id":9632596},{"trd":[[2.2,5.15]],"batb":[[0,2.18,34.73],[1,2.04,41.67],[2,1.86,36.8]],"ltp":2.2,"tv":1131.2,"id":9433864}],"tv":1389.92}]}
{"op":"mcm","clk":"4233271906","pt":1631532822717,"mc":[{"id":"1.187557653","rc":[{"batl":[[0,1.83,129.16]],"ltp":1.83,"tv":258.71,"id":9632596},{"batl":[[0,2.42,103.06],[1,2.82,253.59],[2,2.82,0]],"ltp":2.2,"tv":1131.2,"id":9433864}]}]}
{"op":"mcm","clk":"4233271985","pt":1631532823642,"mc":[{"id":"1.187557653","rc":[{"trd":[[1.83,26.71]],"batl":[[0,1.83,118.9]],"ltp":1.83,"tv":279.23,"id":9632596}],"tv":1410.44}]}
{"op":"mcm","clk":"4233272160","pt":1631532825735,"mc":[{"id":"1.187557653","rc":[{"batb":[[0,1.8,7.67],[1,1.75,20.55],[2,1.74,8.58]],"batl":[[0,1.83,128.31]],"ltp":1.83,"tv":279.23,"id":9632596}]}]}
{"op":"mcm","clk":"4233273106","pt":1631532836864,"mc":[{"id":"1.187557653","rc":[{"batl":[[0,1.81,36.8],[1,1.83,128.31],[2,1.84,16.3]],"ltp":1.83,"tv":279.23,"id":9632596}]}]}
{"op":"mcm","clk":"4233274052","pt":1631532848072,"mc":[{"id":"1.187557653","rc":[{"trd":[[1.8,15.34]],"batb":[[0,1.75,20.55],[1,1.74,8.58],[2,1.73,8.58]],"batl":[[0,1.8,4.33],[1,1.81,36.8],[2,1.83,128.31]],"ltp":1.8,"tv":294.57,"id":9632596}],"tv":1425.78}]}
{"op":"mcm","clk":"4233274540","pt":1631532853881,"mc":[{"id":"1.187557653","rc":[{"batl":[[2,1.82,33.85]],"ltp":1.8,"tv":294.57,"id":9632596}]}]}
{"op":"mcm","clk":"4233274976","pt":1631532858781,"mc":[{"id":"1.187557653","rc":[{"batb":[[2,1.77,378.13]],"ltp":2.2,"tv":1131.2,"id":9433864}]}]}
{"op":"mcm","clk":"4233275163","pt":1631532861178,"mc":[{"id":"1.187557653","rc":[{"batl":[[0,2.28,8.8],[1,2.42,103.06],[2,2.82,253.59]],"ltp":2.2,"tv":1131.2,"id":9433864}]}]}
{"op":"mcm","clk":"4233277762","pt":1631532891248,"mc":[{"id":"1.187557653","rc":[{"batb":[[0,1.75,11.98],[1,1.74,4.29],[2,1.73,4.29]],"ltp":1.8,"tv":294.57,"id":9632596},{"batl":[[0,2.82,253.59],[1,2.42,0],[2,2.82,0]],"ltp":2.2,"tv":1131.2,"id":9433864}]}]}
{"op":"mcm","clk":"4233277794","pt":1631532891510,"mc":[{"id":"1.187557653","rc":[{"batb":[[0,1.75,3.41],[1,1.63,45.77],[2,1.4,148.56]],"ltp":1.8,"tv":294.57,"id":9632596},{"batb":[[0,2.04,41.67],[1,1.77,378.13],[2,1.4,148.56]],"ltp":2.2,"tv":1131.2,"id":9433864}]}]}
{"op":"mcm","clk":"4233278102","pt":1631532894745,"mc":[{"id":"1.187557653","rc":[{"batl":[[1,1.81,0],[2,1.82,0]],"ltp":1.8,"tv":294.57,"id":9632596}]}]}
{"op":"mcm","clk":"4233279461","pt":1631532908882,"mc":[{"id":"1.187557653","rc":[{"trd":[[1.8,24]],"batb":[[0,1.85,16.22],[1,1.84,8.1],[2,1.83,8.1]],"batl":[[0,1.91,36.8],[1,1.92,133.92]],"ltp":1.8,"tv":303.23,"id":9632596},{"trd":[[2.04,30.38]],"batb":[[0,2.04,36.29]],"batl":[[0,2.16,13.58],[1,2.24,81.09],[2,2.82,253.59]],"ltp":2.04,"tv":1141.96,"id":9433864}],"tv":1445.2}]}
{"op":"mcm","clk":"4233279547","pt":1631532909876,"mc":[{"id":"1.187557653","rc":[{"batl":[[2,2.38,4.2]],"ltp":1.8,"tv":303.23,"id":9632596},{"batb":[[0,2.06,14.56],[1,2.04,43.57],[2,2.02,7.28]],"ltp":2.04,"tv":1141.96,"id":9433864}]}]}
{"op":"mcm","clk":"4233281318","pt":1631532929119,"mc":[{"id":"1.187557653","rc":[{"batb":[[0,1.75,3.41],[1,1.71,39.08],[2,1.4,148.56]],"batl":[[1,1.92,0],[2,2.38,0]],"ltp":1.8,"tv":303.23,"id":9632596},{"batb":[[0,1.93,49.87],[1,1.77,378.13],[2,1.4,148.56]],"batl":[[0,2.82,253.59],[1,2.24,0],[2,2.82,0]],"ltp":2.04,"tv":1141.96,"id":9433864}]}]}
{"op":"mcm","clk":"4233283343","pt":1631532951650,"mc":[{"id":"1.187557653","rc":[{"batb":[[0,1.8,9.13],[1,1.75,3.41],[2,1.74,97.15]],"batl":[[0,1.83,102.45],[1,1.91,36.8],[2,2.28,4.39]],"ltp":1.8,"tv":303.23,"id":9632596},{"batb":[[0,2.18,68.8],[1,2.16,52.92],[2,2.14,34.4]],"ltp":2.04,"tv":1141.96,"id":9433864}]}]}
{"op":"mcm","clk":"4233283444","pt":1631532952751,"mc":[{"id":"1.187557653","rc":[{"trd":[[1.83,32.94]],"batl":[[0,1.83,96.22]],"ltp":1.83,"tv":309.46,"id":9632596},{"trd":[[2.2,10.33]],"batb":[[0,2.18,41.28],[1,2.16,74.47],[2,2.14,20.64]],"batl":[[0,2.32,12.94],[1,2.34,6.46],[2,2.36,6.46]],"ltp":2.2,"tv":1147.14,"id":9433864}],"tv":1456.61}]}
{"op":"mcm","clk":"4233284348","pt":1631532962453,"mc":[{"id":"1.187557653","rc":[{"batb":[[0,1.75,3.41],[1,1.74,97.15],[2,1.71,39.08]],"batl":[[0,1.83,94.43]],"ltp":1.83,"tv":309.46,"id":9632596}]}]}
{"op":"mcm","clk":"4233284647","pt":1631532965469,"mc":[{"id":"1.187557653","rc":[{"batl":[[1,1.86,17.84],[2,1.91,36.8]],"ltp":1.83,"tv":309.46,"id":9632596},{"batl":[[0,2.24,9.39],[1,2.32,12.94],[2,2.34,6.46]],"ltp":2.2,"tv":1147.14,"id":9433864}]}]}
{"op":"mcm","clk":"4233285062","pt":1631532969784,"mc":[{"id":"1.187557653","rc":[{"batb":[[1,1.64,45.52],[2,1.4,148.56]],"batl":[[0,1.91,36.8],[1,1.86,0],[2,1.91,0]],"ltp":1.83,"tv":309.46,"id":9632596},{"batb":[[0,2.02,43.51],[1,1.77,378.13],[2,1.4,148.56]],"batl":[[0,2.82,253.59],[1,2.32,0],[2,2.34,0]],"ltp":2.2,"tv":1147.14,"id":9433864}]}]}
{"op":"mcm","clk":"4233285365","pt":1631532973179,"mc":[{"id":"1.187557653","rc":[{"batb":[[1,1.64,45.35]],"ltp":1.83,"tv":309.46,"id":9632596},{"batb":[[0,2,43.68]],"ltp":2.2,"tv":1147.14,"id":9433864}]}]}
{"op":"mcm","clk":"4233285657","pt":1631532976199,"mc":[{"id":"1.187557653","rc":[{"batb":[[1,1.74,10.12],[2,1.64,45.35]],"batl":[[0,1.78,144.21],[1,1.79,8.42],[2,1.8,8.42]],"ltp":1.83,"tv":309.46,"id":9632596},{"batl":[[0,2.5,96.38]],"ltp":2.2,"tv":1147.14,"id":9433864}]}]}
{"op":"mcm","clk":"4233285710","pt":1631532976776,"mc":[{"id":"1.187557653","rc":[{"trd":[[1.78,6.34]],"batb":[[2,1.7,17.64]],"batl":[[0,1.78,137.87]],"ltp":1.78,"tv":315.8,"id":9632596},{"trd":[[2.28,4.95]],"batb":[[0,2.28,29.96],[1,2.14,36.48],[2,1.77,378.13]],"ltp":2.28,"tv":1152.09,"id":9433864}],"tv":1467.9}]}
{"op":"mcm","clk":"4233285838","pt":1631532978286,"mc":[{"id":"1.187557653","rc":[{"batl":[[1,3.15,220.27]],"ltp":2.28,"tv":1152.09,"id":9433864}]}]}
{"op":"mcm","clk":"4233286249","pt":1631532982200,"mc":[{"id":"1.187557653","rc":[{"batl":[[0,2.48,109.68],[1,2.5,96.38],[2,3.15,220.27]],"ltp":2.28,"tv":1152.09,"id":9433864}]}]}
{"op":"mcm","clk":"4233286274","pt":1631532982407,"mc":[{"id":"1.187557653","rc":[{"batl":[[0,2.5,96.38],[1,3.15,220.27],[2,3.15,0]],"ltp":2.28,"tv":1152.09,"id":9433864}]}]}
{"op":"mcm","clk":"4233286622","pt":1631532985591,"mc":[{"id":"1.187557653","rc":[{"batl":[[0,2.48,109.68],[1,2.5,96.38],[2,3.15,220.27]],"ltp":2.28,"tv":1152.09,"id":9433864}]}]}
{"op":"mcm","clk":"4233286808","pt":1631532987201,"mc":[{"id":"1.187557653","rc":[{"batb":[[1,1.7,8.82],[2,1.69,4.41]],"batl":[[0,1.78,64.61],[1,1.79,4.21],[2,1.8,4.21]],"ltp":1.78,"tv":315.8,"id":9632596},{"batl":[[1,3.15,220.27],[2,3.15,0]],"ltp":2.28,"tv":1152.09,"id":9433864}]}]}
{"op":"mcm","clk":"4233286900","pt":1631532988204,"mc":[{"id":"1.187557653","rc":[{"batb":[[1,1.57,52.64],[2,1.4,148.56]],"batl":[[0,1.91,36.8],[1,1.79,0],[2,1.8,0]],"ltp":1.78,"tv":315.8,"id":9632596},{"batb":[[0,2.14,36.32],[1,1.77,378.13],[2,1.4,148.56]],"batl":[[0,3.15,220.27],[1,3.15,0]],"ltp":2.28,"tv":1152.09,"id":9433864}]}]}
{"op":"mcm","clk":"4233288335","pt":1631533002034,"mc":[{"id":"1.187557653","rc":[{"batl":[[0,1.86,36.8],[1,1.91,36.8]],"ltp":1.78,"tv":315.8,"id":9632596}]}]}
{"op":"mcm","clk":"4233288515","pt":1631533004116,"mc":[{"id":"1.187557653","rc":[{"trd":[[1.86,6.05]],"batb":[[0,1.82,16.48],[1,1.81,8.24],[2,1.8,8.24]],"batl":[[0,1.86,170.55]],"ltp":1.86,"tv":321.85,"id":9632596},{"trd":[[2.16,5.21]],"batl":[[0,2.24,16.9],[1,2.28,87.72]],"ltp":2.16,"tv":1157.3,"id":9433864}],"tv":1479.16}]}
{"op":"mcm","clk":"4233288602","pt":1631533005257,"mc":[{"id":"1.187557653","rc":[{"batl":[[0,1.86,139.8],[1,1.92,15.62],[2,1.93,7.82]],"ltp":1.86,"tv":321.85,"id":9632596},{"batb":[[1,1.98,46.28],[2,1.77,378.13]],"ltp":2.16,"tv":1157.3,"id":9433864}]}]}
{"op":"mcm","clk":"4233288664","pt":1631533005938,"mc":[{"id":"1.187557653","rc":[{"batl":[[2,2.92,242.8]],"ltp":2.16,"tv":1157.3,"id":9433864}]}]}
{"op":"mcm","clk":"4233289903","pt":1631533019048,"mc":[{"id":"1.187557653","rc":[{"batb":[[0,1.75,3.41],[1,1.63,45.94],[2,1.4,148.56]],"ltp":1.86,"tv":321.85,"id":9632596},{"batb":[[0,1.98,46.28],[1,1.77,378.13],[2,1.4,148.56]],"batl":[[0,2.92,242.8],[1,2.28,0],[2,2.92,0]],"ltp":2.16,"tv":1157.3,"id":9433864}]}]}
{"op":"mcm","clk":"4233291246","pt":1631533032672,"mc":[{"id":"1.187557653","rc":[{"batl":[[0,1.94,18.4]],"ltp":1.86,"tv":321.85,"id":9632596}]}]}
{"op":"mcm","clk":"4233291894","pt":1631533039978,"mc":[{"id":"1.187557653","rc":[{"batb":[[0,1.93,15.54],[1,1.92,7.78],[2,1.91,7.78]],"batl":[[0,2,75.23]],"ltp":1.86,"tv":321.85,"id":9632596},{"trd":[[1.98,11.04]],"batb":[[0,2,75.23],[1,1.98,40.75],[2,1.77,378.13]],"batl":[[0,2.06,109.34],[1,2.16,90.22]],"ltp":1.98,"tv":1168.34,"id":9433864}],"tv":1490.2}]}
{"op":"mcm","clk":"4233292010","pt":1631533041288,"mc":[{"id":"1.187557653","rc":[{"batl":[[1,2.48,4.03]],"ltp":1.86,"tv":321.85,"id":9632596},{"batb":[[2,1.97,15.22]],"batl":[[2,2.72,264.63]],"ltp":1.98,"tv":1168.34,"id":9433864}]}]}
{"op":"mcm","clk":"4233293503","pt":1631533059753,"mc":[{"id":"1.187557653","rc":[{"batl":[[0,1.99,18.4],[1,2,75.23],[2,2.48,4.03]],"ltp":1.86,"tv":321.85,"id":9632596}]}]}
{"op":"mcm","clk":"4233294058","pt":1631533066034,"mc":[{"id":"1.187557653","rc":[{"batb":[[0,1.75,3.41],[1,1.74,37.15],[2,1.4,148.56]],"batl":[[1,2,0],[2,2.48,0]],"ltp":1.86,"tv":321.85,"id":9632596},{"batb":[[0,1.84,28.87],[1,1.77,378.13],[2,1.4,148.56]],"batl":[[0,2.72,264.63],[1,2.16,0],[2,2.72,0]],"ltp":1.98,"tv":1168.34,"id":9433864}]}]}
{"op":"mcm","clk":"4233299239","pt":1631533124767,"mc":[{"id":"1.187557653","rc":[{"batb":[[1,1.4,148.56],[2,1.3,198.07]],"ltp":1.98,"tv":1168.34,"id":9433864}]}]}
{"op":"mcm","clk":"4233299323","pt":1631533125863,"mc":[{"id":"1.187557653","rc":[{"batb":[[0,2,70.54],[1,1.95,102.56],[2,1.75,3.41]],"batl":[[0,2.2,171.52]],"ltp":1.86,"tv":321.85,"id":9632596},{"trd":[[1.84,11.84]],"batb":[[0,1.84,22.95]],"batl":[[0,1.89,10.26],[1,1.92,15.62],[2,1.93,7.82]],"ltp":1.84,"tv":1180.18,"id":9433864}],"tv":1502.04}]}
{"op":"mcm","clk":"4233299428","pt":1631533127181,"mc":[{"id":"1.187557653","rc":[{"batb":[[1,1.99,48.53],[2,1.95,102.56]],"batl":[[1,2.72,3.68]],"ltp":1.86,"tv":321.85,"id":9632596},{"batb":[[1,1.82,16.48],[2,1.81,8.24]],"ltp":1.84,"tv":1180.18,"id":9433864}]}]}
{"op":"mcm","clk":"4233300952","pt":1631533147682,"mc":[{"id":"1.187557653","rc":[{"batb":[[0,1.85,18.4],[1,1.84,22.95],[2,1.82,16.48]],"ltp":1.84,"tv":1180.18,"id":9433864}]}]}
{"op":"mcm","clk":"4233301071","pt":1631533149507,"mc":[{"id":"1.187557653","rc":[{"trd":[[1.85,17.04]],"batb":[[0,1.85,9.88]],"ltp":1.85,"tv":1197.22,"id":9433864}],"tv":1519.08}]}
{"op":"mcm","clk":"4233303175","pt":1631533178838,"mc":[{"id":"1.187557653","rc":[{"batb":[[0,1.84,22.95],[1,1.82,16.48],[2,1.81,8.24]],"ltp":1.85,"tv":1197.22,"id":9433864}]}]}
{"op":"mcm","clk":"4233303280","pt":1631533180144,"mc":[{"id":"1.187557653","rc":[{"batb":[[0,1.99,48.53],[1,1.87,29.2],[2,1.75,3.41]],"ltp":1.86,"tv":321.85,"id":9632596},{"batb":[[1,1.75,34.14],[2,1.62,388.38]],"batl":[[0,2.6,281.81],[1,1.92,0],[2,1.93,0]],"ltp":1.85,"tv":1197.22,"id":9433864}]}]}
{"op":"mcm","clk":"4233303315","pt":1631533180657,"mc":[{"id":"1.187557653","rc":[{"batb":[[0,1.87,29.2],[1,1.75,3.41],[2,1.5,106.96]],"ltp":1.86,"tv":321.85,"id":9632596},{"batb":[[0,1.75,34.14],[1,1.62,388.38],[2,1.4,148.56]],"batl":[[0,2.6,282.51]],"ltp":1.85,"tv":1197.22,"id":9433864}]}]}
{"op":"mcm","clk":"4233303389","pt":1631533181959,"mc":[{"id":"1.187557653","rc":[{"trd":[[1.85,18.45]],"batb":[[0,1.89,9.18],[1,1.75,34.14],[2,1.62,388.38]],"batl":[[0,2.6,281.81]],"ltp":1.85,"tv":1198.63,"id":9433864}],"tv":1520.49}]}
{"op":"mcm","clk":"4233304333","pt":1631533196772,"mc":[{"id":"1.187557653","rc":[{"batb":[[0,1.75,34.14],[1,1.62,388.38],[2,1.4,148.56]],"ltp":1.85,"tv":1198.63,"id":9433864}]}]}
{"op":"mcm","clk":"4233304412","pt":1631533197866,"mc":[{"id":"1.187557653","rc":[{"batb":[[0,2.2,68.18],[1,2.18,34.1],[2,2.16,34.1]],"batl":[[0,2.28,123.74]],"ltp":1.86,"tv":321.85,"id":9632596},{"trd":[[1.75,12.12]],"batb":[[0,1.75,28.08]],"batl":[[0,1.83,18.25],[1,1.84,21.74],[2,1.89,85.93]],"ltp":1.75,"tv":1210.75,"id":9433864}],"tv":1532.61}]}
{"op":"mcm","clk":"4233304503","pt":1631533199271,"mc":[{"id":"1.187557653","rc":[{"batb":[[0,2.2,13.64],[1,2.18,6.82],[2,2.16,6.82]],"batl":[[1,2.84,3.52]],"ltp":1.86,"tv":321.85,"id":9632596},{"batb":[[0,1.75,45.22],[1,1.74,8.58],[2,1.73,8.58]],"ltp":1.75,"tv":1210.75,"id":9433864}]}]}
{"op":"mcm","clk":"4233305348","pt":1631533211715,"mc":[{"id":"1.187557653","rc":[{"trd":[[1.83,29.44]],"batl":[[0,1.83,3.53]],"ltp":1.83,"tv":1240.19,"id":9433864}],"tv":1562.05}]}
{"op":"mcm","clk":"4233305412","pt":1631533212711,"mc":[{"id":"1.187557653","rc":[{"trd":[[2.28,10.79]],"batl":[[0,2.28,123.19]],"ltp":2.28,"tv":322.4,"id":9632596},{"trd":[[1.78,13.81]],"ltp":1.78,"tv":1240.89,"id":9433864}],"tv":1563.3}]}
{"op":"mcm","clk":"4233305891","pt":1631533219943,"mc":[{"id":"1.187557653","rc":[{"batb":[[0,1.98,49.04],[1,1.75,3.41],[2,1.5,106.96]],"ltp":2.28,"tv":322.4,"id":9632596},{"batb":[[0,1.68,39.25],[1,1.4,148.56],[2,1.3,198.07]],"ltp":1.78,"tv":1240.89,"id":9433864}]}]}
{"op":"mcm","clk":"4233306601","pt":1631533230621,"mc":[{"id":"1.187557653","rc":[{"batb":[[0,1.76,7.36],[1,1.68,39.25],[2,1.4,148.56]],"ltp":1.78,"tv":1240.89,"id":9433864}]}]}
{"op":"mcm","clk":"4233307023","pt":1631533237164,"mc":[{"id":"1.187557653","rc":[{"batb":[[0,2,48.79],[1,1.98,49.04],[2,1.75,3.41]],"batl":[[0,2.12,11.18],[1,2.16,69.44],[2,2.18,34.72]],"ltp":2.28,"tv":322.4,"id":9632596},{"batb":[[0,1.84,108.7],[1,1.8,380.3],[2,1.76,7.36]],"batl":[[0,1.94,10.28],[1,2,48.79]],"ltp":1.78,"tv":1240.89,"id":9433864}]}]}
{"op":"mcm","clk":"4233307083","pt":1631533238161,"mc":[{"id":"1.187557653","rc":[{"trd":[[2.12,5.22]],"batb":[[2,1.84,30.54]],"batl":[[0,2.12,5.96],[1,2.16,41.66],[2,2.18,20.83]],"ltp":2.12,"tv":327.62,"id":9632596},{"trd":[[1.89,5.85]],"batb":[[0,1.85,28.62],[1,1.84,65.22],[2,1.8,380.3]],"batl":[[1,1.96,76.52],[2,1.97,38.26]],"ltp":1.89,"tv":1246.74,"id":9433864}],"tv":1574.37}]}
{"op":"mcm","clk":"4233307114","pt":1631533238578,"mc":[{"id":"1.187557653","rc":[{"batl":[[1,2.16,13.88],[2,2.18,6.94]],"ltp":2.12,"tv":327.62,"id":9632596},{"batl":[[1,1.96,15.3],[2,1.97,7.66]],"ltp":1.89,"tv":1246.74,"id":9433864}]}]}
{"op":"mcm","clk":"4233307739","pt":1631533248191,"mc":[{"id":"1.187557653","rc":[{"batl":[[0,2.16,13.88],[1,2.18,6.94],[2,2.2,6.94]],"ltp":2.12,"tv":327.62,"id":9632596},{"batl":[[0,1.96,15.3],[1,1.97,7.66],[2,1.98,7.66]],"ltp":1.89,"tv":1246.74,"id":9433864}]}]}
{"op":"mcm","clk":"4233307925","pt":1631533251056,"mc":[{"id":"1.187557653","rc":[{"batb":[[0,2.08,8.76],[1,2,48.79],[2,1.98,49.04]],"ltp":2.12,"tv":327.62,"id":9632596},{"batb":[[0,1.89,8.12],[1,1.85,28.62],[2,1.84,65.22]],"ltp":1.89,"tv":1246.74,"id":9433864}]}]}
{"op":"mcm","clk":"4233308510","pt":1631533259977,"mc":[{"id":"1.187557653","rc":[{"batb":[[0,1.84,30.54],[1,1.75,3.41],[2,1.5,106.96]],"ltp":2.12,"tv":327.62,"id":9632596},{"batb":[[0,1.76,7.36],[1,1.75,34.31],[2,1.4,148.56]],"ltp":1.89,"tv":1246.74,"id":9433864}]}]}
{"op":"mcm","clk":"4233308776","pt":1631533263683,"mc":[{"id":"1.187557653","rc":[{"batb":[[2,1.7,36.8]],"ltp":1.89,"tv":1246.74,"id":9433864}]}]}
{"op":"mcm","clk":"4233309093","pt":1631533268181,"mc":[{"id":"1.187557653","rc":[{"batb":[[0,2.1,57.14],[1,1.84,30.54],[2,1.75,3.41]],"batl":[[0,2.24,7.53]],"ltp":2.12,"tv":327.62,"id":9632596},{"trd":[[1.76,12.04]],"batb":[[0,1.8,109.75],[1,1.76,1.34],[2,1.75,34.31]],"batl":[[0,1.86,20.28],[1,1.87,48.12],[2,1.88,24.06]],"ltp":1.76,"tv":1258.78,"id":9433864}],"tv":1586.41}]}
{"op":"mcm","clk":"4233309154","pt":1631533269215,"mc":[{"id":"1.187557653","rc":[{"batb":[[0,2.1,97.73],[1,1.97,49.71]],"batl":[[1,2.82,3.55]],"ltp":2.12,"tv":327.62,"id":9632596}]}]}
{"op":"mcm","clk":"4233310663","pt":1631533292046,"mc":[{"id":"1.187557653","rc":[{"batb":[[0,2.1,40.59]],"ltp":2.12,"tv":327.62,"id":9632596},{"batb":[[0,1.76,1.34],[1,1.75,34.31],[2,1.7,36.8]],"ltp":1.76,"tv":1258.78,"id":9433864}]}]}
{"op":"mcm","clk":"4233310732","pt":1631533292980,"mc":[{"id":"1.187557653","rc":[{"batb":[[0,1.97,49.71],[1,1.75,3.41],[2,1.5,106.96]],"batl":[[0,2.3,6.81]],"ltp":2.12,"tv":327.62,"id":9632596},{"batb":[[1,1.7,36.8],[2,1.67,40.25]],"ltp":1.76,"tv":1258.78,"id":9433864}]}]}
{"op":"mcm","clk":"4233311232","pt":1631533300749,"mc":[{"id":"1.187557653","rc":[{"trd":[[2.3,55.86]],"batb":[[0,2.24,13.4],[1,2.22,6.7],[2,2.2,6.7]],"batl":[[0,2.3,3.12]],"ltp":2.3,"tv":331.32,"id":9632596},{"trd":[[1.76,19.55]],"batb":[[0,1.74,109.95]],"batl":[[0,1.78,14.67],[1,1.79,111.74],[2,1.83,96.43]],"ltp":1.76,"tv":1266.29,"id":9433864}],"tv":1597.62}]}
{"op":"mcm","clk":"4233311293","pt":1631533301883,"mc":[{"id":"1.187557653","rc":[{"batb":[[0,2.24,47.63]],"batl":[[1,2.38,12.6],[2,2.4,6.3]],"ltp":2.3,"tv":331.32,"id":9632596}]}]}
{"op":"mcm","clk":"4233311363","pt":1631533302856,"mc":[{"id":"1.187557653","rc":[{"batb":[[1,1.67,40.25],[2,1.62,44.69]],"ltp":1.76,"tv":1266.29,"id":9433864}]}]}
{"op":"mcm","clk":"4233311657","pt":1631533307286,"mc":[{"id":"1.187557653","rc":[{"trd":[[2.3,58.97]],"batl":[[0,2.38,12.6],[1,2.4,6.3],[2,2.42,6.3]],"ltp":2.3,"tv":334.44,"id":9632596},{"trd":[[1.74,20.85],[1.76,23.62]],"batb":[[0,1.74,104.42]],"ltp":1.74,"tv":1281.42,"id":9433864}],"tv":1615.86}]}
{"op":"mcm","clk":"4233312487","pt":1631533319686,"mc":[{"id":"1.187557653","rc":[{"batb":[[1,1.67,77.05]],"ltp":1.74,"tv":1281.42,"id":9433864}]}]}
{"op":"mcm","clk":"4233312671","pt":1631533322208,"mc":[{"id":"1.187557653","rc":[{"batb":[[0,2.12,40],[1,1.75,3.41],[2,1.6,99.04]],"ltp":2.3,"tv":334.44,"id":9632596},{"batb":[[0,1.67,36.8],[1,1.62,44.69],[2,1.4,148.56]],"ltp":1.74,"tv":1281.42,"id":9433864}]}]}
{"op":"mcm","clk":"4233313277","pt":1631533332213,"mc":[{"id":"1.187557653","rc":[{"batb":[[0,2.36,10.54],[1,2.12,40],[2,1.75,3.41]],"ltp":2.3,"tv":334.44,"id":9632596},{"trd":[[1.7,25.32]],"batb":[[0,1.7,99.93],[1,1.67,36.8],[2,1.62,44.69]],"batl":[[0,1.75,200],[1,1.76,42.86],[2,1.77,328.64]],"ltp":1.7,"tv":1293.92,"id":9433864}],"tv":1628.36}]}
{"op":"mcm","clk":"4233313340","pt":1631533333035,"mc":[{"id":"1.187557653","rc":[{"batb":[[1,2.32,30.38],[2,2.14,38.83]],"batl":[[0,3.05,3.28]],"ltp":2.3,"tv":334.44,"id":9632596},{"batb":[[1,1.67,126.62],[2,1.66,44.9]],"batl":[[0,1.75,120],[1,1.76,25.72],[2,1.77,25.72]],"ltp":1.7,"tv":1293.92,"id":9433864}]}]}
{"op":"mcm","clk":"4233313367","pt":1631533333410,"mc":[{"id":"1.187557653","rc":[{"batb":[[1,1.67,54.76],[2,1.66,8.98]],"ltp":1.7,"tv":1293.92,"id":9433864}]}]}
{"op":"mcm","clk":"4233313620","pt":1631533337011,"mc":[{"id":"1.187557653","rc":[{"batl":[[0,2.4,41.51],[1,3.05,3.28]],"ltp":2.3,"tv":334.44,"id":9632596},{"batl":[[2,1.77,75.56]],"ltp":1.7,"tv":1293.92,"id":9433864}]}]}
{"op":"mcm","clk":"4233313647","pt":1631533337324,"mc":[{"id":"1.187557653","rc":[{"batl":[[0,3.05,3.28],[1,3.05,0]],"ltp":2.3,"tv":334.44,"id":9632596},{"batl":[[2,1.77,25.72]],"ltp":1.7,"tv":1293.92,"id":9433864}]}]}
{"op":"mcm","clk":"4233314782","pt":1631533354639,"mc":[{"id":"1.187557653","rc":[{"trd":[[2.36,0.03]],"batb":[[0,2.36,10.51]],"ltp":2.36,"tv":334.47,"id":9632596},{"trd":[[1.74,20.89]],"ltp":1.74,"tv":1293.97,"id":9433864}],"tv":1628.44}]}
{"op":"mcm","clk":"4233315439","pt":1631533364847,"mc":[{"id":"1.187557653","rc":[{"batb":[[0,2.32,30.38],[1,2.14,38.83],[2,1.75,3.41]],"ltp":2.36,"tv":334.47,"id":9632596},{"batb":[[0,1.7,89.93]],"ltp":1.74,"tv":1293.97,"id":9433864}]}]}
{"op":"mcm","clk":"4233315614","pt":1631533367772,"mc":[{"id":"1.187557653","rc":[{"batb":[[0,2.36,10.51],[1,2.32,30.38],[2,2.14,38.83]],"ltp":2.36,"tv":334.47,"id":9632596},{"batb":[[0,1.7,99.98]],"ltp":1.74,"tv":1293.97,"id":9433864}]}]}
{"op":"mcm","clk":"4233315796","pt":1631533370491,"mc":[{"id":"1.187557653","rc":[{"batl":[[0,2.88,218.34],[1,3.05,3.28]],"ltp":2.36,"tv":334.47,"id":9632596}]}]}
{"op":"mcm","clk":"4233318213","pt":1631533405860,"mc":[{"id":"1.187557653","rc":[{"batb":[[1,1.67,17.96]],"ltp":1.74,"tv":1293.97,"id":9433864}]}]}
{"op":"mcm","clk":"4233318437","pt":1631533409171,"mc":[{"id":"1.187557653","rc":[{"trd":[[2.36,1.61]],"batb":[[0,2.36,9.72]],"ltp":2.36,"tv":336.05,"id":9632596}],"tv":1630.02}]}
{"op":"mcm","clk":"4233319141","pt":1631533419252,"mc":[{"id":"1.187557653","rc":[{"batb":[[0,2.32,30.38],[1,2.14,38.83],[2,1.75,3.41]],"ltp":2.36,"tv":336.05,"id":9632596},{"batb":[[0,1.7,89.93]],"ltp":1.74,"tv":1293.97,"id":9433864}]}]}
{"op":"mcm","clk":"4233319399","pt":1631533422161,"mc":[{"id":"1.187557653","rc":[{"batb":[[0,2.36,9.72],[1,2.32,30.38],[2,2.14,38.83]],"ltp":2.36,"tv":336.05,"id":9632596},{"batb":[[0,1.7,101.07]],"ltp":1.74,"tv":1293.97,"id":9433864}]}]}
{"op":"mcm","clk":"4233319773","pt":1631533427276,"mc":[{"id":"1.187557653","rc":[{"batl":[[1,3.05,0]],"ltp":2.36,"tv":336.05,"id":9632596}]}]}
{"op":"mcm","clk":"4233319808","pt":1631533427685,"mc":[{"id":"1.187557653","rc":[{"batb":[[0,2.14,38.83],[1,1.75,3.41],[2,1.7,16.97]],"ltp":2.36,"tv":336.05,"id":9632596},{"batb":[[0,1.52,396.29],[1,1.51,58.07],[2,1.3,198.07]],"batl":[[0,2.36,326.18],[1,1.76,0],[2,1.77,0]],"ltp":1.74,"tv":1293.97,"id":9433864}]}]}
{"op":"mcm","clk":"4233321028","pt":1631533442396,"mc":[{"id":"1.187557653","rc":[{"batb":[[0,1.51,58.07],[1,1.3,198.07],[2,1.25,237.69]],"ltp":1.74,"tv":1293.97,"id":9433864}]}]}
{"op":"mcm","clk":"4233321157","pt":1631533444115,"mc":[{"id":"1.187557653","rc":[{"batb":[[2,1.6,99.04]],"batl":[[0,2.24,7.05],[1,2.28,154.96],[2,2.3,19.74]],"ltp":2.36,"tv":336.05,"id":9632596},{"batl":[[0,1.86,20.85],[1,1.92,150.53],[2,2.36,326.18]],"ltp":1.74,"tv":1293.97,"id":9433864}]}]}
{"op":"mcm","clk":"4233321236","pt":1631533444997,"mc":[{"id":"1.187557653","rc":[{"trd":[[2.24,4.78]],"batb":[[0,2.14,52.85],[1,2.12,7],[2,2.1,7]],"batl":[[0,2.24,2.27],[1,2.28,128.64],[2,2.3,6.58]],"ltp":2.24,"tv":340.83,"id":9632596},{"trd":[[1.8,18.45]],"batb":[[0,1.72,35.82],[1,1.61,45.94],[2,1.3,198.07]],"ltp":1.8,"tv":1299.92,"id":9433864}],"tv":1640.75}]}
{"op":"mcm","clk":"4233321334","pt":1631533446508,"mc":[{"id":"1.187557653","rc":[{"batb":[[2,1.58,388.69]],"ltp":1.8,"tv":1299.92,"id":9433864}]}]}
{"op":"mcm","clk":"4233321864","pt":1631533453055,"mc":[{"id":"1.187557653","rc":[{"batb":[[0,1.72,2179.84]],"ltp":1.8,"tv":1299.92,"id":9433864}]}]}
{"op":"mcm","clk":"4233321984","pt":1631533455039,"mc":[{"id":"1.187557653","rc":[{"batl":[[0,2.28,128.64],[1,2.3,6.58],[2,2.32,6.58]],"ltp":2.24,"tv":340.83,"id":9632596},{"batb":[[0,1.72,35.82]],"batl":[[0,1.92,150.53],[1,2.36,326.18],[2,2.36,0]],"ltp":1.8,"tv":1299.92,"id":9433864}]}]}
{"op":"mcm","clk":"4233322238","pt":1631533458132,"mc":[{"id":"1.187557653","rc":[{"batl":[[0,2.28,142.75]],"ltp":2.24,"tv":340.83,"id":9632596},{"batb":[[0,1.72,1341.71]],"batl":[[0,1.83,10.59],[1,1.92,150.53],[2,2.36,326.18]],"ltp":1.8,"tv":1299.92,"id":9433864}]}]}
{"op":"mcm","clk":"4233322251","pt":1631533458341,"mc":[{"id":"1.187557653","rc":[{"batb":[[0,1.72,35.82]],"ltp":1.8,"tv":1299.92,"id":9433864}]}]}
{"op":"mcm","clk":"4233322388","pt":1631533459748,"mc":[{"id":"1.187557653","rc":[{"batb":[[0,1.98,49.2],[1,1.75,3.41],[2,1.6,99.04]],"ltp":2.24,"tv":340.83,"id":9632596},{"batb":[[0,1.61,45.94],[1,1.58,388.69],[2,1.3,198.07]],"batl":[[0,2.36,326.18],[1,1.92,0],[2,2.36,0]],"ltp":1.8,"tv":1299.92,"id":9433864}]}]}
{"op":"mcm","clk":"4233322940","pt":1631533466950,"mc":[{"id":"1.187557653","rc":[{"batb":[[1,1.3,198.07],[2,1.25,237.69]],"ltp":1.8,"tv":1299.92,"id":9433864}]}]}
{"op":"mcm","clk":"4233323121","pt":1631533469287,"mc":[{"id":"1.187557653","rc":[{"batb":[[2,1.5,106.96]],"batl":[[0,2.12,10.86],[1,2.28,392.62],[2,2.58,3.88]],"ltp":2.24,"tv":340.83,"id":9632596},{"batb":[[0,1.87,123],[1,1.86,8.02],[2,1.85,8.02]],"batl":[[0,1.94,10.64],[1,2.02,96.87]],"ltp":1.8,"tv":1299.92,"id":9433864}]}]}
{"op":"mcm","clk":"4233323146","pt":1631533469651,"mc":[{"id":"1.187557653","rc":[{"trd":[[2.12,10.31]],"batb":[[1,1.87,29.37],[2,1.75,3.41]],"batl":[[0,2.12,5.77]],"ltp":2.12,"tv":345.92,"id":9632596},{"trd":[[1.89,11.56]],"batb":[[2,1.85,36.56]],"batl":[[1,1.97,15.22],[2,1.98,7.62]],"ltp":1.89,"tv":1305.63,"id":9433864}],"tv":1651.55}]}
{"op":"mcm","clk":"4233323960","pt":1631533478984,"mc":[{"id":"1.187557653","rc":[{"batb":[[0,1.85,28.54],[1,1.73,35.23],[2,1.62,388.38]],"batl":[[0,2.6,281.81],[1,1.97,0],[2,1.98,0]],"ltp":1.89,"tv":1305.63,"id":9433864}]}]}
{"op":"mcm","clk":"4233324080","pt":1631533480280,"mc":[{"id":"1.187557653","rc":[{"batb":[[0,1.98,29.14]],"ltp":2.12,"tv":345.92,"id":9632596},{"batb":[[0,1.73,35.23],[1,1.62,388.38],[2,1.4,148.56]],"ltp":1.89,"tv":1305.63,"id":9433864}]}]}
{"op":"mcm","clk":"4233324093","pt":1631533480488,"mc":[{"id":"1.187557653","rc":[{"batb":[[0,1.87,29.37],[1,1.75,3.41],[2,1.5,106.96]],"ltp":2.12,"tv":345.92,"id":9632596}]}]}
{"op":"mcm","clk":"4233325649","pt":1631533501013,"mc":[{"id":"1.187557653","rc":[{"batb":[[1,1.4,148.56],[2,1.3,198.07]],"ltp":1.89,"tv":1305.63,"id":9433864}]}]}
{"op":"mcm","clk":"4233325797","pt":1631533502613,"mc":[{"id":"1.187557653","rc":[{"batl":[[0,2.04,58.34],[1,2.06,22.06],[2,2.08,22.06]],"ltp":2.12,"tv":345.92,"id":9632596},{"batb":[[0,1.93,62.17],[1,1.73,35.23],[2,1.4,148.56]],"batl":[[0,2.02,10.38],[1,2.12,96.71],[2,2.6,281.81]],"ltp":1.89,"tv":1305.63,"id":9433864}]}]}
{"op":"mcm","clk":"4233325956","pt":1631533504225,"mc":[{"id":"1.187557653","rc":[{"trd":[[2.04,5.27]],"batb":[[0,1.93,15.54],[1,1.92,7.78],[2,1.91,7.78]],"batl":[[0,2.04,23.66],[1,2.06,7.36],[2,2.08,7.36]],"ltp":2.04,"tv":351.19,"id":9632596},{"trd":[[1.96,5.49]],"batb":[[0,1.96,47.78],[1,1.93,62.17],[2,1.87,27.28]],"ltp":1.96,"tv":1311.12,"id":9433864}],"tv":1662.31}]}
{"op":"mcm","clk":"4233326820","pt":1631533513925,"mc":[{"id":"1.187557653","rc":[{"batb":[[0,1.79,33.39],[1,1.75,3.41],[2,1.5,106.96]],"ltp":2.04,"tv":351.19,"id":9632596},{"batb":[[0,1.87,27.28],[1,1.67,383.76],[2,1.4,148.56]],"batl":[[0,2.6,281.81],[1,2.12,0],[2,2.6,0]],"ltp":1.96,"tv":1311.12,"id":9433864}]}]}
{"op":"mcm","clk":"4233327552","pt":1631533523244,"mc":[{"id":"1.187557653","rc":[{"batl":[[0,2.12,136.98]],"ltp":2.04,"tv":351.19,"id":9632596},{"trd":[[1.87,11.3]],"batb":[[0,1.87,21.63]],"batl":[[0,1.94,12.63],[1,1.95,46.15],[2,1.96,23.08]],"ltp":1.87,"tv":1322.42,"id":9433864}],"tv":1673.61}]}
{"op":"mcm","clk":"4233327636","pt":1631533524233,"mc":[{"id":"1.187557653","rc":[{"batb":[[0,1.95,51.55],[1,1.84,30.54],[2,1.79,33.39]],"batl":[[1,2.56,3.91]],"ltp":2.04,"tv":351.19,"id":9632596},{"batb":[[1,1.85,16.22],[2,1.84,8.1]],"batl":[[1,1.95,15.38],[2,1.96,7.7]],"ltp":1.87,"tv":1322.42,"id":9433864}]}]}
{"op":"mcm","clk":"4233327725","pt":1631533525172,"mc":[{"id":"1.187557653","rc":[{"batb":[[2,1.75,3.41]],"ltp":2.04,"tv":351.19,"id":9632596}]}]}
{"op":"mcm","clk":"4233327986","pt":1631533527952,"mc":[{"id":"1.187557653","rc":[{"trd":[[2.06,11.89]],"ltp":2.06,"tv":363.08,"id":9632596},{"trd":[[1.94,24.05]],"batl":[[0,1.95,15.38],[1,1.96,7.7],[2,1.97,7.7]],"ltp":1.94,"tv":1335.05,"id":9433864}],"tv":1698.13}]}
{"op":"mcm","clk":"4233328493","pt":1631533534075,"mc":[{"id":"1.187557653","rc":[{"batb":[[0,1.84,30.54],[1,1.75,3.41],[2,1.5,106.96]],"ltp":2.06,"tv":363.08,"id":9632596},{"batb":[[0,1.75,33.89],[1,1.67,383.76],[2,1.4,148.56]],"batl":[[0,2.6,281.81],[1,1.96,0],[2,1.97,0]],"ltp":1.94,"tv":1335.05,"id":9433864}]}]}
{"op":"mcm","clk":"4233328738","pt":1631533537165,"mc":[{"id":"1.187557653","rc":[{"batb":[[0,1.85,30.46],[1,1.84,30.54],[2,1.75,3.41]],"ltp":2.06,"tv":363.08,"id":9632596}]}]}
{"op":"mcm","clk":"4233328758","pt":1631533537371,"mc":[{"id":"1.187557653","rc":[{"batb":[[1,1.75,3.41],[2,1.5,106.96]],"ltp":2.06,"tv":363.08,"id":9632596}]}]}
{"op":"mcm","clk":"4233329653","pt":1631533548774,"mc":[{"id":"1.187557653","rc":[{"batl":[[0,2,6.09],[1,2.12,342.76],[2,2.44,4.1]],"ltp":2.06,"tv":363.08,"id":9632596},{"batb":[[0,2,6.09],[1,1.97,15.22],[2,1.96,7.62]],"batl":[[0,2.06,12.13],[1,2.12,85.78],[2,2.6,281.81]],"ltp":1.94,"tv":1335.05,"id":9433864}]}]}
{"op":"mcm","clk":"4233329745","pt":1631533549975,"mc":[{"id":"1.187557653","rc":[{"batb":[[0,1.93,15.54],[1,1.92,7.78],[2,1.91,7.78]],"ltp":2.06,"tv":363.08,"id":9632596},{"trd":[[2,10.92]],"batb":[[0,1.98,46.74]],"ltp":2.0,"tv":1345.97,"id":9433864}],"tv":1709.05}]}
{"op":"mcm","clk":"4233330560","pt":1631533559697,"mc":[{"id":"1.187557653","rc":[{"batl":[[0,2.12,342.76],[1,2.44,4.1],[2,2.44,0]],"ltp":2.06,"tv":363.08,"id":9632596},{"batb":[[0,1.98,46.11]],"batl":[[0,2.12,85.78],[1,2.6,281.81],[2,2.6,0]],"ltp":2.0,"tv":1345.97,"id":9433864}]}]}
{"op":"mcm","clk":"4233330817","pt":1631533562999,"mc":[{"id":"1.187557653","rc":[{"batl":[[0,2.02,14.96],[1,2.12,342.76],[2,2.44,4.1]],"ltp":2.06,"tv":363.08,"id":9632596},{"batl":[[0,2.04,9.68],[1,2.12,85.78],[2,2.6,281.81]],"ltp":2.0,"tv":1345.97,"id":9433864}]}]}
{"op":"mcm","clk":"4233331511","pt":1631533572816,"mc":[{"id":"1.187557653","rc":[{"batl":[[0,2.02,4.26],[1,2.04,9.68],[2,2.12,85.78]],"ltp":2.0,"tv":1345.97,"id":9433864}]}]}
{"op":"mcm","clk":"4233332656","pt":1631533586556,"mc":[{"id":"1.187557653","rc":[{"batl":[[0,2.04,9.68],[1,2.12,85.78],[2,2.6,281.81]],"ltp":2.0,"tv":1345.97,"id":9433864}]}]}
{"op":"mcm","clk":"4233332963","pt":1631533590253,"mc":[{"id":"1.187557653","rc":[{"batb":[[0,1.75,3.41],[1,1.74,36.65],[2,1.5,106.96]],"ltp":2.06,"tv":363.08,"id":9632596},{"batb":[[0,1.89,26.44],[1,1.67,383.76],[2,1.4,148.56]],"batl":[[0,2,4.26],[1,2.6,281.81],[2,2.6,0]],"ltp":2.0,"tv":1345.97,"id":9433864}]}]}
{"op":"mcm","clk":"4233333378","pt":1631533595291,"mc":[{"id":"1.187557653","rc":[{"batl":[[0,2.6,281.81],[1,2.6,0]],"ltp":2.0,"tv":1345.97,"id":9433864}]}]}
{"op":"mcm","clk":"4233334768","pt":1631533611997,"mc":[{"id":"1.187557653","rc":[{"batb":[[0,2.04,7.03],[1,1.97,60.91],[2,1.75,3.41]],"batl":[[0,2.08,98.42]],"ltp":2.06,"tv":363.08,"id":9632596},{"trd":[[1.89,22.74]],"batb":[[0,1.89,20.85]],"batl":[[0,1.99,45.23],[1,2,22.61],[2,2.02,22.61]],"ltp":1.89,"tv":1357.15,"id":9433864}],"tv":1720.23}]}
{"op":"mcm","clk":"4233334846","pt":1631533612994,"mc":[{"id":"1.187557653","rc":[{"batb":[[2,1.93,26.61]],"batl":[[1,2.52,3.97]],"ltp":2.06,"tv":363.08,"id":9632596},{"batb":[[1,1.88,15.96],[2,1.87,7.98]],"batl":[[0,1.99,15.08],[1,2,7.54],[2,2.02,7.54]],"ltp":1.89,"tv":1357.15,"id":9433864}]}]}
{"op":"mcm","clk":"4233335155","pt":1631533616902,"mc":[{"id":"1.187557653","rc":[{"trd":[[2.04,19.33]],"batb":[[0,1.97,60.91],[1,1.93,26.61],[2,1.83,31.38]],"ltp":2.04,"tv":377.14,"id":9632596}],"tv":1734.29}]}
{"op":"mcm","clk":"4233336008","pt":1631533626910,"mc":[{"id":"1.187557653","rc":[{"batl":[[0,2.08,89.93]],"ltp":2.04,"tv":377.14,"id":9632596}]}]}
{"op":"mcm","clk":"4233336230","pt":1631533629831,"mc":[{"id":"1.187557653","rc":[{"batl":[[0,2.06,7.84],[1,2.08,89.93],[2,2.52,3.97]],"ltp":2.04,"tv":377.14,"id":9632596},{"batl":[[0,1.98,8.15],[1,1.99,15.08],[2,2,7.54]],"ltp":1.89,"tv":1357.15,"id":9433864}]}]}
{"op":"mcm","clk":"4233336414","pt":1631533632021,"mc":[{"id":"1.187557653","rc":[{"batb":[[0,1.83,31.38],[1,1.75,3.41],[2,1.5,106.96]],"ltp":2.04,"tv":377.14,"id":9632596},{"batb":[[0,1.82,29.96],[1,1.67,383.76],[2,1.4,148.56]],"batl":[[0,2.6,281.81],[1,1.99,0],[2,2,0]],"ltp":1.89,"tv":1357.15,"id":9433864}]}]}
{"op":"mcm","clk":"4233336915","pt":1631533638235,"mc":[{"id":"1.187557653","rc":[{"batb":[[0,2.06,58.25],[1,2,75.44],[2,1.84,68.12]],"batl":[[0,2.16,126.83]],"ltp":2.04,"tv":377.14,"id":9632596},{"trd":[[1.82,11.42]],"batb":[[0,1.82,24.25]],"batl":[[0,1.92,8.25],[1,1.95,46.15],[2,1.96,23.08]],"ltp":1.82,"tv":1368.57,"id":9433864}],"tv":1745.71}]}
{"op":"mcm","clk":"4233336996","pt":1631533639179,"mc":[{"id":"1.187557653","rc":[{"batb":[[1,2,122.13],[2,1.92,27.11]],"batl":[[1,2.58,3.88]],"ltp":2.04,"tv":377.14,"id":9632596},{"batb":[[0,1.85,16.22],[1,1.84,8.1],[2,1.83,8.1]],"batl":[[1,1.95,15.38],[2,1.96,7.7]],"ltp":1.82,"tv":1368.57,"id":9433864}]}]}
{"op":"mcm","clk":"4233338491","pt":1631533656980,"mc":[{"id":"1.187557653","rc":[{"batb":[[0,1.92,27.11],[1,1.75,3.41],[2,1.5,106.96]],"ltp":2.04,"tv":377.14,"id":9632596},{"batb":[[0,1.77,32.89],[1,1.67,383.76],[2,1.4,148.56]],"batl":[[0,2.6,281.81],[1,1.95,0],[2,1.96,0]],"ltp":1.82,"tv":1368.57,"id":9433864}]}]}
{"op":"mcm","clk":"4233339243","pt":1631533666096,"mc":[{"id":"1.187557653","rc":[{"batb":[[0,2,5.31],[1,1.92,27.11],[2,1.75,3.41]],"batl":[[0,2.06,92.45],[1,2.08,1524],[2,2.1,36.06]],"ltp":2.04,"tv":377.14,"id":9632596},{"batl":[[0,2,5.31],[1,2.06,97.83],[2,2.6,281.81]],"ltp":1.82,"tv":1368.57,"id":9433864}]}]}
{"op":"mcm","clk":"4233339342","pt":1631533667283,"mc":[{"id":"1.187557653","rc":[{"trd":[[2.06,17.13]],"batb":[[1,1.97,76.14],[2,1.96,38.08]],"batl":[[0,2.06,87.21],[1,2.08,14.42],[2,2.1,7.22]],"ltp":2.06,"tv":382.38,"id":9632596},{"trd":[[1.94,29.61]],"batb":[[0,1.9,52.05],[1,1.82,30.04],[2,1.67,383.76]],"ltp":1.94,"tv":1374.13,"id":9433864}],"tv":1756.51}]}
{"op":"mcm","clk":"4233339387","pt":1631533667816,"mc":[{"id":"1.187557653","rc":[{"batb":[[1,1.97,15.22],[2,1.96,7.62]],"ltp":2.06,"tv":382.38,"id":9632596}]}]}
{"op":"mcm","clk":"4233340962","pt":1631533686844,"mc":[{"id":"1.187557653","rc":[{"batb":[[0,1.81,32.22],[1,1.75,3.41],[2,1.5,106.96]],"ltp":2.06,"tv":382.38,"id":9632596},{"batb":[[0,1.82,30.04],[1,1.67,383.76],[2,1.4,148.56]],"batl":[[0,2.6,281.81],[1,2.06,0],[2,2.6,0]],"ltp":1.94,"tv":1374.13,"id":9433864}]}]}
{"op":"mcm","clk":"4233343624","pt":1631533721193,"mc":[{"id":"1.187557653","rc":[{"batb":[[2,1.4,148.56]],"batl":[[0,1.97,96.44],[1,1.98,38.08],[2,1.99,38.08]],"ltp":2.06,"tv":382.38,"id":9632596},{"batb":[[0,2.06,7.88],[1,2.04,81.3],[2,1.82,30.04]],"batl":[[0,2.12,14.34],[1,2.2,141.23],[2,2.6,281.81]],"ltp":1.94,"tv":1374.13,"id":9433864}]}]}
{"op":"mcm","clk":"4233343685","pt":1631533722106,"mc":[{"id":"1.187557653","rc":[{"batb":[[0,1.87,48.12],[1,1.86,24.06],[2,1.85,24.06]],"ltp":2.06,"tv":382.38,"id":9632596},{"trd":[[2.06,10.7]],"batb":[[0,2.06,2.53],[2,2.02,43.43]],"ltp":2.06,"tv":1384.83,"id":9433864}],"tv":1767.21}]}
{"op":"mcm","clk":"4233343698","pt":1631533722313,"mc":[{"id":"1.187557653","rc":[{"batb":[[0,1.87,16.04],[1,1.86,8.02],[2,1.85,8.02]],"batl":[[0,1.97,65.98],[1,1.98,22.85],[2,1.99,22.85]],"ltp":2.06,"tv":382.38,"id":9632596}]}]}
{"op":"mcm","clk":"4233344418","pt":1631533732109,"mc":[{"id":"1.187557653","rc":[{"batb":[[0,2.04,81.3],[1,2.02,43.43],[2,1.89,26.44]],"batl":[[0,2.2,141.23],[1,2.6,281.81],[2,2.6,0]],"ltp":2.06,"tv":1384.83,"id":9433864}]}]}
{"op":"mcm","clk":"4233344636","pt":1631533735041,"mc":[{"id":"1.187557653","rc":[{"batb":[[0,1.92,8.36],[1,1.87,16.04],[2,1.86,8.02]],"batl":[[0,1.96,10.18],[1,1.97,65.98],[2,1.98,22.85]],"ltp":2.06,"tv":382.38,"id":9632596}]}]}
{"op":"mcm","clk":"4233345160","pt":1631533741443,"mc":[{"id":"1.187557653","rc":[{"batl":[[0,2.2,183.81]],"ltp":2.06,"tv":1384.83,"id":9433864}]}]}
{"op":"mcm","clk":"4233345690","pt":1631533749173,"mc":[{"id":"1.187557653","rc":[{"batb":[[0,1.81,32.22],[1,1.75,3.41],[2,1.67,42.18]],"ltp":2.06,"tv":382.38,"id":9632596},{"batb":[[0,2.02,43.43],[1,1.89,26.44],[2,1.67,383.76]],"batl":[[0,2.6,281.81],[1,2.6,0]],"ltp":2.06,"tv":1384.83,"id":9433864}]}]}
{"op":"mcm","clk":"4233345750","pt":1631533750065,"mc":[{"id":"1.187557653","rc":[{"batb":[[0,1.75,3.41],[1,1.67,42.18],[2,1.4,148.56]],"ltp":2.06,"tv":382.38,"id":9632596},{"batb":[[0,1.89,26.44],[1,1.67,383.76],[2,1.4,148.56]],"ltp":2.06,"tv":1384.83,"id":9433864}]}]}
{"op":"mcm","clk":"4233347863","pt":1631533778093,"mc":[{"id":"1.187557653","rc":[{"batb":[[0,2,7.22],[1,1.97,60.91],[2,1.75,3.41]],"batl":[[0,2.06,88.98]],"ltp":2.06,"tv":382.38,"id":9632596},{"trd":[[1.89,33.86]],"batb":[[0,1.89,20.88]],"batl":[[0,2,7.22],[1,2.02,44.56],[2,2.04,22.28]],"ltp":1.89,"tv":1395.95,"id":9433864}],"tv":1778.33}]}
{"op":"mcm","clk":"4233347933","pt":1631533779086,"mc":[{"id":"1.187557653","rc":[{"batb":[[2,1.93,26.61]],"batl":[[1,2.48,4.03]],"ltp":2.06,"tv":382.38,"id":9632596},{"batb":[[0,1.91,15.7],[1,1.9,7.86],[2,1.89,28.74]],"ltp":1.89,"tv":1395.95,"id":9433864}]}]}
{"op":"mcm","clk":"4233349856","pt":1631533805275,"mc":[{"id":"1.187557653","rc":[{"batb":[[0,1.93,26.61],[1,1.8,32.89],[2,1.75,3.41]],"ltp":2.06,"tv":382.38,"id":9632596},{"batb":[[0,1.89,20.88],[1,1.8,30.79],[2,1.67,383.76]],"batl":[[0,2.6,281.81],[1,2.02,0],[2,2.04,0]],"ltp":1.89,"tv":1395.95,"id":9433864}]}]}
{"op":"mcm","clk":"4233349878","pt":1631533805542,"mc":[{"id":"1.187557653","rc":[{"batb":[[0,1.8,32.89],[1,1.75,3.41],[2,1.5,106.96]],"ltp":2.06,"tv":382.38,"id":9632596},{"batb":[[0,1.8,30.79],[1,1.67,383.76],[2,1.4,148.56]],"ltp":1.89,"tv":1395.95,"id":9433864}]}]}
{"op":"mcm","clk":"4233351314","pt":1631533823693,"mc":[{"id":"1.187557653","rc":[{"batl":[[0,1.94,110.47],[1,1.96,130.47],[2,1.97,7.66]],"ltp":2.06,"tv":382.38,"id":9632596},{"batl":[[0,2.12,13.79],[1,2.2,106.3],[2,2.6,281.81]],"ltp":1.89,"tv":1395.95,"id":9433864}]}]}
{"op":"mcm","clk":"4233351421","pt":1631533824787,"mc":[{"id":"1.187557653","rc":[{"trd":[[1.94,5.65]],"batb":[[2,1.67,42.59]],"batl":[[0,1.94,104.82]],"ltp":1.94,"tv":388.03,"id":9632596},{"trd":[[2.06,16.02]],"batb":[[0,2.02,42.59],[1,1.9,26.19],[2,1.67,383.76]],"batl":[[1,2.16,13.88],[2,2.18,6.94]],"ltp":2.06,"tv":1401.27,"id":9433864}],"tv":1789.3}]}
{"op":"mcm","clk":"4233351956","pt":1631533831573,"mc":[{"id":"1.187557653","rc":[{"batb":[[0,1.81,745.51],[1,1.8,32.89],[2,1.75,3.41]],"ltp":1.94,"tv":388.03,"id":9632596}]}]}
{"op":"mcm","clk":"4233352924","pt":1631533844110,"mc":[{"id":"1.187557653","rc":[{"batb":[[0,1.8,32.89],[1,1.75,3.41],[2,1.67,42.59]],"ltp":1.94,"tv":388.03,"id":9632596},{"batl":[[0,2.6,281.81],[1,2.16,0],[2,2.18,0]],"ltp":2.06,"tv":1401.27,"id":9433864}]}]}
{"op":"mcm","clk":"4233352951","pt":1631533844528,"mc":[{"id":"1.187557653","rc":[{"batb":[[0,1.75,3.41],[1,1.67,42.59],[2,1.4,148.56]],"ltp":1.94,"tv":388.03,"id":9632596},{"batb":[[0,1.9,26.19],[1,1.67,383.76],[2,1.4,148.56]],"ltp":2.06,"tv":1401.27,"id":9433864}]}]}
{"op":"mcm","clk":"4233353144","pt":1631533846623,"mc":[{"id":"1.187557653","rc":[{"batb":[[1,1.4,148.56],[2,1.3,198.07]],"ltp":2.06,"tv":1401.27,"id":9433864}]}]}
{"op":"mcm","clk":"4233353491","pt":1631533851212,"mc":[{"id":"1.187557653","rc":[{"batb":[[1,1.74,379.61],[2,1.4,148.56]],"batl":[[0,2.92,242.8]],"ltp":2.06,"tv":1401.27,"id":9433864}]}]}
{"op":"mcm","clk":"4233354354","pt":1631533862050,"mc":[{"id":"1.187557653","rc":[{"batb":[[1,1.4,148.56],[2,1.3,198.07]],"ltp":2.06,"tv":1401.27,"id":9433864}]}]}
{"op":"mcm","clk":"4233354533","pt":1631533864255,"mc":[{"id":"1.187557653","rc":[{"batb":[[1,1.72,142.12],[2,1.67,42.59]],"batl":[[0,1.79,111.74],[1,1.83,137.71],[2,1.84,8.2]],"ltp":1.94,"tv":388.03,"id":9632596},{"batb":[[0,2.22,32.13],[1,2.04,42.09],[2,1.9,26.19]],"batl":[[0,2.28,9.8],[1,2.92,242.8]],"ltp":2.06,"tv":1401.27,"id":9433864}]}]}
{"op":"mcm","clk":"4233354557","pt":1631533864664,"mc":[{"id":"1.187557653","rc":[{"trd":[[1.79,6.31]],"batb":[[1,1.74,17.24],[2,1.73,8.62]],"batl":[[0,1.79,105.43]],"ltp":1.79,"tv":394.34,"id":9632596},{"trd":[[2.26,5]],"batb":[[2,1.4,148.56]],"ltp":2.26,"tv":1406.27,"id":9433864}],"tv":1800.61}]}
{"op":"mcm","clk":"4233354614","pt":1631533865557,"mc":[{"id":"1.187557653","rc":[{"batb":[[2,1.82,377.89]],"ltp":2.26,"tv":1406.27,"id":9433864}]}]}
{"op":"mcm","clk":"4233356494","pt":1631533888100,"mc":[{"id":"1.187557653","rc":[{"batb":[[1,1.67,42.59],[2,1.53,58.41]],"ltp":1.79,"tv":394.34,"id":9632596},{"batl":[[0,2.92,242.8],[1,2.92,0]],"ltp":2.26,"tv":1406.27,"id":9433864}]}]}
{"op":"mcm","clk":"4233356529","pt":1631533888470,"mc":[{"id":"1.187557653","rc":[{"batb":[[1,1.53,58.41],[2,1.4,148.56]],"ltp":1.79,"tv":394.34,"id":9632596},{"batb":[[0,2.04,42.09],[1,1.82,377.89],[2,1.4,148.56]],"ltp":2.26,"tv":1406.27,"id":9433864}]}]}
{"op":"mcm","clk":"4233357285","pt":1631533897277,"mc":[{"id":"1.187557653","rc":[{"batb":[[0,1.85,48.65],[1,1.84,24.32],[2,1.83,121.43]],"batl":[[0,1.94,108.54]],"ltp":1.79,"tv":394.34,"id":9632596},{"trd":[[2.04,40.96]],"batb":[[0,2.04,36.8]],"batl":[[0,2.12,64.8],[1,2.92,242.8]],"ltp":2.04,"tv":1416.85,"id":9433864}],"tv":1811.19}]}
{"op":"mcm","clk":"4233357365","pt":1631533898207,"mc":[{"id":"1.187557653","rc":[{"batl":[[1,2.34,4.27]],"ltp":1.79,"tv":394.34,"id":9632596},{"batb":[[0,2.06,72.82],[1,2.04,73.2],[2,2.02,36.4]],"ltp":2.04,"tv":1416.85,"id":9433864}]}]}
{"op":"mcm","clk":"4233357388","pt":1631533898415,"mc":[{"id":"1.187557653","rc":[{"batb":[[0,1.85,16.22],[1,1.84,8.1],[2,1.83,105.21]],"ltp":1.79,"tv":394.34,"id":9632596},{"batb":[[0,2.06,14.56],[1,2.04,44.08],[2,2.02,7.28]],"ltp":2.04,"tv":1416.85,"id":9433864}]}]}
{"op":"mcm","clk":"4233357794","pt":1631533903400,"mc":[{"id":"1.187557653","rc":[{"trd":[[1.94,222.49]],"batl":[[0,2.34,4.39],[1,2.34,0]],"ltp":1.94,"tv":611.18,"id":9632596}],"tv":2028.03}]}
{"op":"mcm","clk":"4233357992","pt":1631533905707,"mc":[{"id":"1.187557653","rc":[{"trd":[[1.94,222.73]],"batb":[[0,1.85,16.8]],"batl":[[0,2.34,4.27]],"ltp":1.94,"tv":611.42,"id":9632596}],"tv":2028.27}]}
{"op":"mcm","clk":"4233358227","pt":1631533908923,"mc":[{"id":"1.187557653","rc":[{"batl":[[0,2.26,317.46],[1,2.34,4.27]],"ltp":1.94,"tv":611.42,"id":9632596}]}]}
{"op":"mcm","clk":"4233358658","pt":1631533913525,"mc":[{"id":"1.187557653","rc":[{"batl":[[0,2.12,56.6]],"ltp":2.04,"tv":1416.85,"id":9433864}]}]}
{"op":"mcm","clk":"4233358922","pt":1631533916708,"mc":[{"id":"1.187557653","rc":[{"batl":[[0,2.34,4.27],[1,2.34,0]],"ltp":1.94,"tv":611.42,"id":9632596}]}]}
{"op":"mcm","clk":"4233359162","pt":1631533919933,"mc":[{"id":"1.187557653","rc":[{"batb":[[0,1.92,10.04],[1,1.85,16.22],[2,1.84,8.1]],"batl":[[0,1.96,9.06],[1,2.34,4.27]],"ltp":1.94,"tv":611.42,"id":9632596}]}]}
{"op":"mcm","clk":"4233359330","pt":1631533922027,"mc":[{"id":"1.187557653","rc":[{"batb":[[0,1.75,3.99],[1,1.66,43.01],[2,1.4,148.56]],"ltp":1.94,"tv":611.42,"id":9632596},{"batb":[[0,1.9,51.97],[1,1.82,377.89],[2,1.4,148.56]],"batl":[[0,2.92,242.8],[1,2.92,0]],"ltp":2.04,"tv":1416.85,"id":9433864}]}]}
{"op":"mcm","clk":"4233359593","pt":1631533925234,"mc":[{"id":"1.187557653","rc":[{"batb":[[1,1.67,42.84]],"ltp":1.94,"tv":611.42,"id":9632596}]}]}
{"op":"mcm","clk":"4233360050","pt":1631533931038,"mc":[{"id":"1.187557653","rc":[{"batb":[[1,1.4,148.56],[2,1.3,198.07]],"ltp":2.04,"tv":1416.85,"id":9433864}]}]}
{"op":"mcm","clk":"4233360118","pt":1631533932143,"mc":[{"id":"1.187557653","rc":[{"batb":[[0,1.97,45.68],[1,1.96,22.85],[2,1.95,22.85]],"batl":[[0,2.06,8.93],[1,2.08,103.55]],"ltp":1.94,"tv":611.42,"id":9632596},{"trd":[[1.9,108.2]],"batb":[[0,1.9,46.51]],"batl":[[0,1.98,6.98],[1,1.99,60.3],[2,2.06,109.11]],"ltp":1.9,"tv":1427.77,"id":9433864}],"tv":2039.19}]}
{"op":"mcm","clk":"4233360183","pt":1631533933180,"mc":[{"id":"1.187557653","rc":[{"batl":[[2,2.44,4.1]],"ltp":1.94,"tv":611.42,"id":9632596},{"batb":[[0,1.92,15.62],[1,1.91,7.82],[2,1.9,54.33]],"ltp":1.9,"tv":1427.77,"id":9433864}]}]}
{"op":"mcm","clk":"4233360431","pt":1631533936984,"mc":[{"id":"1.187557653","rc":[{"trd":[[2.02,6.84]],"ltp":2.02,"tv":618.26,"id":9632596},{"trd":[[1.98,18.02]],"batl":[[0,1.99,60.3],[1,2.06,109.11],[2,2.72,264.63]],"ltp":1.98,"tv":1434.75,"id":9433864}],"tv":2053.01}]}
{"op":"mcm","clk":"4233360857","pt":1631533943061,"mc":[{"id":"1.187557653","rc":[{"trd":[[2,7.2],[2.06,17.79]],"batl":[[0,2.06,8.27]],"ltp":2.0,"tv":626.12,"id":9632596},{"trd":[[1.94,30.32],[1.99,7.24]],"batl":[[0,1.99,53.06]],"ltp":1.99,"tv":1442.69,"id":9433864}],"tv":2068.82}]}
{"op":"mcm","clk":"4233361116","pt":1631533946901,"mc":[{"id":"1.187557653","rc":[{"batl":[[0,2.08,103.55],[1,2.44,4.1],[2,2.44,0]],"ltp":2.0,"tv":626.12,"id":9632596}]}]}
{"op":"mcm","clk":"4233361328","pt":1631533949884,"mc":[{"id":"1.187557653","rc":[{"batb":[[0,2,4.61],[1,1.97,45.68],[2,1.96,22.85]],"batl":[[0,2.04,7.23],[1,2.08,103.55],[2,2.44,4.1]],"ltp":2.0,"tv":626.12,"id":9632596},{"batl":[[1,2,4.61],[2,2.06,109.11]],"ltp":1.99,"tv":1442.69,"id":9433864}]}]}
{"op":"mcm","clk":"4233361522","pt":1631533952917,"mc":[{"id":"1.187557653","rc":[{"batb":[[0,1.79,33.39],[1,1.75,3.41],[2,1.5,106.96]],"ltp":2.0,"tv":626.12,"id":9632596},{"batb":[[0,1.81,30.38],[1,1.67,383.76],[2,1.4,148.56]],"batl":[[0,2.72,264.63],[1,2,0],[2,2.06,0]],"ltp":1.99,"tv":1442.69,"id":9433864}]}]}
{"op":"mcm","clk":"4233361735","pt":1631533956198,"mc":[{"id":"1.187557653","rc":[{"batb":[[0,1.8,33.22]],"ltp":2.0,"tv":626.12,"id":9632596}]}]}
{"op":"mcm","clk":"4233362120","pt":1631533961820,"mc":[{"id":"1.187557653","rc":[{"batb":[[0,2.08,8.8],[1,1.8,33.22],[2,1.75,3.41]],"batl":[[0,2.16,91.56]],"ltp":2.0,"tv":626.12,"id":9632596},{"trd":[[1.81,11.24]],"batb":[[0,1.89,8.06],[1,1.81,24.76],[2,1.67,383.76]],"batl":[[0,1.94,61.86],[1,1.95,46.15],[2,1.96,23.08]],"ltp":1.81,"tv":1453.93,"id":9433864}],"tv":2080.06}]}
{"op":"mcm","clk":"4233362210","pt":1631533962914,"mc":[{"id":"1.187557653","rc":[{"batb":[[1,2.02,45.94],[2,1.84,30.88]],"batl":[[1,2.52,3.97]],"ltp":2.0,"tv":626.12,"id":9632596},{"batb":[[1,1.85,16.22],[2,1.84,8.1]],"batl":[[1,1.95,15.38],[2,1.96,7.7]],"ltp":1.81,"tv":1453.93,"id":9433864}]}]}
{"op":"mcm","clk":"4233362468","pt":1631533966743,"mc":[{"id":"1.187557653","rc":[{"trd":[[2.08,17.6]],"batb":[[0,2.02,45.94],[1,1.84,30.88],[2,1.75,3.41]],"ltp":2.08,"tv":643.72,"id":9632596}],"tv":2097.66}]}
{"op":"mcm","clk":"4233363141","pt":1631533976634,"mc":[{"id":"1.187557653","rc":[{"batb":[[0,1.85,16.22],[1,1.84,8.1],[2,1.83,8.1]],"ltp":1.81,"tv":1453.93,"id":9433864}]}]}
{"op":"mcm","clk":"4233363351","pt":1631533979645,"mc":[{"id":"1.187557653","rc":[{"batb":[[0,2.06,7.69],[1,2.02,45.94],[2,1.84,30.88]],"batl":[[0,2.12,14.54],[1,2.16,91.56],[2,2.52,3.97]],"ltp":2.08,"tv":643.72,"id":9632596}]}]}
{"op":"mcm","clk":"4233369390","pt":1631534067893,"mc":[{"id":"1.187557653","rc":[{"batb":[[0,1.84,30.88],[1,1.75,3.41],[2,1.5,106.96]],"ltp":2.08,"tv":643.72,"id":9632596},{"batb":[[0,1.67,383.76],[1,1.64,42.76],[2,1.4,148.56]],"batl":[[0,2.72,264.63],[1,1.95,0],[2,1.96,0]],"ltp":1.81,"tv":1453.93,"id":9433864}]}]}
{"op":"mcm","clk":"4233369754","pt":1631534074484,"mc":[{"id":"1.187557653","rc":[{"batl":[[0,2.6,281.81]],"ltp":1.81,"tv":1453.93,"id":9433864}]}]}
{"op":"mcm","clk":"4233370872","pt":1631534092700,"mc":[{"id":"1.187557653","rc":[{"batb":[[0,1.86,107.19],[1,1.84,30.88],[2,1.75,3.41]],"batl":[[0,1.94,12.96],[1,1.98,15.16],[2,1.99,7.58]],"ltp":2.08,"tv":643.72,"id":9632596},{"batb":[[0,1.97,101.52],[1,1.67,383.76],[2,1.64,42.76]],"batl":[[0,2.12,8.65],[1,2.6,281.81]],"ltp":1.81,"tv":1453.93,"id":9433864}]}]}
{"op":"mcm","clk":"4233370928","pt":1631534093626,"mc":[{"id":"1.187557653","rc":[{"trd":[[1.94,228.29]],"batl":[[0,1.94,7.4]],"ltp":1.94,"tv":649.28,"id":9632596},{"trd":[[2.06,21.26]],"batb":[[0,1.99,45.52],[1,1.97,101.52],[2,1.79,31.46]],"batl":[[1,2.14,14.02],[2,2.16,7]],"ltp":2.06,"tv":1459.17,"id":9433864}],"tv":2108.46}]}
{"op":"mcm","clk":"4233371614","pt":1631534104040,"mc":[{"id":"1.187557653","rc":[{"batl":[[0,1.98,15.16],[1,1.99,7.58],[2,2,7.58]],"ltp":1.94,"tv":649.28,"id":9632596},{"batl":[[0,2.14,14.02],[1,2.16,7],[2,2.18,7]],"ltp":2.06,"tv":1459.17,"id":9433864}]}]}
{"op":"mcm","clk":"4233371766","pt":1631534106415,"mc":[{"id":"1.187557653","rc":[{"batl":[[0,1.94,7.4],[1,1.98,15.16],[2,1.99,7.58]],"ltp":1.94,"tv":649.28,"id":9632596},{"batl":[[0,2.12,13.73],[1,2.14,14.02],[2,2.16,7]],"ltp":2.06,"tv":1459.17,"id":9433864}]}]}
{"op":"mcm","clk":"4233372055","pt":1631534110947,"mc":[{"id":"1.187557653","rc":[{"batb":[[0,1.84,30.88],[1,1.75,3.41],[2,1.7,39.83]],"ltp":1.94,"tv":649.28,"id":9632596},{"batb":[[1,1.79,31.46],[2,1.67,383.76]],"batl":[[0,2.6,281.81],[1,2.14,0],[2,2.16,0]],"ltp":2.06,"tv":1459.17,"id":9433864}]}]}
{"op":"mcm","clk":"4233372110","pt":1631534111367,"mc":[{"id":"1.187557653","rc":[{"batb":[[0,1.75,3.41],[1,1.7,39.83],[2,1.4,148.56]],"ltp":1.94,"tv":649.28,"id":9632596},{"batb":[[0,1.79,31.46],[1,1.67,383.76],[2,1.4,148.56]],"ltp":2.06,"tv":1459.17,"id":9433864}]}]}
{"op":"mcm","clk":"4233373304","pt":1631534128870,"mc":[{"id":"1.187557653","rc":[{"batb":[[1,1.4,148.56],[2,1.3,198.07]],"ltp":2.06,"tv":1459.17,"id":9433864}]}]}
{"op":"mcm","clk":"4233373392","pt":1631534130146,"mc":[{"id":"1.187557653","rc":[{"batb":[[1,1.74,116.71],[2,1.7,39.83]],"batl":[[0,1.83,134.61],[1,1.84,24.59],[2,1.85,24.59]],"ltp":1.94,"tv":649.28,"id":9632596},{"batl":[[0,2.28,6.37]],"ltp":2.06,"tv":1459.17,"id":9433864}]}]}
{"op":"mcm","clk":"4233373466","pt":1631534131088,"mc":[{"id":"1.187557653","rc":[{"trd":[[1.83,38.83]],"batl":[[0,1.83,95.94],[1,1.84,8.2],[2,1.85,8.2]],"ltp":1.83,"tv":655.17,"id":9632596},{"trd":[[2.2,15.23]],"batb":[[0,2.18,34.56],[1,1.99,45.61],[2,1.4,148.56]],"batl":[[1,2.34,12.82],[2,2.36,6.4]],"ltp":2.2,"tv":1464.07,"id":9433864}],"tv":2119.25}]}
{"op":"mcm","clk":"4233373566","pt":1631534132461,"mc":[{"id":"1.187557653","rc":[{"batb":[[2,1.82,377.89]],"ltp":2.2,"tv":1464.07,"id":9433864}]}]}
{"op":"mcm","clk":"4233374258","pt":1631534142072,"mc":[{"id":"1.187557653","rc":[{"batb":[[1,1.6,49.04],[2,1.4,148.56]],"ltp":1.83,"tv":655.17,"id":9632596},{"batb":[[0,1.99,45.61],[1,1.82,377.89],[2,1.4,148.56]],"batl":[[0,3.15,220.27],[1,2.34,0],[2,2.36,0]],"ltp":2.2,"tv":1464.07,"id":9433864}]}]}
{"op":"mcm","clk":"4233374638","pt":1631534147786,"mc":[{"id":"1.187557653","rc":[{"batl":[[0,3,234.38]],"ltp":2.2,"tv":1464.07,"id":9433864}]}]}
{"op":"mcm","clk":"4233375355","pt":1631534160114,"mc":[{"id":"1.187557653","rc":[{"batb":[[0,1.87,106.96],[1,1.75,3.41],[2,1.6,49.04]],"batl":[[0,1.94,7.56],[1,2,67.66]],"ltp":1.83,"tv":655.17,"id":9632596},{"trd":[[1.99,17.72]],"batb":[[0,2,67.66],[1,1.99,40.37],[2,1.82,377.89]],"batl":[[0,2.12,84.34],[1,2.14,35.38],[2,2.16,124.78]],"ltp":1.99,"tv":1474.55,"id":9433864}],"tv":2129.73}]}
{"op":"mcm","clk":"4233375438","pt":1631534161123,"mc":[{"id":"1.187557653","rc":[{"batl":[[1,1.99,75.38],[2,2,105.34]],"ltp":1.83,"tv":655.17,"id":9632596},{"batl":[[0,2.12,27.74],[1,2.14,7.08],[2,2.16,96.48]],"ltp":1.99,"tv":1474.55,"id":9433864}]}]}
{"op":"mcm","clk":"4233375513","pt":1631534162123,"mc":[{"id":"1.187557653","rc":[{"batb":[[1,1.84,30.71],[2,1.75,3.41]],"batl":[[1,1.99,15.08],[2,2,75.2]],"ltp":1.83,"tv":655.17,"id":9632596}]}]}
{"op":"mcm","clk":"4233375711","pt":1631534165130,"mc":[{"id":"1.187557653","rc":[{"batl":[[0,1.91,47.01],[1,1.94,7.56],[2,1.99,15.08]],"ltp":1.83,"tv":655.17,"id":9632596}]}]}
{"op":"mcm","clk":"4233375723","pt":1631534165336,"mc":[{"id":"1.187557653","rc":[{"batl":[[0,1.94,7.56],[1,1.99,15.08],[2,2,75.2]],"ltp":1.83,"tv":655.17,"id":9632596}]}]}
{"op":"mcm","clk":"4233376579","pt":1631534178880,"mc":[{"id":"1.187557653","rc":[{"batb":[[0,1.75,3.41],[1,1.68,41.51],[2,1.4,148.56]],"ltp":1.83,"tv":655.17,"id":9632596},{"batb":[[0,1.82,377.89],[1,1.77,32.8],[2,1.4,148.56]],"batl":[[0,2.82,253.59],[1,2.14,0],[2,2.16,0]],"ltp":1.99,"tv":1474.55,"id":9433864}]}]}
{"op":"mcm","clk":"4233377331","pt":1631534189970,"mc":[{"id":"1.187557653","rc":[{"batb":[[0,1.76,10.96],[1,1.75,3.41],[2,1.72,128.83]],"batl":[[0,1.8,13.25],[1,1.83,103.23],[2,1.92,104.16]],"ltp":1.83,"tv":655.17,"id":9632596},{"batb":[[0,2.22,13.52],[1,2.2,6.76],[2,2.18,6.76]],"ltp":1.99,"tv":1474.55,"id":9433864}]}]}
{"op":"mcm","clk":"4233377394","pt":1631534190918,"mc":[{"id":"1.187557653","rc":[{"trd":[[1.8,30.04]],"batb":[[2,1.73,17.34]],"batl":[[0,1.8,7.21]],"ltp":1.8,"tv":661.21,"id":9632596},{"trd":[[2.24,4.85]],"batb":[[1,2.2,39.81]],"ltp":2.24,"tv":1479.4,"id":9433864}],"tv":2140.62}]}
{"op":"mcm","clk":"4233377624","pt":1631534193703,"mc":[{"id":"1.187557653","rc":[{"batl":[[0,3.15,220.27]],"ltp":2.24,"tv":1479.4,"id":9433864}]}]}
{"op":"mcm","clk":"4233378071","pt":1631534200919,"mc":[{"id":"1.187557653","rc":[{"batb":[[0,1.75,3.41],[1,1.73,17.34],[2,1.72,137.51]],"batl":[[0,1.83,103.23],[1,1.92,104.16],[2,2.12,4.72]],"ltp":1.8,"tv":661.21,"id":9632596}]}]}
{"op":"mcm","clk":"4233378230","pt":1631534203703,"mc":[{"id":"1.187557653","rc":[{"batb":[[0,1.76,17.13],[1,1.75,3.41],[2,1.73,17.34]],"ltp":1.8,"tv":661.21,"id":9632596},{"batb":[[0,2.24,8.8],[1,2.22,13.52],[2,2.2,39.81]],"ltp":2.24,"tv":1479.4,"id":9433864}]}]}
{"op":"mcm","clk":"4233378394","pt":1631534206220,"mc":[{"id":"1.187557653","rc":[{"batb":[[0,1.75,3.41],[1,1.58,51.21],[2,1.4,148.56]],"ltp":1.8,"tv":661.21,"id":9632596},{"batb":[[0,2.02,43.1],[1,1.82,377.89],[2,1.4,148.56]],"ltp":2.24,"tv":1479.4,"id":9433864}]}]}
{"op":"mcm","clk":"4233379481","pt":1631534221623,"mc":[{"id":"1.187557653","rc":[{"batb":[[0,1.76,392.88],[1,1.75,3.41],[2,1.58,51.21]],"batl":[[0,1.96,106.57]],"ltp":1.8,"tv":661.21,"id":9632596},{"trd":[[2.02,10.3]],"batb":[[0,2.08,7.07],[1,2.02,37.95],[2,1.82,377.89]],"batl":[[0,2.12,7.52],[1,2.16,97.22],[2,2.18,20.83]],"ltp":2.02,"tv":1489.7,"id":9433864}],"tv":2150.92}]}
{"op":"mcm","clk":"4233379615","pt":1631534223141,"mc":[{"id":"1.187557653","rc":[{"batb":[[0,1.81,32.47],[1,1.76,392.88],[2,1.75,3.41]],"batl":[[0,1.96,121.87],[1,1.97,7.66],[2,1.98,7.66]],"ltp":1.8,"tv":661.21,"id":9632596},{"batl":[[1,2.16,69.44],[2,2.18,6.94]],"ltp":2.02,"tv":1489.7,"id":9433864}]}]}
{"op":"mcm","clk":"4233379748","pt":1631534225028,"mc":[{"id":"1.187557653","rc":[{"trd":[[2.12,14.58]],"batl":[[0,2.16,69.67],[1,2.18,6.94],[2,2.2,6.94]],"ltp":2.12,"tv":1504.28,"id":9433864}],"tv":2165.5}]}
{"op":"mcm","clk":"4233379831","pt":1631534226435,"mc":[{"id":"1.187557653","rc":[{"trd":[[1.89,0.26]],"ltp":1.89,"tv":661.47,"id":9632596},{"trd":[[2.12,14.81]],"batl":[[0,2.16,69.44]],"ltp":2.12,"tv":1504.51,"id":9433864}],"tv":2165.99}]}
{"op":"mcm","clk":"4233380326","pt":1631534234029,"mc":[{"id":"1.187557653","rc":[{"batb":[[0,1.75,3.41],[1,1.62,47.03],[2,1.4,148.56]],"ltp":1.89,"tv":661.47,"id":9632596},{"batb":[[0,1.82,377.89],[1,1.76,33.72],[2,1.4,148.56]],"batl":[[0,2.92,242.8],[1,880,0.01],[2,2.2,0]],"ltp":2.12,"tv":1504.51,"id":9433864}]}]}
{"op":"mcm","clk":"4233380553","pt":1631534237247,"mc":[{"id":"1.187557653","rc":[{"batb":[[1,1.75,33.81]],"ltp":2.12,"tv":1504.51,"id":9433864}]}]}
{"op":"mcm","clk":"4233380878","pt":1631534241968,"mc":[{"id":"1.187557653","rc":[{"batb":[[2,1.19,1]],"ltp":2.12,"tv":1504.51,"id":9433864}]}]}
{"op":"mcm","clk":"4233382492","pt":1631534267073,"mc":[{"id":"1.187557653","rc":[{"batb":[[0,1.75,33.81],[1,1.19,1],[2,1.03,494.08]],"batl":[[0,880,0.01],[1,880,0]],"ltp":2.12,"tv":1504.51,"id":9433864}]}]}
{"op":"mcm","clk":"4233382560","pt":1631534268112,"mc":[{"id":"1.187557653","rc":[{"trd":[[1.75,6.82]],"batb":[[0,1.62,47.03],[1,1.6,33.89]],"batl":[[0,1.74,8.42],[1,1.78,137.22],[2,1.79,42.14]],"ltp":1.75,"tv":668.29,"id":9632596},{"batl":[[0,2.4,6.28],[1,2.5,115.07],[2,880,0.01]],"ltp":2.12,"tv":1504.51,"id":9433864}],"tv":2172.8}]}
{"op":"mcm","clk":"4233382609","pt":1631534269206,"mc":[{"id":"1.187557653","rc":[{"trd":[[1.74,6.28]],"batb":[[2,1.53,58.49]],"batl":[[0,1.74,2.14],[1,1.78,103.51],[2,1.79,25.28]],"ltp":1.74,"tv":674.57,"id":9632596},{"trd":[[2.34,4.67]],"batb":[[0,2.32,28.79],[1,2.18,34.06],[2,1.19,1]],"batl":[[1,2.44,12.3],[2,2.46,6.14]],"ltp":2.34,"tv":1509.18,"id":9433864}],"tv":2183.75}]}
{"op":"mcm","clk":"4233382650","pt":1631534270201,"mc":[{"id":"1.187557653","rc":[{"batb":[[2,1.75,3061.22]],"ltp":2.34,"tv":1509.18,"id":9433864}]}]}
{"op":"mcm","clk":"4233382696","pt":1631534271088,"mc":[{"id":"1.187557653","rc":[{"batb":[[2,1.92,373.16]],"ltp":2.34,"tv":1509.18,"id":9433864}]}]}
{"op":"mcm","clk":"4233382906","pt":1631534274220,"mc":[{"id":"1.187557653","rc":[{"batb":[[0,1.63,77.02],[1,1.62,47.03],[2,1.6,33.89]],"ltp":1.74,"tv":674.57,"id":9632596}]}]}
{"op":"mcm","clk":"4233383186","pt":1631534279134,"mc":[{"id":"1.187557653","rc":[{"batl":[[0,1.78,103.51],[1,1.79,25.28],[2,1.8,189.3]],"ltp":1.74,"tv":674.57,"id":9632596},{"batl":[[0,2.44,12.3],[1,2.46,6.14],[2,2.48,6.14]],"ltp":2.34,"tv":1509.18,"id":9433864}]}]}
{"op":"mcm","clk":"4233383207","pt":1631534279608,"mc":[{"id":"1.187557653","rc":[{"batb":[[0,1.62,47.03],[1,1.6,33.89],[2,1.53,58.49]],"ltp":1.74,"tv":674.57,"id":9632596}]}]}
{"op":"mcm","clk":"4233383378","pt":1631534281997,"mc":[{"id":"1.187557653","rc":[{"batb":[[0,1.72,11.22],[1,1.62,47.03],[2,1.6,33.89]],"ltp":1.74,"tv":674.57,"id":9632596},{"batb":[[0,2.32,38.86]],"ltp":2.34,"tv":1509.18,"id":9433864}]}]}
{"op":"mcm","clk":"4233383522","pt":1631534284210,"mc":[{"id":"1.187557653","rc":[{"batb":[[1,1.62,46.86]],"ltp":1.74,"tv":674.57,"id":9632596},{"trd":[[2.32,2.76]],"batb":[[0,2.32,37.48]],"ltp":2.32,"tv":1511.94,"id":9433864}],"tv":2186.51}]}
{"op":"mcm","clk":"4233383881","pt":1631534289819,"mc":[{"id":"1.187557653","rc":[{"trd":[[1.72,11.22]],"batb":[[0,1.62,46.86],[1,1.6,33.89],[2,1.53,58.49]],"ltp":1.72,"tv":685.79,"id":9632596},{"trd":[[2.4,8.04],[2.44,24.6],[2.46,9.32]],"batl":[[0,2.46,1.48],[1,2.48,6.14],[2,2.5,115.07]],"ltp":2.46,"tv":1553.9,"id":9433864}],"tv":2239.69}]}
{"op":"mcm","clk":"4233384093","pt":1631534293232,"mc":[{"id":"1.187557653","rc":[{"trd":[[1.76,25]],"ltp":1.76,"tv":710.79,"id":9632596},{"trd":[[2.32,21.72]],"batb":[[0,2.32,18.51]],"ltp":2.32,"tv":1572.86,"id":9433864}],"tv":2283.66}]}
{"op":"mcm","clk":"4233384344","pt":1631534297134,"mc":[{"id":"1.187557653","rc":[{"trd":[[1.68,2.02]],"batb":[[0,1.63,46.36],[1,1.62,35.7],[2,1.6,33.89]],"ltp":1.68,"tv":712.81,"id":9632596},{"trd":[[2.46,10.7]],"batb":[[0,2.32,10.07],[1,2.3,29.2],[2,2.18,34.06]],"batl":[[0,2.48,6.24],[1,2.5,115.07],[2,3.45,198.52]],"ltp":2.46,"tv":1574.24,"id":9433864}],"tv":2287.05}]}
{"op":"mcm","clk":"4233384493","pt":1631534299926,"mc":[{"id":"1.187557653","rc":[{"batb":[[0,2.3,29.2],[1,2.18,34.06],[2,1.92,373.16]],"ltp":2.46,"tv":1574.24,"id":9433864}]}]}
{"op":"mcm","clk":"4233384679","pt":1631534303253,"mc":[{"id":"1.187557653","rc":[{"batb":[[1,1.6,33.89],[2,1.53,57.74]],"ltp":1.68,"tv":712.81,"id":9632596},{"batb":[[0,2.36,7.49],[1,2.3,29.2],[2,2.18,34.06]],"batl":[[0,2.42,7.72],[1,2.48,6.24],[2,2.5,115.07]],"ltp":2.46,"tv":1574.24,"id":9433864}]}]}
{"op":"mcm","clk":"4233384984","pt":1631534307670,"mc":[{"id":"1.187557653","rc":[{"batl":[[0,1.72,2.56],[1,1.78,103.51],[2,1.79,25.28]],"ltp":1.68,"tv":712.81,"id":9632596}]}]}
{"op":"mcm","clk":"4233385073","pt":1631534309247,"mc":[{"id":"1.187557653","rc":[{"batb":[[0,1.64,918.78],[1,1.63,46.36],[2,1.6,33.89]],"ltp":1.68,"tv":712.81,"id":9632596}]}]}
{"op":"mcm","clk":"4233385083","pt":1631534309484,"mc":[{"id":"1.187557653","rc":[{"batb":[[1,1.63,46.02]],"ltp":1.68,"tv":712.81,"id":9632596},{"batb":[[2,2.16,34.81]],"ltp":2.46,"tv":1574.24,"id":9433864}]}]}
{"op":"mcm","clk":"4233385175","pt":1631534310854,"mc":[{"id":"1.187557653","rc":[{"trd":[[1.7,10.99]],"batb":[[0,1.63,46.02],[1,1.6,33.89],[2,1.54,57.4]],"batl":[[0,1.7,10.31],[1,1.72,2.56],[2,1.78,103.51]],"ltp":1.7,"tv":723.79,"id":9632596},{"trd":[[2.42,7.72]],"batl":[[0,2.48,6.24],[1,2.5,115.07],[2,3.45,198.52]],"ltp":2.42,"tv":1581.96,"id":9433864}],"tv":2305.76}]}
{"op":"mcm","clk":"4233385429","pt":1631534314577,"mc":[{"id":"1.187557653","rc":[{"batb":[[2,1.54,57.24]],"ltp":1.7,"tv":723.79,"id":9632596}]}]}
{"op":"mcm","clk":"4233385509","pt":1631534315892,"mc":[{"id":"1.187557653","rc":[{"batl":[[1,1.78,103.51],[2,1.79,25.28]],"ltp":1.7,"tv":723.79,"id":9632596}]}]}
{"op":"mcm","clk":"4233385829","pt":1631534320755,"mc":[{"id":"1.187557653","rc":[{"batb":[[0,2.3,29.2],[1,2.16,34.81],[2,1.92,373.16]],"ltp":2.42,"tv":1581.96,"id":9433864}]}]}
{"op":"mcm","clk":"4233385993","pt":1631534322375,"mc":[{"id":"1.187557653","rc":[{"batb":[[0,1.63,45.86]],"ltp":1.7,"tv":723.79,"id":9632596}]}]}
{"op":"mcm","clk":"4233386074","pt":1631534323789,"mc":[{"id":"1.187557653","rc":[{"batl":[[0,1.69,2.56],[1,1.7,10.31],[2,1.72,10.87]],"ltp":1.7,"tv":723.79,"id":9632596},{"batl":[[0,2.46,9.67],[1,2.48,6.14],[2,2.5,115.07]],"ltp":2.42,"tv":1581.96,"id":9433864}]}]}
{"op":"mcm","clk":"4233386197","pt":1631534325786,"mc":[{"id":"1.187557653","rc":[{"trd":[[1.68,13.26]],"ltp":1.68,"tv":735.04,"id":9632596},{"trd":[[2.46,18.38]],"batl":[[0,2.46,1.99]],"ltp":2.46,"tv":1589.64,"id":9433864}],"tv":2324.69}]}
{"op":"mcm","clk":"4233386639","pt":1631534332909,"mc":[{"id":"1.187557653","rc":[{"batl":[[1,1.72,10.87],[2,1.78,103.51]],"ltp":1.68,"tv":735.04,"id":9632596}]}]}
{"op":"mcm","clk":"4233386872","pt":1631534335997,"mc":[{"id":"1.187557653","rc":[{"trd":[[1.67,7.39],[1.68,16.18]],"batl":[[1,1.78,103.51],[2,1.79,25.28]],"ltp":1.67,"tv":745.34,"id":9632596},{"trd":[[2.46,20.37],[2.48,4.98]],"batl":[[0,2.48,1.16],[1,2.5,115.07],[2,3.45,198.52]],"ltp":2.48,"tv":1596.61,"id":9433864}],"tv":2341.96}]}
{"op":"mcm","clk":"4233386993","pt":1631534337819,"mc":[{"id":"1.187557653","rc":[{"batl":[[0,1.78,103.51],[1,1.79,25.28],[2,1.8,189.3]],"ltp":1.67,"tv":745.34,"id":9632596}]}]}
{"op":"mcm","clk":"4233387064","pt":1631534338872,"mc":[{"id":"1.187557653","rc":[{"batb":[[0,2.42,7.71],[1,2.3,29.2],[2,2.16,34.81]],"batl":[[1,2.5,126.24]],"ltp":2.48,"tv":1596.61,"id":9433864}]}]}
{"op":"mcm","clk":"4233387218","pt":1631534340872,"mc":[{"id":"1.187557653","rc":[{"batl":[[0,1.68,2.56],[1,1.78,103.51],[2,1.79,25.28]],"ltp":1.67,"tv":745.34,"id":9632596}]}]}
{"op":"mcm","clk":"4233387622","pt":1631534346232,"mc":[{"id":"1.187557653","rc":[{"batb":[[0,2.3,29.2],[1,2.16,34.81],[2,1.92,373.16]],"batl":[[1,2.5,115.07]],"ltp":2.48,"tv":1596.61,"id":9433864}]}]}
{"op":"mcm","clk":"4233387811","pt":1631534349122,"mc":[{"id":"1.187557653","rc":[{"batl":[[1,1.7,10.86],[2,1.78,103.51]],"ltp":1.67,"tv":745.34,"id":9632596},{"batl":[[1,2.5,124.29]],"ltp":2.48,"tv":1596.61,"id":9433864}]}]}
{"op":"mcm","clk":"4233387891","pt":1631534350328,"mc":[{"id":"1.187557653","rc":[{"batl":[[0,1.7,10.86],[1,1.78,103.51],[2,1.79,25.28]],"ltp":1.67,"tv":745.34,"id":9632596}]}]}
{"op":"mcm","clk":"4233388311","pt":1631534356445,"mc":[{"id":"1.187557653","rc":[{"trd":[[1.67,9.11]],"batl":[[0,1.7,11.69]],"ltp":1.67,"tv":747.07,"id":9632596},{"trd":[[2.48,6.14]],"batl":[[0,2.5,124.29],[1,3.45,198.52],[2,990,0.01]],"ltp":2.48,"tv":1597.77,"id":9433864}],"tv":2344.84}]}
{"op":"mcm","clk":"4233389131","pt":1631534367629,"mc":[{"id":"1.187557653","rc":[{"batl":[[0,1.7,10.86]],"ltp":1.67,"tv":747.07,"id":9632596}]}]}
{"op":"mcm","clk":"4233389363","pt":1631534370742,"mc":[{"id":"1.187557653","rc":[{"trd":[[1.66,0.83]],"ltp":1.66,"tv":747.9,"id":9632596},{"trd":[[2.5,0.55]],"batl":[[0,2.5,123.74]],"ltp":2.5,"tv":1598.32,"id":9433864}],"tv":2346.23}]}
{"op":"mcm","clk":"4233391426","pt":1631534398696,"mc":[{"id":"1.187557653","rc":[{"trd":[[1.7,14.01]],"batl":[[0,1.7,9.35]],"ltp":1.7,"tv":750.92,"id":9632596}],"tv":2349.25}]}
{"op":"mcm","clk":"4233391482","pt":1631534399392,"mc":[{"id":"1.187557653","rc":[{"batl":[[1,990,0.01],[2,990,0]],"ltp":2.5,"tv":1598.32,"id":9433864}]}]}
{"op":"mcm","clk":"4233391613","pt":1631534400989,"mc":[{"id":"1.187557653","rc":[{"trd":[[1.7,17.53]],"batl":[[0,1.7,7.59]],"ltp":1.7,"tv":754.44,"id":9632596}],"tv":2352.77}]}
{"op":"mcm","clk":"4233391723","pt":1631534402099,"mc":[{"id":"1.187557653","rc":[{"batb":[[2,1.19,1]],"ltp":2.5,"tv":1598.32,"id":9433864}]}]}
{"op":"mcm","clk":"4233391930","pt":1631534404323,"mc":[{"id":"1.187557653","rc":[{"batl":[[1,3,234.38],[2,990,0.01]],"ltp":2.5,"tv":1598.32,"id":9433864}]}]}
{"op":"mcm","clk":"4233392019","pt":1631534405322,"mc":[{"id":"1.187557653","rc":[{"batb":[[2,1.77,378.13]],"ltp":2.5,"tv":1598.32,"id":9433864}]}]}
{"op":"mcm","clk":"4233392248","pt":1631534408024,"mc":[{"id":"1.187557653","rc":[{"batb":[[0,1.54,57.24],[1,1.01,113.7],[2,1.54,0]],"batl":[[0,990,0.01],[1,1.78,0],[2,1.79,0]],"ltp":1.7,"tv":754.44,"id":9632596},{"batb":[[0,2.16,34.81],[1,1.77,378.13],[2,1.19,1]],"batl":[[0,3,234.38],[1,990,0.01],[2,990,0]],"ltp":2.5,"tv":1598.32,"id":9433864}]}]}
{"op":"mcm","clk":"4233393378","pt":1631534420959,"mc":[{"id":"1.187557653","rc":[{"batb":[[0,1.76,112.57],[1,1.74,16.81],[2,1.66,32.67]],"batl":[[0,1.78,8.72],[1,1.86,123.34],[2,990,0.01]],"ltp":1.7,"tv":754.44,"id":9632596},{"trd":[[2.16,15.01]],"batb":[[0,2.16,29.91]],"batl":[[0,2.38,50.42],[1,2.4,37.5],[2,2.42,18.74]],"ltp":2.16,"tv":1608.13,"id":9433864}],"tv":2362.57}]}
{"op":"mcm","clk":"4233393477","pt":1631534422064,"mc":[{"id":"1.187557653","rc":[{"batb":[[2,1.71,39.41]],"batl":[[1,1.83,16.4],[2,1.84,8.2]],"ltp":1.7,"tv":754.44,"id":9632596},{"batb":[[1,2.06,40.25],[2,1.77,378.13]],"batl":[[1,2.4,12.5],[2,2.42,6.24]],"ltp":2.16,"tv":1608.13,"id":9433864}]}]}
{"op":"mcm","clk":"4233394447","pt":1631534433660,"mc":[{"id":"1.187557653","rc":[{"batl":[[0,2.3,2.56],[1,2.38,50.42],[2,2.4,12.5]],"ltp":2.16,"tv":1608.13,"id":9433864}]}]}
{"op":"mcm","clk":"4233394895","pt":1631534439079,"mc":[{"id":"1.187557653","rc":[{"batb":[[0,1.71,39.41],[1,1.66,32.67],[2,1.62,47.53]],"batl":[[0,1.86,29.15],[1,990,0.01],[2,1.84,0]],"ltp":1.7,"tv":754.44,"id":9632596},{"batl":[[1,3,234.38],[2,990,0.01]],"ltp":2.16,"tv":1608.13,"id":9433864}]}]}
{"op":"mcm","clk":"4233394934","pt":1631534439456,"mc":[{"id":"1.187557653","rc":[{"batb":[[0,1.62,47.53],[1,1.01,113.7],[2,1.62,0]],"batl":[[0,990,0.01],[1,990,0]],"ltp":1.7,"tv":754.44,"id":9632596},{"batb":[[0,2.06,40.25],[1,1.77,378.13],[2,1.19,1]],"ltp":2.16,"tv":1608.13,"id":9433864}]}]}
{"op":"mcm","clk":"4233395272","pt":1631534443279,"mc":[{"id":"1.187557653","rc":[{"batb":[[0,1.61,47.78]],"ltp":1.7,"tv":754.44,"id":9632596}]}]}
{"op":"mcm","clk":"4233395706","pt":1631534448200,"mc":[{"id":"1.187557653","rc":[{"batb":[[0,1.84,108.7],[1,1.8,83.32],[2,1.79,41.66]],"batl":[[0,1.86,12.41],[1,1.94,94.61],[2,990,0.01]],"ltp":1.7,"tv":754.44,"id":9632596},{"trd":[[2.06,31.42]],"batb":[[0,2.06,35.17]],"batl":[[0,2.2,85.61],[1,2.24,14.1]],"ltp":2.06,"tv":1618.29,"id":9433864}],"tv":2372.73}]}
{"op":"mcm","clk":"4233395784","pt":1631534449201,"mc":[{"id":"1.187557653","rc":[{"batb":[[0,1.84,65.22],[1,1.8,49.99],[2,1.79,25]],"batl":[[1,1.89,79.36],[2,1.9,39.68]],"ltp":1.7,"tv":754.44,"id":9632596},{"batb":[[1,1.98,45.86],[2,1.77,378.13]],"ltp":2.06,"tv":1618.29,"id":9433864}]}]}
{"op":"mcm","clk":"4233395817","pt":1631534449614,"mc":[{"id":"1.187557653","rc":[{"batb":[[1,1.8,16.66],[2,1.79,8.34]],"batl":[[1,1.89,15.88],[2,1.9,7.94]],"ltp":1.7,"tv":754.44,"id":9632596}]}]}
{"op":"mcm","clk":"4233395973","pt":1631534451192,"mc":[{"id":"1.187557653","rc":[{"batl":[[2,2.72,264.63]],"ltp":2.06,"tv":1618.29,"id":9433864}]}]}
{"op":"mcm","clk":"4233396179","pt":1631534453191,"mc":[{"id":"1.187557653","rc":[{"trd":[[1.84,82.9]],"batb":[[0,1.84,23.77]],"ltp":1.84,"tv":837.34,"id":9632596},{"batl":[[2,2.28,46.11]],"ltp":2.06,"tv":1618.29,"id":9433864}],"tv":2455.63}]}
{"op":"mcm","clk":"4233396190","pt":1631534453400,"mc":[{"id":"1.187557653","rc":[{"batl":[[2,2.72,264.63]],"ltp":2.06,"tv":1618.29,"id":9433864}]}]}
{"op":"mcm","clk":"4233396468","pt":1631534456381,"mc":[{"id":"1.187557653","rc":[{"batb":[[0,2.06,118.66]],"ltp":2.06,"tv":1618.29,"id":9433864}]}]}
{"op":"mcm","clk":"4233397055","pt":1631534464239,"mc":[{"id":"1.187557653","rc":[{"batb":[[0,1.78,34.23],[1,1.72,31.52],[2,1.7,40.17]],"batl":[[1,1.92,28.24],[2,1.94,94.61]],"ltp":1.84,"tv":837.34,"id":9632596}]}]}
{"op":"mcm","clk":"4233397088","pt":1631534464608,"mc":[{"id":"1.187557653","rc":[{"batb":[[0,1.7,40],[1,1.01,113.7],[2,1.7,0]],"batl":[[0,990,0.01],[1,1.92,0],[2,1.94,0]],"ltp":1.84,"tv":837.34,"id":9632596},{"batb":[[0,1.98,45.86],[1,1.77,378.13],[2,1.19,1]],"batl":[[0,2.72,264.63],[1,990,0.01],[2,2.72,0]],"ltp":2.06,"tv":1618.29,"id":9433864}]}]}
{"op":"mcm","clk":"4233399047","pt":1631534487073,"mc":[{"id":"1.187557653","rc":[{"batb":[[0,1.74,166.54],[1,1.7,40],[2,1.65,32.86]],"batl":[[0,1.78,14.62],[1,1.84,65.22],[2,1.85,29.31]],"ltp":1.84,"tv":837.34,"id":9632596},{"batb":[[0,2.24,40.18],[1,2.22,20.09],[2,2.2,20.09]],"ltp":2.06,"tv":1618.29,"id":9433864}]}]}
{"op":"mcm","clk":"4233399116","pt":1631534487965,"mc":[{"id":"1.187557653","rc":[{"trd":[[1.78,12.55]],"batl":[[0,1.78,8.41]],"ltp":1.78,"tv":843.55,"id":9632596},{"trd":[[2.28,9.8]],"batl":[[0,2.38,12.6],[1,2.4,6.3],[2,2.42,6.3]],"ltp":2.28,"tv":1623.14,"id":9433864}],"tv":2466.69}]}
{"op":"mcm","clk":"4233399946","pt":1631534497792,"mc":[{"id":"1.187557653","rc":[{"batb":[[0,1.74,155.81]],"batl":[[0,1.84,65.22],[1,1.85,29.31],[2,1.86,128.12]],"ltp":1.78,"tv":843.55,"id":9632596}]}]}
{"op":"mcm","clk":"4233400183","pt":1631534500699,"mc":[{"id":"1.187557653","rc":[{"batb":[[0,1.74,172.89]],"batl":[[0,1.78,8.41],[1,1.84,65.22],[2,1.85,29.31]],"ltp":1.78,"tv":843.55,"id":9632596}]}]}
{"op":"mcm","clk":"4233401087","pt":1631534511921,"mc":[{"id":"1.187557653","rc":[{"batb":[[0,1.6,49.29],[1,1.01,113.7],[2,1.65,0]],"batl":[[0,990,0.01],[1,1.84,0],[2,1.85,0]],"ltp":1.78,"tv":843.55,"id":9632596},{"batb":[[0,2.06,40.92],[1,1.77,378.13],[2,1.19,1]],"batl":[[0,2.72,264.63],[1,990,0.01],[2,2.42,0]],"ltp":2.28,"tv":1623.14,"id":9433864}]}]}
{"op":"mcm","clk":"4233402083","pt":1631534522140,"mc":[{"id":"1.187557653","rc":[{"batb":[[0,1.77,113],[1,1.74,449.37],[2,1.6,49.29]],"batl":[[0,1.94,94.51],[1,990,0.01]],"ltp":1.78,"tv":843.55,"id":9632596},{"trd":[[2.06,41.59]],"batb":[[0,2.16,6.85],[1,2.06,35.84],[2,1.77,378.13]],"batl":[[0,2.2,6.35],[1,2.26,66.36],[2,2.28,33.18]],"ltp":2.06,"tv":1633.3,"id":9433864}],"tv":2476.86}]}
{"op":"mcm","clk":"4233402192","pt":1631534523235,"mc":[{"id":"1.187557653","rc":[{"batb":[[0,1.78,34.06],[1,1.77,67.8],[2,1.74,449.37]],"batl":[[0,1.88,79.8],[1,1.89,39.9],[2,1.9,39.9]],"ltp":1.78,"tv":843.55,"id":9632596},{"batb":[[2,1.98,45.86]],"batl":[[1,2.26,39.82],[2,2.28,19.91]],"ltp":2.06,"tv":1633.3,"id":9433864}]}]}
{"op":"mcm","clk":"4233402211","pt":1631534523450,"mc":[{"id":"1.187557653","rc":[{"batl":[[0,1.88,15.96],[1,1.89,7.98],[2,1.9,7.98]],"ltp":1.78,"tv":843.55,"id":9632596},{"batl":[[1,2.26,13.28],[2,2.28,6.64]],"ltp":2.06,"tv":1633.3,"id":9433864}]}]}
{"op":"mcm","clk":"4233402579","pt":1631534527163,"mc":[{"id":"1.187557653","rc":[{"batl":[[0,1.85,39.79],[1,1.88,15.96],[2,1.89,7.98]],"ltp":1.78,"tv":843.55,"id":9632596},{"batl":[[2,2.28,66.91]],"ltp":2.06,"tv":1633.3,"id":9433864}]}]}
{"op":"mcm","clk":"4233402594","pt":1631534527336,"mc":[{"id":"1.187557653","rc":[{"batl":[[0,1.88,15.96],[1,1.89,7.98],[2,1.9,7.98]],"ltp":1.78,"tv":843.55,"id":9632596},{"batl":[[2,2.28,6.64]],"ltp":2.06,"tv":1633.3,"id":9433864}]}]}
{"op":"mcm","clk":"4233403831","pt":1631534541272,"mc":[{"id":"1.187557653","rc":[{"batb":[[1,1.72,31.52],[2,1.7,39.83]],"batl":[[0,1.93,28.09],[1,990,0.01],[2,1.9,0]],"ltp":1.78,"tv":843.55,"id":9632596},{"batb":[[0,2.06,35.84],[1,1.98,45.86],[2,1.77,378.13]],"batl":[[0,2.72,264.63],[1,990,0.01],[2,2.28,0]],"ltp":2.06,"tv":1633.3,"id":9433864}]}]}
{"op":"mcm","clk":"4233403872","pt":1631534541683,"mc":[{"id":"1.187557653","rc":[{"batb":[[0,1.7,39.83],[1,1.01,113.7],[2,1.7,0]],"batl":[[0,990,0.01],[1,990,0]],"ltp":1.78,"tv":843.55,"id":9632596},{"batb":[[0,1.98,45.86],[1,1.77,378.13],[2,1.19,1]],"ltp":2.06,"tv":1633.3,"id":9433864}]}]}
{"op":"mcm","clk":"4233404460","pt":1631534548003,"mc":[{"id":"1.187557653","rc":[{"batb":[[0,1.76,91.77],[1,1.74,19.26],[2,1.7,39.83]],"batl":[[0,1.8,18.11],[1,1.85,29.31],[2,1.86,138.83]],"ltp":1.78,"tv":843.55,"id":9632596},{"batb":[[0,2.24,66.96],[1,2.22,33.48],[2,2.2,33.48]],"ltp":2.06,"tv":1633.3,"id":9433864}]}]}
{"op":"mcm","clk":"4233404561","pt":1631534549101,"mc":[{"id":"1.187557653","rc":[{"trd":[[2.24,14.55]],"batb":[[0,2.24,35.33],[1,2.22,20.09],[2,2.2,20.09]],"batl":[[0,2.38,37.82],[1,2.4,18.91],[2,2.42,18.91]],"ltp":2.24,"tv":1643.0,"id":9433864}],"tv":2486.56}]}
{"op":"mcm","clk":"4233404595","pt":1631534549476,"mc":[{"id":"1.187557653","rc":[{"batb":[[0,2.24,8.55],[1,2.22,6.7],[2,2.2,6.7]],"batl":[[0,2.38,12.6],[1,2.4,6.3],[2,2.42,6.3]],"ltp":2.24,"tv":1643.0,"id":9433864}]}]}
{"op":"mcm","clk":"4233406192","pt":1631534568117,"mc":[{"id":"1.187557653","rc":[{"batb":[[0,1.59,50.12],[1,1.01,113.7],[2,1.7,0]],"batl":[[0,990,0.01],[1,1.85,0],[2,1.86,0]],"ltp":1.78,"tv":843.55,"id":9632596},{"batb":[[0,2.02,42.34],[1,1.77,378.13],[2,1.19,1]],"batl":[[0,2.72,264.63],[1,990,0.01],[2,2.42,0]],"ltp":2.24,"tv":1643.0,"id":9433864}]}]}
{"op":"mcm","clk":"4233406438","pt":1631534571081,"mc":[{"id":"1.187557653","rc":[{"batl":[[0,2.62,99.82],[1,2.72,264.63],[2,990,0.01]],"ltp":2.24,"tv":1643.0,"id":9433864}]}]}
{"op":"mcm","clk":"4233406458","pt":1631534571471,"mc":[{"id":"1.187557653","rc":[{"batl":[[0,2.72,264.63],[1,990,0.01],[2,990,0]],"ltp":2.24,"tv":1643.0,"id":9433864}]}]}
{"op":"mcm","clk":"4233407022","pt":1631534576236,"mc":[{"id":"1.187557653","rc":[{"batb":[[1,1.56,34.75],[2,1.01,113.7]],"batl":[[0,1.66,10],[1,1.67,119.76],[2,1.73,31.34]],"ltp":1.78,"tv":843.55,"id":9632596},{"batb":[[0,2.44,61.48],[1,2.42,30.74],[2,2.4,30.74]],"batl":[[0,2.6,103.31]],"ltp":2.24,"tv":1643.0,"id":9433864}]}]}
{"op":"mcm","clk":"4233407122","pt":1631534577229,"mc":[{"id":"1.187557653","rc":[{"trd":[[1.66,7.61]],"batb":[[2,1.47,68.12]],"batl":[[0,1.66,3.22],[1,1.67,71.86]],"ltp":1.66,"tv":850.33,"id":9632596},{"trd":[[2.5,5.05]],"batb":[[0,2.44,36.89],[1,2.42,18.44],[2,2.4,18.44]],"batl":[[0,2.6,160.99],[1,2.62,28.84],[2,2.64,28.84]],"ltp":2.5,"tv":1647.5,"id":9433864}],"tv":2497.84}]}
{"op":"mcm","clk":"4233407151","pt":1631534577547,"mc":[{"id":"1.187557653","rc":[{"batl":[[0,2.6,114.85],[1,2.62,5.76],[2,2.64,5.76]],"ltp":2.5,"tv":1647.5,"id":9433864}]}]}
{"op":"mcm","clk":"4233408113","pt":1631534587269,"mc":[{"id":"1.187557653","rc":[{"batl":[[0,1.67,71.86],[1,1.73,31.34],[2,1.98,5.05]],"ltp":1.66,"tv":850.33,"id":9632596},{"batl":[[0,2.6,103.46]],"ltp":2.5,"tv":1647.5,"id":9433864}]}]}
{"op":"mcm","clk":"4233408419","pt":1631534590152,"mc":[{"id":"1.187557653","rc":[{"batb":[[0,2.5,5.53],[1,2.44,36.89],[2,2.42,18.44]],"batl":[[0,2.56,7.54],[1,2.6,103.46],[2,2.62,5.76]],"ltp":2.5,"tv":1647.5,"id":9433864}]}]}
{"op":"mcm","clk":"4233408741","pt":1631534593268,"mc":[{"id":"1.187557653","rc":[{"batb":[[0,1.66,20],[1,1.59,50.12],[2,1.56,34.75]],"ltp":1.66,"tv":850.33,"id":9632596}]}]}
{"op":"mcm","clk":"4233408947","pt":1631534595274,"mc":[{"id":"1.187557653","rc":[{"batl":[[0,1.73,31.34],[1,990,0.01],[2,1.98,0]],"ltp":1.66,"tv":850.33,"id":9632596},{"batb":[[0,2.38,26.69],[1,2.18,34.14],[2,1.77,378.13]],"batl":[[0,3.15,220.27],[1,990,0.01],[2,2.62,0]],"ltp":2.5,"tv":1647.5,"id":9433864}]}]}
{"op":"mcm","clk":"4233409000","pt":1631534595793,"mc":[{"id":"1.187557653","rc":[{"batb":[[1,1.47,68.12],[2,1.01,113.7]],"batl":[[0,990,0.01],[1,990,0]],"ltp":1.66,"tv":850.33,"id":9632596},{"batb":[[0,2.18,34.14],[1,1.77,378.13],[2,1.19,1]],"ltp":2.5,"tv":1647.5,"id":9433864}]}]}
{"op":"mcm","clk":"4233409523","pt":1631534602059,"mc":[{"id":"1.187557653","rc":[{"batl":[[0,990,0.01],[1,990,0]],"ltp":2.5,"tv":1647.5,"id":9433864}]}]}
{"op":"mcm","clk":"4233409629","pt":1631534603276,"mc":[{"id":"1.187557653","rc":[{"batb":[[0,1.74,18.6],[1,1.66,20],[2,1.47,68.12]],"batl":[[0,1.8,18.65],[1,1.86,143.1],[2,990,0.01]],"ltp":1.66,"tv":850.33,"id":9632596},{"trd":[[2.18,9.7]],"batb":[[0,2.18,29.29]],"batl":[[0,2.32,86.2],[1,2.36,1288.86],[2,2.38,63.04]],"ltp":2.18,"tv":1657.2,"id":9433864}],"tv":2507.54}]}
{"op":"mcm","clk":"4233409742","pt":1631534604279,"mc":[{"id":"1.187557653","rc":[{"batb":[[1,1.7,40.25],[2,1.66,20]],"batl":[[1,1.81,82.88],[2,1.82,41.44]],"ltp":1.66,"tv":850.33,"id":9632596},{"batb":[[1,2.04,41.17],[2,1.77,378.13]],"batl":[[0,2.32,51.72],[1,2.38,37.82],[2,2.4,18.91]],"ltp":2.18,"tv":1657.2,"id":9433864}]}]}
{"op":"mcm","clk":"4233409832","pt":1631534605165,"mc":[{"id":"1.187557653","rc":[{"batl":[[1,1.81,16.58],[2,1.82,8.28]],"ltp":1.66,"tv":850.33,"id":9632596},{"batl":[[1,2.38,12.6],[2,2.4,6.3]],"ltp":2.18,"tv":1657.2,"id":9433864}]}]}
{"op":"mcm","clk":"4233410517","pt":1631534612284,"mc":[{"id":"1.187557653","rc":[{"batb":[[2,1.65,32.86]],"ltp":1.66,"tv":850.33,"id":9632596}]}]}
{"op":"mcm","clk":"4233410921","pt":1631534616416,"mc":[{"id":"1.187557653","rc":[{"trd":[[1.8,48.69],[1.81,6.14]],"batl":[[0,1.81,10.44],[1,1.82,8.28],[2,1.83,8.28]],"ltp":1.81,"tv":875.12,"id":9632596},{"trd":[[2.22,5.01],[2.24,29.54]],"ltp":2.22,"tv":1677.2,"id":9433864}],"tv":2552.33}]}
{"op":"mcm","clk":"4233411894","pt":1631534626026,"mc":[{"id":"1.187557653","rc":[{"batb":[[0,1.58,51.13],[1,1.01,113.7],[2,1.65,0]],"batl":[[0,990,0.01],[1,1.82,0],[2,1.83,0]],"ltp":1.81,"tv":875.12,"id":9632596},{"batb":[[0,2.04,41.17],[1,1.77,378.13],[2,1.19,1]],"batl":[[0,2.82,253.59],[1,990,0.01],[2,2.4,0]],"ltp":2.22,"tv":1677.2,"id":9433864}]}]}
{"op":"mcm","clk":"4233413440","pt":1631534640047,"mc":[{"id":"1.187557653","rc":[{"batb":[[0,1.82,49.45],[1,1.81,24.73],[2,1.8,24.73]],"batl":[[0,1.92,11.44],[1,1.93,28.09],[2,990,0.01]],"ltp":1.81,"tv":875.12,"id":9632596},{"trd":[[2.04,51.06]],"batb":[[0,2.06,87.06],[1,2.04,36.12],[2,1.77,378.13]],"batl":[[0,2.16,15.25],[1,2.2,54.54],[2,2.82,253.59]],"ltp":2.04,"tv":1687.31,"id":9433864}],"tv":2562.43}]}
{"op":"mcm","clk":"4233413557","pt":1631534641059,"mc":[{"id":"1.187557653","rc":[{"batb":[[0,1.82,16.48],[1,1.81,8.24],[2,1.8,8.24]],"batl":[[0,1.92,27.06],[1,1.93,35.91],[2,1.94,7.82]],"ltp":1.81,"tv":875.12,"id":9632596},{"batb":[[2,1.92,50.79]],"ltp":2.04,"tv":1687.31,"id":9433864}]}]}
{"op":"mcm","clk":"4233414030","pt":1631534644972,"mc":[{"id":"1.187557653","rc":[{"trd":[[1.86,23.76]],"ltp":1.86,"tv":892.83,"id":9632596},{"trd":[[2.16,30.26]],"batl":[[0,2.2,54.54],[1,2.82,253.59],[2,990,0.01]],"ltp":2.16,"tv":1702.56,"id":9433864}],"tv":2595.39}]}
{"op":"mcm","clk":"4233414485","pt":1631534649070,"mc":[{"id":"1.187557653","rc":[{"batb":[[2,1.91,50.96]],"ltp":2.16,"tv":1702.56,"id":9433864}]}]}
{"op":"mcm","clk":"4233415097","pt":1631534654967,"mc":[{"id":"1.187557653","rc":[{"batl":[[0,1.92,15.62]],"ltp":1.86,"tv":892.83,"id":9632596}]}]}
{"op":"mcm","clk":"4233415381","pt":1631534657873,"mc":[{"id":"1.187557653","rc":[{"batl":[[0,1.89,14.27],[1,1.92,15.62],[2,1.93,35.91]],"ltp":1.86,"tv":892.83,"id":9632596},{"batl":[[0,2.2,67.6]],"ltp":2.16,"tv":1702.56,"id":9433864}]}]}
{"op":"mcm","clk":"4233417359","pt":1631534677007,"mc":[{"id":"1.187557653","rc":[{"batl":[[2,1.93,7.82]],"ltp":1.86,"tv":892.83,"id":9632596}]}]}
{"op":"mcm","clk":"4233420760","pt":1631534710102,"mc":[{"id":"1.187557653","rc":[{"batb":[[0,1.71,39.41],[1,1.01,113.7],[2,1.8,0]],"batl":[[0,990,0.01],[1,1.92,0],[2,1.93,0]],"ltp":1.86,"tv":892.83,"id":9632596},{"batb":[[0,1.91,50.96],[1,1.77,378.13],[2,1.19,1]],"batl":[[0,2.82,253.59],[1,990,0.01],[2,990,0]],"ltp":2.16,"tv":1702.56,"id":9433864}]}]}
{"op":"mcm","clk":"4233421645","pt":1631534718104,"mc":[{"id":"1.187557653","rc":[{"batb":[[1,1.19,1],[2,1.01,113.7]],"batl":[[0,990,0.01],[1,990,0]],"ltp":2.16,"tv":1702.56,"id":9433864}]}]}
{"op":"mcm","clk":"4233421868","pt":1631534720205,"mc":[{"id":"1.187557653","rc":[{"batb":[[0,1.95,102.56],[1,1.71,39.41],[2,1.01,113.7]],"batl":[[0,2.02,10.3],[1,2.12,145.77],[2,990,0.01]],"ltp":1.86,"tv":892.83,"id":9632596},{"trd":[[1.91,10.7]],"batb":[[0,1.91,45.61]],"batl":[[0,2.04,14.34],[1,2.06,72.82],[2,2.08,36.4]],"ltp":1.91,"tv":1713.26,"id":9433864}],"tv":2606.1}]}
{"op":"mcm","clk":"4233421967","pt":1631534721090,"mc":[{"id":"1.187557653","rc":[{"batb":[[0,1.95,20.52],[1,1.91,27.53],[2,1.82,29.79]],"batl":[[2,2.38,4.2]],"ltp":1.86,"tv":892.83,"id":9632596},{"batb":[[0,1.95,104.73],[1,1.94,38.46],[2,1.93,38.46]],"ltp":1.91,"tv":1713.26,"id":9433864}]}]}
{"op":"mcm","clk":"4233422051","pt":1631534721827,"mc":[{"id":"1.187557653","rc":[{"batb":[[0,1.95,43.19],[1,1.94,7.7],[2,1.93,7.7]],"batl":[[1,2.06,14.56],[2,2.08,7.28]],"ltp":1.91,"tv":1713.26,"id":9433864}]}]}
{"op":"mcm","clk":"4233422540","pt":1631534725916,"mc":[{"id":"1.187557653","rc":[{"batb":[[0,1.81,32.55],[1,1.01,113.7],[2,1.82,0]],"batl":[[0,990,0.01],[1,2.12,0],[2,2.38,0]],"ltp":1.86,"tv":892.83,"id":9632596},{"batb":[[0,1.79,31.38],[1,1.58,388.69],[2,1.19,1]],"batl":[[0,2.5,299.95],[1,990,0.01],[2,2.08,0]],"ltp":1.91,"tv":1713.26,"id":9433864}]}]}
{"op":"mcm","clk":"4233425647","pt":1631534753859,"mc":[{"id":"1.187557653","rc":[{"batb":[[1,1.19,1],[2,1.01,113.7]],"ltp":1.91,"tv":1713.26,"id":9433864}]}]}
{"op":"mcm","clk":"4233425790","pt":1631534755174,"mc":[{"id":"1.187557653","rc":[{"batb":[[1,1.73,31.34],[2,1.01,113.7]],"batl":[[0,1.9,47.38],[1,1.91,23.69],[2,1.92,43.29]],"ltp":1.86,"tv":892.83,"id":9632596},{"batl":[[0,2.16,8.05],[1,2.2,131.92],[2,2.5,299.95]],"ltp":1.91,"tv":1713.26,"id":9433864}]}]}
{"op":"mcm","clk":"4233425894","pt":1631534756171,"mc":[{"id":"1.187557653","rc":[{"trd":[[1.9,5.64]],"batb":[[0,1.81,115.43],[1,1.8,24.86],[2,1.79,24.86]],"batl":[[0,1.9,41.74]],"ltp":1.9,"tv":898.47,"id":9632596},{"trd":[[2.1,5.1]],"batb":[[0,2.02,42.93],[1,1.89,26.78],[2,1.19,1]],"ltp":2.1,"tv":1718.36,"id":9433864}],"tv":2616.84}]}
{"op":"mcm","clk":"4233425911","pt":1631534756290,"mc":[{"id":"1.187557653","rc":[{"batb":[[0,1.81,49.13],[1,1.8,8.28],[2,1.79,8.28]],"batl":[[0,1.9,10.16],[1,1.91,7.9],[2,1.92,27.5]],"ltp":1.9,"tv":898.47,"id":9632596}]}]}
{"op":"mcm","clk":"4233426037","pt":1631534757379,"mc":[{"id":"1.187557653","rc":[{"batb":[[2,1.67,383.76]],"ltp":2.1,"tv":1718.36,"id":9433864}]}]}
{"op":"mcm","clk":"4233427412","pt":1631534771003,"mc":[{"id":"1.187557653","rc":[{"batb":[[0,1.71,38.91],[1,1.01,113.7],[2,1.79,0]],"batl":[[0,990,0.01],[1,1.91,0],[2,1.92,0]],"ltp":1.9,"tv":898.47,"id":9632596},{"batb":[[0,1.89,26.78],[1,1.67,383.76],[2,1.19,1]],"batl":[[0,2.5,299.95],[1,990,0.01],[2,2.5,0]],"ltp":2.1,"tv":1718.36,"id":9433864}]}]}
{"op":"mcm","clk":"4233429357","pt":1631534789221,"mc":[{"id":"1.187557653","rc":[{"batb":[[0,2.02,6.88],[1,1.71,38.91],[2,1.01,113.7]],"batl":[[0,2.06,9.09],[1,2.16,125.81],[2,990,0.01]],"ltp":1.9,"tv":898.47,"id":9632596},{"trd":[[1.89,44.72]],"batb":[[0,1.89,21.34]],"batl":[[0,2.02,1705.1],[1,2.04,37.14],[2,2.06,134.22]],"ltp":1.89,"tv":1729.22,"id":9433864}],"tv":2627.7}]}
{"op":"mcm","clk":"4233429485","pt":1631534790224,"mc":[{"id":"1.187557653","rc":[{"batb":[[1,1.94,26.28],[2,1.85,29.31]],"batl":[[2,2.42,4.13]],"ltp":1.9,"tv":898.47,"id":9632596},{"batb":[[0,1.92,28.24],[1,1.91,78.52],[2,1.9,39.26]],"batl":[[0,2.02,184.4],[1,2.04,22.28],[2,2.06,80.53]],"ltp":1.89,"tv":1729.22,"id":9433864}]}]}
{"op":"mcm","clk":"4233429516","pt":1631534790523,"mc":[{"id":"1.187557653","rc":[{"batb":[[1,1.91,15.7],[2,1.9,7.86]],"batl":[[0,2.02,154.7],[1,2.04,7.42],[2,2.06,65.67]],"ltp":1.89,"tv":1729.22,"id":9433864}]}]}
{"op":"mcm","clk":"4233429918","pt":1631534794235,"mc":[{"id":"1.187557653","rc":[{"trd":[[2.02,20.6]],"batb":[[0,1.94,26.28],[1,1.85,29.31],[2,1.82,31.63]],"batl":[[0,2,14.42],[1,2.06,9.09],[2,2.16,125.81]],"ltp":2.02,"tv":912.23,"id":9632596}],"tv":2641.46}]}
{"op":"mcm","clk":"4233429942","pt":1631534794443,"mc":[{"id":"1.187557653","rc":[{"batl":[[0,2.06,9.09],[1,2.16,125.81],[2,2.42,4.13]],"ltp":2.02,"tv":912.23,"id":9632596}]}]}
{"op":"mcm","clk":"4233430923","pt":1631534804434,"mc":[{"id":"1.187557653","rc":[{"batl":[[0,2.16,125.81],[1,2.42,4.13],[2,990,0.01]],"ltp":2.02,"tv":912.23,"id":9632596}]}]}
{"op":"mcm","clk":"4233431136","pt":1631534806440,"mc":[{"id":"1.187557653","rc":[{"batb":[[1,1.82,31.63],[2,1.01,113.7]],"ltp":2.02,"tv":912.23,"id":9632596},{"batb":[[0,1.91,15.7],[1,1.9,7.86],[2,1.89,29.2]],"ltp":1.89,"tv":1729.22,"id":9433864}]}]}
{"op":"mcm","clk":"4233431275","pt":1631534807850,"mc":[{"id":"1.187557653","rc":[{"batb":[[0,2,4.2],[1,1.94,26.28],[2,1.82,31.63]],"batl":[[0,2.04,8.07],[1,2.16,125.81],[2,2.42,4.13]],"ltp":2.02,"tv":912.23,"id":9632596},{"batl":[[0,2,4.2],[1,2.02,154.7],[2,2.04,7.42]],"ltp":1.89,"tv":1729.22,"id":9433864}]}]}
{"op":"mcm","clk":"4233431447","pt":1631534809655,"mc":[{"id":"1.187557653","rc":[{"trd":[[2,12.24]],"batb":[[0,2,1.68]],"ltp":2.0,"tv":917.27,"id":9632596}],"tv":2646.5}]}
{"op":"mcm","clk":"4233431594","pt":1631534811245,"mc":[{"id":"1.187557653","rc":[{"batb":[[0,1.82,31.63],[1,1.01,113.7],[2,1.82,0]],"batl":[[0,990,0.01],[1,2.16,0],[2,2.42,0]],"ltp":2.0,"tv":917.27,"id":9632596},{"batb":[[0,1.75,34.06],[1,1.67,383.76],[2,1.19,1]],"batl":[[0,2.5,299.95],[1,990,0.01],[2,2.04,0]],"ltp":1.89,"tv":1729.22,"id":9433864}]}]}
{"op":"mcm","clk":"4233431882","pt":1631534814230,"mc":[{"id":"1.187557653","rc":[{"batb":[[0,1.83,31.55],[1,1.82,31.63],[2,1.01,113.7]],"ltp":2.0,"tv":917.27,"id":9632596}]}]}
{"op":"mcm","clk":"4233431909","pt":1631534814542,"mc":[{"id":"1.187557653","rc":[{"batb":[[1,1.01,113.7],[2,1.01,0]],"ltp":2.0,"tv":917.27,"id":9632596}]}]}
{"op":"mcm","clk":"4233434286","pt":1631534837288,"mc":[{"id":"1.187557653","rc":[{"batl":[[0,1.92,1567.26],[1,1.94,77.32],[2,1.95,38.66]],"ltp":2.0,"tv":917.27,"id":9632596},{"batb":[[0,2,163.66],[1,1.75,34.06],[2,1.67,383.76]],"batl":[[0,2.16,99],[1,2.5,299.95],[2,990,0.01]],"ltp":1.89,"tv":1729.22,"id":9433864}]}]}
{"op":"mcm","clk":"4233434381","pt":1631534838280,"mc":[{"id":"1.187557653","rc":[{"batb":[[0,1.84,81.52],[1,1.83,72.31],[2,1.82,40.76]],"batl":[[0,1.94,15.46],[1,1.95,7.74],[2,1.96,35.4]],"ltp":2.0,"tv":917.27,"id":9632596},{"trd":[[2.12,25.07]],"batb":[[0,2.12,1.47],[1,2,163.66],[2,1.75,34.06]],"batl":[[0,2.16,106.29]],"ltp":2.12,"tv":1739.48,"id":9433864}],"tv":2656.76}]}
{"op":"mcm","clk":"4233434431","pt":1631534838655,"mc":[{"id":"1.187557653","rc":[{"batb":[[0,1.84,16.3],[1,1.83,39.71],[2,1.82,8.16]],"ltp":2.0,"tv":917.27,"id":9632596},{"batb":[[1,2,208.09],[2,1.84,28.87]],"ltp":2.12,"tv":1739.48,"id":9433864}]}]}
{"op":"mcm","clk":"4233434582","pt":1631534840102,"mc":[{"id":"1.187557653","rc":[{"batl":[[2,1.96,7.74]],"ltp":2.0,"tv":917.27,"id":9632596},{"batb":[[0,2,144.43],[1,1.84,28.87],[2,1.67,383.76]],"batl":[[0,2.5,299.95],[1,990,0.01],[2,990,0]],"ltp":2.12,"tv":1739.48,"id":9433864}]}]}
{"op":"mcm","clk":"4233434658","pt":1631534840775,"mc":[{"id":"1.187557653","rc":[{"batb":[[1,1.83,8.16]],"ltp":2.0,"tv":917.27,"id":9632596},{"batb":[[0,2,100]],"ltp":2.12,"tv":1739.48,"id":9433864}]}]}
{"op":"mcm","clk":"4233435071","pt":1631534845177,"mc":[{"id":"1.187557653","rc":[{"batl":[[0,2.12,2.72],[1,2.5,299.95],[2,990,0.01]],"ltp":2.12,"tv":1739.48,"id":9433864}]}]}
{"op":"mcm","clk":"4233435724","pt":1631534852193,"mc":[{"id":"1.187557653","rc":[{"batb":[[0,1.7,39.58],[1,1.01,113.7],[2,1.82,0]],"batl":[[0,990,0.01],[1,1.95,0],[2,1.96,0]],"ltp":2.0,"tv":917.27,"id":9632596},{"batb":[[0,1.84,28.87],[1,1.67,383.76],[2,1.19,1]],"ltp":2.12,"tv":1739.48,"id":9433864}]}]}
{"op":"mcm","clk":"4233436263","pt":1631534858122,"mc":[{"id":"1.187557653","rc":[{"batl":[[1,990,0.01],[2,990,0]],"ltp":2.12,"tv":1739.48,"id":9433864}]}]}
{"op":"mcm","clk":"4233436315","pt":1631534858602,"mc":[{"id":"1.187557653","rc":[{"batl":[[0,990,0.01],[1,990,0]],"ltp":2.12,"tv":1739.48,"id":9433864}]}]}
{"op":"mcm","clk":"4233436479","pt":1631534860223,"mc":[{"id":"1.187557653","rc":[{"batb":[[0,1.74,12.22],[1,1.7,39.58],[2,1.01,113.7]],"batl":[[0,1.78,13.06],[1,1.82,1666.98],[2,1.83,81.96]],"ltp":2.0,"tv":917.27,"id":9632596},{"batb":[[0,2.18,91.74],[1,1.84,28.87],[2,1.67,383.76]],"batl":[[0,2.36,87.58],[1,990,0.01]],"ltp":2.12,"tv":1739.48,"id":9433864}]}]}
{"op":"mcm","clk":"4233436579","pt":1631534861212,"mc":[{"id":"1.187557653","rc":[{"trd":[[1.78,18.71]],"batb":[[2,1.64,33.06]],"batl":[[0,1.78,6.9],[1,1.83,46.03],[2,1.84,8.2]],"ltp":1.78,"tv":923.43,"id":9632596},{"trd":[[2.28,14.61]],"batb":[[1,2.16,34.81],[2,1.99,45.61]],"batl":[[0,2.34,64.1],[1,2.36,119.62],[2,2.38,32.04]],"ltp":2.28,"tv":1744.29,"id":9433864}],"tv":2667.73}]}
{"op":"mcm","clk":"4233436648","pt":1631534862130,"mc":[{"id":"1.187557653","rc":[{"batl":[[0,2.34,12.82],[1,2.36,93.98],[2,2.38,6.4]],"ltp":2.28,"tv":1744.29,"id":9433864}]}]}
{"op":"mcm","clk":"4233436917","pt":1631534865234,"mc":[{"id":"1.187557653","rc":[{"batl":[[0,1.77,40.33],[1,1.78,6.9],[2,1.83,46.03]],"ltp":1.78,"tv":923.43,"id":9632596}]}]}
{"op":"mcm","clk":"4233436935","pt":1631534865437,"mc":[{"id":"1.187557653","rc":[{"batl":[[0,1.78,6.9],[1,1.83,46.03],[2,1.84,8.2]],"ltp":1.78,"tv":923.43,"id":9632596}]}]}
{"op":"mcm","clk":"4233437492","pt":1631534871450,"mc":[{"id":"1.187557653","rc":[{"batb":[[0,1.7,39.58],[1,1.64,33.06],[2,1.61,48.2]],"batl":[[0,1.83,46.03],[1,1.84,8.2],[2,1.85,8.2]],"ltp":1.78,"tv":923.43,"id":9632596}]}]}
{"op":"mcm","clk":"4233437774","pt":1631534874219,"mc":[{"id":"1.187557653","rc":[{"batb":[[1,1.61,48.2],[2,1.01,113.7]],"batl":[[0,990,0.01],[1,1.84,0],[2,1.85,0]],"ltp":1.78,"tv":923.43,"id":9632596},{"batb":[[0,2.16,34.81],[1,1.99,45.61],[2,1.67,383.76]],"batl":[[0,2.82,253.59],[1,990,0.01],[2,2.38,0]],"ltp":2.28,"tv":1744.29,"id":9433864}]}]}
{"op":"mcm","clk":"4233437807","pt":1631534874530,"mc":[{"id":"1.187557653","rc":[{"batb":[[0,1.61,48.2],[1,1.01,113.7],[2,1.01,0]],"ltp":1.78,"tv":923.43,"id":9632596},{"batb":[[0,1.99,45.61],[1,1.67,383.76],[2,1.19,1]],"ltp":2.28,"tv":1744.29,"id":9433864}]}]}
{"op":"mcm","clk":"4233438679","pt":1631534882636,"mc":[{"id":"1.187557653","rc":[{"batl":[[0,990,0.01],[1,990,0]],"ltp":2.28,"tv":1744.29,"id":9433864}]}]}
{"op":"mcm","clk":"4233438813","pt":1631534883951,"mc":[{"id":"1.187557653","rc":[{"batb":[[0,1.88,15.96],[1,1.87,7.98],[2,1.86,7.98]],"batl":[[0,1.94,13.54],[1,1.97,27.52],[2,2,47.21]],"ltp":1.78,"tv":923.43,"id":9632596},{"trd":[[1.99,28.02]],"batb":[[0,2,47.21],[1,1.99,40.45],[2,1.67,383.76]],"batl":[[0,2.1,95.24],[1,2.12,8.14],[2,990,0.01]],"ltp":1.99,"tv":1754.6,"id":9433864}],"tv":2678.03}]}
{"op":"mcm","clk":"4233438961","pt":1631534885157,"mc":[{"id":"1.187557653","rc":[{"batl":[[2,1.98,45.46]],"ltp":1.78,"tv":923.43,"id":9632596},{"batb":[[2,1.82,29.96]],"ltp":1.99,"tv":1754.6,"id":9433864}]}]}
{"op":"mcm","clk":"4233439071","pt":1631534886150,"mc":[{"id":"1.187557653","rc":[{"batl":[[2,1.98,15.16]],"ltp":1.78,"tv":923.43,"id":9632596},{"batl":[[2,2.6,281.81]],"ltp":1.99,"tv":1754.6,"id":9433864}]}]}
{"op":"mcm","clk":"4233439374","pt":1631534888970,"mc":[{"id":"1.187557653","rc":[{"trd":[[1.9,34.86]],"ltp":1.9,"tv":952.65,"id":9632596},{"trd":[[2.1,31.54]],"batl":[[0,2.1,68.8]],"ltp":2.1,"tv":1781.04,"id":9433864}],"tv":2733.69}]}
{"op":"mcm","clk":"4233440497","pt":1631534900082,"mc":[{"id":"1.187557653","rc":[{"batb":[[0,1.72,38.41],[1,1.01,113.7],[2,1.86,0]],"batl":[[0,990,0.01],[1,1.97,0],[2,1.98,0]],"ltp":1.9,"tv":952.65,"id":9632596},{"batb":[[0,1.82,29.96],[1,1.67,383.76],[2,1.19,1]],"batl":[[0,2.6,281.81],[1,990,0.01],[2,2.6,0]],"ltp":2.1,"tv":1781.04,"id":9433864}]}]}
{"op":"mcm","clk":"4233442379","pt":1631534919205,"mc":[{"id":"1.187557653","rc":[{"batb":[[1,1.19,1],[2,1.01,113.7]],"batl":[[0,990,0.01],[1,990,0]],"ltp":2.1,"tv":1781.04,"id":9433864}]}]}
{"op":"mcm","clk":"4233442645","pt":1631534921816,"mc":[{"id":"1.187557653","rc":[{"batb":[[0,1.9,28.53],[1,1.72,38.41],[2,1.01,113.7]],"batl":[[0,2.16,14.75],[1,2.24,104.1],[2,990,0.01]],"ltp":1.9,"tv":952.65,"id":9632596},{"trd":[[1.82,22.6]],"batb":[[0,1.87,29],[1,1.82,24.36],[2,1.19,1]],"batl":[[0,1.92,12.15],[1,1.94,125.73],[2,1.95,7.74]],"ltp":1.82,"tv":1792.22,"id":9433864}],"tv":2744.87}]}
{"op":"mcm","clk":"4233442759","pt":1631534922909,"mc":[{"id":"1.187557653","rc":[{"batb":[[0,2,46.69],[1,1.9,28.53],[2,1.85,30.13]],"batl":[[2,2.5,4]],"ltp":1.9,"tv":952.65,"id":9632596},{"batb":[[1,1.84,16.3],[2,1.83,8.16]],"ltp":1.82,"tv":1792.22,"id":9433864}]}]}
{"op":"mcm","clk":"4233443063","pt":1631534926509,"mc":[{"id":"1.187557653","rc":[{"trd":[[2.08,28.82]],"ltp":2.08,"tv":963.87,"id":9632596},{"trd":[[1.92,12.15]],"batl":[[0,1.94,125.73],[1,1.95,7.74],[2,1.96,7.74]],"ltp":1.92,"tv":1804.37,"id":9433864}],"tv":2768.24}]}
{"op":"mcm","clk":"4233443698","pt":1631534933130,"mc":[{"id":"1.187557653","rc":[{"batl":[[0,990,0.01],[1,2.24,0],[2,2.5,0]],"ltp":2.08,"tv":963.87,"id":9632596},{"batb":[[1,1.82,24.36],[2,1.67,40.08]],"batl":[[0,2.42,312.73],[1,990,0.01],[2,1.96,0]],"ltp":1.92,"tv":1804.37,"id":9433864}]}]}
{"op":"mcm","clk":"4233443736","pt":1631534933550,"mc":[{"id":"1.187557653","rc":[{"batb":[[0,1.85,30.13],[1,1.01,113.7],[2,1.85,0]],"ltp":2.08,"tv":963.87,"id":9632596},{"batb":[[0,1.67,40.08],[1,1.55,392.04],[2,1.19,1]],"ltp":1.92,"tv":1804.37,"id":9433864}]}]}
{"op":"mcm","clk":"4233444224","pt":1631534938732,"mc":[{"id":"1.187557653","rc":[{"batb":[[1,1.19,1],[2,1.01,113.7]],"ltp":1.92,"tv":1804.37,"id":9433864}]}]}
{"op":"mcm","clk":"4233444316","pt":1631534939839,"mc":[{"id":"1.187557653","rc":[{"batb":[[1,1.76,30.8],[2,1.01,113.7]],"batl":[[0,1.94,61.86],[1,1.97,27.52],[2,1.98,45.46]],"ltp":2.08,"tv":963.87,"id":9632596},{"batb":[[0,1.89,377.95],[1,1.67,40.08],[2,1.19,1]],"batl":[[0,2.16,139.79],[1,2.42,312.73],[2,990,0.01]],"ltp":1.92,"tv":1804.37,"id":9433864}]}]}
{"op":"mcm","clk":"4233444436","pt":1631534940947,"mc":[{"id":"1.187557653","rc":[{"trd":[[1.94,233.79]],"batb":[[2,1.73,37.82]],"batl":[[0,1.94,56.36],[2,1.98,15.16]],"ltp":1.94,"tv":969.37,"id":9632596},{"trd":[[2.06,46.77]],"batb":[[0,1.97,46.61],[1,1.89,377.95],[2,1.81,30.38]],"batl":[[0,2.14,14.02],[1,2.16,146.79],[2,2.18,7]],"ltp":2.06,"tv":1809.55,"id":9433864}],"tv":2778.92}]}
{"op":"mcm","clk":"4233444585","pt":1631534942540,"mc":[{"id":"1.187557653","rc":[{"batl":[[0,1.92,11.77],[1,1.94,56.36],[2,1.97,27.52]],"ltp":1.94,"tv":969.37,"id":9632596},{"batl":[[1,2.16,161.82]],"ltp":2.06,"tv":1809.55,"id":9433864}]}]}
{"op":"mcm","clk":"4233445686","pt":1631534953285,"mc":[{"id":"1.187557653","rc":[{"batl":[[0,1.97,27.52],[1,990,0.01],[2,1.97,0]],"ltp":1.94,"tv":969.37,"id":9632596},{"batb":[[1,1.81,30.38],[2,1.62,388.38]],"batl":[[0,2.42,312.73],[1,990,0.01],[2,2.18,0]],"ltp":2.06,"tv":1809.55,"id":9433864}]}]}
{"op":"mcm","clk":"4233445790","pt":1631534954072,"mc":[{"id":"1.187557653","rc":[{"batb":[[0,1.73,37.82],[1,1.01,113.7],[2,1.73,0]],"batl":[[0,990,0.01],[1,990,0]],"ltp":1.94,"tv":969.37,"id":9632596},{"batb":[[0,1.81,30.38],[1,1.19,1],[2,1.01,113.7]],"batl":[[0,990,0.11],[1,990,0]],"ltp":2.06,"tv":1809.55,"id":9433864}]}]}
{"op":"mcm","clk":"4233447196","pt":1631534970779,"mc":[{"id":"1.187557653","rc":[{"trd":[[1.92,6.06]],"batb":[[0,1.74,178.86],[1,1.73,37.82],[2,1.65,32.86]],"batl":[[0,1.78,9.69],[1,1.83,65.57],[2,1.85,29.31]],"ltp":1.92,"tv":969.48,"id":9632596},{"trd":[[2.08,5.59]],"batb":[[0,2.22,40.54],[1,2.2,20.27],[2,2.18,20.27]],"batl":[[0,990,0.01]],"ltp":2.08,"tv":1809.65,"id":9433864}],"tv":2779.13}]}
{"op":"mcm","clk":"4233447281","pt":1631534971813,"mc":[{"id":"1.187557653","rc":[{"trd":[[1.78,24.87]],"batb":[[1,1.73,55.16],[2,1.72,8.68]],"batl":[[0,1.78,3.53]],"ltp":1.78,"tv":975.64,"id":9632596},{"trd":[[2.28,19.42]],"batb":[[0,2.22,13.52],[1,2.2,6.76],[2,2.18,6.76]],"ltp":2.28,"tv":1814.46,"id":9433864}],"tv":2790.1}]}
{"op":"mcm","clk":"4233448128","pt":1631534981725,"mc":[{"id":"1.187557653","rc":[{"batb":[[0,1.74,163.18]],"batl":[[0,1.83,65.57],[1,1.85,29.31],[2,2.12,4.72]],"ltp":1.78,"tv":975.64,"id":9632596}]}]}
{"op":"mcm","clk":"4233448368","pt":1631534984642,"mc":[{"id":"1.187557653","rc":[{"batb":[[0,1.76,8.89],[1,1.74,163.18],[2,1.73,55.16]],"batl":[[0,1.8,15.33],[1,1.83,65.57],[2,1.85,29.31]],"ltp":1.78,"tv":975.64,"id":9632596}]}]}
{"op":"mcm","clk":"4233448625","pt":1631534987726,"mc":[{"id":"1.187557653","rc":[{"batl":[[2,2.12,4.72]],"ltp":1.78,"tv":975.64,"id":9632596}]}]}
{"op":"mcm","clk":"4233449085","pt":1631534993156,"mc":[{"id":"1.187557653","rc":[{"trd":[[1.8,79.35]],"batb":[[0,1.8,9.67],[1,1.76,8.89],[2,1.74,163.18]],"batl":[[0,1.83,65.57],[1,2.12,4.72],[2,990,0.01]],"ltp":1.8,"tv":1006.3,"id":9632596}],"tv":2820.76}]}
{"op":"mcm","clk":"4233449425","pt":1631534997170,"mc":[{"id":"1.187557653","rc":[{"batb":[[0,1.76,8.89],[1,1.74,163.18],[2,1.73,55.16]],"ltp":1.8,"tv":1006.3,"id":9632596}]}]}
{"op":"mcm","clk":"4233449940","pt":1631535003361,"mc":[{"id":"1.187557653","rc":[{"batb":[[0,1.74,163.18],[1,1.73,55.16],[2,1.72,8.68]],"ltp":1.8,"tv":1006.3,"id":9632596}]}]}
{"op":"mcm","clk":"4233450222","pt":1631535006290,"mc":[{"id":"1.187557653","rc":[{"batl":[[0,1.83,82.44]],"ltp":1.8,"tv":1006.3,"id":9632596},{"batl":[[0,2.28,8.75],[1,990,0.01]],"ltp":2.28,"tv":1814.46,"id":9433864}]}]}
{"op":"mcm","clk":"4233450836","pt":1631535013091,"mc":[{"id":"1.187557653","rc":[{"batb":[[0,1.63,46.28],[1,1.01,113.7],[2,1.72,0]],"batl":[[0,990,0.01],[1,2.12,0],[2,990,0]],"ltp":1.8,"tv":1006.3,"id":9632596},{"batb":[[0,1.95,47.87],[1,1.19,1],[2,1.01,113.7]],"batl":[[0,990,0.01],[1,990,0]],"ltp":2.28,"tv":1814.46,"id":9433864}]}]}
{"op":"mcm","clk":"4233451002","pt":1631535014966,"mc":[{"id":"1.187557653","rc":[{"batb":[[0,1.82,25],[1,1.63,46.28],[2,1.01,113.7]],"ltp":1.8,"tv":1006.3,"id":9632596}]}]}
{"op":"mcm","clk":"4233451360","pt":1631535018980,"mc":[{"id":"1.187557653","rc":[{"batb":[[1,1.63,46.34]],"ltp":1.8,"tv":1006.3,"id":9632596}]}]}
{"op":"mcm","clk":"4233451406","pt":1631535019506,"mc":[{"id":"1.187557653","rc":[{"batb":[[0,1.63,46.34],[1,1.01,113.7],[2,1.01,0]],"ltp":1.8,"tv":1006.3,"id":9632596}]}]}
{"op":"mcm","clk":"4233451524","pt":1631535021087,"mc":[{"id":"1.187557653","rc":[{"trd":[[1.8,79.47]],"batb":[[0,1.66,130.39],[1,1.63,46.28],[2,1.01,113.7]],"batl":[[0,1.72,1783.14],[1,1.99,5.03],[2,990,0.01]],"ltp":1.8,"tv":1006.42,"id":9632596},{"batb":[[0,2.4,5.77],[1,2.36,84.74],[2,2.34,64.1]],"batl":[[0,2.46,8.68],[1,990,0.01]],"ltp":2.28,"tv":1814.46,"id":9433864}],"tv":2820.88}]}
{"op":"mcm","clk":"4233451628","pt":1631535022085,"mc":[{"id":"1.187557653","rc":[{"batb":[[2,1.58,34.32]],"batl":[[0,1.75,30.99]],"ltp":1.8,"tv":1006.42,"id":9632596},{"trd":[[2.4,17.14]],"batb":[[0,2.4,1.22],[2,2.34,12.82]],"batl":[[1,2.5,60],[2,2.52,30]],"ltp":2.4,"tv":1823.56,"id":9433864}],"tv":2829.98}]}
{"op":"mcm","clk":"4233451661","pt":1631535022398,"mc":[{"id":"1.187557653","rc":[{"batl":[[1,2.5,12],[2,2.52,6]],"ltp":2.4,"tv":1823.56,"id":9433864}]}]}
{"op":"mcm","clk":"4233452009","pt":1631535026100,"mc":[{"id":"1.187557653","rc":[{"batl":[[0,1.69,24.92],[1,1.75,30.99],[2,1.99,5.03]],"ltp":1.8,"tv":1006.42,"id":9632596}]}]}
{"op":"mcm","clk":"4233452052","pt":1631535026415,"mc":[{"id":"1.187557653","rc":[{"batl":[[0,1.75,30.99],[1,1.99,5.03],[2,990,0.01]],"ltp":1.8,"tv":1006.42,"id":9632596}]}]}
{"op":"mcm","clk":"4233452631","pt":1631535032691,"mc":[{"id":"1.187557653","rc":[{"batb":[[0,2.36,84.74],[1,2.34,12.82],[2,2.32,94.55]],"batl":[[0,2.4,7.23]],"ltp":2.4,"tv":1823.56,"id":9433864}]}]}
{"op":"mcm","clk":"4233452853","pt":1631535035230,"mc":[{"id":"1.187557653","rc":[{"batb":[[0,1.7,8.22],[1,1.66,130.39],[2,1.63,46.28]],"ltp":1.8,"tv":1006.42,"id":9632596},{"batb":[[0,2.36,96.22]],"ltp":2.4,"tv":1823.56,"id":9433864}]}]}
{"op":"mcm","clk":"4233453386","pt":1631535041221,"mc":[{"id":"1.187557653","rc":[{"trd":[[1.74,31.28]],"ltp":1.74,"tv":1031.42,"id":9632596},{"trd":[[2.36,18.43]],"batb":[[0,2.36,77.79]],"ltp":2.36,"tv":1841.99,"id":9433864}],"tv":2873.41}]}
{"op":"mcm","clk":"4233453629","pt":1631535043845,"mc":[{"id":"1.187557653","rc":[{"trd":[[2.36,23.54]],"batb":[[0,2.36,75.24]],"batl":[[0,2.5,12],[1,2.52,6],[2,2.54,6]],"ltp":2.36,"tv":1847.1,"id":9433864}],"tv":2878.52}]}
{"op":"mcm","clk":"4233454034","pt":1631535048145,"mc":[{"id":"1.187557653","rc":[{"trd":[[1.74,41.05]],"ltp":1.74,"tv":1041.19,"id":9632596},{"trd":[[2.36,30.75]],"batb":[[0,2.36,68.03]],"ltp":2.36,"tv":1854.31,"id":9433864}],"tv":2895.5}]}
{"op":"mcm","clk":"4233454810","pt":1631535057053,"mc":[{"id":"1.187557653","rc":[{"batb":[[0,1.53,57.99],[1,1.01,113.7],[2,1.63,0]],"batl":[[0,990,0.01],[1,1.99,0],[2,990,0]],"ltp":1.74,"tv":1041.19,"id":9632596},{"batb":[[0,2.16,35.15],[1,1.19,1],[2,1.01,113.7]],"batl":[[0,990,0.01],[1,2.52,0],[2,2.54,0]],"ltp":2.36,"tv":1854.31,"id":9433864}]}]}
{"op":"mcm","clk":"4233455751","pt":1631535067277,"mc":[{"id":"1.187557653","rc":[{"batb":[[0,1.64,33.06],[1,1.53,57.99],[2,1.01,113.7]],"batl":[[0,1.83,48.41],[1,1.86,152.89],[2,990,0.01]],"ltp":1.74,"tv":1041.19,"id":9632596},{"trd":[[2.16,39.79]],"batb":[[0,2.16,30.38]],"batl":[[0,2.28,7.16],[1,2.32,64.66],[2,2.34,32.32]],"ltp":2.16,"tv":1863.83,"id":9433864}],"tv":2905.02}]}
{"op":"mcm","clk":"4233455818","pt":1631535068061,"mc":[{"id":"1.187557653","rc":[{"batb":[[0,1.71,39.25],[1,1.64,33.06],[2,1.61,48.03]],"batl":[[1,1.84,81.52],[2,1.85,40.76]],"ltp":1.74,"tv":1041.19,"id":9632596},{"batb":[[1,2.04,41.51],[2,1.19,1]],"batl":[[1,2.32,38.8],[2,2.34,19.39]],"ltp":2.16,"tv":1863.83,"id":9433864}]}]}
{"op":"mcm","clk":"4233455849","pt":1631535068375,"mc":[{"id":"1.187557653","rc":[{"batl":[[1,1.84,16.3],[2,1.85,8.16]],"ltp":1.74,"tv":1041.19,"id":9632596},{"batl":[[1,2.32,12.94],[2,2.34,6.46]],"ltp":2.16,"tv":1863.83,"id":9433864}]}]}
{"op":"mcm","clk":"4233456169","pt":1631535072085,"mc":[{"id":"1.187557653","rc":[{"trd":[[1.78,34.04]],"batl":[[0,1.76,11.66],[1,1.83,48.41],[2,1.84,16.3]],"ltp":1.78,"tv":1050.36,"id":9632596},{"trd":[[2.28,26.58]],"batl":[[0,2.32,12.94],[1,2.34,6.46],[2,2.36,6.46]],"ltp":2.28,"tv":1870.99,"id":9433864}],"tv":2921.35}]}
{"op":"mcm","clk":"4233456193","pt":1631535072294,"mc":[{"id":"1.187557653","rc":[{"batl":[[0,1.83,48.41],[1,1.84,16.3],[2,1.85,8.16]],"ltp":1.78,"tv":1050.36,"id":9632596}]}]}
{"op":"mcm","clk":"4233457103","pt":1631535082327,"mc":[{"id":"1.187557653","rc":[{"batl":[[0,1.83,29.63]],"ltp":1.78,"tv":1050.36,"id":9632596}]}]}
{"op":"mcm","clk":"4233457389","pt":1631535085205,"mc":[{"id":"1.187557653","rc":[{"batb":[[0,1.76,13.19],[1,1.71,39.25]],"batl":[[0,1.8,11.06]],"ltp":1.78,"tv":1050.36,"id":9632596}]}]}
{"op":"mcm","clk":"4233457462","pt":1631535085937,"mc":[{"id":"1.187557653","rc":[{"batb":[[0,1.61,48.03],[1,1.01,113.7],[2,1.61,0]],"batl":[[0,990,0.01],[1,1.84,0],[2,1.85,0]],"ltp":1.78,"tv":1050.36,"id":9632596},{"batb":[[0,2.04,41.51],[1,1.19,1],[2,1.01,113.7]],"batl":[[0,990,0.01],[1,2.34,0],[2,2.36,0]],"ltp":2.28,"tv":1870.99,"id":9433864}]}]}
{"op":"mcm","clk":"4233458037","pt":1631535092445,"mc":[{"id":"1.187557653","rc":[{"batb":[[1,1.74,379.61],[2,1.19,1]],"batl":[[0,2.92,242.8],[1,990,0.01]],"ltp":2.28,"tv":1870.99,"id":9433864}]}]}
{"op":"mcm","clk":"4233459286","pt":1631535106050,"mc":[{"id":"1.187557653","rc":[{"batl":[[0,990,0.01],[1,990,0]],"ltp":2.28,"tv":1870.99,"id":9433864}]}]}
{"op":"mcm","clk":"4233459510","pt":1631535108260,"mc":[{"id":"1.187557653","rc":[{"batb":[[0,1.81,16.58],[1,1.8,8.28],[2,1.79,41.84]],"batl":[[0,1.89,16.22],[1,1.9,28.53],[2,1.92,83.73]],"ltp":1.78,"tv":1050.36,"id":9632596},{"trd":[[2.04,60.97]],"batb":[[0,2.04,36.55],[1,1.97,46.94],[2,1.74,379.61]],"batl":[[0,2.2,102.14],[1,990,0.01]],"ltp":2.04,"tv":1880.89,"id":9433864}],"tv":2931.26}]}
{"op":"mcm","clk":"4233459603","pt":1631535109240,"mc":[{"id":"1.187557653","rc":[{"batl":[[1,1.9,44.33],[2,1.91,7.9]],"ltp":1.78,"tv":1050.36,"id":9632596},{"batl":[[1,3.75,247.82],[2,990,0.01]],"ltp":2.04,"tv":1880.89,"id":9433864}]}]}
{"op":"mcm","clk":"4233459623","pt":1631535109548,"mc":[{"id":"1.187557653","rc":[{"batl":[[1,2.72,264.63]],"ltp":2.04,"tv":1880.89,"id":9433864}]}]}
{"op":"mcm","clk":"4233459905","pt":1631535112476,"mc":[{"id":"1.187557653","rc":[{"trd":[[1.83,50.57]],"ltp":1.83,"tv":1062.1,"id":9632596},{"trd":[[2.2,25]],"batl":[[0,2.2,92.37]],"ltp":2.2,"tv":1890.66,"id":9433864}],"tv":2952.77}]}
{"op":"mcm","clk":"4233460312","pt":1631535116180,"mc":[{"id":"1.187557653","rc":[{"trd":[[1.83,53.87]],"ltp":1.83,"tv":1065.39,"id":9632596},{"trd":[[2.2,27.74]],"batb":[[0,2.04,119.29]],"batl":[[0,2.2,89.63]],"ltp":2.2,"tv":1893.4,"id":9433864}],"tv":2958.8}]}
{"op":"mcm","clk":"4233461146","pt":1631535124666,"mc":[{"id":"1.187557653","rc":[{"batl":[[1,1.9,15.8]],"ltp":1.83,"tv":1065.39,"id":9632596}]}]}
{"op":"mcm","clk":"4233461286","pt":1631535126283,"mc":[{"id":"1.187557653","rc":[{"batb":[[0,2.04,36.55]],"ltp":2.2,"tv":1893.4,"id":9433864}]}]}
{"op":"mcm","clk":"4233461465","pt":1631535128176,"mc":[{"id":"1.187557653","rc":[{"trd":[[1.89,32.71]],"batb":[[0,1.89,239.31],[1,1.7,40.33],[2,1.01,113.7]],"batl":[[0,990,0.01],[1,1.9,0],[2,1.91,0]],"ltp":1.89,"tv":1097.84,"id":9632596},{"batb":[[0,1.97,46.94],[1,1.74,379.61],[2,1.19,1]],"batl":[[0,2.72,264.63],[1,990,0.01],[2,990,0]],"ltp":2.2,"tv":1893.4,"id":9433864}],"tv":2991.25}]}
{"op":"mcm","clk":"4233461745","pt":1631535131108,"mc":[{"id":"1.187557653","rc":[{"batb":[[1,1.96,47.11],[2,1.74,379.61]],"ltp":2.2,"tv":1893.4,"id":9433864}]}]}
{"op":"mcm","clk":"4233461776","pt":1631535131384,"mc":[{"id":"1.187557653","rc":[{"batb":[[0,1.96,47.11],[1,1.74,379.61],[2,1.19,1]],"ltp":2.2,"tv":1893.4,"id":9433864}]}]}
{"op":"mcm","clk":"4233462654","pt":1631535140231,"mc":[{"id":"1.187557653","rc":[{"trd":[[1.89,511.29]],"batb":[[0,1.74,94.24]],"batl":[[0,1.81,1439.65],[1,1.83,15.94],[2,1.92,352.4]],"ltp":1.89,"tv":1576.42,"id":9632596},{"batb":[[0,2.22,67.56],[1,2.2,33.78],[2,2.18,125.52]],"batl":[[0,2.28,9.42],[1,2.72,264.63],[2,990,0.01]],"ltp":2.2,"tv":1893.4,"id":9433864}],"tv":3469.83}]}
{"op":"mcm","clk":"4233462762","pt":1631535141229,"mc":[{"id":"1.187557653","rc":[{"batb":[[1,1.73,86.72],[2,1.72,43.36]],"batl":[[0,1.82,29.79],[1,1.92,352.4],[2,2.08,4.81]],"ltp":1.89,"tv":1576.42,"id":9632596},{"trd":[[2.22,14.53]],"batb":[[0,2.22,35.78],[1,2.2,20.27],[2,2.18,109.54]],"batl":[[0,2.72,264.63],[1,990,0.01],[2,990,0]],"ltp":2.22,"tv":1902.92,"id":9433864}],"tv":3479.35}]}
{"op":"mcm","clk":"4233462855","pt":1631535142121,"mc":[{"id":"1.187557653","rc":[{"batb":[[1,1.73,17.34],[2,1.72,8.68]],"ltp":1.89,"tv":1576.42,"id":9632596}]}]}
{"op":"mcm","clk":"4233462973","pt":1631535143341,"mc":[{"id":"1.187557653","rc":[{"batl":[[1,1.83,15.94],[2,1.92,352.4]],"ltp":1.89,"tv":1576.42,"id":9632596},{"batl":[[0,2.28,9.42],[1,2.72,264.63],[2,990,0.01]],"ltp":2.22,"tv":1902.92,"id":9433864}]}]}
{"op":"mcm","clk":"4233463167","pt":1631535145202,"mc":[{"id":"1.187557653","rc":[{"trd":[[1.78,46.11]],"batl":[[0,1.76,11.97],[1,1.82,29.79],[2,1.83,15.94]],"ltp":1.78,"tv":1588.49,"id":9632596},{"trd":[[2.28,36]],"batl":[[0,2.42,61.3]],"ltp":2.28,"tv":1912.34,"id":9433864}],"tv":3500.84}]}
{"op":"mcm","clk":"4233463188","pt":1631535145410,"mc":[{"id":"1.187557653","rc":[{"batl":[[0,1.82,29.79],[1,1.83,15.94],[2,1.92,352.4]],"ltp":1.78,"tv":1588.49,"id":9632596},{"batl":[[0,2.72,264.63],[1,990,0.01],[2,990,0]],"ltp":2.28,"tv":1912.34,"id":9433864}]}]}
{"op":"mcm","clk":"4233464105","pt":1631535155456,"mc":[{"id":"1.187557653","rc":[{"batl":[[1,1.92,352.4],[2,2.08,4.81]],"ltp":1.78,"tv":1588.49,"id":9632596}]}]}
{"op":"mcm","clk":"4233464304","pt":1631535157450,"mc":[{"id":"1.187557653","rc":[{"batl":[[0,1.92,352.4],[1,2.08,4.81],[2,990,0.01]],"ltp":1.78,"tv":1588.49,"id":9632596}]}]}
{"op":"mcm","clk":"4233464383","pt":1631535158362,"mc":[{"id":"1.187557653","rc":[{"batb":[[0,1.76,13.18],[1,1.74,94.24],[2,1.73,17.34]],"batl":[[0,1.8,11.06],[1,1.92,352.4],[2,2.08,4.81]],"ltp":1.78,"tv":1588.49,"id":9632596}]}]}
{"op":"mcm","clk":"4233465021","pt":1631535165160,"mc":[{"id":"1.187557653","rc":[{"batb":[[0,1.7,40.33],[1,1.6,49.79],[2,1.01,113.7]],"batl":[[0,990,0.01],[1,1.92,0],[2,2.08,0]],"ltp":1.78,"tv":1588.49,"id":9632596},{"batb":[[0,2.18,34.23],[1,2.04,41.84],[2,1.74,379.61]],"ltp":2.28,"tv":1912.34,"id":9433864}]}]}
{"op":"mcm","clk":"4233465060","pt":1631535165440,"mc":[{"id":"1.187557653","rc":[{"batb":[[0,1.6,49.79],[1,1.01,113.7],[2,1.01,0]],"ltp":1.78,"tv":1588.49,"id":9632596},{"batb":[[0,2.04,41.84],[1,1.74,379.61],[2,1.19,1]],"ltp":2.28,"tv":1912.34,"id":9433864}]}]}
{"op":"mcm","clk":"4233465333","pt":1631535168271,"mc":[{"id":"1.187557653","rc":[{"batl":[[0,2.7,122.85],[1,2.72,264.63],[2,990,0.01]],"ltp":2.28,"tv":1912.34,"id":9433864}]}]}
{"op":"mcm","clk":"4233465349","pt":1631535168436,"mc":[{"id":"1.187557653","rc":[{"batl":[[0,2.72,264.63],[1,990,0.01],[2,990,0]],"ltp":2.28,"tv":1912.34,"id":9433864}]}]}
{"op":"mcm","clk":"4233467241","pt":1631535187894,"mc":[{"id":"1.187557653","rc":[{"batb":[[0,1.82,82.42],[1,1.81,41.22],[2,1.8,41.22]],"batl":[[0,1.89,10.4],[1,1.9,28.53],[2,990,0.01]],"ltp":1.78,"tv":1588.49,"id":9632596},{"trd":[[2.08,15.49]],"batb":[[0,2.08,79.88],[1,2.04,41.84],[2,1.74,379.61]],"batl":[[0,2.2,16.26],[1,2.72,264.63],[2,990,0.01]],"ltp":2.08,"tv":1922.24,"id":9433864}],"tv":3510.74}]}
{"op":"mcm","clk":"4233467355","pt":1631535188871,"mc":[{"id":"1.187557653","rc":[{"batb":[[0,1.82,49.45],[1,1.81,24.73],[2,1.8,24.73]],"batl":[[2,2.18,4.59]],"ltp":1.78,"tv":1588.49,"id":9632596},{"batb":[[0,2.1,14.28],[1,2.08,87.02],[2,2.06,7.14]],"ltp":2.08,"tv":1922.24,"id":9433864}]}]}
