{"op":"mcm","clk":"4206563098","pt":1631438901939,"mc":[{"id":"1.187552292","marketDefinition":{"bspMarket":false,"turnInPlayEnabled":true,"persistenceEnabled":true,"marketBaseRate":5.0,"eventId":"30895224","eventTypeId":"2","numberOfWinners":1,"bettingType":"ODDS","marketType":"MATCH_ODDS","marketTime":"2021-09-12T12:00:00.000Z","suspendTime":"2021-09-12T12:00:00.000Z","bspReconciled":false,"complete":true,"inPlay":false,"crossMatching":false,"runnersVoidable":false,"numberOfActiveRunners":2,"betDelay":0,"status":"OPEN","runners":[{"status":"ACTIVE","sortPriority":1,"id":11486880,"name":"S Ma"},{"status":"ACTIVE","sortPriority":2,"id":9631381,"name":"O Nicholls"}],"regulators":["MR_INT"],"countryCode":"GB","discountAllowed":false,"timezone":"GMT","openDate":"2021-09-12T12:00:00.000Z","version":4027604624,"name":"Match Odds","eventName":"S Ma v O Nicholls"},"rc":[{"batb":[[0,1.01,25]],"ltp":0.0,"tv":0.0,"id":9631381},{"batb":[[0,1.01,25]],"ltp":0.0,"tv":0.0,"id":11486880}]}]}
{"op":"mcm","clk":"4206563234","pt":1631438903729,"mc":[{"id":"1.187552292","marketDefinition":{"bspMarket":false,"turnInPlayEnabled":true,"persistenceEnabled":true,"marketBaseRate":5.0,"eventId":"30895224","eventTypeId":"2","numberOfWinners":1,"bettingType":"ODDS","marketType":"MATCH_ODDS","marketTime":"2021-09-12T12:00:00.000Z","suspendTime":"2021-09-12T12:00:00.000Z","bspReconciled":false,"complete":true,"inPlay":false,"crossMatching":false,"runnersVoidable":false,"numberOfActiveRunners":2,"betDelay":0,"status":"OPEN","runners":[{"status":"ACTIVE","sortPriority":1,"id":11486880,"name":"S Ma"},{"status":"ACTIVE","sortPriority":2,"id":9631381,"name":"O Nicholls"}],"regulators":["MR_INT"],"countryCode":"GB","discountAllowed":true,"timezone":"GMT","openDate":"2021-09-12T12:00:00.000Z","version":4027604624,"name":"Match Odds","eventName":"S Ma v O Nicholls"}}]}
{"op":"mcm","clk":"4206572135","pt":1631439019086,"mc":[{"id":"1.187552292","rc":[{"batb":[[0,1.01,7]],"ltp":0.0,"tv":0.0,"id":9631381},{"batb":[[0,1.01,7]],"ltp":0.0,"tv":0.0,"id":11486880}]}]}
{"op":"mcm","clk":"4206623497","pt":1631439537677,"mc":[{"id":"1.187552292","rc":[{"batl":[[0,490,6.16]],"ltp":0.0,"tv":0.0,"id":9631381},{"batl":[[0,490,6.16]],"ltp":0.0,"tv":0.0,"id":11486880}]}]}
{"op":"mcm","clk":"4206624694","pt":1631439549697,"mc":[{"id":"1.187552292","rc":[{"batb":[[0,1.05,879.5],[1,1.01,7]],"ltp":0.0,"tv":0.0,"id":9631381},{"batb":[[0,1.05,879.5],[1,1.01,7]],"ltp":0.0,"tv":0.0,"id":11486880}]}]}
{"op":"mcm","clk":"4206779580","pt":1631440928852,"mc":[{"id":"1.187552292","rc":[{"batb":[[0,3,22.54],[1,1.05,879.5],[2,1.01,7]],"ltp":0.0,"tv":0.0,"id":9631381},{"batb":[[0,1.33,136.64],[1,1.05,879.5],[2,1.01,7]],"ltp":0.0,"tv":0.0,"id":11486880}]}]}
{"op":"mcm","clk":"4206783109","pt":1631440957953,"mc":[{"id":"1.187552292","marketDefinition":{"bspMarket":false,"turnInPlayEnabled":true,"persistenceEnabled":true,"marketBaseRate":5.0,"eventId":"30895224","eventTypeId":"2","numberOfWinners":1,"bettingType":"ODDS","marketType":"MATCH_ODDS","marketTime":"2021-09-12T12:00:00.000Z","suspendTime":"2021-09-12T12:00:00.000Z","bspReconciled":false,"complete":true,"inPlay":false,"crossMatching":true,"runnersVoidable":false,"numberOfActiveRunners":2,"betDelay":0,"status":"OPEN","runners":[{"status":"ACTIVE","sortPriority":1,"id":11486880,"name":"S Ma"},{"status":"ACTIVE","sortPriority":2,"id":9631381,"name":"O Nicholls"}],"regulators":["MR_INT"],"countryCode":"GB","discountAllowed":true,"timezone":"GMT","openDate":"2021-09-12T12:00:00.000Z","version":4027604624,"name":"Match Odds","eventName":"S Ma v O Nicholls"}}]}
{"op":"mcm","clk":"4207243277","pt":1631444401050,"mc":[{"id":"1.187552292","rc":[{"batb":[[0,3.05,6.25],[1,3,22.54],[2,1.05,879.5]],"ltp":0.0,"tv":0.0,"id":9631381},{"batb":[[0,1.34,37.68],[1,1.33,136.64],[2,1.05,879.5]],"ltp":0.0,"tv":0.0,"id":11486880}]}]}
{"op":"mcm","clk":"4207551102","pt":1631446123283,"mc":[{"id":"1.187552292","rc":[{"batb":[[1,3,25.2]],"ltp":0.0,"tv":0.0,"id":9631381},{"batb":[[1,1.33,139.3]],"ltp":0.0,"tv":0.0,"id":11486880}]}]}
{"op":"mcm","clk":"4207899654","pt":1631448068365,"mc":[{"id":"1.187552292","marketDefinition":{"bspMarket":false,"turnInPlayEnabled":true,"persistenceEnabled":true,"marketBaseRate":5.0,"eventId":"30895224","eventTypeId":"2","numberOfWinners":1,"bettingType":"ODDS","marketType":"MATCH_ODDS","marketTime":"2021-09-12T12:00:00.000Z","suspendTime":"2021-09-12T12:00:00.000Z","bspReconciled":false,"complete":true,"inPlay":true,"crossMatching":true,"runnersVoidable":false,"numberOfActiveRunners":2,"betDelay":5,"status":"OPEN","runners":[{"status":"ACTIVE","sortPriority":1,"id":11486880,"name":"S Ma"},{"status":"ACTIVE","sortPriority":2,"id":9631381,"name":"O Nicholls"}],"regulators":["MR_INT"],"countryCode":"GB","discountAllowed":true,"timezone":"GMT","openDate":"2021-09-12T12:00:00.000Z","version":4028034788,"name":"Match Odds","eventName":"S Ma v O Nicholls"},"rc":[{"batb":[[0,1.01,12],[1,3,0],[2,1.05,0]],"ltp":0.0,"tv":0.0,"id":9631381},{"batb":[[0,1.01,12],[1,1.33,0],[2,1.05,0]],"ltp":0.0,"tv":0.0,"id":11486880}]}]}
{"op":"mcm","clk":"4207900609","pt":1631448073415,"mc":[{"id":"1.187552292","rc":[{"batl":[[0,11.5,8.68]],"ltp":0.0,"tv":0.0,"id":11486880}]}]}
{"op":"mcm","clk":"4208123306","pt":1631449165481,"mc":[{"id":"1.187552292","marketDefinition":{"bspMarket":false,"turnInPlayEnabled":true,"persistenceEnabled":true,"marketBaseRate":5.0,"eventId":"30895224","eventTypeId":"2","numberOfWinners":1,"bettingType":"ODDS","marketType":"MATCH_ODDS","marketTime":"2021-09-12T12:19:25.000Z","suspendTime":"2021-09-12T12:19:25.000Z","bspReconciled":false,"complete":true,"inPlay":true,"crossMatching":true,"runnersVoidable":false,"numberOfActiveRunners":2,"betDelay":5,"status":"OPEN","runners":[{"status":"ACTIVE","sortPriority":1,"id":11486880,"name":"S Ma"},{"status":"ACTIVE","sortPriority":2,"id":9631381,"name":"O Nicholls"}],"regulators":["MR_INT"],"countryCode":"GB","discountAllowed":true,"timezone":"GMT","openDate":"2021-09-12T12:00:00.000Z","version":4028101332,"name":"Match Odds","eventName":"S Ma v O Nicholls"}}]}
{"op":"mcm","clk":"4208123890","pt":1631449168490,"mc":[{"id":"1.187552292","marketDefinition":{"bspMarket":false,"turnInPlayEnabled":true,"persistenceEnabled":true,"marketBaseRate":5.0,"eventId":"30895224","eventTypeId":"2","numberOfWinners":1,"bettingType":"ODDS","marketType":"MATCH_ODDS","marketTime":"2021-09-12T12:19:25.000Z","suspendTime":"2021-09-12T12:19:25.000Z","bspReconciled":false,"complete":true,"inPlay":true,"crossMatching":true,"runnersVoidable":false,"numberOfActiveRunners":2,"betDelay":5,"status":"OPEN","runners":[{"status":"ACTIVE","sortPriority":1,"id":11486880,"name":"S Ma"},{"status":"ACTIVE","sortPriority":2,"id":9631381,"name":"O Nicholls"}],"regulators":["MR_INT"],"countryCode":"GB","discountAllowed":true,"timezone":"GMT","openDate":"2021-09-12T12:19:25.000Z","version":4028101332,"name":"Match Odds","eventName":"S Ma v O Nicholls"}}]}
{"op":"mcm","clk":"4208157003","pt":1631449337702,"mc":[{"id":"1.187552292","rc":[{"batb":[[0,1.38,455.84],[1,1.01,12]],"batl":[[0,2.04,389.32],[1,11.5,8.68]],"ltp":0.0,"tv":0.0,"id":11486880}]}]}
{"op":"mcm","clk":"4208168691","pt":1631449395931,"mc":[{"id":"1.187552292","rc":[{"batb":[[0,1.01,12],[1,1.01,0]],"ltp":0.0,"tv":0.0,"id":11486880}]}]}
{"op":"mcm","clk":"4208169869","pt":1631449401919,"mc":[{"id":"1.187552292","rc":[{"batb":[[0,1.4,458.43],[1,1.01,12]],"ltp":0.0,"tv":0.0,"id":11486880}]}]}
{"op":"mcm","clk":"4208172745","pt":1631449416324,"mc":[{"id":"1.187552292","rc":[{"batb":[[0,1.01,12],[1,1.01,0]],"ltp":0.0,"tv":0.0,"id":11486880}]}]}
{"op":"mcm","clk":"4208173873","pt":1631449422142,"mc":[{"id":"1.187552292","rc":[{"batb":[[0,1.44,443.37],[1,1.01,12]],"ltp":0.0,"tv":0.0,"id":11486880}]}]}
{"op":"mcm","clk":"4208176419","pt":1631449434710,"mc":[{"id":"1.187552292","rc":[{"batb":[[0,1.01,12],[1,1.01,0]],"ltp":0.0,"tv":0.0,"id":11486880}]}]}
{"op":"mcm","clk":"4208177690","pt":1631449440619,"mc":[{"id":"1.187552292","rc":[{"batb":[[0,1.38,455.84],[1,1.01,12]],"ltp":0.0,"tv":0.0,"id":11486880}]}]}
{"op":"mcm","clk":"4208189174","pt":1631449497905,"mc":[{"id":"1.187552292","rc":[{"batb":[[0,1.01,12],[1,1.01,0]],"batl":[[0,11.5,8.68],[1,11.5,0]],"ltp":0.0,"tv":0.0,"id":11486880}]}]}
{"op":"mcm","clk":"4208190316","pt":1631449503439,"mc":[{"id":"1.187552292","rc":[{"batb":[[0,1.31,485.38],[1,1.01,12]],"batl":[[0,1.89,442.45],[1,11.5,8.68]],"ltp":0.0,"tv":0.0,"id":11486880}]}]}
{"op":"mcm","clk":"4208193310","pt":1631449518431,"mc":[{"id":"1.187552292","rc":[{"batb":[[0,1.01,12],[1,1.01,0]],"ltp":0.0,"tv":0.0,"id":11486880}]}]}
{"op":"mcm","clk":"4208194515","pt":1631449524660,"mc":[{"id":"1.187552292","rc":[{"batb":[[0,1.34,473.1],[1,1.01,12]],"ltp":0.0,"tv":0.0,"id":11486880}]}]}
{"op":"mcm","clk":"4208199874","pt":1631449552218,"mc":[{"id":"1.187552292","rc":[{"batb":[[0,1.01,12],[1,1.01,0]],"ltp":0.0,"tv":0.0,"id":11486880}]}]}
{"op":"mcm","clk":"4208201081","pt":1631449558433,"mc":[{"id":"1.187552292","rc":[{"batb":[[0,1.38,455.84],[1,1.01,12]],"batl":[[0,11.5,8.68],[1,11.5,0]],"ltp":0.0,"tv":0.0,"id":11486880}]}]}
{"op":"mcm","clk":"4208201271","pt":1631449559399,"mc":[{"id":"1.187552292","rc":[{"batb":[[0,1.01,12],[1,1.01,0]],"ltp":0.0,"tv":0.0,"id":11486880}]}]}
{"op":"mcm","clk":"4208206691","pt":1631449588356,"mc":[{"id":"1.187552292","rc":[{"batb":[[0,1.34,473.1],[1,1.01,12]],"batl":[[0,1.95,416.62],[1,11.5,8.68]],"ltp":0.0,"tv":0.0,"id":11486880}]}]}
{"op":"mcm","clk":"4208223013","pt":1631449671153,"mc":[{"id":"1.187552292","rc":[{"batb":[[0,1.01,12],[1,1.01,0]],"batl":[[0,11.5,8.68],[1,11.5,0]],"ltp":0.0,"tv":0.0,"id":11486880}]}]}
{"op":"mcm","clk":"4208224055","pt":1631449676520,"mc":[{"id":"1.187552292","rc":[{"batb":[[0,1.25,513.42],[1,1.01,12]],"batl":[[0,1.77,508.86],[1,11.5,8.68]],"ltp":0.0,"tv":0.0,"id":11486880}]}]}
{"op":"mcm","clk":"4208228007","pt":1631449697557,"mc":[{"id":"1.187552292","rc":[{"batb":[[0,1.01,12],[1,1.01,0]],"ltp":0.0,"tv":0.0,"id":11486880}]}]}
{"op":"mcm","clk":"4208229274","pt":1631449703867,"mc":[{"id":"1.187552292","rc":[{"batb":[[0,1.31,485.38],[1,1.01,12]],"ltp":0.0,"tv":0.0,"id":11486880}]}]}
{"op":"mcm","clk":"4208231591","pt":1631449715101,"mc":[{"id":"1.187552292","rc":[{"batb":[[0,1.01,12],[1,1.01,0]],"batl":[[0,11.5,8.68],[1,11.5,0]],"ltp":0.0,"tv":0.0,"id":11486880}]}]}
{"op":"mcm","clk":"4208232752","pt":1631449721092,"mc":[{"id":"1.187552292","rc":[{"batb":[[0,1.34,473.1],[1,1.01,12]],"batl":[[0,1.95,416.62],[1,11.5,8.68]],"ltp":0.0,"tv":0.0,"id":11486880}]}]}
{"op":"mcm","clk":"4208236646","pt":1631449741640,"mc":[{"id":"1.187552292","rc":[{"batb":[[0,1.01,12],[1,1.01,0]],"batl":[[0,11.5,8.68],[1,11.5,0]],"ltp":0.0,"tv":0.0,"id":11486880}]}]}
{"op":"mcm","clk":"4208237850","pt":1631449747639,"mc":[{"id":"1.187552292","rc":[{"batb":[[0,1.28,493.9],[1,1.01,12]],"batl":[[0,1.82,476.84],[1,11.5,8.68]],"ltp":0.0,"tv":0.0,"id":11486880}]}]}
{"op":"mcm","clk":"4208243873","pt":1631449778476,"mc":[{"id":"1.187552292","rc":[{"batb":[[0,1.01,12],[1,1.01,0]],"ltp":0.0,"tv":0.0,"id":11486880}]}]}
{"op":"mcm","clk":"4208244848","pt":1631449784186,"mc":[{"id":"1.187552292","rc":[{"batb":[[0,1.34,473.1],[1,1.01,12]],"ltp":0.0,"tv":0.0,"id":11486880}]}]}
{"op":"mcm","clk":"4208251502","pt":1631449817449,"mc":[{"id":"1.187552292","rc":[{"batb":[[0,1.01,12],[1,1.01,0]],"batl":[[0,11.5,8.68],[1,11.5,0]],"ltp":0.0,"tv":0.0,"id":11486880}]}]}
{"op":"mcm","clk":"4208252838","pt":1631449823773,"mc":[{"id":"1.187552292","rc":[{"batb":[[0,1.38,455.84],[1,1.01,12]],"batl":[[0,2.04,389.32],[1,11.5,8.68]],"ltp":0.0,"tv":0.0,"id":11486880}]}]}
{"op":"mcm","clk":"4208276187","pt":1631449937302,"mc":[{"id":"1.187552292","rc":[{"batb":[[0,1.01,12],[1,1.01,0]],"batl":[[0,11.5,8.68],[1,11.5,0]],"ltp":0.0,"tv":0.0,"id":11486880}]}]}
{"op":"mcm","clk":"4208277332","pt":1631449942922,"mc":[{"id":"1.187552292","rc":[{"batb":[[0,1.31,485.38],[1,1.01,12]],"batl":[[0,1.89,442.45],[1,11.5,8.68]],"ltp":0.0,"tv":0.0,"id":11486880}]}]}
{"op":"mcm","clk":"4208283517","pt":1631449972982,"mc":[{"id":"1.187552292","rc":[{"batb":[[0,1.01,12],[1,1.01,0]],"ltp":0.0,"tv":0.0,"id":11486880}]}]}
{"op":"mcm","clk":"4208284586","pt":1631449978198,"mc":[{"id":"1.187552292","rc":[{"batb":[[0,1.34,473.1],[1,1.01,12]],"ltp":0.0,"tv":0.0,"id":11486880}]}]}
{"op":"mcm","clk":"4208289809","pt":1631450002751,"mc":[{"id":"1.187552292","rc":[{"batb":[[0,1.01,12],[1,1.01,0]],"batl":[[0,11.5,8.68],[1,11.5,0]],"ltp":0.0,"tv":0.0,"id":11486880}]}]}
{"op":"mcm","clk":"4208291103","pt":1631450008990,"mc":[{"id":"1.187552292","rc":[{"batb":[[0,1.4,458.43],[1,1.01,12]],"batl":[[0,2.1,369.3],[1,11.5,8.68]],"ltp":0.0,"tv":0.0,"id":11486880}]}]}
{"op":"mcm","clk":"4208296569","pt":1631450035636,"mc":[{"id":"1.187552292","rc":[{"batb":[[0,1.01,12],[1,1.01,0]],"ltp":0.0,"tv":0.0,"id":11486880}]}]}
{"op":"mcm","clk":"4208297743","pt":1631450041504,"mc":[{"id":"1.187552292","rc":[{"batb":[[0,1.46,442.88],[1,1.01,12]],"ltp":0.0,"tv":0.0,"id":11486880}]}]}
{"op":"mcm","clk":"4208302425","pt":1631450063216,"mc":[{"id":"1.187552292","rc":[{"batb":[[0,1.01,12],[1,1.01,0]],"batl":[[0,11.5,8.68],[1,11.5,0]],"ltp":0.0,"tv":0.0,"id":11486880}]}]}
{"op":"mcm","clk":"4208303637","pt":1631450069142,"mc":[{"id":"1.187552292","rc":[{"batb":[[0,1.5,433.94],[1,1.01,12]],"batl":[[0,2.3,314.85],[1,11.5,8.68]],"ltp":0.0,"tv":0.0,"id":11486880}]}]}
{"op":"mcm","clk":"4208306346","pt":1631450082526,"mc":[{"id":"1.187552292","rc":[{"batb":[[0,1.01,12],[1,1.01,0]],"batl":[[0,11.5,8.68],[1,11.5,0]],"ltp":0.0,"tv":0.0,"id":11486880}]}]}
{"op":"mcm","clk":"4208307582","pt":1631450088571,"mc":[{"id":"1.187552292","rc":[{"batb":[[0,1.4,458.43],[1,1.01,12]],"batl":[[0,2.1,369.3],[1,11.5,8.68]],"ltp":0.0,"tv":0.0,"id":11486880}]}]}
{"op":"mcm","clk":"4208312851","pt":1631450114204,"mc":[{"id":"1.187552292","rc":[{"batb":[[0,1.01,12],[1,1.01,0]],"batl":[[0,11.5,8.68],[1,11.5,0]],"ltp":0.0,"tv":0.0,"id":11486880}]}]}
{"op":"mcm","clk":"4208314087","pt":1631450119940,"mc":[{"id":"1.187552292","rc":[{"batb":[[0,1.34,473.1],[1,1.01,12]],"batl":[[0,1.95,416.62],[1,11.5,8.68]],"ltp":0.0,"tv":0.0,"id":11486880}]}]}
{"op":"mcm","clk":"4208328577","pt":1631450186875,"mc":[{"id":"1.187552292","rc":[{"batb":[[0,1.01,12],[1,1.01,0]],"batl":[[0,11.5,8.68],[1,11.5,0]],"ltp":0.0,"tv":0.0,"id":11486880}]}]}
{"op":"mcm","clk":"4208329795","pt":1631450193069,"mc":[{"id":"1.187552292","rc":[{"batb":[[0,1.25,513.42],[1,1.01,12]],"batl":[[0,1.77,508.86],[1,11.5,8.68]],"ltp":0.0,"tv":0.0,"id":11486880}]}]}
{"op":"mcm","clk":"4208334790","pt":1631450215422,"mc":[{"id":"1.187552292","rc":[{"batb":[[0,1.01,12],[1,1.01,0]],"ltp":0.0,"tv":0.0,"id":11486880}]}]}
{"op":"mcm","clk":"4208336095","pt":1631450221263,"mc":[{"id":"1.187552292","rc":[{"batb":[[0,1.22,531.62],[1,1.01,12]],"ltp":0.0,"tv":0.0,"id":11486880}]}]}
{"op":"mcm","clk":"4208341462","pt":1631450245292,"mc":[{"id":"1.187552292","rc":[{"batb":[[0,1.01,12],[1,1.01,0]],"batl":[[0,11.5,8.68],[1,11.5,0]],"ltp":0.0,"tv":0.0,"id":11486880}]}]}
{"op":"mcm","clk":"4208342728","pt":1631450251221,"mc":[{"id":"1.187552292","rc":[{"batb":[[0,1.18,558.78],[1,1.01,12]],"batl":[[0,1.62,624.53],[1,11.5,8.68]],"ltp":0.0,"tv":0.0,"id":11486880}]}]}
{"op":"mcm","clk":"4208367027","pt":1631450361111,"mc":[{"id":"1.187552292","rc":[{"batb":[[0,1.01,12],[1,1.01,0]],"ltp":0.0,"tv":0.0,"id":11486880}]}]}
{"op":"mcm","clk":"4208368319","pt":1631450366719,"mc":[{"id":"1.187552292","rc":[{"batb":[[0,1.2,539.61],[1,1.01,12]],"ltp":0.0,"tv":0.0,"id":11486880}]}]}
{"op":"mcm","clk":"4208374918","pt":1631450398065,"mc":[{"id":"1.187552292","rc":[{"batb":[[0,1.01,12],[1,1.01,0]],"ltp":0.0,"tv":0.0,"id":11486880}]}]}
{"op":"mcm","clk":"4208376270","pt":1631450404366,"mc":[{"id":"1.187552292","rc":[{"batb":[[0,1.22,531.62],[1,1.01,12]],"ltp":0.0,"tv":0.0,"id":11486880}]}]}
{"op":"mcm","clk":"4208393293","pt":1631450488172,"mc":[{"id":"1.187552292","rc":[{"batb":[[0,1.01,12],[1,1.01,0]],"batl":[[0,11.5,8.68],[1,11.5,0]],"ltp":0.0,"tv":0.0,"id":11486880}]}]}
{"op":"mcm","clk":"4208394380","pt":1631450493660,"mc":[{"id":"1.187552292","rc":[{"batb":[[0,1.28,493.9],[1,1.01,12]],"batl":[[0,1.82,476.84],[1,11.5,8.68]],"ltp":0.0,"tv":0.0,"id":11486880}]}]}
{"op":"mcm","clk":"4208403546","pt":1631450534219,"mc":[{"id":"1.187552292","rc":[{"batb":[[0,1.01,12],[1,1.01,0]],"batl":[[0,11.5,8.68],[1,11.5,0]],"ltp":0.0,"tv":0.0,"id":11486880}]}]}
{"op":"mcm","clk":"4208441708","pt":1631450700306,"mc":[{"id":"1.187552292","rc":[{"batb":[[0,1.16,585.63],[1,1.01,12]],"batl":[[0,1.58,661.3],[1,11.5,8.68]],"ltp":0.0,"tv":0.0,"id":11486880}]}]}
{"op":"mcm","clk":"4208458733","pt":1631450779093,"mc":[{"id":"1.187552292","rc":[{"batb":[[0,1.01,12],[1,1.01,0]],"ltp":0.0,"tv":0.0,"id":11486880}]}]}
{"op":"mcm","clk":"4208459979","pt":1631450784960,"mc":[{"id":"1.187552292","rc":[{"batb":[[0,1.18,558.78],[1,1.01,12]],"ltp":0.0,"tv":0.0,"id":11486880}]}]}
{"op":"mcm","clk":"4208463779","pt":1631450803613,"mc":[{"id":"1.187552292","rc":[{"batb":[[0,1.01,12],[1,1.01,0]],"ltp":0.0,"tv":0.0,"id":11486880}]}]}
{"op":"mcm","clk":"4208464852","pt":1631450809229,"mc":[{"id":"1.187552292","rc":[{"batb":[[0,1.2,539.61],[1,1.01,12]],"ltp":0.0,"tv":0.0,"id":11486880}]}]}
{"op":"mcm","clk":"4208469031","pt":1631450830287,"mc":[{"id":"1.187552292","rc":[{"batb":[[0,1.01,12],[1,1.01,0]],"ltp":0.0,"tv":0.0,"id":11486880}]}]}
{"op":"mcm","clk":"4208470355","pt":1631450836687,"mc":[{"id":"1.187552292","rc":[{"batb":[[0,1.22,531.62],[1,1.01,12]],"ltp":0.0,"tv":0.0,"id":11486880}]}]}
{"op":"mcm","clk":"4208480387","pt":1631450884466,"mc":[{"id":"1.187552292","rc":[{"batb":[[0,1.01,12],[1,1.01,0]],"ltp":0.0,"tv":0.0,"id":11486880}]}]}
{"op":"mcm","clk":"4208481576","pt":1631450890658,"mc":[{"id":"1.187552292","rc":[{"batb":[[0,1.16,585.63],[1,1.01,12]],"ltp":0.0,"tv":0.0,"id":11486880}]}]}
{"op":"mcm","clk":"4208484035","pt":1631450902856,"mc":[{"id":"1.187552292","rc":[{"batb":[[0,1.01,12],[1,1.01,0]],"batl":[[0,11.5,8.68],[1,11.5,0]],"ltp":0.0,"tv":0.0,"id":11486880}]}]}
{"op":"mcm","clk":"4208485192","pt":1631450909006,"mc":[{"id":"1.187552292","rc":[{"batb":[[0,1.12,661.06],[1,1.01,12]],"batl":[[0,1.51,753.29],[1,11.5,8.68]],"ltp":0.0,"tv":0.0,"id":11486880}]}]}
{"op":"mcm","clk":"4208488237","pt":1631450925316,"mc":[{"id":"1.187552292","rc":[{"batb":[[0,1.01,12],[1,1.01,0]],"ltp":0.0,"tv":0.0,"id":11486880}]}]}
{"op":"mcm","clk":"4208489353","pt":1631450931044,"mc":[{"id":"1.187552292","rc":[{"batb":[[0,1.1,735.13],[1,1.01,12]],"ltp":0.0,"tv":0.0,"id":11486880}]}]}
{"op":"mcm","clk":"4208496173","pt":1631450966099,"mc":[{"id":"1.187552292","rc":[{"batb":[[0,1.01,12],[1,1.01,0]],"ltp":0.0,"tv":0.0,"id":11486880}]}]}
{"op":"mcm","clk":"4208497150","pt":1631450971382,"mc":[{"id":"1.187552292","rc":[{"batb":[[0,1.09,765.47],[1,1.01,12]],"ltp":0.0,"tv":0.0,"id":11486880}]}]}
{"op":"mcm","clk":"4208498234","pt":1631450977310,"mc":[{"id":"1.187552292","rc":[{"batb":[[0,1.01,12],[1,1.01,0]],"ltp":0.0,"tv":0.0,"id":11486880}]}]}
{"op":"mcm","clk":"4208499253","pt":1631450982807,"mc":[{"id":"1.187552292","rc":[{"batb":[[0,1.12,661.06],[1,1.01,12]],"ltp":0.0,"tv":0.0,"id":11486880}]}]}
{"op":"mcm","clk":"4208505638","pt":1631451018980,"mc":[{"id":"1.187552292","rc":[{"batb":[[0,1.01,12],[1,1.01,0]],"ltp":0.0,"tv":0.0,"id":11486880}]}]}
{"op":"mcm","clk":"4208506546","pt":1631451024480,"mc":[{"id":"1.187552292","rc":[{"batb":[[0,1.1,735.13],[1,1.01,12]],"ltp":0.0,"tv":0.0,"id":11486880}]}]}
{"op":"mcm","clk":"4208509879","pt":1631451045469,"mc":[{"id":"1.187552292","rc":[{"batb":[[0,1.01,12],[1,1.01,0]],"ltp":0.0,"tv":0.0,"id":11486880}]}]}
{"op":"mcm","clk":"4208510923","pt":1631451051607,"mc":[{"id":"1.187552292","rc":[{"batb":[[0,1.09,765.47],[1,1.01,12]],"ltp":0.0,"tv":0.0,"id":11486880}]}]}
{"op":"mcm","clk":"4208511488","pt":1631451055086,"mc":[{"id":"1.187552292","rc":[{"batl":[[0,11.5,8.68],[1,11.5,0]],"ltp":0.0,"tv":0.0,"id":11486880}]}]}
{"op":"mcm","clk":"4208512457","pt":1631451060854,"mc":[{"id":"1.187552292","rc":[{"batl":[[0,1.44,871.88],[1,11.5,8.68]],"ltp":0.0,"tv":0.0,"id":11486880}]}]}
{"op":"mcm","clk":"4208518068","pt":1631451094347,"mc":[{"id":"1.187552292","rc":[{"batb":[[0,1.01,12],[1,1.01,0]],"ltp":0.0,"tv":0.0,"id":11486880}]}]}
{"op":"mcm","clk":"4208519071","pt":1631451100506,"mc":[{"id":"1.187552292","rc":[{"batb":[[0,1.1,735.13],[1,1.01,12]],"ltp":0.0,"tv":0.0,"id":11486880}]}]}
{"op":"mcm","clk":"4208523464","pt":1631451127774,"mc":[{"id":"1.187552292","rc":[{"batb":[[0,1.01,12],[1,1.01,0]],"ltp":0.0,"tv":0.0,"id":11486880}]}]}
{"op":"mcm","clk":"4208524429","pt":1631451133877,"mc":[{"id":"1.187552292","rc":[{"batb":[[0,1.08,814.16],[1,1.01,12]],"ltp":0.0,"tv":0.0,"id":11486880}]}]}
{"op":"mcm","clk":"4208530409","pt":1631451167534,"mc":[{"id":"1.187552292","rc":[{"batb":[[0,1.01,12],[1,1.01,0]],"ltp":0.0,"tv":0.0,"id":11486880}]}]}
{"op":"mcm","clk":"4208531500","pt":1631451173461,"mc":[{"id":"1.187552292","rc":[{"batb":[[0,1.1,735.13],[1,1.01,12]],"ltp":0.0,"tv":0.0,"id":11486880}]}]}
{"op":"mcm","clk":"4208537756","pt":1631451207292,"mc":[{"id":"1.187552292","rc":[{"batb":[[0,1.01,12],[1,1.01,0]],"ltp":0.0,"tv":0.0,"id":11486880}]}]}
{"op":"mcm","clk":"4208538739","pt":1631451212870,"mc":[{"id":"1.187552292","rc":[{"batb":[[0,1.12,661.06],[1,1.01,12]],"ltp":0.0,"tv":0.0,"id":11486880}]}]}
{"op":"mcm","clk":"4208541769","pt":1631451230715,"mc":[{"id":"1.187552292","rc":[{"batb":[[0,1.01,12],[1,1.01,0]],"ltp":0.0,"tv":0.0,"id":11486880}]}]}
{"op":"mcm","clk":"4208542689","pt":1631451236378,"mc":[{"id":"1.187552292","rc":[{"batb":[[0,1.14,620.51],[1,1.01,12]],"ltp":0.0,"tv":0.0,"id":11486880}]}]}
{"op":"mcm","clk":"4208558932","pt":1631451333899,"mc":[{"id":"1.187552292","rc":[{"batb":[[0,1.01,12],[1,1.01,0]],"ltp":0.0,"tv":0.0,"id":11486880}]}]}
{"op":"mcm","clk":"4208559933","pt":1631451339465,"mc":[{"id":"1.187552292","rc":[{"batb":[[0,1.12,661.06],[1,1.01,12]],"ltp":0.0,"tv":0.0,"id":11486880}]}]}
{"op":"mcm","clk":"4208565258","pt":1631451372552,"mc":[{"id":"1.187552292","rc":[{"batb":[[0,1.01,12],[1,1.01,0]],"ltp":0.0,"tv":0.0,"id":11486880}]}]}
{"op":"mcm","clk":"4208566038","pt":1631451377868,"mc":[{"id":"1.187552292","rc":[{"batb":[[0,1.14,620.51],[1,1.01,12]],"ltp":0.0,"tv":0.0,"id":11486880}]}]}
{"op":"mcm","clk":"4208570215","pt":1631451405173,"mc":[{"id":"1.187552292","rc":[{"batb":[[0,1.01,12],[1,1.01,0]],"ltp":0.0,"tv":0.0,"id":11486880}]}]}
{"op":"mcm","clk":"4208571260","pt":1631451411604,"mc":[{"id":"1.187552292","rc":[{"batb":[[0,1.12,661.06],[1,1.01,12]],"ltp":0.0,"tv":0.0,"id":11486880}]}]}
{"op":"mcm","clk":"4208575118","pt":1631451436742,"mc":[{"id":"1.187552292","rc":[{"batb":[[0,1.01,12],[1,1.01,0]],"ltp":0.0,"tv":0.0,"id":11486880}]}]}
{"op":"mcm","clk":"4208576032","pt":1631451442943,"mc":[{"id":"1.187552292","rc":[{"batb":[[0,1.14,620.51],[1,1.01,12]],"ltp":0.0,"tv":0.0,"id":11486880}]}]}
{"op":"mcm","clk":"4208578586","pt":1631451457966,"mc":[{"id":"1.187552292","rc":[{"batb":[[0,1.01,12],[1,1.01,0]],"batl":[[0,11.5,8.68],[1,11.5,0]],"ltp":0.0,"tv":0.0,"id":11486880}]}]}
{"op":"mcm","clk":"4208579612","pt":1631451464198,"mc":[{"id":"1.187552292","rc":[{"batb":[[0,1.16,585.63],[1,1.01,12]],"batl":[[0,1.58,661.3],[1,11.5,8.68]],"ltp":0.0,"tv":0.0,"id":11486880}]}]}
{"op":"mcm","clk":"4208580381","pt":1631451469093,"mc":[{"id":"1.187552292","rc":[{"batb":[[0,1.01,12],[1,1.01,0]],"batl":[[0,11.5,8.68],[1,11.5,0]],"ltp":0.0,"tv":0.0,"id":11486880}]}]}
{"op":"mcm","clk":"4208581357","pt":1631451474999,"mc":[{"id":"1.187552292","rc":[{"batb":[[0,1.1,735.13],[1,1.01,12]],"batl":[[0,1.48,797.87],[1,11.5,8.68]],"ltp":0.0,"tv":0.0,"id":11486880}]}]}
{"op":"mcm","clk":"4208585140","pt":1631451498741,"mc":[{"id":"1.187552292","rc":[{"batb":[[0,1.01,12],[1,1.01,0]],"ltp":0.0,"tv":0.0,"id":11486880}]}]}
{"op":"mcm","clk":"4208586102","pt":1631451504545,"mc":[{"id":"1.187552292","rc":[{"batb":[[0,1.08,814.16],[1,1.01,12]],"ltp":0.0,"tv":0.0,"id":11486880}]}]}
{"op":"mcm","clk":"4208589046","pt":1631451523179,"mc":[{"id":"1.187552292","rc":[{"batb":[[0,1.01,12],[1,1.01,0]],"batl":[[0,11.5,8.68],[1,11.5,0]],"ltp":0.0,"tv":0.0,"id":11486880}]}]}
{"op":"mcm","clk":"4208589899","pt":1631451528790,"mc":[{"id":"1.187552292","rc":[{"batb":[[0,1.06,1010.28],[1,1.01,12]],"batl":[[0,1.41,917.52],[1,11.5,8.68]],"ltp":0.0,"tv":0.0,"id":11486880}]}]}
{"op":"mcm","clk":"4208602366","pt":1631451607432,"mc":[{"id":"1.187552292","rc":[{"batb":[[0,1.01,12],[1,1.01,0]],"ltp":0.0,"tv":0.0,"id":11486880}]}]}
{"op":"mcm","clk":"4208603504","pt":1631451612998,"mc":[{"id":"1.187552292","rc":[{"batb":[[0,1.09,765.47],[1,1.01,12]],"ltp":0.0,"tv":0.0,"id":11486880}]}]}
{"op":"mcm","clk":"4208606191","pt":1631451628839,"mc":[{"id":"1.187552292","rc":[{"batb":[[0,1.01,12],[1,1.01,0]],"ltp":0.0,"tv":0.0,"id":11486880}]}]}
{"op":"mcm","clk":"4208607201","pt":1631451635051,"mc":[{"id":"1.187552292","rc":[{"batb":[[0,1.06,1010.28],[1,1.01,12]],"ltp":0.0,"tv":0.0,"id":11486880}]}]}
{"op":"mcm","clk":"4208609302","pt":1631451647192,"mc":[{"id":"1.187552292","rc":[{"batb":[[0,1.01,12],[1,1.01,0]],"ltp":0.0,"tv":0.0,"id":11486880}]}]}
{"op":"mcm","clk":"4208610719","pt":1631451653526,"mc":[{"id":"1.187552292","rc":[{"batb":[[0,1.09,765.47],[1,1.01,12]],"ltp":0.0,"tv":0.0,"id":11486880}]}]}
{"op":"mcm","clk":"4208615986","pt":1631451680672,"mc":[{"id":"1.187552292","rc":[{"batb":[[0,1.01,12],[1,1.01,0]],"ltp":0.0,"tv":0.0,"id":11486880}]}]}
{"op":"mcm","clk":"4208617234","pt":1631451686582,"mc":[{"id":"1.187552292","rc":[{"batb":[[0,1.06,1010.28],[1,1.01,12]],"ltp":0.0,"tv":0.0,"id":11486880}]}]}
{"op":"mcm","clk":"4208625357","pt":1631451726636,"mc":[{"id":"1.187552292","rc":[{"batb":[[0,1.01,12],[1,1.01,0]],"ltp":0.0,"tv":0.0,"id":11486880}]}]}
{"op":"mcm","clk":"4208626452","pt":1631451732141,"mc":[{"id":"1.187552292","rc":[{"batb":[[0,1.05,1087.21],[1,1.01,12]],"ltp":0.0,"tv":0.0,"id":11486880}]}]}
{"op":"mcm","clk":"4208632824","pt":1631451762111,"mc":[{"id":"1.187552292","rc":[{"batb":[[0,1.01,12],[1,1.01,0]],"ltp":0.0,"tv":0.0,"id":11486880}]}]}
{"op":"mcm","clk":"4208634077","pt":1631451767934,"mc":[{"id":"1.187552292","rc":[{"batb":[[0,1.04,1254.9],[1,1.01,12]],"ltp":0.0,"tv":0.0,"id":11486880}]}]}
{"op":"mcm","clk":"4208646289","pt":1631451828004,"mc":[{"id":"1.187552292","rc":[{"batb":[[0,1.01,12],[1,1.01,0]],"ltp":0.0,"tv":0.0,"id":11486880}]}]}
{"op":"mcm","clk":"4208647687","pt":1631451833485,"mc":[{"id":"1.187552292","rc":[{"batb":[[0,1.05,1087.21],[1,1.01,12]],"ltp":0.0,"tv":0.0,"id":11486880}]}]}
{"op":"mcm","clk":"4208655758","pt":1631451864450,"mc":[{"id":"1.187552292","rc":[{"batb":[[0,1.01,12],[1,1.01,0]],"ltp":0.0,"tv":0.0,"id":11486880}]}]}
{"op":"mcm","clk":"4208657543","pt":1631451870787,"mc":[{"id":"1.187552292","rc":[{"batb":[[0,1.06,1010.28],[1,1.01,12]],"ltp":0.0,"tv":0.0,"id":11486880}]}]}
{"op":"mcm","clk":"4208661703","pt":1631451887803,"mc":[{"id":"1.187552292","rc":[{"batb":[[0,1.01,12],[1,1.01,0]],"ltp":0.0,"tv":0.0,"id":11486880}]}]}
{"op":"mcm","clk":"4208663180","pt":1631451894104,"mc":[{"id":"1.187552292","rc":[{"batb":[[0,1.08,814.16],[1,1.01,12]],"ltp":0.0,"tv":0.0,"id":11486880}]}]}
{"op":"mcm","clk":"4208665671","pt":1631451904998,"mc":[{"id":"1.187552292","rc":[{"batb":[[0,1.01,12],[1,1.01,0]],"ltp":0.0,"tv":0.0,"id":11486880}]}]}
{"op":"mcm","clk":"4208667193","pt":1631451910955,"mc":[{"id":"1.187552292","rc":[{"batb":[[0,1.09,765.47],[1,1.01,12]],"ltp":0.0,"tv":0.0,"id":11486880}]}]}
{"op":"mcm","clk":"4208675669","pt":1631451948594,"mc":[{"id":"1.187552292","rc":[{"batb":[[0,1.01,12],[1,1.01,0]],"ltp":0.0,"tv":0.0,"id":11486880}]}]}
{"op":"mcm","clk":"4208676950","pt":1631451954612,"mc":[{"id":"1.187552292","rc":[{"batb":[[0,1.06,1010.28],[1,1.01,12]],"ltp":0.0,"tv":0.0,"id":11486880}]}]}
{"op":"mcm","clk":"4208680264","pt":1631451969930,"mc":[{"id":"1.187552292","rc":[{"batb":[[0,1.01,12],[1,1.01,0]],"ltp":0.0,"tv":0.0,"id":11486880}]}]}
{"op":"mcm","clk":"4208681607","pt":1631451975662,"mc":[{"id":"1.187552292","rc":[{"batb":[[0,1.09,765.47],[1,1.01,12]],"ltp":0.0,"tv":0.0,"id":11486880}]}]}
{"op":"mcm","clk":"4208690110","pt":1631452017535,"mc":[{"id":"1.187552292","rc":[{"batb":[[0,1.01,12],[1,1.01,0]],"ltp":0.0,"tv":0.0,"id":11486880}]}]}
{"op":"mcm","clk":"4208691205","pt":1631452023227,"mc":[{"id":"1.187552292","rc":[{"batb":[[0,1.06,1010.28],[1,1.01,12]],"ltp":0.0,"tv":0.0,"id":11486880}]}]}
{"op":"mcm","clk":"4208702460","pt":1631452077534,"mc":[{"id":"1.187552292","rc":[{"batb":[[0,1.01,12],[1,1.01,0]],"ltp":0.0,"tv":0.0,"id":11486880}]}]}
{"op":"mcm","clk":"4208702547","pt":1631452077920,"mc":[{"id":"1.187552292","rc":[{"batl":[[0,11.5,8.68],[1,11.5,0]],"ltp":0.0,"tv":0.0,"id":11486880}]}]}
{"op":"mcm","clk":"4208703848","pt":1631452083845,"mc":[{"id":"1.187552292","rc":[{"batb":[[0,1.06,952.24],[1,1.01,12]],"ltp":0.0,"tv":0.0,"id":11486880}]}]}
{"op":"mcm","clk":"4208707973","pt":1631452102776,"mc":[{"id":"1.187552292","rc":[{"batb":[[0,1.01,12],[1,1.01,0]],"ltp":0.0,"tv":0.0,"id":11486880}]}]}
{"op":"mcm","clk":"4208709364","pt":1631452108980,"mc":[{"id":"1.187552292","rc":[{"batb":[[0,1.05,1087.21],[1,1.01,12]],"ltp":0.0,"tv":0.0,"id":11486880}]}]}
{"op":"mcm","clk":"4208713324","pt":1631452127015,"mc":[{"id":"1.187552292","rc":[{"batb":[[0,1.01,12],[1,1.01,0]],"ltp":0.0,"tv":0.0,"id":11486880}]}]}
{"op":"mcm","clk":"4208714660","pt":1631452133127,"mc":[{"id":"1.187552292","rc":[{"batb":[[0,1.04,1254.9],[1,1.01,12]],"ltp":0.0,"tv":0.0,"id":11486880}]}]}
{"op":"mcm","clk":"4208738654","pt":1631452235664,"mc":[{"id":"1.187552292","rc":[{"batb":[[0,1.01,12],[1,1.01,0]],"ltp":0.0,"tv":0.0,"id":11486880}]}]}
{"op":"mcm","clk":"4208739965","pt":1631452241262,"mc":[{"id":"1.187552292","rc":[{"batb":[[0,1.05,1087.21],[1,1.01,12]],"ltp":0.0,"tv":0.0,"id":11486880}]}]}
{"op":"mcm","clk":"4208748330","pt":1631452278151,"mc":[{"id":"1.187552292","rc":[{"batb":[[0,1.01,12],[1,1.01,0]],"ltp":0.0,"tv":0.0,"id":11486880}]}]}
{"op":"mcm","clk":"4208749656","pt":1631452283886,"mc":[{"id":"1.187552292","rc":[{"batb":[[0,1.06,1010.28],[1,1.01,12]],"ltp":0.0,"tv":0.0,"id":11486880}]}]}
{"op":"mcm","clk":"4208752655","pt":1631452297382,"mc":[{"id":"1.187552292","rc":[{"batb":[[0,1.01,12],[1,1.01,0]],"ltp":0.0,"tv":0.0,"id":11486880}]}]}
{"op":"mcm","clk":"4208753941","pt":1631452302987,"mc":[{"id":"1.187552292","rc":[{"batb":[[0,1.06,952.24],[1,1.01,12]],"ltp":0.0,"tv":0.0,"id":11486880}]}]}
{"op":"mcm","clk":"4208754313","pt":1631452304587,"mc":[{"id":"1.187552292","rc":[{"batb":[[0,1.01,12],[1,1.01,0]],"ltp":0.0,"tv":0.0,"id":11486880}]}]}
{"op":"mcm","clk":"4208785506","pt":1631452446304,"mc":[{"id":"1.187552292","rc":[{"batl":[[0,1.32,1173.52],[1,11.5,8.68]],"ltp":0.0,"tv":0.0,"id":11486880}]}]}
{"op":"mcm","clk":"4208785720","pt":1631452447289,"mc":[{"id":"1.187552292","rc":[{"batb":[[0,1.01,4176.78]],"ltp":0.0,"tv":0.0,"id":11486880}]}]}
{"op":"mcm","clk":"4208796528","pt":1631452496900,"mc":[{"id":"1.187552292","rc":[{"batb":[[0,1.01,12]],"ltp":0.0,"tv":0.0,"id":11486880}]}]}
{"op":"mcm","clk":"4208797826","pt":1631452503295,"mc":[{"id":"1.187552292","rc":[{"batl":[[0,170,37.59]],"ltp":0.0,"tv":0.0,"id":9631381}]}]}
{"op":"mcm","clk":"4208805447","pt":1631452541529,"mc":[{"id":"1.187552292","rc":[{"batb":[[0,1.01,4176.78]],"ltp":0.0,"tv":0.0,"id":11486880}]}]}
{"op":"mcm","clk":"4208812474","pt":1631452575850,"mc":[{"id":"1.187552292","rc":[{"batb":[[0,1.01,12]],"ltp":0.0,"tv":0.0,"id":11486880}]}]}
{"op":"mcm","clk":"4208813700","pt":1631452581827,"mc":[{"id":"1.187552292","rc":[{"batl":[[0,170,37.59]],"ltp":0.0,"tv":0.0,"id":9631381}]}]}
{"op":"mcm","clk":"4208829689","pt":1631452661754,"mc":[{"id":"1.187552292","rc":[{"batl":[[0,11.5,8.68],[1,11.5,0]],"ltp":0.0,"tv":0.0,"id":11486880}]}]}
{"op":"mcm","clk":"4208841784","pt":1631452673697,"mc":[{"id":"1.187552292","rc":[{"batl":[[0,170,37.59]],"ltp":0.0,"tv":0.0,"id":9631381},{"batl":[[0,1.3,1247.38],[1,11.5,8.68]],"ltp":0.0,"tv":0.0,"id":11486880}]}]}
{"op":"mcm","clk":"4208853047","pt":1631452731769,"mc":[{"id":"1.187552292","rc":[{"batl":[[0,11.5,8.68],[1,11.5,0]],"ltp":0.0,"tv":0.0,"id":11486880}]}]}
{"op":"mcm","clk":"4208855651","pt":1631452745485,"mc":[{"id":"1.187552292","rc":[{"batl":[[0,1.28,1370.09],[1,11.5,8.68]],"ltp":0.0,"tv":0.0,"id":11486880}]}]}
{"op":"mcm","clk":"4208885160","pt":1631452904853,"mc":[{"id":"1.187552292","rc":[{"batl":[[0,11.5,8.68],[1,11.5,0]],"ltp":0.0,"tv":0.0,"id":11486880}]}]}
{"op":"mcm","clk":"4208890934","pt":1631452935816,"mc":[{"id":"1.187552292","rc":[{"batl":[[0,1.27,1416.65],[1,11.5,8.68]],"ltp":0.0,"tv":0.0,"id":11486880}]}]}
{"op":"mcm","clk":"4208893620","pt":1631452950000,"mc":[{"id":"1.187552292","rc":[{"trd":[[1.01,24]],"batl":[[0,1.01,45],[1,1.27,1416.65],[2,11.5,8.68]],"ltp":1.01,"tv":24.0,"id":11486880}],"tv":24.0}]}
{"op":"mcm","clk":"4208895547","pt":1631452960665,"mc":[{"id":"1.187552292","rc":[{"batl":[[0,1.27,1416.65],[1,11.5,8.68],[2,11.5,0]],"ltp":1.01,"tv":24.0,"id":11486880}]}]}
{"op":"mcm","clk":"4208896426","pt":1631452965483,"mc":[{"id":"1.187552292","rc":[{"batl":[[0,11.5,8.68],[1,11.5,0]],"ltp":1.01,"tv":24.0,"id":11486880}]}]}
{"op":"mcm","clk":"4208912832","pt":1631453056005,"mc":[{"id":"1.187552292","rc":[{"batl":[[0,1.27,1397.51],[1,11.5,8.68]],"ltp":1.01,"tv":24.0,"id":11486880}]}]}
{"op":"mcm","clk":"4208929775","pt":1631453140621,"mc":[{"id":"1.187552292","rc":[{"batl":[[0,11.5,8.68],[1,11.5,0]],"ltp":1.01,"tv":24.0,"id":11486880}]}]}
{"op":"mcm","clk":"4208938135","pt":1631453182157,"mc":[{"id":"1.187552292","rc":[{"batl":[[0,1.27,1416.65],[1,11.5,8.68]],"ltp":1.01,"tv":24.0,"id":11486880}]}]}
{"op":"mcm","clk":"4208940040","pt":1631453192277,"mc":[{"id":"1.187552292","rc":[{"batl":[[0,11.5,8.68],[1,11.5,0]],"ltp":1.01,"tv":24.0,"id":11486880}]}]}
{"op":"mcm","clk":"4208943825","pt":1631453212388,"mc":[{"id":"1.187552292","rc":[{"batl":[[0,1.27,1397.51],[1,11.5,8.68]],"ltp":1.01,"tv":24.0,"id":11486880}]}]}
{"op":"mcm","clk":"4208947371","pt":1631453231648,"mc":[{"id":"1.187552292","rc":[{"batl":[[0,11.5,8.68],[1,11.5,0]],"ltp":1.01,"tv":24.0,"id":11486880}]}]}
{"op":"mcm","clk":"4208951602","pt":1631453253990,"mc":[{"id":"1.187552292","rc":[{"batl":[[0,1.27,1416.65],[1,11.5,8.68]],"ltp":1.01,"tv":24.0,"id":11486880}]}]}
{"op":"mcm","clk":"4208953826","pt":1631453266106,"mc":[{"id":"1.187552292","rc":[{"batl":[[0,11.5,8.68],[1,11.5,0]],"ltp":1.01,"tv":24.0,"id":11486880}]}]}
{"op":"mcm","clk":"4208973733","pt":1631453372084,"mc":[{"id":"1.187552292","rc":[{"batl":[[0,11,256.21],[1,11.5,8.68]],"ltp":1.01,"tv":24.0,"id":11486880}]}]}
{"op":"mcm","clk":"4208974348","pt":1631453375671,"mc":[{"id":"1.187552292","marketDefinition":{"bspMarket":false,"turnInPlayEnabled":true,"persistenceEnabled":true,"marketBaseRate":5.0,"eventId":"30895224","eventTypeId":"2","numberOfWinners":1,"bettingType":"ODDS","marketType":"MATCH_ODDS","marketTime":"2021-09-12T12:19:25.000Z","suspendTime":"2021-09-12T12:19:25.000Z","bspReconciled":false,"complete":true,"inPlay":true,"crossMatching":true,"runnersVoidable":false,"numberOfActiveRunners":2,"betDelay":5,"status":"SUSPENDED","runners":[{"status":"ACTIVE","sortPriority":1,"id":11486880,"name":"S Ma"},{"status":"ACTIVE","sortPriority":2,"id":9631381,"name":"O Nicholls"}],"regulators":["MR_INT"],"countryCode":"GB","discountAllowed":true,"timezone":"GMT","openDate":"2021-09-12T12:19:25.000Z","version":4028374266,"name":"Match Odds","eventName":"S Ma v O Nicholls"}}]}
{"op":"mcm","clk":"4208975145","pt":1631453379702,"mc":[{"id":"1.187552292","marketDefinition":{"bspMarket":false,"turnInPlayEnabled":true,"persistenceEnabled":true,"marketBaseRate":5.0,"eventId":"30895224","eventTypeId":"2","numberOfWinners":1,"bettingType":"ODDS","marketType":"MATCH_ODDS","marketTime":"2021-09-12T12:19:25.000Z","suspendTime":"2021-09-12T12:19:25.000Z","bspReconciled":false,"complete":true,"inPlay":true,"crossMatching":false,"runnersVoidable":false,"numberOfActiveRunners":0,"betDelay":5,"status":"CLOSED","settledTime":"2021-09-12T13:29:37.000Z","runners":[{"status":"WINNER","sortPriority":1,"id":11486880,"name":"S Ma"},{"status":"LOSER","sortPriority":2,"id":9631381,"name":"O Nicholls"}],"regulators":["MR_INT"],"countryCode":"GB","discountAllowed":true,"timezone":"GMT","openDate":"2021-09-12T12:19:25.000Z","version":4028374384,"name":"Match Odds","eventName":"S Ma v O Nicholls"},"tv":0.0}]}
