{"op":"mcm","clk":"4226590036","pt":1631450134043,"mc":[{"id":"1.187552454","rc":[{"batl":[[2,3.95,10.35]],"ltp":3.3,"tv":4543.35,"id":9345630}]}]}
{"op":"mcm","clk":"4226590200","pt":1631450135059,"mc":[{"id":"1.187552454","rc":[{"trd":[[3.4,0.02]],"batl":[[0,3.4,2.98],[2,3.9,2.55]],"ltp":3.4,"tv":4543.37,"id":9345630},{"trd":[[1.41,562.98]],"batb":[[0,1.4,311.89],[1,1.39,446.07],[2,1.38,762.23]],"batl":[[2,1.44,1644.82]],"ltp":1.41,"tv":52375.12,"id":9028621}],"tv":56918.49}]}
{"op":"mcm","clk":"4226590305","pt":1631450135857,"mc":[{"id":"1.187552454","rc":[{"trd":[[1.42,1404.2]],"batl":[[0,1.42,9.42]],"ltp":1.42,"tv":52378.75,"id":9028621}],"tv":56922.13}]}
{"op":"mcm","clk":"4226590515","pt":1631450137266,"mc":[{"id":"1.187552454","rc":[{"batl":[[2,3.7,36.51]],"ltp":3.4,"tv":4543.37,"id":9345630}]}]}
{"op":"mcm","clk":"4226590663","pt":1631450138178,"mc":[{"id":"1.187552454","rc":[{"batb":[[0,1.4,377.54]],"ltp":1.42,"tv":52378.75,"id":9028621}]}]}
{"op":"mcm","clk":"4226590878","pt":1631450139467,"mc":[{"id":"1.187552454","rc":[{"trd":[[3.4,0.1]],"batl":[[0,3.4,2.9]],"ltp":3.4,"tv":4543.45,"id":9345630},{"trd":[[1.41,563.17],[1.42,1405.37]],"batl":[[0,1.42,228.71]],"ltp":1.41,"tv":52380.12,"id":9028621}],"tv":56923.57}]}
{"op":"mcm","clk":"4226591058","pt":1631450140488,"mc":[{"id":"1.187552454","rc":[{"batl":[[2,1.44,325.57]],"ltp":1.41,"tv":52380.12,"id":9028621}]}]}
{"op":"mcm","clk":"4226591307","pt":1631450142050,"mc":[{"id":"1.187552454","rc":[{"trd":[[3.4,0.62]],"batl":[[0,3.4,2.38]],"ltp":3.4,"tv":4543.97,"id":9345630},{"trd":[[1.41,564.42]],"ltp":1.41,"tv":52381.37,"id":9028621}],"tv":56925.34}]}
{"op":"mcm","clk":"4226591526","pt":1631450143570,"mc":[{"id":"1.187552454","rc":[{"trd":[[1.42,1428.31]],"batl":[[0,1.42,217.24]],"ltp":1.42,"tv":52404.31,"id":9028621}],"tv":56948.29}]}
{"op":"mcm","clk":"4226591706","pt":1631450144978,"mc":[{"id":"1.187552454","rc":[{"trd":[[1.42,1438.92]],"batl":[[0,1.42,211.93]],"ltp":1.42,"tv":52414.92,"id":9028621}],"tv":56958.89}]}
{"op":"mcm","clk":"4226591911","pt":1631450146282,"mc":[{"id":"1.187552454","rc":[{"trd":[[3.35,430.18]],"batl":[[0,3.35,10.17],[1,3.4,2.38],[2,3.6,8.36]],"ltp":3.35,"tv":4633.8,"id":9345630},{"trd":[[1.42,1650.85]],"batl":[[0,1.43,275.93],[1,1.44,320.03],[2,1.45,185.11]],"ltp":1.42,"tv":52626.85,"id":9028621}],"tv":57260.66}]}
{"op":"mcm","clk":"4226592052","pt":1631450147038,"mc":[{"id":"1.187552454","rc":[{"batb":[[0,3.2,3],[1,1.01,30],[2,2.86,0]],"ltp":3.35,"tv":4633.8,"id":9345630}]}]}
{"op":"mcm","clk":"4226592436","pt":1631450149468,"mc":[{"id":"1.187552454","rc":[{"trd":[[3.35,450.2]],"batl":[[0,3.4,2.54],[1,3.6,8.36],[2,3.7,36.51]],"ltp":3.35,"tv":4653.82,"id":9345630}],"tv":57280.68}]}
{"op":"mcm","clk":"4226592608","pt":1631450150397,"mc":[{"id":"1.187552454","rc":[{"trd":[[3.35,450.29]],"batl":[[0,3.35,46.19],[1,3.4,2.38],[2,3.6,8.36]],"ltp":3.35,"tv":4653.91,"id":9345630},{"trd":[[1.42,1651.06]],"ltp":1.42,"tv":52627.06,"id":9028621}],"tv":57280.97}]}
{"op":"mcm","clk":"4226592648","pt":1631450150666,"mc":[{"id":"1.187552454","rc":[{"trd":[[3.35,467.54]],"batl":[[0,3.35,28.94]],"ltp":3.35,"tv":4671.16,"id":9345630},{"trd":[[1.42,1691.77]],"ltp":1.42,"tv":52667.77,"id":9028621}],"tv":57338.94}]}
{"op":"mcm","clk":"4226593095","pt":1631450153488,"mc":[{"id":"1.187552454","rc":[{"trd":[[3.35,476.24]],"batb":[[0,3.25,26.66],[1,3.2,3],[2,2.86,85.4]],"batl":[[0,3.35,24.59]],"ltp":3.35,"tv":4679.86,"id":9345630}],"tv":57347.63}]}
{"op":"mcm","clk":"4226593183","pt":1631450154007,"mc":[{"id":"1.187552454","rc":[{"trd":[[3.35,493.08]],"batl":[[0,3.35,16.17]],"ltp":3.35,"tv":4696.7,"id":9345630}],"tv":57364.47}]}
{"op":"mcm","clk":"4226593390","pt":1631450155297,"mc":[{"id":"1.187552454","rc":[{"batb":[[1,1.01,30],[2,2.86,0]],"batl":[[0,3.4,2.38],[1,3.7,36.51],[2,3.9,2.55]],"ltp":3.35,"tv":4696.7,"id":9345630},{"batb":[[0,1.37,24.65],[1,1.35,66.47],[2,1.32,64.89]],"batl":[[0,1.43,60],[1,1.68,635.46],[2,3.8,27.47]],"ltp":1.42,"tv":52667.77,"id":9028621}]}]}
{"op":"mcm","clk":"4226593550","pt":1631450156410,"mc":[{"id":"1.187552454","rc":[{"batb":[[0,1.01,30],[1,1.01,0]],"batl":[[0,3.9,2.55],[1,4.2,2.18],[2,4.3,2.15]],"ltp":3.35,"tv":4696.7,"id":9345630},{"batb":[[0,1.35,66.47],[1,1.32,64.89],[2,1.31,63.79]],"batl":[[0,1.68,635.46],[1,3.8,27.47],[2,8.8,7.23]],"ltp":1.42,"tv":52667.77,"id":9028621}]}]}
{"op":"mcm","clk":"4226593591","pt":1631450156686,"mc":[{"id":"1.187552454","rc":[{"batl":[[0,4.3,2.15],[1,4.8,2.02],[2,990,0.01]],"ltp":3.35,"tv":4696.7,"id":9345630},{"batb":[[0,1.31,63.79],[1,1.27,73.03],[2,1.24,426.73]],"ltp":1.42,"tv":52667.77,"id":9028621}]}]}
{"op":"mcm","clk":"4226593874","pt":1631450158506,"mc":[{"id":"1.187552454","rc":[{"batl":[[0,1.51,7],[1,1.68,635.46],[2,3.8,27.47]],"ltp":1.42,"tv":52667.77,"id":9028621}]}]}
{"op":"mcm","clk":"4226594156","pt":1631450160195,"mc":[{"id":"1.187552454","rc":[{"batb":[[0,2.46,3],[1,2.44,3],[2,1.01,30]],"batl":[[0,3.9,2],[1,4.3,5.15],[2,4.8,2.02]],"ltp":3.35,"tv":4696.7,"id":9345630},{"batb":[[0,1.35,8],[1,1.34,6],[2,1.33,8]],"batl":[[1,1.68,639.46]],"ltp":1.42,"tv":52667.77,"id":9028621}]}]}
{"op":"mcm","clk":"4226594334","pt":1631450161405,"mc":[{"id":"1.187552454","rc":[{"batb":[[0,3.2,19.57],[1,2.96,3],[2,2.94,4]],"batl":[[0,3.4,18.99],[1,3.9,2],[2,3.95,3]],"ltp":3.35,"tv":4696.7,"id":9345630},{"batb":[[0,1.41,543.79],[1,1.4,370.43],[2,1.35,8]],"batl":[[0,1.45,315.57],[1,1.46,301.57],[2,1.51,7]],"ltp":1.42,"tv":52667.77,"id":9028621}]}]}
{"op":"mcm","clk":"4226594373","pt":1631450161717,"mc":[{"id":"1.187552454","rc":[{"batb":[[0,2.96,3],[1,2.94,4],[2,2.46,3]],"batl":[[0,3.9,2],[1,3.95,3],[2,4.3,5.15]],"ltp":3.35,"tv":4696.7,"id":9345630},{"batl":[[0,1.45,294.07]],"ltp":1.42,"tv":52667.77,"id":9028621}]}]}
{"op":"mcm","clk":"4226594647","pt":1631450163498,"mc":[{"id":"1.187552454","rc":[{"batl":[[0,3.85,10.75],[1,3.9,4.55],[2,3.95,3]],"ltp":3.35,"tv":4696.7,"id":9345630},{"batb":[[2,1.35,74.27]],"batl":[[2,1.5,35]],"ltp":1.42,"tv":52667.77,"id":9028621}]}]}
{"op":"mcm","clk":"4226595134","pt":1631450166491,"mc":[{"id":"1.187552454","rc":[{"batb":[[0,2.98,15],[1,2.96,3],[2,2.94,4]],"ltp":3.35,"tv":4696.7,"id":9345630},{"batb":[[0,1.42,41.41],[1,1.41,543.79],[2,1.4,370.43]],"ltp":1.42,"tv":52667.77,"id":9028621}]}]}
{"op":"mcm","clk":"4226595151","pt":1631450166599,"mc":[{"id":"1.187552454","rc":[{"trd":[[1.45,6360.76]],"batl":[[0,1.45,293.52]],"ltp":1.45,"tv":52668.87,"id":9028621}],"tv":57365.57}]}
{"op":"mcm","clk":"4226595423","pt":1631450168408,"mc":[{"id":"1.187552454","rc":[{"batb":[[1,1.35,74.27],[2,1.34,6]],"batl":[[0,1.5,35],[1,1.51,7],[2,1.68,639.46]],"ltp":1.45,"tv":52668.87,"id":9028621}]}]}
{"op":"mcm","clk":"4226595583","pt":1631450169384,"mc":[{"id":"1.187552454","rc":[{"batb":[[0,2.96,3],[1,2.94,4],[2,2.46,3]],"batl":[[0,3.9,2],[1,3.95,3],[2,4.3,5.15]],"ltp":3.35,"tv":4696.7,"id":9345630},{"batb":[[0,1.35,8],[1,1.34,6],[2,1.33,8]],"batl":[[0,1.51,7],[1,1.68,639.46],[2,3.8,27.47]],"ltp":1.45,"tv":52668.87,"id":9028621}]}]}
{"op":"mcm","clk":"4226595696","pt":1631450170103,"mc":[{"id":"1.187552454","rc":[{"batl":[[0,3.9,2.44]],"ltp":3.35,"tv":4696.7,"id":9345630}]}]}
{"op":"mcm","clk":"4226595907","pt":1631450171510,"mc":[{"id":"1.187552454","rc":[{"batb":[[2,1.01,30]],"batl":[[0,3.95,3.44],[1,4.3,2.15],[2,4.8,2.02]],"ltp":3.35,"tv":4696.7,"id":9345630},{"batb":[[1,1.34,595.62],[2,1.33,473.75]],"batl":[[1,1.53,399.54],[2,1.54,243.84]],"ltp":1.45,"tv":52668.87,"id":9028621}]}]}
{"op":"mcm","clk":"4226596033","pt":1631450172313,"mc":[{"id":"1.187552454","rc":[{"batl":[[0,3.9,2.89],[1,3.95,3],[2,4.3,2.15]],"ltp":3.35,"tv":4696.7,"id":9345630},{"batb":[[0,1.35,65.67]],"ltp":1.45,"tv":52668.87,"id":9028621}]}]}
{"op":"mcm","clk":"4226596076","pt":1631450172608,"mc":[{"id":"1.187552454","rc":[{"batl":[[0,3.95,3.44],[1,4.3,2.15],[2,4.8,2.02]],"ltp":3.35,"tv":4696.7,"id":9345630},{"batb":[[0,1.35,8]],"ltp":1.45,"tv":52668.87,"id":9028621}]}]}
{"op":"mcm","clk":"4226596373","pt":1631450174429,"mc":[{"id":"1.187552454","rc":[{"batb":[[1,1.01,30],[2,1.01,0]],"batl":[[0,3.95,3]],"ltp":3.35,"tv":4696.7,"id":9345630}]}]}
{"op":"mcm","clk":"4226596439","pt":1631450174814,"mc":[{"id":"1.187552454","rc":[{"batl":[[0,3.9,2],[1,3.95,3],[2,4.3,2.15]],"ltp":3.35,"tv":4696.7,"id":9345630},{"batb":[[1,1.34,601.62]],"ltp":1.45,"tv":52668.87,"id":9028621}]}]}
{"op":"mcm","clk":"4226597000","pt":1631450177324,"mc":[{"id":"1.187552454","rc":[{"batl":[[0,1.51,7.6]],"ltp":1.45,"tv":52668.87,"id":9028621}]}]}
{"op":"mcm","clk":"4226597059","pt":1631450177616,"mc":[{"id":"1.187552454","rc":[{"batb":[[1,2.94,3],[2,1.01,30]],"ltp":3.35,"tv":4696.7,"id":9345630}]}]}
{"op":"mcm","clk":"4226597400","pt":1631450179506,"mc":[{"id":"1.187552454","rc":[{"batl":[[0,3.9,4.55]],"ltp":3.35,"tv":4696.7,"id":9345630},{"batb":[[0,1.35,67.67]],"ltp":1.45,"tv":52668.87,"id":9028621}]}]}
{"op":"mcm","clk":"4226597481","pt":1631450179944,"mc":[{"id":"1.187552454","rc":[{"batl":[[0,3.9,2]],"ltp":3.35,"tv":4696.7,"id":9345630},{"batb":[[0,1.35,8]],"ltp":1.45,"tv":52668.87,"id":9028621}]}]}
{"op":"mcm","clk":"4226598575","pt":1631450187246,"mc":[{"id":"1.187552454","rc":[{"batl":[[1,4.3,2.15],[2,4.8,2.02]],"ltp":3.35,"tv":4696.7,"id":9345630},{"batb":[[0,1.36,73.13],[1,1.35,8],[2,1.34,595.62]],"ltp":1.45,"tv":52668.87,"id":9028621}]}]}
{"op":"mcm","clk":"4226598651","pt":1631450187834,"mc":[{"id":"1.187552454","rc":[{"trd":[[1.36,1397.23]],"batb":[[0,1.36,51.44]],"ltp":1.36,"tv":52712.25,"id":9028621}],"tv":57408.96}]}
{"op":"mcm","clk":"4226599030","pt":1631450190557,"mc":[{"id":"1.187552454","rc":[{"batb":[[1,1.01,30],[2,1.01,0]],"batl":[[0,3.9,4.35]],"ltp":3.35,"tv":4696.7,"id":9345630},{"batb":[[1,1.35,69.07],[2,1.34,601.62]],"ltp":1.36,"tv":52712.25,"id":9028621}]}]}
{"op":"mcm","clk":"4226599058","pt":1631450190771,"mc":[{"id":"1.187552454","rc":[{"batl":[[0,3.9,2]],"ltp":3.35,"tv":4696.7,"id":9345630},{"batb":[[1,1.35,8]],"ltp":1.36,"tv":52712.25,"id":9028621}]}]}
{"op":"mcm","clk":"4226599605","pt":1631450194550,"mc":[{"id":"1.187552454","rc":[{"batb":[[0,3.65,523.97],[1,3.6,508.56],[2,3.55,508.56]],"batl":[[0,3.9,4.15]],"ltp":3.35,"tv":4696.7,"id":9345630},{"trd":[[1.36,1414.32]],"batb":[[0,1.36,42.9],[1,1.35,72.27]],"batl":[[0,1.38,4067.56],[1,1.51,7.6],[2,1.53,399.54]],"ltp":1.36,"tv":52729.33,"id":9028621}],"tv":57426.04}]}
{"op":"mcm","clk":"4226599740","pt":1631450195476,"mc":[{"id":"1.187552454","rc":[{"batb":[[0,3.65,26.2],[1,3.6,25.43],[2,3.55,25.43]],"batl":[[0,3.9,2]],"ltp":3.35,"tv":4696.7,"id":9345630},{"batb":[[1,1.35,8]],"batl":[[0,1.38,4054.68],[2,1.68,635.46]],"ltp":1.36,"tv":52729.33,"id":9028621}]}]}
{"op":"mcm","clk":"4226600022","pt":1631450197457,"mc":[{"id":"1.187552454","rc":[{"batl":[[0,4.3,2.15],[1,4.8,2.02],[2,990,0.01]],"ltp":3.35,"tv":4696.7,"id":9345630},{"batb":[[1,1.34,595.62],[2,1.33,473.75]],"ltp":1.36,"tv":52729.33,"id":9028621}]}]}
{"op":"mcm","clk":"4226600163","pt":1631450198539,"mc":[{"id":"1.187552454","rc":[{"trd":[[3.65,129.64]],"batb":[[0,3.65,44.97],[1,3.6,69.07],[2,3.55,69.07]],"ltp":3.65,"tv":4786.5,"id":9345630},{"batl":[[0,1.37,11.65],[1,1.38,4602.16],[2,1.39,374.8]],"ltp":1.36,"tv":52729.33,"id":9028621}],"tv":57515.83}]}
{"op":"mcm","clk":"4226600207","pt":1631450198853,"mc":[{"id":"1.187552454","rc":[{"batl":[[1,1.38,547.48]],"ltp":1.36,"tv":52729.33,"id":9028621}]}]}
{"op":"mcm","clk":"4226600478","pt":1631450200472,"mc":[{"id":"1.187552454","rc":[{"batb":[[2,3.55,92.59]],"batl":[[0,4.1,34.07],[1,4.3,2.15],[2,4.8,2.02]],"ltp":3.65,"tv":4786.5,"id":9345630},{"batl":[[2,1.39,434.8]],"ltp":1.36,"tv":52729.33,"id":9028621}]}]}
{"op":"mcm","clk":"4226600620","pt":1631450201352,"mc":[{"id":"1.187552454","rc":[{"batb":[[1,1.35,48.63],[2,1.34,595.62]],"ltp":1.36,"tv":52729.33,"id":9028621}]}]}
{"op":"mcm","clk":"4226600793","pt":1631450202530,"mc":[{"id":"1.187552454","rc":[{"batb":[[2,3.55,69.07]],"batl":[[0,4.3,2.15],[1,4.8,2.02],[2,990,0.01]],"ltp":3.65,"tv":4786.5,"id":9345630},{"batb":[[0,1.36,32.2],[1,1.35,62.8]],"batl":[[2,1.39,374.8]],"ltp":1.36,"tv":52729.33,"id":9028621}]}]}
{"op":"mcm","clk":"4226601067","pt":1631450204395,"mc":[{"id":"1.187552454","rc":[{"trd":[[1.36,1440.34]],"batb":[[0,1.36,19.19]],"ltp":1.36,"tv":52755.36,"id":9028621}],"tv":57541.86}]}
{"op":"mcm","clk":"4226601221","pt":1631450205493,"mc":[{"id":"1.187552454","rc":[{"trd":[[3.65,173.12],[3.7,39.67]],"batb":[[0,3.65,45.87]],"batl":[[1,4.6,2.01],[2,4.8,2.02]],"ltp":3.65,"tv":4834.29,"id":9345630},{"trd":[[1.37,677.83]],"batl":[[0,1.37,60]],"ltp":1.37,"tv":52767.01,"id":9028621}],"tv":57601.3}]}
{"op":"mcm","clk":"4226601401","pt":1631450206563,"mc":[{"id":"1.187552454","rc":[{"trd":[[3.7,45.3]],"ltp":3.7,"tv":4839.92,"id":9345630},{"trd":[[1.37,693.04]],"batl":[[0,1.37,44.79]],"ltp":1.37,"tv":52782.22,"id":9028621}],"tv":57622.14}]}
{"op":"mcm","clk":"4226601537","pt":1631450207455,"mc":[{"id":"1.187552454","rc":[{"batl":[[0,4.2,13.28],[1,4.3,2.15],[2,4.6,2.01]],"ltp":3.7,"tv":4839.92,"id":9345630},{"batl":[[0,1.37,1364.05]],"ltp":1.37,"tv":52782.22,"id":9028621}]}]}
{"op":"mcm","clk":"4226601693","pt":1631450208582,"mc":[{"id":"1.187552454","rc":[{"batl":[[0,4.2,46.82],[1,4.3,34.2]],"ltp":3.7,"tv":4839.92,"id":9345630},{"trd":[[1.36,1478.72]],"batb":[[0,1.35,62.8],[1,1.34,595.62],[2,1.33,473.75]],"batl":[[0,1.36,207.85],[1,1.37,1364.05],[2,1.38,547.48]],"ltp":1.36,"tv":52820.59,"id":9028621}],"tv":57660.52}]}
{"op":"mcm","clk":"4226601754","pt":1631450208951,"mc":[{"id":"1.187552454","rc":[{"batl":[[0,4.2,33.54]],"ltp":3.7,"tv":4839.92,"id":9345630},{"trd":[[1.36,1539.69]],"batl":[[0,1.36,201.12]],"ltp":1.36,"tv":52881.56,"id":9028621}],"tv":57721.49}]}
{"op":"mcm","clk":"4226601888","pt":1631450209763,"mc":[{"id":"1.187552454","rc":[{"trd":[[1.36,1544.61]],"batl":[[0,1.36,198.66],[1,1.37,1379.26]],"ltp":1.36,"tv":52886.48,"id":9028621}],"tv":57726.4}]}
{"op":"mcm","clk":"4226602245","pt":1631450212090,"mc":[{"id":"1.187552454","rc":[{"batl":[[0,4.1,32.51],[1,4.2,33.54],[2,4.3,34.2]],"ltp":3.7,"tv":4839.92,"id":9345630},{"batb":[[0,1.35,102.51]],"batl":[[0,1.36,174.91]],"ltp":1.36,"tv":52886.48,"id":9028621}]}]}
{"op":"mcm","clk":"4226602451","pt":1631450213363,"mc":[{"id":"1.187552454","rc":[{"trd":[[1.35,2179.48]],"batb":[[0,1.34,595.62],[1,1.33,473.75],[2,1.32,796.87]],"batl":[[0,1.35,45.76],[1,1.36,174.91],[2,1.37,1379.26]],"ltp":1.35,"tv":53136.57,"id":9028621}],"tv":57976.5}]}
{"op":"mcm","clk":"4226602499","pt":1631450213637,"mc":[{"id":"1.187552454","rc":[{"batl":[[1,1.36,189.54]],"ltp":1.35,"tv":53136.57,"id":9028621}]}]}
{"op":"mcm","clk":"4226602804","pt":1631450215472,"mc":[{"id":"1.187552454","rc":[{"trd":[[1.35,2181.93]],"batl":[[0,1.35,44.53],[1,1.36,14.63]],"ltp":1.35,"tv":53139.03,"id":9028621}],"tv":57978.96}]}
{"op":"mcm","clk":"4226603001","pt":1631450216558,"mc":[{"id":"1.187552454","rc":[{"batl":[[2,4.3,2.15]],"ltp":3.7,"tv":4839.92,"id":9345630}]}]}
{"op":"mcm","clk":"4226603093","pt":1631450217157,"mc":[{"id":"1.187552454","rc":[{"batb":[[0,1.34,653.03]],"batl":[[0,1.36,14.63],[1,1.37,1379.26],[2,1.38,547.48]],"ltp":1.35,"tv":53139.03,"id":9028621}]}]}
{"op":"mcm","clk":"4226603254","pt":1631450218345,"mc":[{"id":"1.187552454","rc":[{"trd":[[1.35,2296.21]],"batl":[[0,1.35,117.77],[1,1.36,14.63],[2,1.37,1379.26]],"ltp":1.35,"tv":53253.31,"id":9028621}],"tv":58093.24}]}
{"op":"mcm","clk":"4226603539","pt":1631450220243,"mc":[{"id":"1.187552454","rc":[{"trd":[[1.34,15119.08]],"batb":[[0,1.34,608.5]],"ltp":1.34,"tv":53342.37,"id":9028621}],"tv":58182.3}]}
{"op":"mcm","clk":"4226603978","pt":1631450222971,"mc":[{"id":"1.187552454","rc":[{"batl":[[0,1.36,14.63],[1,1.37,1379.26],[2,1.38,547.48]],"ltp":1.34,"tv":53342.37,"id":9028621}]}]}
{"op":"mcm","clk":"4226604202","pt":1631450224465,"mc":[{"id":"1.187552454","rc":[{"batb":[[0,3.65,22.64],[1,2.96,3],[2,1.01,30]],"batl":[[0,4.2,33.54],[1,4.8,2.02],[2,990,0.01]],"ltp":3.7,"tv":4839.92,"id":9345630},{"batb":[[0,1.31,26.94],[1,1.27,73.03],[2,1.24,426.73]],"batl":[[0,1.37,1379.26],[1,1.51,7.6],[2,1.68,635.46]],"ltp":1.34,"tv":53342.37,"id":9028621}]}]}
{"op":"mcm","clk":"4226604382","pt":1631450225510,"mc":[{"id":"1.187552454","rc":[{"batb":[[0,2.96,3],[1,1.01,30],[2,1.01,0]],"batl":[[0,4.8,2.02],[1,990,0.01],[2,990,0]],"ltp":3.7,"tv":4839.92,"id":9345630},{"batb":[[0,1.27,73.03],[1,1.24,426.73],[2,1.12,6.16]],"batl":[[0,1.37,1319.26]],"ltp":1.34,"tv":53342.37,"id":9028621}]}]}
{"op":"mcm","clk":"4226604502","pt":1631450226275,"mc":[{"id":"1.187552454","rc":[{"batl":[[0,1.32,38.62],[1,1.34,117.77],[2,1.51,7.6]],"ltp":1.34,"tv":53342.37,"id":9028621}]}]}
{"op":"mcm","clk":"4226604675","pt":1631450227487,"mc":[{"id":"1.187552454","rc":[{"batl":[[0,4.4,2.04],[1,4.8,2.02],[2,990,0.01]],"ltp":3.7,"tv":4839.92,"id":9345630},{"batb":[[0,1.3,65.88],[1,1.29,529.84],[2,1.28,579.53]],"batl":[[2,1.47,463.32]],"ltp":1.34,"tv":53342.37,"id":9028621}]}]}
{"op":"mcm","clk":"4226604741","pt":1631450227972,"mc":[{"id":"1.187552454","rc":[{"batl":[[0,4.8,2.02],[1,990,0.01],[2,990,0]],"ltp":3.7,"tv":4839.92,"id":9345630},{"batb":[[0,1.29,529.84],[1,1.28,579.53],[2,1.27,73.03]],"batl":[[1,1.34,119.33]],"ltp":1.34,"tv":53342.37,"id":9028621}]}]}
{"op":"mcm","clk":"4226604868","pt":1631450228875,"mc":[{"id":"1.187552454","rc":[{"batb":[[1,2.94,4],[2,1.01,30]],"batl":[[0,4.8,5.02]],"ltp":3.7,"tv":4839.92,"id":9345630},{"batb":[[0,1.29,538.84],[1,1.28,589.53],[2,1.27,82.03]],"ltp":1.34,"tv":53342.37,"id":9028621}]}]}
{"op":"mcm","clk":"4226605171","pt":1631450230596,"mc":[{"id":"1.187552454","rc":[{"trd":[[4.1,7.29]],"batl":[[0,4.5,2],[1,4.8,5.02],[2,990,0.01]],"ltp":4.1,"tv":4841.61,"id":9345630},{"trd":[[1.32,317.52]],"batl":[[0,1.32,33.37]],"ltp":1.32,"tv":53347.62,"id":9028621}],"tv":58189.23}]}
{"op":"mcm","clk":"4226605276","pt":1631450231187,"mc":[{"id":"1.187552454","rc":[{"batl":[[0,4.4,2],[1,4.5,2],[2,4.8,5.02]],"ltp":4.1,"tv":4841.61,"id":9345630},{"batb":[[0,1.3,10],[1,1.29,538.84],[2,1.28,589.53]],"ltp":1.32,"tv":53347.62,"id":9028621}]}]}
{"op":"mcm","clk":"4226605667","pt":1631450233597,"mc":[{"id":"1.187552454","rc":[{"batl":[[1,1.34,1.56],[2,1.47,462.72]],"ltp":1.32,"tv":53347.62,"id":9028621}]}]}
{"op":"mcm","clk":"4226605945","pt":1631450235522,"mc":[{"id":"1.187552454","rc":[{"trd":[[1.32,320.85]],"batl":[[0,1.32,31.71]],"ltp":1.32,"tv":53350.95,"id":9028621}],"tv":58192.56}]}
{"op":"mcm","clk":"4226606310","pt":1631450237589,"mc":[{"id":"1.187552454","rc":[{"trd":[[1.32,337.93]],"batl":[[0,1.32,23.17]],"ltp":1.32,"tv":53368.03,"id":9028621}],"tv":58209.64}]}
{"op":"mcm","clk":"4226606717","pt":1631450240274,"mc":[{"id":"1.187552454","rc":[{"trd":[[4.1,14.75]],"batb":[[1,1.01,30],[2,1.01,0]],"batl":[[0,4.1,3.27],[1,4.4,2],[2,4.5,2]],"ltp":4.1,"tv":4849.07,"id":9345630},{"trd":[[1.32,361.1]],"batb":[[1,1.29,529.84],[2,1.28,579.53]],"batl":[[0,1.34,1.56],[1,1.47,462.72],[2,1.48,284.15]],"ltp":1.32,"tv":53391.2,"id":9028621}],"tv":58240.28}]}
{"op":"mcm","clk":"4226606884","pt":1631450241284,"mc":[{"id":"1.187552454","rc":[{"batl":[[0,4.4,4.04],[1,4.5,2],[2,4.8,5.02]],"ltp":4.1,"tv":4849.07,"id":9345630},{"batb":[[0,1.3,79.58]],"ltp":1.32,"tv":53391.2,"id":9028621}]}]}
{"op":"mcm","clk":"4226607056","pt":1631450242423,"mc":[{"id":"1.187552454","rc":[{"batl":[[0,4.4,2],[1,4.8,2.02],[2,990,0.01]],"ltp":4.1,"tv":4849.07,"id":9345630},{"trd":[[1.3,446.31]],"batb":[[0,1.29,529.84],[1,1.28,579.53],[2,1.27,73.03]],"batl":[[0,1.33,71.9],[1,1.34,69.78],[2,1.35,69.78]],"ltp":1.3,"tv":53408.28,"id":9028621}],"tv":58257.36}]}
{"op":"mcm","clk":"4226607227","pt":1631450243398,"mc":[{"id":"1.187552454","rc":[{"batb":[[0,3.1,3],[1,3.05,3],[2,2.96,3]],"batl":[[0,4.8,2.02],[1,990,0.01],[2,990,0]],"ltp":4.1,"tv":4849.07,"id":9345630}]}]}
{"op":"mcm","clk":"4226607394","pt":1631450244466,"mc":[{"id":"1.187552454","rc":[{"batb":[[0,1.29,539.84]],"ltp":1.3,"tv":53408.28,"id":9028621}]}]}
{"op":"mcm","clk":"4226607600","pt":1631450245513,"mc":[{"id":"1.187552454","rc":[{"batl":[[0,4.7,406.92],[1,4.8,396.98],[2,4.9,394.96]],"ltp":4.1,"tv":4849.07,"id":9345630},{"trd":[[1.32,368.9]],"batb":[[0,1.29,529.84],[1,1.28,590.53]],"batl":[[0,1.32,456.83],[1,1.33,648.81],[2,1.34,175.78]],"ltp":1.32,"tv":53416.08,"id":9028621}],"tv":58265.16}]}
{"op":"mcm","clk":"4226607740","pt":1631450246408,"mc":[{"id":"1.187552454","rc":[{"batb":[[0,4.1,19.35],[1,3.95,2],[2,3.9,2]],"batl":[[1,4.8,427.75]],"ltp":4.1,"tv":4849.07,"id":9345630},{"batb":[[0,1.29,586.85]],"batl":[[1,1.33,752.29]],"ltp":1.32,"tv":53416.08,"id":9028621}]}]}
{"op":"mcm","clk":"4226607866","pt":1631450247236,"mc":[{"id":"1.187552454","rc":[{"trd":[[1.32,487.76]],"batl":[[0,1.32,397.4]],"ltp":1.32,"tv":53534.94,"id":9028621}],"tv":58384.02}]}
{"op":"mcm","clk":"4226608036","pt":1631450248502,"mc":[{"id":"1.187552454","rc":[{"batl":[[0,1.3,11],[1,1.32,397.4],[2,1.33,692.29]],"ltp":1.32,"tv":53534.94,"id":9028621}]}]}
{"op":"mcm","clk":"4226608144","pt":1631450249403,"mc":[{"id":"1.187552454","rc":[{"batl":[[0,4.4,13.55],[1,4.7,406.92],[2,4.8,427.75]],"ltp":4.1,"tv":4849.07,"id":9345630}]}]}
{"op":"mcm","clk":"4226608232","pt":1631450250091,"mc":[{"id":"1.187552454","rc":[{"batl":[[0,4.7,406.92],[1,4.8,427.75],[2,4.9,394.96]],"ltp":4.1,"tv":4849.07,"id":9345630}]}]}
{"op":"mcm","clk":"4226608430","pt":1631450251484,"mc":[{"id":"1.187552454","rc":[{"batl":[[2,4.9,397.01]],"ltp":4.1,"tv":4849.07,"id":9345630},{"trd":[[1.3,447.11]],"batl":[[0,1.3,10.6]],"ltp":1.3,"tv":53535.74,"id":9028621}],"tv":58384.82}]}
{"op":"mcm","clk":"4226608502","pt":1631450252116,"mc":[{"id":"1.187552454","rc":[{"batl":[[1,1.32,457.4]],"ltp":1.3,"tv":53535.74,"id":9028621}]}]}
{"op":"mcm","clk":"4226608744","pt":1631450253823,"mc":[{"id":"1.187552454","rc":[{"batl":[[0,1.32,457.4],[1,1.33,692.29],[2,1.34,175.78]],"ltp":1.3,"tv":53535.74,"id":9028621}]}]}
{"op":"mcm","clk":"4226609148","pt":1631450256427,"mc":[{"id":"1.187552454","rc":[{"batl":[[0,4.4,13.55],[1,4.7,406.92],[2,4.8,427.75]],"ltp":4.1,"tv":4849.07,"id":9345630},{"batb":[[0,1.3,24.19],[1,1.29,586.85],[2,1.28,590.53]],"ltp":1.3,"tv":53535.74,"id":9028621}]}]}
{"op":"mcm","clk":"4226609196","pt":1631450256707,"mc":[{"id":"1.187552454","rc":[{"batl":[[0,4.7,406.92],[1,4.8,427.75],[2,4.9,397.01]],"ltp":4.1,"tv":4849.07,"id":9345630}]}]}
{"op":"mcm","clk":"4226609435","pt":1631450258453,"mc":[{"id":"1.187552454","rc":[{"batb":[[2,3.85,15]],"ltp":4.1,"tv":4849.07,"id":9345630},{"batb":[[0,1.3,32.85]],"ltp":1.3,"tv":53535.74,"id":9028621}]}]}
{"op":"mcm","clk":"4226609545","pt":1631450259313,"mc":[{"id":"1.187552454","rc":[{"batl":[[0,4.6,2.11],[1,4.7,406.92],[2,4.8,427.75]],"ltp":4.1,"tv":4849.07,"id":9345630},{"batb":[[2,1.28,654.19]],"ltp":1.3,"tv":53535.74,"id":9028621}]}]}
{"op":"mcm","clk":"4226609865","pt":1631450261384,"mc":[{"id":"1.187552454","rc":[{"batb":[[0,1.3,26.14]],"ltp":1.3,"tv":53535.74,"id":9028621}]}]}
{"op":"mcm","clk":"4226609928","pt":1631450261856,"mc":[{"id":"1.187552454","rc":[{"batl":[[1,1.33,680.29]],"ltp":1.3,"tv":53535.74,"id":9028621}]}]}
{"op":"mcm","clk":"4226610104","pt":1631450263190,"mc":[{"id":"1.187552454","rc":[{"batl":[[0,4.5,13.84],[1,4.6,2.11],[2,4.7,406.92]],"ltp":4.1,"tv":4849.07,"id":9345630}]}]}
{"op":"mcm","clk":"4226610723","pt":1631450267396,"mc":[{"id":"1.187552454","rc":[{"batl":[[2,4.8,32.79]],"ltp":4.1,"tv":4849.07,"id":9345630},{"trd":[[1.3,491.11],[1.32,504.84]],"batb":[[0,1.3,4.14]],"batl":[[0,1.32,448.86],[1,1.33,499.18],[2,1.38,7]],"ltp":1.32,"tv":53596.82,"id":9028621}],"tv":58445.9}]}
{"op":"mcm","clk":"4226610829","pt":1631450268093,"mc":[{"id":"1.187552454","rc":[{"batb":[[1,1.01,30],[2,3.85,0]],"batl":[[0,4.8,30.77],[1,4.9,2.05],[2,5,2]],"ltp":4.1,"tv":4849.07,"id":9345630},{"trd":[[1.3,494.13]],"batb":[[0,1.3,2.62],[1,1.27,6.16],[2,1.26,65.48]],"batl":[[0,1.32,60],[1,1.47,6],[2,1.68,635.46]],"ltp":1.3,"tv":53599.85,"id":9028621}],"tv":58448.93}]}
{"op":"mcm","clk":"4226611029","pt":1631450269500,"mc":[{"id":"1.187552454","rc":[{"batb":[[0,1.01,30],[1,1.01,0]],"batl":[[0,4.9,2.05],[1,5,2],[2,5.2,2]],"ltp":4.1,"tv":4849.07,"id":9345630},{"batl":[[0,1.47,6],[1,1.68,635.46],[2,3.8,27.47]],"ltp":1.3,"tv":53599.85,"id":9028621}]}]}
{"op":"mcm","clk":"4226611185","pt":1631450270582,"mc":[{"id":"1.187552454","rc":[{"batl":[[1,990,0.01],[2,5.2,0]],"ltp":4.1,"tv":4849.07,"id":9345630},{"batl":[[0,1.38,289.52],[1,1.39,372.18],[2,1.47,6]],"ltp":1.3,"tv":53599.85,"id":9028621}]}]}
{"op":"mcm","clk":"4226611333","pt":1631450271494,"mc":[{"id":"1.187552454","rc":[{"batl":[[0,4.8,2],[1,4.9,2.05],[2,990,0.01]],"ltp":4.1,"tv":4849.07,"id":9345630},{"batl":[[0,1.47,6],[1,1.68,635.46],[2,3.8,27.47]],"ltp":1.3,"tv":53599.85,"id":9028621}]}]}
{"op":"mcm","clk":"4226611531","pt":1631450272895,"mc":[{"id":"1.187552454","rc":[{"batb":[[0,3.1,2],[1,3.05,3],[2,1.01,30]],"batl":[[1,4.9,4.05]],"ltp":4.1,"tv":4849.07,"id":9345630}]}]}
{"op":"mcm","clk":"4226611776","pt":1631450274390,"mc":[{"id":"1.187552454","rc":[{"batb":[[0,4,21.35],[1,3.6,3],[2,3.55,2]],"batl":[[0,4.4,19.19],[1,4.8,2],[2,4.9,4.05]],"ltp":4.1,"tv":4849.07,"id":9345630},{"batl":[[0,1.33,22.5],[1,1.38,3],[2,1.47,6]],"ltp":1.3,"tv":53599.85,"id":9028621}]}]}
{"op":"mcm","clk":"4226611884","pt":1631450275139,"mc":[{"id":"1.187552454","rc":[{"batb":[[0,3.6,3],[1,3.55,2],[2,3.1,2]],"batl":[[0,4.8,2],[1,4.9,4.05],[2,990,0.01]],"ltp":4.1,"tv":4849.07,"id":9345630},{"batb":[[0,1.3,616.34],[1,1.29,556.18],[2,1.27,6.16]],"batl":[[0,1.33,327.07],[1,1.34,440.92],[2,1.38,3]],"ltp":1.3,"tv":53599.85,"id":9028621}]}]}
{"op":"mcm","clk":"4226612111","pt":1631450276581,"mc":[{"id":"1.187552454","rc":[{"batl":[[0,4.7,10],[1,4.8,2],[2,4.9,4.05]],"ltp":4.1,"tv":4849.07,"id":9345630},{"trd":[[1.33,594.24]],"batb":[[0,1.3,629.44]],"batl":[[0,1.33,283.69],[2,1.36,9.75]],"ltp":1.33,"tv":53686.61,"id":9028621}],"tv":58535.69}]}
{"op":"mcm","clk":"4226612389","pt":1631450278300,"mc":[{"id":"1.187552454","rc":[{"batl":[[0,4.6,2.01],[1,4.7,10],[2,4.8,2]],"ltp":4.1,"tv":4849.07,"id":9345630},{"batb":[[2,1.28,67.16]],"ltp":1.33,"tv":53686.61,"id":9028621}]}]}
{"op":"mcm","clk":"4226612566","pt":1631450279486,"mc":[{"id":"1.187552454","rc":[{"batb":[[0,3.65,71.57],[1,3.6,3],[2,3.55,2]],"batl":[[1,4.8,2],[2,4.9,4.05]],"ltp":4.1,"tv":4849.07,"id":9345630},{"batb":[[0,1.3,627.49]],"ltp":1.33,"tv":53686.61,"id":9028621}]}]}
{"op":"mcm","clk":"4226612641","pt":1631450280142,"mc":[{"id":"1.187552454","rc":[{"batb":[[0,3.6,3],[1,3.55,2],[2,3.1,2]],"ltp":4.1,"tv":4849.07,"id":9345630}]}]}
{"op":"mcm","clk":"4226612782","pt":1631450281253,"mc":[{"id":"1.187552454","rc":[{"batb":[[0,1.3,13.1],[1,1.28,67.16],[2,1.27,6.16]],"batl":[[0,1.36,9.75],[1,1.38,3],[2,1.41,30]],"ltp":1.33,"tv":53686.61,"id":9028621}]}]}
{"op":"mcm","clk":"4226612930","pt":1631450282055,"mc":[{"id":"1.187552454","rc":[{"batl":[[0,4.8,2],[1,4.9,4.05],[2,990,0.01]],"ltp":4.1,"tv":4849.07,"id":9345630},{"batb":[[0,1.27,6.16],[1,1.26,65.48],[2,1.21,440.98]],"batl":[[2,1.47,6]],"ltp":1.33,"tv":53686.61,"id":9028621}]}]}
{"op":"mcm","clk":"4226613156","pt":1631450283329,"mc":[{"id":"1.187552454","rc":[{"batb":[[0,3.7,37.53],[1,3.6,3],[2,3.55,2]],"ltp":4.1,"tv":4849.07,"id":9345630}]}]}
{"op":"mcm","clk":"4226613350","pt":1631450284559,"mc":[{"id":"1.187552454","rc":[{"batb":[[0,4.4,10]],"batl":[[1,4.9,2.05]],"ltp":4.1,"tv":4849.07,"id":9345630},{"batb":[[2,1.25,838.5]],"batl":[[1,1.38,271.44],[2,1.39,372.17]],"ltp":1.33,"tv":53686.61,"id":9028621}]}]}
{"op":"mcm","clk":"4226613494","pt":1631450285454,"mc":[{"id":"1.187552454","rc":[{"trd":[[4.4,36.26]],"batb":[[0,3.6,3],[1,1.01,30],[2,3.55,0]],"ltp":4.4,"tv":4859.07,"id":9345630},{"trd":[[1.3,527.98]],"batb":[[0,1.27,14.16],[1,1.26,75.48]],"batl":[[0,1.35,48.75],[1,1.36,9.75],[2,1.38,271.44]],"ltp":1.3,"tv":53720.46,"id":9028621}],"tv":58579.54}]}
{"op":"mcm","clk":"4226613528","pt":1631450285680,"mc":[{"id":"1.187552454","rc":[{"batl":[[0,1.36,9.75],[1,1.38,271.44],[2,1.39,372.17]],"ltp":1.3,"tv":53720.46,"id":9028621}]}]}
{"op":"mcm","clk":"4226614011","pt":1631450288535,"mc":[{"id":"1.187552454","rc":[{"batl":[[0,4.5,10.05],[1,4.6,2.01],[2,4.7,2]],"ltp":4.4,"tv":4859.07,"id":9345630},{"batb":[[0,1.28,71.16],[1,1.27,14.16],[2,1.26,75.48]],"ltp":1.3,"tv":53720.46,"id":9028621}]}]}
{"op":"mcm","clk":"4226614066","pt":1631450288989,"mc":[{"id":"1.187552454","rc":[{"batl":[[0,4.7,2],[1,4.8,2],[2,4.9,2.05]],"ltp":4.4,"tv":4859.07,"id":9345630},{"batb":[[0,1.27,14.16],[1,1.26,75.48],[2,1.25,838.5]],"ltp":1.3,"tv":53720.46,"id":9028621}]}]}
{"op":"mcm","clk":"4226614653","pt":1631450292847,"mc":[{"id":"1.187552454","rc":[{"trd":[[1.36,1564.11]],"batb":[[0,1.36,11.94],[1,1.27,14.16],[2,1.26,75.48]],"batl":[[0,1.38,271.44],[1,1.39,372.17],[2,1.68,635.46]],"ltp":1.36,"tv":53739.96,"id":9028621}],"tv":58599.04}]}
{"op":"mcm","clk":"4226615033","pt":1631450295444,"mc":[{"id":"1.187552454","rc":[{"batl":[[0,4.6,2.26],[1,4.7,2],[2,4.8,2]],"ltp":4.4,"tv":4859.07,"id":9345630},{"batb":[[0,1.28,63.16]],"ltp":1.36,"tv":53739.96,"id":9028621}]}]}
{"op":"mcm","clk":"4226615231","pt":1631450296582,"mc":[{"id":"1.187552454","rc":[{"batb":[[1,3.55,3],[2,1.01,30]],"batl":[[0,4.7,2],[1,4.8,2],[2,4.9,2.05]],"ltp":4.4,"tv":4859.07,"id":9345630},{"batb":[[0,1.27,14.16],[1,1.26,65.48],[2,1.25,838.5]],"batl":[[0,1.36,2],[1,1.38,271.44],[2,1.39,372.17]],"ltp":1.36,"tv":53739.96,"id":9028621}]}]}
{"op":"mcm","clk":"4226615776","pt":1631450300350,"mc":[{"id":"1.187552454","rc":[{"batb":[[1,1.26,75.48]],"batl":[[0,1.38,271.44],[1,1.39,372.17],[2,1.68,635.46]],"ltp":1.36,"tv":53739.96,"id":9028621}]}]}
{"op":"mcm","clk":"4226615931","pt":1631450301267,"mc":[{"id":"1.187552454","rc":[{"batl":[[1,4.9,2.05],[2,990,0.01]],"ltp":4.4,"tv":4859.07,"id":9345630},{"batb":[[2,1.22,31.31]],"ltp":1.36,"tv":53739.96,"id":9028621}]}]}
{"op":"mcm","clk":"4226616141","pt":1631450302548,"mc":[{"id":"1.187552454","rc":[{"batl":[[0,4.6,2.01],[1,4.7,2],[2,4.9,2.05]],"ltp":4.4,"tv":4859.07,"id":9345630},{"batb":[[0,1.28,64.91],[1,1.27,14.16],[2,1.26,75.48]],"ltp":1.36,"tv":53739.96,"id":9028621}]}]}
{"op":"mcm","clk":"4226616259","pt":1631450303458,"mc":[{"id":"1.187552454","rc":[{"trd":[[3.6,22.45]],"batb":[[0,3.55,3],[1,1.01,30],[2,1.01,0]],"batl":[[0,4.7,2],[1,4.9,2.05],[2,990,0.01]],"ltp":3.6,"tv":4870.61,"id":9345630},{"trd":[[1.38,37.55]],"batb":[[0,1.34,71.36],[1,1.33,69.26],[2,1.32,69.26]],"batl":[[0,1.38,256.98]],"ltp":1.38,"tv":53754.42,"id":9028621}],"tv":58625.04}]}
{"op":"mcm","clk":"4226616448","pt":1631450304579,"mc":[{"id":"1.187552454","rc":[{"batb":[[0,3.5,71],[1,3.45,307.58],[2,3.4,307.58]],"batl":[[0,3.65,3],[1,3.9,7.75],[2,4.7,2]],"ltp":3.6,"tv":4870.61,"id":9345630},{"trd":[[1.38,65.55]],"batb":[[0,1.35,507.16],[1,1.34,1238.65],[2,1.33,761.89]],"batl":[[0,1.38,254.54],[2,1.4,5.7]],"ltp":1.38,"tv":53782.42,"id":9028621}],"tv":58653.04}]}
{"op":"mcm","clk":"4226616586","pt":1631450305512,"mc":[{"id":"1.187552454","rc":[{"trd":[[3.65,179.12]],"batb":[[0,3.65,19.64],[1,3.5,71],[2,3.45,307.58]],"batl":[[0,3.9,7.75],[1,4.2,33.54],[2,4.4,10]],"ltp":3.65,"tv":4876.61,"id":9345630},{"batl":[[0,1.38,314.54]],"ltp":1.38,"tv":53782.42,"id":9028621}],"tv":58659.04}]}
{"op":"mcm","clk":"4226616624","pt":1631450305771,"mc":[{"id":"1.187552454","rc":[{"batl":[[2,4.7,2]],"ltp":3.65,"tv":4876.61,"id":9345630}]}]}
{"op":"mcm","clk":"4226616825","pt":1631450307266,"mc":[{"id":"1.187552454","rc":[{"batb":[[1,3.55,14.87],[2,3.5,71]],"ltp":3.65,"tv":4876.61,"id":9345630},{"batb":[[0,1.35,526.84]],"ltp":1.38,"tv":53782.42,"id":9028621}]}]}
{"op":"mcm","clk":"4226616904","pt":1631450307912,"mc":[{"id":"1.187552454","rc":[{"batl":[[1,4.7,2],[2,4.9,2.05]],"ltp":3.65,"tv":4876.61,"id":9345630}]}]}
{"op":"mcm","clk":"4226617168","pt":1631450309483,"mc":[{"id":"1.187552454","rc":[{"batb":[[1,3.6,3],[2,3.55,14.87]],"batl":[[0,3.85,15.6],[1,3.9,7.75],[2,4.7,2]],"ltp":3.65,"tv":4876.61,"id":9345630},{"batb":[[0,1.35,559.84]],"ltp":1.38,"tv":53782.42,"id":9028621}]}]}
{"op":"mcm","clk":"4226617486","pt":1631450311432,"mc":[{"id":"1.187552454","rc":[{"batl":[[2,4.1,34.07]],"ltp":3.65,"tv":4876.61,"id":9345630},{"trd":[[1.38,82.63]],"batl":[[0,1.38,306]],"ltp":1.38,"tv":53799.5,"id":9028621}],"tv":58676.12}]}
{"op":"mcm","clk":"4226617647","pt":1631450312406,"mc":[{"id":"1.187552454","rc":[{"batl":[[0,1.38,368.56]],"ltp":1.38,"tv":53799.5,"id":9028621}]}]}
{"op":"mcm","clk":"4226618069","pt":1631450315110,"mc":[{"id":"1.187552454","rc":[{"trd":[[1.35,2424.87]],"batb":[[0,1.35,495.51]],"ltp":1.35,"tv":53928.16,"id":9028621}],"tv":58804.78}]}
{"op":"mcm","clk":"4226618581","pt":1631450318383,"mc":[{"id":"1.187552454","rc":[{"trd":[[3.65,212.2]],"batb":[[0,3.65,3.1]],"ltp":3.65,"tv":4909.7,"id":9345630}],"tv":58837.86}]}
{"op":"mcm","clk":"4226618977","pt":1631450321076,"mc":[{"id":"1.187552454","rc":[{"batl":[[0,1.38,357],[2,1.68,635.46]],"ltp":1.35,"tv":53928.16,"id":9028621}]}]}
{"op":"mcm","clk":"4226619100","pt":1631450321818,"mc":[{"id":"1.187552454","rc":[{"batb":[[1,3.6,19.54]],"ltp":3.65,"tv":4909.7,"id":9345630}]}]}
{"op":"mcm","clk":"4226619415","pt":1631450324108,"mc":[{"id":"1.187552454","rc":[{"batb":[[2,1.01,30]],"batl":[[0,4.1,34.07],[1,4.3,2.25],[2,4.6,2.11]],"ltp":3.65,"tv":4909.7,"id":9345630},{"batb":[[0,1.32,26.51],[1,1.31,63.79],[2,1.28,66.16]],"batl":[[0,1.38,60],[1,1.68,635.46],[2,3.8,27.47]],"ltp":1.35,"tv":53928.16,"id":9028621}]}]}
{"op":"mcm","clk":"4226619626","pt":1631450325528,"mc":[{"id":"1.187552454","rc":[{"batb":[[0,1.01,30],[1,3.6,0],[2,1.01,0]],"batl":[[0,4.3,2.25],[1,4.6,2.11],[2,4.7,2]],"ltp":3.65,"tv":4909.7,"id":9345630},{"batb":[[0,1.31,63.79],[1,1.28,66.16],[2,1.27,14.16]],"batl":[[0,1.68,635.46],[1,3.8,27.47],[2,8.8,7.23]],"ltp":1.35,"tv":53928.16,"id":9028621}]}]}
{"op":"mcm","clk":"4226619688","pt":1631450325919,"mc":[{"id":"1.187552454","rc":[{"batl":[[0,4.6,2.11],[1,4.7,2],[2,990,0.01]],"ltp":3.65,"tv":4909.7,"id":9345630},{"batb":[[0,1.28,66.16],[1,1.27,14.16],[2,1.24,426.73]],"ltp":1.35,"tv":53928.16,"id":9028621}]}]}
{"op":"mcm","clk":"4226619915","pt":1631450327296,"mc":[{"id":"1.187552454","rc":[{"batb":[[0,3.1,2.04],[1,2.92,2.44],[2,1.01,30]],"batl":[[0,3.65,12.81],[1,4.6,2.11],[2,4.7,2]],"ltp":3.65,"tv":4909.7,"id":9345630},{"batb":[[0,1.3,263.06],[1,1.29,549.88],[2,1.28,66.16]],"batl":[[0,1.47,250.02],[1,1.48,286.05],[2,1.52,26.26]],"ltp":1.35,"tv":53928.16,"id":9028621}]}]}
{"op":"mcm","clk":"4226620238","pt":1631450329483,"mc":[{"id":"1.187552454","rc":[{"batb":[[2,2.46,4]],"batl":[[1,4.3,3],[2,4.6,4.11]],"ltp":3.65,"tv":4909.7,"id":9345630},{"batb":[[0,1.31,8],[1,1.3,272.06],[2,1.29,559.88]],"ltp":1.35,"tv":53928.16,"id":9028621}]}]}
{"op":"mcm","clk":"4226620367","pt":1631450330277,"mc":[{"id":"1.187552454","rc":[{"batb":[[0,3.1,3],[1,3.05,3],[2,2.92,2.44]],"batl":[[2,4.4,2]],"ltp":3.65,"tv":4909.7,"id":9345630},{"batl":[[0,1.47,6],[1,1.52,26.26],[2,1.68,640.46]],"ltp":1.35,"tv":53928.16,"id":9028621}]}]}
{"op":"mcm","clk":"4226620527","pt":1631450331524,"mc":[{"id":"1.187552454","rc":[{"batl":[[0,4.3,3],[1,4.4,2],[2,4.6,4.11]],"ltp":3.65,"tv":4909.7,"id":9345630}]}]}
{"op":"mcm","clk":"4226620686","pt":1631450332400,"mc":[{"id":"1.187552454","rc":[{"trd":[[4.4,42.94]],"batb":[[0,3.9,99.84],[1,3.85,96.9],[2,3.8,96.9]],"batl":[[0,4.6,4.11],[1,4.7,2],[2,990,0.01]],"ltp":4.4,"tv":4916.38,"id":9345630},{"trd":[[1.3,550.58]],"batb":[[0,1.3,240.46],[1,1.29,549.88],[2,1.28,3063.44]],"batl":[[0,1.37,8.54],[1,1.47,6],[2,1.52,26.26]],"ltp":1.3,"tv":53950.76,"id":9028621}],"tv":58867.14}]}
{"op":"mcm","clk":"4226620869","pt":1631450333409,"mc":[{"id":"1.187552454","rc":[{"batb":[[0,3.9,65.18],[1,3.85,60.35],[2,3.8,60.35]],"ltp":4.4,"tv":4916.38,"id":9345630},{"batb":[[2,1.28,896.94]],"batl":[[0,1.33,666.3],[1,1.34,435.99],[2,1.35,5.91]],"ltp":1.3,"tv":53950.76,"id":9028621}]}]}
{"op":"mcm","clk":"4226621048","pt":1631450334418,"mc":[{"id":"1.187552454","rc":[{"batl":[[1,1.34,495.99]],"ltp":1.3,"tv":53950.76,"id":9028621}]}]}
{"op":"mcm","clk":"4226621228","pt":1631450335399,"mc":[{"id":"1.187552454","rc":[{"batb":[[0,3.95,3],[1,3.9,68.18],[2,3.85,60.35]],"batl":[[0,4.5,20.55],[1,4.6,4.11],[2,4.7,33.19]],"ltp":4.4,"tv":4916.38,"id":9345630},{"batb":[[0,1.3,281.14]],"batl":[[1,1.34,442.99]],"ltp":1.3,"tv":53950.76,"id":9028621}]}]}
{"op":"mcm","clk":"4226621596","pt":1631450337598,"mc":[{"id":"1.187552454","rc":[{"batb":[[0,3.95,41.59]],"ltp":4.4,"tv":4916.38,"id":9345630}]}]}
{"op":"mcm","clk":"4226621642","pt":1631450337916,"mc":[{"id":"1.187552454","rc":[{"batb":[[0,3.95,23.33]],"ltp":4.4,"tv":4916.38,"id":9345630},{"batl":[[0,1.33,726.3]],"ltp":1.3,"tv":53950.76,"id":9028621}]}]}
{"op":"mcm","clk":"4226622179","pt":1631450341521,"mc":[{"id":"1.187552454","rc":[{"batb":[[0,4,18.26],[1,3.95,23.33],[2,3.9,68.18]],"ltp":4.4,"tv":4916.38,"id":9345630},{"trd":[[1.33,595.04]],"batl":[[0,1.33,725.9]],"ltp":1.33,"tv":53951.56,"id":9028621}],"tv":58867.94}]}
{"op":"mcm","clk":"4226622216","pt":1631450341730,"mc":[{"id":"1.187552454","rc":[{"batl":[[2,4.7,31.19]],"ltp":4.4,"tv":4916.38,"id":9345630}]}]}
{"op":"mcm","clk":"4226622631","pt":1631450344319,"mc":[{"id":"1.187552454","rc":[{"trd":[[4.4,43.24]],"ltp":4.4,"tv":4916.68,"id":9345630},{"trd":[[1.3,576.32]],"batb":[[0,1.3,267.75]],"ltp":1.3,"tv":53977.3,"id":9028621}],"tv":58893.99}]}
{"op":"mcm","clk":"4226622694","pt":1631450344712,"mc":[{"id":"1.187552454","rc":[{"batb":[[0,1.3,40.68]],"ltp":1.3,"tv":53977.3,"id":9028621}]}]}
{"op":"mcm","clk":"4226622928","pt":1631450346418,"mc":[{"id":"1.187552454","rc":[{"batb":[[1,3.95,3],[2,3.9,65.18]],"ltp":4.4,"tv":4916.68,"id":9345630}]}]}
{"op":"mcm","clk":"4226623098","pt":1631450347511,"mc":[{"id":"1.187552454","rc":[{"batb":[[0,3.5,2.04],[1,1.01,30],[2,3.9,0]],"batl":[[0,4.7,31.19],[1,4.9,2],[2,990,0.01]],"ltp":4.4,"tv":4916.68,"id":9345630},{"batb":[[0,1.27,35.02],[1,1.26,44.98],[2,1.21,440.98]],"batl":[[0,1.33,60],[1,1.4,35.49],[2,1.68,635.46]],"ltp":1.3,"tv":53977.3,"id":9028621}]}]}
{"op":"mcm","clk":"4226623245","pt":1631450348522,"mc":[{"id":"1.187552454","rc":[{"batl":[[0,4.9,2],[1,990,0.01],[2,990,0]],"ltp":4.4,"tv":4916.68,"id":9345630},{"batb":[[0,1.27,6.16]],"batl":[[0,1.4,35.49],[1,1.68,635.46],[2,3.8,27.47]],"ltp":1.3,"tv":53977.3,"id":9028621}]}]}
{"op":"mcm","clk":"4226623414","pt":1631450349534,"mc":[{"id":"1.187552454","rc":[{"batb":[[0,4,20],[1,3.5,2.04],[2,1.01,30]],"ltp":4.4,"tv":4916.68,"id":9345630},{"batb":[[0,1.27,6.58]],"ltp":1.3,"tv":53977.3,"id":9028621}]}]}
{"op":"mcm","clk":"4226623571","pt":1631450350507,"mc":[{"id":"1.187552454","rc":[{"batb":[[0,3.7,2.02]],"batl":[[0,4.6,2],[1,4.9,2],[2,990,0.01]],"ltp":4.4,"tv":4916.68,"id":9345630},{"batb":[[0,1.28,44.09],[1,1.27,6.16],[2,1.26,44.98]],"batl":[[0,1.37,35.5],[1,1.4,35.49],[2,1.68,635.46]],"ltp":1.3,"tv":53977.3,"id":9028621}]}]}
{"op":"mcm","clk":"4226623616","pt":1631450350828,"mc":[{"id":"1.187552454","rc":[{"batb":[[0,3.5,2.04],[1,1.01,30],[2,1.01,0]],"batl":[[0,4.9,2],[1,990,0.01],[2,990,0]],"ltp":4.4,"tv":4916.68,"id":9345630},{"batb":[[0,1.27,6.58],[1,1.26,44.98],[2,1.21,440.98]],"batl":[[0,1.4,35.49],[1,1.68,635.46],[2,3.8,27.47]],"ltp":1.3,"tv":53977.3,"id":9028621}]}]}
{"op":"mcm","clk":"4226623888","pt":1631450352455,"mc":[{"id":"1.187552454","rc":[{"trd":[[4.1,14.89]],"batb":[[0,3.5,5.21],[1,3.45,3],[2,1.01,30]],"ltp":4.1,"tv":4916.82,"id":9345630},{"trd":[[1.33,595.47]],"batb":[[0,1.27,6.16]],"batl":[[0,1.4,42.49]],"ltp":1.33,"tv":53977.72,"id":9028621}],"tv":58894.55}]}
{"op":"mcm","clk":"4226624050","pt":1631450353464,"mc":[{"id":"1.187552454","rc":[{"trd":[[4.4,43.58]],"batb":[[0,3.55,3],[1,3.5,5.04],[2,3.45,3]],"ltp":4.4,"tv":4917.16,"id":9345630},{"batl":[[0,1.39,8],[1,1.4,42.49],[2,1.68,635.46]],"ltp":1.33,"tv":53977.72,"id":9028621}],"tv":58894.89}]}
{"op":"mcm","clk":"4226624231","pt":1631450354371,"mc":[{"id":"1.187552454","rc":[{"batb":[[0,1.31,310.55],[1,1.3,528.8],[2,1.27,6.16]],"batl":[[0,1.34,561.92],[1,1.35,422.51],[2,1.39,8]],"ltp":1.33,"tv":53977.72,"id":9028621}]}]}
{"op":"mcm","clk":"4226624428","pt":1631450355466,"mc":[{"id":"1.187552454","rc":[{"batl":[[0,4.8,10],[1,4.9,2],[2,990,0.01]],"ltp":4.4,"tv":4917.16,"id":9345630},{"batl":[[2,1.39,139.15]],"ltp":1.33,"tv":53977.72,"id":9028621}]}]}
{"op":"mcm","clk":"4226624768","pt":1631450357566,"mc":[{"id":"1.187552454","rc":[{"batb":[[0,3.7,2.02],[1,3.55,3],[2,3.5,5.04]],"batl":[[0,4.6,2],[1,4.8,10],[2,4.9,2]],"ltp":4.4,"tv":4917.16,"id":9345630},{"batb":[[2,1.28,50.66]],"batl":[[2,1.37,30.5]],"ltp":1.33,"tv":53977.72,"id":9028621}]}]}
{"op":"mcm","clk":"4226624948","pt":1631450358577,"mc":[{"id":"1.187552454","rc":[{"batb":[[1,3.6,25.2],[2,3.55,3]],"batl":[[1,4.9,2],[2,990,0.01]],"ltp":4.4,"tv":4917.16,"id":9345630}]}]}
{"op":"mcm","clk":"4226624995","pt":1631450358901,"mc":[{"id":"1.187552454","rc":[{"batb":[[1,3.55,3],[2,3.5,5.04]],"ltp":4.4,"tv":4917.16,"id":9345630},{"batb":[[0,1.31,354.91]],"ltp":1.33,"tv":53977.72,"id":9028621}]}]}
{"op":"mcm","clk":"4226625370","pt":1631450361280,"mc":[{"id":"1.187552454","rc":[{"batb":[[0,3.55,3],[1,3.5,5.04],[2,3.45,3]],"batl":[[0,4.9,2],[1,990,0.01],[2,990,0]],"ltp":4.4,"tv":4917.16,"id":9345630},{"batb":[[0,1.27,6.16],[1,1.26,44.98],[2,1.22,31.31]],"batl":[[0,1.39,8],[1,1.4,42.49],[2,1.68,635.46]],"ltp":1.33,"tv":53977.72,"id":9028621}]}]}
{"op":"mcm","clk":"4226625689","pt":1631450363480,"mc":[{"id":"1.187552454","rc":[{"batb":[[1,3.5,2.04],[2,1.01,30]],"ltp":4.4,"tv":4917.16,"id":9345630},{"batb":[[0,1.34,8.55],[1,1.27,6.16],[2,1.26,417.38]],"batl":[[0,1.39,464.34],[1,1.4,401.48]],"ltp":1.33,"tv":53977.72,"id":9028621}]}]}
{"op":"mcm","clk":"4226625841","pt":1631450364498,"mc":[{"id":"1.187552454","rc":[{"batb":[[0,3.7,2],[1,3.55,3],[2,3.5,2.04]],"batl":[[0,4.8,10],[1,4.9,2],[2,1000,0.35]],"ltp":4.4,"tv":4917.16,"id":9345630},{"batl":[[0,1.37,33.5],[1,1.39,464.34],[2,1.4,401.48]],"ltp":1.33,"tv":53977.72,"id":9028621}]}]}
{"op":"mcm","clk":"4226625868","pt":1631450364712,"mc":[{"id":"1.187552454","rc":[{"batb":[[0,3.55,3],[1,3.5,2.04],[2,1.01,30]],"batl":[[0,4.9,2],[1,990,0.01],[2,1000,0]],"ltp":4.4,"tv":4917.16,"id":9345630},{"batl":[[0,1.39,464.34],[1,1.4,401.48],[2,1.68,635.46]],"ltp":1.33,"tv":53977.72,"id":9028621}]}]}
{"op":"mcm","clk":"4226626151","pt":1631450366497,"mc":[{"id":"1.187552454","rc":[{"batb":[[1,3.5,5.04]],"ltp":4.4,"tv":4917.16,"id":9345630}]}]}
{"op":"mcm","clk":"4226626198","pt":1631450366818,"mc":[{"id":"1.187552454","rc":[{"batl":[[1,1.4,394.48]],"ltp":1.33,"tv":53977.72,"id":9028621}]}]}
{"op":"mcm","clk":"4226626448","pt":1631450368423,"mc":[{"id":"1.187552454","rc":[{"trd":[[3.9,27.77]],"ltp":3.9,"tv":4917.5,"id":9345630},{"trd":[[1.27,2658.9],[1.34,15120.08]],"batb":[[0,1.26,417.38],[1,1.25,661.29],[2,1.22,31.31]],"batl":[[0,1.27,23.55],[1,1.39,464.34],[2,1.4,394.48]],"ltp":1.27,"tv":54016.39,"id":9028621}],"tv":58933.9}]}
{"op":"mcm","clk":"4226626662","pt":1631450369897,"mc":[{"id":"1.187552454","rc":[{"batb":[[0,1.26,44.98],[1,1.22,31.31],[2,1.21,440.98]],"ltp":1.27,"tv":54016.39,"id":9028621}]}]}
{"op":"mcm","clk":"4226626879","pt":1631450371498,"mc":[{"id":"1.187552454","rc":[{"batb":[[0,3.7,2],[1,3.5,2.04]],"batl":[[0,4.6,2],[1,4.9,2],[2,990,0.01]],"ltp":3.9,"tv":4917.5,"id":9345630},{"batb":[[0,1.28,40.66],[1,1.26,44.98],[2,1.22,31.31]],"batl":[[0,1.37,31.5],[1,1.39,456.34]],"ltp":1.27,"tv":54016.39,"id":9028621}]}]}
{"op":"mcm","clk":"4226627034","pt":1631450372473,"mc":[{"id":"1.187552454","rc":[{"batb":[[0,3.5,2.04],[1,1.01,30],[2,1.01,0]],"batl":[[0,4.7,8.54]],"ltp":3.9,"tv":4917.5,"id":9345630},{"batb":[[0,1.35,1416.67],[1,1.34,1375],[2,1.33,1375]],"batl":[[0,1.39,456.34],[1,1.4,394.48],[2,1.68,635.46]],"ltp":1.27,"tv":54016.39,"id":9028621}]}]}
{"op":"mcm","clk":"4226627195","pt":1631450373497,"mc":[{"id":"1.187552454","rc":[{"batb":[[1,3.45,321.74],[2,3.4,70.16]],"batl":[[0,3.9,3.85],[1,4.7,8.54],[2,4.9,2]],"ltp":3.9,"tv":4917.5,"id":9345630},{"trd":[[1.38,105.75]],"batb":[[0,1.38,2.44],[1,1.35,1453.9],[2,1.34,1213.69]],"batl":[[1,1.4,400.18]],"ltp":1.38,"tv":54039.51,"id":9028621}],"tv":58957.02}]}
{"op":"mcm","clk":"4226627365","pt":1631450374423,"mc":[{"id":"1.187552454","rc":[{"batb":[[0,3.55,23.52],[1,3.5,2.04],[2,3.45,321.74]],"batl":[[1,4.1,34.07],[2,4.7,11.54]],"ltp":3.9,"tv":4917.5,"id":9345630},{"batb":[[0,1.35,1453.9],[1,1.34,1213.69],[2,1.33,756.25]],"batl":[[0,1.39,516.34]],"ltp":1.38,"tv":54039.51,"id":9028621}]}]}
{"op":"mcm","clk":"4226627556","pt":1631450375526,"mc":[{"id":"1.187552454","rc":[{"batl":[[2,4.5,2]],"ltp":3.9,"tv":4917.5,"id":9345630},{"trd":[[1.35,2441.55]],"batb":[[0,1.35,1445.56]],"ltp":1.35,"tv":54056.19,"id":9028621}],"tv":58973.7}]}
{"op":"mcm","clk":"4226628001","pt":1631450378294,"mc":[{"id":"1.187552454","rc":[{"batl":[[0,3.85,19.25],[1,3.9,3.85],[2,4.1,34.07]],"ltp":3.9,"tv":4917.5,"id":9345630},{"batb":[[0,1.36,38.01],[1,1.35,1445.56],[2,1.34,1213.69]],"ltp":1.35,"tv":54056.19,"id":9028621}]}]}
{"op":"mcm","clk":"4226628441","pt":1631450381301,"mc":[{"id":"1.187552454","rc":[{"batl":[[2,1.48,25.49]],"ltp":1.35,"tv":54056.19,"id":9028621}]}]}
{"op":"mcm","clk":"4226629180","pt":1631450386416,"mc":[{"id":"1.187552454","rc":[{"batl":[[0,1.38,11.7],[1,1.39,516.34],[2,1.4,400.18]],"ltp":1.35,"tv":54056.19,"id":9028621}]}]}
{"op":"mcm","clk":"4226629305","pt":1631450387213,"mc":[{"id":"1.187552454","rc":[{"trd":[[1.36,1564.67]],"batb":[[0,1.36,37.73]],"batl":[[0,1.38,11.37]],"ltp":1.36,"tv":54056.75,"id":9028621}],"tv":58974.26}]}
{"op":"mcm","clk":"4226629455","pt":1631450388374,"mc":[{"id":"1.187552454","rc":[{"batl":[[2,4.2,2]],"ltp":3.9,"tv":4917.5,"id":9345630},{"trd":[[1.36,1564.99],[1.38,128.5]],"batb":[[0,1.38,24.78],[1,1.36,37.57],[2,1.35,1445.56]],"batl":[[0,1.39,516.34],[1,1.4,400.18],[2,1.48,25.49]],"ltp":1.38,"tv":54079.82,"id":9028621}],"tv":58997.33}]}
{"op":"mcm","clk":"4226629670","pt":1631450389818,"mc":[{"id":"1.187552454","rc":[{"batl":[[1,1.4,394.48]],"ltp":1.38,"tv":54079.82,"id":9028621}]}]}
{"op":"mcm","clk":"4226629901","pt":1631450391494,"mc":[{"id":"1.187552454","rc":[{"batl":[[2,4,34.64]],"ltp":3.9,"tv":4917.5,"id":9345630},{"trd":[[1.38,165.06]],"batb":[[0,1.36,37.57],[1,1.35,1445.56],[2,1.34,1213.69]],"ltp":1.38,"tv":54116.38,"id":9028621}],"tv":59033.89}]}
{"op":"mcm","clk":"4226630129","pt":1631450392827,"mc":[{"id":"1.187552454","rc":[{"batb":[[0,1.38,8.54],[1,1.36,37.57],[2,1.35,1445.56]],"ltp":1.38,"tv":54116.38,"id":9028621}]}]}
{"op":"mcm","clk":"4226630347","pt":1631450394417,"mc":[{"id":"1.187552454","rc":[{"batb":[[1,3.05,2.09],[2,2.88,2.46]],"batl":[[0,4,34.64],[1,4.2,2],[2,4.5,2]],"ltp":3.9,"tv":4917.5,"id":9345630},{"batb":[[1,1.33,26.11],[2,1.32,43.39]],"batl":[[0,1.39,60],[1,1.48,25.49],[2,1.53,27.5]],"ltp":1.38,"tv":54116.38,"id":9028621}]}]}
{"op":"mcm","clk":"4226630502","pt":1631450395452,"mc":[{"id":"1.187552454","rc":[{"batb":[[0,3.05,2.09],[1,2.88,2.46],[2,1.01,30]],"batl":[[0,4.2,2],[1,4.5,2],[2,4.6,2]],"ltp":3.9,"tv":4917.5,"id":9345630},{"batb":[[1,1.32,43.39],[2,1.29,54.81]],"batl":[[0,1.48,25.49],[1,1.53,27.5],[2,1.68,635.46]],"ltp":1.38,"tv":54116.38,"id":9028621}]}]}
{"op":"mcm","clk":"4226630657","pt":1631450396402,"mc":[{"id":"1.187552454","rc":[{"batb":[[0,2.88,2.46],[1,1.01,30],[2,1.01,0]],"batl":[[0,4.5,2],[1,4.6,2],[2,990,0.01]],"ltp":3.9,"tv":4917.5,"id":9345630},{"trd":[[1.38,173.05]],"batb":[[0,1.38,4.54],[1,1.29,54.81],[2,1.24,426.73]],"batl":[[0,1.53,27.5],[1,1.68,635.46],[2,3.8,27.47]],"ltp":1.38,"tv":54124.37,"id":9028621}],"tv":59041.88}]}
{"op":"mcm","clk":"4226630794","pt":1631450397357,"mc":[{"id":"1.187552454","rc":[{"batb":[[1,1.3,498.29],[2,1.29,609.6]],"batl":[[0,1.48,318.8],[1,1.49,277.95],[2,1.53,27.5]],"ltp":1.38,"tv":54124.37,"id":9028621}]}]}
{"op":"mcm","clk":"4226631034","pt":1631450399220,"mc":[{"id":"1.187552454","rc":[{"batb":[[0,3.05,5.09],[1,3,3],[2,2.88,5.46]],"ltp":3.9,"tv":4917.5,"id":9345630},{"batl":[[0,1.48,354.04],[1,1.49,284.95],[2,1.53,32.5]],"ltp":1.38,"tv":54124.37,"id":9028621}]}]}
{"op":"mcm","clk":"4226631481","pt":1631450402458,"mc":[{"id":"1.187552454","rc":[{"batl":[[0,4.2,2],[1,4.5,2],[2,4.6,2]],"ltp":3.9,"tv":4917.5,"id":9345630},{"batb":[[1,1.32,38.89],[2,1.3,498.29]],"ltp":1.38,"tv":54124.37,"id":9028621}]}]}
{"op":"mcm","clk":"4226631536","pt":1631450402725,"mc":[{"id":"1.187552454","rc":[{"batl":[[0,4.5,2],[1,4.6,2],[2,990,0.01]],"ltp":3.9,"tv":4917.5,"id":9345630},{"batb":[[1,1.3,498.29],[2,1.29,609.6]],"ltp":1.38,"tv":54124.37,"id":9028621}]}]}
{"op":"mcm","clk":"4226631686","pt":1631450403768,"mc":[{"id":"1.187552454","rc":[{"trd":[[1.38,173.48]],"batb":[[0,1.38,4.33]],"ltp":1.38,"tv":54124.8,"id":9028621}],"tv":59042.31}]}
{"op":"mcm","clk":"4226631865","pt":1631450404964,"mc":[{"id":"1.187552454","rc":[{"batb":[[0,3.05,3]],"ltp":3.9,"tv":4917.5,"id":9345630},{"batl":[[0,1.48,6],[1,1.49,7]],"ltp":1.38,"tv":54124.8,"id":9028621}]}]}
{"op":"mcm","clk":"4226632093","pt":1631450406307,"mc":[{"id":"1.187552454","rc":[{"batb":[[0,3.9,24.52],[1,3.85,23.8],[2,3.8,23.8]],"ltp":3.9,"tv":4917.5,"id":9345630},{"trd":[[1.38,182.14]],"batb":[[0,1.3,498.29],[1,1.29,609.6],[2,1.22,31.31]],"batl":[[0,1.38,4.21],[1,1.48,6],[2,1.49,7]],"ltp":1.38,"tv":54133.46,"id":9028621}],"tv":59050.97}]}
{"op":"mcm","clk":"4226632312","pt":1631450407575,"mc":[{"id":"1.187552454","rc":[{"batb":[[0,3.9,99.84],[1,3.85,96.9],[2,3.8,96.9]],"ltp":3.9,"tv":4917.5,"id":9345630},{"batb":[[2,1.28,2988.28]],"batl":[[0,1.33,4196.56],[1,1.34,451.76],[2,1.36,5.87]],"ltp":1.38,"tv":54133.46,"id":9028621}]}]}
{"op":"mcm","clk":"4226632469","pt":1631450408494,"mc":[{"id":"1.187552454","rc":[{"trd":[[4,12.64]],"batb":[[0,3.9,62.18],[1,3.85,63.35],[2,3.8,60.35]],"ltp":4.0,"tv":4930.04,"id":9345630},{"trd":[[1.33,633.18]],"batb":[[2,1.28,1494.14]],"batl":[[0,1.33,437.02],[2,1.36,12.87]],"ltp":1.33,"tv":54171.17,"id":9028621}],"tv":59101.22}]}
{"op":"mcm","clk":"4226632685","pt":1631450409576,"mc":[{"id":"1.187552454","rc":[{"batb":[[0,3.95,20.33],[1,3.9,62.18],[2,3.85,63.35]],"batl":[[0,4.4,10],[1,4.5,2],[2,4.6,33.62]],"ltp":4.0,"tv":4930.04,"id":9345630},{"batb":[[0,1.3,550.46]],"batl":[[1,1.34,511.76]],"ltp":1.33,"tv":54171.17,"id":9028621}]}]}
{"op":"mcm","clk":"4226632977","pt":1631450411496,"mc":[{"id":"1.187552454","rc":[{"batl":[[1,1.34,451.76]],"ltp":1.33,"tv":54171.17,"id":9028621}]}]}
{"op":"mcm","clk":"4226633157","pt":1631450412568,"mc":[{"id":"1.187552454","rc":[{"batb":[[0,3.95,35.33]],"ltp":4.0,"tv":4930.04,"id":9345630}]}]}
{"op":"mcm","clk":"4226633397","pt":1631450414294,"mc":[{"id":"1.187552454","rc":[{"batl":[[2,4.6,35.62]],"ltp":4.0,"tv":4930.04,"id":9345630},{"batb":[[2,1.28,1540.8]],"ltp":1.33,"tv":54171.17,"id":9028621}]}]}
{"op":"mcm","clk":"4226633457","pt":1631450414677,"mc":[{"id":"1.187552454","rc":[{"batl":[[0,1.33,497.02]],"ltp":1.33,"tv":54171.17,"id":9028621}]}]}
{"op":"mcm","clk":"4226634020","pt":1631450418503,"mc":[{"id":"1.187552454","rc":[{"trd":[[4,13.33]],"ltp":4.0,"tv":4930.74,"id":9345630},{"trd":[[1.33,635.28]],"batl":[[0,1.33,494.92]],"ltp":1.33,"tv":54173.27,"id":9028621}],"tv":59104.02}]}
{"op":"mcm","clk":"4226634171","pt":1631450419515,"mc":[{"id":"1.187552454","rc":[{"trd":[[1.33,644.26]],"batl":[[0,1.33,490.43]],"ltp":1.33,"tv":54182.25,"id":9028621}],"tv":59113.0}]}
{"op":"mcm","clk":"4226634202","pt":1631450419726,"mc":[{"id":"1.187552454","rc":[{"trd":[[4,13.43]],"ltp":4.0,"tv":4930.84,"id":9345630},{"trd":[[1.33,644.56]],"batl":[[0,1.33,490.13]],"ltp":1.33,"tv":54182.55,"id":9028621}],"tv":59113.4}]}
{"op":"mcm","clk":"4226634625","pt":1631450422807,"mc":[{"id":"1.187552454","rc":[{"trd":[[1.33,644.96]],"batl":[[0,1.33,489.93]],"ltp":1.33,"tv":54182.95,"id":9028621}],"tv":59113.79}]}
{"op":"mcm","clk":"4226634905","pt":1631450424613,"mc":[{"id":"1.187552454","rc":[{"batl":[[1,1.34,439.85],[2,1.36,7]],"ltp":1.33,"tv":54182.95,"id":9028621}]}]}
{"op":"mcm","clk":"4226635188","pt":1631450426390,"mc":[{"id":"1.187552454","rc":[{"trd":[[4,16.07]],"batb":[[1,3.85,3],[2,3.6,2.04]],"ltp":4.0,"tv":4933.48,"id":9345630},{"trd":[[1.3,580.22],[1.33,652.89]],"batb":[[0,1.3,548.51],[2,1.28,46.66]],"batl":[[0,1.33,482]],"ltp":1.3,"tv":54194.78,"id":9028621}],"tv":59128.26}]}
{"op":"mcm","clk":"4226635290","pt":1631450427203,"mc":[{"id":"1.187552454","rc":[{"batb":[[0,3.95,20.33],[1,3.6,2.04],[2,3.4,2.01]],"batl":[[0,4.6,33.62],[1,4.9,2],[2,990,0.01]],"ltp":4.0,"tv":4933.48,"id":9345630},{"trd":[[1.33,669.99]],"batb":[[0,1.27,28.86],[1,1.26,50.98],[2,1.21,440.98]],"batl":[[0,1.33,60],[1,1.38,33.07],[2,1.41,26.5]],"ltp":1.33,"tv":54211.89,"id":9028621}],"tv":59145.37}]}
{"op":"mcm","clk":"4226635466","pt":1631450428534,"mc":[{"id":"1.187552454","rc":[{"batb":[[0,3.6,2.04],[1,3.4,2.01],[2,3.1,3]],"batl":[[0,4.6,2]],"ltp":4.0,"tv":4933.48,"id":9345630},{"batb":[[0,1.26,50.98],[1,1.21,440.98],[2,1.12,6.16]],"batl":[[0,1.38,33.07],[1,1.41,26.5],[2,1.53,27.5]],"ltp":1.33,"tv":54211.89,"id":9028621}]}]}
{"op":"mcm","clk":"4226635520","pt":1631450428916,"mc":[{"id":"1.187552454","rc":[{"batb":[[0,3.4,2.01],[1,3.1,3],[2,2.88,2.46]],"ltp":4.0,"tv":4933.48,"id":9345630},{"batl":[[0,1.41,26.82],[1,1.53,27.5],[2,1.68,635.46]],"ltp":1.33,"tv":54211.89,"id":9028621}]}]}
{"op":"mcm","clk":"4226635766","pt":1631450430416,"mc":[{"id":"1.187552454","rc":[{"batb":[[0,3.5,3],[1,3.45,2],[2,3.4,2.01]],"batl":[[0,4.5,3],[1,4.6,4],[2,4.9,2]],"ltp":4.0,"tv":4933.48,"id":9345630},{"batb":[[0,1.28,56.16],[1,1.27,8],[2,1.26,692.85]],"batl":[[0,1.4,579.29],[1,1.41,373.01],[2,1.53,27.5]],"ltp":1.33,"tv":54211.89,"id":9028621}]}]}
{"op":"mcm","clk":"4226635822","pt":1631450430804,"mc":[{"id":"1.187552454","rc":[{"batl":[[1,4.6,2]],"ltp":4.0,"tv":4933.48,"id":9345630},{"batb":[[0,1.28,10]],"batl":[[0,1.38,1319.57],[1,1.4,578.97],[2,1.41,373.01]],"ltp":1.33,"tv":54211.89,"id":9028621}]}]}
{"op":"mcm","clk":"4226636028","pt":1631450432320,"mc":[{"id":"1.187552454","rc":[{"batb":[[0,3.6,2.04],[1,3.5,3],[2,3.45,2]],"ltp":4.0,"tv":4933.48,"id":9345630},{"batl":[[0,1.38,1354.32],[2,1.41,379.01]],"ltp":1.33,"tv":54211.89,"id":9028621}]}]}
{"op":"mcm","clk":"4226636123","pt":1631450433015,"mc":[{"id":"1.187552454","rc":[{"batl":[[1,1.4,586.97]],"ltp":1.33,"tv":54211.89,"id":9028621}]}]}
{"op":"mcm","clk":"4226636831","pt":1631450437912,"mc":[{"id":"1.187552454","rc":[{"batb":[[2,1.26,699.01]],"ltp":1.33,"tv":54211.89,"id":9028621}]}]}
{"op":"mcm","clk":"4226637330","pt":1631450441527,"mc":[{"id":"1.187552454","rc":[{"batb":[[2,3.4,4.01]],"batl":[[1,4.9,2],[2,990,0.01]],"ltp":4.0,"tv":4933.48,"id":9345630},{"batb":[[1,1.26,699.01],[2,1.25,676.31]],"ltp":1.33,"tv":54211.89,"id":9028621}]}]}
{"op":"mcm","clk":"4226637799","pt":1631450445027,"mc":[{"id":"1.187552454","rc":[{"batb":[[2,3.45,3]],"ltp":4.0,"tv":4933.48,"id":9345630},{"batb":[[1,1.27,11],[2,1.26,689.01]],"batl":[[2,1.41,373.01]],"ltp":1.33,"tv":54211.89,"id":9028621}]}]}
{"op":"mcm","clk":"4226637987","pt":1631450446286,"mc":[{"id":"1.187552454","rc":[{"trd":[[3.6,33.13]],"batb":[[0,3.5,3],[1,3.45,3],[2,3.4,2.01]],"ltp":3.6,"tv":4944.16,"id":9345630},{"trd":[[1.38,199.35]],"batb":[[0,1.36,70.31],[1,1.35,68.24],[2,1.34,68.24]],"batl":[[0,1.38,1337.11]],"ltp":1.38,"tv":54229.1,"id":9028621}],"tv":59173.26}]}
{"op":"mcm","clk":"4226638368","pt":1631450448589,"mc":[{"id":"1.187552454","rc":[{"batb":[[0,3.4,2.01],[1,3.35,663.84],[2,3.3,644.31]],"batl":[[0,3.9,3.85],[1,4.5,3],[2,4.9,2]],"ltp":3.6,"tv":4944.16,"id":9345630},{"batb":[[0,1.36,1476.56],[1,1.35,1466.6],[2,1.34,1433.13]],"batl":[[1,1.4,578.97]],"ltp":1.38,"tv":54229.1,"id":9028621}]}]}
{"op":"mcm","clk":"4226638506","pt":1631450449504,"mc":[{"id":"1.187552454","rc":[{"batb":[[1,3.35,75.01],[2,3.3,72.82]],"ltp":3.6,"tv":4944.16,"id":9345630},{"trd":[[1.36,1699.81]],"batb":[[0,1.37,14],[1,1.36,1166.15],[2,1.35,1222.58]],"batl":[[1,1.39,11.48],[2,1.4,578.97]],"ltp":1.36,"tv":54363.92,"id":9028621}],"tv":59308.08}]}
{"op":"mcm","clk":"4226638659","pt":1631450450477,"mc":[{"id":"1.187552454","rc":[{"batb":[[0,3.5,24],[1,3.4,2.01],[2,3.35,75.01]],"batl":[[1,4.1,34.07],[2,4.5,3]],"ltp":3.6,"tv":4944.16,"id":9345630},{"batb":[[0,1.37,7]],"batl":[[2,1.4,638.97]],"ltp":1.36,"tv":54363.92,"id":9028621}]}]}
{"op":"mcm","clk":"4226638761","pt":1631450451175,"mc":[{"id":"1.187552454","rc":[{"batb":[[0,1.37,47.09]],"ltp":1.36,"tv":54363.92,"id":9028621}]}]}
{"op":"mcm","clk":"4226638952","pt":1631450452563,"mc":[{"id":"1.187552454","rc":[{"batb":[[0,3.55,5.39],[1,3.5,24],[2,3.4,12.06]],"batl":[[1,4.5,3],[2,4.9,2]],"ltp":3.6,"tv":4944.16,"id":9345630},{"batl":[[0,1.38,1302.36]],"ltp":1.36,"tv":54363.92,"id":9028621}]}]}
{"op":"mcm","clk":"4226639070","pt":1631450453473,"mc":[{"id":"1.187552454","rc":[{"batl":[[2,4.6,88.2]],"ltp":3.6,"tv":4944.16,"id":9345630},{"trd":[[1.37,693.83]],"batb":[[0,1.37,46.7]],"ltp":1.37,"tv":54364.7,"id":9028621}],"tv":59308.86}]}
{"op":"mcm","clk":"4226639182","pt":1631450454287,"mc":[{"id":"1.187552454","rc":[{"batl":[[0,3.85,19.25],[1,3.9,3.85],[2,4.5,3]],"ltp":3.6,"tv":4944.16,"id":9345630}]}]}
{"op":"mcm","clk":"4226639349","pt":1631450455317,"mc":[{"id":"1.187552454","rc":[{"batl":[[2,4.2,2]],"ltp":3.6,"tv":4944.16,"id":9345630},{"trd":[[1.36,1726.17],[1.37,787.23]],"batb":[[0,1.36,1152.97],[1,1.35,1222.58],[2,1.34,776.4]],"ltp":1.36,"tv":54484.46,"id":9028621}],"tv":59428.62}]}
{"op":"mcm","clk":"4226639830","pt":1631450458462,"mc":[{"id":"1.187552454","rc":[{"batl":[[1,3.9,39.08]],"ltp":3.6,"tv":4944.16,"id":9345630},{"batl":[[0,1.38,1302.56]],"ltp":1.36,"tv":54484.46,"id":9028621}]}]}
{"op":"mcm","clk":"4226640007","pt":1631450459583,"mc":[{"id":"1.187552454","rc":[{"trd":[[1.37,787.63]],"batb":[[0,1.37,37.13],[1,1.36,1152.97],[2,1.35,1222.58]],"batl":[[0,1.38,1302.36]],"ltp":1.37,"tv":54484.86,"id":9028621}],"tv":59429.02}]}
{"op":"mcm","clk":"4226641018","pt":1631450465810,"mc":[{"id":"1.187552454","rc":[{"trd":[[1.38,199.75]],"batl":[[0,1.38,1302.17],[1,1.4,638.97],[2,1.41,373.01]],"ltp":1.38,"tv":54485.25,"id":9028621}],"tv":59429.41}]}
{"op":"mcm","clk":"4226641651","pt":1631450469929,"mc":[{"id":"1.187552454","rc":[{"trd":[[3.75,9.02]],"ltp":3.75,"tv":4952.35,"id":9345630},{"trd":[[1.37,810.07]],"batb":[[0,1.36,1152.97],[1,1.35,1222.58],[2,1.34,776.4]],"batl":[[0,1.4,638.97],[1,1.41,373.01],[2,1.49,26.5]],"ltp":1.37,"tv":54507.69,"id":9028621}],"tv":59460.05}]}
{"op":"mcm","clk":"4226641818","pt":1631450471058,"mc":[{"id":"1.187552454","rc":[{"trd":[[3.7,46.03]],"batl":[[0,3.6,12.08],[1,3.85,19.25],[2,3.9,39.08]],"ltp":3.7,"tv":4953.08,"id":9345630},{"trd":[[1.37,812.01]],"ltp":1.37,"tv":54509.64,"id":9028621}],"tv":59462.73}]}
{"op":"mcm","clk":"4226642377","pt":1631450474514,"mc":[{"id":"1.187552454","rc":[{"batb":[[0,1.38,50],[1,1.36,1208.13],[2,1.35,1222.58]],"ltp":1.37,"tv":54509.64,"id":9028621}]}]}
{"op":"mcm","clk":"4226642527","pt":1631450475484,"mc":[{"id":"1.187552454","rc":[{"batb":[[0,3.5,24],[1,2.88,2.46],[2,2.84,2.47]],"batl":[[0,3.9,35.23],[1,3.95,2],[2,4.1,2]],"ltp":3.7,"tv":4953.08,"id":9345630},{"batb":[[1,1.34,60.94],[2,1.33,37.53]],"batl":[[0,1.4,60],[1,1.49,26.5],[2,1.53,27.5]],"ltp":1.37,"tv":54509.64,"id":9028621}]}]}
{"op":"mcm","clk":"4226642689","pt":1631450476544,"mc":[{"id":"1.187552454","rc":[{"batb":[[0,2.88,2.46],[1,2.84,2.47],[2,2.8,2.08]],"batl":[[0,4.1,2],[1,4.2,2],[2,4.3,2]],"ltp":3.7,"tv":4953.08,"id":9345630},{"batb":[[1,1.33,37.53],[2,1.32,40.89]],"batl":[[0,1.49,26.5],[1,1.53,27.5],[2,1.54,24.25]],"ltp":1.37,"tv":54509.64,"id":9028621}]}]}
{"op":"mcm","clk":"4226642770","pt":1631450476933,"mc":[{"id":"1.187552454","rc":[{"batb":[[0,2.84,2.47],[1,1.01,30],[2,2.8,0]],"batl":[[0,4.3,2],[1,4.5,3],[2,990,0.01]],"ltp":3.7,"tv":4953.08,"id":9345630},{"batb":[[1,1.31,40.79],[2,1.28,10]],"batl":[[0,1.54,24.25],[1,1.68,635.46],[2,3.8,27.47]],"ltp":1.37,"tv":54509.64,"id":9028621}]}]}
{"op":"mcm","clk":"4226642979","pt":1631450478477,"mc":[{"id":"1.187552454","rc":[{"batb":[[2,1.3,761.29]],"batl":[[0,1.49,384.35],[1,1.5,270.14],[2,1.54,24.25]],"ltp":1.37,"tv":54509.64,"id":9028621}]}]}
{"op":"mcm","clk":"4226643283","pt":1631450480248,"mc":[{"id":"1.187552454","rc":[{"batb":[[0,3,3],[1,2.98,3],[2,2.84,5.47]],"ltp":3.7,"tv":4953.08,"id":9345630},{"batl":[[0,1.49,413.85],[1,1.5,277.14],[2,1.54,29.25]],"ltp":1.37,"tv":54509.64,"id":9028621}]}]}
{"op":"mcm","clk":"4226643748","pt":1631450483373,"mc":[{"id":"1.187552454","rc":[{"trd":[[1.38,200.16]],"batb":[[0,1.38,49.79]],"ltp":1.38,"tv":54510.06,"id":9028621}],"tv":59463.14}]}
{"op":"mcm","clk":"4226644209","pt":1631450486346,"mc":[{"id":"1.187552454","rc":[{"batl":[[0,3.95,2],[1,4.3,2],[2,4.5,3]],"ltp":3.7,"tv":4953.08,"id":9345630},{"batb":[[1,1.34,41.22],[2,1.31,40.79]],"ltp":1.38,"tv":54510.06,"id":9028621}]}]}
{"op":"mcm","clk":"4226644256","pt":1631450486673,"mc":[{"id":"1.187552454","rc":[{"batl":[[0,4.3,2],[1,4.5,3],[2,990,0.01]],"ltp":3.7,"tv":4953.08,"id":9345630},{"batb":[[1,1.31,40.79],[2,1.3,761.29]],"ltp":1.38,"tv":54510.06,"id":9028621}]}]}
{"op":"mcm","clk":"4226644488","pt":1631450488167,"mc":[{"id":"1.187552454","rc":[{"batl":[[0,1.49,5],[1,1.5,7]],"ltp":1.38,"tv":54510.06,"id":9028621}]}]}
{"op":"mcm","clk":"4226644715","pt":1631450489563,"mc":[{"id":"1.187552454","rc":[{"batl":[[0,3.6,4.4],[1,4.3,2],[2,4.5,3]],"ltp":3.7,"tv":4953.08,"id":9345630},{"trd":[[1.38,217.24]],"batb":[[0,1.38,41.25]],"ltp":1.38,"tv":54527.14,"id":9028621}],"tv":59480.22}]}
{"op":"mcm","clk":"4226644827","pt":1631450490276,"mc":[{"id":"1.187552454","rc":[{"trd":[[3.6,41.92],[3.65,227.8]],"batb":[[0,3.9,24.52],[1,3.85,23.8],[2,3.8,23.8]],"batl":[[0,4.3,2],[1,4.5,3],[2,990,0.01]],"ltp":3.65,"tv":4977.48,"id":9345630},{"trd":[[1.34,15146.24],[1.38,258.49]],"batb":[[0,1.31,40.79],[1,1.3,761.29],[2,1.29,559.53]],"ltp":1.34,"tv":54594.55,"id":9028621}],"tv":59572.03}]}
{"op":"mcm","clk":"4226645042","pt":1631450491475,"mc":[{"id":"1.187552454","rc":[{"batb":[[0,3.9,62.78],[1,3.85,66.94],[2,3.8,60.94]],"ltp":3.65,"tv":4977.48,"id":9345630},{"batl":[[0,1.34,679.08],[1,1.35,421.27],[2,1.36,5.87]],"ltp":1.34,"tv":54594.55,"id":9028621}]}]}
{"op":"mcm","clk":"4226645199","pt":1631450492461,"mc":[{"id":"1.187552454","rc":[{"batb":[[1,3.85,63.94]],"batl":[[1,4.5,35.07]],"ltp":3.65,"tv":4977.48,"id":9345630}]}]}
{"op":"mcm","clk":"4226645340","pt":1631450493387,"mc":[{"id":"1.187552454","rc":[{"batl":[[0,4.2,10],[1,4.3,2],[2,4.5,35.07]],"ltp":3.65,"tv":4977.48,"id":9345630},{"batb":[[0,1.31,86.34],[1,1.3,770.29]],"batl":[[1,1.35,481.27]],"ltp":1.34,"tv":54594.55,"id":9028621}]}]}
{"op":"mcm","clk":"4226645642","pt":1631450495037,"mc":[{"id":"1.187552454","rc":[{"batl":[[1,1.35,421.27]],"ltp":1.34,"tv":54594.55,"id":9028621}]}]}
{"op":"mcm","clk":"4226646212","pt":1631450498257,"mc":[{"id":"1.187552454","rc":[{"batl":[[2,4.5,37.07]],"ltp":3.65,"tv":4977.48,"id":9345630},{"batb":[[2,1.29,606.34]],"batl":[[0,1.34,739.08]],"ltp":1.34,"tv":54594.55,"id":9028621}]}]}
{"op":"mcm","clk":"4226646422","pt":1631450499344,"mc":[{"id":"1.187552454","rc":[{"batb":[[0,3.95,20.33],[1,3.9,62.78],[2,3.85,63.94]],"ltp":3.65,"tv":4977.48,"id":9345630}]}]}
{"op":"mcm","clk":"4226646999","pt":1631450502761,"mc":[{"id":"1.187552454","rc":[{"batl":[[0,1.34,706.36]],"ltp":1.34,"tv":54594.55,"id":9028621}]}]}
{"op":"mcm","clk":"4226647445","pt":1631450505447,"mc":[{"id":"1.187552454","rc":[{"trd":[[1.34,15163.82]],"batl":[[0,1.34,697.57]],"ltp":1.34,"tv":54612.13,"id":9028621}],"tv":59589.61}]}
{"op":"mcm","clk":"4226647828","pt":1631450507850,"mc":[{"id":"1.187552454","rc":[{"batl":[[0,1.34,694.45],[2,1.38,7]],"ltp":1.34,"tv":54612.13,"id":9028621}]}]}
{"op":"mcm","clk":"4226648090","pt":1631450509463,"mc":[{"id":"1.187552454","rc":[{"trd":[[1.34,15164.21]],"batl":[[0,1.34,694.25]],"ltp":1.34,"tv":54612.53,"id":9028621}],"tv":59590.01}]}
{"op":"mcm","clk":"4226648543","pt":1631450511547,"mc":[{"id":"1.187552454","rc":[{"batb":[[1,3.85,3],[2,3.55,2.02]],"ltp":3.65,"tv":4977.48,"id":9345630}]}]}
{"op":"mcm","clk":"4226648794","pt":1631450512543,"mc":[{"id":"1.187552454","rc":[{"batb":[[2,3.35,2]],"batl":[[0,4.5,35.07],[1,4.8,2],[2,990,0.01]],"ltp":3.65,"tv":4977.48,"id":9345630},{"batb":[[0,1.28,28.34],[1,1.27,51.87],[2,1.26,6.16]],"batl":[[0,1.34,60],[1,1.38,7],[2,1.42,32.75]],"ltp":1.34,"tv":54612.53,"id":9028621}]}]}
{"op":"mcm","clk":"4226649138","pt":1631450513488,"mc":[{"id":"1.187552454","rc":[{"batb":[[0,3.35,2],[1,3,3],[2,2.84,2.47]],"batl":[[0,4.5,3]],"ltp":3.65,"tv":4977.48,"id":9345630},{"batb":[[0,1.27,51.87],[1,1.26,11.9],[2,1.21,440.98]],"batl":[[0,1.42,32.75],[1,1.54,29.25],[2,1.68,635.46]],"ltp":1.34,"tv":54612.53,"id":9028621}]}]}
{"op":"mcm","clk":"4226649208","pt":1631450513660,"mc":[{"id":"1.187552454","rc":[{"batl":[[0,1.39,1319.26],[1,1.42,32.75],[2,1.54,29.25]],"ltp":1.34,"tv":54612.53,"id":9028621}]}]}
{"op":"mcm","clk":"4226649610","pt":1631450515082,"mc":[{"id":"1.187552454","rc":[{"batl":[[0,4.4,3],[1,4.5,3],[2,4.8,2]],"ltp":3.65,"tv":4977.48,"id":9345630},{"batb":[[0,1.29,10],[1,1.28,9],[2,1.27,304.68]],"batl":[[1,1.4,353.86],[2,1.41,349.03]],"ltp":1.34,"tv":54612.53,"id":9028621}]}]}
{"op":"mcm","clk":"4226649863","pt":1631450516057,"mc":[{"id":"1.187552454","rc":[{"batb":[[0,3.55,2],[1,3.35,2],[2,3,3]],"ltp":3.65,"tv":4977.48,"id":9345630},{"batb":[[2,1.27,313.68]],"batl":[[0,1.39,1350.76]],"ltp":1.34,"tv":54612.53,"id":9028621}]}]}
{"op":"mcm","clk":"4226650044","pt":1631450516858,"mc":[{"id":"1.187552454","rc":[{"batb":[[2,1.27,60.87]],"batl":[[1,1.42,32.75],[2,1.54,29.25]],"ltp":1.34,"tv":54612.53,"id":9028621}]}]}
{"op":"mcm","clk":"4226650663","pt":1631450519376,"mc":[{"id":"1.187552454","rc":[{"batl":[[1,4.5,5]],"ltp":3.65,"tv":4977.48,"id":9345630},{"batb":[[0,1.29,54.81]],"ltp":1.34,"tv":54612.53,"id":9028621}]}]}
{"op":"mcm","clk":"4226650852","pt":1631450520160,"mc":[{"id":"1.187552454","rc":[{"batl":[[1,4.5,3]],"ltp":3.65,"tv":4977.48,"id":9345630},{"trd":[[1.34,15164.61]],"batb":[[0,1.32,319.69],[1,1.31,507.84],[2,1.29,10]],"batl":[[0,1.35,506.58],[1,1.36,408.7],[2,1.39,1350.76]],"ltp":1.34,"tv":54612.92,"id":9028621}],"tv":59590.4}]}
{"op":"mcm","clk":"4226651081","pt":1631450521210,"mc":[{"id":"1.187552454","rc":[{"batb":[[0,3.6,10],[1,3.55,2],[2,3.35,2]],"batl":[[0,4.3,15],[1,4.4,3],[2,4.5,3]],"ltp":3.65,"tv":4977.48,"id":9345630},{"batl":[[2,1.38,81.02]],"ltp":1.34,"tv":54612.92,"id":9028621}]}]}
{"op":"mcm","clk":"4226651547","pt":1631450523323,"mc":[{"id":"1.187552454","rc":[{"batl":[[2,4.5,5]],"ltp":3.65,"tv":4977.48,"id":9345630},{"batb":[[2,1.29,54.81]],"ltp":1.34,"tv":54612.92,"id":9028621}]}]}
{"op":"mcm","clk":"4226651832","pt":1631450524272,"mc":[{"id":"1.187552454","rc":[{"batb":[[0,1.32,369.69]],"ltp":1.34,"tv":54612.92,"id":9028621}]}]}
{"op":"mcm","clk":"4226652271","pt":1631450526195,"mc":[{"id":"1.187552454","rc":[{"batb":[[0,3.55,2],[1,3.35,2],[2,3,3]],"batl":[[0,4.4,3],[1,4.8,2],[2,990,0.01]],"ltp":3.65,"tv":4977.48,"id":9345630},{"batb":[[0,1.29,10],[1,1.27,60.87],[2,1.26,28.06]],"batl":[[0,1.39,1350.76],[1,1.42,32.75],[2,1.54,29.25]],"ltp":1.34,"tv":54612.92,"id":9028621}]}]}
{"op":"mcm","clk":"4226652919","pt":1631450529504,"mc":[{"id":"1.187552454","rc":[{"batl":[[1,4.5,2],[2,4.8,2]],"ltp":3.65,"tv":4977.48,"id":9345630},{"batb":[[0,1.29,52.81],[1,1.28,10],[2,1.27,304.68]],"batl":[[1,1.4,353.86],[2,1.41,349.03]],"ltp":1.34,"tv":54612.92,"id":9028621}]}]}
{"op":"mcm","clk":"4226653036","pt":1631450530123,"mc":[{"id":"1.187552454","rc":[{"batl":[[1,4.8,2],[2,990,0.01]],"ltp":3.65,"tv":4977.48,"id":9345630},{"batb":[[0,1.29,10]],"batl":[[0,1.31,1.56],[1,1.39,1350.76],[2,1.4,353.86]],"ltp":1.34,"tv":54612.92,"id":9028621}]}]}
{"op":"mcm","clk":"4226653241","pt":1631450531227,"mc":[{"id":"1.187552454","rc":[{"batb":[[2,1.27,51.87]],"ltp":1.34,"tv":54612.92,"id":9028621}]}]}
{"op":"mcm","clk":"4226653441","pt":1631450532383,"mc":[{"id":"1.187552454","rc":[{"batl":[[0,1.31,1.36]],"ltp":1.34,"tv":54612.92,"id":9028621}]}]}
{"op":"mcm","clk":"4226653611","pt":1631450533322,"mc":[{"id":"1.187552454","rc":[{"trd":[[3.55,23.83]],"batb":[[0,3.35,2],[1,3,3],[2,2.84,2.47]],"batl":[[1,4.5,2],[2,4.8,2]],"ltp":3.55,"tv":4988.02,"id":9345630},{"trd":[[1.31,740.57],[1.39,288.19]],"batb":[[0,1.36,70.31],[1,1.35,68.24],[2,1.34,68.24]],"batl":[[0,1.39,1334.05],[1,1.4,353.86],[2,1.41,349.03]],"ltp":1.39,"tv":54632.36,"id":9028621}],"tv":59620.38}]}
{"op":"mcm","clk":"4226653869","pt":1631450534397,"mc":[{"id":"1.187552454","rc":[{"batb":[[0,3.55,2],[1,3.5,2],[2,3.35,77.76]],"batl":[[0,3.9,3.35],[1,4.4,3]],"ltp":3.55,"tv":4988.02,"id":9345630},{"batb":[[0,1.37,276.9],[1,1.36,1194.15],[2,1.35,779.95]],"batl":[[0,1.39,1341.05],[1,1.4,365.26]],"ltp":1.39,"tv":54632.36,"id":9028621}]}]}
{"op":"mcm","clk":"4226654138","pt":1631450535438,"mc":[{"id":"1.187552454","rc":[{"batb":[[0,3.45,24.48],[1,3.35,77.76],[2,3.3,322.88]],"batl":[[1,3.95,34.93],[2,4.2,15]],"ltp":3.55,"tv":4988.02,"id":9345630},{"batb":[[0,1.37,283.9]],"batl":[[0,1.39,1334.05],[2,1.41,409.03]],"ltp":1.39,"tv":54632.36,"id":9028621}]}]}
{"op":"mcm","clk":"4226654372","pt":1631450536189,"mc":[{"id":"1.187552454","rc":[{"batb":[[1,3.4,10],[2,3.35,77.76]],"batl":[[2,4.3,3]],"ltp":3.55,"tv":4988.02,"id":9345630}]}]}
{"op":"mcm","clk":"4226654572","pt":1631450536961,"mc":[{"id":"1.187552454","rc":[{"batl":[[0,1.38,3.79],[1,1.39,1334.05],[2,1.4,365.26]],"ltp":1.39,"tv":54632.36,"id":9028621}]}]}
{"op":"mcm","clk":"4226654941","pt":1631450538259,"mc":[{"id":"1.187552454","rc":[{"batl":[[1,1.39,1302.55]],"ltp":1.39,"tv":54632.36,"id":9028621}]}]}
{"op":"mcm","clk":"4226655272","pt":1631450539535,"mc":[{"id":"1.187552454","rc":[{"batl":[[0,3.85,16.75],[1,3.9,3.35]],"ltp":3.55,"tv":4988.02,"id":9345630},{"batb":[[0,1.37,333.9]],"ltp":1.39,"tv":54632.36,"id":9028621}]}]}
{"op":"mcm","clk":"4226655426","pt":1631450540246,"mc":[{"id":"1.187552454","rc":[{"batl":[[0,1.39,1302.55],[1,1.4,365.26],[2,1.41,409.03]],"ltp":1.39,"tv":54632.36,"id":9028621}]}]}
{"op":"mcm","clk":"4226655755","pt":1631450541573,"mc":[{"id":"1.187552454","rc":[{"batl":[[2,4.2,2]],"ltp":3.55,"tv":4988.02,"id":9345630},{"batb":[[2,1.35,805.3]],"ltp":1.39,"tv":54632.36,"id":9028621}]}]}
{"op":"mcm","clk":"4226656243","pt":1631450543472,"mc":[{"id":"1.187552454","rc":[{"batl":[[0,3.85,35.54]],"ltp":3.55,"tv":4988.02,"id":9345630}]}]}
{"op":"mcm","clk":"4226656486","pt":1631450544264,"mc":[{"id":"1.187552454","rc":[{"batl":[[2,4.1,2]],"ltp":3.55,"tv":4988.02,"id":9345630}]}]}
{"op":"mcm","clk":"4226657092","pt":1631450546439,"mc":[{"id":"1.187552454","rc":[{"batl":[[0,3.8,26.57],[1,3.85,35.54],[2,3.9,3.35]],"ltp":3.55,"tv":4988.02,"id":9345630},{"trd":[[1.37,812.41]],"batb":[[0,1.37,333.7]],"ltp":1.37,"tv":54632.75,"id":9028621}],"tv":59620.78}]}
{"op":"mcm","clk":"4226657199","pt":1631450546965,"mc":[{"id":"1.187552454","rc":[{"batl":[[0,3.85,35.98],[1,3.9,3.35],[2,4.1,2]],"ltp":3.55,"tv":4988.02,"id":9345630}]}]}
{"op":"mcm","clk":"4226657802","pt":1631450549542,"mc":[{"id":"1.187552454","rc":[{"batl":[[0,3.85,35.54]],"ltp":3.55,"tv":4988.02,"id":9345630}]}]}
{"op":"mcm","clk":"4226658182","pt":1631450551201,"mc":[{"id":"1.187552454","rc":[{"batl":[[0,1.39,1303.5],[1,1.4,353.86]],"ltp":1.37,"tv":54632.75,"id":9028621}]}]}
{"op":"mcm","clk":"4226658656","pt":1631450553410,"mc":[{"id":"1.187552454","rc":[{"trd":[[3.75,17.1]],"batl":[[0,3.8,26.13],[1,3.85,35.54],[2,3.9,3.35]],"ltp":3.75,"tv":4996.11,"id":9345630},{"trd":[[1.37,834.55]],"batb":[[0,1.37,311.56]],"ltp":1.37,"tv":54654.89,"id":9028621}],"tv":59651.0}]}
{"op":"mcm","clk":"4226659387","pt":1631450556559,"mc":[{"id":"1.187552454","rc":[{"trd":[[3.55,23.91],[3.6,42.29]],"ltp":3.55,"tv":4996.55,"id":9345630},{"trd":[[1.38,259.45],[1.39,350.64]],"batl":[[0,1.39,1271.22]],"ltp":1.39,"tv":54718.3,"id":9028621}],"tv":59714.85}]}
{"op":"mcm","clk":"4226659422","pt":1631450556667,"mc":[{"id":"1.187552454","rc":[{"trd":[[1.39,362.34]],"batl":[[0,1.39,1265.37]],"ltp":1.39,"tv":54730.0,"id":9028621}],"tv":59726.55}]}
{"op":"mcm","clk":"4226660078","pt":1631450559521,"mc":[{"id":"1.187552454","rc":[{"batb":[[2,3.35,2]],"ltp":3.55,"tv":4996.55,"id":9345630},{"batb":[[1,1.36,420.71],[2,1.35,54.62]],"ltp":1.39,"tv":54730.0,"id":9028621}]}]}
{"op":"mcm","clk":"4226660148","pt":1631450559831,"mc":[{"id":"1.187552454","rc":[{"batb":[[1,3,3],[2,2.96,2.38]],"batl":[[0,3.85,35.54],[1,4.1,2],[2,4.2,2]],"ltp":3.55,"tv":4996.55,"id":9345630},{"batb":[[0,1.37,7],[1,1.35,25.35],[2,1.33,44.53]],"batl":[[1,1.41,60],[2,1.51,25.7]],"ltp":1.39,"tv":54730.0,"id":9028621}]}]}
{"op":"mcm","clk":"4226660529","pt":1631450561462,"mc":[{"id":"1.187552454","rc":[{"batb":[[0,3,3],[1,2.96,2.38],[2,2.84,2.47]],"batl":[[0,4.1,2],[1,4.2,2],[2,4.3,3]],"ltp":3.55,"tv":4996.55,"id":9345630},{"batb":[[0,1.33,44.53],[1,1.32,43.64],[2,1.3,53.98]],"batl":[[1,1.51,25.7],[2,1.54,29.25]],"ltp":1.39,"tv":54730.0,"id":9028621}]}]}
{"op":"mcm","clk":"4226660683","pt":1631450562253,"mc":[{"id":"1.187552454","rc":[{"batb":[[1,2.74,2.79],[2,1.01,30]],"batl":[[0,4.3,3],[1,4.4,2],[2,990,0.01]],"ltp":3.55,"tv":4996.55,"id":9345630},{"batb":[[0,1.3,53.98],[1,1.26,6.16],[2,1.22,31.31]],"batl":[[0,1.54,5.2],[1,1.57,22.5],[2,3.8,27.47]],"ltp":1.39,"tv":54730.0,"id":9028621}]}]}
{"op":"mcm","clk":"4226660891","pt":1631450563216,"mc":[{"id":"1.187552454","rc":[{"batb":[[0,1.31,463.08],[1,1.3,585.5],[2,1.26,6.16]],"batl":[[0,1.5,467.44],[1,1.51,262.69],[2,1.54,5]],"ltp":1.39,"tv":54730.0,"id":9028621}]}]}
{"op":"mcm","clk":"4226661339","pt":1631450565519,"mc":[{"id":"1.187552454","rc":[{"batb":[[1,2.98,3],[2,2.96,2.13]],"ltp":3.55,"tv":4996.55,"id":9345630},{"batb":[[2,1.29,6]],"batl":[[0,1.5,473.44],[1,1.51,292.19]],"ltp":1.39,"tv":54730.0,"id":9028621}]}]}
{"op":"mcm","clk":"4226661413","pt":1631450565942,"mc":[{"id":"1.187552454","rc":[{"batb":[[0,1.31,470.08]],"ltp":1.39,"tv":54730.0,"id":9028621}]}]}
{"op":"mcm","clk":"4226661603","pt":1631450567011,"mc":[{"id":"1.187552454","rc":[{"batl":[[0,1.49,3.98],[1,1.5,473.24],[2,1.51,292.19]],"ltp":1.39,"tv":54730.0,"id":9028621}]}]}
{"op":"mcm","clk":"4226661887","pt":1631450568550,"mc":[{"id":"1.187552454","rc":[{"batl":[[0,4.1,2],[1,4.3,3],[2,4.4,2]],"ltp":3.55,"tv":4996.55,"id":9345630},{"batb":[[0,1.33,35.53],[1,1.32,10],[2,1.31,470.08]],"ltp":1.39,"tv":54730.0,"id":9028621}]}]}
{"op":"mcm","clk":"4226662033","pt":1631450569424,"mc":[{"id":"1.187552454","rc":[{"batl":[[0,4.3,3],[1,4.4,2],[2,990,0.01]],"ltp":3.55,"tv":4996.55,"id":9345630},{"trd":[[1.45,6361.15],[1.49,11.23]],"batb":[[0,1.32,10.35],[1,1.31,470.08],[2,1.3,585.5]],"batl":[[0,1.5,6],[1,1.51,29.5],[2,1.54,5]],"ltp":1.49,"tv":54737.96,"id":9028621}],"tv":59734.52}]}
{"op":"mcm","clk":"4226662089","pt":1631450569732,"mc":[{"id":"1.187552454","rc":[{"batb":[[2,2.74,2.79]],"ltp":3.55,"tv":4996.55,"id":9345630},{"batl":[[1,1.54,5],[2,3.8,27.47]],"ltp":1.49,"tv":54737.96,"id":9028621}]}]}
{"op":"mcm","clk":"4226662440","pt":1631450571422,"mc":[{"id":"1.187552454","rc":[{"trd":[[3.05,21.23]],"batb":[[0,3.9,490.39],[1,3.85,475.79],[2,3.8,475.96]],"ltp":3.05,"tv":4996.72,"id":9345630},{"trd":[[1.49,11.59]],"batb":[[0,1.32,10]],"batl":[[0,1.34,14.6],[1,1.5,6],[2,1.54,5]],"ltp":1.49,"tv":54738.32,"id":9028621}],"tv":59735.04}]}
{"op":"mcm","clk":"4226662639","pt":1631450572442,"mc":[{"id":"1.187552454","rc":[{"batb":[[0,3.9,62.78],[1,3.85,66.94],[2,3.8,60.94]],"batl":[[0,4.2,3],[1,4.3,3],[2,4.4,2]],"ltp":3.05,"tv":4996.72,"id":9345630},{"trd":[[1.33,687.07],[1.34,15168.95]],"batl":[[0,1.34,5028.13],[1,1.35,424.65],[2,1.36,19.87]],"ltp":1.34,"tv":54759.74,"id":9028621}],"tv":59756.46}]}
{"op":"mcm","clk":"4226662796","pt":1631450573466,"mc":[{"id":"1.187552454","rc":[{"batb":[[1,3.85,63.94],[2,3.8,82.36]],"batl":[[2,4.4,34.53]],"ltp":3.05,"tv":4996.72,"id":9345630},{"batl":[[0,1.34,466.05],[2,1.36,72.87]],"ltp":1.34,"tv":54759.74,"id":9028621}]}]}
{"op":"mcm","clk":"4226663100","pt":1631450575364,"mc":[{"id":"1.187552454","rc":[{"batl":[[0,4.1,2],[1,4.2,3],[2,4.3,3]],"ltp":3.05,"tv":4996.72,"id":9345630}]}]}
{"op":"mcm","clk":"4226663521","pt":1631450577534,"mc":[{"id":"1.187552454","rc":[{"batb":[[2,3.8,60.94]],"batl":[[0,4.3,3],[1,4.4,34.53],[2,990,0.01]],"ltp":3.05,"tv":4996.72,"id":9345630},{"batb":[[0,1.31,463.08],[1,1.3,585.5],[2,1.29,843.26]],"batl":[[2,1.36,12.87]],"ltp":1.34,"tv":54759.74,"id":9028621}]}]}
{"op":"mcm","clk":"4226663637","pt":1631450578182,"mc":[{"id":"1.187552454","rc":[{"trd":[[1.31,752.57]],"batb":[[0,1.31,457.08]],"ltp":1.31,"tv":54771.74,"id":9028621}],"tv":59768.46}]}
{"op":"mcm","clk":"4226663875","pt":1631450579440,"mc":[{"id":"1.187552454","rc":[{"batl":[[2,4.5,2]],"ltp":3.05,"tv":4996.72,"id":9345630},{"batb":[[2,1.29,888.07]],"ltp":1.31,"tv":54771.74,"id":9028621}]}]}
{"op":"mcm","clk":"4226663976","pt":1631450580040,"mc":[{"id":"1.187552454","rc":[{"batb":[[0,3.9,83.46],[2,3.8,62.94]],"batl":[[0,4.2,15],[1,4.3,3],[2,4.4,34.53]],"ltp":3.05,"tv":4996.72,"id":9345630},{"batb":[[0,1.31,512.91]],"batl":[[1,1.35,484.65]],"ltp":1.31,"tv":54771.74,"id":9028621}]}]}
{"op":"mcm","clk":"4226664690","pt":1631450584169,"mc":[{"id":"1.187552454","rc":[{"batl":[[0,1.34,431.72]],"ltp":1.31,"tv":54771.74,"id":9028621}]}]}
{"op":"mcm","clk":"4226665462","pt":1631450588246,"mc":[{"id":"1.187552454","rc":[{"batb":[[0,3.9,20.68],[1,3.8,2],[2,3.75,2]],"batl":[[0,4.3,3],[1,4.4,32.53],[2,4.8,2]],"ltp":3.05,"tv":4996.72,"id":9345630},{"batb":[[0,1.3,10.27],[1,1.29,27.85],[2,1.27,47.87]],"batl":[[0,1.35,60],[1,1.4,30.64],[2,1.44,26.58]],"ltp":1.31,"tv":54771.74,"id":9028621}]}]}
{"op":"mcm","clk":"4226665672","pt":1631450589462,"mc":[{"id":"1.187552454","rc":[{"batb":[[0,3.8,2],[1,3.75,2],[2,3.5,2]],"batl":[[1,4.8,2],[2,990,0.01]],"ltp":3.05,"tv":4996.72,"id":9345630},{"batb":[[1,1.27,47.87],[2,1.26,6.16]],"batl":[[0,1.4,30.64],[1,1.44,26.58],[2,1.5,6]],"ltp":1.31,"tv":54771.74,"id":9028621}]}]}
{"op":"mcm","clk":"4226665722","pt":1631450589779,"mc":[{"id":"1.187552454","rc":[{"batb":[[0,3.25,2.05],[1,3,3],[2,1.01,30]],"batl":[[0,4.8,2],[1,990,0.01],[2,990,0]],"ltp":3.05,"tv":4996.72,"id":9345630},{"batb":[[0,1.27,48.14],[1,1.26,6.16],[2,1.22,31.31]],"batl":[[0,1.44,26.58],[1,1.5,6],[2,3.8,27.47]],"ltp":1.31,"tv":54771.74,"id":9028621}]}]}
{"op":"mcm","clk":"4226666025","pt":1631450591591,"mc":[{"id":"1.187552454","rc":[{"batl":[[0,4.5,2],[1,4.8,2],[2,990,0.01]],"ltp":3.05,"tv":4996.72,"id":9345630},{"batb":[[0,1.29,44.08],[1,1.27,539.05],[2,1.26,639.35]],"batl":[[0,1.41,486.79],[1,1.42,337.01],[2,1.44,26.58]],"ltp":1.31,"tv":54771.74,"id":9028621}]}]}
{"op":"mcm","clk":"4226666073","pt":1631450591875,"mc":[{"id":"1.187552454","rc":[{"batl":[[0,4.8,2],[1,990,0.01],[2,990,0]],"ltp":3.05,"tv":4996.72,"id":9345630},{"batb":[[0,1.34,8.75]],"ltp":1.31,"tv":54771.74,"id":9028621}]}]}
{"op":"mcm","clk":"4226666324","pt":1631450593396,"mc":[{"id":"1.187552454","rc":[{"batb":[[0,3.25,5.05],[1,3.2,3],[2,3,3]],"batl":[[0,4.8,5]],"ltp":3.05,"tv":4996.72,"id":9345630},{"trd":[[1.34,15186.46]],"batb":[[0,1.28,5],[1,1.27,545.05],[2,1.26,647.35]],"batl":[[0,1.32,38.16],[1,1.41,486.79],[2,1.42,337.01]],"ltp":1.34,"tv":54789.24,"id":9028621}],"tv":59785.97}]}
{"op":"mcm","clk":"4226666453","pt":1631450594228,"mc":[{"id":"1.187552454","rc":[{"batb":[[0,3.4,3],[1,3.35,3],[2,3.25,5.05]],"ltp":3.05,"tv":4996.72,"id":9345630}]}]}
{"op":"mcm","clk":"4226666882","pt":1631450596590,"mc":[{"id":"1.187552454","rc":[{"batb":[[0,3.5,2.04],[1,3.4,3],[2,3.35,3]],"ltp":3.05,"tv":4996.72,"id":9345630},{"batl":[[1,1.4,35.34],[2,1.41,486.79]],"ltp":1.34,"tv":54789.24,"id":9028621}]}]}
{"op":"mcm","clk":"4226666927","pt":1631450596941,"mc":[{"id":"1.187552454","rc":[{"batb":[[0,3.4,3],[1,3.35,3],[2,3.25,5.05]],"ltp":3.05,"tv":4996.72,"id":9345630},{"batl":[[1,1.41,486.79],[2,1.42,337.01]],"ltp":1.34,"tv":54789.24,"id":9028621}]}]}
{"op":"mcm","clk":"4226667363","pt":1631450599307,"mc":[{"id":"1.187552454","rc":[{"batb":[[1,1.27,53.87],[2,1.26,14.16]],"ltp":1.34,"tv":54789.24,"id":9028621}]}]}
{"op":"mcm","clk":"4226667547","pt":1631450600493,"mc":[{"id":"1.187552454","rc":[{"batb":[[0,3.5,2],[1,3.25,5.05],[2,3.2,3]],"ltp":3.05,"tv":4996.72,"id":9345630},{"batl":[[1,1.4,29.14],[2,1.41,486.79]],"ltp":1.34,"tv":54789.24,"id":9028621}]}]}
{"op":"mcm","clk":"4226667567","pt":1631450600609,"mc":[{"id":"1.187552454","rc":[{"batb":[[0,3.25,5.05],[1,3.2,3],[2,3,3]],"ltp":3.05,"tv":4996.72,"id":9345630},{"batl":[[1,1.41,486.79],[2,1.42,337.01]],"ltp":1.34,"tv":54789.24,"id":9028621}]}]}
{"op":"mcm","clk":"4226667930","pt":1631450602542,"mc":[{"id":"1.187552454","rc":[{"trd":[[4.1,23.43]],"batb":[[0,3.35,75.76],[1,3.3,73.54],[2,3.25,78.59]],"batl":[[0,3.75,280.5],[1,3.8,272.25],[2,3.85,272.25]],"ltp":4.1,"tv":5005.26,"id":9345630},{"trd":[[1.32,554.63]],"batb":[[0,1.37,507.13],[1,1.36,423.65],[2,1.35,27.67]],"batl":[[0,1.4,11.4],[2,1.42,342.63]],"ltp":1.32,"tv":54839.03,"id":9028621}],"tv":59844.3}]}
{"op":"mcm","clk":"4226668107","pt":1631450603499,"mc":[{"id":"1.187552454","rc":[{"batb":[[0,3.45,24.48],[1,3.35,75.76],[2,3.3,73.54]],"ltp":4.1,"tv":5005.26,"id":9345630},{"batb":[[0,1.38,7],[1,1.37,507.13],[2,1.36,423.65]],"ltp":1.32,"tv":54839.03,"id":9028621}]}]}
{"op":"mcm","clk":"4226668238","pt":1631450604330,"mc":[{"id":"1.187552454","rc":[{"batb":[[2,3.3,98.79]],"ltp":4.1,"tv":5005.26,"id":9345630}]}]}
{"op":"mcm","clk":"4226668400","pt":1631450605418,"mc":[{"id":"1.187552454","rc":[{"trd":[[1.37,954.55],[1.38,273.45]],"batb":[[0,1.37,447.13],[1,1.36,423.65],[2,1.35,27.67]],"batl":[[1,1.41,546.79]],"ltp":1.37,"tv":54973.03,"id":9028621}],"tv":59978.3}]}
{"op":"mcm","clk":"4226668748","pt":1631450607442,"mc":[{"id":"1.187552454","rc":[{"batl":[[0,3.7,25],[1,3.75,280.5],[2,3.8,272.25]],"ltp":4.1,"tv":5005.26,"id":9345630},{"batb":[[0,1.38,35],[1,1.37,447.13],[2,1.36,423.65]],"ltp":1.37,"tv":54973.03,"id":9028621}]}]}
{"op":"mcm","clk":"4226668927","pt":1631450608347,"mc":[{"id":"1.187552454","rc":[{"batb":[[0,3.35,75.76],[1,3.3,73.54],[2,3.25,78.59]],"ltp":4.1,"tv":5005.26,"id":9345630},{"batl":[[0,1.4,11.57]],"ltp":1.37,"tv":54973.03,"id":9028621}]}]}
{"op":"mcm","clk":"4226669546","pt":1631450611440,"mc":[{"id":"1.187552454","rc":[{"batb":[[0,3.35,126.54]],"ltp":4.1,"tv":5005.26,"id":9345630}]}]}
{"op":"mcm","clk":"4226669952","pt":1631450613496,"mc":[{"id":"1.187552454","rc":[{"trd":[[1.37,954.75],[1.38,274.04]],"batb":[[0,1.37,447.03],[1,1.36,423.65],[2,1.35,53.02]],"ltp":1.37,"tv":54973.83,"id":9028621}],"tv":59979.09}]}
{"op":"mcm","clk":"4226670123","pt":1631450614321,"mc":[{"id":"1.187552454","rc":[{"trd":[[3.5,20.14]],"ltp":3.5,"tv":5006.84,"id":9345630},{"trd":[[1.4,128.76]],"batl":[[0,1.4,7.62]],"ltp":1.4,"tv":54977.79,"id":9028621}],"tv":59984.63}]}
{"op":"mcm","clk":"4226670329","pt":1631450615328,"mc":[{"id":"1.187552454","rc":[{"batb":[[0,3.65,9.59],[1,3.35,126.54],[2,3.3,73.54]],"ltp":3.5,"tv":5006.84,"id":9345630}]}]}
{"op":"mcm","clk":"4226670552","pt":1631450616412,"mc":[{"id":"1.187552454","rc":[{"batl":[[0,1.38,1.83],[1,1.4,1326.87],[2,1.41,546.79]],"ltp":1.4,"tv":54977.79,"id":9028621}]}]}
{"op":"mcm","clk":"4226670746","pt":1631450617539,"mc":[{"id":"1.187552454","rc":[{"trd":[[3.65,237.39]],"batb":[[0,3.35,126.54],[1,3.3,73.54],[2,3.25,78.59]],"ltp":3.65,"tv":5016.43,"id":9345630},{"trd":[[1.38,303.08]],"batl":[[0,1.4,1326.87],[1,1.41,546.79],[2,1.42,342.63]],"ltp":1.38,"tv":55006.82,"id":9028621}],"tv":60023.26}]}
{"op":"mcm","clk":"4226670914","pt":1631450618414,"mc":[{"id":"1.187552454","rc":[{"trd":[[1.37,1339.07]],"batb":[[0,1.37,254.87]],"batl":[[1,1.41,411.46],[2,1.42,5.62]],"ltp":1.37,"tv":55391.14,"id":9028621}],"tv":60407.58}]}
{"op":"mcm","clk":"4226671077","pt":1631450619336,"mc":[{"id":"1.187552454","rc":[{"batl":[[0,1.4,1319.43],[2,1.44,32.58]],"ltp":1.37,"tv":55391.14,"id":9028621}]}]}
{"op":"mcm","clk":"4226671422","pt":1631450621305,"mc":[{"id":"1.187552454","rc":[{"batb":[[0,1.37,401]],"batl":[[0,1.4,1559.68]],"ltp":1.37,"tv":55391.14,"id":9028621}]}]}
{"op":"mcm","clk":"4226671472","pt":1631450621644,"mc":[{"id":"1.187552454","rc":[{"batb":[[0,1.37,455.25]],"ltp":1.37,"tv":55391.14,"id":9028621}]}]}
{"op":"mcm","clk":"4226672048","pt":1631450625232,"mc":[{"id":"1.187552454","rc":[{"trd":[[1.37,1347.33],[1.4,135.98]],"batb":[[0,1.37,451.12]],"batl":[[0,1.4,1555.9]],"ltp":1.37,"tv":55406.62,"id":9028621}],"tv":60423.06}]}
{"op":"mcm","clk":"4226672516","pt":1631450627957,"mc":[{"id":"1.187552454","rc":[{"trd":[[3.5,27.94]],"ltp":3.5,"tv":5024.23,"id":9345630},{"trd":[[1.4,155.48]],"batl":[[0,1.4,1536.4]],"ltp":1.4,"tv":55426.12,"id":9028621}],"tv":60450.36}]}
{"op":"mcm","clk":"4226673210","pt":1631450632248,"mc":[{"id":"1.187552454","rc":[{"batl":[[0,1.4,240.25]],"ltp":1.4,"tv":55426.12,"id":9028621}]}]}
{"op":"mcm","clk":"4226673387","pt":1631450633356,"mc":[{"id":"1.187552454","rc":[{"batb":[[0,3.35,101.29]],"ltp":3.5,"tv":5024.23,"id":9345630}]}]}
{"op":"mcm","clk":"4226673768","pt":1631450635481,"mc":[{"id":"1.187552454","rc":[{"batb":[[0,3.35,104.29],[1,3.3,75.54]],"ltp":3.5,"tv":5024.23,"id":9345630}]}]}
{"op":"mcm","clk":"4226673930","pt":1631450636511,"mc":[{"id":"1.187552454","rc":[{"batb":[[0,3.4,25.25],[1,3.35,104.29],[2,3.3,75.54]],"ltp":3.5,"tv":5024.23,"id":9345630}]}]}
{"op":"mcm","clk":"4226674131","pt":1631450637478,"mc":[{"id":"1.187552454","rc":[{"batb":[[0,3.35,25.53],[1,2.96,2.38],[2,2.74,2.52]],"batl":[[0,3.85,35.54],[1,4.1,2.1],[2,4.2,2]],"ltp":3.5,"tv":5024.23,"id":9345630},{"batb":[[0,1.37,396.87],[2,1.35,25.35]],"batl":[[2,1.51,25.5]],"ltp":1.4,"tv":55426.12,"id":9028621}]}]}
{"op":"mcm","clk":"4226674315","pt":1631450638407,"mc":[{"id":"1.187552454","rc":[{"batb":[[0,2.96,2.38],[1,2.74,2.52],[2,2.72,2.84]],"batl":[[0,4.1,2.1],[1,4.2,2],[2,4.3,2]],"ltp":3.5,"tv":5024.23,"id":9345630},{"batb":[[0,1.33,35.53],[1,1.32,38.14],[2,1.31,36.79]],"batl":[[0,1.51,25.5],[1,1.57,23.5],[2,1.58,22.75]],"ltp":1.4,"tv":55426.12,"id":9028621}]}]}
{"op":"mcm","clk":"4226674403","pt":1631450638895,"mc":[{"id":"1.187552454","rc":[{"batb":[[0,2.74,2.52],[1,1.01,30],[2,2.72,0]],"batl":[[0,4.4,2.1],[1,990,0.01],[2,4.3,0]],"ltp":3.5,"tv":5024.23,"id":9345630},{"batb":[[0,1.3,42.68],[1,1.26,6.16],[2,1.22,31.31]],"batl":[[0,1.57,23.5],[1,3.8,27.47],[2,8.8,7.23]],"ltp":1.4,"tv":55426.12,"id":9028621}]}]}
{"op":"mcm","clk":"4226674918","pt":1631450641401,"mc":[{"id":"1.187552454","rc":[{"batb":[[0,1.31,597.91],[1,1.3,578.21],[2,1.26,6.16]],"batl":[[0,1.5,369.59],[1,1.51,264.13],[2,1.57,23.5]],"ltp":1.4,"tv":55426.12,"id":9028621}]}]}
{"op":"mcm","clk":"4226675071","pt":1631450642208,"mc":[{"id":"1.187552454","rc":[{"batb":[[0,2.96,5.13],[1,2.94,4],[2,2.74,6.52]],"batl":[[0,4.4,4.1]],"ltp":3.5,"tv":5024.23,"id":9345630},{"batb":[[1,1.3,586.21],[2,1.29,8]],"batl":[[0,1.5,369.8],[1,1.51,293.63],[2,1.52,6]],"ltp":1.4,"tv":55426.12,"id":9028621}]}]}
{"op":"mcm","clk":"4226675454","pt":1631450644191,"mc":[{"id":"1.187552454","rc":[{"batb":[[0,3,3],[1,2.98,4],[2,2.96,5.13]],"batl":[[0,4.3,3.1],[1,4.4,4],[2,990,0.01]],"ltp":3.5,"tv":5024.23,"id":9345630},{"batb":[[0,1.31,607.91]],"batl":[[0,1.5,375.8]],"ltp":1.4,"tv":55426.12,"id":9028621}]}]}
{"op":"mcm","clk":"4226675639","pt":1631450645413,"mc":[{"id":"1.187552454","rc":[{"batl":[[0,4.1,2.1],[1,4.3,3],[2,4.4,4]],"ltp":3.5,"tv":5024.23,"id":9345630},{"batb":[[0,1.33,42.53],[1,1.31,607.91],[2,1.3,586.21]],"ltp":1.4,"tv":55426.12,"id":9028621}]}]}
{"op":"mcm","clk":"4226675702","pt":1631450645790,"mc":[{"id":"1.187552454","rc":[{"batl":[[0,4.3,3.1],[1,4.4,4],[2,990,0.01]],"ltp":3.5,"tv":5024.23,"id":9345630},{"batb":[[0,1.31,607.91],[1,1.3,586.21],[2,1.29,8]],"ltp":1.4,"tv":55426.12,"id":9028621}]}]}
{"op":"mcm","clk":"4226675931","pt":1631450646826,"mc":[{"id":"1.187552454","rc":[{"trd":[[4,16.17]],"batl":[[0,4.3,3]],"ltp":4.0,"tv":5024.33,"id":9345630},{"trd":[[1.31,766.27],[1.33,687.37]],"batb":[[0,1.31,601.06]],"ltp":1.31,"tv":55440.12,"id":9028621}],"tv":60464.45}]}
{"op":"mcm","clk":"4226676953","pt":1631450652594,"mc":[{"id":"1.187552454","rc":[{"batl":[[0,4.1,2],[1,4.3,3],[2,4.4,4]],"ltp":4.0,"tv":5024.33,"id":9345630},{"batb":[[0,1.33,43.53],[1,1.31,601.06],[2,1.3,586.21]],"ltp":1.31,"tv":55440.12,"id":9028621}]}]}
{"op":"mcm","clk":"4226677008","pt":1631450652923,"mc":[{"id":"1.187552454","rc":[{"batl":[[0,4.3,3],[1,4.4,4],[2,990,0.01]],"ltp":4.0,"tv":5024.33,"id":9345630},{"batb":[[0,1.31,601.06],[1,1.3,586.21],[2,1.29,8]],"batl":[[0,1.5,375.59]],"ltp":1.31,"tv":55440.12,"id":9028621}]}]}
{"op":"mcm","clk":"4226677620","pt":1631450656524,"mc":[{"id":"1.187552454","rc":[{"batb":[[1,2.96,2.13],[2,2.74,2.52]],"batl":[[1,4.4,2]],"ltp":4.0,"tv":5024.33,"id":9345630},{"batb":[[1,1.3,578.21],[2,1.26,6.16]],"batl":[[0,1.5,6],[1,1.51,22.5],[2,3.8,27.47]],"ltp":1.31,"tv":55440.12,"id":9028621}]}]}
{"op":"mcm","clk":"4226677683","pt":1631450656833,"mc":[{"id":"1.187552454","rc":[{"batb":[[1,2.74,2.52],[2,1.01,30]],"ltp":4.0,"tv":5024.33,"id":9345630},{"batl":[[1,3.8,27.47],[2,8.8,7.23]],"ltp":1.31,"tv":55440.12,"id":9028621}]}]}
{"op":"mcm","clk":"4226677986","pt":1631450658524,"mc":[{"id":"1.187552454","rc":[{"batb":[[0,3.9,490.39],[1,3.85,475.96],[2,3.8,475.96]],"ltp":4.0,"tv":5024.33,"id":9345630},{"trd":[[1.31,783.35]],"batb":[[0,1.31,592.52]],"batl":[[0,1.34,12.68],[1,1.5,6],[2,3.8,27.47]],"ltp":1.31,"tv":55457.2,"id":9028621}],"tv":60481.53}]}
{"op":"mcm","clk":"4226678126","pt":1631450659518,"mc":[{"id":"1.187552454","rc":[{"batb":[[0,3.9,62.78],[1,3.85,60.94],[2,3.8,60.94]],"ltp":4.0,"tv":5024.33,"id":9345630},{"batb":[[2,1.29,815.41]],"batl":[[0,1.34,4293.84],[1,1.35,439.69],[2,1.37,5.82]],"ltp":1.31,"tv":55457.2,"id":9028621}]}]}
{"op":"mcm","clk":"4226678302","pt":1631450660420,"mc":[{"id":"1.187552454","rc":[{"batb":[[0,3.9,65.78]],"batl":[[1,4.4,34.53]],"ltp":4.0,"tv":5024.33,"id":9345630},{"batb":[[1,1.3,585.21],[2,1.29,843.26]],"batl":[[0,1.34,333.07],[2,1.36,60]],"ltp":1.31,"tv":55457.2,"id":9028621}]}]}
{"op":"mcm","clk":"4226678396","pt":1631450661026,"mc":[{"id":"1.187552454","rc":[{"batl":[[0,4.2,15],[1,4.3,3],[2,4.4,34.53]],"ltp":4.0,"tv":5024.33,"id":9345630},{"batb":[[0,1.32,39.14],[1,1.31,592.52],[2,1.3,585.21]],"ltp":1.31,"tv":55457.2,"id":9028621}]}]}
{"op":"mcm","clk":"4226678965","pt":1631450664462,"mc":[{"id":"1.187552454","rc":[{"batl":[[2,1.37,12.82]],"ltp":1.31,"tv":55457.2,"id":9028621}]}]}
{"op":"mcm","clk":"4226679360","pt":1631450667029,"mc":[{"id":"1.187552454","rc":[{"batb":[[1,3.85,81.99]],"ltp":4.0,"tv":5024.33,"id":9345630},{"batl":[[1,1.35,499.69]],"ltp":1.31,"tv":55457.2,"id":9028621}]}]}
{"op":"mcm","clk":"4226680265","pt":1631450671353,"mc":[{"id":"1.187552454","rc":[{"batb":[[2,1.3,578.21]],"batl":[[0,1.34,301.38]],"ltp":1.31,"tv":55457.2,"id":9028621}]}]}
{"op":"mcm","clk":"4226680655","pt":1631450673352,"mc":[{"id":"1.187552454","rc":[{"trd":[[3.9,78.89]],"batb":[[0,3.9,40.22]],"ltp":3.9,"tv":5075.45,"id":9345630}],"tv":60532.65}]}
{"op":"mcm","clk":"4226680912","pt":1631450674569,"mc":[{"id":"1.187552454","rc":[{"batb":[[2,1.3,588.21]],"ltp":1.31,"tv":55457.2,"id":9028621}]}]}
{"op":"mcm","clk":"4226681263","pt":1631450676463,"mc":[{"id":"1.187552454","rc":[{"trd":[[1.34,15200.88]],"batb":[[0,1.32,14.49]],"batl":[[0,1.34,294.17],[1,1.35,487.87],[2,1.37,7]],"ltp":1.34,"tv":55471.62,"id":9028621}],"tv":60547.07}]}
{"op":"mcm","clk":"4226681447","pt":1631450677447,"mc":[{"id":"1.187552454","rc":[{"batb":[[1,1.31,582.52]],"ltp":1.34,"tv":55471.62,"id":9028621}]}]}
{"op":"mcm","clk":"4226681824","pt":1631450679558,"mc":[{"id":"1.187552454","rc":[{"batb":[[0,3.9,3],[1,3.85,21.05],[2,3.25,2.01]],"batl":[[0,4.4,32.53],[1,4.8,2],[2,990,0.01]],"ltp":3.9,"tv":5075.45,"id":9345630},{"batb":[[0,1.29,27.85],[1,1.27,51.87],[2,1.26,6.16]],"batl":[[0,1.35,60],[1,1.37,7],[2,1.44,26.58]],"ltp":1.34,"tv":55471.62,"id":9028621}]}]}
{"op":"mcm","clk":"4226681976","pt":1631450680482,"mc":[{"id":"1.187552454","rc":[{"batb":[[0,3.25,2.01],[1,3.05,3],[2,1.01,30]],"batl":[[0,4.8,2],[1,990,0.01],[2,990,0]],"ltp":3.9,"tv":5075.45,"id":9345630},{"batb":[[0,1.27,51.87],[1,1.26,6.16],[2,1.21,38.96]],"batl":[[0,1.44,27.24],[1,1.49,1.65],[2,1.5,6]],"ltp":1.34,"tv":55471.62,"id":9028621}]}]}
{"op":"mcm","clk":"4226682139","pt":1631450681257,"mc":[{"id":"1.187552454","rc":[{"trd":[[1.32,555.48]],"batb":[[0,1.34,7.93],[1,1.27,51.87],[2,1.26,6.16]],"batl":[[0,1.44,26.58]],"ltp":1.32,"tv":55472.47,"id":9028621}],"tv":60547.92}]}
{"op":"mcm","clk":"4226682407","pt":1631450682556,"mc":[{"id":"1.187552454","rc":[{"batb":[[0,3.5,2.04],[1,3.25,2.01],[2,3.05,3]],"batl":[[0,4.5,2],[1,4.8,2],[2,990,0.01]],"ltp":3.9,"tv":5075.45,"id":9345630},{"batb":[[1,1.29,52.81],[2,1.28,7]],"batl":[[0,1.4,1266.85],[1,1.41,389.75],[2,1.42,339.29]],"ltp":1.32,"tv":55472.47,"id":9028621}]}]}
{"op":"mcm","clk":"4226682577","pt":1631450683368,"mc":[{"id":"1.187552454","rc":[{"batl":[[0,4.8,2],[1,990,0.01],[2,990,0]],"ltp":3.9,"tv":5075.45,"id":9345630},{"batb":[[0,1.29,8],[1,1.28,7],[2,1.27,650.32]],"ltp":1.32,"tv":55472.47,"id":9028621}]}]}
{"op":"mcm","clk":"4226682701","pt":1631450684067,"mc":[{"id":"1.187552454","rc":[{"batb":[[1,3.25,4.01],[2,3.2,3]],"batl":[[0,4.5,2],[1,4.8,5],[2,990,0.01]],"ltp":3.9,"tv":5075.45,"id":9345630},{"batb":[[2,1.27,660.32]],"ltp":1.32,"tv":55472.47,"id":9028621}]}]}
{"op":"mcm","clk":"4226683520","pt":1631450688793,"mc":[{"id":"1.187552454","rc":[{"trd":[[1.4,170.67]],"batl":[[0,1.4,1259.25]],"ltp":1.4,"tv":55487.65,"id":9028621}],"tv":60563.11}]}
{"op":"mcm","clk":"4226684185","pt":1631450693487,"mc":[{"id":"1.187552454","rc":[{"trd":[[4.5,26.48]],"batl":[[0,4.8,5],[1,990,0.01],[2,990,0]],"ltp":4.5,"tv":5078.06,"id":9345630},{"trd":[[1.28,649.58],[1.29,1941.72]],"batb":[[0,1.27,660.32],[1,1.26,653.14],[2,1.21,38.96]],"ltp":1.28,"tv":55612.46,"id":9028621}],"tv":60690.53}]}
{"op":"mcm","clk":"4226684366","pt":1631450694665,"mc":[{"id":"1.187552454","rc":[{"batb":[[0,1.3,20.82],[1,1.27,660.32],[2,1.26,653.14]],"ltp":1.28,"tv":55612.46,"id":9028621}]}]}
{"op":"mcm","clk":"4226684668","pt":1631450696596,"mc":[{"id":"1.187552454","rc":[{"batb":[[1,1.29,49.81],[2,1.27,660.32]],"ltp":1.28,"tv":55612.46,"id":9028621}]}]}
{"op":"mcm","clk":"4226684713","pt":1631450696882,"mc":[{"id":"1.187552454","rc":[{"batb":[[2,1.01,30]],"ltp":4.5,"tv":5078.06,"id":9345630},{"batb":[[1,1.28,8],[2,1.27,650.32]],"ltp":1.28,"tv":55612.46,"id":9028621}]}]}
{"op":"mcm","clk":"4226684984","pt":1631450698412,"mc":[{"id":"1.187552454","rc":[{"trd":[[1.3,621.86]],"batb":[[0,1.28,8],[1,1.27,650.32],[2,1.26,644.14]],"batl":[[0,1.3,4586.7],[1,1.31,1459.92],[2,1.32,1416.98]],"ltp":1.3,"tv":55654.1,"id":9028621}],"tv":60732.17}]}
{"op":"mcm","clk":"4226685156","pt":1631450699388,"mc":[{"id":"1.187552454","rc":[{"batb":[[0,3.25,4.01],[1,1.01,30],[2,1.01,0]],"ltp":4.5,"tv":5078.06,"id":9345630},{"batl":[[0,1.3,8.54],[1,1.31,73],[2,1.32,70.85]],"ltp":1.3,"tv":55654.1,"id":9028621}]}]}
{"op":"mcm","clk":"4226685574","pt":1631450701598,"mc":[{"id":"1.187552454","rc":[{"batl":[[0,4.4,2],[1,4.8,5],[2,5,210.37]],"ltp":4.5,"tv":5078.06,"id":9345630},{"trd":[[1.3,625.08]],"batb":[[0,1.27,660.32],[1,1.26,644.14],[2,1.21,38.96]],"batl":[[0,1.3,529.81],[1,1.31,688.3],[2,1.32,178.05]],"ltp":1.3,"tv":55657.32,"id":9028621}],"tv":60735.38}]}
{"op":"mcm","clk":"4226685749","pt":1631450702502,"mc":[{"id":"1.187552454","rc":[{"trd":[[4.7,52.6]],"batb":[[0,4.2,18.75],[1,3.7,20.05],[2,3.35,726.15]],"batl":[[0,4.7,12.19],[2,5,240.37]],"ltp":4.7,"tv":5086.06,"id":9345630},{"trd":[[1.27,2690.9],[1.3,629.42]],"batb":[[0,1.27,634.32],[2,1.25,30]],"batl":[[0,1.3,527.65],[1,1.31,748.3]],"ltp":1.27,"tv":55693.65,"id":9028621}],"tv":60779.72}]}
{"op":"mcm","clk":"4226685839","pt":1631450702982,"mc":[{"id":"1.187552454","rc":[{"batb":[[1,3.35,726.15],[2,3.25,4.01]],"ltp":4.7,"tv":5086.06,"id":9345630},{"trd":[[1.3,633.75]],"batl":[[0,1.3,525.48]],"ltp":1.3,"tv":55697.99,"id":9028621}],"tv":60784.06}]}
{"op":"mcm","clk":"4226686150","pt":1631450704514,"mc":[{"id":"1.187552454","rc":[{"batl":[[1,1.31,688.3]],"ltp":1.3,"tv":55697.99,"id":9028621}]}]}
{"op":"mcm","clk":"4226686191","pt":1631450704678,"mc":[{"id":"1.187552454","rc":[{"batb":[[0,1.27,684.07]],"ltp":1.3,"tv":55697.99,"id":9028621}]}]}
{"op":"mcm","clk":"4226686707","pt":1631450707193,"mc":[{"id":"1.187552454","rc":[{"trd":[[4.3,41.3]],"batb":[[1,3.25,4.01],[2,1.01,30]],"ltp":4.3,"tv":5094.11,"id":9345630},{"trd":[[1.3,660.38]],"batl":[[0,1.3,498.85]],"ltp":1.3,"tv":55724.62,"id":9028621}],"tv":60818.74}]}
{"op":"mcm","clk":"4226686946","pt":1631450708501,"mc":[{"id":"1.187552454","rc":[{"batb":[[1,3.9,2],[2,3.7,2]],"ltp":4.3,"tv":5094.11,"id":9345630},{"trd":[[1.3,664.28]],"batb":[[0,1.28,24.6],[1,1.27,684.07],[2,1.26,644.14]],"batl":[[0,1.3,556.9]],"ltp":1.3,"tv":55728.52,"id":9028621}],"tv":60822.64}]}
{"op":"mcm","clk":"4226687128","pt":1631450709491,"mc":[{"id":"1.187552454","rc":[{"trd":[[4.3,43.25]],"batb":[[0,4.2,36.02]],"ltp":4.3,"tv":5096.06,"id":9345630},{"trd":[[1.3,670.73]],"batl":[[0,1.3,550.45]],"ltp":1.3,"tv":55734.97,"id":9028621}],"tv":60831.04}]}
{"op":"mcm","clk":"4226687286","pt":1631450710406,"mc":[{"id":"1.187552454","rc":[{"batb":[[0,4.2,26.15]],"ltp":4.3,"tv":5096.06,"id":9345630},{"batb":[[0,1.28,488.54]],"ltp":1.3,"tv":55734.97,"id":9028621}]}]}
{"op":"mcm","clk":"4226687691","pt":1631450712516,"mc":[{"id":"1.187552454","rc":[{"trd":[[4.3,63.31]],"ltp":4.3,"tv":5116.12,"id":9345630},{"trd":[[1.3,737.08]],"batl":[[0,1.3,484.1]],"ltp":1.3,"tv":55801.32,"id":9028621}],"tv":60917.45}]}
{"op":"mcm","clk":"4226688009","pt":1631450714112,"mc":[{"id":"1.187552454","rc":[{"batl":[[0,1.29,1233.74],[1,1.3,484.1],[2,1.31,688.3]],"ltp":1.3,"tv":55801.32,"id":9028621}]}]}
{"op":"mcm","clk":"4226688442","pt":1631450716415,"mc":[{"id":"1.187552454","rc":[{"trd":[[1.29,1953.21]],"batb":[[1,1.27,726.63]],"batl":[[0,1.29,1227.99],[1,1.3,541.32]],"ltp":1.29,"tv":55812.8,"id":9028621}],"tv":60928.93}]}
{"op":"mcm","clk":"4226688611","pt":1631450717403,"mc":[{"id":"1.187552454","rc":[{"trd":[[1.29,1970.29]],"batb":[[0,1.28,463.94]],"batl":[[0,1.29,1219.45]],"ltp":1.29,"tv":55829.88,"id":9028621}],"tv":60946.01}]}
{"op":"mcm","clk":"4226688769","pt":1631450718294,"mc":[{"id":"1.187552454","rc":[{"trd":[[4.4,65.58]],"ltp":4.4,"tv":5138.12,"id":9345630},{"trd":[[1.29,2079.06]],"batl":[[0,1.29,1127.55]],"ltp":1.29,"tv":55938.66,"id":9028621}],"tv":61076.79}]}
{"op":"mcm","clk":"4226688907","pt":1631450719020,"mc":[{"id":"1.187552454","rc":[{"trd":[[1.29,2082.9]],"batl":[[0,1.29,1125.63]],"ltp":1.29,"tv":55942.49,"id":9028621}],"tv":61080.62}]}
{"op":"mcm","clk":"4226689069","pt":1631450719925,"mc":[{"id":"1.187552454","rc":[{"trd":[[1.28,658.39]],"batb":[[0,1.28,459.54]],"ltp":1.28,"tv":55951.3,"id":9028621}],"tv":61089.42}]}
{"op":"mcm","clk":"4226689381","pt":1631450721715,"mc":[{"id":"1.187552454","rc":[{"batl":[[0,1.29,1117.07]],"ltp":1.28,"tv":55951.3,"id":9028621}]}]}
{"op":"mcm","clk":"4226689631","pt":1631450723428,"mc":[{"id":"1.187552454","rc":[{"trd":[[4.4,70.66]],"ltp":4.4,"tv":5143.19,"id":9345630},{"trd":[[1.29,2177.44]],"batl":[[0,1.29,1061.15]],"ltp":1.29,"tv":56045.84,"id":9028621}],"tv":61189.04}]}
{"op":"mcm","clk":"4226690213","pt":1631450726956,"mc":[{"id":"1.187552454","rc":[{"trd":[[1.29,2194.55]],"batl":[[0,1.29,832.72]],"ltp":1.29,"tv":56062.95,"id":9028621}],"tv":61206.15}]}
{"op":"mcm","clk":"4226690613","pt":1631450729450,"mc":[{"id":"1.187552454","rc":[{"trd":[[1.29,2196.89]],"batl":[[0,1.29,821.52]],"ltp":1.29,"tv":56065.29,"id":9028621}],"tv":61208.49}]}
{"op":"mcm","clk":"4226690858","pt":1631450731053,"mc":[{"id":"1.187552454","rc":[{"trd":[[4.4,72.61]],"ltp":4.4,"tv":5145.14,"id":9345630},{"trd":[[1.29,2203.54]],"batl":[[0,1.29,814.88]],"ltp":1.29,"tv":56071.94,"id":9028621}],"tv":61217.09}]}
{"op":"mcm","clk":"4226691015","pt":1631450732052,"mc":[{"id":"1.187552454","rc":[{"trd":[[1.28,678.59]],"batb":[[0,1.28,449.44]],"ltp":1.28,"tv":56092.14,"id":9028621}],"tv":61237.29}]}
{"op":"mcm","clk":"4226691484","pt":1631450735279,"mc":[{"id":"1.187552454","rc":[{"trd":[[1.29,2203.96]],"batl":[[0,1.29,814.67]],"ltp":1.29,"tv":56092.56,"id":9028621}],"tv":61237.71}]}
{"op":"mcm","clk":"4226691550","pt":1631450735659,"mc":[{"id":"1.187552454","rc":[{"trd":[[1.29,2204.75]],"batl":[[0,1.29,814.27]],"ltp":1.29,"tv":56093.35,"id":9028621}],"tv":61238.5}]}
{"op":"mcm","clk":"4226692017","pt":1631450738573,"mc":[{"id":"1.187552454","rc":[{"batb":[[1,1.27,85.62],[2,1.26,6.16]],"batl":[[1,1.3,60],[2,1.31,183.45]],"ltp":1.29,"tv":56093.35,"id":9028621}]}]}
{"op":"mcm","clk":"4226692166","pt":1631450739575,"mc":[{"id":"1.187552454","rc":[{"trd":[[4.6,94.6]],"ltp":4.6,"tv":5230.55,"id":9345630},{"trd":[[1.28,986.85]],"batb":[[0,1.28,141.85]],"ltp":1.28,"tv":56401.61,"id":9028621}],"tv":61632.16}]}
{"op":"mcm","clk":"4226692482","pt":1631450741475,"mc":[{"id":"1.187552454","rc":[{"batl":[[2,5,30]],"ltp":4.6,"tv":5230.55,"id":9345630},{"batl":[[2,1.34,40.25]],"ltp":1.28,"tv":56401.61,"id":9028621}]}]}
{"op":"mcm","clk":"4226692614","pt":1631450742266,"mc":[{"id":"1.187552454","rc":[{"batb":[[0,4.2,18.75]],"batl":[[0,5,30],[1,5.4,2],[2,5.8,2]],"ltp":4.6,"tv":5230.55,"id":9345630},{"batb":[[1,1.26,6.16],[2,1.25,30]],"batl":[[2,1.34,458.06]],"ltp":1.28,"tv":56401.61,"id":9028621}]}]}
{"op":"mcm","clk":"4226692818","pt":1631450743588,"mc":[{"id":"1.187552454","rc":[{"batb":[[0,3.9,2],[1,3.7,2],[2,3.25,2]],"batl":[[0,5.4,2],[1,5.8,2],[2,6,2]],"ltp":4.6,"tv":5230.55,"id":9345630},{"batb":[[2,1.23,450.31]],"batl":[[0,1.34,458.06],[1,1.35,425.53],[2,1.37,33.5]],"ltp":1.28,"tv":56401.61,"id":9028621}]}]}
{"op":"mcm","clk":"4226693017","pt":1631450744786,"mc":[{"id":"1.187552454","rc":[{"batb":[[0,1.26,6.16],[1,1.23,450.31],[2,1.22,772.29]],"ltp":1.28,"tv":56401.61,"id":9028621}]}]}
{"op":"mcm","clk":"4226693401","pt":1631450747201,"mc":[{"id":"1.187552454","rc":[{"batb":[[0,3.9,4],[1,3.85,3],[2,3.7,2]],"ltp":4.6,"tv":5230.55,"id":9345630},{"batl":[[0,1.34,466.06]],"ltp":1.28,"tv":56401.61,"id":9028621}]}]}
{"op":"mcm","clk":"4226693518","pt":1631450748006,"mc":[{"id":"1.187552454","rc":[{"batl":[[0,5.4,4]],"ltp":4.6,"tv":5230.55,"id":9345630}]}]}
{"op":"mcm","clk":"4226693930","pt":1631450750592,"mc":[{"id":"1.187552454","rc":[{"batl":[[0,5.4,2],[1,6,2],[2,990,0.01]],"ltp":4.6,"tv":5230.55,"id":9345630},{"batb":[[1,1.21,6.16],[2,1.2,71.02]],"batl":[[2,1.44,8.21]],"ltp":1.28,"tv":56401.61,"id":9028621}]}]}
{"op":"mcm","clk":"4226694221","pt":1631450752590,"mc":[{"id":"1.187552454","rc":[{"trd":[[3.9,91.43]],"batb":[[0,3.85,3],[1,3.7,2],[2,3.25,2]],"batl":[[0,4.2,556.13],[1,4.4,534.09],[2,5.4,2]],"ltp":3.9,"tv":5243.09,"id":9345630},{"trd":[[1.34,15215.44]],"batl":[[0,1.34,452.17]],"ltp":1.34,"tv":56416.16,"id":9028621}],"tv":61659.26}]}
{"op":"mcm","clk":"4226694336","pt":1631450753365,"mc":[{"id":"1.187552454","rc":[{"batb":[[0,3.7,2],[1,3.25,2],[2,1.01,30]],"batl":[[0,4.4,137.52],[1,5.4,2],[2,6,2]],"ltp":3.9,"tv":5243.09,"id":9345630},{"batb":[[0,1.31,468.02],[1,1.3,532.58],[2,1.29,16]],"batl":[[0,1.34,456.08],[2,1.36,5.87]],"ltp":1.34,"tv":56416.16,"id":9028621}]}]}
{"op":"mcm","clk":"4226694501","pt":1631450754404,"mc":[{"id":"1.187552454","rc":[{"batb":[[0,3.9,20.68],[1,3.7,2],[2,3.25,2]],"batl":[[0,4.4,135.52],[1,4.6,31.62],[2,4.8,10]],"ltp":3.9,"tv":5243.09,"id":9345630},{"batb":[[2,1.29,8]],"batl":[[1,1.35,485.53]],"ltp":1.34,"tv":56416.16,"id":9028621}]}]}
{"op":"mcm","clk":"4226694555","pt":1631450754714,"mc":[{"id":"1.187552454","rc":[{"batl":[[2,5.4,2]],"ltp":3.9,"tv":5243.09,"id":9345630}]}]}
{"op":"mcm","clk":"4226694871","pt":1631450756589,"mc":[{"id":"1.187552454","rc":[{"batb":[[1,3.85,15],[2,3.8,2]],"batl":[[0,4.3,2],[1,4.4,135.52],[2,4.6,31.62]],"ltp":3.9,"tv":5243.09,"id":9345630},{"batb":[[1,1.3,541.58],[2,1.29,15]],"ltp":1.34,"tv":56416.16,"id":9028621}]}]}
{"op":"mcm","clk":"4226694899","pt":1631450756747,"mc":[{"id":"1.187552454","rc":[{"batl":[[0,1.34,429.72]],"ltp":1.34,"tv":56416.16,"id":9028621}]}]}
{"op":"mcm","clk":"4226695192","pt":1631450758581,"mc":[{"id":"1.187552454","rc":[{"batl":[[2,5.3,2]],"ltp":3.9,"tv":5243.09,"id":9345630},{"batb":[[0,1.31,518]],"ltp":1.34,"tv":56416.16,"id":9028621}]}]}
{"op":"mcm","clk":"4226695352","pt":1631450759593,"mc":[{"id":"1.187552454","rc":[{"batb":[[0,1.32,21.53],[1,1.31,518],[2,1.3,541.58]],"ltp":1.34,"tv":56416.16,"id":9028621}]}]}
{"op":"mcm","clk":"4226695396","pt":1631450759770,"mc":[{"id":"1.187552454","rc":[{"batl":[[2,4.5,2]],"ltp":3.9,"tv":5243.09,"id":9345630},{"batl":[[2,1.36,39.94]],"ltp":1.34,"tv":56416.16,"id":9028621}]}]}
{"op":"mcm","clk":"4226695678","pt":1631450761480,"mc":[{"id":"1.187552454","rc":[{"batl":[[0,4.2,10],[1,4.3,2],[2,4.4,135.52]],"ltp":3.9,"tv":5243.09,"id":9345630}]}]}
{"op":"mcm","clk":"4226695994","pt":1631450763403,"mc":[{"id":"1.187552454","rc":[{"trd":[[4.2,71.3]],"batl":[[0,4.2,2.25]],"ltp":4.2,"tv":5258.58,"id":9345630}],"tv":61674.75}]}
{"op":"mcm","clk":"4226696130","pt":1631450764211,"mc":[{"id":"1.187552454","rc":[{"trd":[[1.34,15215.55]],"batb":[[0,1.33,35],[1,1.32,21.53],[2,1.31,518]],"batl":[[0,1.34,429.66]],"ltp":1.34,"tv":56416.28,"id":9028621}],"tv":61674.87}]}
{"op":"mcm","clk":"4226696421","pt":1631450765791,"mc":[{"id":"1.187552454","rc":[{"trd":[[1.33,729.01]],"batb":[[0,1.33,14.18]],"ltp":1.33,"tv":56457.92,"id":9028621}],"tv":61716.51}]}
{"op":"mcm","clk":"4226696856","pt":1631450768312,"mc":[{"id":"1.187552454","rc":[{"trd":[[1.34,15217.94]],"batl":[[0,1.34,428.47]],"ltp":1.34,"tv":56460.3,"id":9028621}],"tv":61718.89}]}
{"op":"mcm","clk":"4226697067","pt":1631450769585,"mc":[{"id":"1.187552454","rc":[{"trd":[[3.9,91.79]],"batb":[[0,3.9,20.5]],"ltp":3.9,"tv":5258.94,"id":9345630}],"tv":61719.25}]}
{"op":"mcm","clk":"4226697187","pt":1631450770289,"mc":[{"id":"1.187552454","rc":[{"batl":[[0,1.34,416.56],[2,1.36,34.07]],"ltp":1.34,"tv":56460.3,"id":9028621}]}]}
{"op":"mcm","clk":"4226697449","pt":1631450771909,"mc":[{"id":"1.187552454","rc":[{"batl":[[0,1.34,416.93]],"ltp":1.34,"tv":56460.3,"id":9028621}]}]}
{"op":"mcm","clk":"4226697592","pt":1631450772722,"mc":[{"id":"1.187552454","rc":[{"trd":[[1.34,15230.38]],"batl":[[0,1.34,410.71]],"ltp":1.34,"tv":56472.74,"id":9028621}],"tv":61731.69}]}
{"op":"mcm","clk":"4226697915","pt":1631450774532,"mc":[{"id":"1.187552454","rc":[{"batb":[[1,3.8,2],[2,3.75,2]],"batl":[[0,4.3,2],[1,4.4,2],[2,4.5,34.07]],"ltp":3.9,"tv":5258.94,"id":9345630},{"batb":[[2,1.3,9]],"batl":[[0,1.35,60.37],[1,1.37,30.5],[2,1.38,33.75]],"ltp":1.34,"tv":56472.74,"id":9028621}]}]}
{"op":"mcm","clk":"4226698078","pt":1631450775431,"mc":[{"id":"1.187552454","rc":[{"batb":[[0,3.55,2.19],[1,2.32,102.49],[2,1.01,30]],"batl":[[0,4.8,2],[1,4.9,2],[2,6,2]],"ltp":3.9,"tv":5258.94,"id":9345630},{"batb":[[2,1.27,44.87]],"batl":[[0,1.39,31.87],[1,1.44,8.21],[2,1.49,1.65]],"ltp":1.34,"tv":56472.74,"id":9028621}]}]}
{"op":"mcm","clk":"4226698278","pt":1631450776546,"mc":[{"id":"1.187552454","rc":[{"batb":[[0,1.33,14.57],[1,1.27,44.87],[2,1.26,53.64]],"batl":[[0,1.39,31.5]],"ltp":1.34,"tv":56472.74,"id":9028621}]}]}
{"op":"mcm","clk":"4226698454","pt":1631450777511,"mc":[{"id":"1.187552454","rc":[{"batb":[[1,1.27,348.45],[2,1.26,684.08]],"batl":[[0,1.38,437.04],[1,1.39,403.02],[2,1.44,8.21]],"ltp":1.34,"tv":56472.74,"id":9028621}]}]}
{"op":"mcm","clk":"4226698768","pt":1631450779449,"mc":[{"id":"1.187552454","rc":[{"batb":[[0,3.55,5.19],[1,3.5,3],[2,2.32,102.49]],"ltp":3.9,"tv":5258.94,"id":9345630},{"batl":[[1,1.39,411.02]],"ltp":1.34,"tv":56472.74,"id":9028621}]}]}
{"op":"mcm","clk":"4226698844","pt":1631450779922,"mc":[{"id":"1.187552454","rc":[{"batb":[[1,1.29,23.75],[2,1.27,348.45]],"ltp":1.34,"tv":56472.74,"id":9028621}]}]}
{"op":"mcm","clk":"4226699072","pt":1631450781433,"mc":[{"id":"1.187552454","rc":[{"batb":[[0,3.7,2],[1,3.6,3],[2,3.55,5.19]],"batl":[[0,4.5,2],[1,4.8,2],[2,4.9,2]],"ltp":3.9,"tv":5258.94,"id":9345630},{"batb":[[1,1.29,39.81]],"batl":[[0,1.37,43.5],[1,1.38,445.04],[2,1.39,411.02]],"ltp":1.34,"tv":56472.74,"id":9028621}]}]}
{"op":"mcm","clk":"4226699170","pt":1631450781641,"mc":[{"id":"1.187552454","rc":[{"batb":[[0,3.6,3],[1,3.55,5.19],[2,3.5,3]],"batl":[[0,4.8,2],[1,4.9,2],[2,6,2]],"ltp":3.9,"tv":5258.94,"id":9345630},{"batb":[[1,1.27,348.45],[2,1.26,684.08]],"batl":[[0,1.37,7],[1,1.38,8],[2,1.39,8]],"ltp":1.34,"tv":56472.74,"id":9028621}]}]}
{"op":"mcm","clk":"4226699491","pt":1631450783544,"mc":[{"id":"1.187552454","rc":[{"trd":[[1.33,757.37],[1.34,15231.16]],"batb":[[0,1.27,348.45],[1,1.26,684.08],[2,1.21,447.13]],"batl":[[0,1.29,16.18],[1,1.31,1459.92],[2,1.32,1416.98]],"ltp":1.33,"tv":56501.88,"id":9028621}],"tv":61760.83}]}
{"op":"mcm","clk":"4226699637","pt":1631450784440,"mc":[{"id":"1.187552454","rc":[{"batl":[[2,5,765]],"ltp":3.9,"tv":5258.94,"id":9345630},{"batb":[[0,1.28,24.6],[1,1.27,348.45],[2,1.26,684.08]],"batl":[[0,1.31,293.89],[1,1.32,285.25],[2,1.33,293.79]],"ltp":1.33,"tv":56501.88,"id":9028621}]}]}
{"op":"mcm","clk":"4226699818","pt":1631450785540,"mc":[{"id":"1.187552454","rc":[{"batb":[[0,3.95,3],[1,3.8,15],[2,3.7,666.51]],"batl":[[0,4.7,10],[1,4.8,2],[2,4.9,2]],"ltp":3.9,"tv":5258.94,"id":9345630},{"batl":[[0,1.29,277.09],[1,1.3,516.55],[2,1.31,195.63]],"ltp":1.33,"tv":56501.88,"id":9028621}]}]}
{"op":"mcm","clk":"4226699968","pt":1631450786401,"mc":[{"id":"1.187552454","rc":[{"batb":[[0,4.2,18.75],[1,4.1,2],[2,4,2]],"ltp":3.9,"tv":5258.94,"id":9345630},{"batb":[[1,1.27,390.5]],"batl":[[2,1.31,255.63]],"ltp":1.33,"tv":56501.88,"id":9028621}]}]}
{"op":"mcm","clk":"4226700434","pt":1631450789442,"mc":[{"id":"1.187552454","rc":[{"batl":[[2,1.31,195.63]],"ltp":1.33,"tv":56501.88,"id":9028621}]}]}
{"op":"mcm","clk":"4226700779","pt":1631450791544,"mc":[{"id":"1.187552454","rc":[{"trd":[[1.29,2204.99]],"batl":[[0,1.29,276.97]],"ltp":1.29,"tv":56502.12,"id":9028621}],"tv":61761.07}]}
{"op":"mcm","clk":"4226700932","pt":1631450792442,"mc":[{"id":"1.187552454","rc":[{"batb":[[0,4.3,15],[1,4.2,18.75],[2,4.1,2]],"ltp":3.9,"tv":5258.94,"id":9345630},{"batb":[[0,1.27,390.5],[1,1.26,684.08],[2,1.25,30]],"batl":[[1,1.3,576.55]],"ltp":1.29,"tv":56502.12,"id":9028621}]}]}
{"op":"mcm","clk":"4226701065","pt":1631450793268,"mc":[{"id":"1.187552454","rc":[{"trd":[[4.4,74.56]],"ltp":4.4,"tv":5260.89,"id":9345630},{"trd":[[1.29,2211.64]],"batl":[[0,1.29,270.32]],"ltp":1.29,"tv":56508.77,"id":9028621}],"tv":61769.67}]}
{"op":"mcm","clk":"4226701623","pt":1631450796663,"mc":[{"id":"1.187552454","rc":[{"trd":[[1.29,2212.3]],"batl":[[0,1.29,269.99]],"ltp":1.29,"tv":56509.43,"id":9028621}],"tv":61770.33}]}
{"op":"mcm","clk":"4226701864","pt":1631450798034,"mc":[{"id":"1.187552454","rc":[{"batb":[[0,4.1,2],[1,3.95,3],[2,3.9,2]],"ltp":4.4,"tv":5260.89,"id":9345630},{"batl":[[0,1.28,9.58],[1,1.29,269.99],[2,1.3,576.55]],"ltp":1.29,"tv":56509.43,"id":9028621}]}]}
{"op":"mcm","clk":"4226702250","pt":1631450800213,"mc":[{"id":"1.187552454","rc":[{"batb":[[0,3.7,2],[1,2.32,102.49],[2,1.01,30]],"batl":[[0,5,30],[1,6,2],[2,6.4,2]],"ltp":4.4,"tv":5260.89,"id":9345630},{"batb":[[0,1.26,6.16],[1,1.25,30],[2,1.22,31.31]],"batl":[[1,1.3,60],[2,1.37,37.5]],"ltp":1.29,"tv":56509.43,"id":9028621}]}]}
{"op":"mcm","clk":"4226702486","pt":1631450801472,"mc":[{"id":"1.187552454","rc":[{"batb":[[0,3.7,2.17]],"batl":[[0,6,2],[1,6.4,2],[2,990,0.01]],"ltp":4.4,"tv":5260.89,"id":9345630},{"batb":[[1,1.21,447.13],[2,1.2,71.02]],"batl":[[1,1.37,37.5],[2,1.49,1.87]],"ltp":1.29,"tv":56509.43,"id":9028621}]}]}
{"op":"mcm","clk":"4226702548","pt":1631450801852,"mc":[{"id":"1.187552454","rc":[{"batl":[[0,5.8,2],[1,6,2],[2,6.4,2]],"ltp":4.4,"tv":5260.89,"id":9345630},{"batb":[[1,1.21,510.82]],"ltp":1.29,"tv":56509.43,"id":9028621}]}]}
{"op":"mcm","clk":"4226702837","pt":1631450803458,"mc":[{"id":"1.187552454","rc":[{"batb":[[1,1.22,272.18],[2,1.21,1322.38]],"batl":[[1,1.34,395.57],[2,1.35,425.73]],"ltp":1.29,"tv":56509.43,"id":9028621}]}]}
{"op":"mcm","clk":"4226702875","pt":1631450803660,"mc":[{"id":"1.187552454","rc":[{"batb":[[0,3.9,2.17],[1,3.7,2],[2,2.32,102.49]],"batl":[[0,5.6,2],[1,5.8,2],[2,6,2]],"ltp":4.4,"tv":5260.89,"id":9345630},{"batb":[[1,1.22,332.02]],"batl":[[1,1.34,427.82]],"ltp":1.29,"tv":56509.43,"id":9028621}]}]}
{"op":"mcm","clk":"4226703090","pt":1631450804957,"mc":[{"id":"1.187552454","rc":[{"batl":[[0,5.6,4]],"ltp":4.4,"tv":5260.89,"id":9345630},{"batb":[[1,1.22,363.33]],"ltp":1.29,"tv":56509.43,"id":9028621}]}]}
{"op":"mcm","clk":"4226703362","pt":1631450806664,"mc":[{"id":"1.187552454","rc":[{"batl":[[0,1.28,9.46]],"ltp":1.29,"tv":56509.43,"id":9028621}]}]}
{"op":"mcm","clk":"4226703535","pt":1631450807781,"mc":[{"id":"1.187552454","rc":[{"batb":[[0,3.9,2]],"ltp":4.4,"tv":5260.89,"id":9345630}]}]}
{"op":"mcm","clk":"4226703981","pt":1631450810288,"mc":[{"id":"1.187552454","rc":[{"batl":[[0,1.28,8.63]],"ltp":1.29,"tv":56509.43,"id":9028621}]}]}
{"op":"mcm","clk":"4226704304","pt":1631450812172,"mc":[{"id":"1.187552454","rc":[{"batb":[[0,3.7,2],[1,2.32,102.49],[2,1.01,30]],"ltp":4.4,"tv":5260.89,"id":9345630},{"batl":[[1,1.49,1.87],[2,1.64,674.86]],"ltp":1.29,"tv":56509.43,"id":9028621}]}]}
{"op":"mcm","clk":"4226704556","pt":1631450813583,"mc":[{"id":"1.187552454","rc":[{"batl":[[0,5.6,2]],"ltp":4.4,"tv":5260.89,"id":9345630},{"trd":[[1.26,380.02]],"batb":[[0,1.22,332.02],[1,1.21,1322.38],[2,1.2,105.46]],"ltp":1.26,"tv":56521.74,"id":9028621}],"tv":61782.64}]}
{"op":"mcm","clk":"4226704664","pt":1631450814267,"mc":[{"id":"1.187552454","rc":[{"trd":[[5.6,461.02]],"batb":[[0,5.1,18.75],[1,5,18.2],[2,4.9,18.2]],"batl":[[0,5.6,1.86]],"ltp":5.6,"tv":5261.17,"id":9345630},{"batb":[[1,1.21,881.41]],"batl":[[0,1.26,8.54],[1,1.28,8.63],[2,1.49,1.87]],"ltp":1.26,"tv":56521.74,"id":9028621}],"tv":61782.92}]}
{"op":"mcm","clk":"4226704839","pt":1631450815392,"mc":[{"id":"1.187552454","rc":[{"batb":[[0,5.1,45.69],[1,5,44.35],[2,4.9,44.35]],"batl":[[2,5.9,178.29]],"ltp":5.6,"tv":5261.17,"id":9345630},{"batl":[[0,1.24,575.44],[1,1.25,634.93],[2,1.26,21.2]],"ltp":1.26,"tv":56521.74,"id":9028621}]}]}
{"op":"mcm","clk":"4226705021","pt":1631450816566,"mc":[{"id":"1.187552454","rc":[{"batl":[[0,5.5,9],[1,5.6,1.86],[2,5.8,29.38]],"ltp":5.6,"tv":5261.17,"id":9345630},{"batb":[[2,1.2,139]],"batl":[[2,1.26,27.2]],"ltp":1.26,"tv":56521.74,"id":9028621}]}]}
{"op":"mcm","clk":"4226705144","pt":1631450817491,"mc":[{"id":"1.187552454","rc":[{"batl":[[2,5.7,2]],"ltp":5.6,"tv":5261.17,"id":9345630},{"batb":[[0,1.22,380.64],[2,1.2,104.56]],"ltp":1.26,"tv":56521.74,"id":9028621}]}]}
{"op":"mcm","clk":"4226705239","pt":1631450818066,"mc":[{"id":"1.187552454","rc":[{"trd":[[1.24,3824]],"batl":[[0,1.24,571.54]],"ltp":1.24,"tv":56529.54,"id":9028621}],"tv":61790.72}]}
{"op":"mcm","clk":"4226705481","pt":1631450819586,"mc":[{"id":"1.187552454","rc":[{"batl":[[2,1.26,18.66]],"ltp":1.24,"tv":56529.54,"id":9028621}]}]}
{"op":"mcm","clk":"4226705618","pt":1631450820187,"mc":[{"id":"1.187552454","rc":[{"trd":[[1.22,232.97]],"batb":[[0,1.22,358.5]],"ltp":1.22,"tv":56573.82,"id":9028621}],"tv":61835.0}]}
{"op":"mcm","clk":"4226706015","pt":1631450822596,"mc":[{"id":"1.187552454","rc":[{"batb":[[1,5,59.35]],"ltp":5.6,"tv":5261.17,"id":9345630}]}]}
{"op":"mcm","clk":"4226706186","pt":1631450823576,"mc":[{"id":"1.187552454","rc":[{"batl":[[1,1.25,694.93]],"ltp":1.22,"tv":56573.82,"id":9028621}]}]}
{"op":"mcm","clk":"4226706421","pt":1631450824909,"mc":[{"id":"1.187552454","rc":[{"trd":[[1.24,3867.78]],"batl":[[0,1.24,549.65]],"ltp":1.24,"tv":56617.6,"id":9028621}],"tv":61878.78}]}
{"op":"mcm","clk":"4226706592","pt":1631450825987,"mc":[{"id":"1.187552454","rc":[{"trd":[[1.22,309.23]],"batb":[[0,1.22,320.37]],"ltp":1.22,"tv":56693.86,"id":9028621}],"tv":61955.04}]}
{"op":"mcm","clk":"4226707176","pt":1631450829516,"mc":[{"id":"1.187552454","rc":[{"trd":[[1.22,309.51]],"batb":[[0,1.22,366.71]],"ltp":1.22,"tv":56694.15,"id":9028621}],"tv":61955.32}]}
{"op":"mcm","clk":"4226707241","pt":1631450829896,"mc":[{"id":"1.187552454","rc":[{"batb":[[0,1.22,108.46]],"ltp":1.22,"tv":56694.15,"id":9028621}]}]}
{"op":"mcm","clk":"4226707460","pt":1631450831291,"mc":[{"id":"1.187552454","rc":[{"trd":[[1.24,3874.79]],"batl":[[0,1.24,546.14]],"ltp":1.24,"tv":56701.15,"id":9028621}],"tv":61962.33}]}
{"op":"mcm","clk":"4226707536","pt":1631450831892,"mc":[{"id":"1.187552454","rc":[{"batl":[[2,1.26,6]],"ltp":1.24,"tv":56701.15,"id":9028621}]}]}
{"op":"mcm","clk":"4226707768","pt":1631450833432,"mc":[{"id":"1.187552454","rc":[{"batb":[[0,5,15],[1,4.6,2],[2,4.5,2]],"batl":[[0,5.6,1.86],[1,5.7,2],[2,5.8,29.38]],"ltp":5.6,"tv":5261.17,"id":9345630},{"batb":[[0,1.22,59.84],[1,1.21,69.85]],"batl":[[0,1.25,60],[1,1.26,6],[2,1.28,50.97]],"ltp":1.24,"tv":56701.15,"id":9028621}]}]}
{"op":"mcm","clk":"4226707964","pt":1631450834531,"mc":[{"id":"1.187552454","rc":[{"batb":[[0,4.5,2],[1,4.2,2],[2,2.32,102.49]],"batl":[[0,9.4,2],[1,990,0.01],[2,5.8,0]],"ltp":5.6,"tv":5261.17,"id":9345630},{"batb":[[0,1.22,259.11],[1,1.21,6.16],[2,1.2,9.75]],"batl":[[0,1.24,40.53],[1,1.28,50.97],[2,1.31,39.5]],"ltp":1.24,"tv":56701.15,"id":9028621}]}]}
{"op":"mcm","clk":"4226707999","pt":1631450834717,"mc":[{"id":"1.187552454","rc":[{"batb":[[0,4.2,2],[1,2.32,102.49],[2,1.01,30]],"ltp":5.6,"tv":5261.17,"id":9345630},{"batb":[[0,1.21,6.16],[1,1.2,9.75],[2,1.15,554.94]],"batl":[[0,1.28,8.63],[1,1.31,39.5],[2,1.49,1.87]],"ltp":1.24,"tv":56701.15,"id":9028621}]}]}
{"op":"mcm","clk":"4226708588","pt":1631450838514,"mc":[{"id":"1.187552454","rc":[{"batb":[[0,4.3,2],[1,4.2,4],[2,2.32,102.49]],"batl":[[0,7.8,2],[1,9.4,2],[2,990,0.01]],"ltp":5.6,"tv":5261.17,"id":9345630}]}]}
{"op":"mcm","clk":"4226708754","pt":1631450839533,"mc":[{"id":"1.187552454","rc":[{"batl":[[0,7.4,2],[1,7.8,2],[2,9.4,2]],"ltp":5.6,"tv":5261.17,"id":9345630}]}]}
{"op":"mcm","clk":"4226708828","pt":1631450840017,"mc":[{"id":"1.187552454","rc":[{"batb":[[1,1.2,1079.83],[2,1.19,686.6]],"batl":[[0,1.23,702.51],[1,1.24,663.08],[2,1.28,8.63]],"ltp":1.24,"tv":56701.15,"id":9028621}]}]}
{"op":"mcm","clk":"4226709045","pt":1631450841535,"mc":[{"id":"1.187552454","rc":[{"batl":[[0,6.8,10],[1,7.4,4],[2,7.8,2]],"ltp":5.6,"tv":5261.17,"id":9345630},{"batb":[[0,1.21,36.96]],"batl":[[2,1.27,163.12]],"ltp":1.24,"tv":56701.15,"id":9028621}]}]}
{"op":"mcm","clk":"4226709075","pt":1631450841743,"mc":[{"id":"1.187552454","rc":[{"batb":[[0,4.5,2],[1,4.4,2],[2,4.3,2]],"ltp":5.6,"tv":5261.17,"id":9345630}]}]}
{"op":"mcm","clk":"4226709624","pt":1631450845239,"mc":[{"id":"1.187552454","rc":[{"batb":[[0,4.4,2],[1,4.3,2],[2,4.2,4]],"batl":[[0,7.4,2],[1,7.8,2],[2,9.4,2]],"ltp":5.6,"tv":5261.17,"id":9345630},{"batb":[[0,1.21,6.16],[1,1.2,9.75],[2,1.15,554.94]],"batl":[[0,1.28,8.63],[1,1.31,39.5],[2,1.49,1.87]],"ltp":1.24,"tv":56701.15,"id":9028621}]}]}
{"op":"mcm","clk":"4226710111","pt":1631450848426,"mc":[{"id":"1.187552454","rc":[{"batb":[[0,4.5,2],[1,4.4,2],[2,4.3,2]],"batl":[[0,7.4,4]],"ltp":5.6,"tv":5261.17,"id":9345630},{"batb":[[2,1.16,1305.6]],"batl":[[0,1.28,52.72],[1,1.29,577.86],[2,1.3,510.88]],"ltp":1.24,"tv":56701.15,"id":9028621}]}]}
{"op":"mcm","clk":"4226710139","pt":1631450848652,"mc":[{"id":"1.187552454","rc":[{"batb":[[0,4.4,2],[1,4.3,2],[2,4.2,4]],"ltp":5.6,"tv":5261.17,"id":9345630},{"batl":[[0,1.28,8.63]],"ltp":1.24,"tv":56701.15,"id":9028621}]}]}
{"op":"mcm","clk":"4226710689","pt":1631450852232,"mc":[{"id":"1.187552454","rc":[{"batb":[[1,4.2,2],[2,2.32,102.49]],"batl":[[1,9.4,2],[2,990,0.01]],"ltp":5.6,"tv":5261.17,"id":9345630}]}]}
{"op":"mcm","clk":"4226711173","pt":1631450855489,"mc":[{"id":"1.187552454","rc":[{"batb":[[0,4.5,2],[1,4.4,2],[2,4.3,2]],"ltp":5.6,"tv":5261.17,"id":9345630},{"batl":[[0,1.28,51.47]],"ltp":1.24,"tv":56701.15,"id":9028621}]}]}
{"op":"mcm","clk":"4226711218","pt":1631450855754,"mc":[{"id":"1.187552454","rc":[{"batb":[[0,4.4,2],[1,4.3,2],[2,4.2,2]],"ltp":5.6,"tv":5261.17,"id":9345630},{"batb":[[0,1.2,9.75],[1,1.16,1305.6],[2,1.15,1138.24]],"batl":[[0,1.28,8.63]],"ltp":1.24,"tv":56701.15,"id":9028621}]}]}
{"op":"mcm","clk":"4226711445","pt":1631450857259,"mc":[{"id":"1.187552454","rc":[{"batb":[[1,1.17,163.99],[2,1.16,1305.6]],"ltp":1.24,"tv":56701.15,"id":9028621}]}]}
{"op":"mcm","clk":"4226711580","pt":1631450858059,"mc":[{"id":"1.187552454","rc":[{"trd":[[1.17,1395.24],[1.2,540.99]],"batb":[[0,1.17,137.59],[1,1.16,1305.6],[2,1.15,1138.24]],"ltp":1.17,"tv":56773.45,"id":9028621}],"tv":62034.63}]}
{"op":"mcm","clk":"4226711797","pt":1631450859139,"mc":[{"id":"1.187552454","rc":[{"batb":[[0,1.17,143.75]],"ltp":1.17,"tv":56773.45,"id":9028621}]}]}
{"op":"mcm","clk":"4226712147","pt":1631450861381,"mc":[{"id":"1.187552454","rc":[{"batl":[[0,7,2],[1,7.4,4],[2,9.4,2]],"ltp":5.6,"tv":5261.17,"id":9345630},{"batb":[[0,1.17,152.75],[1,1.16,1314.6]],"ltp":1.17,"tv":56773.45,"id":9028621}]}]}
{"op":"mcm","clk":"4226712289","pt":1631450862350,"mc":[{"id":"1.187552454","rc":[{"batb":[[0,4.5,2],[1,4.4,2],[2,4.3,2]],"ltp":5.6,"tv":5261.17,"id":9345630},{"batl":[[0,1.28,48.22]],"ltp":1.17,"tv":56773.45,"id":9028621}]}]}
{"op":"mcm","clk":"4226712374","pt":1631450862881,"mc":[{"id":"1.187552454","rc":[{"batb":[[0,4.4,2],[1,4.3,2],[2,4.2,2]],"ltp":5.6,"tv":5261.17,"id":9345630},{"batl":[[0,1.28,8.63]],"ltp":1.17,"tv":56773.45,"id":9028621}]}]}
{"op":"mcm","clk":"4226712763","pt":1631450865472,"mc":[{"id":"1.187552454","rc":[{"batl":[[0,6.8,2.37],[1,7,2],[2,7.4,4]],"ltp":5.6,"tv":5261.17,"id":9345630},{"batb":[[1,1.16,81.53],[2,1.15,554.94]],"ltp":1.17,"tv":56773.45,"id":9028621}]}]}
{"op":"mcm","clk":"4226712923","pt":1631450866386,"mc":[{"id":"1.187552454","rc":[{"trd":[[6.8,4.74],[7,7.28]],"batl":[[0,7,1.48],[1,7.4,4],[2,9.4,2]],"ltp":7.0,"tv":5266.95,"id":9345630}],"tv":62040.41}]}
{"op":"mcm","clk":"4226713269","pt":1631450868571,"mc":[{"id":"1.187552454","rc":[{"trd":[[4.5,28.93]],"batb":[[0,4.3,55.71],[1,4.2,56.07],[2,4.1,54.07]],"batl":[[0,4.5,6.09],[1,4.9,2],[2,5,210.37]],"ltp":4.5,"tv":5269.4,"id":9345630},{"trd":[[1.28,995.48]],"batb":[[0,1.26,617.48],[1,1.25,668.3],[2,1.19,13.41]],"batl":[[0,1.29,577.86],[1,1.3,523.15],[2,1.31,39.5]],"ltp":1.28,"tv":56782.08,"id":9028621}],"tv":62051.49}]}
{"op":"mcm","clk":"4226713442","pt":1631450869584,"mc":[{"id":"1.187552454","rc":[{"batl":[[1,4.6,2],[2,4.9,2]],"ltp":4.5,"tv":5269.4,"id":9345630},{"batb":[[0,1.26,625.48],[2,1.22,192.66]],"ltp":1.28,"tv":56782.08,"id":9028621}]}]}
{"op":"mcm","clk":"4226713574","pt":1631450870548,"mc":[{"id":"1.187552454","rc":[{"batb":[[0,4.3,73.89]],"ltp":4.5,"tv":5269.4,"id":9345630},{"batb":[[2,1.24,30.61]],"batl":[[1,1.3,583.15]],"ltp":1.28,"tv":56782.08,"id":9028621}]}]}
{"op":"mcm","clk":"4226713697","pt":1631450871295,"mc":[{"id":"1.187552454","rc":[{"batb":[[0,4.3,83.89]],"batl":[[2,4.9,4]],"ltp":4.5,"tv":5269.4,"id":9345630}]}]}
{"op":"mcm","clk":"4226714062","pt":1631450873469,"mc":[{"id":"1.187552454","rc":[{"batb":[[0,1.26,690.54]],"ltp":1.28,"tv":56782.08,"id":9028621}]}]}
{"op":"mcm","clk":"4226714981","pt":1631450879194,"mc":[{"id":"1.187552454","rc":[{"trd":[[4.5,36.03]],"batl":[[0,4.5,2.54]],"ltp":4.5,"tv":5276.51,"id":9345630}],"tv":62058.6}]}
{"op":"mcm","clk":"4226715795","pt":1631450884418,"mc":[{"id":"1.187552454","rc":[{"trd":[[4.4,80.67]],"batl":[[0,4.6,2],[1,4.9,4],[2,5,210.37]],"ltp":4.4,"tv":5282.62,"id":9345630},{"trd":[[1.29,2233.16]],"batl":[[0,1.29,557]],"ltp":1.29,"tv":56802.94,"id":9028621}],"tv":62085.57}]}
{"op":"mcm","clk":"4226715864","pt":1631450884794,"mc":[{"id":"1.187552454","rc":[{"trd":[[4.4,85.16]],"ltp":4.4,"tv":5287.11,"id":9345630},{"trd":[[1.29,2248.47]],"batl":[[0,1.29,541.69]],"ltp":1.29,"tv":56818.25,"id":9028621}],"tv":62105.37}]}
{"op":"mcm","clk":"4226715967","pt":1631450885609,"mc":[{"id":"1.187552454","rc":[{"batl":[[1,1.3,570.88]],"ltp":1.29,"tv":56818.25,"id":9028621}]}]}
{"op":"mcm","clk":"4226716262","pt":1631450887390,"mc":[{"id":"1.187552454","rc":[{"batb":[[0,4.5,6.01],[1,4.3,83.89],[2,4.2,56.07]],"ltp":4.4,"tv":5287.11,"id":9345630}]}]}
{"op":"mcm","clk":"4226716379","pt":1631450888218,"mc":[{"id":"1.187552454","rc":[{"batl":[[0,1.29,541.92]],"ltp":1.29,"tv":56818.25,"id":9028621}]}]}
{"op":"mcm","clk":"4226717336","pt":1631450894282,"mc":[{"id":"1.187552454","rc":[{"batb":[[0,4.3,83.89],[1,4.2,56.07],[2,4.1,54.07]],"ltp":4.4,"tv":5287.11,"id":9345630}]}]}
{"op":"mcm","clk":"4226717667","pt":1631450896400,"mc":[{"id":"1.187552454","rc":[{"batl":[[0,1.28,102.72],[1,1.29,541.69],[2,1.3,570.88]],"ltp":1.29,"tv":56818.25,"id":9028621}]}]}
{"op":"mcm","clk":"4226717829","pt":1631450897518,"mc":[{"id":"1.187552454","rc":[{"batb":[[0,4.3,18.18],[1,4,2],[2,3.9,2]],"batl":[[0,4.9,2],[1,5.1,29.63],[2,6,2]],"ltp":4.4,"tv":5287.11,"id":9345630},{"batb":[[0,1.24,30.61],[1,1.21,6.16],[2,1.2,59.72]],"batl":[[1,1.3,60],[2,1.33,40.5]],"ltp":1.29,"tv":56818.25,"id":9028621}]}]}
{"op":"mcm","clk":"4226717960","pt":1631450898428,"mc":[{"id":"1.187552454","rc":[{"batb":[[0,4,2],[1,3.9,2],[2,3.75,2]],"batl":[[0,6,2],[1,7.4,2],[2,9.4,2]],"ltp":4.4,"tv":5287.11,"id":9345630},{"batb":[[0,1.21,6.16],[1,1.2,59.72],[2,1.19,452.83]],"batl":[[1,1.33,40.5],[2,1.34,37.25]],"ltp":1.29,"tv":56818.25,"id":9028621}]}]}
{"op":"mcm","clk":"4226718118","pt":1631450899516,"mc":[{"id":"1.187552454","rc":[{"batl":[[0,7.4,2],[1,9.4,2],[2,990,0.01]],"ltp":4.4,"tv":5287.11,"id":9345630},{"trd":[[1.28,996.6]],"batb":[[1,1.19,452.83],[2,1.18,47.27]],"batl":[[0,1.28,101.92]],"ltp":1.28,"tv":56819.38,"id":9028621}],"tv":62106.5}]}
{"op":"mcm","clk":"4226718275","pt":1631450900384,"mc":[{"id":"1.187552454","rc":[{"batb":[[0,4.6,5.88],[1,4,2],[2,3.9,2]],"ltp":4.4,"tv":5287.11,"id":9345630},{"batb":[[1,1.2,478.86],[2,1.19,1372.03]],"ltp":1.28,"tv":56819.38,"id":9028621}]}]}
{"op":"mcm","clk":"4226718447","pt":1631450901413,"mc":[{"id":"1.187552454","rc":[{"batb":[[1,3.75,2],[2,3.7,2]],"ltp":4.4,"tv":5287.11,"id":9345630},{"batb":[[1,1.19,452.83],[2,1.18,47.27]],"batl":[[0,1.36,33.57],[1,1.37,34.5],[2,1.49,1.87]],"ltp":1.28,"tv":56819.38,"id":9028621}]}]}
{"op":"mcm","clk":"4226718611","pt":1631450902521,"mc":[{"id":"1.187552454","rc":[{"batb":[[0,3.75,2],[1,2.32,102.49],[2,1.01,30]],"ltp":4.4,"tv":5287.11,"id":9345630},{"batl":[[1,1.49,1.87],[2,1.57,743.76]],"ltp":1.28,"tv":56819.38,"id":9028621}]}]}
{"op":"mcm","clk":"4226718686","pt":1631450903023,"mc":[{"id":"1.187552454","rc":[{"batl":[[0,6.4,3],[1,7.4,2],[2,9.4,2]],"ltp":4.4,"tv":5287.11,"id":9345630}]}]}
{"op":"mcm","clk":"4226718898","pt":1631450904427,"mc":[{"id":"1.187552454","rc":[{"batb":[[0,4.5,20.02],[1,3.75,2],[2,2.32,102.49]],"batl":[[0,4.8,20.07],[1,6.4,3],[2,7.4,2]],"ltp":4.4,"tv":5287.11,"id":9345630},{"batb":[[0,1.25,432.48],[1,1.24,697.04],[2,1.21,6.16]],"batl":[[0,1.27,250.12],[1,1.28,561.84],[2,1.29,19.5]],"ltp":1.28,"tv":56819.38,"id":9028621}]}]}
{"op":"mcm","clk":"4226719025","pt":1631450905269,"mc":[{"id":"1.187552454","rc":[{"batb":[[0,4,2]],"batl":[[0,5.7,10]],"ltp":4.4,"tv":5287.11,"id":9345630},{"batb":[[2,1.22,30.8]],"batl":[[2,1.33,35.5]],"ltp":1.28,"tv":56819.38,"id":9028621}]}]}
{"op":"mcm","clk":"4226719188","pt":1631450906332,"mc":[{"id":"1.187552454","rc":[{"batb":[[1,3.75,4],[2,3.7,2]],"batl":[[1,6,2],[2,6.4,3]],"ltp":4.4,"tv":5287.11,"id":9345630},{"batb":[[2,1.21,6.16]],"ltp":1.28,"tv":56819.38,"id":9028621}]}]}
{"op":"mcm","clk":"4226719441","pt":1631450908228,"mc":[{"id":"1.187552454","rc":[{"trd":[[5,246.87]],"ltp":5.0,"tv":5291.34,"id":9345630},{"trd":[[1.25,1248.76]],"batb":[[0,1.25,415.57]],"ltp":1.25,"tv":56836.29,"id":9028621}],"tv":62127.64}]}
{"op":"mcm","clk":"4226719596","pt":1631450909326,"mc":[{"id":"1.187552454","rc":[{"batb":[[0,4.1,10]],"batl":[[0,6.4,3],[1,7.4,2],[2,9.4,2]],"ltp":5.0,"tv":5291.34,"id":9345630},{"batb":[[0,1.21,6.16],[1,1.19,452.83],[2,1.18,47.27]],"batl":[[0,1.36,40.57],[1,1.49,1.87],[2,1.57,743.76]],"ltp":1.25,"tv":56836.29,"id":9028621}]}]}
{"op":"mcm","clk":"4226719639","pt":1631450909603,"mc":[{"id":"1.187552454","rc":[{"batb":[[0,3.75,4],[1,3.7,2],[2,2.32,102.49]],"ltp":5.0,"tv":5291.34,"id":9345630}]}]}
{"op":"mcm","clk":"4226720104","pt":1631450912594,"mc":[{"id":"1.187552454","rc":[{"batb":[[0,3.9,2],[1,3.85,2],[2,3.75,4]],"ltp":5.0,"tv":5291.34,"id":9345630},{"batl":[[0,1.34,5],[1,1.36,40.57],[2,1.49,1.87]],"ltp":1.25,"tv":56836.29,"id":9028621}]}]}
{"op":"mcm","clk":"4226720166","pt":1631450913036,"mc":[{"id":"1.187552454","rc":[{"batb":[[1,1.2,471.45],[2,1.19,1372.02]],"batl":[[1,1.35,498.35],[2,1.36,450.29]],"ltp":1.25,"tv":56836.29,"id":9028621}]}]}
{"op":"mcm","clk":"4226720344","pt":1631450914048,"mc":[{"id":"1.187552454","rc":[{"batb":[[0,1.22,13.65],[1,1.21,6.16],[2,1.2,471.45]],"ltp":1.25,"tv":56836.29,"id":9028621}]}]}
{"op":"mcm","clk":"4226720580","pt":1631450915536,"mc":[{"id":"1.187552454","rc":[{"trd":[[1.22,336.81]],"batb":[[0,1.21,6.16],[1,1.2,471.45],[2,1.19,1372.02]],"batl":[[0,1.22,8.04],[1,1.34,5],[2,1.35,498.35]],"ltp":1.22,"tv":56863.59,"id":9028621}],"tv":62154.94}]}
{"op":"mcm","clk":"4226720739","pt":1631450916410,"mc":[{"id":"1.187552454","rc":[{"batl":[[2,1.36,7]],"ltp":1.22,"tv":56863.59,"id":9028621}]}]}
{"op":"mcm","clk":"4226720904","pt":1631450917418,"mc":[{"id":"1.187552454","rc":[{"batb":[[2,3.75,2]],"ltp":5.0,"tv":5291.34,"id":9345630},{"batb":[[2,1.19,919.19]],"batl":[[0,1.22,8.54]],"ltp":1.22,"tv":56863.59,"id":9028621}]}]}
{"op":"mcm","clk":"4226721096","pt":1631450918541,"mc":[{"id":"1.187552454","rc":[{"batb":[[0,5.4,67.91],[1,5.3,65.92],[2,5.2,65.92]],"batl":[[0,6.2,3.55],[1,6.4,600.66],[2,6.6,580.08]],"ltp":5.0,"tv":5291.34,"id":9345630},{"trd":[[1.22,352.89]],"batl":[[0,1.22,537.7],[1,1.23,701.52],[2,1.34,5]],"ltp":1.22,"tv":56879.67,"id":9028621}],"tv":62171.01}]}
{"op":"mcm","clk":"4226721259","pt":1631450919544,"mc":[{"id":"1.187552454","rc":[{"trd":[[5.8,1.02]],"batb":[[0,5.4,42.81],[1,5.3,41.56],[2,5.2,41.56]],"batl":[[1,6.4,167.36],[2,6.6,159.52]],"ltp":5.8,"tv":5292.26,"id":9345630},{"trd":[[1.21,2838.89],[1.22,415.51]],"batb":[[0,1.21,1.74],[1,1.2,480.45]],"batl":[[0,1.22,506.39],[2,1.25,12.76]],"ltp":1.21,"tv":56946.71,"id":9028621}],"tv":62238.98}]}
{"op":"mcm","clk":"4226721401","pt":1631450920445,"mc":[{"id":"1.187552454","rc":[{"batl":[[0,6.2,29.86]],"ltp":5.8,"tv":5292.26,"id":9345630},{"batb":[[2,1.19,958.6]],"batl":[[2,1.25,72.76]],"ltp":1.21,"tv":56946.71,"id":9028621}]}]}
{"op":"mcm","clk":"4226721723","pt":1631450922338,"mc":[{"id":"1.187552454","rc":[{"batl":[[2,1.25,12.76]],"ltp":1.21,"tv":56946.71,"id":9028621}]}]}
{"op":"mcm","clk":"4226721886","pt":1631450923521,"mc":[{"id":"1.187552454","rc":[{"batb":[[0,5.4,53.47]],"batl":[[0,6,15],[1,6.2,26.31],[2,6.4,167.36]],"ltp":5.8,"tv":5292.26,"id":9345630},{"trd":[[1.2,651.21],[1.21,2842.37]],"batb":[[0,1.2,425.34],[1,1.19,958.6],[2,1.18,9]],"ltp":1.2,"tv":57060.41,"id":9028621}],"tv":62352.68}]}
{"op":"mcm","clk":"4226722007","pt":1631450924357,"mc":[{"id":"1.187552454","rc":[{"batl":[[0,1.22,537.7]],"ltp":1.2,"tv":57060.41,"id":9028621}]}]}
{"op":"mcm","clk":"4226722126","pt":1631450925049,"mc":[{"id":"1.187552454","rc":[{"trd":[[1.22,431.37]],"batl":[[0,1.22,529.77],[2,1.24,60]],"ltp":1.22,"tv":57076.27,"id":9028621}],"tv":62368.54}]}
{"op":"mcm","clk":"4226722273","pt":1631450926061,"mc":[{"id":"1.187552454","rc":[{"trd":[[1.22,448.45]],"batl":[[0,1.22,521.23]],"ltp":1.22,"tv":57093.35,"id":9028621}],"tv":62385.62}]}
{"op":"mcm","clk":"4226722486","pt":1631450927447,"mc":[{"id":"1.187552454","rc":[{"trd":[[1.2,670.71]],"batb":[[0,1.2,460.69]],"ltp":1.2,"tv":57112.85,"id":9028621}],"tv":62405.12}]}
{"op":"mcm","clk":"4226722582","pt":1631450928152,"mc":[{"id":"1.187552454","rc":[{"batb":[[1,1.19,1061.83]],"batl":[[0,1.22,566.52]],"ltp":1.2,"tv":57112.85,"id":9028621}]}]}
{"op":"mcm","clk":"4226722666","pt":1631450928753,"mc":[{"id":"1.187552454","rc":[{"batb":[[0,1.2,519.95]],"ltp":1.2,"tv":57112.85,"id":9028621}]}]}
{"op":"mcm","clk":"4226723043","pt":1631450931060,"mc":[{"id":"1.187552454","rc":[{"trd":[[6,7.17]],"batl":[[0,6.2,26.31],[1,6.4,167.36],[2,6.6,159.52]],"ltp":6.0,"tv":5292.45,"id":9345630},{"batb":[[2,1.16,72.53]],"ltp":1.2,"tv":57112.85,"id":9028621}],"tv":62405.3}]}
{"op":"mcm","clk":"4226723414","pt":1631450933461,"mc":[{"id":"1.187552454","rc":[{"batb":[[0,5.1,14.63],[1,4.5,2],[2,4.3,2]],"batl":[[1,9.4,2],[2,15.5,2]],"ltp":6.0,"tv":5292.45,"id":9345630},{"batb":[[0,1.21,120.04],[1,1.19,137.64],[2,1.13,534.98]],"batl":[[0,1.22,31.31],[1,1.24,60],[2,1.3,39.15]],"ltp":1.2,"tv":57112.85,"id":9028621}]}]}
{"op":"mcm","clk":"4226723568","pt":1631450934452,"mc":[{"id":"1.187552454","rc":[{"batb":[[0,4.3,2],[1,3.95,3],[2,2.32,102.49]],"batl":[[0,9.4,2],[1,15.5,2],[2,990,0.01]],"ltp":6.0,"tv":5292.45,"id":9345630},{"batb":[[1,1.13,534.98],[2,1.12,106.7]],"batl":[[1,1.3,39.15],[2,1.33,7]],"ltp":1.2,"tv":57112.85,"id":9028621}]}]}
{"op":"mcm","clk":"4226724176","pt":1631450938254,"mc":[{"id":"1.187552454","rc":[{"trd":[[1.21,2986.97]],"batb":[[0,1.21,47.74]],"ltp":1.21,"tv":57257.45,"id":9028621}],"tv":62549.91}]}
{"op":"mcm","clk":"4226724372","pt":1631450939574,"mc":[{"id":"1.187552454","rc":[{"batb":[[0,1.13,534.98],[1,1.12,106.7],[2,1.11,7.92]],"ltp":1.21,"tv":57257.45,"id":9028621}]}]}
{"op":"mcm","clk":"4226724460","pt":1631450940267,"mc":[{"id":"1.187552454","rc":[{"batb":[[0,4.7,2],[1,4.3,2],[2,3.95,3]],"ltp":6.0,"tv":5292.45,"id":9345630},{"batb":[[0,1.18,1069.83],[1,1.17,716.89],[2,1.13,534.98]],"batl":[[0,1.21,960.28],[1,1.22,757.27],[2,1.27,45.5]],"ltp":1.21,"tv":57257.45,"id":9028621}]}]}
{"op":"mcm","clk":"4226724670","pt":1631450941559,"mc":[{"id":"1.187552454","rc":[{"batb":[[0,5,10],[1,4.7,6.92],[2,4.3,7.98]],"batl":[[0,7.4,10],[1,9.4,2],[2,15.5,2]],"ltp":6.0,"tv":5292.45,"id":9345630},{"batl":[[0,1.21,1002.41],[2,1.27,52.26]],"ltp":1.21,"tv":57257.45,"id":9028621}]}]}
{"op":"mcm","clk":"4226724774","pt":1631450942247,"mc":[{"id":"1.187552454","rc":[{"batl":[[1,8.8,2],[2,9.4,2]],"ltp":6.0,"tv":5292.45,"id":9345630},{"batb":[[2,1.13,551.98]],"batl":[[0,1.21,1002.8],[2,1.26,13.65]],"ltp":1.21,"tv":57257.45,"id":9028621}]}]}
{"op":"mcm","clk":"4226724950","pt":1631450943477,"mc":[{"id":"1.187552454","rc":[{"batb":[[0,4.7,6.92],[1,4.3,7.98],[2,3.95,3]],"batl":[[0,8.8,2],[1,9.4,2],[2,15.5,2]],"ltp":6.0,"tv":5292.45,"id":9345630},{"trd":[[1.21,3059.27]],"batb":[[0,1.13,551.98],[1,1.12,127.7],[2,1.11,7.92]],"batl":[[0,1.22,31.7],[1,1.26,13.65],[2,1.27,52.26]],"ltp":1.21,"tv":57329.75,"id":9028621}],"tv":62622.21}]}
{"op":"mcm","clk":"4226724994","pt":1631450943749,"mc":[{"id":"1.187552454","rc":[{"batb":[[0,4.3,2],[1,3.95,3],[2,2.32,102.49]],"ltp":6.0,"tv":5292.45,"id":9345630},{"batl":[[2,1.3,39.15]],"ltp":1.21,"tv":57329.75,"id":9028621}]}]}
{"op":"mcm","clk":"4226725556","pt":1631450947279,"mc":[{"id":"1.187552454","rc":[{"batb":[[0,1.13,1412.33],[1,1.12,1135.71]],"batl":[[0,1.22,31.31],[2,1.33,7]],"ltp":1.21,"tv":57329.75,"id":9028621}]}]}
{"op":"mcm","clk":"4226725837","pt":1631450949051,"mc":[{"id":"1.187552454","rc":[{"batl":[[0,1.26,13.65],[1,1.33,7],[2,1.49,1.87]],"ltp":1.21,"tv":57329.75,"id":9028621}]}]}
{"op":"mcm","clk":"4226726086","pt":1631450950584,"mc":[{"id":"1.187552454","rc":[{"batb":[[0,7.6,2.59],[1,7.4,30.18],[2,7.2,29.29]],"batl":[[2,9.6,109.57]],"ltp":6.0,"tv":5292.45,"id":9345630},{"batb":[[0,1.13,877.35]],"batl":[[0,1.15,1050.34],[1,1.16,775.71],[2,1.19,13.41]],"ltp":1.21,"tv":57329.75,"id":9028621}]}]}
{"op":"mcm","clk":"4226726224","pt":1631450951485,"mc":[{"id":"1.187552454","rc":[{"batl":[[0,7.8,23],[1,8.6,8.9],[2,8.8,2]],"ltp":6.0,"tv":5292.45,"id":9345630},{"batb":[[0,1.14,184.04],[1,1.13,955.25],[2,1.12,1135.71]],"batl":[[2,1.18,156.55]],"ltp":1.21,"tv":57329.75,"id":9028621}]}]}
{"op":"mcm","clk":"4226726372","pt":1631450952399,"mc":[{"id":"1.187552454","rc":[{"batl":[[0,8.6,8.9],[1,8.8,2],[2,9.4,2]],"ltp":6.0,"tv":5292.45,"id":9345630},{"trd":[[1.14,59.55]],"batb":[[0,1.14,165.96]],"batl":[[2,1.19,13.41]],"ltp":1.14,"tv":57365.9,"id":9028621}],"tv":62658.36}]}
{"op":"mcm","clk":"4226726552","pt":1631450953589,"mc":[{"id":"1.187552454","rc":[{"batl":[[0,8.6,2]],"ltp":6.0,"tv":5292.45,"id":9345630},{"batb":[[2,1.12,1056.18]],"batl":[[0,1.15,993.35],[1,1.16,792.71]],"ltp":1.14,"tv":57365.9,"id":9028621}]}]}
{"op":"mcm","clk":"4226726716","pt":1631450954565,"mc":[{"id":"1.187552454","rc":[{"trd":[[1.14,76.63],[1.15,232.19]],"batb":[[0,1.14,157.42]],"batl":[[0,1.15,942.74]],"ltp":1.15,"tv":57484.21,"id":9028621}],"tv":62776.66}]}
{"op":"mcm","clk":"4226726827","pt":1631450955259,"mc":[{"id":"1.187552454","rc":[{"batb":[[0,7.6,12.59]],"ltp":6.0,"tv":5292.45,"id":9345630},{"trd":[[1.14,315.55]],"batb":[[0,1.14,37.96]],"batl":[[0,1.15,990.67]],"ltp":1.14,"tv":57723.13,"id":9028621}],"tv":63015.58}]}
{"op":"mcm","clk":"4226727029","pt":1631450956489,"mc":[{"id":"1.187552454","rc":[{"batl":[[0,8.4,8.9],[1,8.6,2],[2,8.8,2]],"ltp":6.0,"tv":5292.45,"id":9345630},{"batb":[[1,1.13,1013.25]],"batl":[[1,1.16,849.21]],"ltp":1.14,"tv":57723.13,"id":9028621}]}]}
{"op":"mcm","clk":"4226727189","pt":1631450957581,"mc":[{"id":"1.187552454","rc":[{"trd":[[1.14,384.81]],"batb":[[0,1.13,1013.25],[1,1.12,999.78],[2,1.11,7.92]],"ltp":1.14,"tv":57792.39,"id":9028621}],"tv":63084.84}]}
{"op":"mcm","clk":"4226727322","pt":1631450958497,"mc":[{"id":"1.187552454","rc":[{"batl":[[0,8.4,30.95]],"ltp":6.0,"tv":5292.45,"id":9345630}]}]}
{"op":"mcm","clk":"4226727498","pt":1631450959554,"mc":[{"id":"1.187552454","rc":[{"batl":[[0,8.4,8.9]],"ltp":6.0,"tv":5292.45,"id":9345630}]}]}
{"op":"mcm","clk":"4226727577","pt":1631450960096,"mc":[{"id":"1.187552454","rc":[{"batb":[[0,1.13,1069.16]],"batl":[[1,1.16,903.59]],"ltp":1.14,"tv":57792.39,"id":9028621}]}]}
{"op":"mcm","clk":"4226727977","pt":1631450962396,"mc":[{"id":"1.187552454","rc":[{"batl":[[1,8.6,23.76]],"ltp":6.0,"tv":5292.45,"id":9345630},{"batb":[[0,1.13,1235.57]],"batl":[[0,1.14,4.25],[1,1.15,990.67],[2,1.16,903.59]],"ltp":1.14,"tv":57792.39,"id":9028621}]}]}
{"op":"mcm","clk":"4226728146","pt":1631450963486,"mc":[{"id":"1.187552454","rc":[{"trd":[[1.13,316.31],[1.14,393.31],[1.15,273.69]],"batb":[[0,1.13,1160.1]],"batl":[[0,1.15,969.92],[1,1.16,903.59],[2,1.17,60]],"ltp":1.15,"tv":57993.33,"id":9028621}],"tv":63285.78}]}
{"op":"mcm","clk":"4226728435","pt":1631450965393,"mc":[{"id":"1.187552454","rc":[{"batl":[[2,9.4,2]],"ltp":6.0,"tv":5292.45,"id":9345630},{"trd":[[1.14,422.24]],"batl":[[0,1.14,425.29],[1,1.15,969.92],[2,1.16,903.59]],"ltp":1.14,"tv":58022.25,"id":9028621}],"tv":63314.7}]}
{"op":"mcm","clk":"4226728603","pt":1631450966461,"mc":[{"id":"1.187552454","rc":[{"trd":[[8.4,2.32]],"batl":[[0,8.4,7.74]],"ltp":8.4,"tv":5294.77,"id":9345630},{"trd":[[1.13,587.99]],"batb":[[0,1.13,1024.26]],"batl":[[0,1.14,1323.08],[2,1.16,849.21]],"ltp":1.13,"tv":58293.93,"id":9028621}],"tv":63588.7}]}
{"op":"mcm","clk":"4226728624","pt":1631450966689,"mc":[{"id":"1.187552454","rc":[{"trd":[[1.14,422.9]],"batl":[[0,1.14,1347.62]],"ltp":1.14,"tv":58294.6,"id":9028621}],"tv":63589.37}]}
{"op":"mcm","clk":"4226728895","pt":1631450968597,"mc":[{"id":"1.187552454","rc":[{"trd":[[8.4,7.64],[8.6,20.2]],"batl":[[0,8.6,17.93],[1,9.4,2],[2,9.6,109.57]],"ltp":8.6,"tv":5311.75,"id":9345630},{"trd":[[1.14,440.62]],"batl":[[0,1.14,1338.76]],"ltp":1.14,"tv":58312.32,"id":9028621}],"tv":63624.07}]}
{"op":"mcm","clk":"4226729043","pt":1631450969459,"mc":[{"id":"1.187552454","rc":[{"batb":[[0,1.13,1145.7],[1,1.12,1073.3]],"batl":[[1,1.15,1052.48]],"ltp":1.14,"tv":58312.32,"id":9028621}]}]}
{"op":"mcm","clk":"4226729220","pt":1631450970586,"mc":[{"id":"1.187552454","rc":[{"batl":[[0,1.14,1377.39]],"ltp":1.14,"tv":58312.32,"id":9028621}]}]}
{"op":"mcm","clk":"4226729475","pt":1631450972194,"mc":[{"id":"1.187552454","rc":[{"batl":[[0,8.6,30.34]],"ltp":8.6,"tv":5311.75,"id":9345630}]}]}
{"op":"mcm","clk":"4226729749","pt":1631450974009,"mc":[{"id":"1.187552454","rc":[{"trd":[[1.14,442.14]],"batl":[[0,1.14,1376.63]],"ltp":1.14,"tv":58313.84,"id":9028621}],"tv":63625.59}]}
{"op":"mcm","clk":"4226729975","pt":1631450975305,"mc":[{"id":"1.187552454","rc":[{"trd":[[1.13,615.08]],"batb":[[0,1.13,1132.16]],"ltp":1.13,"tv":58340.92,"id":9028621}],"tv":63652.67}]}
{"op":"mcm","clk":"4226730106","pt":1631450976101,"mc":[{"id":"1.187552454","rc":[{"trd":[[1.14,452.14]],"batl":[[0,1.14,1371.63]],"ltp":1.14,"tv":58350.92,"id":9028621}],"tv":63662.67}]}
{"op":"mcm","clk":"4226730416","pt":1631450978024,"mc":[{"id":"1.187552454","rc":[{"trd":[[8,0.1]],"ltp":8.0,"tv":5311.84,"id":9345630},{"trd":[[1.14,525.43]],"batl":[[0,1.14,1334.64]],"ltp":1.14,"tv":58424.2,"id":9028621}],"tv":63736.05}]}
{"op":"mcm","clk":"4226730709","pt":1631450979516,"mc":[{"id":"1.187552454","rc":[{"trd":[[1.13,650.65]],"batb":[[0,1.13,1114.37]],"ltp":1.13,"tv":58459.78,"id":9028621}],"tv":63771.63}]}
{"op":"mcm","clk":"4226731229","pt":1631450982530,"mc":[{"id":"1.187552454","rc":[{"trd":[[8.6,50.54]],"batb":[[0,7.6,2.59]],"batl":[[0,9.4,2],[1,9.6,109.57],[2,9.8,106.35]],"ltp":8.6,"tv":5342.18,"id":9345630},{"trd":[[1.13,3114.19]],"batb":[[0,1.12,1073.3],[1,1.11,7.92],[2,1.1,127.44]],"batl":[[0,1.13,327.56],[1,1.14,1310.95],[2,1.15,1052.48]],"ltp":1.13,"tv":60923.32,"id":9028621}],"tv":66265.51}]}
{"op":"mcm","clk":"4226731368","pt":1631450983539,"mc":[{"id":"1.187552454","rc":[{"trd":[[8.6,56.04]],"ltp":8.6,"tv":5347.68,"id":9345630},{"trd":[[1.13,3156.05]],"batl":[[0,1.13,285.7]],"ltp":1.13,"tv":60965.17,"id":9028621}],"tv":66312.86}]}
{"op":"mcm","clk":"4226731471","pt":1631450984334,"mc":[{"id":"1.187552454","rc":[{"trd":[[8.6,56.48]],"ltp":8.6,"tv":5348.12,"id":9345630},{"trd":[[1.13,3159.37]],"batl":[[0,1.13,282.38]],"ltp":1.13,"tv":60968.5,"id":9028621}],"tv":66316.62}]}
{"op":"mcm","clk":"4226731670","pt":1631450985558,"mc":[{"id":"1.187552454","rc":[{"trd":[[8.6,58.48]],"batb":[[0,7.8,18.82],[1,7.6,2.59],[2,7.4,30.18]],"batl":[[2,9.8,126.57]],"ltp":8.6,"tv":5350.12,"id":9345630},{"trd":[[1.13,3708.91]],"batb":[[0,1.13,268.98],[1,1.12,1470.94],[2,1.11,188.82]],"batl":[[0,1.14,1310.95],[1,1.15,1485.86],[2,1.16,462.29]],"ltp":1.13,"tv":61518.04,"id":9028621}],"tv":66868.16}]}
{"op":"mcm","clk":"4226731748","pt":1631450985929,"mc":[{"id":"1.187552454","rc":[{"batl":[[0,9.2,10],[1,9.4,2],[2,9.6,109.57]],"ltp":8.6,"tv":5350.12,"id":9345630},{"batb":[[0,1.13,329.72]],"batl":[[1,1.15,1285.42],[2,1.16,17]],"ltp":1.13,"tv":61518.04,"id":9028621}]}]}
{"op":"mcm","clk":"4226732150","pt":1631450988510,"mc":[{"id":"1.187552454","rc":[{"trd":[[1.13,3756.29]],"batb":[[0,1.13,306.03]],"ltp":1.13,"tv":61565.41,"id":9028621}],"tv":66915.54}]}
{"op":"mcm","clk":"4226732226","pt":1631450989039,"mc":[{"id":"1.187552454","rc":[{"trd":[[1.14,625.63]],"batb":[[0,1.13,452.67],[1,1.12,1578.4]],"batl":[[0,1.14,1568.53]],"ltp":1.14,"tv":61665.61,"id":9028621}],"tv":67015.74}]}
{"op":"mcm","clk":"4226732501","pt":1631450990710,"mc":[{"id":"1.187552454","rc":[{"trd":[[8,77.6]],"ltp":8.0,"tv":5427.62,"id":9345630},{"trd":[[1.14,1169.48]],"batl":[[0,1.14,1024.68]],"ltp":1.14,"tv":62209.47,"id":9028621}],"tv":67637.1}]}
{"op":"mcm","clk":"4226732915","pt":1631450993570,"mc":[{"id":"1.187552454","rc":[{"batl":[[0,9.2,10.15]],"ltp":8.0,"tv":5427.62,"id":9345630},{"trd":[[1.14,1179.8]],"batl":[[0,1.14,1019.52]],"ltp":1.14,"tv":62219.79,"id":9028621}],"tv":67647.42}]}
{"op":"mcm","clk":"4226733039","pt":1631450994249,"mc":[{"id":"1.187552454","rc":[{"batl":[[0,9.4,2.15],[1,9.6,109.57],[2,9.8,126.57]],"ltp":8.0,"tv":5427.62,"id":9345630},{"batb":[[0,1.13,452.87]],"ltp":1.14,"tv":62219.79,"id":9028621}]}]}
{"op":"mcm","clk":"4226733142","pt":1631450994922,"mc":[{"id":"1.187552454","rc":[{"trd":[[1.14,1180.59]],"batl":[[0,1.14,1019.12]],"ltp":1.14,"tv":62220.58,"id":9028621}],"tv":67648.21}]}
{"op":"mcm","clk":"4226733280","pt":1631450995945,"mc":[{"id":"1.187552454","rc":[{"trd":[[1.13,3912.86]],"batb":[[0,1.13,374.58]],"ltp":1.13,"tv":62377.15,"id":9028621}],"tv":67804.78}]}
{"op":"mcm","clk":"4226733514","pt":1631450997333,"mc":[{"id":"1.187552454","rc":[{"trd":[[1.14,1271.4]],"batl":[[0,1.14,973.72]],"ltp":1.14,"tv":62467.96,"id":9028621}],"tv":67895.59}]}
{"op":"mcm","clk":"4226733679","pt":1631450998442,"mc":[{"id":"1.187552454","rc":[{"batb":[[0,1.13,374.38]],"ltp":1.14,"tv":62467.96,"id":9028621}]}]}
{"op":"mcm","clk":"4226733845","pt":1631450999561,"mc":[{"id":"1.187552454","rc":[{"batl":[[0,8.6,2.15],[1,9.4,2],[2,9.6,109.57]],"ltp":8.0,"tv":5427.62,"id":9345630},{"trd":[[1.14,1281.72]],"batb":[[0,1.13,432.48]],"batl":[[0,1.14,968.56]],"ltp":1.14,"tv":62478.28,"id":9028621}],"tv":67905.91}]}
{"op":"mcm","clk":"4226734022","pt":1631451000546,"mc":[{"id":"1.187552454","rc":[{"batl":[[1,9,11],[2,9.4,2]],"ltp":8.0,"tv":5427.62,"id":9345630},{"batb":[[0,1.13,532.48]],"ltp":1.14,"tv":62478.28,"id":9028621}]}]}
{"op":"mcm","clk":"4226734053","pt":1631451000729,"mc":[{"id":"1.187552454","rc":[{"batl":[[1,9.4,2],[2,9.6,109.57]],"ltp":8.0,"tv":5427.62,"id":9345630}]}]}
{"op":"mcm","clk":"4226734810","pt":1631451005301,"mc":[{"id":"1.187552454","rc":[{"trd":[[1.14,1282.11]],"batl":[[0,1.14,968.37]],"ltp":1.14,"tv":62478.67,"id":9028621}],"tv":67906.3}]}
{"op":"mcm","clk":"4226734891","pt":1631451005661,"mc":[{"id":"1.187552454","rc":[{"trd":[[1.14,1299.09]],"batl":[[0,1.14,959.88]],"ltp":1.14,"tv":62495.65,"id":9028621}],"tv":67923.28}]}
{"op":"mcm","clk":"4226735220","pt":1631451007682,"mc":[{"id":"1.187552454","rc":[{"trd":[[1.14,1327.6]],"batl":[[0,1.14,945.62]],"ltp":1.14,"tv":62524.16,"id":9028621}],"tv":67951.79}]}
{"op":"mcm","clk":"4226735919","pt":1631451012399,"mc":[{"id":"1.187552454","rc":[{"trd":[[1.14,1328.21]],"batl":[[0,1.14,945.32]],"ltp":1.14,"tv":62524.77,"id":9028621}],"tv":67952.4}]}
{"op":"mcm","clk":"4226736646","pt":1631451017400,"mc":[{"id":"1.187552454","rc":[{"batl":[[0,8.6,13.15]],"ltp":8.0,"tv":5427.62,"id":9345630}]}]}
{"op":"mcm","clk":"4226736773","pt":1631451018394,"mc":[{"id":"1.187552454","rc":[{"batl":[[1,1.15,1301.22]],"ltp":1.14,"tv":62524.77,"id":9028621}]}]}
{"op":"mcm","clk":"4226738381","pt":1631451029583,"mc":[{"id":"1.187552454","rc":[{"trd":[[1.14,1328.86]],"batl":[[0,1.14,944.99]],"ltp":1.14,"tv":62525.43,"id":9028621}],"tv":67953.05}]}
{"op":"mcm","clk":"4226738836","pt":1631451032732,"mc":[{"id":"1.187552454","rc":[{"trd":[[1.13,3913.24]],"batb":[[0,1.13,532.29]],"ltp":1.13,"tv":62525.81,"id":9028621}],"tv":67953.43}]}
{"op":"mcm","clk":"4226739564","pt":1631451038165,"mc":[{"id":"1.187552454","rc":[{"trd":[[1.13,3924.52]],"batb":[[0,1.13,526.65]],"ltp":1.13,"tv":62537.08,"id":9028621}],"tv":67964.71}]}
{"op":"mcm","clk":"4226739711","pt":1631451039279,"mc":[{"id":"1.187552454","rc":[{"trd":[[8,78.29]],"ltp":8.0,"tv":5428.31,"id":9345630},{"trd":[[1.14,1333.7]],"batl":[[0,1.14,940.15]],"ltp":1.14,"tv":62541.93,"id":9028621}],"tv":67970.24}]}
{"op":"mcm","clk":"4226740014","pt":1631451041483,"mc":[{"id":"1.187552454","rc":[{"batb":[[2,1.11,306.41]],"ltp":1.14,"tv":62541.93,"id":9028621}]}]}
{"op":"mcm","clk":"4226740175","pt":1631451042445,"mc":[{"id":"1.187552454","rc":[{"trd":[[1.13,3928.86]],"batb":[[0,1.13,524.48],[1,1.12,1625.15]],"batl":[[0,1.14,986.1]],"ltp":1.13,"tv":62546.27,"id":9028621}],"tv":67974.58}]}
{"op":"mcm","clk":"4226740815","pt":1631451047332,"mc":[{"id":"1.187552454","rc":[{"trd":[[8.6,71.62]],"batl":[[0,9.6,109.57],[1,9.8,126.57],[2,10,106.35]],"ltp":8.6,"tv":5441.46,"id":9345630},{"trd":[[1.12,404.2],[1.13,5077.87]],"batb":[[0,1.12,1423.05],[1,1.11,306.41],[2,1.1,127.44]],"ltp":1.12,"tv":64099.47,"id":9028621}],"tv":69540.93}]}
{"op":"mcm","clk":"4226741092","pt":1631451049342,"mc":[{"id":"1.187552454","rc":[{"trd":[[1.14,1334.2]],"batl":[[0,1.14,985.85]],"ltp":1.14,"tv":64099.97,"id":9028621}],"tv":69541.43}]}
{"op":"mcm","clk":"4226741215","pt":1631451050359,"mc":[{"id":"1.187552454","rc":[{"batl":[[0,8.6,2],[1,9.2,2],[2,9.4,2]],"ltp":8.6,"tv":5441.46,"id":9345630},{"batb":[[0,1.13,19],[1,1.12,4014.4],[2,1.11,306.41]],"batl":[[0,1.14,1178]],"ltp":1.14,"tv":64099.97,"id":9028621}]}]}
{"op":"mcm","clk":"4226741361","pt":1631451051427,"mc":[{"id":"1.187552454","rc":[{"batl":[[2,9.4,15.41]],"ltp":8.6,"tv":5441.46,"id":9345630},{"trd":[[1.13,5078.75]],"batb":[[0,1.13,18.56],[1,1.12,4120.58]],"ltp":1.13,"tv":64100.85,"id":9028621}],"tv":69542.31}]}
{"op":"mcm","clk":"4226741498","pt":1631451052651,"mc":[{"id":"1.187552454","rc":[{"trd":[[1.14,1334.98]],"batl":[[0,1.14,1177.61]],"ltp":1.14,"tv":64101.63,"id":9028621}],"tv":69543.1}]}
{"op":"mcm","clk":"4226741750","pt":1631451054532,"mc":[{"id":"1.187552454","rc":[{"batb":[[0,7.8,8.82]],"batl":[[0,9.2,2],[1,9.4,2],[2,9.6,109.57]],"ltp":8.6,"tv":5441.46,"id":9345630}]}]}
{"op":"mcm","clk":"4226742098","pt":1631451057376,"mc":[{"id":"1.187552454","rc":[{"batb":[[0,8,10],[1,7.8,8.82],[2,7.6,2.59]],"ltp":8.6,"tv":5441.46,"id":9345630},{"trd":[[1.13,5091.85]],"batb":[[0,1.13,12.01],[1,1.12,1869.83]],"ltp":1.13,"tv":64114.74,"id":9028621}],"tv":69556.2}]}
{"op":"mcm","clk":"4226742214","pt":1631451058299,"mc":[{"id":"1.187552454","rc":[{"batb":[[0,7.8,8.82],[1,6.2,5.62],[2,5.5,6.49]],"batl":[[0,9.8,20.22],[1,10.5,2],[2,990,0.01]],"ltp":8.6,"tv":5441.46,"id":9345630},{"batb":[[0,1.11,306.41],[1,1.09,679.66],[2,1.08,86.11]],"batl":[[0,1.14,631.83],[1,1.15,75.8],[2,1.19,78.58]],"ltp":1.13,"tv":64114.74,"id":9028621}]}]}
{"op":"mcm","clk":"4226742383","pt":1631451059464,"mc":[{"id":"1.187552454","rc":[{"batb":[[0,6.2,5.62],[1,5.5,6.49],[2,3.95,3]],"batl":[[0,10.5,2],[1,990,0.01],[2,990,0]],"ltp":8.6,"tv":5441.46,"id":9345630},{"batb":[[0,1.11,125.51]],"batl":[[1,1.15,15.8]],"ltp":1.13,"tv":64114.74,"id":9028621}]}]}
{"op":"mcm","clk":"4226742689","pt":1631451061493,"mc":[{"id":"1.187552454","rc":[{"batb":[[1,1.1,1815.79],[2,1.09,679.66]],"batl":[[2,1.18,870.32]],"ltp":1.13,"tv":64114.74,"id":9028621}]}]}
{"op":"mcm","clk":"4226743404","pt":1631451066299,"mc":[{"id":"1.187552454","rc":[{"batl":[[2,1.19,78.58]],"ltp":1.13,"tv":64114.74,"id":9028621}]}]}
{"op":"mcm","clk":"4226743732","pt":1631451068572,"mc":[{"id":"1.187552454","rc":[{"batb":[[0,8.8,12.2],[1,6.2,5.62],[2,5.5,6.49]],"ltp":8.6,"tv":5441.46,"id":9345630},{"trd":[[1.11,17.08]],"batb":[[0,1.11,116.97]],"ltp":1.11,"tv":64131.81,"id":9028621}],"tv":69573.28}]}
{"op":"mcm","clk":"4226743849","pt":1631451069379,"mc":[{"id":"1.187552454","rc":[{"batb":[[1,8.6,2.04],[2,8.4,17.56]],"batl":[[0,10.5,4]],"ltp":8.6,"tv":5441.46,"id":9345630},{"batb":[[0,1.11,135.97],[1,1.1,1835.79],[2,1.09,6.16]],"batl":[[0,1.12,1027.1],[1,1.13,885.92],[2,1.14,631.83]],"ltp":1.11,"tv":64131.81,"id":9028621}]}]}
{"op":"mcm","clk":"4226744047","pt":1631451070598,"mc":[{"id":"1.187552454","rc":[{"batb":[[1,8.6,9.93]],"batl":[[0,10.5,10.68],[1,12,18.09],[2,990,0.01]],"ltp":8.6,"tv":5441.46,"id":9345630},{"batl":[[1,1.13,1072.94]],"ltp":1.11,"tv":64131.81,"id":9028621}]}]}
{"op":"mcm","clk":"4226744163","pt":1631451071289,"mc":[{"id":"1.187552454","rc":[{"batl":[[0,10.5,4]],"ltp":8.6,"tv":5441.46,"id":9345630},{"batl":[[1,1.13,961.92]],"ltp":1.11,"tv":64131.81,"id":9028621}]}]}
{"op":"mcm","clk":"4226744456","pt":1631451073464,"mc":[{"id":"1.187552454","rc":[{"batb":[[1,8.6,2.04]],"ltp":8.6,"tv":5441.46,"id":9345630}]}]}
{"op":"mcm","clk":"4226744568","pt":1631451074379,"mc":[{"id":"1.187552454","rc":[{"batl":[[0,1.12,1079.12]],"ltp":1.11,"tv":64131.81,"id":9028621}]}]}
{"op":"mcm","clk":"4226744717","pt":1631451075577,"mc":[{"id":"1.187552454","rc":[{"trd":[[1.12,405.03]],"batl":[[0,1.12,1078.7]],"ltp":1.12,"tv":64132.65,"id":9028621}],"tv":69574.11}]}
{"op":"mcm","clk":"4226744792","pt":1631451076009,"mc":[{"id":"1.187552454","rc":[{"batl":[[1,11,2],[2,12,18.09]],"ltp":8.6,"tv":5441.46,"id":9345630},{"batb":[[1,1.1,1952.73],[2,1.09,149.77]],"ltp":1.12,"tv":64132.65,"id":9028621}]}]}
{"op":"mcm","clk":"4226745023","pt":1631451077583,"mc":[{"id":"1.187552454","rc":[{"batb":[[0,9.2,11.23],[1,9,7.5],[2,8.8,12.2]],"batl":[[0,10.5,10.68]],"ltp":8.6,"tv":5441.46,"id":9345630},{"trd":[[1.11,17.68]],"batb":[[0,1.11,135.67]],"ltp":1.11,"tv":64133.25,"id":9028621}],"tv":69574.71}]}
{"op":"mcm","clk":"4226745331","pt":1631451079811,"mc":[{"id":"1.187552454","rc":[{"trd":[[1.12,805.03]],"batl":[[0,1.12,878.7]],"ltp":1.12,"tv":64533.25,"id":9028621}],"tv":69974.71}]}
{"op":"mcm","clk":"4226745580","pt":1631451081593,"mc":[{"id":"1.187552454","rc":[{"trd":[[1.12,805.7]],"batb":[[1,1.1,116.94]],"batl":[[0,1.12,52.02],[1,1.13,120.5]],"ltp":1.12,"tv":64533.91,"id":9028621}],"tv":69975.38}]}
{"op":"mcm","clk":"4226745940","pt":1631451084286,"mc":[{"id":"1.187552454","rc":[{"batl":[[0,1.12,68.01]],"ltp":1.12,"tv":64533.91,"id":9028621}]}]}
{"op":"mcm","clk":"4226746067","pt":1631451085198,"mc":[{"id":"1.187552454","rc":[{"batb":[[1,1.1,137.94]],"ltp":1.12,"tv":64533.91,"id":9028621}]}]}
{"op":"mcm","clk":"4226746243","pt":1631451086410,"mc":[{"id":"1.187552454","rc":[{"batb":[[0,9,7.5],[1,7.6,2],[2,6.8,2]],"batl":[[0,12,18.09],[1,12.5,2],[2,990,0.01]],"ltp":8.6,"tv":5441.46,"id":9345630},{"trd":[[1.12,834.62]],"batb":[[0,1.09,149.77],[1,1.07,785.87],[2,1.02,5]],"batl":[[0,1.12,15.99],[1,1.13,60]],"ltp":1.12,"tv":64562.83,"id":9028621}],"tv":70004.3}]}
{"op":"mcm","clk":"4226746403","pt":1631451087418,"mc":[{"id":"1.187552454","rc":[{"batb":[[0,7.6,2],[1,6.8,2],[2,6.2,5.62]],"batl":[[0,12.5,2],[1,990,0.01],[2,990,0]],"ltp":8.6,"tv":5441.46,"id":9345630},{"batl":[[1,1.14,631.83],[2,1.15,88.5]],"ltp":1.12,"tv":64562.83,"id":9028621}]}]}
{"op":"mcm","clk":"4226746529","pt":1631451088387,"mc":[{"id":"1.187552454","rc":[{"trd":[[1.12,866.59]],"batb":[[0,1.12,43.16],[1,1.09,149.77],[2,1.07,785.87]],"batl":[[0,1.14,631.83],[1,1.15,88.5],[2,1.16,83.22]],"ltp":1.12,"tv":64594.81,"id":9028621}],"tv":70036.27}]}
{"op":"mcm","clk":"4226746679","pt":1631451089495,"mc":[{"id":"1.187552454","rc":[{"batb":[[1,1.09,740.23],[2,1.08,1349.59]],"batl":[[1,1.15,1013.5],[2,1.16,977.54]],"ltp":1.12,"tv":64594.81,"id":9028621}]}]}
{"op":"mcm","clk":"4226746837","pt":1631451090917,"mc":[{"id":"1.187552454","rc":[{"batb":[[0,1.09,740.23],[1,1.08,1349.59],[2,1.07,785.87]],"ltp":1.12,"tv":64594.81,"id":9028621}]}]}
{"op":"mcm","clk":"4226747177","pt":1631451093512,"mc":[{"id":"1.187552454","rc":[{"batb":[[0,10.5,182.14],[1,10,176.78],[2,9.8,176.78]],"ltp":8.6,"tv":5441.46,"id":9345630},{"batl":[[0,1.1,11498.12],[1,1.14,631.83],[2,1.15,1013.5]],"ltp":1.12,"tv":64594.81,"id":9028621}]}]}
{"op":"mcm","clk":"4226747254","pt":1631451093990,"mc":[{"id":"1.187552454","rc":[{"batb":[[0,10.5,9.11],[1,10,8.84],[2,9.8,8.84]],"ltp":8.6,"tv":5441.46,"id":9345630},{"batl":[[0,1.1,11461.74],[1,1.12,8.54],[2,1.14,631.83]],"ltp":1.12,"tv":64594.81,"id":9028621}]}]}
{"op":"mcm","clk":"4226747567","pt":1631451096212,"mc":[{"id":"1.187552454","rc":[{"trd":[[11,2]],"ltp":11.0,"tv":5443.46,"id":9345630},{"trd":[[1.1,275.68]],"batl":[[0,1.1,11313.9]],"ltp":1.1,"tv":64870.49,"id":9028621}],"tv":70313.95}]}
{"op":"mcm","clk":"4226747704","pt":1631451097220,"mc":[{"id":"1.187552454","rc":[{"trd":[[11,6.65]],"ltp":11.0,"tv":5448.11,"id":9345630},{"trd":[[1.1,322.23]],"batb":[[1,1.08,1503.15]],"batl":[[0,1.1,11267.35]],"ltp":1.1,"tv":64917.04,"id":9028621}],"tv":70365.16}]}
{"op":"mcm","clk":"4226747841","pt":1631451098435,"mc":[{"id":"1.187552454","rc":[{"trd":[[1.09,15.3]],"batb":[[0,1.09,732.58]],"ltp":1.09,"tv":64932.34,"id":9028621}],"tv":70380.46}]}
{"op":"mcm","clk":"4226747929","pt":1631451099026,"mc":[{"id":"1.187552454","rc":[{"batl":[[1,1.14,631.83],[2,1.15,1013.5]],"ltp":1.09,"tv":64932.34,"id":9028621}]}]}
{"op":"mcm","clk":"4226749002","pt":1631451106205,"mc":[{"id":"1.187552454","rc":[{"trd":[[1.1,322.75]],"batl":[[0,1.1,11267.09]],"ltp":1.1,"tv":64932.86,"id":9028621}],"tv":70380.97}]}
{"op":"mcm","clk":"4226749745","pt":1631451112501,"mc":[{"id":"1.187552454","rc":[{"trd":[[11,6.75]],"ltp":11.0,"tv":5448.21,"id":9345630},{"trd":[[1.09,85.38],[1.1,323.74]],"batb":[[0,1.09,697.54]],"batl":[[0,1.1,11266.1]],"ltp":1.1,"tv":65003.93,"id":9028621}],"tv":70452.15}]}
{"op":"mcm","clk":"4226750206","pt":1631451116313,"mc":[{"id":"1.187552454","rc":[{"trd":[[1.1,556.66]],"batl":[[0,1.1,11149.64],[2,1.15,88.5]],"ltp":1.1,"tv":65236.85,"id":9028621}],"tv":70685.07}]}
{"op":"mcm","clk":"4226750575","pt":1631451119546,"mc":[{"id":"1.187552454","rc":[{"batb":[[0,10.5,20.74],[1,10,25.45],[2,9.8,20.12]],"batl":[[0,12.5,4],[1,14,75.13],[2,14.5,72.92]],"ltp":11.0,"tv":5448.21,"id":9345630},{"batb":[[0,1.09,719.54],[1,1.08,1526.15],[2,1.06,15.05]],"batl":[[0,1.1,839.58],[1,1.11,1296.57],[2,1.14,645.83]],"ltp":1.1,"tv":65236.85,"id":9028621}]}]}
{"op":"mcm","clk":"4226750691","pt":1631451120425,"mc":[{"id":"1.187552454","rc":[{"batb":[[0,11,5.36],[1,10.5,27.05],[2,10,25.45]],"batl":[[1,14,91.77]],"ltp":11.0,"tv":5448.21,"id":9345630},{"trd":[[1.09,220.48]],"batb":[[0,1.09,651.99]],"batl":[[1,1.11,1356.57]],"ltp":1.09,"tv":65371.95,"id":9028621}],"tv":70820.17}]}
{"op":"mcm","clk":"4226750846","pt":1631451121542,"mc":[{"id":"1.187552454","rc":[{"trd":[[1.09,229.02]],"batb":[[0,1.09,647.72]],"ltp":1.09,"tv":65380.49,"id":9028621}],"tv":70828.71}]}
{"op":"mcm","clk":"4226750967","pt":1631451122327,"mc":[{"id":"1.187552454","rc":[{"batl":[[0,12,2],[1,12.5,4],[2,14,91.77]],"ltp":11.0,"tv":5448.21,"id":9345630}]}]}
{"op":"mcm","clk":"4226751130","pt":1631451123495,"mc":[{"id":"1.187552454","rc":[{"batb":[[0,10.5,6.31],[1,9.6,2],[2,7.6,2]],"batl":[[0,14,16.64],[1,15,3.55],[2,990,0.01]],"ltp":11.0,"tv":5448.21,"id":9345630},{"trd":[[1.1,575.82]],"batb":[[0,1.08,23],[1,1.06,867.8],[2,1.04,7.67]],"batl":[[0,1.11,60],[1,1.14,645.83],[2,1.15,97.5]],"ltp":1.1,"tv":65399.65,"id":9028621}],"tv":70847.87}]}
{"op":"mcm","clk":"4226751272","pt":1631451124513,"mc":[{"id":"1.187552454","rc":[{"batb":[[0,7.6,2],[1,6.8,2],[2,6.2,5.62]],"batl":[[0,15,3.55],[1,990,0.01],[2,990,0]],"ltp":11.0,"tv":5448.21,"id":9345630},{"batb":[[1,1.06,852.75],[2,1.03,229.62]],"batl":[[0,1.14,631.83],[1,1.15,88.5],[2,1.16,83.22]],"ltp":1.1,"tv":65399.65,"id":9028621}]}]}
{"op":"mcm","clk":"4226751536","pt":1631451126421,"mc":[{"id":"1.187552454","rc":[{"batb":[[0,8.6,2.04],[1,7.6,2],[2,6.8,2]],"ltp":11.0,"tv":5448.21,"id":9345630},{"batb":[[1,1.07,1668.19],[2,1.06,852.75]],"batl":[[0,1.12,747.09],[1,1.13,1257.46],[2,1.14,747.58]],"ltp":1.1,"tv":65399.65,"id":9028621}]}]}
{"op":"mcm","clk":"4226751589","pt":1631451126834,"mc":[{"id":"1.187552454","rc":[{"batl":[[0,14,2],[1,15,3.55],[2,990,0.01]],"ltp":11.0,"tv":5448.21,"id":9345630},{"batb":[[0,1.08,315.77],[1,1.07,1704.19]],"ltp":1.1,"tv":65399.65,"id":9028621}]}]}
{"op":"mcm","clk":"4226751757","pt":1631451128041,"mc":[{"id":"1.187552454","rc":[{"batl":[[1,15,5.55],[2,1000,0.32]],"ltp":11.0,"tv":5448.21,"id":9345630}]}]}
{"op":"mcm","clk":"4226751910","pt":1631451129213,"mc":[{"id":"1.187552454","rc":[{"batb":[[0,9.2,2.02],[1,8.6,2.04],[2,7.6,2]],"ltp":11.0,"tv":5448.21,"id":9345630},{"batl":[[0,1.12,898.3]],"ltp":1.1,"tv":65399.65,"id":9028621}]}]}
{"op":"mcm","clk":"4226751995","pt":1631451129945,"mc":[{"id":"1.187552454","rc":[{"batl":[[0,13.5,2],[1,14,2],[2,15,5.55]],"ltp":11.0,"tv":5448.21,"id":9345630}]}]}
{"op":"mcm","clk":"4226752113","pt":1631451130952,"mc":[{"id":"1.187552454","rc":[{"trd":[[13.5,9.23]],"batl":[[0,14,2],[1,15,5.55],[2,1000,0.32]],"ltp":13.5,"tv":5457.44,"id":9345630},{"trd":[[1.08,65.34]],"batb":[[0,1.08,250.43]],"ltp":1.08,"tv":65464.99,"id":9028621}],"tv":70922.44}]}
{"op":"mcm","clk":"4226752218","pt":1631451131638,"mc":[{"id":"1.187552454","rc":[{"batb":[[0,1.07,1704.19],[1,1.06,852.75],[2,1.03,229.62]],"ltp":1.08,"tv":65464.99,"id":9028621}]}]}
{"op":"mcm","clk":"4226752568","pt":1631451134557,"mc":[{"id":"1.187552454","rc":[{"batb":[[0,1.08,28],[1,1.07,1999.7],[2,1.06,852.75]],"ltp":1.08,"tv":65464.99,"id":9028621}]}]}
{"op":"mcm","clk":"4226752690","pt":1631451135446,"mc":[{"id":"1.187552454","rc":[{"trd":[[1.08,67.04]],"batb":[[0,1.08,27.15],[2,1.06,891.75]],"ltp":1.08,"tv":65466.69,"id":9028621}],"tv":70924.14}]}
{"op":"mcm","clk":"4226752779","pt":1631451136143,"mc":[{"id":"1.187552454","rc":[{"trd":[[1.08,87.04]],"batb":[[0,1.08,17.15]],"ltp":1.08,"tv":65486.69,"id":9028621}],"tv":70944.14}]}
{"op":"mcm","clk":"4226752937","pt":1631451137425,"mc":[{"id":"1.187552454","rc":[{"trd":[[13.5,10.6],[14,4],[15,7.71]],"batl":[[0,1000,0.32],[1,15,0],[2,1000,0]],"ltp":15.0,"tv":5470.52,"id":9345630},{"trd":[[1.08,104.19]],"batb":[[0,1.07,1999.7],[1,1.06,891.75],[2,1.03,229.62]],"ltp":1.08,"tv":65503.84,"id":9028621}],"tv":70974.37}]}
{"op":"mcm","clk":"4226753195","pt":1631451139555,"mc":[{"id":"1.187552454","rc":[{"batb":[[0,1.07,36]],"batl":[[2,1.14,155.57]],"ltp":1.08,"tv":65503.84,"id":9028621}]}]}
{"op":"mcm","clk":"4226753316","pt":1631451140566,"mc":[{"id":"1.187552454","rc":[{"batl":[[0,11.5,186.11],[1,15.5,2],[2,1000,0.32]],"ltp":15.0,"tv":5470.52,"id":9345630},{"batb":[[0,1.11,39.28],[1,1.07,36],[2,1.06,891.75]],"ltp":1.08,"tv":65503.84,"id":9028621}]}]}
{"op":"mcm","clk":"4226753418","pt":1631451141529,"mc":[{"id":"1.187552454","rc":[{"trd":[[9.2,10.56]],"batb":[[0,8.6,2.04],[1,7.6,2],[2,6.8,2]],"batl":[[0,11.5,167.31]],"ltp":9.2,"tv":5481.08,"id":9345630},{"trd":[[1.12,920.12]],"batb":[[0,1.1,1910.15],[2,1.06,39]],"batl":[[0,1.12,844.77]],"ltp":1.12,"tv":65557.37,"id":9028621}],"tv":71038.46}]}
{"op":"mcm","clk":"4226753530","pt":1631451142427,"mc":[{"id":"1.187552454","rc":[{"batl":[[0,9.4,2],[1,11.5,40.91],[2,15.5,2]],"ltp":9.2,"tv":5481.08,"id":9345630},{"batb":[[0,1.1,1919.15],[1,1.08,2589.7],[2,1.07,50.91]],"ltp":1.12,"tv":65557.37,"id":9028621}]}]}
{"op":"mcm","clk":"4226753644","pt":1631451143544,"mc":[{"id":"1.187552454","rc":[{"trd":[[9.4,2]],"batb":[[0,9,7.5],[1,8.6,2.04],[2,7.6,2]],"batl":[[0,11.5,40.91],[1,12,18.09]],"ltp":9.4,"tv":5483.08,"id":9345630},{"trd":[[1.1,1725.98],[1.11,34.61]],"batb":[[0,1.1,1344.07],[1,1.09,200],[2,1.08,2589.7]],"batl":[[1,1.13,1090.81]],"ltp":1.1,"tv":66724.47,"id":9028621}],"tv":72207.56}]}
{"op":"mcm","clk":"4226753753","pt":1631451144562,"mc":[{"id":"1.187552454","rc":[{"batb":[[0,9.2,6.05],[1,9,7.5],[2,8.6,2.04]],"batl":[[0,11,12.25],[1,11.5,40.91],[2,12,18.09]],"ltp":9.4,"tv":5483.08,"id":9345630},{"batb":[[0,1.1,1412.96]],"ltp":1.1,"tv":66724.47,"id":9028621}]}]}
{"op":"mcm","clk":"4226753856","pt":1631451145460,"mc":[{"id":"1.187552454","rc":[{"trd":[[1.12,928.12]],"batb":[[0,1.11,23],[1,1.1,1438.96],[2,1.09,200]],"batl":[[0,1.12,689.56]],"ltp":1.12,"tv":66732.47,"id":9028621}],"tv":72215.56}]}
{"op":"mcm","clk":"4226754007","pt":1631451146573,"mc":[{"id":"1.187552454","rc":[{"batl":[[0,10.5,2]],"ltp":9.4,"tv":5483.08,"id":9345630},{"batb":[[1,1.1,2003.94]],"batl":[[0,1.12,971.75]],"ltp":1.12,"tv":66732.47,"id":9028621}]}]}
{"op":"mcm","clk":"4226754107","pt":1631451147361,"mc":[{"id":"1.187552454","rc":[{"batb":[[1,1.1,2183.94]],"ltp":1.12,"tv":66732.47,"id":9028621}]}]}
{"op":"mcm","clk":"4226754381","pt":1631451149440,"mc":[{"id":"1.187552454","rc":[{"batl":[[0,10.5,14.25]],"ltp":9.4,"tv":5483.08,"id":9345630},{"batb":[[1,1.1,2373.53]],"ltp":1.12,"tv":66732.47,"id":9028621}]}]}
{"op":"mcm","clk":"4226755106","pt":1631451154586,"mc":[{"id":"1.187552454","rc":[{"batl":[[0,1.12,917.56]],"ltp":1.12,"tv":66732.47,"id":9028621}]}]}
{"op":"mcm","clk":"4226755203","pt":1631451155385,"mc":[{"id":"1.187552454","rc":[{"batl":[[2,15.5,2]],"ltp":9.4,"tv":5483.08,"id":9345630},{"batl":[[0,1.12,872.09]],"ltp":1.12,"tv":66732.47,"id":9028621}]}]}
{"op":"mcm","clk":"4226755479","pt":1631451157466,"mc":[{"id":"1.187552454","rc":[{"batl":[[1,1.13,1148.49]],"ltp":1.12,"tv":66732.47,"id":9028621}]}]}
{"op":"mcm","clk":"4226755607","pt":1631451158368,"mc":[{"id":"1.187552454","rc":[{"batl":[[1,11.5,59.42],[2,1000,0.32]],"ltp":9.4,"tv":5483.08,"id":9345630},{"batb":[[1,1.1,2157.94]],"batl":[[1,1.13,1193.56]],"ltp":1.12,"tv":66732.47,"id":9028621}]}]}
{"op":"mcm","clk":"4226755909","pt":1631451160405,"mc":[{"id":"1.187552454","rc":[{"trd":[[10.5,14.96]],"batl":[[0,11.5,59.42],[1,1000,0.32],[2,1000,0]],"ltp":10.5,"tv":5498.05,"id":9345630}],"tv":72230.52}]}
{"op":"mcm","clk":"4226756024","pt":1631451161372,"mc":[{"id":"1.187552454","rc":[{"batb":[[0,9.4,5.92],[1,9.2,6.05],[2,9,7.5]],"ltp":10.5,"tv":5498.05,"id":9345630}]}]}
{"op":"mcm","clk":"4226756332","pt":1631451163517,"mc":[{"id":"1.187552454","rc":[{"trd":[[9.2,25.15],[9.4,13.84]],"batb":[[0,9,7.5],[1,6.8,2],[2,6.2,3.62]],"batl":[[0,11.5,18.51]],"ltp":9.2,"tv":5524.48,"id":9345630},{"trd":[[1.12,948.55]],"batb":[[0,1.1,77.89],[1,1.09,200],[2,1.07,14.91]],"batl":[[0,1.13,60],[1,1.14,39.82],[2,1.15,88.5]],"ltp":1.12,"tv":66752.9,"id":9028621}],"tv":72277.38}]}
{"op":"mcm","clk":"4226756471","pt":1631451164519,"mc":[{"id":"1.187552454","rc":[{"batb":[[0,6.8,2],[1,6.2,3.62],[2,5.5,4.49]],"batl":[[0,1000,0.32],[1,1000,0]],"ltp":9.2,"tv":5524.48,"id":9345630},{"batb":[[0,1.06,852.75],[1,1.03,229.62],[2,1.02,5]],"batl":[[0,1.14,40.21],[1,1.15,88.5],[2,1.16,83.22]],"ltp":1.12,"tv":66752.9,"id":9028621}]}]}
{"op":"mcm","clk":"4226756518","pt":1631451164782,"mc":[{"id":"1.187552454","rc":[{"batb":[[1,2.32,102.49],[2,1.01,30]],"ltp":9.2,"tv":5524.48,"id":9345630},{"batl":[[1,1.17,71.5],[2,1.25,14.83]],"ltp":1.12,"tv":66752.9,"id":9028621}]}]}
{"op":"mcm","clk":"4226756738","pt":1631451166478,"mc":[{"id":"1.187552454","rc":[{"trd":[[1.11,35.4]],"batb":[[0,1.11,141.38],[1,1.08,1945.52],[2,1.06,852.75]],"batl":[[0,1.14,39.82],[1,1.16,1369.74],[2,1.17,509.33]],"ltp":1.11,"tv":66753.69,"id":9028621}],"tv":72278.17}]}
{"op":"mcm","clk":"4226756813","pt":1631451167077,"mc":[{"id":"1.187552454","rc":[{"batb":[[1,1.06,852.75],[2,1.03,229.62]],"batl":[[1,1.17,71.5],[2,1.25,14.83]],"ltp":1.11,"tv":66753.69,"id":9028621}]}]}
{"op":"mcm","clk":"4226756960","pt":1631451168315,"mc":[{"id":"1.187552454","rc":[{"batl":[[0,18,3],[1,1000,0.32]],"ltp":9.2,"tv":5524.48,"id":9345630},{"batb":[[0,1.06,891.75],[1,1.05,34]],"batl":[[0,1.14,40.49]],"ltp":1.11,"tv":66753.69,"id":9028621}]}]}
{"op":"mcm","clk":"4226757109","pt":1631451169581,"mc":[{"id":"1.187552454","rc":[{"batb":[[0,9.2,22.02],[1,6.8,2],[2,2.32,102.49]],"ltp":9.2,"tv":5524.48,"id":9345630},{"batb":[[0,1.07,98.41],[1,1.06,891.75],[2,1.05,34]],"batl":[[0,1.12,21.63],[1,1.14,39.82],[2,1.17,71.5]],"ltp":1.11,"tv":66753.69,"id":9028621}]}]}
{"op":"mcm","clk":"4226757231","pt":1631451170384,"mc":[{"id":"1.187552454","rc":[{"batb":[[0,7.6,2.14],[1,7.4,10],[2,6.8,2]],"batl":[[0,11.5,1.65],[1,18,3],[2,1000,0.32]],"ltp":9.2,"tv":5524.48,"id":9345630},{"trd":[[1.11,36.74]],"batb":[[0,1.11,1304.87],[1,1.1,680.91],[2,1.07,98.41]],"batl":[[0,1.13,1308.69],[1,1.14,644.23]],"ltp":1.11,"tv":66755.03,"id":9028621}],"tv":72279.51}]}
{"op":"mcm","clk":"4226757281","pt":1631451170693,"mc":[{"id":"1.187552454","rc":[{"batb":[[1,6.8,2],[2,2.32,102.49]],"ltp":9.2,"tv":5524.48,"id":9345630}]}]}
{"op":"mcm","clk":"4226757472","pt":1631451172090,"mc":[{"id":"1.187552454","rc":[{"batl":[[1,15.5,2],[2,18,3]],"ltp":9.2,"tv":5524.48,"id":9345630},{"batb":[[2,1.07,128.41]],"batl":[[2,1.15,115.7]],"ltp":1.11,"tv":66755.03,"id":9028621}]}]}
{"op":"mcm","clk":"4226757758","pt":1631451174422,"mc":[{"id":"1.187552454","rc":[{"batl":[[0,15.5,2],[1,18,3],[2,1000,0.32]],"ltp":9.2,"tv":5524.48,"id":9345630},{"batb":[[0,1.08,21.45],[1,1.07,128.41],[2,1.06,891.75]],"batl":[[0,1.14,39.82],[1,1.15,115.7],[2,1.16,122.97]],"ltp":1.11,"tv":66755.03,"id":9028621}]}]}
{"op":"mcm","clk":"4226757860","pt":1631451175316,"mc":[{"id":"1.187552454","rc":[{"batb":[[0,6.8,2],[1,2.32,102.49],[2,1.01,30]],"ltp":9.2,"tv":5524.48,"id":9345630},{"trd":[[1.08,147.09]],"batb":[[0,1.07,128.41],[1,1.06,891.75],[2,1.05,34]],"batl":[[0,1.08,105.87],[1,1.14,39.82],[2,1.17,71.5]],"ltp":1.08,"tv":66797.93,"id":9028621}],"tv":72322.41}]}
{"op":"mcm","clk":"4226757919","pt":1631451175798,"mc":[{"id":"1.187552454","rc":[{"trd":[[1.08,197.07]],"batl":[[0,1.08,80.88]],"ltp":1.08,"tv":66847.9,"id":9028621}],"tv":72372.39}]}
{"op":"mcm","clk":"4226758116","pt":1631451177293,"mc":[{"id":"1.187552454","rc":[{"trd":[[1.08,358.83]],"batb":[[0,1.08,1864.64],[1,1.07,128.41],[2,1.06,891.75]],"batl":[[0,1.14,39.82],[1,1.16,1801.43],[2,1.17,517.32]],"ltp":1.08,"tv":67009.66,"id":9028621}],"tv":72534.15}]}
{"op":"mcm","clk":"4226758234","pt":1631451178174,"mc":[{"id":"1.187552454","rc":[{"batl":[[1,1.16,1666.7],[2,1.17,71.5]],"ltp":1.08,"tv":67009.66,"id":9028621}]}]}
{"op":"mcm","clk":"4226758451","pt":1631451180102,"mc":[{"id":"1.187552454","rc":[{"batb":[[0,1.09,76.54],[1,1.08,1864.64],[2,1.07,128.41]],"ltp":1.08,"tv":67009.66,"id":9028621}]}]}
{"op":"mcm","clk":"4226758698","pt":1631451181928,"mc":[{"id":"1.187552454","rc":[{"batb":[[1,1.08,1945.52]],"batl":[[1,1.15,287.35],[2,1.16,1666.7]],"ltp":1.08,"tv":67009.66,"id":9028621}]}]}
{"op":"mcm","clk":"4226759159","pt":1631451185505,"mc":[{"id":"1.187552454","rc":[{"batl":[[1,1000,0.32],[2,1000,0]],"ltp":9.2,"tv":5524.48,"id":9345630}]}]}
{"op":"mcm","clk":"4226759513","pt":1631451188414,"mc":[{"id":"1.187552454","rc":[{"batb":[[0,9.6,10.59],[1,6.8,2],[2,2.32,102.49]],"ltp":9.2,"tv":5524.48,"id":9345630},{"trd":[[1.09,246.1]],"batb":[[0,1.09,68]],"batl":[[1,1.16,558.22],[2,1.17,71.5]],"ltp":1.09,"tv":67026.74,"id":9028621}],"tv":72551.23}]}
{"op":"mcm","clk":"4226759659","pt":1631451189523,"mc":[{"id":"1.187552454","rc":[{"trd":[[9.6,0.01]],"batb":[[0,9.6,10.58]],"ltp":9.6,"tv":5524.49,"id":9345630},{"trd":[[1.12,948.65]],"batb":[[0,1.11,94.8],[1,1.09,68],[2,1.08,1945.52]],"ltp":1.12,"tv":67026.84,"id":9028621}],"tv":72551.34}]}
{"op":"mcm","clk":"4226759779","pt":1631451190419,"mc":[{"id":"1.187552454","rc":[{"batb":[[0,10,6.24],[1,9.6,86.13],[2,6.8,2]],"ltp":9.6,"tv":5524.49,"id":9345630},{"trd":[[1.11,226.34]],"batb":[[0,1.08,1945.52],[1,1.07,30],[2,1.02,5]],"batl":[[0,1.11,71.7],[1,1.13,19.5],[2,1.14,39.82]],"ltp":1.11,"tv":67216.44,"id":9028621}],"tv":72740.94}]}
{"op":"mcm","clk":"4226759912","pt":1631451191422,"mc":[{"id":"1.187552454","rc":[{"batb":[[0,10,8.24],[1,9.6,25.69]],"ltp":9.6,"tv":5524.49,"id":9345630},{"trd":[[1.1,1783.82]],"batb":[[2,1.05,15.19]],"batl":[[0,1.1,1200.27],[1,1.11,746.52],[2,1.12,9]],"ltp":1.1,"tv":67274.28,"id":9028621}],"tv":72798.78}]}
{"op":"mcm","clk":"4226760045","pt":1631451192445,"mc":[{"id":"1.187552454","rc":[{"batb":[[0,10,14.9],[1,9.8,22.39],[2,9.6,27.69]],"batl":[[0,12,2],[1,14.5,10],[2,15,16.03]],"ltp":9.6,"tv":5524.49,"id":9345630},{"batl":[[1,1.11,768.52],[2,1.12,208.1]],"ltp":1.1,"tv":67274.28,"id":9028621}]}]}
{"op":"mcm","clk":"4226760098","pt":1631451192755,"mc":[{"id":"1.187552454","rc":[{"batb":[[1,9.8,2]],"ltp":9.6,"tv":5524.49,"id":9345630},{"batl":[[2,1.12,9]],"ltp":1.1,"tv":67274.28,"id":9028621}]}]}
{"op":"mcm","clk":"4226760247","pt":1631451193720,"mc":[{"id":"1.187552454","rc":[{"batl":[[1,13,2],[2,14.5,10]],"ltp":9.6,"tv":5524.49,"id":9345630},{"trd":[[1.09,263.18]],"batb":[[0,1.09,15.46],[1,1.08,2114.96],[2,1.07,256.77]],"batl":[[1,1.11,828.52]],"ltp":1.09,"tv":67291.36,"id":9028621}],"tv":72815.86}]}
{"op":"mcm","clk":"4226760426","pt":1631451195423,"mc":[{"id":"1.187552454","rc":[{"batl":[[2,14.5,41.68]],"ltp":9.6,"tv":5524.49,"id":9345630},{"batl":[[0,1.1,1421.54]],"ltp":1.09,"tv":67291.36,"id":9028621}]}]}
{"op":"mcm","clk":"4226760514","pt":1631451196107,"mc":[{"id":"1.187552454","rc":[{"trd":[[12,4]],"batb":[[0,12,3.1],[1,10.5,20.39],[2,10,14.9]],"batl":[[0,13,2],[1,15,16.03],[2,15.5,2]],"ltp":12.0,"tv":5528.49,"id":9345630},{"batl":[[0,1.1,1254.35]],"ltp":1.09,"tv":67291.36,"id":9028621}],"tv":72819.86}]}
{"op":"mcm","clk":"4226760690","pt":1631451197435,"mc":[{"id":"1.187552454","rc":[{"batl":[[1,13.5,2],[2,15.5,4]],"ltp":12.0,"tv":5528.49,"id":9345630},{"batb":[[1,1.08,2285.52],[2,1.07,441.84]],"batl":[[2,1.12,105.96]],"ltp":1.09,"tv":67291.36,"id":9028621}]}]}
{"op":"mcm","clk":"4226760816","pt":1631451198335,"mc":[{"id":"1.187552454","rc":[{"trd":[[1.1,1806.78]],"batl":[[0,1.1,1242.87]],"ltp":1.1,"tv":67314.33,"id":9028621}],"tv":72842.82}]}
{"op":"mcm","clk":"4226760909","pt":1631451199190,"mc":[{"id":"1.187552454","rc":[{"batl":[[0,12.5,10],[1,13,2],[2,13.5,2]],"ltp":12.0,"tv":5528.49,"id":9345630},{"trd":[[1.09,294.1]],"batb":[[0,1.08,2285.52],[1,1.07,441.84],[2,1.06,211.08]],"batl":[[0,1.09,30.16],[1,1.1,1242.87],[2,1.11,828.52]],"ltp":1.09,"tv":67345.25,"id":9028621}],"tv":72873.74}]}
{"op":"mcm","clk":"4226761060","pt":1631451200244,"mc":[{"id":"1.187552454","rc":[{"trd":[[1.09,354.43]],"batb":[[0,1.09,74.03],[1,1.08,2285.52],[2,1.07,441.84]],"batl":[[0,1.1,1242.87],[1,1.11,828.52],[2,1.12,105.96]],"ltp":1.09,"tv":67405.58,"id":9028621}],"tv":72934.07}]}
{"op":"mcm","clk":"4226761153","pt":1631451201040,"mc":[{"id":"1.187552454","rc":[{"batb":[[2,10,8.24]],"ltp":12.0,"tv":5528.49,"id":9345630}]}]}
{"op":"mcm","clk":"4226761296","pt":1631451202059,"mc":[{"id":"1.187552454","rc":[{"batb":[[1,1.08,4735.07]],"ltp":1.09,"tv":67405.58,"id":9028621}]}]}
{"op":"mcm","clk":"4226761601","pt":1631451204452,"mc":[{"id":"1.187552454","rc":[{"batb":[[1,10.5,26.7]],"ltp":12.0,"tv":5528.49,"id":9345630}]}]}
{"op":"mcm","clk":"4226761846","pt":1631451206211,"mc":[{"id":"1.187552454","rc":[{"trd":[[1.1,1809.88]],"batb":[[1,1.08,2285.52],[2,1.07,411.84]],"batl":[[0,1.1,1241.32]],"ltp":1.1,"tv":67408.67,"id":9028621}],"tv":72937.17}]}
{"op":"mcm","clk":"4226762013","pt":1631451207426,"mc":[{"id":"1.187552454","rc":[{"trd":[[12,8]],"batb":[[0,12,1.1]],"ltp":12.0,"tv":5532.49,"id":9345630}],"tv":72941.17}]}
{"op":"mcm","clk":"4226762145","pt":1631451208443,"mc":[{"id":"1.187552454","rc":[{"batb":[[1,10.5,6.31],[2,9.2,2]],"batl":[[0,14.5,16.32],[1,15.5,2],[2,50,35.53]],"ltp":12.0,"tv":5532.49,"id":9345630},{"trd":[[1.1,1826.8]],"batb":[[1,1.08,28]],"batl":[[0,1.11,60],[1,1.12,96.96],[2,1.14,39.82]],"ltp":1.1,"tv":67425.6,"id":9028621}],"tv":72958.09}]}
{"op":"mcm","clk":"4226762289","pt":1631451209554,"mc":[{"id":"1.187552454","rc":[{"batb":[[1,9.2,2],[2,6.8,2]],"batl":[[0,15.5,2],[1,50,35.53],[2,1000,0.32]],"ltp":12.0,"tv":5532.49,"id":9345630},{"batb":[[2,1.07,185.07]],"batl":[[0,1.12,96.96],[1,1.14,39.82],[2,1.16,558.22]],"ltp":1.1,"tv":67425.6,"id":9028621}]}]}
{"op":"mcm","clk":"4226762516","pt":1631451211413,"mc":[{"id":"1.187552454","rc":[{"batb":[[1,10,2],[2,9.2,2]],"ltp":12.0,"tv":5532.49,"id":9345630},{"batl":[[0,1.11,115.5],[1,1.12,96.96],[2,1.14,39.82]],"ltp":1.1,"tv":67425.6,"id":9028621}]}]}
{"op":"mcm","clk":"4226762577","pt":1631451211840,"mc":[{"id":"1.187552454","rc":[{"batb":[[1,9.2,2],[2,6.8,2]],"batl":[[0,14.5,2],[1,15.5,2]],"ltp":12.0,"tv":5532.49,"id":9345630},{"batl":[[0,1.12,96.96],[1,1.14,39.82],[2,1.16,558.22]],"ltp":1.1,"tv":67425.6,"id":9028621}]}]}
{"op":"mcm","clk":"4226762929","pt":1631451214529,"mc":[{"id":"1.187552454","rc":[{"batb":[[0,1.09,907.64],[1,1.08,1132.19]],"batl":[[0,1.1,536.27],[1,1.11,1361.49],[2,1.12,96.96]],"ltp":1.1,"tv":67425.6,"id":9028621}]}]}
{"op":"mcm","clk":"4226763067","pt":1631451215359,"mc":[{"id":"1.187552454","rc":[{"batb":[[1,10,2],[2,9.2,2]],"batl":[[0,13.5,2],[1,14.5,2],[2,15.5,2]],"ltp":12.0,"tv":5532.49,"id":9345630},{"batb":[[1,1.08,1134.25]],"batl":[[1,1.11,1495.49]],"ltp":1.1,"tv":67425.6,"id":9028621}]}]}
{"op":"mcm","clk":"4226763213","pt":1631451216314,"mc":[{"id":"1.187552454","rc":[{"trd":[[1.1,1971.41]],"batb":[[0,1.09,979.01]],"batl":[[0,1.1,463.97],[1,1.11,1607.96]],"ltp":1.1,"tv":67570.2,"id":9028621}],"tv":73102.69}]}
{"op":"mcm","clk":"4226763494","pt":1631451217637,"mc":[{"id":"1.187552454","rc":[{"trd":[[1.1,1974.74]],"batl":[[0,1.1,462.3]],"ltp":1.1,"tv":67573.53,"id":9028621}],"tv":73106.03}]}
{"op":"mcm","clk":"4226763642","pt":1631451218955,"mc":[{"id":"1.187552454","rc":[{"batl":[[0,13,10],[1,13.5,2],[2,14.5,2]],"ltp":12.0,"tv":5532.49,"id":9345630}]}]}
{"op":"mcm","clk":"4226763963","pt":1631451221571,"mc":[{"id":"1.187552454","rc":[{"batb":[[1,9.2,2],[2,6.8,2]],"ltp":12.0,"tv":5532.49,"id":9345630},{"batb":[[0,1.09,145.4],[1,1.08,30.06]],"batl":[[0,1.11,131.97],[1,1.12,96.96],[2,1.13,95.5]],"ltp":1.1,"tv":67573.53,"id":9028621}]}]}
{"op":"mcm","clk":"4226764097","pt":1631451222529,"mc":[{"id":"1.187552454","rc":[{"batl":[[0,14.5,2],[1,15.5,2],[2,1000,0.32]],"ltp":12.0,"tv":5532.49,"id":9345630},{"trd":[[1.09,552.43]],"batb":[[0,1.09,46.4],[1,1.08,28]],"ltp":1.09,"tv":67771.53,"id":9028621}],"tv":73304.03}]}
{"op":"mcm","clk":"4226764135","pt":1631451222851,"mc":[{"id":"1.187552454","rc":[{"batb":[[0,1.08,28],[1,1.07,185.07],[2,1.05,275.54]],"batl":[[0,1.11,19.5],[2,1.14,39.82]],"ltp":1.09,"tv":67771.53,"id":9028621}]}]}
{"op":"mcm","clk":"4226764309","pt":1631451224256,"mc":[{"id":"1.187552454","rc":[{"batb":[[1,1.07,2148.77]],"batl":[[1,1.12,1328.46],[2,1.13,638.83]],"ltp":1.09,"tv":67771.53,"id":9028621}]}]}
{"op":"mcm","clk":"4226764489","pt":1631451225553,"mc":[{"id":"1.187552454","rc":[{"batl":[[0,13.5,2],[1,14.5,2],[2,15.5,2]],"ltp":12.0,"tv":5532.49,"id":9345630},{"batb":[[0,1.08,30.06]],"ltp":1.09,"tv":67771.53,"id":9028621}]}]}
{"op":"mcm","clk":"4226764625","pt":1631451226557,"mc":[{"id":"1.187552454","rc":[{"trd":[[12,8.18]],"batb":[[0,9.2,2.92],[1,6.8,2],[2,2.32,102.49]],"ltp":12.0,"tv":5532.67,"id":9345630},{"trd":[[1.1,1976.69]],"batb":[[0,1.08,28],[1,1.07,2159.77],[2,1.06,226.08]],"batl":[[2,1.13,736.33]],"ltp":1.1,"tv":67773.48,"id":9028621}],"tv":73306.16}]}
{"op":"mcm","clk":"4226764926","pt":1631451228575,"mc":[{"id":"1.187552454","rc":[{"trd":[[12,9.1]],"batb":[[0,9.2,2]],"ltp":12.0,"tv":5533.59,"id":9345630},{"trd":[[1.1,1986.73],[1.11,370.94]],"batb":[[0,1.1,78.96],[1,1.08,28],[2,1.07,2159.77]],"batl":[[0,1.12,1328.46],[1,1.13,736.33],[2,1.14,39.82]],"ltp":1.11,"tv":67928.12,"id":9028621}],"tv":73461.72}]}
{"op":"mcm","clk":"4226765024","pt":1631451229364,"mc":[{"id":"1.187552454","rc":[{"batb":[[1,2.32,102.49],[2,1.01,30]],"ltp":12.0,"tv":5533.59,"id":9345630},{"trd":[[1.1,2036.7]],"batb":[[0,1.1,53.98]],"batl":[[0,1.14,39.82],[1,1.16,439.75],[2,1.23,29.67]],"ltp":1.1,"tv":67978.09,"id":9028621}],"tv":73511.68}]}
{"op":"mcm","clk":"4226765267","pt":1631451231538,"mc":[{"id":"1.187552454","rc":[{"batb":[[0,11.5,170.43],[1,9.2,2],[2,2.32,102.49]],"batl":[[0,14.5,2],[1,15.5,2],[2,20,20.72]],"ltp":12.0,"tv":5533.59,"id":9345630},{"trd":[[1.1,2144.66]],"batb":[[0,1.07,2159.77],[1,1.06,226.08],[2,1.05,275.54]],"ltp":1.1,"tv":68086.05,"id":9028621}],"tv":73619.64}]}
{"op":"mcm","clk":"4226765397","pt":1631451232547,"mc":[{"id":"1.187552454","rc":[{"trd":[[14.5,4],[15.5,4]],"batb":[[0,11.5,20.9],[1,9.2,245.93]],"batl":[[0,20,20.72],[1,1000,0.32],[2,20,0]],"ltp":15.5,"tv":5541.59,"id":9345630},{"batb":[[0,1.07,2253.48]],"batl":[[0,1.08,9],[1,1.09,1989.94],[2,1.13,14.12]],"ltp":1.1,"tv":68086.05,"id":9028621}],"tv":73627.64}]}
{"op":"mcm","clk":"4226765535","pt":1631451233444,"mc":[{"id":"1.187552454","rc":[{"batb":[[0,12,5.45],[1,11.5,20.9],[2,9.2,245.93]],"ltp":15.5,"tv":5541.59,"id":9345630},{"batl":[[2,1.1,153.14]],"ltp":1.1,"tv":68086.05,"id":9028621}]}]}
{"op":"mcm","clk":"4226765720","pt":1631451234589,"mc":[{"id":"1.187552454","rc":[{"batb":[[0,11.5,20.9],[1,11,2],[2,10.5,2]],"batl":[[0,14,2],[1,20,20.72],[2,1000,0.32]],"ltp":15.5,"tv":5541.59,"id":9345630},{"batb":[[0,1.07,2377.37],[1,1.06,471.02]],"batl":[[2,1.1,87.54]],"ltp":1.1,"tv":68086.05,"id":9028621}]}]}
{"op":"mcm","clk":"4226765859","pt":1631451235587,"mc":[{"id":"1.187552454","rc":[{"batl":[[1,15,2],[2,17.5,2]],"ltp":15.5,"tv":5541.59,"id":9345630},{"batb":[[1,1.06,226.08]],"batl":[[2,1.1,27.54]],"ltp":1.1,"tv":68086.05,"id":9028621}]}]}
{"op":"mcm","clk":"4226765971","pt":1631451236589,"mc":[{"id":"1.187552454","rc":[{"batb":[[0,12,10.35],[1,11.5,20.9],[2,11,2]],"ltp":15.5,"tv":5541.59,"id":9345630}]}]}
{"op":"mcm","clk":"4226766078","pt":1631451237175,"mc":[{"id":"1.187552454","rc":[{"batb":[[0,12,5.45]],"ltp":15.5,"tv":5541.59,"id":9345630}]}]}
{"op":"mcm","clk":"4226766251","pt":1631451238350,"mc":[{"id":"1.187552454","rc":[{"batb":[[2,11,4]],"batl":[[2,17,15]],"ltp":15.5,"tv":5541.59,"id":9345630},{"trd":[[1.07,53.66]],"batb":[[0,1.07,2350.54],[1,1.06,471.02],[2,1.05,532.43]],"batl":[[2,1.1,146.65]],"ltp":1.07,"tv":68139.71,"id":9028621}],"tv":73681.3}]}
{"op":"mcm","clk":"4226766513","pt":1631451240372,"mc":[{"id":"1.187552454","rc":[{"batb":[[0,12.5,10.35],[1,12,5.45],[2,11.5,20.9]],"ltp":15.5,"tv":5541.59,"id":9345630}]}]}
{"op":"mcm","clk":"4226766822","pt":1631451242501,"mc":[{"id":"1.187552454","rc":[{"batl":[[1,1.09,2049.94]],"ltp":1.07,"tv":68139.71,"id":9028621}]}]}
{"op":"mcm","clk":"4226766877","pt":1631451242780,"mc":[{"id":"1.187552454","rc":[{"trd":[[1.07,334.44]],"batb":[[0,1.07,2210.15]],"ltp":1.07,"tv":68420.49,"id":9028621}],"tv":73962.08}]}
{"op":"mcm","clk":"4226767108","pt":1631451244464,"mc":[{"id":"1.187552454","rc":[{"trd":[[12.5,9.4],[13.5,11.33]],"batb":[[0,12.5,5.65]],"ltp":12.5,"tv":5551.71,"id":9345630},{"trd":[[1.07,422.46],[1.08,367.83]],"batb":[[0,1.07,2166.14]],"batl":[[0,1.09,2049.94],[1,1.1,146.65],[2,1.12,105.96]],"ltp":1.08,"tv":68517.51,"id":9028621}],"tv":74069.22}]}
{"op":"mcm","clk":"4226767229","pt":1631451245411,"mc":[{"id":"1.187552454","rc":[{"batb":[[0,1.08,14.46],[1,1.07,2166.14],[2,1.06,471.02]],"ltp":1.08,"tv":68517.51,"id":9028621}]}]}
{"op":"mcm","clk":"4226767329","pt":1631451246212,"mc":[{"id":"1.187552454","rc":[{"trd":[[1.08,467.83]],"batb":[[0,1.08,214.46]],"ltp":1.08,"tv":68617.51,"id":9028621}],"tv":74169.22}]}
{"op":"mcm","clk":"4226767502","pt":1631451247586,"mc":[{"id":"1.187552454","rc":[{"batl":[[0,14,5.74]],"ltp":12.5,"tv":5551.71,"id":9345630},{"batl":[[0,1.09,2249.04]],"ltp":1.08,"tv":68617.51,"id":9028621}]}]}
{"op":"mcm","clk":"4226767541","pt":1631451247902,"mc":[{"id":"1.187552454","rc":[{"batl":[[1,17,15],[2,18,2]],"ltp":12.5,"tv":5551.71,"id":9345630},{"batl":[[0,1.09,2148.45]],"ltp":1.08,"tv":68617.51,"id":9028621}]}]}
{"op":"mcm","clk":"4226767708","pt":1631451249174,"mc":[{"id":"1.187552454","rc":[{"trd":[[1.09,559.66]],"batb":[[0,1.08,215.98]],"batl":[[0,1.09,2144.83]],"ltp":1.09,"tv":68624.74,"id":9028621}],"tv":74176.46}]}
{"op":"mcm","clk":"4226767844","pt":1631451250284,"mc":[{"id":"1.187552454","rc":[{"trd":[[12,166.6],[12.5,20.7]],"batb":[[0,11.5,20.9],[1,11,4],[2,10,2]],"ltp":12.0,"tv":5720.52,"id":9345630},{"trd":[[1.09,2173.66]],"batl":[[0,1.09,530.83]],"ltp":1.09,"tv":70238.74,"id":9028621}],"tv":75959.26}]}
{"op":"mcm","clk":"4226767913","pt":1631451250821,"mc":[{"id":"1.187552454","rc":[{"batl":[[1,18,2],[2,20,20.72]],"ltp":12.0,"tv":5720.52,"id":9345630}]}]}
{"op":"mcm","clk":"4226768152","pt":1631451252595,"mc":[{"id":"1.187552454","rc":[{"trd":[[1.08,580.56]],"batb":[[0,1.08,159.61]],"batl":[[0,1.09,541.63]],"ltp":1.08,"tv":70351.48,"id":9028621}],"tv":76072.0}]}
{"op":"mcm","clk":"4226768271","pt":1631451253505,"mc":[{"id":"1.187552454","rc":[{"batb":[[0,12,5.45],[1,11.5,20.9],[2,11,4]],"ltp":12.0,"tv":5720.52,"id":9345630}]}]}
{"op":"mcm","clk":"4226768398","pt":1631451254566,"mc":[{"id":"1.187552454","rc":[{"batb":[[0,12,14.72]],"batl":[[0,14,5.91],[2,21,2]],"ltp":12.0,"tv":5720.52,"id":9345630},{"trd":[[1.09,2206.99]],"batb":[[0,1.08,158.09]],"batl":[[0,1.09,1461.45],[1,1.1,851.04]],"ltp":1.09,"tv":70384.8,"id":9028621}],"tv":76105.33}]}
{"op":"mcm","clk":"4226768487","pt":1631451255254,"mc":[{"id":"1.187552454","rc":[{"batb":[[0,12,5.45]],"ltp":12.0,"tv":5720.52,"id":9345630},{"trd":[[1.08,583.98]],"batb":[[0,1.08,156.38]],"ltp":1.08,"tv":70388.22,"id":9028621}],"tv":76108.74}]}
{"op":"mcm","clk":"4226768616","pt":1631451256075,"mc":[{"id":"1.187552454","rc":[{"trd":[[1.08,589.19]],"batb":[[0,1.08,153.78]],"ltp":1.08,"tv":70393.43,"id":9028621}],"tv":76113.95}]}
{"op":"mcm","clk":"4226768813","pt":1631451257564,"mc":[{"id":"1.187552454","rc":[{"trd":[[1.08,590.19],[1.09,2210.03]],"batb":[[0,1.08,153.28]],"batl":[[0,1.09,1459.93]],"ltp":1.08,"tv":70397.47,"id":9028621}],"tv":76117.99}]}
{"op":"mcm","clk":"4226768890","pt":1631451258073,"mc":[{"id":"1.187552454","rc":[{"trd":[[12.5,21.04]],"batb":[[0,12.5,4.06],[1,12,5.45],[2,11.5,20.9]],"batl":[[0,14,5.74]],"ltp":12.5,"tv":5720.85,"id":9345630},{"trd":[[1.08,666.19]],"batb":[[0,1.08,115.28]],"ltp":1.08,"tv":70473.47,"id":9028621}],"tv":76194.33}]}
{"op":"mcm","clk":"4226769162","pt":1631451260281,"mc":[{"id":"1.187552454","rc":[{"trd":[[1.09,2214.49]],"batl":[[0,1.09,1457.7]],"ltp":1.09,"tv":70477.92,"id":9028621}],"tv":76198.78}]}
{"op":"mcm","clk":"4226769584","pt":1631451263593,"mc":[{"id":"1.187552454","rc":[{"batb":[[0,12,5.45],[1,11,2],[2,10,2]],"batl":[[0,18,2],[1,21,2],[2,1000,0.32]],"ltp":12.5,"tv":5720.85,"id":9345630},{"batb":[[1,1.06,471.02],[2,1.05,532.43]],"batl":[[0,1.09,70.8],[1,1.1,127.65]],"ltp":1.09,"tv":70477.92,"id":9028621}]}]}
{"op":"mcm","clk":"4226769706","pt":1631451264494,"mc":[{"id":"1.187552454","rc":[{"batb":[[0,10,2],[1,2.32,102.49],[2,1.01,30]],"batl":[[0,21,2],[1,1000,0.32],[2,1000,0]],"ltp":12.5,"tv":5720.85,"id":9345630},{"batb":[[1,1.05,532.43],[2,1.03,2409.87]],"batl":[[0,1.09,10.8],[1,1.14,39.82],[2,1.21,14.83]],"ltp":1.09,"tv":70477.92,"id":9028621}]}]}
{"op":"mcm","clk":"4226769948","pt":1631451266512,"mc":[{"id":"1.187552454","rc":[{"batb":[[1,1.06,1188.18],[2,1.05,1429.53]],"batl":[[1,1.11,1841.37],[2,1.14,39.82]],"ltp":1.09,"tv":70477.92,"id":9028621}]}]}
{"op":"mcm","clk":"4226770064","pt":1631451267374,"mc":[{"id":"1.187552454","rc":[{"batl":[[2,1.12,126.21]],"ltp":1.09,"tv":70477.92,"id":9028621}]}]}
{"op":"mcm","clk":"4226770110","pt":1631451267685,"mc":[{"id":"1.187552454","rc":[{"batb":[[0,10,5],[1,9.8,2],[2,2.32,102.49]],"ltp":12.5,"tv":5720.85,"id":9345630}]}]}
{"op":"mcm","clk":"4226770285","pt":1631451269174,"mc":[{"id":"1.187552454","rc":[{"trd":[[1.09,2217.67]],"batb":[[1,1.05,532.43],[2,1.03,2409.87]],"batl":[[0,1.09,9.21],[1,1.1,143.96],[2,1.11,137.5]],"ltp":1.09,"tv":70481.1,"id":9028621}],"tv":76201.96}]}
{"op":"mcm","clk":"4226770452","pt":1631451270568,"mc":[{"id":"1.187552454","rc":[{"batb":[[0,11,2],[1,10,5],[2,9.8,2]],"ltp":12.5,"tv":5720.85,"id":9345630},{"batl":[[1,1.1,312.21]],"ltp":1.09,"tv":70481.1,"id":9028621}]}]}
{"op":"mcm","clk":"4226770493","pt":1631451270883,"mc":[{"id":"1.187552454","rc":[{"batb":[[0,10,5],[1,9.8,2],[2,2.32,102.49]],"ltp":12.5,"tv":5720.85,"id":9345630},{"batl":[[1,1.1,143.96]],"ltp":1.09,"tv":70481.1,"id":9028621}]}]}
{"op":"mcm","clk":"4226770619","pt":1631451272092,"mc":[{"id":"1.187552454","rc":[{"trd":[[1.08,748.57]],"batb":[[0,1.08,74.09],[1,1.07,2057.41],[2,1.05,532.43]],"batl":[[0,1.09,2028.87]],"ltp":1.08,"tv":70563.48,"id":9028621}],"tv":76284.34}]}
{"op":"mcm","clk":"4226770778","pt":1631451273498,"mc":[{"id":"1.187552454","rc":[{"batb":[[0,11,22.73],[1,10,5],[2,9.8,2]],"batl":[[0,17,10],[1,21,2],[2,1000,0.32]],"ltp":12.5,"tv":5720.85,"id":9345630},{"batl":[[0,1.09,2074.92]],"ltp":1.08,"tv":70563.48,"id":9028621}]}]}
{"op":"mcm","clk":"4226770894","pt":1631451274388,"mc":[{"id":"1.187552454","rc":[{"batb":[[0,11,2]],"ltp":12.5,"tv":5720.85,"id":9345630},{"batl":[[1,1.1,295.81]],"ltp":1.08,"tv":70563.48,"id":9028621}]}]}
{"op":"mcm","clk":"4226771023","pt":1631451275506,"mc":[{"id":"1.187552454","rc":[{"batl":[[0,21,2],[1,1000,0.32],[2,1000,0]],"ltp":12.5,"tv":5720.85,"id":9345630},{"batb":[[1,1.05,532.43],[2,1.03,2409.87]],"batl":[[0,1.09,9.21],[1,1.1,298.66]],"ltp":1.08,"tv":70563.48,"id":9028621}]}]}
{"op":"mcm","clk":"4226771056","pt":1631451275803,"mc":[{"id":"1.187552454","rc":[{"batb":[[0,10,5],[1,9.8,2],[2,2.32,102.49]],"ltp":12.5,"tv":5720.85,"id":9345630},{"batl":[[1,1.1,146.81]],"ltp":1.08,"tv":70563.48,"id":9028621}]}]}
{"op":"mcm","clk":"4226771245","pt":1631451277512,"mc":[{"id":"1.187552454","rc":[{"batb":[[0,11.5,22.73],[1,10,5],[2,9.8,2]],"ltp":12.5,"tv":5720.85,"id":9345630}]}]}
{"op":"mcm","clk":"4226771364","pt":1631451278527,"mc":[{"id":"1.187552454","rc":[{"batb":[[0,10,5],[1,9.8,2],[2,2.32,102.49]],"ltp":12.5,"tv":5720.85,"id":9345630},{"batb":[[0,1.08,77.92],[1,1.06,1188.18],[2,1.05,1429.53]],"batl":[[2,1.11,1841.37]],"ltp":1.08,"tv":70563.48,"id":9028621}]}]}
{"op":"mcm","clk":"4226771443","pt":1631451279212,"mc":[{"id":"1.187552454","rc":[{"batb":[[1,2.32,102.49],[2,1.01,30]],"ltp":12.5,"tv":5720.85,"id":9345630}]}]}
{"op":"mcm","clk":"4226771810","pt":1631451282497,"mc":[{"id":"1.187552454","rc":[{"batb":[[0,11,2],[1,10,5],[2,9.8,2]],"ltp":12.5,"tv":5720.85,"id":9345630},{"trd":[[1.09,2235.71]],"batl":[[0,1.1,296.65],[1,1.11,1841.37],[2,1.12,126.21]],"ltp":1.09,"tv":70581.53,"id":9028621}],"tv":76302.39}]}
{"op":"mcm","clk":"4226771850","pt":1631451282808,"mc":[{"id":"1.187552454","rc":[{"batb":[[0,10,5],[1,9.8,2],[2,2.32,102.49]],"ltp":12.5,"tv":5720.85,"id":9345630},{"batl":[[0,1.1,147]],"ltp":1.09,"tv":70581.53,"id":9028621}]}]}
{"op":"mcm","clk":"4226772431","pt":1631451288017,"mc":[{"id":"1.187552454","rc":[{"trd":[[1.08,904.41]],"batb":[[0,1.06,1188.18],[1,1.05,1429.53],[2,1.03,2409.87]],"batl":[[1,1.14,39.82],[2,1.21,14.83]],"ltp":1.08,"tv":70737.37,"id":9028621}],"tv":76458.23}]}
{"op":"mcm","clk":"4226772607","pt":1631451289505,"mc":[{"id":"1.187552454","rc":[{"batb":[[0,14,6.7],[1,10,5],[2,9.8,2]],"batl":[[0,17.5,17.76],[1,21,2],[2,1000,0.32]],"ltp":12.5,"tv":5720.85,"id":9345630},{"batl":[[0,1.08,8.54],[1,1.1,147],[2,1.14,39.82]],"ltp":1.08,"tv":70737.37,"id":9028621}]}]}
{"op":"mcm","clk":"4226772768","pt":1631451290557,"mc":[{"id":"1.187552454","rc":[{"batb":[[0,15,5.23],[1,14,56.68],[2,10,5]],"ltp":12.5,"tv":5720.85,"id":9345630},{"batb":[[2,1.03,964.33]],"batl":[[0,1.07,1396.62],[1,1.08,884.64],[2,1.1,147]],"ltp":1.08,"tv":70737.37,"id":9028621}]}]}
{"op":"mcm","clk":"4226772901","pt":1631451291306,"mc":[{"id":"1.187552454","rc":[{"trd":[[17.5,8]],"batb":[[1,14,16.7]],"batl":[[0,17.5,13.77],[1,18,2],[2,21,2]],"ltp":17.5,"tv":5728.85,"id":9345630},{"batb":[[0,1.06,1221.18],[1,1.05,1469.53]],"batl":[[1,1.08,893.64]],"ltp":1.08,"tv":70737.37,"id":9028621}],"tv":76466.23}]}
{"op":"mcm","clk":"4226773040","pt":1631451292407,"mc":[{"id":"1.187552454","rc":[{"batb":[[2,13,5]],"batl":[[0,17.5,16.77],[2,21,15.41]],"ltp":17.5,"tv":5728.85,"id":9345630},{"batb":[[0,1.06,1292.36],[1,1.05,1737.85]],"batl":[[2,1.09,60.19]],"ltp":1.08,"tv":70737.37,"id":9028621}]}]}
{"op":"mcm","clk":"4226773174","pt":1631451293517,"mc":[{"id":"1.187552454","rc":[{"batl":[[1,1.08,1031.73]],"ltp":1.08,"tv":70737.37,"id":9028621}]}]}
{"op":"mcm","clk":"4226773289","pt":1631451294415,"mc":[{"id":"1.187552454","rc":[{"batb":[[2,11.5,2]],"ltp":17.5,"tv":5728.85,"id":9345630}]}]}
{"op":"mcm","clk":"4226773418","pt":1631451295520,"mc":[{"id":"1.187552454","rc":[{"batb":[[0,15.5,4.07],[1,15,5.23],[2,14,16.7]],"batl":[[0,17.5,20.54]],"ltp":17.5,"tv":5728.85,"id":9345630},{"batb":[[1,1.05,1462.31]],"batl":[[0,1.07,1470.4],[2,1.1,3.04]],"ltp":1.08,"tv":70737.37,"id":9028621}]}]}
{"op":"mcm","clk":"4226773471","pt":1631451295923,"mc":[{"id":"1.187552454","rc":[{"trd":[[17.5,45.59]],"batl":[[0,17.5,1.74]],"ltp":17.5,"tv":5766.45,"id":9345630}],"tv":76503.83}]}
{"op":"mcm","clk":"4226773624","pt":1631451297210,"mc":[{"id":"1.187552454","rc":[{"batb":[[2,1.04,172.21]],"batl":[[1,1.08,1202.17],[2,1.09,139.69]],"ltp":1.08,"tv":70737.37,"id":9028621}]}]}
{"op":"mcm","clk":"4226773734","pt":1631451297895,"mc":[{"id":"1.187552454","rc":[{"batb":[[2,14,21.31]],"ltp":17.5,"tv":5766.45,"id":9345630},{"batl":[[1,1.08,1262.17]],"ltp":1.08,"tv":70737.37,"id":9028621}]}]}
{"op":"mcm","clk":"4226773932","pt":1631451299438,"mc":[{"id":"1.187552454","rc":[{"trd":[[1.07,579.76]],"batb":[[2,1.04,344.43]],"batl":[[0,1.07,1391.75]],"ltp":1.07,"tv":70894.67,"id":9028621}],"tv":76661.12}]}
{"op":"mcm","clk":"4226774159","pt":1631451301035,"mc":[{"id":"1.187552454","rc":[{"trd":[[1.06,845.28]],"batb":[[0,1.06,869.72]],"batl":[[1,1.08,1079.09]],"ltp":1.06,"tv":71739.95,"id":9028621}],"tv":77506.4}]}
{"op":"mcm","clk":"4226774615","pt":1631451304126,"mc":[{"id":"1.187552454","rc":[{"batb":[[0,1.06,1106.04],[1,1.05,1610.41]],"batl":[[0,1.07,1576.54]],"ltp":1.06,"tv":71739.95,"id":9028621}]}]}
{"op":"mcm","clk":"4226774685","pt":1631451304654,"mc":[{"id":"1.187552454","rc":[{"trd":[[1.07,587.33]],"batl":[[0,1.07,1572.75]],"ltp":1.07,"tv":71747.53,"id":9028621}],"tv":77513.98}]}
{"op":"mcm","clk":"4226775133","pt":1631451307552,"mc":[{"id":"1.187552454","rc":[{"batl":[[0,17.5,3.74]],"ltp":17.5,"tv":5766.45,"id":9345630}]}]}
{"op":"mcm","clk":"4226775525","pt":1631451310249,"mc":[{"id":"1.187552454","rc":[{"batb":[[0,14,4.61],[1,13.5,2],[2,12,2]],"batl":[[0,17.5,2],[2,21,13.41]],"ltp":17.5,"tv":5766.45,"id":9345630},{"trd":[[1.07,601.79]],"batb":[[0,1.06,33],[1,1.05,268.32]],"batl":[[0,1.08,386.07],[1,1.09,139.69],[2,1.1,128.3]],"ltp":1.07,"tv":71761.99,"id":9028621}],"tv":77528.44}]}
{"op":"mcm","clk":"4226775687","pt":1631451311556,"mc":[{"id":"1.187552454","rc":[{"batb":[[0,13.5,2],[1,12,2],[2,11.5,2]],"batl":[[0,1000,0.32],[1,18,0],[2,21,0]],"ltp":17.5,"tv":5766.45,"id":9345630},{"batb":[[0,1.04,344.43],[1,1.03,948.84],[2,1.02,3022.35]],"batl":[[0,1.08,317.07]],"ltp":1.07,"tv":71761.99,"id":9028621}]}]}
{"op":"mcm","clk":"4226775771","pt":1631451312180,"mc":[{"id":"1.187552454","rc":[{"batb":[[0,12,2],[1,11.5,2],[2,2.32,102.49]],"ltp":17.5,"tv":5766.45,"id":9345630},{"batl":[[0,1.08,146.63],[2,1.1,2.85]],"ltp":1.07,"tv":71761.99,"id":9028621}]}]}
{"op":"mcm","clk":"4226775946","pt":1631451313439,"mc":[{"id":"1.187552454","rc":[{"batb":[[0,14.5,2],[1,14,2],[2,12,2]],"ltp":17.5,"tv":5766.45,"id":9345630},{"batb":[[0,1.04,2461.19]],"batl":[[1,1.09,1939.81]],"ltp":1.07,"tv":71761.99,"id":9028621}]}]}
{"op":"mcm","clk":"4226776072","pt":1631451314452,"mc":[{"id":"1.187552454","rc":[{"batb":[[0,12,2],[1,11.5,2],[2,2.32,102.49]],"ltp":17.5,"tv":5766.45,"id":9345630},{"batb":[[0,1.07,8.73],[1,1.04,2461.19],[2,1.03,948.84]],"ltp":1.07,"tv":71761.99,"id":9028621}]}]}
{"op":"mcm","clk":"4226776177","pt":1631451315318,"mc":[{"id":"1.187552454","rc":[{"trd":[[15.5,4.6]],"batb":[[0,15.5,6.03],[1,13.5,2],[2,12,4]],"ltp":15.5,"tv":5767.05,"id":9345630},{"trd":[[1.07,610.53]],"batb":[[0,1.04,2461.19],[1,1.03,948.84],[2,1.02,3022.35]],"batl":[[0,1.08,320.82],[2,1.1,130.8]],"ltp":1.07,"tv":71770.72,"id":9028621}],"tv":77537.78}]}
{"op":"mcm","clk":"4226776215","pt":1631451315646,"mc":[{"id":"1.187552454","rc":[{"batb":[[1,12,4],[2,11.5,2]],"ltp":15.5,"tv":5767.05,"id":9345630},{"batl":[[0,1.08,146.63]],"ltp":1.07,"tv":71770.72,"id":9028621}]}]}
{"op":"mcm","clk":"4226776561","pt":1631451318396,"mc":[{"id":"1.187552454","rc":[{"batl":[[0,1.06,1995.69],[1,1.08,146.63],[2,1.09,139.69]],"ltp":1.07,"tv":71770.72,"id":9028621}]}]}
{"op":"mcm","clk":"4226776650","pt":1631451319082,"mc":[{"id":"1.187552454","rc":[{"batb":[[1,13.5,2],[2,12,4]],"ltp":15.5,"tv":5767.05,"id":9345630},{"trd":[[1.04,17.08]],"batb":[[0,1.04,2452.65]],"batl":[[0,1.06,99.78],[1,1.08,322.07]],"ltp":1.04,"tv":71787.8,"id":9028621}],"tv":77554.86}]}
{"op":"mcm","clk":"4226776722","pt":1631451319715,"mc":[{"id":"1.187552454","rc":[{"batb":[[2,1.02,953.84]],"ltp":1.04,"tv":71787.8,"id":9028621}]}]}
{"op":"mcm","clk":"4226777009","pt":1631451321584,"mc":[{"id":"1.187552454","rc":[{"batb":[[0,21,7.33],[1,15.5,6.03],[2,13.5,2]],"batl":[[0,26,2],[1,1000,0.32]],"ltp":15.5,"tv":5767.05,"id":9345630},{"batb":[[0,1.04,2499.65],[1,1.03,1011.84]],"batl":[[0,1.05,1338.34],[1,1.06,1179.03],[2,1.07,18]],"ltp":1.04,"tv":71787.8,"id":9028621}]}]}
{"op":"mcm","clk":"4226777139","pt":1631451322395,"mc":[{"id":"1.187552454","rc":[{"batb":[[0,21,5.33],[1,18,13.89],[2,16.5,3.87]],"batl":[[0,25,2],[1,26,2],[2,28,11.54]],"ltp":15.5,"tv":5767.05,"id":9345630},{"batb":[[0,1.04,2628.42],[1,1.03,1358.25]],"batl":[[0,1.05,1417.29],[2,1.07,69]],"ltp":1.04,"tv":71787.8,"id":9028621}]}]}
{"op":"mcm","clk":"4226777288","pt":1631451323391,"mc":[{"id":"1.187552454","rc":[{"batb":[[1,16.5,3.87],[2,16,2]],"ltp":15.5,"tv":5767.05,"id":9345630}]}]}
{"op":"mcm","clk":"4226777451","pt":1631451324410,"mc":[{"id":"1.187552454","rc":[{"trd":[[21,23.41]],"batb":[[0,16.5,3.87],[1,16,2],[2,15.5,8.03]],"ltp":21.0,"tv":5790.46,"id":9345630},{"trd":[[1.05,254.79]],"batb":[[0,1.04,2292.53]],"batl":[[0,1.05,1162.5],[2,1.07,9]],"ltp":1.05,"tv":72042.59,"id":9028621}],"tv":77833.06}]}
{"op":"mcm","clk":"4226777555","pt":1631451325191,"mc":[{"id":"1.187552454","rc":[{"batl":[[0,24,2],[1,25,2],[2,26,2]],"ltp":21.0,"tv":5790.46,"id":9345630}]}]}
{"op":"mcm","clk":"4226777681","pt":1631451326195,"mc":[{"id":"1.187552454","rc":[{"batl":[[0,24,4.41]],"ltp":21.0,"tv":5790.46,"id":9345630}]}]}
{"op":"mcm","clk":"4226777855","pt":1631451327514,"mc":[{"id":"1.187552454","rc":[{"batb":[[0,18,2],[1,17.5,2],[2,16.5,3.87]],"ltp":21.0,"tv":5790.46,"id":9345630},{"batl":[[0,1.05,1170.96]],"ltp":1.05,"tv":72042.59,"id":9028621}]}]}
{"op":"mcm","clk":"4226777869","pt":1631451327633,"mc":[{"id":"1.187552454","rc":[{"batb":[[2,1.02,1635.08]],"batl":[[1,1.06,1239.03],[2,1.07,215.5]],"ltp":1.05,"tv":72042.59,"id":9028621}]}]}
{"op":"mcm","clk":"4226778104","pt":1631451329425,"mc":[{"id":"1.187552454","rc":[{"trd":[[1.05,254.99]],"batl":[[0,1.05,1170.86]],"ltp":1.05,"tv":72042.79,"id":9028621}],"tv":77833.25}]}
{"op":"mcm","clk":"4226778313","pt":1631451331009,"mc":[{"id":"1.187552454","rc":[{"trd":[[1.05,262.79]],"batl":[[0,1.05,1166.96]],"ltp":1.05,"tv":72050.59,"id":9028621}],"tv":77841.06}]}
{"op":"mcm","clk":"4226778511","pt":1631451332497,"mc":[{"id":"1.187552454","rc":[{"batb":[[0,18.5,13.89],[1,18,2],[2,17.5,2]],"ltp":21.0,"tv":5790.46,"id":9345630},{"trd":[[1.05,279.71]],"batl":[[0,1.05,1158.5]],"ltp":1.05,"tv":72067.52,"id":9028621}],"tv":77857.98}]}
{"op":"mcm","clk":"4226778802","pt":1631451334553,"mc":[{"id":"1.187552454","rc":[{"batl":[[1,28,11.54],[2,55,2]],"ltp":21.0,"tv":5790.46,"id":9345630},{"trd":[[1.05,294.17]],"batb":[[1,1.03,1295.25],[2,1.02,1979.51]],"batl":[[0,1.05,1151.27],[1,1.06,1286.64]],"ltp":1.05,"tv":72081.98,"id":9028621}],"tv":77872.44}]}
{"op":"mcm","clk":"4226779064","pt":1631451336302,"mc":[{"id":"1.187552454","rc":[{"batb":[[0,16.5,3.87],[1,13.5,2],[2,12,2]],"batl":[[0,28,11.54],[1,55,2],[2,1000,0.32]],"ltp":21.0,"tv":5790.46,"id":9345630},{"trd":[[1.05,311.09]],"batb":[[0,1.05,20.06]],"batl":[[0,1.06,60],[1,1.08,322.07],[2,1.09,139.69]],"ltp":1.05,"tv":72098.9,"id":9028621}],"tv":77889.36}]}
{"op":"mcm","clk":"4226779217","pt":1631451337425,"mc":[{"id":"1.187552454","rc":[{"batb":[[0,13.5,2],[1,12,2],[2,2.32,102.49]],"batl":[[0,55,2],[1,1000,0.32],[2,1000,0]],"ltp":21.0,"tv":5790.46,"id":9345630},{"batb":[[0,1.05,19.66],[1,1.03,948.84]],"batl":[[0,1.08,322.07],[1,1.09,139.69],[2,1.1,2.85]],"ltp":1.05,"tv":72098.9,"id":9028621}]}]}
{"op":"mcm","clk":"4226779299","pt":1631451338129,"mc":[{"id":"1.187552454","rc":[{"batb":[[0,1.05,31.94]],"ltp":1.05,"tv":72098.9,"id":9028621}]}]}
{"op":"mcm","clk":"4226779513","pt":1631451339523,"mc":[{"id":"1.187552454","rc":[{"batb":[[0,16.5,2],[1,16,2],[2,15,2]],"ltp":21.0,"tv":5790.46,"id":9345630},{"trd":[[1.05,351.21]],"batb":[[0,1.05,11.88],[1,1.03,1830.41],[2,1.02,3247.55]],"batl":[[0,1.07,2211.91],[1,1.08,322.07],[2,1.09,139.69]],"ltp":1.05,"tv":72139.01,"id":9028621}],"tv":77929.48}]}
{"op":"mcm","clk":"4226779569","pt":1631451340013,"mc":[{"id":"1.187552454","rc":[{"batl":[[1,1.08,175.44]],"ltp":1.05,"tv":72139.01,"id":9028621}]}]}
{"op":"mcm","clk":"4226779696","pt":1631451341115,"mc":[{"id":"1.187552454","rc":[{"trd":[[21,24]],"batb":[[0,24,1.77],[1,16.5,2],[2,16,2]],"ltp":21.0,"tv":5791.05,"id":9345630},{"trd":[[1.05,363.09]],"batb":[[0,1.03,1830.41],[1,1.02,3247.55],[2,1.01,5980.2]],"batl":[[0,1.07,2229.91],[1,1.08,191.44]],"ltp":1.05,"tv":72150.89,"id":9028621}],"tv":77941.95}]}
{"op":"mcm","clk":"4226779819","pt":1631451342216,"mc":[{"id":"1.187552454","rc":[{"batl":[[0,1.06,149.4],[1,1.07,2229.91],[2,1.08,191.44]],"ltp":1.05,"tv":72150.89,"id":9028621}]}]}
{"op":"mcm","clk":"4226779985","pt":1631451343677,"mc":[{"id":"1.187552454","rc":[{"batl":[[0,1.04,8.54],[1,1.06,149.4],[2,1.07,2229.91]],"ltp":1.05,"tv":72150.89,"id":9028621}]}]}
{"op":"mcm","clk":"4226780145","pt":1631451344836,"mc":[{"id":"1.187552454","rc":[{"batb":[[0,16.5,2],[1,16,2],[2,15,4]],"ltp":21.0,"tv":5791.05,"id":9345630}]}]}
{"op":"mcm","clk":"4226780788","pt":1631451350139,"mc":[{"id":"1.187552454","rc":[{"batb":[[0,1.03,948.84],[1,1.02,1979.51]],"ltp":1.05,"tv":72150.89,"id":9028621}]}]}
{"op":"mcm","clk":"4226780981","pt":1631451351548,"mc":[{"id":"1.187552454","rc":[{"batb":[[0,15,4],[1,14.5,2],[2,13.5,4]],"ltp":21.0,"tv":5791.05,"id":9345630},{"trd":[[1.04,34.16]],"batb":[[0,1.04,41.87],[1,1.03,948.84],[2,1.02,1979.51]],"batl":[[0,1.07,2229.91],[1,1.08,191.44],[2,1.09,139.69]],"ltp":1.04,"tv":72167.97,"id":9028621}],"tv":77959.03}]}
{"op":"mcm","clk":"4226781098","pt":1631451352363,"mc":[{"id":"1.187552454","rc":[{"batb":[[2,13.5,2]],"batl":[[0,24,4.03],[1,55,2],[2,1000,0.32]],"ltp":21.0,"tv":5791.05,"id":9345630},{"batl":[[1,1.08,175.44]],"ltp":1.04,"tv":72167.97,"id":9028621}]}]}
