{"op":"mcm","clk":"4232350272","pt":1631518387236,"mc":[{"id":"1.187594316","marketDefinition":{"bspMarket":false,"turnInPlayEnabled":true,"persistenceEnabled":true,"marketBaseRate":5.0,"eventId":"30897697","eventTypeId":"2","numberOfWinners":1,"bettingType":"ODDS","marketType":"MATCH_ODDS","marketTime":"2021-09-13T06:00:00.000Z","suspendTime":"2021-09-13T06:00:00.000Z","bspReconciled":false,"complete":true,"inPlay":false,"crossMatching":false,"runnersVoidable":false,"numberOfActiveRunners":2,"betDelay":0,"status":"OPEN","runners":[{"status":"ACTIVE","sortPriority":1,"id":11486880,"name":"S Ma"},{"status":"ACTIVE","sortPriority":2,"id":9626933,"name":"S Sekulic"}],"regulators":["MR_INT"],"countryCode":"GB","discountAllowed":false,"timezone":"GMT","openDate":"2021-09-13T09:00:00.000Z","version":4030164801,"name":"Match Odds","eventName":"S Ma v S Sekulic"},"rc":[{"batb":[[0,1.01,25]],"ltp":0.0,"tv":0.0,"id":9626933},{"batb":[[0,1.01,25]],"ltp":0.0,"tv":0.0,"id":11486880}]}]}
{"op":"mcm","clk":"4232350345","pt":1631518388646,"mc":[{"id":"1.187594316","marketDefinition":{"bspMarket":false,"turnInPlayEnabled":true,"persistenceEnabled":true,"marketBaseRate":5.0,"eventId":"30897697","eventTypeId":"2","numberOfWinners":1,"bettingType":"ODDS","marketType":"MATCH_ODDS","marketTime":"2021-09-13T06:00:00.000Z","suspendTime":"2021-09-13T06:00:00.000Z","bspReconciled":false,"complete":true,"inPlay":false,"crossMatching":false,"runnersVoidable":false,"numberOfActiveRunners":2,"betDelay":0,"status":"OPEN","runners":[{"status":"ACTIVE","sortPriority":1,"id":11486880,"name":"S Ma"},{"status":"ACTIVE","sortPriority":2,"id":9626933,"name":"S Sekulic"}],"regulators":["MR_INT"],"countryCode":"GB","discountAllowed":true,"timezone":"GMT","openDate":"2021-09-13T09:00:00.000Z","version":4030164801,"name":"Match Odds","eventName":"S Ma v S Sekulic"}}]}
{"op":"mcm","clk":"4232393726","pt":1631519074656,"mc":[{"id":"1.187594316","rc":[{"batb":[[0,1.05,880.88],[1,1.01,25]],"ltp":0.0,"tv":0.0,"id":9626933},{"batb":[[0,1.05,880.88],[1,1.01,25]],"ltp":0.0,"tv":0.0,"id":11486880}]}]}
{"op":"mcm","clk":"4232396314","pt":1631519121800,"mc":[{"id":"1.187594316","rc":[{"batb":[[1,1.01,7]],"ltp":0.0,"tv":0.0,"id":9626933},{"batb":[[1,1.01,7]],"ltp":0.0,"tv":0.0,"id":11486880}]}]}
{"op":"mcm","clk":"4232605055","pt":1631522384015,"mc":[{"id":"1.187594316","rc":[{"batl":[[0,2.16,2.66]],"ltp":0.0,"tv":0.0,"id":11486880}]}]}
{"op":"mcm","clk":"4232605346","pt":1631522389107,"mc":[{"id":"1.187594316","rc":[{"batb":[[0,1.16,15.97],[1,1.05,880.88],[2,1.01,7]],"ltp":0.0,"tv":0.0,"id":11486880}]}]}
{"op":"mcm","clk":"4232615769","pt":1631522577828,"mc":[{"id":"1.187594316","rc":[{"batb":[[1,1.01,7],[2,1.01,0]],"ltp":0.0,"tv":0.0,"id":11486880}]}]}
{"op":"mcm","clk":"4232616740","pt":1631522593657,"mc":[{"id":"1.187594316","rc":[{"batb":[[0,1.18,246.65],[1,1.16,15.97],[2,1.01,7]],"ltp":0.0,"tv":0.0,"id":11486880}]}]}
{"op":"mcm","clk":"4232626385","pt":1631522762130,"mc":[{"id":"1.187594316","marketDefinition":{"bspMarket":false,"turnInPlayEnabled":true,"persistenceEnabled":true,"marketBaseRate":5.0,"eventId":"30897697","eventTypeId":"2","numberOfWinners":1,"bettingType":"ODDS","marketType":"MATCH_ODDS","marketTime":"2021-09-13T11:00:00.000Z","suspendTime":"2021-09-13T11:00:00.000Z","bspReconciled":false,"complete":true,"inPlay":false,"crossMatching":false,"runnersVoidable":false,"numberOfActiveRunners":2,"betDelay":0,"status":"OPEN","runners":[{"status":"ACTIVE","sortPriority":1,"id":11486880,"name":"S Ma"},{"status":"ACTIVE","sortPriority":2,"id":9626933,"name":"S Sekulic"}],"regulators":["MR_INT"],"countryCode":"GB","discountAllowed":true,"timezone":"GMT","openDate":"2021-09-13T09:00:00.000Z","version":4030340776,"name":"Match Odds","eventName":"S Ma v S Sekulic"}}]}
{"op":"mcm","clk":"4232626494","pt":1631522764139,"mc":[{"id":"1.187594316","marketDefinition":{"bspMarket":false,"turnInPlayEnabled":true,"persistenceEnabled":true,"marketBaseRate":5.0,"eventId":"30897697","eventTypeId":"2","numberOfWinners":1,"bettingType":"ODDS","marketType":"MATCH_ODDS","marketTime":"2021-09-13T11:00:00.000Z","suspendTime":"2021-09-13T11:00:00.000Z","bspReconciled":false,"complete":true,"inPlay":false,"crossMatching":false,"runnersVoidable":false,"numberOfActiveRunners":2,"betDelay":0,"status":"OPEN","runners":[{"status":"ACTIVE","sortPriority":1,"id":11486880,"name":"S Ma"},{"status":"ACTIVE","sortPriority":2,"id":9626933,"name":"S Sekulic"}],"regulators":["MR_INT"],"countryCode":"GB","discountAllowed":true,"timezone":"GMT","openDate":"2021-09-13T11:00:00.000Z","version":4030340776,"name":"Match Odds","eventName":"S Ma v S Sekulic"}}]}
{"op":"mcm","clk":"4232667702","pt":1631523680206,"mc":[{"id":"1.187594316","rc":[{"batb":[[0,1.05,880.36]],"ltp":0.0,"tv":0.0,"id":9626933},{"batb":[[0,1.18,246.5],[1,1.16,15.98]],"batl":[[0,2,100],[1,2.16,2.66]],"ltp":0.0,"tv":0.0,"id":11486880}]}]}
{"op":"mcm","clk":"4232668831","pt":1631523701969,"mc":[{"id":"1.187594316","marketDefinition":{"bspMarket":false,"turnInPlayEnabled":true,"persistenceEnabled":true,"marketBaseRate":5.0,"eventId":"30897697","eventTypeId":"2","numberOfWinners":1,"bettingType":"ODDS","marketType":"MATCH_ODDS","marketTime":"2021-09-13T11:00:00.000Z","suspendTime":"2021-09-13T11:00:00.000Z","bspReconciled":false,"complete":true,"inPlay":false,"crossMatching":true,"runnersVoidable":false,"numberOfActiveRunners":2,"betDelay":0,"status":"OPEN","runners":[{"status":"ACTIVE","sortPriority":1,"id":11486880,"name":"S Ma"},{"status":"ACTIVE","sortPriority":2,"id":9626933,"name":"S Sekulic"}],"regulators":["MR_INT"],"countryCode":"GB","discountAllowed":true,"timezone":"GMT","openDate":"2021-09-13T11:00:00.000Z","version":4030340776,"name":"Match Odds","eventName":"S Ma v S Sekulic"}}]}
{"op":"mcm","clk":"4232673407","pt":1631523785915,"mc":[{"id":"1.187594316","rc":[{"batb":[[0,2.5,27.84],[1,1.05,880.36],[2,1.01,7]],"ltp":0.0,"tv":0.0,"id":9626933},{"batb":[[0,1.5,83.53],[1,1.18,246.5],[2,1.16,15.98]],"ltp":0.0,"tv":0.0,"id":11486880}]}]}
{"op":"mcm","clk":"4232684513","pt":1631524000717,"mc":[{"id":"1.187594316","rc":[{"batb":[[1,1.01,7],[2,1.01,0]],"ltp":0.0,"tv":0.0,"id":9626933}]}]}
{"op":"mcm","clk":"4232684832","pt":1631524006854,"mc":[{"id":"1.187594316","rc":[{"batl":[[2,2.4,44.02]],"ltp":0.0,"tv":0.0,"id":11486880}]}]}
{"op":"mcm","clk":"4232737310","pt":1631524801354,"mc":[{"id":"1.187594316","rc":[{"batl":[[0,1.66,100]],"ltp":0.0,"tv":0.0,"id":11486880}]}]}
{"op":"mcm","clk":"4232778811","pt":1631525603850,"mc":[{"id":"1.187594316","rc":[{"batl":[[2,2.3,44.02]],"ltp":0.0,"tv":0.0,"id":11486880}]}]}
{"op":"mcm","clk":"4232806223","pt":1631526086028,"mc":[{"id":"1.187594316","marketDefinition":{"bspMarket":false,"turnInPlayEnabled":true,"persistenceEnabled":true,"marketBaseRate":5.0,"eventId":"30897697","eventTypeId":"2","numberOfWinners":1,"bettingType":"ODDS","marketType":"MATCH_ODDS","marketTime":"2021-09-13T11:10:00.000Z","suspendTime":"2021-09-13T11:10:00.000Z","bspReconciled":false,"complete":true,"inPlay":false,"crossMatching":true,"runnersVoidable":false,"numberOfActiveRunners":2,"betDelay":0,"status":"OPEN","runners":[{"status":"ACTIVE","sortPriority":1,"id":11486880,"name":"S Ma"},{"status":"ACTIVE","sortPriority":2,"id":9626933,"name":"S Sekulic"}],"regulators":["MR_INT"],"countryCode":"GB","discountAllowed":true,"timezone":"GMT","openDate":"2021-09-13T11:00:00.000Z","version":4030511786,"name":"Match Odds","eventName":"S Ma v S Sekulic"}}]}
{"op":"mcm","clk":"4232806642","pt":1631526089043,"mc":[{"id":"1.187594316","marketDefinition":{"bspMarket":false,"turnInPlayEnabled":true,"persistenceEnabled":true,"marketBaseRate":5.0,"eventId":"30897697","eventTypeId":"2","numberOfWinners":1,"bettingType":"ODDS","marketType":"MATCH_ODDS","marketTime":"2021-09-13T11:10:00.000Z","suspendTime":"2021-09-13T11:10:00.000Z","bspReconciled":false,"complete":true,"inPlay":false,"crossMatching":true,"runnersVoidable":false,"numberOfActiveRunners":2,"betDelay":0,"status":"OPEN","runners":[{"status":"ACTIVE","sortPriority":1,"id":11486880,"name":"S Ma"},{"status":"ACTIVE","sortPriority":2,"id":9626933,"name":"S Sekulic"}],"regulators":["MR_INT"],"countryCode":"GB","discountAllowed":true,"timezone":"GMT","openDate":"2021-09-13T11:10:00.000Z","version":4030511786,"name":"Match Odds","eventName":"S Ma v S Sekulic"}}]}
{"op":"mcm","clk":"4232905168","pt":1631527800811,"mc":[{"id":"1.187594316","rc":[{"batb":[[0,2.52,8.42],[1,2.5,27.84],[2,1.01,7]],"ltp":0.0,"tv":0.0,"id":9626933},{"batb":[[0,1.51,25.1],[1,1.5,83.53],[2,1.18,246.5]],"ltp":0.0,"tv":0.0,"id":11486880}]}]}
{"op":"mcm","clk":"4232965846","pt":1631528675506,"mc":[{"id":"1.187594316","rc":[{"batb":[[2,2.46,59.14]],"ltp":0.0,"tv":0.0,"id":9626933},{"batb":[[2,1.48,59.14]],"ltp":0.0,"tv":0.0,"id":11486880}]}]}
{"op":"mcm","clk":"4232966120","pt":1631528681240,"mc":[{"id":"1.187594316","rc":[{"batb":[[2,1.01,7]],"ltp":0.0,"tv":0.0,"id":9626933},{"batb":[[2,1.18,246.5]],"ltp":0.0,"tv":0.0,"id":11486880}]}]}
{"op":"mcm","clk":"4232966521","pt":1631528689424,"mc":[{"id":"1.187594316","rc":[{"batb":[[2,2.46,2.66]],"ltp":0.0,"tv":0.0,"id":9626933},{"batb":[[2,1.48,2.66]],"ltp":0.0,"tv":0.0,"id":11486880}]}]}
{"op":"mcm","clk":"4233037890","pt":1631529804853,"mc":[{"id":"1.187594316","marketDefinition":{"bspMarket":false,"turnInPlayEnabled":true,"persistenceEnabled":true,"marketBaseRate":5.0,"eventId":"30897697","eventTypeId":"2","numberOfWinners":1,"bettingType":"ODDS","marketType":"MATCH_ODDS","marketTime":"2021-09-13T11:00:00.000Z","suspendTime":"2021-09-13T11:00:00.000Z","bspReconciled":false,"complete":true,"inPlay":false,"crossMatching":true,"runnersVoidable":false,"numberOfActiveRunners":2,"betDelay":0,"status":"OPEN","runners":[{"status":"ACTIVE","sortPriority":1,"id":11486880,"name":"S Ma"},{"status":"ACTIVE","sortPriority":2,"id":9626933,"name":"S Sekulic"}],"regulators":["MR_INT"],"countryCode":"GB","discountAllowed":true,"timezone":"GMT","openDate":"2021-09-13T11:10:00.000Z","version":4030552798,"name":"Match Odds","eventName":"S Ma v S Sekulic"}}]}
{"op":"mcm","clk":"4233038000","pt":1631529806862,"mc":[{"id":"1.187594316","marketDefinition":{"bspMarket":false,"turnInPlayEnabled":true,"persistenceEnabled":true,"marketBaseRate":5.0,"eventId":"30897697","eventTypeId":"2","numberOfWinners":1,"bettingType":"ODDS","marketType":"MATCH_ODDS","marketTime":"2021-09-13T11:00:00.000Z","suspendTime":"2021-09-13T11:00:00.000Z","bspReconciled":false,"complete":true,"inPlay":false,"crossMatching":true,"runnersVoidable":false,"numberOfActiveRunners":2,"betDelay":0,"status":"OPEN","runners":[{"status":"ACTIVE","sortPriority":1,"id":11486880,"name":"S Ma"},{"status":"ACTIVE","sortPriority":2,"id":9626933,"name":"S Sekulic"}],"regulators":["MR_INT"],"countryCode":"GB","discountAllowed":true,"timezone":"GMT","openDate":"2021-09-13T11:00:00.000Z","version":4030552798,"name":"Match Odds","eventName":"S Ma v S Sekulic"}}]}
{"op":"mcm","clk":"4233121358","pt":1631530885730,"mc":[{"id":"1.187594316","marketDefinition":{"bspMarket":false,"turnInPlayEnabled":true,"persistenceEnabled":true,"marketBaseRate":5.0,"eventId":"30897697","eventTypeId":"2","numberOfWinners":1,"bettingType":"ODDS","marketType":"MATCH_ODDS","marketTime":"2021-09-13T11:00:00.000Z","suspendTime":"2021-09-13T11:00:00.000Z","bspReconciled":false,"complete":true,"inPlay":true,"crossMatching":true,"runnersVoidable":false,"numberOfActiveRunners":2,"betDelay":5,"status":"OPEN","runners":[{"status":"ACTIVE","sortPriority":1,"id":11486880,"name":"S Ma"},{"status":"ACTIVE","sortPriority":2,"id":9626933,"name":"S Sekulic"}],"regulators":["MR_INT"],"countryCode":"GB","discountAllowed":true,"timezone":"GMT","openDate":"2021-09-13T11:00:00.000Z","version":4030571889,"name":"Match Odds","eventName":"S Ma v S Sekulic"},"rc":[{"batb":[[0,1.01,7],[1,2.5,0],[2,2.46,0]],"ltp":0.0,"tv":0.0,"id":9626933},{"batb":[[0,1.01,7],[1,1.5,0],[2,1.48,0]],"batl":[[1,2.16,0],[2,2.3,0]],"ltp":0.0,"tv":0.0,"id":11486880}]}]}
{"op":"mcm","clk":"4233167657","pt":1631531419762,"mc":[{"id":"1.187594316","marketDefinition":{"bspMarket":false,"turnInPlayEnabled":true,"persistenceEnabled":true,"marketBaseRate":5.0,"eventId":"30897697","eventTypeId":"2","numberOfWinners":1,"bettingType":"ODDS","marketType":"MATCH_ODDS","marketTime":"2021-09-13T11:10:19.000Z","suspendTime":"2021-09-13T11:10:19.000Z","bspReconciled":false,"complete":true,"inPlay":true,"crossMatching":true,"runnersVoidable":false,"numberOfActiveRunners":2,"betDelay":5,"status":"OPEN","runners":[{"status":"ACTIVE","sortPriority":1,"id":11486880,"name":"S Ma"},{"status":"ACTIVE","sortPriority":2,"id":9626933,"name":"S Sekulic"}],"regulators":["MR_INT"],"countryCode":"GB","discountAllowed":true,"timezone":"GMT","openDate":"2021-09-13T11:00:00.000Z","version":4030578420,"name":"Match Odds","eventName":"S Ma v S Sekulic"}}]}
{"op":"mcm","clk":"4233167946","pt":1631531423785,"mc":[{"id":"1.187594316","marketDefinition":{"bspMarket":false,"turnInPlayEnabled":true,"persistenceEnabled":true,"marketBaseRate":5.0,"eventId":"30897697","eventTypeId":"2","numberOfWinners":1,"bettingType":"ODDS","marketType":"MATCH_ODDS","marketTime":"2021-09-13T11:10:19.000Z","suspendTime":"2021-09-13T11:10:19.000Z","bspReconciled":false,"complete":true,"inPlay":true,"crossMatching":true,"runnersVoidable":false,"numberOfActiveRunners":2,"betDelay":5,"status":"OPEN","runners":[{"status":"ACTIVE","sortPriority":1,"id":11486880,"name":"S Ma"},{"status":"ACTIVE","sortPriority":2,"id":9626933,"name":"S Sekulic"}],"regulators":["MR_INT"],"countryCode":"GB","discountAllowed":true,"timezone":"GMT","openDate":"2021-09-13T11:10:19.000Z","version":4030578424,"name":"Match Odds","eventName":"S Ma v S Sekulic"}}]}
{"op":"mcm","clk":"4233179442","pt":1631531581018,"mc":[{"id":"1.187594316","rc":[{"batb":[[0,1.5,432.79],[1,1.01,7]],"batl":[[1,2.3,314.02]],"ltp":0.0,"tv":0.0,"id":11486880}]}]}
{"op":"mcm","clk":"4233179666","pt":1631531584315,"mc":[{"id":"1.187594316","rc":[{"trd":[[2.5,34.07]],"ltp":2.5,"tv":34.07,"id":9626933},{"trd":[[1.66,51.31]],"batl":[[0,1.66,48.69]],"ltp":1.66,"tv":51.31,"id":11486880}],"tv":85.38}]}
{"op":"mcm","clk":"4233179781","pt":1631531586029,"mc":[{"id":"1.187594316","rc":[{"trd":[[1.66,61.63]],"batl":[[0,1.66,43.53]],"ltp":1.66,"tv":61.63,"id":11486880}],"tv":95.7}]}
{"op":"mcm","clk":"4233180166","pt":1631531591335,"mc":[{"id":"1.187594316","rc":[{"trd":[[1.66,100.6]],"batl":[[0,1.66,24.05]],"ltp":1.66,"tv":100.6,"id":11486880}],"tv":134.67}]}
{"op":"mcm","clk":"4233180584","pt":1631531596544,"mc":[{"id":"1.187594316","rc":[{"batb":[[0,1.01,7],[1,1.01,0]],"ltp":1.66,"tv":100.6,"id":11486880}]}]}
{"op":"mcm","clk":"4233181016","pt":1631531602460,"mc":[{"id":"1.187594316","rc":[{"batb":[[0,1.55,426.3],[1,1.01,7]],"ltp":1.66,"tv":100.6,"id":11486880}]}]}
{"op":"mcm","clk":"4233181169","pt":1631531604338,"mc":[{"id":"1.187594316","rc":[{"trd":[[1.66,148.7]],"batb":[[0,1.66,47.89],[1,1.55,426.3],[2,1.01,7]],"batl":[[0,2.3,314.02],[1,2.3,0]],"ltp":1.66,"tv":148.7,"id":11486880}],"tv":182.77}]}
{"op":"mcm","clk":"4233181281","pt":1631531605542,"mc":[{"id":"1.187594316","rc":[{"batb":[[0,1.66,381.24]],"ltp":1.66,"tv":148.7,"id":11486880}]}]}
{"op":"mcm","clk":"4233181358","pt":1631531606567,"mc":[{"id":"1.187594316","rc":[{"batb":[[0,1.66,372.8]],"ltp":1.66,"tv":148.7,"id":11486880}]}]}
{"op":"mcm","clk":"4233181436","pt":1631531607459,"mc":[{"id":"1.187594316","rc":[{"batb":[[0,1.66,95.89]],"ltp":1.66,"tv":148.7,"id":11486880}]}]}
{"op":"mcm","clk":"4233181518","pt":1631531608441,"mc":[{"id":"1.187594316","rc":[{"batb":[[0,1.66,103.62]],"ltp":1.66,"tv":148.7,"id":11486880}]}]}
{"op":"mcm","clk":"4233181601","pt":1631531609371,"mc":[{"id":"1.187594316","rc":[{"batb":[[0,1.66,145.86]],"ltp":1.66,"tv":148.7,"id":11486880}]}]}
{"op":"mcm","clk":"4233181702","pt":1631531610463,"mc":[{"id":"1.187594316","rc":[{"batb":[[0,1.66,62.27]],"ltp":1.66,"tv":148.7,"id":11486880}]}]}
{"op":"mcm","clk":"4233181801","pt":1631531611349,"mc":[{"id":"1.187594316","rc":[{"batb":[[0,1.66,23.94]],"ltp":1.66,"tv":148.7,"id":11486880}]}]}
{"op":"mcm","clk":"4233181872","pt":1631531612168,"mc":[{"id":"1.187594316","rc":[{"batb":[[0,1.66,10.34]],"ltp":1.66,"tv":148.7,"id":11486880}]}]}
{"op":"mcm","clk":"4233182020","pt":1631531614149,"mc":[{"id":"1.187594316","rc":[{"batb":[[0,1.55,426.3],[1,1.01,7],[2,1.01,0]],"ltp":1.66,"tv":148.7,"id":11486880}]}]}
{"op":"mcm","clk":"4233185427","pt":1631531660338,"mc":[{"id":"1.187594316","rc":[{"batb":[[0,1.01,7],[1,1.01,0]],"ltp":1.66,"tv":148.7,"id":11486880}]}]}
{"op":"mcm","clk":"4233185906","pt":1631531666235,"mc":[{"id":"1.187594316","rc":[{"batb":[[0,1.62,421.17],[1,1.01,7]],"batl":[[0,2.6,261.12]],"ltp":1.66,"tv":148.7,"id":11486880}]}]}
{"op":"mcm","clk":"4233188092","pt":1631531694776,"mc":[{"id":"1.187594316","rc":[{"batb":[[0,1.01,7],[1,1.01,0]],"ltp":1.66,"tv":148.7,"id":11486880}]}]}
{"op":"mcm","clk":"4233188576","pt":1631531700481,"mc":[{"id":"1.187594316","rc":[{"batb":[[0,1.67,415.42],[1,1.01,7]],"ltp":1.66,"tv":148.7,"id":11486880}]}]}
{"op":"mcm","clk":"4233192066","pt":1631531743550,"mc":[{"id":"1.187594316","rc":[{"batb":[[0,1.01,7],[1,1.01,0]],"ltp":1.66,"tv":148.7,"id":11486880}]}]}
{"op":"mcm","clk":"4233192526","pt":1631531749162,"mc":[{"id":"1.187594316","rc":[{"batb":[[0,1.74,409.86],[1,1.01,7]],"batl":[[0,2.92,224.31]],"ltp":1.66,"tv":148.7,"id":11486880}]}]}
{"op":"mcm","clk":"4233202765","pt":1631531874497,"mc":[{"id":"1.187594316","rc":[{"batb":[[0,1.01,7],[1,1.01,0]],"ltp":1.66,"tv":148.7,"id":11486880}]}]}
{"op":"mcm","clk":"4233203222","pt":1631531880605,"mc":[{"id":"1.187594316","rc":[{"batb":[[0,1.82,406.77],[1,1.01,7]],"ltp":1.66,"tv":148.7,"id":11486880}]}]}
{"op":"mcm","clk":"4233206399","pt":1631531927955,"mc":[{"id":"1.187594316","rc":[{"batl":[[0,3.3,194.57]],"ltp":1.66,"tv":148.7,"id":11486880}]}]}
{"op":"mcm","clk":"4233207281","pt":1631531940381,"mc":[{"id":"1.187594316","rc":[{"batl":[[0,3,216.4]],"ltp":1.66,"tv":148.7,"id":11486880}]}]}
{"op":"mcm","clk":"4233215175","pt":1631532048206,"mc":[{"id":"1.187594316","rc":[{"batb":[[0,1.01,7],[1,1.01,0]],"ltp":1.66,"tv":148.7,"id":11486880}]}]}
{"op":"mcm","clk":"4233215629","pt":1631532054422,"mc":[{"id":"1.187594316","rc":[{"batb":[[0,2.04,399.53],[1,1.01,7]],"batl":[[0,3.9,160.43]],"ltp":1.66,"tv":148.7,"id":11486880}]}]}
{"op":"mcm","clk":"4233223980","pt":1631532163752,"mc":[{"id":"1.187594316","rc":[{"batl":[[0,3.45,182.89]],"ltp":1.66,"tv":148.7,"id":11486880}]}]}
{"op":"mcm","clk":"4233226856","pt":1631532209122,"mc":[{"id":"1.187594316","rc":[{"batb":[[0,1.01,7],[1,1.01,0]],"ltp":1.66,"tv":148.7,"id":11486880}]}]}
{"op":"mcm","clk":"4233227237","pt":1631532214498,"mc":[{"id":"1.187594316","rc":[{"batb":[[0,1.82,406.77],[1,1.01,7]],"batl":[[0,3.15,203.19]],"ltp":1.66,"tv":148.7,"id":11486880}]}]}
{"op":"mcm","clk":"4233229332","pt":1631532246032,"mc":[{"id":"1.187594316","rc":[{"batl":[[0,3,216.4]],"ltp":1.66,"tv":148.7,"id":11486880}]}]}
{"op":"mcm","clk":"4233230649","pt":1631532266643,"mc":[{"id":"1.187594316","rc":[{"batb":[[0,1.85,29.05],[1,1.82,406.77],[2,1.01,7]],"ltp":1.66,"tv":148.7,"id":11486880}]}]}
{"op":"mcm","clk":"4233236922","pt":1631532367641,"mc":[{"id":"1.187594316","rc":[{"batb":[[0,1.87,32.25],[1,1.85,29.05],[2,1.82,406.77]],"ltp":1.66,"tv":148.7,"id":11486880}]}]}
{"op":"mcm","clk":"4233242555","pt":1631532452241,"mc":[{"id":"1.187594316","rc":[{"batl":[[0,2.82,234.47]],"ltp":1.66,"tv":148.7,"id":11486880}]}]}
{"op":"mcm","clk":"4233244271","pt":1631532476680,"mc":[{"id":"1.187594316","rc":[{"batb":[[0,1.56,29.05],[1,1.01,7]],"ltp":2.5,"tv":34.07,"id":9626933}]}]}
{"op":"mcm","clk":"4233244709","pt":1631532482816,"mc":[{"id":"1.187594316","rc":[{"batb":[[0,1.85,29.05],[1,1.82,406.77],[2,1.01,7]],"ltp":1.66,"tv":148.7,"id":11486880}]}]}
{"op":"mcm","clk":"4233244807","pt":1631532484008,"mc":[{"id":"1.187594316","rc":[{"batb":[[1,1.01,7],[2,1.01,0]],"ltp":1.66,"tv":148.7,"id":11486880}]}]}
{"op":"mcm","clk":"4233245194","pt":1631532489822,"mc":[{"id":"1.187594316","rc":[{"batb":[[1,1.62,421.17],[2,1.01,7]],"batl":[[0,2.6,261.12]],"ltp":1.66,"tv":148.7,"id":11486880}]}]}
{"op":"mcm","clk":"4233245266","pt":1631532490706,"mc":[{"id":"1.187594316","rc":[{"batb":[[0,1.62,421.17],[1,1.01,7],[2,1.01,0]],"ltp":1.66,"tv":148.7,"id":11486880}]}]}
{"op":"mcm","clk":"4233245623","pt":1631532495792,"mc":[{"id":"1.187594316","rc":[{"batb":[[0,1.76,29.05],[1,1.62,421.17],[2,1.01,7]],"ltp":1.66,"tv":148.7,"id":11486880}]}]}
{"op":"mcm","clk":"4233247085","pt":1631532513743,"mc":[{"id":"1.187594316","rc":[{"batb":[[0,1.01,7],[1,1.01,0]],"ltp":2.5,"tv":34.07,"id":9626933}]}]}
{"op":"mcm","clk":"4233247413","pt":1631532518965,"mc":[{"id":"1.187594316","rc":[{"batb":[[0,1.63,29.05],[1,1.01,7]],"ltp":2.5,"tv":34.07,"id":9626933}]}]}
{"op":"mcm","clk":"4233248312","pt":1631532529678,"mc":[{"id":"1.187594316","rc":[{"batb":[[0,1.62,421.17],[1,1.01,7],[2,1.01,0]],"ltp":1.66,"tv":148.7,"id":11486880}]}]}
{"op":"mcm","clk":"4233248651","pt":1631532534792,"mc":[{"id":"1.187594316","rc":[{"batb":[[0,1.63,29.05],[1,1.62,421.17],[2,1.01,7]],"ltp":1.66,"tv":148.7,"id":11486880}]}]}
{"op":"mcm","clk":"4233251453","pt":1631532571310,"mc":[{"id":"1.187594316","rc":[{"batb":[[1,1.01,7],[2,1.01,0]],"ltp":1.66,"tv":148.7,"id":11486880}]}]}
{"op":"mcm","clk":"4233251615","pt":1631532573706,"mc":[{"id":"1.187594316","rc":[{"batb":[[0,1.01,7],[1,1.01,0]],"ltp":2.5,"tv":34.07,"id":9626933}]}]}
{"op":"mcm","clk":"4233251820","pt":1631532576832,"mc":[{"id":"1.187594316","rc":[{"batb":[[0,1.7,414.97],[1,1.63,29.05],[2,1.01,7]],"ltp":1.66,"tv":148.7,"id":11486880}]}]}
{"op":"mcm","clk":"4233251885","pt":1631532577829,"mc":[{"id":"1.187594316","rc":[{"batb":[[1,1.01,7],[2,1.01,0]],"ltp":1.66,"tv":148.7,"id":11486880}]}]}
{"op":"mcm","clk":"4233253472","pt":1631532601808,"mc":[{"id":"1.187594316","rc":[{"batb":[[0,1.01,7],[1,1.01,0]],"ltp":1.66,"tv":148.7,"id":11486880}]}]}
{"op":"mcm","clk":"4233254009","pt":1631532608340,"mc":[{"id":"1.187594316","rc":[{"batb":[[0,1.77,407.82],[1,1.01,7]],"batl":[[0,3,216.4]],"ltp":1.66,"tv":148.7,"id":11486880}]}]}
{"op":"mcm","clk":"4233255638","pt":1631532628266,"mc":[{"id":"1.187594316","rc":[{"batb":[[0,1.01,7],[1,1.01,0]],"ltp":1.66,"tv":148.7,"id":11486880}]}]}
{"op":"mcm","clk":"4233255848","pt":1631532630670,"mc":[{"id":"1.187594316","rc":[{"batb":[[0,1.81,29.05],[1,1.01,7]],"ltp":1.66,"tv":148.7,"id":11486880}]}]}
{"op":"mcm","clk":"4233256133","pt":1631532634589,"mc":[{"id":"1.187594316","rc":[{"batb":[[0,1.86,404.12],[1,1.81,29.05],[2,1.01,7]],"ltp":1.66,"tv":148.7,"id":11486880}]}]}
{"op":"mcm","clk":"4233256578","pt":1631532640686,"mc":[{"id":"1.187594316","rc":[{"batb":[[1,1.01,7],[2,1.01,0]],"ltp":1.66,"tv":148.7,"id":11486880}]}]}
{"op":"mcm","clk":"4233256991","pt":1631532645882,"mc":[{"id":"1.187594316","rc":[{"batb":[[0,1.87,29.05],[1,1.86,404.12],[2,1.01,7]],"ltp":1.66,"tv":148.7,"id":11486880}]}]}
{"op":"mcm","clk":"4233266325","pt":1631532760940,"mc":[{"id":"1.187594316","rc":[{"batb":[[1,1.01,7],[2,1.01,0]],"ltp":1.66,"tv":148.7,"id":11486880}]}]}
{"op":"mcm","clk":"4233266930","pt":1631532767562,"mc":[{"id":"1.187594316","rc":[{"batb":[[1,1.86,404.12],[2,1.01,7]],"batl":[[0,3.3,194.57]],"ltp":1.66,"tv":148.7,"id":11486880}]}]}
{"op":"mcm","clk":"4233274914","pt":1631532857909,"mc":[{"id":"1.187594316","rc":[{"batb":[[1,1.01,7],[2,1.01,0]],"ltp":1.66,"tv":148.7,"id":11486880}]}]}
{"op":"mcm","clk":"4233275398","pt":1631532864232,"mc":[{"id":"1.187594316","rc":[{"batb":[[0,2.04,399.53],[1,1.87,29.05],[2,1.01,7]],"batl":[[0,3.9,160.43]],"ltp":1.66,"tv":148.7,"id":11486880}]}]}
{"op":"mcm","clk":"4233278018","pt":1631532893761,"mc":[{"id":"1.187594316","rc":[{"batb":[[0,1.87,29.05],[1,1.01,7],[2,1.01,0]],"ltp":1.66,"tv":148.7,"id":11486880}]}]}
{"op":"mcm","clk":"4233278595","pt":1631532900195,"mc":[{"id":"1.187594316","rc":[{"batb":[[0,2.22,389.82],[1,1.87,29.05],[2,1.01,7]],"batl":[[0,4.6,137.93]],"ltp":1.66,"tv":148.7,"id":11486880}]}]}
{"op":"mcm","clk":"4233278757","pt":1631532901884,"mc":[{"id":"1.187594316","rc":[{"batb":[[0,1.87,29.05],[1,1.01,7],[2,1.01,0]],"ltp":1.66,"tv":148.7,"id":11486880}]}]}
{"op":"mcm","clk":"4233280795","pt":1631532922733,"mc":[{"id":"1.187594316","rc":[{"batl":[[0,1.88,29.05]],"ltp":2.5,"tv":34.07,"id":9626933}]}]}
{"op":"mcm","clk":"4233296933","pt":1631533096678,"mc":[{"id":"1.187594316","rc":[{"batb":[[0,1.01,7],[1,1.01,0]],"ltp":1.66,"tv":148.7,"id":11486880}]}]}
{"op":"mcm","clk":"4233301599","pt":1631533157828,"mc":[{"id":"1.187594316","rc":[{"batl":[[0,1.86,44.16],[1,1.88,29.05]],"ltp":2.5,"tv":34.07,"id":9626933}]}]}
{"op":"mcm","clk":"4233317024","pt":1631533388220,"mc":[{"id":"1.187594316","rc":[{"batb":[[0,2.12,394.01],[1,1.01,7]],"batl":[[0,4.2,150.07]],"ltp":1.66,"tv":148.7,"id":11486880}]}]}
{"op":"mcm","clk":"4233318488","pt":1631533409958,"mc":[{"id":"1.187594316","rc":[{"batl":[[0,3.9,160.43]],"ltp":1.66,"tv":148.7,"id":11486880}]}]}
{"op":"mcm","clk":"4233319103","pt":1631533418776,"mc":[{"id":"1.187594316","rc":[{"batl":[[0,1.88,29.05],[1,1.88,0]],"ltp":2.5,"tv":34.07,"id":9626933}]}]}
{"op":"mcm","clk":"4233327028","pt":1631533516691,"mc":[{"id":"1.187594316","rc":[{"batl":[[0,3.65,172.76]],"ltp":1.66,"tv":148.7,"id":11486880}]}]}
{"op":"mcm","clk":"4233331862","pt":1631533576955,"mc":[{"id":"1.187594316","rc":[{"batl":[[0,4.2,150.07]],"ltp":1.66,"tv":148.7,"id":11486880}]}]}
{"op":"mcm","clk":"4233332995","pt":1631533590725,"mc":[{"id":"1.187594316","rc":[{"batl":[[0,1.88,29.05]],"ltp":2.5,"tv":34.07,"id":9626933}]}]}
{"op":"mcm","clk":"4233333826","pt":1631533600344,"mc":[{"id":"1.187594316","rc":[{"batb":[[0,1.01,7],[1,1.01,0]],"ltp":1.66,"tv":148.7,"id":11486880}]}]}
{"op":"mcm","clk":"4233334334","pt":1631533606523,"mc":[{"id":"1.187594316","rc":[{"batb":[[0,2.3,390.4],[1,1.01,7]],"batl":[[0,4.9,128.02]],"ltp":1.66,"tv":148.7,"id":11486880}]}]}
{"op":"mcm","clk":"4233336570","pt":1631533634000,"mc":[{"id":"1.187594316","rc":[{"batl":[[0,1.73,29.05]],"ltp":2.5,"tv":34.07,"id":9626933},{"batl":[[0,4.6,137.93]],"ltp":1.66,"tv":148.7,"id":11486880}]}]}
{"op":"mcm","clk":"4233337984","pt":1631533651096,"mc":[{"id":"1.187594316","rc":[{"batl":[[0,4.2,150.07]],"ltp":1.66,"tv":148.7,"id":11486880}]}]}
{"op":"mcm","clk":"4233338244","pt":1631533653920,"mc":[{"id":"1.187594316","rc":[{"batl":[[0,1.76,29.05]],"ltp":2.5,"tv":34.07,"id":9626933}]}]}
{"op":"mcm","clk":"4233339240","pt":1631533666039,"mc":[{"id":"1.187594316","rc":[{"batb":[[0,1.01,7],[1,1.01,0]],"ltp":1.66,"tv":148.7,"id":11486880}]}]}
{"op":"mcm","clk":"4233339769","pt":1631533671955,"mc":[{"id":"1.187594316","rc":[{"batb":[[0,1.97,400.31],[1,1.01,7]],"batl":[[0,3.65,172.76]],"ltp":1.66,"tv":148.7,"id":11486880}]}]}
{"op":"mcm","clk":"4233341443","pt":1631533693067,"mc":[{"id":"1.187594316","rc":[{"batl":[[0,3.3,194.57]],"ltp":1.66,"tv":148.7,"id":11486880}]}]}
{"op":"mcm","clk":"4233343219","pt":1631533715718,"mc":[{"id":"1.187594316","rc":[{"batb":[[0,1.45,23.24],[1,1.01,7]],"ltp":2.5,"tv":34.07,"id":9626933}]}]}
{"op":"mcm","clk":"4233343638","pt":1631533721328,"mc":[{"id":"1.187594316","rc":[{"batb":[[0,1.01,7],[1,1.01,0]],"ltp":1.66,"tv":148.7,"id":11486880}]}]}
{"op":"mcm","clk":"4233344102","pt":1631533727430,"mc":[{"id":"1.187594316","rc":[{"batb":[[0,1.77,407.82],[1,1.01,7]],"batl":[[0,3,216.4]],"ltp":1.66,"tv":148.7,"id":11486880}]}]}
{"op":"mcm","clk":"4233344300","pt":1631533730647,"mc":[{"id":"1.187594316","rc":[{"batb":[[0,1.01,7],[1,1.01,0]],"ltp":2.5,"tv":34.07,"id":9626933}]}]}
{"op":"mcm","clk":"4233349589","pt":1631533801589,"mc":[{"id":"1.187594316","rc":[{"batb":[[0,1.01,7],[1,1.01,0]],"ltp":1.66,"tv":148.7,"id":11486880}]}]}
{"op":"mcm","clk":"4233350026","pt":1631533807378,"mc":[{"id":"1.187594316","rc":[{"batb":[[0,1.92,400.36],[1,1.01,7]],"batl":[[0,3.45,182.89]],"ltp":1.66,"tv":148.7,"id":11486880}]}]}
{"op":"mcm","clk":"4233351347","pt":1631533824111,"mc":[{"id":"1.187594316","rc":[{"batb":[[0,1.01,7],[1,1.01,0]],"ltp":1.66,"tv":148.7,"id":11486880}]}]}
{"op":"mcm","clk":"4233351811","pt":1631533829726,"mc":[{"id":"1.187594316","rc":[{"batb":[[0,2.04,399.53],[1,1.01,7]],"batl":[[0,3.9,160.43]],"ltp":1.66,"tv":148.7,"id":11486880}]}]}
{"op":"mcm","clk":"4233356399","pt":1631533886955,"mc":[{"id":"1.187594316","rc":[{"batl":[[0,3.45,182.89]],"ltp":1.66,"tv":148.7,"id":11486880}]}]}
{"op":"mcm","clk":"4233356716","pt":1631533890660,"mc":[{"id":"1.187594316","rc":[{"batl":[[0,1.95,29.05]],"ltp":2.5,"tv":34.07,"id":9626933}]}]}
{"op":"mcm","clk":"4233357506","pt":1631533899994,"mc":[{"id":"1.187594316","rc":[{"batb":[[0,1.01,7],[1,1.01,0]],"ltp":1.66,"tv":148.7,"id":11486880}]}]}
{"op":"mcm","clk":"4233358023","pt":1631533906174,"mc":[{"id":"1.187594316","rc":[{"batb":[[0,1.77,407.82],[1,1.01,7]],"batl":[[0,3,216.4]],"ltp":1.66,"tv":148.7,"id":11486880}]}]}
{"op":"mcm","clk":"4233359639","pt":1631533925813,"mc":[{"id":"1.187594316","rc":[{"batb":[[0,1.01,7],[1,1.01,0]],"ltp":1.66,"tv":148.7,"id":11486880}]}]}
{"op":"mcm","clk":"4233360110","pt":1631533932038,"mc":[{"id":"1.187594316","rc":[{"batb":[[0,1.58,422.21],[1,1.01,7]],"batl":[[0,2.5,278.33]],"ltp":1.66,"tv":148.7,"id":11486880}]}]}
{"op":"mcm","clk":"4233361573","pt":1631533953590,"mc":[{"id":"1.187594316","rc":[{"batb":[[0,1.01,7],[1,1.01,0]],"ltp":1.66,"tv":148.7,"id":11486880}]}]}
{"op":"mcm","clk":"4233361930","pt":1631533959391,"mc":[{"id":"1.187594316","rc":[{"batb":[[0,1.74,409.86],[1,1.01,7]],"batl":[[0,2.92,224.31]],"ltp":1.66,"tv":148.7,"id":11486880}]}]}
{"op":"mcm","clk":"4233363321","pt":1631533979223,"mc":[{"id":"1.187594316","rc":[{"batb":[[0,1.01,7],[1,1.01,0]],"ltp":1.66,"tv":148.7,"id":11486880}]}]}
{"op":"mcm","clk":"4233363705","pt":1631533985007,"mc":[{"id":"1.187594316","rc":[{"batb":[[0,1.97,400.31],[1,1.01,7]],"batl":[[0,3.65,172.76]],"ltp":1.66,"tv":148.7,"id":11486880}]}]}
{"op":"mcm","clk":"4233365335","pt":1631534011062,"mc":[{"id":"1.187594316","rc":[{"batb":[[0,1.01,7],[1,1.01,0]],"ltp":1.66,"tv":148.7,"id":11486880}]}]}
{"op":"mcm","clk":"4233365790","pt":1631534017462,"mc":[{"id":"1.187594316","rc":[{"batb":[[0,1.74,409.86],[1,1.01,7]],"batl":[[0,2.92,224.31]],"ltp":1.66,"tv":148.7,"id":11486880}]}]}
{"op":"mcm","clk":"4233366012","pt":1631534021067,"mc":[{"id":"1.187594316","rc":[{"batl":[[1,4,4.26]],"ltp":1.66,"tv":148.7,"id":11486880}]}]}
{"op":"mcm","clk":"4233366180","pt":1631534023274,"mc":[{"id":"1.187594316","rc":[{"batl":[[1,4,0]],"ltp":1.66,"tv":148.7,"id":11486880}]}]}
{"op":"mcm","clk":"4233367340","pt":1631534038699,"mc":[{"id":"1.187594316","rc":[{"batb":[[0,1.01,7],[1,1.01,0]],"ltp":1.66,"tv":148.7,"id":11486880}]}]}
{"op":"mcm","clk":"4233367767","pt":1631534044724,"mc":[{"id":"1.187594316","rc":[{"batb":[[0,1.97,400.31],[1,1.01,7]],"batl":[[0,3.65,172.76]],"ltp":1.66,"tv":148.7,"id":11486880}]}]}
{"op":"mcm","clk":"4233369297","pt":1631534066332,"mc":[{"id":"1.187594316","rc":[{"batl":[[0,3.45,182.89]],"ltp":1.66,"tv":148.7,"id":11486880}]}]}
{"op":"mcm","clk":"4233369845","pt":1631534075623,"mc":[{"id":"1.187594316","rc":[{"batb":[[0,1.01,7],[1,1.01,0]],"ltp":1.66,"tv":148.7,"id":11486880}]}]}
{"op":"mcm","clk":"4233370205","pt":1631534081558,"mc":[{"id":"1.187594316","rc":[{"batb":[[0,2.22,389.82],[1,1.01,7]],"batl":[[0,4.6,137.93]],"ltp":1.66,"tv":148.7,"id":11486880}]}]}
{"op":"mcm","clk":"4233371590","pt":1631534103693,"mc":[{"id":"1.187594316","rc":[{"batl":[[0,4.2,4.26],[1,4.6,137.93]],"ltp":1.66,"tv":148.7,"id":11486880}]}]}
{"op":"mcm","clk":"4233377978","pt":1631534199444,"mc":[{"id":"1.187594316","rc":[{"batb":[[0,1.01,7],[1,1.01,0]],"batl":[[1,4.6,0]],"ltp":1.66,"tv":148.7,"id":11486880}]}]}
{"op":"mcm","clk":"4233378356","pt":1631534205648,"mc":[{"id":"1.187594316","rc":[{"batb":[[0,2.38,387.57],[1,1.01,7]],"batl":[[1,5.3,120.43]],"ltp":1.66,"tv":148.7,"id":11486880}]}]}
{"op":"mcm","clk":"4233379516","pt":1631534222050,"mc":[{"id":"1.187594316","rc":[{"batb":[[0,1.01,7],[1,1.01,0]],"batl":[[1,5.3,0]],"ltp":1.66,"tv":148.7,"id":11486880}]}]}
{"op":"mcm","clk":"4233379944","pt":1631534228169,"mc":[{"id":"1.187594316","rc":[{"batb":[[0,2.52,386.72],[1,1.01,7]],"batl":[[0,6,107.64]],"ltp":1.66,"tv":148.7,"id":11486880}]}]}
{"op":"mcm","clk":"4233385330","pt":1631534313109,"mc":[{"id":"1.187594316","rc":[{"batb":[[0,1.01,7],[1,1.01,0]],"ltp":1.66,"tv":148.7,"id":11486880}]}]}
{"op":"mcm","clk":"4233385712","pt":1631534318723,"mc":[{"id":"1.187594316","rc":[{"batb":[[0,2.72,383.47],[1,1.01,7]],"batl":[[0,7.2,93.45]],"ltp":1.66,"tv":148.7,"id":11486880}]}]}
{"op":"mcm","clk":"4233389747","pt":1631534375766,"mc":[{"id":"1.187594316","rc":[{"batl":[[0,8.2,86.64]],"ltp":1.66,"tv":148.7,"id":11486880}]}]}
{"op":"mcm","clk":"4233390689","pt":1631534389213,"mc":[{"id":"1.187594316","rc":[{"batb":[[0,1.01,7],[1,1.01,0]],"ltp":1.66,"tv":148.7,"id":11486880}]}]}
{"op":"mcm","clk":"4233391134","pt":1631534395049,"mc":[{"id":"1.187594316","rc":[{"batb":[[0,2.98,379.45],[1,1.01,7]],"batl":[[0,9.4,79.11]],"ltp":1.66,"tv":148.7,"id":11486880}]}]}
{"op":"mcm","clk":"4233392361","pt":1631534409402,"mc":[{"id":"1.187594316","rc":[{"trd":[[1.11,669.97]],"batl":[[0,1.1,2311.29]],"ltp":1.11,"tv":704.04,"id":9626933},{"trd":[[9.4,79.11]],"ltp":9.4,"tv":227.81,"id":11486880}],"tv":931.86}]}
{"op":"mcm","clk":"4233393160","pt":1631534418296,"mc":[{"id":"1.187594316","rc":[{"batl":[[0,1.04,3407.16],[1,1.1,2311.29]],"ltp":1.11,"tv":704.04,"id":9626933}]}]}
{"op":"mcm","clk":"4233393344","pt":1631534420501,"mc":[{"id":"1.187594316","rc":[{"trd":[[1.04,51.11]],"batl":[[0,1.04,3356.05]],"ltp":1.04,"tv":755.15,"id":9626933},{"trd":[[26,2.04]],"ltp":26.0,"tv":229.86,"id":11486880}],"tv":985.01}]}
{"op":"mcm","clk":"4233393433","pt":1631534421604,"mc":[{"id":"1.187594316","rc":[{"trd":[[1.04,95.83]],"batl":[[0,1.04,3311.33]],"ltp":1.04,"tv":799.87,"id":9626933},{"trd":[[26,3.83]],"ltp":26.0,"tv":231.65,"id":11486880}],"tv":1031.52}]}
{"op":"mcm","clk":"4233393657","pt":1631534423964,"mc":[{"id":"1.187594316","rc":[{"trd":[[1.04,189.52]],"batl":[[0,1.04,3264.48]],"ltp":1.04,"tv":893.56,"id":9626933}],"tv":1125.22}]}
{"op":"mcm","clk":"4233393977","pt":1631534428002,"mc":[{"id":"1.187594316","rc":[{"batb":[[0,1.01,7],[1,1.01,0]],"ltp":26.0,"tv":231.65,"id":11486880}]}]}
{"op":"mcm","clk":"4233394930","pt":1631534439403,"mc":[{"id":"1.187594316","rc":[{"batl":[[0,1000,3.28]],"ltp":26.0,"tv":231.65,"id":11486880}]}]}
{"op":"mcm","clk":"4233395145","pt":1631534441721,"mc":[{"id":"1.187594316","rc":[{"batl":[[0,1.02,1703.58],[1,1.04,3264.48],[2,1.1,2311.29]],"ltp":1.04,"tv":893.56,"id":9626933}]}]}
{"op":"mcm","clk":"4233395424","pt":1631534444949,"mc":[{"id":"1.187594316","rc":[{"trd":[[1.02,160.76]],"batl":[[0,1.02,1542.82]],"ltp":1.02,"tv":1054.32,"id":9626933},{"trd":[[50,3.28]],"ltp":50.0,"tv":234.93,"id":11486880}],"tv":1289.25}]}
{"op":"mcm","clk":"4233397617","pt":1631534470496,"mc":[{"id":"1.187594316","rc":[{"trd":[[1.01,14]],"batl":[[0,1.01,844.79],[1,1.02,1542.82],[2,1.04,3264.48]],"ltp":1.01,"tv":1068.32,"id":9626933}],"tv":1303.25}]}
{"op":"mcm","clk":"4233398054","pt":1631534475619,"mc":[{"id":"1.187594316","rc":[{"batl":[[0,1.02,1542.82],[1,1.04,3264.48],[2,1.1,2311.29]],"ltp":1.01,"tv":1068.32,"id":9626933}]}]}
{"op":"mcm","clk":"4233398964","pt":1631534485981,"mc":[{"id":"1.187594316","rc":[{"batl":[[2,1.1,0]],"ltp":1.01,"tv":1068.32,"id":9626933}]}]}
{"op":"mcm","clk":"4233399379","pt":1631534491141,"mc":[{"id":"1.187594316","rc":[{"batl":[[0,1.01,2311.29],[1,1.02,1542.82],[2,1.04,3264.48]],"ltp":1.01,"tv":1068.32,"id":9626933}]}]}
{"op":"mcm","clk":"4233402223","pt":1631534523530,"mc":[{"id":"1.187594316","marketDefinition":{"bspMarket":false,"turnInPlayEnabled":true,"persistenceEnabled":true,"marketBaseRate":5.0,"eventId":"30897697","eventTypeId":"2","numberOfWinners":1,"bettingType":"ODDS","marketType":"MATCH_ODDS","marketTime":"2021-09-13T11:10:19.000Z","suspendTime":"2021-09-13T11:10:19.000Z","bspReconciled":false,"complete":true,"inPlay":true,"crossMatching":true,"runnersVoidable":false,"numberOfActiveRunners":2,"betDelay":5,"status":"SUSPENDED","runners":[{"status":"ACTIVE","sortPriority":1,"id":11486880,"name":"S Ma"},{"status":"ACTIVE","sortPriority":2,"id":9626933,"name":"S Sekulic"}],"regulators":["MR_INT"],"countryCode":"GB","discountAllowed":true,"timezone":"GMT","openDate":"2021-09-13T11:10:19.000Z","version":4030619437,"name":"Match Odds","eventName":"S Ma v S Sekulic"}}]}
{"op":"mcm","clk":"4233402828","pt":1631534530006,"mc":[{"id":"1.187594316","rc":[{"batl":[[0,1.02,1542.82],[1,1.04,3264.48],[2,1.04,0]],"ltp":1.01,"tv":1068.32,"id":9626933}]}]}
{"op":"mcm","clk":"4233419264","pt":1631534696105,"mc":[{"id":"1.187594316","tv":0.0}]}
{"op":"mcm","clk":"4233419373","pt":1631534697429,"mc":[{"id":"1.187594316","marketDefinition":{"bspMarket":false,"turnInPlayEnabled":true,"persistenceEnabled":true,"marketBaseRate":5.0,"eventId":"30897697","eventTypeId":"2","numberOfWinners":1,"bettingType":"ODDS","marketType":"MATCH_ODDS","marketTime":"2021-09-13T11:10:19.000Z","suspendTime":"2021-09-13T11:10:19.000Z","bspReconciled":false,"complete":true,"inPlay":true,"crossMatching":false,"runnersVoidable":false,"numberOfActiveRunners":0,"betDelay":5,"status":"CLOSED","settledTime":"2021-09-13T12:04:54.000Z","runners":[{"status":"LOSER","sortPriority":1,"id":11486880,"name":"S Ma"},{"status":"WINNER","sortPriority":2,"id":9626933,"name":"S Sekulic"}],"regulators":["MR_INT"],"countryCode":"GB","discountAllowed":true,"timezone":"GMT","openDate":"2021-09-13T11:10:19.000Z","version":4030621227,"name":"Match Odds","eventName":"S Ma v S Sekulic"}}]}
