{"op":"mcm","clk":"4232350267","pt":1631518387108,"mc":[{"id":"1.187594273","marketDefinition":{"bspMarket":false,"turnInPlayEnabled":true,"persistenceEnabled":true,"marketBaseRate":5.0,"eventId":"30897691","eventTypeId":"2","numberOfWinners":1,"bettingType":"ODDS","marketType":"MATCH_ODDS","marketTime":"2021-09-13T06:00:00.000Z","suspendTime":"2021-09-13T06:00:00.000Z","bspReconciled":false,"complete":true,"inPlay":false,"crossMatching":false,"runnersVoidable":false,"numberOfActiveRunners":2,"betDelay":0,"status":"OPEN","runners":[{"status":"ACTIVE","sortPriority":1,"id":12531094,"name":"S Djoubri"},{"status":"ACTIVE","sortPriority":2,"id":13689566,"name":"E Shalimova"}],"regulators":["MR_INT"],"countryCode":"GB","discountAllowed":false,"timezone":"GMT","openDate":"2021-09-13T09:00:00.000Z","version":4030164799,"name":"Match Odds","eventName":"S Djoubri v E Shalimova"},"rc":[{"batb":[[0,1.01,25]],"ltp":0.0,"tv":0.0,"id":13689566},{"batb":[[0,1.01,25]],"ltp":0.0,"tv":0.0,"id":12531094}]}]}
{"op":"mcm","clk":"4232350346","pt":1631518388646,"mc":[{"id":"1.187594273","marketDefinition":{"bspMarket":false,"turnInPlayEnabled":true,"persistenceEnabled":true,"marketBaseRate":5.0,"eventId":"30897691","eventTypeId":"2","numberOfWinners":1,"bettingType":"ODDS","marketType":"MATCH_ODDS","marketTime":"2021-09-13T06:00:00.000Z","suspendTime":"2021-09-13T06:00:00.000Z","bspReconciled":false,"complete":true,"inPlay":false,"crossMatching":false,"runnersVoidable":false,"numberOfActiveRunners":2,"betDelay":0,"status":"OPEN","runners":[{"status":"ACTIVE","sortPriority":1,"id":12531094,"name":"S Djoubri"},{"status":"ACTIVE","sortPriority":2,"id":13689566,"name":"E Shalimova"}],"regulators":["MR_INT"],"countryCode":"GB","discountAllowed":true,"timezone":"GMT","openDate":"2021-09-13T09:00:00.000Z","version":4030164799,"name":"Match Odds","eventName":"S Djoubri v E Shalimova"}}]}
{"op":"mcm","clk":"4232396306","pt":1631519121696,"mc":[{"id":"1.187594273","rc":[{"batb":[[0,1.01,7]],"ltp":0.0,"tv":0.0,"id":13689566},{"batb":[[0,1.01,7]],"ltp":0.0,"tv":0.0,"id":12531094}]}]}
{"op":"mcm","clk":"4232397441","pt":1631519141705,"mc":[{"id":"1.187594273","rc":[{"batb":[[0,1.05,880.88],[1,1.01,7]],"ltp":0.0,"tv":0.0,"id":13689566},{"batb":[[0,1.05,880.88],[1,1.01,7]],"ltp":0.0,"tv":0.0,"id":12531094}]}]}
{"op":"mcm","clk":"4232527270","pt":1631521060629,"mc":[{"id":"1.187594273","rc":[{"trd":[[1.05,0.19]],"batb":[[0,1.05,880.79]],"ltp":1.05,"tv":0.18,"id":13689566}],"tv":0.18}]}
{"op":"mcm","clk":"4232546970","pt":1631521330485,"mc":[{"id":"1.187594273","rc":[{"trd":[[1.05,0.37]],"batb":[[0,1.05,880.69]],"ltp":1.05,"tv":0.37,"id":13689566}],"tv":0.37}]}
{"op":"mcm","clk":"4232604399","pt":1631522372747,"mc":[{"id":"1.187594273","rc":[{"batl":[[0,2.16,2.66]],"ltp":0.0,"tv":0.0,"id":12531094}]}]}
{"op":"mcm","clk":"4232604644","pt":1631522376862,"mc":[{"id":"1.187594273","rc":[{"batb":[[0,1.16,15.97],[1,1.05,880.88],[2,1.01,7]],"ltp":0.0,"tv":0.0,"id":12531094}]}]}
{"op":"mcm","clk":"4232618799","pt":1631522628791,"mc":[{"id":"1.187594273","rc":[{"batb":[[1,1.01,7],[2,1.01,0]],"ltp":0.0,"tv":0.0,"id":12531094}]}]}
{"op":"mcm","clk":"4232619307","pt":1631522636668,"mc":[{"id":"1.187594273","rc":[{"batb":[[0,1.18,246.65],[1,1.16,15.97],[2,1.01,7]],"ltp":0.0,"tv":0.0,"id":12531094}]}]}
{"op":"mcm","clk":"4232626386","pt":1631522762131,"mc":[{"id":"1.187594273","marketDefinition":{"bspMarket":false,"turnInPlayEnabled":true,"persistenceEnabled":true,"marketBaseRate":5.0,"eventId":"30897691","eventTypeId":"2","numberOfWinners":1,"bettingType":"ODDS","marketType":"MATCH_ODDS","marketTime":"2021-09-13T09:30:00.000Z","suspendTime":"2021-09-13T09:30:00.000Z","bspReconciled":false,"complete":true,"inPlay":false,"crossMatching":false,"runnersVoidable":false,"numberOfActiveRunners":2,"betDelay":0,"status":"OPEN","runners":[{"status":"ACTIVE","sortPriority":1,"id":12531094,"name":"S Djoubri"},{"status":"ACTIVE","sortPriority":2,"id":13689566,"name":"E Shalimova"}],"regulators":["MR_INT"],"countryCode":"GB","discountAllowed":true,"timezone":"GMT","openDate":"2021-09-13T09:00:00.000Z","version":4030340786,"name":"Match Odds","eventName":"S Djoubri v E Shalimova"}}]}
{"op":"mcm","clk":"4232626497","pt":1631522764146,"mc":[{"id":"1.187594273","marketDefinition":{"bspMarket":false,"turnInPlayEnabled":true,"persistenceEnabled":true,"marketBaseRate":5.0,"eventId":"30897691","eventTypeId":"2","numberOfWinners":1,"bettingType":"ODDS","marketType":"MATCH_ODDS","marketTime":"2021-09-13T09:30:00.000Z","suspendTime":"2021-09-13T09:30:00.000Z","bspReconciled":false,"complete":true,"inPlay":false,"crossMatching":false,"runnersVoidable":false,"numberOfActiveRunners":2,"betDelay":0,"status":"OPEN","runners":[{"status":"ACTIVE","sortPriority":1,"id":12531094,"name":"S Djoubri"},{"status":"ACTIVE","sortPriority":2,"id":13689566,"name":"E Shalimova"}],"regulators":["MR_INT"],"countryCode":"GB","discountAllowed":true,"timezone":"GMT","openDate":"2021-09-13T09:30:00.000Z","version":4030340786,"name":"Match Odds","eventName":"S Djoubri v E Shalimova"}}]}
{"op":"mcm","clk":"4232666768","pt":1631523661423,"mc":[{"id":"1.187594273","rc":[{"batb":[[0,1.05,880.17]],"ltp":1.05,"tv":0.37,"id":13689566},{"batb":[[0,1.18,246.5],[1,1.16,15.98]],"batl":[[0,2,100],[1,2.16,2.66]],"ltp":0.0,"tv":0.0,"id":12531094}]}]}
{"op":"mcm","clk":"4232667182","pt":1631523670682,"mc":[{"id":"1.187594273","marketDefinition":{"bspMarket":false,"turnInPlayEnabled":true,"persistenceEnabled":true,"marketBaseRate":5.0,"eventId":"30897691","eventTypeId":"2","numberOfWinners":1,"bettingType":"ODDS","marketType":"MATCH_ODDS","marketTime":"2021-09-13T09:30:00.000Z","suspendTime":"2021-09-13T09:30:00.000Z","bspReconciled":false,"complete":true,"inPlay":false,"crossMatching":true,"runnersVoidable":false,"numberOfActiveRunners":2,"betDelay":0,"status":"OPEN","runners":[{"status":"ACTIVE","sortPriority":1,"id":12531094,"name":"S Djoubri"},{"status":"ACTIVE","sortPriority":2,"id":13689566,"name":"E Shalimova"}],"regulators":["MR_INT"],"countryCode":"GB","discountAllowed":true,"timezone":"GMT","openDate":"2021-09-13T09:30:00.000Z","version":4030340786,"name":"Match Odds","eventName":"S Djoubri v E Shalimova"}}]}
{"op":"mcm","clk":"4232673414","pt":1631523785964,"mc":[{"id":"1.187594273","rc":[{"batb":[[0,2.38,30.26],[1,1.05,880.17],[2,1.01,7]],"ltp":1.05,"tv":0.37,"id":13689566},{"batb":[[0,1.53,78.8],[1,1.18,246.5],[2,1.16,15.98]],"ltp":0.0,"tv":0.0,"id":12531094}]}]}
{"op":"mcm","clk":"4232673519","pt":1631523787156,"mc":[{"id":"1.187594273","rc":[{"batb":[[0,2.4,9.14],[1,2.38,30.26],[2,1.05,880.17]],"ltp":1.05,"tv":0.37,"id":13689566},{"batb":[[0,1.54,23.71],[1,1.53,78.8],[2,1.18,246.5]],"ltp":0.0,"tv":0.0,"id":12531094}]}]}
{"op":"mcm","clk":"4232685894","pt":1631524024869,"mc":[{"id":"1.187594273","rc":[{"batb":[[2,1.01,7]],"ltp":1.05,"tv":0.37,"id":13689566}]}]}
{"op":"mcm","clk":"4232686185","pt":1631524030691,"mc":[{"id":"1.187594273","rc":[{"batl":[[2,2.4,44.02]],"ltp":0.0,"tv":0.0,"id":12531094}]}]}
{"op":"mcm","clk":"4232735220","pt":1631524759816,"mc":[{"id":"1.187594273","rc":[{"batb":[[2,2.36,2.66]],"ltp":1.05,"tv":0.37,"id":13689566},{"batb":[[2,1.52,2.66]],"ltp":0.0,"tv":0.0,"id":12531094}]}]}
{"op":"mcm","clk":"4232736727","pt":1631524790580,"mc":[{"id":"1.187594273","rc":[{"batl":[[0,2.16,2.66],[1,2.4,44.02],[2,2.4,0]],"ltp":0.0,"tv":0.0,"id":12531094}]}]}
{"op":"mcm","clk":"4232736742","pt":1631524790683,"mc":[{"id":"1.187594273","rc":[{"batl":[[0,1.71,100],[1,2.16,2.66],[2,2.4,44.02]],"ltp":0.0,"tv":0.0,"id":12531094}]}]}
{"op":"mcm","clk":"4232771632","pt":1631525507521,"mc":[{"id":"1.187594273","marketDefinition":{"bspMarket":false,"turnInPlayEnabled":true,"persistenceEnabled":true,"marketBaseRate":5.0,"eventId":"30897691","eventTypeId":"2","numberOfWinners":1,"bettingType":"ODDS","marketType":"MATCH_ODDS","marketTime":"2021-09-13T09:30:00.000Z","suspendTime":"2021-09-13T09:30:00.000Z","bspReconciled":false,"complete":true,"inPlay":true,"crossMatching":true,"runnersVoidable":false,"numberOfActiveRunners":2,"betDelay":5,"status":"OPEN","runners":[{"status":"ACTIVE","sortPriority":1,"id":12531094,"name":"S Djoubri"},{"status":"ACTIVE","sortPriority":2,"id":13689566,"name":"E Shalimova"}],"regulators":["MR_INT"],"countryCode":"GB","discountAllowed":true,"timezone":"GMT","openDate":"2021-09-13T09:30:00.000Z","version":4030508223,"name":"Match Odds","eventName":"S Djoubri v E Shalimova"},"rc":[{"batb":[[0,1.01,7],[1,2.38,0],[2,2.36,0]],"ltp":1.05,"tv":0.37,"id":13689566},{"batb":[[0,1.01,7],[1,1.53,0],[2,1.52,0]],"batl":[[1,2.16,0],[2,2.4,0]],"ltp":0.0,"tv":0.0,"id":12531094}]}]}
{"op":"mcm","clk":"4232816589","pt":1631526207619,"mc":[{"id":"1.187594273","marketDefinition":{"bspMarket":false,"turnInPlayEnabled":true,"persistenceEnabled":true,"marketBaseRate":5.0,"eventId":"30897691","eventTypeId":"2","numberOfWinners":1,"bettingType":"ODDS","marketType":"MATCH_ODDS","marketTime":"2021-09-13T09:45:00.000Z","suspendTime":"2021-09-13T09:45:00.000Z","bspReconciled":false,"complete":true,"inPlay":true,"crossMatching":true,"runnersVoidable":false,"numberOfActiveRunners":2,"betDelay":5,"status":"OPEN","runners":[{"status":"ACTIVE","sortPriority":1,"id":12531094,"name":"S Djoubri"},{"status":"ACTIVE","sortPriority":2,"id":13689566,"name":"E Shalimova"}],"regulators":["MR_INT"],"countryCode":"GB","discountAllowed":true,"timezone":"GMT","openDate":"2021-09-13T09:30:00.000Z","version":4030512632,"name":"Match Odds","eventName":"S Djoubri v E Shalimova"}}]}
{"op":"mcm","clk":"4232816670","pt":1631526208624,"mc":[{"id":"1.187594273","marketDefinition":{"bspMarket":false,"turnInPlayEnabled":true,"persistenceEnabled":true,"marketBaseRate":5.0,"eventId":"30897691","eventTypeId":"2","numberOfWinners":1,"bettingType":"ODDS","marketType":"MATCH_ODDS","marketTime":"2021-09-13T09:45:00.000Z","suspendTime":"2021-09-13T09:45:00.000Z","bspReconciled":false,"complete":true,"inPlay":true,"crossMatching":true,"runnersVoidable":false,"numberOfActiveRunners":2,"betDelay":5,"status":"OPEN","runners":[{"status":"ACTIVE","sortPriority":1,"id":12531094,"name":"S Djoubri"},{"status":"ACTIVE","sortPriority":2,"id":13689566,"name":"E Shalimova"}],"regulators":["MR_INT"],"countryCode":"GB","discountAllowed":true,"timezone":"GMT","openDate":"2021-09-13T09:45:00.000Z","version":4030512632,"name":"Match Odds","eventName":"S Djoubri v E Shalimova"}}]}
{"op":"mcm","clk":"4232847616","pt":1631526714240,"mc":[{"id":"1.187594273","marketDefinition":{"bspMarket":false,"turnInPlayEnabled":true,"persistenceEnabled":true,"marketBaseRate":5.0,"eventId":"30897691","eventTypeId":"2","numberOfWinners":1,"bettingType":"ODDS","marketType":"MATCH_ODDS","marketTime":"2021-09-13T09:51:53.000Z","suspendTime":"2021-09-13T09:51:53.000Z","bspReconciled":false,"complete":true,"inPlay":true,"crossMatching":true,"runnersVoidable":false,"numberOfActiveRunners":2,"betDelay":5,"status":"OPEN","runners":[{"status":"ACTIVE","sortPriority":1,"id":12531094,"name":"S Djoubri"},{"status":"ACTIVE","sortPriority":2,"id":13689566,"name":"E Shalimova"}],"regulators":["MR_INT"],"countryCode":"GB","discountAllowed":true,"timezone":"GMT","openDate":"2021-09-13T09:45:00.000Z","version":4030517950,"name":"Match Odds","eventName":"S Djoubri v E Shalimova"}}]}
{"op":"mcm","clk":"4232847812","pt":1631526717255,"mc":[{"id":"1.187594273","marketDefinition":{"bspMarket":false,"turnInPlayEnabled":true,"persistenceEnabled":true,"marketBaseRate":5.0,"eventId":"30897691","eventTypeId":"2","numberOfWinners":1,"bettingType":"ODDS","marketType":"MATCH_ODDS","marketTime":"2021-09-13T09:51:53.000Z","suspendTime":"2021-09-13T09:51:53.000Z","bspReconciled":false,"complete":true,"inPlay":true,"crossMatching":true,"runnersVoidable":false,"numberOfActiveRunners":2,"betDelay":5,"status":"OPEN","runners":[{"status":"ACTIVE","sortPriority":1,"id":12531094,"name":"S Djoubri"},{"status":"ACTIVE","sortPriority":2,"id":13689566,"name":"E Shalimova"}],"regulators":["MR_INT"],"countryCode":"GB","discountAllowed":true,"timezone":"GMT","openDate":"2021-09-13T09:51:53.000Z","version":4030517950,"name":"Match Odds","eventName":"S Djoubri v E Shalimova"}}]}
{"op":"mcm","clk":"4232855641","pt":1631526841811,"mc":[{"id":"1.187594273","rc":[{"trd":[[2.4,35.56]],"ltp":2.4,"tv":35.93,"id":13689566},{"trd":[[1.71,49.91]],"batl":[[0,1.71,50.09]],"ltp":1.71,"tv":49.91,"id":12531094}],"tv":85.84}]}
{"op":"mcm","clk":"4232856080","pt":1631526849803,"mc":[{"id":"1.187594273","rc":[{"trd":[[1.71,59.51]],"batl":[[0,1.71,45.29]],"ltp":1.71,"tv":59.51,"id":12531094}],"tv":95.45}]}
{"op":"mcm","clk":"4232856423","pt":1631526855599,"mc":[{"id":"1.187594273","rc":[{"trd":[[2.4,54.61]],"ltp":2.4,"tv":54.98,"id":13689566},{"trd":[[1.71,86.25]],"batl":[[0,1.71,18.55]],"ltp":1.71,"tv":86.25,"id":12531094}],"tv":141.24}]}
{"op":"mcm","clk":"4232856446","pt":1631526856004,"mc":[{"id":"1.187594273","rc":[{"trd":[[2.4,67.83]],"ltp":2.4,"tv":68.2,"id":13689566},{"trd":[[1.71,104.8]],"ltp":1.71,"tv":104.8,"id":12531094}],"tv":173.01}]}
{"op":"mcm","clk":"4232861087","pt":1631526946475,"mc":[{"id":"1.187594273","rc":[{"batb":[[0,1.62,421.99],[1,1.01,7]],"batl":[[0,2.6,261.64]],"ltp":1.71,"tv":104.8,"id":12531094}]}]}
{"op":"mcm","clk":"4232863105","pt":1631526988732,"mc":[{"id":"1.187594273","rc":[{"batb":[[0,1.01,7],[1,1.01,0]],"ltp":1.71,"tv":104.8,"id":12531094}]}]}
{"op":"mcm","clk":"4232863439","pt":1631526994268,"mc":[{"id":"1.187594273","rc":[{"batb":[[0,1.67,416.23],[1,1.01,7]],"ltp":1.71,"tv":104.8,"id":12531094}]}]}
{"op":"mcm","clk":"4232865584","pt":1631527030523,"mc":[{"id":"1.187594273","rc":[{"batb":[[0,1.01,7],[1,1.01,0]],"ltp":1.71,"tv":104.8,"id":12531094}]}]}
{"op":"mcm","clk":"4232865925","pt":1631527035695,"mc":[{"id":"1.187594273","rc":[{"batb":[[0,1.74,410.67],[1,1.01,7]],"batl":[[0,2.92,224.75]],"ltp":1.71,"tv":104.8,"id":12531094}]}]}
{"op":"mcm","clk":"4232887988","pt":1631527434740,"mc":[{"id":"1.187594273","rc":[{"batb":[[0,1.01,7],[1,1.01,0]],"ltp":1.71,"tv":104.8,"id":12531094}]}]}
{"op":"mcm","clk":"4232926610","pt":1631528071851,"mc":[{"id":"1.187594273","rc":[{"batb":[[0,1.77,408.62],[1,1.01,7]],"batl":[[0,3,216.82]],"ltp":1.71,"tv":104.8,"id":12531094}]}]}
{"op":"mcm","clk":"4232936820","pt":1631528178767,"mc":[{"id":"1.187594273","rc":[{"batb":[[0,1.01,7],[1,1.01,0]],"ltp":1.71,"tv":104.8,"id":12531094}]}]}
{"op":"mcm","clk":"4232937148","pt":1631528184465,"mc":[{"id":"1.187594273","rc":[{"batb":[[0,1.86,404.92],[1,1.01,7]],"ltp":1.71,"tv":104.8,"id":12531094}]}]}
{"op":"mcm","clk":"4232943563","pt":1631528296830,"mc":[{"id":"1.187594273","rc":[{"batl":[[0,3,236.82]],"ltp":1.71,"tv":104.8,"id":12531094}]}]}
{"op":"mcm","clk":"4232946507","pt":1631528351225,"mc":[{"id":"1.187594273","rc":[{"batl":[[0,3,216.82]],"ltp":1.71,"tv":104.8,"id":12531094}]}]}
{"op":"mcm","clk":"4232952428","pt":1631528439055,"mc":[{"id":"1.187594273","rc":[{"batb":[[0,1.01,7],[1,1.01,0]],"ltp":1.71,"tv":104.8,"id":12531094}]}]}
{"op":"mcm","clk":"4232952798","pt":1631528444852,"mc":[{"id":"1.187594273","rc":[{"batb":[[0,1.7,415.78],[1,1.01,7]],"batl":[[0,2.82,234.93]],"ltp":1.71,"tv":104.8,"id":12531094}]}]}
{"op":"mcm","clk":"4232959745","pt":1631528563912,"mc":[{"id":"1.187594273","rc":[{"batl":[[0,2.6,261.64]],"ltp":1.71,"tv":104.8,"id":12531094}]}]}
{"op":"mcm","clk":"4232961992","pt":1631528604855,"mc":[{"id":"1.187594273","rc":[{"batb":[[0,1.01,7],[1,1.01,0]],"ltp":1.71,"tv":104.8,"id":12531094}]}]}
{"op":"mcm","clk":"4232962280","pt":1631528610461,"mc":[{"id":"1.187594273","rc":[{"batb":[[0,1.58,423.04],[1,1.01,7]],"batl":[[0,2.5,278.88]],"ltp":1.71,"tv":104.8,"id":12531094}]}]}
{"op":"mcm","clk":"4232963970","pt":1631528641614,"mc":[{"id":"1.187594273","rc":[{"batb":[[0,1.01,7],[1,1.01,0]],"ltp":1.71,"tv":104.8,"id":12531094}]}]}
{"op":"mcm","clk":"4232964275","pt":1631528647018,"mc":[{"id":"1.187594273","rc":[{"batb":[[0,1.62,421.99],[1,1.01,7]],"ltp":1.71,"tv":104.8,"id":12531094}]}]}
{"op":"mcm","clk":"4232967848","pt":1631528712140,"mc":[{"id":"1.187594273","rc":[{"batb":[[0,1.01,7],[1,1.01,0]],"ltp":1.71,"tv":104.8,"id":12531094}]}]}
{"op":"mcm","clk":"4232968290","pt":1631528718147,"mc":[{"id":"1.187594273","rc":[{"batb":[[0,1.46,442.58],[1,1.01,7]],"batl":[[0,2.22,334.21]],"ltp":1.71,"tv":104.8,"id":12531094}]}]}
{"op":"mcm","clk":"4232971546","pt":1631528776097,"mc":[{"id":"1.187594273","rc":[{"batl":[[0,2.1,369.04]],"ltp":1.71,"tv":104.8,"id":12531094}]}]}
{"op":"mcm","clk":"4232972561","pt":1631528793963,"mc":[{"id":"1.187594273","rc":[{"batb":[[0,1.01,7],[1,1.01,0]],"ltp":1.71,"tv":104.8,"id":12531094}]}]}
{"op":"mcm","clk":"4232972917","pt":1631528800448,"mc":[{"id":"1.187594273","rc":[{"batb":[[0,1.34,472.77],[1,1.01,7]],"batl":[[0,1.95,416.34]],"ltp":1.71,"tv":104.8,"id":12531094}]}]}
{"op":"mcm","clk":"4232984173","pt":1631528994436,"mc":[{"id":"1.187594273","rc":[{"batb":[[0,1.01,7],[1,1.01,0]],"ltp":1.71,"tv":104.8,"id":12531094}]}]}
{"op":"mcm","clk":"4232984570","pt":1631529000547,"mc":[{"id":"1.187594273","rc":[{"batb":[[0,1.28,493.56],[1,1.01,7]],"batl":[[0,1.82,476.51]],"ltp":1.71,"tv":104.8,"id":12531094}]}]}
{"op":"mcm","clk":"4232985663","pt":1631529013864,"mc":[{"id":"1.187594273","rc":[{"batb":[[0,1.01,7],[1,1.01,0]],"ltp":1.71,"tv":104.8,"id":12531094}]}]}
{"op":"mcm","clk":"4232986140","pt":1631529019785,"mc":[{"id":"1.187594273","rc":[{"batb":[[0,1.23,524.63],[1,1.01,7]],"batl":[[0,1.73,535.9]],"ltp":1.71,"tv":104.8,"id":12531094}]}]}
{"op":"mcm","clk":"4232989005","pt":1631529059792,"mc":[{"id":"1.187594273","rc":[{"batb":[[0,1.01,7],[1,1.01,0]],"ltp":1.71,"tv":104.8,"id":12531094}]}]}
{"op":"mcm","clk":"4232989421","pt":1631529065300,"mc":[{"id":"1.187594273","rc":[{"batb":[[0,1.2,539.24],[1,1.01,7]],"batl":[[0,1.66,588.96]],"ltp":1.71,"tv":104.8,"id":12531094}]}]}
{"op":"mcm","clk":"4232992677","pt":1631529109694,"mc":[{"id":"1.187594273","rc":[{"batb":[[0,1.01,7],[1,1.01,0]],"ltp":1.71,"tv":104.8,"id":12531094}]}]}
{"op":"mcm","clk":"4232993115","pt":1631529114961,"mc":[{"id":"1.187594273","rc":[{"batb":[[0,1.23,524.63],[1,1.01,7]],"ltp":1.71,"tv":104.8,"id":12531094}]}]}
{"op":"mcm","clk":"4232995618","pt":1631529151622,"mc":[{"id":"1.187594273","rc":[{"batb":[[0,1.01,7],[1,1.01,0]],"ltp":1.71,"tv":104.8,"id":12531094}]}]}
{"op":"mcm","clk":"4232996023","pt":1631529157744,"mc":[{"id":"1.187594273","rc":[{"batb":[[0,1.18,558.4],[1,1.01,7]],"ltp":1.71,"tv":104.8,"id":12531094}]}]}
{"op":"mcm","clk":"4232997802","pt":1631529183177,"mc":[{"id":"1.187594273","rc":[{"batl":[[0,1.58,660.85]],"ltp":1.71,"tv":104.8,"id":12531094}]}]}
{"op":"mcm","clk":"4233012001","pt":1631529357922,"mc":[{"id":"1.187594273","rc":[{"batb":[[0,1.01,7],[1,1.01,0]],"ltp":1.71,"tv":104.8,"id":12531094}]}]}
{"op":"mcm","clk":"4233012578","pt":1631529364033,"mc":[{"id":"1.187594273","rc":[{"batb":[[0,1.2,539.24],[1,1.01,7]],"ltp":1.71,"tv":104.8,"id":12531094}]}]}
{"op":"mcm","clk":"4233014342","pt":1631529383448,"mc":[{"id":"1.187594273","rc":[{"batb":[[0,1.01,7],[1,1.01,0]],"ltp":1.71,"tv":104.8,"id":12531094}]}]}
{"op":"mcm","clk":"4233014795","pt":1631529389467,"mc":[{"id":"1.187594273","rc":[{"batb":[[0,1.22,531.25],[1,1.01,7]],"ltp":1.71,"tv":104.8,"id":12531094}]}]}
{"op":"mcm","clk":"4233018736","pt":1631529445757,"mc":[{"id":"1.187594273","rc":[{"batb":[[0,1.01,7],[1,1.01,0]],"ltp":1.71,"tv":104.8,"id":12531094}]}]}
{"op":"mcm","clk":"4233019085","pt":1631529451556,"mc":[{"id":"1.187594273","rc":[{"batb":[[0,1.16,585.23],[1,1.01,7]],"ltp":1.71,"tv":104.8,"id":12531094}]}]}
{"op":"mcm","clk":"4233021285","pt":1631529483733,"mc":[{"id":"1.187594273","rc":[{"batb":[[0,1.01,7],[1,1.01,0]],"ltp":1.71,"tv":104.8,"id":12531094}]}]}
{"op":"mcm","clk":"4233021665","pt":1631529489703,"mc":[{"id":"1.187594273","rc":[{"batb":[[0,1.14,620.09],[1,1.01,7]],"ltp":1.71,"tv":104.8,"id":12531094}]}]}
{"op":"mcm","clk":"4233024362","pt":1631529533076,"mc":[{"id":"1.187594273","rc":[{"batb":[[0,1.01,7],[1,1.01,0]],"ltp":1.71,"tv":104.8,"id":12531094}]}]}
{"op":"mcm","clk":"4233024650","pt":1631529538679,"mc":[{"id":"1.187594273","rc":[{"batb":[[0,1.1,734.62],[1,1.01,7]],"batl":[[0,1.48,797.33]],"ltp":1.71,"tv":104.8,"id":12531094}]}]}
{"op":"mcm","clk":"4233031164","pt":1631529668938,"mc":[{"id":"1.187594273","rc":[{"batb":[[0,1.01,7],[1,1.01,0]],"ltp":1.71,"tv":104.8,"id":12531094}]}]}
{"op":"mcm","clk":"4233047265","pt":1631529954089,"mc":[{"id":"1.187594273","rc":[{"batb":[[0,1.08,813.6],[1,1.01,7]],"batl":[[0,1.44,871.28]],"ltp":1.71,"tv":104.8,"id":12531094}]}]}
{"op":"mcm","clk":"4233049204","pt":1631529978519,"mc":[{"id":"1.187594273","rc":[{"batb":[[0,1.01,7],[1,1.01,0]],"ltp":1.71,"tv":104.8,"id":12531094}]}]}
{"op":"mcm","clk":"4233049571","pt":1631529984510,"mc":[{"id":"1.187594273","rc":[{"batb":[[0,1.06,1009.59],[1,1.01,7]],"ltp":1.71,"tv":104.8,"id":12531094}]}]}
{"op":"mcm","clk":"4233051414","pt":1631530010154,"mc":[{"id":"1.187594273","rc":[{"batb":[[0,1.01,7],[1,1.01,0]],"ltp":1.71,"tv":104.8,"id":12531094}]}]}
{"op":"mcm","clk":"4233051889","pt":1631530016048,"mc":[{"id":"1.187594273","rc":[{"batb":[[0,1.08,813.6],[1,1.01,7]],"ltp":1.71,"tv":104.8,"id":12531094}]}]}
{"op":"mcm","clk":"4233052885","pt":1631530030467,"mc":[{"id":"1.187594273","rc":[{"batb":[[0,1.01,7],[1,1.01,0]],"ltp":1.71,"tv":104.8,"id":12531094}]}]}
{"op":"mcm","clk":"4233053333","pt":1631530036395,"mc":[{"id":"1.187594273","rc":[{"batb":[[0,1.1,734.62],[1,1.01,7]],"ltp":1.71,"tv":104.8,"id":12531094}]}]}
{"op":"mcm","clk":"4233054833","pt":1631530060013,"mc":[{"id":"1.187594273","rc":[{"batb":[[0,1.01,7],[1,1.01,0]],"ltp":1.71,"tv":104.8,"id":12531094}]}]}
{"op":"mcm","clk":"4233063694","pt":1631530065846,"mc":[{"id":"1.187594273","rc":[{"batb":[[0,1.08,813.6],[1,1.01,7]],"ltp":1.71,"tv":104.8,"id":12531094}]}]}
{"op":"mcm","clk":"4233064397","pt":1631530075606,"mc":[{"id":"1.187594273","rc":[{"batb":[[1,1.01,9]],"ltp":1.71,"tv":104.8,"id":12531094}]}]}
{"op":"mcm","clk":"4233064623","pt":1631530079225,"mc":[{"id":"1.187594273","rc":[{"batb":[[0,1.01,9],[1,1.01,0]],"ltp":1.71,"tv":104.8,"id":12531094}]}]}
{"op":"mcm","clk":"4233065006","pt":1631530084721,"mc":[{"id":"1.187594273","rc":[{"batb":[[0,1.06,1009.59],[1,1.01,9]],"ltp":1.71,"tv":104.8,"id":12531094}]}]}
{"op":"mcm","clk":"4233065495","pt":1631530091558,"mc":[{"id":"1.187594273","rc":[{"batb":[[0,1.01,9],[1,1.01,0]],"ltp":1.71,"tv":104.8,"id":12531094}]}]}
{"op":"mcm","clk":"4233065901","pt":1631530097079,"mc":[{"id":"1.187594273","rc":[{"batb":[[0,1.1,734.62],[1,1.01,9]],"ltp":1.71,"tv":104.8,"id":12531094}]}]}
{"op":"mcm","clk":"4233068712","pt":1631530139385,"mc":[{"id":"1.187594273","rc":[{"batb":[[0,1.01,9],[1,1.01,0]],"ltp":1.71,"tv":104.8,"id":12531094}]}]}
{"op":"mcm","clk":"4233069107","pt":1631530145613,"mc":[{"id":"1.187594273","rc":[{"batb":[[0,1.08,813.6],[1,1.01,9]],"ltp":1.71,"tv":104.8,"id":12531094}]}]}
{"op":"mcm","clk":"4233070301","pt":1631530163817,"mc":[{"id":"1.187594273","rc":[{"batb":[[0,1.01,9],[1,1.01,0]],"ltp":1.71,"tv":104.8,"id":12531094}]}]}
{"op":"mcm","clk":"4233070688","pt":1631530170159,"mc":[{"id":"1.187594273","rc":[{"batb":[[0,1.06,1009.59],[1,1.01,9]],"ltp":1.71,"tv":104.8,"id":12531094}]}]}
{"op":"mcm","clk":"4233071936","pt":1631530187284,"mc":[{"id":"1.187594273","rc":[{"batb":[[0,1.01,9],[1,1.01,0]],"ltp":1.71,"tv":104.8,"id":12531094}]}]}
{"op":"mcm","clk":"4233072368","pt":1631530193381,"mc":[{"id":"1.187594273","rc":[{"batb":[[0,1.05,1086.47],[1,1.01,9]],"ltp":1.71,"tv":104.8,"id":12531094}]}]}
{"op":"mcm","clk":"4233077095","pt":1631530256475,"mc":[{"id":"1.187594273","rc":[{"batb":[[0,1.01,9],[1,1.01,0]],"ltp":1.71,"tv":104.8,"id":12531094}]}]}
{"op":"mcm","clk":"4233077552","pt":1631530262074,"mc":[{"id":"1.187594273","rc":[{"batb":[[0,1.04,1254.04],[1,1.01,9]],"batl":[[0,1.36,1042.16]],"ltp":1.71,"tv":104.8,"id":12531094}]}]}
{"op":"mcm","clk":"4233079615","pt":1631530292107,"mc":[{"id":"1.187594273","rc":[{"batl":[[0,1.05,183.8],[1,1.36,1042.16]],"ltp":1.71,"tv":104.8,"id":12531094}]}]}
{"op":"mcm","clk":"4233080185","pt":1631530300290,"mc":[{"id":"1.187594273","rc":[{"batb":[[0,1.01,9],[1,1.01,0]],"ltp":1.71,"tv":104.8,"id":12531094}]}]}
{"op":"mcm","clk":"4233080346","pt":1631530302511,"mc":[{"id":"1.187594273","rc":[{"batl":[[0,1.36,1042.16],[1,1.36,0]],"ltp":1.71,"tv":104.8,"id":12531094}]}]}
{"op":"mcm","clk":"4233080655","pt":1631530306412,"mc":[{"id":"1.187594273","rc":[{"batb":[[0,1.05,1086.47],[1,1.01,9]],"ltp":1.71,"tv":104.8,"id":12531094}]}]}
{"op":"mcm","clk":"4233080725","pt":1631530307608,"mc":[{"id":"1.187594273","rc":[{"trd":[[1.05,367.7]],"batb":[[0,1.05,902.58]],"ltp":1.05,"tv":472.5,"id":12531094}],"tv":540.7}]}
{"op":"mcm","clk":"4233082893","pt":1631530335968,"mc":[{"id":"1.187594273","rc":[{"batb":[[0,1.01,9],[1,1.01,0]],"ltp":1.05,"tv":472.5,"id":12531094}]}]}
{"op":"mcm","clk":"4233083345","pt":1631530342146,"mc":[{"id":"1.187594273","rc":[{"batb":[[0,1.06,800.22],[1,1.01,9]],"ltp":1.05,"tv":472.5,"id":12531094}]}]}
{"op":"mcm","clk":"4233085661","pt":1631530373599,"mc":[{"id":"1.187594273","rc":[{"batb":[[0,1.01,9],[1,1.01,0]],"ltp":1.05,"tv":472.5,"id":12531094}]}]}
{"op":"mcm","clk":"4233086085","pt":1631530379512,"mc":[{"id":"1.187594273","rc":[{"batb":[[0,1.09,583.79],[1,1.01,9]],"ltp":1.05,"tv":472.5,"id":12531094}]}]}
{"op":"mcm","clk":"4233090706","pt":1631530444808,"mc":[{"id":"1.187594273","rc":[{"batb":[[0,1.01,9],[1,1.01,0]],"ltp":1.05,"tv":472.5,"id":12531094}]}]}
{"op":"mcm","clk":"4233091090","pt":1631530450404,"mc":[{"id":"1.187594273","rc":[{"batb":[[0,1.06,769.33],[1,1.01,9]],"ltp":1.05,"tv":472.5,"id":12531094}]}]}
{"op":"mcm","clk":"4233092856","pt":1631530475351,"mc":[{"id":"1.187594273","rc":[{"batb":[[0,1.01,9],[1,1.01,0]],"ltp":1.05,"tv":472.5,"id":12531094}]}]}
{"op":"mcm","clk":"4233093178","pt":1631530480733,"mc":[{"id":"1.187594273","rc":[{"batb":[[0,1.08,630.79],[1,1.01,9]],"ltp":1.05,"tv":472.5,"id":12531094}]}]}
{"op":"mcm","clk":"4233094671","pt":1631530503763,"mc":[{"id":"1.187594273","rc":[{"batb":[[0,1.01,9],[1,1.01,0]],"ltp":1.05,"tv":472.5,"id":12531094}]}]}
{"op":"mcm","clk":"4233095115","pt":1631530510287,"mc":[{"id":"1.187594273","rc":[{"batb":[[0,1.06,769.33],[1,1.01,9]],"ltp":1.05,"tv":472.5,"id":12531094}]}]}
{"op":"mcm","clk":"4233098071","pt":1631530554727,"mc":[{"id":"1.187594273","rc":[{"batb":[[0,1.01,9],[1,1.01,0]],"ltp":1.05,"tv":472.5,"id":12531094}]}]}
{"op":"mcm","clk":"4233098548","pt":1631530560752,"mc":[{"id":"1.187594273","rc":[{"batb":[[0,1.04,1064.04],[1,1.01,9]],"ltp":1.05,"tv":472.5,"id":12531094}]}]}
{"op":"mcm","clk":"4233101029","pt":1631530593258,"mc":[{"id":"1.187594273","rc":[{"batb":[[0,1.01,9],[1,1.01,0]],"ltp":1.05,"tv":472.5,"id":12531094}]}]}
{"op":"mcm","clk":"4233101476","pt":1631530599098,"mc":[{"id":"1.187594273","rc":[{"batb":[[0,1.06,769.33],[1,1.01,9]],"ltp":1.05,"tv":472.5,"id":12531094}]}]}
{"op":"mcm","clk":"4233103904","pt":1631530632041,"mc":[{"id":"1.187594273","rc":[{"batb":[[0,1.01,9],[1,1.01,0]],"ltp":1.05,"tv":472.5,"id":12531094}]}]}
{"op":"mcm","clk":"4233104319","pt":1631530637339,"mc":[{"id":"1.187594273","rc":[{"batb":[[0,1.04,1088.26],[1,1.01,9]],"ltp":1.05,"tv":472.5,"id":12531094}]}]}
{"op":"mcm","clk":"4233107187","pt":1631530678695,"mc":[{"id":"1.187594273","rc":[{"batb":[[0,1.01,9],[1,1.01,0]],"ltp":1.05,"tv":472.5,"id":12531094}]}]}
{"op":"mcm","clk":"4233107580","pt":1631530684221,"mc":[{"id":"1.187594273","rc":[{"batb":[[0,1.06,769.33],[1,1.01,9]],"ltp":1.05,"tv":472.5,"id":12531094}]}]}
{"op":"mcm","clk":"4233109453","pt":1631530712227,"mc":[{"id":"1.187594273","rc":[{"batb":[[0,1.01,9],[1,1.01,0]],"ltp":1.05,"tv":472.5,"id":12531094}]}]}
{"op":"mcm","clk":"4233109914","pt":1631530718622,"mc":[{"id":"1.187594273","rc":[{"batb":[[0,1.04,1088.26],[1,1.01,9]],"ltp":1.05,"tv":472.5,"id":12531094}]}]}
{"op":"mcm","clk":"4233111250","pt":1631530739773,"mc":[{"id":"1.187594273","rc":[{"batb":[[0,1.01,9],[1,1.01,0]],"ltp":1.05,"tv":472.5,"id":12531094}]}]}
{"op":"mcm","clk":"4233111630","pt":1631530745855,"mc":[{"id":"1.187594273","rc":[{"batb":[[0,1.06,769.33],[1,1.01,9]],"ltp":1.05,"tv":472.5,"id":12531094}]}]}
{"op":"mcm","clk":"4233113347","pt":1631530772210,"mc":[{"id":"1.187594273","rc":[{"batb":[[0,1.01,9],[1,1.01,0]],"ltp":1.05,"tv":472.5,"id":12531094}]}]}
{"op":"mcm","clk":"4233113682","pt":1631530778299,"mc":[{"id":"1.187594273","rc":[{"batb":[[0,1.08,630.79],[1,1.01,9]],"ltp":1.05,"tv":472.5,"id":12531094}]}]}
{"op":"mcm","clk":"4233115783","pt":1631530807669,"mc":[{"id":"1.187594273","rc":[{"trd":[[2.4,67.76]],"ltp":2.4,"tv":68.13,"id":13689566},{"trd":[[1.05,367.33],[1.71,104.8]],"batb":[[0,1.01,9],[1,1.01,0]],"batl":[[0,1.36,1040.12]],"ltp":1.05,"tv":472.13,"id":12531094}],"tv":540.26}]}
{"op":"mcm","clk":"4233116215","pt":1631530813654,"mc":[{"id":"1.187594273","rc":[{"batb":[[0,1.06,767.82],[1,1.01,9]],"ltp":1.05,"tv":472.13,"id":12531094}]}]}
{"op":"mcm","clk":"4233118906","pt":1631530851410,"mc":[{"id":"1.187594273","rc":[{"batb":[[0,1.01,9],[1,1.01,0]],"ltp":1.05,"tv":472.13,"id":12531094}]}]}
{"op":"mcm","clk":"4233119297","pt":1631530856793,"mc":[{"id":"1.187594273","rc":[{"batb":[[0,1.04,1086.12],[1,1.01,9]],"ltp":1.05,"tv":472.13,"id":12531094}]}]}
{"op":"mcm","clk":"4233120703","pt":1631530876925,"mc":[{"id":"1.187594273","rc":[{"batb":[[0,1.01,9],[1,1.01,0]],"ltp":1.05,"tv":472.13,"id":12531094}]}]}
{"op":"mcm","clk":"4233121183","pt":1631530883354,"mc":[{"id":"1.187594273","rc":[{"batb":[[0,1.03,1359.51],[1,1.01,9]],"ltp":1.05,"tv":472.13,"id":12531094}]}]}
{"op":"mcm","clk":"4233122581","pt":1631530900675,"mc":[{"id":"1.187594273","rc":[{"batl":[[0,1.31,29.05],[1,1.36,1040.12]],"ltp":1.05,"tv":472.13,"id":12531094}]}]}
{"op":"mcm","clk":"4233125991","pt":1631530938827,"mc":[{"id":"1.187594273","rc":[{"batb":[[0,1.01,9],[1,1.01,0]],"ltp":1.05,"tv":472.13,"id":12531094}]}]}
{"op":"mcm","clk":"4233126519","pt":1631530944919,"mc":[{"id":"1.187594273","rc":[{"batb":[[0,1.02,1961.01],[1,1.01,9]],"ltp":1.05,"tv":472.13,"id":12531094}]}]}
{"op":"mcm","clk":"4233127977","pt":1631530961676,"mc":[{"id":"1.187594273","rc":[{"batl":[[0,1.29,29.05],[1,1.31,29.05],[2,1.36,1040.12]],"ltp":1.05,"tv":472.13,"id":12531094}]}]}
{"op":"mcm","clk":"4233128676","pt":1631530969360,"mc":[{"id":"1.187594273","rc":[{"batb":[[0,1.01,9],[1,1.01,0]],"ltp":1.05,"tv":472.13,"id":12531094}]}]}
{"op":"mcm","clk":"4233129215","pt":1631530975080,"mc":[{"id":"1.187594273","rc":[{"batb":[[0,1.01,3742.54]],"ltp":1.05,"tv":472.13,"id":12531094}]}]}
{"op":"mcm","clk":"4233129428","pt":1631530977675,"mc":[{"id":"1.187594273","rc":[{"batl":[[0,1.31,29.05],[1,1.36,1040.12],[2,1.36,0]],"ltp":1.05,"tv":472.13,"id":12531094}]}]}
{"op":"mcm","clk":"4233129843","pt":1631530982783,"mc":[{"id":"1.187594273","rc":[{"batl":[[0,1.28,32.54],[1,1.31,29.05],[2,1.36,1040.12]],"ltp":1.05,"tv":472.13,"id":12531094}]}]}
{"op":"mcm","clk":"4233131322","pt":1631531000910,"mc":[{"id":"1.187594273","rc":[{"batb":[[0,1.01,9]],"ltp":1.05,"tv":472.13,"id":12531094}]}]}
{"op":"mcm","clk":"4233131820","pt":1631531007012,"mc":[{"id":"1.187594273","rc":[{"batb":[[0,1.02,1961.01],[1,1.01,9]],"ltp":1.05,"tv":472.13,"id":12531094}]}]}
{"op":"mcm","clk":"4233132330","pt":1631531012818,"mc":[{"id":"1.187594273","rc":[{"batl":[[1,1.36,1040.12],[2,1.36,0]],"ltp":1.05,"tv":472.13,"id":12531094}]}]}
{"op":"mcm","clk":"4233132743","pt":1631531017933,"mc":[{"id":"1.187594273","rc":[{"batl":[[0,1.27,44.16],[1,1.28,32.54],[2,1.36,1040.12]],"ltp":1.05,"tv":472.13,"id":12531094}]}]}
{"op":"mcm","clk":"4233134316","pt":1631531035498,"mc":[{"id":"1.187594273","rc":[{"batb":[[0,1.01,9],[1,1.01,0]],"ltp":1.05,"tv":472.13,"id":12531094}]}]}
{"op":"mcm","clk":"4233134810","pt":1631531041100,"mc":[{"id":"1.187594273","rc":[{"batb":[[0,1.01,3742.54]],"ltp":1.05,"tv":472.13,"id":12531094}]}]}
{"op":"mcm","clk":"4233136523","pt":1631531059730,"mc":[{"id":"1.187594273","rc":[{"batl":[[1,1.36,1040.12],[2,1.36,0]],"ltp":1.05,"tv":472.13,"id":12531094}]}]}
{"op":"mcm","clk":"4233136867","pt":1631531063728,"mc":[{"id":"1.187594273","rc":[{"batb":[[0,1.01,9]],"ltp":1.05,"tv":472.13,"id":12531094}]}]}
{"op":"mcm","clk":"4233136956","pt":1631531064818,"mc":[{"id":"1.187594273","rc":[{"batl":[[0,1.26,29.05],[1,1.27,44.16],[2,1.36,1040.12]],"ltp":1.05,"tv":472.13,"id":12531094}]}]}
{"op":"mcm","clk":"4233137367","pt":1631531069327,"mc":[{"id":"1.187594273","rc":[{"batb":[[0,1.01,3832.75]],"ltp":1.05,"tv":472.13,"id":12531094}]}]}
{"op":"mcm","clk":"4233140055","pt":1631531100398,"mc":[{"id":"1.187594273","rc":[{"batb":[[0,1.01,9]],"batl":[[2,1.36,0]],"ltp":1.05,"tv":472.13,"id":12531094}]}]}
{"op":"mcm","clk":"4233140292","pt":1631531102787,"mc":[{"id":"1.187594273","rc":[{"batl":[[1,1.27,0]],"ltp":1.05,"tv":472.13,"id":12531094}]}]}
{"op":"mcm","clk":"4233140623","pt":1631531105984,"mc":[{"id":"1.187594273","rc":[{"batl":[[0,170,36.3]],"ltp":2.4,"tv":68.13,"id":13689566},{"batl":[[1,1.3,1390.38]],"ltp":1.05,"tv":472.13,"id":12531094}]}]}
{"op":"mcm","clk":"4233140815","pt":1631531107968,"mc":[{"id":"1.187594273","rc":[{"batl":[[0,1.25,44.16],[1,1.26,29.05],[2,1.3,1390.38]],"ltp":1.05,"tv":472.13,"id":12531094}]}]}
{"op":"mcm","clk":"4233152008","pt":1631531230764,"mc":[{"id":"1.187594273","rc":[{"batl":[[1,1.3,1390.38],[2,1.3,0]],"ltp":1.05,"tv":472.13,"id":12531094}]}]}
{"op":"mcm","clk":"4233152424","pt":1631531235861,"mc":[{"id":"1.187594273","rc":[{"batl":[[0,1.25,73.21]],"ltp":1.05,"tv":472.13,"id":12531094}]}]}
{"op":"mcm","clk":"4233152501","pt":1631531236753,"mc":[{"id":"1.187594273","rc":[{"batl":[[0,1.25,29.05]],"ltp":1.05,"tv":472.13,"id":12531094}]}]}
{"op":"mcm","clk":"4233152931","pt":1631531241979,"mc":[{"id":"1.187594273","rc":[{"batl":[[0,1.24,44.16],[1,1.25,29.05],[2,1.3,1390.38]],"ltp":1.05,"tv":472.13,"id":12531094}]}]}
{"op":"mcm","clk":"4233155391","pt":1631531269701,"mc":[{"id":"1.187594273","rc":[{"batl":[[1,1.3,1390.38],[2,1.3,0]],"ltp":1.05,"tv":472.13,"id":12531094}]}]}
{"op":"mcm","clk":"4233155853","pt":1631531274784,"mc":[{"id":"1.187594273","rc":[{"batl":[[0,1.2,29.05],[1,1.24,44.16],[2,1.3,1390.38]],"ltp":1.05,"tv":472.13,"id":12531094}]}]}
{"op":"mcm","clk":"4233155927","pt":1631531275712,"mc":[{"id":"1.187594273","rc":[{"batl":[[1,1.3,1390.38],[2,1.3,0]],"ltp":1.05,"tv":472.13,"id":12531094}]}]}
{"op":"mcm","clk":"4233156338","pt":1631531280790,"mc":[{"id":"1.187594273","rc":[{"batl":[[0,1.19,44.16],[1,1.2,29.05],[2,1.3,1390.38]],"ltp":1.05,"tv":472.13,"id":12531094}]}]}
{"op":"mcm","clk":"4233159887","pt":1631531321650,"mc":[{"id":"1.187594273","rc":[{"trd":[[1.01,18]],"batl":[[0,1.01,86],[1,1.19,44.16],[2,1.2,29.05]],"ltp":1.01,"tv":490.13,"id":12531094}],"tv":558.26}]}
{"op":"mcm","clk":"4233165447","pt":1631531391861,"mc":[{"id":"1.187594273","rc":[{"batl":[[0,1.19,44.16],[1,1.2,29.05],[2,1.3,1390.38]],"ltp":1.01,"tv":490.13,"id":12531094}]}]}
{"op":"mcm","clk":"4233169422","pt":1631531444546,"mc":[{"id":"1.187594273","rc":[{"batl":[[2,1.3,0]],"ltp":1.01,"tv":490.13,"id":12531094}]}]}
{"op":"mcm","clk":"4233174563","pt":1631531512855,"mc":[{"id":"1.187594273","rc":[{"batl":[[0,1.18,766.61],[1,1.19,44.16],[2,1.2,29.05]],"ltp":1.01,"tv":490.13,"id":12531094}]}]}
{"op":"mcm","clk":"4233174753","pt":1631531515353,"mc":[{"id":"1.187594273","rc":[{"batl":[[0,1.17,56.22],[1,1.18,766.61],[2,1.19,44.16]],"ltp":1.01,"tv":490.13,"id":12531094}]}]}
{"op":"mcm","clk":"4233179581","pt":1631531582857,"mc":[{"id":"1.187594273","rc":[{"batl":[[2,1.2,29.05]],"ltp":1.01,"tv":490.13,"id":12531094}]}]}
{"op":"mcm","clk":"4233179933","pt":1631531588063,"mc":[{"id":"1.187594273","rc":[{"batl":[[0,1.09,44.16],[1,1.17,56.22],[2,1.18,766.61]],"ltp":1.01,"tv":490.13,"id":12531094}]}]}
{"op":"mcm","clk":"4233180847","pt":1631531600041,"mc":[{"id":"1.187594273","rc":[{"batl":[[0,1.09,73.21]],"ltp":1.01,"tv":490.13,"id":12531094}]}]}
{"op":"mcm","clk":"4233181988","pt":1631531613720,"mc":[{"id":"1.187594273","rc":[{"batl":[[0,1.08,396.93],[1,1.09,73.21],[2,1.17,56.22]],"ltp":1.01,"tv":490.13,"id":12531094}]}]}
{"op":"mcm","clk":"4233186517","pt":1631531675182,"mc":[{"id":"1.187594273","rc":[{"batl":[[0,1.01,17.04],[1,1.08,396.93],[2,1.09,73.21]],"ltp":1.01,"tv":490.13,"id":12531094}]}]}
{"op":"mcm","clk":"4233187733","pt":1631531690874,"mc":[{"id":"1.187594273","rc":[{"batl":[[2,1.09,29.05]],"ltp":1.01,"tv":490.13,"id":12531094}]}]}
{"op":"mcm","clk":"4233188223","pt":1631531696117,"mc":[{"id":"1.187594273","rc":[{"batl":[[1,1.07,44.16],[2,1.08,396.93]],"ltp":1.01,"tv":490.13,"id":12531094}]}]}
{"op":"mcm","clk":"4233191650","pt":1631531738543,"mc":[{"id":"1.187594273","rc":[{"batl":[[2,1.09,29.05]],"ltp":1.01,"tv":490.13,"id":12531094}]}]}
{"op":"mcm","clk":"4233192080","pt":1631531743651,"mc":[{"id":"1.187594273","rc":[{"batl":[[1,1.06,396.93],[2,1.07,44.16]],"ltp":1.01,"tv":490.13,"id":12531094}]}]}
{"op":"mcm","clk":"4233196505","pt":1631531796329,"mc":[{"id":"1.187594273","rc":[{"batl":[[0,1.01,4275.98]],"ltp":1.01,"tv":490.13,"id":12531094}]}]}
{"op":"mcm","clk":"4233198744","pt":1631531822858,"mc":[{"id":"1.187594273","marketDefinition":{"bspMarket":false,"turnInPlayEnabled":true,"persistenceEnabled":true,"marketBaseRate":5.0,"eventId":"30897691","eventTypeId":"2","numberOfWinners":1,"bettingType":"ODDS","marketType":"MATCH_ODDS","marketTime":"2021-09-13T09:51:53.000Z","suspendTime":"2021-09-13T09:51:53.000Z","bspReconciled":false,"complete":true,"inPlay":true,"crossMatching":true,"runnersVoidable":false,"numberOfActiveRunners":2,"betDelay":5,"status":"SUSPENDED","runners":[{"status":"ACTIVE","sortPriority":1,"id":12531094,"name":"S Djoubri"},{"status":"ACTIVE","sortPriority":2,"id":13689566,"name":"E Shalimova"}],"regulators":["MR_INT"],"countryCode":"GB","discountAllowed":true,"timezone":"GMT","openDate":"2021-09-13T09:51:53.000Z","version":4030582489,"name":"Match Odds","eventName":"S Djoubri v E Shalimova"}}]}
{"op":"mcm","clk":"4233199105","pt":1631531827857,"mc":[{"id":"1.187594273","tv":0.0}]}
{"op":"mcm","clk":"4233199188","pt":1631531828887,"mc":[{"id":"1.187594273","marketDefinition":{"bspMarket":false,"turnInPlayEnabled":true,"persistenceEnabled":true,"marketBaseRate":5.0,"eventId":"30897691","eventTypeId":"2","numberOfWinners":1,"bettingType":"ODDS","marketType":"MATCH_ODDS","marketTime":"2021-09-13T09:51:53.000Z","suspendTime":"2021-09-13T09:51:53.000Z","bspReconciled":false,"complete":true,"inPlay":true,"crossMatching":false,"runnersVoidable":false,"numberOfActiveRunners":0,"betDelay":5,"status":"CLOSED","settledTime":"2021-09-13T11:17:06.000Z","runners":[{"status":"WINNER","sortPriority":1,"id":12531094,"name":"S Djoubri"},{"status":"LOSER","sortPriority":2,"id":13689566,"name":"E Shalimova"}],"regulators":["MR_INT"],"countryCode":"GB","discountAllowed":true,"timezone":"GMT","openDate":"2021-09-13T09:51:53.000Z","version":4030582525,"name":"Match Odds","eventName":"S Djoubri v E Shalimova"}}]}
