{"op":"mcm","clk":"4234788252","pt":1631549913419,"mc":[{"id":"1.187560677","rc":[{"batb":[[0,4.1,2.94],[1,3.75,52.97],[2,1.3,5]],"ltp":7.2,"tv":1657.22,"id":7588306},{"batl":[[0,1.32,82.36],[1,1.39,18.43],[2,1.44,94.65]],"ltp":1.22,"tv":28019.82,"id":11439844}]}]}
{"op":"mcm","clk":"4234788902","pt":1631549919711,"mc":[{"id":"1.187560677","rc":[{"batb":[[0,4.4,2.66],[1,4.1,2.94],[2,3.75,52.97]],"ltp":7.2,"tv":1657.22,"id":7588306},{"batl":[[0,1.29,89.5],[1,1.32,82.36],[2,1.39,18.43]],"ltp":1.22,"tv":28019.82,"id":11439844}]}]}
{"op":"mcm","clk":"4234788958","pt":1631549920545,"mc":[{"id":"1.187560677","rc":[{"batb":[[0,4.1,2.94],[1,3.75,52.97],[2,1.3,5]],"batl":[[0,6.6,2],[1,7,2],[2,7.4,3]],"ltp":7.2,"tv":1657.22,"id":7588306},{"batb":[[0,1.18,135.86],[1,1.17,347.28],[2,1.16,371]],"batl":[[0,1.32,82.36],[1,1.39,18.43],[2,1.44,94.65]],"ltp":1.22,"tv":28019.82,"id":11439844}]}]}
{"op":"mcm","clk":"4234788976","pt":1631549920835,"mc":[{"id":"1.187560677","rc":[{"batl":[[0,7,2],[1,7.4,3],[2,7.8,5]],"ltp":7.2,"tv":1657.22,"id":7588306},{"batb":[[0,1.17,347.28],[1,1.16,371],[2,1.15,303.63]],"ltp":1.22,"tv":28019.82,"id":11439844}]}]}
{"op":"mcm","clk":"4234789154","pt":1631549922630,"mc":[{"id":"1.187560677","rc":[{"batl":[[0,4.6,43.48],[1,4.8,4.51],[2,4.9,2]],"ltp":7.2,"tv":1657.22,"id":7588306},{"batb":[[0,1.26,18.98],[1,1.17,347.28],[2,1.16,371]],"batl":[[0,1.28,26.76],[1,1.3,918.64],[2,1.32,82.36]],"ltp":1.22,"tv":28019.82,"id":11439844}]}]}
{"op":"mcm","clk":"4234789223","pt":1631549923520,"mc":[{"id":"1.187560677","rc":[{"batb":[[2,2.8,18.54]],"batl":[[0,4.6,8.7]],"ltp":7.2,"tv":1657.22,"id":7588306},{"trd":[[1.28,173.42]],"batb":[[0,1.28,96.54],[1,1.26,18.98],[2,1.2,568.88]],"batl":[[0,1.3,918.64],[1,1.32,82.36],[2,1.44,95.15]],"ltp":1.28,"tv":28073.34,"id":11439844}],"tv":29730.56}]}
{"op":"mcm","clk":"4234789860","pt":1631549930220,"mc":[{"id":"1.187560677","rc":[{"batb":[[2,3.2,4.07]],"ltp":7.2,"tv":1657.22,"id":7588306},{"batb":[[2,1.21,136.69]],"ltp":1.28,"tv":28073.34,"id":11439844}]}]}
{"op":"mcm","clk":"4234790234","pt":1631549933955,"mc":[{"id":"1.187560677","rc":[{"batl":[[1,4.9,2],[2,5.1,216.81]],"ltp":7.2,"tv":1657.22,"id":7588306}]}]}
{"op":"mcm","clk":"4234790488","pt":1631549936612,"mc":[{"id":"1.187560677","rc":[{"batb":[[0,4.5,3.95],[1,4.1,2.94],[2,3.75,43.11]],"batl":[[1,4.7,6.73],[2,4.9,2]],"ltp":7.2,"tv":1657.22,"id":7588306}]}]}
{"op":"mcm","clk":"4234790802","pt":1631549940148,"mc":[{"id":"1.187560677","rc":[{"batl":[[2,1.44,146.98]],"ltp":1.28,"tv":28073.34,"id":11439844}]}]}
{"op":"mcm","clk":"4234791210","pt":1631549944544,"mc":[{"id":"1.187560677","rc":[{"batb":[[0,3.75,43.11],[1,3.3,11.77],[2,3.25,3.89]],"batl":[[0,5.8,2],[1,6,13],[2,6.4,3]],"ltp":7.2,"tv":1657.22,"id":7588306},{"batb":[[1,1.21,136.69],[2,1.2,568.88]],"batl":[[0,1.44,146.98],[1,1.45,49.15],[2,1.49,45.5]],"ltp":1.28,"tv":28073.34,"id":11439844}]}]}
{"op":"mcm","clk":"4234791290","pt":1631549945687,"mc":[{"id":"1.187560677","rc":[{"batb":[[0,3.3,11.77],[1,3,5],[2,2.8,18.54]],"batl":[[0,6,13],[1,6.4,3],[2,6.6,5]],"ltp":7.2,"tv":1657.22,"id":7588306},{"batb":[[0,1.2,568.88],[1,1.19,103],[2,1.18,254.36]],"batl":[[0,1.44,95.15],[1,1.49,45.75],[2,1.94,3.08]],"ltp":1.28,"tv":28073.34,"id":11439844}]}]}
{"op":"mcm","clk":"4234791561","pt":1631549948543,"mc":[{"id":"1.187560677","rc":[{"batb":[[1,3.25,3.85],[2,3,5]],"batl":[[0,5.8,2],[1,6,13],[2,6.6,2]],"ltp":7.2,"tv":1657.22,"id":7588306},{"batb":[[0,1.21,109.69],[1,1.2,568.88],[2,1.18,148.36]],"batl":[[0,1.44,148.23],[1,1.94,3.33],[2,3.8,27.43]],"ltp":1.28,"tv":28073.34,"id":11439844}]}]}
{"op":"mcm","clk":"4234791593","pt":1631549948856,"mc":[{"id":"1.187560677","rc":[{"batb":[[1,3,5],[2,2.82,18.29]],"batl":[[0,6,13],[1,6.6,2],[2,7,5]],"ltp":7.2,"tv":1657.22,"id":7588306},{"batb":[[0,1.2,568.88],[1,1.18,148.36],[2,1.17,241.97]],"batl":[[0,1.44,95.15]],"ltp":1.28,"tv":28073.34,"id":11439844}]}]}
{"op":"mcm","clk":"4234791858","pt":1631549951258,"mc":[{"id":"1.187560677","rc":[{"batb":[[0,4.4,1090.35],[1,3.3,11.77],[2,3,5]],"batl":[[0,5.7,5.07],[1,6,13],[2,6.6,2]],"ltp":7.2,"tv":1657.22,"id":7588306},{"batb":[[1,1.19,1032.4],[2,1.18,148.36]],"batl":[[0,1.23,65.05],[1,1.44,95.15],[2,1.94,3.33]],"ltp":1.28,"tv":28073.34,"id":11439844}]}]}
{"op":"mcm","clk":"4234791994","pt":1631549952461,"mc":[{"id":"1.187560677","rc":[{"batb":[[0,4.6,26.17],[1,4.4,1090.35],[2,3.7,22.4]],"ltp":7.2,"tv":1657.22,"id":7588306},{"batl":[[1,1.4,2.21],[2,1.44,94.65]],"ltp":1.28,"tv":28073.34,"id":11439844}]}]}
{"op":"mcm","clk":"4234792637","pt":1631549958481,"mc":[{"id":"1.187560677","rc":[{"batb":[[2,4.3,2.68]],"ltp":7.2,"tv":1657.22,"id":7588306},{"batl":[[1,1.3,88.25],[2,1.33,67.5]],"ltp":1.28,"tv":28073.34,"id":11439844}]}]}
{"op":"mcm","clk":"4234793092","pt":1631549962968,"mc":[{"id":"1.187560677","rc":[{"trd":[[5.3,7.67]],"ltp":5.3,"tv":1657.39,"id":7588306},{"trd":[[1.23,112.5]],"batl":[[0,1.23,64.28]],"ltp":1.23,"tv":28074.11,"id":11439844}],"tv":29731.51}]}
{"op":"mcm","clk":"4234793654","pt":1631549968595,"mc":[{"id":"1.187560677","rc":[{"batb":[[0,4,2.93],[1,3.7,22.4],[2,3.3,11.77]],"batl":[[0,6.6,2],[1,7,5],[2,7.4,5]],"ltp":5.3,"tv":1657.39,"id":7588306},{"batb":[[0,1.18,148.36],[1,1.17,452.01],[2,1.16,532.03]],"batl":[[0,1.44,95.15],[1,1.94,3.33],[2,3.8,27.43]],"ltp":1.23,"tv":28074.11,"id":11439844}]}]}
{"op":"mcm","clk":"4234793678","pt":1631549968806,"mc":[{"id":"1.187560677","rc":[{"batl":[[0,7,5],[1,7.4,5],[2,7.8,5]],"ltp":5.3,"tv":1657.39,"id":7588306},{"batb":[[0,1.17,452.01],[1,1.16,532.03],[2,1.15,303.63]],"ltp":1.23,"tv":28074.11,"id":11439844}]}]}
{"op":"mcm","clk":"4234793758","pt":1631549969798,"mc":[{"id":"1.187560677","rc":[{"batb":[[0,1.23,34],[1,1.17,452.01],[2,1.16,532.03]],"ltp":1.23,"tv":28074.11,"id":11439844}]}]}
{"op":"mcm","clk":"4234793915","pt":1631549971470,"mc":[{"id":"1.187560677","rc":[{"batb":[[0,4.3,2.38],[1,4,2.93],[2,3.7,22.4]],"ltp":5.3,"tv":1657.39,"id":7588306},{"batl":[[0,1.3,75.25],[1,1.33,78.5],[2,1.44,95.15]],"ltp":1.23,"tv":28074.11,"id":11439844}]}]}
{"op":"mcm","clk":"4234794006","pt":1631549972413,"mc":[{"id":"1.187560677","rc":[{"batb":[[0,4,2.93],[1,3.7,22.4],[2,3.3,11.77]],"ltp":5.3,"tv":1657.39,"id":7588306},{"batl":[[0,1.33,78.5],[1,1.44,95.15],[2,1.94,3.33]],"ltp":1.23,"tv":28074.11,"id":11439844}]}]}
{"op":"mcm","clk":"4234794340","pt":1631549975692,"mc":[{"id":"1.187560677","rc":[{"batl":[[0,6.6,2],[1,7,2],[2,7.4,5]],"ltp":5.3,"tv":1657.39,"id":7588306},{"batb":[[1,1.18,122.86],[2,1.17,343.01]],"ltp":1.23,"tv":28074.11,"id":11439844}]}]}
{"op":"mcm","clk":"4234794362","pt":1631549975901,"mc":[{"id":"1.187560677","rc":[{"batl":[[0,7,2],[1,7.4,5],[2,7.8,5]],"ltp":5.3,"tv":1657.39,"id":7588306},{"batb":[[1,1.17,343.01],[2,1.16,532.03]],"ltp":1.23,"tv":28074.11,"id":11439844}]}]}
{"op":"mcm","clk":"4234794619","pt":1631549978697,"mc":[{"id":"1.187560677","rc":[{"trd":[[7,12]],"batb":[[0,6.8,6],[1,6,117.67],[2,4,2.93]],"batl":[[0,7.2,163.06]],"ltp":7.0,"tv":1665.39,"id":7588306},{"trd":[[1.17,1279.69],[1.18,210.45],[1.23,180.5]],"batb":[[0,1.17,118.06],[1,1.16,532.03],[2,1.15,303.63]],"batl":[[0,1.18,33.9],[1,1.19,19.62],[2,1.2,588.37]],"ltp":1.17,"tv":28610.08,"id":11439844}],"tv":30275.48}]}
{"op":"mcm","clk":"4234794664","pt":1631549979220,"mc":[{"id":"1.187560677","rc":[{"batb":[[2,5.1,19.96]],"ltp":7.0,"tv":1665.39,"id":7588306},{"batb":[[2,1.15,537.32]],"ltp":1.17,"tv":28610.08,"id":11439844}]}]}
{"op":"mcm","clk":"4234795212","pt":1631549985430,"mc":[{"id":"1.187560677","rc":[{"batb":[[2,5.5,2.12]],"ltp":7.0,"tv":1665.39,"id":7588306}]}]}
{"op":"mcm","clk":"4234795482","pt":1631549988194,"mc":[{"id":"1.187560677","rc":[{"batl":[[1,1.2,588.37],[2,1.22,116.25]],"ltp":1.17,"tv":28610.08,"id":11439844}]}]}
{"op":"mcm","clk":"4234795786","pt":1631549991115,"mc":[{"id":"1.187560677","rc":[{"trd":[[6.8,33.99]],"batb":[[0,6.4,4.15]],"ltp":6.8,"tv":1677.05,"id":7588306}],"tv":30287.14}]}
{"op":"mcm","clk":"4234796239","pt":1631549996635,"mc":[{"id":"1.187560677","rc":[{"batb":[[0,5.1,22],[1,4.5,27.93],[2,3.3,11.77]],"batl":[[0,7.4,5],[1,7.8,5],[2,9.4,3]],"ltp":6.8,"tv":1677.05,"id":7588306},{"batl":[[0,1.44,95.15],[1,1.94,3.33],[2,3.8,27.43]],"ltp":1.17,"tv":28610.08,"id":11439844}]}]}
{"op":"mcm","clk":"4234796263","pt":1631549996844,"mc":[{"id":"1.187560677","rc":[{"batb":[[0,5.1,2.04],[1,4.5,26.93]],"ltp":6.8,"tv":1677.05,"id":7588306},{"batb":[[0,1.16,532.03],[1,1.15,537.32],[2,1.14,298.11]],"ltp":1.17,"tv":28610.08,"id":11439844}]}]}
{"op":"mcm","clk":"4234796494","pt":1631549999643,"mc":[{"id":"1.187560677","rc":[{"batl":[[0,7.8,5],[1,9.4,3],[2,10.5,3]],"ltp":6.8,"tv":1677.05,"id":7588306},{"batb":[[0,1.15,537.32],[1,1.14,298.11],[2,1.13,346.04]],"ltp":1.17,"tv":28610.08,"id":11439844}]}]}
{"op":"mcm","clk":"4234796530","pt":1631550000010,"mc":[{"id":"1.187560677","rc":[{"batl":[[0,1.24,102.23],[1,1.44,95.15],[2,1.94,3.33]],"ltp":1.17,"tv":28610.08,"id":11439844}]}]}
{"op":"mcm","clk":"4234796801","pt":1631550002532,"mc":[{"id":"1.187560677","rc":[{"batb":[[0,6.2,20.87],[1,5.1,2.04],[2,4.5,26.93]],"batl":[[0,6.6,21.81],[1,7.8,5],[2,9.4,3]],"ltp":6.8,"tv":1677.05,"id":7588306},{"batl":[[0,1.19,22.5],[1,1.24,102.23],[2,1.44,95.15]],"ltp":1.17,"tv":28610.08,"id":11439844}]}]}
{"op":"mcm","clk":"4234796909","pt":1631550003422,"mc":[{"id":"1.187560677","rc":[{"batb":[[0,5.1,2.04],[1,4.5,26.93],[2,3.3,11.77]],"batl":[[0,7.8,5],[1,9.4,3],[2,10.5,3]],"ltp":6.8,"tv":1677.05,"id":7588306},{"batl":[[0,1.24,102.23],[1,1.44,95.15],[2,1.94,3.33]],"ltp":1.17,"tv":28610.08,"id":11439844}]}]}
{"op":"mcm","clk":"4234797225","pt":1631550006661,"mc":[{"id":"1.187560677","rc":[{"batb":[[0,5.5,2.12],[1,5.1,2.04],[2,4.5,26.93]],"batl":[[0,6.4,5],[1,7.4,2],[2,7.8,5]],"ltp":6.8,"tv":1677.05,"id":7588306},{"batb":[[0,1.16,146.28],[1,1.15,537.32],[2,1.14,298.11]],"batl":[[0,1.22,119.75],[1,1.23,112.5],[2,1.24,102.23]],"ltp":1.17,"tv":28610.08,"id":11439844}]}]}
{"op":"mcm","clk":"4234797258","pt":1631550006928,"mc":[{"id":"1.187560677","rc":[{"batb":[[0,5.1,2.04],[1,4.5,26.93],[2,3.3,11.77]],"batl":[[1,7.8,5],[2,9.4,3]],"ltp":6.8,"tv":1677.05,"id":7588306},{"batb":[[0,1.15,537.32],[1,1.14,298.11],[2,1.13,346.04]],"batl":[[0,1.24,102.23],[1,1.44,95.15],[2,1.94,3.33]],"ltp":1.17,"tv":28610.08,"id":11439844}]}]}
{"op":"mcm","clk":"4234797505","pt":1631550009635,"mc":[{"id":"1.187560677","rc":[{"batl":[[0,1.44,95.15],[1,1.94,3.33],[2,3.8,27.43]],"ltp":1.17,"tv":28610.08,"id":11439844}]}]}
{"op":"mcm","clk":"4234797614","pt":1631550010526,"mc":[{"id":"1.187560677","rc":[{"batb":[[1,1.14,177.11]],"ltp":1.17,"tv":28610.08,"id":11439844}]}]}
{"op":"mcm","clk":"4234797821","pt":1631550012659,"mc":[{"id":"1.187560677","rc":[{"trd":[[6.4,23.05]],"batb":[[0,6.8,143.74],[1,6.4,15.45],[2,5.1,2.04]],"batl":[[0,7.8,5],[1,8,167.47]],"ltp":6.4,"tv":1682.05,"id":7588306},{"trd":[[1.18,237.57]],"batl":[[0,1.16,35.74],[1,1.18,152.25],[2,1.19,109]],"ltp":1.18,"tv":28637.2,"id":11439844}],"tv":30319.26}]}
{"op":"mcm","clk":"4234797918","pt":1631550013550,"mc":[{"id":"1.187560677","rc":[{"batb":[[2,5.5,33.05]],"ltp":6.4,"tv":1682.05,"id":7588306}]}]}
{"op":"mcm","clk":"4234798558","pt":1631550019970,"mc":[{"id":"1.187560677","rc":[{"batb":[[2,6.2,2]],"batl":[[2,9.4,5]],"ltp":6.4,"tv":1682.05,"id":7588306},{"batl":[[2,1.19,246.5]],"ltp":1.18,"tv":28637.2,"id":11439844}]}]}
{"op":"mcm","clk":"4234798759","pt":1631550022317,"mc":[{"id":"1.187560677","rc":[{"trd":[[1.15,884.11]],"batb":[[0,1.15,535.22]],"ltp":1.15,"tv":28641.4,"id":11439844}],"tv":30323.46}]}
{"op":"mcm","clk":"4234800975","pt":1631550045327,"mc":[{"id":"1.187560677","rc":[{"batb":[[0,6,2],[1,5.2,19.63],[2,1.3,5]],"batl":[[0,9.4,5],[1,10.5,3],[2,11,5]],"ltp":6.4,"tv":1682.05,"id":7588306},{"batb":[[0,1.12,640.89],[1,1.11,360.59],[2,1.1,366.01]],"batl":[[0,1.19,109],[1,1.2,210.28],[2,1.44,95.15]],"ltp":1.15,"tv":28641.4,"id":11439844}]}]}
{"op":"mcm","clk":"4234801178","pt":1631550047565,"mc":[{"id":"1.187560677","rc":[{"batl":[[0,9.4,2]],"ltp":6.4,"tv":1682.05,"id":7588306},{"batb":[[0,1.12,514.87]],"ltp":1.15,"tv":28641.4,"id":11439844}]}]}
{"op":"mcm","clk":"4234801312","pt":1631550048653,"mc":[{"id":"1.187560677","rc":[{"batb":[[0,6.2,2.02],[1,6,2],[2,5.1,19.88]],"ltp":6.4,"tv":1682.05,"id":7588306},{"batb":[[0,1.12,511.93]],"batl":[[0,1.19,236.5]],"ltp":1.15,"tv":28641.4,"id":11439844}]}]}
{"op":"mcm","clk":"4234801324","pt":1631550048763,"mc":[{"id":"1.187560677","rc":[{"batb":[[0,6,2],[1,5.1,19.88],[2,1.3,5]],"ltp":6.4,"tv":1682.05,"id":7588306},{"batl":[[0,1.19,109]],"ltp":1.15,"tv":28641.4,"id":11439844}]}]}
{"op":"mcm","clk":"4234801475","pt":1631550050490,"mc":[{"id":"1.187560677","rc":[{"batb":[[0,7.2,37.47],[1,6,2],[2,5.1,19.88]],"batl":[[0,7.6,38.36],[1,9.4,2],[2,10.5,3]],"ltp":6.4,"tv":1682.05,"id":7588306},{"batl":[[0,1.17,37.5],[1,1.19,109],[2,1.2,210.28]],"ltp":1.15,"tv":28641.4,"id":11439844}]}]}
{"op":"mcm","clk":"4234801549","pt":1631550051130,"mc":[{"id":"1.187560677","rc":[{"batb":[[0,6,2],[1,5.1,19.88],[2,1.3,5]],"batl":[[0,9.4,2],[1,10.5,3],[2,11,5]],"ltp":6.4,"tv":1682.05,"id":7588306},{"batl":[[0,1.19,109],[1,1.2,210.28],[2,1.44,95.15]],"ltp":1.15,"tv":28641.4,"id":11439844}]}]}
{"op":"mcm","clk":"4234802358","pt":1631550059651,"mc":[{"id":"1.187560677","rc":[{"batb":[[0,6.2,2],[1,6,2],[2,5.1,19.88]],"ltp":6.4,"tv":1682.05,"id":7588306},{"batl":[[0,1.19,260.5]],"ltp":1.15,"tv":28641.4,"id":11439844}]}]}
{"op":"mcm","clk":"4234802391","pt":1631550059977,"mc":[{"id":"1.187560677","rc":[{"batb":[[0,6,2],[1,5.1,19.88],[2,1.3,5]],"ltp":6.4,"tv":1682.05,"id":7588306},{"batl":[[0,1.19,109]],"ltp":1.15,"tv":28641.4,"id":11439844}]}]}
{"op":"mcm","clk":"4234802946","pt":1631550066667,"mc":[{"id":"1.187560677","rc":[{"batb":[[0,6.2,2],[1,6,2],[2,5.1,19.88]],"ltp":6.4,"tv":1682.05,"id":7588306},{"batl":[[0,1.19,254.5]],"ltp":1.15,"tv":28641.4,"id":11439844}]}]}
{"op":"mcm","clk":"4234803004","pt":1631550067237,"mc":[{"id":"1.187560677","rc":[{"batb":[[0,6,2],[1,5.1,19.88],[2,1.3,5]],"batl":[[2,11,2]],"ltp":6.4,"tv":1682.05,"id":7588306},{"batb":[[2,1.1,216.01]],"batl":[[0,1.44,95.15],[1,1.94,3.33],[2,3.8,27.43]],"ltp":1.15,"tv":28641.4,"id":11439844}]}]}
{"op":"mcm","clk":"4234803259","pt":1631550070689,"mc":[{"id":"1.187560677","rc":[{"batb":[[0,8,153.71],[1,7.6,5],[2,7.2,6]],"batl":[[1,10,185.12],[2,10.5,3]],"ltp":6.4,"tv":1682.05,"id":7588306},{"trd":[[1.13,143.58],[1.14,360.6]],"batb":[[0,1.12,537.3]],"batl":[[0,1.13,40.01],[1,1.15,142.78],[2,1.16,98]],"ltp":1.13,"tv":28642.6,"id":11439844}],"tv":30324.66}]}
{"op":"mcm","clk":"4234803316","pt":1631550071172,"mc":[{"id":"1.187560677","rc":[{"batb":[[0,1.12,534.95]],"ltp":1.13,"tv":28642.6,"id":11439844}]}]}
{"op":"mcm","clk":"4234803452","pt":1631550072884,"mc":[{"id":"1.187560677","rc":[{"trd":[[1.13,207.82]],"batl":[[0,1.13,7.89]],"ltp":1.13,"tv":28706.84,"id":11439844}],"tv":30388.9}]}
{"op":"mcm","clk":"4234804098","pt":1631550080657,"mc":[{"id":"1.187560677","rc":[{"batb":[[0,1.12,508.98]],"batl":[[0,1.15,142.78],[1,1.16,98],[2,1.17,243.5]],"ltp":1.13,"tv":28706.84,"id":11439844}]}]}
{"op":"mcm","clk":"4234804459","pt":1631550084582,"mc":[{"id":"1.187560677","rc":[{"batb":[[0,7.6,5],[1,7.2,6],[2,6.8,8]],"batl":[[0,10.5,3],[1,12,20.8],[2,12.5,33.34]],"ltp":6.4,"tv":1682.05,"id":7588306},{"batb":[[0,1.12,300.44],[1,1.11,141],[2,1.09,270.53]],"batl":[[0,1.15,108]],"ltp":1.13,"tv":28706.84,"id":11439844}]}]}
{"op":"mcm","clk":"4234804521","pt":1631550085163,"mc":[{"id":"1.187560677","rc":[{"batb":[[0,6.8,6],[1,6.2,2.02],[2,6,35.82]],"batl":[[0,12,20.8],[1,12.5,33.34],[2,13,35.88]],"ltp":6.4,"tv":1682.05,"id":7588306},{"batb":[[0,1.09,270.77],[1,1.08,1316.43],[2,1.07,1019.67]],"batl":[[0,1.17,93],[1,1.19,139.5],[2,1.2,165.01]],"ltp":1.13,"tv":28706.84,"id":11439844}]}]}
{"op":"mcm","clk":"4234804783","pt":1631550087667,"mc":[{"id":"1.187560677","rc":[{"batb":[[1,6.4,6],[2,6.2,2.02]],"ltp":6.4,"tv":1682.05,"id":7588306},{"batl":[[1,1.18,102],[2,1.19,244.5]],"ltp":1.13,"tv":28706.84,"id":11439844}]}]}
{"op":"mcm","clk":"4234804956","pt":1631550089602,"mc":[{"id":"1.187560677","rc":[{"batl":[[0,1.15,699.85],[1,1.17,93],[2,1.18,102]],"ltp":1.13,"tv":28706.84,"id":11439844}]}]}
{"op":"mcm","clk":"4234805045","pt":1631550090487,"mc":[{"id":"1.187560677","rc":[{"batl":[[0,1.17,93.31],[1,1.18,102],[2,1.19,244.5]],"ltp":1.13,"tv":28706.84,"id":11439844}]}]}
{"op":"mcm","clk":"4234805149","pt":1631550091484,"mc":[{"id":"1.187560677","rc":[{"batl":[[0,1.17,93.6]],"ltp":1.13,"tv":28706.84,"id":11439844}]}]}
{"op":"mcm","clk":"4234806130","pt":1631550102700,"mc":[{"id":"1.187560677","rc":[{"batb":[[0,6.2,2.02],[1,5.7,30.45],[2,1.3,5]],"ltp":6.4,"tv":1682.05,"id":7588306},{"batb":[[2,1.07,826.67]],"batl":[[0,1.37,1.1],[1,1.44,94.65],[2,1.94,3.33]],"ltp":1.13,"tv":28706.84,"id":11439844}]}]}
{"op":"mcm","clk":"4234806321","pt":1631550104681,"mc":[{"id":"1.187560677","rc":[{"batb":[[0,10,2.56],[1,8,5],[2,6.2,2.02]],"batl":[[0,12,25.65]],"ltp":6.4,"tv":1682.05,"id":7588306},{"trd":[[1.1,969.91],[1.12,61.82]],"batb":[[0,1.09,270.26],[1,1.08,2485.62]],"batl":[[0,1.1,13.36],[1,1.11,1445.13],[2,1.12,99]],"ltp":1.1,"tv":28707.86,"id":11439844}],"tv":30389.92}]}
{"op":"mcm","clk":"4234806378","pt":1631550105342,"mc":[{"id":"1.187560677","rc":[{"batb":[[1,8.2,12.5],[2,8,5]],"ltp":6.4,"tv":1682.05,"id":7588306}]}]}
{"op":"mcm","clk":"4234806595","pt":1631550107702,"mc":[{"id":"1.187560677","rc":[{"trd":[[1.1,996.63]],"batl":[[0,1.11,1445.13],[1,1.12,99],[2,1.13,90]],"ltp":1.1,"tv":28734.58,"id":11439844}],"tv":30416.64}]}
{"op":"mcm","clk":"4234806709","pt":1631550109113,"mc":[{"id":"1.187560677","rc":[{"batb":[[0,11,46.98],[1,10,71.08],[2,8.2,12.5]],"ltp":6.4,"tv":1682.05,"id":7588306},{"batl":[[0,1.1,469.82],[1,1.11,2062.46],[2,1.12,99]],"ltp":1.1,"tv":28734.58,"id":11439844}]}]}
{"op":"mcm","clk":"4234806866","pt":1631550110943,"mc":[{"id":"1.187560677","rc":[{"batb":[[2,8.6,4.69]],"ltp":6.4,"tv":1682.05,"id":7588306}]}]}
{"op":"mcm","clk":"4234807191","pt":1631550114544,"mc":[{"id":"1.187560677","rc":[{"batl":[[0,12,20.8]],"ltp":6.4,"tv":1682.05,"id":7588306}]}]}
{"op":"mcm","clk":"4234807465","pt":1631550117422,"mc":[{"id":"1.187560677","rc":[{"batl":[[0,12,26.9]],"ltp":6.4,"tv":1682.05,"id":7588306},{"batl":[[1,1.11,2149.49]],"ltp":1.1,"tv":28734.58,"id":11439844}]}]}
{"op":"mcm","clk":"4234807492","pt":1631550117738,"mc":[{"id":"1.187560677","rc":[{"batl":[[0,12,20.8]],"ltp":6.4,"tv":1682.05,"id":7588306},{"batl":[[1,1.11,2062.46]],"ltp":1.1,"tv":28734.58,"id":11439844}]}]}
{"op":"mcm","clk":"4234807799","pt":1631550120609,"mc":[{"id":"1.187560677","rc":[{"batl":[[0,12,26.9]],"ltp":6.4,"tv":1682.05,"id":7588306},{"batl":[[1,1.11,2149.49]],"ltp":1.1,"tv":28734.58,"id":11439844}]}]}
{"op":"mcm","clk":"4234807867","pt":1631550121240,"mc":[{"id":"1.187560677","rc":[{"trd":[[11,39.91]],"batb":[[0,11,45.95]],"ltp":11.0,"tv":1684.12,"id":7588306}],"tv":30418.71}]}
{"op":"mcm","clk":"4234808487","pt":1631550127654,"mc":[{"id":"1.187560677","rc":[{"batb":[[0,8.6,2.69],[1,8.2,12.5],[2,8,9.83]],"batl":[[0,18,2],[1,21,2],[2,26,4]],"ltp":11.0,"tv":1684.12,"id":7588306},{"batb":[[0,1.08,456.15],[1,1.07,23.13],[2,1.06,465.87]],"batl":[[0,1.13,6.82],[1,1.14,291.81],[2,1.15,183.89]],"ltp":1.1,"tv":28734.58,"id":11439844}]}]}
{"op":"mcm","clk":"4234808551","pt":1631550128439,"mc":[{"id":"1.187560677","rc":[{"batb":[[0,8,9.83],[1,6.8,18.96],[2,1.3,5]],"batl":[[0,21,2],[1,26,4],[2,990,0.01]],"ltp":11.0,"tv":1684.12,"id":7588306},{"batb":[[0,1.08,20.89],[2,1.06,26.29]],"batl":[[0,1.14,292.32],[1,1.15,183.89],[2,1.25,14.94]],"ltp":1.1,"tv":28734.58,"id":11439844}]}]}
{"op":"mcm","clk":"4234808752","pt":1631550130473,"mc":[{"id":"1.187560677","rc":[{"batb":[[1,7.6,5],[2,7.2,6]],"ltp":11.0,"tv":1684.12,"id":7588306},{"batl":[[1,1.15,290.89],[2,1.16,94]],"ltp":1.1,"tv":28734.58,"id":11439844}]}]}
{"op":"mcm","clk":"4234808858","pt":1631550131469,"mc":[{"id":"1.187560677","rc":[{"batl":[[0,11,3.61],[1,21,2],[2,26,4]],"ltp":11.0,"tv":1684.12,"id":7588306}]}]}
{"op":"mcm","clk":"4234808952","pt":1631550132659,"mc":[{"id":"1.187560677","rc":[{"batl":[[0,21,2],[1,26,4],[2,990,0.01]],"ltp":11.0,"tv":1684.12,"id":7588306}]}]}
{"op":"mcm","clk":"4234809122","pt":1631550134648,"mc":[{"id":"1.187560677","rc":[{"batb":[[0,8.6,4.49],[1,8,9.83],[2,7.6,5]],"batl":[[0,18,2],[1,21,2],[2,26,4]],"ltp":11.0,"tv":1684.12,"id":7588306},{"batb":[[2,1.06,445.87]],"batl":[[0,1.13,197.82],[1,1.14,291.81],[2,1.15,290.89]],"ltp":1.1,"tv":28734.58,"id":11439844}]}]}
{"op":"mcm","clk":"4234809169","pt":1631550135168,"mc":[{"id":"1.187560677","rc":[{"batb":[[0,8,9.83],[1,7.6,5],[2,7.2,6]],"batl":[[0,21,2],[1,26,4],[2,990,0.01]],"ltp":11.0,"tv":1684.12,"id":7588306},{"batb":[[2,1.06,26.29]],"batl":[[0,1.14,292.32],[1,1.15,290.89],[2,1.16,94]],"ltp":1.1,"tv":28734.58,"id":11439844}]}]}
{"op":"mcm","clk":"4234809602","pt":1631550139646,"mc":[{"id":"1.187560677","rc":[{"batb":[[0,8,4.83],[1,6.8,18.96],[2,1.3,5]],"batl":[[1,26,2]],"ltp":11.0,"tv":1684.12,"id":7588306},{"batl":[[0,1.14,183.32],[1,1.15,183.89],[2,1.25,14.94]],"ltp":1.1,"tv":28734.58,"id":11439844}]}]}
{"op":"mcm","clk":"4234809629","pt":1631550140064,"mc":[{"id":"1.187560677","rc":[{"batb":[[0,8,2]],"ltp":11.0,"tv":1684.12,"id":7588306},{"batl":[[0,1.14,177.07],[1,1.15,6.79]],"ltp":1.1,"tv":28734.58,"id":11439844}]}]}
{"op":"mcm","clk":"4234809772","pt":1631550141687,"mc":[{"id":"1.187560677","rc":[{"batb":[[0,8.6,4.49],[1,8,2],[2,6.8,18.96]],"ltp":11.0,"tv":1684.12,"id":7588306},{"batb":[[0,1.08,2.85]],"batl":[[0,1.13,218.82],[1,1.14,176.56],[2,1.15,6.79]],"ltp":1.1,"tv":28734.58,"id":11439844}]}]}
{"op":"mcm","clk":"4234809858","pt":1631550142572,"mc":[{"id":"1.187560677","rc":[{"batb":[[0,13.5,79.99],[1,13,3.08],[2,12,3]],"batl":[[0,17.5,7.39],[1,18,2],[2,21,119.25]],"ltp":11.0,"tv":1684.12,"id":7588306},{"trd":[[1.07,70.43],[1.08,167.96],[1.09,2135.15]],"batb":[[0,1.06,446.37],[1,1.05,3100.13],[2,1.04,1411.22]],"batl":[[0,1.08,1096.47],[1,1.09,90],[2,1.1,99]],"ltp":1.07,"tv":28786.57,"id":11439844}],"tv":30470.69}]}
{"op":"mcm","clk":"4234810416","pt":1631550148169,"mc":[{"id":"1.187560677","rc":[{"batl":[[0,1.08,1114.51]],"ltp":1.07,"tv":28786.57,"id":11439844}]}]}
{"op":"mcm","clk":"4234810531","pt":1631550149376,"mc":[{"id":"1.187560677","rc":[{"batb":[[2,12,7.21]],"ltp":11.0,"tv":1684.12,"id":7588306},{"batl":[[1,1.09,389],[2,1.1,350.9]],"ltp":1.07,"tv":28786.57,"id":11439844}]}]}
{"op":"mcm","clk":"4234810729","pt":1631550151535,"mc":[{"id":"1.187560677","rc":[{"batb":[[0,13.5,118.26],[2,12,55.07]],"ltp":11.0,"tv":1684.12,"id":7588306},{"batl":[[0,1.07,20.63],[1,1.08,1751.81],[2,1.09,915.94]],"ltp":1.07,"tv":28786.57,"id":11439844}]}]}
{"op":"mcm","clk":"4234810994","pt":1631550154283,"mc":[{"id":"1.187560677","rc":[{"batl":[[1,18,30.82],[2,21,153.23]],"ltp":11.0,"tv":1684.12,"id":7588306},{"batb":[[0,1.06,935.79],[1,1.05,3779.7]],"ltp":1.07,"tv":28786.57,"id":11439844}]}]}
{"op":"mcm","clk":"4234811214","pt":1631550156675,"mc":[{"id":"1.187560677","rc":[{"trd":[[1.06,81.45]],"batb":[[0,1.06,895.07]],"ltp":1.06,"tv":28868.02,"id":11439844}],"tv":30552.14}]}
{"op":"mcm","clk":"4234811280","pt":1631550157508,"mc":[{"id":"1.187560677","rc":[{"batl":[[2,1.09,918.51]],"ltp":1.06,"tv":28868.02,"id":11439844}]}]}
{"op":"mcm","clk":"4234811369","pt":1631550158609,"mc":[{"id":"1.187560677","rc":[{"batb":[[0,13.5,5],[1,12,7.21],[2,11.5,13.17]],"batl":[[0,21,2],[1,26,2],[2,36,2]],"ltp":11.0,"tv":1684.12,"id":7588306},{"batb":[[0,1.05,281.1],[1,1.04,1411.22],[2,1.03,1318.68]],"batl":[[1,1.08,295.12],[2,1.09,391.56]],"ltp":1.06,"tv":28868.02,"id":11439844}]}]}
{"op":"mcm","clk":"4234811491","pt":1631550159700,"mc":[{"id":"1.187560677","rc":[{"batb":[[0,13.5,2],[1,12,4.21],[2,11,8.14]],"batl":[[0,36,2],[1,990,0.01],[2,36,0]],"ltp":11.0,"tv":1684.12,"id":7588306},{"trd":[[1.07,111.7],[1.08,216.84]],"batb":[[0,1.05,31.1],[1,1.04,39.07]],"batl":[[0,1.08,2.43],[1,1.09,301.56],[2,1.1,350.9]],"ltp":1.08,"tv":28958.17,"id":11439844}],"tv":30642.29}]}
{"op":"mcm","clk":"4234811592","pt":1631550160688,"mc":[{"id":"1.187560677","rc":[{"batb":[[0,15,6.45],[1,13.5,10.19]],"ltp":11.0,"tv":1684.12,"id":7588306},{"batl":[[0,1.07,90.38],[1,1.08,104.75],[2,1.09,2.56]],"ltp":1.08,"tv":28958.17,"id":11439844}]}]}
{"op":"mcm","clk":"4234811671","pt":1631550161616,"mc":[{"id":"1.187560677","rc":[{"batb":[[0,13.5,2],[1,11,8.14],[2,9.6,20.97]],"ltp":11.0,"tv":1684.12,"id":7588306},{"batl":[[0,1.07,20.63],[1,1.08,2.43]],"ltp":1.08,"tv":28958.17,"id":11439844}]}]}
{"op":"mcm","clk":"4234811744","pt":1631550162397,"mc":[{"id":"1.187560677","rc":[{"batl":[[0,26,2],[1,36,2],[2,990,0.01]],"ltp":11.0,"tv":1684.12,"id":7588306},{"batb":[[1,1.04,588.69]],"ltp":1.08,"tv":28958.17,"id":11439844}]}]}
{"op":"mcm","clk":"4234811855","pt":1631550163595,"mc":[{"id":"1.187560677","rc":[{"batb":[[1,12,4],[2,11,8.14]],"ltp":11.0,"tv":1684.12,"id":7588306},{"batl":[[2,1.09,298.56]],"ltp":1.08,"tv":28958.17,"id":11439844}]}]}
{"op":"mcm","clk":"4234812004","pt":1631550165211,"mc":[{"id":"1.187560677","rc":[{"trd":[[15,1.47]],"batb":[[1,12,7]],"batl":[[0,15,106.74],[1,15.5,8],[2,17,2.36]],"ltp":15.0,"tv":1685.59,"id":7588306},{"trd":[[1.07,132.32]],"batb":[[0,1.07,589],[1,1.05,31.1],[2,1.04,588.69]],"batl":[[0,1.08,2.43],[1,1.09,1457.33],[2,1.1,351.11]],"ltp":1.07,"tv":28978.79,"id":11439844}],"tv":30664.38}]}
{"op":"mcm","clk":"4234812090","pt":1631550166101,"mc":[{"id":"1.187560677","rc":[{"batb":[[1,1.06,561.16],[2,1.05,31.1]],"ltp":1.07,"tv":28978.79,"id":11439844}]}]}
{"op":"mcm","clk":"4234812295","pt":1631550168489,"mc":[{"id":"1.187560677","rc":[{"batb":[[1,12,3],[2,11,6]],"ltp":15.0,"tv":1685.59,"id":7588306},{"batl":[[1,1.09,1449.83],[2,1.1,344.76]],"ltp":1.07,"tv":28978.79,"id":11439844}]}]}
{"op":"mcm","clk":"4234812458","pt":1631550170124,"mc":[{"id":"1.187560677","rc":[{"batb":[[0,12,3],[1,11,6],[2,9.6,20.97]],"ltp":15.0,"tv":1685.59,"id":7588306},{"trd":[[1.07,136.77]],"batb":[[0,1.07,586.78]],"ltp":1.07,"tv":28983.24,"id":11439844}],"tv":30668.83}]}
{"op":"mcm","clk":"4234812589","pt":1631550171520,"mc":[{"id":"1.187560677","rc":[{"batb":[[0,13.5,34.92],[1,12,51.01],[2,11,6]],"ltp":15.0,"tv":1685.59,"id":7588306},{"batl":[[0,1.08,439],[1,1.09,1978.48]],"ltp":1.07,"tv":28983.24,"id":11439844}]}]}
{"op":"mcm","clk":"4234812684","pt":1631550172422,"mc":[{"id":"1.187560677","rc":[{"batl":[[1,15.5,45.43]],"ltp":15.0,"tv":1685.59,"id":7588306},{"batb":[[0,1.07,1129.07],[1,1.06,1268.01]],"ltp":1.07,"tv":28983.24,"id":11439844}]}]}
{"op":"mcm","clk":"4234812781","pt":1631550173316,"mc":[{"id":"1.187560677","rc":[{"batb":[[1,1.06,706.86]],"ltp":1.07,"tv":28983.24,"id":11439844}]}]}
{"op":"mcm","clk":"4234812910","pt":1631550174411,"mc":[{"id":"1.187560677","rc":[{"trd":[[1.07,150.69]],"batb":[[0,1.07,1122.11]],"ltp":1.07,"tv":28997.16,"id":11439844}],"tv":30682.75}]}
{"op":"mcm","clk":"4234813298","pt":1631550178274,"mc":[{"id":"1.187560677","rc":[{"batb":[[1,1.06,709.41]],"ltp":1.07,"tv":28997.16,"id":11439844}]}]}
{"op":"mcm","clk":"4234814354","pt":1631550188546,"mc":[{"id":"1.187560677","rc":[{"batb":[[0,8,4.58],[1,1.3,5],[2,1.01,105.79]],"batl":[[0,36,2],[1,55,2],[2,990,0.01]],"ltp":15.0,"tv":1685.59,"id":7588306},{"batb":[[0,1.06,2.56],[1,1.05,31.1],[2,1.04,39.07]],"batl":[[0,1.08,2.43],[1,1.09,2.56],[2,1.12,104.48]],"ltp":1.07,"tv":28997.16,"id":11439844}]}]}
{"op":"mcm","clk":"4234814707","pt":1631550191553,"mc":[{"id":"1.187560677","rc":[{"batb":[[0,9.2,2],[1,8,9.58],[2,1.3,5]],"ltp":15.0,"tv":1685.59,"id":7588306},{"batl":[[2,1.12,326.94]],"ltp":1.07,"tv":28997.16,"id":11439844}]}]}
{"op":"mcm","clk":"4234814821","pt":1631550192230,"mc":[{"id":"1.187560677","rc":[{"batb":[[0,8,9.58],[1,1.3,5],[2,1.01,105.79]],"ltp":15.0,"tv":1685.59,"id":7588306},{"batl":[[2,1.12,104.48]],"ltp":1.07,"tv":28997.16,"id":11439844}]}]}
{"op":"mcm","clk":"4234815225","pt":1631550195535,"mc":[{"id":"1.187560677","rc":[{"batb":[[0,9.2,2.17],[1,8,9.58],[2,1.3,5]],"ltp":15.0,"tv":1685.59,"id":7588306},{"batl":[[2,1.12,111.19]],"ltp":1.07,"tv":28997.16,"id":11439844}]}]}
{"op":"mcm","clk":"4234815326","pt":1631550196640,"mc":[{"id":"1.187560677","rc":[{"batb":[[0,8,2],[1,1.3,5],[2,1.01,105.79]],"ltp":15.0,"tv":1685.59,"id":7588306},{"batl":[[2,1.14,1.03]],"ltp":1.07,"tv":28997.16,"id":11439844}]}]}
{"op":"mcm","clk":"4234815340","pt":1631550196852,"mc":[{"id":"1.187560677","rc":[{"batb":[[1,1.05,2.23]],"ltp":1.07,"tv":28997.16,"id":11439844}]}]}
{"op":"mcm","clk":"4234815488","pt":1631550198515,"mc":[{"id":"1.187560677","rc":[{"batb":[[0,9.2,2],[1,8,2],[2,1.3,5]],"ltp":15.0,"tv":1685.59,"id":7588306},{"batl":[[2,1.12,184.94]],"ltp":1.07,"tv":28997.16,"id":11439844}]}]}
{"op":"mcm","clk":"4234815573","pt":1631550199343,"mc":[{"id":"1.187560677","rc":[{"batb":[[0,21,4.04],[1,17.5,2],[2,17,2.36]],"batl":[[0,26,79.2],[1,36,2],[2,55,2]],"ltp":15.0,"tv":1685.59,"id":7588306},{"trd":[[1.05,4.46],[1.06,86.57]],"batb":[[0,1.04,2447.12],[1,1.03,1318.68],[2,1.02,1933.82]],"batl":[[0,1.05,107.8],[1,1.06,193.92],[2,1.07,3558.65]],"ltp":1.05,"tv":29006.73,"id":11439844}],"tv":30692.32}]}
{"op":"mcm","clk":"4234816024","pt":1631550204036,"mc":[{"id":"1.187560677","rc":[{"batb":[[0,21,32.82],[1,17.5,40.52]],"ltp":15.0,"tv":1685.59,"id":7588306},{"batl":[[0,1.05,683.35],[1,1.06,830]],"ltp":1.05,"tv":29006.73,"id":11439844}]}]}
{"op":"mcm","clk":"4234816206","pt":1631550206174,"mc":[{"id":"1.187560677","rc":[{"batl":[[0,26,104],[1,36,25.78]],"ltp":15.0,"tv":1685.59,"id":7588306},{"batb":[[0,1.04,3067],[1,1.03,2150.03]],"ltp":1.05,"tv":29006.73,"id":11439844}]}]}
{"op":"mcm","clk":"4234816465","pt":1631550209354,"mc":[{"id":"1.187560677","rc":[{"batl":[[2,1.07,3561.08]],"ltp":1.05,"tv":29006.73,"id":11439844}]}]}
{"op":"mcm","clk":"4234816575","pt":1631550210548,"mc":[{"id":"1.187560677","rc":[{"batl":[[1,1.06,832.24]],"ltp":1.05,"tv":29006.73,"id":11439844}]}]}
{"op":"mcm","clk":"4234816840","pt":1631550213568,"mc":[{"id":"1.187560677","rc":[{"trd":[[21,19.44]],"batb":[[0,21,23.1]],"ltp":21.0,"tv":1705.02,"id":7588306},{"trd":[[1.04,189.31]],"batb":[[0,1.04,2972.33]],"batl":[[0,1.05,697.78]],"ltp":1.04,"tv":29196.04,"id":11439844}],"tv":30901.07}]}
{"op":"mcm","clk":"4234817017","pt":1631550215646,"mc":[{"id":"1.187560677","rc":[{"trd":[[21,20.87]],"batb":[[0,21,22.38]],"ltp":21.0,"tv":1706.46,"id":7588306}],"tv":30902.51}]}
{"op":"mcm","clk":"4234817394","pt":1631550220076,"mc":[{"id":"1.187560677","rc":[{"trd":[[1.05,4.52]],"batl":[[0,1.05,697.75]],"ltp":1.05,"tv":29196.1,"id":11439844}],"tv":30902.57}]}
{"op":"mcm","clk":"4234817846","pt":1631550225385,"mc":[{"id":"1.187560677","rc":[{"batl":[[0,1.05,700.13]],"ltp":1.05,"tv":29196.1,"id":11439844}]}]}
{"op":"mcm","clk":"4234818192","pt":1631550229079,"mc":[{"id":"1.187560677","rc":[{"trd":[[21,21.89]],"batb":[[0,21,21.87]],"ltp":21.0,"tv":1707.48,"id":7588306}],"tv":30903.59}]}
{"op":"mcm","clk":"4234819139","pt":1631550239268,"mc":[{"id":"1.187560677","rc":[{"trd":[[1.04,225.6]],"batb":[[0,1.04,2954.19]],"batl":[[0,1.05,327.77]],"ltp":1.04,"tv":29232.39,"id":11439844}],"tv":30939.88}]}
{"op":"mcm","clk":"4234819350","pt":1631550241467,"mc":[{"id":"1.187560677","rc":[{"trd":[[21,29.11]],"batb":[[0,21,3.83]],"ltp":21.0,"tv":1714.7,"id":7588306}],"tv":30947.09}]}
{"op":"mcm","clk":"4234819664","pt":1631550244686,"mc":[{"id":"1.187560677","rc":[{"batb":[[0,17.5,2],[1,17,2.36],[2,15,3]],"ltp":21.0,"tv":1714.7,"id":7588306},{"batl":[[0,1.05,124.58],[1,1.06,196.15]],"ltp":1.04,"tv":29232.39,"id":11439844}]}]}
{"op":"mcm","clk":"4234821367","pt":1631550261990,"mc":[{"id":"1.187560677","rc":[{"trd":[[1.05,130.75]],"batl":[[0,1.05,61.45]],"ltp":1.05,"tv":29358.62,"id":11439844}],"tv":31073.32}]}
{"op":"mcm","clk":"4234822337","pt":1631550271873,"mc":[{"id":"1.187560677","rc":[{"batl":[[0,26,79.2],[1,36,2]],"ltp":21.0,"tv":1714.7,"id":7588306},{"batb":[[0,1.04,2334.31],[1,1.03,1318.68]],"ltp":1.05,"tv":29358.62,"id":11439844}]}]}
{"op":"mcm","clk":"4234823737","pt":1631550286217,"mc":[{"id":"1.187560677","rc":[{"trd":[[1.05,134.75]],"batl":[[0,1.05,59.45]],"ltp":1.05,"tv":29362.62,"id":11439844}],"tv":31077.32}]}
{"op":"mcm","clk":"4234824268","pt":1631550292319,"mc":[{"id":"1.187560677","rc":[{"trd":[[1.05,136.75]],"batl":[[0,1.05,58.45]],"ltp":1.05,"tv":29364.62,"id":11439844}],"tv":31079.32}]}
{"op":"mcm","clk":"4234825603","pt":1631550305543,"mc":[{"id":"1.187560677","rc":[{"batb":[[0,13.5,7],[1,12,4.08],[2,1.3,5]],"batl":[[0,36,2],[1,990,0.01],[2,55,0]],"ltp":21.0,"tv":1714.7,"id":7588306},{"batb":[[0,1.03,1318.68],[1,1.02,628.14],[2,1.01,1314.97]],"batl":[[0,1.05,16.81],[1,1.06,2.23],[2,1.07,2.43]],"ltp":1.05,"tv":29364.62,"id":11439844}]}]}
{"op":"mcm","clk":"4234825654","pt":1631550306014,"mc":[{"id":"1.187560677","rc":[{"batb":[[0,13.5,3]],"ltp":21.0,"tv":1714.7,"id":7588306}]}]}
{"op":"mcm","clk":"4234825898","pt":1631550308535,"mc":[{"id":"1.187560677","rc":[{"batb":[[1,12,7.08],[2,11,4]],"ltp":21.0,"tv":1714.7,"id":7588306}]}]}
{"op":"mcm","clk":"4234826307","pt":1631550312533,"mc":[{"id":"1.187560677","rc":[{"batb":[[0,13.5,5]],"ltp":21.0,"tv":1714.7,"id":7588306}]}]}
{"op":"mcm","clk":"4234826378","pt":1631550313257,"mc":[{"id":"1.187560677","rc":[{"batb":[[0,13.5,3]],"ltp":21.0,"tv":1714.7,"id":7588306}]}]}
{"op":"mcm","clk":"4234826454","pt":1631550314141,"mc":[{"id":"1.187560677","rc":[{"batb":[[2,1.3,5]],"ltp":21.0,"tv":1714.7,"id":7588306}]}]}
{"op":"mcm","clk":"4234826601","pt":1631550315665,"mc":[{"id":"1.187560677","rc":[{"batl":[[0,1.05,2.38]],"ltp":1.05,"tv":29364.62,"id":11439844}]}]}
{"op":"mcm","clk":"4234826712","pt":1631550316660,"mc":[{"id":"1.187560677","rc":[{"trd":[[21,29.23]],"batb":[[0,13.5,5]],"batl":[[0,17.5,122.16],[1,18.5,349.32],[2,22,9.1]],"ltp":21.0,"tv":1714.82,"id":7588306},{"trd":[[1.05,139.13],[1.06,91.03],[1.07,155.54]],"batb":[[0,1.07,38.27],[1,1.03,1318.68],[2,1.02,628.14]],"batl":[[0,1.08,137.95],[1,1.09,3156.31],[2,1.14,1.03]],"ltp":1.07,"tv":29376.31,"id":11439844}],"tv":31091.14}]}
{"op":"mcm","clk":"4234826777","pt":1631550317130,"mc":[{"id":"1.187560677","rc":[{"batb":[[0,13.5,3]],"batl":[[1,21,6],[2,22,1.82]],"ltp":21.0,"tv":1714.82,"id":7588306},{"batb":[[1,1.05,595],[2,1.04,595]],"batl":[[0,1.08,131.26],[2,1.11,94.48]],"ltp":1.07,"tv":29376.31,"id":11439844}]}]}
{"op":"mcm","clk":"4234827037","pt":1631550319663,"mc":[{"id":"1.187560677","rc":[{"trd":[[1.07,203.68]],"batb":[[0,1.07,14.19]],"ltp":1.07,"tv":29424.46,"id":11439844}],"tv":31139.28}]}
{"op":"mcm","clk":"4234827128","pt":1631550320556,"mc":[{"id":"1.187560677","rc":[{"batb":[[1,12,5]],"ltp":21.0,"tv":1714.82,"id":7588306},{"trd":[[1.07,232.06]],"batb":[[0,1.05,595],[1,1.04,595],[2,1.03,1318.68]],"batl":[[1,1.09,3149.81]],"ltp":1.07,"tv":29452.84,"id":11439844}],"tv":31167.66}]}
{"op":"mcm","clk":"4234827441","pt":1631550323533,"mc":[{"id":"1.187560677","rc":[{"batb":[[2,10,4.24]],"batl":[[1,21,8]],"ltp":21.0,"tv":1714.82,"id":7588306},{"batb":[[0,1.05,597.09],[1,1.04,1219.12]],"batl":[[2,1.11,296.48]],"ltp":1.07,"tv":29452.84,"id":11439844}]}]}
{"op":"mcm","clk":"4234827648","pt":1631550325667,"mc":[{"id":"1.187560677","rc":[{"batb":[[0,10,2.24],[1,8.6,4.24],[2,1.3,5]],"batl":[[0,26,7],[1,36,2],[2,990,0.01]],"ltp":21.0,"tv":1714.82,"id":7588306},{"batb":[[0,1.04,1219.12],[1,1.03,1318.68],[2,1.02,628.14]],"batl":[[0,1.08,2.43],[1,1.09,2.56],[2,1.11,100.98]],"ltp":1.07,"tv":29452.84,"id":11439844}]}]}
{"op":"mcm","clk":"4234827752","pt":1631550326656,"mc":[{"id":"1.187560677","rc":[{"batb":[[0,8.6,29.51],[1,1.3,5],[2,1.01,105.79]],"ltp":21.0,"tv":1714.82,"id":7588306},{"batb":[[2,1.02,1728.98]],"batl":[[0,1.08,119.43],[2,1.11,94.48]],"ltp":1.07,"tv":29452.84,"id":11439844}]}]}
{"op":"mcm","clk":"4234827770","pt":1631550326866,"mc":[{"id":"1.187560677","rc":[{"batl":[[0,1.08,2.43]],"ltp":1.07,"tv":29452.84,"id":11439844}]}]}
{"op":"mcm","clk":"4234828054","pt":1631550329690,"mc":[{"id":"1.187560677","rc":[{"batb":[[0,10,2.24],[1,8.6,31.8],[2,1.3,5]],"ltp":21.0,"tv":1714.82,"id":7588306},{"batl":[[2,1.11,100.98]],"ltp":1.07,"tv":29452.84,"id":11439844}]}]}
{"op":"mcm","clk":"4234828131","pt":1631550330373,"mc":[{"id":"1.187560677","rc":[{"batb":[[0,8.6,31.8],[1,1.3,5],[2,1.01,105.79]],"ltp":21.0,"tv":1714.82,"id":7588306},{"batb":[[0,1.04,1221.64]],"batl":[[2,1.11,94.48]],"ltp":1.07,"tv":29452.84,"id":11439844}]}]}
{"op":"mcm","clk":"4234828221","pt":1631550331565,"mc":[{"id":"1.187560677","rc":[{"batl":[[0,17.5,58.47],[1,26,7],[2,36,2]],"ltp":21.0,"tv":1714.82,"id":7588306}]}]}
{"op":"mcm","clk":"4234828317","pt":1631550332660,"mc":[{"id":"1.187560677","rc":[{"batb":[[0,10,2],[1,8.6,31.8],[2,1.3,5]],"batl":[[0,21,2]],"ltp":21.0,"tv":1714.82,"id":7588306},{"batb":[[0,1.05,2.09],[1,1.04,1221.64],[2,1.03,1318.68]],"batl":[[0,1.08,71.43],[2,1.11,356.98]],"ltp":1.07,"tv":29452.84,"id":11439844}]}]}
{"op":"mcm","clk":"4234828410","pt":1631550333676,"mc":[{"id":"1.187560677","rc":[{"batb":[[0,8.6,31.8],[1,1.3,5],[2,1.01,105.79]],"batl":[[0,26,7],[1,36,2],[2,990,0.01]],"ltp":21.0,"tv":1714.82,"id":7588306},{"batb":[[0,1.04,1221.64],[1,1.03,1318.68],[2,1.02,1728.98]],"batl":[[2,1.11,94.48]],"ltp":1.07,"tv":29452.84,"id":11439844}]}]}
{"op":"mcm","clk":"4234828658","pt":1631550336592,"mc":[{"id":"1.187560677","rc":[{"batb":[[0,10,2],[1,8.6,31.8],[2,1.3,5]],"batl":[[0,21,2],[1,26,7],[2,36,2]],"ltp":21.0,"tv":1714.82,"id":7588306},{"batb":[[0,1.05,2.09],[1,1.04,1219.12],[2,1.03,1318.68]],"batl":[[2,1.11,293.98]],"ltp":1.07,"tv":29452.84,"id":11439844}]}]}
{"op":"mcm","clk":"4234828751","pt":1631550337700,"mc":[{"id":"1.187560677","rc":[{"batb":[[0,8.6,31.8],[1,1.3,5],[2,1.01,105.79]],"batl":[[0,26,7],[1,36,2],[2,990,0.01]],"ltp":21.0,"tv":1714.82,"id":7588306},{"batb":[[0,1.04,1255.21],[1,1.03,1318.68],[2,1.02,1728.98]],"batl":[[0,1.08,2.43],[2,1.11,94.48]],"ltp":1.07,"tv":29452.84,"id":11439844}]}]}
{"op":"mcm","clk":"4234829002","pt":1631550340681,"mc":[{"id":"1.187560677","rc":[{"batb":[[0,10,2.24],[1,8.6,31.8],[2,1.3,5]],"ltp":21.0,"tv":1714.82,"id":7588306},{"batl":[[2,1.11,100.98]],"ltp":1.07,"tv":29452.84,"id":11439844}]}]}
{"op":"mcm","clk":"4234829063","pt":1631550341370,"mc":[{"id":"1.187560677","rc":[{"batb":[[0,8.6,29.51],[1,1.3,5],[2,1.01,105.79]],"ltp":21.0,"tv":1714.82,"id":7588306},{"batl":[[2,1.11,94.48]],"ltp":1.07,"tv":29452.84,"id":11439844}]}]}
{"op":"mcm","clk":"4234829222","pt":1631550343565,"mc":[{"id":"1.187560677","rc":[{"trd":[[12,134.09],[13.5,6.31]],"batl":[[0,12,6.2],[1,12.5,3.2],[2,13.5,127.05]],"ltp":12.0,"tv":1715.24,"id":7588306},{"trd":[[1.08,219.28],[1.09,2137.72]],"batb":[[0,1.08,1588.16],[1,1.04,1255.21],[2,1.03,1318.68]],"batl":[[0,1.11,186.64],[1,1.12,2073.98],[2,1.13,187.74]],"ltp":1.09,"tv":29457.83,"id":11439844}],"tv":31173.08}]}
{"op":"mcm","clk":"4234829332","pt":1631550344665,"mc":[{"id":"1.187560677","rc":[{"batb":[[1,7.6,5],[2,6.4,23.23]],"batl":[[2,13.5,136.05]],"ltp":12.0,"tv":1715.24,"id":7588306},{"batb":[[0,1.08,2166.16],[1,1.07,478.12],[2,1.06,578]],"ltp":1.09,"tv":29457.83,"id":11439844}]}]}
{"op":"mcm","clk":"4234829417","pt":1631550345603,"mc":[{"id":"1.187560677","rc":[{"batb":[[2,1.06,602.06]],"ltp":1.09,"tv":29457.83,"id":11439844}]}]}
{"op":"mcm","clk":"4234829470","pt":1631550346186,"mc":[{"id":"1.187560677","rc":[{"batb":[[1,1.07,498.74]],"ltp":1.09,"tv":29457.83,"id":11439844}]}]}
{"op":"mcm","clk":"4234829950","pt":1631550351067,"mc":[{"id":"1.187560677","rc":[{"batb":[[2,7.2,4.72]],"ltp":12.0,"tv":1715.24,"id":7588306},{"batb":[[1,1.07,877.81],[2,1.06,1004.64]],"ltp":1.09,"tv":29457.83,"id":11439844}]}]}
{"op":"mcm","clk":"4234830185","pt":1631550353312,"mc":[{"id":"1.187560677","rc":[{"trd":[[1.1,997.05],[1.11,111.57]],"batl":[[0,1.11,146.64]],"ltp":1.11,"tv":29537.84,"id":11439844}],"tv":31253.08}]}
{"op":"mcm","clk":"4234830344","pt":1631550354505,"mc":[{"id":"1.187560677","rc":[{"batl":[[0,1.11,282.64]],"ltp":1.11,"tv":29537.84,"id":11439844}]}]}
{"op":"mcm","clk":"4234830893","pt":1631550360404,"mc":[{"id":"1.187560677","rc":[{"batl":[[2,1.13,187.5]],"ltp":1.11,"tv":29537.84,"id":11439844}]}]}
{"op":"mcm","clk":"4234831030","pt":1631550361715,"mc":[{"id":"1.187560677","rc":[{"batb":[[0,8.6,27.51]],"batl":[[0,13.5,9],[1,15.5,2],[2,18,2]],"ltp":12.0,"tv":1715.24,"id":7588306},{"batb":[[0,1.08,578]],"batl":[[0,1.11,190.48],[1,1.12,98],[2,1.15,96]],"ltp":1.11,"tv":29537.84,"id":11439844}]}]}
{"op":"mcm","clk":"4234831122","pt":1631550362497,"mc":[{"id":"1.187560677","rc":[{"trd":[[10,7.06]],"batb":[[0,7.6,5],[1,7.2,4.72],[2,6.4,28.79]],"batl":[[0,18,2],[1,21,4],[2,26,7]],"ltp":10.0,"tv":1715.49,"id":7588306},{"trd":[[1.11,113.82]],"batb":[[0,1.07,20.63],[1,1.06,1004.64],[2,1.05,1430.36]],"batl":[[0,1.15,96],[1,1.16,164.19],[2,1.17,161]],"ltp":1.11,"tv":29540.09,"id":11439844}],"tv":31255.58}]}
{"op":"mcm","clk":"4234831189","pt":1631550363070,"mc":[{"id":"1.187560677","rc":[{"batb":[[1,6.4,25.23],[2,1.3,5]],"ltp":10.0,"tv":1715.49,"id":7588306},{"batl":[[1,1.18,139.75],[2,1.19,14.94]],"ltp":1.11,"tv":29540.09,"id":11439844}]}]}
{"op":"mcm","clk":"4234831414","pt":1631550365422,"mc":[{"id":"1.187560677","rc":[{"batb":[[0,6.4,2],[1,6.2,24.07]],"batl":[[0,15.5,2],[1,18,2],[2,21,2]],"ltp":10.0,"tv":1715.49,"id":7588306},{"batb":[[0,1.07,372.7],[2,1.05,1166.1]],"batl":[[0,1.18,139.75],[1,1.19,14.94],[2,1.21,14.94]],"ltp":1.11,"tv":29540.09,"id":11439844}]}]}
{"op":"mcm","clk":"4234831708","pt":1631550368308,"mc":[{"id":"1.187560677","rc":[{"batb":[[0,13.5,3],[1,12,112.21],[2,6.4,2]],"batl":[[0,15,99.97],[1,15.5,2],[2,18,2]],"ltp":10.0,"tv":1715.49,"id":7588306},{"batl":[[0,1.08,101],[1,1.09,211.02],[2,1.11,36.04]],"ltp":1.11,"tv":29540.09,"id":11439844}]}]}
{"op":"mcm","clk":"4234831786","pt":1631550369203,"mc":[{"id":"1.187560677","rc":[{"batb":[[2,10.5,16.78]],"ltp":10.0,"tv":1715.49,"id":7588306}]}]}
{"op":"mcm","clk":"4234832439","pt":1631550376681,"mc":[{"id":"1.187560677","rc":[{"batb":[[0,12,2],[1,10.5,16.78],[2,7.2,17.03]],"batl":[[0,21,2],[1,26,7],[2,36,2]],"ltp":10.0,"tv":1715.49,"id":7588306},{"batb":[[0,1.07,20.63],[1,1.06,24.06]],"batl":[[0,1.09,6.5],[1,1.13,103],[2,1.18,139.75]],"ltp":1.11,"tv":29540.09,"id":11439844}]}]}
{"op":"mcm","clk":"4234832524","pt":1631550377618,"mc":[{"id":"1.187560677","rc":[{"batb":[[1,8.6,2],[2,7.6,2]],"batl":[[0,26,7],[1,36,2],[2,990,0.01]],"ltp":10.0,"tv":1715.49,"id":7588306},{"batb":[[2,1.05,28.87]],"batl":[[1,1.13,294.5],[2,1.14,201.25]],"ltp":1.11,"tv":29540.09,"id":11439844}]}]}
{"op":"mcm","clk":"4234832535","pt":1631550377730,"mc":[{"id":"1.187560677","rc":[{"batb":[[1,8.6,4.54],[2,7.6,4.79]],"ltp":10.0,"tv":1715.49,"id":7588306},{"batl":[[1,1.13,300.77],[2,1.14,207.5]],"ltp":1.11,"tv":29540.09,"id":11439844}]}]}
{"op":"mcm","clk":"4234832712","pt":1631550379708,"mc":[{"id":"1.187560677","rc":[{"batb":[[2,8,5]],"ltp":10.0,"tv":1715.49,"id":7588306},{"batl":[[2,1.14,308.5]],"ltp":1.11,"tv":29540.09,"id":11439844}]}]}
{"op":"mcm","clk":"4234833160","pt":1631550385198,"mc":[{"id":"1.187560677","rc":[{"batb":[[0,1.06,24.06],[1,1.05,28.87],[2,1.04,1255.21]],"ltp":1.11,"tv":29540.09,"id":11439844}]}]}
{"op":"mcm","clk":"4234833544","pt":1631550389549,"mc":[{"id":"1.187560677","rc":[{"batb":[[2,7.6,4.79]],"ltp":10.0,"tv":1715.49,"id":7588306},{"batl":[[1,1.13,197.77],[2,1.14,207.5]],"ltp":1.11,"tv":29540.09,"id":11439844}]}]}
{"op":"mcm","clk":"4234833661","pt":1631550390643,"mc":[{"id":"1.187560677","rc":[{"batb":[[0,1.04,1255.21],[1,1.03,1314.96],[2,1.02,1567.18]],"ltp":1.11,"tv":29540.09,"id":11439844}]}]}
{"op":"mcm","clk":"4234833690","pt":1631550390910,"mc":[{"id":"1.187560677","rc":[{"batl":[[0,21,2],[1,26,7],[2,36,2]],"ltp":10.0,"tv":1715.49,"id":7588306},{"batb":[[0,1.05,486.49],[1,1.04,1255.21],[2,1.03,1314.96]],"ltp":1.11,"tv":29540.09,"id":11439844}]}]}
{"op":"mcm","clk":"4234833825","pt":1631550392221,"mc":[{"id":"1.187560677","rc":[{"batb":[[0,17.5,6],[1,15,3],[2,14,2.86]],"batl":[[0,21,61.54]],"ltp":10.0,"tv":1715.49,"id":7588306},{"batb":[[0,1.05,1677.27]],"batl":[[0,1.06,119.5],[1,1.07,1858.43],[2,1.09,6.5]],"ltp":1.11,"tv":29540.09,"id":11439844}]}]}
{"op":"mcm","clk":"4234834148","pt":1631550395502,"mc":[{"id":"1.187560677","rc":[{"batl":[[2,1.11,95]],"ltp":1.11,"tv":29540.09,"id":11439844}]}]}
{"op":"mcm","clk":"4234834184","pt":1631550395923,"mc":[{"id":"1.187560677","rc":[{"batb":[[0,1.05,1706.14]],"ltp":1.11,"tv":29540.09,"id":11439844}]}]}
{"op":"mcm","clk":"4234834458","pt":1631550399134,"mc":[{"id":"1.187560677","rc":[{"batl":[[2,1.11,314]],"ltp":1.11,"tv":29540.09,"id":11439844}]}]}
{"op":"mcm","clk":"4234835587","pt":1631550411643,"mc":[{"id":"1.187560677","rc":[{"batb":[[2,13.5,8.56]],"ltp":10.0,"tv":1715.49,"id":7588306}]}]}
{"op":"mcm","clk":"4234835676","pt":1631550412483,"mc":[{"id":"1.187560677","rc":[{"batb":[[0,17.5,2],[1,10,4.24],[2,8.8,26.17]],"batl":[[0,36,2],[1,55,2],[2,990,0.01]],"ltp":10.0,"tv":1715.49,"id":7588306},{"batb":[[0,1.05,28.87],[1,1.04,36.09]],"batl":[[0,1.06,5.75],[1,1.11,314],[2,1.12,189.17]],"ltp":1.11,"tv":29540.09,"id":11439844}]}]}
{"op":"mcm","clk":"4234835878","pt":1631550414650,"mc":[{"id":"1.187560677","rc":[{"trd":[[17.5,4.35]],"batb":[[0,8.8,26.17],[1,8.6,2],[2,7.6,2]],"batl":[[0,17.5,10.15],[1,36,2],[2,55,2]],"ltp":17.5,"tv":1719.84,"id":7588306},{"trd":[[1.06,96.78]],"batl":[[0,1.11,95],[1,1.13,191.5],[2,1.14,201.25]],"ltp":1.06,"tv":29545.84,"id":11439844}],"tv":31265.68}]}
{"op":"mcm","clk":"4234835907","pt":1631550415074,"mc":[{"id":"1.187560677","rc":[{"batl":[[1,1.12,110],[2,1.13,288.5]],"ltp":1.06,"tv":29545.84,"id":11439844}]}]}
{"op":"mcm","clk":"4234836148","pt":1631550417656,"mc":[{"id":"1.187560677","rc":[{"batb":[[0,10,2],[1,8.8,26.17],[2,8.6,2]],"ltp":17.5,"tv":1719.84,"id":7588306},{"batl":[[0,1.11,312.5]],"ltp":1.06,"tv":29545.84,"id":11439844}]}]}
{"op":"mcm","clk":"4234836206","pt":1631550418243,"mc":[{"id":"1.187560677","rc":[{"batb":[[0,8.8,26.17],[1,8.6,2],[2,7.6,2]],"ltp":17.5,"tv":1719.84,"id":7588306},{"batl":[[0,1.11,95]],"ltp":1.06,"tv":29545.84,"id":11439844}]}]}
{"op":"mcm","clk":"4234836480","pt":1631550421468,"mc":[{"id":"1.187560677","rc":[{"batl":[[1,1.12,324.46]],"ltp":1.06,"tv":29545.84,"id":11439844}]}]}
{"op":"mcm","clk":"4234836501","pt":1631550421785,"mc":[{"id":"1.187560677","rc":[{"batl":[[1,1.12,110]],"ltp":1.06,"tv":29545.84,"id":11439844}]}]}
{"op":"mcm","clk":"4234836723","pt":1631550424673,"mc":[{"id":"1.187560677","rc":[{"batb":[[0,10,2],[1,8.8,26.17],[2,8.6,2]],"ltp":17.5,"tv":1719.84,"id":7588306},{"batl":[[0,1.11,316.5]],"ltp":1.06,"tv":29545.84,"id":11439844}]}]}
{"op":"mcm","clk":"4234836774","pt":1631550425360,"mc":[{"id":"1.187560677","rc":[{"batb":[[0,8.8,26.17],[1,8.6,2],[2,7.6,2]],"ltp":17.5,"tv":1719.84,"id":7588306},{"batl":[[0,1.11,95]],"ltp":1.06,"tv":29545.84,"id":11439844}]}]}
{"op":"mcm","clk":"4234837050","pt":1631550428674,"mc":[{"id":"1.187560677","rc":[{"batl":[[1,1.12,338.71]],"ltp":1.06,"tv":29545.84,"id":11439844}]}]}
{"op":"mcm","clk":"4234837107","pt":1631550429405,"mc":[{"id":"1.187560677","rc":[{"batb":[[2,1.3,5]],"ltp":17.5,"tv":1719.84,"id":7588306},{"batl":[[0,1.13,191.5],[1,1.14,201.25],[2,1.17,29.89]],"ltp":1.06,"tv":29545.84,"id":11439844}]}]}
{"op":"mcm","clk":"4234837219","pt":1631550430662,"mc":[{"id":"1.187560677","rc":[{"batb":[[0,1.04,36.09],[1,1.03,1314.96],[2,1.02,1904.71]],"batl":[[1,1.17,29.89],[2,1.19,14.94]],"ltp":1.06,"tv":29545.84,"id":11439844}]}]}
{"op":"mcm","clk":"4234837392","pt":1631550432600,"mc":[{"id":"1.187560677","rc":[{"trd":[[17.5,14.5]],"batb":[[0,26,2],[1,21,63.99],[2,17.5,7.8]],"batl":[[0,34,141.05]],"ltp":17.5,"tv":1729.99,"id":7588306},{"trd":[[1.04,297.8],[1.06,264.35]],"batb":[[0,1.03,1314.96],[1,1.02,1904.71],[2,1.01,4144.89]],"batl":[[0,1.04,62.89],[1,1.05,1324.11],[2,1.06,37.74]],"ltp":1.04,"tv":29785.61,"id":11439844}],"tv":31515.6}]}
{"op":"mcm","clk":"4234837737","pt":1631550437069,"mc":[{"id":"1.187560677","rc":[{"batl":[[0,1.04,98.98]],"ltp":1.04,"tv":29785.61,"id":11439844}]}]}
{"op":"mcm","clk":"4234838049","pt":1631550440383,"mc":[{"id":"1.187560677","rc":[{"batb":[[2,17.5,9.8]],"ltp":17.5,"tv":1729.99,"id":7588306},{"batl":[[2,1.06,461.49]],"ltp":1.04,"tv":29785.61,"id":11439844}]}]}
{"op":"mcm","clk":"4234838786","pt":1631550448313,"mc":[{"id":"1.187560677","rc":[{"trd":[[1.04,297.84]],"batl":[[0,1.04,98.96]],"ltp":1.04,"tv":29785.65,"id":11439844}],"tv":31515.64}]}
{"op":"mcm","clk":"4234839060","pt":1631550450723,"mc":[{"id":"1.187560677","rc":[{"trd":[[1.03,10.52]],"batb":[[0,1.03,1309.7]],"ltp":1.03,"tv":29796.17,"id":11439844}],"tv":31526.16}]}
{"op":"mcm","clk":"4234839419","pt":1631550454620,"mc":[{"id":"1.187560677","rc":[{"batl":[[2,1.06,423.75]],"ltp":1.03,"tv":29796.17,"id":11439844}]}]}
{"op":"mcm","clk":"4234839490","pt":1631550455409,"mc":[{"id":"1.187560677","rc":[{"batb":[[0,15,5],[1,13,9.39],[2,10,2]],"batl":[[0,55,2],[1,990,0.01],[2,55,0]],"ltp":17.5,"tv":1729.99,"id":7588306},{"batb":[[0,1.03,48.13]],"batl":[[0,1.04,36.09],[1,1.07,469.5],[2,1.08,323.69]],"ltp":1.03,"tv":29796.17,"id":11439844}]}]}
{"op":"mcm","clk":"4234839511","pt":1631550455719,"mc":[{"id":"1.187560677","rc":[{"batl":[[2,1.11,224.5]],"ltp":1.03,"tv":29796.17,"id":11439844}]}]}
{"op":"mcm","clk":"4234839747","pt":1631550458640,"mc":[{"id":"1.187560677","rc":[{"batb":[[0,17.5,2],[1,15,2],[2,13,9.39]],"batl":[[0,36,2],[1,55,2],[2,990,0.01]],"ltp":17.5,"tv":1729.99,"id":7588306},{"batb":[[0,1.03,50.29]],"batl":[[1,1.06,398.75],[2,1.13,14.94]],"ltp":1.03,"tv":29796.17,"id":11439844}]}]}
{"op":"mcm","clk":"4234839792","pt":1631550459115,"mc":[{"id":"1.187560677","rc":[{"batl":[[0,55,2],[1,990,0.01],[2,990,0]],"ltp":17.5,"tv":1729.99,"id":7588306},{"batb":[[0,1.02,1904.71],[1,1.01,4144.89],[2,1.01,0]],"batl":[[2,1.08,342.19]],"ltp":1.03,"tv":29796.17,"id":11439844}]}]}
{"op":"mcm","clk":"4234839999","pt":1631550461414,"mc":[{"id":"1.187560677","rc":[{"batb":[[0,26,77.97],[1,23,1.74],[2,21,2]],"batl":[[0,50,132.73],[1,55,2],[2,990,0.01]],"ltp":17.5,"tv":1729.99,"id":7588306},{"batl":[[0,1.04,2004.75],[1,1.05,95],[2,1.06,490.75]],"ltp":1.03,"tv":29796.17,"id":11439844}]}]}
{"op":"mcm","clk":"4234840120","pt":1631550462714,"mc":[{"id":"1.187560677","rc":[{"batl":[[0,1.03,48.13],[1,1.04,2004.75],[2,1.05,95]],"ltp":1.03,"tv":29796.17,"id":11439844}]}]}
{"op":"mcm","clk":"4234840220","pt":1631550464018,"mc":[{"id":"1.187560677","rc":[{"batl":[[1,1.04,1968.66]],"ltp":1.03,"tv":29796.17,"id":11439844}]}]}
{"op":"mcm","clk":"4234840544","pt":1631550468140,"mc":[{"id":"1.187560677","rc":[{"batb":[[2,21,4]],"batl":[[2,110,2]],"ltp":17.5,"tv":1729.99,"id":7588306},{"batl":[[0,1.04,1968.66],[1,1.05,650.3],[2,1.06,490.75]],"ltp":1.03,"tv":29796.17,"id":11439844}]}]}
{"op":"mcm","clk":"4234841604","pt":1631550479940,"mc":[{"id":"1.187560677","rc":[{"batl":[[0,1.04,2004.75]],"ltp":1.03,"tv":29796.17,"id":11439844}]}]}
{"op":"mcm","clk":"4234842745","pt":1631550492663,"mc":[{"id":"1.187560677","rc":[{"batb":[[0,26,4],[1,21,4],[2,20,8.98]],"batl":[[0,55,2],[1,110,2],[2,990,0.01]],"ltp":17.5,"tv":1729.99,"id":7588306},{"batl":[[0,1.04,155.47]],"ltp":1.03,"tv":29796.17,"id":11439844}]}]}
{"op":"mcm","clk":"4234842805","pt":1631550493178,"mc":[{"id":"1.187560677","rc":[{"batb":[[0,26,2],[2,19,11.74]],"batl":[[0,110,2],[1,990,0.01],[2,990,0]],"ltp":17.5,"tv":1729.99,"id":7588306},{"batb":[[0,1.02,72.19]],"batl":[[0,1.04,141.09]],"ltp":1.03,"tv":29796.17,"id":11439844}]}]}
{"op":"mcm","clk":"4234843161","pt":1631550496559,"mc":[{"id":"1.187560677","rc":[{"trd":[[26,1.8]],"batb":[[0,26,3.1]],"ltp":26.0,"tv":1731.79,"id":7588306},{"batl":[[0,1.04,769.47]],"ltp":1.03,"tv":29796.17,"id":11439844}],"tv":31527.96}]}
{"op":"mcm","clk":"4234843341","pt":1631550498660,"mc":[{"id":"1.187560677","rc":[{"batb":[[0,26,1.1]],"ltp":26.0,"tv":1731.79,"id":7588306},{"batl":[[0,1.04,179.97]],"ltp":1.03,"tv":29796.17,"id":11439844}]}]}
{"op":"mcm","clk":"4234843366","pt":1631550499083,"mc":[{"id":"1.187560677","rc":[{"batl":[[0,1.04,141.09]],"ltp":1.03,"tv":29796.17,"id":11439844}]}]}
{"op":"mcm","clk":"4234843599","pt":1631550501559,"mc":[{"id":"1.187560677","rc":[{"batb":[[0,26,3.1]],"ltp":26.0,"tv":1731.79,"id":7588306},{"batl":[[0,1.04,753.72]],"ltp":1.03,"tv":29796.17,"id":11439844}]}]}
{"op":"mcm","clk":"4234844664","pt":1631550513179,"mc":[{"id":"1.187560677","rc":[{"batb":[[0,26,1.1]],"ltp":26.0,"tv":1731.79,"id":7588306},{"batl":[[0,1.04,141.09],[1,1.05,95],[2,1.09,11.96]],"ltp":1.03,"tv":29796.17,"id":11439844}]}]}
{"op":"mcm","clk":"4234844895","pt":1631550515698,"mc":[{"id":"1.187560677","rc":[{"batb":[[0,34,2],[1,27,7.4],[2,26,1.1]],"batl":[[0,100,184.43],[1,110,2],[2,990,0.01]],"ltp":26.0,"tv":1731.79,"id":7588306},{"batb":[[0,1.02,69.93]],"batl":[[0,1.03,4039.35],[1,1.04,141.09],[2,1.05,95]],"ltp":1.03,"tv":29796.17,"id":11439844}]}]}
{"op":"mcm","clk":"4234845001","pt":1631550516689,"mc":[{"id":"1.187560677","rc":[{"batb":[[0,34,4],[1,27,1.48]],"ltp":26.0,"tv":1731.79,"id":7588306},{"batl":[[0,1.03,4133.35]],"ltp":1.03,"tv":29796.17,"id":11439844}]}]}
{"op":"mcm","clk":"4234845299","pt":1631550520097,"mc":[{"id":"1.187560677","rc":[{"batb":[[0,1.02,142.12]],"ltp":1.03,"tv":29796.17,"id":11439844}]}]}
{"op":"mcm","clk":"4234845502","pt":1631550522499,"mc":[{"id":"1.187560677","rc":[{"batb":[[2,26,3.1]],"ltp":26.0,"tv":1731.79,"id":7588306},{"batl":[[1,1.04,700.13],[2,1.05,626.1]],"ltp":1.03,"tv":29796.17,"id":11439844}]}]}
{"op":"mcm","clk":"4234845693","pt":1631550524897,"mc":[{"id":"1.187560677","rc":[{"batl":[[0,1.03,4181.48]],"ltp":1.03,"tv":29796.17,"id":11439844}]}]}
{"op":"mcm","clk":"4234846427","pt":1631550533692,"mc":[{"id":"1.187560677","rc":[{"batb":[[0,34,2],[1,26,3.1],[2,24,4.36]],"batl":[[0,110,2],[1,990,0.01],[2,990,0]],"ltp":26.0,"tv":1731.79,"id":7588306},{"batb":[[0,1.02,72.19]],"batl":[[0,1.03,142.13]],"ltp":1.03,"tv":29796.17,"id":11439844}]}]}
{"op":"mcm","clk":"4234846461","pt":1631550534105,"mc":[{"id":"1.187560677","rc":[{"batb":[[0,26,3.1],[1,21,11.65],[2,1.3,5]],"ltp":26.0,"tv":1731.79,"id":7588306},{"trd":[[1.03,10.59]],"batb":[[1,1.01,3094.89]],"batl":[[0,1.03,48.09]],"ltp":1.03,"tv":29796.24,"id":11439844}],"tv":31528.03}]}
{"op":"mcm","clk":"4234846808","pt":1631550537316,"mc":[{"id":"1.187560677","rc":[{"batb":[[2,17.5,2]],"ltp":26.0,"tv":1731.79,"id":7588306}]}]}
{"op":"mcm","clk":"4234847096","pt":1631550540626,"mc":[{"id":"1.187560677","rc":[{"batb":[[0,34,2],[1,26,3.1],[2,21,9.65]],"ltp":26.0,"tv":1731.79,"id":7588306},{"batl":[[0,1.03,885.59],[1,1.04,105],[2,1.05,95]],"ltp":1.03,"tv":29796.24,"id":11439844}]}]}
{"op":"mcm","clk":"4234847168","pt":1631550541417,"mc":[{"id":"1.187560677","rc":[{"batb":[[0,26,3.1],[1,21,9.65],[2,17.5,2]],"ltp":26.0,"tv":1731.79,"id":7588306},{"trd":[[1.02,22.22]],"batb":[[0,1.02,61.08]],"batl":[[0,1.03,48.09]],"ltp":1.02,"tv":29818.46,"id":11439844}],"tv":31550.25}]}
{"op":"mcm","clk":"4234847221","pt":1631550542046,"mc":[{"id":"1.187560677","rc":[{"batl":[[0,1.04,105],[1,1.05,95],[2,1.06,96]],"ltp":1.02,"tv":29818.46,"id":11439844}]}]}
{"op":"mcm","clk":"4234847344","pt":1631550543523,"mc":[{"id":"1.187560677","rc":[{"batb":[[0,26,88.7]],"batl":[[0,50,119.02],[1,110,2],[2,990,0.01]],"ltp":26.0,"tv":1731.79,"id":7588306},{"batl":[[0,1.03,65.25],[1,1.04,2245.11],[2,1.05,95]],"ltp":1.02,"tv":29818.46,"id":11439844}]}]}
{"op":"mcm","clk":"4234847406","pt":1631550544347,"mc":[{"id":"1.187560677","rc":[{"batb":[[2,19,11.49]],"ltp":26.0,"tv":1731.79,"id":7588306},{"batb":[[0,1.02,732.08],[1,1.01,3765.89]],"ltp":1.02,"tv":29818.46,"id":11439844}]}]}
{"op":"mcm","clk":"4234847493","pt":1631550545446,"mc":[{"id":"1.187560677","rc":[{"batl":[[0,1.03,73.78]],"ltp":1.02,"tv":29818.46,"id":11439844}]}]}
{"op":"mcm","clk":"4234847876","pt":1631550550060,"mc":[{"id":"1.187560677","rc":[{"batb":[[1,21,11.65]],"ltp":26.0,"tv":1731.79,"id":7588306},{"batl":[[2,1.05,656.9]],"ltp":1.02,"tv":29818.46,"id":11439844}]}]}
{"op":"mcm","clk":"4234848200","pt":1631550553312,"mc":[{"id":"1.187560677","rc":[{"batl":[[1,1.04,2883.24]],"ltp":1.02,"tv":29818.46,"id":11439844}]}]}
{"op":"mcm","clk":"4234849223","pt":1631550563517,"mc":[{"id":"1.187560677","rc":[{"trd":[[1.03,158.12]],"batb":[[0,1.03,98.57],[1,1.02,732.08],[2,1.01,3765.89]],"batl":[[0,1.04,2883.24],[1,1.05,656.9],[2,1.06,547.25]],"ltp":1.03,"tv":29965.99,"id":11439844}],"tv":31697.78}]}
{"op":"mcm","clk":"4234849640","pt":1631550567612,"mc":[{"id":"1.187560677","rc":[{"batb":[[0,26,1.1]],"batl":[[0,110,2],[1,990,0.01],[2,990,0]],"ltp":26.0,"tv":1731.79,"id":7588306},{"batl":[[0,1.04,105]],"ltp":1.03,"tv":29965.99,"id":11439844}]}]}
{"op":"mcm","clk":"4234849661","pt":1631550567823,"mc":[{"id":"1.187560677","rc":[{"batb":[[1,21,4]],"ltp":26.0,"tv":1731.79,"id":7588306},{"batb":[[1,1.02,61.08]],"ltp":1.03,"tv":29965.99,"id":11439844}]}]}
{"op":"mcm","clk":"4234850243","pt":1631550574409,"mc":[{"id":"1.187560677","rc":[{"batb":[[0,26,3.1]],"ltp":26.0,"tv":1731.79,"id":7588306},{"batl":[[0,1.04,742.38]],"ltp":1.03,"tv":29965.99,"id":11439844}]}]}
{"op":"mcm","clk":"4234850272","pt":1631550574721,"mc":[{"id":"1.187560677","rc":[{"batb":[[0,26,1.1]],"ltp":26.0,"tv":1731.79,"id":7588306},{"batl":[[0,1.04,105]],"ltp":1.03,"tv":29965.99,"id":11439844}]}]}
{"op":"mcm","clk":"4234851557","pt":1631550588423,"mc":[{"id":"1.187560677","rc":[{"batb":[[0,26,3.1]],"ltp":26.0,"tv":1731.79,"id":7588306},{"batl":[[0,1.04,703.63]],"ltp":1.03,"tv":29965.99,"id":11439844}]}]}
{"op":"mcm","clk":"4234851616","pt":1631550589001,"mc":[{"id":"1.187560677","rc":[{"batb":[[0,21,4],[1,19,11.49],[2,17.5,2]],"ltp":26.0,"tv":1731.79,"id":7588306},{"batl":[[0,1.05,656.9],[1,1.06,547.25],[2,1.11,11.96]],"ltp":1.03,"tv":29965.99,"id":11439844}]}]}
{"op":"mcm","clk":"4234851948","pt":1631550592353,"mc":[{"id":"1.187560677","rc":[{"batl":[[2,1.07,97]],"ltp":1.03,"tv":29965.99,"id":11439844}]}]}
{"op":"mcm","clk":"4234852282","pt":1631550595546,"mc":[{"id":"1.187560677","rc":[{"batb":[[0,26,2],[1,21,4],[2,19,11.49]],"ltp":26.0,"tv":1731.79,"id":7588306},{"batl":[[0,1.04,683.13],[1,1.05,656.9],[2,1.06,547.25]],"ltp":1.03,"tv":29965.99,"id":11439844}]}]}
{"op":"mcm","clk":"4234852316","pt":1631550595860,"mc":[{"id":"1.187560677","rc":[{"batb":[[0,21,4],[1,19,11.49],[2,17.5,2]],"ltp":26.0,"tv":1731.79,"id":7588306},{"batl":[[0,1.05,656.9],[1,1.06,547.25],[2,1.07,97]],"ltp":1.03,"tv":29965.99,"id":11439844}]}]}
{"op":"mcm","clk":"4234852638","pt":1631550599052,"mc":[{"id":"1.187560677","rc":[{"batb":[[0,26,2],[1,21,4],[2,19,11.49]],"ltp":26.0,"tv":1731.79,"id":7588306},{"batl":[[0,1.04,593.63],[1,1.05,656.9],[2,1.06,547.25]],"ltp":1.03,"tv":29965.99,"id":11439844}]}]}
{"op":"mcm","clk":"4234853027","pt":1631550602357,"mc":[{"id":"1.187560677","rc":[{"batb":[[1,21,112.1]],"batl":[[0,34,6.17],[1,40,1],[2,50,234.84]],"ltp":26.0,"tv":1731.79,"id":7588306},{"batb":[[0,1.03,762.57],[1,1.02,725.08]],"batl":[[0,1.04,619.86],[1,1.05,2818.93]],"ltp":1.03,"tv":29965.99,"id":11439844}]}]}
{"op":"mcm","clk":"4234853496","pt":1631550605794,"mc":[{"id":"1.187560677","rc":[{"batb":[[0,1.03,810.69]],"ltp":1.03,"tv":29965.99,"id":11439844}]}]}
{"op":"mcm","clk":"4234853812","pt":1631550608751,"mc":[{"id":"1.187560677","rc":[{"batb":[[1,1.02,1972.2]],"ltp":1.03,"tv":29965.99,"id":11439844}]}]}
{"op":"mcm","clk":"4234854510","pt":1631550615493,"mc":[{"id":"1.187560677","rc":[{"batl":[[1,1.05,3766.24]],"ltp":1.03,"tv":29965.99,"id":11439844}]}]}
{"op":"mcm","clk":"4234855770","pt":1631550627411,"mc":[{"id":"1.187560677","rc":[{"batb":[[0,21,4],[1,18,6.96],[2,17.5,2]],"batl":[[0,55,2],[1,110,2],[2,990,0.01]],"ltp":26.0,"tv":1731.79,"id":7588306},{"batb":[[0,1.03,146.69]],"batl":[[0,1.05,1604.21],[1,1.06,547.25],[2,1.07,97]],"ltp":1.03,"tv":29965.99,"id":11439844}]}]}
{"op":"mcm","clk":"4234856771","pt":1631550637491,"mc":[{"id":"1.187560677","rc":[{"batb":[[0,26,2],[1,21,4],[2,18,6.96]],"ltp":26.0,"tv":1731.79,"id":7588306},{"batl":[[0,1.04,559.63],[1,1.05,1604.21],[2,1.06,547.25]],"ltp":1.03,"tv":29965.99,"id":11439844}]}]}
{"op":"mcm","clk":"4234856804","pt":1631550637919,"mc":[{"id":"1.187560677","rc":[{"batb":[[0,21,4],[1,18,6.96],[2,17.5,2]],"ltp":26.0,"tv":1731.79,"id":7588306},{"batl":[[0,1.05,1604.21],[1,1.06,547.25],[2,1.07,97]],"ltp":1.03,"tv":29965.99,"id":11439844}]}]}
{"op":"mcm","clk":"4234857433","pt":1631550644526,"mc":[{"id":"1.187560677","rc":[{"batb":[[0,26,2],[1,21,4],[2,18,6.96]],"ltp":26.0,"tv":1731.79,"id":7588306},{"batl":[[0,1.04,616.63],[1,1.05,1604.21],[2,1.06,547.25]],"ltp":1.03,"tv":29965.99,"id":11439844}]}]}
{"op":"mcm","clk":"4234857462","pt":1631550644790,"mc":[{"id":"1.187560677","rc":[{"batb":[[0,21,4],[1,18,6.96],[2,17.5,2]],"ltp":26.0,"tv":1731.79,"id":7588306},{"batl":[[0,1.05,1604.21],[1,1.06,547.25],[2,1.11,11.96]],"ltp":1.03,"tv":29965.99,"id":11439844}]}]}
{"op":"mcm","clk":"4234857609","pt":1631550646516,"mc":[{"id":"1.187560677","rc":[{"batb":[[0,21,54.4]],"batl":[[0,26,3.63],[1,32,259.5],[2,34,170.48]],"ltp":26.0,"tv":1731.79,"id":7588306},{"batl":[[0,1.05,2660.62]],"ltp":1.03,"tv":29965.99,"id":11439844}]}]}
{"op":"mcm","clk":"4234857721","pt":1631550647509,"mc":[{"id":"1.187560677","rc":[{"trd":[[26,5.43]],"batb":[[0,26,2],[1,21,54.4],[2,18,6.96]],"batl":[[0,34,170.48],[1,55,2.9],[2,110,2]],"ltp":26.0,"tv":1735.42,"id":7588306},{"trd":[[1.04,388.59]],"batb":[[0,1.03,810.69]],"batl":[[0,1.04,1.25],[1,1.05,2660.62],[2,1.06,547.25]],"ltp":1.04,"tv":30056.74,"id":11439844}],"tv":31792.16}]}
{"op":"mcm","clk":"4234857802","pt":1631550648192,"mc":[{"id":"1.187560677","rc":[{"trd":[[26,6.82]],"batb":[[0,21,55.01],[1,18,6.96],[2,17.5,9.88]],"ltp":26.0,"tv":1736.81,"id":7588306},{"trd":[[1.04,425.93]],"batl":[[0,1.05,2660.62],[1,1.06,547.25],[2,1.11,11.96]],"ltp":1.04,"tv":30094.08,"id":11439844}],"tv":31830.89}]}
{"op":"mcm","clk":"4234858356","pt":1631550653534,"mc":[{"id":"1.187560677","rc":[{"batb":[[2,17.5,11.88]],"batl":[[1,36,2],[2,55,2.9]],"ltp":26.0,"tv":1736.81,"id":7588306},{"batb":[[0,1.03,1670.52]],"batl":[[2,1.07,364.5]],"ltp":1.04,"tv":30094.08,"id":11439844}]}]}
{"op":"mcm","clk":"4234858620","pt":1631550655731,"mc":[{"id":"1.187560677","rc":[{"batl":[[0,1.04,22.37],[1,1.05,2660.62],[2,1.06,547.25]],"ltp":1.04,"tv":30094.08,"id":11439844}]}]}
{"op":"mcm","clk":"4234858791","pt":1631550657316,"mc":[{"id":"1.187560677","rc":[{"batl":[[1,1.05,2612.25]],"ltp":1.04,"tv":30094.08,"id":11439844}]}]}
{"op":"mcm","clk":"4234859017","pt":1631550660035,"mc":[{"id":"1.187560677","rc":[{"batb":[[0,21,59.68]],"batl":[[0,34,179.54]],"ltp":26.0,"tv":1736.81,"id":7588306},{"batl":[[1,1.05,2705.58]],"ltp":1.04,"tv":30094.08,"id":11439844}]}]}
{"op":"mcm","clk":"4234859122","pt":1631550661249,"mc":[{"id":"1.187560677","rc":[{"batb":[[0,1.03,1571.96]],"ltp":1.04,"tv":30094.08,"id":11439844}]}]}
{"op":"mcm","clk":"4234859316","pt":1631550663338,"mc":[{"id":"1.187560677","rc":[{"trd":[[1.03,162.12]],"batb":[[0,1.03,1569.96]],"ltp":1.03,"tv":30098.08,"id":11439844}],"tv":31834.89}]}
{"op":"mcm","clk":"4234860165","pt":1631550671557,"mc":[{"id":"1.187560677","rc":[{"batb":[[0,21,4],[1,17.5,11.88],[2,1.3,5]],"batl":[[0,55,2],[1,110,2],[2,990,0.01]],"ltp":26.0,"tv":1736.81,"id":7588306},{"batb":[[0,1.03,46.13]],"batl":[[1,1.05,1604.21]],"ltp":1.03,"tv":30098.08,"id":11439844}]}]}
{"op":"mcm","clk":"4234860449","pt":1631550674229,"mc":[{"id":"1.187560677","rc":[{"batb":[[2,15,3]],"ltp":26.0,"tv":1736.81,"id":7588306}]}]}
{"op":"mcm","clk":"4234861138","pt":1631550681248,"mc":[{"id":"1.187560677","rc":[{"batb":[[2,1.3,5]],"ltp":26.0,"tv":1736.81,"id":7588306},{"trd":[[1.04,428.63]],"batl":[[0,1.04,21.02]],"ltp":1.04,"tv":30100.78,"id":11439844}],"tv":31837.59}]}
{"op":"mcm","clk":"4234861192","pt":1631550681762,"mc":[{"id":"1.187560677","rc":[{"batl":[[0,36,2],[1,55,2],[2,110,2]],"ltp":26.0,"tv":1736.81,"id":7588306},{"batb":[[0,1.03,886.96]],"ltp":1.04,"tv":30100.78,"id":11439844}]}]}
{"op":"mcm","clk":"4234861449","pt":1631550684162,"mc":[{"id":"1.187560677","rc":[{"batb":[[0,26,2],[1,21,104.04],[2,20,2]],"batl":[[0,34,85.2],[1,36,2],[2,55,2]],"ltp":26.0,"tv":1736.81,"id":7588306},{"batl":[[0,1.04,186.89],[1,1.05,3605.11]],"ltp":1.04,"tv":30100.78,"id":11439844}]}]}
{"op":"mcm","clk":"4234863251","pt":1631550701685,"mc":[{"id":"1.187560677","rc":[{"trd":[[1.04,432.04]],"batl":[[0,1.04,185.19]],"ltp":1.04,"tv":30104.19,"id":11439844}],"tv":31841.0}]}
{"op":"mcm","clk":"4234863520","pt":1631550704613,"mc":[{"id":"1.187560677","rc":[{"batb":[[0,21,4],[1,19.5,11.24],[2,18,7.05]],"batl":[[0,55,2],[1,110,2],[2,990,0.01]],"ltp":26.0,"tv":1736.81,"id":7588306},{"batb":[[0,1.03,46.13]],"batl":[[0,1.04,111.32],[1,1.05,1604.21]],"ltp":1.04,"tv":30104.19,"id":11439844}]}]}
{"op":"mcm","clk":"4234863546","pt":1631550704822,"mc":[{"id":"1.187560677","rc":[{"batb":[[1,18,7.05],[2,17.5,4]],"ltp":26.0,"tv":1736.81,"id":7588306},{"batl":[[0,1.04,19.32]],"ltp":1.04,"tv":30104.19,"id":11439844}]}]}
{"op":"mcm","clk":"4234865481","pt":1631550723358,"mc":[{"id":"1.187560677","rc":[{"trd":[[1.04,435.45]],"batl":[[0,1.04,17.62]],"ltp":1.04,"tv":30107.6,"id":11439844}],"tv":31844.41}]}
{"op":"mcm","clk":"4234865787","pt":1631550725547,"mc":[{"id":"1.187560677","rc":[{"batb":[[0,21,7.66]],"batl":[[0,34,208.33],[1,55,2],[2,110,2]],"ltp":26.0,"tv":1736.81,"id":7588306},{"batb":[[0,1.03,787.13]],"batl":[[1,1.05,1677.41],[2,1.06,4444.92]],"ltp":1.04,"tv":30107.6,"id":11439844}]}]}
{"op":"mcm","clk":"4234866156","pt":1631550728827,"mc":[{"id":"1.187560677","rc":[{"batb":[[0,21,5.66]],"ltp":26.0,"tv":1736.81,"id":7588306}]}]}
{"op":"mcm","clk":"4234867541","pt":1631550743075,"mc":[{"id":"1.187560677","rc":[{"batl":[[0,1.04,2017.62]],"ltp":1.04,"tv":30107.6,"id":11439844}]}]}
{"op":"mcm","clk":"4234867937","pt":1631550747161,"mc":[{"id":"1.187560677","rc":[{"trd":[[1.03,562.1]],"batb":[[0,1.03,587.15]],"ltp":1.03,"tv":30507.58,"id":11439844}],"tv":32244.39}]}
{"op":"mcm","clk":"4234868065","pt":1631550748263,"mc":[{"id":"1.187560677","rc":[{"batl":[[0,1.04,2160.16]],"ltp":1.03,"tv":30507.58,"id":11439844}]}]}
{"op":"mcm","clk":"4234868409","pt":1631550751492,"mc":[{"id":"1.187560677","rc":[{"trd":[[26,14.04]],"ltp":26.0,"tv":1744.03,"id":7588306},{"trd":[[1.04,616.03]],"batl":[[0,1.04,1979.57]],"ltp":1.04,"tv":30688.16,"id":11439844}],"tv":32432.2}]}
{"op":"mcm","clk":"4234868968","pt":1631550756183,"mc":[{"id":"1.187560677","rc":[{"trd":[[1.03,576.54]],"batb":[[0,1.03,579.93]],"batl":[[0,1.04,2015.66]],"ltp":1.03,"tv":30702.6,"id":11439844}],"tv":32446.63}]}
{"op":"mcm","clk":"4234870787","pt":1631550774615,"mc":[{"id":"1.187560677","rc":[{"trd":[[1.04,619.45]],"batl":[[0,1.04,2013.95]],"ltp":1.04,"tv":30706.02,"id":11439844}],"tv":32450.05}]}
{"op":"mcm","clk":"4234872262","pt":1631550789343,"mc":[{"id":"1.187560677","rc":[{"trd":[[26,16.04]],"ltp":26.0,"tv":1746.03,"id":7588306},{"trd":[[1.04,669.45]],"batl":[[0,1.04,1963.95]],"ltp":1.04,"tv":30756.02,"id":11439844}],"tv":32502.05}]}
{"op":"mcm","clk":"4234872391","pt":1631550790745,"mc":[{"id":"1.187560677","rc":[{"trd":[[1.03,593.13]],"batb":[[0,1.03,571.63]],"ltp":1.03,"tv":30772.61,"id":11439844}],"tv":32518.64}]}
{"op":"mcm","clk":"4234872731","pt":1631550794352,"mc":[{"id":"1.187560677","rc":[{"trd":[[1.03,613.13]],"batb":[[0,1.03,561.63]],"ltp":1.03,"tv":30792.61,"id":11439844}],"tv":32538.64}]}
{"op":"mcm","clk":"4234875960","pt":1631550826101,"mc":[{"id":"1.187560677","rc":[{"batl":[[0,1.04,1821.41]],"ltp":1.03,"tv":30792.61,"id":11439844}]}]}
{"op":"mcm","clk":"4234876286","pt":1631550829222,"mc":[{"id":"1.187560677","rc":[{"trd":[[1.03,898.21]],"batb":[[0,1.03,419.09]],"ltp":1.03,"tv":31077.69,"id":11439844}],"tv":32823.72}]}
{"op":"mcm","clk":"4234877051","pt":1631550836629,"mc":[{"id":"1.187560677","rc":[{"batb":[[0,21,2],[2,17.5,2]],"batl":[[0,55,2],[1,110,2],[2,990,0.01]],"ltp":26.0,"tv":1746.03,"id":7588306},{"batl":[[1,1.05,1042.31],[2,1.06,96]],"ltp":1.03,"tv":31077.69,"id":11439844}]}]}
{"op":"mcm","clk":"4234877095","pt":1631550837047,"mc":[{"id":"1.187560677","rc":[{"batb":[[0,15,5],[1,13.5,2],[2,13,9.31]],"ltp":26.0,"tv":1746.03,"id":7588306},{"batb":[[0,1.02,1972.2],[1,1.01,3765.89],[2,1.01,0]],"batl":[[1,1.05,947.31],[2,1.07,458.5]],"ltp":1.03,"tv":31077.69,"id":11439844}]}]}
{"op":"mcm","clk":"4234877455","pt":1631550840322,"mc":[{"id":"1.187560677","rc":[{"batb":[[1,13.5,5],[2,12.5,9.65]],"ltp":26.0,"tv":1746.03,"id":7588306}]}]}
{"op":"mcm","clk":"4234877565","pt":1631550841439,"mc":[{"id":"1.187560677","rc":[{"batl":[[1,1.05,988.41]],"ltp":1.03,"tv":31077.69,"id":11439844}]}]}
{"op":"mcm","clk":"4234877600","pt":1631550841812,"mc":[{"id":"1.187560677","rc":[{"batl":[[1,1.05,947.31]],"ltp":1.03,"tv":31077.69,"id":11439844}]}]}
{"op":"mcm","clk":"4234878900","pt":1631550854640,"mc":[{"id":"1.187560677","rc":[{"trd":[[21,76.62],[26,87.45]],"batb":[[1,13.5,87.67]],"batl":[[0,21,105.77],[1,23,8.7],[2,55,2]],"ltp":21.0,"tv":1864.83,"id":7588306},{"trd":[[1.04,2454.77],[1.05,1086.43]],"batb":[[0,1.05,2115.32],[1,1.02,1972.2],[2,1.01,3765.89]],"batl":[[0,1.07,550.03],[1,1.08,1427.27],[2,1.11,11.96]],"ltp":1.05,"tv":33810.32,"id":11439844}],"tv":35675.15}]}
{"op":"mcm","clk":"4234879016","pt":1631550855649,"mc":[{"id":"1.187560677","rc":[{"batb":[[0,15,3]],"batl":[[0,21,110.77],[1,23,1.74]],"ltp":21.0,"tv":1864.83,"id":7588306},{"batb":[[0,1.05,2653.32],[1,1.03,1417.06],[2,1.02,1972.2]],"batl":[[0,1.07,185.53],[2,1.1,104]],"ltp":1.05,"tv":33810.32,"id":11439844}]}]}
{"op":"mcm","clk":"4234879421","pt":1631550859671,"mc":[{"id":"1.187560677","rc":[{"batl":[[0,1.06,24.06],[1,1.07,185.53],[2,1.08,1427.27]],"ltp":1.05,"tv":33810.32,"id":11439844}]}]}
{"op":"mcm","clk":"4234879648","pt":1631550861832,"mc":[{"id":"1.187560677","rc":[{"batl":[[2,26,2]],"ltp":21.0,"tv":1864.83,"id":7588306},{"batb":[[1,1.04,611.12],[2,1.03,2240.89]],"ltp":1.05,"tv":33810.32,"id":11439844}]}]}
{"op":"mcm","clk":"4234879901","pt":1631550864449,"mc":[{"id":"1.187560677","rc":[{"batb":[[0,11,4],[1,10,2],[2,8.6,29.6]],"batl":[[0,36,2],[1,55,2],[2,110,2]],"ltp":21.0,"tv":1864.83,"id":7588306},{"batb":[[0,1.03,1361.83],[1,1.02,1972.2],[2,1.01,3765.89]],"batl":[[1,1.1,104],[2,1.11,219.46]],"ltp":1.05,"tv":33810.32,"id":11439844}]}]}
{"op":"mcm","clk":"4234880234","pt":1631550867676,"mc":[{"id":"1.187560677","rc":[{"batb":[[0,10,2],[1,8.6,29.6],[2,1.3,5]],"batl":[[0,26,2],[1,36,2],[2,55,2]],"ltp":21.0,"tv":1864.83,"id":7588306},{"batb":[[0,1.04,571.87],[1,1.03,1361.83],[2,1.02,1972.2]],"batl":[[1,1.11,314.46],[2,1.12,286.96]],"ltp":1.05,"tv":33810.32,"id":11439844}]}]}
{"op":"mcm","clk":"4234880254","pt":1631550867837,"mc":[{"id":"1.187560677","rc":[{"batl":[[0,36,2],[1,55,2],[2,110,2]],"ltp":21.0,"tv":1864.83,"id":7588306},{"batb":[[0,1.03,1361.83],[1,1.02,1972.2],[2,1.01,3765.89]],"ltp":1.05,"tv":33810.32,"id":11439844}]}]}
{"op":"mcm","clk":"4234880452","pt":1631550869669,"mc":[{"id":"1.187560677","rc":[{"batl":[[0,19.5,54.82],[1,36,2],[2,55,2]],"ltp":21.0,"tv":1864.83,"id":7588306}]}]}
{"op":"mcm","clk":"4234880533","pt":1631550870256,"mc":[{"id":"1.187560677","rc":[{"batl":[[0,36,2],[1,55,2],[2,110,2]],"ltp":21.0,"tv":1864.83,"id":7588306}]}]}
{"op":"mcm","clk":"4234880990","pt":1631550874549,"mc":[{"id":"1.187560677","rc":[{"batl":[[0,26,2],[1,36,2],[2,55,2]],"ltp":21.0,"tv":1864.83,"id":7588306},{"batb":[[0,1.04,661.62],[1,1.03,1361.83],[2,1.02,1972.2]],"ltp":1.05,"tv":33810.32,"id":11439844}]}]}
{"op":"mcm","clk":"4234881243","pt":1631550877149,"mc":[{"id":"1.187560677","rc":[{"batl":[[0,36,2],[1,55,2],[2,110,2]],"ltp":21.0,"tv":1864.83,"id":7588306},{"batb":[[0,1.03,1361.83],[1,1.02,1972.2],[2,1.01,3765.89]],"ltp":1.05,"tv":33810.32,"id":11439844}]}]}
{"op":"mcm","clk":"4234881673","pt":1631550881615,"mc":[{"id":"1.187560677","rc":[{"batl":[[1,1.11,219.46],[2,1.12,195.96]],"ltp":1.05,"tv":33810.32,"id":11439844}]}]}
{"op":"mcm","clk":"4234881984","pt":1631550884587,"mc":[{"id":"1.187560677","rc":[{"batb":[[0,21,4],[1,17.5,2],[2,13.5,3]],"batl":[[0,26,54.58],[1,36,2],[2,55,2]],"ltp":21.0,"tv":1864.83,"id":7588306},{"batb":[[0,1.04,1221.85],[1,1.03,1361.83],[2,1.02,1972.2]],"batl":[[0,1.05,147.68],[1,1.06,2583.38],[2,1.08,98]],"ltp":1.05,"tv":33810.32,"id":11439844}]}]}
{"op":"mcm","clk":"4234882095","pt":1631550885578,"mc":[{"id":"1.187560677","rc":[{"batb":[[2,16,9.98]],"ltp":21.0,"tv":1864.83,"id":7588306}]}]}
{"op":"mcm","clk":"4234882286","pt":1631550887511,"mc":[{"id":"1.187560677","rc":[{"trd":[[1.04,2526.97]],"batb":[[0,1.04,1185.74]],"batl":[[1,1.06,2559.32]],"ltp":1.04,"tv":33882.52,"id":11439844}],"tv":35747.35}]}
{"op":"mcm","clk":"4234882322","pt":1631550887872,"mc":[{"id":"1.187560677","rc":[{"trd":[[1.04,2534.19]],"batb":[[0,1.04,1182.13]],"ltp":1.04,"tv":33889.74,"id":11439844}],"tv":35754.57}]}
{"op":"mcm","clk":"4234882832","pt":1631550893303,"mc":[{"id":"1.187560677","rc":[{"batb":[[1,1.03,1409.96]],"ltp":1.04,"tv":33889.74,"id":11439844}]}]}
{"op":"mcm","clk":"4234884274","pt":1631550907616,"mc":[{"id":"1.187560677","rc":[{"batl":[[0,26,5.71]],"ltp":21.0,"tv":1864.83,"id":7588306},{"batb":[[0,1.03,1409.96],[1,1.02,1972.2],[2,1.01,3765.89]],"batl":[[1,1.06,96]],"ltp":1.04,"tv":33889.74,"id":11439844}]}]}
{"op":"mcm","clk":"4234884344","pt":1631550908187,"mc":[{"id":"1.187560677","rc":[{"batb":[[0,13.5,3],[1,12,2],[2,10.5,15.35]],"batl":[[0,55,2],[1,110,2],[2,990,0.01]],"ltp":21.0,"tv":1864.83,"id":7588306},{"batb":[[0,1.03,48.13]],"batl":[[0,1.08,98],[1,1.09,279.5],[2,1.1,239.65]],"ltp":1.04,"tv":33889.74,"id":11439844}]}]}
{"op":"mcm","clk":"4234884617","pt":1631550911021,"mc":[{"id":"1.187560677","rc":[{"batb":[[1,12,5],[2,11,4]],"ltp":21.0,"tv":1864.83,"id":7588306},{"batl":[[1,1.09,388.5],[2,1.1,349.65]],"ltp":1.04,"tv":33889.74,"id":11439844}]}]}
{"op":"mcm","clk":"4234885452","pt":1631550919618,"mc":[{"id":"1.187560677","rc":[{"batb":[[0,12,3],[1,11,4],[2,10.5,15.35]],"ltp":21.0,"tv":1864.83,"id":7588306},{"batl":[[0,1.09,109],[1,1.1,349.65],[2,1.11,219.46]],"ltp":1.04,"tv":33889.74,"id":11439844}]}]}
{"op":"mcm","clk":"4234885751","pt":1631550922228,"mc":[{"id":"1.187560677","rc":[{"batl":[[2,1.11,322.46]],"ltp":1.04,"tv":33889.74,"id":11439844}]}]}
{"op":"mcm","clk":"4234885809","pt":1631550922816,"mc":[{"id":"1.187560677","rc":[{"batb":[[0,12,5]],"ltp":21.0,"tv":1864.83,"id":7588306},{"batl":[[0,1.09,385.5],[2,1.11,219.46]],"ltp":1.04,"tv":33889.74,"id":11439844}]}]}
{"op":"mcm","clk":"4234886102","pt":1631550925668,"mc":[{"id":"1.187560677","rc":[{"batl":[[0,17.5,193.13],[1,18,6],[2,19,2.1]],"ltp":21.0,"tv":1864.83,"id":7588306},{"batb":[[0,1.07,38.6],[1,1.06,533],[2,1.04,533]],"batl":[[0,1.08,39.37],[1,1.09,1981.18],[2,1.1,349.65]],"ltp":1.04,"tv":33889.74,"id":11439844}]}]}
{"op":"mcm","clk":"4234886207","pt":1631550926512,"mc":[{"id":"1.187560677","rc":[{"batb":[[2,1.04,1205.3]],"ltp":1.04,"tv":33889.74,"id":11439844}]}]}
{"op":"mcm","clk":"4234886331","pt":1631550927718,"mc":[{"id":"1.187560677","rc":[{"batb":[[2,1.04,1241.39]],"ltp":1.04,"tv":33889.74,"id":11439844}]}]}
{"op":"mcm","clk":"4234886500","pt":1631550929351,"mc":[{"id":"1.187560677","rc":[{"batb":[[0,12,3]],"ltp":21.0,"tv":1864.83,"id":7588306}]}]}
{"op":"mcm","clk":"4234886838","pt":1631550932348,"mc":[{"id":"1.187560677","rc":[{"batb":[[2,1.04,1887.26]],"ltp":1.04,"tv":33889.74,"id":11439844}]}]}
{"op":"mcm","clk":"4234887198","pt":1631550935618,"mc":[{"id":"1.187560677","rc":[{"batl":[[0,1.08,326.37]],"ltp":1.04,"tv":33889.74,"id":11439844}]}]}
{"op":"mcm","clk":"4234887877","pt":1631550941963,"mc":[{"id":"1.187560677","rc":[{"trd":[[1.08,297]],"batl":[[0,1.08,287.51]],"ltp":1.08,"tv":33967.46,"id":11439844}],"tv":35832.29}]}
{"op":"mcm","clk":"4234888462","pt":1631550947640,"mc":[{"id":"1.187560677","rc":[{"batl":[[0,18,6],[1,26,6],[2,55,2]],"ltp":21.0,"tv":1864.83,"id":7588306},{"batb":[[0,1.06,533],[1,1.04,1887.26],[2,1.03,1302.96]],"batl":[[0,1.08,287],[1,1.09,385.5]],"ltp":1.08,"tv":33967.46,"id":11439844}]}]}
{"op":"mcm","clk":"4234888548","pt":1631550948473,"mc":[{"id":"1.187560677","rc":[{"batb":[[0,8,7],[1,7.2,2],[2,7,18.12]],"batl":[[0,26,6],[1,55,2],[2,110,2]],"ltp":21.0,"tv":1864.83,"id":7588306},{"batb":[[0,1.04,1214.96],[1,1.03,1302.96],[2,1.02,3081.18]],"batl":[[0,1.07,1.35],[1,1.13,14.94],[2,1.14,281.75]],"ltp":1.08,"tv":33967.46,"id":11439844}]}]}
{"op":"mcm","clk":"4234888822","pt":1631550951269,"mc":[{"id":"1.187560677","rc":[{"batb":[[1,7.6,5],[2,7.2,24.69]],"ltp":21.0,"tv":1864.83,"id":7588306}]}]}
{"op":"mcm","clk":"4234888960","pt":1631550952478,"mc":[{"id":"1.187560677","rc":[{"trd":[[15,1.57]],"batb":[[0,8,5]],"ltp":15.0,"tv":1864.93,"id":7588306},{"trd":[[1.07,233.41]],"batl":[[0,1.1,19.15],[2,1.14,96]],"ltp":1.07,"tv":33968.81,"id":11439844}],"tv":35833.74}]}
{"op":"mcm","clk":"4234889071","pt":1631550953369,"mc":[{"id":"1.187560677","rc":[{"batb":[[0,1.08,287.46],[1,1.04,1214.96],[2,1.03,1302.96]],"batl":[[0,1.13,14.94],[1,1.14,96],[2,1.15,110.94]],"ltp":1.07,"tv":33968.81,"id":11439844}]}]}
{"op":"mcm","clk":"4234889320","pt":1631550955582,"mc":[{"id":"1.187560677","rc":[{"batb":[[0,8,7]],"ltp":15.0,"tv":1864.93,"id":7588306},{"batl":[[1,1.14,285.25],[2,1.15,274.44]],"ltp":1.07,"tv":33968.81,"id":11439844}]}]}
{"op":"mcm","clk":"4234889351","pt":1631550955848,"mc":[{"id":"1.187560677","rc":[{"batb":[[0,8,5]],"ltp":15.0,"tv":1864.93,"id":7588306},{"batl":[[1,1.14,96],[2,1.15,110.94]],"ltp":1.07,"tv":33968.81,"id":11439844}]}]}
{"op":"mcm","clk":"4234890395","pt":1631550966689,"mc":[{"id":"1.187560677","rc":[{"batb":[[0,8,7]],"ltp":15.0,"tv":1864.93,"id":7588306},{"batl":[[1,1.14,285.25],[2,1.15,277.04]],"ltp":1.07,"tv":33968.81,"id":11439844}]}]}
{"op":"mcm","clk":"4234890425","pt":1631550966962,"mc":[{"id":"1.187560677","rc":[{"batb":[[0,8,5]],"ltp":15.0,"tv":1864.93,"id":7588306},{"batl":[[1,1.14,96],[2,1.15,110.94]],"ltp":1.07,"tv":33968.81,"id":11439844}]}]}
{"op":"mcm","clk":"4234890829","pt":1631550970992,"mc":[{"id":"1.187560677","rc":[{"batb":[[0,7.2,18.69],[1,1.3,5],[2,1.01,105.79]],"ltp":15.0,"tv":1864.93,"id":7588306},{"batb":[[2,1.03,919.96]],"batl":[[1,1.15,14.94],[2,1.16,136.47]],"ltp":1.07,"tv":33968.81,"id":11439844}]}]}
{"op":"mcm","clk":"4234891093","pt":1631550973679,"mc":[{"id":"1.187560677","rc":[{"batb":[[0,17.5,2],[1,7.2,18.69],[2,1.3,5]],"batl":[[0,26,89.46]],"ltp":15.0,"tv":1864.93,"id":7588306},{"trd":[[1.08,871.96]],"batb":[[0,1.04,3301.44],[1,1.03,919.96],[2,1.02,3081.18]],"batl":[[0,1.06,1375.36],[1,1.07,186.92],[2,1.09,5165.89]],"ltp":1.08,"tv":34543.77,"id":11439844}],"tv":36408.7}]}
{"op":"mcm","clk":"4234891205","pt":1631550974576,"mc":[{"id":"1.187560677","rc":[{"batb":[[0,17.5,4],[1,15,15.08],[2,9.2,23.07]],"ltp":15.0,"tv":1864.93,"id":7588306},{"batl":[[0,1.06,231.36],[1,1.07,137.38]],"ltp":1.08,"tv":34543.77,"id":11439844}]}]}
{"op":"mcm","clk":"4234891720","pt":1631550979617,"mc":[{"id":"1.187560677","rc":[{"batl":[[0,1.06,453.36],[2,1.08,18.04]],"ltp":1.08,"tv":34543.77,"id":11439844}]}]}
{"op":"mcm","clk":"4234891769","pt":1631550980095,"mc":[{"id":"1.187560677","rc":[{"batb":[[2,10,2]],"ltp":15.0,"tv":1864.93,"id":7588306}]}]}
{"op":"mcm","clk":"4234892599","pt":1631550988601,"mc":[{"id":"1.187560677","rc":[{"trd":[[17.5,23.5]],"batb":[[0,15,15.08],[1,10,2],[2,9.2,23.07]],"ltp":17.5,"tv":1873.93,"id":7588306},{"trd":[[1.06,280.86]],"batl":[[0,1.06,436.85]],"ltp":1.06,"tv":34560.28,"id":11439844}],"tv":36434.21}]}
{"op":"mcm","clk":"4234893031","pt":1631550992700,"mc":[{"id":"1.187560677","rc":[{"batl":[[0,26,4]],"ltp":17.5,"tv":1873.93,"id":7588306},{"batb":[[0,1.04,569.09],[1,1.03,48.13]],"batl":[[0,1.06,328],[1,1.07,100]],"ltp":1.06,"tv":34560.28,"id":11439844}]}]}
{"op":"mcm","clk":"4234893114","pt":1631550993519,"mc":[{"id":"1.187560677","rc":[{"batb":[[0,10,2],[1,9.2,23.07],[2,8.6,2]],"batl":[[0,55,2],[1,110,2],[2,990,0.01]],"ltp":17.5,"tv":1873.93,"id":7588306},{"batb":[[0,1.04,36.09],[2,1.02,1972.2]],"batl":[[0,1.08,18.04],[1,1.11,208.5],[2,1.12,308.21]],"ltp":1.06,"tv":34560.28,"id":11439844}]}]}
{"op":"mcm","clk":"4234893187","pt":1631550994409,"mc":[{"id":"1.187560677","rc":[{"batb":[[0,9.2,23.07],[1,8.6,2],[2,7.2,2]],"ltp":17.5,"tv":1873.93,"id":7588306},{"batb":[[0,1.06,453.02],[1,1.04,36.09],[2,1.03,48.13]],"batl":[[1,1.12,102],[2,1.13,194.44]],"ltp":1.06,"tv":34560.28,"id":11439844}]}]}
{"op":"mcm","clk":"4234893362","pt":1631550996131,"mc":[{"id":"1.187560677","rc":[{"batb":[[2,8,5]],"ltp":17.5,"tv":1873.93,"id":7588306},{"batl":[[2,1.13,294.44]],"ltp":1.06,"tv":34560.28,"id":11439844}]}]}
{"op":"mcm","clk":"4234893514","pt":1631550997699,"mc":[{"id":"1.187560677","rc":[{"batl":[[0,22,51.7],[1,55,2],[2,110,2]],"ltp":17.5,"tv":1873.93,"id":7588306},{"batb":[[0,1.04,36.09],[1,1.03,48.13],[2,1.02,1972.2]],"ltp":1.06,"tv":34560.28,"id":11439844}]}]}
{"op":"mcm","clk":"4234893576","pt":1631550998420,"mc":[{"id":"1.187560677","rc":[{"batl":[[0,55,2],[1,110,2],[2,990,0.01]],"ltp":17.5,"tv":1873.93,"id":7588306}]}]}
{"op":"mcm","clk":"4234893795","pt":1631551000619,"mc":[{"id":"1.187560677","rc":[{"batb":[[0,10,2],[1,9.2,23.07],[2,8.6,2]],"ltp":17.5,"tv":1873.93,"id":7588306},{"batl":[[1,1.11,248.5],[2,1.12,322.21]],"ltp":1.06,"tv":34560.28,"id":11439844}]}]}
{"op":"mcm","clk":"4234893858","pt":1631551001207,"mc":[{"id":"1.187560677","rc":[{"batb":[[0,9.2,23.07],[1,8.6,2],[2,8,5]],"ltp":17.5,"tv":1873.93,"id":7588306},{"trd":[[1.08,908.04]],"batb":[[0,1.08,1.96],[1,1.04,36.09],[2,1.03,48.13]],"batl":[[0,1.12,102],[1,1.13,294.44],[2,1.14,94]],"ltp":1.08,"tv":34596.36,"id":11439844}],"tv":36470.29}]}
{"op":"mcm","clk":"4234893978","pt":1631551002416,"mc":[{"id":"1.187560677","rc":[{"trd":[[1.08,911.96]],"batb":[[0,1.05,40]],"batl":[[0,1.08,55.04],[1,1.12,102],[2,1.13,294.44]],"ltp":1.08,"tv":34600.28,"id":11439844}],"tv":36474.21}]}
{"op":"mcm","clk":"4234894088","pt":1631551003514,"mc":[{"id":"1.187560677","rc":[{"batb":[[2,1.03,88.13]],"batl":[[0,1.12,102],[1,1.13,294.44],[2,1.14,94]],"ltp":1.08,"tv":34600.28,"id":11439844}]}]}
{"op":"mcm","clk":"4234894262","pt":1631551005337,"mc":[{"id":"1.187560677","rc":[{"batl":[[1,990,0.01],[2,990,0]],"ltp":17.5,"tv":1873.93,"id":7588306}]}]}
{"op":"mcm","clk":"4234894529","pt":1631551007707,"mc":[{"id":"1.187560677","rc":[{"batb":[[0,10,2],[1,9.2,23.07],[2,8.6,2]],"ltp":17.5,"tv":1873.93,"id":7588306},{"batb":[[0,1.05,20]],"batl":[[0,1.11,235.5],[1,1.12,307.21],[2,1.13,294.44]],"ltp":1.08,"tv":34600.28,"id":11439844}]}]}
{"op":"mcm","clk":"4234894565","pt":1631551008125,"mc":[{"id":"1.187560677","rc":[{"batb":[[0,9.2,23.07],[1,8.6,2],[2,8,5]],"ltp":17.5,"tv":1873.93,"id":7588306},{"batl":[[0,1.12,102],[1,1.13,294.44],[2,1.14,94]],"ltp":1.08,"tv":34600.28,"id":11439844}]}]}
{"op":"mcm","clk":"4234894684","pt":1631551009527,"mc":[{"id":"1.187560677","rc":[{"batb":[[0,1.08,17.57],[1,1.05,20],[2,1.04,36.09]],"ltp":1.08,"tv":34600.28,"id":11439844}]}]}
{"op":"mcm","clk":"4234894730","pt":1631551009844,"mc":[{"id":"1.187560677","rc":[{"batl":[[0,990,0.01],[1,990,0]],"ltp":17.5,"tv":1873.93,"id":7588306}]}]}
{"op":"mcm","clk":"4234895072","pt":1631551013028,"mc":[{"id":"1.187560677","rc":[{"batl":[[0,55,2],[1,990,0.01]],"ltp":17.5,"tv":1873.93,"id":7588306}]}]}
{"op":"mcm","clk":"4234895249","pt":1631551014709,"mc":[{"id":"1.187560677","rc":[{"batb":[[0,10,2],[1,9.2,23.07],[2,8.6,2]],"ltp":17.5,"tv":1873.93,"id":7588306},{"batb":[[0,1.05,20],[1,1.04,36.09],[2,1.03,88.13]],"ltp":1.08,"tv":34600.28,"id":11439844}]}]}
{"op":"mcm","clk":"4234895356","pt":1631551015648,"mc":[{"id":"1.187560677","rc":[{"batb":[[0,9.2,23.07],[1,8.6,2],[2,7.2,2]],"ltp":17.5,"tv":1873.93,"id":7588306},{"batb":[[0,1.04,36.09],[1,1.03,88.13],[2,1.02,1972.2]],"batl":[[0,1.11,242.5],[1,1.12,201.96],[2,1.13,194.44]],"ltp":1.08,"tv":34600.28,"id":11439844}]}]}
{"op":"mcm","clk":"4234895427","pt":1631551016134,"mc":[{"id":"1.187560677","rc":[{"batb":[[2,1.3,5]],"ltp":17.5,"tv":1873.93,"id":7588306},{"batb":[[0,1.03,88.13],[1,1.02,1972.2],[2,1.01,3765.89]],"batl":[[0,1.13,194.44],[1,1.15,14.94],[2,1.17,29.89]],"ltp":1.08,"tv":34600.28,"id":11439844}]}]}
{"op":"mcm","clk":"4234895687","pt":1631551018631,"mc":[{"id":"1.187560677","rc":[{"batb":[[0,26,3.46],[1,21,9.57],[2,19.5,2.06]],"batl":[[0,50,153.18],[1,55,2],[2,990,0.01]],"ltp":17.5,"tv":1873.93,"id":7588306},{"batl":[[0,1.04,191.57],[1,1.05,91],[2,1.06,5165.89]],"ltp":1.08,"tv":34600.28,"id":11439844}]}]}
{"op":"mcm","clk":"4234896307","pt":1631551024564,"mc":[{"id":"1.187560677","rc":[{"batb":[[0,1.03,68.13]],"ltp":1.08,"tv":34600.28,"id":11439844}]}]}
{"op":"mcm","clk":"4234896402","pt":1631551025563,"mc":[{"id":"1.187560677","rc":[{"batl":[[2,110,2]],"ltp":17.5,"tv":1873.93,"id":7588306},{"batl":[[2,1.06,5575.14]],"ltp":1.08,"tv":34600.28,"id":11439844}]}]}
{"op":"mcm","clk":"4234896460","pt":1631551026053,"mc":[{"id":"1.187560677","rc":[{"batb":[[0,1.03,48.13]],"ltp":1.08,"tv":34600.28,"id":11439844}]}]}
{"op":"mcm","clk":"4234896650","pt":1631551027936,"mc":[{"id":"1.187560677","rc":[{"trd":[[1.04,2574.19]],"batl":[[0,1.04,171.57]],"ltp":1.04,"tv":34640.28,"id":11439844}],"tv":36514.21}]}
{"op":"mcm","clk":"4234897674","pt":1631551038343,"mc":[{"id":"1.187560677","rc":[{"batb":[[0,21,9.57],[1,19.5,2.06],[2,17.5,2]],"ltp":17.5,"tv":1873.93,"id":7588306},{"trd":[[1.04,2610.27]],"batl":[[0,1.04,86.96]],"ltp":1.04,"tv":34676.36,"id":11439844}],"tv":36550.29}]}
{"op":"mcm","clk":"4234897933","pt":1631551041062,"mc":[{"id":"1.187560677","rc":[{"batl":[[0,1.04,163.53]],"ltp":1.04,"tv":34676.36,"id":11439844}]}]}
{"op":"mcm","clk":"4234898118","pt":1631551042655,"mc":[{"id":"1.187560677","rc":[{"batb":[[0,21,7.57],[1,17.5,2],[2,15,5]],"batl":[[0,110,2],[1,990,0.01],[2,110,0]],"ltp":17.5,"tv":1873.93,"id":7588306},{"batb":[[1,1.02,61.08]],"batl":[[0,1.06,409.25],[1,1.07,429.5],[2,1.08,293.19]],"ltp":1.04,"tv":34676.36,"id":11439844}]}]}
{"op":"mcm","clk":"4234898185","pt":1631551043335,"mc":[{"id":"1.187560677","rc":[{"batb":[[0,15,5],[1,14.5,6.96],[2,8.6,2]],"ltp":17.5,"tv":1873.93,"id":7588306},{"batb":[[0,1.04,257.65],[1,1.03,48.13],[2,1.02,61.08]],"batl":[[0,1.07,429.5],[1,1.13,194.44],[2,1.15,14.94]],"ltp":1.04,"tv":34676.36,"id":11439844}]}]}
{"op":"mcm","clk":"4234898423","pt":1631551045572,"mc":[{"id":"1.187560677","rc":[{"batb":[[2,13.5,3]],"ltp":17.5,"tv":1873.93,"id":7588306},{"batl":[[1,1.08,108],[2,1.09,104]],"ltp":1.04,"tv":34676.36,"id":11439844}]}]}
{"op":"mcm","clk":"4234898518","pt":1631551046460,"mc":[{"id":"1.187560677","rc":[{"batb":[[0,1.03,48.13],[1,1.02,61.08],[2,1.01,3765.89]],"batl":[[1,1.08,447.94]],"ltp":1.04,"tv":34676.36,"id":11439844}]}]}
{"op":"mcm","clk":"4234898625","pt":1631551047654,"mc":[{"id":"1.187560677","rc":[{"trd":[[1.03,938.2]],"batb":[[0,1.03,28.14]],"batl":[[0,1.04,20],[1,1.05,20],[2,1.07,97]],"ltp":1.03,"tv":34716.35,"id":11439844}],"tv":36590.28}]}
{"op":"mcm","clk":"4234898732","pt":1631551048641,"mc":[{"id":"1.187560677","rc":[{"batb":[[0,15,2],[2,1.3,5]],"ltp":17.5,"tv":1873.93,"id":7588306},{"batl":[[0,1.06,20],[1,1.13,14.94],[2,1.15,14.94]],"ltp":1.03,"tv":34716.35,"id":11439844}]}]}
{"op":"mcm","clk":"4234898822","pt":1631551049683,"mc":[{"id":"1.187560677","rc":[{"batb":[[0,17.5,2],[1,15,2],[2,14.5,6.96]],"ltp":17.5,"tv":1873.93,"id":7588306},{"batb":[[0,1.02,61.08],[1,1.01,3765.89],[2,1.01,0]],"batl":[[0,1.06,448.75]],"ltp":1.03,"tv":34716.35,"id":11439844}]}]}
{"op":"mcm","clk":"4234898911","pt":1631551050677,"mc":[{"id":"1.187560677","rc":[{"batb":[[0,28,7.14],[1,26,103.32],[2,17.5,2]],"batl":[[0,100,151.65],[1,110,2],[2,990,0.01]],"ltp":17.5,"tv":1873.93,"id":7588306},{"batl":[[0,1.03,276.87],[1,1.04,2582.94],[2,1.06,448.75]],"ltp":1.03,"tv":34716.35,"id":11439844}]}]}
{"op":"mcm","clk":"4234899009","pt":1631551051683,"mc":[{"id":"1.187560677","rc":[{"batb":[[0,34,2],[1,28,1.42],[2,27,5.45]],"ltp":17.5,"tv":1873.93,"id":7588306},{"batl":[[0,1.03,372.87],[1,1.04,2692.94],[2,1.05,105]],"ltp":1.03,"tv":34716.35,"id":11439844}]}]}
{"op":"mcm","clk":"4234899252","pt":1631551053972,"mc":[{"id":"1.187560677","rc":[{"batl":[[0,1.03,412.87]],"ltp":1.03,"tv":34716.35,"id":11439844}]}]}
{"op":"mcm","clk":"4234899571","pt":1631551057401,"mc":[{"id":"1.187560677","rc":[{"batl":[[0,1.03,461],[1,1.04,3300.32],[2,1.05,609.5]],"ltp":1.03,"tv":34716.35,"id":11439844}]}]}
{"op":"mcm","clk":"4234899850","pt":1631551059339,"mc":[{"id":"1.187560677","rc":[{"batl":[[0,1.03,640.79]],"ltp":1.03,"tv":34716.35,"id":11439844}]}]}
{"op":"mcm","clk":"4234899940","pt":1631551060386,"mc":[{"id":"1.187560677","rc":[{"batb":[[0,34,4]],"ltp":17.5,"tv":1873.93,"id":7588306},{"trd":[[1.02,142.19]],"batb":[[0,1.02,21.11]],"batl":[[0,1.03,1466.29]],"ltp":1.02,"tv":34836.32,"id":11439844}],"tv":36710.25}]}
{"op":"mcm","clk":"4234900543","pt":1631551065671,"mc":[{"id":"1.187560677","rc":[{"batl":[[0,1.03,1469.17]],"ltp":1.02,"tv":34836.32,"id":11439844}]}]}
{"op":"mcm","clk":"4234900756","pt":1631551067864,"mc":[{"id":"1.187560677","rc":[{"trd":[[1.03,952.92]],"batl":[[0,1.03,1461.81]],"ltp":1.03,"tv":34851.03,"id":11439844}],"tv":36724.97}]}
{"op":"mcm","clk":"4234901697","pt":1631551078099,"mc":[{"id":"1.187560677","rc":[{"batl":[[0,100,142.39]],"ltp":17.5,"tv":1873.93,"id":7588306},{"batl":[[0,1.03,1192.3]],"ltp":1.03,"tv":34851.03,"id":11439844}]}]}
{"op":"mcm","clk":"4234901778","pt":1631551079081,"mc":[{"id":"1.187560677","rc":[{"trd":[[1.03,2727.44]],"batl":[[0,1.03,305.02]],"ltp":1.03,"tv":36625.55,"id":11439844}],"tv":38499.48}]}
{"op":"mcm","clk":"4234901968","pt":1631551081006,"mc":[{"id":"1.187560677","rc":[{"batl":[[0,100,151.73]],"ltp":17.5,"tv":1873.93,"id":7588306},{"batl":[[0,1.03,574.53]],"ltp":1.03,"tv":36625.55,"id":11439844}]}]}
{"op":"mcm","clk":"4234902107","pt":1631551082214,"mc":[{"id":"1.187560677","rc":[{"trd":[[34,0.9]],"batb":[[0,34,3.55]],"ltp":34.0,"tv":1874.83,"id":7588306}],"tv":38500.38}]}
{"op":"mcm","clk":"4234903089","pt":1631551092604,"mc":[{"id":"1.187560677","rc":[{"batb":[[0,34,1.55],[1,27,5.45],[2,26,2]],"batl":[[0,990,0.01],[1,110,0],[2,990,0]],"ltp":34.0,"tv":1874.83,"id":7588306},{"batb":[[1,1.01,250.18]],"batl":[[0,1.03,2.89],[1,1.04,110],[2,1.05,105]],"ltp":1.03,"tv":36625.55,"id":11439844}]}]}
{"op":"mcm","clk":"4234903118","pt":1631551092816,"mc":[{"id":"1.187560677","rc":[{"batb":[[1,26,2],[2,25,3.46]],"ltp":34.0,"tv":1874.83,"id":7588306}]}]}
{"op":"mcm","clk":"4234903379","pt":1631551095713,"mc":[{"id":"1.187560677","rc":[{"batb":[[0,26,2],[1,25,3.46],[2,1.3,5]],"ltp":34.0,"tv":1874.83,"id":7588306},{"batl":[[0,1.03,101.89]],"ltp":1.03,"tv":36625.55,"id":11439844}]}]}
{"op":"mcm","clk":"4234903650","pt":1631551098595,"mc":[{"id":"1.187560677","rc":[{"batb":[[2,17.5,2]],"ltp":34.0,"tv":1874.83,"id":7588306}]}]}
{"op":"mcm","clk":"4234903921","pt":1631551100529,"mc":[{"id":"1.187560677","rc":[{"batb":[[0,1.02,22.82]],"ltp":1.03,"tv":36625.55,"id":11439844}]}]}
{"op":"mcm","clk":"4234904169","pt":1631551102993,"mc":[{"id":"1.187560677","rc":[{"batl":[[0,1.03,2.89]],"ltp":1.03,"tv":36625.55,"id":11439844}]}]}
{"op":"mcm","clk":"4234904454","pt":1631551106328,"mc":[{"id":"1.187560677","rc":[{"batb":[[1,1.01,290.18]],"ltp":1.03,"tv":36625.55,"id":11439844}]}]}
{"op":"mcm","clk":"4234904797","pt":1631551110240,"mc":[{"id":"1.187560677","rc":[{"batb":[[2,1.3,5]],"ltp":34.0,"tv":1874.83,"id":7588306}]}]}
{"op":"mcm","clk":"4234904912","pt":1631551111556,"mc":[{"id":"1.187560677","rc":[{"batb":[[0,1.02,2.82]],"ltp":1.03,"tv":36625.55,"id":11439844}]}]}
{"op":"mcm","clk":"4234905115","pt":1631551113609,"mc":[{"id":"1.187560677","rc":[{"batb":[[0,34,2],[1,26,2],[2,25,3.46]],"batl":[[0,50,4.28],[1,100,226.04],[2,990,0.01]],"ltp":34.0,"tv":1874.83,"id":7588306},{"batb":[[1,1.01,949.18]],"batl":[[0,1.03,2770.12]],"ltp":1.03,"tv":36625.55,"id":11439844}]}]}
{"op":"mcm","clk":"4234905283","pt":1631551115442,"mc":[{"id":"1.187560677","rc":[{"trd":[[1.03,2745.35]],"batb":[[0,1.02,22.82]],"batl":[[0,1.03,2761.16]],"ltp":1.03,"tv":36643.46,"id":11439844}],"tv":38518.29}]}
{"op":"mcm","clk":"4234905677","pt":1631551119523,"mc":[{"id":"1.187560677","rc":[{"batb":[[0,1.02,95.01]],"ltp":1.03,"tv":36643.46,"id":11439844}]}]}
{"op":"mcm","clk":"4234905700","pt":1631551119726,"mc":[{"id":"1.187560677","rc":[{"batl":[[2,110,2]],"ltp":34.0,"tv":1874.83,"id":7588306},{"batb":[[1,1.01,3271.96]],"ltp":1.03,"tv":36643.46,"id":11439844}]}]}
{"op":"mcm","clk":"4234906672","pt":1631551129453,"mc":[{"id":"1.187560677","rc":[{"batb":[[0,26,2],[1,25,3.46],[2,24,4.03]],"batl":[[0,110,2],[1,990,0.01],[2,110,0]],"ltp":34.0,"tv":1874.83,"id":7588306},{"batl":[[0,1.04,110],[1,1.05,105],[2,1.09,11.96]],"ltp":1.03,"tv":36643.46,"id":11439844}]}]}
{"op":"mcm","clk":"4234906734","pt":1631551129871,"mc":[{"id":"1.187560677","rc":[{"batb":[[1,24,4.03],[2,1.3,5]],"ltp":34.0,"tv":1874.83,"id":7588306}]}]}
{"op":"mcm","clk":"4234907004","pt":1631551132456,"mc":[{"id":"1.187560677","rc":[{"batb":[[2,17.5,2]],"ltp":34.0,"tv":1874.83,"id":7588306},{"batl":[[2,1.06,98]],"ltp":1.03,"tv":36643.46,"id":11439844}]}]}
{"op":"mcm","clk":"4234907138","pt":1631551133653,"mc":[{"id":"1.187560677","rc":[{"batb":[[2,1.3,5]],"ltp":34.0,"tv":1874.83,"id":7588306},{"batl":[[2,1.09,11.96]],"ltp":1.03,"tv":36643.46,"id":11439844}]}]}
{"op":"mcm","clk":"4234907352","pt":1631551135641,"mc":[{"id":"1.187560677","rc":[{"batb":[[0,27,7.4],[1,26,2],[2,24,4.03]],"batl":[[0,100,145.6],[1,110,2],[2,990,0.01]],"ltp":34.0,"tv":1874.83,"id":7588306},{"batb":[[0,1.02,21.71]],"batl":[[0,1.03,9202.83],[1,1.04,110],[2,1.05,105]],"ltp":1.03,"tv":36643.46,"id":11439844}]}]}
{"op":"mcm","clk":"4234907468","pt":1631551136572,"mc":[{"id":"1.187560677","rc":[{"batb":[[0,34,2],[1,27,6.33],[2,26,2]],"ltp":34.0,"tv":1874.83,"id":7588306},{"batl":[[0,1.03,5547.83]],"ltp":1.03,"tv":36643.46,"id":11439844}]}]}
{"op":"mcm","clk":"4234909728","pt":1631551158222,"mc":[{"id":"1.187560677","rc":[{"trd":[[1.02,158.96]],"batb":[[0,1.02,13.32]],"ltp":1.02,"tv":36660.23,"id":11439844}],"tv":38535.07}]}
{"op":"mcm","clk":"4234910330","pt":1631551163206,"mc":[{"id":"1.187560677","rc":[{"trd":[[1.02,185.59]],"batb":[[0,1.01,3271.96],[1,1.01,0]],"batl":[[0,1.02,71.96],[1,1.03,5547.83],[2,1.04,110]],"ltp":1.02,"tv":36686.86,"id":11439844}],"tv":38561.7}]}
{"op":"mcm","clk":"4234911305","pt":1631551170522,"mc":[{"id":"1.187560677","rc":[{"batb":[[1,27,4.85]],"batl":[[0,110,2],[1,990,0.01],[2,990,0]],"ltp":34.0,"tv":1874.83,"id":7588306},{"batl":[[1,1.03,95]],"ltp":1.02,"tv":36686.86,"id":11439844}]}]}
{"op":"mcm","clk":"4234911379","pt":1631551171007,"mc":[{"id":"1.187560677","rc":[{"batb":[[1,26,2],[2,25,7.62]],"ltp":34.0,"tv":1874.83,"id":7588306},{"batb":[[0,1.01,2612.96]],"ltp":1.02,"tv":36686.86,"id":11439844}]}]}
{"op":"mcm","clk":"4234912022","pt":1631551176397,"mc":[{"id":"1.187560677","rc":[{"batl":[[1,1.03,102.94]],"ltp":1.02,"tv":36686.86,"id":11439844}]}]}
{"op":"mcm","clk":"4234912316","pt":1631551179618,"mc":[{"id":"1.187560677","rc":[{"batl":[[1,1.03,123.44]],"ltp":1.02,"tv":36686.86,"id":11439844}]}]}
{"op":"mcm","clk":"4234912343","pt":1631551179927,"mc":[{"id":"1.187560677","rc":[{"batl":[[1,1.03,102.94]],"ltp":1.02,"tv":36686.86,"id":11439844}]}]}
{"op":"mcm","clk":"4234912516","pt":1631551181493,"mc":[{"id":"1.187560677","rc":[{"trd":[[1.02,205.58]],"batl":[[0,1.02,61.96]],"ltp":1.02,"tv":36706.86,"id":11439844}],"tv":38581.69}]}
{"op":"mcm","clk":"4234912803","pt":1631551184320,"mc":[{"id":"1.187560677","rc":[{"trd":[[1.02,218.92]],"batl":[[0,1.02,55.3]],"ltp":1.02,"tv":36720.2,"id":11439844}],"tv":38595.03}]}
{"op":"mcm","clk":"4234913122","pt":1631551187137,"mc":[{"id":"1.187560677","rc":[{"batb":[[0,1.01,2572.96]],"ltp":1.02,"tv":36720.2,"id":11439844}]}]}
{"op":"mcm","clk":"4234913271","pt":1631551188707,"mc":[{"id":"1.187560677","rc":[{"batb":[[1,32,1.24],[2,26,2]],"ltp":34.0,"tv":1874.83,"id":7588306},{"batb":[[0,1.01,4985.12]],"batl":[[0,1.02,5515.26]],"ltp":1.02,"tv":36720.2,"id":11439844}]}]}
{"op":"mcm","clk":"4234913358","pt":1631551189543,"mc":[{"id":"1.187560677","rc":[{"batb":[[2,28,4.03]],"ltp":34.0,"tv":1874.83,"id":7588306}]}]}
{"op":"mcm","clk":"4234913518","pt":1631551191100,"mc":[{"id":"1.187560677","rc":[{"batl":[[0,1.02,5587.44]],"ltp":1.02,"tv":36720.2,"id":11439844}]}]}
{"op":"mcm","clk":"4234914089","pt":1631551196736,"mc":[{"id":"1.187560677","rc":[{"batb":[[0,1.01,5005.12]],"ltp":1.02,"tv":36720.2,"id":11439844}]}]}
{"op":"mcm","clk":"4234915017","pt":1631551205422,"mc":[{"id":"1.187560677","rc":[{"batb":[[1,28,4.03],[2,1.3,5]],"ltp":34.0,"tv":1874.83,"id":7588306},{"batb":[[0,1.01,2592.96]],"batl":[[0,1.02,127.48]],"ltp":1.02,"tv":36720.2,"id":11439844}]}]}
{"op":"mcm","clk":"4234915354","pt":1631551208559,"mc":[{"id":"1.187560677","rc":[{"batb":[[0,50,2],[1,34,2],[2,28,4.03]],"ltp":34.0,"tv":1874.83,"id":7588306},{"batl":[[0,1.02,149.3]],"ltp":1.02,"tv":36720.2,"id":11439844}]}]}
{"op":"mcm","clk":"4234915467","pt":1631551209553,"mc":[{"id":"1.187560677","rc":[{"trd":[[50,0.9]],"batb":[[0,50,1.55]],"ltp":50.0,"tv":1875.73,"id":7588306}],"tv":38595.93}]}
{"op":"mcm","clk":"4234915557","pt":1631551210436,"mc":[{"id":"1.187560677","rc":[{"batl":[[0,1.02,170.55]],"ltp":1.02,"tv":36720.2,"id":11439844}]}]}
{"op":"mcm","clk":"4234915593","pt":1631551210758,"mc":[{"id":"1.187560677","rc":[{"batl":[[0,1.02,149.3]],"ltp":1.02,"tv":36720.2,"id":11439844}]}]}
{"op":"mcm","clk":"4234915726","pt":1631551212057,"mc":[{"id":"1.187560677","rc":[{"trd":[[1.02,219.3]],"batl":[[0,1.02,149.11]],"ltp":1.02,"tv":36720.57,"id":11439844}],"tv":38596.3}]}
{"op":"mcm","clk":"4234916802","pt":1631551222167,"mc":[{"id":"1.187560677","rc":[{"batb":[[0,34,2],[1,28,4.03],[2,1.3,5]],"ltp":50.0,"tv":1875.73,"id":7588306},{"trd":[[1.02,219.48]],"batl":[[0,1.02,55.01]],"ltp":1.02,"tv":36720.75,"id":11439844}],"tv":38596.49}]}
{"op":"mcm","clk":"4234917422","pt":1631551227663,"mc":[{"id":"1.187560677","rc":[{"batl":[[0,100,130.55],[1,110,2],[2,990,0.01]],"ltp":50.0,"tv":1875.73,"id":7588306},{"batl":[[1,1.03,5262.76]],"ltp":1.02,"tv":36720.75,"id":11439844}]}]}
{"op":"mcm","clk":"4234917536","pt":1631551228450,"mc":[{"id":"1.187560677","rc":[{"batb":[[2,25,3.2]],"ltp":50.0,"tv":1875.73,"id":7588306},{"batb":[[0,1.01,3264.96]],"ltp":1.02,"tv":36720.75,"id":11439844}]}]}
{"op":"mcm","clk":"4234917824","pt":1631551231385,"mc":[{"id":"1.187560677","rc":[{"trd":[[1.02,239.48]],"batl":[[0,1.02,45.02]],"ltp":1.02,"tv":36740.75,"id":11439844}],"tv":38616.48}]}
{"op":"mcm","clk":"4234918038","pt":1631551233361,"mc":[{"id":"1.187560677","rc":[{"trd":[[1.02,248.5]],"batl":[[0,1.02,40.51]],"ltp":1.02,"tv":36749.77,"id":11439844}],"tv":38625.5}]}
{"op":"mcm","clk":"4234920123","pt":1631551254579,"mc":[{"id":"1.187560677","rc":[{"batb":[[1,25,3.2],[2,1.3,5]],"batl":[[0,110,2],[1,990,0.01],[2,990,0]],"ltp":50.0,"tv":1875.73,"id":7588306},{"batb":[[0,1.01,2592.96]],"batl":[[1,1.03,102.94]],"ltp":1.02,"tv":36749.77,"id":11439844}]}]}
{"op":"mcm","clk":"4234920557","pt":1631551258429,"mc":[{"id":"1.187560677","rc":[{"trd":[[1.02,258.49]],"batl":[[0,1.02,35.51]],"ltp":1.02,"tv":36759.77,"id":11439844}],"tv":38635.5}]}
{"op":"mcm","clk":"4234921557","pt":1631551267540,"mc":[{"id":"1.187560677","rc":[{"trd":[[50,1.62]],"batl":[[0,50,58.47],[1,55,2.01],[2,110,2]],"ltp":50.0,"tv":1876.45,"id":7588306},{"trd":[[1.02,294.01]],"batb":[[0,1.02,270.74],[1,1.01,3304.56]],"batl":[[0,1.03,2003.75],[1,1.04,110],[2,1.05,109]],"ltp":1.02,"tv":36795.28,"id":11439844}],"tv":38671.73}]}
{"op":"mcm","clk":"4234921623","pt":1631551268163,"mc":[{"id":"1.187560677","rc":[{"batb":[[2,24,4.16]],"ltp":50.0,"tv":1876.45,"id":7588306}]}]}
{"op":"mcm","clk":"4234921784","pt":1631551269679,"mc":[{"id":"1.187560677","rc":[{"batb":[[0,1.02,275.74]],"ltp":1.02,"tv":36795.28,"id":11439844}]}]}
{"op":"mcm","clk":"4234922546","pt":1631551277589,"mc":[{"id":"1.187560677","rc":[{"batl":[[0,1.03,2039.6]],"ltp":1.02,"tv":36795.28,"id":11439844}]}]}
{"op":"mcm","clk":"4234924008","pt":1631551292579,"mc":[{"id":"1.187560677","rc":[{"batb":[[1,24,4.16],[2,1.3,5]],"batl":[[0,110,2],[1,990,0.01],[2,110,0]],"ltp":50.0,"tv":1876.45,"id":7588306},{"batb":[[0,1.02,5],[1,1.01,2592.96]],"batl":[[0,1.03,138.79]],"ltp":1.02,"tv":36795.28,"id":11439844}]}]}
{"op":"mcm","clk":"4234924508","pt":1631551297660,"mc":[{"id":"1.187560677","rc":[{"batb":[[1,26,71.14],[2,24,4.16]],"batl":[[0,42,221.76],[1,50,149.88],[2,110,2]],"ltp":50.0,"tv":1876.45,"id":7588306},{"batl":[[1,1.04,1888.45]],"ltp":1.02,"tv":36795.28,"id":11439844}]}]}
{"op":"mcm","clk":"4234924595","pt":1631551298654,"mc":[{"id":"1.187560677","rc":[{"batl":[[0,50,149.88],[1,110,2],[2,990,0.01]],"ltp":50.0,"tv":1876.45,"id":7588306},{"batb":[[1,1.01,3264.96]],"ltp":1.02,"tv":36795.28,"id":11439844}]}]}
{"op":"mcm","clk":"4234924905","pt":1631551302050,"mc":[{"id":"1.187560677","rc":[{"batb":[[0,1.02,15]],"ltp":1.02,"tv":36795.28,"id":11439844}]}]}
{"op":"mcm","clk":"4234926211","pt":1631551315410,"mc":[{"id":"1.187560677","rc":[{"trd":[[1.03,2889.78]],"batl":[[0,1.03,66.55]],"ltp":1.03,"tv":36939.72,"id":11439844}],"tv":38816.17}]}
{"op":"mcm","clk":"4234926477","pt":1631551318642,"mc":[{"id":"1.187560677","rc":[{"batl":[[2,1.09,11.96]],"ltp":1.03,"tv":36939.72,"id":11439844}]}]}
{"op":"mcm","clk":"4234926731","pt":1631551321483,"mc":[{"id":"1.187560677","rc":[{"batl":[[2,1.06,104]],"ltp":1.03,"tv":36939.72,"id":11439844}]}]}
{"op":"mcm","clk":"4234926911","pt":1631551323387,"mc":[{"id":"1.187560677","rc":[{"trd":[[1.02,297.42]],"batb":[[0,1.02,13.29]],"ltp":1.02,"tv":36943.13,"id":11439844}],"tv":38819.58}]}
{"op":"mcm","clk":"4234927090","pt":1631551325706,"mc":[{"id":"1.187560677","rc":[{"trd":[[1.03,2992.8]],"batl":[[0,1.03,15.04]],"ltp":1.03,"tv":37046.15,"id":11439844}],"tv":38922.6}]}
{"op":"mcm","clk":"4234927293","pt":1631551327710,"mc":[{"id":"1.187560677","rc":[{"trd":[[1.03,2996.21]],"batl":[[0,1.03,13.33]],"ltp":1.03,"tv":37049.56,"id":11439844}],"tv":38926.01}]}
{"op":"mcm","clk":"4234927343","pt":1631551328227,"mc":[{"id":"1.187560677","rc":[{"trd":[[50,1.84]],"batl":[[0,50,149.66]],"ltp":50.0,"tv":1876.67,"id":7588306},{"trd":[[1.02,334.84]],"batb":[[0,1.01,3264.96],[1,1.01,0]],"ltp":1.02,"tv":37086.97,"id":11439844}],"tv":38963.65}]}
{"op":"mcm","clk":"4234928755","pt":1631551342177,"mc":[{"id":"1.187560677","rc":[{"batl":[[0,1.03,118.33]],"ltp":1.02,"tv":37086.97,"id":11439844}]}]}
{"op":"mcm","clk":"4234931532","pt":1631551372081,"mc":[{"id":"1.187560677","rc":[{"batb":[[0,1.02,723],[1,1.01,3264.96]],"ltp":1.02,"tv":37086.97,"id":11439844}]}]}
{"op":"mcm","clk":"4234933718","pt":1631551393102,"mc":[{"id":"1.187560677","rc":[{"batb":[[1,1.01,3244.96]],"ltp":1.02,"tv":37086.97,"id":11439844}]}]}
{"op":"mcm","clk":"4234934566","pt":1631551401709,"mc":[{"id":"1.187560677","rc":[{"batb":[[1,24,4.16],[2,17.5,2]],"batl":[[0,110,2],[1,990,0.01],[2,990,0]],"ltp":50.0,"tv":1876.67,"id":7588306},{"batl":[[1,1.04,110]],"ltp":1.02,"tv":37086.97,"id":11439844}]}]}
{"op":"mcm","clk":"4234934617","pt":1631551402339,"mc":[{"id":"1.187560677","rc":[{"batb":[[0,15,12.16],[1,1.3,5],[2,1.01,105.79]],"ltp":50.0,"tv":1876.67,"id":7588306},{"batb":[[0,1.01,3244.96],[1,1.01,0]],"batl":[[0,1.03,13.33],[1,1.09,11.96],[2,1.11,12.23]],"ltp":1.02,"tv":37086.97,"id":11439844}]}]}
{"op":"mcm","clk":"4234934908","pt":1631551405021,"mc":[{"id":"1.187560677","rc":[{"batb":[[1,13.5,3],[2,12,3]],"ltp":50.0,"tv":1876.67,"id":7588306},{"batl":[[1,1.07,108],[2,1.08,94]],"ltp":1.02,"tv":37086.97,"id":11439844}]}]}
{"op":"mcm","clk":"4234935276","pt":1631551408674,"mc":[{"id":"1.187560677","rc":[{"batb":[[1,1.3,5],[2,1.01,105.79]],"ltp":50.0,"tv":1876.67,"id":7588306},{"batl":[[1,1.09,11.96],[2,1.11,12.23]],"ltp":1.02,"tv":37086.97,"id":11439844}]}]}
{"op":"mcm","clk":"4234935407","pt":1631551409848,"mc":[{"id":"1.187560677","rc":[{"batb":[[0,1.01,3100.57]],"ltp":1.02,"tv":37086.97,"id":11439844}]}]}
{"op":"mcm","clk":"4234935560","pt":1631551411547,"mc":[{"id":"1.187560677","rc":[{"batb":[[0,50,2],[1,34,2],[2,30,1.34]],"batl":[[0,100,93.3],[1,110,2],[2,990,0.01]],"ltp":50.0,"tv":1876.67,"id":7588306},{"batl":[[0,1.02,202.31],[1,1.03,5288.93],[2,1.05,94]],"ltp":1.02,"tv":37086.97,"id":11439844}]}]}
{"op":"mcm","clk":"4234935712","pt":1631551413152,"mc":[{"id":"1.187560677","rc":[{"batl":[[0,1.02,222.52]],"ltp":1.02,"tv":37086.97,"id":11439844}]}]}
{"op":"mcm","clk":"4234935925","pt":1631551415254,"mc":[{"id":"1.187560677","rc":[{"batl":[[1,1.03,5275.6]],"ltp":1.02,"tv":37086.97,"id":11439844}]}]}
{"op":"mcm","clk":"4234936879","pt":1631551424659,"mc":[{"id":"1.187560677","rc":[{"batb":[[2,21,7.97]],"batl":[[0,110,2],[1,990,0.01],[2,990,0]],"ltp":50.0,"tv":1876.67,"id":7588306},{"batl":[[0,1.02,114.21],[1,1.03,105]],"ltp":1.02,"tv":37086.97,"id":11439844}]}]}
{"op":"mcm","clk":"4234936953","pt":1631551425445,"mc":[{"id":"1.187560677","rc":[{"batb":[[0,21,7.97],[1,1.3,5],[2,1.01,105.79]],"batl":[[0,990,0.01],[1,990,0]],"ltp":50.0,"tv":1876.67,"id":7588306},{"batb":[[0,1.01,105.79]],"batl":[[0,1.02,20.21],[1,1.05,94],[2,1.09,11.96]],"ltp":1.02,"tv":37086.97,"id":11439844}]}]}
{"op":"mcm","clk":"4234937140","pt":1631551427250,"mc":[{"id":"1.187560677","rc":[{"batb":[[0,1.01,12]],"ltp":1.02,"tv":37086.97,"id":11439844}]}]}
{"op":"mcm","clk":"4234937242","pt":1631551428041,"mc":[{"id":"1.187560677","rc":[{"batb":[[1,17.5,2],[2,1.3,5]],"ltp":50.0,"tv":1876.67,"id":7588306},{"batl":[[2,1.06,107]],"ltp":1.02,"tv":37086.97,"id":11439844}]}]}
{"op":"mcm","clk":"4234937498","pt":1631551430266,"mc":[{"id":"1.187560677","rc":[{"trd":[[50,2.25]],"batl":[[0,990,0.05]],"ltp":50.0,"tv":1877.08,"id":7588306},{"trd":[[1.02,355.04]],"batl":[[0,1.05,94],[1,1.06,107],[2,1.07,108]],"ltp":1.02,"tv":37107.18,"id":11439844}],"tv":38984.26}]}
{"op":"mcm","clk":"4234937722","pt":1631551432272,"mc":[{"id":"1.187560677","rc":[{"trd":[[50,2.29]],"batl":[[0,990,0.01]],"ltp":50.0,"tv":1877.12,"id":7588306},{"trd":[[1.02,357]],"ltp":1.02,"tv":37109.14,"id":11439844}],"tv":38986.26}]}
{"op":"mcm","clk":"4234938405","pt":1631551437868,"mc":[{"id":"1.187560677","rc":[{"batl":[[0,1.06,107],[1,1.07,108],[2,1.09,11.96]],"ltp":1.02,"tv":37109.14,"id":11439844}]}]}
{"op":"mcm","clk":"4234938745","pt":1631551440781,"mc":[{"id":"1.187560677","rc":[{"batb":[[2,13.5,3]],"ltp":50.0,"tv":1877.12,"id":7588306},{"batl":[[2,1.08,102]],"ltp":1.02,"tv":37109.14,"id":11439844}]}]}
{"op":"mcm","clk":"4234940099","pt":1631551452708,"mc":[{"id":"1.187560677","rc":[{"batb":[[1,1.3,5],[2,1.01,105.79]],"ltp":50.0,"tv":1877.12,"id":7588306},{"batl":[[0,1.09,11.96],[1,1.11,12.23],[2,1.13,14.94]],"ltp":1.02,"tv":37109.14,"id":11439844}]}]}
{"op":"mcm","clk":"4234940208","pt":1631551453708,"mc":[{"id":"1.187560677","rc":[{"batb":[[0,1.3,5],[1,1.01,105.79],[2,1.01,0]],"ltp":50.0,"tv":1877.12,"id":7588306},{"batb":[[0,1.01,12.93]],"ltp":1.02,"tv":37109.14,"id":11439844}]}]}
{"op":"mcm","clk":"4234940403","pt":1631551455534,"mc":[{"id":"1.187560677","rc":[{"trd":[[21,76.67]],"batb":[[0,1.3,5.96]],"batl":[[0,290,42.91],[1,990,0.01]],"ltp":21.0,"tv":1877.17,"id":7588306},{"trd":[[1.01,24],[1.05,1087.36]],"batl":[[0,1.01,226.48],[1,1.02,5170.6],[2,1.09,11.96]],"ltp":1.01,"tv":37134.07,"id":11439844}],"tv":39011.24}]}
{"op":"mcm","clk":"4234940757","pt":1631551458604,"mc":[{"id":"1.187560677","rc":[{"batl":[[2,1.05,56.28]],"ltp":1.01,"tv":37134.07,"id":11439844}]}]}
{"op":"mcm","clk":"4234940858","pt":1631551459395,"mc":[{"id":"1.187560677","rc":[{"batl":[[2,1.09,11.96]],"ltp":1.01,"tv":37134.07,"id":11439844}]}]}
{"op":"mcm","clk":"4234941358","pt":1631551463998,"mc":[{"id":"1.187560677","rc":[{"trd":[[1.01,44]],"batl":[[0,1.01,216.48]],"ltp":1.01,"tv":37154.07,"id":11439844}],"tv":39031.24}]}
{"op":"mcm","clk":"4234941492","pt":1631551465408,"mc":[{"id":"1.187560677","rc":[{"batl":[[0,1.02,5170.6],[1,1.09,11.96],[2,1.11,13.94]],"ltp":1.01,"tv":37154.07,"id":11439844}]}]}
{"op":"mcm","clk":"4234941665","pt":1631551466936,"mc":[{"id":"1.187560677","rc":[{"batl":[[2,1.11,12.23]],"ltp":1.01,"tv":37154.07,"id":11439844}]}]}
{"op":"mcm","clk":"4234941828","pt":1631551468304,"mc":[{"id":"1.187560677","rc":[{"batl":[[0,1.01,216.48],[1,1.02,5170.6],[2,1.09,11.96]],"ltp":1.01,"tv":37154.07,"id":11439844}]}]}
{"op":"mcm","clk":"4234942324","pt":1631551472351,"mc":[{"id":"1.187560677","rc":[{"batl":[[0,990,0.01],[1,990,0]],"ltp":21.0,"tv":1877.17,"id":7588306},{"batl":[[0,1.09,11.96],[1,1.11,12.23],[2,1.13,14.94]],"ltp":1.01,"tv":37154.07,"id":11439844}]}]}
{"op":"mcm","clk":"4234942675","pt":1631551475623,"mc":[{"id":"1.187560677","rc":[{"batb":[[0,34,2.96],[1,1.3,5],[2,1.01,105.79]],"ltp":21.0,"tv":1877.17,"id":7588306},{"batl":[[0,1.03,105],[1,1.04,104],[2,1.05,94]],"ltp":1.01,"tv":37154.07,"id":11439844}]}]}
{"op":"mcm","clk":"4234943482","pt":1631551483124,"mc":[{"id":"1.187560677","rc":[{"batl":[[1,1.09,11.96],[2,1.11,12.23]],"ltp":1.01,"tv":37154.07,"id":11439844}]}]}
{"op":"mcm","clk":"4234943725","pt":1631551485621,"mc":[{"id":"1.187560677","rc":[{"batb":[[0,290,17.89],[1,34,2.96],[2,1.3,5]],"ltp":21.0,"tv":1877.17,"id":7588306}]}]}
{"op":"mcm","clk":"4234943806","pt":1631551486453,"mc":[{"id":"1.187560677","rc":[{"batl":[[2,1.11,13.94]],"ltp":1.01,"tv":37154.07,"id":11439844}]}]}
{"op":"mcm","clk":"4234944524","pt":1631551493837,"mc":[{"id":"1.187560677","rc":[{"batl":[[0,1.01,100],[1,1.03,105],[2,1.09,11.96]],"ltp":1.01,"tv":37154.07,"id":11439844}]}]}
{"op":"mcm","clk":"4234944727","pt":1631551495836,"mc":[{"id":"1.187560677","rc":[{"batl":[[1,1.02,77.19],[2,1.03,105]],"ltp":1.01,"tv":37154.07,"id":11439844}]}]}
{"op":"mcm","clk":"4234945601","pt":1631551503349,"mc":[{"id":"1.187560677","rc":[{"batb":[[0,34,2.96],[1,1.3,5],[2,1.01,105.79]],"ltp":21.0,"tv":1877.17,"id":7588306}]}]}
{"op":"mcm","clk":"4234946027","pt":1631551506642,"mc":[{"id":"1.187560677","rc":[{"batb":[[0,50,2],[1,34,2.96],[2,1.3,5]],"ltp":21.0,"tv":1877.17,"id":7588306},{"batl":[[1,1.02,178.19]],"ltp":1.01,"tv":37154.07,"id":11439844}]}]}
{"op":"mcm","clk":"4234946631","pt":1631551511593,"mc":[{"id":"1.187560677","marketDefinition":{"bspMarket":false,"turnInPlayEnabled":true,"persistenceEnabled":true,"marketBaseRate":5.0,"eventId":"30896281","eventTypeId":"2","numberOfWinners":1,"bettingType":"ODDS","marketType":"MATCH_ODDS","marketTime":"2021-09-13T14:56:00.000Z","suspendTime":"2021-09-13T14:56:00.000Z","bspReconciled":false,"complete":true,"inPlay":true,"crossMatching":true,"runnersVoidable":false,"numberOfActiveRunners":2,"betDelay":3,"status":"SUSPENDED","runners":[{"status":"ACTIVE","sortPriority":1,"id":11439844,"name":"Aleksandar Kovacevic"},{"status":"ACTIVE","sortPriority":2,"id":7588306,"name":"Strong Kirchheimer"}],"regulators":["MR_INT"],"countryCode":"US","discountAllowed":true,"timezone":"UTC","openDate":"2021-09-13T14:56:00.000Z","version":4030940445,"name":"Match Odds","eventName":"Al Kovacevic v Str Kirchheimer"}}]}
{"op":"mcm","clk":"4234946837","pt":1631551513180,"mc":[{"id":"1.187560677","rc":[{"batb":[[0,1.3,5.96],[1,1.01,105.79],[2,1.3,0]],"ltp":21.0,"tv":1877.17,"id":7588306},{"batl":[[0,1.02,77.19],[1,1.2,410.36],[2,1.44,95.15]],"ltp":1.01,"tv":37154.07,"id":11439844}]}]}
{"op":"mcm","clk":"4234947427","pt":1631551518687,"mc":[{"id":"1.187560677","rc":[{"batb":[[0,1.3,5]],"ltp":21.0,"tv":1877.17,"id":7588306},{"batl":[[0,1.2,410.08],[1,1.45,0.75],[2,1.44,0]],"ltp":1.01,"tv":37154.07,"id":11439844}]}]}
{"op":"mcm","clk":"4234951948","pt":1631551560768,"mc":[{"id":"1.187560677","tv":0.0}]}
{"op":"mcm","clk":"4234952174","pt":1631551562863,"mc":[{"id":"1.187560677","marketDefinition":{"bspMarket":false,"turnInPlayEnabled":true,"persistenceEnabled":true,"marketBaseRate":5.0,"eventId":"30896281","eventTypeId":"2","numberOfWinners":1,"bettingType":"ODDS","marketType":"MATCH_ODDS","marketTime":"2021-09-13T14:56:00.000Z","suspendTime":"2021-09-13T14:56:00.000Z","bspReconciled":false,"complete":true,"inPlay":true,"crossMatching":false,"runnersVoidable":false,"numberOfActiveRunners":0,"betDelay":3,"status":"CLOSED","settledTime":"2021-09-13T16:45:49.000Z","runners":[{"status":"WINNER","sortPriority":1,"id":11439844,"name":"Aleksandar Kovacevic"},{"status":"LOSER","sortPriority":2,"id":7588306,"name":"Strong Kirchheimer"}],"regulators":["MR_INT"],"countryCode":"US","discountAllowed":true,"timezone":"UTC","openDate":"2021-09-13T14:56:00.000Z","version":4030941647,"name":"Match Odds","eventName":"Al Kovacevic v Str Kirchheimer"}}]}
