{"op":"mcm","clk":"4225136332","pt":1631440798116,"mc":[{"id":"1.187552449","marketDefinition":{"bspMarket":false,"turnInPlayEnabled":true,"persistenceEnabled":true,"marketBaseRate":5.0,"eventId":"30895261","eventTypeId":"2","numberOfWinners":1,"bettingType":"ODDS","marketType":"MATCH_ODDS","marketTime":"2021-09-12T12:00:00.000Z","suspendTime":"2021-09-12T12:00:00.000Z","bspReconciled":false,"complete":true,"inPlay":false,"crossMatching":false,"runnersVoidable":false,"numberOfActiveRunners":2,"betDelay":0,"status":"OPEN","runners":[{"status":"ACTIVE","sortPriority":1,"id":13310360,"name":"W Falkowska"},{"status":"ACTIVE","sortPriority":2,"id":40084547,"name":"M Sequeira"}],"regulators":["MR_INT"],"countryCode":"GB","discountAllowed":false,"timezone":"GMT","openDate":"2021-09-12T12:00:00.000Z","version":4027665820,"name":"Match Odds","eventName":"W Falkowska v M Sequeira"},"rc":[{"batb":[[0,1.01,25]],"ltp":0.0,"tv":0.0,"id":13310360},{"batb":[[0,1.01,25]],"ltp":0.0,"tv":0.0,"id":40084547}]}]}
{"op":"mcm","clk":"4225136572","pt":1631440799973,"mc":[{"id":"1.187552449","marketDefinition":{"bspMarket":false,"turnInPlayEnabled":true,"persistenceEnabled":true,"marketBaseRate":5.0,"eventId":"30895261","eventTypeId":"2","numberOfWinners":1,"bettingType":"ODDS","marketType":"MATCH_ODDS","marketTime":"2021-09-12T12:00:00.000Z","suspendTime":"2021-09-12T12:00:00.000Z","bspReconciled":false,"complete":true,"inPlay":false,"crossMatching":false,"runnersVoidable":false,"numberOfActiveRunners":2,"betDelay":0,"status":"OPEN","runners":[{"status":"ACTIVE","sortPriority":1,"id":13310360,"name":"W Falkowska"},{"status":"ACTIVE","sortPriority":2,"id":40084547,"name":"M Sequeira"}],"regulators":["MR_INT"],"countryCode":"GB","discountAllowed":true,"timezone":"GMT","openDate":"2021-09-12T12:00:00.000Z","version":4027665820,"name":"Match Odds","eventName":"W Falkowska v M Sequeira"}}]}
{"op":"mcm","clk":"4225229541","pt":1631441422634,"mc":[{"id":"1.187552449","rc":[{"batb":[[0,1.05,879.5],[1,1.01,25]],"ltp":0.0,"tv":0.0,"id":40084547}]}]}
{"op":"mcm","clk":"4225271002","pt":1631441707461,"mc":[{"id":"1.187552449","rc":[{"batb":[[0,1.01,7]],"ltp":0.0,"tv":0.0,"id":13310360},{"batb":[[1,1.01,7]],"ltp":0.0,"tv":0.0,"id":40084547}]}]}
{"op":"mcm","clk":"4225318975","pt":1631442021816,"mc":[{"id":"1.187552449","rc":[{"batb":[[0,40,10],[1,1.05,879.5],[2,1.01,7]],"ltp":0.0,"tv":0.0,"id":40084547}]}]}
{"op":"mcm","clk":"4225321338","pt":1631442036423,"mc":[{"id":"1.187552449","marketDefinition":{"bspMarket":false,"turnInPlayEnabled":true,"persistenceEnabled":true,"marketBaseRate":5.0,"eventId":"30895261","eventTypeId":"2","numberOfWinners":1,"bettingType":"ODDS","marketType":"MATCH_ODDS","marketTime":"2021-09-12T12:00:00.000Z","suspendTime":"2021-09-12T12:00:00.000Z","bspReconciled":false,"complete":true,"inPlay":false,"crossMatching":true,"runnersVoidable":false,"numberOfActiveRunners":2,"betDelay":0,"status":"OPEN","runners":[{"status":"ACTIVE","sortPriority":1,"id":13310360,"name":"W Falkowska"},{"status":"ACTIVE","sortPriority":2,"id":40084547,"name":"M Sequeira"}],"regulators":["MR_INT"],"countryCode":"GB","discountAllowed":true,"timezone":"GMT","openDate":"2021-09-12T12:00:00.000Z","version":4027665820,"name":"Match Odds","eventName":"W Falkowska v M Sequeira"}}]}
{"op":"mcm","clk":"4225407524","pt":1631442661900,"mc":[{"id":"1.187552449","rc":[{"batl":[[0,1.02,1228.11]],"ltp":0.0,"tv":0.0,"id":13310360}]}]}
{"op":"mcm","clk":"4225433869","pt":1631442841708,"mc":[{"id":"1.187552449","rc":[{"batl":[[1,29,19.35]],"ltp":0.0,"tv":0.0,"id":13310360},{"batl":[[0,680,19.35]],"ltp":0.0,"tv":0.0,"id":40084547}]}]}
{"op":"mcm","clk":"4225452982","pt":1631442945700,"mc":[{"id":"1.187552449","rc":[{"batl":[[0,200,15.37],[1,680,19.35]],"ltp":0.0,"tv":0.0,"id":40084547}]}]}
{"op":"mcm","clk":"4225558021","pt":1631443595263,"mc":[{"id":"1.187552449","rc":[{"batl":[[1,20,44.41],[2,29,19.35]],"ltp":0.0,"tv":0.0,"id":13310360}]}]}
{"op":"mcm","clk":"4225560486","pt":1631443609500,"mc":[{"id":"1.187552449","rc":[{"batl":[[0,1.02,4644.29]],"ltp":0.0,"tv":0.0,"id":13310360}]}]}
{"op":"mcm","clk":"4225647908","pt":1631444132895,"mc":[{"id":"1.187552449","rc":[{"batb":[[1,1.01,7],[2,1.01,0]],"ltp":0.0,"tv":0.0,"id":40084547}]}]}
{"op":"mcm","clk":"4225648488","pt":1631444137737,"mc":[{"id":"1.187552449","rc":[{"batl":[[1,6,43.98],[2,20,44.41]],"ltp":0.0,"tv":0.0,"id":13310360}]}]}
{"op":"mcm","clk":"4225689488","pt":1631444458148,"mc":[{"id":"1.187552449","rc":[{"batl":[[1,5,44.41],[2,6,43.98]],"ltp":0.0,"tv":0.0,"id":13310360}]}]}
{"op":"mcm","clk":"4225694716","pt":1631444494014,"mc":[{"id":"1.187552449","rc":[{"batb":[[0,1.01,12]],"ltp":0.0,"tv":0.0,"id":13310360},{"batb":[[1,1.01,12]],"ltp":0.0,"tv":0.0,"id":40084547}]}]}
{"op":"mcm","clk":"4225740788","pt":1631444783161,"mc":[{"id":"1.187552449","rc":[{"trd":[[1.01,24]],"batl":[[0,1.01,2188.56],[1,1.02,4644.29],[2,5,44.41]],"ltp":1.01,"tv":23.99,"id":13310360}],"tv":23.99}]}
{"op":"mcm","clk":"4225740983","pt":1631444784333,"mc":[{"id":"1.187552449","rc":[{"batb":[[0,42,10.66],[1,40,10],[2,1.01,12]],"ltp":0.0,"tv":0.0,"id":40084547}]}]}
{"op":"mcm","clk":"4225743324","pt":1631444797944,"mc":[{"id":"1.187552449","rc":[{"batl":[[2,1.1,43.98]],"ltp":1.01,"tv":23.99,"id":13310360}]}]}
{"op":"mcm","clk":"4225865756","pt":1631445530030,"mc":[{"id":"1.187552449","rc":[{"trd":[[1.01,194.81]],"batl":[[0,1.01,2103.15]],"ltp":1.01,"tv":194.8,"id":13310360}],"tv":194.8}]}
{"op":"mcm","clk":"4225913680","pt":1631445819378,"mc":[{"id":"1.187552449","rc":[{"trd":[[1.01,411.72]],"batl":[[0,1.01,1994.7]],"ltp":1.01,"tv":411.71,"id":13310360},{"batb":[[2,1.02,108.45]],"ltp":0.0,"tv":0.0,"id":40084547}],"tv":411.71}]}
{"op":"mcm","clk":"4225971730","pt":1631446168990,"mc":[{"id":"1.187552449","rc":[{"batb":[[0,65,2.66],[1,42,10.66],[2,40,10]],"ltp":0.0,"tv":0.0,"id":40084547}]}]}
{"op":"mcm","clk":"4226084783","pt":1631446881414,"mc":[{"id":"1.187552449","rc":[{"batl":[[1,1.02,3416.18]],"ltp":1.01,"tv":411.71,"id":13310360}]}]}
{"op":"mcm","clk":"4226085985","pt":1631446889130,"mc":[{"id":"1.187552449","rc":[{"batb":[[0,110,10.88],[1,65,2.66],[2,42,10.66]],"ltp":0.0,"tv":0.0,"id":40084547}]}]}
{"op":"mcm","clk":"4226197416","pt":1631447650947,"mc":[{"id":"1.187552449","rc":[{"batl":[[0,1.01,1994.69]],"ltp":1.01,"tv":411.71,"id":13310360}]}]}
{"op":"mcm","clk":"4226250544","pt":1631448049395,"mc":[{"id":"1.187552449","marketDefinition":{"bspMarket":false,"turnInPlayEnabled":true,"persistenceEnabled":true,"marketBaseRate":5.0,"eventId":"30895261","eventTypeId":"2","numberOfWinners":1,"bettingType":"ODDS","marketType":"MATCH_ODDS","marketTime":"2021-09-12T12:00:00.000Z","suspendTime":"2021-09-12T12:00:00.000Z","bspReconciled":false,"complete":true,"inPlay":true,"crossMatching":true,"runnersVoidable":false,"numberOfActiveRunners":2,"betDelay":5,"status":"OPEN","runners":[{"status":"ACTIVE","sortPriority":1,"id":13310360,"name":"W Falkowska"},{"status":"ACTIVE","sortPriority":2,"id":40084547,"name":"M Sequeira"}],"regulators":["MR_INT"],"countryCode":"GB","discountAllowed":true,"timezone":"GMT","openDate":"2021-09-12T12:00:00.000Z","version":4028030894,"name":"Match Odds","eventName":"W Falkowska v M Sequeira"},"rc":[{"batl":[[0,1.02,3416.18],[1,1.02,0],[2,1.1,0]],"ltp":1.01,"tv":411.71,"id":13310360},{"batb":[[1,1.01,12],[2,42,0]],"ltp":0.0,"tv":0.0,"id":40084547}]}]}
{"op":"mcm","clk":"4226323120","pt":1631448482310,"mc":[{"id":"1.187552449","rc":[{"batb":[[0,1.01,12],[1,1.01,0]],"ltp":0.0,"tv":0.0,"id":40084547}]}]}
{"op":"mcm","clk":"4226325243","pt":1631448495116,"mc":[{"id":"1.187552449","rc":[{"batl":[[0,1.01,1400.82],[1,1.02,3416.18]],"ltp":1.01,"tv":411.71,"id":13310360}]}]}
{"op":"mcm","clk":"4226350763","pt":1631448642287,"mc":[{"id":"1.187552449","rc":[{"trd":[[1.01,845.53]],"batl":[[0,1.01,1183.91]],"ltp":1.01,"tv":845.52,"id":13310360}],"tv":845.52}]}
{"op":"mcm","clk":"4226353563","pt":1631448657885,"mc":[{"id":"1.187552449","rc":[{"trd":[[1.01,2029.44]],"batl":[[0,1.02,3416.18],[1,1.02,0]],"ltp":1.01,"tv":2029.43,"id":13310360},{"trd":[[100,11.96]],"batl":[[0,100,29.61]],"ltp":100.0,"tv":11.96,"id":40084547}],"tv":2041.39}]}
{"op":"mcm","clk":"4226354498","pt":1631448663083,"mc":[{"id":"1.187552449","rc":[{"batl":[[1,11.5,8.68]],"ltp":1.01,"tv":2029.43,"id":13310360}]}]}
{"op":"mcm","clk":"4226366539","pt":1631448730710,"mc":[{"id":"1.187552449","rc":[{"batb":[[0,1.01,817.65]],"ltp":1.01,"tv":2029.43,"id":13310360}]}]}
{"op":"mcm","clk":"4226372237","pt":1631448761949,"mc":[{"id":"1.187552449","rc":[{"trd":[[1.02,1451.47]],"batl":[[0,1.02,1964.7]],"ltp":1.02,"tv":3480.9,"id":13310360},{"trd":[[50,29.61]],"ltp":50.0,"tv":41.57,"id":40084547}],"tv":3522.47}]}
{"op":"mcm","clk":"4226379609","pt":1631448806987,"mc":[{"id":"1.187552449","rc":[{"batb":[[0,70,7.08],[1,1.01,12]],"ltp":50.0,"tv":41.57,"id":40084547}]}]}
{"op":"mcm","clk":"4226381013","pt":1631448816116,"mc":[{"id":"1.187552449","rc":[{"trd":[[1.01,2931.31]],"batb":[[0,1.01,366.72]],"ltp":1.01,"tv":4382.77,"id":13310360}],"tv":4424.34}]}
{"op":"mcm","clk":"4226391955","pt":1631448885600,"mc":[{"id":"1.187552449","rc":[{"trd":[[1.02,1500.48]],"batl":[[0,1.02,1940.2]],"ltp":1.02,"tv":4431.78,"id":13310360}],"tv":4473.35}]}
{"op":"mcm","clk":"4226393776","pt":1631448897807,"mc":[{"id":"1.187552449","marketDefinition":{"bspMarket":false,"turnInPlayEnabled":true,"persistenceEnabled":true,"marketBaseRate":5.0,"eventId":"30895261","eventTypeId":"2","numberOfWinners":1,"bettingType":"ODDS","marketType":"MATCH_ODDS","marketTime":"2021-09-12T12:14:57.000Z","suspendTime":"2021-09-12T12:14:57.000Z","bspReconciled":false,"complete":true,"inPlay":true,"crossMatching":true,"runnersVoidable":false,"numberOfActiveRunners":2,"betDelay":5,"status":"OPEN","runners":[{"status":"ACTIVE","sortPriority":1,"id":13310360,"name":"W Falkowska"},{"status":"ACTIVE","sortPriority":2,"id":40084547,"name":"M Sequeira"}],"regulators":["MR_INT"],"countryCode":"GB","discountAllowed":true,"timezone":"GMT","openDate":"2021-09-12T12:00:00.000Z","version":4028088674,"name":"Match Odds","eventName":"W Falkowska v M Sequeira"}}]}
{"op":"mcm","clk":"4226394207","pt":1631448900833,"mc":[{"id":"1.187552449","marketDefinition":{"bspMarket":false,"turnInPlayEnabled":true,"persistenceEnabled":true,"marketBaseRate":5.0,"eventId":"30895261","eventTypeId":"2","numberOfWinners":1,"bettingType":"ODDS","marketType":"MATCH_ODDS","marketTime":"2021-09-12T12:14:57.000Z","suspendTime":"2021-09-12T12:14:57.000Z","bspReconciled":false,"complete":true,"inPlay":true,"crossMatching":true,"runnersVoidable":false,"numberOfActiveRunners":2,"betDelay":5,"status":"OPEN","runners":[{"status":"ACTIVE","sortPriority":1,"id":13310360,"name":"W Falkowska"},{"status":"ACTIVE","sortPriority":2,"id":40084547,"name":"M Sequeira"}],"regulators":["MR_INT"],"countryCode":"GB","discountAllowed":true,"timezone":"GMT","openDate":"2021-09-12T12:14:57.000Z","version":4028088674,"name":"Match Odds","eventName":"W Falkowska v M Sequeira"}}]}
{"op":"mcm","clk":"4226395061","pt":1631448906062,"mc":[{"id":"1.187552449","rc":[{"trd":[[70,14.16]],"batb":[[0,1.01,12],[1,1.01,0]],"batl":[[0,70,10.07]],"ltp":70.0,"tv":55.73,"id":40084547}],"tv":4487.51}]}
{"op":"mcm","clk":"4226397435","pt":1631448921475,"mc":[{"id":"1.187552449","rc":[{"trd":[[70,34.2]],"batl":[[0,70,0.05]],"ltp":70.0,"tv":75.76,"id":40084547}],"tv":4507.54}]}
{"op":"mcm","clk":"4226399078","pt":1631448932310,"mc":[{"id":"1.187552449","rc":[{"batb":[[0,55,10.54],[1,1.01,12]],"ltp":70.0,"tv":75.76,"id":40084547}]}]}
{"op":"mcm","clk":"4226430266","pt":1631449068243,"mc":[{"id":"1.187552449","rc":[{"batl":[[1,11,42.7],[2,11.5,8.68]],"ltp":1.02,"tv":4431.78,"id":13310360}]}]}
{"op":"mcm","clk":"4226438329","pt":1631449117723,"mc":[{"id":"1.187552449","rc":[{"trd":[[1.02,2236.44]],"batl":[[0,1.02,1572.22]],"ltp":1.02,"tv":5167.74,"id":13310360}],"tv":5243.51}]}
{"op":"mcm","clk":"4226442326","pt":1631449142723,"mc":[{"id":"1.187552449","rc":[{"batb":[[0,55,7.08]],"ltp":70.0,"tv":75.76,"id":40084547}]}]}
{"op":"mcm","clk":"4226444257","pt":1631449155216,"mc":[{"id":"1.187552449","rc":[{"batl":[[1,1.3,1269.21],[2,11,42.7]],"ltp":1.02,"tv":5167.74,"id":13310360},{"batl":[[0,340,36.48]],"ltp":70.0,"tv":75.76,"id":40084547}]}]}
{"op":"mcm","clk":"4226461444","pt":1631449261627,"mc":[{"id":"1.187552449","rc":[{"batb":[[0,1.01,12],[1,1.01,0]],"ltp":70.0,"tv":75.76,"id":40084547}]}]}
{"op":"mcm","clk":"4226462350","pt":1631449266776,"mc":[{"id":"1.187552449","rc":[{"batb":[[0,60,7.08],[1,1.01,12]],"ltp":70.0,"tv":75.76,"id":40084547}]}]}
{"op":"mcm","clk":"4226471640","pt":1631449325631,"mc":[{"id":"1.187552449","rc":[{"trd":[[1.01,3365.11]],"batb":[[0,1.01,149.81]],"ltp":1.01,"tv":5601.55,"id":13310360}],"tv":5677.31}]}
{"op":"mcm","clk":"4226480988","pt":1631449385774,"mc":[{"id":"1.187552449","rc":[{"batl":[[0,170,37.59]],"ltp":70.0,"tv":75.76,"id":40084547}]}]}
{"op":"mcm","clk":"4226484497","pt":1631449408904,"mc":[{"id":"1.187552449","rc":[{"batb":[[0,1.01,4126.99]],"ltp":1.01,"tv":5601.55,"id":13310360}]}]}
{"op":"mcm","clk":"4226487176","pt":1631449425497,"mc":[{"id":"1.187552449","rc":[{"batb":[[0,1.01,149.81]],"ltp":1.01,"tv":5601.55,"id":13310360}]}]}
{"op":"mcm","clk":"4226488013","pt":1631449431204,"mc":[{"id":"1.187552449","rc":[{"batl":[[0,170,37.59]],"ltp":70.0,"tv":75.76,"id":40084547}]}]}
{"op":"mcm","clk":"4226497330","pt":1631449494439,"mc":[{"id":"1.187552449","rc":[{"batl":[[0,340,36.48]],"ltp":70.0,"tv":75.76,"id":40084547}]}]}
{"op":"mcm","clk":"4226501825","pt":1631449524668,"mc":[{"id":"1.187552449","rc":[{"batl":[[0,170,37.59]],"ltp":70.0,"tv":75.76,"id":40084547}]}]}
{"op":"mcm","clk":"4226506817","pt":1631449558436,"mc":[{"id":"1.187552449","rc":[{"batl":[[1,11,42.7],[2,11.5,8.68]],"ltp":1.01,"tv":5601.55,"id":13310360}]}]}
{"op":"mcm","clk":"4226518389","pt":1631449634819,"mc":[{"id":"1.187552449","rc":[{"batb":[[0,1.01,4314.59]],"ltp":1.01,"tv":5601.55,"id":13310360}]}]}
{"op":"mcm","clk":"4226518434","pt":1631449635130,"mc":[{"id":"1.187552449","rc":[{"batl":[[1,1.32,1173.52],[2,11,42.7]],"ltp":1.01,"tv":5601.55,"id":13310360}]}]}
{"op":"mcm","clk":"4226520610","pt":1631449650676,"mc":[{"id":"1.187552449","rc":[{"batb":[[0,1.01,149.81]],"ltp":1.01,"tv":5601.55,"id":13310360}]}]}
{"op":"mcm","clk":"4226521381","pt":1631449656139,"mc":[{"id":"1.187552449","rc":[{"batb":[[0,1.01,4126.99]],"ltp":1.01,"tv":5601.55,"id":13310360}]}]}
{"op":"mcm","clk":"4226524650","pt":1631449680431,"mc":[{"id":"1.187552449","rc":[{"batb":[[0,1.01,149.81]],"ltp":1.01,"tv":5601.55,"id":13310360}]}]}
{"op":"mcm","clk":"4226525536","pt":1631449686650,"mc":[{"id":"1.187552449","rc":[{"batb":[[0,1.01,4314.59]],"ltp":1.01,"tv":5601.55,"id":13310360}]}]}
{"op":"mcm","clk":"4226527732","pt":1631449703760,"mc":[{"id":"1.187552449","rc":[{"batb":[[0,1.01,149.81]],"ltp":1.01,"tv":5601.55,"id":13310360}]}]}
{"op":"mcm","clk":"4226528504","pt":1631449710001,"mc":[{"id":"1.187552449","rc":[{"batb":[[0,1.01,4126.99]],"ltp":1.01,"tv":5601.55,"id":13310360}]}]}
{"op":"mcm","clk":"4226537265","pt":1631449776363,"mc":[{"id":"1.187552449","rc":[{"batb":[[0,1.01,149.81]],"ltp":1.01,"tv":5601.55,"id":13310360}]}]}
{"op":"mcm","clk":"4226538010","pt":1631449782553,"mc":[{"id":"1.187552449","rc":[{"trd":[[1.02,5797.4]],"batl":[[0,1.32,1173.52],[1,11,42.7],[2,11.5,8.68]],"ltp":1.02,"tv":9162.51,"id":13310360},{"trd":[[60,7.08]],"batb":[[0,1.01,12],[1,1.01,0]],"ltp":60.0,"tv":82.84,"id":40084547}],"tv":9245.36}]}
{"op":"mcm","clk":"4226540996","pt":1631449805520,"mc":[{"id":"1.187552449","rc":[{"batb":[[0,1.01,1700.77]],"ltp":1.02,"tv":9162.51,"id":13310360}]}]}
{"op":"mcm","clk":"4226541085","pt":1631449806121,"mc":[{"id":"1.187552449","rc":[{"batb":[[0,36,12.26],[1,1.01,12]],"ltp":60.0,"tv":82.84,"id":40084547}]}]}
{"op":"mcm","clk":"4226542084","pt":1631449813234,"mc":[{"id":"1.187552449","rc":[{"batb":[[0,36,7.08]],"ltp":60.0,"tv":82.84,"id":40084547}]}]}
{"op":"mcm","clk":"4226543408","pt":1631449823412,"mc":[{"id":"1.187552449","rc":[{"batl":[[0,1.09,142.31],[1,1.32,1173.52],[2,11,42.7]],"ltp":1.02,"tv":9162.51,"id":13310360}]}]}
{"op":"mcm","clk":"4226546969","pt":1631449850124,"mc":[{"id":"1.187552449","rc":[{"batb":[[0,1.01,149.81]],"ltp":1.02,"tv":9162.51,"id":13310360}]}]}
{"op":"mcm","clk":"4226547828","pt":1631449856323,"mc":[{"id":"1.187552449","rc":[{"batl":[[0,170,25.31]],"ltp":60.0,"tv":82.84,"id":40084547}]}]}
{"op":"mcm","clk":"4226567781","pt":1631449992823,"mc":[{"id":"1.187552449","rc":[{"batl":[[0,1.02,1029.24],[1,1.09,142.31],[2,1.32,1173.52]],"ltp":1.02,"tv":9162.51,"id":13310360}]}]}
{"op":"mcm","clk":"4226576686","pt":1631450052007,"mc":[{"id":"1.187552449","rc":[{"batl":[[2,11,42.7]],"ltp":1.02,"tv":9162.51,"id":13310360}]}]}
{"op":"mcm","clk":"4226577741","pt":1631450057883,"mc":[{"id":"1.187552449","rc":[{"batl":[[2,1.27,2975.92]],"ltp":1.02,"tv":9162.51,"id":13310360}]}]}
{"op":"mcm","clk":"4226582984","pt":1631450089513,"mc":[{"id":"1.187552449","rc":[{"batb":[[0,1.01,12],[1,1.01,0]],"ltp":60.0,"tv":82.84,"id":40084547}]}]}
{"op":"mcm","clk":"4226583731","pt":1631450094630,"mc":[{"id":"1.187552449","rc":[{"batb":[[0,55,7.08],[1,1.01,12]],"ltp":60.0,"tv":82.84,"id":40084547}]}]}
{"op":"mcm","clk":"4226590179","pt":1631450134953,"mc":[{"id":"1.187552449","rc":[{"trd":[[1.01,3629.35]],"batb":[[0,1.01,17.69]],"ltp":1.01,"tv":9426.75,"id":13310360}],"tv":9509.6}]}
{"op":"mcm","clk":"4226604012","pt":1631450223284,"mc":[{"id":"1.187552449","rc":[{"trd":[[1.02,7797.4]],"batl":[[0,1.02,29.24]],"ltp":1.02,"tv":11426.75,"id":13310360}],"tv":11509.6}]}
{"op":"mcm","clk":"4226606318","pt":1631450237701,"mc":[{"id":"1.187552449","rc":[{"batb":[[0,1.01,1244.18]],"ltp":1.02,"tv":11426.75,"id":13310360}]}]}
{"op":"mcm","clk":"4226634429","pt":1631450421298,"mc":[{"id":"1.187552449","rc":[{"trd":[[1.01,3663.52]],"batb":[[0,1.01,1227.09]],"ltp":1.01,"tv":11460.91,"id":13310360}],"tv":11543.76}]}
{"op":"mcm","clk":"4226653800","pt":1631450534267,"mc":[{"id":"1.187552449","rc":[{"batl":[[2,11,42.7]],"ltp":1.01,"tv":11460.91,"id":13310360}]}]}
{"op":"mcm","clk":"4226662832","pt":1631450573733,"mc":[{"id":"1.187552449","rc":[{"batb":[[0,1.01,0.61]],"ltp":1.01,"tv":11460.91,"id":13310360}]}]}
{"op":"mcm","clk":"4226667643","pt":1631450600981,"mc":[{"id":"1.187552449","rc":[{"batb":[[0,1.01,12],[1,1.01,0]],"ltp":60.0,"tv":82.84,"id":40084547}]}]}
{"op":"mcm","clk":"4226668504","pt":1631450606108,"mc":[{"id":"1.187552449","rc":[{"batb":[[0,70,7.08],[1,1.01,12]],"ltp":60.0,"tv":82.84,"id":40084547}]}]}
{"op":"mcm","clk":"4226672352","pt":1631450626957,"mc":[{"id":"1.187552449","rc":[{"batl":[[1,1.06,75.13],[2,1.09,142.31]],"ltp":1.01,"tv":11460.91,"id":13310360}]}]}
{"op":"mcm","clk":"4226689698","pt":1631450723815,"mc":[{"id":"1.187552449","rc":[{"batb":[[0,1.01,1104.56]],"ltp":1.01,"tv":11460.91,"id":13310360}]}]}
{"op":"mcm","clk":"4226708868","pt":1631450840348,"mc":[{"id":"1.187552449","rc":[{"batl":[[1,1.09,142.31],[2,1.28,2941.83]],"ltp":1.01,"tv":11460.91,"id":13310360}]}]}
{"op":"mcm","clk":"4226709640","pt":1631450845415,"mc":[{"id":"1.187552449","rc":[{"batl":[[1,1.05,75.13],[2,1.09,142.31]],"ltp":1.01,"tv":11460.91,"id":13310360}]}]}
{"op":"mcm","clk":"4226719649","pt":1631450909698,"mc":[{"id":"1.187552449","rc":[{"batl":[[0,1.05,75.13],[1,1.09,142.31],[2,1.28,2941.83]],"ltp":1.01,"tv":11460.91,"id":13310360}]}]}
{"op":"mcm","clk":"4226722119","pt":1631450925048,"mc":[{"id":"1.187552449","rc":[{"batl":[[0,340,30.35]],"ltp":60.0,"tv":82.84,"id":40084547}]}]}
{"op":"mcm","clk":"4226727474","pt":1631450959466,"mc":[{"id":"1.187552449","rc":[{"batl":[[0,170,25.31]],"ltp":60.0,"tv":82.84,"id":40084547}]}]}
{"op":"mcm","clk":"4226728908","pt":1631450968700,"mc":[{"id":"1.187552449","rc":[{"trd":[[1.02,8283.13]],"ltp":1.02,"tv":11946.64,"id":13310360},{"trd":[[70,41.28]],"batb":[[0,1.01,12],[1,1.01,0]],"ltp":70.0,"tv":89.92,"id":40084547}],"tv":12036.57}]}
{"op":"mcm","clk":"4226731944","pt":1631450987131,"mc":[{"id":"1.187552449","rc":[{"batl":[[0,1.09,142.31],[1,1.28,2941.83],[2,11,42.7]],"ltp":1.02,"tv":11946.64,"id":13310360}]}]}
{"op":"mcm","clk":"4226732735","pt":1631450992406,"mc":[{"id":"1.187552449","rc":[{"batl":[[0,1.04,75.13],[1,1.09,142.31],[2,1.28,2941.83]],"ltp":1.02,"tv":11946.64,"id":13310360}]}]}
{"op":"mcm","clk":"4226736334","pt":1631451015367,"mc":[{"id":"1.187552449","rc":[{"batb":[[0,1.01,1825]],"ltp":1.02,"tv":11946.64,"id":13310360}]}]}
{"op":"mcm","clk":"4226739582","pt":1631451038319,"mc":[{"id":"1.187552449","rc":[{"batb":[[0,1.01,1104.56]],"ltp":1.02,"tv":11946.64,"id":13310360}]}]}
{"op":"mcm","clk":"4226740442","pt":1631451044456,"mc":[{"id":"1.187552449","rc":[{"batb":[[0,1.01,2655.51]],"ltp":1.02,"tv":11946.64,"id":13310360}]}]}
{"op":"mcm","clk":"4226742708","pt":1631451061648,"mc":[{"id":"1.187552449","rc":[{"batb":[[0,1.01,1104.56]],"ltp":1.02,"tv":11946.64,"id":13310360}]}]}
{"op":"mcm","clk":"4226747284","pt":1631451094309,"mc":[{"id":"1.187552449","rc":[{"batb":[[0,1.01,1825]],"ltp":1.02,"tv":11946.64,"id":13310360}]}]}
{"op":"mcm","clk":"4226752094","pt":1631451130855,"mc":[{"id":"1.187552449","rc":[{"batb":[[0,1.01,1104.56]],"batl":[[2,11,42.7]],"ltp":1.02,"tv":11946.64,"id":13310360}]}]}
{"op":"mcm","clk":"4226753778","pt":1631451144770,"mc":[{"id":"1.187552449","rc":[{"batl":[[2,1.3,2786.44]],"ltp":1.02,"tv":11946.64,"id":13310360},{"batl":[[0,170,25.31]],"ltp":70.0,"tv":89.92,"id":40084547}]}]}
{"op":"mcm","clk":"4226754735","pt":1631451151957,"mc":[{"id":"1.187552449","rc":[{"batl":[[0,1.04,247.83]],"ltp":1.02,"tv":11946.64,"id":13310360}]}]}
{"op":"mcm","clk":"4226755902","pt":1631451160405,"mc":[{"id":"1.187552449","rc":[{"batl":[[2,11,42.7]],"ltp":1.02,"tv":11946.64,"id":13310360}]}]}
{"op":"mcm","clk":"4226757501","pt":1631451172406,"mc":[{"id":"1.187552449","rc":[{"batl":[[2,1.3,2814.45]],"ltp":1.02,"tv":11946.64,"id":13310360},{"batl":[[0,340,30.35]],"ltp":70.0,"tv":89.92,"id":40084547}]}]}
{"op":"mcm","clk":"4226794366","pt":1631451454900,"mc":[{"id":"1.187552449","rc":[{"batl":[[2,11,42.7]],"ltp":1.02,"tv":11946.64,"id":13310360}]}]}
{"op":"mcm","clk":"4226798388","pt":1631451483161,"mc":[{"id":"1.187552449","rc":[{"batl":[[2,1.28,2892.45]],"ltp":1.02,"tv":11946.64,"id":13310360}]}]}
{"op":"mcm","clk":"4226801172","pt":1631451502796,"mc":[{"id":"1.187552449","rc":[{"batl":[[2,11,42.7]],"ltp":1.02,"tv":11946.64,"id":13310360}]}]}
{"op":"mcm","clk":"4226803000","pt":1631451516745,"mc":[{"id":"1.187552449","rc":[{"batl":[[2,1.3,2786.44]],"ltp":1.02,"tv":11946.64,"id":13310360},{"batl":[[0,170,25.31]],"ltp":70.0,"tv":89.92,"id":40084547}]}]}
{"op":"mcm","clk":"4226803852","pt":1631451523544,"mc":[{"id":"1.187552449","rc":[{"batl":[[0,1.09,142.31],[1,1.3,2786.44],[2,11,42.7]],"ltp":1.02,"tv":11946.64,"id":13310360}]}]}
{"op":"mcm","clk":"4226804502","pt":1631451528638,"mc":[{"id":"1.187552449","rc":[{"batl":[[0,1.03,247.83],[1,1.09,142.31],[2,1.3,2786.44]],"ltp":1.02,"tv":11946.64,"id":13310360}]}]}
{"op":"mcm","clk":"4226806472","pt":1631451544051,"mc":[{"id":"1.187552449","rc":[{"batb":[[0,1.01,2655.51]],"ltp":1.02,"tv":11946.64,"id":13310360}]}]}
{"op":"mcm","clk":"4226807539","pt":1631451553668,"mc":[{"id":"1.187552449","rc":[{"batb":[[0,1.01,1104.56]],"ltp":1.02,"tv":11946.64,"id":13310360}]}]}
{"op":"mcm","clk":"4226814581","pt":1631451606629,"mc":[{"id":"1.187552449","rc":[{"trd":[[1.03,165.84]],"batl":[[0,1.03,164.92]],"ltp":1.03,"tv":12112.48,"id":13310360}],"tv":12202.41}]}
{"op":"mcm","clk":"4226815825","pt":1631451612942,"mc":[{"id":"1.187552449","rc":[{"trd":[[1.03,495.67]],"batb":[[0,1.03,83.47],[1,1.01,1104.56]],"batl":[[0,1.09,142.31],[1,1.3,2786.44],[2,11,42.7]],"ltp":1.03,"tv":12442.31,"id":13310360}],"tv":12532.24}]}
{"op":"mcm","clk":"4226816572","pt":1631451618437,"mc":[{"id":"1.187552449","rc":[{"trd":[[1.03,662.61]],"batb":[[0,1.01,1104.56],[1,1.01,0]],"batl":[[0,1.03,22.88],[1,1.09,142.31],[2,1.3,2786.44]],"ltp":1.03,"tv":12609.26,"id":13310360}],"tv":12699.19}]}
{"op":"mcm","clk":"4226817381","pt":1631451623561,"mc":[{"id":"1.187552449","rc":[{"trd":[[1.03,708.37]],"batl":[[0,1.09,142.31],[1,1.3,2786.44],[2,11,42.7]],"ltp":1.03,"tv":12655.01,"id":13310360}],"tv":12744.94}]}
{"op":"mcm","clk":"4226825659","pt":1631451678789,"mc":[{"id":"1.187552449","rc":[{"batl":[[0,1.08,73.6],[1,1.09,142.31],[2,1.3,2786.44]],"ltp":1.03,"tv":12655.01,"id":13310360}]}]}
{"op":"mcm","clk":"4226826946","pt":1631451686744,"mc":[{"id":"1.187552449","rc":[{"batb":[[0,1.01,1825]],"ltp":1.03,"tv":12655.01,"id":13310360}]}]}
{"op":"mcm","clk":"4226833783","pt":1631451729739,"mc":[{"id":"1.187552449","rc":[{"batb":[[0,1.01,1104.56]],"ltp":1.03,"tv":12655.01,"id":13310360}]}]}
{"op":"mcm","clk":"4226834706","pt":1631451735383,"mc":[{"id":"1.187552449","rc":[{"batl":[[0,170,25.31]],"ltp":70.0,"tv":89.92,"id":40084547}]}]}
{"op":"mcm","clk":"4226867918","pt":1631451907156,"mc":[{"id":"1.187552449","rc":[{"batl":[[0,340,30.35]],"ltp":70.0,"tv":89.92,"id":40084547}]}]}
{"op":"mcm","clk":"4226887621","pt":1631452010829,"mc":[{"id":"1.187552449","rc":[{"batl":[[0,170,25.31]],"ltp":70.0,"tv":89.92,"id":40084547}]}]}
{"op":"mcm","clk":"4226891106","pt":1631452030249,"mc":[{"id":"1.187552449","rc":[{"batb":[[0,1.01,1825]],"ltp":1.03,"tv":12655.01,"id":13310360}]}]}
{"op":"mcm","clk":"4226894282","pt":1631452048058,"mc":[{"id":"1.187552449","rc":[{"batb":[[0,1.01,1104.56]],"ltp":1.03,"tv":12655.01,"id":13310360}]}]}
{"op":"mcm","clk":"4226895393","pt":1631452054499,"mc":[{"id":"1.187552449","rc":[{"batl":[[0,340,30.35]],"ltp":70.0,"tv":89.92,"id":40084547}]}]}
{"op":"mcm","clk":"4226899417","pt":1631452077888,"mc":[{"id":"1.187552449","rc":[{"batl":[[2,11,42.7]],"ltp":1.03,"tv":12655.01,"id":13310360}]}]}
{"op":"mcm","clk":"4226900001","pt":1631452080691,"mc":[{"id":"1.187552449","rc":[{"batl":[[0,1.03,70.98],[1,1.08,73.6],[2,1.09,142.31]],"ltp":1.03,"tv":12655.01,"id":13310360}]}]}
{"op":"mcm","clk":"4226902231","pt":1631452093797,"mc":[{"id":"1.187552449","rc":[{"batb":[[0,1.01,1825]],"ltp":1.03,"tv":12655.01,"id":13310360}]}]}
{"op":"mcm","clk":"4226906169","pt":1631452116346,"mc":[{"id":"1.187552449","rc":[{"batl":[[0,1.08,73.6],[1,1.09,142.31],[2,11,42.7]],"ltp":1.03,"tv":12655.01,"id":13310360}]}]}
{"op":"mcm","clk":"4226906906","pt":1631452119955,"mc":[{"id":"1.187552449","rc":[{"batb":[[0,1.01,1104.56]],"ltp":1.03,"tv":12655.01,"id":13310360}]}]}
{"op":"mcm","clk":"4226907191","pt":1631452121436,"mc":[{"id":"1.187552449","rc":[{"batl":[[0,1.04,70.98],[1,1.08,73.6],[2,1.09,142.31]],"ltp":1.03,"tv":12655.01,"id":13310360}]}]}
{"op":"mcm","clk":"4226909132","pt":1631452131767,"mc":[{"id":"1.187552449","rc":[{"batl":[[0,1.04,243.69]],"ltp":1.03,"tv":12655.01,"id":13310360}]}]}
{"op":"mcm","clk":"4226915549","pt":1631452166504,"mc":[{"id":"1.187552449","rc":[{"batl":[[0,170,25.31]],"ltp":70.0,"tv":89.92,"id":40084547}]}]}
{"op":"mcm","clk":"4226931524","pt":1631452250671,"mc":[{"id":"1.187552449","rc":[{"batl":[[1,1.09,142.31],[2,1.28,2941.83]],"ltp":1.03,"tv":12655.01,"id":13310360}]}]}
{"op":"mcm","clk":"4226931832","pt":1631452251989,"mc":[{"id":"1.187552449","rc":[{"batl":[[0,1.09,142.31],[1,1.28,2941.83],[2,11,42.7]],"ltp":1.03,"tv":12655.01,"id":13310360}]}]}
{"op":"mcm","clk":"4226932824","pt":1631452257075,"mc":[{"id":"1.187552449","rc":[{"batl":[[0,1.02,243.69],[1,1.09,142.31],[2,1.28,2941.83]],"ltp":1.03,"tv":12655.01,"id":13310360}]}]}
{"op":"mcm","clk":"4226933964","pt":1631452262624,"mc":[{"id":"1.187552449","rc":[{"batl":[[0,1.09,142.31],[1,1.28,2941.83],[2,11,42.7]],"ltp":1.03,"tv":12655.01,"id":13310360}]}]}
{"op":"mcm","clk":"4226934973","pt":1631452267722,"mc":[{"id":"1.187552449","rc":[{"batl":[[0,1.03,243.69],[1,1.09,142.31],[2,1.28,2941.83]],"ltp":1.03,"tv":12655.01,"id":13310360}]}]}
{"op":"mcm","clk":"4226942133","pt":1631452304716,"mc":[{"id":"1.187552449","rc":[{"batl":[[2,11,42.7]],"ltp":1.03,"tv":12655.01,"id":13310360}]}]}
{"op":"mcm","clk":"4226988960","pt":1631452562855,"mc":[{"id":"1.187552449","rc":[{"batl":[[2,1.27,2975.92]],"ltp":1.03,"tv":12655.01,"id":13310360}]}]}
{"op":"mcm","clk":"4226998369","pt":1631452615642,"mc":[{"id":"1.187552449","rc":[{"batl":[[0,1.09,142.31],[1,1.27,2975.92],[2,11,42.7]],"ltp":1.03,"tv":12655.01,"id":13310360}]}]}
{"op":"mcm","clk":"4226999288","pt":1631452620716,"mc":[{"id":"1.187552449","rc":[{"batl":[[0,1.02,243.69],[1,1.09,142.31],[2,1.27,2975.92]],"ltp":1.03,"tv":12655.01,"id":13310360}]}]}
{"op":"mcm","clk":"4227025593","pt":1631452766825,"mc":[{"id":"1.187552449","rc":[{"batb":[[0,1.01,1108.69]],"ltp":1.03,"tv":12655.01,"id":13310360}]}]}
{"op":"mcm","clk":"4227030701","pt":1631452795415,"mc":[{"id":"1.187552449","rc":[{"batb":[[0,1.01,1104.56]],"ltp":1.03,"tv":12655.01,"id":13310360}]}]}
{"op":"mcm","clk":"4227032715","pt":1631452808361,"mc":[{"id":"1.187552449","rc":[{"trd":[[1.02,8291.4]],"batl":[[0,1.02,239.55]],"ltp":1.02,"tv":12663.28,"id":13310360}],"tv":12753.21}]}
{"op":"mcm","clk":"4227037322","pt":1631452838705,"mc":[{"id":"1.187552449","rc":[{"batb":[[0,1.01,0.61]],"ltp":1.02,"tv":12663.28,"id":13310360}]}]}
{"op":"mcm","clk":"4227039284","pt":1631452852004,"mc":[{"id":"1.187552449","rc":[{"batl":[[1,1.04,3.86],[2,1.09,142.31]],"ltp":1.02,"tv":12663.28,"id":13310360}]}]}
{"op":"mcm","clk":"4227040421","pt":1631452859213,"mc":[{"id":"1.187552449","rc":[{"batl":[[2,1.08,291.23]],"ltp":1.02,"tv":12663.28,"id":13310360}]}]}
{"op":"mcm","clk":"4227047792","pt":1631452904582,"mc":[{"id":"1.187552449","rc":[{"batl":[[1,1.08,291.23],[2,1.09,142.31]],"ltp":1.02,"tv":12663.28,"id":13310360}]}]}
{"op":"mcm","clk":"4227051928","pt":1631452931646,"mc":[{"id":"1.187552449","rc":[{"batl":[[1,1.04,3.86],[2,1.08,291.23]],"ltp":1.02,"tv":12663.28,"id":13310360}]}]}
{"op":"mcm","clk":"4227116328","pt":1631453333020,"mc":[{"id":"1.187552449","rc":[{"batl":[[1,1.08,291.23],[2,1.09,142.31]],"ltp":1.02,"tv":12663.28,"id":13310360}]}]}
{"op":"mcm","clk":"4227308721","pt":1631454469705,"mc":[{"id":"1.187552449","rc":[{"batl":[[0,1.01,837.38],[1,1.02,239.55],[2,1.08,291.23]],"ltp":1.02,"tv":12663.28,"id":13310360}]}]}
{"op":"mcm","clk":"4227314318","pt":1631454506458,"mc":[{"id":"1.187552449","rc":[{"batl":[[0,1.02,239.55],[1,1.08,291.23],[2,1.09,142.31]],"ltp":1.02,"tv":12663.28,"id":13310360}]}]}
{"op":"mcm","clk":"4227381543","pt":1631455081645,"mc":[{"id":"1.187552449","rc":[{"batl":[[0,170,25.31]],"ltp":70.0,"tv":89.92,"id":40084547}]}]}
{"op":"mcm","clk":"4227402135","pt":1631455252999,"mc":[{"id":"1.187552449","rc":[{"batb":[[0,1.01,720.45]],"ltp":1.02,"tv":12663.28,"id":13310360}]}]}
{"op":"mcm","clk":"4227408500","pt":1631455299444,"mc":[{"id":"1.187552449","rc":[{"batl":[[1,1.09,142.31],[2,1.32,2690.33]],"ltp":1.02,"tv":12663.28,"id":13310360}]}]}
{"op":"mcm","clk":"4227409028","pt":1631455303466,"mc":[{"id":"1.187552449","rc":[{"batl":[[0,170,25.31]],"ltp":70.0,"tv":89.92,"id":40084547}]}]}
{"op":"mcm","clk":"4227433058","pt":1631455459515,"mc":[{"id":"1.187552449","rc":[{"batl":[[2,11,42.7]],"ltp":1.02,"tv":12663.28,"id":13310360}]}]}
{"op":"mcm","clk":"4227437388","pt":1631455485152,"mc":[{"id":"1.187552449","rc":[{"batl":[[2,1.3,2786.44]],"ltp":1.02,"tv":12663.28,"id":13310360},{"batl":[[0,170,25.31]],"ltp":70.0,"tv":89.92,"id":40084547}]}]}
{"op":"mcm","clk":"4227440523","pt":1631455502985,"mc":[{"id":"1.187552449","rc":[{"batl":[[2,11,42.7]],"ltp":1.02,"tv":12663.28,"id":13310360}]}]}
{"op":"mcm","clk":"4227443455","pt":1631455519276,"mc":[{"id":"1.187552449","rc":[{"batl":[[2,1.28,2892.45]],"ltp":1.02,"tv":12663.28,"id":13310360}]}]}
{"op":"mcm","clk":"4227446318","pt":1631455535315,"mc":[{"id":"1.187552449","rc":[{"batl":[[0,1.09,142.31],[1,1.28,2892.45],[2,11,42.7]],"ltp":1.02,"tv":12663.28,"id":13310360}]}]}
{"op":"mcm","clk":"4227447199","pt":1631455540393,"mc":[{"id":"1.187552449","rc":[{"batl":[[0,1.03,239.55],[1,1.09,142.31],[2,1.28,2892.45]],"ltp":1.02,"tv":12663.28,"id":13310360}]}]}
{"op":"mcm","clk":"4227460230","pt":1631455613207,"mc":[{"id":"1.187552449","rc":[{"batl":[[2,11,42.7]],"ltp":1.02,"tv":12663.28,"id":13310360}]}]}
{"op":"mcm","clk":"4227463233","pt":1631455629353,"mc":[{"id":"1.187552449","rc":[{"batl":[[2,1.27,2975.92]],"ltp":1.02,"tv":12663.28,"id":13310360}]}]}
{"op":"mcm","clk":"4227464730","pt":1631455637483,"mc":[{"id":"1.187552449","rc":[{"batl":[[2,11,42.7]],"ltp":1.02,"tv":12663.28,"id":13310360}]}]}
{"op":"mcm","clk":"4227469481","pt":1631455663601,"mc":[{"id":"1.187552449","rc":[{"batl":[[2,1.27,2999.57]],"ltp":1.02,"tv":12663.28,"id":13310360}]}]}
{"op":"mcm","clk":"4227471485","pt":1631455674796,"mc":[{"id":"1.187552449","rc":[{"batl":[[2,11,42.7]],"ltp":1.02,"tv":12663.28,"id":13310360}]}]}
{"op":"mcm","clk":"4227485265","pt":1631455750234,"mc":[{"id":"1.187552449","rc":[{"batl":[[2,1.27,2975.92]],"ltp":1.02,"tv":12663.28,"id":13310360}]}]}
{"op":"mcm","clk":"4227487649","pt":1631455761677,"mc":[{"id":"1.187552449","rc":[{"batl":[[2,11,42.7]],"ltp":1.02,"tv":12663.28,"id":13310360}]}]}
{"op":"mcm","clk":"4227498363","pt":1631455816647,"mc":[{"id":"1.187552449","rc":[{"batl":[[0,11,42.7],[1,11.5,8.68],[2,11,0]],"ltp":1.02,"tv":12663.28,"id":13310360}]}]}
{"op":"mcm","clk":"4227499389","pt":1631455821954,"mc":[{"id":"1.187552449","rc":[{"batl":[[0,10.5,2.89],[1,11,42.7],[2,11.5,8.68]],"ltp":1.02,"tv":12663.28,"id":13310360}]}]}
{"op":"mcm","clk":"4227501115","pt":1631455830576,"mc":[{"id":"1.187552449","rc":[{"batb":[[0,690,2.07],[1,1.01,12]],"ltp":70.0,"tv":89.92,"id":40084547}]}]}
{"op":"mcm","clk":"4227503927","pt":1631455844831,"mc":[{"id":"1.187552449","marketDefinition":{"bspMarket":false,"turnInPlayEnabled":true,"persistenceEnabled":true,"marketBaseRate":5.0,"eventId":"30895261","eventTypeId":"2","numberOfWinners":1,"bettingType":"ODDS","marketType":"MATCH_ODDS","marketTime":"2021-09-12T12:14:57.000Z","suspendTime":"2021-09-12T12:14:57.000Z","bspReconciled":false,"complete":true,"inPlay":true,"crossMatching":true,"runnersVoidable":false,"numberOfActiveRunners":2,"betDelay":5,"status":"SUSPENDED","runners":[{"status":"ACTIVE","sortPriority":1,"id":13310360,"name":"W Falkowska"},{"status":"ACTIVE","sortPriority":2,"id":40084547,"name":"M Sequeira"}],"regulators":["MR_INT"],"countryCode":"GB","discountAllowed":true,"timezone":"GMT","openDate":"2021-09-12T12:14:57.000Z","version":4028543711,"name":"Match Odds","eventName":"W Falkowska v M Sequeira"}}]}
{"op":"mcm","clk":"4227504918","pt":1631455849838,"mc":[{"id":"1.187552449","marketDefinition":{"bspMarket":false,"turnInPlayEnabled":true,"persistenceEnabled":true,"marketBaseRate":5.0,"eventId":"30895261","eventTypeId":"2","numberOfWinners":1,"bettingType":"ODDS","marketType":"MATCH_ODDS","marketTime":"2021-09-12T12:14:57.000Z","suspendTime":"2021-09-12T12:14:57.000Z","bspReconciled":false,"complete":true,"inPlay":true,"crossMatching":false,"runnersVoidable":false,"numberOfActiveRunners":0,"betDelay":5,"status":"CLOSED","settledTime":"2021-09-12T14:10:47.000Z","runners":[{"status":"WINNER","sortPriority":1,"id":13310360,"name":"W Falkowska"},{"status":"LOSER","sortPriority":2,"id":40084547,"name":"M Sequeira"}],"regulators":["MR_INT"],"countryCode":"GB","discountAllowed":true,"timezone":"GMT","openDate":"2021-09-12T12:14:57.000Z","version":4028544333,"name":"Match Odds","eventName":"W Falkowska v M Sequeira"},"tv":0.0}]}
