{"op":"mcm","clk":"4230414066","pt":1631474813317,"mc":[{"id":"1.187562121","marketDefinition":{"bspMarket":false,"turnInPlayEnabled":true,"persistenceEnabled":true,"marketBaseRate":5.0,"eventId":"30896488","eventTypeId":"2","numberOfWinners":1,"bettingType":"ODDS","marketType":"MATCH_ODDS","marketTime":"2021-09-13T15:00:00.000Z","suspendTime":"2021-09-13T15:00:00.000Z","bspReconciled":false,"complete":true,"inPlay":false,"crossMatching":false,"runnersVoidable":false,"numberOfActiveRunners":2,"betDelay":0,"status":"OPEN","runners":[{"status":"ACTIVE","sortPriority":1,"id":20955040,"name":"Shintaro Mochizuki"},{"status":"ACTIVE","sortPriority":2,"id":9625551,"name":"Evan Song"}],"regulators":["MR_INT"],"countryCode":"US","discountAllowed":false,"timezone":"UTC","openDate":"2021-09-13T15:00:00.000Z","version":4029632148,"name":"Match Odds","eventName":"Sh Mochizuki v E Song"},"rc":[{"batb":[[0,1.01,25]],"ltp":0.0,"tv":0.0,"id":20955040},{"batb":[[0,1.01,25]],"ltp":0.0,"tv":0.0,"id":9625551}]}]}
{"op":"mcm","clk":"4230414127","pt":1631474813916,"mc":[{"id":"1.187562121","marketDefinition":{"bspMarket":false,"turnInPlayEnabled":true,"persistenceEnabled":true,"marketBaseRate":5.0,"eventId":"30896488","eventTypeId":"2","numberOfWinners":1,"bettingType":"ODDS","marketType":"MATCH_ODDS","marketTime":"2021-09-13T15:00:00.000Z","suspendTime":"2021-09-13T15:00:00.000Z","bspReconciled":false,"complete":true,"inPlay":false,"crossMatching":false,"runnersVoidable":false,"numberOfActiveRunners":2,"betDelay":0,"status":"OPEN","runners":[{"status":"ACTIVE","sortPriority":1,"id":20955040,"name":"Shintaro Mochizuki"},{"status":"ACTIVE","sortPriority":2,"id":9625551,"name":"Evan Song"}],"regulators":["MR_INT"],"countryCode":"US","discountAllowed":false,"timezone":"UTC","openDate":"2021-09-13T15:00:00.000Z","version":4029632148,"name":"Match Odds","eventName":"Sh Mochizuki v E Song"}}]}
{"op":"mcm","clk":"4230414303","pt":1631474815927,"mc":[{"id":"1.187562121","marketDefinition":{"bspMarket":false,"turnInPlayEnabled":true,"persistenceEnabled":true,"marketBaseRate":5.0,"eventId":"30896488","eventTypeId":"2","numberOfWinners":1,"bettingType":"ODDS","marketType":"MATCH_ODDS","marketTime":"2021-09-13T15:00:00.000Z","suspendTime":"2021-09-13T15:00:00.000Z","bspReconciled":false,"complete":true,"inPlay":false,"crossMatching":false,"runnersVoidable":false,"numberOfActiveRunners":2,"betDelay":0,"status":"OPEN","runners":[{"status":"ACTIVE","sortPriority":1,"id":20955040,"name":"Shintaro Mochizuki"},{"status":"ACTIVE","sortPriority":2,"id":9625551,"name":"Evan Song"}],"regulators":["MR_INT"],"countryCode":"US","discountAllowed":true,"timezone":"UTC","openDate":"2021-09-13T15:00:00.000Z","version":4029632148,"name":"Match Odds","eventName":"Sh Mochizuki v E Song"}}]}
{"op":"mcm","clk":"4230429727","pt":1631475008362,"mc":[{"id":"1.187562121","rc":[{"batb":[[0,1.01,7]],"ltp":0.0,"tv":0.0,"id":20955040},{"batb":[[0,1.01,7]],"ltp":0.0,"tv":0.0,"id":9625551}]}]}
{"op":"mcm","clk":"4230595085","pt":1631477173460,"mc":[{"id":"1.187562121","rc":[{"batb":[[0,1.01,12]],"ltp":0.0,"tv":0.0,"id":20955040},{"batb":[[0,1.01,12]],"ltp":0.0,"tv":0.0,"id":9625551}]}]}
{"op":"mcm","clk":"4230625938","pt":1631477539496,"mc":[{"id":"1.187562121","rc":[{"batl":[[0,990,2.2]],"ltp":0.0,"tv":0.0,"id":20955040},{"batl":[[0,990,2.2]],"ltp":0.0,"tv":0.0,"id":9625551}]}]}
{"op":"mcm","clk":"4230641750","pt":1631477748463,"mc":[{"id":"1.187562121","rc":[{"batb":[[0,1.01,105.91]],"ltp":0.0,"tv":0.0,"id":20955040},{"batb":[[0,1.01,105.91]],"ltp":0.0,"tv":0.0,"id":9625551}]}]}
{"op":"mcm","clk":"4230644366","pt":1631477779788,"mc":[{"id":"1.187562121","marketDefinition":{"bspMarket":false,"turnInPlayEnabled":true,"persistenceEnabled":true,"marketBaseRate":5.0,"eventId":"30896488","eventTypeId":"2","numberOfWinners":1,"bettingType":"ODDS","marketType":"MATCH_ODDS","marketTime":"2021-09-13T15:00:00.000Z","suspendTime":"2021-09-13T15:00:00.000Z","bspReconciled":false,"complete":true,"inPlay":false,"crossMatching":true,"runnersVoidable":false,"numberOfActiveRunners":2,"betDelay":0,"status":"OPEN","runners":[{"status":"ACTIVE","sortPriority":1,"id":20955040,"name":"Shintaro Mochizuki"},{"status":"ACTIVE","sortPriority":2,"id":9625551,"name":"Evan Song"}],"regulators":["MR_INT"],"countryCode":"US","discountAllowed":true,"timezone":"UTC","openDate":"2021-09-13T15:00:00.000Z","version":4029632148,"name":"Match Odds","eventName":"Sh Mochizuki v E Song"}}]}
{"op":"mcm","clk":"4231008175","pt":1631485983070,"mc":[{"id":"1.187562121","rc":[{"batb":[[0,1.1,768.51],[1,1.01,105.93]],"ltp":0.0,"tv":0.0,"id":20955040},{"batb":[[0,1.4,768.51],[1,1.01,105.93]],"ltp":0.0,"tv":0.0,"id":9625551}]}]}
{"op":"mcm","clk":"4231008215","pt":1631485984097,"mc":[{"id":"1.187562121","rc":[{"batb":[[0,1.1,777.61]],"ltp":0.0,"tv":0.0,"id":20955040}]}]}
{"op":"mcm","clk":"4231008518","pt":1631485991391,"mc":[{"id":"1.187562121","rc":[{"batb":[[0,1.11,34.16],[1,1.1,777.61],[2,1.01,105.93]],"ltp":0.0,"tv":0.0,"id":20955040},{"batb":[[0,1.41,23.91],[1,1.4,768.51],[2,1.01,105.93]],"ltp":0.0,"tv":0.0,"id":9625551}]}]}
{"op":"mcm","clk":"4231008748","pt":1631485997175,"mc":[{"id":"1.187562121","rc":[{"batb":[[1,1.1,768.51]],"ltp":0.0,"tv":0.0,"id":20955040}]}]}
{"op":"mcm","clk":"4231009065","pt":1631486003797,"mc":[{"id":"1.187562121","rc":[{"batb":[[0,1.11,43.18]],"ltp":0.0,"tv":0.0,"id":20955040}]}]}
{"op":"mcm","clk":"4231029841","pt":1631486486822,"mc":[{"id":"1.187562121","rc":[{"batb":[[0,1.11,50.19]],"ltp":0.0,"tv":0.0,"id":20955040},{"batb":[[0,1.41,30.45]],"ltp":0.0,"tv":0.0,"id":9625551}]}]}
{"op":"mcm","clk":"4231325412","pt":1631492265609,"mc":[{"id":"1.187562121","rc":[{"batb":[[0,1.11,50.19],[1,1.1,768.38],[2,1.01,105.91]],"ltp":0.0,"tv":0.0,"id":20955040},{"batb":[[0,1.41,30.45],[1,1.4,768.38],[2,1.01,105.91]],"ltp":0.0,"tv":0.0,"id":9625551}]}]}
{"op":"mcm","clk":"4231448426","pt":1631494392623,"mc":[{"id":"1.187562121","rc":[{"batb":[[0,1.12,15.37],[1,1.11,50.19],[2,1.1,768.38]],"batl":[[0,10.5,3.42],[1,990,2.2]],"ltp":0.0,"tv":0.0,"id":20955040},{"batb":[[0,1.42,15.37],[1,1.41,30.45],[2,1.4,768.38]],"batl":[[0,14,3.42],[1,990,2.2]],"ltp":0.0,"tv":0.0,"id":9625551}]}]}
{"op":"mcm","clk":"4231589613","pt":1631497665664,"mc":[{"id":"1.187562121","rc":[{"batb":[[0,1.12,15.36],[1,1.11,50.17],[2,1.1,767.98]],"batl":[[0,10.5,3.41]],"ltp":0.0,"tv":0.0,"id":20955040},{"batb":[[0,1.42,15.36],[1,1.41,30.43],[2,1.4,767.98]],"batl":[[0,14,3.41]],"ltp":0.0,"tv":0.0,"id":9625551}]}]}
{"op":"mcm","clk":"4231751611","pt":1631503065624,"mc":[{"id":"1.187562121","rc":[{"batb":[[0,1.12,15.36],[1,1.11,50.16],[2,1.1,767.79]],"ltp":0.0,"tv":0.0,"id":20955040},{"batb":[[0,1.42,15.36],[1,1.41,30.43],[2,1.4,767.79]],"ltp":0.0,"tv":0.0,"id":9625551}]}]}
{"op":"mcm","clk":"4231991696","pt":1631510149879,"mc":[{"id":"1.187562121","rc":[{"batb":[[0,1.12,15.36],[1,1.11,50.17],[2,1.1,767.85]],"batl":[[0,3.3,42.66],[1,10.5,3.41],[2,990,2.2]],"ltp":0.0,"tv":0.0,"id":20955040},{"batb":[[0,1.42,15.36],[1,1.41,30.43],[2,1.4,767.85]],"ltp":0.0,"tv":0.0,"id":9625551}]}]}
{"op":"mcm","clk":"4231992225","pt":1631510161169,"mc":[{"id":"1.187562121","rc":[{"batl":[[0,5,42.66],[1,14,3.41],[2,990,2.2]],"ltp":0.0,"tv":0.0,"id":9625551}]}]}
{"op":"mcm","clk":"4231992516","pt":1631510167273,"mc":[{"id":"1.187562121","rc":[{"batb":[[1,1.11,41.15]],"ltp":0.0,"tv":0.0,"id":20955040}]}]}
{"op":"mcm","clk":"4231992817","pt":1631510173988,"mc":[{"id":"1.187562121","rc":[{"batb":[[0,1.25,8],[1,1.12,15.36],[2,1.11,41.15]],"ltp":0.0,"tv":0.0,"id":20955040}]}]}
{"op":"mcm","clk":"4231994162","pt":1631510200610,"mc":[{"id":"1.187562121","rc":[{"batb":[[1,1.11,41.15],[2,1.1,767.85]],"batl":[[1,990,2.2],[2,990,0]],"ltp":0.0,"tv":0.0,"id":20955040},{"batl":[[1,990,2.2],[2,990,0]],"ltp":0.0,"tv":0.0,"id":9625551}]}]}
{"op":"mcm","clk":"4231997537","pt":1631510268530,"mc":[{"id":"1.187562121","rc":[{"batb":[[0,1.26,14.5],[1,1.25,8],[2,1.11,41.15]],"batl":[[0,3.25,3.41],[1,3.3,42.66],[2,990,2.2]],"ltp":0.0,"tv":0.0,"id":20955040},{"batl":[[0,4.9,3.41],[1,5,42.66],[2,990,2.2]],"ltp":0.0,"tv":0.0,"id":9625551}]}]}
{"op":"mcm","clk":"4232044683","pt":1631511575300,"mc":[{"id":"1.187562121","rc":[{"batb":[[2,1.11,34.13]],"ltp":0.0,"tv":0.0,"id":20955040}]}]}
{"op":"mcm","clk":"4232079669","pt":1631512515660,"mc":[{"id":"1.187562121","rc":[{"batl":[[2,46,29.03]],"ltp":0.0,"tv":0.0,"id":20955040},{"batl":[[2,46,29.03]],"ltp":0.0,"tv":0.0,"id":9625551}]}]}
{"op":"mcm","clk":"4232405933","pt":1631519265609,"mc":[{"id":"1.187562121","rc":[{"batb":[[0,1.26,14.51],[2,1.11,34.13]],"batl":[[1,3.3,42.67],[2,46,29.07]],"ltp":0.0,"tv":0.0,"id":20955040},{"batb":[[0,1.42,15.36],[1,1.41,30.45],[2,1.4,767.98]],"batl":[[1,5,42.67],[2,46,29.07]],"ltp":0.0,"tv":0.0,"id":9625551}]}]}
{"op":"mcm","clk":"4232724326","pt":1631524665608,"mc":[{"id":"1.187562121","rc":[{"batb":[[0,1.26,14.51],[2,1.11,34.14]],"batl":[[1,3.3,42.67],[2,46,29.05]],"ltp":0.0,"tv":0.0,"id":20955040},{"batb":[[0,1.42,15.36],[2,1.4,768.11]],"batl":[[1,5,42.67],[2,46,29.05]],"ltp":0.0,"tv":0.0,"id":9625551}]}]}
{"op":"mcm","clk":"4232772606","pt":1631525531235,"mc":[{"id":"1.187562121","rc":[{"batl":[[0,1.8,25],[1,3.25,3.41],[2,3.3,42.67]],"ltp":0.0,"tv":0.0,"id":20955040},{"batl":[[0,2.74,25],[1,4.9,3.41],[2,5,42.67]],"ltp":0.0,"tv":0.0,"id":9625551}]}]}
{"op":"mcm","clk":"4232772673","pt":1631525532218,"mc":[{"id":"1.187562121","rc":[{"batb":[[1,1.11,34.14],[2,1.1,768.11]],"ltp":0.0,"tv":0.0,"id":20955040}]}]}
{"op":"mcm","clk":"4232773078","pt":1631525538825,"mc":[{"id":"1.187562121","rc":[{"batb":[[0,1.57,6.38],[1,1.26,14.51],[2,1.11,34.14]],"ltp":0.0,"tv":0.0,"id":20955040}]}]}
{"op":"mcm","clk":"4232774382","pt":1631525553836,"mc":[{"id":"1.187562121","rc":[{"batl":[[1,3.3,42.67],[2,46,29.05]],"ltp":0.0,"tv":0.0,"id":20955040},{"batl":[[1,5,42.67],[2,46,29.05]],"ltp":0.0,"tv":0.0,"id":9625551}]}]}
{"op":"mcm","clk":"4232774404","pt":1631525554040,"mc":[{"id":"1.187562121","rc":[{"batb":[[1,1.11,34.14],[2,1.1,768.11]],"ltp":0.0,"tv":0.0,"id":20955040}]}]}
{"op":"mcm","clk":"4232786874","pt":1631525740318,"mc":[{"id":"1.187562121","rc":[{"batb":[[0,1.57,61.33]],"ltp":0.0,"tv":0.0,"id":20955040},{"batb":[[0,2.24,25.26],[1,1.42,15.36],[2,1.41,30.45]],"ltp":0.0,"tv":0.0,"id":9625551}]}]}
{"op":"mcm","clk":"4232791587","pt":1631525831964,"mc":[{"id":"1.187562121","rc":[{"batb":[[1,1.41,30.45],[2,1.4,768.11]],"ltp":0.0,"tv":0.0,"id":9625551}]}]}
{"op":"mcm","clk":"4232806217","pt":1631526085864,"mc":[{"id":"1.187562121","rc":[{"batb":[[1,1.41,23.9]],"ltp":0.0,"tv":0.0,"id":9625551}]}]}
{"op":"mcm","clk":"4232879547","pt":1631527272053,"mc":[{"id":"1.187562121","rc":[{"batb":[[1,1.23,77.35],[2,1.17,63.86]],"ltp":0.0,"tv":0.0,"id":20955040},{"batb":[[1,1.5,39.14],[2,1.41,23.9]],"ltp":0.0,"tv":0.0,"id":9625551}]}]}
{"op":"mcm","clk":"4233188489","pt":1631531699488,"mc":[{"id":"1.187562121","rc":[{"trd":[[1.57,166.29]],"batb":[[0,1.23,77.28],[1,1.17,63.81],[2,1.11,34.07]],"batl":[[0,1.57,1040.52],[1,1.8,25],[2,3.3,42.59]],"ltp":1.57,"tv":166.28,"id":20955040},{"trd":[[2.74,25]],"batb":[[1,1.5,39.1],[2,1.41,23.85]],"batl":[[0,5,42.59],[1,46,29.02],[2,990,2.2]],"ltp":2.74,"tv":25.0,"id":9625551}],"tv":191.28}]}
{"op":"mcm","clk":"4233188585","pt":1631531700579,"mc":[{"id":"1.187562121","rc":[{"batb":[[0,1.49,63.93],[1,1.23,77.28],[2,1.17,63.81]],"ltp":1.57,"tv":166.28,"id":20955040}]}]}
{"op":"mcm","clk":"4233189154","pt":1631531707204,"mc":[{"id":"1.187562121","rc":[{"batl":[[0,1.59,1040.52]],"ltp":1.57,"tv":166.28,"id":20955040}]}]}
{"op":"mcm","clk":"4233231253","pt":1631532276881,"mc":[{"id":"1.187562121","rc":[{"batb":[[2,1.37,29.32]],"ltp":2.74,"tv":25.0,"id":9625551}]}]}
{"op":"mcm","clk":"4233231262","pt":1631532276985,"mc":[{"id":"1.187562121","rc":[{"batb":[[2,1.18,766.61]],"ltp":1.57,"tv":166.28,"id":20955040},{"batb":[[1,1.52,23.85],[2,1.51,766.61]],"ltp":2.74,"tv":25.0,"id":9625551}]}]}
{"op":"mcm","clk":"4233279689","pt":1631532911191,"mc":[{"id":"1.187562121","rc":[{"batl":[[0,5,43.44]],"ltp":2.74,"tv":25.0,"id":9625551}]}]}
{"op":"mcm","clk":"4233309437","pt":1631533273735,"mc":[{"id":"1.187562121","rc":[{"trd":[[1.59,8.4]],"batl":[[0,1.59,1036.32]],"ltp":1.59,"tv":174.69,"id":20955040}],"tv":199.69}]}
{"op":"mcm","clk":"4233465067","pt":1631535165537,"mc":[{"id":"1.187562121","rc":[{"batl":[[2,2.16,2.66]],"ltp":1.59,"tv":174.69,"id":20955040}]}]}
{"op":"mcm","clk":"4233465233","pt":1631535167017,"mc":[{"id":"1.187562121","rc":[{"batb":[[0,2.32,94.49],[1,2.24,25.26],[2,1.52,23.85]],"ltp":2.74,"tv":25.0,"id":9625551}]}]}
{"op":"mcm","clk":"4233538319","pt":1631535766786,"mc":[{"id":"1.187562121","rc":[{"batb":[[0,2.24,25.26],[1,1.52,23.85],[2,1.51,766.61]],"ltp":2.74,"tv":25.0,"id":9625551}]}]}
{"op":"mcm","clk":"4233538387","pt":1631535767514,"mc":[{"id":"1.187562121","rc":[{"batb":[[0,2.28,96.16],[1,2.24,25.26],[2,1.52,23.85]],"ltp":2.74,"tv":25.0,"id":9625551}]}]}
{"op":"mcm","clk":"4233563612","pt":1631536067604,"mc":[{"id":"1.187562121","rc":[{"batb":[[0,2.26,937.72]],"ltp":2.74,"tv":25.0,"id":9625551}]}]}
{"op":"mcm","clk":"4233563667","pt":1631536068228,"mc":[{"id":"1.187562121","rc":[{"batb":[[0,2.28,96.16]],"ltp":2.74,"tv":25.0,"id":9625551}]}]}
{"op":"mcm","clk":"4233588973","pt":1631536368462,"mc":[{"id":"1.187562121","rc":[{"batb":[[0,2.48,853.95]],"ltp":2.74,"tv":25.0,"id":9625551}]}]}
{"op":"mcm","clk":"4233589129","pt":1631536369766,"mc":[{"id":"1.187562121","rc":[{"batb":[[0,1.52,23.85],[1,1.51,766.61],[2,1.5,39.1]],"ltp":2.74,"tv":25.0,"id":9625551}]}]}
{"op":"mcm","clk":"4233589687","pt":1631536374894,"mc":[{"id":"1.187562121","rc":[{"batb":[[0,2.36,92.87],[1,2.24,25.26],[2,1.52,23.85]],"ltp":2.74,"tv":25.0,"id":9625551}]}]}
{"op":"mcm","clk":"4233617049","pt":1631536675533,"mc":[{"id":"1.187562121","rc":[{"batb":[[0,2.28,96.16]],"ltp":2.74,"tv":25.0,"id":9625551}]}]}
{"op":"mcm","clk":"4233627613","pt":1631536793067,"mc":[{"id":"1.187562121","rc":[{"batl":[[0,1.52,3.44],[1,1.59,1036.32],[2,1.8,25]],"ltp":1.59,"tv":174.69,"id":20955040}]}]}
{"op":"mcm","clk":"4233633967","pt":1631536866596,"mc":[{"id":"1.187562121","rc":[{"batb":[[0,2.24,25.26],[1,1.52,23.85],[2,1.51,766.61]],"ltp":2.74,"tv":25.0,"id":9625551}]}]}
{"op":"mcm","clk":"4233645727","pt":1631537009030,"mc":[{"id":"1.187562121","rc":[{"trd":[[1.52,6.81]],"batl":[[0,1.59,1036.34],[1,1.8,25],[2,2.16,2.66]],"ltp":1.52,"tv":181.5,"id":20955040}],"tv":206.5}]}
{"op":"mcm","clk":"4233646193","pt":1631537014805,"mc":[{"id":"1.187562121","rc":[{"trd":[[1.52,6.87]],"batb":[[0,1.52,7.71],[1,1.49,63.93],[2,1.23,77.28]],"batl":[[0,1.59,1036.32]],"ltp":1.52,"tv":181.56,"id":20955040}],"tv":206.56}]}
{"op":"mcm","clk":"4233647757","pt":1631537034605,"mc":[{"id":"1.187562121","rc":[{"batb":[[0,1.49,63.93],[1,1.23,77.28],[2,1.18,766.61]],"ltp":1.52,"tv":181.56,"id":20955040}]}]}
{"op":"mcm","clk":"4233656307","pt":1631537139534,"mc":[{"id":"1.187562121","rc":[{"batb":[[0,2.26,97.02],[1,2.24,25.26],[2,1.52,23.85]],"ltp":2.74,"tv":25.0,"id":9625551}]}]}
{"op":"mcm","clk":"4233698474","pt":1631537755961,"mc":[{"id":"1.187562121","rc":[{"batb":[[1,1.25,78.43],[2,1.23,77.28]],"ltp":1.52,"tv":181.56,"id":20955040}]}]}
{"op":"mcm","clk":"4233701893","pt":1631537811785,"mc":[{"id":"1.187562121","rc":[{"trd":[[1.59,37.4]],"batl":[[0,1.59,1021.81]],"ltp":1.59,"tv":210.56,"id":20955040}],"tv":235.56}]}
{"op":"mcm","clk":"4233713467","pt":1631538001227,"mc":[{"id":"1.187562121","rc":[{"batb":[[0,1.49,85.24]],"ltp":1.59,"tv":210.56,"id":20955040},{"batb":[[1,2.24,33.68]],"ltp":2.74,"tv":25.0,"id":9625551}]}]}
{"op":"mcm","clk":"4233725698","pt":1631538156577,"mc":[{"id":"1.187562121","rc":[{"trd":[[1.52,6.87],[1.57,166.27],[1.59,37.4]],"batb":[[1,1.25,78.38],[2,1.23,77.23]],"batl":[[0,1.59,1021.65],[2,2.16,2.66]],"ltp":1.59,"tv":210.54,"id":20955040},{"batb":[[0,2.32,94.51],[2,1.52,23.85]],"batl":[[0,5,43.43],[1,46,29]],"ltp":2.74,"tv":25.0,"id":9625551}],"tv":235.54}]}
{"op":"mcm","clk":"4233729694","pt":1631538203739,"mc":[{"id":"1.187562121","rc":[{"batl":[[0,1.57,1021.65],[1,1.74,122.52],[2,1.8,25]],"ltp":1.59,"tv":210.54,"id":20955040}]}]}
{"op":"mcm","clk":"4233729734","pt":1631538204150,"mc":[{"id":"1.187562121","rc":[{"batl":[[1,1.8,25],[2,2.16,2.66]],"ltp":1.59,"tv":210.54,"id":20955040},{"batb":[[0,2.24,33.68],[1,1.52,23.85],[2,1.51,766.48]],"ltp":2.74,"tv":25.0,"id":9625551}]}]}
{"op":"mcm","clk":"4233751716","pt":1631538444780,"mc":[{"id":"1.187562121","rc":[{"batb":[[0,2.26,126.19],[1,2.24,33.68],[2,1.52,23.85]],"ltp":2.74,"tv":25.0,"id":9625551}]}]}
{"op":"mcm","clk":"4233769853","pt":1631538640888,"mc":[{"id":"1.187562121","rc":[{"batb":[[0,2.24,33.68],[1,1.52,23.85],[2,1.51,766.48]],"ltp":2.74,"tv":25.0,"id":9625551}]}]}
{"op":"mcm","clk":"4233799451","pt":1631538911554,"mc":[{"id":"1.187562121","rc":[{"batb":[[0,2.32,100.02],[1,2.24,33.68],[2,1.52,23.85]],"ltp":2.74,"tv":25.0,"id":9625551}]}]}
{"op":"mcm","clk":"4233833796","pt":1631539211858,"mc":[{"id":"1.187562121","rc":[{"batb":[[0,2.26,102.7]],"ltp":2.74,"tv":25.0,"id":9625551}]}]}
{"op":"mcm","clk":"4233835672","pt":1631539229667,"mc":[{"id":"1.187562121","rc":[{"batl":[[0,15,3.52]],"ltp":2.74,"tv":25.0,"id":9625551}]}]}
{"op":"mcm","clk":"4233839111","pt":1631539261886,"mc":[{"id":"1.187562121","rc":[{"batb":[[1,1.27,157.31],[2,1.25,78.38]],"ltp":1.59,"tv":210.54,"id":20955040}]}]}
{"op":"mcm","clk":"4233865934","pt":1631539511902,"mc":[{"id":"1.187562121","rc":[{"batb":[[0,2.24,33.68],[1,1.52,23.85],[2,1.51,766.48]],"ltp":2.74,"tv":25.0,"id":9625551}]}]}
{"op":"mcm","clk":"4233865955","pt":1631539512097,"mc":[{"id":"1.187562121","rc":[{"batb":[[0,2.48,219.22],[1,2.24,33.68],[2,1.52,23.85]],"ltp":2.74,"tv":25.0,"id":9625551}]}]}
{"op":"mcm","clk":"4233867826","pt":1631539529803,"mc":[{"id":"1.187562121","rc":[{"batb":[[0,2.34,99.16]],"batl":[[0,7,29.02]],"ltp":2.74,"tv":25.0,"id":9625551}]}]}
{"op":"mcm","clk":"4233867866","pt":1631539530218,"mc":[{"id":"1.187562121","rc":[{"batl":[[0,15.5,3.72]],"ltp":2.74,"tv":25.0,"id":9625551}]}]}
{"op":"mcm","clk":"4233898752","pt":1631539829909,"mc":[{"id":"1.187562121","rc":[{"batl":[[0,46,29.86],[1,990,2.2],[2,990,0]],"ltp":2.74,"tv":25.0,"id":9625551}]}]}
{"op":"mcm","clk":"4233898800","pt":1631539830324,"mc":[{"id":"1.187562121","rc":[{"batl":[[0,12.5,4.41],[1,46,29],[2,990,2.2]],"ltp":2.74,"tv":25.0,"id":9625551}]}]}
{"op":"mcm","clk":"4233899852","pt":1631539840567,"mc":[{"id":"1.187562121","rc":[{"batb":[[0,2.38,97.48]],"ltp":2.74,"tv":25.0,"id":9625551}]}]}
{"op":"mcm","clk":"4233924826","pt":1631540096570,"mc":[{"id":"1.187562121","rc":[{"batl":[[0,1.56,1021.65]],"ltp":1.59,"tv":210.54,"id":20955040},{"batb":[[0,2.26,25.43]],"ltp":2.74,"tv":25.0,"id":9625551}]}]}
{"op":"mcm","clk":"4233931096","pt":1631540156644,"mc":[{"id":"1.187562121","rc":[{"trd":[[1.56,19.51]],"batl":[[0,1.56,1011.89]],"ltp":1.56,"tv":230.05,"id":20955040}],"tv":255.05}]}
{"op":"mcm","clk":"4233949266","pt":1631540356970,"mc":[{"id":"1.187562121","rc":[{"batl":[[2,2.1,43.7]],"ltp":1.56,"tv":230.05,"id":20955040}]}]}
{"op":"mcm","clk":"4233952695","pt":1631540396716,"mc":[{"id":"1.187562121","rc":[{"batb":[[0,2.28,914.03]],"ltp":2.74,"tv":25.0,"id":9625551}]}]}
{"op":"mcm","clk":"4233952884","pt":1631540399138,"mc":[{"id":"1.187562121","rc":[{"batb":[[1,1.52,23.85],[2,1.51,766.48]],"ltp":2.74,"tv":25.0,"id":9625551}]}]}
{"op":"mcm","clk":"4234049155","pt":1631541601374,"mc":[{"id":"1.187562121","rc":[{"batb":[[1,1.47,27.18],[2,1.27,157.31]],"ltp":1.56,"tv":230.05,"id":20955040},{"batb":[[0,2.76,7.26]],"ltp":2.74,"tv":25.0,"id":9625551}]}]}
{"op":"mcm","clk":"4234049600","pt":1631541606593,"mc":[{"id":"1.187562121","rc":[{"batb":[[1,2.24,33.68],[2,1.52,23.85]],"ltp":2.74,"tv":25.0,"id":9625551}]}]}
{"op":"mcm","clk":"4234051619","pt":1631541630626,"mc":[{"id":"1.187562121","rc":[{"batl":[[0,8.6,24.15]],"ltp":2.74,"tv":25.0,"id":9625551}]}]}
{"op":"mcm","clk":"4234062007","pt":1631541757669,"mc":[{"id":"1.187562121","rc":[{"batl":[[0,1.56,1024.67]],"ltp":1.56,"tv":230.05,"id":20955040}]}]}
{"op":"mcm","clk":"4234078323","pt":1631541930770,"mc":[{"id":"1.187562121","rc":[{"batl":[[0,6,41.31]],"ltp":2.74,"tv":25.0,"id":9625551}]}]}
{"op":"mcm","clk":"4234139932","pt":1631542545340,"mc":[{"id":"1.187562121","rc":[{"batl":[[1,1.6,2.06],[2,1.8,25]],"ltp":1.56,"tv":230.05,"id":20955040}]}]}
{"op":"mcm","clk":"4234146211","pt":1631542610840,"mc":[{"id":"1.187562121","rc":[{"batb":[[2,1.28,182.49]],"ltp":1.56,"tv":230.05,"id":20955040},{"batl":[[0,46,29.86],[1,990,2.2],[2,990,0]],"ltp":2.74,"tv":25.0,"id":9625551}]}]}
{"op":"mcm","clk":"4234146222","pt":1631542610944,"mc":[{"id":"1.187562121","rc":[{"batl":[[0,10.5,8.86],[1,46,29],[2,990,2.2]],"ltp":2.74,"tv":25.0,"id":9625551}]}]}
{"op":"mcm","clk":"4234146723","pt":1631542616458,"mc":[{"id":"1.187562121","rc":[{"batb":[[2,1.55,154.85]],"ltp":2.74,"tv":25.0,"id":9625551}]}]}
{"op":"mcm","clk":"4234166865","pt":1631542830682,"mc":[{"id":"1.187562121","rc":[{"batl":[[0,5.7,41.67]],"ltp":2.74,"tv":25.0,"id":9625551}]}]}
{"op":"mcm","clk":"4234260134","pt":1631543724424,"mc":[{"id":"1.187562121","rc":[{"batl":[[0,1.53,2.5],[1,1.56,1024.67],[2,1.6,2.06]],"ltp":1.56,"tv":230.05,"id":20955040}]}]}
{"op":"mcm","clk":"4234263091","pt":1631543747666,"mc":[{"id":"1.187562121","rc":[{"batl":[[0,1.56,1024.67],[1,1.6,2.06],[2,1.8,25]],"ltp":1.56,"tv":230.05,"id":20955040}]}]}
{"op":"mcm","clk":"4234264490","pt":1631543759151,"mc":[{"id":"1.187562121","rc":[{"trd":[[1.49,1.58],[1.5,1.71]],"batb":[[0,1.49,84.45]],"ltp":1.49,"tv":233.34,"id":20955040},{"trd":[[3,0.85]],"batl":[[0,5.7,40.82]],"ltp":3.0,"tv":25.85,"id":9625551}],"tv":259.2}]}
{"op":"mcm","clk":"4234265027","pt":1631543762995,"mc":[{"id":"1.187562121","rc":[{"batb":[[0,1.49,85.24]],"ltp":1.49,"tv":233.34,"id":20955040}]}]}
{"op":"mcm","clk":"4234294164","pt":1631544008837,"mc":[{"id":"1.187562121","rc":[{"batb":[[1,1.47,32.99]],"ltp":1.49,"tv":233.34,"id":20955040}]}]}
{"op":"mcm","clk":"4234294169","pt":1631544008938,"mc":[{"id":"1.187562121","rc":[{"batb":[[1,2.72,1.72],[2,2.24,33.68]],"ltp":3.0,"tv":25.85,"id":9625551}]}]}
{"op":"mcm","clk":"4234302249","pt":1631544088843,"mc":[{"id":"1.187562121","rc":[{"batb":[[2,1.3,157.31]],"ltp":1.49,"tv":233.34,"id":20955040}]}]}
{"op":"mcm","clk":"4234302324","pt":1631544089524,"mc":[{"id":"1.187562121","rc":[{"batl":[[0,10.5,2.49]],"ltp":3.0,"tv":25.85,"id":9625551}]}]}
{"op":"mcm","clk":"4234326837","pt":1631544330684,"mc":[{"id":"1.187562121","rc":[{"batl":[[0,5.7,38.64]],"ltp":3.0,"tv":25.85,"id":9625551}]}]}
{"op":"mcm","clk":"4234334417","pt":1631544398780,"mc":[{"id":"1.187562121","rc":[{"batl":[[0,1.54,1011.89],[1,1.56,12.77],[2,1.6,2.06]],"ltp":1.49,"tv":233.34,"id":20955040},{"batl":[[0,11,2.38]],"ltp":3.0,"tv":25.85,"id":9625551}]}]}
{"op":"mcm","clk":"4234334459","pt":1631544399045,"mc":[{"id":"1.187562121","rc":[{"batb":[[0,2.8,7.09],[1,2.76,7.26],[2,2.72,1.72]],"ltp":3.0,"tv":25.85,"id":9625551}]}]}
{"op":"mcm","clk":"4234348322","pt":1631544539961,"mc":[{"id":"1.187562121","rc":[{"batl":[[0,1.52,2.55],[1,1.54,1011.89],[2,1.56,12.77]],"ltp":1.49,"tv":233.34,"id":20955040}]}]}
{"op":"mcm","clk":"4234348600","pt":1631544543428,"mc":[{"id":"1.187562121","rc":[{"batl":[[0,1.51,2.55]],"ltp":1.49,"tv":233.34,"id":20955040}]}]}
{"op":"mcm","clk":"4234348705","pt":1631544544733,"mc":[{"id":"1.187562121","rc":[{"batb":[[1,1.47,5.81],[2,1.44,29.03]],"ltp":1.49,"tv":233.34,"id":20955040},{"batl":[[0,46,29],[1,990,2.2],[2,990,0]],"ltp":3.0,"tv":25.85,"id":9625551}]}]}
{"op":"mcm","clk":"4234348740","pt":1631544545208,"mc":[{"id":"1.187562121","rc":[{"batl":[[0,4.3,6.22],[1,46,29],[2,990,2.2]],"ltp":3.0,"tv":25.85,"id":9625551}]}]}
{"op":"mcm","clk":"4234348843","pt":1631544546551,"mc":[{"id":"1.187562121","rc":[{"batl":[[0,1.5,2.55]],"ltp":1.49,"tv":233.34,"id":20955040}]}]}
{"op":"mcm","clk":"4234349149","pt":1631544549844,"mc":[{"id":"1.187562121","rc":[{"batl":[[0,1.54,1011.89],[1,1.56,12.77],[2,1.6,2.06]],"ltp":1.49,"tv":233.34,"id":20955040}]}]}
{"op":"mcm","clk":"4234349176","pt":1631544550251,"mc":[{"id":"1.187562121","rc":[{"trd":[[1.49,6.69]],"batb":[[0,1.49,82.68],[1,1.47,32.99]],"ltp":1.49,"tv":238.46,"id":20955040}],"tv":264.31}]}
{"op":"mcm","clk":"4234349526","pt":1631544554629,"mc":[{"id":"1.187562121","rc":[{"batb":[[0,1.49,85.24]],"ltp":1.49,"tv":238.46,"id":20955040}]}]}
{"op":"mcm","clk":"4234377983","pt":1631544900460,"mc":[{"id":"1.187562121","rc":[{"trd":[[1.49,12.51]],"batb":[[0,1.49,82.33]],"ltp":1.49,"tv":244.28,"id":20955040}],"tv":270.13}]}
{"op":"mcm","clk":"4234378299","pt":1631544904090,"mc":[{"id":"1.187562121","rc":[{"batb":[[0,1.49,85.24]],"ltp":1.49,"tv":244.28,"id":20955040}]}]}
{"op":"mcm","clk":"4234378447","pt":1631544905760,"mc":[{"id":"1.187562121","rc":[{"trd":[[1.54,8.87]],"batl":[[0,1.54,1007.46]],"ltp":1.54,"tv":253.15,"id":20955040}],"tv":279.0}]}
{"op":"mcm","clk":"4234379721","pt":1631544921788,"mc":[{"id":"1.187562121","rc":[{"trd":[[1.54,14.31]],"batl":[[0,1.54,1004.74]],"ltp":1.54,"tv":258.59,"id":20955040}],"tv":284.44}]}
{"op":"mcm","clk":"4234380577","pt":1631544933609,"mc":[{"id":"1.187562121","rc":[{"batb":[[2,1.4,375]],"ltp":1.54,"tv":258.59,"id":20955040},{"trd":[[2.9,5.69]],"batb":[[0,2.76,7.26],[1,2.72,1.72],[2,2.56,96.15]],"batl":[[0,2.9,50.81]],"ltp":2.9,"tv":31.54,"id":9625551}],"tv":290.14}]}
{"op":"mcm","clk":"4234381593","pt":1631544948561,"mc":[{"id":"1.187562121","rc":[{"trd":[[1.54,27.72]],"batb":[[1,1.48,26.61],[2,1.47,32.99]],"batl":[[0,1.54,998.04]],"ltp":1.54,"tv":272.0,"id":20955040}],"tv":303.55}]}
{"op":"mcm","clk":"4234385735","pt":1631545007956,"mc":[{"id":"1.187562121","marketDefinition":{"bspMarket":false,"turnInPlayEnabled":true,"persistenceEnabled":true,"marketBaseRate":5.0,"eventId":"30896488","eventTypeId":"2","numberOfWinners":1,"bettingType":"ODDS","marketType":"MATCH_ODDS","marketTime":"2021-09-13T14:56:00.000Z","suspendTime":"2021-09-13T14:56:00.000Z","bspReconciled":false,"complete":true,"inPlay":false,"crossMatching":true,"runnersVoidable":false,"numberOfActiveRunners":2,"betDelay":0,"status":"OPEN","runners":[{"status":"ACTIVE","sortPriority":1,"id":20955040,"name":"Shintaro Mochizuki"},{"status":"ACTIVE","sortPriority":2,"id":9625551,"name":"Evan Song"}],"regulators":["MR_INT"],"countryCode":"US","discountAllowed":true,"timezone":"UTC","openDate":"2021-09-13T15:00:00.000Z","version":4030797384,"name":"Match Odds","eventName":"Sh Mochizuki v E Song"}}]}
{"op":"mcm","clk":"4234386465","pt":1631545017767,"mc":[{"id":"1.187562121","rc":[{"trd":[[1.52,103.81]],"batl":[[0,1.52,901.1]],"ltp":1.52,"tv":368.94,"id":20955040},{"trd":[[2.9,56.5]],"batl":[[0,46,29],[1,990,2.2],[2,990,0]],"ltp":2.9,"tv":82.35,"id":9625551}],"tv":451.3}]}
{"op":"mcm","clk":"4234386530","pt":1631545018656,"mc":[{"id":"1.187562121","rc":[{"batb":[[1,1.47,5.81],[2,1.46,27.77]],"ltp":1.52,"tv":368.94,"id":20955040},{"batb":[[0,2.84,6.94],[1,2.76,7.26],[2,2.72,1.72]],"batl":[[0,5,4.65],[1,46,29],[2,990,2.2]],"ltp":2.9,"tv":82.35,"id":9625551}]}]}
{"op":"mcm","clk":"4234386564","pt":1631545019126,"mc":[{"id":"1.187562121","rc":[{"batl":[[0,4.6,5.13]],"ltp":2.9,"tv":82.35,"id":9625551}]}]}
{"op":"mcm","clk":"4234386653","pt":1631545020214,"mc":[{"id":"1.187562121","marketDefinition":{"bspMarket":false,"turnInPlayEnabled":true,"persistenceEnabled":true,"marketBaseRate":5.0,"eventId":"30896488","eventTypeId":"2","numberOfWinners":1,"bettingType":"ODDS","marketType":"MATCH_ODDS","marketTime":"2021-09-13T14:56:00.000Z","suspendTime":"2021-09-13T14:56:00.000Z","bspReconciled":false,"complete":true,"inPlay":false,"crossMatching":true,"runnersVoidable":false,"numberOfActiveRunners":2,"betDelay":0,"status":"OPEN","runners":[{"status":"ACTIVE","sortPriority":1,"id":20955040,"name":"Shintaro Mochizuki"},{"status":"ACTIVE","sortPriority":2,"id":9625551,"name":"Evan Song"}],"regulators":["MR_INT"],"countryCode":"US","discountAllowed":true,"timezone":"UTC","openDate":"2021-09-13T14:56:00.000Z","version":4030797384,"name":"Match Odds","eventName":"Sh Mochizuki v E Song"},"rc":[{"batl":[[0,46,29],[1,990,2.2],[2,990,0]],"ltp":2.9,"tv":82.35,"id":9625551}]}]}
{"op":"mcm","clk":"4234387175","pt":1631545026867,"mc":[{"id":"1.187562121","rc":[{"batl":[[0,5.5,4.29],[1,46,29],[2,990,2.2]],"ltp":2.9,"tv":82.35,"id":9625551}]}]}
{"op":"mcm","clk":"4234387733","pt":1631545034490,"mc":[{"id":"1.187562121","rc":[{"batl":[[0,1.52,903.1]],"ltp":1.52,"tv":368.94,"id":20955040},{"batl":[[0,3.05,2]],"ltp":2.9,"tv":82.35,"id":9625551}]}]}
{"op":"mcm","clk":"4234389560","pt":1631545061716,"mc":[{"id":"1.187562121","rc":[{"trd":[[1.49,12.71]],"batb":[[0,1.49,85.14]],"ltp":1.49,"tv":369.14,"id":20955040}],"tv":451.5}]}
{"op":"mcm","clk":"4234389888","pt":1631545066510,"mc":[{"id":"1.187562121","rc":[{"batb":[[0,1.49,85.24]],"ltp":1.49,"tv":369.14,"id":20955040}]}]}
{"op":"mcm","clk":"4234393045","pt":1631545112681,"mc":[{"id":"1.187562121","rc":[{"batb":[[2,2.74,17.99]],"ltp":2.9,"tv":82.35,"id":9625551}]}]}
{"op":"mcm","clk":"4234394124","pt":1631545126993,"mc":[{"id":"1.187562121","rc":[{"batl":[[1,3.8,2.58],[2,46,29]],"ltp":2.9,"tv":82.35,"id":9625551}]}]}
{"op":"mcm","clk":"4234403323","pt":1631545246807,"mc":[{"id":"1.187562121","rc":[{"trd":[[1.49,12.72],[1.52,107.22],[1.54,27.74],[1.56,19.52],[1.57,166.4],[1.59,37.42]],"batb":[[2,1.46,27.81]],"batl":[[0,1.52,900.94],[1,1.56,12.79]],"ltp":1.52,"tv":372.72,"id":20955040},{"trd":[[2.9,56.57],[2.92,1.71],[3,0.85]],"batb":[[0,2.84,6.95],[1,2.76,7.26],[2,2.74,18.03]],"batl":[[1,3.8,2.58],[2,46,28.97]],"ltp":2.92,"tv":84.12,"id":9625551}],"tv":456.85}]}
{"op":"mcm","clk":"4234407600","pt":1631545299858,"mc":[{"id":"1.187562121","rc":[{"batb":[[0,1.47,5.81],[1,1.46,27.81],[2,1.44,69.79]],"ltp":1.52,"tv":372.72,"id":20955040}]}]}
{"op":"mcm","clk":"4234407693","pt":1631545300846,"mc":[{"id":"1.187562121","rc":[{"batb":[[0,1.48,13.29],[1,1.47,5.81],[2,1.44,98.86]],"ltp":1.52,"tv":372.72,"id":20955040},{"batb":[[1,2.74,18.03],[2,2.72,1.72]],"ltp":2.92,"tv":84.12,"id":9625551}]}]}
{"op":"mcm","clk":"4234411036","pt":1631545339463,"mc":[{"id":"1.187562121","rc":[{"batl":[[0,1.49,2.66],[1,1.52,900.94],[2,1.56,12.79]],"ltp":1.52,"tv":372.72,"id":20955040}]}]}
{"op":"mcm","clk":"4234411078","pt":1631545339981,"mc":[{"id":"1.187562121","rc":[{"batb":[[2,1.44,69.79]],"ltp":1.52,"tv":372.72,"id":20955040},{"batb":[[0,2.9,6.73],[1,2.84,6.95],[2,2.74,18.03]],"ltp":2.92,"tv":84.12,"id":9625551}]}]}
{"op":"mcm","clk":"4234413054","pt":1631545361706,"mc":[{"id":"1.187562121","rc":[{"trd":[[1.49,18.04],[1.52,1824.27]],"batl":[[0,1.52,42.41],[1,1.56,12.79],[2,1.6,2.06]],"ltp":1.52,"tv":2095.1,"id":20955040}],"tv":2179.22}]}
{"op":"mcm","clk":"4234413081","pt":1631545362117,"mc":[{"id":"1.187562121","rc":[{"batb":[[2,1.44,98.86]],"ltp":1.52,"tv":2095.1,"id":20955040},{"trd":[[3.05,4]],"batl":[[0,3.7,14.06]],"ltp":3.05,"tv":88.12,"id":9625551}],"tv":2183.23}]}
{"op":"mcm","clk":"4234413993","pt":1631545372439,"mc":[{"id":"1.187562121","rc":[{"trd":[[1.48,1.18]],"batb":[[0,1.48,12.7]],"ltp":1.48,"tv":2096.28,"id":20955040}],"tv":2184.41}]}
{"op":"mcm","clk":"4234417265","pt":1631545411336,"mc":[{"id":"1.187562121","rc":[{"trd":[[1.52,1863.49]],"batl":[[0,1.52,22.8]],"ltp":1.52,"tv":2135.5,"id":20955040}],"tv":2223.63}]}
{"op":"mcm","clk":"4234425868","pt":1631545517613,"mc":[{"id":"1.187562121","rc":[{"batl":[[0,1.52,1169.51]],"ltp":1.52,"tv":2135.5,"id":20955040}]}]}
{"op":"mcm","clk":"4234432499","pt":1631545615553,"mc":[{"id":"1.187562121","marketDefinition":{"bspMarket":false,"turnInPlayEnabled":true,"persistenceEnabled":true,"marketBaseRate":5.0,"eventId":"30896488","eventTypeId":"2","numberOfWinners":1,"bettingType":"ODDS","marketType":"MATCH_ODDS","marketTime":"2021-09-13T14:56:00.000Z","suspendTime":"2021-09-13T14:56:00.000Z","bspReconciled":false,"complete":true,"inPlay":true,"crossMatching":true,"runnersVoidable":false,"numberOfActiveRunners":2,"betDelay":3,"status":"OPEN","runners":[{"status":"ACTIVE","sortPriority":1,"id":20955040,"name":"Shintaro Mochizuki"},{"status":"ACTIVE","sortPriority":2,"id":9625551,"name":"Evan Song"}],"regulators":["MR_INT"],"countryCode":"US","discountAllowed":true,"timezone":"UTC","openDate":"2021-09-13T14:56:00.000Z","version":4030811179,"name":"Match Odds","eventName":"Sh Mochizuki v E Song"},"rc":[{"batb":[[0,1.17,42.47],[1,1.01,577.96],[2,1.44,0]],"batl":[[0,1.52,1167.51],[2,1.6,0]],"ltp":1.52,"tv":2135.5,"id":20955040},{"batb":[[0,1.46,3.41],[1,1.37,19.51],[2,1.01,577.96]],"ltp":3.05,"tv":88.12,"id":9625551}]}]}
{"op":"mcm","clk":"4234434287","pt":1631545641147,"mc":[{"id":"1.187562121","rc":[{"batb":[[0,1.5,6.89],[1,1.17,42.47],[2,1.01,577.96]],"batl":[[1,1.54,380.83],[2,1.56,12.79]],"ltp":1.52,"tv":2135.5,"id":20955040},{"batb":[[0,2.88,10.69],[1,1.46,3.41],[2,1.37,19.51]],"batl":[[0,3,3.45],[1,3.05,178.48]],"ltp":3.05,"tv":88.12,"id":9625551}]}]}
{"op":"mcm","clk":"4234434395","pt":1631545642643,"mc":[{"id":"1.187562121","rc":[{"batb":[[1,1.4,78.93],[2,1.37,86.06]],"ltp":1.52,"tv":2135.5,"id":20955040},{"batb":[[0,2.9,39.09],[1,2.88,10.69],[2,2.7,19.04]],"ltp":3.05,"tv":88.12,"id":9625551}]}]}
{"op":"mcm","clk":"4234434639","pt":1631545646251,"mc":[{"id":"1.187562121","rc":[{"trd":[[1.5,22.39]],"batb":[[0,1.4,78.93],[1,1.37,86.06],[2,1.17,42.47]],"ltp":1.5,"tv":2156.18,"id":20955040},{"trd":[[3,4.3]],"batl":[[0,3.05,178.48],[1,3.05,0]],"ltp":3.0,"tv":91.57,"id":9625551}],"tv":2247.76}]}
{"op":"mcm","clk":"4234434825","pt":1631545649259,"mc":[{"id":"1.187562121","rc":[{"batb":[[0,1.41,13.98],[1,1.4,78.93],[2,1.37,86.06]],"ltp":1.5,"tv":2156.18,"id":20955040}]}]}
{"op":"mcm","clk":"4234435188","pt":1631545655390,"mc":[{"id":"1.187562121","rc":[{"batb":[[0,1.37,86.06],[1,1.17,42.47],[2,1.01,577.96]],"batl":[[1,1.56,12.79],[2,1.56,0]],"ltp":1.5,"tv":2156.18,"id":20955040},{"batb":[[0,2.7,19.04],[1,1.46,3.41],[2,1.37,19.51]],"ltp":3.0,"tv":91.57,"id":9625551}]}]}
{"op":"mcm","clk":"4234435740","pt":1631545663672,"mc":[{"id":"1.187562121","rc":[{"trd":[[1.45,13.88]],"batb":[[0,1.45,432.47],[1,1.37,86.06],[2,1.17,42.47]],"batl":[[0,1.52,1832.61]],"ltp":1.45,"tv":2170.06,"id":20955040},{"batb":[[0,3.1,5.57],[1,2.7,19.04],[2,1.46,3.41]],"batl":[[0,3.2,6.84]],"ltp":3.0,"tv":91.57,"id":9625551}],"tv":2261.64}]}
{"op":"mcm","clk":"4234435810","pt":1631545664809,"mc":[{"id":"1.187562121","rc":[{"batb":[[2,1.35,92.69]],"ltp":1.45,"tv":2170.06,"id":20955040},{"batb":[[1,3,34.98],[2,2.84,41.02]],"batl":[[1,3.8,2.63]],"ltp":3.0,"tv":91.57,"id":9625551}]}]}
{"op":"mcm","clk":"4234436547","pt":1631545675693,"mc":[{"id":"1.187562121","rc":[{"batb":[[0,1.37,86.06],[1,1.35,92.69],[2,1.17,42.47]],"batl":[[0,1.52,1167.51]],"ltp":1.45,"tv":2170.06,"id":20955040},{"batb":[[0,3,34.98],[1,2.84,41.02],[2,1.46,3.41]],"ltp":3.0,"tv":91.57,"id":9625551}]}]}
{"op":"mcm","clk":"4234436573","pt":1631545676103,"mc":[{"id":"1.187562121","rc":[{"batb":[[0,1.35,92.69],[1,1.17,42.47],[2,1.01,577.96]],"ltp":1.45,"tv":2170.06,"id":20955040},{"batb":[[0,2.84,41.02],[1,1.46,3.41],[2,1.37,19.51]],"ltp":3.0,"tv":91.57,"id":9625551}]}]}
{"op":"mcm","clk":"4234436863","pt":1631545680624,"mc":[{"id":"1.187562121","rc":[{"trd":[[1.35,50]],"batb":[[0,1.35,67.69]],"ltp":1.35,"tv":2220.06,"id":20955040}],"tv":2311.64}]}
{"op":"mcm","clk":"4234437103","pt":1631545684425,"mc":[{"id":"1.187562121","rc":[{"trd":[[1.42,7.04]],"batb":[[0,1.43,16.39],[1,1.35,67.69],[2,1.17,42.47]],"batl":[[0,1.45,10.26],[1,1.46,20.54],[2,1.47,10.28]],"ltp":1.42,"tv":2227.1,"id":20955040},{"trd":[[3.35,2.98]],"batl":[[0,3.35,200.95]],"ltp":3.35,"tv":94.55,"id":9625551}],"tv":2321.66}]}
{"op":"mcm","clk":"4234437208","pt":1631545685691,"mc":[{"id":"1.187562121","rc":[{"batb":[[2,1.33,98.73]],"ltp":1.42,"tv":2227.1,"id":20955040},{"batb":[[0,3.15,31.37],[1,3,35.57],[2,1.46,3.41]],"batl":[[1,3.95,2.53],[2,4.7,6.38]],"ltp":3.35,"tv":94.55,"id":9625551}]}]}
{"op":"mcm","clk":"4234437558","pt":1631545691195,"mc":[{"id":"1.187562121","rc":[{"trd":[[1.45,24.14]],"batl":[[0,1.46,20.54],[1,1.47,10.28],[2,1.48,420.2]],"ltp":1.45,"tv":2237.36,"id":20955040},{"trd":[[3.15,40.7],[3.2,4.65]],"batb":[[0,3.15,11.02]],"ltp":3.15,"tv":139.9,"id":9625551}],"tv":2377.27}]}
{"op":"mcm","clk":"4234437678","pt":1631545692911,"mc":[{"id":"1.187562121","rc":[{"trd":[[1.44,20.02]],"batb":[[0,1.33,98.73],[1,1.17,42.47],[2,1.01,577.96]],"batl":[[0,1.52,1167.51],[1,1.56,12.79],[2,1.48,0]],"ltp":1.44,"tv":2257.38,"id":20955040},{"batb":[[0,3,35.57],[1,1.46,3.41],[2,1.37,19.51]],"ltp":3.15,"tv":139.9,"id":9625551}],"tv":2397.29}]}
{"op":"mcm","clk":"4234437873","pt":1631545695527,"mc":[{"id":"1.187562121","rc":[{"batb":[[0,1.34,97.13]],"ltp":1.44,"tv":2257.38,"id":20955040},{"batb":[[0,2.98,36.32]],"ltp":3.15,"tv":139.9,"id":9625551}]}]}
{"op":"mcm","clk":"4234438792","pt":1631545707320,"mc":[{"id":"1.187562121","rc":[{"batb":[[0,1.43,139.86],[1,1.34,97.13],[2,1.17,42.47]],"batl":[[0,1.5,7],[1,1.52,1553.55],[2,1.56,12.79]],"ltp":1.44,"tv":2257.38,"id":20955040},{"batb":[[0,3,3.5],[1,2.98,36.32],[2,1.46,3.41]],"batl":[[0,3.1,6.36],[1,3.3,498.38],[2,3.75,2.67]],"ltp":3.15,"tv":139.9,"id":9625551}]}]}
{"op":"mcm","clk":"4234438868","pt":1631545708415,"mc":[{"id":"1.187562121","rc":[{"trd":[[1.47,6.9]],"batb":[[1,1.39,83.71],[2,1.37,89.92]],"ltp":1.47,"tv":2264.28,"id":20955040},{"trd":[[3.1,3.27]],"batb":[[2,2.9,10.34]],"batl":[[0,3.1,3.09]],"ltp":3.1,"tv":143.17,"id":9625551}],"tv":2407.46}]}
{"op":"mcm","clk":"4234439077","pt":1631545711848,"mc":[{"id":"1.187562121","rc":[{"batl":[[0,1.5,127]],"ltp":1.47,"tv":2264.28,"id":20955040}]}]}
{"op":"mcm","clk":"4234439143","pt":1631545712833,"mc":[{"id":"1.187562121","rc":[{"trd":[[1.47,13.41]],"batl":[[0,1.5,7]],"ltp":1.47,"tv":2270.79,"id":20955040},{"trd":[[3.1,6.36]],"batl":[[0,3.3,498.38],[1,3.75,2.67],[2,3.8,7.9]],"ltp":3.1,"tv":146.26,"id":9625551}],"tv":2417.06}]}
{"op":"mcm","clk":"4234439426","pt":1631545716865,"mc":[{"id":"1.187562121","rc":[{"batl":[[0,1.52,1167.51],[1,1.56,12.79],[2,1.56,0]],"ltp":1.47,"tv":2270.79,"id":20955040},{"batb":[[0,2.98,36.32],[1,2.9,10.34],[2,2.88,5.18]],"batl":[[0,3.8,7.9],[1,3.85,3.94],[2,3.9,3.94]],"ltp":3.1,"tv":146.26,"id":9625551}]}]}
{"op":"mcm","clk":"4234439467","pt":1631545717432,"mc":[{"id":"1.187562121","rc":[{"batb":[[0,1.37,89.92],[1,1.17,42.47],[2,1.05,477.24]],"ltp":1.47,"tv":2270.79,"id":20955040},{"batb":[[0,2.8,42.69],[1,1.8,11.93],[2,1.46,3.41]],"ltp":3.1,"tv":146.26,"id":9625551}]}]}
{"op":"mcm","clk":"4234439697","pt":1631545720444,"mc":[{"id":"1.187562121","rc":[{"batb":[[2,1.11,271.16]],"ltp":1.47,"tv":2270.79,"id":20955040}]}]}
{"op":"mcm","clk":"4234441532","pt":1631545748488,"mc":[{"id":"1.187562121","rc":[{"batb":[[0,1.5,20],[1,1.49,144.22],[2,1.48,10]],"batl":[[1,1.54,15.23],[2,1.56,12.79]],"ltp":1.47,"tv":2270.79,"id":20955040},{"batl":[[0,2.96,197.87],[1,3.5,2.86]],"ltp":3.1,"tv":146.26,"id":9625551}]}]}
{"op":"mcm","clk":"4234441638","pt":1631545749885,"mc":[{"id":"1.187562121","rc":[{"trd":[[1.51,6.71]],"ltp":1.51,"tv":2277.5,"id":20955040},{"trd":[[2.96,3.42]],"batb":[[1,2.78,10.8],[2,2.76,5.4]],"batl":[[0,2.96,194.45]],"ltp":2.96,"tv":149.68,"id":9625551}],"tv":2427.19}]}
{"op":"mcm","clk":"4234441857","pt":1631545752894,"mc":[{"id":"1.187562121","rc":[{"trd":[[1.52,1992.49]],"batl":[[0,1.52,1038.51]],"ltp":1.52,"tv":2406.51,"id":20955040},{"trd":[[2.92,68.86]],"ltp":2.92,"tv":216.83,"id":9625551}],"tv":2623.34}]}
{"op":"mcm","clk":"4234441900","pt":1631545753519,"mc":[{"id":"1.187562121","rc":[{"trd":[[1.51,104.98]],"ltp":1.51,"tv":2504.78,"id":20955040},{"trd":[[2.96,53.55]],"batl":[[0,2.96,144.32]],"ltp":2.96,"tv":266.96,"id":9625551}],"tv":2771.74}]}
{"op":"mcm","clk":"4234442087","pt":1631545756780,"mc":[{"id":"1.187562121","rc":[{"batl":[[0,1.52,1223.51]],"ltp":1.51,"tv":2504.78,"id":20955040}]}]}
{"op":"mcm","clk":"4234442388","pt":1631545761194,"mc":[{"id":"1.187562121","rc":[{"trd":[[1.52,2009.82]],"batl":[[0,1.52,1214.85]],"ltp":1.52,"tv":2522.1,"id":20955040}],"tv":2789.07}]}
{"op":"mcm","clk":"4234442735","pt":1631545766627,"mc":[{"id":"1.187562121","rc":[{"batb":[[0,1.39,83.21],[1,1.2,387.76],[2,1.17,42.47]],"batl":[[1,1.56,12.79],[2,1.56,0]],"ltp":1.52,"tv":2522.1,"id":20955040},{"batb":[[0,2.58,21.56],[1,1.8,11.93],[2,1.7,17.05]],"ltp":2.96,"tv":266.96,"id":9625551}]}]}
{"op":"mcm","clk":"4234442756","pt":1631545766932,"mc":[{"id":"1.187562121","rc":[{"batl":[[0,1.52,1029.85]],"ltp":1.52,"tv":2522.1,"id":20955040}]}]}
{"op":"mcm","clk":"4234442900","pt":1631545769528,"mc":[{"id":"1.187562121","rc":[{"batb":[[1,1.25,238.62],[2,1.2,387.76]],"ltp":1.52,"tv":2522.1,"id":20955040}]}]}
{"op":"mcm","clk":"4234444310","pt":1631545792341,"mc":[{"id":"1.187562121","rc":[{"trd":[[1.45,37.94]],"batb":[[0,1.47,8.45],[1,1.39,83.21],[2,1.25,238.62]],"batl":[[0,1.49,20.14],[1,1.5,19.92],[2,1.51,10.06]],"ltp":1.45,"tv":2535.9,"id":20955040},{"batb":[[0,3,4.93],[1,2.92,186.15],[2,2.58,21.56]],"batl":[[0,3.15,175.91]],"ltp":2.96,"tv":266.96,"id":9625551}],"tv":2802.87}]}
{"op":"mcm","clk":"4234444410","pt":1631545793737,"mc":[{"id":"1.187562121","rc":[{"batb":[[2,1.34,98.89]],"ltp":1.45,"tv":2535.9,"id":20955040},{"batb":[[1,2.98,36.57],[2,2.92,186.15]],"batl":[[1,3.3,9.08],[2,3.35,4.54]],"ltp":2.96,"tv":266.96,"id":9625551}]}]}
{"op":"mcm","clk":"4234444611","pt":1631545797115,"mc":[{"id":"1.187562121","rc":[{"trd":[[1.46,49.35],[1.47,30.31]],"batb":[[0,1.39,83.21],[1,1.34,98.89],[2,1.25,238.62]],"ltp":1.46,"tv":2602.15,"id":20955040},{"trd":[[3.15,63.57]],"batl":[[0,3.15,153.04]],"ltp":3.15,"tv":289.83,"id":9625551}],"tv":2891.99}]}
{"op":"mcm","clk":"4234444795","pt":1631545800240,"mc":[{"id":"1.187562121","rc":[{"batl":[[0,1.49,120.14]],"ltp":1.46,"tv":2602.15,"id":20955040}]}]}
{"op":"mcm","clk":"4234444913","pt":1631545802221,"mc":[{"id":"1.187562121","rc":[{"batl":[[1,1.5,10.06]],"ltp":1.46,"tv":2602.15,"id":20955040},{"batb":[[0,2.98,36.57],[1,2.92,186.15],[2,2.82,42.36]],"ltp":3.15,"tv":289.83,"id":9625551}]}]}
{"op":"mcm","clk":"4234445080","pt":1631545805138,"mc":[{"id":"1.187562121","rc":[{"batb":[[0,1.46,12.57],[1,1.39,83.21],[2,1.34,98.89]],"batl":[[0,1.48,12.04],[1,1.49,120.14],[2,1.5,10.06]],"ltp":1.46,"tv":2602.15,"id":20955040}]}]}
{"op":"mcm","clk":"4234445223","pt":1631545807264,"mc":[{"id":"1.187562121","rc":[{"batb":[[0,1.39,83.21],[1,1.34,98.89],[2,1.25,238.62]],"batl":[[0,1.49,120.14],[1,1.5,10.06],[2,1.51,10.06]],"ltp":1.46,"tv":2602.15,"id":20955040}]}]}
{"op":"mcm","clk":"4234445449","pt":1631545810135,"mc":[{"id":"1.187562121","rc":[{"batb":[[0,1.46,12.57],[1,1.39,83.21],[2,1.34,98.89]],"batl":[[0,1.48,12.04],[1,1.49,120.14],[2,1.5,10.06]],"ltp":1.46,"tv":2602.15,"id":20955040}]}]}
{"op":"mcm","clk":"4234445618","pt":1631545812675,"mc":[{"id":"1.187562121","rc":[{"batb":[[0,1.47,5],[1,1.46,12.57],[2,1.39,83.21]],"ltp":1.46,"tv":2602.15,"id":20955040}]}]}
{"op":"mcm","clk":"4234446566","pt":1631545828586,"mc":[{"id":"1.187562121","rc":[{"batb":[[0,1.46,12.57],[1,1.39,83.21],[2,1.34,98.89]],"ltp":1.46,"tv":2602.15,"id":20955040}]}]}
{"op":"mcm","clk":"4234446770","pt":1631545831651,"mc":[{"id":"1.187562121","rc":[{"trd":[[1.48,11.18]],"batl":[[0,1.48,7.04]],"ltp":1.48,"tv":2612.15,"id":20955040}],"tv":2901.99}]}
{"op":"mcm","clk":"4234447424","pt":1631545841881,"mc":[{"id":"1.187562121","rc":[{"batb":[[0,1.39,83.21],[1,1.34,98.89],[2,1.25,238.62]],"batl":[[0,1.49,120.14],[1,1.5,10.06],[2,1.51,10.06]],"ltp":1.48,"tv":2612.15,"id":20955040}]}]}
{"op":"mcm","clk":"4234447566","pt":1631545844785,"mc":[{"id":"1.187562121","rc":[{"batb":[[0,3.05,7.86],[1,2.98,36.57],[2,2.92,186.15]],"batl":[[0,3.15,158.22]],"ltp":3.15,"tv":289.83,"id":9625551}]}]}
{"op":"mcm","clk":"4234447784","pt":1631545847881,"mc":[{"id":"1.187562121","rc":[{"batb":[[0,1.34,98.89],[1,1.25,238.62],[2,1.2,387.76]],"batl":[[0,1.52,1029.85],[1,1.56,12.79],[2,1.51,0]],"ltp":1.48,"tv":2612.15,"id":20955040},{"batb":[[0,2.82,42.36],[1,1.8,11.93],[2,1.7,17.05]],"ltp":3.15,"tv":289.83,"id":9625551}]}]}
{"op":"mcm","clk":"4234448605","pt":1631545861794,"mc":[{"id":"1.187562121","rc":[{"trd":[[1.4,7.14]],"batb":[[1,1.2,387.76],[2,1.17,42.47]],"batl":[[0,1.43,160.84],[1,1.44,10.5],[2,1.45,10.5]],"ltp":1.4,"tv":2619.29,"id":20955040},{"trd":[[3.5,2.86]],"batb":[[0,3.4,4.92],[1,3.2,228.87],[2,2.82,42.36]],"batl":[[0,3.5,2.26],[1,3.55,212.08]],"ltp":3.5,"tv":292.69,"id":9625551}],"tv":2911.99}]}
{"op":"mcm","clk":"4234448682","pt":1631545862782,"mc":[{"id":"1.187562121","rc":[{"batb":[[0,1.38,21.74],[1,1.37,10.88],[2,1.36,10.88]],"ltp":1.4,"tv":2619.29,"id":20955040},{"batb":[[1,3.25,29.11],[2,3.2,228.87]],"batl":[[2,4.1,2.44]],"ltp":3.5,"tv":292.69,"id":9625551}]}]}
{"op":"mcm","clk":"4234448940","pt":1631545866581,"mc":[{"id":"1.187562121","rc":[{"trd":[[1.4,12.79]],"ltp":1.4,"tv":2624.94,"id":20955040},{"trd":[[3.5,5.12]],"batl":[[0,3.55,212.08],[1,4.1,2.44],[2,4.1,0]],"ltp":3.5,"tv":294.95,"id":9625551}],"tv":2919.9}]}
{"op":"mcm","clk":"4234449138","pt":1631545869740,"mc":[{"id":"1.187562121","rc":[{"trd":[[1.39,184.29]],"ltp":1.39,"tv":2809.23,"id":20955040},{"trd":[[3.55,72.15]],"batl":[[0,3.55,139.93]],"ltp":3.55,"tv":367.1,"id":9625551}],"tv":3176.34}]}
{"op":"mcm","clk":"4234449225","pt":1631545870832,"mc":[{"id":"1.187562121","rc":[{"trd":[[1.42,15.7]],"batb":[[0,1.38,10.87],[1,1.37,5.44],[2,1.36,5.44]],"batl":[[0,1.43,80.42],[1,1.44,5.25],[2,1.45,5.25]],"ltp":1.42,"tv":2817.9,"id":20955040},{"trd":[[3.4,3.62]],"batb":[[0,3.25,29.11],[1,3,35.15],[2,2,11.93]],"ltp":3.4,"tv":370.72,"id":9625551}],"tv":3188.63}]}
{"op":"mcm","clk":"4234449250","pt":1631545871208,"mc":[{"id":"1.187562121","rc":[{"batb":[[0,1.28,121.79],[1,1.25,512.59],[2,1.2,387.76]],"batl":[[0,1.52,1029.85],[1,1.56,12.79],[2,1.77,508.04]],"ltp":1.42,"tv":2817.9,"id":20955040},{"batb":[[0,3,35.15],[1,2,11.93],[2,1.8,11.93]],"ltp":3.4,"tv":370.72,"id":9625551}]}]}
{"op":"mcm","clk":"4234450202","pt":1631545886424,"mc":[{"id":"1.187562121","rc":[{"batb":[[1,1.2,387.76],[2,1.17,42.47]],"ltp":1.42,"tv":2817.9,"id":20955040}]}]}
{"op":"mcm","clk":"4234450297","pt":1631545887849,"mc":[{"id":"1.187562121","rc":[{"batb":[[0,1.43,20.98],[1,1.42,10.5],[2,1.41,10.5]],"batl":[[0,1.5,259.95],[1,1.52,1029.85],[2,1.56,12.79]],"ltp":1.42,"tv":2817.9,"id":20955040},{"batb":[[0,3.15,6.67],[1,3,165.12],[2,2,11.93]],"batl":[[0,3.25,5.42],[1,3.3,212.53],[2,3.55,56.34]],"ltp":3.4,"tv":370.72,"id":9625551}]}]}
{"op":"mcm","clk":"4234450393","pt":1631545888912,"mc":[{"id":"1.187562121","rc":[{"trd":[[1.44,26.96]],"ltp":1.44,"tv":2824.84,"id":20955040},{"trd":[[3.25,3.07]],"batb":[[1,3.05,9.84],[2,3,170.04]],"batl":[[0,3.25,2.35]],"ltp":3.25,"tv":373.79,"id":9625551}],"tv":3198.64}]}
{"op":"mcm","clk":"4234450828","pt":1631545895727,"mc":[{"id":"1.187562121","rc":[{"batl":[[0,1.45,180],[1,1.5,259.95],[2,1.52,1029.85]],"ltp":1.44,"tv":2824.84,"id":20955040}]}]}
{"op":"mcm","clk":"4234451034","pt":1631545898732,"mc":[{"id":"1.187562121","rc":[{"batb":[[0,3.05,9.84],[1,3,170.04],[2,2.98,4.92]],"batl":[[0,3.3,212.53],[1,3.55,56.34],[2,3.8,2.63]],"ltp":3.25,"tv":373.79,"id":9625551}]}]}
{"op":"mcm","clk":"4234451236","pt":1631545901643,"mc":[{"id":"1.187562121","rc":[{"batb":[[0,1.44,11.29],[1,1.43,20.98],[2,1.42,10.5]],"batl":[[1,1.46,14.83],[2,1.5,259.95]],"ltp":1.44,"tv":2824.84,"id":20955040}]}]}
{"op":"mcm","clk":"4234451257","pt":1631545901954,"mc":[{"id":"1.187562121","rc":[{"trd":[[1.43,160.62],[1.44,49.54]],"batb":[[0,1.42,10.5],[1,1.41,10.5],[2,1.38,85.81]],"ltp":1.43,"tv":3008.04,"id":20955040},{"trd":[[3.3,51.44]],"batl":[[0,3.3,161.09]],"ltp":3.3,"tv":425.23,"id":9625551}],"tv":3433.28}]}
{"op":"mcm","clk":"4234451754","pt":1631545908861,"mc":[{"id":"1.187562121","rc":[{"batb":[[0,1.32,104.6],[1,1.28,493.1],[2,1.2,387.76]],"batl":[[0,1.52,1029.85],[1,1.56,12.79],[2,1.77,508.04]],"ltp":1.43,"tv":3008.04,"id":20955040},{"batb":[[0,2.82,41.94],[1,2,11.93],[2,1.8,11.93]],"ltp":3.3,"tv":425.23,"id":9625551}]}]}
{"op":"mcm","clk":"4234452092","pt":1631545913756,"mc":[{"id":"1.187562121","rc":[{"batl":[[0,1.48,370.81],[1,1.52,1029.85],[2,1.56,12.79]],"ltp":1.43,"tv":3008.04,"id":20955040}]}]}
{"op":"mcm","clk":"4234452107","pt":1631545913963,"mc":[{"id":"1.187562121","rc":[{"batl":[[0,1.52,1029.85],[1,1.56,12.79],[2,1.77,508.04]],"ltp":1.43,"tv":3008.04,"id":20955040}]}]}
{"op":"mcm","clk":"4234452817","pt":1631545923856,"mc":[{"id":"1.187562121","rc":[{"batb":[[1,1.2,387.76],[2,1.17,42.47]],"ltp":1.43,"tv":3008.04,"id":20955040}]}]}
{"op":"mcm","clk":"4234452968","pt":1631545925473,"mc":[{"id":"1.187562121","rc":[{"batb":[[0,1.48,438.47],[1,1.47,61.22],[2,1.46,30.61]],"batl":[[0,1.5,6.76],[1,1.52,1029.85],[2,1.56,12.79]],"ltp":1.43,"tv":3008.04,"id":20955040},{"batb":[[0,3,3.38],[1,2.84,217.83],[2,2.82,41.94]],"batl":[[0,3.15,38.1],[1,3.5,2.86]],"ltp":3.3,"tv":425.23,"id":9625551}]}]}
{"op":"mcm","clk":"4234453052","pt":1631545926879,"mc":[{"id":"1.187562121","rc":[{"trd":[[1.48,24.7]],"batb":[[0,1.48,431.71],[1,1.47,20.4],[2,1.46,10.2]],"ltp":1.48,"tv":3021.56,"id":20955040},{"batb":[[1,2.9,10.34],[2,2.88,5.18]],"ltp":3.3,"tv":425.23,"id":9625551}],"tv":3446.8}]}
{"op":"mcm","clk":"4234453608","pt":1631545933376,"mc":[{"id":"1.187562121","rc":[{"batl":[[0,1.49,237],[1,1.5,6.76],[2,1.52,1029.85]],"ltp":1.48,"tv":3021.56,"id":20955040}]}]}
{"op":"mcm","clk":"4234453688","pt":1631545934161,"mc":[{"id":"1.187562121","rc":[{"trd":[[1.48,888.12]],"batb":[[0,1.47,20.4],[1,1.46,10.2],[2,1.45,10.2]],"batl":[[0,1.48,274.17],[1,1.49,237],[2,1.5,6.76]],"ltp":1.48,"tv":3884.98,"id":20955040}],"tv":4310.22}]}
{"op":"mcm","clk":"4234454059","pt":1631545939696,"mc":[{"id":"1.187562121","rc":[{"batl":[[0,1.49,237],[1,1.5,6.76],[2,1.52,1029.85]],"ltp":1.48,"tv":3884.98,"id":20955040}]}]}
{"op":"mcm","clk":"4234454302","pt":1631545943907,"mc":[{"id":"1.187562121","rc":[{"batl":[[1,1.52,1029.85],[2,1.56,12.79]],"ltp":1.48,"tv":3884.98,"id":20955040},{"batb":[[0,2.9,10.34],[1,2.88,5.18],[2,2.86,5.18]],"batl":[[1,3.5,0]],"ltp":3.3,"tv":425.23,"id":9625551}]}]}
{"op":"mcm","clk":"4234454372","pt":1631545944893,"mc":[{"id":"1.187562121","rc":[{"batb":[[0,1.37,89.08],[1,1.31,484.59],[2,1.2,387.76]],"batl":[[0,1.52,1029.85],[1,1.56,12.79],[2,1.77,508.04]],"ltp":1.48,"tv":3884.98,"id":20955040},{"batb":[[0,2.7,19.12],[1,2,11.93],[2,1.8,11.93]],"ltp":3.3,"tv":425.23,"id":9625551}]}]}
{"op":"mcm","clk":"4234454782","pt":1631545952312,"mc":[{"id":"1.187562121","rc":[{"batb":[[1,1.2,387.76],[2,1.17,42.47]],"batl":[[2,44,7.22]],"ltp":1.48,"tv":3884.98,"id":20955040}]}]}
{"op":"mcm","clk":"4234454893","pt":1631545954233,"mc":[{"id":"1.187562121","rc":[{"batb":[[0,1.49,134.22],[1,1.37,89.08],[2,1.2,387.76]],"batl":[[2,1.58,589.87]],"ltp":1.48,"tv":3884.98,"id":20955040},{"batb":[[0,2.88,5.05],[1,2.7,19.12],[2,2,11.93]],"batl":[[0,2.96,7.23],[1,2.98,10.06],[2,3,5.04]],"ltp":3.3,"tv":425.23,"id":9625551}]}]}
{"op":"mcm","clk":"4234454997","pt":1631545955912,"mc":[{"id":"1.187562121","rc":[{"batb":[[1,1.46,66.68],[2,1.42,75.32]],"batl":[[1,1.53,6.54],[2,1.56,12.79]],"ltp":1.48,"tv":3884.98,"id":20955040},{"batb":[[1,2.76,10.88],[2,2.74,5.44]],"ltp":3.3,"tv":425.23,"id":9625551}]}]}
{"op":"mcm","clk":"4234455388","pt":1631545962625,"mc":[{"id":"1.187562121","rc":[{"batb":[[0,1.46,66.68],[1,1.42,75.32],[2,1.34,472.33]],"batl":[[1,1.56,12.79],[2,1.95,415.94]],"ltp":1.48,"tv":3884.98,"id":20955040},{"batb":[[0,2.7,19.12],[1,2.58,21.22],[2,2,11.93]],"ltp":3.3,"tv":425.23,"id":9625551}]}]}
{"op":"mcm","clk":"4234455402","pt":1631545962951,"mc":[{"id":"1.187562121","rc":[{"batb":[[0,1.42,75.32],[1,1.34,472.33],[2,1.25,238.62]],"ltp":1.48,"tv":3884.98,"id":20955040},{"batb":[[0,2.58,21.22],[1,2,11.93],[2,1.8,11.93]],"ltp":3.3,"tv":425.23,"id":9625551}]}]}
{"op":"mcm","clk":"4234455782","pt":1631545969619,"mc":[{"id":"1.187562121","rc":[{"batb":[[1,1.25,238.62],[2,1.2,387.76]],"ltp":1.48,"tv":3884.98,"id":20955040}]}]}
{"op":"mcm","clk":"4234455841","pt":1631545970852,"mc":[{"id":"1.187562121","rc":[{"trd":[[1.52,3186.73]],"batb":[[0,1.54,341.46],[1,1.51,49.02],[2,1.42,75.32]],"batl":[[0,1.56,12.79],[1,1.58,24.19],[2,1.6,343.95]],"ltp":1.52,"tv":5061.88,"id":20955040},{"trd":[[2.92,528.39]],"batl":[[0,2.84,6.17],[1,2.9,693.71],[2,3.15,4.81]],"ltp":2.92,"tv":884.76,"id":9625551}],"tv":5946.65}]}
{"op":"mcm","clk":"4234455895","pt":1631545971845,"mc":[{"id":"1.187562121","rc":[{"batb":[[1,1.51,9.8]],"batl":[[0,1.56,19.2],[2,1.59,94.34]],"ltp":1.52,"tv":5061.88,"id":20955040},{"batb":[[1,1.8,11.93],[2,1.7,17.05]],"batl":[[1,3.2,3.12],[2,3.15,0]],"ltp":2.92,"tv":884.76,"id":9625551}]}]}
{"op":"mcm","clk":"4234455925","pt":1631545972254,"mc":[{"id":"1.187562121","rc":[{"trd":[[1.54,31.74]],"batb":[[0,1.54,339.46],[2,1.5,61.15]],"batl":[[2,1.59,18.86]],"ltp":1.54,"tv":5065.88,"id":20955040},{"batb":[[1,2.36,27.18],[2,1.8,11.93]],"ltp":2.92,"tv":884.76,"id":9625551}],"tv":5950.65}]}
{"op":"mcm","clk":"4234456176","pt":1631545975850,"mc":[{"id":"1.187562121","rc":[{"batb":[[1,1.52,2],[2,1.51,9.8]],"batl":[[1,1.57,34.92],[2,1.58,24.19]],"ltp":1.54,"tv":5065.88,"id":20955040},{"batl":[[1,2.9,49.62],[2,3.2,3.12]],"ltp":2.92,"tv":884.76,"id":9625551}]}]}
{"op":"mcm","clk":"4234456186","pt":1631545976049,"mc":[{"id":"1.187562121","rc":[{"batl":[[1,1.58,24.19],[2,1.59,18.86]],"ltp":1.54,"tv":5065.88,"id":20955040},{"batl":[[1,3.2,3.12],[2,3.2,0]],"ltp":2.92,"tv":884.76,"id":9625551}]}]}
{"op":"mcm","clk":"4234456322","pt":1631545978363,"mc":[{"id":"1.187562121","rc":[{"batl":[[0,1.56,180.2]],"ltp":1.54,"tv":5065.88,"id":20955040}]}]}
{"op":"mcm","clk":"4234456374","pt":1631545979046,"mc":[{"id":"1.187562121","rc":[{"trd":[[1.54,722.04]],"batb":[[0,1.52,2],[1,1.51,9.8],[2,1.5,61.15]],"batl":[[0,1.54,355.04],[1,1.56,180.2],[2,1.58,24.19]],"ltp":1.54,"tv":5756.18,"id":20955040},{"trd":[[2.84,6.17]],"batl":[[0,3.2,3.12],[1,3.2,0]],"ltp":2.84,"tv":890.93,"id":9625551}],"tv":6647.12}]}
{"op":"mcm","clk":"4234456563","pt":1631545981646,"mc":[{"id":"1.187562121","rc":[{"batl":[[0,1.56,180.2],[1,1.58,24.19],[2,1.59,18.86]],"ltp":1.54,"tv":5756.18,"id":20955040}]}]}
{"op":"mcm","clk":"4234457017","pt":1631545988750,"mc":[{"id":"1.187562121","rc":[{"batb":[[0,2.58,74.1]],"ltp":2.84,"tv":890.93,"id":9625551}]}]}
{"op":"mcm","clk":"4234457043","pt":1631545989224,"mc":[{"id":"1.187562121","rc":[{"batl":[[1,1.59,18.86],[2,1.6,353.39]],"ltp":1.54,"tv":5756.18,"id":20955040}]}]}
{"op":"mcm","clk":"4234457159","pt":1631545990853,"mc":[{"id":"1.187562121","rc":[{"batb":[[1,1.46,68.11],[2,1.38,455.1]],"batl":[[0,1.56,173.79],[1,1.95,415.94],[2,44,7.22]],"ltp":1.54,"tv":5756.18,"id":20955040},{"batb":[[0,2.36,27.18],[1,1.8,11.93],[2,1.7,17.05]],"ltp":2.84,"tv":890.93,"id":9625551}]}]}
{"op":"mcm","clk":"4234457213","pt":1631545991848,"mc":[{"id":"1.187562121","rc":[{"batl":[[0,1.56,12.79]],"ltp":1.54,"tv":5756.18,"id":20955040}]}]}
{"op":"mcm","clk":"4234457676","pt":1631545999069,"mc":[{"id":"1.187562121","rc":[{"batb":[[2,1.25,238.62]],"batl":[[1,44,7.22],[2,810,0.07]],"ltp":1.54,"tv":5756.18,"id":20955040}]}]}
{"op":"mcm","clk":"4234457801","pt":1631546000859,"mc":[{"id":"1.187562121","rc":[{"trd":[[1.56,32.31]],"batb":[[0,1.62,9.99],[1,1.61,55.9],[2,1.6,27.95]],"batl":[[0,1.66,22.59]],"ltp":1.56,"tv":5768.97,"id":20955040},{"trd":[[2.78,7.18]],"batb":[[0,2.46,263.12],[1,2.36,27.18],[2,1.8,11.93]],"batl":[[0,2.88,3.47],[1,2.92,1082.89]],"ltp":2.78,"tv":898.11,"id":9625551}],"tv":6667.09}]}
{"op":"mcm","clk":"4234457865","pt":1631546001753,"mc":[{"id":"1.187562121","rc":[{"trd":[[1.62,4]],"batb":[[0,1.62,7.99],[1,1.61,18.64],[2,1.6,9.32]],"batl":[[0,1.64,6.1],[1,1.66,22.59],[2,1.68,17.86]],"ltp":1.62,"tv":5772.97,"id":20955040},{"batb":[[2,2.14,36.07]],"ltp":2.78,"tv":898.11,"id":9625551}],"tv":6671.09}]}
{"op":"mcm","clk":"4234458525","pt":1631546010656,"mc":[{"id":"1.187562121","rc":[{"batb":[[1,2.38,6.96],[2,2.36,27.18]],"batl":[[2,2.98,4.25]],"ltp":2.78,"tv":898.11,"id":9625551}]}]}
{"op":"mcm","clk":"4234458576","pt":1631546011655,"mc":[{"id":"1.187562121","rc":[{"batb":[[0,1.61,18.64],[1,1.6,9.32],[2,1.59,84.79]],"batl":[[1,1.68,17.86],[2,1.69,8.92]],"ltp":1.62,"tv":5772.97,"id":20955040},{"batb":[[1,2.36,27.18],[2,2.14,36.07]],"ltp":2.78,"tv":898.11,"id":9625551}]}]}
{"op":"mcm","clk":"4234458767","pt":1631546014845,"mc":[{"id":"1.187562121","rc":[{"batb":[[0,1.58,2],[1,1.52,59.79],[2,1.51,48.99]],"batl":[[0,2.16,347.9],[1,44,7.22],[2,810,0.07]],"ltp":1.62,"tv":5772.97,"id":20955040},{"batb":[[0,2.32,5.64],[1,2.14,36.07],[2,1.8,11.93]],"batl":[[0,2.98,4.25],[1,2.92,0],[2,2.98,0]],"ltp":2.78,"tv":898.11,"id":9625551}]}]}
{"op":"mcm","clk":"4234458805","pt":1631546015526,"mc":[{"id":"1.187562121","rc":[{"batl":[[0,1.74,31.25],[1,2.16,347.9],[2,44,7.22]],"ltp":1.62,"tv":5772.97,"id":20955040},{"batb":[[0,2.34,6.72],[1,2.32,5.64],[2,2.14,36.07]],"ltp":2.78,"tv":898.11,"id":9625551}]}]}
{"op":"mcm","clk":"4234458955","pt":1631546017838,"mc":[{"id":"1.187562121","rc":[{"batl":[[0,1.72,36.91],[1,1.74,31.25],[2,1.75,30.86]],"ltp":1.62,"tv":5772.97,"id":20955040}]}]}
{"op":"mcm","clk":"4234458977","pt":1631546018259,"mc":[{"id":"1.187562121","rc":[{"batl":[[0,1.74,31.25],[1,1.75,30.86],[2,2.16,347.9]],"ltp":1.62,"tv":5772.97,"id":20955040}]}]}
{"op":"mcm","clk":"4234459156","pt":1631546020829,"mc":[{"id":"1.187562121","rc":[{"batl":[[0,1.65,18.7],[1,1.74,31.25],[2,1.75,30.86]],"ltp":1.62,"tv":5772.97,"id":20955040},{"batb":[[0,2.52,20.24],[1,2.34,6.72],[2,2.32,5.64]],"batl":[[0,2.62,21.75],[1,2.98,4.25]],"ltp":2.78,"tv":898.11,"id":9625551}]}]}
{"op":"mcm","clk":"4234459224","pt":1631546021831,"mc":[{"id":"1.187562121","rc":[{"batl":[[0,1.74,31.25],[1,1.75,30.86],[2,2.16,347.9]],"ltp":1.62,"tv":5772.97,"id":20955040},{"batb":[[0,2.34,6.72],[1,2.32,5.64],[2,2.14,36.07]],"batl":[[0,2.98,4.25],[1,2.98,0]],"ltp":2.78,"tv":898.11,"id":9625551}]}]}
{"op":"mcm","clk":"4234459383","pt":1631546024748,"mc":[{"id":"1.187562121","rc":[{"batl":[[0,1.72,36.16],[1,1.74,31.25],[2,1.75,30.86]],"ltp":1.62,"tv":5772.97,"id":20955040}]}]}
{"op":"mcm","clk":"4234459416","pt":1631546025269,"mc":[{"id":"1.187562121","rc":[{"batl":[[0,1.74,31.25],[1,1.75,30.86],[2,2.16,347.9]],"ltp":1.62,"tv":5772.97,"id":20955040}]}]}
{"op":"mcm","clk":"4234460195","pt":1631546031899,"mc":[{"id":"1.187562121","rc":[{"batl":[[0,1.72,34.91],[1,1.74,31.25],[2,1.75,30.86]],"ltp":1.62,"tv":5772.97,"id":20955040}]}]}
{"op":"mcm","clk":"4234460330","pt":1631546032716,"mc":[{"id":"1.187562121","rc":[{"trd":[[1.74,24.98]],"batl":[[0,1.74,18.76],[1,1.75,30.86],[2,1.78,13.12]],"ltp":1.74,"tv":5797.95,"id":20955040},{"batl":[[0,2.38,147.08],[1,2.4,31.52],[2,2.42,1287.92]],"ltp":2.78,"tv":898.11,"id":9625551}],"tv":6696.07}]}
{"op":"mcm","clk":"4234460472","pt":1631546033716,"mc":[{"id":"1.187562121","rc":[{"trd":[[1.72,2]],"batb":[[0,1.7,38.5],[1,1.62,46.22],[2,1.58,2]],"batl":[[2,1.76,5.68]],"ltp":1.72,"tv":5799.95,"id":20955040},{"trd":[[2.38,1.45]],"batb":[[2,2.24,66.96]],"batl":[[0,2.38,86.79],[1,2.4,18.91],[2,2.42,18.91]],"ltp":2.38,"tv":899.56,"id":9625551}],"tv":6699.52}]}
{"op":"mcm","clk":"4234460697","pt":1631546034893,"mc":[{"id":"1.187562121","rc":[{"batb":[[2,2.24,13.4]],"batl":[[0,2.38,61.57],[1,2.4,6.3],[2,2.42,6.3]],"ltp":2.38,"tv":899.56,"id":9625551}]}]}
{"op":"mcm","clk":"4234461021","pt":1631546036874,"mc":[{"id":"1.187562121","rc":[{"batb":[[1,1.66,2],[2,1.62,46.22]],"ltp":1.72,"tv":5799.95,"id":20955040}]}]}
{"op":"mcm","clk":"4234461368","pt":1631546039461,"mc":[{"id":"1.187562121","rc":[{"batb":[[2,1.63,38.23]],"ltp":1.72,"tv":5799.95,"id":20955040}]}]}
{"op":"mcm","clk":"4234461603","pt":1631546041772,"mc":[{"id":"1.187562121","rc":[{"trd":[[1.72,10.66]],"ltp":1.72,"tv":5808.61,"id":20955040},{"trd":[[2.38,7.71]],"batl":[[0,2.38,55.31]],"ltp":2.38,"tv":905.82,"id":9625551}],"tv":6714.44}]}
{"op":"mcm","clk":"4234462082","pt":1631546046887,"mc":[{"id":"1.187562121","rc":[{"batb":[[0,1.66,2],[1,1.62,46.22],[2,1.59,41.11]],"batl":[[0,1.9,28.65],[1,2.16,347.9],[2,810,0.07]],"ltp":1.72,"tv":5808.61,"id":20955040},{"batb":[[0,2.1,7.64],[1,1.96,47.81],[2,1.7,17.05]],"batl":[[0,2.7,5.15],[1,2.98,4.25],[2,2.42,0]],"ltp":2.38,"tv":905.82,"id":9625551}]}]}
{"op":"mcm","clk":"4234462425","pt":1631546049911,"mc":[{"id":"1.187562121","rc":[{"batb":[[1,1.63,44.23],[2,1.62,46.22]],"ltp":1.72,"tv":5808.61,"id":20955040},{"batl":[[0,2.6,4.86],[1,2.7,5.15],[2,2.98,4.25]],"ltp":2.38,"tv":905.82,"id":9625551}]}]}
{"op":"mcm","clk":"4234462456","pt":1631546050336,"mc":[{"id":"1.187562121","rc":[{"batb":[[1,1.62,46.22],[2,1.59,41.11]],"ltp":1.72,"tv":5808.61,"id":20955040},{"batl":[[0,2.7,5.15],[1,2.98,4.25],[2,2.98,0]],"ltp":2.38,"tv":905.82,"id":9625551}]}]}
{"op":"mcm","clk":"4234462523","pt":1631546051120,"mc":[{"id":"1.187562121","rc":[{"batl":[[0,1.72,1146.71],[1,1.9,28.65],[2,2.16,347.9]],"ltp":1.72,"tv":5808.61,"id":20955040}]}]}
{"op":"mcm","clk":"4234462755","pt":1631546053598,"mc":[{"id":"1.187562121","rc":[{"batl":[[1,1.86,32.75],[2,1.9,28.65]],"ltp":1.72,"tv":5808.61,"id":20955040},{"batb":[[0,2.16,7.78],[1,2.1,7.64],[2,1.96,47.81]],"ltp":2.38,"tv":905.82,"id":9625551}]}]}
{"op":"mcm","clk":"4234463072","pt":1631546056828,"mc":[{"id":"1.187562121","rc":[{"batb":[[1,1.63,37.23],[2,1.62,46.22]],"batl":[[0,1.9,28.65],[1,2.16,347.9],[2,810,0.07]],"ltp":1.72,"tv":5808.61,"id":20955040},{"batb":[[0,2.1,7.64],[1,1.96,47.81],[2,1.7,17.05]],"batl":[[0,2.6,4.76],[1,2.7,5.15],[2,2.98,4.25]],"ltp":2.38,"tv":905.82,"id":9625551}]}]}
{"op":"mcm","clk":"4234463111","pt":1631546057238,"mc":[{"id":"1.187562121","rc":[{"batb":[[1,1.62,46.22],[2,1.59,41.11]],"ltp":1.72,"tv":5808.61,"id":20955040},{"batl":[[0,2.7,5.15],[1,2.98,4.25],[2,2.98,0]],"ltp":2.38,"tv":905.82,"id":9625551}]}]}
{"op":"mcm","clk":"4234463830","pt":1631546060356,"mc":[{"id":"1.187562121","rc":[{"batl":[[0,1.68,41.59],[1,1.69,8.92],[2,1.7,8.92]],"ltp":1.72,"tv":5808.61,"id":20955040},{"batb":[[0,2.16,7.03],[1,2.1,7.64],[2,1.96,47.81]],"batl":[[0,2.56,293.13],[1,2.7,5.15],[2,2.98,4.25]],"ltp":2.38,"tv":905.82,"id":9625551}]}]}
{"op":"mcm","clk":"4234464271","pt":1631546061474,"mc":[{"id":"1.187562121","rc":[{"batb":[[2,1.61,18.64]],"ltp":1.72,"tv":5808.61,"id":20955040},{"batb":[[0,2.3,29.44],[1,2.16,7.03],[2,2.1,7.64]],"batl":[[2,2.76,3.62]],"ltp":2.38,"tv":905.82,"id":9625551}]}]}
{"op":"mcm","clk":"4234465457","pt":1631546066532,"mc":[{"id":"1.187562121","rc":[{"batb":[[1,2.2,6.52],[2,2.16,7.03]],"batl":[[2,2.76,9.14]],"ltp":2.38,"tv":905.82,"id":9625551}]}]}
{"op":"mcm","clk":"4234465605","pt":1631546068825,"mc":[{"id":"1.187562121","rc":[{"batl":[[0,1.68,152.59]],"ltp":1.72,"tv":5808.61,"id":20955040}]}]}
{"op":"mcm","clk":"4234466018","pt":1631546074837,"mc":[{"id":"1.187562121","rc":[{"batb":[[1,1.58,2],[2,1.57,37.57]],"batl":[[0,1.82,31.75],[1,1.86,28.25],[2,1.87,29.5]],"ltp":1.72,"tv":5808.61,"id":20955040},{"batb":[[0,2.16,7.03],[1,2.14,7.82],[2,2.1,7.64]],"batl":[[0,2.76,5.52],[1,2.86,4.75],[2,2.98,4.25]],"ltp":2.38,"tv":905.82,"id":9625551}]}]}
{"op":"mcm","clk":"4234466033","pt":1631546075046,"mc":[{"id":"1.187562121","rc":[{"batl":[[0,1.87,29.5],[1,2.16,347.9],[2,810,0.07]],"ltp":1.72,"tv":5808.61,"id":20955040},{"batb":[[0,2.14,7.82],[1,2.04,41.35],[2,1.7,17.05]],"ltp":2.38,"tv":905.82,"id":9625551}]}]}
{"op":"mcm","clk":"4234466189","pt":1631546077661,"mc":[{"id":"1.187562121","rc":[{"trd":[[1.66,4]],"batb":[[0,1.58,2],[1,1.54,100.06],[2,1.52,2]],"batl":[[0,1.64,571.36],[1,1.87,29.5],[2,2.16,347.9]],"ltp":1.66,"tv":5812.61,"id":20955040},{"batl":[[0,2.86,4.75],[1,2.86,0],[2,2.98,0]],"ltp":2.38,"tv":905.82,"id":9625551}],"tv":6718.44}]}
{"op":"mcm","clk":"4234466234","pt":1631546078238,"mc":[{"id":"1.187562121","rc":[{"batl":[[1,1.82,32.25],[2,1.87,29.5]],"ltp":1.66,"tv":5812.61,"id":20955040}]}]}
{"op":"mcm","clk":"4234466341","pt":1631546079857,"mc":[{"id":"1.187562121","rc":[{"batl":[[0,2.58,201.84],[1,2.86,4.75]],"ltp":2.38,"tv":905.82,"id":9625551}]}]}
{"op":"mcm","clk":"4234466419","pt":1631546080852,"mc":[{"id":"1.187562121","rc":[{"trd":[[1.64,32.8]],"batl":[[0,1.64,538.56]],"ltp":1.64,"tv":5845.41,"id":20955040},{"trd":[[2.56,21.01]],"batb":[[0,2.2,7.72],[1,2.14,7.82],[2,2.04,41.35]],"batl":[[0,2.86,4.75],[1,2.86,0]],"ltp":2.56,"tv":926.83,"id":9625551}],"tv":6772.25}]}
{"op":"mcm","clk":"4234466440","pt":1631546081072,"mc":[{"id":"1.187562121","rc":[{"batb":[[0,2.14,7.82],[1,2.04,41.35],[2,1.8,11.93]],"ltp":2.56,"tv":926.83,"id":9625551}]}]}
{"op":"mcm","clk":"4234466586","pt":1631546082736,"mc":[{"id":"1.187562121","rc":[{"batl":[[0,1.87,29.5],[1,2.16,347.9],[2,810,0.07]],"ltp":1.64,"tv":5845.41,"id":20955040}]}]}
{"op":"mcm","clk":"4234466903","pt":1631546087743,"mc":[{"id":"1.187562121","rc":[{"batb":[[0,2.2,6.52],[1,2.14,7.82],[2,2.04,41.35]],"ltp":2.56,"tv":926.83,"id":9625551}]}]}
{"op":"mcm","clk":"4234466918","pt":1631546087948,"mc":[{"id":"1.187562121","rc":[{"batb":[[0,2.14,7.82],[1,2.04,41.35],[2,1.8,11.93]],"ltp":2.56,"tv":926.83,"id":9625551}]}]}
{"op":"mcm","clk":"4234467017","pt":1631546089883,"mc":[{"id":"1.187562121","rc":[{"batl":[[2,820,0.14]],"ltp":1.64,"tv":5845.41,"id":20955040}]}]}
{"op":"mcm","clk":"4234467025","pt":1631546090043,"mc":[{"id":"1.187562121","rc":[{"batl":[[2,810,0.07]],"ltp":1.64,"tv":5845.41,"id":20955040}]}]}
{"op":"mcm","clk":"4234467347","pt":1631546095796,"mc":[{"id":"1.187562121","rc":[{"batl":[[0,1.6,28.09],[1,1.87,29.5],[2,2.16,347.9]],"ltp":1.64,"tv":5845.41,"id":20955040},{"batb":[[0,2.62,11.44],[1,2.6,82.64],[2,2.58,5.72]],"batl":[[0,2.78,270.47],[1,2.86,4.75]],"ltp":2.56,"tv":926.83,"id":9625551}]}]}
{"op":"mcm","clk":"4234467394","pt":1631546096690,"mc":[{"id":"1.187562121","rc":[{"batb":[[1,1.55,96.76],[2,1.54,148.44]],"ltp":1.64,"tv":5845.41,"id":20955040},{"batl":[[2,3,3.33]],"ltp":2.56,"tv":926.83,"id":9625551}]}]}
{"op":"mcm","clk":"4234467412","pt":1631546096954,"mc":[{"id":"1.187562121","rc":[{"batb":[[1,1.55,19.36],[2,1.54,109.74]],"ltp":1.64,"tv":5845.41,"id":20955040}]}]}
{"op":"mcm","clk":"4234467728","pt":1631546102069,"mc":[{"id":"1.187562121","rc":[{"batl":[[1,1.73,34.5],[2,1.78,33.25]],"ltp":1.64,"tv":5845.41,"id":20955040},{"batl":[[2,2.98,4.25]],"ltp":2.56,"tv":926.83,"id":9625551}]}]}
{"op":"mcm","clk":"4234467823","pt":1631546103706,"mc":[{"id":"1.187562121","rc":[{"batl":[[0,1.6,180.09]],"ltp":1.64,"tv":5845.41,"id":20955040}]}]}
{"op":"mcm","clk":"4234468160","pt":1631546108500,"mc":[{"id":"1.187562121","rc":[{"trd":[[1.6,44.71]],"batl":[[0,1.6,146.21]],"ltp":1.6,"tv":5890.12,"id":20955040},{"trd":[[2.66,13.86]],"ltp":2.66,"tv":940.7,"id":9625551}],"tv":6830.82}]}
{"op":"mcm","clk":"4234468630","pt":1631546115874,"mc":[{"id":"1.187562121","rc":[{"batb":[[1,1.52,2],[2,1.51,47.99]],"batl":[[0,1.73,34.5],[1,1.78,33.25],[2,1.87,29.5]],"ltp":1.6,"tv":5890.12,"id":20955040},{"batb":[[0,2.36,6.68],[1,2.28,5.91],[2,2.18,34.06]],"batl":[[0,2.98,4.25],[1,3.1,4.05],[2,2.98,0]],"ltp":2.66,"tv":940.7,"id":9625551}]}]}
{"op":"mcm","clk":"4234468644","pt":1631546116187,"mc":[{"id":"1.187562121","rc":[{"batl":[[0,1.78,33.25],[1,2.16,347.9],[2,810,0.07]],"ltp":1.6,"tv":5890.12,"id":20955040},{"batb":[[0,2.28,5.91],[1,2.18,34.06],[2,1.8,11.93]],"ltp":2.66,"tv":940.7,"id":9625551}]}]}
{"op":"mcm","clk":"4234469005","pt":1631546121828,"mc":[{"id":"1.187562121","rc":[{"batl":[[0,1.62,18.75],[1,1.78,33.25],[2,2.16,347.9]],"ltp":1.6,"tv":5890.12,"id":20955040},{"batb":[[0,2.6,18.74],[1,2.28,5.91],[2,2.18,34.06]],"batl":[[0,2.74,21.75],[1,2.78,190.1],[2,2.98,4.25]],"ltp":2.66,"tv":940.7,"id":9625551}]}]}
{"op":"mcm","clk":"4234469060","pt":1631546122824,"mc":[{"id":"1.187562121","rc":[{"batl":[[0,1.73,37.5]],"ltp":1.6,"tv":5890.12,"id":20955040},{"batb":[[0,2.36,6.68]],"batl":[[0,2.98,4.25],[1,3.1,4.05],[2,2.98,0]],"ltp":2.66,"tv":940.7,"id":9625551}]}]}
{"op":"mcm","clk":"4234469069","pt":1631546123032,"mc":[{"id":"1.187562121","rc":[{"batl":[[0,1.78,33.25],[1,2.16,347.9],[2,810,0.07]],"ltp":1.6,"tv":5890.12,"id":20955040},{"batb":[[0,2.28,5.91],[1,2.18,34.06],[2,1.8,11.93]],"ltp":2.66,"tv":940.7,"id":9625551}]}]}
{"op":"mcm","clk":"4234469453","pt":1631546129716,"mc":[{"id":"1.187562121","rc":[{"batl":[[0,1.73,36.5],[1,1.78,33.25],[2,2.16,347.9]],"ltp":1.6,"tv":5890.12,"id":20955040},{"batb":[[0,2.36,6.68],[1,2.28,5.91],[2,2.18,34.06]],"ltp":2.66,"tv":940.7,"id":9625551}]}]}
{"op":"mcm","clk":"4234469469","pt":1631546130028,"mc":[{"id":"1.187562121","rc":[{"batl":[[0,1.78,33.25],[1,2.16,347.9],[2,810,0.07]],"ltp":1.6,"tv":5890.12,"id":20955040},{"batb":[[0,2.28,5.91],[1,2.18,34.06],[2,1.8,11.93]],"ltp":2.66,"tv":940.7,"id":9625551}]}]}
{"op":"mcm","clk":"4234469856","pt":1631546136807,"mc":[{"id":"1.187562121","rc":[{"batl":[[0,1.73,34.5],[1,1.78,33.25],[2,2.16,347.9]],"ltp":1.6,"tv":5890.12,"id":20955040},{"batb":[[0,2.36,6.43],[1,2.28,5.91],[2,2.18,34.06]],"ltp":2.66,"tv":940.7,"id":9625551}]}]}
{"op":"mcm","clk":"4234469873","pt":1631546137123,"mc":[{"id":"1.187562121","rc":[{"batl":[[0,1.78,33.25],[1,2.16,347.9],[2,810,0.07]],"ltp":1.6,"tv":5890.12,"id":20955040},{"batb":[[0,2.28,5.91],[1,2.18,34.06],[2,1.8,11.93]],"ltp":2.66,"tv":940.7,"id":9625551}]}]}
{"op":"mcm","clk":"4234469959","pt":1631546138425,"mc":[{"id":"1.187562121","rc":[{"batb":[[0,1.69,6.92],[1,1.58,2],[2,1.52,2]],"batl":[[0,1.78,52.18],[1,1.83,600.31],[2,2.16,347.9]],"ltp":1.6,"tv":5890.12,"id":20955040},{"batb":[[2,1.7,17.05]],"batl":[[0,2.36,7.05],[1,2.42,12.4],[2,2.44,6.2]],"ltp":2.66,"tv":940.7,"id":9625551}]}]}
{"op":"mcm","clk":"4234470038","pt":1631546139418,"mc":[{"id":"1.187562121","rc":[{"batb":[[1,1.68,40.6],[2,1.58,2]],"batl":[[0,1.74,5.75],[1,1.78,52.18],[2,1.79,16.76]],"ltp":1.6,"tv":5890.12,"id":20955040},{"batb":[[2,1.89,26.67]],"ltp":2.66,"tv":940.7,"id":9625551}]}]}
{"op":"mcm","clk":"4234470398","pt":1631546144649,"mc":[{"id":"1.187562121","rc":[{"batb":[[2,1.59,47.11]],"ltp":1.6,"tv":5890.12,"id":20955040},{"batb":[[2,2,29.51]],"ltp":2.66,"tv":940.7,"id":9625551}]}]}
{"op":"mcm","clk":"4234470686","pt":1631546146837,"mc":[{"id":"1.187562121","rc":[{"batb":[[0,1.68,40.6],[1,1.58,2],[2,1.55,53.35]],"batl":[[0,2.08,7.94],[1,2.16,347.9],[2,810,0.07]],"ltp":1.6,"tv":5890.12,"id":20955040},{"batb":[[0,2.18,34.06],[1,1.93,30.93],[2,1.89,26.67]],"batl":[[0,2.86,4.25],[1,2.98,4.25],[2,3.1,4.05]],"ltp":2.66,"tv":940.7,"id":9625551}]}]}
{"op":"mcm","clk":"4234470834","pt":1631546147850,"mc":[{"id":"1.187562121","rc":[{"batb":[[0,1.58,2],[1,1.55,53.35],[2,1.54,43.12]],"ltp":1.6,"tv":5890.12,"id":20955040},{"batb":[[0,1.93,30.93],[1,1.89,26.67],[2,1.7,17.05]],"ltp":2.66,"tv":940.7,"id":9625551}]}]}
{"op":"mcm","clk":"4234471475","pt":1631546151756,"mc":[{"id":"1.187562121","rc":[{"batl":[[0,2.16,347.9],[1,810,0.07],[2,810,0]],"ltp":1.6,"tv":5890.12,"id":20955040}]}]}
{"op":"mcm","clk":"4234471802","pt":1631546153768,"mc":[{"id":"1.187562121","rc":[{"batb":[[0,1.59,44.11],[1,1.58,2],[2,1.55,53.35]],"batl":[[0,2,24.53],[1,2.16,347.9],[2,810,0.07]],"ltp":1.6,"tv":5890.12,"id":20955040},{"batb":[[0,2,21.98],[1,1.93,30.93],[2,1.89,26.67]],"batl":[[0,2.7,5.35],[1,2.86,4.25],[2,2.98,4.25]],"ltp":2.66,"tv":940.7,"id":9625551}]}]}
{"op":"mcm","clk":"4234471940","pt":1631546154774,"mc":[{"id":"1.187562121","rc":[{"trd":[[1.6,56.93]],"batb":[[0,1.58,2],[1,1.55,53.35],[2,1.54,43.12]],"batl":[[0,1.6,112.78],[1,1.62,6.17],[2,1.64,19.71]],"ltp":1.6,"tv":5902.34,"id":20955040},{"trd":[[2.66,21.21]],"batb":[[0,2.56,11.72],[1,2.54,5.86],[2,2.52,5.86]],"batl":[[0,2.78,396.97]],"ltp":2.66,"tv":948.05,"id":9625551}],"tv":6850.39}]}
{"op":"mcm","clk":"4234472112","pt":1631546155888,"mc":[{"id":"1.187562121","rc":[{"batl":[[0,2.74,10.94],[1,2.76,5.48],[2,2.78,402.45]],"ltp":2.66,"tv":948.05,"id":9625551}]}]}
{"op":"mcm","clk":"4234472611","pt":1631546159680,"mc":[{"id":"1.187562121","rc":[{"trd":[[1.6,63.59]],"batl":[[0,1.6,106.12]],"ltp":1.6,"tv":5909.0,"id":20955040},{"trd":[[2.66,25.21]],"ltp":2.66,"tv":952.05,"id":9625551}],"tv":6861.05}]}
{"op":"mcm","clk":"4234472939","pt":1631546162977,"mc":[{"id":"1.187562121","rc":[{"batl":[[0,1.6,247.12]],"ltp":1.6,"tv":5909.0,"id":20955040}]}]}
{"op":"mcm","clk":"4234473159","pt":1631546164679,"mc":[{"id":"1.187562121","rc":[{"batb":[[1,1.52,52.99],[2,1.51,47.99]],"batl":[[0,1.6,141],[1,1.75,31.7],[2,1.8,30.92]],"ltp":1.6,"tv":5909.0,"id":20955040},{"batb":[[0,2.32,6.14],[1,2.24,6.77],[2,2.16,34.81]],"batl":[[0,2.94,4.25],[1,2.98,4.25],[2,3.05,3.7]],"ltp":2.66,"tv":952.05,"id":9625551}]}]}
{"op":"mcm","clk":"4234473318","pt":1631546165893,"mc":[{"id":"1.187562121","rc":[{"batl":[[0,1.75,31.7],[1,1.8,30.92],[2,2.16,347.9]],"ltp":1.6,"tv":5909.0,"id":20955040}]}]}
{"op":"mcm","clk":"4234473358","pt":1631546166253,"mc":[{"id":"1.187562121","rc":[{"batl":[[0,1.8,30.92],[1,2.16,347.9],[2,810,0.07]],"ltp":1.6,"tv":5909.0,"id":20955040},{"batb":[[0,2.24,6.77],[1,2.16,34.81],[2,1.8,11.93]],"ltp":2.66,"tv":952.05,"id":9625551}]}]}
{"op":"mcm","clk":"4234474120","pt":1631546172908,"mc":[{"id":"1.187562121","rc":[{"batl":[[0,1.75,35.3],[1,1.8,30.92],[2,2.16,347.9]],"ltp":1.6,"tv":5909.0,"id":20955040},{"batb":[[0,2.32,6.14],[1,2.24,6.77],[2,2.16,34.81]],"ltp":2.66,"tv":952.05,"id":9625551}]}]}
{"op":"mcm","clk":"4234474147","pt":1631546173213,"mc":[{"id":"1.187562121","rc":[{"batl":[[0,1.8,30.92],[1,2.16,347.9],[2,810,0.07]],"ltp":1.6,"tv":5909.0,"id":20955040},{"batb":[[0,2.24,6.77],[1,2.16,34.81],[2,1.8,11.93]],"ltp":2.66,"tv":952.05,"id":9625551}]}]}
{"op":"mcm","clk":"4234475275","pt":1631546184721,"mc":[{"id":"1.187562121","rc":[{"batl":[[1,810,0.07],[2,810,0]],"ltp":1.6,"tv":5909.0,"id":20955040}]}]}
{"op":"mcm","clk":"4234475440","pt":1631546186626,"mc":[{"id":"1.187562121","rc":[{"trd":[[1.58,4]],"batb":[[0,1.52,2],[1,1.51,47.99],[2,1.49,54.01]],"batl":[[0,1.54,10.72],[1,1.55,6.45],[2,1.62,1094.16]],"ltp":1.58,"tv":5913.0,"id":20955040},{"batb":[[0,2.84,10.56],[1,2.82,5.28],[2,2.8,5.28]],"batl":[[0,2.92,5.07],[1,2.96,215.48],[2,2.98,4.25]],"ltp":2.66,"tv":952.05,"id":9625551}],"tv":6865.05}]}
{"op":"mcm","clk":"4234475944","pt":1631546192435,"mc":[{"id":"1.187562121","rc":[{"batl":[[0,1.54,202.72]],"ltp":1.58,"tv":5913.0,"id":20955040}]}]}
{"op":"mcm","clk":"4234476025","pt":1631546193538,"mc":[{"id":"1.187562121","rc":[{"batl":[[2,1.6,41.56]],"ltp":1.58,"tv":5913.0,"id":20955040}]}]}
{"op":"mcm","clk":"4234476299","pt":1631546196830,"mc":[{"id":"1.187562121","rc":[{"trd":[[1.51,623.36],[1.52,3200.47]],"batb":[[0,1.49,54.01],[1,1.48,137.63],[2,1.47,10.14]],"batl":[[0,1.51,223.75],[1,1.54,202.72],[2,1.55,6.45]],"ltp":1.51,"tv":6445.12,"id":20955040},{"trd":[[2.92,533.46],[2.96,269.03]],"batl":[[0,2.98,4.25],[1,3.05,3.7],[2,3.1,4.05]],"ltp":2.96,"tv":1172.6,"id":9625551}],"tv":7617.72}]}
{"op":"mcm","clk":"4234476577","pt":1631546199927,"mc":[{"id":"1.187562121","rc":[{"trd":[[1.51,638.68]],"batl":[[0,1.51,216.09]],"ltp":1.51,"tv":6460.44,"id":20955040}],"tv":7633.04}]}
{"op":"mcm","clk":"4234476962","pt":1631546203811,"mc":[{"id":"1.187562121","rc":[{"batb":[[0,1.43,72.81],[1,1.38,455.1],[2,1.25,238.62]],"batl":[[1,1.6,41.56],[2,1.63,40.5]],"ltp":1.51,"tv":6460.44,"id":20955040},{"batb":[[0,2.66,5.28],[1,2.58,5.56],[2,2.42,25.75]],"batl":[[0,3.3,3.55],[1,6,3],[2,6.4,3]],"ltp":2.96,"tv":1172.6,"id":9625551}]}]}
{"op":"mcm","clk":"4234477024","pt":1631546204653,"mc":[{"id":"1.187562121","rc":[{"batl":[[0,1.63,40.5],[1,2.04,388.69],[2,810,0.07]],"ltp":1.51,"tv":6460.44,"id":20955040},{"batb":[[0,2.58,5.56],[1,2.42,25.75],[2,1.8,11.93]],"ltp":2.96,"tv":1172.6,"id":9625551}]}]}
{"op":"mcm","clk":"4234477244","pt":1631546206848,"mc":[{"id":"1.187562121","rc":[{"batb":[[0,1.44,63.17],[1,1.43,72.81],[2,1.38,455.1]],"ltp":1.51,"tv":6460.44,"id":20955040}]}]}
{"op":"mcm","clk":"4234477356","pt":1631546207846,"mc":[{"id":"1.187562121","rc":[{"batl":[[0,1.6,40.11],[1,1.63,40.5],[2,2.04,388.69]],"ltp":1.51,"tv":6460.44,"id":20955040},{"batb":[[0,2.66,5.28],[1,2.58,5.56],[2,2.42,25.75]],"ltp":2.96,"tv":1172.6,"id":9625551}]}]}
{"op":"mcm","clk":"4234477375","pt":1631546208053,"mc":[{"id":"1.187562121","rc":[{"batl":[[0,1.63,40.5],[1,2.04,388.69],[2,810,0.07]],"ltp":1.51,"tv":6460.44,"id":20955040},{"batb":[[0,2.58,5.56],[1,2.42,25.75],[2,1.8,11.93]],"ltp":2.96,"tv":1172.6,"id":9625551}]}]}
{"op":"mcm","clk":"4234477753","pt":1631546212207,"mc":[{"id":"1.187562121","rc":[{"batl":[[0,2.04,388.69],[1,810,0.07],[2,810,0]],"ltp":1.51,"tv":6460.44,"id":20955040}]}]}
{"op":"mcm","clk":"4234478002","pt":1631546214905,"mc":[{"id":"1.187562121","rc":[{"batb":[[0,1.45,500.84],[1,1.44,63.17],[2,1.43,72.81]],"batl":[[0,1.5,2153.41],[1,1.54,1044.08],[2,1.56,9.85]],"ltp":1.51,"tv":6460.44,"id":20955040},{"batb":[[0,3.05,55.43],[1,3,91.24],[2,2.98,24.58]],"batl":[[0,3.15,7.16],[1,3.3,3.55],[2,6,3]],"ltp":2.96,"tv":1172.6,"id":9625551}]}]}
{"op":"mcm","clk":"4234478093","pt":1631546215905,"mc":[{"id":"1.187562121","rc":[{"batb":[[2,1.43,177.71]],"batl":[[0,1.49,17.99],[1,1.5,6.67],[2,1.54,1044.08]],"ltp":1.51,"tv":6460.44,"id":20955040},{"batb":[[0,3.05,35.76],[1,3,57.65],[2,2.98,14.75]],"batl":[[2,3.45,2.9]],"ltp":2.96,"tv":1172.6,"id":9625551}]}]}
{"op":"mcm","clk":"4234478129","pt":1631546216324,"mc":[{"id":"1.187562121","rc":[{"batb":[[2,1.43,93.79]],"ltp":1.51,"tv":6460.44,"id":20955040},{"batb":[[0,3.05,16.09],[1,3,47.82],[2,2.98,4.92]],"ltp":2.96,"tv":1172.6,"id":9625551}]}]}
{"op":"mcm","clk":"4234478715","pt":1631546223089,"mc":[{"id":"1.187562121","rc":[{"batl":[[0,1.48,273],[1,1.49,17.99],[2,1.5,6.67]],"ltp":1.51,"tv":6460.44,"id":20955040}]}]}
{"op":"mcm","clk":"4234479088","pt":1631546227515,"mc":[{"id":"1.187562121","rc":[{"trd":[[1.45,854.1],[1.46,64.8]],"batb":[[0,1.45,92.76]],"ltp":1.45,"tv":7292.05,"id":20955040},{"trd":[[3.15,70.73]],"batl":[[0,3.3,3.55],[1,3.45,2.9],[2,6,3]],"ltp":3.15,"tv":1179.76,"id":9625551}],"tv":8471.81}]}
{"op":"mcm","clk":"4234479954","pt":1631546237705,"mc":[{"id":"1.187562121","rc":[{"trd":[[1.45,1039.62]],"batb":[[0,1.44,63.17],[1,1.43,93.79],[2,1.42,10.5]],"batl":[[0,1.45,613.12],[1,1.48,273],[2,1.49,17.99]],"ltp":1.45,"tv":7477.57,"id":20955040},{"batb":[[0,3.05,9.84]],"ltp":3.15,"tv":1179.76,"id":9625551}],"tv":8657.33}]}
{"op":"mcm","clk":"4234480233","pt":1631546240624,"mc":[{"id":"1.187562121","rc":[{"trd":[[1.45,1053.63]],"batl":[[0,1.45,599.11]],"ltp":1.45,"tv":7491.58,"id":20955040},{"trd":[[3.2,11]],"batb":[[0,3.1,6.66],[1,3.05,9.84],[2,3,47.82]],"ltp":3.2,"tv":1186.11,"id":9625551}],"tv":8677.69}]}
{"op":"mcm","clk":"4234480675","pt":1631546246935,"mc":[{"id":"1.187562121","rc":[{"batl":[[0,1.48,273],[1,1.49,17.99],[2,1.5,6.67]],"ltp":1.45,"tv":7491.58,"id":20955040}]}]}
{"op":"mcm","clk":"4234480995","pt":1631546250818,"mc":[{"id":"1.187562121","rc":[{"batb":[[0,3.05,9.84],[1,3,47.82],[2,2.98,4.92]],"ltp":3.2,"tv":1186.11,"id":9625551}]}]}
{"op":"mcm","clk":"4234481258","pt":1631546253866,"mc":[{"id":"1.187562121","rc":[{"batb":[[0,3.15,6.45],[1,3.05,9.84],[2,3,47.82]],"batl":[[0,3.25,6.15],[1,3.3,3.55],[2,3.45,2.9]],"ltp":3.2,"tv":1186.11,"id":9625551}]}]}
{"op":"mcm","clk":"4234482254","pt":1631546264662,"mc":[{"id":"1.187562121","rc":[{"trd":[[1.43,356.39],[1.44,189.76]],"batb":[[0,1.42,10.5],[1,1.41,10.5],[2,1.38,455.1]],"batl":[[0,1.43,280.12],[1,1.48,273],[2,1.49,17.99]],"ltp":1.43,"tv":7827.57,"id":20955040},{"trd":[[3.25,9.22],[3.3,54.99]],"batl":[[0,3.45,2.9],[1,6,3],[2,6.4,3]],"ltp":3.3,"tv":1195.81,"id":9625551}],"tv":9023.38}]}
{"op":"mcm","clk":"4234491072","pt":1631546267862,"mc":[{"id":"1.187562121","rc":[{"trd":[[1.43,423.15]],"batl":[[0,1.43,246.74]],"ltp":1.43,"tv":7894.33,"id":20955040}],"tv":9090.14}]}
{"op":"mcm","clk":"4234491127","pt":1631546268646,"mc":[{"id":"1.187562121","rc":[{"batb":[[0,1.42,85.32]],"ltp":1.43,"tv":7894.33,"id":20955040}]}]}
{"op":"mcm","clk":"4234491737","pt":1631546274847,"mc":[{"id":"1.187562121","rc":[{"batb":[[0,3.05,9.84],[1,3,47.82],[2,2.98,4.92]],"ltp":3.3,"tv":1195.81,"id":9625551}]}]}
{"op":"mcm","clk":"4234491933","pt":1631546277763,"mc":[{"id":"1.187562121","rc":[{"trd":[[1.43,436.95]],"batl":[[0,1.43,232.94]],"ltp":1.43,"tv":7908.13,"id":20955040},{"trd":[[3.3,60.97]],"batb":[[0,3.2,6.25],[1,3.05,9.84],[2,3,47.82]],"ltp":3.3,"tv":1201.79,"id":9625551}],"tv":9109.92}]}
{"op":"mcm","clk":"4234492699","pt":1631546287996,"mc":[{"id":"1.187562121","rc":[{"batb":[[0,3.05,9.84],[1,3,47.82],[2,2.98,4.92]],"ltp":3.3,"tv":1201.79,"id":9625551}]}]}
{"op":"mcm","clk":"4234492870","pt":1631546290914,"mc":[{"id":"1.187562121","rc":[{"batb":[[0,3.25,6.06],[1,3.05,9.84],[2,3,47.82]],"batl":[[0,3.35,5.8],[1,3.45,2.9],[2,6,3]],"ltp":3.3,"tv":1201.79,"id":9625551}]}]}
{"op":"mcm","clk":"4234493019","pt":1631546292803,"mc":[{"id":"1.187562121","rc":[{"batl":[[0,1.48,273],[1,1.49,17.99],[2,1.5,6.67]],"ltp":1.43,"tv":7908.13,"id":20955040}]}]}
{"op":"mcm","clk":"4234493219","pt":1631546295901,"mc":[{"id":"1.187562121","rc":[{"trd":[[1.41,21],[1.42,200.03],[1.43,615.84]],"batb":[[0,1.38,455.1],[1,1.36,91.43],[2,1.2,487.76]],"batl":[[0,1.41,33.99],[1,1.48,273],[2,1.49,17.99]],"ltp":1.41,"tv":8292.34,"id":20955040},{"trd":[[3.35,8.78]],"batl":[[0,3.45,2.9],[1,6,3],[2,6.4,3]],"ltp":3.35,"tv":1207.59,"id":9625551}],"tv":9499.94}]}
{"op":"mcm","clk":"4234493433","pt":1631546299008,"mc":[{"id":"1.187562121","rc":[{"trd":[[1.41,60.2]],"batl":[[0,1.41,14.39]],"ltp":1.41,"tv":8331.54,"id":20955040}],"tv":9539.14}]}
{"op":"mcm","clk":"4234494031","pt":1631546306421,"mc":[{"id":"1.187562121","rc":[{"trd":[[1.41,88.99]],"batb":[[0,1.41,38.94],[1,1.38,455.1],[2,1.36,91.43]],"batl":[[0,1.49,17.99],[1,1.5,6.67],[2,1.52,50.01]],"ltp":1.41,"tv":8360.33,"id":20955040},{"batb":[[0,3.05,9.84],[1,3,47.82],[2,2.98,4.92]],"batl":[[1,3.9,3.25],[2,4.1,2.85]],"ltp":3.35,"tv":1207.59,"id":9625551}],"tv":9567.92}]}
{"op":"mcm","clk":"4234494251","pt":1631546309137,"mc":[{"id":"1.187562121","rc":[{"batb":[[0,3.3,5.88],[1,3.05,9.84],[2,3,47.82]],"batl":[[0,3.4,5.64],[1,3.45,2.9],[2,3.9,3.25]],"ltp":3.35,"tv":1207.59,"id":9625551}]}]}
{"op":"mcm","clk":"4234494399","pt":1631546310704,"mc":[{"id":"1.187562121","rc":[{"batb":[[0,1.41,44.72]],"ltp":1.41,"tv":8360.33,"id":20955040}]}]}
{"op":"mcm","clk":"4234494648","pt":1631546313824,"mc":[{"id":"1.187562121","rc":[{"batb":[[0,1.41,38.94]],"batl":[[0,2.04,388.69],[1,1.5,0],[2,1.52,0]],"ltp":1.41,"tv":8360.33,"id":20955040},{"batb":[[0,2.88,41.94],[1,2.76,19.12],[2,2,11.93]],"batl":[[0,3.9,3.25],[1,6,3],[2,6.4,3]],"ltp":3.35,"tv":1207.59,"id":9625551}]}]}
{"op":"mcm","clk":"4234494692","pt":1631546314199,"mc":[{"id":"1.187562121","rc":[{"batb":[[2,1.37,69.77]],"batl":[[0,1.55,50.3],[1,2.04,388.69]],"ltp":1.41,"tv":8360.33,"id":20955040},{"batb":[[0,2.8,5.08]],"batl":[[0,3.75,2.74],[1,3.9,3.25],[2,6,3]],"ltp":3.35,"tv":1207.59,"id":9625551}]}]}
{"op":"mcm","clk":"4234494954","pt":1631546317538,"mc":[{"id":"1.187562121","rc":[{"batb":[[0,2.8,23.62],[1,2,11.93],[2,1.8,11.93]],"ltp":3.35,"tv":1207.59,"id":9625551}]}]}
{"op":"mcm","clk":"4234495197","pt":1631546320726,"mc":[{"id":"1.187562121","rc":[{"batl":[[0,1.52,47.51],[1,1.55,50.3],[2,2.04,388.69]],"ltp":1.41,"tv":8360.33,"id":20955040},{"batb":[[0,2.92,4.69],[1,2.8,23.62],[2,2,11.93]],"ltp":3.35,"tv":1207.59,"id":9625551}]}]}
{"op":"mcm","clk":"4234495212","pt":1631546320933,"mc":[{"id":"1.187562121","rc":[{"batl":[[0,1.55,50.3],[1,2.04,388.69],[2,2.04,0]],"ltp":1.41,"tv":8360.33,"id":20955040},{"batb":[[0,2.8,23.62],[1,2,11.93],[2,1.8,11.93]],"ltp":3.35,"tv":1207.59,"id":9625551}]}]}
{"op":"mcm","clk":"4234495491","pt":1631546324421,"mc":[{"id":"1.187562121","rc":[{"batl":[[0,2.04,388.69],[1,2.04,0]],"ltp":1.41,"tv":8360.33,"id":20955040}]}]}
{"op":"mcm","clk":"4234495690","pt":1631546326715,"mc":[{"id":"1.187562121","rc":[{"batb":[[0,1.45,62.06],[1,1.44,31.03],[2,1.43,31.03]],"ltp":1.41,"tv":8360.33,"id":20955040},{"trd":[[3.1,17.28]],"batl":[[0,3.2,48.46],[1,3.75,2.74],[2,3.9,3.25]],"ltp":3.1,"tv":1218.51,"id":9625551}],"tv":9578.84}]}
{"op":"mcm","clk":"4234495794","pt":1631546327816,"mc":[{"id":"1.187562121","rc":[{"batb":[[0,1.45,89.13],[1,1.44,10.34],[2,1.43,10.34]],"batl":[[0,1.54,465.99],[1,1.55,6.45],[2,2.04,388.69]],"ltp":1.41,"tv":8360.33,"id":20955040},{"batb":[[0,2.98,30.2],[1,2.96,5.04],[2,2.94,5.04]],"batl":[[0,3.1,211.03],[1,3.2,48.46],[2,3.75,2.74]],"ltp":3.1,"tv":1218.51,"id":9625551}]}]}
{"op":"mcm","clk":"4234496213","pt":1631546332837,"mc":[{"id":"1.187562121","rc":[{"batl":[[0,1.51,53],[1,1.54,465.99],[2,1.55,6.45]],"ltp":1.41,"tv":8360.33,"id":20955040}]}]}
{"op":"mcm","clk":"4234496331","pt":1631546334137,"mc":[{"id":"1.187562121","rc":[{"batb":[[0,1.45,144.94],[2,1.43,78.77]],"batl":[[1,1.54,518.24]],"ltp":1.41,"tv":8360.33,"id":20955040},{"batl":[[2,3.25,3.7]],"ltp":3.1,"tv":1218.51,"id":9625551}]}]}
{"op":"mcm","clk":"4234496553","pt":1631546336640,"mc":[{"id":"1.187562121","rc":[{"batl":[[1,3.2,40.62]],"ltp":3.1,"tv":1218.51,"id":9625551}]}]}
{"op":"mcm","clk":"4234496600","pt":1631546337448,"mc":[{"id":"1.187562121","rc":[{"batb":[[0,1.43,68.43],[1,1.41,38.94],[2,1.39,80.61]],"batl":[[0,1.56,42.42],[1,2.04,388.69],[2,1.55,0]],"ltp":1.41,"tv":8360.33,"id":20955040},{"batb":[[0,2.78,5.16],[1,2.66,21.22],[2,2,11.93]],"batl":[[0,3.35,3.7],[1,3.75,2.74],[2,3.9,3.25]],"ltp":3.1,"tv":1218.51,"id":9625551}]}]}
{"op":"mcm","clk":"4234497079","pt":1631546343756,"mc":[{"id":"1.187562121","rc":[{"batl":[[0,1.5,21.79],[1,1.54,43.75],[2,1.56,42.42]],"ltp":1.41,"tv":8360.33,"id":20955040},{"batb":[[0,3,20],[1,2.84,4.72],[2,2.78,5.16]],"batl":[[0,3.1,20.25],[1,3.35,3.7],[2,3.75,2.74]],"ltp":3.1,"tv":1218.51,"id":9625551}]}]}
{"op":"mcm","clk":"4234497128","pt":1631546344385,"mc":[{"id":"1.187562121","rc":[{"batl":[[0,1.56,42.42],[1,2.04,388.69],[2,1.56,0]],"ltp":1.41,"tv":8360.33,"id":20955040},{"batb":[[0,2.78,5.16],[1,2.66,21.22],[2,2,11.93]],"batl":[[0,3.35,3.7],[1,3.75,2.74],[2,3.9,3.25]],"ltp":3.1,"tv":1218.51,"id":9625551}]}]}
{"op":"mcm","clk":"4234497363","pt":1631546347662,"mc":[{"id":"1.187562121","rc":[{"batb":[[0,1.45,57.41],[1,1.43,68.43],[2,1.41,38.94]],"batl":[[0,1.54,50.75],[1,1.56,42.42],[2,2.04,388.69]],"ltp":1.41,"tv":8360.33,"id":20955040},{"batb":[[0,2.84,4.22],[1,2.78,5.16],[2,2.66,21.22]],"batl":[[0,3.25,3.86],[1,3.35,3.7],[2,3.75,2.74]],"ltp":3.1,"tv":1218.51,"id":9625551}]}]}
{"op":"mcm","clk":"4234497393","pt":1631546347981,"mc":[{"id":"1.187562121","rc":[{"batb":[[0,1.43,68.43],[1,1.41,38.94],[2,1.39,80.61]],"batl":[[0,1.56,42.42],[1,2.04,388.69],[2,2.04,0]],"ltp":1.41,"tv":8360.33,"id":20955040},{"batb":[[0,2.78,5.16],[1,2.66,21.22],[2,2,11.93]],"batl":[[0,3.35,3.7],[1,3.75,2.74],[2,3.9,3.25]],"ltp":3.1,"tv":1218.51,"id":9625551}]}]}
{"op":"mcm","clk":"4234497931","pt":1631546354760,"mc":[{"id":"1.187562121","rc":[{"batb":[[0,1.45,57.81],[1,1.43,68.43],[2,1.41,38.94]],"batl":[[0,1.54,48.25],[1,1.56,42.42],[2,2.04,388.69]],"ltp":1.41,"tv":8360.33,"id":20955040},{"batb":[[0,2.84,4.47],[1,2.78,5.16],[2,2.66,21.22]],"batl":[[0,3.25,3.86],[1,3.35,3.7],[2,3.75,2.74]],"ltp":3.1,"tv":1218.51,"id":9625551}]}]}
{"op":"mcm","clk":"4234497949","pt":1631546355074,"mc":[{"id":"1.187562121","rc":[{"batb":[[0,1.43,68.43],[1,1.41,38.94],[2,1.39,80.61]],"batl":[[0,1.56,42.42],[1,2.04,388.69],[2,2.04,0]],"ltp":1.41,"tv":8360.33,"id":20955040},{"batb":[[0,2.78,5.16],[1,2.66,21.22],[2,2,11.93]],"batl":[[0,3.35,3.7],[1,3.75,2.74],[2,3.9,3.25]],"ltp":3.1,"tv":1218.51,"id":9625551}]}]}
{"op":"mcm","clk":"4234498551","pt":1631546361770,"mc":[{"id":"1.187562121","rc":[{"batb":[[0,1.45,58.81],[1,1.43,68.43],[2,1.41,38.94]],"batl":[[0,1.54,46.75],[1,1.56,42.42],[2,2.04,388.69]],"ltp":1.41,"tv":8360.33,"id":20955040},{"batb":[[0,2.84,4.47],[1,2.78,5.16],[2,2.66,21.22]],"batl":[[0,3.25,3.66],[1,3.35,3.7],[2,3.75,2.74]],"ltp":3.1,"tv":1218.51,"id":9625551}]}]}
{"op":"mcm","clk":"4234498586","pt":1631546362185,"mc":[{"id":"1.187562121","rc":[{"batb":[[0,1.43,68.43],[1,1.41,38.94],[2,1.39,80.61]],"batl":[[0,1.56,42.42],[1,2.04,388.69],[2,2.04,0]],"ltp":1.41,"tv":8360.33,"id":20955040},{"batb":[[0,2.78,5.16],[1,2.66,21.22],[2,2,11.93]],"batl":[[0,3.35,3.7],[1,3.75,2.74],[2,3.9,3.25]],"ltp":3.1,"tv":1218.51,"id":9625551}]}]}
{"op":"mcm","clk":"4234499147","pt":1631546368875,"mc":[{"id":"1.187562121","rc":[{"batb":[[0,1.45,51.21],[1,1.43,68.43],[2,1.41,38.94]],"batl":[[0,1.54,49.75]],"ltp":1.41,"tv":8360.33,"id":20955040},{"batb":[[0,2.84,4.97],[1,2.78,5.16],[2,2.66,21.22]],"batl":[[0,3.25,3.22],[1,3.35,3.7],[2,3.75,2.74]],"ltp":3.1,"tv":1218.51,"id":9625551}]}]}
{"op":"mcm","clk":"4234499219","pt":1631546369705,"mc":[{"id":"1.187562121","rc":[{"batb":[[0,1.43,68.43],[1,1.41,38.94],[2,1.39,80.61]],"ltp":1.41,"tv":8360.33,"id":20955040},{"batb":[[0,2.78,5.16],[1,2.66,21.22],[2,2,11.93]],"batl":[[0,3.35,3.7],[1,6,3],[2,6.4,3]],"ltp":3.1,"tv":1218.51,"id":9625551}]}]}
{"op":"mcm","clk":"4234499301","pt":1631546370695,"mc":[{"id":"1.187562121","rc":[{"trd":[[1.43,619.54]],"batb":[[0,1.43,64.73],[1,1.41,685.11],[2,1.4,13.74]],"batl":[[0,1.45,62.06],[1,1.46,31.03],[2,1.47,85.53]],"ltp":1.43,"tv":8364.03,"id":20955040},{"trd":[[3.35,17.76]],"batb":[[0,3.1,295.92],[1,2.78,5.16],[2,2.66,21.22]],"batl":[[0,3.5,5.5]],"ltp":3.35,"tv":1227.49,"id":9625551}],"tv":9591.52}]}
{"op":"mcm","clk":"4234499377","pt":1631546371688,"mc":[{"id":"1.187562121","rc":[{"batl":[[0,1.45,20.68],[1,1.46,10.34],[2,1.47,64.84]],"ltp":1.43,"tv":8364.03,"id":20955040},{"batb":[[1,3,38.08],[2,2.84,17.87]],"batl":[[0,3.5,8.36],[1,3.55,8.44],[2,3.6,4.22]],"ltp":3.35,"tv":1227.49,"id":9625551}]}]}
{"op":"mcm","clk":"4234499802","pt":1631546376704,"mc":[{"id":"1.187562121","rc":[{"batb":[[1,1.41,646.17]],"ltp":1.43,"tv":8364.03,"id":20955040}]}]}
{"op":"mcm","clk":"4234499870","pt":1631546377393,"mc":[{"id":"1.187562121","rc":[{"batb":[[1,3,41.65],[2,2.96,4.38]],"ltp":3.35,"tv":1227.49,"id":9625551}]}]}
{"op":"mcm","clk":"4234500117","pt":1631546380685,"mc":[{"id":"1.187562121","rc":[{"batb":[[2,1.39,80.61]],"batl":[[0,1.45,189.68]],"ltp":1.43,"tv":8364.03,"id":20955040},{"batl":[[0,3.5,2.86]],"ltp":3.35,"tv":1227.49,"id":9625551}]}]}
{"op":"mcm","clk":"4234500401","pt":1631546383877,"mc":[{"id":"1.187562121","rc":[{"trd":[[1.45,1117.63]],"batl":[[0,1.46,10.34],[1,1.47,64.84],[2,1.49,57.21]],"ltp":1.45,"tv":8428.03,"id":20955040},{"batb":[[0,3.3,5.82],[1,3.1,295.92],[2,3,41.65]],"batl":[[0,3.4,5.58],[1,3.5,2.86],[2,3.55,8.44]],"ltp":3.35,"tv":1227.49,"id":9625551}],"tv":9655.52}]}
{"op":"mcm","clk":"4234500696","pt":1631546387890,"mc":[{"id":"1.187562121","rc":[{"batb":[[0,1.33,102.08],[1,1.31,484.59],[2,1.2,487.76]],"batl":[[0,1.44,383],[1,1.49,50.5],[2,1.51,56.5]],"ltp":1.45,"tv":8428.03,"id":20955040},{"batb":[[0,2.96,4.38],[1,2.84,17.87],[2,2,11.93]],"batl":[[0,6,3],[1,6.4,3],[2,6.6,3]],"ltp":3.35,"tv":1227.49,"id":9625551}]}]}
{"op":"mcm","clk":"4234500763","pt":1631546388768,"mc":[{"id":"1.187562121","rc":[{"batl":[[0,1.49,50.5],[1,1.51,56.5],[2,1.89,441.74]],"ltp":1.45,"tv":8428.03,"id":20955040}]}]}
{"op":"mcm","clk":"4234500772","pt":1631546388979,"mc":[{"id":"1.187562121","rc":[{"batl":[[0,1.51,56.5],[1,1.89,441.74],[2,1.89,0]],"ltp":1.45,"tv":8428.03,"id":20955040}]}]}
{"op":"mcm","clk":"4234500883","pt":1631546390493,"mc":[{"id":"1.187562121","rc":[{"batb":[[0,1.33,176.61]],"ltp":1.45,"tv":8428.03,"id":20955040},{"batl":[[0,4.1,2.75],[1,6,3],[2,6.4,3]],"ltp":3.35,"tv":1227.49,"id":9625551}]}]}
{"op":"mcm","clk":"4234501111","pt":1631546393722,"mc":[{"id":"1.187562121","rc":[{"batb":[[0,1.36,80.68],[1,1.33,176.61],[2,1.31,484.59]],"ltp":1.45,"tv":8428.03,"id":20955040},{"batl":[[0,3.8,2.82],[1,4.1,2.75],[2,6,3]],"ltp":3.35,"tv":1227.49,"id":9625551}]}]}
{"op":"mcm","clk":"4234501257","pt":1631546395696,"mc":[{"id":"1.187562121","rc":[{"batb":[[0,1.33,176.61],[1,1.31,484.59],[2,1.2,487.76]],"batl":[[0,1.49,54.5],[1,1.51,56.5],[2,1.89,441.74]],"ltp":1.45,"tv":8428.03,"id":20955040},{"batl":[[0,4.1,2.75],[1,6,3],[2,6.4,3]],"ltp":3.35,"tv":1227.49,"id":9625551}]}]}
{"op":"mcm","clk":"4234501279","pt":1631546396009,"mc":[{"id":"1.187562121","rc":[{"batl":[[0,1.51,56.5],[1,1.89,441.74],[2,1.89,0]],"ltp":1.45,"tv":8428.03,"id":20955040}]}]}
{"op":"mcm","clk":"4234501383","pt":1631546397719,"mc":[{"id":"1.187562121","rc":[{"batb":[[0,1.44,7.47],[1,1.33,176.61],[2,1.31,484.59]],"ltp":1.45,"tv":8428.03,"id":20955040}]}]}
{"op":"mcm","clk":"4234501451","pt":1631546398802,"mc":[{"id":"1.187562121","rc":[{"batb":[[2,1.2,487.76]],"batl":[[1,1.89,0]],"ltp":1.45,"tv":8428.03,"id":20955040},{"batb":[[0,3,3.62],[1,2.96,4.38],[2,2.84,17.87]],"ltp":3.35,"tv":1227.49,"id":9625551}]}]}
{"op":"mcm","clk":"4234501520","pt":1631546399790,"mc":[{"id":"1.187562121","rc":[{"trd":[[1.44,204.7]],"batb":[[0,1.34,741.81],[2,1.2,100]],"batl":[[0,1.38,152.17],[1,1.39,100.12],[2,1.4,309.58]],"ltp":1.44,"tv":8442.97,"id":20955040},{"batb":[[0,3.75,5.17],[1,3.55,8.79],[2,3.5,110.78]],"batl":[[0,3.9,7.38],[1,4.1,2.75],[2,6,3]],"ltp":3.35,"tv":1227.49,"id":9625551}],"tv":9670.46}]}
{"op":"mcm","clk":"4234501594","pt":1631546400729,"mc":[{"id":"1.187562121","rc":[{"batb":[[2,1.26,133.87]],"batl":[[0,1.38,108.69],[1,1.39,78.38],[2,1.4,287.84]],"ltp":1.44,"tv":8442.97,"id":20955040},{"batl":[[1,4,10],[2,4.1,6.51]],"ltp":3.35,"tv":1227.49,"id":9625551}]}]}
{"op":"mcm","clk":"4234501765","pt":1631546402521,"mc":[{"id":"1.187562121","rc":[{"trd":[[3.75,2.78]],"batb":[[0,3.75,3.78]],"ltp":3.75,"tv":1230.27,"id":9625551}],"tv":9673.25}]}
{"op":"mcm","clk":"4234501969","pt":1631546404826,"mc":[{"id":"1.187562121","rc":[{"batl":[[0,1.37,111],[1,1.38,108.69],[2,1.39,78.38]],"ltp":1.44,"tv":8442.97,"id":20955040},{"trd":[[3.75,10.34]],"batb":[[0,3.55,8.79],[1,3.5,110.78],[2,3.4,27.93]],"ltp":3.75,"tv":1237.83,"id":9625551}],"tv":9680.81}]}
{"op":"mcm","clk":"4234502085","pt":1631546406397,"mc":[{"id":"1.187562121","rc":[{"batb":[[2,1.28,87.91]],"ltp":1.44,"tv":8442.97,"id":20955040}]}]}
{"op":"mcm","clk":"4234502224","pt":1631546408128,"mc":[{"id":"1.187562121","rc":[{"batb":[[2,1.3,83.68]],"ltp":1.44,"tv":8442.97,"id":20955040}]}]}
{"op":"mcm","clk":"4234502586","pt":1631546412624,"mc":[{"id":"1.187562121","rc":[{"batl":[[0,4,10],[1,4.1,6.51],[2,4.2,3.76]],"ltp":3.75,"tv":1237.83,"id":9625551}]}]}
{"op":"mcm","clk":"4234502613","pt":1631546412935,"mc":[{"id":"1.187562121","rc":[{"batl":[[0,1.38,108.69],[1,1.39,78.38],[2,1.4,287.84]],"ltp":1.44,"tv":8442.97,"id":20955040}]}]}
{"op":"mcm","clk":"4234502880","pt":1631546416024,"mc":[{"id":"1.187562121","rc":[{"batl":[[0,1.36,291],[1,1.38,108.69],[2,1.39,78.38]],"ltp":1.44,"tv":8442.97,"id":20955040}]}]}
{"op":"mcm","clk":"4234503106","pt":1631546418746,"mc":[{"id":"1.187562121","rc":[{"batb":[[0,3.7,4.43],[1,3.55,8.79],[2,3.5,110.78]],"batl":[[0,3.85,8.39],[1,4,10],[2,4.1,6.51]],"ltp":3.75,"tv":1237.83,"id":9625551}]}]}
{"op":"mcm","clk":"4234503424","pt":1631546421856,"mc":[{"id":"1.187562121","rc":[{"batb":[[0,1.26,133.87],[1,1.25,607.24],[2,1.2,100]],"batl":[[0,1.44,59.58],[1,1.46,56.25],[2,1.47,55.5]],"ltp":1.44,"tv":8442.97,"id":20955040},{"batb":[[0,3.25,4.21],[1,3.15,4.23],[2,3.1,40.19]],"batl":[[0,5,2],[1,6,3],[2,6.4,3]],"ltp":3.75,"tv":1237.83,"id":9625551}]}]}
{"op":"mcm","clk":"4234503454","pt":1631546422169,"mc":[{"id":"1.187562121","rc":[{"batl":[[0,1.47,55.5],[1,1.77,508.04],[2,44,7.22]],"ltp":1.44,"tv":8442.97,"id":20955040},{"batb":[[0,3.1,40.19],[1,2,11.93],[2,1.8,11.93]],"ltp":3.75,"tv":1237.83,"id":9625551}]}]}
{"op":"mcm","clk":"4234503693","pt":1631546424845,"mc":[{"id":"1.187562121","rc":[{"batb":[[0,1.28,85.16],[1,1.26,133.87],[2,1.25,607.24]],"ltp":1.44,"tv":8442.97,"id":20955040},{"batl":[[0,4.6,2.36],[1,5,2],[2,6,3]],"ltp":3.75,"tv":1237.83,"id":9625551}]}]}
{"op":"mcm","clk":"4234503746","pt":1631546425632,"mc":[{"id":"1.187562121","rc":[{"batb":[[0,1.26,133.87],[1,1.25,607.24],[2,1.2,100]],"ltp":1.44,"tv":8442.97,"id":20955040},{"batl":[[0,5,2],[1,6,3],[2,6.4,3]],"ltp":3.75,"tv":1237.83,"id":9625551}]}]}
{"op":"mcm","clk":"4234504016","pt":1631546428828,"mc":[{"id":"1.187562121","rc":[{"batl":[[0,1.44,62.33],[1,1.47,55.5],[2,1.77,508.04]],"ltp":1.44,"tv":8442.97,"id":20955040},{"batb":[[0,3.25,3.41],[1,3.1,40.19],[2,2,11.93]],"ltp":3.75,"tv":1237.83,"id":9625551}]}]}
{"op":"mcm","clk":"4234504054","pt":1631546429351,"mc":[{"id":"1.187562121","rc":[{"batl":[[0,1.77,508.04],[1,44,7.22],[2,1.77,0]],"ltp":1.44,"tv":8442.97,"id":20955040},{"batb":[[0,3.1,40.19],[1,2,11.93],[2,1.8,11.93]],"ltp":3.75,"tv":1237.83,"id":9625551}]}]}
{"op":"mcm","clk":"4234504136","pt":1631546430458,"mc":[{"id":"1.187562121","rc":[{"batb":[[1,1.25,94.65]],"ltp":1.44,"tv":8442.97,"id":20955040}]}]}
{"op":"mcm","clk":"4234504257","pt":1631546431879,"mc":[{"id":"1.187562121","rc":[{"batb":[[0,1.28,100.91],[1,1.26,133.87],[2,1.25,94.65]],"ltp":1.44,"tv":8442.97,"id":20955040},{"batl":[[0,4.6,2.46],[1,5,2],[2,6,3]],"ltp":3.75,"tv":1237.83,"id":9625551}]}]}
{"op":"mcm","clk":"4234504298","pt":1631546432457,"mc":[{"id":"1.187562121","rc":[{"batb":[[0,1.28,19.21]],"batl":[[0,1.3,23.08],[1,1.31,11.54],[2,1.32,81.9]],"ltp":1.44,"tv":8442.97,"id":20955040},{"batb":[[0,4.4,50.01],[1,4.1,256.62],[2,3.1,40.19]],"batl":[[0,4.8,272.02]],"ltp":3.75,"tv":1237.83,"id":9625551}]}]}
{"op":"mcm","clk":"4234504399","pt":1631546433668,"mc":[{"id":"1.187562121","rc":[{"batb":[[1,1.26,157.67],[2,1.25,106.55]],"ltp":1.44,"tv":8442.97,"id":20955040},{"batb":[[2,3.9,38.84]],"batl":[[0,4.7,2.13],[1,4.8,272.02],[2,5,2]],"ltp":3.75,"tv":1237.83,"id":9625551}]}]}
{"op":"mcm","clk":"4234504709","pt":1631546437390,"mc":[{"id":"1.187562121","rc":[{"trd":[[4.4,63.44]],"batb":[[0,4.4,18.29]],"ltp":4.4,"tv":1301.27,"id":9625551}],"tv":9744.25}]}
{"op":"mcm","clk":"4234504986","pt":1631546440764,"mc":[{"id":"1.187562121","rc":[{"batl":[[0,1.3,440.08]],"ltp":1.44,"tv":8442.97,"id":20955040}]}]}
{"op":"mcm","clk":"4234505705","pt":1631546448482,"mc":[{"id":"1.187562121","rc":[{"trd":[[1.3,0.12]],"batl":[[0,1.3,440.02]],"ltp":1.3,"tv":8443.09,"id":20955040}],"tv":9744.37}]}
{"op":"mcm","clk":"4234505854","pt":1631546449784,"mc":[{"id":"1.187562121","rc":[{"trd":[[1.3,2.26]],"batb":[[0,1.22,638.1],[1,1.2,275.9],[2,1.19,103]],"batl":[[0,1.36,69.57],[1,1.39,66.5],[2,1.77,508.04]],"ltp":1.3,"tv":8445.23,"id":20955040},{"batb":[[0,3.75,2.79],[1,3.55,27.68],[2,2.2,42.6]],"batl":[[0,5.6,2.01],[1,6,3],[2,6.4,3]],"ltp":4.4,"tv":1301.27,"id":9625551}],"tv":9746.51}]}
{"op":"mcm","clk":"4234505897","pt":1631546449986,"mc":[{"id":"1.187562121","rc":[{"batl":[[0,1.39,66.5],[1,1.77,508.04],[2,44,7.22]],"ltp":1.3,"tv":8445.23,"id":20955040},{"batb":[[0,3.55,27.68],[1,2.2,42.6],[2,2,11.93]],"ltp":4.4,"tv":1301.27,"id":9625551}]}]}
{"op":"mcm","clk":"4234506060","pt":1631546451875,"mc":[{"id":"1.187562121","rc":[{"batl":[[2,8.8,7.22]],"ltp":1.3,"tv":8445.23,"id":20955040}]}]}
{"op":"mcm","clk":"4234506556","pt":1631546456698,"mc":[{"id":"1.187562121","rc":[{"batl":[[0,1.36,72.32],[1,1.39,66.5],[2,1.77,508.04]],"ltp":1.3,"tv":8445.23,"id":20955040},{"batb":[[0,3.75,2.75],[1,3.55,27.68],[2,2.2,42.6]],"ltp":4.4,"tv":1301.27,"id":9625551}]}]}
{"op":"mcm","clk":"4234506632","pt":1631546457530,"mc":[{"id":"1.187562121","rc":[{"batl":[[0,1.34,13.29],[1,1.37,717.41],[2,1.39,66.5]],"ltp":1.3,"tv":8445.23,"id":20955040},{"batb":[[0,3.55,27.68],[1,2.2,42.6],[2,2,11.93]],"batl":[[0,4.1,7.24],[1,4.2,246.63],[2,4.3,3.58]],"ltp":4.4,"tv":1301.27,"id":9625551}]}]}
{"op":"mcm","clk":"4234506718","pt":1631546458628,"mc":[{"id":"1.187562121","rc":[{"batb":[[0,1.3,112.15],[1,1.22,638.1],[2,1.21,165.75]],"ltp":1.3,"tv":8445.23,"id":20955040},{"batb":[[0,3.8,3.95],[1,3.75,1.97],[2,3.7,1.97]],"ltp":4.4,"tv":1301.27,"id":9625551}]}]}
{"op":"mcm","clk":"4234506781","pt":1631546459314,"mc":[{"id":"1.187562121","rc":[{"batl":[[2,1.39,73.69]],"ltp":1.3,"tv":8445.23,"id":20955040}]}]}
{"op":"mcm","clk":"4234506873","pt":1631546460423,"mc":[{"id":"1.187562121","rc":[{"batb":[[0,3.8,7.9],[1,3.75,3.94],[2,3.7,3.94]],"ltp":4.4,"tv":1301.27,"id":9625551}]}]}
{"op":"mcm","clk":"4234507044","pt":1631546462423,"mc":[{"id":"1.187562121","rc":[{"trd":[[1.34,13.29]],"batl":[[0,1.37,717.41],[1,1.39,73.69],[2,1.77,508.04]],"ltp":1.34,"tv":8458.52,"id":20955040},{"trd":[[3.9,4.57]],"ltp":3.9,"tv":1305.84,"id":9625551}],"tv":9764.37}]}
{"op":"mcm","clk":"4234507177","pt":1631546463787,"mc":[{"id":"1.187562121","rc":[{"batl":[[0,1.34,131],[1,1.37,717.41],[2,1.39,73.69]],"ltp":1.34,"tv":8458.52,"id":20955040}]}]}
{"op":"mcm","clk":"4234507622","pt":1631546468800,"mc":[{"id":"1.187562121","rc":[{"batb":[[0,1.22,530.76],[1,1.21,165.75],[2,1.2,100]],"batl":[[0,1.41,51.5],[1,1.42,64.25],[2,1.44,52.83]],"ltp":1.34,"tv":8458.52,"id":20955040},{"batb":[[0,3.4,3.16],[1,3.35,3.27],[2,3.25,4.05]],"batl":[[0,6,3],[1,6.4,3],[2,6.6,3]],"ltp":3.9,"tv":1305.84,"id":9625551}]}]}
{"op":"mcm","clk":"4234507670","pt":1631546469326,"mc":[{"id":"1.187562121","rc":[{"batl":[[0,1.44,52.83],[1,1.77,508.04],[2,8.8,7.22]],"ltp":1.34,"tv":8458.52,"id":20955040},{"batb":[[0,3.25,4.05],[1,3.1,34.98],[2,2.2,42.6]],"ltp":3.9,"tv":1305.84,"id":9625551}]}]}
{"op":"mcm","clk":"4234508184","pt":1631546475694,"mc":[{"id":"1.187562121","rc":[{"batl":[[0,1.41,55.5],[1,1.44,52.83],[2,1.77,508.04]],"ltp":1.34,"tv":8458.52,"id":20955040},{"batb":[[0,3.4,3.86],[1,3.25,4.05],[2,3.1,34.98]],"ltp":3.9,"tv":1305.84,"id":9625551}]}]}
{"op":"mcm","clk":"4234508211","pt":1631546476018,"mc":[{"id":"1.187562121","rc":[{"batl":[[0,1.44,52.83],[1,1.77,508.04],[2,8.8,7.22]],"ltp":1.34,"tv":8458.52,"id":20955040},{"batb":[[0,3.25,4.05],[1,3.1,34.98],[2,2.2,42.6]],"ltp":3.9,"tv":1305.84,"id":9625551}]}]}
{"op":"mcm","clk":"4234508509","pt":1631546479819,"mc":[{"id":"1.187562121","rc":[{"batl":[[0,1.35,439.39],[1,1.44,52.83],[2,1.77,508.04]],"ltp":1.34,"tv":8458.52,"id":20955040}]}]}
{"op":"mcm","clk":"4234508555","pt":1631546480339,"mc":[{"id":"1.187562121","rc":[{"batl":[[0,1.44,52.83],[1,1.77,508.04],[2,8.8,7.22]],"ltp":1.34,"tv":8458.52,"id":20955040}]}]}
{"op":"mcm","clk":"4234509392","pt":1631546489909,"mc":[{"id":"1.187562121","rc":[{"batb":[[0,1.34,45],[1,1.22,530.76],[2,1.21,165.75]],"ltp":1.34,"tv":8458.52,"id":20955040}]}]}
{"op":"mcm","clk":"4234509924","pt":1631546496662,"mc":[{"id":"1.187562121","rc":[{"batl":[[0,1.41,66.5],[1,1.44,52.83],[2,1.77,508.04]],"ltp":1.34,"tv":8458.52,"id":20955040},{"batb":[[0,3.4,3.46],[1,3.25,4.05],[2,3.1,34.98]],"ltp":3.9,"tv":1305.84,"id":9625551}]}]}
{"op":"mcm","clk":"4234509940","pt":1631546496923,"mc":[{"id":"1.187562121","rc":[{"batl":[[0,1.44,52.83],[1,1.77,508.04],[2,8.8,7.22]],"ltp":1.34,"tv":8458.52,"id":20955040},{"batb":[[0,3.25,4.05],[1,3.1,34.98],[2,2.2,42.6]],"ltp":3.9,"tv":1305.84,"id":9625551}]}]}
{"op":"mcm","clk":"4234510254","pt":1631546500643,"mc":[{"id":"1.187562121","rc":[{"batl":[[0,1.77,508.04],[1,8.8,7.22],[2,44,7.22]],"ltp":1.34,"tv":8458.52,"id":20955040}]}]}
{"op":"mcm","clk":"4234510455","pt":1631546502740,"mc":[{"id":"1.187562121","rc":[{"batb":[[1,1.21,165.75],[2,1.2,100]],"batl":[[0,8.8,7.22],[1,44,7.22],[2,50,7.22]],"ltp":1.34,"tv":8458.52,"id":20955040}]}]}
{"op":"mcm","clk":"4234510541","pt":1631546503740,"mc":[{"id":"1.187562121","rc":[{"trd":[[1.34,103.29]],"batb":[[0,1.21,1339.22],[1,1.2,100],[2,1.19,103]],"batl":[[0,1.26,82.75],[1,1.28,7.81],[2,1.34,2]],"ltp":1.34,"tv":8548.52,"id":20955040},{"batb":[[0,5.1,4.17],[1,4.9,18.36],[2,4.8,41.36]],"batl":[[0,5.3,4.1],[1,6,3],[2,6.4,3]],"ltp":3.9,"tv":1305.84,"id":9625551}],"tv":9854.37}]}
{"op":"mcm","clk":"4234510626","pt":1631546504739,"mc":[{"id":"1.187562121","rc":[{"batb":[[0,1.22,8.2],[1,1.21,1339.22],[2,1.2,100]],"ltp":1.34,"tv":8548.52,"id":20955040},{"batb":[[1,4.9,6.12],[2,4.8,35.24]],"batl":[[1,5.6,5.36],[2,5.7,2.68]],"ltp":3.9,"tv":1305.84,"id":9625551}]}]}
{"op":"mcm","clk":"4234510802","pt":1631546507057,"mc":[{"id":"1.187562121","rc":[{"trd":[[1.25,2]],"ltp":1.25,"tv":8550.52,"id":20955040},{"trd":[[5.1,0.49]],"batb":[[0,5.1,3.68]],"ltp":5.1,"tv":1306.33,"id":9625551}],"tv":9856.86}]}
{"op":"mcm","clk":"4234510942","pt":1631546508578,"mc":[{"id":"1.187562121","rc":[{"trd":[[4.9,12.24],[5.1,7.85]],"batb":[[0,4.8,35.24],[1,4.7,3.06],[2,4.4,28.44]],"ltp":4.9,"tv":1325.93,"id":9625551}],"tv":9876.46}]}
{"op":"mcm","clk":"4234511099","pt":1631546510254,"mc":[{"id":"1.187562121","rc":[{"batb":[[0,1.22,116.54],[1,1.21,1455.91]],"batl":[[2,1.3,87.45]],"ltp":1.25,"tv":8550.52,"id":20955040},{"batl":[[1,5.6,7.37]],"ltp":4.9,"tv":1325.93,"id":9625551}]}]}
{"op":"mcm","clk":"4234511510","pt":1631546515390,"mc":[{"id":"1.187562121","rc":[{"trd":[[1.23,8.59]],"ltp":1.23,"tv":8559.11,"id":20955040},{"trd":[[5.3,1.99]],"batl":[[0,5.3,2.11]],"ltp":5.3,"tv":1327.92,"id":9625551}],"tv":9887.04}]}
{"op":"mcm","clk":"4234511645","pt":1631546517165,"mc":[{"id":"1.187562121","rc":[{"batl":[[0,1.25,300],[1,1.26,82.75],[2,1.28,7.81]],"ltp":1.23,"tv":8559.11,"id":20955040},{"batl":[[0,5.6,7.37],[1,5.7,2.68],[2,5.8,4.7]],"ltp":5.3,"tv":1327.92,"id":9625551}]}]}
{"op":"mcm","clk":"4234512071","pt":1631546522363,"mc":[{"id":"1.187562121","rc":[{"batb":[[2,1.2,229.67]],"ltp":1.23,"tv":8559.11,"id":20955040}]}]}
{"op":"mcm","clk":"4234512130","pt":1631546523193,"mc":[{"id":"1.187562121","rc":[{"batl":[[0,1.25,312.93]],"ltp":1.23,"tv":8559.11,"id":20955040},{"batl":[[0,5.3,6.13],[1,5.6,7.37],[2,5.7,2.68]],"ltp":5.3,"tv":1327.92,"id":9625551}]}]}
{"op":"mcm","clk":"4234512317","pt":1631546525766,"mc":[{"id":"1.187562121","rc":[{"batb":[[0,1.24,3.04],[1,1.22,116.54],[2,1.21,1455.91]],"batl":[[0,1.25,300]],"ltp":1.23,"tv":8559.11,"id":20955040},{"batl":[[0,5.6,7.37],[1,5.7,2.68],[2,5.8,4.7]],"ltp":5.3,"tv":1327.92,"id":9625551}]}]}
{"op":"mcm","clk":"4234512547","pt":1631546528492,"mc":[{"id":"1.187562121","rc":[{"batl":[[0,1.25,312.93]],"ltp":1.23,"tv":8559.11,"id":20955040},{"batl":[[0,5.3,6.13],[1,5.6,7.37],[2,5.7,2.68]],"ltp":5.3,"tv":1327.92,"id":9625551}]}]}
{"op":"mcm","clk":"4234512674","pt":1631546530416,"mc":[{"id":"1.187562121","rc":[{"trd":[[1.25,9.22]],"batl":[[0,1.25,309.32]],"ltp":1.25,"tv":8566.33,"id":20955040}],"tv":9894.26}]}
{"op":"mcm","clk":"4234513450","pt":1631546539685,"mc":[{"id":"1.187562121","rc":[{"batb":[[1,1.21,116.69],[2,1.2,100]],"batl":[[0,1.25,296.39],[1,1.3,87.45],[2,1.32,73.86]],"ltp":1.25,"tv":8566.33,"id":20955040},{"batb":[[0,4.3,2.58],[1,4.1,2.54],[2,3.95,37.75]],"batl":[[0,5.8,2.02],[1,6,3],[2,6.4,3]],"ltp":5.3,"tv":1327.92,"id":9625551}]}]}
{"op":"mcm","clk":"4234513558","pt":1631546540801,"mc":[{"id":"1.187562121","rc":[{"batl":[[0,1.3,87.45],[1,1.32,73.86],[2,1.34,2]],"ltp":1.25,"tv":8566.33,"id":20955040}]}]}
{"op":"mcm","clk":"4234513581","pt":1631546541112,"mc":[{"id":"1.187562121","rc":[{"batl":[[0,1.32,73.86],[1,1.34,2],[2,1.62,623.52]],"ltp":1.25,"tv":8566.33,"id":20955040},{"batb":[[0,4.1,2.54],[1,3.95,37.75],[2,3,5.96]],"ltp":5.3,"tv":1327.92,"id":9625551}]}]}
{"op":"mcm","clk":"4234513739","pt":1631546542726,"mc":[{"id":"1.187562121","rc":[{"batb":[[1,1.22,110.34],[2,1.21,116.69]],"ltp":1.25,"tv":8566.33,"id":20955040},{"batl":[[0,5.6,2.01],[1,5.8,2.02],[2,6,3]],"ltp":5.3,"tv":1327.92,"id":9625551}]}]}
{"op":"mcm","clk":"4234513772","pt":1631546542996,"mc":[{"id":"1.187562121","rc":[{"batb":[[1,1.21,116.69],[2,1.2,100]],"ltp":1.25,"tv":8566.33,"id":20955040},{"batl":[[0,5.8,2.02],[1,6,3],[2,6.4,3]],"ltp":5.3,"tv":1327.92,"id":9625551}]}]}
{"op":"mcm","clk":"4234513997","pt":1631546545800,"mc":[{"id":"1.187562121","rc":[{"batl":[[0,1.26,40.25],[1,1.32,73.86],[2,1.34,2]],"ltp":1.25,"tv":8566.33,"id":20955040},{"batb":[[0,4.8,43.93],[1,4.1,2.54],[2,3.95,37.75]],"batl":[[0,5.2,43.88],[1,5.8,2.02],[2,6,3]],"ltp":5.3,"tv":1327.92,"id":9625551}]}]}
{"op":"mcm","clk":"4234514026","pt":1631546546211,"mc":[{"id":"1.187562121","rc":[{"batb":[[1,1.22,131.84],[2,1.21,116.69]],"batl":[[0,1.32,73.86],[1,1.34,2],[2,1.62,623.52]],"ltp":1.25,"tv":8566.33,"id":20955040},{"batb":[[0,4.1,2.54],[1,3.95,37.75],[2,3,5.96]],"batl":[[0,5.6,2.01]],"ltp":5.3,"tv":1327.92,"id":9625551}]}]}
{"op":"mcm","clk":"4234514675","pt":1631546554823,"mc":[{"id":"1.187562121","rc":[{"batl":[[0,1.3,83.65],[1,1.32,73.86],[2,1.34,2]],"ltp":1.25,"tv":8566.33,"id":20955040},{"batb":[[0,4.3,2.58],[1,4.1,2.54],[2,3.95,37.75]],"ltp":5.3,"tv":1327.92,"id":9625551}]}]}
{"op":"mcm","clk":"4234514721","pt":1631546555711,"mc":[{"id":"1.187562121","rc":[{"batl":[[0,1.32,73.86],[1,1.34,2],[2,1.62,623.52]],"ltp":1.25,"tv":8566.33,"id":20955040},{"batb":[[0,4.1,2.54],[1,3.95,37.75],[2,3,5.96]],"ltp":5.3,"tv":1327.92,"id":9625551}]}]}
{"op":"mcm","clk":"4234514788","pt":1631546556704,"mc":[{"id":"1.187562121","rc":[{"batb":[[0,1.22,131.84],[1,1.21,116.69],[2,1.2,100]],"ltp":1.25,"tv":8566.33,"id":20955040}]}]}
{"op":"mcm","clk":"4234514819","pt":1631546557121,"mc":[{"id":"1.187562121","rc":[{"batb":[[0,1.21,116.69],[1,1.2,100],[2,1.19,290.14]],"ltp":1.25,"tv":8566.33,"id":20955040},{"batl":[[0,5.8,2.02],[1,6,3],[2,6.4,3]],"ltp":5.3,"tv":1327.92,"id":9625551}]}]}
{"op":"mcm","clk":"4234515001","pt":1631546559734,"mc":[{"id":"1.187562121","rc":[{"batb":[[1,1.2,483]],"batl":[[0,1.23,36.05],[1,1.24,161.3],[2,1.25,68.22]],"ltp":1.25,"tv":8566.33,"id":20955040},{"batb":[[0,5.3,154.82],[1,5.2,5.76],[2,5.1,2.88]],"batl":[[0,5.7,4.42],[1,5.8,2.02],[2,6,79.6]],"ltp":5.3,"tv":1327.92,"id":9625551}]}]}
{"op":"mcm","clk":"4234515095","pt":1631546560727,"mc":[{"id":"1.187562121","rc":[{"batb":[[1,1.2,491.33]],"ltp":1.25,"tv":8566.33,"id":20955040},{"batl":[[2,6,84.6]],"ltp":5.3,"tv":1327.92,"id":9625551}]}]}
{"op":"mcm","clk":"4234515560","pt":1631546564636,"mc":[{"id":"1.187562121","rc":[{"trd":[[5.3,42.29]],"batb":[[0,5.3,134.67]],"ltp":5.3,"tv":1368.22,"id":9625551}],"tv":9934.56}]}
{"op":"mcm","clk":"4234515746","pt":1631546566725,"mc":[{"id":"1.187562121","rc":[{"batb":[[1,1.2,624.1],[2,1.19,415.85]],"ltp":1.25,"tv":8566.33,"id":20955040},{"batl":[[2,6,86.61]],"ltp":5.3,"tv":1368.22,"id":9625551}]}]}
{"op":"mcm","clk":"4234515801","pt":1631546567660,"mc":[{"id":"1.187562121","rc":[{"trd":[[1.21,2.62]],"batb":[[0,1.21,115.38]],"batl":[[0,1.23,110.05]],"ltp":1.21,"tv":8568.95,"id":20955040}],"tv":9937.18}]}
{"op":"mcm","clk":"4234516175","pt":1631546571837,"mc":[{"id":"1.187562121","rc":[{"batb":[[0,1.22,21.66],[1,1.21,115.38],[2,1.2,232.77]],"batl":[[0,1.23,74],[1,1.25,68.22],[2,1.26,88.75]],"ltp":1.21,"tv":8568.95,"id":20955040},{"batb":[[0,5,5.68],[1,4.8,25.92],[2,4.5,2.58]],"batl":[[0,5.8,2.02],[1,6,5.01],[2,6.4,5]],"ltp":5.3,"tv":1368.22,"id":9625551}]}]}
{"op":"mcm","clk":"4234516251","pt":1631546572831,"mc":[{"id":"1.187562121","rc":[{"batb":[[1,1.2,100],[2,1.19,228.71]],"batl":[[0,1.28,88.59],[1,1.32,73.86],[2,1.34,2]],"ltp":1.21,"tv":8568.95,"id":20955040},{"batb":[[0,4.5,2.58],[1,4.3,30.53],[2,4.1,2.54]],"batl":[[0,6,3],[1,6.4,5],[2,6.6,3]],"ltp":5.3,"tv":1368.22,"id":9625551}]}]}
{"op":"mcm","clk":"4234516686","pt":1631546578777,"mc":[{"id":"1.187562121","rc":[{"batb":[[0,1.2,235.62],[1,1.19,228.71],[2,1.18,663.88]],"batl":[[0,1.26,82.75],[1,1.28,88.59],[2,1.32,73.86]],"ltp":1.21,"tv":8568.95,"id":20955040},{"batb":[[0,4.8,2.23],[1,4.5,2.58],[2,4.3,30.53]],"batl":[[0,6,5.01]],"ltp":5.3,"tv":1368.22,"id":9625551}]}]}
{"op":"mcm","clk":"4234516697","pt":1631546578978,"mc":[{"id":"1.187562121","rc":[{"batb":[[0,1.2,100]],"batl":[[0,1.28,88.59],[1,1.32,73.86],[2,1.34,2]],"ltp":1.21,"tv":8568.95,"id":20955040},{"batb":[[0,4.5,2.58],[1,4.3,30.53],[2,4.1,2.54]],"batl":[[0,6,3]],"ltp":5.3,"tv":1368.22,"id":9625551}]}]}
{"op":"mcm","clk":"4234516943","pt":1631546582751,"mc":[{"id":"1.187562121","rc":[{"batl":[[1,1.34,2],[2,1.62,623.52]],"ltp":1.21,"tv":8568.95,"id":20955040},{"batb":[[2,3,5.96]],"ltp":5.3,"tv":1368.22,"id":9625551}]}]}
{"op":"mcm","clk":"4234516967","pt":1631546583100,"mc":[{"id":"1.187562121","rc":[{"batb":[[2,1.18,106]],"batl":[[2,8.8,7.22]],"ltp":1.21,"tv":8568.95,"id":20955040}]}]}
{"op":"mcm","clk":"4234517163","pt":1631546585593,"mc":[{"id":"1.187562121","rc":[{"batl":[[0,1.21,30.01],[1,1.22,973.34],[2,1.23,68.5]],"ltp":1.21,"tv":8568.95,"id":20955040},{"batb":[[0,5.6,41.08],[1,5.5,2.68],[2,5.4,2.68]],"batl":[[1,6.2,6.96],[2,6.4,154.11]],"ltp":5.3,"tv":1368.22,"id":9625551}]}]}
{"op":"mcm","clk":"4234517254","pt":1631546586766,"mc":[{"id":"1.187562121","rc":[{"batb":[[2,1.18,114.47]],"ltp":1.21,"tv":8568.95,"id":20955040},{"batl":[[2,6.4,158.79]],"ltp":5.3,"tv":1368.22,"id":9625551}]}]}
{"op":"mcm","clk":"4234517527","pt":1631546590508,"mc":[{"id":"1.187562121","rc":[{"trd":[[1.21,32.63]],"batl":[[0,1.22,973.34],[1,1.23,68.5],[2,1.24,8.06]],"ltp":1.21,"tv":8598.96,"id":20955040},{"trd":[[5.6,3.82],[5.7,6.37]],"batb":[[0,5.6,39.17]],"ltp":5.6,"tv":1378.41,"id":9625551}],"tv":9977.38}]}
{"op":"mcm","clk":"4234517632","pt":1631546591878,"mc":[{"id":"1.187562121","rc":[{"batb":[[2,1.18,236.83]],"batl":[[2,1.24,110.54]],"ltp":1.21,"tv":8598.96,"id":20955040}]}]}
{"op":"mcm","clk":"4234517663","pt":1631546592304,"mc":[{"id":"1.187562121","rc":[{"trd":[[1.2,44.72]],"batb":[[0,1.2,77.64]],"ltp":1.2,"tv":8643.68,"id":20955040}],"tv":10022.1}]}
{"op":"mcm","clk":"4234517781","pt":1631546593580,"mc":[{"id":"1.187562121","rc":[{"batl":[[0,1.21,260],[1,1.22,973.34],[2,1.23,68.5]],"ltp":1.2,"tv":8643.68,"id":20955040}]}]}
{"op":"mcm","clk":"4234517834","pt":1631546594103,"mc":[{"id":"1.187562121","rc":[{"batb":[[0,1.2,191.26]],"ltp":1.2,"tv":8643.68,"id":20955040},{"batl":[[0,6,5.01]],"ltp":5.6,"tv":1378.41,"id":9625551}]}]}
{"op":"mcm","clk":"4234518356","pt":1631546600486,"mc":[{"id":"1.187562121","rc":[{"batl":[[1,6.4,158.79],[2,6.6,7.34]],"ltp":5.6,"tv":1378.41,"id":9625551}]}]}
{"op":"mcm","clk":"4234518550","pt":1631546602901,"mc":[{"id":"1.187562121","rc":[{"batb":[[0,1.2,77.64],[1,1.19,103],[2,1.18,228.36]],"batl":[[0,1.24,102.48],[1,1.28,88.59],[2,1.34,2]],"ltp":1.2,"tv":8643.68,"id":20955040},{"batb":[[0,5.1,2.24],[1,4.7,24.74],[2,4.5,2.58]],"batl":[[0,6,3],[1,6.4,3],[2,6.6,5]],"ltp":5.6,"tv":1378.41,"id":9625551}]}]}
{"op":"mcm","clk":"4234518612","pt":1631546603584,"mc":[{"id":"1.187562121","rc":[{"batl":[[1,1.34,2],[2,1.53,724.69]],"ltp":1.2,"tv":8643.68,"id":20955040},{"batb":[[2,3,5.96]],"ltp":5.6,"tv":1378.41,"id":9625551}]}]}
{"op":"mcm","clk":"4234518793","pt":1631546605785,"mc":[{"id":"1.187562121","rc":[{"batl":[[0,1.23,120.5],[1,1.24,102.48],[2,1.34,2]],"ltp":1.2,"tv":8643.68,"id":20955040},{"batb":[[0,5.3,2.08],[1,5.1,2.24],[2,4.7,24.74]],"ltp":5.6,"tv":1378.41,"id":9625551}]}]}
{"op":"mcm","clk":"4234518827","pt":1631546606200,"mc":[{"id":"1.187562121","rc":[{"batl":[[0,1.24,102.48],[1,1.34,2],[2,1.53,724.69]],"ltp":1.2,"tv":8643.68,"id":20955040},{"batb":[[0,5.1,2.24],[1,4.7,24.74],[2,3,5.96]],"ltp":5.6,"tv":1378.41,"id":9625551}]}]}
{"op":"mcm","clk":"4234519080","pt":1631546609702,"mc":[{"id":"1.187562121","rc":[{"batl":[[0,1.22,131],[1,1.23,120.5],[2,1.24,102.48]],"ltp":1.2,"tv":8643.68,"id":20955040},{"batb":[[0,5.3,2.08],[1,5.1,2.24],[2,4.7,24.74]],"ltp":5.6,"tv":1378.41,"id":9625551}]}]}
{"op":"mcm","clk":"4234519235","pt":1631546611812,"mc":[{"id":"1.187562121","rc":[{"batl":[[0,1.23,120.5],[1,1.24,102.48],[2,1.34,2]],"ltp":1.2,"tv":8643.68,"id":20955040}]}]}
{"op":"mcm","clk":"4234519268","pt":1631546612125,"mc":[{"id":"1.187562121","rc":[{"batl":[[0,1.24,102.48],[1,1.34,2],[2,1.53,724.69]],"ltp":1.2,"tv":8643.68,"id":20955040},{"batb":[[0,5.1,2.24],[1,4.7,24.74],[2,3,5.96]],"ltp":5.6,"tv":1378.41,"id":9625551}]}]}
{"op":"mcm","clk":"4234519672","pt":1631546616996,"mc":[{"id":"1.187562121","rc":[{"batl":[[0,1.34,2],[1,1.53,724.69],[2,8.8,7.22]],"ltp":1.2,"tv":8643.68,"id":20955040}]}]}
{"op":"mcm","clk":"4234519795","pt":1631546618725,"mc":[{"id":"1.187562121","rc":[{"batb":[[0,1.19,103],[1,1.18,228.36],[2,1.17,109]],"ltp":1.2,"tv":8643.68,"id":20955040},{"batl":[[0,6.4,3],[1,6.6,5],[2,7,3]],"ltp":5.6,"tv":1378.41,"id":9625551}]}]}
{"op":"mcm","clk":"4234519886","pt":1631546619827,"mc":[{"id":"1.187562121","rc":[{"batl":[[0,1.21,3475.93],[1,1.22,1854.28],[2,1.23,8.13]],"ltp":1.2,"tv":8643.68,"id":20955040},{"batb":[[0,5.9,25.42],[1,5.8,12.72],[2,5.7,52.82]],"batl":[[0,6.2,3.76],[1,6.4,3],[2,6.6,5]],"ltp":5.6,"tv":1378.41,"id":9625551}]}]}
{"op":"mcm","clk":"4234519968","pt":1631546620723,"mc":[{"id":"1.187562121","rc":[{"batb":[[2,1.17,117.55]],"batl":[[0,1.21,115.45]],"ltp":1.2,"tv":8643.68,"id":20955040},{"batb":[[0,5.9,15.25],[1,5.8,7.63],[2,5.7,33.7]],"ltp":5.6,"tv":1378.41,"id":9625551}]}]}
{"op":"mcm","clk":"4234519995","pt":1631546621032,"mc":[{"id":"1.187562121","rc":[{"batb":[[0,5.9,5.08],[1,5.8,2.54],[2,5.7,28.61]],"ltp":5.6,"tv":1378.41,"id":9625551}]}]}
{"op":"mcm","clk":"4234520285","pt":1631546624842,"mc":[{"id":"1.187562121","rc":[{"trd":[[5.9,10.16]],"batb":[[0,5.8,2.54],[1,5.7,28.61],[2,5.3,17.87]],"ltp":5.9,"tv":1388.57,"id":9625551}],"tv":10032.26}]}
{"op":"mcm","clk":"4234520447","pt":1631546626837,"mc":[{"id":"1.187562121","rc":[{"batb":[[0,1.19,226.71]],"batl":[[1,1.22,1967.53]],"ltp":1.2,"tv":8643.68,"id":20955040},{"batb":[[2,5.5,2.12]],"batl":[[1,6.4,5]],"ltp":5.9,"tv":1388.57,"id":9625551}]}]}
{"op":"mcm","clk":"4234520522","pt":1631546627939,"mc":[{"id":"1.187562121","rc":[{"batl":[[0,1.21,213.45]],"ltp":1.2,"tv":8643.68,"id":20955040}]}]}
{"op":"mcm","clk":"4234520793","pt":1631546631827,"mc":[{"id":"1.187562121","rc":[{"batb":[[0,1.19,103],[2,1.17,109]],"batl":[[0,1.22,113.25],[1,1.34,2],[2,1.53,724.69]],"ltp":1.2,"tv":8643.68,"id":20955040},{"batb":[[0,5.5,2.12],[1,5.3,17.87],[2,5,20.89]],"batl":[[0,6.4,3],[1,6.6,5],[2,7,3]],"ltp":5.9,"tv":1388.57,"id":9625551}]}]}
{"op":"mcm","clk":"4234520810","pt":1631546632134,"mc":[{"id":"1.187562121","rc":[{"batb":[[1,5,20.89],[2,3,5.96]],"ltp":5.9,"tv":1388.57,"id":9625551}]}]}
{"op":"mcm","clk":"4234521022","pt":1631546634818,"mc":[{"id":"1.187562121","rc":[{"trd":[[1.19,110]],"batb":[[0,1.19,48]],"ltp":1.19,"tv":8753.68,"id":20955040}],"tv":10142.26}]}
{"op":"mcm","clk":"4234521093","pt":1631546635834,"mc":[{"id":"1.187562121","rc":[{"batb":[[0,1.21,2.13],[1,1.19,48],[2,1.18,228.36]],"ltp":1.19,"tv":8753.68,"id":20955040}]}]}
{"op":"mcm","clk":"4234521146","pt":1631546636625,"mc":[{"id":"1.187562121","rc":[{"trd":[[1.19,206],[1.21,36.89]],"batb":[[0,1.18,228.36],[1,1.17,109],[2,1.16,113]],"batl":[[0,1.19,671.84]],"ltp":1.19,"tv":8853.93,"id":20955040}],"tv":10242.51}]}
{"op":"mcm","clk":"4234521245","pt":1631546637825,"mc":[{"id":"1.187562121","rc":[{"batb":[[0,1.18,122.36]],"ltp":1.19,"tv":8853.93,"id":20955040},{"batl":[[1,6.6,2]],"ltp":5.9,"tv":1388.57,"id":9625551}]}]}
{"op":"mcm","clk":"4234521303","pt":1631546638852,"mc":[{"id":"1.187562121","rc":[{"trd":[[1.19,465.42]],"batl":[[0,1.19,542.13],[1,1.2,19.73],[2,1.21,3677.54]],"ltp":1.19,"tv":9113.35,"id":20955040},{"batb":[[0,6.2,111.62],[1,6,3.95],[2,5.9,25.42]],"ltp":5.9,"tv":1388.57,"id":9625551}],"tv":10501.93}]}
{"op":"mcm","clk":"4234521424","pt":1631546639858,"mc":[{"id":"1.187562121","rc":[{"batb":[[2,1.16,121.62]],"batl":[[1,1.2,92.56],[2,1.21,215.67]],"ltp":1.19,"tv":9113.35,"id":20955040},{"batb":[[1,6,9.18],[2,5.9,15.25]],"batl":[[2,6.8,22.06]],"ltp":5.9,"tv":1388.57,"id":9625551}]}]}
{"op":"mcm","clk":"4234521479","pt":1631546640644,"mc":[{"id":"1.187562121","rc":[{"trd":[[1.19,671.42]],"batl":[[0,1.19,439.13],[2,1.21,217.67]],"ltp":1.19,"tv":9319.36,"id":20955040},{"batb":[[2,5.9,5.08]],"batl":[[2,6.8,4.42]],"ltp":5.9,"tv":1388.57,"id":9625551}],"tv":10707.94}]}
{"op":"mcm","clk":"4234521611","pt":1631546642353,"mc":[{"id":"1.187562121","rc":[{"trd":[[1.19,714.74]],"batl":[[0,1.19,417.47]],"ltp":1.19,"tv":9362.67,"id":20955040}],"tv":10751.25}]}
{"op":"mcm","clk":"4234521713","pt":1631546643868,"mc":[{"id":"1.187562121","rc":[{"trd":[[6.2,30.38]],"batb":[[0,6.2,96.43]],"ltp":6.2,"tv":1418.95,"id":9625551}],"tv":10781.63}]}
{"op":"mcm","clk":"4234521852","pt":1631546645865,"mc":[{"id":"1.187562121","rc":[{"batl":[[0,1.19,579.47]],"ltp":1.19,"tv":9362.67,"id":20955040}]}]}
{"op":"mcm","clk":"4234522039","pt":1631546648071,"mc":[{"id":"1.187562121","rc":[{"batl":[[0,1.19,162]],"ltp":1.19,"tv":9362.67,"id":20955040}]}]}
{"op":"mcm","clk":"4234522254","pt":1631546651166,"mc":[{"id":"1.187562121","rc":[{"trd":[[1.18,260.99]],"batb":[[0,1.17,109],[1,1.16,121.62],[2,1.15,359.5]],"batl":[[0,1.18,278.84],[1,1.19,162],[2,1.2,92.56]],"ltp":1.18,"tv":9623.67,"id":20955040},{"trd":[[6.4,3]],"batl":[[0,6.6,2],[1,6.8,4.42],[2,7,5.2]],"ltp":6.4,"tv":1421.95,"id":9625551}],"tv":11045.63}]}
{"op":"mcm","clk":"4234522344","pt":1631546652571,"mc":[{"id":"1.187562121","rc":[{"batl":[[0,1.18,278.92]],"ltp":1.18,"tv":9623.67,"id":20955040}]}]}
{"op":"mcm","clk":"4234522943","pt":1631546660795,"mc":[{"id":"1.187562121","rc":[{"batl":[[0,1.19,162.08],[1,1.2,92.56],[2,1.21,217.67]],"ltp":1.18,"tv":9623.67,"id":20955040}]}]}
{"op":"mcm","clk":"4234523184","pt":1631546663887,"mc":[{"id":"1.187562121","rc":[{"trd":[[1.17,254.98]],"batb":[[0,1.16,121.62],[1,1.15,359.5],[2,1.14,121]],"batl":[[0,1.17,132.86],[1,1.19,162.08],[2,1.2,92.56]],"ltp":1.17,"tv":9878.64,"id":20955040},{"trd":[[6.6,2],[6.8,4.42]],"batl":[[0,7,5.2],[1,7.2,233.9],[2,7.4,3]],"ltp":6.8,"tv":1428.37,"id":9625551}],"tv":11307.02}]}
{"op":"mcm","clk":"4234523265","pt":1631546664780,"mc":[{"id":"1.187562121","rc":[{"batl":[[1,1.19,162]],"ltp":1.17,"tv":9878.64,"id":20955040}]}]}
{"op":"mcm","clk":"4234523519","pt":1631546667869,"mc":[{"id":"1.187562121","rc":[{"batl":[[0,1.17,132.94]],"ltp":1.17,"tv":9878.64,"id":20955040}]}]}
{"op":"mcm","clk":"4234524051","pt":1631546675624,"mc":[{"id":"1.187562121","rc":[{"batl":[[0,1.19,162.08],[1,1.2,92.56],[2,1.21,217.67]],"ltp":1.17,"tv":9878.64,"id":20955040}]}]}
{"op":"mcm","clk":"4234524278","pt":1631546678697,"mc":[{"id":"1.187562121","rc":[{"trd":[[1.16,254.48]],"batb":[[0,1.15,359.5],[1,1.14,121],[2,1.13,399.78]],"ltp":1.16,"tv":10133.13,"id":20955040},{"trd":[[7,1.86]],"batl":[[0,7,3.34]],"ltp":7.0,"tv":1430.23,"id":9625551}],"tv":11563.36}]}
{"op":"mcm","clk":"4234524515","pt":1631546681994,"mc":[{"id":"1.187562121","rc":[{"trd":[[1.17,255.13]],"batb":[[0,1.17,108.92],[1,1.16,113],[2,1.15,359.5]],"batl":[[0,1.19,162]],"ltp":1.17,"tv":10133.29,"id":20955040}],"tv":11563.52}]}
{"op":"mcm","clk":"4234525720","pt":1631546698411,"mc":[{"id":"1.187562121","rc":[{"batb":[[0,1.16,113],[1,1.15,359.5],[2,1.14,121]],"ltp":1.17,"tv":10133.29,"id":20955040},{"batl":[[0,7,2.2]],"ltp":7.0,"tv":1430.23,"id":9625551}]}]}
{"op":"mcm","clk":"4234528051","pt":1631546729351,"mc":[{"id":"1.187562121","rc":[{"batb":[[0,1.17,154.97],[1,1.16,291.28],[2,1.15,359.5]],"ltp":1.17,"tv":10133.29,"id":20955040},{"batl":[[0,7,4.2],[2,7.4,5]],"ltp":7.0,"tv":1430.23,"id":9625551}]}]}
{"op":"mcm","clk":"4234528346","pt":1631546733593,"mc":[{"id":"1.187562121","rc":[{"batl":[[2,1.21,215.67]],"ltp":1.17,"tv":10133.29,"id":20955040}]}]}
{"op":"mcm","clk":"4234528531","pt":1631546736571,"mc":[{"id":"1.187562121","rc":[{"batl":[[1,1.2,303.56]],"ltp":1.17,"tv":10133.29,"id":20955040},{"batb":[[1,6,23.18]],"ltp":7.0,"tv":1430.23,"id":9625551}]}]}
{"op":"mcm","clk":"4234528728","pt":1631546739692,"mc":[{"id":"1.187562121","rc":[{"batb":[[0,1.16,113],[1,1.15,117],[2,1.14,121]],"batl":[[1,1.2,211],[2,1.21,116.5]],"ltp":1.17,"tv":10133.29,"id":20955040},{"batb":[[0,6,14],[1,5.7,2.02],[2,5.5,2.12]],"batl":[[0,7.4,5],[1,7.8,3],[2,8.2,3]],"ltp":7.0,"tv":1430.23,"id":9625551}]}]}
{"op":"mcm","clk":"4234528817","pt":1631546740892,"mc":[{"id":"1.187562121","rc":[{"batb":[[0,1.14,121],[1,1.13,399.78],[2,1.12,133]],"batl":[[0,1.21,116.5],[1,1.22,169.75],[2,1.34,2]],"ltp":1.17,"tv":10133.29,"id":20955040},{"batb":[[0,5.7,2.02],[1,5.5,2.12],[2,5.3,18.12]],"batl":[[0,7.4,2],[1,8.2,3],[2,8.8,3]],"ltp":7.0,"tv":1430.23,"id":9625551}]}]}
{"op":"mcm","clk":"4234528845","pt":1631546741203,"mc":[{"id":"1.187562121","rc":[{"batl":[[0,1.22,169.75],[1,1.34,2],[2,1.39,17.9]],"ltp":1.17,"tv":10133.29,"id":20955040},{"batb":[[0,5.5,2.12],[1,5.3,18.12],[2,3,5.96]],"ltp":7.0,"tv":1430.23,"id":9625551}]}]}
{"op":"mcm","clk":"4234528941","pt":1631546742815,"mc":[{"id":"1.187562121","rc":[{"batb":[[0,1.17,145.97],[1,1.16,153.53],[2,1.14,121]],"ltp":1.17,"tv":10133.29,"id":20955040},{"batl":[[0,7,2],[1,7.4,2],[2,8.2,3]],"ltp":7.0,"tv":1430.23,"id":9625551}]}]}
{"op":"mcm","clk":"4234528962","pt":1631546742981,"mc":[{"id":"1.187562121","rc":[{"batb":[[0,1.16,153.53],[1,1.14,121],[2,1.13,399.78]],"ltp":1.17,"tv":10133.29,"id":20955040},{"batl":[[0,7.4,2],[1,8.2,3],[2,8.8,3]],"ltp":7.0,"tv":1430.23,"id":9625551}]}]}
{"op":"mcm","clk":"4234529361","pt":1631546747882,"mc":[{"id":"1.187562121","rc":[{"batl":[[0,1.21,169.5],[1,1.22,169.75],[2,1.34,2]],"ltp":1.17,"tv":10133.29,"id":20955040},{"batb":[[0,5.7,4.32],[1,5.5,2.12],[2,5.3,18.12]],"ltp":7.0,"tv":1430.23,"id":9625551}]}]}
{"op":"mcm","clk":"4234529388","pt":1631546748198,"mc":[{"id":"1.187562121","rc":[{"batl":[[0,1.22,169.75],[1,1.34,2],[2,1.39,17.9]],"ltp":1.17,"tv":10133.29,"id":20955040},{"batb":[[0,5.5,2.12],[1,5.3,18.12],[2,3,5.96]],"ltp":7.0,"tv":1430.23,"id":9625551}]}]}
{"op":"mcm","clk":"4234529703","pt":1631546751882,"mc":[{"id":"1.187562121","rc":[{"batl":[[0,1.34,2],[1,1.39,17.9],[2,1.53,724.69]],"ltp":1.17,"tv":10133.29,"id":20955040}]}]}
{"op":"mcm","clk":"4234529823","pt":1631546753384,"mc":[{"id":"1.187562121","rc":[{"batb":[[0,1.18,950.72],[1,1.17,72.11],[2,1.16,217.09]],"batl":[[0,1.21,751.25],[1,1.34,2],[2,1.39,17.9]],"ltp":1.17,"tv":10133.29,"id":20955040},{"batl":[[0,6.2,7.88],[1,6.8,5.88],[2,7.4,2]],"ltp":7.0,"tv":1430.23,"id":9625551}]}]}
{"op":"mcm","clk":"4234529940","pt":1631546754900,"mc":[{"id":"1.187562121","rc":[{"batb":[[0,1.18,955.02],[1,1.17,130.27],[2,1.16,502.71]],"batl":[[0,1.21,960.25],[1,1.23,8.13],[2,1.34,2]],"ltp":1.17,"tv":10133.29,"id":20955040},{"batb":[[0,5.7,5.26],[1,5.6,2.64],[2,5.5,4.76]],"batl":[[1,6.6,3],[2,6.8,5.88]],"ltp":7.0,"tv":1430.23,"id":9625551}]}]}
{"op":"mcm","clk":"4234530461","pt":1631546761614,"mc":[{"id":"1.187562121","rc":[{"batb":[[0,1.19,129.71],[1,1.18,1099.38],[2,1.17,130.27]],"batl":[[0,1.21,1311.75],[1,1.22,168.25],[2,1.23,198.63]],"ltp":1.17,"tv":10133.29,"id":20955040},{"batb":[[0,5.7,9.88]],"batl":[[1,6.4,2],[2,6.6,5]],"ltp":7.0,"tv":1430.23,"id":9625551}]}]}
{"op":"mcm","clk":"4234531044","pt":1631546768907,"mc":[{"id":"1.187562121","rc":[{"batb":[[0,1.17,109],[1,1.16,266.53],[2,1.15,117]],"batl":[[0,1.21,192.5],[2,1.23,190.5]],"ltp":1.17,"tv":10133.29,"id":20955040},{"batb":[[0,5.7,4.62],[1,5.5,2.12],[2,5.3,4.98]],"batl":[[0,6.6,2],[1,7,3],[2,7.4,5]],"ltp":7.0,"tv":1430.23,"id":9625551}]}]}
{"op":"mcm","clk":"4234531062","pt":1631546769127,"mc":[{"id":"1.187562121","rc":[{"batl":[[0,1.22,168.25],[1,1.34,2],[2,1.39,17.9]],"ltp":1.17,"tv":10133.29,"id":20955040},{"batb":[[0,5.5,2.12],[1,5.1,20.55],[2,3,5.96]],"ltp":7.0,"tv":1430.23,"id":9625551}]}]}
{"op":"mcm","clk":"4234531246","pt":1631546771520,"mc":[{"id":"1.187562121","rc":[{"batb":[[0,1.19,113.71],[1,1.18,128.36],[2,1.17,109]],"ltp":1.17,"tv":10133.29,"id":20955040},{"batl":[[0,6.4,2],[1,6.6,2],[2,7,3]],"ltp":7.0,"tv":1430.23,"id":9625551}]}]}
{"op":"mcm","clk":"4234531338","pt":1631546772705,"mc":[{"id":"1.187562121","rc":[{"batb":[[0,1.18,128.36],[1,1.17,109],[2,1.16,266.53]],"ltp":1.17,"tv":10133.29,"id":20955040},{"batl":[[0,6.6,2],[1,7,3],[2,7.4,5]],"ltp":7.0,"tv":1430.23,"id":9625551}]}]}
{"op":"mcm","clk":"4234531621","pt":1631546776817,"mc":[{"id":"1.187562121","rc":[{"batl":[[0,1.21,101],[1,1.22,168.25],[2,1.34,2]],"ltp":1.17,"tv":10133.29,"id":20955040}]}]}
{"op":"mcm","clk":"4234531648","pt":1631546777228,"mc":[{"id":"1.187562121","rc":[{"batb":[[0,1.18,234.36]],"ltp":1.17,"tv":10133.29,"id":20955040},{"batl":[[0,6.6,5]],"ltp":7.0,"tv":1430.23,"id":9625551}]}]}
{"op":"mcm","clk":"4234531917","pt":1631546781342,"mc":[{"id":"1.187562121","rc":[{"batl":[[0,1.22,168.25],[1,1.34,2],[2,1.39,17.9]],"ltp":1.17,"tv":10133.29,"id":20955040}]}]}
{"op":"mcm","clk":"4234532567","pt":1631546791654,"mc":[{"id":"1.187562121","rc":[{"batb":[[0,1.19,117.71],[1,1.18,234.36],[2,1.17,109]],"batl":[[0,1.21,207.5],[1,1.22,168.25],[2,1.34,2]],"ltp":1.17,"tv":10133.29,"id":20955040},{"batb":[[0,5.7,4.32],[1,5.5,2.12],[2,5.1,20.55]],"batl":[[0,6.4,2],[1,6.6,5],[2,7,3]],"ltp":7.0,"tv":1430.23,"id":9625551}]}]}
{"op":"mcm","clk":"4234532584","pt":1631546791963,"mc":[{"id":"1.187562121","rc":[{"batb":[[0,1.18,234.36],[1,1.17,109],[2,1.16,266.53]],"batl":[[0,1.22,168.25],[1,1.34,2],[2,1.39,17.9]],"ltp":1.17,"tv":10133.29,"id":20955040},{"batb":[[0,5.5,2.12],[1,5.1,20.55],[2,3,5.96]],"batl":[[0,6.6,5],[1,7,3],[2,7.4,5]],"ltp":7.0,"tv":1430.23,"id":9625551}]}]}
{"op":"mcm","clk":"4234532801","pt":1631546795457,"mc":[{"id":"1.187562121","rc":[{"trd":[[1.19,757.48]],"batb":[[0,1.18,253.08]],"batl":[[0,1.2,204.43],[1,1.21,181.5],[2,1.22,8.2]],"ltp":1.19,"tv":10176.03,"id":20955040},{"batb":[[0,6.2,156.37],[1,6,19.07],[2,5.9,2.5]],"batl":[[2,7.2,164.25]],"ltp":7.0,"tv":1430.23,"id":9625551}],"tv":11606.26}]}
{"op":"mcm","clk":"4234532877","pt":1631546796656,"mc":[{"id":"1.187562121","rc":[{"batb":[[2,1.16,275.15]],"ltp":1.19,"tv":10176.03,"id":20955040},{"batl":[[2,7.2,168.41]],"ltp":7.0,"tv":1430.23,"id":9625551}]}]}
{"op":"mcm","clk":"4234532940","pt":1631546797584,"mc":[{"id":"1.187562121","rc":[{"trd":[[1.18,266.99]],"batb":[[0,1.18,250.08],[2,1.16,121.62]],"batl":[[0,1.2,415.43]],"ltp":1.18,"tv":10182.03,"id":20955040},{"batb":[[1,6,33.07]],"ltp":7.0,"tv":1430.23,"id":9625551}],"tv":11612.26}]}
{"op":"mcm","clk":"4234533157","pt":1631546800886,"mc":[{"id":"1.187562121","rc":[{"batl":[[0,1.19,272],[1,1.2,415.43],[2,1.21,181.5]],"ltp":1.18,"tv":10182.03,"id":20955040},{"trd":[[6.2,40.54]],"batb":[[0,6.2,151.29]],"ltp":6.2,"tv":1440.39,"id":9625551}],"tv":11622.42}]}
{"op":"mcm","clk":"4234533438","pt":1631546805276,"mc":[{"id":"1.187562121","rc":[{"batb":[[0,1.18,231.36]],"ltp":1.18,"tv":10182.03,"id":20955040}]}]}
{"op":"mcm","clk":"4234533643","pt":1631546808304,"mc":[{"id":"1.187562121","rc":[{"batl":[[1,1.2,433.56]],"ltp":1.18,"tv":10182.03,"id":20955040},{"batb":[[1,6,36.7]],"batl":[[0,6.4,3.49],[1,6.6,5],[2,7,3]],"ltp":6.2,"tv":1440.39,"id":9625551}]}]}
{"op":"mcm","clk":"4234533994","pt":1631546812806,"mc":[{"id":"1.187562121","rc":[{"batb":[[2,1.16,113]],"batl":[[1,1.2,415.43]],"ltp":1.18,"tv":10182.03,"id":20955040},{"batb":[[0,6,28.07],[1,5.7,4.32],[2,5.6,31.29]],"batl":[[0,6.6,5],[1,7,3],[2,7.4,3]],"ltp":6.2,"tv":1440.39,"id":9625551}]}]}
{"op":"mcm","clk":"4234534107","pt":1631546813909,"mc":[{"id":"1.187562121","rc":[{"batb":[[0,1.17,109],[1,1.16,113],[2,1.15,117]],"batl":[[0,1.21,181.5],[1,1.34,2],[2,1.39,17.9]],"ltp":1.18,"tv":10182.03,"id":20955040},{"batb":[[0,5.7,4.32],[1,5.3,17.95],[2,3,5.96]],"batl":[[0,7,3],[1,7.4,3],[2,7.8,3]],"ltp":6.2,"tv":1440.39,"id":9625551}]}]}
{"op":"mcm","clk":"4234534636","pt":1631546820818,"mc":[{"id":"1.187562121","rc":[{"batb":[[0,1.19,25.2],[1,1.18,12.6],[2,1.17,130.15]],"batl":[[0,1.21,1180.74]],"ltp":1.18,"tv":10182.03,"id":20955040},{"batl":[[0,6,3.55],[1,6.8,239.59],[2,7,3]],"ltp":6.2,"tv":1440.39,"id":9625551}]}]}
{"op":"mcm","clk":"4234534713","pt":1631546821822,"mc":[{"id":"1.187562121","rc":[{"batl":[[1,1.23,8.13],[2,1.34,2]],"ltp":1.18,"tv":10182.03,"id":20955040},{"batb":[[1,5.5,5.46],[2,5.4,2.72]],"ltp":6.2,"tv":1440.39,"id":9625551}]}]}
{"op":"mcm","clk":"4234534741","pt":1631546822194,"mc":[{"id":"1.187562121","rc":[{"batb":[[0,1.19,128.2]],"batl":[[0,1.21,1389.74]],"ltp":1.18,"tv":10182.03,"id":20955040},{"batl":[[1,6.4,3],[2,6.8,239.59]],"ltp":6.2,"tv":1440.39,"id":9625551}]}]}
{"op":"mcm","clk":"4234535218","pt":1631546828600,"mc":[{"id":"1.187562121","rc":[{"batl":[[1,1.22,199.75],[2,1.23,191.63]],"ltp":1.18,"tv":10182.03,"id":20955040},{"batb":[[1,5.5,10.68]],"ltp":6.2,"tv":1440.39,"id":9625551}]}]}
{"op":"mcm","clk":"4234535564","pt":1631546832837,"mc":[{"id":"1.187562121","rc":[{"batb":[[0,1.19,103],[1,1.17,109],[2,1.16,337.97]],"batl":[[0,1.21,209],[1,1.23,183.5],[2,1.34,2]],"ltp":1.18,"tv":10182.03,"id":20955040},{"batb":[[0,5.3,22.73],[1,5.1,20.3],[2,3,5.96]],"batl":[[0,6.4,3],[1,7,3],[2,7.4,3]],"ltp":6.2,"tv":1440.39,"id":9625551}]}]}
{"op":"mcm","clk":"4234535593","pt":1631546833214,"mc":[{"id":"1.187562121","rc":[{"batb":[[0,1.17,109],[1,1.16,113],[2,1.15,117]],"batl":[[0,1.23,183.5],[1,1.34,2],[2,1.39,17.9]],"ltp":1.18,"tv":10182.03,"id":20955040},{"batb":[[0,5.3,4.78]],"batl":[[0,7,3],[1,7.4,3],[2,7.8,3]],"ltp":6.2,"tv":1440.39,"id":9625551}]}]}
{"op":"mcm","clk":"4234536043","pt":1631546839551,"mc":[{"id":"1.187562121","rc":[{"batl":[[0,1.22,184.25],[1,1.23,183.5],[2,1.34,2]],"ltp":1.18,"tv":10182.03,"id":20955040},{"batb":[[0,5.5,5.06],[1,5.3,4.78],[2,5.1,20.3]],"ltp":6.2,"tv":1440.39,"id":9625551}]}]}
{"op":"mcm","clk":"4234536322","pt":1631546843724,"mc":[{"id":"1.187562121","rc":[{"batb":[[0,1.18,21.09],[1,1.17,109],[2,1.16,864.9]],"batl":[[0,1.19,994.79],[1,1.2,221.03],[2,1.21,8.26]],"ltp":1.18,"tv":10182.03,"id":20955040},{"batb":[[0,6,29.82],[1,5.9,7.5],[2,5.8,7.5]],"ltp":6.2,"tv":1440.39,"id":9625551}]}]}
{"op":"mcm","clk":"4234536386","pt":1631546844758,"mc":[{"id":"1.187562121","rc":[{"batb":[[0,6,19.82],[1,5.9,2.5],[2,5.8,2.5]],"batl":[[0,7,7.28],[1,7.2,2.14],[2,7.4,5.14]],"ltp":6.2,"tv":1440.39,"id":9625551}]}]}
{"op":"mcm","clk":"4234536452","pt":1631546845744,"mc":[{"id":"1.187562121","rc":[{"batl":[[1,1.2,432.03]],"ltp":1.18,"tv":10182.03,"id":20955040},{"batb":[[0,6,33.82]],"ltp":6.2,"tv":1440.39,"id":9625551}]}]}
{"op":"mcm","clk":"4234536726","pt":1631546849847,"mc":[{"id":"1.187562121","rc":[{"batl":[[0,1.19,1144.79]],"ltp":1.18,"tv":10182.03,"id":20955040}]}]}
{"op":"mcm","clk":"4234536910","pt":1631546853024,"mc":[{"id":"1.187562121","rc":[{"batl":[[2,1.21,184.76]],"ltp":1.18,"tv":10182.03,"id":20955040}]}]}
{"op":"mcm","clk":"4234538093","pt":1631546870586,"mc":[{"id":"1.187562121","rc":[{"batb":[[0,1.16,113],[1,1.15,117],[2,1.14,121]],"batl":[[0,1.19,150],[1,1.21,176.5],[2,1.22,184.25]],"ltp":1.18,"tv":10182.03,"id":20955040},{"batb":[[0,5.7,4.72],[1,5.5,5.06],[2,5.3,22.65]],"batl":[[0,7.4,3],[1,7.8,3],[2,8.2,3]],"ltp":6.2,"tv":1440.39,"id":9625551}]}]}
{"op":"mcm","clk":"4234538128","pt":1631546871169,"mc":[{"id":"1.187562121","rc":[{"batl":[[0,1.21,176.5],[1,1.34,2],[2,1.39,17.9]],"ltp":1.18,"tv":10182.03,"id":20955040},{"batb":[[1,5.3,17.87],[2,3,5.96]],"ltp":6.2,"tv":1440.39,"id":9625551}]}]}
{"op":"mcm","clk":"4234538537","pt":1631546876892,"mc":[{"id":"1.187562121","rc":[{"batb":[[0,1.15,117],[1,1.14,121],[2,1.13,127]],"batl":[[0,1.2,208.23],[1,1.21,176.5],[2,1.34,2]],"ltp":1.18,"tv":10182.03,"id":20955040},{"batb":[[0,6,5.23],[1,5.7,4.72],[2,5.3,17.87]],"batl":[[0,7.8,3],[1,8.2,3],[2,8.8,3]],"ltp":6.2,"tv":1440.39,"id":9625551}]}]}
{"op":"mcm","clk":"4234538585","pt":1631546877479,"mc":[{"id":"1.187562121","rc":[{"batl":[[0,1.21,176.5],[1,1.34,2],[2,1.39,17.9]],"ltp":1.18,"tv":10182.03,"id":20955040},{"batb":[[0,5.7,4.72],[1,5.3,17.87],[2,3,5.96]],"ltp":6.2,"tv":1440.39,"id":9625551}]}]}
{"op":"mcm","clk":"4234539036","pt":1631546883888,"mc":[{"id":"1.187562121","rc":[{"batl":[[0,1.2,211.33],[1,1.21,176.5],[2,1.34,2]],"ltp":1.18,"tv":10182.03,"id":20955040},{"batb":[[0,6,5.23],[1,5.7,4.72],[2,5.3,17.87]],"ltp":6.2,"tv":1440.39,"id":9625551}]}]}
{"op":"mcm","clk":"4234539057","pt":1631546884198,"mc":[{"id":"1.187562121","rc":[{"batl":[[0,1.21,176.5],[1,1.34,2],[2,1.39,17.9]],"ltp":1.18,"tv":10182.03,"id":20955040},{"batb":[[0,5.7,4.72],[1,5.3,17.87],[2,3,5.96]],"ltp":6.2,"tv":1440.39,"id":9625551}]}]}
{"op":"mcm","clk":"4234539310","pt":1631546887899,"mc":[{"id":"1.187562121","rc":[{"batl":[[0,1.2,207.38],[1,1.21,176.5],[2,1.34,2]],"ltp":1.18,"tv":10182.03,"id":20955040},{"batb":[[0,6,5.23],[1,5.7,4.72],[2,5.3,17.87]],"ltp":6.2,"tv":1440.39,"id":9625551}]}]}
{"op":"mcm","clk":"4234539328","pt":1631546888314,"mc":[{"id":"1.187562121","rc":[{"batl":[[0,1.21,176.5],[1,1.34,2],[2,1.39,17.9]],"ltp":1.18,"tv":10182.03,"id":20955040},{"batb":[[0,5.7,4.72],[1,5.3,17.87],[2,3,5.96]],"ltp":6.2,"tv":1440.39,"id":9625551}]}]}
{"op":"mcm","clk":"4234539413","pt":1631546889711,"mc":[{"id":"1.187562121","rc":[{"trd":[[1.15,13.57]],"batb":[[0,1.15,103.43]],"ltp":1.15,"tv":10195.6,"id":20955040},{"trd":[[7.8,8]],"batl":[[0,8.2,3],[1,8.8,3],[2,9.4,3]],"ltp":7.8,"tv":1448.39,"id":9625551}],"tv":11643.99}]}
{"op":"mcm","clk":"4234539483","pt":1631546890716,"mc":[{"id":"1.187562121","rc":[{"batb":[[0,1.19,126.04],[1,1.18,63.02],[2,1.17,71.57]],"batl":[[0,1.21,1340.64]],"ltp":1.15,"tv":10195.6,"id":20955040},{"batl":[[0,6.2,7.31],[1,6.8,202.69],[2,8.2,3]],"ltp":7.8,"tv":1448.39,"id":9625551}]}]}
{"op":"mcm","clk":"4234539585","pt":1631546891810,"mc":[{"id":"1.187562121","rc":[{"batb":[[0,1.19,25.2],[1,1.18,12.6],[2,1.17,21.15]],"batl":[[1,1.23,8.13],[2,1.34,2]],"ltp":1.15,"tv":10195.6,"id":20955040},{"batb":[[1,5.5,27.28],[2,5.4,13.64]],"ltp":7.8,"tv":1448.39,"id":9625551}]}]}
{"op":"mcm","clk":"4234539636","pt":1631546892495,"mc":[{"id":"1.187562121","rc":[{"batb":[[0,1.19,128.2],[2,1.17,130.15]],"batl":[[0,1.21,1549.64]],"ltp":1.15,"tv":10195.6,"id":20955040},{"batb":[[1,5.5,5.46],[2,5.4,2.72]],"batl":[[1,6.4,3],[2,6.8,202.69]],"ltp":7.8,"tv":1448.39,"id":9625551}]}]}
{"op":"mcm","clk":"4234540011","pt":1631546897741,"mc":[{"id":"1.187562121","rc":[{"batl":[[1,1.22,189.25],[2,1.23,8.13]],"ltp":1.15,"tv":10195.6,"id":20955040},{"batb":[[1,5.5,10.56]],"ltp":7.8,"tv":1448.39,"id":9625551}]}]}
{"op":"mcm","clk":"4234540521","pt":1631546904662,"mc":[{"id":"1.187562121","rc":[{"batl":[[0,1.2,329],[1,1.21,1549.64],[2,1.22,189.25]],"ltp":1.15,"tv":10195.6,"id":20955040}]}]}
{"op":"mcm","clk":"4234540853","pt":1631546908620,"mc":[{"id":"1.187562121","rc":[{"batb":[[0,1.19,103],[1,1.17,109],[2,1.16,340.73]],"batl":[[1,1.21,385.5]],"ltp":1.15,"tv":10195.6,"id":20955040},{"batb":[[1,5.5,5.1],[2,5.3,17.87]],"batl":[[0,6.4,3],[1,7,3],[2,7.4,3]],"ltp":7.8,"tv":1448.39,"id":9625551}]}]}
{"op":"mcm","clk":"4234540880","pt":1631546909143,"mc":[{"id":"1.187562121","rc":[{"batb":[[0,1.17,109],[1,1.16,113],[2,1.15,103.43]],"batl":[[1,1.21,176.5]],"ltp":1.15,"tv":10195.6,"id":20955040},{"batb":[[2,5.1,20.22]],"batl":[[0,7,3],[1,7.4,3],[2,8.2,3]],"ltp":7.8,"tv":1448.39,"id":9625551}]}]}
{"op":"mcm","clk":"4234540934","pt":1631546910125,"mc":[{"id":"1.187562121","rc":[{"batl":[[0,1.22,189.25],[1,1.34,2],[2,1.39,17.9]],"ltp":1.15,"tv":10195.6,"id":20955040},{"batb":[[0,5.5,5.1],[1,5.1,20.22],[2,3,5.96]],"ltp":7.8,"tv":1448.39,"id":9625551}]}]}
{"op":"mcm","clk":"4234541066","pt":1631546912248,"mc":[{"id":"1.187562121","rc":[{"batl":[[2,7.8,3]],"ltp":7.8,"tv":1448.39,"id":9625551}]}]}
{"op":"mcm","clk":"4234541390","pt":1631546916874,"mc":[{"id":"1.187562121","rc":[{"batl":[[0,1.21,197.5],[1,1.22,189.25],[2,1.34,2]],"ltp":1.15,"tv":10195.6,"id":20955040},{"batb":[[0,5.7,4.82],[1,5.5,5.1],[2,5.1,20.22]],"ltp":7.8,"tv":1448.39,"id":9625551}]}]}
{"op":"mcm","clk":"4234541416","pt":1631546917138,"mc":[{"id":"1.187562121","rc":[{"batl":[[0,1.22,189.25],[1,1.34,2],[2,1.39,17.9]],"ltp":1.15,"tv":10195.6,"id":20955040},{"batb":[[0,5.5,5.1],[1,5.1,20.22],[2,3,5.96]],"ltp":7.8,"tv":1448.39,"id":9625551}]}]}
{"op":"mcm","clk":"4234542158","pt":1631546927880,"mc":[{"id":"1.187562121","rc":[{"trd":[[1.21,85.71]],"batb":[[0,1.18,8.47],[1,1.17,109],[2,1.16,113]],"batl":[[0,1.22,1008.02]],"ltp":1.21,"tv":10244.42,"id":20955040},{"batb":[[0,5.5,8.62]],"batl":[[0,6.2,56.46],[1,6.4,197.94],[2,6.6,12.1]],"ltp":7.8,"tv":1448.39,"id":9625551}],"tv":11692.81}]}
{"op":"mcm","clk":"4234542218","pt":1631546928868,"mc":[{"id":"1.187562121","rc":[{"batb":[[1,1.17,317.69]],"batl":[[1,1.23,121.96],[2,1.24,69.04]],"ltp":1.21,"tv":10244.42,"id":20955040},{"batb":[[2,4.4,28.18]],"batl":[[0,6.2,37.1],[1,6.4,188.26],[2,6.6,2.42]],"ltp":7.8,"tv":1448.39,"id":9625551}]}]}
{"op":"mcm","clk":"4234542260","pt":1631546929384,"mc":[{"id":"1.187562121","rc":[{"batb":[[0,1.2,100],[1,1.18,114.47],[2,1.17,317.69]],"batl":[[0,1.22,1230.02],[1,1.23,24.4],[2,1.24,20.26]],"ltp":1.21,"tv":10244.42,"id":20955040},{"batl":[[0,6,3],[1,6.2,37.1],[2,6.4,188.26]],"ltp":7.8,"tv":1448.39,"id":9625551}]}]}
{"op":"mcm","clk":"4234542497","pt":1631546932864,"mc":[{"id":"1.187562121","rc":[{"trd":[[5.5,10.5]],"batb":[[0,5.5,3.37]],"ltp":5.5,"tv":1458.89,"id":9625551}],"tv":11703.31}]}
{"op":"mcm","clk":"4234542646","pt":1631546934790,"mc":[{"id":"1.187562121","rc":[{"batb":[[2,5,4.71]],"ltp":5.5,"tv":1458.89,"id":9625551}]}]}
{"op":"mcm","clk":"4234542741","pt":1631546935970,"mc":[{"id":"1.187562121","rc":[{"batl":[[0,1.22,1311.02]],"ltp":1.21,"tv":10244.42,"id":20955040}]}]}
{"op":"mcm","clk":"4234542859","pt":1631546937884,"mc":[{"id":"1.187562121","rc":[{"batb":[[0,5.1,20.22],[1,5,4.71],[2,4.7,4.32]],"ltp":5.5,"tv":1458.89,"id":9625551}]}]}
{"op":"mcm","clk":"4234543040","pt":1631546940786,"mc":[{"id":"1.187562121","rc":[{"batb":[[0,1.2,118.52]],"batl":[[0,1.22,1343.41]],"ltp":1.21,"tv":10244.42,"id":20955040},{"batl":[[0,6,6.7]],"ltp":5.5,"tv":1458.89,"id":9625551}]}]}
{"op":"mcm","clk":"4234543211","pt":1631546942805,"mc":[{"id":"1.187562121","rc":[{"batb":[[0,1.2,100]],"batl":[[0,1.22,1311.02]],"ltp":1.21,"tv":10244.42,"id":20955040},{"batl":[[0,6,3]],"ltp":5.5,"tv":1458.89,"id":9625551}]}]}
{"op":"mcm","clk":"4234543426","pt":1631546945778,"mc":[{"id":"1.187562121","rc":[{"batb":[[0,1.2,118.52]],"batl":[[0,1.22,1343.41]],"ltp":1.21,"tv":10244.42,"id":20955040},{"batl":[[0,6,6.7]],"ltp":5.5,"tv":1458.89,"id":9625551}]}]}
{"op":"mcm","clk":"4234544088","pt":1631546955909,"mc":[{"id":"1.187562121","rc":[{"batb":[[0,1.2,100],[1,1.18,106],[2,1.17,109]],"batl":[[0,1.22,303],[1,1.25,157.82],[2,1.27,169.5]],"ltp":1.21,"tv":10244.42,"id":20955040},{"batb":[[0,5,4.71],[1,4.7,4.32],[2,4.4,28.18]],"batl":[[0,6,3],[1,6.6,3],[2,7,3]],"ltp":5.5,"tv":1458.89,"id":9625551}]}]}
{"op":"mcm","clk":"4234544168","pt":1631546956822,"mc":[{"id":"1.187562121","rc":[{"batb":[[0,1.18,106],[1,1.17,109],[2,1.16,113]],"batl":[[0,1.27,169.5],[1,1.34,2],[2,1.39,17.9]],"ltp":1.21,"tv":10244.42,"id":20955040},{"batb":[[0,4.7,4.32],[1,4.4,28.18],[2,3,5.96]],"batl":[[0,6.6,3],[1,7,3],[2,7.4,3]],"ltp":5.5,"tv":1458.89,"id":9625551}]}]}
{"op":"mcm","clk":"4234544345","pt":1631546958798,"mc":[{"id":"1.187562121","rc":[{"batb":[[1,4.5,27.6],[2,4.4,28.18]],"ltp":5.5,"tv":1458.89,"id":9625551}]}]}
{"op":"mcm","clk":"4234544433","pt":1631546959739,"mc":[{"id":"1.187562121","rc":[{"batl":[[0,1.25,157.82],[1,1.27,169.5],[2,1.34,2]],"ltp":1.21,"tv":10244.42,"id":20955040},{"batb":[[0,5,4.61],[1,4.7,4.32],[2,4.5,27.6]],"ltp":5.5,"tv":1458.89,"id":9625551}]}]}
{"op":"mcm","clk":"4234544476","pt":1631546960223,"mc":[{"id":"1.187562121","rc":[{"batl":[[0,1.27,169.5],[1,1.34,2],[2,1.39,17.9]],"ltp":1.21,"tv":10244.42,"id":20955040},{"batb":[[0,4.7,4.32],[1,4.5,27.6],[2,3,5.96]],"ltp":5.5,"tv":1458.89,"id":9625551}]}]}
{"op":"mcm","clk":"4234544662","pt":1631546962442,"mc":[{"id":"1.187562121","rc":[{"batl":[[0,1.2,672.23],[1,1.22,8.2],[2,1.27,169.5]],"ltp":1.21,"tv":10244.42,"id":20955040},{"batb":[[0,6,107.87],[1,5.9,5.08],[2,5.8,2.54]],"batl":[[2,7.2,247.95]],"ltp":5.5,"tv":1458.89,"id":9625551}]}]}
{"op":"mcm","clk":"4234544771","pt":1631546963849,"mc":[{"id":"1.187562121","rc":[{"batb":[[2,1.16,121.62]],"batl":[[0,1.2,898.23]],"ltp":1.21,"tv":10244.42,"id":20955040},{"batb":[[0,6,122.87]],"batl":[[1,6.8,4.42],[2,7,5.2]],"ltp":5.5,"tv":1458.89,"id":9625551}]}]}
{"op":"mcm","clk":"4234545104","pt":1631546969135,"mc":[{"id":"1.187562121","rc":[{"batb":[[1,1.17,247.97],[2,1.16,255.15]],"batl":[[1,1.22,161.95],[2,1.23,164.5]],"ltp":1.21,"tv":10244.42,"id":20955040},{"batl":[[2,7,7.2]],"ltp":5.5,"tv":1458.89,"id":9625551}]}]}
{"op":"mcm","clk":"4234545340","pt":1631546972347,"mc":[{"id":"1.187562121","rc":[{"batl":[[0,1.2,1013.23]],"ltp":1.21,"tv":10244.42,"id":20955040}]}]}
{"op":"mcm","clk":"4234545466","pt":1631546974541,"mc":[{"id":"1.187562121","rc":[{"batb":[[2,1.16,246.53]],"batl":[[0,1.2,341],[1,1.22,153.75]],"ltp":1.21,"tv":10244.42,"id":20955040},{"batb":[[0,6,15],[1,5.5,4.39],[2,5.3,4.38]],"batl":[[1,7,5],[2,7.4,5]],"ltp":5.5,"tv":1458.89,"id":9625551}]}]}
{"op":"mcm","clk":"4234545503","pt":1631546975214,"mc":[{"id":"1.187562121","rc":[{"batb":[[0,1.17,109],[1,1.16,246.53],[2,1.15,103.43]],"batl":[[0,1.23,164.5],[1,1.34,2],[2,1.39,17.9]],"ltp":1.21,"tv":10244.42,"id":20955040},{"batb":[[0,5.3,4.38],[1,4.9,21.72],[2,3,5.96]],"batl":[[0,7,3],[1,7.4,5],[2,7.8,3]],"ltp":5.5,"tv":1458.89,"id":9625551}]}]}
{"op":"mcm","clk":"4234546449","pt":1631546988856,"mc":[{"id":"1.187562121","rc":[{"batb":[[0,1.17,252.97]],"batl":[[0,1.22,160.75],[1,1.23,164.5],[2,1.34,2]],"ltp":1.21,"tv":10244.42,"id":20955040},{"batb":[[0,5.5,4.27],[1,5.3,4.38],[2,4.9,21.72]],"batl":[[0,7,5]],"ltp":5.5,"tv":1458.89,"id":9625551}]}]}
{"op":"mcm","clk":"4234546482","pt":1631546989168,"mc":[{"id":"1.187562121","rc":[{"batb":[[0,1.17,109]],"batl":[[0,1.23,164.5],[1,1.34,2],[2,1.39,17.9]],"ltp":1.21,"tv":10244.42,"id":20955040},{"batb":[[0,5.3,4.38],[1,4.9,21.72],[2,3,5.96]],"batl":[[0,7,3]],"ltp":5.5,"tv":1458.89,"id":9625551}]}]}
{"op":"mcm","clk":"4234547719","pt":1631547002881,"mc":[{"id":"1.187562121","rc":[{"batb":[[0,1.17,253.97]],"batl":[[0,1.22,160.75],[1,1.23,164.5],[2,1.34,2]],"ltp":1.21,"tv":10244.42,"id":20955040},{"batb":[[0,5.5,4.24],[1,5.3,4.38],[2,4.9,21.72]],"batl":[[0,7,5]],"ltp":5.5,"tv":1458.89,"id":9625551}]}]}
{"op":"mcm","clk":"4234547800","pt":1631547003768,"mc":[{"id":"1.187562121","rc":[{"batb":[[0,1.21,24.8],[1,1.2,12.4],[2,1.19,20.8]],"batl":[[0,1.23,846.6],[1,1.34,2],[2,3.8,27.43]],"ltp":1.21,"tv":10244.42,"id":20955040},{"batb":[[0,5.3,4.38],[1,4.9,21.72],[2,3,5.96]],"batl":[[0,5.7,5.83],[1,6.2,240.84],[2,7,3]],"ltp":5.5,"tv":1458.89,"id":9625551}]}]}
{"op":"mcm","clk":"4234547906","pt":1631547004874,"mc":[{"id":"1.187562121","rc":[{"batb":[[1,1.2,112.4]],"batl":[[0,1.23,1066.6],[1,1.25,8],[2,1.34,2]],"ltp":1.21,"tv":10244.42,"id":20955040},{"batb":[[1,5.1,5.88],[2,5,2.94]],"ltp":5.5,"tv":1458.89,"id":9625551}]}]}
{"op":"mcm","clk":"4234548561","pt":1631547011507,"mc":[{"id":"1.187562121","rc":[{"batl":[[0,1.23,1163.6]],"ltp":1.21,"tv":10244.42,"id":20955040}]}]}
{"op":"mcm","clk":"4234548640","pt":1631547012494,"mc":[{"id":"1.187562121","rc":[{"batl":[[2,1.27,153.5]],"ltp":1.21,"tv":10244.42,"id":20955040}]}]}
{"op":"mcm","clk":"4234548697","pt":1631547013068,"mc":[{"id":"1.187562121","rc":[{"trd":[[1.23,8.77]],"batl":[[0,1.23,1163.51]],"ltp":1.23,"tv":10244.6,"id":20955040}],"tv":11703.5}]}
{"op":"mcm","clk":"4234549622","pt":1631547023895,"mc":[{"id":"1.187562121","rc":[{"batb":[[0,1.18,106],[1,1.17,109],[2,1.16,113]],"batl":[[0,1.23,97],[1,1.27,153.5],[2,1.29,148.5]],"ltp":1.23,"tv":10244.6,"id":20955040},{"batb":[[0,4.7,4.82],[1,4.4,4.66],[2,4.2,32.63]],"batl":[[0,7,3],[1,7.4,3],[2,7.8,3]],"ltp":5.5,"tv":1458.89,"id":9625551}]}]}
{"op":"mcm","clk":"4234549701","pt":1631547024887,"mc":[{"id":"1.187562121","rc":[{"batl":[[0,1.29,148.5],[1,1.34,2],[2,3.8,27.43]],"ltp":1.23,"tv":10244.6,"id":20955040},{"batb":[[0,4.4,4.66],[1,4.2,32.63],[2,3,5.96]],"ltp":5.5,"tv":1458.89,"id":9625551}]}]}
{"op":"mcm","clk":"4234550548","pt":1631547034515,"mc":[{"id":"1.187562121","rc":[{"batl":[[0,1.27,147.5],[1,1.29,148.5],[2,1.34,2]],"ltp":1.23,"tv":10244.6,"id":20955040},{"batb":[[0,4.7,4.42],[1,4.4,4.66],[2,4.2,32.63]],"ltp":5.5,"tv":1458.89,"id":9625551}]}]}
{"op":"mcm","clk":"4234550648","pt":1631547035842,"mc":[{"id":"1.187562121","rc":[{"trd":[[1.26,2]],"batb":[[0,1.24,738.84],[1,1.23,8.13],[2,1.18,106]],"batl":[[0,1.28,22.06]],"ltp":1.26,"tv":10246.6,"id":20955040},{"trd":[[4.8,0.53]],"batb":[[0,4.5,214.25]],"batl":[[0,4.8,4.88],[1,4.9,42.85],[2,5,9.18]],"ltp":4.8,"tv":1459.42,"id":9625551}],"tv":11706.03}]}
{"op":"mcm","clk":"4234550715","pt":1631547036831,"mc":[{"id":"1.187562121","rc":[{"batb":[[1,1.23,159.2],[2,1.19,184.03]],"batl":[[2,1.3,30.77]],"ltp":1.26,"tv":10246.6,"id":20955040},{"batl":[[1,4.9,30.61],[2,5,3.06]],"ltp":4.8,"tv":1459.42,"id":9625551}]}]}
{"op":"mcm","clk":"4234550744","pt":1631547037247,"mc":[{"id":"1.187562121","rc":[{"batb":[[2,1.2,100]],"batl":[[0,1.27,213],[1,1.28,22.06],[2,1.29,148.5]],"ltp":1.26,"tv":10246.6,"id":20955040}]}]}
{"op":"mcm","clk":"4234550932","pt":1631547039187,"mc":[{"id":"1.187562121","rc":[{"batb":[[2,1.22,2]],"ltp":1.26,"tv":10246.6,"id":20955040}]}]}
{"op":"mcm","clk":"4234551497","pt":1631547046046,"mc":[{"id":"1.187562121","rc":[{"batl":[[1,1.29,148.5],[2,1.3,30.77]],"ltp":1.26,"tv":10246.6,"id":20955040},{"batl":[[0,4.9,30.61],[1,5,3.06],[2,5.1,3.06]],"ltp":4.8,"tv":1459.42,"id":9625551}]}]}
{"op":"mcm","clk":"4234551759","pt":1631547049374,"mc":[{"id":"1.187562121","rc":[{"batl":[[1,1.28,24.04],[2,1.29,148.5]],"ltp":1.26,"tv":10246.6,"id":20955040},{"batl":[[0,4.8,4.88],[1,4.9,30.61],[2,5,3.06]],"ltp":4.8,"tv":1459.42,"id":9625551}]}]}
{"op":"mcm","clk":"4234551960","pt":1631547051812,"mc":[{"id":"1.187562121","rc":[{"batb":[[0,1.23,151.07],[1,1.22,2],[2,1.2,100]],"batl":[[1,1.34,137.75],[2,1.36,127.07]],"ltp":1.26,"tv":10246.6,"id":20955040},{"batb":[[0,4.2,32.63],[1,3.9,5.56],[2,3.75,5.51]],"batl":[[0,6.4,3],[1,7,3],[2,7.4,3]],"ltp":4.8,"tv":1459.42,"id":9625551}]}]}
{"op":"mcm","clk":"4234552023","pt":1631547052486,"mc":[{"id":"1.187562121","rc":[{"batb":[[0,1.22,2],[1,1.2,100],[2,1.19,287.03]],"batl":[[0,1.34,2],[1,1.36,127.07],[2,1.37,121.5]],"ltp":1.26,"tv":10246.6,"id":20955040},{"batb":[[0,3.75,5.51],[1,3.7,5.12],[2,3.55,24.91]],"ltp":4.8,"tv":1459.42,"id":9625551}]}]}
{"op":"mcm","clk":"4234552512","pt":1631547058805,"mc":[{"id":"1.187562121","rc":[{"batl":[[0,1.33,138.5],[1,1.34,2],[2,1.36,127.07]],"ltp":1.26,"tv":10246.6,"id":20955040},{"batb":[[0,4,5.36],[1,3.75,5.51],[2,3.7,5.12]],"ltp":4.8,"tv":1459.42,"id":9625551}]}]}
{"op":"mcm","clk":"4234552536","pt":1631547059066,"mc":[{"id":"1.187562121","rc":[{"batl":[[0,1.34,2],[1,1.36,127.07],[2,1.37,121.5]],"ltp":1.26,"tv":10246.6,"id":20955040},{"batb":[[0,3.75,5.51],[1,3.7,5.12],[2,3.55,24.91]],"ltp":4.8,"tv":1459.42,"id":9625551}]}]}
{"op":"mcm","clk":"4234552874","pt":1631547063715,"mc":[{"id":"1.187562121","rc":[{"trd":[[1.34,105.29]],"batb":[[0,1.34,15.55],[1,1.25,1998.76],[2,1.22,2]],"batl":[[0,1.36,148.25],[1,1.37,851.39],[2,3.8,27.43]],"ltp":1.34,"tv":10248.6,"id":20955040},{"trd":[[3.9,5.26]],"batl":[[0,3.9,10.26],[1,4.1,36.6],[2,4.2,18.3]],"ltp":3.9,"tv":1460.11,"id":9625551}],"tv":11708.72}]}
{"op":"mcm","clk":"4234552959","pt":1631547064711,"mc":[{"id":"1.187562121","rc":[{"trd":[[1.34,109.29]],"batb":[[0,1.34,13.55],[1,1.3,110.89],[2,1.26,133.62]],"batl":[[1,1.37,873.29],[2,1.38,18.19]],"ltp":1.34,"tv":10252.6,"id":20955040},{"batl":[[1,4.1,7.32],[2,4.2,3.66]],"ltp":3.9,"tv":1460.11,"id":9625551}],"tv":11712.72}]}
{"op":"mcm","clk":"4234553011","pt":1631547065286,"mc":[{"id":"1.187562121","rc":[{"batl":[[0,1.36,347.25]],"ltp":1.34,"tv":10252.6,"id":20955040}]}]}
{"op":"mcm","clk":"4234553201","pt":1631547067881,"mc":[{"id":"1.187562121","rc":[{"batb":[[2,1.28,2]],"ltp":1.34,"tv":10252.6,"id":20955040}]}]}
{"op":"mcm","clk":"4234553771","pt":1631547074818,"mc":[{"id":"1.187562121","rc":[{"trd":[[1.34,113.29]],"batb":[[0,1.3,110.89],[1,1.28,2],[2,1.26,133.62]],"batl":[[0,1.36,326.07]],"ltp":1.34,"tv":10256.6,"id":20955040}],"tv":11716.72}]}
{"op":"mcm","clk":"4234553801","pt":1631547075027,"mc":[{"id":"1.187562121","rc":[{"trd":[[1.36,73.04]],"batl":[[0,1.36,253.03]],"ltp":1.36,"tv":10329.64,"id":20955040},{"trd":[[3.75,47.85]],"batb":[[0,3.7,5.12],[1,3.55,24.91],[2,3.3,6.28]],"ltp":3.75,"tv":1497.62,"id":9625551}],"tv":11827.27}]}
{"op":"mcm","clk":"4234554021","pt":1631547077841,"mc":[{"id":"1.187562121","rc":[{"batb":[[0,1.34,13.55]],"batl":[[0,1.36,222.14],[1,1.43,143.5],[2,1.46,117.25]],"ltp":1.36,"tv":10329.64,"id":20955040},{"batb":[[0,3.3,6.28],[1,3.15,6.43],[2,3,37.83]],"batl":[[0,6.4,3],[1,7,3],[2,7.4,3]],"ltp":3.75,"tv":1497.62,"id":9625551}]}]}
{"op":"mcm","clk":"4234554079","pt":1631547078407,"mc":[{"id":"1.187562121","rc":[{"batb":[[0,1.28,4],[1,1.26,133.62],[2,1.22,2]],"batl":[[0,1.46,117.25],[1,3.8,27.43],[2,8.8,7.22]],"ltp":1.36,"tv":10329.64,"id":20955040},{"batb":[[0,3.15,6.43],[1,3,37.83],[2,2.2,42.6]],"ltp":3.75,"tv":1497.62,"id":9625551}]}]}
{"op":"mcm","clk":"4234554332","pt":1631547081623,"mc":[{"id":"1.187562121","rc":[{"batl":[[0,1.43,93.5],[1,1.46,117.25],[2,3.8,27.43]],"ltp":1.36,"tv":10329.64,"id":20955040},{"batb":[[0,3.3,4.68],[1,3.15,6.43],[2,3.05,37.16]],"ltp":3.75,"tv":1497.62,"id":9625551}]}]}
{"op":"mcm","clk":"4234554352","pt":1631547081935,"mc":[{"id":"1.187562121","rc":[{"batl":[[0,1.46,117.25],[1,3.8,27.43],[2,8.8,7.22]],"ltp":1.36,"tv":10329.64,"id":20955040},{"batb":[[0,3.15,6.43],[1,3.05,37.16],[2,2.2,42.6]],"ltp":3.75,"tv":1497.62,"id":9625551}]}]}
{"op":"mcm","clk":"4234554755","pt":1631547086720,"mc":[{"id":"1.187562121","rc":[{"batl":[[0,1.32,137.86],[1,1.33,7.52],[2,1.46,117.25]],"ltp":1.36,"tv":10329.64,"id":20955040},{"batb":[[0,4.2,189.05],[1,4.1,51.34],[2,4,18.3]],"batl":[[0,4.8,250],[1,6.4,3],[2,7,3]],"ltp":3.75,"tv":1497.62,"id":9625551}]}]}
{"op":"mcm","clk":"4234554831","pt":1631547087812,"mc":[{"id":"1.187562121","rc":[{"batb":[[0,1.28,74.32],[1,1.27,35.16],[2,1.26,168.78]],"ltp":1.36,"tv":10329.64,"id":20955040},{"batb":[[1,4.1,22.06],[2,4,3.66]],"batl":[[0,4.8,252.08]],"ltp":3.75,"tv":1497.62,"id":9625551}]}]}
{"op":"mcm","clk":"4234554896","pt":1631547088749,"mc":[{"id":"1.187562121","rc":[{"batb":[[0,1.28,27.44],[1,1.27,11.72],[2,1.26,145.34]],"batl":[[0,1.32,342.86]],"ltp":1.36,"tv":10329.64,"id":20955040}]}]}
{"op":"mcm","clk":"4234554956","pt":1631547089739,"mc":[{"id":"1.187562121","rc":[{"batb":[[0,1.29,18.27],[1,1.28,27.44],[2,1.27,11.72]],"batl":[[0,1.31,26.48],[1,1.32,342.86],[2,1.33,7.52]],"ltp":1.36,"tv":10329.64,"id":20955040}]}]}
{"op":"mcm","clk":"4234555524","pt":1631547097725,"mc":[{"id":"1.187562121","rc":[{"batb":[[0,1.28,4],[1,1.22,2],[2,1.2,279.08]],"batl":[[0,1.42,96.25],[1,1.46,117.25],[2,3.8,27.43]],"ltp":1.36,"tv":10329.64,"id":20955040},{"batb":[[0,3.35,4.67],[1,3.15,6.43],[2,3.1,34.64]],"batl":[[0,6.4,3],[1,7,3],[2,7.4,3]],"ltp":3.75,"tv":1497.62,"id":9625551}]}]}
{"op":"mcm","clk":"4234555547","pt":1631547098037,"mc":[{"id":"1.187562121","rc":[{"batl":[[0,1.46,117.25],[1,3.8,27.43],[2,8.8,7.22]],"ltp":1.36,"tv":10329.64,"id":20955040},{"batb":[[0,3.15,6.43],[1,3.1,34.64],[2,2.2,42.6]],"ltp":3.75,"tv":1497.62,"id":9625551}]}]}
{"op":"mcm","clk":"4234555864","pt":1631547102856,"mc":[{"id":"1.187562121","rc":[{"batl":[[0,1.42,94.25],[1,1.46,117.25],[2,3.8,27.43]],"ltp":1.36,"tv":10329.64,"id":20955040},{"batb":[[0,3.35,4.47],[1,3.15,6.43],[2,3.1,34.64]],"ltp":3.75,"tv":1497.62,"id":9625551}]}]}
{"op":"mcm","clk":"4234555896","pt":1631547103378,"mc":[{"id":"1.187562121","rc":[{"batb":[[2,1.2,179.08]],"batl":[[0,3.8,27.43],[1,8.8,7.22],[2,44,7.22]],"ltp":1.36,"tv":10329.64,"id":20955040},{"batb":[[0,3.15,6.43],[1,3.1,34.64],[2,2.2,42.6]],"batl":[[0,7,3],[1,7.4,3],[2,7.8,3]],"ltp":3.75,"tv":1497.62,"id":9625551}]}]}
{"op":"mcm","clk":"4234556006","pt":1631547104669,"mc":[{"id":"1.187562121","rc":[{"trd":[[1.28,8]],"batb":[[0,1.23,18.43],[2,1.2,946.78]],"batl":[[0,1.25,156.9],[1,1.26,1195.83],[2,1.27,7.87]],"ltp":1.28,"tv":10337.64,"id":20955040},{"batb":[[0,5.1,5.68],[1,5,13.08],[2,4.9,38.76]],"batl":[[0,6,153.54],[1,7,3],[2,7.4,3]],"ltp":3.75,"tv":1497.62,"id":9625551}],"tv":11835.27}]}
{"op":"mcm","clk":"4234556088","pt":1631547105703,"mc":[{"id":"1.187562121","rc":[{"batb":[[2,1.2,955.11]],"ltp":1.28,"tv":10337.64,"id":20955040},{"batb":[[2,4.9,14.28]],"batl":[[0,5.5,5.46],[1,5.6,2.72],[2,5.7,2.72]],"ltp":3.75,"tv":1497.62,"id":9625551}]}]}
{"op":"mcm","clk":"4234556124","pt":1631547106326,"mc":[{"id":"1.187562121","rc":[{"batl":[[0,1.25,373.9]],"ltp":1.28,"tv":10337.64,"id":20955040}]}]}
{"op":"mcm","clk":"4234556293","pt":1631547108540,"mc":[{"id":"1.187562121","rc":[{"trd":[[5.1,11.93]],"batb":[[0,5.1,3.64]],"ltp":5.1,"tv":1501.7,"id":9625551}],"tv":11839.35}]}
{"op":"mcm","clk":"4234556763","pt":1631547114614,"mc":[{"id":"1.187562121","rc":[{"trd":[[1.25,9.42]],"batl":[[0,1.25,373.8]],"ltp":1.25,"tv":10337.84,"id":20955040}],"tv":11839.55}]}
{"op":"mcm","clk":"4234557041","pt":1631547118734,"mc":[{"id":"1.187562121","rc":[{"batb":[[0,1.22,2],[1,1.2,955.11],[2,1.18,106]],"ltp":1.25,"tv":10337.84,"id":20955040},{"batb":[[0,5,13.08],[1,4.9,14.28],[2,4.8,3.06]],"ltp":5.1,"tv":1501.7,"id":9625551}]}]}
{"op":"mcm","clk":"4234557310","pt":1631547121648,"mc":[{"id":"1.187562121","rc":[{"batb":[[0,5.1,3.64],[1,5,13.08],[2,4.9,14.28]],"batl":[[0,5.3,4.38],[1,5.5,5.46],[2,5.6,2.72]],"ltp":5.1,"tv":1501.7,"id":9625551}]}]}
{"op":"mcm","clk":"4234557407","pt":1631547122847,"mc":[{"id":"1.187562121","rc":[{"batb":[[1,1.18,106],[2,1.17,109]],"batl":[[0,1.25,217],[1,1.32,107.61],[2,1.35,87.3]],"ltp":1.25,"tv":10337.84,"id":20955040},{"batb":[[0,4.1,3.74],[1,3.85,44.42],[2,3,5.96]],"batl":[[0,7,3],[1,7.4,3],[2,7.8,3]],"ltp":5.1,"tv":1501.7,"id":9625551}]}]}
{"op":"mcm","clk":"4234557466","pt":1631547123580,"mc":[{"id":"1.187562121","rc":[{"batl":[[0,1.35,87.3],[1,1.56,685.62],[2,3.8,27.43]],"ltp":1.25,"tv":10337.84,"id":20955040},{"batb":[[0,3.85,44.42],[1,3,5.96],[2,2.6,3.73]],"ltp":5.1,"tv":1501.7,"id":9625551}]}]}
{"op":"mcm","clk":"4234557662","pt":1631547126734,"mc":[{"id":"1.187562121","rc":[{"batl":[[0,1.32,101.11],[1,1.35,87.3],[2,1.56,685.62]],"ltp":1.25,"tv":10337.84,"id":20955040},{"batb":[[0,4.1,3.34],[1,3.85,44.42],[2,3,5.96]],"ltp":5.1,"tv":1501.7,"id":9625551}]}]}
{"op":"mcm","clk":"4234557677","pt":1631547126944,"mc":[{"id":"1.187562121","rc":[{"batl":[[0,1.35,87.3],[1,1.56,685.62],[2,3.8,27.43]],"ltp":1.25,"tv":10337.84,"id":20955040},{"batb":[[0,3.85,44.42],[1,3,5.96],[2,2.6,3.73]],"ltp":5.1,"tv":1501.7,"id":9625551}]}]}
{"op":"mcm","clk":"4234558160","pt":1631547133664,"mc":[{"id":"1.187562121","rc":[{"batl":[[0,1.32,102.36],[1,1.35,87.3],[2,1.56,685.62]],"ltp":1.25,"tv":10337.84,"id":20955040},{"batb":[[0,4.1,3.34],[1,3.85,44.42],[2,3,5.96]],"ltp":5.1,"tv":1501.7,"id":9625551}]}]}
{"op":"mcm","clk":"4234558178","pt":1631547133963,"mc":[{"id":"1.187562121","rc":[{"batl":[[0,1.35,87.3],[1,1.56,685.62],[2,3.8,27.43]],"ltp":1.25,"tv":10337.84,"id":20955040},{"batb":[[0,3.85,44.42],[1,3,5.96],[2,2.6,3.73]],"ltp":5.1,"tv":1501.7,"id":9625551}]}]}
{"op":"mcm","clk":"4234558614","pt":1631547140676,"mc":[{"id":"1.187562121","rc":[{"batl":[[0,1.32,100.86],[1,1.35,87.3],[2,1.56,685.62]],"ltp":1.25,"tv":10337.84,"id":20955040},{"batb":[[0,4.1,3.44],[1,3.85,44.42],[2,3,5.96]],"ltp":5.1,"tv":1501.7,"id":9625551}]}]}
{"op":"mcm","clk":"4234558636","pt":1631547140989,"mc":[{"id":"1.187562121","rc":[{"batl":[[0,1.35,87.3],[1,1.56,685.62],[2,3.8,27.43]],"ltp":1.25,"tv":10337.84,"id":20955040},{"batb":[[0,3.85,44.42],[1,3,5.96],[2,2.6,3.73]],"ltp":5.1,"tv":1501.7,"id":9625551}]}]}
{"op":"mcm","clk":"4234559144","pt":1631547147695,"mc":[{"id":"1.187562121","rc":[{"batl":[[0,1.32,105.11],[1,1.35,87.3],[2,1.56,685.62]],"ltp":1.25,"tv":10337.84,"id":20955040},{"batb":[[0,4.1,3.34],[1,3.85,44.42],[2,3,5.96]],"ltp":5.1,"tv":1501.7,"id":9625551}]}]}
{"op":"mcm","clk":"4234559165","pt":1631547147961,"mc":[{"id":"1.187562121","rc":[{"batl":[[0,1.35,87.3],[1,1.56,685.62],[2,3.8,27.43]],"ltp":1.25,"tv":10337.84,"id":20955040},{"batb":[[0,3.85,44.42],[1,3,5.96],[2,2.6,3.73]],"ltp":5.1,"tv":1501.7,"id":9625551}]}]}
{"op":"mcm","clk":"4234559249","pt":1631547149269,"mc":[{"id":"1.187562121","rc":[{"batl":[[1,3.8,27.43],[2,8.8,7.22]],"ltp":1.25,"tv":10337.84,"id":20955040}]}]}
{"op":"mcm","clk":"4234559303","pt":1631547150304,"mc":[{"id":"1.187562121","rc":[{"batb":[[1,1.17,109],[2,1.16,331.59]],"ltp":1.25,"tv":10337.84,"id":20955040}]}]}
{"op":"mcm","clk":"4234559390","pt":1631547151606,"mc":[{"id":"1.187562121","rc":[{"trd":[[1.22,4]],"batb":[[0,1.17,109],[1,1.16,331.59],[2,1.15,103.43]],"batl":[[0,1.21,177.65],[1,1.23,8.13],[2,1.25,1437.48]],"ltp":1.22,"tv":10341.84,"id":20955040},{"batb":[[0,5.7,10.82],[1,5.6,5.36],[2,5.5,2.68]],"batl":[[0,6.2,8.05],[1,6.8,252.78],[2,7,3]],"ltp":5.1,"tv":1501.7,"id":9625551}],"tv":11843.55}]}
{"op":"mcm","clk":"4234559484","pt":1631547152900,"mc":[{"id":"1.187562121","rc":[{"batb":[[0,1.17,117.55]],"ltp":1.22,"tv":10341.84,"id":20955040},{"batl":[[1,6.4,4.68],[2,6.6,2.34]],"ltp":5.1,"tv":1501.7,"id":9625551}]}]}
{"op":"mcm","clk":"4234559502","pt":1631547153162,"mc":[{"id":"1.187562121","rc":[{"batb":[[0,1.19,103],[1,1.17,117.55],[2,1.16,331.59]],"batl":[[0,1.21,401.65]],"ltp":1.22,"tv":10341.84,"id":20955040},{"batl":[[1,6.4,7.68]],"ltp":5.1,"tv":1501.7,"id":9625551}]}]}
{"op":"mcm","clk":"4234559799","pt":1631547156906,"mc":[{"id":"1.187562121","rc":[{"batl":[[0,1.21,480.65]],"ltp":1.22,"tv":10341.84,"id":20955040}]}]}
{"op":"mcm","clk":"4234560040","pt":1631547159708,"mc":[{"id":"1.187562121","rc":[{"batb":[[1,1.18,158.86],[2,1.17,273.52]],"batl":[[2,1.25,1557.86]],"ltp":1.22,"tv":10341.84,"id":20955040},{"batl":[[2,6.6,4.34]],"ltp":5.1,"tv":1501.7,"id":9625551}]}]}
{"op":"mcm","clk":"4234560694","pt":1631547168705,"mc":[{"id":"1.187562121","rc":[{"trd":[[1.19,775.33]],"batb":[[0,1.19,94.07]],"ltp":1.19,"tv":10359.7,"id":20955040}],"tv":11861.4}]}
{"op":"mcm","clk":"4234561355","pt":1631547177831,"mc":[{"id":"1.187562121","rc":[{"batl":[[0,1.21,457.5],[2,1.25,120.38]],"ltp":1.19,"tv":10359.7,"id":20955040},{"batl":[[0,6.4,7.68],[1,6.6,4.34],[2,6.8,2.34]],"ltp":5.1,"tv":1501.7,"id":9625551}]}]}
{"op":"mcm","clk":"4234561433","pt":1631547178828,"mc":[{"id":"1.187562121","rc":[{"batb":[[0,1.17,109],[1,1.16,113],[2,1.15,103.43]],"batl":[[0,1.27,98.5],[1,1.49,772.97],[2,3.8,27.43]],"ltp":1.19,"tv":10359.7,"id":20955040},{"batb":[[0,4.7,3.22],[1,4.5,27.6],[2,3,5.96]],"batl":[[0,7,5],[1,7.4,3],[2,7.8,3]],"ltp":5.1,"tv":1501.7,"id":9625551}]}]}
{"op":"mcm","clk":"4234561663","pt":1631547181616,"mc":[{"id":"1.187562121","rc":[{"batb":[[0,1.17,259.97]],"ltp":1.19,"tv":10359.7,"id":20955040}]}]}
{"op":"mcm","clk":"4234561908","pt":1631547184824,"mc":[{"id":"1.187562121","rc":[{"batb":[[0,1.18,122.36],[1,1.17,259.97],[2,1.16,113]],"ltp":1.19,"tv":10359.7,"id":20955040},{"batl":[[0,6.6,2],[1,7,5],[2,7.4,3]],"ltp":5.1,"tv":1501.7,"id":9625551}]}]}
{"op":"mcm","clk":"4234561987","pt":1631547185853,"mc":[{"id":"1.187562121","rc":[{"batb":[[0,1.17,259.97],[1,1.16,113],[2,1.15,103.43]],"ltp":1.19,"tv":10359.7,"id":20955040},{"batl":[[0,7,5],[1,7.4,3],[2,7.8,3]],"ltp":5.1,"tv":1501.7,"id":9625551}]}]}
{"op":"mcm","clk":"4234562258","pt":1631547189156,"mc":[{"id":"1.187562121","rc":[{"batl":[[0,1.25,117.26],[1,1.27,98.5],[2,1.49,772.97]],"ltp":1.19,"tv":10359.7,"id":20955040},{"batb":[[0,5,3.22],[1,4.7,3.22],[2,4.5,27.6]],"ltp":5.1,"tv":1501.7,"id":9625551}]}]}
{"op":"mcm","clk":"4234562484","pt":1631547191837,"mc":[{"id":"1.187562121","rc":[{"batb":[[0,1.18,140.86],[1,1.17,259.97],[2,1.16,113]],"batl":[[0,1.49,772.97],[1,3.8,27.43],[2,8.8,7.22]],"ltp":1.19,"tv":10359.7,"id":20955040},{"batb":[[0,4.7,3.22],[1,4.5,27.6],[2,3,5.96]],"batl":[[0,6.6,2],[1,7,5],[2,7.4,3]],"ltp":5.1,"tv":1501.7,"id":9625551}]}]}
{"op":"mcm","clk":"4234562521","pt":1631547192255,"mc":[{"id":"1.187562121","rc":[{"batb":[[0,1.17,259.97],[1,1.16,113],[2,1.15,103.43]],"ltp":1.19,"tv":10359.7,"id":20955040},{"batl":[[0,7,5],[1,7.4,3],[2,7.8,3]],"ltp":5.1,"tv":1501.7,"id":9625551}]}]}
{"op":"mcm","clk":"4234562626","pt":1631547193617,"mc":[{"id":"1.187562121","rc":[{"batl":[[0,1.19,807.8],[1,1.2,141.58],[2,1.21,8.26]],"ltp":1.19,"tv":10359.7,"id":20955040},{"batb":[[0,6.2,4.84],[1,6,12.13],[2,5.9,36.32]],"batl":[[0,6.8,7.18],[1,7,5],[2,7.2,132.23]],"ltp":5.1,"tv":1501.7,"id":9625551}]}]}
{"op":"mcm","clk":"4234562740","pt":1631547194831,"mc":[{"id":"1.187562121","rc":[{"batb":[[2,1.15,112.13]],"ltp":1.19,"tv":10359.7,"id":20955040},{"batl":[[2,7.2,136.39]],"ltp":5.1,"tv":1501.7,"id":9625551}]}]}
{"op":"mcm","clk":"4234562771","pt":1631547195143,"mc":[{"id":"1.187562121","rc":[{"batl":[[0,1.19,1039.8],[1,1.2,373.58]],"ltp":1.19,"tv":10359.7,"id":20955040},{"batb":[[0,6.2,19.84],[1,6,27.13]],"ltp":5.1,"tv":1501.7,"id":9625551}]}]}
{"op":"mcm","clk":"4234563410","pt":1631547201560,"mc":[{"id":"1.187562121","rc":[{"batl":[[0,1.19,1116.8]],"ltp":1.19,"tv":10359.7,"id":20955040}]}]}
{"op":"mcm","clk":"4234566263","pt":1631547237072,"mc":[{"id":"1.187562121","rc":[{"trd":[[1.17,431.13]],"batb":[[0,1.17,171.97]],"ltp":1.17,"tv":10535.7,"id":20955040}],"tv":12037.4}]}
{"op":"mcm","clk":"4234566576","pt":1631547240838,"mc":[{"id":"1.187562121","rc":[{"trd":[[6.2,74.64]],"batb":[[0,6.2,2.79]],"ltp":6.2,"tv":1535.81,"id":9625551}],"tv":12071.51}]}
{"op":"mcm","clk":"4234566867","pt":1631547244369,"mc":[{"id":"1.187562121","rc":[{"batb":[[0,1.17,150.97]],"ltp":1.17,"tv":10535.7,"id":20955040},{"batl":[[1,7,2]],"ltp":6.2,"tv":1535.81,"id":9625551}]}]}
{"op":"mcm","clk":"4234567092","pt":1631547247359,"mc":[{"id":"1.187562121","rc":[{"batb":[[0,1.18,106],[1,1.17,150.97],[2,1.16,113]],"ltp":1.17,"tv":10535.7,"id":20955040}]}]}
{"op":"mcm","clk":"4234567644","pt":1631547254559,"mc":[{"id":"1.187562121","rc":[{"batb":[[0,1.17,150.97],[1,1.16,113],[2,1.15,112.13]],"ltp":1.17,"tv":10535.7,"id":20955040}]}]}
{"op":"mcm","clk":"4234567836","pt":1631547257699,"mc":[{"id":"1.187562121","rc":[{"batb":[[0,1.17,259.97]],"ltp":1.17,"tv":10535.7,"id":20955040},{"batl":[[1,7,5]],"ltp":6.2,"tv":1535.81,"id":9625551}]}]}
{"op":"mcm","clk":"4234568262","pt":1631547263182,"mc":[{"id":"1.187562121","rc":[{"batl":[[0,1.19,1116.81]],"ltp":1.17,"tv":10535.7,"id":20955040}]}]}
{"op":"mcm","clk":"4234569850","pt":1631547285133,"mc":[{"id":"1.187562121","rc":[{"batb":[[1,1.16,268.53]],"batl":[[2,1.21,133.76]],"ltp":1.17,"tv":10535.7,"id":20955040}]}]}
{"op":"mcm","clk":"4234570354","pt":1631547291864,"mc":[{"id":"1.187562121","rc":[{"batb":[[0,1.16,268.53],[1,1.15,103.43],[2,1.14,121]],"batl":[[0,1.19,77.01],[1,1.2,232],[2,1.21,125.5]],"ltp":1.17,"tv":10535.7,"id":20955040},{"batb":[[0,6,15],[1,5.7,2.72],[2,5.4,34.73]],"batl":[[0,7.4,5],[1,7.8,3],[2,8.2,3]],"ltp":6.2,"tv":1535.81,"id":9625551}]}]}
{"op":"mcm","clk":"4234570433","pt":1631547292969,"mc":[{"id":"1.187562121","rc":[{"batl":[[0,1.2,232.01],[1,1.21,125.5],[2,3.8,27.43]],"ltp":1.17,"tv":10535.7,"id":20955040}]}]}
{"op":"mcm","clk":"4234570556","pt":1631547294658,"mc":[{"id":"1.187562121","rc":[{"batb":[[0,1.17,168.97],[1,1.16,268.53],[2,1.15,103.43]],"batl":[[0,1.2,368.89]],"ltp":1.17,"tv":10535.7,"id":20955040},{"batb":[[0,6,17.99]],"batl":[[0,7,2],[1,7.4,5],[2,7.8,3]],"ltp":6.2,"tv":1535.81,"id":9625551}]}]}
{"op":"mcm","clk":"4234570580","pt":1631547294960,"mc":[{"id":"1.187562121","rc":[{"batb":[[0,1.16,268.53],[1,1.15,103.43],[2,1.14,121]],"ltp":1.17,"tv":10535.7,"id":20955040},{"batl":[[0,7.4,5],[1,7.8,3],[2,8.2,3]],"ltp":6.2,"tv":1535.81,"id":9625551}]}]}
{"op":"mcm","clk":"4234571081","pt":1631547301685,"mc":[{"id":"1.187562121","rc":[{"batb":[[0,1.17,154.97],[1,1.16,268.53],[2,1.15,103.43]],"ltp":1.17,"tv":10535.7,"id":20955040},{"batl":[[0,7,2],[1,7.4,5],[2,7.8,3]],"ltp":6.2,"tv":1535.81,"id":9625551}]}]}
{"op":"mcm","clk":"4234571106","pt":1631547301976,"mc":[{"id":"1.187562121","rc":[{"batb":[[0,1.16,268.53],[1,1.15,103.43],[2,1.14,121]],"ltp":1.17,"tv":10535.7,"id":20955040},{"batl":[[0,7.4,5],[1,7.8,3],[2,8.2,3]],"ltp":6.2,"tv":1535.81,"id":9625551}]}]}
{"op":"mcm","clk":"4234571559","pt":1631547308266,"mc":[{"id":"1.187562121","rc":[{"batl":[[0,1.2,232.01],[1,3.8,27.43],[2,8.8,7.22]],"ltp":1.17,"tv":10535.7,"id":20955040},{"batb":[[0,6,15]],"ltp":6.2,"tv":1535.81,"id":9625551}]}]}
{"op":"mcm","clk":"4234571773","pt":1631547310880,"mc":[{"id":"1.187562121","rc":[{"trd":[[1.18,267.01]],"batb":[[0,1.18,127.11],[1,1.17,63.56],[2,1.16,340.71]],"batl":[[0,1.2,616.56]],"ltp":1.18,"tv":10535.71,"id":20955040},{"batb":[[0,6,89.29]],"batl":[[0,6.4,5.69],[1,6.6,18.18],[2,6.8,128.85]],"ltp":6.2,"tv":1535.81,"id":9625551}],"tv":12071.53}]}
{"op":"mcm","clk":"4234571855","pt":1631547311879,"mc":[{"id":"1.187562121","rc":[{"batb":[[0,1.18,25.42],[1,1.17,12.72],[2,1.16,289.87]],"batl":[[1,1.21,24.8],[2,1.22,20.6]],"ltp":1.18,"tv":10535.71,"id":20955040}]}]}
{"op":"mcm","clk":"4234571909","pt":1631547312577,"mc":[{"id":"1.187562121","rc":[{"batb":[[1,1.17,121.72]],"ltp":1.18,"tv":10535.71,"id":20955040}]}]}
{"op":"mcm","clk":"4234572428","pt":1631547318684,"mc":[{"id":"1.187562121","rc":[{"batb":[[0,1.18,170.28],[1,1.17,252.69]],"batl":[[0,1.2,755.09],[1,1.21,150.3]],"ltp":1.18,"tv":10535.71,"id":20955040},{"batb":[[0,6,92.28]],"batl":[[1,6.6,20.19]],"ltp":6.2,"tv":1535.81,"id":9625551}]}]}
{"op":"mcm","clk":"4234572512","pt":1631547319881,"mc":[{"id":"1.187562121","rc":[{"batl":[[0,1.2,826.09],[2,1.22,140.85]],"ltp":1.18,"tv":10535.71,"id":20955040},{"batb":[[2,5.5,3.7]],"ltp":6.2,"tv":1535.81,"id":9625551}]}]}
{"op":"mcm","clk":"4234572742","pt":1631547322865,"mc":[{"id":"1.187562121","rc":[{"batb":[[0,1.16,268.53],[1,1.15,103.43],[2,1.14,380.36]],"batl":[[0,1.2,232],[1,1.21,125.5],[2,1.22,120.25]],"ltp":1.18,"tv":10535.71,"id":20955040},{"batb":[[0,6,15]],"batl":[[0,7,2],[1,7.4,5],[2,7.8,3]],"ltp":6.2,"tv":1535.81,"id":9625551}]}]}
{"op":"mcm","clk":"4234572750","pt":1631547322972,"mc":[{"id":"1.187562121","rc":[{"batb":[[0,1.16,113]],"ltp":1.18,"tv":10535.71,"id":20955040},{"batl":[[1,7.4,3]],"ltp":6.2,"tv":1535.81,"id":9625551}]}]}
{"op":"mcm","clk":"4234572952","pt":1631547325689,"mc":[{"id":"1.187562121","rc":[{"batb":[[0,1.18,135.86],[1,1.17,148.97],[2,1.16,113]],"ltp":1.18,"tv":10535.71,"id":20955040},{"batl":[[0,6.6,2.01],[1,7,2],[2,7.4,3]],"ltp":6.2,"tv":1535.81,"id":9625551}]}]}
{"op":"mcm","clk":"4234572971","pt":1631547325990,"mc":[{"id":"1.187562121","rc":[{"batb":[[0,1.17,148.97],[1,1.16,113],[2,1.15,103.43]],"ltp":1.18,"tv":10535.71,"id":20955040},{"batl":[[0,7,2],[1,7.4,3],[2,7.8,3]],"ltp":6.2,"tv":1535.81,"id":9625551}]}]}
{"op":"mcm","clk":"4234573618","pt":1631547336169,"mc":[{"id":"1.187562121","rc":[{"batb":[[0,1.18,129.36],[1,1.17,148.97],[2,1.16,113]],"ltp":1.18,"tv":10535.71,"id":20955040},{"batl":[[0,6.6,2],[1,7,2],[2,7.4,3]],"ltp":6.2,"tv":1535.81,"id":9625551}]}]}
{"op":"mcm","clk":"4234573728","pt":1631547337681,"mc":[{"id":"1.187562121","rc":[{"batb":[[0,1.17,148.97],[1,1.16,113],[2,1.15,103.43]],"ltp":1.18,"tv":10535.71,"id":20955040},{"batl":[[0,7,2],[1,7.4,3],[2,7.8,3]],"ltp":6.2,"tv":1535.81,"id":9625551}]}]}
{"op":"mcm","clk":"4234573979","pt":1631547340872,"mc":[{"id":"1.187562121","rc":[{"batb":[[0,1.19,25.2],[1,1.18,1078.32],[2,1.17,170.12]],"batl":[[1,1.21,850.39]],"ltp":1.18,"tv":10535.71,"id":20955040},{"batl":[[0,6.2,7.95],[1,7,2],[2,7.4,3]],"ltp":6.2,"tv":1535.81,"id":9625551}]}]}
{"op":"mcm","clk":"4234574051","pt":1631547341911,"mc":[{"id":"1.187562121","rc":[{"batb":[[0,1.19,128.2],[1,1.18,1184.32],[2,1.17,279.12]],"ltp":1.18,"tv":10535.71,"id":20955040},{"batb":[[2,5.5,9.16]],"batl":[[1,6.4,3],[2,7,5]],"ltp":6.2,"tv":1535.81,"id":9625551}]}]}
{"op":"mcm","clk":"4234574466","pt":1631547348285,"mc":[{"id":"1.187562121","rc":[{"batb":[[0,1.19,252.91],[1,1.18,1325.18]],"ltp":1.18,"tv":10535.71,"id":20955040},{"batl":[[1,6.4,5],[2,6.6,2]],"ltp":6.2,"tv":1535.81,"id":9625551}]}]}
{"op":"mcm","clk":"4234575123","pt":1631547357832,"mc":[{"id":"1.187562121","rc":[{"batb":[[0,1.19,103],[1,1.18,246.86],[2,1.17,257.97]],"batl":[[1,1.21,125.5]],"ltp":1.18,"tv":10535.71,"id":20955040},{"batb":[[2,5.5,3.7]],"batl":[[0,6.4,3],[1,6.6,2],[2,7,5]],"ltp":6.2,"tv":1535.81,"id":9625551}]}]}
{"op":"mcm","clk":"4234575182","pt":1631547358715,"mc":[{"id":"1.187562121","rc":[{"batb":[[0,1.18,246.86],[1,1.17,257.97],[2,1.16,113]],"batl":[[0,1.21,125.5],[1,3.8,27.43],[2,8.8,7.22]],"ltp":1.18,"tv":10535.71,"id":20955040},{"batb":[[0,5.7,2.72],[1,5,20.72],[2,3,5.96]],"batl":[[0,6.6,2],[1,7,5],[2,7.4,3]],"ltp":6.2,"tv":1535.81,"id":9625551}]}]}
{"op":"mcm","clk":"4234575858","pt":1631547367631,"mc":[{"id":"1.187562121","rc":[{"batl":[[0,1.2,18.43],[1,1.21,125.5],[2,3.8,27.43]],"ltp":1.18,"tv":10535.71,"id":20955040},{"batb":[[0,6,22.42],[1,5.7,2.72],[2,5,20.72]],"batl":[[0,6.2,21.53],[1,6.6,2],[2,7,5]],"ltp":6.2,"tv":1535.81,"id":9625551}]}]}
{"op":"mcm","clk":"4234575921","pt":1631547368313,"mc":[{"id":"1.187562121","rc":[{"batl":[[0,1.21,125.5],[1,3.8,27.43],[2,8.8,7.22]],"ltp":1.18,"tv":10535.71,"id":20955040},{"batb":[[0,5.7,2.72],[1,5,20.72],[2,3,5.96]],"batl":[[0,6.6,2],[1,7,5],[2,7.4,3]],"ltp":6.2,"tv":1535.81,"id":9625551}]}]}
{"op":"mcm","clk":"4234576176","pt":1631547371646,"mc":[{"id":"1.187562121","rc":[{"batb":[[0,1.19,134.71],[1,1.18,246.86],[2,1.17,257.97]],"ltp":1.18,"tv":10535.71,"id":20955040},{"batl":[[0,6.4,2],[1,6.6,2],[2,7,5]],"ltp":6.2,"tv":1535.81,"id":9625551}]}]}
{"op":"mcm","clk":"4234576204","pt":1631547371914,"mc":[{"id":"1.187562121","rc":[{"batb":[[0,1.18,246.86],[1,1.17,257.97],[2,1.16,113]],"ltp":1.18,"tv":10535.71,"id":20955040},{"batl":[[0,6.6,2],[1,7,5],[2,7.4,3]],"ltp":6.2,"tv":1535.81,"id":9625551}]}]}
{"op":"mcm","clk":"4234576816","pt":1631547380853,"mc":[{"id":"1.187562121","rc":[{"batb":[[0,1.2,22.48],[1,1.19,917.42],[2,1.18,255.33]],"batl":[[1,1.22,762.38],[2,3.8,27.43]],"ltp":1.18,"tv":10535.71,"id":20955040},{"batl":[[0,6,4.5],[1,6.2,24.2],[2,6.4,12.1]],"ltp":6.2,"tv":1535.81,"id":9625551}]}]}
{"op":"mcm","clk":"4234576892","pt":1631547381746,"mc":[{"id":"1.187562121","rc":[{"batb":[[1,1.19,850.2]],"batl":[[2,1.24,8.06]],"ltp":1.18,"tv":10535.71,"id":20955040},{"batb":[[1,5.4,27.78],[2,5.3,13.9]],"batl":[[1,6.2,14.52],[2,6.4,7.26]],"ltp":6.2,"tv":1535.81,"id":9625551}]}]}
{"op":"mcm","clk":"4234576970","pt":1631547382739,"mc":[{"id":"1.187562121","rc":[{"batb":[[1,1.19,953.2]],"batl":[[0,1.21,363.5]],"ltp":1.18,"tv":10535.71,"id":20955040},{"batb":[[1,5.4,5.56],[2,5.3,2.78]],"batl":[[2,6.4,10.26]],"ltp":6.2,"tv":1535.81,"id":9625551}]}]}
{"op":"mcm","clk":"4234577374","pt":1631547387487,"mc":[{"id":"1.187562121","rc":[{"batb":[[1,1.19,1088.91]],"batl":[[1,1.22,896.13]],"ltp":1.18,"tv":10535.71,"id":20955040},{"batb":[[1,5.5,3.7],[2,5.4,5.56]],"batl":[[2,6.4,12.3]],"ltp":6.2,"tv":1535.81,"id":9625551}]}]}
{"op":"mcm","clk":"4234578040","pt":1631547397807,"mc":[{"id":"1.187562121","rc":[{"batb":[[0,1.18,246.86],[1,1.17,257.97],[2,1.16,336.96]],"batl":[[0,1.21,125.5],[1,1.22,133.75],[2,3.8,27.43]],"ltp":1.18,"tv":10535.71,"id":20955040},{"batb":[[2,4.9,22.65]],"batl":[[0,6.6,2],[1,7,5],[2,7.4,3]],"ltp":6.2,"tv":1535.81,"id":9625551}]}]}
{"op":"mcm","clk":"4234578056","pt":1631547398013,"mc":[{"id":"1.187562121","rc":[{"batl":[[0,1.22,133.75],[1,3.8,27.43],[2,8.8,7.22]],"ltp":1.18,"tv":10535.71,"id":20955040},{"batb":[[0,5.5,3.7],[1,4.9,22.65],[2,3,5.96]],"ltp":6.2,"tv":1535.81,"id":9625551}]}]}
{"op":"mcm","clk":"4234578254","pt":1631547400828,"mc":[{"id":"1.187562121","rc":[{"batb":[[0,1.19,149.71],[1,1.18,246.86],[2,1.17,257.97]],"ltp":1.18,"tv":10535.71,"id":20955040},{"batl":[[0,6.4,2],[1,6.6,2],[2,7,5]],"ltp":6.2,"tv":1535.81,"id":9625551}]}]}
{"op":"mcm","clk":"4234578297","pt":1631547401502,"mc":[{"id":"1.187562121","rc":[{"batb":[[0,1.18,246.86],[1,1.17,257.97],[2,1.16,336.96]],"ltp":1.18,"tv":10535.71,"id":20955040},{"batl":[[0,6.6,2],[1,7,5],[2,7.4,3]],"ltp":6.2,"tv":1535.81,"id":9625551}]}]}
{"op":"mcm","clk":"4234578520","pt":1631547404906,"mc":[{"id":"1.187562121","rc":[{"batl":[[0,1.21,153],[1,1.22,133.75],[2,3.8,27.43]],"ltp":1.18,"tv":10535.71,"id":20955040},{"batb":[[0,5.8,18.78],[1,5.7,3.42],[2,5.5,3.7]],"batl":[[0,5.9,20.35],[1,6.6,2],[2,7,5]],"ltp":6.2,"tv":1535.81,"id":9625551}]}]}
{"op":"mcm","clk":"4234578533","pt":1631547405113,"mc":[{"id":"1.187562121","rc":[{"batl":[[0,1.22,133.75],[1,3.8,27.43],[2,8.8,7.22]],"ltp":1.18,"tv":10535.71,"id":20955040},{"batb":[[0,5.5,3.7],[1,4.9,22.65],[2,3,5.96]],"batl":[[0,6.6,2],[1,7,5],[2,7.4,3]],"ltp":6.2,"tv":1535.81,"id":9625551}]}]}
{"op":"mcm","clk":"4234579334","pt":1631547415640,"mc":[{"id":"1.187562121","rc":[{"batl":[[0,1.21,141.5],[1,1.22,133.75],[2,3.8,27.43]],"ltp":1.18,"tv":10535.71,"id":20955040},{"batb":[[0,5.7,3.12],[1,5.5,3.7],[2,4.9,22.65]],"ltp":6.2,"tv":1535.81,"id":9625551}]}]}
{"op":"mcm","clk":"4234579459","pt":1631547417311,"mc":[{"id":"1.187562121","rc":[{"batl":[[0,1.21,1159.92],[2,1.23,8.13]],"ltp":1.18,"tv":10535.71,"id":20955040},{"batb":[[0,5.9,5.08],[1,5.8,2.54],[2,5.7,5.66]],"batl":[[0,6.2,4.94],[1,6.6,2],[2,6.8,214.71]],"ltp":6.2,"tv":1535.81,"id":9625551}]}]}
{"op":"mcm","clk":"4234579560","pt":1631547418825,"mc":[{"id":"1.187562121","rc":[{"batb":[[1,1.17,266.52]],"batl":[[0,1.21,1397.92]],"ltp":1.18,"tv":10535.71,"id":20955040},{"batl":[[2,6.8,219.13]],"ltp":6.2,"tv":1535.81,"id":9625551}]}]}
{"op":"mcm","clk":"4234580024","pt":1631547424355,"mc":[{"id":"1.187562121","rc":[{"batb":[[0,1.19,126.71],[1,1.18,246.86],[2,1.17,266.52]],"ltp":1.18,"tv":10535.71,"id":20955040},{"batl":[[1,6.4,2],[2,6.6,2]],"ltp":6.2,"tv":1535.81,"id":9625551}]}]}
{"op":"mcm","clk":"4234580116","pt":1631547425817,"mc":[{"id":"1.187562121","rc":[{"batl":[[0,1.21,1485.92]],"ltp":1.18,"tv":10535.71,"id":20955040}]}]}
{"op":"mcm","clk":"4234580753","pt":1631547432766,"mc":[{"id":"1.187562121","rc":[{"batb":[[2,1.17,257.97]],"batl":[[0,1.21,467.5],[2,3.8,27.43]],"ltp":1.18,"tv":10535.71,"id":20955040},{"batb":[[0,5.7,3.12],[1,5.5,3.7],[2,5.3,18.03]],"batl":[[0,6.4,2],[1,6.6,2],[2,7,5]],"ltp":6.2,"tv":1535.81,"id":9625551}]}]}
{"op":"mcm","clk":"4234580853","pt":1631547433734,"mc":[{"id":"1.187562121","rc":[{"batb":[[0,1.18,106],[1,1.17,257.97],[2,1.16,113]],"batl":[[0,1.21,88]],"ltp":1.18,"tv":10535.71,"id":20955040},{"batb":[[0,5.5,3.7],[1,5.1,19.71],[2,3,5.96]],"batl":[[0,6.6,2],[1,7,5],[2,7.4,3]],"ltp":6.2,"tv":1535.81,"id":9625551}]}]}
{"op":"mcm","clk":"4234580864","pt":1631547433930,"mc":[{"id":"1.187562121","rc":[{"batl":[[0,1.22,133.75],[1,3.8,27.43],[2,8.8,7.22]],"ltp":1.18,"tv":10535.71,"id":20955040}]}]}
{"op":"mcm","clk":"4234581089","pt":1631547436465,"mc":[{"id":"1.187562121","rc":[{"batb":[[0,1.18,252.86]],"ltp":1.18,"tv":10535.71,"id":20955040}]}]}
{"op":"mcm","clk":"4234581340","pt":1631547440446,"mc":[{"id":"1.187562121","rc":[{"batl":[[0,1.21,138.5],[1,1.22,133.75],[2,3.8,27.43]],"ltp":1.18,"tv":10535.71,"id":20955040},{"batb":[[0,5.7,2.92],[1,5.5,3.7],[2,5.1,19.71]],"ltp":6.2,"tv":1535.81,"id":9625551}]}]}
{"op":"mcm","clk":"4234581461","pt":1631547441854,"mc":[{"id":"1.187562121","rc":[{"batb":[[0,1.18,146.86]],"batl":[[0,1.22,133.75],[1,3.8,27.43],[2,8.8,7.22]],"ltp":1.18,"tv":10535.71,"id":20955040},{"batb":[[0,5.5,3.7],[1,5.1,19.71],[2,3,5.96]],"ltp":6.2,"tv":1535.81,"id":9625551}]}]}
{"op":"mcm","clk":"4234581540","pt":1631547442844,"mc":[{"id":"1.187562121","rc":[{"batb":[[0,1.18,155.33],[1,1.17,109]],"ltp":1.18,"tv":10535.71,"id":20955040},{"batb":[[0,5.7,124.27],[1,5.5,3.7],[2,5.1,19.71]],"batl":[[0,6,5.76],[1,6.2,681.44],[2,6.4,163.71]],"ltp":6.2,"tv":1535.81,"id":9625551}]}]}
{"op":"mcm","clk":"4234581626","pt":1631547443849,"mc":[{"id":"1.187562121","rc":[{"batl":[[1,1.24,8.06],[2,3.8,27.43]],"ltp":1.18,"tv":10535.71,"id":20955040},{"batb":[[2,5.4,27.78]],"batl":[[1,6.2,4.84],[2,6.4,154.03]],"ltp":6.2,"tv":1535.81,"id":9625551}]}]}
{"op":"mcm","clk":"4234581704","pt":1631547444852,"mc":[{"id":"1.187562121","rc":[{"trd":[[1.2,46.72]],"batb":[[0,1.19,103],[1,1.18,155.33],[2,1.17,320.38]],"batl":[[0,1.21,238],[1,1.22,133.75],[2,1.24,8.06]],"ltp":1.2,"tv":10537.71,"id":20955040},{"trd":[[6,0.4]],"batb":[[2,5.4,5.56]],"batl":[[0,6,5.36],[2,6.4,157.03]],"ltp":6.0,"tv":1536.21,"id":9625551}],"tv":12073.93}]}
{"op":"mcm","clk":"4234581891","pt":1631547447868,"mc":[{"id":"1.187562121","rc":[{"batb":[[1,1.18,157.33]],"batl":[[2,1.24,270.51]],"ltp":1.2,"tv":10537.71,"id":20955040},{"batl":[[0,5.8,4.65],[1,6,5.36],[2,6.2,4.84]],"ltp":6.0,"tv":1536.21,"id":9625551}]}]}
{"op":"mcm","clk":"4234581896","pt":1631547447972,"mc":[{"id":"1.187562121","rc":[{"batl":[[2,1.24,8.06]],"ltp":1.2,"tv":10537.71,"id":20955040},{"batl":[[0,6,5.36],[1,6.2,4.84],[2,6.4,157.03]],"ltp":6.0,"tv":1536.21,"id":9625551}]}]}
{"op":"mcm","clk":"4234581990","pt":1631547449588,"mc":[{"id":"1.187562121","rc":[{"batb":[[2,1.17,455.35]],"ltp":1.2,"tv":10537.71,"id":20955040}]}]}
{"op":"mcm","clk":"4234582334","pt":1631547454371,"mc":[{"id":"1.187562121","rc":[{"batb":[[0,5.7,120.75]],"batl":[[0,6.2,4.84],[1,6.4,157.03],[2,6.6,4.42]],"ltp":6.0,"tv":1536.21,"id":9625551}]}]}
{"op":"mcm","clk":"4234582564","pt":1631547457571,"mc":[{"id":"1.187562121","rc":[{"batb":[[0,5.7,124.69]],"batl":[[0,6,5.36],[1,6.2,4.84],[2,6.4,157.03]],"ltp":6.0,"tv":1536.21,"id":9625551}]}]}
{"op":"mcm","clk":"4234583073","pt":1631547465420,"mc":[{"id":"1.187562121","rc":[{"trd":[[1.21,92.33]],"batl":[[0,1.21,234.69]],"ltp":1.21,"tv":10544.34,"id":20955040}],"tv":12080.55}]}
{"op":"mcm","clk":"4234584042","pt":1631547480705,"mc":[{"id":"1.187562121","rc":[{"batb":[[1,1.18,148.86],[2,1.17,243.97]],"batl":[[1,1.25,117.7],[2,1.26,103.25]],"ltp":1.21,"tv":10544.34,"id":20955040},{"batb":[[0,5,3.04],[1,4.7,3.32],[2,4.4,29.44]],"batl":[[0,6.4,3],[1,6.6,2],[2,7,5]],"ltp":6.0,"tv":1536.21,"id":9625551}]}]}
{"op":"mcm","clk":"4234584099","pt":1631547481500,"mc":[{"id":"1.187562121","rc":[{"batb":[[0,1.18,2],[1,1.17,243.97],[2,1.16,113]],"batl":[[0,1.27,105.5],[1,3.8,27.43],[2,8.8,7.22]],"ltp":1.21,"tv":10544.34,"id":20955040},{"batb":[[0,4.7,3.32],[1,4.4,29.44],[2,3,5.96]],"batl":[[0,7,5],[1,7.4,3],[2,7.8,3]],"ltp":6.0,"tv":1536.21,"id":9625551}]}]}
{"op":"mcm","clk":"4234584676","pt":1631547491749,"mc":[{"id":"1.187562121","rc":[{"batb":[[0,1.18,141.86]],"batl":[[0,1.25,109.62],[1,1.27,105.5],[2,3.8,27.43]],"ltp":1.21,"tv":10544.34,"id":20955040},{"batb":[[0,5,2.92],[1,4.7,3.32],[2,4.4,29.44]],"batl":[[0,6.6,2],[1,7,5],[2,7.4,3]],"ltp":6.0,"tv":1536.21,"id":9625551}]}]}
{"op":"mcm","clk":"4234584687","pt":1631547491959,"mc":[{"id":"1.187562121","rc":[{"batb":[[0,1.18,2]],"batl":[[0,1.27,105.5],[1,3.8,27.43],[2,8.8,7.22]],"ltp":1.21,"tv":10544.34,"id":20955040},{"batb":[[0,4.7,3.32],[1,4.4,29.44],[2,3,5.96]],"batl":[[0,7,5],[1,7.4,3],[2,7.8,3]],"ltp":6.0,"tv":1536.21,"id":9625551}]}]}
{"op":"mcm","clk":"4234584929","pt":1631547495769,"mc":[{"id":"1.187562121","rc":[{"batb":[[0,1.18,150.86]],"batl":[[0,1.25,108.14],[1,1.27,105.5],[2,3.8,27.43]],"ltp":1.21,"tv":10544.34,"id":20955040},{"batb":[[0,5,3.43],[1,4.7,3.32],[2,4.4,29.44]],"batl":[[0,6.6,2],[1,7,5],[2,7.4,3]],"ltp":6.0,"tv":1536.21,"id":9625551}]}]}
{"op":"mcm","clk":"4234584954","pt":1631547496140,"mc":[{"id":"1.187562121","rc":[{"batb":[[0,1.18,2]],"batl":[[0,1.27,105.5],[1,3.8,27.43],[2,8.8,7.22]],"ltp":1.21,"tv":10544.34,"id":20955040},{"batb":[[0,4.7,3.32],[1,4.4,29.44],[2,3,5.96]],"batl":[[0,7,5],[1,7.4,3],[2,7.8,3]],"ltp":6.0,"tv":1536.21,"id":9625551}]}]}
{"op":"mcm","clk":"4234585416","pt":1631547502862,"mc":[{"id":"1.187562121","rc":[{"batb":[[0,1.18,140.86]],"batl":[[0,1.25,111.3],[1,1.27,105.5],[2,3.8,27.43]],"ltp":1.21,"tv":10544.34,"id":20955040},{"batb":[[0,5,3.11],[1,4.7,3.32],[2,4.4,29.44]],"batl":[[0,6.6,2],[1,7,5],[2,7.4,3]],"ltp":6.0,"tv":1536.21,"id":9625551}]}]}
{"op":"mcm","clk":"4234585465","pt":1631547503642,"mc":[{"id":"1.187562121","rc":[{"batb":[[0,1.23,162.6],[1,1.22,8.2],[2,1.18,2]],"batl":[[0,1.26,23.77]],"ltp":1.21,"tv":10544.34,"id":20955040},{"batb":[[0,4.8,181.3]],"batl":[[0,5.1,5.09],[1,5.3,28.3],[2,5.4,14.16]],"ltp":6.0,"tv":1536.21,"id":9625551}]}]}
{"op":"mcm","clk":"4234585527","pt":1631547504846,"mc":[{"id":"1.187562121","rc":[{"trd":[[1.24,2]],"batb":[[0,1.23,97.56],[1,1.22,170.42],[2,1.18,198.45]],"batl":[[2,1.28,7.81]],"ltp":1.24,"tv":10546.34,"id":20955040},{"trd":[[5.1,12.42]],"batb":[[2,4.6,6.52]],"batl":[[0,5.1,4.6],[1,5.3,16.98],[2,5.4,8.5]],"ltp":5.1,"tv":1536.7,"id":9625551}],"tv":12083.04}]}
{"op":"mcm","clk":"4234585553","pt":1631547505256,"mc":[{"id":"1.187562121","rc":[{"batb":[[2,1.2,100]],"batl":[[0,1.26,250.77]],"ltp":1.24,"tv":10546.34,"id":20955040}]}]}
{"op":"mcm","clk":"4234585675","pt":1631547507149,"mc":[{"id":"1.187562121","rc":[{"batb":[[2,1.2,102]],"ltp":1.24,"tv":10546.34,"id":20955040}]}]}
{"op":"mcm","clk":"4234585950","pt":1631547511868,"mc":[{"id":"1.187562121","rc":[{"batb":[[2,1.2,108.12]],"ltp":1.24,"tv":10546.34,"id":20955040}]}]}
{"op":"mcm","clk":"4234586085","pt":1631547514167,"mc":[{"id":"1.187562121","rc":[{"batl":[[0,1.26,227]],"ltp":1.24,"tv":10546.34,"id":20955040},{"batl":[[0,5.3,16.98],[1,5.4,8.5],[2,5.5,8.5]],"ltp":5.1,"tv":1536.7,"id":9625551}]}]}
{"op":"mcm","clk":"4234586303","pt":1631547517881,"mc":[{"id":"1.187562121","rc":[{"batb":[[0,1.2,102],[1,1.19,103],[2,1.18,311.81]],"batl":[[0,1.32,113.61],[1,1.35,103.1],[2,3.8,27.43]],"ltp":1.24,"tv":10546.34,"id":20955040},{"batb":[[0,4.1,3.84],[1,3.85,3.97],[2,3.7,22.23]],"batl":[[0,6.4,3],[1,6.6,2],[2,7,3]],"ltp":5.1,"tv":1536.7,"id":9625551}]}]}
{"op":"mcm","clk":"4234586363","pt":1631547518875,"mc":[{"id":"1.187562121","rc":[{"batl":[[0,1.31,114.5],[1,1.33,106.5],[2,1.35,103.1]],"ltp":1.24,"tv":10546.34,"id":20955040},{"batb":[[0,4.2,3.92],[1,4,3.43],[2,3.85,3.97]],"ltp":5.1,"tv":1536.7,"id":9625551}]}]}
{"op":"mcm","clk":"4234586379","pt":1631547519186,"mc":[{"id":"1.187562121","rc":[{"batl":[[0,1.33,106.5],[1,1.35,103.1],[2,3.8,27.43]],"ltp":1.24,"tv":10546.34,"id":20955040},{"batb":[[0,4,3.43],[1,3.85,3.97],[2,3.7,22.23]],"ltp":5.1,"tv":1536.7,"id":9625551}]}]}
{"op":"mcm","clk":"4234586500","pt":1631547520801,"mc":[{"id":"1.187562121","rc":[{"batb":[[0,1.2,108.07]],"ltp":1.24,"tv":10546.34,"id":20955040},{"batl":[[0,6,2],[1,6.4,3],[2,6.6,2]],"ltp":5.1,"tv":1536.7,"id":9625551}]}]}
{"op":"mcm","clk":"4234586545","pt":1631547521481,"mc":[{"id":"1.187562121","rc":[{"batb":[[0,1.2,102]],"ltp":1.24,"tv":10546.34,"id":20955040},{"batl":[[0,6.4,3],[1,6.6,2],[2,7,3]],"ltp":5.1,"tv":1536.7,"id":9625551}]}]}
{"op":"mcm","clk":"4234586957","pt":1631547527792,"mc":[{"id":"1.187562121","rc":[{"batb":[[0,1.2,107.82]],"ltp":1.24,"tv":10546.34,"id":20955040},{"batl":[[0,6,2],[1,6.4,3],[2,6.6,2]],"ltp":5.1,"tv":1536.7,"id":9625551}]}]}
{"op":"mcm","clk":"4234586973","pt":1631547528104,"mc":[{"id":"1.187562121","rc":[{"batb":[[0,1.2,102]],"ltp":1.24,"tv":10546.34,"id":20955040},{"batl":[[0,6.4,3],[1,6.6,2],[2,7,3]],"ltp":5.1,"tv":1536.7,"id":9625551}]}]}
{"op":"mcm","clk":"4234587135","pt":1631547530792,"mc":[{"id":"1.187562121","rc":[{"trd":[[1.31,4]],"batb":[[0,1.31,11.09],[1,1.3,92.3],[2,1.29,4.12]],"ltp":1.31,"tv":10550.34,"id":20955040},{"batb":[[0,4.1,4.28],[1,4,226.18],[2,3.85,3.97]],"batl":[[0,4.4,20.46],[1,4.5,12.22],[2,4.6,12.39]],"ltp":5.1,"tv":1536.7,"id":9625551}],"tv":12087.04}]}
{"op":"mcm","clk":"4234587203","pt":1631547531682,"mc":[{"id":"1.187562121","rc":[{"batl":[[0,1.32,217],[1,1.33,106.5],[2,1.35,110.51]],"ltp":1.31,"tv":10550.34,"id":20955040},{"batb":[[2,3.95,7.6]],"ltp":5.1,"tv":1536.7,"id":9625551}]}]}
{"op":"mcm","clk":"4234587380","pt":1631547534600,"mc":[{"id":"1.187562121","rc":[{"trd":[[1.31,15.09]],"batb":[[0,1.3,92.3],[1,1.29,4.12],[2,1.28,120.45]],"ltp":1.31,"tv":10561.43,"id":20955040},{"trd":[[4.3,3.38]],"batb":[[0,4.3,103.04],[1,4.1,4.28],[2,4,226.18]],"ltp":4.3,"tv":1540.08,"id":9625551}],"tv":12101.51}]}
{"op":"mcm","clk":"4234587422","pt":1631547535083,"mc":[{"id":"1.187562121","rc":[{"batb":[[0,4.1,4.28],[1,4,226.18],[2,3.95,7.6]],"ltp":4.3,"tv":1540.08,"id":9625551}]}]}
{"op":"mcm","clk":"4234587806","pt":1631547541003,"mc":[{"id":"1.187562121","rc":[{"batb":[[0,4,226.18],[1,3.95,7.6],[2,3.9,3.8]],"ltp":4.3,"tv":1540.08,"id":9625551}]}]}
{"op":"mcm","clk":"4234588149","pt":1631547545909,"mc":[{"id":"1.187562121","rc":[{"batb":[[0,1.29,4.12],[1,1.25,6.69],[2,1.24,146.2]],"batl":[[1,1.39,96.5],[2,1.4,98.94]],"ltp":1.31,"tv":10561.43,"id":20955040},{"batb":[[0,3.55,4.79],[1,3.5,4.78],[2,3.4,4.56]],"batl":[[0,4.5,2],[1,5,2],[2,5.4,2]],"ltp":4.3,"tv":1540.08,"id":9625551}]}]}
{"op":"mcm","clk":"4234588186","pt":1631547546428,"mc":[{"id":"1.187562121","rc":[{"batb":[[1,1.25,2]],"batl":[[0,1.42,88.25],[1,1.66,831.03],[2,3.8,27.43]],"ltp":1.31,"tv":10561.43,"id":20955040},{"batb":[[0,3.35,4.27],[1,3.15,34.22],[2,2.2,42.6]],"batl":[[1,5.4,2],[2,6.4,3]],"ltp":4.3,"tv":1540.08,"id":9625551}]}]}
{"op":"mcm","clk":"4234588261","pt":1631547547695,"mc":[{"id":"1.187562121","rc":[{"batl":[[0,1.32,21.01],[1,1.42,88.25],[2,1.66,831.03]],"ltp":1.31,"tv":10561.43,"id":20955040},{"batl":[[0,4.3,4.68],[1,4.5,2],[2,5.4,2]],"ltp":4.3,"tv":1540.08,"id":9625551}]}]}
{"op":"mcm","clk":"4234588280","pt":1631547548010,"mc":[{"id":"1.187562121","rc":[{"batl":[[0,1.42,88.25],[1,1.66,831.03],[2,3.8,27.43]],"ltp":1.31,"tv":10561.43,"id":20955040},{"batl":[[0,4.5,2],[1,5.4,2],[2,6.4,3]],"ltp":4.3,"tv":1540.08,"id":9625551}]}]}
{"op":"mcm","clk":"4234588388","pt":1631547549719,"mc":[{"id":"1.187562121","rc":[{"batl":[[0,1.39,99.5],[1,1.42,88.25],[2,1.66,831.03]],"ltp":1.31,"tv":10561.43,"id":20955040},{"batb":[[0,3.55,4.19],[1,3.35,4.27],[2,3.15,34.22]],"ltp":4.3,"tv":1540.08,"id":9625551}]}]}
{"op":"mcm","clk":"4234588450","pt":1631547550823,"mc":[{"id":"1.187562121","rc":[{"batl":[[0,1.42,88.25],[1,1.66,831.03],[2,3.8,27.43]],"ltp":1.31,"tv":10561.43,"id":20955040},{"batb":[[0,3.35,4.27],[1,3.15,34.22],[2,2.2,42.6]],"ltp":4.3,"tv":1540.08,"id":9625551}]}]}
{"op":"mcm","clk":"4234588807","pt":1631547556646,"mc":[{"id":"1.187562121","rc":[{"batb":[[1,1.25,7.33]],"ltp":1.31,"tv":10561.43,"id":20955040},{"batl":[[1,5,2],[2,5.4,2]],"ltp":4.3,"tv":1540.08,"id":9625551}]}]}
{"op":"mcm","clk":"4234588876","pt":1631547557688,"mc":[{"id":"1.187562121","rc":[{"batb":[[0,1.25,2],[1,1.24,146.2],[2,1.23,5.02]],"batl":[[0,1.39,109.5],[1,1.42,88.25],[2,1.66,831.03]],"ltp":1.31,"tv":10561.43,"id":20955040},{"batb":[[0,3.55,4.19],[1,3.35,4.27],[2,3.15,34.22]],"batl":[[0,5.4,2],[1,6.4,3],[2,7,3]],"ltp":4.3,"tv":1540.08,"id":9625551}]}]}
{"op":"mcm","clk":"4234588899","pt":1631547558001,"mc":[{"id":"1.187562121","rc":[{"batl":[[0,1.42,88.25],[1,1.66,831.03],[2,3.8,27.43]],"ltp":1.31,"tv":10561.43,"id":20955040},{"batb":[[0,3.35,4.27],[1,3.15,34.22],[2,2.2,42.6]],"ltp":4.3,"tv":1540.08,"id":9625551}]}]}
{"op":"mcm","clk":"4234589093","pt":1631547560673,"mc":[{"id":"1.187562121","rc":[{"batl":[[1,3.8,27.43],[2,8.8,7.22]],"ltp":1.31,"tv":10561.43,"id":20955040}]}]}
{"op":"mcm","clk":"4234589288","pt":1631547563902,"mc":[{"id":"1.187562121","rc":[{"batb":[[0,1.25,7.41]],"ltp":1.31,"tv":10561.43,"id":20955040},{"batl":[[0,5,2],[1,5.4,2],[2,6.4,3]],"ltp":4.3,"tv":1540.08,"id":9625551}]}]}
{"op":"mcm","clk":"4234589332","pt":1631547564689,"mc":[{"id":"1.187562121","rc":[{"batb":[[0,1.25,2]],"batl":[[0,1.39,100.5],[1,1.42,88.25],[2,3.8,27.43]],"ltp":1.31,"tv":10561.43,"id":20955040},{"batb":[[0,3.55,4.39],[1,3.35,4.27],[2,3.15,34.22]],"batl":[[0,5.4,2],[1,6.4,3],[2,7,3]],"ltp":4.3,"tv":1540.08,"id":9625551}]}]}
{"op":"mcm","clk":"4234589348","pt":1631547565003,"mc":[{"id":"1.187562121","rc":[{"batl":[[0,1.42,88.25],[1,3.8,27.43],[2,8.8,7.22]],"ltp":1.31,"tv":10561.43,"id":20955040},{"batb":[[0,3.35,4.27],[1,3.15,34.22],[2,2.2,42.6]],"ltp":4.3,"tv":1540.08,"id":9625551}]}]}
{"op":"mcm","clk":"4234589668","pt":1631547570782,"mc":[{"id":"1.187562121","rc":[{"batb":[[0,1.25,7.05]],"ltp":1.31,"tv":10561.43,"id":20955040},{"batl":[[0,5,2],[1,5.4,2],[2,6.4,3]],"ltp":4.3,"tv":1540.08,"id":9625551}]}]}
{"op":"mcm","clk":"4234589734","pt":1631547571803,"mc":[{"id":"1.187562121","rc":[{"batb":[[0,1.26,19.03],[1,1.25,2],[2,1.24,146.2]],"batl":[[0,1.28,176.04],[1,1.31,160.31],[2,1.39,101.5]],"ltp":1.31,"tv":10561.43,"id":20955040},{"batb":[[0,4.5,221.98],[1,4.4,3.34],[2,4.3,3.34]],"batl":[[0,5.1,162.98]],"ltp":4.3,"tv":1540.08,"id":9625551}]}]}
{"op":"mcm","clk":"4234589804","pt":1631547572899,"mc":[{"id":"1.187562121","rc":[{"batb":[[2,1.24,154.26]],"ltp":1.31,"tv":10561.43,"id":20955040},{"batl":[[0,5.1,168.86],[1,5.2,2.94],[2,5.3,2.94]],"ltp":4.3,"tv":1540.08,"id":9625551}]}]}
{"op":"mcm","clk":"4234589826","pt":1631547573313,"mc":[{"id":"1.187562121","rc":[{"batl":[[0,1.28,400.04]],"ltp":1.31,"tv":10561.43,"id":20955040}]}]}
{"op":"mcm","clk":"4234590148","pt":1631547578819,"mc":[{"id":"1.187562121","rc":[{"batl":[[2,1.36,106.32]],"ltp":1.31,"tv":10561.43,"id":20955040}]}]}
{"op":"mcm","clk":"4234590491","pt":1631547586480,"mc":[{"id":"1.187562121","rc":[{"trd":[[1.28,52]],"batl":[[0,1.28,378.04]],"ltp":1.28,"tv":10605.43,"id":20955040}],"tv":12145.51}]}
{"op":"mcm","clk":"4234590665","pt":1631547589715,"mc":[{"id":"1.187562121","rc":[{"batb":[[0,1.25,2],[1,1.24,146.2],[2,1.23,5.02]],"batl":[[0,1.28,224],[1,1.36,106.32],[2,1.39,101.5]],"ltp":1.28,"tv":10605.43,"id":20955040},{"batb":[[0,4.1,34.22],[1,3.75,4.19],[2,3.55,4.39]],"batl":[[0,5.4,2],[1,6.4,3],[2,7,3]],"ltp":4.3,"tv":1540.08,"id":9625551}]}]}
{"op":"mcm","clk":"4234590697","pt":1631547590188,"mc":[{"id":"1.187562121","rc":[{"batb":[[1,1.2,102],[2,1.19,286.61]],"batl":[[0,1.39,101.5],[1,3.8,27.43],[2,8.8,7.22]],"ltp":1.28,"tv":10605.43,"id":20955040},{"batb":[[0,3.55,4.39],[1,3.4,27.93],[2,2.6,3.73]],"batl":[[0,6.4,3],[1,7,3],[2,7.4,3]],"ltp":4.3,"tv":1540.08,"id":9625551}]}]}
{"op":"mcm","clk":"4234590956","pt":1631547594827,"mc":[{"id":"1.187562121","rc":[{"batl":[[0,1.29,20.5],[1,1.39,101.5],[2,3.8,27.43]],"ltp":1.28,"tv":10605.43,"id":20955040},{"batb":[[0,4.4,19.96],[1,3.55,4.39],[2,3.4,27.93]],"batl":[[0,4.8,19.57],[1,6.4,3],[2,7,3]],"ltp":4.3,"tv":1540.08,"id":9625551}]}]}
{"op":"mcm","clk":"4234590983","pt":1631547595090,"mc":[{"id":"1.187562121","rc":[{"batl":[[0,1.39,101.5],[1,3.8,27.43],[2,8.8,7.22]],"ltp":1.28,"tv":10605.43,"id":20955040},{"batb":[[0,3.55,4.39],[1,3.4,27.93],[2,2.6,3.73]],"batl":[[0,6.4,3],[1,7,3],[2,7.4,3]],"ltp":4.3,"tv":1540.08,"id":9625551}]}]}
{"op":"mcm","clk":"4234591071","pt":1631547596906,"mc":[{"id":"1.187562121","rc":[{"batl":[[0,1.36,96.82],[1,1.39,101.5],[2,3.8,27.43]],"ltp":1.28,"tv":10605.43,"id":20955040},{"batb":[[0,3.75,3.95],[1,3.55,4.39],[2,3.4,27.93]],"ltp":4.3,"tv":1540.08,"id":9625551}]}]}
{"op":"mcm","clk":"4234591103","pt":1631547597425,"mc":[{"id":"1.187562121","rc":[{"batb":[[0,1.28,2.71],[1,1.25,2],[2,1.2,102]],"batl":[[0,1.39,101.5],[1,3.8,27.43],[2,8.8,7.22]],"ltp":1.28,"tv":10605.43,"id":20955040},{"batb":[[0,3.55,4.39],[1,3.4,27.93],[2,2.6,3.73]],"ltp":4.3,"tv":1540.08,"id":9625551}]}]}
{"op":"mcm","clk":"4234591142","pt":1631547598003,"mc":[{"id":"1.187562121","rc":[{"batl":[[0,4.5,2],[1,6.4,3],[2,7,3]],"ltp":4.3,"tv":1540.08,"id":9625551}]}]}
{"op":"mcm","clk":"4234591403","pt":1631547602825,"mc":[{"id":"1.187562121","rc":[{"batl":[[0,1.38,24.1],[1,1.39,101.5],[2,3.8,27.43]],"ltp":1.28,"tv":10605.43,"id":20955040},{"batb":[[0,3.6,281.82],[1,3.55,4.39],[2,3.4,27.93]],"batl":[[0,3.85,9.25],[1,4,895.2],[2,4.1,67.54]],"ltp":4.3,"tv":1540.08,"id":9625551}]}]}
{"op":"mcm","clk":"4234591470","pt":1631547603821,"mc":[{"id":"1.187562121","rc":[{"batb":[[0,1.33,105.53],[1,1.28,2.71],[2,1.27,126.32]],"batl":[[1,1.39,108.69]],"ltp":1.28,"tv":10605.43,"id":20955040},{"batb":[[0,3.6,323.5],[1,3.55,25.23],[2,3.5,20.84]],"batl":[[1,4,7.5],[2,4.1,54.54]],"ltp":4.3,"tv":1540.08,"id":9625551}]}]}
{"op":"mcm","clk":"4234591501","pt":1631547604345,"mc":[{"id":"1.187562121","rc":[{"batl":[[2,1.73,769.67]],"ltp":1.28,"tv":10605.43,"id":20955040},{"batb":[[0,3.6,290.16],[1,3.55,8.55],[2,3.5,4.16]],"ltp":4.3,"tv":1540.08,"id":9625551}]}]}
{"op":"mcm","clk":"4234591587","pt":1631547605723,"mc":[{"id":"1.187562121","rc":[{"batb":[[1,1.27,126.32],[2,1.25,2]],"batl":[[1,1.39,314.69]],"ltp":1.28,"tv":10605.43,"id":20955040}]}]}
{"op":"mcm","clk":"4234591643","pt":1631547606807,"mc":[{"id":"1.187562121","rc":[{"trd":[[3.85,18.5]],"batl":[[0,4,7.5],[1,4.1,54.54],[2,4.2,6.14]],"ltp":3.85,"tv":1558.58,"id":9625551}],"tv":12164.01}]}
{"op":"mcm","clk":"4234591710","pt":1631547607849,"mc":[{"id":"1.187562121","rc":[{"batl":[[0,1.38,192.97]],"ltp":1.28,"tv":10605.43,"id":20955040},{"batl":[[0,3.9,2.41],[1,4,7.5],[2,4.1,54.54]],"ltp":3.85,"tv":1558.58,"id":9625551}]}]}
{"op":"mcm","clk":"4234591721","pt":1631547608009,"mc":[{"id":"1.187562121","rc":[{"batl":[[0,1.38,24.1]],"ltp":1.28,"tv":10605.43,"id":20955040},{"batl":[[0,4,7.5],[1,4.1,54.54],[2,4.2,6.14]],"ltp":3.85,"tv":1558.58,"id":9625551}]}]}
{"op":"mcm","clk":"4234591826","pt":1631547609951,"mc":[{"id":"1.187562121","rc":[{"batb":[[1,1.28,4.66],[2,1.27,126.32]],"batl":[[2,1.47,102.5]],"ltp":1.28,"tv":10605.43,"id":20955040}]}]}
{"op":"mcm","clk":"4234591920","pt":1631547611634,"mc":[{"id":"1.187562121","rc":[{"batl":[[2,1.46,96.75]],"ltp":1.28,"tv":10605.43,"id":20955040}]}]}
{"op":"mcm","clk":"4234592073","pt":1631547614831,"mc":[{"id":"1.187562121","rc":[{"batl":[[0,1.39,307.5],[1,1.46,96.75],[2,1.47,102.5]],"ltp":1.28,"tv":10605.43,"id":20955040},{"batb":[[0,3.6,4.17],[1,3.55,6.47],[2,3.5,2.08]],"batl":[[0,4,3.75],[1,4.1,28.27],[2,4.2,1.88]],"ltp":3.85,"tv":1558.58,"id":9625551}]}]}
{"op":"mcm","clk":"4234592137","pt":1631547615834,"mc":[{"id":"1.187562121","rc":[{"batb":[[0,1.33,3.53],[1,1.27,126.32],[2,1.25,6.73]],"batl":[[0,1.5,83.01],[1,1.73,769.67],[2,3.8,27.43]],"ltp":1.28,"tv":10605.43,"id":20955040},{"batb":[[0,3,5.22],[1,2.84,17.78],[2,2.2,42.6]],"batl":[[0,4.1,2],[1,4.5,2],[2,5,2]],"ltp":3.85,"tv":1558.58,"id":9625551}]}]}
{"op":"mcm","clk":"4234592300","pt":1631547618796,"mc":[{"id":"1.187562121","rc":[{"batb":[[1,1.28,4.66],[2,1.27,126.32]],"ltp":1.28,"tv":10605.43,"id":20955040},{"batl":[[2,4.6,2]],"ltp":3.85,"tv":1558.58,"id":9625551}]}]}
{"op":"mcm","clk":"4234592352","pt":1631547619793,"mc":[{"id":"1.187562121","rc":[{"batb":[[1,1.27,126.32],[2,1.25,6.73]],"ltp":1.28,"tv":10605.43,"id":20955040},{"batl":[[2,5,2]],"ltp":3.85,"tv":1558.58,"id":9625551}]}]}
{"op":"mcm","clk":"4234592753","pt":1631547625690,"mc":[{"id":"1.187562121","rc":[{"batb":[[1,1.28,4.41],[2,1.27,126.32]],"ltp":1.28,"tv":10605.43,"id":20955040},{"batl":[[2,4.6,2]],"ltp":3.85,"tv":1558.58,"id":9625551}]}]}
{"op":"mcm","clk":"4234592810","pt":1631547626835,"mc":[{"id":"1.187562121","rc":[{"batb":[[1,1.27,126.32],[2,1.25,6.73]],"ltp":1.28,"tv":10605.43,"id":20955040},{"batl":[[2,5,2]],"ltp":3.85,"tv":1558.58,"id":9625551}]}]}
{"op":"mcm","clk":"4234593035","pt":1631547630900,"mc":[{"id":"1.187562121","rc":[{"batb":[[0,1.27,126.32],[1,1.25,6.73],[2,1.2,102]],"batl":[[1,3.8,27.43],[2,8.8,7.22]],"ltp":1.28,"tv":10605.43,"id":20955040},{"batl":[[0,4.5,2],[1,5,2],[2,6.4,3]],"ltp":3.85,"tv":1558.58,"id":9625551}]}]}
{"op":"mcm","clk":"4234593115","pt":1631547631838,"mc":[{"id":"1.187562121","rc":[{"batb":[[0,1.29,17.16],[1,1.27,126.32],[2,1.25,6.73]],"batl":[[0,1.32,2717.82],[1,1.34,156.72],[2,1.5,83.01]],"ltp":1.28,"tv":10605.43,"id":20955040},{"batb":[[0,4.3,3.9],[1,4.1,36.6],[2,4,18.3]],"batl":[[1,4.7,224.72],[2,5,2]],"ltp":3.85,"tv":1558.58,"id":9625551}]}]}
{"op":"mcm","clk":"4234593171","pt":1631547632833,"mc":[{"id":"1.187562121","rc":[{"batb":[[1,1.28,117.2],[2,1.27,184.92]],"batl":[[0,1.32,140.61]],"ltp":1.28,"tv":10605.43,"id":20955040},{"batb":[[1,4.1,22.36],[2,4,3.66]],"batl":[[1,4.7,226.85]],"ltp":3.85,"tv":1558.58,"id":9625551}]}]}
{"op":"mcm","clk":"4234593232","pt":1631547633837,"mc":[{"id":"1.187562121","rc":[{"batb":[[1,1.28,23.44],[2,1.27,138.04]],"batl":[[0,1.31,218],[1,1.32,140.61],[2,1.34,156.72]],"ltp":1.28,"tv":10605.43,"id":20955040}]}]}
{"op":"mcm","clk":"4234593394","pt":1631547636804,"mc":[{"id":"1.187562121","rc":[{"batl":[[2,1.33,197.76]],"ltp":1.28,"tv":10605.43,"id":20955040},{"batl":[[0,4.4,6.03],[1,4.5,2],[2,4.7,226.85]],"ltp":3.85,"tv":1558.58,"id":9625551}]}]}
{"op":"mcm","clk":"4234593410","pt":1631547637011,"mc":[{"id":"1.187562121","rc":[{"batl":[[2,1.34,156.72]],"ltp":1.28,"tv":10605.43,"id":20955040},{"batl":[[0,4.5,2],[1,4.7,226.85],[2,5,2]],"ltp":3.85,"tv":1558.58,"id":9625551}]}]}
{"op":"mcm","clk":"4234593661","pt":1631547641541,"mc":[{"id":"1.187562121","rc":[{"trd":[[4.3,11.18]],"batb":[[0,4.1,22.36],[1,4,3.66],[2,3.95,3.66]],"batl":[[0,4.3,33.36],[1,4.5,2],[2,4.7,226.85]],"ltp":4.3,"tv":1566.38,"id":9625551}],"tv":12171.81}]}
{"op":"mcm","clk":"4234593748","pt":1631547642857,"mc":[{"id":"1.187562121","rc":[{"batb":[[0,1.25,6.73],[1,1.2,480.16],[2,1.19,103]],"batl":[[1,1.47,77.5],[2,1.5,83.01]],"ltp":1.28,"tv":10605.43,"id":20955040},{"batb":[[0,3.1,4.04],[1,3,5.22],[2,2.92,41.6]],"batl":[[2,5,2]],"ltp":4.3,"tv":1566.38,"id":9625551}]}]}
{"op":"mcm","clk":"4234593785","pt":1631547643423,"mc":[{"id":"1.187562121","rc":[{"batl":[[0,1.53,75.5],[1,1.66,831.03],[2,3.8,27.43]],"ltp":1.28,"tv":10605.43,"id":20955040},{"batb":[[0,2.92,41.6],[1,2.88,4.71],[2,2.2,42.6]],"ltp":4.3,"tv":1566.38,"id":9625551}]}]}
{"op":"mcm","clk":"4234593822","pt":1631547644206,"mc":[{"id":"1.187562121","rc":[{"batl":[[1,3.8,27.43],[2,8.8,7.22]],"ltp":1.28,"tv":10605.43,"id":20955040}]}]}
