{"op":"mcm","clk":"4224268596","pt":1631432584230,"mc":[{"id":"1.187548830","marketDefinition":{"bspMarket":false,"turnInPlayEnabled":true,"persistenceEnabled":true,"marketBaseRate":5.0,"eventId":"30895000","eventTypeId":"2","numberOfWinners":1,"bettingType":"ODDS","marketType":"MATCH_ODDS","marketTime":"2021-09-12T11:30:00.000Z","suspendTime":"2021-09-12T11:30:00.000Z","bspReconciled":false,"complete":true,"inPlay":false,"crossMatching":false,"runnersVoidable":false,"numberOfActiveRunners":2,"betDelay":0,"status":"OPEN","runners":[{"status":"ACTIVE","sortPriority":1,"id":9638175,"name":"E Guerrero Alvarez"},{"status":"ACTIVE","sortPriority":2,"id":11270552,"name":"A Fita Boluda"}],"regulators":["MR_INT"],"countryCode":"GB","discountAllowed":false,"timezone":"GMT","openDate":"2021-09-12T12:30:00.000Z","version":4027491843,"name":"Match Odds","eventName":"E Guerrero Alvarez v A Fita Boluda"},"rc":[{"batb":[[0,1.01,25]],"ltp":0.0,"tv":0.0,"id":11270552},{"batb":[[0,1.01,25]],"ltp":0.0,"tv":0.0,"id":9638175}]}]}
{"op":"mcm","clk":"4224268755","pt":1631432585965,"mc":[{"id":"1.187548830","marketDefinition":{"bspMarket":false,"turnInPlayEnabled":true,"persistenceEnabled":true,"marketBaseRate":5.0,"eventId":"30895000","eventTypeId":"2","numberOfWinners":1,"bettingType":"ODDS","marketType":"MATCH_ODDS","marketTime":"2021-09-12T11:30:00.000Z","suspendTime":"2021-09-12T11:30:00.000Z","bspReconciled":false,"complete":true,"inPlay":false,"crossMatching":false,"runnersVoidable":false,"numberOfActiveRunners":2,"betDelay":0,"status":"OPEN","runners":[{"status":"ACTIVE","sortPriority":1,"id":9638175,"name":"E Guerrero Alvarez"},{"status":"ACTIVE","sortPriority":2,"id":11270552,"name":"A Fita Boluda"}],"regulators":["MR_INT"],"countryCode":"GB","discountAllowed":true,"timezone":"GMT","openDate":"2021-09-12T12:30:00.000Z","version":4027491843,"name":"Match Odds","eventName":"E Guerrero Alvarez v A Fita Boluda"}}]}
{"op":"mcm","clk":"4224278119","pt":1631432707835,"mc":[{"id":"1.187548830","rc":[{"batb":[[0,1.01,7]],"ltp":0.0,"tv":0.0,"id":11270552},{"batb":[[0,1.01,7]],"ltp":0.0,"tv":0.0,"id":9638175}]}]}
{"op":"mcm","clk":"4224403261","pt":1631434068662,"mc":[{"id":"1.187548830","rc":[{"batl":[[0,490,6.16]],"ltp":0.0,"tv":0.0,"id":11270552},{"batl":[[0,490,6.16]],"ltp":0.0,"tv":0.0,"id":9638175}]}]}
{"op":"mcm","clk":"4224431525","pt":1631434340153,"mc":[{"id":"1.187548830","rc":[{"batl":[[1,990,2.2]],"ltp":0.0,"tv":0.0,"id":11270552},{"batl":[[1,990,2.2]],"ltp":0.0,"tv":0.0,"id":9638175}]}]}
{"op":"mcm","clk":"4224436623","pt":1631434390801,"mc":[{"id":"1.187548830","rc":[{"batb":[[0,1.05,879.5],[1,1.01,7]],"ltp":0.0,"tv":0.0,"id":11270552},{"batb":[[0,1.05,879.5],[1,1.01,7]],"ltp":0.0,"tv":0.0,"id":9638175}]}]}
{"op":"mcm","clk":"4224580938","pt":1631435897809,"mc":[{"id":"1.187548830","rc":[{"batb":[[0,1.67,50.47],[1,1.05,879.5],[2,1.01,7]],"ltp":0.0,"tv":0.0,"id":11270552},{"batb":[[0,2.1,30.74],[1,1.05,879.5],[2,1.01,7]],"ltp":0.0,"tv":0.0,"id":9638175}]}]}
{"op":"mcm","clk":"4224582937","pt":1631435916384,"mc":[{"id":"1.187548830","marketDefinition":{"bspMarket":false,"turnInPlayEnabled":true,"persistenceEnabled":true,"marketBaseRate":5.0,"eventId":"30895000","eventTypeId":"2","numberOfWinners":1,"bettingType":"ODDS","marketType":"MATCH_ODDS","marketTime":"2021-09-12T11:30:00.000Z","suspendTime":"2021-09-12T11:30:00.000Z","bspReconciled":false,"complete":true,"inPlay":false,"crossMatching":true,"runnersVoidable":false,"numberOfActiveRunners":2,"betDelay":0,"status":"OPEN","runners":[{"status":"ACTIVE","sortPriority":1,"id":9638175,"name":"E Guerrero Alvarez"},{"status":"ACTIVE","sortPriority":2,"id":11270552,"name":"A Fita Boluda"}],"regulators":["MR_INT"],"countryCode":"GB","discountAllowed":true,"timezone":"GMT","openDate":"2021-09-12T12:30:00.000Z","version":4027491843,"name":"Match Odds","eventName":"E Guerrero Alvarez v A Fita Boluda"}}]}
{"op":"mcm","clk":"4224613412","pt":1631436229780,"mc":[{"id":"1.187548830","rc":[{"batb":[[1,1.01,7],[2,1.01,0]],"ltp":0.0,"tv":0.0,"id":9638175}]}]}
{"op":"mcm","clk":"4224613510","pt":1631436230664,"mc":[{"id":"1.187548830","rc":[{"batb":[[1,1.01,7],[2,1.01,0]],"ltp":0.0,"tv":0.0,"id":11270552}]}]}
{"op":"mcm","clk":"4224763186","pt":1631437658714,"mc":[{"id":"1.187548830","rc":[{"batb":[[1,1.05,879.5],[2,1.01,7]],"ltp":0.0,"tv":0.0,"id":11270552},{"batb":[[1,1.05,879.5],[2,1.01,7]],"ltp":0.0,"tv":0.0,"id":9638175}]}]}
{"op":"mcm","clk":"4224915861","pt":1631439003874,"mc":[{"id":"1.187548830","rc":[{"batb":[[0,1.67,67.3]],"ltp":0.0,"tv":0.0,"id":11270552},{"batb":[[0,2.1,40.99]],"ltp":0.0,"tv":0.0,"id":9638175}]}]}
{"op":"mcm","clk":"4225398344","pt":1631442600892,"mc":[{"id":"1.187548830","rc":[{"batb":[[0,1.68,18.84],[1,1.67,67.3],[2,1.05,879.5]],"ltp":0.0,"tv":0.0,"id":11270552},{"batb":[[0,2.12,11.44],[1,2.1,40.99],[2,1.05,879.5]],"ltp":0.0,"tv":0.0,"id":9638175}]}]}
{"op":"mcm","clk":"4225400843","pt":1631442617929,"mc":[{"id":"1.187548830","rc":[{"batl":[[0,2.4,2.03],[1,490,6.16],[2,990,2.2]],"ltp":0.0,"tv":0.0,"id":11270552}]}]}
{"op":"mcm","clk":"4225564971","pt":1631443635737,"mc":[{"id":"1.187548830","rc":[{"batb":[[2,1.01,7]],"ltp":0.0,"tv":0.0,"id":9638175}]}]}
{"op":"mcm","clk":"4225565927","pt":1631443641727,"mc":[{"id":"1.187548830","rc":[{"batl":[[1,2.8,43.98],[2,490,6.16]],"ltp":0.0,"tv":0.0,"id":11270552}]}]}
{"op":"mcm","clk":"4225642437","pt":1631444090693,"mc":[{"id":"1.187548830","rc":[{"batb":[[2,1.66,2.66]],"ltp":0.0,"tv":0.0,"id":11270552},{"batb":[[2,2.08,2.66]],"ltp":0.0,"tv":0.0,"id":9638175}]}]}
{"op":"mcm","clk":"4225682654","pt":1631444415163,"mc":[{"id":"1.187548830","rc":[{"batl":[[0,2.8,43.98],[1,490,6.16],[2,990,2.2]],"ltp":0.0,"tv":0.0,"id":11270552}]}]}
{"op":"mcm","clk":"4225683240","pt":1631444419382,"mc":[{"id":"1.187548830","rc":[{"batl":[[0,2.52,2.27],[1,2.8,43.98],[2,490,6.16]],"ltp":0.0,"tv":0.0,"id":11270552}]}]}
{"op":"mcm","clk":"4226243266","pt":1631448000250,"mc":[{"id":"1.187548830","rc":[{"batb":[[0,1.67,67.3],[1,1.66,2.66],[2,1.34,127.53]],"ltp":0.0,"tv":0.0,"id":11270552},{"batb":[[0,2.1,40.99],[1,2.08,2.66],[2,1.02,108.45]],"ltp":0.0,"tv":0.0,"id":9638175}]}]}
{"op":"mcm","clk":"4226247723","pt":1631448029304,"mc":[{"id":"1.187548830","rc":[{"batl":[[0,2.8,43.98],[1,490,6.16],[2,990,2.2]],"ltp":0.0,"tv":0.0,"id":11270552}]}]}
{"op":"mcm","clk":"4226526940","pt":1631449697331,"mc":[{"id":"1.187548830","rc":[{"trd":[[1.67,4]],"batb":[[0,1.67,65.3]],"ltp":1.67,"tv":4.0,"id":11270552}],"tv":4.0}]}
{"op":"mcm","clk":"4226527470","pt":1631449701753,"mc":[{"id":"1.187548830","rc":[{"batb":[[0,1.67,67.3]],"ltp":1.67,"tv":4.0,"id":11270552}]}]}
{"op":"mcm","clk":"4226547847","pt":1631449856434,"mc":[{"id":"1.187548830","marketDefinition":{"bspMarket":false,"turnInPlayEnabled":true,"persistenceEnabled":true,"marketBaseRate":5.0,"eventId":"30895000","eventTypeId":"2","numberOfWinners":1,"bettingType":"ODDS","marketType":"MATCH_ODDS","marketTime":"2021-09-12T11:30:00.000Z","suspendTime":"2021-09-12T11:30:00.000Z","bspReconciled":false,"complete":true,"inPlay":true,"crossMatching":true,"runnersVoidable":false,"numberOfActiveRunners":2,"betDelay":5,"status":"OPEN","runners":[{"status":"ACTIVE","sortPriority":1,"id":9638175,"name":"E Guerrero Alvarez"},{"status":"ACTIVE","sortPriority":2,"id":11270552,"name":"A Fita Boluda"}],"regulators":["MR_INT"],"countryCode":"GB","discountAllowed":true,"timezone":"GMT","openDate":"2021-09-12T12:30:00.000Z","version":4028132559,"name":"Match Odds","eventName":"E Guerrero Alvarez v A Fita Boluda"},"rc":[{"batb":[[0,1.01,12],[1,1.66,0],[2,1.34,0]],"ltp":1.67,"tv":4.0,"id":11270552},{"batb":[[0,1.01,12],[1,2.08,0],[2,1.02,0]],"ltp":0.0,"tv":0.0,"id":9638175}]}]}
{"op":"mcm","clk":"4226781955","pt":1631451358632,"mc":[{"id":"1.187548830","rc":[{"batb":[[0,1.67,1.38],[1,1.01,12]],"ltp":1.67,"tv":4.0,"id":11270552}]}]}
{"op":"mcm","clk":"4227436529","pt":1631455480248,"mc":[{"id":"1.187548830","marketDefinition":{"bspMarket":false,"turnInPlayEnabled":true,"persistenceEnabled":true,"marketBaseRate":5.0,"eventId":"30895000","eventTypeId":"2","numberOfWinners":1,"bettingType":"ODDS","marketType":"MATCH_ODDS","marketTime":"2021-09-12T14:04:39.000Z","suspendTime":"2021-09-12T14:04:39.000Z","bspReconciled":false,"complete":true,"inPlay":true,"crossMatching":true,"runnersVoidable":false,"numberOfActiveRunners":2,"betDelay":5,"status":"OPEN","runners":[{"status":"ACTIVE","sortPriority":1,"id":9638175,"name":"E Guerrero Alvarez"},{"status":"ACTIVE","sortPriority":2,"id":11270552,"name":"A Fita Boluda"}],"regulators":["MR_INT"],"countryCode":"GB","discountAllowed":true,"timezone":"GMT","openDate":"2021-09-12T12:30:00.000Z","version":4028529507,"name":"Match Odds","eventName":"E Guerrero Alvarez v A Fita Boluda"}}]}
{"op":"mcm","clk":"4227437048","pt":1631455483254,"mc":[{"id":"1.187548830","marketDefinition":{"bspMarket":false,"turnInPlayEnabled":true,"persistenceEnabled":true,"marketBaseRate":5.0,"eventId":"30895000","eventTypeId":"2","numberOfWinners":1,"bettingType":"ODDS","marketType":"MATCH_ODDS","marketTime":"2021-09-12T14:04:39.000Z","suspendTime":"2021-09-12T14:04:39.000Z","bspReconciled":false,"complete":true,"inPlay":true,"crossMatching":true,"runnersVoidable":false,"numberOfActiveRunners":2,"betDelay":5,"status":"OPEN","runners":[{"status":"ACTIVE","sortPriority":1,"id":9638175,"name":"E Guerrero Alvarez"},{"status":"ACTIVE","sortPriority":2,"id":11270552,"name":"A Fita Boluda"}],"regulators":["MR_INT"],"countryCode":"GB","discountAllowed":true,"timezone":"GMT","openDate":"2021-09-12T14:04:39.000Z","version":4028529507,"name":"Match Odds","eventName":"E Guerrero Alvarez v A Fita Boluda"}}]}
{"op":"mcm","clk":"4227649371","pt":1631456652688,"mc":[{"id":"1.187548830","rc":[{"batl":[[0,2.4,100]],"ltp":1.67,"tv":4.0,"id":11270552}]}]}
{"op":"mcm","clk":"4227876819","pt":1631457969057,"mc":[{"id":"1.187548830","rc":[{"batb":[[0,1.01,12],[1,1.01,0]],"ltp":1.67,"tv":4.0,"id":11270552}]}]}
{"op":"mcm","clk":"4228370076","pt":1631461232675,"mc":[{"id":"1.187548830","rc":[{"trd":[[1.01,24]],"batl":[[0,1.01,5.08]],"ltp":1.01,"tv":27.99,"id":11270552}],"tv":27.99}]}
{"op":"mcm","clk":"4228373682","pt":1631461254307,"mc":[{"id":"1.187548830","rc":[{"batl":[[1,11.5,39.77]],"ltp":1.01,"tv":27.99,"id":11270552}]}]}
{"op":"mcm","clk":"4228375647","pt":1631461264819,"mc":[{"id":"1.187548830","marketDefinition":{"bspMarket":false,"turnInPlayEnabled":true,"persistenceEnabled":true,"marketBaseRate":5.0,"eventId":"30895000","eventTypeId":"2","numberOfWinners":1,"bettingType":"ODDS","marketType":"MATCH_ODDS","marketTime":"2021-09-12T14:04:39.000Z","suspendTime":"2021-09-12T14:04:39.000Z","bspReconciled":false,"complete":true,"inPlay":true,"crossMatching":true,"runnersVoidable":false,"numberOfActiveRunners":2,"betDelay":5,"status":"SUSPENDED","runners":[{"status":"ACTIVE","sortPriority":1,"id":9638175,"name":"E Guerrero Alvarez"},{"status":"ACTIVE","sortPriority":2,"id":11270552,"name":"A Fita Boluda"}],"regulators":["MR_INT"],"countryCode":"GB","discountAllowed":true,"timezone":"GMT","openDate":"2021-09-12T14:04:39.000Z","version":4028929191,"name":"Match Odds","eventName":"E Guerrero Alvarez v A Fita Boluda"}}]}
{"op":"mcm","clk":"4228376180","pt":1631461267736,"mc":[{"id":"1.187548830","tv":0.0}]}
{"op":"mcm","clk":"4228376395","pt":1631461268855,"mc":[{"id":"1.187548830","marketDefinition":{"bspMarket":false,"turnInPlayEnabled":true,"persistenceEnabled":true,"marketBaseRate":5.0,"eventId":"30895000","eventTypeId":"2","numberOfWinners":1,"bettingType":"ODDS","marketType":"MATCH_ODDS","marketTime":"2021-09-12T14:04:39.000Z","suspendTime":"2021-09-12T14:04:39.000Z","bspReconciled":false,"complete":true,"inPlay":true,"crossMatching":false,"runnersVoidable":false,"numberOfActiveRunners":0,"betDelay":5,"status":"CLOSED","settledTime":"2021-09-12T15:41:06.000Z","runners":[{"status":"LOSER","sortPriority":1,"id":9638175,"name":"E Guerrero Alvarez"},{"status":"WINNER","sortPriority":2,"id":11270552,"name":"A Fita Boluda"}],"regulators":["MR_INT"],"countryCode":"GB","discountAllowed":true,"timezone":"GMT","openDate":"2021-09-12T14:04:39.000Z","version":4028929225,"name":"Match Odds","eventName":"E Guerrero Alvarez v A Fita Boluda"}}]}
