{"op":"mcm","clk":"4224841314","pt":1631438297862,"mc":[{"id":"1.187552052","marketDefinition":{"bspMarket":false,"turnInPlayEnabled":true,"persistenceEnabled":true,"marketBaseRate":5.0,"eventId":"30895183","eventTypeId":"2","numberOfWinners":1,"bettingType":"ODDS","marketType":"MATCH_ODDS","marketTime":"2021-09-12T14:00:00.000Z","suspendTime":"2021-09-12T14:00:00.000Z","bspReconciled":false,"complete":true,"inPlay":false,"crossMatching":false,"runnersVoidable":false,"numberOfActiveRunners":2,"betDelay":0,"status":"OPEN","runners":[{"status":"ACTIVE","sortPriority":1,"id":9636182,"name":"A Carrillo Marin"},{"status":"ACTIVE","sortPriority":2,"id":16206893,"name":"Y Cavalle-Reimers"}],"regulators":["MR_INT"],"countryCode":"GB","discountAllowed":false,"timezone":"GMT","openDate":"2021-09-12T14:00:00.000Z","version":4027593618,"name":"Match Odds","eventName":"A Carrillo Marin v Y Cavalle-reimers"},"rc":[{"batb":[[0,1.01,25]],"ltp":0.0,"tv":0.0,"id":9636182},{"batb":[[0,1.01,25]],"ltp":0.0,"tv":0.0,"id":16206893}]}]}
{"op":"mcm","clk":"4224841608","pt":1631438300504,"mc":[{"id":"1.187552052","marketDefinition":{"bspMarket":false,"turnInPlayEnabled":true,"persistenceEnabled":true,"marketBaseRate":5.0,"eventId":"30895183","eventTypeId":"2","numberOfWinners":1,"bettingType":"ODDS","marketType":"MATCH_ODDS","marketTime":"2021-09-12T14:00:00.000Z","suspendTime":"2021-09-12T14:00:00.000Z","bspReconciled":false,"complete":true,"inPlay":false,"crossMatching":false,"runnersVoidable":false,"numberOfActiveRunners":2,"betDelay":0,"status":"OPEN","runners":[{"status":"ACTIVE","sortPriority":1,"id":9636182,"name":"A Carrillo Marin"},{"status":"ACTIVE","sortPriority":2,"id":16206893,"name":"Y Cavalle-Reimers"}],"regulators":["MR_INT"],"countryCode":"GB","discountAllowed":true,"timezone":"GMT","openDate":"2021-09-12T14:00:00.000Z","version":4027593618,"name":"Match Odds","eventName":"A Carrillo Marin v Y Cavalle-reimers"}}]}
{"op":"mcm","clk":"4224917344","pt":1631439018294,"mc":[{"id":"1.187552052","rc":[{"batb":[[0,1.01,7]],"ltp":0.0,"tv":0.0,"id":9636182},{"batb":[[0,1.01,7]],"ltp":0.0,"tv":0.0,"id":16206893}]}]}
{"op":"mcm","clk":"4224935555","pt":1631439170467,"mc":[{"id":"1.187552052","rc":[{"batb":[[0,3.25,15.03],[1,1.01,7]],"ltp":0.0,"tv":0.0,"id":9636182},{"batb":[[0,1.29,116.61],[1,1.01,7]],"ltp":0.0,"tv":0.0,"id":16206893}]}]}
{"op":"mcm","clk":"4224937471","pt":1631439186398,"mc":[{"id":"1.187552052","marketDefinition":{"bspMarket":false,"turnInPlayEnabled":true,"persistenceEnabled":true,"marketBaseRate":5.0,"eventId":"30895183","eventTypeId":"2","numberOfWinners":1,"bettingType":"ODDS","marketType":"MATCH_ODDS","marketTime":"2021-09-12T14:00:00.000Z","suspendTime":"2021-09-12T14:00:00.000Z","bspReconciled":false,"complete":true,"inPlay":false,"crossMatching":true,"runnersVoidable":false,"numberOfActiveRunners":2,"betDelay":0,"status":"OPEN","runners":[{"status":"ACTIVE","sortPriority":1,"id":9636182,"name":"A Carrillo Marin"},{"status":"ACTIVE","sortPriority":2,"id":16206893,"name":"Y Cavalle-Reimers"}],"regulators":["MR_INT"],"countryCode":"GB","discountAllowed":true,"timezone":"GMT","openDate":"2021-09-12T14:00:00.000Z","version":4027593618,"name":"Match Odds","eventName":"A Carrillo Marin v Y Cavalle-reimers"}}]}
{"op":"mcm","clk":"4225159602","pt":1631440960327,"mc":[{"id":"1.187552052","rc":[{"batl":[[0,14,24.03],[1,95,19.35]],"ltp":0.0,"tv":0.0,"id":9636182},{"batl":[[0,1.8,60.04],[1,95,19.35]],"ltp":0.0,"tv":0.0,"id":16206893}]}]}
{"op":"mcm","clk":"4225184294","pt":1631441121231,"mc":[{"id":"1.187552052","rc":[{"batl":[[0,95,19.35],[1,95,0]],"ltp":0.0,"tv":0.0,"id":16206893}]}]}
{"op":"mcm","clk":"4225184383","pt":1631441121710,"mc":[{"id":"1.187552052","rc":[{"batl":[[0,1.68,61.19],[1,95,19.35]],"ltp":0.0,"tv":0.0,"id":16206893}]}]}
{"op":"mcm","clk":"4225205370","pt":1631441260268,"mc":[{"id":"1.187552052","rc":[{"batl":[[0,95,19.35],[1,95,0]],"ltp":0.0,"tv":0.0,"id":9636182}]}]}
{"op":"mcm","clk":"4225229391","pt":1631441421904,"mc":[{"id":"1.187552052","rc":[{"batl":[[0,1.8,112.88]],"ltp":0.0,"tv":0.0,"id":16206893}]}]}
{"op":"mcm","clk":"4225248212","pt":1631441550165,"mc":[{"id":"1.187552052","rc":[{"batl":[[0,9.8,62.09],[1,95,19.35],[2,990,2.2]],"ltp":0.0,"tv":0.0,"id":9636182},{"batl":[[2,990,2.2]],"ltp":0.0,"tv":0.0,"id":16206893}]}]}
{"op":"mcm","clk":"4225281501","pt":1631441782295,"mc":[{"id":"1.187552052","rc":[{"batl":[[0,95,19.35],[1,990,2.2],[2,990,0]],"ltp":0.0,"tv":0.0,"id":16206893}]}]}
{"op":"mcm","clk":"4225281618","pt":1631441783134,"mc":[{"id":"1.187552052","rc":[{"batl":[[0,1.74,62.13],[1,95,19.35],[2,990,2.2]],"ltp":0.0,"tv":0.0,"id":16206893}]}]}
{"op":"mcm","clk":"4225682674","pt":1631444415279,"mc":[{"id":"1.187552052","rc":[{"batl":[[0,95,19.35],[1,990,2.2],[2,990,0]],"ltp":0.0,"tv":0.0,"id":9636182},{"batl":[[0,95,19.35],[1,990,2.2],[2,990,0]],"ltp":0.0,"tv":0.0,"id":16206893}]}]}
{"op":"mcm","clk":"4225685849","pt":1631444434641,"mc":[{"id":"1.187552052","rc":[{"batl":[[0,11,30.57],[1,95,19.35],[2,990,2.2]],"ltp":0.0,"tv":0.0,"id":9636182},{"batl":[[0,1.83,59.11],[1,95,19.35],[2,990,2.2]],"ltp":0.0,"tv":0.0,"id":16206893}]}]}
{"op":"mcm","clk":"4225693389","pt":1631444485173,"mc":[{"id":"1.187552052","rc":[{"batb":[[1,1.01,12]],"ltp":0.0,"tv":0.0,"id":9636182},{"batb":[[1,1.01,12]],"ltp":0.0,"tv":0.0,"id":16206893}]}]}
{"op":"mcm","clk":"4225912549","pt":1631445813099,"mc":[{"id":"1.187552052","rc":[{"batb":[[1,1.02,108.45],[2,1.01,12]],"ltp":0.0,"tv":0.0,"id":9636182},{"batb":[[1,1.02,108.45],[2,1.01,12]],"ltp":0.0,"tv":0.0,"id":16206893}]}]}
{"op":"mcm","clk":"4226096995","pt":1631446956686,"mc":[{"id":"1.187552052","rc":[{"batb":[[1,1.05,879.5],[2,1.02,108.45]],"ltp":0.0,"tv":0.0,"id":9636182},{"batb":[[1,1.12,351.8],[2,1.02,108.45]],"ltp":0.0,"tv":0.0,"id":16206893}]}]}
{"op":"mcm","clk":"4226097785","pt":1631446961727,"mc":[{"id":"1.187552052","rc":[{"batb":[[1,1.02,108.45],[2,1.01,12]],"ltp":0.0,"tv":0.0,"id":9636182}]}]}
{"op":"mcm","clk":"4226098716","pt":1631446967735,"mc":[{"id":"1.187552052","rc":[{"batl":[[0,1.81,43.98],[1,1.83,59.11],[2,95,19.35]],"ltp":0.0,"tv":0.0,"id":16206893}]}]}
{"op":"mcm","clk":"4226123401","pt":1631447134889,"mc":[{"id":"1.187552052","rc":[{"batl":[[0,1.8,129.92],[1,1.81,43.98]],"ltp":0.0,"tv":0.0,"id":16206893}]}]}
{"op":"mcm","clk":"4226204983","pt":1631447708257,"mc":[{"id":"1.187552052","rc":[{"batl":[[0,95,19.35],[1,990,2.2],[2,990,0]],"ltp":0.0,"tv":0.0,"id":9636182},{"batl":[[0,1.78,43.98],[1,95,19.35],[2,990,2.2]],"ltp":0.0,"tv":0.0,"id":16206893}]}]}
{"op":"mcm","clk":"4226243486","pt":1631448001553,"mc":[{"id":"1.187552052","rc":[{"batb":[[0,3.25,20.04]],"ltp":0.0,"tv":0.0,"id":9636182},{"batb":[[0,1.29,155.49]],"ltp":0.0,"tv":0.0,"id":16206893}]}]}
{"op":"mcm","clk":"4226445568","pt":1631449163305,"mc":[{"id":"1.187552052","rc":[{"batl":[[0,75,14.59],[1,95,19.35],[2,990,2.2]],"ltp":0.0,"tv":0.0,"id":9636182},{"batl":[[0,2.12,89.61]],"ltp":0.0,"tv":0.0,"id":16206893}]}]}
{"op":"mcm","clk":"4226445634","pt":1631449163682,"mc":[{"id":"1.187552052","rc":[{"batl":[[0,70,15.64]],"ltp":0.0,"tv":0.0,"id":9636182},{"batl":[[0,2.24,84.85]],"ltp":0.0,"tv":0.0,"id":16206893}]}]}
{"op":"mcm","clk":"4226445810","pt":1631449164915,"mc":[{"id":"1.187552052","rc":[{"batb":[[1,1.02,108.45],[2,1.01,12]],"ltp":0.0,"tv":0.0,"id":16206893}]}]}
{"op":"mcm","clk":"4226448109","pt":1631449178964,"mc":[{"id":"1.187552052","rc":[{"batb":[[1,1.03,1495.16],[2,1.02,108.45]],"batl":[[0,2.2,43.98],[1,2.24,84.85],[2,95,19.35]],"ltp":0.0,"tv":0.0,"id":16206893}]}]}
{"op":"mcm","clk":"4226492852","pt":1631449464490,"mc":[{"id":"1.187552052","rc":[{"batl":[[0,90,12.16]],"ltp":0.0,"tv":0.0,"id":9636182},{"batl":[[0,2.16,87.96],[1,2.2,43.98]],"ltp":0.0,"tv":0.0,"id":16206893}]}]}
{"op":"mcm","clk":"4226535809","pt":1631449765389,"mc":[{"id":"1.187552052","rc":[{"batl":[[0,50,21.89]],"ltp":0.0,"tv":0.0,"id":9636182}]}]}
{"op":"mcm","clk":"4226579006","pt":1631450065453,"mc":[{"id":"1.187552052","rc":[{"batl":[[0,95,19.35],[1,990,2.2],[2,990,0]],"ltp":0.0,"tv":0.0,"id":9636182}]}]}
{"op":"mcm","clk":"4226579113","pt":1631450066043,"mc":[{"id":"1.187552052","rc":[{"batl":[[0,32,34.2],[1,95,19.35],[2,990,2.2]],"ltp":0.0,"tv":0.0,"id":9636182}]}]}
{"op":"mcm","clk":"4226618010","pt":1631450314728,"mc":[{"id":"1.187552052","rc":[{"batb":[[0,3.25,32.85]],"ltp":0.0,"tv":0.0,"id":9636182},{"batl":[[0,1.45,25.62]],"ltp":0.0,"tv":0.0,"id":16206893}]}]}
{"op":"mcm","clk":"4226626122","pt":1631450366323,"mc":[{"id":"1.187552052","rc":[{"batl":[[0,50,28.67]],"ltp":0.0,"tv":0.0,"id":9636182}]}]}
{"op":"mcm","clk":"4226626200","pt":1631450366819,"mc":[{"id":"1.187552052","rc":[{"batl":[[0,90,12.16]],"ltp":0.0,"tv":0.0,"id":9636182}]}]}
{"op":"mcm","clk":"4226679421","pt":1631450667421,"mc":[{"id":"1.187552052","rc":[{"batl":[[0,95,19.35],[1,990,2.2],[2,990,0]],"ltp":0.0,"tv":0.0,"id":9636182}]}]}
{"op":"mcm","clk":"4226679450","pt":1631450667632,"mc":[{"id":"1.187552052","rc":[{"batl":[[0,90,12.16],[1,95,19.35],[2,990,2.2]],"ltp":0.0,"tv":0.0,"id":9636182}]}]}
{"op":"mcm","clk":"4226693433","pt":1631450747449,"mc":[{"id":"1.187552052","rc":[{"batl":[[0,1.44,80],[1,1.45,25.62],[2,2.2,43.98]],"ltp":0.0,"tv":0.0,"id":16206893}]}]}
{"op":"mcm","clk":"4226728838","pt":1631450968268,"mc":[{"id":"1.187552052","rc":[{"batl":[[0,80,13.68]],"ltp":0.0,"tv":0.0,"id":9636182}]}]}
{"op":"mcm","clk":"4226770203","pt":1631451268426,"mc":[{"id":"1.187552052","rc":[{"batl":[[0,70,20.48]],"ltp":0.0,"tv":0.0,"id":9636182}]}]}
{"op":"mcm","clk":"4226770243","pt":1631451268849,"mc":[{"id":"1.187552052","rc":[{"batl":[[0,90,12.16]],"ltp":0.0,"tv":0.0,"id":9636182}]}]}
{"op":"mcm","clk":"4226809507","pt":1631451569251,"mc":[{"id":"1.187552052","rc":[{"batl":[[0,60,23.9]],"ltp":0.0,"tv":0.0,"id":9636182}]}]}
{"op":"mcm","clk":"4226809571","pt":1631451569692,"mc":[{"id":"1.187552052","rc":[{"batl":[[0,80,13.68]],"ltp":0.0,"tv":0.0,"id":9636182}]}]}
{"op":"mcm","clk":"4226813324","pt":1631451600784,"mc":[{"id":"1.187552052","rc":[{"batb":[[0,3.3,5.57],[1,3.25,32.85],[2,1.02,108.45]],"ltp":0.0,"tv":0.0,"id":9636182},{"batb":[[0,1.3,42.7],[1,1.29,155.49],[2,1.03,1495.16]],"ltp":0.0,"tv":0.0,"id":16206893}]}]}
{"op":"mcm","clk":"4226836115","pt":1631451743803,"mc":[{"id":"1.187552052","rc":[{"batl":[[0,1.44,105.62],[1,2.2,43.98],[2,95,19.35]],"ltp":0.0,"tv":0.0,"id":16206893}]}]}
{"op":"mcm","clk":"4226860088","pt":1631451870222,"mc":[{"id":"1.187552052","rc":[{"batl":[[0,95,19.35],[1,990,2.2],[2,990,0]],"ltp":0.0,"tv":0.0,"id":9636182}]}]}
{"op":"mcm","clk":"4226860161","pt":1631451870547,"mc":[{"id":"1.187552052","rc":[{"batl":[[0,85,12.88],[1,95,19.35],[2,990,2.2]],"ltp":0.0,"tv":0.0,"id":9636182}]}]}
{"op":"mcm","clk":"4226869088","pt":1631451912776,"mc":[{"id":"1.187552052","rc":[{"batl":[[1,1.85,2.66],[2,2.2,43.98]],"ltp":0.0,"tv":0.0,"id":16206893}]}]}
{"op":"mcm","clk":"4226870618","pt":1631451920517,"mc":[{"id":"1.187552052","rc":[{"batb":[[2,1.05,42.54]],"ltp":0.0,"tv":0.0,"id":16206893}]}]}
{"op":"mcm","clk":"4226916359","pt":1631452171191,"mc":[{"id":"1.187552052","rc":[{"batl":[[0,55,19.9]],"ltp":0.0,"tv":0.0,"id":9636182}]}]}
{"op":"mcm","clk":"4226973016","pt":1631452471421,"mc":[{"id":"1.187552052","rc":[{"batl":[[0,80,17.92]],"ltp":0.0,"tv":0.0,"id":9636182}]}]}
{"op":"mcm","clk":"4226973112","pt":1631452471923,"mc":[{"id":"1.187552052","rc":[{"batl":[[0,75,14.59]],"ltp":0.0,"tv":0.0,"id":9636182}]}]}
{"op":"mcm","clk":"4227026626","pt":1631452772436,"mc":[{"id":"1.187552052","rc":[{"batl":[[0,95,19.35],[1,990,2.2],[2,990,0]],"ltp":0.0,"tv":0.0,"id":9636182}]}]}
{"op":"mcm","clk":"4227026689","pt":1631452772718,"mc":[{"id":"1.187552052","rc":[{"batl":[[0,75,14.59],[1,95,19.35],[2,990,2.2]],"ltp":0.0,"tv":0.0,"id":9636182}]}]}
{"op":"mcm","clk":"4227026998","pt":1631452774375,"mc":[{"id":"1.187552052","rc":[{"batb":[[0,3.25,32.85],[1,1.02,108.45],[2,1.01,12]],"ltp":0.0,"tv":0.0,"id":9636182},{"batb":[[0,1.29,155.49],[1,1.05,42.54],[2,1.03,1495.16]],"ltp":0.0,"tv":0.0,"id":16206893}]}]}
{"op":"mcm","clk":"4227027178","pt":1631452775261,"mc":[{"id":"1.187552052","rc":[{"batb":[[0,3.3,5.57],[1,3.25,32.85],[2,1.02,108.45]],"ltp":0.0,"tv":0.0,"id":9636182},{"batb":[[0,1.3,42.7],[1,1.29,155.49],[2,1.05,42.54]],"ltp":0.0,"tv":0.0,"id":16206893}]}]}
{"op":"mcm","clk":"4227037953","pt":1631452843121,"mc":[{"id":"1.187552052","rc":[{"batb":[[0,3.25,32.85],[1,1.02,108.45],[2,1.01,12]],"ltp":0.0,"tv":0.0,"id":9636182},{"batb":[[0,1.29,155.49],[1,1.05,42.54],[2,1.03,1495.16]],"ltp":0.0,"tv":0.0,"id":16206893}]}]}
{"op":"mcm","clk":"4227038112","pt":1631452844345,"mc":[{"id":"1.187552052","rc":[{"batb":[[0,3.3,5.57],[1,3.25,32.85],[2,1.02,108.45]],"ltp":0.0,"tv":0.0,"id":9636182},{"batb":[[0,1.3,42.7],[1,1.29,155.49],[2,1.05,42.54]],"ltp":0.0,"tv":0.0,"id":16206893}]}]}
{"op":"mcm","clk":"4227075074","pt":1631453073468,"mc":[{"id":"1.187552052","rc":[{"batl":[[0,46,23.79]],"ltp":0.0,"tv":0.0,"id":9636182}]}]}
{"op":"mcm","clk":"4227123012","pt":1631453373472,"mc":[{"id":"1.187552052","rc":[{"batl":[[0,95,19.35],[1,990,2.2],[2,990,0]],"ltp":0.0,"tv":0.0,"id":9636182}]}]}
{"op":"mcm","clk":"4227123130","pt":1631453374173,"mc":[{"id":"1.187552052","rc":[{"batl":[[0,70,15.64],[1,95,19.35],[2,990,2.2]],"ltp":0.0,"tv":0.0,"id":9636182}]}]}
{"op":"mcm","clk":"4227130432","pt":1631453417918,"mc":[{"id":"1.187552052","rc":[{"batb":[[2,1.07,615.65]],"ltp":0.0,"tv":0.0,"id":16206893}]}]}
{"op":"mcm","clk":"4227131817","pt":1631453426132,"mc":[{"id":"1.187552052","rc":[{"batl":[[1,1.84,43.98],[2,1.85,2.66]],"ltp":0.0,"tv":0.0,"id":16206893}]}]}
{"op":"mcm","clk":"4227172298","pt":1631453674461,"mc":[{"id":"1.187552052","rc":[{"batl":[[0,80,17.92]],"ltp":0.0,"tv":0.0,"id":9636182}]}]}
{"op":"mcm","clk":"4227172369","pt":1631453674841,"mc":[{"id":"1.187552052","rc":[{"batl":[[0,90,12.16]],"ltp":0.0,"tv":0.0,"id":9636182}]}]}
{"op":"mcm","clk":"4227218451","pt":1631453975065,"mc":[{"id":"1.187552052","rc":[{"batl":[[0,90,15.93]],"ltp":0.0,"tv":0.0,"id":9636182}]}]}
{"op":"mcm","clk":"4227267984","pt":1631454275420,"mc":[{"id":"1.187552052","rc":[{"batl":[[0,90,12.16]],"ltp":0.0,"tv":0.0,"id":9636182}]}]}
{"op":"mcm","clk":"4227325100","pt":1631454576318,"mc":[{"id":"1.187552052","rc":[{"batl":[[0,70,15.64]],"ltp":0.0,"tv":0.0,"id":9636182}]}]}
{"op":"mcm","clk":"4227359662","pt":1631454876393,"mc":[{"id":"1.187552052","rc":[{"batl":[[0,95,19.35],[1,990,2.2],[2,990,0]],"ltp":0.0,"tv":0.0,"id":9636182}]}]}
{"op":"mcm","clk":"4227392657","pt":1631455176360,"mc":[{"id":"1.187552052","rc":[{"batl":[[0,85,16.87],[1,95,19.35],[2,990,2.2]],"ltp":0.0,"tv":0.0,"id":9636182}]}]}
{"op":"mcm","clk":"4227396367","pt":1631455205386,"mc":[{"id":"1.187552052","rc":[{"trd":[[3.3,20]],"batb":[[0,3.25,32.85],[1,1.02,108.45],[2,1.01,12]],"batl":[[0,95,19.35],[1,990,2.2],[2,990,0]],"ltp":3.3,"tv":19.99,"id":9636182}],"tv":19.99}]}
{"op":"mcm","clk":"4227396446","pt":1631455205858,"mc":[{"id":"1.187552052","rc":[{"batb":[[0,3.3,5.57],[1,3.25,32.85],[2,1.02,108.45]],"ltp":3.3,"tv":19.99,"id":9636182}]}]}
{"op":"mcm","clk":"4227407051","pt":1631455289660,"mc":[{"id":"1.187552052","marketDefinition":{"bspMarket":false,"turnInPlayEnabled":true,"persistenceEnabled":true,"marketBaseRate":5.0,"eventId":"30895183","eventTypeId":"2","numberOfWinners":1,"bettingType":"ODDS","marketType":"MATCH_ODDS","marketTime":"2021-09-12T14:00:00.000Z","suspendTime":"2021-09-12T14:00:00.000Z","bspReconciled":false,"complete":true,"inPlay":true,"crossMatching":true,"runnersVoidable":false,"numberOfActiveRunners":2,"betDelay":5,"status":"OPEN","runners":[{"status":"ACTIVE","sortPriority":1,"id":9636182,"name":"A Carrillo Marin"},{"status":"ACTIVE","sortPriority":2,"id":16206893,"name":"Y Cavalle-Reimers"}],"regulators":["MR_INT"],"countryCode":"GB","discountAllowed":true,"timezone":"GMT","openDate":"2021-09-12T14:00:00.000Z","version":4028510603,"name":"Match Odds","eventName":"A Carrillo Marin v Y Cavalle-reimers"},"rc":[{"batb":[[0,1.01,12],[1,3.25,0],[2,1.02,0]],"ltp":3.3,"tv":19.99,"id":9636182},{"batb":[[0,1.01,12],[1,1.29,0],[2,1.07,0]],"batl":[[0,1.44,80],[1,1.84,0],[2,1.85,0]],"ltp":0.0,"tv":0.0,"id":16206893}]}]}
{"op":"mcm","clk":"4227407833","pt":1631455295082,"mc":[{"id":"1.187552052","rc":[{"batl":[[1,11.5,8.68]],"ltp":0.0,"tv":0.0,"id":16206893}]}]}
{"op":"mcm","clk":"4228409371","pt":1631461458950,"mc":[{"id":"1.187552052","rc":[{"batb":[[0,1.02,20],[1,1.01,12]],"ltp":0.0,"tv":0.0,"id":16206893}]}]}
{"op":"mcm","clk":"4228518785","pt":1631462175206,"mc":[{"id":"1.187552052","marketDefinition":{"bspMarket":false,"turnInPlayEnabled":true,"persistenceEnabled":true,"marketBaseRate":5.0,"eventId":"30895183","eventTypeId":"2","numberOfWinners":1,"bettingType":"ODDS","marketType":"MATCH_ODDS","marketTime":"2021-09-12T15:56:14.000Z","suspendTime":"2021-09-12T15:56:14.000Z","bspReconciled":false,"complete":true,"inPlay":true,"crossMatching":true,"runnersVoidable":false,"numberOfActiveRunners":2,"betDelay":5,"status":"OPEN","runners":[{"status":"ACTIVE","sortPriority":1,"id":9636182,"name":"A Carrillo Marin"},{"status":"ACTIVE","sortPriority":2,"id":16206893,"name":"Y Cavalle-Reimers"}],"regulators":["MR_INT"],"countryCode":"GB","discountAllowed":true,"timezone":"GMT","openDate":"2021-09-12T14:00:00.000Z","version":4028984707,"name":"Match Odds","eventName":"A Carrillo Marin v Y Cavalle-reimers"}}]}
{"op":"mcm","clk":"4228522873","pt":1631462207216,"mc":[{"id":"1.187552052","marketDefinition":{"bspMarket":false,"turnInPlayEnabled":true,"persistenceEnabled":true,"marketBaseRate":5.0,"eventId":"30895183","eventTypeId":"2","numberOfWinners":1,"bettingType":"ODDS","marketType":"MATCH_ODDS","marketTime":"2021-09-12T15:56:14.000Z","suspendTime":"2021-09-12T15:56:14.000Z","bspReconciled":false,"complete":true,"inPlay":true,"crossMatching":true,"runnersVoidable":false,"numberOfActiveRunners":2,"betDelay":5,"status":"OPEN","runners":[{"status":"ACTIVE","sortPriority":1,"id":9636182,"name":"A Carrillo Marin"},{"status":"ACTIVE","sortPriority":2,"id":16206893,"name":"Y Cavalle-Reimers"}],"regulators":["MR_INT"],"countryCode":"GB","discountAllowed":true,"timezone":"GMT","openDate":"2021-09-12T15:56:14.000Z","version":4028984707,"name":"Match Odds","eventName":"A Carrillo Marin v Y Cavalle-reimers"}}]}
{"op":"mcm","clk":"4228599647","pt":1631462699758,"mc":[{"id":"1.187552052","rc":[{"batl":[[0,1.44,101.99]],"ltp":0.0,"tv":0.0,"id":16206893}]}]}
{"op":"mcm","clk":"4228627166","pt":1631462831768,"mc":[{"id":"1.187552052","rc":[{"batl":[[0,1.44,80]],"ltp":0.0,"tv":0.0,"id":16206893}]}]}
{"op":"mcm","clk":"4228741570","pt":1631463431398,"mc":[{"id":"1.187552052","rc":[{"trd":[[1.44,160]],"batb":[[0,1.44,20],[1,1.02,20],[2,1.01,12]],"batl":[[0,11.5,8.68],[1,11.5,0]],"ltp":1.44,"tv":160.0,"id":16206893}],"tv":179.99}]}
{"op":"mcm","clk":"4228744524","pt":1631463446407,"mc":[{"id":"1.187552052","rc":[{"trd":[[1.44,199.98]],"batb":[[0,1.02,20.01],[1,1.01,12],[2,1.01,0]],"ltp":1.44,"tv":199.98,"id":16206893}],"tv":219.98}]}
{"op":"mcm","clk":"4228745914","pt":1631463453305,"mc":[{"id":"1.187552052","rc":[{"batb":[[0,1.02,20]],"ltp":1.44,"tv":199.98,"id":16206893}]}]}
{"op":"mcm","clk":"4228847640","pt":1631464010545,"mc":[{"id":"1.187552052","rc":[{"batb":[[0,1.01,12],[1,1.01,0]],"ltp":1.44,"tv":199.98,"id":16206893}]}]}
{"op":"mcm","clk":"4228960504","pt":1631464712244,"mc":[{"id":"1.187552052","rc":[{"batb":[[0,1.02,100],[1,1.01,12]],"ltp":1.44,"tv":199.98,"id":16206893}]}]}
{"op":"mcm","clk":"4228962308","pt":1631464722753,"mc":[{"id":"1.187552052","rc":[{"batb":[[0,1.1,100],[1,1.01,12]],"ltp":3.3,"tv":19.99,"id":9636182}]}]}
{"op":"mcm","clk":"4228963226","pt":1631464727946,"mc":[{"id":"1.187552052","rc":[{"batl":[[0,10.5,2.89],[1,11.5,8.68]],"ltp":1.44,"tv":199.98,"id":16206893}]}]}
{"op":"mcm","clk":"4229022277","pt":1631465066096,"mc":[{"id":"1.187552052","rc":[{"batb":[[0,1.04,10.85],[1,1.02,100],[2,1.01,12]],"ltp":1.44,"tv":199.98,"id":16206893}]}]}
{"op":"mcm","clk":"4229023069","pt":1631465070697,"mc":[{"id":"1.187552052","rc":[{"batb":[[0,1.25,18.08],[1,1.1,100],[2,1.01,12]],"ltp":3.3,"tv":19.99,"id":9636182}]}]}
{"op":"mcm","clk":"4229081625","pt":1631465403523,"mc":[{"id":"1.187552052","rc":[{"batb":[[0,1.02,100],[1,1.01,12],[2,1.01,0]],"ltp":1.44,"tv":199.98,"id":16206893}]}]}
{"op":"mcm","clk":"4229082278","pt":1631465408599,"mc":[{"id":"1.187552052","rc":[{"batb":[[0,1.03,10.85],[1,1.02,100],[2,1.01,12]],"ltp":1.44,"tv":199.98,"id":16206893}]}]}
{"op":"mcm","clk":"4229100770","pt":1631465565458,"mc":[{"id":"1.187552052","rc":[{"batb":[[0,2,1.45],[1,1.25,18.08],[2,1.1,100]],"ltp":3.3,"tv":19.99,"id":9636182}]}]}
{"op":"mcm","clk":"4229137519","pt":1631465849122,"mc":[{"id":"1.187552052","rc":[{"trd":[[1.03,21.69]],"batb":[[0,1.02,100],[1,1.01,12],[2,1.01,0]],"batl":[[0,1.03,159.96],[1,10.5,2.89],[2,11.5,8.68]],"ltp":1.03,"tv":221.67,"id":16206893}],"tv":241.67}]}
{"op":"mcm","clk":"4229137941","pt":1631465852617,"mc":[{"id":"1.187552052","rc":[{"batl":[[1,1.9,5],[2,10.5,2.89]],"ltp":1.03,"tv":221.67,"id":16206893}]}]}
{"op":"mcm","clk":"4229138155","pt":1631465854283,"mc":[{"id":"1.187552052","rc":[{"trd":[[1.03,341.61]],"batl":[[0,10.5,2.89],[1,11.5,8.68],[2,10.5,0]],"ltp":1.03,"tv":541.59,"id":16206893}],"tv":561.59}]}
{"op":"mcm","clk":"4229139578","pt":1631465865023,"mc":[{"id":"1.187552052","rc":[{"batl":[[0,1.8,6.51],[1,10.5,2.89],[2,11.5,8.68]],"ltp":1.03,"tv":541.59,"id":16206893}]}]}
{"op":"mcm","clk":"4229140758","pt":1631465874301,"mc":[{"id":"1.187552052","rc":[{"batl":[[0,1.5,5],[1,1.8,6.51],[2,10.5,2.89]],"ltp":1.03,"tv":541.59,"id":16206893}]}]}
{"op":"mcm","clk":"4229141653","pt":1631465881244,"mc":[{"id":"1.187552052","rc":[{"batl":[[0,1.5,5.72]],"ltp":1.03,"tv":541.59,"id":16206893}]}]}
{"op":"mcm","clk":"4229142107","pt":1631465884442,"mc":[{"id":"1.187552052","rc":[{"batl":[[0,1.4,5.78],[1,1.5,5],[2,1.8,6.51]],"ltp":1.03,"tv":541.59,"id":16206893}]}]}
{"op":"mcm","clk":"4229144733","pt":1631465903180,"mc":[{"id":"1.187552052","rc":[{"batl":[[0,1.2,2.72],[1,1.4,5.78],[2,1.5,5]],"ltp":1.03,"tv":541.59,"id":16206893}]}]}
{"op":"mcm","clk":"4229154671","pt":1631465976310,"mc":[{"id":"1.187552052","rc":[{"batl":[[0,1.15,1.45],[1,1.2,2.72],[2,1.4,5.78]],"ltp":1.03,"tv":541.59,"id":16206893}]}]}
{"op":"mcm","clk":"4229160161","pt":1631466015527,"mc":[{"id":"1.187552052","rc":[{"batb":[[2,1.01,12]],"ltp":3.3,"tv":19.99,"id":9636182},{"batb":[[0,1.01,12],[1,1.01,0]],"ltp":1.03,"tv":541.59,"id":16206893}]}]}
{"op":"mcm","clk":"4229179269","pt":1631466127132,"mc":[{"id":"1.187552052","rc":[{"batl":[[2,1.4,2.89]],"ltp":1.03,"tv":541.59,"id":16206893}]}]}
{"op":"mcm","clk":"4229495637","pt":1631467798503,"mc":[{"id":"1.187552052","rc":[{"trd":[[1.01,5]],"batb":[[0,1.01,9.5]],"ltp":1.01,"tv":546.59,"id":16206893}],"tv":566.59}]}
{"op":"mcm","clk":"4229503986","pt":1631467848348,"mc":[{"id":"1.187552052","rc":[{"trd":[[1.01,23]],"batb":[[0,1.01,0.5]],"ltp":1.01,"tv":564.59,"id":16206893}],"tv":584.59}]}
{"op":"mcm","clk":"4229558116","pt":1631468155605,"mc":[{"id":"1.187552052","marketDefinition":{"bspMarket":false,"turnInPlayEnabled":true,"persistenceEnabled":true,"marketBaseRate":5.0,"eventId":"30895183","eventTypeId":"2","numberOfWinners":1,"bettingType":"ODDS","marketType":"MATCH_ODDS","marketTime":"2021-09-12T15:56:14.000Z","suspendTime":"2021-09-12T15:56:14.000Z","bspReconciled":false,"complete":true,"inPlay":true,"crossMatching":true,"runnersVoidable":false,"numberOfActiveRunners":2,"betDelay":5,"status":"SUSPENDED","runners":[{"status":"ACTIVE","sortPriority":1,"id":9636182,"name":"A Carrillo Marin"},{"status":"ACTIVE","sortPriority":2,"id":16206893,"name":"Y Cavalle-Reimers"}],"regulators":["MR_INT"],"countryCode":"GB","discountAllowed":true,"timezone":"GMT","openDate":"2021-09-12T15:56:14.000Z","version":4029364317,"name":"Match Odds","eventName":"A Carrillo Marin v Y Cavalle-reimers"}}]}
{"op":"mcm","clk":"4229558719","pt":1631468158690,"mc":[{"id":"1.187552052","tv":0.0}]}
{"op":"mcm","clk":"4229558933","pt":1631468159632,"mc":[{"id":"1.187552052","marketDefinition":{"bspMarket":false,"turnInPlayEnabled":true,"persistenceEnabled":true,"marketBaseRate":5.0,"eventId":"30895183","eventTypeId":"2","numberOfWinners":1,"bettingType":"ODDS","marketType":"MATCH_ODDS","marketTime":"2021-09-12T15:56:14.000Z","suspendTime":"2021-09-12T15:56:14.000Z","bspReconciled":false,"complete":true,"inPlay":true,"crossMatching":false,"runnersVoidable":false,"numberOfActiveRunners":0,"betDelay":5,"status":"CLOSED","settledTime":"2021-09-12T17:35:57.000Z","runners":[{"status":"LOSER","sortPriority":1,"id":9636182,"name":"A Carrillo Marin"},{"status":"WINNER","sortPriority":2,"id":16206893,"name":"Y Cavalle-Reimers"}],"regulators":["MR_INT"],"countryCode":"GB","discountAllowed":true,"timezone":"GMT","openDate":"2021-09-12T15:56:14.000Z","version":4029364337,"name":"Match Odds","eventName":"A Carrillo Marin v Y Cavalle-reimers"}}]}
