{"op":"mcm","clk":"4206613184","pt":1631439438070,"mc":[{"id":"1.187552299","marketDefinition":{"bspMarket":false,"turnInPlayEnabled":true,"persistenceEnabled":true,"marketBaseRate":5.0,"eventId":"30895245","eventTypeId":"2","numberOfWinners":1,"bettingType":"ODDS","marketType":"MATCH_ODDS","marketTime":"2021-09-12T15:30:00.000Z","suspendTime":"2021-09-12T15:30:00.000Z","bspReconciled":false,"complete":true,"inPlay":false,"crossMatching":false,"runnersVoidable":false,"numberOfActiveRunners":2,"betDelay":0,"status":"OPEN","runners":[{"status":"ACTIVE","sortPriority":1,"id":23806970,"name":"D Semenistaja"},{"status":"ACTIVE","sortPriority":2,"id":16100628,"name":"G Maristany Zuleta de Reales"}],"regulators":["MR_INT"],"countryCode":"GB","discountAllowed":false,"timezone":"GMT","openDate":"2021-09-12T15:30:00.000Z","version":4027634792,"name":"Match Odds","eventName":"D Semenistaja v G Maristany Zuleta De Reales"},"rc":[{"batb":[[0,1.01,25]],"ltp":0.0,"tv":0.0,"id":16100628},{"batb":[[0,1.01,25]],"ltp":0.0,"tv":0.0,"id":23806970}]}]}
{"op":"mcm","clk":"4206613465","pt":1631439440941,"mc":[{"id":"1.187552299","marketDefinition":{"bspMarket":false,"turnInPlayEnabled":true,"persistenceEnabled":true,"marketBaseRate":5.0,"eventId":"30895245","eventTypeId":"2","numberOfWinners":1,"bettingType":"ODDS","marketType":"MATCH_ODDS","marketTime":"2021-09-12T15:30:00.000Z","suspendTime":"2021-09-12T15:30:00.000Z","bspReconciled":false,"complete":true,"inPlay":false,"crossMatching":false,"runnersVoidable":false,"numberOfActiveRunners":2,"betDelay":0,"status":"OPEN","runners":[{"status":"ACTIVE","sortPriority":1,"id":23806970,"name":"D Semenistaja"},{"status":"ACTIVE","sortPriority":2,"id":16100628,"name":"G Maristany Zuleta de Reales"}],"regulators":["MR_INT"],"countryCode":"GB","discountAllowed":true,"timezone":"GMT","openDate":"2021-09-12T15:30:00.000Z","version":4027634792,"name":"Match Odds","eventName":"D Semenistaja v G Maristany Zuleta De Reales"}}]}
{"op":"mcm","clk":"4206662641","pt":1631439907602,"mc":[{"id":"1.187552299","rc":[{"batb":[[0,1.01,7]],"ltp":0.0,"tv":0.0,"id":16100628},{"batb":[[0,1.01,7]],"ltp":0.0,"tv":0.0,"id":23806970}]}]}
{"op":"mcm","clk":"4206708653","pt":1631440322303,"mc":[{"id":"1.187552299","rc":[{"batb":[[0,1.83,40.74],[1,1.01,7]],"ltp":0.0,"tv":0.0,"id":16100628},{"batb":[[0,1.83,40.74],[1,1.01,7]],"ltp":0.0,"tv":0.0,"id":23806970}]}]}
{"op":"mcm","clk":"4206709150","pt":1631440326603,"mc":[{"id":"1.187552299","marketDefinition":{"bspMarket":false,"turnInPlayEnabled":true,"persistenceEnabled":true,"marketBaseRate":5.0,"eventId":"30895245","eventTypeId":"2","numberOfWinners":1,"bettingType":"ODDS","marketType":"MATCH_ODDS","marketTime":"2021-09-12T15:30:00.000Z","suspendTime":"2021-09-12T15:30:00.000Z","bspReconciled":false,"complete":true,"inPlay":false,"crossMatching":true,"runnersVoidable":false,"numberOfActiveRunners":2,"betDelay":0,"status":"OPEN","runners":[{"status":"ACTIVE","sortPriority":1,"id":23806970,"name":"D Semenistaja"},{"status":"ACTIVE","sortPriority":2,"id":16100628,"name":"G Maristany Zuleta de Reales"}],"regulators":["MR_INT"],"countryCode":"GB","discountAllowed":true,"timezone":"GMT","openDate":"2021-09-12T15:30:00.000Z","version":4027634792,"name":"Match Odds","eventName":"D Semenistaja v G Maristany Zuleta De Reales"}}]}
{"op":"mcm","clk":"4206787399","pt":1631440990664,"mc":[{"id":"1.187552299","rc":[{"batl":[[0,95,19.35]],"ltp":0.0,"tv":0.0,"id":16100628},{"batl":[[0,95,19.35]],"ltp":0.0,"tv":0.0,"id":23806970}]}]}
{"op":"mcm","clk":"4206864886","pt":1631441550317,"mc":[{"id":"1.187552299","rc":[{"batl":[[1,990,2.2]],"ltp":0.0,"tv":0.0,"id":16100628},{"batl":[[1,990,2.2]],"ltp":0.0,"tv":0.0,"id":23806970}]}]}
{"op":"mcm","clk":"4207257758","pt":1631444489178,"mc":[{"id":"1.187552299","rc":[{"batb":[[1,1.01,12]],"ltp":0.0,"tv":0.0,"id":16100628},{"batb":[[1,1.01,12]],"ltp":0.0,"tv":0.0,"id":23806970}]}]}
{"op":"mcm","clk":"4207496140","pt":1631445812783,"mc":[{"id":"1.187552299","rc":[{"batb":[[1,1.02,108.45],[2,1.01,12]],"ltp":0.0,"tv":0.0,"id":16100628},{"batb":[[1,1.02,108.45],[2,1.01,12]],"ltp":0.0,"tv":0.0,"id":23806970}]}]}
{"op":"mcm","clk":"4208007370","pt":1631448599759,"mc":[{"id":"1.187552299","rc":[{"batb":[[1,1.05,879.5],[2,1.02,108.45]],"ltp":0.0,"tv":0.0,"id":16100628},{"batb":[[1,1.05,879.5],[2,1.02,108.45]],"ltp":0.0,"tv":0.0,"id":23806970}]}]}
{"op":"mcm","clk":"4208448125","pt":1631450727558,"mc":[{"id":"1.187552299","rc":[{"batb":[[0,1.85,34.16],[1,1.83,40.74],[2,1.05,879.5]],"ltp":0.0,"tv":0.0,"id":16100628}]}]}
{"op":"mcm","clk":"4208679327","pt":1631451965531,"mc":[{"id":"1.187552299","rc":[{"batl":[[0,2.5,2.66],[1,95,19.35],[2,990,2.2]],"ltp":0.0,"tv":0.0,"id":16100628}]}]}
{"op":"mcm","clk":"4208680490","pt":1631451970836,"mc":[{"id":"1.187552299","rc":[{"batb":[[2,1.4,5.32]],"ltp":0.0,"tv":0.0,"id":16100628}]}]}
{"op":"mcm","clk":"4208979903","pt":1631453404424,"mc":[{"id":"1.187552299","rc":[{"batb":[[1,1.83,54.32]],"ltp":0.0,"tv":0.0,"id":16100628},{"batb":[[0,1.83,54.32]],"ltp":0.0,"tv":0.0,"id":23806970}]}]}
{"op":"mcm","clk":"4208999249","pt":1631453503862,"mc":[{"id":"1.187552299","rc":[{"batb":[[2,1.42,97.62]],"ltp":0.0,"tv":0.0,"id":16100628}]}]}
{"op":"mcm","clk":"4209651866","pt":1631456889697,"mc":[{"id":"1.187552299","rc":[{"trd":[[1.83,32.92]],"batb":[[0,1.83,37.86]],"ltp":1.83,"tv":32.92,"id":23806970}],"tv":32.92}]}
{"op":"mcm","clk":"4209652090","pt":1631456890906,"mc":[{"id":"1.187552299","rc":[{"batb":[[0,1.83,54.32]],"ltp":1.83,"tv":32.92,"id":23806970}]}]}
{"op":"mcm","clk":"4209674356","pt":1631457001320,"mc":[{"id":"1.187552299","rc":[{"batb":[[0,1.86,14.89],[1,1.85,34.16],[2,1.83,54.32]],"ltp":0.0,"tv":0.0,"id":16100628},{"batb":[[0,1.84,15.25],[1,1.83,54.32],[2,1.05,879.5]],"ltp":1.83,"tv":32.92,"id":23806970}]}]}
{"op":"mcm","clk":"4209825283","pt":1631457762821,"mc":[{"id":"1.187552299","rc":[{"batb":[[2,1.02,108.45]],"ltp":1.83,"tv":32.92,"id":23806970}]}]}
{"op":"mcm","clk":"4209895996","pt":1631458103655,"mc":[{"id":"1.187552299","rc":[{"batb":[[0,1.88,14.56],[1,1.87,34.16],[2,1.86,14.89]],"ltp":0.0,"tv":0.0,"id":16100628}]}]}
{"op":"mcm","clk":"4209899334","pt":1631458124562,"mc":[{"id":"1.187552299","rc":[{"batb":[[0,1.89,34.16],[1,1.88,14.56]],"ltp":0.0,"tv":0.0,"id":16100628}]}]}
{"op":"mcm","clk":"4209899524","pt":1631458125658,"mc":[{"id":"1.187552299","rc":[{"batb":[[2,1.83,54.32]],"ltp":0.0,"tv":0.0,"id":16100628}]}]}
{"op":"mcm","clk":"4210309584","pt":1631460681255,"mc":[{"id":"1.187552299","marketDefinition":{"bspMarket":false,"turnInPlayEnabled":true,"persistenceEnabled":true,"marketBaseRate":5.0,"eventId":"30895245","eventTypeId":"2","numberOfWinners":1,"bettingType":"ODDS","marketType":"MATCH_ODDS","marketTime":"2021-09-12T15:30:00.000Z","suspendTime":"2021-09-12T15:30:00.000Z","bspReconciled":false,"complete":true,"inPlay":true,"crossMatching":true,"runnersVoidable":false,"numberOfActiveRunners":2,"betDelay":5,"status":"OPEN","runners":[{"status":"ACTIVE","sortPriority":1,"id":23806970,"name":"D Semenistaja"},{"status":"ACTIVE","sortPriority":2,"id":16100628,"name":"G Maristany Zuleta de Reales"}],"regulators":["MR_INT"],"countryCode":"GB","discountAllowed":true,"timezone":"GMT","openDate":"2021-09-12T15:30:00.000Z","version":4028892175,"name":"Match Odds","eventName":"D Semenistaja v G Maristany Zuleta De Reales"},"rc":[{"batb":[[0,1.01,12],[1,1.88,0],[2,1.83,0]],"ltp":0.0,"tv":0.0,"id":16100628},{"batb":[[0,1.01,12],[1,1.83,0],[2,1.02,0]],"ltp":1.83,"tv":32.92,"id":23806970}]}]}
{"op":"mcm","clk":"4210477827","pt":1631461659316,"mc":[{"id":"1.187552299","rc":[{"batl":[[0,1.04,2.17]],"ltp":1.83,"tv":32.92,"id":23806970}]}]}
{"op":"mcm","clk":"4210478595","pt":1631461664489,"mc":[{"id":"1.187552299","rc":[{"batl":[[1,11.5,8.68]],"ltp":1.83,"tv":32.92,"id":23806970}]}]}
{"op":"mcm","clk":"4210479427","pt":1631461669423,"mc":[{"id":"1.187552299","rc":[{"batl":[[0,11.5,8.68],[1,11.5,0]],"ltp":1.83,"tv":32.92,"id":23806970}]}]}
{"op":"mcm","clk":"4211402254","pt":1631469000593,"mc":[{"id":"1.187552299","marketDefinition":{"bspMarket":false,"turnInPlayEnabled":true,"persistenceEnabled":true,"marketBaseRate":5.0,"eventId":"30895245","eventTypeId":"2","numberOfWinners":1,"bettingType":"ODDS","marketType":"MATCH_ODDS","marketTime":"2021-09-12T17:49:59.000Z","suspendTime":"2021-09-12T17:49:59.000Z","bspReconciled":false,"complete":true,"inPlay":true,"crossMatching":true,"runnersVoidable":false,"numberOfActiveRunners":2,"betDelay":5,"status":"OPEN","runners":[{"status":"ACTIVE","sortPriority":1,"id":23806970,"name":"D Semenistaja"},{"status":"ACTIVE","sortPriority":2,"id":16100628,"name":"G Maristany Zuleta de Reales"}],"regulators":["MR_INT"],"countryCode":"GB","discountAllowed":true,"timezone":"GMT","openDate":"2021-09-12T15:30:00.000Z","version":4029395033,"name":"Match Odds","eventName":"D Semenistaja v G Maristany Zuleta De Reales"}}]}
{"op":"mcm","clk":"4211402473","pt":1631469003612,"mc":[{"id":"1.187552299","marketDefinition":{"bspMarket":false,"turnInPlayEnabled":true,"persistenceEnabled":true,"marketBaseRate":5.0,"eventId":"30895245","eventTypeId":"2","numberOfWinners":1,"bettingType":"ODDS","marketType":"MATCH_ODDS","marketTime":"2021-09-12T17:49:59.000Z","suspendTime":"2021-09-12T17:49:59.000Z","bspReconciled":false,"complete":true,"inPlay":true,"crossMatching":true,"runnersVoidable":false,"numberOfActiveRunners":2,"betDelay":5,"status":"OPEN","runners":[{"status":"ACTIVE","sortPriority":1,"id":23806970,"name":"D Semenistaja"},{"status":"ACTIVE","sortPriority":2,"id":16100628,"name":"G Maristany Zuleta de Reales"}],"regulators":["MR_INT"],"countryCode":"GB","discountAllowed":true,"timezone":"GMT","openDate":"2021-09-12T17:49:59.000Z","version":4029395033,"name":"Match Odds","eventName":"D Semenistaja v G Maristany Zuleta De Reales"}}]}
{"op":"mcm","clk":"4211458704","pt":1631469897516,"mc":[{"id":"1.187552299","rc":[{"batb":[[0,1.02,12],[1,1.01,12]],"ltp":1.83,"tv":32.92,"id":23806970}]}]}
{"op":"mcm","clk":"4211527844","pt":1631470690023,"mc":[{"id":"1.187552299","rc":[{"batb":[[0,1.48,18.08],[1,1.02,12],[2,1.01,12]],"ltp":1.83,"tv":32.92,"id":23806970}]}]}
{"op":"mcm","clk":"4211530216","pt":1631470716764,"mc":[{"id":"1.187552299","rc":[{"batb":[[0,1.88,13.01],[1,1.48,18.08],[2,1.02,12]],"ltp":1.83,"tv":32.92,"id":23806970}]}]}
{"op":"mcm","clk":"4211540746","pt":1631470828117,"mc":[{"id":"1.187552299","rc":[{"batb":[[2,1.01,12]],"ltp":1.83,"tv":32.92,"id":23806970}]}]}
{"op":"mcm","clk":"4211572623","pt":1631471158639,"mc":[{"id":"1.187552299","rc":[{"batb":[[0,1.88,7.95]],"ltp":1.83,"tv":32.92,"id":23806970}]}]}
{"op":"mcm","clk":"4211667891","pt":1631472211666,"mc":[{"id":"1.187552299","rc":[{"batb":[[0,1.48,18.08],[1,1.01,12],[2,1.01,0]],"ltp":1.83,"tv":32.92,"id":23806970}]}]}
{"op":"mcm","clk":"4211668070","pt":1631472213781,"mc":[{"id":"1.187552299","rc":[{"batb":[[0,1.48,10.85]],"ltp":1.83,"tv":32.92,"id":23806970}]}]}
{"op":"mcm","clk":"4211783387","pt":1631473381069,"mc":[{"id":"1.187552299","rc":[{"trd":[[1.09,10]],"ltp":1.09,"tv":10.0,"id":16100628},{"trd":[[11.5,0.95]],"batl":[[0,11.5,7.73]],"ltp":11.5,"tv":33.86,"id":23806970}],"tv":43.86}]}
{"op":"mcm","clk":"4211790039","pt":1631473438749,"mc":[{"id":"1.187552299","rc":[{"batb":[[0,1.01,1207.86]],"ltp":1.09,"tv":10.0,"id":16100628}]}]}
{"op":"mcm","clk":"4211791092","pt":1631473447893,"mc":[{"id":"1.187552299","rc":[{"batb":[[0,1.5,7.26],[1,1.48,10.85],[2,1.01,12]],"ltp":11.5,"tv":33.86,"id":23806970}]}]}
{"op":"mcm","clk":"4211792187","pt":1631473458118,"mc":[{"id":"1.187552299","rc":[{"batb":[[0,1.55,7.23],[1,1.5,7.26],[2,1.48,10.85]],"ltp":11.5,"tv":33.86,"id":23806970}]}]}
{"op":"mcm","clk":"4211794438","pt":1631473478015,"mc":[{"id":"1.187552299","rc":[{"batb":[[0,2,232.09],[1,1.55,7.23],[2,1.5,7.26]],"ltp":11.5,"tv":33.86,"id":23806970}]}]}
{"op":"mcm","clk":"4211794733","pt":1631473480434,"mc":[{"id":"1.187552299","rc":[{"batb":[[0,2,232.81]],"ltp":11.5,"tv":33.86,"id":23806970}]}]}
{"op":"mcm","clk":"4211795935","pt":1631473491576,"mc":[{"id":"1.187552299","rc":[{"batb":[[0,2.2,23.86],[1,2,232.09],[2,1.55,7.23]],"ltp":11.5,"tv":33.86,"id":23806970}]}]}
{"op":"mcm","clk":"4211797200","pt":1631473502871,"mc":[{"id":"1.187552299","rc":[{"batl":[[0,1.5,72.3]],"ltp":1.09,"tv":10.0,"id":16100628},{"batb":[[1,1.55,7.23],[2,1.5,7.26]],"ltp":11.5,"tv":33.86,"id":23806970}]}]}
{"op":"mcm","clk":"4211797292","pt":1631473503556,"mc":[{"id":"1.187552299","rc":[{"batb":[[0,1.02,100],[1,1.01,1207.86]],"ltp":1.09,"tv":10.0,"id":16100628}]}]}
{"op":"mcm","clk":"4211797978","pt":1631473508883,"mc":[{"id":"1.187552299","rc":[{"batb":[[1,1.01,12]],"ltp":1.09,"tv":10.0,"id":16100628}]}]}
{"op":"mcm","clk":"4211798455","pt":1631473513000,"mc":[{"id":"1.187552299","rc":[{"batb":[[0,3.2,13.01],[1,2.2,23.86],[2,1.55,7.23]],"ltp":11.5,"tv":33.86,"id":23806970}]}]}
{"op":"mcm","clk":"4211799746","pt":1631473523894,"mc":[{"id":"1.187552299","rc":[{"batl":[[0,1.4,3.62],[1,1.5,72.3]],"ltp":1.09,"tv":10.0,"id":16100628}]}]}
{"op":"mcm","clk":"4211800485","pt":1631473529803,"mc":[{"id":"1.187552299","rc":[{"batb":[[1,2.2,23.14]],"ltp":11.5,"tv":33.86,"id":23806970}]}]}
{"op":"mcm","clk":"4211801077","pt":1631473534921,"mc":[{"id":"1.187552299","rc":[{"batb":[[0,3.2,13.74]],"ltp":11.5,"tv":33.86,"id":23806970}]}]}
{"op":"mcm","clk":"4211802927","pt":1631473550754,"mc":[{"id":"1.187552299","rc":[{"batl":[[0,1.3,1.45],[1,1.4,3.62],[2,1.5,72.3]],"ltp":1.09,"tv":10.0,"id":16100628}]}]}
{"op":"mcm","clk":"4211806251","pt":1631473579087,"mc":[{"id":"1.187552299","rc":[{"batb":[[0,1.03,9],[1,1.02,100],[2,1.01,12]],"ltp":1.09,"tv":10.0,"id":16100628}]}]}
{"op":"mcm","clk":"4211807974","pt":1631473593384,"mc":[{"id":"1.187552299","rc":[{"trd":[[1.03,18]],"batb":[[0,1.02,100],[1,1.01,12],[2,1.01,0]],"batl":[[0,1.03,4.78],[1,1.3,1.45],[2,1.4,3.62]],"ltp":1.03,"tv":28.0,"id":16100628}],"tv":61.86}]}
{"op":"mcm","clk":"4211808638","pt":1631473598905,"mc":[{"id":"1.187552299","rc":[{"batl":[[0,1.3,1.45],[1,1.4,3.62],[2,1.5,72.3]],"ltp":1.03,"tv":28.0,"id":16100628}]}]}
{"op":"mcm","clk":"4211809694","pt":1631473608114,"mc":[{"id":"1.187552299","rc":[{"batb":[[0,1.03,72.3],[1,1.02,100],[2,1.01,12]],"ltp":1.03,"tv":28.0,"id":16100628}]}]}
{"op":"mcm","clk":"4211810730","pt":1631473617536,"mc":[{"id":"1.187552299","rc":[{"trd":[[1.03,45.56]],"batb":[[0,1.03,58.52]],"ltp":1.03,"tv":55.55,"id":16100628}],"tv":89.42}]}
{"op":"mcm","clk":"4211811553","pt":1631473625045,"mc":[{"id":"1.187552299","rc":[{"batb":[[0,1.02,100],[1,1.01,12],[2,1.01,0]],"ltp":1.03,"tv":55.55,"id":16100628}]}]}
{"op":"mcm","clk":"4211813337","pt":1631473642655,"mc":[{"id":"1.187552299","rc":[{"batl":[[0,1.2,4],[1,1.3,1.45],[2,1.4,3.62]],"ltp":1.03,"tv":55.55,"id":16100628}]}]}
{"op":"mcm","clk":"4211813832","pt":1631473647794,"mc":[{"id":"1.187552299","rc":[{"trd":[[1.02,200]],"batb":[[0,1.01,12],[1,1.01,0]],"batl":[[0,1.02,113.51],[1,1.2,4],[2,1.3,1.45]],"ltp":1.02,"tv":255.55,"id":16100628}],"tv":289.42}]}
{"op":"mcm","clk":"4211814934","pt":1631473658222,"mc":[{"id":"1.187552299","rc":[{"trd":[[1.02,344.6]],"batl":[[0,1.02,41.21]],"ltp":1.02,"tv":400.16,"id":16100628}],"tv":434.03}]}
{"op":"mcm","clk":"4211816131","pt":1631473669621,"mc":[{"id":"1.187552299","rc":[{"batb":[[0,4,1.45],[1,3.2,13.01],[2,2.2,23.14]],"ltp":11.5,"tv":33.86,"id":23806970}]}]}
{"op":"mcm","clk":"4211816686","pt":1631473674750,"mc":[{"id":"1.187552299","rc":[{"batb":[[0,4.5,1.45],[1,3.2,13.74]],"ltp":11.5,"tv":33.86,"id":23806970}]}]}
{"op":"mcm","clk":"4211818251","pt":1631473689063,"mc":[{"id":"1.187552299","rc":[{"trd":[[1.02,427.02]],"batb":[[0,1.02,31.1],[1,1.01,12]],"batl":[[0,1.2,4],[1,1.3,1.45],[2,1.4,3.62]],"ltp":1.02,"tv":482.57,"id":16100628}],"tv":516.44}]}
{"op":"mcm","clk":"4211818591","pt":1631473692071,"mc":[{"id":"1.187552299","rc":[{"batb":[[0,1.01,12],[1,1.01,0]],"ltp":1.02,"tv":482.57,"id":16100628}]}]}
{"op":"mcm","clk":"4211819192","pt":1631473697479,"mc":[{"id":"1.187552299","rc":[{"batb":[[0,4,1.45],[1,3.2,13.01]],"ltp":11.5,"tv":33.86,"id":23806970}]}]}
{"op":"mcm","clk":"4211819801","pt":1631473703184,"mc":[{"id":"1.187552299","rc":[{"batb":[[0,1.01,84.3]],"ltp":1.02,"tv":482.57,"id":16100628}]}]}
{"op":"mcm","clk":"4211821915","pt":1631473722624,"mc":[{"id":"1.187552299","rc":[{"batb":[[0,1.01,316.39]],"ltp":1.02,"tv":482.57,"id":16100628}]}]}
{"op":"mcm","clk":"4211823694","pt":1631473738121,"mc":[{"id":"1.187552299","rc":[{"batl":[[0,1.19,72.3],[1,1.2,4],[2,1.3,1.45]],"ltp":1.02,"tv":482.57,"id":16100628}]}]}
{"op":"mcm","clk":"4211824843","pt":1631473748365,"mc":[{"id":"1.187552299","rc":[{"batl":[[1,1.3,1.45],[2,1.4,3.62]],"ltp":1.02,"tv":482.57,"id":16100628}]}]}
{"op":"mcm","clk":"4211825451","pt":1631473753437,"mc":[{"id":"1.187552299","rc":[{"batl":[[0,1.17,4],[1,1.19,72.3],[2,1.3,1.45]],"ltp":1.02,"tv":482.57,"id":16100628}]}]}
{"op":"mcm","clk":"4211826819","pt":1631473766186,"mc":[{"id":"1.187552299","rc":[{"batl":[[0,1.12,3.62],[1,1.17,4],[2,1.19,72.3]],"ltp":1.02,"tv":482.57,"id":16100628}]}]}
{"op":"mcm","clk":"4211828024","pt":1631473777684,"mc":[{"id":"1.187552299","rc":[{"batb":[[1,3.2,8.68]],"ltp":11.5,"tv":33.86,"id":23806970}]}]}
{"op":"mcm","clk":"4211828812","pt":1631473783012,"mc":[{"id":"1.187552299","rc":[{"batl":[[1,1.19,72.3],[2,1.3,1.45]],"ltp":1.02,"tv":482.57,"id":16100628}]}]}
{"op":"mcm","clk":"4211829446","pt":1631473787407,"mc":[{"id":"1.187552299","rc":[{"batl":[[0,1.19,72.3],[1,1.3,1.45],[2,1.4,3.62]],"ltp":1.02,"tv":482.57,"id":16100628}]}]}
{"op":"mcm","clk":"4211829519","pt":1631473788091,"mc":[{"id":"1.187552299","rc":[{"batl":[[0,1.1,4],[1,1.19,72.3],[2,1.3,1.45]],"ltp":1.02,"tv":482.57,"id":16100628}]}]}
{"op":"mcm","clk":"4211831320","pt":1631473804723,"mc":[{"id":"1.187552299","rc":[{"trd":[[1.01,4]],"batb":[[0,1.01,314.39]],"ltp":1.01,"tv":486.57,"id":16100628}],"tv":520.44}]}
{"op":"mcm","clk":"4211844185","pt":1631473913634,"mc":[{"id":"1.187552299","rc":[{"batl":[[1,1.3,1.45],[2,1.4,3.62]],"ltp":1.01,"tv":486.57,"id":16100628}]}]}
{"op":"mcm","clk":"4211844376","pt":1631473915239,"mc":[{"id":"1.187552299","rc":[{"trd":[[1.01,38]],"batb":[[0,1.01,297.39]],"ltp":1.01,"tv":520.57,"id":16100628}],"tv":554.44}]}
{"op":"mcm","clk":"4211845444","pt":1631473924629,"mc":[{"id":"1.187552299","rc":[{"batb":[[0,3.2,8.68],[1,2.2,23.14],[2,1.55,7.23]],"ltp":11.5,"tv":33.86,"id":23806970}]}]}
{"op":"mcm","clk":"4211845521","pt":1631473925222,"mc":[{"id":"1.187552299","rc":[{"batb":[[0,2.2,23.14],[1,1.55,7.23],[2,1.5,7.26]],"ltp":11.5,"tv":33.86,"id":23806970}]}]}
{"op":"mcm","clk":"4211845883","pt":1631473928623,"mc":[{"id":"1.187552299","rc":[{"batl":[[0,1.3,1.45],[1,1.4,3.62],[2,1.5,72.3]],"ltp":1.01,"tv":520.57,"id":16100628}]}]}
{"op":"mcm","clk":"4211846434","pt":1631473934172,"mc":[{"id":"1.187552299","rc":[{"batb":[[0,1.02,17.35],[1,1.01,297.39]],"ltp":1.01,"tv":520.57,"id":16100628}]}]}
{"op":"mcm","clk":"4211847808","pt":1631473947977,"mc":[{"id":"1.187552299","rc":[{"batb":[[0,3.1,2.17],[1,2.2,23.14],[2,1.55,7.23]],"ltp":11.5,"tv":33.86,"id":23806970}]}]}
{"op":"mcm","clk":"4211848843","pt":1631473958314,"mc":[{"id":"1.187552299","rc":[{"batl":[[0,1.3,4.45]],"ltp":1.01,"tv":520.57,"id":16100628}]}]}
{"op":"mcm","clk":"4211850417","pt":1631473973923,"mc":[{"id":"1.187552299","rc":[{"batb":[[0,1.03,232.09],[1,1.02,17.35],[2,1.01,297.39]],"ltp":1.01,"tv":520.57,"id":16100628},{"batb":[[0,2.2,23.14],[1,1.55,7.23],[2,1.5,7.26]],"ltp":11.5,"tv":33.86,"id":23806970}]}]}
{"op":"mcm","clk":"4211850621","pt":1631473975780,"mc":[{"id":"1.187552299","rc":[{"batb":[[0,1.03,242.93]],"ltp":1.01,"tv":520.57,"id":16100628}]}]}
{"op":"mcm","clk":"4211851002","pt":1631473979839,"mc":[{"id":"1.187552299","rc":[{"batb":[[0,2.2,13.01]],"ltp":11.5,"tv":33.86,"id":23806970}]}]}
{"op":"mcm","clk":"4211851540","pt":1631473985329,"mc":[{"id":"1.187552299","rc":[{"trd":[[1.3,4.45],[1.4,3.62]],"batl":[[0,1.5,72.3],[1,1.4,0],[2,1.5,0]],"ltp":1.4,"tv":528.63,"id":16100628},{"trd":[[3.5,1.45],[4.3,1.34]],"batl":[[0,3.4,47.21]],"ltp":3.5,"tv":36.65,"id":23806970}],"tv":565.29}]}
{"op":"mcm","clk":"4211851934","pt":1631473989433,"mc":[{"id":"1.187552299","rc":[{"batb":[[0,1.04,10.85],[1,1.03,242.93],[2,1.02,17.35]],"ltp":1.4,"tv":528.63,"id":16100628}]}]}
{"op":"mcm","clk":"4211852482","pt":1631473994842,"mc":[{"id":"1.187552299","rc":[{"trd":[[3.4,94.4]],"batb":[[0,3.4,29.36],[1,2.2,13.01],[2,1.55,7.23]],"ltp":3.4,"tv":131.06,"id":23806970}],"tv":659.69}]}
{"op":"mcm","clk":"4211852586","pt":1631473995841,"mc":[{"id":"1.187552299","rc":[{"batb":[[0,3.4,215.81]],"ltp":3.4,"tv":131.06,"id":23806970}]}]}
{"op":"mcm","clk":"4211852715","pt":1631473996837,"mc":[{"id":"1.187552299","rc":[{"batl":[[0,1.41,132.87],[1,1.5,72.3]],"ltp":1.4,"tv":528.63,"id":16100628},{"batb":[[0,3.4,173.28]],"ltp":3.4,"tv":131.06,"id":23806970}]}]}
{"op":"mcm","clk":"4211852802","pt":1631473997779,"mc":[{"id":"1.187552299","rc":[{"batl":[[0,1.41,72.3]],"ltp":1.4,"tv":528.63,"id":16100628},{"batb":[[0,3.4,37.04]],"ltp":3.4,"tv":131.06,"id":23806970}]}]}
{"op":"mcm","clk":"4211852908","pt":1631473998846,"mc":[{"id":"1.187552299","rc":[{"batb":[[0,3.4,90.65]],"ltp":3.4,"tv":131.06,"id":23806970}]}]}
{"op":"mcm","clk":"4211853020","pt":1631473999844,"mc":[{"id":"1.187552299","rc":[{"batb":[[0,3.4,137.39]],"ltp":3.4,"tv":131.06,"id":23806970}]}]}
{"op":"mcm","clk":"4211853120","pt":1631474000750,"mc":[{"id":"1.187552299","rc":[{"batl":[[0,1.41,144.6]],"ltp":1.4,"tv":528.63,"id":16100628},{"batb":[[0,3.4,33.94]],"ltp":3.4,"tv":131.06,"id":23806970}]}]}
{"op":"mcm","clk":"4211853206","pt":1631474001643,"mc":[{"id":"1.187552299","rc":[{"batb":[[0,2.2,13.01],[1,1.55,7.23],[2,1.5,7.26]],"ltp":3.4,"tv":131.06,"id":23806970}]}]}
{"op":"mcm","clk":"4211853335","pt":1631474002847,"mc":[{"id":"1.187552299","rc":[{"batb":[[0,3.4,4.95],[1,2.2,13.01],[2,1.55,7.23]],"ltp":3.4,"tv":131.06,"id":23806970}]}]}
{"op":"mcm","clk":"4211853370","pt":1631474003151,"mc":[{"id":"1.187552299","rc":[{"batb":[[0,2.2,13.01],[1,1.55,7.23],[2,1.5,7.26]],"ltp":3.4,"tv":131.06,"id":23806970}]}]}
{"op":"mcm","clk":"4211853460","pt":1631474004054,"mc":[{"id":"1.187552299","rc":[{"batb":[[0,1.03,242.93],[1,1.02,17.35],[2,1.01,297.39]],"ltp":1.4,"tv":528.63,"id":16100628}]}]}
{"op":"mcm","clk":"4211853629","pt":1631474005787,"mc":[{"id":"1.187552299","rc":[{"batl":[[0,1.35,72.3],[1,1.41,144.6],[2,1.5,72.3]],"ltp":1.4,"tv":528.63,"id":16100628}]}]}
{"op":"mcm","clk":"4211853712","pt":1631474006575,"mc":[{"id":"1.187552299","rc":[{"batl":[[1,1.39,7.95],[2,1.41,144.6]],"ltp":1.4,"tv":528.63,"id":16100628}]}]}
{"op":"mcm","clk":"4211854070","pt":1631474010297,"mc":[{"id":"1.187552299","rc":[{"batl":[[1,1.41,144.6],[2,1.5,72.3]],"ltp":1.4,"tv":528.63,"id":16100628}]}]}
{"op":"mcm","clk":"4211854592","pt":1631474015368,"mc":[{"id":"1.187552299","rc":[{"batl":[[0,1.34,7.95],[1,1.35,72.3],[2,1.41,144.6]],"ltp":1.4,"tv":528.63,"id":16100628}]}]}
{"op":"mcm","clk":"4211854794","pt":1631474017576,"mc":[{"id":"1.187552299","rc":[{"batl":[[2,1.41,72.3]],"ltp":1.4,"tv":528.63,"id":16100628}]}]}
{"op":"mcm","clk":"4211854878","pt":1631474018418,"mc":[{"id":"1.187552299","rc":[{"batl":[[0,1.34,6.51]],"ltp":1.4,"tv":528.63,"id":16100628}]}]}
{"op":"mcm","clk":"4211855085","pt":1631474020624,"mc":[{"id":"1.187552299","rc":[{"batl":[[1,1.41,72.3],[2,1.5,72.3]],"ltp":1.4,"tv":528.63,"id":16100628}]}]}
{"op":"mcm","clk":"4211855600","pt":1631474025728,"mc":[{"id":"1.187552299","rc":[{"batl":[[0,1.32,72.3],[1,1.34,6.51]],"ltp":1.4,"tv":528.63,"id":16100628}]}]}
{"op":"mcm","clk":"4211855790","pt":1631474027823,"mc":[{"id":"1.187552299","rc":[{"batl":[[1,1.5,72.3],[2,1.5,0]],"ltp":1.4,"tv":528.63,"id":16100628}]}]}
{"op":"mcm","clk":"4211856179","pt":1631474031654,"mc":[{"id":"1.187552299","rc":[{"batb":[[0,4,20],[1,2.2,13.01],[2,1.55,7.23]],"ltp":3.4,"tv":131.06,"id":23806970}]}]}
{"op":"mcm","clk":"4211856388","pt":1631474033549,"mc":[{"id":"1.187552299","rc":[{"batb":[[0,1.03,10.85]],"ltp":1.4,"tv":528.63,"id":16100628}]}]}
{"op":"mcm","clk":"4211856465","pt":1631474034236,"mc":[{"id":"1.187552299","rc":[{"batb":[[0,2.2,13.01],[1,1.55,7.23],[2,1.5,7.26]],"ltp":3.4,"tv":131.06,"id":23806970}]}]}
{"op":"mcm","clk":"4211857051","pt":1631474039381,"mc":[{"id":"1.187552299","rc":[{"batb":[[0,4.2,20],[1,2.2,13.01],[2,1.55,7.23]],"ltp":3.4,"tv":131.06,"id":23806970}]}]}
{"op":"mcm","clk":"4211857495","pt":1631474043281,"mc":[{"id":"1.187552299","rc":[{"batb":[[0,1.02,17.35],[1,1.01,297.39],[2,1.01,0]],"ltp":1.4,"tv":528.63,"id":16100628}]}]}
{"op":"mcm","clk":"4211857854","pt":1631474046394,"mc":[{"id":"1.187552299","rc":[{"batl":[[0,1.3,10.85],[1,1.32,72.3],[2,1.5,72.3]],"ltp":1.4,"tv":528.63,"id":16100628}]}]}
{"op":"mcm","clk":"4211858769","pt":1631474055101,"mc":[{"id":"1.187552299","rc":[{"batl":[[0,1.25,72.3],[1,1.3,10.85],[2,1.32,72.3]],"ltp":1.4,"tv":528.63,"id":16100628}]}]}
{"op":"mcm","clk":"4211859553","pt":1631474062645,"mc":[{"id":"1.187552299","rc":[{"batl":[[0,1.3,10.85],[1,1.32,72.3],[2,1.5,72.3]],"ltp":1.4,"tv":528.63,"id":16100628}]}]}
{"op":"mcm","clk":"4211859932","pt":1631474066446,"mc":[{"id":"1.187552299","rc":[{"batl":[[0,1.23,5.78],[1,1.3,10.85],[2,1.32,72.3]],"ltp":1.4,"tv":528.63,"id":16100628}]}]}
{"op":"mcm","clk":"4211860065","pt":1631474067731,"mc":[{"id":"1.187552299","rc":[{"batl":[[0,1.3,10.85],[1,1.32,72.3],[2,1.5,72.3]],"ltp":1.4,"tv":528.63,"id":16100628}]}]}
{"op":"mcm","clk":"4211860140","pt":1631474068366,"mc":[{"id":"1.187552299","rc":[{"batl":[[0,1.32,72.3],[1,1.5,72.3],[2,1.5,0]],"ltp":1.4,"tv":528.63,"id":16100628}]}]}
{"op":"mcm","clk":"4211860596","pt":1631474072654,"mc":[{"id":"1.187552299","rc":[{"batb":[[0,1.03,232.09],[1,1.02,17.35],[2,1.01,297.39]],"ltp":1.4,"tv":528.63,"id":16100628}]}]}
{"op":"mcm","clk":"4211860851","pt":1631474074972,"mc":[{"id":"1.187552299","rc":[{"batl":[[1,1.5,0]],"ltp":1.4,"tv":528.63,"id":16100628}]}]}
{"op":"mcm","clk":"4211861137","pt":1631474077457,"mc":[{"id":"1.187552299","rc":[{"batb":[[0,1.04,10.85],[1,1.03,232.09],[2,1.02,17.35]],"ltp":1.4,"tv":528.63,"id":16100628}]}]}
{"op":"mcm","clk":"4211863435","pt":1631474098861,"mc":[{"id":"1.187552299","rc":[{"batl":[[0,1.7,72.3]],"ltp":1.4,"tv":528.63,"id":16100628}]}]}
{"op":"mcm","clk":"4211864411","pt":1631474107949,"mc":[{"id":"1.187552299","rc":[{"batb":[[0,1.05,232.09],[1,1.04,10.85],[2,1.03,232.09]],"ltp":1.4,"tv":528.63,"id":16100628}]}]}
{"op":"mcm","clk":"4211864843","pt":1631474112026,"mc":[{"id":"1.187552299","rc":[{"batb":[[0,1.08,10.85],[1,1.05,232.09],[2,1.04,10.85]],"ltp":1.4,"tv":528.63,"id":16100628}]}]}
{"op":"mcm","clk":"4211870443","pt":1631474164402,"mc":[{"id":"1.187552299","rc":[{"trd":[[4.2,16.74]],"batb":[[0,4.2,11.63]],"ltp":4.2,"tv":147.8,"id":23806970}],"tv":676.44}]}
{"op":"mcm","clk":"4211870854","pt":1631474168662,"mc":[{"id":"1.187552299","rc":[{"batl":[[0,1.3,3.62],[1,1.7,72.3]],"ltp":1.4,"tv":528.63,"id":16100628}]}]}
{"op":"mcm","clk":"4211875168","pt":1631474207924,"mc":[{"id":"1.187552299","rc":[{"batb":[[1,1.04,10.85],[2,1.03,232.09]],"ltp":1.4,"tv":528.63,"id":16100628}]}]}
{"op":"mcm","clk":"4211876332","pt":1631474217819,"mc":[{"id":"1.187552299","rc":[{"batl":[[0,1.3,75.92]],"ltp":1.4,"tv":528.63,"id":16100628}]}]}
{"op":"mcm","clk":"4211877100","pt":1631474224365,"mc":[{"id":"1.187552299","rc":[{"batl":[[0,1.16,12.29],[1,1.3,75.92],[2,1.7,72.3]],"ltp":1.4,"tv":528.63,"id":16100628}]}]}
{"op":"mcm","clk":"4211877568","pt":1631474228053,"mc":[{"id":"1.187552299","rc":[{"batb":[[2,1.02,17.35]],"ltp":1.4,"tv":528.63,"id":16100628}]}]}
{"op":"mcm","clk":"4211880413","pt":1631474251776,"mc":[{"id":"1.187552299","rc":[{"batl":[[1,1.3,3.62]],"ltp":1.4,"tv":528.63,"id":16100628},{"batl":[[0,1000,1.97]],"ltp":4.2,"tv":147.8,"id":23806970}]}]}
{"op":"mcm","clk":"4211881086","pt":1631474257191,"mc":[{"id":"1.187552299","rc":[{"trd":[[1.16,12.25]],"batl":[[0,1.3,3.66],[1,1.7,72.3],[2,1.7,0]],"ltp":1.16,"tv":540.88,"id":16100628},{"trd":[[7.2,1.97]],"ltp":7.2,"tv":149.77,"id":23806970}],"tv":690.66}]}
{"op":"mcm","clk":"4211890389","pt":1631474279730,"mc":[{"id":"1.187552299","rc":[{"batb":[[0,1.1,72.3],[1,1.08,10.85],[2,1.04,10.85]],"ltp":1.16,"tv":540.88,"id":16100628}]}]}
{"op":"mcm","clk":"4211890484","pt":1631474280519,"mc":[{"id":"1.187552299","rc":[{"trd":[[1.16,12.33],[1.3,11.67],[1.32,37]],"batl":[[0,1.7,72.3],[1,1.7,0]],"ltp":1.32,"tv":585.19,"id":16100628},{"trd":[[4.2,28.37]],"batb":[[0,2.2,13.01],[1,1.55,7.23],[2,1.5,7.26]],"ltp":4.2,"tv":161.4,"id":23806970}],"tv":746.6}]}
{"op":"mcm","clk":"4211892050","pt":1631474294191,"mc":[{"id":"1.187552299","rc":[{"batb":[[0,1.12,15.91],[1,1.1,72.3],[2,1.08,10.85]],"ltp":1.32,"tv":585.19,"id":16100628},{"batb":[[0,1.55,7.23],[1,1.5,7.26],[2,1.48,10.85]],"ltp":4.2,"tv":161.4,"id":23806970}]}]}
{"op":"mcm","clk":"4211892454","pt":1631474297548,"mc":[{"id":"1.187552299","rc":[{"batb":[[0,2.46,8.68],[1,1.55,7.23],[2,1.5,7.26]],"ltp":4.2,"tv":161.4,"id":23806970}]}]}
{"op":"mcm","clk":"4211892719","pt":1631474299922,"mc":[{"id":"1.187552299","rc":[{"batl":[[0,1.4,3.62],[1,1.7,72.3]],"ltp":1.32,"tv":585.19,"id":16100628}]}]}
{"op":"mcm","clk":"4211893925","pt":1631474310875,"mc":[{"id":"1.187552299","rc":[{"batl":[[0,1.32,23.86],[1,1.4,3.62],[2,1.7,72.3]],"ltp":1.32,"tv":585.19,"id":16100628}]}]}
{"op":"mcm","clk":"4211894470","pt":1631474315870,"mc":[{"id":"1.187552299","rc":[{"batb":[[1,1.08,10.85],[2,1.04,10.85]],"ltp":1.32,"tv":585.19,"id":16100628}]}]}
{"op":"mcm","clk":"4211895826","pt":1631474328071,"mc":[{"id":"1.187552299","rc":[{"batb":[[0,1.08,10.85],[1,1.04,10.85],[2,1.02,17.35]],"ltp":1.32,"tv":585.19,"id":16100628}]}]}
{"op":"mcm","clk":"4211896361","pt":1631474332801,"mc":[{"id":"1.187552299","rc":[{"batl":[[0,1.4,3.62],[1,1.7,72.3],[2,1.7,0]],"ltp":1.32,"tv":585.19,"id":16100628}]}]}
{"op":"mcm","clk":"4211897498","pt":1631474342988,"mc":[{"id":"1.187552299","rc":[{"batb":[[0,1.09,72.3],[1,1.08,10.85],[2,1.04,10.85]],"ltp":1.32,"tv":585.19,"id":16100628}]}]}
{"op":"mcm","clk":"4211898445","pt":1631474351441,"mc":[{"id":"1.187552299","rc":[{"batb":[[0,1.12,11.57],[1,1.09,72.3],[2,1.08,10.85]],"ltp":1.32,"tv":585.19,"id":16100628}]}]}
{"op":"mcm","clk":"4211900495","pt":1631474370049,"mc":[{"id":"1.187552299","rc":[{"batl":[[1,1.7,0]],"ltp":1.32,"tv":585.19,"id":16100628}]}]}
{"op":"mcm","clk":"4211900593","pt":1631474370939,"mc":[{"id":"1.187552299","rc":[{"batl":[[1,1.5,23.86]],"ltp":1.32,"tv":585.19,"id":16100628}]}]}
{"op":"mcm","clk":"4211901100","pt":1631474375171,"mc":[{"id":"1.187552299","rc":[{"batl":[[2,2.4,72.3]],"ltp":1.32,"tv":585.19,"id":16100628}]}]}
{"op":"mcm","clk":"4211903097","pt":1631474392268,"mc":[{"id":"1.187552299","rc":[{"batb":[[0,1.09,72.3],[1,1.08,10.85],[2,1.04,10.85]],"ltp":1.32,"tv":585.19,"id":16100628}]}]}
{"op":"mcm","clk":"4211903661","pt":1631474396631,"mc":[{"id":"1.187552299","rc":[{"batb":[[1,1.04,10.85],[2,1.02,17.35]],"ltp":1.32,"tv":585.19,"id":16100628}]}]}
{"op":"mcm","clk":"4211904764","pt":1631474405012,"mc":[{"id":"1.187552299","rc":[{"trd":[[1.4,7.23],[1.5,1.45]],"batl":[[0,1.5,22.41],[1,2.4,72.3],[2,2.4,0]],"ltp":1.5,"tv":590.25,"id":16100628},{"trd":[[3,0.72],[3.5,2.9]],"ltp":3.0,"tv":163.57,"id":23806970}],"tv":753.83}]}
{"op":"mcm","clk":"4211905910","pt":1631474414144,"mc":[{"id":"1.187552299","rc":[{"batb":[[0,1.04,10.85],[1,1.02,17.35],[2,1.01,297.39]],"ltp":1.5,"tv":590.25,"id":16100628}]}]}
{"op":"mcm","clk":"4211906594","pt":1631474419828,"mc":[{"id":"1.187552299","rc":[{"batl":[[2,1000,2.17]],"ltp":1.5,"tv":590.25,"id":16100628}]}]}
{"op":"mcm","clk":"4211906706","pt":1631474420831,"mc":[{"id":"1.187552299","rc":[{"batl":[[2,1000,0]],"ltp":1.5,"tv":590.25,"id":16100628}]}]}
{"op":"mcm","clk":"4211907309","pt":1631474425955,"mc":[{"id":"1.187552299","rc":[{"batl":[[0,1.4,72.3],[1,1.46,1.45],[2,1.5,22.41]],"ltp":1.5,"tv":590.25,"id":16100628}]}]}
{"op":"mcm","clk":"4211907480","pt":1631474427534,"mc":[{"id":"1.187552299","rc":[{"batb":[[1,1.74,18.08],[2,1.55,7.23]],"ltp":3.0,"tv":163.57,"id":23806970}]}]}
{"op":"mcm","clk":"4211908683","pt":1631474437477,"mc":[{"id":"1.187552299","rc":[{"batl":[[0,1.38,5.06],[1,1.4,72.3],[2,1.46,1.45]],"ltp":1.5,"tv":590.25,"id":16100628}]}]}
{"op":"mcm","clk":"4211911096","pt":1631474457889,"mc":[{"id":"1.187552299","rc":[{"batb":[[0,1.05,72.3],[1,1.04,10.85],[2,1.02,17.35]],"batl":[[0,1.4,72.3],[1,1.46,1.45],[2,1.5,22.41]],"ltp":1.5,"tv":590.25,"id":16100628}]}]}
{"op":"mcm","clk":"4211911108","pt":1631474457997,"mc":[{"id":"1.187552299","rc":[{"batl":[[1,1.5,22.41],[2,2.4,72.3]],"ltp":1.5,"tv":590.25,"id":16100628}]}]}
{"op":"mcm","clk":"4211911434","pt":1631474460797,"mc":[{"id":"1.187552299","rc":[{"batb":[[1,1.74,10.85]],"ltp":3.0,"tv":163.57,"id":23806970}]}]}
{"op":"mcm","clk":"4211912538","pt":1631474470015,"mc":[{"id":"1.187552299","rc":[{"batl":[[0,1.5,22.41],[1,2.4,72.3],[2,2.4,0]],"ltp":1.5,"tv":590.25,"id":16100628}]}]}
{"op":"mcm","clk":"4211914948","pt":1631474489486,"mc":[{"id":"1.187552299","rc":[{"batb":[[0,1.1,72.3],[1,1.05,72.3],[2,1.04,10.85]],"ltp":1.5,"tv":590.25,"id":16100628}]}]}
{"op":"mcm","clk":"4211917714","pt":1631474514010,"mc":[{"id":"1.187552299","rc":[{"batb":[[0,1.05,72.3],[1,1.04,10.85],[2,1.02,17.35]],"ltp":1.5,"tv":590.25,"id":16100628}]}]}
{"op":"mcm","clk":"4211918966","pt":1631474525031,"mc":[{"id":"1.187552299","rc":[{"batl":[[0,1.5,94.71]],"ltp":1.5,"tv":590.25,"id":16100628}]}]}
{"op":"mcm","clk":"4211923674","pt":1631474564486,"mc":[{"id":"1.187552299","rc":[{"batb":[[0,1.08,17.35],[1,1.05,72.3],[2,1.04,10.85]],"ltp":1.5,"tv":590.25,"id":16100628}]}]}
{"op":"mcm","clk":"4211923992","pt":1631474567174,"mc":[{"id":"1.187552299","rc":[{"batl":[[0,1.5,22.41]],"ltp":1.5,"tv":590.25,"id":16100628}]}]}
{"op":"mcm","clk":"4211924315","pt":1631474569797,"mc":[{"id":"1.187552299","rc":[{"batb":[[0,1.74,10.85],[1,1.55,7.23],[2,1.5,7.26]],"ltp":3.0,"tv":163.57,"id":23806970}]}]}
{"op":"mcm","clk":"4211925379","pt":1631474577927,"mc":[{"id":"1.187552299","rc":[{"batl":[[1,1.67,72.3],[2,2.4,72.3]],"ltp":1.5,"tv":590.25,"id":16100628}]}]}
{"op":"mcm","clk":"4211926072","pt":1631474583321,"mc":[{"id":"1.187552299","rc":[{"batb":[[0,1.1,72.3],[1,1.08,17.35],[2,1.05,72.3]],"ltp":1.5,"tv":590.25,"id":16100628}]}]}
{"op":"mcm","clk":"4211926182","pt":1631474584160,"mc":[{"id":"1.187552299","rc":[{"batb":[[0,1.15,11.57],[1,1.1,72.3],[2,1.08,17.35]],"ltp":1.5,"tv":590.25,"id":16100628}]}]}
{"op":"mcm","clk":"4211926436","pt":1631474586157,"mc":[{"id":"1.187552299","rc":[{"batl":[[1,2.4,72.3],[2,2.4,0]],"ltp":1.5,"tv":590.25,"id":16100628}]}]}
{"op":"mcm","clk":"4211926993","pt":1631474591257,"mc":[{"id":"1.187552299","rc":[{"batl":[[1,1.95,72.3],[2,2.4,72.3]],"ltp":1.5,"tv":590.25,"id":16100628}]}]}
{"op":"mcm","clk":"4211938113","pt":1631474690515,"mc":[{"id":"1.187552299","rc":[{"batl":[[0,1.95,72.3],[1,2.4,72.3],[2,2.4,0]],"ltp":1.5,"tv":590.25,"id":16100628}]}]}
{"op":"mcm","clk":"4211938679","pt":1631474695594,"mc":[{"id":"1.187552299","rc":[{"batl":[[0,1.62,22.41],[1,1.95,72.3],[2,2.4,72.3]],"ltp":1.5,"tv":590.25,"id":16100628}]}]}
{"op":"mcm","clk":"4211938735","pt":1631474696114,"mc":[{"id":"1.187552299","rc":[{"batl":[[2,2.4,0]],"ltp":1.5,"tv":590.25,"id":16100628}]}]}
{"op":"mcm","clk":"4211941435","pt":1631474718666,"mc":[{"id":"1.187552299","rc":[{"batb":[[0,1.16,72.3],[1,1.15,11.57],[2,1.1,72.3]],"ltp":1.5,"tv":590.25,"id":16100628}]}]}
{"op":"mcm","clk":"4211945076","pt":1631474748986,"mc":[{"id":"1.187552299","rc":[{"batb":[[0,1.18,17.35],[1,1.16,72.3],[2,1.15,11.57]],"ltp":1.5,"tv":590.25,"id":16100628}]}]}
{"op":"mcm","clk":"4211945656","pt":1631474753999,"mc":[{"id":"1.187552299","rc":[{"batb":[[0,1.18,14.46]],"ltp":1.5,"tv":590.25,"id":16100628}]}]}
{"op":"mcm","clk":"4211945799","pt":1631474755324,"mc":[{"id":"1.187552299","rc":[{"batb":[[2,1.1,72.3]],"ltp":1.5,"tv":590.25,"id":16100628}]}]}
{"op":"mcm","clk":"4211946968","pt":1631474765017,"mc":[{"id":"1.187552299","rc":[{"trd":[[1.18,17.82]],"batb":[[0,1.18,5.55]],"ltp":1.18,"tv":608.07,"id":16100628}],"tv":771.64}]}
{"op":"mcm","clk":"4211947899","pt":1631474772507,"mc":[{"id":"1.187552299","rc":[{"batb":[[1,1.1,72.3],[2,1.08,17.35]],"ltp":1.18,"tv":608.07,"id":16100628}]}]}
{"op":"mcm","clk":"4211949080","pt":1631474781822,"mc":[{"id":"1.187552299","rc":[{"batb":[[2,1.48,10.85]],"ltp":3.0,"tv":163.57,"id":23806970}]}]}
{"op":"mcm","clk":"4211949831","pt":1631474787797,"mc":[{"id":"1.187552299","rc":[{"batb":[[0,1.1,72.3],[1,1.08,17.35],[2,1.05,72.3]],"ltp":1.18,"tv":608.07,"id":16100628}]}]}
{"op":"mcm","clk":"4211949993","pt":1631474789022,"mc":[{"id":"1.187552299","rc":[{"batl":[[0,1.34,5.78],[1,1.62,22.41],[2,1.95,72.3]],"ltp":1.18,"tv":608.07,"id":16100628}]}]}
{"op":"mcm","clk":"4211950481","pt":1631474793128,"mc":[{"id":"1.187552299","rc":[{"batb":[[0,1.14,5.55],[1,1.1,72.3],[2,1.08,17.35]],"ltp":1.18,"tv":608.07,"id":16100628}]}]}
{"op":"mcm","clk":"4211952309","pt":1631474808708,"mc":[{"id":"1.187552299","rc":[{"batb":[[0,1.15,72.3],[1,1.14,5.55],[2,1.1,72.3]],"ltp":1.18,"tv":608.07,"id":16100628}]}]}
{"op":"mcm","clk":"4211956812","pt":1631474849890,"mc":[{"id":"1.187552299","rc":[{"trd":[[1.34,11.57]],"batb":[[0,1.34,66.52],[1,1.15,72.3],[2,1.14,5.55]],"batl":[[0,1.62,22.41],[1,1.95,72.3],[2,1.95,0]],"ltp":1.34,"tv":619.64,"id":16100628}],"tv":783.21}]}
{"op":"mcm","clk":"4211956986","pt":1631474851887,"mc":[{"id":"1.187552299","rc":[{"batl":[[0,3.9,7.04]],"ltp":3.0,"tv":163.57,"id":23806970}]}]}
{"op":"mcm","clk":"4211957045","pt":1631474852567,"mc":[{"id":"1.187552299","rc":[{"trd":[[1.62,14.48]],"batb":[[1,1.18,5.78],[2,1.15,72.3]],"batl":[[0,1.62,7.93]],"ltp":1.62,"tv":634.12,"id":16100628},{"trd":[[2.6,9.02]],"ltp":2.6,"tv":172.59,"id":23806970}],"tv":806.72}]}
{"op":"mcm","clk":"4211957174","pt":1631474853989,"mc":[{"id":"1.187552299","rc":[{"batb":[[0,1.18,5.78],[1,1.15,72.3],[2,1.1,72.3]],"ltp":1.62,"tv":634.12,"id":16100628}]}]}
{"op":"mcm","clk":"4211957332","pt":1631474855561,"mc":[{"id":"1.187552299","rc":[{"batb":[[0,1.55,7.23],[1,1.48,10.85],[2,1.01,12]],"ltp":2.6,"tv":172.59,"id":23806970}]}]}
{"op":"mcm","clk":"4211957472","pt":1631474857093,"mc":[{"id":"1.187552299","rc":[{"batb":[[2,1.12,5.55]],"ltp":1.62,"tv":634.12,"id":16100628}]}]}
{"op":"mcm","clk":"4211958394","pt":1631474867478,"mc":[{"id":"1.187552299","rc":[{"batl":[[2,1000,2.17]],"ltp":1.62,"tv":634.12,"id":16100628}]}]}
{"op":"mcm","clk":"4211958479","pt":1631474868515,"mc":[{"id":"1.187552299","rc":[{"batl":[[2,1000,0]],"ltp":1.62,"tv":634.12,"id":16100628}]}]}
{"op":"mcm","clk":"4211958761","pt":1631474871401,"mc":[{"id":"1.187552299","rc":[{"batl":[[0,1.62,31.79],[1,1.95,0]],"ltp":1.62,"tv":634.12,"id":16100628}]}]}
{"op":"mcm","clk":"4211958948","pt":1631474873594,"mc":[{"id":"1.187552299","rc":[{"batl":[[0,1.62,32.51]],"ltp":1.62,"tv":634.12,"id":16100628}]}]}
{"op":"mcm","clk":"4211960386","pt":1631474890010,"mc":[{"id":"1.187552299","rc":[{"batl":[[1,2.6,72.3]],"ltp":1.62,"tv":634.12,"id":16100628}]}]}
{"op":"mcm","clk":"4211962008","pt":1631474907560,"mc":[{"id":"1.187552299","rc":[{"batb":[[0,1.64,10.85],[1,1.55,7.23],[2,1.48,10.85]],"ltp":2.6,"tv":172.59,"id":23806970}]}]}
{"op":"mcm","clk":"4211963033","pt":1631474918676,"mc":[{"id":"1.187552299","rc":[{"batl":[[0,1.62,31.79]],"ltp":1.62,"tv":634.12,"id":16100628}]}]}
{"op":"mcm","clk":"4211963484","pt":1631474923765,"mc":[{"id":"1.187552299","rc":[{"batl":[[0,1.62,32.51]],"ltp":1.62,"tv":634.12,"id":16100628}]}]}
{"op":"mcm","clk":"4211964753","pt":1631474938178,"mc":[{"id":"1.187552299","rc":[{"batl":[[0,1.62,28.9]],"ltp":1.62,"tv":634.12,"id":16100628}]}]}
{"op":"mcm","clk":"4211965200","pt":1631474943187,"mc":[{"id":"1.187552299","rc":[{"batl":[[0,1.62,26.01]],"ltp":1.62,"tv":634.12,"id":16100628}]}]}
{"op":"mcm","clk":"4211965714","pt":1631474949413,"mc":[{"id":"1.187552299","rc":[{"batl":[[0,1.47,222],[1,1.62,22.39],[2,2.6,72.3]],"ltp":1.62,"tv":634.12,"id":16100628}]}]}
{"op":"mcm","clk":"4211966412","pt":1631474956854,"mc":[{"id":"1.187552299","rc":[{"batl":[[0,1.62,22.39],[1,2.6,72.3],[2,2.6,0]],"ltp":1.62,"tv":634.12,"id":16100628}]}]}
{"op":"mcm","clk":"4211967138","pt":1631474965037,"mc":[{"id":"1.187552299","rc":[{"batb":[[0,1.2,72.3],[1,1.18,5.78],[2,1.15,72.3]],"ltp":1.62,"tv":634.12,"id":16100628}]}]}
{"op":"mcm","clk":"4211967566","pt":1631474970042,"mc":[{"id":"1.187552299","rc":[{"batb":[[0,1.21,222],[1,1.2,72.3],[2,1.18,5.78]],"ltp":1.62,"tv":634.12,"id":16100628}]}]}
{"op":"mcm","clk":"4211967927","pt":1631474974046,"mc":[{"id":"1.187552299","rc":[{"batb":[[1,1.2,144.6]],"batl":[[0,1.62,21.67]],"ltp":1.62,"tv":634.12,"id":16100628}]}]}
{"op":"mcm","clk":"4211968404","pt":1631474979132,"mc":[{"id":"1.187552299","rc":[{"batl":[[0,1.62,22.39]],"ltp":1.62,"tv":634.12,"id":16100628}]}]}
{"op":"mcm","clk":"4211968487","pt":1631474980029,"mc":[{"id":"1.187552299","rc":[{"batb":[[0,1.25,72.3],[1,1.21,222],[2,1.2,144.6]],"ltp":1.62,"tv":634.12,"id":16100628}]}]}
{"op":"mcm","clk":"4211968667","pt":1631474981862,"mc":[{"id":"1.187552299","rc":[{"batb":[[0,1.64,5.78]],"ltp":2.6,"tv":172.59,"id":23806970}]}]}
{"op":"mcm","clk":"4211968834","pt":1631474983659,"mc":[{"id":"1.187552299","rc":[{"batb":[[1,1.48,10.85],[2,1.01,12]],"ltp":2.6,"tv":172.59,"id":23806970}]}]}
{"op":"mcm","clk":"4211969083","pt":1631474986347,"mc":[{"id":"1.187552299","rc":[{"batl":[[0,2.6,73.02],[1,2.6,0]],"ltp":1.62,"tv":634.12,"id":16100628}]}]}
{"op":"mcm","clk":"4211969554","pt":1631474991338,"mc":[{"id":"1.187552299","rc":[{"batl":[[0,2.6,72.3]],"ltp":1.62,"tv":634.12,"id":16100628}]}]}
{"op":"mcm","clk":"4211969706","pt":1631474992968,"mc":[{"id":"1.187552299","rc":[{"batl":[[0,2.6,6.16]],"ltp":2.6,"tv":172.59,"id":23806970}]}]}
{"op":"mcm","clk":"4211970148","pt":1631474997752,"mc":[{"id":"1.187552299","rc":[{"batb":[[1,1.63,2],[2,1.48,10.85]],"ltp":2.6,"tv":172.59,"id":23806970}]}]}
{"op":"mcm","clk":"4211970178","pt":1631474998165,"mc":[{"id":"1.187552299","rc":[{"batb":[[0,1.29,222],[1,1.25,72.3],[2,1.21,222]],"ltp":1.62,"tv":634.12,"id":16100628}]}]}
{"op":"mcm","clk":"4211970531","pt":1631475001964,"mc":[{"id":"1.187552299","rc":[{"batl":[[0,2.4,31.81],[1,2.6,72.3]],"ltp":1.62,"tv":634.12,"id":16100628}]}]}
{"op":"mcm","clk":"4211970694","pt":1631475003395,"mc":[{"id":"1.187552299","rc":[{"batb":[[0,1.32,13.01],[1,1.29,222],[2,1.25,72.3]],"ltp":1.62,"tv":634.12,"id":16100628}]}]}
{"op":"mcm","clk":"4211971400","pt":1631475010004,"mc":[{"id":"1.187552299","rc":[{"batb":[[1,1.3,72.3],[2,1.29,222]],"ltp":1.62,"tv":634.12,"id":16100628}]}]}
{"op":"mcm","clk":"4211971707","pt":1631475012990,"mc":[{"id":"1.187552299","rc":[{"batb":[[0,1.35,72.3],[1,1.32,13.01],[2,1.3,72.3]],"ltp":1.62,"tv":634.12,"id":16100628}]}]}
{"op":"mcm","clk":"4211972817","pt":1631475024006,"mc":[{"id":"1.187552299","rc":[{"batb":[[0,1.4,72.3],[1,1.35,72.3],[2,1.32,13.01]],"ltp":1.62,"tv":634.12,"id":16100628}]}]}
{"op":"mcm","clk":"4211973174","pt":1631475027697,"mc":[{"id":"1.187552299","rc":[{"batb":[[0,1.9,1.23],[1,1.64,5.78],[2,1.63,2]],"ltp":2.6,"tv":172.59,"id":23806970}]}]}
{"op":"mcm","clk":"4211974282","pt":1631475036607,"mc":[{"id":"1.187552299","rc":[{"batb":[[0,1.42,10.12],[1,1.4,72.3],[2,1.35,72.3]],"ltp":1.62,"tv":634.12,"id":16100628},{"batb":[[2,1.63,3]],"ltp":2.6,"tv":172.59,"id":23806970}]}]}
{"op":"mcm","clk":"4211974548","pt":1631475039018,"mc":[{"id":"1.187552299","rc":[{"batl":[[0,2.06,23.86],[1,2.4,31.81],[2,2.6,72.3]],"ltp":1.62,"tv":634.12,"id":16100628}]}]}
{"op":"mcm","clk":"4211974765","pt":1631475041269,"mc":[{"id":"1.187552299","rc":[{"batb":[[2,1.63,1]],"ltp":2.6,"tv":172.59,"id":23806970}]}]}
{"op":"mcm","clk":"4211975953","pt":1631475052686,"mc":[{"id":"1.187552299","rc":[{"batl":[[0,2.4,31.81],[1,2.6,72.3],[2,2.6,0]],"ltp":1.62,"tv":634.12,"id":16100628}]}]}
{"op":"mcm","clk":"4211976346","pt":1631475056372,"mc":[{"id":"1.187552299","rc":[{"batb":[[2,1.48,10.85]],"ltp":2.6,"tv":172.59,"id":23806970}]}]}
{"op":"mcm","clk":"4211976479","pt":1631475057783,"mc":[{"id":"1.187552299","rc":[{"batl":[[0,1.98,23.86],[1,2.4,31.81],[2,2.6,72.3]],"ltp":1.62,"tv":634.12,"id":16100628}]}]}
{"op":"mcm","clk":"4211976530","pt":1631475058305,"mc":[{"id":"1.187552299","rc":[{"batb":[[0,1.64,5.78],[1,1.48,10.85],[2,1.01,12]],"ltp":2.6,"tv":172.59,"id":23806970}]}]}
{"op":"mcm","clk":"4211976816","pt":1631475061525,"mc":[{"id":"1.187552299","rc":[{"batb":[[0,1.72,1],[1,1.64,5.78],[2,1.48,10.85]],"ltp":2.6,"tv":172.59,"id":23806970}]}]}
{"op":"mcm","clk":"4211976970","pt":1631475063431,"mc":[{"id":"1.187552299","rc":[{"batb":[[0,2,1.23],[1,1.72,1],[2,1.64,5.78]],"ltp":2.6,"tv":172.59,"id":23806970}]}]}
{"op":"mcm","clk":"4211977162","pt":1631475065497,"mc":[{"id":"1.187552299","rc":[{"batb":[[0,1.72,1],[1,1.64,5.78],[2,1.48,10.85]],"ltp":2.6,"tv":172.59,"id":23806970}]}]}
{"op":"mcm","clk":"4211977264","pt":1631475066552,"mc":[{"id":"1.187552299","rc":[{"batl":[[2,2.6,0]],"ltp":1.62,"tv":634.12,"id":16100628}]}]}
{"op":"mcm","clk":"4211977695","pt":1631475070648,"mc":[{"id":"1.187552299","rc":[{"batb":[[0,2.06,1.23],[1,1.72,1],[2,1.64,5.78]],"ltp":2.6,"tv":172.59,"id":23806970}]}]}
{"op":"mcm","clk":"4211978141","pt":1631475075210,"mc":[{"id":"1.187552299","rc":[{"batl":[[0,2.4,31.81],[1,2.4,0]],"ltp":1.62,"tv":634.12,"id":16100628},{"batb":[[2,1.48,10.85]],"ltp":2.6,"tv":172.59,"id":23806970}]}]}
{"op":"mcm","clk":"4211978976","pt":1631475084057,"mc":[{"id":"1.187552299","rc":[{"batb":[[0,1.42,6.51]],"ltp":1.62,"tv":634.12,"id":16100628}]}]}
{"op":"mcm","clk":"4211979461","pt":1631475089250,"mc":[{"id":"1.187552299","rc":[{"batl":[[0,1.9,7.23],[1,2.4,31.81]],"ltp":1.62,"tv":634.12,"id":16100628}]}]}
{"op":"mcm","clk":"4211979800","pt":1631475092774,"mc":[{"id":"1.187552299","rc":[{"batb":[[0,1.72,1],[1,1.48,10.85],[2,1.01,12]],"ltp":2.6,"tv":172.59,"id":23806970}]}]}
{"op":"mcm","clk":"4211980273","pt":1631475097877,"mc":[{"id":"1.187552299","rc":[{"batb":[[0,2.12,1.23],[1,1.72,1],[2,1.48,10.85]],"ltp":2.6,"tv":172.59,"id":23806970}]}]}
{"op":"mcm","clk":"4211981362","pt":1631475109382,"mc":[{"id":"1.187552299","rc":[{"batl":[[0,2.4,31.81],[1,2.4,0]],"ltp":1.62,"tv":634.12,"id":16100628}]}]}
{"op":"mcm","clk":"4211981569","pt":1631475111481,"mc":[{"id":"1.187552299","rc":[{"batl":[[0,1.9,59.66],[1,2.4,31.81]],"ltp":1.62,"tv":634.12,"id":16100628}]}]}
{"op":"mcm","clk":"4211982139","pt":1631475117182,"mc":[{"id":"1.187552299","rc":[{"batl":[[0,2.4,31.81],[1,2.4,0]],"ltp":1.62,"tv":634.12,"id":16100628}]}]}
{"op":"mcm","clk":"4211982636","pt":1631475122292,"mc":[{"id":"1.187552299","rc":[{"batl":[[0,1.82,59.66],[1,2.4,31.81]],"ltp":1.62,"tv":634.12,"id":16100628}]}]}
{"op":"mcm","clk":"4211982846","pt":1631475124699,"mc":[{"id":"1.187552299","rc":[{"batl":[[0,2.4,31.81],[1,2.4,0]],"ltp":1.62,"tv":634.12,"id":16100628},{"trd":[[2.12,2.46]],"batb":[[0,1.72,1],[1,1.48,10.85],[2,1.01,12]],"batl":[[0,2.12,7.57]],"ltp":2.12,"tv":175.05,"id":23806970}],"tv":809.18}]}
{"op":"mcm","clk":"4211983021","pt":1631475126184,"mc":[{"id":"1.187552299","rc":[{"trd":[[2.4,5.23]],"batl":[[0,2.4,26.59]],"ltp":2.4,"tv":639.35,"id":16100628},{"trd":[[1.71,7.34],[1.72,2]],"batb":[[0,1.48,10.85],[1,1.01,12],[2,1.01,0]],"ltp":1.71,"tv":184.39,"id":23806970}],"tv":823.74}]}
{"op":"mcm","clk":"4211983256","pt":1631475128596,"mc":[{"id":"1.187552299","rc":[{"batb":[[0,1.82,46.93],[1,1.42,6.51],[2,1.4,72.3]],"ltp":2.4,"tv":639.35,"id":16100628}]}]}
{"op":"mcm","clk":"4211983309","pt":1631475129118,"mc":[{"id":"1.187552299","rc":[{"batb":[[0,1.42,6.51],[1,1.4,72.3],[2,1.35,72.3]],"ltp":2.4,"tv":639.35,"id":16100628}]}]}
{"op":"mcm","clk":"4211983439","pt":1631475130672,"mc":[{"id":"1.187552299","rc":[{"batb":[[0,1.01,12],[1,1.01,0]],"ltp":1.71,"tv":184.39,"id":23806970}]}]}
{"op":"mcm","clk":"4211983499","pt":1631475131317,"mc":[{"id":"1.187552299","rc":[{"batb":[[0,1.4,72.3],[1,1.35,72.3],[2,1.3,72.3]],"ltp":2.4,"tv":639.35,"id":16100628}]}]}
{"op":"mcm","clk":"4211984237","pt":1631475139164,"mc":[{"id":"1.187552299","rc":[{"batl":[[0,2,23.86],[1,2.4,26.59]],"ltp":2.4,"tv":639.35,"id":16100628}]}]}
{"op":"mcm","clk":"4211985473","pt":1631475148822,"mc":[{"id":"1.187552299","rc":[{"trd":[[2,23.86]],"batl":[[0,2.4,26.59],[1,2.4,0]],"ltp":2.0,"tv":663.2,"id":16100628},{"trd":[[2,23.86]],"batl":[[0,2,8.25]],"ltp":2.0,"tv":208.25,"id":23806970}],"tv":871.46}]}
{"op":"mcm","clk":"4211986256","pt":1631475156848,"mc":[{"id":"1.187552299","rc":[{"batb":[[0,1.42,222],[1,1.4,72.3],[2,1.35,72.3]],"ltp":2.0,"tv":663.2,"id":16100628}]}]}
{"op":"mcm","clk":"4211988198","pt":1631475176742,"mc":[{"id":"1.187552299","rc":[{"trd":[[1.42,5.52]],"batb":[[0,1.42,219.24]],"ltp":1.42,"tv":668.72,"id":16100628}],"tv":876.98}]}
{"op":"mcm","clk":"4211988552","pt":1631475180294,"mc":[{"id":"1.187552299","rc":[{"batb":[[0,1.02,11],[1,1.01,12]],"ltp":2.0,"tv":208.25,"id":23806970}]}]}
{"op":"mcm","clk":"4211989737","pt":1631475192021,"mc":[{"id":"1.187552299","rc":[{"batb":[[0,1.4,72.3],[1,1.35,72.3],[2,1.3,72.3]],"ltp":1.42,"tv":668.72,"id":16100628}]}]}
{"op":"mcm","clk":"4211990857","pt":1631475202812,"mc":[{"id":"1.187552299","rc":[{"batl":[[0,1.53,2.56],[1,2.4,26.59]],"ltp":1.42,"tv":668.72,"id":16100628}]}]}
{"op":"mcm","clk":"4211991118","pt":1631475205355,"mc":[{"id":"1.187552299","rc":[{"batl":[[1,2.4,0]],"ltp":1.42,"tv":668.72,"id":16100628}]}]}
{"op":"mcm","clk":"4211991609","pt":1631475210434,"mc":[{"id":"1.187552299","rc":[{"batl":[[1,2,26.59]],"ltp":1.42,"tv":668.72,"id":16100628}]}]}
{"op":"mcm","clk":"4211991937","pt":1631475213660,"mc":[{"id":"1.187552299","rc":[{"trd":[[1.53,5.12]],"batb":[[0,1.53,1.06],[1,1.4,72.3],[2,1.35,72.3]],"batl":[[0,2,26.59],[1,2,0]],"ltp":1.53,"tv":673.84,"id":16100628}],"tv":882.1}]}
{"op":"mcm","clk":"4211992415","pt":1631475218261,"mc":[{"id":"1.187552299","rc":[{"batb":[[1,1.2,144.6],[2,1.15,72.3]],"ltp":1.53,"tv":673.84,"id":16100628}]}]}
{"op":"mcm","clk":"4211992905","pt":1631475223296,"mc":[{"id":"1.187552299","rc":[{"batb":[[0,1.2,144.6],[1,1.15,72.3],[2,1.1,72.3]],"ltp":1.53,"tv":673.84,"id":16100628}]}]}
{"op":"mcm","clk":"4211993522","pt":1631475229286,"mc":[{"id":"1.187552299","rc":[{"batb":[[0,1.15,72.3],[1,1.1,72.3],[2,1.05,72.3]],"ltp":1.53,"tv":673.84,"id":16100628}]}]}
{"op":"mcm","clk":"4211993621","pt":1631475230386,"mc":[{"id":"1.187552299","rc":[{"batl":[[0,1.66,170],[1,2,26.59]],"ltp":1.53,"tv":673.84,"id":16100628}]}]}
{"op":"mcm","clk":"4211993865","pt":1631475232705,"mc":[{"id":"1.187552299","rc":[{"batb":[[0,1.1,72.3],[1,1.05,72.3],[2,1.01,297.39]],"ltp":1.53,"tv":673.84,"id":16100628}]}]}
{"op":"mcm","clk":"4211994236","pt":1631475236172,"mc":[{"id":"1.187552299","rc":[{"batb":[[0,1.05,72.3],[1,1.01,297.39],[2,1.01,0]],"ltp":1.53,"tv":673.84,"id":16100628}]}]}
{"op":"mcm","clk":"4211994907","pt":1631475242200,"mc":[{"id":"1.187552299","rc":[{"batl":[[0,2,26.59],[1,2,0]],"ltp":1.53,"tv":673.84,"id":16100628}]}]}
{"op":"mcm","clk":"4211995865","pt":1631475252105,"mc":[{"id":"1.187552299","rc":[{"batl":[[0,2.44,108.45]],"ltp":2.0,"tv":208.25,"id":23806970}]}]}
{"op":"mcm","clk":"4211996285","pt":1631475256519,"mc":[{"id":"1.187552299","rc":[{"batb":[[0,1.1,232.09],[1,1.02,11],[2,1.01,12]],"ltp":2.0,"tv":208.25,"id":23806970}]}]}
{"op":"mcm","clk":"4211997535","pt":1631475268511,"mc":[{"id":"1.187552299","rc":[{"batl":[[0,1.7,23.86]],"ltp":1.53,"tv":673.84,"id":16100628},{"batb":[[0,1.22,18.08],[1,1.12,20],[2,1.1,232.09]],"ltp":2.0,"tv":208.25,"id":23806970}]}]}
{"op":"mcm","clk":"4211998254","pt":1631475275641,"mc":[{"id":"1.187552299","rc":[{"batb":[[0,1.7,14.59],[1,1.05,72.3],[2,1.01,297.39]],"ltp":1.53,"tv":673.84,"id":16100628}]}]}
{"op":"mcm","clk":"4211998370","pt":1631475276849,"mc":[{"id":"1.187552299","rc":[{"batb":[[0,1.7,9.77]],"ltp":1.53,"tv":673.84,"id":16100628}]}]}
{"op":"mcm","clk":"4211998473","pt":1631475277852,"mc":[{"id":"1.187552299","rc":[{"batb":[[0,1.05,72.3],[1,1.01,297.39],[2,1.01,0]],"ltp":1.53,"tv":673.84,"id":16100628},{"batl":[[0,2.42,6.16]],"ltp":2.0,"tv":208.25,"id":23806970}]}]}
{"op":"mcm","clk":"4211998551","pt":1631475278646,"mc":[{"id":"1.187552299","rc":[{"batb":[[0,1.3,72.3],[1,1.22,18.08],[2,1.12,20]],"ltp":2.0,"tv":208.25,"id":23806970}]}]}
{"op":"mcm","clk":"4211998974","pt":1631475282538,"mc":[{"id":"1.187552299","rc":[{"batl":[[0,2.28,108.45]],"ltp":2.0,"tv":208.25,"id":23806970}]}]}
{"op":"mcm","clk":"4211999046","pt":1631475283273,"mc":[{"id":"1.187552299","rc":[{"batl":[[0,2,15.91]],"ltp":1.53,"tv":673.84,"id":16100628}]}]}
{"op":"mcm","clk":"4211999134","pt":1631475284059,"mc":[{"id":"1.187552299","rc":[{"batb":[[0,1.15,15.18],[1,1.05,72.3],[2,1.01,297.39]],"ltp":1.53,"tv":673.84,"id":16100628}]}]}
{"op":"mcm","clk":"4211999412","pt":1631475286744,"mc":[{"id":"1.187552299","rc":[{"trd":[[1.78,3.62]],"ltp":1.78,"tv":677.45,"id":16100628},{"trd":[[2.28,2.82]],"batl":[[0,2.28,105.63]],"ltp":2.28,"tv":211.07,"id":23806970}],"tv":888.53}]}
{"op":"mcm","clk":"4211999647","pt":1631475288971,"mc":[{"id":"1.187552299","rc":[{"batb":[[1,1.12,20],[2,1.1,232.09]],"ltp":2.28,"tv":211.07,"id":23806970}]}]}
{"op":"mcm","clk":"4211999843","pt":1631475290764,"mc":[{"id":"1.187552299","rc":[{"batb":[[0,1.36,10.12],[1,1.3,72.3],[2,1.12,20]],"ltp":2.28,"tv":211.07,"id":23806970}]}]}
{"op":"mcm","clk":"4212000999","pt":1631475300844,"mc":[{"id":"1.187552299","rc":[{"batb":[[0,2,15.9],[1,1.15,15.18],[2,1.05,72.3]],"ltp":1.78,"tv":677.45,"id":16100628}]}]}
{"op":"mcm","clk":"4212001073","pt":1631475301479,"mc":[{"id":"1.187552299","rc":[{"batb":[[0,1.15,15.18],[1,1.05,72.3],[2,1.01,297.39]],"ltp":1.78,"tv":677.45,"id":16100628},{"batb":[[0,1.3,72.3],[1,1.12,20],[2,1.1,232.09]],"ltp":2.28,"tv":211.07,"id":23806970}]}]}
{"op":"mcm","clk":"4212001218","pt":1631475302854,"mc":[{"id":"1.187552299","rc":[{"batl":[[0,2,6.16],[1,2.28,105.63]],"ltp":2.28,"tv":211.07,"id":23806970}]}]}
{"op":"mcm","clk":"4212001298","pt":1631475303486,"mc":[{"id":"1.187552299","rc":[{"batb":[[0,1.05,72.3],[1,1.01,297.39],[2,1.01,0]],"ltp":1.78,"tv":677.45,"id":16100628}]}]}
{"op":"mcm","clk":"4212001545","pt":1631475305803,"mc":[{"id":"1.187552299","rc":[{"batl":[[0,2.28,105.63],[1,2.28,0]],"ltp":2.28,"tv":211.07,"id":23806970}]}]}
{"op":"mcm","clk":"4212001699","pt":1631475307182,"mc":[{"id":"1.187552299","rc":[{"batb":[[0,1.12,20],[1,1.1,232.09],[2,1.02,11]],"ltp":2.28,"tv":211.07,"id":23806970}]}]}
{"op":"mcm","clk":"4212001822","pt":1631475308453,"mc":[{"id":"1.187552299","rc":[{"batl":[[0,2.3,21.99]],"ltp":1.78,"tv":677.45,"id":16100628}]}]}
{"op":"mcm","clk":"4212004401","pt":1631475332717,"mc":[{"id":"1.187552299","rc":[{"trd":[[2.3,43.97]],"ltp":2.3,"tv":721.42,"id":16100628}],"tv":932.5}]}
{"op":"mcm","clk":"4212004868","pt":1631475337240,"mc":[{"id":"1.187552299","rc":[{"batb":[[1,1.02,11],[2,1.01,12]],"ltp":2.28,"tv":211.07,"id":23806970}]}]}
{"op":"mcm","clk":"4212005574","pt":1631475344404,"mc":[{"id":"1.187552299","rc":[{"batb":[[1,1.01,0]],"ltp":2.3,"tv":721.42,"id":16100628}]}]}
{"op":"mcm","clk":"4212005816","pt":1631475346718,"mc":[{"id":"1.187552299","rc":[{"batb":[[0,1.15,72.3],[1,1.12,20],[2,1.02,11]],"ltp":2.28,"tv":211.07,"id":23806970}]}]}
{"op":"mcm","clk":"4212007579","pt":1631475362362,"mc":[{"id":"1.187552299","rc":[{"batb":[[0,1.05,304.39]],"ltp":2.3,"tv":721.42,"id":16100628}]}]}
{"op":"mcm","clk":"4212008182","pt":1631475367642,"mc":[{"id":"1.187552299","rc":[{"batl":[[0,2,8.8]],"ltp":2.28,"tv":211.07,"id":23806970}]}]}
{"op":"mcm","clk":"4212009984","pt":1631475383846,"mc":[{"id":"1.187552299","rc":[{"batb":[[0,1.06,435.56],[1,1.05,304.39]],"ltp":2.3,"tv":721.42,"id":16100628}]}]}
{"op":"mcm","clk":"4212011336","pt":1631475396366,"mc":[{"id":"1.187552299","rc":[{"batb":[[0,1.1,472.85],[1,1.06,435.56],[2,1.05,304.39]],"ltp":2.3,"tv":721.42,"id":16100628}]}]}
{"op":"mcm","clk":"4212012956","pt":1631475410598,"mc":[{"id":"1.187552299","rc":[{"batb":[[0,1.11,472.29],[1,1.1,472.85],[2,1.06,435.56]],"ltp":2.3,"tv":721.42,"id":16100628}]}]}
{"op":"mcm","clk":"4212013413","pt":1631475414491,"mc":[{"id":"1.187552299","rc":[{"batb":[[1,1.06,435.56],[2,1.05,304.39]],"ltp":2.3,"tv":721.42,"id":16100628}]}]}
{"op":"mcm","clk":"4212014047","pt":1631475419597,"mc":[{"id":"1.187552299","rc":[{"batb":[[0,1.13,472.85],[1,1.11,472.29],[2,1.06,435.56]],"ltp":2.3,"tv":721.42,"id":16100628}]}]}
{"op":"mcm","clk":"4212014968","pt":1631475427838,"mc":[{"id":"1.187552299","rc":[{"batb":[[0,1.2,472.29],[1,1.13,472.85],[2,1.11,472.29]],"ltp":2.3,"tv":721.42,"id":16100628}]}]}
{"op":"mcm","clk":"4212015317","pt":1631475430897,"mc":[{"id":"1.187552299","rc":[{"batb":[[0,1.3,472.29],[1,1.2,544.59],[2,1.13,472.85]],"ltp":2.3,"tv":721.42,"id":16100628},{"batb":[[0,1.12,20],[1,1.02,11],[2,1.01,12]],"ltp":2.28,"tv":211.07,"id":23806970}]}]}
{"op":"mcm","clk":"4212016554","pt":1631475442428,"mc":[{"id":"1.187552299","rc":[{"batb":[[0,1.15,72.3],[1,1.12,20],[2,1.02,11]],"ltp":2.28,"tv":211.07,"id":23806970}]}]}
{"op":"mcm","clk":"4212016843","pt":1631475445029,"mc":[{"id":"1.187552299","rc":[{"batb":[[0,1.2,544.59],[1,1.13,472.85],[2,1.11,472.29]],"ltp":2.3,"tv":721.42,"id":16100628}]}]}
{"op":"mcm","clk":"4212017022","pt":1631475446511,"mc":[{"id":"1.187552299","rc":[{"batb":[[0,1.31,72.3],[1,1.2,544.59],[2,1.13,472.85]],"ltp":2.3,"tv":721.42,"id":16100628}]}]}
{"op":"mcm","clk":"4212017339","pt":1631475449550,"mc":[{"id":"1.187552299","rc":[{"batb":[[1,1.2,472.29],[2,1.11,472.29]],"ltp":2.3,"tv":721.42,"id":16100628}]}]}
{"op":"mcm","clk":"4212018034","pt":1631475455856,"mc":[{"id":"1.187552299","rc":[{"batb":[[0,1.32,81.13],[1,1.31,72.3],[2,1.2,472.29]],"ltp":2.3,"tv":721.42,"id":16100628}]}]}
{"op":"mcm","clk":"4212018402","pt":1631475459461,"mc":[{"id":"1.187552299","rc":[{"batb":[[1,1.2,472.29],[2,1.11,472.29]],"ltp":2.3,"tv":721.42,"id":16100628}]}]}
{"op":"mcm","clk":"4212018833","pt":1631475463604,"mc":[{"id":"1.187552299","rc":[{"batb":[[0,1.16,81.13],[1,1.15,72.3],[2,1.12,20]],"ltp":2.28,"tv":211.07,"id":23806970}]}]}
{"op":"mcm","clk":"4212019284","pt":1631475467552,"mc":[{"id":"1.187552299","rc":[{"batb":[[1,1.12,20],[2,1.02,11]],"ltp":2.28,"tv":211.07,"id":23806970}]}]}
{"op":"mcm","clk":"4212019825","pt":1631475472682,"mc":[{"id":"1.187552299","rc":[{"batb":[[0,1.18,72.3],[1,1.16,81.13],[2,1.12,20]],"ltp":2.28,"tv":211.07,"id":23806970}]}]}
{"op":"mcm","clk":"4212019865","pt":1631475473091,"mc":[{"id":"1.187552299","rc":[{"batb":[[0,1.11,472.29],[1,1.06,435.56],[2,1.05,304.39]],"ltp":2.3,"tv":721.42,"id":16100628}]}]}
{"op":"mcm","clk":"4212020616","pt":1631475479202,"mc":[{"id":"1.187552299","rc":[{"batb":[[0,1.06,435.56],[1,1.05,304.39],[2,1.05,0]],"ltp":2.3,"tv":721.42,"id":16100628},{"batb":[[1,1.12,20],[2,1.02,11]],"ltp":2.28,"tv":211.07,"id":23806970}]}]}
{"op":"mcm","clk":"4212021261","pt":1631475484279,"mc":[{"id":"1.187552299","rc":[{"batb":[[0,1.19,81.13],[1,1.18,72.3],[2,1.12,20]],"ltp":2.28,"tv":211.07,"id":23806970}]}]}
{"op":"mcm","clk":"4212022027","pt":1631475490830,"mc":[{"id":"1.187552299","rc":[{"batb":[[1,1.12,20],[2,1.02,11]],"ltp":2.28,"tv":211.07,"id":23806970}]}]}
{"op":"mcm","clk":"4212022645","pt":1631475495939,"mc":[{"id":"1.187552299","rc":[{"batb":[[0,1.21,72.3],[1,1.19,81.13],[2,1.12,20]],"ltp":2.28,"tv":211.07,"id":23806970}]}]}
{"op":"mcm","clk":"4212022857","pt":1631475497528,"mc":[{"id":"1.187552299","rc":[{"batb":[[1,1.05,72.3]],"ltp":2.3,"tv":721.42,"id":16100628}]}]}
{"op":"mcm","clk":"4212023092","pt":1631475499435,"mc":[{"id":"1.187552299","rc":[{"batb":[[1,1.12,20],[2,1.02,11]],"ltp":2.28,"tv":211.07,"id":23806970}]}]}
{"op":"mcm","clk":"4212023511","pt":1631475502626,"mc":[{"id":"1.187552299","rc":[{"batb":[[0,1.07,232.09],[1,1.06,435.56],[2,1.05,72.3]],"ltp":2.3,"tv":721.42,"id":16100628}]}]}
{"op":"mcm","clk":"4212023754","pt":1631475504528,"mc":[{"id":"1.187552299","rc":[{"batb":[[0,1.23,81.13],[1,1.21,72.3],[2,1.12,20]],"ltp":2.28,"tv":211.07,"id":23806970}]}]}
{"op":"mcm","clk":"4212024514","pt":1631475510544,"mc":[{"id":"1.187552299","rc":[{"batb":[[0,1.21,72.3],[1,1.12,20],[2,1.02,11]],"ltp":2.28,"tv":211.07,"id":23806970}]}]}
{"op":"mcm","clk":"4212024671","pt":1631475512062,"mc":[{"id":"1.187552299","rc":[{"batb":[[0,1.2,473.99],[1,1.07,232.09],[2,1.06,435.56]],"ltp":2.3,"tv":721.42,"id":16100628}]}]}
{"op":"mcm","clk":"4212025105","pt":1631475515571,"mc":[{"id":"1.187552299","rc":[{"batb":[[0,1.2,546.3]],"ltp":2.3,"tv":721.42,"id":16100628}]}]}
{"op":"mcm","clk":"4212025326","pt":1631475517573,"mc":[{"id":"1.187552299","rc":[{"batb":[[0,1.12,20],[1,1.02,11],[2,1.01,12]],"ltp":2.28,"tv":211.07,"id":23806970}]}]}
{"op":"mcm","clk":"4212026874","pt":1631475530484,"mc":[{"id":"1.187552299","rc":[{"batb":[[0,1.13,72.3],[1,1.12,20],[2,1.02,11]],"ltp":2.28,"tv":211.07,"id":23806970}]}]}
{"op":"mcm","clk":"4212027230","pt":1631475533597,"mc":[{"id":"1.187552299","rc":[{"batb":[[0,1.22,72.3],[1,1.2,546.3],[2,1.07,232.09]],"ltp":2.3,"tv":721.42,"id":16100628}]}]}
{"op":"mcm","clk":"4212028047","pt":1631475540376,"mc":[{"id":"1.187552299","rc":[{"batb":[[0,1.14,81.13],[1,1.13,72.3],[2,1.12,20]],"ltp":2.28,"tv":211.07,"id":23806970}]}]}
{"op":"mcm","clk":"4212028968","pt":1631475548522,"mc":[{"id":"1.187552299","rc":[{"batb":[[0,1.24,81.13],[1,1.2,473.99],[2,1.06,435.56]],"ltp":2.3,"tv":721.42,"id":16100628},{"batb":[[1,1.12,20],[2,1.02,11]],"ltp":2.28,"tv":211.07,"id":23806970}]}]}
{"op":"mcm","clk":"4212029696","pt":1631475554898,"mc":[{"id":"1.187552299","rc":[{"batb":[[1,1.06,435.56],[2,1.06,0]],"ltp":2.3,"tv":721.42,"id":16100628},{"batb":[[0,1.12,20],[1,1.02,11],[2,1.01,12]],"ltp":2.28,"tv":211.07,"id":23806970}]}]}
{"op":"mcm","clk":"4212029989","pt":1631475557521,"mc":[{"id":"1.187552299","rc":[{"batb":[[0,1.3,72.3],[1,1.24,81.13],[2,1.06,435.56]],"ltp":2.3,"tv":721.42,"id":16100628}]}]}
{"op":"mcm","clk":"4212030272","pt":1631475559982,"mc":[{"id":"1.187552299","rc":[{"batb":[[0,1.35,473.99],[1,1.3,72.3],[2,1.24,81.13]],"ltp":2.3,"tv":721.42,"id":16100628}]}]}
{"op":"mcm","clk":"4212030970","pt":1631475565919,"mc":[{"id":"1.187552299","rc":[{"batb":[[0,1.4,72.3],[1,1.35,473.99],[2,1.3,72.3]],"ltp":2.3,"tv":721.42,"id":16100628}]}]}
{"op":"mcm","clk":"4212031509","pt":1631475570507,"mc":[{"id":"1.187552299","rc":[{"batb":[[0,1.5,81.13],[1,1.4,72.3],[2,1.35,473.99]],"ltp":2.3,"tv":721.42,"id":16100628}]}]}
{"op":"mcm","clk":"4212031979","pt":1631475574410,"mc":[{"id":"1.187552299","rc":[{"batb":[[0,1.55,72.3],[1,1.5,81.13],[2,1.4,72.3]],"ltp":2.3,"tv":721.42,"id":16100628}]}]}
{"op":"mcm","clk":"4212032628","pt":1631475580149,"mc":[{"id":"1.187552299","rc":[{"batb":[[0,1.6,81.13],[1,1.55,72.3],[2,1.5,81.13]],"ltp":2.3,"tv":721.42,"id":16100628}]}]}
{"op":"mcm","clk":"4212032970","pt":1631475582883,"mc":[{"id":"1.187552299","rc":[{"batb":[[0,1.62,72.3],[1,1.6,81.13],[2,1.55,72.3]],"ltp":2.3,"tv":721.42,"id":16100628}]}]}
{"op":"mcm","clk":"4212033179","pt":1631475584468,"mc":[{"id":"1.187552299","rc":[{"batb":[[0,1.6,81.13],[1,1.5,81.13],[2,1.35,473.99]],"ltp":2.3,"tv":721.42,"id":16100628}]}]}
{"op":"mcm","clk":"4212034098","pt":1631475591825,"mc":[{"id":"1.187552299","rc":[{"batb":[[0,1.64,81.13],[1,1.6,81.13],[2,1.5,81.13]],"ltp":2.3,"tv":721.42,"id":16100628}]}]}
{"op":"mcm","clk":"4212035891","pt":1631475606923,"mc":[{"id":"1.187552299","rc":[{"batb":[[0,1.35,473.99],[1,1.06,435.56],[2,1.5,0]],"ltp":2.3,"tv":721.42,"id":16100628}]}]}
{"op":"mcm","clk":"4212037044","pt":1631475616670,"mc":[{"id":"1.187552299","rc":[{"batb":[[0,1.15,72.3],[1,1.12,20],[2,1.02,11]],"ltp":2.28,"tv":211.07,"id":23806970}]}]}
{"op":"mcm","clk":"4212037382","pt":1631475619715,"mc":[{"id":"1.187552299","rc":[{"batb":[[0,1.1,72.3]],"ltp":2.3,"tv":721.42,"id":16100628}]}]}
{"op":"mcm","clk":"4212039241","pt":1631475635885,"mc":[{"id":"1.187552299","rc":[{"batb":[[0,1.11,284.4],[1,1.1,72.3]],"ltp":2.3,"tv":721.42,"id":16100628},{"batb":[[0,1.16,284.4],[1,1.15,72.3],[2,1.12,20]],"ltp":2.28,"tv":211.07,"id":23806970}]}]}
{"op":"mcm","clk":"4212040589","pt":1631475647429,"mc":[{"id":"1.187552299","rc":[{"batb":[[0,1.2,72.3],[1,1.16,284.4],[2,1.15,72.3]],"ltp":2.28,"tv":211.07,"id":23806970}]}]}
{"op":"mcm","clk":"4212040814","pt":1631475649532,"mc":[{"id":"1.187552299","rc":[{"batb":[[0,1.15,72.3],[1,1.11,284.4],[2,1.1,72.3]],"ltp":2.3,"tv":721.42,"id":16100628}]}]}
{"op":"mcm","clk":"4212041994","pt":1631475659573,"mc":[{"id":"1.187552299","rc":[{"batb":[[0,1.17,284.4],[1,1.15,72.3],[2,1.11,284.4]],"ltp":2.3,"tv":721.42,"id":16100628},{"batb":[[0,1.22,284.4],[1,1.2,72.3],[2,1.16,284.4]],"ltp":2.28,"tv":211.07,"id":23806970}]}]}
{"op":"mcm","clk":"4212043143","pt":1631475668640,"mc":[{"id":"1.187552299","rc":[{"batb":[[0,1.25,72.3],[1,1.22,284.4],[2,1.2,72.3]],"ltp":2.28,"tv":211.07,"id":23806970}]}]}
{"op":"mcm","clk":"4212043359","pt":1631475670748,"mc":[{"id":"1.187552299","rc":[{"batb":[[0,1.2,72.3],[1,1.17,284.4],[2,1.15,72.3]],"ltp":2.3,"tv":721.42,"id":16100628}]}]}
{"op":"mcm","clk":"4212044570","pt":1631475680469,"mc":[{"id":"1.187552299","rc":[{"batb":[[0,1.21,284.4],[1,1.2,72.3],[2,1.17,284.4]],"ltp":2.3,"tv":721.42,"id":16100628},{"batb":[[0,1.26,284.4],[1,1.25,72.3],[2,1.22,284.4]],"ltp":2.28,"tv":211.07,"id":23806970}]}]}
{"op":"mcm","clk":"4212045692","pt":1631475689771,"mc":[{"id":"1.187552299","rc":[{"batb":[[0,1.3,72.3],[1,1.26,284.4],[2,1.25,72.3]],"ltp":2.28,"tv":211.07,"id":23806970}]}]}
{"op":"mcm","clk":"4212045901","pt":1631475691405,"mc":[{"id":"1.187552299","rc":[{"batb":[[0,1.25,72.3],[1,1.21,284.4],[2,1.2,72.3]],"ltp":2.3,"tv":721.42,"id":16100628}]}]}
{"op":"mcm","clk":"4212047176","pt":1631475701590,"mc":[{"id":"1.187552299","rc":[{"batb":[[0,1.26,284.4],[1,1.25,72.3],[2,1.21,284.4]],"ltp":2.3,"tv":721.42,"id":16100628},{"batb":[[0,1.31,284.4],[1,1.3,72.3],[2,1.26,284.4]],"ltp":2.28,"tv":211.07,"id":23806970}]}]}
{"op":"mcm","clk":"4212049351","pt":1631475721028,"mc":[{"id":"1.187552299","rc":[{"batb":[[1,1.21,284.4],[2,1.17,284.4]],"ltp":2.3,"tv":721.42,"id":16100628},{"batb":[[1,1.26,284.4],[2,1.22,284.4]],"ltp":2.28,"tv":211.07,"id":23806970}]}]}
{"op":"mcm","clk":"4212050467","pt":1631475730641,"mc":[{"id":"1.187552299","rc":[{"batb":[[0,1.16,284.4],[1,1.12,20],[2,1.02,11]],"ltp":2.28,"tv":211.07,"id":23806970}]}]}
{"op":"mcm","clk":"4212050790","pt":1631475733660,"mc":[{"id":"1.187552299","rc":[{"batb":[[0,1.3,72.3],[1,1.26,284.4],[2,1.21,284.4]],"ltp":2.3,"tv":721.42,"id":16100628}]}]}
{"op":"mcm","clk":"4212050875","pt":1631475734448,"mc":[{"id":"1.187552299","rc":[{"batb":[[0,1.12,20],[1,1.02,11],[2,1.01,12]],"ltp":2.28,"tv":211.07,"id":23806970}]}]}
{"op":"mcm","clk":"4212051010","pt":1631475735656,"mc":[{"id":"1.187552299","rc":[{"batb":[[0,1.35,72.3],[1,1.3,72.3],[2,1.26,284.4]],"ltp":2.3,"tv":721.42,"id":16100628}]}]}
{"op":"mcm","clk":"4212051212","pt":1631475737351,"mc":[{"id":"1.187552299","rc":[{"batb":[[2,1.21,284.4]],"ltp":2.3,"tv":721.42,"id":16100628}]}]}
{"op":"mcm","clk":"4212051297","pt":1631475738135,"mc":[{"id":"1.187552299","rc":[{"batb":[[0,1.4,72.3],[1,1.35,72.3],[2,1.3,72.3]],"ltp":2.3,"tv":721.42,"id":16100628}]}]}
{"op":"mcm","clk":"4212051515","pt":1631475740291,"mc":[{"id":"1.187552299","rc":[{"batb":[[0,1.45,72.3],[1,1.4,72.3],[2,1.35,72.3]],"ltp":2.3,"tv":721.42,"id":16100628}]}]}
{"op":"mcm","clk":"4212052111","pt":1631475745545,"mc":[{"id":"1.187552299","rc":[{"batb":[[0,1.15,72.3],[1,1.12,20],[2,1.02,11]],"ltp":2.28,"tv":211.07,"id":23806970}]}]}
{"op":"mcm","clk":"4212052556","pt":1631475749692,"mc":[{"id":"1.187552299","rc":[{"batb":[[0,1.5,81.13],[1,1.45,72.3],[2,1.4,72.3]],"ltp":2.3,"tv":721.42,"id":16100628}]}]}
{"op":"mcm","clk":"4212052782","pt":1631475751600,"mc":[{"id":"1.187552299","rc":[{"batb":[[0,1.55,81.13],[1,1.5,81.13],[2,1.45,72.3]],"ltp":2.3,"tv":721.42,"id":16100628}]}]}
{"op":"mcm","clk":"4212052996","pt":1631475753374,"mc":[{"id":"1.187552299","rc":[{"batb":[[0,1.6,81.13],[1,1.55,81.13],[2,1.5,81.13]],"ltp":2.3,"tv":721.42,"id":16100628}]}]}
{"op":"mcm","clk":"4212053938","pt":1631475761257,"mc":[{"id":"1.187552299","rc":[{"batb":[[0,1.16,81.13],[1,1.15,72.3],[2,1.12,20]],"ltp":2.28,"tv":211.07,"id":23806970}]}]}
{"op":"mcm","clk":"4212054274","pt":1631475764357,"mc":[{"id":"1.187552299","rc":[{"batb":[[0,1.16,84.13]],"ltp":2.28,"tv":211.07,"id":23806970}]}]}
{"op":"mcm","clk":"4212055788","pt":1631475777521,"mc":[{"id":"1.187552299","rc":[{"batb":[[1,1.12,20],[2,1.02,11]],"ltp":2.28,"tv":211.07,"id":23806970}]}]}
{"op":"mcm","clk":"4212056265","pt":1631475781498,"mc":[{"id":"1.187552299","rc":[{"batb":[[0,1.12,20],[1,1.02,11],[2,1.01,12]],"ltp":2.28,"tv":211.07,"id":23806970}]}]}
{"op":"mcm","clk":"4212056894","pt":1631475786592,"mc":[{"id":"1.187552299","rc":[{"batb":[[0,1.17,3],[1,1.12,20],[2,1.02,11]],"ltp":2.28,"tv":211.07,"id":23806970}]}]}
{"op":"mcm","clk":"4212057241","pt":1631475789517,"mc":[{"id":"1.187552299","rc":[{"batb":[[0,1.2,72.3],[1,1.17,3],[2,1.12,20]],"ltp":2.28,"tv":211.07,"id":23806970}]}]}
{"op":"mcm","clk":"4212057453","pt":1631475791552,"mc":[{"id":"1.187552299","rc":[{"batb":[[0,1.15,72.3]],"ltp":2.3,"tv":721.42,"id":16100628}]}]}
{"op":"mcm","clk":"4212058220","pt":1631475798127,"mc":[{"id":"1.187552299","rc":[{"batb":[[2,1.15,2]],"ltp":2.28,"tv":211.07,"id":23806970}]}]}
{"op":"mcm","clk":"4212058712","pt":1631475802836,"mc":[{"id":"1.187552299","rc":[{"batb":[[0,1.25,72.3],[1,1.2,72.3],[2,1.17,3]],"ltp":2.28,"tv":211.07,"id":23806970}]}]}
{"op":"mcm","clk":"4212058755","pt":1631475803211,"mc":[{"id":"1.187552299","rc":[{"batb":[[0,1.2,81.13],[1,1.15,72.3]],"ltp":2.3,"tv":721.42,"id":16100628},{"batb":[[0,1.25,153.44]],"ltp":2.28,"tv":211.07,"id":23806970}]}]}
{"op":"mcm","clk":"4212058905","pt":1631475804826,"mc":[{"id":"1.187552299","rc":[{"batb":[[0,1.2,153.44]],"ltp":2.3,"tv":721.42,"id":16100628}]}]}
{"op":"mcm","clk":"4212059738","pt":1631475813041,"mc":[{"id":"1.187552299","rc":[{"batb":[[2,1.15,2]],"ltp":2.28,"tv":211.07,"id":23806970}]}]}
{"op":"mcm","clk":"4212059911","pt":1631475814721,"mc":[{"id":"1.187552299","rc":[{"batb":[[0,1.35,81.13],[1,1.3,72.3],[2,1.25,153.44]],"ltp":2.28,"tv":211.07,"id":23806970}]}]}
{"op":"mcm","clk":"4212060134","pt":1631475817074,"mc":[{"id":"1.187552299","rc":[{"batb":[[0,1.22,72.3],[1,1.2,153.44],[2,1.15,72.3]],"ltp":2.3,"tv":721.42,"id":16100628}]}]}
{"op":"mcm","clk":"4212060776","pt":1631475822649,"mc":[{"id":"1.187552299","rc":[{"batb":[[0,1.2,81.13],[1,1.2,0],[2,1.15,0]],"ltp":2.3,"tv":721.42,"id":16100628},{"batb":[[1,1.25,81.13],[2,1.15,2]],"ltp":2.28,"tv":211.07,"id":23806970}]}]}
{"op":"mcm","clk":"4212061072","pt":1631475825944,"mc":[{"id":"1.187552299","rc":[{"batb":[[0,1.24,81.13],[1,1.2,81.13]],"ltp":2.3,"tv":721.42,"id":16100628}]}]}
{"op":"mcm","clk":"4212062111","pt":1631475836957,"mc":[{"id":"1.187552299","rc":[{"batb":[[0,1.15,2],[1,1.12,20],[2,1.01,12]],"ltp":2.28,"tv":211.07,"id":23806970}]}]}
{"op":"mcm","clk":"4212063054","pt":1631475845795,"mc":[{"id":"1.187552299","rc":[{"batb":[[0,1.15,2]],"ltp":2.3,"tv":721.42,"id":16100628},{"batb":[[0,1.3,81.13],[1,1.15,2],[2,1.12,20]],"ltp":2.28,"tv":211.07,"id":23806970}]}]}
{"op":"mcm","clk":"4212063083","pt":1631475846064,"mc":[{"id":"1.187552299","rc":[{"batb":[[0,1.4,72.3],[1,1.3,81.13],[2,1.15,2]],"ltp":2.28,"tv":211.07,"id":23806970}]}]}
{"op":"mcm","clk":"4212063645","pt":1631475850798,"mc":[{"id":"1.187552299","rc":[{"batb":[[1,1.05,232.09]],"ltp":2.3,"tv":721.42,"id":16100628}]}]}
{"op":"mcm","clk":"4212064185","pt":1631475855662,"mc":[{"id":"1.187552299","rc":[{"batb":[[0,1.6,81.13],[1,1.4,72.3],[2,1.3,81.13]],"ltp":2.28,"tv":211.07,"id":23806970}]}]}
{"op":"mcm","clk":"4212064304","pt":1631475856962,"mc":[{"id":"1.187552299","rc":[{"batb":[[1,1.52,72.3],[2,1.4,72.3]],"ltp":2.28,"tv":211.07,"id":23806970}]}]}
{"op":"mcm","clk":"4212064643","pt":1631475860073,"mc":[{"id":"1.187552299","rc":[{"batb":[[1,1.05,0]],"ltp":2.3,"tv":721.42,"id":16100628},{"batb":[[1,1.3,81.13],[2,1.15,2]],"ltp":2.28,"tv":211.07,"id":23806970}]}]}
{"op":"mcm","clk":"4212064971","pt":1631475862891,"mc":[{"id":"1.187552299","rc":[{"batb":[[1,1.1,256.21]],"ltp":2.3,"tv":721.42,"id":16100628}]}]}
{"op":"mcm","clk":"4212065358","pt":1631475866672,"mc":[{"id":"1.187552299","rc":[{"batb":[[0,1.15,2],[1,1.12,20],[2,1.01,12]],"ltp":2.28,"tv":211.07,"id":23806970}]}]}
{"op":"mcm","clk":"4212065510","pt":1631475868111,"mc":[{"id":"1.187552299","rc":[{"batb":[[0,1.2,72.3],[1,1.15,2],[2,1.1,256.21]],"ltp":2.3,"tv":721.42,"id":16100628}]}]}
{"op":"mcm","clk":"4212066365","pt":1631475875071,"mc":[{"id":"1.187552299","rc":[{"batb":[[0,1.2,72.3],[1,1.15,2],[2,1.12,20]],"ltp":2.28,"tv":211.07,"id":23806970}]}]}
{"op":"mcm","clk":"4212066698","pt":1631475878001,"mc":[{"id":"1.187552299","rc":[{"batb":[[0,1.22,81.13],[1,1.2,72.3],[2,1.15,2]],"ltp":2.3,"tv":721.42,"id":16100628}]}]}
{"op":"mcm","clk":"4212067581","pt":1631475885420,"mc":[{"id":"1.187552299","rc":[{"batb":[[0,1.22,81.13],[1,1.2,72.3],[2,1.15,2]],"ltp":2.28,"tv":211.07,"id":23806970}]}]}
{"op":"mcm","clk":"4212068425","pt":1631475892312,"mc":[{"id":"1.187552299","rc":[{"batb":[[1,1.15,2],[2,1.1,256.21]],"ltp":2.3,"tv":721.42,"id":16100628},{"batb":[[1,1.15,2],[2,1.12,20]],"ltp":2.28,"tv":211.07,"id":23806970}]}]}
{"op":"mcm","clk":"4212068802","pt":1631475895214,"mc":[{"id":"1.187552299","rc":[{"batb":[[0,1.15,2],[1,1.15,0],[2,1.1,0]],"ltp":2.3,"tv":721.42,"id":16100628},{"batb":[[0,1.15,2],[1,1.12,20],[2,1.01,12]],"ltp":2.28,"tv":211.07,"id":23806970}]}]}
{"op":"mcm","clk":"4212069890","pt":1631475903722,"mc":[{"id":"1.187552299","rc":[{"batb":[[0,1.5,81.13],[1,1.3,72.3],[2,1.15,2]],"ltp":2.28,"tv":211.07,"id":23806970}]}]}
{"op":"mcm","clk":"4212070379","pt":1631475907648,"mc":[{"id":"1.187552299","rc":[{"batb":[[1,1.4,72.3],[2,1.3,72.3]],"ltp":2.28,"tv":211.07,"id":23806970}]}]}
{"op":"mcm","clk":"4212070797","pt":1631475911224,"mc":[{"id":"1.187552299","rc":[{"batb":[[0,1.55,72.3],[1,1.5,81.13],[2,1.4,72.3]],"ltp":2.28,"tv":211.07,"id":23806970}]}]}
{"op":"mcm","clk":"4212070947","pt":1631475912331,"mc":[{"id":"1.187552299","rc":[{"batb":[[0,1.6,81.13],[1,1.55,72.3],[2,1.5,81.13]],"ltp":2.28,"tv":211.07,"id":23806970}]}]}
{"op":"mcm","clk":"4212071827","pt":1631475919864,"mc":[{"id":"1.187552299","rc":[{"batb":[[0,1.65,72.3],[1,1.6,81.13],[2,1.55,72.3]],"ltp":2.28,"tv":211.07,"id":23806970}]}]}
{"op":"mcm","clk":"4212072118","pt":1631475922339,"mc":[{"id":"1.187552299","rc":[{"batb":[[0,1.75,72.3],[1,1.65,72.3],[2,1.6,81.13]],"ltp":2.28,"tv":211.07,"id":23806970}]}]}
{"op":"mcm","clk":"4212072883","pt":1631475928468,"mc":[{"id":"1.187552299","rc":[{"batb":[[1,1.7,81.13],[2,1.65,72.3]],"ltp":2.28,"tv":211.07,"id":23806970}]}]}
{"op":"mcm","clk":"4212073850","pt":1631475936473,"mc":[{"id":"1.187552299","rc":[{"batb":[[0,1.85,81.13],[2,1.6,81.13]],"ltp":2.28,"tv":211.07,"id":23806970}]}]}
{"op":"mcm","clk":"4212075034","pt":1631475946976,"mc":[{"id":"1.187552299","rc":[{"batl":[[0,1.01,7686.4]],"ltp":2.3,"tv":721.42,"id":16100628}]}]}
{"op":"mcm","clk":"4212075225","pt":1631475948701,"mc":[{"id":"1.187552299","rc":[{"batl":[[0,1.01,7703.48],[1,1.15,21.99]],"ltp":2.3,"tv":721.42,"id":16100628}]}]}
{"op":"mcm","clk":"4212075339","pt":1631475949809,"mc":[{"id":"1.187552299","rc":[{"batb":[[0,2,72.3],[1,1.85,81.13],[2,1.7,81.13]],"ltp":2.28,"tv":211.07,"id":23806970}]}]}
{"op":"mcm","clk":"4212075657","pt":1631475952512,"mc":[{"id":"1.187552299","rc":[{"batb":[[0,2.2,72.3],[1,2,72.3],[2,1.85,81.13]],"ltp":2.28,"tv":211.07,"id":23806970}]}]}
{"op":"mcm","clk":"4212075793","pt":1631475953720,"mc":[{"id":"1.187552299","rc":[{"batl":[[1,1.15,0]],"ltp":2.3,"tv":721.42,"id":16100628}]}]}
{"op":"mcm","clk":"4212075909","pt":1631475954818,"mc":[{"id":"1.187552299","rc":[{"batl":[[1,1.2,768.64]],"ltp":2.3,"tv":721.42,"id":16100628}]}]}
{"op":"mcm","clk":"4212076153","pt":1631475956820,"mc":[{"id":"1.187552299","rc":[{"batl":[[1,1.02,768.64],[2,1.2,768.64]],"ltp":2.3,"tv":721.42,"id":16100628}]}]}
{"op":"mcm","clk":"4212076528","pt":1631475959908,"mc":[{"id":"1.187552299","rc":[{"batl":[[0,1.01,7710.71]],"ltp":2.3,"tv":721.42,"id":16100628}]}]}
{"op":"mcm","clk":"4212077061","pt":1631475964923,"mc":[{"id":"1.187552299","rc":[{"batl":[[2,1.05,768.64]],"ltp":2.3,"tv":721.42,"id":16100628}]}]}
{"op":"mcm","clk":"4212077587","pt":1631475970216,"mc":[{"id":"1.187552299","marketDefinition":{"bspMarket":false,"turnInPlayEnabled":true,"persistenceEnabled":true,"marketBaseRate":5.0,"eventId":"30895245","eventTypeId":"2","numberOfWinners":1,"bettingType":"ODDS","marketType":"MATCH_ODDS","marketTime":"2021-09-12T17:49:59.000Z","suspendTime":"2021-09-12T17:49:59.000Z","bspReconciled":false,"complete":true,"inPlay":true,"crossMatching":true,"runnersVoidable":false,"numberOfActiveRunners":2,"betDelay":5,"status":"SUSPENDED","runners":[{"status":"ACTIVE","sortPriority":1,"id":23806970,"name":"D Semenistaja"},{"status":"ACTIVE","sortPriority":2,"id":16100628,"name":"G Maristany Zuleta de Reales"}],"regulators":["MR_INT"],"countryCode":"GB","discountAllowed":true,"timezone":"GMT","openDate":"2021-09-12T17:49:59.000Z","version":4029664176,"name":"Match Odds","eventName":"D Semenistaja v G Maristany Zuleta De Reales"}}]}
{"op":"mcm","clk":"4212078150","pt":1631475975825,"mc":[{"id":"1.187552299","tv":0.0}]}
{"op":"mcm","clk":"4212078310","pt":1631475977251,"mc":[{"id":"1.187552299","marketDefinition":{"bspMarket":false,"turnInPlayEnabled":true,"persistenceEnabled":true,"marketBaseRate":5.0,"eventId":"30895245","eventTypeId":"2","numberOfWinners":1,"bettingType":"ODDS","marketType":"MATCH_ODDS","marketTime":"2021-09-12T17:49:59.000Z","suspendTime":"2021-09-12T17:49:59.000Z","bspReconciled":false,"complete":true,"inPlay":true,"crossMatching":false,"runnersVoidable":false,"numberOfActiveRunners":0,"betDelay":5,"status":"CLOSED","settledTime":"2021-09-12T19:46:13.000Z","runners":[{"status":"LOSER","sortPriority":1,"id":23806970,"name":"D Semenistaja"},{"status":"WINNER","sortPriority":2,"id":16100628,"name":"G Maristany Zuleta de Reales"}],"regulators":["MR_INT"],"countryCode":"GB","discountAllowed":true,"timezone":"GMT","openDate":"2021-09-12T17:49:59.000Z","version":4029664194,"name":"Match Odds","eventName":"D Semenistaja v G Maristany Zuleta De Reales"}}]}
