{"op":"mcm","clk":"4216793606","pt":1631555373745,"mc":[{"id":"1.187566733","rc":[{"batl":[[1,2.36,77.13],[2,2.38,46.24]],"ltp":1.94,"tv":12768.21,"id":8734382},{"batl":[[1,2.38,6.25],[2,2.4,6.19]],"ltp":2.04,"tv":27449.88,"id":9323645}]}]}
{"op":"mcm","clk":"4216793724","pt":1631555374949,"mc":[{"id":"1.187566733","rc":[{"batl":[[0,2.06,256.2]],"ltp":1.94,"tv":12768.21,"id":8734382},{"batl":[[0,2.4,6.19],[1,2.52,5.51],[2,2.54,5.75]],"ltp":2.04,"tv":27449.88,"id":9323645}]}]}
{"op":"mcm","clk":"4216794012","pt":1631555378052,"mc":[{"id":"1.187566733","rc":[{"trd":[[1.95,53.01],[2.06,3.23]],"batb":[[0,1.77,256.02],[1,1.72,55.84],[2,1.68,134.88]],"batl":[[0,2.06,252.78]],"ltp":2.06,"tv":12771.63,"id":8734382},{"trd":[[1.94,3.43],[2.04,50.53]],"ltp":1.94,"tv":27453.49,"id":9323645}],"tv":40225.13}]}
{"op":"mcm","clk":"4216794374","pt":1631555382262,"mc":[{"id":"1.187566733","rc":[{"batb":[[0,1.78,8.88],[1,1.77,256.02],[2,1.72,55.84]],"ltp":2.06,"tv":12771.63,"id":8734382}]}]}
{"op":"mcm","clk":"4216795239","pt":1631555392167,"mc":[{"id":"1.187566733","rc":[{"batb":[[0,2.24,19.52],[1,1.78,8.88]],"batl":[[0,2.42,468.79]],"ltp":2.06,"tv":12771.63,"id":8734382},{"trd":[[1.8,147.54]],"batb":[[0,1.74,94],[1,1.72,120.13],[2,1.66,41.12]],"batl":[[0,1.76,94.21],[1,1.78,9.76],[2,1.79,68.08]],"ltp":1.8,"tv":27493.49,"id":9323645}],"tv":40265.13}]}
{"op":"mcm","clk":"4216795315","pt":1631555393056,"mc":[{"id":"1.187566733","rc":[{"batb":[[1,2.22,33.57],[2,1.88,27.86]],"batl":[[1,2.46,4.07]],"ltp":2.06,"tv":12771.63,"id":8734382},{"batb":[[1,1.73,17.34],[2,1.72,128.81]],"ltp":1.8,"tv":27493.49,"id":9323645}]}]}
{"op":"mcm","clk":"4216795357","pt":1631555393471,"mc":[{"id":"1.187566733","rc":[{"batb":[[2,2,6.93]],"ltp":2.06,"tv":12771.63,"id":8734382}]}]}
{"op":"mcm","clk":"4216795573","pt":1631555395784,"mc":[{"id":"1.187566733","rc":[{"batb":[[0,2.32,5.25],[1,2.24,19.52],[2,2.22,33.57]],"ltp":2.06,"tv":12771.63,"id":8734382}]}]}
{"op":"mcm","clk":"4216795619","pt":1631555396365,"mc":[{"id":"1.187566733","rc":[{"trd":[[2.3,43.38],[2.32,10.5]],"batb":[[0,2.24,19.52],[1,2.22,33.57],[2,2,6.93]],"ltp":2.3,"tv":12817.69,"id":8734382},{"trd":[[1.76,296.37]],"batl":[[0,1.76,47.74]],"ltp":1.76,"tv":27539.96,"id":9323645}],"tv":40357.66}]}
{"op":"mcm","clk":"4216795746","pt":1631555397569,"mc":[{"id":"1.187566733","rc":[{"batb":[[2,1.88,27.86]],"ltp":2.3,"tv":12817.69,"id":8734382},{"batl":[[0,1.76,138.74]],"ltp":1.76,"tv":27539.96,"id":9323645}]}]}
{"op":"mcm","clk":"4216795903","pt":1631555399090,"mc":[{"id":"1.187566733","rc":[{"trd":[[2.3,58.56]],"batb":[[2,1.91,45.39]],"ltp":2.3,"tv":12832.87,"id":8734382},{"trd":[[1.74,8.62],[1.76,316.21]],"batb":[[0,1.74,89.69]],"batl":[[0,1.76,118.9]],"ltp":1.74,"tv":27568.42,"id":9323645}],"tv":40401.3}]}
{"op":"mcm","clk":"4216795989","pt":1631555399884,"mc":[{"id":"1.187566733","rc":[{"trd":[[1.74,52.06],[1.76,326.21]],"batb":[[0,1.74,67.97],[2,1.72,173.9]],"batl":[[0,1.76,113.9]],"ltp":1.74,"tv":27621.86,"id":9323645}],"tv":40454.74}]}
{"op":"mcm","clk":"4216796123","pt":1631555401067,"mc":[{"id":"1.187566733","rc":[{"batl":[[0,2.34,5.2],[1,2.42,468.79],[2,2.46,4.07]],"ltp":2.3,"tv":12832.87,"id":8734382},{"trd":[[1.76,360.33]],"batl":[[0,1.76,96.84]],"ltp":1.76,"tv":27655.99,"id":9323645}],"tv":40488.87}]}
{"op":"mcm","clk":"4216796194","pt":1631555401688,"mc":[{"id":"1.187566733","rc":[{"trd":[[1.76,366]],"batl":[[0,1.76,94.01]],"ltp":1.76,"tv":27661.65,"id":9323645}],"tv":40494.53}]}
{"op":"mcm","clk":"4216796547","pt":1631555405174,"mc":[{"id":"1.187566733","rc":[{"batb":[[1,1.73,60.36]],"ltp":1.76,"tv":27661.65,"id":9323645}]}]}
{"op":"mcm","clk":"4216796650","pt":1631555406075,"mc":[{"id":"1.187566733","rc":[{"trd":[[1.76,369.96]],"batl":[[0,1.76,92.03]],"ltp":1.76,"tv":27665.61,"id":9323645}],"tv":40498.49}]}
{"op":"mcm","clk":"4216796756","pt":1631555407075,"mc":[{"id":"1.187566733","rc":[{"trd":[[1.76,482.22]],"batl":[[0,1.76,35.9]],"ltp":1.76,"tv":27777.88,"id":9323645}],"tv":40610.76}]}
{"op":"mcm","clk":"4216796901","pt":1631555408654,"mc":[{"id":"1.187566733","rc":[{"trd":[[2.3,86.03]],"batl":[[0,2.3,147.32],[1,2.34,5.2],[2,2.42,468.79]],"ltp":2.3,"tv":12860.34,"id":8734382},{"trd":[[1.76,518.12]],"batl":[[0,1.78,9.76],[1,1.79,68.08],[2,1.8,72.62]],"ltp":1.76,"tv":27813.78,"id":9323645}],"tv":40674.13}]}
{"op":"mcm","clk":"4216796976","pt":1631555409388,"mc":[{"id":"1.187566733","rc":[{"trd":[[2.3,91.4]],"batl":[[0,2.3,141.95]],"ltp":2.3,"tv":12865.71,"id":8734382},{"trd":[[1.76,525.14]],"batl":[[0,1.79,68.08],[1,1.8,72.62],[2,1.81,119.64]],"ltp":1.76,"tv":27820.79,"id":9323645}],"tv":40686.51}]}
{"op":"mcm","clk":"4216797255","pt":1631555412187,"mc":[{"id":"1.187566733","rc":[{"trd":[[2.3,109.62]],"batl":[[0,2.3,132.84]],"ltp":2.3,"tv":12883.93,"id":8734382},{"batb":[[0,1.74,105.48],[2,1.72,188.18]],"ltp":1.76,"tv":27820.79,"id":9323645}],"tv":40704.73}]}
{"op":"mcm","clk":"4216797272","pt":1631555412392,"mc":[{"id":"1.187566733","rc":[{"batb":[[2,1.72,173.9]],"ltp":1.76,"tv":27820.79,"id":9323645}]}]}
{"op":"mcm","clk":"4216797411","pt":1631555413985,"mc":[{"id":"1.187566733","rc":[{"batb":[[0,1.74,105.52]],"ltp":1.76,"tv":27820.79,"id":9323645}]}]}
{"op":"mcm","clk":"4216797520","pt":1631555415083,"mc":[{"id":"1.187566733","rc":[{"batl":[[0,1.79,135.08]],"ltp":1.76,"tv":27820.79,"id":9323645}]}]}
{"op":"mcm","clk":"4216797537","pt":1631555415297,"mc":[{"id":"1.187566733","rc":[{"trd":[[2.3,127.84]],"batl":[[0,2.3,123.73]],"ltp":2.3,"tv":12902.15,"id":8734382},{"batb":[[2,1.72,188.18]],"ltp":1.76,"tv":27820.79,"id":9323645}],"tv":40722.95}]}
{"op":"mcm","clk":"4216797718","pt":1631555417090,"mc":[{"id":"1.187566733","rc":[{"trd":[[2.3,251.57]],"batl":[[0,2.34,5.2],[1,2.42,468.79],[2,2.46,4.07]],"ltp":2.3,"tv":13025.88,"id":8734382},{"trd":[[1.76,686.91]],"batb":[[0,1.74,105.48]],"batl":[[0,1.76,77.21],[1,1.79,135.08],[2,1.8,72.62]],"ltp":1.76,"tv":27982.56,"id":9323645}],"tv":41008.45}]}
{"op":"mcm","clk":"4216797748","pt":1631555417392,"mc":[{"id":"1.187566733","rc":[{"batl":[[1,1.79,68.08]],"ltp":1.76,"tv":27982.56,"id":9323645}]}]}
{"op":"mcm","clk":"4216798063","pt":1631555420494,"mc":[{"id":"1.187566733","rc":[{"batl":[[0,1.76,246.21]],"ltp":1.76,"tv":27982.56,"id":9323645}]}]}
{"op":"mcm","clk":"4216798283","pt":1631555422699,"mc":[{"id":"1.187566733","rc":[{"batl":[[0,2.42,468.79],[1,2.46,4.07],[2,2.46,0]],"ltp":2.3,"tv":13025.88,"id":8734382},{"batb":[[2,1.72,173.9]],"batl":[[0,1.76,169]],"ltp":1.76,"tv":27982.56,"id":9323645}]}]}
{"op":"mcm","clk":"4216798592","pt":1631555425803,"mc":[{"id":"1.187566733","rc":[{"batl":[[0,2.34,5.2],[1,2.42,468.79],[2,2.46,4.07]],"ltp":2.3,"tv":13025.88,"id":8734382},{"trd":[[1.76,707.51]],"batl":[[0,1.75,77.21],[1,1.76,158.7],[2,1.79,68.08]],"ltp":1.76,"tv":28003.16,"id":9323645}],"tv":41029.05}]}
{"op":"mcm","clk":"4216798643","pt":1631555426380,"mc":[{"id":"1.187566733","rc":[{"trd":[[1.75,11.86]],"batl":[[0,1.75,77.21]],"ltp":1.75,"tv":28003.18,"id":9323645}],"tv":41029.07}]}
{"op":"mcm","clk":"4216798740","pt":1631555427290,"mc":[{"id":"1.187566733","rc":[{"trd":[[1.75,166.28],[1.76,893.09]],"batl":[[0,1.76,65.91],[1,1.79,68.08],[2,1.8,72.62]],"ltp":1.76,"tv":28343.18,"id":9323645}],"tv":41369.07}]}
{"op":"mcm","clk":"4216798887","pt":1631555428704,"mc":[{"id":"1.187566733","rc":[{"trd":[[1.76,913.69]],"batb":[[0,1.74,37.51],[2,1.72,53.77]],"batl":[[0,1.76,55.61],[1,1.8,87.92],[2,1.81,16.58]],"ltp":1.76,"tv":28363.78,"id":9323645}],"tv":41389.67}]}
{"op":"mcm","clk":"4216799212","pt":1631555432177,"mc":[{"id":"1.187566733","rc":[{"batb":[[0,2.22,33.57],[1,1.91,45.39],[2,1.88,27.86]],"batl":[[1,2.42,0],[2,2.46,0]],"ltp":2.3,"tv":13025.88,"id":8734382},{"trd":[[1.74,52.18]],"batb":[[0,1.66,41.12],[1,1.6,256.02],[2,1.46,174.76]],"batl":[[0,1.76,158.7],[1,1.89,256.02],[2,2.1,62.49]],"ltp":1.74,"tv":28363.9,"id":9323645}],"tv":41389.79}]}
{"op":"mcm","clk":"4216799246","pt":1631555432592,"mc":[{"id":"1.187566733","rc":[{"batb":[[0,1.91,45.39],[1,1.88,27.86],[2,1.84,48.72]],"ltp":2.3,"tv":13025.88,"id":8734382},{"batb":[[0,1.6,256.02],[1,1.46,174.76],[2,1.45,118.24]],"batl":[[0,1.89,256.02],[1,2.1,62.49],[2,2.12,62.94]],"ltp":1.74,"tv":28363.9,"id":9323645}]}]}
{"op":"mcm","clk":"4216799851","pt":1631555439188,"mc":[{"id":"1.187566733","rc":[{"trd":[[2.12,745.08]],"batb":[[0,1.88,27.86],[1,1.82,47.64],[2,1.5,108]],"ltp":2.12,"tv":13037.88,"id":8734382},{"trd":[[1.89,975.07]],"batl":[[0,1.89,242.56],[1,880,0.48],[2,2.12,0]],"ltp":1.89,"tv":28377.36,"id":9323645}],"tv":41415.24}]}
{"op":"mcm","clk":"4216799918","pt":1631555440119,"mc":[{"id":"1.187566733","rc":[{"batb":[[0,1.46,174.76],[1,1.45,118.24],[2,1.4,79.98]],"ltp":1.89,"tv":28377.36,"id":9323645}]}]}
{"op":"mcm","clk":"4216800062","pt":1631555441902,"mc":[{"id":"1.187566733","rc":[{"batb":[[0,2.9,41.38],[1,1.88,27.86],[2,1.82,47.64]],"ltp":2.12,"tv":13037.88,"id":8734382},{"batb":[[2,1.43,870.12]],"batl":[[0,1.5,99.77],[1,1.51,158.47],[2,1.52,36.39]],"ltp":1.89,"tv":28377.36,"id":9323645}]}]}
{"op":"mcm","clk":"4216800164","pt":1631555443010,"mc":[{"id":"1.187566733","rc":[{"batb":[[0,2.94,38.52],[1,2.9,41.38],[2,2.6,21.57]],"batl":[[0,3.35,2.99]],"ltp":2.12,"tv":13037.88,"id":8734382},{"batb":[[1,1.45,138.92],[2,1.44,10.34]],"batl":[[1,1.51,118.73],[2,1.52,16.52]],"ltp":1.89,"tv":28377.36,"id":9323645}]}]}
{"op":"mcm","clk":"4216800250","pt":1631555444007,"mc":[{"id":"1.187566733","rc":[{"trd":[[3,38.06]],"ltp":3.0,"tv":13039.88,"id":8734382},{"trd":[[1.5,178.87]],"batl":[[0,1.5,95.77]],"ltp":1.5,"tv":28381.36,"id":9323645}],"tv":41421.24}]}
{"op":"mcm","clk":"4216800316","pt":1631555444791,"mc":[{"id":"1.187566733","rc":[{"batb":[[0,3.1,8.23],[1,2.94,38.52],[2,2.9,41.38]],"batl":[[0,3.2,5.31],[1,3.35,2.99]],"ltp":3.0,"tv":13039.88,"id":8734382}]}]}
{"op":"mcm","clk":"4216800408","pt":1631555446208,"mc":[{"id":"1.187566733","rc":[{"trd":[[3.1,8.81]],"batb":[[0,3.1,4.3]],"ltp":3.1,"tv":13047.74,"id":8734382},{"batb":[[0,1.47,44.5],[1,1.46,174.76],[2,1.45,138.92]],"ltp":1.5,"tv":28381.36,"id":9323645}],"tv":41429.1}]}
{"op":"mcm","clk":"4216800455","pt":1631555446726,"mc":[{"id":"1.187566733","rc":[{"trd":[[3.1,17.41]],"batb":[[0,2.94,38.52],[1,2.9,41.38],[2,2.6,21.57]],"ltp":3.1,"tv":13056.34,"id":8734382}],"tv":41437.7}]}
{"op":"mcm","clk":"4216800572","pt":1631555447931,"mc":[{"id":"1.187566733","rc":[{"batb":[[0,1.47,59.23]],"batl":[[0,1.49,100],[1,1.5,95.77],[2,1.51,118.73]],"ltp":1.5,"tv":28381.36,"id":9323645}]}]}
{"op":"mcm","clk":"4216800690","pt":1631555449130,"mc":[{"id":"1.187566733","rc":[{"batb":[[2,2.62,5.54]],"batl":[[0,3.1,23.78],[1,3.2,5.31],[2,3.35,2.99]],"ltp":3.1,"tv":13056.34,"id":8734382},{"batb":[[0,1.47,73.97]],"ltp":1.5,"tv":28381.36,"id":9323645}]}]}
{"op":"mcm","clk":"4216800778","pt":1631555450130,"mc":[{"id":"1.187566733","rc":[{"batb":[[0,1.48,17.2],[1,1.47,73.97],[2,1.46,174.76]],"ltp":1.5,"tv":28381.36,"id":9323645}]}]}
{"op":"mcm","clk":"4216800812","pt":1631555450711,"mc":[{"id":"1.187566733","rc":[{"trd":[[3,45.33]],"ltp":3.0,"tv":13063.61,"id":8734382},{"trd":[[1.49,105.31]],"batb":[[2,1.46,222.45]],"batl":[[0,1.49,85.36]],"ltp":1.49,"tv":28396.0,"id":9323645}],"tv":41459.61}]}
{"op":"mcm","clk":"4216800910","pt":1631555452026,"mc":[{"id":"1.187566733","rc":[{"trd":[[3,115.5]],"ltp":3.0,"tv":13133.78,"id":8734382},{"trd":[[1.49,190.67],[1.5,234.42]],"batb":[[2,1.46,161.82]],"batl":[[0,1.51,118.73],[1,1.52,16.52],[2,1.53,9.94]],"ltp":1.5,"tv":28536.91,"id":9323645}],"tv":41670.69}]}
{"op":"mcm","clk":"4216801013","pt":1631555453536,"mc":[{"id":"1.187566733","rc":[{"batl":[[0,3,2],[1,3.1,23.78],[2,3.2,5.31]],"ltp":3.0,"tv":13133.78,"id":8734382}]}]}
{"op":"mcm","clk":"4216801141","pt":1631555455042,"mc":[{"id":"1.187566733","rc":[{"batb":[[0,1.48,60.63],[1,1.47,167.86]],"batl":[[0,1.51,185.11],[1,1.52,112.3]],"ltp":1.5,"tv":28536.91,"id":9323645}]}]}
{"op":"mcm","clk":"4216801213","pt":1631555455920,"mc":[{"id":"1.187566733","rc":[{"batl":[[0,3.1,23.78],[1,3.2,5.31],[2,3.35,2.99]],"ltp":3.0,"tv":13133.78,"id":8734382},{"batl":[[0,1.51,118.73],[1,1.52,16.52]],"ltp":1.5,"tv":28536.91,"id":9323645}]}]}
{"op":"mcm","clk":"4216801299","pt":1631555456909,"mc":[{"id":"1.187566733","rc":[{"batl":[[1,3.35,2.99],[2,3.35,0]],"ltp":3.0,"tv":13133.78,"id":8734382},{"trd":[[1.48,521.97],[1.49,190.69]],"batb":[[0,1.48,61.2]],"batl":[[0,1.5,70.98],[1,1.51,118.73],[2,1.52,16.52]],"ltp":1.48,"tv":28564.61,"id":9323645}],"tv":41698.39}]}
{"op":"mcm","clk":"4216801392","pt":1631555458009,"mc":[{"id":"1.187566733","rc":[{"batb":[[1,1.47,182.59]],"ltp":1.48,"tv":28564.61,"id":9323645}]}]}
{"op":"mcm","clk":"4216801442","pt":1631555458524,"mc":[{"id":"1.187566733","rc":[{"batl":[[1,1.51,239.73]],"ltp":1.48,"tv":28564.61,"id":9323645}]}]}
{"op":"mcm","clk":"4216801570","pt":1631555459828,"mc":[{"id":"1.187566733","rc":[{"trd":[[3,117.5],[3.05,1.73]],"ltp":3.0,"tv":13137.51,"id":8734382},{"trd":[[1.49,194.23],[1.5,238.42]],"batl":[[0,1.5,66.98]],"ltp":1.5,"tv":28572.16,"id":9323645}],"tv":41709.67}]}
{"op":"mcm","clk":"4216801625","pt":1631555460516,"mc":[{"id":"1.187566733","rc":[{"trd":[[1.48,624.21]],"batb":[[0,1.48,10.08]],"batl":[[0,1.51,239.73],[1,1.52,16.52],[2,1.53,9.94]],"ltp":1.48,"tv":28674.4,"id":9323645}],"tv":41811.91}]}
{"op":"mcm","clk":"4216801723","pt":1631555461512,"mc":[{"id":"1.187566733","rc":[{"batl":[[0,1.51,118.73]],"ltp":1.48,"tv":28674.4,"id":9323645}]}]}
{"op":"mcm","clk":"4216801821","pt":1631555462720,"mc":[{"id":"1.187566733","rc":[{"batb":[[0,3.05,7.13],[1,2.94,38.52],[2,2.9,41.38]],"batl":[[1,3.15,6.81],[2,3.35,2.99]],"ltp":3.0,"tv":13137.51,"id":8734382}]}]}
{"op":"mcm","clk":"4216801915","pt":1631555463712,"mc":[{"id":"1.187566733","rc":[{"batb":[[0,1.48,50.51]],"batl":[[0,1.51,187.01],[1,1.52,112.3]],"ltp":1.48,"tv":28674.4,"id":9323645}]}]}
{"op":"mcm","clk":"4216802067","pt":1631555465133,"mc":[{"id":"1.187566733","rc":[{"batl":[[0,1.5,186],[1,1.51,187.01],[2,1.52,112.3]],"ltp":1.48,"tv":28674.4,"id":9323645}]}]}
{"op":"mcm","clk":"4216802203","pt":1631555466137,"mc":[{"id":"1.187566733","rc":[{"trd":[[1.48,725.23]],"batb":[[0,1.47,182.59],[1,1.46,161.82],[2,1.45,20.68]],"batl":[[0,1.48,1.91],[1,1.5,271.34],[2,1.51,187.01]],"ltp":1.48,"tv":28775.42,"id":9323645}],"tv":41912.93}]}
{"op":"mcm","clk":"4216802263","pt":1631555466713,"mc":[{"id":"1.187566733","rc":[{"batl":[[0,1.48,1.86]],"ltp":1.48,"tv":28775.42,"id":9323645}]}]}
{"op":"mcm","clk":"4216802549","pt":1631555469040,"mc":[{"id":"1.187566733","rc":[{"trd":[[1.48,728.95]],"batb":[[0,1.48,43.23],[1,1.47,138.39],[2,1.46,161.82]],"batl":[[0,1.49,33.19],[1,1.5,304.38]],"ltp":1.48,"tv":28779.14,"id":9323645}],"tv":41916.65}]}
{"op":"mcm","clk":"4216802637","pt":1631555470033,"mc":[{"id":"1.187566733","rc":[{"batb":[[0,2.94,38.52],[1,2.9,41.38],[2,2.62,5.54]],"batl":[[1,3.35,2.99],[2,3.35,0]],"ltp":3.0,"tv":13137.51,"id":8734382},{"trd":[[1.48,778.95]],"batb":[[0,1.48,18.23]],"ltp":1.48,"tv":28829.14,"id":9323645}],"tv":41966.65}]}
{"op":"mcm","clk":"4216802713","pt":1631555470961,"mc":[{"id":"1.187566733","rc":[{"trd":[[1.49,202.57]],"batl":[[0,1.49,29.02]],"ltp":1.49,"tv":28837.48,"id":9323645}],"tv":41974.99}]}
{"op":"mcm","clk":"4216802916","pt":1631555473162,"mc":[{"id":"1.187566733","rc":[{"batb":[[0,3.05,5.4],[1,2.94,38.52],[2,2.9,41.38]],"ltp":3.0,"tv":13137.51,"id":8734382},{"batb":[[1,1.47,150.09]],"batl":[[1,1.5,233.28]],"ltp":1.49,"tv":28837.48,"id":9323645}]}]}
{"op":"mcm","clk":"4216802954","pt":1631555473635,"mc":[{"id":"1.187566733","rc":[{"trd":[[1.49,203.47]],"batl":[[0,1.49,28.57]],"ltp":1.49,"tv":28838.38,"id":9323645}],"tv":41975.89}]}
{"op":"mcm","clk":"4216803039","pt":1631555474666,"mc":[{"id":"1.187566733","rc":[{"trd":[[1.49,205.39]],"batl":[[0,1.49,27.61]],"ltp":1.49,"tv":28840.3,"id":9323645}],"tv":41977.81}]}
{"op":"mcm","clk":"4216803173","pt":1631555476159,"mc":[{"id":"1.187566733","rc":[{"trd":[[3,123.27],[3.05,15.82]],"batb":[[0,2.94,38.52],[1,2.9,41.38],[2,2.62,5.54]],"batl":[[0,3.05,20]],"ltp":3.0,"tv":13157.36,"id":8734382},{"trd":[[1.48,822.18],[1.49,217]],"batb":[[0,1.47,150.09],[1,1.46,161.82],[2,1.45,20.68]],"batl":[[0,1.49,16]],"ltp":1.49,"tv":28895.14,"id":9323645}],"tv":42052.5}]}
{"op":"mcm","clk":"4216803264","pt":1631555477160,"mc":[{"id":"1.187566733","rc":[{"trd":[[3.05,35.82]],"batb":[[0,2.62,5.54],[1,2.6,21.57],[2,2.58,5.06]],"batl":[[0,3.05,24.18],[1,3.35,0]],"ltp":3.05,"tv":13177.36,"id":8734382},{"trd":[[1.47,426.6],[1.48,863.4]],"batb":[[0,1.46,48.07],[1,1.43,256.02],[2,1.34,95.67]],"batl":[[1,1.5,219.04],[2,1.56,256.02]],"ltp":1.47,"tv":29024.6,"id":9323645}],"tv":42201.96}]}
{"op":"mcm","clk":"4216803309","pt":1631555477550,"mc":[{"id":"1.187566733","rc":[{"batb":[[0,1.43,256.02],[1,1.34,95.67],[2,1.32,12.7]],"batl":[[0,1.56,256.02],[1,1.61,59.5],[2,1.63,64.5]],"ltp":1.47,"tv":29024.6,"id":9323645}]}]}
{"op":"mcm","clk":"4216803515","pt":1631555479946,"mc":[{"id":"1.187566733","rc":[{"trd":[[3.05,42.81]],"batl":[[0,3.05,17.18]],"ltp":3.05,"tv":13184.36,"id":8734382},{"trd":[[1.48,877.83]],"batb":[[1,1.4,197.47],[2,1.39,143.3]],"batl":[[2,1.63,181.26]],"ltp":1.48,"tv":29039.02,"id":9323645}],"tv":42223.39}]}
{"op":"mcm","clk":"4216803596","pt":1631555480944,"mc":[{"id":"1.187566733","rc":[{"batb":[[0,2.62,26.77],[1,2.58,5.06],[2,2.52,5.99]],"ltp":3.05,"tv":13184.36,"id":8734382}]}]}
{"op":"mcm","clk":"4216803660","pt":1631555481579,"mc":[{"id":"1.187566733","rc":[{"trd":[[1.48,897.83]],"batb":[[0,1.48,41],[1,1.43,256.02],[2,1.4,197.47]],"ltp":1.48,"tv":29059.02,"id":9323645}],"tv":42243.39}]}
{"op":"mcm","clk":"4216803764","pt":1631555482583,"mc":[{"id":"1.187566733","rc":[{"trd":[[1.48,957.83]],"batb":[[0,1.48,11]],"ltp":1.48,"tv":29119.02,"id":9323645}],"tv":42303.39}]}
{"op":"mcm","clk":"4216804512","pt":1631555489957,"mc":[{"id":"1.187566733","rc":[{"trd":[[3.05,56.89]],"batl":[[0,3.05,3.11]],"ltp":3.05,"tv":13198.43,"id":8734382},{"trd":[[1.48,1008.83]],"batb":[[0,1.43,256.02],[1,1.4,197.47],[2,1.39,143.3]],"ltp":1.48,"tv":29170.02,"id":9323645}],"tv":42368.46}]}
{"op":"mcm","clk":"4216804713","pt":1631555492055,"mc":[{"id":"1.187566733","rc":[{"batb":[[0,1.4,197.47],[1,1.39,143.3],[2,1.34,95.67]],"batl":[[2,1.63,64.5]],"ltp":1.48,"tv":29170.02,"id":9323645}]}]}
{"op":"mcm","clk":"4216804986","pt":1631555494989,"mc":[{"id":"1.187566733","rc":[{"trd":[[3.05,59.99]],"batb":[[0,3.3,36.36],[1,3.25,7.32],[2,3.2,12.37]],"batl":[[0,3.5,130.75]],"ltp":3.05,"tv":13201.54,"id":8734382},{"trd":[[1.48,1015.23]],"batb":[[0,1.42,19.26],[1,1.4,524.35],[2,1.39,143.3]],"batl":[[0,1.44,153.69],[1,1.45,260.79],[2,1.46,31.03]],"ltp":1.48,"tv":29176.42,"id":9323645}],"tv":42377.97}]}
{"op":"mcm","clk":"4216805060","pt":1631555495777,"mc":[{"id":"1.187566733","rc":[{"batb":[[2,3.2,42.58]],"batl":[[1,3.55,8.44],[2,3.6,7]],"ltp":3.05,"tv":13201.54,"id":8734382},{"batl":[[1,1.45,219.41],[2,1.46,10.34]],"ltp":1.48,"tv":29176.42,"id":9323645}]}]}
{"op":"mcm","clk":"4216805184","pt":1631555497191,"mc":[{"id":"1.187566733","rc":[{"trd":[[1.44,484.29]],"batl":[[0,1.44,149.42]],"ltp":1.44,"tv":29184.96,"id":9323645}],"tv":42386.5}]}
{"op":"mcm","clk":"4216805338","pt":1631555498901,"mc":[{"id":"1.187566733","rc":[{"batb":[[0,1.42,46.13],[1,1.41,16.89],[2,1.4,524.35]],"batl":[[0,1.44,312.37]],"ltp":1.44,"tv":29184.96,"id":9323645}]}]}
{"op":"mcm","clk":"4216805471","pt":1631555500099,"mc":[{"id":"1.187566733","rc":[{"trd":[[3.3,47.48]],"batb":[[0,3.3,24.62]],"ltp":3.3,"tv":13225.02,"id":8734382},{"batb":[[1,1.41,272.91]],"ltp":1.44,"tv":29184.96,"id":9323645}],"tv":42409.98}]}
{"op":"mcm","clk":"4216805588","pt":1631555501459,"mc":[{"id":"1.187566733","rc":[{"batl":[[2,3.6,10.16]],"ltp":3.3,"tv":13225.02,"id":8734382}]}]}
{"op":"mcm","clk":"4216805955","pt":1631555504975,"mc":[{"id":"1.187566733","rc":[{"trd":[[1.44,485.19]],"batl":[[0,1.44,311.92]],"ltp":1.44,"tv":29185.86,"id":9323645}],"tv":42410.88}]}
{"op":"mcm","clk":"4216806251","pt":1631555508581,"mc":[{"id":"1.187566733","rc":[{"trd":[[1.44,486.99]],"batl":[[0,1.44,311.02]],"ltp":1.44,"tv":29187.66,"id":9323645}],"tv":42412.68}]}
{"op":"mcm","clk":"4216806389","pt":1631555510196,"mc":[{"id":"1.187566733","rc":[{"batb":[[0,3,5],[1,2.88,4.21],[2,2.86,41.37]],"batl":[[0,3.6,3.16],[1,3.75,3.1],[2,3.6,0]],"ltp":3.3,"tv":13225.02,"id":8734382},{"batb":[[0,1.41,272.91],[1,1.39,70.91],[2,1.37,62.77]],"batl":[[0,1.44,110],[1,1.48,256.02],[2,1.5,72.51]],"ltp":1.44,"tv":29187.66,"id":9323645}]}]}
{"op":"mcm","clk":"4216806439","pt":1631555510811,"mc":[{"id":"1.187566733","rc":[{"batb":[[0,1.41,256.02]],"batl":[[0,1.48,256.02],[1,1.5,72.51],[2,1.53,69.5]],"ltp":1.44,"tv":29187.66,"id":9323645}]}]}
{"op":"mcm","clk":"4216806555","pt":1631555512011,"mc":[{"id":"1.187566733","rc":[{"batl":[[0,1.42,172.44],[1,1.48,256.02],[2,1.5,72.51]],"ltp":1.44,"tv":29187.66,"id":9323645}]}]}
{"op":"mcm","clk":"4216807193","pt":1631555519116,"mc":[{"id":"1.187566733","rc":[{"batl":[[0,3.45,160.98],[1,3.6,3.16],[2,3.75,3.1]],"ltp":3.3,"tv":13225.02,"id":8734382},{"batl":[[0,1.48,256.02],[1,1.5,72.51],[2,1.53,69.5]],"ltp":1.44,"tv":29187.66,"id":9323645}]}]}
{"op":"mcm","clk":"4216807287","pt":1631555520013,"mc":[{"id":"1.187566733","rc":[{"batl":[[0,3.6,3.16],[1,3.75,3.1],[2,3.75,0]],"ltp":3.3,"tv":13225.02,"id":8734382},{"batb":[[0,1.42,141.85],[1,1.41,389.63],[2,1.39,70.91]],"batl":[[0,1.46,178.04],[1,1.47,109.68],[2,1.48,256.02]],"ltp":1.44,"tv":29187.66,"id":9323645}]}]}
{"op":"mcm","clk":"4216807385","pt":1631555521206,"mc":[{"id":"1.187566733","rc":[{"batb":[[0,1.41,256.02],[1,1.39,70.91],[2,1.37,62.77]],"batl":[[0,1.48,256.02],[1,1.5,72.51],[2,1.53,69.5]],"ltp":1.44,"tv":29187.66,"id":9323645}]}]}
{"op":"mcm","clk":"4216807460","pt":1631555521991,"mc":[{"id":"1.187566733","rc":[{"trd":[[1.42,1343.48]],"batb":[[0,1.42,83.57],[1,1.41,256.02],[2,1.39,70.91]],"ltp":1.42,"tv":29532.55,"id":9323645}],"tv":42757.57}]}
{"op":"mcm","clk":"4216807646","pt":1631555524124,"mc":[{"id":"1.187566733","rc":[{"batl":[[2,1.53,191.67]],"ltp":1.42,"tv":29532.55,"id":9323645}]}]}
{"op":"mcm","clk":"4216807903","pt":1631555526725,"mc":[{"id":"1.187566733","rc":[{"batb":[[0,1.41,256.02],[1,1.39,70.91],[2,1.37,62.77]],"ltp":1.42,"tv":29532.55,"id":9323645}]}]}
{"op":"mcm","clk":"4216808032","pt":1631555528330,"mc":[{"id":"1.187566733","rc":[{"batl":[[0,1.43,171.24],[1,1.48,256.02],[2,1.5,72.51]],"ltp":1.42,"tv":29532.55,"id":9323645}]}]}
{"op":"mcm","clk":"4216808553","pt":1631555534716,"mc":[{"id":"1.187566733","rc":[{"trd":[[1.41,1749.11]],"batb":[[0,1.41,227.42]],"ltp":1.41,"tv":29589.74,"id":9323645}],"tv":42814.77}]}
{"op":"mcm","clk":"4216809223","pt":1631555542031,"mc":[{"id":"1.187566733","rc":[{"batl":[[0,3.75,3.1],[1,3.75,0]],"ltp":3.3,"tv":13225.02,"id":8734382},{"batb":[[0,1.37,62.77],[1,1.36,117],[2,1.35,164.26]],"ltp":1.41,"tv":29589.74,"id":9323645}]}]}
{"op":"mcm","clk":"4216809397","pt":1631555544116,"mc":[{"id":"1.187566733","rc":[{"batb":[[0,3.5,11.38],[1,3.45,101.46],[2,3.4,214.48]],"batl":[[0,3.6,5.1],[1,3.75,242.41]],"ltp":3.3,"tv":13225.02,"id":8734382},{"batl":[[0,1.39,159.27],[1,1.4,227.24],[2,1.43,178.23]],"ltp":1.41,"tv":29589.74,"id":9323645}]}]}
{"op":"mcm","clk":"4216809481","pt":1631555544950,"mc":[{"id":"1.187566733","rc":[{"batb":[[1,3.45,55.08]],"batl":[[2,3.9,2.56]],"ltp":3.3,"tv":13225.02,"id":8734382},{"trd":[[1.39,1118.75]],"batb":[[1,1.36,227.28],[2,1.35,219.4]],"batl":[[0,1.39,159.21],[2,1.43,6.99]],"ltp":1.39,"tv":29589.86,"id":9323645}],"tv":42814.89}]}
{"op":"mcm","clk":"4216809558","pt":1631555545531,"mc":[{"id":"1.187566733","rc":[{"batb":[[1,3.45,63.12],[2,3.4,205.78]],"ltp":3.3,"tv":13225.02,"id":8734382},{"batb":[[1,1.36,139.06],[2,1.35,175.28]],"ltp":1.39,"tv":29589.86,"id":9323645}]}]}
{"op":"mcm","clk":"4216809793","pt":1631555547626,"mc":[{"id":"1.187566733","rc":[{"trd":[[1.39,1153.03]],"batl":[[0,1.39,142.07]],"ltp":1.39,"tv":29624.14,"id":9323645}],"tv":42849.17}]}
{"op":"mcm","clk":"4216809927","pt":1631555549133,"mc":[{"id":"1.187566733","rc":[{"trd":[[3.55,68.46]],"ltp":3.55,"tv":13241.11,"id":8734382},{"trd":[[1.39,1194.12]],"batb":[[0,1.37,106.53]],"batl":[[0,1.39,167.13]],"ltp":1.39,"tv":29665.23,"id":9323645}],"tv":42906.35}]}
{"op":"mcm","clk":"4216810028","pt":1631555550129,"mc":[{"id":"1.187566733","rc":[{"trd":[[3.6,5.12]],"batl":[[0,3.75,242.41],[1,3.9,2.56],[2,3.9,0]],"ltp":3.6,"tv":13246.21,"id":8734382},{"trd":[[1.38,555.02]],"batl":[[0,1.38,193.36],[1,1.39,167.13],[2,1.4,227.24]],"ltp":1.38,"tv":29678.54,"id":9323645}],"tv":42924.75}]}
{"op":"mcm","clk":"4216810104","pt":1631555551115,"mc":[{"id":"1.187566733","rc":[{"batl":[[1,3.8,3.02],[2,3.9,5.61]],"ltp":3.6,"tv":13246.21,"id":8734382},{"batb":[[1,1.36,217.74],[2,1.35,240.75]],"batl":[[1,1.39,317.13]],"ltp":1.38,"tv":29678.54,"id":9323645}]}]}
{"op":"mcm","clk":"4216810226","pt":1631555552361,"mc":[{"id":"1.187566733","rc":[{"batb":[[1,1.36,241.03]],"batl":[[1,1.39,343.21]],"ltp":1.38,"tv":29678.54,"id":9323645}]}]}
{"op":"mcm","clk":"4216810423","pt":1631555554149,"mc":[{"id":"1.187566733","rc":[{"batl":[[0,1.38,257.38]],"ltp":1.38,"tv":29678.54,"id":9323645}]}]}
{"op":"mcm","clk":"4216810586","pt":1631555555862,"mc":[{"id":"1.187566733","rc":[{"batb":[[1,1.36,538.4]],"ltp":1.38,"tv":29678.54,"id":9323645}]}]}
{"op":"mcm","clk":"4216810917","pt":1631555559167,"mc":[{"id":"1.187566733","rc":[{"trd":[[1.37,1696.28]],"batb":[[0,1.36,538.4],[1,1.35,240.75],[2,1.34,88.74]],"batl":[[0,1.37,97.57],[1,1.38,257.38],[2,1.39,193.21]],"ltp":1.37,"tv":29891.6,"id":9323645}],"tv":43137.81}]}
{"op":"mcm","clk":"4216811067","pt":1631555561062,"mc":[{"id":"1.187566733","rc":[{"batl":[[0,1.37,197.57]],"ltp":1.37,"tv":29891.6,"id":9323645}]}]}
{"op":"mcm","clk":"4216811153","pt":1631555562058,"mc":[{"id":"1.187566733","rc":[{"trd":[[1.36,1861.71],[1.37,1873.08]],"batb":[[0,1.36,130.5]],"batl":[[0,1.37,109.17]],"ltp":1.36,"tv":30884.19,"id":9323645}],"tv":44130.4}]}
{"op":"mcm","clk":"4216811266","pt":1631555563160,"mc":[{"id":"1.187566733","rc":[{"batl":[[0,1.37,100]],"ltp":1.36,"tv":30884.19,"id":9323645}]}]}
{"op":"mcm","clk":"4216811275","pt":1631555563271,"mc":[{"id":"1.187566733","rc":[{"trd":[[3.7,162.96]],"batb":[[0,3.55,4.98],[1,3.5,11.38],[2,3.45,63.12]],"ltp":3.7,"tv":13255.61,"id":8734382},{"trd":[[1.37,1898.47]],"batl":[[0,1.37,74.61]],"ltp":1.37,"tv":30909.58,"id":9323645}],"tv":44165.19}]}
{"op":"mcm","clk":"4216811498","pt":1631555565573,"mc":[{"id":"1.187566733","rc":[{"batb":[[1,1.35,308.5],[2,1.34,261.23]],"batl":[[0,1.37,154.87],[2,1.39,274.15]],"ltp":1.37,"tv":30909.58,"id":9323645}]}]}
{"op":"mcm","clk":"4216811844","pt":1631555569161,"mc":[{"id":"1.187566733","rc":[{"batb":[[0,3.3,3.48],[1,3.2,4.07],[2,3.15,31.81]],"batl":[[0,3.95,3.1],[1,4.1,2.55],[2,3.9,0]],"ltp":3.7,"tv":13255.61,"id":8734382},{"trd":[[1.37,2129.11]],"batb":[[1,1.34,77.72],[2,1.33,75.53]],"batl":[[0,1.37,345.77],[1,1.38,193.36],[2,1.43,74.5]],"ltp":1.37,"tv":31140.21,"id":9323645}],"tv":44395.83}]}
{"op":"mcm","clk":"4216811938","pt":1631555570061,"mc":[{"id":"1.187566733","rc":[{"trd":[[1.37,2139.35]],"batl":[[0,1.37,133.77]],"ltp":1.37,"tv":31150.45,"id":9323645}],"tv":44406.07}]}
{"op":"mcm","clk":"4216812107","pt":1631555571878,"mc":[{"id":"1.187566733","rc":[{"trd":[[1.36,1919.52]],"batb":[[0,1.36,101.6]],"ltp":1.36,"tv":31208.27,"id":9323645}],"tv":44463.88}]}
{"op":"mcm","clk":"4216812342","pt":1631555574177,"mc":[{"id":"1.187566733","rc":[{"batl":[[0,4.1,2.55],[1,4.1,0]],"ltp":3.7,"tv":13255.61,"id":8734382},{"batb":[[0,1.33,75.53],[1,1.32,261.47],[2,1.31,194.54]],"ltp":1.36,"tv":31208.27,"id":9323645}]}]}
{"op":"mcm","clk":"4216812587","pt":1631555576181,"mc":[{"id":"1.187566733","rc":[{"batb":[[0,3.65,54.8],[1,3.3,3.48],[2,3.2,4.07]],"batl":[[0,3.9,169.17],[1,4,8.71],[2,4.1,2.55]],"ltp":3.7,"tv":13255.61,"id":8734382},{"batl":[[0,1.36,137.33],[1,1.37,188.91],[2,1.38,2715.82]],"ltp":1.36,"tv":31208.27,"id":9323645}]}]}
{"op":"mcm","clk":"4216812701","pt":1631555577171,"mc":[{"id":"1.187566733","rc":[{"batb":[[1,3.6,18.24],[2,3.3,3.48]],"batl":[[1,4.1,4.99],[2,4.2,35.72]],"ltp":3.7,"tv":13255.61,"id":8734382},{"batl":[[0,1.35,100.56],[1,1.36,179.04],[2,1.37,11.02]],"ltp":1.36,"tv":31208.27,"id":9323645}]}]}
{"op":"mcm","clk":"4216812728","pt":1631555577580,"mc":[{"id":"1.187566733","rc":[{"batb":[[0,3.65,77.12],[2,3.45,25.76]],"batl":[[2,4.2,7.14]],"ltp":3.7,"tv":13255.61,"id":8734382}]}]}
{"op":"mcm","clk":"4216812937","pt":1631555580003,"mc":[{"id":"1.187566733","rc":[{"batl":[[1,4,8.71],[2,4.1,4.99]],"ltp":3.7,"tv":13255.61,"id":8734382},{"batl":[[1,1.36,206.09]],"ltp":1.36,"tv":31208.27,"id":9323645}]}]}
{"op":"mcm","clk":"4216813082","pt":1631555581200,"mc":[{"id":"1.187566733","rc":[{"trd":[[3.85,343.09],[3.9,20.37]],"batl":[[0,3.9,167.93]],"ltp":3.85,"tv":13265.16,"id":8734382},{"trd":[[1.34,927.43],[1.35,3559.32]],"batb":[[0,1.33,98.82]],"batl":[[0,1.35,161.74]],"ltp":1.35,"tv":31235.58,"id":9323645}],"tv":44500.74}]}
{"op":"mcm","clk":"4216813176","pt":1631555582196,"mc":[{"id":"1.187566733","rc":[{"trd":[[3.9,79.2]],"batl":[[0,3.9,109.1]],"ltp":3.9,"tv":13323.99,"id":8734382},{"trd":[[1.34,1098.65]],"batb":[[0,1.33,354.84],[1,1.32,197.04],[2,1.29,23.88]],"ltp":1.34,"tv":31406.8,"id":9323645}],"tv":44730.79}]}
{"op":"mcm","clk":"4216813344","pt":1631555583766,"mc":[{"id":"1.187566733","rc":[{"batb":[[2,3.5,6.28]],"ltp":3.9,"tv":13323.99,"id":8734382},{"batb":[[1,1.32,276.68]],"ltp":1.34,"tv":31406.8,"id":9323645}]}]}
{"op":"mcm","clk":"4216813490","pt":1631555585189,"mc":[{"id":"1.187566733","rc":[{"batb":[[0,3.65,22.32],[1,3.5,6.28],[2,3.45,25.76]],"batl":[[0,4.1,2.55],[1,4.2,3.03],[2,4.1,0]],"ltp":3.9,"tv":13323.99,"id":8734382},{"batb":[[0,1.33,331.55],[1,1.32,92.34]],"batl":[[0,1.35,155],[1,1.4,138.94],[2,1.43,74.5]],"ltp":1.34,"tv":31406.8,"id":9323645}]}]}
{"op":"mcm","clk":"4216813503","pt":1631555585290,"mc":[{"id":"1.187566733","rc":[{"batb":[[0,3.5,6.28],[1,3.45,25.76],[2,3.3,3.48]],"ltp":3.9,"tv":13323.99,"id":8734382}]}]}
{"op":"mcm","clk":"4216813659","pt":1631555586804,"mc":[{"id":"1.187566733","rc":[{"batb":[[2,2.2,42.64]],"ltp":3.9,"tv":13323.99,"id":8734382},{"batl":[[0,1.4,138.94],[1,1.72,16],[2,44,7.7]],"ltp":1.34,"tv":31406.8,"id":9323645}]}]}
{"op":"mcm","clk":"4216813795","pt":1631555588178,"mc":[{"id":"1.187566733","rc":[{"batb":[[2,1.31,134.06]],"batl":[[0,1.35,256.02],[1,1.39,184.42],[2,1.4,274.86]],"ltp":1.34,"tv":31406.8,"id":9323645}]}]}
{"op":"mcm","clk":"4216813821","pt":1631555588486,"mc":[{"id":"1.187566733","rc":[{"batb":[[0,3.6,5.74],[1,3.5,6.28],[2,3.45,25.76]],"ltp":3.9,"tv":13323.99,"id":8734382},{"batb":[[2,1.29,23.88]],"batl":[[1,1.38,134.25],[2,1.4,138.94]],"ltp":1.34,"tv":31406.8,"id":9323645}]}]}
{"op":"mcm","clk":"4216814060","pt":1631555591205,"mc":[{"id":"1.187566733","rc":[{"batb":[[0,3.85,21.37],[1,3.6,5.74],[2,3.5,6.28]],"batl":[[0,3.95,19.5],[1,4.1,2.55],[2,4.2,3.03]],"ltp":3.9,"tv":13323.99,"id":8734382},{"batl":[[0,1.35,20.7]],"ltp":1.34,"tv":31406.8,"id":9323645}]}]}
{"op":"mcm","clk":"4216814114","pt":1631555591594,"mc":[{"id":"1.187566733","rc":[{"batb":[[0,3.5,6.28],[1,3.45,25.76],[2,2.2,42.64]],"batl":[[0,4.1,2.55],[1,4.2,3.03],[2,4.2,0]],"ltp":3.9,"tv":13323.99,"id":8734382},{"batb":[[0,1.33,519.31],[1,1.32,278.08]],"batl":[[0,1.36,139.67],[1,1.37,150.9]],"ltp":1.34,"tv":31406.8,"id":9323645}]}]}
{"op":"mcm","clk":"4216814258","pt":1631555592894,"mc":[{"id":"1.187566733","rc":[{"batb":[[0,1.34,256.02],[1,1.33,331.55],[2,1.32,92.34]],"batl":[[0,1.4,138.94],[1,1.72,16],[2,44,7.7]],"ltp":1.34,"tv":31406.8,"id":9323645}]}]}
{"op":"mcm","clk":"4216814341","pt":1631555593890,"mc":[{"id":"1.187566733","rc":[{"batb":[[0,1.35,172.44],[1,1.34,256.02],[2,1.33,331.55]],"ltp":1.34,"tv":31406.8,"id":9323645}]}]}
{"op":"mcm","clk":"4216814437","pt":1631555594989,"mc":[{"id":"1.187566733","rc":[{"batb":[[0,3.6,6.24],[1,3.5,6.28],[2,3.45,25.76]],"ltp":3.9,"tv":13323.99,"id":8734382},{"batl":[[0,1.38,137.25],[1,1.4,138.94],[2,1.72,16]],"ltp":1.34,"tv":31406.8,"id":9323645}]}]}
{"op":"mcm","clk":"4216814542","pt":1631555596107,"mc":[{"id":"1.187566733","rc":[{"batb":[[0,3.5,6.28],[1,3.45,25.76],[2,2.2,42.64]],"ltp":3.9,"tv":13323.99,"id":8734382},{"trd":[[1.35,3904.2]],"batb":[[0,1.35,20.36]],"batl":[[0,1.39,265.04],[1,1.4,274.86]],"ltp":1.35,"tv":31751.68,"id":9323645}],"tv":45075.67}]}
{"op":"mcm","clk":"4216814628","pt":1631555596892,"mc":[{"id":"1.187566733","rc":[{"batb":[[0,1.34,256.02],[1,1.33,331.55],[2,1.32,92.34]],"batl":[[0,1.36,256.02],[1,1.39,184.42],[2,1.4,274.86]],"ltp":1.35,"tv":31751.68,"id":9323645}]}]}
{"op":"mcm","clk":"4216814836","pt":1631555598889,"mc":[{"id":"1.187566733","rc":[{"batl":[[0,1.39,184.42],[1,1.4,274.86],[2,1.72,16]],"ltp":1.35,"tv":31751.68,"id":9323645}]}]}
{"op":"mcm","clk":"4216815038","pt":1631555601189,"mc":[{"id":"1.187566733","rc":[{"batb":[[1,3.45,65.18],[2,3.4,273.94]],"batl":[[0,3.75,226.65],[1,3.9,2.56],[2,4.1,2.55]],"ltp":3.9,"tv":13323.99,"id":8734382},{"batb":[[0,1.36,91.41],[1,1.35,2381.13],[2,1.34,354.55]],"batl":[[0,1.38,12.6],[1,1.39,184.42],[2,1.4,274.86]],"ltp":1.35,"tv":31751.68,"id":9323645}]}]}
{"op":"mcm","clk":"4216815125","pt":1631555602131,"mc":[{"id":"1.187566733","rc":[{"batb":[[1,1.35,436.09],[2,1.34,98.53]],"ltp":1.35,"tv":31751.68,"id":9323645}]}]}
{"op":"mcm","clk":"4216815154","pt":1631555602397,"mc":[{"id":"1.187566733","rc":[{"trd":[[1.36,1928.64]],"batb":[[0,1.36,86.85]],"ltp":1.36,"tv":31760.8,"id":9323645}],"tv":45084.79}]}
{"op":"mcm","clk":"4216815344","pt":1631555604124,"mc":[{"id":"1.187566733","rc":[{"trd":[[1.36,1936.99]],"batb":[[0,1.36,82.68]],"ltp":1.36,"tv":31769.14,"id":9323645}],"tv":45093.14}]}
{"op":"mcm","clk":"4216815398","pt":1631555604604,"mc":[{"id":"1.187566733","rc":[{"batb":[[0,1.37,18.72],[1,1.36,82.68],[2,1.35,436.09]],"batl":[[0,1.38,62.6]],"ltp":1.36,"tv":31769.14,"id":9323645}]}]}
{"op":"mcm","clk":"4216815550","pt":1631555606119,"mc":[{"id":"1.187566733","rc":[{"trd":[[3.6,10.7],[3.75,33.71]],"batl":[[0,3.75,194.65]],"ltp":3.6,"tv":13361.57,"id":8734382},{"trd":[[1.36,2231],[1.37,2176.79],[1.38,569.58]],"batb":[[0,1.35,436.09],[1,1.34,98.53],[2,1.33,173.31]],"batl":[[0,1.38,81.2],[1,1.39,141.9],[2,1.4,138.94]],"ltp":1.38,"tv":32115.15,"id":9323645}],"tv":45476.72}]}
{"op":"mcm","clk":"4216815642","pt":1631555607010,"mc":[{"id":"1.187566733","rc":[{"batb":[[0,1.36,256.02],[1,1.35,436.09],[2,1.34,98.53]],"batl":[[0,1.38,337.22]],"ltp":1.38,"tv":32115.15,"id":9323645}]}]}
{"op":"mcm","clk":"4216815709","pt":1631555607631,"mc":[{"id":"1.187566733","rc":[{"trd":[[1.38,569.7]],"batl":[[0,1.38,337.16]],"ltp":1.38,"tv":32115.27,"id":9323645}],"tv":45476.84}]}
{"op":"mcm","clk":"4216815855","pt":1631555608940,"mc":[{"id":"1.187566733","rc":[{"batb":[[2,3.4,280.45]],"batl":[[1,3.9,5.61],[2,3.95,2.7]],"ltp":3.6,"tv":13361.57,"id":8734382},{"batb":[[1,1.35,549.42],[2,1.34,343.77]],"batl":[[0,1.38,429.72]],"ltp":1.38,"tv":32115.27,"id":9323645}]}]}
{"op":"mcm","clk":"4216816129","pt":1631555611525,"mc":[{"id":"1.187566733","rc":[{"batl":[[0,1.38,549.72]],"ltp":1.38,"tv":32115.27,"id":9323645}]}]}
{"op":"mcm","clk":"4216816283","pt":1631555612933,"mc":[{"id":"1.187566733","rc":[{"batb":[[1,1.35,378.39]],"ltp":1.38,"tv":32115.27,"id":9323645}]}]}
{"op":"mcm","clk":"4216816367","pt":1631555613824,"mc":[{"id":"1.187566733","rc":[{"batl":[[0,1.38,429.72]],"ltp":1.38,"tv":32115.27,"id":9323645}]}]}
{"op":"mcm","clk":"4216816603","pt":1631555616115,"mc":[{"id":"1.187566733","rc":[{"batl":[[0,3.75,188.38]],"ltp":3.6,"tv":13361.57,"id":8734382},{"batb":[[0,1.37,256.02],[1,1.36,276.9],[2,1.35,378.39]],"ltp":1.38,"tv":32115.27,"id":9323645}]}]}
{"op":"mcm","clk":"4216816666","pt":1631555616840,"mc":[{"id":"1.187566733","rc":[{"trd":[[1.37,2688.82]],"batb":[[0,1.36,276.9],[1,1.35,378.39],[2,1.34,343.77]],"batl":[[0,1.37,246.7],[1,1.38,429.72],[2,1.39,141.9]],"ltp":1.37,"tv":32627.3,"id":9323645}],"tv":45988.88}]}
{"op":"mcm","clk":"4216816865","pt":1631555619031,"mc":[{"id":"1.187566733","rc":[{"trd":[[3.7,169.39]],"ltp":3.7,"tv":13368.0,"id":8734382},{"trd":[[1.37,2706.19]],"batl":[[0,1.37,229.33],[2,1.39,159.01]],"ltp":1.37,"tv":32644.67,"id":9323645}],"tv":46012.68}]}
{"op":"mcm","clk":"4216816960","pt":1631555620029,"mc":[{"id":"1.187566733","rc":[{"batl":[[0,1.37,330.71]],"ltp":1.37,"tv":32644.67,"id":9323645}]}]}
{"op":"mcm","clk":"4216817046","pt":1631555620843,"mc":[{"id":"1.187566733","rc":[{"trd":[[1.37,2746.19]],"batl":[[0,1.37,310.71]],"ltp":1.37,"tv":32684.67,"id":9323645}],"tv":46052.68}]}
{"op":"mcm","clk":"4216817217","pt":1631555622644,"mc":[{"id":"1.187566733","rc":[{"trd":[[1.37,2766.19]],"batl":[[0,1.37,555.38]],"ltp":1.37,"tv":32704.67,"id":9323645}],"tv":46072.68}]}
{"op":"mcm","clk":"4216817342","pt":1631555623950,"mc":[{"id":"1.187566733","rc":[{"batb":[[1,3.4,6.51],[2,3.35,6.27]],"batl":[[0,3.95,2.7],[1,4.1,2.55],[2,4.2,3.03]],"ltp":3.7,"tv":13368.0,"id":8734382},{"batb":[[0,1.36,256.02],[1,1.34,72.72],[2,1.33,75.53]],"batl":[[0,1.37,454],[1,1.38,256.02],[2,1.4,138.94]],"ltp":1.37,"tv":32704.67,"id":9323645}]}]}
{"op":"mcm","clk":"4216817423","pt":1631555624952,"mc":[{"id":"1.187566733","rc":[{"batb":[[2,1.33,175.53]],"batl":[[0,1.38,256.02],[1,1.4,138.94],[2,1.41,122.5]],"ltp":1.37,"tv":32704.67,"id":9323645}]}]}
{"op":"mcm","clk":"4216817602","pt":1631555626731,"mc":[{"id":"1.187566733","rc":[{"batb":[[2,1.33,125.53]],"ltp":1.37,"tv":32704.67,"id":9323645}]}]}
{"op":"mcm","clk":"4216817719","pt":1631555628028,"mc":[{"id":"1.187566733","rc":[{"batl":[[0,4.1,2.55],[1,4.2,3.03],[2,4.2,0]],"ltp":3.7,"tv":13368.0,"id":8734382},{"batb":[[0,1.33,125.53],[1,1.32,92.34],[2,1.28,119.67]],"ltp":1.37,"tv":32704.67,"id":9323645}]}]}
{"op":"mcm","clk":"4216817757","pt":1631555628444,"mc":[{"id":"1.187566733","rc":[{"batl":[[1,4.2,0]],"ltp":3.7,"tv":13368.0,"id":8734382},{"batb":[[1,1.32,12.7]],"ltp":1.37,"tv":32704.67,"id":9323645}]}]}
{"op":"mcm","clk":"4216817963","pt":1631555631057,"mc":[{"id":"1.187566733","rc":[{"batb":[[0,3.6,19.44],[1,3.5,6.28],[2,3.4,6.51]],"batl":[[0,3.8,21.67],[1,4.1,2.55]],"ltp":3.7,"tv":13368.0,"id":8734382},{"batb":[[0,1.36,202.65],[1,1.35,166.09],[2,1.33,125.53]],"batl":[[0,1.38,275.27],[1,1.39,80.68],[2,1.4,276.32]],"ltp":1.37,"tv":32704.67,"id":9323645}]}]}
{"op":"mcm","clk":"4216818075","pt":1631555632152,"mc":[{"id":"1.187566733","rc":[{"batb":[[0,3.5,6.28],[1,3.4,6.51],[2,3.35,6.27]],"batl":[[0,3.95,2.9]],"ltp":3.7,"tv":13368.0,"id":8734382},{"trd":[[1.36,2252.68]],"batb":[[0,1.34,66.72],[1,1.33,125.53],[2,1.32,12.7]],"batl":[[0,1.38,256.02],[1,1.4,138.94],[2,1.41,122.5]],"ltp":1.36,"tv":32726.35,"id":9323645}],"tv":46094.36}]}
{"op":"mcm","clk":"4216818121","pt":1631555632629,"mc":[{"id":"1.187566733","rc":[{"batl":[[0,4.1,2.55],[1,4.1,0]],"ltp":3.7,"tv":13368.0,"id":8734382},{"batb":[[0,1.35,256.02]],"ltp":1.36,"tv":32726.35,"id":9323645}]}]}
{"op":"mcm","clk":"4216818206","pt":1631555633560,"mc":[{"id":"1.187566733","rc":[{"batb":[[0,1.36,20],[1,1.35,256.02],[2,1.33,125.53]],"ltp":1.36,"tv":32726.35,"id":9323645}]}]}
{"op":"mcm","clk":"4216818342","pt":1631555635132,"mc":[{"id":"1.187566733","rc":[{"batb":[[0,3.35,6.27],[1,3.15,31.89],[2,2.2,42.64]],"ltp":3.7,"tv":13368.0,"id":8734382},{"batl":[[0,1.42,133.75],[1,1.72,16],[2,44,7.7]],"ltp":1.36,"tv":32726.35,"id":9323645}]}]}
{"op":"mcm","clk":"4216818423","pt":1631555636169,"mc":[{"id":"1.187566733","rc":[{"batl":[[0,3.95,3.5],[1,4.1,2.55]],"ltp":3.7,"tv":13368.0,"id":8734382},{"batb":[[2,1.34,92.09]],"batl":[[1,1.44,146.44],[2,1.45,117.1]],"ltp":1.36,"tv":32726.35,"id":9323645}]}]}
{"op":"mcm","clk":"4216818501","pt":1631555637168,"mc":[{"id":"1.187566733","rc":[{"batb":[[0,1.38,10],[1,1.36,20],[2,1.35,256.02]],"ltp":1.36,"tv":32726.35,"id":9323645}]}]}
{"op":"mcm","clk":"4216818611","pt":1631555638155,"mc":[{"id":"1.187566733","rc":[{"batb":[[0,3.35,13.5],[1,3.15,294.12]],"batl":[[0,3.5,143.8],[1,3.55,2.82],[2,3.95,3.5]],"ltp":3.7,"tv":13368.0,"id":8734382},{"batb":[[0,1.4,784.88],[1,1.39,241.95],[2,1.38,104.96]],"ltp":1.36,"tv":32726.35,"id":9323645}]}]}
{"op":"mcm","clk":"4216818706","pt":1631555638941,"mc":[{"id":"1.187566733","rc":[{"batb":[[2,2.76,18.71]],"ltp":3.7,"tv":13368.0,"id":8734382}]}]}
{"op":"mcm","clk":"4216819005","pt":1631555642140,"mc":[{"id":"1.187566733","rc":[{"batl":[[2,4.1,2.55]],"ltp":3.7,"tv":13368.0,"id":8734382},{"trd":[[1.4,2644.85],[1.41,1750.53]],"batb":[[0,1.4,183.85]],"batl":[[0,1.42,240.87]],"ltp":1.4,"tv":34007.99,"id":9323645}],"tv":47375.99}]}
{"op":"mcm","clk":"4216819033","pt":1631555642448,"mc":[{"id":"1.187566733","rc":[{"trd":[[1.42,1363.48]],"batb":[[1,1.39,497.97]],"batl":[[0,1.42,230.87]],"ltp":1.42,"tv":34027.99,"id":9323645}],"tv":47395.99}]}
{"op":"mcm","clk":"4216819182","pt":1631555644170,"mc":[{"id":"1.187566733","rc":[{"batl":[[1,1.43,256.02],[2,1.44,146.44]],"ltp":1.42,"tv":34027.99,"id":9323645}]}]}
{"op":"mcm","clk":"4216819270","pt":1631555645165,"mc":[{"id":"1.187566733","rc":[{"batb":[[2,3,6.2]],"ltp":3.7,"tv":13368.0,"id":8734382},{"batb":[[0,1.4,212.44]],"batl":[[2,1.44,180.66]],"ltp":1.42,"tv":34027.99,"id":9323645}]}]}
{"op":"mcm","clk":"4216819306","pt":1631555645581,"mc":[{"id":"1.187566733","rc":[{"batb":[[0,1.41,10],[1,1.4,212.44],[2,1.39,497.97]],"batl":[[0,1.42,426.87]],"ltp":1.42,"tv":34027.99,"id":9323645}]}]}
{"op":"mcm","clk":"4216819435","pt":1631555647150,"mc":[{"id":"1.187566733","rc":[{"trd":[[1.41,1755.53]],"batb":[[0,1.41,7.5]],"ltp":1.41,"tv":34032.99,"id":9323645}],"tv":47400.99}]}
{"op":"mcm","clk":"4216819642","pt":1631555648974,"mc":[{"id":"1.187566733","rc":[{"trd":[[1.41,1770.53],[1.42,1364.59]],"batb":[[0,1.4,212.44],[1,1.39,497.97],[2,1.38,94.96]],"batl":[[0,1.41,103.1],[1,1.42,426.31],[2,1.43,256.02]],"ltp":1.41,"tv":34049.11,"id":9323645}],"tv":47417.11}]}
{"op":"mcm","clk":"4216819702","pt":1631555649561,"mc":[{"id":"1.187566733","rc":[{"trd":[[1.41,1777.33]],"batl":[[0,1.41,99.7]],"ltp":1.41,"tv":34055.9,"id":9323645}],"tv":47423.91}]}
{"op":"mcm","clk":"4216819931","pt":1631555652173,"mc":[{"id":"1.187566733","rc":[{"batb":[[0,3.35,6.27]],"batl":[[0,3.5,139.06]],"ltp":3.7,"tv":13368.0,"id":8734382}]}]}
{"op":"mcm","clk":"4216820197","pt":1631555655198,"mc":[{"id":"1.187566733","rc":[{"batb":[[0,3.4,6.3],[1,3.35,6.27],[2,3.15,294.12]],"batl":[[0,3.5,143.81]],"ltp":3.7,"tv":13368.0,"id":8734382}]}]}
{"op":"mcm","clk":"4216820305","pt":1631555656295,"mc":[{"id":"1.187566733","rc":[{"trd":[[1.41,1794.39]],"batl":[[0,1.41,91.17]],"ltp":1.41,"tv":34072.97,"id":9323645}],"tv":47440.97}]}
{"op":"mcm","clk":"4216820614","pt":1631555659794,"mc":[{"id":"1.187566733","rc":[{"trd":[[1.4,2968.71]],"batb":[[0,1.4,50.51]],"ltp":1.4,"tv":34396.83,"id":9323645}],"tv":47764.83}]}
{"op":"mcm","clk":"4216820747","pt":1631555661209,"mc":[{"id":"1.187566733","rc":[{"batb":[[0,3.35,6.27],[1,3.15,31.89],[2,3,6.2]],"batl":[[0,4.1,2.55],[1,3.55,0],[2,4.1,0]],"ltp":3.7,"tv":13368.0,"id":8734382},{"batb":[[1,1.39,400.13],[2,1.35,122.48]],"ltp":1.4,"tv":34396.83,"id":9323645}]}]}
{"op":"mcm","clk":"4216820794","pt":1631555661787,"mc":[{"id":"1.187566733","rc":[{"batb":[[0,3,6.2],[1,2.92,6.44],[2,2.88,6.96]],"ltp":3.7,"tv":13368.0,"id":8734382},{"batb":[[0,1.39,256.02],[1,1.35,30],[2,1.34,30]],"batl":[[0,1.42,196],[1,1.43,256.02],[2,1.49,118.5]],"ltp":1.4,"tv":34396.83,"id":9323645}]}]}
{"op":"mcm","clk":"4216820897","pt":1631555662992,"mc":[{"id":"1.187566733","rc":[{"batl":[[0,1.43,256.02],[1,1.49,118.5],[2,1.5,115.29]],"ltp":1.4,"tv":34396.83,"id":9323645}]}]}
{"op":"mcm","clk":"4216821048","pt":1631555664573,"mc":[{"id":"1.187566733","rc":[{"batb":[[1,1.34,30],[2,1.33,288.56]],"ltp":1.4,"tv":34396.83,"id":9323645}]}]}
{"op":"mcm","clk":"4216821286","pt":1631555667078,"mc":[{"id":"1.187566733","rc":[{"trd":[[1.39,1244.71]],"batb":[[0,1.39,230.72]],"ltp":1.39,"tv":34447.42,"id":9323645}],"tv":47815.42}]}
{"op":"mcm","clk":"4216821893","pt":1631555673927,"mc":[{"id":"1.187566733","rc":[{"batb":[[0,2.92,6.44],[1,2.76,18.71],[2,2.2,42.64]],"ltp":3.7,"tv":13368.0,"id":8734382},{"batl":[[0,1.52,114.26],[1,1.55,115.52],[2,1.56,87.74]],"ltp":1.39,"tv":34447.42,"id":9323645}]}]}
{"op":"mcm","clk":"4216821993","pt":1631555674820,"mc":[{"id":"1.187566733","rc":[{"batb":[[2,1.33,50]],"batl":[[1,44,7.7],[2,1.56,0]],"ltp":1.39,"tv":34447.42,"id":9323645}]}]}
{"op":"mcm","clk":"4216822216","pt":1631555677118,"mc":[{"id":"1.187566733","rc":[{"batb":[[0,3,5.8],[1,2.92,6.44],[2,2.76,18.71]],"ltp":3.7,"tv":13368.0,"id":8734382},{"batl":[[0,1.49,115.5],[1,1.52,114.26],[2,44,7.7]],"ltp":1.39,"tv":34447.42,"id":9323645}]}]}
{"op":"mcm","clk":"4216822322","pt":1631555678011,"mc":[{"id":"1.187566733","rc":[{"batb":[[0,3.3,21.48]],"batl":[[0,3.5,19.25]],"ltp":3.7,"tv":13368.0,"id":8734382},{"batb":[[0,1.42,96.82],[1,1.41,134.91],[2,1.39,230.72]],"batl":[[0,1.43,19.57],[1,1.45,112.46],[2,1.46,114.81]],"ltp":1.39,"tv":34447.42,"id":9323645}]}]}
{"op":"mcm","clk":"4216822349","pt":1631555678321,"mc":[{"id":"1.187566733","rc":[{"batb":[[0,2.92,6.44],[1,2.76,18.71],[2,2.2,42.64]],"ltp":3.7,"tv":13368.0,"id":8734382},{"batb":[[0,1.39,230.72],[1,1.34,30],[2,1.33,50]],"batl":[[0,1.52,114.26],[1,44,7.7],[2,1.46,0]],"ltp":1.39,"tv":34447.42,"id":9323645}]}]}
{"op":"mcm","clk":"4216822633","pt":1631555680824,"mc":[{"id":"1.187566733","rc":[{"batl":[[0,1.41,24.94],[1,1.52,114.26],[2,44,7.7]],"ltp":1.39,"tv":34447.42,"id":9323645}]}]}
{"op":"mcm","clk":"4216822735","pt":1631555681922,"mc":[{"id":"1.187566733","rc":[{"batl":[[2,1.55,115.52]],"ltp":1.39,"tv":34447.42,"id":9323645}]}]}
{"op":"mcm","clk":"4216822837","pt":1631555682934,"mc":[{"id":"1.187566733","rc":[{"trd":[[2.96,10.47],[3.4,10.34]],"batb":[[2,2,12]],"batl":[[0,2.96,57.36],[1,3.05,9.72],[2,3.1,3.23]],"ltp":2.96,"tv":13388.54,"id":8734382},{"trd":[[1.41,1819.33],[1.51,20.52]],"batb":[[0,1.51,110.94],[1,1.5,103.01],[2,1.48,20.28]],"batl":[[0,1.52,133.54],[1,1.55,115.52],[2,1.56,87.74]],"ltp":1.51,"tv":34492.35,"id":9323645}],"tv":47880.9}]}
{"op":"mcm","clk":"4216822960","pt":1631555684028,"mc":[{"id":"1.187566733","rc":[{"batb":[[1,2.86,10.48],[2,2.84,5.24]],"ltp":2.96,"tv":13388.54,"id":8734382}]}]}
{"op":"mcm","clk":"4216823370","pt":1631555688209,"mc":[{"id":"1.187566733","rc":[{"trd":[[2.92,16.77]],"batb":[[0,2.86,10.48],[1,2.84,5.24],[2,2.82,5.24]],"ltp":2.92,"tv":13405.31,"id":8734382},{"trd":[[1.51,187.84],[1.52,299.99]],"batb":[[0,1.5,129.39],[1,1.48,20.28],[2,1.47,10.14]],"batl":[[0,1.52,121.07],[1,1.53,90.71],[2,1.55,90.33]],"ltp":1.52,"tv":34677.14,"id":9323645}],"tv":48082.45}]}
{"op":"mcm","clk":"4216823569","pt":1631555690042,"mc":[{"id":"1.187566733","rc":[{"trd":[[2.96,53.15]],"batl":[[0,2.96,14.68]],"ltp":2.96,"tv":13447.99,"id":8734382},{"trd":[[1.51,271.5],[1.52,326.63]],"batl":[[0,1.52,107.75]],"ltp":1.52,"tv":34787.43,"id":9323645}],"tv":48235.43}]}
{"op":"mcm","clk":"4216823690","pt":1631555691152,"mc":[{"id":"1.187566733","rc":[{"batb":[[0,1.51,26.21],[1,1.5,194.61],[2,1.49,106.39]],"batl":[[0,1.52,365.06],[2,1.54,70.59]],"ltp":1.52,"tv":34787.43,"id":9323645}]}]}
{"op":"mcm","clk":"4216823756","pt":1631555691629,"mc":[{"id":"1.187566733","rc":[{"trd":[[1.52,344.29]],"batb":[[0,1.5,194.61],[1,1.49,106.39],[2,1.48,20.28]],"batl":[[0,1.52,356.23]],"ltp":1.52,"tv":34805.1,"id":9323645}],"tv":48253.09}]}
{"op":"mcm","clk":"4216824148","pt":1631555695136,"mc":[{"id":"1.187566733","rc":[{"batb":[[2,1.48,276.3]],"ltp":1.52,"tv":34805.1,"id":9323645}]}]}
{"op":"mcm","clk":"4216824501","pt":1631555698628,"mc":[{"id":"1.187566733","rc":[{"batl":[[2,1.54,83.73]],"ltp":1.52,"tv":34805.1,"id":9323645}]}]}
{"op":"mcm","clk":"4216825396","pt":1631555706785,"mc":[{"id":"1.187566733","rc":[{"batb":[[0,2.34,7.22],[1,2.28,31.13],[2,2.22,7.34]],"batl":[[0,880,0.01],[1,3.05,0],[2,3.1,0]],"ltp":2.96,"tv":13447.99,"id":8734382},{"batb":[[0,1.48,256.02],[1,1.36,89.79],[2,1.34,30]],"batl":[[0,1.52,166],[1,1.54,13.14],[2,1.63,256.02]],"ltp":1.52,"tv":34805.1,"id":9323645}]}]}
{"op":"mcm","clk":"4216825509","pt":1631555707564,"mc":[{"id":"1.187566733","rc":[{"batl":[[0,1.54,13.14],[1,1.63,256.02],[2,1.74,93.75]],"ltp":1.52,"tv":34805.1,"id":9323645}]}]}
{"op":"mcm","clk":"4216825955","pt":1631555711542,"mc":[{"id":"1.187566733","rc":[{"batl":[[0,1.63,256.02],[1,1.74,93.75],[2,1.81,79.5]],"ltp":1.52,"tv":34805.1,"id":9323645}]}]}
{"op":"mcm","clk":"4216826101","pt":1631555712947,"mc":[{"id":"1.187566733","rc":[{"batb":[[0,2.78,20.16],[1,2.34,7.22],[2,2.28,31.13]],"batl":[[0,2.98,19.75],[1,880,0.01]],"ltp":2.96,"tv":13447.99,"id":8734382},{"batb":[[0,1.54,113.32],[1,1.53,95.15],[2,1.48,256.02]],"batl":[[0,1.56,18.92],[1,1.58,89.25],[2,1.59,81.83]],"ltp":1.52,"tv":34805.1,"id":9323645}]}]}
{"op":"mcm","clk":"4216826210","pt":1631555714052,"mc":[{"id":"1.187566733","rc":[{"batb":[[0,2.34,7.22],[1,2.28,31.13],[2,2.22,7.34]],"batl":[[0,880,0.01],[1,880,0]],"ltp":2.96,"tv":13447.99,"id":8734382},{"batb":[[0,1.48,256.02],[1,1.36,89.79],[2,1.34,30]],"batl":[[0,1.63,256.02],[1,1.74,93.75],[2,1.81,79.5]],"ltp":1.52,"tv":34805.1,"id":9323645}]}]}
{"op":"mcm","clk":"4216826403","pt":1631555715854,"mc":[{"id":"1.187566733","rc":[{"batl":[[0,1.59,12.73],[1,1.63,256.02],[2,1.74,93.75]],"ltp":1.52,"tv":34805.1,"id":9323645}]}]}
{"op":"mcm","clk":"4216826559","pt":1631555717069,"mc":[{"id":"1.187566733","rc":[{"batb":[[1,1.4,161.64],[2,1.39,145.08]],"ltp":1.52,"tv":34805.1,"id":9323645}]}]}
{"op":"mcm","clk":"4216826786","pt":1631555718890,"mc":[{"id":"1.187566733","rc":[{"batl":[[1,1.6,4],[2,1.63,256.02]],"ltp":1.52,"tv":34805.1,"id":9323645}]}]}
{"op":"mcm","clk":"4216827328","pt":1631555723652,"mc":[{"id":"1.187566733","rc":[{"batb":[[0,1.4,161.64],[1,1.39,145.08],[2,1.37,20]],"ltp":1.52,"tv":34805.1,"id":9323645}]}]}
{"op":"mcm","clk":"4216827607","pt":1631555726167,"mc":[{"id":"1.187566733","rc":[{"batb":[[0,3.35,6.69],[1,3.3,18.28],[2,3.15,265.12]],"batl":[[0,3.5,5.06],[1,3.55,310.63],[2,880,0.01]],"ltp":2.96,"tv":13447.99,"id":8734382},{"batb":[[0,1.4,174.28],[2,1.38,197.1]],"batl":[[0,1.42,3.52],[1,1.43,200.49],[2,1.44,1502.22]],"ltp":1.52,"tv":34805.1,"id":9323645}]}]}
{"op":"mcm","clk":"4216827715","pt":1631555727062,"mc":[{"id":"1.187566733","rc":[{"batl":[[0,3.5,7.92]],"ltp":2.96,"tv":13447.99,"id":8734382},{"batb":[[2,1.38,98.56]],"batl":[[0,1.43,201.19],[1,1.44,233.95],[2,1.45,93.78]],"ltp":1.52,"tv":34805.1,"id":9323645}]}]}
{"op":"mcm","clk":"4216827925","pt":1631555728804,"mc":[{"id":"1.187566733","rc":[{"trd":[[1.42,1365.99],[1.43,2359.69]],"batl":[[0,1.43,200.12]],"ltp":1.43,"tv":34807.24,"id":9323645}],"tv":48255.23}]}
{"op":"mcm","clk":"4216828093","pt":1631555730158,"mc":[{"id":"1.187566733","rc":[{"batl":[[0,1.42,85.88],[1,1.43,200.12],[2,1.44,233.95]],"ltp":1.43,"tv":34807.24,"id":9323645}]}]}
{"op":"mcm","clk":"4216828201","pt":1631555731155,"mc":[{"id":"1.187566733","rc":[{"trd":[[3.35,129.78]],"batb":[[0,3.3,18.28],[1,3.15,265.12],[2,3.1,33.15]],"ltp":3.35,"tv":13463.29,"id":8734382},{"trd":[[1.42,1370.52]],"batb":[[0,1.41,16.89],[1,1.4,174.28],[2,1.39,145.08]],"batl":[[0,1.42,81.35]],"ltp":1.42,"tv":34811.77,"id":9323645}],"tv":48275.06}]}
{"op":"mcm","clk":"4216828284","pt":1631555732092,"mc":[{"id":"1.187566733","rc":[{"batb":[[0,1.41,50.67]],"batl":[[1,1.43,285.12]],"ltp":1.42,"tv":34811.77,"id":9323645}]}]}
{"op":"mcm","clk":"4216828482","pt":1631555733982,"mc":[{"id":"1.187566733","rc":[{"batl":[[1,1.43,368.04]],"ltp":1.42,"tv":34811.77,"id":9323645}]}]}
{"op":"mcm","clk":"4216828744","pt":1631555736665,"mc":[{"id":"1.187566733","rc":[{"trd":[[1.41,1839.33]],"batb":[[0,1.41,40.67]],"ltp":1.41,"tv":34831.77,"id":9323645}],"tv":48295.06}]}
{"op":"mcm","clk":"4216828861","pt":1631555737972,"mc":[{"id":"1.187566733","rc":[{"batl":[[2,1.44,122.43]],"ltp":1.41,"tv":34831.77,"id":9323645}]}]}
{"op":"mcm","clk":"4216829167","pt":1631555741110,"mc":[{"id":"1.187566733","rc":[{"batl":[[0,3.5,2.86]],"ltp":3.35,"tv":13463.29,"id":8734382},{"batb":[[1,1.4,161.64]],"batl":[[1,1.43,283.04]],"ltp":1.41,"tv":34831.77,"id":9323645}]}]}
{"op":"mcm","clk":"4216829298","pt":1631555742480,"mc":[{"id":"1.187566733","rc":[{"batb":[[0,1.4,161.64],[1,1.39,145.08],[2,1.38,98.56]],"ltp":1.41,"tv":34831.77,"id":9323645}]}]}
{"op":"mcm","clk":"4216829481","pt":1631555744101,"mc":[{"id":"1.187566733","rc":[{"trd":[[3.35,154.78]],"batb":[[0,3.3,24.27]],"batl":[[0,3.4,5.75],[1,3.5,2.86],[2,3.55,310.63]],"ltp":3.35,"tv":13488.29,"id":8734382},{"trd":[[1.42,1429.5]],"batl":[[0,1.42,308.37]],"ltp":1.42,"tv":34890.75,"id":9323645}],"tv":48379.04}]}
{"op":"mcm","clk":"4216829646","pt":1631555745621,"mc":[{"id":"1.187566733","rc":[{"batl":[[0,1.42,332.55],[1,1.43,210.05]],"ltp":1.42,"tv":34890.75,"id":9323645}]}]}
{"op":"mcm","clk":"4216829788","pt":1631555746986,"mc":[{"id":"1.187566733","rc":[{"batb":[[0,1.4,227.8]],"ltp":1.42,"tv":34890.75,"id":9323645}]}]}
{"op":"mcm","clk":"4216829998","pt":1631555749014,"mc":[{"id":"1.187566733","rc":[{"batb":[[0,3.3,18.28],[1,3.1,33.15],[2,3,5]],"batl":[[0,880,0.01],[1,3.5,0],[2,3.55,0]],"ltp":3.35,"tv":13488.29,"id":8734382},{"batb":[[0,1.4,237.27],[2,1.37,258.71]],"batl":[[2,1.44,185.72]],"ltp":1.42,"tv":34890.75,"id":9323645}]}]}
{"op":"mcm","clk":"4216830065","pt":1631555749588,"mc":[{"id":"1.187566733","rc":[{"batb":[[0,2.96,5.63],[1,2.88,4.96],[2,2.84,5.72]],"ltp":3.35,"tv":13488.29,"id":8734382},{"batb":[[0,1.37,258.71],[1,1.34,30],[2,1.33,50]],"batl":[[0,1.42,24.18],[1,1.46,256.02],[2,1.51,94.5]],"ltp":1.42,"tv":34890.75,"id":9323645}]}]}
{"op":"mcm","clk":"4216830335","pt":1631555752198,"mc":[{"id":"1.187566733","rc":[{"batb":[[1,1.34,164.11],[2,1.33,230.55]],"ltp":1.42,"tv":34890.75,"id":9323645}]}]}
{"op":"mcm","clk":"4216830869","pt":1631555757002,"mc":[{"id":"1.187566733","rc":[{"batb":[[0,2.84,5.72],[1,2.74,19.13],[2,1.4,150]],"ltp":3.35,"tv":13488.29,"id":8734382},{"batb":[[0,1.37,2.7]],"batl":[[2,1.6,4]],"ltp":1.42,"tv":34890.75,"id":9323645}]}]}
{"op":"mcm","clk":"4216830958","pt":1631555757936,"mc":[{"id":"1.187566733","rc":[{"batb":[[1,1.34,134.11]],"batl":[[0,1.46,256.02],[1,1.6,4],[2,44,7.7]],"ltp":1.42,"tv":34890.75,"id":9323645}]}]}
{"op":"mcm","clk":"4216831103","pt":1631555759197,"mc":[{"id":"1.187566733","rc":[{"batl":[[0,1.43,11.32],[1,1.46,256.02],[2,1.6,4]],"ltp":1.42,"tv":34890.75,"id":9323645}]}]}
{"op":"mcm","clk":"4216831213","pt":1631555760112,"mc":[{"id":"1.187566733","rc":[{"batb":[[0,3.7,15.72],[1,3.6,32.38],[2,3.55,12.5]],"batl":[[0,3.75,6.81],[1,3.85,220.35],[2,880,0.01]],"ltp":3.35,"tv":13488.29,"id":8734382},{"trd":[[1.37,2771.59]],"batb":[[0,1.34,134.11],[1,1.33,230.55],[2,1.32,12.7]],"batl":[[0,1.37,305.57],[1,1.38,147.41],[2,1.39,87.05]],"ltp":1.37,"tv":34896.14,"id":9323645}],"tv":48384.44}]}
{"op":"mcm","clk":"4216831287","pt":1631555760736,"mc":[{"id":"1.187566733","rc":[{"batb":[[1,3.6,15.71],[2,3.55,4.16]],"batl":[[2,3.9,2.56]],"ltp":3.35,"tv":13488.29,"id":8734382},{"batb":[[0,1.34,156.49],[1,1.33,241.75],[2,1.32,23.9]],"ltp":1.37,"tv":34896.14,"id":9323645}]}]}
{"op":"mcm","clk":"4216831700","pt":1631555764149,"mc":[{"id":"1.187566733","rc":[{"trd":[[3.75,40.52]],"batl":[[0,3.85,220.35],[1,3.9,2.56],[2,1000,0.01]],"ltp":3.75,"tv":13495.1,"id":8734382},{"trd":[[1.36,2309.93]],"batb":[[0,1.35,74.58],[1,1.34,156.49],[2,1.33,241.75]],"batl":[[0,1.36,48.64],[1,1.37,305.57],[2,1.38,147.41]],"ltp":1.36,"tv":34953.4,"id":9323645}],"tv":48448.5}]}
{"op":"mcm","clk":"4216831805","pt":1631555765147,"mc":[{"id":"1.187566733","rc":[{"trd":[[3.75,43.15]],"batl":[[2,880,0.01]],"ltp":3.75,"tv":13497.73,"id":8734382},{"trd":[[1.36,2317.18]],"batb":[[0,1.35,330.6]],"batl":[[0,1.36,41.39]],"ltp":1.36,"tv":34960.65,"id":9323645}],"tv":48458.38}]}
{"op":"mcm","clk":"4216831894","pt":1631555766038,"mc":[{"id":"1.187566733","rc":[{"batl":[[0,1.37,305.57],[1,1.38,147.41],[2,1.39,343.07]],"ltp":1.36,"tv":34960.65,"id":9323645}]}]}
{"op":"mcm","clk":"4216832003","pt":1631555767144,"mc":[{"id":"1.187566733","rc":[{"trd":[[1.35,4267.8]],"batb":[[0,1.35,148.8],[1,1.34,241.84]],"ltp":1.35,"tv":35324.25,"id":9323645}],"tv":48821.98}]}
{"op":"mcm","clk":"4216832052","pt":1631555767618,"mc":[{"id":"1.187566733","rc":[{"batl":[[2,990,0.01]],"ltp":3.75,"tv":13497.73,"id":8734382},{"batb":[[0,1.36,50],[1,1.35,148.8],[2,1.34,241.84]],"ltp":1.35,"tv":35324.25,"id":9323645}]}]}
{"op":"mcm","clk":"4216832121","pt":1631555768354,"mc":[{"id":"1.187566733","rc":[{"batl":[[0,1.37,390.6]],"ltp":1.35,"tv":35324.25,"id":9323645}]}]}
{"op":"mcm","clk":"4216832316","pt":1631555770027,"mc":[{"id":"1.187566733","rc":[{"batl":[[2,990,0.01]],"ltp":3.75,"tv":13497.73,"id":8734382}]}]}
{"op":"mcm","clk":"4216832389","pt":1631555770712,"mc":[{"id":"1.187566733","rc":[{"batb":[[0,1.36,52.01],[1,1.35,192.39]],"ltp":1.35,"tv":35324.25,"id":9323645}]}]}
{"op":"mcm","clk":"4216832566","pt":1631555772538,"mc":[{"id":"1.187566733","rc":[{"batl":[[0,1.37,633.6]],"ltp":1.35,"tv":35324.25,"id":9323645}]}]}
{"op":"mcm","clk":"4216832776","pt":1631555774123,"mc":[{"id":"1.187566733","rc":[{"batb":[[1,3.6,8.34]],"ltp":3.75,"tv":13497.73,"id":8734382},{"trd":[[1.36,2320.39]],"batb":[[0,1.36,50.41]],"batl":[[0,1.37,634.99]],"ltp":1.36,"tv":35327.45,"id":9323645}],"tv":48825.19}]}
{"op":"mcm","clk":"4216832905","pt":1631555775160,"mc":[{"id":"1.187566733","rc":[{"trd":[[3.7,193.37]],"batb":[[0,3.7,3.73]],"ltp":3.7,"tv":13521.71,"id":8734382},{"trd":[[1.37,2771.96]],"batl":[[0,1.37,634.8],[1,1.38,148.8],[2,1.39,344.45]],"ltp":1.37,"tv":35327.83,"id":9323645}],"tv":48849.54}]}
{"op":"mcm","clk":"4216833122","pt":1631555777053,"mc":[{"id":"1.187566733","rc":[{"trd":[[3.75,71.63]],"batb":[[0,3.7,8.37]],"batl":[[0,3.85,229.14]],"ltp":3.75,"tv":13550.19,"id":8734382},{"trd":[[1.36,2499.74]],"batb":[[0,1.35,192.39],[1,1.34,241.84],[2,1.33,241.75]],"batl":[[0,1.36,9.58],[1,1.37,634.8],[2,1.38,148.8]],"ltp":1.36,"tv":35507.18,"id":9323645}],"tv":49057.37}]}
{"op":"mcm","clk":"4216833216","pt":1631555777988,"mc":[{"id":"1.187566733","rc":[{"trd":[[1.35,4496.8]],"batb":[[0,1.35,77.89]],"batl":[[1,1.37,636.18]],"ltp":1.35,"tv":35736.18,"id":9323645}],"tv":49286.37}]}
{"op":"mcm","clk":"4216833322","pt":1631555779138,"mc":[{"id":"1.187566733","rc":[{"trd":[[3.75,72.99]],"ltp":3.75,"tv":13551.55,"id":8734382},{"trd":[[1.36,2503.48]],"batl":[[0,1.36,5.84],[2,1.38,150.18]],"ltp":1.36,"tv":35739.92,"id":9323645}],"tv":49291.47}]}
{"op":"mcm","clk":"4216833380","pt":1631555779718,"mc":[{"id":"1.187566733","rc":[{"trd":[[1.36,2504.54]],"batb":[[2,1.33,191.75]],"batl":[[0,1.36,5.31]],"ltp":1.36,"tv":35740.98,"id":9323645}],"tv":49292.53}]}
{"op":"mcm","clk":"4216833615","pt":1631555782165,"mc":[{"id":"1.187566733","rc":[{"batl":[[1,1.37,464.71]],"ltp":1.36,"tv":35740.98,"id":9323645}]}]}
{"op":"mcm","clk":"4216833689","pt":1631555782948,"mc":[{"id":"1.187566733","rc":[{"batl":[[2,1.38,151.57]],"ltp":1.36,"tv":35740.98,"id":9323645}]}]}
{"op":"mcm","clk":"4216833930","pt":1631555785138,"mc":[{"id":"1.187566733","rc":[{"trd":[[3.75,75.11],[3.85,393.84]],"batl":[[0,3.85,178.39]],"ltp":3.85,"tv":13604.42,"id":8734382},{"trd":[[1.35,4797.3],[1.36,2510.37]],"batb":[[0,1.34,241.84],[1,1.33,191.75],[2,1.32,23.9]],"batl":[[0,1.37,464.71],[1,1.38,151.57],[2,1.39,347.22]],"ltp":1.35,"tv":36047.31,"id":9323645}],"tv":49651.73}]}
{"op":"mcm","clk":"4216833984","pt":1631555785772,"mc":[{"id":"1.187566733","rc":[{"trd":[[3.85,463.97]],"batl":[[0,3.85,108.26]],"ltp":3.85,"tv":13674.55,"id":8734382},{"trd":[[1.35,4997.3]],"ltp":1.35,"tv":36247.31,"id":9323645}],"tv":49921.86}]}
{"op":"mcm","clk":"4216834169","pt":1631555787748,"mc":[{"id":"1.187566733","rc":[{"batb":[[0,1.35,487.64],[1,1.34,241.84],[2,1.33,191.75]],"ltp":1.35,"tv":36247.31,"id":9323645}]}]}
{"op":"mcm","clk":"4216834327","pt":1631555789155,"mc":[{"id":"1.187566733","rc":[{"batb":[[0,1.35,589.17]],"ltp":1.35,"tv":36247.31,"id":9323645}]}]}
{"op":"mcm","clk":"4216834481","pt":1631555790775,"mc":[{"id":"1.187566733","rc":[{"batb":[[0,1.35,589.84]],"batl":[[0,1.37,682.71]],"ltp":1.35,"tv":36247.31,"id":9323645}]}]}
{"op":"mcm","clk":"4216834559","pt":1631555791559,"mc":[{"id":"1.187566733","rc":[{"trd":[[1.37,2975.96]],"batl":[[0,1.37,580.71]],"ltp":1.37,"tv":36451.31,"id":9323645}],"tv":50125.86}]}
{"op":"mcm","clk":"4216834667","pt":1631555792866,"mc":[{"id":"1.187566733","rc":[{"batb":[[0,1.36,4.67],[1,1.35,589.17],[2,1.34,241.84]],"ltp":1.37,"tv":36451.31,"id":9323645}]}]}
{"op":"mcm","clk":"4216834820","pt":1631555794378,"mc":[{"id":"1.187566733","rc":[{"trd":[[1.35,5987.96],[1.36,2518.37]],"batb":[[0,1.35,93.84],[1,1.34,241.84],[2,1.33,191.75]],"ltp":1.35,"tv":37449.97,"id":9323645}],"tv":51124.52}]}
{"op":"mcm","clk":"4216834959","pt":1631555795635,"mc":[{"id":"1.187566733","rc":[{"batl":[[0,3.85,108.45]],"ltp":3.85,"tv":13674.55,"id":8734382}]}]}
{"op":"mcm","clk":"4216835111","pt":1631555797201,"mc":[{"id":"1.187566733","rc":[{"trd":[[3.75,75.29],[3.85,472.96]],"batl":[[0,3.85,99.27]],"ltp":3.85,"tv":13683.72,"id":8734382},{"trd":[[1.35,6201.29],[1.36,2518.88]],"batb":[[0,1.34,241.84],[1,1.33,191.75],[2,1.32,23.9]],"ltp":1.35,"tv":37663.81,"id":9323645}],"tv":51347.54}]}
{"op":"mcm","clk":"4216835197","pt":1631555797933,"mc":[{"id":"1.187566733","rc":[{"batl":[[0,1.36,659.77],[1,1.37,580.71],[2,1.38,151.57]],"ltp":1.35,"tv":37663.81,"id":9323645}]}]}
{"op":"mcm","clk":"4216835312","pt":1631555799136,"mc":[{"id":"1.187566733","rc":[{"batb":[[0,1.35,243.82],[1,1.34,241.84],[2,1.33,191.75]],"ltp":1.35,"tv":37663.81,"id":9323645}]}]}
{"op":"mcm","clk":"4216835460","pt":1631555800439,"mc":[{"id":"1.187566733","rc":[{"batl":[[1,1.37,509.18]],"ltp":1.35,"tv":37663.81,"id":9323645}]}]}
{"op":"mcm","clk":"4216835716","pt":1631555802944,"mc":[{"id":"1.187566733","rc":[{"trd":[[3.85,498.28]],"batl":[[0,3.85,73.95]],"ltp":3.85,"tv":13709.04,"id":8734382},{"trd":[[1.35,6761.13]],"batb":[[0,1.34,241.84],[1,1.33,191.75],[2,1.32,23.9]],"ltp":1.35,"tv":38223.65,"id":9323645}],"tv":51932.7}]}
{"op":"mcm","clk":"4216835846","pt":1631555804146,"mc":[{"id":"1.187566733","rc":[{"batb":[[0,1.34,446.16]],"batl":[[1,1.37,482.7],[2,1.38,4.16]],"ltp":1.35,"tv":38223.65,"id":9323645}]}]}
{"op":"mcm","clk":"4216835888","pt":1631555804563,"mc":[{"id":"1.187566733","rc":[{"batl":[[1,1.37,264.7]],"ltp":1.35,"tv":38223.65,"id":9323645}]}]}
{"op":"mcm","clk":"4216836053","pt":1631555806177,"mc":[{"id":"1.187566733","rc":[{"batl":[[0,1.36,871.8]],"ltp":1.35,"tv":38223.65,"id":9323645}]}]}
{"op":"mcm","clk":"4216836147","pt":1631555807167,"mc":[{"id":"1.187566733","rc":[{"trd":[[3.85,568.41]],"batl":[[0,3.85,3.82]],"ltp":3.85,"tv":13779.17,"id":8734382},{"trd":[[1.35,6961.13]],"batl":[[0,1.36,949.16]],"ltp":1.35,"tv":38423.65,"id":9323645}],"tv":52202.83}]}
{"op":"mcm","clk":"4216836204","pt":1631555807684,"mc":[{"id":"1.187566733","rc":[{"trd":[[3.85,572.23]],"batl":[[0,3.9,2.56],[1,990,0.01],[2,990,0]],"ltp":3.85,"tv":13782.99,"id":8734382},{"trd":[[1.35,6972.02]],"batl":[[0,1.35,9.11],[1,1.36,1334.8],[2,1.37,264.7]],"ltp":1.35,"tv":38434.54,"id":9323645}],"tv":52217.54}]}
{"op":"mcm","clk":"4216836384","pt":1631555809673,"mc":[{"id":"1.187566733","rc":[{"batl":[[2,1.37,337.12]],"ltp":1.35,"tv":38434.54,"id":9323645}]}]}
{"op":"mcm","clk":"4216836724","pt":1631555813164,"mc":[{"id":"1.187566733","rc":[{"batl":[[0,1.35,19.11]],"ltp":1.35,"tv":38434.54,"id":9323645}]}]}
{"op":"mcm","clk":"4216836871","pt":1631555814686,"mc":[{"id":"1.187566733","rc":[{"batl":[[0,1.35,29.11]],"ltp":1.35,"tv":38434.54,"id":9323645}]}]}
{"op":"mcm","clk":"4216837082","pt":1631555817086,"mc":[{"id":"1.187566733","rc":[{"batb":[[0,3.7,3.73]],"ltp":3.85,"tv":13782.99,"id":8734382},{"trd":[[1.35,6974.28]],"batl":[[0,1.35,27.98]],"ltp":1.35,"tv":38436.79,"id":9323645}],"tv":52219.79}]}
{"op":"mcm","clk":"4216837122","pt":1631555817500,"mc":[{"id":"1.187566733","rc":[{"trd":[[1.35,7030.24]],"batb":[[0,1.35,74.02],[1,1.34,446.16],[2,1.33,191.75]],"batl":[[0,1.36,1334.8],[1,1.37,337.12],[2,1.38,151.61]],"ltp":1.35,"tv":38492.75,"id":9323645}],"tv":52275.75}]}
{"op":"mcm","clk":"4216837411","pt":1631555820799,"mc":[{"id":"1.187566733","rc":[{"trd":[[1.34,1750.61],[1.35,7178.28]],"batb":[[0,1.34,120.17],[1,1.33,191.75],[2,1.32,23.9]],"batl":[[2,1.38,4.16]],"ltp":1.34,"tv":39292.76,"id":9323645}],"tv":53075.76}]}
{"op":"mcm","clk":"4216837600","pt":1631555823105,"mc":[{"id":"1.187566733","rc":[{"batb":[[0,1.34,142.76]],"batl":[[0,1.36,1352.69]],"ltp":1.34,"tv":39292.76,"id":9323645}]}]}
{"op":"mcm","clk":"4216837696","pt":1631555823991,"mc":[{"id":"1.187566733","rc":[{"batb":[[0,1.34,200.77],[1,1.33,233.14],[2,1.32,213.73]],"batl":[[0,1.36,1470.46]],"ltp":1.34,"tv":39292.76,"id":9323645}]}]}
{"op":"mcm","clk":"4216839111","pt":1631555837690,"mc":[{"id":"1.187566733","rc":[{"batl":[[0,1.36,1446.46]],"ltp":1.34,"tv":39292.76,"id":9323645}]}]}
{"op":"mcm","clk":"4216839338","pt":1631555840101,"mc":[{"id":"1.187566733","rc":[{"batl":[[0,1.35,134.84],[1,1.36,1446.46],[2,1.37,337.12]],"ltp":1.34,"tv":39292.76,"id":9323645}]}]}
{"op":"mcm","clk":"4216839391","pt":1631555840722,"mc":[{"id":"1.187566733","rc":[{"trd":[[3.85,573.04]],"ltp":3.85,"tv":13783.81,"id":8734382},{"trd":[[1.35,7180.6]],"batl":[[0,1.35,132.51]],"ltp":1.35,"tv":39295.08,"id":9323645}],"tv":53078.89}]}
{"op":"mcm","clk":"4216839487","pt":1631555841828,"mc":[{"id":"1.187566733","rc":[{"trd":[[1.34,2142.78]],"batb":[[0,1.33,233.14],[1,1.32,213.73],[2,1.31,109.1]],"ltp":1.34,"tv":39687.24,"id":9323645}],"tv":53471.06}]}
{"op":"mcm","clk":"4216839601","pt":1631555843019,"mc":[{"id":"1.187566733","rc":[{"batl":[[0,1.35,137.51]],"ltp":1.34,"tv":39687.24,"id":9323645}]}]}
{"op":"mcm","clk":"4216839665","pt":1631555843641,"mc":[{"id":"1.187566733","rc":[{"batl":[[0,1.35,352.35],[1,1.36,1440.46]],"ltp":1.34,"tv":39687.24,"id":9323645}]}]}
{"op":"mcm","clk":"4216839800","pt":1631555844797,"mc":[{"id":"1.187566733","rc":[{"batb":[[0,1.33,360.74]],"ltp":1.34,"tv":39687.24,"id":9323645}]}]}
{"op":"mcm","clk":"4216840086","pt":1631555848025,"mc":[{"id":"1.187566733","rc":[{"batl":[[1,1.36,1413.85]],"ltp":1.34,"tv":39687.24,"id":9323645}]}]}
{"op":"mcm","clk":"4216840250","pt":1631555849941,"mc":[{"id":"1.187566733","rc":[{"trd":[[3.9,81.76]],"batl":[[0,4.8,2.27],[1,5.2,2.03],[2,990,0.01]],"ltp":3.9,"tv":13786.37,"id":8734382},{"trd":[[1.33,509.78],[1.34,2150.23]],"batb":[[0,1.33,168.19]],"ltp":1.33,"tv":40079.79,"id":9323645}],"tv":53866.17}]}
{"op":"mcm","clk":"4216840351","pt":1631555851142,"mc":[{"id":"1.187566733","rc":[{"batb":[[0,1.33,195.57]],"batl":[[0,1.34,253.68],[1,1.35,352.35],[2,1.36,1413.85]],"ltp":1.33,"tv":40079.79,"id":9323645}]}]}
{"op":"mcm","clk":"4216840415","pt":1631555851829,"mc":[{"id":"1.187566733","rc":[{"batl":[[1,1.35,219.84],[2,1.36,1395.96]],"ltp":1.33,"tv":40079.79,"id":9323645}]}]}
{"op":"mcm","clk":"4216840591","pt":1631555853918,"mc":[{"id":"1.187566733","rc":[{"batl":[[1,4.9,2.15],[2,5.2,2.03]],"ltp":3.9,"tv":13786.37,"id":8734382},{"batb":[[0,1.33,276.7]],"batl":[[0,1.34,436.94],[2,1.36,1493.62]],"ltp":1.33,"tv":40079.79,"id":9323645}]}]}
{"op":"mcm","clk":"4216840667","pt":1631555854848,"mc":[{"id":"1.187566733","rc":[{"batl":[[0,4,4.81],[1,4.8,2.27],[2,4.9,2.15]],"ltp":3.9,"tv":13786.37,"id":8734382},{"batl":[[1,1.35,240.46]],"ltp":1.33,"tv":40079.79,"id":9323645}]}]}
{"op":"mcm","clk":"4216840718","pt":1631555855434,"mc":[{"id":"1.187566733","rc":[{"batl":[[1,1.35,235.46]],"ltp":1.33,"tv":40079.79,"id":9323645}]}]}
{"op":"mcm","clk":"4216840876","pt":1631555857401,"mc":[{"id":"1.187566733","rc":[{"batb":[[2,1.31,365.11]],"ltp":1.33,"tv":40079.79,"id":9323645}]}]}
{"op":"mcm","clk":"4216841665","pt":1631555866032,"mc":[{"id":"1.187566733","rc":[{"batl":[[0,1.34,183.26]],"ltp":1.33,"tv":40079.79,"id":9323645}]}]}
{"op":"mcm","clk":"4216841686","pt":1631555866242,"mc":[{"id":"1.187566733","rc":[{"batb":[[0,1.33,149.1]],"ltp":1.33,"tv":40079.79,"id":9323645}]}]}
{"op":"mcm","clk":"4216842123","pt":1631555870876,"mc":[{"id":"1.187566733","rc":[{"trd":[[4,4.81]],"batl":[[0,4.8,2.27],[1,4.9,2.15],[2,5.2,2.03]],"ltp":4.0,"tv":13791.18,"id":8734382},{"trd":[[1.33,822.44]],"batb":[[0,1.32,213.73],[1,1.31,365.11],[2,1.27,102.87]],"batl":[[0,1.33,92.03],[1,1.34,183.26],[2,1.35,235.46]],"ltp":1.33,"tv":40392.45,"id":9323645}],"tv":54183.64}]}
{"op":"mcm","clk":"4216842435","pt":1631555874237,"mc":[{"id":"1.187566733","rc":[{"batb":[[0,1.32,281.11],[1,1.31,565.38]],"batl":[[2,1.35,343.72]],"ltp":1.33,"tv":40392.45,"id":9323645}]}]}
{"op":"mcm","clk":"4216842551","pt":1631555875345,"mc":[{"id":"1.187566733","rc":[{"batl":[[2,5,2]],"ltp":4.0,"tv":13791.18,"id":8734382}]}]}
{"op":"mcm","clk":"4216842843","pt":1631555878747,"mc":[{"id":"1.187566733","rc":[{"trd":[[1.33,832.44]],"batl":[[0,1.33,87.03]],"ltp":1.33,"tv":40402.45,"id":9323645}],"tv":54193.64}]}
{"op":"mcm","clk":"4216842954","pt":1631555879959,"mc":[{"id":"1.187566733","rc":[{"trd":[[1.33,842.44]],"batl":[[0,1.33,82.03]],"ltp":1.33,"tv":40412.45,"id":9323645}],"tv":54203.64}]}
{"op":"mcm","clk":"4216843049","pt":1631555881071,"mc":[{"id":"1.187566733","rc":[{"batl":[[2,1.35,323.1]],"ltp":1.33,"tv":40412.45,"id":9323645}]}]}
{"op":"mcm","clk":"4216843237","pt":1631555883145,"mc":[{"id":"1.187566733","rc":[{"trd":[[1.33,892.45]],"batl":[[0,1.33,57.02]],"ltp":1.33,"tv":40462.46,"id":9323645}],"tv":54253.64}]}
{"op":"mcm","clk":"4216843311","pt":1631555883988,"mc":[{"id":"1.187566733","rc":[{"batl":[[0,4.1,7.86],[1,4.8,2.27],[2,4.9,2.15]],"ltp":4.0,"tv":13791.18,"id":8734382},{"batl":[[1,1.34,197.61]],"ltp":1.33,"tv":40462.46,"id":9323645}]}]}
{"op":"mcm","clk":"4216843714","pt":1631555887990,"mc":[{"id":"1.187566733","rc":[{"trd":[[1.33,996.44]],"batl":[[0,1.33,5.03]],"ltp":1.33,"tv":40566.46,"id":9323645}],"tv":54357.64}]}
{"op":"mcm","clk":"4216843906","pt":1631555889683,"mc":[{"id":"1.187566733","rc":[{"trd":[[1.33,1006.5]],"batb":[[0,1.33,24.97],[1,1.32,281.11],[2,1.31,565.38]],"batl":[[0,1.34,197.61],[1,1.35,323.1],[2,1.36,1466.57]],"ltp":1.33,"tv":40576.51,"id":9323645}],"tv":54367.69}]}
{"op":"mcm","clk":"4216843978","pt":1631555890400,"mc":[{"id":"1.187566733","rc":[{"batl":[[0,4,1.44],[1,4.1,7.86],[2,4.8,2.27]],"ltp":4.0,"tv":13791.18,"id":8734382}]}]}
{"op":"mcm","clk":"4216844179","pt":1631555892500,"mc":[{"id":"1.187566733","rc":[{"batb":[[0,1.32,281.11],[1,1.31,565.38],[2,1.27,102.87]],"ltp":1.33,"tv":40576.51,"id":9323645}]}]}
{"op":"mcm","clk":"4216844548","pt":1631555895665,"mc":[{"id":"1.187566733","rc":[{"trd":[[1.34,2200.17]],"batl":[[0,1.34,172.64]],"ltp":1.34,"tv":40626.45,"id":9323645}],"tv":54417.63}]}
{"op":"mcm","clk":"4216845377","pt":1631555906211,"mc":[{"id":"1.187566733","rc":[{"batl":[[0,4.1,7.86],[1,4.8,2.27],[2,4.9,2.15]],"ltp":4.0,"tv":13791.18,"id":8734382},{"batb":[[0,1.33,5],[1,1.32,281.11],[2,1.31,565.38]],"ltp":1.34,"tv":40626.45,"id":9323645}]}]}
{"op":"mcm","clk":"4216845682","pt":1631555909733,"mc":[{"id":"1.187566733","rc":[{"batb":[[0,1.32,281.11],[1,1.31,565.38],[2,1.27,102.87]],"ltp":1.34,"tv":40626.45,"id":9323645}]}]}
{"op":"mcm","clk":"4216845773","pt":1631555910906,"mc":[{"id":"1.187566733","rc":[{"batl":[[2,1.36,277.48]],"ltp":1.34,"tv":40626.45,"id":9323645}]}]}
{"op":"mcm","clk":"4216846019","pt":1631555913998,"mc":[{"id":"1.187566733","rc":[{"batl":[[0,1.34,527.64]],"ltp":1.34,"tv":40626.45,"id":9323645}]}]}
{"op":"mcm","clk":"4216846253","pt":1631555916923,"mc":[{"id":"1.187566733","rc":[{"batb":[[0,1.32,537.13]],"ltp":1.34,"tv":40626.45,"id":9323645}]}]}
{"op":"mcm","clk":"4216846400","pt":1631555918827,"mc":[{"id":"1.187566733","rc":[{"batb":[[0,3.4,3.46],[1,3.25,3.53],[2,3.1,33.32]],"batl":[[0,4.9,2.15],[1,5.4,2.04],[2,990,0.01]],"ltp":4.0,"tv":13791.18,"id":8734382},{"batb":[[0,1.32,268.72],[1,1.31,256.02],[2,1.26,93.98]],"batl":[[0,1.34,355],[1,1.37,2.77],[2,1.38,4.16]],"ltp":1.34,"tv":40626.45,"id":9323645}]}]}
{"op":"mcm","clk":"4216846478","pt":1631555919615,"mc":[{"id":"1.187566733","rc":[{"batl":[[0,1.37,2.77],[1,1.38,4.16],[2,1.39,290.17]],"ltp":1.34,"tv":40626.45,"id":9323645}]}]}
{"op":"mcm","clk":"4216846715","pt":1631555922132,"mc":[{"id":"1.187566733","rc":[{"batl":[[0,3.9,1.44],[1,4.9,2.15],[2,5.4,2.04]],"ltp":4.0,"tv":13791.18,"id":8734382}]}]}
{"op":"mcm","clk":"4216846745","pt":1631555922408,"mc":[{"id":"1.187566733","rc":[{"batb":[[0,1.32,12.7]],"batl":[[0,1.39,286.02],[1,1.4,30],[2,1.41,90.5]],"ltp":1.34,"tv":40626.45,"id":9323645}]}]}
{"op":"mcm","clk":"4216846874","pt":1631555923952,"mc":[{"id":"1.187566733","rc":[{"trd":[[3.9,83.2]],"batl":[[0,5.4,2.04],[1,990,0.01],[2,5.4,0]],"ltp":3.9,"tv":13792.62,"id":8734382},{"trd":[[1.34,2204.36]],"batb":[[1,1.31,187.78],[2,1.3,208.03]],"batl":[[0,1.34,188.86],[1,1.35,166.85],[2,1.39,286.02]],"ltp":1.34,"tv":40630.64,"id":9323645}],"tv":54423.26}]}
{"op":"mcm","clk":"4216847119","pt":1631555927136,"mc":[{"id":"1.187566733","rc":[{"batb":[[1,1.24,144.34],[2,1.23,106.63]],"batl":[[0,1.37,30],[1,1.39,286.02],[2,1.4,30]],"ltp":1.34,"tv":40630.64,"id":9323645}]}]}
{"op":"mcm","clk":"4216847216","pt":1631555928131,"mc":[{"id":"1.187566733","rc":[{"batl":[[0,1.39,286.02],[1,1.4,30],[2,1.41,90.5]],"ltp":1.34,"tv":40630.64,"id":9323645}]}]}
{"op":"mcm","clk":"4216847246","pt":1631555928546,"mc":[{"id":"1.187566733","rc":[{"batb":[[1,1.3,256.02],[2,1.24,144.34]],"ltp":1.34,"tv":40630.64,"id":9323645}]}]}
{"op":"mcm","clk":"4216847400","pt":1631555930133,"mc":[{"id":"1.187566733","rc":[{"batb":[[2,1.26,144.46]],"batl":[[0,1.34,109.26],[1,1.38,105.87],[2,1.39,286.02]],"ltp":1.34,"tv":40630.64,"id":9323645}]}]}
{"op":"mcm","clk":"4216847483","pt":1631555930921,"mc":[{"id":"1.187566733","rc":[{"batl":[[0,4.9,2.35],[1,5.4,2.04],[2,990,0.01]],"ltp":3.9,"tv":13792.62,"id":8734382},{"batb":[[2,1.26,240.94]],"batl":[[0,1.39,286.02],[1,1.41,175.25],[2,1.42,131.9]],"ltp":1.34,"tv":40630.64,"id":9323645}]}]}
{"op":"mcm","clk":"4216847552","pt":1631555931744,"mc":[{"id":"1.187566733","rc":[{"batl":[[0,1.38,30],[1,1.39,286.02],[2,1.41,175.25]],"ltp":1.34,"tv":40630.64,"id":9323645}]}]}
{"op":"mcm","clk":"4216847874","pt":1631555935635,"mc":[{"id":"1.187566733","rc":[{"batl":[[1,1.39,256.02]],"ltp":1.34,"tv":40630.64,"id":9323645}]}]}
{"op":"mcm","clk":"4216849141","pt":1631555950055,"mc":[{"id":"1.187566733","rc":[{"batb":[[2,1.26,96.48]],"ltp":1.34,"tv":40630.64,"id":9323645}]}]}
{"op":"mcm","clk":"4216849196","pt":1631555950642,"mc":[{"id":"1.187566733","rc":[{"batb":[[0,3.25,3.53],[1,3.1,33.32],[2,1.01,98.87]],"ltp":3.9,"tv":13792.62,"id":8734382},{"batl":[[1,1.41,114.75],[2,1.42,131.9]],"ltp":1.34,"tv":40630.64,"id":9323645}]}]}
{"op":"mcm","clk":"4216849243","pt":1631555951259,"mc":[{"id":"1.187566733","rc":[{"batl":[[0,1.41,114.75],[1,1.42,131.9],[2,1.44,56.83]],"ltp":1.34,"tv":40630.64,"id":9323645}]}]}
{"op":"mcm","clk":"4216849369","pt":1631555952940,"mc":[{"id":"1.187566733","rc":[{"trd":[[3.55,71.28]],"batl":[[0,3.6,211.96],[1,3.7,6.98],[2,3.75,53.34]],"ltp":3.55,"tv":13795.44,"id":8734382},{"trd":[[1.39,1251.91]],"batb":[[0,1.38,173.29],[1,1.37,157.69],[2,1.36,22.06]],"batl":[[0,1.39,10.14],[1,1.41,114.75],[2,1.42,131.9]],"ltp":1.39,"tv":40637.84,"id":9323645}],"tv":54433.28}]}
{"op":"mcm","clk":"4216849479","pt":1631555954168,"mc":[{"id":"1.187566733","rc":[{"batb":[[0,3.3,9.08],[1,3.25,8.07],[2,3.2,4.54]],"ltp":3.55,"tv":13795.44,"id":8734382},{"batb":[[2,1.36,111.52]],"ltp":1.39,"tv":40637.84,"id":9323645}]}]}
{"op":"mcm","clk":"4216849784","pt":1631555957181,"mc":[{"id":"1.187566733","rc":[{"trd":[[3.6,39.68]],"batl":[[0,3.6,182.98]],"ltp":3.6,"tv":13824.42,"id":8734382},{"trd":[[1.38,991.88]],"batb":[[0,1.37,157.69],[1,1.36,111.52],[2,1.35,11.02]],"ltp":1.38,"tv":41060.02,"id":9323645}],"tv":54884.44}]}
{"op":"mcm","clk":"4216849884","pt":1631555958080,"mc":[{"id":"1.187566733","rc":[{"trd":[[3.4,16.6],[3.55,71.31]],"ltp":3.4,"tv":13830.71,"id":8734382},{"trd":[[1.39,1272.11],[1.41,1854.43]],"batb":[[0,1.39,276.14],[1,1.37,157.69],[2,1.36,111.52]],"batl":[[0,1.41,99.65],[1,1.42,131.9],[2,1.44,560.96]],"ltp":1.41,"tv":41095.32,"id":9323645}],"tv":54926.04}]}
{"op":"mcm","clk":"4216849963","pt":1631555958765,"mc":[{"id":"1.187566733","rc":[{"trd":[[1.39,1292.11]],"batb":[[0,1.39,294.09]],"batl":[[0,1.41,355.67],[2,1.43,42.31]],"ltp":1.39,"tv":41115.32,"id":9323645}],"tv":54946.04}]}
{"op":"mcm","clk":"4216850105","pt":1631555960075,"mc":[{"id":"1.187566733","rc":[{"trd":[[1.39,1502.33]],"batb":[[0,1.39,148.73],[1,1.38,77.52],[2,1.37,157.69]],"batl":[[0,1.41,456.23]],"ltp":1.39,"tv":41325.55,"id":9323645}],"tv":55156.26}]}
{"op":"mcm","clk":"4216850206","pt":1631555961189,"mc":[{"id":"1.187566733","rc":[{"trd":[[1.39,1820.36]],"batb":[[0,1.38,77.52],[1,1.37,157.69],[2,1.36,111.52]],"batl":[[0,1.39,119.99],[1,1.4,102.34],[2,1.41,557.72]],"ltp":1.39,"tv":41643.57,"id":9323645}],"tv":55474.29}]}
{"op":"mcm","clk":"4216850300","pt":1631555962088,"mc":[{"id":"1.187566733","rc":[{"trd":[[1.38,1011.88],[1.39,1840.36]],"batb":[[0,1.37,157.69],[1,1.36,111.52],[2,1.35,11.02]],"batl":[[0,1.39,109.99],[1,1.4,315.69]],"ltp":1.39,"tv":41683.57,"id":9323645}],"tv":55514.29}]}
{"op":"mcm","clk":"4216850392","pt":1631555963007,"mc":[{"id":"1.187566733","rc":[{"batl":[[1,3.75,53.34],[2,3.95,2.9]],"ltp":3.4,"tv":13830.71,"id":8734382},{"trd":[[1.39,1961.92]],"batb":[[0,1.38,61.28],[1,1.37,157.69],[2,1.36,111.52]],"batl":[[0,1.39,268.03]],"ltp":1.39,"tv":41805.13,"id":9323645}],"tv":55635.85}]}
{"op":"mcm","clk":"4216850477","pt":1631555963669,"mc":[{"id":"1.187566733","rc":[{"batb":[[0,1.37,157.69],[1,1.36,111.52],[2,1.35,11.02]],"batl":[[2,1.41,542.82]],"ltp":1.39,"tv":41805.13,"id":9323645}]}]}
{"op":"mcm","clk":"4216850610","pt":1631555965183,"mc":[{"id":"1.187566733","rc":[{"trd":[[3.6,125.76]],"batl":[[0,3.6,96.9]],"ltp":3.6,"tv":13916.79,"id":8734382},{"trd":[[1.38,1236.45],[1.39,2090.59]],"batb":[[0,1.37,290.43],[1,1.36,276.51]],"batl":[[0,1.39,203.7]],"ltp":1.38,"tv":42158.37,"id":9323645}],"tv":56075.17}]}
{"op":"mcm","clk":"4216850691","pt":1631555965979,"mc":[{"id":"1.187566733","rc":[{"batb":[[0,3.5,3.44],[1,3.3,9.08],[2,3.25,8.07]],"ltp":3.6,"tv":13916.79,"id":8734382},{"batb":[[0,1.38,18.13],[1,1.37,290.43],[2,1.36,276.51]],"batl":[[0,1.39,305.13],[1,1.4,324.3]],"ltp":1.38,"tv":42158.37,"id":9323645}]}]}
{"op":"mcm","clk":"4216850750","pt":1631555966559,"mc":[{"id":"1.187566733","rc":[{"batl":[[0,1.39,534.92]],"ltp":1.38,"tv":42158.37,"id":9323645}]}]}
{"op":"mcm","clk":"4216850904","pt":1631555968181,"mc":[{"id":"1.187566733","rc":[{"trd":[[3.6,222.66]],"batb":[[0,3.3,9.08],[1,3.25,8.07],[2,3.2,4.54]],"batl":[[0,3.75,53.34],[1,3.95,2.9],[2,4.1,3.05]],"ltp":3.6,"tv":14013.69,"id":8734382},{"trd":[[1.38,1489.23],[1.39,2347.03]],"batb":[[0,1.37,230.36],[1,1.36,276.51],[2,1.35,11.02]],"batl":[[0,1.38,5.27],[1,1.39,406.69],[2,1.4,315.69]],"ltp":1.38,"tv":42667.59,"id":9323645}],"tv":56681.29}]}
{"op":"mcm","clk":"4216851005","pt":1631555969179,"mc":[{"id":"1.187566733","rc":[{"trd":[[1.38,1499.77],[1.39,2435.39]],"batb":[[0,1.37,486.38]],"batl":[[0,1.39,362.51],[1,1.4,315.69],[2,1.41,542.82]],"ltp":1.39,"tv":42766.5,"id":9323645}],"tv":56780.19}]}
{"op":"mcm","clk":"4216851076","pt":1631555970069,"mc":[{"id":"1.187566733","rc":[{"trd":[[1.39,2601.18]],"batl":[[0,1.39,279.62],[1,1.4,102.34]],"ltp":1.39,"tv":42932.28,"id":9323645}],"tv":56945.98}]}
{"op":"mcm","clk":"4216851239","pt":1631555971792,"mc":[{"id":"1.187566733","rc":[{"trd":[[1.39,2666.82]],"batl":[[0,1.39,246.8]],"ltp":1.39,"tv":42997.93,"id":9323645}],"tv":57011.62}]}
{"op":"mcm","clk":"4216851396","pt":1631555973093,"mc":[{"id":"1.187566733","rc":[{"batb":[[0,3.25,3.53],[1,3.15,3.83],[2,3.1,33.32]],"batl":[[0,4.1,3.05],[1,4.2,2.68],[2,4.3,2.85]],"ltp":3.6,"tv":14013.69,"id":8734382},{"batb":[[0,1.37,256.02],[1,1.36,89.46],[2,1.34,1.71]],"batl":[[0,1.39,249.53],[2,1.41,357.51]],"ltp":1.39,"tv":42997.93,"id":9323645}]}]}
{"op":"mcm","clk":"4216851477","pt":1631555974188,"mc":[{"id":"1.187566733","rc":[{"batb":[[2,2.86,41.37]],"ltp":3.6,"tv":14013.69,"id":8734382},{"batb":[[1,1.34,1.71],[2,1.33,76.53]],"batl":[[0,1.39,221.55],[1,1.41,256.02],[2,1.43,42.31]],"ltp":1.39,"tv":42997.93,"id":9323645}]}]}
{"op":"mcm","clk":"4216851519","pt":1631555974707,"mc":[{"id":"1.187566733","rc":[{"trd":[[1.39,2677.08]],"batl":[[0,1.39,216.42]],"ltp":1.39,"tv":43008.18,"id":9323645}],"tv":57021.88}]}
{"op":"mcm","clk":"4216851635","pt":1631555976180,"mc":[{"id":"1.187566733","rc":[{"batb":[[0,1.38,256.02],[1,1.37,256.02],[2,1.34,1.71]],"ltp":1.39,"tv":43008.18,"id":9323645}]}]}
{"op":"mcm","clk":"4216851926","pt":1631555979003,"mc":[{"id":"1.187566733","rc":[{"trd":[[1.39,2769.38]],"batl":[[0,1.43,42.31],[1,1.44,56.83],[2,1.45,34.9]],"ltp":1.39,"tv":43100.49,"id":9323645}],"tv":57114.18}]}
{"op":"mcm","clk":"4216851982","pt":1631555979688,"mc":[{"id":"1.187566733","rc":[{"batb":[[0,3.15,3.83],[1,2.86,41.37],[2,1.01,98.87]],"batl":[[0,3.55,11.69],[1,4.1,3.05],[2,4.2,2.68]],"ltp":3.6,"tv":14013.69,"id":8734382},{"batl":[[0,1.45,34.9],[1,1.46,134.04],[2,1.47,113.85]],"ltp":1.39,"tv":43100.49,"id":9323645}]}]}
{"op":"mcm","clk":"4216852081","pt":1631555981093,"mc":[{"id":"1.187566733","rc":[{"trd":[[3.25,35.28]],"batb":[[0,3.25,3.54],[1,3.15,3.83],[2,2.86,41.37]],"batl":[[0,3.35,5.91]],"ltp":3.25,"tv":14019.85,"id":8734382},{"batb":[[0,1.43,277.82],[1,1.42,133.18],[2,1.41,621.18]],"batl":[[2,1.47,621.45]],"ltp":1.39,"tv":43100.49,"id":9323645}],"tv":57120.34}]}
{"op":"mcm","clk":"4216852154","pt":1631555982185,"mc":[{"id":"1.187566733","rc":[{"batb":[[1,3.2,9.38],[2,3.15,8.51]],"ltp":3.25,"tv":14019.85,"id":8734382},{"batb":[[0,1.43,219.08],[1,1.42,208.79]],"ltp":1.39,"tv":43100.49,"id":9323645}]}]}
{"op":"mcm","clk":"4216852270","pt":1631555983917,"mc":[{"id":"1.187566733","rc":[{"batl":[[0,1.45,14.9]],"ltp":1.39,"tv":43100.49,"id":9323645}]}]}
{"op":"mcm","clk":"4216852441","pt":1631555986112,"mc":[{"id":"1.187566733","rc":[{"trd":[[3.25,42.28]],"batb":[[0,3.2,9.42],[1,3.15,8.51],[2,3.1,4.68]],"ltp":3.25,"tv":14026.85,"id":8734382},{"batb":[[0,1.43,303.99]],"batl":[[0,1.44,42.02],[1,1.45,306.07],[2,1.46,134.04]],"ltp":1.39,"tv":43100.49,"id":9323645}],"tv":57127.34}]}
{"op":"mcm","clk":"4216852585","pt":1631555987896,"mc":[{"id":"1.187566733","rc":[{"trd":[[1.44,531.74]],"batl":[[0,1.44,19.64]],"ltp":1.44,"tv":43145.24,"id":9323645}],"tv":57172.09}]}
{"op":"mcm","clk":"4216852632","pt":1631555988520,"mc":[{"id":"1.187566733","rc":[{"batb":[[2,3.1,8.72]],"batl":[[1,3.6,3.11],[2,3.75,3.1]],"ltp":3.25,"tv":14026.85,"id":8734382},{"batl":[[1,1.45,477.07]],"ltp":1.44,"tv":43145.24,"id":9323645}]}]}
{"op":"mcm","clk":"4216852793","pt":1631555990009,"mc":[{"id":"1.187566733","rc":[{"trd":[[1.43,2385.83]],"batb":[[0,1.43,546.94]],"batl":[[1,1.45,733.09]],"ltp":1.43,"tv":43171.38,"id":9323645}],"tv":57198.23}]}
{"op":"mcm","clk":"4216852882","pt":1631555991140,"mc":[{"id":"1.187566733","rc":[{"trd":[[3.2,46.28],[3.25,42.36]],"batb":[[0,3.15,8.51],[1,3.1,8.72],[2,3.05,4.49]],"batl":[[0,3.6,3.11],[1,3.75,3.1],[2,4.1,3.05]],"ltp":3.2,"tv":14068.07,"id":8734382},{"trd":[[1.44,571.02],[1.45,4250.91]],"batb":[[0,1.44,236.38],[1,1.43,546.94],[2,1.42,208.79]],"batl":[[0,1.45,512.71],[1,1.46,134.04],[2,1.47,671.95]],"ltp":1.45,"tv":43260.04,"id":9323645}],"tv":57328.11}]}
{"op":"mcm","clk":"4216852959","pt":1631555992105,"mc":[{"id":"1.187566733","rc":[{"batb":[[0,3.05,4.49],[1,3,3.5],[2,2.74,18.97]],"ltp":3.2,"tv":14068.07,"id":8734382},{"batb":[[1,1.43,256.02],[2,1.39,63.91]],"batl":[[0,1.45,445.66],[1,1.48,53.74],[2,1.49,52.5]],"ltp":1.45,"tv":43260.04,"id":9323645}]}]}
{"op":"mcm","clk":"4216853026","pt":1631555992939,"mc":[{"id":"1.187566733","rc":[{"trd":[[1.44,571.56]],"batb":[[0,1.44,236.11]],"ltp":1.44,"tv":43260.58,"id":9323645}],"tv":57328.65}]}
{"op":"mcm","clk":"4216853105","pt":1631555994110,"mc":[{"id":"1.187566733","rc":[{"batb":[[0,3.2,6.6],[1,3.05,4.49],[2,3,3.5]],"batl":[[0,3.3,6.31],[1,3.6,3.11],[2,3.75,3.1]],"ltp":3.2,"tv":14068.07,"id":8734382},{"trd":[[1.44,930.8]],"batb":[[0,1.44,56.49]],"ltp":1.44,"tv":43619.81,"id":9323645}],"tv":57687.88}]}
{"op":"mcm","clk":"4216853189","pt":1631555995001,"mc":[{"id":"1.187566733","rc":[{"batb":[[0,3.1,4.04]],"batl":[[0,3.6,3.11],[1,3.75,3.1],[2,4.1,3.05]],"ltp":3.2,"tv":14068.07,"id":8734382},{"batl":[[1,1.47,53.5],[2,1.48,53.74]],"ltp":1.44,"tv":43619.81,"id":9323645}]}]}
{"op":"mcm","clk":"4216853268","pt":1631555995939,"mc":[{"id":"1.187566733","rc":[{"batb":[[2,1.42,10]],"ltp":1.44,"tv":43619.81,"id":9323645}]}]}
{"op":"mcm","clk":"4216853383","pt":1631555997200,"mc":[{"id":"1.187566733","rc":[{"trd":[[1.44,1043.78]],"batb":[[0,1.43,256.02],[1,1.42,20],[2,1.39,63.91]],"batl":[[0,1.44,40.48],[1,1.45,445.66],[2,1.47,53.5]],"ltp":1.44,"tv":43732.8,"id":9323645}],"tv":57800.87}]}
{"op":"mcm","clk":"4216853485","pt":1631555998505,"mc":[{"id":"1.187566733","rc":[{"trd":[[3.25,48.77]],"ltp":3.25,"tv":14074.47,"id":8734382},{"trd":[[1.44,1058.24]],"batl":[[0,1.44,26.02]],"ltp":1.44,"tv":43747.26,"id":9323645}],"tv":57821.73}]}
{"op":"mcm","clk":"4216853635","pt":1631556000238,"mc":[{"id":"1.187566733","rc":[{"batb":[[1,1.39,63.91],[2,1.38,10]],"ltp":1.44,"tv":43747.26,"id":9323645}]}]}
{"op":"mcm","clk":"4216853863","pt":1631556001840,"mc":[{"id":"1.187566733","rc":[{"batb":[[2,1.37,253.24]],"ltp":1.44,"tv":43747.26,"id":9323645}]}]}
{"op":"mcm","clk":"4216853970","pt":1631556002725,"mc":[{"id":"1.187566733","rc":[{"trd":[[1.44,1110.21]],"batl":[[0,1.45,445.69],[1,1.47,53.5],[2,1.48,53.74]],"ltp":1.44,"tv":43799.23,"id":9323645}],"tv":57873.7}]}
{"op":"mcm","clk":"4216854053","pt":1631556003540,"mc":[{"id":"1.187566733","rc":[{"trd":[[1.44,1110.28]],"batb":[[0,1.44,9.97],[1,1.43,256.02],[2,1.39,63.91]],"batl":[[0,1.45,445.66]],"ltp":1.44,"tv":43799.29,"id":9323645}],"tv":57873.77}]}
{"op":"mcm","clk":"4216854314","pt":1631556005255,"mc":[{"id":"1.187566733","rc":[{"trd":[[1.44,1110.72]],"batb":[[0,1.44,9.75]],"ltp":1.44,"tv":43799.73,"id":9323645}],"tv":57874.21}]}
{"op":"mcm","clk":"4216854654","pt":1631556007167,"mc":[{"id":"1.187566733","rc":[{"trd":[[1.44,1130.22]],"batb":[[0,1.39,63.91],[1,1.37,253.24],[2,1.36,255.73]],"ltp":1.44,"tv":43819.23,"id":9323645}],"tv":57893.71}]}
{"op":"mcm","clk":"4216854660","pt":1631556007224,"mc":[{"id":"1.187566733","rc":[{"batl":[[0,3.75,3.1],[1,4.1,3.05],[2,4.2,2.68]],"ltp":3.25,"tv":14074.47,"id":8734382},{"batb":[[0,1.37,253.24],[1,1.36,255.73],[2,1.34,1.71]],"ltp":1.44,"tv":43819.23,"id":9323645}]}]}
{"op":"mcm","clk":"4216854907","pt":1631556008959,"mc":[{"id":"1.187566733","rc":[{"batb":[[0,1.37,243.24]],"ltp":1.44,"tv":43819.23,"id":9323645}]}]}
{"op":"mcm","clk":"4216855043","pt":1631556010171,"mc":[{"id":"1.187566733","rc":[{"batb":[[0,3.4,242.86],[1,3.35,19.91],[2,3.3,49.6]],"batl":[[0,3.6,6.23],[1,3.75,225.2],[2,4.1,3.05]],"ltp":3.25,"tv":14074.47,"id":8734382},{"batl":[[0,1.4,104.96],[1,1.41,163.97],[2,1.42,47.25]],"ltp":1.44,"tv":43819.23,"id":9323645}]}]}
{"op":"mcm","clk":"4216855149","pt":1631556011145,"mc":[{"id":"1.187566733","rc":[{"batb":[[0,3.4,225.21],[1,3.35,11.09],[2,3.3,40.78]],"batl":[[0,3.55,2.82],[1,3.6,6.23],[2,3.75,233.2]],"ltp":3.25,"tv":14074.47,"id":8734382}]}]}
{"op":"mcm","clk":"4216855259","pt":1631556012561,"mc":[{"id":"1.187566733","rc":[{"batb":[[0,1.38,18.22],[1,1.37,243.24],[2,1.36,255.73]],"ltp":1.44,"tv":43819.23,"id":9323645}]}]}
{"op":"mcm","clk":"4216855509","pt":1631556015070,"mc":[{"id":"1.187566733","rc":[{"trd":[[3.55,74.13]],"batl":[[0,3.6,6.23],[1,3.75,233.2],[2,3.8,4]],"ltp":3.55,"tv":14077.29,"id":8734382},{"trd":[[1.39,2776.58]],"batb":[[0,1.38,118.52]],"batl":[[0,1.39,311.2],[1,1.4,104.96],[2,1.41,163.97]],"ltp":1.39,"tv":43826.43,"id":9323645}],"tv":57903.73}]}
{"op":"mcm","clk":"4216855595","pt":1631556015982,"mc":[{"id":"1.187566733","rc":[{"trd":[[1.39,2786.58]],"batb":[[0,1.38,100.3]],"batl":[[0,1.39,306.2],[1,1.4,345.32]],"ltp":1.39,"tv":43836.43,"id":9323645}],"tv":57913.73}]}
{"op":"mcm","clk":"4216855773","pt":1631556017755,"mc":[{"id":"1.187566733","rc":[{"batb":[[1,1.37,336.2]],"ltp":1.39,"tv":43836.43,"id":9323645}]}]}
{"op":"mcm","clk":"4216856094","pt":1631556021156,"mc":[{"id":"1.187566733","rc":[{"batb":[[0,1.37,336.2],[1,1.36,255.73],[2,1.34,1.71]],"batl":[[0,1.39,415.6]],"ltp":1.39,"tv":43836.43,"id":9323645}]}]}
{"op":"mcm","clk":"4216856463","pt":1631556024176,"mc":[{"id":"1.187566733","rc":[{"trd":[[3.6,228.89]],"batl":[[0,3.75,233.2],[1,3.8,4],[2,3.85,4]],"ltp":3.6,"tv":14083.52,"id":8734382},{"trd":[[1.38,1516.03]],"batl":[[0,1.38,96.02],[1,1.39,415.6],[2,1.4,200.32]],"ltp":1.38,"tv":43852.69,"id":9323645}],"tv":57936.22}]}
{"op":"mcm","clk":"4216856517","pt":1631556024657,"mc":[{"id":"1.187566733","rc":[{"batl":[[0,1.38,363.17]],"ltp":1.38,"tv":43852.69,"id":9323645}]}]}
{"op":"mcm","clk":"4216856596","pt":1631556025459,"mc":[{"id":"1.187566733","rc":[{"batb":[[0,1.37,592.22]],"ltp":1.38,"tv":43852.69,"id":9323645}]}]}
{"op":"mcm","clk":"4216856893","pt":1631556027872,"mc":[{"id":"1.187566733","rc":[{"batl":[[0,1.38,807.44]],"ltp":1.38,"tv":43852.69,"id":9323645}]}]}
{"op":"mcm","clk":"4216857116","pt":1631556030201,"mc":[{"id":"1.187566733","rc":[{"batb":[[0,3.25,3.33],[1,3.2,3.27],[2,3.15,36.11]],"batl":[[0,4.3,2.85],[1,4.4,2.44],[2,4.5,2.33]],"ltp":3.6,"tv":14083.52,"id":8734382},{"trd":[[1.37,3337.26]],"batb":[[0,1.37,348.98],[1,1.36,91.22]],"batl":[[2,1.4,95.36]],"ltp":1.37,"tv":44213.99,"id":9323645}],"tv":58297.52}]}
{"op":"mcm","clk":"4216857169","pt":1631556030691,"mc":[{"id":"1.187566733","rc":[{"batb":[[2,3.15,3.63]],"ltp":3.6,"tv":14083.52,"id":8734382},{"batb":[[0,1.37,256.02],[1,1.34,1.71],[2,1.32,12.7]],"batl":[[0,1.38,363.17],[1,1.39,328.22],[2,1.44,54.58]],"ltp":1.37,"tv":44213.99,"id":9323645}]}]}
{"op":"mcm","clk":"4216857609","pt":1631556034986,"mc":[{"id":"1.187566733","rc":[{"batb":[[0,1.34,1.71],[1,1.32,12.7],[2,1.31,71.79]],"ltp":1.37,"tv":44213.99,"id":9323645}]}]}
{"op":"mcm","clk":"4216857710","pt":1631556036086,"mc":[{"id":"1.187566733","rc":[{"batl":[[0,4.5,2.33],[1,4.9,2.35],[2,5.4,2.04]],"ltp":3.6,"tv":14083.52,"id":8734382},{"batb":[[1,1.32,22.7],[2,1.31,10]],"ltp":1.37,"tv":44213.99,"id":9323645}]}]}
{"op":"mcm","clk":"4216857810","pt":1631556036997,"mc":[{"id":"1.187566733","rc":[{"batb":[[0,3.65,21.93],[1,3.25,3.33],[2,3.2,3.27]],"batl":[[0,3.8,20.62],[1,4.5,2.33],[2,4.9,2.35]],"ltp":3.6,"tv":14083.52,"id":8734382},{"batb":[[0,1.35,195.03],[1,1.34,180.04],[2,1.32,22.7]],"batl":[[0,1.38,504.49],[1,1.39,475.07]],"ltp":1.37,"tv":44213.99,"id":9323645}]}]}
{"op":"mcm","clk":"4216857883","pt":1631556037575,"mc":[{"id":"1.187566733","rc":[{"batb":[[0,3.25,3.33],[1,3.2,3.27],[2,3.15,3.63]],"batl":[[0,4.5,2.33],[1,4.9,2.35],[2,5.4,2.04]],"ltp":3.6,"tv":14083.52,"id":8734382},{"batb":[[2,1.32,12.7]],"batl":[[0,1.38,482.24]],"ltp":1.37,"tv":44213.99,"id":9323645}]}]}
{"op":"mcm","clk":"4216858028","pt":1631556038988,"mc":[{"id":"1.187566733","rc":[{"batb":[[0,1.34,1.71],[1,1.33,256.02]],"batl":[[0,1.37,115.32],[1,1.38,363.17],[2,1.39,328.22]],"ltp":1.37,"tv":44213.99,"id":9323645}]}]}
{"op":"mcm","clk":"4216858104","pt":1631556039780,"mc":[{"id":"1.187566733","rc":[{"batl":[[2,1.44,54.58]],"ltp":1.37,"tv":44213.99,"id":9323645}]}]}
{"op":"mcm","clk":"4216858303","pt":1631556041980,"mc":[{"id":"1.187566733","rc":[{"batl":[[0,4.3,2.45],[1,4.5,2.33],[2,4.9,2.35]],"ltp":3.6,"tv":14083.52,"id":8734382}]}]}
{"op":"mcm","clk":"4216858738","pt":1631556046112,"mc":[{"id":"1.187566733","rc":[{"batb":[[1,1.32,12.7],[2,1.31,107.79]],"ltp":1.37,"tv":44213.99,"id":9323645}]}]}
{"op":"mcm","clk":"4216858771","pt":1631556046369,"mc":[{"id":"1.187566733","rc":[{"batl":[[0,4.5,2.33],[1,4.9,2.35],[2,5.4,2.04]],"ltp":3.6,"tv":14083.52,"id":8734382},{"batb":[[2,1.31,20]],"batl":[[0,1.38,267.14],[1,1.44,54.58],[2,1.45,54.7]],"ltp":1.37,"tv":44213.99,"id":9323645}]}]}
{"op":"mcm","clk":"4216859006","pt":1631556048858,"mc":[{"id":"1.187566733","rc":[{"batb":[[0,3.95,30.38],[1,3.9,10.16],[2,3.5,485.56]],"batl":[[0,4.4,244.35],[1,4.5,2.33],[2,4.9,2.35]],"ltp":3.6,"tv":14083.52,"id":8734382},{"trd":[[1.32,425.4],[1.34,2207.77]],"batb":[[0,1.31,36.32],[1,1.29,469.9],[2,1.28,231.01]],"batl":[[0,1.32,152.44],[1,1.33,279.49],[2,1.34,123.59]],"ltp":1.32,"tv":44242.81,"id":9323645}],"tv":58326.33}]}
{"op":"mcm","clk":"4216859130","pt":1631556050037,"mc":[{"id":"1.187566733","rc":[{"trd":[[4.1,2.44]],"batb":[[2,3.6,22.99]],"batl":[[1,4.5,8.99],[2,4.6,3.34]],"ltp":4.1,"tv":14085.96,"id":8734382},{"trd":[[1.32,432.98]],"batl":[[0,1.32,144.86],[1,1.33,234.38],[2,1.34,101.03]],"ltp":1.32,"tv":44250.39,"id":9323645}],"tv":58336.35}]}
{"op":"mcm","clk":"4216859235","pt":1631556050994,"mc":[{"id":"1.187566733","rc":[{"batl":[[1,1.33,241.31]],"ltp":1.32,"tv":44250.39,"id":9323645}]}]}
{"op":"mcm","clk":"4216859353","pt":1631556052103,"mc":[{"id":"1.187566733","rc":[{"trd":[[1.32,500.94]],"batb":[[0,1.31,16.32]],"batl":[[0,1.32,110.88]],"ltp":1.32,"tv":44318.35,"id":9323645}],"tv":58404.31}]}
{"op":"mcm","clk":"4216859471","pt":1631556053003,"mc":[{"id":"1.187566733","rc":[{"batb":[[1,1.3,130.34],[2,1.29,416.32]],"batl":[[0,1.32,682.4],[1,1.33,234.38]],"ltp":1.32,"tv":44318.35,"id":9323645}]}]}
{"op":"mcm","clk":"4216859569","pt":1631556053892,"mc":[{"id":"1.187566733","rc":[{"trd":[[1.29,278.21],[1.3,260.7],[1.31,32.65],[1.32,570.94]],"batb":[[0,1.29,277.21],[1,1.19,182.86],[2,1.17,36.86]],"batl":[[0,1.31,446.54],[1,1.32,647.4],[2,1.33,234.38]],"ltp":1.32,"tv":44959.9,"id":9323645}],"tv":59045.87}]}
{"op":"mcm","clk":"4216859671","pt":1631556054996,"mc":[{"id":"1.187566733","rc":[{"trd":[[1.31,72.65]],"batl":[[0,1.31,433.47],[1,1.32,204.24]],"ltp":1.31,"tv":44999.91,"id":9323645}],"tv":59085.87}]}
{"op":"mcm","clk":"4216859756","pt":1631556055739,"mc":[{"id":"1.187566733","rc":[{"batb":[[0,1.3,83.62],[1,1.29,277.21],[2,1.19,182.86]],"batl":[[1,1.32,458.51]],"ltp":1.31,"tv":44999.91,"id":9323645}]}]}
{"op":"mcm","clk":"4216859944","pt":1631556057000,"mc":[{"id":"1.187566733","rc":[{"batb":[[1,1.29,307.26]],"batl":[[0,1.31,556.58]],"ltp":1.31,"tv":44999.91,"id":9323645}]}]}
{"op":"mcm","clk":"4216860071","pt":1631556058108,"mc":[{"id":"1.187566733","rc":[{"batb":[[0,1.3,103.34]],"batl":[[0,1.31,549.65],[1,1.32,474.16]],"ltp":1.31,"tv":44999.91,"id":9323645}]}]}
{"op":"mcm","clk":"4216860168","pt":1631556059019,"mc":[{"id":"1.187566733","rc":[{"trd":[[1.29,760.35],[1.3,467.38],[1.31,93.98]],"batb":[[0,1.29,66.19],[1,1.19,182.86],[2,1.17,36.86]],"batl":[[0,1.3,6.93],[1,1.31,538.98],[2,1.32,474.16]],"ltp":1.29,"tv":45710.06,"id":9323645}],"tv":59796.03}]}
{"op":"mcm","clk":"4216860260","pt":1631556059918,"mc":[{"id":"1.187566733","rc":[{"batl":[[0,1.3,13.85]],"ltp":1.29,"tv":45710.06,"id":9323645}]}]}
{"op":"mcm","clk":"4216860378","pt":1631556060919,"mc":[{"id":"1.187566733","rc":[{"trd":[[1.3,471.39]],"batl":[[0,1.3,11.85]],"ltp":1.3,"tv":45714.06,"id":9323645}],"tv":59800.03}]}
{"op":"mcm","clk":"4216860515","pt":1631556061922,"mc":[{"id":"1.187566733","rc":[{"trd":[[1.3,471.76]],"batb":[[0,1.29,194.13],[1,1.28,231.03],[2,1.19,182.86]],"batl":[[0,1.3,11.66],[2,1.32,627.81]],"ltp":1.3,"tv":45714.44,"id":9323645}],"tv":59800.4}]}
{"op":"mcm","clk":"4216860647","pt":1631556063091,"mc":[{"id":"1.187566733","rc":[{"batl":[[0,1.3,130.86],[1,1.31,795]],"ltp":1.3,"tv":45714.44,"id":9323645}]}]}
{"op":"mcm","clk":"4216860747","pt":1631556064001,"mc":[{"id":"1.187566733","rc":[{"batb":[[0,1.29,450.15]],"ltp":1.3,"tv":45714.44,"id":9323645}]}]}
{"op":"mcm","clk":"4216860915","pt":1631556065642,"mc":[{"id":"1.187566733","rc":[{"batb":[[0,3.5,4.08],[1,3.25,3.33],[2,3.1,33.48]],"batl":[[0,990,0.01],[1,4.5,0],[2,4.6,0]],"ltp":4.1,"tv":14085.96,"id":8734382},{"batb":[[0,1.29,286.07],[1,1.19,182.86],[2,1.17,36.86]],"batl":[[1,1.31,379.13],[2,1.32,358.36]],"ltp":1.3,"tv":45714.44,"id":9323645}]}]}
{"op":"mcm","clk":"4216861099","pt":1631556067119,"mc":[{"id":"1.187566733","rc":[{"trd":[[4.3,5.22]],"ltp":4.3,"tv":14091.18,"id":8734382},{"trd":[[1.3,489.04]],"batb":[[0,1.29,256.02]],"batl":[[0,1.3,1.3],[1,1.31,256.02],[2,1.4,65.99]],"ltp":1.3,"tv":45731.72,"id":9323645}],"tv":59822.91}]}
{"op":"mcm","clk":"4216861155","pt":1631556067698,"mc":[{"id":"1.187566733","rc":[{"trd":[[1.29,1272.38]],"batb":[[0,1.19,182.86],[1,1.17,36.86],[2,1.15,50.83]],"batl":[[0,1.29,38.25],[1,1.3,1.3],[2,1.31,256.02]],"ltp":1.29,"tv":46243.75,"id":9323645}],"tv":60334.94}]}
{"op":"mcm","clk":"4216861286","pt":1631556068903,"mc":[{"id":"1.187566733","rc":[{"batb":[[2,3.2,31.81]],"ltp":4.3,"tv":14091.18,"id":8734382},{"batb":[[0,1.2,329.5],[1,1.19,428.74],[2,1.17,36.86]],"ltp":1.29,"tv":46243.75,"id":9323645}]}]}
{"op":"mcm","clk":"4216861384","pt":1631556069695,"mc":[{"id":"1.187566733","rc":[{"trd":[[1.3,491.64]],"batb":[[0,1.3,49.7],[1,1.19,182.86]],"batl":[[0,1.31,256.02],[1,1.4,65.99],[2,1.44,54.58]],"ltp":1.3,"tv":46246.36,"id":9323645}],"tv":60337.54}]}
{"op":"mcm","clk":"4216861629","pt":1631556072119,"mc":[{"id":"1.187566733","rc":[{"trd":[[4.4,14.68]],"ltp":4.4,"tv":14105.86,"id":8734382},{"trd":[[1.3,541.88]],"batb":[[0,1.27,206.45],[1,1.26,254.76],[2,1.19,182.86]],"batl":[[0,1.3,281.49],[1,1.31,453.75],[2,1.4,65.99]],"ltp":1.3,"tv":46296.6,"id":9323645}],"tv":60402.46}]}
{"op":"mcm","clk":"4216861684","pt":1631556072704,"mc":[{"id":"1.187566733","rc":[{"batb":[[2,1.21,20.92]],"ltp":1.3,"tv":46296.6,"id":9323645}]}]}
{"op":"mcm","clk":"4216861836","pt":1631556074013,"mc":[{"id":"1.187566733","rc":[{"batb":[[0,1.27,206.82],[2,1.24,256.02]],"batl":[[0,1.3,446.52]],"ltp":1.3,"tv":46296.6,"id":9323645}]}]}
{"op":"mcm","clk":"4216861947","pt":1631556074910,"mc":[{"id":"1.187566733","rc":[{"batb":[[0,1.24,256.39],[1,1.21,20.92],[2,1.2,20]],"batl":[[0,1.3,251.85],[1,1.31,256.02]],"ltp":1.3,"tv":46296.6,"id":9323645}]}]}
{"op":"mcm","clk":"4216862179","pt":1631556077119,"mc":[{"id":"1.187566733","rc":[{"batb":[[0,1.29,5.37],[1,1.24,256.02],[2,1.21,20.92]],"ltp":1.3,"tv":46296.6,"id":9323645}]}]}
{"op":"mcm","clk":"4216862204","pt":1631556077431,"mc":[{"id":"1.187566733","rc":[{"batl":[[2,1.4,228.62]],"ltp":1.3,"tv":46296.6,"id":9323645}]}]}
{"op":"mcm","clk":"4216862344","pt":1631556078742,"mc":[{"id":"1.187566733","rc":[{"batb":[[0,1.24,256.39],[1,1.21,20.92],[2,1.2,369.5]],"ltp":1.3,"tv":46296.6,"id":9323645}]}]}
{"op":"mcm","clk":"4216862722","pt":1631556082018,"mc":[{"id":"1.187566733","rc":[{"trd":[[3.5,31.89],[4.2,79.84],[4.3,79.84]],"batb":[[0,3.25,3.33],[1,3.2,31.81],[2,1.01,98.87]],"ltp":3.5,"tv":14282.35,"id":8734382},{"trd":[[1.3,798.74],[1.31,350],[1.4,3003.38]],"batl":[[0,1.4,193.95],[1,1.41,137.88],[2,1.44,54.58]],"ltp":1.4,"tv":46844.13,"id":9323645}],"tv":61126.49}]}
{"op":"mcm","clk":"4216862805","pt":1631556082860,"mc":[{"id":"1.187566733","rc":[{"batl":[[0,1.3,2.13],[1,1.4,162.63],[2,1.41,137.88]],"ltp":1.4,"tv":46844.13,"id":9323645}]}]}
{"op":"mcm","clk":"4216863233","pt":1631556087146,"mc":[{"id":"1.187566733","rc":[{"batl":[[1,1.39,10],[2,1.4,162.63]],"ltp":1.4,"tv":46844.13,"id":9323645}]}]}
{"op":"mcm","clk":"4216863270","pt":1631556087561,"mc":[{"id":"1.187566733","rc":[{"batl":[[1,1.39,30]],"ltp":1.4,"tv":46844.13,"id":9323645}]}]}
{"op":"mcm","clk":"4216863729","pt":1631556091930,"mc":[{"id":"1.187566733","rc":[{"batb":[[1,1.2,369.5],[2,1.19,428.74]],"ltp":1.4,"tv":46844.13,"id":9323645}]}]}
{"op":"mcm","clk":"4216864081","pt":1631556095149,"mc":[{"id":"1.187566733","rc":[{"batl":[[2,8.8,7.7]],"ltp":1.4,"tv":46844.13,"id":9323645}]}]}
{"op":"mcm","clk":"4216864103","pt":1631556095389,"mc":[{"id":"1.187566733","rc":[{"batb":[[0,1.2,369.87],[1,1.19,428.74],[2,1.17,36.86]],"ltp":1.4,"tv":46844.13,"id":9323645}]}]}
{"op":"mcm","clk":"4216864386","pt":1631556097966,"mc":[{"id":"1.187566733","rc":[{"batb":[[0,5.5,10.05],[1,5.4,25.18],[2,5.3,24.44]],"batl":[[0,5.7,4.4],[1,6,165.7],[2,6.4,21.26]],"ltp":3.5,"tv":14282.35,"id":8734382},{"trd":[[1.29,1273.12]],"batb":[[0,1.2,1197.99]],"batl":[[0,1.22,278.63],[1,1.23,2230.32],[2,1.24,4.03]],"ltp":1.29,"tv":46844.88,"id":9323645}],"tv":61127.23}]}
{"op":"mcm","clk":"4216864532","pt":1631556099175,"mc":[{"id":"1.187566733","rc":[{"trd":[[1.22,20.42]],"batb":[[1,1.19,429.16]],"batl":[[0,1.22,268.42],[1,1.23,487.34]],"ltp":1.22,"tv":46865.3,"id":9323645}],"tv":61147.65}]}
{"op":"mcm","clk":"4216864617","pt":1631556100063,"mc":[{"id":"1.187566733","rc":[{"batb":[[0,1.2,1177.99]],"ltp":1.22,"tv":46865.3,"id":9323645}]}]}
{"op":"mcm","clk":"4216864940","pt":1631556103167,"mc":[{"id":"1.187566733","rc":[{"trd":[[1.22,570.17]],"batb":[[0,1.2,1157.99],[1,1.19,348.11]],"batl":[[0,1.22,111.49]],"ltp":1.22,"tv":47415.05,"id":9323645}],"tv":61697.4}]}
{"op":"mcm","clk":"4216865011","pt":1631556103689,"mc":[{"id":"1.187566733","rc":[{"trd":[[5.7,0.42]],"batl":[[0,5.7,3.98]],"ltp":5.7,"tv":14282.77,"id":8734382},{"trd":[[1.21,2]],"batl":[[0,1.22,349.49]],"ltp":1.21,"tv":47417.05,"id":9323645}],"tv":61699.82}]}
{"op":"mcm","clk":"4216865294","pt":1631556106052,"mc":[{"id":"1.187566733","rc":[{"trd":[[1.22,644.99]],"batb":[[0,1.2,1238.37]],"batl":[[0,1.22,312.08],[1,1.23,669.99],[2,1.24,208.61]],"ltp":1.22,"tv":47491.87,"id":9323645}],"tv":61774.64}]}
{"op":"mcm","clk":"4216865393","pt":1631556106988,"mc":[{"id":"1.187566733","rc":[{"batb":[[0,1.2,1264.8]],"ltp":1.22,"tv":47491.87,"id":9323645}]}]}
{"op":"mcm","clk":"4216865663","pt":1631556109163,"mc":[{"id":"1.187566733","rc":[{"trd":[[5.7,4.4]],"batl":[[0,6,165.7],[1,6.4,21.26],[2,6.6,20.62]],"ltp":5.7,"tv":14286.75,"id":8734382},{"trd":[[1.2,169.62],[1.21,20.75]],"batb":[[0,1.2,1181.36]],"batl":[[0,1.21,81.25],[1,1.22,312.08],[2,1.23,669.99]],"ltp":1.2,"tv":47680.24,"id":9323645}],"tv":61967.0}]}
{"op":"mcm","clk":"4216865736","pt":1631556109791,"mc":[{"id":"1.187566733","rc":[{"trd":[[1.21,183.27],[1.22,679.67]],"batb":[[0,1.21,121.92],[1,1.2,1181.36],[2,1.19,349.5]],"batl":[[0,1.22,294.74],[1,1.23,517.09],[2,1.24,4.03]],"ltp":1.22,"tv":47877.44,"id":9323645}],"tv":62164.2}]}
{"op":"mcm","clk":"4216865870","pt":1631556111097,"mc":[{"id":"1.187566733","rc":[{"trd":[[1.21,301.02],[1.22,680.21]],"batb":[[0,1.21,63.03]],"batl":[[0,1.22,294.47]],"ltp":1.21,"tv":47995.73,"id":9323645}],"tv":62282.49}]}
{"op":"mcm","clk":"4216865983","pt":1631556112196,"mc":[{"id":"1.187566733","rc":[{"trd":[[1.2,1272.58],[1.21,559.37],[1.22,680.59]],"batb":[[0,1.2,629.88],[1,1.19,349.5],[2,1.18,1.39]],"batl":[[0,1.22,294.28]],"ltp":1.22,"tv":49357.42,"id":9323645}],"tv":63644.18}]}
{"op":"mcm","clk":"4216866049","pt":1631556112781,"mc":[{"id":"1.187566733","rc":[{"batb":[[0,1.2,667.83],[1,1.19,396.77]],"batl":[[0,1.22,402.96]],"ltp":1.22,"tv":49357.42,"id":9323645}]}]}
{"op":"mcm","clk":"4216866178","pt":1631556113888,"mc":[{"id":"1.187566733","rc":[{"trd":[[1.22,720.59]],"batl":[[0,1.22,382.96],[1,1.23,474.01]],"ltp":1.22,"tv":49397.42,"id":9323645}],"tv":63684.18}]}
{"op":"mcm","clk":"4216866290","pt":1631556114889,"mc":[{"id":"1.187566733","rc":[{"batl":[[1,1.23,411.85]],"ltp":1.22,"tv":49397.42,"id":9323645}]}]}
{"op":"mcm","clk":"4216866375","pt":1631556115777,"mc":[{"id":"1.187566733","rc":[{"batb":[[0,1.2,744.91],[1,1.19,533.12]],"batl":[[0,1.22,515.41]],"ltp":1.22,"tv":49397.42,"id":9323645}]}]}
{"op":"mcm","clk":"4216866474","pt":1631556116882,"mc":[{"id":"1.187566733","rc":[{"batl":[[0,6,171.1]],"ltp":5.7,"tv":14286.75,"id":8734382},{"batb":[[0,1.21,5],[1,1.2,771.92],[2,1.19,533.12]],"batl":[[0,1.22,543.23]],"ltp":1.22,"tv":49397.42,"id":9323645}]}]}
{"op":"mcm","clk":"4216866579","pt":1631556117777,"mc":[{"id":"1.187566733","rc":[{"batb":[[2,1.19,564.63]],"batl":[[0,1.22,575.03]],"ltp":1.22,"tv":49397.42,"id":9323645}]}]}
{"op":"mcm","clk":"4216866740","pt":1631556119177,"mc":[{"id":"1.187566733","rc":[{"batl":[[0,6,165.7]],"ltp":5.7,"tv":14286.75,"id":8734382},{"trd":[[1.21,568.37],[1.22,877.45]],"batb":[[0,1.2,745.41],[1,1.19,564.63],[2,1.18,428.08]],"batl":[[0,1.22,468.78]],"ltp":1.22,"tv":49563.28,"id":9323645}],"tv":63850.04}]}
{"op":"mcm","clk":"4216866844","pt":1631556120077,"mc":[{"id":"1.187566733","rc":[{"trd":[[1.21,569.85]],"batb":[[0,1.21,4.76],[1,1.2,744.91],[2,1.19,564.63]],"ltp":1.21,"tv":49564.76,"id":9323645}],"tv":63851.52}]}
{"op":"mcm","clk":"4216866938","pt":1631556120810,"mc":[{"id":"1.187566733","rc":[{"trd":[[1.22,957.01]],"batl":[[0,1.22,429]],"ltp":1.22,"tv":49644.33,"id":9323645}],"tv":63931.08}]}
{"op":"mcm","clk":"4216867070","pt":1631556121991,"mc":[{"id":"1.187566733","rc":[{"batl":[[0,6,171.1]],"ltp":5.7,"tv":14286.75,"id":8734382},{"batb":[[1,1.2,771.92]],"batl":[[0,1.22,456.82]],"ltp":1.22,"tv":49644.33,"id":9323645}]}]}
{"op":"mcm","clk":"4216867194","pt":1631556122782,"mc":[{"id":"1.187566733","rc":[{"batl":[[0,1.22,623.86]],"ltp":1.22,"tv":49644.33,"id":9323645}]}]}
{"op":"mcm","clk":"4216867728","pt":1631556127194,"mc":[{"id":"1.187566733","rc":[{"trd":[[1.22,963.51]],"batl":[[0,1.22,620.61]],"ltp":1.22,"tv":49650.83,"id":9323645}],"tv":63937.58}]}
{"op":"mcm","clk":"4216867788","pt":1631556127675,"mc":[{"id":"1.187566733","rc":[{"trd":[[5.7,5.3]],"ltp":5.7,"tv":14287.65,"id":8734382},{"trd":[[1.21,583.61]],"batb":[[0,1.2,771.92],[1,1.19,564.63],[2,1.18,428.08]],"batl":[[0,1.21,335.83],[1,1.22,620.61],[2,1.23,411.85]],"ltp":1.21,"tv":49664.59,"id":9323645}],"tv":63952.24}]}
{"op":"mcm","clk":"4216867887","pt":1631556128575,"mc":[{"id":"1.187566733","rc":[{"batl":[[0,1.21,296.61]],"ltp":1.21,"tv":49664.59,"id":9323645}]}]}
{"op":"mcm","clk":"4216868063","pt":1631556130002,"mc":[{"id":"1.187566733","rc":[{"batb":[[0,1.2,745.49],[1,1.19,381.77]],"batl":[[1,1.22,453.57],[2,1.23,291.36]],"ltp":1.21,"tv":49664.59,"id":9323645}]}]}
{"op":"mcm","clk":"4216868438","pt":1631556133182,"mc":[{"id":"1.187566733","rc":[{"trd":[[1.2,2384.32]],"batb":[[0,1.2,189.62]],"batl":[[2,1.23,276.89]],"ltp":1.2,"tv":50776.33,"id":9323645}],"tv":65063.98}]}
{"op":"mcm","clk":"4216868496","pt":1631556133706,"mc":[{"id":"1.187566733","rc":[{"batl":[[1,1.22,300.75]],"ltp":1.2,"tv":50776.33,"id":9323645}]}]}
{"op":"mcm","clk":"4216868677","pt":1631556135139,"mc":[{"id":"1.187566733","rc":[{"batb":[[0,1.2,28.4],[1,1.19,1.81]],"batl":[[1,1.22,27.82],[2,1.24,4.44]],"ltp":1.2,"tv":50776.33,"id":9323645}]}]}
{"op":"mcm","clk":"4216868868","pt":1631556136828,"mc":[{"id":"1.187566733","rc":[{"batl":[[0,1.21,705.61]],"ltp":1.2,"tv":50776.33,"id":9323645}]}]}
{"op":"mcm","clk":"4216869122","pt":1631556138996,"mc":[{"id":"1.187566733","rc":[{"batb":[[0,4.1,2.54],[1,3.85,2.77],[2,3.75,46.59]],"batl":[[0,13.5,2],[1,21,2],[2,26,2]],"ltp":5.7,"tv":14287.65,"id":8734382},{"trd":[[1.2,2387.09]],"batb":[[0,1.19,1.39],[1,1.18,428.08],[2,1.17,38.24]],"batl":[[0,1.21,706.36],[1,1.25,426.69],[2,1.3,110.6]],"ltp":1.2,"tv":50779.09,"id":9323645}],"tv":65066.75}]}
{"op":"mcm","clk":"4216869254","pt":1631556140107,"mc":[{"id":"1.187566733","rc":[{"batl":[[0,1.21,297.36]],"ltp":1.2,"tv":50779.09,"id":9323645}]}]}
{"op":"mcm","clk":"4216869505","pt":1631556142128,"mc":[{"id":"1.187566733","rc":[{"trd":[[1.2,2388.59]],"batl":[[0,1.21,296.61],[2,1.3,2.13]],"ltp":1.2,"tv":50780.59,"id":9323645}],"tv":65068.25}]}
{"op":"mcm","clk":"4216869569","pt":1631556142598,"mc":[{"id":"1.187566733","rc":[{"batl":[[0,1.25,426.69],[1,1.3,2.13],[2,1.32,82.61]],"ltp":1.2,"tv":50780.59,"id":9323645}]}]}
{"op":"mcm","clk":"4216869665","pt":1631556143336,"mc":[{"id":"1.187566733","rc":[{"batb":[[1,1.18,1.39]],"ltp":1.2,"tv":50780.59,"id":9323645}]}]}
{"op":"mcm","clk":"4216869895","pt":1631556145142,"mc":[{"id":"1.187566733","rc":[{"batb":[[0,5.9,18.66],[1,4.1,2.54],[2,3.85,2.77]],"batl":[[0,6.6,20.46],[1,13.5,2],[2,21,2]],"ltp":5.7,"tv":14287.65,"id":8734382},{"batb":[[0,1.19,5],[1,1.18,270.69],[2,1.17,351.89]],"batl":[[0,1.2,283.47],[1,1.21,308.97],[2,1.25,426.69]],"ltp":1.2,"tv":50780.59,"id":9323645}]}]}
{"op":"mcm","clk":"4216869933","pt":1631556145421,"mc":[{"id":"1.187566733","rc":[{"batb":[[0,4.1,2.54],[1,3.85,2.77],[2,3.75,46.59]],"batl":[[0,13.5,2],[1,21,2],[2,26,2]],"ltp":5.7,"tv":14287.65,"id":8734382},{"batl":[[1,1.21,287.47]],"ltp":1.2,"tv":50780.59,"id":9323645}]}]}
{"op":"mcm","clk":"4216870219","pt":1631556147941,"mc":[{"id":"1.187566733","rc":[{"batb":[[0,1.17,36.86],[1,1.1,19.96],[2,1.09,374.87]],"batl":[[0,1.25,426.69],[1,1.3,2.13],[2,1.32,82.61]],"ltp":1.2,"tv":50780.59,"id":9323645}]}]}
{"op":"mcm","clk":"4216870282","pt":1631556148526,"mc":[{"id":"1.187566733","rc":[{"batb":[[0,1.17,38.24]],"ltp":1.2,"tv":50780.59,"id":9323645}]}]}
{"op":"mcm","clk":"4216870417","pt":1631556149844,"mc":[{"id":"1.187566733","rc":[{"batb":[[0,1.19,1.39],[1,1.18,1.39],[2,1.17,36.86]],"ltp":1.2,"tv":50780.59,"id":9323645}]}]}
{"op":"mcm","clk":"4216870539","pt":1631556151056,"mc":[{"id":"1.187566733","rc":[{"batb":[[0,1.2,5],[1,1.17,36.86],[2,1.11,619.83]],"batl":[[1,1.3,110.6],[2,1.31,202.62]],"ltp":1.2,"tv":50780.59,"id":9323645}]}]}
{"op":"mcm","clk":"4216870963","pt":1631556154645,"mc":[{"id":"1.187566733","rc":[{"batb":[[2,1.12,22.63]],"ltp":1.2,"tv":50780.59,"id":9323645}]}]}
{"op":"mcm","clk":"4216871676","pt":1631556161043,"mc":[{"id":"1.187566733","rc":[{"batb":[[0,1.17,36.86],[1,1.12,22.63],[2,1.11,619.83]],"ltp":1.2,"tv":50780.59,"id":9323645}]}]}
{"op":"mcm","clk":"4216872051","pt":1631556164538,"mc":[{"id":"1.187566733","rc":[{"batb":[[1,1.13,5],[2,1.12,22.63]],"ltp":1.2,"tv":50780.59,"id":9323645}]}]}
{"op":"mcm","clk":"4216872510","pt":1631556168566,"mc":[{"id":"1.187566733","rc":[{"batb":[[1,1.13,10]],"ltp":1.2,"tv":50780.59,"id":9323645}]}]}
{"op":"mcm","clk":"4216875677","pt":1631556194091,"mc":[{"id":"1.187566733","rc":[{"batb":[[0,3.75,46.59],[1,1.01,98.87],[2,3.75,0]],"ltp":5.7,"tv":14287.65,"id":8734382},{"batl":[[1,1.3,2.13],[2,1.39,30]],"ltp":1.2,"tv":50780.59,"id":9323645}]}]}
{"op":"mcm","clk":"4216875811","pt":1631556195077,"mc":[{"id":"1.187566733","rc":[{"batb":[[1,1.12,22.63],[2,1.11,619.83]],"ltp":1.2,"tv":50780.59,"id":9323645}]}]}
{"op":"mcm","clk":"4216875936","pt":1631556196093,"mc":[{"id":"1.187566733","rc":[{"batb":[[1,1.11,619.83],[2,1.1,19.96]],"ltp":1.2,"tv":50780.59,"id":9323645}]}]}
{"op":"mcm","clk":"4216876091","pt":1631556197210,"mc":[{"id":"1.187566733","rc":[{"batb":[[0,8.4,23.8],[1,3.75,46.59],[2,1.01,98.87]],"batl":[[0,10,8.81],[1,11,145.35],[2,13.5,2]],"ltp":5.7,"tv":14287.65,"id":8734382},{"trd":[[1.17,73.73]],"batb":[[0,1.12,52.75],[2,1.1,1473.45]],"batl":[[0,1.13,559.08],[1,1.14,156.78],[2,1.15,1969.32]],"ltp":1.17,"tv":50854.32,"id":9323645}],"tv":65141.98}]}
{"op":"mcm","clk":"4216876172","pt":1631556197792,"mc":[{"id":"1.187566733","rc":[{"batb":[[1,7.4,16.03],[2,6.4,22.49]],"ltp":5.7,"tv":14287.65,"id":8734382},{"batb":[[0,1.12,61.68],[2,1.1,1501.19]],"ltp":1.17,"tv":50854.32,"id":9323645}]}]}
{"op":"mcm","clk":"4216876464","pt":1631556200083,"mc":[{"id":"1.187566733","rc":[{"trd":[[8.6,2]],"ltp":8.6,"tv":14289.65,"id":8734382},{"trd":[[1.13,15.22]],"batl":[[0,1.13,543.86]],"ltp":1.13,"tv":50869.54,"id":9323645}],"tv":65159.2}]}
{"op":"mcm","clk":"4216876611","pt":1631556201204,"mc":[{"id":"1.187566733","rc":[{"trd":[[1.13,55.22]],"batb":[[0,1.12,84.31],[1,1.11,757.15]],"batl":[[0,1.13,698.52]],"ltp":1.13,"tv":50909.54,"id":9323645}],"tv":65199.2}]}
{"op":"mcm","clk":"4216876675","pt":1631556201594,"mc":[{"id":"1.187566733","rc":[{"trd":[[8.6,4.77]],"ltp":8.6,"tv":14292.42,"id":8734382},{"trd":[[1.13,76.3]],"batl":[[0,1.13,677.44]],"ltp":1.13,"tv":50930.62,"id":9323645}],"tv":65223.05}]}
{"op":"mcm","clk":"4216876894","pt":1631556203193,"mc":[{"id":"1.187566733","rc":[{"batl":[[0,1.13,869.44]],"ltp":1.13,"tv":50930.62,"id":9323645}]}]}
{"op":"mcm","clk":"4216877261","pt":1631556206110,"mc":[{"id":"1.187566733","rc":[{"trd":[[8.6,6.77]],"ltp":8.6,"tv":14294.42,"id":8734382},{"trd":[[1.12,4],[1.13,91.52]],"batb":[[0,1.12,182.31]],"batl":[[0,1.13,854.22]],"ltp":1.12,"tv":50949.84,"id":9323645}],"tv":65244.27}]}
{"op":"mcm","clk":"4216877362","pt":1631556206904,"mc":[{"id":"1.187566733","rc":[{"batb":[[0,1.12,1604.62],[1,1.11,857.15]],"ltp":1.12,"tv":50949.84,"id":9323645}]}]}
{"op":"mcm","clk":"4216877534","pt":1631556208085,"mc":[{"id":"1.187566733","rc":[{"trd":[[8.6,55.58]],"ltp":8.6,"tv":14343.23,"id":8734382},{"trd":[[1.13,462.89]],"batb":[[1,1.11,737.2],[2,1.1,1481.23]],"batl":[[0,1.13,482.85]],"ltp":1.13,"tv":51321.21,"id":9323645}],"tv":65664.44}]}
{"op":"mcm","clk":"4216877562","pt":1631556208341,"mc":[{"id":"1.187566733","rc":[{"batb":[[1,1.11,699.06]],"ltp":1.13,"tv":51321.21,"id":9323645}]}]}
{"op":"mcm","clk":"4216877698","pt":1631556209405,"mc":[{"id":"1.187566733","rc":[{"batb":[[0,1.12,1736.68]],"ltp":1.13,"tv":51321.21,"id":9323645}]}]}
{"op":"mcm","clk":"4216877946","pt":1631556211203,"mc":[{"id":"1.187566733","rc":[{"trd":[[1.12,1037.89]],"batb":[[0,1.12,2086.34]],"batl":[[0,1.13,600.62],[1,1.14,567.63]],"ltp":1.12,"tv":52355.1,"id":9323645}],"tv":66698.33}]}
{"op":"mcm","clk":"4216878068","pt":1631556212105,"mc":[{"id":"1.187566733","rc":[{"batl":[[0,11,145.35],[1,13.5,2],[2,21,2]],"ltp":8.6,"tv":14343.23,"id":8734382},{"trd":[[1.13,501.75]],"batl":[[0,1.13,581.19]],"ltp":1.13,"tv":52393.96,"id":9323645}],"tv":66737.19}]}
{"op":"mcm","clk":"4216878226","pt":1631556213426,"mc":[{"id":"1.187566733","rc":[{"batb":[[0,1.12,2144.05]],"ltp":1.13,"tv":52393.96,"id":9323645}]}]}
{"op":"mcm","clk":"4216878396","pt":1631556214731,"mc":[{"id":"1.187566733","rc":[{"batb":[[1,1.11,599.06]],"ltp":1.13,"tv":52393.96,"id":9323645}]}]}
{"op":"mcm","clk":"4216878565","pt":1631556215812,"mc":[{"id":"1.187566733","rc":[{"trd":[[9.4,2.41]],"ltp":9.4,"tv":14345.64,"id":8734382},{"trd":[[1.12,1058.12]],"batb":[[0,1.12,2181.52]],"ltp":1.12,"tv":52414.19,"id":9323645}],"tv":66759.83}]}
{"op":"mcm","clk":"4216878728","pt":1631556217203,"mc":[{"id":"1.187566733","rc":[{"batl":[[0,1.13,1336.76]],"ltp":1.12,"tv":52414.19,"id":9323645}]}]}
{"op":"mcm","clk":"4216878798","pt":1631556217794,"mc":[{"id":"1.187566733","rc":[{"trd":[[8.6,69.64]],"ltp":8.6,"tv":14359.7,"id":8734382},{"trd":[[1.12,1458.15],[1.13,608.76]],"batb":[[0,1.12,1981.49],[1,1.11,514.99]],"batl":[[0,1.13,1229.75]],"ltp":1.12,"tv":52921.24,"id":9323645}],"tv":67280.94}]}
{"op":"mcm","clk":"4216878904","pt":1631556218696,"mc":[{"id":"1.187566733","rc":[{"trd":[[8.6,70.09]],"ltp":8.6,"tv":14360.15,"id":8734382},{"trd":[[1.13,612.18]],"batl":[[0,1.13,1226.33]],"ltp":1.13,"tv":52924.66,"id":9323645}],"tv":67284.81}]}
{"op":"mcm","clk":"4216879168","pt":1631556220926,"mc":[{"id":"1.187566733","rc":[{"batb":[[0,1.12,2064.81]],"batl":[[0,1.13,1260.18],[1,1.14,649.25]],"ltp":1.13,"tv":52924.66,"id":9323645}]}]}
{"op":"mcm","clk":"4216879430","pt":1631556223005,"mc":[{"id":"1.187566733","rc":[{"trd":[[1.13,740.18]],"batl":[[0,1.13,1196.18]],"ltp":1.13,"tv":53052.66,"id":9323645}],"tv":67412.81}]}
{"op":"mcm","clk":"4216879557","pt":1631556223901,"mc":[{"id":"1.187566733","rc":[{"trd":[[8.6,83.9]],"batl":[[0,9.2,7.11],[1,11,145.35],[2,13.5,2]],"ltp":8.6,"tv":14373.96,"id":8734382},{"trd":[[1.13,845.38]],"batl":[[0,1.13,1090.98],[1,1.14,712.34]],"ltp":1.13,"tv":53157.86,"id":9323645}],"tv":67531.82}]}
{"op":"mcm","clk":"4216879600","pt":1631556224219,"mc":[{"id":"1.187566733","rc":[{"trd":[[8.6,86.25]],"ltp":8.6,"tv":14376.31,"id":8734382},{"trd":[[1.13,863.26]],"batl":[[0,1.13,1073.1]],"ltp":1.13,"tv":53175.74,"id":9323645}],"tv":67552.05}]}
{"op":"mcm","clk":"4216879800","pt":1631556225713,"mc":[{"id":"1.187566733","rc":[{"trd":[[1.13,864.38]],"batl":[[0,1.13,1072.54]],"ltp":1.13,"tv":53176.85,"id":9323645}],"tv":67553.17}]}
{"op":"mcm","clk":"4216879975","pt":1631556227042,"mc":[{"id":"1.187566733","rc":[{"batb":[[0,1.12,1949.39]],"batl":[[0,1.13,1418.35]],"ltp":1.13,"tv":53176.85,"id":9323645}]}]}
{"op":"mcm","clk":"4216880110","pt":1631556227960,"mc":[{"id":"1.187566733","rc":[{"trd":[[1.12,2710.61]],"batb":[[0,1.12,1323.11]],"ltp":1.12,"tv":54429.31,"id":9323645}],"tv":68805.63}]}
{"op":"mcm","clk":"4216880478","pt":1631556230757,"mc":[{"id":"1.187566733","rc":[{"trd":[[8.6,92.27]],"ltp":8.6,"tv":14382.33,"id":8734382},{"trd":[[1.13,910.2]],"batl":[[0,1.13,1372.53]],"ltp":1.13,"tv":54475.13,"id":9323645}],"tv":68857.47}]}
{"op":"mcm","clk":"4216880706","pt":1631556232140,"mc":[{"id":"1.187566733","rc":[{"trd":[[1.12,2870.62]],"batb":[[0,1.12,1243.09]],"batl":[[0,1.13,2028.98]],"ltp":1.12,"tv":54635.14,"id":9323645}],"tv":69017.48}]}
{"op":"mcm","clk":"4216880773","pt":1631556232634,"mc":[{"id":"1.187566733","rc":[{"trd":[[1.13,918.94]],"batl":[[0,1.13,2024.61]],"ltp":1.13,"tv":54643.88,"id":9323645}],"tv":69026.22}]}
{"op":"mcm","clk":"4216881181","pt":1631556235738,"mc":[{"id":"1.187566733","rc":[{"trd":[[1.12,2887.69],[1.13,919.31]],"batb":[[0,1.12,1234.56]],"batl":[[0,1.13,2024.42]],"ltp":1.13,"tv":54661.32,"id":9323645}],"tv":69043.66}]}
{"op":"mcm","clk":"4216881635","pt":1631556239044,"mc":[{"id":"1.187566733","rc":[{"batb":[[1,1.11,489.82]],"batl":[[0,1.13,1999.78]],"ltp":1.13,"tv":54661.32,"id":9323645}]}]}
{"op":"mcm","clk":"4216882034","pt":1631556241956,"mc":[{"id":"1.187566733","rc":[{"batb":[[0,1.12,1259.51]],"batl":[[1,1.14,736.76]],"ltp":1.13,"tv":54661.32,"id":9323645}]}]}
{"op":"mcm","clk":"4216882353","pt":1631556244054,"mc":[{"id":"1.187566733","rc":[{"trd":[[1.13,1019.31]],"batl":[[0,1.13,1949.78]],"ltp":1.13,"tv":54761.32,"id":9323645}],"tv":69143.66}]}
{"op":"mcm","clk":"4216882465","pt":1631556244747,"mc":[{"id":"1.187566733","rc":[{"trd":[[1.13,1032.03]],"batl":[[0,1.13,1943.42]],"ltp":1.13,"tv":54774.04,"id":9323645}],"tv":69156.38}]}
{"op":"mcm","clk":"4216882906","pt":1631556248054,"mc":[{"id":"1.187566733","rc":[{"trd":[[1.12,3574.74]],"batb":[[0,1.12,915.97],[1,1.11,1265.63]],"batl":[[1,1.14,712.34]],"ltp":1.12,"tv":55461.08,"id":9323645}],"tv":69843.42}]}
{"op":"mcm","clk":"4216883231","pt":1631556249742,"mc":[{"id":"1.187566733","rc":[{"trd":[[1.12,4833.59]],"batb":[[0,1.12,286.38]],"batl":[[1,1.14,673]],"ltp":1.12,"tv":56719.94,"id":9323645}],"tv":71102.28}]}
{"op":"mcm","clk":"4216883399","pt":1631556251071,"mc":[{"id":"1.187566733","rc":[{"batb":[[0,1.12,312.75],[1,1.11,1298.5]],"batl":[[0,1.13,1975.64]],"ltp":1.12,"tv":56719.94,"id":9323645}]}]}
{"op":"mcm","clk":"4216883425","pt":1631556251284,"mc":[{"id":"1.187566733","rc":[{"batb":[[0,1.12,773.15]],"ltp":1.12,"tv":56719.94,"id":9323645}]}]}
{"op":"mcm","clk":"4216883621","pt":1631556252669,"mc":[{"id":"1.187566733","rc":[{"batb":[[0,1.12,799.44],[1,1.11,1331.25]],"batl":[[0,1.13,2141.14]],"ltp":1.12,"tv":56719.94,"id":9323645}]}]}
{"op":"mcm","clk":"4216884203","pt":1631556256870,"mc":[{"id":"1.187566733","rc":[{"trd":[[8.6,93.17]],"ltp":8.6,"tv":14383.23,"id":8734382},{"trd":[[1.13,1038.88]],"batl":[[0,1.13,2134.29]],"ltp":1.13,"tv":56726.79,"id":9323645}],"tv":71110.03}]}
{"op":"mcm","clk":"4216884415","pt":1631556258158,"mc":[{"id":"1.187566733","rc":[{"batb":[[0,1.12,659.13],[1,1.11,1826.21]],"ltp":1.13,"tv":56726.79,"id":9323645}]}]}
{"op":"mcm","clk":"4216884765","pt":1631556260294,"mc":[{"id":"1.187566733","rc":[{"batl":[[0,1.13,2790.74]],"ltp":1.13,"tv":56726.79,"id":9323645}]}]}
{"op":"mcm","clk":"4216885038","pt":1631556261989,"mc":[{"id":"1.187566733","rc":[{"batl":[[1,13.5,2],[2,21,2]],"ltp":8.6,"tv":14383.23,"id":8734382},{"trd":[[1.13,1041.77]],"batb":[[2,1.1,27.74]],"batl":[[0,1.13,2789.29],[2,1.15,13.28]],"ltp":1.13,"tv":56729.68,"id":9323645}],"tv":71112.92}]}
{"op":"mcm","clk":"4216885268","pt":1631556263595,"mc":[{"id":"1.187566733","rc":[{"batl":[[0,1.13,2605.59]],"ltp":1.13,"tv":56729.68,"id":9323645}]}]}
{"op":"mcm","clk":"4216885476","pt":1631556265095,"mc":[{"id":"1.187566733","rc":[{"batl":[[0,1.13,1949.14]],"ltp":1.13,"tv":56729.68,"id":9323645}]}]}
{"op":"mcm","clk":"4216887629","pt":1631556280000,"mc":[{"id":"1.187566733","rc":[{"batb":[[0,8.6,85.34],[1,8.4,23.8],[2,7.4,16.03]],"ltp":8.6,"tv":14383.23,"id":8734382}]}]}
{"op":"mcm","clk":"4216887751","pt":1631556280910,"mc":[{"id":"1.187566733","rc":[{"trd":[[1.13,1048.83]],"batl":[[0,1.13,1945.61]],"ltp":1.13,"tv":56736.74,"id":9323645}],"tv":71119.98}]}
{"op":"mcm","clk":"4216888529","pt":1631556285917,"mc":[{"id":"1.187566733","rc":[{"batb":[[1,1.11,1050.41]],"ltp":1.13,"tv":56736.74,"id":9323645}]}]}
{"op":"mcm","clk":"4216888832","pt":1631556288110,"mc":[{"id":"1.187566733","rc":[{"trd":[[1.13,1049.29]],"batl":[[0,1.13,1896.26]],"ltp":1.13,"tv":56737.2,"id":9323645}],"tv":71120.44}]}
{"op":"mcm","clk":"4216889106","pt":1631556289926,"mc":[{"id":"1.187566733","rc":[{"batl":[[0,9,1.01],[1,9.2,7.11],[2,13.5,2]],"ltp":8.6,"tv":14383.23,"id":8734382},{"batb":[[2,1.1,27.99]],"ltp":1.13,"tv":56737.2,"id":9323645}]}]}
{"op":"mcm","clk":"4216889278","pt":1631556291023,"mc":[{"id":"1.187566733","rc":[{"batb":[[1,1.11,1050.63]],"ltp":1.13,"tv":56737.2,"id":9323645}]}]}
{"op":"mcm","clk":"4216889435","pt":1631556292139,"mc":[{"id":"1.187566733","rc":[{"trd":[[1.13,1049.79]],"batb":[[0,1.12,659.34]],"batl":[[0,1.13,1896.01]],"ltp":1.13,"tv":56737.7,"id":9323645}],"tv":71120.94}]}
{"op":"mcm","clk":"4216889690","pt":1631556293947,"mc":[{"id":"1.187566733","rc":[{"trd":[[1.12,4913.59]],"batb":[[0,1.12,619.34]],"ltp":1.12,"tv":56817.7,"id":9323645}],"tv":71200.94}]}
{"op":"mcm","clk":"4216889740","pt":1631556294222,"mc":[{"id":"1.187566733","rc":[{"batl":[[1,1.14,659.34]],"ltp":1.12,"tv":56817.7,"id":9323645}]}]}
{"op":"mcm","clk":"4216890137","pt":1631556296829,"mc":[{"id":"1.187566733","rc":[{"batb":[[0,1.12,630.52]],"batl":[[0,1.13,1908.74]],"ltp":1.12,"tv":56817.7,"id":9323645}]}]}
{"op":"mcm","clk":"4216890198","pt":1631556297249,"mc":[{"id":"1.187566733","rc":[{"batb":[[1,1.11,1070.68]],"ltp":1.12,"tv":56817.7,"id":9323645}]}]}
{"op":"mcm","clk":"4216890606","pt":1631556300041,"mc":[{"id":"1.187566733","rc":[{"trd":[[1.12,4940.94]],"batb":[[0,1.12,616.84]],"ltp":1.12,"tv":56845.05,"id":9323645}],"tv":71228.29}]}
{"op":"mcm","clk":"4216890676","pt":1631556300429,"mc":[{"id":"1.187566733","rc":[{"batl":[[1,1.14,646.12]],"ltp":1.12,"tv":56845.05,"id":9323645}]}]}
{"op":"mcm","clk":"4216891204","pt":1631556303836,"mc":[{"id":"1.187566733","rc":[{"batb":[[0,1.12,631.91]],"batl":[[0,1.13,1927.14],[2,1.15,13.5]],"ltp":1.12,"tv":56845.05,"id":9323645}]}]}
{"op":"mcm","clk":"4216891938","pt":1631556308564,"mc":[{"id":"1.187566733","rc":[{"batl":[[0,1.13,1877.14]],"ltp":1.12,"tv":56845.05,"id":9323645}]}]}
{"op":"mcm","clk":"4216892141","pt":1631556309932,"mc":[{"id":"1.187566733","rc":[{"trd":[[1.13,1135.99]],"batl":[[0,1.13,1834.04]],"ltp":1.13,"tv":56931.25,"id":9323645}],"tv":71314.49}]}
{"op":"mcm","clk":"4216892303","pt":1631556310939,"mc":[{"id":"1.187566733","rc":[{"trd":[[1.13,1175.99]],"batb":[[1,1.11,1050.63]],"batl":[[0,1.13,1814.04],[1,1.14,646.36]],"ltp":1.13,"tv":56971.25,"id":9323645}],"tv":71354.49}]}
{"op":"mcm","clk":"4216892660","pt":1631556313168,"mc":[{"id":"1.187566733","rc":[{"trd":[[1.12,4980.94]],"batb":[[0,1.12,611.91]],"ltp":1.12,"tv":57011.25,"id":9323645}],"tv":71394.49}]}
{"op":"mcm","clk":"4216892778","pt":1631556313964,"mc":[{"id":"1.187566733","rc":[{"trd":[[1.12,5020.94]],"batb":[[0,1.12,627.2]],"batl":[[0,1.13,1833.33],[1,1.14,669.96]],"ltp":1.12,"tv":57051.25,"id":9323645}],"tv":71434.49}]}
{"op":"mcm","clk":"4216892920","pt":1631556314867,"mc":[{"id":"1.187566733","rc":[{"trd":[[1.12,5155.89]],"batb":[[0,1.12,559.73]],"batl":[[1,1.14,630.96]],"ltp":1.12,"tv":57186.2,"id":9323645}],"tv":71569.44}]}
{"op":"mcm","clk":"4216893153","pt":1631556316730,"mc":[{"id":"1.187566733","rc":[{"batb":[[0,1.12,577.62],[1,1.11,1065.01]],"batl":[[0,1.13,1864.14]],"ltp":1.12,"tv":57186.2,"id":9323645}]}]}
{"op":"mcm","clk":"4216893284","pt":1631556317753,"mc":[{"id":"1.187566733","rc":[{"batb":[[0,1.12,607.81],[1,1.11,1102.62]],"batl":[[0,1.13,1901.01]],"ltp":1.12,"tv":57186.2,"id":9323645}]}]}
{"op":"mcm","clk":"4216895370","pt":1631556333166,"mc":[{"id":"1.187566733","rc":[{"batb":[[0,1.12,1034.5]],"ltp":1.12,"tv":57186.2,"id":9323645}]}]}
{"op":"mcm","clk":"4216896522","pt":1631556341087,"mc":[{"id":"1.187566733","rc":[{"trd":[[1.12,7155.96]],"batb":[[0,1.12,461.13]],"batl":[[1,1.14,542.95]],"ltp":1.12,"tv":59186.27,"id":9323645}],"tv":73569.51}]}
{"op":"mcm","clk":"4216896944","pt":1631556343991,"mc":[{"id":"1.187566733","rc":[{"batb":[[1,1.11,1251.16]],"batl":[[0,1.13,1981.47]],"ltp":1.12,"tv":59186.27,"id":9323645}]}]}
{"op":"mcm","clk":"4216897512","pt":1631556348010,"mc":[{"id":"1.187566733","rc":[{"trd":[[1.13,1186.23]],"batl":[[0,1.13,1976.35]],"ltp":1.13,"tv":59196.51,"id":9323645}],"tv":73579.75}]}
{"op":"mcm","clk":"4216897952","pt":1631556351085,"mc":[{"id":"1.187566733","rc":[{"trd":[[9,1.01],[9.2,7.11]],"batl":[[0,13.5,2],[1,21,2],[2,26,2]],"ltp":9.2,"tv":14391.35,"id":8734382},{"trd":[[1.11,944.92],[1.12,8144.63]],"batb":[[0,1.11,761.34],[1,1.1,27.99],[2,1.09,388.7]],"batl":[[1,1.14,356.91]],"ltp":1.11,"tv":61130.1,"id":9323645}],"tv":75521.45}]}
{"op":"mcm","clk":"4216898365","pt":1631556353906,"mc":[{"id":"1.187566733","rc":[{"batb":[[0,1.11,1072.79]],"batl":[[0,1.13,2169.15]],"ltp":1.11,"tv":61130.1,"id":9323645}]}]}
{"op":"mcm","clk":"4216898870","pt":1631556357183,"mc":[{"id":"1.187566733","rc":[{"batb":[[0,8.8,108.61],[1,8.6,85.34],[2,8.4,23.8]],"ltp":9.2,"tv":14391.35,"id":8734382}]}]}
{"op":"mcm","clk":"4216898951","pt":1631556357817,"mc":[{"id":"1.187566733","rc":[{"batl":[[0,1.13,2169.35]],"ltp":1.11,"tv":61130.1,"id":9323645}]}]}
{"op":"mcm","clk":"4216899375","pt":1631556360705,"mc":[{"id":"1.187566733","rc":[{"batl":[[1,1.14,293.82]],"ltp":1.11,"tv":61130.1,"id":9323645}]}]}
{"op":"mcm","clk":"4216899690","pt":1631556362950,"mc":[{"id":"1.187566733","rc":[{"trd":[[1.13,1586.26]],"batl":[[0,1.13,1969.32]],"ltp":1.13,"tv":61530.13,"id":9323645}],"tv":75921.48}]}
{"op":"mcm","clk":"4216899825","pt":1631556363700,"mc":[{"id":"1.187566733","rc":[{"batl":[[0,10,10.11],[1,13.5,2],[2,21,2]],"ltp":9.2,"tv":14391.35,"id":8734382},{"batl":[[0,1.13,2027.08]],"ltp":1.13,"tv":61530.13,"id":9323645}]}]}
{"op":"mcm","clk":"4216900182","pt":1631556365902,"mc":[{"id":"1.187566733","rc":[{"batb":[[0,8.6,85.34],[1,8.4,23.8],[2,7.4,16.03]],"ltp":9.2,"tv":14391.35,"id":8734382},{"batb":[[0,1.11,1098.6]],"batl":[[0,1.13,2047.45],[1,1.14,318.77]],"ltp":1.13,"tv":61530.13,"id":9323645}]}]}
{"op":"mcm","clk":"4216900943","pt":1631556370842,"mc":[{"id":"1.187566733","rc":[{"batl":[[0,1.12,853.39],[1,1.13,2047.45],[2,1.14,318.77]],"ltp":1.13,"tv":61530.13,"id":9323645}]}]}
{"op":"mcm","clk":"4216901415","pt":1631556374037,"mc":[{"id":"1.187566733","rc":[{"batl":[[0,1.12,1303.79]],"ltp":1.13,"tv":61530.13,"id":9323645}]}]}
{"op":"mcm","clk":"4216901865","pt":1631556377124,"mc":[{"id":"1.187566733","rc":[{"batb":[[0,1.11,1525.29]],"ltp":1.13,"tv":61530.13,"id":9323645}]}]}
{"op":"mcm","clk":"4216902366","pt":1631556380165,"mc":[{"id":"1.187566733","rc":[{"trd":[[9.2,9.81]],"ltp":9.2,"tv":14394.05,"id":8734382},{"trd":[[1.12,8169.65]],"batl":[[0,1.12,1280.18]],"ltp":1.12,"tv":61555.15,"id":9323645}],"tv":75949.21}]}
{"op":"mcm","clk":"4216904346","pt":1631556392460,"mc":[{"id":"1.187566733","rc":[{"trd":[[1.12,8169.87]],"batl":[[0,1.12,1280.07]],"ltp":1.12,"tv":61555.38,"id":9323645}],"tv":75949.43}]}
{"op":"mcm","clk":"4216906469","pt":1631556405986,"mc":[{"id":"1.187566733","rc":[{"trd":[[1.11,951.56]],"batb":[[0,1.11,1521.97]],"ltp":1.11,"tv":61562.02,"id":9323645}],"tv":75956.07}]}
{"op":"mcm","clk":"4216907344","pt":1631556411982,"mc":[{"id":"1.187566733","rc":[{"trd":[[1.12,8530]],"batl":[[0,1.12,1100.01]],"ltp":1.12,"tv":61922.15,"id":9323645}],"tv":76316.2}]}
{"op":"mcm","clk":"4216908478","pt":1631556419346,"mc":[{"id":"1.187566733","rc":[{"trd":[[1.12,8743.36]],"batl":[[0,1.12,993.32]],"ltp":1.12,"tv":62135.51,"id":9323645}],"tv":76529.56}]}
{"op":"mcm","clk":"4216908665","pt":1631556420627,"mc":[{"id":"1.187566733","rc":[{"batb":[[1,1.1,881.37]],"ltp":1.12,"tv":62135.51,"id":9323645}]}]}
{"op":"mcm","clk":"4216910844","pt":1631556434657,"mc":[{"id":"1.187566733","rc":[{"trd":[[1.12,8909.49]],"batl":[[0,1.12,910.29]],"ltp":1.12,"tv":62301.64,"id":9323645}],"tv":76695.69}]}
{"op":"mcm","clk":"4216910985","pt":1631556435555,"mc":[{"id":"1.187566733","rc":[{"batl":[[1,1.13,1998.17]],"ltp":1.12,"tv":62301.64,"id":9323645}]}]}
{"op":"mcm","clk":"4216911469","pt":1631556438440,"mc":[{"id":"1.187566733","rc":[{"batb":[[0,1.11,1540.53]],"batl":[[2,1.14,367.62]],"ltp":1.12,"tv":62301.64,"id":9323645}]}]}
{"op":"mcm","clk":"4216914560","pt":1631556459369,"mc":[{"id":"1.187566733","rc":[{"batl":[[0,1.12,930.29]],"ltp":1.12,"tv":62301.64,"id":9323645}]}]}
{"op":"mcm","clk":"4216920204","pt":1631556498207,"mc":[{"id":"1.187566733","rc":[{"trd":[[1.12,9129.91]],"batl":[[0,1.12,820.08]],"ltp":1.12,"tv":62522.05,"id":9323645}],"tv":76916.11}]}
{"op":"mcm","clk":"4216920237","pt":1631556498416,"mc":[{"id":"1.187566733","rc":[{"batl":[[0,9.8,5.35],[1,10,10.11],[2,13.5,2]],"ltp":9.2,"tv":14394.05,"id":8734382}]}]}
{"op":"mcm","clk":"4216920781","pt":1631556501720,"mc":[{"id":"1.187566733","rc":[{"batb":[[0,1.11,1045.57]],"ltp":1.12,"tv":62522.05,"id":9323645}]}]}
{"op":"mcm","clk":"4216921328","pt":1631556504815,"mc":[{"id":"1.187566733","rc":[{"trd":[[1.12,9135.33]],"batb":[[2,1.09,883.67]],"batl":[[0,1.12,817.36]],"ltp":1.12,"tv":62527.47,"id":9323645}],"tv":76921.53}]}
{"op":"mcm","clk":"4216924388","pt":1631556524753,"mc":[{"id":"1.187566733","rc":[{"trd":[[1.11,968.63]],"batb":[[0,1.11,1037.04]],"ltp":1.11,"tv":62544.54,"id":9323645}],"tv":76938.59}]}
{"op":"mcm","clk":"4216925142","pt":1631556529884,"mc":[{"id":"1.187566733","rc":[{"batb":[[1,1.1,983.77]],"ltp":1.11,"tv":62544.54,"id":9323645}]}]}
{"op":"mcm","clk":"4216925633","pt":1631556533176,"mc":[{"id":"1.187566733","rc":[{"trd":[[1.11,1624.09]],"batb":[[0,1.11,709.3]],"ltp":1.11,"tv":63200.0,"id":9323645}],"tv":77594.06}]}
{"op":"mcm","clk":"4216925711","pt":1631556533660,"mc":[{"id":"1.187566733","rc":[{"batl":[[2,1.14,197.42]],"ltp":1.11,"tv":63200.0,"id":9323645}]}]}
{"op":"mcm","clk":"4216926178","pt":1631556536696,"mc":[{"id":"1.187566733","rc":[{"trd":[[9.2,17.85]],"ltp":9.2,"tv":14402.09,"id":8734382},{"trd":[[1.12,9201.38]],"batb":[[0,1.11,894.95],[1,1.1,1135.52]],"batl":[[0,1.12,751.31],[1,1.13,2169.88]],"ltp":1.12,"tv":63266.05,"id":9323645}],"tv":77668.15}]}
{"op":"mcm","clk":"4216926703","pt":1631556539988,"mc":[{"id":"1.187566733","rc":[{"batl":[[0,1.12,984.31]],"ltp":1.12,"tv":63266.05,"id":9323645}]}]}
{"op":"mcm","clk":"4216926783","pt":1631556540480,"mc":[{"id":"1.187566733","rc":[{"batb":[[1,1.1,282.14]],"ltp":1.12,"tv":63266.05,"id":9323645}]}]}
{"op":"mcm","clk":"4216927334","pt":1631556543895,"mc":[{"id":"1.187566733","rc":[{"batb":[[0,1.11,1670.76]],"ltp":1.12,"tv":63266.05,"id":9323645}]}]}
{"op":"mcm","clk":"4216927826","pt":1631556546789,"mc":[{"id":"1.187566733","rc":[{"batb":[[0,1.11,2097.45]],"ltp":1.12,"tv":63266.05,"id":9323645}]}]}
{"op":"mcm","clk":"4216927978","pt":1631556547795,"mc":[{"id":"1.187566733","rc":[{"batb":[[0,1.11,2485.35]],"ltp":1.12,"tv":63266.05,"id":9323645}]}]}
{"op":"mcm","clk":"4216928151","pt":1631556548993,"mc":[{"id":"1.187566733","rc":[{"batl":[[0,1.12,984.53]],"ltp":1.12,"tv":63266.05,"id":9323645}]}]}
{"op":"mcm","clk":"4216929404","pt":1631556557194,"mc":[{"id":"1.187566733","rc":[{"trd":[[1.11,3023.28]],"batb":[[0,1.11,932.34]],"ltp":1.11,"tv":64665.25,"id":9323645}],"tv":79067.34}]}
{"op":"mcm","clk":"4216929474","pt":1631556557715,"mc":[{"id":"1.187566733","rc":[{"trd":[[1.12,9205.8]],"batl":[[0,1.12,982.32],[1,1.13,1895.83]],"ltp":1.12,"tv":64669.67,"id":9323645}],"tv":79071.76}]}
{"op":"mcm","clk":"4216929600","pt":1631556558520,"mc":[{"id":"1.187566733","rc":[{"trd":[[1.12,9369.09]],"batl":[[0,1.12,900.66]],"ltp":1.12,"tv":64832.96,"id":9323645}],"tv":79235.05}]}
{"op":"mcm","clk":"4216929916","pt":1631556560519,"mc":[{"id":"1.187566733","rc":[{"batb":[[0,1.11,1144.51],[1,1.1,540.56]],"batl":[[0,1.12,1406.45]],"ltp":1.12,"tv":64832.96,"id":9323645}]}]}
{"op":"mcm","clk":"4216930958","pt":1631556567122,"mc":[{"id":"1.187566733","rc":[{"trd":[[1.11,5023.45]],"batb":[[0,1.11,144.35]],"ltp":1.11,"tv":66833.12,"id":9323645}],"tv":81235.22}]}
{"op":"mcm","clk":"4216931035","pt":1631556567706,"mc":[{"id":"1.187566733","rc":[{"batl":[[1,1.13,1859.13]],"ltp":1.11,"tv":66833.12,"id":9323645}]}]}
{"op":"mcm","clk":"4216931313","pt":1631556569703,"mc":[{"id":"1.187566733","rc":[{"batb":[[0,1.11,571.04]],"ltp":1.11,"tv":66833.12,"id":9323645}]}]}
{"op":"mcm","clk":"4216931458","pt":1631556570619,"mc":[{"id":"1.187566733","rc":[{"batb":[[0,1.11,601.38],[1,1.1,578.38]],"batl":[[0,1.12,2367.5]],"ltp":1.11,"tv":66833.12,"id":9323645}]}]}
{"op":"mcm","clk":"4216943155","pt":1631556646134,"mc":[{"id":"1.187566733","rc":[{"batb":[[1,1.1,563.45]],"batl":[[0,1.12,2352.89]],"ltp":1.11,"tv":66833.12,"id":9323645}]}]}
{"op":"mcm","clk":"4216943317","pt":1631556647244,"mc":[{"id":"1.187566733","rc":[{"trd":[[1.12,9373.36]],"batl":[[0,1.12,2350.75]],"ltp":1.12,"tv":66837.39,"id":9323645}],"tv":81239.48}]}
{"op":"mcm","clk":"4216943597","pt":1631556649153,"mc":[{"id":"1.187566733","rc":[{"batb":[[0,1.11,616.17]],"batl":[[1,1.13,1873.61]],"ltp":1.12,"tv":66837.39,"id":9323645}]}]}
{"op":"mcm","clk":"4216943785","pt":1631556650339,"mc":[{"id":"1.187566733","rc":[{"trd":[[9.8,1.23]],"batl":[[0,9.8,4.73]],"ltp":9.8,"tv":14403.32,"id":8734382}],"tv":81240.71}]}
{"op":"mcm","clk":"4216944486","pt":1631556655361,"mc":[{"id":"1.187566733","rc":[{"trd":[[1.11,5023.69]],"batb":[[0,1.11,616.05]],"ltp":1.11,"tv":66837.63,"id":9323645}],"tv":81240.95}]}
{"op":"mcm","clk":"4216945470","pt":1631556662042,"mc":[{"id":"1.187566733","rc":[{"batb":[[1,7.4,16.03],[2,6.4,22.49]],"batl":[[1,990,0.01],[2,13.5,0]],"ltp":9.8,"tv":14403.32,"id":8734382},{"batb":[[0,1.11,426.69],[1,1.1,102.65],[2,1.09,870.03]],"batl":[[0,1.12,1601.44],[1,1.13,1158.61],[2,1.23,1.9]],"ltp":1.11,"tv":66837.63,"id":9323645}]}]}
{"op":"mcm","clk":"4216945509","pt":1631556662364,"mc":[{"id":"1.187566733","rc":[{"batb":[[1,6.4,22.49],[2,2.5,1.82]],"ltp":9.8,"tv":14403.32,"id":8734382},{"batb":[[2,1.09,495.16]],"ltp":1.11,"tv":66837.63,"id":9323645}]}]}
{"op":"mcm","clk":"4216945687","pt":1631556663541,"mc":[{"id":"1.187566733","rc":[{"trd":[[1.11,5463.73]],"batb":[[0,1.11,206.66]],"batl":[[0,1.12,1368.44]],"ltp":1.11,"tv":67277.67,"id":9323645}],"tv":81680.99}]}
{"op":"mcm","clk":"4216945876","pt":1631556664765,"mc":[{"id":"1.187566733","rc":[{"batb":[[2,1.09,1125.16]],"batl":[[2,1.15,511.22]],"ltp":1.11,"tv":67277.67,"id":9323645}]}]}
{"op":"mcm","clk":"4216946239","pt":1631556667050,"mc":[{"id":"1.187566733","rc":[{"batl":[[0,1.12,1173.53]],"ltp":1.11,"tv":67277.67,"id":9323645}]}]}
{"op":"mcm","clk":"4216946362","pt":1631556667959,"mc":[{"id":"1.187566733","rc":[{"batl":[[0,1.12,1711.78]],"ltp":1.11,"tv":67277.67,"id":9323645}]}]}
{"op":"mcm","clk":"4216946740","pt":1631556670180,"mc":[{"id":"1.187566733","rc":[{"trd":[[9.2,26.47]],"ltp":9.2,"tv":14411.94,"id":8734382},{"trd":[[1.12,9444.19]],"batl":[[0,1.12,1640.95]],"ltp":1.12,"tv":67348.5,"id":9323645}],"tv":81760.44}]}
{"op":"mcm","clk":"4216946770","pt":1631556670352,"mc":[{"id":"1.187566733","rc":[{"batl":[[0,1.12,1835.95]],"ltp":1.12,"tv":67348.5,"id":9323645}]}]}
{"op":"mcm","clk":"4216947218","pt":1631556673081,"mc":[{"id":"1.187566733","rc":[{"trd":[[1.12,9450.19]],"batl":[[0,1.12,1832.94]],"ltp":1.12,"tv":67354.5,"id":9323645}],"tv":81766.45}]}
{"op":"mcm","clk":"4216947516","pt":1631556675058,"mc":[{"id":"1.187566733","rc":[{"batb":[[0,6.4,22.49],[1,2.5,1.82],[2,1.01,98.87]],"ltp":9.2,"tv":14411.94,"id":8734382},{"batl":[[0,1.12,1294.69]],"ltp":1.12,"tv":67354.5,"id":9323645}]}]}
{"op":"mcm","clk":"4216947655","pt":1631556675984,"mc":[{"id":"1.187566733","rc":[{"batl":[[0,1.12,1099.69],[1,1.15,511.41],[2,1.23,1.45]],"ltp":1.12,"tv":67354.5,"id":9323645}]}]}
{"op":"mcm","clk":"4216947939","pt":1631556677650,"mc":[{"id":"1.187566733","rc":[{"batb":[[2,1.09,495.16]],"batl":[[1,1.23,2.1],[2,1.3,2.13]],"ltp":1.12,"tv":67354.5,"id":9323645}]}]}
{"op":"mcm","clk":"4216948245","pt":1631556679754,"mc":[{"id":"1.187566733","rc":[{"batl":[[1,1.14,1219.55],[2,1.23,1.66]],"ltp":1.12,"tv":67354.5,"id":9323645}]}]}
{"op":"mcm","clk":"4216948432","pt":1631556680978,"mc":[{"id":"1.187566733","rc":[{"batb":[[0,1.11,740.43]],"batl":[[0,1.12,1259.69],[1,1.13,591.81],[2,1.14,1219.35]],"ltp":1.12,"tv":67354.5,"id":9323645}]}]}
{"op":"mcm","clk":"4216948524","pt":1631556681578,"mc":[{"id":"1.187566733","rc":[{"batb":[[0,1.11,206.66]],"batl":[[1,1.14,1219.55],[2,1.23,1.66]],"ltp":1.12,"tv":67354.5,"id":9323645}]}]}
{"op":"mcm","clk":"4216948685","pt":1631556682586,"mc":[{"id":"1.187566733","rc":[{"batl":[[0,1.12,1512.68]],"ltp":1.12,"tv":67354.5,"id":9323645}]}]}
{"op":"mcm","clk":"4216948890","pt":1631556683767,"mc":[{"id":"1.187566733","rc":[{"batl":[[1,1.13,656.65],[2,1.14,1219.35]],"ltp":1.12,"tv":67354.5,"id":9323645}]}]}
{"op":"mcm","clk":"4216949038","pt":1631556684685,"mc":[{"id":"1.187566733","rc":[{"batb":[[2,1.09,1125.16]],"batl":[[1,1.14,1219.55],[2,1.15,510.98]],"ltp":1.12,"tv":67354.5,"id":9323645}]}]}
{"op":"mcm","clk":"4216949500","pt":1631556687791,"mc":[{"id":"1.187566733","rc":[{"batb":[[0,1.11,206.89]],"ltp":1.12,"tv":67354.5,"id":9323645}]}]}
{"op":"mcm","clk":"4216949809","pt":1631556689876,"mc":[{"id":"1.187566733","rc":[{"batl":[[2,1.23,1.66]],"ltp":1.12,"tv":67354.5,"id":9323645}]}]}
{"op":"mcm","clk":"4216949914","pt":1631556690600,"mc":[{"id":"1.187566733","rc":[{"batb":[[0,1.1,102.88],[1,1.09,1125.16],[2,1.08,425.84]],"ltp":1.12,"tv":67354.5,"id":9323645}]}]}
{"op":"mcm","clk":"4216950277","pt":1631556693090,"mc":[{"id":"1.187566733","rc":[{"trd":[[9.8,5.96]],"batb":[[0,9.6,9.37],[1,9.4,4.68],[2,9.2,139.56]],"batl":[[0,11,74.08]],"ltp":9.8,"tv":14416.67,"id":8734382},{"trd":[[1.11,5505.96]],"batb":[[0,1.1,897.2],[2,1.08,453.19]],"batl":[[0,1.11,576.65],[1,1.12,1644.72],[2,1.14,1219.55]],"ltp":1.11,"tv":67396.73,"id":9323645}],"tv":81813.41}]}
{"op":"mcm","clk":"4216950470","pt":1631556694207,"mc":[{"id":"1.187566733","rc":[{"batl":[[1,12,2.5],[2,12.5,1.24]],"ltp":9.8,"tv":14416.67,"id":8734382},{"trd":[[1.11,5523.98]],"batb":[[1,1.09,1125.62]],"batl":[[0,1.11,567.64],[1,1.12,1231.73]],"ltp":1.11,"tv":67414.75,"id":9323645}],"tv":81831.43}]}
{"op":"mcm","clk":"4216950574","pt":1631556694800,"mc":[{"id":"1.187566733","rc":[{"batl":[[1,1.12,1942.89]],"ltp":1.11,"tv":67414.75,"id":9323645}]}]}
{"op":"mcm","clk":"4216950752","pt":1631556695994,"mc":[{"id":"1.187566733","rc":[{"batl":[[0,1.11,587.73]],"ltp":1.11,"tv":67414.75,"id":9323645}]}]}
{"op":"mcm","clk":"4216950841","pt":1631556696626,"mc":[{"id":"1.187566733","rc":[{"trd":[[10,1.95]],"ltp":10.0,"tv":14418.62,"id":8734382},{"trd":[[1.1,1125.53],[1.11,5541.55]],"batb":[[0,1.1,334.43]],"batl":[[0,1.11,570.16]],"ltp":1.1,"tv":68557.86,"id":9323645}],"tv":82976.48}]}
{"op":"mcm","clk":"4216951064","pt":1631556697918,"mc":[{"id":"1.187566733","rc":[{"batl":[[0,1.11,1041.86]],"ltp":1.1,"tv":68557.86,"id":9323645}]}]}
{"op":"mcm","clk":"4216951173","pt":1631556698595,"mc":[{"id":"1.187566733","rc":[{"batl":[[0,1.11,1190.86]],"ltp":1.1,"tv":68557.86,"id":9323645}]}]}
{"op":"mcm","clk":"4216951388","pt":1631556699934,"mc":[{"id":"1.187566733","rc":[{"batl":[[0,11,76.08],[2,12.5,3.24]],"ltp":10.0,"tv":14418.62,"id":8734382},{"batb":[[0,1.1,571.87],[1,1.09,1418.23]],"batl":[[0,1.11,1202.75],[1,1.12,132.04],[2,1.13,179.7]],"ltp":1.1,"tv":68557.86,"id":9323645}]}]}
{"op":"mcm","clk":"4216951451","pt":1631556700324,"mc":[{"id":"1.187566733","rc":[{"batb":[[0,1.1,1425.26]],"ltp":1.1,"tv":68557.86,"id":9323645}]}]}
{"op":"mcm","clk":"4216951645","pt":1631556701632,"mc":[{"id":"1.187566733","rc":[{"batl":[[0,1.11,1619.46]],"ltp":1.1,"tv":68557.86,"id":9323645}]}]}
{"op":"mcm","clk":"4216952373","pt":1631556706043,"mc":[{"id":"1.187566733","rc":[{"trd":[[11,57.49]],"batl":[[0,11,18.59]],"ltp":11.0,"tv":14476.11,"id":8734382},{"trd":[[1.1,4550.79]],"batb":[[0,1.09,1418.23],[1,1.08,453.19],[2,1.07,480.64]],"ltp":1.1,"tv":71983.12,"id":9323645}],"tv":86459.23}]}
{"op":"mcm","clk":"4216952494","pt":1631556706834,"mc":[{"id":"1.187566733","rc":[{"batb":[[0,1.1,17],[1,1.09,1418.23],[2,1.08,453.19]],"batl":[[1,1.12,43.41]],"ltp":1.1,"tv":71983.12,"id":9323645}]}]}
{"op":"mcm","clk":"4216952869","pt":1631556709125,"mc":[{"id":"1.187566733","rc":[{"batb":[[0,8.6,2],[1,8,15.09],[2,7.2,17.54]],"batl":[[0,11,2],[1,12.5,2],[2,990,0.01]],"ltp":11.0,"tv":14476.11,"id":8734382},{"batb":[[1,1.09,787.77]],"batl":[[0,1.11,1037.41],[1,1.13,179.7],[2,1.14,1394.6]],"ltp":1.1,"tv":71983.12,"id":9323645}]}]}
{"op":"mcm","clk":"4216953000","pt":1631556709922,"mc":[{"id":"1.187566733","rc":[{"batb":[[1,8,2]],"batl":[[0,12.5,2],[1,990,0.01],[2,990,0]],"ltp":11.0,"tv":14476.11,"id":8734382},{"batb":[[2,1.08,2.21]],"batl":[[0,1.11,416.71]],"ltp":1.1,"tv":71983.12,"id":9323645}]}]}
{"op":"mcm","clk":"4216953343","pt":1631556712118,"mc":[{"id":"1.187566733","rc":[{"batb":[[2,1.08,638.05]],"batl":[[0,1.11,416.94],[1,1.13,671.2],[2,1.14,1509.77]],"ltp":1.1,"tv":71983.12,"id":9323645}]}]}
{"op":"mcm","clk":"4216953489","pt":1631556713122,"mc":[{"id":"1.187566733","rc":[{"batb":[[0,1.1,262.74]],"batl":[[1,1.13,671.43]],"ltp":1.1,"tv":71983.12,"id":9323645}]}]}
{"op":"mcm","clk":"4216953632","pt":1631556714126,"mc":[{"id":"1.187566733","rc":[{"batb":[[0,1.1,17]],"ltp":1.1,"tv":71983.12,"id":9323645}]}]}
{"op":"mcm","clk":"4216953804","pt":1631556715238,"mc":[{"id":"1.187566733","rc":[{"batl":[[1,1.13,179.93],[2,1.14,1394.6]],"ltp":1.1,"tv":71983.12,"id":9323645}]}]}
{"op":"mcm","clk":"4216954249","pt":1631556718127,"mc":[{"id":"1.187566733","rc":[{"batb":[[0,11,4.78],[1,10.5,14.28],[2,10,13.38]],"batl":[[1,13.5,121.1],[2,990,0.01]],"ltp":11.0,"tv":14476.11,"id":8734382},{"batb":[[0,1.09,841.97],[1,1.08,2151.87],[2,1.07,508.25]],"batl":[[0,1.1,672.04],[1,1.11,2989.9],[2,1.13,179.93]],"ltp":1.1,"tv":71983.12,"id":9323645}]}]}
{"op":"mcm","clk":"4216954403","pt":1631556719037,"mc":[{"id":"1.187566733","rc":[{"batb":[[0,10.5,8.57],[1,10,10.52],[2,9.8,4.28]],"batl":[[1,13.5,115.55]],"ltp":11.0,"tv":14476.11,"id":8734382},{"trd":[[1.1,4568.97]],"batb":[[1,1.08,2223.65],[2,1.07,577.69]],"batl":[[0,1.1,615.18],[1,1.11,2499.32]],"ltp":1.1,"tv":72001.3,"id":9323645}],"tv":86477.41}]}
{"op":"mcm","clk":"4216954436","pt":1631556719250,"mc":[{"id":"1.187566733","rc":[{"batb":[[0,10.5,2.86],[1,10,7.66],[2,9.8,1.42]],"ltp":11.0,"tv":14476.11,"id":8734382},{"batb":[[1,1.08,2110.69],[2,1.07,522.13]],"ltp":1.1,"tv":72001.3,"id":9323645}]}]}
{"op":"mcm","clk":"4216954720","pt":1631556721151,"mc":[{"id":"1.187566733","rc":[{"batb":[[0,11,4.78],[1,10.5,2.86],[2,10,7.66]],"batl":[[1,13.5,121.1]],"ltp":11.0,"tv":14476.11,"id":8734382},{"trd":[[1.1,4602.97]],"batb":[[1,1.08,2180.11]],"batl":[[0,1.1,645.95]],"ltp":1.1,"tv":72035.3,"id":9323645}],"tv":86511.41}]}
{"op":"mcm","clk":"4216955012","pt":1631556723042,"mc":[{"id":"1.187566733","rc":[{"batl":[[0,1.1,1078.61]],"ltp":1.1,"tv":72035.3,"id":9323645}]}]}
{"op":"mcm","clk":"4216955273","pt":1631556724543,"mc":[{"id":"1.187566733","rc":[{"batl":[[0,1.1,1104.7]],"ltp":1.1,"tv":72035.3,"id":9323645}]}]}
{"op":"mcm","clk":"4216955469","pt":1631556725861,"mc":[{"id":"1.187566733","rc":[{"batl":[[1,13.5,123.1]],"ltp":11.0,"tv":14476.11,"id":8734382},{"batb":[[1,1.08,2500.92],[2,1.07,894.2]],"batl":[[0,1.1,1335.7],[2,1.12,195.19]],"ltp":1.1,"tv":72035.3,"id":9323645}]}]}
{"op":"mcm","clk":"4216955984","pt":1631556729167,"mc":[{"id":"1.187566733","rc":[{"batb":[[0,10,6.24],[1,9.2,2.02],[2,8.6,29.53]],"batl":[[1,13.5,2]],"ltp":11.0,"tv":14476.11,"id":8734382},{"batb":[[1,1.08,323.02],[2,1.07,880.32]],"batl":[[0,1.1,4072.57],[1,1.11,161.73]],"ltp":1.1,"tv":72035.3,"id":9323645}]}]}
{"op":"mcm","clk":"4216956066","pt":1631556729653,"mc":[{"id":"1.187566733","rc":[{"batb":[[0,9.2,2.02],[1,8.6,2],[2,8,2]],"ltp":11.0,"tv":14476.11,"id":8734382},{"batb":[[0,1.09,787.77],[2,1.07,374.29]],"batl":[[0,1.1,3408.91],[1,1.12,195.42],[2,1.13,179.7]],"ltp":1.1,"tv":72035.3,"id":9323645}]}]}
{"op":"mcm","clk":"4216956290","pt":1631556731047,"mc":[{"id":"1.187566733","rc":[{"batb":[[0,1.09,1641.16]],"ltp":1.1,"tv":72035.3,"id":9323645}]}]}
{"op":"mcm","clk":"4216956629","pt":1631556733145,"mc":[{"id":"1.187566733","rc":[{"batb":[[0,10,2.24],[1,9.2,2.02],[2,8.6,2]],"ltp":11.0,"tv":14476.11,"id":8734382},{"batb":[[1,1.08,538.06]],"batl":[[1,1.11,234.73],[2,1.12,195.19]],"ltp":1.1,"tv":72035.3,"id":9323645}]}]}
{"op":"mcm","clk":"4216956933","pt":1631556734970,"mc":[{"id":"1.187566733","rc":[{"batb":[[0,1.09,1834.01],[1,1.08,764.22]],"batl":[[0,1.1,3855.65]],"ltp":1.1,"tv":72035.3,"id":9323645}]}]}
{"op":"mcm","clk":"4216957066","pt":1631556735841,"mc":[{"id":"1.187566733","rc":[{"trd":[[1.09,1033.76]],"batb":[[0,1.09,1317.09]],"batl":[[1,1.11,410.66]],"ltp":1.09,"tv":73069.06,"id":9323645}],"tv":87545.17}]}
{"op":"mcm","clk":"4216957237","pt":1631556736969,"mc":[{"id":"1.187566733","rc":[{"trd":[[12.5,2],[13.5,2]],"batl":[[0,990,0.01],[1,13.5,0],[2,990,0]],"ltp":13.5,"tv":14480.11,"id":8734382},{"trd":[[1.08,1576.59],[1.09,3667.79]],"batb":[[0,1.07,2.22],[1,1.06,521.1],[2,1.05,2.23]],"batl":[[0,1.08,1870.69],[1,1.1,4075.65],[2,1.11,410.66]],"ltp":1.08,"tv":77279.68,"id":9323645}],"tv":91759.79}]}
{"op":"mcm","clk":"4216957294","pt":1631556737380,"mc":[{"id":"1.187566733","rc":[{"batl":[[2,1.11,234.73]],"ltp":1.08,"tv":77279.68,"id":9323645}]}]}
{"op":"mcm","clk":"4216957667","pt":1631556740090,"mc":[{"id":"1.187566733","rc":[{"trd":[[13.5,6]],"ltp":13.5,"tv":14484.11,"id":8734382},{"trd":[[1.08,2272.71]],"batl":[[0,1.08,2046.47],[1,1.1,4613.86]],"ltp":1.08,"tv":77975.8,"id":9323645}],"tv":92459.91}]}
{"op":"mcm","clk":"4216957787","pt":1631556740783,"mc":[{"id":"1.187566733","rc":[{"trd":[[1.08,3544.39]],"batl":[[0,1.08,861.79],[1,1.1,3628.91]],"ltp":1.08,"tv":79247.48,"id":9323645}],"tv":93731.59}]}
{"op":"mcm","clk":"4216957926","pt":1631556741645,"mc":[{"id":"1.187566733","rc":[{"batl":[[1,1.1,3408.91]],"ltp":1.08,"tv":79247.48,"id":9323645}]}]}
{"op":"mcm","clk":"4216958250","pt":1631556743838,"mc":[{"id":"1.187566733","rc":[{"trd":[[1.08,4077.7]],"batb":[[0,1.07,1048.07]],"batl":[[0,1.08,595.16],[1,1.1,229.46],[2,1.11,625.98]],"ltp":1.08,"tv":79780.78,"id":9323645}],"tv":94264.9}]}
{"op":"mcm","clk":"4216958381","pt":1631556744772,"mc":[{"id":"1.187566733","rc":[{"trd":[[1.08,5268.12]],"batb":[[0,1.08,258.12],[1,1.07,1048.07],[2,1.06,521.1]],"batl":[[0,1.1,229.46],[1,1.11,625.98],[2,1.12,195.19]],"ltp":1.08,"tv":80971.2,"id":9323645}],"tv":95455.32}]}
{"op":"mcm","clk":"4216959396","pt":1631556751167,"mc":[{"id":"1.187566733","rc":[{"batb":[[0,9.2,2.02],[1,7.8,13.76],[2,2.5,1.82]],"ltp":13.5,"tv":14484.11,"id":8734382},{"trd":[[1.1,4611.77]],"batb":[[0,1.07,1048.07],[1,1.06,521.1],[2,1.05,2.23]],"batl":[[0,1.12,195.42],[1,1.21,15.65],[2,1.23,31.44]],"ltp":1.1,"tv":80980.0,"id":9323645}],"tv":95464.12}]}
{"op":"mcm","clk":"4216959834","pt":1631556754191,"mc":[{"id":"1.187566733","rc":[{"batb":[[0,11.5,11.82],[1,11,125.71],[2,10.5,11.48]],"batl":[[0,13.5,59.7],[1,16,8.5],[2,16.5,8.26]],"ltp":13.5,"tv":14484.11,"id":8734382},{"trd":[[1.08,5807.7]],"batb":[[0,1.08,471.67],[1,1.07,1048.07],[2,1.06,548.97]],"batl":[[0,1.09,427.78],[1,1.1,1588.37],[2,1.11,1.13]],"ltp":1.08,"tv":81519.58,"id":9323645}],"tv":96003.7}]}
{"op":"mcm","clk":"4216959975","pt":1631556755160,"mc":[{"id":"1.187566733","rc":[{"trd":[[1.09,3686.13]],"batb":[[1,1.07,1048.54]],"batl":[[0,1.09,418.61],[1,1.1,1586.55]],"ltp":1.09,"tv":81537.92,"id":9323645}],"tv":96022.04}]}
{"op":"mcm","clk":"4216960053","pt":1631556755797,"mc":[{"id":"1.187566733","rc":[{"batl":[[0,1.09,3147.37]],"ltp":1.09,"tv":81537.92,"id":9323645}]}]}
{"op":"mcm","clk":"4216960210","pt":1631556756974,"mc":[{"id":"1.187566733","rc":[{"trd":[[1.08,6044.12]],"batb":[[0,1.08,353.46]],"batl":[[0,1.09,3297.56]],"ltp":1.08,"tv":81774.34,"id":9323645}],"tv":96258.46}]}
{"op":"mcm","clk":"4216960311","pt":1631556757765,"mc":[{"id":"1.187566733","rc":[{"batl":[[0,1.09,3836.97]],"ltp":1.08,"tv":81774.34,"id":9323645}]}]}
{"op":"mcm","clk":"4216960523","pt":1631556759093,"mc":[{"id":"1.187566733","rc":[{"trd":[[13.5,8.7]],"batl":[[0,13.5,57]],"ltp":13.5,"tv":14486.81,"id":8734382},{"trd":[[1.08,6784.71]],"batb":[[0,1.07,1048.54],[1,1.06,548.97],[2,1.05,2.23]],"ltp":1.08,"tv":82514.93,"id":9323645}],"tv":97001.75}]}
{"op":"mcm","clk":"4216960637","pt":1631556759900,"mc":[{"id":"1.187566733","rc":[{"batl":[[1,15.5,2],[2,16,8.5]],"ltp":13.5,"tv":14486.81,"id":8734382},{"batb":[[0,1.07,1167.43],[1,1.06,930.55]],"batl":[[0,1.09,4230.1],[2,1.11,585.63]],"ltp":1.08,"tv":82514.93,"id":9323645}]}]}
{"op":"mcm","clk":"4216960920","pt":1631556762185,"mc":[{"id":"1.187566733","rc":[{"batl":[[1,1.1,1586.73]],"ltp":1.08,"tv":82514.93,"id":9323645}]}]}
{"op":"mcm","clk":"4216961076","pt":1631556763193,"mc":[{"id":"1.187566733","rc":[{"batl":[[0,1.09,7934.51]],"ltp":1.08,"tv":82514.93,"id":9323645}]}]}
{"op":"mcm","clk":"4216961183","pt":1631556763898,"mc":[{"id":"1.187566733","rc":[{"trd":[[13.5,65.7]],"batl":[[0,15.5,2],[1,16,8.5],[2,16.5,8.26]],"ltp":13.5,"tv":14543.81,"id":8734382},{"trd":[[1.07,2334.86],[1.08,7497.21]],"batb":[[0,1.06,930.55],[1,1.05,2.23],[2,1.04,2.98]],"batl":[[0,1.07,120.07],[1,1.09,3843.49],[2,1.1,1586.73]],"ltp":1.07,"tv":85562.29,"id":9323645}],"tv":100106.11}]}
{"op":"mcm","clk":"4216961282","pt":1631556764587,"mc":[{"id":"1.187566733","rc":[{"batl":[[1,1.09,1061.01]],"ltp":1.07,"tv":85562.29,"id":9323645}]}]}
{"op":"mcm","clk":"4216961615","pt":1631556767020,"mc":[{"id":"1.187566733","rc":[{"trd":[[1.07,2575]],"batb":[[0,1.07,617.59],[1,1.06,1070.86],[2,1.05,499.52]],"batl":[[0,1.08,1054.86]],"ltp":1.07,"tv":85802.43,"id":9323645}],"tv":100346.25}]}
{"op":"mcm","clk":"4216961772","pt":1631556767900,"mc":[{"id":"1.187566733","rc":[{"batl":[[0,15,10.05],[1,15.5,2],[2,16,8.5]],"ltp":13.5,"tv":14543.81,"id":8734382},{"trd":[[1.08,7587.21]],"batl":[[0,1.08,3128],[1,1.09,1173.47]],"ltp":1.08,"tv":85892.43,"id":9323645}],"tv":100436.25}]}
{"op":"mcm","clk":"4216961893","pt":1631556768814,"mc":[{"id":"1.187566733","rc":[{"batl":[[0,15.5,2],[1,16,8.5],[2,16.5,8.26]],"ltp":13.5,"tv":14543.81,"id":8734382},{"batl":[[1,1.09,1061.01]],"ltp":1.08,"tv":85892.43,"id":9323645}]}]}
{"op":"mcm","clk":"4216962102","pt":1631556770099,"mc":[{"id":"1.187566733","rc":[{"batl":[[0,1.08,5882.03]],"ltp":1.08,"tv":85892.43,"id":9323645}]}]}
{"op":"mcm","clk":"4216962212","pt":1631556770899,"mc":[{"id":"1.187566733","rc":[{"batb":[[0,1.07,633.18]],"batl":[[1,1.09,1076.19]],"ltp":1.08,"tv":85892.43,"id":9323645}]}]}
{"op":"mcm","clk":"4216962342","pt":1631556771812,"mc":[{"id":"1.187566733","rc":[{"batl":[[0,15,10.05],[1,15.5,2],[2,16,8.5]],"ltp":13.5,"tv":14543.81,"id":8734382},{"batl":[[1,1.09,1188.65]],"ltp":1.08,"tv":85892.43,"id":9323645}]}]}
{"op":"mcm","clk":"4216962594","pt":1631556773613,"mc":[{"id":"1.187566733","rc":[{"batl":[[0,15.5,2],[1,16,8.5],[2,16.5,8.26]],"ltp":13.5,"tv":14543.81,"id":8734382},{"batl":[[1,1.09,1076.19]],"ltp":1.08,"tv":85892.43,"id":9323645}]}]}
{"op":"mcm","clk":"4216963101","pt":1631556777145,"mc":[{"id":"1.187566733","rc":[{"batl":[[0,15,10.05],[1,15.5,2],[2,16,8.5]],"ltp":13.5,"tv":14543.81,"id":8734382},{"batb":[[0,1.07,1486.57]],"batl":[[0,1.08,5884.25],[1,1.09,1188.65]],"ltp":1.08,"tv":85892.43,"id":9323645}]}]}
{"op":"mcm","clk":"4216963261","pt":1631556778125,"mc":[{"id":"1.187566733","rc":[{"batb":[[0,10,6.45],[1,9.2,2.02],[2,8.6,6.94]],"batl":[[0,15.5,2],[1,18,2],[2,21,2]],"ltp":13.5,"tv":14543.81,"id":8734382},{"batb":[[0,1.07,853.39],[1,1.06,902.68]],"batl":[[0,1.08,4889.71],[1,1.09,536.78],[2,1.11,584.91]],"ltp":1.08,"tv":85892.43,"id":9323645}]}]}
{"op":"mcm","clk":"4216963421","pt":1631556779206,"mc":[{"id":"1.187566733","rc":[{"trd":[[1.08,7607.21]],"batl":[[0,1.08,4879.71],[1,1.09,260.78]],"ltp":1.08,"tv":85912.43,"id":9323645}],"tv":100456.25}]}
{"op":"mcm","clk":"4216963619","pt":1631556780621,"mc":[{"id":"1.187566733","rc":[{"trd":[[1.07,3528.81]],"batb":[[0,1.07,729.51],[1,1.06,1550.51]],"batl":[[1,1.09,524.57],[2,1.1,106.83]],"ltp":1.07,"tv":86866.24,"id":9323645}],"tv":101410.06}]}
{"op":"mcm","clk":"4216964679","pt":1631556788193,"mc":[{"id":"1.187566733","rc":[{"batb":[[2,8.4,28.95]],"ltp":13.5,"tv":14543.81,"id":8734382},{"batb":[[1,1.06,902.68]],"ltp":1.07,"tv":86866.24,"id":9323645}]}]}
{"op":"mcm","clk":"4216964813","pt":1631556789203,"mc":[{"id":"1.187566733","rc":[{"batl":[[0,1.08,2.22]],"ltp":1.07,"tv":86866.24,"id":9323645}]}]}
{"op":"mcm","clk":"4216965080","pt":1631556791107,"mc":[{"id":"1.187566733","rc":[{"batb":[[0,12,3.69],[1,11,81.69],[2,10,6.45]],"batl":[[0,13.5,75.42],[1,14.5,6.2],[2,15,16.44]],"ltp":13.5,"tv":14543.81,"id":8734382},{"trd":[[1.08,7611.65],[1.09,3808.24]],"batb":[[0,1.08,1246.32],[1,1.07,1093.04],[2,1.06,902.68]],"batl":[[0,1.09,463.53],[1,1.1,923.72],[2,1.11,584.73]],"ltp":1.09,"tv":86992.79,"id":9323645}],"tv":101536.61}]}
{"op":"mcm","clk":"4216965250","pt":1631556792204,"mc":[{"id":"1.187566733","rc":[{"batl":[[1,14.5,2.06],[2,15,9.04]],"ltp":13.5,"tv":14543.81,"id":8734382},{"batb":[[1,1.07,1146.97],[2,1.06,894.12]],"batl":[[2,1.11,612.2]],"ltp":1.09,"tv":86992.79,"id":9323645}]}]}
{"op":"mcm","clk":"4216965375","pt":1631556793112,"mc":[{"id":"1.187566733","rc":[{"batl":[[0,1.09,2359.95]],"ltp":1.09,"tv":86992.79,"id":9323645}]}]}
{"op":"mcm","clk":"4216965552","pt":1631556794401,"mc":[{"id":"1.187566733","rc":[{"batb":[[0,1.08,1280.54]],"batl":[[0,1.09,2386.52],[1,1.1,957.88]],"ltp":1.09,"tv":86992.79,"id":9323645}]}]}
{"op":"mcm","clk":"4216965730","pt":1631556795925,"mc":[{"id":"1.187566733","rc":[{"batb":[[0,1.08,1645.01]],"batl":[[0,1.09,3167.62]],"ltp":1.09,"tv":86992.79,"id":9323645}]}]}
{"op":"mcm","clk":"4216965812","pt":1631556796516,"mc":[{"id":"1.187566733","rc":[{"batl":[[0,1.09,3555.62]],"ltp":1.09,"tv":86992.79,"id":9323645}]}]}
{"op":"mcm","clk":"4216966032","pt":1631556797527,"mc":[{"id":"1.187566733","rc":[{"batb":[[1,1.07,1149.48]],"ltp":1.09,"tv":86992.79,"id":9323645}]}]}
{"op":"mcm","clk":"4216966189","pt":1631556798620,"mc":[{"id":"1.187566733","rc":[{"trd":[[1.08,8982.99]],"batb":[[0,1.08,949.34]],"ltp":1.08,"tv":88364.13,"id":9323645}],"tv":102907.95}]}
{"op":"mcm","clk":"4216966321","pt":1631556799628,"mc":[{"id":"1.187566733","rc":[{"batl":[[0,1.09,6752.57]],"ltp":1.08,"tv":88364.13,"id":9323645}]}]}
{"op":"mcm","clk":"4216966546","pt":1631556801130,"mc":[{"id":"1.187566733","rc":[{"batb":[[0,10,6.45],[1,9.2,2.02],[2,8.4,28.95]],"batl":[[0,15.5,2],[1,18,2],[2,21,2]],"ltp":13.5,"tv":14543.81,"id":8734382},{"batb":[[0,1.07,1121.4],[1,1.06,894.12],[2,1.05,499.52]],"batl":[[0,1.09,6264.68],[1,1.1,140.99],[2,1.11,584.73]],"ltp":1.08,"tv":88364.13,"id":9323645}]}]}
{"op":"mcm","clk":"4216966646","pt":1631556801828,"mc":[{"id":"1.187566733","rc":[{"batb":[[2,7.8,14.1]],"batl":[[0,18,2],[1,21,2],[2,990,0.01]],"ltp":13.5,"tv":14543.81,"id":8734382},{"trd":[[1.09,3828.24]],"batb":[[0,1.07,303.42]],"batl":[[0,1.09,5085.58]],"ltp":1.09,"tv":88384.14,"id":9323645}],"tv":102927.95}]}
{"op":"mcm","clk":"4216966827","pt":1631556803018,"mc":[{"id":"1.187566733","rc":[{"batl":[[0,1.09,6033.79]],"ltp":1.09,"tv":88384.14,"id":9323645}]}]}
{"op":"mcm","clk":"4216966982","pt":1631556804024,"mc":[{"id":"1.187566733","rc":[{"batb":[[0,1.07,644.29]],"batl":[[1,1.1,218.86],[2,1.11,986.66]],"ltp":1.09,"tv":88384.14,"id":9323645}]}]}
{"op":"mcm","clk":"4216967141","pt":1631556805147,"mc":[{"id":"1.187566733","rc":[{"batb":[[0,1.07,2.51]],"batl":[[2,1.11,584.73]],"ltp":1.09,"tv":88384.14,"id":9323645}]}]}
{"op":"mcm","clk":"4216967665","pt":1631556809034,"mc":[{"id":"1.187566733","rc":[{"batb":[[0,1.08,2.46],[1,1.07,2.51],[2,1.06,894.12]],"ltp":1.09,"tv":88384.14,"id":9323645}]}]}
{"op":"mcm","clk":"4216967919","pt":1631556810741,"mc":[{"id":"1.187566733","rc":[{"batb":[[1,1.07,644.29]],"batl":[[2,1.11,995.72]],"ltp":1.09,"tv":88384.14,"id":9323645}]}]}
{"op":"mcm","clk":"4216968093","pt":1631556811966,"mc":[{"id":"1.187566733","rc":[{"batl":[[0,15.5,2.59],[1,18,2],[2,21,2]],"ltp":13.5,"tv":14543.81,"id":8734382},{"batb":[[1,1.07,2047.53]],"ltp":1.09,"tv":88384.14,"id":9323645}]}]}
{"op":"mcm","clk":"4216968195","pt":1631556812659,"mc":[{"id":"1.187566733","rc":[{"batb":[[0,9.2,2.02],[1,7.8,14.1],[2,2.5,1.82]],"ltp":13.5,"tv":14543.81,"id":8734382},{"batl":[[1,1.14,1.08],[2,1.19,15.22]],"ltp":1.09,"tv":88384.14,"id":9323645}]}]}
{"op":"mcm","clk":"4216968384","pt":1631556813835,"mc":[{"id":"1.187566733","rc":[{"trd":[[1.07,5523.89],[1.08,8987.91]],"batb":[[0,1.07,1049.99],[1,1.06,894.12],[2,1.05,499.52]],"ltp":1.07,"tv":90384.13,"id":9323645}],"tv":104927.95}]}
{"op":"mcm","clk":"4216968582","pt":1631556815156,"mc":[{"id":"1.187566733","rc":[{"batb":[[0,10.5,19.04],[1,9.2,2.02],[2,7.8,14.1]],"batl":[[0,15,168.53],[1,15.5,2.59],[2,18,2]],"ltp":13.5,"tv":14543.81,"id":8734382},{"batl":[[0,1.09,7843.98],[1,1.1,68.98],[2,1.11,69.03]],"ltp":1.07,"tv":90384.13,"id":9323645}]}]}
{"op":"mcm","clk":"4216968720","pt":1631556816151,"mc":[{"id":"1.187566733","rc":[{"batb":[[2,9,24.67]],"batl":[[2,16,9.38]],"ltp":13.5,"tv":14543.81,"id":8734382},{"trd":[[1.08,9115.63]],"batb":[[1,1.06,921.99],[2,1.05,1139.16]],"batl":[[0,1.08,194.82],[1,1.09,4535.08],[2,1.1,13.94]],"ltp":1.08,"tv":90511.86,"id":9323645}],"tv":105055.68}]}
{"op":"mcm","clk":"4216968839","pt":1631556816956,"mc":[{"id":"1.187566733","rc":[{"batl":[[2,16,1.88]],"ltp":13.5,"tv":14543.81,"id":8734382},{"batb":[[0,1.07,1453.22],[1,1.06,1127.09]],"batl":[[0,1.08,544.7]],"ltp":1.08,"tv":90511.86,"id":9323645}]}]}
{"op":"mcm","clk":"4216968996","pt":1631556818128,"mc":[{"id":"1.187566733","rc":[{"batl":[[1,1.09,1698.25]],"ltp":1.08,"tv":90511.86,"id":9323645}]}]}
{"op":"mcm","clk":"4216969115","pt":1631556818926,"mc":[{"id":"1.187566733","rc":[{"batb":[[0,1.07,1483.9]],"batl":[[0,1.08,569.17]],"ltp":1.08,"tv":90511.86,"id":9323645}]}]}
{"op":"mcm","clk":"4216969302","pt":1631556820154,"mc":[{"id":"1.187566733","rc":[{"trd":[[1.07,7785.13],[1.08,9120.75]],"batb":[[0,1.07,755.49]],"batl":[[0,1.08,1386.63]],"ltp":1.07,"tv":92778.22,"id":9323645}],"tv":107322.04}]}
{"op":"mcm","clk":"4216969619","pt":1631556822153,"mc":[{"id":"1.187566733","rc":[{"batl":[[0,1.08,6746.65]],"ltp":1.07,"tv":92778.22,"id":9323645}]}]}
{"op":"mcm","clk":"4216969807","pt":1631556823074,"mc":[{"id":"1.187566733","rc":[{"batb":[[0,1.07,798.14],[1,1.06,1170.62]],"batl":[[0,1.08,6795.85]],"ltp":1.07,"tv":92778.22,"id":9323645}]}]}
{"op":"mcm","clk":"4216969901","pt":1631556823759,"mc":[{"id":"1.187566733","rc":[{"batl":[[0,1.08,7163.85]],"ltp":1.07,"tv":92778.22,"id":9323645}]}]}
{"op":"mcm","clk":"4216970104","pt":1631556824948,"mc":[{"id":"1.187566733","rc":[{"batb":[[0,1.07,395.93],[1,1.06,1505.84]],"ltp":1.07,"tv":92778.22,"id":9323645}]}]}
{"op":"mcm","clk":"4216970724","pt":1631556829073,"mc":[{"id":"1.187566733","rc":[{"batb":[[1,1.06,1490.27]],"batl":[[0,1.08,7148.66]],"ltp":1.07,"tv":92778.22,"id":9323645}]}]}
{"op":"mcm","clk":"4216970855","pt":1631556829939,"mc":[{"id":"1.187566733","rc":[{"batl":[[1,1.09,1700.63]],"ltp":1.07,"tv":92778.22,"id":9323645}]}]}
{"op":"mcm","clk":"4216971051","pt":1631556831060,"mc":[{"id":"1.187566733","rc":[{"batl":[[0,1.08,7151.09]],"ltp":1.07,"tv":92778.22,"id":9323645}]}]}
{"op":"mcm","clk":"4216971229","pt":1631556832090,"mc":[{"id":"1.187566733","rc":[{"batb":[[0,1.07,411.36]],"ltp":1.07,"tv":92778.22,"id":9323645}]}]}
{"op":"mcm","clk":"4216971401","pt":1631556833048,"mc":[{"id":"1.187566733","rc":[{"trd":[[15,29.9]],"batb":[[0,10.5,34.57]],"batl":[[0,15,138.63]],"ltp":15.0,"tv":14573.71,"id":8734382},{"trd":[[1.07,9027.09]],"batb":[[0,1.06,1490.27],[1,1.05,1139.16],[2,1.04,549.1]],"batl":[[0,1.08,5017.63]],"ltp":1.07,"tv":94020.18,"id":9323645}],"tv":108593.9}]}
{"op":"mcm","clk":"4216971431","pt":1631556833262,"mc":[{"id":"1.187566733","rc":[{"batb":[[0,10.5,19.04]],"ltp":15.0,"tv":14573.71,"id":8734382}]}]}
{"op":"mcm","clk":"4216971615","pt":1631556834375,"mc":[{"id":"1.187566733","rc":[{"trd":[[13.5,67.41]],"ltp":13.5,"tv":14575.42,"id":8734382},{"trd":[[1.08,9142.08]],"batl":[[0,1.08,4996.3]],"ltp":1.08,"tv":94041.51,"id":9323645}],"tv":108616.93}]}
{"op":"mcm","clk":"4216971875","pt":1631556835972,"mc":[{"id":"1.187566733","rc":[{"batb":[[0,1.07,184.02],[1,1.06,1707.66],[2,1.05,1139.16]],"batl":[[0,1.08,5031.52]],"ltp":1.08,"tv":94041.51,"id":9323645}]}]}
{"op":"mcm","clk":"4216971958","pt":1631556836455,"mc":[{"id":"1.187566733","rc":[{"batb":[[0,13.5,170.68],[1,10.5,19.04],[2,9.2,2.02]],"ltp":13.5,"tv":14575.42,"id":8734382}]}]}
{"op":"mcm","clk":"4216972192","pt":1631556837950,"mc":[{"id":"1.187566733","rc":[{"trd":[[13.5,69.2]],"batb":[[0,13.5,169.78]],"ltp":13.5,"tv":14577.21,"id":8734382},{"batb":[[0,1.07,196]],"batl":[[0,1.08,5052.85]],"ltp":1.08,"tv":94041.51,"id":9323645}],"tv":108618.73}]}
{"op":"mcm","clk":"4216972378","pt":1631556839085,"mc":[{"id":"1.187566733","rc":[{"batb":[[1,10.5,34.57]],"ltp":13.5,"tv":14577.21,"id":8734382}]}]}
{"op":"mcm","clk":"4216972490","pt":1631556839682,"mc":[{"id":"1.187566733","rc":[{"batb":[[1,10.5,19.04]],"ltp":13.5,"tv":14577.21,"id":8734382},{"trd":[[1.08,9182.08]],"batl":[[0,1.08,5032.85]],"ltp":1.08,"tv":94081.51,"id":9323645}],"tv":108658.73}]}
{"op":"mcm","clk":"4216973004","pt":1631556843195,"mc":[{"id":"1.187566733","rc":[{"trd":[[1.08,9183.94]],"batb":[[1,1.06,1695.8]],"batl":[[0,1.08,5051.92]],"ltp":1.08,"tv":94083.37,"id":9323645}],"tv":108660.59}]}
{"op":"mcm","clk":"4216973475","pt":1631556846193,"mc":[{"id":"1.187566733","rc":[{"batb":[[0,1.07,207.74]],"ltp":1.08,"tv":94083.37,"id":9323645}]}]}
{"op":"mcm","clk":"4216973622","pt":1631556847098,"mc":[{"id":"1.187566733","rc":[{"trd":[[15,67.47]],"batl":[[0,15,101.06]],"ltp":15.0,"tv":14614.78,"id":8734382},{"trd":[[1.07,9969.51]],"batb":[[0,1.06,1695.8],[1,1.05,1139.16],[2,1.04,549.1]],"ltp":1.07,"tv":95025.79,"id":9323645}],"tv":109640.58}]}
{"op":"mcm","clk":"4216973974","pt":1631556849190,"mc":[{"id":"1.187566733","rc":[{"batl":[[0,1.08,1825.37]],"ltp":1.07,"tv":95025.79,"id":9323645}]}]}
{"op":"mcm","clk":"4216974136","pt":1631556850183,"mc":[{"id":"1.187566733","rc":[{"batb":[[0,1.06,1792.08]],"batl":[[0,1.08,2892.09]],"ltp":1.07,"tv":95025.79,"id":9323645}]}]}
{"op":"mcm","clk":"4216974212","pt":1631556850671,"mc":[{"id":"1.187566733","rc":[{"trd":[[14,1.72],[15,70.12]],"batl":[[0,15,98.41]],"ltp":15.0,"tv":14619.16,"id":8734382},{"trd":[[1.07,10029.24]],"ltp":1.07,"tv":95085.53,"id":9323645}],"tv":109704.69}]}
{"op":"mcm","clk":"4216974518","pt":1631556852599,"mc":[{"id":"1.187566733","rc":[{"batb":[[0,1.06,1229.81]],"batl":[[0,1.08,2257.18]],"ltp":1.07,"tv":95085.53,"id":9323645}]}]}
{"op":"mcm","clk":"4216974750","pt":1631556854004,"mc":[{"id":"1.187566733","rc":[{"trd":[[15,168.53]],"batl":[[0,15.5,2.59],[1,16,1.88],[2,17,1.88]],"ltp":15.0,"tv":14717.57,"id":8734382},{"trd":[[1.07,11409.06]],"batl":[[0,1.07,1876.89],[1,1.08,2257.18],[2,1.09,1700.63]],"ltp":1.07,"tv":96465.34,"id":9323645}],"tv":111182.92}]}
{"op":"mcm","clk":"4216974955","pt":1631556855499,"mc":[{"id":"1.187566733","rc":[{"batb":[[1,1.05,1793.16]],"batl":[[1,1.08,1190.46],[2,1.09,2301.62]],"ltp":1.07,"tv":96465.34,"id":9323645}]}]}
{"op":"mcm","clk":"4216975290","pt":1631556857200,"mc":[{"id":"1.187566733","rc":[{"batl":[[0,1.07,2747.46]],"ltp":1.07,"tv":96465.34,"id":9323645}]}]}
{"op":"mcm","clk":"4216975444","pt":1631556858206,"mc":[{"id":"1.187566733","rc":[{"batb":[[0,10.5,19.04],[1,9.2,2.02],[2,9,24.67]],"ltp":15.0,"tv":14717.57,"id":8734382}]}]}
{"op":"mcm","clk":"4216975551","pt":1631556858905,"mc":[{"id":"1.187566733","rc":[{"trd":[[1.06,1670.95]],"batb":[[0,1.06,394.33]],"ltp":1.06,"tv":98136.29,"id":9323645}],"tv":112853.86}]}
{"op":"mcm","clk":"4216975986","pt":1631556862109,"mc":[{"id":"1.187566733","rc":[{"batb":[[0,11,15.3],[1,10.5,19.04],[2,9.2,2.02]],"ltp":15.0,"tv":14717.57,"id":8734382},{"batb":[[1,1.05,2153.61]],"ltp":1.06,"tv":98136.29,"id":9323645}]}]}
{"op":"mcm","clk":"4216976289","pt":1631556864199,"mc":[{"id":"1.187566733","rc":[{"batl":[[2,1.09,2202.66]],"ltp":1.06,"tv":98136.29,"id":9323645}]}]}
{"op":"mcm","clk":"4216976511","pt":1631556865710,"mc":[{"id":"1.187566733","rc":[{"trd":[[1.07,11458.52]],"batl":[[0,1.07,2722.73]],"ltp":1.07,"tv":98185.75,"id":9323645}],"tv":112903.32}]}
{"op":"mcm","clk":"4216976736","pt":1631556867211,"mc":[{"id":"1.187566733","rc":[{"batb":[[0,13.5,5.25],[1,11,15.3],[2,10.5,19.04]],"ltp":15.0,"tv":14717.57,"id":8734382},{"batl":[[1,1.08,1256.03]],"ltp":1.07,"tv":98185.75,"id":9323645}]}]}
{"op":"mcm","clk":"4216976762","pt":1631556867420,"mc":[{"id":"1.187566733","rc":[{"batb":[[1,10.5,19.04],[2,9.2,2.02]],"ltp":15.0,"tv":14717.57,"id":8734382},{"batb":[[0,1.06,1247.72]],"ltp":1.07,"tv":98185.75,"id":9323645}]}]}
{"op":"mcm","clk":"4216977277","pt":1631556871129,"mc":[{"id":"1.187566733","rc":[{"trd":[[1.07,11458.91]],"batl":[[0,1.07,2724.76]],"ltp":1.07,"tv":98186.14,"id":9323645}],"tv":112903.71}]}
{"op":"mcm","clk":"4216977344","pt":1631556871621,"mc":[{"id":"1.187566733","rc":[{"trd":[[1.06,2539.97]],"batb":[[0,1.06,813.2]],"batl":[[0,1.07,3943.88]],"ltp":1.06,"tv":99055.16,"id":9323645}],"tv":113772.74}]}
{"op":"mcm","clk":"4216977515","pt":1631556872915,"mc":[{"id":"1.187566733","rc":[{"batl":[[0,1.07,2724.76]],"ltp":1.06,"tv":99055.16,"id":9323645}]}]}
{"op":"mcm","clk":"4216977627","pt":1631556873809,"mc":[{"id":"1.187566733","rc":[{"batb":[[0,1.06,1666.59]],"ltp":1.06,"tv":99055.16,"id":9323645}]}]}
{"op":"mcm","clk":"4216977940","pt":1631556876046,"mc":[{"id":"1.187566733","rc":[{"batb":[[2,10,12.9]],"ltp":15.0,"tv":14717.57,"id":8734382},{"trd":[[1.07,11512.26]],"batl":[[0,1.07,2698.08]],"ltp":1.07,"tv":99108.51,"id":9323645}],"tv":113826.08}]}
{"op":"mcm","clk":"4216978009","pt":1631556876525,"mc":[{"id":"1.187566733","rc":[{"trd":[[1.07,11521.28]],"batl":[[0,1.07,2693.57]],"ltp":1.07,"tv":99117.54,"id":9323645}],"tv":113835.11}]}
{"op":"mcm","clk":"4216978492","pt":1631556879831,"mc":[{"id":"1.187566733","rc":[{"trd":[[1.06,2557.04]],"batb":[[0,1.06,1658.06],[1,1.05,2155.31]],"ltp":1.06,"tv":99134.6,"id":9323645}],"tv":113852.18}]}
{"op":"mcm","clk":"4216978811","pt":1631556882133,"mc":[{"id":"1.187566733","rc":[{"batb":[[0,10,12.9],[1,9,24.67],[2,8.6,14.54]],"batl":[[0,990,0.01],[1,16,0],[2,17,0]],"ltp":15.0,"tv":14717.57,"id":8734382},{"batb":[[1,1.05,1658.02],[2,1.04,2.98]],"batl":[[1,1.08,1190.46],[2,1.09,603.37]],"ltp":1.06,"tv":99134.6,"id":9323645}]}]}
{"op":"mcm","clk":"4216978884","pt":1631556882631,"mc":[{"id":"1.187566733","rc":[{"batb":[[1,8.6,14.54],[2,8.2,12.42]],"ltp":15.0,"tv":14717.57,"id":8734382},{"batb":[[1,1.05,1297.57]],"batl":[[0,1.07,1823],[1,1.08,2.44]],"ltp":1.06,"tv":99134.6,"id":9323645}]}]}
{"op":"mcm","clk":"4216979236","pt":1631556885211,"mc":[{"id":"1.187566733","rc":[{"batb":[[2,1.04,747.85]],"ltp":1.06,"tv":99134.6,"id":9323645}]}]}
{"op":"mcm","clk":"4216979296","pt":1631556885626,"mc":[{"id":"1.187566733","rc":[{"batb":[[2,2.5,1.82]],"ltp":15.0,"tv":14717.57,"id":8734382},{"batb":[[1,1.05,657.94]],"ltp":1.06,"tv":99134.6,"id":9323645}]}]}
{"op":"mcm","clk":"4216979454","pt":1631556886850,"mc":[{"id":"1.187566733","rc":[{"trd":[[1.06,5872.87]],"batb":[[0,1.05,657.94],[1,1.04,747.85],[2,1.03,3.73]],"batl":[[0,1.06,342.23],[1,1.07,1823],[2,1.08,2.44]],"ltp":1.06,"tv":102450.43,"id":9323645}],"tv":117168.0}]}
{"op":"mcm","clk":"4216980029","pt":1631556890738,"mc":[{"id":"1.187566733","rc":[{"trd":[[1.06,5918.39]],"batl":[[0,1.06,319.47]],"ltp":1.06,"tv":102495.95,"id":9323645}],"tv":117213.52}]}
{"op":"mcm","clk":"4216980447","pt":1631556893557,"mc":[{"id":"1.187566733","rc":[{"batl":[[0,1.07,1823],[1,1.08,2.44],[2,1.09,603.37]],"ltp":1.06,"tv":102495.95,"id":9323645}]}]}
{"op":"mcm","clk":"4216980559","pt":1631556894245,"mc":[{"id":"1.187566733","rc":[{"trd":[[1.05,21.9]],"batb":[[0,1.05,646.99]],"ltp":1.05,"tv":102517.85,"id":9323645}],"tv":117235.43}]}
{"op":"mcm","clk":"4216980815","pt":1631556895850,"mc":[{"id":"1.187566733","rc":[{"batb":[[0,8.6,14.54],[1,2.5,1.82],[2,1.01,98.87]],"ltp":15.0,"tv":14717.57,"id":8734382},{"batb":[[0,1.05,1.71]],"batl":[[0,1.07,2.23]],"ltp":1.05,"tv":102517.85,"id":9323645}]}]}
{"op":"mcm","clk":"4216981172","pt":1631556898049,"mc":[{"id":"1.187566733","rc":[{"trd":[[13.5,69.39],[15,168.69]],"batb":[[0,11,154.44],[1,8.6,14.54],[2,2.5,1.82]],"batl":[[0,15,11.96],[1,17.5,481.62],[2,990,0.01]],"ltp":13.5,"tv":14717.92,"id":8734382},{"trd":[[1.07,11523.51],[1.08,9186.38],[1.09,3846.42]],"batb":[[0,1.07,334.13],[1,1.06,70.1],[2,1.05,71.81]],"batl":[[0,1.09,709.81],[1,1.1,1544.55],[2,1.15,1.11]],"ltp":1.09,"tv":102540.69,"id":9323645}],"tv":117258.61}]}
{"op":"mcm","clk":"4216981305","pt":1631556898964,"mc":[{"id":"1.187566733","rc":[{"batb":[[1,10.5,14.28],[2,10,7.14]],"ltp":13.5,"tv":14717.92,"id":8734382},{"trd":[[1.09,3954.79]],"batb":[[0,1.08,264.76],[1,1.07,567.22],[2,1.06,584.03]],"batl":[[0,1.09,655.64],[2,1.11,2.48]],"ltp":1.09,"tv":102649.06,"id":9323645}],"tv":117366.98}]}
{"op":"mcm","clk":"4216981451","pt":1631556899946,"mc":[{"id":"1.187566733","rc":[{"batb":[[1,10.5,2.86],[2,10,1.42]],"ltp":13.5,"tv":14717.92,"id":8734382},{"batb":[[1,1.07,509.27],[2,1.06,589.32]],"batl":[[2,1.13,1.11]],"ltp":1.09,"tv":102649.06,"id":9323645}]}]}
{"op":"mcm","clk":"4216981610","pt":1631556900966,"mc":[{"id":"1.187566733","rc":[{"trd":[[1.08,9715.94]],"batb":[[0,1.07,509.27],[1,1.06,789.32],[2,1.05,627.83]],"batl":[[0,1.08,3214.29],[1,1.09,655.64],[2,1.1,1544.55]],"ltp":1.08,"tv":103178.63,"id":9323645}],"tv":117896.55}]}
{"op":"mcm","clk":"4216981784","pt":1631556902148,"mc":[{"id":"1.187566733","rc":[{"trd":[[1.08,9784.25]],"batb":[[1,1.06,822.65]],"batl":[[0,1.08,3180.13],[1,1.09,687.44]],"ltp":1.08,"tv":103246.93,"id":9323645}],"tv":117964.85}]}
{"op":"mcm","clk":"4216981984","pt":1631556903167,"mc":[{"id":"1.187566733","rc":[{"batb":[[1,1.06,789.32]],"batl":[[1,1.09,1354.43]],"ltp":1.08,"tv":103246.93,"id":9323645}]}]}
{"op":"mcm","clk":"4216982180","pt":1631556904159,"mc":[{"id":"1.187566733","rc":[{"batl":[[0,1.08,3855.81]],"ltp":1.08,"tv":103246.93,"id":9323645}]}]}
{"op":"mcm","clk":"4216982353","pt":1631556905067,"mc":[{"id":"1.187566733","rc":[{"batb":[[2,10,19.31]],"ltp":13.5,"tv":14717.92,"id":8734382},{"trd":[[1.08,10051.73]],"batb":[[0,1.07,676],[1,1.06,755.99]],"batl":[[0,1.08,4196.06],[1,1.09,1412.51]],"ltp":1.08,"tv":103514.41,"id":9323645}],"tv":118232.34}]}
{"op":"mcm","clk":"4216982500","pt":1631556905982,"mc":[{"id":"1.187566733","rc":[{"batb":[[1,1.06,522.66]],"ltp":1.08,"tv":103514.41,"id":9323645}]}]}
{"op":"mcm","clk":"4216982546","pt":1631556906255,"mc":[{"id":"1.187566733","rc":[{"trd":[[13.5,141.66]],"ltp":13.5,"tv":14790.19,"id":8734382},{"trd":[[1.08,10955.59]],"batl":[[0,1.08,3292.2]],"ltp":1.08,"tv":104418.27,"id":9323645}],"tv":119208.46}]}
{"op":"mcm","clk":"4216982778","pt":1631556907882,"mc":[{"id":"1.187566733","rc":[{"batb":[[0,10,17.89],[1,9.2,15.37],[2,9,24.84]],"batl":[[0,990,0.01],[1,17.5,0],[2,990,0]],"ltp":13.5,"tv":14790.19,"id":8734382},{"batb":[[0,1.06,508.64],[1,1.05,613.81],[2,1.04,2.98]],"batl":[[0,1.08,2616.52],[1,1.11,1203.48],[2,1.12,1099.35]],"ltp":1.08,"tv":104418.27,"id":9323645}]}]}
{"op":"mcm","clk":"4216982891","pt":1631556908685,"mc":[{"id":"1.187566733","rc":[{"batb":[[2,8.6,14.54]],"ltp":13.5,"tv":14790.19,"id":8734382},{"batb":[[0,1.05,613.81],[1,1.04,2.98],[2,1.03,3.73]],"batl":[[0,1.08,4275.99]],"ltp":1.08,"tv":104418.27,"id":9323645}]}]}
{"op":"mcm","clk":"4216983218","pt":1631556910998,"mc":[{"id":"1.187566733","rc":[{"batb":[[0,1.06,650.39],[1,1.05,613.81],[2,1.04,2.98]],"batl":[[1,1.1,613.92],[2,1.11,1203.3]],"ltp":1.08,"tv":104418.27,"id":9323645}]}]}
{"op":"mcm","clk":"4216983350","pt":1631556911763,"mc":[{"id":"1.187566733","rc":[{"batb":[[0,1.07,2.75],[1,1.06,650.39],[2,1.05,613.81]],"ltp":1.08,"tv":104418.27,"id":9323645}]}]}
{"op":"mcm","clk":"4216983525","pt":1631556912962,"mc":[{"id":"1.187566733","rc":[{"trd":[[1.08,10960.88]],"batb":[[0,1.06,650.91],[1,1.05,613.81],[2,1.04,2.98]],"batl":[[0,1.08,4273.34]],"ltp":1.08,"tv":104423.56,"id":9323645}],"tv":119213.75}]}
{"op":"mcm","clk":"4216983642","pt":1631556913671,"mc":[{"id":"1.187566733","rc":[{"batl":[[1,1.1,2320.69]],"ltp":1.08,"tv":104423.56,"id":9323645}]}]}
{"op":"mcm","clk":"4216983838","pt":1631556914758,"mc":[{"id":"1.187566733","rc":[{"batl":[[0,1.08,2139.88]],"ltp":1.08,"tv":104423.56,"id":9323645}]}]}
{"op":"mcm","clk":"4216984178","pt":1631556916962,"mc":[{"id":"1.187566733","rc":[{"batb":[[0,9.2,15.37],[1,8.2,12.25],[2,2.5,1.82]],"ltp":13.5,"tv":14790.19,"id":8734382},{"trd":[[1.07,11524.55]],"batb":[[0,1.06,2.56]],"batl":[[0,1.07,9.48],[1,1.08,2139.88],[2,1.1,2320.69]],"ltp":1.07,"tv":104424.6,"id":9323645}],"tv":119214.79}]}
{"op":"mcm","clk":"4216984324","pt":1631556917975,"mc":[{"id":"1.187566733","rc":[{"trd":[[1.07,11543.51],[1.08,11161.93]],"batl":[[0,1.07,1219.12],[1,1.1,2320.69],[2,1.15,1.11]],"ltp":1.08,"tv":104644.62,"id":9323645}],"tv":119434.81}]}
{"op":"mcm","clk":"4216984384","pt":1631556918364,"mc":[{"id":"1.187566733","rc":[{"batl":[[0,1.1,613.92],[1,1.15,1.11],[2,1.17,30]],"ltp":1.08,"tv":104644.62,"id":9323645}]}]}
{"op":"mcm","clk":"4216984634","pt":1631556920175,"mc":[{"id":"1.187566733","rc":[{"batb":[[0,11,5.65],[1,9.2,15.37],[2,8.2,12.25]],"batl":[[0,12.5,3.2],[1,13.5,126.87],[2,14.5,10.34]],"ltp":13.5,"tv":14790.19,"id":8734382},{"trd":[[1.1,4737.03]],"batb":[[0,1.09,137.08],[1,1.08,6198.61],[2,1.06,3.03]],"batl":[[0,1.1,607.8],[1,1.11,2880.64],[2,1.17,30.88]],"ltp":1.1,"tv":104769.87,"id":9323645}],"tv":119560.06}]}
{"op":"mcm","clk":"4216984812","pt":1631556921192,"mc":[{"id":"1.187566733","rc":[{"batl":[[2,14.5,2.06]],"ltp":13.5,"tv":14790.19,"id":8734382},{"batb":[[1,1.08,2898.44],[2,1.06,518.13]],"batl":[[1,1.11,2908.11],[2,1.12,13.75]],"ltp":1.1,"tv":104769.87,"id":9323645}]}]}
{"op":"mcm","clk":"4216984891","pt":1631556921793,"mc":[{"id":"1.187566733","rc":[{"batb":[[1,1.08,2848.44]],"ltp":1.1,"tv":104769.87,"id":9323645}]}]}
{"op":"mcm","clk":"4216985086","pt":1631556923078,"mc":[{"id":"1.187566733","rc":[{"batl":[[0,1.1,1461.18],[1,1.11,3683.92]],"ltp":1.1,"tv":104769.87,"id":9323645}]}]}
{"op":"mcm","clk":"4216985188","pt":1631556923782,"mc":[{"id":"1.187566733","rc":[{"batb":[[0,1.09,172.1],[1,1.08,2834.72]],"batl":[[0,1.1,1475.71]],"ltp":1.1,"tv":104769.87,"id":9323645}]}]}
{"op":"mcm","clk":"4216985366","pt":1631556924967,"mc":[{"id":"1.187566733","rc":[{"trd":[[11,61.27]],"batb":[[0,11,3.76]],"ltp":11.0,"tv":14793.97,"id":8734382},{"trd":[[1.09,4299.02]],"batb":[[0,1.08,2834.72],[1,1.06,518.13],[2,1.05,1.71]],"batl":[[0,1.09,1851.17],[1,1.1,2148.66],[2,1.11,3683.92]],"ltp":1.09,"tv":105114.1,"id":9323645}],"tv":119908.08}]}
{"op":"mcm","clk":"4216985551","pt":1631556926189,"mc":[{"id":"1.187566733","rc":[{"batb":[[2,1.05,4.32]],"batl":[[0,1.09,2799.38]],"ltp":1.09,"tv":105114.1,"id":9323645}]}]}
{"op":"mcm","clk":"4216985699","pt":1631556927200,"mc":[{"id":"1.187566733","rc":[{"batb":[[1,10,17.89],[2,9.2,15.37]],"ltp":11.0,"tv":14793.97,"id":8734382},{"trd":[[1.09,4326.22]],"batl":[[0,1.09,2788.34],[1,1.1,2525.66],[2,1.11,5265.26]],"ltp":1.09,"tv":105141.3,"id":9323645}],"tv":119935.28}]}
{"op":"mcm","clk":"4216985867","pt":1631556928179,"mc":[{"id":"1.187566733","rc":[{"batb":[[0,10,17.89],[1,9.2,15.37],[2,7.8,14.27]],"batl":[[0,990,0.01],[1,13.5,0],[2,14.5,0]],"ltp":11.0,"tv":14793.97,"id":8734382},{"batb":[[0,1.06,517.66],[1,1.05,4.32],[2,1.04,2.98]],"batl":[[0,1.09,3455.48],[1,1.1,1903.33],[2,1.11,2357.38]],"ltp":1.09,"tv":105141.3,"id":9323645}]}]}
{"op":"mcm","clk":"4216986014","pt":1631556929097,"mc":[{"id":"1.187566733","rc":[{"trd":[[1.08,11340.19],[1.09,4520.96]],"batl":[[0,1.09,2690.97],[1,1.1,853.38]],"ltp":1.09,"tv":105514.3,"id":9323645}],"tv":120308.27}]}
{"op":"mcm","clk":"4216986161","pt":1631556930110,"mc":[{"id":"1.187566733","rc":[{"trd":[[1.09,4546.7]],"batl":[[0,1.09,2678.1]],"ltp":1.09,"tv":105540.04,"id":9323645}],"tv":120334.01}]}
{"op":"mcm","clk":"4216986323","pt":1631556931185,"mc":[{"id":"1.187566733","rc":[{"trd":[[1.09,4573.8]],"batb":[[0,1.08,20],[1,1.07,641.78],[2,1.06,517.66]],"batl":[[0,1.09,2664.55],[2,1.11,2976.03]],"ltp":1.09,"tv":105567.14,"id":9323645}],"tv":120361.11}]}
{"op":"mcm","clk":"4216986567","pt":1631556932896,"mc":[{"id":"1.187566733","rc":[{"trd":[[1.08,11380.19]],"batb":[[0,1.07,641.78],[1,1.06,517.66],[2,1.05,4.32]],"batl":[[0,1.08,1980],[1,1.09,2664.55],[2,1.1,853.38]],"ltp":1.08,"tv":105607.14,"id":9323645}],"tv":120401.11}]}
{"op":"mcm","clk":"4216986689","pt":1631556933698,"mc":[{"id":"1.187566733","rc":[{"trd":[[1.08,11428.19]],"batl":[[0,1.08,1956]],"ltp":1.08,"tv":105655.14,"id":9323645}],"tv":120449.11}]}
{"op":"mcm","clk":"4216987067","pt":1631556935992,"mc":[{"id":"1.187566733","rc":[{"batb":[[0,1.06,517.66],[1,1.05,4.32],[2,1.04,2.98]],"batl":[[1,1.09,2.57],[2,1.11,2200.22]],"ltp":1.08,"tv":105655.14,"id":9323645}]}]}
{"op":"mcm","clk":"4216987208","pt":1631556936711,"mc":[{"id":"1.187566733","rc":[{"trd":[[1.08,11878.19]],"batl":[[0,1.08,1731]],"ltp":1.08,"tv":106105.14,"id":9323645}],"tv":120899.11}]}
{"op":"mcm","clk":"4216987418","pt":1631556938083,"mc":[{"id":"1.187566733","rc":[{"batl":[[0,12,26.31],[1,13,11.54],[2,13.5,210.45]],"ltp":11.0,"tv":14793.97,"id":8734382},{"trd":[[1.08,15340.19],[1.09,4578.93],[1.11,5559.25]],"batb":[[0,1.09,2316.07],[1,1.08,2560.99],[2,1.06,517.66]],"batl":[[0,1.11,3639.48],[1,1.12,1427.14],[2,1.13,1172.67]],"ltp":1.11,"tv":109589.97,"id":9323645}],"tv":124383.95}]}
{"op":"mcm","clk":"4216987592","pt":1631556939196,"mc":[{"id":"1.187566733","rc":[{"batl":[[1,13,2.3],[2,13.5,205.85]],"ltp":11.0,"tv":14793.97,"id":8734382},{"trd":[[1.11,5665.68]],"batb":[[0,1.09,977.99],[1,1.08,3000.63],[2,1.07,3.02]],"batl":[[0,1.11,3723.67],[1,1.12,1494.7],[2,1.13,1240.23]],"ltp":1.11,"tv":109696.4,"id":9323645}],"tv":124490.38}]}
{"op":"mcm","clk":"4216987685","pt":1631556939788,"mc":[{"id":"1.187566733","rc":[{"batb":[[0,1.09,1477.99]],"batl":[[0,1.11,3613.75],[1,1.12,2151.82],[2,1.13,1186.19]],"ltp":1.11,"tv":109696.4,"id":9323645}]}]}
{"op":"mcm","clk":"4216987814","pt":1631556940808,"mc":[{"id":"1.187566733","rc":[{"batb":[[1,1.08,3854.02]],"batl":[[0,1.11,4389.56]],"ltp":1.11,"tv":109696.4,"id":9323645}]}]}
{"op":"mcm","clk":"4216987929","pt":1631556941610,"mc":[{"id":"1.187566733","rc":[{"batb":[[0,9.2,15.37],[1,7.8,14.27],[2,7.4,16.36]],"ltp":11.0,"tv":14793.97,"id":8734382},{"batl":[[0,1.11,3645.84]],"ltp":1.11,"tv":109696.4,"id":9323645}]}]}
{"op":"mcm","clk":"4216988159","pt":1631556943094,"mc":[{"id":"1.187566733","rc":[{"batl":[[0,1.11,4642.34],[1,1.12,1440.66]],"ltp":1.11,"tv":109696.4,"id":9323645}]}]}
{"op":"mcm","clk":"4216988461","pt":1631556945134,"mc":[{"id":"1.187566733","rc":[{"batb":[[0,10,19.14],[1,9.2,15.37],[2,7.8,14.27]],"batl":[[1,12.5,2.89],[2,13,2.3]],"ltp":11.0,"tv":14793.97,"id":8734382},{"batb":[[0,1.09,2827.92],[1,1.08,4943.33],[2,1.07,1524.67]],"batl":[[0,1.1,1698.2],[1,1.11,4642.34],[2,1.12,1440.66]],"ltp":1.11,"tv":109696.4,"id":9323645}]}]}
{"op":"mcm","clk":"4216988613","pt":1631556946101,"mc":[{"id":"1.187566733","rc":[{"trd":[[11,63.27]],"ltp":11.0,"tv":14795.97,"id":8734382},{"trd":[[1.09,5727.21],[1.1,4757.03]],"batb":[[0,1.09,2150.24]],"batl":[[0,1.1,1678.2]],"ltp":1.09,"tv":110864.69,"id":9323645}],"tv":125660.66}]}
{"op":"mcm","clk":"4216988901","pt":1631556948087,"mc":[{"id":"1.187566733","rc":[{"batb":[[0,1.09,2150.43]],"batl":[[0,1.1,2492.53]],"ltp":1.09,"tv":110864.69,"id":9323645}]}]}
{"op":"mcm","clk":"4216989055","pt":1631556949102,"mc":[{"id":"1.187566733","rc":[{"batb":[[0,1.09,1903.68]],"ltp":1.09,"tv":110864.69,"id":9323645}]}]}
{"op":"mcm","clk":"4216989210","pt":1631556950120,"mc":[{"id":"1.187566733","rc":[{"batl":[[0,12.5,2.89],[1,13.5,2.63],[2,990,0.01]],"ltp":11.0,"tv":14795.97,"id":8734382},{"batb":[[0,1.09,1273.68],[1,1.08,2384.2]],"batl":[[1,1.11,2835.71],[2,1.12,1427.14]],"ltp":1.09,"tv":110864.69,"id":9323645}]}]}
{"op":"mcm","clk":"4216989291","pt":1631556950599,"mc":[{"id":"1.187566733","rc":[{"batb":[[2,7.4,16.36]],"batl":[[0,13.5,2.63],[1,990,0.01],[2,990,0]],"ltp":11.0,"tv":14795.97,"id":8734382},{"batb":[[0,1.08,2387.24],[1,1.07,1524.67],[2,1.06,2.56]],"batl":[[0,1.1,1678.2],[1,1.11,1839.21]],"ltp":1.09,"tv":110864.69,"id":9323645}]}]}
{"op":"mcm","clk":"4216989531","pt":1631556952198,"mc":[{"id":"1.187566733","rc":[{"trd":[[1.1,5757.11]],"batl":[[0,1.1,1204.78]],"ltp":1.1,"tv":111864.77,"id":9323645}],"tv":126660.74}]}
{"op":"mcm","clk":"4216989681","pt":1631556953208,"mc":[{"id":"1.187566733","rc":[{"batl":[[1,1.11,3326.78]],"ltp":1.1,"tv":111864.77,"id":9323645}]}]}
{"op":"mcm","clk":"4216989803","pt":1631556954008,"mc":[{"id":"1.187566733","rc":[{"batb":[[2,7.4,19.33]],"ltp":11.0,"tv":14795.97,"id":8734382},{"batl":[[1,1.11,1775.17]],"ltp":1.1,"tv":111864.77,"id":9323645}]}]}
{"op":"mcm","clk":"4216990107","pt":1631556956001,"mc":[{"id":"1.187566733","rc":[{"batb":[[0,1.09,630.2],[1,1.08,2387.05],[2,1.07,1524.67]],"batl":[[0,1.1,1379.92],[1,1.11,1954.1]],"ltp":1.1,"tv":111864.77,"id":9323645}]}]}
{"op":"mcm","clk":"4216990146","pt":1631556956313,"mc":[{"id":"1.187566733","rc":[{"batl":[[0,1.1,1358.27]],"ltp":1.1,"tv":111864.77,"id":9323645}]}]}
{"op":"mcm","clk":"4216990371","pt":1631556957805,"mc":[{"id":"1.187566733","rc":[{"batl":[[0,12.5,2.67],[1,13.5,2.63],[2,990,0.01]],"ltp":11.0,"tv":14795.97,"id":8734382},{"batb":[[0,1.09,1709.64]],"batl":[[0,1.1,2211.65]],"ltp":1.1,"tv":111864.77,"id":9323645}]}]}
{"op":"mcm","clk":"4216990540","pt":1631556959123,"mc":[{"id":"1.187566733","rc":[{"batl":[[0,13.5,2.63],[1,990,0.01],[2,990,0]],"ltp":11.0,"tv":14795.97,"id":8734382},{"trd":[[1.09,7567.21],[1.1,5757.62]],"batb":[[0,1.08,2387.05],[1,1.07,1524.67],[2,1.06,2.56]],"batl":[[0,1.1,3064.77]],"ltp":1.1,"tv":113705.27,"id":9323645}],"tv":128501.25}]}
{"op":"mcm","clk":"4216990608","pt":1631556959605,"mc":[{"id":"1.187566733","rc":[{"batl":[[1,1.11,1621.17]],"ltp":1.1,"tv":113705.27,"id":9323645}]}]}
{"op":"mcm","clk":"4216990725","pt":1631556960407,"mc":[{"id":"1.187566733","rc":[{"batl":[[0,1.1,3943.46]],"ltp":1.1,"tv":113705.27,"id":9323645}]}]}
{"op":"mcm","clk":"4216990997","pt":1631556962201,"mc":[{"id":"1.187566733","rc":[{"batl":[[0,12.5,2.85],[1,13.5,2.63],[2,990,0.01]],"ltp":11.0,"tv":14795.97,"id":8734382},{"batb":[[0,1.09,498.22],[1,1.08,2884.59],[2,1.07,1524.67]],"batl":[[0,1.1,4279.42]],"ltp":1.1,"tv":113705.27,"id":9323645}]}]}
{"op":"mcm","clk":"4216991048","pt":1631556962519,"mc":[{"id":"1.187566733","rc":[{"batl":[[0,13.5,2.63],[1,990,0.01],[2,990,0]],"ltp":11.0,"tv":14795.97,"id":8734382},{"trd":[[1.08,16574.54]],"batb":[[0,1.08,2085.03],[1,1.07,1524.67],[2,1.06,2.56]],"batl":[[0,1.1,2911.28]],"ltp":1.08,"tv":114939.62,"id":9323645}],"tv":129735.59}]}
{"op":"mcm","clk":"4216991597","pt":1631556965924,"mc":[{"id":"1.187566733","rc":[{"batb":[[0,1.08,2405.63]],"batl":[[1,1.11,2106.22]],"ltp":1.08,"tv":114939.62,"id":9323645}]}]}
{"op":"mcm","clk":"4216992087","pt":1631556969163,"mc":[{"id":"1.187566733","rc":[{"batl":[[0,12.5,3.39],[1,13.5,2.63],[2,990,0.01]],"ltp":11.0,"tv":14795.97,"id":8734382},{"trd":[[1.08,20574.65]],"batb":[[0,1.08,405.52],[1,1.07,3.02]],"batl":[[1,1.11,2882.03]],"ltp":1.08,"tv":118939.73,"id":9323645}],"tv":133735.7}]}
{"op":"mcm","clk":"4216992172","pt":1631556969645,"mc":[{"id":"1.187566733","rc":[{"batl":[[0,13.5,2.63],[1,990,0.01],[2,990,0]],"ltp":11.0,"tv":14795.97,"id":8734382},{"trd":[[1.1,5798.45]],"batl":[[0,1.1,2890.87]],"ltp":1.1,"tv":118980.55,"id":9323645}],"tv":133776.53}]}
{"op":"mcm","clk":"4216992521","pt":1631556972140,"mc":[{"id":"1.187566733","rc":[{"batb":[[0,1.08,1824.82],[1,1.07,1252.27]],"ltp":1.1,"tv":118980.55,"id":9323645}]}]}
{"op":"mcm","clk":"4216992650","pt":1631556973149,"mc":[{"id":"1.187566733","rc":[{"batl":[[0,12.5,2.89],[1,13.5,2.63],[2,990,0.01]],"ltp":11.0,"tv":14795.97,"id":8734382}]}]}
{"op":"mcm","clk":"4216992706","pt":1631556973524,"mc":[{"id":"1.187566733","rc":[{"batl":[[0,13.5,2.63],[1,990,0.01],[2,990,0]],"ltp":11.0,"tv":14795.97,"id":8734382}]}]}
{"op":"mcm","clk":"4216992911","pt":1631556975054,"mc":[{"id":"1.187566733","rc":[{"trd":[[1.1,6018.47]],"batl":[[0,1.1,2780.85],[1,1.11,2263.38]],"ltp":1.1,"tv":119200.57,"id":9323645}],"tv":133996.55}]}
{"op":"mcm","clk":"4216993164","pt":1631556977172,"mc":[{"id":"1.187566733","rc":[{"batb":[[0,11,18.49],[1,10.5,6.82],[2,10,25.96]],"batl":[[0,13.5,129.33]],"ltp":11.0,"tv":14795.97,"id":8734382},{"batb":[[0,1.08,3408.68]],"batl":[[0,1.1,14279.15],[1,1.11,5237.95],[2,1.12,2138.3]],"ltp":1.1,"tv":119200.57,"id":9323645}]}]}
{"op":"mcm","clk":"4216993308","pt":1631556978131,"mc":[{"id":"1.187566733","rc":[{"batb":[[0,11,90.57],[1,10.5,4.09],[2,10,23.23]],"batl":[[1,14.5,10.34],[2,15,5.16]],"ltp":11.0,"tv":14795.97,"id":8734382},{"trd":[[1.09,7692.46]],"batb":[[0,1.08,3436.03],[1,1.07,1745.29],[2,1.06,568.01]],"batl":[[0,1.09,214.38],[1,1.1,5370.78],[2,1.11,5237.95]],"ltp":1.09,"tv":119325.82,"id":9323645}],"tv":134121.8}]}
{"op":"mcm","clk":"4216993429","pt":1631556979034,"mc":[{"id":"1.187566733","rc":[{"batl":[[1,14.5,2.06],[2,15,1.04]],"ltp":11.0,"tv":14795.97,"id":8734382},{"batb":[[1,1.07,1743.42]],"batl":[[2,1.11,5238.2]],"ltp":1.09,"tv":119325.82,"id":9323645}]}]}
{"op":"mcm","clk":"4216993520","pt":1631556979729,"mc":[{"id":"1.187566733","rc":[{"batl":[[1,1.1,5370.97]],"ltp":1.09,"tv":119325.82,"id":9323645}]}]}
{"op":"mcm","clk":"4216993677","pt":1631556980946,"mc":[{"id":"1.187566733","rc":[{"batl":[[0,1.09,238.4],[1,1.1,5400.37]],"ltp":1.09,"tv":119325.82,"id":9323645}]}]}
{"op":"mcm","clk":"4216993927","pt":1631556982966,"mc":[{"id":"1.187566733","rc":[{"batb":[[0,1.08,3658.09]],"batl":[[0,1.09,2143.75],[1,1.1,6313.34]],"ltp":1.09,"tv":119325.82,"id":9323645}]}]}
{"op":"mcm","clk":"4216994089","pt":1631556984144,"mc":[{"id":"1.187566733","rc":[{"batb":[[2,1.06,2432.83]],"ltp":1.09,"tv":119325.82,"id":9323645}]}]}
{"op":"mcm","clk":"4216994369","pt":1631556986156,"mc":[{"id":"1.187566733","rc":[{"trd":[[1.08,23309.97]],"batb":[[0,1.08,2290.43]],"batl":[[0,1.09,3101.77],[1,1.1,6099.61]],"ltp":1.08,"tv":122061.14,"id":9323645}],"tv":136857.12}]}
{"op":"mcm","clk":"4216994539","pt":1631556987473,"mc":[{"id":"1.187566733","rc":[{"batl":[[1,1.1,4392.86]],"ltp":1.08,"tv":122061.14,"id":9323645}]}]}
{"op":"mcm","clk":"4216994788","pt":1631556989172,"mc":[{"id":"1.187566733","rc":[{"batb":[[0,1.08,2579.69],[1,1.07,1860.75]],"batl":[[0,1.09,3326.39],[1,1.1,3476.17],[2,1.11,4462.39]],"ltp":1.08,"tv":122061.14,"id":9323645}]}]}
{"op":"mcm","clk":"4216994997","pt":1631556990592,"mc":[{"id":"1.187566733","rc":[{"batb":[[1,1.07,1847.02]],"batl":[[0,1.09,3313]],"ltp":1.08,"tv":122061.14,"id":9323645}]}]}
{"op":"mcm","clk":"4216995154","pt":1631556991565,"mc":[{"id":"1.187566733","rc":[{"batl":[[0,1.09,3682]],"ltp":1.08,"tv":122061.14,"id":9323645}]}]}
{"op":"mcm","clk":"4216995382","pt":1631556993063,"mc":[{"id":"1.187566733","rc":[{"batb":[[0,10,19.14],[1,9.2,15.37],[2,8.2,12.17]],"batl":[[0,15.5,2.01],[1,990,0.01],[2,15,0]],"ltp":11.0,"tv":14795.97,"id":8734382},{"batb":[[0,1.07,1355.87],[1,1.06,568.01],[2,1.05,4.32]],"batl":[[0,1.09,2274.35],[1,1.1,192.33],[2,1.11,1487.82]],"ltp":1.08,"tv":122061.14,"id":9323645}]}]}
{"op":"mcm","clk":"4216995470","pt":1631556993690,"mc":[{"id":"1.187566733","rc":[{"batl":[[0,1.09,1905.35],[1,1.1,205.59]],"ltp":1.08,"tv":122061.14,"id":9323645}]}]}
{"op":"mcm","clk":"4216995760","pt":1631556995572,"mc":[{"id":"1.187566733","rc":[{"batb":[[0,1.07,1894.05]],"batl":[[1,1.1,610.22]],"ltp":1.08,"tv":122061.14,"id":9323645}]}]}
{"op":"mcm","clk":"4216996059","pt":1631556997791,"mc":[{"id":"1.187566733","rc":[{"trd":[[1.09,7897.65]],"batl":[[0,1.09,1802.75]],"ltp":1.09,"tv":122266.33,"id":9323645}],"tv":137062.31}]}
{"op":"mcm","clk":"4216997322","pt":1631557006785,"mc":[{"id":"1.187566733","rc":[{"batb":[[0,1.07,1252.27]],"batl":[[0,1.09,2.76],[1,1.1,594.5]],"ltp":1.09,"tv":122266.33,"id":9323645}]}]}
{"op":"mcm","clk":"4216997406","pt":1631557007379,"mc":[{"id":"1.187566733","rc":[{"batl":[[1,1.1,561.71]],"ltp":1.09,"tv":122266.33,"id":9323645}]}]}
{"op":"mcm","clk":"4216997681","pt":1631557009191,"mc":[{"id":"1.187566733","rc":[{"batl":[[0,12,158.77],[1,15.5,2.01],[2,990,0.01]],"ltp":11.0,"tv":14795.97,"id":8734382},{"trd":[[1.09,7903.17],[1.1,6138.04]],"batb":[[0,1.08,3754.28],[1,1.07,1321.71],[2,1.06,637.45]],"batl":[[0,1.1,501.94],[1,1.11,3039.77],[2,1.12,1427.14]],"ltp":1.1,"tv":122391.43,"id":9323645}],"tv":137187.4}]}
{"op":"mcm","clk":"4216997809","pt":1631557010121,"mc":[{"id":"1.187566733","rc":[{"batb":[[0,10.5,7.14],[1,10,22.71],[2,9.8,3.57]],"ltp":11.0,"tv":14795.97,"id":8734382},{"batb":[[0,1.09,360.28],[1,1.08,1257.82],[2,1.07,1293.93]],"batl":[[1,1.11,3042.02]],"ltp":1.1,"tv":122391.43,"id":9323645}]}]}
{"op":"mcm","clk":"4216997930","pt":1631557011008,"mc":[{"id":"1.187566733","rc":[{"batb":[[0,10.5,2.86],[1,10,20.56],[2,9.8,1.42]],"ltp":11.0,"tv":14795.97,"id":8734382},{"batb":[[0,1.09,393.54],[1,1.08,1202.27],[2,1.07,1266.15]],"batl":[[1,1.11,3040.22]],"ltp":1.1,"tv":122391.43,"id":9323645}]}]}
{"op":"mcm","clk":"4216998002","pt":1631557011379,"mc":[{"id":"1.187566733","rc":[{"batb":[[0,1.09,290.95]],"ltp":1.1,"tv":122391.43,"id":9323645}]}]}
{"op":"mcm","clk":"4216998196","pt":1631557012774,"mc":[{"id":"1.187566733","rc":[{"batb":[[0,1.09,309.55]],"batl":[[0,1.1,516.75],[1,1.11,3137.03]],"ltp":1.1,"tv":122391.43,"id":9323645}]}]}
{"op":"mcm","clk":"4216998384","pt":1631557014210,"mc":[{"id":"1.187566733","rc":[{"trd":[[12,158.77]],"batl":[[0,15.5,2.01],[1,990,0.01],[2,990,0]],"ltp":12.0,"tv":14954.74,"id":8734382},{"trd":[[1.09,10943.95]],"batb":[[0,1.08,1202.27],[1,1.07,1266.15],[2,1.06,524.82]],"batl":[[0,1.09,114.09],[1,1.1,1512.97],[2,1.11,3040.22]],"ltp":1.09,"tv":125432.21,"id":9323645}],"tv":140386.95}]}
{"op":"mcm","clk":"4216998817","pt":1631557017204,"mc":[{"id":"1.187566733","rc":[{"trd":[[1.09,11172.11]],"batb":[[0,1.09,31.04],[1,1.08,1316.48],[2,1.07,1266.15]],"batl":[[0,1.1,1610.67],[1,1.11,3040.22],[2,1.12,1427.14]],"ltp":1.09,"tv":125660.37,"id":9323645}],"tv":140615.11}]}
{"op":"mcm","clk":"4216998873","pt":1631557017585,"mc":[{"id":"1.187566733","rc":[{"batb":[[1,1.08,1202.27]],"ltp":1.09,"tv":125660.37,"id":9323645}]}]}
{"op":"mcm","clk":"4216999146","pt":1631557019512,"mc":[{"id":"1.187566733","rc":[{"batb":[[0,1.09,75.72]],"ltp":1.09,"tv":125660.37,"id":9323645}]}]}
{"op":"mcm","clk":"4216999346","pt":1631557021017,"mc":[{"id":"1.187566733","rc":[{"batb":[[0,1.09,133.35],[1,1.08,927.8]],"ltp":1.09,"tv":125660.37,"id":9323645}]}]}
{"op":"mcm","clk":"4216999406","pt":1631557021424,"mc":[{"id":"1.187566733","rc":[{"batb":[[1,1.08,930.86]],"ltp":1.09,"tv":125660.37,"id":9323645}]}]}
{"op":"mcm","clk":"4216999600","pt":1631557022846,"mc":[{"id":"1.187566733","rc":[{"batb":[[0,1.09,150.63]],"ltp":1.09,"tv":125660.37,"id":9323645}]}]}
{"op":"mcm","clk":"4216999755","pt":1631557023927,"mc":[{"id":"1.187566733","rc":[{"batb":[[1,1.08,1091.26]],"batl":[[1,1.11,2922.37]],"ltp":1.09,"tv":125660.37,"id":9323645}]}]}
{"op":"mcm","clk":"4217000069","pt":1631557026025,"mc":[{"id":"1.187566733","rc":[{"batl":[[0,1.1,2464.04]],"ltp":1.09,"tv":125660.37,"id":9323645}]}]}
{"op":"mcm","clk":"4217000197","pt":1631557026817,"mc":[{"id":"1.187566733","rc":[{"batb":[[0,11,5.65],[1,10.5,2.86],[2,10,20.56]],"batl":[[0,13.5,6.78],[1,15.5,2.01],[2,990,0.01]],"ltp":12.0,"tv":14954.74,"id":8734382},{"batb":[[1,1.08,1175.98]],"batl":[[0,1.1,2520.54]],"ltp":1.09,"tv":125660.37,"id":9323645}]}]}
{"op":"mcm","clk":"4217000342","pt":1631557027724,"mc":[{"id":"1.187566733","rc":[{"trd":[[1.09,11179.07]],"batb":[[0,1.09,147.15]],"batl":[[0,1.1,2871.54]],"ltp":1.09,"tv":125667.32,"id":9323645}],"tv":140622.07}]}
{"op":"mcm","clk":"4217001037","pt":1631557032420,"mc":[{"id":"1.187566733","rc":[{"batl":[[0,1.1,3724.92]],"ltp":1.09,"tv":125667.32,"id":9323645}]}]}
{"op":"mcm","clk":"4217002238","pt":1631557041209,"mc":[{"id":"1.187566733","rc":[{"batb":[[0,9.2,15.37],[1,8.6,31.49],[2,8.2,12.17]],"batl":[[0,15.5,2.01],[1,990,0.01],[2,990,0]],"ltp":12.0,"tv":14954.74,"id":8734382},{"batb":[[0,1.08,446.33],[1,1.07,3.02],[2,1.06,510.94]],"batl":[[0,1.1,3054.17],[1,1.12,1427.39],[2,1.13,1172.67]],"ltp":1.09,"tv":125667.32,"id":9323645}]}]}
{"op":"mcm","clk":"4217002250","pt":1631557041321,"mc":[{"id":"1.187566733","rc":[{"batb":[[2,7.4,2.97]],"ltp":12.0,"tv":14954.74,"id":8734382},{"batb":[[0,1.08,3.06]],"batl":[[0,1.1,2057.95]],"ltp":1.09,"tv":125667.32,"id":9323645}]}]}
{"op":"mcm","clk":"4217002434","pt":1631557042638,"mc":[{"id":"1.187566733","rc":[{"batb":[[2,7.2,17.54]],"ltp":12.0,"tv":14954.74,"id":8734382},{"batl":[[0,1.1,1706.95]],"ltp":1.09,"tv":125667.32,"id":9323645}]}]}
{"op":"mcm","clk":"4217002653","pt":1631557044134,"mc":[{"id":"1.187566733","rc":[{"batb":[[1,1.07,634.49]],"batl":[[1,1.12,1920.39],[2,1.13,1281.97]],"ltp":1.09,"tv":125667.32,"id":9323645}]}]}
{"op":"mcm","clk":"4217002833","pt":1631557045432,"mc":[{"id":"1.187566733","rc":[{"batb":[[0,10,2.2],[1,9.2,15.37],[2,8.6,31.49]],"ltp":12.0,"tv":14954.74,"id":8734382},{"trd":[[1.1,6222.04]],"batl":[[0,1.1,1664.95]],"ltp":1.1,"tv":125751.33,"id":9323645}],"tv":140706.07}]}
{"op":"mcm","clk":"4217003303","pt":1631557049165,"mc":[{"id":"1.187566733","rc":[{"batb":[[1,8.6,31.49],[2,7.2,17.54]],"ltp":12.0,"tv":14954.74,"id":8734382},{"batb":[[1,1.07,3.02]],"batl":[[1,1.12,493.48]],"ltp":1.1,"tv":125751.33,"id":9323645}]}]}
{"op":"mcm","clk":"4217003373","pt":1631557049649,"mc":[{"id":"1.187566733","rc":[{"batl":[[0,1.12,493.48],[1,1.13,1281.97],[2,1.14,1889.48]],"ltp":1.1,"tv":125751.33,"id":9323645}]}]}
{"op":"mcm","clk":"4217003739","pt":1631557052160,"mc":[{"id":"1.187566733","rc":[{"batl":[[0,10.5,8.57],[1,11,10.08],[2,11.5,4.28]],"ltp":12.0,"tv":14954.74,"id":8734382},{"trd":[[1.11,5666.18],[1.12,9571.48]],"batb":[[0,1.11,159.54],[1,1.1,972.47],[2,1.08,4262.54]],"batl":[[0,1.12,536.66],[1,1.13,3649.23]],"ltp":1.12,"tv":125873.12,"id":9323645}],"tv":140827.86}]}
{"op":"mcm","clk":"4217003838","pt":1631557052845,"mc":[{"id":"1.187566733","rc":[{"batl":[[0,10.5,2.86],[1,11,7.22],[2,11.5,1.42]],"ltp":12.0,"tv":14954.74,"id":8734382},{"batb":[[1,1.1,1292.14],[2,1.08,4683.9]],"batl":[[1,1.13,3676.21],[2,1.14,1902.76]],"ltp":1.12,"tv":125873.12,"id":9323645}]}]}
{"op":"mcm","clk":"4217003986","pt":1631557053963,"mc":[{"id":"1.187566733","rc":[{"batl":[[0,1.12,1247.81]],"ltp":1.12,"tv":125873.12,"id":9323645}]}]}
{"op":"mcm","clk":"4217004091","pt":1631557054757,"mc":[{"id":"1.187566733","rc":[{"batl":[[0,1.12,1958.97]],"ltp":1.12,"tv":125873.12,"id":9323645}]}]}
{"op":"mcm","clk":"4217004290","pt":1631557056144,"mc":[{"id":"1.187566733","rc":[{"trd":[[10,3.33]],"batb":[[0,10,1.51]],"ltp":10.0,"tv":14956.12,"id":8734382},{"trd":[[1.12,9582.86]],"batb":[[0,1.11,193.47],[2,1.08,4680.84]],"batl":[[0,1.12,1980.3],[1,1.13,3709.1],[2,1.14,1902.52]],"ltp":1.12,"tv":125884.5,"id":9323645}],"tv":140840.62}]}
{"op":"mcm","clk":"4217004412","pt":1631557057140,"mc":[{"id":"1.187566733","rc":[{"batl":[[0,1.12,2656.99]],"ltp":1.12,"tv":125884.5,"id":9323645}]}]}
{"op":"mcm","clk":"4217004572","pt":1631557058466,"mc":[{"id":"1.187566733","rc":[{"batb":[[2,7.2,53.96]],"ltp":10.0,"tv":14956.12,"id":8734382}]}]}
{"op":"mcm","clk":"4217004787","pt":1631557060172,"mc":[{"id":"1.187566733","rc":[{"batb":[[1,1.1,1397.45]],"ltp":1.12,"tv":125884.5,"id":9323645}]}]}
{"op":"mcm","clk":"4217004846","pt":1631557060540,"mc":[{"id":"1.187566733","rc":[{"trd":[[1.11,5669.6]],"batb":[[0,1.11,191.77]],"batl":[[0,1.12,3020.99]],"ltp":1.11,"tv":125887.91,"id":9323645}],"tv":140844.03}]}
{"op":"mcm","clk":"4217005039","pt":1631557061861,"mc":[{"id":"1.187566733","rc":[{"batb":[[1,1.1,1292.14]],"batl":[[0,1.12,3732.14]],"ltp":1.11,"tv":125887.91,"id":9323645}]}]}
{"op":"mcm","clk":"4217005211","pt":1631557063079,"mc":[{"id":"1.187566733","rc":[{"trd":[[1.1,7838.54],[1.11,6053.11]],"batb":[[0,1.1,483.89],[1,1.08,4680.84],[2,1.05,1.71]],"ltp":1.1,"tv":127887.93,"id":9323645}],"tv":142844.05}]}
{"op":"mcm","clk":"4217005281","pt":1631557063692,"mc":[{"id":"1.187566733","rc":[{"batl":[[0,1.12,3368.14],[1,1.13,3566.71]],"ltp":1.1,"tv":127887.93,"id":9323645}]}]}
{"op":"mcm","clk":"4217005450","pt":1631557064873,"mc":[{"id":"1.187566733","rc":[{"trd":[[1.12,9583.26]],"batl":[[0,1.12,3367.94]],"ltp":1.12,"tv":127888.33,"id":9323645}],"tv":142844.45}]}
{"op":"mcm","clk":"4217005625","pt":1631557066181,"mc":[{"id":"1.187566733","rc":[{"batb":[[0,8.6,31.49],[1,7.2,53.96],[2,6.4,36.76]],"ltp":10.0,"tv":14956.12,"id":8734382},{"trd":[[1.12,9790.06]],"batl":[[0,1.12,3264.55]],"ltp":1.12,"tv":128095.12,"id":9323645}],"tv":143051.24}]}
{"op":"mcm","clk":"4217005714","pt":1631557066765,"mc":[{"id":"1.187566733","rc":[{"batb":[[0,1.1,969.98]],"batl":[[0,1.11,1195],[1,1.12,3413.9],[2,1.13,3566.71]],"ltp":1.12,"tv":128095.12,"id":9323645}]}]}
{"op":"mcm","clk":"4217006077","pt":1631557069167,"mc":[{"id":"1.187566733","rc":[{"trd":[[10.5,2.88]],"batl":[[0,10.5,1.42]],"ltp":10.5,"tv":14959.0,"id":8734382}],"tv":143054.12}]}
{"op":"mcm","clk":"4217006221","pt":1631557070186,"mc":[{"id":"1.187566733","rc":[{"batl":[[0,15.5,2.01],[1,990,0.01],[2,11.5,0]],"ltp":10.5,"tv":14959.0,"id":8734382},{"batb":[[1,1.08,421.36]],"batl":[[0,1.11,1944.58],[1,1.12,3413.43],[2,1.13,1172.47]],"ltp":1.12,"tv":128095.12,"id":9323645}]}]}
{"op":"mcm","clk":"4217006372","pt":1631557071198,"mc":[{"id":"1.187566733","rc":[{"batb":[[0,7.2,36.42],[1,6.4,36.76],[2,6,26.43]],"batl":[[0,990,0.01],[1,990,0]],"ltp":10.5,"tv":14959.0,"id":8734382},{"batb":[[0,1.08,418],[1,1.05,1.71],[2,1.05,0]],"batl":[[0,1.12,2133.46],[1,1.16,2007.69],[2,1.17,2118.93]],"ltp":1.12,"tv":128095.12,"id":9323645}]}]}
{"op":"mcm","clk":"4217006399","pt":1631557071381,"mc":[{"id":"1.187566733","rc":[{"batb":[[0,1.08,418.2]],"ltp":1.12,"tv":128095.12,"id":9323645}]}]}
{"op":"mcm","clk":"4217006694","pt":1631557073587,"mc":[{"id":"1.187566733","rc":[{"batb":[[0,1.09,512.56],[1,1.08,526.52],[2,1.05,1.71]],"batl":[[1,1.15,587.54],[2,1.16,2007.69]],"ltp":1.12,"tv":128095.12,"id":9323645}]}]}
{"op":"mcm","clk":"4217006931","pt":1631557075201,"mc":[{"id":"1.187566733","rc":[{"batb":[[0,1.08,418.2],[1,1.05,1.71],[2,1.05,0]],"batl":[[1,1.15,568.92]],"ltp":1.12,"tv":128095.12,"id":9323645}]}]}
{"op":"mcm","clk":"4217007050","pt":1631557076006,"mc":[{"id":"1.187566733","rc":[{"batl":[[1,1.15,1137.84]],"ltp":1.12,"tv":128095.12,"id":9323645}]}]}
{"op":"mcm","clk":"4217007351","pt":1631557078204,"mc":[{"id":"1.187566733","rc":[{"batb":[[0,8.6,21.24],[1,7.2,36.42],[2,6.4,36.76]],"batl":[[0,9.4,20.49],[1,990,0.01]],"ltp":10.5,"tv":14959.0,"id":8734382},{"batb":[[0,1.11,457.23],[1,1.1,153.06],[2,1.08,418]],"batl":[[0,1.12,2332.76],[1,1.13,420.9],[2,1.15,1137.84]],"ltp":1.12,"tv":128095.12,"id":9323645}]}]}
{"op":"mcm","clk":"4217007454","pt":1631557079006,"mc":[{"id":"1.187566733","rc":[{"batb":[[0,7.2,36.42],[1,6.4,36.76],[2,6,26.43]],"batl":[[0,990,0.01],[1,990,0]],"ltp":10.5,"tv":14959.0,"id":8734382},{"batb":[[0,1.08,418.2],[1,1.05,1.71],[2,1.08,0]],"batl":[[0,1.12,2197.46],[1,1.15,1137.84],[2,1.16,2007.69]],"ltp":1.12,"tv":128095.12,"id":9323645}]}]}
{"op":"mcm","clk":"4217007591","pt":1631557080005,"mc":[{"id":"1.187566733","rc":[{"trd":[[9.2,30.74]],"ltp":9.2,"tv":14963.27,"id":8734382},{"trd":[[1.12,9825.55]],"batl":[[0,1.12,2098.17]],"ltp":1.12,"tv":128130.62,"id":9323645}],"tv":143093.89}]}
{"op":"mcm","clk":"4217007899","pt":1631557081999,"mc":[{"id":"1.187566733","rc":[{"batb":[[0,1.09,512.56],[1,1.08,526.52],[2,1.05,1.71]],"batl":[[1,1.15,1725.38]],"ltp":1.12,"tv":128130.62,"id":9323645}]}]}
{"op":"mcm","clk":"4217008717","pt":1631557088113,"mc":[{"id":"1.187566733","rc":[{"batl":[[1,1.15,1137.84]],"ltp":1.12,"tv":128130.62,"id":9323645}]}]}
{"op":"mcm","clk":"4217008986","pt":1631557089831,"mc":[{"id":"1.187566733","rc":[{"trd":[[1.12,9825.95]],"batl":[[0,1.12,2097.97]],"ltp":1.12,"tv":128131.01,"id":9323645}],"tv":143094.29}]}
{"op":"mcm","clk":"4217009209","pt":1631557091208,"mc":[{"id":"1.187566733","rc":[{"batb":[[0,11,5.91],[1,10,113.59],[2,9.4,21.28]],"batl":[[0,13.5,183.62],[1,990,0.01]],"ltp":9.2,"tv":14963.27,"id":8734382},{"trd":[[1.11,6053.51]],"batb":[[0,1.09,566.56],[1,1.08,2821.71],[2,1.07,27.61]],"batl":[[0,1.1,412.07],[1,1.11,8615.76],[2,1.12,2111.49]],"ltp":1.11,"tv":128131.41,"id":9323645}],"tv":143094.69}]}
{"op":"mcm","clk":"4217009317","pt":1631557092018,"mc":[{"id":"1.187566733","rc":[{"trd":[[1.1,7856.24]],"batb":[[1,1.08,2962.91],[2,1.07,582.86]],"batl":[[0,1.1,403.22],[1,1.11,5208.01]],"ltp":1.1,"tv":128149.11,"id":9323645}],"tv":143112.39}]}
