{"op":"mcm","clk":"4229490600","pt":1631518387105,"mc":[{"id":"1.187594321","marketDefinition":{"bspMarket":false,"turnInPlayEnabled":true,"persistenceEnabled":true,"marketBaseRate":5.0,"eventId":"30897905","eventTypeId":"2","numberOfWinners":1,"bettingType":"ODDS","marketType":"MATCH_ODDS","marketTime":"2021-09-13T09:00:00.000Z","suspendTime":"2021-09-13T09:00:00.000Z","bspReconciled":false,"complete":true,"inPlay":false,"crossMatching":false,"runnersVoidable":false,"numberOfActiveRunners":2,"betDelay":0,"status":"OPEN","runners":[{"status":"ACTIVE","sortPriority":1,"id":8679184,"name":"I Rosca"},{"status":"ACTIVE","sortPriority":2,"id":11862899,"name":"C Cervino Ruiz"}],"regulators":["MR_INT"],"countryCode":"GB","discountAllowed":false,"timezone":"GMT","openDate":"2021-09-13T12:00:00.000Z","version":4030164797,"name":"Match Odds","eventName":"I Rosca v C Cervino Ruiz"},"rc":[{"batb":[[0,1.01,25]],"ltp":0.0,"tv":0.0,"id":11862899},{"batb":[[0,1.01,25]],"ltp":0.0,"tv":0.0,"id":8679184}]}]}
{"op":"mcm","clk":"4229490651","pt":1631518388647,"mc":[{"id":"1.187594321","marketDefinition":{"bspMarket":false,"turnInPlayEnabled":true,"persistenceEnabled":true,"marketBaseRate":5.0,"eventId":"30897905","eventTypeId":"2","numberOfWinners":1,"bettingType":"ODDS","marketType":"MATCH_ODDS","marketTime":"2021-09-13T09:00:00.000Z","suspendTime":"2021-09-13T09:00:00.000Z","bspReconciled":false,"complete":true,"inPlay":false,"crossMatching":false,"runnersVoidable":false,"numberOfActiveRunners":2,"betDelay":0,"status":"OPEN","runners":[{"status":"ACTIVE","sortPriority":1,"id":8679184,"name":"I Rosca"},{"status":"ACTIVE","sortPriority":2,"id":11862899,"name":"C Cervino Ruiz"}],"regulators":["MR_INT"],"countryCode":"GB","discountAllowed":true,"timezone":"GMT","openDate":"2021-09-13T12:00:00.000Z","version":4030164797,"name":"Match Odds","eventName":"I Rosca v C Cervino Ruiz"}}]}
{"op":"mcm","clk":"4229517264","pt":1631519122673,"mc":[{"id":"1.187594321","rc":[{"batb":[[0,1.01,7]],"ltp":0.0,"tv":0.0,"id":11862899},{"batb":[[0,1.01,7]],"ltp":0.0,"tv":0.0,"id":8679184}]}]}
{"op":"mcm","clk":"4229527860","pt":1631519431726,"mc":[{"id":"1.187594321","rc":[{"batb":[[0,1.05,880.88],[1,1.01,7]],"ltp":0.0,"tv":0.0,"id":11862899},{"batb":[[0,1.05,880.88],[1,1.01,7]],"ltp":0.0,"tv":0.0,"id":8679184}]}]}
{"op":"mcm","clk":"4229679419","pt":1631522468900,"mc":[{"id":"1.187594321","rc":[{"batl":[[0,2.3,2.66]],"ltp":0.0,"tv":0.0,"id":8679184}]}]}
{"op":"mcm","clk":"4229679617","pt":1631522474366,"mc":[{"id":"1.187594321","rc":[{"batb":[[0,1.2,13.31],[1,1.05,880.88],[2,1.01,7]],"ltp":0.0,"tv":0.0,"id":8679184}]}]}
{"op":"mcm","clk":"4229689758","pt":1631522694770,"mc":[{"id":"1.187594321","rc":[{"batb":[[1,1.01,7],[2,1.01,0]],"ltp":0.0,"tv":0.0,"id":8679184}]}]}
{"op":"mcm","clk":"4229690002","pt":1631522700701,"mc":[{"id":"1.187594321","rc":[{"batb":[[0,1.22,195.55],[1,1.2,13.31],[2,1.01,7]],"ltp":0.0,"tv":0.0,"id":8679184}]}]}
{"op":"mcm","clk":"4229693159","pt":1631522762130,"mc":[{"id":"1.187594321","marketDefinition":{"bspMarket":false,"turnInPlayEnabled":true,"persistenceEnabled":true,"marketBaseRate":5.0,"eventId":"30897905","eventTypeId":"2","numberOfWinners":1,"bettingType":"ODDS","marketType":"MATCH_ODDS","marketTime":"2021-09-13T14:00:00.000Z","suspendTime":"2021-09-13T14:00:00.000Z","bspReconciled":false,"complete":true,"inPlay":false,"crossMatching":false,"runnersVoidable":false,"numberOfActiveRunners":2,"betDelay":0,"status":"OPEN","runners":[{"status":"ACTIVE","sortPriority":1,"id":8679184,"name":"I Rosca"},{"status":"ACTIVE","sortPriority":2,"id":11862899,"name":"C Cervino Ruiz"}],"regulators":["MR_INT"],"countryCode":"GB","discountAllowed":true,"timezone":"GMT","openDate":"2021-09-13T12:00:00.000Z","version":4030340768,"name":"Match Odds","eventName":"I Rosca v C Cervino Ruiz"}}]}
{"op":"mcm","clk":"4229693274","pt":1631522764139,"mc":[{"id":"1.187594321","marketDefinition":{"bspMarket":false,"turnInPlayEnabled":true,"persistenceEnabled":true,"marketBaseRate":5.0,"eventId":"30897905","eventTypeId":"2","numberOfWinners":1,"bettingType":"ODDS","marketType":"MATCH_ODDS","marketTime":"2021-09-13T14:00:00.000Z","suspendTime":"2021-09-13T14:00:00.000Z","bspReconciled":false,"complete":true,"inPlay":false,"crossMatching":false,"runnersVoidable":false,"numberOfActiveRunners":2,"betDelay":0,"status":"OPEN","runners":[{"status":"ACTIVE","sortPriority":1,"id":8679184,"name":"I Rosca"},{"status":"ACTIVE","sortPriority":2,"id":11862899,"name":"C Cervino Ruiz"}],"regulators":["MR_INT"],"countryCode":"GB","discountAllowed":true,"timezone":"GMT","openDate":"2021-09-13T14:00:00.000Z","version":4030340768,"name":"Match Odds","eventName":"I Rosca v C Cervino Ruiz"}}]}
{"op":"mcm","clk":"4229736952","pt":1631523664163,"mc":[{"id":"1.187594321","rc":[{"batb":[[0,2.24,25.26],[1,1.05,880.36],[2,1.01,7]],"ltp":0.0,"tv":0.0,"id":11862899},{"batb":[[0,1.57,54.95],[1,1.22,195.44],[2,1.2,13.32]],"batl":[[0,2.3,2.66]],"ltp":0.0,"tv":0.0,"id":8679184}]}]}
{"op":"mcm","clk":"4229737268","pt":1631523670683,"mc":[{"id":"1.187594321","marketDefinition":{"bspMarket":false,"turnInPlayEnabled":true,"persistenceEnabled":true,"marketBaseRate":5.0,"eventId":"30897905","eventTypeId":"2","numberOfWinners":1,"bettingType":"ODDS","marketType":"MATCH_ODDS","marketTime":"2021-09-13T14:00:00.000Z","suspendTime":"2021-09-13T14:00:00.000Z","bspReconciled":false,"complete":true,"inPlay":false,"crossMatching":true,"runnersVoidable":false,"numberOfActiveRunners":2,"betDelay":0,"status":"OPEN","runners":[{"status":"ACTIVE","sortPriority":1,"id":8679184,"name":"I Rosca"},{"status":"ACTIVE","sortPriority":2,"id":11862899,"name":"C Cervino Ruiz"}],"regulators":["MR_INT"],"countryCode":"GB","discountAllowed":true,"timezone":"GMT","openDate":"2021-09-13T14:00:00.000Z","version":4030340768,"name":"Match Odds","eventName":"I Rosca v C Cervino Ruiz"}}]}
{"op":"mcm","clk":"4229776933","pt":1631524352186,"mc":[{"id":"1.187594321","rc":[{"batl":[[0,990,2.2]],"ltp":0.0,"tv":0.0,"id":11862899},{"batl":[[1,990,2.2]],"ltp":0.0,"tv":0.0,"id":8679184}]}]}
{"op":"mcm","clk":"4229794641","pt":1631524649519,"mc":[{"id":"1.187594321","rc":[{"batl":[[2,1000,2.51]],"ltp":0.0,"tv":0.0,"id":8679184}]}]}
{"op":"mcm","clk":"4229795054","pt":1631524656825,"mc":[{"id":"1.187594321","rc":[{"batl":[[2,1000,3.35]],"ltp":0.0,"tv":0.0,"id":8679184}]}]}
{"op":"mcm","clk":"4229795315","pt":1631524661406,"mc":[{"id":"1.187594321","rc":[{"batl":[[2,1000,0.84]],"ltp":0.0,"tv":0.0,"id":8679184}]}]}
{"op":"mcm","clk":"4229795797","pt":1631524671423,"mc":[{"id":"1.187594321","rc":[{"trd":[[1.57,1.68]],"batb":[[0,1.57,54.11]],"batl":[[2,1000,0]],"ltp":1.57,"tv":1.67,"id":8679184}],"tv":1.67}]}
{"op":"mcm","clk":"4229796092","pt":1631524676332,"mc":[{"id":"1.187594321","rc":[{"batb":[[0,1.57,54.95]],"ltp":1.57,"tv":1.67,"id":8679184}]}]}
{"op":"mcm","clk":"4229881530","pt":1631526086028,"mc":[{"id":"1.187594321","marketDefinition":{"bspMarket":false,"turnInPlayEnabled":true,"persistenceEnabled":true,"marketBaseRate":5.0,"eventId":"30897905","eventTypeId":"2","numberOfWinners":1,"bettingType":"ODDS","marketType":"MATCH_ODDS","marketTime":"2021-09-13T14:10:00.000Z","suspendTime":"2021-09-13T14:10:00.000Z","bspReconciled":false,"complete":true,"inPlay":false,"crossMatching":true,"runnersVoidable":false,"numberOfActiveRunners":2,"betDelay":0,"status":"OPEN","runners":[{"status":"ACTIVE","sortPriority":1,"id":8679184,"name":"I Rosca"},{"status":"ACTIVE","sortPriority":2,"id":11862899,"name":"C Cervino Ruiz"}],"regulators":["MR_INT"],"countryCode":"GB","discountAllowed":true,"timezone":"GMT","openDate":"2021-09-13T14:00:00.000Z","version":4030511782,"name":"Match Odds","eventName":"I Rosca v C Cervino Ruiz"}}]}
{"op":"mcm","clk":"4229881987","pt":1631526089043,"mc":[{"id":"1.187594321","marketDefinition":{"bspMarket":false,"turnInPlayEnabled":true,"persistenceEnabled":true,"marketBaseRate":5.0,"eventId":"30897905","eventTypeId":"2","numberOfWinners":1,"bettingType":"ODDS","marketType":"MATCH_ODDS","marketTime":"2021-09-13T14:10:00.000Z","suspendTime":"2021-09-13T14:10:00.000Z","bspReconciled":false,"complete":true,"inPlay":false,"crossMatching":true,"runnersVoidable":false,"numberOfActiveRunners":2,"betDelay":0,"status":"OPEN","runners":[{"status":"ACTIVE","sortPriority":1,"id":8679184,"name":"I Rosca"},{"status":"ACTIVE","sortPriority":2,"id":11862899,"name":"C Cervino Ruiz"}],"regulators":["MR_INT"],"countryCode":"GB","discountAllowed":true,"timezone":"GMT","openDate":"2021-09-13T14:10:00.000Z","version":4030511782,"name":"Match Odds","eventName":"I Rosca v C Cervino Ruiz"}}]}
{"op":"mcm","clk":"4230167020","pt":1631529804853,"mc":[{"id":"1.187594321","marketDefinition":{"bspMarket":false,"turnInPlayEnabled":true,"persistenceEnabled":true,"marketBaseRate":5.0,"eventId":"30897905","eventTypeId":"2","numberOfWinners":1,"bettingType":"ODDS","marketType":"MATCH_ODDS","marketTime":"2021-09-13T14:00:00.000Z","suspendTime":"2021-09-13T14:00:00.000Z","bspReconciled":false,"complete":true,"inPlay":false,"crossMatching":true,"runnersVoidable":false,"numberOfActiveRunners":2,"betDelay":0,"status":"OPEN","runners":[{"status":"ACTIVE","sortPriority":1,"id":8679184,"name":"I Rosca"},{"status":"ACTIVE","sortPriority":2,"id":11862899,"name":"C Cervino Ruiz"}],"regulators":["MR_INT"],"countryCode":"GB","discountAllowed":true,"timezone":"GMT","openDate":"2021-09-13T14:10:00.000Z","version":4030552802,"name":"Match Odds","eventName":"I Rosca v C Cervino Ruiz"}}]}
{"op":"mcm","clk":"4230167214","pt":1631529806864,"mc":[{"id":"1.187594321","marketDefinition":{"bspMarket":false,"turnInPlayEnabled":true,"persistenceEnabled":true,"marketBaseRate":5.0,"eventId":"30897905","eventTypeId":"2","numberOfWinners":1,"bettingType":"ODDS","marketType":"MATCH_ODDS","marketTime":"2021-09-13T14:00:00.000Z","suspendTime":"2021-09-13T14:00:00.000Z","bspReconciled":false,"complete":true,"inPlay":false,"crossMatching":true,"runnersVoidable":false,"numberOfActiveRunners":2,"betDelay":0,"status":"OPEN","runners":[{"status":"ACTIVE","sortPriority":1,"id":8679184,"name":"I Rosca"},{"status":"ACTIVE","sortPriority":2,"id":11862899,"name":"C Cervino Ruiz"}],"regulators":["MR_INT"],"countryCode":"GB","discountAllowed":true,"timezone":"GMT","openDate":"2021-09-13T14:00:00.000Z","version":4030552802,"name":"Match Odds","eventName":"I Rosca v C Cervino Ruiz"}}]}
{"op":"mcm","clk":"4230305922","pt":1631531508208,"mc":[{"id":"1.187594321","marketDefinition":{"bspMarket":false,"turnInPlayEnabled":true,"persistenceEnabled":true,"marketBaseRate":5.0,"eventId":"30897905","eventTypeId":"2","numberOfWinners":1,"bettingType":"ODDS","marketType":"MATCH_ODDS","marketTime":"2021-09-13T14:10:00.000Z","suspendTime":"2021-09-13T14:10:00.000Z","bspReconciled":false,"complete":true,"inPlay":false,"crossMatching":true,"runnersVoidable":false,"numberOfActiveRunners":2,"betDelay":0,"status":"OPEN","runners":[{"status":"ACTIVE","sortPriority":1,"id":8679184,"name":"I Rosca"},{"status":"ACTIVE","sortPriority":2,"id":11862899,"name":"C Cervino Ruiz"}],"regulators":["MR_INT"],"countryCode":"GB","discountAllowed":true,"timezone":"GMT","openDate":"2021-09-13T14:00:00.000Z","version":4030580020,"name":"Match Odds","eventName":"I Rosca v C Cervino Ruiz"}}]}
{"op":"mcm","clk":"4230306179","pt":1631531511221,"mc":[{"id":"1.187594321","marketDefinition":{"bspMarket":false,"turnInPlayEnabled":true,"persistenceEnabled":true,"marketBaseRate":5.0,"eventId":"30897905","eventTypeId":"2","numberOfWinners":1,"bettingType":"ODDS","marketType":"MATCH_ODDS","marketTime":"2021-09-13T14:10:00.000Z","suspendTime":"2021-09-13T14:10:00.000Z","bspReconciled":false,"complete":true,"inPlay":false,"crossMatching":true,"runnersVoidable":false,"numberOfActiveRunners":2,"betDelay":0,"status":"OPEN","runners":[{"status":"ACTIVE","sortPriority":1,"id":8679184,"name":"I Rosca"},{"status":"ACTIVE","sortPriority":2,"id":11862899,"name":"C Cervino Ruiz"}],"regulators":["MR_INT"],"countryCode":"GB","discountAllowed":true,"timezone":"GMT","openDate":"2021-09-13T14:10:00.000Z","version":4030580020,"name":"Match Odds","eventName":"I Rosca v C Cervino Ruiz"}}]}
{"op":"mcm","clk":"4230341878","pt":1631531865779,"mc":[{"id":"1.187594321","rc":[{"batb":[[1,1.05,879.51]],"ltp":0.0,"tv":0.0,"id":11862899},{"batb":[[1,1.22,195.25],[2,1.2,13.29]],"batl":[[0,2.3,2.66]],"ltp":1.57,"tv":1.67,"id":8679184}]}]}
{"op":"mcm","clk":"4230584277","pt":1631534545650,"mc":[{"id":"1.187594321","marketDefinition":{"bspMarket":false,"turnInPlayEnabled":true,"persistenceEnabled":true,"marketBaseRate":5.0,"eventId":"30897905","eventTypeId":"2","numberOfWinners":1,"bettingType":"ODDS","marketType":"MATCH_ODDS","marketTime":"2021-09-13T14:00:00.000Z","suspendTime":"2021-09-13T14:00:00.000Z","bspReconciled":false,"complete":true,"inPlay":false,"crossMatching":true,"runnersVoidable":false,"numberOfActiveRunners":2,"betDelay":0,"status":"OPEN","runners":[{"status":"ACTIVE","sortPriority":1,"id":8679184,"name":"I Rosca"},{"status":"ACTIVE","sortPriority":2,"id":11862899,"name":"C Cervino Ruiz"}],"regulators":["MR_INT"],"countryCode":"GB","discountAllowed":true,"timezone":"GMT","openDate":"2021-09-13T14:10:00.000Z","version":4030620725,"name":"Match Odds","eventName":"I Rosca v C Cervino Ruiz"}}]}
{"op":"mcm","clk":"4230584625","pt":1631534548664,"mc":[{"id":"1.187594321","marketDefinition":{"bspMarket":false,"turnInPlayEnabled":true,"persistenceEnabled":true,"marketBaseRate":5.0,"eventId":"30897905","eventTypeId":"2","numberOfWinners":1,"bettingType":"ODDS","marketType":"MATCH_ODDS","marketTime":"2021-09-13T14:00:00.000Z","suspendTime":"2021-09-13T14:00:00.000Z","bspReconciled":false,"complete":true,"inPlay":false,"crossMatching":true,"runnersVoidable":false,"numberOfActiveRunners":2,"betDelay":0,"status":"OPEN","runners":[{"status":"ACTIVE","sortPriority":1,"id":8679184,"name":"I Rosca"},{"status":"ACTIVE","sortPriority":2,"id":11862899,"name":"C Cervino Ruiz"}],"regulators":["MR_INT"],"countryCode":"GB","discountAllowed":true,"timezone":"GMT","openDate":"2021-09-13T14:00:00.000Z","version":4030620725,"name":"Match Odds","eventName":"I Rosca v C Cervino Ruiz"}}]}
{"op":"mcm","clk":"4230596905","pt":1631534656327,"mc":[{"id":"1.187594321","rc":[{"batb":[[0,2.24,33.68]],"ltp":0.0,"tv":0.0,"id":11862899},{"batb":[[0,1.57,73.27]],"ltp":1.57,"tv":1.67,"id":8679184}]}]}
{"op":"mcm","clk":"4230596941","pt":1631534656703,"mc":[{"id":"1.187594321","rc":[{"batl":[[0,3.85,10.6],[1,990,2.2]],"ltp":0.0,"tv":0.0,"id":11862899}]}]}
{"op":"mcm","clk":"4230630358","pt":1631534957058,"mc":[{"id":"1.187594321","rc":[{"batl":[[0,2.3,26.72]],"ltp":1.57,"tv":1.67,"id":8679184}]}]}
{"op":"mcm","clk":"4230638755","pt":1631535038159,"mc":[{"id":"1.187594321","rc":[{"batb":[[0,1.57,74.12]],"ltp":1.57,"tv":1.67,"id":8679184}]}]}
{"op":"mcm","clk":"4230669080","pt":1631535357884,"mc":[{"id":"1.187594321","rc":[{"batb":[[0,1.57,73.27]],"ltp":1.57,"tv":1.67,"id":8679184}]}]}
{"op":"mcm","clk":"4230670729","pt":1631535375379,"mc":[{"id":"1.187594321","rc":[{"batb":[[0,1.6,94.55],[1,1.57,73.27],[2,1.22,195.25]],"ltp":1.57,"tv":1.67,"id":8679184}]}]}
{"op":"mcm","clk":"4230670794","pt":1631535375921,"mc":[{"id":"1.187594321","rc":[{"batl":[[0,2.26,3.5],[1,2.3,2.66],[2,990,2.2]],"ltp":1.57,"tv":1.67,"id":8679184}]}]}
{"op":"mcm","clk":"4230734938","pt":1631536033765,"mc":[{"id":"1.187594321","rc":[{"batb":[[1,1.01,7],[2,1.01,0]],"ltp":0.0,"tv":0.0,"id":11862899}]}]}
{"op":"mcm","clk":"4230735004","pt":1631536034720,"mc":[{"id":"1.187594321","rc":[{"batb":[[2,1.2,13.29]],"ltp":1.57,"tv":1.67,"id":8679184}]}]}
{"op":"mcm","clk":"4230736186","pt":1631536048921,"mc":[{"id":"1.187594321","rc":[{"batb":[[2,1.37,122.44]],"batl":[[2,2.6,43.73]],"ltp":1.57,"tv":1.67,"id":8679184}]}]}
{"op":"mcm","clk":"4230811129","pt":1631536866591,"mc":[{"id":"1.187594321","rc":[{"batl":[[0,990,2.2],[1,990,0]],"ltp":0.0,"tv":0.0,"id":11862899},{"batl":[[0,2.3,2.66],[1,2.6,43.73],[2,990,2.2]],"ltp":1.57,"tv":1.67,"id":8679184}]}]}
{"op":"mcm","clk":"4230817177","pt":1631536926685,"mc":[{"id":"1.187594321","rc":[{"batl":[[0,1.8,75],[1,2.3,2.66],[2,2.6,43.73]],"ltp":1.57,"tv":1.67,"id":8679184}]}]}
{"op":"mcm","clk":"4230818348","pt":1631536938261,"mc":[{"id":"1.187594321","marketDefinition":{"bspMarket":false,"turnInPlayEnabled":true,"persistenceEnabled":true,"marketBaseRate":5.0,"eventId":"30897905","eventTypeId":"2","numberOfWinners":1,"bettingType":"ODDS","marketType":"MATCH_ODDS","marketTime":"2021-09-13T14:10:00.000Z","suspendTime":"2021-09-13T14:10:00.000Z","bspReconciled":false,"complete":true,"inPlay":false,"crossMatching":true,"runnersVoidable":false,"numberOfActiveRunners":2,"betDelay":0,"status":"OPEN","runners":[{"status":"ACTIVE","sortPriority":1,"id":8679184,"name":"I Rosca"},{"status":"ACTIVE","sortPriority":2,"id":11862899,"name":"C Cervino Ruiz"}],"regulators":["MR_INT"],"countryCode":"GB","discountAllowed":true,"timezone":"GMT","openDate":"2021-09-13T14:00:00.000Z","version":4030656490,"name":"Match Odds","eventName":"I Rosca v C Cervino Ruiz"}}]}
{"op":"mcm","clk":"4230818635","pt":1631536941264,"mc":[{"id":"1.187594321","marketDefinition":{"bspMarket":false,"turnInPlayEnabled":true,"persistenceEnabled":true,"marketBaseRate":5.0,"eventId":"30897905","eventTypeId":"2","numberOfWinners":1,"bettingType":"ODDS","marketType":"MATCH_ODDS","marketTime":"2021-09-13T14:10:00.000Z","suspendTime":"2021-09-13T14:10:00.000Z","bspReconciled":false,"complete":true,"inPlay":false,"crossMatching":true,"runnersVoidable":false,"numberOfActiveRunners":2,"betDelay":0,"status":"OPEN","runners":[{"status":"ACTIVE","sortPriority":1,"id":8679184,"name":"I Rosca"},{"status":"ACTIVE","sortPriority":2,"id":11862899,"name":"C Cervino Ruiz"}],"regulators":["MR_INT"],"countryCode":"GB","discountAllowed":true,"timezone":"GMT","openDate":"2021-09-13T14:10:00.000Z","version":4030656490,"name":"Match Odds","eventName":"I Rosca v C Cervino Ruiz"}}]}
{"op":"mcm","clk":"4230831314","pt":1631537081508,"mc":[{"id":"1.187594321","rc":[{"batl":[[0,1.8,100]],"ltp":1.57,"tv":1.67,"id":8679184}]}]}
{"op":"mcm","clk":"4231012436","pt":1631538922266,"mc":[{"id":"1.187594321","rc":[{"batl":[[0,4.1,10.39],[1,990,2.2]],"ltp":0.0,"tv":0.0,"id":11862899},{"batb":[[0,1.6,94.53],[2,1.37,122.36]],"batl":[[1,2.3,2.66],[2,2.6,43.7]],"ltp":1.57,"tv":1.67,"id":8679184}]}]}
{"op":"mcm","clk":"4231134119","pt":1631540183799,"mc":[{"id":"1.187594321","rc":[{"batb":[[0,1.6,174.59]],"ltp":1.57,"tv":1.67,"id":8679184}]}]}
{"op":"mcm","clk":"4231286600","pt":1631542011866,"mc":[{"id":"1.187594321","marketDefinition":{"bspMarket":false,"turnInPlayEnabled":true,"persistenceEnabled":true,"marketBaseRate":5.0,"eventId":"30897905","eventTypeId":"2","numberOfWinners":1,"bettingType":"ODDS","marketType":"MATCH_ODDS","marketTime":"2021-09-13T14:20:00.000Z","suspendTime":"2021-09-13T14:20:00.000Z","bspReconciled":false,"complete":true,"inPlay":false,"crossMatching":true,"runnersVoidable":false,"numberOfActiveRunners":2,"betDelay":0,"status":"OPEN","runners":[{"status":"ACTIVE","sortPriority":1,"id":8679184,"name":"I Rosca"},{"status":"ACTIVE","sortPriority":2,"id":11862899,"name":"C Cervino Ruiz"}],"regulators":["MR_INT"],"countryCode":"GB","discountAllowed":true,"timezone":"GMT","openDate":"2021-09-13T14:10:00.000Z","version":4030749815,"name":"Match Odds","eventName":"I Rosca v C Cervino Ruiz"}}]}
{"op":"mcm","clk":"4231286849","pt":1631542015055,"mc":[{"id":"1.187594321","marketDefinition":{"bspMarket":false,"turnInPlayEnabled":true,"persistenceEnabled":true,"marketBaseRate":5.0,"eventId":"30897905","eventTypeId":"2","numberOfWinners":1,"bettingType":"ODDS","marketType":"MATCH_ODDS","marketTime":"2021-09-13T14:20:00.000Z","suspendTime":"2021-09-13T14:20:00.000Z","bspReconciled":false,"complete":true,"inPlay":false,"crossMatching":true,"runnersVoidable":false,"numberOfActiveRunners":2,"betDelay":0,"status":"OPEN","runners":[{"status":"ACTIVE","sortPriority":1,"id":8679184,"name":"I Rosca"},{"status":"ACTIVE","sortPriority":2,"id":11862899,"name":"C Cervino Ruiz"}],"regulators":["MR_INT"],"countryCode":"GB","discountAllowed":true,"timezone":"GMT","openDate":"2021-09-13T14:20:00.000Z","version":4030749815,"name":"Match Odds","eventName":"I Rosca v C Cervino Ruiz"},"rc":[{"batl":[[0,990,2.2],[1,990,0]],"ltp":0.0,"tv":0.0,"id":11862899}]}]}
{"op":"mcm","clk":"4231287082","pt":1631542017652,"mc":[{"id":"1.187594321","rc":[{"batl":[[0,4.4,9.7],[1,990,2.2]],"ltp":0.0,"tv":0.0,"id":11862899}]}]}
{"op":"mcm","clk":"4231330476","pt":1631542558023,"mc":[{"id":"1.187594321","marketDefinition":{"bspMarket":false,"turnInPlayEnabled":true,"persistenceEnabled":true,"marketBaseRate":5.0,"eventId":"30897905","eventTypeId":"2","numberOfWinners":1,"bettingType":"ODDS","marketType":"MATCH_ODDS","marketTime":"2021-09-13T14:30:00.000Z","suspendTime":"2021-09-13T14:30:00.000Z","bspReconciled":false,"complete":true,"inPlay":false,"crossMatching":true,"runnersVoidable":false,"numberOfActiveRunners":2,"betDelay":0,"status":"OPEN","runners":[{"status":"ACTIVE","sortPriority":1,"id":8679184,"name":"I Rosca"},{"status":"ACTIVE","sortPriority":2,"id":11862899,"name":"C Cervino Ruiz"}],"regulators":["MR_INT"],"countryCode":"GB","discountAllowed":true,"timezone":"GMT","openDate":"2021-09-13T14:20:00.000Z","version":4030758185,"name":"Match Odds","eventName":"I Rosca v C Cervino Ruiz"}}]}
{"op":"mcm","clk":"4231330693","pt":1631542560288,"mc":[{"id":"1.187594321","marketDefinition":{"bspMarket":false,"turnInPlayEnabled":true,"persistenceEnabled":true,"marketBaseRate":5.0,"eventId":"30897905","eventTypeId":"2","numberOfWinners":1,"bettingType":"ODDS","marketType":"MATCH_ODDS","marketTime":"2021-09-13T14:30:00.000Z","suspendTime":"2021-09-13T14:30:00.000Z","bspReconciled":false,"complete":true,"inPlay":false,"crossMatching":true,"runnersVoidable":false,"numberOfActiveRunners":2,"betDelay":0,"status":"OPEN","runners":[{"status":"ACTIVE","sortPriority":1,"id":8679184,"name":"I Rosca"},{"status":"ACTIVE","sortPriority":2,"id":11862899,"name":"C Cervino Ruiz"}],"regulators":["MR_INT"],"countryCode":"GB","discountAllowed":true,"timezone":"GMT","openDate":"2021-09-13T14:30:00.000Z","version":4030758185,"name":"Match Odds","eventName":"I Rosca v C Cervino Ruiz"},"rc":[{"batl":[[0,990,2.2],[1,990,0]],"ltp":0.0,"tv":0.0,"id":11862899}]}]}
{"op":"mcm","clk":"4231331390","pt":1631542566629,"mc":[{"id":"1.187594321","rc":[{"batl":[[0,3.7,11.53],[1,990,2.2]],"ltp":0.0,"tv":0.0,"id":11862899}]}]}
{"op":"mcm","clk":"4231389791","pt":1631543228751,"mc":[{"id":"1.187594321","marketDefinition":{"bspMarket":false,"turnInPlayEnabled":true,"persistenceEnabled":true,"marketBaseRate":5.0,"eventId":"30897905","eventTypeId":"2","numberOfWinners":1,"bettingType":"ODDS","marketType":"MATCH_ODDS","marketTime":"2021-09-13T14:40:00.000Z","suspendTime":"2021-09-13T14:40:00.000Z","bspReconciled":false,"complete":true,"inPlay":false,"crossMatching":true,"runnersVoidable":false,"numberOfActiveRunners":2,"betDelay":0,"status":"OPEN","runners":[{"status":"ACTIVE","sortPriority":1,"id":8679184,"name":"I Rosca"},{"status":"ACTIVE","sortPriority":2,"id":11862899,"name":"C Cervino Ruiz"}],"regulators":["MR_INT"],"countryCode":"GB","discountAllowed":true,"timezone":"GMT","openDate":"2021-09-13T14:30:00.000Z","version":4030771297,"name":"Match Odds","eventName":"I Rosca v C Cervino Ruiz"}}]}
{"op":"mcm","clk":"4231390002","pt":1631543231967,"mc":[{"id":"1.187594321","marketDefinition":{"bspMarket":false,"turnInPlayEnabled":true,"persistenceEnabled":true,"marketBaseRate":5.0,"eventId":"30897905","eventTypeId":"2","numberOfWinners":1,"bettingType":"ODDS","marketType":"MATCH_ODDS","marketTime":"2021-09-13T14:40:00.000Z","suspendTime":"2021-09-13T14:40:00.000Z","bspReconciled":false,"complete":true,"inPlay":false,"crossMatching":true,"runnersVoidable":false,"numberOfActiveRunners":2,"betDelay":0,"status":"OPEN","runners":[{"status":"ACTIVE","sortPriority":1,"id":8679184,"name":"I Rosca"},{"status":"ACTIVE","sortPriority":2,"id":11862899,"name":"C Cervino Ruiz"}],"regulators":["MR_INT"],"countryCode":"GB","discountAllowed":true,"timezone":"GMT","openDate":"2021-09-13T14:40:00.000Z","version":4030771297,"name":"Match Odds","eventName":"I Rosca v C Cervino Ruiz"},"rc":[{"batl":[[0,990,2.2],[1,990,0]],"ltp":0.0,"tv":0.0,"id":11862899}]}]}
{"op":"mcm","clk":"4231390337","pt":1631543237570,"mc":[{"id":"1.187594321","rc":[{"batl":[[0,3.1,13.76],[1,990,2.2]],"ltp":0.0,"tv":0.0,"id":11862899}]}]}
{"op":"mcm","clk":"4231398177","pt":1631543352183,"mc":[{"id":"1.187594321","rc":[{"batb":[[0,1.65,1.41],[1,1.6,174.59],[2,1.57,73.27]],"ltp":1.57,"tv":1.67,"id":8679184}]}]}
{"op":"mcm","clk":"4231420816","pt":1631543613365,"mc":[{"id":"1.187594321","rc":[{"batb":[[1,1.6,94.53]],"ltp":1.57,"tv":1.67,"id":8679184}]}]}
{"op":"mcm","clk":"4231438016","pt":1631543800833,"mc":[{"id":"1.187594321","marketDefinition":{"bspMarket":false,"turnInPlayEnabled":true,"persistenceEnabled":true,"marketBaseRate":5.0,"eventId":"30897905","eventTypeId":"2","numberOfWinners":1,"bettingType":"ODDS","marketType":"MATCH_ODDS","marketTime":"2021-09-13T14:50:00.000Z","suspendTime":"2021-09-13T14:50:00.000Z","bspReconciled":false,"complete":true,"inPlay":false,"crossMatching":true,"runnersVoidable":false,"numberOfActiveRunners":2,"betDelay":0,"status":"OPEN","runners":[{"status":"ACTIVE","sortPriority":1,"id":8679184,"name":"I Rosca"},{"status":"ACTIVE","sortPriority":2,"id":11862899,"name":"C Cervino Ruiz"}],"regulators":["MR_INT"],"countryCode":"GB","discountAllowed":true,"timezone":"GMT","openDate":"2021-09-13T14:40:00.000Z","version":4030783429,"name":"Match Odds","eventName":"I Rosca v C Cervino Ruiz"}}]}
{"op":"mcm","clk":"4231438230","pt":1631543803057,"mc":[{"id":"1.187594321","marketDefinition":{"bspMarket":false,"turnInPlayEnabled":true,"persistenceEnabled":true,"marketBaseRate":5.0,"eventId":"30897905","eventTypeId":"2","numberOfWinners":1,"bettingType":"ODDS","marketType":"MATCH_ODDS","marketTime":"2021-09-13T14:50:00.000Z","suspendTime":"2021-09-13T14:50:00.000Z","bspReconciled":false,"complete":true,"inPlay":false,"crossMatching":true,"runnersVoidable":false,"numberOfActiveRunners":2,"betDelay":0,"status":"OPEN","runners":[{"status":"ACTIVE","sortPriority":1,"id":8679184,"name":"I Rosca"},{"status":"ACTIVE","sortPriority":2,"id":11862899,"name":"C Cervino Ruiz"}],"regulators":["MR_INT"],"countryCode":"GB","discountAllowed":true,"timezone":"GMT","openDate":"2021-09-13T14:50:00.000Z","version":4030783429,"name":"Match Odds","eventName":"I Rosca v C Cervino Ruiz"},"rc":[{"batl":[[0,990,2.2],[1,990,0]],"ltp":0.0,"tv":0.0,"id":11862899}]}]}
{"op":"mcm","clk":"4231438711","pt":1631543807347,"mc":[{"id":"1.187594321","rc":[{"batl":[[0,4.1,12.67],[1,990,2.2]],"ltp":0.0,"tv":0.0,"id":11862899}]}]}
{"op":"mcm","clk":"4231487418","pt":1631544418969,"mc":[{"id":"1.187594321","marketDefinition":{"bspMarket":false,"turnInPlayEnabled":true,"persistenceEnabled":true,"marketBaseRate":5.0,"eventId":"30897905","eventTypeId":"2","numberOfWinners":1,"bettingType":"ODDS","marketType":"MATCH_ODDS","marketTime":"2021-09-13T15:00:00.000Z","suspendTime":"2021-09-13T15:00:00.000Z","bspReconciled":false,"complete":true,"inPlay":false,"crossMatching":true,"runnersVoidable":false,"numberOfActiveRunners":2,"betDelay":0,"status":"OPEN","runners":[{"status":"ACTIVE","sortPriority":1,"id":8679184,"name":"I Rosca"},{"status":"ACTIVE","sortPriority":2,"id":11862899,"name":"C Cervino Ruiz"}],"regulators":["MR_INT"],"countryCode":"GB","discountAllowed":true,"timezone":"GMT","openDate":"2021-09-13T14:50:00.000Z","version":4030789669,"name":"Match Odds","eventName":"I Rosca v C Cervino Ruiz"}}]}
{"op":"mcm","clk":"4231487720","pt":1631544423142,"mc":[{"id":"1.187594321","marketDefinition":{"bspMarket":false,"turnInPlayEnabled":true,"persistenceEnabled":true,"marketBaseRate":5.0,"eventId":"30897905","eventTypeId":"2","numberOfWinners":1,"bettingType":"ODDS","marketType":"MATCH_ODDS","marketTime":"2021-09-13T15:00:00.000Z","suspendTime":"2021-09-13T15:00:00.000Z","bspReconciled":false,"complete":true,"inPlay":false,"crossMatching":true,"runnersVoidable":false,"numberOfActiveRunners":2,"betDelay":0,"status":"OPEN","runners":[{"status":"ACTIVE","sortPriority":1,"id":8679184,"name":"I Rosca"},{"status":"ACTIVE","sortPriority":2,"id":11862899,"name":"C Cervino Ruiz"}],"regulators":["MR_INT"],"countryCode":"GB","discountAllowed":true,"timezone":"GMT","openDate":"2021-09-13T15:00:00.000Z","version":4030789669,"name":"Match Odds","eventName":"I Rosca v C Cervino Ruiz"},"rc":[{"batl":[[0,990,2.2],[1,990,0]],"ltp":0.0,"tv":0.0,"id":11862899}]}]}
{"op":"mcm","clk":"4231488014","pt":1631544427363,"mc":[{"id":"1.187594321","rc":[{"batl":[[0,3.05,17],[1,990,2.2]],"ltp":0.0,"tv":0.0,"id":11862899}]}]}
{"op":"mcm","clk":"4231524928","pt":1631544968751,"mc":[{"id":"1.187594321","marketDefinition":{"bspMarket":false,"turnInPlayEnabled":true,"persistenceEnabled":true,"marketBaseRate":5.0,"eventId":"30897905","eventTypeId":"2","numberOfWinners":1,"bettingType":"ODDS","marketType":"MATCH_ODDS","marketTime":"2021-09-13T15:10:00.000Z","suspendTime":"2021-09-13T15:10:00.000Z","bspReconciled":false,"complete":true,"inPlay":false,"crossMatching":true,"runnersVoidable":false,"numberOfActiveRunners":2,"betDelay":0,"status":"OPEN","runners":[{"status":"ACTIVE","sortPriority":1,"id":8679184,"name":"I Rosca"},{"status":"ACTIVE","sortPriority":2,"id":11862899,"name":"C Cervino Ruiz"}],"regulators":["MR_INT"],"countryCode":"GB","discountAllowed":true,"timezone":"GMT","openDate":"2021-09-13T15:00:00.000Z","version":4030796871,"name":"Match Odds","eventName":"I Rosca v C Cervino Ruiz"}}]}
{"op":"mcm","clk":"4231526781","pt":1631544993986,"mc":[{"id":"1.187594321","marketDefinition":{"bspMarket":false,"turnInPlayEnabled":true,"persistenceEnabled":true,"marketBaseRate":5.0,"eventId":"30897905","eventTypeId":"2","numberOfWinners":1,"bettingType":"ODDS","marketType":"MATCH_ODDS","marketTime":"2021-09-13T15:10:00.000Z","suspendTime":"2021-09-13T15:10:00.000Z","bspReconciled":false,"complete":true,"inPlay":false,"crossMatching":true,"runnersVoidable":false,"numberOfActiveRunners":2,"betDelay":0,"status":"OPEN","runners":[{"status":"ACTIVE","sortPriority":1,"id":8679184,"name":"I Rosca"},{"status":"ACTIVE","sortPriority":2,"id":11862899,"name":"C Cervino Ruiz"}],"regulators":["MR_INT"],"countryCode":"GB","discountAllowed":true,"timezone":"GMT","openDate":"2021-09-13T15:10:00.000Z","version":4030796871,"name":"Match Odds","eventName":"I Rosca v C Cervino Ruiz"},"rc":[{"batl":[[0,990,2.2],[1,990,0]],"ltp":0.0,"tv":0.0,"id":11862899}]}]}
{"op":"mcm","clk":"4231526980","pt":1631544996714,"mc":[{"id":"1.187594321","rc":[{"batl":[[0,4,12.98],[1,990,2.2]],"ltp":0.0,"tv":0.0,"id":11862899}]}]}
{"op":"mcm","clk":"4231533956","pt":1631545090399,"mc":[{"id":"1.187594321","marketDefinition":{"bspMarket":false,"turnInPlayEnabled":true,"persistenceEnabled":true,"marketBaseRate":5.0,"eventId":"30897905","eventTypeId":"2","numberOfWinners":1,"bettingType":"ODDS","marketType":"MATCH_ODDS","marketTime":"2021-09-13T15:00:00.000Z","suspendTime":"2021-09-13T15:00:00.000Z","bspReconciled":false,"complete":true,"inPlay":false,"crossMatching":true,"runnersVoidable":false,"numberOfActiveRunners":2,"betDelay":0,"status":"OPEN","runners":[{"status":"ACTIVE","sortPriority":1,"id":8679184,"name":"I Rosca"},{"status":"ACTIVE","sortPriority":2,"id":11862899,"name":"C Cervino Ruiz"}],"regulators":["MR_INT"],"countryCode":"GB","discountAllowed":true,"timezone":"GMT","openDate":"2021-09-13T15:10:00.000Z","version":4030799123,"name":"Match Odds","eventName":"I Rosca v C Cervino Ruiz"}}]}
{"op":"mcm","clk":"4231534794","pt":1631545101460,"mc":[{"id":"1.187594321","marketDefinition":{"bspMarket":false,"turnInPlayEnabled":true,"persistenceEnabled":true,"marketBaseRate":5.0,"eventId":"30897905","eventTypeId":"2","numberOfWinners":1,"bettingType":"ODDS","marketType":"MATCH_ODDS","marketTime":"2021-09-13T15:00:00.000Z","suspendTime":"2021-09-13T15:00:00.000Z","bspReconciled":false,"complete":true,"inPlay":false,"crossMatching":true,"runnersVoidable":false,"numberOfActiveRunners":2,"betDelay":0,"status":"OPEN","runners":[{"status":"ACTIVE","sortPriority":1,"id":8679184,"name":"I Rosca"},{"status":"ACTIVE","sortPriority":2,"id":11862899,"name":"C Cervino Ruiz"}],"regulators":["MR_INT"],"countryCode":"GB","discountAllowed":true,"timezone":"GMT","openDate":"2021-09-13T15:00:00.000Z","version":4030799123,"name":"Match Odds","eventName":"I Rosca v C Cervino Ruiz"}}]}
{"op":"mcm","clk":"4231534807","pt":1631545101663,"mc":[{"id":"1.187594321","rc":[{"batl":[[0,990,2.2],[1,990,0]],"ltp":0.0,"tv":0.0,"id":11862899}]}]}
{"op":"mcm","clk":"4231545548","pt":1631545259120,"mc":[{"id":"1.187594321","marketDefinition":{"bspMarket":false,"turnInPlayEnabled":true,"persistenceEnabled":true,"marketBaseRate":5.0,"eventId":"30897905","eventTypeId":"2","numberOfWinners":1,"bettingType":"ODDS","marketType":"MATCH_ODDS","marketTime":"2021-09-13T15:00:00.000Z","suspendTime":"2021-09-13T15:00:00.000Z","bspReconciled":false,"complete":true,"inPlay":true,"crossMatching":true,"runnersVoidable":false,"numberOfActiveRunners":2,"betDelay":5,"status":"OPEN","runners":[{"status":"ACTIVE","sortPriority":1,"id":8679184,"name":"I Rosca"},{"status":"ACTIVE","sortPriority":2,"id":11862899,"name":"C Cervino Ruiz"}],"regulators":["MR_INT"],"countryCode":"GB","discountAllowed":true,"timezone":"GMT","openDate":"2021-09-13T15:00:00.000Z","version":4030804472,"name":"Match Odds","eventName":"I Rosca v C Cervino Ruiz"},"rc":[{"batb":[[0,1.01,7],[1,1.01,0]],"ltp":0.0,"tv":0.0,"id":11862899},{"trd":[[1.57,1.68]],"batb":[[0,1.65,1.41],[1,1.01,7],[2,1.57,0]],"batl":[[1,2.3,0],[2,2.6,0]],"ltp":1.57,"tv":1.67,"id":8679184}],"tv":1.67}]}
{"op":"mcm","clk":"4231545950","pt":1631545264388,"mc":[{"id":"1.187594321","rc":[{"batb":[[0,2.2,24.99],[1,1.01,7]],"ltp":0.0,"tv":0.0,"id":11862899},{"batb":[[1,1.55,54.54],[2,1.01,7]],"ltp":1.57,"tv":1.67,"id":8679184}]}]}
{"op":"mcm","clk":"4231872302","pt":1631549092077,"mc":[{"id":"1.187594321","rc":[{"batb":[[1,1.01,12]],"ltp":0.0,"tv":0.0,"id":11862899},{"batb":[[2,1.01,12]],"ltp":1.57,"tv":1.67,"id":8679184}]}]}
{"op":"mcm","clk":"4231884850","pt":1631549234905,"mc":[{"id":"1.187594321","marketDefinition":{"bspMarket":false,"turnInPlayEnabled":true,"persistenceEnabled":true,"marketBaseRate":5.0,"eventId":"30897905","eventTypeId":"2","numberOfWinners":1,"bettingType":"ODDS","marketType":"MATCH_ODDS","marketTime":"2021-09-13T16:20:00.000Z","suspendTime":"2021-09-13T16:20:00.000Z","bspReconciled":false,"complete":true,"inPlay":true,"crossMatching":true,"runnersVoidable":false,"numberOfActiveRunners":2,"betDelay":5,"status":"OPEN","runners":[{"status":"ACTIVE","sortPriority":1,"id":8679184,"name":"I Rosca"},{"status":"ACTIVE","sortPriority":2,"id":11862899,"name":"C Cervino Ruiz"}],"regulators":["MR_INT"],"countryCode":"GB","discountAllowed":true,"timezone":"GMT","openDate":"2021-09-13T15:00:00.000Z","version":4030878770,"name":"Match Odds","eventName":"I Rosca v C Cervino Ruiz"}}]}
{"op":"mcm","clk":"4231885127","pt":1631549237922,"mc":[{"id":"1.187594321","marketDefinition":{"bspMarket":false,"turnInPlayEnabled":true,"persistenceEnabled":true,"marketBaseRate":5.0,"eventId":"30897905","eventTypeId":"2","numberOfWinners":1,"bettingType":"ODDS","marketType":"MATCH_ODDS","marketTime":"2021-09-13T16:20:00.000Z","suspendTime":"2021-09-13T16:20:00.000Z","bspReconciled":false,"complete":true,"inPlay":true,"crossMatching":true,"runnersVoidable":false,"numberOfActiveRunners":2,"betDelay":5,"status":"OPEN","runners":[{"status":"ACTIVE","sortPriority":1,"id":8679184,"name":"I Rosca"},{"status":"ACTIVE","sortPriority":2,"id":11862899,"name":"C Cervino Ruiz"}],"regulators":["MR_INT"],"countryCode":"GB","discountAllowed":true,"timezone":"GMT","openDate":"2021-09-13T16:20:00.000Z","version":4030878770,"name":"Match Odds","eventName":"I Rosca v C Cervino Ruiz"}}]}
{"op":"mcm","clk":"4231932209","pt":1631549785939,"mc":[{"id":"1.187594321","marketDefinition":{"bspMarket":false,"turnInPlayEnabled":true,"persistenceEnabled":true,"marketBaseRate":5.0,"eventId":"30897905","eventTypeId":"2","numberOfWinners":1,"bettingType":"ODDS","marketType":"MATCH_ODDS","marketTime":"2021-09-13T16:30:00.000Z","suspendTime":"2021-09-13T16:30:00.000Z","bspReconciled":false,"complete":true,"inPlay":true,"crossMatching":true,"runnersVoidable":false,"numberOfActiveRunners":2,"betDelay":5,"status":"OPEN","runners":[{"status":"ACTIVE","sortPriority":1,"id":8679184,"name":"I Rosca"},{"status":"ACTIVE","sortPriority":2,"id":11862899,"name":"C Cervino Ruiz"}],"regulators":["MR_INT"],"countryCode":"GB","discountAllowed":true,"timezone":"GMT","openDate":"2021-09-13T16:20:00.000Z","version":4030892957,"name":"Match Odds","eventName":"I Rosca v C Cervino Ruiz"}}]}
{"op":"mcm","clk":"4231932474","pt":1631549788954,"mc":[{"id":"1.187594321","marketDefinition":{"bspMarket":false,"turnInPlayEnabled":true,"persistenceEnabled":true,"marketBaseRate":5.0,"eventId":"30897905","eventTypeId":"2","numberOfWinners":1,"bettingType":"ODDS","marketType":"MATCH_ODDS","marketTime":"2021-09-13T16:30:00.000Z","suspendTime":"2021-09-13T16:30:00.000Z","bspReconciled":false,"complete":true,"inPlay":true,"crossMatching":true,"runnersVoidable":false,"numberOfActiveRunners":2,"betDelay":5,"status":"OPEN","runners":[{"status":"ACTIVE","sortPriority":1,"id":8679184,"name":"I Rosca"},{"status":"ACTIVE","sortPriority":2,"id":11862899,"name":"C Cervino Ruiz"}],"regulators":["MR_INT"],"countryCode":"GB","discountAllowed":true,"timezone":"GMT","openDate":"2021-09-13T16:30:00.000Z","version":4030892957,"name":"Match Odds","eventName":"I Rosca v C Cervino Ruiz"}}]}
{"op":"mcm","clk":"4232038295","pt":1631551058176,"mc":[{"id":"1.187594321","rc":[{"batb":[[0,1.01,12],[1,1.01,0]],"ltp":0.0,"tv":0.0,"id":11862899},{"batb":[[1,1.01,12],[2,1.01,0]],"ltp":1.57,"tv":1.67,"id":8679184}]}]}
{"op":"mcm","clk":"4232038362","pt":1631551059014,"mc":[{"id":"1.187594321","marketDefinition":{"bspMarket":false,"turnInPlayEnabled":true,"persistenceEnabled":true,"marketBaseRate":5.0,"eventId":"30897905","eventTypeId":"2","numberOfWinners":1,"bettingType":"ODDS","marketType":"MATCH_ODDS","marketTime":"2021-09-13T16:37:37.000Z","suspendTime":"2021-09-13T16:37:37.000Z","bspReconciled":false,"complete":true,"inPlay":true,"crossMatching":true,"runnersVoidable":false,"numberOfActiveRunners":2,"betDelay":5,"status":"OPEN","runners":[{"status":"ACTIVE","sortPriority":1,"id":8679184,"name":"I Rosca"},{"status":"ACTIVE","sortPriority":2,"id":11862899,"name":"C Cervino Ruiz"}],"regulators":["MR_INT"],"countryCode":"GB","discountAllowed":true,"timezone":"GMT","openDate":"2021-09-13T16:30:00.000Z","version":4030925935,"name":"Match Odds","eventName":"I Rosca v C Cervino Ruiz"}}]}
{"op":"mcm","clk":"4232038586","pt":1631551062029,"mc":[{"id":"1.187594321","marketDefinition":{"bspMarket":false,"turnInPlayEnabled":true,"persistenceEnabled":true,"marketBaseRate":5.0,"eventId":"30897905","eventTypeId":"2","numberOfWinners":1,"bettingType":"ODDS","marketType":"MATCH_ODDS","marketTime":"2021-09-13T16:37:37.000Z","suspendTime":"2021-09-13T16:37:37.000Z","bspReconciled":false,"complete":true,"inPlay":true,"crossMatching":true,"runnersVoidable":false,"numberOfActiveRunners":2,"betDelay":5,"status":"OPEN","runners":[{"status":"ACTIVE","sortPriority":1,"id":8679184,"name":"I Rosca"},{"status":"ACTIVE","sortPriority":2,"id":11862899,"name":"C Cervino Ruiz"}],"regulators":["MR_INT"],"countryCode":"GB","discountAllowed":true,"timezone":"GMT","openDate":"2021-09-13T16:37:37.000Z","version":4030925935,"name":"Match Odds","eventName":"I Rosca v C Cervino Ruiz"}}]}
{"op":"mcm","clk":"4232038655","pt":1631551063072,"mc":[{"id":"1.187594321","rc":[{"batb":[[0,2.26,23.8],[1,1.01,12]],"ltp":0.0,"tv":0.0,"id":11862899},{"batb":[[1,1.58,51.72],[2,1.01,12]],"ltp":1.57,"tv":1.67,"id":8679184}]}]}
{"op":"mcm","clk":"4232038975","pt":1631551068282,"mc":[{"id":"1.187594321","rc":[{"batb":[[1,1.01,12],[2,1.01,0]],"ltp":1.57,"tv":1.67,"id":8679184}]}]}
{"op":"mcm","clk":"4232039317","pt":1631551073162,"mc":[{"id":"1.187594321","rc":[{"batb":[[1,1.6,49.99],[2,1.01,12]],"ltp":1.57,"tv":1.67,"id":8679184}]}]}
{"op":"mcm","clk":"4232040248","pt":1631551085729,"mc":[{"id":"1.187594321","rc":[{"batb":[[0,1.01,12],[1,1.01,0]],"ltp":0.0,"tv":0.0,"id":11862899},{"batb":[[1,1.01,12],[2,1.01,0]],"ltp":1.57,"tv":1.67,"id":8679184}]}]}
{"op":"mcm","clk":"4232040609","pt":1631551090607,"mc":[{"id":"1.187594321","rc":[{"batb":[[0,2.06,28.3],[1,1.01,12]],"ltp":0.0,"tv":0.0,"id":11862899},{"batb":[[0,1.71,42.25],[1,1.65,1.41],[2,1.01,12]],"ltp":1.57,"tv":1.67,"id":8679184}]}]}
{"op":"mcm","clk":"4232043035","pt":1631551119147,"mc":[{"id":"1.187594321","rc":[{"batb":[[0,1.01,12],[1,1.01,0]],"ltp":0.0,"tv":0.0,"id":11862899},{"batb":[[0,1.65,1.41],[1,1.01,12],[2,1.01,0]],"ltp":1.57,"tv":1.67,"id":8679184}]}]}
{"op":"mcm","clk":"4232043425","pt":1631551124047,"mc":[{"id":"1.187594321","rc":[{"batb":[[0,1.88,34.09],[1,1.01,12]],"ltp":0.0,"tv":0.0,"id":11862899}]}]}
{"op":"mcm","clk":"4232044493","pt":1631551137361,"mc":[{"id":"1.187594321","rc":[{"batb":[[0,1.01,12],[1,1.01,0]],"ltp":0.0,"tv":0.0,"id":11862899}]}]}
{"op":"mcm","clk":"4232044859","pt":1631551142261,"mc":[{"id":"1.187594321","rc":[{"batb":[[0,2.06,28.3],[1,1.01,12]],"ltp":0.0,"tv":0.0,"id":11862899},{"batb":[[0,1.71,42.25],[1,1.65,1.41],[2,1.01,12]],"ltp":1.57,"tv":1.67,"id":8679184}]}]}
{"op":"mcm","clk":"4232046589","pt":1631551161106,"mc":[{"id":"1.187594321","rc":[{"batb":[[0,1.01,12],[1,1.01,0]],"ltp":0.0,"tv":0.0,"id":11862899},{"batb":[[0,1.65,1.41],[1,1.01,12],[2,1.01,0]],"ltp":1.57,"tv":1.67,"id":8679184}]}]}
{"op":"mcm","clk":"4232047143","pt":1631551165978,"mc":[{"id":"1.187594321","rc":[{"batb":[[0,2.16,25.86],[1,1.01,12]],"ltp":0.0,"tv":0.0,"id":11862899},{"batb":[[1,1.63,47.61],[2,1.01,12]],"ltp":1.57,"tv":1.67,"id":8679184}]}]}
{"op":"mcm","clk":"4232049412","pt":1631551192710,"mc":[{"id":"1.187594321","rc":[{"batb":[[0,1.01,12],[1,1.01,0]],"ltp":0.0,"tv":0.0,"id":11862899},{"batb":[[1,1.01,12],[2,1.01,0]],"ltp":1.57,"tv":1.67,"id":8679184}]}]}
{"op":"mcm","clk":"4232049780","pt":1631551197614,"mc":[{"id":"1.187594321","rc":[{"batb":[[0,2.42,21.12],[1,1.01,12]],"ltp":0.0,"tv":0.0,"id":11862899},{"batb":[[1,1.51,58.82],[2,1.01,12]],"ltp":1.57,"tv":1.67,"id":8679184}]}]}
{"op":"mcm","clk":"4232051219","pt":1631551217028,"mc":[{"id":"1.187594321","rc":[{"batb":[[0,1.01,12],[1,1.01,0]],"ltp":0.0,"tv":0.0,"id":11862899},{"batb":[[1,1.01,12],[2,1.01,0]],"ltp":1.57,"tv":1.67,"id":8679184}]}]}
{"op":"mcm","clk":"4232051614","pt":1631551222271,"mc":[{"id":"1.187594321","rc":[{"trd":[[2.54,0.92]],"ltp":2.54,"tv":0.92,"id":11862899},{"trd":[[1.65,1.41]],"batb":[[0,1.45,66.66]],"ltp":1.65,"tv":3.09,"id":8679184}],"tv":4.01}]}
{"op":"mcm","clk":"4232052016","pt":1631551227139,"mc":[{"id":"1.187594321","rc":[{"batb":[[0,2.58,18.98],[1,1.01,12]],"ltp":2.54,"tv":0.92,"id":11862899}]}]}
{"op":"mcm","clk":"4232055899","pt":1631551275541,"mc":[{"id":"1.187594321","rc":[{"batb":[[0,1.01,12],[1,1.01,0]],"ltp":2.54,"tv":0.92,"id":11862899},{"batb":[[0,1.01,12],[1,1.01,0]],"ltp":1.65,"tv":3.09,"id":8679184}]}]}
{"op":"mcm","clk":"4232056330","pt":1631551280563,"mc":[{"id":"1.187594321","rc":[{"batb":[[0,2.42,21.12],[1,1.01,12]],"ltp":2.54,"tv":0.92,"id":11862899},{"batb":[[0,1.51,58.82],[1,1.01,12]],"ltp":1.65,"tv":3.09,"id":8679184}]}]}
{"op":"mcm","clk":"4232058040","pt":1631551301058,"mc":[{"id":"1.187594321","rc":[{"batb":[[0,1.01,12],[1,1.01,0]],"ltp":2.54,"tv":0.92,"id":11862899},{"batb":[[0,1.01,12],[1,1.01,0]],"ltp":1.65,"tv":3.09,"id":8679184}]}]}
{"op":"mcm","clk":"4232058518","pt":1631551306084,"mc":[{"id":"1.187594321","rc":[{"batb":[[0,2.58,18.98],[1,1.01,12]],"ltp":2.54,"tv":0.92,"id":11862899},{"batb":[[0,1.45,66.66],[1,1.01,12]],"ltp":1.65,"tv":3.09,"id":8679184}]}]}
{"op":"mcm","clk":"4232060118","pt":1631551323699,"mc":[{"id":"1.187594321","rc":[{"batb":[[0,1.01,12],[1,1.01,0]],"ltp":2.54,"tv":0.92,"id":11862899},{"batb":[[0,1.01,12],[1,1.01,0]],"ltp":1.65,"tv":3.09,"id":8679184}]}]}
{"op":"mcm","clk":"4232060536","pt":1631551328589,"mc":[{"id":"1.187594321","rc":[{"batb":[[0,2.42,21.12],[1,1.01,12]],"ltp":2.54,"tv":0.92,"id":11862899},{"batb":[[0,1.51,58.82],[1,1.01,12]],"ltp":1.65,"tv":3.09,"id":8679184}]}]}
{"op":"mcm","clk":"4232062256","pt":1631551349332,"mc":[{"id":"1.187594321","rc":[{"batb":[[0,1.01,12],[1,1.01,0]],"ltp":2.54,"tv":0.92,"id":11862899},{"batb":[[0,1.01,12],[1,1.01,0]],"ltp":1.65,"tv":3.09,"id":8679184}]}]}
{"op":"mcm","clk":"4232062716","pt":1631551354356,"mc":[{"id":"1.187594321","rc":[{"batb":[[0,2.26,23.8],[1,1.01,12]],"ltp":2.54,"tv":0.92,"id":11862899},{"batb":[[0,1.58,51.72],[1,1.01,12]],"ltp":1.65,"tv":3.09,"id":8679184}]}]}
{"op":"mcm","clk":"4232069562","pt":1631551438912,"mc":[{"id":"1.187594321","rc":[{"batb":[[0,1.01,12],[1,1.01,0]],"ltp":2.54,"tv":0.92,"id":11862899},{"batb":[[0,1.01,12],[1,1.01,0]],"ltp":1.65,"tv":3.09,"id":8679184}]}]}
{"op":"mcm","clk":"4232069998","pt":1631551443960,"mc":[{"id":"1.187594321","rc":[{"batb":[[0,2.16,25.86],[1,1.01,12]],"ltp":2.54,"tv":0.92,"id":11862899},{"batb":[[0,1.63,47.61],[1,1.01,12]],"ltp":1.65,"tv":3.09,"id":8679184}]}]}
{"op":"mcm","clk":"4232072151","pt":1631551469983,"mc":[{"id":"1.187594321","rc":[{"batb":[[0,1.01,12],[1,1.01,0]],"ltp":2.54,"tv":0.92,"id":11862899},{"batb":[[0,1.01,12],[1,1.01,0]],"ltp":1.65,"tv":3.09,"id":8679184}]}]}
{"op":"mcm","clk":"4232072533","pt":1631551474888,"mc":[{"id":"1.187594321","rc":[{"batb":[[0,1.98,30.61],[1,1.01,12]],"ltp":2.54,"tv":0.92,"id":11862899},{"batb":[[0,1.78,38.46],[1,1.01,12]],"ltp":1.65,"tv":3.09,"id":8679184}]}]}
{"op":"mcm","clk":"4232075557","pt":1631551514441,"mc":[{"id":"1.187594321","rc":[{"batb":[[0,1.01,12],[1,1.01,0]],"ltp":2.54,"tv":0.92,"id":11862899},{"batb":[[0,1.01,12],[1,1.01,0]],"ltp":1.65,"tv":3.09,"id":8679184}]}]}
{"op":"mcm","clk":"4232075969","pt":1631551519363,"mc":[{"id":"1.187594321","rc":[{"batb":[[0,1.85,35.29],[1,1.01,12]],"ltp":2.54,"tv":0.92,"id":11862899}]}]}
{"op":"mcm","clk":"4232076150","pt":1631551521365,"mc":[{"id":"1.187594321","rc":[{"trd":[[1.8,142.14]],"batl":[[0,1.8,28.91]],"ltp":1.8,"tv":145.23,"id":8679184}],"tv":146.15}]}
{"op":"mcm","clk":"4232076305","pt":1631551523563,"mc":[{"id":"1.187594321","rc":[{"trd":[[1.8,199.95]],"batb":[[0,1.8,218.37],[1,1.01,12]],"ltp":1.8,"tv":203.03,"id":8679184}],"tv":203.95}]}
{"op":"mcm","clk":"4232076389","pt":1631551524570,"mc":[{"id":"1.187594321","rc":[{"batb":[[0,1.8,524.44]],"ltp":1.8,"tv":203.03,"id":8679184}]}]}
{"op":"mcm","clk":"4232076477","pt":1631551525570,"mc":[{"id":"1.187594321","rc":[{"batb":[[0,1.8,314.12]],"ltp":1.8,"tv":203.03,"id":8679184}]}]}
{"op":"mcm","clk":"4232076579","pt":1631551526563,"mc":[{"id":"1.187594321","rc":[{"batb":[[0,1.8,178.32]],"ltp":1.8,"tv":203.03,"id":8679184}]}]}
{"op":"mcm","clk":"4232076655","pt":1631551527568,"mc":[{"id":"1.187594321","rc":[{"batb":[[0,1.8,76.47]],"ltp":1.8,"tv":203.03,"id":8679184}]}]}
{"op":"mcm","clk":"4232076734","pt":1631551528564,"mc":[{"id":"1.187594321","rc":[{"batb":[[0,1.88,34.09],[1,1.8,76.94],[2,1.01,12]],"ltp":1.8,"tv":203.03,"id":8679184}]}]}
{"op":"mcm","clk":"4232076833","pt":1631551529574,"mc":[{"id":"1.187594321","rc":[{"batb":[[1,1.8,57.44]],"ltp":1.8,"tv":203.03,"id":8679184}]}]}
{"op":"mcm","clk":"4232076861","pt":1631551529882,"mc":[{"id":"1.187594321","rc":[{"batb":[[1,1.8,23.44]],"ltp":1.8,"tv":203.03,"id":8679184}]}]}
{"op":"mcm","clk":"4232076936","pt":1631551530816,"mc":[{"id":"1.187594321","rc":[{"batb":[[1,1.01,12],[2,1.01,0]],"ltp":1.8,"tv":203.03,"id":8679184}]}]}
{"op":"mcm","clk":"4232078295","pt":1631551548690,"mc":[{"id":"1.187594321","rc":[{"batb":[[0,1.01,12],[1,1.01,0]],"ltp":2.54,"tv":0.92,"id":11862899},{"batb":[[0,1.01,12],[1,1.01,0]],"ltp":1.8,"tv":203.03,"id":8679184}]}]}
{"op":"mcm","clk":"4232078686","pt":1631551553761,"mc":[{"id":"1.187594321","rc":[{"batb":[[0,1.88,34.09],[1,1.01,12]],"ltp":2.54,"tv":0.92,"id":11862899},{"batb":[[0,1.85,35.29],[1,1.01,12]],"ltp":1.8,"tv":203.03,"id":8679184}]}]}
{"op":"mcm","clk":"4232081455","pt":1631551589367,"mc":[{"id":"1.187594321","rc":[{"batb":[[0,1.01,12],[1,1.01,0]],"ltp":2.54,"tv":0.92,"id":11862899},{"batb":[[0,1.01,12],[1,1.01,0]],"ltp":1.8,"tv":203.03,"id":8679184}]}]}
{"op":"mcm","clk":"4232081809","pt":1631551594419,"mc":[{"id":"1.187594321","rc":[{"batb":[[0,1.85,35.29],[1,1.01,12]],"ltp":2.54,"tv":0.92,"id":11862899},{"batb":[[0,1.88,34.09],[1,1.01,12]],"ltp":1.8,"tv":203.03,"id":8679184}]}]}
{"op":"mcm","clk":"4232083419","pt":1631551615308,"mc":[{"id":"1.187594321","rc":[{"batb":[[0,1.01,12],[1,1.01,0]],"ltp":2.54,"tv":0.92,"id":11862899},{"batb":[[0,1.01,12],[1,1.01,0]],"ltp":1.8,"tv":203.03,"id":8679184}]}]}
{"op":"mcm","clk":"4232083831","pt":1631551620209,"mc":[{"id":"1.187594321","rc":[{"batb":[[0,1.88,34.09],[1,1.01,12]],"ltp":2.54,"tv":0.92,"id":11862899},{"batb":[[0,1.85,35.29],[1,1.01,12]],"ltp":1.8,"tv":203.03,"id":8679184}]}]}
{"op":"mcm","clk":"4232086222","pt":1631551652142,"mc":[{"id":"1.187594321","rc":[{"batb":[[0,1.01,12],[1,1.01,0]],"ltp":2.54,"tv":0.92,"id":11862899},{"batb":[[0,1.01,12],[1,1.01,0]],"ltp":1.8,"tv":203.03,"id":8679184}]}]}
{"op":"mcm","clk":"4232086594","pt":1631551657157,"mc":[{"id":"1.187594321","rc":[{"batb":[[0,1.71,42.25],[1,1.01,12]],"ltp":2.54,"tv":0.92,"id":11862899},{"batb":[[0,2.06,28.3],[1,1.01,12]],"ltp":1.8,"tv":203.03,"id":8679184}]}]}
{"op":"mcm","clk":"4232094609","pt":1631551758499,"mc":[{"id":"1.187594321","rc":[{"trd":[[2.06,3.42]],"batb":[[0,2.06,26.59]],"ltp":2.06,"tv":206.45,"id":8679184}],"tv":207.37}]}
{"op":"mcm","clk":"4232094633","pt":1631551758809,"mc":[{"id":"1.187594321","rc":[{"batb":[[0,1.01,12],[1,1.01,0]],"ltp":2.06,"tv":206.45,"id":8679184}]}]}
{"op":"mcm","clk":"4232094773","pt":1631551760633,"mc":[{"id":"1.187594321","rc":[{"batb":[[0,1.01,12],[1,1.01,0]],"ltp":2.54,"tv":0.92,"id":11862899}]}]}
{"op":"mcm","clk":"4232095219","pt":1631551765616,"mc":[{"id":"1.187594321","rc":[{"batb":[[0,1.85,35.29],[1,1.01,12]],"ltp":2.54,"tv":0.92,"id":11862899}]}]}
{"op":"mcm","clk":"4232095506","pt":1631551768908,"mc":[{"id":"1.187594321","rc":[{"batb":[[0,1.88,34.09],[1,1.01,12]],"ltp":2.06,"tv":206.45,"id":8679184}]}]}
{"op":"mcm","clk":"4232099632","pt":1631551818770,"mc":[{"id":"1.187594321","rc":[{"batb":[[0,1.01,12],[1,1.01,0]],"ltp":2.54,"tv":0.92,"id":11862899},{"batb":[[0,1.01,12],[1,1.01,0]],"ltp":2.06,"tv":206.45,"id":8679184}]}]}
{"op":"mcm","clk":"4232099997","pt":1631551823638,"mc":[{"id":"1.187594321","rc":[{"batb":[[0,1.71,42.25],[1,1.01,12]],"ltp":2.54,"tv":0.92,"id":11862899},{"batb":[[0,2.06,28.3],[1,1.01,12]],"ltp":2.06,"tv":206.45,"id":8679184}]}]}
{"op":"mcm","clk":"4232102854","pt":1631551857943,"mc":[{"id":"1.187594321","rc":[{"batb":[[0,1.01,12],[1,1.01,0]],"ltp":2.54,"tv":0.92,"id":11862899},{"batb":[[0,1.01,12],[1,1.01,0]],"ltp":2.06,"tv":206.45,"id":8679184}]}]}
{"op":"mcm","clk":"4232103343","pt":1631551862935,"mc":[{"id":"1.187594321","rc":[{"batb":[[0,1.85,35.29],[1,1.01,12]],"ltp":2.54,"tv":0.92,"id":11862899},{"batb":[[0,1.88,34.09],[1,1.01,12]],"ltp":2.06,"tv":206.45,"id":8679184}]}]}
{"op":"mcm","clk":"4232105317","pt":1631551886446,"mc":[{"id":"1.187594321","rc":[{"batb":[[0,1.01,12],[1,1.01,0]],"ltp":2.54,"tv":0.92,"id":11862899},{"batb":[[0,1.01,12],[1,1.01,0]],"ltp":2.06,"tv":206.45,"id":8679184}]}]}
{"op":"mcm","clk":"4232105752","pt":1631551891467,"mc":[{"id":"1.187594321","rc":[{"batb":[[0,1.71,42.25],[1,1.01,12]],"ltp":2.54,"tv":0.92,"id":11862899},{"batb":[[0,2.06,28.3],[1,1.01,12]],"ltp":2.06,"tv":206.45,"id":8679184}]}]}
{"op":"mcm","clk":"4232107122","pt":1631551909682,"mc":[{"id":"1.187594321","rc":[{"batb":[[0,1.01,12],[1,1.01,0]],"ltp":2.54,"tv":0.92,"id":11862899},{"batb":[[0,1.01,12],[1,1.01,0]],"ltp":2.06,"tv":206.45,"id":8679184}]}]}
{"op":"mcm","clk":"4232107498","pt":1631551914591,"mc":[{"id":"1.187594321","rc":[{"batb":[[0,1.78,38.46],[1,1.01,12]],"ltp":2.54,"tv":0.92,"id":11862899},{"batb":[[0,1.98,30.61],[1,1.01,12]],"ltp":2.06,"tv":206.45,"id":8679184}]}]}
{"op":"mcm","clk":"4232108296","pt":1631551923523,"mc":[{"id":"1.187594321","rc":[{"batb":[[0,1.01,12],[1,1.01,0]],"ltp":2.54,"tv":0.92,"id":11862899},{"batb":[[0,1.01,12],[1,1.01,0]],"ltp":2.06,"tv":206.45,"id":8679184}]}]}
{"op":"mcm","clk":"4232108723","pt":1631551928533,"mc":[{"id":"1.187594321","rc":[{"batb":[[0,1.6,49.99],[1,1.01,12]],"ltp":2.54,"tv":0.92,"id":11862899},{"batb":[[0,2.2,24.99],[1,1.01,12]],"ltp":2.06,"tv":206.45,"id":8679184}]}]}
{"op":"mcm","clk":"4232111446","pt":1631551961834,"mc":[{"id":"1.187594321","rc":[{"batb":[[0,1.01,12],[1,1.01,0]],"ltp":2.54,"tv":0.92,"id":11862899},{"batb":[[0,1.01,12],[1,1.01,0]],"ltp":2.06,"tv":206.45,"id":8679184}]}]}
{"op":"mcm","clk":"4232111864","pt":1631551966840,"mc":[{"id":"1.187594321","rc":[{"batb":[[0,1.73,41.09],[1,1.01,12]],"ltp":2.54,"tv":0.92,"id":11862899},{"batb":[[0,2,30],[1,1.01,12]],"ltp":2.06,"tv":206.45,"id":8679184}]}]}
{"op":"mcm","clk":"4232114459","pt":1631551998979,"mc":[{"id":"1.187594321","rc":[{"batb":[[0,1.01,12],[1,1.01,0]],"ltp":2.54,"tv":0.92,"id":11862899},{"batb":[[0,1.01,12],[1,1.01,0]],"ltp":2.06,"tv":206.45,"id":8679184}]}]}
{"op":"mcm","clk":"4232114841","pt":1631552004021,"mc":[{"id":"1.187594321","rc":[{"batb":[[0,1.6,49.99],[1,1.01,12]],"ltp":2.54,"tv":0.92,"id":11862899},{"batb":[[0,2.2,24.99],[1,1.01,12]],"ltp":2.06,"tv":206.45,"id":8679184}]}]}
{"op":"mcm","clk":"4232116721","pt":1631552029120,"mc":[{"id":"1.187594321","rc":[{"batb":[[0,1.01,12],[1,1.01,0]],"ltp":2.54,"tv":0.92,"id":11862899},{"batb":[[0,1.01,12],[1,1.01,0]],"ltp":2.06,"tv":206.45,"id":8679184}]}]}
{"op":"mcm","clk":"4232117148","pt":1631552034129,"mc":[{"id":"1.187594321","rc":[{"batb":[[0,1.73,41.09],[1,1.01,12]],"ltp":2.54,"tv":0.92,"id":11862899},{"batb":[[0,2,30],[1,1.01,12]],"ltp":2.06,"tv":206.45,"id":8679184}]}]}
{"op":"mcm","clk":"4232119203","pt":1631552060356,"mc":[{"id":"1.187594321","rc":[{"batb":[[0,1.01,12],[1,1.01,0]],"ltp":2.54,"tv":0.92,"id":11862899}]}]}
{"op":"mcm","clk":"4232119615","pt":1631552065360,"mc":[{"id":"1.187594321","rc":[{"batb":[[0,1.78,38.46],[1,1.01,12]],"ltp":2.54,"tv":0.92,"id":11862899}]}]}
{"op":"mcm","clk":"4232120409","pt":1631552076094,"mc":[{"id":"1.187594321","rc":[{"batb":[[0,1.01,12],[1,1.01,0]],"ltp":2.54,"tv":0.92,"id":11862899},{"batb":[[0,1.01,12],[1,1.01,0]],"ltp":2.06,"tv":206.45,"id":8679184}]}]}
{"op":"mcm","clk":"4232120815","pt":1631552081103,"mc":[{"id":"1.187594321","rc":[{"batb":[[0,1.88,34.09],[1,1.01,12]],"ltp":2.54,"tv":0.92,"id":11862899},{"batb":[[0,1.85,35.29],[1,1.01,12]],"ltp":2.06,"tv":206.45,"id":8679184}]}]}
{"op":"mcm","clk":"4232122230","pt":1631552100829,"mc":[{"id":"1.187594321","rc":[{"batb":[[0,1.01,12],[1,1.01,0]],"ltp":2.54,"tv":0.92,"id":11862899},{"batb":[[0,1.01,12],[1,1.01,0]],"ltp":2.06,"tv":206.45,"id":8679184}]}]}
{"op":"mcm","clk":"4232122624","pt":1631552105743,"mc":[{"id":"1.187594321","rc":[{"batb":[[0,2.1,27.27],[1,1.01,12]],"ltp":2.54,"tv":0.92,"id":11862899},{"batb":[[0,1.65,46.15],[1,1.01,12]],"ltp":2.06,"tv":206.45,"id":8679184}]}]}
{"op":"mcm","clk":"4232125782","pt":1631552149080,"mc":[{"id":"1.187594321","rc":[{"batb":[[0,1.01,12],[1,1.01,0]],"ltp":2.54,"tv":0.92,"id":11862899},{"batb":[[0,1.01,12],[1,1.01,0]],"ltp":2.06,"tv":206.45,"id":8679184}]}]}
{"op":"mcm","clk":"4232126133","pt":1631552153956,"mc":[{"id":"1.187594321","rc":[{"batb":[[0,1.98,30.61],[1,1.01,12]],"ltp":2.54,"tv":0.92,"id":11862899},{"batb":[[0,1.78,38.46],[1,1.01,12]],"ltp":2.06,"tv":206.45,"id":8679184}]}]}
{"op":"mcm","clk":"4232129228","pt":1631552198548,"mc":[{"id":"1.187594321","rc":[{"batb":[[0,1.01,12],[1,1.01,0]],"ltp":2.54,"tv":0.92,"id":11862899},{"batb":[[0,1.01,12],[1,1.01,0]],"ltp":2.06,"tv":206.45,"id":8679184}]}]}
{"op":"mcm","clk":"4232129565","pt":1631552203411,"mc":[{"id":"1.187594321","rc":[{"batb":[[0,1.85,35.29],[1,1.01,12]],"ltp":2.54,"tv":0.92,"id":11862899},{"batb":[[0,1.88,34.09],[1,1.01,12]],"ltp":2.06,"tv":206.45,"id":8679184}]}]}
{"op":"mcm","clk":"4232131777","pt":1631552233978,"mc":[{"id":"1.187594321","rc":[{"batl":[[0,1.88,60]],"ltp":2.54,"tv":0.92,"id":11862899}]}]}
{"op":"mcm","clk":"4232132122","pt":1631552238897,"mc":[{"id":"1.187594321","rc":[{"batb":[[0,1.01,12],[1,1.01,0]],"ltp":2.54,"tv":0.92,"id":11862899},{"batb":[[0,1.01,12],[1,1.01,0]],"ltp":2.06,"tv":206.45,"id":8679184}]}]}
{"op":"mcm","clk":"4232132456","pt":1631552243673,"mc":[{"id":"1.187594321","rc":[{"batb":[[0,1.85,35.29],[1,1.01,12]],"ltp":2.06,"tv":206.45,"id":8679184}]}]}
{"op":"mcm","clk":"4232132553","pt":1631552245080,"mc":[{"id":"1.187594321","rc":[{"trd":[[1.88,50.12]],"batl":[[0,1.88,34.94]],"ltp":1.88,"tv":51.04,"id":11862899}],"tv":257.49}]}
{"op":"mcm","clk":"4232132718","pt":1631552247583,"mc":[{"id":"1.187594321","rc":[{"trd":[[1.88,85.06]],"ltp":1.88,"tv":85.98,"id":11862899},{"trd":[[2.12,30.97]],"batl":[[0,2.12,369.96]],"ltp":2.12,"tv":237.42,"id":8679184}],"tv":323.4}]}
{"op":"mcm","clk":"4232132798","pt":1631552248613,"mc":[{"id":"1.187594321","rc":[{"batl":[[0,2.12,681.89]],"ltp":2.12,"tv":237.42,"id":8679184}]}]}
{"op":"mcm","clk":"4232132870","pt":1631552249598,"mc":[{"id":"1.187594321","rc":[{"batl":[[0,2.12,313.02]],"ltp":2.12,"tv":237.42,"id":8679184}]}]}
{"op":"mcm","clk":"4232132948","pt":1631552250599,"mc":[{"id":"1.187594321","rc":[{"batl":[[0,2.12,159.76]],"ltp":2.12,"tv":237.42,"id":8679184}]}]}
{"op":"mcm","clk":"4232133043","pt":1631552251590,"mc":[{"id":"1.187594321","rc":[{"batl":[[0,2.12,308.58]],"ltp":2.12,"tv":237.42,"id":8679184}]}]}
{"op":"mcm","clk":"4232133100","pt":1631552252415,"mc":[{"id":"1.187594321","rc":[{"batb":[[0,1.88,34.09],[1,1.01,12]],"ltp":1.88,"tv":85.98,"id":11862899},{"batl":[[0,2.12,141.5]],"ltp":2.12,"tv":237.42,"id":8679184}]}]}
{"op":"mcm","clk":"4232133143","pt":1631552252997,"mc":[{"id":"1.187594321","rc":[{"batl":[[0,2.12,28.3]],"ltp":2.12,"tv":237.42,"id":8679184}]}]}
{"op":"mcm","clk":"4232134180","pt":1631552269522,"mc":[{"id":"1.187594321","rc":[{"trd":[[1.88,93.44]],"batb":[[0,1.88,29.9]],"ltp":1.88,"tv":94.36,"id":11862899}],"tv":331.78}]}
{"op":"mcm","clk":"4232134205","pt":1631552269935,"mc":[{"id":"1.187594321","rc":[{"batb":[[0,1.01,12],[1,1.01,0]],"ltp":1.88,"tv":94.36,"id":11862899}]}]}
{"op":"mcm","clk":"4232134490","pt":1631552274818,"mc":[{"id":"1.187594321","rc":[{"batb":[[0,1.88,34.09],[1,1.01,12]],"ltp":1.88,"tv":94.36,"id":11862899}]}]}
{"op":"mcm","clk":"4232135210","pt":1631552285251,"mc":[{"id":"1.187594321","rc":[{"batb":[[0,1.01,12],[1,1.01,0]],"ltp":1.88,"tv":94.36,"id":11862899},{"batb":[[0,1.01,12],[1,1.01,0]],"ltp":2.12,"tv":237.42,"id":8679184}]}]}
{"op":"mcm","clk":"4232135556","pt":1631552290237,"mc":[{"id":"1.187594321","rc":[{"batb":[[0,2.1,27.27],[1,1.01,12]],"ltp":1.88,"tv":94.36,"id":11862899},{"batb":[[0,1.65,46.15],[1,1.01,12]],"ltp":2.12,"tv":237.42,"id":8679184}]}]}
{"op":"mcm","clk":"4232137363","pt":1631552315286,"mc":[{"id":"1.187594321","rc":[{"batb":[[0,1.01,12],[1,1.01,0]],"ltp":1.88,"tv":94.36,"id":11862899},{"batb":[[0,1.01,12],[1,1.01,0]],"ltp":2.12,"tv":237.42,"id":8679184}]}]}
{"op":"mcm","clk":"4232137730","pt":1631552320280,"mc":[{"id":"1.187594321","rc":[{"batb":[[0,2.06,28.3],[1,1.01,12]],"ltp":1.88,"tv":94.36,"id":11862899},{"batb":[[0,1.71,42.25],[1,1.01,12]],"ltp":2.12,"tv":237.42,"id":8679184}]}]}
{"op":"mcm","clk":"4232138596","pt":1631552330618,"mc":[{"id":"1.187594321","rc":[{"batb":[[0,1.01,12],[1,1.01,0]],"ltp":1.88,"tv":94.36,"id":11862899},{"batb":[[0,1.01,12],[1,1.01,0]],"ltp":2.12,"tv":237.42,"id":8679184}]}]}
{"op":"mcm","clk":"4232138992","pt":1631552335591,"mc":[{"id":"1.187594321","rc":[{"batb":[[0,2.34,22.38],[1,1.01,12]],"ltp":1.88,"tv":94.36,"id":11862899},{"batb":[[0,1.55,54.54],[1,1.01,12]],"ltp":2.12,"tv":237.42,"id":8679184}]}]}
{"op":"mcm","clk":"4232141161","pt":1631552361448,"mc":[{"id":"1.187594321","rc":[{"batb":[[0,1.01,12],[1,1.01,0]],"ltp":1.88,"tv":94.36,"id":11862899},{"batb":[[0,1.01,12],[1,1.01,0]],"ltp":2.12,"tv":237.42,"id":8679184}]}]}
{"op":"mcm","clk":"4232141815","pt":1631552366487,"mc":[{"id":"1.187594321","rc":[{"batb":[[0,2.5,20],[1,1.01,12]],"ltp":1.88,"tv":94.36,"id":11862899},{"batb":[[0,1.48,62.5],[1,1.01,12]],"ltp":2.12,"tv":237.42,"id":8679184}]}]}
{"op":"mcm","clk":"4232152637","pt":1631552476177,"mc":[{"id":"1.187594321","rc":[{"batb":[[0,1.01,12],[1,1.01,0]],"ltp":1.88,"tv":94.36,"id":11862899},{"trd":[[1.65,1.41],[1.8,200.03],[2.06,3.42],[2.12,31]],"batb":[[0,1.01,12],[1,1.01,0]],"ltp":2.12,"tv":237.53,"id":8679184}],"tv":331.89}]}
{"op":"mcm","clk":"4232153130","pt":1631552481075,"mc":[{"id":"1.187594321","rc":[{"batb":[[0,2.34,22.38],[1,1.01,12]],"ltp":1.88,"tv":94.36,"id":11862899},{"batb":[[0,1.55,54.54],[1,1.01,12]],"ltp":2.12,"tv":237.53,"id":8679184}]}]}
{"op":"mcm","clk":"4232155357","pt":1631552503519,"mc":[{"id":"1.187594321","rc":[{"batb":[[0,1.01,12],[1,1.01,0]],"ltp":1.88,"tv":94.36,"id":11862899},{"batb":[[0,1.01,12],[1,1.01,0]],"ltp":2.12,"tv":237.53,"id":8679184}]}]}
{"op":"mcm","clk":"4232155809","pt":1631552508326,"mc":[{"id":"1.187594321","rc":[{"batb":[[0,2.16,25.86],[1,1.01,12]],"ltp":1.88,"tv":94.36,"id":11862899},{"batb":[[0,1.63,47.61],[1,1.01,12]],"ltp":2.12,"tv":237.53,"id":8679184}]}]}
{"op":"mcm","clk":"4232157677","pt":1631552529667,"mc":[{"id":"1.187594321","rc":[{"batb":[[0,1.01,12],[1,1.01,0]],"ltp":1.88,"tv":94.36,"id":11862899},{"batb":[[0,1.01,12],[1,1.01,0]],"ltp":2.12,"tv":237.53,"id":8679184}]}]}
{"op":"mcm","clk":"4232158100","pt":1631552534562,"mc":[{"id":"1.187594321","rc":[{"batb":[[0,2.34,22.38],[1,1.01,12]],"ltp":1.88,"tv":94.36,"id":11862899},{"batb":[[0,1.55,54.54],[1,1.01,12]],"ltp":2.12,"tv":237.53,"id":8679184}]}]}
{"op":"mcm","clk":"4232160077","pt":1631552561265,"mc":[{"id":"1.187594321","rc":[{"batb":[[0,1.01,12],[1,1.01,0]],"ltp":1.88,"tv":94.36,"id":11862899},{"batb":[[0,1.01,12],[1,1.01,0]],"ltp":2.12,"tv":237.53,"id":8679184}]}]}
{"op":"mcm","clk":"4232160398","pt":1631552566159,"mc":[{"id":"1.187594321","rc":[{"batb":[[0,2.16,25.86],[1,1.01,12]],"ltp":1.88,"tv":94.36,"id":11862899},{"batb":[[0,1.63,47.61],[1,1.01,12]],"ltp":2.12,"tv":237.53,"id":8679184}]}]}
{"op":"mcm","clk":"4232163415","pt":1631552606426,"mc":[{"id":"1.187594321","rc":[{"batb":[[0,1.01,12],[1,1.01,0]],"ltp":1.88,"tv":94.36,"id":11862899},{"batb":[[0,1.01,12],[1,1.01,0]],"ltp":2.12,"tv":237.53,"id":8679184}]}]}
{"op":"mcm","clk":"4232163797","pt":1631552611320,"mc":[{"id":"1.187594321","rc":[{"batb":[[0,2.34,22.38],[1,1.01,12]],"ltp":1.88,"tv":94.36,"id":11862899},{"batb":[[0,1.55,54.54],[1,1.01,12]],"ltp":2.12,"tv":237.53,"id":8679184}]}]}
{"op":"mcm","clk":"4232166124","pt":1631552642096,"mc":[{"id":"1.187594321","rc":[{"batb":[[0,1.01,12],[1,1.01,0]],"ltp":1.88,"tv":94.36,"id":11862899},{"batb":[[0,1.01,12],[1,1.01,0]],"ltp":2.12,"tv":237.53,"id":8679184}]}]}
{"op":"mcm","clk":"4232166561","pt":1631552647092,"mc":[{"id":"1.187594321","rc":[{"batb":[[0,2.1,27.27],[1,1.01,12]],"ltp":1.88,"tv":94.36,"id":11862899},{"batb":[[0,1.65,46.15],[1,1.01,12]],"ltp":2.12,"tv":237.53,"id":8679184}]}]}
{"op":"mcm","clk":"4232169052","pt":1631552679149,"mc":[{"id":"1.187594321","rc":[{"batb":[[0,1.01,12],[1,1.01,0]],"ltp":1.88,"tv":94.36,"id":11862899},{"batb":[[0,1.01,12],[1,1.01,0]],"ltp":2.12,"tv":237.53,"id":8679184}]}]}
{"op":"mcm","clk":"4232169442","pt":1631552684019,"mc":[{"id":"1.187594321","rc":[{"batb":[[0,1.88,34.09],[1,1.01,12]],"ltp":1.88,"tv":94.36,"id":11862899},{"batb":[[0,1.85,35.29],[1,1.01,12]],"ltp":2.12,"tv":237.53,"id":8679184}]}]}
{"op":"mcm","clk":"4232171059","pt":1631552702637,"mc":[{"id":"1.187594321","rc":[{"batb":[[0,1.01,12],[1,1.01,0]],"ltp":1.88,"tv":94.36,"id":11862899},{"batb":[[0,1.01,12],[1,1.01,0]],"ltp":2.12,"tv":237.53,"id":8679184}]}]}
{"op":"mcm","clk":"4232171560","pt":1631552707556,"mc":[{"id":"1.187594321","rc":[{"batb":[[0,2.06,28.3],[1,1.01,12]],"ltp":1.88,"tv":94.36,"id":11862899},{"batb":[[0,1.71,42.25],[1,1.01,12]],"ltp":2.12,"tv":237.53,"id":8679184}]}]}
{"op":"mcm","clk":"4232174479","pt":1631552742193,"mc":[{"id":"1.187594321","rc":[{"batb":[[0,1.01,12],[1,1.01,0]],"ltp":1.88,"tv":94.36,"id":11862899},{"batb":[[0,1.01,12],[1,1.01,0]],"ltp":2.12,"tv":237.53,"id":8679184}]}]}
{"op":"mcm","clk":"4232174868","pt":1631552747083,"mc":[{"id":"1.187594321","rc":[{"batb":[[0,1.88,34.09],[1,1.01,12]],"ltp":1.88,"tv":94.36,"id":11862899},{"batb":[[0,1.85,35.29],[1,1.01,12]],"ltp":2.12,"tv":237.53,"id":8679184}]}]}
{"op":"mcm","clk":"4232176283","pt":1631552764787,"mc":[{"id":"1.187594321","rc":[{"batb":[[0,1.01,12],[1,1.01,0]],"ltp":1.88,"tv":94.36,"id":11862899},{"batb":[[0,1.01,12],[1,1.01,0]],"ltp":2.12,"tv":237.53,"id":8679184}]}]}
{"op":"mcm","clk":"4232176709","pt":1631552769810,"mc":[{"id":"1.187594321","rc":[{"batb":[[0,2.06,28.3],[1,1.01,12]],"ltp":1.88,"tv":94.36,"id":11862899},{"batb":[[0,1.71,42.25],[1,1.01,12]],"ltp":2.12,"tv":237.53,"id":8679184}]}]}
{"op":"mcm","clk":"4232178279","pt":1631552788164,"mc":[{"id":"1.187594321","rc":[{"batb":[[0,1.01,12],[1,1.01,0]],"ltp":2.12,"tv":237.53,"id":8679184}]}]}
{"op":"mcm","clk":"4232178708","pt":1631552793132,"mc":[{"id":"1.187594321","rc":[{"batb":[[0,1.73,41.09],[1,1.01,12]],"ltp":2.12,"tv":237.53,"id":8679184}]}]}
{"op":"mcm","clk":"4232179594","pt":1631552803858,"mc":[{"id":"1.187594321","rc":[{"batb":[[0,1.01,12],[1,1.01,0]],"ltp":1.88,"tv":94.36,"id":11862899},{"batb":[[0,1.01,12],[1,1.01,0]],"ltp":2.12,"tv":237.53,"id":8679184}]}]}
{"op":"mcm","clk":"4232180005","pt":1631552808741,"mc":[{"id":"1.187594321","rc":[{"batb":[[0,1.85,35.29],[1,1.01,12]],"ltp":1.88,"tv":94.36,"id":11862899},{"batb":[[0,1.88,34.09],[1,1.01,12]],"ltp":2.12,"tv":237.53,"id":8679184}]}]}
{"op":"mcm","clk":"4232183019","pt":1631552842721,"mc":[{"id":"1.187594321","rc":[{"batb":[[0,1.01,12],[1,1.01,0]],"ltp":1.88,"tv":94.36,"id":11862899},{"batb":[[0,1.01,12],[1,1.01,0]],"ltp":2.12,"tv":237.53,"id":8679184}]}]}
{"op":"mcm","clk":"4232183485","pt":1631552847592,"mc":[{"id":"1.187594321","rc":[{"batb":[[0,2.06,28.3],[1,1.01,12]],"ltp":1.88,"tv":94.36,"id":11862899},{"batb":[[0,1.71,42.25],[1,1.01,12]],"ltp":2.12,"tv":237.53,"id":8679184}]}]}
{"op":"mcm","clk":"4232185282","pt":1631552868612,"mc":[{"id":"1.187594321","rc":[{"trd":[[2.06,8.68]],"batb":[[0,2.06,23.96]],"ltp":2.06,"tv":103.03,"id":11862899}],"tv":340.57}]}
{"op":"mcm","clk":"4232185318","pt":1631552869041,"mc":[{"id":"1.187594321","rc":[{"batb":[[0,1.01,12],[1,1.01,0]],"ltp":2.06,"tv":103.03,"id":11862899}]}]}
{"op":"mcm","clk":"4232185441","pt":1631552870243,"mc":[{"id":"1.187594321","rc":[{"batb":[[0,1.01,12],[1,1.01,0]],"ltp":2.12,"tv":237.53,"id":8679184}]}]}
{"op":"mcm","clk":"4232185923","pt":1631552875137,"mc":[{"id":"1.187594321","rc":[{"batb":[[0,1.55,54.54],[1,1.01,12]],"ltp":2.12,"tv":237.53,"id":8679184}]}]}
{"op":"mcm","clk":"4232186294","pt":1631552879160,"mc":[{"id":"1.187594321","rc":[{"batb":[[0,2.34,22.38],[1,1.01,12]],"ltp":2.06,"tv":103.03,"id":11862899}]}]}
{"op":"mcm","clk":"4232189463","pt":1631552915373,"mc":[{"id":"1.187594321","rc":[{"batl":[[0,2.6,0.05]],"ltp":2.06,"tv":103.03,"id":11862899}]}]}
{"op":"mcm","clk":"4232190020","pt":1631552921380,"mc":[{"id":"1.187594321","rc":[{"batb":[[0,1.01,12],[1,1.01,0]],"ltp":2.06,"tv":103.03,"id":11862899},{"batb":[[0,1.01,12],[1,1.01,0]],"ltp":2.12,"tv":237.53,"id":8679184}]}]}
{"op":"mcm","clk":"4232190445","pt":1631552926380,"mc":[{"id":"1.187594321","rc":[{"batb":[[0,2.26,23.8],[1,1.01,12]],"ltp":2.06,"tv":103.03,"id":11862899},{"batb":[[0,1.58,51.72],[1,1.01,12]],"ltp":2.12,"tv":237.53,"id":8679184}]}]}
{"op":"mcm","clk":"4232190998","pt":1631552932894,"mc":[{"id":"1.187594321","rc":[{"batb":[[0,1.01,12],[1,1.01,0]],"ltp":2.06,"tv":103.03,"id":11862899},{"batb":[[0,1.01,12],[1,1.01,0]],"ltp":2.12,"tv":237.53,"id":8679184}]}]}
{"op":"mcm","clk":"4232191472","pt":1631552937794,"mc":[{"id":"1.187594321","rc":[{"batb":[[0,2,30],[1,1.01,12]],"ltp":2.06,"tv":103.03,"id":11862899},{"batb":[[0,1.73,41.09],[1,1.01,12]],"ltp":2.12,"tv":237.53,"id":8679184}]}]}
{"op":"mcm","clk":"4232192482","pt":1631552948419,"mc":[{"id":"1.187594321","rc":[{"trd":[[2,0.1]],"batb":[[0,1.01,12],[1,1.01,0]],"ltp":2.0,"tv":103.13,"id":11862899}],"tv":340.67}]}
{"op":"mcm","clk":"4232192969","pt":1631552953303,"mc":[{"id":"1.187594321","rc":[{"batb":[[0,2,30],[1,1.01,12]],"ltp":2.0,"tv":103.13,"id":11862899}]}]}
{"op":"mcm","clk":"4232194114","pt":1631552965746,"mc":[{"id":"1.187594321","rc":[{"batb":[[0,1.01,12],[1,1.01,0]],"ltp":2.0,"tv":103.13,"id":11862899},{"batb":[[0,1.01,12],[1,1.01,0]],"ltp":2.12,"tv":237.53,"id":8679184}]}]}
{"op":"mcm","clk":"4232194560","pt":1631552970641,"mc":[{"id":"1.187594321","rc":[{"batb":[[0,1.85,35.29],[1,1.01,12]],"ltp":2.0,"tv":103.13,"id":11862899},{"batb":[[0,1.88,34.09],[1,1.01,12]],"ltp":2.12,"tv":237.53,"id":8679184}]}]}
{"op":"mcm","clk":"4232195512","pt":1631552981156,"mc":[{"id":"1.187594321","rc":[{"batb":[[0,1.01,12],[1,1.01,0]],"ltp":2.0,"tv":103.13,"id":11862899},{"batb":[[0,1.01,12],[1,1.01,0]],"ltp":2.12,"tv":237.53,"id":8679184}]}]}
{"op":"mcm","clk":"4232195966","pt":1631552986159,"mc":[{"id":"1.187594321","rc":[{"batb":[[0,1.78,38.46],[1,1.01,12]],"ltp":2.0,"tv":103.13,"id":11862899},{"batb":[[0,1.98,30.61],[1,1.01,12]],"ltp":2.12,"tv":237.53,"id":8679184}]}]}
{"op":"mcm","clk":"4232198436","pt":1631553011872,"mc":[{"id":"1.187594321","rc":[{"batb":[[0,1.01,12],[1,1.01,0]],"ltp":2.0,"tv":103.13,"id":11862899},{"batb":[[0,1.01,12],[1,1.01,0]],"ltp":2.12,"tv":237.53,"id":8679184}]}]}
{"op":"mcm","clk":"4232198877","pt":1631553016903,"mc":[{"id":"1.187594321","rc":[{"batb":[[0,2,30],[1,1.01,12]],"ltp":2.0,"tv":103.13,"id":11862899},{"batb":[[0,1.73,41.09],[1,1.01,12]],"ltp":2.12,"tv":237.53,"id":8679184}]}]}
{"op":"mcm","clk":"4232200725","pt":1631553036321,"mc":[{"id":"1.187594321","rc":[{"batb":[[0,1.01,12],[1,1.01,0]],"ltp":2.12,"tv":237.53,"id":8679184}]}]}
{"op":"mcm","clk":"4232201202","pt":1631553041232,"mc":[{"id":"1.187594321","rc":[{"batb":[[0,1.78,38.46],[1,1.01,12]],"ltp":2.12,"tv":237.53,"id":8679184}]}]}
{"op":"mcm","clk":"4232202423","pt":1631553053222,"mc":[{"id":"1.187594321","rc":[{"batb":[[0,1.01,12],[1,1.01,0]],"ltp":2.0,"tv":103.13,"id":11862899},{"batb":[[0,1.01,12],[1,1.01,0]],"ltp":2.12,"tv":237.53,"id":8679184}]}]}
{"op":"mcm","clk":"4232202928","pt":1631553058252,"mc":[{"id":"1.187594321","rc":[{"batb":[[0,1.85,35.29],[1,1.01,12]],"ltp":2.0,"tv":103.13,"id":11862899},{"batb":[[0,1.88,34.09],[1,1.01,12]],"ltp":2.12,"tv":237.53,"id":8679184}]}]}
{"op":"mcm","clk":"4232204467","pt":1631553073683,"mc":[{"id":"1.187594321","rc":[{"batb":[[0,1.01,12],[1,1.01,0]],"ltp":2.0,"tv":103.13,"id":11862899}]}]}
{"op":"mcm","clk":"4232204932","pt":1631553078542,"mc":[{"id":"1.187594321","rc":[{"batb":[[0,1.78,38.46],[1,1.01,12]],"ltp":2.0,"tv":103.13,"id":11862899}]}]}
{"op":"mcm","clk":"4232205731","pt":1631553086284,"mc":[{"id":"1.187594321","rc":[{"batb":[[0,1.01,12],[1,1.01,0]],"ltp":2.0,"tv":103.13,"id":11862899},{"batb":[[0,1.01,12],[1,1.01,0]],"ltp":2.12,"tv":237.53,"id":8679184}]}]}
{"op":"mcm","clk":"4232206186","pt":1631553091270,"mc":[{"id":"1.187594321","rc":[{"batb":[[0,2,30],[1,1.01,12]],"ltp":2.0,"tv":103.13,"id":11862899},{"batb":[[0,1.73,41.09],[1,1.01,12]],"ltp":2.12,"tv":237.53,"id":8679184}]}]}
{"op":"mcm","clk":"4232207572","pt":1631553106689,"mc":[{"id":"1.187594321","rc":[{"batb":[[0,1.01,12],[1,1.01,0]],"ltp":2.0,"tv":103.13,"id":11862899},{"batb":[[0,1.01,12],[1,1.01,0]],"ltp":2.12,"tv":237.53,"id":8679184}]}]}
{"op":"mcm","clk":"4232207984","pt":1631553111476,"mc":[{"id":"1.187594321","rc":[{"batb":[[0,2.26,23.8],[1,1.01,12]],"ltp":2.0,"tv":103.13,"id":11862899},{"batb":[[0,1.58,51.72],[1,1.01,12]],"ltp":2.12,"tv":237.53,"id":8679184}]}]}
{"op":"mcm","clk":"4232209208","pt":1631553125229,"mc":[{"id":"1.187594321","rc":[{"batb":[[0,1.01,12],[1,1.01,0]],"ltp":2.0,"tv":103.13,"id":11862899},{"batb":[[0,1.01,12],[1,1.01,0]],"ltp":2.12,"tv":237.53,"id":8679184}]}]}
{"op":"mcm","clk":"4232209711","pt":1631553130124,"mc":[{"id":"1.187594321","rc":[{"batb":[[0,2.2,24.99],[1,1.01,12]],"ltp":2.0,"tv":103.13,"id":11862899},{"batb":[[0,1.6,49.99],[1,1.01,12]],"ltp":2.12,"tv":237.53,"id":8679184}]}]}
{"op":"mcm","clk":"4232210693","pt":1631553140714,"mc":[{"id":"1.187594321","rc":[{"batb":[[0,1.01,12],[1,1.01,0]],"ltp":2.0,"tv":103.13,"id":11862899},{"batb":[[0,1.01,12],[1,1.01,0]],"ltp":2.12,"tv":237.53,"id":8679184}]}]}
{"op":"mcm","clk":"4232211124","pt":1631553145702,"mc":[{"id":"1.187594321","rc":[{"batb":[[0,2.5,20],[1,1.01,12]],"ltp":2.0,"tv":103.13,"id":11862899},{"batb":[[0,1.48,62.5],[1,1.01,12]],"ltp":2.12,"tv":237.53,"id":8679184}]}]}
{"op":"mcm","clk":"4232222359","pt":1631553270302,"mc":[{"id":"1.187594321","rc":[{"batb":[[0,1.01,12],[1,1.01,0]],"ltp":2.0,"tv":103.13,"id":11862899},{"batb":[[0,1.01,12],[1,1.01,0]],"ltp":2.12,"tv":237.53,"id":8679184}]}]}
{"op":"mcm","clk":"4232222818","pt":1631553275207,"mc":[{"id":"1.187594321","rc":[{"batb":[[0,2.84,16.3],[1,1.01,12]],"ltp":2.0,"tv":103.13,"id":11862899},{"batb":[[0,1.38,78.94],[1,1.01,12]],"ltp":2.12,"tv":237.53,"id":8679184}]}]}
{"op":"mcm","clk":"4232226925","pt":1631553317716,"mc":[{"id":"1.187594321","rc":[{"batb":[[0,1.01,12],[1,1.01,0]],"ltp":2.0,"tv":103.13,"id":11862899},{"batb":[[0,1.01,12],[1,1.01,0]],"ltp":2.12,"tv":237.53,"id":8679184}]}]}
{"op":"mcm","clk":"4232227412","pt":1631553322605,"mc":[{"id":"1.187594321","rc":[{"batb":[[0,2.5,20],[1,1.01,12]],"ltp":2.0,"tv":103.13,"id":11862899},{"batb":[[0,1.48,62.5],[1,1.01,12]],"ltp":2.12,"tv":237.53,"id":8679184}]}]}
{"op":"mcm","clk":"4232229622","pt":1631553349553,"mc":[{"id":"1.187594321","rc":[{"batb":[[0,1.01,12],[1,1.01,0]],"ltp":2.0,"tv":103.13,"id":11862899},{"batb":[[0,1.01,12],[1,1.01,0]],"ltp":2.12,"tv":237.53,"id":8679184}]}]}
{"op":"mcm","clk":"4232230003","pt":1631553354427,"mc":[{"id":"1.187594321","rc":[{"batb":[[0,2.84,16.3],[1,1.01,12]],"ltp":2.0,"tv":103.13,"id":11862899},{"batb":[[0,1.38,78.94],[1,1.01,12]],"ltp":2.12,"tv":237.53,"id":8679184}]}]}
{"op":"mcm","clk":"4232231844","pt":1631553374283,"mc":[{"id":"1.187594321","rc":[{"batb":[[0,1.01,12],[1,1.01,0]],"ltp":2.0,"tv":103.13,"id":11862899},{"batb":[[0,1.01,12],[1,1.01,0]],"ltp":2.12,"tv":237.53,"id":8679184}]}]}
{"op":"mcm","clk":"4232232349","pt":1631553379182,"mc":[{"id":"1.187594321","rc":[{"batb":[[0,2.5,20],[1,1.01,12]],"ltp":2.0,"tv":103.13,"id":11862899},{"batb":[[0,1.48,62.5],[1,1.01,12]],"ltp":2.12,"tv":237.53,"id":8679184}]}]}
{"op":"mcm","clk":"4232233782","pt":1631553393636,"mc":[{"id":"1.187594321","rc":[{"batb":[[0,1.01,12],[1,1.01,0]],"ltp":2.0,"tv":103.13,"id":11862899},{"batb":[[0,1.01,12],[1,1.01,0]],"ltp":2.12,"tv":237.53,"id":8679184}]}]}
{"op":"mcm","clk":"4232234246","pt":1631553398414,"mc":[{"id":"1.187594321","rc":[{"batb":[[0,2.58,18.98],[1,1.01,12]],"ltp":2.0,"tv":103.13,"id":11862899},{"batb":[[0,1.45,66.66],[1,1.01,12]],"ltp":2.12,"tv":237.53,"id":8679184}]}]}
{"op":"mcm","clk":"4232235200","pt":1631553407315,"mc":[{"id":"1.187594321","rc":[{"batb":[[0,1.01,12],[1,1.01,0]],"ltp":2.0,"tv":103.13,"id":11862899},{"batb":[[0,1.01,12],[1,1.01,0]],"ltp":2.12,"tv":237.53,"id":8679184}]}]}
{"op":"mcm","clk":"4232235742","pt":1631553412348,"mc":[{"id":"1.187594321","rc":[{"batb":[[0,2.26,23.8],[1,1.01,12]],"ltp":2.0,"tv":103.13,"id":11862899},{"batb":[[0,1.58,51.72],[1,1.01,12]],"ltp":2.12,"tv":237.53,"id":8679184}]}]}
{"op":"mcm","clk":"4232238924","pt":1631553442862,"mc":[{"id":"1.187594321","rc":[{"batb":[[0,1.01,12],[1,1.01,0]],"ltp":2.0,"tv":103.13,"id":11862899},{"batb":[[0,1.01,12],[1,1.01,0]],"ltp":2.12,"tv":237.53,"id":8679184}]}]}
{"op":"mcm","clk":"4232239452","pt":1631553447839,"mc":[{"id":"1.187594321","rc":[{"batb":[[0,2.06,28.3],[1,1.01,12]],"ltp":2.0,"tv":103.13,"id":11862899},{"batb":[[0,1.71,42.25],[1,1.01,12]],"ltp":2.12,"tv":237.53,"id":8679184}]}]}
{"op":"mcm","clk":"4232250024","pt":1631553472540,"mc":[{"id":"1.187594321","rc":[{"batb":[[0,1.01,12],[1,1.01,0]],"ltp":2.0,"tv":103.13,"id":11862899},{"batb":[[0,1.01,12],[1,1.01,0]],"ltp":2.12,"tv":237.53,"id":8679184}]}]}
{"op":"mcm","clk":"4232250541","pt":1631553477452,"mc":[{"id":"1.187594321","rc":[{"batb":[[0,2,30],[1,1.01,12]],"ltp":2.0,"tv":103.13,"id":11862899},{"batb":[[0,1.73,41.09],[1,1.01,12]],"ltp":2.12,"tv":237.53,"id":8679184}]}]}
{"op":"mcm","clk":"4232251860","pt":1631553490368,"mc":[{"id":"1.187594321","rc":[{"batb":[[0,1.01,12],[1,1.01,0]],"ltp":2.0,"tv":103.13,"id":11862899},{"batb":[[0,1.01,12],[1,1.01,0]],"ltp":2.12,"tv":237.53,"id":8679184}]}]}
{"op":"mcm","clk":"4232252333","pt":1631553495280,"mc":[{"id":"1.187594321","rc":[{"batb":[[0,1.85,35.29],[1,1.01,12]],"ltp":2.0,"tv":103.13,"id":11862899},{"batb":[[0,1.88,34.09],[1,1.01,12]],"ltp":2.12,"tv":237.53,"id":8679184}]}]}
{"op":"mcm","clk":"4232254727","pt":1631553517810,"mc":[{"id":"1.187594321","rc":[{"batb":[[0,1.01,12],[1,1.01,0]],"ltp":2.0,"tv":103.13,"id":11862899},{"batb":[[0,1.01,12],[1,1.01,0]],"ltp":2.12,"tv":237.53,"id":8679184}]}]}
{"op":"mcm","clk":"4232255235","pt":1631553522706,"mc":[{"id":"1.187594321","rc":[{"batb":[[0,2.06,28.3],[1,1.01,12]],"ltp":2.0,"tv":103.13,"id":11862899},{"batb":[[0,1.71,42.25],[1,1.01,12]],"ltp":2.12,"tv":237.53,"id":8679184}]}]}
{"op":"mcm","clk":"4232256700","pt":1631553536846,"mc":[{"id":"1.187594321","rc":[{"batb":[[0,1.01,12],[1,1.01,0]],"ltp":2.0,"tv":103.13,"id":11862899},{"batb":[[0,1.01,12],[1,1.01,0]],"ltp":2.12,"tv":237.53,"id":8679184}]}]}
{"op":"mcm","clk":"4232257183","pt":1631553541854,"mc":[{"id":"1.187594321","rc":[{"batb":[[0,1.98,30.61],[1,1.01,12]],"ltp":2.0,"tv":103.13,"id":11862899},{"batb":[[0,1.78,38.46],[1,1.01,12]],"ltp":2.12,"tv":237.53,"id":8679184}]}]}
{"op":"mcm","clk":"4232257819","pt":1631553548454,"mc":[{"id":"1.187594321","rc":[{"batb":[[0,1.01,12],[1,1.01,0]],"ltp":2.0,"tv":103.13,"id":11862899},{"batb":[[0,1.01,12],[1,1.01,0]],"ltp":2.12,"tv":237.53,"id":8679184}]}]}
{"op":"mcm","clk":"4232258346","pt":1631553553360,"mc":[{"id":"1.187594321","rc":[{"batb":[[0,2.26,23.8],[1,1.01,12]],"ltp":2.0,"tv":103.13,"id":11862899},{"batb":[[0,1.58,51.72],[1,1.01,12]],"ltp":2.12,"tv":237.53,"id":8679184}]}]}
{"op":"mcm","clk":"4232259620","pt":1631553569251,"mc":[{"id":"1.187594321","rc":[{"batb":[[0,1.01,12],[1,1.01,0]],"ltp":2.0,"tv":103.13,"id":11862899},{"batb":[[0,1.01,12],[1,1.01,0]],"ltp":2.12,"tv":237.53,"id":8679184}]}]}
{"op":"mcm","clk":"4232260185","pt":1631553574188,"mc":[{"id":"1.187594321","rc":[{"batb":[[0,2.2,24.99],[1,1.01,12]],"ltp":2.0,"tv":103.13,"id":11862899},{"batb":[[0,1.6,49.99],[1,1.01,12]],"ltp":2.12,"tv":237.53,"id":8679184}]}]}
{"op":"mcm","clk":"4232261903","pt":1631553594020,"mc":[{"id":"1.187594321","rc":[{"batb":[[0,1.01,12],[1,1.01,0]],"ltp":2.0,"tv":103.13,"id":11862899},{"batb":[[0,1.01,12],[1,1.01,0]],"ltp":2.12,"tv":237.53,"id":8679184}]}]}
{"op":"mcm","clk":"4232262308","pt":1631553598914,"mc":[{"id":"1.187594321","rc":[{"batb":[[0,2.5,20],[1,1.01,12]],"ltp":2.0,"tv":103.13,"id":11862899},{"batb":[[0,1.48,62.5],[1,1.01,12]],"ltp":2.12,"tv":237.53,"id":8679184}]}]}
{"op":"mcm","clk":"4232264745","pt":1631553627749,"mc":[{"id":"1.187594321","rc":[{"batb":[[0,1.01,12],[1,1.01,0]],"ltp":2.0,"tv":103.13,"id":11862899},{"batb":[[0,1.01,12],[1,1.01,0]],"ltp":2.12,"tv":237.53,"id":8679184}]}]}
{"op":"mcm","clk":"4232265184","pt":1631553632665,"mc":[{"id":"1.187594321","rc":[{"batb":[[0,2.34,22.38],[1,1.01,12]],"ltp":2.0,"tv":103.13,"id":11862899},{"batb":[[0,1.55,54.54],[1,1.01,12]],"ltp":2.12,"tv":237.53,"id":8679184}]}]}
{"op":"mcm","clk":"4232267162","pt":1631553654843,"mc":[{"id":"1.187594321","rc":[{"batb":[[0,1.01,12],[1,1.01,0]],"ltp":2.0,"tv":103.13,"id":11862899},{"batb":[[0,1.01,12],[1,1.01,0]],"ltp":2.12,"tv":237.53,"id":8679184}]}]}
{"op":"mcm","clk":"4232267592","pt":1631553659738,"mc":[{"id":"1.187594321","rc":[{"batb":[[0,2.58,18.98],[1,1.01,12]],"ltp":2.0,"tv":103.13,"id":11862899},{"batb":[[0,1.45,66.66],[1,1.01,12]],"ltp":2.12,"tv":237.53,"id":8679184}]}]}
{"op":"mcm","clk":"4232277796","pt":1631553777816,"mc":[{"id":"1.187594321","rc":[{"batb":[[0,1.01,12],[1,1.01,0]],"ltp":2.0,"tv":103.13,"id":11862899},{"batb":[[0,1.01,12],[1,1.01,0]],"ltp":2.12,"tv":237.53,"id":8679184}]}]}
{"op":"mcm","clk":"4232278253","pt":1631553782701,"mc":[{"id":"1.187594321","rc":[{"batb":[[0,3,15],[1,1.01,12]],"ltp":2.0,"tv":103.13,"id":11862899},{"batb":[[0,1.34,88.23],[1,1.01,12]],"ltp":2.12,"tv":237.53,"id":8679184}]}]}
{"op":"mcm","clk":"4232280958","pt":1631553812740,"mc":[{"id":"1.187594321","rc":[{"batb":[[0,1.01,12],[1,1.01,0]],"ltp":2.0,"tv":103.13,"id":11862899},{"batb":[[0,1.01,12],[1,1.01,0]],"ltp":2.12,"tv":237.53,"id":8679184}]}]}
{"op":"mcm","clk":"4232281393","pt":1631553817652,"mc":[{"id":"1.187594321","rc":[{"batb":[[0,3.3,13.04],[1,1.01,12]],"ltp":2.0,"tv":103.13,"id":11862899},{"batb":[[0,1.28,107.14],[1,1.01,12]],"ltp":2.12,"tv":237.53,"id":8679184}]}]}
{"op":"mcm","clk":"4232284076","pt":1631553849328,"mc":[{"id":"1.187594321","rc":[{"batb":[[0,1.01,12],[1,1.01,0]],"ltp":2.0,"tv":103.13,"id":11862899},{"batb":[[0,1.01,12],[1,1.01,0]],"ltp":2.12,"tv":237.53,"id":8679184}]}]}
{"op":"mcm","clk":"4232284506","pt":1631553854219,"mc":[{"id":"1.187594321","rc":[{"batb":[[0,3,15],[1,1.01,12]],"ltp":2.0,"tv":103.13,"id":11862899},{"batb":[[0,1.34,88.23],[1,1.01,12]],"ltp":2.12,"tv":237.53,"id":8679184}]}]}
{"op":"mcm","clk":"4232288391","pt":1631553898057,"mc":[{"id":"1.187594321","rc":[{"batb":[[0,1.01,12],[1,1.01,0]],"ltp":2.0,"tv":103.13,"id":11862899},{"batb":[[0,1.01,12],[1,1.01,0]],"ltp":2.12,"tv":237.53,"id":8679184}]}]}
{"op":"mcm","clk":"4232288857","pt":1631553902980,"mc":[{"id":"1.187594321","rc":[{"batb":[[0,2.66,18.07],[1,1.01,12]],"ltp":2.0,"tv":103.13,"id":11862899},{"batb":[[0,1.42,71.42],[1,1.01,12]],"ltp":2.12,"tv":237.53,"id":8679184}]}]}
{"op":"mcm","clk":"4232293543","pt":1631553955491,"mc":[{"id":"1.187594321","rc":[{"batb":[[0,1.01,12],[1,1.01,0]],"ltp":2.0,"tv":103.13,"id":11862899},{"batb":[[0,1.01,12],[1,1.01,0]],"ltp":2.12,"tv":237.53,"id":8679184}]}]}
{"op":"mcm","clk":"4232294002","pt":1631553960404,"mc":[{"id":"1.187594321","rc":[{"batb":[[0,2.26,23.8],[1,1.01,12]],"ltp":2.0,"tv":103.13,"id":11862899},{"batb":[[0,1.58,51.72],[1,1.01,12]],"ltp":2.12,"tv":237.53,"id":8679184}]}]}
{"op":"mcm","clk":"4232296796","pt":1631553990951,"mc":[{"id":"1.187594321","rc":[{"batb":[[0,1.01,12],[1,1.01,0]],"ltp":2.0,"tv":103.13,"id":11862899},{"batb":[[0,1.01,12],[1,1.01,0]],"ltp":2.12,"tv":237.53,"id":8679184}]}]}
{"op":"mcm","clk":"4232297220","pt":1631553995858,"mc":[{"id":"1.187594321","rc":[{"batb":[[0,2.66,18.07],[1,1.01,12]],"ltp":2.0,"tv":103.13,"id":11862899},{"batb":[[0,1.42,71.42],[1,1.01,12]],"ltp":2.12,"tv":237.53,"id":8679184}]}]}
{"op":"mcm","clk":"4232299179","pt":1631554016060,"mc":[{"id":"1.187594321","rc":[{"batb":[[0,1.01,12],[1,1.01,0]],"ltp":2.0,"tv":103.13,"id":11862899},{"batb":[[0,1.01,12],[1,1.01,0]],"ltp":2.12,"tv":237.53,"id":8679184}]}]}
{"op":"mcm","clk":"4232299652","pt":1631554021057,"mc":[{"id":"1.187594321","rc":[{"batb":[[0,2.84,16.3],[1,1.01,12]],"ltp":2.0,"tv":103.13,"id":11862899},{"batb":[[0,1.38,78.94],[1,1.01,12]],"ltp":2.12,"tv":237.53,"id":8679184}]}]}
{"op":"mcm","clk":"4232300636","pt":1631554031691,"mc":[{"id":"1.187594321","rc":[{"batb":[[0,1.01,12],[1,1.01,0]],"ltp":2.0,"tv":103.13,"id":11862899},{"batb":[[0,1.01,12],[1,1.01,0]],"ltp":2.12,"tv":237.53,"id":8679184}]}]}
{"op":"mcm","clk":"4232301127","pt":1631554036576,"mc":[{"id":"1.187594321","rc":[{"batb":[[0,2.26,23.8],[1,1.01,12]],"ltp":2.0,"tv":103.13,"id":11862899},{"batb":[[0,1.58,51.72],[1,1.01,12]],"ltp":2.12,"tv":237.53,"id":8679184}]}]}
{"op":"mcm","clk":"4232306838","pt":1631554097722,"mc":[{"id":"1.187594321","rc":[{"batb":[[0,1.01,12],[1,1.01,0]],"ltp":2.0,"tv":103.13,"id":11862899},{"batb":[[0,1.01,12],[1,1.01,0]],"ltp":2.12,"tv":237.53,"id":8679184}]}]}
{"op":"mcm","clk":"4232307323","pt":1631554102758,"mc":[{"id":"1.187594321","rc":[{"batb":[[0,2.66,18.07],[1,1.01,12]],"ltp":2.0,"tv":103.13,"id":11862899},{"batb":[[0,1.42,71.42],[1,1.01,12]],"ltp":2.12,"tv":237.53,"id":8679184}]}]}
{"op":"mcm","clk":"4232309364","pt":1631554124990,"mc":[{"id":"1.187594321","rc":[{"batb":[[0,1.01,12],[1,1.01,0]],"ltp":2.0,"tv":103.13,"id":11862899},{"batb":[[0,1.01,12],[1,1.01,0]],"ltp":2.12,"tv":237.53,"id":8679184}]}]}
{"op":"mcm","clk":"4232309822","pt":1631554129975,"mc":[{"id":"1.187594321","rc":[{"batb":[[0,3.15,13.95],[1,1.01,12]],"ltp":2.0,"tv":103.13,"id":11862899},{"batb":[[0,1.31,96.77],[1,1.01,12]],"ltp":2.12,"tv":237.53,"id":8679184}]}]}
{"op":"mcm","clk":"4232311600","pt":1631554148429,"mc":[{"id":"1.187594321","rc":[{"batb":[[0,1.01,12],[1,1.01,0]],"ltp":2.0,"tv":103.13,"id":11862899},{"batb":[[0,1.01,12],[1,1.01,0]],"ltp":2.12,"tv":237.53,"id":8679184}]}]}
{"op":"mcm","clk":"4232312048","pt":1631554153351,"mc":[{"id":"1.187594321","rc":[{"batb":[[0,3.3,13.04],[1,1.01,12]],"ltp":2.0,"tv":103.13,"id":11862899},{"batb":[[0,1.28,107.14],[1,1.01,12]],"ltp":2.12,"tv":237.53,"id":8679184}]}]}
{"op":"mcm","clk":"4232315092","pt":1631554182086,"mc":[{"id":"1.187594321","rc":[{"batb":[[0,1.01,12],[1,1.01,0]],"ltp":2.0,"tv":103.13,"id":11862899},{"batb":[[0,1.01,12],[1,1.01,0]],"ltp":2.12,"tv":237.53,"id":8679184}]}]}
{"op":"mcm","clk":"4232315570","pt":1631554186989,"mc":[{"id":"1.187594321","rc":[{"batb":[[0,2.66,18.07],[1,1.01,12]],"ltp":2.0,"tv":103.13,"id":11862899},{"batb":[[0,1.42,71.42],[1,1.01,12]],"ltp":2.12,"tv":237.53,"id":8679184}]}]}
{"op":"mcm","clk":"4232317330","pt":1631554204207,"mc":[{"id":"1.187594321","rc":[{"batl":[[0,1.57,38.26]],"ltp":2.12,"tv":237.53,"id":8679184}]}]}
{"op":"mcm","clk":"4232321213","pt":1631554240402,"mc":[{"id":"1.187594321","rc":[{"batb":[[0,1.01,12],[1,1.01,0]],"ltp":2.0,"tv":103.13,"id":11862899},{"batb":[[0,1.01,12],[1,1.01,0]],"ltp":2.12,"tv":237.53,"id":8679184}]}]}
{"op":"mcm","clk":"4232321793","pt":1631554245366,"mc":[{"id":"1.187594321","rc":[{"batb":[[0,3.15,13.95],[1,1.01,12]],"ltp":2.0,"tv":103.13,"id":11862899},{"batb":[[0,1.31,96.77],[1,1.01,12]],"ltp":2.12,"tv":237.53,"id":8679184}]}]}
{"op":"mcm","clk":"4232323210","pt":1631554258099,"mc":[{"id":"1.187594321","rc":[{"batl":[[0,1.42,38.26]],"ltp":2.12,"tv":237.53,"id":8679184}]}]}
{"op":"mcm","clk":"4232324811","pt":1631554272421,"mc":[{"id":"1.187594321","rc":[{"batb":[[0,1.01,12],[1,1.01,0]],"ltp":2.0,"tv":103.13,"id":11862899},{"batb":[[0,1.01,12],[1,1.01,0]],"ltp":2.12,"tv":237.53,"id":8679184}]}]}
{"op":"mcm","clk":"4232325318","pt":1631554277017,"mc":[{"id":"1.187594321","rc":[{"batb":[[0,4.1,10],[1,1.01,12]],"ltp":2.0,"tv":103.13,"id":11862899},{"batb":[[0,1.18,166.66],[1,1.01,12]],"ltp":2.12,"tv":237.53,"id":8679184}]}]}
{"op":"mcm","clk":"4232326169","pt":1631554284730,"mc":[{"id":"1.187594321","rc":[{"trd":[[4.1,10]],"batb":[[0,1.01,12],[1,1.01,0]],"ltp":4.1,"tv":113.13,"id":11862899},{"trd":[[1.33,30.83]],"batb":[[0,1.33,7.43],[1,1.18,166.66],[2,1.01,12]],"ltp":1.33,"tv":268.36,"id":8679184}],"tv":381.5}]}
{"op":"mcm","clk":"4232326483","pt":1631554287532,"mc":[{"id":"1.187594321","rc":[{"batb":[[0,1.18,166.66],[1,1.01,12],[2,1.01,0]],"ltp":1.33,"tv":268.36,"id":8679184}]}]}
{"op":"mcm","clk":"4232326814","pt":1631554290550,"mc":[{"id":"1.187594321","rc":[{"batb":[[0,4.1,2],[1,3.7,11.11],[2,1.01,12]],"ltp":4.1,"tv":113.13,"id":11862899}]}]}
{"op":"mcm","clk":"4232326836","pt":1631554290722,"mc":[{"id":"1.187594321","rc":[{"batb":[[0,3.7,11.11],[1,1.01,12],[2,1.01,0]],"ltp":4.1,"tv":113.13,"id":11862899}]}]}
{"op":"mcm","clk":"4232328745","pt":1631554307371,"mc":[{"id":"1.187594321","rc":[{"batb":[[0,1.2,136],[1,1.18,166.66],[2,1.01,12]],"ltp":1.33,"tv":268.36,"id":8679184}]}]}
{"op":"mcm","clk":"4232329096","pt":1631554310377,"mc":[{"id":"1.187594321","rc":[{"batl":[[0,1.33,68]],"ltp":1.33,"tv":268.36,"id":8679184}]}]}
{"op":"mcm","clk":"4232339320","pt":1631554405441,"mc":[{"id":"1.187594321","rc":[{"batb":[[0,1.01,12],[1,1.01,0]],"ltp":4.1,"tv":113.13,"id":11862899},{"batb":[[1,1.01,12],[2,1.01,0]],"ltp":1.33,"tv":268.36,"id":8679184}]}]}
{"op":"mcm","clk":"4232339810","pt":1631554410333,"mc":[{"id":"1.187594321","rc":[{"batb":[[0,4.8,10],[1,1.01,12]],"ltp":4.1,"tv":113.13,"id":11862899},{"batb":[[1,1.15,200],[2,1.01,12]],"ltp":1.33,"tv":268.36,"id":8679184}]}]}
{"op":"mcm","clk":"4232344234","pt":1631554455142,"mc":[{"id":"1.187594321","rc":[{"batb":[[0,1.15,200],[1,1.01,12],[2,1.01,0]],"ltp":1.33,"tv":268.36,"id":8679184}]}]}
{"op":"mcm","clk":"4232344361","pt":1631554456322,"mc":[{"id":"1.187594321","rc":[{"batb":[[0,1.01,12],[1,1.01,0]],"ltp":4.1,"tv":113.13,"id":11862899},{"batb":[[0,1.01,12],[1,1.01,0]],"ltp":1.33,"tv":268.36,"id":8679184}]}]}
{"op":"mcm","clk":"4232344822","pt":1631554461370,"mc":[{"id":"1.187594321","rc":[{"batb":[[0,5.3,10],[1,1.01,12]],"ltp":4.1,"tv":113.13,"id":11862899},{"batb":[[0,1.12,249.99],[1,1.01,12]],"ltp":1.33,"tv":268.36,"id":8679184}]}]}
{"op":"mcm","clk":"4232347019","pt":1631554484486,"mc":[{"id":"1.187594321","rc":[{"batb":[[0,1.01,12],[1,1.01,0]],"ltp":4.1,"tv":113.13,"id":11862899},{"batb":[[0,1.01,12],[1,1.01,0]],"ltp":1.33,"tv":268.36,"id":8679184}]}]}
{"op":"mcm","clk":"4232347508","pt":1631554489384,"mc":[{"id":"1.187594321","rc":[{"batb":[[0,5.8,10],[1,1.01,12]],"ltp":4.1,"tv":113.13,"id":11862899},{"batb":[[0,1.11,272.72],[1,1.01,12]],"ltp":1.33,"tv":268.36,"id":8679184}]}]}
{"op":"mcm","clk":"4232349835","pt":1631554513500,"mc":[{"id":"1.187594321","rc":[{"batb":[[0,1.01,12],[1,1.01,0]],"ltp":4.1,"tv":113.13,"id":11862899},{"batb":[[0,1.01,12],[1,1.01,0]],"ltp":1.33,"tv":268.36,"id":8679184}]}]}
{"op":"mcm","clk":"4232350348","pt":1631554518517,"mc":[{"id":"1.187594321","rc":[{"batb":[[0,6,10],[1,1.01,12]],"ltp":4.1,"tv":113.13,"id":11862899},{"batb":[[0,1.08,374.99],[1,1.01,12]],"ltp":1.33,"tv":268.36,"id":8679184}]}]}
{"op":"mcm","clk":"4232351265","pt":1631554528438,"mc":[{"id":"1.187594321","rc":[{"batb":[[0,1.11,68],[1,1.08,374.99],[2,1.01,12]],"ltp":1.33,"tv":268.36,"id":8679184}]}]}
{"op":"mcm","clk":"4232351336","pt":1631554529233,"mc":[{"id":"1.187594321","rc":[{"batb":[[0,1.11,136],[1,1.1,68],[2,1.08,374.99]],"ltp":1.33,"tv":268.36,"id":8679184}]}]}
{"op":"mcm","clk":"4232354793","pt":1631554561280,"mc":[{"id":"1.187594321","rc":[{"batb":[[0,1.08,374.99],[1,1.01,12],[2,1.08,0]],"ltp":1.33,"tv":268.36,"id":8679184}]}]}
{"op":"mcm","clk":"4232355972","pt":1631554573611,"mc":[{"id":"1.187594321","rc":[{"batb":[[0,1.01,12],[1,1.01,0]],"ltp":4.1,"tv":113.13,"id":11862899},{"batb":[[0,1.01,12],[1,1.01,0]],"ltp":1.33,"tv":268.36,"id":8679184}]}]}
{"op":"mcm","clk":"4232356401","pt":1631554578613,"mc":[{"id":"1.187594321","rc":[{"batb":[[0,5.8,10],[1,1.01,12]],"ltp":4.1,"tv":113.13,"id":11862899},{"batb":[[0,1.11,272.72],[1,1.01,12]],"ltp":1.33,"tv":268.36,"id":8679184}]}]}
{"op":"mcm","clk":"4232359211","pt":1631554610909,"mc":[{"id":"1.187594321","rc":[{"batb":[[0,1.01,12],[1,1.01,0]],"ltp":4.1,"tv":113.13,"id":11862899},{"batb":[[0,1.01,12],[1,1.01,0]],"ltp":1.33,"tv":268.36,"id":8679184}]}]}
{"op":"mcm","clk":"4232359643","pt":1631554615849,"mc":[{"id":"1.187594321","rc":[{"batb":[[0,4.8,10],[1,1.01,12]],"ltp":4.1,"tv":113.13,"id":11862899},{"batb":[[0,1.15,200],[1,1.01,12]],"ltp":1.33,"tv":268.36,"id":8679184}]}]}
{"op":"mcm","clk":"4232362173","pt":1631554642376,"mc":[{"id":"1.187594321","rc":[{"batb":[[0,1.01,12],[1,1.01,0]],"ltp":4.1,"tv":113.13,"id":11862899},{"batb":[[0,1.01,12],[1,1.01,0]],"ltp":1.33,"tv":268.36,"id":8679184}]}]}
{"op":"mcm","clk":"4232362631","pt":1631554647275,"mc":[{"id":"1.187594321","rc":[{"batb":[[0,4.3,10],[1,1.01,12]],"ltp":4.1,"tv":113.13,"id":11862899},{"batb":[[0,1.18,166.66],[1,1.01,12]],"ltp":1.33,"tv":268.36,"id":8679184}]}]}
{"op":"mcm","clk":"4232364353","pt":1631554665973,"mc":[{"id":"1.187594321","rc":[{"batb":[[0,1.01,12],[1,1.01,0]],"ltp":4.1,"tv":113.13,"id":11862899},{"batb":[[0,1.01,12],[1,1.01,0]],"ltp":1.33,"tv":268.36,"id":8679184}]}]}
{"op":"mcm","clk":"4232364850","pt":1631554670898,"mc":[{"id":"1.187594321","rc":[{"batb":[[0,4.8,10],[1,1.01,12]],"ltp":4.1,"tv":113.13,"id":11862899},{"batb":[[0,1.15,200],[1,1.01,12]],"ltp":1.33,"tv":268.36,"id":8679184}]}]}
{"op":"mcm","clk":"4232367116","pt":1631554695531,"mc":[{"id":"1.187594321","rc":[{"batb":[[0,1.01,12],[1,1.01,0]],"ltp":4.1,"tv":113.13,"id":11862899},{"batb":[[0,1.01,12],[1,1.01,0]],"ltp":1.33,"tv":268.36,"id":8679184}]}]}
{"op":"mcm","clk":"4232367576","pt":1631554700453,"mc":[{"id":"1.187594321","rc":[{"batb":[[0,5.8,10],[1,1.01,12]],"ltp":4.1,"tv":113.13,"id":11862899},{"batb":[[0,1.11,272.72],[1,1.01,12]],"ltp":1.33,"tv":268.36,"id":8679184}]}]}
{"op":"mcm","clk":"4232370266","pt":1631554729901,"mc":[{"id":"1.187594321","rc":[{"batb":[[0,1.01,12],[1,1.01,0]],"ltp":4.1,"tv":113.13,"id":11862899},{"batb":[[0,1.01,12],[1,1.01,0]],"ltp":1.33,"tv":268.36,"id":8679184}]}]}
{"op":"mcm","clk":"4232370689","pt":1631554734892,"mc":[{"id":"1.187594321","rc":[{"batb":[[0,4.8,10],[1,1.01,12]],"ltp":4.1,"tv":113.13,"id":11862899},{"batb":[[0,1.15,200],[1,1.01,12]],"ltp":1.33,"tv":268.36,"id":8679184}]}]}
{"op":"mcm","clk":"4232373433","pt":1631554765398,"mc":[{"id":"1.187594321","rc":[{"batb":[[0,1.01,12],[1,1.01,0]],"ltp":4.1,"tv":113.13,"id":11862899},{"batb":[[0,1.01,12],[1,1.01,0]],"ltp":1.33,"tv":268.36,"id":8679184}]}]}
{"op":"mcm","clk":"4232373857","pt":1631554770347,"mc":[{"id":"1.187594321","rc":[{"batb":[[0,5.3,10],[1,1.01,12]],"ltp":4.1,"tv":113.13,"id":11862899},{"batb":[[0,1.12,249.99],[1,1.01,12]],"ltp":1.33,"tv":268.36,"id":8679184}]}]}
{"op":"mcm","clk":"4232375260","pt":1631554786116,"mc":[{"id":"1.187594321","rc":[{"batb":[[0,1.01,12],[1,1.01,0]],"ltp":4.1,"tv":113.13,"id":11862899},{"batb":[[0,1.01,12],[1,1.01,0]],"ltp":1.33,"tv":268.36,"id":8679184}]}]}
{"op":"mcm","clk":"4232375726","pt":1631554791040,"mc":[{"id":"1.187594321","rc":[{"batb":[[0,5.8,10],[1,1.01,12]],"ltp":4.1,"tv":113.13,"id":11862899},{"batb":[[0,1.11,272.72],[1,1.01,12]],"ltp":1.33,"tv":268.36,"id":8679184}]}]}
{"op":"mcm","clk":"4232378312","pt":1631554818596,"mc":[{"id":"1.187594321","rc":[{"batb":[[0,1.01,12],[1,1.01,0]],"ltp":4.1,"tv":113.13,"id":11862899},{"batb":[[0,1.01,12],[1,1.01,0]],"ltp":1.33,"tv":268.36,"id":8679184}]}]}
{"op":"mcm","clk":"4232378758","pt":1631554823569,"mc":[{"id":"1.187594321","rc":[{"batb":[[0,6,10],[1,1.01,12]],"ltp":4.1,"tv":113.13,"id":11862899},{"batb":[[0,1.08,374.99],[1,1.01,12]],"ltp":1.33,"tv":268.36,"id":8679184}]}]}
{"op":"mcm","clk":"4232380209","pt":1631554838896,"mc":[{"id":"1.187594321","rc":[{"batb":[[0,1.01,12],[1,1.01,0]],"ltp":4.1,"tv":113.13,"id":11862899},{"batb":[[0,1.01,12],[1,1.01,0]],"ltp":1.33,"tv":268.36,"id":8679184}]}]}
{"op":"mcm","clk":"4232380692","pt":1631554843785,"mc":[{"id":"1.187594321","rc":[{"batb":[[0,5.8,10],[1,1.01,12]],"ltp":4.1,"tv":113.13,"id":11862899},{"batb":[[0,1.11,272.72],[1,1.01,12]],"ltp":1.33,"tv":268.36,"id":8679184}]}]}
{"op":"mcm","clk":"4232383918","pt":1631554880647,"mc":[{"id":"1.187594321","rc":[{"batb":[[0,1.01,12],[1,1.01,0]],"ltp":4.1,"tv":113.13,"id":11862899},{"batb":[[0,1.01,12],[1,1.01,0]],"ltp":1.33,"tv":268.36,"id":8679184}]}]}
{"op":"mcm","clk":"4232384424","pt":1631554885546,"mc":[{"id":"1.187594321","rc":[{"batb":[[0,5.3,10],[1,1.01,12]],"ltp":4.1,"tv":113.13,"id":11862899},{"batb":[[0,1.12,249.99],[1,1.01,12]],"ltp":1.33,"tv":268.36,"id":8679184}]}]}
{"op":"mcm","clk":"4232387129","pt":1631554914719,"mc":[{"id":"1.187594321","rc":[{"batb":[[0,1.01,12],[1,1.01,0]],"ltp":4.1,"tv":113.13,"id":11862899},{"batb":[[0,1.01,12],[1,1.01,0]],"ltp":1.33,"tv":268.36,"id":8679184}]}]}
{"op":"mcm","clk":"4232387605","pt":1631554919622,"mc":[{"id":"1.187594321","rc":[{"batb":[[0,4.3,10],[1,1.01,12]],"ltp":4.1,"tv":113.13,"id":11862899},{"batb":[[0,1.18,166.66],[1,1.01,12]],"ltp":1.33,"tv":268.36,"id":8679184}]}]}
{"op":"mcm","clk":"4232389266","pt":1631554936463,"mc":[{"id":"1.187594321","rc":[{"batb":[[0,1.01,12],[1,1.01,0]],"ltp":4.1,"tv":113.13,"id":11862899}]}]}
{"op":"mcm","clk":"4232389760","pt":1631554941381,"mc":[{"id":"1.187594321","rc":[{"batb":[[0,4.1,10],[1,1.01,12]],"ltp":4.1,"tv":113.13,"id":11862899}]}]}
{"op":"mcm","clk":"4232390734","pt":1631554951796,"mc":[{"id":"1.187594321","rc":[{"batb":[[0,1.01,12],[1,1.01,0]],"ltp":4.1,"tv":113.13,"id":11862899},{"batb":[[0,1.01,12],[1,1.01,0]],"ltp":1.33,"tv":268.36,"id":8679184}]}]}
{"op":"mcm","clk":"4232391182","pt":1631554956702,"mc":[{"id":"1.187594321","rc":[{"batb":[[0,3.7,11.11],[1,1.01,12]],"ltp":4.1,"tv":113.13,"id":11862899},{"batb":[[0,1.23,130.43],[1,1.01,12]],"ltp":1.33,"tv":268.36,"id":8679184}]}]}
{"op":"mcm","clk":"4232396207","pt":1631555011901,"mc":[{"id":"1.187594321","rc":[{"batb":[[0,1.01,12],[1,1.01,0]],"ltp":4.1,"tv":113.13,"id":11862899},{"batb":[[0,1.01,12],[1,1.01,0]],"ltp":1.33,"tv":268.36,"id":8679184}]}]}
{"op":"mcm","clk":"4232396668","pt":1631555016923,"mc":[{"id":"1.187594321","rc":[{"batb":[[0,3,15],[1,1.01,12]],"ltp":4.1,"tv":113.13,"id":11862899},{"batb":[[0,1.34,88.23],[1,1.01,12]],"ltp":1.33,"tv":268.36,"id":8679184}]}]}
{"op":"mcm","clk":"4232407943","pt":1631555123821,"mc":[{"id":"1.187594321","rc":[{"batb":[[0,1.01,12],[1,1.01,0]],"ltp":4.1,"tv":113.13,"id":11862899},{"batb":[[0,1.01,12],[1,1.01,0]],"ltp":1.33,"tv":268.36,"id":8679184}]}]}
{"op":"mcm","clk":"4232408477","pt":1631555128826,"mc":[{"id":"1.187594321","rc":[{"batb":[[0,3.4,12.5],[1,1.01,12]],"ltp":4.1,"tv":113.13,"id":11862899},{"batb":[[0,1.27,111.11],[1,1.01,12]],"ltp":1.33,"tv":268.36,"id":8679184}]}]}
{"op":"mcm","clk":"4232410019","pt":1631555143588,"mc":[{"id":"1.187594321","rc":[{"batb":[[0,1.01,12],[1,1.01,0]],"ltp":4.1,"tv":113.13,"id":11862899},{"batb":[[0,1.01,12],[1,1.01,0]],"ltp":1.33,"tv":268.36,"id":8679184}]}]}
{"op":"mcm","clk":"4232410561","pt":1631555148608,"mc":[{"id":"1.187594321","rc":[{"batb":[[0,3,15],[1,1.01,12]],"ltp":4.1,"tv":113.13,"id":11862899},{"batb":[[0,1.34,88.23],[1,1.01,12]],"ltp":1.33,"tv":268.36,"id":8679184}]}]}
{"op":"mcm","clk":"4232412296","pt":1631555164819,"mc":[{"id":"1.187594321","rc":[{"batb":[[0,1.01,12],[1,1.01,0]],"ltp":4.1,"tv":113.13,"id":11862899},{"batb":[[0,1.01,12],[1,1.01,0]],"ltp":1.33,"tv":268.36,"id":8679184}]}]}
{"op":"mcm","clk":"4232412820","pt":1631555169711,"mc":[{"id":"1.187594321","rc":[{"batb":[[0,3.15,13.95],[1,1.01,12]],"ltp":4.1,"tv":113.13,"id":11862899},{"batb":[[0,1.31,96.77],[1,1.01,12]],"ltp":1.33,"tv":268.36,"id":8679184}]}]}
{"op":"mcm","clk":"4232414210","pt":1631555183720,"mc":[{"id":"1.187594321","rc":[{"batb":[[0,1.01,12],[1,1.01,0]],"ltp":4.1,"tv":113.13,"id":11862899},{"batb":[[0,1.01,12],[1,1.01,0]],"ltp":1.33,"tv":268.36,"id":8679184}]}]}
{"op":"mcm","clk":"4232414782","pt":1631555188739,"mc":[{"id":"1.187594321","rc":[{"batb":[[0,2.84,16.3],[1,1.01,12]],"ltp":4.1,"tv":113.13,"id":11862899},{"batb":[[0,1.38,78.94],[1,1.01,12]],"ltp":1.33,"tv":268.36,"id":8679184}]}]}
{"op":"mcm","clk":"4232417544","pt":1631555214564,"mc":[{"id":"1.187594321","rc":[{"batb":[[0,1.01,12],[1,1.01,0]],"ltp":4.1,"tv":113.13,"id":11862899},{"batb":[[0,1.01,12],[1,1.01,0]],"ltp":1.33,"tv":268.36,"id":8679184}]}]}
{"op":"mcm","clk":"4232417995","pt":1631555219489,"mc":[{"id":"1.187594321","rc":[{"batb":[[0,2.58,18.98],[1,1.01,12]],"ltp":4.1,"tv":113.13,"id":11862899},{"batb":[[0,1.45,66.66],[1,1.01,12]],"ltp":1.33,"tv":268.36,"id":8679184}]}]}
{"op":"mcm","clk":"4232420819","pt":1631555244625,"mc":[{"id":"1.187594321","rc":[{"batb":[[0,1.01,12],[1,1.01,0]],"ltp":4.1,"tv":113.13,"id":11862899},{"batb":[[0,1.01,12],[1,1.01,0]],"ltp":1.33,"tv":268.36,"id":8679184}]}]}
{"op":"mcm","clk":"4232421359","pt":1631555249444,"mc":[{"id":"1.187594321","rc":[{"batb":[[0,2.84,16.3],[1,1.01,12]],"ltp":4.1,"tv":113.13,"id":11862899},{"batb":[[0,1.38,78.94],[1,1.01,12]],"ltp":1.33,"tv":268.36,"id":8679184}]}]}
{"op":"mcm","clk":"4232425125","pt":1631555283294,"mc":[{"id":"1.187594321","rc":[{"batb":[[0,1.01,12],[1,1.01,0]],"ltp":4.1,"tv":113.13,"id":11862899},{"batb":[[0,1.01,12],[1,1.01,0]],"ltp":1.33,"tv":268.36,"id":8679184}]}]}
{"op":"mcm","clk":"4232425626","pt":1631555288078,"mc":[{"id":"1.187594321","rc":[{"batb":[[0,3.15,13.95],[1,1.01,12]],"ltp":4.1,"tv":113.13,"id":11862899},{"batb":[[0,1.31,96.77],[1,1.01,12]],"ltp":1.33,"tv":268.36,"id":8679184}]}]}
{"op":"mcm","clk":"4232429383","pt":1631555327508,"mc":[{"id":"1.187594321","rc":[{"batb":[[0,1.01,12],[1,1.01,0]],"ltp":4.1,"tv":113.13,"id":11862899},{"batb":[[0,1.01,12],[1,1.01,0]],"ltp":1.33,"tv":268.36,"id":8679184}]}]}
{"op":"mcm","clk":"4232429839","pt":1631555332533,"mc":[{"id":"1.187594321","rc":[{"batb":[[0,2.84,16.3],[1,1.01,12]],"ltp":4.1,"tv":113.13,"id":11862899},{"batb":[[0,1.38,78.94],[1,1.01,12]],"ltp":1.33,"tv":268.36,"id":8679184}]}]}
{"op":"mcm","clk":"4232434971","pt":1631555386258,"mc":[{"id":"1.187594321","rc":[{"batb":[[0,1.01,12],[1,1.01,0]],"ltp":4.1,"tv":113.13,"id":11862899},{"batb":[[0,1.01,12],[1,1.01,0]],"ltp":1.33,"tv":268.36,"id":8679184}]}]}
{"op":"mcm","clk":"4232435419","pt":1631555391226,"mc":[{"id":"1.187594321","rc":[{"batb":[[0,3.15,13.95],[1,1.01,12]],"ltp":4.1,"tv":113.13,"id":11862899},{"batb":[[0,1.31,96.77],[1,1.01,12]],"ltp":1.33,"tv":268.36,"id":8679184}]}]}
{"op":"mcm","clk":"4232436923","pt":1631555406754,"mc":[{"id":"1.187594321","rc":[{"batl":[[0,100,0.93]],"ltp":1.33,"tv":268.36,"id":8679184}]}]}
{"op":"mcm","clk":"4232439236","pt":1631555430698,"mc":[{"id":"1.187594321","rc":[{"batb":[[0,1.01,12],[1,1.01,0]],"ltp":4.1,"tv":113.13,"id":11862899},{"batb":[[0,1.01,12],[1,1.01,0]],"ltp":1.33,"tv":268.36,"id":8679184}]}]}
{"op":"mcm","clk":"4232439670","pt":1631555435567,"mc":[{"id":"1.187594321","rc":[{"batb":[[0,2.84,16.3],[1,1.01,12]],"ltp":4.1,"tv":113.13,"id":11862899},{"batb":[[0,1.38,78.94],[1,1.01,12]],"ltp":1.33,"tv":268.36,"id":8679184}]}]}
{"op":"mcm","clk":"4232442872","pt":1631555467923,"mc":[{"id":"1.187594321","rc":[{"batb":[[0,1.01,12],[1,1.01,0]],"ltp":4.1,"tv":113.13,"id":11862899},{"batb":[[0,1.01,12],[1,1.01,0]],"ltp":1.33,"tv":268.36,"id":8679184}]}]}
{"op":"mcm","clk":"4232443336","pt":1631555472843,"mc":[{"id":"1.187594321","rc":[{"batb":[[0,2.58,18.98],[1,1.01,12]],"ltp":4.1,"tv":113.13,"id":11862899},{"batb":[[0,1.45,66.66],[1,1.01,12]],"ltp":1.33,"tv":268.36,"id":8679184}]}]}
{"op":"mcm","clk":"4232446282","pt":1631555504766,"mc":[{"id":"1.187594321","rc":[{"batl":[[0,100,0.19]],"ltp":4.1,"tv":113.13,"id":11862899}]}]}
{"op":"mcm","clk":"4232446379","pt":1631555505756,"mc":[{"id":"1.187594321","rc":[{"batb":[[0,1.01,12],[1,1.01,0]],"ltp":4.1,"tv":113.13,"id":11862899},{"batb":[[0,1.01,12],[1,1.01,0]],"ltp":1.33,"tv":268.36,"id":8679184}]}]}
{"op":"mcm","clk":"4232446795","pt":1631555510658,"mc":[{"id":"1.187594321","rc":[{"batb":[[0,2.42,21.12],[1,1.01,12]],"ltp":4.1,"tv":113.13,"id":11862899},{"batb":[[0,1.51,58.82],[1,1.01,12]],"ltp":1.33,"tv":268.36,"id":8679184}]}]}
{"op":"mcm","clk":"4232449235","pt":1631555538119,"mc":[{"id":"1.187594321","rc":[{"batb":[[0,1.01,12],[1,1.01,0]],"ltp":4.1,"tv":113.13,"id":11862899},{"batb":[[0,1.01,12],[1,1.01,0]],"ltp":1.33,"tv":268.36,"id":8679184}]}]}
{"op":"mcm","clk":"4232449651","pt":1631555543124,"mc":[{"id":"1.187594321","rc":[{"batb":[[0,2.58,18.98],[1,1.01,12]],"ltp":4.1,"tv":113.13,"id":11862899},{"batb":[[0,1.45,66.66],[1,1.01,12]],"ltp":1.33,"tv":268.36,"id":8679184}]}]}
{"op":"mcm","clk":"4232450155","pt":1631555548553,"mc":[{"id":"1.187594321","rc":[{"trd":[[2.58,2.78]],"batb":[[0,1.01,12],[1,1.01,0]],"ltp":2.58,"tv":115.91,"id":11862899}],"tv":384.27}]}
{"op":"mcm","clk":"4232450609","pt":1631555553460,"mc":[{"id":"1.187594321","rc":[{"batb":[[0,2.58,18.98],[1,1.01,12]],"ltp":2.58,"tv":115.91,"id":11862899}]}]}
{"op":"mcm","clk":"4232451402","pt":1631555563069,"mc":[{"id":"1.187594321","rc":[{"batb":[[0,1.01,12],[1,1.01,0]],"ltp":2.58,"tv":115.91,"id":11862899},{"batb":[[0,1.01,12],[1,1.01,0]],"ltp":1.33,"tv":268.36,"id":8679184}]}]}
{"op":"mcm","clk":"4232451842","pt":1631555567985,"mc":[{"id":"1.187594321","rc":[{"batb":[[0,2.84,16.3],[1,1.01,12]],"ltp":2.58,"tv":115.91,"id":11862899},{"batb":[[0,1.38,78.94],[1,1.01,12]],"ltp":1.33,"tv":268.36,"id":8679184}]}]}
{"op":"mcm","clk":"4232454918","pt":1631555603755,"mc":[{"id":"1.187594321","rc":[{"batb":[[0,1.01,12],[1,1.01,0]],"ltp":2.58,"tv":115.91,"id":11862899},{"batb":[[0,1.01,12],[1,1.01,0]],"ltp":1.33,"tv":268.36,"id":8679184}]}]}
{"op":"mcm","clk":"4232455365","pt":1631555608629,"mc":[{"id":"1.187594321","rc":[{"batb":[[0,2.66,18.07],[1,1.01,12]],"ltp":2.58,"tv":115.91,"id":11862899},{"batb":[[0,1.42,71.42],[1,1.01,12]],"ltp":1.33,"tv":268.36,"id":8679184}]}]}
{"op":"mcm","clk":"4232455996","pt":1631555616787,"mc":[{"id":"1.187594321","rc":[{"batb":[[0,1.01,12],[1,1.01,0]],"ltp":2.58,"tv":115.91,"id":11862899},{"batb":[[0,1.01,12],[1,1.01,0]],"ltp":1.33,"tv":268.36,"id":8679184}]}]}
{"op":"mcm","clk":"4232456459","pt":1631555621656,"mc":[{"id":"1.187594321","rc":[{"batb":[[0,2.84,16.3],[1,1.01,12]],"ltp":2.58,"tv":115.91,"id":11862899},{"batb":[[0,1.38,78.94],[1,1.01,12]],"ltp":1.33,"tv":268.36,"id":8679184}]}]}
{"op":"mcm","clk":"4232458306","pt":1631555643389,"mc":[{"id":"1.187594321","rc":[{"trd":[[1.38,3.42]],"batb":[[0,1.01,12],[1,1.01,0]],"ltp":1.38,"tv":271.78,"id":8679184}],"tv":387.69}]}
{"op":"mcm","clk":"4232458782","pt":1631555648298,"mc":[{"id":"1.187594321","rc":[{"batb":[[0,1.38,78.94],[1,1.01,12]],"ltp":1.38,"tv":271.78,"id":8679184}]}]}
{"op":"mcm","clk":"4232459532","pt":1631555656869,"mc":[{"id":"1.187594321","rc":[{"batb":[[0,1.01,12],[1,1.01,0]],"ltp":2.58,"tv":115.91,"id":11862899},{"batb":[[0,1.01,12],[1,1.01,0]],"ltp":1.38,"tv":271.78,"id":8679184}]}]}
{"op":"mcm","clk":"4232459942","pt":1631555661785,"mc":[{"id":"1.187594321","rc":[{"batb":[[0,3,15],[1,1.01,12]],"ltp":2.58,"tv":115.91,"id":11862899},{"batb":[[0,1.34,88.23],[1,1.01,12]],"ltp":1.38,"tv":271.78,"id":8679184}]}]}
{"op":"mcm","clk":"4232473065","pt":1631555798884,"mc":[{"id":"1.187594321","rc":[{"batb":[[0,1.01,12],[1,1.01,0]],"ltp":2.58,"tv":115.91,"id":11862899},{"batb":[[0,1.01,12],[1,1.01,0]],"ltp":1.38,"tv":271.78,"id":8679184}]}]}
{"op":"mcm","clk":"4232473510","pt":1631555803890,"mc":[{"id":"1.187594321","rc":[{"batb":[[0,2.84,16.3],[1,1.01,12]],"ltp":2.58,"tv":115.91,"id":11862899},{"batb":[[0,1.38,78.94],[1,1.01,12]],"ltp":1.38,"tv":271.78,"id":8679184}]}]}
{"op":"mcm","clk":"4232475799","pt":1631555829329,"mc":[{"id":"1.187594321","rc":[{"batb":[[0,1.01,12],[1,1.01,0]],"ltp":2.58,"tv":115.91,"id":11862899},{"batb":[[0,1.01,12],[1,1.01,0]],"ltp":1.38,"tv":271.78,"id":8679184}]}]}
{"op":"mcm","clk":"4232476275","pt":1631555834235,"mc":[{"id":"1.187594321","rc":[{"batb":[[0,3,15],[1,1.01,12]],"ltp":2.58,"tv":115.91,"id":11862899},{"batb":[[0,1.34,88.23],[1,1.01,12]],"ltp":1.38,"tv":271.78,"id":8679184}]}]}
{"op":"mcm","clk":"4232479778","pt":1631555870148,"mc":[{"id":"1.187594321","rc":[{"batb":[[0,1.01,12],[1,1.01,0]],"ltp":2.58,"tv":115.91,"id":11862899},{"batb":[[0,1.01,12],[1,1.01,0]],"ltp":1.38,"tv":271.78,"id":8679184}]}]}
{"op":"mcm","clk":"4232480263","pt":1631555875074,"mc":[{"id":"1.187594321","rc":[{"batb":[[0,3.4,12.5],[1,1.01,12]],"ltp":2.58,"tv":115.91,"id":11862899},{"batb":[[0,1.27,111.11],[1,1.01,12]],"ltp":1.38,"tv":271.78,"id":8679184}]}]}
{"op":"mcm","clk":"4232487785","pt":1631555949893,"mc":[{"id":"1.187594321","rc":[{"batb":[[0,1.01,12],[1,1.01,0]],"ltp":2.58,"tv":115.91,"id":11862899},{"batb":[[0,1.01,12],[1,1.01,0]],"ltp":1.38,"tv":271.78,"id":8679184}]}]}
{"op":"mcm","clk":"4232488301","pt":1631555954797,"mc":[{"id":"1.187594321","rc":[{"batb":[[0,3,15],[1,1.01,12]],"ltp":2.58,"tv":115.91,"id":11862899},{"batb":[[0,1.34,88.23],[1,1.01,12]],"ltp":1.38,"tv":271.78,"id":8679184}]}]}
{"op":"mcm","clk":"4232493897","pt":1631556008368,"mc":[{"id":"1.187594321","rc":[{"batb":[[0,1.01,12],[1,1.01,0]],"ltp":2.58,"tv":115.91,"id":11862899},{"batb":[[0,1.01,12],[1,1.01,0]],"ltp":1.38,"tv":271.78,"id":8679184}]}]}
{"op":"mcm","clk":"4232494484","pt":1631556013305,"mc":[{"id":"1.187594321","rc":[{"batb":[[0,3.7,11.11],[1,1.01,12]],"ltp":2.58,"tv":115.91,"id":11862899},{"batb":[[0,1.23,130.43],[1,1.01,12]],"ltp":1.38,"tv":271.78,"id":8679184}]}]}
{"op":"mcm","clk":"4232496950","pt":1631556035506,"mc":[{"id":"1.187594321","rc":[{"batb":[[0,1.01,12],[1,1.01,0]],"ltp":2.58,"tv":115.91,"id":11862899},{"batb":[[0,1.01,12],[1,1.01,0]],"ltp":1.38,"tv":271.78,"id":8679184}]}]}
{"op":"mcm","clk":"4232497487","pt":1631556040404,"mc":[{"id":"1.187594321","rc":[{"batb":[[0,3,15],[1,1.01,12]],"ltp":2.58,"tv":115.91,"id":11862899},{"batb":[[0,1.34,88.23],[1,1.01,12]],"ltp":1.38,"tv":271.78,"id":8679184}]}]}
{"op":"mcm","clk":"4232499753","pt":1631556062451,"mc":[{"id":"1.187594321","rc":[{"batb":[[0,1.01,12],[1,1.01,0]],"ltp":2.58,"tv":115.91,"id":11862899},{"batb":[[0,1.01,12],[1,1.01,0]],"ltp":1.38,"tv":271.78,"id":8679184}]}]}
{"op":"mcm","clk":"4232500289","pt":1631556067433,"mc":[{"id":"1.187594321","rc":[{"batb":[[0,3.7,11.11],[1,1.01,12]],"ltp":2.58,"tv":115.91,"id":11862899},{"batb":[[0,1.23,130.43],[1,1.01,12]],"ltp":1.38,"tv":271.78,"id":8679184}]}]}
{"op":"mcm","clk":"4232502282","pt":1631556085021,"mc":[{"id":"1.187594321","rc":[{"batb":[[0,1.01,12],[1,1.01,0]],"ltp":2.58,"tv":115.91,"id":11862899},{"batb":[[0,1.01,12],[1,1.01,0]],"ltp":1.38,"tv":271.78,"id":8679184}]}]}
{"op":"mcm","clk":"4232502891","pt":1631556089976,"mc":[{"id":"1.187594321","rc":[{"batb":[[0,3,15],[1,1.01,12]],"ltp":2.58,"tv":115.91,"id":11862899},{"batb":[[0,1.34,88.23],[1,1.01,12]],"ltp":1.38,"tv":271.78,"id":8679184}]}]}
{"op":"mcm","clk":"4232504939","pt":1631556110306,"mc":[{"id":"1.187594321","rc":[{"batb":[[0,1.01,12],[1,1.01,0]],"ltp":2.58,"tv":115.91,"id":11862899},{"batb":[[0,1.01,12],[1,1.01,0]],"ltp":1.38,"tv":271.78,"id":8679184}]}]}
{"op":"mcm","clk":"4232505419","pt":1631556115206,"mc":[{"id":"1.187594321","rc":[{"batb":[[0,2.84,16.3],[1,1.01,12]],"ltp":2.58,"tv":115.91,"id":11862899},{"batb":[[0,1.38,78.94],[1,1.01,12]],"ltp":1.38,"tv":271.78,"id":8679184}]}]}
{"op":"mcm","clk":"4232507461","pt":1631556132755,"mc":[{"id":"1.187594321","rc":[{"batb":[[0,1.01,12],[1,1.01,0]],"ltp":2.58,"tv":115.91,"id":11862899},{"batb":[[0,1.01,12],[1,1.01,0]],"ltp":1.38,"tv":271.78,"id":8679184}]}]}
{"op":"mcm","clk":"4232508064","pt":1631556137782,"mc":[{"id":"1.187594321","rc":[{"batb":[[0,2.5,20],[1,1.01,12]],"ltp":2.58,"tv":115.91,"id":11862899},{"batb":[[0,1.48,62.5],[1,1.01,12]],"ltp":1.38,"tv":271.78,"id":8679184}]}]}
{"op":"mcm","clk":"4232511028","pt":1631556159628,"mc":[{"id":"1.187594321","rc":[{"trd":[[1.48,4.82]],"batb":[[0,1.48,60.09]],"ltp":1.48,"tv":276.6,"id":8679184}],"tv":392.51}]}
{"op":"mcm","clk":"4232511079","pt":1631556160035,"mc":[{"id":"1.187594321","rc":[{"batb":[[0,1.01,12],[1,1.01,0]],"ltp":1.48,"tv":276.6,"id":8679184}]}]}
{"op":"mcm","clk":"4232511610","pt":1631556164906,"mc":[{"id":"1.187594321","rc":[{"batb":[[0,1.48,62.5],[1,1.01,12]],"ltp":1.48,"tv":276.6,"id":8679184}]}]}
{"op":"mcm","clk":"4232512275","pt":1631556170739,"mc":[{"id":"1.187594321","rc":[{"batb":[[0,1.01,12],[1,1.01,0]],"ltp":2.58,"tv":115.91,"id":11862899},{"batb":[[0,1.01,12],[1,1.01,0]],"ltp":1.48,"tv":276.6,"id":8679184}]}]}
{"op":"mcm","clk":"4232512880","pt":1631556175518,"mc":[{"id":"1.187594321","rc":[{"batb":[[0,2.34,22.38],[1,1.01,12]],"ltp":2.58,"tv":115.91,"id":11862899},{"batb":[[0,1.55,54.54],[1,1.01,12]],"ltp":1.48,"tv":276.6,"id":8679184}]}]}
{"op":"mcm","clk":"4232515700","pt":1631556199458,"mc":[{"id":"1.187594321","rc":[{"batb":[[0,1.01,12],[1,1.01,0]],"ltp":2.58,"tv":115.91,"id":11862899},{"batb":[[0,1.01,12],[1,1.01,0]],"ltp":1.48,"tv":276.6,"id":8679184}]}]}
{"op":"mcm","clk":"4232516358","pt":1631556204371,"mc":[{"id":"1.187594321","rc":[{"batb":[[0,2.5,20],[1,1.01,12]],"ltp":2.58,"tv":115.91,"id":11862899},{"batb":[[0,1.48,62.5],[1,1.01,12]],"ltp":1.48,"tv":276.6,"id":8679184}]}]}
{"op":"mcm","clk":"4232518542","pt":1631556221247,"mc":[{"id":"1.187594321","rc":[{"batb":[[0,1.01,12],[1,1.01,0]],"ltp":2.58,"tv":115.91,"id":11862899},{"batb":[[0,1.01,12],[1,1.01,0]],"ltp":1.48,"tv":276.6,"id":8679184}]}]}
{"op":"mcm","clk":"4232519246","pt":1631556226128,"mc":[{"id":"1.187594321","rc":[{"batb":[[0,2.58,18.98],[1,1.01,12]],"ltp":2.58,"tv":115.91,"id":11862899},{"batb":[[0,1.45,66.66],[1,1.01,12]],"ltp":1.48,"tv":276.6,"id":8679184}]}]}
{"op":"mcm","clk":"4232521066","pt":1631556239832,"mc":[{"id":"1.187594321","rc":[{"batb":[[0,1.01,12],[1,1.01,0]],"ltp":2.58,"tv":115.91,"id":11862899},{"batb":[[0,1.01,12],[1,1.01,0]],"ltp":1.48,"tv":276.6,"id":8679184}]}]}
{"op":"mcm","clk":"4232521702","pt":1631556244752,"mc":[{"id":"1.187594321","rc":[{"batb":[[0,2.84,16.3],[1,1.01,12]],"ltp":2.58,"tv":115.91,"id":11862899},{"batb":[[0,1.38,78.94],[1,1.01,12]],"ltp":1.48,"tv":276.6,"id":8679184}]}]}
{"op":"mcm","clk":"4232530132","pt":1631556309042,"mc":[{"id":"1.187594321","rc":[{"batl":[[0,3.3,27.04],[1,100,0.19]],"ltp":2.58,"tv":115.91,"id":11862899}]}]}
{"op":"mcm","clk":"4232532485","pt":1631556326773,"mc":[{"id":"1.187594321","rc":[{"batl":[[0,100,0.19],[1,100,0]],"ltp":2.58,"tv":115.91,"id":11862899}]}]}
{"op":"mcm","clk":"4232549133","pt":1631556450742,"mc":[{"id":"1.187594321","rc":[{"trd":[[1.38,161.27]],"batb":[[0,1.01,12],[1,1.01,0]],"batl":[[0,1.38,263.08],[1,100,0.93]],"ltp":1.38,"tv":434.45,"id":8679184}],"tv":550.37}]}
{"op":"mcm","clk":"4232549799","pt":1631556456084,"mc":[{"id":"1.187594321","rc":[{"batb":[[0,1.31,96.77],[1,1.01,12]],"ltp":1.38,"tv":434.45,"id":8679184}]}]}
{"op":"mcm","clk":"4232554331","pt":1631556488508,"mc":[{"id":"1.187594321","rc":[{"batb":[[0,1.01,12],[1,1.01,0]],"ltp":2.58,"tv":115.91,"id":11862899},{"batb":[[0,1.01,12],[1,1.01,0]],"ltp":1.38,"tv":434.45,"id":8679184}]}]}
{"op":"mcm","clk":"4232554787","pt":1631556491722,"mc":[{"id":"1.187594321","rc":[{"batl":[[0,100,0.93],[1,100,0]],"ltp":1.38,"tv":434.45,"id":8679184}]}]}
{"op":"mcm","clk":"4232555030","pt":1631556493438,"mc":[{"id":"1.187594321","rc":[{"batb":[[0,2.58,18.98],[1,1.01,12]],"ltp":2.58,"tv":115.91,"id":11862899}]}]}
{"op":"mcm","clk":"4232555480","pt":1631556496417,"mc":[{"id":"1.187594321","rc":[{"batb":[[0,1.38,65.35],[1,1.01,12]],"ltp":1.38,"tv":434.45,"id":8679184}]}]}
{"op":"mcm","clk":"4232555620","pt":1631556497436,"mc":[{"id":"1.187594321","rc":[{"batb":[[0,1.45,66.66],[1,1.38,238.74],[2,1.01,12]],"ltp":1.38,"tv":434.45,"id":8679184}]}]}
{"op":"mcm","clk":"4232555760","pt":1631556498524,"mc":[{"id":"1.187594321","rc":[{"batb":[[1,1.38,119.54]],"ltp":1.38,"tv":434.45,"id":8679184}]}]}
{"op":"mcm","clk":"4232555822","pt":1631556498914,"mc":[{"id":"1.187594321","rc":[{"batb":[[1,1.38,48.34]],"ltp":1.38,"tv":434.45,"id":8679184}]}]}
{"op":"mcm","clk":"4232556287","pt":1631556502724,"mc":[{"id":"1.187594321","rc":[{"batb":[[1,1.01,12],[2,1.01,0]],"ltp":1.38,"tv":434.45,"id":8679184}]}]}
{"op":"mcm","clk":"4232559047","pt":1631556523452,"mc":[{"id":"1.187594321","rc":[{"batb":[[0,1.01,12],[1,1.01,0]],"ltp":2.58,"tv":115.91,"id":11862899},{"batb":[[0,1.01,12],[1,1.01,0]],"ltp":1.38,"tv":434.45,"id":8679184}]}]}
{"op":"mcm","clk":"4232559660","pt":1631556528374,"mc":[{"id":"1.187594321","rc":[{"batb":[[0,2.42,21.12],[1,1.01,12]],"ltp":2.58,"tv":115.91,"id":11862899},{"batb":[[0,1.48,62.5],[1,1.01,12]],"ltp":1.38,"tv":434.45,"id":8679184}]}]}
{"op":"mcm","clk":"4232562207","pt":1631556545887,"mc":[{"id":"1.187594321","rc":[{"batb":[[0,1.01,12],[1,1.01,0]],"ltp":2.58,"tv":115.91,"id":11862899}]}]}
{"op":"mcm","clk":"4232562910","pt":1631556550858,"mc":[{"id":"1.187594321","rc":[{"batb":[[0,2.5,20],[1,1.01,12]],"ltp":2.58,"tv":115.91,"id":11862899}]}]}
{"op":"mcm","clk":"4232564780","pt":1631556564506,"mc":[{"id":"1.187594321","rc":[{"batb":[[0,1.01,12],[1,1.01,0]],"ltp":2.58,"tv":115.91,"id":11862899},{"batb":[[0,1.01,12],[1,1.01,0]],"ltp":1.38,"tv":434.45,"id":8679184}]}]}
{"op":"mcm","clk":"4232565554","pt":1631556569391,"mc":[{"id":"1.187594321","rc":[{"batb":[[0,2.58,18.98],[1,1.01,12]],"ltp":2.58,"tv":115.91,"id":11862899},{"batb":[[0,1.45,66.66],[1,1.01,12]],"ltp":1.38,"tv":434.45,"id":8679184}]}]}
{"op":"mcm","clk":"4232569707","pt":1631556599224,"mc":[{"id":"1.187594321","rc":[{"batb":[[0,1.01,12],[1,1.01,0]],"ltp":2.58,"tv":115.91,"id":11862899},{"batb":[[0,1.01,12],[1,1.01,0]],"ltp":1.38,"tv":434.45,"id":8679184}]}]}
{"op":"mcm","clk":"4232570397","pt":1631556604169,"mc":[{"id":"1.187594321","rc":[{"batb":[[0,3,15],[1,1.01,12]],"ltp":2.58,"tv":115.91,"id":11862899},{"batb":[[0,1.34,88.23],[1,1.01,12]],"ltp":1.38,"tv":434.45,"id":8679184}]}]}
{"op":"mcm","clk":"4232571573","pt":1631556612658,"mc":[{"id":"1.187594321","rc":[{"trd":[[1.34,176.43]],"batb":[[0,1.01,12],[1,1.01,0]],"batl":[[0,1.34,58.89],[1,100,0.93]],"ltp":1.34,"tv":610.88,"id":8679184}],"tv":726.79}]}
{"op":"mcm","clk":"4232572311","pt":1631556617866,"mc":[{"id":"1.187594321","rc":[{"batb":[[0,1.27,111.11],[1,1.01,12]],"ltp":1.34,"tv":610.88,"id":8679184}]}]}
{"op":"mcm","clk":"4232574224","pt":1631556632691,"mc":[{"id":"1.187594321","rc":[{"batb":[[0,1.01,12],[1,1.01,0]],"ltp":2.58,"tv":115.91,"id":11862899}]}]}
{"op":"mcm","clk":"4232574851","pt":1631556637709,"mc":[{"id":"1.187594321","rc":[{"batb":[[0,3.4,12.5],[1,1.01,12]],"ltp":2.58,"tv":115.91,"id":11862899}]}]}
{"op":"mcm","clk":"4232574986","pt":1631556638827,"mc":[{"id":"1.187594321","rc":[{"batl":[[0,100,0.93],[1,100,0]],"ltp":1.34,"tv":610.88,"id":8679184}]}]}
{"op":"mcm","clk":"4232575716","pt":1631556644316,"mc":[{"id":"1.187594321","rc":[{"trd":[[1.27,117.82]],"batb":[[0,1.01,12],[1,1.01,0]],"ltp":1.27,"tv":728.7,"id":8679184}],"tv":844.61}]}
{"op":"mcm","clk":"4232576333","pt":1631556649259,"mc":[{"id":"1.187594321","rc":[{"batb":[[0,1.27,111.11],[1,1.01,12]],"ltp":1.27,"tv":728.7,"id":8679184}]}]}
{"op":"mcm","clk":"4232577801","pt":1631556660757,"mc":[{"id":"1.187594321","rc":[{"batb":[[0,1.01,12],[1,1.01,0]],"ltp":2.58,"tv":115.91,"id":11862899},{"batb":[[0,1.01,12],[1,1.01,0]],"ltp":1.27,"tv":728.7,"id":8679184}]}]}
{"op":"mcm","clk":"4232578432","pt":1631556665683,"mc":[{"id":"1.187594321","rc":[{"batb":[[0,4.3,10],[1,1.01,12]],"ltp":2.58,"tv":115.91,"id":11862899},{"batb":[[0,1.18,166.66],[1,1.01,12]],"ltp":1.27,"tv":728.7,"id":8679184}]}]}
{"op":"mcm","clk":"4232582344","pt":1631556692815,"mc":[{"id":"1.187594321","rc":[{"batb":[[0,1.01,12],[1,1.01,0]],"ltp":2.58,"tv":115.91,"id":11862899},{"batb":[[0,1.01,12],[1,1.01,0]],"ltp":1.27,"tv":728.7,"id":8679184}]}]}
{"op":"mcm","clk":"4232582984","pt":1631556697703,"mc":[{"id":"1.187594321","rc":[{"batb":[[0,5.3,10],[1,1.01,12]],"ltp":2.58,"tv":115.91,"id":11862899},{"batb":[[0,1.12,249.99],[1,1.01,12]],"ltp":1.27,"tv":728.7,"id":8679184}]}]}
{"op":"mcm","clk":"4232585857","pt":1631556721048,"mc":[{"id":"1.187594321","rc":[{"batb":[[0,1.01,12],[1,1.01,0]],"ltp":2.58,"tv":115.91,"id":11862899},{"batb":[[0,1.01,12],[1,1.01,0]],"ltp":1.27,"tv":728.7,"id":8679184}]}]}
{"op":"mcm","clk":"4232586425","pt":1631556725916,"mc":[{"id":"1.187594321","rc":[{"batb":[[0,6,10],[1,1.01,12]],"ltp":2.58,"tv":115.91,"id":11862899},{"batb":[[0,1.08,374.99],[1,1.01,12]],"ltp":1.27,"tv":728.7,"id":8679184}]}]}
{"op":"mcm","clk":"4232588906","pt":1631556745457,"mc":[{"id":"1.187594321","rc":[{"batb":[[0,1.01,12],[1,1.01,0]],"ltp":2.58,"tv":115.91,"id":11862899},{"batb":[[0,1.01,12],[1,1.01,0]],"ltp":1.27,"tv":728.7,"id":8679184}]}]}
{"op":"mcm","clk":"4232589547","pt":1631556750390,"mc":[{"id":"1.187594321","rc":[{"batb":[[0,5.3,10],[1,1.01,12]],"ltp":2.58,"tv":115.91,"id":11862899},{"batb":[[0,1.12,249.99],[1,1.01,12]],"ltp":1.27,"tv":728.7,"id":8679184}]}]}
{"op":"mcm","clk":"4232593700","pt":1631556781291,"mc":[{"id":"1.187594321","rc":[{"batb":[[0,1.01,12],[1,1.01,0]],"ltp":2.58,"tv":115.91,"id":11862899},{"batb":[[0,1.01,12],[1,1.01,0]],"ltp":1.27,"tv":728.7,"id":8679184}]}]}
{"op":"mcm","clk":"4232594376","pt":1631556786229,"mc":[{"id":"1.187594321","rc":[{"batb":[[0,6,10],[1,1.01,12]],"ltp":2.58,"tv":115.91,"id":11862899},{"batb":[[0,1.08,374.99],[1,1.01,12]],"ltp":1.27,"tv":728.7,"id":8679184}]}]}
{"op":"mcm","clk":"4232596580","pt":1631556803397,"mc":[{"id":"1.187594321","rc":[{"batb":[[0,1.01,12],[1,1.01,0]],"ltp":2.58,"tv":115.91,"id":11862899},{"batb":[[0,1.01,12],[1,1.01,0]],"ltp":1.27,"tv":728.7,"id":8679184}]}]}
{"op":"mcm","clk":"4232597247","pt":1631556808367,"mc":[{"id":"1.187594321","rc":[{"batb":[[0,7.6,10],[1,1.01,12]],"ltp":2.58,"tv":115.91,"id":11862899},{"batb":[[0,1.05,599.99],[1,1.01,12]],"ltp":1.27,"tv":728.7,"id":8679184}]}]}
{"op":"mcm","clk":"4232611939","pt":1631556920772,"mc":[{"id":"1.187594321","rc":[{"batb":[[0,1.01,12],[1,1.01,0]],"ltp":2.58,"tv":115.91,"id":11862899},{"batb":[[0,1.01,12],[1,1.01,0]],"ltp":1.27,"tv":728.7,"id":8679184}]}]}
{"op":"mcm","clk":"4232612561","pt":1631556925706,"mc":[{"id":"1.187594321","rc":[{"batb":[[0,6,10],[1,1.01,12]],"ltp":2.58,"tv":115.91,"id":11862899},{"batb":[[0,1.08,374.99],[1,1.01,12]],"ltp":1.27,"tv":728.7,"id":8679184}]}]}
{"op":"mcm","clk":"4232614633","pt":1631556942839,"mc":[{"id":"1.187594321","rc":[{"batb":[[0,1.01,12],[1,1.01,0]],"ltp":2.58,"tv":115.91,"id":11862899},{"batb":[[0,1.01,12],[1,1.01,0]],"ltp":1.27,"tv":728.7,"id":8679184}]}]}
{"op":"mcm","clk":"4232615160","pt":1631556947823,"mc":[{"id":"1.187594321","rc":[{"batb":[[0,4.8,10],[1,1.01,12]],"ltp":2.58,"tv":115.91,"id":11862899},{"batb":[[0,1.15,200],[1,1.01,12]],"ltp":1.27,"tv":728.7,"id":8679184}]}]}
{"op":"mcm","clk":"4232618323","pt":1631556977439,"mc":[{"id":"1.187594321","rc":[{"batb":[[0,1.01,12],[1,1.01,0]],"ltp":2.58,"tv":115.91,"id":11862899},{"batb":[[0,1.01,12],[1,1.01,0]],"ltp":1.27,"tv":728.7,"id":8679184}]}]}
{"op":"mcm","clk":"4232618941","pt":1631556982333,"mc":[{"id":"1.187594321","rc":[{"batb":[[0,6,10],[1,1.01,12]],"ltp":2.58,"tv":115.91,"id":11862899},{"batb":[[0,1.08,374.99],[1,1.01,12]],"ltp":1.27,"tv":728.7,"id":8679184}]}]}
{"op":"mcm","clk":"4232621141","pt":1631557001277,"mc":[{"id":"1.187594321","rc":[{"batb":[[0,1.01,12],[1,1.01,0]],"ltp":2.58,"tv":115.91,"id":11862899},{"batb":[[0,1.01,12],[1,1.01,0]],"ltp":1.27,"tv":728.7,"id":8679184}]}]}
{"op":"mcm","clk":"4232621741","pt":1631557006305,"mc":[{"id":"1.187594321","rc":[{"batb":[[0,4.8,10],[1,1.01,12]],"ltp":2.58,"tv":115.91,"id":11862899},{"batb":[[0,1.15,200],[1,1.01,12]],"ltp":1.27,"tv":728.7,"id":8679184}]}]}
{"op":"mcm","clk":"4232625048","pt":1631557032517,"mc":[{"id":"1.187594321","rc":[{"batb":[[0,1.01,12],[1,1.01,0]],"ltp":2.58,"tv":115.91,"id":11862899},{"batb":[[0,1.01,12],[1,1.01,0]],"ltp":1.27,"tv":728.7,"id":8679184}]}]}
{"op":"mcm","clk":"4232625621","pt":1631557037436,"mc":[{"id":"1.187594321","rc":[{"batb":[[0,4.1,10],[1,1.01,12]],"ltp":2.58,"tv":115.91,"id":11862899},{"batb":[[0,1.18,166.66],[1,1.01,12]],"ltp":1.27,"tv":728.7,"id":8679184}]}]}
{"op":"mcm","clk":"4232630461","pt":1631557078475,"mc":[{"id":"1.187594321","rc":[{"batb":[[0,1.01,12],[1,1.01,0]],"ltp":2.58,"tv":115.91,"id":11862899},{"batb":[[0,1.01,12],[1,1.01,0]],"ltp":1.27,"tv":728.7,"id":8679184}]}]}
{"op":"mcm","clk":"4232631099","pt":1631557083476,"mc":[{"id":"1.187594321","rc":[{"batb":[[0,5.3,10],[1,1.01,12]],"ltp":2.58,"tv":115.91,"id":11862899},{"batb":[[0,1.12,249.99],[1,1.01,12]],"ltp":1.27,"tv":728.7,"id":8679184}]}]}
{"op":"mcm","clk":"4232636259","pt":1631557126207,"mc":[{"id":"1.187594321","rc":[{"batb":[[0,1.01,12],[1,1.01,0]],"ltp":2.58,"tv":115.91,"id":11862899},{"batb":[[0,1.01,12],[1,1.01,0]],"ltp":1.27,"tv":728.7,"id":8679184}]}]}
{"op":"mcm","clk":"4232637047","pt":1631557132228,"mc":[{"id":"1.187594321","rc":[{"batb":[[0,4.1,10],[1,1.01,12]],"ltp":2.58,"tv":115.91,"id":11862899},{"batb":[[0,1.18,166.66],[1,1.01,12]],"ltp":1.27,"tv":728.7,"id":8679184}]}]}
{"op":"mcm","clk":"4232640435","pt":1631557149934,"mc":[{"id":"1.187594321","rc":[{"batb":[[0,1.01,12],[1,1.01,0]],"ltp":2.58,"tv":115.91,"id":11862899},{"batb":[[0,1.01,12],[1,1.01,0]],"ltp":1.27,"tv":728.7,"id":8679184}]}]}
{"op":"mcm","clk":"4232641082","pt":1631557154826,"mc":[{"id":"1.187594321","rc":[{"batb":[[0,5.3,10],[1,1.01,12]],"ltp":2.58,"tv":115.91,"id":11862899},{"batb":[[0,1.12,249.99],[1,1.01,12]],"ltp":1.27,"tv":728.7,"id":8679184}]}]}
{"op":"mcm","clk":"4232642668","pt":1631557166847,"mc":[{"id":"1.187594321","rc":[{"batb":[[0,1.01,12],[1,1.01,0]],"ltp":1.27,"tv":728.7,"id":8679184}]}]}
{"op":"mcm","clk":"4232643268","pt":1631557171745,"mc":[{"id":"1.187594321","rc":[{"batb":[[0,1.15,200],[1,1.01,12]],"ltp":1.27,"tv":728.7,"id":8679184}]}]}
{"op":"mcm","clk":"4232645305","pt":1631557189197,"mc":[{"id":"1.187594321","rc":[{"batb":[[0,1.01,12],[1,1.01,0]],"ltp":2.58,"tv":115.91,"id":11862899},{"batb":[[0,1.01,12],[1,1.01,0]],"ltp":1.27,"tv":728.7,"id":8679184}]}]}
{"op":"mcm","clk":"4232645908","pt":1631557194101,"mc":[{"id":"1.187594321","rc":[{"batb":[[0,6,10],[1,1.01,12]],"ltp":2.58,"tv":115.91,"id":11862899},{"batb":[[0,1.08,374.99],[1,1.01,12]],"ltp":1.27,"tv":728.7,"id":8679184}]}]}
{"op":"mcm","clk":"4232662755","pt":1631557332176,"mc":[{"id":"1.187594321","rc":[{"batb":[[0,1.01,12],[1,1.01,0]],"ltp":2.58,"tv":115.91,"id":11862899},{"batb":[[0,1.01,12],[1,1.01,0]],"ltp":1.27,"tv":728.7,"id":8679184}]}]}
{"op":"mcm","clk":"4232663370","pt":1631557337012,"mc":[{"id":"1.187594321","rc":[{"batb":[[0,5.8,10],[1,1.01,12]],"ltp":2.58,"tv":115.91,"id":11862899},{"batb":[[0,1.11,272.72],[1,1.01,12]],"ltp":1.27,"tv":728.7,"id":8679184}]}]}
{"op":"mcm","clk":"4232665517","pt":1631557354336,"mc":[{"id":"1.187594321","rc":[{"batb":[[0,1.01,12],[1,1.01,0]],"ltp":2.58,"tv":115.91,"id":11862899},{"batb":[[0,1.01,12],[1,1.01,0]],"ltp":1.27,"tv":728.7,"id":8679184}]}]}
{"op":"mcm","clk":"4232666108","pt":1631557359281,"mc":[{"id":"1.187594321","rc":[{"batb":[[0,4.8,10],[1,1.01,12]],"ltp":2.58,"tv":115.91,"id":11862899},{"batb":[[0,1.15,200],[1,1.01,12]],"ltp":1.27,"tv":728.7,"id":8679184}]}]}
{"op":"mcm","clk":"4232668246","pt":1631557376869,"mc":[{"id":"1.187594321","rc":[{"batb":[[0,1.01,12],[1,1.01,0]],"ltp":2.58,"tv":115.91,"id":11862899},{"batb":[[0,1.01,12],[1,1.01,0]],"ltp":1.27,"tv":728.7,"id":8679184}]}]}
{"op":"mcm","clk":"4232668836","pt":1631557381792,"mc":[{"id":"1.187594321","rc":[{"batb":[[0,4.3,10],[1,1.01,12]],"ltp":2.58,"tv":115.91,"id":11862899},{"batb":[[0,1.18,166.66],[1,1.01,12]],"ltp":1.27,"tv":728.7,"id":8679184}]}]}
{"op":"mcm","clk":"4232671152","pt":1631557400427,"mc":[{"id":"1.187594321","rc":[{"batb":[[0,1.01,12],[1,1.01,0]],"ltp":2.58,"tv":115.91,"id":11862899},{"batb":[[0,1.01,12],[1,1.01,0]],"ltp":1.27,"tv":728.7,"id":8679184}]}]}
{"op":"mcm","clk":"4232671748","pt":1631557405395,"mc":[{"id":"1.187594321","rc":[{"batb":[[0,4.8,10],[1,1.01,12]],"ltp":2.58,"tv":115.91,"id":11862899},{"batb":[[0,1.15,200],[1,1.01,12]],"ltp":1.27,"tv":728.7,"id":8679184}]}]}
{"op":"mcm","clk":"4232674750","pt":1631557429664,"mc":[{"id":"1.187594321","rc":[{"batb":[[0,1.01,12],[1,1.01,0]],"ltp":2.58,"tv":115.91,"id":11862899},{"batb":[[0,1.01,12],[1,1.01,0]],"ltp":1.27,"tv":728.7,"id":8679184}]}]}
{"op":"mcm","clk":"4232675396","pt":1631557434663,"mc":[{"id":"1.187594321","rc":[{"batb":[[0,5.3,10],[1,1.01,12]],"ltp":2.58,"tv":115.91,"id":11862899},{"batb":[[0,1.12,249.99],[1,1.01,12]],"ltp":1.27,"tv":728.7,"id":8679184}]}]}
{"op":"mcm","clk":"4232678397","pt":1631557459169,"mc":[{"id":"1.187594321","rc":[{"batb":[[0,1.01,12],[1,1.01,0]],"ltp":2.58,"tv":115.91,"id":11862899},{"batb":[[0,1.01,12],[1,1.01,0]],"ltp":1.27,"tv":728.7,"id":8679184}]}]}
{"op":"mcm","clk":"4232678902","pt":1631557464001,"mc":[{"id":"1.187594321","rc":[{"batb":[[0,5.8,10],[1,1.01,12]],"ltp":2.58,"tv":115.91,"id":11862899},{"batb":[[0,1.11,272.72],[1,1.01,12]],"ltp":1.27,"tv":728.7,"id":8679184}]}]}
{"op":"mcm","clk":"4232680587","pt":1631557478794,"mc":[{"id":"1.187594321","rc":[{"batb":[[0,1.01,12],[1,1.01,0]],"ltp":2.58,"tv":115.91,"id":11862899},{"batb":[[0,1.01,12],[1,1.01,0]],"ltp":1.27,"tv":728.7,"id":8679184}]}]}
{"op":"mcm","clk":"4232681205","pt":1631557483809,"mc":[{"id":"1.187594321","rc":[{"batb":[[0,7,10],[1,1.01,12]],"ltp":2.58,"tv":115.91,"id":11862899},{"batb":[[0,1.06,499.99],[1,1.01,12]],"ltp":1.27,"tv":728.7,"id":8679184}]}]}
{"op":"mcm","clk":"4232684151","pt":1631557507760,"mc":[{"id":"1.187594321","rc":[{"batb":[[0,1.01,12],[1,1.01,0]],"ltp":2.58,"tv":115.91,"id":11862899},{"batb":[[0,1.01,12],[1,1.01,0]],"ltp":1.27,"tv":728.7,"id":8679184}]}]}
{"op":"mcm","clk":"4232684764","pt":1631557512777,"mc":[{"id":"1.187594321","rc":[{"batb":[[0,5.3,10],[1,1.01,12]],"ltp":2.58,"tv":115.91,"id":11862899},{"batb":[[0,1.12,249.99],[1,1.01,12]],"ltp":1.27,"tv":728.7,"id":8679184}]}]}
{"op":"mcm","clk":"4232688488","pt":1631557542665,"mc":[{"id":"1.187594321","rc":[{"batb":[[0,1.01,12],[1,1.01,0]],"ltp":2.58,"tv":115.91,"id":11862899},{"batb":[[0,1.01,12],[1,1.01,0]],"ltp":1.27,"tv":728.7,"id":8679184}]}]}
{"op":"mcm","clk":"4232689057","pt":1631557547717,"mc":[{"id":"1.187594321","rc":[{"batb":[[0,4.1,10],[1,1.01,12]],"ltp":2.58,"tv":115.91,"id":11862899},{"batb":[[0,1.18,166.66],[1,1.01,12]],"ltp":1.27,"tv":728.7,"id":8679184}]}]}
{"op":"mcm","clk":"4232694137","pt":1631557591989,"mc":[{"id":"1.187594321","rc":[{"batb":[[0,1.01,12],[1,1.01,0]],"ltp":2.58,"tv":115.91,"id":11862899},{"batb":[[0,1.01,12],[1,1.01,0]],"ltp":1.27,"tv":728.7,"id":8679184}]}]}
{"op":"mcm","clk":"4232694663","pt":1631557596898,"mc":[{"id":"1.187594321","rc":[{"batb":[[0,5.3,10],[1,1.01,12]],"ltp":2.58,"tv":115.91,"id":11862899},{"batb":[[0,1.12,249.99],[1,1.01,12]],"ltp":1.27,"tv":728.7,"id":8679184}]}]}
{"op":"mcm","clk":"4232697604","pt":1631557624508,"mc":[{"id":"1.187594321","rc":[{"batb":[[0,1.01,12],[1,1.01,0]],"ltp":2.58,"tv":115.91,"id":11862899},{"batb":[[0,1.01,12],[1,1.01,0]],"ltp":1.27,"tv":728.7,"id":8679184}]}]}
{"op":"mcm","clk":"4232698095","pt":1631557629391,"mc":[{"id":"1.187594321","rc":[{"batb":[[0,4.1,10],[1,1.01,12]],"ltp":2.58,"tv":115.91,"id":11862899},{"batb":[[0,1.18,166.66],[1,1.01,12]],"ltp":1.27,"tv":728.7,"id":8679184}]}]}
{"op":"mcm","clk":"4232700159","pt":1631557648576,"mc":[{"id":"1.187594321","rc":[{"batb":[[0,1.01,12],[1,1.01,0]],"ltp":2.58,"tv":115.91,"id":11862899}]}]}
{"op":"mcm","clk":"4232700675","pt":1631557653478,"mc":[{"id":"1.187594321","rc":[{"batb":[[0,4.3,10],[1,1.01,12]],"ltp":2.58,"tv":115.91,"id":11862899}]}]}
{"op":"mcm","clk":"4232702297","pt":1631557670805,"mc":[{"id":"1.187594321","rc":[{"batb":[[0,1.01,12],[1,1.01,0]],"ltp":2.58,"tv":115.91,"id":11862899},{"batb":[[0,1.01,12],[1,1.01,0]],"ltp":1.27,"tv":728.7,"id":8679184}]}]}
{"op":"mcm","clk":"4232702773","pt":1631557675721,"mc":[{"id":"1.187594321","rc":[{"batb":[[0,3.4,12.5],[1,1.01,12]],"ltp":2.58,"tv":115.91,"id":11862899},{"batb":[[0,1.27,111.11],[1,1.01,12]],"ltp":1.27,"tv":728.7,"id":8679184}]}]}
{"op":"mcm","clk":"4232706408","pt":1631557710745,"mc":[{"id":"1.187594321","rc":[{"batb":[[0,1.01,12],[1,1.01,0]],"ltp":2.58,"tv":115.91,"id":11862899},{"batb":[[0,1.01,12],[1,1.01,0]],"ltp":1.27,"tv":728.7,"id":8679184}]}]}
{"op":"mcm","clk":"4232706900","pt":1631557715669,"mc":[{"id":"1.187594321","rc":[{"batb":[[0,2.66,18.07],[1,1.01,12]],"ltp":2.58,"tv":115.91,"id":11862899},{"batb":[[0,1.42,71.42],[1,1.01,12]],"ltp":1.27,"tv":728.7,"id":8679184}]}]}
{"op":"mcm","clk":"4232709552","pt":1631557742195,"mc":[{"id":"1.187594321","rc":[{"batb":[[0,1.01,12],[1,1.01,0]],"ltp":2.58,"tv":115.91,"id":11862899},{"batb":[[0,1.01,12],[1,1.01,0]],"ltp":1.27,"tv":728.7,"id":8679184}]}]}
{"op":"mcm","clk":"4232710050","pt":1631557747102,"mc":[{"id":"1.187594321","rc":[{"batb":[[0,2.34,22.38],[1,1.01,12]],"ltp":2.58,"tv":115.91,"id":11862899},{"batb":[[0,1.55,54.54],[1,1.01,12]],"ltp":1.27,"tv":728.7,"id":8679184}]}]}
{"op":"mcm","clk":"4232712958","pt":1631557776959,"mc":[{"id":"1.187594321","rc":[{"batb":[[0,1.01,12],[1,1.01,0]],"ltp":2.58,"tv":115.91,"id":11862899},{"batb":[[0,1.01,12],[1,1.01,0]],"ltp":1.27,"tv":728.7,"id":8679184}]}]}
{"op":"mcm","clk":"4232713456","pt":1631557781848,"mc":[{"id":"1.187594321","rc":[{"batb":[[0,2.06,28.3],[1,1.01,12]],"ltp":2.58,"tv":115.91,"id":11862899},{"batb":[[0,1.71,42.25],[1,1.01,12]],"ltp":1.27,"tv":728.7,"id":8679184}]}]}
{"op":"mcm","clk":"4232721573","pt":1631557855042,"mc":[{"id":"1.187594321","rc":[{"batb":[[0,1.01,12],[1,1.01,0]],"ltp":2.58,"tv":115.91,"id":11862899}]}]}
{"op":"mcm","clk":"4232722157","pt":1631557859961,"mc":[{"id":"1.187594321","rc":[{"batb":[[0,2.1,27.27],[1,1.01,12]],"ltp":2.58,"tv":115.91,"id":11862899}]}]}
{"op":"mcm","clk":"4232723528","pt":1631557873459,"mc":[{"id":"1.187594321","rc":[{"batb":[[0,1.01,12],[1,1.01,0]],"ltp":2.58,"tv":115.91,"id":11862899},{"batb":[[0,1.01,12],[1,1.01,0]],"ltp":1.27,"tv":728.7,"id":8679184}]}]}
{"op":"mcm","clk":"4232723951","pt":1631557878300,"mc":[{"id":"1.187594321","rc":[{"batb":[[0,1.98,30.61],[1,1.01,12]],"ltp":2.58,"tv":115.91,"id":11862899},{"batb":[[0,1.78,38.46],[1,1.01,12]],"ltp":1.27,"tv":728.7,"id":8679184}]}]}
{"op":"mcm","clk":"4232725832","pt":1631557898300,"mc":[{"id":"1.187594321","rc":[{"batb":[[0,1.01,12],[1,1.01,0]],"ltp":2.58,"tv":115.91,"id":11862899},{"batb":[[0,1.01,12],[1,1.01,0]],"ltp":1.27,"tv":728.7,"id":8679184}]}]}
{"op":"mcm","clk":"4232726299","pt":1631557903202,"mc":[{"id":"1.187594321","rc":[{"batb":[[0,2,30],[1,1.01,12]],"ltp":2.58,"tv":115.91,"id":11862899},{"batb":[[0,1.73,41.09],[1,1.01,12]],"ltp":1.27,"tv":728.7,"id":8679184}]}]}
{"op":"mcm","clk":"4232727907","pt":1631557923051,"mc":[{"id":"1.187594321","rc":[{"batb":[[0,1.01,12],[1,1.01,0]],"ltp":2.58,"tv":115.91,"id":11862899},{"batb":[[0,1.01,12],[1,1.01,0]],"ltp":1.27,"tv":728.7,"id":8679184}]}]}
{"op":"mcm","clk":"4232728288","pt":1631557927936,"mc":[{"id":"1.187594321","rc":[{"batb":[[0,2.1,27.27],[1,1.01,12]],"ltp":2.58,"tv":115.91,"id":11862899},{"batb":[[0,1.65,46.15],[1,1.01,12]],"ltp":1.27,"tv":728.7,"id":8679184}]}]}
{"op":"mcm","clk":"4232730775","pt":1631557954388,"mc":[{"id":"1.187594321","rc":[{"batb":[[0,1.01,12],[1,1.01,0]],"ltp":2.58,"tv":115.91,"id":11862899},{"batb":[[0,1.01,12],[1,1.01,0]],"ltp":1.27,"tv":728.7,"id":8679184}]}]}
{"op":"mcm","clk":"4232731252","pt":1631557959302,"mc":[{"id":"1.187594321","rc":[{"batb":[[0,1.98,30.61],[1,1.01,12]],"ltp":2.58,"tv":115.91,"id":11862899},{"batb":[[0,1.78,38.46],[1,1.01,12]],"ltp":1.27,"tv":728.7,"id":8679184}]}]}
{"op":"mcm","clk":"4232745832","pt":1631558105684,"mc":[{"id":"1.187594321","rc":[{"batb":[[0,1.01,12],[1,1.01,0]],"ltp":2.58,"tv":115.91,"id":11862899},{"batb":[[0,1.01,12],[1,1.01,0]],"ltp":1.27,"tv":728.7,"id":8679184}]}]}
{"op":"mcm","clk":"4232746383","pt":1631558110575,"mc":[{"id":"1.187594321","rc":[{"batb":[[0,1.85,35.29],[1,1.01,12]],"ltp":2.58,"tv":115.91,"id":11862899},{"batb":[[0,1.88,34.09],[1,1.01,12]],"ltp":1.27,"tv":728.7,"id":8679184}]}]}
{"op":"mcm","clk":"4232746416","pt":1631558110891,"mc":[{"id":"1.187594321","rc":[{"batb":[[0,1.01,12],[1,1.01,0]],"ltp":2.58,"tv":115.91,"id":11862899},{"batb":[[0,1.01,12],[1,1.01,0]],"ltp":1.27,"tv":728.7,"id":8679184}]}]}
{"op":"mcm","clk":"4232747582","pt":1631558120980,"mc":[{"id":"1.187594321","rc":[{"batb":[[0,2.2,24.99],[1,1.01,12]],"ltp":2.58,"tv":115.91,"id":11862899},{"batb":[[0,1.6,49.99],[1,1.01,12]],"ltp":1.27,"tv":728.7,"id":8679184}]}]}
{"op":"mcm","clk":"4232763432","pt":1631558267091,"mc":[{"id":"1.187594321","rc":[{"batb":[[0,1.01,12],[1,1.01,0]],"ltp":2.58,"tv":115.91,"id":11862899},{"batb":[[0,1.01,12],[1,1.01,0]],"ltp":1.27,"tv":728.7,"id":8679184}]}]}
{"op":"mcm","clk":"4232763984","pt":1631558272084,"mc":[{"id":"1.187594321","rc":[{"batb":[[0,2.58,18.98],[1,1.01,12]],"ltp":2.58,"tv":115.91,"id":11862899},{"batb":[[0,1.45,66.66],[1,1.01,12]],"ltp":1.27,"tv":728.7,"id":8679184}]}]}
{"op":"mcm","clk":"4232764878","pt":1631558281503,"mc":[{"id":"1.187594321","rc":[{"trd":[[2.58,40.74]],"batb":[[0,1.01,12],[1,1.01,0]],"batl":[[0,2.58,43.88],[1,100,0.19]],"ltp":2.58,"tv":153.87,"id":11862899}],"tv":882.57}]}
{"op":"mcm","clk":"4232764911","pt":1631558281781,"mc":[{"id":"1.187594321","rc":[{"batl":[[0,100,0.19],[1,100,0]],"ltp":2.58,"tv":153.87,"id":11862899}]}]}
{"op":"mcm","clk":"4232765318","pt":1631558285890,"mc":[{"id":"1.187594321","rc":[{"batl":[[0,2.58,16.9],[1,100,0.19]],"ltp":2.58,"tv":153.87,"id":11862899}]}]}
{"op":"mcm","clk":"4232765458","pt":1631558287303,"mc":[{"id":"1.187594321","rc":[{"trd":[[2.58,74.52]],"batb":[[0,2.44,20.83],[1,1.01,12]],"batl":[[0,2.58,15.7]],"ltp":2.58,"tv":187.65,"id":11862899}],"tv":916.36}]}
{"op":"mcm","clk":"4232765601","pt":1631558288580,"mc":[{"id":"1.187594321","rc":[{"batl":[[0,100,0.19],[1,100,0]],"ltp":2.58,"tv":187.65,"id":11862899}]}]}
{"op":"mcm","clk":"4232769338","pt":1631558322705,"mc":[{"id":"1.187594321","rc":[{"batb":[[0,1.01,12],[1,1.01,0]],"ltp":2.58,"tv":187.65,"id":11862899},{"batb":[[0,1.01,12],[1,1.01,0]],"ltp":1.27,"tv":728.7,"id":8679184}]}]}
{"op":"mcm","clk":"4232769868","pt":1631558327698,"mc":[{"id":"1.187594321","rc":[{"batb":[[0,2.84,16.3],[1,1.01,12]],"ltp":2.58,"tv":187.65,"id":11862899},{"batb":[[0,1.38,78.94],[1,1.01,12]],"ltp":1.27,"tv":728.7,"id":8679184}]}]}
{"op":"mcm","clk":"4232770097","pt":1631558330065,"mc":[{"id":"1.187594321","rc":[{"trd":[[2.84,32.6]],"batb":[[0,1.01,12],[1,1.01,0]],"ltp":2.84,"tv":220.25,"id":11862899}],"tv":948.96}]}
{"op":"mcm","clk":"4232770688","pt":1631558335311,"mc":[{"id":"1.187594321","rc":[{"batb":[[0,2.7,17.64],[1,1.01,12]],"ltp":2.84,"tv":220.25,"id":11862899}]}]}
{"op":"mcm","clk":"4232771855","pt":1631558345910,"mc":[{"id":"1.187594321","rc":[{"trd":[[2.7,12.28]],"batb":[[0,1.01,12],[1,1.01,0]],"ltp":2.7,"tv":232.53,"id":11862899}],"tv":961.24}]}
{"op":"mcm","clk":"4232772427","pt":1631558350923,"mc":[{"id":"1.187594321","rc":[{"batb":[[0,2.7,17.64],[1,1.01,12]],"ltp":2.7,"tv":232.53,"id":11862899}]}]}
{"op":"mcm","clk":"4232773568","pt":1631558359831,"mc":[{"id":"1.187594321","rc":[{"batb":[[0,1.01,12],[1,1.01,0]],"ltp":2.7,"tv":232.53,"id":11862899},{"batb":[[0,1.01,12],[1,1.01,0]],"ltp":1.27,"tv":728.7,"id":8679184}]}]}
{"op":"mcm","clk":"4232774168","pt":1631558364720,"mc":[{"id":"1.187594321","rc":[{"batb":[[0,2.66,18.07],[1,1.01,12]],"ltp":2.7,"tv":232.53,"id":11862899},{"batb":[[0,1.42,71.42],[1,1.01,12]],"ltp":1.27,"tv":728.7,"id":8679184}]}]}
{"op":"mcm","clk":"4232775417","pt":1631558375137,"mc":[{"id":"1.187594321","rc":[{"trd":[[2.66,18.07]],"batb":[[0,1.01,12],[1,1.01,0]],"ltp":2.66,"tv":250.6,"id":11862899},{"trd":[[1.61,29.86]],"ltp":1.61,"tv":758.56,"id":8679184}],"tv":1009.17}]}
{"op":"mcm","clk":"4232776014","pt":1631558380247,"mc":[{"id":"1.187594321","rc":[{"batb":[[0,2.52,19.73],[1,1.01,12]],"ltp":2.66,"tv":250.6,"id":11862899},{"batb":[[0,1.61,32.34],[1,1.42,71.42],[2,1.01,12]],"ltp":1.61,"tv":758.56,"id":8679184}]}]}
{"op":"mcm","clk":"4232776136","pt":1631558381247,"mc":[{"id":"1.187594321","rc":[{"batb":[[0,1.61,2.54]],"ltp":1.61,"tv":758.56,"id":8679184}]}]}
{"op":"mcm","clk":"4232776864","pt":1631558387369,"mc":[{"id":"1.187594321","rc":[{"trd":[[2.52,39.42]],"batb":[[0,1.01,12],[1,1.01,0]],"batl":[[0,2.52,14.8],[1,100,0.19]],"ltp":2.52,"tv":290.03,"id":11862899},{"batb":[[0,1.42,71.42],[1,1.01,12],[2,1.01,0]],"ltp":1.61,"tv":758.56,"id":8679184}],"tv":1048.59}]}
{"op":"mcm","clk":"4232776908","pt":1631558387748,"mc":[{"id":"1.187594321","rc":[{"batb":[[0,1.66,29.87],[1,1.42,71.42],[2,1.01,12]],"ltp":1.61,"tv":758.56,"id":8679184}]}]}
{"op":"mcm","clk":"4232777053","pt":1631558389059,"mc":[{"id":"1.187594321","rc":[{"batl":[[0,100,0.19],[1,100,0]],"ltp":2.52,"tv":290.03,"id":11862899},{"batb":[[0,1.42,71.42],[1,1.01,12],[2,1.01,0]],"ltp":1.61,"tv":758.56,"id":8679184}]}]}
{"op":"mcm","clk":"4232777189","pt":1631558390164,"mc":[{"id":"1.187594321","rc":[{"batl":[[0,2.52,12.8],[1,100,0.19]],"ltp":2.52,"tv":290.03,"id":11862899}]}]}
{"op":"mcm","clk":"4232777413","pt":1631558391859,"mc":[{"id":"1.187594321","rc":[{"batb":[[0,1.66,2.54],[1,1.42,71.42],[2,1.01,12]],"ltp":1.61,"tv":758.56,"id":8679184}]}]}
{"op":"mcm","clk":"4232777569","pt":1631558393171,"mc":[{"id":"1.187594321","rc":[{"batb":[[1,1.01,12],[2,1.01,0]],"ltp":1.61,"tv":758.56,"id":8679184}]}]}
{"op":"mcm","clk":"4232778190","pt":1631558398209,"mc":[{"id":"1.187594321","rc":[{"batb":[[1,1.34,88.23],[2,1.01,12]],"ltp":1.61,"tv":758.56,"id":8679184}]}]}
{"op":"mcm","clk":"4232778798","pt":1631558403610,"mc":[{"id":"1.187594321","rc":[{"batl":[[0,100,0.19],[1,100,0]],"ltp":2.52,"tv":290.03,"id":11862899}]}]}
{"op":"mcm","clk":"4232779441","pt":1631558409102,"mc":[{"id":"1.187594321","rc":[{"trd":[[2.52,41.09]],"ltp":2.52,"tv":291.7,"id":11862899},{"trd":[[1.66,2.54]],"batb":[[0,1.34,88.23],[1,1.01,12],[2,1.01,0]],"ltp":1.66,"tv":761.09,"id":8679184}],"tv":1052.8}]}
{"op":"mcm","clk":"4232780070","pt":1631558414088,"mc":[{"id":"1.187594321","rc":[{"batb":[[0,3,15],[1,1.01,12]],"ltp":2.52,"tv":291.7,"id":11862899}]}]}
{"op":"mcm","clk":"4232780595","pt":1631558418798,"mc":[{"id":"1.187594321","rc":[{"batb":[[0,1.01,12],[1,1.01,0]],"ltp":2.52,"tv":291.7,"id":11862899},{"batb":[[0,1.01,12],[1,1.01,0]],"ltp":1.66,"tv":761.09,"id":8679184}]}]}
{"op":"mcm","clk":"4232781111","pt":1631558423115,"mc":[{"id":"1.187594321","rc":[{"batl":[[0,3,14.42],[1,100,0.19]],"ltp":2.52,"tv":291.7,"id":11862899}]}]}
{"op":"mcm","clk":"4232781309","pt":1631558424607,"mc":[{"id":"1.187594321","rc":[{"batb":[[0,2.84,16.3],[1,1.01,12]],"batl":[[0,3,28.59]],"ltp":2.52,"tv":291.7,"id":11862899},{"batb":[[0,1.38,78.94],[1,1.01,12]],"ltp":1.66,"tv":761.09,"id":8679184}]}]}
{"op":"mcm","clk":"4232781391","pt":1631558425205,"mc":[{"id":"1.187594321","rc":[{"batl":[[0,3,13.65]],"ltp":2.52,"tv":291.7,"id":11862899}]}]}
{"op":"mcm","clk":"4232781656","pt":1631558427344,"mc":[{"id":"1.187594321","rc":[{"batl":[[0,100,0.19],[1,100,0]],"ltp":2.52,"tv":291.7,"id":11862899}]}]}
{"op":"mcm","clk":"4232782165","pt":1631558431494,"mc":[{"id":"1.187594321","rc":[{"trd":[[2.84,64.52]],"batb":[[0,1.01,12],[1,1.01,0]],"ltp":2.84,"tv":323.62,"id":11862899}],"tv":1084.72}]}
{"op":"mcm","clk":"4232782189","pt":1631558431763,"mc":[{"id":"1.187594321","rc":[{"batl":[[0,2.84,16.3],[1,100,0.19]],"ltp":2.84,"tv":323.62,"id":11862899}]}]}
{"op":"mcm","clk":"4232782335","pt":1631558433006,"mc":[{"id":"1.187594321","rc":[{"batl":[[0,100,0.19],[1,100,0]],"ltp":2.84,"tv":323.62,"id":11862899}]}]}
{"op":"mcm","clk":"4232782735","pt":1631558436403,"mc":[{"id":"1.187594321","rc":[{"batb":[[0,2.7,17.64],[1,1.01,12]],"ltp":2.84,"tv":323.62,"id":11862899}]}]}
{"op":"mcm","clk":"4232783094","pt":1631558439497,"mc":[{"id":"1.187594321","rc":[{"batb":[[0,1.01,12],[1,1.01,0]],"ltp":2.84,"tv":323.62,"id":11862899},{"batb":[[0,1.01,12],[1,1.01,0]],"ltp":1.66,"tv":761.09,"id":8679184}]}]}
{"op":"mcm","clk":"4232783668","pt":1631558444278,"mc":[{"id":"1.187594321","rc":[{"batl":[[0,2.7,14.51],[1,100,0.19]],"ltp":2.84,"tv":323.62,"id":11862899}]}]}
{"op":"mcm","clk":"4232785633","pt":1631558459333,"mc":[{"id":"1.187594321","rc":[{"batl":[[0,100,0.19],[1,100,0]],"ltp":2.84,"tv":323.62,"id":11862899}]}]}
{"op":"mcm","clk":"4232827273","pt":1631558861366,"mc":[{"id":"1.187594321","marketDefinition":{"bspMarket":false,"turnInPlayEnabled":true,"persistenceEnabled":true,"marketBaseRate":5.0,"eventId":"30897905","eventTypeId":"2","numberOfWinners":1,"bettingType":"ODDS","marketType":"MATCH_ODDS","marketTime":"2021-09-13T16:37:37.000Z","suspendTime":"2021-09-13T16:37:37.000Z","bspReconciled":false,"complete":true,"inPlay":true,"crossMatching":true,"runnersVoidable":false,"numberOfActiveRunners":2,"betDelay":5,"status":"SUSPENDED","runners":[{"status":"ACTIVE","sortPriority":1,"id":8679184,"name":"I Rosca"},{"status":"ACTIVE","sortPriority":2,"id":11862899,"name":"C Cervino Ruiz"}],"regulators":["MR_INT"],"countryCode":"GB","discountAllowed":true,"timezone":"GMT","openDate":"2021-09-13T16:37:37.000Z","version":4031264853,"name":"Match Odds","eventName":"I Rosca v C Cervino Ruiz"}}]}
{"op":"mcm","clk":"4232835588","pt":1631558866397,"mc":[{"id":"1.187594321","marketDefinition":{"bspMarket":false,"turnInPlayEnabled":true,"persistenceEnabled":true,"marketBaseRate":5.0,"eventId":"30897905","eventTypeId":"2","numberOfWinners":1,"bettingType":"ODDS","marketType":"MATCH_ODDS","marketTime":"2021-09-13T16:37:37.000Z","suspendTime":"2021-09-13T16:37:37.000Z","bspReconciled":false,"complete":true,"inPlay":true,"crossMatching":false,"runnersVoidable":false,"numberOfActiveRunners":0,"betDelay":5,"status":"CLOSED","settledTime":"2021-09-13T18:47:43.000Z","runners":[{"status":"WINNER","sortPriority":1,"id":8679184,"name":"I Rosca"},{"status":"LOSER","sortPriority":2,"id":11862899,"name":"C Cervino Ruiz"}],"regulators":["MR_INT"],"countryCode":"GB","discountAllowed":true,"timezone":"GMT","openDate":"2021-09-13T16:37:37.000Z","version":4031264883,"name":"Match Odds","eventName":"I Rosca v C Cervino Ruiz"},"tv":0.0}]}
