{"op":"mcm","clk":"4229490606","pt":1631518387208,"mc":[{"id":"1.187594319","marketDefinition":{"bspMarket":false,"turnInPlayEnabled":true,"persistenceEnabled":true,"marketBaseRate":5.0,"eventId":"30897887","eventTypeId":"2","numberOfWinners":1,"bettingType":"ODDS","marketType":"MATCH_ODDS","marketTime":"2021-09-13T07:30:00.000Z","suspendTime":"2021-09-13T07:30:00.000Z","bspReconciled":false,"complete":true,"inPlay":false,"crossMatching":false,"runnersVoidable":false,"numberOfActiveRunners":2,"betDelay":0,"status":"OPEN","runners":[{"status":"ACTIVE","sortPriority":1,"id":13310360,"name":"W Falkowska"},{"status":"ACTIVE","sortPriority":2,"id":9628382,"name":"A Barnett"}],"regulators":["MR_INT"],"countryCode":"GB","discountAllowed":false,"timezone":"GMT","openDate":"2021-09-13T10:30:00.000Z","version":4030164805,"name":"Match Odds","eventName":"W Falkowska v A Barnett"},"rc":[{"batb":[[0,1.01,25]],"ltp":0.0,"tv":0.0,"id":13310360},{"batb":[[0,1.01,25]],"ltp":0.0,"tv":0.0,"id":9628382}]}]}
{"op":"mcm","clk":"4229490649","pt":1631518388646,"mc":[{"id":"1.187594319","marketDefinition":{"bspMarket":false,"turnInPlayEnabled":true,"persistenceEnabled":true,"marketBaseRate":5.0,"eventId":"30897887","eventTypeId":"2","numberOfWinners":1,"bettingType":"ODDS","marketType":"MATCH_ODDS","marketTime":"2021-09-13T07:30:00.000Z","suspendTime":"2021-09-13T07:30:00.000Z","bspReconciled":false,"complete":true,"inPlay":false,"crossMatching":false,"runnersVoidable":false,"numberOfActiveRunners":2,"betDelay":0,"status":"OPEN","runners":[{"status":"ACTIVE","sortPriority":1,"id":13310360,"name":"W Falkowska"},{"status":"ACTIVE","sortPriority":2,"id":9628382,"name":"A Barnett"}],"regulators":["MR_INT"],"countryCode":"GB","discountAllowed":true,"timezone":"GMT","openDate":"2021-09-13T10:30:00.000Z","version":4030164805,"name":"Match Odds","eventName":"W Falkowska v A Barnett"}}]}
{"op":"mcm","clk":"4229517255","pt":1631519122212,"mc":[{"id":"1.187594319","rc":[{"batb":[[0,1.01,7]],"ltp":0.0,"tv":0.0,"id":13310360},{"batb":[[0,1.01,7]],"ltp":0.0,"tv":0.0,"id":9628382}]}]}
{"op":"mcm","clk":"4229519412","pt":1631519188676,"mc":[{"id":"1.187594319","rc":[{"batb":[[0,1.02,2202.2],[1,1.01,7]],"ltp":0.0,"tv":0.0,"id":13310360},{"batb":[[0,1.05,880.88],[1,1.01,7]],"ltp":0.0,"tv":0.0,"id":9628382}]}]}
{"op":"mcm","clk":"4229678817","pt":1631522452668,"mc":[{"id":"1.187594319","rc":[{"batl":[[0,1.68,2.66]],"ltp":0.0,"tv":0.0,"id":13310360}]}]}
{"op":"mcm","clk":"4229679008","pt":1631522456992,"mc":[{"id":"1.187594319","rc":[{"batb":[[1,1.01,60.23]],"ltp":0.0,"tv":0.0,"id":13310360}]}]}
{"op":"mcm","clk":"4229693161","pt":1631522762133,"mc":[{"id":"1.187594319","marketDefinition":{"bspMarket":false,"turnInPlayEnabled":true,"persistenceEnabled":true,"marketBaseRate":5.0,"eventId":"30897887","eventTypeId":"2","numberOfWinners":1,"bettingType":"ODDS","marketType":"MATCH_ODDS","marketTime":"2021-09-13T12:30:00.000Z","suspendTime":"2021-09-13T12:30:00.000Z","bspReconciled":false,"complete":true,"inPlay":false,"crossMatching":false,"runnersVoidable":false,"numberOfActiveRunners":2,"betDelay":0,"status":"OPEN","runners":[{"status":"ACTIVE","sortPriority":1,"id":13310360,"name":"W Falkowska"},{"status":"ACTIVE","sortPriority":2,"id":9628382,"name":"A Barnett"}],"regulators":["MR_INT"],"countryCode":"GB","discountAllowed":true,"timezone":"GMT","openDate":"2021-09-13T10:30:00.000Z","version":4030340782,"name":"Match Odds","eventName":"W Falkowska v A Barnett"}}]}
{"op":"mcm","clk":"4229693276","pt":1631522764139,"mc":[{"id":"1.187594319","marketDefinition":{"bspMarket":false,"turnInPlayEnabled":true,"persistenceEnabled":true,"marketBaseRate":5.0,"eventId":"30897887","eventTypeId":"2","numberOfWinners":1,"bettingType":"ODDS","marketType":"MATCH_ODDS","marketTime":"2021-09-13T12:30:00.000Z","suspendTime":"2021-09-13T12:30:00.000Z","bspReconciled":false,"complete":true,"inPlay":false,"crossMatching":false,"runnersVoidable":false,"numberOfActiveRunners":2,"betDelay":0,"status":"OPEN","runners":[{"status":"ACTIVE","sortPriority":1,"id":13310360,"name":"W Falkowska"},{"status":"ACTIVE","sortPriority":2,"id":9628382,"name":"A Barnett"}],"regulators":["MR_INT"],"countryCode":"GB","discountAllowed":true,"timezone":"GMT","openDate":"2021-09-13T12:30:00.000Z","version":4030340782,"name":"Match Odds","eventName":"W Falkowska v A Barnett"}}]}
{"op":"mcm","clk":"4229743022","pt":1631523785965,"mc":[{"id":"1.187594319","rc":[{"batb":[[0,1.06,500],[1,1.02,2200.89],[2,1.01,60.28]],"batl":[[0,1.68,2.66]],"ltp":0.0,"tv":0.0,"id":13310360},{"batb":[[0,7.4,10],[1,1.05,880.36],[2,1.01,7]],"ltp":0.0,"tv":0.0,"id":9628382}]}]}
{"op":"mcm","clk":"4229743314","pt":1631523791426,"mc":[{"id":"1.187594319","marketDefinition":{"bspMarket":false,"turnInPlayEnabled":true,"persistenceEnabled":true,"marketBaseRate":5.0,"eventId":"30897887","eventTypeId":"2","numberOfWinners":1,"bettingType":"ODDS","marketType":"MATCH_ODDS","marketTime":"2021-09-13T12:30:00.000Z","suspendTime":"2021-09-13T12:30:00.000Z","bspReconciled":false,"complete":true,"inPlay":false,"crossMatching":true,"runnersVoidable":false,"numberOfActiveRunners":2,"betDelay":0,"status":"OPEN","runners":[{"status":"ACTIVE","sortPriority":1,"id":13310360,"name":"W Falkowska"},{"status":"ACTIVE","sortPriority":2,"id":9628382,"name":"A Barnett"}],"regulators":["MR_INT"],"countryCode":"GB","discountAllowed":true,"timezone":"GMT","openDate":"2021-09-13T12:30:00.000Z","version":4030340782,"name":"Match Odds","eventName":"W Falkowska v A Barnett"}}]}
{"op":"mcm","clk":"4229776982","pt":1631524352813,"mc":[{"id":"1.187594319","rc":[{"batl":[[1,990,2.2]],"ltp":0.0,"tv":0.0,"id":13310360},{"batl":[[0,990,2.2]],"ltp":0.0,"tv":0.0,"id":9628382}]}]}
{"op":"mcm","clk":"4229850902","pt":1631525635684,"mc":[{"id":"1.187594319","rc":[{"batb":[[1,1.01,7],[2,1.01,0]],"ltp":0.0,"tv":0.0,"id":9628382}]}]}
{"op":"mcm","clk":"4229851377","pt":1631525642738,"mc":[{"id":"1.187594319","rc":[{"batl":[[0,1.66,44.02],[1,1.68,2.66],[2,990,2.2]],"ltp":0.0,"tv":0.0,"id":13310360}]}]}
{"op":"mcm","clk":"4229881529","pt":1631526086028,"mc":[{"id":"1.187594319","marketDefinition":{"bspMarket":false,"turnInPlayEnabled":true,"persistenceEnabled":true,"marketBaseRate":5.0,"eventId":"30897887","eventTypeId":"2","numberOfWinners":1,"bettingType":"ODDS","marketType":"MATCH_ODDS","marketTime":"2021-09-13T12:40:00.000Z","suspendTime":"2021-09-13T12:40:00.000Z","bspReconciled":false,"complete":true,"inPlay":false,"crossMatching":true,"runnersVoidable":false,"numberOfActiveRunners":2,"betDelay":0,"status":"OPEN","runners":[{"status":"ACTIVE","sortPriority":1,"id":13310360,"name":"W Falkowska"},{"status":"ACTIVE","sortPriority":2,"id":9628382,"name":"A Barnett"}],"regulators":["MR_INT"],"countryCode":"GB","discountAllowed":true,"timezone":"GMT","openDate":"2021-09-13T12:30:00.000Z","version":4030511781,"name":"Match Odds","eventName":"W Falkowska v A Barnett"}}]}
{"op":"mcm","clk":"4229881982","pt":1631526089042,"mc":[{"id":"1.187594319","marketDefinition":{"bspMarket":false,"turnInPlayEnabled":true,"persistenceEnabled":true,"marketBaseRate":5.0,"eventId":"30897887","eventTypeId":"2","numberOfWinners":1,"bettingType":"ODDS","marketType":"MATCH_ODDS","marketTime":"2021-09-13T12:40:00.000Z","suspendTime":"2021-09-13T12:40:00.000Z","bspReconciled":false,"complete":true,"inPlay":false,"crossMatching":true,"runnersVoidable":false,"numberOfActiveRunners":2,"betDelay":0,"status":"OPEN","runners":[{"status":"ACTIVE","sortPriority":1,"id":13310360,"name":"W Falkowska"},{"status":"ACTIVE","sortPriority":2,"id":9628382,"name":"A Barnett"}],"regulators":["MR_INT"],"countryCode":"GB","discountAllowed":true,"timezone":"GMT","openDate":"2021-09-13T12:40:00.000Z","version":4030511781,"name":"Match Odds","eventName":"W Falkowska v A Barnett"}}]}
{"op":"mcm","clk":"4230118805","pt":1631529187383,"mc":[{"id":"1.187594319","rc":[{"batb":[[0,1.07,447.51]],"ltp":0.0,"tv":0.0,"id":13310360},{"batb":[[0,7,10]],"ltp":0.0,"tv":0.0,"id":9628382}]}]}
{"op":"mcm","clk":"4230151064","pt":1631529604938,"mc":[{"id":"1.187594319","rc":[{"batb":[[0,1.07,500]],"ltp":0.0,"tv":0.0,"id":13310360}]}]}
{"op":"mcm","clk":"4230167021","pt":1631529804853,"mc":[{"id":"1.187594319","marketDefinition":{"bspMarket":false,"turnInPlayEnabled":true,"persistenceEnabled":true,"marketBaseRate":5.0,"eventId":"30897887","eventTypeId":"2","numberOfWinners":1,"bettingType":"ODDS","marketType":"MATCH_ODDS","marketTime":"2021-09-13T12:30:00.000Z","suspendTime":"2021-09-13T12:30:00.000Z","bspReconciled":false,"complete":true,"inPlay":false,"crossMatching":true,"runnersVoidable":false,"numberOfActiveRunners":2,"betDelay":0,"status":"OPEN","runners":[{"status":"ACTIVE","sortPriority":1,"id":13310360,"name":"W Falkowska"},{"status":"ACTIVE","sortPriority":2,"id":9628382,"name":"A Barnett"}],"regulators":["MR_INT"],"countryCode":"GB","discountAllowed":true,"timezone":"GMT","openDate":"2021-09-13T12:40:00.000Z","version":4030552806,"name":"Match Odds","eventName":"W Falkowska v A Barnett"}}]}
{"op":"mcm","clk":"4230167212","pt":1631529806864,"mc":[{"id":"1.187594319","marketDefinition":{"bspMarket":false,"turnInPlayEnabled":true,"persistenceEnabled":true,"marketBaseRate":5.0,"eventId":"30897887","eventTypeId":"2","numberOfWinners":1,"bettingType":"ODDS","marketType":"MATCH_ODDS","marketTime":"2021-09-13T12:30:00.000Z","suspendTime":"2021-09-13T12:30:00.000Z","bspReconciled":false,"complete":true,"inPlay":false,"crossMatching":true,"runnersVoidable":false,"numberOfActiveRunners":2,"betDelay":0,"status":"OPEN","runners":[{"status":"ACTIVE","sortPriority":1,"id":13310360,"name":"W Falkowska"},{"status":"ACTIVE","sortPriority":2,"id":9628382,"name":"A Barnett"}],"regulators":["MR_INT"],"countryCode":"GB","discountAllowed":true,"timezone":"GMT","openDate":"2021-09-13T12:30:00.000Z","version":4030552806,"name":"Match Odds","eventName":"W Falkowska v A Barnett"}}]}
{"op":"mcm","clk":"4230305920","pt":1631531508207,"mc":[{"id":"1.187594319","marketDefinition":{"bspMarket":false,"turnInPlayEnabled":true,"persistenceEnabled":true,"marketBaseRate":5.0,"eventId":"30897887","eventTypeId":"2","numberOfWinners":1,"bettingType":"ODDS","marketType":"MATCH_ODDS","marketTime":"2021-09-13T12:40:00.000Z","suspendTime":"2021-09-13T12:40:00.000Z","bspReconciled":false,"complete":true,"inPlay":false,"crossMatching":true,"runnersVoidable":false,"numberOfActiveRunners":2,"betDelay":0,"status":"OPEN","runners":[{"status":"ACTIVE","sortPriority":1,"id":13310360,"name":"W Falkowska"},{"status":"ACTIVE","sortPriority":2,"id":9628382,"name":"A Barnett"}],"regulators":["MR_INT"],"countryCode":"GB","discountAllowed":true,"timezone":"GMT","openDate":"2021-09-13T12:30:00.000Z","version":4030580016,"name":"Match Odds","eventName":"W Falkowska v A Barnett"}}]}
{"op":"mcm","clk":"4230306177","pt":1631531511221,"mc":[{"id":"1.187594319","marketDefinition":{"bspMarket":false,"turnInPlayEnabled":true,"persistenceEnabled":true,"marketBaseRate":5.0,"eventId":"30897887","eventTypeId":"2","numberOfWinners":1,"bettingType":"ODDS","marketType":"MATCH_ODDS","marketTime":"2021-09-13T12:40:00.000Z","suspendTime":"2021-09-13T12:40:00.000Z","bspReconciled":false,"complete":true,"inPlay":false,"crossMatching":true,"runnersVoidable":false,"numberOfActiveRunners":2,"betDelay":0,"status":"OPEN","runners":[{"status":"ACTIVE","sortPriority":1,"id":13310360,"name":"W Falkowska"},{"status":"ACTIVE","sortPriority":2,"id":9628382,"name":"A Barnett"}],"regulators":["MR_INT"],"countryCode":"GB","discountAllowed":true,"timezone":"GMT","openDate":"2021-09-13T12:40:00.000Z","version":4030580016,"name":"Match Odds","eventName":"W Falkowska v A Barnett"}}]}
{"op":"mcm","clk":"4230341822","pt":1631531865777,"mc":[{"id":"1.187594319","rc":[{"batb":[[1,1.02,2198.78],[2,1.01,60.16]],"batl":[[0,1.66,43.98],[1,1.68,2.66]],"ltp":0.0,"tv":0.0,"id":13310360}]}]}
{"op":"mcm","clk":"4230365858","pt":1631532131774,"mc":[{"id":"1.187594319","rc":[{"batl":[[0,1.21,100],[1,1.66,43.98],[2,1.68,2.66]],"ltp":0.0,"tv":0.0,"id":13310360}]}]}
{"op":"mcm","clk":"4230455742","pt":1631533201532,"mc":[{"id":"1.187594319","rc":[{"batb":[[0,1.08,85.18],[1,1.07,500],[2,1.02,2198.78]],"ltp":0.0,"tv":0.0,"id":13310360},{"batb":[[0,7,12.13]],"ltp":0.0,"tv":0.0,"id":9628382}]}]}
{"op":"mcm","clk":"4230584280","pt":1631534545650,"mc":[{"id":"1.187594319","marketDefinition":{"bspMarket":false,"turnInPlayEnabled":true,"persistenceEnabled":true,"marketBaseRate":5.0,"eventId":"30897887","eventTypeId":"2","numberOfWinners":1,"bettingType":"ODDS","marketType":"MATCH_ODDS","marketTime":"2021-09-13T12:30:00.000Z","suspendTime":"2021-09-13T12:30:00.000Z","bspReconciled":false,"complete":true,"inPlay":false,"crossMatching":true,"runnersVoidable":false,"numberOfActiveRunners":2,"betDelay":0,"status":"OPEN","runners":[{"status":"ACTIVE","sortPriority":1,"id":13310360,"name":"W Falkowska"},{"status":"ACTIVE","sortPriority":2,"id":9628382,"name":"A Barnett"}],"regulators":["MR_INT"],"countryCode":"GB","discountAllowed":true,"timezone":"GMT","openDate":"2021-09-13T12:40:00.000Z","version":4030620729,"name":"Match Odds","eventName":"W Falkowska v A Barnett"}}]}
{"op":"mcm","clk":"4230584626","pt":1631534548664,"mc":[{"id":"1.187594319","marketDefinition":{"bspMarket":false,"turnInPlayEnabled":true,"persistenceEnabled":true,"marketBaseRate":5.0,"eventId":"30897887","eventTypeId":"2","numberOfWinners":1,"bettingType":"ODDS","marketType":"MATCH_ODDS","marketTime":"2021-09-13T12:30:00.000Z","suspendTime":"2021-09-13T12:30:00.000Z","bspReconciled":false,"complete":true,"inPlay":false,"crossMatching":true,"runnersVoidable":false,"numberOfActiveRunners":2,"betDelay":0,"status":"OPEN","runners":[{"status":"ACTIVE","sortPriority":1,"id":13310360,"name":"W Falkowska"},{"status":"ACTIVE","sortPriority":2,"id":9628382,"name":"A Barnett"}],"regulators":["MR_INT"],"countryCode":"GB","discountAllowed":true,"timezone":"GMT","openDate":"2021-09-13T12:30:00.000Z","version":4030620729,"name":"Match Odds","eventName":"W Falkowska v A Barnett"}}]}
{"op":"mcm","clk":"4230599112","pt":1631534677521,"mc":[{"id":"1.187594319","rc":[{"trd":[[1.17,0.02]],"ltp":1.17,"tv":0.01,"id":13310360}],"tv":0.01}]}
{"op":"mcm","clk":"4230604127","pt":1631534722824,"mc":[{"id":"1.187594319","rc":[{"trd":[[1.08,0.08]],"batb":[[0,1.08,85.14]],"ltp":1.08,"tv":0.1,"id":13310360}],"tv":0.1}]}
{"op":"mcm","clk":"4230638686","pt":1631535037372,"mc":[{"id":"1.187594319","rc":[{"batb":[[2,1.06,2.66]],"ltp":1.08,"tv":0.1,"id":13310360},{"batb":[[1,6.6,2.66],[2,1.01,7]],"ltp":0.0,"tv":0.0,"id":9628382}]}]}
{"op":"mcm","clk":"4230660472","pt":1631535265982,"mc":[{"id":"1.187594319","rc":[{"batb":[[1,1.06,502.66],[2,1.02,2198.78]],"ltp":1.08,"tv":0.1,"id":13310360},{"batb":[[0,7.4,10],[1,7,2.13],[2,6.6,2.66]],"ltp":0.0,"tv":0.0,"id":9628382}]}]}
{"op":"mcm","clk":"4230660588","pt":1631535267295,"mc":[{"id":"1.187594319","rc":[{"batb":[[0,1.07,85.18]],"ltp":1.08,"tv":0.1,"id":13310360},{"batb":[[0,7.4,11.99]],"ltp":0.0,"tv":0.0,"id":9628382}]}]}
{"op":"mcm","clk":"4230753799","pt":1631536261246,"mc":[{"id":"1.187594319","marketDefinition":{"bspMarket":false,"turnInPlayEnabled":true,"persistenceEnabled":true,"marketBaseRate":5.0,"eventId":"30897887","eventTypeId":"2","numberOfWinners":1,"bettingType":"ODDS","marketType":"MATCH_ODDS","marketTime":"2021-09-13T12:30:00.000Z","suspendTime":"2021-09-13T12:30:00.000Z","bspReconciled":false,"complete":true,"inPlay":true,"crossMatching":true,"runnersVoidable":false,"numberOfActiveRunners":2,"betDelay":5,"status":"OPEN","runners":[{"status":"ACTIVE","sortPriority":1,"id":13310360,"name":"W Falkowska"},{"status":"ACTIVE","sortPriority":2,"id":9628382,"name":"A Barnett"}],"regulators":["MR_INT"],"countryCode":"GB","discountAllowed":true,"timezone":"GMT","openDate":"2021-09-13T12:30:00.000Z","version":4030641030,"name":"Match Odds","eventName":"W Falkowska v A Barnett"},"rc":[{"batb":[[0,1.01,7],[1,1.06,0],[2,1.02,0]],"batl":[[1,1.66,0],[2,1.68,0]],"ltp":1.08,"tv":0.1,"id":13310360},{"batb":[[0,1.01,7],[1,7,0],[2,6.6,0]],"ltp":0.0,"tv":0.0,"id":9628382}]}]}
{"op":"mcm","clk":"4230754247","pt":1631536266420,"mc":[{"id":"1.187594319","rc":[{"batb":[[0,1.04,749.99],[1,1.01,7]],"ltp":1.08,"tv":0.1,"id":13310360},{"batb":[[0,7,10],[1,1.01,7]],"ltp":0.0,"tv":0.0,"id":9628382}]}]}
{"op":"mcm","clk":"4230805878","pt":1631536813534,"mc":[{"id":"1.187594319","marketDefinition":{"bspMarket":false,"turnInPlayEnabled":true,"persistenceEnabled":true,"marketBaseRate":5.0,"eventId":"30897887","eventTypeId":"2","numberOfWinners":1,"bettingType":"ODDS","marketType":"MATCH_ODDS","marketTime":"2021-09-13T12:40:12.000Z","suspendTime":"2021-09-13T12:40:12.000Z","bspReconciled":false,"complete":true,"inPlay":true,"crossMatching":true,"runnersVoidable":false,"numberOfActiveRunners":2,"betDelay":5,"status":"OPEN","runners":[{"status":"ACTIVE","sortPriority":1,"id":13310360,"name":"W Falkowska"},{"status":"ACTIVE","sortPriority":2,"id":9628382,"name":"A Barnett"}],"regulators":["MR_INT"],"countryCode":"GB","discountAllowed":true,"timezone":"GMT","openDate":"2021-09-13T12:30:00.000Z","version":4030653748,"name":"Match Odds","eventName":"W Falkowska v A Barnett"},"rc":[{"batb":[[0,1.01,7],[1,1.01,0]],"ltp":1.08,"tv":0.1,"id":13310360},{"batb":[[0,1.01,7],[1,1.01,0]],"ltp":0.0,"tv":0.0,"id":9628382}]}]}
{"op":"mcm","clk":"4230806129","pt":1631536816550,"mc":[{"id":"1.187594319","marketDefinition":{"bspMarket":false,"turnInPlayEnabled":true,"persistenceEnabled":true,"marketBaseRate":5.0,"eventId":"30897887","eventTypeId":"2","numberOfWinners":1,"bettingType":"ODDS","marketType":"MATCH_ODDS","marketTime":"2021-09-13T12:40:12.000Z","suspendTime":"2021-09-13T12:40:12.000Z","bspReconciled":false,"complete":true,"inPlay":true,"crossMatching":true,"runnersVoidable":false,"numberOfActiveRunners":2,"betDelay":5,"status":"OPEN","runners":[{"status":"ACTIVE","sortPriority":1,"id":13310360,"name":"W Falkowska"},{"status":"ACTIVE","sortPriority":2,"id":9628382,"name":"A Barnett"}],"regulators":["MR_INT"],"countryCode":"GB","discountAllowed":true,"timezone":"GMT","openDate":"2021-09-13T12:40:12.000Z","version":4030653748,"name":"Match Odds","eventName":"W Falkowska v A Barnett"}}]}
{"op":"mcm","clk":"4230806268","pt":1631536818235,"mc":[{"id":"1.187594319","rc":[{"batb":[[0,1.05,599.99],[1,1.01,7]],"ltp":1.08,"tv":0.1,"id":13310360},{"batb":[[0,7.6,10],[1,1.01,7]],"ltp":0.0,"tv":0.0,"id":9628382}]}]}
{"op":"mcm","clk":"4230808100","pt":1631536837945,"mc":[{"id":"1.187594319","rc":[{"batb":[[0,1.01,7],[1,1.01,0]],"ltp":1.08,"tv":0.1,"id":13310360},{"batb":[[0,1.01,7],[1,1.01,0]],"ltp":0.0,"tv":0.0,"id":9628382}]}]}
{"op":"mcm","clk":"4230808545","pt":1631536842960,"mc":[{"id":"1.187594319","rc":[{"batb":[[0,1.04,749.99],[1,1.01,7]],"ltp":1.08,"tv":0.1,"id":13310360},{"batb":[[0,8,10],[1,1.01,7]],"ltp":0.0,"tv":0.0,"id":9628382}]}]}
{"op":"mcm","clk":"4230811657","pt":1631536870192,"mc":[{"id":"1.187594319","rc":[{"batb":[[0,1.01,7],[1,1.01,0]],"ltp":1.08,"tv":0.1,"id":13310360},{"batb":[[0,1.01,7],[1,1.01,0]],"ltp":0.0,"tv":0.0,"id":9628382}]}]}
{"op":"mcm","clk":"4230812118","pt":1631536875104,"mc":[{"id":"1.187594319","rc":[{"batb":[[0,1.05,599.99],[1,1.01,7]],"ltp":1.08,"tv":0.1,"id":13310360},{"batb":[[0,7.6,10],[1,1.01,7]],"ltp":0.0,"tv":0.0,"id":9628382}]}]}
{"op":"mcm","clk":"4230816184","pt":1631536916589,"mc":[{"id":"1.187594319","rc":[{"batb":[[0,1.01,7],[1,1.01,0]],"ltp":1.08,"tv":0.1,"id":13310360},{"batb":[[0,1.01,7],[1,1.01,0]],"ltp":0.0,"tv":0.0,"id":9628382}]}]}
{"op":"mcm","clk":"4230816700","pt":1631536921502,"mc":[{"id":"1.187594319","rc":[{"batb":[[0,1.04,749.99],[1,1.01,7]],"ltp":1.08,"tv":0.1,"id":13310360},{"batb":[[0,8,10],[1,1.01,7]],"ltp":0.0,"tv":0.0,"id":9628382}]}]}
{"op":"mcm","clk":"4230819892","pt":1631536954769,"mc":[{"id":"1.187594319","rc":[{"batb":[[0,1.01,7],[1,1.01,0]],"ltp":1.08,"tv":0.1,"id":13310360},{"batb":[[0,1.01,7],[1,1.01,0]],"ltp":0.0,"tv":0.0,"id":9628382}]}]}
{"op":"mcm","clk":"4230820349","pt":1631536959681,"mc":[{"id":"1.187594319","rc":[{"batb":[[0,1.05,599.99],[1,1.01,7]],"ltp":1.08,"tv":0.1,"id":13310360},{"batb":[[0,7.6,10],[1,1.01,7]],"ltp":0.0,"tv":0.0,"id":9628382}]}]}
{"op":"mcm","clk":"4230822500","pt":1631536983102,"mc":[{"id":"1.187594319","rc":[{"batb":[[0,1.01,7],[1,1.01,0]],"ltp":1.08,"tv":0.1,"id":13310360},{"batb":[[0,1.01,7],[1,1.01,0]],"ltp":0.0,"tv":0.0,"id":9628382}]}]}
{"op":"mcm","clk":"4230822964","pt":1631536988012,"mc":[{"id":"1.187594319","rc":[{"batb":[[0,1.08,374.99],[1,1.01,7]],"ltp":1.08,"tv":0.1,"id":13310360},{"batb":[[0,6,10],[1,1.01,7]],"ltp":0.0,"tv":0.0,"id":9628382}]}]}
{"op":"mcm","clk":"4230823088","pt":1631536989545,"mc":[{"id":"1.187594319","rc":[{"batb":[[0,1.09,763.45],[1,1.08,374.99],[2,1.01,7]],"batl":[[1,1.46,834.89]],"ltp":1.08,"tv":0.1,"id":13310360}]}]}
{"op":"mcm","clk":"4230825285","pt":1631537014382,"mc":[{"id":"1.187594319","rc":[{"batb":[[0,1.08,374.99],[1,1.01,7],[2,1.01,0]],"batl":[[1,1.46,0]],"ltp":1.08,"tv":0.1,"id":13310360}]}]}
{"op":"mcm","clk":"4230826048","pt":1631537023074,"mc":[{"id":"1.187594319","rc":[{"batb":[[0,1.01,7],[1,1.01,0]],"ltp":1.08,"tv":0.1,"id":13310360},{"batb":[[0,1.01,7],[1,1.01,0]],"ltp":0.0,"tv":0.0,"id":9628382}]}]}
{"op":"mcm","clk":"4230826470","pt":1631537028009,"mc":[{"id":"1.187594319","rc":[{"batb":[[0,1.05,599.99],[1,1.01,7]],"ltp":1.08,"tv":0.1,"id":13310360},{"batb":[[0,7.6,10],[1,1.01,7]],"ltp":0.0,"tv":0.0,"id":9628382}]}]}
{"op":"mcm","clk":"4230828813","pt":1631537055356,"mc":[{"id":"1.187594319","rc":[{"batb":[[0,1.01,7],[1,1.01,0]],"ltp":1.08,"tv":0.1,"id":13310360},{"batb":[[0,1.01,7],[1,1.01,0]],"ltp":0.0,"tv":0.0,"id":9628382}]}]}
{"op":"mcm","clk":"4230829323","pt":1631537060386,"mc":[{"id":"1.187594319","rc":[{"batb":[[0,1.04,749.99],[1,1.01,7]],"ltp":1.08,"tv":0.1,"id":13310360},{"batb":[[0,8,10],[1,1.01,7]],"ltp":0.0,"tv":0.0,"id":9628382}]}]}
{"op":"mcm","clk":"4230832808","pt":1631537099414,"mc":[{"id":"1.187594319","rc":[{"batb":[[0,1.01,7],[1,1.01,0]],"ltp":1.08,"tv":0.1,"id":13310360},{"batb":[[0,1.01,7],[1,1.01,0]],"ltp":0.0,"tv":0.0,"id":9628382}]}]}
{"op":"mcm","clk":"4230833301","pt":1631537104445,"mc":[{"id":"1.187594319","rc":[{"batb":[[0,1.05,599.99],[1,1.01,7]],"ltp":1.08,"tv":0.1,"id":13310360},{"batb":[[0,7.6,10],[1,1.01,7]],"ltp":0.0,"tv":0.0,"id":9628382}]}]}
{"op":"mcm","clk":"4230838999","pt":1631537162915,"mc":[{"id":"1.187594319","rc":[{"batb":[[0,1.01,7],[1,1.01,0]],"ltp":1.08,"tv":0.1,"id":13310360},{"batb":[[0,1.01,7],[1,1.01,0]],"ltp":0.0,"tv":0.0,"id":9628382}]}]}
{"op":"mcm","clk":"4230839495","pt":1631537168632,"mc":[{"id":"1.187594319","rc":[{"batb":[[0,1.09,763.45],[1,1.08,374.99],[2,1.01,7]],"batl":[[1,1.46,834.89]],"ltp":1.08,"tv":0.1,"id":13310360},{"batb":[[0,6,10],[1,1.01,7]],"ltp":0.0,"tv":0.0,"id":9628382}]}]}
{"op":"mcm","clk":"4230841806","pt":1631537194866,"mc":[{"id":"1.187594319","rc":[{"batb":[[0,1.01,7],[1,1.08,0],[2,1.01,0]],"ltp":1.08,"tv":0.1,"id":13310360},{"batb":[[0,1.01,7],[1,1.01,0]],"ltp":0.0,"tv":0.0,"id":9628382}]}]}
{"op":"mcm","clk":"4230842282","pt":1631537200203,"mc":[{"id":"1.187594319","rc":[{"batb":[[0,1.11,272.72],[1,1.1,733.19],[2,1.01,7]],"ltp":1.08,"tv":0.1,"id":13310360},{"batb":[[0,5.8,10],[1,1.01,7]],"ltp":0.0,"tv":0.0,"id":9628382}]}]}
{"op":"mcm","clk":"4230843959","pt":1631537218603,"mc":[{"id":"1.187594319","rc":[{"trd":[[1.11,5.11]],"batb":[[0,1.1,733.19],[1,1.01,7],[2,1.01,0]],"ltp":1.11,"tv":5.2,"id":13310360}],"tv":5.2}]}
{"op":"mcm","clk":"4230844440","pt":1631537223512,"mc":[{"id":"1.187594319","rc":[{"batb":[[0,1.11,272.72],[1,1.1,733.19],[2,1.01,7]],"ltp":1.11,"tv":5.2,"id":13310360}]}]}
{"op":"mcm","clk":"4230858108","pt":1631537281550,"mc":[{"id":"1.187594319","rc":[{"batb":[[0,1.1,733.19],[1,1.01,7],[2,1.01,0]],"ltp":1.11,"tv":5.2,"id":13310360},{"batb":[[0,1.01,7],[1,1.01,0]],"ltp":0.0,"tv":0.0,"id":9628382}]}]}
{"op":"mcm","clk":"4230858180","pt":1631537282230,"mc":[{"id":"1.187594319","rc":[{"batb":[[0,1.01,7],[1,1.01,0]],"ltp":1.11,"tv":5.2,"id":13310360}]}]}
{"op":"mcm","clk":"4230858574","pt":1631537286366,"mc":[{"id":"1.187594319","rc":[{"batb":[[0,1.08,374.99],[1,1.01,7]],"ltp":1.11,"tv":5.2,"id":13310360},{"batb":[[0,6,10],[1,1.01,7]],"ltp":0.0,"tv":0.0,"id":9628382}]}]}
{"op":"mcm","clk":"4230858775","pt":1631537287930,"mc":[{"id":"1.187594319","rc":[{"batb":[[0,1.09,763.45],[1,1.08,374.99],[2,1.01,7]],"ltp":1.11,"tv":5.2,"id":13310360}]}]}
{"op":"mcm","clk":"4230877660","pt":1631537488588,"mc":[{"id":"1.187594319","rc":[{"batb":[[1,1.01,7],[2,1.01,0]],"ltp":1.11,"tv":5.2,"id":13310360},{"batb":[[0,1.01,7],[1,1.01,0]],"ltp":0.0,"tv":0.0,"id":9628382}]}]}
{"op":"mcm","clk":"4230877805","pt":1631537489996,"mc":[{"id":"1.187594319","rc":[{"batb":[[0,1.01,7],[1,1.01,0]],"ltp":1.11,"tv":5.2,"id":13310360}]}]}
{"op":"mcm","clk":"4230878171","pt":1631537493753,"mc":[{"id":"1.187594319","rc":[{"batb":[[0,1.06,499.99],[1,1.01,7]],"ltp":1.11,"tv":5.2,"id":13310360},{"batb":[[0,7,10],[1,1.01,7]],"ltp":0.0,"tv":0.0,"id":9628382}]}]}
{"op":"mcm","clk":"4230878448","pt":1631537496315,"mc":[{"id":"1.187594319","rc":[{"batb":[[0,1.06,1507.6]],"ltp":1.11,"tv":5.2,"id":13310360}]}]}
{"op":"mcm","clk":"4230880711","pt":1631537521254,"mc":[{"id":"1.187594319","rc":[{"batb":[[0,1.06,1007.61]],"ltp":1.11,"tv":5.2,"id":13310360},{"batb":[[0,1.01,7],[1,1.01,0]],"ltp":0.0,"tv":0.0,"id":9628382}]}]}
{"op":"mcm","clk":"4230880867","pt":1631537522451,"mc":[{"id":"1.187594319","rc":[{"batb":[[0,1.01,7],[1,1.01,0]],"batl":[[1,1.46,0]],"ltp":1.11,"tv":5.2,"id":13310360}]}]}
{"op":"mcm","clk":"4230881248","pt":1631537526157,"mc":[{"id":"1.187594319","rc":[{"batb":[[0,1.05,599.99],[1,1.01,7]],"ltp":1.11,"tv":5.2,"id":13310360},{"batb":[[0,7.6,10],[1,1.01,7]],"ltp":0.0,"tv":0.0,"id":9628382}]}]}
{"op":"mcm","clk":"4230881503","pt":1631537528652,"mc":[{"id":"1.187594319","rc":[{"batb":[[0,1.05,1684.33]],"batl":[[1,1.38,986.38]],"ltp":1.11,"tv":5.2,"id":13310360}]}]}
{"op":"mcm","clk":"4230885544","pt":1631537572830,"mc":[{"id":"1.187594319","rc":[{"batb":[[0,1.05,1084.34]],"ltp":1.11,"tv":5.2,"id":13310360},{"batb":[[0,1.01,7],[1,1.01,0]],"ltp":0.0,"tv":0.0,"id":9628382}]}]}
{"op":"mcm","clk":"4230885651","pt":1631537574177,"mc":[{"id":"1.187594319","rc":[{"batb":[[0,1.01,7],[1,1.01,0]],"ltp":1.11,"tv":5.2,"id":13310360}]}]}
{"op":"mcm","clk":"4230885925","pt":1631537577858,"mc":[{"id":"1.187594319","rc":[{"batb":[[0,1.06,499.99],[1,1.01,7]],"ltp":1.11,"tv":5.2,"id":13310360},{"batb":[[0,7,10],[1,1.01,7]],"ltp":0.0,"tv":0.0,"id":9628382}]}]}
{"op":"mcm","clk":"4230886074","pt":1631537579774,"mc":[{"id":"1.187594319","rc":[{"batb":[[0,1.06,1449.72]],"ltp":1.11,"tv":5.2,"id":13310360}]}]}
{"op":"mcm","clk":"4230886765","pt":1631537588407,"mc":[{"id":"1.187594319","rc":[{"batl":[[0,1.09,200],[1,1.21,100],[2,1.38,986.38]],"ltp":1.11,"tv":5.2,"id":13310360}]}]}
{"op":"mcm","clk":"4230888301","pt":1631537607639,"mc":[{"id":"1.187594319","rc":[{"batb":[[0,1.06,499.99]],"ltp":1.11,"tv":5.2,"id":13310360}]}]}
{"op":"mcm","clk":"4230888326","pt":1631537607947,"mc":[{"id":"1.187594319","rc":[{"batb":[[0,1.01,7],[1,1.01,0]],"ltp":1.11,"tv":5.2,"id":13310360},{"batb":[[0,1.01,7],[1,1.01,0]],"ltp":0.0,"tv":0.0,"id":9628382}]}]}
{"op":"mcm","clk":"4230888787","pt":1631537613353,"mc":[{"id":"1.187594319","rc":[{"batb":[[0,1.05,1684.33],[1,1.01,7]],"ltp":1.11,"tv":5.2,"id":13310360},{"batb":[[0,7.6,10],[1,1.01,7]],"ltp":0.0,"tv":0.0,"id":9628382}]}]}
{"op":"mcm","clk":"4230890338","pt":1631537631391,"mc":[{"id":"1.187594319","rc":[{"batb":[[0,1.01,7],[1,1.01,0]],"ltp":1.11,"tv":5.2,"id":13310360},{"batb":[[0,1.01,7],[1,1.01,0]],"ltp":0.0,"tv":0.0,"id":9628382}]}]}
{"op":"mcm","clk":"4230890799","pt":1631537636588,"mc":[{"id":"1.187594319","rc":[{"batb":[[0,1.04,2001.57],[1,1.01,7]],"ltp":1.11,"tv":5.2,"id":13310360},{"batb":[[0,8,10],[1,1.01,7]],"ltp":0.0,"tv":0.0,"id":9628382}]}]}
{"op":"mcm","clk":"4230901321","pt":1631537747405,"mc":[{"id":"1.187594319","rc":[{"batb":[[0,1.04,1251.58]],"ltp":1.11,"tv":5.2,"id":13310360},{"batb":[[0,1.01,7],[1,1.01,0]],"ltp":0.0,"tv":0.0,"id":9628382}]}]}
{"op":"mcm","clk":"4230901430","pt":1631537748510,"mc":[{"id":"1.187594319","rc":[{"batb":[[0,1.01,7],[1,1.01,0]],"ltp":1.11,"tv":5.2,"id":13310360}]}]}
{"op":"mcm","clk":"4230901764","pt":1631537752326,"mc":[{"id":"1.187594319","rc":[{"batb":[[0,1.05,599.99],[1,1.01,7]],"ltp":1.11,"tv":5.2,"id":13310360},{"batb":[[0,7.6,10],[1,1.01,7]],"ltp":0.0,"tv":0.0,"id":9628382}]}]}
{"op":"mcm","clk":"4230901995","pt":1631537754614,"mc":[{"id":"1.187594319","rc":[{"batb":[[0,1.05,1684.33]],"ltp":1.11,"tv":5.2,"id":13310360}]}]}
{"op":"mcm","clk":"4230904244","pt":1631537779263,"mc":[{"id":"1.187594319","rc":[{"batb":[[0,1.05,1084.34]],"ltp":1.11,"tv":5.2,"id":13310360},{"batb":[[0,1.01,7],[1,1.01,0]],"ltp":0.0,"tv":0.0,"id":9628382}]}]}
{"op":"mcm","clk":"4230904323","pt":1631537780042,"mc":[{"id":"1.187594319","rc":[{"batb":[[0,1.01,7],[1,1.01,0]],"ltp":1.11,"tv":5.2,"id":13310360}]}]}
{"op":"mcm","clk":"4230904750","pt":1631537784274,"mc":[{"id":"1.187594319","rc":[{"batb":[[0,1.08,374.99],[1,1.01,7]],"ltp":1.11,"tv":5.2,"id":13310360},{"batb":[[0,6,10],[1,1.01,7]],"ltp":0.0,"tv":0.0,"id":9628382}]}]}
{"op":"mcm","clk":"4230904930","pt":1631537786162,"mc":[{"id":"1.187594319","rc":[{"batb":[[1,1.06,949.73],[2,1.01,7]],"ltp":1.11,"tv":5.2,"id":13310360}]}]}
{"op":"mcm","clk":"4230905383","pt":1631537790867,"mc":[{"id":"1.187594319","rc":[{"trd":[[1.08,4.08]],"batb":[[0,1.06,949.73],[1,1.01,7],[2,1.01,0]],"ltp":1.08,"tv":9.2,"id":13310360}],"tv":9.2}]}
{"op":"mcm","clk":"4230905788","pt":1631537795806,"mc":[{"id":"1.187594319","rc":[{"batb":[[0,1.08,374.99],[1,1.06,949.73],[2,1.01,7]],"ltp":1.08,"tv":9.2,"id":13310360}]}]}
{"op":"mcm","clk":"4230906864","pt":1631537808390,"mc":[{"id":"1.187594319","rc":[{"batb":[[1,1.01,7],[2,1.01,0]],"ltp":1.08,"tv":9.2,"id":13310360}]}]}
{"op":"mcm","clk":"4230907386","pt":1631537814608,"mc":[{"id":"1.187594319","rc":[{"batb":[[1,1.06,1007.61],[2,1.01,7]],"ltp":1.08,"tv":9.2,"id":13310360}]}]}
{"op":"mcm","clk":"4230909919","pt":1631537841458,"mc":[{"id":"1.187594319","rc":[{"batb":[[0,1.01,7],[1,1.06,0],[2,1.01,0]],"ltp":1.08,"tv":9.2,"id":13310360},{"batb":[[0,1.01,7],[1,1.01,0]],"ltp":0.0,"tv":0.0,"id":9628382}]}]}
{"op":"mcm","clk":"4230910349","pt":1631537846477,"mc":[{"id":"1.187594319","rc":[{"batb":[[0,5.8,10],[1,1.01,7]],"ltp":0.0,"tv":0.0,"id":9628382}]}]}
{"op":"mcm","clk":"4230910394","pt":1631537846955,"mc":[{"id":"1.187594319","rc":[{"batb":[[0,1.08,812.01],[1,1.01,7]],"ltp":1.08,"tv":9.2,"id":13310360}]}]}
{"op":"mcm","clk":"4230912361","pt":1631537870400,"mc":[{"id":"1.187594319","rc":[{"trd":[[1.09,78.1]],"batl":[[0,1.09,121.9]],"ltp":1.09,"tv":87.3,"id":13310360},{"trd":[[12,7.1]],"ltp":12.0,"tv":7.09,"id":9628382}],"tv":94.4}]}
{"op":"mcm","clk":"4230912554","pt":1631537872910,"mc":[{"id":"1.187594319","rc":[{"batb":[[0,1.01,7],[1,1.01,0]],"ltp":12.0,"tv":7.09,"id":9628382}]}]}
{"op":"mcm","clk":"4230912688","pt":1631537874430,"mc":[{"id":"1.187594319","rc":[{"batb":[[0,1.01,7],[1,1.01,0]],"ltp":1.09,"tv":87.3,"id":13310360}]}]}
{"op":"mcm","clk":"4230912975","pt":1631537877833,"mc":[{"id":"1.187594319","rc":[{"batb":[[0,4.8,10],[1,1.01,7]],"ltp":12.0,"tv":7.09,"id":9628382}]}]}
{"op":"mcm","clk":"4230913170","pt":1631537880516,"mc":[{"id":"1.187594319","rc":[{"trd":[[1.09,321.92]],"batb":[[0,1.09,26.5],[1,1.01,7]],"batl":[[0,1.21,100],[1,1.38,986.38],[2,1.38,0]],"ltp":1.09,"tv":331.12,"id":13310360}],"tv":338.21}]}
{"op":"mcm","clk":"4230913280","pt":1631537881618,"mc":[{"id":"1.187594319","rc":[{"batb":[[0,1.09,267.83]],"ltp":1.09,"tv":331.12,"id":13310360}]}]}
{"op":"mcm","clk":"4230913376","pt":1631537882618,"mc":[{"id":"1.187594319","rc":[{"batb":[[0,1.09,274.46]],"ltp":1.09,"tv":331.12,"id":13310360}]}]}
{"op":"mcm","clk":"4230913466","pt":1631537883621,"mc":[{"id":"1.187594319","rc":[{"batb":[[0,1.09,147.65]],"ltp":1.09,"tv":331.12,"id":13310360}]}]}
{"op":"mcm","clk":"4230913564","pt":1631537884630,"mc":[{"id":"1.187594319","rc":[{"batb":[[0,1.09,186.66]],"ltp":1.09,"tv":331.12,"id":13310360}]}]}
{"op":"mcm","clk":"4230913663","pt":1631537885633,"mc":[{"id":"1.187594319","rc":[{"batb":[[0,1.15,200],[1,1.09,404.43],[2,1.01,7]],"ltp":1.09,"tv":331.12,"id":13310360}]}]}
{"op":"mcm","clk":"4230913739","pt":1631537886530,"mc":[{"id":"1.187594319","rc":[{"batb":[[1,1.09,93.33]],"ltp":1.09,"tv":331.12,"id":13310360}]}]}
{"op":"mcm","clk":"4230913764","pt":1631537886849,"mc":[{"id":"1.187594319","rc":[{"batb":[[1,1.01,7],[2,1.01,0]],"ltp":1.09,"tv":331.12,"id":13310360}]}]}
{"op":"mcm","clk":"4230915111","pt":1631537901554,"mc":[{"id":"1.187594319","rc":[{"batb":[[1,1.12,539.63],[2,1.01,7]],"ltp":1.09,"tv":331.12,"id":13310360}]}]}
{"op":"mcm","clk":"4230916021","pt":1631537911631,"mc":[{"id":"1.187594319","rc":[{"batb":[[0,1.12,539.63],[1,1.01,7],[2,1.01,0]],"ltp":1.09,"tv":331.12,"id":13310360},{"batb":[[0,1.01,7],[1,1.01,0]],"ltp":12.0,"tv":7.09,"id":9628382}]}]}
{"op":"mcm","clk":"4230916051","pt":1631537911896,"mc":[{"id":"1.187594319","rc":[{"batb":[[0,1.01,7],[1,1.01,0]],"batl":[[1,1.38,0]],"ltp":1.09,"tv":331.12,"id":13310360}]}]}
{"op":"mcm","clk":"4230916432","pt":1631537916584,"mc":[{"id":"1.187594319","rc":[{"batb":[[0,1.18,166.66],[1,1.01,7]],"ltp":1.09,"tv":331.12,"id":13310360},{"batb":[[0,4.3,10],[1,1.01,7]],"ltp":12.0,"tv":7.09,"id":9628382}]}]}
{"op":"mcm","clk":"4230916536","pt":1631537917750,"mc":[{"id":"1.187594319","rc":[{"batb":[[1,1.14,501.06],[2,1.01,7]],"batl":[[1,1.55,785.49]],"ltp":1.09,"tv":331.12,"id":13310360}]}]}
{"op":"mcm","clk":"4230919083","pt":1631537947450,"mc":[{"id":"1.187594319","rc":[{"batb":[[0,1.01,7],[1,1.14,0],[2,1.01,0]],"ltp":1.09,"tv":331.12,"id":13310360}]}]}
{"op":"mcm","clk":"4230919243","pt":1631537949386,"mc":[{"id":"1.187594319","rc":[{"trd":[[1.21,6.47]],"batl":[[0,1.21,93.53]],"ltp":1.21,"tv":337.59,"id":13310360},{"trd":[[5.7,1.38]],"ltp":5.7,"tv":8.47,"id":9628382}],"tv":346.06}]}
{"op":"mcm","clk":"4230919515","pt":1631537952079,"mc":[{"id":"1.187594319","rc":[{"batb":[[0,1.15,200],[1,1.01,7]],"ltp":1.21,"tv":337.59,"id":13310360}]}]}
{"op":"mcm","clk":"4230919597","pt":1631537952964,"mc":[{"id":"1.187594319","rc":[{"batb":[[1,1.12,539.63],[2,1.01,7]],"ltp":1.21,"tv":337.59,"id":13310360}]}]}
{"op":"mcm","clk":"4230923447","pt":1631538000250,"mc":[{"id":"1.187594319","rc":[{"batb":[[0,1.01,7],[1,1.12,0],[2,1.01,0]],"batl":[[1,1.55,0]],"ltp":1.21,"tv":337.59,"id":13310360},{"batb":[[0,1.01,7],[1,1.01,0]],"ltp":5.7,"tv":8.47,"id":9628382}]}]}
{"op":"mcm","clk":"4230923945","pt":1631538004744,"mc":[{"id":"1.187594319","rc":[{"trd":[[1.09,321.9]],"batb":[[0,1.12,249.99],[1,1.01,7]],"ltp":1.21,"tv":337.57,"id":13310360},{"trd":[[5.7,1.38],[12,7.09]],"batb":[[0,5.3,10],[1,1.01,7]],"ltp":5.7,"tv":8.47,"id":9628382}],"tv":346.04}]}
{"op":"mcm","clk":"4230924110","pt":1631538006281,"mc":[{"id":"1.187594319","rc":[{"batb":[[1,1.1,606.51],[2,1.01,7]],"batl":[[1,1.48,884.7]],"ltp":1.21,"tv":337.57,"id":13310360}]}]}
{"op":"mcm","clk":"4230926960","pt":1631538041409,"mc":[{"id":"1.187594319","rc":[{"batb":[[0,1.1,606.51],[1,1.01,7],[2,1.01,0]],"ltp":1.21,"tv":337.57,"id":13310360},{"batb":[[0,1.01,7],[1,1.01,0]],"ltp":5.7,"tv":8.47,"id":9628382}]}]}
{"op":"mcm","clk":"4230927102","pt":1631538042824,"mc":[{"id":"1.187594319","rc":[{"batb":[[0,1.01,7],[1,1.01,0]],"ltp":1.21,"tv":337.57,"id":13310360}]}]}
{"op":"mcm","clk":"4230927402","pt":1631538046307,"mc":[{"id":"1.187594319","rc":[{"batb":[[0,1.11,272.72],[1,1.01,7]],"ltp":1.21,"tv":337.57,"id":13310360},{"batb":[[0,5.8,10],[1,1.01,7]],"ltp":5.7,"tv":8.47,"id":9628382}]}]}
{"op":"mcm","clk":"4230927619","pt":1631538049021,"mc":[{"id":"1.187594319","rc":[{"batb":[[1,1.08,685.55],[2,1.01,7]],"ltp":1.21,"tv":337.57,"id":13310360}]}]}
{"op":"mcm","clk":"4230929622","pt":1631538072005,"mc":[{"id":"1.187594319","rc":[{"batb":[[0,1.08,685.55],[1,1.01,7],[2,1.01,0]],"ltp":1.21,"tv":337.57,"id":13310360},{"batb":[[0,1.01,7],[1,1.01,0]],"ltp":5.7,"tv":8.47,"id":9628382}]}]}
{"op":"mcm","clk":"4230929738","pt":1631538073262,"mc":[{"id":"1.187594319","rc":[{"batb":[[0,1.01,7],[1,1.01,0]],"ltp":1.21,"tv":337.57,"id":13310360}]}]}
{"op":"mcm","clk":"4230930034","pt":1631538077009,"mc":[{"id":"1.187594319","rc":[{"batb":[[0,1.12,249.99],[1,1.01,7]],"ltp":1.21,"tv":337.57,"id":13310360},{"batb":[[0,5.3,10],[1,1.01,7]],"ltp":5.7,"tv":8.47,"id":9628382}]}]}
{"op":"mcm","clk":"4230930216","pt":1631538079197,"mc":[{"id":"1.187594319","rc":[{"batb":[[1,1.1,606.51],[2,1.01,7]],"ltp":1.21,"tv":337.57,"id":13310360}]}]}
{"op":"mcm","clk":"4230931857","pt":1631538098943,"mc":[{"id":"1.187594319","rc":[{"batb":[[0,1.1,606.51],[1,1.01,7],[2,1.01,0]],"ltp":1.21,"tv":337.57,"id":13310360},{"batb":[[0,1.01,7],[1,1.01,0]],"ltp":5.7,"tv":8.47,"id":9628382}]}]}
{"op":"mcm","clk":"4230931909","pt":1631538099737,"mc":[{"id":"1.187594319","rc":[{"batb":[[0,1.01,7],[1,1.01,0]],"ltp":1.21,"tv":337.57,"id":13310360}]}]}
{"op":"mcm","clk":"4230932300","pt":1631538103832,"mc":[{"id":"1.187594319","rc":[{"batb":[[0,1.18,166.66],[1,1.01,7]],"ltp":1.21,"tv":337.57,"id":13310360},{"batb":[[0,4.3,10],[1,1.01,7]],"ltp":5.7,"tv":8.47,"id":9628382}]}]}
{"op":"mcm","clk":"4230932458","pt":1631538105542,"mc":[{"id":"1.187594319","rc":[{"batb":[[1,1.14,500.97],[2,1.01,7]],"ltp":1.21,"tv":337.57,"id":13310360}]}]}
{"op":"mcm","clk":"4230934096","pt":1631538123262,"mc":[{"id":"1.187594319","rc":[{"batb":[[0,1.14,500.97],[1,1.01,7],[2,1.01,0]],"ltp":1.21,"tv":337.57,"id":13310360},{"batb":[[0,1.01,7],[1,1.01,0]],"ltp":5.7,"tv":8.47,"id":9628382}]}]}
{"op":"mcm","clk":"4230934581","pt":1631538128297,"mc":[{"id":"1.187594319","rc":[{"batb":[[0,1.15,200],[1,1.14,500.97],[2,1.01,7]],"ltp":1.21,"tv":337.57,"id":13310360},{"batb":[[0,4.8,10],[1,1.01,7]],"ltp":5.7,"tv":8.47,"id":9628382}]}]}
{"op":"mcm","clk":"4230941614","pt":1631538206435,"mc":[{"id":"1.187594319","rc":[{"batb":[[0,1.14,500.97],[1,1.01,7],[2,1.01,0]],"ltp":1.21,"tv":337.57,"id":13310360},{"batb":[[0,1.01,7],[1,1.01,0]],"ltp":5.7,"tv":8.47,"id":9628382}]}]}
{"op":"mcm","clk":"4230941681","pt":1631538207114,"mc":[{"id":"1.187594319","rc":[{"batb":[[0,1.01,7],[1,1.01,0]],"ltp":1.21,"tv":337.57,"id":13310360}]}]}
{"op":"mcm","clk":"4230942075","pt":1631538211342,"mc":[{"id":"1.187594319","rc":[{"batb":[[0,1.12,249.99],[1,1.01,7]],"ltp":1.21,"tv":337.57,"id":13310360},{"batb":[[0,5.3,10],[1,1.01,7]],"ltp":5.7,"tv":8.47,"id":9628382}]}]}
{"op":"mcm","clk":"4230942215","pt":1631538212649,"mc":[{"id":"1.187594319","rc":[{"batb":[[0,1.12,789.53]],"ltp":1.21,"tv":337.57,"id":13310360}]}]}
{"op":"mcm","clk":"4230943734","pt":1631538228943,"mc":[{"id":"1.187594319","rc":[{"batb":[[0,1.12,539.54]],"ltp":1.21,"tv":337.57,"id":13310360},{"batb":[[0,1.01,7],[1,1.01,0]],"ltp":5.7,"tv":8.47,"id":9628382}]}]}
{"op":"mcm","clk":"4230943886","pt":1631538230553,"mc":[{"id":"1.187594319","rc":[{"batb":[[0,1.01,7],[1,1.01,0]],"ltp":1.21,"tv":337.57,"id":13310360}]}]}
{"op":"mcm","clk":"4230944207","pt":1631538233852,"mc":[{"id":"1.187594319","rc":[{"batb":[[0,1.08,374.99],[1,1.01,7]],"ltp":1.21,"tv":337.57,"id":13310360},{"batb":[[0,6,10],[1,1.01,7]],"ltp":5.7,"tv":8.47,"id":9628382}]}]}
{"op":"mcm","clk":"4230944456","pt":1631538236769,"mc":[{"id":"1.187594319","rc":[{"batb":[[0,1.09,638.16],[1,1.08,374.99],[2,1.01,7]],"ltp":1.21,"tv":337.57,"id":13310360}]}]}
{"op":"mcm","clk":"4230959717","pt":1631538413788,"mc":[{"id":"1.187594319","rc":[{"batb":[[1,1.01,7],[2,1.01,0]],"ltp":1.21,"tv":337.57,"id":13310360},{"batb":[[0,1.01,7],[1,1.01,0]],"ltp":5.7,"tv":8.47,"id":9628382}]}]}
{"op":"mcm","clk":"4230959859","pt":1631538415410,"mc":[{"id":"1.187594319","rc":[{"batb":[[0,1.01,7],[1,1.01,0]],"ltp":1.21,"tv":337.57,"id":13310360}]}]}
{"op":"mcm","clk":"4230960175","pt":1631538418825,"mc":[{"id":"1.187594319","rc":[{"batb":[[0,1.11,272.72],[1,1.01,7]],"ltp":1.21,"tv":337.57,"id":13310360},{"batb":[[0,5.8,10],[1,1.01,7]],"ltp":5.7,"tv":8.47,"id":9628382}]}]}
{"op":"mcm","clk":"4230960392","pt":1631538421003,"mc":[{"id":"1.187594319","rc":[{"batb":[[1,1.1,606.51],[2,1.01,7]],"ltp":1.21,"tv":337.57,"id":13310360}]}]}
{"op":"mcm","clk":"4230961552","pt":1631538432919,"mc":[{"id":"1.187594319","rc":[{"batb":[[0,1.1,606.51],[1,1.01,7],[2,1.01,0]],"ltp":1.21,"tv":337.57,"id":13310360},{"batb":[[0,1.01,7],[1,1.01,0]],"ltp":5.7,"tv":8.47,"id":9628382}]}]}
{"op":"mcm","clk":"4230961611","pt":1631538433654,"mc":[{"id":"1.187594319","rc":[{"batb":[[0,1.01,7],[1,1.01,0]],"ltp":1.21,"tv":337.57,"id":13310360}]}]}
{"op":"mcm","clk":"4230962023","pt":1631538437850,"mc":[{"id":"1.187594319","rc":[{"batb":[[0,1.12,249.99],[1,1.01,7]],"ltp":1.21,"tv":337.57,"id":13310360},{"batb":[[0,5.3,10],[1,1.01,7]],"ltp":5.7,"tv":8.47,"id":9628382}]}]}
{"op":"mcm","clk":"4230962191","pt":1631538439329,"mc":[{"id":"1.187594319","rc":[{"batb":[[0,1.12,789.53]],"ltp":1.21,"tv":337.57,"id":13310360}]}]}
{"op":"mcm","clk":"4230964310","pt":1631538463203,"mc":[{"id":"1.187594319","rc":[{"batb":[[0,1.12,539.54]],"ltp":1.21,"tv":337.57,"id":13310360},{"batb":[[0,1.01,7],[1,1.01,0]],"ltp":5.7,"tv":8.47,"id":9628382}]}]}
{"op":"mcm","clk":"4230964384","pt":1631538464090,"mc":[{"id":"1.187594319","rc":[{"batb":[[0,1.01,7],[1,1.01,0]],"ltp":1.21,"tv":337.57,"id":13310360}]}]}
{"op":"mcm","clk":"4230964690","pt":1631538468259,"mc":[{"id":"1.187594319","rc":[{"batb":[[0,1.11,272.72],[1,1.01,7]],"ltp":1.21,"tv":337.57,"id":13310360},{"batb":[[0,5.8,10],[1,1.01,7]],"ltp":5.7,"tv":8.47,"id":9628382}]}]}
{"op":"mcm","clk":"4230964789","pt":1631538469615,"mc":[{"id":"1.187594319","rc":[{"batb":[[1,1.1,606.51],[2,1.01,7]],"ltp":1.21,"tv":337.57,"id":13310360}]}]}
{"op":"mcm","clk":"4230965926","pt":1631538483640,"mc":[{"id":"1.187594319","rc":[{"batb":[[0,1.1,606.51],[1,1.01,7],[2,1.01,0]],"ltp":1.21,"tv":337.57,"id":13310360},{"batb":[[0,1.01,7],[1,1.01,0]],"ltp":5.7,"tv":8.47,"id":9628382}]}]}
{"op":"mcm","clk":"4230966005","pt":1631538484437,"mc":[{"id":"1.187594319","rc":[{"batb":[[0,1.01,7],[1,1.01,0]],"ltp":1.21,"tv":337.57,"id":13310360}]}]}
{"op":"mcm","clk":"4230966373","pt":1631538488555,"mc":[{"id":"1.187594319","rc":[{"batb":[[0,1.15,200],[1,1.01,7]],"ltp":1.21,"tv":337.57,"id":13310360},{"batb":[[0,4.8,10],[1,1.01,7]],"ltp":5.7,"tv":8.47,"id":9628382}]}]}
{"op":"mcm","clk":"4230966466","pt":1631538489654,"mc":[{"id":"1.187594319","rc":[{"batb":[[1,1.14,500.97],[2,1.01,7]],"ltp":1.21,"tv":337.57,"id":13310360}]}]}
{"op":"mcm","clk":"4230967354","pt":1631538499637,"mc":[{"id":"1.187594319","rc":[{"batb":[[1,1.01,7],[2,1.01,0]],"ltp":1.21,"tv":337.57,"id":13310360}]}]}
{"op":"mcm","clk":"4230967905","pt":1631538505762,"mc":[{"id":"1.187594319","rc":[{"batb":[[1,1.12,539.54],[2,1.01,7]],"ltp":1.21,"tv":337.57,"id":13310360}]}]}
{"op":"mcm","clk":"4230968748","pt":1631538515374,"mc":[{"id":"1.187594319","rc":[{"batb":[[0,1.12,539.54],[1,1.01,7],[2,1.01,0]],"ltp":1.21,"tv":337.57,"id":13310360},{"batb":[[0,1.01,7],[1,1.01,0]],"ltp":5.7,"tv":8.47,"id":9628382}]}]}
{"op":"mcm","clk":"4230968809","pt":1631538516003,"mc":[{"id":"1.187594319","rc":[{"batb":[[0,1.01,7],[1,1.01,0]],"ltp":1.21,"tv":337.57,"id":13310360}]}]}
{"op":"mcm","clk":"4230969207","pt":1631538520287,"mc":[{"id":"1.187594319","rc":[{"batb":[[0,1.18,166.66],[1,1.01,7]],"ltp":1.21,"tv":337.57,"id":13310360},{"batb":[[0,4.3,10],[1,1.01,7]],"ltp":5.7,"tv":8.47,"id":9628382}]}]}
{"op":"mcm","clk":"4230969367","pt":1631538522005,"mc":[{"id":"1.187594319","rc":[{"batb":[[1,1.14,500.97],[2,1.01,7]],"ltp":1.21,"tv":337.57,"id":13310360}]}]}
{"op":"mcm","clk":"4230979259","pt":1631538625700,"mc":[{"id":"1.187594319","rc":[{"batb":[[1,1.01,7],[2,1.01,0]],"ltp":1.21,"tv":337.57,"id":13310360}]}]}
{"op":"mcm","clk":"4230979792","pt":1631538631646,"mc":[{"id":"1.187594319","rc":[{"batb":[[1,1.16,469.27],[2,1.01,7]],"ltp":1.21,"tv":337.57,"id":13310360}]}]}
{"op":"mcm","clk":"4230980480","pt":1631538639207,"mc":[{"id":"1.187594319","rc":[{"batb":[[0,1.16,469.27],[1,1.01,7],[2,1.01,0]],"ltp":1.21,"tv":337.57,"id":13310360},{"batb":[[0,1.01,7],[1,1.01,0]],"ltp":5.7,"tv":8.47,"id":9628382}]}]}
{"op":"mcm","clk":"4230980643","pt":1631538640075,"mc":[{"id":"1.187594319","rc":[{"batb":[[0,1.01,7],[1,1.01,0]],"ltp":1.21,"tv":337.57,"id":13310360}]}]}
{"op":"mcm","clk":"4230981409","pt":1631538644260,"mc":[{"id":"1.187594319","rc":[{"batb":[[0,1.15,200],[1,1.01,7]],"ltp":1.21,"tv":337.57,"id":13310360},{"batb":[[0,4.8,10],[1,1.01,7]],"ltp":5.7,"tv":8.47,"id":9628382}]}]}
{"op":"mcm","clk":"4230981544","pt":1631538645831,"mc":[{"id":"1.187594319","rc":[{"batb":[[1,1.12,539.54],[2,1.01,7]],"ltp":1.21,"tv":337.57,"id":13310360}]}]}
{"op":"mcm","clk":"4230983237","pt":1631538664162,"mc":[{"id":"1.187594319","rc":[{"batb":[[0,1.12,539.54],[1,1.01,7],[2,1.01,0]],"ltp":1.21,"tv":337.57,"id":13310360},{"batb":[[0,1.01,7],[1,1.01,0]],"ltp":5.7,"tv":8.47,"id":9628382}]}]}
{"op":"mcm","clk":"4230983350","pt":1631538665373,"mc":[{"id":"1.187594319","rc":[{"batb":[[0,1.01,7],[1,1.01,0]],"ltp":1.21,"tv":337.57,"id":13310360}]}]}
{"op":"mcm","clk":"4230983677","pt":1631538669159,"mc":[{"id":"1.187594319","rc":[{"batb":[[0,1.11,272.72],[1,1.01,7]],"ltp":1.21,"tv":337.57,"id":13310360},{"batb":[[0,5.8,10],[1,1.01,7]],"ltp":5.7,"tv":8.47,"id":9628382}]}]}
{"op":"mcm","clk":"4230983859","pt":1631538671009,"mc":[{"id":"1.187594319","rc":[{"batb":[[1,1.1,606.51],[2,1.01,7]],"ltp":1.21,"tv":337.57,"id":13310360}]}]}
{"op":"mcm","clk":"4230986690","pt":1631538703172,"mc":[{"id":"1.187594319","rc":[{"batb":[[1,1.01,7],[2,1.01,0]],"ltp":1.21,"tv":337.57,"id":13310360}]}]}
{"op":"mcm","clk":"4230987314","pt":1631538709386,"mc":[{"id":"1.187594319","rc":[{"batb":[[1,1.09,638.16],[2,1.01,7]],"ltp":1.21,"tv":337.57,"id":13310360}]}]}
{"op":"mcm","clk":"4230994708","pt":1631538749157,"mc":[{"id":"1.187594319","rc":[{"batb":[[0,1.09,638.16],[1,1.01,7],[2,1.01,0]],"ltp":1.21,"tv":337.57,"id":13310360}]}]}
{"op":"mcm","clk":"4230995309","pt":1631538754126,"mc":[{"id":"1.187594319","rc":[{"batb":[[1,1.08,374.99],[2,1.01,7]],"ltp":1.21,"tv":337.57,"id":13310360}]}]}
{"op":"mcm","clk":"4230997728","pt":1631538779605,"mc":[{"id":"1.187594319","rc":[{"batb":[[0,1.08,374.99],[1,1.01,7],[2,1.01,0]],"batl":[[1,1.48,0]],"ltp":1.21,"tv":337.57,"id":13310360}]}]}
{"op":"mcm","clk":"4230999443","pt":1631538796527,"mc":[{"id":"1.187594319","rc":[{"batb":[[0,1.01,7],[1,1.01,0]],"ltp":1.21,"tv":337.57,"id":13310360},{"batb":[[0,1.01,7],[1,1.01,0]],"ltp":5.7,"tv":8.47,"id":9628382}]}]}
{"op":"mcm","clk":"4230999989","pt":1631538801526,"mc":[{"id":"1.187594319","rc":[{"batb":[[0,1.12,249.99],[1,1.01,7]],"ltp":1.21,"tv":337.57,"id":13310360},{"batb":[[0,5.3,10],[1,1.01,7]],"ltp":5.7,"tv":8.47,"id":9628382}]}]}
{"op":"mcm","clk":"4231001336","pt":1631538815679,"mc":[{"id":"1.187594319","rc":[{"batb":[[0,1.01,7],[1,1.01,0]],"ltp":1.21,"tv":337.57,"id":13310360},{"batb":[[0,1.01,7],[1,1.01,0]],"ltp":5.7,"tv":8.47,"id":9628382}]}]}
{"op":"mcm","clk":"4231001923","pt":1631538820569,"mc":[{"id":"1.187594319","rc":[{"batb":[[0,1.15,200],[1,1.01,7]],"ltp":1.21,"tv":337.57,"id":13310360},{"batb":[[0,4.8,10],[1,1.01,7]],"ltp":5.7,"tv":8.47,"id":9628382}]}]}
{"op":"mcm","clk":"4231003497","pt":1631538834107,"mc":[{"id":"1.187594319","rc":[{"batb":[[0,1.01,7],[1,1.01,0]],"ltp":1.21,"tv":337.57,"id":13310360},{"batb":[[0,1.01,7],[1,1.01,0]],"ltp":5.7,"tv":8.47,"id":9628382}]}]}
{"op":"mcm","clk":"4231003942","pt":1631538838913,"mc":[{"id":"1.187594319","rc":[{"batb":[[0,1.12,249.99],[1,1.01,7]],"ltp":1.21,"tv":337.57,"id":13310360},{"batb":[[0,5.3,10],[1,1.01,7]],"ltp":5.7,"tv":8.47,"id":9628382}]}]}
{"op":"mcm","clk":"4231005715","pt":1631538856719,"mc":[{"id":"1.187594319","rc":[{"batb":[[0,1.01,7],[1,1.01,0]],"ltp":1.21,"tv":337.57,"id":13310360},{"batb":[[0,1.01,7],[1,1.01,0]],"ltp":5.7,"tv":8.47,"id":9628382}]}]}
{"op":"mcm","clk":"4231006289","pt":1631538861646,"mc":[{"id":"1.187594319","rc":[{"batb":[[0,1.08,374.99],[1,1.01,7]],"ltp":1.21,"tv":337.57,"id":13310360},{"batb":[[0,6,10],[1,1.01,7]],"ltp":5.7,"tv":8.47,"id":9628382}]}]}
{"op":"mcm","clk":"4231009942","pt":1631538899034,"mc":[{"id":"1.187594319","rc":[{"batb":[[0,1.01,7],[1,1.01,0]],"ltp":1.21,"tv":337.57,"id":13310360},{"batb":[[0,1.01,7],[1,1.01,0]],"ltp":5.7,"tv":8.47,"id":9628382}]}]}
{"op":"mcm","clk":"4231010487","pt":1631538903950,"mc":[{"id":"1.187594319","rc":[{"batb":[[0,1.15,200],[1,1.01,7]],"ltp":1.21,"tv":337.57,"id":13310360},{"batb":[[0,4.8,10],[1,1.01,7]],"ltp":5.7,"tv":8.47,"id":9628382}]}]}
{"op":"mcm","clk":"4231012718","pt":1631538924886,"mc":[{"id":"1.187594319","rc":[{"batb":[[0,1.01,7],[1,1.01,0]],"ltp":1.21,"tv":337.57,"id":13310360},{"batb":[[0,1.01,7],[1,1.01,0]],"ltp":5.7,"tv":8.47,"id":9628382}]}]}
{"op":"mcm","clk":"4231013471","pt":1631538931794,"mc":[{"id":"1.187594319","rc":[{"batb":[[0,1.08,685.55],[1,1.01,7]],"batl":[[1,1.44,961.06]],"ltp":1.21,"tv":337.57,"id":13310360}]}]}
{"op":"mcm","clk":"4231013585","pt":1631538932692,"mc":[{"id":"1.187594319","rc":[{"batb":[[0,1.01,7],[1,1.01,0]],"ltp":1.21,"tv":337.57,"id":13310360}]}]}
{"op":"mcm","clk":"4231013868","pt":1631538934986,"mc":[{"id":"1.187594319","rc":[{"batb":[[0,1.15,200],[1,1.01,7]],"ltp":1.21,"tv":337.57,"id":13310360},{"batb":[[0,4.8,10],[1,1.01,7]],"ltp":5.7,"tv":8.47,"id":9628382}]}]}
{"op":"mcm","clk":"4231014238","pt":1631538938109,"mc":[{"id":"1.187594319","rc":[{"batb":[[0,1.01,7],[1,1.01,0]],"ltp":1.21,"tv":337.57,"id":13310360},{"batb":[[0,1.01,7],[1,1.01,0]],"ltp":5.7,"tv":8.47,"id":9628382}]}]}
{"op":"mcm","clk":"4231014861","pt":1631538943026,"mc":[{"id":"1.187594319","rc":[{"batb":[[0,1.08,374.99],[1,1.01,7]],"ltp":1.21,"tv":337.57,"id":13310360},{"batb":[[0,6,10],[1,1.01,7]],"ltp":5.7,"tv":8.47,"id":9628382}]}]}
{"op":"mcm","clk":"4231014942","pt":1631538943809,"mc":[{"id":"1.187594319","rc":[{"batb":[[0,1.08,1060.54]],"ltp":1.21,"tv":337.57,"id":13310360}]}]}
{"op":"mcm","clk":"4231019198","pt":1631538978871,"mc":[{"id":"1.187594319","rc":[{"batb":[[0,1.08,685.55]],"ltp":1.21,"tv":337.57,"id":13310360},{"batb":[[0,1.01,7],[1,1.01,0]],"ltp":5.7,"tv":8.47,"id":9628382}]}]}
{"op":"mcm","clk":"4231019297","pt":1631538979657,"mc":[{"id":"1.187594319","rc":[{"batb":[[0,1.01,7],[1,1.01,0]],"ltp":1.21,"tv":337.57,"id":13310360}]}]}
{"op":"mcm","clk":"4231019809","pt":1631538983773,"mc":[{"id":"1.187594319","rc":[{"batb":[[0,1.05,599.99],[1,1.01,7]],"ltp":1.21,"tv":337.57,"id":13310360},{"batb":[[0,7.6,10],[1,1.01,7]],"ltp":5.7,"tv":8.47,"id":9628382}]}]}
{"op":"mcm","clk":"4231020119","pt":1631538985888,"mc":[{"id":"1.187594319","rc":[{"batb":[[0,1.05,1551.1]],"ltp":1.21,"tv":337.57,"id":13310360}]}]}
{"op":"mcm","clk":"4231023643","pt":1631539015462,"mc":[{"id":"1.187594319","rc":[{"batb":[[0,1.05,951.11]],"ltp":1.21,"tv":337.57,"id":13310360},{"batb":[[0,1.01,7],[1,1.01,0]],"ltp":5.7,"tv":8.47,"id":9628382}]}]}
{"op":"mcm","clk":"4231024311","pt":1631539020480,"mc":[{"id":"1.187594319","rc":[{"batb":[[1,1.04,749.99],[2,1.01,7]],"ltp":1.21,"tv":337.57,"id":13310360},{"batb":[[0,8,10],[1,1.01,7]],"ltp":5.7,"tv":8.47,"id":9628382}]}]}
{"op":"mcm","clk":"4231024883","pt":1631539024482,"mc":[{"id":"1.187594319","rc":[{"batb":[[0,1.01,7],[1,1.04,0],[2,1.01,0]],"batl":[[1,1.44,0]],"ltp":1.21,"tv":337.57,"id":13310360},{"batb":[[0,1.01,7],[1,1.01,0]],"ltp":5.7,"tv":8.47,"id":9628382}]}]}
{"op":"mcm","clk":"4231025445","pt":1631539029202,"mc":[{"id":"1.187594319","rc":[{"batb":[[0,1.02,1499.99],[1,1.01,7]],"ltp":1.21,"tv":337.57,"id":13310360},{"batb":[[0,10,10],[1,1.01,7]],"ltp":5.7,"tv":8.47,"id":9628382}]}]}
{"op":"mcm","clk":"4231025556","pt":1631539030401,"mc":[{"id":"1.187594319","rc":[{"batb":[[0,1.03,1419.65],[1,1.02,1499.99],[2,1.01,7]],"batl":[[1,1.35,1185.3]],"ltp":1.21,"tv":337.57,"id":13310360}]}]}
{"op":"mcm","clk":"4231039687","pt":1631539150308,"mc":[{"id":"1.187594319","rc":[{"batb":[[1,1.01,7],[2,1.01,0]],"ltp":1.21,"tv":337.57,"id":13310360},{"batb":[[0,1.01,7],[1,1.01,0]],"ltp":5.7,"tv":8.47,"id":9628382}]}]}
{"op":"mcm","clk":"4231039800","pt":1631539151376,"mc":[{"id":"1.187594319","rc":[{"batb":[[0,1.01,7],[1,1.01,0]],"ltp":1.21,"tv":337.57,"id":13310360}]}]}
{"op":"mcm","clk":"4231040219","pt":1631539155202,"mc":[{"id":"1.187594319","rc":[{"batb":[[0,1.04,749.99],[1,1.01,7]],"ltp":1.21,"tv":337.57,"id":13310360},{"batb":[[0,8,10],[1,1.01,7]],"ltp":5.7,"tv":8.47,"id":9628382}]}]}
{"op":"mcm","clk":"4231042747","pt":1631539177146,"mc":[{"id":"1.187594319","rc":[{"batb":[[0,1.01,7],[1,1.01,0]],"ltp":1.21,"tv":337.57,"id":13310360},{"batb":[[0,1.01,7],[1,1.01,0]],"ltp":5.7,"tv":8.47,"id":9628382}]}]}
{"op":"mcm","clk":"4231043310","pt":1631539182051,"mc":[{"id":"1.187594319","rc":[{"batb":[[0,1.03,999.99],[1,1.01,7]],"ltp":1.21,"tv":337.57,"id":13310360},{"batb":[[0,9.6,10],[1,1.01,7]],"ltp":5.7,"tv":8.47,"id":9628382}]}]}
{"op":"mcm","clk":"4231043423","pt":1631539183147,"mc":[{"id":"1.187594319","rc":[{"batb":[[0,1.03,2419.64]],"ltp":1.21,"tv":337.57,"id":13310360}]}]}
{"op":"mcm","clk":"4231047123","pt":1631539215991,"mc":[{"id":"1.187594319","rc":[{"batb":[[0,1.03,1419.65]],"ltp":1.21,"tv":337.57,"id":13310360},{"batb":[[0,1.01,7],[1,1.01,0]],"ltp":5.7,"tv":8.47,"id":9628382}]}]}
{"op":"mcm","clk":"4231047276","pt":1631539217294,"mc":[{"id":"1.187594319","rc":[{"batb":[[0,1.01,7],[1,1.01,0]],"ltp":1.21,"tv":337.57,"id":13310360}]}]}
{"op":"mcm","clk":"4231047677","pt":1631539221029,"mc":[{"id":"1.187594319","rc":[{"batb":[[0,12,10],[1,1.01,7]],"ltp":5.7,"tv":8.47,"id":9628382}]}]}
{"op":"mcm","clk":"4231047922","pt":1631539223334,"mc":[{"id":"1.187594319","rc":[{"batb":[[0,1.02,2026.61],[1,1.01,7]],"ltp":1.21,"tv":337.57,"id":13310360}]}]}
{"op":"mcm","clk":"4231049818","pt":1631539241462,"mc":[{"id":"1.187594319","rc":[{"batb":[[0,1.01,7],[1,1.01,0]],"ltp":5.7,"tv":8.47,"id":9628382}]}]}
{"op":"mcm","clk":"4231050320","pt":1631539246257,"mc":[{"id":"1.187594319","rc":[{"batb":[[0,11,10],[1,1.01,7]],"ltp":5.7,"tv":8.47,"id":9628382}]}]}
{"op":"mcm","clk":"4231052177","pt":1631539264494,"mc":[{"id":"1.187594319","rc":[{"batb":[[0,1.01,7],[1,1.01,0]],"ltp":5.7,"tv":8.47,"id":9628382}]}]}
{"op":"mcm","clk":"4231052228","pt":1631539265065,"mc":[{"id":"1.187594319","rc":[{"batb":[[0,1.01,7],[1,1.01,0]],"ltp":1.21,"tv":337.57,"id":13310360}]}]}
{"op":"mcm","clk":"4231052712","pt":1631539269404,"mc":[{"id":"1.187594319","rc":[{"batb":[[0,1.03,999.99],[1,1.01,7]],"ltp":1.21,"tv":337.57,"id":13310360},{"batb":[[0,9.6,10],[1,1.01,7]],"ltp":5.7,"tv":8.47,"id":9628382}]}]}
{"op":"mcm","clk":"4231052874","pt":1631539271072,"mc":[{"id":"1.187594319","rc":[{"batb":[[0,1.03,2419.64]],"ltp":1.21,"tv":337.57,"id":13310360}]}]}
{"op":"mcm","clk":"4231056262","pt":1631539305579,"mc":[{"id":"1.187594319","rc":[{"trd":[[9.6,5.32]],"batb":[[0,1.01,7],[1,1.01,0]],"ltp":9.6,"tv":13.79,"id":9628382}],"tv":351.37}]}
{"op":"mcm","clk":"4231056641","pt":1631539309477,"mc":[{"id":"1.187594319","rc":[{"batb":[[0,1.03,1419.65]],"ltp":1.21,"tv":337.57,"id":13310360}]}]}
{"op":"mcm","clk":"4231056746","pt":1631539310468,"mc":[{"id":"1.187594319","rc":[{"batb":[[0,1.01,7],[1,1.01,0]],"ltp":1.21,"tv":337.57,"id":13310360},{"batb":[[0,9.6,10],[1,1.01,7]],"ltp":9.6,"tv":13.79,"id":9628382}]}]}
{"op":"mcm","clk":"4231056777","pt":1631539310781,"mc":[{"id":"1.187594319","rc":[{"batb":[[0,1.01,7],[1,1.01,0]],"ltp":9.6,"tv":13.79,"id":9628382}]}]}
{"op":"mcm","clk":"4231057184","pt":1631539314405,"mc":[{"id":"1.187594319","rc":[{"batb":[[0,1.05,599.99],[1,1.01,7]],"ltp":1.21,"tv":337.57,"id":13310360}]}]}
{"op":"mcm","clk":"4231057310","pt":1631539315601,"mc":[{"id":"1.187594319","rc":[{"batb":[[0,1.06,823.54],[1,1.05,599.99],[2,1.01,7]],"ltp":1.21,"tv":337.57,"id":13310360}]}]}
{"op":"mcm","clk":"4231057325","pt":1631539315704,"mc":[{"id":"1.187594319","rc":[{"batb":[[0,7.6,10],[1,1.01,7]],"ltp":9.6,"tv":13.79,"id":9628382}]}]}
{"op":"mcm","clk":"4231059238","pt":1631539333212,"mc":[{"id":"1.187594319","rc":[{"batb":[[0,1.01,7],[1,1.05,0],[2,1.01,0]],"ltp":1.21,"tv":337.57,"id":13310360},{"batb":[[0,1.01,7],[1,1.01,0]],"ltp":9.6,"tv":13.79,"id":9628382}]}]}
{"op":"mcm","clk":"4231059636","pt":1631539337640,"mc":[{"id":"1.187594319","rc":[{"batb":[[0,1.12,249.99],[1,1.01,7]],"ltp":1.21,"tv":337.57,"id":13310360},{"batb":[[0,5.3,10],[1,1.01,7]],"ltp":9.6,"tv":13.79,"id":9628382}]}]}
{"op":"mcm","clk":"4231059780","pt":1631539338947,"mc":[{"id":"1.187594319","rc":[{"batb":[[1,1.09,638.16],[2,1.01,7]],"ltp":1.21,"tv":337.57,"id":13310360}]}]}
{"op":"mcm","clk":"4231061288","pt":1631539355335,"mc":[{"id":"1.187594319","rc":[{"trd":[[1.21,29.04]],"batl":[[0,1.21,70.96]],"ltp":1.21,"tv":360.14,"id":13310360},{"trd":[[5.7,6.17]],"ltp":5.7,"tv":18.58,"id":9628382}],"tv":378.73}]}
{"op":"mcm","clk":"4231063242","pt":1631539376013,"mc":[{"id":"1.187594319","rc":[{"batb":[[0,1.01,7],[1,1.09,0],[2,1.01,0]],"batl":[[1,1.35,0]],"ltp":1.21,"tv":360.14,"id":13310360},{"batb":[[0,1.01,7],[1,1.01,0]],"ltp":5.7,"tv":18.58,"id":9628382}]}]}
{"op":"mcm","clk":"4231063806","pt":1631539381594,"mc":[{"id":"1.187594319","rc":[{"batb":[[0,1.15,200],[1,1.12,539.54],[2,1.01,7]],"batl":[[1,1.51,838.52]],"ltp":1.21,"tv":360.14,"id":13310360},{"batb":[[0,4.8,10],[1,1.01,7]],"ltp":5.7,"tv":18.58,"id":9628382}]}]}
{"op":"mcm","clk":"4231066222","pt":1631539405571,"mc":[{"id":"1.187594319","rc":[{"batb":[[0,1.12,539.54],[1,1.01,7],[2,1.01,0]],"ltp":1.21,"tv":360.14,"id":13310360},{"batb":[[0,1.01,7],[1,1.01,0]],"ltp":5.7,"tv":18.58,"id":9628382}]}]}
{"op":"mcm","clk":"4231066403","pt":1631539407375,"mc":[{"id":"1.187594319","rc":[{"batb":[[0,1.01,7],[1,1.01,0]],"ltp":1.21,"tv":360.14,"id":13310360}]}]}
{"op":"mcm","clk":"4231066700","pt":1631539410507,"mc":[{"id":"1.187594319","rc":[{"batb":[[0,1.18,166.66],[1,1.01,7]],"ltp":1.21,"tv":360.14,"id":13310360},{"batb":[[0,4.1,10],[1,1.01,7]],"ltp":5.7,"tv":18.58,"id":9628382}]}]}
{"op":"mcm","clk":"4231066902","pt":1631539412700,"mc":[{"id":"1.187594319","rc":[{"batb":[[1,1.16,469.27],[2,1.01,7]],"ltp":1.21,"tv":360.14,"id":13310360}]}]}
{"op":"mcm","clk":"4231067131","pt":1631539415090,"mc":[{"id":"1.187594319","rc":[{"trd":[[1.21,46.16]],"batl":[[0,1.21,62.4]],"ltp":1.21,"tv":377.26,"id":13310360}],"tv":395.85}]}
{"op":"mcm","clk":"4231067999","pt":1631539425328,"mc":[{"id":"1.187594319","rc":[{"trd":[[1.21,72.52]],"batl":[[0,1.21,49.22]],"ltp":1.21,"tv":403.62,"id":13310360}],"tv":422.21}]}
{"op":"mcm","clk":"4231068816","pt":1631539433848,"mc":[{"id":"1.187594319","rc":[{"batb":[[0,1.16,469.27],[1,1.01,7],[2,1.01,0]],"ltp":1.21,"tv":403.62,"id":13310360},{"batb":[[0,1.01,7],[1,1.01,0]],"ltp":5.7,"tv":18.58,"id":9628382}]}]}
{"op":"mcm","clk":"4231068908","pt":1631539434838,"mc":[{"id":"1.187594319","rc":[{"batb":[[0,1.01,7],[1,1.01,0]],"ltp":1.21,"tv":403.62,"id":13310360}]}]}
{"op":"mcm","clk":"4231069298","pt":1631539438856,"mc":[{"id":"1.187594319","rc":[{"batb":[[0,1.2,150],[1,1.01,7]],"ltp":1.21,"tv":403.62,"id":13310360},{"batb":[[0,3.95,10.16],[1,1.01,7]],"ltp":5.7,"tv":18.58,"id":9628382}]}]}
{"op":"mcm","clk":"4231069492","pt":1631539441050,"mc":[{"id":"1.187594319","rc":[{"batb":[[1,1.18,445.2],[2,1.01,7]],"ltp":1.21,"tv":403.62,"id":13310360}]}]}
{"op":"mcm","clk":"4231069678","pt":1631539442947,"mc":[{"id":"1.187594319","rc":[{"trd":[[1.21,121.74]],"batl":[[0,1.51,838.52],[1,1.51,0]],"ltp":1.21,"tv":452.84,"id":13310360},{"trd":[[5.7,16.62]],"ltp":5.7,"tv":29.03,"id":9628382}],"tv":481.88}]}
{"op":"mcm","clk":"4231070618","pt":1631539452577,"mc":[{"id":"1.187594319","rc":[{"batb":[[0,1.2,150.08]],"ltp":1.21,"tv":452.84,"id":13310360}]}]}
{"op":"mcm","clk":"4231071666","pt":1631539462166,"mc":[{"id":"1.187594319","rc":[{"batb":[[0,1.01,7],[1,1.01,0]],"ltp":5.7,"tv":29.03,"id":9628382}]}]}
{"op":"mcm","clk":"4231072193","pt":1631539467072,"mc":[{"id":"1.187594319","rc":[{"batb":[[0,4,10],[1,1.01,7]],"ltp":5.7,"tv":29.03,"id":9628382}]}]}
{"op":"mcm","clk":"4231073969","pt":1631539484701,"mc":[{"id":"1.187594319","rc":[{"batb":[[0,1.18,445.28],[1,1.01,7],[2,1.01,0]],"ltp":1.21,"tv":452.84,"id":13310360},{"batb":[[0,1.01,7],[1,1.01,0]],"ltp":5.7,"tv":29.03,"id":9628382}]}]}
{"op":"mcm","clk":"4231074134","pt":1631539486687,"mc":[{"id":"1.187594319","rc":[{"batb":[[0,1.01,7.08],[1,1.01,0]],"ltp":1.21,"tv":452.84,"id":13310360}]}]}
{"op":"mcm","clk":"4231074391","pt":1631539489721,"mc":[{"id":"1.187594319","rc":[{"batb":[[0,1.18,166.74],[1,1.01,7]],"ltp":1.21,"tv":452.84,"id":13310360},{"batb":[[0,4.3,10],[1,1.01,7]],"ltp":5.7,"tv":29.03,"id":9628382}]}]}
{"op":"mcm","clk":"4231074689","pt":1631539492910,"mc":[{"id":"1.187594319","rc":[{"batb":[[1,1.14,500.97],[2,1.01,7]],"ltp":1.21,"tv":452.84,"id":13310360}]}]}
{"op":"mcm","clk":"4231076733","pt":1631539514447,"mc":[{"id":"1.187594319","rc":[{"batb":[[0,1.14,501.05],[1,1.01,7],[2,1.01,0]],"ltp":1.21,"tv":452.84,"id":13310360},{"batb":[[0,1.01,7],[1,1.01,0]],"ltp":5.7,"tv":29.03,"id":9628382}]}]}
{"op":"mcm","clk":"4231076801","pt":1631539515129,"mc":[{"id":"1.187594319","rc":[{"batb":[[0,1.01,7.08],[1,1.01,0]],"ltp":1.21,"tv":452.84,"id":13310360}]}]}
{"op":"mcm","clk":"4231077220","pt":1631539519575,"mc":[{"id":"1.187594319","rc":[{"trd":[[1.21,121.82]],"batb":[[0,1.11,272.72],[1,1.01,7]],"ltp":1.21,"tv":452.92,"id":13310360},{"trd":[[5.8,0.02]],"ltp":5.8,"tv":29.05,"id":9628382}],"tv":481.98}]}
{"op":"mcm","clk":"4231077354","pt":1631539521036,"mc":[{"id":"1.187594319","rc":[{"batb":[[1,1.09,638.16],[2,1.01,7]],"ltp":1.21,"tv":452.92,"id":13310360}]}]}
{"op":"mcm","clk":"4231077657","pt":1631539524545,"mc":[{"id":"1.187594319","rc":[{"batb":[[0,5.8,10],[1,1.01,7]],"ltp":5.8,"tv":29.05,"id":9628382}]}]}
{"op":"mcm","clk":"4231080538","pt":1631539558813,"mc":[{"id":"1.187594319","rc":[{"batb":[[0,1.09,638.16],[1,1.01,7],[2,1.01,0]],"ltp":1.21,"tv":452.92,"id":13310360},{"batb":[[0,1.01,7],[1,1.01,0]],"ltp":5.8,"tv":29.05,"id":9628382}]}]}
{"op":"mcm","clk":"4231080655","pt":1631539560015,"mc":[{"id":"1.187594319","rc":[{"batb":[[0,1.01,7],[1,1.01,0]],"ltp":1.21,"tv":452.92,"id":13310360}]}]}
{"op":"mcm","clk":"4231081070","pt":1631539563831,"mc":[{"id":"1.187594319","rc":[{"batb":[[0,1.18,166.66],[1,1.01,7]],"ltp":1.21,"tv":452.92,"id":13310360},{"batb":[[0,4.3,10],[1,1.01,7]],"ltp":5.8,"tv":29.05,"id":9628382}]}]}
{"op":"mcm","clk":"4231081261","pt":1631539565718,"mc":[{"id":"1.187594319","rc":[{"batb":[[1,1.14,500.97],[2,1.01,7]],"ltp":1.21,"tv":452.92,"id":13310360}]}]}
{"op":"mcm","clk":"4231082481","pt":1631539579266,"mc":[{"id":"1.187594319","rc":[{"batb":[[0,1.14,500.97],[1,1.01,7],[2,1.01,0]],"ltp":1.21,"tv":452.92,"id":13310360},{"batb":[[0,1.01,7],[1,1.01,0]],"ltp":5.8,"tv":29.05,"id":9628382}]}]}
{"op":"mcm","clk":"4231082606","pt":1631539580365,"mc":[{"id":"1.187594319","rc":[{"batb":[[0,1.01,7],[1,1.01,0]],"ltp":1.21,"tv":452.92,"id":13310360}]}]}
{"op":"mcm","clk":"4231082966","pt":1631539584288,"mc":[{"id":"1.187594319","rc":[{"batb":[[0,1.11,272.72],[1,1.01,7]],"ltp":1.21,"tv":452.92,"id":13310360},{"batb":[[0,5.8,10],[1,1.01,7]],"ltp":5.8,"tv":29.05,"id":9628382}]}]}
{"op":"mcm","clk":"4231083110","pt":1631539586065,"mc":[{"id":"1.187594319","rc":[{"batb":[[1,1.09,638.16],[2,1.01,7]],"ltp":1.21,"tv":452.92,"id":13310360}]}]}
{"op":"mcm","clk":"4231084125","pt":1631539599201,"mc":[{"id":"1.187594319","rc":[{"batb":[[0,1.09,638.16],[1,1.01,7],[2,1.01,0]],"ltp":1.21,"tv":452.92,"id":13310360},{"batb":[[0,1.01,7],[1,1.01,0]],"ltp":5.8,"tv":29.05,"id":9628382}]}]}
{"op":"mcm","clk":"4231084218","pt":1631539600708,"mc":[{"id":"1.187594319","rc":[{"batb":[[0,1.01,7],[1,1.01,0]],"ltp":1.21,"tv":452.92,"id":13310360}]}]}
{"op":"mcm","clk":"4231084491","pt":1631539604102,"mc":[{"id":"1.187594319","rc":[{"batb":[[0,1.18,166.66],[1,1.01,7]],"ltp":1.21,"tv":452.92,"id":13310360},{"batb":[[0,4.3,10],[1,1.01,7]],"ltp":5.8,"tv":29.05,"id":9628382}]}]}
{"op":"mcm","clk":"4231084674","pt":1631539606229,"mc":[{"id":"1.187594319","rc":[{"batb":[[1,1.14,500.97],[2,1.01,7]],"ltp":1.21,"tv":452.92,"id":13310360}]}]}
{"op":"mcm","clk":"4231085142","pt":1631539610932,"mc":[{"id":"1.187594319","rc":[{"batb":[[0,1.14,500.97],[1,1.01,7],[2,1.01,0]],"ltp":1.21,"tv":452.92,"id":13310360},{"batb":[[0,1.01,7],[1,1.01,0]],"ltp":5.8,"tv":29.05,"id":9628382}]}]}
{"op":"mcm","clk":"4231085501","pt":1631539615918,"mc":[{"id":"1.187594319","rc":[{"batb":[[0,1.15,200],[1,1.14,500.97],[2,1.01,7]],"ltp":1.21,"tv":452.92,"id":13310360},{"batb":[[0,4.8,10],[1,1.01,7]],"ltp":5.8,"tv":29.05,"id":9628382}]}]}
{"op":"mcm","clk":"4231086302","pt":1631539625539,"mc":[{"id":"1.187594319","rc":[{"batb":[[0,1.14,500.97],[1,1.01,7],[2,1.01,0]],"ltp":1.21,"tv":452.92,"id":13310360},{"batb":[[0,1.01,7],[1,1.01,0]],"ltp":5.8,"tv":29.05,"id":9628382}]}]}
{"op":"mcm","clk":"4231086338","pt":1631539625952,"mc":[{"id":"1.187594319","rc":[{"batb":[[0,1.01,7],[1,1.01,0]],"ltp":1.21,"tv":452.92,"id":13310360}]}]}
{"op":"mcm","clk":"4231086701","pt":1631539630468,"mc":[{"id":"1.187594319","rc":[{"batb":[[0,1.23,130.43],[1,1.01,7]],"ltp":1.21,"tv":452.92,"id":13310360},{"batb":[[0,3.7,11.11],[1,1.01,7]],"ltp":5.8,"tv":29.05,"id":9628382}]}]}
{"op":"mcm","clk":"4231086776","pt":1631539631249,"mc":[{"id":"1.187594319","rc":[{"batb":[[1,1.18,445.2],[2,1.01,7]],"ltp":1.21,"tv":452.92,"id":13310360}]}]}
{"op":"mcm","clk":"4231094858","pt":1631539731765,"mc":[{"id":"1.187594319","rc":[{"batb":[[1,1.01,7],[2,1.01,0]],"ltp":1.21,"tv":452.92,"id":13310360}]}]}
{"op":"mcm","clk":"4231095432","pt":1631539737862,"mc":[{"id":"1.187594319","rc":[{"batb":[[1,1.2,427.96],[2,1.01,7]],"batl":[[0,1.66,667.28]],"ltp":1.21,"tv":452.92,"id":13310360}]}]}
{"op":"mcm","clk":"4231096369","pt":1631539748599,"mc":[{"id":"1.187594319","rc":[{"batb":[[0,1.2,427.96],[1,1.01,7],[2,1.01,0]],"ltp":1.21,"tv":452.92,"id":13310360},{"batb":[[0,1.01,7],[1,1.01,0]],"ltp":5.8,"tv":29.05,"id":9628382}]}]}
{"op":"mcm","clk":"4231096476","pt":1631539750003,"mc":[{"id":"1.187594319","rc":[{"batb":[[0,1.01,7],[1,1.01,0]],"ltp":1.21,"tv":452.92,"id":13310360}]}]}
{"op":"mcm","clk":"4231096793","pt":1631539753501,"mc":[{"id":"1.187594319","rc":[{"batb":[[0,1.31,96.77],[1,1.01,7]],"ltp":1.21,"tv":452.92,"id":13310360},{"batb":[[0,3.15,13.95],[1,1.01,7]],"ltp":5.8,"tv":29.05,"id":9628382}]}]}
{"op":"mcm","clk":"4231097025","pt":1631539756375,"mc":[{"id":"1.187594319","rc":[{"batb":[[1,1.23,414.27],[2,1.01,7]],"ltp":1.21,"tv":452.92,"id":13310360}]}]}
{"op":"mcm","clk":"4231098191","pt":1631539770229,"mc":[{"id":"1.187594319","rc":[{"batb":[[0,1.01,7],[1,1.23,0],[2,1.01,0]],"ltp":1.21,"tv":452.92,"id":13310360},{"batb":[[0,1.01,7],[1,1.01,0]],"ltp":5.8,"tv":29.05,"id":9628382}]}]}
{"op":"mcm","clk":"4231098607","pt":1631539775132,"mc":[{"id":"1.187594319","rc":[{"batb":[[0,1.23,130.43],[1,1.01,7]],"ltp":1.21,"tv":452.92,"id":13310360},{"batb":[[0,3.7,11.11],[1,1.01,7]],"ltp":5.8,"tv":29.05,"id":9628382}]}]}
{"op":"mcm","clk":"4231098701","pt":1631539776330,"mc":[{"id":"1.187594319","rc":[{"batb":[[1,1.2,427.96],[2,1.01,7]],"ltp":1.21,"tv":452.92,"id":13310360}]}]}
{"op":"mcm","clk":"4231100375","pt":1631539796466,"mc":[{"id":"1.187594319","rc":[{"batb":[[0,1.2,427.96],[1,1.01,7],[2,1.01,0]],"ltp":1.21,"tv":452.92,"id":13310360},{"batb":[[0,1.01,7],[1,1.01,0]],"ltp":5.8,"tv":29.05,"id":9628382}]}]}
{"op":"mcm","clk":"4231100460","pt":1631539797568,"mc":[{"id":"1.187594319","rc":[{"batb":[[0,1.01,7],[1,1.01,0]],"ltp":1.21,"tv":452.92,"id":13310360}]}]}
{"op":"mcm","clk":"4231100793","pt":1631539801496,"mc":[{"id":"1.187594319","rc":[{"batb":[[0,1.18,166.66],[1,1.01,7]],"ltp":1.21,"tv":452.92,"id":13310360},{"batb":[[0,4.1,10],[1,1.01,7]],"ltp":5.8,"tv":29.05,"id":9628382}]}]}
{"op":"mcm","clk":"4231100991","pt":1631539803479,"mc":[{"id":"1.187594319","rc":[{"batb":[[1,1.16,469.27],[2,1.01,7]],"batl":[[0,1.58,742.74]],"ltp":1.21,"tv":452.92,"id":13310360}]}]}
{"op":"mcm","clk":"4231102356","pt":1631539820694,"mc":[{"id":"1.187594319","rc":[{"batb":[[0,1.16,469.27],[1,1.01,7],[2,1.01,0]],"ltp":1.21,"tv":452.92,"id":13310360},{"batb":[[0,1.01,7],[1,1.01,0]],"ltp":5.8,"tv":29.05,"id":9628382}]}]}
{"op":"mcm","clk":"4231102471","pt":1631539821995,"mc":[{"id":"1.187594319","rc":[{"batb":[[0,1.01,7],[1,1.01,0]],"ltp":1.21,"tv":452.92,"id":13310360}]}]}
{"op":"mcm","clk":"4231102784","pt":1631539825738,"mc":[{"id":"1.187594319","rc":[{"batb":[[0,1.15,200],[1,1.01,7]],"ltp":1.21,"tv":452.92,"id":13310360},{"batb":[[0,4.8,10],[1,1.01,7]],"ltp":5.8,"tv":29.05,"id":9628382}]}]}
{"op":"mcm","clk":"4231102945","pt":1631539827620,"mc":[{"id":"1.187594319","rc":[{"batb":[[1,1.12,539.54],[2,1.01,7]],"batl":[[0,1.51,838.52]],"ltp":1.21,"tv":452.92,"id":13310360}]}]}
{"op":"mcm","clk":"4231104764","pt":1631539848359,"mc":[{"id":"1.187594319","rc":[{"batb":[[1,1.01,7],[2,1.01,0]],"ltp":1.21,"tv":452.92,"id":13310360}]}]}
{"op":"mcm","clk":"4231104799","pt":1631539848680,"mc":[{"id":"1.187594319","rc":[{"batb":[[0,1.01,7],[1,1.01,0]],"ltp":1.21,"tv":452.92,"id":13310360},{"batb":[[0,1.01,7],[1,1.01,0]],"ltp":5.8,"tv":29.05,"id":9628382}]}]}
{"op":"mcm","clk":"4231105341","pt":1631539853941,"mc":[{"id":"1.187594319","rc":[{"batb":[[0,1.12,249.99],[1,1.1,606.51],[2,1.01,7]],"ltp":1.21,"tv":452.92,"id":13310360},{"batb":[[0,5.3,10],[1,1.01,7]],"ltp":5.8,"tv":29.05,"id":9628382}]}]}
{"op":"mcm","clk":"4231109668","pt":1631539901866,"mc":[{"id":"1.187594319","rc":[{"batb":[[0,1.1,606.51],[1,1.01,7],[2,1.01,0]],"ltp":1.21,"tv":452.92,"id":13310360},{"batb":[[0,1.01,7],[1,1.01,0]],"ltp":5.8,"tv":29.05,"id":9628382}]}]}
{"op":"mcm","clk":"4231109776","pt":1631539903063,"mc":[{"id":"1.187594319","rc":[{"batb":[[0,1.01,7],[1,1.01,0]],"ltp":1.21,"tv":452.92,"id":13310360}]}]}
{"op":"mcm","clk":"4231110125","pt":1631539906871,"mc":[{"id":"1.187594319","rc":[{"batb":[[0,1.18,166.66],[1,1.01,7]],"ltp":1.21,"tv":452.92,"id":13310360},{"batb":[[0,4.3,10],[1,1.01,7]],"ltp":5.8,"tv":29.05,"id":9628382}]}]}
{"op":"mcm","clk":"4231110340","pt":1631539909165,"mc":[{"id":"1.187594319","rc":[{"batb":[[1,1.14,500.97],[2,1.01,7]],"ltp":1.21,"tv":452.92,"id":13310360}]}]}
{"op":"mcm","clk":"4231112036","pt":1631539927267,"mc":[{"id":"1.187594319","rc":[{"batb":[[0,1.01,7],[1,1.01,0]],"ltp":5.8,"tv":29.05,"id":9628382}]}]}
{"op":"mcm","clk":"4231112136","pt":1631539928405,"mc":[{"id":"1.187594319","rc":[{"batb":[[1,1.01,7],[2,1.01,0]],"ltp":1.21,"tv":452.92,"id":13310360}]}]}
{"op":"mcm","clk":"4231112539","pt":1631539932317,"mc":[{"id":"1.187594319","rc":[{"batb":[[0,4.1,10],[1,1.01,7]],"ltp":5.8,"tv":29.05,"id":9628382}]}]}
{"op":"mcm","clk":"4231112760","pt":1631539934715,"mc":[{"id":"1.187594319","rc":[{"batb":[[1,1.16,469.27],[2,1.01,7]],"ltp":1.21,"tv":452.92,"id":13310360}]}]}
{"op":"mcm","clk":"4231113219","pt":1631539939531,"mc":[{"id":"1.187594319","rc":[{"batb":[[0,1.16,469.27],[1,1.01,7],[2,1.01,0]],"ltp":1.21,"tv":452.92,"id":13310360},{"batb":[[0,1.01,7],[1,1.01,0]],"ltp":5.8,"tv":29.05,"id":9628382}]}]}
{"op":"mcm","clk":"4231113327","pt":1631539940727,"mc":[{"id":"1.187594319","rc":[{"batb":[[0,1.01,7],[1,1.01,0]],"ltp":1.21,"tv":452.92,"id":13310360}]}]}
{"op":"mcm","clk":"4231113698","pt":1631539944548,"mc":[{"id":"1.187594319","rc":[{"batb":[[0,1.27,111.11],[1,1.01,7]],"ltp":1.21,"tv":452.92,"id":13310360},{"batb":[[0,3.4,12.5],[1,1.01,7]],"ltp":5.8,"tv":29.05,"id":9628382}]}]}
{"op":"mcm","clk":"4231113931","pt":1631539946905,"mc":[{"id":"1.187594319","rc":[{"batb":[[1,1.2,427.96],[2,1.01,7]],"batl":[[0,1.66,667.28]],"ltp":1.21,"tv":452.92,"id":13310360}]}]}
{"op":"mcm","clk":"4231115899","pt":1631539968980,"mc":[{"id":"1.187594319","rc":[{"batb":[[0,1.2,427.96],[1,1.01,7],[2,1.01,0]],"ltp":1.21,"tv":452.92,"id":13310360},{"batb":[[0,1.01,7],[1,1.01,0]],"ltp":5.8,"tv":29.05,"id":9628382}]}]}
{"op":"mcm","clk":"4231115983","pt":1631539970173,"mc":[{"id":"1.187594319","rc":[{"batb":[[0,1.01,7],[1,1.01,0]],"ltp":1.21,"tv":452.92,"id":13310360}]}]}
{"op":"mcm","clk":"4231116318","pt":1631539973877,"mc":[{"id":"1.187594319","rc":[{"batb":[[0,1.2,150],[1,1.01,7]],"ltp":1.21,"tv":452.92,"id":13310360},{"batb":[[0,4,10],[1,1.01,7]],"ltp":5.8,"tv":29.05,"id":9628382}]}]}
{"op":"mcm","clk":"4231116516","pt":1631539976466,"mc":[{"id":"1.187594319","rc":[{"batb":[[1,1.16,469.27],[2,1.01,7]],"batl":[[0,1.58,742.74]],"ltp":1.21,"tv":452.92,"id":13310360}]}]}
{"op":"mcm","clk":"4231118807","pt":1631540004508,"mc":[{"id":"1.187594319","rc":[{"batb":[[0,1.16,469.27],[1,1.01,7],[2,1.01,0]],"ltp":1.21,"tv":452.92,"id":13310360},{"batb":[[0,1.01,7],[1,1.01,0]],"ltp":5.8,"tv":29.05,"id":9628382}]}]}
{"op":"mcm","clk":"4231118896","pt":1631540005636,"mc":[{"id":"1.187594319","rc":[{"batb":[[0,1.01,7],[1,1.01,0]],"ltp":1.21,"tv":452.92,"id":13310360}]}]}
{"op":"mcm","clk":"4231119211","pt":1631540009441,"mc":[{"id":"1.187594319","rc":[{"batb":[[0,1.15,200],[1,1.01,7]],"ltp":1.21,"tv":452.92,"id":13310360},{"batb":[[0,4.8,10],[1,1.01,7]],"ltp":5.8,"tv":29.05,"id":9628382}]}]}
{"op":"mcm","clk":"4231119397","pt":1631540011527,"mc":[{"id":"1.187594319","rc":[{"batb":[[1,1.12,539.54],[2,1.01,7]],"batl":[[0,1.51,838.52]],"ltp":1.21,"tv":452.92,"id":13310360}]}]}
{"op":"mcm","clk":"4231121090","pt":1631540031173,"mc":[{"id":"1.187594319","rc":[{"batb":[[0,1.12,539.54],[1,1.01,7],[2,1.01,0]],"ltp":1.21,"tv":452.92,"id":13310360},{"batb":[[0,1.01,7],[1,1.01,0]],"ltp":5.8,"tv":29.05,"id":9628382}]}]}
{"op":"mcm","clk":"4231121158","pt":1631540031951,"mc":[{"id":"1.187594319","rc":[{"batb":[[0,1.01,7],[1,1.01,0]],"ltp":1.21,"tv":452.92,"id":13310360}]}]}
{"op":"mcm","clk":"4231121476","pt":1631540036071,"mc":[{"id":"1.187594319","rc":[{"batb":[[0,1.2,150],[1,1.01,7]],"ltp":1.21,"tv":452.92,"id":13310360},{"batb":[[0,4,10],[1,1.01,7]],"ltp":5.8,"tv":29.05,"id":9628382}]}]}
{"op":"mcm","clk":"4231121646","pt":1631540037799,"mc":[{"id":"1.187594319","rc":[{"batb":[[1,1.16,469.27],[2,1.01,7]],"ltp":1.21,"tv":452.92,"id":13310360}]}]}
{"op":"mcm","clk":"4231124002","pt":1631540062904,"mc":[{"id":"1.187594319","rc":[{"batb":[[0,1.01,7],[1,1.01,0]],"ltp":5.8,"tv":29.05,"id":9628382}]}]}
{"op":"mcm","clk":"4231124131","pt":1631540064410,"mc":[{"id":"1.187594319","rc":[{"batb":[[1,1.01,7],[2,1.01,0]],"ltp":1.21,"tv":452.92,"id":13310360}]}]}
{"op":"mcm","clk":"4231124365","pt":1631540067823,"mc":[{"id":"1.187594319","rc":[{"batb":[[0,3.95,10.16],[1,1.01,7]],"ltp":5.8,"tv":29.05,"id":9628382}]}]}
{"op":"mcm","clk":"4231124536","pt":1631540070127,"mc":[{"id":"1.187594319","rc":[{"batb":[[1,1.18,445.2],[2,1.01,7]],"ltp":1.21,"tv":452.92,"id":13310360}]}]}
{"op":"mcm","clk":"4231125944","pt":1631540088165,"mc":[{"id":"1.187594319","rc":[{"batb":[[0,1.18,445.2],[1,1.01,7],[2,1.01,0]],"ltp":1.21,"tv":452.92,"id":13310360},{"batb":[[0,1.01,7],[1,1.01,0]],"ltp":5.8,"tv":29.05,"id":9628382}]}]}
{"op":"mcm","clk":"4231126084","pt":1631540089776,"mc":[{"id":"1.187594319","rc":[{"batb":[[0,1.01,7],[1,1.01,0]],"ltp":1.21,"tv":452.92,"id":13310360}]}]}
{"op":"mcm","clk":"4231126339","pt":1631540093083,"mc":[{"id":"1.187594319","rc":[{"batb":[[0,1.15,200],[1,1.01,7]],"ltp":1.21,"tv":452.92,"id":13310360},{"batb":[[0,4.8,10],[1,1.01,7]],"ltp":5.8,"tv":29.05,"id":9628382}]}]}
{"op":"mcm","clk":"4231126502","pt":1631540095059,"mc":[{"id":"1.187594319","rc":[{"batb":[[1,1.12,539.54],[2,1.01,7]],"ltp":1.21,"tv":452.92,"id":13310360}]}]}
{"op":"mcm","clk":"4231132857","pt":1631540169081,"mc":[{"id":"1.187594319","rc":[{"batb":[[0,1.12,539.54],[1,1.01,7],[2,1.01,0]],"ltp":1.21,"tv":452.92,"id":13310360},{"batb":[[0,1.01,7],[1,1.01,0]],"ltp":5.8,"tv":29.05,"id":9628382}]}]}
{"op":"mcm","clk":"4231132929","pt":1631540169863,"mc":[{"id":"1.187594319","rc":[{"batb":[[0,1.01,7],[1,1.01,0]],"ltp":1.21,"tv":452.92,"id":13310360}]}]}
{"op":"mcm","clk":"4231133319","pt":1631540174064,"mc":[{"id":"1.187594319","rc":[{"batb":[[0,1.08,374.99],[1,1.01,7]],"ltp":1.21,"tv":452.92,"id":13310360},{"batb":[[0,6,10],[1,1.01,7]],"ltp":5.8,"tv":29.05,"id":9628382}]}]}
{"op":"mcm","clk":"4231133471","pt":1631540175995,"mc":[{"id":"1.187594319","rc":[{"batb":[[0,1.08,1060.54]],"batl":[[0,1.44,961.06]],"ltp":1.21,"tv":452.92,"id":13310360}]}]}
{"op":"mcm","clk":"4231137518","pt":1631540226099,"mc":[{"id":"1.187594319","rc":[{"batb":[[0,1.08,685.55]],"ltp":1.21,"tv":452.92,"id":13310360},{"batb":[[0,1.01,7],[1,1.01,0]],"ltp":5.8,"tv":29.05,"id":9628382}]}]}
{"op":"mcm","clk":"4231137673","pt":1631540227664,"mc":[{"id":"1.187594319","rc":[{"batb":[[0,1.01,7],[1,1.01,0]],"ltp":1.21,"tv":452.92,"id":13310360}]}]}
{"op":"mcm","clk":"4231137977","pt":1631540230962,"mc":[{"id":"1.187594319","rc":[{"batb":[[0,1.04,749.99],[1,1.01,7]],"ltp":1.21,"tv":452.92,"id":13310360},{"batb":[[0,8.6,10],[1,1.01,7]],"ltp":5.8,"tv":29.05,"id":9628382}]}]}
{"op":"mcm","clk":"4231138190","pt":1631540233586,"mc":[{"id":"1.187594319","rc":[{"batb":[[0,1.04,1901.12]],"batl":[[0,1.37,1110.7]],"ltp":1.21,"tv":452.92,"id":13310360}]}]}
{"op":"mcm","clk":"4231139073","pt":1631540244989,"mc":[{"id":"1.187594319","rc":[{"batb":[[0,1.04,749.99]],"ltp":1.21,"tv":452.92,"id":13310360}]}]}
{"op":"mcm","clk":"4231140024","pt":1631540258015,"mc":[{"id":"1.187594319","rc":[{"batb":[[0,1.01,7],[1,1.01,0]],"ltp":1.21,"tv":452.92,"id":13310360},{"batb":[[0,1.01,7],[1,1.01,0]],"ltp":5.8,"tv":29.05,"id":9628382}]}]}
{"op":"mcm","clk":"4231140445","pt":1631540263044,"mc":[{"id":"1.187594319","rc":[{"batb":[[0,1.02,2026.61],[1,1.01,7]],"batl":[[0,1.33,1235.43]],"ltp":1.21,"tv":452.92,"id":13310360},{"batb":[[0,11,10],[1,1.01,7]],"ltp":5.8,"tv":29.05,"id":9628382}]}]}
{"op":"mcm","clk":"4231143783","pt":1631540304027,"mc":[{"id":"1.187594319","rc":[{"batb":[[0,1.01,7],[1,1.01,0]],"ltp":5.8,"tv":29.05,"id":9628382}]}]}
{"op":"mcm","clk":"4231143851","pt":1631540304919,"mc":[{"id":"1.187594319","rc":[{"batb":[[0,1.01,7],[1,1.01,0]],"ltp":1.21,"tv":452.92,"id":13310360}]}]}
{"op":"mcm","clk":"4231144132","pt":1631540308926,"mc":[{"id":"1.187594319","rc":[{"batb":[[0,14,10],[1,1.01,7]],"ltp":5.8,"tv":29.05,"id":9628382}]}]}
{"op":"mcm","clk":"4231144239","pt":1631540310543,"mc":[{"id":"1.187594319","rc":[{"batb":[[0,1.01,3809.99]],"ltp":1.21,"tv":452.92,"id":13310360}]}]}
{"op":"mcm","clk":"4231153559","pt":1631540421849,"mc":[{"id":"1.187594319","rc":[{"batb":[[0,1.05,200],[1,1.01,3809.99]],"ltp":1.21,"tv":452.92,"id":13310360}]}]}
{"op":"mcm","clk":"4231156437","pt":1631540455280,"mc":[{"id":"1.187594319","rc":[{"batb":[[0,1.01,7],[1,1.01,0]],"ltp":5.8,"tv":29.05,"id":9628382}]}]}
{"op":"mcm","clk":"4231156525","pt":1631540456276,"mc":[{"id":"1.187594319","rc":[{"batb":[[1,1.01,7]],"ltp":1.21,"tv":452.92,"id":13310360}]}]}
{"op":"mcm","clk":"4231156836","pt":1631540460190,"mc":[{"id":"1.187594319","rc":[{"batb":[[0,16,10],[1,1.01,7]],"ltp":5.8,"tv":29.05,"id":9628382}]}]}
{"op":"mcm","clk":"4231157046","pt":1631540462408,"mc":[{"id":"1.187594319","rc":[{"batl":[[0,170,36.65]],"ltp":5.8,"tv":29.05,"id":9628382}]}]}
{"op":"mcm","clk":"4231158442","pt":1631540478843,"mc":[{"id":"1.187594319","rc":[{"batb":[[0,1.01,7],[1,1.01,0]],"ltp":5.8,"tv":29.05,"id":9628382}]}]}
{"op":"mcm","clk":"4231158682","pt":1631540481616,"mc":[{"id":"1.187594319","rc":[{"batb":[[0,1.01,7],[1,1.01,0]],"ltp":1.21,"tv":452.92,"id":13310360}]}]}
{"op":"mcm","clk":"4231158881","pt":1631540483752,"mc":[{"id":"1.187594319","rc":[{"batb":[[0,19.5,10],[1,1.01,7]],"ltp":5.8,"tv":29.05,"id":9628382}]}]}
{"op":"mcm","clk":"4231159125","pt":1631540486735,"mc":[{"id":"1.187594319","rc":[{"batl":[[0,340,35.94]],"ltp":5.8,"tv":29.05,"id":9628382}]}]}
{"op":"mcm","clk":"4231172116","pt":1631540631871,"mc":[{"id":"1.187594319","rc":[{"batb":[[0,1.01,7],[1,1.01,0]],"ltp":5.8,"tv":29.05,"id":9628382}]}]}
{"op":"mcm","clk":"4231172589","pt":1631540636750,"mc":[{"id":"1.187594319","rc":[{"batb":[[0,16,10],[1,1.01,7]],"ltp":5.8,"tv":29.05,"id":9628382}]}]}
{"op":"mcm","clk":"4231176409","pt":1631540674511,"mc":[{"id":"1.187594319","rc":[{"batb":[[0,1.01,7],[1,1.01,0]],"ltp":5.8,"tv":29.05,"id":9628382}]}]}
{"op":"mcm","clk":"4231176951","pt":1631540679512,"mc":[{"id":"1.187594319","rc":[{"batb":[[0,14,10],[1,1.01,7]],"ltp":5.8,"tv":29.05,"id":9628382}]}]}
{"op":"mcm","clk":"4231177123","pt":1631540681223,"mc":[{"id":"1.187594319","rc":[{"batb":[[0,1.01,3930.11]],"batl":[[0,1.32,1269.71]],"ltp":1.21,"tv":452.92,"id":13310360}]}]}
{"op":"mcm","clk":"4231180558","pt":1631540714882,"mc":[{"id":"1.187594319","rc":[{"batb":[[0,1.01,7],[1,1.01,0]],"ltp":5.8,"tv":29.05,"id":9628382}]}]}
{"op":"mcm","clk":"4231181060","pt":1631540719721,"mc":[{"id":"1.187594319","rc":[{"batb":[[0,12,10],[1,1.01,7]],"ltp":5.8,"tv":29.05,"id":9628382}]}]}
{"op":"mcm","clk":"4231187325","pt":1631540783822,"mc":[{"id":"1.187594319","rc":[{"batb":[[0,1.01,7],[1,1.01,0]],"ltp":5.8,"tv":29.05,"id":9628382}]}]}
{"op":"mcm","clk":"4231187527","pt":1631540785547,"mc":[{"id":"1.187594319","rc":[{"batb":[[0,1.01,7]],"ltp":1.21,"tv":452.92,"id":13310360}]}]}
{"op":"mcm","clk":"4231187863","pt":1631540788820,"mc":[{"id":"1.187594319","rc":[{"batb":[[0,1.02,1499.99],[1,1.01,7]],"ltp":1.21,"tv":452.92,"id":13310360},{"batb":[[0,10,10],[1,1.01,7]],"ltp":5.8,"tv":29.05,"id":9628382}]}]}
{"op":"mcm","clk":"4231188070","pt":1631540791053,"mc":[{"id":"1.187594319","rc":[{"batb":[[0,1.03,1419.65],[1,1.02,1499.99],[2,1.01,7]],"ltp":1.21,"tv":452.92,"id":13310360}]}]}
{"op":"mcm","clk":"4231193274","pt":1631540841298,"mc":[{"id":"1.187594319","rc":[{"batb":[[1,1.01,7],[2,1.01,0]],"ltp":1.21,"tv":452.92,"id":13310360},{"batb":[[0,1.01,7],[1,1.01,0]],"ltp":5.8,"tv":29.05,"id":9628382}]}]}
{"op":"mcm","clk":"4231193391","pt":1631540842395,"mc":[{"id":"1.187594319","rc":[{"batb":[[0,1.01,7],[1,1.01,0]],"ltp":1.21,"tv":452.92,"id":13310360}]}]}
{"op":"mcm","clk":"4231193760","pt":1631540846187,"mc":[{"id":"1.187594319","rc":[{"batb":[[0,11,10],[1,1.01,7]],"ltp":5.8,"tv":29.05,"id":9628382}]}]}
{"op":"mcm","clk":"4231193927","pt":1631540847810,"mc":[{"id":"1.187594319","rc":[{"batb":[[0,1.02,2026.61],[1,1.01,7]],"ltp":1.21,"tv":452.92,"id":13310360}]}]}
{"op":"mcm","clk":"4231196589","pt":1631540875243,"mc":[{"id":"1.187594319","rc":[{"batb":[[0,1.01,7],[1,1.01,0]],"ltp":5.8,"tv":29.05,"id":9628382}]}]}
{"op":"mcm","clk":"4231196744","pt":1631540876744,"mc":[{"id":"1.187594319","rc":[{"batb":[[0,1.01,7],[1,1.01,0]],"ltp":1.21,"tv":452.92,"id":13310360}]}]}
{"op":"mcm","clk":"4231197100","pt":1631540880178,"mc":[{"id":"1.187594319","rc":[{"batb":[[0,14,10],[1,1.01,7]],"ltp":5.8,"tv":29.05,"id":9628382}]}]}
{"op":"mcm","clk":"4231197394","pt":1631540882973,"mc":[{"id":"1.187594319","rc":[{"batb":[[0,1.01,3809.99]],"ltp":1.21,"tv":452.92,"id":13310360}]}]}
{"op":"mcm","clk":"4231203999","pt":1631540948569,"mc":[{"id":"1.187594319","rc":[{"batb":[[0,1.01,7],[1,1.01,0]],"ltp":5.8,"tv":29.05,"id":9628382}]}]}
{"op":"mcm","clk":"4231204018","pt":1631540948773,"mc":[{"id":"1.187594319","rc":[{"batb":[[0,1.01,7]],"ltp":1.21,"tv":452.92,"id":13310360}]}]}
{"op":"mcm","clk":"4231204495","pt":1631540953573,"mc":[{"id":"1.187594319","rc":[{"batb":[[0,16,10],[1,1.01,7]],"ltp":5.8,"tv":29.05,"id":9628382}]}]}
{"op":"mcm","clk":"4231204618","pt":1631540954878,"mc":[{"id":"1.187594319","rc":[{"batl":[[0,170,36.65]],"ltp":5.8,"tv":29.05,"id":9628382}]}]}
{"op":"mcm","clk":"4231210112","pt":1631541010479,"mc":[{"id":"1.187594319","rc":[{"trd":[[16,20]],"batb":[[0,1.01,7],[1,1.01,0]],"ltp":16.0,"tv":49.05,"id":9628382}],"tv":501.98}]}
{"op":"mcm","clk":"4231213949","pt":1631541051252,"mc":[{"id":"1.187594319","rc":[{"batb":[[0,14,10],[1,1.01,7]],"ltp":16.0,"tv":49.05,"id":9628382}]}]}
{"op":"mcm","clk":"4231214392","pt":1631541056660,"mc":[{"id":"1.187594319","rc":[{"batb":[[1,1.02,10],[2,1.01,7]],"ltp":16.0,"tv":49.05,"id":9628382}]}]}
{"op":"mcm","clk":"4231216580","pt":1631541083890,"mc":[{"id":"1.187594319","rc":[{"batb":[[0,1.02,10],[1,1.01,7],[2,1.01,0]],"ltp":16.0,"tv":49.05,"id":9628382}]}]}
{"op":"mcm","clk":"4231216956","pt":1631541088795,"mc":[{"id":"1.187594319","rc":[{"batb":[[0,12,10],[1,1.02,10],[2,1.01,7]],"ltp":16.0,"tv":49.05,"id":9628382}]}]}
{"op":"mcm","clk":"4231219123","pt":1631541118273,"mc":[{"id":"1.187594319","rc":[{"batb":[[0,1.02,10],[1,1.01,7],[2,1.01,0]],"ltp":16.0,"tv":49.05,"id":9628382}]}]}
{"op":"mcm","clk":"4231219516","pt":1631541123159,"mc":[{"id":"1.187594319","rc":[{"batb":[[0,1.02,1499.99],[1,1.01,7]],"ltp":1.21,"tv":452.92,"id":13310360},{"batb":[[0,10,10],[1,1.02,10],[2,1.01,7]],"ltp":16.0,"tv":49.05,"id":9628382}]}]}
{"op":"mcm","clk":"4231221239","pt":1631541146419,"mc":[{"id":"1.187594319","rc":[{"batb":[[0,1.01,7],[1,1.01,0]],"ltp":1.21,"tv":452.92,"id":13310360},{"batb":[[0,1.02,10],[1,1.01,7],[2,1.01,0]],"ltp":16.0,"tv":49.05,"id":9628382}]}]}
{"op":"mcm","clk":"4231221589","pt":1631541151337,"mc":[{"id":"1.187594319","rc":[{"batb":[[0,11,10],[1,1.02,10],[2,1.01,7]],"ltp":16.0,"tv":49.05,"id":9628382}]}]}
{"op":"mcm","clk":"4231223305","pt":1631541173634,"mc":[{"id":"1.187594319","rc":[{"batb":[[0,1.02,10],[1,1.01,7],[2,1.01,0]],"ltp":16.0,"tv":49.05,"id":9628382}]}]}
{"op":"mcm","clk":"4231223698","pt":1631541178650,"mc":[{"id":"1.187594319","rc":[{"batb":[[0,12,10],[1,1.02,10],[2,1.01,7]],"ltp":16.0,"tv":49.05,"id":9628382}]}]}
{"op":"mcm","clk":"4231224469","pt":1631541189344,"mc":[{"id":"1.187594319","rc":[{"batb":[[0,1.02,10],[1,1.01,7],[2,1.01,0]],"ltp":16.0,"tv":49.05,"id":9628382}]}]}
{"op":"mcm","clk":"4231224796","pt":1631541194387,"mc":[{"id":"1.187594319","rc":[{"batb":[[0,14,10],[1,1.02,10],[2,1.01,7]],"ltp":16.0,"tv":49.05,"id":9628382}]}]}
{"op":"mcm","clk":"4231226486","pt":1631541220988,"mc":[{"id":"1.187594319","rc":[{"batb":[[0,1.02,10],[1,1.01,7],[2,1.01,0]],"ltp":16.0,"tv":49.05,"id":9628382}]}]}
{"op":"mcm","clk":"4231226842","pt":1631541225934,"mc":[{"id":"1.187594319","rc":[{"batb":[[0,11,10],[1,1.02,10],[2,1.01,7]],"ltp":16.0,"tv":49.05,"id":9628382}]}]}
{"op":"mcm","clk":"4231229709","pt":1631541266475,"mc":[{"id":"1.187594319","rc":[{"batb":[[0,1.02,10],[1,1.01,7],[2,1.01,0]],"ltp":16.0,"tv":49.05,"id":9628382}]}]}
{"op":"mcm","clk":"4231230029","pt":1631541271262,"mc":[{"id":"1.187594319","rc":[{"batb":[[0,12,10],[1,1.02,10],[2,1.01,7]],"ltp":16.0,"tv":49.05,"id":9628382}]}]}
{"op":"mcm","clk":"4231231131","pt":1631541289304,"mc":[{"id":"1.187594319","rc":[{"batb":[[0,1.02,10],[1,1.01,7],[2,1.01,0]],"ltp":16.0,"tv":49.05,"id":9628382}]}]}
{"op":"mcm","clk":"4231231430","pt":1631541294345,"mc":[{"id":"1.187594319","rc":[{"batb":[[0,14,10],[1,1.02,10],[2,1.01,7]],"ltp":16.0,"tv":49.05,"id":9628382}]}]}
{"op":"mcm","clk":"4231236799","pt":1631541380171,"mc":[{"id":"1.187594319","rc":[{"trd":[[1.08,133.71]],"batb":[[0,1.08,420.37],[1,1.01,7]],"ltp":1.08,"tv":582.55,"id":13310360},{"trd":[[14,10]],"batb":[[0,1.02,10],[1,1.01,7],[2,1.01,0]],"ltp":14.0,"tv":59.05,"id":9628382}],"tv":641.61}]}
{"op":"mcm","clk":"4231238823","pt":1631541406691,"mc":[{"id":"1.187594319","rc":[{"trd":[[1.08,258.71]],"batb":[[0,1.08,295.37]],"ltp":1.08,"tv":707.55,"id":13310360},{"trd":[[13.5,10]],"ltp":13.5,"tv":69.05,"id":9628382}],"tv":776.61}]}
{"op":"mcm","clk":"4231238972","pt":1631541409014,"mc":[{"id":"1.187594319","rc":[{"batl":[[0,1.3,1344.81]],"ltp":1.08,"tv":707.55,"id":13310360},{"batl":[[0,170,36.65]],"ltp":13.5,"tv":69.05,"id":9628382}]}]}
{"op":"mcm","clk":"4231239749","pt":1631541420106,"mc":[{"id":"1.187594319","rc":[{"trd":[[1.08,416.42]],"batb":[[0,1.08,216.52]],"ltp":1.08,"tv":865.25,"id":13310360}],"tv":934.31}]}
{"op":"mcm","clk":"4231242005","pt":1631541451869,"mc":[{"id":"1.187594319","rc":[{"trd":[[1.08,441.42]],"batb":[[0,1.08,191.52]],"ltp":1.08,"tv":890.25,"id":13310360},{"trd":[[13.5,12]],"ltp":13.5,"tv":71.05,"id":9628382}],"tv":961.31}]}
{"op":"mcm","clk":"4231244405","pt":1631541485897,"mc":[{"id":"1.187594319","rc":[{"trd":[[1.08,599.12]],"batb":[[0,1.08,112.67]],"ltp":1.08,"tv":1047.96,"id":13310360}],"tv":1119.02}]}
{"op":"mcm","clk":"4231246709","pt":1631541515957,"mc":[{"id":"1.187594319","rc":[{"trd":[[1.08,756.83]],"batb":[[0,1.08,33.82]],"ltp":1.08,"tv":1205.66,"id":13310360}],"tv":1276.72}]}
{"op":"mcm","clk":"4231248140","pt":1631541534469,"mc":[{"id":"1.187594319","rc":[{"trd":[[1.08,790.65]],"batb":[[0,1.01,7],[1,1.01,0]],"ltp":1.08,"tv":1239.48,"id":13310360},{"trd":[[13.5,14.71]],"batb":[[0,5,10],[1,1.02,10],[2,1.01,7]],"ltp":13.5,"tv":73.76,"id":9628382}],"tv":1313.25}]}
{"op":"mcm","clk":"4231248204","pt":1631541535397,"mc":[{"id":"1.187594319","rc":[{"batb":[[0,1.01,3930.11]],"ltp":1.08,"tv":1239.48,"id":13310360}]}]}
{"op":"mcm","clk":"4231248454","pt":1631541539287,"mc":[{"id":"1.187594319","rc":[{"batb":[[0,14,10],[1,5,10],[2,1.02,10]],"ltp":13.5,"tv":73.76,"id":9628382}]}]}
{"op":"mcm","clk":"4231248718","pt":1631541542989,"mc":[{"id":"1.187594319","rc":[{"batb":[[1,1.01,7],[2,1.02,0]],"ltp":13.5,"tv":73.76,"id":9628382}]}]}
{"op":"mcm","clk":"4231248785","pt":1631541543917,"mc":[{"id":"1.187594319","rc":[{"batb":[[0,1.01,7]],"ltp":1.08,"tv":1239.48,"id":13310360}]}]}
{"op":"mcm","clk":"4231249170","pt":1631541549620,"mc":[{"id":"1.187594319","rc":[{"batb":[[0,1.01,3809.99]],"ltp":1.08,"tv":1239.48,"id":13310360}]}]}
{"op":"mcm","clk":"4231249853","pt":1631541559017,"mc":[{"id":"1.187594319","rc":[{"batb":[[0,1.01,7],[1,1.01,0]],"ltp":13.5,"tv":73.76,"id":9628382}]}]}
{"op":"mcm","clk":"4231249945","pt":1631541560215,"mc":[{"id":"1.187594319","rc":[{"batb":[[0,1.01,7]],"ltp":1.08,"tv":1239.48,"id":13310360}]}]}
{"op":"mcm","clk":"4231250293","pt":1631541563914,"mc":[{"id":"1.187594319","rc":[{"batb":[[0,11,10],[1,1.01,7]],"ltp":13.5,"tv":73.76,"id":9628382}]}]}
{"op":"mcm","clk":"4231250431","pt":1631541565737,"mc":[{"id":"1.187594319","rc":[{"batb":[[0,1.02,2026.61],[1,1.01,7]],"ltp":1.08,"tv":1239.48,"id":13310360}]}]}
{"op":"mcm","clk":"4231251510","pt":1631541580153,"mc":[{"id":"1.187594319","rc":[{"batb":[[0,1.01,7],[1,1.01,0]],"ltp":13.5,"tv":73.76,"id":9628382}]}]}
{"op":"mcm","clk":"4231251673","pt":1631541582546,"mc":[{"id":"1.187594319","rc":[{"batb":[[0,1.01,7],[1,1.01,0]],"ltp":1.08,"tv":1239.48,"id":13310360}]}]}
{"op":"mcm","clk":"4231251867","pt":1631541585033,"mc":[{"id":"1.187594319","rc":[{"batb":[[0,12,10],[1,1.01,7]],"ltp":13.5,"tv":73.76,"id":9628382}]}]}
{"op":"mcm","clk":"4231252080","pt":1631541587955,"mc":[{"id":"1.187594319","rc":[{"batb":[[0,1.01,3930.11]],"ltp":1.08,"tv":1239.48,"id":13310360}]}]}
{"op":"mcm","clk":"4231253394","pt":1631541603886,"mc":[{"id":"1.187594319","rc":[{"batb":[[0,1.01,7]],"ltp":1.08,"tv":1239.48,"id":13310360}]}]}
{"op":"mcm","clk":"4231253931","pt":1631541610196,"mc":[{"id":"1.187594319","rc":[{"batb":[[0,1.01,3809.99]],"ltp":1.08,"tv":1239.48,"id":13310360}]}]}
{"op":"mcm","clk":"4231255462","pt":1631541630210,"mc":[{"id":"1.187594319","rc":[{"batb":[[0,1.01,7],[1,1.01,0]],"ltp":13.5,"tv":73.76,"id":9628382}]}]}
{"op":"mcm","clk":"4231255597","pt":1631541632293,"mc":[{"id":"1.187594319","rc":[{"batb":[[0,1.01,7]],"ltp":1.08,"tv":1239.48,"id":13310360}]}]}
{"op":"mcm","clk":"4231255789","pt":1631541635204,"mc":[{"id":"1.187594319","rc":[{"batb":[[0,16,10],[1,1.01,7]],"ltp":13.5,"tv":73.76,"id":9628382}]}]}
{"op":"mcm","clk":"4231256008","pt":1631541638501,"mc":[{"id":"1.187594319","rc":[{"batl":[[0,170,36.65]],"ltp":13.5,"tv":73.76,"id":9628382}]}]}
{"op":"mcm","clk":"4231258386","pt":1631541669171,"mc":[{"id":"1.187594319","rc":[{"batb":[[0,1.01,7],[1,1.01,0]],"ltp":13.5,"tv":73.76,"id":9628382}]}]}
{"op":"mcm","clk":"4231258815","pt":1631541674174,"mc":[{"id":"1.187594319","rc":[{"batb":[[0,12,10],[1,1.01,7]],"ltp":13.5,"tv":73.76,"id":9628382}]}]}
{"op":"mcm","clk":"4231259128","pt":1631541677190,"mc":[{"id":"1.187594319","rc":[{"batb":[[0,1.01,3930.11]],"ltp":1.08,"tv":1239.48,"id":13310360}]}]}
{"op":"mcm","clk":"4231261368","pt":1631541701008,"mc":[{"id":"1.187594319","rc":[{"batb":[[0,1.01,7],[1,1.01,0]],"ltp":13.5,"tv":73.76,"id":9628382}]}]}
{"op":"mcm","clk":"4231261493","pt":1631541702412,"mc":[{"id":"1.187594319","rc":[{"batb":[[0,1.01,7]],"ltp":1.08,"tv":1239.48,"id":13310360}]}]}
{"op":"mcm","clk":"4231261795","pt":1631541705947,"mc":[{"id":"1.187594319","rc":[{"batb":[[0,16,10],[1,1.01,7]],"ltp":13.5,"tv":73.76,"id":9628382}]}]}
{"op":"mcm","clk":"4231262016","pt":1631541708458,"mc":[{"id":"1.187594319","rc":[{"batl":[[0,170,36.65]],"ltp":13.5,"tv":73.76,"id":9628382}]}]}
{"op":"mcm","clk":"4231264174","pt":1631541732556,"mc":[{"id":"1.187594319","rc":[{"batb":[[0,1.01,7],[1,1.01,0]],"ltp":13.5,"tv":73.76,"id":9628382}]}]}
{"op":"mcm","clk":"4231264657","pt":1631541737491,"mc":[{"id":"1.187594319","rc":[{"batb":[[0,19.5,10],[1,1.01,7]],"ltp":13.5,"tv":73.76,"id":9628382}]}]}
{"op":"mcm","clk":"4231267356","pt":1631541772333,"mc":[{"id":"1.187594319","rc":[{"batl":[[0,1.28,1429.36]],"ltp":1.08,"tv":1239.48,"id":13310360}]}]}
{"op":"mcm","clk":"4231267781","pt":1631541777847,"mc":[{"id":"1.187594319","rc":[{"batb":[[0,1.01,7],[1,1.01,0]],"ltp":13.5,"tv":73.76,"id":9628382}]}]}
{"op":"mcm","clk":"4231268181","pt":1631541782861,"mc":[{"id":"1.187594319","rc":[{"batb":[[0,16,10],[1,1.01,7]],"ltp":13.5,"tv":73.76,"id":9628382}]}]}
{"op":"mcm","clk":"4231268364","pt":1631541785371,"mc":[{"id":"1.187594319","rc":[{"batl":[[0,1.3,1344.81]],"ltp":1.08,"tv":1239.48,"id":13310360},{"batl":[[0,170,36.65]],"ltp":13.5,"tv":73.76,"id":9628382}]}]}
{"op":"mcm","clk":"4231270829","pt":1631541818534,"mc":[{"id":"1.187594319","rc":[{"batb":[[0,1.01,7],[1,1.01,0]],"ltp":13.5,"tv":73.76,"id":9628382}]}]}
{"op":"mcm","clk":"4231271150","pt":1631541823021,"mc":[{"id":"1.187594319","rc":[{"batb":[[0,19.5,10],[1,1.01,7]],"ltp":13.5,"tv":73.76,"id":9628382}]}]}
{"op":"mcm","clk":"4231275274","pt":1631541875132,"mc":[{"id":"1.187594319","rc":[{"batb":[[0,1.01,7],[1,1.01,0]],"ltp":13.5,"tv":73.76,"id":9628382}]}]}
{"op":"mcm","clk":"4231291582","pt":1631542070254,"mc":[{"id":"1.187594319","rc":[{"batb":[[0,19.5,10],[1,1.01,7]],"ltp":13.5,"tv":73.76,"id":9628382}]}]}
{"op":"mcm","clk":"4231294980","pt":1631542110810,"mc":[{"id":"1.187594319","rc":[{"batb":[[0,1.01,7],[1,1.01,0]],"ltp":13.5,"tv":73.76,"id":9628382}]}]}
{"op":"mcm","clk":"4231295513","pt":1631542117523,"mc":[{"id":"1.187594319","rc":[{"batl":[[0,1.28,1469.32]],"ltp":1.08,"tv":1239.48,"id":13310360}]}]}
{"op":"mcm","clk":"4231304616","pt":1631542223669,"mc":[{"id":"1.187594319","rc":[{"trd":[[1.01,13.99]],"batl":[[0,1.01,10.04],[1,1.28,1469.32]],"ltp":1.01,"tv":1253.47,"id":13310360}],"tv":1327.24}]}
{"op":"mcm","clk":"4231331832","pt":1631542571895,"mc":[{"id":"1.187594319","rc":[{"batl":[[1,1.28,0]],"ltp":1.01,"tv":1253.47,"id":13310360}]}]}
{"op":"mcm","clk":"4231351046","pt":1631542713308,"mc":[{"id":"1.187594319","rc":[{"batl":[[1,1.27,1497.1]],"ltp":1.01,"tv":1253.47,"id":13310360}]}]}
{"op":"mcm","clk":"4231352044","pt":1631542726021,"mc":[{"id":"1.187594319","rc":[{"batl":[[1,1.27,0]],"ltp":1.01,"tv":1253.47,"id":13310360}]}]}
{"op":"mcm","clk":"4231352850","pt":1631542735746,"mc":[{"id":"1.187594319","rc":[{"batl":[[1,1.28,1469.32]],"ltp":1.01,"tv":1253.47,"id":13310360}]}]}
{"op":"mcm","clk":"4231356758","pt":1631542784941,"mc":[{"id":"1.187594319","rc":[{"batl":[[1,1.28,0]],"ltp":1.01,"tv":1253.47,"id":13310360}]}]}
{"op":"mcm","clk":"4231357604","pt":1631542797580,"mc":[{"id":"1.187594319","rc":[{"batl":[[1,1.28,1455.25]],"ltp":1.01,"tv":1253.47,"id":13310360}]}]}
{"op":"mcm","clk":"4231357704","pt":1631542799186,"mc":[{"id":"1.187594319","rc":[{"batl":[[1,1.28,0]],"ltp":1.01,"tv":1253.47,"id":13310360}]}]}
{"op":"mcm","clk":"4231361228","pt":1631542849656,"mc":[{"id":"1.187594319","rc":[{"batb":[[0,19.5,10],[1,1.01,7]],"ltp":13.5,"tv":73.76,"id":9628382}]}]}
{"op":"mcm","clk":"4231361970","pt":1631542859138,"mc":[{"id":"1.187594319","rc":[{"batb":[[0,1.01,7],[1,1.01,0]],"ltp":13.5,"tv":73.76,"id":9628382}]}]}
{"op":"mcm","clk":"4231362364","pt":1631542864075,"mc":[{"id":"1.187594319","rc":[{"batb":[[0,14,10],[1,1.01,7]],"ltp":13.5,"tv":73.76,"id":9628382}]}]}
{"op":"mcm","clk":"4231363311","pt":1631542876180,"mc":[{"id":"1.187594319","rc":[{"trd":[[1.01,34.08]],"batb":[[0,1.02,39.95]],"ltp":1.01,"tv":1273.56,"id":13310360}],"tv":1347.33}]}
{"op":"mcm","clk":"4231363948","pt":1631542884582,"mc":[{"id":"1.187594319","rc":[{"batb":[[0,1.01,100]],"ltp":1.01,"tv":1273.56,"id":13310360}]}]}
{"op":"mcm","clk":"4231363967","pt":1631542884892,"mc":[{"id":"1.187594319","rc":[{"batb":[[0,1.01,200]],"ltp":1.01,"tv":1273.56,"id":13310360}]}]}
{"op":"mcm","clk":"4231364030","pt":1631542885724,"mc":[{"id":"1.187594319","rc":[{"batb":[[0,1.01,250]],"ltp":1.01,"tv":1273.56,"id":13310360}]}]}
{"op":"mcm","clk":"4231368182","pt":1631542942996,"mc":[{"id":"1.187594319","rc":[{"batb":[[0,1.01,7],[1,1.01,0]],"ltp":13.5,"tv":73.76,"id":9628382}]}]}
{"op":"mcm","clk":"4231368500","pt":1631542947538,"mc":[{"id":"1.187594319","rc":[{"batb":[[0,1.01,150]],"ltp":1.01,"tv":1273.56,"id":13310360}]}]}
{"op":"mcm","clk":"4231372198","pt":1631542998194,"mc":[{"id":"1.187594319","rc":[{"batb":[[0,1.01,300]],"ltp":1.01,"tv":1273.56,"id":13310360}]}]}
{"op":"mcm","clk":"4231381933","pt":1631543122276,"mc":[{"id":"1.187594319","rc":[{"batb":[[0,1.02,2.17],[1,1.01,300]],"ltp":1.01,"tv":1273.56,"id":13310360}]}]}
{"op":"mcm","clk":"4231385236","pt":1631543164661,"mc":[{"id":"1.187594319","rc":[{"batb":[[0,1.01,300],[1,1.01,0]],"ltp":1.01,"tv":1273.56,"id":13310360}]}]}
{"op":"mcm","clk":"4231441580","pt":1631543837660,"mc":[{"id":"1.187594319","rc":[{"batl":[[0,1.39,38.32]],"ltp":1.01,"tv":1273.56,"id":13310360}]}]}
{"op":"mcm","clk":"4231476496","pt":1631544270219,"mc":[{"id":"1.187594319","rc":[{"batb":[[0,4,10],[1,1.01,7]],"ltp":13.5,"tv":73.76,"id":9628382}]}]}
{"op":"mcm","clk":"4231485648","pt":1631544395904,"mc":[{"id":"1.187594319","rc":[{"batl":[[0,1.32,38.32]],"ltp":1.01,"tv":1273.56,"id":13310360}]}]}
{"op":"mcm","clk":"4231525984","pt":1631544982750,"mc":[{"id":"1.187594319","rc":[{"batb":[[0,1.02,1.7],[1,1.01,300]],"ltp":1.01,"tv":1273.56,"id":13310360}]}]}
{"op":"mcm","clk":"4231568501","pt":1631545548491,"mc":[{"id":"1.187594319","rc":[{"trd":[[1.01,34.1],[1.08,790.93],[1.09,322.04],[1.11,5.11],[1.21,121.85]],"batb":[[0,1.02,1.71]],"ltp":1.01,"tv":1274.04,"id":13310360},{"trd":[[5.7,16.64],[12,7.1]],"batb":[[0,1.01,7],[1,1.01,0]],"ltp":13.5,"tv":73.79,"id":9628382}],"tv":1347.83}]}
{"op":"mcm","clk":"4231579842","pt":1631545689734,"mc":[{"id":"1.187594319","rc":[{"batl":[[0,1.39,43.5]],"ltp":1.01,"tv":1274.04,"id":13310360}]}]}
{"op":"mcm","clk":"4231861635","pt":1631548956657,"mc":[{"id":"1.187594319","rc":[{"batl":[[0,1.3,5.03],[1,1.39,43.5]],"ltp":1.01,"tv":1274.04,"id":13310360}]}]}
{"op":"mcm","clk":"4231866575","pt":1631549019949,"mc":[{"id":"1.187594319","rc":[{"batl":[[0,1.39,43.5],[1,1.39,0]],"ltp":1.01,"tv":1274.04,"id":13310360}]}]}
{"op":"mcm","clk":"4231866986","pt":1631549025033,"mc":[{"id":"1.187594319","rc":[{"batl":[[0,1.36,5.03],[1,1.39,43.5]],"ltp":1.01,"tv":1274.04,"id":13310360}]}]}
{"op":"mcm","clk":"4231871904","pt":1631549087127,"mc":[{"id":"1.187594319","rc":[{"batb":[[1,1.01,305]],"ltp":1.01,"tv":1274.04,"id":13310360},{"batb":[[0,1.01,12]],"ltp":13.5,"tv":73.79,"id":9628382}]}]}
{"op":"mcm","clk":"4231886066","pt":1631549247663,"mc":[{"id":"1.187594319","rc":[{"trd":[[1.36,1.37]],"batl":[[0,1.36,3.65]],"ltp":1.36,"tv":1275.41,"id":13310360},{"trd":[[3.75,0.5]],"ltp":3.75,"tv":74.29,"id":9628382}],"tv":1349.7}]}
{"op":"mcm","clk":"4231897061","pt":1631549382863,"mc":[{"id":"1.187594319","rc":[{"batl":[[1,1.39,0]],"ltp":1.36,"tv":1275.41,"id":13310360}]}]}
{"op":"mcm","clk":"4231897490","pt":1631549387978,"mc":[{"id":"1.187594319","rc":[{"batl":[[0,1.35,43.5],[1,1.36,3.65]],"ltp":1.36,"tv":1275.41,"id":13310360}]}]}
{"op":"mcm","clk":"4231899972","pt":1631549415722,"mc":[{"id":"1.187594319","rc":[{"batl":[[0,1.34,5.03],[1,1.35,43.5],[2,1.36,3.65]],"ltp":1.36,"tv":1275.41,"id":13310360}]}]}
{"op":"mcm","clk":"4231921707","pt":1631549671392,"mc":[{"id":"1.187594319","rc":[{"batl":[[0,1.33,61.39],[1,1.34,5.03],[2,1.35,43.5]],"ltp":1.36,"tv":1275.41,"id":13310360}]}]}
{"op":"mcm","clk":"4231930400","pt":1631549765660,"mc":[{"id":"1.187594319","rc":[{"batl":[[0,1.31,47.75],[1,1.33,61.39],[2,1.34,5.03]],"ltp":1.36,"tv":1275.41,"id":13310360}]}]}
{"op":"mcm","clk":"4231931262","pt":1631549774762,"mc":[{"id":"1.187594319","rc":[{"batl":[[2,1.35,43.5]],"ltp":1.36,"tv":1275.41,"id":13310360}]}]}
{"op":"mcm","clk":"4231931696","pt":1631549779849,"mc":[{"id":"1.187594319","rc":[{"batl":[[0,1.31,52.77]],"ltp":1.36,"tv":1275.41,"id":13310360}]}]}
{"op":"mcm","clk":"4231933574","pt":1631549803714,"mc":[{"id":"1.187594319","rc":[{"batl":[[2,1.36,3.65]],"ltp":1.36,"tv":1275.41,"id":13310360}]}]}
{"op":"mcm","clk":"4231933950","pt":1631549808889,"mc":[{"id":"1.187594319","rc":[{"batl":[[0,1.29,43.5],[1,1.31,52.77],[2,1.33,61.39]],"ltp":1.36,"tv":1275.41,"id":13310360}]}]}
{"op":"mcm","clk":"4231944660","pt":1631549927169,"mc":[{"id":"1.187594319","rc":[{"batl":[[1,1.31,5.03]],"ltp":1.36,"tv":1275.41,"id":13310360}]}]}
{"op":"mcm","clk":"4231944757","pt":1631549928373,"mc":[{"id":"1.187594319","rc":[{"batb":[[0,14,10],[1,1.01,12]],"ltp":3.75,"tv":74.29,"id":9628382}]}]}
{"op":"mcm","clk":"4231944910","pt":1631549930262,"mc":[{"id":"1.187594319","rc":[{"batb":[[0,1.01,12],[1,1.01,0]],"ltp":3.75,"tv":74.29,"id":9628382}]}]}
{"op":"mcm","clk":"4231945072","pt":1631549932285,"mc":[{"id":"1.187594319","rc":[{"batl":[[0,1.28,47.75],[1,1.29,43.5],[2,1.31,5.03]],"ltp":1.36,"tv":1275.41,"id":13310360}]}]}
{"op":"mcm","clk":"4231945318","pt":1631549935197,"mc":[{"id":"1.187594319","rc":[{"batb":[[0,11,10],[1,1.01,12]],"ltp":3.75,"tv":74.29,"id":9628382}]}]}
{"op":"mcm","clk":"4231945524","pt":1631549937695,"mc":[{"id":"1.187594319","rc":[{"batb":[[0,1.01,12],[1,1.01,0]],"ltp":3.75,"tv":74.29,"id":9628382}]}]}
{"op":"mcm","clk":"4231946342","pt":1631549948015,"mc":[{"id":"1.187594319","rc":[{"batb":[[0,19.5,10],[1,1.01,12]],"ltp":3.75,"tv":74.29,"id":9628382}]}]}
{"op":"mcm","clk":"4231947374","pt":1631549960453,"mc":[{"id":"1.187594319","rc":[{"batb":[[0,1.01,12],[1,1.01,0]],"ltp":3.75,"tv":74.29,"id":9628382}]}]}
{"op":"mcm","clk":"4231947814","pt":1631549965415,"mc":[{"id":"1.187594319","rc":[{"batb":[[0,14,10],[1,1.01,12]],"ltp":3.75,"tv":74.29,"id":9628382}]}]}
{"op":"mcm","clk":"4231950356","pt":1631549996684,"mc":[{"id":"1.187594319","rc":[{"batl":[[1,1.31,5.03],[2,1.33,61.39]],"ltp":1.36,"tv":1275.41,"id":13310360}]}]}
{"op":"mcm","clk":"4231950832","pt":1631550001783,"mc":[{"id":"1.187594319","rc":[{"batl":[[0,1.27,43.5],[1,1.28,47.75],[2,1.31,5.03]],"ltp":1.36,"tv":1275.41,"id":13310360}]}]}
{"op":"mcm","clk":"4231951465","pt":1631550008011,"mc":[{"id":"1.187594319","rc":[{"batl":[[1,1.31,5.03],[2,1.33,61.39]],"ltp":1.36,"tv":1275.41,"id":13310360}]}]}
{"op":"mcm","clk":"4231951933","pt":1631550013081,"mc":[{"id":"1.187594319","rc":[{"batl":[[0,1.26,47.75],[1,1.27,43.5],[2,1.31,5.03]],"ltp":1.36,"tv":1275.41,"id":13310360}]}]}
{"op":"mcm","clk":"4231952266","pt":1631550016582,"mc":[{"id":"1.187594319","rc":[{"batb":[[0,1.01,12],[1,1.01,0]],"ltp":3.75,"tv":74.29,"id":9628382}]}]}
{"op":"mcm","clk":"4231952737","pt":1631550021633,"mc":[{"id":"1.187594319","rc":[{"batb":[[0,1.02,1501.7]],"ltp":1.36,"tv":1275.41,"id":13310360},{"batb":[[0,10,10],[1,1.01,12]],"ltp":3.75,"tv":74.29,"id":9628382}]}]}
{"op":"mcm","clk":"4231952756","pt":1631550021803,"mc":[{"id":"1.187594319","rc":[{"batb":[[0,1.02,1.71]],"ltp":1.36,"tv":1275.41,"id":13310360},{"batb":[[0,1.01,12],[1,1.01,0]],"ltp":3.75,"tv":74.29,"id":9628382}]}]}
{"op":"mcm","clk":"4231953228","pt":1631550026835,"mc":[{"id":"1.187594319","rc":[{"batb":[[0,19.5,10],[1,1.01,12]],"ltp":3.75,"tv":74.29,"id":9628382}]}]}
{"op":"mcm","clk":"4231955202","pt":1631550047869,"mc":[{"id":"1.187594319","rc":[{"batb":[[0,1.04,1.79],[1,1.02,1.71],[2,1.01,305]],"ltp":1.36,"tv":1275.41,"id":13310360}]}]}
{"op":"mcm","clk":"4231955748","pt":1631550053852,"mc":[{"id":"1.187594319","rc":[{"batb":[[0,1.01,12],[1,1.01,0]],"ltp":3.75,"tv":74.29,"id":9628382}]}]}
{"op":"mcm","clk":"4231956162","pt":1631550058763,"mc":[{"id":"1.187594319","rc":[{"batb":[[0,14,10],[1,1.01,12]],"ltp":3.75,"tv":74.29,"id":9628382}]}]}
{"op":"mcm","clk":"4231958466","pt":1631550085008,"mc":[{"id":"1.187594319","rc":[{"batb":[[0,1.01,12],[1,1.01,0]],"ltp":3.75,"tv":74.29,"id":9628382}]}]}
{"op":"mcm","clk":"4231958872","pt":1631550089928,"mc":[{"id":"1.187594319","rc":[{"batb":[[0,19.5,10],[1,1.01,12]],"ltp":3.75,"tv":74.29,"id":9628382}]}]}
{"op":"mcm","clk":"4231959724","pt":1631550099824,"mc":[{"id":"1.187594319","rc":[{"batl":[[0,1.24,3.66],[1,1.26,47.75],[2,1.27,43.5]],"ltp":1.36,"tv":1275.41,"id":13310360}]}]}
{"op":"mcm","clk":"4231960062","pt":1631550103539,"mc":[{"id":"1.187594319","rc":[{"batb":[[0,1.01,12],[1,1.01,0]],"ltp":3.75,"tv":74.29,"id":9628382}]}]}
{"op":"mcm","clk":"4231960482","pt":1631550108543,"mc":[{"id":"1.187594319","rc":[{"batb":[[0,24,10],[1,1.01,12]],"ltp":3.75,"tv":74.29,"id":9628382}]}]}
{"op":"mcm","clk":"4231961448","pt":1631550119942,"mc":[{"id":"1.187594319","rc":[{"batb":[[0,1.02,1.71],[1,1.01,305],[2,1.01,0]],"batl":[[0,1.26,47.75],[1,1.27,43.5],[2,1.33,61.39]],"ltp":1.36,"tv":1275.41,"id":13310360}]}]}
{"op":"mcm","clk":"4231961777","pt":1631550123863,"mc":[{"id":"1.187594319","rc":[{"batb":[[0,1.01,12],[1,1.01,0]],"ltp":3.75,"tv":74.29,"id":9628382}]}]}
{"op":"mcm","clk":"4231964592","pt":1631550157717,"mc":[{"id":"1.187594319","rc":[{"batl":[[1,1.33,61.39],[2,1.33,0]],"ltp":1.36,"tv":1275.41,"id":13310360}]}]}
{"op":"mcm","clk":"4231965058","pt":1631550163024,"mc":[{"id":"1.187594319","marketDefinition":{"bspMarket":false,"turnInPlayEnabled":true,"persistenceEnabled":true,"marketBaseRate":5.0,"eventId":"30897887","eventTypeId":"2","numberOfWinners":1,"bettingType":"ODDS","marketType":"MATCH_ODDS","marketTime":"2021-09-13T12:40:12.000Z","suspendTime":"2021-09-13T12:40:12.000Z","bspReconciled":false,"complete":true,"inPlay":true,"crossMatching":true,"runnersVoidable":false,"numberOfActiveRunners":2,"betDelay":5,"status":"SUSPENDED","runners":[{"status":"ACTIVE","sortPriority":1,"id":13310360,"name":"W Falkowska"},{"status":"ACTIVE","sortPriority":2,"id":9628382,"name":"A Barnett"}],"regulators":["MR_INT"],"countryCode":"GB","discountAllowed":true,"timezone":"GMT","openDate":"2021-09-13T12:40:12.000Z","version":4030903076,"name":"Match Odds","eventName":"W Falkowska v A Barnett"}}]}
{"op":"mcm","clk":"4231967819","pt":1631550196863,"mc":[{"id":"1.187594319","tv":0.0}]}
{"op":"mcm","clk":"4231967942","pt":1631550198227,"mc":[{"id":"1.187594319","marketDefinition":{"bspMarket":false,"turnInPlayEnabled":true,"persistenceEnabled":true,"marketBaseRate":5.0,"eventId":"30897887","eventTypeId":"2","numberOfWinners":1,"bettingType":"ODDS","marketType":"MATCH_ODDS","marketTime":"2021-09-13T12:40:12.000Z","suspendTime":"2021-09-13T12:40:12.000Z","bspReconciled":false,"complete":true,"inPlay":true,"crossMatching":false,"runnersVoidable":false,"numberOfActiveRunners":0,"betDelay":5,"status":"CLOSED","settledTime":"2021-09-13T16:23:14.000Z","runners":[{"status":"WINNER","sortPriority":1,"id":13310360,"name":"W Falkowska"},{"status":"LOSER","sortPriority":2,"id":9628382,"name":"A Barnett"}],"regulators":["MR_INT"],"countryCode":"GB","discountAllowed":true,"timezone":"GMT","openDate":"2021-09-13T12:40:12.000Z","version":4030905104,"name":"Match Odds","eventName":"W Falkowska v A Barnett"}}]}
