{"op":"mcm","clk":"4215151936","pt":1631535315439,"mc":[{"id":"1.187557985","rc":[{"batl":[[0,1.68,305.72],[1,1.69,241.2],[2,1.7,333.65]],"ltp":1.53,"tv":9434.7,"id":9629022}]}]}
{"op":"mcm","clk":"4215152033","pt":1631535316632,"mc":[{"id":"1.187557985","rc":[{"batb":[[0,2.66,3],[1,2.56,60.84],[2,2.48,145.86]],"ltp":2.92,"tv":15982.13,"id":5300820},{"batb":[[1,1.5,6],[2,1.4,358.6]],"ltp":1.53,"tv":9434.7,"id":9629022}]}]}
{"op":"mcm","clk":"4215152092","pt":1631535317534,"mc":[{"id":"1.187557985","rc":[{"batb":[[0,2.56,60.84],[1,2.48,145.86],[2,2.46,173.89]],"ltp":2.92,"tv":15982.13,"id":5300820},{"batb":[[1,1.4,358.6],[2,1.39,784.82]],"batl":[[0,1.68,473.95],[2,1.7,566.56]],"ltp":1.53,"tv":9434.7,"id":9629022}]}]}
{"op":"mcm","clk":"4215152129","pt":1631535318010,"mc":[{"id":"1.187557985","rc":[{"trd":[[1.51,394.76]],"batb":[[0,1.51,2.31]],"ltp":1.51,"tv":9434.74,"id":9629022}],"tv":25416.87}]}
{"op":"mcm","clk":"4215152310","pt":1631535320217,"mc":[{"id":"1.187557985","rc":[{"trd":[[1.51,394.79]],"batb":[[0,1.51,2.29]],"ltp":1.51,"tv":9434.77,"id":9629022}],"tv":25416.91}]}
{"op":"mcm","clk":"4215152635","pt":1631535324641,"mc":[{"id":"1.187557985","rc":[{"batl":[[0,3.45,144.59]],"ltp":2.92,"tv":15982.13,"id":5300820},{"batb":[[0,1.41,92.89]],"ltp":1.51,"tv":9434.77,"id":9629022}]}]}
{"op":"mcm","clk":"4215152691","pt":1631535325133,"mc":[{"id":"1.187557985","rc":[{"batl":[[0,3.45,140.69]],"ltp":2.92,"tv":15982.13,"id":5300820},{"batb":[[0,1.4,358.6],[1,1.39,784.82],[2,1.38,931.94]],"ltp":1.51,"tv":9434.77,"id":9629022}]}]}
{"op":"mcm","clk":"4215152786","pt":1631535326411,"mc":[{"id":"1.187557985","rc":[{"batl":[[0,3.45,2.32],[1,3.55,3.98],[2,3.8,3.42]],"ltp":2.92,"tv":15982.13,"id":5300820},{"batb":[[0,1.38,233.72],[1,1.37,4],[2,1.36,88.18]],"ltp":1.51,"tv":9434.77,"id":9629022}]}]}
{"op":"mcm","clk":"4215152867","pt":1631535327608,"mc":[{"id":"1.187557985","rc":[{"batb":[[0,1.4,7],[1,1.39,7],[2,1.38,233.72]],"ltp":1.51,"tv":9434.77,"id":9629022}]}]}
{"op":"mcm","clk":"4215152939","pt":1631535328447,"mc":[{"id":"1.187557985","rc":[{"batb":[[1,2.5,1.45],[2,2.48,145.86]],"ltp":2.92,"tv":15982.13,"id":5300820}]}]}
{"op":"mcm","clk":"4215153021","pt":1631535329641,"mc":[{"id":"1.187557985","rc":[{"trd":[[2.56,30.41]],"batb":[[0,2.56,51.98]],"batl":[[0,3.15,126.77],[1,3.45,2.32],[2,3.55,3.98]],"ltp":2.56,"tv":15999.84,"id":5300820},{"batb":[[0,1.63,182.97],[1,1.62,137.83],[2,1.61,1187.88]],"batl":[[0,1.65,6],[1,1.68,473.95],[2,1.69,241.2]],"ltp":1.51,"tv":9434.77,"id":9629022}],"tv":25434.62}]}
{"op":"mcm","clk":"4215153087","pt":1631535330648,"mc":[{"id":"1.187557985","rc":[{"batl":[[0,2.8,11.6],[1,3.15,126.77],[2,3.45,2.32]],"ltp":2.56,"tv":15999.84,"id":5300820},{"batl":[[0,1.68,473.95],[1,1.69,241.2],[2,1.7,566.56]],"ltp":1.51,"tv":9434.77,"id":9629022}]}]}
{"op":"mcm","clk":"4215153201","pt":1631535331647,"mc":[{"id":"1.187557985","rc":[{"trd":[[2.56,38.41]],"batb":[[0,2.56,47.98]],"batl":[[1,3.45,2.32],[2,3.55,3.98]],"ltp":2.56,"tv":16007.84,"id":5300820}],"tv":25442.62}]}
{"op":"mcm","clk":"4215153266","pt":1631535332530,"mc":[{"id":"1.187557985","rc":[{"trd":[[2.56,76.91]],"batb":[[0,2.56,9.48]],"ltp":2.56,"tv":16046.34,"id":5300820},{"trd":[[1.63,189.05],[1.64,17.34],[1.65,59.7]],"batb":[[0,1.63,162.14],[1,1.62,142.83],[2,1.61,1193.88]],"ltp":1.63,"tv":9554.13,"id":9629022}],"tv":25600.48}]}
{"op":"mcm","clk":"4215153330","pt":1631535333663,"mc":[{"id":"1.187557985","rc":[{"batl":[[0,2.58,3],[1,2.8,11.6],[2,3.45,2.32]],"ltp":2.56,"tv":16046.34,"id":5300820},{"trd":[[1.63,274.31]],"batb":[[0,1.63,119.51]],"ltp":1.63,"tv":9639.39,"id":9629022}],"tv":25685.74}]}
{"op":"mcm","clk":"4215153399","pt":1631535334553,"mc":[{"id":"1.187557985","rc":[{"batb":[[1,2.52,19.73],[2,2.5,1.45]],"batl":[[1,2.82,22.23]],"ltp":2.56,"tv":16046.34,"id":5300820},{"batb":[[0,1.64,50.66],[1,1.63,119.51],[2,1.62,142.83]],"ltp":1.63,"tv":9639.39,"id":9629022}]}]}
{"op":"mcm","clk":"4215153466","pt":1631535335649,"mc":[{"id":"1.187557985","rc":[{"batb":[[1,1.63,199.51]],"batl":[[0,1.68,490.55]],"ltp":1.63,"tv":9639.39,"id":9629022}]}]}
{"op":"mcm","clk":"4215153508","pt":1631535336552,"mc":[{"id":"1.187557985","rc":[{"batl":[[1,2.8,153.45],[2,2.82,198.42]],"ltp":2.56,"tv":16046.34,"id":5300820},{"batb":[[1,1.63,226.4]],"batl":[[0,1.68,513.46]],"ltp":1.63,"tv":9639.39,"id":9629022}]}]}
{"op":"mcm","clk":"4215153562","pt":1631535337242,"mc":[{"id":"1.187557985","rc":[{"trd":[[2.56,95.86]],"batb":[[0,2.52,19.73],[1,2.48,145.86],[2,2.46,173.89]],"batl":[[0,2.56,5.53],[1,2.58,3],[2,2.8,153.45]],"ltp":2.56,"tv":16065.29,"id":5300820}],"tv":25704.69}]}
{"op":"mcm","clk":"4215153661","pt":1631535338638,"mc":[{"id":"1.187557985","rc":[{"batb":[[0,2.54,62.01],[1,2.52,19.73],[2,2.48,145.86]],"ltp":2.56,"tv":16065.29,"id":5300820},{"batl":[[0,1.67,30],[1,1.68,513.46],[2,1.69,241.2]],"ltp":1.63,"tv":9639.39,"id":9629022}]}]}
{"op":"mcm","clk":"4215153700","pt":1631535339170,"mc":[{"id":"1.187557985","rc":[{"batl":[[2,2.76,22.61]],"ltp":2.56,"tv":16065.29,"id":5300820}]}]}
{"op":"mcm","clk":"4215153789","pt":1631535340159,"mc":[{"id":"1.187557985","rc":[{"trd":[[2.56,98.74]],"batl":[[0,2.58,3],[1,2.76,22.61],[2,2.8,153.45]],"ltp":2.56,"tv":16068.18,"id":5300820}],"tv":25707.57}]}
{"op":"mcm","clk":"4215154105","pt":1631535343577,"mc":[{"id":"1.187557985","rc":[{"trd":[[2.54,0.06]],"batb":[[0,2.54,61.95]],"ltp":2.54,"tv":16068.24,"id":5300820},{"trd":[[1.65,59.79]],"ltp":1.65,"tv":9639.49,"id":9629022}],"tv":25707.73}]}
{"op":"mcm","clk":"4215154208","pt":1631535344571,"mc":[{"id":"1.187557985","rc":[{"batl":[[0,2.56,15],[1,2.58,3],[2,2.76,22.61]],"ltp":2.54,"tv":16068.24,"id":5300820},{"trd":[[1.64,22.34]],"batb":[[0,1.64,48.16],[2,1.62,137.83]],"ltp":1.64,"tv":9644.49,"id":9629022}],"tv":25712.73}]}
{"op":"mcm","clk":"4215154440","pt":1631535347410,"mc":[{"id":"1.187557985","rc":[{"trd":[[2.54,85.26]],"batb":[[0,2.54,19.34]],"ltp":2.54,"tv":16153.43,"id":5300820}],"tv":25797.92}]}
{"op":"mcm","clk":"4215154748","pt":1631535351588,"mc":[{"id":"1.187557985","rc":[{"trd":[[2.54,89.62]],"batb":[[0,2.54,16.44],[1,2.48,145.86],[2,2.46,173.89]],"batl":[[2,2.8,153.45]],"ltp":2.54,"tv":16157.79,"id":5300820},{"trd":[[1.65,62]],"batl":[[0,1.68,513.46],[1,1.69,241.2],[2,1.7,566.56]],"ltp":1.65,"tv":9646.69,"id":9629022}],"tv":25804.49}]}
{"op":"mcm","clk":"4215155013","pt":1631535354598,"mc":[{"id":"1.187557985","rc":[{"batl":[[2,2.66,23.28]],"ltp":2.54,"tv":16157.79,"id":5300820}]}]}
{"op":"mcm","clk":"4215155052","pt":1631535355017,"mc":[{"id":"1.187557985","rc":[{"batl":[[2,2.8,153.45]],"ltp":2.54,"tv":16157.79,"id":5300820}]}]}
{"op":"mcm","clk":"4215155309","pt":1631535358197,"mc":[{"id":"1.187557985","rc":[{"trd":[[2.56,100.19]],"batl":[[0,2.56,14.28],[2,2.64,23.42]],"ltp":2.56,"tv":16159.24,"id":5300820}],"tv":25805.93}]}
{"op":"mcm","clk":"4215155387","pt":1631535358931,"mc":[{"id":"1.187557985","rc":[{"trd":[[2.46,81.31],[2.48,291.69],[2.54,122.49]],"batb":[[0,2.46,133.24],[1,2.44,237.16],[2,2.42,434.66]],"ltp":2.46,"tv":16565.1,"id":5300820}],"tv":26211.8}]}
{"op":"mcm","clk":"4215155505","pt":1631535360398,"mc":[{"id":"1.187557985","rc":[{"trd":[[2.56,101.63]],"batl":[[0,2.58,3],[1,2.64,23.42],[2,2.8,153.45]],"ltp":2.56,"tv":16566.55,"id":5300820},{"batb":[[1,1.63,146.4]],"ltp":1.65,"tv":9646.69,"id":9629022}],"tv":26213.24}]}
{"op":"mcm","clk":"4215155752","pt":1631535363493,"mc":[{"id":"1.187557985","rc":[{"batl":[[0,2.54,13.56],[1,2.58,3],[2,2.64,23.42]],"ltp":2.56,"tv":16566.55,"id":5300820}]}]}
{"op":"mcm","clk":"4215155769","pt":1631535363702,"mc":[{"id":"1.187557985","rc":[{"batl":[[0,2.58,3],[1,2.64,23.42],[2,2.8,153.45]],"ltp":2.56,"tv":16566.55,"id":5300820}]}]}
{"op":"mcm","clk":"4215155992","pt":1631535366623,"mc":[{"id":"1.187557985","rc":[{"batb":[[0,1.64,20],[1,1.63,4],[2,1.61,3422.08]],"batl":[[0,1.68,305.72],[2,1.7,333.65]],"ltp":1.65,"tv":9646.69,"id":9629022}]}]}
{"op":"mcm","clk":"4215156011","pt":1631535366934,"mc":[{"id":"1.187557985","rc":[{"batl":[[0,2.56,15],[1,2.58,3],[2,2.64,23.42]],"ltp":2.56,"tv":16566.55,"id":5300820},{"batb":[[0,1.63,4],[1,1.61,3422.08],[2,1.6,1152.94]],"ltp":1.65,"tv":9646.69,"id":9629022}]}]}
{"op":"mcm","clk":"4215156142","pt":1631535368548,"mc":[{"id":"1.187557985","rc":[{"batl":[[0,2.54,13.78],[1,2.56,15],[2,2.58,3]],"ltp":2.56,"tv":16566.55,"id":5300820}]}]}
{"op":"mcm","clk":"4215156222","pt":1631535369642,"mc":[{"id":"1.187557985","rc":[{"batl":[[1,2.56,3]],"ltp":2.56,"tv":16566.55,"id":5300820}]}]}
{"op":"mcm","clk":"4215156249","pt":1631535370008,"mc":[{"id":"1.187557985","rc":[{"batb":[[2,2.42,455.78]],"ltp":2.56,"tv":16566.55,"id":5300820},{"batb":[[0,1.64,4],[1,1.63,4],[2,1.61,3422.08]],"ltp":1.65,"tv":9646.69,"id":9629022}]}]}
{"op":"mcm","clk":"4215156449","pt":1631535372613,"mc":[{"id":"1.187557985","rc":[{"batl":[[0,2.52,20.75]],"ltp":2.56,"tv":16566.55,"id":5300820}]}]}
{"op":"mcm","clk":"4215156487","pt":1631535373237,"mc":[{"id":"1.187557985","rc":[{"batl":[[0,2.56,3],[1,2.58,3],[2,2.64,23.42]],"ltp":2.56,"tv":16566.55,"id":5300820},{"batl":[[2,1.7,363.65]],"ltp":1.65,"tv":9646.69,"id":9629022}]}]}
{"op":"mcm","clk":"4215156577","pt":1631535374434,"mc":[{"id":"1.187557985","rc":[{"batb":[[0,1.65,20],[1,1.64,4],[2,1.63,4]],"ltp":1.65,"tv":9646.69,"id":9629022}]}]}
{"op":"mcm","clk":"4215156743","pt":1631535376021,"mc":[{"id":"1.187557985","rc":[{"batl":[[0,2.54,20.75],[1,2.56,3],[2,2.58,3]],"ltp":2.56,"tv":16566.55,"id":5300820},{"batb":[[0,1.65,53]],"ltp":1.65,"tv":9646.69,"id":9629022}]}]}
{"op":"mcm","clk":"4215157027","pt":1631535379539,"mc":[{"id":"1.187557985","rc":[{"batb":[[0,2.42,21.12],[1,2.34,246.92],[2,2.32,201.27]],"batl":[[0,2.64,23.42],[1,2.8,153.45],[2,2.82,198.42]],"ltp":2.56,"tv":16566.55,"id":5300820},{"batb":[[1,1.61,2234.2],[2,1.6,38.72]],"batl":[[0,1.7,30],[1,1.75,251.91],[2,1.76,236.58]],"ltp":1.65,"tv":9646.69,"id":9629022}]}]}
{"op":"mcm","clk":"4215157104","pt":1631535380426,"mc":[{"id":"1.187557985","rc":[{"batb":[[0,2.34,246.92],[1,2.32,201.27],[2,2.3,245.84]],"batl":[[0,2.8,153.45],[1,2.82,198.42],[2,2.84,206.47]],"ltp":2.56,"tv":16566.55,"id":5300820},{"batb":[[1,1.55,342.39],[2,1.54,465.57]],"batl":[[0,1.75,251.91],[1,1.76,236.58],[2,1.77,461.35]],"ltp":1.65,"tv":9646.69,"id":9629022}]}]}
{"op":"mcm","clk":"4215157160","pt":1631535381164,"mc":[{"id":"1.187557985","rc":[{"batb":[[0,1.65,53.45]],"ltp":1.65,"tv":9646.69,"id":9629022}]}]}
{"op":"mcm","clk":"4215157245","pt":1631535382455,"mc":[{"id":"1.187557985","rc":[{"batb":[[1,2.32,280.34]],"batl":[[0,2.46,13.78],[1,2.8,153.45],[2,2.82,198.42]],"ltp":2.56,"tv":16566.55,"id":5300820},{"batb":[[2,1.54,697.92]],"ltp":1.65,"tv":9646.69,"id":9629022}]}]}
{"op":"mcm","clk":"4215157336","pt":1631535383665,"mc":[{"id":"1.187557985","rc":[{"batb":[[0,2.34,173.85]],"ltp":2.56,"tv":16566.55,"id":5300820},{"batl":[[0,1.75,256.91]],"ltp":1.65,"tv":9646.69,"id":9629022}]}]}
{"op":"mcm","clk":"4215157461","pt":1631535385049,"mc":[{"id":"1.187557985","rc":[{"batl":[[0,2.8,153.45],[1,2.82,198.42],[2,2.84,206.47]],"ltp":2.56,"tv":16566.55,"id":5300820},{"batb":[[2,1.54,505.16]],"batl":[[2,1.77,300.68]],"ltp":1.65,"tv":9646.69,"id":9629022}]}]}
{"op":"mcm","clk":"4215157689","pt":1631535388650,"mc":[{"id":"1.187557985","rc":[{"trd":[[1.67,15.32]],"batb":[[0,1.65,53]],"ltp":1.67,"tv":9647.59,"id":9629022}],"tv":26214.14}]}
{"op":"mcm","clk":"4215157883","pt":1631535391586,"mc":[{"id":"1.187557985","rc":[{"batl":[[0,1.74,5],[1,1.75,256.91],[2,1.76,236.58]],"ltp":1.67,"tv":9647.59,"id":9629022}]}]}
{"op":"mcm","clk":"4215157899","pt":1631535391798,"mc":[{"id":"1.187557985","rc":[{"batb":[[2,1.54,697.92]],"ltp":1.67,"tv":9647.59,"id":9629022}]}]}
{"op":"mcm","clk":"4215158361","pt":1631535398204,"mc":[{"id":"1.187557985","rc":[{"batb":[[0,2.34,3],[1,2.32,79.08],[2,1.97,400.31]],"ltp":2.56,"tv":16566.55,"id":5300820},{"batl":[[1,1.75,5],[2,44,7.23]],"ltp":1.67,"tv":9647.59,"id":9629022}]}]}
{"op":"mcm","clk":"4215158470","pt":1631535399406,"mc":[{"id":"1.187557985","rc":[{"batl":[[0,2.84,206.47],[1,2.86,5.25],[2,3.1,4.05]],"ltp":2.56,"tv":16566.55,"id":5300820},{"trd":[[1.65,168]],"batb":[[0,1.54,697.92],[1,1.53,486.61],[2,1.48,87.26]],"ltp":1.65,"tv":9753.59,"id":9629022}],"tv":26320.14}]}
{"op":"mcm","clk":"4215158556","pt":1631535400665,"mc":[{"id":"1.187557985","rc":[{"batb":[[0,2.62,2530.48],[1,2.6,448.48],[2,2.58,448.48]],"ltp":2.56,"tv":16566.55,"id":5300820},{"batl":[[2,1.85,10.81]],"ltp":1.65,"tv":9753.59,"id":9629022}]}]}
{"op":"mcm","clk":"4215158630","pt":1631535401599,"mc":[{"id":"1.187557985","rc":[{"batb":[[0,2.7,52.05],[1,2.62,1223.66],[2,2.6,448.48]],"ltp":2.56,"tv":16566.55,"id":5300820},{"batb":[[2,1.52,10.49]],"batl":[[0,1.58,137.26],[1,1.59,146.74],[2,1.68,9.49]],"ltp":1.65,"tv":9753.59,"id":9629022}]}]}
{"op":"mcm","clk":"4215158719","pt":1631535402605,"mc":[{"id":"1.187557985","rc":[{"trd":[[2.72,8.33]],"batl":[[0,2.82,3],[1,2.84,206.47],[2,2.86,5.25]],"ltp":2.72,"tv":16574.88,"id":5300820},{"trd":[[1.58,94.46]],"batb":[[0,1.55,6],[1,1.54,702.92],[2,1.53,486.61]],"batl":[[0,1.59,146.74],[1,1.68,9.49],[2,1.7,4.69]],"ltp":1.58,"tv":9767.93,"id":9629022}],"tv":26342.81}]}
{"op":"mcm","clk":"4215158919","pt":1631535405580,"mc":[{"id":"1.187557985","rc":[{"batl":[[0,2.78,21.91],[1,2.82,3],[2,2.84,206.47]],"ltp":2.72,"tv":16574.88,"id":5300820},{"batl":[[0,1.59,273.93],[1,1.6,142.71],[2,1.63,30]],"ltp":1.58,"tv":9767.93,"id":9629022}]}]}
{"op":"mcm","clk":"4215158968","pt":1631535406208,"mc":[{"id":"1.187557985","rc":[{"trd":[[2.7,22.12]],"batb":[[0,2.7,50.79]],"batl":[[0,2.78,5.05]],"ltp":2.7,"tv":16577.39,"id":5300820},{"trd":[[1.59,922.48]],"batb":[[0,1.56,30],[1,1.55,6],[2,1.54,702.92]],"batl":[[0,1.59,271.8],[2,1.68,9.49]],"ltp":1.59,"tv":9772.19,"id":9629022}],"tv":26349.58}]}
{"op":"mcm","clk":"4215159226","pt":1631535409512,"mc":[{"id":"1.187557985","rc":[{"batb":[[1,2.64,18.29],[2,2.62,1223.66]],"ltp":2.7,"tv":16577.39,"id":5300820},{"batl":[[2,1.61,30]],"ltp":1.59,"tv":9772.19,"id":9629022}]}]}
{"op":"mcm","clk":"4215159387","pt":1631535412221,"mc":[{"id":"1.187557985","rc":[{"batb":[[0,1.56,88]],"ltp":1.59,"tv":9772.19,"id":9629022}]}]}
{"op":"mcm","clk":"4215159453","pt":1631535413528,"mc":[{"id":"1.187557985","rc":[{"batb":[[0,2.64,18.29],[1,2.5,64.69],[2,2.46,3.93]],"batl":[[0,2.78,1.45],[1,2.9,21.76],[2,3.05,4.7]],"ltp":2.7,"tv":16577.39,"id":5300820},{"batb":[[0,1.56,58],[1,1.52,41.6],[2,1.49,95.01]],"batl":[[0,1.61,30],[1,1.73,4],[2,44,7.23]],"ltp":1.59,"tv":9772.19,"id":9629022}]}]}
{"op":"mcm","clk":"4215159545","pt":1631535414625,"mc":[{"id":"1.187557985","rc":[{"batb":[[0,2.5,64.69],[1,2.46,3.93],[2,2.36,4]],"batl":[[0,2.7,2.32],[1,2.78,1.45],[2,3.25,4.58]],"ltp":2.7,"tv":16577.39,"id":5300820},{"batb":[[0,1.46,188.45],[1,1.45,93.81],[2,1.37,4]],"batl":[[0,1.73,4],[1,44,7.23],[2,990,0.01]],"ltp":1.59,"tv":9772.19,"id":9629022}]}]}
{"op":"mcm","clk":"4215159614","pt":1631535415514,"mc":[{"id":"1.187557985","rc":[{"batl":[[1,3.25,4.58],[2,3.45,2.32]],"ltp":2.7,"tv":16577.39,"id":5300820}]}]}
{"op":"mcm","clk":"4215159680","pt":1631535416413,"mc":[{"id":"1.187557985","rc":[{"batb":[[0,1.59,1.39],[1,1.46,188.45],[2,1.45,93.81]],"ltp":1.59,"tv":9772.19,"id":9629022}]}]}
{"op":"mcm","clk":"4215159740","pt":1631535417337,"mc":[{"id":"1.187557985","rc":[{"batb":[[1,1.5,15],[2,1.46,188.45]],"ltp":1.59,"tv":9772.19,"id":9629022}]}]}
{"op":"mcm","clk":"4215159950","pt":1631535419635,"mc":[{"id":"1.187557985","rc":[{"trd":[[2.7,24.44]],"batb":[[2,1.97,400.31]],"batl":[[0,2.78,20.75]],"ltp":2.7,"tv":16579.71,"id":5300820},{"trd":[[1.58,98.43],[1.59,925.26]],"batb":[[0,1.56,21.33]],"batl":[[0,1.59,20.89]],"ltp":1.58,"tv":9778.94,"id":9629022}],"tv":26358.66}]}
{"op":"mcm","clk":"4215160035","pt":1631535420627,"mc":[{"id":"1.187557985","rc":[{"batl":[[0,3.05,4.7]],"ltp":2.7,"tv":16579.71,"id":5300820},{"batb":[[0,1.5,15],[1,1.49,90.01]],"batl":[[0,44,7.23],[1,990,0.01],[2,990,0]],"ltp":1.58,"tv":9778.94,"id":9629022}]}]}
{"op":"mcm","clk":"4215160051","pt":1631535420837,"mc":[{"id":"1.187557985","rc":[{"batl":[[0,3.25,4.58],[1,3.45,2.32],[2,3.9,160.43]],"ltp":2.7,"tv":16579.71,"id":5300820},{"batb":[[1,1.46,188.45],[2,1.45,93.81]],"ltp":1.58,"tv":9778.94,"id":9629022}]}]}
{"op":"mcm","clk":"4215160310","pt":1631535424322,"mc":[{"id":"1.187557985","rc":[{"batb":[[1,1.46,376.18],[2,1.45,306.51]],"batl":[[0,1.67,138.57],[1,1.69,237.99],[2,44,7.23]],"ltp":1.58,"tv":9778.94,"id":9629022}]}]}
{"op":"mcm","clk":"4215160557","pt":1631535427516,"mc":[{"id":"1.187557985","rc":[{"batl":[[0,3.05,4.9],[1,3.25,4.58],[2,3.45,2.32]],"ltp":2.7,"tv":16579.71,"id":5300820},{"batb":[[1,1.49,89.01],[2,1.46,376.18]],"ltp":1.58,"tv":9778.94,"id":9629022}]}]}
{"op":"mcm","clk":"4215160571","pt":1631535427724,"mc":[{"id":"1.187557985","rc":[{"batl":[[0,3.25,4.58],[1,3.45,2.32],[2,3.9,160.43]],"ltp":2.7,"tv":16579.71,"id":5300820},{"batb":[[1,1.46,188.45],[2,1.45,93.81]],"ltp":1.58,"tv":9778.94,"id":9629022}]}]}
{"op":"mcm","clk":"4215160686","pt":1631535429325,"mc":[{"id":"1.187557985","rc":[{"batl":[[2,990,0.01]],"ltp":2.7,"tv":16579.71,"id":5300820}]}]}
{"op":"mcm","clk":"4215160782","pt":1631535430629,"mc":[{"id":"1.187557985","rc":[{"trd":[[2.5,17.55]],"batb":[[0,2.5,55.91],[2,2.44,1567.62]],"batl":[[0,2.64,17.68],[1,2.66,1437.96],[2,2.68,1395.68]],"ltp":2.5,"tv":16597.26,"id":5300820},{"batb":[[0,1.62,3.97],[1,1.61,87.09],[2,1.58,10.09]],"batl":[[2,1.76,9.06]],"ltp":1.58,"tv":9778.94,"id":9629022}],"tv":26376.2}]}
{"op":"mcm","clk":"4215160840","pt":1631535431516,"mc":[{"id":"1.187557985","rc":[{"batb":[[2,2.44,431.1]],"batl":[[1,2.66,718.98],[2,2.68,697.84]],"ltp":2.5,"tv":16597.26,"id":5300820},{"batb":[[0,1.62,359.37],[1,1.61,228.29]],"ltp":1.58,"tv":9778.94,"id":9629022}]}]}
{"op":"mcm","clk":"4215160918","pt":1631535432446,"mc":[{"id":"1.187557985","rc":[{"batb":[[2,2.44,451.93]],"batl":[[2,2.68,720.98]],"ltp":2.5,"tv":16597.26,"id":5300820},{"batb":[[2,1.59,39.05]],"batl":[[2,1.7,30]],"ltp":1.58,"tv":9778.94,"id":9629022}]}]}
{"op":"mcm","clk":"4215161010","pt":1631535433644,"mc":[{"id":"1.187557985","rc":[{"batl":[[0,2.6,4],[1,2.64,21.68],[2,2.66,718.98]],"ltp":2.5,"tv":16597.26,"id":5300820},{"batb":[[0,1.63,5],[1,1.62,364.37],[2,1.61,228.29]],"ltp":1.58,"tv":9778.94,"id":9629022}]}]}
{"op":"mcm","clk":"4215161135","pt":1631535435632,"mc":[{"id":"1.187557985","rc":[{"trd":[[2.5,20.28]],"batb":[[0,2.5,54.54]],"ltp":2.5,"tv":16599.99,"id":5300820},{"trd":[[1.67,19.36]],"batl":[[0,1.67,136.55],[1,1.68,121.03],[2,1.69,237.99]],"ltp":1.67,"tv":9782.98,"id":9629022}],"tv":26382.98}]}
{"op":"mcm","clk":"4215161170","pt":1631535436247,"mc":[{"id":"1.187557985","rc":[{"batl":[[1,1.69,237.99],[2,1.7,30]],"ltp":1.67,"tv":9782.98,"id":9629022}]}]}
{"op":"mcm","clk":"4215161247","pt":1631535437355,"mc":[{"id":"1.187557985","rc":[{"batl":[[0,2.58,3],[1,2.6,4],[2,2.64,21.68]],"ltp":2.5,"tv":16599.99,"id":5300820}]}]}
{"op":"mcm","clk":"4215161345","pt":1631535438657,"mc":[{"id":"1.187557985","rc":[{"batb":[[0,1.64,25],[1,1.63,5],[2,1.62,364.37]],"ltp":1.67,"tv":9782.98,"id":9629022}]}]}
{"op":"mcm","clk":"4215161391","pt":1631535439339,"mc":[{"id":"1.187557985","rc":[{"batb":[[0,1.63,5],[1,1.62,364.37],[2,1.61,228.29]],"ltp":1.67,"tv":9782.98,"id":9629022}]}]}
{"op":"mcm","clk":"4215161633","pt":1631535442562,"mc":[{"id":"1.187557985","rc":[{"trd":[[2.5,47.81]],"batb":[[0,2.5,40.8]],"batl":[[0,2.56,15],[1,2.58,3],[2,2.6,4]],"ltp":2.5,"tv":16627.52,"id":5300820},{"batb":[[1,1.62,360.4]],"ltp":1.67,"tv":9782.98,"id":9629022}],"tv":26410.5}]}
{"op":"mcm","clk":"4215161776","pt":1631535444657,"mc":[{"id":"1.187557985","rc":[{"trd":[[2.56,131.63],[2.58,97]],"batb":[[0,2.58,33.11],[1,2.5,40.8],[2,2.46,3.93]],"batl":[[0,2.6,4],[1,2.64,21.68],[2,2.68,23.14]],"ltp":2.58,"tv":16663.52,"id":5300820}],"tv":26446.5}]}
{"op":"mcm","clk":"4215161948","pt":1631535445618,"mc":[{"id":"1.187557985","rc":[{"trd":[[2.58,115.99]],"batb":[[0,2.58,14.11],[1,2.46,3.93],[2,2.44,20.83]],"batl":[[0,2.68,23.14],[1,3,4.69],[2,3.25,4.58]],"ltp":2.58,"tv":16682.51,"id":5300820},{"trd":[[1.63,278.96],[1.64,52.22]],"batb":[[0,1.6,38.72],[1,1.53,157.65],[2,1.5,104.38]],"batl":[[0,1.7,30],[1,44,7.23],[2,990,0.01]],"ltp":1.64,"tv":9817.51,"id":9629022}],"tv":26500.02}]}
{"op":"mcm","clk":"4215162100","pt":1631535446450,"mc":[{"id":"1.187557985","rc":[{"batb":[[2,2.32,3]],"batl":[[0,3,4.69],[1,3.25,4.58],[2,3.45,2.32]],"ltp":2.58,"tv":16682.51,"id":5300820},{"batb":[[0,1.53,157.65],[1,1.5,104.38],[2,1.45,93.81]],"batl":[[0,44,7.23],[1,990,0.01],[2,990,0]],"ltp":1.64,"tv":9817.51,"id":9629022}]}]}
{"op":"mcm","clk":"4215162445","pt":1631535448293,"mc":[{"id":"1.187557985","rc":[{"trd":[[2.58,144.22]],"batb":[[0,2.46,3.93],[1,2.32,3],[2,2.3,80.84]],"ltp":2.58,"tv":16710.73,"id":5300820},{"batb":[[1,1.52,287.84],[2,1.51,180.73]],"batl":[[0,1.78,187.51],[1,1.8,192.97],[2,44,7.23]],"ltp":1.64,"tv":9817.51,"id":9629022}],"tv":26528.25}]}
{"op":"mcm","clk":"4215162602","pt":1631535449062,"mc":[{"id":"1.187557985","rc":[{"batb":[[1,1.5,104.38],[2,1.45,93.81]],"ltp":1.64,"tv":9817.51,"id":9629022}]}]}
{"op":"mcm","clk":"4215162777","pt":1631535449883,"mc":[{"id":"1.187557985","rc":[{"batb":[[1,2.3,80.84],[2,1.2,62]],"batl":[[0,2.74,4],[1,2.9,3],[2,3,4.69]],"ltp":2.58,"tv":16710.73,"id":5300820},{"batb":[[0,1.53,162.65],[1,1.52,5],[2,1.5,104.38]],"ltp":1.64,"tv":9817.51,"id":9629022}]}]}
{"op":"mcm","clk":"4215162989","pt":1631535451274,"mc":[{"id":"1.187557985","rc":[{"trd":[[2.46,89.16]],"batb":[[0,2.3,80.84],[1,1.2,62],[2,1.06,2.07]],"ltp":2.46,"tv":16718.59,"id":5300820}],"tv":26536.1}]}
{"op":"mcm","clk":"4215163173","pt":1631535452587,"mc":[{"id":"1.187557985","rc":[{"trd":[[2.3,37.77]],"batb":[[0,2.3,71.57],[1,2.24,853.8],[2,2.22,455.77]],"batl":[[0,2.42,790.3],[1,2.44,767.06],[2,2.46,767.06]],"ltp":2.3,"tv":16737.12,"id":5300820},{"batb":[[0,1.72,173.65],[1,1.7,231.05],[2,1.65,9.66]],"batl":[[2,1.84,8.66]],"ltp":1.64,"tv":9817.51,"id":9629022}],"tv":26554.63}]}
{"op":"mcm","clk":"4215163272","pt":1631535453476,"mc":[{"id":"1.187557985","rc":[{"batb":[[1,2.24,877.99]],"batl":[[2,2.46,770.06]],"ltp":2.3,"tv":16737.12,"id":5300820},{"batb":[[0,1.72,278.84],[2,1.69,5]],"batl":[[1,1.8,222.97]],"ltp":1.64,"tv":9817.51,"id":9629022}]}]}
{"op":"mcm","clk":"4215163364","pt":1631535454466,"mc":[{"id":"1.187557985","rc":[{"batl":[[1,2.44,770.06]],"ltp":2.3,"tv":16737.12,"id":5300820}]}]}
{"op":"mcm","clk":"4215163431","pt":1631535455352,"mc":[{"id":"1.187557985","rc":[{"batl":[[0,2.38,4],[1,2.4,4],[2,2.42,790.3]],"ltp":2.3,"tv":16737.12,"id":5300820},{"batb":[[1,1.71,4],[2,1.7,236.05]],"ltp":1.64,"tv":9817.51,"id":9629022}]}]}
{"op":"mcm","clk":"4215163619","pt":1631535457484,"mc":[{"id":"1.187557985","rc":[{"trd":[[2.3,40.87]],"batb":[[0,2.3,70.02]],"ltp":2.3,"tv":16740.22,"id":5300820},{"trd":[[1.76,4.01]],"ltp":1.76,"tv":9821.52,"id":9629022}],"tv":26561.75}]}
{"op":"mcm","clk":"4215163965","pt":1631535460567,"mc":[{"id":"1.187557985","rc":[{"batl":[[0,2.36,34.89],[1,2.38,4],[2,2.4,4]],"ltp":2.3,"tv":16740.22,"id":5300820}]}]}
{"op":"mcm","clk":"4215164929","pt":1631535466314,"mc":[{"id":"1.187557985","rc":[{"batl":[[2,2.42,790.3]],"ltp":2.3,"tv":16740.22,"id":5300820},{"batb":[[0,1.73,35.97],[1,1.72,278.84],[2,1.71,4]],"ltp":1.76,"tv":9821.52,"id":9629022}]}]}
{"op":"mcm","clk":"4215165159","pt":1631535467577,"mc":[{"id":"1.187557985","rc":[{"batb":[[0,2.24,24.19],[1,2.18,4],[2,2.14,98.83]],"batl":[[0,2.44,25],[1,2.5,5.91],[2,2.6,5.96]],"ltp":2.3,"tv":16740.22,"id":5300820},{"batb":[[0,1.69,36.11],[1,1.67,77.47],[2,1.63,71.23]],"batl":[[0,1.8,30],[1,990,0.01],[2,1.84,0]],"ltp":1.76,"tv":9821.52,"id":9629022}]}]}
{"op":"mcm","clk":"4215165279","pt":1631535468388,"mc":[{"id":"1.187557985","rc":[{"batb":[[0,2.18,4],[1,2.14,98.83],[2,2.1,1.45]],"batl":[[0,2.5,5.91],[1,2.6,5.96],[2,2.62,5.25]],"ltp":2.3,"tv":16740.22,"id":5300820},{"batb":[[0,1.67,77.47],[1,1.63,71.23],[2,1.62,202.74]],"batl":[[0,990,0.01],[1,990,0]],"ltp":1.76,"tv":9821.52,"id":9629022}]}]}
{"op":"mcm","clk":"4215165473","pt":1631535469585,"mc":[{"id":"1.187557985","rc":[{"batb":[[1,2.16,3],[2,2.14,98.83]],"batl":[[0,2.6,5.96],[1,2.74,5.48],[2,3,4.69]],"ltp":2.3,"tv":16740.22,"id":5300820},{"batb":[[0,1.63,71.23],[1,1.62,128.2],[2,1.58,74.06]],"batl":[[0,1.76,2.5],[1,990,0.01]],"ltp":1.76,"tv":9821.52,"id":9629022}]}]}
{"op":"mcm","clk":"4215165645","pt":1631535470613,"mc":[{"id":"1.187557985","rc":[{"batl":[[0,990,0.01],[1,990,0]],"ltp":1.76,"tv":9821.52,"id":9629022}]}]}
{"op":"mcm","clk":"4215165688","pt":1631535470798,"mc":[{"id":"1.187557985","rc":[{"batb":[[1,1.62,264.67],[2,1.61,140.82]],"batl":[[0,1.88,116.48],[1,1.9,163.02],[2,990,0.01]],"ltp":1.76,"tv":9821.52,"id":9629022}]}]}
{"op":"mcm","clk":"4215165931","pt":1631535472208,"mc":[{"id":"1.187557985","rc":[{"batl":[[0,2.54,3],[1,2.6,9.96],[2,2.74,5.48]],"ltp":2.3,"tv":16740.22,"id":5300820},{"batb":[[0,1.63,75.23],[1,1.62,269.67]],"batl":[[0,1.85,5],[1,1.88,116.48],[2,1.9,163.02]],"ltp":1.76,"tv":9821.52,"id":9629022}]}]}
{"op":"mcm","clk":"4215166390","pt":1631535475419,"mc":[{"id":"1.187557985","rc":[{"batl":[[0,2.5,6.23],[1,2.54,3],[2,2.6,9.96]],"ltp":2.3,"tv":16740.22,"id":5300820},{"batb":[[0,1.67,80.47],[1,1.64,6],[2,1.63,75.23]],"ltp":1.76,"tv":9821.52,"id":9629022}]}]}
{"op":"mcm","clk":"4215166465","pt":1631535475902,"mc":[{"id":"1.187557985","rc":[{"batb":[[0,2.14,98.83],[1,2.1,1.45],[2,1.2,62]],"batl":[[0,2.6,5.96],[1,2.74,5.48],[2,3,4.69]],"ltp":2.3,"tv":16740.22,"id":5300820},{"batb":[[0,1.63,71.23],[1,1.62,264.67],[2,1.61,140.82]],"batl":[[0,1.88,116.48],[1,1.9,163.02],[2,990,0.01]],"ltp":1.76,"tv":9821.52,"id":9629022}]}]}
{"op":"mcm","clk":"4215166753","pt":1631535478227,"mc":[{"id":"1.187557985","rc":[{"batb":[[1,1.62,128.2],[2,1.58,74.06]],"batl":[[0,990,0.01],[1,1.9,0],[2,990,0]],"ltp":1.76,"tv":9821.52,"id":9629022}]}]}
{"op":"mcm","clk":"4215167333","pt":1631535482615,"mc":[{"id":"1.187557985","rc":[{"trd":[[2.14,19.25]],"batb":[[0,2.14,89.2],[1,2.1,1822.87],[2,2.08,1767.86]],"batl":[[0,2.26,1692.48],[1,2.28,1663.29],[2,2.3,1642.7]],"ltp":2.14,"tv":16759.47,"id":5300820},{"batb":[[0,1.82,156.03],[1,1.8,190.66],[2,1.79,78.31]],"batl":[[0,1.88,116.48],[1,1.9,163.02],[2,1.92,8.31]],"ltp":1.76,"tv":9821.52,"id":9629022}],"tv":26580.99}]}
{"op":"mcm","clk":"4215167485","pt":1631535483616,"mc":[{"id":"1.187557985","rc":[{"batb":[[1,2.1,502.34],[2,2.08,486.17]],"batl":[[0,2.26,846.24],[1,2.28,841.93],[2,2.3,821.34]],"ltp":2.14,"tv":16759.47,"id":5300820},{"batb":[[1,1.81,87.78],[2,1.8,190.66]],"ltp":1.76,"tv":9821.52,"id":9629022}]}]}
{"op":"mcm","clk":"4215167605","pt":1631535484621,"mc":[{"id":"1.187557985","rc":[{"batb":[[2,2.08,513.94]],"batl":[[1,2.28,868.44]],"ltp":2.14,"tv":16759.47,"id":5300820}]}]}
{"op":"mcm","clk":"4215167738","pt":1631535485621,"mc":[{"id":"1.187557985","rc":[{"batl":[[0,2.24,3],[1,2.26,846.24],[2,2.28,872.44]],"ltp":2.14,"tv":16759.47,"id":5300820},{"batb":[[2,1.8,195.66]],"ltp":1.76,"tv":9821.52,"id":9629022}]}]}
{"op":"mcm","clk":"4215167840","pt":1631535486422,"mc":[{"id":"1.187557985","rc":[{"trd":[[2.14,197.6]],"batb":[[0,2.1,502.34],[1,2.08,513.94],[2,2.06,486.17]],"batl":[[0,2.14,10.85],[1,2.24,3],[2,2.26,846.24]],"ltp":2.14,"tv":16937.82,"id":5300820},{"batl":[[2,1.92,34.53]],"ltp":1.76,"tv":9821.52,"id":9629022}],"tv":26759.35}]}
{"op":"mcm","clk":"4215167978","pt":1631535487529,"mc":[{"id":"1.187557985","rc":[{"trd":[[2.14,208.45]],"batl":[[0,2.24,3],[1,2.26,846.24],[2,2.28,845.93]],"ltp":2.14,"tv":16948.67,"id":5300820},{"trd":[[1.87,12.42],[1.88,51.75]],"batl":[[0,1.88,114.73]],"ltp":1.87,"tv":9837.44,"id":9629022}],"tv":26786.11}]}
{"op":"mcm","clk":"4215168125","pt":1631535488628,"mc":[{"id":"1.187557985","rc":[{"batb":[[0,2.1,500.89]],"ltp":2.14,"tv":16948.67,"id":5300820},{"batb":[[0,1.83,28.7],[1,1.82,156.03],[2,1.81,87.78]],"ltp":1.87,"tv":9837.44,"id":9629022}]}]}
{"op":"mcm","clk":"4215168244","pt":1631535489620,"mc":[{"id":"1.187557985","rc":[{"batb":[[2,2.06,708.33]],"ltp":2.14,"tv":16948.67,"id":5300820},{"trd":[[1.83,5]],"batb":[[0,1.83,26.2]],"ltp":1.83,"tv":9842.44,"id":9629022}],"tv":26791.11}]}
{"op":"mcm","clk":"4215168343","pt":1631535490617,"mc":[{"id":"1.187557985","rc":[{"batl":[[1,2.26,872.96]],"ltp":2.14,"tv":16948.67,"id":5300820}]}]}
{"op":"mcm","clk":"4215168435","pt":1631535491509,"mc":[{"id":"1.187557985","rc":[{"batb":[[0,2.14,1.45],[1,2.1,500.89],[2,2.08,513.94]],"batl":[[0,2.22,36.22],[1,2.24,3],[2,2.26,872.96]],"ltp":2.14,"tv":16948.67,"id":5300820}]}]}
{"op":"mcm","clk":"4215168482","pt":1631535491925,"mc":[{"id":"1.187557985","rc":[{"batl":[[0,2.22,15]],"ltp":2.14,"tv":16948.67,"id":5300820}]}]}
{"op":"mcm","clk":"4215168819","pt":1631535495322,"mc":[{"id":"1.187557985","rc":[{"trd":[[1.88,56.4]],"batl":[[0,1.88,112.41]],"ltp":1.88,"tv":9847.08,"id":9629022}],"tv":26795.76}]}
{"op":"mcm","clk":"4215169156","pt":1631535498541,"mc":[{"id":"1.187557985","rc":[{"batb":[[1,2.08,27.77],[2,2.06,222.16]],"batl":[[0,2.26,26.72],[1,2.32,164.2],[2,2.34,193.94]],"ltp":2.14,"tv":16948.67,"id":5300820},{"batb":[[0,1.8,33.54],[1,1.76,364.96],[2,1.75,243.94]],"batl":[[0,1.93,30],[1,1.94,248.05],[2,1.95,204.05]],"ltp":1.88,"tv":9847.08,"id":9629022}]}]}
{"op":"mcm","clk":"4215169217","pt":1631535499438,"mc":[{"id":"1.187557985","rc":[{"batb":[[1,2.06,222.16],[2,2.04,376.67]],"batl":[[0,2.32,164.2],[1,2.34,193.94],[2,2.36,217.32]],"ltp":2.14,"tv":16948.67,"id":5300820},{"batb":[[0,1.76,364.96],[1,1.75,243.94],[2,1.74,492.8]],"batl":[[0,1.94,248.05],[1,1.95,204.05],[2,1.96,295.95]],"ltp":1.88,"tv":9847.08,"id":9629022}]}]}
{"op":"mcm","clk":"4215169385","pt":1631535501613,"mc":[{"id":"1.187557985","rc":[{"batl":[[0,2.26,4],[1,2.32,164.2],[2,2.34,193.94]],"ltp":2.14,"tv":16948.67,"id":5300820},{"batb":[[1,1.75,342.34]],"ltp":1.88,"tv":9847.08,"id":9629022}]}]}
{"op":"mcm","clk":"4215169466","pt":1631535502651,"mc":[{"id":"1.187557985","rc":[{"batb":[[2,2.04,263.71]],"batl":[[1,2.32,167.2]],"ltp":2.14,"tv":16948.67,"id":5300820},{"batb":[[0,1.76,369.96],[1,1.75,347.34],[2,1.74,391.88]],"ltp":1.88,"tv":9847.08,"id":9629022}]}]}
{"op":"mcm","clk":"4215169629","pt":1631535504644,"mc":[{"id":"1.187557985","rc":[{"batl":[[0,2.2,18.63],[1,2.26,4],[2,2.28,4]],"ltp":2.14,"tv":16948.67,"id":5300820},{"batb":[[0,1.83,19.03],[1,1.8,184.44],[2,1.79,5]],"batl":[[0,1.87,208.06],[1,1.89,165.51],[2,1.94,248.05]],"ltp":1.88,"tv":9847.08,"id":9629022}]}]}
{"op":"mcm","clk":"4215169730","pt":1631535505641,"mc":[{"id":"1.187557985","rc":[{"batl":[[0,2.24,20],[2,2.28,10.34]],"ltp":2.14,"tv":16948.67,"id":5300820},{"batb":[[0,1.8,184.44],[1,1.79,77.31],[2,1.78,201.86]],"batl":[[0,1.87,189.33],[2,1.93,41.13]],"ltp":1.88,"tv":9847.08,"id":9629022}]}]}
{"op":"mcm","clk":"4215169901","pt":1631535507541,"mc":[{"id":"1.187557985","rc":[{"batl":[[0,2.26,4],[1,2.28,4],[2,2.32,167.2]],"ltp":2.14,"tv":16948.67,"id":5300820},{"batb":[[0,1.79,5],[1,1.78,4],[2,1.77,4]],"batl":[[0,1.94,248.05],[1,1.95,204.05],[2,1.96,295.95]],"ltp":1.88,"tv":9847.08,"id":9629022}]}]}
{"op":"mcm","clk":"4215170087","pt":1631535509577,"mc":[{"id":"1.187557985","rc":[{"batb":[[0,2.06,222.16],[1,2.04,263.71],[2,2.02,377.86]],"ltp":2.14,"tv":16948.67,"id":5300820}]}]}
{"op":"mcm","clk":"4215170426","pt":1631535513314,"mc":[{"id":"1.187557985","rc":[{"trd":[[2.06,97.52],[2.08,183.54]],"batb":[[0,2.06,193.59]],"ltp":2.06,"tv":17008.69,"id":5300820},{"batl":[[0,1.94,252.05]],"ltp":1.88,"tv":9847.08,"id":9629022}],"tv":26855.77}]}
{"op":"mcm","clk":"4215170541","pt":1631535514428,"mc":[{"id":"1.187557985","rc":[{"batl":[[2,2.32,9.86]],"ltp":2.06,"tv":17008.69,"id":5300820}]}]}
{"op":"mcm","clk":"4215170573","pt":1631535514689,"mc":[{"id":"1.187557985","rc":[{"batl":[[0,2.28,4],[1,2.32,6.86],[2,3.45,2.32]],"ltp":2.06,"tv":17008.69,"id":5300820}]}]}
{"op":"mcm","clk":"4215170756","pt":1631535516590,"mc":[{"id":"1.187557985","rc":[{"trd":[[2.06,117.32]],"batb":[[0,2.06,183.7]],"ltp":2.06,"tv":17028.48,"id":5300820},{"batb":[[0,1.88,2034.58],[1,1.87,1974.74],[2,1.86,1974.74]],"batl":[[0,1.94,248.05]],"ltp":1.88,"tv":9847.08,"id":9629022}],"tv":26875.57}]}
{"op":"mcm","clk":"4215170850","pt":1631535517587,"mc":[{"id":"1.187557985","rc":[{"batl":[[0,2.16,21.47],[1,2.24,20],[2,2.28,4]],"ltp":2.06,"tv":17028.48,"id":5300820},{"batb":[[0,1.9,202.99],[1,1.88,1183.07],[2,1.87,1061.63]],"batl":[[0,1.95,204.05],[1,1.96,295.95],[2,1.97,163.59]],"ltp":1.88,"tv":9847.08,"id":9629022}]}]}
{"op":"mcm","clk":"4215170932","pt":1631535518634,"mc":[{"id":"1.187557985","rc":[{"batl":[[0,2.14,28.09],[1,2.16,21.47],[2,2.26,268.88]],"ltp":2.06,"tv":17028.48,"id":5300820},{"batb":[[1,1.88,1215.05]],"ltp":1.88,"tv":9847.08,"id":9629022}]}]}
{"op":"mcm","clk":"4215171036","pt":1631535519638,"mc":[{"id":"1.187557985","rc":[{"batl":[[2,2.18,4]],"ltp":2.06,"tv":17028.48,"id":5300820}]}]}
{"op":"mcm","clk":"4215171043","pt":1631535519690,"mc":[{"id":"1.187557985","rc":[{"batb":[[1,1.89,5],[2,1.88,1219.05]],"ltp":1.88,"tv":9847.08,"id":9629022}]}]}
{"op":"mcm","clk":"4215171209","pt":1631535521634,"mc":[{"id":"1.187557985","rc":[{"trd":[[1.9,209.35]],"batb":[[0,1.9,133.06]],"ltp":1.9,"tv":10044.7,"id":9629022}],"tv":27073.19}]}
{"op":"mcm","clk":"4215171231","pt":1631535522002,"mc":[{"id":"1.187557985","rc":[{"batb":[[0,1.9,104.44],[2,1.88,1021.3]],"batl":[[2,1.98,8.05]],"ltp":1.9,"tv":10044.7,"id":9629022}]}]}
{"op":"mcm","clk":"4215171463","pt":1631535524439,"mc":[{"id":"1.187557985","rc":[{"batl":[[0,2.12,37.6],[1,2.14,28.09],[2,2.16,21.47]],"ltp":2.06,"tv":17028.48,"id":5300820}]}]}
{"op":"mcm","clk":"4215171562","pt":1631535525342,"mc":[{"id":"1.187557985","rc":[{"trd":[[2.12,22]],"batl":[[0,2.12,26.6]],"ltp":2.12,"tv":17050.48,"id":5300820},{"trd":[[1.9,260.47]],"batb":[[0,1.9,78.88],[1,1.89,193.57]],"batl":[[1,1.96,438.33],[2,1.98,151.94]],"ltp":1.9,"tv":10095.82,"id":9629022}],"tv":27146.31}]}
{"op":"mcm","clk":"4215171648","pt":1631535526134,"mc":[{"id":"1.187557985","rc":[{"batl":[[0,1.91,2.5],[1,1.95,204.05],[2,1.96,438.33]],"ltp":1.9,"tv":10095.82,"id":9629022}]}]}
{"op":"mcm","clk":"4215171805","pt":1631535527621,"mc":[{"id":"1.187557985","rc":[{"trd":[[2.06,119.3],[2.08,185.84]],"batb":[[0,2.06,182.71]],"ltp":2.06,"tv":17054.76,"id":5300820},{"trd":[[1.91,7.14],[1.95,3.48]],"batl":[[0,1.95,202.31],[1,1.96,438.33],[2,1.98,151.94]],"ltp":1.95,"tv":10101.8,"id":9629022}],"tv":27156.56}]}
{"op":"mcm","clk":"4215171897","pt":1631535528564,"mc":[{"id":"1.187557985","rc":[{"trd":[[1.9,296.69]],"batb":[[0,1.9,60.79]],"ltp":1.9,"tv":10138.01,"id":9629022}],"tv":27192.78}]}
{"op":"mcm","clk":"4215171996","pt":1631535529619,"mc":[{"id":"1.187557985","rc":[{"batl":[[1,2.16,21.47],[2,2.18,11.75]],"ltp":2.06,"tv":17054.76,"id":5300820},{"batb":[[0,1.9,31.91]],"ltp":1.9,"tv":10138.01,"id":9629022}]}]}
{"op":"mcm","clk":"4215172014","pt":1631535530033,"mc":[{"id":"1.187557985","rc":[{"batl":[[0,2.16,21.47],[1,2.18,11.75],[2,2.22,7.25]],"ltp":2.06,"tv":17054.76,"id":5300820},{"batb":[[1,1.89,188.57]],"ltp":1.9,"tv":10138.01,"id":9629022}]}]}
{"op":"mcm","clk":"4215172210","pt":1631535532612,"mc":[{"id":"1.187557985","rc":[{"trd":[[2.06,119.32]],"batb":[[0,2.06,182.7]],"ltp":2.06,"tv":17054.77,"id":5300820}],"tv":27192.79}]}
{"op":"mcm","clk":"4215172223","pt":1631535532820,"mc":[{"id":"1.187557985","rc":[{"batl":[[0,2.12,28.34],[1,2.16,21.47],[2,2.18,11.75]],"ltp":2.06,"tv":17054.77,"id":5300820}]}]}
{"op":"mcm","clk":"4215172439","pt":1631535535429,"mc":[{"id":"1.187557985","rc":[{"batl":[[0,2.16,21.47],[1,2.18,11.75],[2,2.22,7.25]],"ltp":2.06,"tv":17054.77,"id":5300820}]}]}
{"op":"mcm","clk":"4215172559","pt":1631535536633,"mc":[{"id":"1.187557985","rc":[{"trd":[[1.9,296.91]],"batb":[[0,1.9,31.8]],"ltp":1.9,"tv":10138.24,"id":9629022}],"tv":27193.01}]}
{"op":"mcm","clk":"4215172609","pt":1631535537415,"mc":[{"id":"1.187557985","rc":[{"batl":[[0,2.12,31.95],[1,2.16,21.47],[2,2.18,11.75]],"ltp":2.06,"tv":17054.77,"id":5300820}]}]}
{"op":"mcm","clk":"4215172706","pt":1631535538614,"mc":[{"id":"1.187557985","rc":[{"trd":[[2.06,139.32]],"batb":[[0,2.06,172.7]],"batl":[[0,2.14,28.09]],"ltp":2.06,"tv":17074.77,"id":5300820}],"tv":27213.01}]}
{"op":"mcm","clk":"4215173137","pt":1631535543354,"mc":[{"id":"1.187557985","rc":[{"batb":[[0,1.9,32.6]],"ltp":1.9,"tv":10138.24,"id":9629022}]}]}
{"op":"mcm","clk":"4215173200","pt":1631535544342,"mc":[{"id":"1.187557985","rc":[{"batb":[[0,2.04,263.71],[1,2.02,377.86],[2,2,956.26]],"batl":[[0,2.12,31.95],[1,2.14,28.09],[2,2.16,21.47]],"ltp":2.06,"tv":17074.77,"id":5300820}]}]}
{"op":"mcm","clk":"4215173350","pt":1631535546344,"mc":[{"id":"1.187557985","rc":[{"batl":[[0,2.16,21.47],[1,2.18,11.75],[2,2.22,7.25]],"ltp":2.06,"tv":17074.77,"id":5300820}]}]}
{"op":"mcm","clk":"4215173602","pt":1631535549635,"mc":[{"id":"1.187557985","rc":[{"batl":[[0,2.06,15.66],[1,2.12,28.34],[2,2.16,21.47]],"ltp":2.06,"tv":17074.77,"id":5300820}]}]}
{"op":"mcm","clk":"4215173635","pt":1631535550159,"mc":[{"id":"1.187557985","rc":[{"trd":[[2.06,139.5]],"batl":[[0,2.06,15.57]],"ltp":2.06,"tv":17074.96,"id":5300820}],"tv":27213.2}]}
{"op":"mcm","clk":"4215173855","pt":1631535553347,"mc":[{"id":"1.187557985","rc":[{"batl":[[1,2.12,60.29]],"ltp":2.06,"tv":17074.96,"id":5300820}]}]}
{"op":"mcm","clk":"4215173946","pt":1631535554555,"mc":[{"id":"1.187557985","rc":[{"batb":[[2,1.99,26.51]],"ltp":2.06,"tv":17074.96,"id":5300820},{"batb":[[1,1.89,31.79],[2,1.88,4]],"batl":[[1,1.96,295.95],[2,2.02,8.25]],"ltp":1.9,"tv":10138.24,"id":9629022}]}]}
{"op":"mcm","clk":"4215173981","pt":1631535554967,"mc":[{"id":"1.187557985","rc":[{"batb":[[0,1.98,3],[1,1.97,4],[2,1.93,68.12]],"batl":[[1,2.12,28.34],[2,3.45,2.32]],"ltp":2.06,"tv":17074.96,"id":5300820},{"batb":[[0,1.89,32.59],[1,1.81,87.45],[2,1.8,66.33]],"batl":[[0,2.08,8.94],[1,990,0.01],[2,2.02,0]],"ltp":1.9,"tv":10138.24,"id":9629022}]}]}
{"op":"mcm","clk":"4215174129","pt":1631535556456,"mc":[{"id":"1.187557985","rc":[{"trd":[[2.06,141.38]],"batl":[[0,2.06,13.69],[1,3.45,2.32],[2,990,0.01]],"ltp":2.06,"tv":17076.84,"id":5300820},{"trd":[[1.94,39.91]],"batb":[[0,1.81,88.24],[1,1.8,66.33],[2,1.5,15]],"ltp":1.94,"tv":10140.24,"id":9629022}],"tv":27217.08}]}
{"op":"mcm","clk":"4215174180","pt":1631535556971,"mc":[{"id":"1.187557985","rc":[{"trd":[[2.06,153.41]],"batl":[[0,2.06,1.66]],"ltp":2.06,"tv":17088.87,"id":5300820},{"trd":[[1.94,52.69]],"batb":[[1,1.8,248.17],[2,1.78,197.87]],"batl":[[0,2.08,111.11],[1,2.1,121.15],[2,990,0.01]],"ltp":1.94,"tv":10153.01,"id":9629022}],"tv":27241.89}]}
{"op":"mcm","clk":"4215174307","pt":1631535558575,"mc":[{"id":"1.187557985","rc":[{"batb":[[2,1.92,68.37]],"batl":[[1,2.26,7.75],[2,3.45,2.32]],"ltp":2.06,"tv":17088.87,"id":5300820},{"batl":[[0,2.04,3],[1,2.08,111.11],[2,2.1,121.15]],"ltp":1.94,"tv":10153.01,"id":9629022}]}]}
{"op":"mcm","clk":"4215174328","pt":1631535558787,"mc":[{"id":"1.187557985","rc":[{"batb":[[1,1.8,66.33],[2,1.5,15]],"batl":[[1,2.08,8.94],[2,990,0.01]],"ltp":1.94,"tv":10153.01,"id":9629022}]}]}
{"op":"mcm","clk":"4215174591","pt":1631535561580,"mc":[{"id":"1.187557985","rc":[{"trd":[[2.06,155.07]],"batb":[[1,1.92,68.37],[2,1.2,62]],"batl":[[0,2.2,461.54]],"ltp":2.06,"tv":17090.53,"id":5300820},{"trd":[[1.92,1.59],[1.94,54.45]],"batb":[[0,1.81,87.45]],"batl":[[0,1.9,23],[1,2.04,3],[2,2.08,8.94]],"ltp":1.92,"tv":10156.37,"id":9629022}],"tv":27246.9}]}
{"op":"mcm","clk":"4215174638","pt":1631535561987,"mc":[{"id":"1.187557985","rc":[{"batl":[[0,2.26,7.75],[1,3.45,2.32],[2,990,0.01]],"ltp":2.06,"tv":17090.53,"id":5300820},{"trd":[[1.9,342.9]],"batb":[[0,1.91,172.41],[1,1.89,163.16],[2,1.81,87.45]],"batl":[[0,1.98,113.19],[1,2,139.69],[2,2.04,3]],"ltp":1.9,"tv":10202.35,"id":9629022}],"tv":27292.89}]}
{"op":"mcm","clk":"4215174772","pt":1631535563464,"mc":[{"id":"1.187557985","rc":[{"batb":[[0,1.98,3.09]],"ltp":2.06,"tv":17090.53,"id":5300820},{"batl":[[0,1.94,2],[1,1.98,113.19],[2,2,139.69]],"ltp":1.9,"tv":10202.35,"id":9629022}]}]}
{"op":"mcm","clk":"4215174847","pt":1631535564662,"mc":[{"id":"1.187557985","rc":[{"trd":[[2.02,10.93],[2.06,157.14]],"batb":[[0,1.98,3]],"batl":[[0,2.24,4],[1,2.26,7.75],[2,3.45,2.32]],"ltp":2.02,"tv":17103.53,"id":5300820},{"trd":[[1.94,56.45],[1.98,11.15]],"batb":[[0,1.81,91.45],[1,1.8,71.33],[2,1.5,15]],"batl":[[0,2.04,3],[1,2.08,8.94],[2,990,0.01]],"ltp":1.98,"tv":10215.5,"id":9629022}],"tv":27319.03}]}
{"op":"mcm","clk":"4215174904","pt":1631535565486,"mc":[{"id":"1.187557985","rc":[{"batb":[[1,1.97,5],[2,1.92,68.37]],"batl":[[0,2.24,4.01]],"ltp":2.02,"tv":17103.53,"id":5300820},{"batb":[[0,1.83,4],[1,1.82,4],[2,1.81,91.45]],"ltp":1.98,"tv":10215.5,"id":9629022}]}]}
{"op":"mcm","clk":"4215175045","pt":1631535567484,"mc":[{"id":"1.187557985","rc":[{"batl":[[2,2.1,216.57]],"ltp":1.98,"tv":10215.5,"id":9629022}]}]}
{"op":"mcm","clk":"4215175085","pt":1631535567959,"mc":[{"id":"1.187557985","rc":[{"batl":[[0,2.22,3.01],[1,2.24,4],[2,2.26,7.75]],"ltp":2.02,"tv":17103.53,"id":5300820}]}]}
{"op":"mcm","clk":"4215175260","pt":1631535570189,"mc":[{"id":"1.187557985","rc":[{"trd":[[2.04,50.02]],"batb":[[0,2.1,17.49],[1,1.98,3],[2,1.97,5]],"batl":[[0,2.22,3]],"ltp":2.04,"tv":17103.55,"id":5300820},{"trd":[[1.83,6.48]],"batb":[[0,1.83,3.26]],"batl":[[0,2.02,5],[1,2.04,3],[2,2.08,8.94]],"ltp":1.83,"tv":10216.98,"id":9629022}],"tv":27320.54}]}
{"op":"mcm","clk":"4215175639","pt":1631535575489,"mc":[{"id":"1.187557985","rc":[{"batl":[[0,2.18,6.75],[1,2.22,3],[2,2.24,4]],"ltp":2.04,"tv":17103.55,"id":5300820},{"batb":[[0,1.85,69.37],[1,1.83,3.26],[2,1.82,4]],"ltp":1.83,"tv":10216.98,"id":9629022}]}]}
{"op":"mcm","clk":"4215175744","pt":1631535576593,"mc":[{"id":"1.187557985","rc":[{"batb":[[2,1.92,68.37]],"batl":[[0,2.22,3],[1,2.24,4],[2,2.26,7.75]],"ltp":2.04,"tv":17103.55,"id":5300820},{"batb":[[0,1.83,3.26],[1,1.81,87.45],[2,1.8,248.17]],"ltp":1.83,"tv":10216.98,"id":9629022}]}]}
{"op":"mcm","clk":"4215176003","pt":1631535579510,"mc":[{"id":"1.187557985","rc":[{"batb":[[0,2.1,688.91],[1,2.08,335.71],[2,2.06,335.71]],"batl":[[0,2.26,7.75],[1,3.45,2.32],[2,990,0.01]],"ltp":2.04,"tv":17103.55,"id":5300820},{"batb":[[0,1.81,87.45],[1,1.8,248.17],[2,1.78,197.87]],"batl":[[0,1.87,186.07],[1,1.89,1504.93],[2,1.91,8.35]],"ltp":1.83,"tv":10216.98,"id":9629022}]}]}
{"op":"mcm","clk":"4215176094","pt":1631535580507,"mc":[{"id":"1.187557985","rc":[{"trd":[[2.14,217.97]],"batb":[[0,2.14,99.25],[1,2.1,688.91],[2,2.08,363.48]],"batl":[[1,2.28,26.51],[2,3.45,2.32]],"ltp":2.14,"tv":17113.07,"id":5300820},{"trd":[[1.87,23.31]],"batb":[[2,1.79,33.75]],"batl":[[0,1.87,175.18]],"ltp":1.87,"tv":10227.87,"id":9629022}],"tv":27340.95}]}
{"op":"mcm","clk":"4215176168","pt":1631535581607,"mc":[{"id":"1.187557985","rc":[{"batb":[[1,2.1,718.83],[2,2.08,335.71]],"batl":[[1,3.45,2.32],[2,990,0.01]],"ltp":2.14,"tv":17113.07,"id":5300820},{"batb":[[2,1.78,197.87]],"ltp":1.87,"tv":10227.87,"id":9629022}]}]}
{"op":"mcm","clk":"4215176204","pt":1631535582083,"mc":[{"id":"1.187557985","rc":[{"batl":[[0,2.24,25.38],[1,2.26,7.75],[2,3.45,2.32]],"ltp":2.14,"tv":17113.07,"id":5300820},{"batb":[[0,1.81,116.45],[1,1.8,252.17],[2,1.79,4]],"ltp":1.87,"tv":10227.87,"id":9629022}]}]}
{"op":"mcm","clk":"4215176410","pt":1631535584597,"mc":[{"id":"1.187557985","rc":[{"trd":[[2.14,252.68],[2.2,1.51]],"batb":[[0,2.14,81.88]],"ltp":2.14,"tv":17149.29,"id":5300820},{"trd":[[1.82,5.39]],"ltp":1.82,"tv":10233.26,"id":9629022}],"tv":27382.56}]}
{"op":"mcm","clk":"4215176483","pt":1631535585605,"mc":[{"id":"1.187557985","rc":[{"batb":[[1,2.1,746.1]],"batl":[[0,2.22,6.75],[1,2.24,25.38],[2,2.26,7.75]],"ltp":2.14,"tv":17149.29,"id":5300820},{"batb":[[0,1.83,76.03],[1,1.81,116.45],[2,1.8,252.17]],"ltp":1.82,"tv":10233.26,"id":9629022}]}]}
{"op":"mcm","clk":"4215176495","pt":1631535585803,"mc":[{"id":"1.187557985","rc":[{"batb":[[1,2.1,728.61]],"ltp":2.14,"tv":17149.29,"id":5300820}]}]}
{"op":"mcm","clk":"4215176638","pt":1631535587603,"mc":[{"id":"1.187557985","rc":[{"batl":[[2,1.9,30]],"ltp":1.82,"tv":10233.26,"id":9629022}]}]}
{"op":"mcm","clk":"4215177202","pt":1631535594212,"mc":[{"id":"1.187557985","rc":[{"trd":[[2.14,562.56]],"batb":[[0,2.1,728.61],[1,2.08,335.71],[2,2.06,353.2]],"ltp":2.14,"tv":17459.18,"id":5300820},{"trd":[[1.87,190.58]],"batb":[[2,1.8,70.33]],"batl":[[0,1.89,1339.39],[1,1.9,30],[2,1.91,8.35]],"ltp":1.87,"tv":10400.53,"id":9629022}],"tv":27859.71}]}
{"op":"mcm","clk":"4215177342","pt":1631535595635,"mc":[{"id":"1.187557985","rc":[{"batb":[[0,2.1,27.27],[1,2.06,17.49],[2,2.02,116.65]],"batl":[[0,2.3,6.45],[1,2.32,26.11],[2,3.45,2.32]],"ltp":2.14,"tv":17459.18,"id":5300820},{"batb":[[0,1.8,4],[1,1.77,71.37],[2,1.75,34.64]],"batl":[[0,1.9,30],[1,2.02,5],[2,990,0.01]],"ltp":1.87,"tv":10400.53,"id":9629022}]}]}
{"op":"mcm","clk":"4215177415","pt":1631535596421,"mc":[{"id":"1.187557985","rc":[{"batb":[[0,2.06,17.49],[1,2.02,116.65],[2,1.98,3]],"batl":[[1,3.45,2.32],[2,990,0.01]],"ltp":2.14,"tv":17459.18,"id":5300820},{"batb":[[2,1.74,100.58]],"batl":[[0,2.02,5],[1,990,0.01],[2,990,0]],"ltp":1.87,"tv":10400.53,"id":9629022}]}]}
{"op":"mcm","clk":"4215177491","pt":1631535597429,"mc":[{"id":"1.187557985","rc":[{"batb":[[1,1.79,4],[2,1.77,71.37]],"ltp":1.87,"tv":10400.53,"id":9629022}]}]}
{"op":"mcm","clk":"4215177587","pt":1631535598628,"mc":[{"id":"1.187557985","rc":[{"batb":[[2,2,119.66]],"ltp":2.14,"tv":17459.18,"id":5300820},{"batl":[[0,1.99,157.61],[1,2.02,209.18],[2,990,0.01]],"ltp":1.87,"tv":10400.53,"id":9629022}]}]}
{"op":"mcm","clk":"4215177631","pt":1631535599105,"mc":[{"id":"1.187557985","rc":[{"batb":[[1,2,119.66],[2,1.98,3]],"batl":[[0,2.26,4],[1,2.3,6.45],[2,3.45,2.32]],"ltp":2.14,"tv":17459.18,"id":5300820},{"batl":[[0,2.02,5],[1,990,0.01],[2,990,0]],"ltp":1.87,"tv":10400.53,"id":9629022}]}]}
{"op":"mcm","clk":"4215177876","pt":1631535602220,"mc":[{"id":"1.187557985","rc":[{"batb":[[0,1.83,187.83],[1,1.81,187.12],[2,1.8,4]],"batl":[[0,1.9,159.18],[1,1.92,157.6],[2,2.02,5]],"ltp":1.87,"tv":10400.53,"id":9629022}]}]}
{"op":"mcm","clk":"4215177979","pt":1631535603328,"mc":[{"id":"1.187557985","rc":[{"batb":[[0,2.08,26.35],[1,2.06,17.49],[2,2,119.66]],"batl":[[0,2.24,20],[1,2.26,11.25],[2,2.3,6.45]],"ltp":2.14,"tv":17459.18,"id":5300820},{"batb":[[2,1.8,75.53]],"batl":[[2,2,25]],"ltp":1.87,"tv":10400.53,"id":9629022}]}]}
{"op":"mcm","clk":"4215178271","pt":1631535606617,"mc":[{"id":"1.187557985","rc":[{"batb":[[0,2.06,17.49],[1,2,119.66],[2,1.98,3]],"batl":[[0,2.26,11.25],[1,2.3,6.45],[2,3.45,2.32]],"ltp":2.14,"tv":17459.18,"id":5300820},{"batb":[[0,1.83,29.76],[1,1.8,75.53],[2,1.79,4]],"batl":[[0,2.02,5],[1,990,0.01],[2,2,0]],"ltp":1.87,"tv":10400.53,"id":9629022}]}]}
{"op":"mcm","clk":"4215178292","pt":1631535606825,"mc":[{"id":"1.187557985","rc":[{"batl":[[0,2.26,4]],"ltp":2.14,"tv":17459.18,"id":5300820},{"batb":[[0,1.8,4],[1,1.79,4],[2,1.77,71.37]],"ltp":1.87,"tv":10400.53,"id":9629022}]}]}
{"op":"mcm","clk":"4215178503","pt":1631535609548,"mc":[{"id":"1.187557985","rc":[{"trd":[[2.06,177.14]],"batb":[[0,2.06,7.49]],"ltp":2.06,"tv":17479.18,"id":5300820},{"batb":[[1,1.77,71.37],[2,1.75,98.16]],"batl":[[0,1.99,157.61],[1,2.02,209.18],[2,990,0.01]],"ltp":1.87,"tv":10400.53,"id":9629022}],"tv":27879.71}]}
{"op":"mcm","clk":"4215178770","pt":1631535612540,"mc":[{"id":"1.187557985","rc":[{"batb":[[1,1.79,5],[2,1.77,71.37]],"batl":[[0,2.02,5],[1,990,0.01],[2,990,0]],"ltp":1.87,"tv":10400.53,"id":9629022}]}]}
{"op":"mcm","clk":"4215178835","pt":1631535613522,"mc":[{"id":"1.187557985","rc":[{"batl":[[0,2.26,10.75]],"ltp":2.06,"tv":17479.18,"id":5300820},{"batb":[[0,1.8,79.13]],"ltp":1.87,"tv":10400.53,"id":9629022}]}]}
{"op":"mcm","clk":"4215178880","pt":1631535614104,"mc":[{"id":"1.187557985","rc":[{"batb":[[0,2,119.66],[1,1.98,3],[2,1.2,62]],"batl":[[0,2.3,6.45],[1,3.45,2.32],[2,990,0.01]],"ltp":2.06,"tv":17479.18,"id":5300820},{"batb":[[0,1.77,71.37],[1,1.75,98.16],[2,1.74,140.7]],"ltp":1.87,"tv":10400.53,"id":9629022}]}]}
{"op":"mcm","clk":"4215179007","pt":1631535615630,"mc":[{"id":"1.187557985","rc":[{"batl":[[0,1.8,198.6],[1,1.81,1056.62],[2,1.82,1211.39]],"ltp":1.87,"tv":10400.53,"id":9629022}]}]}
{"op":"mcm","clk":"4215179077","pt":1631535616441,"mc":[{"id":"1.187557985","rc":[{"trd":[[2.24,9.26]],"batb":[[0,2.24,111.97],[1,2.12,101.92],[2,2.08,37.45]],"ltp":2.24,"tv":17488.44,"id":5300820},{"trd":[[1.8,11.52]],"batl":[[0,1.8,187.08]],"ltp":1.8,"tv":10412.05,"id":9629022}],"tv":27900.49}]}
{"op":"mcm","clk":"4215179133","pt":1631535617117,"mc":[{"id":"1.187557985","rc":[{"batb":[[2,2.08,40.45]],"ltp":2.24,"tv":17488.44,"id":5300820}]}]}
{"op":"mcm","clk":"4215179317","pt":1631535619615,"mc":[{"id":"1.187557985","rc":[{"batl":[[1,1.81,1086.62]],"ltp":1.8,"tv":10412.05,"id":9629022}]}]}
{"op":"mcm","clk":"4215179374","pt":1631535620405,"mc":[{"id":"1.187557985","rc":[{"trd":[[2.3,48.92]],"batl":[[0,3.45,2.32],[1,990,0.01],[2,990,0]],"ltp":2.3,"tv":17496.48,"id":5300820},{"trd":[[1.76,18.67],[1.77,142.74],[1.8,11.56]],"batb":[[0,1.75,98.16],[1,1.74,140.7],[2,1.72,221.36]],"batl":[[0,1.8,187.06],[1,1.81,1056.62]],"ltp":1.8,"tv":10569.49,"id":9629022}],"tv":28065.97}]}
{"op":"mcm","clk":"4215179500","pt":1631535622340,"mc":[{"id":"1.187557985","rc":[{"batb":[[1,2.16,190.49],[2,2.14,194.17]],"batl":[[0,2.34,6.25],[1,2.38,6.25],[2,2.42,211.6]],"ltp":2.3,"tv":17496.48,"id":5300820},{"batb":[[0,1.75,169.67],[2,1.73,81.13]],"ltp":1.8,"tv":10569.49,"id":9629022}]}]}
{"op":"mcm","clk":"4215179607","pt":1631535623663,"mc":[{"id":"1.187557985","rc":[{"batl":[[2,2.4,41.36]],"ltp":2.3,"tv":17496.48,"id":5300820},{"batl":[[0,1.79,30],[1,1.8,187.06],[2,1.81,1056.62]],"ltp":1.8,"tv":10569.49,"id":9629022}]}]}
{"op":"mcm","clk":"4215179693","pt":1631535624550,"mc":[{"id":"1.187557985","rc":[{"batl":[[1,2.36,5.32],[2,2.38,6.25]],"ltp":2.3,"tv":17496.48,"id":5300820},{"batb":[[1,1.74,177.72]],"ltp":1.8,"tv":10569.49,"id":9629022}]}]}
{"op":"mcm","clk":"4215180230","pt":1631535631532,"mc":[{"id":"1.187557985","rc":[{"batb":[[0,2.24,24.19]],"batl":[[0,2.4,5.94],[1,2.42,211.6],[2,2.44,187.66]],"ltp":2.3,"tv":17496.48,"id":5300820},{"batb":[[0,1.72,37.09],[1,1.71,236.01],[2,1.7,291.91]],"batl":[[1,1.83,2.32],[2,1.87,211.95]],"ltp":1.8,"tv":10569.49,"id":9629022}]}]}
{"op":"mcm","clk":"4215180299","pt":1631535632439,"mc":[{"id":"1.187557985","rc":[{"batb":[[0,2.16,190.49],[1,2.14,194.17],[2,2.12,416.08]],"ltp":2.3,"tv":17496.48,"id":5300820},{"batl":[[0,1.83,2.32],[1,1.87,211.95],[2,1.88,252.09]],"ltp":1.8,"tv":10569.49,"id":9629022}]}]}
{"op":"mcm","clk":"4215180474","pt":1631535634646,"mc":[{"id":"1.187557985","rc":[{"batl":[[0,2.36,6.07],[1,2.4,5.94],[2,2.42,211.6]],"ltp":2.3,"tv":17496.48,"id":5300820},{"batb":[[0,1.74,38.02],[1,1.72,37.09],[2,1.71,236.01]],"batl":[[2,1.88,396.35]],"ltp":1.8,"tv":10569.49,"id":9629022}]}]}
{"op":"mcm","clk":"4215180484","pt":1631535634751,"mc":[{"id":"1.187557985","rc":[{"batl":[[0,2.4,8.94],[1,2.42,211.6],[2,2.44,187.66]],"ltp":2.3,"tv":17496.48,"id":5300820},{"batb":[[0,1.72,42.09],[1,1.71,241.01],[2,1.7,291.91]],"ltp":1.8,"tv":10569.49,"id":9629022}]}]}
{"op":"mcm","clk":"4215180926","pt":1631535640659,"mc":[{"id":"1.187557985","rc":[{"batl":[[2,1.88,252.09]],"ltp":1.8,"tv":10569.49,"id":9629022}]}]}
{"op":"mcm","clk":"4215180992","pt":1631535641455,"mc":[{"id":"1.187557985","rc":[{"batb":[[0,2.12,101.92],[1,2.08,3],[2,2.04,15.36]],"batl":[[0,2.36,5.57],[1,2.4,8.94],[2,2.42,211.6]],"ltp":2.3,"tv":17496.48,"id":5300820},{"batb":[[0,1.74,34.02],[1,1.72,42.09],[2,1.71,241.01]],"batl":[[1,1.94,3],[2,990,0.01]],"ltp":1.8,"tv":10569.49,"id":9629022}]}]}
{"op":"mcm","clk":"4215181013","pt":1631535641667,"mc":[{"id":"1.187557985","rc":[{"batl":[[0,2.4,8.94],[1,2.42,211.6],[2,2.44,187.66]],"ltp":2.3,"tv":17496.48,"id":5300820},{"batb":[[0,1.72,42.09],[1,1.71,241.01],[2,1.7,291.91]],"ltp":1.8,"tv":10569.49,"id":9629022}]}]}
{"op":"mcm","clk":"4215181160","pt":1631535643577,"mc":[{"id":"1.187557985","rc":[{"batl":[[0,2.4,5.94]],"ltp":2.3,"tv":17496.48,"id":5300820},{"batb":[[0,1.72,37.09],[1,1.71,236.01]],"batl":[[0,1.75,2185.72],[1,1.76,2121.44],[2,1.77,2121.44]],"ltp":1.8,"tv":10569.49,"id":9629022}]}]}
{"op":"mcm","clk":"4215181284","pt":1631535644666,"mc":[{"id":"1.187557985","rc":[{"trd":[[2.34,18.03]],"batb":[[0,2.34,68.14],[1,2.24,87.2],[2,2.08,3]],"ltp":2.34,"tv":17514.51,"id":5300820},{"batb":[[1,1.7,291.91],[2,1.69,417.02]],"batl":[[0,1.74,226.28],[1,1.75,1092.86],[2,1.76,1267.42]],"ltp":1.8,"tv":10569.49,"id":9629022}],"tv":28084.0}]}
{"op":"mcm","clk":"4215181359","pt":1631535645571,"mc":[{"id":"1.187557985","rc":[{"batb":[[2,2.14,94.79]],"ltp":2.34,"tv":17514.51,"id":5300820}]}]}
{"op":"mcm","clk":"4215181408","pt":1631535646256,"mc":[{"id":"1.187557985","rc":[{"batb":[[2,2.18,3]],"ltp":2.34,"tv":17514.51,"id":5300820}]}]}
{"op":"mcm","clk":"4215181587","pt":1631535648537,"mc":[{"id":"1.187557985","rc":[{"trd":[[2.34,21.22]],"batb":[[0,2.34,66.54]],"ltp":2.34,"tv":17517.7,"id":5300820},{"trd":[[1.72,120.42],[1.74,4.5]],"batb":[[0,1.7,291.91],[1,1.69,417.02],[2,1.68,177.37]],"batl":[[0,1.72,31.85],[1,1.74,224.03],[2,1.75,1092.86]],"ltp":1.72,"tv":10648.17,"id":9629022}],"tv":28165.87}]}
{"op":"mcm","clk":"4215181672","pt":1631535649553,"mc":[{"id":"1.187557985","rc":[{"batb":[[0,2.36,22.05],[1,2.34,66.54],[2,2.24,87.2]],"ltp":2.34,"tv":17517.7,"id":5300820},{"batl":[[0,1.74,224.03],[1,1.75,1092.86],[2,1.76,1267.42]],"ltp":1.72,"tv":10648.17,"id":9629022}]}]}
{"op":"mcm","clk":"4215181783","pt":1631535651076,"mc":[{"id":"1.187557985","rc":[{"batb":[[2,2.26,167.34]],"batl":[[1,2.42,217.85]],"ltp":2.34,"tv":17517.7,"id":5300820},{"batb":[[0,1.71,39.19],[1,1.7,291.91],[2,1.69,417.02]],"ltp":1.72,"tv":10648.17,"id":9629022}]}]}
{"op":"mcm","clk":"4215181860","pt":1631535652182,"mc":[{"id":"1.187557985","rc":[{"trd":[[1.71,152.94]],"batb":[[0,1.71,9.19],[2,1.69,455.23]],"ltp":1.71,"tv":10708.17,"id":9629022}],"tv":28225.87}]}
{"op":"mcm","clk":"4215182083","pt":1631535655401,"mc":[{"id":"1.187557985","rc":[{"batl":[[0,1.72,4.88],[1,1.73,30],[2,1.74,224.03]],"ltp":1.71,"tv":10708.17,"id":9629022}]}]}
{"op":"mcm","clk":"4215182316","pt":1631535658273,"mc":[{"id":"1.187557985","rc":[{"batb":[[1,2.26,167.34],[2,2.24,308.62]],"batl":[[0,2.46,5.75],[1,2.5,158.9],[2,2.52,229.23]],"ltp":2.34,"tv":17517.7,"id":5300820},{"batb":[[0,1.7,34.52],[1,1.69,38.21],[2,1.67,226.57]],"batl":[[2,1.79,279.07]],"ltp":1.71,"tv":10708.17,"id":9629022}]}]}
{"op":"mcm","clk":"4215182412","pt":1631535659482,"mc":[{"id":"1.187557985","rc":[{"batb":[[0,2.26,167.34],[1,2.24,308.62],[2,2.22,290.03]],"ltp":2.34,"tv":17517.7,"id":5300820},{"batl":[[1,1.79,279.07],[2,1.8,234.55]],"ltp":1.71,"tv":10708.17,"id":9629022}]}]}
{"op":"mcm","clk":"4215182613","pt":1631535661565,"mc":[{"id":"1.187557985","rc":[{"batl":[[0,2.44,5.83],[1,2.46,5.75],[2,2.5,158.9]],"ltp":2.34,"tv":17517.7,"id":5300820},{"batl":[[1,1.79,432.03]],"ltp":1.71,"tv":10708.17,"id":9629022}]}]}
{"op":"mcm","clk":"4215182817","pt":1631535664468,"mc":[{"id":"1.187557985","rc":[{"batb":[[0,2.24,86.69],[1,2.2,7.42],[2,2.18,3]],"ltp":2.34,"tv":17517.7,"id":5300820},{"batl":[[1,1.74,3508.14],[2,1.82,16]],"ltp":1.71,"tv":10708.17,"id":9629022}]}]}
{"op":"mcm","clk":"4215182859","pt":1631535664997,"mc":[{"id":"1.187557985","rc":[{"batl":[[1,1.83,34.82],[2,990,0.01]],"ltp":1.71,"tv":10708.17,"id":9629022}]}]}
{"op":"mcm","clk":"4215182992","pt":1631535666615,"mc":[{"id":"1.187557985","rc":[{"trd":[[1.7,69.04]],"batb":[[0,1.69,38.21],[1,1.67,226.57],[2,1.66,340.73]],"batl":[[0,1.7,2215.48],[1,1.71,2183.82],[2,1.72,2188.7]],"ltp":1.7,"tv":10777.21,"id":9629022}],"tv":28294.91}]}
{"op":"mcm","clk":"4215183067","pt":1631535667615,"mc":[{"id":"1.187557985","rc":[{"trd":[[2.42,17.71],[2.44,5.83]],"batb":[[0,2.42,61.52],[1,2.26,85.02],[2,2.24,86.69]],"batl":[[0,2.46,5.75],[1,2.5,158.9],[2,2.52,229.23]],"ltp":2.42,"tv":17541.23,"id":5300820},{"trd":[[1.69,86.95],[1.7,77.04]],"batb":[[0,1.66,340.73],[1,1.65,457.52],[2,1.64,199.89]],"batl":[[0,1.7,1121],[1,1.71,1091.9],[2,1.72,1096.78]],"ltp":1.7,"tv":10870.05,"id":9629022}],"tv":28411.29}]}
{"op":"mcm","clk":"4215183116","pt":1631535668403,"mc":[{"id":"1.187557985","rc":[{"trd":[[2.42,24.17]],"batb":[[0,2.42,58.29],[1,2.26,157.39],[2,2.2,7.42]],"ltp":2.42,"tv":17547.7,"id":5300820},{"batl":[[1,1.71,1116.3]],"ltp":1.7,"tv":10870.05,"id":9629022}],"tv":28417.75}]}
{"op":"mcm","clk":"4215183266","pt":1631535670505,"mc":[{"id":"1.187557985","rc":[{"batb":[[2,1.64,226.49]],"batl":[[0,1.7,1349.39],[2,1.72,1319.47]],"ltp":1.7,"tv":10870.05,"id":9629022}]}]}
{"op":"mcm","clk":"4215183344","pt":1631535671605,"mc":[{"id":"1.187557985","rc":[{"trd":[[2.46,94.91]],"batb":[[1,2.4,21.42],[2,2.26,157.39]],"batl":[[0,2.5,158.9],[1,2.52,229.23],[2,2.54,241.31]],"ltp":2.46,"tv":17553.45,"id":5300820},{"trd":[[1.68,295.2]],"batl":[[0,1.67,21.58],[1,1.69,51.42],[2,1.7,1349.39]],"ltp":1.68,"tv":10878.47,"id":9629022}],"tv":28431.92}]}
{"op":"mcm","clk":"4215183429","pt":1631535672595,"mc":[{"id":"1.187557985","rc":[{"batl":[[0,2.54,241.31],[1,3.3,194.57],[2,3.45,2.32]],"ltp":2.46,"tv":17553.45,"id":5300820},{"batb":[[0,1.65,457.52],[1,1.64,226.49],[2,1.63,134.36]],"batl":[[0,1.7,1349.39],[1,1.71,1116.3],[2,1.72,1319.47]],"ltp":1.68,"tv":10878.47,"id":9629022}]}]}
{"op":"mcm","clk":"4215183523","pt":1631535673803,"mc":[{"id":"1.187557985","rc":[{"batb":[[2,2.28,166.05]],"batl":[[1,2.74,165.62],[2,2.76,177.25]],"ltp":2.46,"tv":17553.45,"id":5300820}]}]}
{"op":"mcm","clk":"4215183712","pt":1631535675583,"mc":[{"id":"1.187557985","rc":[{"batl":[[1,2.64,23.42],[2,2.74,165.62]],"ltp":2.46,"tv":17553.45,"id":5300820},{"batl":[[1,1.71,1146.3]],"ltp":1.68,"tv":10878.47,"id":9629022}]}]}
{"op":"mcm","clk":"4215184192","pt":1631535681502,"mc":[{"id":"1.187557985","rc":[{"batl":[[1,2.74,165.62],[2,2.76,177.25]],"ltp":2.46,"tv":17553.45,"id":5300820}]}]}
{"op":"mcm","clk":"4215184210","pt":1631535681814,"mc":[{"id":"1.187557985","rc":[{"batl":[[2,1.72,1314.59]],"ltp":1.68,"tv":10878.47,"id":9629022}]}]}
{"op":"mcm","clk":"4215184353","pt":1631535683627,"mc":[{"id":"1.187557985","rc":[{"trd":[[2.54,123.7]],"batl":[[0,2.54,240.71]],"ltp":2.54,"tv":17554.66,"id":5300820}],"tv":28433.13}]}
{"op":"mcm","clk":"4215184415","pt":1631535684416,"mc":[{"id":"1.187557985","rc":[{"batl":[[1,2.6,23.71],[2,2.74,165.62]],"ltp":2.54,"tv":17554.66,"id":5300820}]}]}
{"op":"mcm","clk":"4215184593","pt":1631535686244,"mc":[{"id":"1.187557985","rc":[{"trd":[[1.65,168.07]],"batb":[[0,1.65,457.48]],"ltp":1.65,"tv":10878.54,"id":9629022}],"tv":28433.21}]}
{"op":"mcm","clk":"4215184691","pt":1631535687522,"mc":[{"id":"1.187557985","rc":[{"trd":[[2.42,34.18]],"batb":[[0,2.42,53.28]],"ltp":2.42,"tv":17564.66,"id":5300820}],"tv":28443.21}]}
{"op":"mcm","clk":"4215184749","pt":1631535688109,"mc":[{"id":"1.187557985","rc":[{"trd":[[2.42,37.3]],"batb":[[0,2.42,51.72]],"ltp":2.42,"tv":17567.79,"id":5300820},{"trd":[[1.7,81.48]],"batl":[[0,1.7,1347.17]],"ltp":1.7,"tv":10882.98,"id":9629022}],"tv":28450.78}]}
{"op":"mcm","clk":"4215184882","pt":1631535690238,"mc":[{"id":"1.187557985","rc":[{"trd":[[1.65,188.08]],"batb":[[0,1.65,447.48]],"ltp":1.65,"tv":10902.99,"id":9629022}],"tv":28470.79}]}
{"op":"mcm","clk":"4215184918","pt":1631535690710,"mc":[{"id":"1.187557985","rc":[{"trd":[[1.65,188.14]],"batb":[[0,1.65,447.45]],"ltp":1.65,"tv":10903.05,"id":9629022}],"tv":28470.84}]}
{"op":"mcm","clk":"4215185090","pt":1631535692909,"mc":[{"id":"1.187557985","rc":[{"batb":[[2,2.34,4]],"batl":[[0,2.52,1.45],[1,2.54,240.71],[2,2.6,23.71]],"ltp":2.42,"tv":17567.79,"id":5300820}]}]}
{"op":"mcm","clk":"4215185929","pt":1631535703419,"mc":[{"id":"1.187557985","rc":[{"batl":[[0,2.52,8.68]],"ltp":2.42,"tv":17567.79,"id":5300820}]}]}
{"op":"mcm","clk":"4215187675","pt":1631535725387,"mc":[{"id":"1.187557985","rc":[{"trd":[[1.7,101.48]],"batl":[[0,1.7,1337.17]],"ltp":1.7,"tv":10923.05,"id":9629022}],"tv":28490.84}]}
{"op":"mcm","clk":"4215188834","pt":1631535740318,"mc":[{"id":"1.187557985","rc":[{"batl":[[0,2.54,240.71],[1,2.6,23.71],[2,2.74,165.62]],"ltp":2.42,"tv":17567.79,"id":5300820}]}]}
{"op":"mcm","clk":"4215190407","pt":1631535758048,"mc":[{"id":"1.187557985","rc":[{"batl":[[2,2.74,170.37]],"ltp":2.42,"tv":17567.79,"id":5300820}]}]}
{"op":"mcm","clk":"4215190610","pt":1631535760348,"mc":[{"id":"1.187557985","rc":[{"trd":[[2.42,37.69]],"batb":[[0,2.42,51.52]],"ltp":2.42,"tv":17568.18,"id":5300820}],"tv":28491.23}]}
{"op":"mcm","clk":"4215190718","pt":1631535761663,"mc":[{"id":"1.187557985","rc":[{"trd":[[1.7,101.66]],"batl":[[0,1.7,1337.08]],"ltp":1.7,"tv":10923.23,"id":9629022}],"tv":28491.42}]}
{"op":"mcm","clk":"4215190883","pt":1631535763388,"mc":[{"id":"1.187557985","rc":[{"batl":[[1,1.71,1121.9]],"ltp":1.7,"tv":10923.23,"id":9629022}]}]}
{"op":"mcm","clk":"4215191764","pt":1631535772807,"mc":[{"id":"1.187557985","rc":[{"trd":[[1.7,101.85]],"batl":[[0,1.7,1336.99]],"ltp":1.7,"tv":10923.41,"id":9629022}],"tv":28491.6}]}
{"op":"mcm","clk":"4215192198","pt":1631535777806,"mc":[{"id":"1.187557985","rc":[{"batb":[[0,2.42,71.84]],"ltp":2.42,"tv":17568.18,"id":5300820}]}]}
{"op":"mcm","clk":"4215192515","pt":1631535781007,"mc":[{"id":"1.187557985","rc":[{"batb":[[2,2.36,3]],"ltp":2.42,"tv":17568.18,"id":5300820}]}]}
{"op":"mcm","clk":"4215193446","pt":1631535790506,"mc":[{"id":"1.187557985","rc":[{"batb":[[0,2.4,21.42],[1,2.28,166.05],[2,2.26,276.6]],"batl":[[0,2.6,23.71],[1,2.74,170.37],[2,2.76,177.25]],"ltp":2.42,"tv":17568.18,"id":5300820},{"batb":[[0,1.62,38.1],[1,1.58,285.03],[2,1.57,327.37]],"batl":[[0,1.71,30],[1,1.79,251.58],[2,1.8,276.6]],"ltp":1.7,"tv":10923.41,"id":9629022}]}]}
{"op":"mcm","clk":"4215193536","pt":1631535791401,"mc":[{"id":"1.187557985","rc":[{"batb":[[0,2.28,166.05],[1,2.26,276.6],[2,2.24,257.77]],"batl":[[0,2.74,170.37],[1,2.76,177.25],[2,2.78,174.2]],"ltp":2.42,"tv":17568.18,"id":5300820},{"batb":[[0,1.58,285.03],[1,1.57,327.37],[2,1.56,391.69]],"batl":[[0,1.79,251.58],[1,1.8,276.6],[2,1.81,354.49]],"ltp":1.7,"tv":10923.41,"id":9629022}]}]}
{"op":"mcm","clk":"4215193671","pt":1631535793423,"mc":[{"id":"1.187557985","rc":[{"batb":[[0,1.7,2.32],[1,1.58,285.03],[2,1.57,327.37]],"batl":[[0,1.79,393.31],[2,1.81,543.6]],"ltp":1.7,"tv":10923.41,"id":9629022}]}]}
{"op":"mcm","clk":"4215193759","pt":1631535794626,"mc":[{"id":"1.187557985","rc":[{"batb":[[1,1.58,291.03],[2,1.57,332.37]],"ltp":1.7,"tv":10923.41,"id":9629022}]}]}
{"op":"mcm","clk":"4215193763","pt":1631535794730,"mc":[{"id":"1.187557985","rc":[{"batl":[[0,2.74,174.37]],"ltp":2.42,"tv":17568.18,"id":5300820}]}]}
{"op":"mcm","clk":"4215193993","pt":1631535797598,"mc":[{"id":"1.187557985","rc":[{"batb":[[0,2.26,85.02],[1,2.18,6.86],[2,2.08,6.81]],"ltp":2.42,"tv":17568.18,"id":5300820},{"batl":[[0,1.83,2.32],[1,1.84,31.28],[2,1.92,27.56]],"ltp":1.7,"tv":10923.41,"id":9629022}]}]}
{"op":"mcm","clk":"4215194003","pt":1631535797703,"mc":[{"id":"1.187557985","rc":[{"batb":[[1,2.08,6.81],[2,2.04,7.49]],"ltp":2.42,"tv":17568.18,"id":5300820},{"batl":[[1,990,0.15],[2,1.92,0]],"ltp":1.7,"tv":10923.41,"id":9629022}]}]}
{"op":"mcm","clk":"4215194272","pt":1631535800642,"mc":[{"id":"1.187557985","rc":[{"batb":[[0,2.64,724.44],[1,2.62,703.12],[2,2.6,703.12]],"batl":[[0,2.74,4.75]],"ltp":2.42,"tv":17568.18,"id":5300820},{"trd":[[1.7,106.49]],"batb":[[0,1.58,49.06],[1,1.57,327.37],[2,1.56,391.69]],"batl":[[0,1.59,170.36],[1,1.6,142.3],[2,1.67,9.55]],"ltp":1.7,"tv":10928.06,"id":9629022}],"tv":28496.24}]}
{"op":"mcm","clk":"4215194356","pt":1631535801522,"mc":[{"id":"1.187557985","rc":[{"trd":[[2.68,48.51]],"batb":[[0,2.66,54.23],[1,2.64,724.44],[2,2.62,703.12]],"batl":[[0,2.76,177.25],[1,2.78,174.2],[2,2.9,664.53]],"ltp":2.68,"tv":17576.44,"id":5300820},{"trd":[[1.59,939.18]],"batb":[[0,1.57,327.37],[1,1.56,391.69],[2,1.55,290.69]],"batl":[[0,1.59,156.44]],"ltp":1.59,"tv":10941.98,"id":9629022}],"tv":28518.42}]}
{"op":"mcm","clk":"4215194462","pt":1631535802615,"mc":[{"id":"1.187557985","rc":[{"batl":[[2,2.84,22.11]],"ltp":2.68,"tv":17576.44,"id":5300820}]}]}
{"op":"mcm","clk":"4215194616","pt":1631535804604,"mc":[{"id":"1.187557985","rc":[{"trd":[[1.59,972.62]],"batl":[[0,1.59,139.72]],"ltp":1.59,"tv":10975.42,"id":9629022}],"tv":28551.86}]}
{"op":"mcm","clk":"4215194702","pt":1631535805601,"mc":[{"id":"1.187557985","rc":[{"trd":[[2.68,49.91]],"batb":[[0,2.66,155.1]],"ltp":2.68,"tv":17577.84,"id":5300820},{"trd":[[1.59,979.7]],"batl":[[0,1.59,135],[2,1.65,30]],"ltp":1.59,"tv":10982.49,"id":9629022}],"tv":28560.34}]}
{"op":"mcm","clk":"4215194777","pt":1631535806543,"mc":[{"id":"1.187557985","rc":[{"batb":[[0,2.66,72.89]],"ltp":2.68,"tv":17577.84,"id":5300820},{"batl":[[2,1.67,9.55]],"ltp":1.59,"tv":10982.49,"id":9629022}]}]}
{"op":"mcm","clk":"4215194848","pt":1631535807325,"mc":[{"id":"1.187557985","rc":[{"trd":[[2.68,50.63]],"ltp":2.68,"tv":17578.56,"id":5300820},{"trd":[[1.59,980.92]],"batl":[[0,1.59,133.78]],"ltp":1.59,"tv":10983.71,"id":9629022}],"tv":28562.28}]}
{"op":"mcm","clk":"4215194883","pt":1631535807848,"mc":[{"id":"1.187557985","rc":[{"batb":[[2,1.55,309.39]],"ltp":1.59,"tv":10983.71,"id":9629022}]}]}
{"op":"mcm","clk":"4215195037","pt":1631535809635,"mc":[{"id":"1.187557985","rc":[{"trd":[[2.68,51.47]],"ltp":2.68,"tv":17579.4,"id":5300820},{"trd":[[1.59,982.34]],"batl":[[0,1.59,132.36],[2,1.63,30]],"ltp":1.59,"tv":10985.13,"id":9629022}],"tv":28564.54}]}
{"op":"mcm","clk":"4215195085","pt":1631535810157,"mc":[{"id":"1.187557985","rc":[{"batl":[[0,1.6,142.3],[1,1.63,30],[2,1.67,9.55]],"ltp":1.59,"tv":10985.13,"id":9629022}]}]}
{"op":"mcm","clk":"4215195194","pt":1631535811228,"mc":[{"id":"1.187557985","rc":[{"trd":[[2.66,152.21]],"batb":[[0,2.64,724.44],[1,2.62,703.12],[2,2.6,703.12]],"ltp":2.66,"tv":17731.62,"id":5300820},{"trd":[[1.6,10.75]],"batl":[[0,1.6,131.55]],"ltp":1.6,"tv":10995.88,"id":9629022}],"tv":28727.5}]}
{"op":"mcm","clk":"4215195288","pt":1631535812530,"mc":[{"id":"1.187557985","rc":[{"batb":[[0,2.58,21.98],[1,2.56,4],[2,2.44,68.87]],"batl":[[0,2.84,22.11],[1,3.05,4.3],[2,3.3,3.55]],"ltp":2.66,"tv":17731.62,"id":5300820},{"batb":[[0,1.59,2.11],[1,1.54,45.82],[2,1.53,5]],"batl":[[0,1.63,30],[1,1.67,9.55],[2,1.69,4.72]],"ltp":1.6,"tv":10995.88,"id":9629022}]}]}
{"op":"mcm","clk":"4215195366","pt":1631535813470,"mc":[{"id":"1.187557985","rc":[{"batb":[[0,2.44,68.87],[1,2.38,6.46],[2,2.26,6.98]],"batl":[[0,3.3,3.55],[1,3.45,2.32],[2,3.65,172.76]],"ltp":2.66,"tv":17731.62,"id":5300820},{"batb":[[1,1.5,15],[2,1.46,188.45]],"batl":[[0,1.72,35.91],[1,1.79,34.5],[2,1.83,2.32]],"ltp":1.6,"tv":10995.88,"id":9629022}]}]}
{"op":"mcm","clk":"4215195397","pt":1631535813741,"mc":[{"id":"1.187557985","rc":[{"batb":[[1,2.26,6.98],[2,2.04,7.49]],"ltp":2.66,"tv":17731.62,"id":5300820},{"batl":[[0,1.79,34.5],[1,1.83,2.32],[2,990,0.15]],"ltp":1.6,"tv":10995.88,"id":9629022}]}]}
{"op":"mcm","clk":"4215195505","pt":1631535815149,"mc":[{"id":"1.187557985","rc":[{"batb":[[2,1.46,438.64]],"batl":[[0,1.7,235.52],[1,1.72,221.7],[2,1.79,34.5]],"ltp":1.6,"tv":10995.88,"id":9629022}]}]}
{"op":"mcm","clk":"4215195620","pt":1631535816572,"mc":[{"id":"1.187557985","rc":[{"batb":[[0,2.42,70.38]],"ltp":2.66,"tv":17731.62,"id":5300820},{"batb":[[2,1.47,185.35]],"batl":[[0,1.79,34.5],[1,1.83,2.32],[2,990,0.15]],"ltp":1.6,"tv":10995.88,"id":9629022}]}]}
{"op":"mcm","clk":"4215195798","pt":1631535818639,"mc":[{"id":"1.187557985","rc":[{"batl":[[0,1.63,4],[1,1.79,34.5],[2,1.83,2.32]],"ltp":1.6,"tv":10995.88,"id":9629022}]}]}
{"op":"mcm","clk":"4215195866","pt":1631535819467,"mc":[{"id":"1.187557985","rc":[{"batl":[[0,3.05,3.9],[1,3.3,3.55],[2,3.45,2.32]],"ltp":2.66,"tv":17731.62,"id":5300820},{"trd":[[1.59,986.57]],"batb":[[0,1.53,283.94],[1,1.52,174.25],[2,1.5,15]],"batl":[[0,1.58,205.93],[1,1.59,144.74],[2,1.79,34.5]],"ltp":1.59,"tv":11000.12,"id":9629022}],"tv":28731.74}]}
{"op":"mcm","clk":"4215196074","pt":1631535821661,"mc":[{"id":"1.187557985","rc":[{"batl":[[0,3.3,3.55],[1,3.45,2.32],[2,3.65,172.76]],"ltp":2.66,"tv":17731.62,"id":5300820},{"batb":[[0,1.5,15],[1,1.47,185.35],[2,1.44,61.42]],"batl":[[0,1.79,34.5],[1,1.83,2.32],[2,990,0.15]],"ltp":1.59,"tv":11000.12,"id":9629022}]}]}
{"op":"mcm","clk":"4215196154","pt":1631535822452,"mc":[{"id":"1.187557985","rc":[{"batl":[[0,3,3],[1,3.3,3.55],[2,3.45,2.32]],"ltp":2.66,"tv":17731.62,"id":5300820},{"batb":[[0,1.51,58.67],[1,1.5,21],[2,1.49,5]],"ltp":1.59,"tv":11000.12,"id":9629022}]}]}
{"op":"mcm","clk":"4215196178","pt":1631535822764,"mc":[{"id":"1.187557985","rc":[{"batb":[[0,1.5,21],[1,1.49,5],[2,1.47,185.35]],"ltp":1.59,"tv":11000.12,"id":9629022}]}]}
{"op":"mcm","clk":"4215196346","pt":1631535824446,"mc":[{"id":"1.187557985","rc":[{"batl":[[0,1.7,235.52],[1,1.72,221.7],[2,1.79,34.5]],"ltp":1.59,"tv":11000.12,"id":9629022}]}]}
{"op":"mcm","clk":"4215196462","pt":1631535825645,"mc":[{"id":"1.187557985","rc":[{"batb":[[1,2.38,5.67],[2,2.26,6.98]],"batl":[[0,2.98,3],[1,3,3],[2,3.3,3.55]],"ltp":2.66,"tv":17731.62,"id":5300820},{"batl":[[1,1.72,258.11]],"ltp":1.59,"tv":11000.12,"id":9629022}]}]}
{"op":"mcm","clk":"4215196699","pt":1631535828478,"mc":[{"id":"1.187557985","rc":[{"batb":[[1,2.26,6.98],[2,2.04,7.49]],"batl":[[2,3.05,3.9]],"ltp":2.66,"tv":17731.62,"id":5300820},{"batb":[[1,1.49,56.01]],"batl":[[0,1.83,2.32],[1,990,0.15],[2,1.79,0]],"ltp":1.59,"tv":11000.12,"id":9629022}]}]}
{"op":"mcm","clk":"4215196726","pt":1631535828750,"mc":[{"id":"1.187557985","rc":[{"batl":[[2,3.3,3.55]],"ltp":2.66,"tv":17731.62,"id":5300820},{"batb":[[1,1.49,5]],"ltp":1.59,"tv":11000.12,"id":9629022}]}]}
{"op":"mcm","clk":"4215196876","pt":1631535830579,"mc":[{"id":"1.187557985","rc":[{"batl":[[0,3.3,3.55],[1,3.45,2.32],[2,990,0.01]],"ltp":2.66,"tv":17731.62,"id":5300820},{"batb":[[0,1.5,15],[1,1.47,185.35],[2,1.46,250.19]],"ltp":1.59,"tv":11000.12,"id":9629022}]}]}
{"op":"mcm","clk":"4215196978","pt":1631535831589,"mc":[{"id":"1.187557985","rc":[{"batb":[[0,2.94,105.35],[1,2.78,8.66],[2,2.7,52.72]],"batl":[[0,3.3,583.11],[1,3.35,309.37],[2,3.4,309.37]],"ltp":2.66,"tv":17731.62,"id":5300820},{"trd":[[1.5,440.95]],"batb":[[0,1.47,185.35],[1,1.46,250.19],[2,1.45,210.72]],"batl":[[0,1.5,184.07],[1,1.51,1442.1],[2,1.52,1229.32]],"ltp":1.5,"tv":11030.12,"id":9629022}],"tv":28761.74}]}
{"op":"mcm","clk":"4215197055","pt":1631535832359,"mc":[{"id":"1.187557985","rc":[{"trd":[[3,13.8]],"batb":[[1,2.78,25.51]],"batl":[[0,3.15,20.45],[1,3.3,583.11],[2,3.35,309.37]],"ltp":3.0,"tv":17739.25,"id":5300820},{"trd":[[1.5,456.21]],"batb":[[0,1.47,229.1]],"batl":[[0,1.5,168.81]],"ltp":1.5,"tv":11045.38,"id":9629022}],"tv":28784.63}]}
{"op":"mcm","clk":"4215197168","pt":1631535833468,"mc":[{"id":"1.187557985","rc":[{"batl":[[2,1.52,1278.45]],"ltp":1.5,"tv":11045.38,"id":9629022}]}]}
{"op":"mcm","clk":"4215197218","pt":1631535833991,"mc":[{"id":"1.187557985","rc":[{"batb":[[1,2.88,4],[2,2.86,3]],"batl":[[1,3.25,17.75],[2,3.3,583.11]],"ltp":3.0,"tv":17739.25,"id":5300820}]}]}
{"op":"mcm","clk":"4215197339","pt":1631535835190,"mc":[{"id":"1.187557985","rc":[{"batb":[[1,1.46,268.95]],"ltp":1.5,"tv":11045.38,"id":9629022}]}]}
{"op":"mcm","clk":"4215197453","pt":1631535836566,"mc":[{"id":"1.187557985","rc":[{"trd":[[3,15.03]],"batb":[[0,2.96,91.44],[1,2.94,105.35],[2,2.88,4]],"ltp":3.0,"tv":17740.48,"id":5300820},{"trd":[[1.5,463.6]],"batl":[[0,1.5,163.88]],"ltp":1.5,"tv":11052.77,"id":9629022}],"tv":28793.25}]}
{"op":"mcm","clk":"4215197537","pt":1631535837494,"mc":[{"id":"1.187557985","rc":[{"batb":[[0,2.96,18.68]],"ltp":3.0,"tv":17740.48,"id":5300820}]}]}
{"op":"mcm","clk":"4215197705","pt":1631535839389,"mc":[{"id":"1.187557985","rc":[{"trd":[[1.47,43.92]],"batb":[[0,1.47,290.13]],"ltp":1.47,"tv":11096.69,"id":9629022}],"tv":28837.17}]}
{"op":"mcm","clk":"4215197806","pt":1631535840497,"mc":[{"id":"1.187557985","rc":[{"trd":[[3,15.76]],"ltp":3.0,"tv":17741.2,"id":5300820},{"trd":[[1.5,465.05]],"batl":[[0,1.5,162.43]],"ltp":1.5,"tv":11098.14,"id":9629022}],"tv":28839.34}]}
{"op":"mcm","clk":"4215198003","pt":1631535842464,"mc":[{"id":"1.187557985","rc":[{"trd":[[1.47,129.86]],"batb":[[0,1.47,247.15]],"ltp":1.47,"tv":11184.07,"id":9629022}],"tv":28925.28}]}
{"op":"mcm","clk":"4215198059","pt":1631535843089,"mc":[{"id":"1.187557985","rc":[{"trd":[[1.5,465.13]],"batl":[[0,1.5,162.39]],"ltp":1.5,"tv":11184.15,"id":9629022}],"tv":28925.36}]}
{"op":"mcm","clk":"4215198414","pt":1631535847097,"mc":[{"id":"1.187557985","rc":[{"trd":[[1.5,465.15]],"batl":[[0,1.5,162.38]],"ltp":1.5,"tv":11184.17,"id":9629022}],"tv":28925.38}]}
{"op":"mcm","clk":"4215198625","pt":1631535849615,"mc":[{"id":"1.187557985","rc":[{"trd":[[1.5,470.33]],"batl":[[0,1.5,159.79]],"ltp":1.5,"tv":11189.35,"id":9629022}],"tv":28930.56}]}
{"op":"mcm","clk":"4215198776","pt":1631535851307,"mc":[{"id":"1.187557985","rc":[{"batb":[[0,2.82,16.48],[1,2.72,165.72],[2,2.7,255.46]],"batl":[[1,3.45,119.51],[2,3.5,141.19]],"ltp":3.0,"tv":17741.2,"id":5300820},{"batb":[[0,1.47,126.75],[1,1.4,578.61],[2,1.39,357.1]],"batl":[[0,1.59,288.54],[1,1.6,410.98],[2,1.61,415.64]],"ltp":1.5,"tv":11189.35,"id":9629022}]}]}
{"op":"mcm","clk":"4215198858","pt":1631535852553,"mc":[{"id":"1.187557985","rc":[{"batb":[[0,2.72,165.72],[1,2.7,255.46],[2,2.68,204.87]],"batl":[[0,3.45,119.51],[1,3.5,141.19],[2,3.55,145.91]],"ltp":3.0,"tv":17741.2,"id":5300820},{"batb":[[0,1.4,578.61],[1,1.39,357.1],[2,1.38,410.78]],"ltp":1.5,"tv":11189.35,"id":9629022}]}]}
{"op":"mcm","clk":"4215199004","pt":1631535854446,"mc":[{"id":"1.187557985","rc":[{"batb":[[1,2.7,254.88]],"ltp":3.0,"tv":17741.2,"id":5300820},{"batb":[[0,1.4,347.66],[1,1.39,779.53],[2,1.38,671.57]],"batl":[[0,1.58,177.97],[1,1.59,433.22],[2,1.6,410.98]],"ltp":1.5,"tv":11189.35,"id":9629022}]}]}
{"op":"mcm","clk":"4215199085","pt":1631535855743,"mc":[{"id":"1.187557985","rc":[{"batl":[[0,3.45,122.51]],"ltp":3.0,"tv":17741.2,"id":5300820},{"batb":[[0,1.4,353.66],[1,1.39,786.53]],"ltp":1.5,"tv":11189.35,"id":9629022}]}]}
{"op":"mcm","clk":"4215199425","pt":1631535859453,"mc":[{"id":"1.187557985","rc":[{"batl":[[0,3.45,5.32],[1,3.5,3.29],[2,3.75,3.46]],"ltp":3.0,"tv":17741.2,"id":5300820},{"batb":[[0,1.4,73.11],[1,1.39,240.22],[2,1.37,72.77]],"ltp":1.5,"tv":11189.35,"id":9629022}]}]}
{"op":"mcm","clk":"4215199448","pt":1631535859764,"mc":[{"id":"1.187557985","rc":[{"batl":[[1,3.75,3.46],[2,3.8,3.42]],"ltp":3.0,"tv":17741.2,"id":5300820},{"batb":[[0,1.4,6]],"ltp":1.5,"tv":11189.35,"id":9629022}]}]}
{"op":"mcm","clk":"4215199611","pt":1631535861448,"mc":[{"id":"1.187557985","rc":[{"batb":[[0,1.53,2844.06],[1,1.4,6],[2,1.39,240.22]],"ltp":1.5,"tv":11189.35,"id":9629022}]}]}
{"op":"mcm","clk":"4215199727","pt":1631535862661,"mc":[{"id":"1.187557985","rc":[{"trd":[[2.72,24.59]],"batb":[[0,2.72,157.59]],"batl":[[0,2.94,650.52],[1,2.96,631.38],[2,2.98,631.38]],"ltp":2.72,"tv":17757.47,"id":5300820},{"batb":[[0,1.54,142.81],[1,1.53,168.75],[2,1.49,10.7]],"batl":[[2,1.6,1068.41]],"ltp":1.5,"tv":11189.35,"id":9629022}],"tv":28946.83}]}
{"op":"mcm","clk":"4215199809","pt":1631535863558,"mc":[{"id":"1.187557985","rc":[{"batl":[[0,2.9,21.76],[1,2.94,650.52],[2,2.96,631.38]],"ltp":2.72,"tv":17757.47,"id":5300820},{"batb":[[0,1.54,297.37],[2,1.52,41.6]],"ltp":1.5,"tv":11189.35,"id":9629022}]}]}
{"op":"mcm","clk":"4215199960","pt":1631535865549,"mc":[{"id":"1.187557985","rc":[{"batl":[[1,2.92,3],[2,2.94,650.52]],"ltp":2.72,"tv":17757.47,"id":5300820}]}]}
{"op":"mcm","clk":"4215200071","pt":1631535866652,"mc":[{"id":"1.187557985","rc":[{"batb":[[2,1.49,10.7]],"ltp":1.5,"tv":11189.35,"id":9629022}]}]}
{"op":"mcm","clk":"4215200152","pt":1631535867584,"mc":[{"id":"1.187557985","rc":[{"trd":[[2.72,27.01]],"batb":[[0,2.72,156.38]],"batl":[[0,2.92,3],[1,2.94,650.52],[2,2.96,631.38]],"ltp":2.72,"tv":17759.88,"id":5300820},{"trd":[[1.58,102.58]],"batl":[[0,1.58,175.9]],"ltp":1.58,"tv":11193.5,"id":9629022}],"tv":28953.39}]}
{"op":"mcm","clk":"4215200393","pt":1631535870256,"mc":[{"id":"1.187557985","rc":[{"trd":[[1.58,302.58]],"batb":[[0,1.54,338.19]],"batl":[[0,1.59,433.22],[1,1.6,1068.41],[2,1.61,1575.78]],"ltp":1.58,"tv":11393.5,"id":9629022}],"tv":29153.39}]}
{"op":"mcm","clk":"4215200475","pt":1631535871190,"mc":[{"id":"1.187557985","rc":[{"batl":[[0,2.9,26.6],[1,2.92,3],[2,2.94,650.52]],"ltp":2.72,"tv":17759.88,"id":5300820}]}]}
{"op":"mcm","clk":"4215200658","pt":1631535873483,"mc":[{"id":"1.187557985","rc":[{"batb":[[0,1.54,397.37]],"batl":[[0,1.59,585.99],[1,1.6,1209.1]],"ltp":1.58,"tv":11393.5,"id":9629022}]}]}
{"op":"mcm","clk":"4215200772","pt":1631535874581,"mc":[{"id":"1.187557985","rc":[{"batl":[[0,2.9,21.76]],"ltp":2.72,"tv":17759.88,"id":5300820}]}]}
{"op":"mcm","clk":"4215200901","pt":1631535876466,"mc":[{"id":"1.187557985","rc":[{"batb":[[0,2.7,52.13],[1,2.6,18.75],[2,2.52,5.74]],"batl":[[1,3.25,3.82],[2,3.45,2.32]],"ltp":2.72,"tv":17759.88,"id":5300820},{"batb":[[0,1.58,25],[1,1.54,397.37],[2,1.53,168.75]],"batl":[[0,1.59,264.22],[1,1.6,140.69],[2,1.62,30]],"ltp":1.58,"tv":11393.5,"id":9629022}]}]}
{"op":"mcm","clk":"4215200991","pt":1631535877356,"mc":[{"id":"1.187557985","rc":[{"batb":[[0,2.44,68.12],[1,2.42,5.44],[2,2.12,394.01]],"batl":[[0,3.25,3.82],[1,3.45,2.32],[2,3.5,2.99]],"ltp":2.72,"tv":17759.88,"id":5300820},{"batb":[[1,1.45,62.41],[2,1.44,202.67]],"batl":[[0,1.7,38.65],[1,1.83,2.32],[2,990,0.15]],"ltp":1.58,"tv":11393.5,"id":9629022}]}]}
{"op":"mcm","clk":"4215201273","pt":1631535880600,"mc":[{"id":"1.187557985","rc":[{"batb":[[0,2.46,67.36],[1,2.44,4],[2,2.42,8.44]],"ltp":2.72,"tv":17759.88,"id":5300820},{"batb":[[2,1.43,559.72]],"batl":[[0,1.69,135.73],[1,1.7,38.65],[2,1.71,225.98]],"ltp":1.58,"tv":11393.5,"id":9629022}]}]}
{"op":"mcm","clk":"4215201300","pt":1631535880864,"mc":[{"id":"1.187557985","rc":[{"batl":[[0,3.45,2.32],[1,3.5,2.99],[2,3.9,160.43]],"ltp":2.72,"tv":17759.88,"id":5300820},{"trd":[[1.58,302.76]],"batb":[[0,1.58,24.91],[1,1.43,205.02],[2,1.41,6]],"batl":[[0,1.7,38.65],[1,1.83,2.32],[2,990,0.15]],"ltp":1.58,"tv":11393.68,"id":9629022}],"tv":29153.57}]}
{"op":"mcm","clk":"4215201489","pt":1631535883032,"mc":[{"id":"1.187557985","rc":[{"batb":[[0,2.46,70.36]],"ltp":2.72,"tv":17759.88,"id":5300820},{"batl":[[0,1.69,6],[1,1.7,38.65],[2,1.83,2.32]],"ltp":1.58,"tv":11393.68,"id":9629022}]}]}
{"op":"mcm","clk":"4215201591","pt":1631535884395,"mc":[{"id":"1.187557985","rc":[{"trd":[[2.68,61.47]],"batb":[[0,2.52,608.29],[1,2.46,70.36],[2,2.44,4]],"ltp":2.68,"tv":17769.88,"id":5300820},{"trd":[[1.59,1003.43]],"batb":[[1,1.54,201.99],[2,1.53,168.77]],"batl":[[0,1.59,247.36],[1,1.6,140.69],[2,1.69,6]],"ltp":1.59,"tv":11410.54,"id":9629022}],"tv":29180.43}]}
{"op":"mcm","clk":"4215201671","pt":1631535885596,"mc":[{"id":"1.187557985","rc":[{"batb":[[1,1.43,205.02],[2,1.41,6]],"batl":[[0,1.69,6],[1,1.7,38.65],[2,1.83,2.32]],"ltp":1.59,"tv":11410.54,"id":9629022}]}]}
{"op":"mcm","clk":"4215201680","pt":1631535885701,"mc":[{"id":"1.187557985","rc":[{"batb":[[0,2.46,70.36],[1,2.44,4],[2,2.42,8.44]],"ltp":2.68,"tv":17769.88,"id":5300820}]}]}
{"op":"mcm","clk":"4215201891","pt":1631535888504,"mc":[{"id":"1.187557985","rc":[{"batb":[[1,1.43,570.04],[2,1.42,230.65]],"batl":[[0,1.69,132.92],[2,1.71,225.96]],"ltp":1.59,"tv":11410.54,"id":9629022}]}]}
{"op":"mcm","clk":"4215201962","pt":1631535889604,"mc":[{"id":"1.187557985","rc":[{"trd":[[1.58,302.78]],"batb":[[0,1.58,24.9]],"ltp":1.58,"tv":11410.56,"id":9629022}],"tv":29180.45}]}
{"op":"mcm","clk":"4215202023","pt":1631535890286,"mc":[{"id":"1.187557985","rc":[{"batb":[[1,1.43,205.02],[2,1.41,6]],"batl":[[0,1.69,6.19],[2,1.83,2.32]],"ltp":1.58,"tv":11410.56,"id":9629022}]}]}
{"op":"mcm","clk":"4215202292","pt":1631535893569,"mc":[{"id":"1.187557985","rc":[{"batb":[[1,2.42,5.44],[2,2.12,394.01]],"ltp":2.68,"tv":17769.88,"id":5300820},{"batb":[[1,1.54,211.59],[2,1.53,168.78]],"batl":[[0,1.59,254.9],[1,1.6,140.69],[2,1.69,6.19]],"ltp":1.58,"tv":11410.56,"id":9629022}]}]}
{"op":"mcm","clk":"4215202390","pt":1631535894872,"mc":[{"id":"1.187557985","rc":[{"batb":[[1,1.43,205.02],[2,1.41,6]],"batl":[[0,1.69,6.19],[1,1.7,34.65],[2,1.83,2.32]],"ltp":1.58,"tv":11410.56,"id":9629022}]}]}
{"op":"mcm","clk":"4215202529","pt":1631535896583,"mc":[{"id":"1.187557985","rc":[{"batb":[[0,2.5,613.19],[1,2.46,70.36],[2,2.42,5.44]],"ltp":2.68,"tv":17769.88,"id":5300820}]}]}
{"op":"mcm","clk":"4215202596","pt":1631535897617,"mc":[{"id":"1.187557985","rc":[{"batb":[[0,2.46,70.36],[1,2.42,5.44],[2,2.12,394.01]],"ltp":2.68,"tv":17769.88,"id":5300820},{"batb":[[1,1.43,570.04],[2,1.42,230.65]],"batl":[[0,1.69,133.11],[2,1.71,225.96]],"ltp":1.58,"tv":11410.56,"id":9629022}]}]}
{"op":"mcm","clk":"4215202619","pt":1631535897929,"mc":[{"id":"1.187557985","rc":[{"batb":[[1,2.44,4],[2,2.42,5.44]],"ltp":2.68,"tv":17769.88,"id":5300820},{"batb":[[1,1.43,205.02],[2,1.41,6]],"batl":[[0,1.69,6.19],[2,1.83,2.32]],"ltp":1.58,"tv":11410.56,"id":9629022}]}]}
{"op":"mcm","clk":"4215202791","pt":1631535900523,"mc":[{"id":"1.187557985","rc":[{"batb":[[0,1.43,205.02],[1,1.41,6],[2,1.4,63.51]],"batl":[[0,1.59,664.02],[1,1.69,6.19],[2,1.7,34.65]],"ltp":1.58,"tv":11410.56,"id":9629022}]}]}
{"op":"mcm","clk":"4215202853","pt":1631535901313,"mc":[{"id":"1.187557985","rc":[{"batb":[[0,1.52,182.11],[1,1.51,177.48],[2,1.43,205.02]],"batl":[[0,1.56,165.44],[1,1.57,151.18],[2,1.58,1.25]],"ltp":1.58,"tv":11410.56,"id":9629022}]}]}
{"op":"mcm","clk":"4215202954","pt":1631535902609,"mc":[{"id":"1.187557985","rc":[{"batb":[[0,1.43,205.02],[1,1.41,6],[2,1.4,63.51]],"batl":[[0,1.69,6.19],[1,1.7,34.65],[2,1.83,2.32]],"ltp":1.58,"tv":11410.56,"id":9629022}]}]}
{"op":"mcm","clk":"4215203005","pt":1631535903341,"mc":[{"id":"1.187557985","rc":[{"batl":[[0,3.35,3],[1,3.45,2.32],[2,3.5,2.99]],"ltp":2.68,"tv":17769.88,"id":5300820},{"batb":[[0,1.43,210.02],[1,1.42,6],[2,1.41,6]],"ltp":1.58,"tv":11410.56,"id":9629022}]}]}
{"op":"mcm","clk":"4215203156","pt":1631535905616,"mc":[{"id":"1.187557985","rc":[{"batb":[[0,1.43,575.04],[1,1.42,236.65]],"batl":[[0,1.69,133.11],[2,1.71,225.96]],"ltp":1.58,"tv":11410.56,"id":9629022}]}]}
{"op":"mcm","clk":"4215203226","pt":1631535906403,"mc":[{"id":"1.187557985","rc":[{"batb":[[0,2.46,71.09]],"batl":[[0,3.3,3],[1,3.35,3],[2,3.45,2.32]],"ltp":2.68,"tv":17769.88,"id":5300820},{"batb":[[0,1.44,6],[1,1.43,575.04],[2,1.42,236.65]],"batl":[[0,1.68,5.19],[1,1.69,132.92],[2,1.7,34.65]],"ltp":1.58,"tv":11410.56,"id":9629022}]}]}
{"op":"mcm","clk":"4215203591","pt":1631535911503,"mc":[{"id":"1.187557985","rc":[{"batb":[[0,2.46,70.36],[1,2.42,5.44],[2,2.12,394.01]],"ltp":2.68,"tv":17769.88,"id":5300820}]}]}
{"op":"mcm","clk":"4215203636","pt":1631535912024,"mc":[{"id":"1.187557985","rc":[{"batl":[[1,1.69,6]],"ltp":1.58,"tv":11410.56,"id":9629022}]}]}
{"op":"mcm","clk":"4215203815","pt":1631535914514,"mc":[{"id":"1.187557985","rc":[{"batl":[[0,3.35,3],[1,3.45,2.32],[2,3.5,2.99]],"ltp":2.68,"tv":17769.88,"id":5300820},{"batb":[[0,1.43,570.04],[1,1.42,230.65],[2,1.4,63.51]],"ltp":1.58,"tv":11410.56,"id":9629022}]}]}
{"op":"mcm","clk":"4215203920","pt":1631535915551,"mc":[{"id":"1.187557985","rc":[{"batb":[[0,2.94,159.86],[1,2.92,79.94],[2,2.9,79.94]],"batl":[[1,3.45,584.39],[2,3.5,567.93]],"ltp":2.68,"tv":17769.88,"id":5300820},{"batb":[[0,1.44,321.11],[1,1.43,570.04],[2,1.42,230.65]],"batl":[[0,1.47,146.55],[1,1.48,189.54],[2,1.54,10.36]],"ltp":1.58,"tv":11410.56,"id":9629022}]}]}
{"op":"mcm","clk":"4215204004","pt":1631535916648,"mc":[{"id":"1.187557985","rc":[{"trd":[[3.1,7.35]],"batb":[[0,3.1,92.63],[1,2.94,159.86],[2,2.92,79.94]],"batl":[[0,3.25,20],[1,3.35,3],[2,3.45,584.39]],"ltp":3.1,"tv":17777.23,"id":5300820},{"trd":[[1.47,145.36]],"batb":[[0,1.43,426.59],[1,1.4,74.9],[2,1.38,5.78]],"batl":[[0,1.48,189.54],[1,1.54,10.36],[2,1.56,5.11]],"ltp":1.47,"tv":11426.06,"id":9629022}],"tv":29203.3}]}
{"op":"mcm","clk":"4215204147","pt":1631535918511,"mc":[{"id":"1.187557985","rc":[{"batb":[[1,3,3],[2,2.98,3]],"batl":[[1,3.35,18]],"ltp":3.1,"tv":17777.23,"id":5300820},{"batb":[[0,1.43,465.5]],"batl":[[1,1.51,6],[2,1.54,10.36]],"ltp":1.47,"tv":11426.06,"id":9629022}]}]}
{"op":"mcm","clk":"4215204232","pt":1631535919612,"mc":[{"id":"1.187557985","rc":[{"batb":[[0,1.44,152.9],[1,1.43,465.5],[2,1.4,74.9]],"batl":[[0,1.48,325.07],[1,1.49,182.96],[2,1.51,6]],"ltp":1.47,"tv":11426.06,"id":9629022}]}]}
{"op":"mcm","clk":"4215204295","pt":1631535920341,"mc":[{"id":"1.187557985","rc":[{"batb":[[0,1.44,198.12]],"batl":[[0,1.48,361.6]],"ltp":1.47,"tv":11426.06,"id":9629022}]}]}
{"op":"mcm","clk":"4215204456","pt":1631535922513,"mc":[{"id":"1.187557985","rc":[{"batb":[[0,1.47,25],[1,1.44,198.12],[2,1.43,465.5]],"ltp":1.47,"tv":11426.06,"id":9629022}]}]}
{"op":"mcm","clk":"4215204578","pt":1631535924430,"mc":[{"id":"1.187557985","rc":[{"batb":[[0,1.47,31.83]],"ltp":1.47,"tv":11426.06,"id":9629022}]}]}
{"op":"mcm","clk":"4215204763","pt":1631535926935,"mc":[{"id":"1.187557985","rc":[{"trd":[[3.1,37.36]],"batb":[[0,3.1,77.63]],"ltp":3.1,"tv":17807.24,"id":5300820}],"tv":29233.31}]}
{"op":"mcm","clk":"4215204970","pt":1631535929647,"mc":[{"id":"1.187557985","rc":[{"batl":[[2,3.45,2.32]],"ltp":3.1,"tv":17807.24,"id":5300820}]}]}
{"op":"mcm","clk":"4215205007","pt":1631535930157,"mc":[{"id":"1.187557985","rc":[{"trd":[[3.1,37.38]],"batb":[[0,2.82,47.2],[1,2.8,187.45],[2,2.78,214.53]],"batl":[[1,3.45,2.32],[2,3.65,153.49]],"ltp":3.1,"tv":17807.26,"id":5300820},{"trd":[[1.48,0.04]],"batb":[[1,1.44,45.22],[2,1.37,350.13]],"batl":[[0,1.52,30],[1,1.56,306.33],[2,1.57,376.3]],"ltp":1.48,"tv":11426.1,"id":9629022}],"tv":29233.36}]}
{"op":"mcm","clk":"4215205101","pt":1631535931363,"mc":[{"id":"1.187557985","rc":[{"batl":[[0,3.45,2.32],[1,3.65,153.49],[2,3.7,143.11]],"ltp":3.1,"tv":17807.26,"id":5300820},{"batb":[[1,1.37,350.13],[2,1.36,660.53]],"batl":[[0,1.56,306.33],[1,1.57,376.3],[2,1.58,323.46]],"ltp":1.48,"tv":11426.1,"id":9629022}]}]}
{"op":"mcm","clk":"4215205298","pt":1631535933626,"mc":[{"id":"1.187557985","rc":[{"batb":[[0,2.8,235.15],[1,2.78,214.53],[2,2.76,232.88]],"ltp":3.1,"tv":17807.26,"id":5300820},{"batb":[[0,1.47,31.85],[2,1.36,933.41]],"batl":[[0,1.55,139.04],[1,1.56,461.1],[2,1.57,376.3]],"ltp":1.48,"tv":11426.1,"id":9629022}]}]}
{"op":"mcm","clk":"4215205355","pt":1631535934253,"mc":[{"id":"1.187557985","rc":[{"batb":[[0,2.82,3],[1,2.8,238.15],[2,2.78,214.53]],"ltp":3.1,"tv":17807.26,"id":5300820},{"batl":[[0,1.55,145.04]],"ltp":1.48,"tv":11426.1,"id":9629022}]}]}
{"op":"mcm","clk":"4215205449","pt":1631535935452,"mc":[{"id":"1.187557985","rc":[{"batl":[[1,3.9,160.43],[2,990,0.01]],"ltp":3.1,"tv":17807.26,"id":5300820},{"batb":[[1,1.37,4],[2,1.36,257.49]],"ltp":1.48,"tv":11426.1,"id":9629022}]}]}
{"op":"mcm","clk":"4215205536","pt":1631535936443,"mc":[{"id":"1.187557985","rc":[{"batb":[[1,1.38,321.11],[2,1.37,4]],"ltp":1.48,"tv":11426.1,"id":9629022}]}]}
{"op":"mcm","clk":"4215205601","pt":1631535937168,"mc":[{"id":"1.187557985","rc":[{"batb":[[2,2.78,218.53]],"ltp":3.1,"tv":17807.26,"id":5300820},{"batb":[[1,1.38,642.22]],"ltp":1.48,"tv":11426.1,"id":9629022}]}]}
{"op":"mcm","clk":"4215205717","pt":1631535938567,"mc":[{"id":"1.187557985","rc":[{"trd":[[2.8,18.09],[2.82,6]],"batb":[[0,2.8,230.34],[1,2.78,214.53],[2,2.76,232.88]],"ltp":2.8,"tv":17822.88,"id":5300820},{"batb":[[0,1.51,223.99],[1,1.5,182.31],[2,1.49,1283.56]],"batl":[[0,1.55,139.04],[2,1.57,1594.44]],"ltp":1.48,"tv":11426.1,"id":9629022}],"tv":29248.98}]}
{"op":"mcm","clk":"4215205806","pt":1631535939461,"mc":[{"id":"1.187557985","rc":[{"batb":[[2,2.76,249.92]],"batl":[[0,3.1,20.7],[1,3.4,179.06],[2,3.45,2.32]],"ltp":2.8,"tv":17822.88,"id":5300820},{"batb":[[0,1.51,390.1]],"batl":[[2,1.57,1624.44]],"ltp":1.48,"tv":11426.1,"id":9629022}]}]}
{"op":"mcm","clk":"4215205892","pt":1631535940561,"mc":[{"id":"1.187557985","rc":[{"batl":[[1,3.4,11.6]],"ltp":2.8,"tv":17822.88,"id":5300820}]}]}
{"op":"mcm","clk":"4215205992","pt":1631535941553,"mc":[{"id":"1.187557985","rc":[{"batl":[[1,3.45,2.32],[2,3.9,160.43]],"ltp":2.8,"tv":17822.88,"id":5300820}]}]}
{"op":"mcm","clk":"4215206235","pt":1631535944566,"mc":[{"id":"1.187557985","rc":[{"batl":[[0,3.05,26.28],[1,3.1,20.7],[2,3.45,2.32]],"ltp":2.8,"tv":17822.88,"id":5300820}]}]}
{"op":"mcm","clk":"4215206402","pt":1631535946656,"mc":[{"id":"1.187557985","rc":[{"batb":[[2,2.76,232.88]],"batl":[[0,3.45,2.32],[1,3.9,160.43],[2,990,0.01]],"ltp":2.8,"tv":17822.88,"id":5300820},{"batl":[[2,1.57,1594.44]],"ltp":1.48,"tv":11426.1,"id":9629022}]}]}
{"op":"mcm","clk":"4215206575","pt":1631535948588,"mc":[{"id":"1.187557985","rc":[{"trd":[[1.51,456.37]],"batb":[[0,1.51,359.31]],"ltp":1.51,"tv":11487.68,"id":9629022}],"tv":29310.56}]}
{"op":"mcm","clk":"4215206659","pt":1631535949472,"mc":[{"id":"1.187557985","rc":[{"batl":[[0,3.05,20.95],[1,3.45,2.32],[2,3.9,160.43]],"ltp":2.8,"tv":17822.88,"id":5300820},{"trd":[[1.51,520.01]],"batb":[[0,1.51,327.49]],"ltp":1.51,"tv":11551.32,"id":9629022}],"tv":29374.2}]}
{"op":"mcm","clk":"4215206714","pt":1631535950199,"mc":[{"id":"1.187557985","rc":[{"batb":[[1,1.5,224.73]],"ltp":1.51,"tv":11551.32,"id":9629022}]}]}
{"op":"mcm","clk":"4215206826","pt":1631535951664,"mc":[{"id":"1.187557985","rc":[{"trd":[[1.51,520.09]],"batb":[[0,1.51,327.45],[2,1.48,64.73]],"batl":[[2,1.57,376.3]],"ltp":1.51,"tv":11551.39,"id":9629022}],"tv":29374.28}]}
{"op":"mcm","clk":"4215206910","pt":1631535952659,"mc":[{"id":"1.187557985","rc":[{"batb":[[0,2.72,17.44],[1,2.44,68.37],[2,2.12,394.01]],"ltp":2.8,"tv":17822.88,"id":5300820},{"batb":[[0,1.5,42.42],[1,1.47,6.83],[2,1.39,237.49]],"batl":[[0,1.58,30],[1,1.83,2.52],[2,990,0.15]],"ltp":1.51,"tv":11551.39,"id":9629022}]}]}
{"op":"mcm","clk":"4215206972","pt":1631535953595,"mc":[{"id":"1.187557985","rc":[{"batb":[[0,2.44,68.37],[1,2.12,394.01],[2,2.04,7.49]],"batl":[[0,3.45,2.32],[1,3.9,160.43],[2,990,0.01]],"ltp":2.8,"tv":17822.88,"id":5300820},{"batb":[[0,1.47,6.83],[1,1.39,237.49],[2,1.37,4]],"batl":[[0,1.83,2.52],[1,990,0.15],[2,990,0]],"ltp":1.51,"tv":11551.39,"id":9629022}]}]}
{"op":"mcm","clk":"4215207059","pt":1631535954585,"mc":[{"id":"1.187557985","rc":[{"batb":[[0,2.44,74.29]],"ltp":2.8,"tv":17822.88,"id":5300820},{"batb":[[1,1.4,321.11],[2,1.39,237.49]],"batl":[[0,1.69,39.69],[1,1.83,2.32],[2,990,0.15]],"ltp":1.51,"tv":11551.39,"id":9629022}]}]}
{"op":"mcm","clk":"4215207120","pt":1631535955370,"mc":[{"id":"1.187557985","rc":[{"batl":[[1,3.55,3],[2,3.9,160.43]],"ltp":2.8,"tv":17822.88,"id":5300820},{"batb":[[1,1.4,642.22]],"batl":[[0,1.69,189.99],[1,1.71,225.84],[2,1.83,2.32]],"ltp":1.51,"tv":11551.39,"id":9629022}]}]}
{"op":"mcm","clk":"4215207148","pt":1631535955798,"mc":[{"id":"1.187557985","rc":[{"batl":[[0,1.69,39.69],[1,1.83,2.32],[2,990,0.15]],"ltp":1.51,"tv":11551.39,"id":9629022}]}]}
{"op":"mcm","clk":"4215207286","pt":1631535957467,"mc":[{"id":"1.187557985","rc":[{"batb":[[0,2.44,77.29],[1,2.42,4],[2,2.12,394.01]],"ltp":2.8,"tv":17822.88,"id":5300820},{"batl":[[0,1.65,5.19],[1,1.69,44.5],[2,1.7,5]],"ltp":1.51,"tv":11551.39,"id":9629022}]}]}
{"op":"mcm","clk":"4215207430","pt":1631535959564,"mc":[{"id":"1.187557985","rc":[{"batb":[[0,2.52,471.88],[1,2.44,77.29],[2,2.42,4]],"ltp":2.8,"tv":17822.88,"id":5300820},{"batb":[[0,1.51,189.37],[1,1.5,182.32],[2,1.47,6.83]],"batl":[[0,1.55,172.86],[1,1.56,154.78],[2,1.65,5.19]],"ltp":1.51,"tv":11551.39,"id":9629022}]}]}
{"op":"mcm","clk":"4215207523","pt":1631535960568,"mc":[{"id":"1.187557985","rc":[{"batb":[[0,2.44,77.29],[1,2.42,4],[2,2.12,394.01]],"ltp":2.8,"tv":17822.88,"id":5300820},{"batb":[[0,1.47,6.83],[1,1.4,642.22],[2,1.39,237.49]],"batl":[[0,1.65,5.19],[1,1.69,44.5],[2,1.7,5]],"ltp":1.51,"tv":11551.39,"id":9629022}]}]}
{"op":"mcm","clk":"4215207531","pt":1631535960671,"mc":[{"id":"1.187557985","rc":[{"batb":[[0,2.52,3],[1,2.5,3],[2,2.44,77.29]],"ltp":2.8,"tv":17822.88,"id":5300820}]}]}
{"op":"mcm","clk":"4215207731","pt":1631535963293,"mc":[{"id":"1.187557985","rc":[{"batl":[[1,1.69,194.8]],"ltp":1.51,"tv":11551.39,"id":9629022}]}]}
{"op":"mcm","clk":"4215208167","pt":1631535969505,"mc":[{"id":"1.187557985","rc":[{"batb":[[2,2.44,74.29]],"ltp":2.8,"tv":17822.88,"id":5300820},{"batl":[[1,1.69,189.8],[2,1.71,225.84]],"ltp":1.51,"tv":11551.39,"id":9629022}]}]}
{"op":"mcm","clk":"4215208319","pt":1631535971591,"mc":[{"id":"1.187557985","rc":[{"batb":[[0,2.44,74.29],[1,2.04,7.49],[2,1.2,62]],"batl":[[2,990,0.01]],"ltp":2.8,"tv":17822.88,"id":5300820},{"batb":[[0,1.64,2870.42],[1,1.47,6.83],[2,1.4,642.22]],"batl":[[0,1.69,189.99],[1,1.71,225.84],[2,1.83,2.32]],"ltp":1.51,"tv":11551.39,"id":9629022}]}]}
{"op":"mcm","clk":"4215208407","pt":1631535972583,"mc":[{"id":"1.187557985","rc":[{"trd":[[2.44,22.98],[2.52,0.13]],"batb":[[0,2.44,65.71],[1,2.38,441.96],[2,2.36,428.97]],"batl":[[0,2.66,530.08],[1,2.68,265.04],[2,2.7,265.04]],"ltp":2.44,"tv":17840.16,"id":5300820},{"trd":[[1.65,188.33]],"batb":[[0,1.64,183.21],[1,1.63,133.28],[2,1.56,10.22]],"batl":[[0,1.69,189.8],[2,1.73,9.22]],"ltp":1.65,"tv":11551.59,"id":9629022}],"tv":29391.75}]}
{"op":"mcm","clk":"4215208488","pt":1631535973626,"mc":[{"id":"1.187557985","rc":[{"batb":[[1,2.42,21.12],[2,2.38,441.96]],"batl":[[1,2.68,288.18]],"ltp":2.44,"tv":17840.16,"id":5300820},{"batb":[[0,1.64,305.72],[2,1.6,38.72]],"batl":[[1,1.71,255.84]],"ltp":1.65,"tv":11551.59,"id":9629022}]}]}
{"op":"mcm","clk":"4215208537","pt":1631535974302,"mc":[{"id":"1.187557985","rc":[{"batb":[[2,2.38,445.96]],"ltp":2.44,"tv":17840.16,"id":5300820}]}]}
{"op":"mcm","clk":"4215208605","pt":1631535975289,"mc":[{"id":"1.187557985","rc":[{"batl":[[0,2.64,3],[1,2.66,530.08],[2,2.68,288.18]],"ltp":2.44,"tv":17840.16,"id":5300820}]}]}
{"op":"mcm","clk":"4215208767","pt":1631535977533,"mc":[{"id":"1.187557985","rc":[{"trd":[[2.48,293.06]],"batl":[[2,2.68,265.04]],"ltp":2.48,"tv":17841.53,"id":5300820},{"trd":[[1.67,25.36]],"batb":[[2,1.56,10.22]],"ltp":1.67,"tv":11557.59,"id":9629022}],"tv":29399.12}]}
{"op":"mcm","clk":"4215208992","pt":1631535980618,"mc":[{"id":"1.187557985","rc":[{"batl":[[0,2.6,31.31],[1,2.64,26.42],[2,2.66,530.08]],"ltp":2.48,"tv":17841.53,"id":5300820},{"batb":[[2,1.61,38.41]],"ltp":1.67,"tv":11557.59,"id":9629022}]}]}
{"op":"mcm","clk":"4215209055","pt":1631535981400,"mc":[{"id":"1.187557985","rc":[{"batl":[[0,2.64,26.42],[1,2.66,530.08],[2,2.68,265.04]],"ltp":2.48,"tv":17841.53,"id":5300820}]}]}
{"op":"mcm","clk":"4215209138","pt":1631535982607,"mc":[{"id":"1.187557985","rc":[{"trd":[[1.64,54.72]],"batb":[[0,1.64,304.47]],"ltp":1.64,"tv":11560.09,"id":9629022}],"tv":29401.62}]}
{"op":"mcm","clk":"4215209242","pt":1631535983901,"mc":[{"id":"1.187557985","rc":[{"batl":[[0,2.62,31.31],[1,2.64,26.42],[2,2.66,530.08]],"ltp":2.48,"tv":17841.53,"id":5300820}]}]}
{"op":"mcm","clk":"4215209440","pt":1631535986617,"mc":[{"id":"1.187557985","rc":[{"batb":[[2,2.38,405.78]],"ltp":2.48,"tv":17841.53,"id":5300820}]}]}
{"op":"mcm","clk":"4215209497","pt":1631535987141,"mc":[{"id":"1.187557985","rc":[{"batb":[[0,2.42,21.12],[1,2.2,90.63],[2,2.04,7.49]],"batl":[[0,2.64,23.42],[1,3.45,185.21],[2,2.66,0]],"ltp":2.48,"tv":17841.53,"id":5300820},{"batb":[[0,1.61,38.41],[1,1.51,164.52],[2,1.48,6]],"batl":[[0,1.71,30],[1,1.83,2.32],[2,2,0.14]],"ltp":1.64,"tv":11560.09,"id":9629022}]}]}
{"op":"mcm","clk":"4215209592","pt":1631535988402,"mc":[{"id":"1.187557985","rc":[{"batb":[[0,2.2,90.63],[1,2.04,7.49],[2,1.92,400.36]],"batl":[[0,3.45,185.21],[1,3.45,0]],"ltp":2.48,"tv":17841.53,"id":5300820},{"batb":[[0,1.51,164.52],[1,1.48,6],[2,1.37,4]],"batl":[[0,1.83,2.32],[1,2,0.14],[2,2,0]],"ltp":1.64,"tv":11560.09,"id":9629022}]}]}
{"op":"mcm","clk":"4215209740","pt":1631535990549,"mc":[{"id":"1.187557985","rc":[{"batb":[[0,2.2,91.35]],"ltp":2.48,"tv":17841.53,"id":5300820},{"batb":[[0,1.52,163.85]],"batl":[[0,1.83,162.09],[1,1.85,175.21],[2,2,0.14]],"ltp":1.64,"tv":11560.09,"id":9629022}]}]}
{"op":"mcm","clk":"4215209826","pt":1631535991604,"mc":[{"id":"1.187557985","rc":[{"batb":[[0,2.2,95.35],[1,2.18,4],[2,2.04,7.49]],"batl":[[0,2.98,4],[1,3.45,185.21]],"ltp":2.48,"tv":17841.53,"id":5300820},{"batb":[[1,1.51,2],[2,1.5,3]],"batl":[[0,1.83,166.09]],"ltp":1.64,"tv":11560.09,"id":9629022}]}]}
{"op":"mcm","clk":"4215209894","pt":1631535992649,"mc":[{"id":"1.187557985","rc":[{"batb":[[0,2.2,90.63],[1,2.04,7.49],[2,1.92,400.36]],"batl":[[1,3.45,2.32]],"ltp":2.48,"tv":17841.53,"id":5300820},{"batl":[[0,1.83,162.09]],"ltp":1.64,"tv":11560.09,"id":9629022}]}]}
{"op":"mcm","clk":"4215209953","pt":1631535993440,"mc":[{"id":"1.187557985","rc":[{"trd":[[2.2,20.22],[2.38,55.02]],"batb":[[0,2.2,81.27]],"batl":[[0,2.94,3],[1,2.98,4],[2,3.45,2.32]],"ltp":2.2,"tv":17862.77,"id":5300820},{"trd":[[1.72,123.92]],"batb":[[0,1.77,148],[1,1.75,1300.1],[2,1.74,1060.72]],"batl":[[1,1.84,8.66],[2,1.85,175.21]],"ltp":1.72,"tv":11563.59,"id":9629022}],"tv":29426.36}]}
{"op":"mcm","clk":"4215210055","pt":1631535994653,"mc":[{"id":"1.187557985","rc":[{"batb":[[1,2.18,25.42],[2,2.04,120.79]],"ltp":2.2,"tv":17862.77,"id":5300820},{"batb":[[0,1.77,242.98]],"batl":[[1,1.84,38.66]],"ltp":1.72,"tv":11563.59,"id":9629022}]}]}
{"op":"mcm","clk":"4215210131","pt":1631535995636,"mc":[{"id":"1.187557985","rc":[{"batb":[[0,2.2,106.35],[2,2.16,4]],"batl":[[0,2.4,25.35],[1,2.6,20],[2,2.92,3]],"ltp":2.2,"tv":17862.77,"id":5300820},{"trd":[[1.77,172.74]],"batb":[[0,1.77,227.98]],"batl":[[0,1.83,190.03]],"ltp":1.77,"tv":11593.59,"id":9629022}],"tv":29456.36}]}
{"op":"mcm","clk":"4215210150","pt":1631535995947,"mc":[{"id":"1.187557985","rc":[{"batl":[[1,2.92,3],[2,2.94,3]],"ltp":2.2,"tv":17862.77,"id":5300820}]}]}
{"op":"mcm","clk":"4215210371","pt":1631535998621,"mc":[{"id":"1.187557985","rc":[{"trd":[[2.2,23.19]],"batb":[[0,2.2,104.87]],"ltp":2.2,"tv":17865.73,"id":5300820},{"trd":[[1.77,261.02],[1.83,10.14]],"batb":[[0,1.77,94.98],[1,1.75,1092.86]],"batl":[[0,1.83,188.2]],"ltp":1.77,"tv":11685.53,"id":9629022}],"tv":29551.26}]}
{"op":"mcm","clk":"4215210452","pt":1631535999616,"mc":[{"id":"1.187557985","rc":[{"batl":[[0,2.38,35.38],[1,2.4,25.35],[2,2.92,3]],"ltp":2.2,"tv":17865.73,"id":5300820}]}]}
{"op":"mcm","clk":"4215210501","pt":1631536000348,"mc":[{"id":"1.187557985","rc":[{"batl":[[0,2.92,3],[1,2.94,3],[2,2.98,4]],"ltp":2.2,"tv":17865.73,"id":5300820}]}]}
{"op":"mcm","clk":"4215210618","pt":1631536001664,"mc":[{"id":"1.187557985","rc":[{"trd":[[1.77,361.05]],"batb":[[0,1.77,44.95],[1,1.76,218.2],[2,1.75,1092.86]],"batl":[[0,1.83,219.9]],"ltp":1.77,"tv":11785.56,"id":9629022}],"tv":29651.3}]}
{"op":"mcm","clk":"4215210686","pt":1631536002512,"mc":[{"id":"1.187557985","rc":[{"batb":[[0,2.2,105.59]],"ltp":2.2,"tv":17865.73,"id":5300820}]}]}
{"op":"mcm","clk":"4215210770","pt":1631536003622,"mc":[{"id":"1.187557985","rc":[{"batl":[[0,2.38,25.53],[1,2.6,35.38],[2,2.76,398.04]],"ltp":2.2,"tv":17865.73,"id":5300820},{"trd":[[1.77,363.55]],"batb":[[0,1.77,43.7],[2,1.74,211.68]],"ltp":1.77,"tv":11788.06,"id":9629022}],"tv":29653.8}]}
{"op":"mcm","clk":"4215210836","pt":1631536004464,"mc":[{"id":"1.187557985","rc":[{"batb":[[0,2.22,1.45],[2,2.04,120.04]],"batl":[[1,2.92,3],[2,2.94,3]],"ltp":2.2,"tv":17865.73,"id":5300820},{"batb":[[0,1.73,35.11],[1,1.64,122.93],[2,1.53,5]],"batl":[[0,1.84,30.49],[1,2,0.14],[2,1.85,0]],"ltp":1.77,"tv":11788.06,"id":9629022}]}]}
{"op":"mcm","clk":"4215210923","pt":1631536005657,"mc":[{"id":"1.187557985","rc":[{"batb":[[0,2.22,2.17],[1,2.04,120.04],[2,1.92,400.36]],"batl":[[0,2.92,3],[1,3.15,203.19],[2,3.45,2.32]],"ltp":2.2,"tv":17865.73,"id":5300820},{"batb":[[0,1.64,122.93],[1,1.53,5],[2,1.52,7]],"batl":[[0,2,0.63],[1,2,0]],"ltp":1.77,"tv":11788.06,"id":9629022}]}]}
{"op":"mcm","clk":"4215210994","pt":1631536006657,"mc":[{"id":"1.187557985","rc":[{"batb":[[1,1.63,236.33],[2,1.62,136.58]],"batl":[[0,1.96,172.11],[1,1.98,142.57],[2,2,0.14]],"ltp":1.77,"tv":11788.06,"id":9629022}]}]}
{"op":"mcm","clk":"4215211145","pt":1631536008648,"mc":[{"id":"1.187557985","rc":[{"batl":[[0,2.58,2],[1,2.92,3],[2,3.15,203.19]],"ltp":2.2,"tv":17865.73,"id":5300820},{"batb":[[0,1.64,125.93],[1,1.63,238.33]],"batl":[[0,1.96,172.21]],"ltp":1.77,"tv":11788.06,"id":9629022}]}]}
{"op":"mcm","clk":"4215211152","pt":1631536008753,"mc":[{"id":"1.187557985","rc":[{"batb":[[0,2.04,120.04],[1,1.92,400.36],[2,1.2,62]],"ltp":2.2,"tv":17865.73,"id":5300820}]}]}
{"op":"mcm","clk":"4215211236","pt":1631536010263,"mc":[{"id":"1.187557985","rc":[{"trd":[[2.2,23.6],[2.28,0.07]],"batl":[[0,2.2,42.11],[1,2.58,2],[2,2.92,3]],"ltp":2.2,"tv":17866.21,"id":5300820},{"trd":[[1.77,363.64],[1.83,10.63]],"batb":[[1,1.63,2],[2,1.53,5]],"batl":[[0,1.96,171.62]],"ltp":1.83,"tv":11788.65,"id":9629022}],"tv":29654.86}]}
{"op":"mcm","clk":"4215211419","pt":1631536012576,"mc":[{"id":"1.187557985","rc":[{"batb":[[0,2.08,2.17],[1,2.04,124.04],[2,2.02,4]],"batl":[[0,2.2,2747.1],[1,2.32,12.36],[2,2.58,2]],"ltp":2.2,"tv":17866.21,"id":5300820},{"batl":[[0,1.96,175.62]],"ltp":1.83,"tv":11788.65,"id":9629022}]}]}
{"op":"mcm","clk":"4215211510","pt":1631536013571,"mc":[{"id":"1.187557985","rc":[{"trd":[[2.04,65.5],[2.08,190.17]],"batb":[[0,2.04,112.3],[1,1.2,62],[2,1.06,2.07]],"batl":[[0,2.58,2],[1,2.92,3],[2,3.45,2.32]],"ltp":2.04,"tv":17886.02,"id":5300820},{"batb":[[0,1.89,121.41],[1,1.87,1189.92],[2,1.86,992.66]],"batl":[[0,1.94,8.22],[1,1.96,175.69],[2,1.98,142.57]],"ltp":1.83,"tv":11788.65,"id":9629022}],"tv":29674.67}]}
{"op":"mcm","clk":"4215211607","pt":1631536014570,"mc":[{"id":"1.187557985","rc":[{"batb":[[0,2.04,139.53],[1,1.93,67.53],[2,1.2,62]],"batl":[[0,2.18,60.01],[1,2.58,2],[2,2.92,3]],"ltp":2.04,"tv":17886.02,"id":5300820},{"batb":[[1,1.88,77.82],[2,1.87,1189.92]],"batl":[[1,1.96,203.21]],"ltp":1.83,"tv":11788.65,"id":9629022}]}]}
{"op":"mcm","clk":"4215211659","pt":1631536015352,"mc":[{"id":"1.187557985","rc":[{"batl":[[0,2.46,246.86]],"ltp":2.04,"tv":17886.02,"id":5300820}]}]}
{"op":"mcm","clk":"4215211778","pt":1631536017079,"mc":[{"id":"1.187557985","rc":[{"batb":[[2,1.74,409.86]],"batl":[[2,2.92,227.31]],"ltp":2.04,"tv":17886.02,"id":5300820}]}]}
{"op":"mcm","clk":"4215211916","pt":1631536018650,"mc":[{"id":"1.187557985","rc":[{"batb":[[1,1.99,30.15],[2,1.93,67.53]],"batl":[[0,2.16,27.85]],"ltp":2.04,"tv":17886.02,"id":5300820},{"trd":[[1.89,75.8]],"batb":[[0,1.88,77.82],[1,1.87,1022.72],[2,1.86,992.66]],"batl":[[1,1.96,31.59],[2,2,956.4]],"ltp":1.89,"tv":11864.45,"id":9629022}],"tv":29750.47}]}
{"op":"mcm","clk":"4215211978","pt":1631536019481,"mc":[{"id":"1.187557985","rc":[{"batl":[[1,2.56,2],[2,2.58,2]],"ltp":2.04,"tv":17886.02,"id":5300820}]}]}
{"op":"mcm","clk":"4215212052","pt":1631536020480,"mc":[{"id":"1.187557985","rc":[{"batb":[[1,2,25.65],[2,1.99,30.15]],"batl":[[1,2.3,6.55],[2,2.4,5.84]],"ltp":2.04,"tv":17886.02,"id":5300820},{"batl":[[2,2,981.57]],"ltp":1.89,"tv":11864.45,"id":9629022}]}]}
{"op":"mcm","clk":"4215212142","pt":1631536021583,"mc":[{"id":"1.187557985","rc":[{"batb":[[0,1.88,293.44],[2,1.86,1162.88]],"batl":[[1,1.95,119.26],[2,1.96,31.59]],"ltp":1.89,"tv":11864.45,"id":9629022}]}]}
{"op":"mcm","clk":"4215212253","pt":1631536023158,"mc":[{"id":"1.187557985","rc":[{"trd":[[2.06,178.84]],"ltp":2.06,"tv":17887.72,"id":5300820},{"trd":[[1.94,61.79]],"batl":[[0,1.94,4.65]],"ltp":1.94,"tv":11869.79,"id":9629022}],"tv":29757.51}]}
{"op":"mcm","clk":"4215212354","pt":1631536024466,"mc":[{"id":"1.187557985","rc":[{"batl":[[0,2.16,60.25]],"ltp":2.06,"tv":17887.72,"id":5300820}]}]}
{"op":"mcm","clk":"4215212437","pt":1631536025462,"mc":[{"id":"1.187557985","rc":[{"batl":[[0,2.16,27.85]],"ltp":2.06,"tv":17887.72,"id":5300820}]}]}
{"op":"mcm","clk":"4215212680","pt":1631536028655,"mc":[{"id":"1.187557985","rc":[{"trd":[[2.06,178.84]],"batl":[[0,2.16,52.67]],"ltp":2.06,"tv":17887.72,"id":5300820},{"trd":[[1.88,122.18],[1.94,71.08]],"batb":[[0,1.94,2.19],[1,1.88,260.54],[2,1.87,1022.72]],"batl":[[0,1.95,119.26],[1,1.96,31.59],[2,1.97,144.85]],"ltp":1.94,"tv":11944.86,"id":9629022}],"tv":29832.58}]}
{"op":"mcm","clk":"4215212765","pt":1631536029858,"mc":[{"id":"1.187557985","rc":[{"batl":[[0,2.06,42.59],[1,2.16,52.67],[2,2.3,6.55]],"ltp":2.06,"tv":17887.72,"id":5300820}]}]}
{"op":"mcm","clk":"4215212882","pt":1631536031269,"mc":[{"id":"1.187557985","rc":[{"trd":[[1.94,73.58]],"batb":[[0,1.88,261.48],[1,1.87,1022.72],[2,1.86,1162.88]],"ltp":1.94,"tv":11947.36,"id":9629022}],"tv":29835.08}]}
{"op":"mcm","clk":"4215212964","pt":1631536032314,"mc":[{"id":"1.187557985","rc":[{"trd":[[2.06,180.02]],"batl":[[0,2.16,52.67],[1,2.3,6.55],[2,2.4,5.84]],"ltp":2.06,"tv":17888.9,"id":5300820},{"trd":[[1.94,76.71]],"batb":[[0,1.88,260.54]],"ltp":1.94,"tv":11950.49,"id":9629022}],"tv":29839.39}]}
{"op":"mcm","clk":"4215213068","pt":1631536033664,"mc":[{"id":"1.187557985","rc":[{"trd":[[1.88,122.2]],"batb":[[0,1.88,260.53]],"ltp":1.88,"tv":11950.51,"id":9629022}],"tv":29839.41}]}
{"op":"mcm","clk":"4215213127","pt":1631536034601,"mc":[{"id":"1.187557985","rc":[{"batl":[[0,2.06,5],[1,2.16,52.67],[2,2.3,6.55]],"ltp":2.06,"tv":17888.9,"id":5300820}]}]}
{"op":"mcm","clk":"4215213164","pt":1631536035076,"mc":[{"id":"1.187557985","rc":[{"trd":[[2.06,183.78]],"batl":[[0,2.06,1.24],[1,2.16,24.82]],"ltp":2.06,"tv":17892.66,"id":5300820},{"trd":[[1.94,80.71]],"ltp":1.94,"tv":11954.51,"id":9629022}],"tv":29847.17}]}
{"op":"mcm","clk":"4215213326","pt":1631536037375,"mc":[{"id":"1.187557985","rc":[{"trd":[[2.06,185.02]],"batl":[[0,2.3,6.55],[1,2.4,5.84],[2,2.44,5.58]],"ltp":2.06,"tv":17893.9,"id":5300820},{"trd":[[1.94,82.03]],"ltp":1.94,"tv":11955.83,"id":9629022}],"tv":29849.73}]}
{"op":"mcm","clk":"4215213529","pt":1631536040495,"mc":[{"id":"1.187557985","rc":[{"batl":[[0,2.28,426.32],[1,2.3,6.55],[2,2.4,5.84]],"ltp":2.06,"tv":17893.9,"id":5300820},{"batl":[[0,1.93,2.11],[1,1.95,119.26],[2,1.96,31.59]],"ltp":1.94,"tv":11955.83,"id":9629022}]}]}
{"op":"mcm","clk":"4215213555","pt":1631536040808,"mc":[{"id":"1.187557985","rc":[{"batl":[[0,2.3,6.55],[1,2.4,5.84],[2,2.44,5.58]],"ltp":2.06,"tv":17893.9,"id":5300820}]}]}
{"op":"mcm","clk":"4215213629","pt":1631536041804,"mc":[{"id":"1.187557985","rc":[{"batl":[[0,2.16,27.85],[1,2.3,6.55],[2,2.4,5.84]],"ltp":2.06,"tv":17893.9,"id":5300820}]}]}
{"op":"mcm","clk":"4215213897","pt":1631536045573,"mc":[{"id":"1.187557985","rc":[{"batl":[[1,1.94,9.76],[2,1.95,119.26]],"ltp":1.94,"tv":11955.83,"id":9629022}]}]}
{"op":"mcm","clk":"4215213966","pt":1631536046616,"mc":[{"id":"1.187557985","rc":[{"trd":[[1.88,222.23]],"batb":[[0,1.88,210.5]],"ltp":1.88,"tv":12055.86,"id":9629022}],"tv":29949.76}]}
{"op":"mcm","clk":"4215214124","pt":1631536048497,"mc":[{"id":"1.187557985","rc":[{"batb":[[0,2.04,112.3]],"batl":[[1,2.4,5.84],[2,2.44,5.58]],"ltp":2.06,"tv":17893.9,"id":5300820},{"batb":[[0,1.88,26.86],[1,1.84,2],[2,1.8,89.12]],"batl":[[0,1.94,9.76],[1,1.96,4.07],[2,2,25.31]],"ltp":1.88,"tv":12055.86,"id":9629022}]}]}
{"op":"mcm","clk":"4215214176","pt":1631536049485,"mc":[{"id":"1.187557985","rc":[{"batb":[[0,2,25.65],[1,1.99,30.15],[2,1.97,35.17]],"batl":[[2,2.56,2]],"ltp":2.06,"tv":17893.9,"id":5300820},{"batb":[[0,1.88,31.98],[1,1.8,89.12],[2,1.72,29.59]],"batl":[[1,2,25.31],[2,2.02,29.7]],"ltp":1.88,"tv":12055.86,"id":9629022}]}]}
{"op":"mcm","clk":"4215214234","pt":1631536050420,"mc":[{"id":"1.187557985","rc":[{"batb":[[1,1.97,35.17],[2,1.95,30.51]],"batl":[[0,2.4,5.84],[1,2.56,2],[2,2.92,224.31]],"ltp":2.06,"tv":17893.9,"id":5300820},{"batb":[[0,1.8,89.12],[1,1.72,29.59],[2,1.37,4]],"batl":[[2,2.04,7.88]],"ltp":1.88,"tv":12055.86,"id":9629022}]}]}
{"op":"mcm","clk":"4215214301","pt":1631536051521,"mc":[{"id":"1.187557985","rc":[{"batb":[[0,1.8,252.14],[1,1.78,196.09],[2,1.72,29.59]],"ltp":1.88,"tv":12055.86,"id":9629022}]}]}
{"op":"mcm","clk":"4215214374","pt":1631536052590,"mc":[{"id":"1.187557985","rc":[{"batb":[[0,2,28.65],[1,1.99,5],[2,1.97,35.17]],"ltp":2.06,"tv":17893.9,"id":5300820},{"batb":[[0,1.8,89.12],[1,1.72,29.59],[2,1.37,4]],"batl":[[0,1.94,9.8]],"ltp":1.88,"tv":12055.86,"id":9629022}]}]}
{"op":"mcm","clk":"4215214446","pt":1631536053595,"mc":[{"id":"1.187557985","rc":[{"batl":[[0,2.26,3],[1,2.4,5.84],[2,2.56,2]],"ltp":2.06,"tv":17893.9,"id":5300820},{"batb":[[0,1.8,93.12],[1,1.79,5],[2,1.72,29.59]],"batl":[[0,1.88,20.54],[1,1.94,9.76],[2,2,25.31]],"ltp":1.88,"tv":12055.86,"id":9629022}]}]}
{"op":"mcm","clk":"4215214576","pt":1631536055496,"mc":[{"id":"1.187557985","rc":[{"trd":[[1.88,263.31]],"batb":[[0,1.91,119.99],[1,1.89,161.75],[2,1.8,93.12]],"batl":[[0,1.94,9.76],[1,1.98,159.19],[2,2,163.76]],"ltp":1.88,"tv":12096.94,"id":9629022}],"tv":29990.84}]}
{"op":"mcm","clk":"4215214644","pt":1631536056495,"mc":[{"id":"1.187557985","rc":[{"batb":[[0,2.02,28.09],[1,2,28.65],[2,1.99,5]],"ltp":2.06,"tv":17893.9,"id":5300820},{"batb":[[2,1.81,73.84]],"ltp":1.88,"tv":12096.94,"id":9629022}]}]}
{"op":"mcm","clk":"4215214781","pt":1631536058218,"mc":[{"id":"1.187557985","rc":[{"trd":[[1.91,20.28]],"batb":[[0,1.91,113.42]],"batl":[[0,1.98,159.19],[1,2,163.76],[2,2.04,7.88]],"ltp":1.91,"tv":12110.08,"id":9629022}],"tv":30003.98}]}
{"op":"mcm","clk":"4215214891","pt":1631536059637,"mc":[{"id":"1.187557985","rc":[{"batb":[[0,2,3],[1,1.99,5],[2,1.95,30.51]],"batl":[[0,2.24,29.2],[1,2.26,3],[2,2.4,5.84]],"ltp":2.06,"tv":17893.9,"id":5300820},{"batb":[[0,1.8,93.12],[1,1.79,5],[2,1.72,29.59]],"batl":[[0,2.06,7.89],[1,2,0],[2,2.04,0]],"ltp":1.91,"tv":12110.08,"id":9629022}]}]}
{"op":"mcm","clk":"4215214912","pt":1631536059848,"mc":[{"id":"1.187557985","rc":[{"batl":[[0,2.26,3],[1,2.4,5.84],[2,2.56,2]],"ltp":2.06,"tv":17893.9,"id":5300820}]}]}
{"op":"mcm","clk":"4215215161","pt":1631536062532,"mc":[{"id":"1.187557985","rc":[{"batb":[[0,1.8,252.29],[2,1.78,196.09]],"batl":[[0,2,3.14],[1,2.06,7.75],[2,2.08,138.17]],"ltp":1.91,"tv":12110.08,"id":9629022}]}]}
{"op":"mcm","clk":"4215215238","pt":1631536063421,"mc":[{"id":"1.187557985","rc":[{"batb":[[1,1.95,30.51],[2,1.94,66.44]],"batl":[[0,2.24,3],[1,2.26,3],[2,2.4,5.84]],"ltp":2.06,"tv":17893.9,"id":5300820},{"batb":[[2,1.78,232.75]],"batl":[[1,2.02,5],[2,2.06,7.75]],"ltp":1.91,"tv":12110.08,"id":9629022}]}]}
{"op":"mcm","clk":"4215215502","pt":1631536066605,"mc":[{"id":"1.187557985","rc":[{"batb":[[1,1.99,2],[2,1.95,30.51]],"batl":[[1,2.4,5.84],[2,2.92,224.31]],"ltp":2.06,"tv":17893.9,"id":5300820},{"batb":[[1,1.78,232.75],[2,1.72,29.59]],"ltp":1.91,"tv":12110.08,"id":9629022}]}]}
{"op":"mcm","clk":"4215215643","pt":1631536068333,"mc":[{"id":"1.187557985","rc":[{"batb":[[0,1.8,93.12],[1,1.72,29.59],[2,1.37,4]],"ltp":1.91,"tv":12110.08,"id":9629022}]}]}
{"op":"mcm","clk":"4215215723","pt":1631536069442,"mc":[{"id":"1.187557985","rc":[{"batb":[[0,1.95,30.51],[1,1.94,66.44],[2,1.74,409.86]],"batl":[[1,2.3,6.05],[2,2.4,5.84]],"ltp":2.06,"tv":17893.9,"id":5300820},{"batb":[[1,1.79,4],[2,1.72,29.59]],"batl":[[0,2.06,7.89],[1,2.02,0],[2,2.06,0]],"ltp":1.91,"tv":12110.08,"id":9629022}]}]}
{"op":"mcm","clk":"4215215815","pt":1631536070646,"mc":[{"id":"1.187557985","rc":[{"batl":[[1,2.4,5.84],[2,3.45,2.32]],"ltp":2.06,"tv":17893.9,"id":5300820},{"batb":[[0,1.98,2269.6],[1,1.8,93.12],[2,1.79,4]],"ltp":1.91,"tv":12110.08,"id":9629022}]}]}
{"op":"mcm","clk":"4215215888","pt":1631536071431,"mc":[{"id":"1.187557985","rc":[{"trd":[[1.95,20.34],[2,25.65]],"batb":[[0,1.96,8.14],[1,1.95,20.34],[2,1.94,70.55]],"batl":[[0,2,148.6],[1,2.02,134.69],[2,2.24,3]],"ltp":1.95,"tv":17914.38,"id":5300820},{"trd":[[2,19.51]],"batb":[[0,1.99,961.06],[1,1.98,932.8],[2,1.97,932.8]],"batl":[[0,2.06,7.75]],"ltp":2.0,"tv":12110.22,"id":9629022}],"tv":30024.6}]}
{"op":"mcm","clk":"4215215967","pt":1631536072435,"mc":[{"id":"1.187557985","rc":[{"batl":[[2,2.22,19]],"ltp":1.95,"tv":17914.38,"id":5300820},{"batb":[[0,1.99,1027.17],[1,1.98,963.1]],"batl":[[1,2.26,8.85]],"ltp":2.0,"tv":12110.22,"id":9629022}]}]}
{"op":"mcm","clk":"4215216214","pt":1631536075645,"mc":[{"id":"1.187557985","rc":[{"batl":[[0,2,178.6]],"ltp":1.95,"tv":17914.38,"id":5300820}]}]}
{"op":"mcm","clk":"4215216269","pt":1631536076332,"mc":[{"id":"1.187557985","rc":[{"trd":[[1.96,103.37],[2,43.88]],"batb":[[0,1.96,6.59]],"batl":[[0,2,160.37]],"ltp":1.96,"tv":17935.71,"id":5300820},{"trd":[[2,37.74],[2.06,9.85]],"batb":[[1,1.98,932.8]],"batl":[[0,2.06,6.29]],"ltp":2.06,"tv":12131.36,"id":9629022}],"tv":30067.08}]}
{"op":"mcm","clk":"4215216402","pt":1631536077971,"mc":[{"id":"1.187557985","rc":[{"batl":[[2,2.1,212.61]],"ltp":1.96,"tv":17935.71,"id":5300820},{"batl":[[1,2.2,191.59],[2,2.22,229.23]],"ltp":2.06,"tv":12131.36,"id":9629022}]}]}
{"op":"mcm","clk":"4215216544","pt":1631536079344,"mc":[{"id":"1.187557985","rc":[{"batb":[[0,2,30],[1,1.99,1027.17],[2,1.98,932.8]],"batl":[[1,2.14,7.75],[2,2.2,191.59]],"ltp":2.06,"tv":12131.36,"id":9629022}]}]}
{"op":"mcm","clk":"4215216901","pt":1631536083343,"mc":[{"id":"1.187557985","rc":[{"batl":[[0,2.06,7.14]],"ltp":2.06,"tv":12131.36,"id":9629022}]}]}
{"op":"mcm","clk":"4215217005","pt":1631536084621,"mc":[{"id":"1.187557985","rc":[{"batb":[[0,1.88,29.71],[1,1.84,299.72],[2,1.83,340.35]],"batl":[[0,2,30],[1,2.1,212.61],[2,2.12,233.5]],"ltp":1.96,"tv":17935.71,"id":5300820},{"batb":[[1,1.91,191.04],[2,1.9,228.43]],"batl":[[0,2.14,8.6],[1,2.2,191.59],[2,2.22,236.48]],"ltp":2.06,"tv":12131.36,"id":9629022}]}]}
{"op":"mcm","clk":"4215217064","pt":1631536085441,"mc":[{"id":"1.187557985","rc":[{"batb":[[0,1.84,299.72],[1,1.83,340.35],[2,1.82,349.9]],"batl":[[0,2.1,212.61],[1,2.12,233.5],[2,2.14,312.18]],"ltp":1.96,"tv":17935.71,"id":5300820},{"batb":[[0,1.91,191.04],[1,1.9,228.43],[2,1.89,401.72]],"batl":[[0,2.2,192.44],[1,2.22,236.48],[2,2.24,289.33]],"ltp":2.06,"tv":12131.36,"id":9629022}]}]}
{"op":"mcm","clk":"4215217249","pt":1631536087656,"mc":[{"id":"1.187557985","rc":[{"batl":[[1,2.12,402.11],[2,2.14,426.06]],"ltp":1.96,"tv":17935.71,"id":5300820}]}]}
{"op":"mcm","clk":"4215217318","pt":1631536088349,"mc":[{"id":"1.187557985","rc":[{"batb":[[0,1.88,4],[1,1.87,4],[2,1.84,304.72]],"batl":[[1,2.12,233.5],[2,2.14,312.18]],"ltp":1.96,"tv":17935.71,"id":5300820},{"batl":[[0,2.14,4.85],[1,2.2,194.59],[2,2.22,236.48]],"ltp":2.06,"tv":12131.36,"id":9629022}]}]}
{"op":"mcm","clk":"4215217512","pt":1631536090638,"mc":[{"id":"1.187557985","rc":[{"batb":[[2,1.86,4]],"ltp":1.96,"tv":17935.71,"id":5300820},{"batl":[[1,2.16,4],[2,2.2,194.59]],"ltp":2.06,"tv":12131.36,"id":9629022}]}]}
{"op":"mcm","clk":"4215217592","pt":1631536091642,"mc":[{"id":"1.187557985","rc":[{"trd":[[1.98,0.86],[2,48.52]],"batb":[[0,1.9,175.48],[1,1.88,195.77],[2,1.87,4]],"batl":[[0,1.97,110.13],[1,1.99,140.83],[2,2.1,212.61]],"ltp":1.98,"tv":17941.22,"id":5300820},{"trd":[[2.02,0.85]],"batl":[[0,2.14,10.75]],"ltp":2.02,"tv":12132.21,"id":9629022}],"tv":30073.43}]}
{"op":"mcm","clk":"4215217616","pt":1631536091960,"mc":[{"id":"1.187557985","rc":[{"batl":[[2,2.02,20]],"ltp":1.98,"tv":17941.22,"id":5300820}]}]}
{"op":"mcm","clk":"4215217725","pt":1631536093533,"mc":[{"id":"1.187557985","rc":[{"batb":[[0,1.88,31.21],[1,1.87,4],[2,1.86,4]],"batl":[[0,2.02,20],[1,2.1,212.61],[2,2.12,233.5]],"ltp":1.98,"tv":17941.22,"id":5300820}]}]}
{"op":"mcm","clk":"4215217785","pt":1631536094324,"mc":[{"id":"1.187557985","rc":[{"batb":[[0,1.88,4]],"ltp":1.98,"tv":17941.22,"id":5300820},{"batl":[[0,2.14,4]],"ltp":2.02,"tv":12132.21,"id":9629022}]}]}
{"op":"mcm","clk":"4215217964","pt":1631536096654,"mc":[{"id":"1.187557985","rc":[{"batb":[[0,1.89,5],[1,1.88,4],[2,1.87,4]],"batl":[[2,2.12,400.47]],"ltp":1.98,"tv":17941.22,"id":5300820}]}]}
{"op":"mcm","clk":"4215217993","pt":1631536097025,"mc":[{"id":"1.187557985","rc":[{"batb":[[0,1.88,35.46],[1,1.87,4],[2,1.86,4]],"ltp":1.98,"tv":17941.22,"id":5300820},{"batl":[[0,2.14,11.25]],"ltp":2.02,"tv":12132.21,"id":9629022}]}]}
{"op":"mcm","clk":"4215218066","pt":1631536097870,"mc":[{"id":"1.187557985","rc":[{"batb":[[0,1.88,4]],"ltp":1.98,"tv":17941.22,"id":5300820},{"batl":[[0,2.14,4]],"ltp":2.02,"tv":12132.21,"id":9629022}]}]}
{"op":"mcm","clk":"4215218248","pt":1631536100033,"mc":[{"id":"1.187557985","rc":[{"batb":[[1,1.86,4],[2,1.85,5]],"ltp":1.98,"tv":17941.22,"id":5300820},{"batl":[[0,2.16,4],[1,2.2,191.59],[2,2.22,236.48]],"ltp":2.02,"tv":12132.21,"id":9629022}]}]}
{"op":"mcm","clk":"4215218458","pt":1631536102579,"mc":[{"id":"1.187557985","rc":[{"batb":[[0,1.84,299.72],[1,1.83,340.35],[2,1.82,349.9]],"batl":[[1,2.22,4],[2,2.72,244.88]],"ltp":1.98,"tv":17941.22,"id":5300820},{"batb":[[0,1.89,76.65],[1,1.82,31.14],[2,1.81,5]],"batl":[[0,2.2,191.59],[1,2.22,236.48],[2,2.24,289.33]],"ltp":2.02,"tv":12132.21,"id":9629022}]}]}
{"op":"mcm","clk":"4215218529","pt":1631536103456,"mc":[{"id":"1.187557985","rc":[{"batl":[[2,3.45,2.32]],"ltp":1.98,"tv":17941.22,"id":5300820}]}]}
{"op":"mcm","clk":"4215218606","pt":1631536104561,"mc":[{"id":"1.187557985","rc":[{"batb":[[0,1.88,31.71],[1,1.84,299.72],[2,1.83,340.35]],"ltp":1.98,"tv":17941.22,"id":5300820},{"batl":[[0,2.14,7.25],[1,2.2,191.59],[2,2.22,236.48]],"ltp":2.02,"tv":12132.21,"id":9629022}]}]}
{"op":"mcm","clk":"4215218673","pt":1631536105571,"mc":[{"id":"1.187557985","rc":[{"trd":[[1.88,21.5]],"batb":[[0,1.86,8.57],[1,1.84,304.06]],"batl":[[0,1.88,178.73],[1,1.89,1011.9],[2,1.9,1144.2]],"ltp":1.88,"tv":17962.72,"id":5300820},{"batb":[[0,1.99,4],[1,1.98,3],[2,1.9,629.74]],"batl":[[0,2.2,191.59],[1,2.22,236.48],[2,2.24,289.33]],"ltp":2.02,"tv":12132.21,"id":9629022}],"tv":30094.93}]}
{"op":"mcm","clk":"4215218739","pt":1631536106657,"mc":[{"id":"1.187557985","rc":[{"batl":[[1,1.89,1041.9]],"ltp":1.88,"tv":17962.72,"id":5300820},{"trd":[[2.12,3.5]],"batb":[[0,2.12,25.03],[1,2.1,110.54],[2,2,128.45]],"ltp":2.12,"tv":12135.71,"id":9629022}],"tv":30098.44}]}
{"op":"mcm","clk":"4215218982","pt":1631536110377,"mc":[{"id":"1.187557985","rc":[{"batb":[[1,1.85,1.45],[2,1.84,304.06]],"batl":[[1,1.89,1011.9]],"ltp":1.88,"tv":17962.72,"id":5300820},{"trd":[[2.12,44.76]],"batb":[[0,2.12,4.4]],"ltp":2.12,"tv":12176.97,"id":9629022}],"tv":30139.7}]}
{"op":"mcm","clk":"4215219042","pt":1631536111464,"mc":[{"id":"1.187557985","rc":[{"trd":[[1.88,54.92]],"batl":[[0,1.88,162.02]],"ltp":1.88,"tv":17996.14,"id":5300820}],"tv":30173.12}]}
{"op":"mcm","clk":"4215219110","pt":1631536112564,"mc":[{"id":"1.187557985","rc":[{"batb":[[2,2.02,229.09]],"ltp":2.12,"tv":12176.97,"id":9629022}]}]}
{"op":"mcm","clk":"4215219173","pt":1631536113565,"mc":[{"id":"1.187557985","rc":[{"trd":[[1.86,20.35]],"batb":[[0,1.86,2.18]],"batl":[[2,1.9,1174.2]],"ltp":1.86,"tv":18008.8,"id":5300820},{"trd":[[2.18,3.25]],"ltp":2.18,"tv":12177.09,"id":9629022}],"tv":30185.89}]}
{"op":"mcm","clk":"4215219358","pt":1631536116650,"mc":[{"id":"1.187557985","rc":[{"trd":[[1.86,24.7]],"batb":[[0,1.85,1.45],[1,1.84,304.06],[2,1.83,340.35]],"batl":[[0,1.86,10.59],[1,1.88,162.02],[2,1.89,1011.9]],"ltp":1.86,"tv":18013.16,"id":5300820},{"batb":[[1,2.1,132.92]],"ltp":2.18,"tv":12177.09,"id":9629022}],"tv":30190.25}]}
{"op":"mcm","clk":"4215219366","pt":1631536116759,"mc":[{"id":"1.187557985","rc":[{"batb":[[1,1.84,83.49]],"ltp":1.86,"tv":18013.16,"id":5300820}]}]}
{"op":"mcm","clk":"4215219497","pt":1631536118486,"mc":[{"id":"1.187557985","rc":[{"trd":[[1.86,24.96]],"batl":[[0,1.86,1.59]],"ltp":1.86,"tv":18013.42,"id":5300820}],"tv":30190.51}]}
{"op":"mcm","clk":"4215219649","pt":1631536120579,"mc":[{"id":"1.187557985","rc":[{"batb":[[2,1.83,29.03]],"batl":[[2,1.9,192.06]],"ltp":1.86,"tv":18013.42,"id":5300820},{"batl":[[0,2.22,7.25],[1,2.28,6.09],[2,2.3,33.16]],"ltp":2.18,"tv":12177.09,"id":9629022}]}]}
{"op":"mcm","clk":"4215219719","pt":1631536121370,"mc":[{"id":"1.187557985","rc":[{"batb":[[1,1.8,4],[2,1.79,5]],"batl":[[1,1.9,30],[2,1.97,228.96]],"ltp":1.86,"tv":18013.42,"id":5300820},{"batb":[[1,2.1,22.38],[2,2.02,219.85]],"batl":[[0,2.3,26.31],[1,2.34,197.67],[2,2.36,235.81]],"ltp":2.18,"tv":12177.09,"id":9629022}]}]}
{"op":"mcm","clk":"4215219782","pt":1631536122488,"mc":[{"id":"1.187557985","rc":[{"trd":[[1.85,85.68]],"batb":[[0,1.8,4],[1,1.79,5],[2,1.75,263.14]],"batl":[[0,1.84,7.53],[1,1.86,1.59]],"ltp":1.85,"tv":18016.31,"id":5300820},{"batb":[[0,2.02,219.85],[1,2,396.41],[2,1.99,354.17]],"batl":[[0,2.34,197.67],[1,2.36,235.81],[2,2.38,216.78]],"ltp":2.18,"tv":12177.09,"id":9629022}],"tv":30193.4}]}
{"op":"mcm","clk":"4215219839","pt":1631536123574,"mc":[{"id":"1.187557985","rc":[{"batl":[[2,1.97,359.67]],"ltp":1.85,"tv":18016.31,"id":5300820}]}]}
{"op":"mcm","clk":"4215219971","pt":1631536125468,"mc":[{"id":"1.187557985","rc":[{"trd":[[1.84,32.8]],"batl":[[0,1.86,1.59],[1,1.97,359.67],[2,1.98,217.08]],"ltp":1.84,"tv":18025.59,"id":5300820},{"trd":[[2.18,8.13]],"batl":[[0,2.26,3],[1,2.34,197.67],[2,2.36,235.81]],"ltp":2.18,"tv":12181.97,"id":9629022}],"tv":30207.56}]}
{"op":"mcm","clk":"4215220126","pt":1631536127659,"mc":[{"id":"1.187557985","rc":[{"batb":[[2,1.78,35.66]],"ltp":1.84,"tv":18025.59,"id":5300820}]}]}
{"op":"mcm","clk":"4215220138","pt":1631536127868,"mc":[{"id":"1.187557985","rc":[{"batb":[[2,1.75,263.14]],"ltp":1.84,"tv":18025.59,"id":5300820}]}]}
{"op":"mcm","clk":"4215220247","pt":1631536129585,"mc":[{"id":"1.187557985","rc":[{"batb":[[2,1.74,133.41]],"ltp":1.84,"tv":18025.59,"id":5300820},{"batl":[[1,2.36,6.07],[2,2.36,0]],"ltp":2.18,"tv":12181.97,"id":9629022}]}]}
{"op":"mcm","clk":"4215220355","pt":1631536131365,"mc":[{"id":"1.187557985","rc":[{"batb":[[2,1.99,350.17]],"ltp":2.18,"tv":12181.97,"id":9629022}]}]}
{"op":"mcm","clk":"4215220453","pt":1631536132590,"mc":[{"id":"1.187557985","rc":[{"trd":[[1.86,28.15]],"batb":[[0,1.93,8.26],[1,1.91,4.18],[2,1.9,183.1]],"batl":[[0,1.97,362.67],[1,1.98,217.08],[2,1.99,446.09]],"ltp":1.86,"tv":18028.77,"id":5300820},{"batb":[[0,2.02,222.85],[1,2,926.35],[2,1.99,1278.29]],"batl":[[0,2.12,7.71],[1,2.26,3],[2,2.28,8.77]],"ltp":2.18,"tv":12181.97,"id":9629022}],"tv":30210.74}]}
{"op":"mcm","clk":"4215220508","pt":1631536133424,"mc":[{"id":"1.187557985","rc":[{"trd":[[1.92,4.3],[1.93,16.53]],"batb":[[0,1.92,66.8]],"batl":[[0,1.97,359.67]],"ltp":1.92,"tv":18049.6,"id":5300820},{"batb":[[0,2.02,219.85],[1,2,952.35]],"batl":[[1,2.18,27.61],[2,2.26,3]],"ltp":2.18,"tv":12181.97,"id":9629022}],"tv":30231.58}]}
{"op":"mcm","clk":"4215220569","pt":1631536134204,"mc":[{"id":"1.187557985","rc":[{"batb":[[1,2,922.35]],"batl":[[1,2.24,4]],"ltp":2.18,"tv":12181.97,"id":9629022}]}]}
{"op":"mcm","clk":"4215220644","pt":1631536135505,"mc":[{"id":"1.187557985","rc":[{"batl":[[0,1.97,332.84]],"ltp":1.92,"tv":18049.6,"id":5300820}]}]}
{"op":"mcm","clk":"4215220792","pt":1631536137606,"mc":[{"id":"1.187557985","rc":[{"trd":[[1.92,9.22]],"batb":[[0,1.92,63.53]],"ltp":1.92,"tv":18054.53,"id":5300820},{"trd":[[2.02,8.41],[2.1,643.28]],"batb":[[0,2.02,216.06],[1,2,952.35]],"batl":[[0,2.12,38.89]],"ltp":2.1,"tv":12191.0,"id":9629022}],"tv":30245.53}]}
{"op":"mcm","clk":"4215220879","pt":1631536138612,"mc":[{"id":"1.187557985","rc":[{"batb":[[1,2,978.66]],"batl":[[2,2.26,9.75]],"ltp":2.1,"tv":12191.0,"id":9629022}]}]}
{"op":"mcm","clk":"4215221066","pt":1631536141411,"mc":[{"id":"1.187557985","rc":[{"trd":[[1.92,42.17]],"batb":[[0,1.92,47.05]],"batl":[[0,1.97,333.56]],"ltp":1.92,"tv":18087.48,"id":5300820},{"batl":[[1,2.16,27.85],[2,2.24,4]],"ltp":2.1,"tv":12191.0,"id":9629022}],"tv":30278.48}]}
{"op":"mcm","clk":"4215221115","pt":1631536142146,"mc":[{"id":"1.187557985","rc":[{"trd":[[1.92,88.68]],"batb":[[0,1.92,23.79]],"batl":[[0,1.96,1.45],[1,1.97,332.84],[2,1.98,217.08]],"ltp":1.92,"tv":18133.98,"id":5300820}],"tv":30324.98}]}
{"op":"mcm","clk":"4215221277","pt":1631536145318,"mc":[{"id":"1.187557985","rc":[{"batl":[[2,2.24,10.98]],"ltp":2.1,"tv":12191.0,"id":9629022}]}]}
{"op":"mcm","clk":"4215221300","pt":1631536145738,"mc":[{"id":"1.187557985","rc":[{"trd":[[1.92,88.9]],"batb":[[0,1.92,23.68]],"ltp":1.92,"tv":18134.2,"id":5300820}],"tv":30325.21}]}
{"op":"mcm","clk":"4215221456","pt":1631536148436,"mc":[{"id":"1.187557985","rc":[{"trd":[[1.92,88.92],[1.96,103.56]],"batb":[[0,1.92,23.67]],"batl":[[0,1.96,1.35]],"ltp":1.96,"tv":18134.41,"id":5300820}],"tv":30325.41}]}
{"op":"mcm","clk":"4215221515","pt":1631536149322,"mc":[{"id":"1.187557985","rc":[{"trd":[[1.96,104.49]],"batb":[[1,1.9,183.1],[2,1.88,1181.83]],"batl":[[0,1.97,333.73],[1,1.98,217.08],[2,1.99,446.09]],"ltp":1.96,"tv":18135.33,"id":5300820}],"tv":30326.34}]}
{"op":"mcm","clk":"4215221547","pt":1631536149937,"mc":[{"id":"1.187557985","rc":[{"trd":[[1.92,93.57]],"batb":[[0,1.92,21.35]],"ltp":1.92,"tv":18139.98,"id":5300820}],"tv":30330.99}]}
{"op":"mcm","clk":"4215221633","pt":1631536151207,"mc":[{"id":"1.187557985","rc":[{"trd":[[1.96,106.27],[1.97,198.23]],"batl":[[0,1.97,233.72]],"ltp":1.97,"tv":18340.0,"id":5300820}],"tv":30531.0}]}
{"op":"mcm","clk":"4215221679","pt":1631536152136,"mc":[{"id":"1.187557985","rc":[{"trd":[[1.92,136.24]],"batb":[[0,1.9,183.1],[1,1.88,1181.83],[2,1.87,987.36]],"batl":[[0,1.92,2.67],[1,1.97,233.72],[2,1.98,217.08]],"ltp":1.92,"tv":18382.67,"id":5300820}],"tv":30573.68}]}
{"op":"mcm","clk":"4215221849","pt":1631536155340,"mc":[{"id":"1.187557985","rc":[{"batb":[[0,1.9,213.71]],"ltp":1.92,"tv":18382.67,"id":5300820}]}]}
{"op":"mcm","clk":"4215221926","pt":1631536156625,"mc":[{"id":"1.187557985","rc":[{"batb":[[0,1.9,56.37],[1,1.86,34.66],[2,1.81,36.29]],"batl":[[1,1.97,103.01]],"ltp":1.92,"tv":18382.67,"id":5300820},{"batb":[[1,2,452.72],[2,1.99,350.17]],"ltp":2.1,"tv":12191.0,"id":9629022}]}]}
{"op":"mcm","clk":"4215221977","pt":1631536157519,"mc":[{"id":"1.187557985","rc":[{"trd":[[1.92,138.91]],"batb":[[0,1.86,34.66],[1,1.81,5],[2,1.8,85.1]],"batl":[[0,2,30],[1,2.06,7.42],[2,2.6,261.12]],"ltp":1.92,"tv":18385.34,"id":5300820},{"trd":[[2.08,2.46]],"batb":[[0,2,30],[1,1.95,26.91],[2,1.9,75.23]],"batl":[[0,2.08,39.54],[2,2.24,4]],"ltp":2.08,"tv":12193.46,"id":9629022}],"tv":30578.81}]}
{"op":"mcm","clk":"4215222028","pt":1631536158450,"mc":[{"id":"1.187557985","rc":[{"batb":[[0,1.86,2.32]],"batl":[[0,2.06,7.42],[1,2.6,261.12],[2,3.45,2.32]],"ltp":1.92,"tv":18385.34,"id":5300820},{"batb":[[0,1.95,26.91],[1,1.9,75.23],[2,1.48,6.78]],"batl":[[0,2.08,41.54],[1,2.24,4],[2,2.34,6.25]],"ltp":2.08,"tv":12193.46,"id":9629022}]}]}
{"op":"mcm","clk":"4215222128","pt":1631536159657,"mc":[{"id":"1.187557985","rc":[{"batl":[[1,2.1,147.76],[2,2.12,116.97]],"ltp":1.92,"tv":18385.34,"id":5300820}]}]}
{"op":"mcm","clk":"4215222188","pt":1631536160610,"mc":[{"id":"1.187557985","rc":[{"batb":[[2,1.79,86.36]],"batl":[[0,2,27.47],[1,2.06,7.42],[2,2.1,147.76]],"ltp":1.92,"tv":18385.34,"id":5300820},{"batb":[[0,2,24.56],[1,1.95,26.91],[2,1.91,74.06]],"ltp":2.08,"tv":12193.46,"id":9629022}]}]}
{"op":"mcm","clk":"4215222226","pt":1631536161341,"mc":[{"id":"1.187557985","rc":[{"batl":[[0,2.06,7.42],[1,2.1,147.76],[2,2.12,116.97]],"ltp":1.92,"tv":18385.34,"id":5300820},{"batb":[[0,1.95,26.91],[1,1.91,74.06],[2,1.48,6.78]],"batl":[[0,2.08,2]],"ltp":2.08,"tv":12193.46,"id":9629022}]}]}
{"op":"mcm","clk":"4215222251","pt":1631536161752,"mc":[{"id":"1.187557985","rc":[{"batb":[[0,1.95,30.91],[1,1.94,4],[2,1.91,74.06]],"ltp":2.08,"tv":12193.46,"id":9629022}]}]}
{"op":"mcm","clk":"4215222341","pt":1631536163116,"mc":[{"id":"1.187557985","rc":[{"batl":[[0,2.08,4]],"ltp":2.08,"tv":12193.46,"id":9629022}]}]}
{"op":"mcm","clk":"4215222420","pt":1631536164629,"mc":[{"id":"1.187557985","rc":[{"batl":[[0,2.08,2]],"ltp":2.08,"tv":12193.46,"id":9629022}]}]}
{"op":"mcm","clk":"4215222617","pt":1631536167649,"mc":[{"id":"1.187557985","rc":[{"batb":[[2,1.8,32.43]],"batl":[[0,2,29.36],[1,2.06,7.42],[2,2.1,147.76]],"ltp":1.92,"tv":18385.34,"id":5300820},{"batb":[[0,2,27.48],[1,1.95,30.91],[2,1.94,4]],"batl":[[2,2.26,6.75]],"ltp":2.08,"tv":12193.46,"id":9629022}]}]}
{"op":"mcm","clk":"4215222668","pt":1631536168527,"mc":[{"id":"1.187557985","rc":[{"batb":[[2,1.79,86.36]],"batl":[[0,2.06,7.42],[1,2.1,147.76],[2,2.12,116.97]],"ltp":1.92,"tv":18385.34,"id":5300820},{"batb":[[0,1.95,30.91],[1,1.94,4],[2,1.91,74.06]],"batl":[[0,2.08,42],[2,2.34,6.25]],"ltp":2.08,"tv":12193.46,"id":9629022}]}]}
{"op":"mcm","clk":"4215222734","pt":1631536169664,"mc":[{"id":"1.187557985","rc":[{"batl":[[1,2.6,261.12],[2,3.45,2.32]],"ltp":1.92,"tv":18385.34,"id":5300820},{"trd":[[1.95,7.48]],"batb":[[0,1.95,28.91]],"ltp":1.95,"tv":12197.46,"id":9629022}],"tv":30582.81}]}
{"op":"mcm","clk":"4215222760","pt":1631536170042,"mc":[{"id":"1.187557985","rc":[{"batl":[[0,2.08,40]],"ltp":1.95,"tv":12197.46,"id":9629022}]}]}
{"op":"mcm","clk":"4215222835","pt":1631536171461,"mc":[{"id":"1.187557985","rc":[{"batb":[[1,1.79,86.36],[2,1.77,216.24]],"ltp":1.92,"tv":18385.34,"id":5300820},{"batl":[[1,2.34,6.25],[2,2.34,0]],"ltp":1.95,"tv":12197.46,"id":9629022}]}]}
{"op":"mcm","clk":"4215222914","pt":1631536172547,"mc":[{"id":"1.187557985","rc":[{"trd":[[1.84,63.42],[1.86,32.79],[1.92,182.24]],"batb":[[0,1.82,8.76],[1,1.8,4.43],[2,1.79,86.36]],"batl":[[0,1.84,1220.03],[1,1.85,1008.82],[2,1.86,1181.87]],"ltp":1.84,"tv":18463.94,"id":5300820},{"trd":[[2.08,42.46]],"batb":[[1,1.94,12.22],[2,1.92,4.16]],"batl":[[0,2.34,6.25],[1,2.36,445.71],[2,2.38,432.61]],"ltp":2.08,"tv":12237.46,"id":9629022}],"tv":30701.4}]}
{"op":"mcm","clk":"4215222988","pt":1631536173662,"mc":[{"id":"1.187557985","rc":[{"batb":[[0,2.18,100.84],[1,2.06,117.32],[2,1.96,118.6]],"ltp":2.08,"tv":12237.46,"id":9629022}]}]}
{"op":"mcm","clk":"4215223015","pt":1631536174230,"mc":[{"id":"1.187557985","rc":[{"batb":[[1,2.08,4],[2,2.06,120.32]],"ltp":2.08,"tv":12237.46,"id":9629022}]}]}
{"op":"mcm","clk":"4215223101","pt":1631536175638,"mc":[{"id":"1.187557985","rc":[{"batb":[[1,2.12,4],[2,2.1,4]],"batl":[[0,2.32,31.25],[1,2.34,32.16],[2,2.36,445.71]],"ltp":2.08,"tv":12237.46,"id":9629022}]}]}
{"op":"mcm","clk":"4215223158","pt":1631536176637,"mc":[{"id":"1.187557985","rc":[{"batb":[[1,2.12,30.78]],"ltp":2.08,"tv":12237.46,"id":9629022}]}]}
{"op":"mcm","clk":"4215223240","pt":1631536177640,"mc":[{"id":"1.187557985","rc":[{"trd":[[2.18,26.22]],"batb":[[0,2.18,91.79],[1,2.12,4]],"ltp":2.18,"tv":12255.55,"id":9629022}],"tv":30719.49}]}
{"op":"mcm","clk":"4215223317","pt":1631536178633,"mc":[{"id":"1.187557985","rc":[{"batb":[[1,2.12,11.79]],"ltp":2.18,"tv":12255.55,"id":9629022}]}]}
{"op":"mcm","clk":"4215223454","pt":1631536180625,"mc":[{"id":"1.187557985","rc":[{"trd":[[1.84,63.58]],"batl":[[0,1.84,1219.95]],"ltp":1.84,"tv":18464.1,"id":5300820}],"tv":30719.65}]}
{"op":"mcm","clk":"4215223508","pt":1631536181527,"mc":[{"id":"1.187557985","rc":[{"batb":[[1,2.14,26.31],[2,2.12,11.79]],"ltp":2.18,"tv":12255.55,"id":9629022}]}]}
{"op":"mcm","clk":"4215223621","pt":1631536183574,"mc":[{"id":"1.187557985","rc":[{"trd":[[1.84,63.74]],"batl":[[0,1.84,1219.87]],"ltp":1.84,"tv":18464.26,"id":5300820}],"tv":30719.81}]}
{"op":"mcm","clk":"4215223667","pt":1631536184240,"mc":[{"id":"1.187557985","rc":[{"trd":[[1.82,246.29]],"batb":[[0,1.82,8.57]],"ltp":1.82,"tv":18464.63,"id":5300820}],"tv":30720.18}]}
{"op":"mcm","clk":"4215223812","pt":1631536186474,"mc":[{"id":"1.187557985","rc":[{"batb":[[0,1.7,438.46],[1,1.69,253.91],[2,1.68,370.14]],"batl":[[0,1.87,30],[1,1.89,27.59],[2,1.92,280.87]],"ltp":1.82,"tv":18464.63,"id":5300820},{"batb":[[0,2.14,26.31],[1,2.12,7.79],[2,2.08,179.34]],"batl":[[0,2.34,25.91],[1,2.42,202.85],[2,2.44,238.51]],"ltp":2.18,"tv":12255.55,"id":9629022}]}]}
{"op":"mcm","clk":"4215223882","pt":1631536187576,"mc":[{"id":"1.187557985","rc":[{"batb":[[0,1.7,438.54]],"batl":[[0,1.92,280.87],[1,1.93,264.34],[2,1.94,260.3]],"ltp":1.82,"tv":18464.63,"id":5300820},{"batb":[[0,2.08,179.34],[1,2.06,353.9],[2,2.04,287.28]],"batl":[[0,2.42,202.85],[1,2.44,238.51],[2,2.46,200.27]],"ltp":2.18,"tv":12255.55,"id":9629022}]}]}
{"op":"mcm","clk":"4215223992","pt":1631536189558,"mc":[{"id":"1.187557985","rc":[{"batb":[[0,1.75,34.73],[1,1.7,438.45],[2,1.69,253.91]],"ltp":1.82,"tv":18464.63,"id":5300820}]}]}
{"op":"mcm","clk":"4215224047","pt":1631536190588,"mc":[{"id":"1.187557985","rc":[{"trd":[[1.84,63.91]],"batb":[[0,1.7,444.45],[1,1.69,258.91],[2,1.68,370.14]],"batl":[[0,1.82,25.47],[1,1.92,280.87],[2,1.93,264.34]],"ltp":1.84,"tv":18464.8,"id":5300820},{"batl":[[0,2.42,205.85]],"ltp":2.18,"tv":12255.55,"id":9629022}],"tv":30720.35}]}
{"op":"mcm","clk":"4215224092","pt":1631536191494,"mc":[{"id":"1.187557985","rc":[{"batl":[[0,1.82,2.32]],"ltp":1.84,"tv":18464.8,"id":5300820}]}]}
{"op":"mcm","clk":"4215224151","pt":1631536192376,"mc":[{"id":"1.187557985","rc":[{"trd":[[1.7,63.39],[1.71,656.5]],"batb":[[0,1.7,444.16]],"ltp":1.7,"tv":19107.73,"id":5300820}],"tv":31363.28}]}
{"op":"mcm","clk":"4215224234","pt":1631536193497,"mc":[{"id":"1.187557985","rc":[{"batb":[[0,1.76,125.77],[1,1.74,211.84],[2,1.71,395.2]],"batl":[[0,1.82,194.36],[1,1.84,179.02],[2,1.89,28.5]],"ltp":1.7,"tv":19107.73,"id":5300820},{"batb":[[0,2.12,7.54],[1,2.1,57.24],[2,2.08,179.34]],"batl":[[0,2.4,50.33],[1,2.42,205.85],[2,2.44,238.51]],"ltp":2.18,"tv":12255.55,"id":9629022}]}]}
{"op":"mcm","clk":"4215224277","pt":1631536194072,"mc":[{"id":"1.187557985","rc":[{"batb":[[2,1.71,321.11]],"ltp":1.7,"tv":19107.73,"id":5300820},{"batb":[[1,2.08,179.34],[2,2.06,353.9]],"ltp":2.18,"tv":12255.55,"id":9629022}]}]}
{"op":"mcm","clk":"4215224348","pt":1631536195381,"mc":[{"id":"1.187557985","rc":[{"batb":[[0,1.71,323.11],[1,1.7,444.16],[2,1.69,258.91]],"batl":[[0,1.82,2.32],[1,1.89,28.5],[2,1.92,280.87]],"ltp":1.7,"tv":19107.73,"id":5300820},{"batl":[[0,2.42,205.85],[1,2.44,238.51],[2,2.46,200.27]],"ltp":2.18,"tv":12255.55,"id":9629022}]}]}
{"op":"mcm","clk":"4215224359","pt":1631536195692,"mc":[{"id":"1.187557985","rc":[{"batl":[[1,1.92,280.87],[2,1.93,264.34]],"ltp":1.7,"tv":19107.73,"id":5300820},{"batb":[[0,2.08,179.34],[1,2.06,353.9],[2,2.04,287.28]],"ltp":2.18,"tv":12255.55,"id":9629022}]}]}
{"op":"mcm","clk":"4215224464","pt":1631536197374,"mc":[{"id":"1.187557985","rc":[{"trd":[[1.82,248.05]],"batb":[[0,1.71,2]],"batl":[[0,1.92,281.43],[1,1.93,264.34],[2,1.94,260.3]],"ltp":1.82,"tv":19109.49,"id":5300820},{"trd":[[2.2,134.75]],"ltp":2.2,"tv":12257.0,"id":9629022}],"tv":31366.49}]}
{"op":"mcm","clk":"4215224529","pt":1631536198310,"mc":[{"id":"1.187557985","rc":[{"batl":[[1,1.93,424.79]],"ltp":1.82,"tv":19109.49,"id":5300820}]}]}
{"op":"mcm","clk":"4215224686","pt":1631536200383,"mc":[{"id":"1.187557985","rc":[{"trd":[[1.82,248.22]],"batl":[[0,1.92,281.34]],"ltp":1.82,"tv":19109.66,"id":5300820}],"tv":31366.66}]}
{"op":"mcm","clk":"4215224772","pt":1631536201509,"mc":[{"id":"1.187557985","rc":[{"batl":[[0,1.92,23.79],[1,2.06,7.42],[2,2.5,278.33]],"ltp":1.82,"tv":19109.66,"id":5300820},{"batb":[[0,2.08,8.56],[1,2.06,117.32],[2,1.96,4]],"ltp":2.2,"tv":12257.0,"id":9629022}]}]}
{"op":"mcm","clk":"4215224860","pt":1631536202509,"mc":[{"id":"1.187557985","rc":[{"batb":[[1,1.7,438.16],[2,1.69,253.91]],"batl":[[0,2.5,278.81],[1,3.45,2.32],[2,2.5,0]],"ltp":1.82,"tv":19109.66,"id":5300820}]}]}
{"op":"mcm","clk":"4215224886","pt":1631536202878,"mc":[{"id":"1.187557985","rc":[{"batl":[[0,1.91,287.97],[1,2.5,278.33],[2,3.45,2.32]],"ltp":1.82,"tv":19109.66,"id":5300820}]}]}
{"op":"mcm","clk":"4215225016","pt":1631536204610,"mc":[{"id":"1.187557985","rc":[{"trd":[[1.74,40.01]],"batb":[[0,1.72,4.64],[1,1.71,2],[2,1.7,438.16]],"batl":[[0,1.74,168.98],[1,1.75,1092.86],[2,1.76,1267.23]],"ltp":1.74,"tv":19127.99,"id":5300820}],"tv":31385.0}]}
{"op":"mcm","clk":"4215225097","pt":1631536205615,"mc":[{"id":"1.187557985","rc":[{"batb":[[2,1.7,443.16]],"ltp":1.74,"tv":19127.99,"id":5300820},{"batb":[[0,2.32,83.68],[1,2.2,97.24],[2,2.08,8.56]],"ltp":2.2,"tv":12257.0,"id":9629022}]}]}
{"op":"mcm","clk":"4215225359","pt":1631536208603,"mc":[{"id":"1.187557985","rc":[{"trd":[[1.7,687.86],[1.71,664.7],[1.72,44.18]],"batb":[[0,1.7,130.84],[1,1.69,253.91],[2,1.68,370.14]],"batl":[[0,1.74,155.84]],"ltp":1.7,"tv":19769.94,"id":5300820},{"trd":[[2.4,3]],"batb":[[0,2.34,3],[1,2.32,86.68],[2,2.2,97.24]],"ltp":2.4,"tv":12260.0,"id":9629022}],"tv":32029.95}]}
{"op":"mcm","clk":"4215225445","pt":1631536209496,"mc":[{"id":"1.187557985","rc":[{"trd":[[1.74,52.88]],"batb":[[0,1.7,125.84],[1,1.69,377.35]],"batl":[[0,1.74,140.97]],"ltp":1.74,"tv":19782.81,"id":5300820},{"trd":[[2.34,42.87]],"batb":[[0,2.32,83.68],[1,2.2,97.24],[2,2.08,8.56]],"batl":[[0,2.42,202.85]],"ltp":2.34,"tv":12275.57,"id":9629022}],"tv":32058.39}]}
{"op":"mcm","clk":"4215225510","pt":1631536210284,"mc":[{"id":"1.187557985","rc":[{"trd":[[1.74,55.57]],"batb":[[0,1.71,35.6],[1,1.7,125.84],[2,1.69,377.35]],"batl":[[0,1.74,138.28]],"ltp":1.74,"tv":19785.5,"id":5300820},{"trd":[[2.34,44.87]],"batl":[[0,2.42,228.02]],"ltp":2.34,"tv":12277.57,"id":9629022}],"tv":32063.08}]}
{"op":"mcm","clk":"4215225629","pt":1631536211491,"mc":[{"id":"1.187557985","rc":[{"batb":[[1,2.24,205.72],[2,2.22,228.19]],"ltp":2.34,"tv":12277.57,"id":9629022}]}]}
{"op":"mcm","clk":"4215225713","pt":1631536212383,"mc":[{"id":"1.187557985","rc":[{"batb":[[1,2.26,4],[2,2.24,209.72]],"ltp":2.34,"tv":12277.57,"id":9629022}]}]}
{"op":"mcm","clk":"4215225800","pt":1631536213524,"mc":[{"id":"1.187557985","rc":[{"batb":[[2,1.69,510.16]],"ltp":1.74,"tv":19785.5,"id":5300820},{"batb":[[0,2.34,81.84]],"ltp":2.34,"tv":12277.57,"id":9629022}]}]}
{"op":"mcm","clk":"4215226111","pt":1631536217508,"mc":[{"id":"1.187557985","rc":[{"trd":[[1.74,56.03]],"batl":[[0,1.74,138.05]],"ltp":1.74,"tv":19785.95,"id":5300820}],"tv":32063.53}]}
{"op":"mcm","clk":"4215226204","pt":1631536218500,"mc":[{"id":"1.187557985","rc":[{"trd":[[1.74,56.09]],"batl":[[0,1.74,138.02]],"ltp":1.74,"tv":19786.02,"id":5300820}],"tv":32063.59}]}
{"op":"mcm","clk":"4215226294","pt":1631536219592,"mc":[{"id":"1.187557985","rc":[{"trd":[[1.71,735.91]],"batb":[[0,1.7,125.84],[1,1.69,510.16],[2,1.68,374.14]],"batl":[[0,1.71,6.98],[1,1.74,138.02],[2,1.75,1092.86]],"ltp":1.71,"tv":19857.22,"id":5300820}],"tv":32134.8}]}
{"op":"mcm","clk":"4215226321","pt":1631536219902,"mc":[{"id":"1.187557985","rc":[{"trd":[[1.71,738.41]],"batl":[[0,1.71,5.73]],"ltp":1.71,"tv":19859.72,"id":5300820},{"batl":[[0,2.42,202.85]],"ltp":2.34,"tv":12277.57,"id":9629022}],"tv":32137.3}]}
{"op":"mcm","clk":"4215226545","pt":1631536223109,"mc":[{"id":"1.187557985","rc":[{"trd":[[1.71,749.87]],"batb":[[2,1.68,410.52]],"batl":[[0,1.74,138.02],[1,1.75,1092.86],[2,1.76,1267.23]],"ltp":1.71,"tv":19871.19,"id":5300820},{"batb":[[1,2.28,23.43],[2,2.26,4]],"ltp":2.34,"tv":12277.57,"id":9629022}],"tv":32148.76}]}
{"op":"mcm","clk":"4215226604","pt":1631536223890,"mc":[{"id":"1.187557985","rc":[{"batl":[[0,1.71,7.73],[1,1.74,138.02],[2,1.75,1092.86]],"ltp":1.71,"tv":19871.19,"id":5300820}]}]}
{"op":"mcm","clk":"4215226771","pt":1631536226333,"mc":[{"id":"1.187557985","rc":[{"trd":[[1.71,752.68]],"batl":[[0,1.71,4.93]],"ltp":1.71,"tv":19873.99,"id":5300820},{"trd":[[2.4,5]],"ltp":2.4,"tv":12279.57,"id":9629022}],"tv":32153.57}]}
{"op":"mcm","clk":"4215226892","pt":1631536228221,"mc":[{"id":"1.187557985","rc":[{"batl":[[0,2.44,238.51],[1,2.46,200.27],[2,2.48,24.65]],"ltp":2.4,"tv":12279.57,"id":9629022}]}]}
{"op":"mcm","clk":"4215226970","pt":1631536229525,"mc":[{"id":"1.187557985","rc":[{"trd":[[1.71,753.02]],"batl":[[0,1.71,4.75]],"ltp":1.71,"tv":19874.34,"id":5300820}],"tv":32153.92}]}
{"op":"mcm","clk":"4215227084","pt":1631536231460,"mc":[{"id":"1.187557985","rc":[{"batl":[[0,2.44,261.48]],"ltp":2.4,"tv":12279.57,"id":9629022}]}]}
{"op":"mcm","clk":"4215227245","pt":1631536234334,"mc":[{"id":"1.187557985","rc":[{"trd":[[1.69,870.47],[1.7,939.54],[1.71,755.83]],"batb":[[0,1.69,104.6],[1,1.68,410.52],[2,1.67,5]],"batl":[[0,1.71,1.95]],"ltp":1.71,"tv":20933.34,"id":5300820},{"trd":[[2.4,7]],"ltp":2.4,"tv":12281.57,"id":9629022}],"tv":33214.92}]}
{"op":"mcm","clk":"4215227268","pt":1631536234752,"mc":[{"id":"1.187557985","rc":[{"batl":[[0,1.74,138.02],[1,1.75,1092.86],[2,1.76,1267.23]],"ltp":1.71,"tv":20933.34,"id":5300820}]}]}
{"op":"mcm","clk":"4215227430","pt":1631536237261,"mc":[{"id":"1.187557985","rc":[{"batb":[[0,1.69,141.53],[1,1.68,607.63]],"batl":[[0,1.74,205.93]],"ltp":1.71,"tv":20933.34,"id":5300820}]}]}
{"op":"mcm","clk":"4215227809","pt":1631536243826,"mc":[{"id":"1.187557985","rc":[{"batb":[[2,1.66,249.67]],"batl":[[0,1.73,319.42],[1,1.74,205.93],[2,1.75,1092.86]],"ltp":1.71,"tv":20933.34,"id":5300820},{"batb":[[0,2.36,234.15],[1,2.34,81.84],[2,2.28,23.43]],"ltp":2.4,"tv":12281.57,"id":9629022}]}]}
{"op":"mcm","clk":"4215228010","pt":1631536247077,"mc":[{"id":"1.187557985","rc":[{"batb":[[2,1.67,5]],"ltp":1.71,"tv":20933.34,"id":5300820}]}]}
{"op":"mcm","clk":"4215228112","pt":1631536248538,"mc":[{"id":"1.187557985","rc":[{"batl":[[0,1.71,226.58],[1,1.73,319.42],[2,1.74,205.93]],"ltp":1.71,"tv":20933.34,"id":5300820}]}]}
{"op":"mcm","clk":"4215228465","pt":1631536253982,"mc":[{"id":"1.187557985","rc":[{"trd":[[1.71,756.02]],"batb":[[0,1.69,104.6]],"batl":[[0,1.71,226.48]],"ltp":1.71,"tv":20933.53,"id":5300820},{"batl":[[0,2.44,238.51]],"ltp":2.4,"tv":12281.57,"id":9629022}],"tv":33215.1}]}
{"op":"mcm","clk":"4215228562","pt":1631536255382,"mc":[{"id":"1.187557985","rc":[{"trd":[[2.44,45.44]],"batl":[[0,2.44,218.51]],"ltp":2.44,"tv":12321.57,"id":9629022}],"tv":33255.1}]}
{"op":"mcm","clk":"4215228627","pt":1631536256368,"mc":[{"id":"1.187557985","rc":[{"trd":[[1.69,890.47]],"batb":[[0,1.69,94.59]],"ltp":1.69,"tv":20953.53,"id":5300820}],"tv":33275.11}]}
{"op":"mcm","clk":"4215228724","pt":1631536257558,"mc":[{"id":"1.187557985","rc":[{"trd":[[1.71,956.04]],"batb":[[0,1.7,36.93],[1,1.69,94.59],[2,1.68,607.63]],"batl":[[0,1.71,126.47]],"ltp":1.71,"tv":21153.55,"id":5300820},{"batb":[[1,2.34,81.67]],"batl":[[0,2.42,22.97],[1,2.44,218.51],[2,2.46,200.27]],"ltp":2.44,"tv":12321.57,"id":9629022}],"tv":33475.13}]}
{"op":"mcm","clk":"4215229251","pt":1631536264600,"mc":[{"id":"1.187557985","rc":[{"trd":[[1.7,952.08]],"batb":[[0,1.7,30.66]],"ltp":1.7,"tv":21166.09,"id":5300820},{"batl":[[0,2.44,218.51],[1,2.46,200.27],[2,2.48,24.65]],"ltp":2.44,"tv":12321.57,"id":9629022}],"tv":33487.67}]}
{"op":"mcm","clk":"4215229377","pt":1631536266781,"mc":[{"id":"1.187557985","rc":[{"trd":[[1.71,957.89]],"batl":[[0,1.71,125.54]],"ltp":1.71,"tv":21167.95,"id":5300820}],"tv":33489.52}]}
{"op":"mcm","clk":"4215229435","pt":1631536267812,"mc":[{"id":"1.187557985","rc":[{"batl":[[0,2.44,243.87]],"ltp":2.44,"tv":12321.57,"id":9629022}]}]}
{"op":"mcm","clk":"4215229604","pt":1631536270993,"mc":[{"id":"1.187557985","rc":[{"trd":[[1.7,1013.4]],"batb":[[0,1.69,94.59],[1,1.68,607.63],[2,1.66,249.67]],"batl":[[0,1.7,19.34],[1,1.71,125.54],[2,1.73,319.42]],"ltp":1.7,"tv":21229.27,"id":5300820}],"tv":33550.84}]}
{"op":"mcm","clk":"4215229883","pt":1631536275486,"mc":[{"id":"1.187557985","rc":[{"trd":[[1.7,1052.08]],"batl":[[0,1.71,125.54],[1,1.73,319.42],[2,1.74,205.93]],"ltp":1.7,"tv":21267.95,"id":5300820}],"tv":33589.52}]}
{"op":"mcm","clk":"4215230165","pt":1631536279689,"mc":[{"id":"1.187557985","rc":[{"batb":[[0,1.69,129.94]],"ltp":1.7,"tv":21267.95,"id":5300820}]}]}
{"op":"mcm","clk":"4215230302","pt":1631536281416,"mc":[{"id":"1.187557985","rc":[{"trd":[[1.71,976.63]],"batl":[[0,1.71,116.17]],"ltp":1.71,"tv":21286.69,"id":5300820}],"tv":33608.26}]}
{"op":"mcm","clk":"4215230469","pt":1631536283512,"mc":[{"id":"1.187557985","rc":[{"trd":[[1.69,1233.05]],"batb":[[0,1.68,607.63],[1,1.66,249.67],[2,1.65,1472.06]],"ltp":1.69,"tv":21629.26,"id":5300820},{"trd":[[2.44,102.83]],"batl":[[0,2.44,186.48]],"ltp":2.44,"tv":12378.96,"id":9629022}],"tv":34008.23}]}
{"op":"mcm","clk":"4215230490","pt":1631536283824,"mc":[{"id":"1.187557985","rc":[{"batl":[[0,2.44,161.12]],"ltp":2.44,"tv":12378.96,"id":9629022}]}]}
{"op":"mcm","clk":"4215230750","pt":1631536287826,"mc":[{"id":"1.187557985","rc":[{"batb":[[0,1.69,31.81],[1,1.68,607.63],[2,1.66,249.67]],"ltp":1.69,"tv":21629.26,"id":5300820}]}]}
{"op":"mcm","clk":"4215231046","pt":1631536292108,"mc":[{"id":"1.187557985","rc":[{"batl":[[0,1.73,319.42],[1,1.74,205.93],[2,1.75,1092.86]],"ltp":1.69,"tv":21629.26,"id":5300820}]}]}
{"op":"mcm","clk":"4215231242","pt":1631536295196,"mc":[{"id":"1.187557985","rc":[{"batb":[[2,1.67,37.47]],"batl":[[0,1.7,116.17],[1,1.73,319.42],[2,1.74,205.93]],"ltp":1.69,"tv":21629.26,"id":5300820},{"batb":[[2,2.28,29.59]],"ltp":2.44,"tv":12378.96,"id":9629022}]}]}
{"op":"mcm","clk":"4215231677","pt":1631536301523,"mc":[{"id":"1.187557985","rc":[{"batb":[[0,1.68,607.63],[1,1.67,37.47],[2,1.66,249.67]],"ltp":1.69,"tv":21629.26,"id":5300820}]}]}
{"op":"mcm","clk":"4215231693","pt":1631536301728,"mc":[{"id":"1.187557985","rc":[{"batl":[[0,2.46,200.27],[1,2.48,24.65],[2,2.5,5.97]],"ltp":2.44,"tv":12378.96,"id":9629022}]}]}
{"op":"mcm","clk":"4215232016","pt":1631536306333,"mc":[{"id":"1.187557985","rc":[{"batb":[[2,1.66,281.45]],"batl":[[0,1.7,116.39]],"ltp":1.69,"tv":21629.26,"id":5300820}]}]}
{"op":"mcm","clk":"4215232045","pt":1631536306753,"mc":[{"id":"1.187557985","rc":[{"trd":[[1.69,1233.5],[1.7,1061.62]],"batl":[[0,1.7,111.4]],"ltp":1.7,"tv":21639.26,"id":5300820}],"tv":34018.23}]}
{"op":"mcm","clk":"4215232239","pt":1631536309530,"mc":[{"id":"1.187557985","rc":[{"batb":[[0,1.69,31.81],[1,1.68,607.63],[2,1.67,37.47]],"ltp":1.7,"tv":21639.26,"id":5300820},{"batl":[[0,2.46,225.09]],"ltp":2.44,"tv":12378.96,"id":9629022}]}]}
{"op":"mcm","clk":"4215232416","pt":1631536312032,"mc":[{"id":"1.187557985","rc":[{"trd":[[1.69,1248.2],[1.7,1106.43]],"batb":[[0,1.69,24.46]],"batl":[[0,1.7,88.99]],"ltp":1.7,"tv":21698.76,"id":5300820}],"tv":34077.73}]}
{"op":"mcm","clk":"4215232517","pt":1631536313454,"mc":[{"id":"1.187557985","rc":[{"trd":[[1.7,1206.63]],"batl":[[0,1.7,38.89]],"ltp":1.7,"tv":21798.97,"id":5300820}],"tv":34177.94}]}
{"op":"mcm","clk":"4215232570","pt":1631536314224,"mc":[{"id":"1.187557985","rc":[{"trd":[[1.7,1206.79]],"batl":[[0,1.7,38.82]],"ltp":1.7,"tv":21799.12,"id":5300820}],"tv":34178.09}]}
{"op":"mcm","clk":"4215232991","pt":1631536320568,"mc":[{"id":"1.187557985","rc":[{"batb":[[0,1.68,36.38],[1,1.65,352.49],[2,1.64,252.06]],"batl":[[1,1.78,66.75],[2,1.8,253.11]],"ltp":1.7,"tv":21799.12,"id":5300820},{"batb":[[0,2.28,29.59],[1,2.24,209.72],[2,2.22,323.17]],"batl":[[0,2.48,24.65],[1,2.54,168.49],[2,2.56,178.23]],"ltp":2.44,"tv":12378.96,"id":9629022}]}]}
{"op":"mcm","clk":"4215233042","pt":1631536321362,"mc":[{"id":"1.187557985","rc":[{"batb":[[0,1.65,352.49],[1,1.64,252.06],[2,1.63,510.94]],"batl":[[1,1.78,36.75]],"ltp":1.7,"tv":21799.12,"id":5300820},{"batb":[[0,2.28,6.16]],"batl":[[0,2.54,168.49],[1,2.56,178.23],[2,2.58,188.21]],"ltp":2.44,"tv":12378.96,"id":9629022}]}]}
{"op":"mcm","clk":"4215233112","pt":1631536322356,"mc":[{"id":"1.187557985","rc":[{"batl":[[0,1.69,2.71],[1,1.7,38.82],[2,1.78,36.75]],"ltp":1.7,"tv":21799.12,"id":5300820}]}]}
{"op":"mcm","clk":"4215233211","pt":1631536323573,"mc":[{"id":"1.187557985","rc":[{"batb":[[2,1.63,691.08]],"ltp":1.7,"tv":21799.12,"id":5300820},{"batb":[[1,2.24,302.94]],"ltp":2.44,"tv":12378.96,"id":9629022}]}]}
{"op":"mcm","clk":"4215233294","pt":1631536324563,"mc":[{"id":"1.187557985","rc":[{"batb":[[0,1.67,35.47],[1,1.65,357.49],[2,1.64,258.06]],"ltp":1.7,"tv":21799.12,"id":5300820},{"batb":[[2,2.22,228.19]],"batl":[[0,2.5,5.63],[1,2.54,171.49],[2,2.56,178.23]],"ltp":2.44,"tv":12378.96,"id":9629022}]}]}
{"op":"mcm","clk":"4215233317","pt":1631536324830,"mc":[{"id":"1.187557985","rc":[{"batb":[[0,1.65,357.49],[1,1.64,258.06],[2,1.63,573.5]],"batl":[[0,1.69,5.03]],"ltp":1.7,"tv":21799.12,"id":5300820},{"batl":[[0,2.54,171.49],[1,2.56,178.23],[2,2.58,188.21]],"ltp":2.44,"tv":12378.96,"id":9629022}]}]}
{"op":"mcm","clk":"4215233424","pt":1631536326345,"mc":[{"id":"1.187557985","rc":[{"batb":[[0,1.65,678.6]],"ltp":1.7,"tv":21799.12,"id":5300820}]}]}
{"op":"mcm","clk":"4215233464","pt":1631536327071,"mc":[{"id":"1.187557985","rc":[{"batb":[[0,1.65,999.71]],"ltp":1.7,"tv":21799.12,"id":5300820}]}]}
{"op":"mcm","clk":"4215233670","pt":1631536330154,"mc":[{"id":"1.187557985","rc":[{"trd":[[1.65,16.45]],"batb":[[0,1.65,679.59],[1,1.64,6],[2,1.62,119.91]],"ltp":1.65,"tv":21806.28,"id":5300820},{"trd":[[2.54,21.15]],"ltp":2.54,"tv":12400.11,"id":9629022}],"tv":34206.4}]}
{"op":"mcm","clk":"4215233769","pt":1631536331573,"mc":[{"id":"1.187557985","rc":[{"batb":[[0,1.67,43.47],[1,1.65,679.59],[2,1.64,6]],"batl":[[2,1.72,9.37]],"ltp":1.65,"tv":21806.28,"id":5300820},{"batb":[[1,2.24,298.94]],"batl":[[0,2.5,5.13]],"ltp":2.54,"tv":12400.11,"id":9629022}]}]}
{"op":"mcm","clk":"4215233853","pt":1631536332629,"mc":[{"id":"1.187557985","rc":[{"trd":[[1.69,1258.27],[1.7,1284.41],[1.72,62.92]],"batb":[[0,1.76,131.15],[1,1.74,2410.02],[2,1.73,2133.62]],"batl":[[0,1.78,36.75],[1,1.8,253.11],[2,1.81,218.36]],"ltp":1.72,"tv":21912.71,"id":5300820},{"batl":[[0,2.4,2],[1,2.42,3],[2,2.46,8.13]],"ltp":2.54,"tv":12400.11,"id":9629022}],"tv":34312.83}]}
{"op":"mcm","clk":"4215233935","pt":1631536333567,"mc":[{"id":"1.187557985","rc":[{"trd":[[1.78,17.92]],"batb":[[0,1.76,135.68],[1,1.75,92.97],[2,1.74,1310.88]],"batl":[[0,1.78,27.79]],"ltp":1.78,"tv":21930.63,"id":5300820}],"tv":34330.75}]}
{"op":"mcm","clk":"4215234011","pt":1631536334567,"mc":[{"id":"1.187557985","rc":[{"trd":[[1.74,706.07],[1.75,290.6],[1.76,499.04]],"batb":[[0,1.74,774.18],[1,1.73,1066.82],[2,1.72,1070.91]],"ltp":1.74,"tv":23037.9,"id":5300820},{"batl":[[0,2.4,171.99],[2,2.44,3]],"ltp":2.54,"tv":12400.11,"id":9629022}],"tv":35438.02}]}
{"op":"mcm","clk":"4215234104","pt":1631536335661,"mc":[{"id":"1.187557985","rc":[{"batl":[[0,2.4,27.35]],"ltp":2.54,"tv":12400.11,"id":9629022}]}]}
{"op":"mcm","clk":"4215234115","pt":1631536335766,"mc":[{"id":"1.187557985","rc":[{"batb":[[0,1.75,4],[1,1.74,779.18],[2,1.73,1066.82]],"ltp":1.74,"tv":23037.9,"id":5300820},{"batl":[[0,2.34,4],[1,2.4,27.35],[2,2.42,3]],"ltp":2.54,"tv":12400.11,"id":9629022}]}]}
{"op":"mcm","clk":"4215234276","pt":1631536337567,"mc":[{"id":"1.187557985","rc":[{"trd":[[1.78,27.98]],"batb":[[0,1.76,62.32],[1,1.75,167.09],[2,1.74,779.18]],"batl":[[0,1.78,162.64],[2,1.81,384.04]],"ltp":1.78,"tv":23047.96,"id":5300820},{"trd":[[2.28,65.99]],"batb":[[0,2.26,84.62]],"batl":[[1,2.4,2]],"ltp":2.28,"tv":12420.28,"id":9629022}],"tv":35468.25}]}
{"op":"mcm","clk":"4215234384","pt":1631536338662,"mc":[{"id":"1.187557985","rc":[{"batb":[[2,1.74,841.53]],"batl":[[0,1.78,92.86]],"ltp":1.78,"tv":23047.96,"id":5300820}]}]}
{"op":"mcm","clk":"4215234499","pt":1631536340383,"mc":[{"id":"1.187557985","rc":[{"trd":[[1.76,499.41]],"batb":[[0,1.76,62.13]],"ltp":1.76,"tv":23048.34,"id":5300820},{"batl":[[1,2.36,25.72],[2,2.4,2]],"ltp":2.28,"tv":12420.28,"id":9629022}],"tv":35468.63}]}
{"op":"mcm","clk":"4215234585","pt":1631536341386,"mc":[{"id":"1.187557985","rc":[{"batb":[[0,1.76,90.77]],"ltp":1.76,"tv":23048.34,"id":5300820},{"batl":[[0,2.32,20],[1,2.34,4],[2,2.36,25.72]],"ltp":2.28,"tv":12420.28,"id":9629022}]}]}
{"op":"mcm","clk":"4215234808","pt":1631536344578,"mc":[{"id":"1.187557985","rc":[{"batb":[[2,1.74,779.18]],"batl":[[0,1.77,63.86],[1,1.78,17.73],[2,1.8,253.11]],"ltp":1.76,"tv":23048.34,"id":5300820}]}]}
{"op":"mcm","clk":"4215234924","pt":1631536346261,"mc":[{"id":"1.187557985","rc":[{"batb":[[0,1.76,28.64]],"batl":[[0,1.78,17.73],[1,1.8,253.11],[2,1.81,384.04]],"ltp":1.76,"tv":23048.34,"id":5300820}]}]}
{"op":"mcm","clk":"4215235075","pt":1631536348657,"mc":[{"id":"1.187557985","rc":[{"trd":[[1.76,500.86]],"batb":[[0,1.76,3.6],[2,1.74,774.18]],"ltp":1.76,"tv":23049.78,"id":5300820}],"tv":35470.07}]}
{"op":"mcm","clk":"4215235119","pt":1631536349385,"mc":[{"id":"1.187557985","rc":[{"trd":[[1.76,505.19]],"batb":[[0,1.76,1.44]],"ltp":1.76,"tv":23054.11,"id":5300820}],"tv":35474.4}]}
{"op":"mcm","clk":"4215235149","pt":1631536349759,"mc":[{"id":"1.187557985","rc":[{"trd":[[1.76,506.63]],"batb":[[0,1.75,167.81],[1,1.74,774.18],[2,1.73,1318.15]],"ltp":1.76,"tv":23055.55,"id":5300820}],"tv":35475.84}]}
{"op":"mcm","clk":"4215235751","pt":1631536358618,"mc":[{"id":"1.187557985","rc":[{"trd":[[1.78,31.82]],"batl":[[0,1.78,13.89]],"ltp":1.78,"tv":23059.39,"id":5300820},{"trd":[[2.28,68.99]],"ltp":2.28,"tv":12423.28,"id":9629022}],"tv":35482.68}]}
{"op":"mcm","clk":"4215235803","pt":1631536359611,"mc":[{"id":"1.187557985","rc":[{"batb":[[1,1.74,549.57],[2,1.73,784.74]],"ltp":1.78,"tv":23059.39,"id":5300820},{"batb":[[0,2.24,298.94],[1,2.22,228.19],[2,2.2,303.31]],"ltp":2.28,"tv":12423.28,"id":9629022}]}]}
{"op":"mcm","clk":"4215235843","pt":1631536360194,"mc":[{"id":"1.187557985","rc":[{"batb":[[0,1.73,35.11],[1,1.71,236.83],[2,1.7,276.04]],"batl":[[0,1.86,30.25],[1,1.87,2.04],[2,1.88,257.55]],"ltp":1.78,"tv":23059.39,"id":5300820},{"batb":[[0,2.18,25.42],[1,2.16,7.28],[2,2.14,4]],"batl":[[0,2.36,25.72],[1,2.42,164.97],[2,2.44,179.54]],"ltp":2.28,"tv":12423.28,"id":9629022}]}]}
{"op":"mcm","clk":"4215235931","pt":1631536361395,"mc":[{"id":"1.187557985","rc":[{"batb":[[0,1.71,236.83],[1,1.7,276.04],[2,1.69,998.82]],"ltp":1.78,"tv":23059.39,"id":5300820},{"batb":[[0,2.16,7.28],[1,2.14,4],[2,2.12,335.27]],"batl":[[0,2.42,164.97],[1,2.44,179.54],[2,2.46,204.55]],"ltp":2.28,"tv":12423.28,"id":9629022}]}]}
{"op":"mcm","clk":"4215236082","pt":1631536363496,"mc":[{"id":"1.187557985","rc":[{"batb":[[2,1.69,1131.86]],"batl":[[0,1.81,4],[1,1.83,4],[2,1.84,5]],"ltp":1.78,"tv":23059.39,"id":5300820},{"batb":[[0,2.18,4],[1,2.16,11.28],[2,2.14,4]],"ltp":2.28,"tv":12423.28,"id":9629022}]}]}
{"op":"mcm","clk":"4215236289","pt":1631536366524,"mc":[{"id":"1.187557985","rc":[{"batb":[[0,2.22,4],[1,2.2,4],[2,2.18,4]],"ltp":2.28,"tv":12423.28,"id":9629022}]}]}
{"op":"mcm","clk":"4215236337","pt":1631536367210,"mc":[{"id":"1.187557985","rc":[{"batb":[[0,1.69,679.43],[1,1.67,107.7],[2,1.65,32.37]],"ltp":1.78,"tv":23059.39,"id":5300820},{"batl":[[0,2.46,6.25],[1,2.54,5.88],[2,2.46,0]],"ltp":2.28,"tv":12423.28,"id":9629022}]}]}
{"op":"mcm","clk":"4215236486","pt":1631536369607,"mc":[{"id":"1.187557985","rc":[{"batl":[[0,2.26,2677.08],[1,2.4,12.02],[2,2.46,6.25]],"ltp":2.28,"tv":12423.28,"id":9629022}]}]}
{"op":"mcm","clk":"4215236556","pt":1631536370603,"mc":[{"id":"1.187557985","rc":[{"trd":[[1.81,35.66],[1.82,253.1],[1.83,151.49],[1.84,82.77]],"batb":[[0,1.84,131.98],[1,1.82,1323.26],[2,1.81,1019.92]],"batl":[[0,1.86,30.25],[1,1.88,257.55],[2,1.89,287.57]],"ltp":1.84,"tv":23099.13,"id":5300820},{"trd":[[2.2,138.75],[2.22,12.23]],"batb":[[0,2.16,7.28],[1,2.12,329.18],[2,2.1,249.53]],"batl":[[0,2.3,3.25],[1,2.36,8.47]],"ltp":2.2,"tv":12431.28,"id":9629022}],"tv":35530.42}]}
{"op":"mcm","clk":"4215236604","pt":1631536371392,"mc":[{"id":"1.187557985","rc":[{"batl":[[1,1.87,10.7],[2,1.88,257.55]],"ltp":1.84,"tv":23099.13,"id":5300820},{"batl":[[0,2.28,26.51],[1,2.3,3.25],[2,2.36,8.47]],"ltp":2.2,"tv":12431.28,"id":9629022}]}]}
{"op":"mcm","clk":"4215236730","pt":1631536373118,"mc":[{"id":"1.187557985","rc":[{"batb":[[0,1.84,135.98],[1,1.83,3],[2,1.82,1327.26]],"ltp":1.84,"tv":23099.13,"id":5300820},{"batl":[[0,2.2,4],[1,2.22,4],[2,2.28,26.51]],"ltp":2.2,"tv":12431.28,"id":9629022}]}]}
{"op":"mcm","clk":"4215236828","pt":1631536374585,"mc":[{"id":"1.187557985","rc":[{"batb":[[0,1.85,27.82],[1,1.84,211.19],[2,1.83,3]],"batl":[[0,1.86,95.34],[1,1.87,89.82]],"ltp":1.84,"tv":23099.13,"id":5300820}]}]}
{"op":"mcm","clk":"4215236869","pt":1631536375213,"mc":[{"id":"1.187557985","rc":[{"trd":[[1.85,90.89]],"batb":[[0,1.85,24.37],[2,1.83,74.79]],"ltp":1.85,"tv":23104.34,"id":5300820},{"trd":[[2.18,27.65]],"batl":[[2,2.3,3.25]],"ltp":2.18,"tv":12432.72,"id":9629022}],"tv":35537.06}]}
{"op":"mcm","clk":"4215237034","pt":1631536377607,"mc":[{"id":"1.187557985","rc":[{"batb":[[0,1.85,11.67],[1,1.84,75.21],[2,1.83,71.79]],"batl":[[0,1.86,65.09],[1,1.87,79.12],[2,1.92,30]],"ltp":1.85,"tv":23104.34,"id":5300820},{"batb":[[0,2.08,35.33],[1,2.06,8.08],[2,2.04,186.18]],"batl":[[0,2.18,31.25],[1,2.3,188.23],[2,2.32,207.5]],"ltp":2.18,"tv":12432.72,"id":9629022}]}]}
{"op":"mcm","clk":"4215237113","pt":1631536378594,"mc":[{"id":"1.187557985","rc":[{"batl":[[2,1.92,27.06]],"ltp":1.85,"tv":23104.34,"id":5300820},{"batb":[[0,2.08,7.56],[2,2.04,194.3]],"batl":[[0,2.3,188.23],[1,2.32,207.5],[2,2.34,244.2]],"ltp":2.18,"tv":12432.72,"id":9629022}]}]}
{"op":"mcm","clk":"4215237241","pt":1631536380529,"mc":[{"id":"1.187557985","rc":[{"batl":[[2,1.91,28.5]],"ltp":1.85,"tv":23104.34,"id":5300820}]}]}
{"op":"mcm","clk":"4215237290","pt":1631536381109,"mc":[{"id":"1.187557985","rc":[{"batb":[[0,1.86,9.97],[1,1.85,11.67],[2,1.77,400.29]],"batl":[[0,1.87,79.12],[1,1.91,103.71],[2,1.92,27.06]],"ltp":1.85,"tv":23104.34,"id":5300820}]}]}
{"op":"mcm","clk":"4215237396","pt":1631536382620,"mc":[{"id":"1.187557985","rc":[{"batb":[[0,1.77,400.29],[1,1.76,767.73],[2,1.75,634.81]],"ltp":1.85,"tv":23104.34,"id":5300820},{"batb":[[2,2.04,8.12]],"ltp":2.18,"tv":12432.72,"id":9629022}]}]}
{"op":"mcm","clk":"4215237446","pt":1631536383137,"mc":[{"id":"1.187557985","rc":[{"batb":[[1,1.76,229.65]],"ltp":1.85,"tv":23104.34,"id":5300820},{"batl":[[0,2.16,73.25],[1,2.3,188.23],[2,2.32,207.5]],"ltp":2.18,"tv":12432.72,"id":9629022}]}]}
{"op":"mcm","clk":"4215237551","pt":1631536384503,"mc":[{"id":"1.187557985","rc":[{"trd":[[1.86,117.84]],"batl":[[0,1.83,2144.11],[1,1.87,79.12],[2,1.91,103.71]],"ltp":1.86,"tv":23189.39,"id":5300820},{"trd":[[2.16,402.56]],"batl":[[0,2.3,188.23],[1,2.32,207.5],[2,2.34,244.2]],"ltp":2.16,"tv":12505.97,"id":9629022}],"tv":35695.37}]}
{"op":"mcm","clk":"4215237647","pt":1631536385601,"mc":[{"id":"1.187557985","rc":[{"batb":[[0,1.78,8.96],[1,1.77,400.29],[2,1.76,234.19]],"batl":[[0,1.83,179.02],[1,1.84,1039.4],[2,1.85,1184.92]],"ltp":1.86,"tv":23189.39,"id":5300820}]}]}
{"op":"mcm","clk":"4215237746","pt":1631536386651,"mc":[{"id":"1.187557985","rc":[{"batb":[[0,1.78,547.03]],"ltp":1.86,"tv":23189.39,"id":5300820},{"batb":[[0,2.22,93.97],[1,2.1,112.3],[2,2.08,7.56]],"ltp":2.16,"tv":12505.97,"id":9629022}]}]}
{"op":"mcm","clk":"4215237820","pt":1631536387322,"mc":[{"id":"1.187557985","rc":[{"batb":[[0,1.78,36.33]],"ltp":1.86,"tv":23189.39,"id":5300820},{"batb":[[1,2.1,150.1]],"ltp":2.16,"tv":12505.97,"id":9629022}]}]}
{"op":"mcm","clk":"4215237854","pt":1631536387751,"mc":[{"id":"1.187557985","rc":[{"batl":[[0,2.3,215.42]],"ltp":2.16,"tv":12505.97,"id":9629022}]}]}
{"op":"mcm","clk":"4215238014","pt":1631536389525,"mc":[{"id":"1.187557985","rc":[{"batb":[[0,1.8,66.31],[1,1.78,36.33],[2,1.77,400.29]],"batl":[[0,1.81,79.47],[1,1.83,179.02],[2,1.84,1039.4]],"ltp":1.86,"tv":23189.39,"id":5300820}]}]}
{"op":"mcm","clk":"4215238094","pt":1631536390621,"mc":[{"id":"1.187557985","rc":[{"batb":[[1,1.79,70.42],[2,1.78,36.33]],"batl":[[1,1.82,67.7],[2,1.83,179.02]],"ltp":1.86,"tv":23189.39,"id":5300820},{"batb":[[1,2.14,26.31],[2,2.1,150.1]],"ltp":2.16,"tv":12505.97,"id":9629022}]}]}
{"op":"mcm","clk":"4215238132","pt":1631536391232,"mc":[{"id":"1.187557985","rc":[{"batb":[[1,2.1,150.1],[2,2.08,7.56]],"ltp":2.16,"tv":12505.97,"id":9629022}]}]}
{"op":"mcm","clk":"4215238226","pt":1631536392553,"mc":[{"id":"1.187557985","rc":[{"batb":[[2,1.78,8.96]],"batl":[[2,1.85,30]],"ltp":1.86,"tv":23189.39,"id":5300820},{"batb":[[1,2.1,297.37],[2,2.08,245.29]],"batl":[[0,2.36,25.72],[1,2.4,167.79],[2,2.42,200.98]],"ltp":2.16,"tv":12505.97,"id":9629022}]}]}
{"op":"mcm","clk":"4215238286","pt":1631536393443,"mc":[{"id":"1.187557985","rc":[{"batb":[[2,1.73,3.88]],"batl":[[2,1.91,264.37]],"ltp":1.86,"tv":23189.39,"id":5300820},{"batb":[[0,2.1,297.37],[1,2.08,245.29],[2,2.06,295.92]],"batl":[[0,2.4,167.79],[1,2.42,200.98],[2,2.44,249.2]],"ltp":2.16,"tv":12505.97,"id":9629022}]}]}
{"op":"mcm","clk":"4215238369","pt":1631536394632,"mc":[{"id":"1.187557985","rc":[{"batl":[[2,1.91,264.28]],"ltp":1.86,"tv":23189.39,"id":5300820}]}]}
{"op":"mcm","clk":"4215238511","pt":1631536396645,"mc":[{"id":"1.187557985","rc":[{"batb":[[2,1.75,74.51]],"batl":[[2,1.84,66.61]],"ltp":1.86,"tv":23189.39,"id":5300820}]}]}
{"op":"mcm","clk":"4215238549","pt":1631536397154,"mc":[{"id":"1.187557985","rc":[{"batl":[[0,1.91,264.28],[1,1.92,296.51],[2,1.93,289.62]],"ltp":1.86,"tv":23189.39,"id":5300820}]}]}
{"op":"mcm","clk":"4215238640","pt":1631536398562,"mc":[{"id":"1.187557985","rc":[{"batb":[[0,1.73,3.88],[1,1.71,263.23],[2,1.7,286.65]],"ltp":1.86,"tv":23189.39,"id":5300820}]}]}
{"op":"mcm","clk":"4215238709","pt":1631536399556,"mc":[{"id":"1.187557985","rc":[{"batb":[[1,1.72,321.11],[2,1.71,263.23]],"ltp":1.86,"tv":23189.39,"id":5300820},{"batb":[[0,2.12,7.04],[1,2.1,297.37],[2,2.08,245.29]],"ltp":2.16,"tv":12505.97,"id":9629022}]}]}
{"op":"mcm","clk":"4215238784","pt":1631536400447,"mc":[{"id":"1.187557985","rc":[{"batb":[[0,1.79,136.19],[1,1.77,200.07],[2,1.73,3.88]],"batl":[[0,1.85,156.38],[1,1.87,170.24],[2,1.88,27.54]],"ltp":1.86,"tv":23189.39,"id":5300820},{"batb":[[0,2.1,300.37],[1,2.08,248.29],[2,2.06,295.92]],"ltp":2.16,"tv":12505.97,"id":9629022}]}]}
{"op":"mcm","clk":"4215238836","pt":1631536401462,"mc":[{"id":"1.187557985","rc":[{"batb":[[0,1.73,3.88],[1,1.72,642.22],[2,1.71,263.23]],"batl":[[0,1.91,267.37],[1,1.92,296.51],[2,1.93,289.62]],"ltp":1.86,"tv":23189.39,"id":5300820}]}]}
{"op":"mcm","clk":"4215238947","pt":1631536403152,"mc":[{"id":"1.187557985","rc":[{"batl":[[0,1.9,3.09],[1,1.91,267.28],[2,1.92,296.51]],"ltp":1.86,"tv":23189.39,"id":5300820}]}]}
{"op":"mcm","clk":"4215239096","pt":1631536405651,"mc":[{"id":"1.187557985","rc":[{"batl":[[1,1.91,3],[2,1.92,27.06]],"ltp":1.86,"tv":23189.39,"id":5300820},{"batb":[[0,2.1,115.3],[1,2.08,10.56],[2,2.06,8.08]],"ltp":2.16,"tv":12505.97,"id":9629022}]}]}
{"op":"mcm","clk":"4215239218","pt":1631536407459,"mc":[{"id":"1.187557985","rc":[{"batb":[[1,1.71,263.23],[2,1.7,286.65]],"batl":[[0,1.75,1864.04],[1,1.9,3.09],[2,1.91,3]],"ltp":1.86,"tv":23189.39,"id":5300820}]}]}
{"op":"mcm","clk":"4215239299","pt":1631536408463,"mc":[{"id":"1.187557985","rc":[{"batb":[[0,1.73,13.09],[1,1.71,4.66]],"batl":[[0,1.75,158.07],[1,1.76,1086.64],[2,1.77,1257.81]],"ltp":1.86,"tv":23189.39,"id":5300820},{"batl":[[0,2.42,200.98],[1,2.44,249.2],[2,2.46,6.25]],"ltp":2.16,"tv":12505.97,"id":9629022}]}]}
{"op":"mcm","clk":"4215239361","pt":1631536409338,"mc":[{"id":"1.187557985","rc":[{"batb":[[0,2.36,80.5],[1,2.26,23.8],[2,2.18,98.91]],"ltp":2.16,"tv":12505.97,"id":9629022}]}]}
{"op":"mcm","clk":"4215239499","pt":1631536411466,"mc":[{"id":"1.187557985","rc":[{"trd":[[1.74,815.16],[1.75,606.69]],"batb":[[0,1.75,4.9],[1,1.73,13.09],[2,1.71,4.66]],"batl":[[0,1.76,1086.64],[1,1.77,1257.81],[2,1.78,1065.92]],"ltp":1.75,"tv":23614.57,"id":5300820},{"trd":[[2.36,114.52]],"batb":[[0,2.26,23.8],[1,2.18,98.91],[2,2.1,3]],"ltp":2.36,"tv":12586.47,"id":9629022}],"tv":36201.05}]}
{"op":"mcm","clk":"4215239567","pt":1631536412465,"mc":[{"id":"1.187557985","rc":[{"trd":[[1.75,616.49]],"batb":[[0,1.73,84.23],[1,1.71,4.66],[2,1.7,286.65]],"batl":[[0,1.74,4],[1,1.75,80.99],[2,1.76,1086.64]],"ltp":1.75,"tv":23624.37,"id":5300820},{"batb":[[0,2.36,4],[1,2.34,4],[2,2.26,23.8]],"ltp":2.36,"tv":12586.47,"id":9629022}],"tv":36210.85}]}
{"op":"mcm","clk":"4215239631","pt":1631536413350,"mc":[{"id":"1.187557985","rc":[{"trd":[[1.74,828.58],[1.75,783.79],[1.76,569.53]],"batb":[[1,1.72,67.1],[2,1.71,4.66]],"batl":[[0,1.76,1117.35],[1,1.77,1054.68],[2,1.78,1065.92]],"ltp":1.76,"tv":23867.99,"id":5300820},{"trd":[[2.34,48.87],[2.36,118.52]],"batb":[[0,2.26,23.8],[1,2.18,98.91],[2,2.08,7.56]],"ltp":2.34,"tv":12594.47,"id":9629022}],"tv":36462.47}]}
{"op":"mcm","clk":"4215239703","pt":1631536414645,"mc":[{"id":"1.187557985","rc":[{"batl":[[0,1.76,1122.35]],"ltp":1.76,"tv":23867.99,"id":5300820},{"batb":[[0,2.32,3],[1,2.3,3],[2,2.28,4]],"ltp":2.34,"tv":12594.47,"id":9629022}]}]}
{"op":"mcm","clk":"4215239745","pt":1631536415364,"mc":[{"id":"1.187557985","rc":[{"batl":[[0,1.75,147.63],[1,1.76,1295.55],[2,1.77,1054.68]],"ltp":1.76,"tv":23867.99,"id":5300820}]}]}
{"op":"mcm","clk":"4215239812","pt":1631536416456,"mc":[{"id":"1.187557985","rc":[{"batl":[[1,1.76,1266.65]],"ltp":1.76,"tv":23867.99,"id":5300820}]}]}
{"op":"mcm","clk":"4215239917","pt":1631536417970,"mc":[{"id":"1.187557985","rc":[{"batl":[[1,1.76,1261.65]],"ltp":1.76,"tv":23867.99,"id":5300820},{"batb":[[0,2.28,23.43],[1,2.2,197.04],[2,2.18,358.35]],"ltp":2.34,"tv":12594.47,"id":9629022}]}]}
{"op":"mcm","clk":"4215240037","pt":1631536419578,"mc":[{"id":"1.187557985","rc":[{"batb":[[1,1.71,4.66],[2,1.68,106.19]],"batl":[[0,1.75,56.46],[1,1.78,30],[2,1.82,30.25]],"ltp":1.76,"tv":23867.99,"id":5300820},{"batb":[[1,2.2,190.37],[2,2.18,351.99]],"batl":[[0,2.48,24.65],[1,2.56,169.58],[2,2.58,216.69]],"ltp":2.34,"tv":12594.47,"id":9629022}]}]}
{"op":"mcm","clk":"4215240104","pt":1631536420479,"mc":[{"id":"1.187557985","rc":[{"batb":[[0,1.73,75.02],[1,1.67,36.65],[2,1.64,294.68]],"batl":[[2,1.83,227.78]],"ltp":1.76,"tv":23867.99,"id":5300820}]}]}
{"op":"mcm","clk":"4215240172","pt":1631536421582,"mc":[{"id":"1.187557985","rc":[{"batb":[[0,1.73,3.88],[1,1.64,294.68],[2,1.63,295.29]],"batl":[[0,1.83,227.78],[1,1.84,246.99],[2,1.85,347.88]],"ltp":1.76,"tv":23867.99,"id":5300820},{"batb":[[0,2.2,190.37],[1,2.18,351.99],[2,2.16,246.04]],"batl":[[0,2.56,169.58],[1,2.58,216.69],[2,2.6,200.2]],"ltp":2.34,"tv":12594.47,"id":9629022}]}]}
{"op":"mcm","clk":"4215240228","pt":1631536422460,"mc":[{"id":"1.187557985","rc":[{"batb":[[2,1.63,540.35]],"ltp":1.76,"tv":23867.99,"id":5300820}]}]}
{"op":"mcm","clk":"4215240349","pt":1631536424172,"mc":[{"id":"1.187557985","rc":[{"trd":[[1.73,198.33]],"batb":[[0,1.64,294.68],[1,1.63,540.35],[2,1.62,597.12]],"batl":[[0,1.73,32.38],[1,1.83,227.78],[2,1.84,246.99]],"ltp":1.73,"tv":23876.11,"id":5300820}],"tv":36470.59}]}
{"op":"mcm","clk":"4215240397","pt":1631536424799,"mc":[{"id":"1.187557985","rc":[{"batb":[[1,1.63,295.29],[2,1.62,459.81]],"batl":[[1,1.83,231.78]],"ltp":1.73,"tv":23876.11,"id":5300820}]}]}
{"op":"mcm","clk":"4215240549","pt":1631536426589,"mc":[{"id":"1.187557985","rc":[{"batb":[[0,1.65,321.11],[1,1.64,294.68],[2,1.63,295.29]],"batl":[[1,1.82,27.25],[2,1.83,231.78]],"ltp":1.73,"tv":23876.11,"id":5300820},{"batb":[[0,2.2,197.44]],"ltp":2.34,"tv":12594.47,"id":9629022}]}]}
{"op":"mcm","clk":"4215240630","pt":1631536427578,"mc":[{"id":"1.187557985","rc":[{"batb":[[0,1.65,642.22]],"batl":[[1,1.83,231.78],[2,1.84,246.99]],"ltp":1.73,"tv":23876.11,"id":5300820},{"batb":[[0,2.2,190.37]],"ltp":2.34,"tv":12594.47,"id":9629022}]}]}
{"op":"mcm","clk":"4215240672","pt":1631536428308,"mc":[{"id":"1.187557985","rc":[{"trd":[[1.73,263.11]],"batb":[[0,1.75,184.6],[1,1.72,229.12],[2,1.7,229.53]],"batl":[[0,1.78,130.92],[1,1.8,192],[2,1.83,231.78]],"ltp":1.73,"tv":23940.89,"id":5300820}],"tv":36535.37}]}
{"op":"mcm","clk":"4215240717","pt":1631536428886,"mc":[{"id":"1.187557985","rc":[{"batb":[[0,2.22,28.19],[1,2.2,190.37],[2,2.18,351.99]],"batl":[[0,2.54,66.12],[1,2.56,169.58],[2,2.58,216.69]],"ltp":2.34,"tv":12594.47,"id":9629022}]}]}
{"op":"mcm","clk":"4215240814","pt":1631536430195,"mc":[{"id":"1.187557985","rc":[{"batl":[[2,1.82,33.75]],"ltp":1.73,"tv":23940.89,"id":5300820}]}]}
{"op":"mcm","clk":"4215240897","pt":1631536431612,"mc":[{"id":"1.187557985","rc":[{"trd":[[1.75,1079.11]],"batb":[[0,1.75,36.91],[1,1.65,642.22],[2,1.64,294.68]],"batl":[[0,1.83,231.78],[1,1.84,246.99],[2,1.85,347.88]],"ltp":1.75,"tv":24236.21,"id":5300820},{"batb":[[0,2.2,190.37],[1,2.18,351.99],[2,2.16,246.04]],"batl":[[0,2.56,169.58],[1,2.58,216.69],[2,2.6,200.2]],"ltp":2.34,"tv":12594.47,"id":9629022}],"tv":36830.69}]}
{"op":"mcm","clk":"4215240928","pt":1631536432026,"mc":[{"id":"1.187557985","rc":[{"trd":[[1.75,1103.66]],"batb":[[0,1.65,642.22],[1,1.64,294.68],[2,1.63,295.29]],"batl":[[0,1.75,111.19],[1,1.83,231.78],[2,1.84,246.99]],"ltp":1.75,"tv":24260.75,"id":5300820}],"tv":36855.23}]}
{"op":"mcm","clk":"4215241036","pt":1631536433432,"mc":[{"id":"1.187557985","rc":[{"batl":[[0,1.75,202.29]],"ltp":1.75,"tv":24260.75,"id":5300820},{"batb":[[0,2.2,196.79]],"ltp":2.34,"tv":12594.47,"id":9629022}]}]}
{"op":"mcm","clk":"4215241101","pt":1631536434225,"mc":[{"id":"1.187557985","rc":[{"batb":[[2,1.63,540.35]],"ltp":1.75,"tv":24260.75,"id":5300820},{"batb":[[0,2.2,190.37]],"ltp":2.34,"tv":12594.47,"id":9629022}]}]}
{"op":"mcm","clk":"4215241149","pt":1631536435049,"mc":[{"id":"1.187557985","rc":[{"batl":[[1,1.82,30.25],[2,1.83,231.78]],"ltp":1.75,"tv":24260.75,"id":5300820}]}]}
{"op":"mcm","clk":"4215241234","pt":1631536436354,"mc":[{"id":"1.187557985","rc":[{"batl":[[0,1.75,91.11],[1,1.83,231.78],[2,1.84,246.99]],"ltp":1.75,"tv":24260.75,"id":5300820}]}]}
{"op":"mcm","clk":"4215241304","pt":1631536437444,"mc":[{"id":"1.187557985","rc":[{"batb":[[0,2.2,196.74]],"ltp":2.34,"tv":12594.47,"id":9629022}]}]}
{"op":"mcm","clk":"4215241384","pt":1631536438637,"mc":[{"id":"1.187557985","rc":[{"batl":[[0,1.83,231.78],[1,1.84,246.99],[2,1.85,347.88]],"ltp":1.75,"tv":24260.75,"id":5300820},{"batb":[[0,2.2,190.37]],"ltp":2.34,"tv":12594.47,"id":9629022}]}]}
{"op":"mcm","clk":"4215241438","pt":1631536439521,"mc":[{"id":"1.187557985","rc":[{"batl":[[0,1.82,31.25],[1,1.83,231.78],[2,1.84,246.99]],"ltp":1.75,"tv":24260.75,"id":5300820}]}]}
{"op":"mcm","clk":"4215241504","pt":1631536440460,"mc":[{"id":"1.187557985","rc":[{"batl":[[0,1.83,231.78],[1,1.84,246.99],[2,1.85,347.88]],"ltp":1.75,"tv":24260.75,"id":5300820}]}]}
{"op":"mcm","clk":"4215241583","pt":1631536441663,"mc":[{"id":"1.187557985","rc":[{"batb":[[0,1.65,642.94]],"ltp":1.75,"tv":24260.75,"id":5300820}]}]}
{"op":"mcm","clk":"4215241626","pt":1631536442445,"mc":[{"id":"1.187557985","rc":[{"batb":[[0,1.65,642.22]],"batl":[[0,1.83,4],[1,1.86,30.25],[2,2.36,303.3]],"ltp":1.75,"tv":24260.75,"id":5300820},{"batb":[[0,2.18,98.91],[1,2.16,7.03],[2,1.37,4]],"ltp":2.34,"tv":12594.47,"id":9629022}]}]}
{"op":"mcm","clk":"4215241741","pt":1631536444217,"mc":[{"id":"1.187557985","rc":[{"batb":[[0,1.64,294.68],[1,1.63,540.35],[2,1.62,597.12]],"ltp":1.75,"tv":24260.75,"id":5300820}]}]}
{"op":"mcm","clk":"4215241813","pt":1631536445619,"mc":[{"id":"1.187557985","rc":[{"batb":[[0,1.67,9.55],[1,1.65,4.83],[2,1.64,294.68]],"batl":[[0,1.69,1355.74],[1,1.7,1098.38],[2,1.71,1325.63]],"ltp":1.75,"tv":24260.75,"id":5300820}]}]}
{"op":"mcm","clk":"4215241863","pt":1631536446557,"mc":[{"id":"1.187557985","rc":[{"batb":[[0,2.48,70.21],[1,2.38,21.73],[2,2.34,3]],"ltp":2.34,"tv":12594.47,"id":9629022}]}]}
{"op":"mcm","clk":"4215241917","pt":1631536447442,"mc":[{"id":"1.187557985","rc":[{"batb":[[2,1.64,330.12]],"ltp":1.75,"tv":24260.75,"id":5300820},{"batl":[[0,2.56,191.67]],"ltp":2.34,"tv":12594.47,"id":9629022}]}]}
{"op":"mcm","clk":"4215242029","pt":1631536449465,"mc":[{"id":"1.187557985","rc":[{"batb":[[0,1.67,85.77]],"batl":[[0,1.68,115.92],[1,1.69,1413.7],[2,1.7,1098.38]],"ltp":1.75,"tv":24260.75,"id":5300820}]}]}
{"op":"mcm","clk":"4215242077","pt":1631536450447,"mc":[{"id":"1.187557985","rc":[{"batb":[[1,1.66,74.45],[2,1.65,4.83]],"batl":[[2,1.7,1162.79]],"ltp":1.75,"tv":24260.75,"id":5300820}]}]}
{"op":"mcm","clk":"4215242140","pt":1631536451642,"mc":[{"id":"1.187557985","rc":[{"batb":[[1,2.34,3],[2,2.32,88.35]],"ltp":2.34,"tv":12594.47,"id":9629022}]}]}
{"op":"mcm","clk":"4215242185","pt":1631536452482,"mc":[{"id":"1.187557985","rc":[{"batb":[[1,2.38,6.46],[2,2.34,156.96]],"ltp":2.34,"tv":12594.47,"id":9629022}]}]}
{"op":"mcm","clk":"4215242195","pt":1631536452691,"mc":[{"id":"1.187557985","rc":[{"trd":[[1.67,72.49]],"batb":[[0,1.67,82.16]],"ltp":1.67,"tv":24266.17,"id":5300820},{"trd":[[2.5,12.57]],"ltp":2.5,"tv":12595.68,"id":9629022}],"tv":36861.86}]}
{"op":"mcm","clk":"4215242262","pt":1631536453887,"mc":[{"id":"1.187557985","rc":[{"trd":[[2.48,67.1]],"batb":[[0,2.48,40.83]],"ltp":2.48,"tv":12654.42,"id":9629022}],"tv":36920.6}]}
{"op":"mcm","clk":"4215242377","pt":1631536455660,"mc":[{"id":"1.187557985","rc":[{"trd":[[1.67,88.75]],"batb":[[0,1.67,74.03]],"ltp":1.67,"tv":24282.44,"id":5300820},{"batb":[[1,2.4,21.42],[2,2.38,6.46]],"ltp":2.48,"tv":12654.42,"id":9629022}],"tv":36936.86}]}
{"op":"mcm","clk":"4215242432","pt":1631536456553,"mc":[{"id":"1.187557985","rc":[{"batb":[[0,1.66,35.35],[1,1.65,75.06],[2,1.64,330.12]],"batl":[[0,1.67,3.71],[1,1.68,64.22],[2,1.69,1355.74]],"ltp":1.67,"tv":24282.44,"id":5300820}]}]}
{"op":"mcm","clk":"4215242475","pt":1631536457463,"mc":[{"id":"1.187557985","rc":[{"batb":[[1,1.65,70.23],[2,1.62,119.83]],"batl":[[2,1.71,30]],"ltp":1.67,"tv":24282.44,"id":5300820},{"batl":[[0,2.62,23.57],[1,2.64,5.18],[2,2.68,140.68]],"ltp":2.48,"tv":12654.42,"id":9629022}]}]}
{"op":"mcm","clk":"4215242548","pt":1631536458550,"mc":[{"id":"1.187557985","rc":[{"batb":[[0,1.61,361.2],[1,1.6,280.98],[2,1.59,413.16]],"batl":[[0,1.75,292.84],[1,1.76,280.27],[2,1.77,319.2]],"ltp":1.67,"tv":24282.44,"id":5300820},{"batb":[[0,2.34,156.96],[1,2.32,290.44],[2,2.3,280.71]],"batl":[[0,2.64,5.18],[1,2.68,140.68],[2,2.7,193.23]],"ltp":2.48,"tv":12654.42,"id":9629022}]}]}
{"op":"mcm","clk":"4215242604","pt":1631536459279,"mc":[{"id":"1.187557985","rc":[{"batb":[[0,1.68,2.93],[1,1.61,682.31],[2,1.6,280.98]],"ltp":1.67,"tv":24282.44,"id":5300820}]}]}
{"op":"mcm","clk":"4215242679","pt":1631536460373,"mc":[{"id":"1.187557985","rc":[{"batl":[[0,1.74,32.25],[1,1.75,292.84],[2,1.76,280.27]],"ltp":1.67,"tv":24282.44,"id":5300820},{"batb":[[0,2.34,163.68]],"ltp":2.48,"tv":12654.42,"id":9629022}]}]}
{"op":"mcm","clk":"4215242742","pt":1631536461576,"mc":[{"id":"1.187557985","rc":[{"batl":[[0,1.72,34.91],[1,1.81,5],[2,2.22,333.55]],"ltp":1.67,"tv":24282.44,"id":5300820},{"batb":[[0,2.38,5.96],[1,2.34,9.72],[2,2.32,6.64]],"ltp":2.48,"tv":12654.42,"id":9629022}]}]}
{"op":"mcm","clk":"4215242794","pt":1631536462566,"mc":[{"id":"1.187557985","rc":[{"batb":[[0,1.61,682.31],[1,1.6,280.98],[2,1.59,413.16]],"batl":[[0,1.75,4]],"ltp":1.67,"tv":24282.44,"id":5300820},{"batb":[[0,2.34,9.72],[1,2.32,9.64],[2,2.3,85.1]],"ltp":2.48,"tv":12654.42,"id":9629022}]}]}
{"op":"mcm","clk":"4215242852","pt":1631536463661,"mc":[{"id":"1.187557985","rc":[{"trd":[[1.68,224.38]],"batb":[[0,1.61,40.09]],"batl":[[0,1.67,3684.08],[1,1.74,20.84],[2,1.75,4]],"ltp":1.68,"tv":24287.08,"id":5300820}],"tv":36941.5}]}
{"op":"mcm","clk":"4215242903","pt":1631536464389,"mc":[{"id":"1.187557985","rc":[{"batb":[[0,1.62,9.84],[1,1.6,285.97]],"batl":[[0,1.63,207.67],[1,1.64,130.6],[2,1.65,1159.1]],"ltp":1.68,"tv":24287.08,"id":5300820},{"batl":[[0,2.68,140.68],[1,2.7,193.23],[2,2.72,257.44]],"ltp":2.48,"tv":12654.42,"id":9629022}]}]}
{"op":"mcm","clk":"4215242971","pt":1631536465592,"mc":[{"id":"1.187557985","rc":[{"trd":[[1.62,435.74]],"batb":[[0,1.6,285.97],[1,1.59,413.16],[2,1.58,594.47]],"ltp":1.62,"tv":24296.93,"id":5300820},{"trd":[[2.62,6.09]],"batb":[[0,2.62,54.91],[1,2.52,66.53],[2,2.34,9.72]],"batl":[[2,2.72,264.79]],"ltp":2.62,"tv":12660.51,"id":9629022}],"tv":36957.44}]}
{"op":"mcm","clk":"4215243029","pt":1631536466377,"mc":[{"id":"1.187557985","rc":[{"batb":[[2,2.36,4]],"ltp":2.62,"tv":12660.51,"id":9629022}]}]}
{"op":"mcm","clk":"4215243121","pt":1631536468663,"mc":[{"id":"1.187557985","rc":[{"batb":[[0,1.61,63.59],[1,1.6,285.97],[2,1.59,413.16]],"batl":[[0,1.62,201.21],[1,1.63,207.67],[2,1.64,130.6]],"ltp":1.62,"tv":24296.93,"id":5300820}]}]}
{"op":"mcm","clk":"4215243157","pt":1631536469596,"mc":[{"id":"1.187557985","rc":[{"batl":[[0,1.62,122.48]],"ltp":1.62,"tv":24296.93,"id":5300820},{"batb":[[1,2.52,86.26]],"ltp":2.62,"tv":12660.51,"id":9629022}]}]}
{"op":"mcm","clk":"4215243187","pt":1631536470589,"mc":[{"id":"1.187557985","rc":[{"batb":[[1,1.6,299.46]],"ltp":1.62,"tv":24296.93,"id":5300820},{"batb":[[1,2.52,66.53]],"ltp":2.62,"tv":12660.51,"id":9629022}]}]}
{"op":"mcm","clk":"4215243239","pt":1631536471585,"mc":[{"id":"1.187557985","rc":[{"trd":[[1.62,437.38]],"batl":[[0,1.62,121.66]],"ltp":1.62,"tv":24298.56,"id":5300820},{"trd":[[2.62,40.17]],"batb":[[0,2.62,37.86],[2,2.5,205.59]],"ltp":2.62,"tv":12694.59,"id":9629022}],"tv":36993.16}]}
{"op":"mcm","clk":"4215243340","pt":1631536473594,"mc":[{"id":"1.187557985","rc":[{"batb":[[0,1.61,135.49]],"batl":[[0,1.62,197.84]],"ltp":1.62,"tv":24298.56,"id":5300820},{"batb":[[1,2.56,19.23],[2,2.52,66.53]],"ltp":2.62,"tv":12694.59,"id":9629022}]}]}
{"op":"mcm","clk":"4215243349","pt":1631536473803,"mc":[{"id":"1.187557985","rc":[{"batb":[[0,1.61,63.59]],"ltp":1.62,"tv":24298.56,"id":5300820}]}]}
{"op":"mcm","clk":"4215243620","pt":1631536479618,"mc":[{"id":"1.187557985","rc":[{"batb":[[0,1.6,299.46],[1,1.59,413.16],[2,1.58,594.47]],"batl":[[0,1.63,207.67],[1,1.64,167.78],[2,1.65,1189.1]],"ltp":1.62,"tv":24298.56,"id":5300820},{"batb":[[1,2.56,25.56]],"ltp":2.62,"tv":12694.59,"id":9629022}]}]}
{"op":"mcm","clk":"4215243634","pt":1631536479824,"mc":[{"id":"1.187557985","rc":[{"batl":[[1,1.64,130.6]],"ltp":1.62,"tv":24298.56,"id":5300820},{"batb":[[1,2.56,19.23]],"ltp":2.62,"tv":12694.59,"id":9629022}]}]}
{"op":"mcm","clk":"4215243699","pt":1631536481395,"mc":[{"id":"1.187557985","rc":[{"trd":[[2.62,115.88]],"batb":[[0,2.56,19.23],[1,2.52,66.53],[2,2.5,205.59]],"batl":[[0,2.68,140.7]],"ltp":2.62,"tv":12770.3,"id":9629022}],"tv":37068.87}]}
{"op":"mcm","clk":"4215243733","pt":1631536482020,"mc":[{"id":"1.187557985","rc":[{"batb":[[0,1.62,1.25],[1,1.6,299.46],[2,1.59,413.16]],"ltp":1.62,"tv":24298.56,"id":5300820},{"batl":[[0,2.68,140.68]],"ltp":2.62,"tv":12770.3,"id":9629022}]}]}
{"op":"mcm","clk":"4215243789","pt":1631536483313,"mc":[{"id":"1.187557985","rc":[{"batb":[[0,1.62,5.15]],"ltp":1.62,"tv":24298.56,"id":5300820}]}]}
{"op":"mcm","clk":"4215243866","pt":1631536485386,"mc":[{"id":"1.187557985","rc":[{"batb":[[0,1.62,3.9]],"batl":[[2,1.65,1224]],"ltp":1.62,"tv":24298.56,"id":5300820},{"batb":[[1,2.52,71.52]],"ltp":2.62,"tv":12770.3,"id":9629022}]}]}
{"op":"mcm","clk":"4215243988","pt":1631536487782,"mc":[{"id":"1.187557985","rc":[{"batb":[[0,1.61,1.25]],"ltp":1.62,"tv":24298.56,"id":5300820}]}]}
{"op":"mcm","clk":"4215244081","pt":1631536489718,"mc":[{"id":"1.187557985","rc":[{"batl":[[0,1.62,23.24],[1,1.63,207.67],[2,1.64,130.6]],"ltp":1.62,"tv":24298.56,"id":5300820}]}]}
{"op":"mcm","clk":"4215244159","pt":1631536491602,"mc":[{"id":"1.187557985","rc":[{"trd":[[1.6,1296.33],[1.61,80.94]],"batb":[[0,1.6,185.19],[1,1.59,413.16],[2,1.58,594.47]],"ltp":1.6,"tv":24529.58,"id":5300820}],"tv":37299.88}]}
{"op":"mcm","clk":"4215244292","pt":1631536494520,"mc":[{"id":"1.187557985","rc":[{"batl":[[2,2.72,257.44]],"ltp":2.62,"tv":12770.3,"id":9629022}]}]}
{"op":"mcm","clk":"4215244333","pt":1631536495200,"mc":[{"id":"1.187557985","rc":[{"batb":[[0,1.6,13.5],[1,1.57,278.38],[2,1.56,467.03]],"batl":[[1,1.63,43.5],[2,1.65,30]],"ltp":1.6,"tv":24529.58,"id":5300820},{"batb":[[0,2.58,5.56],[1,2.56,19.23],[2,2.52,66.53]],"batl":[[0,2.74,134.23],[1,2.76,172.16],[2,2.78,233.41]],"ltp":2.62,"tv":12770.3,"id":9629022}]}]}
{"op":"mcm","clk":"4215244411","pt":1631536496448,"mc":[{"id":"1.187557985","rc":[{"batb":[[2,1.56,426.95]],"batl":[[2,1.67,251.7]],"ltp":1.6,"tv":24529.58,"id":5300820},{"batb":[[1,2.52,66.53],[2,2.5,205.59]],"ltp":2.62,"tv":12770.3,"id":9629022}]}]}
{"op":"mcm","clk":"4215244478","pt":1631536497645,"mc":[{"id":"1.187557985","rc":[{"batl":[[2,1.67,473.52]],"ltp":1.6,"tv":24529.58,"id":5300820}]}]}
{"op":"mcm","clk":"4215244520","pt":1631536498325,"mc":[{"id":"1.187557985","rc":[{"batl":[[2,1.64,43.43]],"ltp":1.6,"tv":24529.58,"id":5300820},{"batb":[[1,2.56,5.83],[2,2.52,66.53]],"batl":[[0,2.74,137.23]],"ltp":2.62,"tv":12770.3,"id":9629022}]}]}
{"op":"mcm","clk":"4215244538","pt":1631536498739,"mc":[{"id":"1.187557985","rc":[{"trd":[[1.6,1296.7]],"batb":[[0,1.6,13.31]],"ltp":1.6,"tv":24529.96,"id":5300820}],"tv":37300.26}]}
{"op":"mcm","clk":"4215244602","pt":1631536500052,"mc":[{"id":"1.187557985","rc":[{"trd":[[1.62,442.03]],"batl":[[0,1.62,20.92]],"ltp":1.62,"tv":24534.6,"id":5300820}],"tv":37304.9}]}
{"op":"mcm","clk":"4215244681","pt":1631536501554,"mc":[{"id":"1.187557985","rc":[{"batb":[[1,1.58,46.06],[2,1.57,278.38]],"ltp":1.62,"tv":24534.6,"id":5300820},{"batl":[[0,2.74,142.21]],"ltp":2.62,"tv":12770.3,"id":9629022}]}]}
{"op":"mcm","clk":"4215244764","pt":1631536503337,"mc":[{"id":"1.187557985","rc":[{"batb":[[1,1.57,278.38],[2,1.56,426.95]],"ltp":1.62,"tv":24534.6,"id":5300820},{"batl":[[0,2.74,137.23]],"ltp":2.62,"tv":12770.3,"id":9629022}]}]}
{"op":"mcm","clk":"4215244846","pt":1631536505237,"mc":[{"id":"1.187557985","rc":[{"batl":[[1,1.73,3],[2,1.79,15]],"ltp":1.62,"tv":24534.6,"id":5300820}]}]}
{"op":"mcm","clk":"4215244905","pt":1631536506566,"mc":[{"id":"1.187557985","rc":[{"trd":[[1.62,446.67]],"batb":[[1,1.58,47.06],[2,1.57,278.38]],"batl":[[0,1.62,18.59]],"ltp":1.62,"tv":24539.25,"id":5300820},{"batl":[[0,2.74,141.71]],"ltp":2.62,"tv":12770.3,"id":9629022}],"tv":37309.55}]}
{"op":"mcm","clk":"4215244934","pt":1631536506923,"mc":[{"id":"1.187557985","rc":[{"batb":[[0,1.57,278.38],[1,1.56,426.95],[2,1.55,487.48]],"ltp":1.62,"tv":24539.25,"id":5300820},{"batl":[[0,2.74,137.23]],"ltp":2.62,"tv":12770.3,"id":9629022}]}]}
{"op":"mcm","clk":"4215245035","pt":1631536508553,"mc":[{"id":"1.187557985","rc":[{"trd":[[1.59,76.31]],"batb":[[0,1.57,5.08]],"batl":[[0,1.59,228.39],[1,1.6,1337.97],[2,1.61,1160.14]],"ltp":1.59,"tv":24563.97,"id":5300820},{"batl":[[0,2.78,233.41],[1,2.8,5.12],[2,2.82,4.25]],"ltp":2.62,"tv":12770.3,"id":9629022}],"tv":37334.27}]}
{"op":"mcm","clk":"4215245100","pt":1631536509655,"mc":[{"id":"1.187557985","rc":[{"batb":[[0,2.72,55.15],[1,2.6,106.82],[2,2.58,5.56]],"batl":[[0,2.76,7.25],[1,2.78,233.41],[2,2.8,5.12]],"ltp":2.62,"tv":12770.3,"id":9629022}]}]}
{"op":"mcm","clk":"4215245197","pt":1631536511347,"mc":[{"id":"1.187557985","rc":[{"batb":[[0,1.58,13.48],[1,1.57,5.08],[2,1.56,426.95]],"ltp":1.59,"tv":24563.97,"id":5300820}]}]}
{"op":"mcm","clk":"4215245260","pt":1631536512534,"mc":[{"id":"1.187557985","rc":[{"trd":[[1.58,1181.85]],"batb":[[0,1.57,63.19],[1,1.56,426.95],[2,1.55,487.48]],"batl":[[0,1.58,191.57],[1,1.59,286.92],[2,1.6,1337.97]],"ltp":1.58,"tv":24590.93,"id":5300820}],"tv":37361.23}]}
{"op":"mcm","clk":"4215245292","pt":1631536513168,"mc":[{"id":"1.187557985","rc":[{"batb":[[1,1.56,505.03]],"ltp":1.58,"tv":24590.93,"id":5300820}]}]}
{"op":"mcm","clk":"4215245371","pt":1631536514662,"mc":[{"id":"1.187557985","rc":[{"batb":[[1,2.62,6.04],[2,2.6,88.07]],"ltp":2.62,"tv":12770.3,"id":9629022}]}]}
{"op":"mcm","clk":"4215245418","pt":1631536515652,"mc":[{"id":"1.187557985","rc":[{"batb":[[2,2.6,235.73]],"ltp":2.62,"tv":12770.3,"id":9629022}]}]}
{"op":"mcm","clk":"4215245496","pt":1631536517326,"mc":[{"id":"1.187557985","rc":[{"batb":[[1,1.56,426.95]],"batl":[[0,1.58,210.16],[1,1.59,228.39]],"ltp":1.58,"tv":24590.93,"id":5300820},{"batb":[[1,2.64,18.29],[2,2.62,6.04]],"ltp":2.62,"tv":12770.3,"id":9629022}]}]}
{"op":"mcm","clk":"4215245673","pt":1631536520636,"mc":[{"id":"1.187557985","rc":[{"trd":[[1.57,1092.3]],"batb":[[0,1.57,58.11],[1,1.53,330.75],[2,1.52,444.42]],"batl":[[1,1.61,71.5],[2,1.63,259.3]],"ltp":1.57,"tv":24591.3,"id":5300820},{"batb":[[0,2.64,18.29],[1,2.62,6.04],[2,2.6,209.5]],"batl":[[0,2.88,145.09],[1,2.9,182.7],[2,2.92,176.7]],"ltp":2.62,"tv":12770.3,"id":9629022}],"tv":37361.6}]}
{"op":"mcm","clk":"4215245729","pt":1631536521475,"mc":[{"id":"1.187557985","rc":[{"batb":[[2,1.52,402.82]],"batl":[[1,1.61,41.5]],"ltp":1.57,"tv":24591.3,"id":5300820},{"batb":[[0,2.62,6.04],[1,2.6,209.5],[2,2.58,157.1]],"batl":[[1,2.9,160.94]],"ltp":2.62,"tv":12770.3,"id":9629022}]}]}
{"op":"mcm","clk":"4215245836","pt":1631536523664,"mc":[{"id":"1.187557985","rc":[{"batb":[[0,1.55,50.19]],"batl":[[0,1.57,15],[1,1.58,18.59],[2,1.6,49.42]],"ltp":1.57,"tv":24591.3,"id":5300820},{"batb":[[0,2.66,4.78]],"batl":[[0,2.82,4.75],[1,2.88,145.09],[2,2.9,160.94]],"ltp":2.62,"tv":12770.3,"id":9629022}]}]}
{"op":"mcm","clk":"4215245884","pt":1631536524552,"mc":[{"id":"1.187557985","rc":[{"batb":[[0,1.53,330.75],[1,1.52,402.82],[2,1.51,424.44]],"ltp":1.57,"tv":24591.3,"id":5300820},{"batl":[[0,2.88,145.09],[1,2.9,160.94],[2,2.92,176.7]],"ltp":2.62,"tv":12770.3,"id":9629022}]}]}
{"op":"mcm","clk":"4215246005","pt":1631536526653,"mc":[{"id":"1.187557985","rc":[{"batb":[[0,1.53,625.75],[1,1.52,583.31]],"batl":[[1,1.58,226.14],[2,1.59,146.08]],"ltp":1.57,"tv":24591.3,"id":5300820},{"batl":[[0,2.88,148.09]],"ltp":2.62,"tv":12770.3,"id":9629022}]}]}
{"op":"mcm","clk":"4215246083","pt":1631536527646,"mc":[{"id":"1.187557985","rc":[{"trd":[[1.56,1023.14]],"batb":[[0,1.55,6],[1,1.54,46.58],[2,1.53,625.75]],"batl":[[0,1.56,219.23],[1,1.57,15],[2,1.58,226.14]],"ltp":1.56,"tv":24626.29,"id":5300820},{"trd":[[2.76,96.85]],"batl":[[0,2.82,3],[1,2.86,23.35],[2,2.88,148.09]],"ltp":2.76,"tv":12790.07,"id":9629022}],"tv":37416.36}]}
{"op":"mcm","clk":"4215246128","pt":1631536528187,"mc":[{"id":"1.187557985","rc":[{"batl":[[1,1.58,226.14],[2,1.59,146.08]],"ltp":1.56,"tv":24626.29,"id":5300820}]}]}
{"op":"mcm","clk":"4215246195","pt":1631536529301,"mc":[{"id":"1.187557985","rc":[{"batb":[[1,1.54,327.11],[2,1.53,336.75]],"batl":[[1,1.58,18.59],[2,1.6,49.42]],"ltp":1.56,"tv":24626.29,"id":5300820},{"batl":[[1,2.88,148.09],[2,2.9,160.94]],"ltp":2.76,"tv":12790.07,"id":9629022}]}]}
{"op":"mcm","clk":"4215246256","pt":1631536530648,"mc":[{"id":"1.187557985","rc":[{"batb":[[0,1.55,175]],"ltp":1.56,"tv":24626.29,"id":5300820}]}]}
{"op":"mcm","clk":"4215246314","pt":1631536531649,"mc":[{"id":"1.187557985","rc":[{"batb":[[0,1.55,6]],"batl":[[0,1.56,24.37]],"ltp":1.56,"tv":24626.29,"id":5300820}]}]}
{"op":"mcm","clk":"4215246353","pt":1631536532390,"mc":[{"id":"1.187557985","rc":[{"batb":[[0,1.54,321.11],[1,1.53,330.75],[2,1.52,402.82]],"ltp":1.56,"tv":24626.29,"id":5300820},{"batl":[[0,2.88,145.09],[1,2.9,160.94],[2,2.92,176.7]],"ltp":2.76,"tv":12790.07,"id":9629022}]}]}
{"op":"mcm","clk":"4215246456","pt":1631536534389,"mc":[{"id":"1.187557985","rc":[{"batb":[[0,1.55,44.39]],"ltp":1.56,"tv":24626.29,"id":5300820},{"batl":[[0,2.82,4.86],[1,2.88,145.09],[2,2.9,160.94]],"ltp":2.76,"tv":12790.07,"id":9629022}]}]}
{"op":"mcm","clk":"4215246477","pt":1631536534705,"mc":[{"id":"1.187557985","rc":[{"batb":[[0,1.53,330.75],[1,1.52,402.82],[2,1.51,424.44]],"ltp":1.56,"tv":24626.29,"id":5300820},{"batl":[[0,2.88,145.09],[1,2.9,160.94],[2,2.92,176.7]],"ltp":2.76,"tv":12790.07,"id":9629022}]}]}
{"op":"mcm","clk":"4215246573","pt":1631536536794,"mc":[{"id":"1.187557985","rc":[{"batl":[[0,1.55,23.24],[1,1.56,24.37],[2,1.58,18.59]],"ltp":1.56,"tv":24626.29,"id":5300820},{"batb":[[1,2.6,61.84],[2,1.37,4]],"ltp":2.76,"tv":12790.07,"id":9629022}]}]}
{"op":"mcm","clk":"4215246656","pt":1631536538504,"mc":[{"id":"1.187557985","rc":[{"trd":[[1.55,1044.75]],"batl":[[0,1.56,24.37],[1,1.58,18.59],[2,1.6,3926.31]],"ltp":1.55,"tv":24672.78,"id":5300820}],"tv":37462.85}]}
{"op":"mcm","clk":"4215246698","pt":1631536539507,"mc":[{"id":"1.187557985","rc":[{"batl":[[2,1.6,6.51]],"ltp":1.55,"tv":24672.78,"id":5300820},{"batb":[[0,2.8,1366.08],[1,2.78,1325.9],[2,2.76,1325.9]],"ltp":2.76,"tv":12790.07,"id":9629022}]}]}
{"op":"mcm","clk":"4215246762","pt":1631536540568,"mc":[{"id":"1.187557985","rc":[{"trd":[[1.55,1065.32]],"batb":[[0,1.53,49.54]],"batl":[[0,1.55,226.78],[1,1.56,181.07],[2,1.58,18.59]],"ltp":1.55,"tv":24693.35,"id":5300820},{"trd":[[2.84,476.96]],"batb":[[0,2.84,42.53],[1,2.8,683.04],[2,2.78,662.94]],"batl":[[0,2.9,4.65],[1,3.1,339.32],[2,3.15,598.8]],"ltp":2.84,"tv":12804.25,"id":9629022}],"tv":37497.61}]}
{"op":"mcm","clk":"4215246806","pt":1631536541406,"mc":[{"id":"1.187557985","rc":[{"batl":[[1,1.56,161.95],[2,1.58,48.59]],"ltp":1.55,"tv":24693.35,"id":5300820},{"batl":[[1,3.05,20.95],[2,3.1,339.32]],"ltp":2.84,"tv":12804.25,"id":9629022}]}]}
{"op":"mcm","clk":"4215246950","pt":1631536544603,"mc":[{"id":"1.187557985","rc":[{"batb":[[0,1.53,128.47],[1,1.52,479.42]],"batl":[[0,1.54,78.71],[1,1.55,291.79],[2,1.56,242.75]],"ltp":1.55,"tv":24693.35,"id":5300820}]}]}
{"op":"mcm","clk":"4215247073","pt":1631536546609,"mc":[{"id":"1.187557985","rc":[{"batb":[[2,1.51,477.43]],"ltp":1.55,"tv":24693.35,"id":5300820},{"batl":[[1,2.98,5.25],[2,3.05,25.45]],"ltp":2.84,"tv":12804.25,"id":9629022}]}]}
{"op":"mcm","clk":"4215247168","pt":1631536548474,"mc":[{"id":"1.187557985","rc":[{"batb":[[0,1.53,362.97]],"batl":[[1,1.55,356.22],[2,1.56,237.5]],"ltp":1.55,"tv":24693.35,"id":5300820}]}]}
{"op":"mcm","clk":"4215247182","pt":1631536548685,"mc":[{"id":"1.187557985","rc":[{"batb":[[0,1.53,293.47],[1,1.52,402.82]],"batl":[[1,1.55,291.79],[2,1.56,156.7]],"ltp":1.55,"tv":24693.35,"id":5300820}]}]}
{"op":"mcm","clk":"4215247240","pt":1631536549793,"mc":[{"id":"1.187557985","rc":[{"batl":[[2,1.56,203.37]],"ltp":1.55,"tv":24693.35,"id":5300820},{"batb":[[2,2.78,667.6]],"ltp":2.84,"tv":12804.25,"id":9629022}]}]}
{"op":"mcm","clk":"4215247335","pt":1631536551614,"mc":[{"id":"1.187557985","rc":[{"trd":[[1.53,1197.93]],"batb":[[0,1.53,249.14],[1,1.51,52.99],[2,1.5,160.83]],"batl":[[1,1.55,65.01],[2,1.58,48.59]],"ltp":1.53,"tv":24703.85,"id":5300820},{"batb":[[1,2.74,17.24],[2,2.72,54.98]],"batl":[[0,2.98,5.25],[1,3.05,25.45],[2,3.05,0]],"ltp":2.84,"tv":12804.25,"id":9629022}],"tv":37508.11}]}
{"op":"mcm","clk":"4215247396","pt":1631536552513,"mc":[{"id":"1.187557985","rc":[{"batb":[[0,1.53,243.93],[2,1.49,46.01]],"batl":[[2,1.58,18.59]],"ltp":1.53,"tv":24703.85,"id":5300820},{"batb":[[0,2.72,54.98],[1,2.66,3],[2,2.64,4]],"batl":[[1,3.05,4.5]],"ltp":2.84,"tv":12804.25,"id":9629022}]}]}
{"op":"mcm","clk":"4215247426","pt":1631536552984,"mc":[{"id":"1.187557985","rc":[{"batb":[[0,1.53,78.93],[1,1.49,46.01],[2,1.47,176.82]],"batl":[[2,1.6,6.51]],"ltp":1.53,"tv":24703.85,"id":5300820},{"batl":[[0,3.05,4.5],[1,3.05,0]],"ltp":2.84,"tv":12804.25,"id":9629022}]}]}
{"op":"mcm","clk":"4215247497","pt":1631536554402,"mc":[{"id":"1.187557985","rc":[{"trd":[[1.53,1198.12]],"batb":[[0,1.53,78.83],[2,1.47,462.44]],"batl":[[2,1.56,52.17]],"ltp":1.53,"tv":24704.04,"id":5300820},{"batb":[[0,2.78,5.66],[1,2.72,54.98],[2,2.66,3]],"ltp":2.84,"tv":12804.25,"id":9629022}],"tv":37508.29}]}
{"op":"mcm","clk":"4215247527","pt":1631536554947,"mc":[{"id":"1.187557985","rc":[{"trd":[[1.54,893.6]],"batb":[[0,1.49,46.01],[1,1.47,462.44],[2,1.46,648.89]],"batl":[[0,1.56,52.17],[1,1.58,161.73],[2,1.59,146.25]],"ltp":1.54,"tv":24708.99,"id":5300820}],"tv":37513.25}]}
{"op":"mcm","clk":"4215247586","pt":1631536556280,"mc":[{"id":"1.187557985","rc":[{"batb":[[0,1.51,49.99],[1,1.49,46.01],[2,1.47,462.44]],"ltp":1.54,"tv":24708.99,"id":5300820},{"batl":[[0,2.98,4.25],[1,3.05,4.5]],"ltp":2.84,"tv":12804.25,"id":9629022}]}]}
{"op":"mcm","clk":"4215247636","pt":1631536557275,"mc":[{"id":"1.187557985","rc":[{"batb":[[0,1.49,46.01],[1,1.47,462.44],[2,1.46,648.89]],"ltp":1.54,"tv":24708.99,"id":5300820},{"batl":[[0,3.05,4.5],[1,3.05,0]],"ltp":2.84,"tv":12804.25,"id":9629022}]}]}
{"op":"mcm","clk":"4215247686","pt":1631536558275,"mc":[{"id":"1.187557985","rc":[{"batb":[[0,1.5,5],[1,1.49,52.01],[2,1.48,5]],"ltp":1.54,"tv":24708.99,"id":5300820},{"batl":[[0,3.05,7.5]],"ltp":2.84,"tv":12804.25,"id":9629022}]}]}
{"op":"mcm","clk":"4215247752","pt":1631536559482,"mc":[{"id":"1.187557985","rc":[{"batb":[[0,1.51,5],[1,1.5,5],[2,1.49,52.01]],"ltp":1.54,"tv":24708.99,"id":5300820},{"batl":[[0,2.98,3],[1,3.05,7.5]],"ltp":2.84,"tv":12804.25,"id":9629022}]}]}
{"op":"mcm","clk":"4215247799","pt":1631536560475,"mc":[{"id":"1.187557985","rc":[{"batb":[[0,1.51,57.99]],"ltp":1.54,"tv":24708.99,"id":5300820},{"batl":[[0,2.98,7.75]],"ltp":2.84,"tv":12804.25,"id":9629022}]}]}
{"op":"mcm","clk":"4215247845","pt":1631536561312,"mc":[{"id":"1.187557985","rc":[{"batb":[[0,1.51,5]],"ltp":1.54,"tv":24708.99,"id":5300820},{"batl":[[0,2.98,3],[1,3,3],[2,3.05,7.5]],"ltp":2.84,"tv":12804.25,"id":9629022}]}]}
{"op":"mcm","clk":"4215247941","pt":1631536562990,"mc":[{"id":"1.187557985","rc":[{"batl":[[0,1.53,2],[1,1.56,52.17],[2,1.58,161.73]],"ltp":1.54,"tv":24708.99,"id":5300820}]}]}
{"op":"mcm","clk":"4215248008","pt":1631536564504,"mc":[{"id":"1.187557985","rc":[{"batb":[[0,1.51,53.99]],"ltp":1.54,"tv":24708.99,"id":5300820},{"batl":[[0,2.98,7.25]],"ltp":2.84,"tv":12804.25,"id":9629022}]}]}
{"op":"mcm","clk":"4215248068","pt":1631536565455,"mc":[{"id":"1.187557985","rc":[{"batb":[[0,1.51,5]],"ltp":1.54,"tv":24708.99,"id":5300820},{"batl":[[0,2.98,3]],"ltp":2.84,"tv":12804.25,"id":9629022}]}]}
{"op":"mcm","clk":"4215248112","pt":1631536566187,"mc":[{"id":"1.187557985","rc":[{"trd":[[1.53,1202.12]],"batl":[[0,1.56,52.17],[1,1.58,161.73],[2,1.59,146.25]],"ltp":1.53,"tv":24712.99,"id":5300820}],"tv":37517.25}]}
{"op":"mcm","clk":"4215248228","pt":1631536568489,"mc":[{"id":"1.187557985","rc":[{"trd":[[1.56,1046.19]],"batb":[[0,1.55,5.15],[1,1.54,165.83],[2,1.53,170.34]],"batl":[[0,1.56,39.28]],"ltp":1.56,"tv":24736.04,"id":5300820},{"trd":[[2.78,490.83]],"batb":[[0,2.72,54.98],[1,1.37,4],[2,1.3,10]],"batl":[[0,2.94,650.52],[1,2.96,631.38],[2,2.98,634.38]],"ltp":2.78,"tv":12817.1,"id":9629022}],"tv":37553.15}]}
{"op":"mcm","clk":"4215248295","pt":1631536569530,"mc":[{"id":"1.187557985","rc":[{"batb":[[1,1.54,313.28]],"ltp":1.56,"tv":24736.04,"id":5300820},{"batb":[[1,2.66,18.07],[2,2.6,61.42]],"batl":[[0,2.92,21.65],[1,2.94,650.52],[2,2.96,631.38]],"ltp":2.78,"tv":12817.1,"id":9629022}]}]}
{"op":"mcm","clk":"4215248406","pt":1631536571619,"mc":[{"id":"1.187557985","rc":[{"trd":[[1.55,1075.32]],"batb":[[0,1.54,313.42],[1,1.53,170.34],[2,1.52,1096.87]],"ltp":1.55,"tv":24746.04,"id":5300820},{"batl":[[0,2.84,4],[1,2.92,25.65],[2,2.94,650.52]],"ltp":2.78,"tv":12817.1,"id":9629022}],"tv":37563.14}]}
{"op":"mcm","clk":"4215248460","pt":1631536572619,"mc":[{"id":"1.187557985","rc":[{"trd":[[1.55,1075.61]],"batb":[[0,1.54,385.41],[2,1.52,1138.47]],"batl":[[0,1.55,75.69],[1,1.56,106.55],[2,1.58,161.73]],"ltp":1.55,"tv":24746.33,"id":5300820}],"tv":37563.44}]}
{"op":"mcm","clk":"4215248503","pt":1631536573510,"mc":[{"id":"1.187557985","rc":[{"trd":[[1.54,897.6]],"batb":[[0,1.54,383.41],[1,1.53,236.54]],"batl":[[2,1.57,61.98]],"ltp":1.54,"tv":24750.33,"id":5300820}],"tv":37567.44}]}
{"op":"mcm","clk":"4215248555","pt":1631536574613,"mc":[{"id":"1.187557985","rc":[{"trd":[[1.55,1226.98]],"batb":[[0,1.55,123.32],[1,1.54,425.97],[2,1.53,236.54]],"batl":[[0,1.56,106.55],[1,1.57,61.98],[2,1.58,161.73]],"ltp":1.55,"tv":24901.7,"id":5300820}],"tv":37718.81}]}
{"op":"mcm","clk":"4215248576","pt":1631536575027,"mc":[{"id":"1.187557985","rc":[{"batl":[[1,1.57,102.48]],"ltp":1.55,"tv":24901.7,"id":5300820},{"batb":[[0,2.74,5.29],[1,2.72,54.98],[2,2.66,18.07]],"ltp":2.78,"tv":12817.1,"id":9629022}]}]}
{"op":"mcm","clk":"4215248721","pt":1631536577543,"mc":[{"id":"1.187557985","rc":[{"batb":[[0,1.55,193.71],[1,1.54,353.84],[2,1.53,170.34]],"batl":[[1,1.57,40.5],[2,1.58,204.98]],"ltp":1.55,"tv":24901.7,"id":5300820},{"batb":[[1,2.72,60.57]],"batl":[[0,2.82,31.22],[1,2.84,4],[2,2.92,25.65]],"ltp":2.78,"tv":12817.1,"id":9629022}]}]}
{"op":"mcm","clk":"4215248937","pt":1631536581626,"mc":[{"id":"1.187557985","rc":[{"batb":[[1,1.52,41.6],[2,1.5,209.31]],"batl":[[0,1.56,67.27],[1,1.6,6.51],[2,1.61,30]],"ltp":1.55,"tv":24901.7,"id":5300820},{"batb":[[0,2.72,5.59],[1,2.66,18.07],[2,2.6,61.42]],"batl":[[0,2.92,21.65],[1,3,7.04],[2,3.05,4.5]],"ltp":2.78,"tv":12817.1,"id":9629022}]}]}
{"op":"mcm","clk":"4215248986","pt":1631536582468,"mc":[{"id":"1.187557985","rc":[{"batb":[[1,1.5,209.31],[2,1.49,46.01]],"batl":[[2,1.79,15]],"ltp":1.55,"tv":24901.7,"id":5300820},{"batb":[[1,2.6,61.42],[2,1.37,4]],"batl":[[0,3,7.04],[1,3.05,4.5],[2,3.15,3.7]],"ltp":2.78,"tv":12817.1,"id":9629022}]}]}
{"op":"mcm","clk":"4215249050","pt":1631536583614,"mc":[{"id":"1.187557985","rc":[{"batb":[[0,1.5,162.51],[1,1.49,46.01],[2,1.47,50.67]],"batl":[[0,1.6,6.51],[1,1.79,15],[2,2.1,368.32]],"ltp":1.55,"tv":24901.7,"id":5300820},{"batl":[[0,3,3]],"ltp":2.78,"tv":12817.1,"id":9629022}]}]}
{"op":"mcm","clk":"4215249110","pt":1631536584653,"mc":[{"id":"1.187557985","rc":[{"batb":[[0,1.5,361.04],[1,1.49,235.74]],"batl":[[0,1.57,43.5],[1,1.58,41.25],[2,1.6,6.51]],"ltp":1.55,"tv":24901.7,"id":5300820},{"batb":[[0,2.74,4.52],[1,2.72,5.59],[2,2.6,61.42]],"ltp":2.78,"tv":12817.1,"id":9629022}]}]}
{"op":"mcm","clk":"4215249129","pt":1631536584916,"mc":[{"id":"1.187557985","rc":[{"batl":[[0,1.58,41.25],[1,1.6,6.51],[2,1.62,171]],"ltp":1.55,"tv":24901.7,"id":5300820},{"batb":[[0,2.72,5.59],[1,2.6,61.42],[2,1.37,4]],"ltp":2.78,"tv":12817.1,"id":9629022}]}]}
{"op":"mcm","clk":"4215249195","pt":1631536586264,"mc":[{"id":"1.187557985","rc":[{"batb":[[0,1.5,409.42]],"ltp":1.55,"tv":24901.7,"id":5300820},{"batl":[[0,3,7.43]],"ltp":2.78,"tv":12817.1,"id":9629022}]}]}
{"op":"mcm","clk":"4215249219","pt":1631536586841,"mc":[{"id":"1.187557985","rc":[{"batb":[[0,1.5,414.42],[1,1.49,241.74]],"batl":[[1,1.59,5],[2,1.6,6.51]],"ltp":1.55,"tv":24901.7,"id":5300820},{"batb":[[0,2.72,8.59],[1,2.7,3],[2,2.6,61.42]],"ltp":2.78,"tv":12817.1,"id":9629022}]}]}
{"op":"mcm","clk":"4215249317","pt":1631536588563,"mc":[{"id":"1.187557985","rc":[{"batl":[[0,1.58,45.25]],"ltp":1.55,"tv":24901.7,"id":5300820},{"batb":[[0,2.74,3],[1,2.72,8.59],[2,2.7,3]],"ltp":2.78,"tv":12817.1,"id":9629022}]}]}
{"op":"mcm","clk":"4215249381","pt":1631536589556,"mc":[{"id":"1.187557985","rc":[{"batl":[[0,1.58,4]],"ltp":1.55,"tv":24901.7,"id":5300820}]}]}
{"op":"mcm","clk":"4215249488","pt":1631536591642,"mc":[{"id":"1.187557985","rc":[{"batl":[[0,1.59,5],[1,1.6,6.51],[2,1.79,15]],"ltp":1.55,"tv":24901.7,"id":5300820},{"batb":[[0,2.72,5.59],[1,2.7,3],[2,2.6,61.42]],"ltp":2.78,"tv":12817.1,"id":9629022}]}]}
{"op":"mcm","clk":"4215249523","pt":1631536592169,"mc":[{"id":"1.187557985","rc":[{"batb":[[0,1.51,10.56],[1,1.5,414.42],[2,1.49,247.09]],"batl":[[0,1.54,188.23],[1,1.55,160.79],[2,1.59,5]],"ltp":1.55,"tv":24901.7,"id":5300820},{"batb":[[0,2.8,683.04],[1,2.78,662.94],[2,2.76,662.94]],"batl":[[2,3.1,339.32]],"ltp":2.78,"tv":12817.1,"id":9629022}]}]}
{"op":"mcm","clk":"4215249617","pt":1631536593533,"mc":[{"id":"1.187557985","rc":[{"batb":[[1,1.5,453.84],[2,1.49,289.94]],"batl":[[2,1.57,50]],"ltp":1.55,"tv":24901.7,"id":5300820},{"trd":[[2.84,491.15]],"batb":[[0,2.84,41.94],[1,2.8,683.04],[2,2.78,662.94]],"batl":[[0,2.98,16.54],[1,3,7.43],[2,3.05,25.45]],"ltp":2.84,"tv":12831.28,"id":9629022}],"tv":37732.99}]}
{"op":"mcm","clk":"4215249783","pt":1631536596451,"mc":[{"id":"1.187557985","rc":[{"batb":[[0,1.52,55.62],[1,1.51,10.56],[2,1.5,453.84]],"batl":[[0,1.53,79.66],[1,1.54,249.6],[2,1.55,160.79]],"ltp":1.55,"tv":24901.7,"id":5300820}]}]}
{"op":"mcm","clk":"4215249848","pt":1631536597649,"mc":[{"id":"1.187557985","rc":[{"batb":[[1,1.51,169.72]],"ltp":1.55,"tv":24901.7,"id":5300820}]}]}
{"op":"mcm","clk":"4215249926","pt":1631536599069,"mc":[{"id":"1.187557985","rc":[{"trd":[[1.52,838.18]],"batb":[[0,1.52,53.62]],"ltp":1.52,"tv":24905.7,"id":5300820}],"tv":37736.99}]}
{"op":"mcm","clk":"4215250046","pt":1631536601584,"mc":[{"id":"1.187557985","rc":[{"batb":[[0,1.52,131.97],[1,1.51,101.56]],"batl":[[1,1.54,188.23]],"ltp":1.52,"tv":24905.7,"id":5300820}]}]}
{"op":"mcm","clk":"4215250085","pt":1631536602264,"mc":[{"id":"1.187557985","rc":[{"batb":[[1,1.51,91],[2,1.49,42.85]],"batl":[[1,1.54,40.75],[2,1.57,30]],"ltp":1.52,"tv":24905.7,"id":5300820},{"batb":[[0,2.84,5.22],[1,2.76,17.04],[2,2.72,54.56]],"batl":[[0,3.05,20.95],[1,3.15,3.7],[2,3.3,4.25]],"ltp":2.84,"tv":12831.28,"id":9629022}]}]}
{"op":"mcm","clk":"4215250134","pt":1631536603362,"mc":[{"id":"1.187557985","rc":[{"batb":[[1,1.47,50.67],[2,1.46,622.46]],"batl":[[2,1.59,5]],"ltp":1.52,"tv":24905.7,"id":5300820},{"batb":[[1,2.72,54.56],[2,2.7,3]],"batl":[[0,3.15,3.7],[1,3.3,4.25],[2,3.3,0]],"ltp":2.84,"tv":12831.28,"id":9629022}]}]}
{"op":"mcm","clk":"4215250235","pt":1631536605547,"mc":[{"id":"1.187557985","rc":[{"batb":[[0,1.46,622.46],[1,1.44,58.42],[2,1.2,2]],"ltp":1.52,"tv":24905.7,"id":5300820},{"batl":[[0,3.3,4.25],[1,3.3,0]],"ltp":2.84,"tv":12831.28,"id":9629022}]}]}
{"op":"mcm","clk":"4215250335","pt":1631536607470,"mc":[{"id":"1.187557985","rc":[{"batb":[[0,1.46,180.75]],"batl":[[0,1.54,40.75],[1,1.59,5],[2,1.6,6.51]],"ltp":1.52,"tv":24905.7,"id":5300820}]}]}
{"op":"mcm","clk":"4215250402","pt":1631536608461,"mc":[{"id":"1.187557985","rc":[{"trd":[[1.52,879.13]],"batb":[[0,1.49,264.85],[1,1.48,195.51],[2,1.47,7]],"batl":[[0,1.53,161.81],[1,1.54,205.83],[2,1.59,5]],"ltp":1.52,"tv":24946.65,"id":5300820},{"trd":[[2.92,46.77]],"batb":[[0,2.9,21.86],[1,2.84,5.22],[2,2.72,54.56]],"batl":[[0,3.15,2],[1,3.3,4.25]],"ltp":2.92,"tv":12852.59,"id":9629022}],"tv":37799.25}]}
{"op":"mcm","clk":"4215250463","pt":1631536609552,"mc":[{"id":"1.187557985","rc":[{"batb":[[2,1.47,61.67]],"batl":[[0,1.53,141.31]],"ltp":1.52,"tv":24946.65,"id":5300820},{"batb":[[0,2.84,5.22],[1,2.72,54.56],[2,2.7,3]],"batl":[[0,3.15,6.1],[1,3.2,3],[2,3.3,4.25]],"ltp":2.92,"tv":12852.59,"id":9629022}]}]}
{"op":"mcm","clk":"4215250671","pt":1631536613569,"mc":[{"id":"1.187557985","rc":[{"batb":[[0,1.47,7],[1,1.46,186.75],[2,1.45,5]],"batl":[[0,1.54,40.75],[1,1.59,5],[2,1.6,6.51]],"ltp":1.52,"tv":24946.65,"id":5300820},{"batl":[[0,3.15,2]],"ltp":2.92,"tv":12852.59,"id":9629022}]}]}
