{"op":"mcm","clk":"4225411523","pt":1631458340232,"mc":[{"id":"1.187557146","marketDefinition":{"bspMarket":false,"turnInPlayEnabled":true,"persistenceEnabled":true,"marketBaseRate":5.0,"eventId":"30895970","eventTypeId":"2","numberOfWinners":1,"bettingType":"ODDS","marketType":"MATCH_ODDS","marketTime":"2021-09-13T10:00:00.000Z","suspendTime":"2021-09-13T10:00:00.000Z","bspReconciled":false,"complete":true,"inPlay":false,"crossMatching":false,"runnersVoidable":false,"numberOfActiveRunners":2,"betDelay":0,"status":"OPEN","runners":[{"status":"ACTIVE","sortPriority":1,"id":8257797,"name":"Alessandro Bega"},{"status":"ACTIVE","sortPriority":2,"id":19931652,"name":"Titouan Droguet"}],"regulators":["MR_INT"],"countryCode":"FR","discountAllowed":false,"timezone":"UTC","openDate":"2021-09-13T10:00:00.000Z","version":4028719361,"name":"Match Odds","eventName":"Bega v Ti Droguet"}}]}
{"op":"mcm","clk":"4225411741","pt":1631458341351,"mc":[{"id":"1.187557146","marketDefinition":{"bspMarket":false,"turnInPlayEnabled":true,"persistenceEnabled":true,"marketBaseRate":5.0,"eventId":"30895970","eventTypeId":"2","numberOfWinners":1,"bettingType":"ODDS","marketType":"MATCH_ODDS","marketTime":"2021-09-13T10:00:00.000Z","suspendTime":"2021-09-13T10:00:00.000Z","bspReconciled":false,"complete":true,"inPlay":false,"crossMatching":false,"runnersVoidable":false,"numberOfActiveRunners":2,"betDelay":0,"status":"OPEN","runners":[{"status":"ACTIVE","sortPriority":1,"id":8257797,"name":"Alessandro Bega"},{"status":"ACTIVE","sortPriority":2,"id":19931652,"name":"Titouan Droguet"}],"regulators":["MR_INT"],"countryCode":"FR","discountAllowed":false,"timezone":"UTC","openDate":"2021-09-13T10:00:00.000Z","version":4028719361,"name":"Match Odds","eventName":"Bega v Ti Droguet"},"rc":[{"batb":[[0,1.01,25]],"ltp":0.0,"tv":0.0,"id":19931652},{"batb":[[0,1.01,25]],"ltp":0.0,"tv":0.0,"id":8257797}]}]}
{"op":"mcm","clk":"4225411960","pt":1631458342358,"mc":[{"id":"1.187557146","marketDefinition":{"bspMarket":false,"turnInPlayEnabled":true,"persistenceEnabled":true,"marketBaseRate":5.0,"eventId":"30895970","eventTypeId":"2","numberOfWinners":1,"bettingType":"ODDS","marketType":"MATCH_ODDS","marketTime":"2021-09-13T10:00:00.000Z","suspendTime":"2021-09-13T10:00:00.000Z","bspReconciled":false,"complete":true,"inPlay":false,"crossMatching":false,"runnersVoidable":false,"numberOfActiveRunners":2,"betDelay":0,"status":"OPEN","runners":[{"status":"ACTIVE","sortPriority":1,"id":8257797,"name":"Alessandro Bega"},{"status":"ACTIVE","sortPriority":2,"id":19931652,"name":"Titouan Droguet"}],"regulators":["MR_INT"],"countryCode":"FR","discountAllowed":true,"timezone":"UTC","openDate":"2021-09-13T10:00:00.000Z","version":4028719361,"name":"Match Odds","eventName":"Bega v Ti Droguet"}}]}
{"op":"mcm","clk":"4225492985","pt":1631458812286,"mc":[{"id":"1.187557146","rc":[{"batb":[[0,1.01,7]],"ltp":0.0,"tv":0.0,"id":19931652},{"batb":[[0,1.01,7]],"ltp":0.0,"tv":0.0,"id":8257797}]}]}
{"op":"mcm","clk":"4225634515","pt":1631459539342,"mc":[{"id":"1.187557146","rc":[{"batl":[[0,990,2.2]],"ltp":0.0,"tv":0.0,"id":19931652},{"batl":[[0,990,2.2]],"ltp":0.0,"tv":0.0,"id":8257797}]}]}
{"op":"mcm","clk":"4225679713","pt":1631459751701,"mc":[{"id":"1.187557146","rc":[{"batb":[[0,1.01,100.94]],"ltp":0.0,"tv":0.0,"id":19931652},{"batb":[[0,1.01,100.94]],"ltp":0.0,"tv":0.0,"id":8257797}]}]}
{"op":"mcm","clk":"4227510795","pt":1631471739029,"mc":[{"id":"1.187557146","rc":[{"batb":[[0,1.6,37.57],[1,1.01,100.94]],"ltp":0.0,"tv":0.0,"id":19931652},{"batb":[[0,2.14,19.77],[1,1.01,100.94]],"ltp":0.0,"tv":0.0,"id":8257797}]}]}
{"op":"mcm","clk":"4227512046","pt":1631471749920,"mc":[{"id":"1.187557146","marketDefinition":{"bspMarket":false,"turnInPlayEnabled":true,"persistenceEnabled":true,"marketBaseRate":5.0,"eventId":"30895970","eventTypeId":"2","numberOfWinners":1,"bettingType":"ODDS","marketType":"MATCH_ODDS","marketTime":"2021-09-13T10:00:00.000Z","suspendTime":"2021-09-13T10:00:00.000Z","bspReconciled":false,"complete":true,"inPlay":false,"crossMatching":true,"runnersVoidable":false,"numberOfActiveRunners":2,"betDelay":0,"status":"OPEN","runners":[{"status":"ACTIVE","sortPriority":1,"id":8257797,"name":"Alessandro Bega"},{"status":"ACTIVE","sortPriority":2,"id":19931652,"name":"Titouan Droguet"}],"regulators":["MR_INT"],"countryCode":"FR","discountAllowed":true,"timezone":"UTC","openDate":"2021-09-13T10:00:00.000Z","version":4028719361,"name":"Match Odds","eventName":"Bega v Ti Droguet"}}]}
{"op":"mcm","clk":"4227591953","pt":1631472414158,"mc":[{"id":"1.187557146","rc":[{"batl":[[0,11,3.42],[1,990,2.2]],"ltp":0.0,"tv":0.0,"id":19931652},{"batl":[[0,14,3.42],[1,990,2.2]],"ltp":0.0,"tv":0.0,"id":8257797}]}]}
{"op":"mcm","clk":"4227651087","pt":1631472841012,"mc":[{"id":"1.187557146","rc":[{"batb":[[1,1.01,573.8]],"ltp":0.0,"tv":0.0,"id":19931652},{"batb":[[1,1.01,573.8]],"ltp":0.0,"tv":0.0,"id":8257797}]}]}
{"op":"mcm","clk":"4227801090","pt":1631474302020,"mc":[{"id":"1.187557146","rc":[{"batb":[[1,1.18,20.09],[2,1.01,573.8]],"ltp":0.0,"tv":0.0,"id":19931652},{"batb":[[1,1.34,10.64],[2,1.01,573.8]],"ltp":0.0,"tv":0.0,"id":8257797}]}]}
{"op":"mcm","clk":"4227803925","pt":1631474332693,"mc":[{"id":"1.187557146","rc":[{"batl":[[0,2.68,3.45],[1,14,3.42],[2,990,2.2]],"ltp":0.0,"tv":0.0,"id":8257797}]}]}
{"op":"mcm","clk":"4227806324","pt":1631474358827,"mc":[{"id":"1.187557146","rc":[{"batl":[[1,990,2.2],[2,990,0]],"ltp":0.0,"tv":0.0,"id":8257797}]}]}
{"op":"mcm","clk":"4227845566","pt":1631474785615,"mc":[{"id":"1.187557146","rc":[{"batb":[[0,2.26,3.45],[1,2.14,19.77],[2,1.34,10.64]],"ltp":0.0,"tv":0.0,"id":8257797}]}]}
{"op":"mcm","clk":"4227847976","pt":1631474810742,"mc":[{"id":"1.187557146","rc":[{"batb":[[0,1.62,3.45],[1,1.6,37.57],[2,1.18,20.09]],"ltp":0.0,"tv":0.0,"id":19931652}]}]}
{"op":"mcm","clk":"4227848586","pt":1631474817153,"mc":[{"id":"1.187557146","rc":[{"batb":[[0,2.14,19.77],[1,1.34,10.64],[2,1.01,573.8]],"ltp":0.0,"tv":0.0,"id":8257797}]}]}
{"op":"mcm","clk":"4227848673","pt":1631474818264,"mc":[{"id":"1.187557146","rc":[{"batl":[[0,990,2.2],[1,990,0]],"ltp":0.0,"tv":0.0,"id":8257797}]}]}
{"op":"mcm","clk":"4227853170","pt":1631474868837,"mc":[{"id":"1.187557146","rc":[{"batl":[[0,14,3.42],[1,990,2.2]],"ltp":0.0,"tv":0.0,"id":8257797}]}]}
{"op":"mcm","clk":"4228043302","pt":1631477169870,"mc":[{"id":"1.187557146","rc":[{"batb":[[0,1.62,3.44]],"batl":[[0,11,3.42]],"ltp":0.0,"tv":0.0,"id":19931652},{"batb":[[2,1.01,578.76]],"batl":[[0,14,3.42]],"ltp":0.0,"tv":0.0,"id":8257797}]}]}
{"op":"mcm","clk":"4228383477","pt":1631482625685,"mc":[{"id":"1.187557146","rc":[{"batb":[[0,1.66,1.38],[1,1.62,3.44],[2,1.6,37.57]],"ltp":0.0,"tv":0.0,"id":19931652}]}]}
{"op":"mcm","clk":"4228506316","pt":1631484954146,"mc":[{"id":"1.187557146","rc":[{"batb":[[2,1.6,43.82]],"ltp":0.0,"tv":0.0,"id":19931652},{"batb":[[1,1.34,10.63],[2,1.01,578.68]],"ltp":0.0,"tv":0.0,"id":8257797}]}]}
{"op":"mcm","clk":"4228535805","pt":1631485443313,"mc":[{"id":"1.187557146","rc":[{"batb":[[1,1.34,31.89]],"ltp":0.0,"tv":0.0,"id":8257797}]}]}
{"op":"mcm","clk":"4228549757","pt":1631485672983,"mc":[{"id":"1.187557146","rc":[{"batb":[[1,1.4,768.51],[2,1.34,31.89]],"ltp":0.0,"tv":0.0,"id":8257797}]}]}
{"op":"mcm","clk":"4228550047","pt":1631485678467,"mc":[{"id":"1.187557146","rc":[{"batb":[[1,1.41,23.91],[2,1.4,768.51]],"ltp":0.0,"tv":0.0,"id":8257797}]}]}
{"op":"mcm","clk":"4228599989","pt":1631487273955,"mc":[{"id":"1.187557146","rc":[{"batl":[[0,1.9,25],[1,11,3.42],[2,990,2.2]],"ltp":0.0,"tv":0.0,"id":19931652},{"batl":[[0,2.5,25],[1,14,3.42],[2,990,2.2]],"ltp":0.0,"tv":0.0,"id":8257797}]}]}
{"op":"mcm","clk":"4228600136","pt":1631487280474,"mc":[{"id":"1.187557146","rc":[{"batb":[[2,1.6,37.57]],"ltp":0.0,"tv":0.0,"id":19931652}]}]}
{"op":"mcm","clk":"4228600193","pt":1631487282881,"mc":[{"id":"1.187557146","rc":[{"batl":[[1,990,2.2],[2,990,0]],"ltp":0.0,"tv":0.0,"id":19931652},{"batl":[[1,990,2.2],[2,990,0]],"ltp":0.0,"tv":0.0,"id":8257797}]}]}
{"op":"mcm","clk":"4228600296","pt":1631487287081,"mc":[{"id":"1.187557146","rc":[{"batb":[[0,1.66,7.4]],"ltp":0.0,"tv":0.0,"id":19931652}]}]}
{"op":"mcm","clk":"4228652248","pt":1631488665714,"mc":[{"id":"1.187557146","rc":[{"batb":[[1,1.41,23.91],[2,1.4,768.38]],"ltp":0.0,"tv":0.0,"id":8257797}]}]}
{"op":"mcm","clk":"4228992578","pt":1631498410030,"mc":[{"id":"1.187557146","rc":[{"batb":[[0,1.67,33.65],[1,1.66,7.4],[2,1.62,3.44]],"ltp":0.0,"tv":0.0,"id":19931652},{"batb":[[0,2.1,20.49],[1,1.41,23.89],[2,1.4,767.98]],"ltp":0.0,"tv":0.0,"id":8257797}]}]}
{"op":"mcm","clk":"4228992896","pt":1631498420881,"mc":[{"id":"1.187557146","rc":[{"batb":[[1,1.66,1.38]],"ltp":0.0,"tv":0.0,"id":19931652}]}]}
{"op":"mcm","clk":"4228993132","pt":1631498428402,"mc":[{"id":"1.187557146","rc":[{"batb":[[0,1.67,39.65]],"ltp":0.0,"tv":0.0,"id":19931652}]}]}
{"op":"mcm","clk":"4229197667","pt":1631504865722,"mc":[{"id":"1.187557146","rc":[{"batb":[[2,1.62,3.44]],"ltp":0.0,"tv":0.0,"id":19931652},{"batb":[[1,1.41,23.89],[2,1.4,767.79]],"ltp":0.0,"tv":0.0,"id":8257797}]}]}
{"op":"mcm","clk":"4229215298","pt":1631505604701,"mc":[{"id":"1.187557146","rc":[{"batb":[[0,1.67,56.47]],"ltp":0.0,"tv":0.0,"id":19931652},{"batb":[[0,2.1,30.74]],"ltp":0.0,"tv":0.0,"id":8257797}]}]}
{"op":"mcm","clk":"4229256006","pt":1631507096176,"mc":[{"id":"1.187557146","rc":[{"batb":[[1,1.44,40.23],[2,1.41,23.89]],"ltp":0.0,"tv":0.0,"id":8257797}]}]}
{"op":"mcm","clk":"4229300048","pt":1631510265761,"mc":[{"id":"1.187557146","rc":[{"batb":[[1,1.66,1.38]],"ltp":0.0,"tv":0.0,"id":19931652},{"batb":[[1,1.44,40.26],[2,1.41,23.89]],"ltp":0.0,"tv":0.0,"id":8257797}]}]}
{"op":"mcm","clk":"4229319752","pt":1631511830716,"mc":[{"id":"1.187557146","rc":[{"batl":[[1,46,29.03],[2,990,2.2]],"ltp":0.0,"tv":0.0,"id":19931652},{"batl":[[1,46,29.03],[2,990,2.2]],"ltp":0.0,"tv":0.0,"id":8257797}]}]}
{"op":"mcm","clk":"4229325283","pt":1631512251623,"mc":[{"id":"1.187557146","rc":[{"batl":[[1,2.34,2.66],[2,46,29.03]],"ltp":0.0,"tv":0.0,"id":19931652}]}]}
{"op":"mcm","clk":"4229370261","pt":1631514636811,"mc":[{"id":"1.187557146","rc":[{"batl":[[2,2.8,43.99]],"ltp":0.0,"tv":0.0,"id":19931652}]}]}
{"op":"mcm","clk":"4229370709","pt":1631514657627,"mc":[{"id":"1.187557146","rc":[{"trd":[[2.1,8.8]],"batb":[[0,2.1,26.34]],"ltp":2.1,"tv":8.79,"id":8257797}],"tv":8.79}]}
{"op":"mcm","clk":"4229370804","pt":1631514662833,"mc":[{"id":"1.187557146","rc":[{"batb":[[0,2.1,30.74]],"ltp":2.1,"tv":8.79,"id":8257797}]}]}
{"op":"mcm","clk":"4229539456","pt":1631519787781,"mc":[{"id":"1.187557146","rc":[{"batb":[[1,1.66,1.38]],"batl":[[1,2.34,2.66],[2,2.8,44.04]],"ltp":0.0,"tv":0.0,"id":19931652},{"trd":[[2.1,8.8]],"batb":[[1,1.55,35.48],[2,1.44,40.32]],"batl":[[1,46,29.07]],"ltp":2.1,"tv":8.8,"id":8257797}],"tv":8.8}]}
{"op":"mcm","clk":"4229550473","pt":1631520002724,"mc":[{"id":"1.187557146","rc":[{"batb":[[0,1.67,73.3]],"ltp":0.0,"tv":0.0,"id":19931652},{"batb":[[0,2.1,40.99]],"ltp":2.1,"tv":8.8,"id":8257797}]}]}
{"op":"mcm","clk":"4229572479","pt":1631520388015,"mc":[{"id":"1.187557146","rc":[{"batb":[[0,1.67,68.33]],"ltp":0.0,"tv":0.0,"id":19931652},{"batb":[[0,2.1,37.97]],"ltp":2.1,"tv":8.8,"id":8257797}]}]}
{"op":"mcm","clk":"4229643459","pt":1631521640704,"mc":[{"id":"1.187557146","rc":[{"batb":[[0,1.67,6],[2,1.62,70.8]],"ltp":0.0,"tv":0.0,"id":19931652},{"batb":[[0,2.2,34.8]],"ltp":2.1,"tv":8.8,"id":8257797}]}]}
{"op":"mcm","clk":"4229643590","pt":1631521643231,"mc":[{"id":"1.187557146","rc":[{"batb":[[0,1.66,1.38],[1,1.62,70.8],[2,1.33,59.13]],"ltp":0.0,"tv":0.0,"id":19931652}]}]}
{"op":"mcm","clk":"4229643957","pt":1631521650141,"mc":[{"id":"1.187557146","rc":[{"batb":[[0,1.66,7.4]],"ltp":0.0,"tv":0.0,"id":19931652}]}]}
{"op":"mcm","clk":"4229699718","pt":1631522886885,"mc":[{"id":"1.187557146","rc":[{"batb":[[2,1.34,123.32]],"ltp":0.0,"tv":0.0,"id":19931652}]}]}
{"op":"mcm","clk":"4229703881","pt":1631522966305,"mc":[{"id":"1.187557146","rc":[{"trd":[[1.66,1.68]],"batb":[[0,1.66,6.56]],"ltp":1.66,"tv":1.67,"id":19931652}],"tv":10.47}]}
{"op":"mcm","clk":"4229728290","pt":1631523467509,"mc":[{"id":"1.187557146","rc":[{"batb":[[0,1.68,3.44],[1,1.66,6.56],[2,1.62,70.8]],"ltp":1.66,"tv":1.67,"id":19931652}]}]}
{"op":"mcm","clk":"4229728542","pt":1631523473018,"mc":[{"id":"1.187557146","rc":[{"batb":[[0,1.66,6.56],[1,1.62,70.8],[2,1.34,123.32]],"ltp":1.66,"tv":1.67,"id":19931652}]}]}
{"op":"mcm","clk":"4229733706","pt":1631523601250,"mc":[{"id":"1.187557146","rc":[{"batb":[[0,1.67,19.11],[1,1.66,6.56],[2,1.62,70.8]],"ltp":1.66,"tv":1.67,"id":19931652},{"batb":[[0,2.22,10.5],[1,2.2,34.8],[2,1.55,35.48]],"ltp":2.1,"tv":8.8,"id":8257797}]}]}
{"op":"mcm","clk":"4229739521","pt":1631523718165,"mc":[{"id":"1.187557146","rc":[{"batb":[[0,1.67,19.11]],"batl":[[0,1.8,1.28],[1,1.9,25],[2,2.34,2.66]],"ltp":1.66,"tv":1.67,"id":19931652},{"trd":[[2.1,8.8]],"batb":[[0,2.22,10.5],[2,1.55,35.45]],"batl":[[1,46,29.05]],"ltp":2.1,"tv":8.8,"id":8257797}],"tv":10.47}]}
{"op":"mcm","clk":"4229779417","pt":1631524389067,"mc":[{"id":"1.187557146","rc":[{"batb":[[2,1.41,23.9]],"ltp":2.1,"tv":8.8,"id":8257797}]}]}
{"op":"mcm","clk":"4229806556","pt":1631524861556,"mc":[{"id":"1.187557146","rc":[{"batb":[[2,1.63,2.66]],"ltp":1.66,"tv":1.67,"id":19931652},{"batb":[[2,2.14,2.66]],"ltp":2.1,"tv":8.8,"id":8257797}]}]}
{"op":"mcm","clk":"4229932446","pt":1631526694442,"mc":[{"id":"1.187557146","rc":[{"batl":[[0,1.8,3.28]],"ltp":1.66,"tv":1.67,"id":19931652}]}]}
{"op":"mcm","clk":"4229949082","pt":1631526965564,"mc":[{"id":"1.187557146","rc":[{"batb":[[0,1.72,10.86],[1,1.67,19.11],[2,1.66,6.56]],"ltp":1.66,"tv":1.67,"id":19931652}]}]}
{"op":"mcm","clk":"4229951101","pt":1631527001231,"mc":[{"id":"1.187557146","rc":[{"batl":[[0,1.8,28.28]],"ltp":1.66,"tv":1.67,"id":19931652},{"batb":[[0,2.26,10.16],[1,2.22,10.5],[2,2.2,34.8]],"ltp":2.1,"tv":8.8,"id":8257797}]}]}
{"op":"mcm","clk":"4229951799","pt":1631527014475,"mc":[{"id":"1.187557146","rc":[{"trd":[[1.72,20]],"batb":[[0,1.67,19.96],[1,1.66,6.56],[2,1.63,2.66]],"ltp":1.72,"tv":21.67,"id":19931652}],"tv":30.47}]}
{"op":"mcm","clk":"4229962127","pt":1631527167064,"mc":[{"id":"1.187557146","rc":[{"batb":[[2,1.65,41.96]],"ltp":1.72,"tv":21.67,"id":19931652},{"batb":[[1,2.22,43.16]],"ltp":2.1,"tv":8.8,"id":8257797}]}]}
{"op":"mcm","clk":"4229973016","pt":1631527316226,"mc":[{"id":"1.187557146","marketDefinition":{"bspMarket":false,"turnInPlayEnabled":true,"persistenceEnabled":true,"marketBaseRate":5.0,"eventId":"30895970","eventTypeId":"2","numberOfWinners":1,"bettingType":"ODDS","marketType":"MATCH_ODDS","marketTime":"2021-09-13T09:57:00.000Z","suspendTime":"2021-09-13T09:57:00.000Z","bspReconciled":false,"complete":true,"inPlay":false,"crossMatching":true,"runnersVoidable":false,"numberOfActiveRunners":2,"betDelay":0,"status":"OPEN","runners":[{"status":"ACTIVE","sortPriority":1,"id":8257797,"name":"Alessandro Bega"},{"status":"ACTIVE","sortPriority":2,"id":19931652,"name":"Titouan Droguet"}],"regulators":["MR_INT"],"countryCode":"FR","discountAllowed":true,"timezone":"UTC","openDate":"2021-09-13T10:00:00.000Z","version":4030522366,"name":"Match Odds","eventName":"Bega v Ti Droguet"}}]}
{"op":"mcm","clk":"4229973259","pt":1631527319243,"mc":[{"id":"1.187557146","marketDefinition":{"bspMarket":false,"turnInPlayEnabled":true,"persistenceEnabled":true,"marketBaseRate":5.0,"eventId":"30895970","eventTypeId":"2","numberOfWinners":1,"bettingType":"ODDS","marketType":"MATCH_ODDS","marketTime":"2021-09-13T09:57:00.000Z","suspendTime":"2021-09-13T09:57:00.000Z","bspReconciled":false,"complete":true,"inPlay":false,"crossMatching":true,"runnersVoidable":false,"numberOfActiveRunners":2,"betDelay":0,"status":"OPEN","runners":[{"status":"ACTIVE","sortPriority":1,"id":8257797,"name":"Alessandro Bega"},{"status":"ACTIVE","sortPriority":2,"id":19931652,"name":"Titouan Droguet"}],"regulators":["MR_INT"],"countryCode":"FR","discountAllowed":true,"timezone":"UTC","openDate":"2021-09-13T09:57:00.000Z","version":4030522366,"name":"Match Odds","eventName":"Bega v Ti Droguet"}}]}
{"op":"mcm","clk":"4229987802","pt":1631527536437,"mc":[{"id":"1.187557146","rc":[{"batb":[[2,1.63,2.66]],"ltp":1.72,"tv":21.67,"id":19931652},{"batb":[[1,2.22,10.5]],"ltp":2.1,"tv":8.8,"id":8257797}]}]}
{"op":"mcm","clk":"4229987861","pt":1631527537376,"mc":[{"id":"1.187557146","marketDefinition":{"bspMarket":false,"turnInPlayEnabled":true,"persistenceEnabled":true,"marketBaseRate":5.0,"eventId":"30895970","eventTypeId":"2","numberOfWinners":1,"bettingType":"ODDS","marketType":"MATCH_ODDS","marketTime":"2021-09-13T09:57:00.000Z","suspendTime":"2021-09-13T09:57:00.000Z","bspReconciled":false,"complete":true,"inPlay":true,"crossMatching":true,"runnersVoidable":false,"numberOfActiveRunners":2,"betDelay":3,"status":"OPEN","runners":[{"status":"ACTIVE","sortPriority":1,"id":8257797,"name":"Alessandro Bega"},{"status":"ACTIVE","sortPriority":2,"id":19931652,"name":"Titouan Droguet"}],"regulators":["MR_INT"],"countryCode":"FR","discountAllowed":true,"timezone":"UTC","openDate":"2021-09-13T09:57:00.000Z","version":4030524482,"name":"Match Odds","eventName":"Bega v Ti Droguet"},"rc":[{"batb":[[0,1.66,1.4],[1,1.47,1],[2,1.01,105.88]],"batl":[[0,1.8,27],[1,1.9,0],[2,2.34,0]],"ltp":1.72,"tv":21.67,"id":19931652},{"batb":[[0,1.01,105.88],[1,2.22,0],[2,2.2,0]],"ltp":2.1,"tv":8.8,"id":8257797}]}]}
{"op":"mcm","clk":"4229988205","pt":1631527542774,"mc":[{"id":"1.187557146","rc":[{"trd":[[1.72,20.86]],"batb":[[0,1.68,8.64],[1,1.66,94.06],[2,1.47,1]],"ltp":1.72,"tv":22.53,"id":19931652},{"trd":[[2.4,0.61]],"batb":[[0,2.42,5.46],[1,2.36,94.03],[2,1.01,105.88]],"ltp":2.4,"tv":9.41,"id":8257797}],"tv":31.94}]}
{"op":"mcm","clk":"4229988268","pt":1631527543856,"mc":[{"id":"1.187557146","rc":[{"batb":[[2,1.59,47.48]],"ltp":1.72,"tv":22.53,"id":19931652},{"batb":[[2,2.32,28.47]],"ltp":2.4,"tv":9.41,"id":8257797}]}]}
{"op":"mcm","clk":"4229988790","pt":1631527552269,"mc":[{"id":"1.187557146","rc":[{"batb":[[0,1.59,48.03],[1,1.55,52.59],[2,1.47,1]],"ltp":1.72,"tv":22.53,"id":19931652},{"batb":[[0,2.32,28.47],[1,2.18,34.42],[2,1.03,494.14]],"ltp":2.4,"tv":9.41,"id":8257797}]}]}
{"op":"mcm","clk":"4229988832","pt":1631527552787,"mc":[{"id":"1.187557146","rc":[{"batb":[[0,1.55,53.13],[1,1.47,1],[2,1.03,494.14]],"ltp":1.72,"tv":22.53,"id":19931652},{"batb":[[0,2.18,34.42],[1,1.03,494.14],[2,1.01,579.24]],"ltp":2.4,"tv":9.41,"id":8257797}]}]}
{"op":"mcm","clk":"4229989075","pt":1631527556264,"mc":[{"id":"1.187557146","rc":[{"batb":[[2,1.05,474.38]],"ltp":1.72,"tv":22.53,"id":19931652},{"batb":[[1,1.05,474.38],[2,1.03,494.14]],"ltp":2.4,"tv":9.41,"id":8257797}]}]}
{"op":"mcm","clk":"4229989256","pt":1631527559078,"mc":[{"id":"1.187557146","rc":[{"batb":[[2,1.11,269.53]],"ltp":1.72,"tv":22.53,"id":19931652},{"batb":[[1,1.11,269.53],[2,1.1,296.48]],"ltp":2.4,"tv":9.41,"id":8257797}]}]}
{"op":"mcm","clk":"4229989474","pt":1631527562302,"mc":[{"id":"1.187557146","rc":[{"batb":[[1,1.2,385.43],[2,1.11,269.53]],"ltp":2.4,"tv":9.41,"id":8257797}]}]}
{"op":"mcm","clk":"4229989727","pt":1631527565970,"mc":[{"id":"1.187557146","rc":[{"batb":[[2,1.2,444.72]],"ltp":1.72,"tv":22.53,"id":19931652},{"batb":[[1,1.4,148.24],[2,1.3,197.65]],"ltp":2.4,"tv":9.41,"id":8257797}]}]}
{"op":"mcm","clk":"4229989942","pt":1631527569282,"mc":[{"id":"1.187557146","rc":[{"batb":[[2,1.25,166.03]],"ltp":1.72,"tv":22.53,"id":19931652},{"batb":[[1,1.6,98.83],[2,1.5,106.73]],"ltp":2.4,"tv":9.41,"id":8257797}]}]}
{"op":"mcm","clk":"4229990487","pt":1631527577340,"mc":[{"id":"1.187557146","rc":[{"batb":[[0,1.76,16.56],[1,1.55,53.13],[2,1.47,1]],"batl":[[0,1.8,34.58],[1,1.86,172.26]],"ltp":1.72,"tv":22.53,"id":19931652},{"batl":[[0,2.5,279.27]],"ltp":2.4,"tv":9.41,"id":8257797}]}]}
{"op":"mcm","clk":"4229990570","pt":1631527578634,"mc":[{"id":"1.187557146","rc":[{"batb":[[1,1.67,40.11],[2,1.61,46.69]],"ltp":1.72,"tv":22.53,"id":19931652},{"batb":[[1,2,43.63],[2,1.6,98.83]],"ltp":2.4,"tv":9.41,"id":8257797}]}]}
{"op":"mcm","clk":"4229990695","pt":1631527580505,"mc":[{"id":"1.187557146","rc":[{"trd":[[1.76,20.55]],"batb":[[0,1.76,6.29]],"ltp":1.76,"tv":43.08,"id":19931652}],"tv":52.49}]}
{"op":"mcm","clk":"4229990826","pt":1631527582321,"mc":[{"id":"1.187557146","rc":[{"batl":[[1,1.82,55.96],[2,1.86,172.26]],"ltp":1.76,"tv":43.08,"id":19931652},{"batl":[[0,2.32,41.43],[1,2.5,279.27]],"ltp":2.4,"tv":9.41,"id":8257797}]}]}
{"op":"mcm","clk":"4229990834","pt":1631527582424,"mc":[{"id":"1.187557146","rc":[{"batl":[[1,1.86,172.26],[2,1.86,0]],"ltp":1.76,"tv":43.08,"id":19931652},{"batl":[[0,2.5,279.27],[1,2.5,0]],"ltp":2.4,"tv":9.41,"id":8257797}]}]}
{"op":"mcm","clk":"4229991360","pt":1631527590646,"mc":[{"id":"1.187557146","rc":[{"batb":[[0,1.67,40.11],[1,1.61,46.69],[2,1.47,1]],"batl":[[0,1.8,27]],"ltp":1.76,"tv":43.08,"id":19931652}]}]}
{"op":"mcm","clk":"4229991557","pt":1631527593643,"mc":[{"id":"1.187557146","rc":[{"batl":[[0,1.8,44.62]],"ltp":1.76,"tv":43.08,"id":19931652},{"batl":[[0,2.32,5.93],[1,2.5,279.27]],"ltp":2.4,"tv":9.41,"id":8257797}]}]}
{"op":"mcm","clk":"4229991661","pt":1631527595350,"mc":[{"id":"1.187557146","rc":[{"batb":[[0,1.61,46.69],[1,1.47,1],[2,1.3,197.65]],"batl":[[0,1.8,27],[1,1.86,0]],"ltp":1.76,"tv":43.08,"id":19931652},{"batb":[[0,2,43.63],[1,1.6,98.83],[2,1.5,106.73]],"ltp":2.4,"tv":9.41,"id":8257797}]}]}
{"op":"mcm","clk":"4229993366","pt":1631527621959,"mc":[{"id":"1.187557146","rc":[{"trd":[[1.8,8.23]],"batb":[[0,1.74,567.72],[1,1.61,46.69],[2,1.47,1]],"batl":[[0,1.8,18.77],[1,2,59.37]],"ltp":1.8,"tv":51.31,"id":19931652},{"trd":[[2.24,6.61]],"batb":[[0,2.08,7.86],[1,2,103],[2,1.6,98.83]],"ltp":2.24,"tv":16.02,"id":8257797}],"tv":67.33}]}
{"op":"mcm","clk":"4229993444","pt":1631527623145,"mc":[{"id":"1.187557146","rc":[{"batb":[[0,1.78,32.07],[1,1.74,567.72],[2,1.69,38.44]],"ltp":1.8,"tv":51.31,"id":19931652},{"batb":[[2,1.85,28.64]],"ltp":2.24,"tv":16.02,"id":8257797}]}]}
{"op":"mcm","clk":"4229993694","pt":1631527627078,"mc":[{"id":"1.187557146","rc":[{"trd":[[1.8,27]],"batl":[[0,2,59.37],[1,2,0]],"ltp":1.8,"tv":70.08,"id":19931652},{"trd":[[2.24,21.69]],"ltp":2.24,"tv":31.1,"id":8257797}],"tv":101.18}]}
{"op":"mcm","clk":"4229993892","pt":1631527630183,"mc":[{"id":"1.187557146","rc":[{"batb":[[0,2.1,38.37],[1,2.08,7.86],[2,2,103]],"ltp":2.24,"tv":31.1,"id":8257797}]}]}
{"op":"mcm","clk":"4229993915","pt":1631527630496,"mc":[{"id":"1.187557146","rc":[{"batb":[[0,2.08,7.86],[1,2,103],[2,1.85,28.64]],"ltp":2.24,"tv":31.1,"id":8257797}]}]}
{"op":"mcm","clk":"4229994054","pt":1631527632099,"mc":[{"id":"1.187557146","rc":[{"batb":[[0,2,103],[1,1.85,28.64],[2,1.5,106.73]],"ltp":2.24,"tv":31.1,"id":8257797}]}]}
{"op":"mcm","clk":"4229994183","pt":1631527634063,"mc":[{"id":"1.187557146","rc":[{"batb":[[1,1.69,38.44],[2,1.61,46.69]],"ltp":1.8,"tv":70.08,"id":19931652},{"batb":[[0,2,43.63]],"ltp":2.24,"tv":31.1,"id":8257797}]}]}
{"op":"mcm","clk":"4229994269","pt":1631527635303,"mc":[{"id":"1.187557146","rc":[{"batb":[[0,1.69,38.44],[1,1.47,1.54],[2,1.3,197.65]],"ltp":1.8,"tv":70.08,"id":19931652},{"batb":[[0,1.85,28.64],[1,1.5,106.73],[2,1.4,148.24]],"ltp":2.24,"tv":31.1,"id":8257797}]}]}
{"op":"mcm","clk":"4229994666","pt":1631527641298,"mc":[{"id":"1.187557146","rc":[{"batl":[[0,2.24,4],[1,2.26,223.51]],"ltp":2.24,"tv":31.1,"id":8257797}]}]}
{"op":"mcm","clk":"4229995459","pt":1631527652014,"mc":[{"id":"1.187557146","rc":[{"batl":[[0,2.12,8.81],[1,2.24,120.98]],"ltp":1.8,"tv":70.08,"id":19931652},{"batb":[[1,1.4,148.24],[2,1.3,197.65]],"batl":[[0,1.94,12.5],[1,2.16,568.37]],"ltp":2.24,"tv":31.1,"id":8257797}]}]}
{"op":"mcm","clk":"4229995536","pt":1631527652991,"mc":[{"id":"1.187557146","rc":[{"batb":[[0,1.94,49.07],[1,1.83,29.23],[2,1.69,38.44]],"ltp":1.8,"tv":70.08,"id":19931652},{"batb":[[1,1.7,37.52],[2,1.4,148.24]],"ltp":2.24,"tv":31.1,"id":8257797}]}]}
{"op":"mcm","clk":"4229996731","pt":1631527670108,"mc":[{"id":"1.187557146","rc":[{"batb":[[0,1.83,29.23],[1,1.47,1.54],[2,1.3,197.65]],"ltp":1.8,"tv":70.08,"id":19931652},{"batb":[[0,1.7,37.52],[1,1.4,148.24],[2,1.3,197.65]],"ltp":2.24,"tv":31.1,"id":8257797}]}]}
{"op":"mcm","clk":"4229997265","pt":1631527677228,"mc":[{"id":"1.187557146","rc":[{"batl":[[0,1.99,256.44]],"ltp":2.24,"tv":31.1,"id":8257797}]}]}
{"op":"mcm","clk":"4229998271","pt":1631527691157,"mc":[{"id":"1.187557146","rc":[{"batl":[[0,2,7.26],[1,2.08,115.65]],"ltp":1.8,"tv":70.08,"id":19931652},{"batb":[[0,2,7.26],[1,1.7,37.52],[2,1.4,148.24]],"batl":[[0,2.06,94.66]],"ltp":2.24,"tv":31.1,"id":8257797}]}]}
{"op":"mcm","clk":"4229998350","pt":1631527692142,"mc":[{"id":"1.187557146","rc":[{"batb":[[1,1.7,37.52],[2,1.47,1.54]],"ltp":1.8,"tv":70.08,"id":19931652},{"batb":[[1,1.95,48.07],[2,1.73,35.42]],"ltp":2.24,"tv":31.1,"id":8257797}]}]}
{"op":"mcm","clk":"4229998508","pt":1631527694271,"mc":[{"id":"1.187557146","rc":[{"trd":[[2.06,189.16]],"batl":[[0,2.06,0.08]],"ltp":2.06,"tv":220.26,"id":8257797}],"tv":290.34}]}
{"op":"mcm","clk":"4229998932","pt":1631527700262,"mc":[{"id":"1.187557146","rc":[{"trd":[[1.94,0.08]],"ltp":1.94,"tv":70.16,"id":19931652},{"trd":[[2.06,189.24]],"ltp":2.06,"tv":220.34,"id":8257797}],"tv":290.5}]}
{"op":"mcm","clk":"4229999193","pt":1631527703472,"mc":[{"id":"1.187557146","rc":[{"batl":[[0,2.86,5.31]],"ltp":2.06,"tv":220.34,"id":8257797}]}]}
{"op":"mcm","clk":"4229999262","pt":1631527704361,"mc":[{"id":"1.187557146","rc":[{"batl":[[0,2.08,115.65],[1,2.08,0]],"ltp":1.94,"tv":70.16,"id":19931652},{"batb":[[0,1.95,48.07],[1,1.73,35.42],[2,1.5,106.73]],"ltp":2.06,"tv":220.34,"id":8257797}]}]}
{"op":"mcm","clk":"4229999413","pt":1631527706176,"mc":[{"id":"1.187557146","rc":[{"batb":[[0,1.7,37.52],[1,1.47,1.54],[2,1.4,148.24]],"ltp":1.94,"tv":70.16,"id":19931652},{"batb":[[0,1.73,35.42],[1,1.5,106.73],[2,1.4,148.24]],"ltp":2.06,"tv":220.34,"id":8257797}]}]}
{"op":"mcm","clk":"4229999500","pt":1631527707267,"mc":[{"id":"1.187557146","rc":[{"batl":[[0,1.96,7.44]],"ltp":1.94,"tv":70.16,"id":19931652},{"batl":[[0,2.08,7.51]],"ltp":2.06,"tv":220.34,"id":8257797}]}]}
{"op":"mcm","clk":"4230002241","pt":1631527741131,"mc":[{"id":"1.187557146","rc":[{"batb":[[0,2.24,7.56],[1,2.08,19.24],[2,1.7,37.52]],"batl":[[0,2.42,101.85]],"ltp":1.94,"tv":70.16,"id":19931652},{"batb":[[0,1.76,18.46],[1,1.73,35.42],[2,1.5,106.73]],"batl":[[0,1.86,189.75]],"ltp":2.06,"tv":220.34,"id":8257797}]}]}
{"op":"mcm","clk":"4230002347","pt":1631527742121,"mc":[{"id":"1.187557146","rc":[{"batb":[[1,2.08,58.52],[2,1.95,48.24]],"ltp":1.94,"tv":70.16,"id":19931652},{"batb":[[2,1.66,40.62]],"ltp":2.06,"tv":220.34,"id":8257797}]}]}
{"op":"mcm","clk":"4230002682","pt":1631527746012,"mc":[{"id":"1.187557146","rc":[{"trd":[[1.76,36.92]],"batb":[[0,1.73,35.42],[1,1.66,40.62],[2,1.3,197.65]],"ltp":1.76,"tv":257.26,"id":8257797}],"tv":327.42}]}
{"op":"mcm","clk":"4230003523","pt":1631527755912,"mc":[{"id":"1.187557146","rc":[{"batb":[[0,2.08,58.52],[1,1.95,48.24],[2,1.7,37.52]],"ltp":1.94,"tv":70.16,"id":19931652}]}]}
{"op":"mcm","clk":"4230003823","pt":1631527759224,"mc":[{"id":"1.187557146","rc":[{"batb":[[0,1.74,12.84],[1,1.73,35.42],[2,1.66,40.62]],"batl":[[0,1.78,12.19],[1,1.86,189.75]],"ltp":1.76,"tv":257.26,"id":8257797}]}]}
{"op":"mcm","clk":"4230004636","pt":1631527768462,"mc":[{"id":"1.187557146","rc":[{"trd":[[1.78,20]],"batl":[[0,1.78,2.19]],"ltp":1.78,"tv":277.26,"id":8257797}],"tv":347.42}]}
{"op":"mcm","clk":"4230004831","pt":1631527771154,"mc":[{"id":"1.187557146","rc":[{"trd":[[1.78,24]],"batl":[[0,1.86,189.94],[1,1.86,0]],"ltp":1.78,"tv":281.26,"id":8257797}],"tv":351.42}]}
{"op":"mcm","clk":"4230005432","pt":1631527778675,"mc":[{"id":"1.187557146","rc":[{"batb":[[0,1.73,35.42],[1,1.66,40.62],[2,1.3,197.65]],"batl":[[0,1.86,189.75]],"ltp":1.78,"tv":281.26,"id":8257797}]}]}
{"op":"mcm","clk":"4230005865","pt":1631527784843,"mc":[{"id":"1.187557146","rc":[{"batb":[[0,1.76,12.13],[1,1.73,35.42],[2,1.66,40.62]],"batl":[[0,1.8,11.89],[1,1.86,189.75]],"ltp":1.78,"tv":281.26,"id":8257797}]}]}
{"op":"mcm","clk":"4230006983","pt":1631527799467,"mc":[{"id":"1.187557146","rc":[{"batb":[[0,1.76,120.13]],"ltp":1.78,"tv":281.26,"id":8257797}]}]}
{"op":"mcm","clk":"4230007393","pt":1631527805291,"mc":[{"id":"1.187557146","rc":[{"batb":[[0,1.95,48.24],[1,1.7,37.52],[2,1.47,1.54]],"ltp":1.94,"tv":70.16,"id":19931652},{"batb":[[0,1.76,108],[1,1.66,40.62],[2,1.3,197.65]],"ltp":1.78,"tv":281.26,"id":8257797}]}]}
{"op":"mcm","clk":"4230007455","pt":1631527806116,"mc":[{"id":"1.187557146","rc":[{"batb":[[1,1.47,1.54],[2,1.4,148.24]],"ltp":1.94,"tv":70.16,"id":19931652},{"batb":[[0,1.66,40.62],[1,1.3,197.65],[2,1.25,237.19]],"ltp":1.78,"tv":281.26,"id":8257797}]}]}
{"op":"mcm","clk":"4230007629","pt":1631527808228,"mc":[{"id":"1.187557146","rc":[{"batb":[[1,1.6,99.37],[2,1.5,106.73]],"ltp":1.94,"tv":70.16,"id":19931652}]}]}
{"op":"mcm","clk":"4230008922","pt":1631527825911,"mc":[{"id":"1.187557146","rc":[{"batb":[[1,1.31,768.11],[2,1.3,197.65]],"ltp":1.78,"tv":281.26,"id":8257797}]}]}
{"op":"mcm","clk":"4230009443","pt":1631527833317,"mc":[{"id":"1.187557146","rc":[{"batb":[[0,2.34,51.29],[1,1.95,48.24],[2,1.6,99.37]],"batl":[[0,2.46,10.51],[1,2.56,118.08]],"ltp":1.94,"tv":70.16,"id":19931652},{"batl":[[0,1.72,9.17],[1,1.74,99.6]],"ltp":1.78,"tv":281.26,"id":8257797}]}]}
{"op":"mcm","clk":"4230009500","pt":1631527834150,"mc":[{"id":"1.187557146","rc":[{"batb":[[0,2.34,17.1],[1,2.18,33.83],[2,2.06,41.04]],"ltp":1.94,"tv":70.16,"id":19931652},{"batb":[[1,1.61,45.47],[2,1.31,768.11]],"ltp":1.78,"tv":281.26,"id":8257797}]}]}
{"op":"mcm","clk":"4230010226","pt":1631527844065,"mc":[{"id":"1.187557146","rc":[{"batb":[[0,2.18,33.83],[1,2.06,41.04],[2,1.7,16.94]],"ltp":1.94,"tv":70.16,"id":19931652}]}]}
{"op":"mcm","clk":"4230010259","pt":1631527844476,"mc":[{"id":"1.187557146","rc":[{"batb":[[0,2.06,41.04],[1,1.7,16.94],[2,1.6,99.37]],"ltp":1.94,"tv":70.16,"id":19931652},{"batb":[[0,1.61,45.47],[1,1.31,768.11],[2,1.3,197.65]],"ltp":1.78,"tv":281.26,"id":8257797}]}]}
{"op":"mcm","clk":"4230010735","pt":1631527851245,"mc":[{"id":"1.187557146","rc":[{"batl":[[0,810,0.07]],"ltp":1.78,"tv":281.26,"id":8257797}]}]}
{"op":"mcm","clk":"4230011276","pt":1631527858070,"mc":[{"id":"1.187557146","rc":[{"batl":[[0,820,0.14]],"ltp":1.78,"tv":281.26,"id":8257797}]}]}
{"op":"mcm","clk":"4230011989","pt":1631527868291,"mc":[{"id":"1.187557146","rc":[{"batl":[[0,1.7,1804.62],[1,1.74,114.94],[2,1.77,8.24]],"ltp":1.78,"tv":281.26,"id":8257797}]}]}
{"op":"mcm","clk":"4230012055","pt":1631527869168,"mc":[{"id":"1.187557146","rc":[{"batb":[[0,2.28,29.9],[1,2.16,34.75],[2,2.06,41.04]],"batl":[[0,2.6,11.72],[1,2.66,70.01]],"ltp":1.94,"tv":70.16,"id":19931652},{"batb":[[1,1.57,50.08],[2,1.31,768.11]],"batl":[[0,1.66,9],[1,1.68,109.88],[2,1.74,22.98]],"ltp":1.78,"tv":281.26,"id":8257797}]}]}
{"op":"mcm","clk":"4230012069","pt":1631527869373,"mc":[{"id":"1.187557146","rc":[{"batb":[[2,1.7,16.94]],"ltp":1.94,"tv":70.16,"id":19931652}]}]}
{"op":"mcm","clk":"4230012149","pt":1631527870611,"mc":[{"id":"1.187557146","rc":[{"batb":[[2,1.44,443.07]],"ltp":1.78,"tv":281.26,"id":8257797}]}]}
{"op":"mcm","clk":"4230012586","pt":1631527876196,"mc":[{"id":"1.187557146","rc":[{"batb":[[0,2.16,34.75],[1,1.7,16.94],[2,1.6,99.37]],"ltp":1.94,"tv":70.16,"id":19931652},{"batb":[[0,1.57,50.08],[1,1.44,443.07],[2,1.31,768.11]],"batl":[[0,2.16,348.23],[1,810,0.07],[2,1.74,0]],"ltp":1.78,"tv":281.26,"id":8257797}]}]}
{"op":"mcm","clk":"4230013275","pt":1631527886132,"mc":[{"id":"1.187557146","rc":[{"batb":[[0,2.54,15.74],[1,2.16,34.75],[2,1.7,16.94]],"batl":[[0,2.72,12.34],[1,2.78,71.37]],"ltp":1.94,"tv":70.16,"id":19931652},{"batl":[[0,1.62,12.34],[1,1.64,140.31],[2,2.16,348.23]],"ltp":1.78,"tv":281.26,"id":8257797}]}]}
{"op":"mcm","clk":"4230013337","pt":1631527887008,"mc":[{"id":"1.187557146","rc":[{"batb":[[1,2.38,26.71],[2,2.28,30.32]],"ltp":1.94,"tv":70.16,"id":19931652},{"batb":[[1,1.54,53.35],[2,1.44,443.07]],"ltp":1.78,"tv":281.26,"id":8257797}]}]}
{"op":"mcm","clk":"4230014013","pt":1631527896931,"mc":[{"id":"1.187557146","rc":[{"batb":[[0,2.38,26.71],[1,2.28,30.32],[2,1.7,16.94]],"ltp":1.94,"tv":70.16,"id":19931652},{"batl":[[0,2.16,348.23],[1,810,0.07],[2,2.16,0]],"ltp":1.78,"tv":281.26,"id":8257797}]}]}
{"op":"mcm","clk":"4230014053","pt":1631527897448,"mc":[{"id":"1.187557146","rc":[{"batb":[[0,2.28,30.32],[1,1.7,16.94],[2,1.6,99.37]],"ltp":1.94,"tv":70.16,"id":19931652},{"batb":[[0,1.54,53.35],[1,1.44,443.07],[2,1.31,768.11]],"ltp":1.78,"tv":281.26,"id":8257797}]}]}
{"op":"mcm","clk":"4230015882","pt":1631527921346,"mc":[{"id":"1.187557146","rc":[{"batb":[[1,1.31,768.11],[2,1.3,197.65]],"batl":[[0,810,0.07],[1,810,0]],"ltp":1.78,"tv":281.26,"id":8257797}]}]}
{"op":"mcm","clk":"4230015974","pt":1631527922237,"mc":[{"id":"1.187557146","rc":[{"batl":[[0,2.78,8.09]],"ltp":1.94,"tv":70.16,"id":19931652},{"batb":[[0,1.54,161.47]],"batl":[[0,1.6,116.16],[1,1.63,122.7],[2,810,0.07]],"ltp":1.78,"tv":281.26,"id":8257797}]}]}
{"op":"mcm","clk":"4230016065","pt":1631527923245,"mc":[{"id":"1.187557146","rc":[{"batb":[[0,2.44,24.87],[1,2.36,27.64],[2,2.3,5.66]],"ltp":1.94,"tv":70.16,"id":19931652},{"batb":[[1,1.49,61.55],[2,1.31,768.11]],"batl":[[1,1.63,24.54]],"ltp":1.78,"tv":281.26,"id":8257797}]}]}
{"op":"mcm","clk":"4230016127","pt":1631527923975,"mc":[{"id":"1.187557146","rc":[{"batl":[[2,1.74,6.38]],"ltp":1.78,"tv":281.26,"id":8257797}]}]}
{"op":"mcm","clk":"4230016234","pt":1631527925272,"mc":[{"id":"1.187557146","rc":[{"batb":[[2,1.38,455.53]],"ltp":1.78,"tv":281.26,"id":8257797}]}]}
{"op":"mcm","clk":"4230016378","pt":1631527927245,"mc":[{"id":"1.187557146","rc":[{"batl":[[1,2.8,33.66]],"ltp":1.94,"tv":70.16,"id":19931652},{"batl":[[0,1.6,177.38]],"ltp":1.78,"tv":281.26,"id":8257797}]}]}
{"op":"mcm","clk":"4230016410","pt":1631527927657,"mc":[{"id":"1.187557146","rc":[{"batl":[[1,2.8,0]],"ltp":1.94,"tv":70.16,"id":19931652},{"batl":[[0,1.6,116.16],[2,2.04,389.06]],"ltp":1.78,"tv":281.26,"id":8257797}]}]}
{"op":"mcm","clk":"4230016835","pt":1631527932096,"mc":[{"id":"1.187557146","rc":[{"batb":[[2,1.7,16.94]],"ltp":1.94,"tv":70.16,"id":19931652}]}]}
{"op":"mcm","clk":"4230016962","pt":1631527933703,"mc":[{"id":"1.187557146","rc":[{"batb":[[2,1.31,768.11]],"batl":[[2,810,0.07]],"ltp":1.78,"tv":281.26,"id":8257797}]}]}
{"op":"mcm","clk":"4230017169","pt":1631527935990,"mc":[{"id":"1.187557146","rc":[{"batb":[[0,2.46,8.46],[1,2.44,24.87],[2,2.36,27.64]],"ltp":1.94,"tv":70.16,"id":19931652}]}]}
{"op":"mcm","clk":"4230018768","pt":1631527954307,"mc":[{"id":"1.187557146","rc":[{"batb":[[0,1.54,53.35]],"batl":[[0,810,0.07],[1,1.63,0],[2,810,0]],"ltp":1.78,"tv":281.26,"id":8257797}]}]}
{"op":"mcm","clk":"4230018809","pt":1631527954722,"mc":[{"id":"1.187557146","rc":[{"batb":[[0,2.36,27.64],[1,1.8,11.86],[2,1.7,16.94]],"ltp":1.94,"tv":70.16,"id":19931652},{"batb":[[0,1.49,61.55],[1,1.31,768.11],[2,1.3,197.65]],"ltp":1.78,"tv":281.26,"id":8257797}]}]}
{"op":"mcm","clk":"4230020121","pt":1631527970245,"mc":[{"id":"1.187557146","rc":[{"batb":[[0,2.88,10.51],[1,2.52,79.36],[2,2.36,27.64]],"batl":[[0,3,3.5]],"ltp":1.94,"tv":70.16,"id":19931652},{"batb":[[0,1.5,7],[1,1.49,61.55],[2,1.47,162.87]],"batl":[[0,1.54,121.73],[1,810,0.07]],"ltp":1.78,"tv":281.26,"id":8257797}]}]}
{"op":"mcm","clk":"4230020227","pt":1631527971353,"mc":[{"id":"1.187557146","rc":[{"batb":[[1,2.6,21.02],[2,2.52,15.88]],"ltp":1.94,"tv":70.16,"id":19931652}]}]}
{"op":"mcm","clk":"4230020850","pt":1631527975280,"mc":[{"id":"1.187557146","rc":[{"batl":[[0,2.98,31.09],[1,3,3.5]],"ltp":1.94,"tv":70.16,"id":19931652},{"batl":[[1,1.55,77.4],[2,810,0.07]],"ltp":1.78,"tv":281.26,"id":8257797}]}]}
{"op":"mcm","clk":"4230020872","pt":1631527975439,"mc":[{"id":"1.187557146","rc":[{"batl":[[0,3,3.5],[1,3,0]],"ltp":1.94,"tv":70.16,"id":19931652},{"batl":[[1,810,0.07],[2,810,0]],"ltp":1.78,"tv":281.26,"id":8257797}]}]}
{"op":"mcm","clk":"4230022181","pt":1631527984358,"mc":[{"id":"1.187557146","rc":[{"batb":[[0,2.6,21.02],[1,2.48,23.95],[2,1.8,11.86]],"ltp":1.94,"tv":70.16,"id":19931652},{"batb":[[0,1.49,61.55],[1,1.42,73.53],[2,1.31,768.11]],"batl":[[0,810,0.07],[1,810,0]],"ltp":1.78,"tv":281.26,"id":8257797}]}]}
{"op":"mcm","clk":"4230022226","pt":1631527984779,"mc":[{"id":"1.187557146","rc":[{"batb":[[0,2.48,23.95],[1,1.8,11.86],[2,1.7,16.94]],"ltp":1.94,"tv":70.16,"id":19931652},{"batb":[[0,1.42,73.53],[1,1.31,768.11],[2,1.25,237.19]],"ltp":1.78,"tv":281.26,"id":8257797}]}]}
{"op":"mcm","clk":"4230023733","pt":1631527995253,"mc":[{"id":"1.187557146","rc":[{"batb":[[0,3.2,4.89],[1,3.1,78.54],[2,2.48,23.95]],"batl":[[0,3.3,6.43]],"ltp":1.94,"tv":70.16,"id":19931652},{"batb":[[1,1.41,151.51],[2,1.31,768.11]],"batl":[[0,1.6,25],[1,810,0.07]],"ltp":1.78,"tv":281.26,"id":8257797}]}]}
{"op":"mcm","clk":"4230023874","pt":1631527996155,"mc":[{"id":"1.187557146","rc":[{"batb":[[2,2.8,42.71]],"ltp":1.94,"tv":70.16,"id":19931652},{"batb":[[2,1.37,87.35]],"ltp":1.78,"tv":281.26,"id":8257797}]}]}
{"op":"mcm","clk":"4230024863","pt":1631528003290,"mc":[{"id":"1.187557146","rc":[{"batb":[[0,1.44,127],[1,1.42,73.53],[2,1.41,151.51]],"batl":[[0,1.56,13.76],[1,1.6,25],[2,810,0.07]],"ltp":1.78,"tv":281.26,"id":8257797}]}]}
{"op":"mcm","clk":"4230025101","pt":1631528004908,"mc":[{"id":"1.187557146","rc":[{"batb":[[0,2.66,19.76],[1,1.8,11.86],[2,1.7,16.94]],"ltp":1.94,"tv":70.16,"id":19931652},{"batb":[[0,1.37,87.35],[1,1.31,768.11],[2,1.2,385.43]],"batl":[[0,810,0.07],[1,1.6,0],[2,810,0]],"ltp":1.78,"tv":281.26,"id":8257797}]}]}
{"op":"mcm","clk":"4230026298","pt":1631528013173,"mc":[{"id":"1.187557146","rc":[{"batl":[[0,3.2,61.68],[1,3.25,61.54]],"ltp":1.94,"tv":70.16,"id":19931652},{"batb":[[0,1.48,12.62],[1,1.37,87.35],[2,1.31,768.11]],"batl":[[0,1.5,5.07],[1,1.52,147.98],[2,810,0.07]],"ltp":1.78,"tv":281.26,"id":8257797}]}]}
{"op":"mcm","clk":"4230026377","pt":1631528014100,"mc":[{"id":"1.187557146","rc":[{"batb":[[1,2.5,23.2],[2,1.8,11.86]],"batl":[[1,3.25,12.3]],"ltp":1.94,"tv":70.16,"id":19931652},{"batb":[[1,1.47,64.73],[2,1.4,79.56]],"ltp":1.78,"tv":281.26,"id":8257797}]}]}
{"op":"mcm","clk":"4230026751","pt":1631528018187,"mc":[{"id":"1.187557146","rc":[{"batl":[[0,3.1,42.7],[1,3.2,61.68],[2,3.25,12.3]],"ltp":1.94,"tv":70.16,"id":19931652},{"batl":[[2,1.53,88.24]],"ltp":1.78,"tv":281.26,"id":8257797}]}]}
{"op":"mcm","clk":"4230026771","pt":1631528018390,"mc":[{"id":"1.187557146","rc":[{"batl":[[0,3.2,61.68],[1,3.25,12.3],[2,3.25,0]],"ltp":1.94,"tv":70.16,"id":19931652},{"batl":[[2,810,0.07]],"ltp":1.78,"tv":281.26,"id":8257797}]}]}
{"op":"mcm","clk":"4230027027","pt":1631528021391,"mc":[{"id":"1.187557146","rc":[{"batb":[[0,1.48,122.62]],"ltp":1.78,"tv":281.26,"id":8257797}]}]}
{"op":"mcm","clk":"4230027294","pt":1631528023321,"mc":[{"id":"1.187557146","rc":[{"batb":[[0,1.48,110]],"batl":[[0,810,0.07],[1,1.52,0],[2,810,0]],"ltp":1.78,"tv":281.26,"id":8257797}]}]}
{"op":"mcm","clk":"4230027359","pt":1631528023798,"mc":[{"id":"1.187557146","rc":[{"batb":[[0,2.5,23.2],[1,1.8,11.86],[2,1.7,16.94]],"batl":[[0,3,10]],"ltp":1.94,"tv":70.16,"id":19931652},{"batb":[[0,1.4,79.56],[1,1.31,768.11],[2,1.2,385.43]],"ltp":1.78,"tv":281.26,"id":8257797}]}]}
{"op":"mcm","clk":"4230027838","pt":1631528026991,"mc":[{"id":"1.187557146","rc":[{"batb":[[2,1.25,237.19]],"ltp":1.78,"tv":281.26,"id":8257797}]}]}
{"op":"mcm","clk":"4230029075","pt":1631528035817,"mc":[{"id":"1.187557146","rc":[{"batb":[[1,1.7,16.94],[2,1.6,99.37]],"ltp":1.94,"tv":70.16,"id":19931652},{"batb":[[0,1.65,2.17],[1,1.4,79.56],[2,1.31,768.11]],"ltp":1.78,"tv":281.26,"id":8257797}]}]}
{"op":"mcm","clk":"4230029599","pt":1631528039324,"mc":[{"id":"1.187557146","rc":[{"batb":[[0,3.35,4.97],[1,3.25,68.84],[2,2.5,23.2]],"batl":[[0,3.5,4.97]],"ltp":1.94,"tv":70.16,"id":19931652},{"trd":[[1.65,4.34]],"batb":[[0,1.4,92],[1,1.38,178.95]],"batl":[[0,1.44,2300.88],[1,1.49,8.43],[2,1.58,126.58]],"ltp":1.65,"tv":285.6,"id":8257797}],"tv":355.76}]}
{"op":"mcm","clk":"4230029687","pt":1631528040158,"mc":[{"id":"1.187557146","rc":[{"batb":[[2,2.92,38.61]],"ltp":1.94,"tv":70.16,"id":19931652},{"batb":[[2,1.34,97.06]],"batl":[[0,1.58,25.32],[1,810,0.07],[2,1.58,0]],"ltp":1.65,"tv":285.6,"id":8257797}]}]}
{"op":"mcm","clk":"4230030077","pt":1631528042620,"mc":[{"id":"1.187557146","rc":[{"trd":[[3.35,4.97]],"batb":[[0,3.25,68.84],[1,2.92,38.61],[2,2.74,18.17]],"ltp":3.35,"tv":75.13,"id":19931652},{"trd":[[1.43,11.64]],"ltp":1.43,"tv":297.24,"id":8257797}],"tv":372.37}]}
{"op":"mcm","clk":"4230030337","pt":1631528044343,"mc":[{"id":"1.187557146","rc":[{"batl":[[0,3.4,23.57],[1,3.5,4.97]],"ltp":3.35,"tv":75.13,"id":19931652},{"batl":[[0,1.45,76.92],[1,1.58,25.32],[2,810,0.07]],"ltp":1.43,"tv":297.24,"id":8257797}]}]}
{"op":"mcm","clk":"4230030374","pt":1631528044550,"mc":[{"id":"1.187557146","rc":[{"batl":[[0,3.5,4.97],[1,3.5,0]],"ltp":3.35,"tv":75.13,"id":19931652},{"batl":[[0,1.58,25.32],[1,810,0.07],[2,810,0]],"ltp":1.43,"tv":297.24,"id":8257797}]}]}
{"op":"mcm","clk":"4230030608","pt":1631528046128,"mc":[{"id":"1.187557146","rc":[{"trd":[[1.4,5.11]],"batb":[[0,1.4,89.45]],"ltp":1.4,"tv":302.35,"id":8257797}],"tv":377.48}]}
{"op":"mcm","clk":"4230031280","pt":1631528050352,"mc":[{"id":"1.187557146","rc":[{"batl":[[0,1.56,14.16],[1,1.58,25.32],[2,810,0.07]],"ltp":1.4,"tv":302.35,"id":8257797}]}]}
{"op":"mcm","clk":"4230031629","pt":1631528052857,"mc":[{"id":"1.187557146","rc":[{"batb":[[0,1.4,77.01]],"ltp":1.4,"tv":302.35,"id":8257797}]}]}
{"op":"mcm","clk":"4230031970","pt":1631528055932,"mc":[{"id":"1.187557146","rc":[{"batb":[[0,3.3,5.33],[1,3.25,68.84],[2,2.92,38.61]],"batl":[[0,3.4,5.11]],"ltp":3.35,"tv":75.13,"id":19931652}]}]}
{"op":"mcm","clk":"4230033394","pt":1631528066166,"mc":[{"id":"1.187557146","rc":[{"batb":[[0,2.74,18.17],[1,2,11.86],[2,1.8,11.86]],"ltp":3.35,"tv":75.13,"id":19931652},{"batb":[[0,1.34,97.06],[1,1.2,385.43],[2,1.17,313.93]],"batl":[[0,810,0.07],[1,1.58,0],[2,810,0]],"ltp":1.4,"tv":302.35,"id":8257797}]}]}
{"op":"mcm","clk":"4230034767","pt":1631528076254,"mc":[{"id":"1.187557146","rc":[{"batb":[[0,3.6,55.56],[1,2.74,18.17],[2,2,11.86]],"batl":[[0,3.85,6.85],[1,4.1,63.1]],"ltp":3.35,"tv":75.13,"id":19931652},{"batl":[[0,1.37,12.57],[1,1.44,647.94],[2,810,0.07]],"ltp":1.4,"tv":302.35,"id":8257797}]}]}
{"op":"mcm","clk":"4230034984","pt":1631528077254,"mc":[{"id":"1.187557146","rc":[{"batb":[[0,3.6,11.12],[1,3.2,29.73],[2,2.98,36.26]],"ltp":3.35,"tv":75.13,"id":19931652},{"trd":[[1.37,4.34]],"batb":[[1,1.31,107.03]],"batl":[[0,1.37,10.4]],"ltp":1.37,"tv":306.69,"id":8257797}],"tv":381.82}]}
{"op":"mcm","clk":"4230035118","pt":1631528078344,"mc":[{"id":"1.187557146","rc":[{"batb":[[2,1.23,524.63]],"batl":[[2,1.73,535.9]],"ltp":1.37,"tv":306.69,"id":8257797}]}]}
{"op":"mcm","clk":"4230035485","pt":1631528081261,"mc":[{"id":"1.187557146","rc":[{"batl":[[1,1.39,2.59],[2,1.44,647.94]],"ltp":1.37,"tv":306.69,"id":8257797}]}]}
{"op":"mcm","clk":"4230035680","pt":1631528082469,"mc":[{"id":"1.187557146","rc":[{"batl":[[1,1.44,647.94],[2,1.73,535.9]],"ltp":1.37,"tv":306.69,"id":8257797}]}]}
{"op":"mcm","clk":"4230035929","pt":1631528084396,"mc":[{"id":"1.187557146","rc":[{"batb":[[0,1.35,409],[1,1.34,97.06],[2,1.31,107.03]],"ltp":1.37,"tv":306.69,"id":8257797}]}]}
{"op":"mcm","clk":"4230036134","pt":1631528085805,"mc":[{"id":"1.187557146","rc":[{"trd":[[1.35,4.42]],"batb":[[0,1.35,406.79]],"ltp":1.35,"tv":311.1,"id":8257797}],"tv":386.23}]}
{"op":"mcm","clk":"4230036369","pt":1631528087173,"mc":[{"id":"1.187557146","rc":[{"batl":[[0,4.1,63.1],[1,4.1,0]],"ltp":3.35,"tv":75.13,"id":19931652},{"batl":[[0,1.44,647.94],[1,1.73,535.9],[2,810,0.07]],"ltp":1.35,"tv":311.1,"id":8257797}]}]}
{"op":"mcm","clk":"4230036796","pt":1631528090196,"mc":[{"id":"1.187557146","rc":[{"batb":[[0,3.7,4.07],[1,3.6,11.12],[2,3.2,29.73]],"batl":[[0,3.85,7.62],[1,4.1,63.1]],"ltp":3.35,"tv":75.13,"id":19931652}]}]}
{"op":"mcm","clk":"4230037226","pt":1631528093478,"mc":[{"id":"1.187557146","rc":[{"batl":[[2,44,7.24]],"ltp":1.35,"tv":311.1,"id":8257797}]}]}
{"op":"mcm","clk":"4230037328","pt":1631528094608,"mc":[{"id":"1.187557146","rc":[{"trd":[[1.35,243.6]],"batb":[[0,1.35,287.2]],"ltp":1.35,"tv":550.28,"id":8257797}],"tv":625.41}]}
{"op":"mcm","clk":"4230038918","pt":1631528105602,"mc":[{"id":"1.187557146","rc":[{"batl":[[0,3.8,5],[1,3.85,7.62],[2,4.1,63.1]],"ltp":3.35,"tv":75.13,"id":19931652},{"trd":[[1.35,249.56]],"batb":[[0,1.35,284.22]],"ltp":1.35,"tv":556.24,"id":8257797}],"tv":631.37}]}
{"op":"mcm","clk":"4230041819","pt":1631528136335,"mc":[{"id":"1.187557146","rc":[{"batl":[[0,3.85,7.62],[1,4.1,63.1],[2,4.1,0]],"ltp":3.35,"tv":75.13,"id":19931652}]}]}
{"op":"mcm","clk":"4230042018","pt":1631528139451,"mc":[{"id":"1.187557146","rc":[{"trd":[[3.7,8.14]],"batb":[[0,3.6,11.12],[1,3.2,29.73],[2,2.98,36.26]],"batl":[[0,3.85,8.55]],"ltp":3.7,"tv":83.27,"id":19931652}],"tv":639.51}]}
{"op":"mcm","clk":"4230042317","pt":1631528143039,"mc":[{"id":"1.187557146","rc":[{"batl":[[0,3.85,7.62]],"ltp":3.7,"tv":83.27,"id":19931652}]}]}
{"op":"mcm","clk":"4230042734","pt":1631528149635,"mc":[{"id":"1.187557146","rc":[{"batl":[[0,4.1,63.1],[1,4.1,0]],"ltp":3.7,"tv":83.27,"id":19931652}]}]}
{"op":"mcm","clk":"4230042936","pt":1631528152646,"mc":[{"id":"1.187557146","rc":[{"batl":[[0,3.75,3.98],[1,4.1,63.1]],"ltp":3.7,"tv":83.27,"id":19931652},{"batl":[[0,1.38,14.99],[1,1.44,647.94],[2,1.73,535.9]],"ltp":1.35,"tv":556.24,"id":8257797}]}]}
{"op":"mcm","clk":"4230043045","pt":1631528154154,"mc":[{"id":"1.187557146","rc":[{"batb":[[0,2.98,36.26],[1,2,11.86],[2,1.8,11.86]],"ltp":3.7,"tv":83.27,"id":19931652},{"batb":[[0,1.31,107.03],[1,1.23,524.63],[2,1.17,313.93]],"batl":[[0,1.73,535.9],[1,44,7.24],[2,1.73,0]],"ltp":1.35,"tv":556.24,"id":8257797}]}]}
{"op":"mcm","clk":"4230043297","pt":1631528158294,"mc":[{"id":"1.187557146","rc":[{"batb":[[0,3.85,5.4],[1,2.98,36.26],[2,2,11.86]],"ltp":3.7,"tv":83.27,"id":19931652}]}]}
{"op":"mcm","clk":"4230043436","pt":1631528159852,"mc":[{"id":"1.187557146","rc":[{"batb":[[0,2.98,36.26],[1,2,11.86],[2,1.8,11.86]],"ltp":3.7,"tv":83.27,"id":19931652}]}]}
{"op":"mcm","clk":"4230043748","pt":1631528163488,"mc":[{"id":"1.187557146","rc":[{"batb":[[0,1.5,2.17],[1,1.31,107.03],[2,1.23,524.63]],"ltp":1.35,"tv":556.24,"id":8257797}]}]}
{"op":"mcm","clk":"4230044226","pt":1631528169656,"mc":[{"id":"1.187557146","rc":[{"batl":[[0,5,11]],"ltp":3.7,"tv":83.27,"id":19931652}]}]}
{"op":"mcm","clk":"4230044366","pt":1631528171875,"mc":[{"id":"1.187557146","rc":[{"batb":[[0,3.85,4.06],[1,3.8,10.52],[2,2.98,36.26]],"batl":[[0,4,6.51],[1,4.3,55.4],[2,5,11]],"ltp":3.7,"tv":83.27,"id":19931652},{"trd":[[1.5,4.34]],"batb":[[0,1.31,107.03],[1,1.23,524.63],[2,1.17,313.93]],"batl":[[0,1.35,171.64],[1,1.73,535.9],[2,44,7.24]],"ltp":1.5,"tv":560.59,"id":8257797}],"tv":643.86}]}
{"op":"mcm","clk":"4230044452","pt":1631528172968,"mc":[{"id":"1.187557146","rc":[{"batb":[[2,3.4,26.04]],"ltp":3.7,"tv":83.27,"id":19931652},{"batb":[[1,1.29,115.99],[2,1.25,237.19]],"ltp":1.5,"tv":560.59,"id":8257797}]}]}
{"op":"mcm","clk":"4230044480","pt":1631528173485,"mc":[{"id":"1.187557146","rc":[{"batb":[[2,1.23,524.63]],"ltp":1.5,"tv":560.59,"id":8257797}]}]}
{"op":"mcm","clk":"4230044579","pt":1631528175091,"mc":[{"id":"1.187557146","rc":[{"trd":[[1.35,339.24]],"batl":[[0,1.35,126.8]],"ltp":1.35,"tv":650.27,"id":8257797}],"tv":733.54}]}
{"op":"mcm","clk":"4230044776","pt":1631528178094,"mc":[{"id":"1.187557146","rc":[{"batb":[[0,1.33,112],[1,1.31,107.03],[2,1.29,115.99]],"ltp":1.35,"tv":650.27,"id":8257797}]}]}
{"op":"mcm","clk":"4230044857","pt":1631528179185,"mc":[{"id":"1.187557146","rc":[{"trd":[[1.33,4.9]],"batb":[[0,1.33,109.55]],"ltp":1.33,"tv":655.16,"id":8257797}],"tv":738.43}]}
{"op":"mcm","clk":"4230045236","pt":1631528184103,"mc":[{"id":"1.187557146","rc":[{"batb":[[0,3.15,31.57],[1,3,1.2],[2,2.2,42.7]],"batl":[[0,5,11],[1,4.3,0],[2,5,0]],"ltp":3.7,"tv":83.27,"id":19931652},{"batb":[[0,1.29,115.99],[1,1.23,524.63],[2,1.17,313.93]],"batl":[[0,1.73,535.9],[1,44,7.24],[2,44,0]],"ltp":1.33,"tv":655.16,"id":8257797}]}]}
{"op":"mcm","clk":"4230045602","pt":1631528189429,"mc":[{"id":"1.187557146","rc":[{"trd":[[1.29,33.11]],"batb":[[0,1.29,99.43]],"ltp":1.29,"tv":688.28,"id":8257797}],"tv":771.55}]}
{"op":"mcm","clk":"4230046142","pt":1631528197134,"mc":[{"id":"1.187557146","rc":[{"batb":[[2,2,11.86]],"ltp":3.7,"tv":83.27,"id":19931652},{"batb":[[0,1.45,2.17],[1,1.29,99.43],[2,1.23,524.63]],"ltp":1.29,"tv":688.28,"id":8257797}]}]}
{"op":"mcm","clk":"4230046497","pt":1631528202349,"mc":[{"id":"1.187557146","rc":[{"batb":[[2,1.17,313.93]],"batl":[[0,44,7.24],[1,44,0]],"ltp":1.29,"tv":688.28,"id":8257797}]}]}
{"op":"mcm","clk":"4230046640","pt":1631528204057,"mc":[{"id":"1.187557146","rc":[{"trd":[[4.2,8.8]],"batb":[[0,3.9,10.26],[1,3.15,31.57],[2,3,1.2]],"batl":[[0,4.2,1.69],[1,5,11]],"ltp":4.2,"tv":92.07,"id":19931652},{"trd":[[1.45,4.34]],"batb":[[0,1.29,249.58],[1,1.17,313.93],[2,1.11,269.53]],"batl":[[0,1.33,166.5],[1,44,7.24]],"ltp":1.45,"tv":692.62,"id":8257797}],"tv":784.69}]}
{"op":"mcm","clk":"4230046754","pt":1631528205145,"mc":[{"id":"1.187557146","rc":[{"batb":[[1,3.55,23.2],[2,3.35,27.22]],"ltp":4.2,"tv":92.07,"id":19931652},{"batb":[[1,1.28,123.86],[2,1.17,313.93]],"ltp":1.45,"tv":692.62,"id":8257797}]}]}
{"op":"mcm","clk":"4230046822","pt":1631528206032,"mc":[{"id":"1.187557146","rc":[{"batb":[[2,1.2,539.24]],"batl":[[1,1.66,588.96],[2,44,7.24]],"ltp":1.45,"tv":692.62,"id":8257797}]}]}
{"op":"mcm","clk":"4230047243","pt":1631528210963,"mc":[{"id":"1.187557146","rc":[{"trd":[[4.2,9.55]],"batl":[[0,5,11.94],[1,5,0]],"ltp":4.2,"tv":92.82,"id":19931652},{"trd":[[1.31,2.4]],"ltp":1.31,"tv":695.02,"id":8257797}],"tv":787.84}]}
{"op":"mcm","clk":"4230047304","pt":1631528211945,"mc":[{"id":"1.187557146","rc":[{"batb":[[0,1.31,70],[1,1.29,249.58],[2,1.28,123.86]],"ltp":1.31,"tv":695.02,"id":8257797}]}]}
{"op":"mcm","clk":"4230047384","pt":1631528213149,"mc":[{"id":"1.187557146","rc":[{"batb":[[0,3.35,27.22],[1,3,1.2],[2,2,11.86]],"batl":[[0,5,11]],"ltp":4.2,"tv":92.82,"id":19931652},{"batb":[[0,1.28,123.86],[1,1.2,539.24],[2,1.17,313.93]],"batl":[[0,1.66,588.96],[1,44,7.24],[2,44,0]],"ltp":1.31,"tv":695.02,"id":8257797}]}]}
{"op":"mcm","clk":"4230048350","pt":1631528226260,"mc":[{"id":"1.187557146","rc":[{"batl":[[0,4.7,60.04],[1,5,11]],"ltp":4.2,"tv":92.82,"id":19931652},{"batb":[[0,1.29,16.59],[1,1.28,123.86],[2,1.2,539.24]],"batl":[[0,1.31,149.49],[1,1.32,90.91],[2,1.66,588.96]],"ltp":1.31,"tv":695.02,"id":8257797}]}]}
{"op":"mcm","clk":"4230048401","pt":1631528227184,"mc":[{"id":"1.187557146","rc":[{"batb":[[0,3.65,43.21],[1,3.5,24.12],[2,3,1.2]],"ltp":4.2,"tv":92.82,"id":19931652},{"batb":[[2,1.26,132.32]],"batl":[[1,1.32,30.3]],"ltp":1.31,"tv":695.02,"id":8257797}]}]}
{"op":"mcm","clk":"4230048928","pt":1631528235081,"mc":[{"id":"1.187557146","rc":[{"batb":[[0,1.29,122.59]],"ltp":1.31,"tv":695.02,"id":8257797}]}]}
{"op":"mcm","clk":"4230049315","pt":1631528240308,"mc":[{"id":"1.187557146","rc":[{"batb":[[0,3.5,24.12],[1,3,1.2],[2,2,11.86]],"batl":[[0,5,11],[1,5,0]],"ltp":4.2,"tv":92.82,"id":19931652},{"trd":[[1.29,33.27]],"batb":[[0,1.26,132.32],[1,1.2,539.24],[2,1.17,313.93]],"batl":[[0,1.66,588.96],[1,44,7.24],[2,1.66,0]],"ltp":1.29,"tv":695.18,"id":8257797}],"tv":788.0}]}
{"op":"mcm","clk":"4230049541","pt":1631528243105,"mc":[{"id":"1.187557146","rc":[{"batb":[[2,2.2,42.7]],"ltp":4.2,"tv":92.82,"id":19931652}]}]}
{"op":"mcm","clk":"4230049603","pt":1631528244092,"mc":[{"id":"1.187557146","rc":[{"batb":[[1,1.17,313.93],[2,1.11,269.53]],"batl":[[0,44,7.24],[1,44,0]],"ltp":1.29,"tv":695.18,"id":8257797}]}]}
{"op":"mcm","clk":"4230049758","pt":1631528246309,"mc":[{"id":"1.187557146","rc":[{"batb":[[0,4.4,5.36],[1,3.5,24.12],[2,3,1.2]],"batl":[[0,4.8,44.73],[1,5,11]],"ltp":4.2,"tv":92.82,"id":19931652},{"batb":[[0,1.28,13.01],[1,1.26,132.32],[2,1.17,313.93]],"batl":[[0,1.3,157.85],[1,1.32,30.3],[2,1.66,705.62]],"ltp":1.29,"tv":695.18,"id":8257797}]}]}
{"op":"mcm","clk":"4230049814","pt":1631528247291,"mc":[{"id":"1.187557146","rc":[{"batb":[[1,3.8,39.36],[2,3.65,43.46]],"ltp":4.2,"tv":92.82,"id":19931652},{"batb":[[2,1.24,146.05]],"batl":[[2,44,7.24]],"ltp":1.29,"tv":695.18,"id":8257797}]}]}
{"op":"mcm","clk":"4230049832","pt":1631528247703,"mc":[{"id":"1.187557146","rc":[{"batl":[[2,1.58,660.85]],"ltp":1.29,"tv":695.18,"id":8257797}]}]}
{"op":"mcm","clk":"4230050025","pt":1631528251022,"mc":[{"id":"1.187557146","rc":[{"trd":[[4.4,10.72]],"batb":[[0,3.8,39.36],[1,3.65,43.46],[2,3,1.2]],"ltp":4.4,"tv":103.54,"id":19931652}],"tv":798.72}]}
{"op":"mcm","clk":"4230050254","pt":1631528254230,"mc":[{"id":"1.187557146","rc":[{"batb":[[0,1.29,121],[1,1.28,13.01],[2,1.26,132.32]],"ltp":1.29,"tv":695.18,"id":8257797}]}]}
{"op":"mcm","clk":"4230050683","pt":1631528261034,"mc":[{"id":"1.187557146","rc":[{"batb":[[1,1.26,132.32],[2,1.24,146.05]],"ltp":1.29,"tv":695.18,"id":8257797}]}]}
{"op":"mcm","clk":"4230050868","pt":1631528263925,"mc":[{"id":"1.187557146","rc":[{"batl":[[0,4.5,5.24],[1,4.8,44.73],[2,5,11]],"ltp":4.4,"tv":103.54,"id":19931652},{"batl":[[0,1.3,170.05]],"ltp":1.29,"tv":695.18,"id":8257797}]}]}
{"op":"mcm","clk":"4230051205","pt":1631528269246,"mc":[{"id":"1.187557146","rc":[{"batl":[[0,5,11],[1,4.8,0],[2,5,0]],"ltp":4.4,"tv":103.54,"id":19931652},{"batl":[[0,1.58,660.85],[1,8.8,7.24],[2,44,7.24]],"ltp":1.29,"tv":695.18,"id":8257797}]}]}
{"op":"mcm","clk":"4230051222","pt":1631528269557,"mc":[{"id":"1.187557146","rc":[{"batb":[[0,3.65,43.46],[1,3,1.2],[2,2.2,42.7]],"ltp":4.4,"tv":103.54,"id":19931652},{"batb":[[0,1.24,146.05],[1,1.17,313.93],[2,1.16,585.23]],"ltp":1.29,"tv":695.18,"id":8257797}]}]}
{"op":"mcm","clk":"4230051937","pt":1631528281230,"mc":[{"id":"1.187557146","rc":[{"batb":[[0,4.3,183.67],[1,3.65,43.46],[2,3,1.2]],"batl":[[0,4.8,6.14],[1,5,11],[2,5.1,39.85]],"ltp":4.4,"tv":103.54,"id":19931652},{"batl":[[0,1.28,16.11],[1,1.3,2807.94],[2,1.58,660.85]],"ltp":1.29,"tv":695.18,"id":8257797}]}]}
{"op":"mcm","clk":"4230052013","pt":1631528282261,"mc":[{"id":"1.187557146","rc":[{"batb":[[0,4.3,146.45],[1,4,34.17],[2,3.8,38.86]],"ltp":4.4,"tv":103.54,"id":19931652},{"batb":[[1,1.22,162.88],[2,1.17,313.93]],"batl":[[1,1.58,660.85],[2,8.8,7.24]],"ltp":1.29,"tv":695.18,"id":8257797}]}]}
{"op":"mcm","clk":"4230052293","pt":1631528286251,"mc":[{"id":"1.187557146","rc":[{"trd":[[4.5,4.58]],"batl":[[0,4.5,14.09],[1,4.8,6.14],[2,5,11]],"ltp":4.5,"tv":108.12,"id":19931652},{"trd":[[1.28,16.11]],"batl":[[0,1.32,151.43]],"ltp":1.28,"tv":711.29,"id":8257797}],"tv":819.41}]}
{"op":"mcm","clk":"4230052305","pt":1631528286456,"mc":[{"id":"1.187557146","rc":[{"batl":[[0,4.8,6.14],[1,5,11],[2,5.1,39.85]],"ltp":4.5,"tv":108.12,"id":19931652},{"batl":[[0,1.58,660.85],[1,8.8,7.24],[2,44,7.24]],"ltp":1.28,"tv":711.29,"id":8257797}]}]}
{"op":"mcm","clk":"4230052544","pt":1631528289661,"mc":[{"id":"1.187557146","rc":[{"batl":[[0,1.44,16.48],[1,1.58,660.85],[2,8.8,7.24]],"ltp":1.28,"tv":711.29,"id":8257797}]}]}
{"op":"mcm","clk":"4230052657","pt":1631528291158,"mc":[{"id":"1.187557146","rc":[{"batb":[[0,4,34.17],[1,3.8,38.86],[2,3,1.2]],"batl":[[0,5,11],[1,5,0],[2,5.1,0]],"ltp":4.5,"tv":108.12,"id":19931652},{"batl":[[0,1.58,660.85],[1,8.8,7.24],[2,44,7.24]],"ltp":1.28,"tv":711.29,"id":8257797}]}]}
{"op":"mcm","clk":"4230052696","pt":1631528291572,"mc":[{"id":"1.187557146","rc":[{"batb":[[0,3.8,38.86],[1,3,1.2],[2,2.6,3.71]],"ltp":4.5,"tv":108.12,"id":19931652},{"batb":[[0,1.22,162.88],[1,1.17,313.93],[2,1.16,585.23]],"ltp":1.28,"tv":711.29,"id":8257797}]}]}
{"op":"mcm","clk":"4230053070","pt":1631528297192,"mc":[{"id":"1.187557146","rc":[{"batb":[[0,4.4,44.21],[1,4.3,4.2],[2,3.8,38.86]],"batl":[[0,4.6,785.52],[1,4.7,42.56],[2,5,11]],"ltp":4.5,"tv":108.12,"id":19931652},{"batb":[[0,1.29,13.05],[1,1.26,138.15],[2,1.22,162.88]],"ltp":1.28,"tv":711.29,"id":8257797}]}]}
{"op":"mcm","clk":"4230053143","pt":1631528298276,"mc":[{"id":"1.187557146","rc":[{"batb":[[1,3.8,38.86],[2,3.65,42.88]],"batl":[[0,4.7,8.52],[1,5,11],[2,5,0]],"ltp":4.5,"tv":108.12,"id":19931652},{"batb":[[0,1.26,271.81],[1,1.23,149.74],[2,1.17,313.93]],"ltp":1.28,"tv":711.29,"id":8257797}]}]}
{"op":"mcm","clk":"4230053286","pt":1631528300292,"mc":[{"id":"1.187557146","rc":[{"batb":[[1,4.3,4.2],[2,3.8,38.86]],"ltp":4.5,"tv":108.12,"id":19931652},{"batb":[[0,1.29,13.05],[1,1.26,271.81],[2,1.23,149.74]],"ltp":1.28,"tv":711.29,"id":8257797}]}]}
{"op":"mcm","clk":"4230053447","pt":1631528302269,"mc":[{"id":"1.187557146","rc":[{"trd":[[4.4,49.96]],"batb":[[0,4.4,24.59]],"ltp":4.4,"tv":147.36,"id":19931652}],"tv":858.65}]}
{"op":"mcm","clk":"4230053680","pt":1631528305418,"mc":[{"id":"1.187557146","rc":[{"batb":[[0,1.29,146.05]],"ltp":1.28,"tv":711.29,"id":8257797}]}]}
{"op":"mcm","clk":"4230053805","pt":1631528307170,"mc":[{"id":"1.187557146","rc":[{"batb":[[0,3.65,42.88],[1,3,1.2],[2,2.6,3.71]],"batl":[[0,5,11],[1,5,0]],"ltp":4.4,"tv":147.36,"id":19931652},{"batb":[[0,1.23,149.74],[1,1.17,313.93],[2,1.16,585.23]],"ltp":1.28,"tv":711.29,"id":8257797}]}]}
{"op":"mcm","clk":"4230054100","pt":1631528311457,"mc":[{"id":"1.187557146","rc":[{"batb":[[2,1.11,269.53]],"ltp":1.28,"tv":711.29,"id":8257797}]}]}
{"op":"mcm","clk":"4230054223","pt":1631528312852,"mc":[{"id":"1.187557146","rc":[{"batl":[[0,4.3,6.08],[1,5,11]],"ltp":4.4,"tv":147.36,"id":19931652},{"batb":[[0,1.3,30.76],[1,1.28,132.12],[2,1.23,149.74]],"batl":[[0,1.32,201.1],[1,1.58,660.85],[2,8.8,7.24]],"ltp":1.28,"tv":711.29,"id":8257797}]}]}
{"op":"mcm","clk":"4230054292","pt":1631528313884,"mc":[{"id":"1.187557146","rc":[{"batb":[[1,3.55,23.03],[2,3,1.2]],"ltp":4.4,"tv":147.36,"id":19931652},{"batb":[[2,1.27,124.53]],"ltp":1.28,"tv":711.29,"id":8257797}]}]}
{"op":"mcm","clk":"4230054502","pt":1631528317098,"mc":[{"id":"1.187557146","rc":[{"batb":[[0,1.3,113.76]],"ltp":1.28,"tv":711.29,"id":8257797}]}]}
{"op":"mcm","clk":"4230054674","pt":1631528319276,"mc":[{"id":"1.187557146","rc":[{"batl":[[0,5,11],[1,5,0]],"ltp":4.4,"tv":147.36,"id":19931652},{"batb":[[0,1.3,83],[1,1.27,124.53],[2,1.25,136.09]],"batl":[[0,1.58,660.85],[1,8.8,7.24],[2,44,7.24]],"ltp":1.28,"tv":711.29,"id":8257797}]}]}
{"op":"mcm","clk":"4230054736","pt":1631528320199,"mc":[{"id":"1.187557146","rc":[{"batb":[[0,3.55,23.03],[1,3,1.2],[2,2.6,3.71]],"ltp":4.4,"tv":147.36,"id":19931652},{"batb":[[0,1.25,136.09],[1,1.18,558.4],[2,1.17,313.93]],"ltp":1.28,"tv":711.29,"id":8257797}]}]}
{"op":"mcm","clk":"4230055315","pt":1631528328794,"mc":[{"id":"1.187557146","rc":[{"batb":[[2,2.2,42.7]],"batl":[[0,4.1,4.07],[1,4.2,9.52],[2,4.4,40.99]],"ltp":4.4,"tv":147.36,"id":19931652},{"batl":[[0,1.33,117.12],[1,1.34,18.71],[2,1.58,660.85]],"ltp":1.28,"tv":711.29,"id":8257797}]}]}
{"op":"mcm","clk":"4230055369","pt":1631528329823,"mc":[{"id":"1.187557146","rc":[{"batb":[[1,3.45,24.87],[2,3,1.2]],"ltp":4.4,"tv":147.36,"id":19931652},{"batb":[[0,1.29,116.99],[1,1.27,124.95],[2,1.18,558.4]],"ltp":1.28,"tv":711.29,"id":8257797}]}]}
{"op":"mcm","clk":"4230055502","pt":1631528332305,"mc":[{"id":"1.187557146","rc":[{"trd":[[1.33,9.24]],"batl":[[0,1.33,114.95]],"ltp":1.33,"tv":715.63,"id":8257797}],"tv":862.99}]}
{"op":"mcm","clk":"4230055785","pt":1631528337308,"mc":[{"id":"1.187557146","rc":[{"batb":[[0,1.32,95],[1,1.29,116.99],[2,1.27,124.95]],"ltp":1.33,"tv":715.63,"id":8257797}]}]}
{"op":"mcm","clk":"4230055868","pt":1631528338234,"mc":[{"id":"1.187557146","rc":[{"batl":[[0,5,11],[1,4.2,0],[2,4.4,0]],"ltp":4.4,"tv":147.36,"id":19931652},{"batl":[[0,1.58,660.85],[1,8.8,7.24],[2,44,7.24]],"ltp":1.33,"tv":715.63,"id":8257797}]}]}
{"op":"mcm","clk":"4230055891","pt":1631528338494,"mc":[{"id":"1.187557146","rc":[{"batb":[[0,3.45,24.87],[1,3,1.2],[2,2.2,42.7]],"ltp":4.4,"tv":147.36,"id":19931652},{"batb":[[0,1.27,124.95],[1,1.18,558.4],[2,1.17,313.93]],"ltp":1.33,"tv":715.63,"id":8257797}]}]}
{"op":"mcm","clk":"4230056022","pt":1631528340809,"mc":[{"id":"1.187557146","rc":[{"batl":[[0,1.58,660.93]],"ltp":1.33,"tv":715.63,"id":8257797}]}]}
{"op":"mcm","clk":"4230056371","pt":1631528346318,"mc":[{"id":"1.187557146","rc":[{"trd":[[1.27,4.54]],"batb":[[0,1.27,122.68]],"ltp":1.27,"tv":720.18,"id":8257797}],"tv":867.54}]}
{"op":"mcm","clk":"4230057033","pt":1631528358225,"mc":[{"id":"1.187557146","rc":[{"batb":[[0,3.9,41.08],[1,3.85,4.12],[2,3.45,24.87]],"batl":[[0,4,6.29],[1,4.3,59.14],[2,5,11]],"ltp":4.4,"tv":147.36,"id":19931652},{"trd":[[1.32,0.16]],"batb":[[0,1.34,29.86],[1,1.27,122.68],[2,1.18,558.4]],"batl":[[0,1.58,660.85]],"ltp":1.32,"tv":720.34,"id":8257797}],"tv":867.7}]}
{"op":"mcm","clk":"4230057101","pt":1631528359051,"mc":[{"id":"1.187557146","rc":[{"batb":[[1,1.3,110.79],[2,1.28,119.5]],"ltp":1.32,"tv":720.34,"id":8257797}]}]}
{"op":"mcm","clk":"4230057151","pt":1631528359928,"mc":[{"id":"1.187557146","rc":[{"trd":[[3.9,0.75]],"batb":[[0,3.9,40.33]],"ltp":3.9,"tv":148.11,"id":19931652},{"trd":[[1.35,341.41]],"ltp":1.35,"tv":722.51,"id":8257797}],"tv":870.62}]}
{"op":"mcm","clk":"4230057510","pt":1631528366480,"mc":[{"id":"1.187557146","rc":[{"trd":[[1.34,4.37]],"batb":[[0,1.34,27.68]],"ltp":1.34,"tv":726.87,"id":8257797}],"tv":874.98}]}
{"op":"mcm","clk":"4230057659","pt":1631528369677,"mc":[{"id":"1.187557146","rc":[{"batl":[[0,1.52,16.22],[1,1.58,660.85],[2,8.8,7.24]],"ltp":1.34,"tv":726.87,"id":8257797}]}]}
{"op":"mcm","clk":"4230062299","pt":1631528439161,"mc":[{"id":"1.187557146","rc":[{"batb":[[0,3.45,24.87],[1,3.2,30.23],[2,3,1.2]],"batl":[[0,5,11],[1,4.3,0],[2,5,0]],"ltp":3.9,"tv":148.11,"id":19931652},{"batb":[[0,1.3,110.79],[1,1.28,119.5],[2,1.18,558.4]],"batl":[[0,1.58,660.85],[1,8.8,7.24],[2,44,7.24]],"ltp":1.34,"tv":726.87,"id":8257797}]}]}
{"op":"mcm","clk":"4230062330","pt":1631528439575,"mc":[{"id":"1.187557146","rc":[{"batb":[[0,3.2,30.23],[1,3,1.2],[2,2.2,42.7]],"ltp":3.9,"tv":148.11,"id":19931652},{"batb":[[0,1.28,119.5],[1,1.18,558.4],[2,1.17,313.93]],"ltp":1.34,"tv":726.87,"id":8257797}]}]}
{"op":"mcm","clk":"4230062789","pt":1631528446350,"mc":[{"id":"1.187557146","rc":[{"batb":[[0,3.8,52.64],[1,3.2,30.23],[2,3,1.2]],"batl":[[0,4.2,5.69],[1,4.5,46.64],[2,5,11]],"ltp":3.9,"tv":148.11,"id":19931652},{"batl":[[0,1.33,204.12],[1,1.58,660.85],[2,8.8,7.24]],"ltp":1.34,"tv":726.87,"id":8257797}]}]}
{"op":"mcm","clk":"4230062807","pt":1631528446662,"mc":[{"id":"1.187557146","rc":[{"batb":[[0,3.8,10.52]],"ltp":3.9,"tv":148.11,"id":19931652}]}]}
{"op":"mcm","clk":"4230062871","pt":1631528447644,"mc":[{"id":"1.187557146","rc":[{"batb":[[1,3.6,22.36],[2,3.4,26.63]],"ltp":3.9,"tv":148.11,"id":19931652},{"batb":[[1,1.27,128.8],[2,1.18,558.4]],"ltp":1.34,"tv":726.87,"id":8257797}]}]}
{"op":"mcm","clk":"4230062969","pt":1631528449554,"mc":[{"id":"1.187557146","rc":[{"trd":[[1.33,13.58]],"batl":[[0,1.33,201.95]],"ltp":1.33,"tv":731.21,"id":8257797}],"tv":879.32}]}
{"op":"mcm","clk":"4230063271","pt":1631528453994,"mc":[{"id":"1.187557146","rc":[{"batb":[[0,3.4,26.63],[1,3,1.2],[2,2.2,42.7]],"batl":[[0,5,11],[1,4.5,0],[2,5,0]],"ltp":3.9,"tv":148.11,"id":19931652},{"batb":[[0,1.27,128.8],[1,1.18,558.4],[2,1.17,313.93]],"batl":[[0,1.58,660.85],[1,8.8,7.24],[2,44,7.24]],"ltp":1.33,"tv":731.21,"id":8257797}]}]}
{"op":"mcm","clk":"4230063996","pt":1631528465177,"mc":[{"id":"1.187557146","rc":[{"batb":[[0,1.4,2.17],[1,1.27,128.8],[2,1.18,558.4]],"ltp":1.33,"tv":731.21,"id":8257797}]}]}
{"op":"mcm","clk":"4230064434","pt":1631528472412,"mc":[{"id":"1.187557146","rc":[{"batb":[[0,1.27,128.8],[1,1.18,558.4],[2,1.17,313.93]],"ltp":1.33,"tv":731.21,"id":8257797}]}]}
{"op":"mcm","clk":"4230065077","pt":1631528481318,"mc":[{"id":"1.187557146","rc":[{"batb":[[0,3.95,10.12],[1,3.4,26.63],[2,3,1.2]],"batl":[[0,4.4,5.83],[1,4.7,42.53],[2,5,11]],"ltp":3.9,"tv":148.11,"id":19931652},{"batb":[[1,1.17,313.93],[2,1.11,269.53]],"batl":[[0,1.31,188.61],[1,1.58,660.85],[2,8.8,7.24]],"ltp":1.33,"tv":731.21,"id":8257797}]}]}
{"op":"mcm","clk":"4230065159","pt":1631528482307,"mc":[{"id":"1.187557146","rc":[{"batb":[[1,3.75,40.87],[2,3.55,23.36]],"ltp":3.9,"tv":148.11,"id":19931652},{"trd":[[1.31,6.74]],"batb":[[1,1.25,138.26],[2,1.17,313.93]],"batl":[[0,1.31,186.44]],"ltp":1.31,"tv":735.56,"id":8257797}],"tv":883.67}]}
{"op":"mcm","clk":"4230065487","pt":1631528488131,"mc":[{"id":"1.187557146","rc":[{"trd":[[4.4,51.26]],"batl":[[0,4.4,4.53]],"ltp":4.4,"tv":149.41,"id":19931652},{"trd":[[1.29,37.72]],"ltp":1.29,"tv":740.0,"id":8257797}],"tv":889.41}]}
{"op":"mcm","clk":"4230065556","pt":1631528489316,"mc":[{"id":"1.187557146","rc":[{"batb":[[0,1.29,84],[1,1.27,128.8],[2,1.25,138.26]],"ltp":1.29,"tv":740.0,"id":8257797}]}]}
{"op":"mcm","clk":"4230065913","pt":1631528494327,"mc":[{"id":"1.187557146","rc":[{"batb":[[0,3.55,23.36],[1,3,1.2],[2,2.2,42.7]],"batl":[[0,5,11],[1,4.7,0],[2,5,0]],"ltp":4.4,"tv":149.41,"id":19931652},{"batb":[[0,1.25,138.26],[1,1.17,313.93],[2,1.14,637.83]],"batl":[[0,1.58,660.85],[1,8.8,7.24],[2,44,7.24]],"ltp":1.29,"tv":740.0,"id":8257797}]}]}
{"op":"mcm","clk":"4230066363","pt":1631528501457,"mc":[{"id":"1.187557146","rc":[{"batb":[[2,1.11,269.53]],"ltp":1.29,"tv":740.0,"id":8257797}]}]}
{"op":"mcm","clk":"4230066493","pt":1631528503173,"mc":[{"id":"1.187557146","rc":[{"batb":[[0,4.4,4.21],[1,3.55,23.36],[2,3,1.2]],"batl":[[0,5,46.53]],"ltp":4.4,"tv":149.41,"id":19931652},{"batb":[[0,1.28,16.2],[1,1.25,280.39],[2,1.17,313.93]],"batl":[[0,1.31,378.48],[1,1.58,660.85],[2,8.8,7.24]],"ltp":1.29,"tv":740.0,"id":8257797}]}]}
{"op":"mcm","clk":"4230066575","pt":1631528504266,"mc":[{"id":"1.187557146","rc":[{"batb":[[1,3.9,36.93],[2,3.7,42.29]],"ltp":4.4,"tv":149.41,"id":19931652},{"batb":[[2,1.24,145.55]],"ltp":1.29,"tv":740.0,"id":8257797}]}]}
{"op":"mcm","clk":"4230066650","pt":1631528505351,"mc":[{"id":"1.187557146","rc":[{"trd":[[4.4,51.9]],"batb":[[0,4.4,3.57]],"ltp":4.4,"tv":150.05,"id":19931652},{"trd":[[1.3,2.17]],"ltp":1.3,"tv":742.17,"id":8257797}],"tv":892.22}]}
{"op":"mcm","clk":"4230066955","pt":1631528510171,"mc":[{"id":"1.187557146","rc":[{"batb":[[0,3.7,42.29],[1,3,1.2],[2,2.2,42.7]],"batl":[[0,5,11]],"ltp":4.4,"tv":150.05,"id":19931652},{"batb":[[0,1.24,145.55],[1,1.17,313.93],[2,1.13,639.92]],"batl":[[0,1.58,660.85],[1,8.8,7.24],[2,44,7.24]],"ltp":1.3,"tv":742.17,"id":8257797}]}]}
{"op":"mcm","clk":"4230067101","pt":1631528512239,"mc":[{"id":"1.187557146","rc":[{"batl":[[0,1.28,37.47],[1,1.58,660.85],[2,8.8,7.24]],"ltp":1.3,"tv":742.17,"id":8257797}]}]}
{"op":"mcm","clk":"4230067162","pt":1631528513263,"mc":[{"id":"1.187557146","rc":[{"batl":[[0,1.28,53.68]],"ltp":1.3,"tv":742.17,"id":8257797}]}]}
{"op":"mcm","clk":"4230067234","pt":1631528514354,"mc":[{"id":"1.187557146","rc":[{"batl":[[0,1.28,16.21]],"ltp":1.3,"tv":742.17,"id":8257797}]}]}
{"op":"mcm","clk":"4230067276","pt":1631528514968,"mc":[{"id":"1.187557146","rc":[{"batb":[[2,2.6,3.71]],"ltp":4.4,"tv":150.05,"id":19931652},{"batl":[[0,1.58,660.93],[1,8.8,7.24],[2,44,7.24]],"ltp":1.3,"tv":742.17,"id":8257797}]}]}
{"op":"mcm","clk":"4230067523","pt":1631528519356,"mc":[{"id":"1.187557146","rc":[{"trd":[[5,0.56]],"batl":[[0,5,10.44]],"ltp":5.0,"tv":150.61,"id":19931652},{"trd":[[1.25,2.26]],"ltp":1.25,"tv":744.43,"id":8257797}],"tv":895.04}]}
{"op":"mcm","clk":"4230067908","pt":1631528524894,"mc":[{"id":"1.187557146","rc":[{"batb":[[0,4.5,5],[1,4.3,9.3],[2,3.7,42.29]],"batl":[[0,4.7,4.61],[1,5,27.37]],"ltp":5.0,"tv":150.61,"id":19931652},{"batb":[[0,1.25,67.71],[1,1.24,145.55],[2,1.17,313.93]],"batl":[[0,1.3,369.93]],"ltp":1.25,"tv":744.43,"id":8257797}]}]}
{"op":"mcm","clk":"4230068019","pt":1631528526353,"mc":[{"id":"1.187557146","rc":[{"batb":[[2,4,34.34]],"ltp":5.0,"tv":150.61,"id":19931652},{"batb":[[2,1.22,160.96]],"ltp":1.25,"tv":744.43,"id":8257797}]}]}
{"op":"mcm","clk":"4230068120","pt":1631528528065,"mc":[{"id":"1.187557146","rc":[{"trd":[[4.7,9.22],[5,2.02]],"batl":[[0,5,26.64],[1,5,0]],"ltp":5.0,"tv":161.28,"id":19931652}],"tv":905.71}]}
{"op":"mcm","clk":"4230068208","pt":1631528529259,"mc":[{"id":"1.187557146","rc":[{"trd":[[4.5,5.18]],"batb":[[0,4.7,4.59],[1,4.5,4.4],[2,4.3,9.3]],"ltp":4.5,"tv":161.88,"id":19931652},{"trd":[[1.28,16.27],[1.29,39.81]],"batl":[[0,1.3,369.85],[1,1.49,773.7],[2,8.8,7.24]],"ltp":1.29,"tv":746.68,"id":8257797}],"tv":908.56}]}
{"op":"mcm","clk":"4230068264","pt":1631528530280,"mc":[{"id":"1.187557146","rc":[{"trd":[[4.6,5.34],[4.7,22.99]],"batb":[[0,4.7,1.92]],"ltp":4.6,"tv":180.99,"id":19931652},{"trd":[[1.27,21.53]],"batl":[[0,1.27,84.95],[1,1.3,369.85],[2,1.49,773.7]],"ltp":1.27,"tv":763.66,"id":8257797}],"tv":944.66}]}
{"op":"mcm","clk":"4230068336","pt":1631528531276,"mc":[{"id":"1.187557146","rc":[{"batb":[[0,4.7,4.59]],"ltp":4.6,"tv":180.99,"id":19931652},{"batl":[[0,1.27,322.74]],"ltp":1.27,"tv":763.66,"id":8257797}]}]}
{"op":"mcm","clk":"4230068425","pt":1631528532304,"mc":[{"id":"1.187557146","rc":[{"batl":[[0,1.27,101.94]],"ltp":1.27,"tv":763.66,"id":8257797}]}]}
{"op":"mcm","clk":"4230068463","pt":1631528532670,"mc":[{"id":"1.187557146","rc":[{"trd":[[5,19.08]],"batb":[[0,4.5,4.4],[1,4.3,9.3],[2,4,34.34]],"batl":[[0,5,18.11]],"ltp":5.0,"tv":198.06,"id":19931652},{"batl":[[0,1.27,17]],"ltp":1.27,"tv":763.66,"id":8257797}],"tv":961.73}]}
{"op":"mcm","clk":"4230068507","pt":1631528533385,"mc":[{"id":"1.187557146","rc":[{"batl":[[0,1.3,369.85],[1,1.49,773.7],[2,8.8,7.24]],"ltp":1.27,"tv":763.66,"id":8257797}]}]}
{"op":"mcm","clk":"4230068604","pt":1631528534681,"mc":[{"id":"1.187557146","rc":[{"trd":[[1.25,6.74]],"batb":[[0,1.25,65.47]],"ltp":1.25,"tv":768.15,"id":8257797}],"tv":966.21}]}
{"op":"mcm","clk":"4230068762","pt":1631528537069,"mc":[{"id":"1.187557146","rc":[{"trd":[[5,31.5]],"batl":[[0,5,5.69]],"ltp":5.0,"tv":210.48,"id":19931652},{"trd":[[1.25,187.43]],"batb":[[0,1.24,145.55],[1,1.22,160.96],[2,1.11,964.65]],"ltp":1.25,"tv":948.84,"id":8257797}],"tv":1159.32}]}
{"op":"mcm","clk":"4230068837","pt":1631528538298,"mc":[{"id":"1.187557146","rc":[{"trd":[[5,42.16]],"batb":[[0,4.3,9.3],[1,4,34.34],[2,3.9,37.35]],"batl":[[0,5,0.36]],"ltp":5.0,"tv":221.14,"id":19931652}],"tv":1169.98}]}
{"op":"mcm","clk":"4230069017","pt":1631528541198,"mc":[{"id":"1.187557146","rc":[{"batl":[[0,4.8,5.08],[1,5,0.36]],"ltp":5.0,"tv":221.14,"id":19931652},{"batl":[[0,1.28,20],[1,1.3,369.85],[2,1.49,773.7]],"ltp":1.25,"tv":948.84,"id":8257797}]}]}
{"op":"mcm","clk":"4230069031","pt":1631528541409,"mc":[{"id":"1.187557146","rc":[{"batl":[[0,5,0.36],[1,5,0]],"ltp":5.0,"tv":221.14,"id":19931652},{"batl":[[0,1.3,369.85],[1,1.49,773.7],[2,8.8,7.24]],"ltp":1.25,"tv":948.84,"id":8257797}]}]}
{"op":"mcm","clk":"4230069234","pt":1631528544303,"mc":[{"id":"1.187557146","rc":[{"batl":[[0,4.8,5.08],[1,5,0.36]],"ltp":5.0,"tv":221.14,"id":19931652},{"batl":[[0,1.28,20],[1,1.3,369.85],[2,1.49,773.7]],"ltp":1.25,"tv":948.84,"id":8257797}]}]}
{"op":"mcm","clk":"4230069344","pt":1631528546211,"mc":[{"id":"1.187557146","rc":[{"batb":[[0,4,34.34],[1,3.9,37.35],[2,3,1.2]],"ltp":5.0,"tv":221.14,"id":19931652},{"batl":[[0,1.49,773.7],[1,8.8,7.24],[2,44,7.24]],"ltp":1.25,"tv":948.84,"id":8257797}]}]}
{"op":"mcm","clk":"4230069369","pt":1631528546578,"mc":[{"id":"1.187557146","rc":[{"batb":[[0,3.9,37.35],[1,3,1.2],[2,2.6,3.71]],"ltp":5.0,"tv":221.14,"id":19931652},{"batb":[[0,1.22,160.96],[1,1.11,964.65],[2,1.1,296.48]],"ltp":1.25,"tv":948.84,"id":8257797}]}]}
{"op":"mcm","clk":"4230069593","pt":1631528550516,"mc":[{"id":"1.187557146","rc":[{"batb":[[1,1.11,269.53]],"ltp":1.25,"tv":948.84,"id":8257797}]}]}
{"op":"mcm","clk":"4230069726","pt":1631528552294,"mc":[{"id":"1.187557146","rc":[{"batb":[[0,4.5,46.62],[1,3.9,37.35],[2,3,1.2]],"batl":[[0,4.7,8.24],[1,5,22.22]],"ltp":5.0,"tv":221.14,"id":19931652},{"batb":[[0,1.26,158.74],[1,1.25,88.86],[2,1.22,160.96]],"batl":[[0,1.29,14.36],[1,1.49,773.7],[2,8.8,7.24]],"ltp":1.25,"tv":948.84,"id":8257797}]}]}
{"op":"mcm","clk":"4230069807","pt":1631528553300,"mc":[{"id":"1.187557146","rc":[{"batb":[[2,3.8,39.78]],"ltp":5.0,"tv":221.14,"id":19931652},{"batb":[[0,1.26,31.74],[1,1.25,226.2],[2,1.23,150.57]],"ltp":1.25,"tv":948.84,"id":8257797}]}]}
{"op":"mcm","clk":"4230070064","pt":1631528557324,"mc":[{"id":"1.187557146","rc":[{"batb":[[0,3.8,39.78],[1,3,1.2],[2,2.6,3.71]],"batl":[[0,4.5,6.52],[1,5,0]],"ltp":5.0,"tv":221.14,"id":19931652},{"batb":[[0,1.23,150.57],[1,1.13,639.92],[2,1.11,269.53]],"batl":[[0,1.32,192.49]],"ltp":1.25,"tv":948.84,"id":8257797}]}]}
{"op":"mcm","clk":"4230070085","pt":1631528557488,"mc":[{"id":"1.187557146","rc":[{"batl":[[0,1.49,773.7],[1,8.8,7.24],[2,44,7.24]],"ltp":1.25,"tv":948.84,"id":8257797}]}]}
{"op":"mcm","clk":"4230070684","pt":1631528566038,"mc":[{"id":"1.187557146","rc":[{"batb":[[0,1.34,2.17],[1,1.23,150.57],[2,1.13,639.92]],"ltp":1.25,"tv":948.84,"id":8257797}]}]}
{"op":"mcm","clk":"4230070776","pt":1631528567230,"mc":[{"id":"1.187557146","rc":[{"batb":[[2,2.2,42.7]],"ltp":5.0,"tv":221.14,"id":19931652}]}]}
{"op":"mcm","clk":"4230071005","pt":1631528570238,"mc":[{"id":"1.187557146","rc":[{"batb":[[2,1.15,355.78]],"ltp":1.25,"tv":948.84,"id":8257797}]}]}
{"op":"mcm","clk":"4230071209","pt":1631528572422,"mc":[{"id":"1.187557146","rc":[{"batb":[[0,1.23,150.57],[1,1.15,355.78],[2,1.13,639.92]],"ltp":1.25,"tv":948.84,"id":8257797}]}]}
{"op":"mcm","clk":"4230071857","pt":1631528581346,"mc":[{"id":"1.187557146","rc":[{"batb":[[0,4.3,4.7],[1,3.8,39.78],[2,3.65,42.88]],"batl":[[0,4.5,6.09],[1,4.7,8.52],[2,4.8,36.72]],"ltp":5.0,"tv":221.14,"id":19931652},{"batb":[[0,1.26,131.4],[1,1.25,140.52],[2,1.23,150.57]],"batl":[[0,1.3,188.83],[1,1.49,773.7],[2,8.8,7.24]],"ltp":1.25,"tv":948.84,"id":8257797}]}]}
{"op":"mcm","clk":"4230071906","pt":1631528582030,"mc":[{"id":"1.187557146","rc":[{"batb":[[2,1.15,355.78]],"ltp":1.25,"tv":948.84,"id":8257797}]}]}
{"op":"mcm","clk":"4230072024","pt":1631528583533,"mc":[{"id":"1.187557146","rc":[{"trd":[[4.5,5.8]],"batl":[[0,4.5,5.47]],"ltp":4.5,"tv":221.76,"id":19931652},{"trd":[[1.28,18.44]],"ltp":1.28,"tv":951.01,"id":8257797}],"tv":1172.77}]}
{"op":"mcm","clk":"4230072435","pt":1631528589350,"mc":[{"id":"1.187557146","rc":[{"batb":[[0,3.8,39.78],[1,3.65,42.88],[2,3,1.2]],"ltp":4.5,"tv":221.76,"id":19931652},{"batl":[[0,1.49,773.7],[1,8.8,7.24],[2,44,7.24]],"ltp":1.28,"tv":951.01,"id":8257797}]}]}
{"op":"mcm","clk":"4230072441","pt":1631528589457,"mc":[{"id":"1.187557146","rc":[{"batb":[[0,3.65,42.88],[1,3,1.2],[2,2.2,42.7]],"ltp":4.5,"tv":221.76,"id":19931652},{"batb":[[0,1.25,140.52],[1,1.15,355.78],[2,1.13,639.92]],"ltp":1.28,"tv":951.01,"id":8257797}]}]}
{"op":"mcm","clk":"4230072703","pt":1631528592248,"mc":[{"id":"1.187557146","rc":[{"batb":[[0,4.5,21.85],[1,3.65,42.88],[2,3,1.2]],"ltp":4.5,"tv":221.76,"id":19931652}]}]}
{"op":"mcm","clk":"4230072780","pt":1631528593070,"mc":[{"id":"1.187557146","rc":[{"batb":[[0,4.5,10.92]],"ltp":4.5,"tv":221.76,"id":19931652}]}]}
{"op":"mcm","clk":"4230072816","pt":1631528593436,"mc":[{"id":"1.187557146","rc":[{"batb":[[0,3.65,42.88],[1,3,1.2],[2,2.2,42.7]],"ltp":4.5,"tv":221.76,"id":19931652}]}]}
{"op":"mcm","clk":"4230072991","pt":1631528595563,"mc":[{"id":"1.187557146","rc":[{"batb":[[2,1.11,269.53]],"ltp":1.28,"tv":951.01,"id":8257797}]}]}
{"op":"mcm","clk":"4230073111","pt":1631528597173,"mc":[{"id":"1.187557146","rc":[{"batb":[[0,4.5,5.26],[1,4.3,131.96],[2,3.65,42.88]],"batl":[[0,4.7,4.51],[1,5.1,48.95]],"ltp":4.5,"tv":221.76,"id":19931652},{"batl":[[0,1.31,30.54],[1,1.49,773.7],[2,8.8,7.24]],"ltp":1.28,"tv":951.01,"id":8257797}]}]}
{"op":"mcm","clk":"4230073179","pt":1631528598161,"mc":[{"id":"1.187557146","rc":[{"batb":[[2,3.95,36.09]],"ltp":4.5,"tv":221.76,"id":19931652},{"batb":[[1,1.23,155.01],[2,1.15,355.78]],"ltp":1.28,"tv":951.01,"id":8257797}]}]}
{"op":"mcm","clk":"4230073271","pt":1631528599359,"mc":[{"id":"1.187557146","rc":[{"trd":[[4.7,23.58]],"batl":[[0,4.7,3.92]],"ltp":4.7,"tv":222.35,"id":19931652},{"trd":[[1.27,23.7]],"ltp":1.27,"tv":953.18,"id":8257797}],"tv":1175.53}]}
{"op":"mcm","clk":"4230073585","pt":1631528603867,"mc":[{"id":"1.187557146","rc":[{"trd":[[4.7,27.5]],"batl":[[0,5.1,48.95],[1,5.1,0]],"ltp":4.7,"tv":226.27,"id":19931652},{"trd":[[1.27,38.22]],"batl":[[0,1.27,33.04],[1,1.31,30.54],[2,1.49,773.7]],"ltp":1.27,"tv":967.7,"id":8257797}],"tv":1193.97}]}
{"op":"mcm","clk":"4230073640","pt":1631528604592,"mc":[{"id":"1.187557146","rc":[{"batb":[[2,1.11,964.65]],"batl":[[0,1.31,30.54],[1,1.49,773.7],[2,8.8,7.24]],"ltp":1.27,"tv":967.7,"id":8257797}]}]}
{"op":"mcm","clk":"4230073769","pt":1631528606157,"mc":[{"id":"1.187557146","rc":[{"trd":[[4.5,8.26]],"batb":[[0,4.6,4.75],[1,4.5,4.03],[2,4.3,131.96]],"ltp":4.5,"tv":228.73,"id":19931652},{"trd":[[1.27,72.35]],"batb":[[0,1.27,105.94],[1,1.25,140.52],[2,1.23,155.01]],"ltp":1.27,"tv":1001.82,"id":8257797}],"tv":1230.56}]}
{"op":"mcm","clk":"4230073869","pt":1631528607356,"mc":[{"id":"1.187557146","rc":[{"batb":[[0,3.8,38.94],[1,3,1.2],[2,2.2,42.7]],"ltp":4.5,"tv":228.73,"id":19931652},{"trd":[[1.27,101.35]],"batb":[[0,1.27,91.44],[1,1.23,155.01],[2,1.11,964.65]],"batl":[[0,1.49,773.7],[1,8.8,7.24],[2,44,7.24]],"ltp":1.27,"tv":1030.83,"id":8257797}],"tv":1259.57}]}
{"op":"mcm","clk":"4230073941","pt":1631528608176,"mc":[{"id":"1.187557146","rc":[{"batb":[[2,2.6,3.71]],"ltp":4.5,"tv":228.73,"id":19931652},{"batb":[[0,1.23,155.01],[1,1.11,964.65],[2,1.1,296.48]],"ltp":1.27,"tv":1030.83,"id":8257797}]}]}
{"op":"mcm","clk":"4230074066","pt":1631528609782,"mc":[{"id":"1.187557146","rc":[{"batb":[[0,5,8.53],[1,3.8,38.94],[2,3,1.2]],"ltp":4.5,"tv":228.73,"id":19931652},{"batb":[[1,1.11,695.13],[2,1.06,494.14]],"ltp":1.27,"tv":1030.83,"id":8257797}]}]}
{"op":"mcm","clk":"4230074134","pt":1631528610765,"mc":[{"id":"1.187557146","rc":[{"batb":[[0,3.8,38.94],[1,3,1.2],[2,2.6,3.71]],"ltp":4.5,"tv":228.73,"id":19931652}]}]}
{"op":"mcm","clk":"4230074202","pt":1631528611865,"mc":[{"id":"1.187557146","rc":[{"batb":[[0,4.8,4.49],[1,3.8,38.94],[2,3,1.2]],"ltp":4.5,"tv":228.73,"id":19931652}]}]}
{"op":"mcm","clk":"4230074329","pt":1631528613267,"mc":[{"id":"1.187557146","rc":[{"batb":[[0,3.8,38.94],[1,3,7.13],[2,2.6,3.71]],"ltp":4.5,"tv":228.73,"id":19931652},{"batl":[[0,1.25,29.95],[1,1.49,773.7],[2,8.8,7.24]],"ltp":1.27,"tv":1030.83,"id":8257797}]}]}
{"op":"mcm","clk":"4230074451","pt":1631528614771,"mc":[{"id":"1.187557146","rc":[{"batl":[[1,1.49,774.6]],"ltp":1.27,"tv":1030.83,"id":8257797}]}]}
{"op":"mcm","clk":"4230074616","pt":1631528617071,"mc":[{"id":"1.187557146","rc":[{"batb":[[0,1.24,261],[1,1.23,155.01],[2,1.11,695.13]],"ltp":1.27,"tv":1030.83,"id":8257797}]}]}
{"op":"mcm","clk":"4230075300","pt":1631528627089,"mc":[{"id":"1.187557146","rc":[{"batb":[[0,1.23,155.01],[1,1.11,695.13],[2,1.06,494.14]],"ltp":1.27,"tv":1030.83,"id":8257797}]}]}
{"op":"mcm","clk":"4230075362","pt":1631528627973,"mc":[{"id":"1.187557146","rc":[{"trd":[[1.25,193.75]],"batl":[[0,1.25,26.79]],"ltp":1.25,"tv":1037.15,"id":8257797}],"tv":1265.89}]}
{"op":"mcm","clk":"4230075590","pt":1631528631393,"mc":[{"id":"1.187557146","rc":[{"batb":[[1,1.06,494.14],[2,1.05,474.38]],"ltp":1.25,"tv":1037.15,"id":8257797}]}]}
{"op":"mcm","clk":"4230075837","pt":1631528634814,"mc":[{"id":"1.187557146","rc":[{"batb":[[1,1.13,639.92],[2,1.06,494.14]],"ltp":1.25,"tv":1037.15,"id":8257797}]}]}
{"op":"mcm","clk":"4230075907","pt":1631528635704,"mc":[{"id":"1.187557146","rc":[{"trd":[[5,45.64]],"batb":[[0,4.8,45.76],[1,4.6,8.7],[2,3.8,38.94]],"ltp":5.0,"tv":232.21,"id":19931652},{"trd":[[1.25,207.67]],"batb":[[0,1.23,335.05],[1,1.06,494.14],[2,1.05,474.38]],"batl":[[0,1.25,12.87]],"ltp":1.25,"tv":1051.07,"id":8257797}],"tv":1283.29}]}
{"op":"mcm","clk":"4230075985","pt":1631528636692,"mc":[{"id":"1.187557146","rc":[{"batb":[[2,4.1,31.32]],"ltp":5.0,"tv":232.21,"id":19931652},{"batb":[[1,1.2,173.69],[2,1.06,494.14]],"ltp":1.25,"tv":1051.07,"id":8257797}]}]}
{"op":"mcm","clk":"4230076151","pt":1631528639017,"mc":[{"id":"1.187557146","rc":[{"batb":[[2,1.11,695.13]],"ltp":1.25,"tv":1051.07,"id":8257797}]}]}
{"op":"mcm","clk":"4230076263","pt":1631528640728,"mc":[{"id":"1.187557146","rc":[{"trd":[[4.8,6.8],[5,48.86]],"batb":[[0,4.8,42.36]],"ltp":4.8,"tv":242.23,"id":19931652},{"trd":[[1.25,220.54]],"batl":[[0,1.49,774.6],[1,8.8,7.24],[2,44,7.24]],"ltp":1.25,"tv":1063.94,"id":8257797}],"tv":1306.18}]}
{"op":"mcm","clk":"4230076624","pt":1631528645352,"mc":[{"id":"1.187557146","rc":[{"batl":[[0,1.42,21.48],[1,1.49,773.7],[2,8.8,7.24]],"ltp":1.25,"tv":1063.94,"id":8257797}]}]}
{"op":"mcm","clk":"4230076657","pt":1631528645718,"mc":[{"id":"1.187557146","rc":[{"batb":[[0,4.8,40.68]],"ltp":4.8,"tv":242.23,"id":19931652}]}]}
{"op":"mcm","clk":"4230076812","pt":1631528647737,"mc":[{"id":"1.187557146","rc":[{"batb":[[0,4.6,8.7],[1,4,34.84],[2,3,7.13]],"ltp":4.8,"tv":242.23,"id":19931652},{"batb":[[0,1.2,173.69],[1,1.11,695.13],[2,1.06,494.14]],"batl":[[0,1.49,774.6],[1,8.8,7.24],[2,44,7.24]],"ltp":1.25,"tv":1063.94,"id":8257797}]}]}
{"op":"mcm","clk":"4230078068","pt":1631528666140,"mc":[{"id":"1.187557146","rc":[{"batb":[[1,1.06,494.14],[2,1.05,474.38]],"ltp":1.25,"tv":1063.94,"id":8257797}]}]}
{"op":"mcm","clk":"4230078141","pt":1631528667281,"mc":[{"id":"1.187557146","rc":[{"batl":[[0,5,741.78],[1,5.1,34.21],[2,5.6,3.18]],"ltp":4.8,"tv":242.23,"id":19931652},{"batb":[[0,1.26,18.61],[1,1.2,173.69],[2,1.06,494.14]],"batl":[[0,1.28,242.13],[1,1.49,773.7],[2,8.8,7.24]],"ltp":1.25,"tv":1063.94,"id":8257797}]}]}
{"op":"mcm","clk":"4230078153","pt":1631528667488,"mc":[{"id":"1.187557146","rc":[{"batb":[[2,3,1.2]],"batl":[[0,5.1,34.21],[1,5.1,0],[2,5.6,0]],"ltp":4.8,"tv":242.23,"id":19931652}]}]}
{"op":"mcm","clk":"4230078242","pt":1631528668678,"mc":[{"id":"1.187557146","rc":[{"batb":[[2,3.85,38.1]],"ltp":4.8,"tv":242.23,"id":19931652},{"batb":[[1,1.24,143.96],[2,1.22,156.18]],"ltp":1.25,"tv":1063.94,"id":8257797}]}]}
{"op":"mcm","clk":"4230078515","pt":1631528672352,"mc":[{"id":"1.187557146","rc":[{"trd":[[4.6,13.82],[4.7,27.74],[4.9,4.79]],"batb":[[0,4.6,4.46]],"ltp":4.6,"tv":255.74,"id":19931652},{"trd":[[1.26,18.61],[1.27,102.25]],"batb":[[0,1.24,143.96],[1,1.22,156.18],[2,1.13,639.92]],"batl":[[0,1.28,241.23]],"ltp":1.27,"tv":1083.45,"id":8257797}],"tv":1339.2}]}
{"op":"mcm","clk":"4230078713","pt":1631528675294,"mc":[{"id":"1.187557146","rc":[{"batb":[[0,1.24,216.96]],"ltp":1.27,"tv":1083.45,"id":8257797}]}]}
{"op":"mcm","clk":"4230079051","pt":1631528680260,"mc":[{"id":"1.187557146","rc":[{"batb":[[0,4,34.84],[1,3.85,38.1],[2,3,1.2]],"ltp":4.6,"tv":255.74,"id":19931652},{"batb":[[0,1.24,143.96]],"batl":[[0,1.49,773.7],[1,8.8,7.24],[2,44,7.24]],"ltp":1.27,"tv":1083.45,"id":8257797}]}]}
{"op":"mcm","clk":"4230079134","pt":1631528681292,"mc":[{"id":"1.187557146","rc":[{"batb":[[0,3.85,38.1],[1,3,1.2],[2,2.6,3.71]],"ltp":4.6,"tv":255.74,"id":19931652},{"batb":[[0,1.22,156.18],[1,1.13,639.92],[2,1.06,494.14]],"ltp":1.27,"tv":1083.45,"id":8257797}]}]}
{"op":"mcm","clk":"4230080152","pt":1631528697314,"mc":[{"id":"1.187557146","rc":[{"batb":[[0,4.5,36.29],[1,3.85,38.1],[2,3,1.2]],"batl":[[0,4.8,5.46],[1,5,27.23]],"ltp":4.6,"tv":255.74,"id":19931652},{"batb":[[0,1.26,31.74],[1,1.25,108.9],[2,1.22,156.18]],"batl":[[0,1.28,19.88],[1,1.49,773.7],[2,8.8,7.24]],"ltp":1.27,"tv":1083.45,"id":8257797}]}]}
{"op":"mcm","clk":"4230080177","pt":1631528697625,"mc":[{"id":"1.187557146","rc":[{"batb":[[2,3.6,22.61]],"ltp":4.6,"tv":255.74,"id":19931652},{"batb":[[1,1.25,244.32],[2,1.24,145.63]],"ltp":1.27,"tv":1083.45,"id":8257797}]}]}
{"op":"mcm","clk":"4230080529","pt":1631528702302,"mc":[{"id":"1.187557146","rc":[{"trd":[[4.8,17.72]],"batb":[[0,4.8,42.26],[1,4.5,36.29],[2,3.85,38.1]],"batl":[[0,5,27.23],[1,5,0]],"ltp":4.8,"tv":266.66,"id":19931652}],"tv":1350.12}]}
{"op":"mcm","clk":"4230080562","pt":1631528702608,"mc":[{"id":"1.187557146","rc":[{"batb":[[0,4.5,36.29],[1,3.85,38.1],[2,3.6,22.61]],"ltp":4.8,"tv":266.66,"id":19931652}]}]}
{"op":"mcm","clk":"4230080729","pt":1631528704731,"mc":[{"id":"1.187557146","rc":[{"batb":[[0,1.27,180],[1,1.26,31.74],[2,1.25,244.32]],"ltp":1.27,"tv":1083.45,"id":8257797}]}]}
{"op":"mcm","clk":"4230080835","pt":1631528706030,"mc":[{"id":"1.187557146","rc":[{"trd":[[4.8,58.9]],"ltp":4.8,"tv":307.84,"id":19931652},{"trd":[[1.27,257.89]],"batb":[[0,1.27,24.36]],"ltp":1.27,"tv":1239.09,"id":8257797}],"tv":1546.94}]}
{"op":"mcm","clk":"4230081135","pt":1631528710117,"mc":[{"id":"1.187557146","rc":[{"batb":[[0,1.27,180]],"ltp":1.27,"tv":1239.09,"id":8257797}]}]}
{"op":"mcm","clk":"4230081325","pt":1631528712506,"mc":[{"id":"1.187557146","rc":[{"batl":[[0,1.49,773.7],[1,8.8,7.24],[2,44,7.24]],"ltp":1.27,"tv":1239.09,"id":8257797}]}]}
{"op":"mcm","clk":"4230081597","pt":1631528715608,"mc":[{"id":"1.187557146","rc":[{"batl":[[0,5,31.64]],"ltp":4.8,"tv":307.84,"id":19931652},{"trd":[[1.27,291.93]],"batb":[[0,1.27,162.98],[2,1.25,261.96]],"batl":[[0,1.44,22.55],[1,1.49,773.7],[2,8.8,7.24]],"ltp":1.27,"tv":1273.13,"id":8257797}],"tv":1580.98}]}
{"op":"mcm","clk":"4230082154","pt":1631528722345,"mc":[{"id":"1.187557146","rc":[{"trd":[[4.8,102.02]],"batb":[[0,4.8,28.81],[1,4.5,36.29],[2,3.85,38.1]],"ltp":4.8,"tv":350.96,"id":19931652},{"trd":[[1.27,454.91]],"batb":[[0,1.26,31.74],[1,1.25,261.96],[2,1.24,145.63]],"ltp":1.27,"tv":1436.11,"id":8257797}],"tv":1787.08}]}
{"op":"mcm","clk":"4230082174","pt":1631528722554,"mc":[{"id":"1.187557146","rc":[{"batb":[[0,4.5,36.29],[1,3.85,38.1],[2,3.6,22.61]],"ltp":4.8,"tv":350.96,"id":19931652}]}]}
{"op":"mcm","clk":"4230082422","pt":1631528726151,"mc":[{"id":"1.187557146","rc":[{"batl":[[0,5,27.23]],"ltp":4.8,"tv":350.96,"id":19931652},{"batb":[[0,1.26,148.74],[1,1.25,244.32]],"ltp":1.27,"tv":1436.11,"id":8257797}]}]}
{"op":"mcm","clk":"4230082478","pt":1631528727031,"mc":[{"id":"1.187557146","rc":[{"trd":[[4.9,32.44]],"ltp":4.9,"tv":378.61,"id":19931652},{"trd":[[1.26,126.14]],"batb":[[0,1.26,41.21]],"ltp":1.26,"tv":1543.64,"id":8257797}],"tv":1922.26}]}
{"op":"mcm","clk":"4230082628","pt":1631528729060,"mc":[{"id":"1.187557146","rc":[{"batl":[[0,4.8,4.5],[1,5,27.23]],"ltp":4.9,"tv":378.61,"id":19931652},{"batl":[[0,1.28,23.47]],"ltp":1.26,"tv":1543.64,"id":8257797}]}]}
{"op":"mcm","clk":"4230082810","pt":1631528731142,"mc":[{"id":"1.187557146","rc":[{"batb":[[0,1.26,117]],"ltp":1.26,"tv":1543.64,"id":8257797}]}]}
{"op":"mcm","clk":"4230087005","pt":1631528793239,"mc":[{"id":"1.187557146","rc":[{"batb":[[0,3.6,22.61],[1,3,1.2],[2,2.6,3.71]],"ltp":4.9,"tv":378.61,"id":19931652},{"batb":[[0,1.24,145.63],[1,1.13,639.92],[2,1.06,494.14]],"batl":[[0,1.49,773.7],[1,8.8,7.24],[2,44,7.24]],"ltp":1.26,"tv":1543.64,"id":8257797}]}]}
{"op":"mcm","clk":"4230087392","pt":1631528799054,"mc":[{"id":"1.187557146","rc":[{"batb":[[1,1.06,494.14],[2,1.05,474.38]],"ltp":1.26,"tv":1543.64,"id":8257797}]}]}
{"op":"mcm","clk":"4230087457","pt":1631528800247,"mc":[{"id":"1.187557146","rc":[{"batb":[[0,4.8,4.84],[1,3.6,22.61],[2,3,1.2]],"batl":[[0,5,3.9]],"ltp":4.9,"tv":378.61,"id":19931652},{"batb":[[0,1.24,306.89]],"batl":[[0,1.28,249.48],[1,1.29,31],[2,1.49,773.7]],"ltp":1.26,"tv":1543.64,"id":8257797}]}]}
{"op":"mcm","clk":"4230087511","pt":1631528800978,"mc":[{"id":"1.187557146","rc":[{"batb":[[1,4,34.34],[2,3.75,41.2]],"ltp":4.9,"tv":378.61,"id":19931652},{"batb":[[1,1.22,157.61],[2,1.06,494.14]],"ltp":1.26,"tv":1543.64,"id":8257797}]}]}
{"op":"mcm","clk":"4230087690","pt":1631528803564,"mc":[{"id":"1.187557146","rc":[{"batb":[[2,1.11,695.13]],"ltp":1.26,"tv":1543.64,"id":8257797}]}]}
{"op":"mcm","clk":"4230087809","pt":1631528805087,"mc":[{"id":"1.187557146","rc":[{"trd":[[4.8,111.7]],"batb":[[0,4,34.34],[1,3.75,41.2],[2,3,1.2]],"ltp":4.8,"tv":388.29,"id":19931652}],"tv":1931.94}]}
{"op":"mcm","clk":"4230087936","pt":1631528806767,"mc":[{"id":"1.187557146","rc":[{"batb":[[0,1.24,145.63]],"batl":[[0,1.49,773.7],[1,8.8,7.24],[2,44,7.24]],"ltp":1.26,"tv":1543.64,"id":8257797}]}]}
{"op":"mcm","clk":"4230088037","pt":1631528808159,"mc":[{"id":"1.187557146","rc":[{"batb":[[0,3.75,41.2],[1,3,1.2],[2,2.6,3.71]],"ltp":4.8,"tv":388.29,"id":19931652},{"batb":[[0,1.27,197]],"ltp":1.26,"tv":1543.64,"id":8257797}]}]}
{"op":"mcm","clk":"4230088055","pt":1631528808373,"mc":[{"id":"1.187557146","rc":[{"batb":[[0,1.22,157.61],[1,1.11,695.13],[2,1.06,494.14]],"ltp":1.26,"tv":1543.64,"id":8257797}]}]}
{"op":"mcm","clk":"4230088419","pt":1631528813567,"mc":[{"id":"1.187557146","rc":[{"batb":[[1,1.06,494.14],[2,1.05,474.38]],"ltp":1.26,"tv":1543.64,"id":8257797}]}]}
{"op":"mcm","clk":"4230088602","pt":1631528815862,"mc":[{"id":"1.187557146","rc":[{"batb":[[0,4.6,8.7],[1,3.75,41.2],[2,3,1.2]],"ltp":4.8,"tv":388.29,"id":19931652},{"batb":[[0,1.23,143.9],[1,1.22,157.61],[2,1.06,494.14]],"batl":[[0,1.27,293.16],[1,1.49,773.7],[2,8.8,7.24]],"ltp":1.26,"tv":1543.64,"id":8257797}]}]}
{"op":"mcm","clk":"4230088682","pt":1631528816800,"mc":[{"id":"1.187557146","rc":[{"batb":[[1,4.2,30.57],[2,3.9,36.76]],"ltp":4.8,"tv":388.29,"id":19931652},{"batb":[[2,1.21,167.49]],"ltp":1.26,"tv":1543.64,"id":8257797}]}]}
{"op":"mcm","clk":"4230088816","pt":1631528818300,"mc":[{"id":"1.187557146","rc":[{"trd":[[1.23,209.81]],"batb":[[0,1.23,39.02]],"ltp":1.23,"tv":1753.46,"id":8257797}],"tv":2141.75}]}
{"op":"mcm","clk":"4230088849","pt":1631528818664,"mc":[{"id":"1.187557146","rc":[{"batl":[[0,5.1,4.65]],"ltp":4.8,"tv":388.29,"id":19931652},{"batl":[[0,1.26,22.72],[1,1.27,293.16],[2,1.49,773.7]],"ltp":1.23,"tv":1753.46,"id":8257797}]}]}
{"op":"mcm","clk":"4230089017","pt":1631528820808,"mc":[{"id":"1.187557146","rc":[{"trd":[[4.8,117.66]],"ltp":4.8,"tv":394.25,"id":19931652},{"trd":[[1.26,148.86]],"batl":[[0,1.27,293.16],[1,1.49,773.7],[2,8.8,7.24]],"ltp":1.26,"tv":1776.18,"id":8257797}],"tv":2170.43}]}
{"op":"mcm","clk":"4230089131","pt":1631528822211,"mc":[{"id":"1.187557146","rc":[{"batb":[[0,1.24,110],[1,1.23,39.02],[2,1.22,157.61]],"ltp":1.26,"tv":1776.18,"id":8257797}]}]}
{"op":"mcm","clk":"4230089267","pt":1631528824297,"mc":[{"id":"1.187557146","rc":[{"batb":[[0,3.9,36.76],[1,3,1.2],[2,2.6,3.71]],"ltp":4.8,"tv":394.25,"id":19931652},{"batb":[[0,1.21,167.49],[1,1.09,791.35],[2,1.06,494.14]],"batl":[[0,1.49,773.7],[1,8.8,7.24],[2,44,7.24]],"ltp":1.26,"tv":1776.18,"id":8257797}]}]}
{"op":"mcm","clk":"4230089378","pt":1631528825804,"mc":[{"id":"1.187557146","rc":[{"batl":[[0,1.24,34.14],[1,1.49,773.7],[2,8.8,7.24]],"ltp":1.26,"tv":1776.18,"id":8257797}]}]}
{"op":"mcm","clk":"4230089462","pt":1631528826994,"mc":[{"id":"1.187557146","rc":[{"batb":[[1,1.06,494.14],[2,1.05,474.38]],"batl":[[0,1.49,773.7],[1,8.8,7.24],[2,44,7.24]],"ltp":1.26,"tv":1776.18,"id":8257797}]}]}
{"op":"mcm","clk":"4230089619","pt":1631528828914,"mc":[{"id":"1.187557146","rc":[{"batb":[[1,3,7.13]],"ltp":4.8,"tv":394.25,"id":19931652}]}]}
{"op":"mcm","clk":"4230089762","pt":1631528830893,"mc":[{"id":"1.187557146","rc":[{"batb":[[1,1.11,695.13],[2,1.06,494.14]],"ltp":1.26,"tv":1776.18,"id":8257797}]}]}
{"op":"mcm","clk":"4230090286","pt":1631528838021,"mc":[{"id":"1.187557146","rc":[{"batb":[[1,1.06,494.14],[2,1.05,474.38]],"ltp":1.26,"tv":1776.18,"id":8257797}]}]}
{"op":"mcm","clk":"4230090456","pt":1631528840318,"mc":[{"id":"1.187557146","rc":[{"batb":[[0,4.6,8.7],[1,4.3,27.97],[2,4.1,32.91]],"batl":[[0,5.1,3.58],[1,5.7,41.51]],"ltp":4.8,"tv":394.25,"id":19931652},{"batb":[[1,1.2,175.86],[2,1.06,494.14]],"batl":[[0,1.26,26.02],[1,1.27,548.33],[2,1.49,773.7]],"ltp":1.26,"tv":1776.18,"id":8257797}]}]}
{"op":"mcm","clk":"4230090618","pt":1631528842246,"mc":[{"id":"1.187557146","rc":[{"batb":[[2,1.09,791.35]],"ltp":1.26,"tv":1776.18,"id":8257797}]}]}
{"op":"mcm","clk":"4230090976","pt":1631528846317,"mc":[{"id":"1.187557146","rc":[{"trd":[[5.1,3.58]],"batb":[[0,5.1,3.56],[1,4.6,8.7],[2,4.3,27.97]],"batl":[[0,5.7,41.51],[1,5.7,0]],"ltp":5.1,"tv":397.83,"id":19931652},{"trd":[[1.24,14.74]],"batl":[[0,1.24,117.39],[1,1.26,26.02],[2,1.27,548.33]],"ltp":1.24,"tv":1790.92,"id":8257797}],"tv":2188.76}]}
{"op":"mcm","clk":"4230091077","pt":1631528847243,"mc":[{"id":"1.187557146","rc":[{"batl":[[0,1.24,146.84]],"ltp":1.24,"tv":1790.92,"id":8257797}]}]}
{"op":"mcm","clk":"4230091148","pt":1631528848224,"mc":[{"id":"1.187557146","rc":[{"batb":[[0,4.6,8.7],[1,4.3,27.97],[2,4.1,32.91]],"ltp":5.1,"tv":397.83,"id":19931652},{"batl":[[0,1.24,44.08]],"ltp":1.24,"tv":1790.92,"id":8257797}]}]}
{"op":"mcm","clk":"4230091254","pt":1631528849217,"mc":[{"id":"1.187557146","rc":[{"batl":[[0,1.24,29.4]],"ltp":1.24,"tv":1790.92,"id":8257797}]}]}
{"op":"mcm","clk":"4230091323","pt":1631528850315,"mc":[{"id":"1.187557146","rc":[{"batl":[[0,1.24,14.7]],"ltp":1.24,"tv":1790.92,"id":8257797}]}]}
{"op":"mcm","clk":"4230091335","pt":1631528850419,"mc":[{"id":"1.187557146","rc":[{"batl":[[0,1.26,26.02],[1,1.27,548.33],[2,1.49,773.7]],"ltp":1.24,"tv":1790.92,"id":8257797}]}]}
{"op":"mcm","clk":"4230091498","pt":1631528852248,"mc":[{"id":"1.187557146","rc":[{"batb":[[0,4.3,27.97],[1,4.1,32.91],[2,3,7.13]],"ltp":5.1,"tv":397.83,"id":19931652},{"batl":[[0,1.49,773.7],[1,8.8,7.24],[2,44,7.24]],"ltp":1.24,"tv":1790.92,"id":8257797}]}]}
{"op":"mcm","clk":"4230091543","pt":1631528852620,"mc":[{"id":"1.187557146","rc":[{"batb":[[0,4.1,32.91],[1,3,7.13],[2,2.6,3.71]],"ltp":5.1,"tv":397.83,"id":19931652},{"batb":[[0,1.2,175.86],[1,1.09,791.35],[2,1.06,494.14]],"ltp":1.24,"tv":1790.92,"id":8257797}]}]}
{"op":"mcm","clk":"4230091825","pt":1631528856429,"mc":[{"id":"1.187557146","rc":[{"batb":[[1,1.06,494.14],[2,1.05,474.38]],"ltp":1.24,"tv":1790.92,"id":8257797}]}]}
{"op":"mcm","clk":"4230091958","pt":1631528858348,"mc":[{"id":"1.187557146","rc":[{"batb":[[0,4.6,43.48],[1,4.1,32.91],[2,3,7.13]],"batl":[[0,6,32.47]],"ltp":5.1,"tv":397.83,"id":19931652},{"batb":[[0,1.2,338.23]],"batl":[[0,1.24,239.16],[1,1.49,773.7],[2,8.8,7.24]],"ltp":1.24,"tv":1790.92,"id":8257797}]}]}
{"op":"mcm","clk":"4230092034","pt":1631528859239,"mc":[{"id":"1.187557146","rc":[{"batb":[[0,4.6,8.7],[1,4.5,25.96],[2,4.1,32.91]],"ltp":5.1,"tv":397.83,"id":19931652},{"batb":[[0,1.22,45.86],[1,1.2,338.23],[2,1.16,218.41]],"batl":[[1,1.33,42.06],[2,1.49,773.7]],"ltp":1.24,"tv":1790.92,"id":8257797}]}]}
{"op":"mcm","clk":"4230092112","pt":1631528860223,"mc":[{"id":"1.187557146","rc":[{"batb":[[2,4.1,31.66]],"ltp":5.1,"tv":397.83,"id":19931652}]}]}
{"op":"mcm","clk":"4230092345","pt":1631528863254,"mc":[{"id":"1.187557146","rc":[{"trd":[[5.1,10.21]],"ltp":5.1,"tv":404.46,"id":19931652},{"trd":[[1.24,42.01]],"batl":[[0,1.24,211.89],[1,1.28,196.18],[2,1.33,42.06]],"ltp":1.24,"tv":1818.19,"id":8257797}],"tv":2222.66}]}
{"op":"mcm","clk":"4230092368","pt":1631528863463,"mc":[{"id":"1.187557146","rc":[{"batl":[[1,1.33,42.06],[2,1.49,773.7]],"ltp":1.24,"tv":1818.19,"id":8257797}]}]}
{"op":"mcm","clk":"4230092499","pt":1631528865136,"mc":[{"id":"1.187557146","rc":[{"batb":[[0,5.1,5.24],[1,4.6,8.7],[2,4.5,25.96]],"ltp":5.1,"tv":404.46,"id":19931652},{"batb":[[0,1.23,17.01],[1,1.22,135.86],[2,1.2,338.23]],"ltp":1.24,"tv":1818.19,"id":8257797}]}]}
{"op":"mcm","clk":"4230092623","pt":1631528866350,"mc":[{"id":"1.187557146","rc":[{"trd":[[5.4,3.87],[5.6,29.61]],"batb":[[0,5.6,30.6],[1,5.1,5.24],[2,4.6,8.7]],"ltp":5.6,"tv":437.94,"id":19931652},{"trd":[[1.22,135.86],[1.23,226.82]],"batb":[[0,1.2,338.23],[1,1.16,218.41],[2,1.08,837.7]],"ltp":1.22,"tv":1971.05,"id":8257797}],"tv":2409.0}]}
{"op":"mcm","clk":"4230092707","pt":1631528867350,"mc":[{"id":"1.187557146","rc":[{"batb":[[0,5.6,83.69]],"ltp":5.6,"tv":437.94,"id":19931652},{"batl":[[0,1.22,29.87],[1,1.24,211.89],[2,1.33,42.06]],"ltp":1.22,"tv":1971.05,"id":8257797}]}]}
{"op":"mcm","clk":"4230092802","pt":1631528868348,"mc":[{"id":"1.187557146","rc":[{"batb":[[0,5.6,71.72],[1,5.4,3.86],[2,5.1,5.24]],"ltp":5.6,"tv":437.94,"id":19931652},{"batl":[[0,1.24,211.89],[1,1.33,42.06],[2,1.49,773.7]],"ltp":1.22,"tv":1971.05,"id":8257797}]}]}
{"op":"mcm","clk":"4230092897","pt":1631528869343,"mc":[{"id":"1.187557146","rc":[{"batb":[[0,5.6,13.04],[1,5.4,11.58]],"ltp":5.6,"tv":437.94,"id":19931652}]}]}
{"op":"mcm","clk":"4230092990","pt":1631528870339,"mc":[{"id":"1.187557146","rc":[{"batb":[[0,5.1,5.24],[1,4.6,8.7],[2,4.5,25.96]],"batl":[[1,990,0.01]],"ltp":5.6,"tv":437.94,"id":19931652},{"batb":[[0,1.21,235],[1,1.2,338.23],[2,1.16,218.41]],"ltp":1.22,"tv":1971.05,"id":8257797}]}]}
{"op":"mcm","clk":"4230093021","pt":1631528870864,"mc":[{"id":"1.187557146","rc":[{"trd":[[1.21,44.72]],"batb":[[0,1.21,212.64]],"ltp":1.21,"tv":2015.77,"id":8257797}],"tv":2453.72}]}
{"op":"mcm","clk":"4230093374","pt":1631528875579,"mc":[{"id":"1.187557146","rc":[{"batb":[[0,4.6,8.7],[1,4.5,25.96],[2,4.1,31.66]],"ltp":5.6,"tv":437.94,"id":19931652}]}]}
{"op":"mcm","clk":"4230093605","pt":1631528878547,"mc":[{"id":"1.187557146","rc":[{"batl":[[0,5.5,5.23],[1,6,32.47],[2,990,0.01]],"ltp":5.6,"tv":437.94,"id":19931652},{"batl":[[0,1.24,239.91]],"ltp":1.21,"tv":2015.77,"id":8257797}]}]}
{"op":"mcm","clk":"4230094035","pt":1631528884202,"mc":[{"id":"1.187557146","rc":[{"trd":[[5.5,5.23]],"batl":[[0,6,32.47],[1,990,0.01],[2,990,0]],"ltp":5.5,"tv":443.17,"id":19931652},{"trd":[[1.22,159.43]],"ltp":1.22,"tv":2039.35,"id":8257797}],"tv":2482.52}]}
{"op":"mcm","clk":"4230094128","pt":1631528885499,"mc":[{"id":"1.187557146","rc":[{"batb":[[0,5.5,5.21],[1,4.6,8.7],[2,4.5,25.96]],"ltp":5.5,"tv":443.17,"id":19931652}]}]}
{"op":"mcm","clk":"4230094229","pt":1631528886699,"mc":[{"id":"1.187557146","rc":[{"batb":[[0,4.6,8.7],[1,4.5,25.96],[2,4.1,31.66]],"ltp":5.5,"tv":443.17,"id":19931652}]}]}
{"op":"mcm","clk":"4230094362","pt":1631528888311,"mc":[{"id":"1.187557146","rc":[{"trd":[[5.1,10.84]],"ltp":5.1,"tv":443.81,"id":19931652},{"trd":[[1.24,49.91]],"batl":[[0,1.24,234.66]],"ltp":1.24,"tv":2047.24,"id":8257797}],"tv":2491.05}]}
{"op":"mcm","clk":"4230094783","pt":1631528894202,"mc":[{"id":"1.187557146","rc":[{"trd":[[5.8,3.56]],"ltp":5.8,"tv":447.37,"id":19931652},{"trd":[[1.21,61.77]],"batb":[[0,1.21,195.59]],"batl":[[0,1.24,206.64]],"ltp":1.21,"tv":2064.29,"id":8257797}],"tv":2511.66}]}
{"op":"mcm","clk":"4230094959","pt":1631528896767,"mc":[{"id":"1.187557146","rc":[{"batl":[[0,5.7,6.54],[1,6,32.47],[2,990,0.01]],"ltp":5.8,"tv":447.37,"id":19931652},{"batl":[[0,1.23,23.41],[1,1.24,206.64],[2,1.33,42.06]],"ltp":1.21,"tv":2064.29,"id":8257797}]}]}
{"op":"mcm","clk":"4230095377","pt":1631528903085,"mc":[{"id":"1.187557146","rc":[{"trd":[[1.21,104.44]],"batb":[[0,1.21,174.26]],"ltp":1.21,"tv":2106.96,"id":8257797}],"tv":2554.33}]}
{"op":"mcm","clk":"4230095519","pt":1631528905301,"mc":[{"id":"1.187557146","rc":[{"trd":[[5.7,10.89]],"batl":[[0,5.7,1.1]],"ltp":5.7,"tv":458.25,"id":19931652}],"tv":2565.21}]}
{"op":"mcm","clk":"4230095565","pt":1631528906283,"mc":[{"id":"1.187557146","rc":[{"trd":[[5.7,13.09]],"batb":[[0,5.7,10.88],[1,4.6,8.7],[2,4.5,25.96]],"batl":[[0,6,32.47],[1,990,0.01],[2,990,0]],"ltp":5.7,"tv":460.45,"id":19931652}],"tv":2567.41}]}
{"op":"mcm","clk":"4230095613","pt":1631528907003,"mc":[{"id":"1.187557146","rc":[{"batb":[[0,5.7,5.45]],"ltp":5.7,"tv":460.45,"id":19931652}]}]}
{"op":"mcm","clk":"4230095662","pt":1631528907571,"mc":[{"id":"1.187557146","rc":[{"batb":[[0,4.6,8.7],[1,4.5,25.96],[2,4.1,31.66]],"ltp":5.7,"tv":460.45,"id":19931652},{"trd":[[1.21,213.31]],"batb":[[0,1.21,119.84]],"ltp":1.21,"tv":2215.83,"id":8257797}],"tv":2676.28}]}
{"op":"mcm","clk":"4230095844","pt":1631528910203,"mc":[{"id":"1.187557146","rc":[{"trd":[[5.8,10.67]],"ltp":5.8,"tv":467.56,"id":19931652},{"trd":[[1.21,247.37]],"batb":[[0,1.21,85.78]],"ltp":1.21,"tv":2249.89,"id":8257797}],"tv":2717.45}]}
{"op":"mcm","clk":"4230096016","pt":1631528912277,"mc":[{"id":"1.187557146","rc":[{"trd":[[5.8,16]],"ltp":5.8,"tv":472.89,"id":19931652},{"trd":[[1.21,272.93]],"batb":[[0,1.21,60.22]],"ltp":1.21,"tv":2275.45,"id":8257797}],"tv":2748.35}]}
{"op":"mcm","clk":"4230096261","pt":1631528915376,"mc":[{"id":"1.187557146","rc":[{"batl":[[0,1.24,206.64],[1,1.33,42.06],[2,1.49,773.7]],"ltp":1.21,"tv":2275.45,"id":8257797}]}]}
{"op":"mcm","clk":"4230096478","pt":1631528918585,"mc":[{"id":"1.187557146","rc":[{"batb":[[0,1.21,235]],"ltp":1.21,"tv":2275.45,"id":8257797}]}]}
{"op":"mcm","clk":"4230096682","pt":1631528921534,"mc":[{"id":"1.187557146","rc":[{"batl":[[0,6,37.04]],"ltp":5.8,"tv":472.89,"id":19931652},{"batb":[[1,1.2,361.09]],"batl":[[0,1.22,23.6],[1,1.24,206.64],[2,1.33,42.06]],"ltp":1.21,"tv":2275.45,"id":8257797}]}]}
{"op":"mcm","clk":"4230098057","pt":1631528941351,"mc":[{"id":"1.187557146","rc":[{"batb":[[0,4.5,25.96],[1,4.1,31.66],[2,1.47,1.54]],"batl":[[0,990,0.01],[1,990,0]],"ltp":5.8,"tv":472.89,"id":19931652},{"batb":[[0,1.2,175.86],[1,1.16,218.41],[2,1.08,837.7]],"batl":[[0,1.33,42.06],[1,1.49,773.7],[2,8.8,7.24]],"ltp":1.21,"tv":2275.45,"id":8257797}]}]}
{"op":"mcm","clk":"4230098072","pt":1631528941556,"mc":[{"id":"1.187557146","rc":[{"batb":[[0,4.1,31.66],[1,1.47,1.54],[2,1.36,768.11]],"ltp":5.8,"tv":472.89,"id":19931652},{"batb":[[0,1.16,218.41],[1,1.08,837.7],[2,1.01,105.88]],"batl":[[0,1.49,773.7],[1,8.8,7.24],[2,44,7.24]],"ltp":1.21,"tv":2275.45,"id":8257797}]}]}
{"op":"mcm","clk":"4230099400","pt":1631528959563,"mc":[{"id":"1.187557146","rc":[{"batb":[[1,1.01,105.88],[2,1.01,0]],"ltp":1.21,"tv":2275.45,"id":8257797}]}]}
{"op":"mcm","clk":"4230099513","pt":1631528961180,"mc":[{"id":"1.187557146","rc":[{"batb":[[0,5.1,4.77],[1,4.1,31.66],[2,1.47,1.54]],"ltp":5.8,"tv":472.89,"id":19931652},{"batb":[[0,1.24,45.11],[1,1.23,248.02],[2,1.22,22.92]],"batl":[[0,1.27,218.3],[1,1.35,41.44],[2,1.37,20.42]],"ltp":1.21,"tv":2275.45,"id":8257797}]}]}
{"op":"mcm","clk":"4230099575","pt":1631528962068,"mc":[{"id":"1.187557146","rc":[{"batb":[[2,3.85,37.35]],"ltp":5.8,"tv":472.89,"id":19931652},{"batb":[[1,1.23,402.03]],"ltp":1.21,"tv":2275.45,"id":8257797}]}]}
{"op":"mcm","clk":"4230099785","pt":1631528965174,"mc":[{"id":"1.187557146","rc":[{"trd":[[5.1,13.09]],"batb":[[0,5.1,3.3]],"ltp":5.1,"tv":475.14,"id":19931652},{"trd":[[1.25,223.4]],"ltp":1.25,"tv":2278.31,"id":8257797}],"tv":2753.45}]}
{"op":"mcm","clk":"4230099851","pt":1631528966062,"mc":[{"id":"1.187557146","rc":[{"trd":[[4.7,35.48],[5.1,19.69]],"batb":[[0,4.1,31.66],[1,3.85,37.35],[2,1.47,1.54]],"ltp":4.7,"tv":489.48,"id":19931652},{"trd":[[1.27,483.55]],"batl":[[0,1.27,189.66]],"ltp":1.27,"tv":2306.95,"id":8257797}],"tv":2796.43}]}
{"op":"mcm","clk":"4230100032","pt":1631528968349,"mc":[{"id":"1.187557146","rc":[{"batb":[[0,1.24,187.11]],"ltp":1.27,"tv":2306.95,"id":8257797}]}]}
{"op":"mcm","clk":"4230100078","pt":1631528969173,"mc":[{"id":"1.187557146","rc":[{"batl":[[0,7.2,4.71],[1,990,0.01]],"ltp":4.7,"tv":489.48,"id":19931652},{"trd":[[1.24,53.32]],"batb":[[0,1.24,185.41]],"ltp":1.24,"tv":2310.36,"id":8257797}],"tv":2799.84}]}
{"op":"mcm","clk":"4230100149","pt":1631528970260,"mc":[{"id":"1.187557146","rc":[{"batb":[[0,1.24,142],[1,1.23,154.01],[2,1.19,183.9]],"batl":[[0,1.49,773.7],[1,8.8,7.24],[2,44,7.24]],"ltp":1.24,"tv":2310.36,"id":8257797}]}]}
{"op":"mcm","clk":"4230100215","pt":1631528971293,"mc":[{"id":"1.187557146","rc":[{"batb":[[0,3.85,37.35],[1,1.47,1.54],[2,1.36,768.11]],"batl":[[0,990,0.01],[1,990,0]],"ltp":4.7,"tv":489.48,"id":19931652},{"batb":[[0,1.19,183.9],[1,1.11,695.13],[2,1.01,105.88]],"ltp":1.24,"tv":2310.36,"id":8257797}]}]}
{"op":"mcm","clk":"4230100371","pt":1631528973274,"mc":[{"id":"1.187557146","rc":[{"batl":[[0,1.34,27.24],[1,1.49,773.7],[2,8.8,7.24]],"ltp":1.24,"tv":2310.36,"id":8257797}]}]}
{"op":"mcm","clk":"4230100387","pt":1631528973483,"mc":[{"id":"1.187557146","rc":[{"batl":[[0,1.49,773.7],[1,8.8,7.24],[2,44,7.24]],"ltp":1.24,"tv":2310.36,"id":8257797}]}]}
{"op":"mcm","clk":"4230100610","pt":1631528976910,"mc":[{"id":"1.187557146","rc":[{"batb":[[1,1.01,105.88],[2,1.01,0]],"ltp":1.24,"tv":2310.36,"id":8257797}]}]}
{"op":"mcm","clk":"4230100760","pt":1631528978999,"mc":[{"id":"1.187557146","rc":[{"batb":[[0,4.9,8.16],[1,3.85,37.35],[2,1.47,1.54]],"batl":[[0,6.2,67.69],[1,990,0.01]],"ltp":4.7,"tv":489.48,"id":19931652},{"batb":[[0,1.21,46.23],[1,1.19,207.41],[2,1.01,105.88]],"batl":[[0,1.24,289.37],[1,1.32,42.38],[2,1.34,20.87]],"ltp":1.24,"tv":2310.36,"id":8257797}]}]}
{"op":"mcm","clk":"4230100829","pt":1631528979889,"mc":[{"id":"1.187557146","rc":[{"batb":[[1,4.6,24.29],[2,4.2,30.65]],"ltp":4.7,"tv":489.48,"id":19931652},{"batb":[[2,1.15,240.77]],"ltp":1.24,"tv":2310.36,"id":8257797}]}]}
{"op":"mcm","clk":"4230100966","pt":1631528981813,"mc":[{"id":"1.187557146","rc":[{"batl":[[0,6,3.74],[1,6.2,67.69],[2,990,0.01]],"ltp":4.7,"tv":489.48,"id":19931652},{"batb":[[1,1.2,18.7],[2,1.19,207.41]],"batl":[[0,1.22,30.12],[1,1.24,289.37],[2,1.32,42.38]],"ltp":1.24,"tv":2310.36,"id":8257797}]}]}
{"op":"mcm","clk":"4230101087","pt":1631528983180,"mc":[{"id":"1.187557146","rc":[{"trd":[[5.5,5.82]],"ltp":5.5,"tv":490.06,"id":19931652},{"trd":[[1.22,167.48]],"batl":[[0,1.22,24.77]],"ltp":1.22,"tv":2318.42,"id":8257797}],"tv":2808.48}]}
{"op":"mcm","clk":"4230101237","pt":1631528985095,"mc":[{"id":"1.187557146","rc":[{"batb":[[0,1.21,216.23]],"ltp":1.22,"tv":2318.42,"id":8257797}]}]}
{"op":"mcm","clk":"4230101827","pt":1631528993398,"mc":[{"id":"1.187557146","rc":[{"batl":[[0,6.2,67.69],[1,990,0.01],[2,990,0]],"ltp":5.5,"tv":490.06,"id":19931652},{"batb":[[1,1.19,207.41],[2,1.15,240.77]],"batl":[[0,1.24,289.37],[1,1.32,42.38],[2,1.34,20.87]],"ltp":1.22,"tv":2318.42,"id":8257797}]}]}
{"op":"mcm","clk":"4230101946","pt":1631528995219,"mc":[{"id":"1.187557146","rc":[{"batb":[[0,4.2,30.65],[1,1.47,1.54],[2,1.36,768.11]],"batl":[[0,990,0.01],[1,990,0]],"ltp":5.5,"tv":490.06,"id":19931652},{"batb":[[0,1.21,46.23],[1,1.19,23.51]],"batl":[[0,1.32,42.38],[1,1.34,20.87],[2,1.49,773.7]],"ltp":1.22,"tv":2318.42,"id":8257797}]}]}
{"op":"mcm","clk":"4230102038","pt":1631528996316,"mc":[{"id":"1.187557146","rc":[{"batl":[[0,6,4.28],[1,990,0.01]],"ltp":5.5,"tv":490.06,"id":19931652},{"batb":[[0,1.2,21.42],[1,1.15,240.77],[2,1.08,837.7]],"batl":[[0,1.22,24.77],[1,1.49,773.7],[2,8.8,7.24]],"ltp":1.22,"tv":2318.42,"id":8257797}]}]}
{"op":"mcm","clk":"4230102053","pt":1631528996525,"mc":[{"id":"1.187557146","rc":[{"batl":[[0,990,0.01],[1,990,0]],"ltp":5.5,"tv":490.06,"id":19931652},{"batb":[[0,1.15,240.77],[1,1.08,837.7],[2,1.01,105.88]],"batl":[[0,1.49,773.7],[1,8.8,7.24],[2,44,7.24]],"ltp":1.22,"tv":2318.42,"id":8257797}]}]}
{"op":"mcm","clk":"4230102186","pt":1631528998344,"mc":[{"id":"1.187557146","rc":[{"batb":[[1,1.01,105.88],[2,1.01,0]],"ltp":1.22,"tv":2318.42,"id":8257797}]}]}
{"op":"mcm","clk":"4230102462","pt":1631529001345,"mc":[{"id":"1.187557146","rc":[{"batl":[[0,1.24,4],[1,1.49,773.7],[2,8.8,7.24]],"ltp":1.22,"tv":2318.42,"id":8257797}]}]}
{"op":"mcm","clk":"4230102497","pt":1631529001613,"mc":[{"id":"1.187557146","rc":[{"batb":[[1,1.11,695.13],[2,1.01,105.88]],"batl":[[0,1.49,773.7],[1,8.8,7.24],[2,44,7.24]],"ltp":1.22,"tv":2318.42,"id":8257797}]}]}
{"op":"mcm","clk":"4230103194","pt":1631529009732,"mc":[{"id":"1.187557146","rc":[{"batb":[[1,1.01,105.88],[2,1.01,0]],"ltp":1.22,"tv":2318.42,"id":8257797}]}]}
{"op":"mcm","clk":"4230103332","pt":1631529011259,"mc":[{"id":"1.187557146","rc":[{"batb":[[0,4.8,41.1],[1,4.2,30.65],[2,1.47,1.54]],"batl":[[0,5.3,5.99],[1,5.5,7.28],[2,6,76.58]],"ltp":5.5,"tv":490.06,"id":19931652},{"batb":[[0,1.24,45.11],[1,1.22,22.92],[2,1.2,382.92]],"batl":[[0,1.25,11.9],[1,1.35,41.44],[2,1.37,20.42]],"ltp":1.22,"tv":2318.42,"id":8257797}]}]}
{"op":"mcm","clk":"4230103459","pt":1631529012142,"mc":[{"id":"1.187557146","rc":[{"batb":[[2,3.9,36.76]],"ltp":5.5,"tv":490.06,"id":19931652},{"batb":[[1,1.22,180.28]],"ltp":1.22,"tv":2318.42,"id":8257797}]}]}
{"op":"mcm","clk":"4230103724","pt":1631529014963,"mc":[{"id":"1.187557146","rc":[{"trd":[[5.2,2]],"ltp":5.2,"tv":492.06,"id":19931652},{"trd":[[1.24,61.71]],"batb":[[0,1.24,36.72]],"ltp":1.24,"tv":2326.81,"id":8257797}],"tv":2818.88}]}
{"op":"mcm","clk":"4230103890","pt":1631529016133,"mc":[{"id":"1.187557146","rc":[{"trd":[[5,49.58]],"ltp":5.0,"tv":492.78,"id":19931652},{"trd":[[1.25,231.98]],"batl":[[0,1.25,6.19]],"ltp":1.25,"tv":2335.38,"id":8257797}],"tv":2828.17}]}
{"op":"mcm","clk":"4230104056","pt":1631529018168,"mc":[{"id":"1.187557146","rc":[{"batb":[[0,1.24,145.72]],"ltp":1.25,"tv":2335.38,"id":8257797}]}]}
{"op":"mcm","clk":"4230104319","pt":1631529020949,"mc":[{"id":"1.187557146","rc":[{"batb":[[0,3.9,36.76],[1,1.47,1.54],[2,1.36,768.11]],"batl":[[0,990,0.01],[1,5.5,0],[2,6,0]],"ltp":5.0,"tv":492.78,"id":19931652},{"batb":[[0,1.18,193.28],[1,1.13,639.92],[2,1.01,105.88]],"batl":[[0,1.49,773.7],[1,8.8,7.24],[2,44,7.24]],"ltp":1.25,"tv":2335.38,"id":8257797}]}]}
{"op":"mcm","clk":"4230105989","pt":1631529038995,"mc":[{"id":"1.187557146","rc":[{"batb":[[1,1.56,2.54],[2,1.47,1]],"ltp":5.0,"tv":492.78,"id":19931652}]}]}
{"op":"mcm","clk":"4230106289","pt":1631529042303,"mc":[{"id":"1.187557146","rc":[{"batb":[[1,1.01,105.88],[2,1.01,0]],"ltp":1.25,"tv":2335.38,"id":8257797}]}]}
{"op":"mcm","clk":"4230106440","pt":1631529043877,"mc":[{"id":"1.187557146","rc":[{"trd":[[6.2,0.42]],"batb":[[0,5.7,4.93],[1,5.1,7.84],[2,3.9,36.76]],"batl":[[0,6,3.6],[1,990,0.01]],"ltp":6.2,"tv":493.2,"id":19931652},{"trd":[[1.19,2.17]],"batb":[[0,1.2,46.62],[1,1.19,223.21],[2,1.18,216.99]],"batl":[[0,1.26,714.58],[1,1.31,42.7],[2,1.33,21.03]],"ltp":1.19,"tv":2337.55,"id":8257797}],"tv":2830.76}]}
{"op":"mcm","clk":"4230106493","pt":1631529044605,"mc":[{"id":"1.187557146","rc":[{"batb":[[2,4.7,22.53]],"ltp":6.2,"tv":493.2,"id":19931652}]}]}
{"op":"mcm","clk":"4230106812","pt":1631529048202,"mc":[{"id":"1.187557146","rc":[{"trd":[[5.7,14.26]],"batb":[[0,5.7,4.34]],"ltp":5.7,"tv":494.37,"id":19931652},{"batb":[[0,1.2,149.62]],"ltp":1.19,"tv":2337.55,"id":8257797}],"tv":2831.93}]}
{"op":"mcm","clk":"4230106872","pt":1631529048784,"mc":[{"id":"1.187557146","rc":[{"trd":[[5.7,19.52]],"batb":[[0,5.7,1.71]],"ltp":5.7,"tv":499.63,"id":19931652}],"tv":2837.19}]}
{"op":"mcm","clk":"4230107383","pt":1631529054016,"mc":[{"id":"1.187557146","rc":[{"batb":[[0,5.1,7.84],[1,4.7,22.53],[2,4.2,30.73]],"batl":[[0,990,0.01],[1,990,0]],"ltp":5.7,"tv":499.63,"id":19931652},{"batb":[[0,1.2,46.62]],"ltp":1.19,"tv":2337.55,"id":8257797}]}]}
{"op":"mcm","clk":"4230107720","pt":1631529057192,"mc":[{"id":"1.187557146","rc":[{"trd":[[5.5,6.32]],"batl":[[0,6,6.64],[1,990,0.01]],"ltp":5.5,"tv":500.14,"id":19931652},{"trd":[[1.22,169.76]],"batl":[[0,1.22,30.27],[1,1.26,714.58],[2,1.31,42.7]],"ltp":1.22,"tv":2339.83,"id":8257797}],"tv":2839.98}]}
{"op":"mcm","clk":"4230107804","pt":1631529058333,"mc":[{"id":"1.187557146","rc":[{"batl":[[0,990,0.01],[1,990,0]],"ltp":5.5,"tv":500.14,"id":19931652},{"batl":[[0,1.26,714.58],[1,1.31,42.7],[2,1.33,21.03]],"ltp":1.22,"tv":2339.83,"id":8257797}]}]}
{"op":"mcm","clk":"4230108059","pt":1631529061310,"mc":[{"id":"1.187557146","rc":[{"batl":[[0,6,3.55],[1,990,0.01]],"ltp":5.5,"tv":500.14,"id":19931652},{"batb":[[0,1.2,64.39]],"batl":[[0,1.22,30.27],[1,1.26,714.58],[2,1.31,42.7]],"ltp":1.22,"tv":2339.83,"id":8257797}]}]}
{"op":"mcm","clk":"4230108075","pt":1631529061520,"mc":[{"id":"1.187557146","rc":[{"batl":[[0,990,0.01],[1,990,0]],"ltp":5.5,"tv":500.14,"id":19931652},{"batb":[[0,1.2,46.62]],"batl":[[0,1.26,714.58],[1,1.31,42.7],[2,1.33,21.03]],"ltp":1.22,"tv":2339.83,"id":8257797}]}]}
{"op":"mcm","clk":"4230108346","pt":1631529064514,"mc":[{"id":"1.187557146","rc":[{"batl":[[0,6,3.55],[1,990,0.01]],"ltp":5.5,"tv":500.14,"id":19931652},{"batb":[[0,1.2,64.39]],"batl":[[0,1.22,30.27],[1,1.26,714.58],[2,1.31,42.7]],"ltp":1.22,"tv":2339.83,"id":8257797}]}]}
{"op":"mcm","clk":"4230108579","pt":1631529067125,"mc":[{"id":"1.187557146","rc":[{"batb":[[0,4.2,30.73],[1,1.56,2.54],[2,1.47,1]],"batl":[[0,990,0.01],[1,990,0]],"ltp":5.5,"tv":500.14,"id":19931652},{"batb":[[0,1.26,3.53],[1,1.13,273.51],[2,1.11,695.13]],"batl":[[0,1.49,773.7],[1,8.8,7.24],[2,44,7.24]],"ltp":1.22,"tv":2339.83,"id":8257797}]}]}
{"op":"mcm","clk":"4230109136","pt":1631529073935,"mc":[{"id":"1.187557146","rc":[{"batb":[[2,1.01,105.88]],"ltp":1.22,"tv":2339.83,"id":8257797}]}]}
{"op":"mcm","clk":"4230109252","pt":1631529075338,"mc":[{"id":"1.187557146","rc":[{"batl":[[0,5.2,726],[1,5.5,59.8],[2,5.6,35.72]],"ltp":5.5,"tv":500.14,"id":19931652},{"trd":[[1.26,155.92]],"batb":[[0,1.24,23.78]],"batl":[[0,1.26,25.89],[1,1.27,245.8],[2,1.49,773.7]],"ltp":1.26,"tv":2346.89,"id":8257797}],"tv":2847.04}]}
{"op":"mcm","clk":"4230109345","pt":1631529076228,"mc":[{"id":"1.187557146","rc":[{"batb":[[1,3.9,37.35],[2,1.56,2.54]],"batl":[[0,5.5,59.8],[1,5.6,7.14],[2,990,0.01]],"ltp":5.5,"tv":500.14,"id":19931652},{"batb":[[0,1.24,68.89],[1,1.22,179.95],[2,1.18,197.22]],"batl":[[2,1.35,41.44]],"ltp":1.26,"tv":2346.89,"id":8257797}]}]}
{"op":"mcm","clk":"4230109757","pt":1631529080352,"mc":[{"id":"1.187557146","rc":[{"trd":[[4.8,118.38]],"ltp":4.8,"tv":500.86,"id":19931652},{"trd":[[1.26,164.42]],"batl":[[0,1.26,20.26]],"ltp":1.26,"tv":2355.4,"id":8257797}],"tv":2856.27}]}
{"op":"mcm","clk":"4230109846","pt":1631529081143,"mc":[{"id":"1.187557146","rc":[{"batb":[[0,1.24,170.89]],"ltp":1.26,"tv":2355.4,"id":8257797}]}]}
{"op":"mcm","clk":"4230110041","pt":1631529083120,"mc":[{"id":"1.187557146","rc":[{"batb":[[0,3.9,37.35],[1,1.56,2.54],[2,1.47,1]],"batl":[[0,990,0.01],[1,5.6,0],[2,990,0]],"ltp":4.8,"tv":500.86,"id":19931652},{"trd":[[1.24,61.87]],"batb":[[0,1.24,102],[1,1.18,197.22],[2,1.13,639.92]],"batl":[[0,1.49,773.7],[1,8.8,7.24],[2,44,7.24]],"ltp":1.24,"tv":2355.56,"id":8257797}],"tv":2856.43}]}
{"op":"mcm","clk":"4230110124","pt":1631529084152,"mc":[{"id":"1.187557146","rc":[{"batb":[[0,1.18,197.22],[1,1.13,639.92],[2,1.01,105.88]],"ltp":1.24,"tv":2355.56,"id":8257797}]}]}
{"op":"mcm","clk":"4230110645","pt":1631529090235,"mc":[{"id":"1.187557146","rc":[{"batl":[[0,1.27,502.93],[1,1.49,773.7],[2,8.8,7.24]],"ltp":1.24,"tv":2355.56,"id":8257797}]}]}
{"op":"mcm","clk":"4230110660","pt":1631529090442,"mc":[{"id":"1.187557146","rc":[{"batl":[[0,1.49,773.7],[1,8.8,7.24],[2,44,7.24]],"ltp":1.24,"tv":2355.56,"id":8257797}]}]}
{"op":"mcm","clk":"4230110967","pt":1631529094343,"mc":[{"id":"1.187557146","rc":[{"batb":[[1,1.01,105.88],[2,1.01,0]],"ltp":1.24,"tv":2355.56,"id":8257797}]}]}
{"op":"mcm","clk":"4230111261","pt":1631529097988,"mc":[{"id":"1.187557146","rc":[{"batb":[[1,1.16,585.23],[2,1.01,105.88]],"ltp":1.24,"tv":2355.56,"id":8257797}]}]}
{"op":"mcm","clk":"4230111853","pt":1631529104597,"mc":[{"id":"1.187557146","rc":[{"batb":[[1,1.01,105.88],[2,1.01,0]],"ltp":1.24,"tv":2355.56,"id":8257797}]}]}
{"op":"mcm","clk":"4230111993","pt":1631529106260,"mc":[{"id":"1.187557146","rc":[{"batb":[[0,5.5,46.29],[1,3.9,37.35],[2,1.56,2.54]],"batl":[[0,6,6.23],[1,6.4,45.06],[2,990,0.01]],"ltp":4.8,"tv":500.86,"id":19931652},{"batb":[[0,1.2,46.62],[1,1.18,220.92],[2,1.01,105.88]],"batl":[[0,1.21,165.28],[1,1.22,33.78],[2,1.31,42.7]],"ltp":1.24,"tv":2355.56,"id":8257797}]}]}
{"op":"mcm","clk":"4230112066","pt":1631529107254,"mc":[{"id":"1.187557146","rc":[{"batb":[[1,4.8,21.86],[2,4.2,29.73]],"ltp":4.8,"tv":500.86,"id":19931652},{"batb":[[2,1.13,277.95]],"batl":[[0,1.21,33.06]],"ltp":1.24,"tv":2355.56,"id":8257797}]}]}
{"op":"mcm","clk":"4230112129","pt":1631529108078,"mc":[{"id":"1.187557146","rc":[{"batb":[[2,1.13,917.87]],"ltp":1.24,"tv":2355.56,"id":8257797}]}]}
{"op":"mcm","clk":"4230112424","pt":1631529111265,"mc":[{"id":"1.187557146","rc":[{"trd":[[5.7,20.13]],"ltp":5.7,"tv":501.48,"id":19931652},{"trd":[[1.21,281.61]],"batl":[[0,1.21,27.28]],"ltp":1.21,"tv":2364.23,"id":8257797}],"tv":2865.72}]}
{"op":"mcm","clk":"4230112727","pt":1631529114290,"mc":[{"id":"1.187557146","rc":[{"batb":[[0,1.2,164.62]],"ltp":1.21,"tv":2364.23,"id":8257797}]}]}
{"op":"mcm","clk":"4230113665","pt":1631529125201,"mc":[{"id":"1.187557146","rc":[{"batb":[[0,4.2,29.73],[1,1.56,2.54],[2,1.47,1]],"batl":[[0,990,0.01],[1,6.4,0],[2,990,0]],"ltp":5.7,"tv":501.48,"id":19931652},{"batb":[[0,1.13,917.87],[1,1.01,105.88],[2,1.13,0]],"batl":[[0,1.49,773.7],[1,8.8,7.24],[2,44,7.24]],"ltp":1.21,"tv":2364.23,"id":8257797}]}]}
{"op":"mcm","clk":"4230114591","pt":1631529135411,"mc":[{"id":"1.187557146","rc":[{"batb":[[1,1.47,1.54],[2,1.36,768.11]],"ltp":5.7,"tv":501.48,"id":19931652}]}]}
{"op":"mcm","clk":"4230114893","pt":1631529138532,"mc":[{"id":"1.187557146","rc":[{"batb":[[1,1.94,2],[2,1.47,1.54]],"ltp":5.7,"tv":501.48,"id":19931652}]}]}
{"op":"mcm","clk":"4230115048","pt":1631529140347,"mc":[{"id":"1.187557146","rc":[{"batb":[[0,1.13,277.95]],"ltp":1.21,"tv":2364.23,"id":8257797}]}]}
{"op":"mcm","clk":"4230115144","pt":1631529141338,"mc":[{"id":"1.187557146","rc":[{"batl":[[0,5.2,7.7],[1,5.5,41.12],[2,990,0.01]],"ltp":5.7,"tv":501.48,"id":19931652},{"batb":[[0,1.24,64.61],[1,1.22,22.92],[2,1.13,277.95]],"batl":[[0,1.26,211.32],[1,1.35,41.44],[2,1.37,20.42]],"ltp":1.21,"tv":2364.23,"id":8257797}]}]}
{"op":"mcm","clk":"4230115238","pt":1631529142327,"mc":[{"id":"1.187557146","rc":[{"batb":[[1,3.9,36.85],[2,1.94,2]],"ltp":5.7,"tv":501.48,"id":19931652},{"batb":[[1,1.22,183.55],[2,1.18,200.65]],"ltp":1.21,"tv":2364.23,"id":8257797}]}]}
{"op":"mcm","clk":"4230115539","pt":1631529146264,"mc":[{"id":"1.187557146","rc":[{"trd":[[4.8,119.13]],"ltp":4.8,"tv":502.22,"id":19931652},{"trd":[[1.26,173.04]],"batl":[[0,1.26,205.6]],"ltp":1.26,"tv":2372.85,"id":8257797}],"tv":2875.08}]}
{"op":"mcm","clk":"4230115669","pt":1631529147931,"mc":[{"id":"1.187557146","rc":[{"batb":[[0,1.24,163.61]],"ltp":1.26,"tv":2372.85,"id":8257797}]}]}
{"op":"mcm","clk":"4230116147","pt":1631529153233,"mc":[{"id":"1.187557146","rc":[{"batl":[[0,990,0.01],[1,5.5,0],[2,990,0]],"ltp":4.8,"tv":502.22,"id":19931652},{"batb":[[0,1.24,144.11]],"batl":[[0,1.35,41.44],[1,1.37,20.42],[2,1.49,773.7]],"ltp":1.26,"tv":2372.85,"id":8257797}]}]}
{"op":"mcm","clk":"4230116193","pt":1631529153753,"mc":[{"id":"1.187557146","rc":[{"batb":[[0,3.9,36.85],[1,1.94,2],[2,1.47,1.54]],"ltp":4.8,"tv":502.22,"id":19931652},{"batb":[[0,1.18,200.65],[1,1.16,585.23],[2,1.01,105.88]],"batl":[[0,1.49,773.7],[1,8.8,7.24],[2,44,7.24]],"ltp":1.26,"tv":2372.85,"id":8257797}]}]}
{"op":"mcm","clk":"4230116926","pt":1631529162781,"mc":[{"id":"1.187557146","rc":[{"batb":[[1,1.01,105.88],[2,1.01,0]],"ltp":1.26,"tv":2372.85,"id":8257797}]}]}
{"op":"mcm","clk":"4230117044","pt":1631529164331,"mc":[{"id":"1.187557146","rc":[{"batb":[[0,4.5,6.34],[1,3.9,36.85],[2,1.94,2]],"batl":[[0,4.7,3.67],[1,4.8,25],[2,5,22.18]],"ltp":4.8,"tv":502.22,"id":19931652},{"batb":[[0,1.27,44.05],[1,1.25,111.1],[2,1.18,200.65]],"batl":[[0,1.29,182.28],[1,1.39,40.25],[2,1.41,19.83]],"ltp":1.26,"tv":2372.85,"id":8257797}]}]}
{"op":"mcm","clk":"4230117122","pt":1631529165261,"mc":[{"id":"1.187557146","rc":[{"batb":[[2,3.5,24.54]],"batl":[[1,4.8,8.34]],"ltp":4.8,"tv":502.22,"id":19931652},{"batb":[[1,1.25,249.69],[2,1.23,155.26]],"ltp":1.26,"tv":2372.85,"id":8257797}]}]}
{"op":"mcm","clk":"4230117396","pt":1631529169162,"mc":[{"id":"1.187557146","rc":[{"batl":[[1,1.33,229.21],[2,1.39,40.25]],"ltp":1.26,"tv":2372.85,"id":8257797}]}]}
{"op":"mcm","clk":"4230117408","pt":1631529169370,"mc":[{"id":"1.187557146","rc":[{"batl":[[1,1.39,40.25],[2,1.41,19.83]],"ltp":1.26,"tv":2372.85,"id":8257797}]}]}
{"op":"mcm","clk":"4230117643","pt":1631529172390,"mc":[{"id":"1.187557146","rc":[{"batb":[[0,1.27,147.05]],"ltp":1.26,"tv":2372.85,"id":8257797}]}]}
{"op":"mcm","clk":"4230118714","pt":1631529186193,"mc":[{"id":"1.187557146","rc":[{"trd":[[4.5,10.04]],"batb":[[0,4.5,5.45]],"ltp":4.5,"tv":504.0,"id":19931652},{"trd":[[1.29,45.83]],"batl":[[0,1.29,179.27]],"ltp":1.29,"tv":2378.87,"id":8257797}],"tv":2882.88}]}
{"op":"mcm","clk":"4230119536","pt":1631529196372,"mc":[{"id":"1.187557146","rc":[{"batb":[[0,3.9,36.85],[1,3.5,24.54],[2,1.94,2]],"batl":[[0,4.8,8.34],[1,5,22.18],[2,990,0.01]],"ltp":4.5,"tv":504.0,"id":19931652}]}]}
{"op":"mcm","clk":"4230119728","pt":1631529198716,"mc":[{"id":"1.187557146","rc":[{"batb":[[2,1.47,1.54]],"ltp":4.5,"tv":504.0,"id":19931652}]}]}
{"op":"mcm","clk":"4230119805","pt":1631529199601,"mc":[{"id":"1.187557146","rc":[{"batb":[[0,4.5,5.45],[1,3.9,36.85],[2,3.5,24.54]],"batl":[[0,4.7,4.53],[1,4.8,8.34],[2,5,22.18]],"ltp":4.5,"tv":504.0,"id":19931652}]}]}
{"op":"mcm","clk":"4230119938","pt":1631529201312,"mc":[{"id":"1.187557146","rc":[{"batb":[[0,1.27,103],[1,1.25,227.32]],"batl":[[1,1.49,773.7],[2,8.8,7.24]],"ltp":1.29,"tv":2378.87,"id":8257797}]}]}
{"op":"mcm","clk":"4230120602","pt":1631529210423,"mc":[{"id":"1.187557146","rc":[{"batb":[[2,3.8,2]],"ltp":4.5,"tv":504.0,"id":19931652}]}]}
{"op":"mcm","clk":"4230120711","pt":1631529211927,"mc":[{"id":"1.187557146","rc":[{"batb":[[2,3.5,24.54]],"ltp":4.5,"tv":504.0,"id":19931652}]}]}
{"op":"mcm","clk":"4230120921","pt":1631529215022,"mc":[{"id":"1.187557146","rc":[{"trd":[[4.7,39.48]],"batl":[[0,4.7,2.53]],"ltp":4.7,"tv":508.0,"id":19931652}],"tv":2886.88}]}
{"op":"mcm","clk":"4230121597","pt":1631529225120,"mc":[{"id":"1.187557146","rc":[{"batb":[[0,3.9,36.85],[1,3.5,24.54],[2,1.47,1.54]],"batl":[[0,4.8,8.34],[1,5,22.18],[2,990,0.01]],"ltp":4.7,"tv":508.0,"id":19931652}]}]}
{"op":"mcm","clk":"4230121668","pt":1631529226160,"mc":[{"id":"1.187557146","rc":[{"batl":[[0,4.5,1.29],[1,4.8,8.34],[2,5,22.18]],"ltp":4.7,"tv":508.0,"id":19931652}]}]}
{"op":"mcm","clk":"4230121814","pt":1631529228135,"mc":[{"id":"1.187557146","rc":[{"trd":[[4.5,11.33]],"batl":[[0,4.8,15.5],[1,5,22.18],[2,990,0.01]],"ltp":4.5,"tv":509.29,"id":19931652},{"trd":[[1.28,22.98]],"batl":[[0,1.28,9.1],[1,1.29,179.27],[2,1.49,773.7]],"ltp":1.28,"tv":2383.41,"id":8257797}],"tv":2892.71}]}
{"op":"mcm","clk":"4230122239","pt":1631529233770,"mc":[{"id":"1.187557146","rc":[{"batb":[[0,3.5,24.54],[1,1.47,1.54],[2,1.36,768.11]],"batl":[[0,990,0.01],[1,5,0],[2,990,0]],"ltp":4.5,"tv":509.29,"id":19931652},{"batb":[[0,1.23,155.26],[1,1.18,558.4],[2,1.01,105.88]],"batl":[[0,1.49,773.7],[1,8.8,7.24],[2,44,7.24]],"ltp":1.28,"tv":2383.41,"id":8257797}]}]}
{"op":"mcm","clk":"4230123231","pt":1631529246060,"mc":[{"id":"1.187557146","rc":[{"batb":[[0,4.8,50.52],[1,4.3,9.3],[2,3.5,24.54]],"batl":[[0,5.1,3.99],[1,5.5,58.24],[2,990,0.01]],"ltp":4.5,"tv":509.29,"id":19931652},{"batb":[[0,1.24,45.11],[1,1.23,155.26],[2,1.22,22.92]],"batl":[[0,1.26,25.61],[1,1.35,41.44],[2,1.37,20.42]],"ltp":1.28,"tv":2383.41,"id":8257797}]}]}
{"op":"mcm","clk":"4230123291","pt":1631529246780,"mc":[{"id":"1.187557146","rc":[{"batb":[[2,4.1,31.24]],"ltp":4.5,"tv":509.29,"id":19931652}]}]}
{"op":"mcm","clk":"4230123644","pt":1631529251184,"mc":[{"id":"1.187557146","rc":[{"trd":[[4.8,120.65]],"batb":[[0,4.8,49.76]],"ltp":4.8,"tv":510.81,"id":19931652},{"trd":[[1.26,178.9]],"batl":[[0,1.26,22.68]],"ltp":1.26,"tv":2389.27,"id":8257797}],"tv":2900.09}]}
{"op":"mcm","clk":"4230123810","pt":1631529253263,"mc":[{"id":"1.187557146","rc":[{"batb":[[0,4.1,31.24],[1,3.75,41.12],[2,1.47,1.54]],"batl":[[0,990,0.01],[1,5.5,0],[2,990,0]],"ltp":4.8,"tv":510.81,"id":19931652},{"batl":[[0,1.35,41.44],[1,1.37,20.42],[2,1.49,773.7]],"ltp":1.26,"tv":2389.27,"id":8257797}]}]}
{"op":"mcm","clk":"4230123885","pt":1631529254194,"mc":[{"id":"1.187557146","rc":[{"batb":[[0,3.75,41.12],[1,1.47,1.54],[2,1.36,768.11]],"ltp":4.8,"tv":510.81,"id":19931652},{"batb":[[0,1.21,170.09],[1,1.18,558.4],[2,1.01,105.88]],"batl":[[0,1.49,773.7],[1,8.8,7.24],[2,44,7.24]],"ltp":1.26,"tv":2389.27,"id":8257797}]}]}
{"op":"mcm","clk":"4230124406","pt":1631529260904,"mc":[{"id":"1.187557146","rc":[{"batb":[[1,1.01,105.88],[2,1.01,0]],"ltp":1.26,"tv":2389.27,"id":8257797}]}]}
{"op":"mcm","clk":"4230124519","pt":1631529262203,"mc":[{"id":"1.187557146","rc":[{"batl":[[0,6,37.01],[1,990,0.01]],"ltp":4.8,"tv":510.81,"id":19931652},{"batb":[[0,1.22,45.86],[1,1.21,170.09],[2,1.2,208.35]],"batl":[[0,1.26,460.06],[1,1.27,31.5],[2,1.33,42.06]],"ltp":1.26,"tv":2389.27,"id":8257797}]}]}
{"op":"mcm","clk":"4230124611","pt":1631529263290,"mc":[{"id":"1.187557146","rc":[{"batb":[[0,4.4,27.3],[1,4,34],[2,1.47,1.54]],"ltp":4.8,"tv":510.81,"id":19931652}]}]}
{"op":"mcm","clk":"4230124742","pt":1631529265116,"mc":[{"id":"1.187557146","rc":[{"batl":[[0,5.5,5.87],[1,6,37.01],[2,990,0.01]],"ltp":4.8,"tv":510.81,"id":19931652},{"batl":[[0,1.24,25.11],[1,1.26,460.06],[2,1.27,31.5]],"ltp":1.26,"tv":2389.27,"id":8257797}]}]}
{"op":"mcm","clk":"4230124896","pt":1631529267194,"mc":[{"id":"1.187557146","rc":[{"trd":[[5.1,23.93]],"ltp":5.1,"tv":515.05,"id":19931652},{"trd":[[1.24,84.7]],"batl":[[0,1.24,4.97]],"ltp":1.24,"tv":2412.1,"id":8257797}],"tv":2927.16}]}
{"op":"mcm","clk":"4230125117","pt":1631529270316,"mc":[{"id":"1.187557146","rc":[{"batb":[[0,4,34],[1,1.47,1.54],[2,1.36,768.11]],"batl":[[0,990,0.01],[1,6,0],[2,990,0]],"ltp":5.1,"tv":515.05,"id":19931652},{"batb":[[0,1.19,182.48],[1,1.14,637.83],[2,1.01,105.88]],"batl":[[0,1.49,773.7],[1,8.8,7.24],[2,44,7.24]],"ltp":1.24,"tv":2412.1,"id":8257797}]}]}
{"op":"mcm","clk":"4230125515","pt":1631529275298,"mc":[{"id":"1.187557146","rc":[{"batl":[[0,5.6,117.32],[1,990,0.01]],"ltp":5.1,"tv":515.05,"id":19931652}]}]}
{"op":"mcm","clk":"4230125529","pt":1631529275505,"mc":[{"id":"1.187557146","rc":[{"batl":[[0,990,0.01],[1,990,0]],"ltp":5.1,"tv":515.05,"id":19931652}]}]}
{"op":"mcm","clk":"4230126308","pt":1631529286105,"mc":[{"id":"1.187557146","rc":[{"batl":[[0,5.3,43.74],[1,990,0.01]],"ltp":5.1,"tv":515.05,"id":19931652},{"batb":[[0,1.26,15.32],[1,1.25,44.75],[2,1.24,32.26]],"batl":[[0,1.27,176.86],[1,1.28,31.44],[2,1.36,41.13]],"ltp":1.24,"tv":2412.1,"id":8257797}]}]}
{"op":"mcm","clk":"4230126408","pt":1631529287347,"mc":[{"id":"1.187557146","rc":[{"batb":[[1,3.6,22.95],[2,1.47,1.54]],"ltp":5.1,"tv":515.05,"id":19931652},{"batb":[[2,1.24,178.65]],"ltp":1.24,"tv":2412.1,"id":8257797}]}]}
{"op":"mcm","clk":"4230126550","pt":1631529289118,"mc":[{"id":"1.187557146","rc":[{"trd":[[4.9,36.13]],"ltp":4.9,"tv":518.74,"id":19931652},{"trd":[[1.26,193.25]],"batb":[[0,1.25,45.72],[1,1.24,178.65],[2,1.23,22.74]],"ltp":1.26,"tv":2426.45,"id":8257797}],"tv":2945.2}]}
{"op":"mcm","clk":"4230126692","pt":1631529291252,"mc":[{"id":"1.187557146","rc":[{"trd":[[4.7,46.2]],"ltp":4.7,"tv":525.46,"id":19931652},{"trd":[[1.27,514.34]],"batb":[[0,1.26,135.97],[1,1.25,44.75],[2,1.24,178.65]],"batl":[[0,1.27,149.03]],"ltp":1.27,"tv":2457.24,"id":8257797}],"tv":2982.71}]}
{"op":"mcm","clk":"4230127272","pt":1631529299243,"mc":[{"id":"1.187557146","rc":[{"batl":[[0,990,0.01],[1,990,0]],"ltp":4.7,"tv":525.46,"id":19931652},{"batb":[[0,1.27,141.18],[1,1.24,146.39],[2,1.22,161.96]],"batl":[[0,1.49,773.7],[1,8.8,7.24],[2,44,7.24]],"ltp":1.27,"tv":2457.24,"id":8257797}]}]}
{"op":"mcm","clk":"4230127282","pt":1631529299452,"mc":[{"id":"1.187557146","rc":[{"batb":[[0,3.6,22.95],[1,1.47,1.54],[2,1.36,768.11]],"ltp":4.7,"tv":525.46,"id":19931652},{"batb":[[1,1.22,161.96],[2,1.18,558.4]],"ltp":1.27,"tv":2457.24,"id":8257797}]}]}
{"op":"mcm","clk":"4230127566","pt":1631529303358,"mc":[{"id":"1.187557146","rc":[{"batb":[[0,1.22,161.96],[1,1.18,558.4],[2,1.01,105.88]],"ltp":1.27,"tv":2457.24,"id":8257797}]}]}
{"op":"mcm","clk":"4230127912","pt":1631529307864,"mc":[{"id":"1.187557146","rc":[{"batb":[[1,1.01,105.88],[2,1.01,0]],"batl":[[0,8.8,7.24],[1,44,7.24],[2,50,7.24]],"ltp":1.27,"tv":2457.24,"id":8257797}]}]}
{"op":"mcm","clk":"4230128070","pt":1631529309851,"mc":[{"id":"1.187557146","rc":[{"batl":[[0,4.3,9.3],[1,5,73.66],[2,990,0.01]],"ltp":4.7,"tv":525.46,"id":19931652},{"batb":[[0,1.3,14.71],[1,1.29,43.37],[2,1.27,22.02]],"batl":[[0,1.32,176.54],[1,1.41,39.68],[2,1.43,19.56]],"ltp":1.27,"tv":2457.24,"id":8257797}]}]}
{"op":"mcm","clk":"4230128131","pt":1631529310568,"mc":[{"id":"1.187557146","rc":[{"batb":[[1,3.05,34.92],[2,1.47,1.54]],"ltp":4.7,"tv":525.46,"id":19931652},{"batb":[[1,1.29,160.78]],"ltp":1.27,"tv":2457.24,"id":8257797}]}]}
{"op":"mcm","clk":"4230128453","pt":1631529314261,"mc":[{"id":"1.187557146","rc":[{"trd":[[4.1,0.94]],"ltp":4.1,"tv":526.4,"id":19931652},{"trd":[[1.32,8.91]],"batl":[[0,1.32,170.71]],"ltp":1.32,"tv":2466.0,"id":8257797}],"tv":2992.4}]}
{"op":"mcm","clk":"4230128605","pt":1631529316177,"mc":[{"id":"1.187557146","rc":[{"batb":[[0,1.3,109.71]],"ltp":1.32,"tv":2466.0,"id":8257797}]}]}
{"op":"mcm","clk":"4230129166","pt":1631529323463,"mc":[{"id":"1.187557146","rc":[{"trd":[[1.3,28.22]],"batb":[[0,1.3,96.69]],"ltp":1.3,"tv":2492.04,"id":8257797}],"tv":3018.45}]}
{"op":"mcm","clk":"4230129259","pt":1631529324460,"mc":[{"id":"1.187557146","rc":[{"batb":[[0,1.3,95]],"batl":[[0,1.32,151.04]],"ltp":1.3,"tv":2492.04,"id":8257797}]}]}
{"op":"mcm","clk":"4230129445","pt":1631529326796,"mc":[{"id":"1.187557146","rc":[{"batb":[[1,1.29,117.41],[2,1.25,435.58]],"batl":[[1,1.66,588.96],[2,8.8,7.24]],"ltp":1.3,"tv":2492.04,"id":8257797}]}]}
{"op":"mcm","clk":"4230129487","pt":1631529327375,"mc":[{"id":"1.187557146","rc":[{"batl":[[1,4.4,6.01],[2,5,73.66]],"ltp":4.1,"tv":526.4,"id":19931652},{"batl":[[0,1.31,13.1],[1,1.32,151.04],[2,1.66,588.96]],"ltp":1.3,"tv":2492.04,"id":8257797}]}]}
{"op":"mcm","clk":"4230129644","pt":1631529329190,"mc":[{"id":"1.187557146","rc":[{"batb":[[0,3.05,34.92],[1,1.47,1.54],[2,1.36,768.11]],"batl":[[0,990,0.01],[1,4.4,0],[2,5,0]],"ltp":4.1,"tv":526.4,"id":19931652},{"batb":[[0,1.25,140.94],[1,1.2,539.24],[2,1.01,105.88]],"batl":[[0,1.66,588.96],[1,8.8,7.24],[2,44,7.24]],"ltp":1.3,"tv":2492.04,"id":8257797}]}]}
{"op":"mcm","clk":"4230130093","pt":1631529335009,"mc":[{"id":"1.187557146","rc":[{"batb":[[1,1.01,105.88],[2,1.01,0]],"ltp":1.3,"tv":2492.04,"id":8257797}]}]}
{"op":"mcm","clk":"4230130410","pt":1631529338786,"mc":[{"id":"1.187557146","rc":[{"batb":[[1,1.22,531.25],[2,1.01,105.88]],"ltp":1.3,"tv":2492.04,"id":8257797}]}]}
{"op":"mcm","clk":"4230131902","pt":1631529358025,"mc":[{"id":"1.187557146","rc":[{"batb":[[1,1.01,105.88],[2,1.01,0]],"ltp":1.3,"tv":2492.04,"id":8257797}]}]}
{"op":"mcm","clk":"4230131962","pt":1631529358915,"mc":[{"id":"1.187557146","rc":[{"batl":[[0,5,6.55],[1,5.3,55.99],[2,990,0.01]],"ltp":4.1,"tv":526.4,"id":19931652},{"batb":[[1,1.24,45.11],[2,1.22,22.92]],"batl":[[0,1.27,24.3],[1,1.28,234.1],[2,1.32,30.3]],"ltp":1.3,"tv":2492.04,"id":8257797}]}]}
{"op":"mcm","clk":"4230132045","pt":1631529359907,"mc":[{"id":"1.187557146","rc":[{"batb":[[0,3.95,35.93],[1,3.45,25.21],[2,1.47,1.54]],"ltp":4.1,"tv":526.4,"id":19931652},{"batb":[[2,1.22,182.54]],"ltp":1.3,"tv":2492.04,"id":8257797}]}]}
{"op":"mcm","clk":"4230132388","pt":1631529364239,"mc":[{"id":"1.187557146","rc":[{"trd":[[4.7,51.61]],"ltp":4.7,"tv":531.81,"id":19931652},{"trd":[[1.27,540.12]],"batl":[[0,1.27,1.41]],"ltp":1.27,"tv":2517.83,"id":8257797}],"tv":3049.64}]}
{"op":"mcm","clk":"4230132480","pt":1631529365330,"mc":[{"id":"1.187557146","rc":[{"batb":[[0,1.25,211.94]],"ltp":1.27,"tv":2517.83,"id":8257797}]}]}
{"op":"mcm","clk":"4230132780","pt":1631529369548,"mc":[{"id":"1.187557146","rc":[{"batb":[[0,4,23.24],[1,3.95,35.93],[2,3.45,25.21]],"ltp":4.7,"tv":531.81,"id":19931652}]}]}
{"op":"mcm","clk":"4230132982","pt":1631529372150,"mc":[{"id":"1.187557146","rc":[{"batb":[[0,3.45,25.21],[1,1.47,1.54],[2,1.36,768.11]],"batl":[[0,990,0.01],[1,5.3,0],[2,990,0]],"ltp":4.7,"tv":531.81,"id":19931652},{"batb":[[0,1.22,159.62],[1,1.18,558.4],[2,1.01,105.88]],"batl":[[0,1.66,588.96],[1,8.8,7.24],[2,44,7.24]],"ltp":1.27,"tv":2517.83,"id":8257797}]}]}
{"op":"mcm","clk":"4230134670","pt":1631529394764,"mc":[{"id":"1.187557146","rc":[{"batl":[[0,8.8,7.24],[1,44,7.24],[2,50,7.24]],"ltp":1.27,"tv":2517.83,"id":8257797}]}]}
{"op":"mcm","clk":"4230134777","pt":1631529396274,"mc":[{"id":"1.187557146","rc":[{"batb":[[0,5,27.99],[1,3.45,25.21],[2,1.47,1.54]],"batl":[[0,5.3,6.35],[1,5.7,39.87],[2,990,0.01]],"ltp":4.7,"tv":531.81,"id":19931652},{"batb":[[1,1.21,46.23],[2,1.19,23.51]],"batl":[[0,1.25,121.96],[1,1.28,156.24],[2,1.32,42.38]],"ltp":1.27,"tv":2517.83,"id":8257797}]}]}
{"op":"mcm","clk":"4230134832","pt":1631529397097,"mc":[{"id":"1.187557146","rc":[{"batb":[[1,4.2,29.98],[2,3.9,36.85]],"ltp":4.7,"tv":531.81,"id":19931652},{"batl":[[1,1.28,31.24]],"ltp":1.27,"tv":2517.83,"id":8257797}]}]}
{"op":"mcm","clk":"4230135392","pt":1631529404261,"mc":[{"id":"1.187557146","rc":[{"batb":[[0,1.23,107],[1,1.22,159.62],[2,1.21,46.23]],"ltp":1.27,"tv":2517.83,"id":8257797}]}]}
{"op":"mcm","clk":"4230135544","pt":1631529406185,"mc":[{"id":"1.187557146","rc":[{"trd":[[5,50.86]],"batb":[[0,5,27.35]],"ltp":5.0,"tv":533.09,"id":19931652},{"trd":[[1.25,237.27]],"batl":[[0,1.25,119.31]],"ltp":1.25,"tv":2523.12,"id":8257797}],"tv":3056.22}]}
{"op":"mcm","clk":"4230136948","pt":1631529425314,"mc":[{"id":"1.187557146","rc":[{"batl":[[1,1.32,42.38],[2,1.34,20.87]],"ltp":1.25,"tv":2523.12,"id":8257797}]}]}
{"op":"mcm","clk":"4230136995","pt":1631529426208,"mc":[{"id":"1.187557146","rc":[{"batb":[[0,3.9,36.85],[1,1.47,1.54],[2,1.36,768.11]],"batl":[[0,990,0.01],[1,5.7,0],[2,990,0]],"ltp":5.0,"tv":533.09,"id":19931652},{"batb":[[0,1.18,760.65],[1,1.01,105.88],[2,1.21,0]],"batl":[[0,1.58,660.85],[1,8.8,7.24],[2,44,7.24]],"ltp":1.25,"tv":2523.12,"id":8257797}]}]}
{"op":"mcm","clk":"4230137488","pt":1631529433120,"mc":[{"id":"1.187557146","rc":[{"batl":[[0,4.8,5.49],[1,5.1,7.84],[2,990,0.01]],"ltp":5.0,"tv":533.09,"id":19931652},{"batb":[[0,1.24,211.68],[1,1.22,22.92],[2,1.18,760.65]],"batl":[[0,1.28,228.31],[1,1.36,41.13],[2,1.38,20.27]],"ltp":1.25,"tv":2523.12,"id":8257797}]}]}
{"op":"mcm","clk":"4230137564","pt":1631529434103,"mc":[{"id":"1.187557146","rc":[{"batb":[[1,3.65,21.94],[2,1.47,1.54]],"ltp":5.0,"tv":533.09,"id":19931652},{"batb":[[0,1.25,138.51],[1,1.24,211.68],[2,1.22,22.92]],"ltp":1.25,"tv":2523.12,"id":8257797}]}]}
{"op":"mcm","clk":"4230137805","pt":1631529437224,"mc":[{"id":"1.187557146","rc":[{"trd":[[4.5,12.1]],"ltp":4.5,"tv":533.85,"id":19931652},{"trd":[[1.28,31.12]],"batl":[[0,1.28,222.89]],"ltp":1.28,"tv":2531.27,"id":8257797}],"tv":3065.12}]}
{"op":"mcm","clk":"4230138080","pt":1631529441326,"mc":[{"id":"1.187557146","rc":[{"batl":[[1,990,0.01],[2,990,0]],"ltp":4.5,"tv":533.85,"id":19931652},{"batb":[[0,1.26,95],[1,1.25,138.51],[2,1.24,211.68]],"ltp":1.28,"tv":2531.27,"id":8257797}]}]}
{"op":"mcm","clk":"4230138146","pt":1631529442108,"mc":[{"id":"1.187557146","rc":[{"batb":[[0,3.65,21.94],[1,1.47,1.54],[2,1.36,768.11]],"batl":[[0,990,0.01],[1,990,0]],"ltp":4.5,"tv":533.85,"id":19931652},{"batb":[[0,1.21,167.83],[1,1.18,558.4],[2,1.01,105.88]],"batl":[[0,1.58,660.85],[1,8.8,7.24],[2,44,7.24]],"ltp":1.28,"tv":2531.27,"id":8257797}]}]}
{"op":"mcm","clk":"4230138956","pt":1631529453914,"mc":[{"id":"1.187557146","rc":[{"batb":[[1,1.01,105.88],[2,1.01,0]],"ltp":1.28,"tv":2531.27,"id":8257797}]}]}
{"op":"mcm","clk":"4230139052","pt":1631529455149,"mc":[{"id":"1.187557146","rc":[{"batb":[[0,5.1,5.64],[1,4.6,8.7],[2,4.5,231.24]],"batl":[[0,6,27.77],[1,990,0.01]],"ltp":4.5,"tv":533.85,"id":19931652},{"batb":[[0,1.23,14.77],[1,1.21,214.06],[2,1.2,138.85]],"batl":[[0,1.31,42.7],[1,1.33,21.03],[2,1.58,660.85]],"ltp":1.28,"tv":2531.27,"id":8257797}]}]}
{"op":"mcm","clk":"4230139627","pt":1631529463135,"mc":[{"id":"1.187557146","rc":[{"batb":[[0,1.23,129.77]],"ltp":1.28,"tv":2531.27,"id":8257797}]}]}
{"op":"mcm","clk":"4230139853","pt":1631529466348,"mc":[{"id":"1.187557146","rc":[{"batb":[[0,1.23,14.77]],"ltp":1.28,"tv":2531.27,"id":8257797}]}]}
{"op":"mcm","clk":"4230139994","pt":1631529468272,"mc":[{"id":"1.187557146","rc":[{"batb":[[1,4.5,231.24],[2,4.3,27.89]],"ltp":4.5,"tv":533.85,"id":19931652}]}]}
{"op":"mcm","clk":"4230140034","pt":1631529468646,"mc":[{"id":"1.187557146","rc":[{"batb":[[0,3.95,35.68],[1,1.47,1.54],[2,1.36,768.11]],"batl":[[0,990,0.01],[1,990,0]],"ltp":4.5,"tv":533.85,"id":19931652},{"batb":[[0,1.16,222.26],[1,1.14,637.83],[2,1.01,105.88]],"batl":[[0,1.58,660.85],[1,8.8,7.24],[2,44,7.24]],"ltp":1.28,"tv":2531.27,"id":8257797}]}]}
{"op":"mcm","clk":"4230142713","pt":1631529501201,"mc":[{"id":"1.187557146","rc":[{"batb":[[1,1.01,105.88],[2,1.01,0]],"batl":[[0,8.8,7.24],[1,44,7.24],[2,50,7.24]],"ltp":1.28,"tv":2531.27,"id":8257797}]}]}
{"op":"mcm","clk":"4230142812","pt":1631529502296,"mc":[{"id":"1.187557146","rc":[{"batb":[[0,6.2,3.52],[1,6,35.28],[2,5.9,33.9]],"batl":[[0,7.6,71.84],[1,990,0.01]],"ltp":4.5,"tv":533.85,"id":19931652},{"batb":[[0,1.18,26.52],[1,1.16,222.26],[2,1.01,105.88]],"batl":[[0,1.2,176.38],[1,1.21,3409.92],[2,8.8,7.24]],"ltp":1.28,"tv":2531.27,"id":8257797}]}]}
{"op":"mcm","clk":"4230142911","pt":1631529503183,"mc":[{"id":"1.187557146","rc":[{"batb":[[2,5.9,6.78]],"ltp":4.5,"tv":533.85,"id":19931652},{"batb":[[1,1.16,270.49],[2,1.14,24.53]],"batl":[[1,1.26,44.4],[2,1.28,21.85]],"ltp":1.28,"tv":2531.27,"id":8257797}]}]}
{"op":"mcm","clk":"4230143285","pt":1631529507293,"mc":[{"id":"1.187557146","rc":[{"trd":[[6.2,6.3]],"batb":[[0,6,35.86],[1,5.9,6.78],[2,5.2,18.17]],"ltp":6.2,"tv":539.73,"id":19931652},{"batl":[[1,1.22,260.75],[2,1.26,44.4]],"ltp":1.28,"tv":2531.27,"id":8257797}],"tv":3071.0}]}
{"op":"mcm","clk":"4230143298","pt":1631529507497,"mc":[{"id":"1.187557146","rc":[{"batl":[[1,1.26,44.4],[2,1.28,21.85]],"ltp":1.28,"tv":2531.27,"id":8257797}]}]}
{"op":"mcm","clk":"4230143561","pt":1631529510505,"mc":[{"id":"1.187557146","rc":[{"batb":[[0,1.18,119.52]],"ltp":1.28,"tv":2531.27,"id":8257797}]}]}
{"op":"mcm","clk":"4230144160","pt":1631529517405,"mc":[{"id":"1.187557146","rc":[{"batb":[[0,6,35.28]],"ltp":6.2,"tv":539.73,"id":19931652},{"batb":[[0,1.18,93]],"ltp":1.28,"tv":2531.27,"id":8257797}]}]}
{"op":"mcm","clk":"4230144332","pt":1631529519529,"mc":[{"id":"1.187557146","rc":[{"batb":[[1,1.16,222.26],[2,1.11,1026.59]],"batl":[[1,1.49,773.7],[2,8.8,7.24]],"ltp":1.28,"tv":2531.27,"id":8257797}]}]}
{"op":"mcm","clk":"4230144400","pt":1631529520415,"mc":[{"id":"1.187557146","rc":[{"batl":[[0,6.4,4.13],[1,7.6,71.84],[2,990,0.01]],"ltp":6.2,"tv":539.73,"id":19931652},{"batl":[[0,1.2,190.55]],"ltp":1.28,"tv":2531.27,"id":8257797}]}]}
{"op":"mcm","clk":"4230144511","pt":1631529521944,"mc":[{"id":"1.187557146","rc":[{"batl":[[2,3.8,27.5]],"ltp":1.28,"tv":2531.27,"id":8257797}]}]}
{"op":"mcm","clk":"4230145063","pt":1631529529326,"mc":[{"id":"1.187557146","rc":[{"batb":[[0,5.2,18.17],[1,4.5,25.79],[2,1.47,1.54]],"batl":[[0,990,0.01],[1,7.6,0],[2,990,0]],"ltp":6.2,"tv":539.73,"id":19931652},{"batl":[[0,1.49,773.7],[1,3.8,27.5],[2,8.8,7.24]],"ltp":1.28,"tv":2531.27,"id":8257797}]}]}
{"op":"mcm","clk":"4230145093","pt":1631529529844,"mc":[{"id":"1.187557146","rc":[{"batb":[[0,4.5,25.79],[1,1.47,1.54],[2,1.36,768.11]],"ltp":6.2,"tv":539.73,"id":19931652},{"batb":[[0,1.11,1026.59],[1,1.01,105.88],[2,1.11,0]],"ltp":1.28,"tv":2531.27,"id":8257797}]}]}
{"op":"mcm","clk":"4230146235","pt":1631529544240,"mc":[{"id":"1.187557146","rc":[{"batb":[[0,1.28,2.17],[1,1.11,331.46],[2,1.01,105.88]],"ltp":1.28,"tv":2531.27,"id":8257797}]}]}
{"op":"mcm","clk":"4230146320","pt":1631529545331,"mc":[{"id":"1.187557146","rc":[{"batb":[[0,5.3,49.38],[1,4.5,25.79],[2,1.47,1.54]],"batl":[[0,5.5,6.06],[1,5.6,692.22],[2,6,33.34]],"ltp":6.2,"tv":539.73,"id":19931652},{"trd":[[1.28,35.46]],"batb":[[0,1.18,572.76]],"batl":[[0,1.24,20.12],[1,1.49,773.7],[2,3.8,27.5]],"ltp":1.28,"tv":2535.61,"id":8257797}],"tv":3075.35}]}
{"op":"mcm","clk":"4230146395","pt":1631529546164,"mc":[{"id":"1.187557146","rc":[{"batb":[[2,3.95,35.93]],"batl":[[1,6,6.66],[2,990,0.01]],"ltp":6.2,"tv":539.73,"id":19931652},{"batb":[[0,1.2,223.15],[1,1.18,596.46],[2,1.14,255.34]],"batl":[[1,1.31,42.7],[2,1.33,21.03]],"ltp":1.28,"tv":2535.61,"id":8257797}]}]}
{"op":"mcm","clk":"4230146583","pt":1631529548155,"mc":[{"id":"1.187557146","rc":[{"batb":[[2,1.14,893.17]],"ltp":1.28,"tv":2535.61,"id":8257797}]}]}
{"op":"mcm","clk":"4230146748","pt":1631529550175,"mc":[{"id":"1.187557146","rc":[{"trd":[[5.3,1.24]],"batb":[[0,5.3,48.76]],"ltp":5.3,"tv":540.97,"id":19931652}],"tv":3076.58}]}
{"op":"mcm","clk":"4230147004","pt":1631529553353,"mc":[{"id":"1.187557146","rc":[{"trd":[[5.5,6.82]],"batl":[[0,5.5,5.56]],"ltp":5.5,"tv":541.47,"id":19931652},{"trd":[[1.22,172.04]],"batb":[[0,1.22,82],[1,1.2,223.15],[2,1.18,596.46]],"ltp":1.22,"tv":2537.88,"id":8257797}],"tv":3079.36}]}
{"op":"mcm","clk":"4230147173","pt":1631529555582,"mc":[{"id":"1.187557146","rc":[{"batl":[[0,6,6.66],[1,990,0.01],[2,990,0]],"ltp":5.5,"tv":541.47,"id":19931652},{"batl":[[0,1.31,42.7],[1,1.33,21.03],[2,1.49,773.7]],"ltp":1.22,"tv":2537.88,"id":8257797}]}]}
{"op":"mcm","clk":"4230147421","pt":1631529558469,"mc":[{"id":"1.187557146","rc":[{"batl":[[0,5.5,6.06],[1,6,6.66],[2,990,0.01]],"ltp":5.5,"tv":541.47,"id":19931652},{"batl":[[0,1.24,22.28],[1,1.31,42.7],[2,1.33,21.03]],"ltp":1.22,"tv":2537.88,"id":8257797}]}]}
{"op":"mcm","clk":"4230147676","pt":1631529561160,"mc":[{"id":"1.187557146","rc":[{"batb":[[0,4.5,25.79],[1,3.95,35.93],[2,1.47,1.54]],"batl":[[0,990,0.01],[1,6,0],[2,990,0]],"ltp":5.5,"tv":541.47,"id":19931652},{"batb":[[2,1.18,23.7]],"batl":[[0,1.31,42.7],[1,1.33,21.03],[2,1.49,773.7]],"ltp":1.22,"tv":2537.88,"id":8257797}]}]}
{"op":"mcm","clk":"4230147716","pt":1631529561574,"mc":[{"id":"1.187557146","rc":[{"batb":[[0,3.95,35.93],[1,1.47,1.54],[2,1.36,768.11]],"ltp":5.5,"tv":541.47,"id":19931652},{"batb":[[0,1.14,893.17],[1,1.01,105.88],[2,1.18,0]],"batl":[[0,1.49,773.7],[1,3.8,27.5],[2,8.8,7.24]],"ltp":1.22,"tv":2537.88,"id":8257797}]}]}
{"op":"mcm","clk":"4230148426","pt":1631529569580,"mc":[{"id":"1.187557146","rc":[{"batl":[[0,1.15,2.17],[1,1.49,773.7],[2,3.8,27.5]],"ltp":1.22,"tv":2537.88,"id":8257797}]}]}
{"op":"mcm","clk":"4230148892","pt":1631529576008,"mc":[{"id":"1.187557146","rc":[{"batl":[[0,1.49,773.7],[1,3.8,27.5],[2,8.8,7.24]],"ltp":1.22,"tv":2537.88,"id":8257797}]}]}
{"op":"mcm","clk":"4230150045","pt":1631529592030,"mc":[{"id":"1.187557146","rc":[{"batb":[[0,1.33,2.17],[1,1.14,893.17],[2,1.01,105.88]],"ltp":1.22,"tv":2537.88,"id":8257797}]}]}
{"op":"mcm","clk":"4230150356","pt":1631529596235,"mc":[{"id":"1.187557146","rc":[{"batb":[[0,1.14,893.17],[1,1.01,105.88],[2,1.01,0]],"ltp":1.22,"tv":2537.88,"id":8257797}]}]}
{"op":"mcm","clk":"4230151127","pt":1631529605655,"mc":[{"id":"1.187557146","rc":[{"batl":[[0,1.15,2.17],[1,1.49,773.7],[2,3.8,27.5]],"ltp":1.22,"tv":2537.88,"id":8257797}]}]}
{"op":"mcm","clk":"4230151384","pt":1631529608826,"mc":[{"id":"1.187557146","rc":[{"batb":[[0,1.14,989.17]],"ltp":1.22,"tv":2537.88,"id":8257797}]}]}
{"op":"mcm","clk":"4230151477","pt":1631529610227,"mc":[{"id":"1.187557146","rc":[{"batl":[[0,1.49,773.7],[1,3.8,27.5],[2,8.8,7.24]],"ltp":1.22,"tv":2537.88,"id":8257797}]}]}
{"op":"mcm","clk":"4230151494","pt":1631529610436,"mc":[{"id":"1.187557146","rc":[{"batb":[[0,1.14,893.17]],"ltp":1.22,"tv":2537.88,"id":8257797}]}]}
{"op":"mcm","clk":"4230154223","pt":1631529645011,"mc":[{"id":"1.187557146","rc":[{"batl":[[0,1.15,2.17],[1,1.49,773.7],[2,3.8,27.5]],"ltp":1.22,"tv":2537.88,"id":8257797}]}]}
{"op":"mcm","clk":"4230154338","pt":1631529646309,"mc":[{"id":"1.187557146","rc":[{"trd":[[7.6,0.33]],"batl":[[0,7.2,5.39],[1,8.6,71.95],[2,990,0.01]],"ltp":7.6,"tv":541.8,"id":19931652},{"trd":[[1.15,2.17]],"batb":[[0,1.14,255.34]],"batl":[[0,1.18,1634.1],[1,1.2,166.66],[2,1.49,773.7]],"ltp":1.15,"tv":2540.05,"id":8257797}],"tv":3081.86}]}
{"op":"mcm","clk":"4230154408","pt":1631529647197,"mc":[{"id":"1.187557146","rc":[{"batb":[[0,5.6,29.73],[1,4.5,25.12],[2,1.47,1.54]],"ltp":7.6,"tv":541.8,"id":19931652},{"batb":[[0,1.15,48.64],[1,1.14,255.34],[2,1.13,24.75]],"batl":[[0,1.18,418.92],[1,1.2,33.34],[2,1.24,45.11]],"ltp":1.15,"tv":2540.05,"id":8257797}]}]}
{"op":"mcm","clk":"4230154676","pt":1631529651184,"mc":[{"id":"1.187557146","rc":[{"batl":[[1,1.2,366.11]],"ltp":1.15,"tv":2540.05,"id":8257797}]}]}
{"op":"mcm","clk":"4230154693","pt":1631529651390,"mc":[{"id":"1.187557146","rc":[{"batl":[[1,1.2,33.34]],"ltp":1.15,"tv":2540.05,"id":8257797}]}]}
{"op":"mcm","clk":"4230154934","pt":1631529654405,"mc":[{"id":"1.187557146","rc":[{"batb":[[0,1.16,201],[1,1.15,48.64],[2,1.14,255.34]],"ltp":1.15,"tv":2540.05,"id":8257797}]}]}
{"op":"mcm","clk":"4230155010","pt":1631529655499,"mc":[{"id":"1.187557146","rc":[{"trd":[[1.18,4.14]],"batl":[[0,1.18,416.85]],"ltp":1.18,"tv":2544.19,"id":8257797}],"tv":3086.0}]}
{"op":"mcm","clk":"4230155093","pt":1631529656487,"mc":[{"id":"1.187557146","rc":[{"batl":[[0,8.6,71.95],[1,990,0.01],[2,990,0]],"ltp":7.6,"tv":541.8,"id":19931652},{"batl":[[0,1.18,380.82]],"ltp":1.18,"tv":2544.19,"id":8257797}]}]}
{"op":"mcm","clk":"4230155333","pt":1631529659414,"mc":[{"id":"1.187557146","rc":[{"batl":[[0,7.2,5.71],[1,8.6,71.95],[2,990,0.01]],"ltp":7.6,"tv":541.8,"id":19931652},{"batl":[[0,1.18,418.99]],"ltp":1.18,"tv":2544.19,"id":8257797}]}]}
{"op":"mcm","clk":"4230155701","pt":1631529663303,"mc":[{"id":"1.187557146","rc":[{"batb":[[1,1.14,255.34],[2,1.09,791.35]],"batl":[[2,1.49,773.7]],"ltp":1.18,"tv":2544.19,"id":8257797}]}]}
{"op":"mcm","clk":"4230155781","pt":1631529664131,"mc":[{"id":"1.187557146","rc":[{"batb":[[0,4.5,25.12],[1,1.47,1.54],[2,1.36,768.11]],"batl":[[0,990,0.01],[1,8.6,0],[2,990,0]],"ltp":7.6,"tv":541.8,"id":19931652},{"batb":[[0,1.09,791.35],[1,1.06,503.48],[2,1.01,105.88]],"batl":[[0,1.49,773.7],[1,3.8,27.5],[2,8.8,7.24]],"ltp":1.18,"tv":2544.19,"id":8257797}]}]}
{"op":"mcm","clk":"4230155811","pt":1631529664395,"mc":[{"id":"1.187557146","rc":[{"trd":[[4.5,12.11]],"batb":[[0,4.5,25.11]],"ltp":4.5,"tv":541.81,"id":19931652},{"trd":[[1.29,45.87]],"ltp":1.29,"tv":2544.23,"id":8257797}],"tv":3086.04}]}
{"op":"mcm","clk":"4230155971","pt":1631529666317,"mc":[{"id":"1.187557146","rc":[{"batl":[[0,1.16,21.71],[1,1.49,773.7],[2,3.8,27.5]],"ltp":1.29,"tv":2544.23,"id":8257797}]}]}
{"op":"mcm","clk":"4230156175","pt":1631529669045,"mc":[{"id":"1.187557146","rc":[{"batb":[[0,1.06,503.48],[1,1.01,105.88],[2,1.01,0]],"batl":[[1,3.8,27.5],[2,8.8,7.24]],"ltp":1.29,"tv":2544.23,"id":8257797}]}]}
{"op":"mcm","clk":"4230156290","pt":1631529670341,"mc":[{"id":"1.187557146","rc":[{"batl":[[0,3.8,27.5],[1,8.8,7.24],[2,44,7.24]],"ltp":1.29,"tv":2544.23,"id":8257797}]}]}
{"op":"mcm","clk":"4230156813","pt":1631529677153,"mc":[{"id":"1.187557146","rc":[{"batb":[[0,1.08,837.7],[1,1.06,503.48],[2,1.01,105.88]],"batl":[[0,1.45,853.1],[1,3.8,27.5],[2,8.8,7.24]],"ltp":1.29,"tv":2544.23,"id":8257797}]}]}
{"op":"mcm","clk":"4230157575","pt":1631529687174,"mc":[{"id":"1.187557146","rc":[{"batl":[[0,1.39,17.79],[1,1.45,853.1],[2,3.8,27.5]],"ltp":1.29,"tv":2544.23,"id":8257797}]}]}
{"op":"mcm","clk":"4230157711","pt":1631529689161,"mc":[{"id":"1.187557146","rc":[{"batb":[[0,1.06,503.48],[1,1.01,105.88],[2,1.01,0]],"batl":[[1,3.8,27.5],[2,8.8,7.24]],"ltp":1.29,"tv":2544.23,"id":8257797}]}]}
{"op":"mcm","clk":"4230157911","pt":1631529691770,"mc":[{"id":"1.187557146","rc":[{"batb":[[0,1.28,2.17],[1,1.06,503.48],[2,1.01,105.88]],"ltp":1.29,"tv":2544.23,"id":8257797}]}]}
{"op":"mcm","clk":"4230158027","pt":1631529693278,"mc":[{"id":"1.187557146","rc":[{"batl":[[0,6.2,2.95],[1,990,0.01]],"ltp":4.5,"tv":541.81,"id":19931652}]}]}
{"op":"mcm","clk":"4230158075","pt":1631529694058,"mc":[{"id":"1.187557146","rc":[{"trd":[[4.6,14.42]],"batb":[[0,5.3,57.12],[1,4.5,25.11],[2,4,35.01]],"batl":[[0,5.5,3.49],[1,6,6.66],[2,6.4,61.57]],"ltp":4.6,"tv":542.41,"id":19931652},{"trd":[[1.28,37.64]],"batb":[[0,1.2,226.33],[1,1.18,23.7],[2,1.14,261.79]],"batl":[[0,1.3,43.03],[1,1.32,21.19],[2,1.39,17.79]],"ltp":1.28,"tv":2546.4,"id":8257797}],"tv":3088.82}]}
{"op":"mcm","clk":"4230158366","pt":1631529698272,"mc":[{"id":"1.187557146","rc":[{"trd":[[5.3,2.46]],"batb":[[0,5.3,56.51]],"ltp":5.3,"tv":543.63,"id":19931652}],"tv":3090.04}]}
{"op":"mcm","clk":"4230158517","pt":1631529700562,"mc":[{"id":"1.187557146","rc":[{"trd":[[5.5,7.32]],"batl":[[0,5.5,2.99]],"ltp":5.5,"tv":544.13,"id":19931652},{"trd":[[1.22,174.31]],"ltp":1.22,"tv":2548.67,"id":8257797}],"tv":3092.81}]}
{"op":"mcm","clk":"4230158587","pt":1631529701448,"mc":[{"id":"1.187557146","rc":[{"batb":[[0,1.22,99],[1,1.2,226.33],[2,1.18,23.7]],"ltp":1.22,"tv":2548.67,"id":8257797}]}]}
{"op":"mcm","clk":"4230158697","pt":1631529702553,"mc":[{"id":"1.187557146","rc":[{"batl":[[0,1.28,18.09],[1,1.3,43.03],[2,1.32,21.19]],"ltp":1.22,"tv":2548.67,"id":8257797}]}]}
{"op":"mcm","clk":"4230158926","pt":1631529705247,"mc":[{"id":"1.187557146","rc":[{"batl":[[0,1.3,43.03],[1,1.32,21.19],[2,1.39,17.79]],"ltp":1.22,"tv":2548.67,"id":8257797}]}]}
{"op":"mcm","clk":"4230159402","pt":1631529710985,"mc":[{"id":"1.187557146","rc":[{"batb":[[0,4,35.01],[1,1.47,1.54],[2,1.36,768.11]],"batl":[[0,990,0.01],[1,6,0],[2,6.4,0]],"ltp":5.5,"tv":544.13,"id":19931652},{"batb":[[0,1.14,261.79],[1,1.01,105.88],[2,1.18,0]],"batl":[[0,1.39,17.79],[1,3.8,27.5],[2,8.8,7.24]],"ltp":1.22,"tv":2548.67,"id":8257797}]}]}
{"op":"mcm","clk":"4230160306","pt":1631529722379,"mc":[{"id":"1.187557146","rc":[{"batl":[[0,1.15,2.17],[1,1.39,17.79],[2,3.8,27.5]],"ltp":1.22,"tv":2548.67,"id":8257797}]}]}
{"op":"mcm","clk":"4230160714","pt":1631529727789,"mc":[{"id":"1.187557146","rc":[{"batl":[[0,1.39,17.79],[1,3.8,27.5],[2,8.8,7.24]],"ltp":1.22,"tv":2548.67,"id":8257797}]}]}
{"op":"mcm","clk":"4230161046","pt":1631529732123,"mc":[{"id":"1.187557146","rc":[{"batl":[[0,3.8,27.5],[1,8.8,7.24],[2,44,7.24]],"ltp":1.22,"tv":2548.67,"id":8257797}]}]}
{"op":"mcm","clk":"4230162173","pt":1631529745808,"mc":[{"id":"1.187557146","rc":[{"batb":[[0,6.8,4.14],[1,4,35.01],[2,1.47,1.54]],"batl":[[0,7.2,3.38],[1,8.6,61.75],[2,990,0.01]],"ltp":5.5,"tv":544.13,"id":19931652},{"batb":[[0,1.14,310.86],[1,1.12,24.98],[2,1.01,105.88]],"batl":[[0,1.18,33.9],[1,1.24,965.35],[2,1.26,22.19]],"ltp":1.22,"tv":2548.67,"id":8257797}]}]}
{"op":"mcm","clk":"4230162267","pt":1631529746853,"mc":[{"id":"1.187557146","rc":[{"batb":[[1,5.7,28.64],[2,4.6,24.54]],"ltp":5.5,"tv":544.13,"id":19931652},{"batb":[[2,1.06,510.18]],"ltp":1.22,"tv":2548.67,"id":8257797}]}]}
{"op":"mcm","clk":"4230162872","pt":1631529753833,"mc":[{"id":"1.187557146","rc":[{"batb":[[0,1.16,86],[1,1.14,310.86],[2,1.12,24.98]],"ltp":1.22,"tv":2548.67,"id":8257797}]}]}
{"op":"mcm","clk":"4230163169","pt":1631529757224,"mc":[{"id":"1.187557146","rc":[{"trd":[[1.16,65.12]],"batb":[[0,1.16,53.45]],"ltp":1.16,"tv":2613.79,"id":8257797}],"tv":3157.93}]}
{"op":"mcm","clk":"4230163268","pt":1631529758268,"mc":[{"id":"1.187557146","rc":[{"batb":[[0,1.14,310.86],[1,1.12,24.98],[2,1.06,510.18]],"ltp":1.16,"tv":2613.79,"id":8257797}]}]}
{"op":"mcm","clk":"4230163537","pt":1631529761348,"mc":[{"id":"1.187557146","rc":[{"batb":[[0,1.17,330],[1,1.14,310.86],[2,1.12,24.98]],"ltp":1.16,"tv":2613.79,"id":8257797}]}]}
{"op":"mcm","clk":"4230163648","pt":1631529762867,"mc":[{"id":"1.187557146","rc":[{"batb":[[1,1.14,261.79],[2,1.06,510.18]],"batl":[[1,1.24,920.24],[2,3.8,27.5]],"ltp":1.16,"tv":2613.79,"id":8257797}]}]}
{"op":"mcm","clk":"4230164143","pt":1631529768969,"mc":[{"id":"1.187557146","rc":[{"batb":[[0,4.6,24.54],[1,1.47,1.54],[2,1.36,768.11]],"batl":[[0,990,0.01],[1,8.6,0],[2,990,0]],"ltp":5.5,"tv":544.13,"id":19931652},{"batb":[[0,1.06,510.18],[1,1.01,105.88],[2,1.06,0]],"batl":[[0,3.8,27.5],[1,8.8,7.24],[2,44,7.24]],"ltp":1.16,"tv":2613.79,"id":8257797}]}]}
{"op":"mcm","clk":"4230164600","pt":1631529775345,"mc":[{"id":"1.187557146","rc":[{"batl":[[0,5.5,7.28],[1,5.7,6.63],[2,6.4,48.52]],"ltp":5.5,"tv":544.13,"id":19931652},{"batb":[[0,1.2,46.62],[1,1.18,23.7],[2,1.06,510.18]],"batl":[[0,1.23,286.06],[1,1.3,43.03],[2,1.32,21.19]],"ltp":1.16,"tv":2613.79,"id":8257797}]}]}
{"op":"mcm","clk":"4230164674","pt":1631529776270,"mc":[{"id":"1.187557146","rc":[{"batb":[[1,4,34.42],[2,1.47,1.54]],"ltp":5.5,"tv":544.13,"id":19931652},{"batb":[[1,1.19,182.73],[2,1.18,23.7]],"ltp":1.16,"tv":2613.79,"id":8257797}]}]}
{"op":"mcm","clk":"4230165289","pt":1631529783288,"mc":[{"id":"1.187557146","rc":[{"batb":[[0,1.22,157],[1,1.2,46.62],[2,1.19,182.73]],"ltp":1.16,"tv":2613.79,"id":8257797}]}]}
{"op":"mcm","clk":"4230165767","pt":1631529789189,"mc":[{"id":"1.187557146","rc":[{"batb":[[0,4,34.42],[1,1.47,1.54],[2,1.36,768.11]],"batl":[[0,990,0.01],[1,5.7,0],[2,6.4,0]],"ltp":5.5,"tv":544.13,"id":19931652},{"batb":[[0,1.13,265.3],[1,1.01,105.88],[2,1.19,0]],"batl":[[0,3.8,27.5],[1,8.8,7.24],[2,44,7.24]],"ltp":1.16,"tv":2613.79,"id":8257797}]}]}
{"op":"mcm","clk":"4230166166","pt":1631529794277,"mc":[{"id":"1.187557146","rc":[{"batl":[[0,1.24,534.41],[1,3.8,27.5],[2,8.8,7.24]],"ltp":1.16,"tv":2613.79,"id":8257797}]}]}
{"op":"mcm","clk":"4230166184","pt":1631529794482,"mc":[{"id":"1.187557146","rc":[{"batl":[[0,3.8,27.5],[1,8.8,7.24],[2,44,7.24]],"ltp":1.16,"tv":2613.79,"id":8257797}]}]}
{"op":"mcm","clk":"4230166780","pt":1631529802004,"mc":[{"id":"1.187557146","rc":[{"batl":[[0,1.14,2.17],[1,3.8,27.5],[2,8.8,7.24]],"ltp":1.16,"tv":2613.79,"id":8257797}]}]}
{"op":"mcm","clk":"4230166968","pt":1631529804289,"mc":[{"id":"1.187557146","rc":[{"batl":[[1,1.39,17.79],[2,3.8,27.5]],"ltp":1.16,"tv":2613.79,"id":8257797}]}]}
{"op":"mcm","clk":"4230167142","pt":1631529806209,"mc":[{"id":"1.187557146","rc":[{"batl":[[0,1.39,17.79],[1,3.8,27.5],[2,8.8,7.24]],"ltp":1.16,"tv":2613.79,"id":8257797}]}]}
{"op":"mcm","clk":"4230167220","pt":1631529806890,"mc":[{"id":"1.187557146","rc":[{"batl":[[0,7.6,8.1],[1,8.6,51.1],[2,990,0.01]],"ltp":5.5,"tv":544.13,"id":19931652},{"batb":[[0,1.14,49.07],[1,1.13,265.3],[2,1.12,24.98]],"batl":[[0,1.17,312.59],[1,1.18,33.9],[2,1.24,45.11]],"ltp":1.16,"tv":2613.79,"id":8257797}]}]}
{"op":"mcm","clk":"4230167286","pt":1631529807621,"mc":[{"id":"1.187557146","rc":[{"batb":[[0,5.7,27.97],[1,4.6,23.87],[2,1.47,1.54]],"ltp":5.5,"tv":544.13,"id":19931652}]}]}
{"op":"mcm","clk":"4230167605","pt":1631529811212,"mc":[{"id":"1.187557146","rc":[{"batb":[[0,1.15,73],[1,1.14,49.07],[2,1.13,265.3]],"ltp":1.16,"tv":2613.79,"id":8257797}]}]}
{"op":"mcm","clk":"4230168196","pt":1631529818329,"mc":[{"id":"1.187557146","rc":[{"batb":[[0,1.14,49.07],[1,1.13,265.3],[2,1.12,24.98]],"ltp":1.16,"tv":2613.79,"id":8257797}]}]}
{"op":"mcm","clk":"4230168404","pt":1631529821380,"mc":[{"id":"1.187557146","rc":[{"batb":[[0,1.16,254],[1,1.14,49.07],[2,1.13,265.3]],"ltp":1.16,"tv":2613.79,"id":8257797}]}]}
{"op":"mcm","clk":"4230168573","pt":1631529823724,"mc":[{"id":"1.187557146","rc":[{"batb":[[1,1.13,265.3],[2,1.06,516.46]],"batl":[[2,1.39,17.79]],"ltp":1.16,"tv":2613.79,"id":8257797}]}]}
{"op":"mcm","clk":"4230169008","pt":1631529829144,"mc":[{"id":"1.187557146","rc":[{"batl":[[0,990,0.01],[1,8.6,0],[2,990,0]],"ltp":5.5,"tv":544.13,"id":19931652},{"batl":[[0,1.39,17.79],[1,3.8,27.5],[2,8.8,7.24]],"ltp":1.16,"tv":2613.79,"id":8257797}]}]}
{"op":"mcm","clk":"4230169093","pt":1631529830242,"mc":[{"id":"1.187557146","rc":[{"batb":[[0,4.6,23.87],[1,1.47,1.54],[2,1.36,768.11]],"ltp":5.5,"tv":544.13,"id":19931652},{"batb":[[0,1.06,516.46],[1,1.01,105.88],[2,1.06,0]],"ltp":1.16,"tv":2613.79,"id":8257797}]}]}
{"op":"mcm","clk":"4230169645","pt":1631529837318,"mc":[{"id":"1.187557146","rc":[{"batl":[[0,1.17,638.81],[1,1.39,17.79],[2,3.8,27.5]],"ltp":1.16,"tv":2613.79,"id":8257797}]}]}
{"op":"mcm","clk":"4230169652","pt":1631529837422,"mc":[{"id":"1.187557146","rc":[{"batl":[[0,1.39,17.79],[1,3.8,27.5],[2,8.8,7.24]],"ltp":1.16,"tv":2613.79,"id":8257797}]}]}
{"op":"mcm","clk":"4230169823","pt":1631529839312,"mc":[{"id":"1.187557146","rc":[{"batb":[[0,1.07,908.1],[1,1.06,516.46],[2,1.01,105.88]],"batl":[[1,1.43,886.16],[2,3.8,27.5]],"ltp":1.16,"tv":2613.79,"id":8257797}]}]}
{"op":"mcm","clk":"4230169995","pt":1631529841859,"mc":[{"id":"1.187557146","rc":[{"batl":[[0,1.43,886.16],[1,3.8,27.5],[2,8.8,7.24]],"ltp":1.16,"tv":2613.79,"id":8257797}]}]}
{"op":"mcm","clk":"4230170729","pt":1631529851567,"mc":[{"id":"1.187557146","rc":[{"batb":[[0,1.06,516.46],[1,1.01,105.88],[2,1.01,0]],"batl":[[0,3.8,27.5],[1,8.8,7.24],[2,44,7.24]],"ltp":1.16,"tv":2613.79,"id":8257797}]}]}
{"op":"mcm","clk":"4230170831","pt":1631529852867,"mc":[{"id":"1.187557146","rc":[{"batb":[[0,11,25.89],[1,4.6,23.87],[2,1.47,1.54]],"batl":[[0,13.5,3.55],[1,17.5,71],[2,990,0.01]],"ltp":5.5,"tv":544.13,"id":19931652},{"batb":[[0,1.08,96.2],[1,1.06,542.84],[2,1.01,105.88]],"batl":[[0,1.1,258.95],[1,1.11,36.04],[2,1.16,48.23]],"ltp":1.16,"tv":2613.79,"id":8257797}]}]}
{"op":"mcm","clk":"4230170900","pt":1631529853644,"mc":[{"id":"1.187557146","rc":[{"batb":[[1,8.8,24.03],[2,7.2,16.41]],"ltp":5.5,"tv":544.13,"id":19931652},{"batb":[[2,1.05,630.01]],"ltp":1.16,"tv":2613.79,"id":8257797}]}]}
{"op":"mcm","clk":"4230171082","pt":1631529856148,"mc":[{"id":"1.187557146","rc":[{"batb":[[0,1.08,336.2]],"ltp":1.16,"tv":2613.79,"id":8257797}]}]}
{"op":"mcm","clk":"4230177971","pt":1631529939751,"mc":[{"id":"1.187557146","rc":[{"batb":[[0,1.08,284.4],[1,1.06,516.46]],"batl":[[2,1.25,14.82]],"ltp":1.16,"tv":2613.79,"id":8257797}]}]}
{"op":"mcm","clk":"4230178316","pt":1631529943757,"mc":[{"id":"1.187557146","rc":[{"batb":[[0,7.2,16.41],[1,1.47,1.54],[2,1.36,768.11]],"batl":[[0,990,0.01],[1,17.5,0],[2,990,0]],"ltp":5.5,"tv":544.13,"id":19931652},{"batb":[[0,1.05,630.01],[1,1.03,1596.7],[2,1.01,105.88]],"batl":[[0,1.25,14.82],[1,1.35,1073.88],[2,1.39,17.79]],"ltp":1.16,"tv":2613.79,"id":8257797}]}]}
{"op":"mcm","clk":"4230179999","pt":1631529959200,"mc":[{"id":"1.187557146","rc":[{"batb":[[1,1.01,105.88],[2,1.01,0]],"ltp":1.16,"tv":2613.79,"id":8257797}]}]}
{"op":"mcm","clk":"4230180144","pt":1631529960288,"mc":[{"id":"1.187557146","rc":[{"batl":[[0,10,5.74],[1,11.5,3.48],[2,12,62.18]],"ltp":5.5,"tv":544.13,"id":19931652},{"batb":[[0,1.11,50.39],[1,1.09,25.66],[2,1.05,630.01]],"batl":[[0,1.13,551.21],[1,1.2,46.62],[2,1.22,22.92]],"ltp":1.16,"tv":2613.79,"id":8257797}]}]}
{"op":"mcm","clk":"4230180262","pt":1631529961216,"mc":[{"id":"1.187557146","rc":[{"batb":[[1,5.6,29.65],[2,1.47,1.54]],"ltp":5.5,"tv":544.13,"id":19931652},{"batb":[[1,1.09,394.3],[2,1.07,464.03]],"ltp":1.16,"tv":2613.79,"id":8257797}]}]}
{"op":"mcm","clk":"4230180958","pt":1631529966594,"mc":[{"id":"1.187557146","rc":[{"batb":[[0,1.11,366.39]],"ltp":1.16,"tv":2613.79,"id":8257797}]}]}
{"op":"mcm","clk":"4230181407","pt":1631529971340,"mc":[{"id":"1.187557146","rc":[{"batb":[[0,5.6,29.65],[1,1.47,1.54],[2,1.36,768.11]],"batl":[[0,990,0.01],[1,11.5,0],[2,12,0]],"ltp":5.5,"tv":544.13,"id":19931652},{"batb":[[0,1.07,464.03],[1,1.06,970.7],[2,1.01,105.88]],"batl":[[0,1.25,14.82],[1,1.35,1073.88],[2,1.39,17.79]],"ltp":1.16,"tv":2613.79,"id":8257797}]}]}
{"op":"mcm","clk":"4230182119","pt":1631529979520,"mc":[{"id":"1.187557146","rc":[{"batb":[[1,1.01,105.88],[2,1.01,0]],"ltp":1.16,"tv":2613.79,"id":8257797}]}]}
{"op":"mcm","clk":"4230182240","pt":1631529980817,"mc":[{"id":"1.187557146","rc":[{"batl":[[0,7.2,5.56],[1,7.6,7.53],[2,8.6,49.71]],"ltp":5.5,"tv":544.13,"id":19931652},{"batb":[[0,1.15,48.64],[1,1.13,24.75],[2,1.07,464.03]],"batl":[[0,1.17,348.04],[1,1.24,45.11],[2,1.25,14.82]],"ltp":1.16,"tv":2613.79,"id":8257797}]}]}
{"op":"mcm","clk":"4230182344","pt":1631529981806,"mc":[{"id":"1.187557146","rc":[{"batb":[[1,4.5,25.04],[2,1.47,1.54]],"ltp":5.5,"tv":544.13,"id":19931652},{"batb":[[1,1.14,256.18],[2,1.13,24.75]],"ltp":1.16,"tv":2613.79,"id":8257797}]}]}
{"op":"mcm","clk":"4230182550","pt":1631529984044,"mc":[{"id":"1.187557146","rc":[{"trd":[[7.2,11.12]],"batb":[[0,7.2,2],[1,5.6,29.65],[2,4.5,25.04]],"batl":[[0,7.6,7.53],[1,8.6,49.71],[2,990,0.01]],"ltp":7.2,"tv":555.25,"id":19931652}],"tv":3169.05}]}
{"op":"mcm","clk":"4230182649","pt":1631529985240,"mc":[{"id":"1.187557146","rc":[{"trd":[[6.8,0.5]],"batb":[[0,5.6,29.65],[1,4.5,25.04],[2,1.47,1.54]],"ltp":6.8,"tv":555.75,"id":19931652},{"trd":[[1.17,8.75]],"batl":[[0,1.17,342.21]],"ltp":1.17,"tv":2622.54,"id":8257797}],"tv":3178.3}]}
{"op":"mcm","clk":"4230182850","pt":1631529987225,"mc":[{"id":"1.187557146","rc":[{"batb":[[0,1.16,225],[1,1.15,48.64],[2,1.14,256.18]],"ltp":1.17,"tv":2622.54,"id":8257797}]}]}
{"op":"mcm","clk":"4230183056","pt":1631529989337,"mc":[{"id":"1.187557146","rc":[{"batb":[[0,4.5,25.04],[1,1.47,1.54],[2,1.36,768.11]],"batl":[[0,990,0.01],[1,8.6,0],[2,990,0]],"ltp":6.8,"tv":555.75,"id":19931652},{"batb":[[0,1.11,317.48],[1,1.08,837.7],[2,1.01,105.88]],"batl":[[0,1.25,14.82],[1,1.35,1073.88],[2,1.39,17.79]],"ltp":1.17,"tv":2622.54,"id":8257797}]}]}
{"op":"mcm","clk":"4230184286","pt":1631530002867,"mc":[{"id":"1.187557146","rc":[{"batb":[[1,1.01,105.88],[2,1.01,0]],"batl":[[1,1.39,17.79],[2,3.8,27.5]],"ltp":1.17,"tv":2622.54,"id":8257797}]}]}
{"op":"mcm","clk":"4230184423","pt":1631530004278,"mc":[{"id":"1.187557146","rc":[{"batb":[[0,5.5,48.95],[1,4.5,25.04],[2,1.47,1.54]],"batl":[[0,5.7,35.08],[1,990,0.01]],"ltp":6.8,"tv":555.75,"id":19931652},{"batb":[[0,1.19,47.01],[1,1.18,289.51],[2,1.17,23.91]],"batl":[[0,1.23,34.48],[1,1.25,14.82],[2,1.29,43.37]],"ltp":1.17,"tv":2622.54,"id":8257797}]}]}
{"op":"mcm","clk":"4230184520","pt":1631530005263,"mc":[{"id":"1.187557146","rc":[{"batb":[[2,3.9,36.68]],"batl":[[0,5.7,7.02]],"ltp":6.8,"tv":555.75,"id":19931652},{"batb":[[0,1.2,180.14],[1,1.19,47.01],[2,1.18,289.51]],"ltp":1.17,"tv":2622.54,"id":8257797}]}]}
{"op":"mcm","clk":"4230184856","pt":1631530009269,"mc":[{"id":"1.187557146","rc":[{"trd":[[5.5,8.68]],"batb":[[0,5.5,48.27]],"ltp":5.5,"tv":557.11,"id":19931652},{"trd":[[1.23,232.66]],"batl":[[0,1.23,31.56]],"ltp":1.23,"tv":2628.38,"id":8257797}],"tv":3185.5}]}
{"op":"mcm","clk":"4230185131","pt":1631530012294,"mc":[{"id":"1.187557146","rc":[{"batb":[[0,1.21,85],[1,1.2,180.14],[2,1.19,47.01]],"ltp":1.23,"tv":2628.38,"id":8257797}]}]}
{"op":"mcm","clk":"4230185662","pt":1631530018286,"mc":[{"id":"1.187557146","rc":[{"batb":[[0,3.9,36.68],[1,1.47,1.54],[2,1.36,768.11]],"batl":[[0,990,0.01],[1,990,0]],"ltp":5.5,"tv":557.11,"id":19931652},{"batb":[[0,1.17,211.04],[1,1.13,639.92],[2,1.01,105.88]],"batl":[[0,1.25,14.82],[1,1.39,17.79],[2,1.53,725.37]],"ltp":1.23,"tv":2628.38,"id":8257797}]}]}
{"op":"mcm","clk":"4230186835","pt":1631530032495,"mc":[{"id":"1.187557146","rc":[{"batl":[[0,1.39,17.79],[1,1.53,725.37],[2,3.8,27.5]],"ltp":1.23,"tv":2628.38,"id":8257797}]}]}
{"op":"mcm","clk":"4230187821","pt":1631530043324,"mc":[{"id":"1.187557146","rc":[{"batb":[[0,5.2,7.7],[1,3.9,36.68],[2,1.47,1.54]],"batl":[[0,6.4,4.2],[1,7.2,38.79],[2,990,0.01]],"ltp":5.5,"tv":557.11,"id":19931652},{"batb":[[0,1.17,258.85],[1,1.15,24.32]],"batl":[[0,1.2,13.97],[1,1.23,865.8],[2,1.27,44.05]],"ltp":1.23,"tv":2628.38,"id":8257797}]}]}
{"op":"mcm","clk":"4230187899","pt":1631530044203,"mc":[{"id":"1.187557146","rc":[{"batb":[[1,5,19.68],[2,4,34]],"ltp":5.5,"tv":557.11,"id":19931652},{"trd":[[1.2,4.34]],"batb":[[2,1.13,268.49]],"batl":[[0,1.2,11.8]],"ltp":1.2,"tv":2632.72,"id":8257797}],"tv":3189.84}]}
{"op":"mcm","clk":"4230188062","pt":1631530046219,"mc":[{"id":"1.187557146","rc":[{"trd":[[1.2,27.94]],"batl":[[0,1.23,865.8],[1,1.27,44.05],[2,1.29,21.68]],"ltp":1.2,"tv":2656.32,"id":8257797}],"tv":3213.44}]}
{"op":"mcm","clk":"4230188446","pt":1631530051302,"mc":[{"id":"1.187557146","rc":[{"trd":[[6.4,0.41]],"batl":[[0,6.4,3.79]],"ltp":6.4,"tv":557.52,"id":19931652},{"trd":[[1.18,6.35]],"batb":[[0,1.19,151],[1,1.17,258.85],[2,1.15,24.32]],"ltp":1.18,"tv":2658.53,"id":8257797}],"tv":3216.06}]}
{"op":"mcm","clk":"4230188464","pt":1631530051509,"mc":[{"id":"1.187557146","rc":[{"batb":[[0,1.17,258.85],[1,1.15,24.32],[2,1.13,268.49]],"ltp":1.18,"tv":2658.53,"id":8257797}]}]}
{"op":"mcm","clk":"4230188729","pt":1631530054217,"mc":[{"id":"1.187557146","rc":[{"batb":[[0,5,19.68],[1,4,34],[2,1.47,1.54]],"batl":[[0,990,0.01],[1,7.2,0],[2,990,0]],"ltp":6.4,"tv":557.52,"id":19931652},{"batl":[[0,1.27,44.05],[1,1.29,21.68],[2,1.39,17.79]],"ltp":1.18,"tv":2658.53,"id":8257797}]}]}
{"op":"mcm","clk":"4230188779","pt":1631530054841,"mc":[{"id":"1.187557146","rc":[{"batb":[[0,4,34],[1,1.47,1.54],[2,1.36,768.11]],"ltp":6.4,"tv":557.52,"id":19931652},{"batb":[[0,1.13,268.49],[1,1.11,695.13],[2,1.01,105.88]],"batl":[[0,1.39,17.79],[1,1.53,725.37],[2,3.8,27.5]],"ltp":1.18,"tv":2658.53,"id":8257797}]}]}
{"op":"mcm","clk":"4230188980","pt":1631530057121,"mc":[{"id":"1.187557146","rc":[{"batl":[[0,1.53,725.37],[1,3.8,27.5],[2,8.8,7.24]],"ltp":1.18,"tv":2658.53,"id":8257797}]}]}
{"op":"mcm","clk":"4230189648","pt":1631530065038,"mc":[{"id":"1.187557146","rc":[{"batb":[[0,1.32,2.17],[1,1.13,268.49]],"batl":[[0,3.8,27.5],[1,8.8,7.24],[2,44,7.24]],"ltp":1.18,"tv":2658.53,"id":8257797}]}]}
{"op":"mcm","clk":"4230189757","pt":1631530066330,"mc":[{"id":"1.187557146","rc":[{"batb":[[0,6.4,31.24],[1,4,34],[2,1.47,1.54]],"batl":[[0,7.6,4.47],[1,9.2,65.79],[2,990,0.01]],"ltp":6.4,"tv":557.52,"id":19931652},{"trd":[[1.32,13.26]],"batb":[[0,1.13,268.49],[1,1.01,105.88],[2,1.01,0]],"batl":[[0,1.16,292.23],[1,1.17,46.48],[2,3.8,27.5]],"ltp":1.32,"tv":2662.87,"id":8257797}],"tv":3220.4}]}
{"op":"mcm","clk":"4230189831","pt":1631530067158,"mc":[{"id":"1.187557146","rc":[{"batb":[[0,6.4,6.24],[1,5.8,27.47],[2,4.1,32.41]],"ltp":6.4,"tv":557.52,"id":19931652},{"batb":[[0,1.13,317.99],[1,1.11,25.2],[2,1.09,394.69]],"batl":[[2,1.23,45.48]],"ltp":1.32,"tv":2662.87,"id":8257797}]}]}
{"op":"mcm","clk":"4230190166","pt":1631530071249,"mc":[{"id":"1.187557146","rc":[{"trd":[[7.2,11.59]],"ltp":7.2,"tv":557.99,"id":19931652},{"trd":[[1.16,73.85]],"batl":[[0,1.16,286.41],[1,1.17,366.15]],"ltp":1.16,"tv":2671.6,"id":8257797}],"tv":3229.6}]}
{"op":"mcm","clk":"4230190180","pt":1631530071455,"mc":[{"id":"1.187557146","rc":[{"batl":[[1,1.17,46.48]],"ltp":1.16,"tv":2671.6,"id":8257797}]}]}
{"op":"mcm","clk":"4230190311","pt":1631530073169,"mc":[{"id":"1.187557146","rc":[{"trd":[[7.6,0.71]],"batl":[[0,7.6,4.09]],"ltp":7.6,"tv":558.37,"id":19931652},{"trd":[[1.15,4.67]],"ltp":1.15,"tv":2674.1,"id":8257797}],"tv":3232.47}]}
{"op":"mcm","clk":"4230190401","pt":1631530074361,"mc":[{"id":"1.187557146","rc":[{"batb":[[0,1.15,117],[1,1.13,317.99],[2,1.11,25.2]],"ltp":1.15,"tv":2674.1,"id":8257797}]}]}
{"op":"mcm","clk":"4230190787","pt":1631530079072,"mc":[{"id":"1.187557146","rc":[{"batb":[[0,5.8,27.47],[1,4.1,32.41],[2,1.47,1.54]],"batl":[[0,990,0.01],[1,9.2,0],[2,990,0]],"ltp":7.6,"tv":558.37,"id":19931652},{"batl":[[0,1.23,45.48],[1,1.25,22.38],[2,1.45,853.1]],"ltp":1.15,"tv":2674.1,"id":8257797}]}]}
{"op":"mcm","clk":"4230190843","pt":1631530079642,"mc":[{"id":"1.187557146","rc":[{"batb":[[0,4.1,32.41],[1,1.47,1.54],[2,1.36,768.11]],"ltp":7.6,"tv":558.37,"id":19931652},{"batb":[[0,1.09,394.69],[1,1.08,837.7],[2,1.01,105.88]],"batl":[[0,1.45,853.1],[1,3.8,27.5],[2,8.8,7.24]],"ltp":1.15,"tv":2674.1,"id":8257797}]}]}
{"op":"mcm","clk":"4230191362","pt":1631530085291,"mc":[{"id":"1.187557146","rc":[{"batl":[[0,3.8,27.5],[1,8.8,7.24],[2,44,7.24]],"ltp":1.15,"tv":2674.1,"id":8257797}]}]}
{"op":"mcm","clk":"4230191376","pt":1631530085447,"mc":[{"id":"1.187557146","rc":[{"batb":[[1,1.01,105.88],[2,1.01,0]],"ltp":1.15,"tv":2674.1,"id":8257797}]}]}
{"op":"mcm","clk":"4230191491","pt":1631530087050,"mc":[{"id":"1.187557146","rc":[{"batb":[[0,8.4,4.76],[1,4.1,32.41],[2,1.47,1.54]],"batl":[[0,11,5.51],[1,13.5,27.4],[2,990,0.01]],"ltp":7.6,"tv":558.37,"id":19931652},{"batb":[[0,1.09,446.01],[1,1.08,342.48],[2,1.07,26.14]],"batl":[[0,1.17,905.53],[1,1.18,47.41],[2,1.2,23.31]],"ltp":1.15,"tv":2674.1,"id":8257797}]}]}
{"op":"mcm","clk":"4230191548","pt":1631530087976,"mc":[{"id":"1.187557146","rc":[{"batb":[[1,7.4,14.66],[2,5.5,30.82]],"ltp":7.6,"tv":558.37,"id":19931652}]}]}
{"op":"mcm","clk":"4230191860","pt":1631530091299,"mc":[{"id":"1.187557146","rc":[{"trd":[[11,0.2]],"batl":[[0,11,5.31]],"ltp":11.0,"tv":558.57,"id":19931652},{"trd":[[1.1,2]],"ltp":1.1,"tv":2676.1,"id":8257797}],"tv":3234.67}]}
{"op":"mcm","clk":"4230192300","pt":1631530097182,"mc":[{"id":"1.187557146","rc":[{"batb":[[0,7.4,14.66],[1,5.5,30.82],[2,1.47,1.54]],"batl":[[0,990,0.01],[1,13.5,0],[2,990,0]],"ltp":11.0,"tv":558.57,"id":19931652},{"batb":[[1,1.07,26.14],[2,1.06,548.7]],"batl":[[0,1.18,47.41],[1,1.2,23.31],[2,1.38,988.33]],"ltp":1.1,"tv":2676.1,"id":8257797}]}]}
{"op":"mcm","clk":"4230192331","pt":1631530097705,"mc":[{"id":"1.187557146","rc":[{"batb":[[0,5.5,30.82],[1,1.47,1.54],[2,1.36,768.11]],"ltp":11.0,"tv":558.57,"id":19931652},{"batb":[[0,1.06,548.7],[1,1.05,1086.45],[2,1.01,105.88]],"batl":[[0,1.38,988.33],[1,3.8,27.5],[2,8.8,7.24]],"ltp":1.1,"tv":2676.1,"id":8257797}]}]}
{"op":"mcm","clk":"4230192923","pt":1631530105786,"mc":[{"id":"1.187557146","rc":[{"batb":[[1,1.01,105.88],[2,1.01,0]],"ltp":1.1,"tv":2676.1,"id":8257797}]}]}
{"op":"mcm","clk":"4230193077","pt":1631530107800,"mc":[{"id":"1.187557146","rc":[{"batb":[[0,10.5,3.8],[1,5.5,30.82],[2,1.47,1.54]],"batl":[[0,15,5.6],[1,17.5,34.34],[2,990,0.01]],"ltp":11.0,"tv":558.57,"id":19931652},{"batb":[[0,1.06,601.47],[1,1.04,26.89],[2,1.01,105.88]],"batl":[[0,1.09,85.53],[1,1.12,905.53],[2,1.14,49.07]],"ltp":1.1,"tv":2676.1,"id":8257797}]}]}
{"op":"mcm","clk":"4230193156","pt":1631530108580,"mc":[{"id":"1.187557146","rc":[{"batb":[[1,9.2,21.69],[2,7,16.5]],"ltp":11.0,"tv":558.57,"id":19931652},{"batb":[[1,1.04,727.92]],"ltp":1.1,"tv":2676.1,"id":8257797}]}]}
{"op":"mcm","clk":"4230193245","pt":1631530109529,"mc":[{"id":"1.187557146","rc":[{"batb":[[2,1.03,1596.7]],"ltp":1.1,"tv":2676.1,"id":8257797}]}]}
{"op":"mcm","clk":"4230193754","pt":1631530116093,"mc":[{"id":"1.187557146","rc":[{"batb":[[0,7,16.5],[1,1.47,1.54],[2,1.36,768.11]],"batl":[[0,990,0.01],[1,17.5,0],[2,990,0]],"ltp":11.0,"tv":558.57,"id":19931652},{"batb":[[0,1.04,701.03],[1,1.03,1596.7],[2,1.01,105.88]],"batl":[[0,1.38,988.33],[1,3.8,27.5],[2,8.8,7.24]],"ltp":1.1,"tv":2676.1,"id":8257797}]}]}
{"op":"mcm","clk":"4230194526","pt":1631530126445,"mc":[{"id":"1.187557146","rc":[{"batl":[[1,1.39,17.79],[2,3.8,27.5]],"ltp":1.1,"tv":2676.1,"id":8257797}]}]}
{"op":"mcm","clk":"4230194686","pt":1631530128212,"mc":[{"id":"1.187557146","rc":[{"batb":[[1,1.01,105.88],[2,1.01,0]],"ltp":1.1,"tv":2676.1,"id":8257797}]}]}
{"op":"mcm","clk":"4230194776","pt":1631530129248,"mc":[{"id":"1.187557146","rc":[{"batb":[[0,11,3.64],[1,7,16.5],[2,1.47,1.54]],"batl":[[0,21,9.2],[1,990,0.01]],"ltp":11.0,"tv":558.57,"id":19931652},{"batb":[[0,1.06,31.85],[1,1.05,183.91],[2,1.04,754.82]],"batl":[[0,1.07,717.45],[1,1.12,49.95],[2,1.14,24.53]],"ltp":1.1,"tv":2676.1,"id":8257797}]}]}
{"op":"mcm","clk":"4230194835","pt":1631530130026,"mc":[{"id":"1.187557146","rc":[{"batb":[[1,10.5,14.24],[2,9.6,18.84]],"ltp":11.0,"tv":558.57,"id":19931652}]}]}
{"op":"mcm","clk":"4230195339","pt":1631530135914,"mc":[{"id":"1.187557146","rc":[{"batb":[[0,1.06,148.85]],"ltp":1.1,"tv":2676.1,"id":8257797}]}]}
{"op":"mcm","clk":"4230196559","pt":1631530149869,"mc":[{"id":"1.187557146","rc":[{"trd":[[1.06,3.42]],"batb":[[0,1.06,147.14]],"ltp":1.06,"tv":2679.52,"id":8257797}],"tv":3238.09}]}
{"op":"mcm","clk":"4230197394","pt":1631530159237,"mc":[{"id":"1.187557146","rc":[{"batb":[[0,9.6,18.84],[1,1.47,1.54],[2,1.36,768.11]],"batl":[[0,990,0.01],[1,990,0]],"ltp":11.0,"tv":558.57,"id":19931652},{"batb":[[0,1.03,927.81],[1,1.02,2218.56],[2,1.01,105.88]],"batl":[[0,1.38,988.33],[1,1.39,17.79],[2,3.8,27.5]],"ltp":1.06,"tv":2679.52,"id":8257797}]}]}
{"op":"mcm","clk":"4230197815","pt":1631530164285,"mc":[{"id":"1.187557146","rc":[{"batl":[[0,1.08,983.19],[1,1.38,988.33],[2,1.39,17.79]],"ltp":1.06,"tv":2679.52,"id":8257797}]}]}
{"op":"mcm","clk":"4230197838","pt":1631530164492,"mc":[{"id":"1.187557146","rc":[{"batl":[[0,1.38,988.33],[1,1.39,17.79],[2,3.8,27.5]],"ltp":1.06,"tv":2679.52,"id":8257797}]}]}
{"op":"mcm","clk":"4230198173","pt":1631530168759,"mc":[{"id":"1.187557146","rc":[{"batl":[[0,1.06,2.17],[1,1.38,988.33],[2,1.39,17.79]],"ltp":1.06,"tv":2679.52,"id":8257797}]}]}
{"op":"mcm","clk":"4230199052","pt":1631530180182,"mc":[{"id":"1.187557146","rc":[{"batb":[[1,1.01,105.88],[2,1.01,0]],"batl":[[1,1.19,14.82],[2,1.25,14.82]],"ltp":1.06,"tv":2679.52,"id":8257797}]}]}
{"op":"mcm","clk":"4230199139","pt":1631530181183,"mc":[{"id":"1.187557146","rc":[{"trd":[[17.5,0.13]],"batb":[[0,13.5,23.63],[1,9.6,18.84],[2,1.47,1.54]],"batl":[[0,16.5,2.42],[1,21,31.53],[2,990,0.01]],"ltp":17.5,"tv":558.7,"id":19931652},{"trd":[[1.06,5.59]],"batb":[[0,1.07,30.4],[1,1.05,683.95],[2,1.03,954.97]],"batl":[[0,1.08,327.12],[1,1.14,49.07],[2,1.16,24.11]],"ltp":1.06,"tv":2681.69,"id":8257797}],"tv":3240.39}]}
{"op":"mcm","clk":"4230199227","pt":1631530182110,"mc":[{"id":"1.187557146","rc":[{"batb":[[2,8.8,23.36]],"ltp":17.5,"tv":558.7,"id":19931652},{"batb":[[1,1.05,1277.78],[2,1.04,737.46]],"ltp":1.06,"tv":2681.69,"id":8257797}]}]}
{"op":"mcm","clk":"4230199522","pt":1631530185190,"mc":[{"id":"1.187557146","rc":[{"batb":[[0,1.07,167.4]],"ltp":1.06,"tv":2681.69,"id":8257797}]}]}
{"op":"mcm","clk":"4230200118","pt":1631530192234,"mc":[{"id":"1.187557146","rc":[{"batb":[[0,8.8,23.36],[1,1.47,1.54],[2,1.36,768.11]],"batl":[[0,990,0.01],[1,21,0],[2,990,0]],"ltp":17.5,"tv":558.7,"id":19931652},{"batb":[[0,1.04,737.46],[1,1.03,1596.7],[2,1.01,105.88]],"batl":[[0,1.19,14.82],[1,1.21,14.82],[2,1.23,29.65]],"ltp":1.06,"tv":2681.69,"id":8257797}]}]}
{"op":"mcm","clk":"4230200921","pt":1631530201947,"mc":[{"id":"1.187557146","rc":[{"batl":[[0,15,7.79],[1,17.5,52.85],[2,990,0.01]],"ltp":17.5,"tv":558.7,"id":19931652},{"batb":[[0,1.07,37.38],[1,1.06,52.78],[2,1.04,764.35]],"batl":[[0,1.09,652.11],[1,1.15,48.64],[2,1.17,23.91]],"ltp":1.06,"tv":2681.69,"id":8257797}]}]}
{"op":"mcm","clk":"4230201015","pt":1631530202836,"mc":[{"id":"1.187557146","rc":[{"batb":[[1,8.2,27.55],[2,1.47,1.54]],"ltp":17.5,"tv":558.7,"id":19931652},{"batb":[[1,1.06,578.11],[2,1.05,611.17]],"ltp":1.06,"tv":2681.69,"id":8257797}]}]}
{"op":"mcm","clk":"4230201690","pt":1631530210261,"mc":[{"id":"1.187557146","rc":[{"batb":[[0,1.08,233],[1,1.07,37.38],[2,1.06,578.11]],"ltp":1.06,"tv":2681.69,"id":8257797}]}]}
{"op":"mcm","clk":"4230201945","pt":1631530213448,"mc":[{"id":"1.187557146","rc":[{"trd":[[12,0.09]],"ltp":12.0,"tv":558.79,"id":19931652},{"trd":[[1.09,1.02]],"batl":[[0,1.09,651.09]],"ltp":1.09,"tv":2682.71,"id":8257797}],"tv":3241.51}]}
{"op":"mcm","clk":"4230202127","pt":1631530215340,"mc":[{"id":"1.187557146","rc":[{"batl":[[0,990,0.01],[1,17.5,0],[2,990,0]],"ltp":12.0,"tv":558.79,"id":19931652},{"batb":[[0,1.06,525.33],[1,1.05,611.17],[2,1.03,1596.7]],"batl":[[0,1.19,14.82],[1,1.21,14.82],[2,1.23,29.65]],"ltp":1.09,"tv":2682.71,"id":8257797}]}]}
{"op":"mcm","clk":"4230202137","pt":1631530215441,"mc":[{"id":"1.187557146","rc":[{"batb":[[0,8.2,27.55],[1,1.47,1.54],[2,1.36,768.11]],"ltp":12.0,"tv":558.79,"id":19931652},{"batb":[[0,1.05,611.17],[1,1.03,1596.7],[2,1.01,105.88]],"ltp":1.09,"tv":2682.71,"id":8257797}]}]}
{"op":"mcm","clk":"4230203266","pt":1631530227647,"mc":[{"id":"1.187557146","rc":[{"batl":[[0,1.17,29.65],[1,1.19,14.82],[2,1.21,14.82]],"ltp":1.09,"tv":2682.71,"id":8257797}]}]}
{"op":"mcm","clk":"4230203728","pt":1631530233060,"mc":[{"id":"1.187557146","rc":[{"batb":[[1,1.01,105.88],[2,1.01,0]],"ltp":1.09,"tv":2682.71,"id":8257797}]}]}
{"op":"mcm","clk":"4230203899","pt":1631530235094,"mc":[{"id":"1.187557146","rc":[{"batb":[[0,11,3.79],[1,8.2,27.55],[2,1.47,1.54]],"batl":[[0,13,3.08],[1,13.5,6.65],[2,15,32.84]],"ltp":12.0,"tv":558.79,"id":19931652},{"batb":[[0,1.07,52.28],[1,1.05,637.81],[2,1.01,105.88]],"batl":[[0,1.09,266.49],[1,1.1,37.91],[2,1.16,48.23]],"ltp":1.09,"tv":2682.71,"id":8257797}]}]}
{"op":"mcm","clk":"4230203984","pt":1631530235994,"mc":[{"id":"1.187557146","rc":[{"batb":[[2,8,12.14]],"ltp":12.0,"tv":558.79,"id":19931652},{"batb":[[1,1.06,528.43],[2,1.05,26.64]],"ltp":1.09,"tv":2682.71,"id":8257797}]}]}
{"op":"mcm","clk":"4230204579","pt":1631530243070,"mc":[{"id":"1.187557146","rc":[{"batb":[[0,1.08,86],[1,1.07,52.28],[2,1.06,528.43]],"ltp":1.09,"tv":2682.71,"id":8257797}]}]}
{"op":"mcm","clk":"4230204651","pt":1631530244201,"mc":[{"id":"1.187557146","rc":[{"batb":[[0,8.2,27.55],[1,8,12.14],[2,1.47,1.54]],"batl":[[0,990,0.01],[1,13.5,0],[2,15,0]],"ltp":12.0,"tv":558.79,"id":19931652},{"batl":[[0,1.16,48.23],[1,1.17,29.65],[2,1.18,23.7]],"ltp":1.09,"tv":2682.71,"id":8257797}]}]}
{"op":"mcm","clk":"4230204691","pt":1631530244779,"mc":[{"id":"1.187557146","rc":[{"batb":[[0,8,12.14],[1,1.47,1.54],[2,1.36,768.11]],"ltp":12.0,"tv":558.79,"id":19931652},{"batb":[[0,1.06,528.43],[1,1.04,1282.94],[2,1.01,105.88]],"batl":[[0,1.17,29.65],[1,1.19,14.82],[2,1.21,14.82]],"ltp":1.09,"tv":2682.71,"id":8257797}]}]}
{"op":"mcm","clk":"4230204774","pt":1631530246015,"mc":[{"id":"1.187557146","rc":[{"batb":[[0,1.09,90.16],[1,1.06,528.43],[2,1.04,1282.94]],"ltp":1.09,"tv":2682.71,"id":8257797}]}]}
{"op":"mcm","clk":"4230204996","pt":1631530249286,"mc":[{"id":"1.187557146","rc":[{"batb":[[0,1.06,528.43],[1,1.04,1282.94],[2,1.01,105.88]],"ltp":1.09,"tv":2682.71,"id":8257797}]}]}
{"op":"mcm","clk":"4230205871","pt":1631530260620,"mc":[{"id":"1.187557146","rc":[{"batb":[[1,1.01,105.88],[2,1.01,0]],"ltp":1.09,"tv":2682.71,"id":8257797}]}]}
{"op":"mcm","clk":"4230206017","pt":1631530261817,"mc":[{"id":"1.187557146","rc":[{"batl":[[0,17.5,56.45],[1,990,0.01]],"ltp":12.0,"tv":558.79,"id":19931652},{"batb":[[0,1.06,581.21],[1,1.04,26.89],[2,1.01,105.88]],"batl":[[0,1.09,630.69],[1,1.11,36.04],[2,1.15,48.64]],"ltp":1.09,"tv":2682.71,"id":8257797}]}]}
{"op":"mcm","clk":"4230206105","pt":1631530262701,"mc":[{"id":"1.187557146","rc":[{"batb":[[0,8.8,23.11],[1,8.4,27.3],[2,1.47,1.54]],"ltp":12.0,"tv":558.79,"id":19931652},{"batb":[[1,1.05,604.64],[2,1.04,26.89]],"ltp":1.09,"tv":2682.71,"id":8257797}]}]}
{"op":"mcm","clk":"4230206748","pt":1631530270240,"mc":[{"id":"1.187557146","rc":[{"batb":[[0,1.07,133],[1,1.06,581.21],[2,1.05,604.64]],"ltp":1.09,"tv":2682.71,"id":8257797}]}]}
{"op":"mcm","clk":"4230206919","pt":1631530272208,"mc":[{"id":"1.187557146","rc":[{"trd":[[1.07,10.4]],"batb":[[0,1.06,581.21],[1,1.05,604.64],[2,1.04,26.89]],"ltp":1.07,"tv":2693.11,"id":8257797}],"tv":3251.91}]}
{"op":"mcm","clk":"4230207220","pt":1631530275310,"mc":[{"id":"1.187557146","rc":[{"batb":[[0,8.4,27.3],[1,1.47,1.54],[2,1.36,768.11]],"batl":[[0,990,0.01],[1,990,0]],"ltp":12.0,"tv":558.79,"id":19931652},{"batb":[[0,1.08,327],[2,1.03,1596.7]],"batl":[[0,1.17,29.65],[1,1.19,14.82],[2,1.21,14.82]],"ltp":1.07,"tv":2693.11,"id":8257797}]}]}
{"op":"mcm","clk":"4230207235","pt":1631530275510,"mc":[{"id":"1.187557146","rc":[{"batb":[[0,1.05,604.64],[1,1.03,1596.7],[2,1.01,105.88]],"ltp":1.07,"tv":2693.11,"id":8257797}]}]}
{"op":"mcm","clk":"4230207345","pt":1631530276651,"mc":[{"id":"1.187557146","rc":[{"batb":[[0,1.09,90.16],[1,1.05,604.64],[2,1.03,1596.7]],"ltp":1.07,"tv":2693.11,"id":8257797}]}]}
{"op":"mcm","clk":"4230207627","pt":1631530280163,"mc":[{"id":"1.187557146","rc":[{"batb":[[0,1.05,604.64],[1,1.03,1596.7],[2,1.01,105.88]],"ltp":1.07,"tv":2693.11,"id":8257797}]}]}
{"op":"mcm","clk":"4230207837","pt":1631530282749,"mc":[{"id":"1.187557146","rc":[{"batb":[[0,11,3.71],[1,8.4,27.3],[2,1.47,1.54]],"batl":[[0,13.5,3.4],[1,15,36.51],[2,990,0.01]],"ltp":12.0,"tv":558.79,"id":19931652},{"batb":[[0,1.08,42.51],[1,1.07,52.28],[2,1.05,631.28]],"batl":[[0,1.09,257.83],[1,1.1,37.13],[2,1.16,48.23]],"ltp":1.07,"tv":2693.11,"id":8257797}]}]}
{"op":"mcm","clk":"4230207938","pt":1631530283840,"mc":[{"id":"1.187557146","rc":[{"batb":[[2,6.6,20.1]],"ltp":12.0,"tv":558.79,"id":19931652},{"batb":[[1,1.07,531.55]],"ltp":1.07,"tv":2693.11,"id":8257797}]}]}
{"op":"mcm","clk":"4230208573","pt":1631530292163,"mc":[{"id":"1.187557146","rc":[{"trd":[[12,3.2]],"ltp":12.0,"tv":561.9,"id":19931652},{"trd":[[1.09,35.26]],"batl":[[0,1.09,223.59]],"ltp":1.09,"tv":2727.35,"id":8257797}],"tv":3289.26}]}
{"op":"mcm","clk":"4230208593","pt":1631530292475,"mc":[{"id":"1.187557146","rc":[{"trd":[[1.09,215.58]],"batl":[[0,1.09,133.43]],"ltp":1.09,"tv":2907.67,"id":8257797}],"tv":3469.58}]}
{"op":"mcm","clk":"4230209065","pt":1631530298478,"mc":[{"id":"1.187557146","rc":[{"trd":[[1.08,4]],"batb":[[0,1.08,40.51]],"ltp":1.08,"tv":2911.67,"id":8257797}],"tv":3473.58}]}
{"op":"mcm","clk":"4230209958","pt":1631530308649,"mc":[{"id":"1.187557146","rc":[{"batb":[[0,8.4,27.3],[1,6.6,20.1],[2,1.47,1.54]],"batl":[[0,15,36.51],[1,990,0.01],[2,990,0]],"ltp":12.0,"tv":561.9,"id":19931652},{"batb":[[0,1.07,531.55],[1,1.05,631.28],[2,1.03,1596.7]],"batl":[[1,1.16,48.23],[2,1.18,23.7]],"ltp":1.08,"tv":2911.67,"id":8257797}]}]}
{"op":"mcm","clk":"4230210215","pt":1631530311971,"mc":[{"id":"1.187557146","rc":[{"batb":[[0,11,3.81],[1,8.4,27.3],[2,6.6,20.1]],"batl":[[0,13.5,6.64],[1,15,36.51],[2,990,0.01]],"ltp":12.0,"tv":561.9,"id":19931652},{"batl":[[1,1.1,38.12],[2,1.16,48.23]],"ltp":1.08,"tv":2911.67,"id":8257797}]}]}
{"op":"mcm","clk":"4230215026","pt":1631530369745,"mc":[{"id":"1.187557146","rc":[{"batb":[[0,1.07,479.27],[1,1.05,604.64]],"batl":[[2,1.18,90.16]],"ltp":1.08,"tv":2911.67,"id":8257797}]}]}
{"op":"mcm","clk":"4230215692","pt":1631530380134,"mc":[{"id":"1.187557146","rc":[{"batb":[[0,8.4,27.3],[1,6.6,20.1],[2,1.47,1.54]],"batl":[[0,990,0.01],[1,15,0],[2,990,0]],"ltp":12.0,"tv":561.9,"id":19931652},{"batl":[[0,1.18,90.16],[1,1.19,14.82],[2,1.21,14.82]],"ltp":1.08,"tv":2911.67,"id":8257797}]}]}
{"op":"mcm","clk":"4230215717","pt":1631530380547,"mc":[{"id":"1.187557146","rc":[{"batb":[[0,6.6,20.1],[1,1.47,1.54],[2,1.36,768.11]],"ltp":12.0,"tv":561.9,"id":19931652},{"batb":[[0,1.05,604.64],[1,1.03,1596.7],[2,1.01,105.88]],"ltp":1.08,"tv":2911.67,"id":8257797}]}]}
{"op":"mcm","clk":"4230216049","pt":1631530385270,"mc":[{"id":"1.187557146","rc":[{"batb":[[1,1.01,105.88],[2,1.01,0]],"ltp":1.08,"tv":2911.67,"id":8257797}]}]}
{"op":"mcm","clk":"4230216252","pt":1631530388742,"mc":[{"id":"1.187557146","rc":[{"batb":[[1,1.04,1282.94],[2,1.01,105.88]],"ltp":1.08,"tv":2911.67,"id":8257797}]}]}
{"op":"mcm","clk":"4230218181","pt":1631530416276,"mc":[{"id":"1.187557146","rc":[{"batb":[[1,1.01,105.88],[2,1.01,0]],"ltp":1.08,"tv":2911.67,"id":8257797}]}]}
{"op":"mcm","clk":"4230218270","pt":1631530417306,"mc":[{"id":"1.187557146","rc":[{"batb":[[0,11.5,17.4],[1,11,39.01],[2,6.6,20.1]],"batl":[[0,17.5,7.58],[1,21,30.36],[2,990,0.01]],"ltp":12.0,"tv":561.9,"id":19931652},{"batb":[[0,1.05,1265.13],[1,1.03,27.16],[2,1.01,105.88]],"batl":[[0,1.08,40.4],[1,1.1,390.06],[2,1.13,49.5]],"ltp":1.08,"tv":2911.67,"id":8257797}]}]}
{"op":"mcm","clk":"4230218345","pt":1631530418188,"mc":[{"id":"1.187557146","rc":[{"batb":[[0,11.5,3.48],[2,10,17.5]],"ltp":12.0,"tv":561.9,"id":19931652},{"batb":[[1,1.03,806.99]],"ltp":1.08,"tv":2911.67,"id":8257797}]}]}
{"op":"mcm","clk":"4230218484","pt":1631530420095,"mc":[{"id":"1.187557146","rc":[{"batb":[[2,1.02,2218.56]],"ltp":1.08,"tv":2911.67,"id":8257797}]}]}
{"op":"mcm","clk":"4230219586","pt":1631530434290,"mc":[{"id":"1.187557146","rc":[{"batb":[[0,7.8,12.9],[1,1.47,1.54],[2,1.36,768.11]],"batl":[[0,990,0.01],[1,21,0],[2,990,0]],"ltp":12.0,"tv":561.9,"id":19931652},{"batb":[[0,1.03,779.83],[1,1.02,2218.56],[2,1.01,105.88]],"batl":[[0,1.18,90.16],[1,1.19,14.82],[2,1.21,14.82]],"ltp":1.08,"tv":2911.67,"id":8257797}]}]}
{"op":"mcm","clk":"4230220008","pt":1631530439727,"mc":[{"id":"1.187557146","rc":[{"batb":[[1,1.01,105.88],[2,1.01,0]],"ltp":1.08,"tv":2911.67,"id":8257797}]}]}
{"op":"mcm","clk":"4230220130","pt":1631530441230,"mc":[{"id":"1.187557146","rc":[{"batb":[[0,12.5,16],[1,7.8,12.9],[2,1.47,1.54]],"batl":[[0,21,5.69],[1,26,26.24],[2,990,0.01]],"ltp":12.0,"tv":561.9,"id":19931652},{"batb":[[0,1.04,655.97],[1,1.03,779.83],[2,1.01,105.88]],"batl":[[0,1.06,27.15],[1,1.07,780.11],[2,1.18,90.16]],"ltp":1.08,"tv":2911.67,"id":8257797}]}]}
{"op":"mcm","clk":"4230220208","pt":1631530442325,"mc":[{"id":"1.187557146","rc":[{"batb":[[0,12.5,3.2],[1,11.5,11.81],[2,9.4,20.18]],"ltp":12.0,"tv":561.9,"id":19931652},{"batb":[[0,1.04,709.76],[2,1.02,27.42]],"batl":[[2,1.12,49.95]],"ltp":1.08,"tv":2911.67,"id":8257797}]}]}
{"op":"mcm","clk":"4230220520","pt":1631530446316,"mc":[{"id":"1.187557146","rc":[{"batl":[[2,1.08,15.08]],"ltp":1.08,"tv":2911.67,"id":8257797}]}]}
{"op":"mcm","clk":"4230220529","pt":1631530446416,"mc":[{"id":"1.187557146","rc":[{"batl":[[2,1.12,49.95]],"ltp":1.08,"tv":2911.67,"id":8257797}]}]}
{"op":"mcm","clk":"4230220796","pt":1631530450354,"mc":[{"id":"1.187557146","rc":[{"batb":[[0,11.5,11.81],[1,9.4,20.18],[2,1.47,1.54]],"batl":[[0,990,0.01],[1,26,0],[2,990,0]],"ltp":12.0,"tv":561.9,"id":19931652},{"batb":[[0,1.04,53.79]],"batl":[[0,1.12,49.95],[1,1.14,24.53],[2,1.18,90.16]],"ltp":1.08,"tv":2911.67,"id":8257797}]}]}
{"op":"mcm","clk":"4230220842","pt":1631530450824,"mc":[{"id":"1.187557146","rc":[{"batb":[[0,9.4,20.18],[1,1.47,1.54],[2,1.36,768.11]],"ltp":12.0,"tv":561.9,"id":19931652},{"batb":[[0,1.03,779.83],[1,1.01,4236.55],[2,1.02,0]],"batl":[[0,1.18,90.16],[1,1.19,14.82],[2,1.21,14.82]],"ltp":1.08,"tv":2911.67,"id":8257797}]}]}
{"op":"mcm","clk":"4230221369","pt":1631530457354,"mc":[{"id":"1.187557146","rc":[{"batb":[[0,13,15.38],[1,9.4,20.18],[2,1.47,1.54]],"batl":[[0,26,13.95],[1,990,0.01]],"ltp":12.0,"tv":561.9,"id":19931652},{"batb":[[0,1.04,348.66],[1,1.03,779.83],[2,1.01,4236.55]],"batl":[[0,1.06,905.46],[1,1.18,90.16],[2,1.19,14.82]],"ltp":1.08,"tv":2911.67,"id":8257797}]}]}
{"op":"mcm","clk":"4230221459","pt":1631530458344,"mc":[{"id":"1.187557146","rc":[{"batb":[[0,13,11.71],[1,11,12.39]],"ltp":12.0,"tv":561.9,"id":19931652},{"batb":[[1,1.03,834.14],[2,1.02,1057.78]],"batl":[[1,1.11,50.39],[2,1.13,24.75]],"ltp":1.08,"tv":2911.67,"id":8257797}]}]}
{"op":"mcm","clk":"4230222022","pt":1631530465359,"mc":[{"id":"1.187557146","rc":[{"batb":[[0,11,12.39],[1,1.47,1.54],[2,1.36,768.11]],"batl":[[0,990,0.01],[1,990,0]],"ltp":12.0,"tv":561.9,"id":19931652},{"batb":[[0,1.03,54.31],[1,1.02,1057.78],[2,1.01,4264.25]],"batl":[[0,1.11,50.39],[1,1.13,24.75],[2,1.18,90.16]],"ltp":1.08,"tv":2911.67,"id":8257797}]}]}
{"op":"mcm","clk":"4230222038","pt":1631530465557,"mc":[{"id":"1.187557146","rc":[{"batb":[[0,1.02,1057.78],[1,1.01,4236.55],[2,1.01,0]],"batl":[[0,1.18,90.16],[1,1.19,14.82],[2,1.21,14.82]],"ltp":1.08,"tv":2911.67,"id":8257797}]}]}
{"op":"mcm","clk":"4230223233","pt":1631530483164,"mc":[{"id":"1.187557146","rc":[{"trd":[[17.5,22.97]],"batb":[[0,17.5,7.11],[1,11,12.39],[2,1.47,1.54]],"batl":[[0,21,5.27],[1,26,25.84],[2,990,0.01]],"ltp":17.5,"tv":584.74,"id":19931652},{"batb":[[0,1.04,646],[1,1.03,54.31],[2,1.02,1057.78]],"batl":[[0,1.06,34.2],[1,1.11,50.39],[2,1.13,24.75]],"ltp":1.08,"tv":2911.67,"id":8257797}],"tv":3496.42}]}
{"op":"mcm","clk":"4230223305","pt":1631530484187,"mc":[{"id":"1.187557146","rc":[{"batb":[[2,9.2,20.77]],"ltp":17.5,"tv":584.74,"id":19931652},{"batb":[[0,1.04,1404.9],[1,1.03,963.36]],"ltp":1.08,"tv":2911.67,"id":8257797}]}]}
{"op":"mcm","clk":"4230223347","pt":1631530484966,"mc":[{"id":"1.187557146","rc":[{"batb":[[2,1.01,4264.25]],"ltp":1.08,"tv":2911.67,"id":8257797}]}]}
{"op":"mcm","clk":"4230223432","pt":1631530486465,"mc":[{"id":"1.187557146","rc":[{"trd":[[21,0.14]],"batl":[[0,21,5.13]],"ltp":21.0,"tv":584.88,"id":19931652},{"trd":[[1.05,2.9]],"ltp":1.05,"tv":2914.56,"id":8257797}],"tv":3499.45}]}
{"op":"mcm","clk":"4230223936","pt":1631530493977,"mc":[{"id":"1.187557146","rc":[{"batl":[[1,1.07,214.83],[2,1.11,50.39]],"ltp":1.05,"tv":2914.56,"id":8257797}]}]}
{"op":"mcm","clk":"4230224119","pt":1631530496703,"mc":[{"id":"1.187557146","rc":[{"batl":[[0,26,25.84],[1,990,0.01],[2,990,0]],"ltp":21.0,"tv":584.88,"id":19931652},{"trd":[[1.06,10.89]],"batl":[[0,1.07,214.83],[1,1.11,50.39],[2,1.13,24.75]],"ltp":1.06,"tv":2919.86,"id":8257797}],"tv":3504.75}]}
{"op":"mcm","clk":"4230224219","pt":1631530498199,"mc":[{"id":"1.187557146","rc":[{"batb":[[0,11,12.39],[1,9.2,20.77],[2,1.47,1.54]],"batl":[[0,990,0.01],[1,990,0]],"ltp":21.0,"tv":584.88,"id":19931652},{"batb":[[0,1.04,758.9]],"ltp":1.06,"tv":2919.86,"id":8257797}]}]}
{"op":"mcm","clk":"4230224259","pt":1631530498715,"mc":[{"id":"1.187557146","rc":[{"batb":[[0,9.2,20.77],[1,1.47,1.54],[2,1.36,768.11]],"ltp":21.0,"tv":584.88,"id":19931652},{"batb":[[0,1.03,909.05],[1,1.01,4236.55],[2,1.01,0]],"batl":[[1,1.19,14.82],[2,1.21,14.82]],"ltp":1.06,"tv":2919.86,"id":8257797}]}]}
{"op":"mcm","clk":"4230224444","pt":1631530501313,"mc":[{"id":"1.187557146","rc":[{"batb":[[0,11.5,5.2],[1,9.2,20.77],[2,1.47,1.54]],"ltp":21.0,"tv":584.88,"id":19931652}]}]}
{"op":"mcm","clk":"4230224452","pt":1631530501419,"mc":[{"id":"1.187557146","rc":[{"batb":[[0,9.2,20.77],[1,1.47,1.54],[2,1.36,768.11]],"ltp":21.0,"tv":584.88,"id":19931652}]}]}
{"op":"mcm","clk":"4230225497","pt":1631530515323,"mc":[{"id":"1.187557146","rc":[{"batb":[[0,16,2.5],[1,9.2,20.77],[2,1.47,1.54]],"batl":[[0,26,17.38],[1,990,0.01]],"ltp":21.0,"tv":584.88,"id":19931652},{"batb":[[0,1.04,434.43],[1,1.03,909.05],[2,1.02,54.84]],"batl":[[0,1.06,719.53],[1,1.07,214.83],[2,1.1,50.85]],"ltp":1.06,"tv":2919.86,"id":8257797}]}]}
{"op":"mcm","clk":"4230225570","pt":1631530516211,"mc":[{"id":"1.187557146","rc":[{"batb":[[1,12.5,9.13],[2,11.5,12.23]],"ltp":21.0,"tv":584.88,"id":19931652}]}]}
{"op":"mcm","clk":"4230227368","pt":1631530540352,"mc":[{"id":"1.187557146","rc":[{"batb":[[0,12.5,9.13],[1,11.5,12.23],[2,1.47,1.54]],"batl":[[0,990,0.01],[1,990,0]],"ltp":21.0,"tv":584.88,"id":19931652},{"batb":[[0,1.03,909.05],[1,1.01,4236.55],[2,1.02,0]],"batl":[[0,1.07,214.83],[1,1.19,14.82],[2,1.21,14.82]],"ltp":1.06,"tv":2919.86,"id":8257797}]}]}
{"op":"mcm","clk":"4230227381","pt":1631530540560,"mc":[{"id":"1.187557146","rc":[{"batb":[[0,11.5,12.23],[1,1.47,1.54],[2,1.36,768.11]],"ltp":21.0,"tv":584.88,"id":19931652},{"batb":[[0,1.01,4236.55],[1,1.01,0]],"ltp":1.06,"tv":2919.86,"id":8257797}]}]}
{"op":"mcm","clk":"4230227465","pt":1631530541859,"mc":[{"id":"1.187557146","rc":[{"batl":[[1,1.17,29.65],[2,1.19,14.82]],"ltp":1.06,"tv":2919.86,"id":8257797}]}]}
{"op":"mcm","clk":"4230227793","pt":1631530546578,"mc":[{"id":"1.187557146","rc":[{"trd":[[1.07,10.45]],"batl":[[0,1.07,214.81]],"ltp":1.07,"tv":2919.91,"id":8257797}],"tv":3504.8}]}
{"op":"mcm","clk":"4230228071","pt":1631530550672,"mc":[{"id":"1.187557146","rc":[{"batl":[[0,1.05,90.16],[1,1.07,214.81],[2,1.17,29.65]],"ltp":1.07,"tv":2919.91,"id":8257797}]}]}
{"op":"mcm","clk":"4230228509","pt":1631530557270,"mc":[{"id":"1.187557146","rc":[{"trd":[[50,0.06]],"batb":[[0,21,14.79],[1,19,2.1],[2,11.5,12.23]],"batl":[[0,34,25.24],[1,990,0.01]],"ltp":50.0,"tv":584.94,"id":19931652},{"trd":[[1.02,2.9]],"batb":[[0,1.01,188.96]],"batl":[[0,1.04,19.98],[1,1.05,386],[2,1.07,214.81]],"ltp":1.02,"tv":2922.8,"id":8257797}],"tv":3507.75}]}
{"op":"mcm","clk":"4230228596","pt":1631530558205,"mc":[{"id":"1.187557146","rc":[{"batb":[[2,15,11.22]],"ltp":50.0,"tv":584.94,"id":19931652}]}]}
{"op":"mcm","clk":"4230228801","pt":1631530560907,"mc":[{"id":"1.187557146","rc":[{"batl":[[1,160,37.69],[2,990,0.01]],"ltp":50.0,"tv":584.94,"id":19931652}]}]}
{"op":"mcm","clk":"4230229180","pt":1631530566302,"mc":[{"id":"1.187557146","rc":[{"batb":[[0,15,11.22],[1,13,8.54],[2,1.47,1.54]],"batl":[[0,160,37.69],[1,990,0.01],[2,990,0]],"ltp":50.0,"tv":584.94,"id":19931652},{"batb":[[0,1.01,105.88]],"batl":[[0,1.05,90.16],[1,1.07,214.81],[2,1.17,29.65]],"ltp":1.02,"tv":2922.8,"id":8257797}]}]}
{"op":"mcm","clk":"4230229196","pt":1631530566511,"mc":[{"id":"1.187557146","rc":[{"batb":[[0,13,8.54],[1,1.47,1.54],[2,1.36,768.11]],"ltp":50.0,"tv":584.94,"id":19931652}]}]}
{"op":"mcm","clk":"4230229338","pt":1631530568586,"mc":[{"id":"1.187557146","rc":[{"batb":[[0,1.01,12]],"ltp":1.02,"tv":2922.8,"id":8257797}]}]}
{"op":"mcm","clk":"4230230350","pt":1631530582129,"mc":[{"id":"1.187557146","rc":[{"batl":[[0,990,0.01],[1,990,0]],"ltp":50.0,"tv":584.94,"id":19931652}]}]}
{"op":"mcm","clk":"4230230491","pt":1631530584009,"mc":[{"id":"1.187557146","rc":[{"batl":[[0,26,14.98],[1,32,1.24],[2,990,0.01]],"ltp":50.0,"tv":584.94,"id":19931652},{"batb":[[0,1.04,232],[1,1.02,54.84],[2,1.01,39.69]],"batl":[[0,1.05,107.02],[1,1.06,594.62],[2,1.07,214.81]],"ltp":1.02,"tv":2922.8,"id":8257797}]}]}
{"op":"mcm","clk":"4230230526","pt":1631530584532,"mc":[{"id":"1.187557146","rc":[{"batb":[[1,11.5,11.81],[2,1.47,1.54]],"ltp":50.0,"tv":584.94,"id":19931652},{"batb":[[1,1.02,998.48]],"ltp":1.02,"tv":2922.8,"id":8257797}]}]}
{"op":"mcm","clk":"4230230608","pt":1631530586148,"mc":[{"id":"1.187557146","rc":[{"trd":[[1.05,8.42]],"batb":[[2,1.01,3978.35]],"batl":[[0,1.05,104.26]],"ltp":1.05,"tv":2928.33,"id":8257797}],"tv":3513.28}]}
{"op":"mcm","clk":"4230231073","pt":1631530592051,"mc":[{"id":"1.187557146","rc":[{"batb":[[0,1.04,356]],"ltp":1.05,"tv":2928.33,"id":8257797}]}]}
{"op":"mcm","clk":"4230231166","pt":1631530593354,"mc":[{"id":"1.187557146","rc":[{"trd":[[1.04,22.78]],"batb":[[0,1.04,344.61]],"ltp":1.04,"tv":2951.11,"id":8257797}],"tv":3536.06}]}
{"op":"mcm","clk":"4230231304","pt":1631530595123,"mc":[{"id":"1.187557146","rc":[{"batl":[[0,990,0.01],[1,32,0],[2,990,0]],"ltp":50.0,"tv":584.94,"id":19931652},{"batb":[[0,1.04,124]],"batl":[[0,1.05,87.4],[1,1.07,214.81],[2,1.1,50.85]],"ltp":1.04,"tv":2951.11,"id":8257797}]}]}
{"op":"mcm","clk":"4230231379","pt":1631530596225,"mc":[{"id":"1.187557146","rc":[{"batb":[[0,11.5,11.81],[1,1.47,1.54],[2,1.36,768.11]],"ltp":50.0,"tv":584.94,"id":19931652},{"batb":[[0,1.01,3950.65],[1,1.02,0],[2,1.01,0]],"batl":[[2,1.17,29.65]],"ltp":1.04,"tv":2951.11,"id":8257797}]}]}
{"op":"mcm","clk":"4230231634","pt":1631530599726,"mc":[{"id":"1.187557146","rc":[{"trd":[[1.05,8.52]],"batl":[[0,1.05,87.35]],"ltp":1.05,"tv":2951.21,"id":8257797}],"tv":3536.16}]}
{"op":"mcm","clk":"4230231941","pt":1631530604542,"mc":[{"id":"1.187557146","rc":[{"batb":[[0,1.01,12]],"ltp":1.05,"tv":2951.21,"id":8257797}]}]}
{"op":"mcm","clk":"4230232049","pt":1631530606157,"mc":[{"id":"1.187557146","rc":[{"batb":[[0,26,9.17],[1,18.5,2.16],[2,16,9.21]],"batl":[[0,50,46.37],[1,990,0.01]],"ltp":50.0,"tv":584.94,"id":19931652},{"batb":[[0,1.01,95.08]],"batl":[[0,1.04,285.82],[1,1.05,87.35],[2,1.07,214.81]],"ltp":1.05,"tv":2951.21,"id":8257797}]}]}
{"op":"mcm","clk":"4230232208","pt":1631530608347,"mc":[{"id":"1.187557146","rc":[{"batl":[[1,160,37.69],[2,990,0.01]],"ltp":50.0,"tv":584.94,"id":19931652}]}]}
{"op":"mcm","clk":"4230232717","pt":1631530615094,"mc":[{"id":"1.187557146","rc":[{"batb":[[0,13.5,7.79],[1,1.47,1.54],[2,1.36,768.11]],"batl":[[0,160,37.69],[1,990,0.01],[2,990,0]],"ltp":50.0,"tv":584.94,"id":19931652},{"batb":[[0,1.01,12]],"batl":[[0,1.05,87.35],[1,1.07,214.81],[2,1.17,29.65]],"ltp":1.05,"tv":2951.21,"id":8257797}]}]}
{"op":"mcm","clk":"4230232826","pt":1631530616709,"mc":[{"id":"1.187557146","rc":[{"batl":[[0,990,0.01],[1,990,0]],"ltp":50.0,"tv":584.94,"id":19931652}]}]}
{"op":"mcm","clk":"4230233277","pt":1631530622099,"mc":[{"id":"1.187557146","rc":[{"batl":[[0,520,36.08],[1,990,0.01]],"ltp":50.0,"tv":584.94,"id":19931652},{"batl":[[0,1.02,2.9],[1,1.05,87.35],[2,1.07,214.81]],"ltp":1.05,"tv":2951.21,"id":8257797}]}]}
{"op":"mcm","clk":"4230233490","pt":1631530624923,"mc":[{"id":"1.187557146","rc":[{"batl":[[0,990,0.01],[1,990,0]],"ltp":50.0,"tv":584.94,"id":19931652}]}]}
{"op":"mcm","clk":"4230234000","pt":1631530632199,"mc":[{"id":"1.187557146","rc":[{"batl":[[0,1.05,87.35],[1,1.07,214.81],[2,1.17,29.65]],"ltp":1.05,"tv":2951.21,"id":8257797}]}]}
{"op":"mcm","clk":"4230234493","pt":1631530639111,"mc":[{"id":"1.187557146","rc":[{"batb":[[0,28,1.42],[1,13.5,7.79],[2,1.47,1.54]],"batl":[[0,100,31.69],[1,990,0.01]],"ltp":50.0,"tv":584.94,"id":19931652},{"batl":[[0,1.02,68.11],[1,1.03,606.01],[2,1.05,87.35]],"ltp":1.05,"tv":2951.21,"id":8257797}]}]}
{"op":"mcm","clk":"4230234565","pt":1631530639902,"mc":[{"id":"1.187557146","rc":[{"batb":[[1,23,4.84],[2,18,6.36]],"ltp":50.0,"tv":584.94,"id":19931652}]}]}
{"op":"mcm","clk":"4230235108","pt":1631530648002,"mc":[{"id":"1.187557146","rc":[{"batb":[[0,23,4.84],[1,18,6.36],[2,1.47,1.54]],"batl":[[0,990,0.01],[1,990,0]],"ltp":50.0,"tv":584.94,"id":19931652},{"batl":[[0,1.05,87.35],[1,1.06,52.78],[2,1.07,214.81]],"ltp":1.05,"tv":2951.21,"id":8257797}]}]}
{"op":"mcm","clk":"4230235194","pt":1631530649199,"mc":[{"id":"1.187557146","rc":[{"batb":[[0,18,6.36],[1,1.47,1.54],[2,1.36,768.11]],"ltp":50.0,"tv":584.94,"id":19931652},{"batl":[[1,1.07,214.81],[2,1.17,29.65]],"ltp":1.05,"tv":2951.21,"id":8257797}]}]}
{"op":"mcm","clk":"4230236636","pt":1631530667031,"mc":[{"id":"1.187557146","rc":[{"batb":[[0,1.04,3.62],[1,1.01,12]],"ltp":1.05,"tv":2951.21,"id":8257797}]}]}
{"op":"mcm","clk":"4230236901","pt":1631530670671,"mc":[{"id":"1.187557146","rc":[{"trd":[[1.01,24.01],[1.04,30.02]],"batl":[[0,1.01,159.45],[1,1.05,87.35],[2,1.07,214.81]],"ltp":1.01,"tv":2982.46,"id":8257797}],"tv":3567.41}]}
{"op":"mcm","clk":"4230237318","pt":1631530676353,"mc":[{"id":"1.187557146","rc":[{"trd":[[100,1.61]],"batb":[[0,26,12.12],[1,18,6.36],[2,1.47,1.54]],"batl":[[0,42,223.57],[1,46,4.34],[2,50,27.4]],"ltp":100.0,"tv":586.55,"id":19931652},{"trd":[[1.01,183.46]],"batl":[[0,1.03,49.6],[1,1.04,303],[2,1.05,87.35]],"ltp":1.01,"tv":3141.91,"id":8257797}],"tv":3728.47}]}
{"op":"mcm","clk":"4230237388","pt":1631530677237,"mc":[{"id":"1.187557146","rc":[{"batb":[[2,13.5,7.54]],"batl":[[0,50,28.26],[1,990,0.01],[2,50,0]],"ltp":100.0,"tv":586.55,"id":19931652}]}]}
{"op":"mcm","clk":"4230237525","pt":1631530679265,"mc":[{"id":"1.187557146","rc":[{"batl":[[1,520,36.08],[2,990,0.01]],"ltp":100.0,"tv":586.55,"id":19931652}]}]}
{"op":"mcm","clk":"4230237944","pt":1631530684754,"mc":[{"id":"1.187557146","rc":[{"batl":[[2,1.07,214.81]],"ltp":1.01,"tv":3141.91,"id":8257797}]}]}
{"op":"mcm","clk":"4230239439","pt":1631530703273,"mc":[{"id":"1.187557146","rc":[{"batb":[[0,18,6.36],[1,13.5,7.54],[2,1.47,1.54]],"batl":[[0,520,36.94],[1,990,0.01],[2,990,0]],"ltp":100.0,"tv":586.55,"id":19931652},{"batl":[[0,1.07,214.81],[1,1.13,14.82],[2,1.15,14.82]],"ltp":1.01,"tv":3141.91,"id":8257797}]}]}
{"op":"mcm","clk":"4230239467","pt":1631530703685,"mc":[{"id":"1.187557146","rc":[{"batb":[[0,13.5,7.54],[1,1.47,1.54],[2,1.36,768.11]],"ltp":100.0,"tv":586.55,"id":19931652}]}]}
{"op":"mcm","clk":"4230239571","pt":1631530705081,"mc":[{"id":"1.187557146","rc":[{"batl":[[0,990,0.87],[1,990,0]],"ltp":100.0,"tv":586.55,"id":19931652}]}]}
{"op":"mcm","clk":"4230240999","pt":1631530725000,"mc":[{"id":"1.187557146","rc":[{"batl":[[0,26,3.92],[1,34,47.88],[2,990,0.87]],"ltp":100.0,"tv":586.55,"id":19931652},{"batb":[[0,1.02,54.84],[1,1.01,27.69]],"batl":[[0,1.05,34.84],[1,1.06,606.01],[2,1.07,214.81]],"ltp":1.01,"tv":3141.91,"id":8257797}]}]}
{"op":"mcm","clk":"4230241054","pt":1631530725621,"mc":[{"id":"1.187557146","rc":[{"batb":[[1,11.5,12.23],[2,1.47,1.54]],"ltp":100.0,"tv":586.55,"id":19931652},{"batb":[[0,1.02,1067.15]],"ltp":1.01,"tv":3141.91,"id":8257797}]}]}
{"op":"mcm","clk":"4230241149","pt":1631530726723,"mc":[{"id":"1.187557146","rc":[{"batb":[[1,1.01,3966.35]],"ltp":1.01,"tv":3141.91,"id":8257797}]}]}
{"op":"mcm","clk":"4230241645","pt":1631530732895,"mc":[{"id":"1.187557146","rc":[{"batb":[[0,1.04,164],[1,1.02,1067.15],[2,1.01,3966.35]],"ltp":1.01,"tv":3141.91,"id":8257797}]}]}
{"op":"mcm","clk":"4230241746","pt":1631530734132,"mc":[{"id":"1.187557146","rc":[{"batb":[[0,11.5,12.23],[1,1.47,1.54],[2,1.36,768.11]],"batl":[[0,990,0.01],[1,34,0],[2,990,0]],"ltp":100.0,"tv":586.55,"id":19931652},{"batb":[[1,1.01,3938.65],[2,1.01,0]],"batl":[[0,1.07,214.81],[1,1.13,14.82],[2,1.15,14.82]],"ltp":1.01,"tv":3141.91,"id":8257797}]}]}
{"op":"mcm","clk":"4230241833","pt":1631530735333,"mc":[{"id":"1.187557146","rc":[{"batb":[[0,1.01,3938.65],[1,1.01,0]],"ltp":1.01,"tv":3141.91,"id":8257797}]}]}
{"op":"mcm","clk":"4230243436","pt":1631530758142,"mc":[{"id":"1.187557146","rc":[{"batl":[[0,16.5,2.42],[1,21,15.55],[2,990,0.01]],"ltp":100.0,"tv":586.55,"id":19931652},{"batb":[[0,1.05,185.45],[1,1.03,54.31],[2,1.01,27.69]],"batl":[[0,1.07,914.1],[1,1.11,50.39],[2,1.13,39.58]],"ltp":1.01,"tv":3141.91,"id":8257797}]}]}
{"op":"mcm","clk":"4230243510","pt":1631530758863,"mc":[{"id":"1.187557146","rc":[{"batb":[[1,10,16.25],[2,1.47,1.54]],"ltp":100.0,"tv":586.55,"id":19931652},{"batb":[[1,1.04,764.51],[2,1.03,54.31]],"ltp":1.01,"tv":3141.91,"id":8257797}]}]}
{"op":"mcm","clk":"4230244110","pt":1631530766143,"mc":[{"id":"1.187557146","rc":[{"batb":[[0,1.06,142],[1,1.05,185.45],[2,1.04,764.51]],"ltp":1.01,"tv":3141.91,"id":8257797}]}]}
{"op":"mcm","clk":"4230244569","pt":1631530773153,"mc":[{"id":"1.187557146","rc":[{"batb":[[0,10,16.25],[1,1.47,1.54],[2,1.36,768.11]],"batl":[[0,990,0.01],[1,21,0],[2,990,0]],"ltp":100.0,"tv":586.55,"id":19931652},{"batb":[[1,1.02,1021.61],[2,1.01,4130.67]],"batl":[[0,1.07,214.81],[1,1.13,14.82],[2,1.15,14.82]],"ltp":1.01,"tv":3141.91,"id":8257797}]}]}
{"op":"mcm","clk":"4230244614","pt":1631530774182,"mc":[{"id":"1.187557146","rc":[{"batb":[[0,1.02,1021.61],[1,1.01,4130.67],[2,1.01,0]],"ltp":1.01,"tv":3141.91,"id":8257797}]}]}
{"op":"mcm","clk":"4230245366","pt":1631530785506,"mc":[{"id":"1.187557146","rc":[{"batl":[[0,1.03,2.17],[1,1.07,214.81],[2,1.13,14.82]],"ltp":1.01,"tv":3141.91,"id":8257797}]}]}
