{"op":"mcm","clk":"4221913669","pt":1631439311445,"mc":[{"id":"1.187552298","marketDefinition":{"bspMarket":false,"turnInPlayEnabled":true,"persistenceEnabled":true,"marketBaseRate":5.0,"eventId":"30895244","eventTypeId":"2","numberOfWinners":1,"bettingType":"ODDS","marketType":"MATCH_ODDS","marketTime":"2021-09-12T15:10:00.000Z","suspendTime":"2021-09-12T15:10:00.000Z","bspReconciled":false,"complete":true,"inPlay":false,"crossMatching":false,"runnersVoidable":false,"numberOfActiveRunners":2,"betDelay":0,"status":"OPEN","runners":[{"status":"ACTIVE","sortPriority":1,"id":14036296,"name":"E Avanesyan"},{"status":"ACTIVE","sortPriority":2,"id":11105735,"name":"S Grey"}],"regulators":["MR_INT"],"countryCode":"GB","discountAllowed":false,"timezone":"GMT","openDate":"2021-09-12T15:10:00.000Z","version":4027632259,"name":"Match Odds","eventName":"E Avanesyan v S Grey"},"rc":[{"batb":[[0,1.01,25]],"ltp":0.0,"tv":0.0,"id":14036296},{"batb":[[0,1.01,25]],"ltp":0.0,"tv":0.0,"id":11105735}]}]}
{"op":"mcm","clk":"4221913908","pt":1631439313197,"mc":[{"id":"1.187552298","marketDefinition":{"bspMarket":false,"turnInPlayEnabled":true,"persistenceEnabled":true,"marketBaseRate":5.0,"eventId":"30895244","eventTypeId":"2","numberOfWinners":1,"bettingType":"ODDS","marketType":"MATCH_ODDS","marketTime":"2021-09-12T15:10:00.000Z","suspendTime":"2021-09-12T15:10:00.000Z","bspReconciled":false,"complete":true,"inPlay":false,"crossMatching":false,"runnersVoidable":false,"numberOfActiveRunners":2,"betDelay":0,"status":"OPEN","runners":[{"status":"ACTIVE","sortPriority":1,"id":14036296,"name":"E Avanesyan"},{"status":"ACTIVE","sortPriority":2,"id":11105735,"name":"S Grey"}],"regulators":["MR_INT"],"countryCode":"GB","discountAllowed":true,"timezone":"GMT","openDate":"2021-09-12T15:10:00.000Z","version":4027632259,"name":"Match Odds","eventName":"E Avanesyan v S Grey"}}]}
{"op":"mcm","clk":"4221991373","pt":1631439907385,"mc":[{"id":"1.187552298","rc":[{"batb":[[0,1.01,7]],"ltp":0.0,"tv":0.0,"id":14036296},{"batb":[[0,1.01,7]],"ltp":0.0,"tv":0.0,"id":11105735}]}]}
{"op":"mcm","clk":"4222056977","pt":1631440322300,"mc":[{"id":"1.187552298","rc":[{"batb":[[0,1.3,112.73],[1,1.01,7]],"ltp":0.0,"tv":0.0,"id":14036296},{"batb":[[0,3.2,15.37],[1,1.01,7]],"ltp":0.0,"tv":0.0,"id":11105735}]}]}
{"op":"mcm","clk":"4222057459","pt":1631440326603,"mc":[{"id":"1.187552298","marketDefinition":{"bspMarket":false,"turnInPlayEnabled":true,"persistenceEnabled":true,"marketBaseRate":5.0,"eventId":"30895244","eventTypeId":"2","numberOfWinners":1,"bettingType":"ODDS","marketType":"MATCH_ODDS","marketTime":"2021-09-12T15:10:00.000Z","suspendTime":"2021-09-12T15:10:00.000Z","bspReconciled":false,"complete":true,"inPlay":false,"crossMatching":true,"runnersVoidable":false,"numberOfActiveRunners":2,"betDelay":0,"status":"OPEN","runners":[{"status":"ACTIVE","sortPriority":1,"id":14036296,"name":"E Avanesyan"},{"status":"ACTIVE","sortPriority":2,"id":11105735,"name":"S Grey"}],"regulators":["MR_INT"],"countryCode":"GB","discountAllowed":true,"timezone":"GMT","openDate":"2021-09-12T15:10:00.000Z","version":4027632259,"name":"Match Odds","eventName":"E Avanesyan v S Grey"}}]}
{"op":"mcm","clk":"4222145710","pt":1631440974760,"mc":[{"id":"1.187552298","rc":[{"batl":[[0,95,19.35]],"ltp":0.0,"tv":0.0,"id":14036296},{"batl":[[0,95,19.35]],"ltp":0.0,"tv":0.0,"id":11105735}]}]}
{"op":"mcm","clk":"4222240707","pt":1631441550693,"mc":[{"id":"1.187552298","rc":[{"batl":[[1,990,2.2]],"ltp":0.0,"tv":0.0,"id":14036296},{"batl":[[1,990,2.2]],"ltp":0.0,"tv":0.0,"id":11105735}]}]}
{"op":"mcm","clk":"4222742211","pt":1631444489548,"mc":[{"id":"1.187552298","rc":[{"batb":[[1,1.01,12]],"ltp":0.0,"tv":0.0,"id":14036296},{"batb":[[1,1.01,12]],"ltp":0.0,"tv":0.0,"id":11105735}]}]}
{"op":"mcm","clk":"4222998075","pt":1631445811532,"mc":[{"id":"1.187552298","rc":[{"batb":[[1,1.02,108.45],[2,1.01,12]],"ltp":0.0,"tv":0.0,"id":14036296},{"batb":[[1,1.02,108.45],[2,1.01,12]],"ltp":0.0,"tv":0.0,"id":11105735}]}]}
{"op":"mcm","clk":"4223511088","pt":1631448539720,"mc":[{"id":"1.187552298","rc":[{"batb":[[1,1.05,879.5],[2,1.02,108.45]],"ltp":0.0,"tv":0.0,"id":14036296},{"batb":[[1,1.05,879.5],[2,1.02,108.45]],"ltp":0.0,"tv":0.0,"id":11105735}]}]}
{"op":"mcm","clk":"4223857917","pt":1631450466036,"mc":[{"id":"1.187552298","rc":[{"batl":[[0,1.45,25.62],[1,95,19.35],[2,990,2.2]],"ltp":0.0,"tv":0.0,"id":14036296},{"batb":[[0,3.2,32.45]],"ltp":0.0,"tv":0.0,"id":11105735}]}]}
{"op":"mcm","clk":"4223924512","pt":1631450783369,"mc":[{"id":"1.187552298","rc":[{"batl":[[0,1.44,40],[1,1.45,25.62],[2,95,19.35]],"ltp":0.0,"tv":0.0,"id":14036296}]}]}
{"op":"mcm","clk":"4224150787","pt":1631451978405,"mc":[{"id":"1.187552298","rc":[{"batl":[[2,1.84,2.66]],"ltp":0.0,"tv":0.0,"id":14036296}]}]}
{"op":"mcm","clk":"4224151774","pt":1631451983104,"mc":[{"id":"1.187552298","rc":[{"batb":[[1,1.05,922.05]],"ltp":0.0,"tv":0.0,"id":14036296}]}]}
{"op":"mcm","clk":"4224199269","pt":1631452200238,"mc":[{"id":"1.187552298","rc":[{"batb":[[0,1.3,150.3]],"ltp":0.0,"tv":0.0,"id":14036296},{"batb":[[0,3.2,37.57]],"ltp":0.0,"tv":0.0,"id":11105735}]}]}
{"op":"mcm","clk":"4224348029","pt":1631452855746,"mc":[{"id":"1.187552298","rc":[{"batl":[[0,1.42,2],[1,1.44,40],[2,1.45,25.62]],"ltp":0.0,"tv":0.0,"id":14036296}]}]}
{"op":"mcm","clk":"4224468323","pt":1631453479866,"mc":[{"id":"1.187552298","rc":[{"batb":[[1,1.02,108.45],[2,1.01,12]],"ltp":0.0,"tv":0.0,"id":11105735}]}]}
{"op":"mcm","clk":"4224746102","pt":1631454963581,"mc":[{"id":"1.187552298","rc":[{"batl":[[1,1.43,25.62],[2,1.44,40]],"ltp":0.0,"tv":0.0,"id":14036296},{"batb":[[0,3.25,17.08],[1,3.2,20.49],[2,1.02,108.45]],"ltp":0.0,"tv":0.0,"id":11105735}]}]}
{"op":"mcm","clk":"4224835144","pt":1631455475825,"mc":[{"id":"1.187552298","rc":[{"batl":[[0,1.42,42],[2,1.84,2.66]],"ltp":0.0,"tv":0.0,"id":14036296}]}]}
{"op":"mcm","clk":"4224899833","pt":1631455801156,"mc":[{"id":"1.187552298","rc":[{"batb":[[0,1.31,41.33],[1,1.3,150.3],[2,1.05,922.05]],"ltp":0.0,"tv":0.0,"id":14036296},{"batb":[[0,3.4,5.34],[1,3.25,17.08],[2,3.2,20.49]],"ltp":0.0,"tv":0.0,"id":11105735}]}]}
{"op":"mcm","clk":"4225138646","pt":1631456940960,"mc":[{"id":"1.187552298","rc":[{"batl":[[2,1.84,46.63]],"ltp":0.0,"tv":0.0,"id":14036296}]}]}
{"op":"mcm","clk":"4225339647","pt":1631457934480,"mc":[{"id":"1.187552298","marketDefinition":{"bspMarket":false,"turnInPlayEnabled":true,"persistenceEnabled":true,"marketBaseRate":5.0,"eventId":"30895244","eventTypeId":"2","numberOfWinners":1,"bettingType":"ODDS","marketType":"MATCH_ODDS","marketTime":"2021-09-12T14:45:33.000Z","suspendTime":"2021-09-12T14:45:33.000Z","bspReconciled":false,"complete":true,"inPlay":false,"crossMatching":true,"runnersVoidable":false,"numberOfActiveRunners":2,"betDelay":0,"status":"OPEN","runners":[{"status":"ACTIVE","sortPriority":1,"id":14036296,"name":"E Avanesyan"},{"status":"ACTIVE","sortPriority":2,"id":11105735,"name":"S Grey"}],"regulators":["MR_INT"],"countryCode":"GB","discountAllowed":true,"timezone":"GMT","openDate":"2021-09-12T15:10:00.000Z","version":4028688682,"name":"Match Odds","eventName":"E Avanesyan v S Grey"}}]}
{"op":"mcm","clk":"4225340106","pt":1631457937148,"mc":[{"id":"1.187552298","rc":[{"batb":[[0,1.33,136.64],[1,1.31,41.33]],"ltp":0.0,"tv":0.0,"id":14036296},{"batb":[[1,3.25,37.12],[2,1.02,108.45]],"ltp":0.0,"tv":0.0,"id":11105735}]}]}
{"op":"mcm","clk":"4225340285","pt":1631457938147,"mc":[{"id":"1.187552298","marketDefinition":{"bspMarket":false,"turnInPlayEnabled":true,"persistenceEnabled":true,"marketBaseRate":5.0,"eventId":"30895244","eventTypeId":"2","numberOfWinners":1,"bettingType":"ODDS","marketType":"MATCH_ODDS","marketTime":"2021-09-12T14:45:33.000Z","suspendTime":"2021-09-12T14:45:33.000Z","bspReconciled":false,"complete":true,"inPlay":false,"crossMatching":true,"runnersVoidable":false,"numberOfActiveRunners":2,"betDelay":0,"status":"OPEN","runners":[{"status":"ACTIVE","sortPriority":1,"id":14036296,"name":"E Avanesyan"},{"status":"ACTIVE","sortPriority":2,"id":11105735,"name":"S Grey"}],"regulators":["MR_INT"],"countryCode":"GB","discountAllowed":true,"timezone":"GMT","openDate":"2021-09-12T14:45:33.000Z","version":4028688682,"name":"Match Odds","eventName":"E Avanesyan v S Grey"},"rc":[{"batb":[[0,1.33,175.46]],"ltp":0.0,"tv":0.0,"id":14036296},{"batb":[[0,3.35,5.45]],"ltp":0.0,"tv":0.0,"id":11105735}]}]}
{"op":"mcm","clk":"4225341945","pt":1631457946793,"mc":[{"id":"1.187552298","marketDefinition":{"bspMarket":false,"turnInPlayEnabled":true,"persistenceEnabled":true,"marketBaseRate":5.0,"eventId":"30895244","eventTypeId":"2","numberOfWinners":1,"bettingType":"ODDS","marketType":"MATCH_ODDS","marketTime":"2021-09-12T14:45:33.000Z","suspendTime":"2021-09-12T14:45:33.000Z","bspReconciled":false,"complete":true,"inPlay":true,"crossMatching":true,"runnersVoidable":false,"numberOfActiveRunners":2,"betDelay":5,"status":"OPEN","runners":[{"status":"ACTIVE","sortPriority":1,"id":14036296,"name":"E Avanesyan"},{"status":"ACTIVE","sortPriority":2,"id":11105735,"name":"S Grey"}],"regulators":["MR_INT"],"countryCode":"GB","discountAllowed":true,"timezone":"GMT","openDate":"2021-09-12T14:45:33.000Z","version":4028690132,"name":"Match Odds","eventName":"E Avanesyan v S Grey"},"rc":[{"batb":[[0,1.01,12],[1,1.31,0],[2,1.05,0]],"batl":[[0,1.42,40],[1,1.43,0],[2,1.84,0]],"ltp":0.0,"tv":0.0,"id":14036296},{"batb":[[0,1.01,12],[1,3.25,0],[2,1.02,0]],"ltp":0.0,"tv":0.0,"id":11105735}]}]}
{"op":"mcm","clk":"4225342888","pt":1631457952082,"mc":[{"id":"1.187552298","rc":[{"batl":[[1,11.5,8.68]],"ltp":0.0,"tv":0.0,"id":14036296}]}]}
{"op":"mcm","clk":"4225344835","pt":1631457962694,"mc":[{"id":"1.187552298","marketDefinition":{"bspMarket":false,"turnInPlayEnabled":true,"persistenceEnabled":true,"marketBaseRate":5.0,"eventId":"30895244","eventTypeId":"2","numberOfWinners":1,"bettingType":"ODDS","marketType":"MATCH_ODDS","marketTime":"2021-09-12T14:45:33.000Z","suspendTime":"2021-09-12T14:45:33.000Z","bspReconciled":false,"complete":true,"inPlay":true,"crossMatching":true,"runnersVoidable":false,"numberOfActiveRunners":2,"betDelay":5,"status":"SUSPENDED","runners":[{"status":"ACTIVE","sortPriority":1,"id":14036296,"name":"E Avanesyan"},{"status":"ACTIVE","sortPriority":2,"id":11105735,"name":"S Grey"}],"regulators":["MR_INT"],"countryCode":"GB","discountAllowed":true,"timezone":"GMT","openDate":"2021-09-12T14:45:33.000Z","version":4028691256,"name":"Match Odds","eventName":"E Avanesyan v S Grey"}}]}
{"op":"mcm","clk":"4225522767","pt":1631458965991,"mc":[{"id":"1.187552298","marketDefinition":{"bspMarket":false,"turnInPlayEnabled":true,"persistenceEnabled":true,"marketBaseRate":5.0,"eventId":"30895244","eventTypeId":"2","numberOfWinners":1,"bettingType":"ODDS","marketType":"MATCH_ODDS","marketTime":"2021-09-12T14:45:33.000Z","suspendTime":"2021-09-12T14:45:33.000Z","bspReconciled":false,"complete":true,"inPlay":true,"crossMatching":true,"runnersVoidable":false,"numberOfActiveRunners":2,"betDelay":5,"status":"OPEN","runners":[{"status":"ACTIVE","sortPriority":1,"id":14036296,"name":"E Avanesyan"},{"status":"ACTIVE","sortPriority":2,"id":11105735,"name":"S Grey"}],"regulators":["MR_INT"],"countryCode":"GB","discountAllowed":true,"timezone":"GMT","openDate":"2021-09-12T14:45:33.000Z","version":4028784219,"name":"Match Odds","eventName":"E Avanesyan v S Grey"}}]}
{"op":"mcm","clk":"4225524244","pt":1631458973804,"mc":[{"id":"1.187552298","rc":[{"batb":[[0,1.1,735.13],[1,1.01,12]],"batl":[[1,1.48,797.87],[2,11.5,8.68]],"ltp":0.0,"tv":0.0,"id":14036296}]}]}
{"op":"mcm","clk":"4225531774","pt":1631459012806,"mc":[{"id":"1.187552298","rc":[{"batb":[[0,1.01,12],[1,1.01,0]],"ltp":0.0,"tv":0.0,"id":14036296}]}]}
{"op":"mcm","clk":"4225532795","pt":1631459018103,"mc":[{"id":"1.187552298","rc":[{"batb":[[0,1.09,765.47],[1,1.01,12]],"ltp":0.0,"tv":0.0,"id":14036296}]}]}
{"op":"mcm","clk":"4225543017","pt":1631459070511,"mc":[{"id":"1.187552298","rc":[{"batb":[[0,1.01,12],[1,1.01,0]],"batl":[[1,11.5,8.68],[2,11.5,0]],"ltp":0.0,"tv":0.0,"id":14036296}]}]}
{"op":"mcm","clk":"4225544203","pt":1631459076712,"mc":[{"id":"1.187552298","rc":[{"batb":[[0,1.06,1010.28],[1,1.01,12]],"batl":[[0,1.41,917.52],[1,1.42,40],[2,11.5,8.68]],"ltp":0.0,"tv":0.0,"id":14036296}]}]}
{"op":"mcm","clk":"4225550665","pt":1631459109897,"mc":[{"id":"1.187552298","rc":[{"batb":[[0,1.01,12],[1,1.01,0]],"ltp":0.0,"tv":0.0,"id":14036296}]}]}
{"op":"mcm","clk":"4225551849","pt":1631459115810,"mc":[{"id":"1.187552298","rc":[{"batb":[[0,1.06,952.24],[1,1.01,12]],"ltp":0.0,"tv":0.0,"id":14036296}]}]}
{"op":"mcm","clk":"4225572675","pt":1631459220313,"mc":[{"id":"1.187552298","rc":[{"batb":[[0,1.01,12],[1,1.01,0]],"ltp":0.0,"tv":0.0,"id":14036296}]}]}
{"op":"mcm","clk":"4225573869","pt":1631459226111,"mc":[{"id":"1.187552298","rc":[{"batb":[[0,1.06,1010.28],[1,1.01,12]],"ltp":0.0,"tv":0.0,"id":14036296}]}]}
{"op":"mcm","clk":"4225577223","pt":1631459243494,"mc":[{"id":"1.187552298","rc":[{"batb":[[0,1.01,12],[1,1.01,0]],"ltp":0.0,"tv":0.0,"id":14036296}]}]}
{"op":"mcm","clk":"4225578288","pt":1631459249201,"mc":[{"id":"1.187552298","rc":[{"batb":[[0,1.08,814.16],[1,1.01,12]],"ltp":0.0,"tv":0.0,"id":14036296}]}]}
{"op":"mcm","clk":"4225583304","pt":1631459275910,"mc":[{"id":"1.187552298","rc":[{"batb":[[0,1.39,578.41],[1,1.08,814.16],[2,1.01,12]],"ltp":0.0,"tv":0.0,"id":14036296}]}]}
{"op":"mcm","clk":"4225583618","pt":1631459277725,"mc":[{"id":"1.187552298","rc":[{"batb":[[0,1.08,814.16],[1,1.01,12],[2,1.01,0]],"ltp":0.0,"tv":0.0,"id":14036296}]}]}
{"op":"mcm","clk":"4225583864","pt":1631459278932,"mc":[{"id":"1.187552298","rc":[{"batb":[[0,1.01,12],[1,1.01,0]],"ltp":0.0,"tv":0.0,"id":14036296}]}]}
{"op":"mcm","clk":"4225585064","pt":1631459284923,"mc":[{"id":"1.187552298","rc":[{"batb":[[0,1.06,1010.28],[1,1.01,12]],"ltp":0.0,"tv":0.0,"id":14036296}]}]}
{"op":"mcm","clk":"4225587449","pt":1631459297143,"mc":[{"id":"1.187552298","rc":[{"batb":[[0,1.01,12],[1,1.01,0]],"batl":[[0,1.42,40],[1,11.5,8.68],[2,11.5,0]],"ltp":0.0,"tv":0.0,"id":14036296}]}]}
{"op":"mcm","clk":"4225591928","pt":1631459320193,"mc":[{"id":"1.187552298","rc":[{"batb":[[0,1.08,814.16],[1,1.01,12]],"ltp":0.0,"tv":0.0,"id":14036296}]}]}
{"op":"mcm","clk":"4225592736","pt":1631459324408,"mc":[{"id":"1.187552298","rc":[{"batb":[[0,1.01,12],[1,1.01,0]],"ltp":0.0,"tv":0.0,"id":14036296}]}]}
{"op":"mcm","clk":"4225595678","pt":1631459339645,"mc":[{"id":"1.187552298","rc":[{"batb":[[0,1.38,723.01],[1,1.01,12]],"ltp":0.0,"tv":0.0,"id":14036296}]}]}
{"op":"mcm","clk":"4225596039","pt":1631459341550,"mc":[{"id":"1.187552298","rc":[{"batb":[[0,1.01,12],[1,1.01,0]],"ltp":0.0,"tv":0.0,"id":14036296}]}]}
{"op":"mcm","clk":"4225608963","pt":1631459406644,"mc":[{"id":"1.187552298","rc":[{"batb":[[0,1.39,723.01],[1,1.01,12]],"ltp":0.0,"tv":0.0,"id":14036296}]}]}
{"op":"mcm","clk":"4225609287","pt":1631459408485,"mc":[{"id":"1.187552298","rc":[{"batb":[[0,1.01,12],[1,1.01,0]],"ltp":0.0,"tv":0.0,"id":14036296}]}]}
{"op":"mcm","clk":"4225615634","pt":1631459442801,"mc":[{"id":"1.187552298","rc":[{"batb":[[0,1.38,723.01],[1,1.01,12]],"ltp":0.0,"tv":0.0,"id":14036296}]}]}
{"op":"mcm","clk":"4225616064","pt":1631459444904,"mc":[{"id":"1.187552298","rc":[{"batb":[[0,1.01,12],[1,1.01,0]],"ltp":0.0,"tv":0.0,"id":14036296}]}]}
{"op":"mcm","clk":"4225625124","pt":1631459490460,"mc":[{"id":"1.187552298","rc":[{"batb":[[0,2,20],[1,1.01,12]],"ltp":0.0,"tv":0.0,"id":11105735}]}]}
{"op":"mcm","clk":"4225626287","pt":1631459496569,"mc":[{"id":"1.187552298","rc":[{"batb":[[0,1.41,723.01],[1,1.01,12]],"ltp":0.0,"tv":0.0,"id":14036296}]}]}
{"op":"mcm","clk":"4225626690","pt":1631459498577,"mc":[{"id":"1.187552298","rc":[{"batb":[[0,1.01,12],[1,1.01,0]],"ltp":0.0,"tv":0.0,"id":14036296}]}]}
{"op":"mcm","clk":"4225627628","pt":1631459503848,"mc":[{"id":"1.187552298","rc":[{"batb":[[0,1.06,1010.28],[1,1.01,12]],"batl":[[0,1.41,917.52],[1,1.42,40],[2,11.5,8.68]],"ltp":0.0,"tv":0.0,"id":14036296}]}]}
{"op":"mcm","clk":"4225628057","pt":1631459506294,"mc":[{"id":"1.187552298","rc":[{"batb":[[0,1.01,12],[1,1.01,0]],"ltp":0.0,"tv":0.0,"id":11105735}]}]}
{"op":"mcm","clk":"4225633963","pt":1631459536727,"mc":[{"id":"1.187552298","rc":[{"batb":[[0,1.01,12],[1,1.01,0]],"ltp":0.0,"tv":0.0,"id":14036296}]}]}
{"op":"mcm","clk":"4225635070","pt":1631459542259,"mc":[{"id":"1.187552298","rc":[{"batb":[[0,1.08,814.16],[1,1.01,12]],"ltp":0.0,"tv":0.0,"id":14036296}]}]}
{"op":"mcm","clk":"4225642913","pt":1631459579016,"mc":[{"id":"1.187552298","rc":[{"batb":[[0,1.39,650.71],[1,1.08,814.16],[2,1.01,12]],"ltp":0.0,"tv":0.0,"id":14036296}]}]}
{"op":"mcm","clk":"4225643249","pt":1631459580647,"mc":[{"id":"1.187552298","rc":[{"batb":[[0,1.08,814.16],[1,1.01,12],[2,1.01,0]],"ltp":0.0,"tv":0.0,"id":14036296}]}]}
{"op":"mcm","clk":"4225644865","pt":1631459588351,"mc":[{"id":"1.187552298","rc":[{"batb":[[0,1.01,12],[1,1.01,0]],"ltp":0.0,"tv":0.0,"id":14036296}]}]}
{"op":"mcm","clk":"4225646168","pt":1631459594735,"mc":[{"id":"1.187552298","rc":[{"batb":[[0,1.1,735.13],[1,1.01,12]],"ltp":0.0,"tv":0.0,"id":14036296}]}]}
{"op":"mcm","clk":"4225656874","pt":1631459646033,"mc":[{"id":"1.187552298","rc":[{"batb":[[0,1.01,12],[1,1.01,0]],"ltp":0.0,"tv":0.0,"id":14036296}]}]}
{"op":"mcm","clk":"4225658094","pt":1631459651932,"mc":[{"id":"1.187552298","rc":[{"batb":[[0,1.14,620.51],[1,1.01,12]],"ltp":0.0,"tv":0.0,"id":14036296}]}]}
{"op":"mcm","clk":"4225659037","pt":1631459656542,"mc":[{"id":"1.187552298","rc":[{"batb":[[0,1.01,12],[1,1.01,0]],"batl":[[0,1.42,40],[1,11.5,8.68],[2,11.5,0]],"ltp":0.0,"tv":0.0,"id":14036296}]}]}
{"op":"mcm","clk":"4225666138","pt":1631459689950,"mc":[{"id":"1.187552298","rc":[{"batl":[[0,1.03,426.58],[1,1.42,40],[2,11.5,8.68]],"ltp":0.0,"tv":0.0,"id":14036296}]}]}
{"op":"mcm","clk":"4225666453","pt":1631459691441,"mc":[{"id":"1.187552298","rc":[{"batl":[[0,1.42,40],[1,11.5,8.68],[2,11.5,0]],"ltp":0.0,"tv":0.0,"id":14036296}]}]}
{"op":"mcm","clk":"4225673692","pt":1631459724804,"mc":[{"id":"1.187552298","rc":[{"batl":[[0,1.04,426.58],[1,1.42,40],[2,11.5,8.68]],"ltp":0.0,"tv":0.0,"id":14036296}]}]}
{"op":"mcm","clk":"4225673983","pt":1631459726099,"mc":[{"id":"1.187552298","rc":[{"batl":[[0,1.42,40],[1,11.5,8.68],[2,11.5,0]],"ltp":0.0,"tv":0.0,"id":14036296}]}]}
{"op":"mcm","clk":"4225680424","pt":1631459755255,"mc":[{"id":"1.187552298","rc":[{"batl":[[0,1.03,426.58],[1,1.42,40],[2,11.5,8.68]],"ltp":0.0,"tv":0.0,"id":14036296}]}]}
{"op":"mcm","clk":"4225680792","pt":1631459756854,"mc":[{"id":"1.187552298","rc":[{"batl":[[0,1.42,40],[1,11.5,8.68],[2,11.5,0]],"ltp":0.0,"tv":0.0,"id":14036296}]}]}
{"op":"mcm","clk":"4225681474","pt":1631459760049,"mc":[{"id":"1.187552298","rc":[{"batb":[[0,1.12,661.06],[1,1.01,12]],"ltp":0.0,"tv":0.0,"id":14036296}]}]}
{"op":"mcm","clk":"4225687607","pt":1631459787596,"mc":[{"id":"1.187552298","rc":[{"batb":[[0,1.01,12],[1,1.01,0]],"ltp":0.0,"tv":0.0,"id":14036296}]}]}
{"op":"mcm","clk":"4225688818","pt":1631459793314,"mc":[{"id":"1.187552298","rc":[{"batb":[[0,1.1,735.13],[1,1.01,12]],"ltp":0.0,"tv":0.0,"id":14036296}]}]}
{"op":"mcm","clk":"4225697803","pt":1631459835232,"mc":[{"id":"1.187552298","rc":[{"batb":[[0,1.01,12],[1,1.01,0]],"ltp":0.0,"tv":0.0,"id":14036296}]}]}
{"op":"mcm","clk":"4225698942","pt":1631459840801,"mc":[{"id":"1.187552298","rc":[{"batb":[[0,1.08,814.16],[1,1.01,12]],"ltp":0.0,"tv":0.0,"id":14036296}]}]}
{"op":"mcm","clk":"4225702721","pt":1631459858947,"mc":[{"id":"1.187552298","rc":[{"batb":[[0,1.4,723.01],[1,1.08,814.16],[2,1.01,12]],"ltp":0.0,"tv":0.0,"id":14036296}]}]}
{"op":"mcm","clk":"4225703029","pt":1631459860417,"mc":[{"id":"1.187552298","rc":[{"batb":[[0,1.08,814.16],[1,1.01,12],[2,1.01,0]],"ltp":0.0,"tv":0.0,"id":14036296}]}]}
{"op":"mcm","clk":"4225706826","pt":1631459879418,"mc":[{"id":"1.187552298","rc":[{"batb":[[0,1.39,723.01],[1,1.08,814.16],[2,1.01,12]],"ltp":0.0,"tv":0.0,"id":14036296}]}]}
{"op":"mcm","clk":"4225707140","pt":1631459881079,"mc":[{"id":"1.187552298","rc":[{"batb":[[0,1.08,814.16],[1,1.01,12],[2,1.01,0]],"ltp":0.0,"tv":0.0,"id":14036296}]}]}
{"op":"mcm","clk":"4225709292","pt":1631459892831,"mc":[{"id":"1.187552298","rc":[{"batb":[[0,1.01,12],[1,1.01,0]],"ltp":0.0,"tv":0.0,"id":14036296}]}]}
{"op":"mcm","clk":"4225710335","pt":1631459898319,"mc":[{"id":"1.187552298","rc":[{"batb":[[0,1.06,1010.28],[1,1.01,12]],"ltp":0.0,"tv":0.0,"id":14036296}]}]}
{"op":"mcm","clk":"4225716552","pt":1631459930253,"mc":[{"id":"1.187552298","rc":[{"batb":[[0,1.01,12],[1,1.01,0]],"ltp":0.0,"tv":0.0,"id":14036296}]}]}
{"op":"mcm","clk":"4225716900","pt":1631459931977,"mc":[{"id":"1.187552298","rc":[{"batb":[[0,1.4,723.01],[1,1.01,12]],"ltp":0.0,"tv":0.0,"id":14036296}]}]}
{"op":"mcm","clk":"4225717186","pt":1631459933567,"mc":[{"id":"1.187552298","rc":[{"batb":[[0,1.01,12],[1,1.01,0]],"ltp":0.0,"tv":0.0,"id":14036296}]}]}
{"op":"mcm","clk":"4225717737","pt":1631459936593,"mc":[{"id":"1.187552298","rc":[{"batb":[[0,1.08,814.16],[1,1.01,12]],"ltp":0.0,"tv":0.0,"id":14036296}]}]}
{"op":"mcm","clk":"4225736946","pt":1631460034320,"mc":[{"id":"1.187552298","rc":[{"batb":[[0,1.01,12],[1,1.01,0]],"ltp":0.0,"tv":0.0,"id":14036296}]}]}
{"op":"mcm","clk":"4225738181","pt":1631460040755,"mc":[{"id":"1.187552298","rc":[{"batb":[[0,1.06,1010.28],[1,1.01,12]],"ltp":0.0,"tv":0.0,"id":14036296}]}]}
{"op":"mcm","clk":"4225743941","pt":1631460070740,"mc":[{"id":"1.187552298","rc":[{"batb":[[0,1.01,12],[1,1.01,0]],"ltp":0.0,"tv":0.0,"id":14036296}]}]}
{"op":"mcm","clk":"4225745192","pt":1631460077018,"mc":[{"id":"1.187552298","rc":[{"batb":[[0,1.08,814.16],[1,1.01,12]],"ltp":0.0,"tv":0.0,"id":14036296}]}]}
{"op":"mcm","clk":"4225748768","pt":1631460094933,"mc":[{"id":"1.187552298","rc":[{"batb":[[0,1.01,12],[1,1.01,0]],"ltp":0.0,"tv":0.0,"id":14036296}]}]}
{"op":"mcm","clk":"4225750020","pt":1631460101025,"mc":[{"id":"1.187552298","rc":[{"batb":[[0,1.05,1087.21],[1,1.01,12]],"batl":[[0,1.38,988.99],[1,1.42,40],[2,11.5,8.68]],"ltp":0.0,"tv":0.0,"id":14036296}]}]}
{"op":"mcm","clk":"4225759740","pt":1631460150617,"mc":[{"id":"1.187552298","rc":[{"batb":[[0,1.36,723.01],[1,1.05,1087.21],[2,1.01,12]],"ltp":0.0,"tv":0.0,"id":14036296}]}]}
{"op":"mcm","clk":"4225759931","pt":1631460151551,"mc":[{"id":"1.187552298","rc":[{"batb":[[1,1.01,12],[2,1.01,0]],"ltp":0.0,"tv":0.0,"id":14036296}]}]}
{"op":"mcm","clk":"4225760095","pt":1631460152338,"mc":[{"id":"1.187552298","rc":[{"batb":[[0,1.01,12],[1,1.01,0]],"ltp":0.0,"tv":0.0,"id":14036296}]}]}
{"op":"mcm","clk":"4225761136","pt":1631460157558,"mc":[{"id":"1.187552298","rc":[{"batb":[[0,1.04,1254.9],[1,1.01,12]],"ltp":0.0,"tv":0.0,"id":14036296}]}]}
{"op":"mcm","clk":"4225770919","pt":1631460207111,"mc":[{"id":"1.187552298","rc":[{"batb":[[0,1.01,12],[1,1.01,0]],"ltp":0.0,"tv":0.0,"id":14036296}]}]}
{"op":"mcm","clk":"4225772035","pt":1631460213226,"mc":[{"id":"1.187552298","rc":[{"batb":[[0,1.05,1087.21],[1,1.01,12]],"ltp":0.0,"tv":0.0,"id":14036296}]}]}
{"op":"mcm","clk":"4225777170","pt":1631460241473,"mc":[{"id":"1.187552298","rc":[{"batb":[[0,1.01,12],[1,1.01,0]],"ltp":0.0,"tv":0.0,"id":14036296}]}]}
{"op":"mcm","clk":"4225777645","pt":1631460243777,"mc":[{"id":"1.187552298","rc":[{"batb":[[0,20,18.08],[1,1.01,12]],"ltp":0.0,"tv":0.0,"id":11105735}]}]}
{"op":"mcm","clk":"4225777960","pt":1631460245364,"mc":[{"id":"1.187552298","rc":[{"batb":[[0,1.01,12],[1,1.01,0]],"ltp":0.0,"tv":0.0,"id":11105735}]}]}
{"op":"mcm","clk":"4225778388","pt":1631460247678,"mc":[{"id":"1.187552298","rc":[{"batb":[[0,1.04,1254.9],[1,1.01,12]],"ltp":0.0,"tv":0.0,"id":14036296}]}]}
{"op":"mcm","clk":"4225779511","pt":1631460254096,"mc":[{"id":"1.187552298","rc":[{"batl":[[0,1.37,85.4],[1,1.38,988.99],[2,1.42,40]],"ltp":0.0,"tv":0.0,"id":14036296}]}]}
{"op":"mcm","clk":"4225794662","pt":1631460347166,"mc":[{"id":"1.187552298","rc":[{"batl":[[0,1.38,988.99],[1,1.42,40],[2,11.5,8.68]],"ltp":0.0,"tv":0.0,"id":14036296}]}]}
{"op":"mcm","clk":"4225798323","pt":1631460369008,"mc":[{"id":"1.187552298","rc":[{"batb":[[0,1.36,867.62],[1,1.04,1254.9],[2,1.01,12]],"ltp":0.0,"tv":0.0,"id":14036296}]}]}
{"op":"mcm","clk":"4225798682","pt":1631460371003,"mc":[{"id":"1.187552298","rc":[{"batb":[[0,1.04,1254.9],[1,1.01,12],[2,1.01,0]],"ltp":0.0,"tv":0.0,"id":14036296}]}]}
{"op":"mcm","clk":"4225803189","pt":1631460399121,"mc":[{"id":"1.187552298","rc":[{"batl":[[0,1.36,85.4],[1,1.38,988.99],[2,1.42,40]],"ltp":0.0,"tv":0.0,"id":14036296}]}]}
{"op":"mcm","clk":"4225804096","pt":1631460404367,"mc":[{"id":"1.187552298","rc":[{"batl":[[0,1.38,988.99],[1,1.42,40],[2,11.5,8.68]],"ltp":0.0,"tv":0.0,"id":14036296}]}]}
{"op":"mcm","clk":"4225811416","pt":1631460448435,"mc":[{"id":"1.187552298","rc":[{"batb":[[0,1.01,12],[1,1.01,0]],"batl":[[0,1.42,40],[1,11.5,8.68],[2,11.5,0]],"ltp":0.0,"tv":0.0,"id":14036296}]}]}
{"op":"mcm","clk":"4225812065","pt":1631460452443,"mc":[{"id":"1.187552298","rc":[{"batl":[[0,1.35,85.4],[1,1.42,40],[2,11.5,8.68]],"ltp":0.0,"tv":0.0,"id":14036296}]}]}
{"op":"mcm","clk":"4225813224","pt":1631460458941,"mc":[{"id":"1.187552298","rc":[{"batl":[[0,1.42,40],[1,11.5,8.68],[2,11.5,0]],"ltp":0.0,"tv":0.0,"id":14036296}]}]}
{"op":"mcm","clk":"4225835027","pt":1631460596098,"mc":[{"id":"1.187552298","rc":[{"batl":[[0,1.38,85.4],[1,1.42,40],[2,11.5,8.68]],"ltp":0.0,"tv":0.0,"id":14036296}]}]}
{"op":"mcm","clk":"4225836553","pt":1631460604546,"mc":[{"id":"1.187552298","rc":[{"batl":[[0,1.42,40],[1,11.5,8.68],[2,11.5,0]],"ltp":0.0,"tv":0.0,"id":14036296}]}]}
{"op":"mcm","clk":"4225856426","pt":1631460714393,"mc":[{"id":"1.187552298","rc":[{"batb":[[0,1.05,1087.21],[1,1.01,12]],"batl":[[0,1.38,988.99],[1,1.42,40],[2,11.5,8.68]],"ltp":0.0,"tv":0.0,"id":14036296}]}]}
{"op":"mcm","clk":"4225857407","pt":1631460719775,"mc":[{"id":"1.187552298","rc":[{"batl":[[0,1.38,1074.4]],"ltp":0.0,"tv":0.0,"id":14036296}]}]}
{"op":"mcm","clk":"4225858237","pt":1631460724705,"mc":[{"id":"1.187552298","rc":[{"batl":[[0,1.38,988.99]],"ltp":0.0,"tv":0.0,"id":14036296}]}]}
{"op":"mcm","clk":"4225860044","pt":1631460734409,"mc":[{"id":"1.187552298","rc":[{"batb":[[0,1.01,12],[1,1.01,0]],"ltp":0.0,"tv":0.0,"id":14036296}]}]}
{"op":"mcm","clk":"4225861136","pt":1631460740369,"mc":[{"id":"1.187552298","rc":[{"batb":[[0,1.06,1010.28],[1,1.01,12]],"ltp":0.0,"tv":0.0,"id":14036296}]}]}
{"op":"mcm","clk":"4225863768","pt":1631460755656,"mc":[{"id":"1.187552298","rc":[{"batb":[[0,1.01,12],[1,1.01,0]],"ltp":0.0,"tv":0.0,"id":14036296}]}]}
{"op":"mcm","clk":"4225864818","pt":1631460761645,"mc":[{"id":"1.187552298","rc":[{"batb":[[0,1.08,814.16],[1,1.01,12]],"ltp":0.0,"tv":0.0,"id":14036296}]}]}
{"op":"mcm","clk":"4225870053","pt":1631460792936,"mc":[{"id":"1.187552298","rc":[{"batb":[[0,1.01,12],[1,1.01,0]],"ltp":0.0,"tv":0.0,"id":14036296}]}]}
{"op":"mcm","clk":"4225871078","pt":1631460798836,"mc":[{"id":"1.187552298","rc":[{"batb":[[0,1.06,1010.28],[1,1.01,12]],"ltp":0.0,"tv":0.0,"id":14036296}]}]}
{"op":"mcm","clk":"4225874676","pt":1631460820211,"mc":[{"id":"1.187552298","rc":[{"batb":[[0,1.01,12],[1,1.01,0]],"ltp":0.0,"tv":0.0,"id":14036296}]}]}
{"op":"mcm","clk":"4225875781","pt":1631460826497,"mc":[{"id":"1.187552298","rc":[{"batb":[[0,1.06,952.24],[1,1.01,12]],"ltp":0.0,"tv":0.0,"id":14036296}]}]}
{"op":"mcm","clk":"4225882052","pt":1631460860678,"mc":[{"id":"1.187552298","rc":[{"batb":[[0,1.01,12],[1,1.01,0]],"ltp":0.0,"tv":0.0,"id":14036296}]}]}
{"op":"mcm","clk":"4225883230","pt":1631460867175,"mc":[{"id":"1.187552298","rc":[{"batb":[[0,1.04,1254.9],[1,1.01,12]],"ltp":0.0,"tv":0.0,"id":14036296}]}]}
{"op":"mcm","clk":"4225887030","pt":1631460888762,"mc":[{"id":"1.187552298","rc":[{"batb":[[0,1.01,12],[1,1.01,0]],"ltp":0.0,"tv":0.0,"id":14036296}]}]}
{"op":"mcm","clk":"4225888157","pt":1631460894767,"mc":[{"id":"1.187552298","rc":[{"batb":[[0,1.03,1561.16],[1,1.01,12]],"ltp":0.0,"tv":0.0,"id":14036296}]}]}
{"op":"mcm","clk":"4225897401","pt":1631460945479,"mc":[{"id":"1.187552298","rc":[{"batb":[[0,1.01,12],[1,1.01,0]],"ltp":0.0,"tv":0.0,"id":14036296}]}]}
{"op":"mcm","clk":"4225898415","pt":1631460951305,"mc":[{"id":"1.187552298","rc":[{"batb":[[0,1.04,1254.9],[1,1.01,12]],"ltp":0.0,"tv":0.0,"id":14036296}]}]}
{"op":"mcm","clk":"4225906111","pt":1631460992866,"mc":[{"id":"1.187552298","rc":[{"batb":[[0,1.01,12],[1,1.01,0]],"ltp":0.0,"tv":0.0,"id":14036296}]}]}
{"op":"mcm","clk":"4225907253","pt":1631460998902,"mc":[{"id":"1.187552298","rc":[{"batb":[[0,1.03,1561.16],[1,1.01,12]],"ltp":0.0,"tv":0.0,"id":14036296}]}]}
{"op":"mcm","clk":"4225908031","pt":1631461002991,"mc":[{"id":"1.187552298","rc":[{"batl":[[0,1.35,85.4],[1,1.38,988.99],[2,1.42,40]],"ltp":0.0,"tv":0.0,"id":14036296}]}]}
{"op":"mcm","clk":"4225909294","pt":1631461009624,"mc":[{"id":"1.187552298","rc":[{"batl":[[0,1.38,988.99],[1,1.42,40],[2,11.5,8.68]],"ltp":0.0,"tv":0.0,"id":14036296}]}]}
{"op":"mcm","clk":"4225915144","pt":1631461042290,"mc":[{"id":"1.187552298","rc":[{"batb":[[0,1.01,12],[1,1.01,0]],"batl":[[0,1.42,40],[1,11.5,8.68],[2,11.5,0]],"ltp":0.0,"tv":0.0,"id":14036296}]}]}
{"op":"mcm","clk":"4225916212","pt":1631461048116,"mc":[{"id":"1.187552298","rc":[{"batb":[[0,1.01,4176.78]],"batl":[[0,1.32,1173.52],[1,1.42,40],[2,11.5,8.68]],"ltp":0.0,"tv":0.0,"id":14036296}]}]}
{"op":"mcm","clk":"4225923772","pt":1631461091187,"mc":[{"id":"1.187552298","rc":[{"batb":[[0,1.01,12]],"batl":[[0,1.42,40],[1,11.5,8.68],[2,11.5,0]],"ltp":0.0,"tv":0.0,"id":14036296}]}]}
{"op":"mcm","clk":"4225949751","pt":1631461232921,"mc":[{"id":"1.187552298","rc":[{"batl":[[0,1.3,1247.38],[1,1.42,40],[2,11.5,8.68]],"ltp":0.0,"tv":0.0,"id":14036296},{"batl":[[0,170,37.59]],"ltp":0.0,"tv":0.0,"id":11105735}]}]}
{"op":"mcm","clk":"4225955139","pt":1631461261787,"mc":[{"id":"1.187552298","rc":[{"batl":[[0,1.2,5],[1,1.3,1247.38],[2,1.42,40]],"ltp":0.0,"tv":0.0,"id":14036296}]}]}
{"op":"mcm","clk":"4225956775","pt":1631461270441,"mc":[{"id":"1.187552298","rc":[{"batl":[[0,340,36.48]],"ltp":0.0,"tv":0.0,"id":11105735}]}]}
{"op":"mcm","clk":"4225964906","pt":1631461314610,"mc":[{"id":"1.187552298","rc":[{"batl":[[0,170,37.59]],"ltp":0.0,"tv":0.0,"id":11105735}]}]}
{"op":"mcm","clk":"4225970622","pt":1631461345011,"mc":[{"id":"1.187552298","rc":[{"batl":[[0,340,36.48]],"ltp":0.0,"tv":0.0,"id":11105735}]}]}
{"op":"mcm","clk":"4225979471","pt":1631461390758,"mc":[{"id":"1.187552298","rc":[{"batb":[[0,1.19,903.77],[1,1.01,12]],"ltp":0.0,"tv":0.0,"id":14036296}]}]}
{"op":"mcm","clk":"4225979807","pt":1631461392654,"mc":[{"id":"1.187552298","rc":[{"batb":[[0,1.01,12],[1,1.01,0]],"ltp":0.0,"tv":0.0,"id":14036296}]}]}
{"op":"mcm","clk":"4225988204","pt":1631461439760,"mc":[{"id":"1.187552298","rc":[{"batl":[[0,340,36.48]],"ltp":0.0,"tv":0.0,"id":11105735}]}]}
{"op":"mcm","clk":"4225991955","pt":1631461461083,"mc":[{"id":"1.187552298","rc":[{"batb":[[0,1.01,3989.18]],"ltp":0.0,"tv":0.0,"id":14036296}]}]}
{"op":"mcm","clk":"4225997978","pt":1631461496568,"mc":[{"id":"1.187552298","rc":[{"batb":[[0,1.01,12]],"ltp":0.0,"tv":0.0,"id":14036296}]}]}
{"op":"mcm","clk":"4225999010","pt":1631461502622,"mc":[{"id":"1.187552298","rc":[{"batl":[[0,340,36.48]],"ltp":0.0,"tv":0.0,"id":11105735}]}]}
{"op":"mcm","clk":"4226002549","pt":1631461522679,"mc":[{"id":"1.187552298","rc":[{"batb":[[0,1.19,939.92],[1,1.01,12]],"ltp":0.0,"tv":0.0,"id":14036296}]}]}
{"op":"mcm","clk":"4226002862","pt":1631461524561,"mc":[{"id":"1.187552298","rc":[{"batb":[[0,1.01,12],[1,1.01,0]],"ltp":0.0,"tv":0.0,"id":14036296}]}]}
{"op":"mcm","clk":"4226020396","pt":1631461622376,"mc":[{"id":"1.187552298","rc":[{"batb":[[0,1.01,3989.18]],"ltp":0.0,"tv":0.0,"id":14036296}]}]}
{"op":"mcm","clk":"4226037741","pt":1631461671862,"mc":[{"id":"1.187552298","rc":[{"batb":[[0,1.01,12]],"ltp":0.0,"tv":0.0,"id":14036296}]}]}
{"op":"mcm","clk":"4226038788","pt":1631461677885,"mc":[{"id":"1.187552298","rc":[{"batl":[[0,340,36.48]],"ltp":0.0,"tv":0.0,"id":11105735}]}]}
{"op":"mcm","clk":"4226044696","pt":1631461711746,"mc":[{"id":"1.187552298","rc":[{"batb":[[0,1.01,3989.18]],"ltp":0.0,"tv":0.0,"id":14036296}]}]}
{"op":"mcm","clk":"4226047639","pt":1631461726992,"mc":[{"id":"1.187552298","rc":[{"batb":[[0,95,2.17],[1,1.01,12]],"ltp":0.0,"tv":0.0,"id":11105735}]}]}
{"op":"mcm","clk":"4226048089","pt":1631461729372,"mc":[{"id":"1.187552298","rc":[{"batb":[[0,1.01,12],[1,1.01,0]],"ltp":0.0,"tv":0.0,"id":11105735}]}]}
{"op":"mcm","clk":"4226050484","pt":1631461742619,"mc":[{"id":"1.187552298","rc":[{"batb":[[0,1.01,12]],"ltp":0.0,"tv":0.0,"id":14036296}]}]}
{"op":"mcm","clk":"4226051451","pt":1631461748437,"mc":[{"id":"1.187552298","rc":[{"batl":[[0,340,36.48]],"ltp":0.0,"tv":0.0,"id":11105735}]}]}
{"op":"mcm","clk":"4226055003","pt":1631461768168,"mc":[{"id":"1.187552298","rc":[{"batb":[[0,5,36.15],[1,1.01,12]],"ltp":0.0,"tv":0.0,"id":11105735}]}]}
{"op":"mcm","clk":"4226055467","pt":1631461770537,"mc":[{"id":"1.187552298","rc":[{"batb":[[0,1.01,12],[1,1.01,0]],"ltp":0.0,"tv":0.0,"id":11105735}]}]}
{"op":"mcm","clk":"4226057209","pt":1631461780484,"mc":[{"id":"1.187552298","rc":[{"batb":[[0,1.01,3989.18]],"ltp":0.0,"tv":0.0,"id":14036296}]}]}
{"op":"mcm","clk":"4226063779","pt":1631461818174,"mc":[{"id":"1.187552298","rc":[{"batb":[[0,1.01,12]],"ltp":0.0,"tv":0.0,"id":14036296}]}]}
{"op":"mcm","clk":"4226064679","pt":1631461823751,"mc":[{"id":"1.187552298","rc":[{"batb":[[0,1.02,2183.36],[1,1.01,12]],"ltp":0.0,"tv":0.0,"id":14036296}]}]}
{"op":"mcm","clk":"4226082618","pt":1631461930948,"mc":[{"id":"1.187552298","rc":[{"batb":[[0,1.01,12],[1,1.01,0]],"ltp":0.0,"tv":0.0,"id":14036296}]}]}
{"op":"mcm","clk":"4226083587","pt":1631461936785,"mc":[{"id":"1.187552298","rc":[{"batb":[[0,1.03,1561.16],[1,1.01,12]],"ltp":0.0,"tv":0.0,"id":14036296}]}]}
{"op":"mcm","clk":"4226086406","pt":1631461954226,"mc":[{"id":"1.187552298","rc":[{"batb":[[0,1.01,12],[1,1.01,0]],"ltp":0.0,"tv":0.0,"id":14036296}]}]}
{"op":"mcm","clk":"4226087420","pt":1631461959810,"mc":[{"id":"1.187552298","rc":[{"batb":[[0,1.04,1302.24],[1,1.01,12]],"ltp":0.0,"tv":0.0,"id":14036296}]}]}
{"op":"mcm","clk":"4226090414","pt":1631461977336,"mc":[{"id":"1.187552298","rc":[{"batb":[[0,1.01,12],[1,1.01,0]],"ltp":0.0,"tv":0.0,"id":14036296}]}]}
{"op":"mcm","clk":"4226091343","pt":1631461982944,"mc":[{"id":"1.187552298","rc":[{"batb":[[0,1.03,1561.16],[1,1.01,12]],"ltp":0.0,"tv":0.0,"id":14036296}]}]}
{"op":"mcm","clk":"4226093477","pt":1631461995457,"mc":[{"id":"1.187552298","rc":[{"batb":[[0,1.01,12],[1,1.01,0]],"ltp":0.0,"tv":0.0,"id":14036296}]}]}
{"op":"mcm","clk":"4226094435","pt":1631462001553,"mc":[{"id":"1.187552298","rc":[{"batb":[[0,1.04,1302.24],[1,1.01,12]],"ltp":0.0,"tv":0.0,"id":14036296}]}]}
{"op":"mcm","clk":"4226097453","pt":1631462019205,"mc":[{"id":"1.187552298","rc":[{"trd":[[1.2,2.76]],"batl":[[0,1.2,3.62]],"ltp":1.2,"tv":2.75,"id":14036296}],"tv":2.75}]}
{"op":"mcm","clk":"4226101992","pt":1631462046839,"mc":[{"id":"1.187552298","rc":[{"batb":[[0,1.01,12],[1,1.01,0]],"ltp":1.2,"tv":2.75,"id":14036296}]}]}
{"op":"mcm","clk":"4226102954","pt":1631462052460,"mc":[{"id":"1.187552298","rc":[{"batb":[[0,1.02,2183.36],[1,1.01,12]],"ltp":1.2,"tv":2.75,"id":14036296}]}]}
{"op":"mcm","clk":"4226110840","pt":1631462101281,"mc":[{"id":"1.187552298","rc":[{"batb":[[0,1.01,12],[1,1.01,0]],"ltp":1.2,"tv":2.75,"id":14036296}]}]}
{"op":"mcm","clk":"4226111722","pt":1631462107024,"mc":[{"id":"1.187552298","rc":[{"batb":[[0,1.01,3989.18]],"ltp":1.2,"tv":2.75,"id":14036296}]}]}
{"op":"mcm","clk":"4226114626","pt":1631462124435,"mc":[{"id":"1.187552298","rc":[{"batb":[[0,1.01,12]],"ltp":1.2,"tv":2.75,"id":14036296}]}]}
{"op":"mcm","clk":"4226115468","pt":1631462130007,"mc":[{"id":"1.187552298","rc":[{"batl":[[0,340,36.48]],"ltp":0.0,"tv":0.0,"id":11105735}]}]}
{"op":"mcm","clk":"4226133072","pt":1631462236693,"mc":[{"id":"1.187552298","rc":[{"batb":[[0,1.01,3989.18]],"ltp":1.2,"tv":2.75,"id":14036296}]}]}
{"op":"mcm","clk":"4226139054","pt":1631462275737,"mc":[{"id":"1.187552298","rc":[{"batb":[[0,1.01,12]],"ltp":1.2,"tv":2.75,"id":14036296}]}]}
{"op":"mcm","clk":"4226140064","pt":1631462281917,"mc":[{"id":"1.187552298","rc":[{"batb":[[0,1.01,4176.78]],"ltp":1.2,"tv":2.75,"id":14036296}]}]}
{"op":"mcm","clk":"4226146763","pt":1631462325282,"mc":[{"id":"1.187552298","rc":[{"batb":[[0,1.01,12]],"ltp":1.2,"tv":2.75,"id":14036296}]}]}
{"op":"mcm","clk":"4226147598","pt":1631462330931,"mc":[{"id":"1.187552298","rc":[{"batb":[[0,1.02,2183.36],[1,1.01,12]],"ltp":1.2,"tv":2.75,"id":14036296}]}]}
{"op":"mcm","clk":"4226163843","pt":1631462423166,"mc":[{"id":"1.187552298","rc":[{"trd":[[1.02,329.66]],"batb":[[0,1.02,2018.53]],"ltp":1.02,"tv":332.41,"id":14036296}],"tv":332.41}]}
{"op":"mcm","clk":"4226164214","pt":1631462424944,"mc":[{"id":"1.187552298","rc":[{"batb":[[0,1.01,12],[1,1.01,0]],"ltp":1.02,"tv":332.41,"id":14036296}]}]}
{"op":"mcm","clk":"4226164642","pt":1631462427327,"mc":[{"id":"1.187552298","rc":[{"trd":[[1.2,9.99]],"batl":[[0,1.3,1247.38],[1,1.42,40],[2,11.5,8.68]],"ltp":1.2,"tv":339.65,"id":14036296}],"tv":339.65}]}
{"op":"mcm","clk":"4226165207","pt":1631462430485,"mc":[{"id":"1.187552298","rc":[{"batb":[[0,1.04,1090.24],[1,1.01,12]],"ltp":1.2,"tv":339.65,"id":14036296}]}]}
{"op":"mcm","clk":"4226168355","pt":1631462446984,"mc":[{"id":"1.187552298","rc":[{"batb":[[0,1.01,12],[1,1.01,0]],"ltp":1.2,"tv":339.65,"id":14036296}]}]}
{"op":"mcm","clk":"4226169464","pt":1631462452672,"mc":[{"id":"1.187552298","rc":[{"batb":[[0,1.02,1995.72],[1,1.01,12]],"ltp":1.2,"tv":339.65,"id":14036296}]}]}
{"op":"mcm","clk":"4226171237","pt":1631462462123,"mc":[{"id":"1.187552298","rc":[{"batb":[[0,1.01,12],[1,1.01,0]],"ltp":1.2,"tv":339.65,"id":14036296}]}]}
{"op":"mcm","clk":"4226172315","pt":1631462467741,"mc":[{"id":"1.187552298","rc":[{"batb":[[0,1.03,1389.79],[1,1.01,12]],"ltp":1.2,"tv":339.65,"id":14036296}]}]}
{"op":"mcm","clk":"4226173413","pt":1631462473537,"mc":[{"id":"1.187552298","rc":[{"batb":[[0,1.28,939.92],[1,1.03,1389.79],[2,1.01,12]],"ltp":1.2,"tv":339.65,"id":14036296}]}]}
{"op":"mcm","clk":"4226173766","pt":1631462475350,"mc":[{"id":"1.187552298","rc":[{"batb":[[0,1.03,1389.79],[1,1.01,12],[2,1.01,0]],"ltp":1.2,"tv":339.65,"id":14036296}]}]}
{"op":"mcm","clk":"4226174115","pt":1631462477135,"mc":[{"id":"1.187552298","rc":[{"batb":[[0,1.01,12],[1,1.01,0]],"ltp":1.2,"tv":339.65,"id":14036296}]}]}
{"op":"mcm","clk":"4226175239","pt":1631462482854,"mc":[{"id":"1.187552298","rc":[{"batb":[[0,1.01,3891.32]],"ltp":1.2,"tv":339.65,"id":14036296}]}]}
{"op":"mcm","clk":"4226179206","pt":1631462503282,"mc":[{"id":"1.187552298","rc":[{"batb":[[0,1.01,12]],"ltp":1.2,"tv":339.65,"id":14036296}]}]}
{"op":"mcm","clk":"4226180268","pt":1631462508992,"mc":[{"id":"1.187552298","rc":[{"batl":[[0,170,36.57]],"ltp":0.0,"tv":0.0,"id":11105735}]}]}
{"op":"mcm","clk":"4226184059","pt":1631462529173,"mc":[{"id":"1.187552298","rc":[{"batl":[[0,340,35.97]],"ltp":0.0,"tv":0.0,"id":11105735}]}]}
{"op":"mcm","clk":"4226197316","pt":1631462596465,"mc":[{"id":"1.187552298","rc":[{"batb":[[0,1.27,867.62],[1,1.01,12]],"ltp":1.2,"tv":339.65,"id":14036296}]}]}
{"op":"mcm","clk":"4226197632","pt":1631462598189,"mc":[{"id":"1.187552298","rc":[{"batb":[[0,1.01,12],[1,1.01,0]],"ltp":1.2,"tv":339.65,"id":14036296}]}]}
{"op":"mcm","clk":"4226218678","pt":1631462718921,"mc":[{"id":"1.187552298","rc":[{"trd":[[1.01,24]],"batl":[[0,1.01,5.08],[1,1.3,1247.38],[2,1.42,40]],"ltp":1.01,"tv":363.65,"id":14036296}],"tv":363.65}]}
{"op":"mcm","clk":"4226238434","pt":1631462820419,"mc":[{"id":"1.187552298","rc":[{"trd":[[1.01,34.16]],"batb":[[0,1.01,67.22]],"batl":[[0,1.3,1247.38],[1,1.42,40],[2,11.5,8.68]],"ltp":1.01,"tv":373.81,"id":14036296}],"tv":373.81}]}
{"op":"mcm","clk":"4226241270","pt":1631462830044,"mc":[{"id":"1.187552298","rc":[{"batl":[[0,1.42,40],[1,11.5,8.68],[2,11.5,0]],"ltp":1.01,"tv":373.81,"id":14036296}]}]}
{"op":"mcm","clk":"4226244199","pt":1631462839165,"mc":[{"id":"1.187552298","rc":[{"batl":[[0,1.27,1547.85],[1,1.42,40],[2,11.5,8.68]],"ltp":1.01,"tv":373.81,"id":14036296}]}]}
{"op":"mcm","clk":"4226246042","pt":1631462848748,"mc":[{"id":"1.187552298","rc":[{"batl":[[0,1.42,40],[1,11.5,8.68],[2,11.5,0]],"ltp":1.01,"tv":373.81,"id":14036296}]}]}
{"op":"mcm","clk":"4226246648","pt":1631462852119,"mc":[{"id":"1.187552298","rc":[{"batl":[[0,1.25,4.11],[1,1.42,40],[2,11.5,8.68]],"ltp":1.01,"tv":373.81,"id":14036296}]}]}
{"op":"mcm","clk":"4226246936","pt":1631462853960,"mc":[{"id":"1.187552298","rc":[{"trd":[[1.25,8.21]],"batb":[[0,1.25,0.23]],"batl":[[0,1.42,40],[1,11.5,8.68],[2,11.5,0]],"ltp":1.25,"tv":382.03,"id":14036296}],"tv":382.03}]}
{"op":"mcm","clk":"4226248783","pt":1631462864464,"mc":[{"id":"1.187552298","rc":[{"batl":[[0,1.25,72.3],[1,1.42,40],[2,11.5,8.68]],"ltp":1.25,"tv":382.03,"id":14036296}]}]}
{"op":"mcm","clk":"4226249985","pt":1631462871387,"mc":[{"id":"1.187552298","rc":[{"trd":[[1.25,16.89]],"batl":[[0,1.25,67.96]],"ltp":1.25,"tv":390.7,"id":14036296}],"tv":390.7}]}
{"op":"mcm","clk":"4226250632","pt":1631462875478,"mc":[{"id":"1.187552298","rc":[{"batl":[[2,11.5,80.98]],"ltp":1.25,"tv":390.7,"id":14036296}]}]}
{"op":"mcm","clk":"4226251628","pt":1631462881169,"mc":[{"id":"1.187552298","rc":[{"batb":[[0,1.22,4.34]],"batl":[[0,1.42,40],[1,1.42,0],[2,11.5,0]],"ltp":1.25,"tv":390.7,"id":14036296}]}]}
{"op":"mcm","clk":"4226251745","pt":1631462881891,"mc":[{"id":"1.187552298","rc":[{"trd":[[1.22,8.68]],"batl":[[0,1.01,833.04],[1,1.42,40]],"ltp":1.22,"tv":399.38,"id":14036296}],"tv":399.38}]}
{"op":"mcm","clk":"4226251963","pt":1631462883167,"mc":[{"id":"1.187552298","rc":[{"batl":[[1,1.2,72.3],[2,1.42,40]],"ltp":1.22,"tv":399.38,"id":14036296}]}]}
{"op":"mcm","clk":"4226252593","pt":1631462886375,"mc":[{"id":"1.187552298","rc":[{"trd":[[1.01,42.84]],"batl":[[0,1.01,828.7]],"ltp":1.01,"tv":408.06,"id":14036296}],"tv":408.06}]}
{"op":"mcm","clk":"4226260612","pt":1631462927493,"mc":[{"id":"1.187552298","marketDefinition":{"bspMarket":false,"turnInPlayEnabled":true,"persistenceEnabled":true,"marketBaseRate":5.0,"eventId":"30895244","eventTypeId":"2","numberOfWinners":1,"bettingType":"ODDS","marketType":"MATCH_ODDS","marketTime":"2021-09-12T14:45:33.000Z","suspendTime":"2021-09-12T14:45:33.000Z","bspReconciled":false,"complete":true,"inPlay":true,"crossMatching":true,"runnersVoidable":false,"numberOfActiveRunners":2,"betDelay":5,"status":"SUSPENDED","runners":[{"status":"ACTIVE","sortPriority":1,"id":14036296,"name":"E Avanesyan"},{"status":"ACTIVE","sortPriority":2,"id":11105735,"name":"S Grey"}],"regulators":["MR_INT"],"countryCode":"GB","discountAllowed":true,"timezone":"GMT","openDate":"2021-09-12T14:45:33.000Z","version":4029042671,"name":"Match Odds","eventName":"E Avanesyan v S Grey"}}]}
{"op":"mcm","clk":"4226263199","pt":1631462938178,"mc":[{"id":"1.187552298","tv":0.0}]}
{"op":"mcm","clk":"4226263591","pt":1631462939580,"mc":[{"id":"1.187552298","marketDefinition":{"bspMarket":false,"turnInPlayEnabled":true,"persistenceEnabled":true,"marketBaseRate":5.0,"eventId":"30895244","eventTypeId":"2","numberOfWinners":1,"bettingType":"ODDS","marketType":"MATCH_ODDS","marketTime":"2021-09-12T14:45:33.000Z","suspendTime":"2021-09-12T14:45:33.000Z","bspReconciled":false,"complete":true,"inPlay":true,"crossMatching":false,"runnersVoidable":false,"numberOfActiveRunners":0,"betDelay":5,"status":"CLOSED","settledTime":"2021-09-12T16:08:56.000Z","runners":[{"status":"WINNER","sortPriority":1,"id":14036296,"name":"E Avanesyan"},{"status":"LOSER","sortPriority":2,"id":11105735,"name":"S Grey"}],"regulators":["MR_INT"],"countryCode":"GB","discountAllowed":true,"timezone":"GMT","openDate":"2021-09-12T14:45:33.000Z","version":4029044123,"name":"Match Odds","eventName":"E Avanesyan v S Grey"}}]}
