{"op":"mcm","clk":"4230443408","pt":1631533059658,"mc":[{"id":"1.187557247","rc":[{"batl":[[0,1.7,158],[1,1.71,77.73],[2,1.73,231.95]],"ltp":1.7,"tv":16623.25,"id":9304761}]}]}
{"op":"mcm","clk":"4230443508","pt":1631533060756,"mc":[{"id":"1.187557247","rc":[{"batb":[[1,2.3,46.15],[2,2.12,134.74]],"ltp":2.38,"tv":38365.13,"id":10350473}]}]}
{"op":"mcm","clk":"4230443574","pt":1631533061580,"mc":[{"id":"1.187557247","rc":[{"trd":[[1.7,1423.44]],"batl":[[0,1.7,157.91]],"ltp":1.7,"tv":16623.44,"id":9304761}],"tv":54988.57}]}
{"op":"mcm","clk":"4230443635","pt":1631533062256,"mc":[{"id":"1.187557247","rc":[{"trd":[[2.46,2.5]],"ltp":2.46,"tv":38367.63,"id":10350473},{"trd":[[1.69,889.62]],"batb":[[0,1.69,59.21]],"ltp":1.69,"tv":16627.07,"id":9304761}],"tv":54994.71}]}
{"op":"mcm","clk":"4230443762","pt":1631533063492,"mc":[{"id":"1.187557247","rc":[{"batl":[[0,2.52,35.51],[1,2.54,48.34],[2,2.56,410.88]],"ltp":2.46,"tv":38367.63,"id":10350473},{"trd":[[1.69,901.59]],"batb":[[0,1.68,64.53],[1,1.67,2069.85],[2,1.66,184.31]],"batl":[[0,1.69,67.51],[1,1.7,157.91],[2,1.72,10.37]],"ltp":1.69,"tv":16639.05,"id":9304761}],"tv":55006.68}]}
{"op":"mcm","clk":"4230443866","pt":1631533064590,"mc":[{"id":"1.187557247","rc":[{"batb":[[2,2.12,114.74]],"batl":[[0,2.54,48.34],[1,2.56,410.88],[2,2.58,398.8]],"ltp":2.46,"tv":38367.63,"id":10350473},{"batb":[[1,1.66,184.31],[2,1.54,10.02]],"ltp":1.69,"tv":16639.05,"id":9304761}]}]}
{"op":"mcm","clk":"4230444060","pt":1631533066971,"mc":[{"id":"1.187557247","rc":[{"trd":[[2.44,3.65]],"batb":[[2,2.16,7.28]],"ltp":2.44,"tv":38370.23,"id":10350473},{"trd":[[1.69,905.35]],"batl":[[0,1.69,63.75]],"ltp":1.69,"tv":16642.8,"id":9304761}],"tv":55013.04}]}
{"op":"mcm","clk":"4230444191","pt":1631533068684,"mc":[{"id":"1.187557247","rc":[{"trd":[[2.44,5.65]],"batb":[[0,2.3,46.15],[1,1.63,24],[2,1.45,719.75]],"batl":[[1,2.56,0],[2,2.58,0]],"ltp":2.44,"tv":38372.23,"id":10350473},{"trd":[[1.69,908.23]],"batb":[[1,1.66,73.85]],"batl":[[0,1.69,60.87]],"ltp":1.69,"tv":16645.69,"id":9304761}],"tv":55017.93}]}
{"op":"mcm","clk":"4230444228","pt":1631533069197,"mc":[{"id":"1.187557247","rc":[{"batb":[[0,1.66,73.85],[1,1.54,10.02],[2,1.52,430.52]],"batl":[[0,1.69,56.47],[1,1.72,10.37],[2,1.77,60]],"ltp":1.69,"tv":16645.69,"id":9304761}]}]}
{"op":"mcm","clk":"4230444340","pt":1631533070581,"mc":[{"id":"1.187557247","rc":[{"batb":[[0,1.63,24],[1,1.45,719.75],[2,1.44,851.79]],"ltp":2.44,"tv":38372.23,"id":10350473},{"batb":[[0,1.54,10.02],[1,1.3,198.07],[2,1.2,388.24]],"batl":[[0,1.72,10.37],[1,2.02,9.9],[2,3.45,53.16]],"ltp":1.69,"tv":16645.69,"id":9304761}]}]}
{"op":"mcm","clk":"4230444415","pt":1631533071464,"mc":[{"id":"1.187557247","rc":[{"batl":[[0,2.42,5]],"ltp":2.44,"tv":38372.23,"id":10350473},{"batl":[[0,2.02,9.9],[1,3.45,53.16],[2,810,0.07]],"ltp":1.69,"tv":16645.69,"id":9304761}]}]}
{"op":"mcm","clk":"4230444609","pt":1631533073600,"mc":[{"id":"1.187557247","rc":[{"batb":[[0,2.1,54.54],[1,1.63,24],[2,1.45,719.75]],"batl":[[0,2.3,52.62],[1,2.42,5]],"ltp":2.44,"tv":38372.23,"id":10350473},{"batb":[[0,1.3,198.07],[1,1.2,388.24],[2,1.1,297.11]],"batl":[[0,1.91,60],[1,2.02,9.9],[2,3.45,53.16]],"ltp":1.69,"tv":16645.69,"id":9304761}]}]}
{"op":"mcm","clk":"4230444709","pt":1631533074697,"mc":[{"id":"1.187557247","rc":[{"batb":[[0,1.63,24],[1,1.45,719.75],[2,1.44,851.79]],"batl":[[0,2.42,5],[1,2.42,0]],"ltp":2.44,"tv":38372.23,"id":10350473},{"batb":[[0,1.77,68.37],[1,1.3,198.07],[2,1.2,388.24]],"batl":[[0,2.02,9.9],[1,3.45,53.16],[2,810,0.07]],"ltp":1.69,"tv":16645.69,"id":9304761}]}]}
{"op":"mcm","clk":"4230444820","pt":1631533075585,"mc":[{"id":"1.187557247","rc":[{"batb":[[0,1.3,198.07],[1,1.2,388.24],[2,1.1,297.11]],"ltp":1.69,"tv":16645.69,"id":9304761}]}]}
{"op":"mcm","clk":"4230444924","pt":1631533076970,"mc":[{"id":"1.187557247","rc":[{"batb":[[0,1.94,61.88],[1,1.63,24],[2,1.45,719.75]],"batl":[[0,2.1,57.2]],"ltp":2.44,"tv":38372.23,"id":10350473},{"batl":[[1,2.08,57.73],[2,3.45,53.16]],"ltp":1.69,"tv":16645.69,"id":9304761}]}]}
{"op":"mcm","clk":"4230445043","pt":1631533078372,"mc":[{"id":"1.187557247","rc":[{"batb":[[1,1.81,73.76],[2,1.63,24]],"ltp":2.44,"tv":38372.23,"id":10350473},{"batb":[[0,1.96,464.31],[1,1.91,62.89],[2,1.3,198.07]],"ltp":1.69,"tv":16645.69,"id":9304761}]}]}
{"op":"mcm","clk":"4230445228","pt":1631533080713,"mc":[{"id":"1.187557247","rc":[{"batb":[[1,1.4,148.56]],"ltp":1.69,"tv":16645.69,"id":9304761}]}]}
{"op":"mcm","clk":"4230445364","pt":1631533082284,"mc":[{"id":"1.187557247","rc":[{"trd":[[1.96,923.11]],"batb":[[0,1.96,283.31]],"ltp":1.96,"tv":17007.69,"id":9304761}],"tv":55379.93}]}
{"op":"mcm","clk":"4230445459","pt":1631533083582,"mc":[{"id":"1.187557247","rc":[{"batb":[[1,1.63,24],[2,1.45,719.75]],"ltp":2.44,"tv":38372.23,"id":10350473}]}]}
{"op":"mcm","clk":"4230445482","pt":1631533083895,"mc":[{"id":"1.187557247","rc":[{"batb":[[1,1.93,62.21],[2,1.4,148.56]],"ltp":1.96,"tv":17007.69,"id":9304761}]}]}
{"op":"mcm","clk":"4230445800","pt":1631533087584,"mc":[{"id":"1.187557247","rc":[{"trd":[[1.96,933.53]],"batb":[[0,1.96,278.1]],"ltp":1.96,"tv":17018.11,"id":9304761}],"tv":55390.35}]}
{"op":"mcm","clk":"4230445921","pt":1631533088887,"mc":[{"id":"1.187557247","rc":[{"batb":[[0,1.63,24],[1,1.45,719.75],[2,1.44,851.79]],"ltp":2.44,"tv":38372.23,"id":10350473}]}]}
{"op":"mcm","clk":"4230446167","pt":1631533091694,"mc":[{"id":"1.187557247","rc":[{"trd":[[1.96,933.71]],"batb":[[0,1.96,278.01]],"ltp":1.96,"tv":17018.29,"id":9304761}],"tv":55390.53}]}
{"op":"mcm","clk":"4230446202","pt":1631533092107,"mc":[{"id":"1.187557247","rc":[{"batb":[[0,1.92,62.55],[1,1.64,87.62],[2,1.63,24]],"ltp":2.44,"tv":38372.23,"id":10350473}]}]}
{"op":"mcm","clk":"4230446884","pt":1631533095750,"mc":[{"id":"1.187557247","rc":[{"batb":[[1,1.63,24],[2,1.45,719.75]],"ltp":2.44,"tv":38372.23,"id":10350473}]}]}
{"op":"mcm","clk":"4230447000","pt":1631533096288,"mc":[{"id":"1.187557247","rc":[{"trd":[[1.98,782.98]],"ltp":1.98,"tv":38373.99,"id":10350473},{"trd":[[2.02,9.05]],"batl":[[0,2.02,6.52]],"ltp":2.02,"tv":17023.33,"id":9304761}],"tv":55397.33}]}
{"op":"mcm","clk":"4230447317","pt":1631533099506,"mc":[{"id":"1.187557247","rc":[{"batb":[[0,1.96,510.16]],"ltp":2.02,"tv":17023.33,"id":9304761}]}]}
{"op":"mcm","clk":"4230447398","pt":1631533100532,"mc":[{"id":"1.187557247","rc":[{"batb":[[0,1.98,10],[1,1.92,62.55],[2,1.63,24]],"ltp":1.98,"tv":38373.99,"id":10350473}]}]}
{"op":"mcm","clk":"4230447488","pt":1631533101527,"mc":[{"id":"1.187557247","rc":[{"trd":[[2.06,230.61]],"ltp":2.06,"tv":38382.51,"id":10350473},{"trd":[[1.96,942.67]],"batb":[[0,1.96,501.21]],"ltp":1.96,"tv":17032.29,"id":9304761}],"tv":55414.8}]}
{"op":"mcm","clk":"4230447519","pt":1631533101933,"mc":[{"id":"1.187557247","rc":[{"trd":[[2.06,239.13]],"ltp":2.06,"tv":38391.02,"id":10350473},{"trd":[[1.96,951.62]],"batb":[[0,1.96,492.25]],"ltp":1.96,"tv":17041.24,"id":9304761}],"tv":55432.27}]}
{"op":"mcm","clk":"4230447687","pt":1631533103815,"mc":[{"id":"1.187557247","rc":[{"trd":[[2.06,241.68]],"ltp":2.06,"tv":38393.57,"id":10350473},{"trd":[[1.96,954.3]],"batb":[[0,1.96,489.57]],"ltp":1.96,"tv":17043.92,"id":9304761}],"tv":55437.5}]}
{"op":"mcm","clk":"4230447852","pt":1631533105732,"mc":[{"id":"1.187557247","rc":[{"batb":[[1,1.63,24],[2,1.45,719.75]],"ltp":2.06,"tv":38393.57,"id":10350473}]}]}
{"op":"mcm","clk":"4230448105","pt":1631533108913,"mc":[{"id":"1.187557247","rc":[{"batb":[[1,1.94,61.88],[2,1.63,24]],"ltp":2.06,"tv":38393.57,"id":10350473}]}]}
{"op":"mcm","clk":"4230449398","pt":1631533124665,"mc":[{"id":"1.187557247","rc":[{"trd":[[1.98,809.64]],"batb":[[0,1.94,61.88],[1,1.63,24],[2,1.45,719.75]],"batl":[[0,1.98,7.75],[1,2.1,57.2]],"ltp":1.98,"tv":38420.23,"id":10350473},{"trd":[[2.02,15.57]],"batl":[[0,2.08,57.73],[1,3.45,53.16],[2,3.45,0]],"ltp":2.02,"tv":17050.44,"id":9304761}],"tv":55470.67}]}
{"op":"mcm","clk":"4230449414","pt":1631533124874,"mc":[{"id":"1.187557247","rc":[{"batl":[[1,2.1,0]],"ltp":1.98,"tv":38420.23,"id":10350473}]}]}
{"op":"mcm","clk":"4230449665","pt":1631533128066,"mc":[{"id":"1.187557247","rc":[{"batl":[[1,2.08,57.73]],"ltp":1.98,"tv":38420.23,"id":10350473}]}]}
{"op":"mcm","clk":"4230449913","pt":1631533131663,"mc":[{"id":"1.187557247","rc":[{"trd":[[1.98,815.61]],"batl":[[0,1.98,1.78]],"ltp":1.98,"tv":38426.2,"id":10350473},{"trd":[[2.02,21.43]],"ltp":2.02,"tv":17056.3,"id":9304761}],"tv":55482.51}]}
{"op":"mcm","clk":"4230450435","pt":1631533138996,"mc":[{"id":"1.187557247","rc":[{"batb":[[0,1.95,10],[1,1.94,61.88],[2,1.63,24]],"ltp":1.98,"tv":38426.2,"id":10350473}]}]}
{"op":"mcm","clk":"4230450656","pt":1631533141996,"mc":[{"id":"1.187557247","rc":[{"batl":[[0,2.06,196.85],[1,2.08,57.73],[2,3.45,53.16]],"ltp":2.02,"tv":17056.3,"id":9304761}]}]}
{"op":"mcm","clk":"4230450793","pt":1631533143832,"mc":[{"id":"1.187557247","rc":[{"trd":[[1.98,817.39]],"batl":[[0,2.08,57.73],[1,2.08,0]],"ltp":1.98,"tv":38427.98,"id":10350473},{"trd":[[1.96,980.82],[2.02,23.17]],"batb":[[0,1.96,476.31]],"ltp":1.96,"tv":17084.56,"id":9304761}],"tv":55512.54}]}
{"op":"mcm","clk":"4230451718","pt":1631533155209,"mc":[{"id":"1.187557247","rc":[{"batl":[[0,2.1,57.2]],"ltp":1.98,"tv":38427.98,"id":10350473}]}]}
{"op":"mcm","clk":"4230452087","pt":1631533159719,"mc":[{"id":"1.187557247","rc":[{"batb":[[0,2,2.53],[1,1.99,5.09],[2,1.98,61.38]],"batl":[[0,2.02,77.32],[1,2.04,75.18],[2,2.06,196.85]],"ltp":1.96,"tv":17084.56,"id":9304761}]}]}
{"op":"mcm","clk":"4230453088","pt":1631533168728,"mc":[{"id":"1.187557247","rc":[{"batb":[[2,1.98,63.68]],"ltp":1.96,"tv":17084.56,"id":9304761}]}]}
{"op":"mcm","clk":"4230453110","pt":1631533169033,"mc":[{"id":"1.187557247","rc":[{"batb":[[0,1.98,63.68],[1,1.97,3.08],[2,1.96,476.31]],"ltp":1.96,"tv":17084.56,"id":9304761}]}]}
{"op":"mcm","clk":"4230454814","pt":1631533189246,"mc":[{"id":"1.187557247","rc":[{"batb":[[0,1.94,61.88],[1,1.63,24],[2,1.45,719.75]],"ltp":1.98,"tv":38427.98,"id":10350473}]}]}
{"op":"mcm","clk":"4230455003","pt":1631533191441,"mc":[{"id":"1.187557247","rc":[{"batb":[[0,1.63,24],[1,1.45,719.75],[2,1.44,851.79]],"ltp":1.98,"tv":38427.98,"id":10350473}]}]}
{"op":"mcm","clk":"4230455038","pt":1631533191864,"mc":[{"id":"1.187557247","rc":[{"batl":[[0,2.06,196.85],[1,3.45,53.16],[2,2.06,0]],"ltp":1.96,"tv":17084.56,"id":9304761}]}]}
{"op":"mcm","clk":"4230455143","pt":1631533193427,"mc":[{"id":"1.187557247","rc":[{"batb":[[0,1.4,148.56],[1,1.3,198.07],[2,1.2,388.24]],"ltp":1.96,"tv":17084.56,"id":9304761}]}]}
{"op":"mcm","clk":"4230455708","pt":1631533201062,"mc":[{"id":"1.187557247","rc":[{"batl":[[0,3.45,53.16],[1,3.45,0]],"ltp":1.96,"tv":17084.56,"id":9304761}]}]}
{"op":"mcm","clk":"4230455922","pt":1631533203675,"mc":[{"id":"1.187557247","rc":[{"batb":[[0,2.06,216.97],[1,1.97,216.97],[2,1.4,148.56]],"ltp":1.96,"tv":17084.56,"id":9304761}]}]}
{"op":"mcm","clk":"4230456055","pt":1631533205366,"mc":[{"id":"1.187557247","rc":[{"batb":[[0,1.77,68.37],[1,1.63,24],[2,1.45,719.75]],"batl":[[0,1.9,60]],"ltp":1.98,"tv":38427.98,"id":10350473},{"batb":[[0,2.1,54.54],[1,2.06,216.97],[2,1.97,216.97]],"batl":[[0,2.3,52.62],[1,3.45,53.16]],"ltp":1.96,"tv":17084.56,"id":9304761}]}]}
{"op":"mcm","clk":"4230456236","pt":1631533207454,"mc":[{"id":"1.187557247","rc":[{"batb":[[0,1.63,24],[1,1.45,719.75],[2,1.44,851.79]],"ltp":1.98,"tv":38427.98,"id":10350473},{"batb":[[0,2.06,216.97],[1,1.97,216.97],[2,1.4,148.56]],"batl":[[0,3.45,53.16],[1,3.45,0]],"ltp":1.96,"tv":17084.56,"id":9304761}]}]}
{"op":"mcm","clk":"4230456381","pt":1631533209477,"mc":[{"id":"1.187557247","rc":[{"batb":[[0,1.65,120.92],[1,1.63,24],[2,1.45,719.75]],"ltp":1.98,"tv":38427.98,"id":10350473},{"batb":[[1,1.97,344.75]],"ltp":1.96,"tv":17084.56,"id":9304761}]}]}
{"op":"mcm","clk":"4230456456","pt":1631533210268,"mc":[{"id":"1.187557247","rc":[{"batl":[[0,2.2,196.13],[1,3.45,53.16]],"ltp":1.96,"tv":17084.56,"id":9304761}]}]}
{"op":"mcm","clk":"4230456650","pt":1631533212668,"mc":[{"id":"1.187557247","rc":[{"batb":[[0,1.98,10.51]],"ltp":1.96,"tv":17084.56,"id":9304761}]}]}
{"op":"mcm","clk":"4230457166","pt":1631533218758,"mc":[{"id":"1.187557247","rc":[{"batb":[[0,1.79,2.32],[1,1.65,120.92],[2,1.63,24]],"ltp":1.98,"tv":38427.98,"id":10350473}]}]}
{"op":"mcm","clk":"4230457740","pt":1631533226768,"mc":[{"id":"1.187557247","rc":[{"batb":[[0,1.93,10],[1,1.79,2.32],[2,1.65,120.92]],"ltp":1.98,"tv":38427.98,"id":10350473}]}]}
{"op":"mcm","clk":"4230458282","pt":1631533234511,"mc":[{"id":"1.187557247","rc":[{"batb":[[0,1.97,344.75],[1,1.4,148.56],[2,1.3,198.07]],"ltp":1.96,"tv":17084.56,"id":9304761}]}]}
{"op":"mcm","clk":"4230458372","pt":1631533235708,"mc":[{"id":"1.187557247","rc":[{"batb":[[1,1.8,8.37],[2,1.79,2.32]],"ltp":1.98,"tv":38427.98,"id":10350473}]}]}
{"op":"mcm","clk":"4230458495","pt":1631533237318,"mc":[{"id":"1.187557247","rc":[{"batb":[[0,1.8,8.37],[1,1.79,2.32],[2,1.65,120.92]],"ltp":1.98,"tv":38427.98,"id":10350473}]}]}
{"op":"mcm","clk":"4230458618","pt":1631533238897,"mc":[{"id":"1.187557247","rc":[{"batb":[[1,1.41,13.53],[2,1.4,148.56]],"ltp":1.96,"tv":17084.56,"id":9304761}]}]}
{"op":"mcm","clk":"4230458875","pt":1631533241915,"mc":[{"id":"1.187557247","rc":[{"batl":[[0,3.45,53.16],[1,3.45,0]],"ltp":1.96,"tv":17084.56,"id":9304761}]}]}
{"op":"mcm","clk":"4230459105","pt":1631533244715,"mc":[{"id":"1.187557247","rc":[{"batb":[[0,2.2,216.97],[1,1.97,344.75],[2,1.41,13.53]],"ltp":1.96,"tv":17084.56,"id":9304761}]}]}
{"op":"mcm","clk":"4230459215","pt":1631533245722,"mc":[{"id":"1.187557247","rc":[{"trd":[[1.79,210.42],[1.8,8.37]],"batb":[[0,1.65,120.92],[1,1.63,24],[2,1.56,147.78]],"ltp":1.79,"tv":38438.67,"id":10350473},{"trd":[[2.26,6.67],[2.28,2.27]],"batb":[[0,2.42,61.05],[1,2.2,307.34],[2,1.97,216.97]],"ltp":2.28,"tv":17093.05,"id":9304761}],"tv":55531.72}]}
{"op":"mcm","clk":"4230459440","pt":1631533248410,"mc":[{"id":"1.187557247","rc":[{"batl":[[0,1.75,60]],"ltp":1.79,"tv":38438.67,"id":10350473}]}]}
{"op":"mcm","clk":"4230459512","pt":1631533249341,"mc":[{"id":"1.187557247","rc":[{"batb":[[1,1.63,99.59]],"ltp":1.79,"tv":38438.67,"id":10350473},{"batb":[[1,2.34,44.77],[2,2.2,307.34]],"batl":[[0,2.58,47.73],[1,3.45,53.16]],"ltp":2.28,"tv":17093.05,"id":9304761}]}]}
{"op":"mcm","clk":"4230459608","pt":1631533250540,"mc":[{"id":"1.187557247","rc":[{"batb":[[0,1.69,42.21],[1,1.65,163.45],[2,1.63,99.59]],"batl":[[1,1.94,26.25]],"ltp":1.79,"tv":38438.67,"id":10350473},{"trd":[[2.42,159.04]],"batb":[[0,2.2,307.34],[1,2.06,239.73],[2,1.97,216.97]],"batl":[[0,2.42,117.26],[1,2.46,6.25],[2,2.54,5.75]],"ltp":2.42,"tv":17215.14,"id":9304761}],"tv":55653.82}]}
{"op":"mcm","clk":"4230459668","pt":1631533251216,"mc":[{"id":"1.187557247","rc":[{"trd":[[1.69,197.19],[1.7,319.56]],"batb":[[0,1.69,41.18],[2,1.63,234.37]],"batl":[[1,1.94,0]],"ltp":1.69,"tv":38607.65,"id":10350473},{"trd":[[2.42,276.3]],"batb":[[1,2.06,232.15]],"batl":[[0,2.46,6.25],[1,2.54,5.75],[2,2.58,47.73]],"ltp":2.42,"tv":17332.4,"id":9304761}],"tv":55940.05}]}
{"op":"mcm","clk":"4230459805","pt":1631533252720,"mc":[{"id":"1.187557247","rc":[{"batl":[[0,1.74,96.6],[1,1.75,60]],"ltp":1.69,"tv":38607.65,"id":10350473}]}]}
{"op":"mcm","clk":"4230459882","pt":1631533253746,"mc":[{"id":"1.187557247","rc":[{"batl":[[0,1.72,2.65],[2,1.83,10.68]],"ltp":1.69,"tv":38607.65,"id":10350473},{"batb":[[0,2.42,262.81],[1,2.36,44.11],[2,2.2,307.34]],"ltp":2.42,"tv":17332.4,"id":9304761}]}]}
{"op":"mcm","clk":"4230459954","pt":1631533254534,"mc":[{"id":"1.187557247","rc":[{"trd":[[1.69,274.32]],"batb":[[0,1.65,163.45],[1,1.64,142.79]],"batl":[[0,1.69,192.29],[1,1.71,228.43],[2,1.75,60]],"ltp":1.69,"tv":38684.78,"id":10350473},{"trd":[[2.46,17.31]],"batb":[[0,2.46,104.41],[1,2.42,262.81],[2,2.36,44.11]],"batl":[[0,2.54,5.75],[1,2.58,47.73],[2,3.45,53.16]],"ltp":2.46,"tv":17348.49,"id":9304761}],"tv":56033.28}]}
{"op":"mcm","clk":"4230460048","pt":1631533255734,"mc":[{"id":"1.187557247","rc":[{"batb":[[2,1.63,275.6]],"ltp":1.69,"tv":38684.78,"id":10350473},{"batb":[[0,2.46,190.77],[1,2.42,46.48]],"batl":[[2,2.6,5.56]],"ltp":2.46,"tv":17348.49,"id":9304761}]}]}
{"op":"mcm","clk":"4230460124","pt":1631533256550,"mc":[{"id":"1.187557247","rc":[{"batl":[[2,1.83,10.68]],"ltp":1.69,"tv":38684.78,"id":10350473},{"trd":[[2.46,34.35]],"batb":[[0,2.46,182.26],[1,2.36,44.11],[2,2.2,307.34]],"ltp":2.46,"tv":17365.53,"id":9304761}],"tv":56050.32}]}
{"op":"mcm","clk":"4230460216","pt":1631533257539,"mc":[{"id":"1.187557247","rc":[{"trd":[[1.69,584.32]],"batl":[[0,1.83,10.68],[1,1.97,28.5],[2,1.83,0]],"ltp":1.69,"tv":38994.78,"id":10350473},{"batb":[[0,2.36,44.11],[1,2.2,307.34],[2,2.02,7.74]],"ltp":2.46,"tv":17365.53,"id":9304761}],"tv":56360.32}]}
{"op":"mcm","clk":"4230460294","pt":1631533258634,"mc":[{"id":"1.187557247","rc":[{"batl":[[2,1.98,28.75]],"ltp":1.69,"tv":38994.78,"id":10350473}]}]}
{"op":"mcm","clk":"4230460368","pt":1631533259664,"mc":[{"id":"1.187557247","rc":[{"batl":[[0,1.73,60],[1,1.83,10.68],[2,1.97,28.5]],"ltp":1.69,"tv":38994.78,"id":10350473},{"batb":[[0,2.2,307.34],[1,2.02,7.74],[2,1.97,216.97]],"ltp":2.46,"tv":17365.53,"id":9304761}]}]}
{"op":"mcm","clk":"4230460455","pt":1631533260766,"mc":[{"id":"1.187557247","rc":[{"batb":[[0,1.63,99.59],[1,1.57,54.01],[2,1.56,147.78]],"ltp":1.69,"tv":38994.78,"id":10350473},{"batl":[[0,2.58,47.73],[1,2.76,5.02],[2,3.45,53.16]],"ltp":2.46,"tv":17365.53,"id":9304761}]}]}
{"op":"mcm","clk":"4230460511","pt":1631533261444,"mc":[{"id":"1.187557247","rc":[{"batb":[[0,1.63,24]],"batl":[[0,1.83,10.68],[1,1.97,28.5],[2,1.98,28.75]],"ltp":1.69,"tv":38994.78,"id":10350473},{"batl":[[0,2.76,5.02],[1,3.45,53.16],[2,3.45,0]],"ltp":2.46,"tv":17365.53,"id":9304761}]}]}
{"op":"mcm","clk":"4230460616","pt":1631533262647,"mc":[{"id":"1.187557247","rc":[{"batb":[[0,1.69,110],[1,1.63,24],[2,1.57,54.01]],"ltp":1.69,"tv":38994.78,"id":10350473}]}]}
{"op":"mcm","clk":"4230460698","pt":1631533263638,"mc":[{"id":"1.187557247","rc":[{"batb":[[0,1.69,112.32],[2,1.57,199.19]],"batl":[[0,1.82,133.86],[1,1.83,10.68],[2,1.84,180.42]],"ltp":1.69,"tv":38994.78,"id":10350473}]}]}
{"op":"mcm","clk":"4230460786","pt":1631533264731,"mc":[{"id":"1.187557247","rc":[{"trd":[[1.69,664.32]],"batb":[[0,1.69,72.32],[1,1.63,28],[2,1.62,5]],"batl":[[0,1.97,28.5],[1,1.98,28.75],[2,1.84,0]],"ltp":1.69,"tv":39074.78,"id":10350473},{"batl":[[0,2.6,4],[1,2.76,5.02],[2,3.45,53.16]],"ltp":2.46,"tv":17365.53,"id":9304761}],"tv":56440.32}]}
{"op":"mcm","clk":"4230460951","pt":1631533266755,"mc":[{"id":"1.187557247","rc":[{"trd":[[1.69,818.97]],"batb":[[0,1.68,4]],"batl":[[0,1.69,139.1],[1,1.97,28.5],[2,1.98,28.75]],"ltp":1.69,"tv":39229.43,"id":10350473},{"batl":[[0,2.46,3],[1,2.48,4],[2,2.6,4]],"ltp":2.46,"tv":17365.53,"id":9304761}],"tv":56594.97}]}
{"op":"mcm","clk":"4230460992","pt":1631533267258,"mc":[{"id":"1.187557247","rc":[{"trd":[[1.69,1091.54]],"batb":[[1,1.66,250.57],[2,1.65,129.21]],"batl":[[0,1.69,2.81],[1,1.72,178.08],[2,1.74,215.31]],"ltp":1.69,"tv":39502.0,"id":10350473},{"batl":[[1,2.6,4],[2,2.76,5.02]],"ltp":2.46,"tv":17365.53,"id":9304761}],"tv":56867.54}]}
{"op":"mcm","clk":"4230461114","pt":1631533268750,"mc":[{"id":"1.187557247","rc":[{"batl":[[0,1.72,178.08],[1,1.74,215.31],[2,1.83,130.93]],"ltp":1.69,"tv":39502.0,"id":10350473},{"batb":[[0,2.22,102],[1,2.2,307.34],[2,2.02,7.74]],"batl":[[1,2.6,24],[2,2.68,4.39]],"ltp":2.46,"tv":17365.53,"id":9304761}]}]}
{"op":"mcm","clk":"4230461142","pt":1631533269163,"mc":[{"id":"1.187557247","rc":[{"batb":[[1,1.67,5],[2,1.66,250.57]],"batl":[[2,1.97,28.5]],"ltp":1.69,"tv":39502.0,"id":10350473}]}]}
{"op":"mcm","clk":"4230461191","pt":1631533269843,"mc":[{"id":"1.187557247","rc":[{"batl":[[0,1.69,43.32],[1,1.72,178.08],[2,1.74,215.31]],"ltp":1.69,"tv":39502.0,"id":10350473}]}]}
{"op":"mcm","clk":"4230461449","pt":1631533272753,"mc":[{"id":"1.187557247","rc":[{"trd":[[1.69,1091.82]],"batl":[[0,1.72,178.08],[1,1.74,215.31],[2,1.97,28.5]],"ltp":1.69,"tv":39502.28,"id":10350473},{"trd":[[2.44,6.6]],"batb":[[0,2.2,307.34],[1,2.02,7.74],[2,1.98,12.59]],"batl":[[1,2.6,4]],"ltp":2.44,"tv":17365.72,"id":9304761}],"tv":56868.01}]}
{"op":"mcm","clk":"4230461516","pt":1631533273420,"mc":[{"id":"1.187557247","rc":[{"batb":[[2,1.63,28]],"batl":[[0,1.97,28.5],[1,1.98,28.75],[2,1.97,0]],"ltp":1.69,"tv":39502.28,"id":10350473},{"batl":[[2,2.76,5.02]],"ltp":2.44,"tv":17365.72,"id":9304761}]}]}
{"op":"mcm","clk":"4230461707","pt":1631533275598,"mc":[{"id":"1.187557247","rc":[{"batb":[[0,1.69,2.32],[1,1.68,4],[2,1.67,5]],"ltp":1.69,"tv":39502.28,"id":10350473}]}]}
{"op":"mcm","clk":"4230461813","pt":1631533276694,"mc":[{"id":"1.187557247","rc":[{"batl":[[0,1.82,140.74],[1,1.84,180.43],[2,1.97,28.5]],"ltp":1.69,"tv":39502.28,"id":10350473}]}]}
{"op":"mcm","clk":"4230461832","pt":1631533276903,"mc":[{"id":"1.187557247","rc":[{"batb":[[0,1.72,176.47],[1,1.69,2.32],[2,1.68,4]],"ltp":1.69,"tv":39502.28,"id":10350473}]}]}
{"op":"mcm","clk":"4230462162","pt":1631533280696,"mc":[{"id":"1.187557247","rc":[{"batb":[[0,1.7,4.18]],"ltp":1.69,"tv":39502.28,"id":10350473},{"batl":[[1,2.76,5.02],[2,3.45,53.16]],"ltp":2.44,"tv":17365.72,"id":9304761}]}]}
{"op":"mcm","clk":"4230462276","pt":1631533281895,"mc":[{"id":"1.187557247","rc":[{"trd":[[1.69,1096.47],[1.7,327.93]],"batb":[[0,1.68,4],[1,1.63,24],[2,1.57,186.76]],"batl":[[0,1.69,39.97]],"ltp":1.69,"tv":39515.3,"id":10350473}],"tv":56881.02}]}
{"op":"mcm","clk":"4230462434","pt":1631533283708,"mc":[{"id":"1.187557247","rc":[{"trd":[[1.69,1122.24]],"batb":[[0,1.63,24],[1,1.57,186.76],[2,1.56,153.42]],"batl":[[0,1.69,117.16]],"ltp":1.69,"tv":39541.07,"id":10350473},{"trd":[[2.44,10.6]],"batl":[[0,2.76,5.02],[1,3.45,53.16],[2,3.45,0]],"ltp":2.44,"tv":17369.72,"id":9304761}],"tv":56910.8}]}
{"op":"mcm","clk":"4230462501","pt":1631533284491,"mc":[{"id":"1.187557247","rc":[{"trd":[[1.6,233.7],[1.63,1050.67]],"batb":[[0,1.57,186.76],[1,1.56,153.42],[2,1.55,161.77]],"batl":[[0,1.61,139.5],[1,1.63,1173.32],[2,1.64,1138.8]],"ltp":1.6,"tv":39675.55,"id":10350473},{"batb":[[0,2.5,216.97],[1,2.38,8.46],[2,2.2,307.34]],"batl":[[1,2.84,370.38],[2,2.86,359.48]],"ltp":2.44,"tv":17369.72,"id":9304761}],"tv":57045.28}]}
{"op":"mcm","clk":"4230462620","pt":1631533285744,"mc":[{"id":"1.187557247","rc":[{"trd":[[1.61,166.5]],"batl":[[0,1.61,134.5]],"ltp":1.61,"tv":39685.55,"id":10350473},{"batb":[[0,2.62,56.15],[1,2.5,216.97],[2,2.46,66.61]],"batl":[[1,2.84,414.61]],"ltp":2.44,"tv":17369.72,"id":9304761}],"tv":57055.28}]}
{"op":"mcm","clk":"4230462699","pt":1631533286627,"mc":[{"id":"1.187557247","rc":[{"batl":[[1,1.63,1177.32],[2,1.64,1198.8]],"ltp":1.61,"tv":39685.55,"id":10350473},{"batb":[[1,2.6,3],[2,2.58,3]],"ltp":2.44,"tv":17369.72,"id":9304761}]}]}
{"op":"mcm","clk":"4230462782","pt":1631533287614,"mc":[{"id":"1.187557247","rc":[{"trd":[[1.57,10]],"batb":[[0,1.57,181.76],[1,1.56,170.6]],"batl":[[0,1.61,260.2],[1,1.62,135.8],[2,1.63,1177.32]],"ltp":1.57,"tv":39695.55,"id":10350473},{"trd":[[2.76,8]],"batb":[[0,2.74,3],[1,2.68,3],[2,2.66,3]],"batl":[[0,2.76,1.02]],"ltp":2.76,"tv":17377.72,"id":9304761}],"tv":57073.28}]}
{"op":"mcm","clk":"4230462869","pt":1631533288603,"mc":[{"id":"1.187557247","rc":[{"trd":[[1.58,5.2]],"batb":[[0,1.58,63.19],[1,1.57,181.76],[2,1.56,170.6]],"batl":[[0,1.59,154.41],[1,1.6,58.06],[2,1.61,329.83]],"ltp":1.58,"tv":39700.76,"id":10350473},{"trd":[[2.74,3]],"batb":[[0,2.68,3],[1,2.66,3],[2,2.62,56.15]],"ltp":2.74,"tv":17380.72,"id":9304761}],"tv":57081.48}]}
{"op":"mcm","clk":"4230462949","pt":1631533289637,"mc":[{"id":"1.187557247","rc":[{"batb":[[1,1.57,240.71]],"ltp":1.58,"tv":39700.76,"id":10350473}]}]}
{"op":"mcm","clk":"4230463119","pt":1631533291724,"mc":[{"id":"1.187557247","rc":[{"trd":[[1.58,131.58]],"batb":[[0,1.57,240.71],[1,1.56,170.6],[2,1.55,161.77]],"batl":[[0,1.58,6],[1,1.59,154.41],[2,1.6,58.06]],"ltp":1.58,"tv":39827.13,"id":10350473},{"batb":[[0,2.72,3],[1,2.68,3],[2,2.66,3]],"ltp":2.74,"tv":17380.72,"id":9304761}],"tv":57207.86}]}
{"op":"mcm","clk":"4230463197","pt":1631533292717,"mc":[{"id":"1.187557247","rc":[{"batl":[[0,1.58,209.16]],"ltp":1.58,"tv":39827.13,"id":10350473},{"batb":[[1,2.7,101.19],[2,2.68,1110.33]],"ltp":2.74,"tv":17380.72,"id":9304761}]}]}
{"op":"mcm","clk":"4230463262","pt":1631533293648,"mc":[{"id":"1.187557247","rc":[{"trd":[[1.58,259.74]],"batb":[[0,1.57,181.76]],"batl":[[0,1.58,85.01]],"ltp":1.58,"tv":39955.29,"id":10350473},{"batb":[[1,2.68,1110.33],[2,2.66,3]],"ltp":2.74,"tv":17380.72,"id":9304761}],"tv":57336.02}]}
{"op":"mcm","clk":"4230463435","pt":1631533295735,"mc":[{"id":"1.187557247","rc":[{"batl":[[0,1.58,9.34]],"ltp":1.58,"tv":39955.29,"id":10350473}]}]}
{"op":"mcm","clk":"4230463508","pt":1631533296614,"mc":[{"id":"1.187557247","rc":[{"batb":[[0,1.57,316.76]],"batl":[[0,1.59,154.41],[1,1.6,58.06],[2,1.61,260.2]],"ltp":1.58,"tv":39955.29,"id":10350473},{"trd":[[2.72,116.32]],"batb":[[0,2.68,1107.33],[1,2.62,56.15],[2,2.6,37.5]],"ltp":2.72,"tv":17497.04,"id":9304761}],"tv":57452.34}]}
{"op":"mcm","clk":"4230463629","pt":1631533298447,"mc":[{"id":"1.187557247","rc":[{"trd":[[2.68,5.11]],"batb":[[0,2.68,1104.77]],"ltp":2.68,"tv":17502.15,"id":9304761}],"tv":57457.45}]}
{"op":"mcm","clk":"4230463712","pt":1631533299542,"mc":[{"id":"1.187557247","rc":[{"batb":[[0,2.7,46.03]],"ltp":2.68,"tv":17502.15,"id":9304761}]}]}
{"op":"mcm","clk":"4230463778","pt":1631533300530,"mc":[{"id":"1.187557247","rc":[{"trd":[[1.57,643.46]],"batb":[[0,1.56,170.63],[1,1.55,161.77],[2,1.54,81.64]],"ltp":1.57,"tv":40588.75,"id":10350473},{"batb":[[0,2.62,56.15],[1,2.6,37.5],[2,2.46,66.61]],"ltp":2.68,"tv":17502.15,"id":9304761}],"tv":58090.9}]}
{"op":"mcm","clk":"4230463864","pt":1631533301726,"mc":[{"id":"1.187557247","rc":[{"trd":[[1.59,48.7]],"batb":[[0,1.54,81.67],[1,1.53,10.49],[2,1.52,163.34]],"batl":[[0,1.59,142.41],[2,1.63,60]],"ltp":1.59,"tv":40612.75,"id":10350473},{"batl":[[0,2.84,44.23],[1,3.45,53.16],[2,2.86,0]],"ltp":2.68,"tv":17502.15,"id":9304761}],"tv":58114.9}]}
{"op":"mcm","clk":"4230463929","pt":1631533302476,"mc":[{"id":"1.187557247","rc":[{"trd":[[1.63,1086.67]],"batb":[[0,1.54,81.64]],"batl":[[0,1.63,42],[1,1.67,13.42],[2,1.79,47.5]],"ltp":1.63,"tv":40648.75,"id":10350473},{"batb":[[0,2.6,37.5],[1,2.46,66.61],[2,2.26,7.48]],"ltp":2.68,"tv":17502.15,"id":9304761}],"tv":58150.9}]}
{"op":"mcm","clk":"4230464033","pt":1631533303733,"mc":[{"id":"1.187557247","rc":[{"batb":[[0,1.53,10.49],[1,1.52,163.34],[2,1.48,7]],"batl":[[0,1.67,13.42],[1,1.79,47.5],[2,1.79,0]],"ltp":1.63,"tv":40648.75,"id":10350473},{"batb":[[0,2.46,66.61],[1,2.26,7.48],[2,1.4,148.56]],"batl":[[0,2.68,2.56]],"ltp":2.68,"tv":17502.15,"id":9304761}]}]}
{"op":"mcm","clk":"4230464168","pt":1631533305653,"mc":[{"id":"1.187557247","rc":[{"batb":[[0,1.54,6],[1,1.53,16.49],[2,1.51,419.41]],"batl":[[0,1.67,205.56],[1,1.69,236.9],[2,1.72,65.16]],"ltp":1.63,"tv":40648.75,"id":10350473},{"batb":[[0,2.5,64.69],[1,2.38,5.96],[2,2.26,7.48]],"batl":[[1,2.84,3],[2,3.45,53.16]],"ltp":2.68,"tv":17502.15,"id":9304761}]}]}
{"op":"mcm","clk":"4230464256","pt":1631533306647,"mc":[{"id":"1.187557247","rc":[{"batb":[[2,1.52,5]],"ltp":1.63,"tv":40648.75,"id":10350473},{"batl":[[2,2.9,3]],"ltp":2.68,"tv":17502.15,"id":9304761}]}]}
{"op":"mcm","clk":"4230464410","pt":1631533308426,"mc":[{"id":"1.187557247","rc":[{"batl":[[0,1.79,47.5],[1,1.69,0],[2,1.72,0]],"ltp":1.63,"tv":40648.75,"id":10350473},{"batb":[[1,2.26,7.48],[2,1.4,148.56]],"ltp":2.68,"tv":17502.15,"id":9304761}]}]}
{"op":"mcm","clk":"4230464525","pt":1631533309833,"mc":[{"id":"1.187557247","rc":[{"batl":[[0,2.68,4.88]],"ltp":2.68,"tv":17502.15,"id":9304761}]}]}
{"op":"mcm","clk":"4230464674","pt":1631533311662,"mc":[{"id":"1.187557247","rc":[{"trd":[[1.59,81.48]],"batb":[[0,1.57,192.22],[1,1.56,158.04],[2,1.54,6]],"batl":[[0,1.62,230.45],[1,1.63,133.11],[2,1.72,71.16]],"ltp":1.59,"tv":40681.53,"id":10350473},{"trd":[[2.68,9.99]],"batb":[[1,2.38,6.17],[2,2.26,7.48]],"batl":[[0,2.84,3],[1,2.9,3],[2,3.45,53.16]],"ltp":2.68,"tv":17507.03,"id":9304761}],"tv":58188.57}]}
{"op":"mcm","clk":"4230464930","pt":1631533314735,"mc":[{"id":"1.187557247","rc":[{"batb":[[0,1.54,6],[1,1.53,16.49],[2,1.52,5]],"batl":[[0,1.79,47.5],[1,1.86,9.59],[2,1.72,0]],"ltp":1.59,"tv":40681.53,"id":10350473},{"batb":[[1,2.26,7.48],[2,1.4,148.56]],"ltp":2.68,"tv":17507.03,"id":9304761}]}]}
{"op":"mcm","clk":"4230464980","pt":1631533315357,"mc":[{"id":"1.187557247","rc":[{"batl":[[0,1.61,232.15],[1,1.79,47.5],[2,1.86,9.59]],"ltp":1.59,"tv":40681.53,"id":10350473}]}]}
{"op":"mcm","clk":"4230465204","pt":1631533317754,"mc":[{"id":"1.187557247","rc":[{"batb":[[1,1.53,10.49]],"batl":[[1,1.67,192.14],[2,1.69,236.9]],"ltp":1.59,"tv":40681.53,"id":10350473},{"batb":[[1,2.38,5.46],[2,2.26,7.48]],"ltp":2.68,"tv":17507.03,"id":9304761}]}]}
{"op":"mcm","clk":"4230465318","pt":1631533319151,"mc":[{"id":"1.187557247","rc":[{"trd":[[1.61,172.94]],"batb":[[2,1.51,419.41]],"batl":[[0,1.61,225.71]],"ltp":1.61,"tv":40687.97,"id":10350473},{"trd":[[2.62,3.96]],"batl":[[1,3.45,53.16],[2,3.45,0]],"ltp":2.62,"tv":17510.99,"id":9304761}],"tv":58198.97}]}
{"op":"mcm","clk":"4230465459","pt":1631533320560,"mc":[{"id":"1.187557247","rc":[{"batb":[[1,1.53,16.49]],"ltp":1.61,"tv":40687.97,"id":10350473}]}]}
{"op":"mcm","clk":"4230465742","pt":1631533323446,"mc":[{"id":"1.187557247","rc":[{"batb":[[2,1.51,167.28]],"ltp":1.61,"tv":40687.97,"id":10350473}]}]}
{"op":"mcm","clk":"4230465785","pt":1631533323964,"mc":[{"id":"1.187557247","rc":[{"batl":[[0,1.67,192.14],[1,1.69,236.9],[2,1.72,71.66]],"ltp":1.61,"tv":40687.97,"id":10350473}]}]}
{"op":"mcm","clk":"4230465983","pt":1631533326465,"mc":[{"id":"1.187557247","rc":[{"batb":[[0,1.62,164.87],[1,1.61,140.59],[2,1.53,16.49]],"ltp":1.61,"tv":40687.97,"id":10350473},{"batb":[[1,2.44,783.82],[2,2.42,418.42]],"batl":[[0,2.66,718.98],[1,2.68,697.84],[2,2.7,697.84]],"ltp":2.62,"tv":17510.99,"id":9304761}]}]}
{"op":"mcm","clk":"4230466088","pt":1631533327765,"mc":[{"id":"1.187557247","rc":[{"trd":[[1.62,32.96]],"batb":[[0,1.62,280.99],[2,1.6,77.45]],"batl":[[0,1.66,35.05],[1,1.67,192.14],[2,1.69,236.9]],"ltp":1.62,"tv":40713.13,"id":10350473},{"batb":[[0,2.52,21.78],[1,2.5,64.69],[2,2.44,783.82]],"batl":[[0,2.66,765.54]],"ltp":2.62,"tv":17510.99,"id":9304761}],"tv":58224.13}]}
{"op":"mcm","clk":"4230466322","pt":1631533330687,"mc":[{"id":"1.187557247","rc":[{"batb":[[0,1.64,64.25],[1,1.62,280.99],[2,1.61,140.59]],"batl":[[0,1.65,275.92],[1,1.66,35.05],[2,1.67,192.14]],"ltp":1.62,"tv":40713.13,"id":10350473}]}]}
{"op":"mcm","clk":"4230466407","pt":1631533331578,"mc":[{"id":"1.187557247","rc":[{"batb":[[1,1.63,65.41],[2,1.62,280.99]],"batl":[[1,1.66,111.18]],"ltp":1.62,"tv":40713.13,"id":10350473},{"batb":[[1,2.5,1512.73]],"batl":[[0,2.66,718.98]],"ltp":2.62,"tv":17510.99,"id":9304761}]}]}
{"op":"mcm","clk":"4230466587","pt":1631533333764,"mc":[{"id":"1.187557247","rc":[{"batb":[[0,1.64,260.25]],"ltp":1.62,"tv":40713.13,"id":10350473}]}]}
{"op":"mcm","clk":"4230466679","pt":1631533334697,"mc":[{"id":"1.187557247","rc":[{"batb":[[2,1.62,357.19]],"ltp":1.62,"tv":40713.13,"id":10350473},{"batl":[[0,2.62,47.14],[1,2.66,718.98],[2,2.68,697.84]],"ltp":2.62,"tv":17510.99,"id":9304761}]}]}
{"op":"mcm","clk":"4230466857","pt":1631533336893,"mc":[{"id":"1.187557247","rc":[{"trd":[[1.64,795.44]],"batb":[[0,1.64,258.84]],"ltp":1.64,"tv":40715.95,"id":10350473}],"tv":58226.94}]}
{"op":"mcm","clk":"4230467006","pt":1631533338669,"mc":[{"id":"1.187557247","rc":[{"trd":[[1.64,1315.8]],"batb":[[0,1.62,76.2],[1,1.56,10.29],[2,1.54,154.31]],"batl":[[1,1.66,76.13],[2,1.68,10.47]],"ltp":1.64,"tv":41236.31,"id":10350473},{"batb":[[0,2.5,1448.04],[1,2.4,42.85],[2,2.28,5.91]],"batl":[[1,3.45,53.16],[2,2.68,0]],"ltp":2.62,"tv":17510.99,"id":9304761}],"tv":58747.3}]}
{"op":"mcm","clk":"4230467078","pt":1631533339498,"mc":[{"id":"1.187557247","rc":[{"batb":[[0,1.65,211.76]],"batl":[[0,1.68,10.47],[1,1.78,63.75],[2,1.79,47.5]],"ltp":1.64,"tv":41236.31,"id":10350473},{"batb":[[0,2.28,5.91],[1,2.26,91.58],[2,1.4,148.56]],"batl":[[0,3.45,53.16],[1,3.45,0]],"ltp":2.62,"tv":17510.99,"id":9304761}]}]}
{"op":"mcm","clk":"4230467125","pt":1631533339965,"mc":[{"id":"1.187557247","rc":[{"trd":[[1.65,714.34]],"batb":[[0,1.65,207.76]],"ltp":1.65,"tv":41244.31,"id":10350473}],"tv":58755.3}]}
{"op":"mcm","clk":"4230467256","pt":1631533341687,"mc":[{"id":"1.187557247","rc":[{"batl":[[2,1.79,233.63]],"ltp":1.65,"tv":41244.31,"id":10350473}]}]}
{"op":"mcm","clk":"4230467330","pt":1631533342470,"mc":[{"id":"1.187557247","rc":[{"batb":[[2,2.16,6.78]],"ltp":2.62,"tv":17510.99,"id":9304761}]}]}
{"op":"mcm","clk":"4230467388","pt":1631533343093,"mc":[{"id":"1.187557247","rc":[{"trd":[[1.65,1129.87]],"batb":[[0,1.56,10.29],[1,1.54,154.31],[2,1.53,307.1]],"batl":[[0,1.65,181.57],[1,1.68,10.47],[2,1.78,63.75]],"ltp":1.65,"tv":41659.83,"id":10350473}],"tv":59170.83}]}
{"op":"mcm","clk":"4230467581","pt":1631533345388,"mc":[{"id":"1.187557247","rc":[{"batl":[[0,1.65,92.96]],"ltp":1.65,"tv":41659.83,"id":10350473}]}]}
{"op":"mcm","clk":"4230467748","pt":1631533347567,"mc":[{"id":"1.187557247","rc":[{"batl":[[0,1.68,10.47],[1,1.78,63.75],[2,1.79,47.5]],"ltp":1.65,"tv":41659.83,"id":10350473}]}]}
{"op":"mcm","clk":"4230467785","pt":1631533348191,"mc":[{"id":"1.187557247","rc":[{"batb":[[0,1.54,154.31],[1,1.53,307.1],[2,1.52,177.6]],"ltp":1.65,"tv":41659.83,"id":10350473}]}]}
{"op":"mcm","clk":"4230467982","pt":1631533350694,"mc":[{"id":"1.187557247","rc":[{"trd":[[1.54,388.52]],"batb":[[0,1.54,141.32],[1,1.53,301.1]],"batl":[[0,1.58,189.32],[1,1.59,145.58],[2,1.65,81.1]],"ltp":1.54,"tv":41685.81,"id":10350473},{"batb":[[0,2.7,708.32],[1,2.68,687.5],[2,2.66,687.5]],"batl":[[0,2.8,3],[1,2.98,641.78],[2,3,342.6]],"ltp":2.62,"tv":17510.99,"id":9304761}],"tv":59196.81}]}
{"op":"mcm","clk":"4230468068","pt":1631533351696,"mc":[{"id":"1.187557247","rc":[{"batb":[[2,1.52,260.8]],"batl":[[2,1.62,60]],"ltp":1.54,"tv":41685.81,"id":10350473},{"batb":[[0,2.7,760.54]],"batl":[[0,2.98,641.78],[1,3,342.6],[2,3.05,342.6]],"ltp":2.62,"tv":17510.99,"id":9304761}]}]}
{"op":"mcm","clk":"4230468240","pt":1631533353526,"mc":[{"id":"1.187557247","rc":[{"batl":[[2,1.65,81.1]],"ltp":1.54,"tv":41685.81,"id":10350473}]}]}
{"op":"mcm","clk":"4230468363","pt":1631533354679,"mc":[{"id":"1.187557247","rc":[{"batb":[[0,1.55,64.08],[1,1.54,141.32],[2,1.53,301.1]],"batl":[[0,1.56,360.79],[1,1.57,66.35],[2,1.58,189.32]],"ltp":1.54,"tv":41685.81,"id":10350473}]}]}
{"op":"mcm","clk":"4230468452","pt":1631533355516,"mc":[{"id":"1.187557247","rc":[{"trd":[[1.56,174.96]],"batb":[[1,1.54,209.1]],"batl":[[0,1.56,197.27],[1,1.57,118.7],[2,1.58,248.23]],"ltp":1.56,"tv":41849.33,"id":10350473},{"trd":[[2.78,91.76]],"batb":[[0,2.74,1107.33],[1,2.7,760.54],[2,2.68,687.5]],"batl":[[0,2.96,42.85],[1,2.98,641.78],[2,3,342.6]],"ltp":2.78,"tv":17602.75,"id":9304761}],"tv":59452.08}]}
{"op":"mcm","clk":"4230468549","pt":1631533356725,"mc":[{"id":"1.187557247","rc":[{"batl":[[1,1.57,158.7]],"ltp":1.56,"tv":41849.33,"id":10350473}]}]}
{"op":"mcm","clk":"4230468638","pt":1631533357706,"mc":[{"id":"1.187557247","rc":[{"batb":[[1,1.54,324.1]],"batl":[[1,1.57,118.7]],"ltp":1.56,"tv":41849.33,"id":10350473}]}]}
{"op":"mcm","clk":"4230468728","pt":1631533358700,"mc":[{"id":"1.187557247","rc":[{"trd":[[1.55,444.19],[1.56,226.32]],"batb":[[0,1.54,324.28],[1,1.53,301.1],[2,1.52,260.8]],"batl":[[0,1.56,145.92]],"ltp":1.56,"tv":42028.48,"id":10350473},{"trd":[[2.78,120.57]],"batb":[[0,2.74,1136.88]],"batl":[[0,2.94,71.69],[1,2.96,42.85],[2,2.98,641.78]],"ltp":2.78,"tv":17631.57,"id":9304761}],"tv":59660.06}]}
{"op":"mcm","clk":"4230468749","pt":1631533358910,"mc":[{"id":"1.187557247","rc":[{"batl":[[0,2.94,17.89]],"ltp":2.78,"tv":17631.57,"id":9304761}]}]}
{"op":"mcm","clk":"4230468888","pt":1631533360540,"mc":[{"id":"1.187557247","rc":[{"trd":[[1.55,444.55],[1.56,240.57]],"batb":[[0,1.54,324.1]],"batl":[[0,1.55,39.82],[1,1.56,131.67],[2,1.57,118.7]],"ltp":1.55,"tv":42043.09,"id":10350473},{"trd":[[2.78,128.57]],"batl":[[1,2.98,641.78],[2,3,342.6]],"ltp":2.78,"tv":17639.56,"id":9304761}],"tv":59682.66}]}
{"op":"mcm","clk":"4230468987","pt":1631533361594,"mc":[{"id":"1.187557247","rc":[{"batl":[[0,2.98,641.78],[1,3,342.6],[2,3.05,342.6]],"ltp":2.78,"tv":17639.56,"id":9304761}]}]}
{"op":"mcm","clk":"4230469063","pt":1631533362594,"mc":[{"id":"1.187557247","rc":[{"trd":[[1.55,524.19]],"batb":[[0,1.55,31.63],[1,1.54,256.32],[2,1.53,301.1]],"batl":[[0,1.56,193.48],[1,1.57,52.35],[2,1.58,189.32]],"ltp":1.55,"tv":42122.74,"id":10350473}],"tv":59762.3}]}
{"op":"mcm","clk":"4230469160","pt":1631533363696,"mc":[{"id":"1.187557247","rc":[{"batl":[[0,2.92,43.3],[1,2.98,641.78],[2,3,342.6]],"ltp":2.78,"tv":17639.56,"id":9304761}]}]}
{"op":"mcm","clk":"4230469218","pt":1631533364530,"mc":[{"id":"1.187557247","rc":[{"trd":[[1.56,250.57]],"batl":[[0,1.56,188.48]],"ltp":1.56,"tv":42132.74,"id":10350473},{"batl":[[1,2.96,21.27],[2,2.98,641.78]],"ltp":2.78,"tv":17639.56,"id":9304761}],"tv":59772.3}]}
{"op":"mcm","clk":"4230469311","pt":1631533365625,"mc":[{"id":"1.187557247","rc":[{"trd":[[1.55,562.25]],"batb":[[0,1.55,12.6],[1,1.54,141.32]],"ltp":1.55,"tv":42170.79,"id":10350473}],"tv":59810.36}]}
{"op":"mcm","clk":"4230469375","pt":1631533366413,"mc":[{"id":"1.187557247","rc":[{"batb":[[0,1.52,85.52],[1,1.46,12.63],[2,1.45,719.75]],"batl":[[0,1.6,60],[1,1.64,11.32],[2,1.7,72.25]],"ltp":1.55,"tv":42170.79,"id":10350473},{"batb":[[0,2.74,1107.33],[1,2.66,36.14],[2,2.42,76.32]],"batl":[[1,3.45,53.16],[2,3.65,173.19]],"ltp":2.78,"tv":17639.56,"id":9304761}]}]}
{"op":"mcm","clk":"4230469459","pt":1631533367512,"mc":[{"id":"1.187557247","rc":[{"batb":[[0,1.52,2.32]],"batl":[[0,1.64,11.32],[1,1.77,62.5],[2,1.78,63.75]],"ltp":1.55,"tv":42170.79,"id":10350473},{"batb":[[0,2.42,70.88],[1,2.28,5.91],[2,2.26,7.48]],"batl":[[0,3.45,53.16],[1,3.65,173.19],[2,3.65,0]],"ltp":2.78,"tv":17639.56,"id":9304761}]}]}
{"op":"mcm","clk":"4230469580","pt":1631533369026,"mc":[{"id":"1.187557247","rc":[{"batl":[[1,1.7,190.14],[2,1.72,223.5]],"ltp":1.55,"tv":42170.79,"id":10350473}]}]}
{"op":"mcm","clk":"4230469725","pt":1631533370708,"mc":[{"id":"1.187557247","rc":[{"batl":[[1,1.7,256.99]],"ltp":1.55,"tv":42170.79,"id":10350473},{"batb":[[0,2.44,69.12],[1,2.42,5.63],[2,2.28,5.91]],"batl":[[0,3.2,2],[1,3.45,53.16],[2,3.65,173.19]],"ltp":2.78,"tv":17639.56,"id":9304761}]}]}
{"op":"mcm","clk":"4230469989","pt":1631533373731,"mc":[{"id":"1.187557247","rc":[{"batb":[[1,1.45,719.75],[2,1.44,1253.35]],"batl":[[1,1.7,66.85],[2,1.72,0]],"ltp":1.55,"tv":42170.79,"id":10350473}]}]}
{"op":"mcm","clk":"4230470017","pt":1631533374045,"mc":[{"id":"1.187557247","rc":[{"batl":[[1,1.7,0]],"ltp":1.55,"tv":42170.79,"id":10350473},{"batb":[[1,2.28,5.91],[2,1.97,399.51]],"ltp":2.78,"tv":17639.56,"id":9304761}]}]}
{"op":"mcm","clk":"4230470090","pt":1631533374830,"mc":[{"id":"1.187557247","rc":[{"batb":[[2,1.4,148.56]],"batl":[[2,3.65,0]],"ltp":2.78,"tv":17639.56,"id":9304761}]}]}
{"op":"mcm","clk":"4230470257","pt":1631533376754,"mc":[{"id":"1.187557247","rc":[{"trd":[[1.45,291.67],[1.52,15.84]],"batb":[[0,1.45,705.96],[1,1.44,1253.35],[2,1.43,223.95]],"batl":[[0,1.48,285.68],[1,1.49,283.45],[2,1.52,2.26]],"ltp":1.45,"tv":42203.02,"id":10350473},{"batb":[[0,3.05,627.06],[1,3,624.58],[2,2.98,608.6]],"batl":[[0,3.4,309.37],[1,3.45,599.12],[2,3.5,545.96]],"ltp":2.78,"tv":17639.56,"id":9304761}],"tv":59842.59}]}
{"op":"mcm","clk":"4230470343","pt":1631533377744,"mc":[{"id":"1.187557247","rc":[{"batl":[[2,1.52,0]],"ltp":1.45,"tv":42203.02,"id":10350473},{"batb":[[0,3.05,721.12]],"ltp":2.78,"tv":17639.56,"id":9304761}]}]}
{"op":"mcm","clk":"4230470408","pt":1631533378628,"mc":[{"id":"1.187557247","rc":[{"batb":[[2,1.43,315.44]],"batl":[[0,1.47,144.64],[1,1.48,285.68],[2,1.49,283.45]],"ltp":1.45,"tv":42203.02,"id":10350473},{"batl":[[0,3.3,39.56],[1,3.4,309.37],[2,3.45,599.12]],"ltp":2.78,"tv":17639.56,"id":9304761}]}]}
{"op":"mcm","clk":"4230470494","pt":1631533379726,"mc":[{"id":"1.187557247","rc":[{"batl":[[0,1.48,285.68],[1,1.49,283.45],[2,1.49,0]],"ltp":1.45,"tv":42203.02,"id":10350473},{"batl":[[1,3.4,328.41]],"ltp":2.78,"tv":17639.56,"id":9304761}]}]}
{"op":"mcm","clk":"4230470575","pt":1631533380629,"mc":[{"id":"1.187557247","rc":[{"batb":[[0,1.46,73.46],[1,1.45,705.96],[2,1.44,1253.35]],"batl":[[0,1.47,2883.26],[1,1.48,285.68],[2,1.49,283.45]],"ltp":1.45,"tv":42203.02,"id":10350473}]}]}
{"op":"mcm","clk":"4230470677","pt":1631533381719,"mc":[{"id":"1.187557247","rc":[{"batb":[[1,1.45,766.28]],"batl":[[0,1.47,2939.86],[1,1.48,358.97]],"ltp":1.45,"tv":42203.02,"id":10350473},{"batb":[[0,3.1,86.3],[1,3.05,721.12],[2,3,624.58]],"batl":[[0,3.4,328.41],[1,3.45,599.12],[2,3.5,545.96]],"ltp":2.78,"tv":17639.56,"id":9304761}]}]}
{"op":"mcm","clk":"4230470766","pt":1631533382762,"mc":[{"id":"1.187557247","rc":[{"batb":[[0,1.46,103.46]],"ltp":1.45,"tv":42203.02,"id":10350473},{"batb":[[0,3.1,23.75]],"ltp":2.78,"tv":17639.56,"id":9304761}]}]}
{"op":"mcm","clk":"4230470900","pt":1631533384321,"mc":[{"id":"1.187557247","rc":[{"trd":[[1.46,2627.78]],"batb":[[0,1.46,246.2]],"ltp":1.46,"tv":42349.52,"id":10350473},{"batl":[[0,3.4,367.13]],"ltp":2.78,"tv":17639.56,"id":9304761}],"tv":59989.09}]}
{"op":"mcm","clk":"4230470971","pt":1631533385147,"mc":[{"id":"1.187557247","rc":[{"batb":[[2,3,654.58]],"ltp":2.78,"tv":17639.56,"id":9304761}]}]}
{"op":"mcm","clk":"4230471164","pt":1631533387544,"mc":[{"id":"1.187557247","rc":[{"batb":[[0,1.46,216.2]],"batl":[[1,1.48,285.68]],"ltp":1.46,"tv":42349.52,"id":10350473},{"batb":[[0,3.1,480.11]],"ltp":2.78,"tv":17639.56,"id":9304761}]}]}
{"op":"mcm","clk":"4230471257","pt":1631533388741,"mc":[{"id":"1.187557247","rc":[{"batb":[[0,1.46,280.79],[1,1.45,705.96]],"batl":[[1,1.48,283.86]],"ltp":1.46,"tv":42349.52,"id":10350473}]}]}
{"op":"mcm","clk":"4230471329","pt":1631533389725,"mc":[{"id":"1.187557247","rc":[{"trd":[[1.47,1716.55]],"batl":[[0,1.47,384.5]],"ltp":1.47,"tv":42359.27,"id":10350473}],"tv":59998.83}]}
{"op":"mcm","clk":"4230471383","pt":1631533390454,"mc":[{"id":"1.187557247","rc":[{"batl":[[0,1.47,56.6]],"ltp":1.47,"tv":42359.27,"id":10350473},{"batb":[[0,3.1,23.75]],"ltp":2.78,"tv":17639.56,"id":9304761}]}]}
{"op":"mcm","clk":"4230471451","pt":1631533391240,"mc":[{"id":"1.187557247","rc":[{"trd":[[1.47,1796.55]],"batl":[[0,1.47,16.6]],"ltp":1.47,"tv":42439.27,"id":10350473},{"batl":[[0,3.4,348.09]],"ltp":2.78,"tv":17639.56,"id":9304761}],"tv":60078.83}]}
{"op":"mcm","clk":"4230471530","pt":1631533392131,"mc":[{"id":"1.187557247","rc":[{"trd":[[3.1,0.18]],"batb":[[0,3.1,23.66]],"ltp":3.1,"tv":17639.74,"id":9304761}],"tv":60079.02}]}
{"op":"mcm","clk":"4230471696","pt":1631533393747,"mc":[{"id":"1.187557247","rc":[{"trd":[[1.47,1829.75]],"batb":[[0,1.47,3512.81],[1,1.46,280.79],[2,1.45,705.96]],"batl":[[0,1.48,283.86],[1,1.49,283.45],[2,1.5,60]],"ltp":1.47,"tv":42472.47,"id":10350473}],"tv":60112.22}]}
{"op":"mcm","clk":"4230471785","pt":1631533394739,"mc":[{"id":"1.187557247","rc":[{"batb":[[1,1.46,216.2]],"batl":[[0,1.5,60],[1,1.54,12.47],[2,1.55,4]],"ltp":1.47,"tv":42472.47,"id":10350473},{"batb":[[0,3,30],[1,2.74,5.29],[2,2.72,51.38]],"batl":[[0,3.4,38.72],[1,3.45,53.16],[2,4.2,150.47]],"ltp":3.1,"tv":17639.74,"id":9304761}]}]}
{"op":"mcm","clk":"4230471859","pt":1631533395518,"mc":[{"id":"1.187557247","rc":[{"batb":[[0,1.47,3517.68],[1,1.45,705.96],[2,1.44,851.79]],"batl":[[0,1.54,12.47],[1,1.55,4],[2,1.57,73.5]],"ltp":1.47,"tv":42472.47,"id":10350473},{"batb":[[0,2.74,5.29],[1,2.72,51.38],[2,2.6,5.24]],"batl":[[0,3.45,53.16],[1,4.2,150.47],[2,4.2,0]],"ltp":3.1,"tv":17639.74,"id":9304761}]}]}
{"op":"mcm","clk":"4230471940","pt":1631533396159,"mc":[{"id":"1.187557247","rc":[{"trd":[[1.47,1835.22]],"batb":[[0,1.47,3514.95]],"batl":[[2,1.62,74.25]],"ltp":1.47,"tv":42477.93,"id":10350473},{"batb":[[0,2.72,51.38],[1,2.6,5.24],[2,2.12,393.24]],"ltp":3.1,"tv":17639.74,"id":9304761}],"tv":60117.68}]}
{"op":"mcm","clk":"4230472099","pt":1631533397667,"mc":[{"id":"1.187557247","rc":[{"batb":[[0,1.47,4.87]],"ltp":1.47,"tv":42477.93,"id":10350473}]}]}
{"op":"mcm","clk":"4230472301","pt":1631533399752,"mc":[{"id":"1.187557247","rc":[{"trd":[[1.47,1844.96]],"batb":[[0,1.45,705.96],[1,1.44,870.46],[2,1.42,851.79]],"batl":[[0,1.48,20.99],[1,1.5,452.06],[2,1.54,12.47]],"ltp":1.47,"tv":42487.68,"id":10350473},{"batl":[[0,3.25,18.54],[1,3.45,53.16],[2,4.2,150.47]],"ltp":3.1,"tv":17639.74,"id":9304761}],"tv":60127.43}]}
{"op":"mcm","clk":"4230472388","pt":1631533400685,"mc":[{"id":"1.187557247","rc":[{"trd":[[1.45,1247.14],[1.46,2627.98]],"batb":[[0,1.45,228.23],[1,1.44,851.79],[2,1.42,1111.89]],"batl":[[0,1.46,268.27],[1,1.47,195.26]],"ltp":1.46,"tv":43443.35,"id":10350473},{"trd":[[3.15,0.09]],"batl":[[0,3.45,53.16],[1,4.2,150.47],[2,4.2,0]],"ltp":3.15,"tv":17639.84,"id":9304761}],"tv":61083.19}]}
{"op":"mcm","clk":"4230472482","pt":1631533401581,"mc":[{"id":"1.187557247","rc":[{"trd":[[1.45,1703.59]],"batb":[[0,1.44,851.79],[1,1.43,13.36]],"batl":[[0,1.45,115.74],[1,1.46,268.27],[2,1.47,398.2]],"ltp":1.45,"tv":43899.8,"id":10350473},{"batb":[[0,2.86,85.5],[1,2.72,51.38],[2,2.6,5.24]],"batl":[[0,3.45,68.06]],"ltp":3.15,"tv":17639.84,"id":9304761}],"tv":61539.65}]}
{"op":"mcm","clk":"4230472609","pt":1631533402685,"mc":[{"id":"1.187557247","rc":[{"trd":[[1.45,1787.47]],"batl":[[0,1.45,352.69]],"ltp":1.45,"tv":43983.69,"id":10350473},{"batb":[[1,2.74,5.02],[2,2.72,51.38]],"ltp":3.15,"tv":17639.84,"id":9304761}],"tv":61623.53}]}
{"op":"mcm","clk":"4230472680","pt":1631533403361,"mc":[{"id":"1.187557247","rc":[{"batl":[[0,1.45,445.66]],"ltp":1.45,"tv":43983.69,"id":10350473},{"batb":[[0,2.74,5.02],[1,2.72,51.38],[2,2.6,5.24]],"ltp":3.15,"tv":17639.84,"id":9304761}]}]}
{"op":"mcm","clk":"4230472815","pt":1631533404665,"mc":[{"id":"1.187557247","rc":[{"trd":[[1.45,1791.47]],"batl":[[0,1.45,369.86],[1,1.46,330.62],[2,1.47,195.26]],"ltp":1.45,"tv":43987.69,"id":10350473}],"tv":61627.53}]}
{"op":"mcm","clk":"4230472870","pt":1631533405180,"mc":[{"id":"1.187557247","rc":[{"batb":[[0,1.44,1045.79]],"batl":[[0,1.45,92.96]],"ltp":1.45,"tv":43987.69,"id":10350473}]}]}
{"op":"mcm","clk":"4230473032","pt":1631533406671,"mc":[{"id":"1.187557247","rc":[{"batb":[[2,1.42,851.79]],"batl":[[0,1.54,12.47],[1,1.62,74.25],[2,1.47,0]],"ltp":1.45,"tv":43987.69,"id":10350473},{"batb":[[0,2.72,51.38],[1,2.6,5.24],[2,2.12,393.24]],"batl":[[0,3.45,53.16]],"ltp":3.15,"tv":17639.84,"id":9304761}]}]}
{"op":"mcm","clk":"4230473092","pt":1631533407291,"mc":[{"id":"1.187557247","rc":[{"batb":[[0,1.44,851.79]],"ltp":1.45,"tv":43987.69,"id":10350473}]}]}
{"op":"mcm","clk":"4230473251","pt":1631533408970,"mc":[{"id":"1.187557247","rc":[{"batl":[[1,1.58,192.25],[2,1.59,145.56]],"ltp":1.45,"tv":43987.69,"id":10350473}]}]}
{"op":"mcm","clk":"4230473412","pt":1631533410690,"mc":[{"id":"1.187557247","rc":[{"trd":[[1.45,1796.12]],"batb":[[0,1.45,3527.09],[1,1.44,851.79],[2,1.43,13.36]],"ltp":1.45,"tv":43992.33,"id":10350473}],"tv":61632.17}]}
{"op":"mcm","clk":"4230473593","pt":1631533412489,"mc":[{"id":"1.187557247","rc":[{"batb":[[0,1.44,851.79],[1,1.43,13.36],[2,1.42,851.79]],"ltp":1.45,"tv":43992.33,"id":10350473}]}]}
{"op":"mcm","clk":"4230473695","pt":1631533413583,"mc":[{"id":"1.187557247","rc":[{"batl":[[1,1.57,80.5],[2,1.58,192.25]],"ltp":1.45,"tv":43992.33,"id":10350473},{"batb":[[0,2.74,5.02],[1,2.72,51.38],[2,2.6,5.24]],"ltp":3.15,"tv":17639.84,"id":9304761}]}]}
{"op":"mcm","clk":"4230473792","pt":1631533414572,"mc":[{"id":"1.187557247","rc":[{"batl":[[0,1.45,367.12],[1,1.54,12.47]],"ltp":1.45,"tv":43992.33,"id":10350473},{"batb":[[0,2.72,51.38],[1,2.6,5.24],[2,2.12,393.24]],"ltp":3.15,"tv":17639.84,"id":9304761}]}]}
{"op":"mcm","clk":"4230473862","pt":1631533415504,"mc":[{"id":"1.187557247","rc":[{"batl":[[0,1.45,687.38]],"ltp":1.45,"tv":43992.33,"id":10350473}]}]}
{"op":"mcm","clk":"4230473932","pt":1631533416390,"mc":[{"id":"1.187557247","rc":[{"batl":[[0,1.45,415.74],[1,1.58,192.25],[2,1.59,145.56]],"ltp":1.45,"tv":43992.33,"id":10350473}]}]}
{"op":"mcm","clk":"4230473982","pt":1631533417067,"mc":[{"id":"1.187557247","rc":[{"batl":[[0,1.45,391.47],[1,1.57,77.5],[2,1.58,192.25]],"ltp":1.45,"tv":43992.33,"id":10350473},{"batb":[[0,2.74,4.56],[1,2.72,51.38],[2,2.6,5.24]],"ltp":3.15,"tv":17639.84,"id":9304761}]}]}
{"op":"mcm","clk":"4230474128","pt":1631533418723,"mc":[{"id":"1.187557247","rc":[{"batb":[[0,1.53,3.37],[1,1.44,851.79],[2,1.43,13.36]],"batl":[[0,1.58,192.25],[1,1.59,145.56],[2,1.62,74.25]],"ltp":1.45,"tv":43992.33,"id":10350473},{"batb":[[0,2.72,51.38],[1,2.6,5.24],[2,2.12,393.24]],"batl":[[1,4.2,0]],"ltp":3.15,"tv":17639.84,"id":9304761}]}]}
{"op":"mcm","clk":"4230474208","pt":1631533419603,"mc":[{"id":"1.187557247","rc":[{"batb":[[0,1.53,336.55],[1,1.52,175.25],[2,1.44,851.79]],"batl":[[2,1.6,1195.32]],"ltp":1.45,"tv":43992.33,"id":10350473},{"batl":[[0,2.94,650.52],[1,2.96,631.38],[2,2.98,631.38]],"ltp":3.15,"tv":17639.84,"id":9304761}]}]}
{"op":"mcm","clk":"4230474309","pt":1631533420700,"mc":[{"id":"1.187557247","rc":[{"trd":[[1.53,26.81]],"batb":[[0,1.53,479.88],[2,1.45,9.39]],"ltp":1.53,"tv":44018.47,"id":10350473},{"batb":[[2,2.4,72.3]],"ltp":3.15,"tv":17639.84,"id":9304761}],"tv":61658.31}]}
{"op":"mcm","clk":"4230474403","pt":1631533421695,"mc":[{"id":"1.187557247","rc":[{"batb":[[2,1.45,226.95]],"batl":[[0,1.58,228.95]],"ltp":1.53,"tv":44018.47,"id":10350473},{"batb":[[0,2.72,73.62]],"ltp":3.15,"tv":17639.84,"id":9304761}]}]}
{"op":"mcm","clk":"4230474477","pt":1631533422376,"mc":[{"id":"1.187557247","rc":[{"batb":[[2,1.45,217.56]],"ltp":1.53,"tv":44018.47,"id":10350473}]}]}
{"op":"mcm","clk":"4230474594","pt":1631533423617,"mc":[{"id":"1.187557247","rc":[{"batb":[[0,1.55,189.93],[1,1.54,71.18],[2,1.53,479.88]],"batl":[[0,1.56,80.6],[1,1.57,63.67],[2,1.58,228.95]],"ltp":1.53,"tv":44018.47,"id":10350473},{"batb":[[0,2.72,1180.95]],"ltp":3.15,"tv":17639.84,"id":9304761}]}]}
{"op":"mcm","clk":"4230474696","pt":1631533424602,"mc":[{"id":"1.187557247","rc":[{"batb":[[1,2.64,36.58],[2,2.6,5.24]],"batl":[[0,2.92,18.1],[1,2.94,693.59],[2,2.96,631.38]],"ltp":3.15,"tv":17639.84,"id":9304761}]}]}
{"op":"mcm","clk":"4230474758","pt":1631533425332,"mc":[{"id":"1.187557247","rc":[{"trd":[[1.55,570.06]],"batb":[[0,1.55,186.03]],"ltp":1.55,"tv":44026.27,"id":10350473}],"tv":61666.12}]}
{"op":"mcm","clk":"4230474863","pt":1631533426535,"mc":[{"id":"1.187557247","rc":[{"batb":[[0,2.72,1635.66]],"ltp":3.15,"tv":17639.84,"id":9304761}]}]}
{"op":"mcm","clk":"4230474968","pt":1631533427626,"mc":[{"id":"1.187557247","rc":[{"batb":[[0,1.55,342.03]],"ltp":1.55,"tv":44026.27,"id":10350473}]}]}
{"op":"mcm","clk":"4230475107","pt":1631533429136,"mc":[{"id":"1.187557247","rc":[{"batl":[[1,2.94,650.52]],"ltp":3.15,"tv":17639.84,"id":9304761}]}]}
{"op":"mcm","clk":"4230475219","pt":1631533430544,"mc":[{"id":"1.187557247","rc":[{"batb":[[0,2.72,528.33]],"ltp":3.15,"tv":17639.84,"id":9304761}]}]}
{"op":"mcm","clk":"4230475273","pt":1631533431222,"mc":[{"id":"1.187557247","rc":[{"batb":[[0,1.56,42.21],[1,1.55,156],[2,1.53,454.34]],"batl":[[0,1.57,63.67],[1,1.58,228.95],[2,1.59,145.56]],"ltp":1.55,"tv":44026.27,"id":10350473}]}]}
{"op":"mcm","clk":"4230475414","pt":1631533432632,"mc":[{"id":"1.187557247","rc":[{"batl":[[0,2.9,43.52],[1,2.92,18.1],[2,2.94,650.52]],"ltp":3.15,"tv":17639.84,"id":9304761}]}]}
{"op":"mcm","clk":"4230475578","pt":1631533434410,"mc":[{"id":"1.187557247","rc":[{"trd":[[1.56,334.98]],"batb":[[0,1.55,156],[1,1.53,454.34],[2,1.52,258.45]],"ltp":1.56,"tv":44110.68,"id":10350473}],"tv":61750.52}]}
{"op":"mcm","clk":"4230475808","pt":1631533436711,"mc":[{"id":"1.187557247","rc":[{"batb":[[0,1.56,70.59],[1,1.55,156],[2,1.53,454.34]],"ltp":1.56,"tv":44110.68,"id":10350473}]}]}
{"op":"mcm","clk":"4230476192","pt":1631533441339,"mc":[{"id":"1.187557247","rc":[{"batb":[[0,1.55,156],[1,1.53,454.34],[2,1.52,258.45]],"ltp":1.56,"tv":44110.68,"id":10350473}]}]}
{"op":"mcm","clk":"4230476319","pt":1631533442751,"mc":[{"id":"1.187557247","rc":[{"batb":[[1,1.53,156.4],[2,1.52,83.2]],"batl":[[0,1.61,60],[1,1.67,9.48],[2,1.68,64.39]],"ltp":1.56,"tv":44110.68,"id":10350473},{"batb":[[0,2.72,51.38],[2,2.46,6.38]],"batl":[[1,3.2,3],[2,3.45,53.16]],"ltp":3.15,"tv":17639.84,"id":9304761}]}]}
{"op":"mcm","clk":"4230476402","pt":1631533443744,"mc":[{"id":"1.187557247","rc":[{"batb":[[0,1.46,13.13],[1,1.44,851.79],[2,1.42,1062.66]],"batl":[[0,1.67,9.48],[1,1.74,69.25],[2,1.68,0]],"ltp":1.56,"tv":44110.68,"id":10350473},{"batb":[[0,2.4,71.97],[1,2.34,6.72],[2,2.12,393.24]],"batl":[[0,3.45,53.16],[1,3.65,173.19],[2,3.45,0]],"ltp":3.15,"tv":17639.84,"id":9304761}]}]}
{"op":"mcm","clk":"4230476416","pt":1631533443849,"mc":[{"id":"1.187557247","rc":[{"batl":[[0,3.45,54.06]],"ltp":3.15,"tv":17639.84,"id":9304761}]}]}
{"op":"mcm","clk":"4230476603","pt":1631533445728,"mc":[{"id":"1.187557247","rc":[{"batb":[[2,1.42,1395.09]],"batl":[[1,1.72,191.71],[2,1.74,284.42]],"ltp":1.56,"tv":44110.68,"id":10350473}]}]}
{"op":"mcm","clk":"4230476965","pt":1631533449423,"mc":[{"id":"1.187557247","rc":[{"batb":[[2,1.42,1062.66]],"batl":[[0,1.72,191.71],[1,1.74,284.42],[2,1.74,0]],"ltp":1.56,"tv":44110.68,"id":10350473}]}]}
{"op":"mcm","clk":"4230477178","pt":1631533451655,"mc":[{"id":"1.187557247","rc":[{"batb":[[2,1.4,148.56]],"batl":[[1,3.65,0]],"ltp":3.15,"tv":17639.84,"id":9304761}]}]}
{"op":"mcm","clk":"4230477275","pt":1631533452644,"mc":[{"id":"1.187557247","rc":[{"batb":[[0,1.66,236.02],[1,1.65,129.12],[2,1.46,13.13]],"ltp":1.56,"tv":44110.68,"id":10350473},{"batb":[[1,2.34,456.25],[2,2.32,436.3]],"batl":[[0,2.56,747.06],[1,2.58,725.1],[2,2.6,725.1]],"ltp":3.15,"tv":17639.84,"id":9304761}]}]}
{"op":"mcm","clk":"4230477344","pt":1631533453578,"mc":[{"id":"1.187557247","rc":[{"trd":[[1.66,361.82]],"batb":[[0,1.66,341.07],[2,1.64,75]],"batl":[[2,1.75,60]],"ltp":1.66,"tv":44135.22,"id":10350473},{"batb":[[2,2.32,481.75]],"batl":[[0,2.56,795.09]],"ltp":3.15,"tv":17639.84,"id":9304761}],"tv":61775.06}]}
{"op":"mcm","clk":"4230477426","pt":1631533454262,"mc":[{"id":"1.187557247","rc":[{"batl":[[0,1.72,222.94]],"ltp":1.66,"tv":44135.22,"id":10350473}]}]}
{"op":"mcm","clk":"4230477638","pt":1631533456561,"mc":[{"id":"1.187557247","rc":[{"batb":[[0,1.69,74.4],[1,1.68,67.32],[2,1.67,66.7]],"batl":[[0,1.7,70.84],[1,1.71,60.83],[2,1.72,222.94]],"ltp":1.66,"tv":44135.22,"id":10350473}]}]}
{"op":"mcm","clk":"4230477760","pt":1631533457662,"mc":[{"id":"1.187557247","rc":[{"batl":[[0,2.54,20.33],[1,2.56,747.06],[2,2.58,725.1]],"ltp":3.15,"tv":17639.84,"id":9304761}]}]}
{"op":"mcm","clk":"4230477854","pt":1631533458756,"mc":[{"id":"1.187557247","rc":[{"batb":[[1,2.38,1448.04],[2,2.34,456.25]],"ltp":3.15,"tv":17639.84,"id":9304761}]}]}
{"op":"mcm","clk":"4230478069","pt":1631533460749,"mc":[{"id":"1.187557247","rc":[{"batl":[[0,2.54,68.67]],"ltp":3.15,"tv":17639.84,"id":9304761}]}]}
{"op":"mcm","clk":"4230478180","pt":1631533461685,"mc":[{"id":"1.187557247","rc":[{"trd":[[1.69,1270.98]],"batb":[[0,1.69,187.03]],"ltp":1.69,"tv":44283.96,"id":10350473},{"batb":[[2,2.34,6.72]],"batl":[[1,3.3,195.03],[2,3.45,53.16]],"ltp":3.15,"tv":17639.84,"id":9304761}],"tv":61923.8}]}
{"op":"mcm","clk":"4230478276","pt":1631533462578,"mc":[{"id":"1.187557247","rc":[{"batb":[[0,1.69,187],[1,1.65,74.42],[2,1.53,157.24]],"batl":[[0,1.75,60],[1,1.82,65.75],[2,1.88,66.79]],"ltp":1.69,"tv":44283.96,"id":10350473},{"batb":[[0,2.38,1448.04],[1,2.32,45.45],[2,2.16,97.15]],"batl":[[0,3.3,195.03],[1,3.45,53.16],[2,3.45,0]],"ltp":3.15,"tv":17639.84,"id":9304761}]}]}
{"op":"mcm","clk":"4230478376","pt":1631533463671,"mc":[{"id":"1.187557247","rc":[{"batb":[[0,1.53,157.24],[1,1.44,851.79],[2,1.42,851.79]],"batl":[[0,1.88,66.79],[1,1.89,59.5],[2,1.88,0]],"ltp":1.69,"tv":44283.96,"id":10350473},{"batb":[[0,2.16,97.15],[1,2.12,8.04],[2,1.86,403.32]],"ltp":3.15,"tv":17639.84,"id":9304761}]}]}
{"op":"mcm","clk":"4230478457","pt":1631533464456,"mc":[{"id":"1.187557247","rc":[{"trd":[[1.69,1320.58],[1.7,356.54]],"batb":[[0,1.55,10.96],[1,1.53,157.24],[2,1.44,851.79]],"batl":[[0,1.81,13.14],[1,1.88,66.79],[2,1.89,59.5]],"ltp":1.69,"tv":44362.16,"id":10350473},{"trd":[[2.42,276.32]],"ltp":2.42,"tv":17639.86,"id":9304761}],"tv":62002.02}]}
{"op":"mcm","clk":"4230478588","pt":1631533465757,"mc":[{"id":"1.187557247","rc":[{"batb":[[1,1.53,428.16],[2,1.52,175.12]],"batl":[[1,1.88,246.77]],"ltp":1.69,"tv":44362.16,"id":10350473},{"batl":[[0,2.56,48.03],[1,3.3,195.03],[2,3.45,53.16]],"ltp":2.42,"tv":17639.86,"id":9304761}]}]}
{"op":"mcm","clk":"4230478678","pt":1631533466689,"mc":[{"id":"1.187557247","rc":[{"batb":[[0,1.7,56.47],[1,1.55,10.96],[2,1.53,433.16]],"ltp":1.69,"tv":44362.16,"id":10350473},{"batl":[[0,2.9,3]],"ltp":2.42,"tv":17639.86,"id":9304761}]}]}
{"op":"mcm","clk":"4230478742","pt":1631533467264,"mc":[{"id":"1.187557247","rc":[{"trd":[[1.7,364.54]],"batb":[[0,1.7,52.47]],"ltp":1.7,"tv":44370.16,"id":10350473}],"tv":62010.02}]}
{"op":"mcm","clk":"4230478955","pt":1631533469655,"mc":[{"id":"1.187557247","rc":[{"trd":[[1.7,432.21]],"batb":[[0,1.7,18.63]],"ltp":1.7,"tv":44437.84,"id":10350473}],"tv":62077.7}]}
{"op":"mcm","clk":"4230479026","pt":1631533470487,"mc":[{"id":"1.187557247","rc":[{"trd":[[1.7,469.47]],"batb":[[0,1.55,10.96],[1,1.53,433.16],[2,1.52,182.12]],"batl":[[0,1.7,15.21],[1,1.81,13.14],[2,1.82,68.75]],"ltp":1.7,"tv":44475.1,"id":10350473}],"tv":62114.96}]}
{"op":"mcm","clk":"4230479054","pt":1631533470797,"mc":[{"id":"1.187557247","rc":[{"batl":[[2,1.88,246.77]],"ltp":1.7,"tv":44475.1,"id":10350473}]}]}
{"op":"mcm","clk":"4230479274","pt":1631533473002,"mc":[{"id":"1.187557247","rc":[{"batl":[[0,1.81,13.14],[1,1.88,246.77],[2,1.89,59.5]],"ltp":1.7,"tv":44475.1,"id":10350473}]}]}
{"op":"mcm","clk":"4230479467","pt":1631533475510,"mc":[{"id":"1.187557247","rc":[{"batb":[[0,2.2,6.32],[1,2.16,97.15],[2,2.12,8.04]],"ltp":2.42,"tv":17639.86,"id":9304761}]}]}
{"op":"mcm","clk":"4230479493","pt":1631533475784,"mc":[{"id":"1.187557247","rc":[{"batb":[[0,2.16,97.15],[1,2.12,8.04],[2,1.86,403.32]],"ltp":2.42,"tv":17639.86,"id":9304761}]}]}
{"op":"mcm","clk":"4230479642","pt":1631533477591,"mc":[{"id":"1.187557247","rc":[{"batl":[[1,1.82,62.25],[2,1.88,246.77]],"ltp":1.7,"tv":44475.1,"id":10350473}]}]}
{"op":"mcm","clk":"4230479667","pt":1631533477909,"mc":[{"id":"1.187557247","rc":[{"batl":[[1,1.88,246.77],[2,1.89,59.5]],"ltp":1.7,"tv":44475.1,"id":10350473}]}]}
{"op":"mcm","clk":"4230479787","pt":1631533479194,"mc":[{"id":"1.187557247","rc":[{"batb":[[2,1.52,175.12]],"ltp":1.7,"tv":44475.1,"id":10350473}]}]}
{"op":"mcm","clk":"4230480120","pt":1631533482685,"mc":[{"id":"1.187557247","rc":[{"batb":[[0,1.53,433.16],[1,1.52,175.12],[2,1.44,851.79]],"batl":[[1,1.88,66.79]],"ltp":1.7,"tv":44475.1,"id":10350473},{"batb":[[0,2.2,7.27],[1,2.16,97.15],[2,2.12,8.04]],"ltp":2.42,"tv":17639.86,"id":9304761}]}]}
{"op":"mcm","clk":"4230480193","pt":1631533483513,"mc":[{"id":"1.187557247","rc":[{"batb":[[0,2.16,97.15],[1,2.12,8.04],[2,1.4,148.56]],"batl":[[1,3.45,53.16],[2,3.45,0]],"ltp":2.42,"tv":17639.86,"id":9304761}]}]}
{"op":"mcm","clk":"4230480319","pt":1631533484704,"mc":[{"id":"1.187557247","rc":[{"trd":[[1.53,52.95]],"batb":[[0,1.53,415.09]],"batl":[[0,1.58,1362.2],[1,1.81,13.14],[2,1.82,67.75]],"ltp":1.53,"tv":44501.24,"id":10350473},{"batb":[[0,2.7,1416.66],[1,2.68,1375],[2,2.66,1375]],"batl":[[0,2.98,1283.56],[1,3,1245.8],[2,3.05,1245.8]],"ltp":2.42,"tv":17639.86,"id":9304761}],"tv":62141.1}]}
{"op":"mcm","clk":"4230480418","pt":1631533485594,"mc":[{"id":"1.187557247","rc":[{"batl":[[0,1.58,217.88],[1,1.59,238.95],[2,1.81,13.14]],"ltp":1.53,"tv":44501.24,"id":10350473},{"batb":[[0,2.7,708.32],[1,2.68,706.11],[2,2.66,687.5]],"batl":[[0,2.98,352.98],[1,3,342.6],[2,3.05,342.6]],"ltp":2.42,"tv":17639.86,"id":9304761}]}]}
{"op":"mcm","clk":"4230480520","pt":1631533486483,"mc":[{"id":"1.187557247","rc":[{"batb":[[0,1.53,497.5]],"batl":[[2,1.63,60]],"ltp":1.53,"tv":44501.24,"id":10350473},{"batb":[[0,2.72,51.05],[1,2.7,708.32],[2,2.68,706.11]],"batl":[[0,2.9,43.52],[1,2.98,352.98],[2,3,342.6]],"ltp":2.42,"tv":17639.86,"id":9304761}]}]}
{"op":"mcm","clk":"4230480888","pt":1631533489731,"mc":[{"id":"1.187557247","rc":[{"batb":[[0,1.55,58.52],[1,1.54,68.25],[2,1.53,497.5]],"batl":[[0,1.56,97.27],[1,1.57,58.76],[2,1.58,360.79]],"ltp":1.53,"tv":44501.24,"id":10350473},{"batb":[[0,2.72,87.4]],"batl":[[0,2.84,56.25],[1,2.9,43.52],[2,2.98,352.98]],"ltp":2.42,"tv":17639.86,"id":9304761}]}]}
{"op":"mcm","clk":"4230480919","pt":1631533490043,"mc":[{"id":"1.187557247","rc":[{"batb":[[2,1.53,578.37]],"ltp":1.53,"tv":44501.24,"id":10350473},{"batb":[[0,2.72,1729.26]],"batl":[[0,2.9,43.52],[1,2.98,352.98],[2,3,342.6]],"ltp":2.42,"tv":17639.86,"id":9304761}]}]}
{"op":"mcm","clk":"4230481246","pt":1631533493275,"mc":[{"id":"1.187557247","rc":[{"batb":[[0,1.55,280.52]],"ltp":1.53,"tv":44501.24,"id":10350473}]}]}
{"op":"mcm","clk":"4230481386","pt":1631533494575,"mc":[{"id":"1.187557247","rc":[{"trd":[[1.56,349.63]],"batl":[[0,1.56,89.94]],"ltp":1.56,"tv":44515.89,"id":10350473},{"batb":[[0,2.72,621.94]],"ltp":2.42,"tv":17639.86,"id":9304761}],"tv":62155.75}]}
{"op":"mcm","clk":"4230481415","pt":1631533494782,"mc":[{"id":"1.187557247","rc":[{"trd":[[1.56,369.15]],"batl":[[0,1.56,80.18]],"ltp":1.56,"tv":44535.41,"id":10350473}],"tv":62175.28}]}
{"op":"mcm","clk":"4230481631","pt":1631533497148,"mc":[{"id":"1.187557247","rc":[{"trd":[[1.57,648.11]],"batb":[[0,1.55,222],[1,1.53,497.5],[2,1.52,175.12]],"batl":[[0,1.57,96.45],[1,1.58,283.58],[2,1.59,238.95]],"ltp":1.57,"tv":44540.06,"id":10350473}],"tv":62179.93}]}
{"op":"mcm","clk":"4230482005","pt":1631533500958,"mc":[{"id":"1.187557247","rc":[{"batl":[[0,2.9,44.42]],"ltp":2.42,"tv":17639.86,"id":9304761}]}]}
{"op":"mcm","clk":"4230482404","pt":1631533504541,"mc":[{"id":"1.187557247","rc":[{"batl":[[0,2.98,353.88],[1,3,342.6],[2,3.05,342.6]],"ltp":2.42,"tv":17639.86,"id":9304761}]}]}
{"op":"mcm","clk":"4230482710","pt":1631533507681,"mc":[{"id":"1.187557247","rc":[{"batb":[[1,1.53,226.58],[2,1.45,13.62]],"batl":[[1,1.61,60],[2,1.71,12.3]],"ltp":1.57,"tv":44540.06,"id":10350473},{"batb":[[0,2.72,585.59],[1,2.64,36.58],[2,2.38,5.46]],"batl":[[0,2.94,43.97],[1,3.45,53.16],[2,3.65,173.19]],"ltp":2.42,"tv":17639.86,"id":9304761}]}]}
{"op":"mcm","clk":"4230482793","pt":1631533508463,"mc":[{"id":"1.187557247","rc":[{"batb":[[0,1.45,13.62],[1,1.44,851.79],[2,1.42,851.79]],"batl":[[0,1.71,12.3],[1,1.72,71.66],[2,1.74,66.75]],"ltp":1.57,"tv":44540.06,"id":10350473},{"batb":[[0,2.72,534.54],[1,2.38,5.46],[2,2.34,83.29]],"batl":[[0,3.45,54.06],[1,3.65,173.19],[2,3.65,0]],"ltp":2.42,"tv":17639.86,"id":9304761}]}]}
{"op":"mcm","clk":"4230482995","pt":1631533510602,"mc":[{"id":"1.187557247","rc":[{"batb":[[0,1.57,3.11],[1,1.45,13.62],[2,1.44,851.79]],"ltp":1.57,"tv":44540.06,"id":10350473},{"batb":[[0,2.38,5.46],[1,2.34,83.29],[2,2.26,6.98]],"ltp":2.42,"tv":17639.86,"id":9304761}]}]}
{"op":"mcm","clk":"4230483080","pt":1631533511475,"mc":[{"id":"1.187557247","rc":[{"batl":[[1,1.76,192.85],[2,1.78,200]],"ltp":1.57,"tv":44540.06,"id":10350473},{"batb":[[0,2.34,77.57],[1,2.26,6.98],[2,2.24,6.77]],"ltp":2.42,"tv":17639.86,"id":9304761}]}]}
{"op":"mcm","clk":"4230483155","pt":1631533512263,"mc":[{"id":"1.187557247","rc":[{"batl":[[0,3.45,53.16]],"ltp":2.42,"tv":17639.86,"id":9304761}]}]}
{"op":"mcm","clk":"4230483246","pt":1631533513505,"mc":[{"id":"1.187557247","rc":[{"trd":[[1.57,653.4]],"batb":[[0,1.45,14.16],[1,1.44,851.79],[2,1.42,851.79]],"ltp":1.57,"tv":44545.36,"id":10350473}],"tv":62185.22}]}
{"op":"mcm","clk":"4230483631","pt":1631533517685,"mc":[{"id":"1.187557247","rc":[{"trd":[[1.44,1703.58],[1.45,1823.36],[1.57,654.48]],"batb":[[0,1.42,851.79],[1,1.4,851.79],[2,1.39,612.56]],"batl":[[0,1.43,684.81],[1,1.71,12.3],[2,1.72,67.16]],"ltp":1.44,"tv":46277.26,"id":10350473},{"batb":[[0,2.38,6.46],[1,2.34,77.57],[2,2.26,6.98]],"ltp":2.42,"tv":17639.86,"id":9304761}],"tv":63917.12}]}
{"op":"mcm","clk":"4230483788","pt":1631533519401,"mc":[{"id":"1.187557247","rc":[{"batl":[[1,3.65,0]],"ltp":2.42,"tv":17639.86,"id":9304761}]}]}
{"op":"mcm","clk":"4230483907","pt":1631533520610,"mc":[{"id":"1.187557247","rc":[{"trd":[[1.42,28.58]],"batb":[[0,1.42,837.5]],"batl":[[0,1.43,1026.19],[1,1.44,1540.99],[2,1.45,1289.06]],"ltp":1.42,"tv":46305.84,"id":10350473},{"batb":[[0,3.3,16.18],[1,2.38,6.46],[2,2.34,77.57]],"batl":[[1,3.75,280.5],[2,3.8,272.25]],"ltp":2.42,"tv":17639.86,"id":9304761}],"tv":63945.71}]}
{"op":"mcm","clk":"4230484013","pt":1631533521719,"mc":[{"id":"1.187557247","rc":[{"batl":[[0,1.43,341.38]],"ltp":1.42,"tv":46305.84,"id":10350473},{"batb":[[0,3.3,94.84],[1,2.72,51.46],[2,2.38,6.46]],"ltp":2.42,"tv":17639.86,"id":9304761}]}]}
{"op":"mcm","clk":"4230484109","pt":1631533522612,"mc":[{"id":"1.187557247","rc":[{"trd":[[1.42,696.62]],"batb":[[0,1.42,503.48],[1,1.4,946.65]],"batl":[[0,1.43,392.18]],"ltp":1.42,"tv":46973.88,"id":10350473},{"batb":[[1,3.05,29.26],[2,2.72,51.46]],"batl":[[1,3.5,37.94],[2,3.75,280.5]],"ltp":2.42,"tv":17639.86,"id":9304761}],"tv":64613.75}]}
{"op":"mcm","clk":"4230484159","pt":1631533522980,"mc":[{"id":"1.187557247","rc":[{"trd":[[1.42,1533.3]],"batb":[[0,1.42,85.14]],"ltp":1.42,"tv":47810.56,"id":10350473}],"tv":65450.43}]}
{"op":"mcm","clk":"4230484313","pt":1631533524701,"mc":[{"id":"1.187557247","rc":[{"trd":[[1.42,1857.53]],"batb":[[0,1.4,851.79],[1,1.39,612.56],[2,1.38,1116.31]],"batl":[[0,1.42,2393.25],[1,1.43,504.76],[2,1.44,1540.99]],"ltp":1.42,"tv":48134.79,"id":10350473},{"batb":[[1,2.84,614.1]],"batl":[[1,3.75,280.5],[2,3.8,272.25]],"ltp":2.42,"tv":17639.86,"id":9304761}],"tv":65774.65}]}
{"op":"mcm","clk":"4230484417","pt":1631533525699,"mc":[{"id":"1.187557247","rc":[{"batb":[[0,1.41,66.43],[1,1.4,851.79],[2,1.39,612.56]],"batl":[[2,1.44,1604.07]],"ltp":1.42,"tv":48134.79,"id":10350473},{"batb":[[1,2.72,51.46],[2,2.38,6.46]],"ltp":2.42,"tv":17639.86,"id":9304761}]}]}
{"op":"mcm","clk":"4230484496","pt":1631533526698,"mc":[{"id":"1.187557247","rc":[{"batb":[[1,1.4,908.04]],"batl":[[0,1.42,2532.7]],"ltp":1.42,"tv":48134.79,"id":10350473}]}]}
{"op":"mcm","clk":"4230484586","pt":1631533527690,"mc":[{"id":"1.187557247","rc":[{"trd":[[1.42,2623.84]],"batl":[[0,1.42,139.45]],"ltp":1.42,"tv":48901.1,"id":10350473},{"batb":[[1,2.78,4.66],[2,2.72,51.46]],"ltp":2.42,"tv":17639.86,"id":9304761}],"tv":66540.96}]}
{"op":"mcm","clk":"4230484651","pt":1631533528414,"mc":[{"id":"1.187557247","rc":[{"batl":[[0,1.43,504.76],[1,1.44,1604.07],[2,1.45,1353.14]],"ltp":1.42,"tv":48901.1,"id":10350473},{"batb":[[0,3.3,618.28]],"ltp":2.42,"tv":17639.86,"id":9304761}]}]}
{"op":"mcm","clk":"4230484715","pt":1631533528990,"mc":[{"id":"1.187557247","rc":[{"batb":[[0,3.3,650.58]],"ltp":2.42,"tv":17639.86,"id":9304761}]}]}
{"op":"mcm","clk":"4230484875","pt":1631533530718,"mc":[{"id":"1.187557247","rc":[{"batb":[[2,1.39,708.63]],"ltp":1.42,"tv":48901.1,"id":10350473},{"batb":[[1,3.15,27.9],[2,2.78,4.66]],"batl":[[1,3.55,37.57],[2,3.75,280.5]],"ltp":2.42,"tv":17639.86,"id":9304761}]}]}
{"op":"mcm","clk":"4230484968","pt":1631533531715,"mc":[{"id":"1.187557247","rc":[{"batl":[[0,1.43,3060.13],[2,1.45,1289.06]],"ltp":1.42,"tv":48901.1,"id":10350473},{"batb":[[1,2.78,4.66],[2,2.72,51.46]],"ltp":2.42,"tv":17639.86,"id":9304761}]}]}
{"op":"mcm","clk":"4230485062","pt":1631533532716,"mc":[{"id":"1.187557247","rc":[{"trd":[[1.43,12]],"batb":[[0,1.41,319.43],[1,1.4,851.79]],"batl":[[0,1.42,172.86],[1,1.43,2941.55],[2,1.44,1540.99]],"ltp":1.43,"tv":48913.1,"id":10350473},{"batb":[[0,3.3,127.14]],"ltp":2.42,"tv":17639.86,"id":9304761}],"tv":66552.96}]}
{"op":"mcm","clk":"4230485158","pt":1631533533606,"mc":[{"id":"1.187557247","rc":[{"batb":[[2,1.39,671.62]],"ltp":1.43,"tv":48913.1,"id":10350473},{"batl":[[1,3.75,280.5],[2,3.8,272.25]],"ltp":2.42,"tv":17639.86,"id":9304761}]}]}
{"op":"mcm","clk":"4230485241","pt":1631533534396,"mc":[{"id":"1.187557247","rc":[{"batl":[[1,1.43,386.18]],"ltp":1.43,"tv":48913.1,"id":10350473}]}]}
{"op":"mcm","clk":"4230485340","pt":1631533535388,"mc":[{"id":"1.187557247","rc":[{"trd":[[1.42,2969.56]],"batb":[[0,1.42,1944.79],[1,1.41,319.43],[2,1.4,851.79]],"batl":[[0,1.43,335.38],[1,1.44,1540.99],[2,1.45,1289.06]],"ltp":1.42,"tv":49258.82,"id":10350473}],"tv":66898.68}]}
{"op":"mcm","clk":"4230485433","pt":1631533536382,"mc":[{"id":"1.187557247","rc":[{"batl":[[0,1.43,371.5],[2,1.45,1349.06]],"ltp":1.42,"tv":49258.82,"id":10350473},{"batb":[[0,3.3,94.84]],"batl":[[1,3.6,37.21],[2,3.75,280.5]],"ltp":2.42,"tv":17639.86,"id":9304761}]}]}
{"op":"mcm","clk":"4230485545","pt":1631533537581,"mc":[{"id":"1.187557247","rc":[{"batb":[[1,1.41,253]],"ltp":1.42,"tv":49258.82,"id":10350473},{"batb":[[1,3.2,27.27],[2,2.78,4.66]],"ltp":2.42,"tv":17639.86,"id":9304761}]}]}
{"op":"mcm","clk":"4230485629","pt":1631533538415,"mc":[{"id":"1.187557247","rc":[{"trd":[[1.42,5963.06]],"batb":[[0,1.42,448.04]],"ltp":1.42,"tv":52252.32,"id":10350473}],"tv":69892.18}]}
{"op":"mcm","clk":"4230485743","pt":1631533539721,"mc":[{"id":"1.187557247","rc":[{"batl":[[0,1.45,60],[1,1.55,10.59],[2,1.56,75.17]],"ltp":1.42,"tv":52252.32,"id":10350473},{"batb":[[0,3.3,78.66]],"batl":[[2,4.6,138.3]],"ltp":2.42,"tv":17639.86,"id":9304761}]}]}
{"op":"mcm","clk":"4230485817","pt":1631533540608,"mc":[{"id":"1.187557247","rc":[{"batb":[[1,1.4,851.79],[2,1.39,96.07]],"batl":[[2,1.63,61.5]],"ltp":1.42,"tv":52252.32,"id":10350473},{"batb":[[0,3.2,27.27],[1,2.72,51.46],[2,2.58,5.56]],"batl":[[0,3.45,53.88]],"ltp":2.42,"tv":17639.86,"id":9304761}]}]}
{"op":"mcm","clk":"4230485896","pt":1631533541439,"mc":[{"id":"1.187557247","rc":[{"batb":[[2,1.38,851.79]],"batl":[[0,1.55,10.59],[1,1.63,61.5],[2,1.72,67.16]],"ltp":1.42,"tv":52252.32,"id":10350473},{"batb":[[0,2.72,51.46],[1,2.58,5.56],[2,2.38,6.46]],"batl":[[1,4.6,138.3],[2,4.6,0]],"ltp":2.42,"tv":17639.86,"id":9304761}]}]}
{"op":"mcm","clk":"4230486032","pt":1631533542692,"mc":[{"id":"1.187557247","rc":[{"batl":[[1,1.58,248.07],[2,1.59,145.57]],"ltp":1.42,"tv":52252.32,"id":10350473}]}]}
{"op":"mcm","clk":"4230486111","pt":1631533543628,"mc":[{"id":"1.187557247","rc":[{"batb":[[0,1.4,851.79],[1,1.38,851.79],[2,1.37,9.39]],"ltp":1.42,"tv":52252.32,"id":10350473}]}]}
{"op":"mcm","clk":"4230486233","pt":1631533544735,"mc":[{"id":"1.187557247","rc":[{"batb":[[2,1.36,851.79]],"ltp":1.42,"tv":52252.32,"id":10350473}]}]}
{"op":"mcm","clk":"4230486253","pt":1631533544942,"mc":[{"id":"1.187557247","rc":[{"batl":[[1,1.63,61.5],[2,1.72,67.16]],"ltp":1.42,"tv":52252.32,"id":10350473}]}]}
{"op":"mcm","clk":"4230486415","pt":1631533546511,"mc":[{"id":"1.187557247","rc":[{"trd":[[1.43,13.66]],"batl":[[0,1.42,11.12],[1,1.55,10.59],[2,1.63,61.5]],"ltp":1.43,"tv":52253.98,"id":10350473},{"trd":[[3.3,0.72]],"batl":[[0,3.45,53.16],[1,4.6,0]],"ltp":3.3,"tv":17640.58,"id":9304761}],"tv":69894.56}]}
{"op":"mcm","clk":"4230486543","pt":1631533547719,"mc":[{"id":"1.187557247","rc":[{"trd":[[1.4,272.57]],"batb":[[0,1.4,715.5],[1,1.39,19.91],[2,1.38,851.79]],"batl":[[1,1.45,18.5],[2,1.55,10.59]],"ltp":1.4,"tv":52526.55,"id":10350473},{"batl":[[1,3.55,20.3]],"ltp":3.3,"tv":17640.58,"id":9304761}],"tv":70167.13}]}
{"op":"mcm","clk":"4230486645","pt":1631533548617,"mc":[{"id":"1.187557247","rc":[{"trd":[[1.4,631.97]],"batb":[[0,1.4,535.8],[1,1.38,851.79],[2,1.37,242.98]],"batl":[[0,1.41,233.7],[1,1.42,11.12]],"ltp":1.4,"tv":52885.95,"id":10350473},{"batl":[[1,3.55,0]],"ltp":3.3,"tv":17640.58,"id":9304761}],"tv":70526.54}]}
{"op":"mcm","clk":"4230486750","pt":1631533549610,"mc":[{"id":"1.187557247","rc":[{"batb":[[2,1.37,253.7]],"batl":[[2,1.49,52.95]],"ltp":1.4,"tv":52885.95,"id":10350473},{"batb":[[0,3,83.33],[1,2.72,51.46],[2,2.58,5.56]],"ltp":3.3,"tv":17640.58,"id":9304761}]}]}
{"op":"mcm","clk":"4230486836","pt":1631533550709,"mc":[{"id":"1.187557247","rc":[{"batl":[[1,1.49,52.95],[2,1.55,10.59]],"ltp":1.4,"tv":52885.95,"id":10350473},{"batb":[[1,2.78,5.66],[2,2.72,51.46]],"batl":[[1,5.3,120.75]],"ltp":3.3,"tv":17640.58,"id":9304761}]}]}
{"op":"mcm","clk":"4230486936","pt":1631533551713,"mc":[{"id":"1.187557247","rc":[{"batb":[[2,1.37,355.08]],"batl":[[0,1.41,313.6],[1,1.42,224.06]],"ltp":1.4,"tv":52885.95,"id":10350473},{"batb":[[0,2.78,5.66],[1,2.72,51.46],[2,2.58,5.56]],"ltp":3.3,"tv":17640.58,"id":9304761}]}]}
{"op":"mcm","clk":"4230486989","pt":1631533552233,"mc":[{"id":"1.187557247","rc":[{"batb":[[2,1.37,10.72]],"batl":[[0,1.55,10.59],[1,1.63,61.5],[2,1.72,67.16]],"ltp":1.4,"tv":52885.95,"id":10350473},{"batb":[[0,2.72,51.46],[1,2.58,5.56],[2,2.38,393.33]],"ltp":3.3,"tv":17640.58,"id":9304761}]}]}
{"op":"mcm","clk":"4230487263","pt":1631533554740,"mc":[{"id":"1.187557247","rc":[{"trd":[[1.4,654.21]],"batb":[[0,1.4,524.68]],"ltp":1.4,"tv":52908.18,"id":10350473}],"tv":70548.77}]}
{"op":"mcm","clk":"4230487373","pt":1631533555753,"mc":[{"id":"1.187557247","rc":[{"batl":[[1,1.58,159.03],[2,1.59,145.45]],"ltp":1.4,"tv":52908.18,"id":10350473}]}]}
{"op":"mcm","clk":"4230487630","pt":1631533558332,"mc":[{"id":"1.187557247","rc":[{"batb":[[0,1.41,7.36],[1,1.4,524.68],[2,1.38,851.79]],"ltp":1.4,"tv":52908.18,"id":10350473},{"batl":[[0,3.45,53.79]],"ltp":3.3,"tv":17640.58,"id":9304761}]}]}
{"op":"mcm","clk":"4230487783","pt":1631533559437,"mc":[{"id":"1.187557247","rc":[{"trd":[[1.4,1687.5],[1.41,14.72],[1.42,5964.55]],"batb":[[0,1.4,8.04],[1,1.38,851.79],[2,1.37,10.72]],"ltp":1.4,"tv":53957.68,"id":10350473},{"trd":[[3.35,0.63]],"batl":[[0,3.45,53.16]],"ltp":3.35,"tv":17641.21,"id":9304761}],"tv":71598.9}]}
{"op":"mcm","clk":"4230488131","pt":1631533562529,"mc":[{"id":"1.187557247","rc":[{"batl":[[1,1.56,65.67],[2,1.58,159.03]],"ltp":1.4,"tv":53957.68,"id":10350473},{"batb":[[0,2.78,4.66],[1,2.72,51.46],[2,2.58,5.56]],"ltp":3.35,"tv":17641.21,"id":9304761}]}]}
{"op":"mcm","clk":"4230488249","pt":1631533563732,"mc":[{"id":"1.187557247","rc":[{"batl":[[1,1.58,159.03],[2,1.59,145.45]],"ltp":1.4,"tv":53957.68,"id":10350473},{"batb":[[0,2.72,51.46],[1,2.58,5.56],[2,2.38,386.87]],"ltp":3.35,"tv":17641.21,"id":9304761}]}]}
{"op":"mcm","clk":"4230488287","pt":1631533564048,"mc":[{"id":"1.187557247","rc":[{"batb":[[2,1.36,851.79]],"batl":[[1,880,0.01],[2,1.59,0]],"ltp":1.4,"tv":53957.68,"id":10350473}]}]}
{"op":"mcm","clk":"4230488432","pt":1631533565573,"mc":[{"id":"1.187557247","rc":[{"batb":[[2,1.4,148.56]],"batl":[[1,5.3,0]],"ltp":3.35,"tv":17641.21,"id":9304761}]}]}
{"op":"mcm","clk":"4230488538","pt":1631533566542,"mc":[{"id":"1.187557247","rc":[{"trd":[[1.32,1703.58],[1.36,1703.58],[1.38,1703.58],[1.4,1834.57]],"batb":[[0,1.28,1262.59],[1,1.27,768.76],[2,1.2,2]],"batl":[[0,1.32,2045.93],[1,1.33,1406.25],[2,1.34,2391.76]],"ltp":1.32,"tv":59215.49,"id":10350473},{"trd":[[3.45,53.16]],"batl":[[0,4.8,796.88],[1,4.9,773.44],[2,5,773.44]],"ltp":3.45,"tv":17694.37,"id":9304761}],"tv":76909.86}]}
{"op":"mcm","clk":"4230488681","pt":1631533567742,"mc":[{"id":"1.187557247","rc":[{"batb":[[2,1.22,467.69]],"batl":[[0,1.31,282.7],[1,1.32,1038],[2,1.33,703.13]],"ltp":1.32,"tv":59215.49,"id":10350473},{"batb":[[0,4.2,84.85],[1,3.6,63.43],[2,2.72,51.46]],"batl":[[0,4.8,219.14],[1,4.9,212.7],[2,5,212.7]],"ltp":3.45,"tv":17694.37,"id":9304761}]}]}
{"op":"mcm","clk":"4230488781","pt":1631533568586,"mc":[{"id":"1.187557247","rc":[{"batb":[[2,2.58,5.56]],"ltp":3.45,"tv":17694.37,"id":9304761}]}]}
{"op":"mcm","clk":"4230488913","pt":1631533569676,"mc":[{"id":"1.187557247","rc":[{"trd":[[1.31,7.92]],"batl":[[0,1.31,278.74]],"ltp":1.31,"tv":59223.41,"id":10350473}],"tv":76917.78}]}
{"op":"mcm","clk":"4230489051","pt":1631533570637,"mc":[{"id":"1.187557247","rc":[{"batb":[[0,1.28,1313.67]],"batl":[[1,1.32,1095.2]],"ltp":1.31,"tv":59223.41,"id":10350473},{"batb":[[1,3.65,68.49],[2,3.6,63.43]],"batl":[[0,4.5,32.07],[1,4.7,21.48],[2,4.8,219.14]],"ltp":3.45,"tv":17694.37,"id":9304761}]}]}
{"op":"mcm","clk":"4230489162","pt":1631533571656,"mc":[{"id":"1.187557247","rc":[{"batb":[[0,1.29,941],[1,1.28,1313.67],[2,1.27,768.76]],"batl":[[0,1.3,85.27],[1,1.31,2834.11],[2,1.32,1095.2]],"ltp":1.31,"tv":59223.41,"id":10350473},{"batb":[[1,3.8,21.42],[2,3.65,68.49]],"batl":[[1,4.7,52.82]],"ltp":3.45,"tv":17694.37,"id":9304761}]}]}
{"op":"mcm","clk":"4230489290","pt":1631533572654,"mc":[{"id":"1.187557247","rc":[{"batl":[[0,1.31,2834.11],[1,1.32,1095.2],[2,1.33,703.13]],"ltp":1.31,"tv":59223.41,"id":10350473},{"batb":[[1,3.65,68.49],[2,3.6,63.43]],"batl":[[1,4.7,21.48]],"ltp":3.45,"tv":17694.37,"id":9304761}]}]}
{"op":"mcm","clk":"4230489422","pt":1631533573757,"mc":[{"id":"1.187557247","rc":[{"batb":[[0,1.29,1052.41]],"ltp":1.31,"tv":59223.41,"id":10350473}]}]}
{"op":"mcm","clk":"4230489607","pt":1631533575377,"mc":[{"id":"1.187557247","rc":[{"batl":[[1,1.32,3650.57]],"ltp":1.31,"tv":59223.41,"id":10350473},{"batb":[[1,3.9,20.68],[2,3.65,68.49]],"ltp":3.45,"tv":17694.37,"id":9304761}]}]}
{"op":"mcm","clk":"4230490199","pt":1631533580689,"mc":[{"id":"1.187557247","rc":[{"trd":[[1.31,13.68]],"batl":[[0,1.31,275.86]],"ltp":1.31,"tv":59229.17,"id":10350473}],"tv":76923.54}]}
{"op":"mcm","clk":"4230490361","pt":1631533582162,"mc":[{"id":"1.187557247","rc":[{"trd":[[4.2,10.08]],"batb":[[0,4.2,79.81]],"ltp":4.2,"tv":17704.45,"id":9304761}],"tv":76933.62}]}
{"op":"mcm","clk":"4230490496","pt":1631533583681,"mc":[{"id":"1.187557247","rc":[{"trd":[[1.31,18.9]],"batb":[[0,1.29,1052.5],[2,1.27,768]],"batl":[[0,1.31,273.25]],"ltp":1.31,"tv":59234.39,"id":10350473},{"trd":[[4.2,11.88]],"batb":[[0,4.2,78.91]],"ltp":4.2,"tv":17706.25,"id":9304761}],"tv":76940.64}]}
{"op":"mcm","clk":"4230490802","pt":1631533586662,"mc":[{"id":"1.187557247","rc":[{"trd":[[1.31,23.54]],"batl":[[0,1.31,270.93]],"ltp":1.31,"tv":59239.03,"id":10350473}],"tv":76945.28}]}
{"op":"mcm","clk":"4230491219","pt":1631533591716,"mc":[{"id":"1.187557247","rc":[{"batb":[[1,1.28,1667.32],[2,1.27,767.84]],"ltp":1.31,"tv":59239.03,"id":10350473}]}]}
{"op":"mcm","clk":"4230491319","pt":1631533592721,"mc":[{"id":"1.187557247","rc":[{"batb":[[1,1.28,2020.98]],"ltp":1.31,"tv":59239.03,"id":10350473},{"trd":[[4.2,28.92]],"batb":[[0,4.2,70.39]],"ltp":4.2,"tv":17723.28,"id":9304761}],"tv":76962.32}]}
{"op":"mcm","clk":"4230491582","pt":1631533595545,"mc":[{"id":"1.187557247","rc":[{"trd":[[1.3,0.19]],"batb":[[0,1.29,1052.41]],"batl":[[0,1.3,8.42],[1,1.31,270.93],[2,1.32,3650.57]],"ltp":1.3,"tv":59239.22,"id":10350473}],"tv":76962.51}]}
{"op":"mcm","clk":"4230491854","pt":1631533598314,"mc":[{"id":"1.187557247","rc":[{"batl":[[1,1.31,2826.3]],"ltp":1.3,"tv":59239.22,"id":10350473}]}]}
{"op":"mcm","clk":"4230491904","pt":1631533598840,"mc":[{"id":"1.187557247","rc":[{"batb":[[2,1.27,766.58]],"ltp":1.3,"tv":59239.22,"id":10350473}]}]}
{"op":"mcm","clk":"4230492510","pt":1631533605840,"mc":[{"id":"1.187557247","rc":[{"trd":[[1.29,15.4]],"batb":[[0,1.29,1044.71]],"ltp":1.29,"tv":59254.62,"id":10350473}],"tv":76977.91}]}
{"op":"mcm","clk":"4230493261","pt":1631533613672,"mc":[{"id":"1.187557247","rc":[{"trd":[[1.3,17.04]],"batb":[[0,1.3,202.89],[1,1.29,111.41],[2,1.28,2020.98]],"batl":[[0,1.31,2826.3],[1,1.32,3650.57],[2,1.33,1056.79]],"ltp":1.3,"tv":59271.47,"id":10350473}],"tv":76994.76}]}
{"op":"mcm","clk":"4230493366","pt":1631533614760,"mc":[{"id":"1.187557247","rc":[{"trd":[[1.3,21.68]],"batb":[[0,1.3,200.56]],"ltp":1.3,"tv":59276.12,"id":10350473}],"tv":76999.41}]}
{"op":"mcm","clk":"4230493442","pt":1631533615438,"mc":[{"id":"1.187557247","rc":[{"trd":[[1.31,39.54]],"batl":[[0,1.31,2818.3]],"ltp":1.31,"tv":59292.12,"id":10350473}],"tv":77015.41}]}
{"op":"mcm","clk":"4230493571","pt":1631533616745,"mc":[{"id":"1.187557247","rc":[{"batb":[[0,1.3,3750.56]],"ltp":1.31,"tv":59292.12,"id":10350473}]}]}
{"op":"mcm","clk":"4230493620","pt":1631533617431,"mc":[{"id":"1.187557247","rc":[{"batb":[[0,1.3,3753.08]],"ltp":1.31,"tv":59292.12,"id":10350473}]}]}
{"op":"mcm","clk":"4230494043","pt":1631533621742,"mc":[{"id":"1.187557247","rc":[{"batb":[[0,1.3,3752.89]],"ltp":1.31,"tv":59292.12,"id":10350473}]}]}
{"op":"mcm","clk":"4230494365","pt":1631533624982,"mc":[{"id":"1.187557247","rc":[{"batl":[[0,1.31,262.93]],"ltp":1.31,"tv":59292.12,"id":10350473}]}]}
{"op":"mcm","clk":"4230494671","pt":1631533628164,"mc":[{"id":"1.187557247","rc":[{"trd":[[1.31,39.93]],"batl":[[0,1.31,262.74]],"ltp":1.31,"tv":59292.5,"id":10350473}],"tv":77015.79}]}
{"op":"mcm","clk":"4230495016","pt":1631533631965,"mc":[{"id":"1.187557247","rc":[{"batb":[[0,1.3,3750.56]],"ltp":1.31,"tv":59292.5,"id":10350473}]}]}
{"op":"mcm","clk":"4230495721","pt":1631533640104,"mc":[{"id":"1.187557247","rc":[{"trd":[[1.31,463.45]],"batl":[[0,1.32,3650.57],[1,1.33,1056.79],[2,1.34,1466.26]],"ltp":1.31,"tv":59716.02,"id":10350473}],"tv":77439.31}]}
{"op":"mcm","clk":"4230495855","pt":1631533641611,"mc":[{"id":"1.187557247","rc":[{"batb":[[0,1.31,2.32],[1,1.3,3750.56],[2,1.29,111.41]],"ltp":1.31,"tv":59716.02,"id":10350473},{"trd":[[4.2,33.42]],"batb":[[0,4.2,68.14]],"ltp":4.2,"tv":17727.78,"id":9304761}],"tv":77443.81}]}
{"op":"mcm","clk":"4230495994","pt":1631533643084,"mc":[{"id":"1.187557247","rc":[{"batl":[[0,1.32,3810.95],[1,1.33,1353.44]],"ltp":1.31,"tv":59716.02,"id":10350473}]}]}
{"op":"mcm","clk":"4230496278","pt":1631533646201,"mc":[{"id":"1.187557247","rc":[{"trd":[[1.32,9542.3]],"batb":[[0,1.32,3031.06],[1,1.31,2.32],[2,1.3,3750.56]],"batl":[[0,1.33,1353.44],[1,1.34,1466.26],[2,1.4,353.66]],"ltp":1.32,"tv":67554.74,"id":10350473},{"trd":[[4.2,101.56]],"batb":[[0,3.9,20.68],[1,3.6,63.43],[2,2.58,5.56]],"batl":[[1,4.8,219.14],[2,4.9,212.7]],"ltp":4.2,"tv":17795.93,"id":9304761}],"tv":85350.67}]}
{"op":"mcm","clk":"4230496647","pt":1631533649692,"mc":[{"id":"1.187557247","rc":[{"trd":[[1.32,9966.38]],"batb":[[0,1.32,3204.56],[2,1.29,466.31]],"batl":[[0,1.33,1165.94]],"ltp":1.32,"tv":67978.82,"id":10350473},{"batb":[[0,3.95,28.62],[1,3.9,20.68],[2,3.6,63.43]],"batl":[[0,4.5,96.05]],"ltp":4.2,"tv":17795.93,"id":9304761}],"tv":85774.75}]}
{"op":"mcm","clk":"4230496688","pt":1631533650099,"mc":[{"id":"1.187557247","rc":[{"trd":[[1.32,10061.48]],"batb":[[0,1.32,3157.01],[1,1.31,191.24]],"batl":[[1,1.34,1625.36]],"ltp":1.32,"tv":68073.92,"id":10350473},{"batb":[[0,3.9,20.68],[1,3.6,63.43],[2,2.58,5.56]],"batl":[[0,4.5,74.57]],"ltp":4.2,"tv":17795.93,"id":9304761}],"tv":85869.85}]}
{"op":"mcm","clk":"4230496936","pt":1631533652711,"mc":[{"id":"1.187557247","rc":[{"batb":[[0,1.32,3873.01],[2,1.3,187.17]],"batl":[[0,1.33,1260.21],[1,1.34,1906.45],[2,1.35,353.66]],"ltp":1.32,"tv":68073.92,"id":10350473}]}]}
{"op":"mcm","clk":"4230497016","pt":1631533653503,"mc":[{"id":"1.187557247","rc":[{"batl":[[0,4.4,32.86],[1,4.5,74.57],[2,4.8,219.14]],"ltp":4.2,"tv":17795.93,"id":9304761}]}]}
{"op":"mcm","clk":"4230497056","pt":1631533654018,"mc":[{"id":"1.187557247","rc":[{"trd":[[1.32,10061.66]],"batb":[[0,1.32,3872.92]],"ltp":1.32,"tv":68074.1,"id":10350473}],"tv":85870.03}]}
{"op":"mcm","clk":"4230497202","pt":1631533655683,"mc":[{"id":"1.187557247","rc":[{"batb":[[1,1.31,2.32]],"batl":[[1,1.34,1747.35]],"ltp":1.32,"tv":68074.1,"id":10350473},{"batb":[[0,3.95,18.33],[1,3.9,20.68],[2,3.6,63.43]],"ltp":4.2,"tv":17795.93,"id":9304761}]}]}
{"op":"mcm","clk":"4230497908","pt":1631533663420,"mc":[{"id":"1.187557247","rc":[{"batb":[[0,3.9,20.68],[1,3.6,63.43],[2,3.35,3.47]],"batl":[[0,4.5,74.57],[1,4.8,219.14],[2,4.9,212.7]],"ltp":4.2,"tv":17795.93,"id":9304761}]}]}
{"op":"mcm","clk":"4230498171","pt":1631533666036,"mc":[{"id":"1.187557247","rc":[{"batb":[[0,3.6,63.43],[1,3.35,3.47],[2,3.1,3.74]],"ltp":4.2,"tv":17795.93,"id":9304761}]}]}
{"op":"mcm","clk":"4230498484","pt":1631533669227,"mc":[{"id":"1.187557247","rc":[{"batb":[[0,3.85,21.05],[1,3.6,63.43],[2,3.35,3.47]],"ltp":4.2,"tv":17795.93,"id":9304761}]}]}
{"op":"mcm","clk":"4230498615","pt":1631533670417,"mc":[{"id":"1.187557247","rc":[{"batb":[[1,1.3,187.17],[2,1.29,466.31]],"ltp":1.32,"tv":68074.1,"id":10350473}]}]}
{"op":"mcm","clk":"4230499397","pt":1631533679219,"mc":[{"id":"1.187557247","rc":[{"trd":[[1.33,4.64]],"batl":[[0,1.33,1257.89]],"ltp":1.33,"tv":68078.75,"id":10350473}],"tv":85874.68}]}
{"op":"mcm","clk":"4230499483","pt":1631533680250,"mc":[{"id":"1.187557247","rc":[{"batb":[[0,1.32,716]],"ltp":1.33,"tv":68078.75,"id":10350473}]}]}
{"op":"mcm","clk":"4230499693","pt":1631533682439,"mc":[{"id":"1.187557247","rc":[{"batb":[[1,1.29,111.41],[2,1.28,1559.1]],"batl":[[0,1.34,60],[1,1.35,353.66],[2,1.4,353.66]],"ltp":1.33,"tv":68078.75,"id":10350473},{"batb":[[1,3.35,3.47],[2,3.1,3.74]],"batl":[[0,4.5,32.07],[1,5.5,3.64],[2,6,107.94]],"ltp":4.2,"tv":17795.93,"id":9304761}]}]}
{"op":"mcm","clk":"4230499795","pt":1631533683445,"mc":[{"id":"1.187557247","rc":[{"batb":[[0,1.28,1559.1],[1,1.22,353.66],[2,1.2,2]],"batl":[[0,1.35,353.66],[1,1.4,353.66],[2,1.42,74.25]],"ltp":1.33,"tv":68078.75,"id":10350473},{"batb":[[0,3.35,3.47],[1,3.1,3.74],[2,2.58,5.56]],"batl":[[0,5.5,3.64],[1,6,107.94],[2,990,0.01]],"ltp":4.2,"tv":17795.93,"id":9304761}]}]}
{"op":"mcm","clk":"4230500001","pt":1631533685653,"mc":[{"id":"1.187557247","rc":[{"batl":[[1,1.42,74.25],[2,1.47,62.5]],"ltp":1.33,"tv":68078.75,"id":10350473}]}]}
{"op":"mcm","clk":"4230500112","pt":1631533686642,"mc":[{"id":"1.187557247","rc":[{"batl":[[0,5.4,151.53],[1,5.5,3.64],[2,6,107.94]],"ltp":4.2,"tv":17795.93,"id":9304761}]}]}
{"op":"mcm","clk":"4230500128","pt":1631533686846,"mc":[{"id":"1.187557247","rc":[{"batl":[[0,5.5,3.64],[1,6,107.94],[2,990,0.01]],"ltp":4.2,"tv":17795.93,"id":9304761}]}]}
{"op":"mcm","clk":"4230500677","pt":1631533692322,"mc":[{"id":"1.187557247","rc":[{"batb":[[0,3.45,327.34],[1,3.35,3.47],[2,3.1,3.74]],"ltp":4.2,"tv":17795.93,"id":9304761}]}]}
{"op":"mcm","clk":"4230500800","pt":1631533693438,"mc":[{"id":"1.187557247","rc":[{"batl":[[0,5.3,164.53],[1,5.5,3.64],[2,6,107.94]],"ltp":4.2,"tv":17795.93,"id":9304761}]}]}
{"op":"mcm","clk":"4230501186","pt":1631533697358,"mc":[{"id":"1.187557247","rc":[{"batb":[[0,1.33,29.81],[1,1.28,1559.1],[2,1.22,353.66]],"ltp":1.33,"tv":68078.75,"id":10350473}]}]}
{"op":"mcm","clk":"4230501253","pt":1631533698135,"mc":[{"id":"1.187557247","rc":[{"trd":[[1.35,4.65]],"batl":[[0,1.35,351.33]],"ltp":1.35,"tv":68083.39,"id":10350473}],"tv":85879.32}]}
{"op":"mcm","clk":"4230501422","pt":1631533699866,"mc":[{"id":"1.187557247","rc":[{"batb":[[0,1.33,33.22]],"ltp":1.35,"tv":68083.39,"id":10350473}]}]}
{"op":"mcm","clk":"4230501572","pt":1631533701327,"mc":[{"id":"1.187557247","rc":[{"batl":[[2,1.44,71.83]],"ltp":1.35,"tv":68083.39,"id":10350473},{"batb":[[2,3.25,3.93]],"batl":[[0,5.5,3.64],[1,6,107.94],[2,990,0.01]],"ltp":4.2,"tv":17795.93,"id":9304761}]}]}
{"op":"mcm","clk":"4230501692","pt":1631533702669,"mc":[{"id":"1.187557247","rc":[{"batl":[[0,1.42,74.25],[1,1.44,71.83],[2,1.47,62.5]],"ltp":1.35,"tv":68083.39,"id":10350473}]}]}
{"op":"mcm","clk":"4230501788","pt":1631533703566,"mc":[{"id":"1.187557247","rc":[{"batb":[[0,3.35,3.47],[1,3.25,3.93],[2,3.1,3.74]],"ltp":4.2,"tv":17795.93,"id":9304761}]}]}
{"op":"mcm","clk":"4230501912","pt":1631533704759,"mc":[{"id":"1.187557247","rc":[{"trd":[[1.33,71.08]],"batb":[[0,1.28,1559.1],[1,1.22,353.66],[2,1.2,2]],"batl":[[0,1.33,370.78],[1,1.42,74.25],[2,1.44,71.83]],"ltp":1.33,"tv":68149.83,"id":10350473}],"tv":85945.76}]}
{"op":"mcm","clk":"4230502044","pt":1631533706365,"mc":[{"id":"1.187557247","rc":[{"batb":[[0,1.28,851.79]],"batl":[[0,1.42,74.25],[1,1.44,71.83],[2,1.47,62.5]],"ltp":1.33,"tv":68149.83,"id":10350473}]}]}
{"op":"mcm","clk":"4230502159","pt":1631533707764,"mc":[{"id":"1.187557247","rc":[{"batl":[[0,5.4,161.5],[1,5.5,3.64],[2,6,107.94]],"ltp":4.2,"tv":17795.93,"id":9304761}]}]}
{"op":"mcm","clk":"4230502428","pt":1631533710671,"mc":[{"id":"1.187557247","rc":[{"batl":[[0,1.41,448.39],[1,1.42,74.25],[2,1.44,71.83]],"ltp":1.33,"tv":68149.83,"id":10350473},{"batb":[[0,3.5,164.36],[1,3.35,3.47],[2,3.25,3.93]],"ltp":4.2,"tv":17795.93,"id":9304761}]}]}
{"op":"mcm","clk":"4230502451","pt":1631533710843,"mc":[{"id":"1.187557247","rc":[{"batl":[[0,1.42,74.25],[1,1.44,71.83],[2,1.47,62.5]],"ltp":1.33,"tv":68149.83,"id":10350473},{"batb":[[0,3.35,3.47],[1,3.25,3.93],[2,3.1,3.74]],"ltp":4.2,"tv":17795.93,"id":9304761}]}]}
{"op":"mcm","clk":"4230502527","pt":1631533711788,"mc":[{"id":"1.187557247","rc":[{"batl":[[0,1.41,353.66],[1,1.42,74.25],[2,1.44,71.83]],"ltp":1.33,"tv":68149.83,"id":10350473}]}]}
{"op":"mcm","clk":"4230504639","pt":1631533733574,"mc":[{"id":"1.187557247","rc":[{"batl":[[2,990,0.01]],"ltp":4.2,"tv":17795.93,"id":9304761}]}]}
{"op":"mcm","clk":"4230505832","pt":1631533744322,"mc":[{"id":"1.187557247","rc":[{"batl":[[0,5.5,3.64],[1,990,0.01],[2,990,0]],"ltp":4.2,"tv":17795.93,"id":9304761}]}]}
{"op":"mcm","clk":"4230506132","pt":1631533747410,"mc":[{"id":"1.187557247","rc":[{"batl":[[0,5.2,132.56],[1,5.5,3.64],[2,990,0.01]],"ltp":4.2,"tv":17795.93,"id":9304761}]}]}
{"op":"mcm","clk":"4230507732","pt":1631533764803,"mc":[{"id":"1.187557247","rc":[{"batl":[[0,5.5,3.64],[1,990,0.01],[2,990,0]],"ltp":4.2,"tv":17795.93,"id":9304761}]}]}
{"op":"mcm","clk":"4230507978","pt":1631533767307,"mc":[{"id":"1.187557247","rc":[{"batb":[[0,1.29,2.43],[1,1.28,851.79],[2,1.22,353.66]],"ltp":1.33,"tv":68149.83,"id":10350473}]}]}
{"op":"mcm","clk":"4230508425","pt":1631533771723,"mc":[{"id":"1.187557247","rc":[{"batb":[[2,1.2,2]],"ltp":1.33,"tv":68149.83,"id":10350473}]}]}
{"op":"mcm","clk":"4230508616","pt":1631533773342,"mc":[{"id":"1.187557247","rc":[{"batl":[[0,1.39,50],[1,1.41,353.66],[2,1.42,74.25]],"ltp":1.33,"tv":68149.83,"id":10350473}]}]}
{"op":"mcm","clk":"4230508775","pt":1631533774710,"mc":[{"id":"1.187557247","rc":[{"batl":[[0,5.4,456.96],[1,5.5,3.64],[2,990,0.01]],"ltp":4.2,"tv":17795.93,"id":9304761}]}]}
{"op":"mcm","clk":"4230508864","pt":1631533775739,"mc":[{"id":"1.187557247","rc":[{"batl":[[1,1.42,74.25],[2,1.44,71.83]],"ltp":1.33,"tv":68149.83,"id":10350473},{"batl":[[0,5.5,3.64],[1,990,0.01],[2,990,0]],"ltp":4.2,"tv":17795.93,"id":9304761}]}]}
{"op":"mcm","clk":"4230509588","pt":1631533783430,"mc":[{"id":"1.187557247","rc":[{"batl":[[0,1.38,18.08],[1,1.39,50],[2,1.42,74.25]],"ltp":1.33,"tv":68149.83,"id":10350473}]}]}
{"op":"mcm","clk":"4230510706","pt":1631533794855,"mc":[{"id":"1.187557247","rc":[{"batl":[[0,5.4,456.96],[1,5.5,3.64],[2,990,0.01]],"ltp":4.2,"tv":17795.93,"id":9304761}]}]}
{"op":"mcm","clk":"4230510899","pt":1631533796571,"mc":[{"id":"1.187557247","rc":[{"batb":[[1,3.3,271.05],[2,3.25,3.93]],"ltp":4.2,"tv":17795.93,"id":9304761}]}]}
{"op":"mcm","clk":"4230511155","pt":1631533798773,"mc":[{"id":"1.187557247","rc":[{"trd":[[1.38,1705.5]],"batl":[[0,1.38,16.16]],"ltp":1.38,"tv":68151.75,"id":10350473},{"trd":[[3.6,0.73]],"ltp":3.6,"tv":17796.66,"id":9304761}],"tv":85948.41}]}
{"op":"mcm","clk":"4230511352","pt":1631533800587,"mc":[{"id":"1.187557247","rc":[{"trd":[[1.28,80.32],[1.29,20.26]],"batb":[[0,1.28,811.63],[1,1.2,2],[2,1.01,477.35]],"ltp":1.28,"tv":68236.93,"id":10350473}],"tv":86033.59}]}
{"op":"mcm","clk":"4230511770","pt":1631533804446,"mc":[{"id":"1.187557247","rc":[{"batl":[[1,1.42,74.25],[2,1.44,71.83]],"ltp":1.28,"tv":68236.93,"id":10350473}]}]}
{"op":"mcm","clk":"4230511959","pt":1631533806582,"mc":[{"id":"1.187557247","rc":[{"batb":[[2,1.01,479.52]],"ltp":1.28,"tv":68236.93,"id":10350473}]}]}
{"op":"mcm","clk":"4230512058","pt":1631533807691,"mc":[{"id":"1.187557247","rc":[{"batb":[[2,1.01,477.35]],"batl":[[0,1.42,74.25],[1,1.44,71.83],[2,1.47,62.5]],"ltp":1.28,"tv":68236.93,"id":10350473},{"batb":[[1,3.25,3.93],[2,3.1,3.74]],"ltp":3.6,"tv":17796.66,"id":9304761}]}]}
{"op":"mcm","clk":"4230512372","pt":1631533811188,"mc":[{"id":"1.187557247","rc":[{"batb":[[0,1.3,2.04],[1,1.28,811.63],[2,1.2,2]],"batl":[[0,1.41,18.08],[1,1.42,74.25],[2,1.44,71.83]],"ltp":1.28,"tv":68236.93,"id":10350473}]}]}
{"op":"mcm","clk":"4230515351","pt":1631533841968,"mc":[{"id":"1.187557247","rc":[{"trd":[[1.41,30.33]],"batl":[[0,1.41,10.27]],"ltp":1.41,"tv":68252.55,"id":10350473}],"tv":86049.21}]}
{"op":"mcm","clk":"4230515556","pt":1631533844319,"mc":[{"id":"1.187557247","rc":[{"batb":[[0,1.39,3],[1,1.3,2.04],[2,1.28,811.63]],"ltp":1.41,"tv":68252.55,"id":10350473}]}]}
{"op":"mcm","clk":"4230515939","pt":1631533848326,"mc":[{"id":"1.187557247","rc":[{"batl":[[0,5.5,3.64],[1,990,0.01],[2,990,0]],"ltp":3.6,"tv":17796.66,"id":9304761}]}]}
{"op":"mcm","clk":"4230516049","pt":1631533849530,"mc":[{"id":"1.187557247","rc":[{"batb":[[1,1.28,811.63],[2,1.2,2]],"ltp":1.41,"tv":68252.55,"id":10350473}]}]}
{"op":"mcm","clk":"4230516189","pt":1631533850892,"mc":[{"id":"1.187557247","rc":[{"batl":[[0,5.2,179.89],[1,5.5,3.64],[2,990,0.01]],"ltp":3.6,"tv":17796.66,"id":9304761}]}]}
{"op":"mcm","clk":"4230516355","pt":1631533852430,"mc":[{"id":"1.187557247","rc":[{"trd":[[1.39,6]],"batb":[[0,1.28,811.63],[1,1.2,2],[2,1.01,477.35]],"batl":[[0,1.39,397],[1,1.41,10.27],[2,1.42,74.25]],"ltp":1.39,"tv":68258.55,"id":10350473},{"batl":[[0,5.5,3.64],[1,990,0.01],[2,990,0]],"ltp":3.6,"tv":17796.66,"id":9304761}],"tv":86055.21}]}
{"op":"mcm","clk":"4230516457","pt":1631533853513,"mc":[{"id":"1.187557247","rc":[{"batl":[[0,1.39,403]],"ltp":1.39,"tv":68258.55,"id":10350473}]}]}
{"op":"mcm","clk":"4230516573","pt":1631533854622,"mc":[{"id":"1.187557247","rc":[{"trd":[[1.39,10.64]],"batl":[[0,1.39,15.61]],"ltp":1.39,"tv":68263.19,"id":10350473}],"tv":86059.86}]}
{"op":"mcm","clk":"4230516692","pt":1631533855721,"mc":[{"id":"1.187557247","rc":[{"batb":[[0,1.29,248.49],[1,1.28,811.63],[2,1.2,2]],"batl":[[0,1.39,30.51]],"ltp":1.39,"tv":68263.19,"id":10350473}]}]}
{"op":"mcm","clk":"4230516804","pt":1631533856707,"mc":[{"id":"1.187557247","rc":[{"batb":[[0,1.3,10.51]],"batl":[[0,1.39,15.61]],"ltp":1.39,"tv":68263.19,"id":10350473}]}]}
{"op":"mcm","clk":"4230516893","pt":1631533857596,"mc":[{"id":"1.187557247","rc":[{"batl":[[0,1.39,3.68]],"ltp":1.39,"tv":68263.19,"id":10350473}]}]}
{"op":"mcm","clk":"4230517024","pt":1631533859002,"mc":[{"id":"1.187557247","rc":[{"trd":[[1.28,88.74],[1.3,42.7]],"batb":[[0,1.28,807.42],[1,1.2,2],[2,1.01,477.35]],"batl":[[0,1.39,2]],"ltp":1.28,"tv":68292.63,"id":10350473}],"tv":86089.29}]}
{"op":"mcm","clk":"4230517262","pt":1631533861618,"mc":[{"id":"1.187557247","rc":[{"batl":[[0,1.39,400]],"ltp":1.28,"tv":68292.63,"id":10350473},{"batl":[[0,5.4,206.44],[1,5.5,3.64],[2,990,0.01]],"ltp":3.6,"tv":17796.66,"id":9304761}]}]}
{"op":"mcm","clk":"4230517286","pt":1631533861829,"mc":[{"id":"1.187557247","rc":[{"batl":[[0,5.5,3.64],[1,990,0.01],[2,990,0]],"ltp":3.6,"tv":17796.66,"id":9304761}]}]}
{"op":"mcm","clk":"4230517596","pt":1631533865234,"mc":[{"id":"1.187557247","rc":[{"trd":[[1.39,10.7]],"batl":[[0,1.39,399.97]],"ltp":1.39,"tv":68292.69,"id":10350473}],"tv":86089.35}]}
{"op":"mcm","clk":"4230517702","pt":1631533866332,"mc":[{"id":"1.187557247","rc":[{"batl":[[0,1.38,18.08],[1,1.39,399.97],[2,1.41,10.27]],"ltp":1.39,"tv":68292.69,"id":10350473}]}]}
{"op":"mcm","clk":"4230517816","pt":1631533867424,"mc":[{"id":"1.187557247","rc":[{"batl":[[1,1.41,10.27],[2,1.42,74.25]],"ltp":1.39,"tv":68292.69,"id":10350473}]}]}
{"op":"mcm","clk":"4230517940","pt":1631533868517,"mc":[{"id":"1.187557247","rc":[{"batb":[[0,1.37,3],[1,1.28,807.42],[2,1.2,2]],"ltp":1.39,"tv":68292.69,"id":10350473}]}]}
{"op":"mcm","clk":"4230518241","pt":1631533871634,"mc":[{"id":"1.187557247","rc":[{"batl":[[0,5.4,529.39],[1,5.5,3.64],[2,990,0.01]],"ltp":3.6,"tv":17796.66,"id":9304761}]}]}
{"op":"mcm","clk":"4230518259","pt":1631533871836,"mc":[{"id":"1.187557247","rc":[{"batl":[[0,5.5,3.64],[1,990,0.01],[2,990,0]],"ltp":3.6,"tv":17796.66,"id":9304761}]}]}
{"op":"mcm","clk":"4230518697","pt":1631533875240,"mc":[{"id":"1.187557247","rc":[{"batl":[[0,1.41,10.27],[1,1.42,74.25],[2,1.44,71.83]],"ltp":1.39,"tv":68292.69,"id":10350473}]}]}
{"op":"mcm","clk":"4230518767","pt":1631533876128,"mc":[{"id":"1.187557247","rc":[{"batl":[[0,4.5,78.33],[1,5.5,3.64],[2,990,0.01]],"ltp":3.6,"tv":17796.66,"id":9304761}]}]}
{"op":"mcm","clk":"4230518957","pt":1631533878356,"mc":[{"id":"1.187557247","rc":[{"trd":[[1.37,6]],"batb":[[0,1.28,807.42],[1,1.2,2],[2,1.01,477.35]],"batl":[[0,1.37,399],[1,1.41,10.27],[2,1.42,74.25]],"ltp":1.37,"tv":68298.69,"id":10350473},{"batl":[[0,5.5,3.64],[1,990,0.01],[2,990,0]],"ltp":3.6,"tv":17796.66,"id":9304761}],"tv":86095.35}]}
{"op":"mcm","clk":"4230519061","pt":1631533879446,"mc":[{"id":"1.187557247","rc":[{"batl":[[0,1.37,401]],"ltp":1.37,"tv":68298.69,"id":10350473}]}]}
{"op":"mcm","clk":"4230519111","pt":1631533879912,"mc":[{"id":"1.187557247","rc":[{"batl":[[0,1.37,403]],"ltp":1.37,"tv":68298.69,"id":10350473}]}]}
{"op":"mcm","clk":"4230519288","pt":1631533881659,"mc":[{"id":"1.187557247","rc":[{"batl":[[0,1.37,405.98]],"ltp":1.37,"tv":68298.69,"id":10350473}]}]}
{"op":"mcm","clk":"4230519378","pt":1631533882424,"mc":[{"id":"1.187557247","rc":[{"batl":[[0,1.37,403]],"ltp":1.37,"tv":68298.69,"id":10350473}]}]}
{"op":"mcm","clk":"4230519677","pt":1631533885352,"mc":[{"id":"1.187557247","rc":[{"batl":[[0,1.37,4],[1,1.42,74.25],[2,1.44,71.83]],"ltp":1.37,"tv":68298.69,"id":10350473},{"batb":[[0,3.4,214.75],[1,3.35,3.47],[2,3.25,3.93]],"batl":[[0,5.3,185.71],[1,5.5,3.64],[2,990,0.01]],"ltp":3.6,"tv":17796.66,"id":9304761}]}]}
{"op":"mcm","clk":"4230519830","pt":1631533886763,"mc":[{"id":"1.187557247","rc":[{"batl":[[0,1.3,3],[1,1.37,4],[2,1.42,74.25]],"ltp":1.37,"tv":68298.69,"id":10350473}]}]}
{"op":"mcm","clk":"4230519867","pt":1631533887162,"mc":[{"id":"1.187557247","rc":[{"batl":[[1,1.37,2]],"ltp":1.37,"tv":68298.69,"id":10350473}]}]}
{"op":"mcm","clk":"4230519973","pt":1631533888362,"mc":[{"id":"1.187557247","rc":[{"batl":[[1,1.42,74.25],[2,1.44,71.83]],"ltp":1.37,"tv":68298.69,"id":10350473},{"batb":[[0,3.35,3.47],[1,3.25,3.93],[2,3.1,3.74]],"ltp":3.6,"tv":17796.66,"id":9304761}]}]}
{"op":"mcm","clk":"4230520518","pt":1631533893633,"mc":[{"id":"1.187557247","rc":[{"batl":[[1,1.36,350.87],[2,1.42,74.25]],"ltp":1.37,"tv":68298.69,"id":10350473}]}]}
{"op":"mcm","clk":"4230521007","pt":1631533898369,"mc":[{"id":"1.187557247","rc":[{"trd":[[1.3,47.35]],"batl":[[0,1.36,351.55],[1,1.42,74.25],[2,1.44,71.83]],"ltp":1.3,"tv":68303.33,"id":10350473}],"tv":86100.0}]}
{"op":"mcm","clk":"4230521435","pt":1631533902413,"mc":[{"id":"1.187557247","rc":[{"trd":[[1.3,48.71]],"batb":[[0,1.3,49.32],[1,1.28,807.42],[2,1.2,2]],"batl":[[0,1.36,350.87]],"ltp":1.3,"tv":68304.69,"id":10350473}],"tv":86101.36}]}
{"op":"mcm","clk":"4230522519","pt":1631533912991,"mc":[{"id":"1.187557247","rc":[{"trd":[[1.3,55.43]],"batb":[[0,1.3,45.96]],"ltp":1.3,"tv":68311.41,"id":10350473}],"tv":86108.08}]}
{"op":"mcm","clk":"4230524503","pt":1631533931513,"mc":[{"id":"1.187557247","rc":[{"batb":[[0,1.28,807.42],[1,1.2,2],[2,1.01,477.35]],"ltp":1.3,"tv":68311.41,"id":10350473}]}]}
{"op":"mcm","clk":"4230524833","pt":1631533934639,"mc":[{"id":"1.187557247","rc":[{"trd":[[1.36,1795.5]],"batl":[[0,1.36,304.91]],"ltp":1.36,"tv":68403.33,"id":10350473}],"tv":86200.0}]}
{"op":"mcm","clk":"4230525555","pt":1631533941916,"mc":[{"id":"1.187557247","rc":[{"batl":[[0,5.5,3.64],[1,990,0.01],[2,990,0]],"ltp":3.6,"tv":17796.66,"id":9304761}]}]}
{"op":"mcm","clk":"4230528469","pt":1631533970386,"mc":[{"id":"1.187557247","rc":[{"trd":[[1.36,1801.01]],"batl":[[0,1.36,299.4]],"ltp":1.36,"tv":68408.84,"id":10350473},{"trd":[[3.75,2]],"ltp":3.75,"tv":17798.66,"id":9304761}],"tv":86207.51}]}
{"op":"mcm","clk":"4230528917","pt":1631533975020,"mc":[{"id":"1.187557247","rc":[{"batb":[[2,1.18,70]],"ltp":1.36,"tv":68408.84,"id":10350473}]}]}
{"op":"mcm","clk":"4230529534","pt":1631533981311,"mc":[{"id":"1.187557247","rc":[{"batb":[[0,1.3,98.25],[1,1.28,807.42],[2,1.2,2]],"ltp":1.36,"tv":68408.84,"id":10350473}]}]}
{"op":"mcm","clk":"4230531371","pt":1631533999757,"mc":[{"id":"1.187557247","rc":[{"batb":[[0,1.35,3],[1,1.3,98.25],[2,1.28,807.42]],"ltp":1.36,"tv":68408.84,"id":10350473}]}]}
{"op":"mcm","clk":"4230531791","pt":1631534004150,"mc":[{"id":"1.187557247","rc":[{"batb":[[0,1.3,98.25],[1,1.28,807.42],[2,1.2,2]],"ltp":1.36,"tv":68408.84,"id":10350473}]}]}
{"op":"mcm","clk":"4230533258","pt":1631534018669,"mc":[{"id":"1.187557247","rc":[{"trd":[[1.36,1831.01]],"batl":[[0,1.36,284.4]],"ltp":1.36,"tv":68438.84,"id":10350473}],"tv":86237.51}]}
{"op":"mcm","clk":"4230533438","pt":1631534020391,"mc":[{"id":"1.187557247","rc":[{"batb":[[0,1.35,3],[1,1.3,98.25],[2,1.28,807.42]],"ltp":1.36,"tv":68438.84,"id":10350473}]}]}
{"op":"mcm","clk":"4230534628","pt":1631534031703,"mc":[{"id":"1.187557247","rc":[{"trd":[[1.35,12.19]],"batb":[[0,1.3,98.25],[1,1.28,807.42],[2,1.2,2]],"batl":[[0,1.35,400.23],[1,1.36,284.4],[2,1.42,74.25]],"ltp":1.35,"tv":68446.39,"id":10350473}],"tv":86245.05}]}
{"op":"mcm","clk":"4230534671","pt":1631534032068,"mc":[{"id":"1.187557247","rc":[{"batl":[[0,1.36,284.4],[1,1.42,74.25],[2,1.44,71.83]],"ltp":1.35,"tv":68446.39,"id":10350473}]}]}
{"op":"mcm","clk":"4230534984","pt":1631534034999,"mc":[{"id":"1.187557247","rc":[{"batl":[[0,1.35,2],[1,1.36,284.4],[2,1.42,74.25]],"ltp":1.35,"tv":68446.39,"id":10350473}]}]}
{"op":"mcm","clk":"4230535475","pt":1631534039220,"mc":[{"id":"1.187557247","rc":[{"batl":[[0,1.36,284.4],[1,1.42,74.25],[2,1.44,71.83]],"ltp":1.35,"tv":68446.39,"id":10350473}]}]}
{"op":"mcm","clk":"4230536184","pt":1631534045622,"mc":[{"id":"1.187557247","rc":[{"batl":[[0,1.31,3],[1,1.36,284.4],[2,1.42,74.25]],"ltp":1.35,"tv":68446.39,"id":10350473}]}]}
{"op":"mcm","clk":"4230538033","pt":1631534064937,"mc":[{"id":"1.187557247","rc":[{"batl":[[0,1.36,284.4],[1,1.42,74.25],[2,1.44,71.83]],"ltp":1.35,"tv":68446.39,"id":10350473}]}]}
{"op":"mcm","clk":"4230538613","pt":1631534072041,"mc":[{"id":"1.187557247","rc":[{"trd":[[1.3,86.68]],"batb":[[0,1.3,67]],"ltp":1.3,"tv":68477.64,"id":10350473},{"trd":[[4.4,9.23]],"ltp":4.4,"tv":17807.89,"id":9304761}],"tv":86285.53}]}
{"op":"mcm","clk":"4230538854","pt":1631534074747,"mc":[{"id":"1.187557247","rc":[{"trd":[[1.35,18.19]],"batl":[[0,1.31,4.88],[1,1.36,284.4],[2,1.42,74.25]],"ltp":1.35,"tv":68483.64,"id":10350473}],"tv":86291.53}]}
{"op":"mcm","clk":"4230538874","pt":1631534074952,"mc":[{"id":"1.187557247","rc":[{"batl":[[0,1.36,284.4],[1,1.42,74.25],[2,1.44,71.83]],"ltp":1.35,"tv":68483.64,"id":10350473}]}]}
{"op":"mcm","clk":"4230539037","pt":1631534076658,"mc":[{"id":"1.187557247","rc":[{"batl":[[1,8.8,7.23],[2,44,7.23]],"ltp":1.35,"tv":68483.64,"id":10350473},{"batb":[[0,1.2,2],[1,1.01,123.7],[2,3.1,0]],"batl":[[0,990,0.01],[1,990,0]],"ltp":4.4,"tv":17807.89,"id":9304761}]}]}
{"op":"mcm","clk":"4230539137","pt":1631534077753,"mc":[{"id":"1.187557247","rc":[{"batl":[[0,1.35,402],[1,1.36,284.4],[2,8.8,7.23]],"ltp":1.35,"tv":68483.64,"id":10350473}]}]}
{"op":"mcm","clk":"4230539182","pt":1631534078329,"mc":[{"id":"1.187557247","rc":[{"batl":[[0,1.36,284.4],[1,8.8,7.23],[2,44,7.23]],"ltp":1.35,"tv":68483.64,"id":10350473}]}]}
{"op":"mcm","clk":"4230539377","pt":1631534080674,"mc":[{"id":"1.187557247","rc":[{"batl":[[0,1.33,766.61],[1,1.36,284.4],[2,8.8,7.23]],"ltp":1.35,"tv":68483.64,"id":10350473}]}]}
{"op":"mcm","clk":"4230539473","pt":1631534081759,"mc":[{"id":"1.187557247","rc":[{"trd":[[1.3,90.68]],"batb":[[0,1.3,65]],"ltp":1.3,"tv":68487.63,"id":10350473},{"batb":[[0,2.8,379.97],[1,1.2,2],[2,1.01,123.7]],"batl":[[0,7.8,89.36],[1,990,0.01]],"ltp":4.4,"tv":17807.89,"id":9304761}],"tv":86295.53}]}
{"op":"mcm","clk":"4230539483","pt":1631534081860,"mc":[{"id":"1.187557247","rc":[{"trd":[[1.3,220.68]],"batb":[[0,1.28,807.42],[1,1.2,2],[2,1.18,70]],"batl":[[0,1.3,335],[1,1.33,766.61],[2,1.36,284.4]],"ltp":1.3,"tv":68617.64,"id":10350473}],"tv":86425.54}]}
{"op":"mcm","clk":"4230539672","pt":1631534083630,"mc":[{"id":"1.187557247","rc":[{"trd":[[1.3,890.68]],"batb":[[0,1.31,22.61],[1,1.28,807.42],[2,1.2,2]],"batl":[[0,1.33,766.61],[1,1.35,161.52]],"ltp":1.3,"tv":69287.64,"id":10350473}],"tv":87095.54}]}
{"op":"mcm","clk":"4230539740","pt":1631534084461,"mc":[{"id":"1.187557247","rc":[{"trd":[[1.28,249.4],[1.31,508.67]],"batb":[[0,1.28,727.09],[1,1.2,2],[2,1.18,70]],"ltp":1.28,"tv":69493.52,"id":10350473}],"tv":87301.42}]}
{"op":"mcm","clk":"4230540255","pt":1631534089565,"mc":[{"id":"1.187557247","rc":[{"trd":[[1.28,262.06]],"batb":[[0,1.28,720.76]],"batl":[[1,8.8,7.23],[2,44,7.23]],"ltp":1.28,"tv":69506.18,"id":10350473}],"tv":87314.08}]}
{"op":"mcm","clk":"4230540437","pt":1631534091639,"mc":[{"id":"1.187557247","rc":[{"batb":[[0,1.29,168.65],[1,1.28,720.76],[2,1.21,32.67]],"batl":[[0,1.3,52.41],[1,1.31,104.02],[2,1.32,165.56]],"ltp":1.28,"tv":69506.18,"id":10350473}]}]}
{"op":"mcm","clk":"4230540525","pt":1631534092637,"mc":[{"id":"1.187557247","rc":[{"batl":[[0,1.36,32.77],[1,8.8,7.23],[2,44,7.23]],"ltp":1.28,"tv":69506.18,"id":10350473}]}]}
{"op":"mcm","clk":"4230540562","pt":1631534092946,"mc":[{"id":"1.187557247","rc":[{"batb":[[0,1.28,720.76],[1,1.21,32.67],[2,1.2,2]],"batl":[[0,1.32,284.4],[1,1.36,32.77],[2,8.8,7.23]],"ltp":1.28,"tv":69506.18,"id":10350473}]}]}
{"op":"mcm","clk":"4230540883","pt":1631534096385,"mc":[{"id":"1.187557247","rc":[{"batl":[[1,8.8,7.23],[2,44,7.23]],"ltp":1.28,"tv":69506.18,"id":10350473}]}]}
{"op":"mcm","clk":"4230540962","pt":1631534097162,"mc":[{"id":"1.187557247","rc":[{"batl":[[0,8.8,7.23],[1,44,7.23],[2,50,7.23]],"ltp":1.28,"tv":69506.18,"id":10350473}]}]}
{"op":"mcm","clk":"4230541067","pt":1631534098152,"mc":[{"id":"1.187557247","rc":[{"batl":[[0,990,0.01],[1,990,0]],"ltp":4.4,"tv":17807.89,"id":9304761}]}]}
{"op":"mcm","clk":"4230541266","pt":1631534100381,"mc":[{"id":"1.187557247","rc":[{"batb":[[1,1.2,2],[2,1.18,70]],"batl":[[0,1.29,15.5],[1,8.8,7.23],[2,44,7.23]],"ltp":1.28,"tv":69506.18,"id":10350473}]}]}
{"op":"mcm","clk":"4230541404","pt":1631534101688,"mc":[{"id":"1.187557247","rc":[{"trd":[[1.29,51.26]],"batb":[[0,1.32,751.11],[1,1.28,720.76],[2,1.2,2]],"batl":[[0,8.8,7.23],[1,44,7.23],[2,50,7.23]],"ltp":1.29,"tv":69537.19,"id":10350473},{"batl":[[0,6.6,100.59],[1,990,0.01]],"ltp":4.4,"tv":17807.89,"id":9304761}],"tv":87345.08}]}
{"op":"mcm","clk":"4230541507","pt":1631534102683,"mc":[{"id":"1.187557247","rc":[{"batb":[[0,1.28,720.76],[1,1.2,2],[2,1.18,70]],"ltp":1.29,"tv":69537.19,"id":10350473}]}]}
{"op":"mcm","clk":"4230541588","pt":1631534103368,"mc":[{"id":"1.187557247","rc":[{"batb":[[0,1.28,782.56]],"batl":[[0,1.29,218.16],[1,1.3,80.05],[2,8.8,7.23]],"ltp":1.29,"tv":69537.19,"id":10350473}]}]}
{"op":"mcm","clk":"4230541659","pt":1631534104199,"mc":[{"id":"1.187557247","rc":[{"batb":[[1,1.27,70.62],[2,1.2,2]],"ltp":1.29,"tv":69537.19,"id":10350473}]}]}
{"op":"mcm","clk":"4230542086","pt":1631534108490,"mc":[{"id":"1.187557247","rc":[{"batb":[[0,1.28,720.76],[1,1.2,2],[2,1.18,70]],"batl":[[0,8.8,7.23],[1,44,7.23],[2,50,7.23]],"ltp":1.29,"tv":69537.19,"id":10350473}]}]}
{"op":"mcm","clk":"4230542127","pt":1631534108857,"mc":[{"id":"1.187557247","rc":[{"batb":[[0,1.28,721.07]],"ltp":1.29,"tv":69537.19,"id":10350473}]}]}
{"op":"mcm","clk":"4230542416","pt":1631534111679,"mc":[{"id":"1.187557247","rc":[{"batl":[[0,1.75,975.09],[1,8.8,7.23],[2,44,7.23]],"ltp":1.29,"tv":69537.19,"id":10350473},{"batb":[[1,1.21,9.28],[2,1.2,2]],"batl":[[0,6.4,383.55],[1,6.6,100.59],[2,990,0.01]],"ltp":4.4,"tv":17807.89,"id":9304761}]}]}
{"op":"mcm","clk":"4230542521","pt":1631534112673,"mc":[{"id":"1.187557247","rc":[{"batl":[[0,8.8,7.23],[1,44,7.23],[2,50,7.23]],"ltp":1.29,"tv":69537.19,"id":10350473}]}]}
{"op":"mcm","clk":"4230542563","pt":1631534113189,"mc":[{"id":"1.187557247","rc":[{"batl":[[0,6.6,101.28],[1,990,0.01],[2,990,0]],"ltp":4.4,"tv":17807.89,"id":9304761}]}]}
{"op":"mcm","clk":"4230543237","pt":1631534120297,"mc":[{"id":"1.187557247","rc":[{"batb":[[1,1.2,2],[2,1.01,123.7]],"ltp":4.4,"tv":17807.89,"id":9304761}]}]}
{"op":"mcm","clk":"4230543389","pt":1631534121717,"mc":[{"id":"1.187557247","rc":[{"batb":[[0,1.2,2],[1,1.01,123.7],[2,1.01,0]],"batl":[[0,990,0.7],[1,990,0]],"ltp":4.4,"tv":17807.89,"id":9304761}]}]}
{"op":"mcm","clk":"4230543625","pt":1631534123708,"mc":[{"id":"1.187557247","rc":[{"batl":[[0,1.55,26.15],[1,8.8,7.23],[2,44,7.23]],"ltp":1.29,"tv":69537.19,"id":10350473},{"batl":[[0,6.4,324.15],[1,990,0.01]],"ltp":4.4,"tv":17807.89,"id":9304761}]}]}
{"op":"mcm","clk":"4230543715","pt":1631534124495,"mc":[{"id":"1.187557247","rc":[{"batb":[[0,1.32,766.61],[1,1.28,721.07],[2,1.2,2]],"batl":[[0,1.37,14.6],[1,1.55,26.15],[2,8.8,7.23]],"ltp":1.29,"tv":69537.19,"id":10350473}]}]}
{"op":"mcm","clk":"4230543831","pt":1631534125587,"mc":[{"id":"1.187557247","rc":[{"batb":[[0,1.32,1533.22]],"ltp":1.29,"tv":69537.19,"id":10350473},{"batb":[[0,2.38,386.87],[1,1.2,2],[2,1.01,123.7]],"batl":[[0,5.3,121.45]],"ltp":4.4,"tv":17807.89,"id":9304761}]}]}
{"op":"mcm","clk":"4230543952","pt":1631534126684,"mc":[{"id":"1.187557247","rc":[{"batb":[[1,1.29,795.98],[2,1.28,720.76]],"ltp":1.29,"tv":69537.19,"id":10350473}]}]}
{"op":"mcm","clk":"4230544024","pt":1631534127408,"mc":[{"id":"1.187557247","rc":[{"trd":[[1.32,10154.81]],"batb":[[0,1.32,1486.64],[1,1.3,69.51]],"batl":[[0,1.33,46.11],[1,1.34,61.01],[2,1.35,77.72]],"ltp":1.32,"tv":69630.34,"id":10350473}],"tv":87438.24}]}
{"op":"mcm","clk":"4230544145","pt":1631534128713,"mc":[{"id":"1.187557247","rc":[{"trd":[[1.33,117.19],[1.34,61.01],[1.35,74.97]],"batb":[[2,1.29,60.96]],"batl":[[0,1.35,20.94],[1,1.36,79.55],[2,1.37,14.6]],"ltp":1.35,"tv":69794.24,"id":10350473},{"trd":[[3.85,19.91],[3.9,20.96],[4,15.33]],"batl":[[0,5.2,166.94],[1,5.3,120.75],[2,990,0.01]],"ltp":3.85,"tv":17864.09,"id":9304761}],"tv":87658.34}]}
{"op":"mcm","clk":"4230544221","pt":1631534129520,"mc":[{"id":"1.187557247","rc":[{"batb":[[0,2.78,4.66],[1,2.5,5.56],[2,2.38,386.87]],"batl":[[0,5.3,121.45],[1,990,0.01],[2,990,0]],"ltp":3.85,"tv":17864.09,"id":9304761}]}]}
{"op":"mcm","clk":"4230544304","pt":1631534130404,"mc":[{"id":"1.187557247","rc":[{"batb":[[0,1.3,69.51],[1,1.29,60.96],[2,1.28,720.76]],"ltp":1.35,"tv":69794.24,"id":10350473}]}]}
{"op":"mcm","clk":"4230544377","pt":1631534131092,"mc":[{"id":"1.187557247","rc":[{"batb":[[2,2.48,5.26]],"ltp":3.85,"tv":17864.09,"id":9304761}]}]}
{"op":"mcm","clk":"4230544510","pt":1631534132410,"mc":[{"id":"1.187557247","rc":[{"batb":[[0,1.28,720.76],[1,1.2,2],[2,1.18,70]],"batl":[[0,1.37,14.6],[1,1.55,26.15],[2,1.56,55.92]],"ltp":1.35,"tv":69794.24,"id":10350473}]}]}
{"op":"mcm","clk":"4230544629","pt":1631534133520,"mc":[{"id":"1.187557247","rc":[{"batb":[[0,1.35,66.96],[1,1.28,720.76],[2,1.2,2]],"ltp":1.35,"tv":69794.24,"id":10350473},{"batb":[[1,2.56,232.48],[2,2.5,5.56]],"ltp":3.85,"tv":17864.09,"id":9304761}]}]}
{"op":"mcm","clk":"4230544830","pt":1631534135509,"mc":[{"id":"1.187557247","rc":[{"trd":[[1.37,52.85]],"batb":[[1,1.32,11.64],[2,1.28,720.76]],"batl":[[0,1.54,9.61]],"ltp":1.37,"tv":69841.09,"id":10350473},{"batb":[[1,2.5,5.56],[2,2.48,5.26]],"ltp":3.85,"tv":17864.09,"id":9304761}],"tv":87705.19}]}
{"op":"mcm","clk":"4230545047","pt":1631534137721,"mc":[{"id":"1.187557247","rc":[{"batb":[[0,1.35,79.98]],"ltp":1.37,"tv":69841.09,"id":10350473}]}]}
{"op":"mcm","clk":"4230545151","pt":1631534138714,"mc":[{"id":"1.187557247","rc":[{"trd":[[1.35,195.69]],"batb":[[0,1.35,19.62]],"batl":[[0,1.53,18.08],[1,1.54,9.61],[2,1.55,26.15]],"ltp":1.35,"tv":69961.81,"id":10350473}],"tv":87825.91}]}
{"op":"mcm","clk":"4230545214","pt":1631534139244,"mc":[{"id":"1.187557247","rc":[{"batb":[[0,2.38,386.87],[1,1.2,2],[2,1.01,123.7]],"ltp":3.85,"tv":17864.09,"id":9304761}]}]}
{"op":"mcm","clk":"4230545438","pt":1631534141643,"mc":[{"id":"1.187557247","rc":[{"batl":[[0,1.53,252.86]],"ltp":1.35,"tv":69961.81,"id":10350473},{"batb":[[0,2.9,132.51],[1,2.38,386.87],[2,1.2,2]],"ltp":3.85,"tv":17864.09,"id":9304761}]}]}
{"op":"mcm","clk":"4230545467","pt":1631534142063,"mc":[{"id":"1.187557247","rc":[{"batl":[[0,1.53,18.08]],"ltp":1.35,"tv":69961.81,"id":10350473},{"batb":[[0,2.38,386.87],[1,1.2,2],[2,1.01,123.7]],"ltp":3.85,"tv":17864.09,"id":9304761}]}]}
{"op":"mcm","clk":"4230545781","pt":1631534145368,"mc":[{"id":"1.187557247","rc":[{"batb":[[1,1.28,720.76],[2,1.2,2]],"ltp":1.35,"tv":69961.81,"id":10350473}]}]}
{"op":"mcm","clk":"4230545874","pt":1631534146248,"mc":[{"id":"1.187557247","rc":[{"batl":[[2,1.66,52.75]],"ltp":1.35,"tv":69961.81,"id":10350473},{"batb":[[0,1.2,2],[1,1.01,123.7],[2,1.01,0]],"batl":[[0,990,0.7],[1,990,0]],"ltp":3.85,"tv":17864.09,"id":9304761}]}]}
{"op":"mcm","clk":"4230546100","pt":1631534148682,"mc":[{"id":"1.187557247","rc":[{"trd":[[1.35,226.45]],"batb":[[0,1.35,4.24]],"ltp":1.35,"tv":69992.57,"id":10350473},{"batb":[[0,3.8,1045.35],[1,3.65,125.34],[2,3.6,62.67]],"ltp":3.85,"tv":17864.09,"id":9304761}],"tv":87856.67}]}
{"op":"mcm","clk":"4230546172","pt":1631534149455,"mc":[{"id":"1.187557247","rc":[{"batl":[[0,1.52,26.15],[1,1.53,18.08]],"ltp":1.35,"tv":69992.57,"id":10350473},{"batl":[[0,4.3,68.31],[1,4.4,34.86],[2,4.5,34.16]],"ltp":3.85,"tv":17864.09,"id":9304761}]}]}
{"op":"mcm","clk":"4230546265","pt":1631534150502,"mc":[{"id":"1.187557247","rc":[{"batl":[[0,1.42,766.61],[1,1.52,26.15],[2,1.53,18.08]],"ltp":1.35,"tv":69992.57,"id":10350473}]}]}
{"op":"mcm","clk":"4230546384","pt":1631534151704,"mc":[{"id":"1.187557247","rc":[{"batl":[[0,1.52,26.15],[1,1.53,18.08],[2,1.66,52.75]],"ltp":1.35,"tv":69992.57,"id":10350473}]}]}
{"op":"mcm","clk":"4230546573","pt":1631534153289,"mc":[{"id":"1.187557247","rc":[{"trd":[[1.35,234.92]],"batb":[[0,1.28,720.76],[1,1.2,2],[2,1.18,70]],"ltp":1.35,"tv":70001.04,"id":10350473}],"tv":87865.14}]}
{"op":"mcm","clk":"4230546666","pt":1631534154081,"mc":[{"id":"1.187557247","rc":[{"batl":[[0,1.35,362.75],[1,1.52,26.15],[2,1.53,18.08]],"ltp":1.35,"tv":70001.04,"id":10350473}]}]}
{"op":"mcm","clk":"4230546802","pt":1631534155286,"mc":[{"id":"1.187557247","rc":[{"batl":[[1,1.52,93.16],[2,1.6,54.51]],"ltp":1.35,"tv":70001.04,"id":10350473}]}]}
{"op":"mcm","clk":"4230546945","pt":1631534156788,"mc":[{"id":"1.187557247","rc":[{"batl":[[1,1.48,58.49],[2,1.52,93.16]],"ltp":1.35,"tv":70001.04,"id":10350473}]}]}
{"op":"mcm","clk":"4230547141","pt":1631534158815,"mc":[{"id":"1.187557247","rc":[{"batl":[[2,1.52,67.01]],"ltp":1.35,"tv":70001.04,"id":10350473}]}]}
{"op":"mcm","clk":"4230547303","pt":1631534160491,"mc":[{"id":"1.187557247","rc":[{"batb":[[0,1.33,6.69],[1,1.32,13.47],[2,1.31,20.36]],"batl":[[0,1.34,58.99],[1,1.35,362.75],[2,1.47,12.11]],"ltp":1.35,"tv":70001.04,"id":10350473}]}]}
{"op":"mcm","clk":"4230547402","pt":1631534161490,"mc":[{"id":"1.187557247","rc":[{"batb":[[0,3.05,4.29],[1,2.92,4.69],[2,2.78,4.66]],"batl":[[0,6.6,99.63],[1,990,0.01],[2,4.5,0]],"ltp":3.85,"tv":17864.09,"id":9304761}]}]}
{"op":"mcm","clk":"4230547429","pt":1631534161801,"mc":[{"id":"1.187557247","rc":[{"batb":[[0,2.92,4.69],[1,2.78,4.66],[2,2.66,5.78]],"ltp":3.85,"tv":17864.09,"id":9304761}]}]}
{"op":"mcm","clk":"4230547743","pt":1631534165128,"mc":[{"id":"1.187557247","rc":[{"batb":[[0,3.05,3.89],[1,2.92,4.69],[2,2.78,4.66]],"ltp":3.85,"tv":17864.09,"id":9304761}]}]}
{"op":"mcm","clk":"4230548206","pt":1631534170629,"mc":[{"id":"1.187557247","rc":[{"batl":[[0,1.47,12.11],[1,1.56,57.92],[2,1.66,52.75]],"ltp":1.35,"tv":70001.04,"id":10350473},{"batb":[[0,2.78,4.66],[1,2.62,387.97],[2,1.2,2]],"ltp":3.85,"tv":17864.09,"id":9304761}]}]}
{"op":"mcm","clk":"4230548231","pt":1631534170942,"mc":[{"id":"1.187557247","rc":[{"batb":[[0,1.28,720.76],[1,1.21,9.14],[2,1.2,2]],"ltp":1.35,"tv":70001.04,"id":10350473}]}]}
{"op":"mcm","clk":"4230548482","pt":1631534173705,"mc":[{"id":"1.187557247","rc":[{"batl":[[0,1.33,362.75],[1,1.47,12.11],[2,1.56,57.92]],"ltp":1.35,"tv":70001.04,"id":10350473}]}]}
{"op":"mcm","clk":"4230548553","pt":1631534174640,"mc":[{"id":"1.187557247","rc":[{"batb":[[0,1.34,30],[1,1.28,720.76],[2,1.21,9.14]],"batl":[[0,1.47,12.11],[1,1.56,57.92],[2,1.66,52.75]],"ltp":1.35,"tv":70001.04,"id":10350473}]}]}
{"op":"mcm","clk":"4230548683","pt":1631534176119,"mc":[{"id":"1.187557247","rc":[{"batb":[[0,1.28,720.76],[1,1.21,9.14],[2,1.2,2]],"ltp":1.35,"tv":70001.04,"id":10350473}]}]}
{"op":"mcm","clk":"4230548809","pt":1631534177731,"mc":[{"id":"1.187557247","rc":[{"batl":[[0,1.56,57.92],[1,1.66,52.75],[2,1.99,29.05]],"ltp":1.35,"tv":70001.04,"id":10350473}]}]}
{"op":"mcm","clk":"4230548915","pt":1631534179044,"mc":[{"id":"1.187557247","rc":[{"batl":[[0,990,0.7],[1,990,0]],"ltp":3.85,"tv":17864.09,"id":9304761}]}]}
{"op":"mcm","clk":"4230549047","pt":1631534180722,"mc":[{"id":"1.187557247","rc":[{"batl":[[0,3.25,144.62],[1,3.3,72.3],[2,3.35,72.3]],"ltp":3.85,"tv":17864.09,"id":9304761}]}]}
{"op":"mcm","clk":"4230549128","pt":1631534181651,"mc":[{"id":"1.187557247","rc":[{"trd":[[1.43,64.3],[1.44,2029.98]],"batb":[[0,1.35,766.61],[1,1.28,720.76]],"ltp":1.43,"tv":70378.08,"id":10350473},{"trd":[[3.25,144.62],[3.3,22.66]],"batb":[[0,3,19.58],[1,2.98,88.65],[2,2.96,49.22]],"batl":[[0,3.3,50.36],[1,3.35,72.3],[2,3.55,1323.94]],"ltp":3.3,"tv":18030.65,"id":9304761}],"tv":88408.74}]}
{"op":"mcm","clk":"4230549191","pt":1631534182546,"mc":[{"id":"1.187557247","rc":[{"batb":[[1,1.3,766.61],[2,1.28,720.76]],"ltp":1.43,"tv":70378.08,"id":10350473}]}]}
{"op":"mcm","clk":"4230549479","pt":1631534185326,"mc":[{"id":"1.187557247","rc":[{"trd":[[1.43,102.22]],"ltp":1.43,"tv":70416.0,"id":10350473},{"trd":[[3.3,39.09]],"batl":[[0,3.3,33.93]],"ltp":3.3,"tv":18047.08,"id":9304761}],"tv":88463.09}]}
{"op":"mcm","clk":"4230549650","pt":1631534187518,"mc":[{"id":"1.187557247","rc":[{"batb":[[0,1.35,1668.57]],"batl":[[0,1.55,500.18],[1,1.56,57.92],[2,1.66,52.75]],"ltp":1.43,"tv":70416.0,"id":10350473}]}]}
{"op":"mcm","clk":"4230550111","pt":1631534192453,"mc":[{"id":"1.187557247","rc":[{"trd":[[1.43,115.24],[1.5,1789.44]],"batb":[[1,1.31,11.27],[2,1.3,766.61]],"batl":[[2,1.65,10.38]],"ltp":1.43,"tv":70459.02,"id":10350473},{"trd":[[3,15],[3.3,44.73]],"batb":[[0,3,4.58]],"batl":[[0,3.3,28.29]],"ltp":3.3,"tv":18067.72,"id":9304761}],"tv":88526.75}]}
{"op":"mcm","clk":"4230550266","pt":1631534194230,"mc":[{"id":"1.187557247","rc":[{"batb":[[0,1.35,766.61]],"ltp":1.43,"tv":70459.02,"id":10350473}]}]}
{"op":"mcm","clk":"4230550475","pt":1631534196475,"mc":[{"id":"1.187557247","rc":[{"trd":[[1.5,1791.76]],"ltp":1.5,"tv":70461.34,"id":10350473},{"trd":[[3,16.16]],"batb":[[0,3,3.42]],"ltp":3.0,"tv":18068.88,"id":9304761}],"tv":88530.23}]}
{"op":"mcm","clk":"4230550552","pt":1631534197345,"mc":[{"id":"1.187557247","rc":[{"batb":[[0,1.35,2337.7]],"ltp":1.5,"tv":70461.34,"id":10350473}]}]}
{"op":"mcm","clk":"4230550602","pt":1631534197971,"mc":[{"id":"1.187557247","rc":[{"batb":[[0,1.35,1571.09],[2,1.28,720.76]],"ltp":1.5,"tv":70461.34,"id":10350473}]}]}
{"op":"mcm","clk":"4230550843","pt":1631534200761,"mc":[{"id":"1.187557247","rc":[{"batb":[[0,2.78,4.66],[1,2.62,387.97],[2,2.44,5.42]],"batl":[[0,4.9,126.79],[1,990,0.01],[2,3.55,0]],"ltp":3.0,"tv":18068.88,"id":9304761}]}]}
{"op":"mcm","clk":"4230550865","pt":1631534200988,"mc":[{"id":"1.187557247","rc":[{"batb":[[0,1.31,11.27],[1,1.28,720.76],[2,1.2,2]],"batl":[[0,1.65,10.38],[1,1.69,60.5],[2,1.8,49.42]],"ltp":1.5,"tv":70461.34,"id":10350473},{"batb":[[0,2.62,387.97],[1,2.44,5.42],[2,2.24,7.02]],"ltp":3.0,"tv":18068.88,"id":9304761}]}]}
{"op":"mcm","clk":"4230551012","pt":1631534202561,"mc":[{"id":"1.187557247","rc":[{"batb":[[0,1.35,2.32],[1,1.31,11.27],[2,1.28,720.76]],"ltp":1.5,"tv":70461.34,"id":10350473}]}]}
{"op":"mcm","clk":"4230551222","pt":1631534204656,"mc":[{"id":"1.187557247","rc":[{"batl":[[0,1.69,60.5],[1,1.8,49.42],[2,1.99,29.05]],"ltp":1.5,"tv":70461.34,"id":10350473}]}]}
{"op":"mcm","clk":"4230551518","pt":1631534207552,"mc":[{"id":"1.187557247","rc":[{"batb":[[0,1.43,19.43],[1,1.35,2.32],[2,1.31,11.27]],"batl":[[0,1.48,20.24],[1,1.69,60.5],[2,1.8,49.42]],"ltp":1.5,"tv":70461.34,"id":10350473},{"batl":[[0,3.35,18.9],[1,4.9,126.79],[2,990,0.01]],"ltp":3.0,"tv":18068.88,"id":9304761}]}]}
{"op":"mcm","clk":"4230551548","pt":1631534207868,"mc":[{"id":"1.187557247","rc":[{"batb":[[0,1.35,2.32],[1,1.31,11.27],[2,1.28,720.76]],"batl":[[0,1.69,60.5],[1,1.8,49.42],[2,1.99,29.05]],"ltp":1.5,"tv":70461.34,"id":10350473},{"batl":[[0,4.9,126.79],[1,990,0.01],[2,990,0]],"ltp":3.0,"tv":18068.88,"id":9304761}]}]}
{"op":"mcm","clk":"4230551728","pt":1631534209764,"mc":[{"id":"1.187557247","rc":[{"batb":[[0,1.37,766.61],[1,1.35,2.32],[2,1.31,11.27]],"batl":[[1,1.79,10.94],[2,1.8,49.42]],"ltp":1.5,"tv":70461.34,"id":10350473}]}]}
{"op":"mcm","clk":"4230553469","pt":1631534228590,"mc":[{"id":"1.187557247","rc":[{"batl":[[1,1.8,49.42],[2,1.99,29.05]],"ltp":1.5,"tv":70461.34,"id":10350473},{"trd":[[2.62,52.09]],"batb":[[0,2.62,363.9]],"ltp":2.62,"tv":18117.01,"id":9304761}],"tv":88578.36}]}
{"op":"mcm","clk":"4230553690","pt":1631534230678,"mc":[{"id":"1.187557247","rc":[{"batl":[[0,1.8,49.42],[1,1.99,29.05],[2,8.8,7.23]],"ltp":1.5,"tv":70461.34,"id":10350473},{"batb":[[0,2.24,7.02],[1,1.2,2],[2,1.01,123.7]],"batl":[[0,990,0.7],[1,990,0]],"ltp":2.62,"tv":18117.01,"id":9304761}]}]}
{"op":"mcm","clk":"4230553778","pt":1631534231686,"mc":[{"id":"1.187557247","rc":[{"batb":[[0,1.6,1623.25],[1,1.37,766.61],[2,1.35,2.32]],"ltp":1.5,"tv":70461.34,"id":10350473},{"batb":[[0,2.48,473.79],[1,2.46,236.9],[2,2.44,236.9]],"batl":[[0,2.66,530.08],[1,2.68,265.04],[2,2.7,265.04]],"ltp":2.62,"tv":18117.01,"id":9304761}]}]}
{"op":"mcm","clk":"4230553832","pt":1631534232197,"mc":[{"id":"1.187557247","rc":[{"trd":[[1.6,259.34]],"batb":[[0,1.6,1610.43]],"ltp":1.6,"tv":70486.98,"id":10350473},{"batb":[[0,2.48,118.45],[1,2.46,59.22],[2,2.44,59.22]],"ltp":2.62,"tv":18117.01,"id":9304761}],"tv":88604.0}]}
{"op":"mcm","clk":"4230553945","pt":1631534233408,"mc":[{"id":"1.187557247","rc":[{"batb":[[1,1.54,766.61],[2,1.37,766.61]],"ltp":1.6,"tv":70486.98,"id":10350473}]}]}
{"op":"mcm","clk":"4230554047","pt":1631534234407,"mc":[{"id":"1.187557247","rc":[{"batb":[[1,1.37,766.61],[2,1.35,2.32]],"ltp":1.6,"tv":70486.98,"id":10350473}]}]}
{"op":"mcm","clk":"4230554366","pt":1631534237582,"mc":[{"id":"1.187557247","rc":[{"batl":[[0,1.77,61.5],[1,1.8,49.42],[2,1.84,57.53]],"ltp":1.6,"tv":70486.98,"id":10350473}]}]}
{"op":"mcm","clk":"4230554564","pt":1631534239573,"mc":[{"id":"1.187557247","rc":[{"batl":[[0,1.76,65.52],[1,1.77,61.5],[2,1.8,49.42]],"ltp":1.6,"tv":70486.98,"id":10350473}]}]}
{"op":"mcm","clk":"4230554670","pt":1631534240670,"mc":[{"id":"1.187557247","rc":[{"batl":[[2,1.79,792.11]],"ltp":1.6,"tv":70486.98,"id":10350473}]}]}
{"op":"mcm","clk":"4230554690","pt":1631534240824,"mc":[{"id":"1.187557247","rc":[{"batl":[[2,1.8,49.42]],"ltp":1.6,"tv":70486.98,"id":10350473}]}]}
{"op":"mcm","clk":"4230554919","pt":1631534243491,"mc":[{"id":"1.187557247","rc":[{"batb":[[1,1.38,12.45],[2,1.37,766.61]],"batl":[[2,1.79,10.78]],"ltp":1.6,"tv":70486.98,"id":10350473}]}]}
{"op":"mcm","clk":"4230555004","pt":1631534244407,"mc":[{"id":"1.187557247","rc":[{"trd":[[1.6,359.34]],"batb":[[0,1.6,1560.43]],"batl":[[0,1.76,926.87]],"ltp":1.6,"tv":70586.98,"id":10350473}],"tv":88704.0}]}
{"op":"mcm","clk":"4230555294","pt":1631534247482,"mc":[{"id":"1.187557247","rc":[{"trd":[[2.48,36.11]],"batb":[[0,2.48,103.99]],"ltp":2.48,"tv":18145.94,"id":9304761}],"tv":88732.93}]}
{"op":"mcm","clk":"4230555758","pt":1631534252306,"mc":[{"id":"1.187557247","rc":[{"trd":[[1.6,368.7]],"batb":[[0,1.6,1555.75]],"ltp":1.6,"tv":70596.34,"id":10350473}],"tv":88742.29}]}
{"op":"mcm","clk":"4230555907","pt":1631534253817,"mc":[{"id":"1.187557247","rc":[{"batb":[[2,1.35,2.32]],"ltp":1.6,"tv":70596.34,"id":10350473}]}]}
{"op":"mcm","clk":"4230556028","pt":1631534255225,"mc":[{"id":"1.187557247","rc":[{"trd":[[2.66,41.57]],"batl":[[0,2.66,511.83]],"ltp":2.66,"tv":18182.44,"id":9304761}],"tv":88778.79}]}
{"op":"mcm","clk":"4230556192","pt":1631534256903,"mc":[{"id":"1.187557247","rc":[{"trd":[[1.68,37.55]],"ltp":1.68,"tv":70598.9,"id":10350473},{"trd":[[2.48,37.84]],"batb":[[0,2.48,102.26]],"ltp":2.48,"tv":18184.17,"id":9304761}],"tv":88783.08}]}
{"op":"mcm","clk":"4230556894","pt":1631534264620,"mc":[{"id":"1.187557247","rc":[{"batb":[[0,1.38,12.45],[1,1.35,2.32],[2,1.28,720.76]],"batl":[[0,1.79,10.78],[1,1.8,38],[2,1.82,62.75]],"ltp":1.68,"tv":70598.9,"id":10350473},{"batb":[[0,2.2,7.02],[1,2.18,6.86],[2,2.1,8.04]],"batl":[[0,3.9,171.51],[1,990,0.7],[2,2.7,0]],"ltp":2.48,"tv":18184.17,"id":9304761}]}]}
{"op":"mcm","clk":"4230556924","pt":1631534264938,"mc":[{"id":"1.187557247","rc":[{"batl":[[2,1.9,53.95]],"ltp":1.68,"tv":70598.9,"id":10350473},{"batb":[[0,2.1,8.04],[1,2.04,380.37],[2,1.2,2]],"ltp":2.48,"tv":18184.17,"id":9304761}]}]}
{"op":"mcm","clk":"4230557081","pt":1631534266549,"mc":[{"id":"1.187557247","rc":[{"batl":[[0,1.6,2.5],[1,1.79,10.78],[2,1.8,38]],"ltp":1.68,"tv":70598.9,"id":10350473}]}]}
{"op":"mcm","clk":"4230557559","pt":1631534271614,"mc":[{"id":"1.187557247","rc":[{"batl":[[0,1.79,10.78],[1,1.8,38],[2,1.9,53.95]],"ltp":1.68,"tv":70598.9,"id":10350473},{"batb":[[0,2.2,6.52],[1,2.1,8.04],[2,2.04,380.37]],"ltp":2.48,"tv":18184.17,"id":9304761}]}]}
{"op":"mcm","clk":"4230557585","pt":1631534271935,"mc":[{"id":"1.187557247","rc":[{"batb":[[0,2.1,8.04],[1,2.04,380.37],[2,1.2,2]],"ltp":2.48,"tv":18184.17,"id":9304761}]}]}
{"op":"mcm","clk":"4230557836","pt":1631534274745,"mc":[{"id":"1.187557247","rc":[{"batl":[[0,1.75,4.26],[1,1.79,10.78],[2,1.8,38]],"ltp":1.68,"tv":70598.9,"id":10350473}]}]}
{"op":"mcm","clk":"4230557906","pt":1631534275541,"mc":[{"id":"1.187557247","rc":[{"batb":[[0,1.39,4.43],[1,1.38,12.45],[2,1.35,2.32]],"ltp":1.68,"tv":70598.9,"id":10350473}]}]}
{"op":"mcm","clk":"4230558806","pt":1631534285645,"mc":[{"id":"1.187557247","rc":[{"batl":[[1,1.8,38],[2,1.9,53.95]],"ltp":1.68,"tv":70598.9,"id":10350473}]}]}
{"op":"mcm","clk":"4230558970","pt":1631534287542,"mc":[{"id":"1.187557247","rc":[{"batb":[[1,1.2,2],[2,1.01,123.7]],"batl":[[0,990,0.7],[1,990,0]],"ltp":2.48,"tv":18184.17,"id":9304761}]}]}
{"op":"mcm","clk":"4230559068","pt":1631534288659,"mc":[{"id":"1.187557247","rc":[{"trd":[[1.75,241.91]],"batb":[[0,1.74,1352.85],[1,1.39,4.43],[2,1.38,12.45]],"batl":[[0,1.8,38],[1,1.9,53.95],[2,990,0.01]],"ltp":1.75,"tv":70603.16,"id":10350473},{"trd":[[2.32,6.15]],"batl":[[0,2.3,613.04],[1,2.32,306.53],[2,2.34,306.53]],"ltp":2.32,"tv":18187.38,"id":9304761}],"tv":88790.54}]}
{"op":"mcm","clk":"4230559147","pt":1631534289550,"mc":[{"id":"1.187557247","rc":[{"trd":[[1.76,2392.86]],"batb":[[2,1.35,2.32]],"batl":[[1,1.86,157.93],[2,1.87,78.96]],"ltp":1.76,"tv":70614.99,"id":10350473},{"trd":[[2.3,9.05]],"batl":[[0,2.3,603.99]],"ltp":2.3,"tv":18196.43,"id":9304761}],"tv":88811.42}]}
{"op":"mcm","clk":"4230559247","pt":1631534290666,"mc":[{"id":"1.187557247","rc":[{"batb":[[1,1.6,596.25],[2,1.39,4.43]],"ltp":1.76,"tv":70614.99,"id":10350473}]}]}
{"op":"mcm","clk":"4230559299","pt":1631534291249,"mc":[{"id":"1.187557247","rc":[{"batb":[[1,1.86,383.76],[2,1.2,2]],"ltp":2.3,"tv":18196.43,"id":9304761}]}]}
{"op":"mcm","clk":"4230559406","pt":1631534292452,"mc":[{"id":"1.187557247","rc":[{"batb":[[0,1.77,50.23],[1,1.76,72.71],[2,1.74,1352.85]],"batl":[[0,1.78,70.24],[1,1.8,38],[2,1.86,157.93]],"ltp":1.76,"tv":70614.99,"id":10350473}]}]}
{"op":"mcm","clk":"4230559499","pt":1631534293339,"mc":[{"id":"1.187557247","rc":[{"batb":[[2,1.75,71.87]],"batl":[[1,1.79,70.57],[2,1.8,38]],"ltp":1.76,"tv":70614.99,"id":10350473},{"trd":[[2.3,14.51]],"batl":[[0,2.3,601.26]],"ltp":2.3,"tv":18201.89,"id":9304761}],"tv":88816.89}]}
{"op":"mcm","clk":"4230559588","pt":1631534294281,"mc":[{"id":"1.187557247","rc":[{"batb":[[0,2.1,1088.04]],"ltp":2.3,"tv":18201.89,"id":9304761}]}]}
{"op":"mcm","clk":"4230559645","pt":1631534294871,"mc":[{"id":"1.187557247","rc":[{"batb":[[1,1.9,59.86],[2,1.86,383.76]],"ltp":2.3,"tv":18201.89,"id":9304761}]}]}
{"op":"mcm","clk":"4230559806","pt":1631534296498,"mc":[{"id":"1.187557247","rc":[{"trd":[[1.77,29.24]],"batb":[[0,1.77,47.73]],"ltp":1.77,"tv":70619.99,"id":10350473},{"batb":[[0,2.1,8.04]],"ltp":2.3,"tv":18201.89,"id":9304761}],"tv":88821.89}]}
{"op":"mcm","clk":"4230559858","pt":1631534297187,"mc":[{"id":"1.187557247","rc":[{"trd":[[1.77,30.01]],"batb":[[0,1.77,47.34]],"ltp":1.77,"tv":70620.76,"id":10350473}],"tv":88822.66}]}
{"op":"mcm","clk":"4230560060","pt":1631534299661,"mc":[{"id":"1.187557247","rc":[{"batb":[[0,2.12,554.06],[1,2.1,8.04],[2,1.9,59.86]],"ltp":2.3,"tv":18201.89,"id":9304761}]}]}
{"op":"mcm","clk":"4230560156","pt":1631534300669,"mc":[{"id":"1.187557247","rc":[{"batb":[[0,1.74,1352.85],[1,1.4,10.27],[2,1.39,4.43]],"batl":[[0,1.8,38],[1,1.85,10.26],[2,1.86,157.93]],"ltp":1.77,"tv":70620.76,"id":10350473}]}]}
{"op":"mcm","clk":"4230560204","pt":1631534301253,"mc":[{"id":"1.187557247","rc":[{"batb":[[0,2.1,8.04],[1,1.9,59.86],[2,1.86,383.76]],"ltp":2.3,"tv":18201.89,"id":9304761}]}]}
{"op":"mcm","clk":"4230560342","pt":1631534302781,"mc":[{"id":"1.187557247","rc":[{"batl":[[0,1.77,50],[1,1.8,38],[2,1.85,10.26]],"ltp":1.77,"tv":70620.76,"id":10350473}]}]}
{"op":"mcm","clk":"4230560504","pt":1631534304372,"mc":[{"id":"1.187557247","rc":[{"batb":[[0,2.1,543.99]],"ltp":2.3,"tv":18201.89,"id":9304761}]}]}
{"op":"mcm","clk":"4230560728","pt":1631534306471,"mc":[{"id":"1.187557247","rc":[{"batl":[[0,1.77,52.32],[1,1.85,10.26],[2,1.86,157.93]],"ltp":1.77,"tv":70620.76,"id":10350473}]}]}
{"op":"mcm","clk":"4230561035","pt":1631534309600,"mc":[{"id":"1.187557247","rc":[{"trd":[[1.76,2431.36]],"ltp":1.76,"tv":70659.26,"id":10350473},{"trd":[[2.3,43.97]],"batl":[[0,2.3,571.8]],"ltp":2.3,"tv":18231.35,"id":9304761}],"tv":88890.62}]}
{"op":"mcm","clk":"4230561203","pt":1631534311495,"mc":[{"id":"1.187557247","rc":[{"trd":[[1.77,34.66]],"batb":[[0,1.77,12.68],[1,1.74,1352.85],[2,1.4,10.27]],"batl":[[0,1.85,10.26],[1,1.86,157.93],[2,1.87,78.96]],"ltp":1.77,"tv":70663.91,"id":10350473}],"tv":88895.26}]}
{"op":"mcm","clk":"4230561298","pt":1631534312424,"mc":[{"id":"1.187557247","rc":[{"batb":[[1,1.4,10.27],[2,1.39,4.43]],"batl":[[1,2.12,7.71],[2,2.28,7.09]],"ltp":1.77,"tv":70663.91,"id":10350473},{"batb":[[0,1.9,59.86],[1,1.86,383.76],[2,1.79,52.31]],"batl":[[0,3.3,208.1],[1,990,0.7],[2,2.34,0]],"ltp":2.3,"tv":18231.35,"id":9304761}]}]}
{"op":"mcm","clk":"4230561484","pt":1631534314424,"mc":[{"id":"1.187557247","rc":[{"trd":[[1.77,60.02]],"batb":[[0,1.4,10.27],[1,1.39,4.43],[2,1.35,2.32]],"batl":[[0,1.76,37.32],[1,1.85,10.26],[2,2.12,7.71]],"ltp":1.77,"tv":70689.27,"id":10350473}],"tv":88920.62}]}
{"op":"mcm","clk":"4230561648","pt":1631534316414,"mc":[{"id":"1.187557247","rc":[{"batl":[[1,2.12,7.71],[2,2.28,7.09]],"ltp":1.77,"tv":70689.27,"id":10350473}]}]}
{"op":"mcm","clk":"4230561936","pt":1631534319609,"mc":[{"id":"1.187557247","rc":[{"trd":[[1.76,2505.99]],"batl":[[0,2.12,7.71],[1,2.28,7.09],[2,990,0.01]],"ltp":1.76,"tv":70763.9,"id":10350473}],"tv":88995.26}]}
{"op":"mcm","clk":"4230561963","pt":1631534320030,"mc":[{"id":"1.187557247","rc":[{"batl":[[0,2.28,7.09],[1,990,0.01],[2,990,0]],"ltp":1.76,"tv":70763.9,"id":10350473},{"batb":[[0,1.86,383.76],[1,1.79,52.31],[2,1.2,2]],"ltp":2.3,"tv":18231.35,"id":9304761}]}]}
{"op":"mcm","clk":"4230562093","pt":1631534321713,"mc":[{"id":"1.187557247","rc":[{"batb":[[0,1.69,596.25],[1,1.4,10.27],[2,1.39,4.43]],"ltp":1.76,"tv":70763.9,"id":10350473},{"batb":[[0,1.98,12.03],[1,1.86,383.76],[2,1.79,52.31]],"ltp":2.3,"tv":18231.35,"id":9304761}]}]}
{"op":"mcm","clk":"4230562145","pt":1631534322432,"mc":[{"id":"1.187557247","rc":[{"batb":[[0,1.4,10.27],[1,1.39,4.43],[2,1.35,2.32]],"ltp":1.76,"tv":70763.9,"id":10350473}]}]}
{"op":"mcm","clk":"4230562236","pt":1631534323529,"mc":[{"id":"1.187557247","rc":[{"batb":[[0,1.49,596.25],[1,1.4,10.27],[2,1.39,4.43]],"ltp":1.76,"tv":70763.9,"id":10350473}]}]}
{"op":"mcm","clk":"4230562769","pt":1631534330618,"mc":[{"id":"1.187557247","rc":[{"batb":[[0,1.86,383.76],[1,1.79,52.31],[2,1.2,2]],"ltp":2.3,"tv":18231.35,"id":9304761}]}]}
{"op":"mcm","clk":"4230562859","pt":1631534331514,"mc":[{"id":"1.187557247","rc":[{"batb":[[0,1.79,52.31],[1,1.2,2],[2,1.01,123.7]],"batl":[[0,990,0.7],[1,990,0]],"ltp":2.3,"tv":18231.35,"id":9304761}]}]}
{"op":"mcm","clk":"4230563068","pt":1631534333707,"mc":[{"id":"1.187557247","rc":[{"batb":[[0,2,235],[1,1.99,117.5],[2,1.98,117.5]],"ltp":1.76,"tv":70763.9,"id":10350473},{"batl":[[0,3.25,355.56],[1,990,0.7]],"ltp":2.3,"tv":18231.35,"id":9304761}]}]}
{"op":"mcm","clk":"4230563162","pt":1631534334740,"mc":[{"id":"1.187557247","rc":[{"trd":[[2,94.11]],"batb":[[0,2,224.42]],"ltp":2.0,"tv":70785.06,"id":10350473},{"batb":[[0,1.9,154.6],[1,1.89,77.3],[2,1.88,77.3]],"batl":[[0,990,0.7],[1,990,0]],"ltp":2.3,"tv":18231.35,"id":9304761}],"tv":89016.42}]}
{"op":"mcm","clk":"4230563209","pt":1631534335263,"mc":[{"id":"1.187557247","rc":[{"batl":[[0,2.82,250.69],[1,990,0.7]],"ltp":2.3,"tv":18231.35,"id":9304761}]}]}
{"op":"mcm","clk":"4230563581","pt":1631534339615,"mc":[{"id":"1.187557247","rc":[{"batl":[[1,2.46,6.25],[2,2.86,5.25]],"ltp":2.0,"tv":70785.06,"id":10350473}]}]}
{"op":"mcm","clk":"4230563798","pt":1631534341950,"mc":[{"id":"1.187557247","rc":[{"batl":[[2,2.82,4.75]],"ltp":2.0,"tv":70785.06,"id":10350473}]}]}
{"op":"mcm","clk":"4230564043","pt":1631534344559,"mc":[{"id":"1.187557247","rc":[{"trd":[[2,99.11]],"batb":[[0,2,221.92]],"ltp":2.0,"tv":70790.06,"id":10350473},{"batl":[[0,2.48,414.57],[1,2.82,250.69],[2,990,0.7]],"ltp":2.3,"tv":18231.35,"id":9304761}],"tv":89021.42}]}
{"op":"mcm","clk":"4230564119","pt":1631534345657,"mc":[{"id":"1.187557247","rc":[{"batb":[[0,2.04,3.55],[1,2.02,76.87],[2,2,221.92]],"ltp":2.0,"tv":70790.06,"id":10350473}]}]}
{"op":"mcm","clk":"4230564156","pt":1631534345935,"mc":[{"id":"1.187557247","rc":[{"batb":[[0,2,221.92],[1,1.99,117.5],[2,1.98,117.5]],"ltp":2.0,"tv":70790.06,"id":10350473}]}]}
{"op":"mcm","clk":"4230564385","pt":1631534348240,"mc":[{"id":"1.187557247","rc":[{"trd":[[2,101.43]],"batb":[[0,2,219.6]],"ltp":2.0,"tv":70792.38,"id":10350473},{"trd":[[2,4032.26]],"ltp":2.0,"tv":18233.68,"id":9304761}],"tv":89026.07}]}
{"op":"mcm","clk":"4230564633","pt":1631534350754,"mc":[{"id":"1.187557247","rc":[{"batb":[[0,1.96,13.46],[1,1.82,596.25],[2,1.49,596.25]],"ltp":2.0,"tv":70792.38,"id":10350473},{"batb":[[0,1.8,12.17],[1,1.79,52.31],[2,1.7,393.5]],"batl":[[0,2.82,250.69],[1,990,0.7],[2,990,0]],"ltp":2.0,"tv":18233.68,"id":9304761}]}]}
{"op":"mcm","clk":"4230564643","pt":1631534350868,"mc":[{"id":"1.187557247","rc":[{"batl":[[0,2.46,6.25],[1,2.82,4.75],[2,2.86,5.25]],"ltp":2.0,"tv":70792.38,"id":10350473},{"batb":[[1,1.7,393.5],[2,1.69,59.21]],"ltp":2.0,"tv":18233.68,"id":9304761}]}]}
{"op":"mcm","clk":"4230564871","pt":1631534353522,"mc":[{"id":"1.187557247","rc":[{"batb":[[0,1.95,14.46],[1,1.8,12.17],[2,1.7,393.5]],"ltp":2.0,"tv":18233.68,"id":9304761}]}]}
{"op":"mcm","clk":"4230565165","pt":1631534356928,"mc":[{"id":"1.187557247","rc":[{"batb":[[1,1.7,393.5],[2,1.69,59.21]],"ltp":2.0,"tv":18233.68,"id":9304761}]}]}
{"op":"mcm","clk":"4230565440","pt":1631534359609,"mc":[{"id":"1.187557247","rc":[{"batb":[[0,2.28,1030.7],[1,2.26,515.36],[2,2.24,515.36]],"batl":[[0,2.82,4.75],[1,990,0.01],[2,2.86,0]],"ltp":2.0,"tv":70792.38,"id":10350473},{"trd":[[1.95,621]],"batb":[[0,1.55,60.79],[1,1.2,2],[2,1.01,123.7]],"batl":[[0,1.76,20.09]],"ltp":1.95,"tv":18262.61,"id":9304761}],"tv":89055.0}]}
{"op":"mcm","clk":"4230565576","pt":1631534360706,"mc":[{"id":"1.187557247","rc":[{"trd":[[2.28,132.23]],"batb":[[0,2.28,196.71],[1,2.26,103.08],[2,2.24,103.08]],"batl":[[0,2.42,971.08],[1,2.44,485.54],[2,2.46,485.54]],"ltp":2.28,"tv":70811.24,"id":10350473},{"batl":[[0,990,0.7],[1,990,0]],"ltp":1.95,"tv":18262.61,"id":9304761}],"tv":89073.86}]}
{"op":"mcm","clk":"4230565597","pt":1631534361018,"mc":[{"id":"1.187557247","rc":[{"batl":[[0,2.42,121.39],[1,2.44,60.69],[2,2.46,60.69]],"ltp":2.28,"tv":70811.24,"id":10350473}]}]}
{"op":"mcm","clk":"4230565880","pt":1631534363639,"mc":[{"id":"1.187557247","rc":[{"batb":[[0,1.58,400.24],[1,1.55,60.79],[2,1.2,2]],"batl":[[0,2.5,297.3],[1,990,0.7]],"ltp":1.95,"tv":18262.61,"id":9304761}]}]}
{"op":"mcm","clk":"4230565999","pt":1631534364635,"mc":[{"id":"1.187557247","rc":[{"batl":[[0,2.34,5.96],[1,2.42,121.39],[2,2.44,60.69]],"ltp":2.28,"tv":70811.24,"id":10350473},{"batl":[[0,1.81,104.86],[1,2.5,297.3],[2,990,0.7]],"ltp":1.95,"tv":18262.61,"id":9304761}]}]}
{"op":"mcm","clk":"4230566065","pt":1631534365314,"mc":[{"id":"1.187557247","rc":[{"trd":[[2.28,232.23]],"batb":[[0,2.28,146.71]],"batl":[[0,2.42,121.39],[1,2.44,60.69],[2,2.46,60.69]],"ltp":2.28,"tv":70911.24,"id":10350473},{"batl":[[0,2.5,297.3],[1,990,0.7],[2,990,0]],"ltp":1.95,"tv":18262.61,"id":9304761}],"tv":89173.86}]}
{"op":"mcm","clk":"4230566195","pt":1631534366734,"mc":[{"id":"1.187557247","rc":[{"batb":[[1,1.57,68.57],[2,1.55,60.79]],"batl":[[0,2.36,522.47],[1,2.5,297.3],[2,990,0.7]],"ltp":1.95,"tv":18262.61,"id":9304761}]}]}
{"op":"mcm","clk":"4230566214","pt":1631534366950,"mc":[{"id":"1.187557247","rc":[{"batl":[[0,2.5,297.3],[1,990,0.7],[2,990,0]],"ltp":1.95,"tv":18262.61,"id":9304761}]}]}
{"op":"mcm","clk":"4230566376","pt":1631534368631,"mc":[{"id":"1.187557247","rc":[{"trd":[[2.28,234.05]],"batb":[[0,2.28,144.89]],"ltp":2.28,"tv":70913.06,"id":10350473},{"trd":[[1.79,425.84]],"ltp":1.79,"tv":18264.94,"id":9304761}],"tv":89178.0}]}
{"op":"mcm","clk":"4230566482","pt":1631534369742,"mc":[{"id":"1.187557247","rc":[{"batb":[[0,1.59,1728.13],[1,1.58,400.24],[2,1.57,68.57]],"ltp":1.79,"tv":18264.94,"id":9304761}]}]}
{"op":"mcm","clk":"4230566532","pt":1631534370164,"mc":[{"id":"1.187557247","rc":[{"batl":[[0,2.3,533.03],[1,2.5,297.3],[2,990,0.7]],"ltp":1.79,"tv":18264.94,"id":9304761}]}]}
{"op":"mcm","clk":"4230566644","pt":1631534371322,"mc":[{"id":"1.187557247","rc":[{"trd":[[2.28,240.77]],"batb":[[0,2.28,141.53]],"ltp":2.28,"tv":70919.78,"id":10350473}],"tv":89184.72}]}
{"op":"mcm","clk":"4230566702","pt":1631534371956,"mc":[{"id":"1.187557247","rc":[{"batb":[[1,1.58,410.22]],"ltp":1.79,"tv":18264.94,"id":9304761}]}]}
{"op":"mcm","clk":"4230566861","pt":1631534373434,"mc":[{"id":"1.187557247","rc":[{"trd":[[2.28,245.77]],"batb":[[0,2.28,139.03]],"ltp":2.28,"tv":70924.78,"id":10350473}],"tv":89189.72}]}
{"op":"mcm","clk":"4230566902","pt":1631534373853,"mc":[{"id":"1.187557247","rc":[{"trd":[[2.42,84.18]],"batl":[[0,2.42,98.86]],"ltp":2.42,"tv":70947.31,"id":10350473},{"trd":[[1.7,1455.52]],"ltp":1.7,"tv":18297.02,"id":9304761}],"tv":89244.33}]}
{"op":"mcm","clk":"4230567196","pt":1631534376755,"mc":[{"id":"1.187557247","rc":[{"trd":[[2.28,247.59]],"batb":[[0,1.4,10.04],[1,1.39,4.43],[2,1.35,2.32]],"batl":[[0,2.76,5.27],[1,2.82,4.75],[2,3.15,3.7]],"ltp":2.28,"tv":70949.13,"id":10350473},{"trd":[[1.79,428.17]],"batb":[[0,1.58,410.22],[1,1.57,68.57],[2,1.55,60.79]],"batl":[[0,2.5,297.3],[1,990,0.7],[2,990,0]],"ltp":1.79,"tv":18299.34,"id":9304761}],"tv":89248.47}]}
{"op":"mcm","clk":"4230567468","pt":1631534379759,"mc":[{"id":"1.187557247","rc":[{"batl":[[0,2.28,20],[1,2.76,5.27],[2,2.82,4.75]],"ltp":2.28,"tv":70949.13,"id":10350473}]}]}
{"op":"mcm","clk":"4230567736","pt":1631534382253,"mc":[{"id":"1.187557247","rc":[{"batl":[[0,2.74,4.98],[1,3.15,3.7],[2,990,0.01]],"ltp":2.28,"tv":70949.13,"id":10350473},{"batb":[[0,1.7,3.62],[1,1.58,478.78],[2,1.47,67.67]],"ltp":1.79,"tv":18299.34,"id":9304761}]}]}
{"op":"mcm","clk":"4230568229","pt":1631534386992,"mc":[{"id":"1.187557247","rc":[{"batl":[[1,990,0.01],[2,990,0]],"ltp":2.28,"tv":70949.13,"id":10350473},{"batb":[[1,1.58,468.8]],"ltp":1.79,"tv":18299.34,"id":9304761}]}]}
{"op":"mcm","clk":"4230568428","pt":1631534388685,"mc":[{"id":"1.187557247","rc":[{"trd":[[1.7,1462.76]],"batb":[[0,1.58,468.8],[1,1.47,67.67],[2,1.2,2]],"batl":[[0,1.65,21.46],[1,2.5,297.3],[2,990,0.7]],"ltp":1.7,"tv":18306.58,"id":9304761}],"tv":89255.71}]}
{"op":"mcm","clk":"4230568510","pt":1631534389579,"mc":[{"id":"1.187557247","rc":[{"batb":[[0,2.54,925.2],[1,2.52,462.6],[2,2.5,462.6]],"batl":[[0,990,0.01],[1,990,0]],"ltp":2.28,"tv":70949.13,"id":10350473},{"batb":[[0,1.58,400.24]],"batl":[[0,1.67,2444.77],[1,990,0.7],[2,990,0]],"ltp":1.7,"tv":18306.58,"id":9304761}]}]}
{"op":"mcm","clk":"4230568616","pt":1631534390689,"mc":[{"id":"1.187557247","rc":[{"trd":[[2.54,17.1]],"batb":[[0,2.54,916.65]],"batl":[[0,2.74,450.27],[1,2.76,225.13],[2,2.78,225.13]],"ltp":2.54,"tv":70966.23,"id":10350473},{"batl":[[0,1.67,488.96]],"ltp":1.7,"tv":18306.58,"id":9304761}],"tv":89272.81}]}
{"op":"mcm","clk":"4230568647","pt":1631534391056,"mc":[{"id":"1.187557247","rc":[{"batb":[[0,2.54,546.57],[1,2.52,277.56],[2,2.5,277.56]],"batl":[[0,2.74,107.21],[1,2.76,53.6],[2,2.78,53.6]],"ltp":2.54,"tv":70966.23,"id":10350473}]}]}
{"op":"mcm","clk":"4230568721","pt":1631534392157,"mc":[{"id":"1.187557247","rc":[{"trd":[[2.54,39.19]],"batb":[[0,2.54,524.48]],"ltp":2.54,"tv":70988.32,"id":10350473},{"trd":[[1.65,64.55]],"ltp":1.65,"tv":18340.58,"id":9304761}],"tv":89328.9}]}
{"op":"mcm","clk":"4230568761","pt":1631534392789,"mc":[{"id":"1.187557247","rc":[{"batl":[[1,2.36,324.05],[2,990,0.7]],"ltp":1.65,"tv":18340.58,"id":9304761}]}]}
{"op":"mcm","clk":"4230568959","pt":1631534394679,"mc":[{"id":"1.187557247","rc":[{"batb":[[0,1.6,79.55],[1,1.59,70.72],[2,1.58,400.24]],"batl":[[0,1.62,2.23],[1,1.63,3.33],[2,1.64,4.42]],"ltp":1.65,"tv":18340.58,"id":9304761}]}]}
{"op":"mcm","clk":"4230569016","pt":1631534395277,"mc":[{"id":"1.187557247","rc":[{"trd":[[1.62,9.63],[1.63,6.66],[1.64,8.67]],"batl":[[0,1.65,63.08],[1,1.66,70.63],[2,1.67,488.96]],"ltp":1.64,"tv":18360.37,"id":9304761}],"tv":89348.69}]}
{"op":"mcm","clk":"4230569104","pt":1631534396173,"mc":[{"id":"1.187557247","rc":[{"trd":[[2.54,43.09],[2.56,0.05]],"batb":[[0,2.54,522.53]],"ltp":2.54,"tv":70992.27,"id":10350473},{"trd":[[1.64,8.76]],"batl":[[0,1.65,63]],"ltp":1.64,"tv":18360.46,"id":9304761}],"tv":89352.73}]}
{"op":"mcm","clk":"4230569252","pt":1631534397695,"mc":[{"id":"1.187557247","rc":[{"trd":[[1.65,104.14]],"batl":[[0,1.65,43.2]],"ltp":1.65,"tv":18400.05,"id":9304761}],"tv":89392.32}]}
{"op":"mcm","clk":"4230569339","pt":1631534398696,"mc":[{"id":"1.187557247","rc":[{"trd":[[1.6,36.4],[1.65,123.94]],"batb":[[0,1.6,61.35]],"batl":[[0,1.65,33.3]],"ltp":1.6,"tv":18456.25,"id":9304761}],"tv":89448.52}]}
{"op":"mcm","clk":"4230569484","pt":1631534400307,"mc":[{"id":"1.187557247","rc":[{"trd":[[1.65,143.73]],"batb":[[0,1.58,400.24],[1,1.52,72.49],[2,1.47,67.67]],"batl":[[0,1.67,488.96],[1,2.36,324.05],[2,990,0.7]],"ltp":1.65,"tv":18476.04,"id":9304761}],"tv":89468.31}]}
{"op":"mcm","clk":"4230569570","pt":1631534400989,"mc":[{"id":"1.187557247","rc":[{"batb":[[0,2.68,5.64],[1,1.39,4.43],[2,1.35,2.32]],"batl":[[0,2.94,4.25],[1,3.15,4.1],[2,3.25,3.62]],"ltp":2.54,"tv":70992.27,"id":10350473},{"batl":[[0,2.36,324.05],[1,990,0.7],[2,990,0]],"ltp":1.65,"tv":18476.04,"id":9304761}]}]}
{"op":"mcm","clk":"4230569756","pt":1631534402698,"mc":[{"id":"1.187557247","rc":[{"trd":[[2.68,5.64]],"batb":[[0,1.39,4.43],[1,1.35,2.32],[2,1.28,720.76]],"ltp":2.68,"tv":70997.91,"id":10350473},{"trd":[[1.6,45.85]],"batb":[[0,1.58,400.76],[1,1.53,10.53],[2,1.52,72.49]],"batl":[[0,1.81,10.37],[1,2.36,324.05],[2,990,0.7]],"ltp":1.6,"tv":18485.49,"id":9304761}],"tv":89483.4}]}
{"op":"mcm","clk":"4230569866","pt":1631534403604,"mc":[{"id":"1.187557247","rc":[{"batl":[[0,2.54,2],[1,2.94,4.25],[2,3.15,4.1]],"ltp":2.68,"tv":70997.91,"id":10350473}]}]}
{"op":"mcm","clk":"4230570053","pt":1631534405394,"mc":[{"id":"1.187557247","rc":[{"batl":[[0,2.94,4.25],[1,3.15,4.1],[2,3.25,3.62]],"ltp":2.68,"tv":70997.91,"id":10350473}]}]}
{"op":"mcm","clk":"4230570153","pt":1631534406397,"mc":[{"id":"1.187557247","rc":[{"batb":[[0,1.35,2.32],[1,1.28,720.76],[2,1.2,2]],"ltp":2.68,"tv":70997.91,"id":10350473},{"batl":[[0,2.36,324.05],[1,990,0.7],[2,990,0]],"ltp":1.6,"tv":18485.49,"id":9304761}]}]}
{"op":"mcm","clk":"4230570380","pt":1631534408699,"mc":[{"id":"1.187557247","rc":[{"batl":[[0,2.68,41.68],[1,2.94,4.25],[2,3.15,4.1]],"ltp":2.68,"tv":70997.91,"id":10350473}]}]}
{"op":"mcm","clk":"4230570447","pt":1631534409237,"mc":[{"id":"1.187557247","rc":[{"batl":[[0,2.94,4.25],[1,3.15,4.1],[2,3.25,3.62]],"ltp":2.68,"tv":70997.91,"id":10350473}]}]}
{"op":"mcm","clk":"4230570602","pt":1631534410719,"mc":[{"id":"1.187557247","rc":[{"batb":[[0,1.75,12.28],[1,1.35,2.32],[2,1.28,720.76]],"ltp":2.68,"tv":70997.91,"id":10350473},{"batb":[[0,1.59,596.25],[1,1.58,400.24],[2,1.53,10.53]],"batl":[[0,1.8,6.83],[1,2.36,324.05],[2,990,0.7]],"ltp":1.6,"tv":18485.49,"id":9304761}]}]}
{"op":"mcm","clk":"4230570668","pt":1631534411406,"mc":[{"id":"1.187557247","rc":[{"batb":[[0,1.61,18.08],[1,1.59,596.25],[2,1.58,400.24]],"ltp":1.6,"tv":18485.49,"id":9304761}]}]}
{"op":"mcm","clk":"4230571002","pt":1631534414843,"mc":[{"id":"1.187557247","rc":[{"batl":[[0,2.56,2],[1,2.94,4.25],[2,3.15,4.1]],"ltp":2.68,"tv":70997.91,"id":10350473}]}]}
{"op":"mcm","clk":"4230571267","pt":1631534417430,"mc":[{"id":"1.187557247","rc":[{"batl":[[0,2.94,4.25],[1,3.15,4.1],[2,3.25,3.62]],"ltp":2.68,"tv":70997.91,"id":10350473}]}]}
{"op":"mcm","clk":"4230571324","pt":1631534418124,"mc":[{"id":"1.187557247","rc":[{"batb":[[0,1.35,2.32],[1,1.28,720.76],[2,1.2,2]],"ltp":2.68,"tv":70997.91,"id":10350473}]}]}
{"op":"mcm","clk":"4230571397","pt":1631534419013,"mc":[{"id":"1.187557247","rc":[{"batb":[[1,1.58,400.24],[2,1.53,10.53]],"ltp":1.6,"tv":18485.49,"id":9304761}]}]}
{"op":"mcm","clk":"4230571556","pt":1631534420716,"mc":[{"id":"1.187557247","rc":[{"batl":[[0,2.56,2],[1,2.94,4.25],[2,3.15,4.1]],"ltp":2.68,"tv":70997.91,"id":10350473}]}]}
{"op":"mcm","clk":"4230571648","pt":1631534421716,"mc":[{"id":"1.187557247","rc":[{"trd":[[2.16,124.13],[2.24,31.03]],"batb":[[0,2.32,502.69],[1,2.3,253.23],[2,2.28,253.23]],"batl":[[0,2.56,1695.63],[2,990,0.01]],"ltp":2.16,"tv":71010.94,"id":10350473},{"trd":[[1.8,80.75]],"batb":[[0,1.68,279.76],[1,1.67,139.88],[2,1.66,139.88]],"batl":[[0,2.36,324.05],[1,990,0.7],[2,990,0]],"ltp":1.8,"tv":18492.32,"id":9304761}],"tv":89503.26}]}
{"op":"mcm","clk":"4230571698","pt":1631534422226,"mc":[{"id":"1.187557247","rc":[{"batb":[[0,2.32,126.61],[1,2.3,63.31],[2,2.28,63.31]],"ltp":2.16,"tv":71010.94,"id":10350473}]}]}
{"op":"mcm","clk":"4230572063","pt":1631534425748,"mc":[{"id":"1.187557247","rc":[{"batb":[[0,1.7,18.08],[1,1.68,279.76],[2,1.67,139.88]],"ltp":1.8,"tv":18492.32,"id":9304761}]}]}
{"op":"mcm","clk":"4230572196","pt":1631534427044,"mc":[{"id":"1.187557247","rc":[{"batl":[[1,2.82,4.75],[2,2.94,4.25]],"ltp":2.16,"tv":71010.94,"id":10350473}]}]}
{"op":"mcm","clk":"4230572343","pt":1631534428432,"mc":[{"id":"1.187557247","rc":[{"trd":[[2.32,1.8]],"batb":[[0,2.32,125.71]],"ltp":2.32,"tv":71012.74,"id":10350473}],"tv":89505.06}]}
{"op":"mcm","clk":"4230572640","pt":1631534431535,"mc":[{"id":"1.187557247","rc":[{"batl":[[0,2.2,205.84],[1,2.36,324.05],[2,990,0.7]],"ltp":1.8,"tv":18492.32,"id":9304761}]}]}
{"op":"mcm","clk":"4230572763","pt":1631534433145,"mc":[{"id":"1.187557247","rc":[{"trd":[[2.32,9.21]],"batb":[[0,2.32,118.3]],"ltp":2.32,"tv":71020.15,"id":10350473},{"trd":[[1.76,14.41]],"batb":[[1,1.69,10.25],[2,1.68,279.76]],"ltp":1.76,"tv":18502.08,"id":9304761}],"tv":89522.23}]}
{"op":"mcm","clk":"4230572999","pt":1631534435749,"mc":[{"id":"1.187557247","rc":[{"trd":[[1.7,1462.95]],"batb":[[0,1.7,17.99]],"ltp":1.7,"tv":18502.26,"id":9304761}],"tv":89522.42}]}
{"op":"mcm","clk":"4230573037","pt":1631534436167,"mc":[{"id":"1.187557247","rc":[{"trd":[[1.7,1463.7]],"batb":[[0,1.7,17.61]],"ltp":1.7,"tv":18503.01,"id":9304761}],"tv":89523.17}]}
{"op":"mcm","clk":"4230573267","pt":1631534438348,"mc":[{"id":"1.187557247","rc":[{"trd":[[2.32,14.7]],"batb":[[0,2.32,112.81]],"ltp":2.32,"tv":71025.64,"id":10350473},{"trd":[[1.76,21.64]],"ltp":1.76,"tv":18510.25,"id":9304761}],"tv":89535.89}]}
{"op":"mcm","clk":"4230573505","pt":1631534440560,"mc":[{"id":"1.187557247","rc":[{"trd":[[1.7,1468.34]],"batb":[[0,1.7,15.29]],"ltp":1.7,"tv":18514.89,"id":9304761}],"tv":89540.54}]}
{"op":"mcm","clk":"4230575377","pt":1631534461389,"mc":[{"id":"1.187557247","rc":[{"batb":[[0,1.35,2.32],[1,1.28,720.76],[2,1.2,2]],"batl":[[0,2.82,4.75],[1,2.94,4.25],[2,3.05,4.1]],"ltp":2.32,"tv":71025.64,"id":10350473},{"batb":[[2,1.58,400.24]],"ltp":1.7,"tv":18514.89,"id":9304761}]}]}
{"op":"mcm","clk":"4230575420","pt":1631534461814,"mc":[{"id":"1.187557247","rc":[{"batl":[[0,2.36,324.05],[1,990,0.7],[2,990,0]],"ltp":1.7,"tv":18514.89,"id":9304761}]}]}
{"op":"mcm","clk":"4230575532","pt":1631534462900,"mc":[{"id":"1.187557247","rc":[{"batb":[[0,1.69,10.25],[1,1.55,70.59],[2,1.52,72.49]],"batl":[[0,990,0.7],[1,990,0]],"ltp":1.7,"tv":18514.89,"id":9304761}]}]}
{"op":"mcm","clk":"4230575722","pt":1631534464713,"mc":[{"id":"1.187557247","rc":[{"batl":[[0,2.8,652.34],[1,2.82,4.75],[2,2.94,4.25]],"ltp":2.32,"tv":71025.64,"id":10350473}]}]}
{"op":"mcm","clk":"4230575822","pt":1631534465498,"mc":[{"id":"1.187557247","rc":[{"batl":[[0,2.82,4.75],[1,2.94,4.25],[2,3.05,4.1]],"ltp":2.32,"tv":71025.64,"id":10350473},{"batb":[[0,1.76,2.32]],"ltp":1.7,"tv":18514.89,"id":9304761}]}]}
{"op":"mcm","clk":"4230575908","pt":1631534466401,"mc":[{"id":"1.187557247","rc":[{"batb":[[0,1.76,598.58],[1,1.67,195.06],[2,1.55,70.59]],"batl":[[0,2.72,384.17],[1,990,0.7]],"ltp":1.7,"tv":18514.89,"id":9304761}]}]}
{"op":"mcm","clk":"4230576049","pt":1631534467705,"mc":[{"id":"1.187557247","rc":[{"batl":[[0,990,0.01],[1,2.94,0],[2,3.05,0]],"ltp":2.32,"tv":71025.64,"id":10350473}]}]}
{"op":"mcm","clk":"4230576134","pt":1631534468602,"mc":[{"id":"1.187557247","rc":[{"batl":[[0,2.76,865.38],[1,990,0.01]],"ltp":2.32,"tv":71025.64,"id":10350473},{"batb":[[2,1.4,42.59]],"ltp":1.7,"tv":18514.89,"id":9304761}]}]}
{"op":"mcm","clk":"4230576197","pt":1631534469198,"mc":[{"id":"1.187557247","rc":[{"batl":[[0,990,0.01],[1,990,0]],"ltp":2.32,"tv":71025.64,"id":10350473}]}]}
{"op":"mcm","clk":"4230576324","pt":1631534470509,"mc":[{"id":"1.187557247","rc":[{"batl":[[0,2.84,5.03],[1,3.1,3.85],[2,990,0.01]],"ltp":2.32,"tv":71025.64,"id":10350473},{"batb":[[2,1.48,78.01]],"ltp":1.7,"tv":18514.89,"id":9304761}]}]}
{"op":"mcm","clk":"4230576397","pt":1631534471204,"mc":[{"id":"1.187557247","rc":[{"batl":[[0,990,0.01],[1,3.1,0],[2,990,0]],"ltp":2.32,"tv":71025.64,"id":10350473},{"batb":[[2,1.4,42.59]],"ltp":1.7,"tv":18514.89,"id":9304761}]}]}
{"op":"mcm","clk":"4230576737","pt":1631534474607,"mc":[{"id":"1.187557247","rc":[{"batb":[[0,1.76,596.25]],"ltp":1.7,"tv":18514.89,"id":9304761}]}]}
{"op":"mcm","clk":"4230576832","pt":1631534475622,"mc":[{"id":"1.187557247","rc":[{"batl":[[0,3.2,339],[1,990,0.01]],"ltp":2.32,"tv":71025.64,"id":10350473},{"batb":[[0,1.76,821.26]],"batl":[[0,2.64,114.03],[1,2.72,384.17],[2,990,0.7]],"ltp":1.7,"tv":18514.89,"id":9304761}]}]}
{"op":"mcm","clk":"4230576908","pt":1631534476405,"mc":[{"id":"1.187557247","rc":[{"batb":[[0,1.56,13.42],[1,1.35,2.32],[2,1.28,720.76]],"ltp":2.32,"tv":71025.64,"id":10350473},{"batb":[[0,1.76,596.25],[1,1.68,10.1],[2,1.67,195.06]],"batl":[[0,2.72,384.17],[1,990,0.7],[2,990,0]],"ltp":1.7,"tv":18514.89,"id":9304761}]}]}
{"op":"mcm","clk":"4230577026","pt":1631534477714,"mc":[{"id":"1.187557247","rc":[{"batb":[[1,1.51,646.78],[2,1.35,2.32]],"ltp":2.32,"tv":71025.64,"id":10350473}]}]}
{"op":"mcm","clk":"4230577040","pt":1631534477926,"mc":[{"id":"1.187557247","rc":[{"batb":[[1,1.35,2.32],[2,1.28,720.76]],"ltp":2.32,"tv":71025.64,"id":10350473}]}]}
{"op":"mcm","clk":"4230577139","pt":1631534478823,"mc":[{"id":"1.187557247","rc":[{"batb":[[0,1.8,192],[1,1.76,596.25],[2,1.68,10.1]],"ltp":1.7,"tv":18514.89,"id":9304761}]}]}
{"op":"mcm","clk":"4230577500","pt":1631534482433,"mc":[{"id":"1.187557247","rc":[{"batl":[[0,990,0.01],[1,990,0]],"ltp":2.32,"tv":71025.64,"id":10350473}]}]}
{"op":"mcm","clk":"4230577585","pt":1631534483222,"mc":[{"id":"1.187557247","rc":[{"batb":[[1,1.68,10.1],[2,1.67,195.06]],"ltp":1.7,"tv":18514.89,"id":9304761}]}]}
{"op":"mcm","clk":"4230577832","pt":1631534485513,"mc":[{"id":"1.187557247","rc":[{"batl":[[0,2.68,642.62],[1,990,0.01]],"ltp":2.32,"tv":71025.64,"id":10350473},{"batb":[[1,1.7,596.25],[2,1.68,10.1]],"ltp":1.7,"tv":18514.89,"id":9304761}]}]}
{"op":"mcm","clk":"4230578148","pt":1631534488540,"mc":[{"id":"1.187557247","rc":[{"batl":[[0,990,0.01],[1,990,0]],"ltp":2.32,"tv":71025.64,"id":10350473},{"batb":[[0,1.7,596.25],[1,1.68,10.1],[2,1.67,195.06]],"ltp":1.7,"tv":18514.89,"id":9304761}]}]}
{"op":"mcm","clk":"4230578314","pt":1631534490240,"mc":[{"id":"1.187557247","rc":[{"batb":[[0,1.93,50],[1,1.56,13.42],[2,1.35,2.32]],"ltp":2.32,"tv":71025.64,"id":10350473}]}]}
{"op":"mcm","clk":"4230578461","pt":1631534491725,"mc":[{"id":"1.187557247","rc":[{"batl":[[0,2.68,154.37],[1,990,0.01]],"ltp":2.32,"tv":71025.64,"id":10350473}]}]}
{"op":"mcm","clk":"4230578476","pt":1631534491931,"mc":[{"id":"1.187557247","rc":[{"batb":[[1,1.6,23.24],[2,1.56,13.42]],"batl":[[0,990,0.01],[1,990,0]],"ltp":2.32,"tv":71025.64,"id":10350473}]}]}
{"op":"mcm","clk":"4230579227","pt":1631534498552,"mc":[{"id":"1.187557247","rc":[{"batl":[[0,3.3,329.38],[1,990,0.01]],"ltp":2.32,"tv":71025.64,"id":10350473}]}]}
{"op":"mcm","clk":"4230579754","pt":1631534503738,"mc":[{"id":"1.187557247","rc":[{"batl":[[0,990,0.01],[1,990,0]],"ltp":2.32,"tv":71025.64,"id":10350473}]}]}
{"op":"mcm","clk":"4230579875","pt":1631534504871,"mc":[{"id":"1.187557247","rc":[{"batb":[[2,1.4,42.59]],"batl":[[0,990,0.7],[1,990,0]],"ltp":1.7,"tv":18514.89,"id":9304761}]}]}
{"op":"mcm","clk":"4230580536","pt":1631534511765,"mc":[{"id":"1.187557247","rc":[{"batb":[[1,1.56,13.42],[2,1.35,2.32]],"ltp":2.32,"tv":71025.64,"id":10350473}]}]}
{"op":"mcm","clk":"4230580817","pt":1631534514666,"mc":[{"id":"1.187557247","rc":[{"batb":[[0,1.68,10.1],[1,1.4,42.59],[2,1.2,2]],"ltp":1.7,"tv":18514.89,"id":9304761}]}]}
{"op":"mcm","clk":"4230580837","pt":1631534514878,"mc":[{"id":"1.187557247","rc":[{"batb":[[1,1.57,23.24],[2,1.56,13.42]],"ltp":2.32,"tv":71025.64,"id":10350473}]}]}
{"op":"mcm","clk":"4230581135","pt":1631534517920,"mc":[{"id":"1.187557247","rc":[{"batb":[[0,1.4,42.59],[1,1.2,2],[2,1.01,123.7]],"ltp":1.7,"tv":18514.89,"id":9304761}]}]}
{"op":"mcm","clk":"4230581472","pt":1631534520713,"mc":[{"id":"1.187557247","rc":[{"batb":[[0,2.3,1071.93],[1,1.93,50],[2,1.57,23.24]],"ltp":2.32,"tv":71025.64,"id":10350473},{"batl":[[0,1.69,834.31],[1,1.7,417.16],[2,1.71,417.16]],"ltp":1.7,"tv":18514.89,"id":9304761}]}]}
{"op":"mcm","clk":"4230581587","pt":1631534521718,"mc":[{"id":"1.187557247","rc":[{"trd":[[2.44,14.35]],"ltp":2.44,"tv":71034.34,"id":10350473},{"trd":[[1.69,920.79]],"batb":[[0,1.62,181.33],[1,1.61,90.66],[2,1.6,90.66]],"batl":[[0,1.69,265.54],[1,1.7,139.06],[2,1.71,139.06]],"ltp":1.69,"tv":18527.45,"id":9304761}],"tv":89561.8}]}
{"op":"mcm","clk":"4230581697","pt":1631534522709,"mc":[{"id":"1.187557247","rc":[{"batb":[[1,1.57,23.24],[2,1.35,2.32]],"ltp":2.44,"tv":71034.34,"id":10350473}]}]}
{"op":"mcm","clk":"4230581985","pt":1631534525600,"mc":[{"id":"1.187557247","rc":[{"batb":[[0,1.66,3.87],[1,1.65,7.79],[2,1.64,65.83]],"batl":[[0,1.67,70.55],[1,1.68,60.97],[2,1.69,265.54]],"ltp":1.69,"tv":18527.45,"id":9304761}]}]}
{"op":"mcm","clk":"4230582097","pt":1631534526699,"mc":[{"id":"1.187557247","rc":[{"batb":[[0,2.3,1732.37]],"ltp":2.44,"tv":71034.34,"id":10350473}]}]}
{"op":"mcm","clk":"4230582183","pt":1631534527485,"mc":[{"id":"1.187557247","rc":[{"batb":[[0,2.3,1071.93]],"batl":[[0,3.25,4.3],[1,3.75,3.02],[2,990,0.01]],"ltp":2.44,"tv":71034.34,"id":10350473}]}]}
{"op":"mcm","clk":"4230582308","pt":1631534528585,"mc":[{"id":"1.187557247","rc":[{"batl":[[0,3.1,4.35],[1,3.25,4.3],[2,3.6,3.51]],"ltp":2.44,"tv":71034.34,"id":10350473}]}]}
{"op":"mcm","clk":"4230582529","pt":1631534530739,"mc":[{"id":"1.187557247","rc":[{"trd":[[1.67,9.74]],"batl":[[0,1.67,65.68]],"ltp":1.67,"tv":18537.2,"id":9304761}],"tv":89571.54}]}
{"op":"mcm","clk":"4230582591","pt":1631534531289,"mc":[{"id":"1.187557247","rc":[{"trd":[[1.67,24.21]],"batl":[[0,1.67,58.45]],"ltp":1.67,"tv":18551.66,"id":9304761}],"tv":89586.0}]}
{"op":"mcm","clk":"4230582781","pt":1631534533027,"mc":[{"id":"1.187557247","rc":[{"batl":[[0,1.67,56.52]],"ltp":1.67,"tv":18551.66,"id":9304761}]}]}
{"op":"mcm","clk":"4230583017","pt":1631534534713,"mc":[{"id":"1.187557247","rc":[{"trd":[[2.48,18.06]],"batb":[[0,2.32,676.71],[1,2.3,1071.93]],"ltp":2.48,"tv":71052.4,"id":10350473},{"trd":[[1.67,51.02]],"batl":[[0,1.67,29.71]],"ltp":1.67,"tv":18578.47,"id":9304761}],"tv":89630.88}]}
{"op":"mcm","clk":"4230583156","pt":1631534535718,"mc":[{"id":"1.187557247","rc":[{"trd":[[2.48,38.06]],"batb":[[0,2.3,1071.93],[1,1.35,2.32],[2,1.28,720.76]],"batl":[[0,2.48,210.56],[1,3.1,4.35],[2,3.25,4.3]],"ltp":2.48,"tv":71072.4,"id":10350473},{"trd":[[1.67,80.73]],"batb":[[0,1.62,181.85],[1,1.61,90.66],[2,1.6,90.66]],"batl":[[0,1.69,265.54],[1,1.7,139.06],[2,1.71,139.06]],"ltp":1.67,"tv":18608.19,"id":9304761}],"tv":89680.59}]}
{"op":"mcm","clk":"4230583311","pt":1631534536717,"mc":[{"id":"1.187557247","rc":[{"batl":[[0,2.48,141.78]],"ltp":2.48,"tv":71072.4,"id":10350473},{"batb":[[0,1.67,33.05],[1,1.62,181.33],[2,1.61,90.66]],"ltp":1.67,"tv":18608.19,"id":9304761}]}]}
{"op":"mcm","clk":"4230583420","pt":1631534537719,"mc":[{"id":"1.187557247","rc":[{"batl":[[0,2.48,94.53]],"ltp":2.48,"tv":71072.4,"id":10350473},{"batb":[[0,1.67,30.02]],"ltp":1.67,"tv":18608.19,"id":9304761}]}]}
{"op":"mcm","clk":"4230583509","pt":1631534538615,"mc":[{"id":"1.187557247","rc":[{"batl":[[0,2.48,82.4]],"ltp":2.48,"tv":71072.4,"id":10350473},{"batb":[[0,1.67,33.01]],"ltp":1.67,"tv":18608.19,"id":9304761}]}]}
{"op":"mcm","clk":"4230583615","pt":1631534539663,"mc":[{"id":"1.187557247","rc":[{"trd":[[2.44,31.39]],"batb":[[0,2.3,1553.92]],"batl":[[0,2.48,60]],"ltp":2.44,"tv":71089.43,"id":10350473},{"trd":[[1.69,945.38]],"batb":[[0,1.67,3.51]],"batl":[[0,1.69,240.95]],"ltp":1.69,"tv":18632.78,"id":9304761}],"tv":89722.21}]}
{"op":"mcm","clk":"4230583726","pt":1631534540620,"mc":[{"id":"1.187557247","rc":[{"batl":[[0,3.1,4.35],[1,3.25,4.3],[2,3.6,3.51]],"ltp":2.44,"tv":71089.43,"id":10350473},{"batb":[[0,1.62,181.85],[1,1.61,90.66],[2,1.6,90.66]],"ltp":1.69,"tv":18632.78,"id":9304761}]}]}
{"op":"mcm","clk":"4230583850","pt":1631534541735,"mc":[{"id":"1.187557247","rc":[{"trd":[[2.44,129.51]],"ltp":2.44,"tv":71187.56,"id":10350473},{"trd":[[1.69,1131.73]],"batb":[[0,1.62,181.33]],"batl":[[0,1.69,76.95]],"ltp":1.69,"tv":18819.12,"id":9304761}],"tv":90006.68}]}
{"op":"mcm","clk":"4230583920","pt":1631534542412,"mc":[{"id":"1.187557247","rc":[{"trd":[[2.44,146.55]],"ltp":2.44,"tv":71204.59,"id":10350473},{"trd":[[1.69,1220.22]],"batl":[[0,1.69,20.41]],"ltp":1.69,"tv":18907.61,"id":9304761}],"tv":90112.21}]}
{"op":"mcm","clk":"4230584073","pt":1631534543729,"mc":[{"id":"1.187557247","rc":[{"trd":[[2.44,160.69]],"batb":[[0,2.3,1071.93]],"batl":[[0,2.44,19.93],[1,3.1,4.35],[2,3.25,4.3]],"ltp":2.44,"tv":71218.73,"id":10350473},{"trd":[[1.69,1240.63]],"batb":[[0,1.69,37.04],[1,1.62,181.33],[2,1.61,90.66]],"batl":[[0,1.7,139.06],[1,1.71,139.06],[2,1.87,10.9]],"ltp":1.69,"tv":18928.02,"id":9304761}],"tv":90146.76}]}
{"op":"mcm","clk":"4230584152","pt":1631534544414,"mc":[{"id":"1.187557247","rc":[{"batl":[[0,3.1,4.35],[1,3.25,4.3],[2,3.6,3.51]],"ltp":2.44,"tv":71218.73,"id":10350473},{"batb":[[0,1.69,29.13]],"ltp":1.69,"tv":18928.02,"id":9304761}]}]}
{"op":"mcm","clk":"4230584253","pt":1631534545418,"mc":[{"id":"1.187557247","rc":[{"batb":[[0,1.62,181.33],[1,1.61,90.66],[2,1.6,90.66]],"ltp":1.69,"tv":18928.02,"id":9304761}]}]}
{"op":"mcm","clk":"4230584404","pt":1631534546736,"mc":[{"id":"1.187557247","rc":[{"batb":[[0,1.35,2.32],[1,1.28,720.76],[2,1.2,2]],"ltp":2.44,"tv":71218.73,"id":10350473},{"batb":[[0,1.56,9.43],[1,1.55,213.89],[2,1.48,76.26]],"batl":[[0,1.87,10.9],[1,2.42,432.9],[2,990,0.7]],"ltp":1.69,"tv":18928.02,"id":9304761}]}]}
{"op":"mcm","clk":"4230584548","pt":1631534547944,"mc":[{"id":"1.187557247","rc":[{"batb":[[1,1.48,76.26],[2,1.45,81.21]],"batl":[[1,990,0.7],[2,990,0]],"ltp":1.69,"tv":18928.02,"id":9304761}]}]}
{"op":"mcm","clk":"4230584757","pt":1631534549632,"mc":[{"id":"1.187557247","rc":[{"batb":[[0,1.7,36.51],[1,1.56,9.43],[2,1.48,76.26]],"ltp":1.69,"tv":18928.02,"id":9304761}]}]}
{"op":"mcm","clk":"4230584888","pt":1631534550946,"mc":[{"id":"1.187557247","rc":[{"batb":[[0,1.56,9.43],[1,1.48,76.26],[2,1.45,81.21]],"batl":[[0,1.86,7.23],[1,1.87,10.9],[2,990,0.7]],"ltp":1.69,"tv":18928.02,"id":9304761}]}]}
{"op":"mcm","clk":"4230585535","pt":1631534556759,"mc":[{"id":"1.187557247","rc":[{"batl":[[0,3.25,4.3],[1,3.6,3.51],[2,3.65,3.5]],"ltp":2.44,"tv":71218.73,"id":10350473},{"batb":[[0,1.45,81.21],[1,1.4,42.59],[2,1.39,82.91]],"ltp":1.69,"tv":18928.02,"id":9304761}]}]}
{"op":"mcm","clk":"4230585561","pt":1631534557073,"mc":[{"id":"1.187557247","rc":[{"batl":[[0,3.6,3.51],[1,3.65,3.5],[2,990,0.01]],"ltp":2.44,"tv":71218.73,"id":10350473},{"batb":[[0,1.4,42.59],[1,1.39,82.91],[2,1.38,71.96]],"ltp":1.69,"tv":18928.02,"id":9304761}]}]}
{"op":"mcm","clk":"4230585877","pt":1631534559548,"mc":[{"id":"1.187557247","rc":[{"batb":[[0,2.76,510.86],[1,2.74,255.43],[2,2.72,255.43]],"ltp":2.44,"tv":71218.73,"id":10350473},{"batl":[[0,1.64,1438.53],[1,1.86,7.23],[2,1.87,10.9]],"ltp":1.69,"tv":18928.02,"id":9304761}]}]}
{"op":"mcm","clk":"4230585990","pt":1631534560650,"mc":[{"id":"1.187557247","rc":[{"trd":[[2.76,15.88]],"batb":[[0,2.76,162.34],[1,2.74,85.14],[2,2.72,85.14]],"batl":[[0,2.96,99.24],[1,2.98,49.62],[2,3,49.62]],"ltp":2.76,"tv":71234.61,"id":10350473},{"batl":[[2,990,0.7]],"ltp":1.69,"tv":18928.02,"id":9304761}],"tv":90162.64}]}
{"op":"mcm","clk":"4230586099","pt":1631534561488,"mc":[{"id":"1.187557247","rc":[{"batb":[[0,1.46,226.38],[1,1.4,42.59],[2,1.39,82.91]],"batl":[[1,1.7,596.25],[2,1.86,7.23]],"ltp":1.69,"tv":18928.02,"id":9304761}]}]}
{"op":"mcm","clk":"4230586329","pt":1631534563584,"mc":[{"id":"1.187557247","rc":[{"trd":[[2.76,19.88]],"batb":[[0,2.76,160.34]],"ltp":2.76,"tv":71238.61,"id":10350473},{"batb":[[1,1.42,7.23],[2,1.4,42.59]],"batl":[[0,1.63,125.33],[1,1.64,1438.53],[2,1.7,596.25]],"ltp":1.69,"tv":18928.02,"id":9304761}],"tv":90166.64}]}
{"op":"mcm","clk":"4230586437","pt":1631534564479,"mc":[{"id":"1.187557247","rc":[{"batl":[[0,1.64,1438.53],[1,1.7,596.25],[2,1.86,7.23]],"ltp":1.69,"tv":18928.02,"id":9304761}]}]}
{"op":"mcm","clk":"4230586602","pt":1631534565752,"mc":[{"id":"1.187557247","rc":[{"batb":[[0,1.52,7.23],[1,1.46,226.38],[2,1.43,86.43]],"batl":[[0,1.64,1477.21],[1,1.67,34.5],[2,1.7,596.25]],"ltp":1.69,"tv":18928.02,"id":9304761}]}]}
{"op":"mcm","clk":"4230586829","pt":1631534567694,"mc":[{"id":"1.187557247","rc":[{"trd":[[2.76,20.18]],"batb":[[0,2.76,160.04]],"ltp":2.76,"tv":71238.91,"id":10350473},{"trd":[[1.57,0.52]],"batl":[[0,1.63,312.88],[1,1.64,1477.21],[2,1.67,34.5]],"ltp":1.57,"tv":18928.54,"id":9304761}],"tv":90167.46}]}
{"op":"mcm","clk":"4230587038","pt":1631534569581,"mc":[{"id":"1.187557247","rc":[{"trd":[[2.76,20.32]],"batb":[[0,2.76,159.9]],"ltp":2.76,"tv":71239.05,"id":10350473},{"trd":[[1.57,0.77]],"ltp":1.57,"tv":18928.79,"id":9304761}],"tv":90167.84}]}
{"op":"mcm","clk":"4230587127","pt":1631534570279,"mc":[{"id":"1.187557247","rc":[{"trd":[[2.76,165.37]],"batb":[[0,2.76,14.85]],"ltp":2.76,"tv":71384.1,"id":10350473},{"trd":[[1.57,255.77]],"ltp":1.57,"tv":19183.79,"id":9304761}],"tv":90567.89}]}
{"op":"mcm","clk":"4230587299","pt":1631534571681,"mc":[{"id":"1.187557247","rc":[{"batb":[[0,1.56,17.16],[1,1.55,25.91],[2,1.54,34.77]],"batl":[[0,1.62,62.27],[1,1.63,312.88],[2,1.64,1477.21]],"ltp":1.57,"tv":19183.79,"id":9304761}]}]}
{"op":"mcm","clk":"4230587327","pt":1631534571891,"mc":[{"id":"1.187557247","rc":[{"trd":[[2.76,170.22]],"batb":[[0,2.76,10]],"ltp":2.76,"tv":71388.95,"id":10350473},{"trd":[[1.57,264.29]],"batb":[[0,1.52,7.23],[1,1.47,11.33],[2,1.46,226.38]],"batl":[[0,1.63,312.88],[1,1.64,1477.21],[2,1.66,9.66]],"ltp":1.57,"tv":19192.31,"id":9304761}],"tv":90581.27}]}
{"op":"mcm","clk":"4230587653","pt":1631534574409,"mc":[{"id":"1.187557247","rc":[{"batb":[[0,2.56,5.58],[1,2.48,5.76],[2,1.35,2.32]],"batl":[[0,3.35,3.7],[1,3.6,3.51],[2,3.65,3.5]],"ltp":2.76,"tv":71388.95,"id":10350473},{"batl":[[1,1.64,38.68]],"ltp":1.57,"tv":19192.31,"id":9304761}]}]}
{"op":"mcm","clk":"4230587747","pt":1631534575094,"mc":[{"id":"1.187557247","rc":[{"batb":[[0,1.35,2.32],[1,1.28,720.76],[2,1.2,2]],"ltp":2.76,"tv":71388.95,"id":10350473},{"batl":[[0,1.66,9.66],[1,1.7,596.25],[2,1.86,7.23]],"ltp":1.57,"tv":19192.31,"id":9304761}]}]}
{"op":"mcm","clk":"4230587923","pt":1631534576499,"mc":[{"id":"1.187557247","rc":[{"batb":[[0,2.52,5.99],[1,1.35,2.32],[2,1.28,720.76]],"ltp":2.76,"tv":71388.95,"id":10350473},{"batb":[[2,1.43,86.43]],"batl":[[0,1.65,44.5],[1,1.66,9.66],[2,1.7,596.25]],"ltp":1.57,"tv":19192.31,"id":9304761}]}]}
{"op":"mcm","clk":"4230588675","pt":1631534582677,"mc":[{"id":"1.187557247","rc":[{"batb":[[1,1.43,86.43],[2,1.42,7.23]],"batl":[[2,1.86,7.23]],"ltp":1.57,"tv":19192.31,"id":9304761}]}]}
{"op":"mcm","clk":"4230588789","pt":1631534583619,"mc":[{"id":"1.187557247","rc":[{"trd":[[2.94,3.74]],"batb":[[0,2.94,96.26],[1,2.52,5.99],[2,1.35,2.32]],"batl":[[0,3.8,3.37],[1,990,0.01],[2,3.65,0]],"ltp":2.94,"tv":71392.69,"id":10350473},{"trd":[[1.52,7.23]],"batb":[[0,1.42,7.23],[1,1.4,42.59],[2,1.36,80.93]],"ltp":1.52,"tv":19199.54,"id":9304761}],"tv":90592.24}]}
{"op":"mcm","clk":"4230589064","pt":1631534585590,"mc":[{"id":"1.187557247","rc":[{"batl":[[0,1.51,311.26],[1,1.52,155.62],[2,1.53,155.62]],"ltp":1.52,"tv":19199.54,"id":9304761}]}]}
{"op":"mcm","clk":"4230589159","pt":1631534586424,"mc":[{"id":"1.187557247","rc":[{"trd":[[2.96,7.52]],"ltp":2.96,"tv":71400.21,"id":10350473},{"trd":[[1.51,14.74]],"batb":[[0,1.45,202.59],[1,1.44,101.29],[2,1.43,101.29]],"batl":[[0,1.51,296.52]],"ltp":1.51,"tv":19214.28,"id":9304761}],"tv":90614.5}]}
{"op":"mcm","clk":"4230589366","pt":1631534588223,"mc":[{"id":"1.187557247","rc":[{"trd":[[1.51,49.9]],"batl":[[0,1.51,278.94]],"ltp":1.51,"tv":19249.44,"id":9304761}],"tv":90649.66}]}
{"op":"mcm","clk":"4230589638","pt":1631534590520,"mc":[{"id":"1.187557247","rc":[{"trd":[[1.51,99.9]],"batl":[[0,1.51,253.94]],"ltp":1.51,"tv":19299.44,"id":9304761}],"tv":90699.66}]}
{"op":"mcm","clk":"4230589759","pt":1631534591526,"mc":[{"id":"1.187557247","rc":[{"trd":[[1.51,607.83]],"batb":[[0,1.51,21.14],[1,1.45,202.59],[2,1.44,101.29]],"batl":[[0,1.52,155.62],[1,1.53,155.62],[2,1.56,2550.43]],"ltp":1.51,"tv":19807.37,"id":9304761}],"tv":91207.59}]}
{"op":"mcm","clk":"4230589809","pt":1631534591901,"mc":[{"id":"1.187557247","rc":[{"trd":[[1.51,611.23]],"batb":[[0,1.51,19.44]],"ltp":1.51,"tv":19810.78,"id":9304761}],"tv":91211.0}]}
{"op":"mcm","clk":"4230589965","pt":1631534593214,"mc":[{"id":"1.187557247","rc":[{"batb":[[1,1.46,18.08],[2,1.45,202.59]],"ltp":1.51,"tv":19810.78,"id":9304761}]}]}
{"op":"mcm","clk":"4230590163","pt":1631534594695,"mc":[{"id":"1.187557247","rc":[{"trd":[[1.51,650.1],[1.52,161.07]],"batb":[[0,1.46,18.08],[1,1.45,202.59],[2,1.44,101.29]],"batl":[[0,1.52,78.7]],"ltp":1.51,"tv":20003.49,"id":9304761}],"tv":91403.7}]}
{"op":"mcm","clk":"4230590574","pt":1631534598304,"mc":[{"id":"1.187557247","rc":[{"batb":[[0,1.48,18.08],[1,1.47,18.08],[2,1.46,18.08]],"ltp":1.51,"tv":20003.49,"id":9304761}]}]}
{"op":"mcm","clk":"4230591117","pt":1631534603531,"mc":[{"id":"1.187557247","rc":[{"batb":[[0,1.48,118.08]],"batl":[[0,1.51,26.85],[1,1.52,78.7],[2,1.53,155.62]],"ltp":1.51,"tv":20003.49,"id":9304761}]}]}
{"op":"mcm","clk":"4230591218","pt":1631534604427,"mc":[{"id":"1.187557247","rc":[{"batb":[[0,2.52,5.99],[1,1.35,2.32],[2,1.28,720.76]],"ltp":2.96,"tv":71400.21,"id":10350473}]}]}
{"op":"mcm","clk":"4230591304","pt":1631534605317,"mc":[{"id":"1.187557247","rc":[{"trd":[[1.51,654.75]],"batl":[[0,1.51,24.53]],"ltp":1.51,"tv":20008.13,"id":9304761}],"tv":91408.35}]}
{"op":"mcm","clk":"4230591526","pt":1631534607617,"mc":[{"id":"1.187557247","rc":[{"batb":[[0,2.54,501.57],[1,2.52,5.99],[2,1.35,2.32]],"batl":[[0,3.65,553.93],[1,3.8,3.37],[2,990,0.01]],"ltp":2.96,"tv":71400.21,"id":10350473}]}]}
{"op":"mcm","clk":"4230591607","pt":1631534608405,"mc":[{"id":"1.187557247","rc":[{"trd":[[1.51,703.81],[1.52,177.09]],"batl":[[0,1.52,70.69],[1,1.53,155.62],[2,1.56,2550.43]],"ltp":1.52,"tv":20073.21,"id":9304761}],"tv":91473.43}]}
{"op":"mcm","clk":"4230591745","pt":1631534609717,"mc":[{"id":"1.187557247","rc":[{"trd":[[1.52,180.61]],"batl":[[0,1.52,68.93]],"ltp":1.52,"tv":20076.73,"id":9304761}],"tv":91476.95}]}
{"op":"mcm","clk":"4230591907","pt":1631534611334,"mc":[{"id":"1.187557247","rc":[{"batl":[[0,3.65,554.32]],"ltp":2.96,"tv":71400.21,"id":10350473},{"batb":[[1,1.46,18.08],[2,1.45,202.59]],"ltp":1.52,"tv":20076.73,"id":9304761}]}]}
{"op":"mcm","clk":"4230592114","pt":1631534613228,"mc":[{"id":"1.187557247","rc":[{"batb":[[0,1.49,18.08],[1,1.48,118.08]],"ltp":1.52,"tv":20076.73,"id":9304761}]}]}
{"op":"mcm","clk":"4230592288","pt":1631534614733,"mc":[{"id":"1.187557247","rc":[{"trd":[[1.52,318.48],[1.53,311.26],[1.56,1866.24]],"batb":[[0,1.49,36.16]],"batl":[[0,1.56,1617.39],[1,1.65,44.5],[2,2.04,182.67]],"ltp":1.56,"tv":22392.11,"id":9304761}],"tv":93792.32}]}
{"op":"mcm","clk":"4230592346","pt":1631534615221,"mc":[{"id":"1.187557247","rc":[{"batb":[[0,2.52,5.99],[1,1.35,2.32],[2,1.28,720.76]],"ltp":2.96,"tv":71400.21,"id":10350473}]}]}
{"op":"mcm","clk":"4230592438","pt":1631534616146,"mc":[{"id":"1.187557247","rc":[{"batb":[[0,1.5,18.08],[1,1.49,36.16],[2,1.48,118.08]],"ltp":1.56,"tv":22392.11,"id":9304761}]}]}
{"op":"mcm","clk":"4230592619","pt":1631534617724,"mc":[{"id":"1.187557247","rc":[{"batl":[[0,3.65,553.93]],"ltp":2.96,"tv":71400.21,"id":10350473},{"trd":[[1.5,4.01]],"batb":[[0,1.5,16.08]],"ltp":1.5,"tv":22396.11,"id":9304761}],"tv":93796.33}]}
{"op":"mcm","clk":"4230592641","pt":1631534617934,"mc":[{"id":"1.187557247","rc":[{"trd":[[1.5,30.04]],"batb":[[0,1.5,3.06]],"batl":[[0,1.56,1714.34]],"ltp":1.5,"tv":22422.15,"id":9304761}],"tv":93822.36}]}
{"op":"mcm","clk":"4230592881","pt":1631534620167,"mc":[{"id":"1.187557247","rc":[{"batb":[[0,1.51,18.08],[1,1.5,3.06],[2,1.49,36.16]],"ltp":1.5,"tv":22422.15,"id":9304761}]}]}
{"op":"mcm","clk":"4230593019","pt":1631534621443,"mc":[{"id":"1.187557247","rc":[{"batb":[[0,2.56,169.33],[1,2.52,5.99],[2,1.35,2.32]],"ltp":2.96,"tv":71400.21,"id":10350473}]}]}
{"op":"mcm","clk":"4230593271","pt":1631534623753,"mc":[{"id":"1.187557247","rc":[{"batb":[[0,1.52,2.32],[1,1.51,18.08],[2,1.5,3.06]],"batl":[[1,1.61,851.79],[2,1.65,44.5]],"ltp":1.5,"tv":22422.15,"id":9304761}]}]}
{"op":"mcm","clk":"4230593329","pt":1631534624133,"mc":[{"id":"1.187557247","rc":[{"batl":[[0,1.55,14.54],[1,1.56,1714.34],[2,1.61,851.79]],"ltp":1.5,"tv":22422.15,"id":9304761}]}]}
{"op":"mcm","clk":"4230593748","pt":1631534627758,"mc":[{"id":"1.187557247","rc":[{"batb":[[0,2.52,5.99],[1,1.35,2.32],[2,1.28,720.76]],"batl":[[0,3.8,3.37],[1,990,0.01],[2,990,0]],"ltp":2.96,"tv":71400.21,"id":10350473},{"trd":[[1.51,712.17]],"batb":[[0,1.51,13.9],[1,1.5,3.06],[2,1.49,36.16]],"ltp":1.51,"tv":22430.51,"id":9304761}],"tv":93830.73}]}
{"op":"mcm","clk":"4230593866","pt":1631534628756,"mc":[{"id":"1.187557247","rc":[{"batb":[[0,1.52,20.5],[1,1.51,13.9],[2,1.5,3.06]],"ltp":1.51,"tv":22430.51,"id":9304761}]}]}
{"op":"mcm","clk":"4230593913","pt":1631534629137,"mc":[{"id":"1.187557247","rc":[{"trd":[[1.55,29.08],[1.56,2068.7]],"batb":[[1,1.5,3.06],[2,1.49,36.16]],"batl":[[0,1.56,1613.12],[1,1.61,851.79],[2,1.65,44.5]],"ltp":1.56,"tv":22662.04,"id":9304761}],"tv":94062.26}]}
{"op":"mcm","clk":"4230594075","pt":1631534630648,"mc":[{"id":"1.187557247","rc":[{"batl":[[0,3.55,481.42],[1,3.8,3.37],[2,990,0.01]],"ltp":2.96,"tv":71400.21,"id":10350473}]}]}
{"op":"mcm","clk":"4230594158","pt":1631534631448,"mc":[{"id":"1.187557247","rc":[{"batb":[[0,2.58,328.38],[1,2.52,5.99],[2,1.35,2.32]],"ltp":2.96,"tv":71400.21,"id":10350473},{"batb":[[0,1.53,100],[1,1.52,23.39],[2,1.5,3.06]],"ltp":1.56,"tv":22662.04,"id":9304761}]}]}
{"op":"mcm","clk":"4230594271","pt":1631534632541,"mc":[{"id":"1.187557247","rc":[{"trd":[[2.78,2.17]],"batl":[[0,3.8,3.37],[1,990,0.01],[2,990,0]],"ltp":2.78,"tv":71402.38,"id":10350473},{"trd":[[1.56,2072.57]],"batb":[[0,1.54,26.08],[1,1.53,152.5],[2,1.52,23.39]],"batl":[[0,1.56,1512.3]],"ltp":1.56,"tv":22665.91,"id":9304761}],"tv":94068.3}]}
{"op":"mcm","clk":"4230594610","pt":1631534635679,"mc":[{"id":"1.187557247","rc":[{"trd":[[1.54,52.16]],"batb":[[0,1.53,152.5],[1,1.52,23.39],[2,1.5,3.06]],"batl":[[0,1.55,4.07],[1,1.56,1512.3],[2,1.61,851.79]],"ltp":1.54,"tv":22718.07,"id":9304761}],"tv":94120.46}]}
{"op":"mcm","clk":"4230594724","pt":1631534636576,"mc":[{"id":"1.187557247","rc":[{"trd":[[1.55,33.72]],"batl":[[0,1.55,1.75]],"ltp":1.55,"tv":22722.72,"id":9304761}],"tv":94125.11}]}
{"op":"mcm","clk":"4230594744","pt":1631534636786,"mc":[{"id":"1.187557247","rc":[{"batb":[[1,1.52,20.5]],"ltp":1.55,"tv":22722.72,"id":9304761}]}]}
{"op":"mcm","clk":"4230594848","pt":1631534637787,"mc":[{"id":"1.187557247","rc":[{"batb":[[0,1.53,52.5]],"ltp":1.55,"tv":22722.72,"id":9304761}]}]}
{"op":"mcm","clk":"4230595023","pt":1631534639407,"mc":[{"id":"1.187557247","rc":[{"trd":[[2.8,0.41]],"batl":[[0,3.65,107.48],[1,3.8,3.37],[2,990,0.01]],"ltp":2.8,"tv":71402.79,"id":10350473},{"trd":[[1.55,36.49],[1.56,2075.17]],"batl":[[0,1.56,1511],[1,1.61,851.79],[2,1.65,44.5]],"ltp":1.56,"tv":22728.09,"id":9304761}],"tv":94130.89}]}
{"op":"mcm","clk":"4230595095","pt":1631534640098,"mc":[{"id":"1.187557247","rc":[{"batb":[[0,1.54,2.89],[1,1.53,52.5],[2,1.52,20.5]],"ltp":1.56,"tv":22728.09,"id":9304761}]}]}
{"op":"mcm","clk":"4230595243","pt":1631534641413,"mc":[{"id":"1.187557247","rc":[{"trd":[[1.53,410.49],[1.54,57.94]],"batb":[[0,1.53,2.89],[1,1.52,20.5],[2,1.5,3.06]],"ltp":1.53,"tv":22833.1,"id":9304761}],"tv":94235.89}]}
{"op":"mcm","clk":"4230595365","pt":1631534642673,"mc":[{"id":"1.187557247","rc":[{"batl":[[0,3.8,3.37],[1,990,0.01],[2,990,0]],"ltp":2.8,"tv":71402.79,"id":10350473},{"trd":[[1.56,2079.82]],"batl":[[0,1.56,1508.68]],"ltp":1.56,"tv":22837.74,"id":9304761}],"tv":94240.53}]}
{"op":"mcm","clk":"4230595891","pt":1631534647708,"mc":[{"id":"1.187557247","rc":[{"trd":[[2.78,3.43]],"batl":[[0,2.88,50],[1,3.8,3.37],[2,990,0.01]],"ltp":2.78,"tv":71404.05,"id":10350473},{"trd":[[1.56,2082.07]],"batl":[[0,1.56,1506.43]],"ltp":1.56,"tv":22839.99,"id":9304761}],"tv":94244.04}]}
{"op":"mcm","clk":"4230595969","pt":1631534648390,"mc":[{"id":"1.187557247","rc":[{"trd":[[2.78,16.21]],"ltp":2.78,"tv":71416.83,"id":10350473},{"trd":[[1.56,2110.04]],"batl":[[0,1.56,1481.06]],"ltp":1.56,"tv":22867.96,"id":9304761}],"tv":94284.79}]}
{"op":"mcm","clk":"4230596483","pt":1631534652919,"mc":[{"id":"1.187557247","rc":[{"batb":[[2,1.45,202.59]],"ltp":1.56,"tv":22867.96,"id":9304761}]}]}
{"op":"mcm","clk":"4230596842","pt":1631534655751,"mc":[{"id":"1.187557247","rc":[{"batb":[[0,1.54,11.62],[1,1.53,2.89],[2,1.52,20.5]],"ltp":1.56,"tv":22867.96,"id":9304761}]}]}
{"op":"mcm","clk":"4230597357","pt":1631534660342,"mc":[{"id":"1.187557247","rc":[{"batl":[[0,3.8,3.37],[1,990,0.01],[2,990,0]],"ltp":2.78,"tv":71416.83,"id":10350473},{"batl":[[1,1.65,44.5],[2,2.04,182.67]],"ltp":1.56,"tv":22867.96,"id":9304761}]}]}
{"op":"mcm","clk":"4230597673","pt":1631534663440,"mc":[{"id":"1.187557247","rc":[{"batl":[[0,2.8,50],[1,3.8,3.37],[2,990,0.01]],"ltp":2.78,"tv":71416.83,"id":10350473}]}]}
{"op":"mcm","clk":"4230597753","pt":1631534664119,"mc":[{"id":"1.187557247","rc":[{"batb":[[0,1.54,54.21]],"ltp":1.56,"tv":22867.96,"id":9304761}]}]}
{"op":"mcm","clk":"4230598137","pt":1631534667738,"mc":[{"id":"1.187557247","rc":[{"batb":[[0,1.54,56.71]],"ltp":1.56,"tv":22867.96,"id":9304761}]}]}
{"op":"mcm","clk":"4230598224","pt":1631534668528,"mc":[{"id":"1.187557247","rc":[{"batb":[[0,1.55,2.84],[1,1.54,123.97]],"batl":[[0,1.56,1540.08]],"ltp":1.56,"tv":22867.96,"id":9304761}]}]}
{"op":"mcm","clk":"4230598394","pt":1631534670141,"mc":[{"id":"1.187557247","rc":[{"trd":[[2.8,34.41]],"batl":[[0,2.8,33]],"ltp":2.8,"tv":71450.83,"id":10350473}],"tv":94318.79}]}
{"op":"mcm","clk":"4230598558","pt":1631534671765,"mc":[{"id":"1.187557247","rc":[{"batb":[[1,1.54,112.35]],"ltp":1.56,"tv":22867.96,"id":9304761}]}]}
{"op":"mcm","clk":"4230598614","pt":1631534672341,"mc":[{"id":"1.187557247","rc":[{"batb":[[1,1.54,69.76]],"ltp":1.56,"tv":22867.96,"id":9304761}]}]}
{"op":"mcm","clk":"4230598926","pt":1631534675431,"mc":[{"id":"1.187557247","rc":[{"trd":[[1.56,2133.28]],"batb":[[0,1.55,45.43]],"batl":[[0,1.56,1528.46]],"ltp":1.56,"tv":22891.2,"id":9304761}],"tv":94342.03}]}
{"op":"mcm","clk":"4230598983","pt":1631534676054,"mc":[{"id":"1.187557247","rc":[{"trd":[[1.56,2153.28]],"batl":[[0,1.56,1518.46]],"ltp":1.56,"tv":22911.2,"id":9304761}],"tv":94362.03}]}
{"op":"mcm","clk":"4230599231","pt":1631534678629,"mc":[{"id":"1.187557247","rc":[{"batb":[[0,2.52,5.99],[1,1.35,2.32],[2,1.28,720.76]],"ltp":2.8,"tv":71450.83,"id":10350473}]}]}
{"op":"mcm","clk":"4230600458","pt":1631534690351,"mc":[{"id":"1.187557247","rc":[{"trd":[[1.56,2158.48]],"batl":[[0,1.56,1515.86]],"ltp":1.56,"tv":22916.41,"id":9304761}],"tv":94367.24}]}
{"op":"mcm","clk":"4230601229","pt":1631534697678,"mc":[{"id":"1.187557247","rc":[{"trd":[[1.55,41.47]],"batb":[[0,1.55,42.95]],"ltp":1.55,"tv":22921.38,"id":9304761}],"tv":94372.21}]}
{"op":"mcm","clk":"4230602453","pt":1631534707576,"mc":[{"id":"1.187557247","rc":[{"trd":[[1.55,46.58]],"batb":[[0,1.55,40.39]],"ltp":1.55,"tv":22926.49,"id":9304761}],"tv":94377.32}]}
{"op":"mcm","clk":"4230603132","pt":1631534713877,"mc":[{"id":"1.187557247","rc":[{"batl":[[0,3.8,3.37],[1,990,0.01],[2,990,0]],"ltp":2.8,"tv":71450.83,"id":10350473}]}]}
{"op":"mcm","clk":"4230603472","pt":1631534717036,"mc":[{"id":"1.187557247","rc":[{"trd":[[2.78,49.21]],"ltp":2.78,"tv":71483.83,"id":10350473},{"trd":[[1.56,2217.29]],"batl":[[0,1.56,1457.05]],"ltp":1.56,"tv":22985.3,"id":9304761}],"tv":94469.13}]}
{"op":"mcm","clk":"4230603643","pt":1631534718528,"mc":[{"id":"1.187557247","rc":[{"trd":[[1.56,2225.81]],"batl":[[0,1.56,1452.79]],"ltp":1.56,"tv":22993.82,"id":9304761}],"tv":94477.65}]}
{"op":"mcm","clk":"4230604456","pt":1631534725607,"mc":[{"id":"1.187557247","rc":[{"trd":[[1.56,2231.27]],"batl":[[0,1.56,1450.06]],"ltp":1.56,"tv":22999.28,"id":9304761}],"tv":94483.11}]}
{"op":"mcm","clk":"4230604648","pt":1631534727235,"mc":[{"id":"1.187557247","rc":[{"trd":[[2.82,19]],"ltp":2.82,"tv":71502.83,"id":10350473},{"trd":[[1.55,81.15]],"batb":[[0,1.55,5.82]],"ltp":1.55,"tv":23033.85,"id":9304761}],"tv":94536.68}]}
{"op":"mcm","clk":"4230605397","pt":1631534733523,"mc":[{"id":"1.187557247","rc":[{"batl":[[0,1.56,1452.56]],"ltp":1.55,"tv":23033.85,"id":9304761}]}]}
{"op":"mcm","clk":"4230605799","pt":1631534737132,"mc":[{"id":"1.187557247","rc":[{"batl":[[0,3.4,82.12],[1,3.8,3.37],[2,990,0.01]],"ltp":2.82,"tv":71502.83,"id":10350473},{"trd":[[1.55,92.55]],"batb":[[0,1.54,69.88],[1,1.52,20.5],[2,1.45,202.59]],"ltp":1.55,"tv":23045.25,"id":9304761}],"tv":94548.08}]}
{"op":"mcm","clk":"4230605973","pt":1631534738744,"mc":[{"id":"1.187557247","rc":[{"batl":[[0,1.56,1450.06]],"ltp":1.55,"tv":23045.25,"id":9304761}]}]}
{"op":"mcm","clk":"4230606158","pt":1631534740629,"mc":[{"id":"1.187557247","rc":[{"batb":[[0,1.35,2.32],[1,1.28,720.76],[2,1.2,2]],"batl":[[0,990,0.01],[1,3.8,0],[2,990,0]],"ltp":2.82,"tv":71502.83,"id":10350473},{"batb":[[2,1.4,42.59]],"batl":[[0,2.04,182.67],[1,990,0.01],[2,2.04,0]],"ltp":1.55,"tv":23045.25,"id":9304761}]}]}
{"op":"mcm","clk":"4230606435","pt":1631534743137,"mc":[{"id":"1.187557247","rc":[{"trd":[[1.54,89.72],[1.55,92.79]],"batb":[[0,1.54,53.87]],"ltp":1.54,"tv":23077.27,"id":9304761}],"tv":94580.1}]}
{"op":"mcm","clk":"4230606792","pt":1631534746339,"mc":[{"id":"1.187557247","rc":[{"batb":[[0,1.52,20.5],[1,1.4,42.59],[2,1.38,57.96]],"ltp":1.54,"tv":23077.27,"id":9304761}]}]}
{"op":"mcm","clk":"4230606983","pt":1631534747644,"mc":[{"id":"1.187557247","rc":[{"batb":[[0,1.56,2.5]],"ltp":1.54,"tv":23077.27,"id":9304761}]}]}
{"op":"mcm","clk":"4230607203","pt":1631534749436,"mc":[{"id":"1.187557247","rc":[{"trd":[[1.56,2236.27]],"batb":[[0,1.4,42.59],[1,1.38,57.96],[2,1.2,2]],"ltp":1.56,"tv":23082.27,"id":9304761}],"tv":94585.1}]}
{"op":"mcm","clk":"4230607332","pt":1631534750742,"mc":[{"id":"1.187557247","rc":[{"batb":[[0,1.41,12.27],[1,1.4,42.59],[2,1.38,57.96]],"ltp":1.56,"tv":23082.27,"id":9304761}]}]}
{"op":"mcm","clk":"4230607483","pt":1631534752162,"mc":[{"id":"1.187557247","rc":[{"batl":[[0,1.71,766.61],[1,2.04,182.67],[2,990,0.01]],"ltp":1.56,"tv":23082.27,"id":9304761}]}]}
{"op":"mcm","clk":"4230607795","pt":1631534754849,"mc":[{"id":"1.187557247","rc":[{"batb":[[2,1.2,2]],"ltp":1.56,"tv":23082.27,"id":9304761}]}]}
{"op":"mcm","clk":"4230608132","pt":1631534758159,"mc":[{"id":"1.187557247","rc":[{"batb":[[1,1.4,452.6]],"ltp":1.56,"tv":23082.27,"id":9304761}]}]}
{"op":"mcm","clk":"4230608978","pt":1631534765468,"mc":[{"id":"1.187557247","rc":[{"batb":[[0,1.4,452.6],[1,1.2,2],[2,1.01,123.7]],"ltp":1.56,"tv":23082.27,"id":9304761}]}]}
{"op":"mcm","clk":"4230609187","pt":1631534767293,"mc":[{"id":"1.187557247","rc":[{"batb":[[0,1.4,42.59]],"ltp":1.56,"tv":23082.27,"id":9304761}]}]}
{"op":"mcm","clk":"4230609350","pt":1631534768698,"mc":[{"id":"1.187557247","rc":[{"trd":[[3.1,9.79]],"batb":[[0,3.1,750.3],[1,2.98,473.16],[2,2.96,236.58]],"ltp":3.1,"tv":71512.62,"id":10350473},{"trd":[[1.48,20.5]],"batl":[[0,1.65,245.47],[1,1.71,766.61],[2,2.04,182.67]],"ltp":1.48,"tv":23102.77,"id":9304761}],"tv":94615.39}]}
{"op":"mcm","clk":"4230609435","pt":1631534769391,"mc":[{"id":"1.187557247","rc":[{"trd":[[3.1,23.67]],"batb":[[0,3.1,743.36]],"batl":[[0,3.7,79.39],[1,3.75,39.7],[2,3.8,39.7]],"ltp":3.1,"tv":71526.5,"id":10350473},{"batl":[[0,1.71,766.61],[1,2.04,182.67],[2,990,0.01]],"ltp":1.48,"tv":23102.77,"id":9304761}],"tv":94629.27}]}
{"op":"mcm","clk":"4230609682","pt":1631534771597,"mc":[{"id":"1.187557247","rc":[{"batb":[[1,1.34,422.44],[2,1.2,2]],"ltp":1.48,"tv":23102.77,"id":9304761}]}]}
{"op":"mcm","clk":"4230610043","pt":1631534774699,"mc":[{"id":"1.187557247","rc":[{"batb":[[2,1.33,86.53]],"ltp":1.48,"tv":23102.77,"id":9304761}]}]}
{"op":"mcm","clk":"4230610253","pt":1631534776687,"mc":[{"id":"1.187557247","rc":[{"batb":[[0,3.15,457.41],[1,3.1,743.36],[2,2.98,473.16]],"ltp":3.1,"tv":71526.5,"id":10350473},{"trd":[[1.4,85.17]],"batb":[[0,1.37,222.56],[1,1.36,291.51],[2,1.34,422.44]],"batl":[[0,1.4,184],[1,1.41,242.28],[2,1.71,766.61]],"ltp":1.4,"tv":23187.94,"id":9304761}],"tv":94714.44}]}
{"op":"mcm","clk":"4230610376","pt":1631534777690,"mc":[{"id":"1.187557247","rc":[{"batb":[[0,3.25,69.32],[1,3.15,457.41],[2,3.1,743.36]],"ltp":3.1,"tv":71526.5,"id":10350473}]}]}
{"op":"mcm","clk":"4230610421","pt":1631534778107,"mc":[{"id":"1.187557247","rc":[{"trd":[[3.5,2.56]],"ltp":3.5,"tv":71529.05,"id":10350473},{"trd":[[1.4,117.59]],"batl":[[0,1.4,164.59]],"ltp":1.4,"tv":23220.36,"id":9304761}],"tv":94749.42}]}
{"op":"mcm","clk":"4230610574","pt":1631534779580,"mc":[{"id":"1.187557247","rc":[{"batb":[[0,1.37,248.26]],"batl":[[2,1.48,46.24]],"ltp":1.4,"tv":23220.36,"id":9304761}]}]}
{"op":"mcm","clk":"4230610688","pt":1631534780513,"mc":[{"id":"1.187557247","rc":[{"batb":[[1,3.1,743.36],[2,2.98,473.16]],"ltp":3.5,"tv":71529.05,"id":10350473},{"batb":[[0,1.38,78.64],[1,1.37,248.26],[2,1.36,291.51]],"batl":[[0,1.39,73.26],[1,1.4,164.59],[2,1.41,242.28]],"ltp":1.4,"tv":23220.36,"id":9304761}]}]}
{"op":"mcm","clk":"4230610784","pt":1631534781305,"mc":[{"id":"1.187557247","rc":[{"trd":[[1.39,23.25]],"batl":[[0,1.39,61.64],[1,1.4,190.79]],"ltp":1.39,"tv":23243.62,"id":9304761}],"tv":94772.67}]}
{"op":"mcm","clk":"4230610946","pt":1631534782623,"mc":[{"id":"1.187557247","rc":[{"trd":[[1.39,60.87]],"batl":[[0,1.39,42.83]],"ltp":1.39,"tv":23281.23,"id":9304761}],"tv":94810.29}]}
{"op":"mcm","clk":"4230611081","pt":1631534783719,"mc":[{"id":"1.187557247","rc":[{"batb":[[1,1.35,2.32],[2,1.28,720.76]],"batl":[[0,4.1,3.35],[1,4.2,3.13],[2,4.4,2.89]],"ltp":3.5,"tv":71529.05,"id":10350473},{"trd":[[1.39,146.51],[1.4,227.22]],"batl":[[0,1.4,135.97],[1,1.41,242.28],[2,1.7,9.83]],"ltp":1.4,"tv":23476.49,"id":9304761}],"tv":95005.55}]}
{"op":"mcm","clk":"4230611185","pt":1631534784516,"mc":[{"id":"1.187557247","rc":[{"trd":[[3.6,2.32]],"batb":[[0,1.35,2.32],[1,1.28,720.76],[2,1.2,2]],"ltp":3.6,"tv":71531.38,"id":10350473},{"trd":[[1.38,163.32]],"batb":[[0,1.35,10],[1,1.34,422.44],[2,1.33,86.53]],"batl":[[0,1.7,9.83],[1,1.71,766.61],[2,2.04,182.67]],"ltp":1.38,"tv":23639.81,"id":9304761}],"tv":95171.19}]}
{"op":"mcm","clk":"4230611493","pt":1631534787400,"mc":[{"id":"1.187557247","rc":[{"batb":[[0,3.05,4.69],[1,1.35,2.32],[2,1.28,720.76]],"ltp":3.6,"tv":71531.38,"id":10350473},{"batl":[[0,1.47,306.1],[1,1.48,255.77],[2,1.7,9.83]],"ltp":1.38,"tv":23639.81,"id":9304761}]}]}
{"op":"mcm","clk":"4230611782","pt":1631534790322,"mc":[{"id":"1.187557247","rc":[{"batb":[[0,1.34,422.44],[1,1.33,86.53],[2,1.32,93.64]],"batl":[[0,1.48,60.24],[1,1.7,9.83],[2,1.71,766.61]],"ltp":1.38,"tv":23639.81,"id":9304761}]}]}
{"op":"mcm","clk":"4230612147","pt":1631534793510,"mc":[{"id":"1.187557247","rc":[{"batb":[[0,1.36,249.39],[1,1.35,301.93],[2,1.34,422.44]],"batl":[[0,1.39,223.73],[1,1.4,249.58],[2,1.48,60.24]],"ltp":1.38,"tv":23639.81,"id":9304761}]}]}
{"op":"mcm","clk":"4230612297","pt":1631534794723,"mc":[{"id":"1.187557247","rc":[{"batb":[[0,3.25,23.45],[1,3.05,4.69],[2,1.35,2.32]],"batl":[[0,4.1,20.1]],"ltp":3.6,"tv":71531.38,"id":10350473},{"trd":[[1.39,341.76]],"batl":[[0,1.39,126.09]],"ltp":1.39,"tv":23835.06,"id":9304761}],"tv":95366.44}]}
{"op":"mcm","clk":"4230612411","pt":1631534795620,"mc":[{"id":"1.187557247","rc":[{"trd":[[1.39,346.4]],"batl":[[0,1.39,123.77]],"ltp":1.39,"tv":23839.71,"id":9304761}],"tv":95371.09}]}
{"op":"mcm","clk":"4230612435","pt":1631534795825,"mc":[{"id":"1.187557247","rc":[{"batl":[[2,1.47,766.61]],"ltp":1.39,"tv":23839.71,"id":9304761}]}]}
{"op":"mcm","clk":"4230612648","pt":1631534797605,"mc":[{"id":"1.187557247","rc":[{"batl":[[0,1.38,163.3],[1,1.39,123.77],[2,1.4,249.58]],"ltp":1.39,"tv":23839.71,"id":9304761}]}]}
{"op":"mcm","clk":"4230612761","pt":1631534798710,"mc":[{"id":"1.187557247","rc":[{"batb":[[0,1.36,304.7]],"batl":[[0,1.39,167.45],[1,1.4,249.58],[2,1.47,766.61]],"ltp":1.39,"tv":23839.71,"id":9304761}]}]}
{"op":"mcm","clk":"4230612845","pt":1631534799451,"mc":[{"id":"1.187557247","rc":[{"batl":[[0,1.4,249.58],[1,1.47,766.61],[2,1.48,60.24]],"ltp":1.39,"tv":23839.71,"id":9304761}]}]}
{"op":"mcm","clk":"4230612994","pt":1631534800714,"mc":[{"id":"1.187557247","rc":[{"batl":[[0,3.55,18.23],[1,4.1,20.1],[2,4.2,3.13]],"ltp":3.6,"tv":71531.38,"id":10350473},{"batb":[[0,1.39,79.29],[1,1.34,422.44],[2,1.33,86.53]],"batl":[[0,1.47,766.61],[1,1.48,60.24],[2,1.7,9.83]],"ltp":1.39,"tv":23839.71,"id":9304761}]}]}
{"op":"mcm","clk":"4230613121","pt":1631534801643,"mc":[{"id":"1.187557247","rc":[{"batb":[[0,3.05,4.69],[1,1.35,2.32],[2,1.28,720.76]],"batl":[[0,3.55,37.97],[1,3.6,17.97],[2,4.1,3.35]],"ltp":3.6,"tv":71531.38,"id":10350473},{"trd":[[1.39,469.14]],"batb":[[0,1.39,198.78]],"ltp":1.39,"tv":23962.45,"id":9304761}],"tv":95493.83}]}
{"op":"mcm","clk":"4230613256","pt":1631534802752,"mc":[{"id":"1.187557247","rc":[{"batl":[[0,3.55,19.74],[1,3.6,29.22]],"ltp":3.6,"tv":71531.38,"id":10350473},{"batb":[[0,1.39,25]],"ltp":1.39,"tv":23962.45,"id":9304761}]}]}
{"op":"mcm","clk":"4230613362","pt":1631534803706,"mc":[{"id":"1.187557247","rc":[{"batl":[[0,3.55,1.51],[1,4.1,3.35],[2,4.2,3.13]],"ltp":3.6,"tv":71531.38,"id":10350473},{"batb":[[0,1.4,61.5],[1,1.39,56.03],[2,1.34,422.44]],"batl":[[0,1.47,231.16],[1,1.48,255.7]],"ltp":1.39,"tv":23962.45,"id":9304761}]}]}
{"op":"mcm","clk":"4230613470","pt":1631534804646,"mc":[{"id":"1.187557247","rc":[{"batb":[[0,1.4,92.25],[1,1.39,25]],"ltp":1.39,"tv":23962.45,"id":9304761}]}]}
{"op":"mcm","clk":"4230613555","pt":1631534805334,"mc":[{"id":"1.187557247","rc":[{"batb":[[0,1.39,31.51],[1,1.34,422.44],[2,1.33,86.53]],"ltp":1.39,"tv":23962.45,"id":9304761}]}]}
{"op":"mcm","clk":"4230613695","pt":1631534806749,"mc":[{"id":"1.187557247","rc":[{"batl":[[0,3.55,6.55]],"ltp":3.6,"tv":71531.38,"id":10350473},{"batb":[[0,1.39,36.64],[1,1.38,9.76],[2,1.34,422.44]],"ltp":1.39,"tv":23962.45,"id":9304761}]}]}
{"op":"mcm","clk":"4230613899","pt":1631534808443,"mc":[{"id":"1.187557247","rc":[{"batb":[[0,1.39,6.51]],"ltp":1.39,"tv":23962.45,"id":9304761}]}]}
{"op":"mcm","clk":"4230614169","pt":1631534810749,"mc":[{"id":"1.187557247","rc":[{"batb":[[2,1.35,18.08]],"batl":[[0,1.48,60.24],[1,1.7,9.83],[2,1.71,766.61]],"ltp":1.39,"tv":23962.45,"id":9304761}]}]}
{"op":"mcm","clk":"4230614244","pt":1631534811344,"mc":[{"id":"1.187557247","rc":[{"trd":[[3.55,6.55]],"batl":[[0,4.1,3.35],[1,4.2,3.13],[2,4.4,2.89]],"ltp":3.55,"tv":71537.92,"id":10350473},{"trd":[[1.38,182.84],[1.39,498.88]],"batb":[[0,1.35,18.08],[1,1.34,422.44],[2,1.33,86.53]],"ltp":1.38,"tv":24011.71,"id":9304761}],"tv":95549.63}]}
{"op":"mcm","clk":"4230614343","pt":1631534812343,"mc":[{"id":"1.187557247","rc":[{"batb":[[0,1.39,4.46],[1,1.35,18.08],[2,1.34,422.44]],"ltp":1.38,"tv":24011.71,"id":9304761}]}]}
{"op":"mcm","clk":"4230614505","pt":1631534813758,"mc":[{"id":"1.187557247","rc":[{"trd":[[3.6,4.04],[3.9,6.26]],"batb":[[0,3.9,490.39],[1,3.85,475.96],[2,3.8,475.96]],"ltp":3.9,"tv":71545.9,"id":10350473},{"trd":[[1.35,18.08],[1.39,503.34]],"batb":[[0,1.34,422.44],[1,1.33,86.53],[2,1.32,273.02]],"batl":[[0,1.35,401.33],[1,1.36,282.97],[2,1.48,60.24]],"ltp":1.35,"tv":24034.25,"id":9304761}],"tv":95580.16}]}
{"op":"mcm","clk":"4230614637","pt":1631534814758,"mc":[{"id":"1.187557247","rc":[{"trd":[[3.9,18.76]],"batb":[[0,3.9,484.14]],"ltp":3.9,"tv":71558.4,"id":10350473},{"batl":[[2,1.39,766.61]],"ltp":1.35,"tv":24034.25,"id":9304761}],"tv":95592.66}]}
{"op":"mcm","clk":"4230614711","pt":1631534815234,"mc":[{"id":"1.187557247","rc":[{"batl":[[2,1.39,771.61]],"ltp":1.35,"tv":24034.25,"id":9304761}]}]}
{"op":"mcm","clk":"4230615034","pt":1631534817762,"mc":[{"id":"1.187557247","rc":[{"batb":[[0,1.34,495.03],[2,1.32,93.64]],"batl":[[0,1.35,77.93],[1,1.36,79.48]],"ltp":1.35,"tv":24034.25,"id":9304761}]}]}
{"op":"mcm","clk":"4230615109","pt":1631534818341,"mc":[{"id":"1.187557247","rc":[{"trd":[[3.95,24.24]],"ltp":3.95,"tv":71582.64,"id":10350473},{"trd":[[1.34,76.12]],"batb":[[0,1.34,421.24],[1,1.33,165.29]],"ltp":1.34,"tv":24110.37,"id":9304761}],"tv":95693.02}]}
{"op":"mcm","clk":"4230615284","pt":1631534819757,"mc":[{"id":"1.187557247","rc":[{"batl":[[2,1.38,61.75]],"ltp":1.34,"tv":24110.37,"id":9304761}]}]}
{"op":"mcm","clk":"4230615412","pt":1631534820663,"mc":[{"id":"1.187557247","rc":[{"trd":[[3.9,32.62]],"batb":[[0,3.9,470.28]],"ltp":3.9,"tv":71596.5,"id":10350473},{"trd":[[1.35,213.97]],"batl":[[0,1.36,79.48],[1,1.38,61.75],[2,1.4,59.99]],"ltp":1.35,"tv":24306.27,"id":9304761}],"tv":95902.77}]}
{"op":"mcm","clk":"4230615554","pt":1631534821764,"mc":[{"id":"1.187557247","rc":[{"trd":[[3.9,129.94]],"batb":[[0,3.9,378.5]],"ltp":3.9,"tv":71693.81,"id":10350473},{"trd":[[1.34,201.63],[1.35,463.15]],"batb":[[0,1.34,358.48]],"ltp":1.35,"tv":24680.96,"id":9304761}],"tv":96374.77}]}
{"op":"mcm","clk":"4230615643","pt":1631534822448,"mc":[{"id":"1.187557247","rc":[{"trd":[[3.9,235.89]],"batb":[[0,3.9,325.53]],"ltp":3.9,"tv":71799.77,"id":10350473}],"tv":96480.73}]}
{"op":"mcm","clk":"4230615948","pt":1631534824766,"mc":[{"id":"1.187557247","rc":[{"trd":[[1.35,487.44]],"batb":[[2,1.32,423.69]],"batl":[[0,1.35,387.15],[1,1.36,362.44],[2,1.38,61.75]],"ltp":1.35,"tv":24705.24,"id":9304761}],"tv":96505.01}]}
{"op":"mcm","clk":"4230616076","pt":1631534825661,"mc":[{"id":"1.187557247","rc":[{"trd":[[1.35,730.99]],"batb":[[0,1.34,285.89],[1,1.33,86.53]],"batl":[[0,1.35,265.39],[2,1.37,57.47]],"ltp":1.35,"tv":24948.79,"id":9304761}],"tv":96748.56}]}
{"op":"mcm","clk":"4230616258","pt":1631534826762,"mc":[{"id":"1.187557247","rc":[{"trd":[[3.9,254.63]],"batb":[[0,3.9,316.16]],"ltp":3.9,"tv":71818.51,"id":10350473},{"trd":[[1.35,735.63]],"batl":[[0,1.35,263.07],[1,1.36,282.96],[2,1.38,61.75]],"ltp":1.35,"tv":24953.43,"id":9304761}],"tv":96771.95}]}
{"op":"mcm","clk":"4230616303","pt":1631534827181,"mc":[{"id":"1.187557247","rc":[{"trd":[[1.35,753.74]],"batl":[[0,1.35,254.02]],"ltp":1.35,"tv":24971.54,"id":9304761}],"tv":96790.05}]}
{"op":"mcm","clk":"4230616475","pt":1631534828487,"mc":[{"id":"1.187557247","rc":[{"batb":[[2,1.32,499.59]],"batl":[[0,1.35,313.93]],"ltp":1.35,"tv":24971.54,"id":9304761}]}]}
{"op":"mcm","clk":"4230616538","pt":1631534829071,"mc":[{"id":"1.187557247","rc":[{"trd":[[1.35,762.25]],"batl":[[0,1.35,309.67]],"ltp":1.35,"tv":24980.06,"id":9304761}],"tv":96798.57}]}
{"op":"mcm","clk":"4230616711","pt":1631534830586,"mc":[{"id":"1.187557247","rc":[{"trd":[[1.35,816.76]],"batl":[[0,1.35,282.42]],"ltp":1.35,"tv":25034.57,"id":9304761}],"tv":96853.08}]}
{"op":"mcm","clk":"4230616840","pt":1631534831687,"mc":[{"id":"1.187557247","rc":[{"trd":[[3.9,296.6]],"batb":[[0,3.9,274.19]],"ltp":3.9,"tv":71860.48,"id":10350473},{"trd":[[1.35,1502.93]],"batl":[[0,1.36,282.96],[1,1.38,61.75],[2,1.4,59.99]],"ltp":1.35,"tv":25720.73,"id":9304761}],"tv":97581.21}]}
{"op":"mcm","clk":"4230616959","pt":1631534832680,"mc":[{"id":"1.187557247","rc":[{"batb":[[0,3.6,3.34],[1,3.5,4.08],[2,3.05,4.69]],"ltp":3.9,"tv":71860.48,"id":10350473},{"batb":[[2,1.32,351.01]],"ltp":1.35,"tv":25720.73,"id":9304761}]}]}
{"op":"mcm","clk":"4230617060","pt":1631534833571,"mc":[{"id":"1.187557247","rc":[{"batb":[[0,3.5,4.08],[1,1.35,2.32],[2,1.28,720.76]],"batl":[[0,4.5,2.77],[1,4.9,2.85],[2,5,2.34]],"ltp":3.9,"tv":71860.48,"id":10350473},{"batb":[[1,1.32,30],[2,1.31,10.41]],"batl":[[0,1.4,59.99],[1,1.47,12.97],[2,1.71,766.61]],"ltp":1.35,"tv":25720.73,"id":9304761}]}]}
{"op":"mcm","clk":"4230617172","pt":1631534834597,"mc":[{"id":"1.187557247","rc":[{"batb":[[1,1.31,10.41],[2,1.29,99.81]],"ltp":1.35,"tv":25720.73,"id":9304761}]}]}
{"op":"mcm","clk":"4230617293","pt":1631534835627,"mc":[{"id":"1.187557247","rc":[{"batl":[[0,3.9,40],[1,4.5,2.77],[2,4.9,2.85]],"ltp":3.9,"tv":71860.48,"id":10350473}]}]}
{"op":"mcm","clk":"4230617428","pt":1631534836701,"mc":[{"id":"1.187557247","rc":[{"batb":[[0,3.6,3.64],[1,3.5,7.08],[2,3.45,2]],"batl":[[0,3.9,144.4]],"ltp":3.9,"tv":71860.48,"id":10350473},{"batl":[[0,1.38,60.25],[1,1.4,66.99],[2,1.41,351.06]],"ltp":1.35,"tv":25720.73,"id":9304761}]}]}
{"op":"mcm","clk":"4230617540","pt":1631534837700,"mc":[{"id":"1.187557247","rc":[{"batb":[[0,3.5,7.08],[1,3.45,2],[2,1.35,2.32]],"batl":[[0,3.9,26.8]],"ltp":3.9,"tv":71860.48,"id":10350473},{"batb":[[0,1.35,2.32],[1,1.34,285.89]],"batl":[[0,1.4,66.99],[1,1.47,12.97],[2,1.71,766.61]],"ltp":1.35,"tv":25720.73,"id":9304761}]}]}
{"op":"mcm","clk":"4230617570","pt":1631534837969,"mc":[{"id":"1.187557247","rc":[{"batl":[[0,4.5,2.77],[1,4.9,2.85],[2,5,2.34]],"ltp":3.9,"tv":71860.48,"id":10350473}]}]}
{"op":"mcm","clk":"4230617734","pt":1631534839682,"mc":[{"id":"1.187557247","rc":[{"batl":[[0,1.38,837.2],[1,1.39,17.55],[2,1.4,66.99]],"ltp":1.35,"tv":25720.73,"id":9304761}]}]}
{"op":"mcm","clk":"4230617832","pt":1631534840609,"mc":[{"id":"1.187557247","rc":[{"batb":[[0,3.6,2.99],[1,3.55,35.4],[2,3.5,7.08]],"ltp":3.9,"tv":71860.48,"id":10350473},{"trd":[[1.35,1507.57]],"batb":[[0,1.34,285.89],[1,1.31,477.44],[2,1.3,366.43]],"batl":[[0,1.35,435.12],[1,1.36,479.13],[2,1.38,70.25]],"ltp":1.35,"tv":25725.38,"id":9304761}],"tv":97585.86}]}
{"op":"mcm","clk":"4230617953","pt":1631534841708,"mc":[{"id":"1.187557247","rc":[{"batb":[[1,3.5,7.08],[2,3.45,2]],"batl":[[0,4.4,13.85],[1,4.5,2.77],[2,4.9,2.85]],"ltp":3.9,"tv":71860.48,"id":10350473},{"batb":[[2,1.3,379.12]],"ltp":1.35,"tv":25725.38,"id":9304761}]}]}
{"op":"mcm","clk":"4230618227","pt":1631534844402,"mc":[{"id":"1.187557247","rc":[{"batb":[[0,1.31,477.44],[1,1.3,379.12],[2,1.29,99.81]],"batl":[[1,1.36,353.47]],"ltp":1.35,"tv":25725.38,"id":9304761}]}]}
{"op":"mcm","clk":"4230618381","pt":1631534845600,"mc":[{"id":"1.187557247","rc":[{"batb":[[0,3.5,7.08],[1,3.45,2],[2,1.35,2.32]],"batl":[[0,4.9,2.85],[1,990,0.01],[2,4.9,0]],"ltp":3.9,"tv":71860.48,"id":10350473},{"batb":[[0,1.3,12.69],[1,1.26,98.98],[2,1.2,2]],"batl":[[0,1.39,17.55],[1,1.4,66.99],[2,1.47,12.97]],"ltp":1.35,"tv":25725.38,"id":9304761}]}]}
{"op":"mcm","clk":"4230618587","pt":1631534847688,"mc":[{"id":"1.187557247","rc":[{"trd":[[3.65,0.95]],"batb":[[0,3.65,14],[1,3.5,7.08],[2,3.45,2]],"ltp":3.65,"tv":71861.43,"id":10350473},{"trd":[[1.38,185.36]],"ltp":1.38,"tv":25727.89,"id":9304761}],"tv":97589.33}]}
{"op":"mcm","clk":"4230618676","pt":1631534848511,"mc":[{"id":"1.187557247","rc":[{"batb":[[0,3.6,3.34],[2,1.35,2.32]],"batl":[[0,4.5,3.13],[1,4.9,2.85],[2,990,0.01]],"ltp":3.65,"tv":71861.43,"id":10350473},{"batb":[[1,1.29,103.81],[2,1.28,266.84]],"batl":[[0,1.38,60.25],[1,1.39,17.55],[2,1.4,66.99]],"ltp":1.38,"tv":25727.89,"id":9304761}]}]}
{"op":"mcm","clk":"4230618743","pt":1631534849105,"mc":[{"id":"1.187557247","rc":[{"batb":[[0,3.5,7.08],[1,1.35,2.32],[2,1.28,720.76]],"batl":[[0,4.9,2.85],[1,990,0.01],[2,990,0]],"ltp":3.65,"tv":71861.43,"id":10350473},{"batb":[[0,1.28,266.84],[1,1.27,414.3],[2,1.26,98.98]],"batl":[[0,1.39,17.55],[1,1.4,66.99],[2,1.47,12.97]],"ltp":1.38,"tv":25727.89,"id":9304761}]}]}
{"op":"mcm","clk":"4230619031","pt":1631534851722,"mc":[{"id":"1.187557247","rc":[{"trd":[[3.85,2.32]],"batb":[[1,3.45,3],[2,1.35,2.32]],"batl":[[0,4.8,796.88],[1,4.9,776.29],[2,5,773.44]],"ltp":3.85,"tv":71863.75,"id":10350473},{"trd":[[1.35,1514.2]],"batl":[[0,1.31,3655.62],[1,1.32,2897.72],[2,1.33,2812.5]],"ltp":1.35,"tv":25734.52,"id":9304761}],"tv":97598.28}]}
{"op":"mcm","clk":"4230619136","pt":1631534852627,"mc":[{"id":"1.187557247","rc":[{"trd":[[4.2,5.71]],"batl":[[0,4.8,219.14],[1,4.9,215.55],[2,5,212.7]],"ltp":4.2,"tv":71869.46,"id":10350473},{"trd":[[1.31,18.31]],"batl":[[0,1.31,465.92],[1,1.32,1772.44],[2,1.33,1406.26]],"ltp":1.31,"tv":25752.83,"id":9304761}],"tv":97622.3}]}
{"op":"mcm","clk":"4230619230","pt":1631534853416,"mc":[{"id":"1.187557247","rc":[{"batb":[[0,3.8,35.4],[1,3.5,7.08],[2,3.45,3]],"ltp":4.2,"tv":71869.46,"id":10350473}]}]}
{"op":"mcm","clk":"4230619380","pt":1631534854722,"mc":[{"id":"1.187557247","rc":[{"batb":[[0,3.85,2],[1,3.8,3],[2,3.6,2]],"ltp":4.2,"tv":71869.46,"id":10350473}]}]}
{"op":"mcm","clk":"4230619491","pt":1631534855718,"mc":[{"id":"1.187557247","rc":[{"batb":[[0,3.95,3],[1,3.9,3],[2,3.85,2]],"ltp":4.2,"tv":71869.46,"id":10350473}]}]}
{"op":"mcm","clk":"4230619597","pt":1631534856605,"mc":[{"id":"1.187557247","rc":[{"trd":[[4.5,0.74]],"batl":[[0,4.7,14.25],[1,4.8,219.14],[2,4.9,215.55]],"ltp":4.5,"tv":71870.2,"id":10350473},{"trd":[[1.29,7.96]],"batb":[[0,1.29,53],[1,1.28,331.56],[2,1.27,414.3]],"batl":[[0,1.3,224.59],[1,1.31,532.39],[2,1.32,1772.44]],"ltp":1.29,"tv":25760.8,"id":9304761}],"tv":97631.0}]}
{"op":"mcm","clk":"4230619700","pt":1631534857709,"mc":[{"id":"1.187557247","rc":[{"trd":[[4.3,20.14]],"ltp":4.3,"tv":71890.34,"id":10350473},{"trd":[[1.3,66.64]],"batl":[[0,1.3,107.13]],"ltp":1.3,"tv":25827.44,"id":9304761}],"tv":97717.79}]}
{"op":"mcm","clk":"4230619796","pt":1631534858603,"mc":[{"id":"1.187557247","rc":[{"batb":[[0,4.1,2.94],[1,3.95,3],[2,3.9,5.76]],"ltp":4.3,"tv":71890.34,"id":10350473},{"batl":[[0,1.3,70.2],[2,1.32,1856.55]],"ltp":1.3,"tv":25827.44,"id":9304761}]}]}
{"op":"mcm","clk":"4230619927","pt":1631534859708,"mc":[{"id":"1.187557247","rc":[{"batb":[[1,3.9,5.76],[2,3.85,2]],"ltp":4.3,"tv":71890.34,"id":10350473}]}]}
{"op":"mcm","clk":"4230619945","pt":1631534859911,"mc":[{"id":"1.187557247","rc":[{"batl":[[1,1.31,485.7]],"ltp":1.3,"tv":25827.44,"id":9304761}]}]}
{"op":"mcm","clk":"4230620224","pt":1631534862538,"mc":[{"id":"1.187557247","rc":[{"trd":[[1.3,81.98]],"batl":[[0,1.3,62.53]],"ltp":1.3,"tv":25842.77,"id":9304761}],"tv":97733.12}]}
{"op":"mcm","clk":"4230620360","pt":1631534863723,"mc":[{"id":"1.187557247","rc":[{"batb":[[1,1.28,379.5]],"batl":[[1,1.31,474.97]],"ltp":1.3,"tv":25842.77,"id":9304761}]}]}
{"op":"mcm","clk":"4230620470","pt":1631534864614,"mc":[{"id":"1.187557247","rc":[{"batb":[[0,4.2,14.7],[1,4.1,2.94],[2,3.9,5.76]],"ltp":4.3,"tv":71890.34,"id":10350473},{"batb":[[0,1.29,122.41],[1,1.28,314.78]],"batl":[[1,1.31,408.5]],"ltp":1.3,"tv":25842.77,"id":9304761}]}]}
{"op":"mcm","clk":"4230621320","pt":1631534872548,"mc":[{"id":"1.187557247","rc":[{"batb":[[0,3.9,5.76],[1,1.35,2.32],[2,1.28,720.76]],"batl":[[0,5.2,2.83],[1,990,0.01],[2,4.9,0]],"ltp":4.3,"tv":71890.34,"id":10350473},{"batb":[[0,1.25,11.49],[1,1.24,105.77],[2,1.2,2]],"batl":[[0,1.34,72.75],[1,1.37,10.72],[2,1.38,7]],"ltp":1.3,"tv":25842.77,"id":9304761}]}]}
