{"op":"mcm","clk":"4230621630","pt":1631534875478,"mc":[{"id":"1.187557247","rc":[{"batb":[[0,4.1,2.54],[1,3.9,5.76],[2,3.85,3]],"ltp":4.3,"tv":71890.34,"id":10350473},{"batb":[[0,1.25,437.79],[1,1.24,587.3]],"batl":[[0,1.32,80.11],[1,1.34,451.89],[2,1.35,289.63]],"ltp":1.3,"tv":25842.77,"id":9304761}]}]}
{"op":"mcm","clk":"4230621695","pt":1631534876051,"mc":[{"id":"1.187557247","rc":[{"batb":[[0,3.9,5.76],[1,3.85,3],[2,1.35,2.32]],"ltp":4.3,"tv":71890.34,"id":10350473},{"batl":[[0,1.34,451.89],[1,1.35,289.63],[2,1.37,10.72]],"ltp":1.3,"tv":25842.77,"id":9304761}]}]}
{"op":"mcm","clk":"4230621869","pt":1631534877658,"mc":[{"id":"1.187557247","rc":[{"batl":[[0,5.2,3.73]],"ltp":4.3,"tv":71890.34,"id":10350473},{"batb":[[0,1.25,11.49],[1,1.24,105.77]],"batl":[[0,1.34,81.75],[1,1.37,10.72],[2,1.38,7]],"ltp":1.3,"tv":25842.77,"id":9304761}]}]}
{"op":"mcm","clk":"4230622096","pt":1631534879641,"mc":[{"id":"1.187557247","rc":[{"batb":[[0,3.9,2.76],[1,1.35,2.32],[2,1.28,720.76]],"ltp":4.3,"tv":71890.34,"id":10350473},{"batl":[[0,1.34,72.75],[2,44,7.23]],"ltp":1.3,"tv":25842.77,"id":9304761}]}]}
{"op":"mcm","clk":"4230622188","pt":1631534880698,"mc":[{"id":"1.187557247","rc":[{"batb":[[0,1.24,105.77],[1,1.2,2],[2,1.06,2.07]],"ltp":1.3,"tv":25842.77,"id":9304761}]}]}
{"op":"mcm","clk":"4230622361","pt":1631534882474,"mc":[{"id":"1.187557247","rc":[{"batb":[[0,4.1,2.74],[1,3.9,2.76],[2,1.35,2.32]],"ltp":4.3,"tv":71890.34,"id":10350473},{"batl":[[0,1.32,78.86],[1,1.34,72.75],[2,1.37,10.72]],"ltp":1.3,"tv":25842.77,"id":9304761}]}]}
{"op":"mcm","clk":"4230622489","pt":1631534883684,"mc":[{"id":"1.187557247","rc":[{"trd":[[4.3,21.04]],"batb":[[0,4.5,425],[1,4.4,412.5],[2,4.3,412.5]],"batl":[[0,5.2,2.83],[1,5.3,360.84],[2,5.4,350.24]],"ltp":4.3,"tv":71891.24,"id":10350473},{"trd":[[1.3,84.96]],"batb":[[0,1.25,426.3],[1,1.24,587.3],[2,1.2,2]],"batl":[[0,1.28,4600.37],[1,1.29,364.87],[2,1.33,457.32]],"ltp":1.3,"tv":25845.75,"id":9304761}],"tv":97737.0}]}
{"op":"mcm","clk":"4230622583","pt":1631534884684,"mc":[{"id":"1.187557247","rc":[{"trd":[[4.5,11.4]],"batb":[[0,4.5,419.67]],"batl":[[0,5.1,12.57],[1,5.2,2.83],[2,5.3,360.84]],"ltp":4.5,"tv":71901.9,"id":10350473},{"batb":[[1,1.24,650.92]],"batl":[[0,1.28,479.78],[2,1.3,766.61]],"ltp":1.3,"tv":25845.75,"id":9304761}],"tv":97747.66}]}
{"op":"mcm","clk":"4230622773","pt":1631534886681,"mc":[{"id":"1.187557247","rc":[{"trd":[[1.28,26.04]],"batl":[[0,1.28,466.76]],"ltp":1.28,"tv":25871.79,"id":9304761}],"tv":97773.69}]}
{"op":"mcm","clk":"4230622866","pt":1631534887671,"mc":[{"id":"1.187557247","rc":[{"batb":[[0,1.26,76.16],[1,1.25,426.3],[2,1.24,650.92]],"batl":[[0,1.27,70.62],[1,1.28,466.76],[2,1.29,364.87]],"ltp":1.28,"tv":25871.79,"id":9304761}]}]}
{"op":"mcm","clk":"4230622938","pt":1631534888400,"mc":[{"id":"1.187557247","rc":[{"batb":[[0,4.6,13.8],[1,4.5,419.67],[2,4.4,412.5]],"ltp":4.5,"tv":71901.9,"id":10350473},{"batl":[[1,1.28,647.21]],"ltp":1.28,"tv":25871.79,"id":9304761}]}]}
{"op":"mcm","clk":"4230623497","pt":1631534894087,"mc":[{"id":"1.187557247","rc":[{"batl":[[0,1.27,89.84]],"ltp":1.28,"tv":25871.79,"id":9304761}]}]}
{"op":"mcm","clk":"4230623653","pt":1631534895604,"mc":[{"id":"1.187557247","rc":[{"batb":[[0,1.26,153.2]],"batl":[[0,1.27,159.97],[1,1.28,627.24]],"ltp":1.28,"tv":25871.79,"id":9304761}]}]}
{"op":"mcm","clk":"4230623681","pt":1631534895871,"mc":[{"id":"1.187557247","rc":[{"batb":[[0,1.26,76.16]],"batl":[[0,1.27,89.84]],"ltp":1.28,"tv":25871.79,"id":9304761}]}]}
{"op":"mcm","clk":"4230624265","pt":1631534901721,"mc":[{"id":"1.187557247","rc":[{"trd":[[1.27,39.05]],"batl":[[0,1.27,70.31]],"ltp":1.27,"tv":25910.84,"id":9304761}],"tv":97812.75}]}
{"op":"mcm","clk":"4230624607","pt":1631534905109,"mc":[{"id":"1.187557247","rc":[{"trd":[[4.7,2.34],[4.9,0.7]],"ltp":4.9,"tv":71904.94,"id":10350473},{"trd":[[1.26,8.15],[1.27,47.73]],"batb":[[0,1.26,70.72]],"batl":[[0,1.27,61.64]],"ltp":1.26,"tv":25927.67,"id":9304761}],"tv":97832.62}]}
{"op":"mcm","clk":"4230624851","pt":1631534907211,"mc":[{"id":"1.187557247","rc":[{"trd":[[1.26,34.19]],"batb":[[0,1.26,57.69]],"ltp":1.26,"tv":25953.71,"id":9304761}],"tv":97858.65}]}
{"op":"mcm","clk":"4230625134","pt":1631534909720,"mc":[{"id":"1.187557247","rc":[{"trd":[[1.27,85.23]],"batl":[[0,1.27,42.88]],"ltp":1.27,"tv":25991.21,"id":9304761}],"tv":97896.16}]}
{"op":"mcm","clk":"4230625158","pt":1631534909929,"mc":[{"id":"1.187557247","rc":[{"trd":[[1.27,89.88]],"batl":[[0,1.27,40.55]],"ltp":1.27,"tv":25995.86,"id":9304761}],"tv":97900.81}]}
{"op":"mcm","clk":"4230625274","pt":1631534910991,"mc":[{"id":"1.187557247","rc":[{"trd":[[1.27,94.53]],"batl":[[0,1.27,38.23]],"ltp":1.27,"tv":26000.51,"id":9304761}],"tv":97905.46}]}
{"op":"mcm","clk":"4230625541","pt":1631534913398,"mc":[{"id":"1.187557247","rc":[{"trd":[[1.27,102.34]],"batl":[[0,1.27,34.32]],"ltp":1.27,"tv":26008.33,"id":9304761}],"tv":97913.27}]}
{"op":"mcm","clk":"4230625676","pt":1631534914761,"mc":[{"id":"1.187557247","rc":[{"batl":[[1,1.28,606.36]],"ltp":1.27,"tv":26008.33,"id":9304761}]}]}
{"op":"mcm","clk":"4230625949","pt":1631534917326,"mc":[{"id":"1.187557247","rc":[{"trd":[[1.26,39.4]],"batb":[[0,1.26,55.09],[1,1.25,447.76]],"ltp":1.26,"tv":26013.54,"id":9304761}],"tv":97918.48}]}
{"op":"mcm","clk":"4230626198","pt":1631534919727,"mc":[{"id":"1.187557247","rc":[{"trd":[[4.7,2.85]],"ltp":4.7,"tv":71905.45,"id":10350473},{"trd":[[1.27,104.21]],"batl":[[0,1.27,32.45]],"ltp":1.27,"tv":26015.4,"id":9304761}],"tv":97920.85}]}
{"op":"mcm","clk":"4230626309","pt":1631534920725,"mc":[{"id":"1.187557247","rc":[{"trd":[[4.7,11.62]],"batl":[[0,4.7,11.03],[1,5.1,12.57],[2,5.2,2.83]],"ltp":4.7,"tv":71914.22,"id":10350473},{"trd":[[1.27,136.66]],"batb":[[1,1.24,169.39],[2,1.21,13.38]],"batl":[[0,1.28,180.45],[1,1.31,14.81],[2,1.34,72.75]],"ltp":1.27,"tv":26047.85,"id":9304761}],"tv":97962.08}]}
{"op":"mcm","clk":"4230626389","pt":1631534921505,"mc":[{"id":"1.187557247","rc":[{"batb":[[0,1.27,106.26]],"batl":[[0,1.31,14.81],[1,1.34,72.75],[2,8.8,7.23]],"ltp":1.27,"tv":26047.85,"id":9304761}]}]}
{"op":"mcm","clk":"4230626610","pt":1631534923700,"mc":[{"id":"1.187557247","rc":[{"batb":[[2,1.21,480.76]],"batl":[[1,1.33,279.61],[2,1.34,374.15]],"ltp":1.27,"tv":26047.85,"id":9304761}]}]}
{"op":"mcm","clk":"4230626723","pt":1631534924734,"mc":[{"id":"1.187557247","rc":[{"batb":[[0,1.27,4.26]],"batl":[[0,1.31,170.39]],"ltp":1.27,"tv":26047.85,"id":9304761}]}]}
{"op":"mcm","clk":"4230626918","pt":1631534926719,"mc":[{"id":"1.187557247","rc":[{"batb":[[0,1.27,28.66]],"ltp":1.27,"tv":26047.85,"id":9304761}]}]}
{"op":"mcm","clk":"4230626982","pt":1631534927352,"mc":[{"id":"1.187557247","rc":[{"trd":[[4.6,13.8]],"batb":[[0,4.5,419.67],[1,4.4,412.5],[2,4.3,412.5]],"ltp":4.6,"tv":71928.02,"id":10350473},{"trd":[[1.28,75.63]],"batb":[[0,1.28,52.41],[1,1.27,28.66],[2,1.24,169.39]],"ltp":1.28,"tv":26097.44,"id":9304761}],"tv":98025.47}]}
{"op":"mcm","clk":"4230627254","pt":1631534930033,"mc":[{"id":"1.187557247","rc":[{"batl":[[0,5.1,12.57],[1,5.2,2.83],[2,5.3,360.84]],"ltp":4.6,"tv":71928.02,"id":10350473}]}]}
{"op":"mcm","clk":"4230627418","pt":1631534931514,"mc":[{"id":"1.187557247","rc":[{"trd":[[4.6,14.9]],"batb":[[0,4.6,10.66],[1,4.5,419.67],[2,4.4,412.5]],"ltp":4.6,"tv":71929.12,"id":10350473},{"trd":[[1.28,176.5]],"batb":[[0,1.27,28.66],[1,1.24,169.39],[2,1.21,480.76]],"ltp":1.28,"tv":26198.31,"id":9304761}],"tv":98127.44}]}
{"op":"mcm","clk":"4230627474","pt":1631534932033,"mc":[{"id":"1.187557247","rc":[{"batb":[[0,4.5,419.67],[1,4.4,412.5],[2,4.3,412.5]],"ltp":4.6,"tv":71929.12,"id":10350473},{"batb":[[0,1.28,50],[1,1.27,28.66],[2,1.24,169.39]],"ltp":1.28,"tv":26198.31,"id":9304761}]}]}
{"op":"mcm","clk":"4230627662","pt":1631534933721,"mc":[{"id":"1.187557247","rc":[{"trd":[[4.5,33.46]],"batb":[[0,4.2,3],[1,3.9,2.76],[2,1.35,2.32]],"batl":[[1,990,0.01],[2,5.3,0]],"ltp":4.5,"tv":71951.18,"id":10350473},{"batb":[[2,1.24,63.62]],"batl":[[0,1.31,167.39]],"ltp":1.28,"tv":26198.31,"id":9304761}],"tv":98149.5}]}
{"op":"mcm","clk":"4230627674","pt":1631534933829,"mc":[{"id":"1.187557247","rc":[{"batl":[[0,990,0.01],[1,990,0]],"ltp":4.5,"tv":71951.18,"id":10350473},{"batb":[[2,1.21,480.76]],"batl":[[0,1.31,11.81]],"ltp":1.28,"tv":26198.31,"id":9304761}]}]}
{"op":"mcm","clk":"4230627860","pt":1631534935572,"mc":[{"id":"1.187557247","rc":[{"batb":[[0,3.9,2.76],[1,1.35,2.32],[2,1.28,720.76]],"ltp":4.5,"tv":71951.18,"id":10350473},{"trd":[[1.28,181.14]],"batb":[[0,1.28,47.68]],"ltp":1.28,"tv":26202.96,"id":9304761}],"tv":98154.14}]}
{"op":"mcm","clk":"4230627993","pt":1631534936637,"mc":[{"id":"1.187557247","rc":[{"batb":[[1,3.7,3.42],[2,1.35,2.32]],"batl":[[0,5.8,2.37],[1,7,2],[2,990,0.01]],"ltp":4.5,"tv":71951.18,"id":10350473},{"batb":[[2,1.21,592.45]],"ltp":1.28,"tv":26202.96,"id":9304761}]}]}
{"op":"mcm","clk":"4230628053","pt":1631534937156,"mc":[{"id":"1.187557247","rc":[{"batb":[[0,1.3,4.88],[1,1.28,47.68],[2,1.27,28.66]],"ltp":1.28,"tv":26202.96,"id":9304761}]}]}
{"op":"mcm","clk":"4230628225","pt":1631534938735,"mc":[{"id":"1.187557247","rc":[{"batb":[[0,4,3],[1,3.95,2],[2,3.9,2.76]],"ltp":4.5,"tv":71951.18,"id":10350473}]}]}
{"op":"mcm","clk":"4230628288","pt":1631534939370,"mc":[{"id":"1.187557247","rc":[{"batl":[[0,4.5,25],[1,5.8,2.37],[2,7,2]],"ltp":4.5,"tv":71951.18,"id":10350473}]}]}
{"op":"mcm","clk":"4230628362","pt":1631534940052,"mc":[{"id":"1.187557247","rc":[{"batl":[[0,1.33,279.61],[1,1.34,374.15],[2,1.37,64.5]],"ltp":1.28,"tv":26202.96,"id":9304761}]}]}
{"op":"mcm","clk":"4230628544","pt":1631534941650,"mc":[{"id":"1.187557247","rc":[{"batb":[[1,1.27,28.66],[2,1.21,125.07]],"ltp":1.28,"tv":26202.96,"id":9304761}]}]}
{"op":"mcm","clk":"4230628667","pt":1631534942750,"mc":[{"id":"1.187557247","rc":[{"trd":[[4,5.88]],"batb":[[0,3.9,2.76],[1,3.7,3.42],[2,1.35,2.32]],"batl":[[0,4.3,573.44],[1,4.4,273.26],[2,4.5,307.91]],"ltp":4.0,"tv":71957.06,"id":10350473},{"trd":[[1.33,17.68]],"batb":[[1,1.29,101.81],[2,1.28,3149.99]],"batl":[[0,1.33,261.93]],"ltp":1.33,"tv":26220.64,"id":9304761}],"tv":98177.7}]}
{"op":"mcm","clk":"4230628766","pt":1631534943745,"mc":[{"id":"1.187557247","rc":[{"batb":[[1,3.8,618.42],[2,3.75,309.2]],"batl":[[0,4.3,109.3],[1,4.4,73.37],[2,4.5,79.66]],"ltp":4.0,"tv":71957.06,"id":10350473},{"batb":[[0,1.3,1328.48],[1,1.29,379.48]],"ltp":1.33,"tv":26220.64,"id":9304761}]}]}
{"op":"mcm","clk":"4230628883","pt":1631534944747,"mc":[{"id":"1.187557247","rc":[{"batb":[[1,3.8,77.3],[2,3.75,38.65]],"batl":[[1,4.4,54.66]],"ltp":4.0,"tv":71957.06,"id":10350473},{"batb":[[0,1.31,47.68],[1,1.3,1164.18],[2,1.29,379.48]],"ltp":1.33,"tv":26220.64,"id":9304761}]}]}
{"op":"mcm","clk":"4230628982","pt":1631534945529,"mc":[{"id":"1.187557247","rc":[{"batb":[[0,3.95,13.8],[1,3.9,2.76],[2,3.8,77.3]],"ltp":4.0,"tv":71957.06,"id":10350473},{"batb":[[0,1.31,814.29]],"ltp":1.33,"tv":26220.64,"id":9304761}]}]}
{"op":"mcm","clk":"4230629210","pt":1631534947668,"mc":[{"id":"1.187557247","rc":[{"trd":[[4.1,4.12]],"batl":[[0,4.3,128.01]],"ltp":4.1,"tv":71961.18,"id":10350473},{"trd":[[1.32,12.8]],"batb":[[0,1.31,897.22],[1,1.3,1233.45]],"batl":[[0,1.32,60.46],[1,1.33,339.77],[2,1.34,374.15]],"ltp":1.32,"tv":26233.44,"id":9304761}],"tv":98194.62}]}
{"op":"mcm","clk":"4230629338","pt":1631534948671,"mc":[{"id":"1.187557247","rc":[{"trd":[[4.3,22.52]],"batl":[[0,4.3,127.27],[2,4.5,54.66]],"ltp":4.3,"tv":71962.66,"id":10350473},{"trd":[[1.31,26.11],[1.32,22.56]],"batb":[[0,1.31,893.32]],"batl":[[0,1.32,55.58]],"ltp":1.31,"tv":26251.01,"id":9304761}],"tv":98213.67}]}
{"op":"mcm","clk":"4230629594","pt":1631534950673,"mc":[{"id":"1.187557247","rc":[{"trd":[[1.32,117.94]],"batl":[[0,1.32,7.89]],"ltp":1.32,"tv":26346.38,"id":9304761}],"tv":98309.04}]}
{"op":"mcm","clk":"4230629642","pt":1631534951039,"mc":[{"id":"1.187557247","rc":[{"trd":[[4,28.34],[4.1,6.66]],"ltp":4.0,"tv":71987.66,"id":10350473},{"trd":[[1.32,125.82],[1.33,88.75]],"batl":[[0,1.33,270.46],[1,1.34,374.15],[2,1.37,64.5]],"ltp":1.33,"tv":26425.34,"id":9304761}],"tv":98413.0}]}
{"op":"mcm","clk":"4230629842","pt":1631534952865,"mc":[{"id":"1.187557247","rc":[{"batb":[[1,1.3,1164.18]],"ltp":1.33,"tv":26425.34,"id":9304761}]}]}
{"op":"mcm","clk":"4230630078","pt":1631534954574,"mc":[{"id":"1.187557247","rc":[{"batb":[[0,3.9,2.76],[1,3.8,77.3],[2,3.75,38.65]],"ltp":4.0,"tv":71987.66,"id":10350473},{"batb":[[1,1.3,1215.56]],"batl":[[0,1.33,307.37]],"ltp":1.33,"tv":26425.34,"id":9304761}]}]}
{"op":"mcm","clk":"4230630144","pt":1631534955074,"mc":[{"id":"1.187557247","rc":[{"batb":[[0,1.32,123.59],[1,1.31,842.61],[2,1.3,1215.56]],"batl":[[2,1.36,11.25]],"ltp":1.33,"tv":26425.34,"id":9304761}]}]}
{"op":"mcm","clk":"4230630434","pt":1631534957683,"mc":[{"id":"1.187557247","rc":[{"batb":[[1,3.7,3.42],[2,3.6,3.49]],"batl":[[0,5.4,2.34],[1,5.8,2.37],[2,6.4,2.09]],"ltp":4.0,"tv":71987.66,"id":10350473},{"batb":[[2,1.3,771.49]],"batl":[[0,1.33,77.84],[1,1.34,72.75]],"ltp":1.33,"tv":26425.34,"id":9304761}]}]}
{"op":"mcm","clk":"4230630459","pt":1631534957844,"mc":[{"id":"1.187557247","rc":[{"batb":[[0,3.4,3.81],[1,1.35,2.32],[2,1.28,720.76]],"ltp":4.0,"tv":71987.66,"id":10350473},{"batb":[[0,1.31,762.71],[1,1.3,771.49],[2,1.27,24.4]],"batl":[[1,1.36,11.25],[2,1.41,55.5]],"ltp":1.33,"tv":26425.34,"id":9304761}]}]}
{"op":"mcm","clk":"4230630677","pt":1631534959577,"mc":[{"id":"1.187557247","rc":[{"batb":[[0,1.31,769.94]],"ltp":1.33,"tv":26425.34,"id":9304761}]}]}
{"op":"mcm","clk":"4230630777","pt":1631534960575,"mc":[{"id":"1.187557247","rc":[{"batl":[[0,1.36,11.25],[1,1.39,196.04],[2,1.4,245.09]],"ltp":1.33,"tv":26425.34,"id":9304761}]}]}
{"op":"mcm","clk":"4230630859","pt":1631534961359,"mc":[{"id":"1.187557247","rc":[{"batl":[[0,1.41,55.5],[1,8.8,7.23],[2,44,7.23]],"ltp":1.33,"tv":26425.34,"id":9304761}]}]}
{"op":"mcm","clk":"4230631067","pt":1631534963693,"mc":[{"id":"1.187557247","rc":[{"batl":[[0,4.4,30.14],[1,5.4,2.34],[2,5.8,2.37]],"ltp":4.0,"tv":71987.66,"id":10350473},{"batb":[[1,1.3,4.88]],"ltp":1.33,"tv":26425.34,"id":9304761}]}]}
{"op":"mcm","clk":"4230631156","pt":1631534964582,"mc":[{"id":"1.187557247","rc":[{"batb":[[0,3.6,6.59],[1,3.55,3],[2,3.4,6.81]],"batl":[[0,5.4,2.34],[1,5.8,2.37],[2,6.4,2.09]],"ltp":4.0,"tv":71987.66,"id":10350473},{"batb":[[0,1.31,1213.42],[1,1.3,368.82]],"batl":[[0,1.34,171.76],[1,1.35,291.22],[2,1.38,80.75]],"ltp":1.33,"tv":26425.34,"id":9304761}]}]}
{"op":"mcm","clk":"4230631278","pt":1631534965682,"mc":[{"id":"1.187557247","rc":[{"batb":[[0,3.6,3]],"batl":[[0,4.7,11.7],[1,5.4,2.34],[2,5.8,2.37]],"ltp":4.0,"tv":71987.66,"id":10350473},{"batb":[[0,1.32,39.41],[1,1.31,769.94],[2,1.3,4.88]],"batl":[[0,1.38,8],[1,1.4,122.08],[2,1.41,61.5]],"ltp":1.33,"tv":26425.34,"id":9304761}]}]}
{"op":"mcm","clk":"4230631310","pt":1631534965996,"mc":[{"id":"1.187557247","rc":[{"batl":[[0,5.4,2.34],[1,5.8,2.37],[2,6.4,2.09]],"ltp":4.0,"tv":71987.66,"id":10350473},{"batb":[[0,1.31,769.94],[1,1.3,4.88],[2,1.27,24.4]],"batl":[[1,1.41,61.5],[2,1.48,13.21]],"ltp":1.33,"tv":26425.34,"id":9304761}]}]}
{"op":"mcm","clk":"4230631564","pt":1631534968586,"mc":[{"id":"1.187557247","rc":[{"batb":[[0,3.6,6.44]],"ltp":4.0,"tv":71987.66,"id":10350473},{"batl":[[0,1.38,74.25],[1,1.39,196.04],[2,1.4,245.09]],"ltp":1.33,"tv":26425.34,"id":9304761}]}]}
{"op":"mcm","clk":"4230631665","pt":1631534969481,"mc":[{"id":"1.187557247","rc":[{"batb":[[0,3.6,3]],"ltp":4.0,"tv":71987.66,"id":10350473},{"batb":[[0,1.31,762.71]],"batl":[[0,1.38,8]],"ltp":1.33,"tv":26425.34,"id":9304761}]}]}
{"op":"mcm","clk":"4230631988","pt":1631534972600,"mc":[{"id":"1.187557247","rc":[{"batb":[[0,1.32,7.23],[1,1.31,762.71],[2,1.3,4.88]],"ltp":1.33,"tv":26425.34,"id":9304761}]}]}
{"op":"mcm","clk":"4230632296","pt":1631534975677,"mc":[{"id":"1.187557247","rc":[{"batb":[[0,3.6,6.49]],"ltp":4.0,"tv":71987.66,"id":10350473},{"trd":[[1.32,134.75]],"batb":[[0,1.32,2.77]],"batl":[[0,1.38,75.25]],"ltp":1.32,"tv":26434.26,"id":9304761}],"tv":98421.93}]}
{"op":"mcm","clk":"4230632355","pt":1631534976298,"mc":[{"id":"1.187557247","rc":[{"batb":[[0,3.6,3],[1,3.4,3.81],[2,1.35,2.32]],"batl":[[0,4,3.62],[1,5.4,2.34],[2,5.8,2.37]],"ltp":4.0,"tv":71987.66,"id":10350473},{"batl":[[0,1.38,8]],"ltp":1.32,"tv":26434.26,"id":9304761}]}]}
{"op":"mcm","clk":"4230632717","pt":1631534979493,"mc":[{"id":"1.187557247","rc":[{"batb":[[1,3.55,3],[2,3.4,3.81]],"ltp":4.0,"tv":71987.66,"id":10350473}]}]}
{"op":"mcm","clk":"4230632886","pt":1631534981306,"mc":[{"id":"1.187557247","rc":[{"batl":[[1,1.41,55.5],[2,1.48,13.21]],"ltp":1.32,"tv":26434.26,"id":9304761}]}]}
{"op":"mcm","clk":"4230633051","pt":1631534982721,"mc":[{"id":"1.187557247","rc":[{"trd":[[4,31.96]],"batb":[[0,3.6,6.09]],"batl":[[0,5.4,2.34],[1,5.8,2.37],[2,6.4,2.09]],"ltp":4.0,"tv":71991.28,"id":10350473},{"trd":[[1.3,94.72],[1.31,1551.4],[1.32,140.29],[1.33,99.63]],"batb":[[0,1.27,24.4],[1,1.25,611.86],[2,1.24,484.06]],"batl":[[0,1.38,80.25]],"ltp":1.3,"tv":27985.73,"id":9304761}],"tv":99977.01}]}
{"op":"mcm","clk":"4230633094","pt":1631534983101,"mc":[{"id":"1.187557247","rc":[{"batb":[[0,3.6,3]],"ltp":4.0,"tv":71991.28,"id":10350473},{"batl":[[0,1.38,8]],"ltp":1.3,"tv":27985.73,"id":9304761}]}]}
{"op":"mcm","clk":"4230633255","pt":1631534984711,"mc":[{"id":"1.187557247","rc":[{"batb":[[0,4.5,425],[1,4.4,412.5],[2,4.3,412.5]],"batl":[[0,5.3,198.46],[1,5.4,194.97],[2,5.5,192.63]],"ltp":4.0,"tv":71991.28,"id":10350473},{"batb":[[1,1.25,450.69],[2,1.23,118.63]],"batl":[[0,1.28,230.8],[1,1.29,366.73],[2,1.38,8]],"ltp":1.3,"tv":27985.73,"id":9304761}]}]}
{"op":"mcm","clk":"4230633370","pt":1631534985713,"mc":[{"id":"1.187557247","rc":[{"trd":[[4.5,44.12]],"batb":[[0,4.5,419.67]],"ltp":4.5,"tv":72001.94,"id":10350473},{"trd":[[1.28,185.14]],"batl":[[0,1.28,228.8],[2,1.33,2]],"ltp":1.28,"tv":27989.73,"id":9304761}],"tv":99991.67}]}
{"op":"mcm","clk":"4230633393","pt":1631534986020,"mc":[{"id":"1.187557247","rc":[{"batl":[[2,1.33,402]],"ltp":1.28,"tv":27989.73,"id":9304761}]}]}
{"op":"mcm","clk":"4230633529","pt":1631534987526,"mc":[{"id":"1.187557247","rc":[{"trd":[[1.28,205.14]],"batb":[[1,1.26,202.08],[2,1.25,450.69]],"batl":[[0,1.28,218.8]],"ltp":1.28,"tv":28009.73,"id":9304761}],"tv":100011.67}]}
{"op":"mcm","clk":"4230633636","pt":1631534988522,"mc":[{"id":"1.187557247","rc":[{"batb":[[0,1.27,232.66]],"batl":[[0,1.28,297.43],[1,1.29,445.08]],"ltp":1.28,"tv":28009.73,"id":9304761}]}]}
{"op":"mcm","clk":"4230633726","pt":1631534989517,"mc":[{"id":"1.187557247","rc":[{"trd":[[4.8,0.64]],"batl":[[0,5.2,27.69],[1,5.3,198.46],[2,5.4,194.97]],"ltp":4.8,"tv":72002.58,"id":10350473},{"trd":[[1.27,144.24]],"batb":[[0,1.27,227.66],[1,1.26,277.09]],"batl":[[0,1.28,1064.04]],"ltp":1.27,"tv":28017.31,"id":9304761}],"tv":100019.89}]}
{"op":"mcm","clk":"4230633911","pt":1631534991498,"mc":[{"id":"1.187557247","rc":[{"batl":[[2,1.3,8.91]],"ltp":1.27,"tv":28017.31,"id":9304761}]}]}
{"op":"mcm","clk":"4230634196","pt":1631534994625,"mc":[{"id":"1.187557247","rc":[{"batl":[[0,1.28,218.8],[1,1.29,366.73]],"ltp":1.27,"tv":28017.31,"id":9304761}]}]}
{"op":"mcm","clk":"4230634320","pt":1631534995728,"mc":[{"id":"1.187557247","rc":[{"batb":[[1,1.26,202.08]],"ltp":1.27,"tv":28017.31,"id":9304761}]}]}
{"op":"mcm","clk":"4230634417","pt":1631534996614,"mc":[{"id":"1.187557247","rc":[{"batl":[[0,5.3,198.46],[1,5.4,194.97],[2,5.5,192.63]],"ltp":4.8,"tv":72002.58,"id":10350473},{"trd":[[1.27,599.57]],"batb":[[0,1.26,202.08],[1,1.25,450.69],[2,1.24,12.85]],"batl":[[0,1.27,198.23],[1,1.28,218.8],[2,1.29,366.73]],"ltp":1.27,"tv":28472.64,"id":9304761}],"tv":100475.22}]}
{"op":"mcm","clk":"4230634698","pt":1631534999839,"mc":[{"id":"1.187557247","rc":[{"trd":[[1.27,995.56]],"batb":[[0,1.26,258.2]],"batl":[[0,1.28,219.01],[1,1.29,366.73],[2,1.3,8.91]],"ltp":1.27,"tv":28868.63,"id":9304761}],"tv":100871.21}]}
{"op":"mcm","clk":"4230634896","pt":1631535001552,"mc":[{"id":"1.187557247","rc":[{"batb":[[0,3.6,3],[1,1.35,2.32],[2,1.28,720.76]],"batl":[[0,7.8,2],[1,990,0.01],[2,5.5,0]],"ltp":4.8,"tv":72002.58,"id":10350473},{"batb":[[0,1.24,12.85],[1,1.2,2],[2,1.15,172.03]],"batl":[[0,1.3,9.12],[1,1.32,10.72],[2,1.35,425.89]],"ltp":1.27,"tv":28868.63,"id":9304761}]}]}
{"op":"mcm","clk":"4230635027","pt":1631535002749,"mc":[{"id":"1.187557247","rc":[{"batl":[[0,1.3,8.91],[2,1.37,8]],"ltp":1.27,"tv":28868.63,"id":9304761}]}]}
{"op":"mcm","clk":"4230635073","pt":1631535003118,"mc":[{"id":"1.187557247","rc":[{"batb":[[0,1.29,1300],[1,1.24,12.85],[2,1.2,2]],"batl":[[0,1.32,10.72],[1,1.37,8],[2,8.8,7.23]],"ltp":1.27,"tv":28868.63,"id":9304761}]}]}
{"op":"mcm","clk":"4230635251","pt":1631535004740,"mc":[{"id":"1.187557247","rc":[{"batl":[[0,6.4,2.24],[1,7.8,2],[2,990,0.01]],"ltp":4.8,"tv":72002.58,"id":10350473},{"batl":[[0,1.37,8],[1,8.8,7.23],[2,44,7.23]],"ltp":1.27,"tv":28868.63,"id":9304761}]}]}
{"op":"mcm","clk":"4230635328","pt":1631535005515,"mc":[{"id":"1.187557247","rc":[{"batl":[[0,1.36,340.92],[1,1.37,8],[2,8.8,7.23]],"ltp":1.27,"tv":28868.63,"id":9304761}]}]}
{"op":"mcm","clk":"4230635544","pt":1631535007439,"mc":[{"id":"1.187557247","rc":[{"trd":[[4.5,68.72]],"ltp":4.5,"tv":72027.18,"id":10350473},{"trd":[[1.29,135.95]],"batb":[[0,1.29,1193.1],[1,1.27,258.9],[2,1.26,430.41]],"batl":[[0,1.3,496.63],[1,1.31,332.98],[2,1.35,2.32]],"ltp":1.29,"tv":28996.62,"id":9304761}],"tv":101023.8}]}
{"op":"mcm","clk":"4230635693","pt":1631535008758,"mc":[{"id":"1.187557247","rc":[{"batb":[[0,3.7,15],[1,3.6,3],[2,1.35,2.32]],"batl":[[0,5.3,11.2],[1,6.4,2.24],[2,7.8,2]],"ltp":4.5,"tv":72027.18,"id":10350473}]}]}
{"op":"mcm","clk":"4230636342","pt":1631535014657,"mc":[{"id":"1.187557247","rc":[{"batb":[[0,3.6,3],[1,1.35,2.32],[2,1.28,720.76]],"batl":[[0,6.4,2.24],[1,7.8,2],[2,990,0.01]],"ltp":4.5,"tv":72027.18,"id":10350473},{"batb":[[1,1.24,12.85],[2,1.2,2]],"batl":[[0,1.35,2.32],[1,1.36,340.92],[2,1.37,8]],"ltp":1.29,"tv":28996.62,"id":9304761}]}]}
{"op":"mcm","clk":"4230636631","pt":1631535017528,"mc":[{"id":"1.187557247","rc":[{"batb":[[2,1.21,373.63]],"batl":[[0,1.35,432.8],[1,1.36,617.88]],"ltp":1.29,"tv":28996.62,"id":9304761}]}]}
{"op":"mcm","clk":"4230636783","pt":1631535018937,"mc":[{"id":"1.187557247","rc":[{"batb":[[0,1.24,12.85],[1,1.21,373.63],[2,1.2,596.62]],"ltp":1.29,"tv":28996.62,"id":9304761}]}]}
{"op":"mcm","clk":"4230636926","pt":1631535020347,"mc":[{"id":"1.187557247","rc":[{"batl":[[0,7.8,2],[1,990,0.01],[2,990,0]],"ltp":4.5,"tv":72027.18,"id":10350473},{"batb":[[1,1.2,2],[2,1.15,172.03]],"ltp":1.29,"tv":28996.62,"id":9304761}]}]}
{"op":"mcm","clk":"4230637075","pt":1631535021619,"mc":[{"id":"1.187557247","rc":[{"trd":[[1.35,1607.9]],"batb":[[0,1.31,729.1],[1,1.24,12.85],[2,1.2,2]],"batl":[[0,1.35,385.96]],"ltp":1.35,"tv":29090.31,"id":9304761}],"tv":101117.49}]}
{"op":"mcm","clk":"4230637117","pt":1631535022042,"mc":[{"id":"1.187557247","rc":[{"batb":[[0,1.35,2.32],[1,1.28,720.76],[2,1.2,2]],"ltp":4.5,"tv":72027.18,"id":10350473},{"batb":[[0,1.24,12.85],[1,1.2,2],[2,1.15,172.03]],"batl":[[1,1.36,276.96],[2,8.8,7.23]],"ltp":1.35,"tv":29090.31,"id":9304761}]}]}
{"op":"mcm","clk":"4230637256","pt":1631535023541,"mc":[{"id":"1.187557247","rc":[{"trd":[[3.85,8.29]],"batl":[[0,4.6,9.56],[1,7.8,2],[2,990,0.01]],"ltp":3.85,"tv":72033.15,"id":10350473},{"trd":[[1.35,1624.93]],"batb":[[0,1.31,1803.54],[1,1.3,1416.98],[2,1.29,1416.98]],"batl":[[0,1.35,368.93],[2,1.37,767.79]],"ltp":1.35,"tv":29107.34,"id":9304761}],"tv":101140.49}]}
{"op":"mcm","clk":"4230637380","pt":1631535024693,"mc":[{"id":"1.187557247","rc":[{"batb":[[0,3.65,15],[1,1.35,2.32],[2,1.28,720.76]],"batl":[[1,4.7,10],[2,7.8,2]],"ltp":3.85,"tv":72033.15,"id":10350473},{"batl":[[0,1.35,388.84]],"ltp":1.35,"tv":29107.34,"id":9304761}]}]}
{"op":"mcm","clk":"4230637402","pt":1631535024904,"mc":[{"id":"1.187557247","rc":[{"batb":[[0,1.35,2.32],[1,1.28,720.76],[2,1.2,2]],"batl":[[1,7.8,2],[2,990,0.01]],"ltp":3.85,"tv":72033.15,"id":10350473}]}]}
{"op":"mcm","clk":"4230637533","pt":1631535026206,"mc":[{"id":"1.187557247","rc":[{"batb":[[0,1.32,166.45],[1,1.31,1803.54],[2,1.3,1416.98]],"ltp":1.35,"tv":29107.34,"id":9304761}]}]}
{"op":"mcm","clk":"4230637697","pt":1631535027727,"mc":[{"id":"1.187557247","rc":[{"batb":[[0,1.32,245.47]],"batl":[[0,1.33,76.2],[1,1.34,80.53],[2,1.35,453.3]],"ltp":1.35,"tv":29107.34,"id":9304761}]}]}
{"op":"mcm","clk":"4230637749","pt":1631535028095,"mc":[{"id":"1.187557247","rc":[{"batb":[[0,3.3,15],[1,1.35,2.32],[2,1.28,720.76]],"batl":[[0,4.5,37.08],[1,4.6,9.56],[2,7.8,2]],"ltp":3.85,"tv":72033.15,"id":10350473},{"batb":[[0,1.32,309.72],[1,1.31,1867.97]],"ltp":1.35,"tv":29107.34,"id":9304761}]}]}
{"op":"mcm","clk":"4230637916","pt":1631535029725,"mc":[{"id":"1.187557247","rc":[{"batb":[[0,3.5,11.86],[1,3.25,14.29],[2,1.35,2.32]],"batl":[[2,5.6,6.96]],"ltp":3.85,"tv":72033.15,"id":10350473},{"batl":[[1,1.34,250.89]],"ltp":1.35,"tv":29107.34,"id":9304761}]}]}
{"op":"mcm","clk":"4230638023","pt":1631535030725,"mc":[{"id":"1.187557247","rc":[{"batb":[[1,3.4,13.81],[2,3.25,14.29]],"ltp":3.85,"tv":72033.15,"id":10350473},{"trd":[[1.33,251.54]],"batl":[[0,1.34,251.12],[1,1.35,453.3],[2,1.36,447.32]],"ltp":1.33,"tv":29259.26,"id":9304761}],"tv":101292.41}]}
{"op":"mcm","clk":"4230638136","pt":1631535031737,"mc":[{"id":"1.187557247","rc":[{"batb":[[0,3.55,13.39],[1,3.5,11.86],[2,3.4,13.81]],"ltp":3.85,"tv":72033.15,"id":10350473}]}]}
{"op":"mcm","clk":"4230638443","pt":1631535034712,"mc":[{"id":"1.187557247","rc":[{"batb":[[0,3.5,11.86],[1,3.4,13.81],[2,3.35,13.47]],"batl":[[0,7,6.39],[1,990,0.01],[2,5.6,0]],"ltp":3.85,"tv":72033.15,"id":10350473},{"trd":[[1.33,252.02],[1.34,204.15]],"batb":[[0,1.2,2],[1,1.17,655.97],[2,1.06,2.07]],"batl":[[0,1.34,170.36],[1,1.36,170.36],[2,1.4,237.94]],"ltp":1.34,"tv":29262.26,"id":9304761}],"tv":101295.41}]}
{"op":"mcm","clk":"4230638496","pt":1631535035231,"mc":[{"id":"1.187557247","rc":[{"batb":[[0,3.25,14.29],[1,1.35,2.32],[2,1.28,720.76]],"ltp":3.85,"tv":72033.15,"id":10350473},{"batb":[[0,1.23,11.29],[1,1.2,2],[2,1.17,655.97]],"batl":[[2,1.37,13.21]],"ltp":1.34,"tv":29262.26,"id":9304761}]}]}
{"op":"mcm","clk":"4230638622","pt":1631535036647,"mc":[{"id":"1.187557247","rc":[{"batl":[[0,4,12.59],[1,7,6.39],[2,990,0.01]],"ltp":3.85,"tv":72033.15,"id":10350473}]}]}
{"op":"mcm","clk":"4230638683","pt":1631535037325,"mc":[{"id":"1.187557247","rc":[{"batb":[[0,1.26,356.81],[1,1.25,453.03],[2,1.23,11.29]],"ltp":1.34,"tv":29262.26,"id":9304761}]}]}
{"op":"mcm","clk":"4230638779","pt":1631535038316,"mc":[{"id":"1.187557247","rc":[{"batl":[[1,5.6,6.91],[2,7,6.39]],"ltp":3.85,"tv":72033.15,"id":10350473}]}]}
{"op":"mcm","clk":"4230639074","pt":1631535041652,"mc":[{"id":"1.187557247","rc":[{"batb":[[0,3.5,13.16],[1,3.25,14.29],[2,1.35,2.32]],"ltp":3.85,"tv":72033.15,"id":10350473}]}]}
{"op":"mcm","clk":"4230639120","pt":1631535042124,"mc":[{"id":"1.187557247","rc":[{"batb":[[0,3.25,14.29],[1,1.35,2.32],[2,1.28,720.76]],"ltp":3.85,"tv":72033.15,"id":10350473},{"batb":[[2,1.22,471.34]],"ltp":1.34,"tv":29262.26,"id":9304761}]}]}
{"op":"mcm","clk":"4230639214","pt":1631535043224,"mc":[{"id":"1.187557247","rc":[{"trd":[[4,44.54]],"batl":[[0,5.6,6.91],[1,7,6.39],[2,990,0.01]],"ltp":4.0,"tv":72045.73,"id":10350473},{"trd":[[1.33,289.89]],"ltp":1.33,"tv":29300.13,"id":9304761}],"tv":101345.86}]}
{"op":"mcm","clk":"4230639349","pt":1631535044736,"mc":[{"id":"1.187557247","rc":[{"batl":[[0,5.1,750],[1,5.2,727.94],[2,5.3,727.94]],"ltp":4.0,"tv":72045.73,"id":10350473},{"batl":[[0,1.29,450.77],[1,1.3,3289.24],[2,1.31,2855.76]],"ltp":1.33,"tv":29300.13,"id":9304761}]}]}
{"op":"mcm","clk":"4230639434","pt":1631535045627,"mc":[{"id":"1.187557247","rc":[{"trd":[[4.4,5.33]],"batb":[[0,3.3,1233.53],[1,3.25,14.29],[2,1.35,2.32]],"batl":[[0,5.1,206.25],[1,5.2,200.18],[2,5.3,200.18]],"ltp":4.4,"tv":72051.06,"id":10350473},{"trd":[[1.29,154.13]],"batl":[[0,1.29,432.59],[1,1.3,1818.08],[2,1.31,1427.88]],"ltp":1.29,"tv":29318.31,"id":9304761}],"tv":101369.37}]}
{"op":"mcm","clk":"4230639538","pt":1631535046626,"mc":[{"id":"1.187557247","rc":[{"batb":[[0,3.95,3],[1,3.9,3],[2,3.8,63.38]],"ltp":4.4,"tv":72051.06,"id":10350473},{"batb":[[0,1.26,419.74]],"ltp":1.29,"tv":29318.31,"id":9304761}]}]}
{"op":"mcm","clk":"4230639623","pt":1631535047462,"mc":[{"id":"1.187557247","rc":[{"batb":[[2,3.25,14.29]],"ltp":4.4,"tv":72051.06,"id":10350473}]}]}
{"op":"mcm","clk":"4230639731","pt":1631535048568,"mc":[{"id":"1.187557247","rc":[{"trd":[[1.29,167.8]],"batl":[[0,1.29,425.76]],"ltp":1.29,"tv":29331.97,"id":9304761}],"tv":101383.04}]}
{"op":"mcm","clk":"4230639847","pt":1631535049724,"mc":[{"id":"1.187557247","rc":[{"batb":[[0,3.95,868.91]],"batl":[[0,5,34.55],[1,5.1,206.25],[2,5.2,200.18]],"ltp":4.4,"tv":72051.06,"id":10350473},{"batb":[[0,1.27,61.21],[1,1.26,490.17],[2,1.25,453.03]],"batl":[[0,1.28,79.68],[1,1.29,500.06],[2,1.3,1818.08]],"ltp":1.29,"tv":29331.97,"id":9304761}]}]}
{"op":"mcm","clk":"4230639865","pt":1631535049936,"mc":[{"id":"1.187557247","rc":[{"batb":[[0,4,63.38],[1,3.95,868.91],[2,3.9,3]],"ltp":4.4,"tv":72051.06,"id":10350473}]}]}
{"op":"mcm","clk":"4230640105","pt":1631535052445,"mc":[{"id":"1.187557247","rc":[{"trd":[[1.27,1000.37]],"batb":[[0,1.27,58.81],[1,1.26,1546.74]],"ltp":1.27,"tv":29336.77,"id":9304761}],"tv":101387.84}]}
{"op":"mcm","clk":"4230640392","pt":1631535055530,"mc":[{"id":"1.187557247","rc":[{"trd":[[1.27,1094.07]],"batb":[[0,1.27,11.96]],"ltp":1.27,"tv":29430.47,"id":9304761}],"tv":101481.54}]}
{"op":"mcm","clk":"4230640427","pt":1631535055946,"mc":[{"id":"1.187557247","rc":[{"batb":[[1,1.26,490.17]],"ltp":1.27,"tv":29430.47,"id":9304761}]}]}
{"op":"mcm","clk":"4230640567","pt":1631535057571,"mc":[{"id":"1.187557247","rc":[{"batb":[[1,3.95,3]],"ltp":4.4,"tv":72051.06,"id":10350473},{"trd":[[1.28,364.48],[1.29,1019.32]],"batb":[[0,1.29,494.58],[1,1.27,77.97],[2,1.26,419.74]],"batl":[[0,1.3,1818.08],[1,1.31,1427.88],[2,1.32,1427.88]],"ltp":1.29,"tv":30441.33,"id":9304761}],"tv":102492.39}]}
{"op":"mcm","clk":"4230640654","pt":1631535058457,"mc":[{"id":"1.187557247","rc":[{"batb":[[0,3.95,3],[1,3.5,16.12],[2,1.35,2.32]],"batl":[[0,6.6,6.01],[1,7,6.39],[2,8.8,4.67]],"ltp":4.4,"tv":72051.06,"id":10350473},{"batb":[[2,1.23,11.47]],"batl":[[0,1.34,170.36],[1,1.35,10.37],[2,1.36,170.36]],"ltp":1.29,"tv":30441.33,"id":9304761}]}]}
{"op":"mcm","clk":"4230640712","pt":1631535059185,"mc":[{"id":"1.187557247","rc":[{"batb":[[0,3.5,16.12],[1,1.35,2.32],[2,1.28,720.76]],"ltp":4.4,"tv":72051.06,"id":10350473},{"batb":[[1,1.23,11.47],[2,1.2,2]],"ltp":1.29,"tv":30441.33,"id":9304761}]}]}
{"op":"mcm","clk":"4230640852","pt":1631535060748,"mc":[{"id":"1.187557247","rc":[{"batb":[[0,4,1000],[1,3.5,16.12],[2,1.35,2.32]],"ltp":4.4,"tv":72051.06,"id":10350473},{"trd":[[1.29,1081.86]],"batb":[[0,1.29,463.31]],"ltp":1.29,"tv":30503.87,"id":9304761}],"tv":102554.93}]}
{"op":"mcm","clk":"4230640951","pt":1631535061639,"mc":[{"id":"1.187557247","rc":[{"batb":[[0,3.5,16.12],[1,3.35,16.07]],"ltp":4.4,"tv":72051.06,"id":10350473},{"batb":[[2,1.2,721.9]],"ltp":1.29,"tv":30503.87,"id":9304761}]}]}
{"op":"mcm","clk":"4230640987","pt":1631535062053,"mc":[{"id":"1.187557247","rc":[{"batb":[[0,3.5,19.12],[1,3.45,3],[2,3.35,16.07]],"ltp":4.4,"tv":72051.06,"id":10350473}]}]}
{"op":"mcm","clk":"4230641189","pt":1631535064148,"mc":[{"id":"1.187557247","rc":[{"batb":[[2,1.2,2]],"ltp":1.29,"tv":30503.87,"id":9304761}]}]}
{"op":"mcm","clk":"4230641345","pt":1631535065757,"mc":[{"id":"1.187557247","rc":[{"batb":[[0,3.5,16.12],[1,3.35,16.07],[2,1.35,2.32]],"ltp":4.4,"tv":72051.06,"id":10350473},{"batb":[[1,1.2,2],[2,1.18,640.36]],"ltp":1.29,"tv":30503.87,"id":9304761}]}]}
{"op":"mcm","clk":"4230641397","pt":1631535066487,"mc":[{"id":"1.187557247","rc":[{"batb":[[1,1.28,2.98],[2,1.2,2]],"ltp":1.29,"tv":30503.87,"id":9304761}]}]}
{"op":"mcm","clk":"4230641479","pt":1631535067485,"mc":[{"id":"1.187557247","rc":[{"trd":[[1.29,1090.37]],"batb":[[0,1.29,459.05],[1,1.28,45.57]],"ltp":1.29,"tv":30512.38,"id":9304761}],"tv":102563.45}]}
{"op":"mcm","clk":"4230641580","pt":1631535068587,"mc":[{"id":"1.187557247","rc":[{"batb":[[0,5.4,354.16],[1,5.3,343.74],[2,5.2,343.74]],"batl":[[0,6.4,164.36],[1,6.6,165.53],[2,6.8,159.52]],"ltp":4.4,"tv":72051.06,"id":10350473},{"trd":[[1.28,455.61],[1.29,2008.47]],"batb":[[0,1.2,721.9],[1,1.19,460.23],[2,1.18,640.36]],"batl":[[0,1.23,478.27],[1,1.24,447.88],[2,1.34,170.36]],"ltp":1.28,"tv":31521.62,"id":9304761}],"tv":103572.68}]}
{"op":"mcm","clk":"4230641672","pt":1631535069680,"mc":[{"id":"1.187557247","rc":[{"trd":[[5.4,9.1]],"batb":[[0,5.4,349.61]],"ltp":5.4,"tv":72060.16,"id":10350473},{"batl":[[2,1.29,111.56]],"ltp":1.28,"tv":31521.62,"id":9304761}],"tv":103581.78}]}
{"op":"mcm","clk":"4230641766","pt":1631535070571,"mc":[{"id":"1.187557247","rc":[{"batl":[[2,1.28,908.54]],"ltp":1.28,"tv":31521.62,"id":9304761}]}]}
{"op":"mcm","clk":"4230641854","pt":1631535071503,"mc":[{"id":"1.187557247","rc":[{"batb":[[0,1.21,10],[1,1.2,721.9],[2,1.19,460.23]],"batl":[[2,1.28,1078.9]],"ltp":1.28,"tv":31521.62,"id":9304761}]}]}
{"op":"mcm","clk":"4230641966","pt":1631535072762,"mc":[{"id":"1.187557247","rc":[{"batb":[[0,1.21,100.51],[1,1.2,802.61]],"batl":[[0,1.22,65.25],[1,1.23,550.66],[2,1.24,447.88]],"ltp":1.28,"tv":31521.62,"id":9304761}]}]}
{"op":"mcm","clk":"4230642041","pt":1631535073598,"mc":[{"id":"1.187557247","rc":[{"batl":[[0,6.2,25.17],[1,6.4,164.36],[2,6.6,165.53]],"ltp":5.4,"tv":72060.16,"id":10350473}]}]}
{"op":"mcm","clk":"4230642242","pt":1631535075584,"mc":[{"id":"1.187557247","rc":[{"trd":[[5.8,0.52]],"ltp":5.8,"tv":72060.68,"id":10350473},{"trd":[[1.21,7.48]],"batb":[[0,1.21,95.52]],"ltp":1.21,"tv":31529.1,"id":9304761}],"tv":103589.79}]}
{"op":"mcm","clk":"4230642469","pt":1631535078005,"mc":[{"id":"1.187557247","rc":[{"trd":[[1.21,11.48]],"batb":[[0,1.21,93.52]],"ltp":1.21,"tv":31533.1,"id":9304761}],"tv":103593.79}]}
{"op":"mcm","clk":"4230642668","pt":1631535080181,"mc":[{"id":"1.187557247","rc":[{"batb":[[0,1.21,169.19],[1,1.2,721.9]],"batl":[[1,1.23,478.27]],"ltp":1.21,"tv":31533.1,"id":9304761}]}]}
{"op":"mcm","clk":"4230642814","pt":1631535081490,"mc":[{"id":"1.187557247","rc":[{"trd":[[1.22,130.49],[1.23,469.52]],"batb":[[1,1.2,580.79],[2,1.18,640.36]],"batl":[[0,1.23,243.51],[1,1.24,447.88],[2,1.26,11.88]],"ltp":1.23,"tv":32133.11,"id":9304761}],"tv":104193.79}]}
{"op":"mcm","clk":"4230642929","pt":1631535082689,"mc":[{"id":"1.187557247","rc":[{"batl":[[0,6.2,25.67]],"ltp":5.8,"tv":72060.68,"id":10350473},{"batb":[[0,1.22,2.32],[1,1.21,169.19],[2,1.2,580.79]],"ltp":1.23,"tv":32133.11,"id":9304761}]}]}
{"op":"mcm","clk":"4230642964","pt":1631535083010,"mc":[{"id":"1.187557247","rc":[{"batl":[[0,6.4,164.86],[1,6.6,165.53],[2,6.8,159.52]],"ltp":5.8,"tv":72060.68,"id":10350473}]}]}
{"op":"mcm","clk":"4230643140","pt":1631535084735,"mc":[{"id":"1.187557247","rc":[{"trd":[[5.4,17.43]],"batb":[[0,4.5,14.3],[1,4.3,10.88],[2,4.2,9.32]],"batl":[[0,8.2,4.58],[1,8.8,4.67],[2,9.4,3.59]],"ltp":5.4,"tv":72069.02,"id":10350473},{"batb":[[1,1.21,166.18],[2,1.2,2]],"batl":[[0,1.26,11.88],[1,1.28,1203.88],[2,1.29,10]],"ltp":1.23,"tv":32133.11,"id":9304761}],"tv":104202.13}]}
{"op":"mcm","clk":"4230643217","pt":1631535085408,"mc":[{"id":"1.187557247","rc":[{"trd":[[5.5,0.5]],"batb":[[0,4.5,12.3]],"batl":[[0,11,3.67],[1,990,0.01],[2,9.4,0]],"ltp":5.5,"tv":72069.52,"id":10350473},{"trd":[[1.22,137.4]],"batb":[[0,1.2,2],[1,1.15,11.29],[2,1.1,960.94]],"batl":[[0,1.21,246.93],[1,1.26,11.88],[2,1.28,1203.88]],"ltp":1.22,"tv":32140.02,"id":9304761}],"tv":104209.55}]}
{"op":"mcm","clk":"4230643421","pt":1631535087696,"mc":[{"id":"1.187557247","rc":[{"batb":[[1,1.15,941.52],[2,1.14,299.82]],"ltp":1.22,"tv":32140.02,"id":9304761}]}]}
{"op":"mcm","clk":"4230643522","pt":1631535088626,"mc":[{"id":"1.187557247","rc":[{"trd":[[1.21,213.48]],"batb":[[1,1.15,11.29],[2,1.1,960.94]],"batl":[[0,1.21,145.93]],"ltp":1.21,"tv":32342.02,"id":9304761}],"tv":104411.55}]}
{"op":"mcm","clk":"4230643550","pt":1631535088892,"mc":[{"id":"1.187557247","rc":[{"batl":[[1,1.28,1203.88],[2,1.3,311.45]],"ltp":1.21,"tv":32342.02,"id":9304761}]}]}
{"op":"mcm","clk":"4230643798","pt":1631535091712,"mc":[{"id":"1.187557247","rc":[{"batb":[[0,5.3,21.48],[1,4.5,12.3],[2,4.3,10.88]],"batl":[[0,5.8,18.87],[1,5.9,3.4],[2,8.2,4.28]],"ltp":5.5,"tv":72069.52,"id":10350473},{"batb":[[2,1.14,805.82]],"batl":[[1,1.23,22.5],[2,1.28,1203.88]],"ltp":1.21,"tv":32342.02,"id":9304761}]}]}
{"op":"mcm","clk":"4230643822","pt":1631535092025,"mc":[{"id":"1.187557247","rc":[{"batb":[[0,4.5,12.3],[1,4.3,10.88],[2,4.2,9.32]],"batl":[[0,11,3.67],[1,990,0.01],[2,8.2,0]],"ltp":5.5,"tv":72069.52,"id":10350473},{"batb":[[2,1.1,960.94]],"batl":[[1,1.28,1203.88],[2,1.3,311.45]],"ltp":1.21,"tv":32342.02,"id":9304761}]}]}
{"op":"mcm","clk":"4230643938","pt":1631535093401,"mc":[{"id":"1.187557247","rc":[{"batl":[[1,1.27,10.7],[2,1.28,1203.88]],"ltp":1.21,"tv":32342.02,"id":9304761}]}]}
{"op":"mcm","clk":"4230644139","pt":1631535095536,"mc":[{"id":"1.187557247","rc":[{"trd":[[1.21,505.34]],"batb":[[0,1.21,2.32],[1,1.2,2],[2,1.15,11.29]],"batl":[[0,1.27,10.7],[1,1.28,1203.88],[2,1.3,311.45]],"ltp":1.21,"tv":32633.88,"id":9304761}],"tv":104703.41}]}
{"op":"mcm","clk":"4230644209","pt":1631535096319,"mc":[{"id":"1.187557247","rc":[{"batb":[[0,1.21,48.81]],"ltp":1.21,"tv":32633.88,"id":9304761}]}]}
{"op":"mcm","clk":"4230644330","pt":1631535097730,"mc":[{"id":"1.187557247","rc":[{"batb":[[0,1.21,95.29],[2,1.15,856.12]],"batl":[[2,1.3,628.44]],"ltp":1.21,"tv":32633.88,"id":9304761}]}]}
{"op":"mcm","clk":"4230644403","pt":1631535098529,"mc":[{"id":"1.187557247","rc":[{"batb":[[0,1.21,48.81]],"batl":[[2,1.3,703.48]],"ltp":1.21,"tv":32633.88,"id":9304761}]}]}
{"op":"mcm","clk":"4230644443","pt":1631535099038,"mc":[{"id":"1.187557247","rc":[{"batl":[[0,8.2,4.18],[1,11,3.67],[2,990,0.01]],"ltp":5.5,"tv":72069.52,"id":10350473},{"batb":[[0,1.21,2.32]],"ltp":1.21,"tv":32633.88,"id":9304761}]}]}
{"op":"mcm","clk":"4230644891","pt":1631535103727,"mc":[{"id":"1.187557247","rc":[{"batl":[[2,1.3,311.45]],"ltp":1.21,"tv":32633.88,"id":9304761}]}]}
{"op":"mcm","clk":"4230644910","pt":1631535103939,"mc":[{"id":"1.187557247","rc":[{"batb":[[0,4.2,9.32],[1,1.35,2.32],[2,1.28,720.76]],"ltp":5.5,"tv":72069.52,"id":10350473},{"batb":[[2,1.15,844.83]],"batl":[[1,1.28,851.79],[2,1.34,170.36]],"ltp":1.21,"tv":32633.88,"id":9304761}]}]}
{"op":"mcm","clk":"4230645053","pt":1631535105621,"mc":[{"id":"1.187557247","rc":[{"trd":[[1.2,4],[1.21,509.99]],"batb":[[0,1.15,844.83],[1,1.14,1091.79],[2,1.1,960.94]],"batl":[[0,1.19,7082.88],[1,1.27,10.7],[2,1.28,851.79]],"ltp":1.2,"tv":32642.52,"id":9304761}],"tv":104712.05}]}
{"op":"mcm","clk":"4230645151","pt":1631535106749,"mc":[{"id":"1.187557247","rc":[{"batb":[[0,6.6,571.99],[1,6.4,555.17],[2,6.2,555.17]],"batl":[[1,8.4,455.36],[2,8.6,441.96]],"ltp":5.5,"tv":72069.52,"id":10350473},{"batl":[[0,1.17,254.06],[1,1.18,634.11],[2,1.27,10.7]],"ltp":1.2,"tv":32642.52,"id":9304761}]}]}
{"op":"mcm","clk":"4230645218","pt":1631535107561,"mc":[{"id":"1.187557247","rc":[{"trd":[[6.8,3.85]],"batb":[[0,6.6,286],[1,6.4,277.59],[2,6.2,277.59]],"batl":[[1,8.4,125.22],[2,8.6,121.54]],"ltp":6.8,"tv":72073.37,"id":10350473},{"trd":[[1.17,22.38]],"batl":[[0,1.17,231.68]],"ltp":1.17,"tv":32664.9,"id":9304761}],"tv":104738.28}]}
{"op":"mcm","clk":"4230645330","pt":1631535108759,"mc":[{"id":"1.187557247","rc":[{"batl":[[0,8,17.51],[1,8.2,4.18],[2,8.4,125.22]],"ltp":6.8,"tv":72073.37,"id":10350473},{"batl":[[2,1.22,53.5]],"ltp":1.17,"tv":32664.9,"id":9304761}]}]}
{"op":"mcm","clk":"4230645381","pt":1631535109233,"mc":[{"id":"1.187557247","rc":[{"batb":[[0,1.15,929.67]],"ltp":1.17,"tv":32664.9,"id":9304761}]}]}
{"op":"mcm","clk":"4230645608","pt":1631535111691,"mc":[{"id":"1.187557247","rc":[{"trd":[[6.8,6.94]],"batb":[[0,6.6,329.86]],"ltp":6.8,"tv":72076.46,"id":10350473},{"trd":[[1.17,40.34]],"batb":[[0,1.16,104.07],[1,1.15,990.24],[2,1.14,1091.79]],"batl":[[0,1.17,284.09]],"ltp":1.17,"tv":32682.86,"id":9304761}],"tv":104759.33}]}
{"op":"mcm","clk":"4230645666","pt":1631535112477,"mc":[{"id":"1.187557247","rc":[{"batb":[[0,6.6,296.21]],"ltp":6.8,"tv":72076.46,"id":10350473},{"batb":[[2,1.14,1066.9]],"ltp":1.17,"tv":32682.86,"id":9304761}]}]}
{"op":"mcm","clk":"4230645726","pt":1631535113158,"mc":[{"id":"1.187557247","rc":[{"batl":[[2,1.2,534.93]],"ltp":1.17,"tv":32682.86,"id":9304761}]}]}
{"op":"mcm","clk":"4230645951","pt":1631535115479,"mc":[{"id":"1.187557247","rc":[{"trd":[[1.17,44.98]],"batb":[[1,1.15,1014.91]],"batl":[[0,1.17,281.77]],"ltp":1.17,"tv":32687.51,"id":9304761}],"tv":104763.98}]}
{"op":"mcm","clk":"4230646049","pt":1631535116599,"mc":[{"id":"1.187557247","rc":[{"trd":[[1.16,93.99]],"batb":[[0,1.16,57.08]],"ltp":1.16,"tv":32781.49,"id":9304761}],"tv":104857.96}]}
{"op":"mcm","clk":"4230646111","pt":1631535117193,"mc":[{"id":"1.187557247","rc":[{"trd":[[7.4,0.4]],"ltp":7.4,"tv":72076.87,"id":10350473},{"trd":[[1.16,101.88]],"batb":[[0,1.16,51.84]],"ltp":1.16,"tv":32789.39,"id":9304761}],"tv":104866.26}]}
{"op":"mcm","clk":"4230646176","pt":1631535117816,"mc":[{"id":"1.187557247","rc":[{"trd":[[1.16,103.77]],"batb":[[0,1.16,50.89]],"ltp":1.16,"tv":32791.28,"id":9304761}],"tv":104868.15}]}
{"op":"mcm","clk":"4230646303","pt":1631535119167,"mc":[{"id":"1.187557247","rc":[{"batl":[[2,1.19,13.44]],"ltp":1.16,"tv":32791.28,"id":9304761}]}]}
{"op":"mcm","clk":"4230646751","pt":1631535123669,"mc":[{"id":"1.187557247","rc":[{"trd":[[1.17,46.78]],"batl":[[0,1.17,280.87]],"ltp":1.17,"tv":32793.08,"id":9304761}],"tv":104869.95}]}
{"op":"mcm","clk":"4230646899","pt":1631535125083,"mc":[{"id":"1.187557247","rc":[{"trd":[[1.17,52.78]],"batl":[[0,1.17,277.87]],"ltp":1.17,"tv":32799.08,"id":9304761}],"tv":104875.95}]}
{"op":"mcm","clk":"4230647240","pt":1631535128389,"mc":[{"id":"1.187557247","rc":[{"trd":[[1.17,117.87]],"batl":[[0,1.17,245.32]],"ltp":1.17,"tv":32864.16,"id":9304761}],"tv":104941.04}]}
{"op":"mcm","clk":"4230647290","pt":1631535128811,"mc":[{"id":"1.187557247","rc":[{"batb":[[2,1.14,1044.86]],"ltp":1.17,"tv":32864.16,"id":9304761}]}]}
{"op":"mcm","clk":"4230647593","pt":1631535131686,"mc":[{"id":"1.187557247","rc":[{"batb":[[1,1.15,1036.76]],"batl":[[0,1.17,278.81]],"ltp":1.17,"tv":32864.16,"id":9304761}]}]}
{"op":"mcm","clk":"4230647692","pt":1631535132696,"mc":[{"id":"1.187557247","rc":[{"trd":[[1.17,129.59]],"batl":[[0,1.17,272.95]],"ltp":1.17,"tv":32875.88,"id":9304761}],"tv":104952.75}]}
{"op":"mcm","clk":"4230647957","pt":1631535135740,"mc":[{"id":"1.187557247","rc":[{"batb":[[0,6.6,10.21],[1,6,7.86],[2,5.5,7.4]],"batl":[[2,10.5,3.77]],"ltp":7.4,"tv":72076.87,"id":10350473}]}]}
{"op":"mcm","clk":"4230648027","pt":1631535136308,"mc":[{"id":"1.187557247","rc":[{"batb":[[0,5.5,7.4],[1,4.8,2],[2,1.35,2.32]],"batl":[[0,13.5,2.57],[1,990,0.01],[2,10.5,0]],"ltp":7.4,"tv":72076.87,"id":10350473},{"batb":[[0,1.12,10.12],[1,1.09,537.97],[2,1.08,1220.8]],"batl":[[0,1.19,13.44],[1,1.22,442.75],[2,1.23,1022.15]],"ltp":1.17,"tv":32875.88,"id":9304761}]}]}
{"op":"mcm","clk":"4230648423","pt":1631535139714,"mc":[{"id":"1.187557247","rc":[{"batb":[[0,6,6.66],[1,5.5,7.4],[2,4.8,2]],"batl":[[0,10.5,3.95],[1,13.5,2.57],[2,990,0.01]],"ltp":7.4,"tv":72076.87,"id":10350473},{"batb":[[0,1.17,6.12],[1,1.16,452.01],[2,1.12,1075.69]],"batl":[[1,1.2,507.03],[2,1.21,955.95]],"ltp":1.17,"tv":32875.88,"id":9304761}]}]}
{"op":"mcm","clk":"4230648432","pt":1631535139811,"mc":[{"id":"1.187557247","rc":[{"batb":[[0,5.5,7.4],[1,4.8,2],[2,1.35,2.32]],"ltp":7.4,"tv":72076.87,"id":10350473},{"batl":[[1,1.21,955.95],[2,1.22,937.05]],"ltp":1.17,"tv":32875.88,"id":9304761}]}]}
{"op":"mcm","clk":"4230649099","pt":1631535146514,"mc":[{"id":"1.187557247","rc":[{"batb":[[0,6,6.66],[1,5.5,7.4],[2,4.8,2]],"ltp":7.4,"tv":72076.87,"id":10350473},{"batb":[[0,1.17,46.12]],"batl":[[1,1.2,574.88],[2,1.21,955.95]],"ltp":1.17,"tv":32875.88,"id":9304761}]}]}
{"op":"mcm","clk":"4230649212","pt":1631535147713,"mc":[{"id":"1.187557247","rc":[{"batb":[[0,5.5,7.4],[1,4.8,2],[2,1.35,2.32]],"ltp":7.4,"tv":72076.87,"id":10350473},{"batb":[[0,1.17,40],[1,1.12,1075.69],[2,1.11,1120.09]],"batl":[[1,1.21,955.95],[2,1.22,937.05]],"ltp":1.17,"tv":32875.88,"id":9304761}]}]}
{"op":"mcm","clk":"4230649384","pt":1631535149763,"mc":[{"id":"1.187557247","rc":[{"batb":[[1,1.35,2.32],[2,1.28,720.76]],"batl":[[0,13.5,2.57],[1,990,0.01],[2,990,0]],"ltp":7.4,"tv":72076.87,"id":10350473},{"batb":[[1,1.12,10.12],[2,1.09,537.97]],"batl":[[1,1.22,442.75],[2,1.23,1022.15]],"ltp":1.17,"tv":32875.88,"id":9304761}]}]}
{"op":"mcm","clk":"4230649599","pt":1631535151762,"mc":[{"id":"1.187557247","rc":[{"trd":[[1.19,26.88]],"batb":[[0,1.19,21.97],[1,1.17,40],[2,1.12,10.12]],"batl":[[0,1.22,442.75],[1,1.23,1022.15],[2,1.39,17.83]],"ltp":1.19,"tv":32902.76,"id":9304761}],"tv":104979.63}]}
{"op":"mcm","clk":"4230649683","pt":1631535152748,"mc":[{"id":"1.187557247","rc":[{"batl":[[0,10.5,3.71],[1,13.5,2.57],[2,990,0.01]],"ltp":7.4,"tv":72076.87,"id":10350473},{"batl":[[0,1.21,474.5],[1,1.22,442.75],[2,1.23,1022.15]],"ltp":1.19,"tv":32902.76,"id":9304761}]}]}
{"op":"mcm","clk":"4230649759","pt":1631535153560,"mc":[{"id":"1.187557247","rc":[{"batb":[[0,6,6.66],[1,5.5,7.4],[2,1.35,2.32]],"batl":[[0,13.5,2.57],[1,990,0.01],[2,990,0]],"ltp":7.4,"tv":72076.87,"id":10350473},{"batl":[[0,1.22,442.75],[1,1.23,1022.15],[2,1.39,17.83]],"ltp":1.19,"tv":32902.76,"id":9304761}]}]}
{"op":"mcm","clk":"4230649860","pt":1631535154366,"mc":[{"id":"1.187557247","rc":[{"batb":[[0,5.5,7.4],[1,1.35,2.32],[2,1.28,720.76]],"ltp":7.4,"tv":72076.87,"id":10350473},{"trd":[[1.19,70.81]],"batb":[[0,1.17,40.01],[1,1.12,1075.69],[2,1.11,196.5]],"batl":[[0,1.21,454.45],[1,1.22,937.05],[2,1.23,1022.15]],"ltp":1.19,"tv":32946.69,"id":9304761}],"tv":105023.56}]}
{"op":"mcm","clk":"4230650095","pt":1631535156720,"mc":[{"id":"1.187557247","rc":[{"batl":[[0,10.5,2.99],[1,13.5,2.57],[2,990,0.01]],"ltp":7.4,"tv":72076.87,"id":10350473},{"batb":[[1,1.12,10.12],[2,1.11,998.59]],"batl":[[0,1.21,907.95]],"ltp":1.19,"tv":32946.69,"id":9304761}]}]}
{"op":"mcm","clk":"4230650190","pt":1631535157673,"mc":[{"id":"1.187557247","rc":[{"batl":[[0,13.5,2.57],[1,990,0.01],[2,990,0]],"ltp":7.4,"tv":72076.87,"id":10350473},{"batb":[[2,1.11,657.47]],"batl":[[2,1.39,17.83]],"ltp":1.19,"tv":32946.69,"id":9304761}]}]}
{"op":"mcm","clk":"4230650382","pt":1631535159635,"mc":[{"id":"1.187557247","rc":[{"trd":[[5.7,4.26]],"batb":[[1,5.4,194.79],[2,5.3,189.06]],"batl":[[0,7.4,5.84],[1,10.5,78.11],[2,13.5,2.57]],"ltp":5.7,"tv":72081.13,"id":10350473},{"trd":[[1.21,530.06]],"batb":[[0,1.19,278.23],[1,1.18,2277.09],[2,1.17,1613.1]],"batl":[[0,1.21,887.88]],"ltp":1.21,"tv":32966.76,"id":9304761}],"tv":105047.89}]}
{"op":"mcm","clk":"4230650478","pt":1631535160632,"mc":[{"id":"1.187557247","rc":[{"batb":[[0,5.6,13.9],[1,5.5,7.4],[2,5.4,194.79]],"batl":[[0,7.4,18.69],[1,13.5,2.57],[2,990,0.01]],"ltp":5.7,"tv":72081.13,"id":10350473},{"batb":[[1,1.18,3844.36]],"ltp":1.21,"tv":32966.76,"id":9304761}]}]}
{"op":"mcm","clk":"4230650572","pt":1631535161576,"mc":[{"id":"1.187557247","rc":[{"batl":[[0,7.4,5.84]],"ltp":5.7,"tv":72081.13,"id":10350473},{"batb":[[0,1.19,278.22],[1,1.18,3758.07]],"ltp":1.21,"tv":32966.76,"id":9304761}]}]}
{"op":"mcm","clk":"4230650657","pt":1631535162470,"mc":[{"id":"1.187557247","rc":[{"trd":[[1.19,134.05]],"batb":[[0,1.19,246.6],[2,1.17,2635.25]],"batl":[[0,1.21,434.38]],"ltp":1.19,"tv":33030.0,"id":9304761}],"tv":105111.13}]}
{"op":"mcm","clk":"4230650769","pt":1631535163680,"mc":[{"id":"1.187557247","rc":[{"batl":[[0,7.2,19.84],[1,7.4,5.84],[2,13.5,2.57]],"ltp":5.7,"tv":72081.13,"id":10350473},{"batb":[[0,1.2,62.53],[1,1.19,321.68],[2,1.18,3758.07]],"batl":[[0,1.21,492.71]],"ltp":1.19,"tv":33030.0,"id":9304761}]}]}
{"op":"mcm","clk":"4230650865","pt":1631535164471,"mc":[{"id":"1.187557247","rc":[{"trd":[[6,0.47]],"batl":[[0,7.2,27.23]],"ltp":6.0,"tv":72081.6,"id":10350473},{"trd":[[1.2,11.72]],"batb":[[0,1.2,57.49],[1,1.19,407.97]],"ltp":1.2,"tv":33037.72,"id":9304761}],"tv":105119.32}]}
{"op":"mcm","clk":"4230651001","pt":1631535165754,"mc":[{"id":"1.187557247","rc":[{"batl":[[2,8.2,4.63]],"ltp":6.0,"tv":72081.6,"id":10350473},{"batl":[[2,1.23,449.5]],"ltp":1.2,"tv":33037.72,"id":9304761}]}]}
{"op":"mcm","clk":"4230651098","pt":1631535166764,"mc":[{"id":"1.187557247","rc":[{"batb":[[1,1.19,435.24],[2,1.18,2277.09]],"batl":[[0,1.21,517.07]],"ltp":1.2,"tv":33037.72,"id":9304761}]}]}
{"op":"mcm","clk":"4230651157","pt":1631535167339,"mc":[{"id":"1.187557247","rc":[{"batb":[[1,1.19,946.31]],"ltp":1.2,"tv":33037.72,"id":9304761}]}]}
{"op":"mcm","clk":"4230651295","pt":1631535168766,"mc":[{"id":"1.187557247","rc":[{"trd":[[1.2,11.9]],"batb":[[0,1.2,57.39]],"ltp":1.2,"tv":33037.9,"id":9304761}],"tv":105119.51}]}
{"op":"mcm","clk":"4230651463","pt":1631535170643,"mc":[{"id":"1.187557247","rc":[{"batb":[[1,1.19,435.24]],"ltp":1.2,"tv":33037.9,"id":9304761}]}]}
{"op":"mcm","clk":"4230651660","pt":1631535172473,"mc":[{"id":"1.187557247","rc":[{"trd":[[5.7,4.35]],"ltp":5.7,"tv":72081.69,"id":10350473},{"trd":[[1.21,530.5]],"batl":[[0,1.21,516.63]],"ltp":1.21,"tv":33038.34,"id":9304761}],"tv":105120.04}]}
{"op":"mcm","clk":"4230651788","pt":1631535173786,"mc":[{"id":"1.187557247","rc":[{"trd":[[1.21,610.5]],"batl":[[0,1.21,476.63]],"ltp":1.21,"tv":33118.34,"id":9304761}],"tv":105200.04}]}
{"op":"mcm","clk":"4230652138","pt":1631535177564,"mc":[{"id":"1.187557247","rc":[{"batl":[[0,7,20.03],[1,7.2,27.23],[2,7.4,5.84]],"ltp":5.7,"tv":72081.69,"id":10350473},{"batb":[[1,1.19,457.99]],"ltp":1.21,"tv":33118.34,"id":9304761}]}]}
{"op":"mcm","clk":"4230652244","pt":1631535178763,"mc":[{"id":"1.187557247","rc":[{"batb":[[0,5,7.7],[1,1.35,2.32],[2,1.28,720.76]],"batl":[[0,8.2,4.63],[1,10.5,3.39],[2,13.5,2.57]],"ltp":5.7,"tv":72081.69,"id":10350473},{"batb":[[1,1.19,75.08],[2,1.17,1022.15]],"batl":[[0,1.21,58.33],[1,1.24,359.23],[2,1.25,403.7]],"ltp":1.21,"tv":33118.34,"id":9304761}]}]}
{"op":"mcm","clk":"4230652312","pt":1631535179501,"mc":[{"id":"1.187557247","rc":[{"batl":[[0,10.5,3.39],[1,13.5,2.57],[2,990,0.01]],"ltp":5.7,"tv":72081.69,"id":10350473},{"batb":[[0,1.15,10.21],[1,1.11,1340.63],[2,1.1,833.79]],"batl":[[0,1.25,403.7],[1,1.38,13.45],[2,1.39,17.83]],"ltp":1.21,"tv":33118.34,"id":9304761}]}]}
{"op":"mcm","clk":"4230652498","pt":1631535181567,"mc":[{"id":"1.187557247","rc":[{"batb":[[0,1.15,907.06],[1,1.14,333.72],[2,1.11,1340.4]],"batl":[[0,1.25,900.66],[1,1.26,403.77],[2,1.38,13.45]],"ltp":1.21,"tv":33118.34,"id":9304761}]}]}
{"op":"mcm","clk":"4230652583","pt":1631535182675,"mc":[{"id":"1.187557247","rc":[{"batb":[[0,5,10.7],[1,4.9,3],[2,1.35,2.32]],"batl":[[0,8.2,5.13],[1,10.5,3.39],[2,13.5,2.57]],"ltp":5.7,"tv":72081.69,"id":10350473},{"batb":[[1,1.14,1143.54],[2,1.12,884.75]],"batl":[[0,1.24,414.48],[1,1.25,911.66],[2,1.26,403.77]],"ltp":1.21,"tv":33118.34,"id":9304761}]}]}
{"op":"mcm","clk":"4230652641","pt":1631535183363,"mc":[{"id":"1.187557247","rc":[{"batl":[[0,10.5,3.39],[1,13.5,2.57],[2,990,0.01]],"ltp":5.7,"tv":72081.69,"id":10350473},{"batb":[[0,1.15,10.21],[1,1.11,1340.63],[2,1.1,833.79]],"batl":[[0,1.25,911.66],[1,1.26,403.77],[2,1.39,17.83]],"ltp":1.21,"tv":33118.34,"id":9304761}]}]}
{"op":"mcm","clk":"4230652736","pt":1631535184488,"mc":[{"id":"1.187557247","rc":[{"batb":[[1,1.11,879.5]],"ltp":1.21,"tv":33118.34,"id":9304761}]}]}
{"op":"mcm","clk":"4230652853","pt":1631535185695,"mc":[{"id":"1.187557247","rc":[{"batb":[[0,5.3,8.08],[1,5,7.7]],"ltp":5.7,"tv":72081.69,"id":10350473},{"batb":[[0,1.22,1522.2],[1,1.15,10.21],[2,1.11,879.5]],"batl":[[0,1.23,367.5],[1,1.25,900.66],[2,1.26,403.77]],"ltp":1.21,"tv":33118.34,"id":9304761}]}]}
{"op":"mcm","clk":"4230652953","pt":1631535186604,"mc":[{"id":"1.187557247","rc":[{"trd":[[5.3,9.3]],"batb":[[0,5,7.7],[1,4.7,406.92],[2,4.6,217.23]],"batl":[[0,5.5,347.72],[1,5.6,337.5],[2,5.7,337.5]],"ltp":5.3,"tv":72090.99,"id":10350473},{"batb":[[0,1.22,527.08],[1,1.21,553.99],[2,1.18,108.36]],"batl":[[0,1.25,900.66],[1,1.26,403.77],[2,1.47,981.38]],"ltp":1.21,"tv":33118.34,"id":9304761}],"tv":105209.34}]}
{"op":"mcm","clk":"4230653120","pt":1631535188184,"mc":[{"id":"1.187557247","rc":[{"batb":[[1,1.21,563.99],[2,1.19,2044.29]],"batl":[[0,1.25,948.42]],"ltp":1.21,"tv":33118.34,"id":9304761}]}]}
{"op":"mcm","clk":"4230653338","pt":1631535190592,"mc":[{"id":"1.187557247","rc":[{"batb":[[0,1.23,56],[1,1.22,527.08],[2,1.21,563.99]],"batl":[[0,1.24,60.53],[1,1.25,948.42],[2,1.26,403.77]],"ltp":1.21,"tv":33118.34,"id":9304761}]}]}
{"op":"mcm","clk":"4230653406","pt":1631535191400,"mc":[{"id":"1.187557247","rc":[{"trd":[[5.4,18.1]],"batb":[[0,5,19.64]],"batl":[[0,5.5,364.67]],"ltp":5.4,"tv":72091.66,"id":10350473},{"trd":[[1.23,478.11]],"batb":[[0,1.23,50.23],[1,1.22,578.99]],"ltp":1.23,"tv":33126.94,"id":9304761}],"tv":105218.61}]}
{"op":"mcm","clk":"4230653522","pt":1631535192491,"mc":[{"id":"1.187557247","rc":[{"batb":[[1,4.8,9.53],[2,4.7,406.92]],"ltp":5.4,"tv":72091.66,"id":10350473},{"batl":[[2,1.26,766.52]],"ltp":1.23,"tv":33126.94,"id":9304761}]}]}
{"op":"mcm","clk":"4230653807","pt":1631535195391,"mc":[{"id":"1.187557247","rc":[{"trd":[[1.24,0.31]],"batl":[[0,1.24,60.37]],"ltp":1.24,"tv":33127.25,"id":9304761}],"tv":105218.91}]}
{"op":"mcm","clk":"4230653924","pt":1631535196703,"mc":[{"id":"1.187557247","rc":[{"trd":[[1.24,3.11]],"batl":[[0,1.24,58.97]],"ltp":1.24,"tv":33130.05,"id":9304761}],"tv":105221.72}]}
{"op":"mcm","clk":"4230654050","pt":1631535198241,"mc":[{"id":"1.187557247","rc":[{"trd":[[1.24,23.11]],"batb":[[0,1.23,113.02]],"batl":[[0,1.24,127.32]],"ltp":1.24,"tv":33150.05,"id":9304761}],"tv":105241.72}]}
{"op":"mcm","clk":"4230654166","pt":1631535199402,"mc":[{"id":"1.187557247","rc":[{"trd":[[1.24,42.64]],"batl":[[0,1.24,117.56]],"ltp":1.24,"tv":33169.58,"id":9304761}],"tv":105261.24}]}
{"op":"mcm","clk":"4230654293","pt":1631535200717,"mc":[{"id":"1.187557247","rc":[{"batb":[[2,4.5,12.3]],"batl":[[0,5.5,16.95],[1,6.6,6.46],[2,7,5.14]],"ltp":5.4,"tv":72091.66,"id":10350473}]}]}
{"op":"mcm","clk":"4230654363","pt":1631535201410,"mc":[{"id":"1.187557247","rc":[{"batb":[[0,4.5,12.3],[1,1.35,2.32],[2,1.28,720.76]],"batl":[[0,8.2,4.63],[1,10.5,3.39],[2,13.5,2.57]],"ltp":5.4,"tv":72091.66,"id":10350473},{"batb":[[0,1.21,10],[1,1.2,10.77],[2,1.14,729.05]],"batl":[[0,1.27,9.17],[1,1.28,351.34],[2,1.47,981.38]],"ltp":1.24,"tv":33169.58,"id":9304761}]}]}
{"op":"mcm","clk":"4230654413","pt":1631535201922,"mc":[{"id":"1.187557247","rc":[{"batl":[[0,5.1,2.32],[1,8.2,4.63],[2,10.5,3.39]],"ltp":5.4,"tv":72091.66,"id":10350473}]}]}
{"op":"mcm","clk":"4230654661","pt":1631535204709,"mc":[{"id":"1.187557247","rc":[{"batb":[[0,4.7,2],[1,4.6,2],[2,4.5,12.3]],"ltp":5.4,"tv":72091.66,"id":10350473},{"batb":[[0,1.21,10.39],[1,1.14,729.05],[2,1.13,414.09]],"batl":[[0,1.27,19.17]],"ltp":1.24,"tv":33169.58,"id":9304761}]}]}
{"op":"mcm","clk":"4230654890","pt":1631535207529,"mc":[{"id":"1.187557247","rc":[{"trd":[[5.1,2.32]],"batl":[[0,8.2,4.63],[1,10.5,3.39],[2,13.5,2.57]],"ltp":5.1,"tv":72093.99,"id":10350473},{"trd":[[1.24,52.97]],"batb":[[0,1.22,209.26],[1,1.21,554.72],[2,1.14,729.05]],"batl":[[0,1.24,360],[1,1.25,426.52],[2,1.27,19.17]],"ltp":1.24,"tv":33179.91,"id":9304761}],"tv":105273.9}]}
{"op":"mcm","clk":"4230654935","pt":1631535208019,"mc":[{"id":"1.187557247","rc":[{"batb":[[0,4.8,9.88],[1,4.7,2],[2,4.6,2]],"batl":[[0,7,6.39],[1,8.2,4.63],[2,10.5,3.39]],"ltp":5.1,"tv":72093.99,"id":10350473},{"batb":[[2,1.17,578.97]],"batl":[[2,1.26,432.75]],"ltp":1.24,"tv":33179.91,"id":9304761}]}]}
{"op":"mcm","clk":"4230655058","pt":1631535209328,"mc":[{"id":"1.187557247","rc":[{"trd":[[1.24,62.97]],"batb":[[1,1.21,606.67]],"batl":[[0,1.24,355],[2,1.26,528.6]],"ltp":1.24,"tv":33189.91,"id":9304761}],"tv":105283.9}]}
{"op":"mcm","clk":"4230655174","pt":1631535210736,"mc":[{"id":"1.187557247","rc":[{"batl":[[0,6.6,23.15],[1,7,6.39],[2,8.2,4.63]],"ltp":5.1,"tv":72093.99,"id":10350473}]}]}
{"op":"mcm","clk":"4230655284","pt":1631535211738,"mc":[{"id":"1.187557247","rc":[{"batb":[[0,4.7,2],[1,4.6,2],[2,4.5,12.3]],"batl":[[0,8.2,4.63],[1,10.5,3.39],[2,13.5,2.57]],"ltp":5.1,"tv":72093.99,"id":10350473},{"batb":[[0,1.21,10],[1,1.15,12.48],[2,1.14,729.05]],"batl":[[0,1.27,1041.31],[1,1.28,351.34],[2,1.47,981.38]],"ltp":1.24,"tv":33189.91,"id":9304761}]}]}
{"op":"mcm","clk":"4230655373","pt":1631535212738,"mc":[{"id":"1.187557247","rc":[{"trd":[[4.7,15.94]],"batb":[[0,4.6,2],[1,4.5,12.3],[2,1.35,2.32]],"ltp":4.7,"tv":72098.31,"id":10350473},{"trd":[[1.27,1095.27]],"batl":[[0,1.27,17.96],[2,1.36,1022.15]],"ltp":1.27,"tv":33191.11,"id":9304761}],"tv":105289.43}]}
{"op":"mcm","clk":"4230655504","pt":1631535214321,"mc":[{"id":"1.187557247","rc":[{"batb":[[1,1.19,581.8],[2,1.18,609.5]],"batl":[[1,1.28,680.73],[2,1.29,356.91]],"ltp":1.27,"tv":33191.11,"id":9304761}]}]}
{"op":"mcm","clk":"4230655599","pt":1631535215439,"mc":[{"id":"1.187557247","rc":[{"batb":[[1,4.5,14.3]],"batl":[[0,7,6.39],[1,8.2,4.63],[2,10.5,3.39]],"ltp":4.7,"tv":72098.31,"id":10350473}]}]}
{"op":"mcm","clk":"4230655884","pt":1631535218642,"mc":[{"id":"1.187557247","rc":[{"batb":[[0,4.8,8.68],[1,4.6,2],[2,4.5,14.3]],"ltp":4.7,"tv":72098.31,"id":10350473},{"batl":[[0,1.26,416.75],[1,1.27,17.96],[2,1.28,680.73]],"ltp":1.27,"tv":33191.11,"id":9304761}]}]}
{"op":"mcm","clk":"4230655910","pt":1631535218925,"mc":[{"id":"1.187557247","rc":[{"batb":[[0,4.6,2],[1,4.5,14.3],[2,1.35,2.32]],"ltp":4.7,"tv":72098.31,"id":10350473},{"batl":[[0,1.27,17.96],[1,1.28,680.73],[2,1.29,356.91]],"ltp":1.27,"tv":33191.11,"id":9304761}]}]}
{"op":"mcm","clk":"4230656259","pt":1631535222576,"mc":[{"id":"1.187557247","rc":[{"batb":[[0,4.7,2],[1,4.6,2],[2,4.5,14.3]],"ltp":4.7,"tv":72098.31,"id":10350473}]}]}
{"op":"mcm","clk":"4230656670","pt":1631535226645,"mc":[{"id":"1.187557247","rc":[{"batb":[[0,1.24,20],[1,1.21,10],[2,1.19,581.8]],"ltp":1.27,"tv":33191.11,"id":9304761}]}]}
{"op":"mcm","clk":"4230656866","pt":1631535228735,"mc":[{"id":"1.187557247","rc":[{"batl":[[1,1.28,351.34],[2,1.36,1022.15]],"ltp":1.27,"tv":33191.11,"id":9304761}]}]}
{"op":"mcm","clk":"4230656957","pt":1631535229639,"mc":[{"id":"1.187557247","rc":[{"batb":[[1,4.5,12.3],[2,1.35,2.32]],"ltp":4.7,"tv":72098.31,"id":10350473}]}]}
{"op":"mcm","clk":"4230657167","pt":1631535231742,"mc":[{"id":"1.187557247","rc":[{"batb":[[0,5.5,347.72],[1,5.4,337.5],[2,5.3,337.5]],"batl":[[0,6.8,154.69],[1,7,156.53],[2,7.2,150.14]],"ltp":4.7,"tv":72098.31,"id":10350473},{"trd":[[1.21,630.5],[1.24,102.97]],"batb":[[0,1.19,581.8],[1,1.18,609.5],[2,1.17,570.97]],"batl":[[0,1.22,674.1],[1,1.23,462.29],[2,1.24,19.98]],"ltp":1.21,"tv":33251.11,"id":9304761}],"tv":105349.43}]}
{"op":"mcm","clk":"4230657275","pt":1631535232737,"mc":[{"id":"1.187557247","rc":[{"trd":[[5.5,9.02]],"batb":[[0,5.5,343.46]],"ltp":5.5,"tv":72106.83,"id":10350473},{"batl":[[2,1.24,2]],"ltp":1.21,"tv":33251.11,"id":9304761}],"tv":105357.95}]}
{"op":"mcm","clk":"4230657381","pt":1631535233743,"mc":[{"id":"1.187557247","rc":[{"batl":[[2,1.25,8]],"ltp":1.21,"tv":33251.11,"id":9304761}]}]}
{"op":"mcm","clk":"4230657482","pt":1631535234636,"mc":[{"id":"1.187557247","rc":[{"batb":[[0,1.19,645.76]],"ltp":1.21,"tv":33251.11,"id":9304761}]}]}
{"op":"mcm","clk":"4230657576","pt":1631535235732,"mc":[{"id":"1.187557247","rc":[{"batb":[[0,1.2,132.66],[1,1.19,645.76],[2,1.18,609.5]],"batl":[[0,1.21,72.1],[1,1.22,674.1],[2,1.23,462.29]],"ltp":1.21,"tv":33251.11,"id":9304761}]}]}
{"op":"mcm","clk":"4230657637","pt":1631535236461,"mc":[{"id":"1.187557247","rc":[{"trd":[[1.2,16.96]],"batb":[[0,1.2,130.13]],"ltp":1.2,"tv":33256.17,"id":9304761}],"tv":105363.01}]}
{"op":"mcm","clk":"4230657710","pt":1631535237252,"mc":[{"id":"1.187557247","rc":[{"batb":[[0,5.6,10],[1,5.5,343.46],[2,5.4,337.5]],"batl":[[0,6.6,23.78],[1,6.8,154.69],[2,7,156.53]],"ltp":5.5,"tv":72106.83,"id":10350473},{"batl":[[1,1.22,763.9]],"ltp":1.2,"tv":33256.17,"id":9304761}]}]}
{"op":"mcm","clk":"4230657770","pt":1631535237830,"mc":[{"id":"1.187557247","rc":[{"batb":[[1,1.19,2081.17]],"ltp":1.2,"tv":33256.17,"id":9304761}]}]}
{"op":"mcm","clk":"4230657899","pt":1631535239270,"mc":[{"id":"1.187557247","rc":[{"trd":[[1.21,640.26]],"batl":[[0,1.21,67.21]],"ltp":1.21,"tv":33265.93,"id":9304761}],"tv":105372.77}]}
{"op":"mcm","clk":"4230658141","pt":1631535241763,"mc":[{"id":"1.187557247","rc":[{"batb":[[1,1.19,645.76]],"ltp":1.21,"tv":33265.93,"id":9304761}]}]}
{"op":"mcm","clk":"4230658342","pt":1631535243746,"mc":[{"id":"1.187557247","rc":[{"trd":[[1.21,657.29]],"batb":[[0,1.2,199.67]],"batl":[[0,1.21,122.46]],"ltp":1.21,"tv":33282.97,"id":9304761}],"tv":105389.81}]}
{"op":"mcm","clk":"4230658395","pt":1631535244384,"mc":[{"id":"1.187557247","rc":[{"batb":[[0,1.2,130.13]],"batl":[[0,1.21,58.7]],"ltp":1.21,"tv":33282.97,"id":9304761}]}]}
{"op":"mcm","clk":"4230658502","pt":1631535245581,"mc":[{"id":"1.187557247","rc":[{"trd":[[1.21,696.35]],"batl":[[0,1.21,39.17]],"ltp":1.21,"tv":33322.02,"id":9304761}],"tv":105428.86}]}
{"op":"mcm","clk":"4230659095","pt":1631535251467,"mc":[{"id":"1.187557247","rc":[{"trd":[[1.21,706.11]],"batl":[[0,1.21,34.28]],"ltp":1.21,"tv":33331.79,"id":9304761}],"tv":105438.62}]}
{"op":"mcm","clk":"4230659455","pt":1631535255091,"mc":[{"id":"1.187557247","rc":[{"trd":[[1.21,737.49]],"batl":[[0,1.21,18.59]],"ltp":1.21,"tv":33363.17,"id":9304761}],"tv":105470.0}]}
{"op":"mcm","clk":"4230659675","pt":1631535257668,"mc":[{"id":"1.187557247","rc":[{"batb":[[0,4.8,10.68],[1,4.5,12.3],[2,1.35,2.32]],"batl":[[0,10.5,3.39],[1,13.5,2.57],[2,990,0.01]],"ltp":5.5,"tv":72106.83,"id":10350473},{"batb":[[0,1.15,11.18],[1,1.11,1340.63],[2,1.1,833.79]],"batl":[[0,1.25,18.68],[1,1.26,1431.9],[2,1.28,351.34]],"ltp":1.21,"tv":33363.17,"id":9304761}]}]}
{"op":"mcm","clk":"4230659978","pt":1631535260501,"mc":[{"id":"1.187557247","rc":[{"batb":[[0,1.15,875.85],[1,1.14,366.18],[2,1.11,1340.4]],"batl":[[0,1.25,10.68],[1,1.26,847.02],[2,1.27,386.98]],"ltp":1.21,"tv":33363.17,"id":9304761}]}]}
{"op":"mcm","clk":"4230660046","pt":1631535261300,"mc":[{"id":"1.187557247","rc":[{"batl":[[0,8.2,4.98],[1,10.5,3.39],[2,13.5,2.57]],"ltp":5.5,"tv":72106.83,"id":10350473},{"batb":[[1,1.14,1044.5],[2,1.12,816.75]],"ltp":1.21,"tv":33363.17,"id":9304761}]}]}
{"op":"mcm","clk":"4230660240","pt":1631535263412,"mc":[{"id":"1.187557247","rc":[{"batb":[[0,1.22,4.88],[1,1.15,875.85],[2,1.14,1044.5]],"ltp":1.21,"tv":33363.17,"id":9304761}]}]}
{"op":"mcm","clk":"4230660358","pt":1631535264607,"mc":[{"id":"1.187557247","rc":[{"batb":[[1,4.7,3],[2,4.5,12.3]],"ltp":5.5,"tv":72106.83,"id":10350473},{"batl":[[0,1.25,420.1]],"ltp":1.21,"tv":33363.17,"id":9304761}]}]}
{"op":"mcm","clk":"4230660386","pt":1631535264881,"mc":[{"id":"1.187557247","rc":[{"batl":[[0,1.25,10.68]],"ltp":1.21,"tv":33363.17,"id":9304761}]}]}
{"op":"mcm","clk":"4230660976","pt":1631535271736,"mc":[{"id":"1.187557247","rc":[{"batb":[[2,1.35,2.32]],"ltp":5.5,"tv":72106.83,"id":10350473},{"batb":[[1,1.15,864.67]],"batl":[[1,1.26,409.75],[2,1.36,1022.15]],"ltp":1.21,"tv":33363.17,"id":9304761}]}]}
{"op":"mcm","clk":"4230661092","pt":1631535273044,"mc":[{"id":"1.187557247","rc":[{"trd":[[1.22,147.16]],"batb":[[0,1.15,864.67],[1,1.14,1044.5],[2,1.12,816.75]],"ltp":1.22,"tv":33372.93,"id":9304761}],"tv":105479.76}]}
{"op":"mcm","clk":"4230661258","pt":1631535274739,"mc":[{"id":"1.187557247","rc":[{"batb":[[0,6.6,285.42],[1,6.4,277.02],[2,6.2,277.02]],"batl":[[1,8.4,227.68],[2,8.6,121.54]],"ltp":5.5,"tv":72106.83,"id":10350473},{"batl":[[0,1.17,230.19],[1,1.18,632.21],[2,1.25,10.68]],"ltp":1.22,"tv":33372.93,"id":9304761}]}]}
{"op":"mcm","clk":"4230661343","pt":1631535275736,"mc":[{"id":"1.187557247","rc":[{"trd":[[6.8,10.64]],"batl":[[0,8,18.16],[1,8.2,4.98],[2,8.4,227.68]],"ltp":6.8,"tv":72110.53,"id":10350473},{"trd":[[1.17,151.09]],"batl":[[0,1.17,208.69],[2,1.21,144.64]],"ltp":1.17,"tv":33394.43,"id":9304761}],"tv":105504.96}]}
{"op":"mcm","clk":"4230661394","pt":1631535276363,"mc":[{"id":"1.187557247","rc":[{"batb":[[0,1.15,954.17]],"batl":[[2,1.23,1075.55]],"ltp":1.17,"tv":33394.43,"id":9304761}]}]}
{"op":"mcm","clk":"4230661498","pt":1631535277463,"mc":[{"id":"1.187557247","rc":[{"batl":[[2,1.22,404]],"ltp":1.17,"tv":33394.43,"id":9304761}]}]}
{"op":"mcm","clk":"4230661590","pt":1631535278358,"mc":[{"id":"1.187557247","rc":[{"batb":[[0,1.16,130.55],[1,1.15,1033.15],[2,1.14,1044.5]],"batl":[[0,1.17,280.87],[2,1.22,406]],"ltp":1.17,"tv":33394.43,"id":9304761}]}]}
{"op":"mcm","clk":"4230661693","pt":1631535279264,"mc":[{"id":"1.187557247","rc":[{"trd":[[6.8,12.84]],"batb":[[0,6.6,294.72]],"ltp":6.8,"tv":72112.73,"id":10350473},{"trd":[[1.16,108.93],[1.17,163.88]],"batb":[[0,1.16,127.97],[2,1.14,1124.93]],"batl":[[0,1.17,268.08],[1,1.18,710.01],[2,1.22,6]],"ltp":1.16,"tv":33412.38,"id":9304761}],"tv":105525.11}]}
{"op":"mcm","clk":"4230661840","pt":1631535280582,"mc":[{"id":"1.187557247","rc":[{"batb":[[1,1.15,2355.02]],"batl":[[2,1.21,480.5]],"ltp":1.16,"tv":33412.38,"id":9304761}]}]}
{"op":"mcm","clk":"4230662033","pt":1631535282675,"mc":[{"id":"1.187557247","rc":[{"trd":[[1.17,175.8]],"batb":[[2,1.14,1100.07]],"batl":[[0,1.17,262.12]],"ltp":1.17,"tv":33424.3,"id":9304761}],"tv":105537.03}]}
{"op":"mcm","clk":"4230662224","pt":1631535284573,"mc":[{"id":"1.187557247","rc":[{"batb":[[1,1.15,1033.15]],"ltp":1.17,"tv":33424.3,"id":9304761}]}]}
{"op":"mcm","clk":"4230662324","pt":1631535285677,"mc":[{"id":"1.187557247","rc":[{"batb":[[1,1.15,968.3],[2,1.14,1019.64]],"ltp":1.17,"tv":33424.3,"id":9304761}]}]}
{"op":"mcm","clk":"4230662401","pt":1631535286462,"mc":[{"id":"1.187557247","rc":[{"trd":[[1.17,185.56]],"batl":[[0,1.17,257.24],[1,1.18,632.21],[2,1.2,10.86]],"ltp":1.17,"tv":33434.06,"id":9304761}],"tv":105546.79}]}
{"op":"mcm","clk":"4230662455","pt":1631535287089,"mc":[{"id":"1.187557247","rc":[{"trd":[[1.17,195.56]],"batl":[[0,1.17,252.24]],"ltp":1.17,"tv":33444.06,"id":9304761}],"tv":105556.79}]}
{"op":"mcm","clk":"4230662606","pt":1631535288558,"mc":[{"id":"1.187557247","rc":[{"batb":[[0,1.16,170.05]],"ltp":1.17,"tv":33444.06,"id":9304761}]}]}
{"op":"mcm","clk":"4230662933","pt":1631535292163,"mc":[{"id":"1.187557247","rc":[{"trd":[[6.8,22.91]],"ltp":6.8,"tv":72122.8,"id":10350473},{"trd":[[1.17,254.1]],"batb":[[2,1.14,980.75]],"batl":[[0,1.17,72.18]],"ltp":1.17,"tv":33502.6,"id":9304761}],"tv":105625.4}]}
{"op":"mcm","clk":"4230663168","pt":1631535294684,"mc":[{"id":"1.187557247","rc":[{"batb":[[0,5.7,6.92],[1,5.3,8.28],[2,4.8,10.68]],"batl":[[0,13.5,2.57],[1,21,2.01],[2,990,0.01]],"ltp":6.8,"tv":72122.8,"id":10350473},{"batb":[[0,1.13,10.9],[1,1.08,1806.72],[2,1.07,1466.94]],"batl":[[0,1.2,10.86],[1,1.21,480.5],[2,1.22,877.25]],"ltp":1.17,"tv":33502.6,"id":9304761}]}]}
{"op":"mcm","clk":"4230663232","pt":1631535295373,"mc":[{"id":"1.187557247","rc":[{"batb":[[0,5.3,8.28],[1,4.8,10.68],[2,1.35,2.32]],"ltp":6.8,"tv":72122.8,"id":10350473},{"batl":[[1,1.22,877.25],[2,1.23,1440.65]],"ltp":1.17,"tv":33502.6,"id":9304761}]}]}
{"op":"mcm","clk":"4230663430","pt":1631535297655,"mc":[{"id":"1.187557247","rc":[{"batl":[[0,12.5,2.85],[1,13.5,2.57],[2,21,2.01]],"ltp":6.8,"tv":72122.8,"id":10350473},{"batb":[[1,1.11,782.83],[2,1.1,493.97]],"batl":[[2,1.23,1980.7]],"ltp":1.17,"tv":33502.6,"id":9304761}]}]}
{"op":"mcm","clk":"4230663839","pt":1631535301690,"mc":[{"id":"1.187557247","rc":[{"batb":[[0,5.7,7.52],[1,5.3,8.28],[2,4.8,10.68]],"ltp":6.8,"tv":72122.8,"id":10350473},{"batl":[[1,1.21,442.5],[2,1.22,877.25]],"ltp":1.17,"tv":33502.6,"id":9304761}]}]}
{"op":"mcm","clk":"4230663872","pt":1631535302112,"mc":[{"id":"1.187557247","rc":[{"batb":[[0,5.3,8.28],[1,4.8,10.68],[2,1.35,2.32]],"ltp":6.8,"tv":72122.8,"id":10350473},{"batl":[[1,1.22,877.25],[2,1.23,1980.7]],"ltp":1.17,"tv":33502.6,"id":9304761}]}]}
{"op":"mcm","clk":"4230664124","pt":1631535304711,"mc":[{"id":"1.187557247","rc":[{"trd":[[1.2,26.72]],"batl":[[0,1.2,5.98],[1,1.23,1980.7],[2,1.24,441.41]],"ltp":1.2,"tv":33512.36,"id":9304761}],"tv":105635.17}]}
{"op":"mcm","clk":"4230664376","pt":1631535307519,"mc":[{"id":"1.187557247","rc":[{"batl":[[1,1.22,456.25],[2,1.23,1980.7]],"ltp":1.2,"tv":33512.36,"id":9304761}]}]}
{"op":"mcm","clk":"4230664403","pt":1631535307830,"mc":[{"id":"1.187557247","rc":[{"batl":[[1,1.23,1980.7],[2,1.24,441.41]],"ltp":1.2,"tv":33512.36,"id":9304761}]}]}
{"op":"mcm","clk":"4230664561","pt":1631535309412,"mc":[{"id":"1.187557247","rc":[{"trd":[[1.2,38.68]],"batb":[[0,1.2,1578.26],[1,1.13,10.9],[2,1.11,782.83]],"batl":[[0,1.23,958.55],[1,1.24,441.41],[2,1.26,409.75]],"ltp":1.2,"tv":33524.32,"id":9304761}],"tv":105647.12}]}
{"op":"mcm","clk":"4230664768","pt":1631535311294,"mc":[{"id":"1.187557247","rc":[{"batb":[[2,1.09,1237]],"ltp":1.2,"tv":33524.32,"id":9304761}]}]}
{"op":"mcm","clk":"4230664887","pt":1631535312606,"mc":[{"id":"1.187557247","rc":[{"batb":[[0,5.7,6.32],[1,5.3,11.28],[2,5.2,2]],"ltp":6.8,"tv":72122.8,"id":10350473},{"trd":[[1.2,842.68]],"batb":[[0,1.2,1176.26]],"batl":[[0,1.21,439.5],[1,1.23,967.55],[2,1.24,441.41]],"ltp":1.2,"tv":34328.32,"id":9304761}],"tv":106451.12}]}
{"op":"mcm","clk":"4230664986","pt":1631535313699,"mc":[{"id":"1.187557247","rc":[{"trd":[[5.3,18]],"batb":[[0,5.3,3.93],[1,5.1,750],[2,5,727.94]],"batl":[[0,6,637.5],[1,6.2,618.76],[2,6.4,618.76]],"ltp":5.3,"tv":72131.5,"id":10350473},{"batb":[[1,1.17,121.97],[2,1.13,10.9]],"batl":[[0,1.23,958.55],[1,1.24,441.41],[2,1.26,409.75]],"ltp":1.2,"tv":34328.32,"id":9304761}],"tv":106459.82}]}
{"op":"mcm","clk":"4230665064","pt":1631535314581,"mc":[{"id":"1.187557247","rc":[{"batb":[[1,5.1,206.25],[2,5,200.18]],"batl":[[0,6,318.74],[1,6.2,309.38],[2,6.4,309.38]],"ltp":5.3,"tv":72131.5,"id":10350473},{"batb":[[0,1.2,633.37],[1,1.19,547.49]],"ltp":1.2,"tv":34328.32,"id":9304761}]}]}
{"op":"mcm","clk":"4230665123","pt":1631535315216,"mc":[{"id":"1.187557247","rc":[{"batb":[[0,5.3,16.93]],"ltp":5.3,"tv":72131.5,"id":10350473},{"batb":[[0,1.2,696.56],[2,1.1,1.16]],"batl":[[0,1.23,1005.53]],"ltp":1.2,"tv":34328.32,"id":9304761}]}]}
{"op":"mcm","clk":"4230665260","pt":1631535316750,"mc":[{"id":"1.187557247","rc":[{"batb":[[0,1.2,709.58],[2,1.18,2]],"ltp":1.2,"tv":34328.32,"id":9304761}]}]}
{"op":"mcm","clk":"4230665346","pt":1631535317730,"mc":[{"id":"1.187557247","rc":[{"batb":[[0,1.2,2348.38]],"ltp":1.2,"tv":34328.32,"id":9304761}]}]}
{"op":"mcm","clk":"4230665444","pt":1631535318632,"mc":[{"id":"1.187557247","rc":[{"trd":[[5.8,1.07]],"batl":[[0,5.9,14.25],[1,6,318.74],[2,6.2,309.38]],"ltp":5.8,"tv":72132.05,"id":10350473},{"trd":[[1.21,745.46]],"batb":[[0,1.21,190.23],[1,1.2,2427.71],[2,1.19,547.49]],"batl":[[0,1.22,64.85],[1,1.23,1077.26],[2,1.24,441.41]],"ltp":1.21,"tv":34336.29,"id":9304761}],"tv":106468.34}]}
{"op":"mcm","clk":"4230665705","pt":1631535321724,"mc":[{"id":"1.187557247","rc":[{"batb":[[1,4.8,10.68],[2,4.4,8.81]],"batl":[[1,8.2,4.98],[2,11,3.67]],"ltp":5.8,"tv":72132.05,"id":10350473},{"batb":[[1,1.2,2414.7]],"ltp":1.21,"tv":34336.29,"id":9304761}]}]}
{"op":"mcm","clk":"4230665747","pt":1631535322235,"mc":[{"id":"1.187557247","rc":[{"trd":[[5.8,40.75]],"batb":[[0,4.8,10.68],[1,4.4,8.81],[2,1.35,2.32]],"batl":[[0,11,3.67],[1,12.5,2.85],[2,13.5,2.57]],"ltp":5.8,"tv":72171.73,"id":10350473},{"trd":[[1.21,935.69]],"batb":[[0,1.2,79.34],[1,1.18,2],[2,1.11,462.04]],"batl":[[1,1.23,71.73],[2,1.26,409.75]],"ltp":1.21,"tv":34526.52,"id":9304761}],"tv":106698.25}]}
{"op":"mcm","clk":"4230666086","pt":1631535325734,"mc":[{"id":"1.187557247","rc":[{"batb":[[0,4.8,2]],"batl":[[0,8.2,4.23],[1,11,3.67],[2,12.5,2.85]],"ltp":5.8,"tv":72171.73,"id":10350473},{"trd":[[1.2,844.49]],"batb":[[0,1.18,2],[1,1.15,970.24],[2,1.14,1053.01]],"batl":[[0,1.24,24.23],[1,1.28,245.48],[2,1.29,724.97]],"ltp":1.2,"tv":34528.32,"id":9304761}],"tv":106700.06}]}
{"op":"mcm","clk":"4230666124","pt":1631535326150,"mc":[{"id":"1.187557247","rc":[{"batl":[[0,1.28,245.48],[1,1.29,724.97],[2,1.36,1022.15]],"ltp":1.2,"tv":34528.32,"id":9304761}]}]}
{"op":"mcm","clk":"4230666356","pt":1631535328752,"mc":[{"id":"1.187557247","rc":[{"batb":[[1,4.7,3],[2,4.4,8.81]],"ltp":5.8,"tv":72171.73,"id":10350473}]}]}
{"op":"mcm","clk":"4230666451","pt":1631535329643,"mc":[{"id":"1.187557247","rc":[{"batl":[[0,1.27,2],[1,1.28,245.48],[2,1.29,724.97]],"ltp":1.2,"tv":34528.32,"id":9304761}]}]}
{"op":"mcm","clk":"4230666731","pt":1631535332529,"mc":[{"id":"1.187557247","rc":[{"batb":[[0,4.8,10.33]],"ltp":5.8,"tv":72171.73,"id":10350473},{"batl":[[0,1.26,385.75],[1,1.27,2],[2,1.28,13.6]],"ltp":1.2,"tv":34528.32,"id":9304761}]}]}
{"op":"mcm","clk":"4230666764","pt":1631535332840,"mc":[{"id":"1.187557247","rc":[{"batb":[[0,4.8,2]],"ltp":5.8,"tv":72171.73,"id":10350473},{"batl":[[0,1.27,2],[1,1.28,13.6],[2,1.29,367.5]],"ltp":1.2,"tv":34528.32,"id":9304761}]}]}
{"op":"mcm","clk":"4230666921","pt":1631535334551,"mc":[{"id":"1.187557247","rc":[{"trd":[[5.5,12.93]],"ltp":5.5,"tv":72175.63,"id":10350473},{"trd":[[1.18,4],[1.22,164.77]],"batb":[[0,1.15,970.24],[1,1.14,1053.01],[2,1.12,846]],"ltp":1.18,"tv":34549.93,"id":9304761}],"tv":106725.57}]}
{"op":"mcm","clk":"4230667025","pt":1631535335651,"mc":[{"id":"1.187557247","rc":[{"batb":[[0,6.6,285.42],[1,6.4,277.02],[2,6.2,277.02]],"batl":[[1,8.4,227.68],[2,8.6,121.54]],"ltp":5.5,"tv":72175.63,"id":10350473},{"batl":[[0,1.18,762.57],[1,1.19,430.02],[2,1.27,2]],"ltp":1.18,"tv":34549.93,"id":9304761}]}]}
{"op":"mcm","clk":"4230667105","pt":1631535336349,"mc":[{"id":"1.187557247","rc":[{"trd":[[6.6,7.4]],"batb":[[0,6.6,281.72]],"ltp":6.6,"tv":72183.03,"id":10350473}],"tv":106732.97}]}
{"op":"mcm","clk":"4230667218","pt":1631535337353,"mc":[{"id":"1.187557247","rc":[{"batl":[[0,8,18.8],[1,8.2,4.23],[2,8.4,227.68]],"ltp":6.6,"tv":72183.03,"id":10350473},{"batb":[[0,1.16,43.15],[1,1.15,970.24],[2,1.14,1053.01]],"batl":[[2,1.26,1022.15]],"ltp":1.18,"tv":34549.93,"id":9304761}]}]}
{"op":"mcm","clk":"4230667414","pt":1631535339526,"mc":[{"id":"1.187557247","rc":[{"batb":[[0,1.16,123.26]],"batl":[[0,1.17,140.45],[1,1.18,842.59],[2,1.19,430.02]],"ltp":1.18,"tv":34549.93,"id":9304761}]}]}
{"op":"mcm","clk":"4230667520","pt":1631535340673,"mc":[{"id":"1.187557247","rc":[{"batb":[[0,6.6,291.72]],"ltp":6.6,"tv":72183.03,"id":10350473},{"trd":[[1.16,114.07]],"batb":[[0,1.16,120.69],[1,1.15,1029.3]],"batl":[[1,1.18,896.27]],"ltp":1.16,"tv":34555.08,"id":9304761}],"tv":106738.11}]}
{"op":"mcm","clk":"4230668140","pt":1631535347376,"mc":[{"id":"1.187557247","rc":[{"batb":[[1,1.15,970.24]],"ltp":1.16,"tv":34555.08,"id":9304761}]}]}
{"op":"mcm","clk":"4230668247","pt":1631535348669,"mc":[{"id":"1.187557247","rc":[{"trd":[[1.17,280.14]],"batl":[[0,1.17,127.43]],"ltp":1.17,"tv":34581.12,"id":9304761}],"tv":106764.15}]}
{"op":"mcm","clk":"4230668337","pt":1631535349663,"mc":[{"id":"1.187557247","rc":[{"batb":[[0,5.7,6.92],[1,5.5,10.48],[2,5.3,7.68]],"batl":[[0,12.5,2.85],[1,13.5,2.57],[2,21,2.01]],"ltp":6.6,"tv":72183.03,"id":10350473},{"batb":[[0,1.16,80.11],[1,1.13,12.16],[2,1.09,1237]],"batl":[[1,1.18,80.02],[2,1.2,12.3]],"ltp":1.17,"tv":34581.12,"id":9304761}]}]}
{"op":"mcm","clk":"4230668383","pt":1631535350138,"mc":[{"id":"1.187557247","rc":[{"batb":[[0,5.5,2],[1,5.3,7.68],[2,4.4,8.81]],"batl":[[0,13.5,2.57],[1,21,2.01],[2,990,0.01]],"ltp":6.6,"tv":72183.03,"id":10350473},{"batb":[[0,1.13,12.16],[1,1.08,1806.72],[2,1.07,1466.94]],"batl":[[0,1.2,12.3],[1,1.23,408.5],[2,1.26,1022.15]],"ltp":1.17,"tv":34581.12,"id":9304761}]}]}
{"op":"mcm","clk":"4230668619","pt":1631535352662,"mc":[{"id":"1.187557247","rc":[{"batb":[[1,1.11,827.09],[2,1.1,449.32]],"batl":[[1,1.23,917.47],[2,1.24,442.12]],"ltp":1.17,"tv":34581.12,"id":9304761}]}]}
{"op":"mcm","clk":"4230668690","pt":1631535353354,"mc":[{"id":"1.187557247","rc":[{"batl":[[0,12.5,2.87],[1,13.5,2.57],[2,21,2.01]],"ltp":6.6,"tv":72183.03,"id":10350473}]}]}
{"op":"mcm","clk":"4230668760","pt":1631535354132,"mc":[{"id":"1.187557247","rc":[{"batl":[[0,13.5,2.57],[1,21,2.01],[2,990,0.01]],"ltp":6.6,"tv":72183.03,"id":10350473},{"batb":[[0,1.1,1.16],[1,1.08,1806.04],[2,1.07,1466.94]],"batl":[[1,1.23,408.5],[2,1.26,1022.15]],"ltp":1.17,"tv":34581.12,"id":9304761}]}]}
{"op":"mcm","clk":"4230668980","pt":1631535356753,"mc":[{"id":"1.187557247","rc":[{"batb":[[0,5.7,6.82],[1,5.5,2],[2,5.3,7.68]],"ltp":6.6,"tv":72183.03,"id":10350473},{"batl":[[1,1.21,445.5],[2,1.22,445.75]],"ltp":1.17,"tv":34581.12,"id":9304761}]}]}
{"op":"mcm","clk":"4230669049","pt":1631535357499,"mc":[{"id":"1.187557247","rc":[{"batb":[[0,5.5,2],[1,5.3,7.68],[2,4.4,8.81]],"batl":[[0,12.5,3.01],[1,13.5,2.57],[2,21,2.01]],"ltp":6.6,"tv":72183.03,"id":10350473},{"batb":[[0,1.15,239.47],[1,1.14,870.04],[2,1.09,1177.14]],"batl":[[0,1.17,786.34],[1,1.18,416.56],[2,1.2,12.3]],"ltp":1.17,"tv":34581.12,"id":9304761}]}]}
{"op":"mcm","clk":"4230669150","pt":1631535358469,"mc":[{"id":"1.187557247","rc":[{"batb":[[0,6,10],[1,5.5,2],[2,5.3,7.68]],"batl":[[0,9,12.85],[1,12.5,3.01],[2,13.5,2.57]],"ltp":6.6,"tv":72183.03,"id":10350473}]}]}
{"op":"mcm","clk":"4230669321","pt":1631535360347,"mc":[{"id":"1.187557247","rc":[{"batb":[[1,5.7,6.02],[2,5.5,2]],"ltp":6.6,"tv":72183.03,"id":10350473}]}]}
{"op":"mcm","clk":"4230669463","pt":1631535361765,"mc":[{"id":"1.187557247","rc":[{"batb":[[0,5.5,2],[1,5.3,7.68],[2,4.4,8.81]],"batl":[[0,13.5,2.57],[1,21,2.01],[2,990,0.01]],"ltp":6.6,"tv":72183.03,"id":10350473},{"batb":[[0,1.1,1.16],[1,1.08,1806.04],[2,1.07,1466.94]],"batl":[[0,1.2,12.3],[1,1.23,408.5],[2,1.26,1022.15]],"ltp":1.17,"tv":34581.12,"id":9304761}]}]}
{"op":"mcm","clk":"4230669720","pt":1631535364386,"mc":[{"id":"1.187557247","rc":[{"batb":[[0,1.11,827.57],[1,1.1,449.32],[2,1.08,1806.04]],"batl":[[1,1.23,917.47],[2,1.24,442.12]],"ltp":1.17,"tv":34581.12,"id":9304761}]}]}
{"op":"mcm","clk":"4230669813","pt":1631535365382,"mc":[{"id":"1.187557247","rc":[{"batl":[[0,12.5,3.01],[1,13.5,2.57],[2,21,2.01]],"ltp":6.6,"tv":72183.03,"id":10350473},{"batb":[[2,1.09,1078.5]],"ltp":1.17,"tv":34581.12,"id":9304761}]}]}
{"op":"mcm","clk":"4230669881","pt":1631535366166,"mc":[{"id":"1.187557247","rc":[{"batb":[[0,1.17,5.73],[1,1.11,827.57],[2,1.1,449.32]],"ltp":1.17,"tv":34581.12,"id":9304761}]}]}
{"op":"mcm","clk":"4230669969","pt":1631535367109,"mc":[{"id":"1.187557247","rc":[{"trd":[[1.17,280.3]],"batb":[[0,1.17,5.65]],"ltp":1.17,"tv":34581.28,"id":9304761}],"tv":106764.31}]}
{"op":"mcm","clk":"4230670118","pt":1631535368766,"mc":[{"id":"1.187557247","rc":[{"batb":[[0,5.7,6.92],[1,5.5,2],[2,5.3,7.68]],"ltp":6.6,"tv":72183.03,"id":10350473},{"trd":[[1.2,869.09]],"batb":[[0,1.2,1271.4]],"batl":[[0,1.21,433.5],[1,1.22,490.25],[2,1.23,917.47]],"ltp":1.2,"tv":34605.88,"id":9304761}],"tv":106788.91}]}
{"op":"mcm","clk":"4230670139","pt":1631535369080,"mc":[{"id":"1.187557247","rc":[{"batb":[[0,5.5,2],[1,5.3,7.68],[2,4.4,8.81]],"ltp":6.6,"tv":72183.03,"id":10350473},{"batl":[[0,1.23,917.47],[1,1.24,442.12],[2,1.26,1022.15]],"ltp":1.2,"tv":34605.88,"id":9304761}]}]}
{"op":"mcm","clk":"4230670479","pt":1631535372574,"mc":[{"id":"1.187557247","rc":[{"batb":[[1,5.4,2],[2,5.3,7.68]],"ltp":6.6,"tv":72183.03,"id":10350473},{"trd":[[1.2,1035.87],[1.22,181.81]],"batb":[[0,1.2,1188.02]],"batl":[[0,1.23,926.47]],"ltp":1.2,"tv":34789.69,"id":9304761}],"tv":106972.73}]}
{"op":"mcm","clk":"4230670517","pt":1631535372982,"mc":[{"id":"1.187557247","rc":[{"trd":[[6,47.9]],"ltp":6.0,"tv":72230.46,"id":10350473},{"trd":[[1.2,1273.02]],"batb":[[0,1.2,950.87]],"ltp":1.2,"tv":35026.84,"id":9304761}],"tv":107257.31}]}
{"op":"mcm","clk":"4230670763","pt":1631535375695,"mc":[{"id":"1.187557247","rc":[{"trd":[[1.2,2077.02]],"batb":[[0,1.2,548.87]],"ltp":1.2,"tv":35830.84,"id":9304761}],"tv":108061.31}]}
{"op":"mcm","clk":"4230670864","pt":1631535376510,"mc":[{"id":"1.187557247","rc":[{"batl":[[0,1.22,10],[1,1.23,926.47],[2,1.24,442.12]],"ltp":1.2,"tv":35830.84,"id":9304761}]}]}
{"op":"mcm","clk":"4230671044","pt":1631535378395,"mc":[{"id":"1.187557247","rc":[{"trd":[[1.2,2877.02]],"batb":[[0,1.2,148.87]],"ltp":1.2,"tv":36630.84,"id":9304761}],"tv":108861.31}]}
{"op":"mcm","clk":"4230671159","pt":1631535379598,"mc":[{"id":"1.187557247","rc":[{"batb":[[1,1.1,1.16],[2,1.09,1078.5]],"ltp":1.2,"tv":36630.84,"id":9304761}]}]}
{"op":"mcm","clk":"4230671353","pt":1631535381681,"mc":[{"id":"1.187557247","rc":[{"batb":[[0,5.3,7.68],[1,4.4,8.81],[2,1.35,2.32]],"ltp":6.0,"tv":72230.46,"id":10350473},{"batl":[[0,1.23,917.47],[1,1.24,442.12],[2,1.27,2]],"ltp":1.2,"tv":36630.84,"id":9304761}]}]}
{"op":"mcm","clk":"4230671452","pt":1631535382728,"mc":[{"id":"1.187557247","rc":[{"trd":[[5.3,26.7]],"batb":[[0,5.3,3.33],[1,5.1,206.25],[2,5,200.18]],"batl":[[0,6,318.74],[1,6.2,309.38],[2,6.4,309.38]],"ltp":5.3,"tv":72239.16,"id":10350473},{"trd":[[1.21,957.69]],"batb":[[0,1.21,426.26],[1,1.2,667.85],[2,1.19,512.72]],"ltp":1.21,"tv":36652.84,"id":9304761}],"tv":108892.01}]}
{"op":"mcm","clk":"4230671561","pt":1631535383614,"mc":[{"id":"1.187557247","rc":[{"batb":[[0,1.2,731.49],[1,1.19,512.72],[2,1.17,131.97]],"ltp":1.21,"tv":36652.84,"id":9304761}]}]}
{"op":"mcm","clk":"4230671784","pt":1631535385671,"mc":[{"id":"1.187557247","rc":[{"batb":[[0,5.3,16.03]],"ltp":5.3,"tv":72239.16,"id":10350473},{"batl":[[0,1.23,963.18]],"ltp":1.21,"tv":36652.84,"id":9304761}]}]}
{"op":"mcm","clk":"4230671898","pt":1631535386707,"mc":[{"id":"1.187557247","rc":[{"batl":[[0,5.7,3],[1,5.9,2],[2,6,318.74]],"ltp":5.3,"tv":72239.16,"id":10350473},{"batb":[[0,1.21,85.5],[1,1.2,740.49],[2,1.19,512.72]],"batl":[[0,1.22,111.99],[1,1.23,1032.95],[2,1.24,442.12]],"ltp":1.21,"tv":36652.84,"id":9304761}]}]}
{"op":"mcm","clk":"4230671977","pt":1631535387498,"mc":[{"id":"1.187557247","rc":[{"trd":[[5.7,5.46]],"batl":[[0,5.9,15.05],[1,6,318.74],[2,6.2,309.38]],"ltp":5.7,"tv":72240.27,"id":10350473},{"trd":[[1.21,963.05]],"batb":[[0,1.21,76.5],[1,1.2,791.58]],"ltp":1.21,"tv":36658.19,"id":9304761}],"tv":108898.46}]}
{"op":"mcm","clk":"4230672438","pt":1631535392152,"mc":[{"id":"1.187557247","rc":[{"trd":[[1.21,1004.03]],"batb":[[0,1.21,56.01]],"ltp":1.21,"tv":36699.18,"id":9304761}],"tv":108939.45}]}
{"op":"mcm","clk":"4230672602","pt":1631535393668,"mc":[{"id":"1.187557247","rc":[{"batb":[[0,4.8,8.38],[1,4.5,12.3],[2,4.4,8.81]],"batl":[[0,8.8,4.87],[1,12.5,3.01],[2,13.5,2.57]],"ltp":5.7,"tv":72240.27,"id":10350473},{"batb":[[0,1.13,817.21],[1,1.11,461.57],[2,1.09,1078.74]],"batl":[[0,1.26,410.75],[1,1.28,380.84],[2,1.29,367.5]],"ltp":1.21,"tv":36699.18,"id":9304761}]}]}
{"op":"mcm","clk":"4230672648","pt":1631535394240,"mc":[{"id":"1.187557247","rc":[{"batb":[[0,4.4,8.81],[1,1.35,2.32],[2,1.28,720.76]],"batl":[[0,12.5,3.01],[1,13.5,2.57],[2,21,2.01]],"ltp":5.7,"tv":72240.27,"id":10350473},{"batb":[[0,1.18,13.53],[1,1.11,462.04]],"batl":[[0,1.25,12.08],[1,1.29,367.5],[2,1.47,981.38]],"ltp":1.21,"tv":36699.18,"id":9304761}]}]}
{"op":"mcm","clk":"4230672898","pt":1631535396646,"mc":[{"id":"1.187557247","rc":[{"batl":[[0,5.5,5.03],[1,12.5,3.01],[2,13.5,2.57]],"ltp":5.7,"tv":72240.27,"id":10350473},{"batb":[[0,1.11,462.04],[1,1.09,1078.74],[2,1.08,1223.01]],"ltp":1.21,"tv":36699.18,"id":9304761}]}]}
{"op":"mcm","clk":"4230672968","pt":1631535397485,"mc":[{"id":"1.187557247","rc":[{"batb":[[0,4.4,11.81],[1,4.3,3],[2,1.35,2.32]],"ltp":5.7,"tv":72240.27,"id":10350473},{"batb":[[0,1.11,1418.63]],"batl":[[1,1.29,375.5]],"ltp":1.21,"tv":36699.18,"id":9304761}]}]}
{"op":"mcm","clk":"4230673160","pt":1631535399570,"mc":[{"id":"1.187557247","rc":[{"trd":[[5.5,17.96]],"batl":[[0,12.5,3.01],[1,13.5,2.57],[2,21,2.01]],"ltp":5.5,"tv":72245.3,"id":10350473},{"trd":[[1.22,204.51]],"batb":[[0,1.19,702.8],[1,1.18,487.48],[2,1.11,1418.63]],"batl":[[0,1.22,537.93],[1,1.23,463.51],[2,1.25,12.08]],"ltp":1.22,"tv":36721.88,"id":9304761}],"tv":108967.18}]}
{"op":"mcm","clk":"4230673317","pt":1631535401292,"mc":[{"id":"1.187557247","rc":[{"batb":[[0,4.8,9.28],[1,4.4,11.81],[2,4.3,3]],"batl":[[0,8.8,4.72],[1,12.5,3.01],[2,13.5,2.57]],"ltp":5.5,"tv":72245.3,"id":10350473},{"batb":[[2,1.13,772.21]],"ltp":1.22,"tv":36721.88,"id":9304761}]}]}
{"op":"mcm","clk":"4230673429","pt":1631535402392,"mc":[{"id":"1.187557247","rc":[{"batl":[[0,7.2,15.05],[1,8.8,4.72],[2,12.5,3.01]],"ltp":5.5,"tv":72245.3,"id":10350473}]}]}
{"op":"mcm","clk":"4230673553","pt":1631535403493,"mc":[{"id":"1.187557247","rc":[{"batb":[[0,4.4,11.81],[1,4.3,3],[2,1.35,2.32]],"batl":[[0,12.5,3.01],[1,13.5,2.57],[2,21,2.01]],"ltp":5.5,"tv":72245.3,"id":10350473},{"batb":[[0,1.11,1418.63],[1,1.09,1078.74],[2,1.08,1233.98]],"batl":[[0,1.25,12.08],[1,1.29,375.5],[2,1.47,981.38]],"ltp":1.22,"tv":36721.88,"id":9304761}]}]}
{"op":"mcm","clk":"4230673794","pt":1631535406476,"mc":[{"id":"1.187557247","rc":[{"batb":[[0,1.16,221.06],[1,1.15,802.62],[2,1.11,1418.63]],"batl":[[1,1.27,333.5],[2,1.28,198.82]],"ltp":1.22,"tv":36721.88,"id":9304761}]}]}
{"op":"mcm","clk":"4230673842","pt":1631535406997,"mc":[{"id":"1.187557247","rc":[{"batl":[[0,8.8,4.32],[1,12.5,3.01],[2,13.5,2.57]],"ltp":5.5,"tv":72245.3,"id":10350473},{"batb":[[2,1.13,713.21]],"batl":[[1,1.28,198.82],[2,1.29,733.29]],"ltp":1.22,"tv":36721.88,"id":9304761}]}]}
{"op":"mcm","clk":"4230674200","pt":1631535410496,"mc":[{"id":"1.187557247","rc":[{"batb":[[1,1.35,2.32],[2,1.28,720.76]],"ltp":5.5,"tv":72245.3,"id":10350473}]}]}
{"op":"mcm","clk":"4230674400","pt":1631535412695,"mc":[{"id":"1.187557247","rc":[{"batb":[[0,1.13,713.21],[1,1.11,461.57],[2,1.09,1078.74]],"batl":[[0,1.28,198.82],[1,1.29,733.29],[2,1.47,981.38]],"ltp":1.22,"tv":36721.88,"id":9304761}]}]}
{"op":"mcm","clk":"4230674504","pt":1631535413694,"mc":[{"id":"1.187557247","rc":[{"batb":[[0,4.8,9.63],[1,4.4,11.81],[2,1.35,2.32]],"batl":[[0,12.5,3.01],[1,13.5,2.57],[2,21,2.01]],"ltp":5.5,"tv":72245.3,"id":10350473},{"batb":[[0,1.11,462.04],[1,1.09,1078.74],[2,1.08,1233.98]],"batl":[[0,1.26,333.75],[1,1.28,198.82],[2,1.29,733.29]],"ltp":1.22,"tv":36721.88,"id":9304761}]}]}
{"op":"mcm","clk":"4230674580","pt":1631535414682,"mc":[{"id":"1.187557247","rc":[{"batb":[[0,4.4,8.81],[1,1.35,2.32],[2,1.28,720.76]],"batl":[[0,5.3,47.42],[1,5.9,6.12],[2,12.5,3.01]],"ltp":5.5,"tv":72245.3,"id":10350473},{"batb":[[0,1.1,1.16],[1,1.09,1078.5]],"batl":[[0,1.28,198.82],[1,1.29,725.29],[2,1.47,981.38]],"ltp":1.22,"tv":36721.88,"id":9304761}]}]}
{"op":"mcm","clk":"4230674674","pt":1631535415717,"mc":[{"id":"1.187557247","rc":[{"trd":[[4.5,73.6]],"batb":[[1,4.3,244.63],[2,4.2,237.43]],"batl":[[0,6,9.29],[1,12.5,3.01],[2,13.5,2.57]],"ltp":4.5,"tv":72250.18,"id":10350473},{"trd":[[1.28,472.77]],"batb":[[0,1.26,214.76],[1,1.25,451.68],[2,1.24,1542.34]],"batl":[[0,1.28,181.66]],"ltp":1.28,"tv":36739.04,"id":9304761}],"tv":108989.22}]}
{"op":"mcm","clk":"4230674746","pt":1631535416506,"mc":[{"id":"1.187557247","rc":[{"batb":[[1,1.25,439.83]],"ltp":1.28,"tv":36739.04,"id":9304761}]}]}
{"op":"mcm","clk":"4230674775","pt":1631535416814,"mc":[{"id":"1.187557247","rc":[{"batb":[[0,4.5,15.99],[1,4.4,8.81],[2,4.3,244.63]],"batl":[[0,5.8,15.05],[1,6,9.29],[2,12.5,3.01]],"ltp":4.5,"tv":72250.18,"id":10350473},{"batl":[[0,1.28,222.06]],"ltp":1.28,"tv":36739.04,"id":9304761}]}]}
{"op":"mcm","clk":"4230675044","pt":1631535419696,"mc":[{"id":"1.187557247","rc":[{"trd":[[4.9,29.92]],"ltp":4.9,"tv":72279.4,"id":10350473},{"trd":[[1.26,153.03]],"batb":[[0,1.26,101.13],[1,1.25,695.37]],"ltp":1.26,"tv":36852.67,"id":9304761}],"tv":109132.07}]}
{"op":"mcm","clk":"4230675122","pt":1631535420522,"mc":[{"id":"1.187557247","rc":[{"batb":[[0,1.25,255.54],[1,1.24,1542.34],[2,1.23,2519.13]],"batl":[[0,1.28,40.4],[1,1.29,367.5]],"ltp":1.26,"tv":36852.67,"id":9304761}]}]}
{"op":"mcm","clk":"4230675309","pt":1631535422722,"mc":[{"id":"1.187557247","rc":[{"batb":[[2,1.23,1496.98]],"ltp":1.26,"tv":36852.67,"id":9304761}]}]}
{"op":"mcm","clk":"4230675394","pt":1631535423524,"mc":[{"id":"1.187557247","rc":[{"batl":[[0,6,9.29],[1,12.5,3.01],[2,13.5,2.57]],"ltp":4.9,"tv":72279.4,"id":10350473},{"batb":[[0,1.25,466.8],[1,1.24,2014.94]],"batl":[[0,1.28,107.77]],"ltp":1.26,"tv":36852.67,"id":9304761}]}]}
{"op":"mcm","clk":"4230675504","pt":1631535424530,"mc":[{"id":"1.187557247","rc":[{"batb":[[0,1.25,906.63]],"batl":[[0,1.28,289.43],[1,1.29,725.31]],"ltp":1.26,"tv":36852.67,"id":9304761}]}]}
{"op":"mcm","clk":"4230675690","pt":1631535426624,"mc":[{"id":"1.187557247","rc":[{"batl":[[0,5.7,35.21],[1,5.8,6.06],[2,6,9.29]],"ltp":4.9,"tv":72279.4,"id":10350473}]}]}
{"op":"mcm","clk":"4230675789","pt":1631535427619,"mc":[{"id":"1.187557247","rc":[{"batl":[[0,6,9.29],[1,12.5,3.01],[2,13.5,2.57]],"ltp":4.9,"tv":72279.4,"id":10350473},{"batl":[[0,1.26,1.87],[1,1.28,289.43],[2,1.29,725.31]],"ltp":1.26,"tv":36852.67,"id":9304761}]}]}
{"op":"mcm","clk":"4230675862","pt":1631535428198,"mc":[{"id":"1.187557247","rc":[{"batl":[[0,1.26,5.77]],"ltp":1.26,"tv":36852.67,"id":9304761}]}]}
{"op":"mcm","clk":"4230676045","pt":1631535430209,"mc":[{"id":"1.187557247","rc":[{"batl":[[0,5.9,10.08],[1,6,9.29],[2,12.5,3.01]],"ltp":4.9,"tv":72279.4,"id":10350473}]}]}
{"op":"mcm","clk":"4230676180","pt":1631535431413,"mc":[{"id":"1.187557247","rc":[{"trd":[[1.26,164.45]],"batl":[[0,1.28,289.43],[1,1.29,725.31],[2,1.47,981.38]],"ltp":1.26,"tv":36864.09,"id":9304761}],"tv":109143.49}]}
{"op":"mcm","clk":"4230676388","pt":1631535433594,"mc":[{"id":"1.187557247","rc":[{"trd":[[1.25,3.41]],"batb":[[0,1.25,904.92]],"ltp":1.25,"tv":36867.49,"id":9304761}],"tv":109146.9}]}
{"op":"mcm","clk":"4230676714","pt":1631535437249,"mc":[{"id":"1.187557247","rc":[{"trd":[[5,0.74]],"batl":[[0,5.8,37.64],[1,5.9,10.08],[2,6,9.29]],"ltp":5.0,"tv":72280.14,"id":10350473},{"trd":[[1.25,12.06]],"batb":[[0,1.25,899.11]],"ltp":1.25,"tv":36876.15,"id":9304761}],"tv":109156.3}]}
{"op":"mcm","clk":"4230676956","pt":1631535440111,"mc":[{"id":"1.187557247","rc":[{"trd":[[1.25,19.88]],"batb":[[0,1.25,895.2]],"ltp":1.25,"tv":36883.97,"id":9304761}],"tv":109164.11}]}
{"op":"mcm","clk":"4230677108","pt":1631535441740,"mc":[{"id":"1.187557247","rc":[{"batl":[[2,1.5,5]],"ltp":1.25,"tv":36883.97,"id":9304761}]}]}
{"op":"mcm","clk":"4230677232","pt":1631535443134,"mc":[{"id":"1.187557247","rc":[{"trd":[[1.25,35.88]],"batb":[[0,1.25,887.2]],"ltp":1.25,"tv":36899.96,"id":9304761}],"tv":109180.11}]}
{"op":"mcm","clk":"4230679029","pt":1631535453627,"mc":[{"id":"1.187557247","rc":[{"batl":[[2,1.43,1.7]],"ltp":1.25,"tv":36899.96,"id":9304761}]}]}
{"op":"mcm","clk":"4230679086","pt":1631535454145,"mc":[{"id":"1.187557247","rc":[{"batl":[[1,6,9.29],[2,12.5,3.01]],"ltp":5.0,"tv":72280.14,"id":10350473}]}]}
{"op":"mcm","clk":"4230679171","pt":1631535455030,"mc":[{"id":"1.187557247","rc":[{"trd":[[1.28,489.8]],"batl":[[0,1.28,280.91]],"ltp":1.28,"tv":36917.0,"id":9304761}],"tv":109197.15}]}
{"op":"mcm","clk":"4230679396","pt":1631535457636,"mc":[{"id":"1.187557247","rc":[{"trd":[[4.5,83.67]],"batb":[[0,4.5,10.95]],"batl":[[0,4.6,1]],"ltp":4.5,"tv":72290.22,"id":10350473}],"tv":109207.23}]}
{"op":"mcm","clk":"4230679462","pt":1631535458371,"mc":[{"id":"1.187557247","rc":[{"trd":[[4.5,185.47]],"batb":[[0,4.4,8.81],[1,4.3,244.63],[2,4.2,237.43]],"batl":[[0,4.5,179.64],[1,4.6,1],[2,6,9.29]],"ltp":4.5,"tv":72392.02,"id":10350473},{"trd":[[1.28,770.71]],"batb":[[0,1.25,722.06],[1,1.24,1542.34]],"batl":[[0,1.29,725.31],[1,1.43,1.7],[2,1.5,5]],"ltp":1.28,"tv":37197.91,"id":9304761}],"tv":109589.94}]}
{"op":"mcm","clk":"4230679549","pt":1631535459051,"mc":[{"id":"1.187557247","rc":[{"batl":[[1,6,9.29],[2,12.5,3.01]],"ltp":4.5,"tv":72392.02,"id":10350473}]}]}
{"op":"mcm","clk":"4230679717","pt":1631535460336,"mc":[{"id":"1.187557247","rc":[{"batl":[[1,5.6,37.64],[2,6,9.29]],"ltp":4.5,"tv":72392.02,"id":10350473}]}]}
{"op":"mcm","clk":"4230679937","pt":1631535461766,"mc":[{"id":"1.187557247","rc":[{"batb":[[0,1.26,303.71],[1,1.25,722.06],[2,1.24,1542.34]],"batl":[[0,1.29,835.87],[1,1.3,336.68],[2,1.43,1.7]],"ltp":1.28,"tv":37197.91,"id":9304761}]}]}
{"op":"mcm","clk":"4230680025","pt":1631535462318,"mc":[{"id":"1.187557247","rc":[{"trd":[[4.5,227.81]],"batl":[[0,4.5,150.54]],"ltp":4.5,"tv":72434.36,"id":10350473},{"trd":[[1.28,826.48]],"batl":[[0,1.29,893.73]],"ltp":1.28,"tv":37253.68,"id":9304761}],"tv":109688.04}]}
{"op":"mcm","clk":"4230680760","pt":1631535466695,"mc":[{"id":"1.187557247","rc":[{"batb":[[1,1.25,485.95]],"ltp":1.28,"tv":37253.68,"id":9304761}]}]}
{"op":"mcm","clk":"4230680884","pt":1631535467355,"mc":[{"id":"1.187557247","rc":[{"batl":[[0,5.6,37.64],[1,6,9.29],[2,12.5,3.01]],"ltp":4.5,"tv":72434.36,"id":10350473}]}]}
{"op":"mcm","clk":"4230681078","pt":1631535468491,"mc":[{"id":"1.187557247","rc":[{"batl":[[0,6,9.29],[1,12.5,3.01],[2,13.5,2.57]],"ltp":4.5,"tv":72434.36,"id":10350473},{"trd":[[1.29,2010.47]],"batl":[[0,1.29,892.73]],"ltp":1.29,"tv":37255.68,"id":9304761}],"tv":109690.04}]}
{"op":"mcm","clk":"4230681474","pt":1631535470667,"mc":[{"id":"1.187557247","rc":[{"trd":[[1.29,2012.47]],"batb":[[0,1.25,46.04],[1,1.24,1542.34],[2,1.23,1496.98]],"batl":[[0,1.29,423.36],[1,1.43,1.7],[2,1.5,5]],"ltp":1.29,"tv":37257.68,"id":9304761}],"tv":109692.04}]}
{"op":"mcm","clk":"4230681609","pt":1631535471384,"mc":[{"id":"1.187557247","rc":[{"batb":[[2,4.2,239.43]],"ltp":4.5,"tv":72434.36,"id":10350473}]}]}
{"op":"mcm","clk":"4230682290","pt":1631535474596,"mc":[{"id":"1.187557247","rc":[{"batl":[[0,5.4,30.62],[1,6,9.29],[2,12.5,3.01]],"ltp":4.5,"tv":72434.36,"id":10350473},{"batb":[[0,1.26,303.71],[1,1.25,485.95],[2,1.24,1542.34]],"batl":[[0,1.29,891.73],[1,1.3,336.68],[2,1.43,1.7]],"ltp":1.29,"tv":37257.68,"id":9304761}]}]}
{"op":"mcm","clk":"4230682411","pt":1631535475253,"mc":[{"id":"1.187557247","rc":[{"batl":[[0,6,9.29],[1,12.5,3.01],[2,13.5,2.57]],"ltp":4.5,"tv":72434.36,"id":10350473},{"batb":[[0,1.25,46.04],[1,1.24,1542.34],[2,1.23,1496.98]],"batl":[[0,1.29,423.36],[1,1.43,1.7],[2,1.5,5]],"ltp":1.29,"tv":37257.68,"id":9304761}]}]}
{"op":"mcm","clk":"4230682653","pt":1631535476698,"mc":[{"id":"1.187557247","rc":[{"batb":[[0,1.24,1542.34],[1,1.23,1496.98],[2,1.22,1496.98]],"batl":[[0,1.29,365.5]],"ltp":1.29,"tv":37257.68,"id":9304761}]}]}
{"op":"mcm","clk":"4230682918","pt":1631535478166,"mc":[{"id":"1.187557247","rc":[{"batb":[[2,4.2,237.43]],"ltp":4.5,"tv":72434.36,"id":10350473}]}]}
{"op":"mcm","clk":"4230683729","pt":1631535483090,"mc":[{"id":"1.187557247","rc":[{"trd":[[4.4,130.11]],"batb":[[0,4.3,244.63],[1,4.2,237.43],[2,4.1,237.43]],"batl":[[0,4.4,34.51],[1,6,9.29],[2,12.5,3.01]],"ltp":4.4,"tv":72559.14,"id":10350473},{"trd":[[1.29,2377.97]],"batl":[[0,1.43,1.7],[1,1.5,5],[2,1.54,316.84]],"ltp":1.29,"tv":37623.18,"id":9304761}],"tv":110182.32}]}
{"op":"mcm","clk":"4230683956","pt":1631535484460,"mc":[{"id":"1.187557247","rc":[{"trd":[[4.4,164.62]],"batl":[[0,6,9.29],[1,12.5,3.01],[2,13.5,2.57]],"ltp":4.4,"tv":72593.65,"id":10350473},{"trd":[[1.29,2495.68]],"batb":[[0,1.26,303.71],[1,1.25,439.91],[2,1.24,1542.34]],"batl":[[0,1.29,350.66],[1,1.3,336.68],[2,1.43,1.7]],"ltp":1.29,"tv":37740.89,"id":9304761}],"tv":110334.54}]}
{"op":"mcm","clk":"4230684159","pt":1631535485678,"mc":[{"id":"1.187557247","rc":[{"trd":[[1.26,201.95]],"batb":[[0,1.26,284.96]],"ltp":1.26,"tv":37778.39,"id":9304761}],"tv":110372.04}]}
{"op":"mcm","clk":"4230684231","pt":1631535486099,"mc":[{"id":"1.187557247","rc":[{"trd":[[4.4,172.12]],"ltp":4.4,"tv":72601.15,"id":10350473},{"trd":[[1.29,2521.26]],"batl":[[0,1.29,325.08]],"ltp":1.29,"tv":37803.97,"id":9304761}],"tv":110405.12}]}
{"op":"mcm","clk":"4230684435","pt":1631535487468,"mc":[{"id":"1.187557247","rc":[{"batb":[[1,4.2,239.43],[2,4.1,240.43]],"ltp":4.4,"tv":72601.15,"id":10350473},{"batb":[[0,1.26,351.67]],"batl":[[0,1.29,377.75]],"ltp":1.29,"tv":37803.97,"id":9304761}]}]}
{"op":"mcm","clk":"4230684580","pt":1631535488570,"mc":[{"id":"1.187557247","rc":[{"trd":[[1.26,207.73]],"batb":[[0,1.26,348.78]],"ltp":1.26,"tv":37809.75,"id":9304761}],"tv":110410.91}]}
{"op":"mcm","clk":"4230684705","pt":1631535489510,"mc":[{"id":"1.187557247","rc":[{"batb":[[0,1.26,371.66]],"batl":[[0,1.29,399.32]],"ltp":1.26,"tv":37809.75,"id":9304761}]}]}
{"op":"mcm","clk":"4230684836","pt":1631535490509,"mc":[{"id":"1.187557247","rc":[{"batl":[[0,1.29,401.32]],"ltp":1.26,"tv":37809.75,"id":9304761}]}]}
{"op":"mcm","clk":"4230685186","pt":1631535493421,"mc":[{"id":"1.187557247","rc":[{"batl":[[0,1.29,399.32]],"ltp":1.26,"tv":37809.75,"id":9304761}]}]}
{"op":"mcm","clk":"4230685286","pt":1631535494203,"mc":[{"id":"1.187557247","rc":[{"trd":[[1.26,212.94]],"batb":[[0,1.26,369.06]],"ltp":1.26,"tv":37814.95,"id":9304761}],"tv":110416.11}]}
{"op":"mcm","clk":"4230685698","pt":1631535498390,"mc":[{"id":"1.187557247","rc":[{"batb":[[0,1.27,63.56],[1,1.26,369.06],[2,1.25,439.91]],"batl":[[0,1.28,72.88],[1,1.29,399.32],[2,1.3,336.68]],"ltp":1.26,"tv":37814.95,"id":9304761}]}]}
{"op":"mcm","clk":"4230685939","pt":1631535500717,"mc":[{"id":"1.187557247","rc":[{"batb":[[0,4.4,17.5],[1,4.3,244.63],[2,4.2,239.43]],"batl":[[0,5.6,36.76],[1,6,9.29],[2,12.5,3.01]],"ltp":4.4,"tv":72601.15,"id":10350473},{"batl":[[1,1.29,447.89]],"ltp":1.26,"tv":37814.95,"id":9304761}]}]}
{"op":"mcm","clk":"4230686529","pt":1631535505634,"mc":[{"id":"1.187557247","rc":[{"batl":[[2,6.6,7.06]],"ltp":4.4,"tv":72601.15,"id":10350473}]}]}
{"op":"mcm","clk":"4230686726","pt":1631535507319,"mc":[{"id":"1.187557247","rc":[{"trd":[[1.28,843.52]],"batl":[[0,1.28,64.36]],"ltp":1.28,"tv":37831.99,"id":9304761}],"tv":110433.14}]}
{"op":"mcm","clk":"4230687285","pt":1631535512209,"mc":[{"id":"1.187557247","rc":[{"batb":[[0,4.3,244.63],[1,4.2,239.43],[2,4.1,240.43]],"batl":[[0,6,9.29],[1,6.6,7.06],[2,8.8,4.37]],"ltp":4.4,"tv":72601.15,"id":10350473},{"batl":[[1,1.29,399.32]],"ltp":1.28,"tv":37831.99,"id":9304761}]}]}
{"op":"mcm","clk":"4230687796","pt":1631535516747,"mc":[{"id":"1.187557247","rc":[{"trd":[[4.5,239.81]],"batb":[[2,4.1,237.43]],"ltp":4.5,"tv":72613.15,"id":10350473},{"trd":[[1.28,885.71]],"batl":[[0,1.28,22.16]],"ltp":1.28,"tv":37874.19,"id":9304761}],"tv":110487.34}]}
{"op":"mcm","clk":"4230688122","pt":1631535519848,"mc":[{"id":"1.187557247","rc":[{"batb":[[2,4.1,240.43]],"ltp":4.5,"tv":72613.15,"id":10350473}]}]}
{"op":"mcm","clk":"4230688631","pt":1631535524864,"mc":[{"id":"1.187557247","rc":[{"batb":[[0,4.4,17.5],[1,4.3,244.63],[2,4.2,239.43]],"batl":[[0,5.6,36.76],[1,6,9.29],[2,6.6,7.06]],"ltp":4.5,"tv":72613.15,"id":10350473}]}]}
{"op":"mcm","clk":"4230688988","pt":1631535528264,"mc":[{"id":"1.187557247","rc":[{"batl":[[0,5.6,39.35]],"ltp":4.5,"tv":72613.15,"id":10350473}]}]}
{"op":"mcm","clk":"4230689337","pt":1631535531667,"mc":[{"id":"1.187557247","rc":[{"batb":[[0,4.2,2],[1,3.9,11.86],[2,3.7,12.22]],"batl":[[0,8.8,4.37],[1,990,0.01],[2,6.6,0]],"ltp":4.5,"tv":72613.15,"id":10350473},{"batb":[[1,1.13,719.21],[2,1.08,3.09]],"batl":[[1,1.34,277.25],[2,1.37,276.5]],"ltp":1.28,"tv":37874.19,"id":9304761}]}]}
{"op":"mcm","clk":"4230689539","pt":1631535533764,"mc":[{"id":"1.187557247","rc":[{"batl":[[0,1.34,277.25],[1,1.37,276.5],[2,1.43,1.7]],"ltp":1.28,"tv":37874.19,"id":9304761}]}]}
{"op":"mcm","clk":"4230689643","pt":1631535534755,"mc":[{"id":"1.187557247","rc":[{"batb":[[0,4.1,2],[1,3.7,12.22],[2,1.35,2.32]],"ltp":4.5,"tv":72613.15,"id":10350473},{"batl":[[0,1.37,276.5],[1,1.43,1.7],[2,1.5,5]],"ltp":1.28,"tv":37874.19,"id":9304761}]}]}
{"op":"mcm","clk":"4230689662","pt":1631535534962,"mc":[{"id":"1.187557247","rc":[{"batb":[[0,3.7,12.22],[1,1.35,2.32],[2,1.28,720.76]],"ltp":4.5,"tv":72613.15,"id":10350473}]}]}
{"op":"mcm","clk":"4230689816","pt":1631535536578,"mc":[{"id":"1.187557247","rc":[{"batb":[[0,1.27,405.48],[1,1.26,420.16],[2,1.13,719.21]],"batl":[[0,1.3,326.51],[1,1.31,324.77],[2,1.37,276.5]],"ltp":1.28,"tv":37874.19,"id":9304761}]}]}
{"op":"mcm","clk":"4230689920","pt":1631535537570,"mc":[{"id":"1.187557247","rc":[{"batb":[[0,4.3,10],[1,3.9,11.86],[2,3.85,3]],"ltp":4.5,"tv":72613.15,"id":10350473},{"batl":[[2,1.33,117.41]],"ltp":1.28,"tv":37874.19,"id":9304761}]}]}
{"op":"mcm","clk":"4230690003","pt":1631535538252,"mc":[{"id":"1.187557247","rc":[{"batb":[[0,3.9,11.86],[1,3.85,3],[2,3.8,2]],"batl":[[0,6.6,6.71],[1,8.8,4.37],[2,990,0.01]],"ltp":4.5,"tv":72613.15,"id":10350473},{"batb":[[2,1.18,553.36]],"batl":[[2,1.34,280.25]],"ltp":1.28,"tv":37874.19,"id":9304761}]}]}
{"op":"mcm","clk":"4230690232","pt":1631535540568,"mc":[{"id":"1.187557247","rc":[{"batl":[[0,4.8,21.85],[1,6.6,6.71],[2,8.8,4.37]],"ltp":4.5,"tv":72613.15,"id":10350473},{"batb":[[0,1.18,553.36],[1,1.13,719.21],[2,1.08,3.09]],"batl":[[0,1.34,280.25],[1,1.35,7],[2,1.37,283.5]],"ltp":1.28,"tv":37874.19,"id":9304761}]}]}
{"op":"mcm","clk":"4230690300","pt":1631535541256,"mc":[{"id":"1.187557247","rc":[{"batb":[[0,3.85,3],[1,3.8,2],[2,3.7,15.22]],"batl":[[0,8.8,4.37],[1,990,0.01],[2,8.8,0]],"ltp":4.5,"tv":72613.15,"id":10350473},{"batb":[[0,1.13,719.21],[1,1.08,3.09],[2,1.07,2.22]],"batl":[[0,1.35,7],[1,1.37,283.5],[2,1.43,1.7]],"ltp":1.28,"tv":37874.19,"id":9304761}]}]}
{"op":"mcm","clk":"4230690517","pt":1631535543564,"mc":[{"id":"1.187557247","rc":[{"batb":[[0,1.21,640.08],[1,1.2,530.88],[2,1.13,719.21]],"batl":[[0,1.35,298.44],[1,1.36,270.09],[2,1.37,283.5]],"ltp":1.28,"tv":37874.19,"id":9304761}]}]}
{"op":"mcm","clk":"4230690589","pt":1631535544349,"mc":[{"id":"1.187557247","rc":[{"batb":[[0,3.9,2],[1,3.85,3],[2,3.8,2]],"batl":[[0,6.6,6.36],[1,8.8,4.37],[2,990,0.01]],"ltp":4.5,"tv":72613.15,"id":10350473},{"batb":[[2,1.18,555.36]],"batl":[[0,1.34,9],[1,1.35,298.44],[2,1.36,270.09]],"ltp":1.28,"tv":37874.19,"id":9304761}]}]}
{"op":"mcm","clk":"4230690779","pt":1631535546341,"mc":[{"id":"1.187557247","rc":[{"batb":[[0,1.3,3.9],[1,1.21,640.08],[2,1.2,530.88]],"ltp":1.28,"tv":37874.19,"id":9304761}]}]}
{"op":"mcm","clk":"4230690914","pt":1631535547744,"mc":[{"id":"1.187557247","rc":[{"batb":[[0,3.9,14.66]],"batl":[[0,8.8,4.37],[1,990,0.01],[2,990,0]],"ltp":4.5,"tv":72613.15,"id":10350473},{"batb":[[1,1.13,719.21],[2,1.08,3.09]],"batl":[[0,1.34,317.75]],"ltp":1.28,"tv":37874.19,"id":9304761}]}]}
{"op":"mcm","clk":"4230690926","pt":1631535547859,"mc":[{"id":"1.187557247","rc":[{"batb":[[0,3.9,2]],"ltp":4.5,"tv":72613.15,"id":10350473},{"batl":[[0,1.34,9]],"ltp":1.28,"tv":37874.19,"id":9304761}]}]}
{"op":"mcm","clk":"4230691188","pt":1631535550738,"mc":[{"id":"1.187557247","rc":[{"trd":[[3.85,9.23],[3.9,303.69]],"batb":[[0,3.95,10],[1,3.7,12.22],[2,1.35,2.32]],"batl":[[0,5,27.81],[1,5.5,31.8],[2,8.8,4.37]],"ltp":3.85,"tv":72621.18,"id":10350473},{"trd":[[1.34,213.15]],"batb":[[0,1.32,266.39],[1,1.31,1795.23],[2,1.3,1420.88]],"batl":[[0,1.33,45],[1,1.35,291.44]],"ltp":1.34,"tv":37883.19,"id":9304761}],"tv":110504.37}]}
{"op":"mcm","clk":"4230691227","pt":1631535551146,"mc":[{"id":"1.187557247","rc":[{"batb":[[0,3.7,12.22],[1,1.35,2.32],[2,1.28,720.76]],"batl":[[1,8.8,4.37],[2,990,0.01]],"ltp":3.85,"tv":72621.18,"id":10350473},{"batl":[[0,1.35,291.44],[1,1.36,270.09],[2,1.37,1044.29]],"ltp":1.34,"tv":37883.19,"id":9304761}]}]}
{"op":"mcm","clk":"4230691316","pt":1631535552037,"mc":[{"id":"1.187557247","rc":[{"batb":[[1,1.31,1814.73]],"ltp":1.34,"tv":37883.19,"id":9304761}]}]}
{"op":"mcm","clk":"4230691441","pt":1631535553346,"mc":[{"id":"1.187557247","rc":[{"batl":[[0,4.1,3],[1,5,27.81],[2,8.8,4.37]],"ltp":3.85,"tv":72621.18,"id":10350473},{"batb":[[1,1.31,1821.73],[2,1.3,1428.88]],"ltp":1.34,"tv":37883.19,"id":9304761}]}]}
{"op":"mcm","clk":"4230691576","pt":1631535554551,"mc":[{"id":"1.187557247","rc":[{"batb":[[0,3.75,25.59],[1,3.7,12.22],[2,1.35,2.32]],"batl":[[1,4.8,43.8],[2,5,27.81]],"ltp":3.85,"tv":72621.18,"id":10350473},{"batb":[[0,1.33,119.74],[1,1.32,266.39],[2,1.31,1821.73]],"batl":[[0,1.34,63.49],[1,1.35,336.44],[2,1.36,270.09]],"ltp":1.34,"tv":37883.19,"id":9304761}]}]}
{"op":"mcm","clk":"4230691661","pt":1631535555342,"mc":[{"id":"1.187557247","rc":[{"trd":[[4.1,8.3]],"batl":[[0,4.1,2.18]],"ltp":4.1,"tv":72622.82,"id":10350473},{"trd":[[1.33,295.27]],"batb":[[0,1.33,117.05],[1,1.32,333.03]],"batl":[[1,1.35,396.81]],"ltp":1.33,"tv":37888.57,"id":9304761}],"tv":110511.39}]}
{"op":"mcm","clk":"4230691880","pt":1631535557437,"mc":[{"id":"1.187557247","rc":[{"batb":[[2,3.5,12.36]],"ltp":4.1,"tv":72622.82,"id":10350473}]}]}
{"op":"mcm","clk":"4230692018","pt":1631535559047,"mc":[{"id":"1.187557247","rc":[{"trd":[[1.33,299.92]],"batb":[[0,1.33,114.73]],"ltp":1.33,"tv":37893.22,"id":9304761}],"tv":110516.04}]}
{"op":"mcm","clk":"4230692436","pt":1631535562674,"mc":[{"id":"1.187557247","rc":[{"batb":[[1,1.32,249.14]],"batl":[[1,1.35,336.44]],"ltp":1.33,"tv":37893.22,"id":9304761}]}]}
{"op":"mcm","clk":"4230692518","pt":1631535563568,"mc":[{"id":"1.187557247","rc":[{"trd":[[1.34,220.97]],"batl":[[0,1.34,59.58]],"ltp":1.34,"tv":37901.03,"id":9304761}],"tv":110523.86}]}
{"op":"mcm","clk":"4230692616","pt":1631535564661,"mc":[{"id":"1.187557247","rc":[{"batb":[[0,3.3,15.48],[1,1.35,2.32],[2,1.28,720.76]],"batl":[[1,7.4,5.79],[2,990,0.01]],"ltp":4.1,"tv":72622.82,"id":10350473},{"trd":[[1.34,225.62]],"batb":[[0,1.31,7],[1,1.3,11.9],[2,1.26,9.23]],"batl":[[0,1.42,11.39],[1,1.43,256.2],[2,1.5,5]],"ltp":1.34,"tv":37905.68,"id":9304761}],"tv":110528.5}]}
{"op":"mcm","clk":"4230692644","pt":1631535564967,"mc":[{"id":"1.187557247","rc":[{"batl":[[0,7.4,5.79],[1,990,0.01],[2,990,0]],"ltp":4.1,"tv":72622.82,"id":10350473},{"batb":[[0,1.3,3.9],[1,1.26,9.23],[2,1.16,700.03]],"ltp":1.34,"tv":37905.68,"id":9304761}]}]}
{"op":"mcm","clk":"4230692858","pt":1631535567166,"mc":[{"id":"1.187557247","rc":[{"trd":[[1.3,102.53]],"batb":[[0,1.26,518.6],[1,1.25,443.05]],"batl":[[0,1.27,1.09],[1,1.42,218.58],[2,1.43,472.24]],"ltp":1.3,"tv":37913.5,"id":9304761}],"tv":110536.32}]}
{"op":"mcm","clk":"4230692993","pt":1631535568584,"mc":[{"id":"1.187557247","rc":[{"batb":[[0,3.35,2],[1,3.3,17.48],[2,1.35,2.32]],"batl":[[0,5.6,7.31],[1,7.4,5.79],[2,990,0.01]],"ltp":4.1,"tv":72622.82,"id":10350473},{"batb":[[2,1.22,422.84]],"batl":[[1,1.42,225.58]],"ltp":1.3,"tv":37913.5,"id":9304761}]}]}
{"op":"mcm","clk":"4230693187","pt":1631535570241,"mc":[{"id":"1.187557247","rc":[{"trd":[[1.27,1097.45]],"batl":[[0,1.42,225.58],[1,1.43,472.24],[2,1.5,5]],"ltp":1.27,"tv":37915.68,"id":9304761}],"tv":110538.5}]}
{"op":"mcm","clk":"4230693319","pt":1631535571566,"mc":[{"id":"1.187557247","rc":[{"batb":[[0,3.5,2],[1,3.45,3],[2,3.35,2]],"ltp":4.1,"tv":72622.82,"id":10350473},{"batb":[[0,1.26,509.37]],"batl":[[0,1.4,6],[1,1.42,18.39],[2,1.43,256.2]],"ltp":1.27,"tv":37915.68,"id":9304761}]}]}
{"op":"mcm","clk":"4230693485","pt":1631535573291,"mc":[{"id":"1.187557247","rc":[{"batl":[[0,1.33,1929.2],[1,1.4,6],[2,1.42,18.39]],"ltp":1.27,"tv":37915.68,"id":9304761}]}]}
{"op":"mcm","clk":"4230693637","pt":1631535574752,"mc":[{"id":"1.187557247","rc":[{"batl":[[0,990,0.01],[1,7.4,0],[2,990,0]],"ltp":4.1,"tv":72622.82,"id":10350473},{"batb":[[0,1.1,1.16],[1,1.08,2.41],[2,1.07,2.22]],"ltp":1.27,"tv":37915.68,"id":9304761}]}]}
{"op":"mcm","clk":"4230693719","pt":1631535575538,"mc":[{"id":"1.187557247","rc":[{"batl":[[0,4.1,4.88],[1,990,0.01]],"ltp":4.1,"tv":72622.82,"id":10350473},{"batl":[[2,1.42,7]],"ltp":1.27,"tv":37915.68,"id":9304761}]}]}
{"op":"mcm","clk":"4230693821","pt":1631535576744,"mc":[{"id":"1.187557247","rc":[{"batb":[[0,1.21,428.69],[1,1.2,576.63],[2,1.1,1.16]],"batl":[[1,1.36,175.86],[2,1.37,262.35]],"ltp":1.27,"tv":37915.68,"id":9304761}]}]}
{"op":"mcm","clk":"4230693868","pt":1631535577264,"mc":[{"id":"1.187557247","rc":[{"batl":[[1,5.6,2],[2,990,0.01]],"ltp":4.1,"tv":72622.82,"id":10350473},{"batb":[[0,1.22,9],[1,1.21,442.69],[2,1.2,586.63]],"ltp":1.27,"tv":37915.68,"id":9304761}]}]}
{"op":"mcm","clk":"4230693987","pt":1631535578684,"mc":[{"id":"1.187557247","rc":[{"trd":[[4.1,13.18]],"batl":[[0,5.6,2],[1,990,0.01],[2,990,0]],"ltp":4.1,"tv":72627.7,"id":10350473},{"trd":[[1.32,155.45]],"batb":[[0,1.3,17.17],[1,1.29,34.62],[2,1.28,67.8]],"batl":[[0,1.31,60.09],[1,1.33,1929.2],[2,1.36,175.86]],"ltp":1.32,"tv":37930.84,"id":9304761}],"tv":110558.54}]}
{"op":"mcm","clk":"4230694047","pt":1631535579303,"mc":[{"id":"1.187557247","rc":[{"batb":[[2,3.3,15.48]],"ltp":4.1,"tv":72627.7,"id":10350473},{"batl":[[1,1.32,71.66],[2,1.33,1929.2]],"ltp":1.32,"tv":37930.84,"id":9304761}]}]}
{"op":"mcm","clk":"4230694122","pt":1631535579984,"mc":[{"id":"1.187557247","rc":[{"trd":[[4.4,172.8]],"ltp":4.4,"tv":72628.38,"id":10350473},{"trd":[[1.3,110.33]],"batb":[[0,1.3,12.12]],"ltp":1.3,"tv":37938.63,"id":9304761}],"tv":110567.02}]}
{"op":"mcm","clk":"4230694541","pt":1631535584744,"mc":[{"id":"1.187557247","rc":[{"batb":[[1,3.3,15.48],[2,1.35,2.32]],"ltp":4.4,"tv":72628.38,"id":10350473},{"batb":[[0,1.22,9],[1,1.21,442.69],[2,1.2,586.63]],"batl":[[0,1.36,175.86],[1,1.37,262.35],[2,1.4,6]],"ltp":1.3,"tv":37938.63,"id":9304761}]}]}
{"op":"mcm","clk":"4230694571","pt":1631535585170,"mc":[{"id":"1.187557247","rc":[{"batb":[[1,1.35,2.32],[2,1.28,720.76]],"ltp":4.4,"tv":72628.38,"id":10350473},{"batb":[[1,1.21,14],[2,1.2,10]],"batl":[[0,1.4,6],[1,1.43,1.7],[2,1.5,5]],"ltp":1.3,"tv":37938.63,"id":9304761}]}]}
{"op":"mcm","clk":"4230694722","pt":1631535586754,"mc":[{"id":"1.187557247","rc":[{"batb":[[1,1.28,720.76],[2,1.2,2]],"ltp":4.4,"tv":72628.38,"id":10350473},{"batl":[[0,1.35,13.52],[1,1.4,6],[2,1.43,1.7]],"ltp":1.3,"tv":37938.63,"id":9304761}]}]}
{"op":"mcm","clk":"4230694802","pt":1631535587751,"mc":[{"id":"1.187557247","rc":[{"batb":[[0,1.26,509.37],[1,1.25,443.05],[2,1.22,9]],"batl":[[0,1.29,275.65],[1,1.3,339.02],[2,1.32,1929.2]],"ltp":1.3,"tv":37938.63,"id":9304761}]}]}
{"op":"mcm","clk":"4230694871","pt":1631535588584,"mc":[{"id":"1.187557247","rc":[{"batb":[[0,3.6,335.88],[1,3.5,2],[2,3.45,3]],"ltp":4.4,"tv":72628.38,"id":10350473},{"batb":[[2,1.23,1118.62]],"ltp":1.3,"tv":37938.63,"id":9304761}]}]}
{"op":"mcm","clk":"4230695370","pt":1631535594686,"mc":[{"id":"1.187557247","rc":[{"batl":[[2,1.32,1931.2]],"ltp":1.3,"tv":37938.63,"id":9304761}]}]}
{"op":"mcm","clk":"4230695407","pt":1631535595206,"mc":[{"id":"1.187557247","rc":[{"batb":[[2,1.22,9]],"ltp":1.3,"tv":37938.63,"id":9304761}]}]}
{"op":"mcm","clk":"4230696031","pt":1631535601679,"mc":[{"id":"1.187557247","rc":[{"batb":[[0,3.5,2],[1,1.28,720.76],[2,1.2,2]],"ltp":4.4,"tv":72628.38,"id":10350473},{"batb":[[0,1.22,9],[1,1.1,1.16],[2,1.09,13.12]],"batl":[[0,1.32,1931.2],[1,1.35,13.52],[2,1.4,6]],"ltp":1.3,"tv":37938.63,"id":9304761}]}]}
{"op":"mcm","clk":"4230696300","pt":1631535604608,"mc":[{"id":"1.187557247","rc":[{"batb":[[1,1.21,448.4],[2,1.2,576.67]],"batl":[[2,1.36,170.42]],"ltp":1.3,"tv":37938.63,"id":9304761}]}]}
{"op":"mcm","clk":"4230696327","pt":1631535604872,"mc":[{"id":"1.187557247","rc":[{"batb":[[1,3.45,2],[2,1.28,720.76]],"ltp":4.4,"tv":72628.38,"id":10350473}]}]}
{"op":"mcm","clk":"4230696632","pt":1631535608591,"mc":[{"id":"1.187557247","rc":[{"batl":[[2,1.4,6]],"ltp":1.3,"tv":37938.63,"id":9304761}]}]}
{"op":"mcm","clk":"4230696715","pt":1631535609481,"mc":[{"id":"1.187557247","rc":[{"batl":[[0,1.32,2]],"ltp":1.3,"tv":37938.63,"id":9304761}]}]}
{"op":"mcm","clk":"4230696814","pt":1631535610579,"mc":[{"id":"1.187557247","rc":[{"batl":[[1,6.2,616.94],[2,6.4,598.8]],"ltp":4.4,"tv":72628.38,"id":10350473},{"batb":[[0,1.21,448.4],[1,1.2,576.67],[2,1.1,1.16]],"batl":[[0,1.24,1895.16],[1,1.25,947.58],[2,1.26,947.58]],"ltp":1.3,"tv":37938.63,"id":9304761}]}]}
{"op":"mcm","clk":"4230696906","pt":1631535611577,"mc":[{"id":"1.187557247","rc":[{"trd":[[5.3,30.96]],"batb":[[0,4,357.39],[1,3.5,2],[2,3.45,2]],"batl":[[1,6.2,169.65],[2,6.4,164.67]],"ltp":5.3,"tv":72632.64,"id":10350473},{"trd":[[1.23,496.47]],"batl":[[0,1.23,165.63],[1,1.24,1583.21],[2,1.25,568.55]],"ltp":1.23,"tv":37956.99,"id":9304761}],"tv":110589.64}]}
{"op":"mcm","clk":"4230697012","pt":1631535612579,"mc":[{"id":"1.187557247","rc":[{"batl":[[0,1.22,1929.2]],"ltp":1.23,"tv":37956.99,"id":9304761}]}]}
{"op":"mcm","clk":"4230697080","pt":1631535613308,"mc":[{"id":"1.187557247","rc":[{"batb":[[0,4.6,10],[1,4,357.39],[2,3.9,3]],"ltp":5.3,"tv":72632.64,"id":10350473},{"batb":[[0,1.21,489.26]],"ltp":1.23,"tv":37956.99,"id":9304761}]}]}
{"op":"mcm","clk":"4230697285","pt":1631535615683,"mc":[{"id":"1.187557247","rc":[{"trd":[[5.6,1.34]],"batl":[[0,6.2,169.65],[1,6.4,164.67],[2,6.6,164.67]],"ltp":5.6,"tv":72633.98,"id":10350473},{"trd":[[1.21,1009.4],[1.22,336.56]],"batb":[[0,1.21,566.73]],"batl":[[0,1.22,1863.08],[1,1.23,76.19],[2,1.24,1583.21]],"ltp":1.21,"tv":38094.42,"id":9304761}],"tv":110728.4}]}
{"op":"mcm","clk":"4230697571","pt":1631535618721,"mc":[{"id":"1.187557247","rc":[{"batl":[[0,5.7,2],[1,6,15.78],[2,6.2,169.65]],"ltp":5.6,"tv":72633.98,"id":10350473},{"batl":[[1,1.23,249.69]],"ltp":1.21,"tv":38094.42,"id":9304761}]}]}
{"op":"mcm","clk":"4230697583","pt":1631535618828,"mc":[{"id":"1.187557247","rc":[{"batb":[[1,3.9,3],[2,3.85,2]],"ltp":5.6,"tv":72633.98,"id":10350473}]}]}
{"op":"mcm","clk":"4230697811","pt":1631535621612,"mc":[{"id":"1.187557247","rc":[{"batb":[[0,4.9,2],[1,4.8,2],[2,4.6,10]],"batl":[[0,5.6,3],[1,5.7,2],[2,6,15.78]],"ltp":5.6,"tv":72633.98,"id":10350473},{"batb":[[0,1.21,53.86],[1,1.1,1.16],[2,1.08,2.41]],"batl":[[0,1.28,10],[1,1.34,7],[2,1.4,6]],"ltp":1.21,"tv":38094.42,"id":9304761}]}]}
{"op":"mcm","clk":"4230697842","pt":1631535622028,"mc":[{"id":"1.187557247","rc":[{"batb":[[0,3.9,3],[1,3.85,2],[2,1.28,720.76]],"ltp":5.6,"tv":72633.98,"id":10350473}]}]}
{"op":"mcm","clk":"4230697938","pt":1631535623231,"mc":[{"id":"1.187557247","rc":[{"batl":[[0,990,0.01],[1,5.7,0],[2,6,0]],"ltp":5.6,"tv":72633.98,"id":10350473},{"batb":[[0,1.1,1.16],[1,1.09,10.86],[2,1.08,2.21]],"batl":[[0,1.27,10.18]],"ltp":1.21,"tv":38094.42,"id":9304761}]}]}
{"op":"mcm","clk":"4230698080","pt":1631535624711,"mc":[{"id":"1.187557247","rc":[{"batb":[[0,4.6,2],[1,3.9,3]],"ltp":5.6,"tv":72633.98,"id":10350473},{"batb":[[0,1.17,192.41],[1,1.16,736.9],[2,1.1,1.16]],"batl":[[0,1.21,1882.6],[1,1.27,10.18],[2,1.3,455.6]],"ltp":1.21,"tv":38094.42,"id":9304761}]}]}
{"op":"mcm","clk":"4230698148","pt":1631535625341,"mc":[{"id":"1.187557247","rc":[{"batb":[[1,4.5,2],[2,3.9,3]],"ltp":5.6,"tv":72633.98,"id":10350473}]}]}
{"op":"mcm","clk":"4230698267","pt":1631535626393,"mc":[{"id":"1.187557247","rc":[{"batb":[[2,4.4,2]],"ltp":5.6,"tv":72633.98,"id":10350473}]}]}
{"op":"mcm","clk":"4230698513","pt":1631535629651,"mc":[{"id":"1.187557247","rc":[{"trd":[[1.21,1014.06]],"batl":[[0,1.21,1880.27]],"ltp":1.21,"tv":38099.07,"id":9304761}],"tv":110733.05}]}
{"op":"mcm","clk":"4230698680","pt":1631535631423,"mc":[{"id":"1.187557247","rc":[{"batl":[[0,1.21,1860.75]],"ltp":1.21,"tv":38099.07,"id":9304761}]}]}
{"op":"mcm","clk":"4230698868","pt":1631535633641,"mc":[{"id":"1.187557247","rc":[{"batl":[[2,1.34,7]],"ltp":1.21,"tv":38099.07,"id":9304761}]}]}
{"op":"mcm","clk":"4230699106","pt":1631535636455,"mc":[{"id":"1.187557247","rc":[{"batb":[[0,6,316.05],[1,5.9,306.77],[2,5.8,306.77]],"batl":[[0,7.6,138.4],[1,7.8,134.33],[2,8,134.33]],"ltp":5.6,"tv":72633.98,"id":10350473},{"batl":[[0,1.19,648],[1,1.2,533.69],[2,1.21,1860.75]],"ltp":1.21,"tv":38099.07,"id":9304761}]}]}
{"op":"mcm","clk":"4230699188","pt":1631535637459,"mc":[{"id":"1.187557247","rc":[{"trd":[[6.2,3.64]],"ltp":6.2,"tv":72637.62,"id":10350473},{"trd":[[1.19,153.01]],"batl":[[0,1.19,629.04]],"ltp":1.19,"tv":38118.03,"id":9304761}],"tv":110755.65}]}
{"op":"mcm","clk":"4230699378","pt":1631535639667,"mc":[{"id":"1.187557247","rc":[{"batl":[[0,7.4,12.87],[1,7.6,138.4],[2,7.8,134.33]],"ltp":6.2,"tv":72637.62,"id":10350473},{"trd":[[1.19,179.05]],"batl":[[0,1.19,616.02]],"ltp":1.19,"tv":38144.07,"id":9304761}],"tv":110781.69}]}
{"op":"mcm","clk":"4230699434","pt":1631535640452,"mc":[{"id":"1.187557247","rc":[{"batb":[[0,1.17,270.98],[2,1.11,462.04]],"batl":[[0,1.19,681.37]],"ltp":1.19,"tv":38144.07,"id":9304761}]}]}
{"op":"mcm","clk":"4230699511","pt":1631535641242,"mc":[{"id":"1.187557247","rc":[{"trd":[[7,0.49]],"batb":[[0,6.2,17.25],[1,6,316.05],[2,5.9,306.77]],"ltp":7.0,"tv":72638.11,"id":10350473},{"trd":[[1.17,289.1]],"batb":[[0,1.17,265.1]],"batl":[[0,1.19,805.09]],"ltp":1.17,"tv":38152.86,"id":9304761}],"tv":110790.98}]}
{"op":"mcm","clk":"4230699604","pt":1631535642147,"mc":[{"id":"1.187557247","rc":[{"trd":[[1.17,329.6]],"batb":[[0,1.17,244.85]],"ltp":1.17,"tv":38193.36,"id":9304761}],"tv":110831.48}]}
{"op":"mcm","clk":"4230699720","pt":1631535643351,"mc":[{"id":"1.187557247","rc":[{"batl":[[0,6.8,3],[1,7.4,12.87],[2,7.6,138.4]],"ltp":7.0,"tv":72638.11,"id":10350473}]}]}
{"op":"mcm","clk":"4230699855","pt":1631535644668,"mc":[{"id":"1.187557247","rc":[{"batb":[[0,1.17,267.44]],"batl":[[0,1.19,736.79]],"ltp":1.17,"tv":38193.36,"id":9304761}]}]}
{"op":"mcm","clk":"4230699939","pt":1631535645574,"mc":[{"id":"1.187557247","rc":[{"batb":[[1,4.6,2],[2,1.28,720.76]],"batl":[[2,990,0.01]],"ltp":7.0,"tv":72638.11,"id":10350473},{"batl":[[0,1.19,763.38]],"ltp":1.17,"tv":38193.36,"id":9304761}]}]}
{"op":"mcm","clk":"4230699990","pt":1631535646050,"mc":[{"id":"1.187557247","rc":[{"batb":[[0,4.6,2],[1,1.28,720.76],[2,1.2,2]],"batl":[[0,990,0.01],[1,7.4,0],[2,990,0]],"ltp":7.0,"tv":72638.11,"id":10350473},{"batb":[[0,1.11,462.04],[1,1.09,10.44],[2,1.08,2.21]],"batl":[[0,1.21,1860.75],[1,1.34,7],[2,1.43,1.7]],"ltp":1.17,"tv":38193.36,"id":9304761}]}]}
{"op":"mcm","clk":"4230700273","pt":1631535648647,"mc":[{"id":"1.187557247","rc":[{"batb":[[0,5.7,7.12],[1,5.3,7.08],[2,4.6,2]],"batl":[[0,11,4.17],[1,990,0.01]],"ltp":7.0,"tv":72638.11,"id":10350473},{"batb":[[0,1.14,332.54],[1,1.13,914.17],[2,1.12,9.37]],"batl":[[0,1.21,2398.25],[1,1.22,647.64],[2,1.23,907.77]],"ltp":1.17,"tv":38193.36,"id":9304761}]}]}
{"op":"mcm","clk":"4230700336","pt":1631535649396,"mc":[{"id":"1.187557247","rc":[{"batl":[[0,10.5,2],[1,11,4.17],[2,990,0.01]],"ltp":7.0,"tv":72638.11,"id":10350473},{"batb":[[0,1.12,9.84],[1,1.11,479.36],[2,1.1,1043.49]],"batl":[[1,1.22,428.25],[2,1.23,439.5]],"ltp":1.17,"tv":38193.36,"id":9304761}]}]}
{"op":"mcm","clk":"4230700527","pt":1631535651390,"mc":[{"id":"1.187557247","rc":[{"batl":[[0,8.8,2],[1,10.5,2],[2,11,4.17]],"ltp":7.0,"tv":72638.11,"id":10350473},{"batb":[[0,1.19,4],[1,1.13,15.48],[2,1.12,29.37]],"ltp":1.17,"tv":38193.36,"id":9304761}]}]}
{"op":"mcm","clk":"4230700672","pt":1631535652684,"mc":[{"id":"1.187557247","rc":[{"batl":[[0,8.2,3],[1,8.8,2],[2,10.5,2]],"ltp":7.0,"tv":72638.11,"id":10350473},{"trd":[[1.19,187.05]],"batb":[[0,1.17,650.93],[1,1.16,560.32],[2,1.13,15.48]],"batl":[[0,1.19,227.3],[1,1.2,551.34],[2,1.21,2398.25]],"ltp":1.19,"tv":38201.36,"id":9304761}],"tv":110839.48}]}
{"op":"mcm","clk":"4230700757","pt":1631535653563,"mc":[{"id":"1.187557247","rc":[{"batb":[[0,5.8,21.51],[1,5.7,7.12],[2,5.3,7.08]],"batl":[[0,7.8,10],[1,8.2,3],[2,8.8,2]],"ltp":7.0,"tv":72638.11,"id":10350473},{"batb":[[2,1.14,49.48]],"batl":[[1,1.2,619.83]],"ltp":1.19,"tv":38201.36,"id":9304761}]}]}
{"op":"mcm","clk":"4230700845","pt":1631535654458,"mc":[{"id":"1.187557247","rc":[{"batb":[[2,1.13,15.48]],"batl":[[2,1.21,537.5]],"ltp":1.19,"tv":38201.36,"id":9304761}]}]}
{"op":"mcm","clk":"4230700941","pt":1631535655401,"mc":[{"id":"1.187557247","rc":[{"batl":[[2,8.8,7.42]],"ltp":7.0,"tv":72638.11,"id":10350473},{"batb":[[2,1.13,665.21]],"ltp":1.19,"tv":38201.36,"id":9304761}]}]}
{"op":"mcm","clk":"4230701160","pt":1631535657583,"mc":[{"id":"1.187557247","rc":[{"trd":[[8.2,3],[8.8,2]],"batb":[[0,5.3,7.08],[1,4.6,2],[2,1.28,720.76]],"batl":[[0,10.5,2],[1,11,4.17],[2,990,0.01]],"ltp":8.8,"tv":72643.11,"id":10350473},{"trd":[[1.11,960.11],[1.12,74.59],[1.13,52.38],[1.14,0.46]],"batb":[[0,1.1,1043.49],[1,1.09,10.2],[2,1.08,2.21]],"batl":[[0,1.11,1297.41],[1,1.23,439.5],[2,1.33,10.03]],"ltp":1.11,"tv":39288.91,"id":9304761}],"tv":111932.02}]}
{"op":"mcm","clk":"4230701190","pt":1631535657899,"mc":[{"id":"1.187557247","rc":[{"batl":[[0,11,4.17],[1,990,0.01],[2,990,0]],"ltp":8.8,"tv":72643.11,"id":10350473},{"batb":[[0,1.1,1024.49],[1,1.08,2.41],[2,1.07,2.22]],"ltp":1.11,"tv":39288.91,"id":9304761}]}]}
{"op":"mcm","clk":"4230701486","pt":1631535660667,"mc":[{"id":"1.187557247","rc":[{"batb":[[0,5.7,6.72],[1,5.5,2],[2,5.4,3]],"batl":[[0,8.8,5.17],[1,11,4.17],[2,990,0.01]],"ltp":8.8,"tv":72643.11,"id":10350473},{"trd":[[1.11,3550.93]],"batb":[[0,1.13,672.73],[1,1.12,781.59],[2,1.1,1024.49]],"batl":[[0,1.21,455.5],[1,1.22,608.99],[2,1.23,449.5]],"ltp":1.11,"tv":41879.72,"id":9304761}],"tv":114522.84}]}
{"op":"mcm","clk":"4230701529","pt":1631535661088,"mc":[{"id":"1.187557247","rc":[{"batb":[[0,5.5,2],[1,5.4,3],[2,5.3,10.08]],"batl":[[0,11,4.17],[1,990,0.01],[2,990,0]],"ltp":8.8,"tv":72643.11,"id":10350473},{"batb":[[0,1.1,1024.49],[1,1.08,2.41],[2,1.07,2.22]],"batl":[[0,1.22,217.24],[1,1.23,449.5],[2,1.33,10.03]],"ltp":1.11,"tv":41879.72,"id":9304761}]}]}
{"op":"mcm","clk":"4230701780","pt":1631535663468,"mc":[{"id":"1.187557247","rc":[{"batb":[[0,1.13,604.38],[1,1.12,650.55],[2,1.1,1024.49]],"batl":[[0,1.21,336.25],[1,1.22,510.68],[2,1.23,449.5]],"ltp":1.11,"tv":41879.72,"id":9304761}]}]}
{"op":"mcm","clk":"4230701884","pt":1631535664471,"mc":[{"id":"1.187557247","rc":[{"batb":[[0,1.1,1024.49],[1,1.08,2.41],[2,1.07,2.22]],"batl":[[1,1.22,970.43]],"ltp":1.11,"tv":41879.72,"id":9304761}]}]}
{"op":"mcm","clk":"4230702076","pt":1631535666722,"mc":[{"id":"1.187557247","rc":[{"trd":[[5.7,9.54]],"batb":[[2,5.3,731.78]],"batl":[[0,6.2,616.94],[1,6.4,598.8],[2,6.6,598.8]],"ltp":5.7,"tv":72647.19,"id":10350473},{"trd":[[1.21,1033.28]],"batb":[[0,1.2,755.56],[1,1.17,338.97],[2,1.1,1024.49]],"batl":[[0,1.21,317.03]],"ltp":1.21,"tv":41898.94,"id":9304761}],"tv":114546.14}]}
{"op":"mcm","clk":"4230702179","pt":1631535667723,"mc":[{"id":"1.187557247","rc":[{"batb":[[0,5.3,205.54],[1,5.2,192.63],[2,5.1,192.63]],"batl":[[0,6.2,308.46],[1,6.4,299.4],[2,6.6,299.4]],"ltp":5.7,"tv":72647.19,"id":10350473},{"batb":[[0,1.2,18.36],[1,1.19,436.28],[2,1.18,677.92]],"batl":[[1,1.22,961.43],[2,1.23,439.5]],"ltp":1.21,"tv":41898.94,"id":9304761}]}]}
{"op":"mcm","clk":"4230702453","pt":1631535670509,"mc":[{"id":"1.187557247","rc":[{"batb":[[0,5.4,12.21],[1,5.3,205.54],[2,5.2,192.63]],"ltp":5.7,"tv":72647.19,"id":10350473},{"batl":[[1,1.22,510.68]],"ltp":1.21,"tv":41898.94,"id":9304761}]}]}
{"op":"mcm","clk":"4230702554","pt":1631535671602,"mc":[{"id":"1.187557247","rc":[{"trd":[[6,48.42]],"batl":[[0,6,20.85],[1,6.2,308.46],[2,6.4,299.4]],"ltp":6.0,"tv":72647.71,"id":10350473},{"trd":[[1.2,2885.03]],"batb":[[0,1.2,242.77]],"batl":[[0,1.21,387.53],[1,1.22,584.95],[2,1.23,728.59]],"ltp":1.2,"tv":41906.95,"id":9304761}],"tv":114554.67}]}
{"op":"mcm","clk":"4230702660","pt":1631535672701,"mc":[{"id":"1.187557247","rc":[{"batb":[[0,1.2,122.33],[1,1.19,495.39]],"batl":[[2,1.23,439.5]],"ltp":1.2,"tv":41906.95,"id":9304761}]}]}
{"op":"mcm","clk":"4230703086","pt":1631535676689,"mc":[{"id":"1.187557247","rc":[{"trd":[[1.2,2885.5]],"batb":[[0,1.2,191.41]],"batl":[[0,1.21,445.89]],"ltp":1.2,"tv":41907.43,"id":9304761}],"tv":114555.15}]}
{"op":"mcm","clk":"4230703110","pt":1631535676908,"mc":[{"id":"1.187557247","rc":[{"batb":[[0,1.2,122.09],[1,1.19,436.28]],"batl":[[0,1.21,387.53],[1,1.22,510.68]],"ltp":1.2,"tv":41907.43,"id":9304761}]}]}
{"op":"mcm","clk":"4230703286","pt":1631535678727,"mc":[{"id":"1.187557247","rc":[{"trd":[[1.2,2886.34]],"batb":[[0,1.2,109.28]],"ltp":1.2,"tv":41908.26,"id":9304761}],"tv":114555.98}]}
{"op":"mcm","clk":"4230703339","pt":1631535679210,"mc":[{"id":"1.187557247","rc":[{"trd":[[1.2,2886.77]],"batb":[[0,1.2,109.06]],"ltp":1.2,"tv":41908.69,"id":9304761}],"tv":114556.41}]}
{"op":"mcm","clk":"4230703580","pt":1631535681712,"mc":[{"id":"1.187557247","rc":[{"trd":[[1.21,1037.92]],"batl":[[0,1.21,385.21]],"ltp":1.21,"tv":41913.34,"id":9304761}],"tv":114561.06}]}
{"op":"mcm","clk":"4230703842","pt":1631535684624,"mc":[{"id":"1.187557247","rc":[{"batb":[[0,4.6,2],[1,1.28,720.76],[2,1.2,2]],"batl":[[0,12.5,2.95],[1,990,0.01],[2,6.4,0]],"ltp":6.0,"tv":72647.71,"id":10350473},{"batb":[[0,1.14,9.65],[1,1.09,1124.01],[2,1.08,2.21]],"batl":[[0,1.33,11.64],[1,1.34,7],[2,1.43,1.7]],"ltp":1.21,"tv":41913.34,"id":9304761}]}]}
{"op":"mcm","clk":"4230704019","pt":1631535686426,"mc":[{"id":"1.187557247","rc":[{"batl":[[0,1.2,13],[1,1.33,11.64],[2,1.34,7]],"ltp":1.21,"tv":41913.34,"id":9304761}]}]}
{"op":"mcm","clk":"4230704104","pt":1631535687313,"mc":[{"id":"1.187557247","rc":[{"batb":[[0,1.14,336.46],[1,1.13,919.46],[2,1.09,1124.01]],"batl":[[1,1.28,203.25],[2,1.29,368.27]],"ltp":1.21,"tv":41913.34,"id":9304761}]}]}
{"op":"mcm","clk":"4230704229","pt":1631535688628,"mc":[{"id":"1.187557247","rc":[{"batb":[[1,4.5,3],[2,1.28,720.76]],"batl":[[0,8.8,4.77],[1,12.5,2.95],[2,990,0.01]],"ltp":6.0,"tv":72647.71,"id":10350473},{"batb":[[1,1.13,1759.19],[2,1.11,882.59]],"batl":[[1,1.28,9],[2,1.33,11.64]],"ltp":1.21,"tv":41913.34,"id":9304761}]}]}
{"op":"mcm","clk":"4230704303","pt":1631535689410,"mc":[{"id":"1.187557247","rc":[{"batb":[[0,1.14,326.81]],"ltp":1.21,"tv":41913.34,"id":9304761}]}]}
{"op":"mcm","clk":"4230704496","pt":1631535691707,"mc":[{"id":"1.187557247","rc":[{"batb":[[0,7,267.19],[1,6.8,259.33],[2,6.6,259.33]],"batl":[[1,9,116.87],[2,9.2,113.44]],"ltp":6.0,"tv":72647.71,"id":10350473},{"batl":[[0,1.16,855.84],[1,1.17,357.66],[2,1.2,13]],"ltp":1.21,"tv":41913.34,"id":9304761}]}]}
{"op":"mcm","clk":"4230704593","pt":1631535692641,"mc":[{"id":"1.187557247","rc":[{"trd":[[7.2,3.33]],"ltp":7.2,"tv":72651.04,"id":10350473},{"trd":[[1.16,134.74]],"batb":[[1,1.13,1759.44],[2,1.11,882.8]],"batl":[[0,1.16,835.17]],"ltp":1.16,"tv":41934.01,"id":9304761}],"tv":114585.06}]}
{"op":"mcm","clk":"4230704671","pt":1631535693541,"mc":[{"id":"1.187557247","rc":[{"batl":[[0,8.6,18.44],[1,8.8,4.77],[2,9,116.87]],"ltp":7.2,"tv":72651.04,"id":10350473},{"batb":[[0,1.14,418.5]],"batl":[[2,1.19,65]],"ltp":1.16,"tv":41934.01,"id":9304761}]}]}
{"op":"mcm","clk":"4230704788","pt":1631535694638,"mc":[{"id":"1.187557247","rc":[{"batl":[[2,1.19,78]],"ltp":1.16,"tv":41934.01,"id":9304761}]}]}
{"op":"mcm","clk":"4230704965","pt":1631535696511,"mc":[{"id":"1.187557247","rc":[{"batb":[[0,1.14,494.69]],"batl":[[0,1.15,9.14],[1,1.16,910.19],[2,1.17,357.66]],"ltp":1.16,"tv":41934.01,"id":9304761}]}]}
{"op":"mcm","clk":"4230705031","pt":1631535697449,"mc":[{"id":"1.187557247","rc":[{"batb":[[0,7,277.19]],"ltp":7.2,"tv":72651.04,"id":10350473}]}]}
{"op":"mcm","clk":"4230705242","pt":1631535699747,"mc":[{"id":"1.187557247","rc":[{"batb":[[2,1.12,21.18]],"ltp":1.16,"tv":41934.01,"id":9304761}]}]}
{"op":"mcm","clk":"4230705255","pt":1631535699865,"mc":[{"id":"1.187557247","rc":[{"batb":[[1,1.13,1734.57]],"ltp":1.16,"tv":41934.01,"id":9304761}]}]}
{"op":"mcm","clk":"4230705396","pt":1631535701624,"mc":[{"id":"1.187557247","rc":[{"trd":[[8.2,3.38]],"ltp":8.2,"tv":72651.42,"id":10350473},{"trd":[[1.14,8.48]],"batb":[[0,1.14,489.32]],"ltp":1.14,"tv":41942.02,"id":9304761}],"tv":114593.45}]}
{"op":"mcm","clk":"4230705482","pt":1631535702632,"mc":[{"id":"1.187557247","rc":[{"trd":[[1.15,4.65]],"batl":[[0,1.15,6.81]],"ltp":1.15,"tv":41946.67,"id":9304761}],"tv":114598.1}]}
{"op":"mcm","clk":"4230705576","pt":1631535703733,"mc":[{"id":"1.187557247","rc":[{"trd":[[1.15,18.27]],"batb":[[0,1.14,569.64]],"batl":[[0,1.16,981.33],[1,1.17,381.44],[2,1.18,585.75]],"ltp":1.15,"tv":41960.3,"id":9304761}],"tv":114611.72}]}
{"op":"mcm","clk":"4230705630","pt":1631535704473,"mc":[{"id":"1.187557247","rc":[{"batb":[[0,1.14,513.93]],"batl":[[0,1.16,910.19]],"ltp":1.15,"tv":41960.3,"id":9304761}]}]}
{"op":"mcm","clk":"4230705734","pt":1631535705616,"mc":[{"id":"1.187557247","rc":[{"batb":[[0,1.15,18.75],[1,1.14,513.93],[2,1.13,1734.57]],"ltp":1.15,"tv":41960.3,"id":9304761}]}]}
{"op":"mcm","clk":"4230705761","pt":1631535705950,"mc":[{"id":"1.187557247","rc":[{"trd":[[1.16,139.38]],"batl":[[0,1.16,907.87]],"ltp":1.16,"tv":41964.94,"id":9304761}],"tv":114616.37}]}
{"op":"mcm","clk":"4230705862","pt":1631535707223,"mc":[{"id":"1.187557247","rc":[{"batb":[[1,1.14,1949.03]],"ltp":1.16,"tv":41964.94,"id":9304761}]}]}
{"op":"mcm","clk":"4230706033","pt":1631535709519,"mc":[{"id":"1.187557247","rc":[{"batb":[[0,1.15,22.65]],"ltp":1.16,"tv":41964.94,"id":9304761}]}]}
{"op":"mcm","clk":"4230706092","pt":1631535710457,"mc":[{"id":"1.187557247","rc":[{"trd":[[1.15,45.41]],"batb":[[0,1.15,9.08]],"ltp":1.15,"tv":41992.08,"id":9304761}],"tv":114643.51}]}
{"op":"mcm","clk":"4230706268","pt":1631535712643,"mc":[{"id":"1.187557247","rc":[{"trd":[[7.2,3.83]],"ltp":7.2,"tv":72651.92,"id":10350473},{"trd":[[1.16,142.51]],"batb":[[1,1.14,513.93]],"batl":[[0,1.16,904.74]],"ltp":1.16,"tv":41995.21,"id":9304761}],"tv":114647.14}]}
{"op":"mcm","clk":"4230706360","pt":1631535713741,"mc":[{"id":"1.187557247","rc":[{"trd":[[1.16,147.62]],"batb":[[0,1.15,3.9]],"batl":[[0,1.16,902.19]],"ltp":1.16,"tv":42000.32,"id":9304761}],"tv":114652.25}]}
{"op":"mcm","clk":"4230706435","pt":1631535714834,"mc":[{"id":"1.187557247","rc":[{"batb":[[0,1.15,8.9]],"ltp":1.16,"tv":42000.32,"id":9304761}]}]}
{"op":"mcm","clk":"4230706518","pt":1631535716032,"mc":[{"id":"1.187557247","rc":[{"batb":[[0,1.15,18.67]],"ltp":1.16,"tv":42000.32,"id":9304761}]}]}
{"op":"mcm","clk":"4230706746","pt":1631535718633,"mc":[{"id":"1.187557247","rc":[{"batb":[[0,6.4,5.51],[1,6.2,9.22],[2,6,7.11]],"batl":[[0,11,4.02],[1,12.5,2.95],[2,15.5,2.61]],"ltp":7.2,"tv":72651.92,"id":10350473},{"batb":[[1,1.14,76.42],[2,1.12,21.44]],"batl":[[0,1.16,75.02],[1,1.18,585.75],[2,1.19,557.5]],"ltp":1.16,"tv":42000.32,"id":9304761}]}]}
{"op":"mcm","clk":"4230706812","pt":1631535719357,"mc":[{"id":"1.187557247","rc":[{"batb":[[0,6.2,3],[1,6,7.11],[2,1.28,720.76]],"batl":[[0,15.5,2.61],[1,990,0.01],[2,15.5,0]],"ltp":7.2,"tv":72651.92,"id":10350473},{"batb":[[1,1.12,21.67],[2,1.11,11.74]],"batl":[[0,1.19,13],[1,1.2,532.68],[2,1.38,10.32]],"ltp":1.16,"tv":42000.32,"id":9304761}]}]}
{"op":"mcm","clk":"4230706992","pt":1631535721445,"mc":[{"id":"1.187557247","rc":[{"batb":[[2,1.11,365.54]],"batl":[[0,1.19,498.12],[1,1.2,1097.66]],"ltp":1.16,"tv":42000.32,"id":9304761}]}]}
{"op":"mcm","clk":"4230707078","pt":1631535722542,"mc":[{"id":"1.187557247","rc":[{"batb":[[1,6,10.11]],"batl":[[0,11,4.02],[1,15.5,2.61],[2,990,0.01]],"ltp":7.2,"tv":72651.92,"id":10350473}]}]}
{"op":"mcm","clk":"4230707221","pt":1631535724278,"mc":[{"id":"1.187557247","rc":[{"trd":[[1.15,62.45]],"batb":[[0,1.15,10.15]],"ltp":1.15,"tv":42017.35,"id":9304761}],"tv":114669.28}]}
{"op":"mcm","clk":"4230707327","pt":1631535725655,"mc":[{"id":"1.187557247","rc":[{"batb":[[0,6.4,6.31],[1,6.2,3],[2,6,10.11]],"ltp":7.2,"tv":72651.92,"id":10350473},{"batl":[[0,1.18,545.25],[1,1.19,958.62],[2,1.2,1097.66]],"ltp":1.15,"tv":42017.35,"id":9304761}]}]}
{"op":"mcm","clk":"4230707386","pt":1631535726382,"mc":[{"id":"1.187557247","rc":[{"batb":[[0,6.2,3],[1,6,10.11],[2,1.28,720.76]],"ltp":7.2,"tv":72651.92,"id":10350473},{"batb":[[0,1.12,22.06],[1,1.11,354.03],[2,1.1,2042.09]],"batl":[[0,1.19,958.62],[1,1.2,1097.66],[2,1.38,10.32]],"ltp":1.15,"tv":42017.35,"id":9304761}]}]}
{"op":"mcm","clk":"4230707464","pt":1631535727177,"mc":[{"id":"1.187557247","rc":[{"batl":[[0,1.19,13],[1,1.2,532.68]],"ltp":1.15,"tv":42017.35,"id":9304761}]}]}
{"op":"mcm","clk":"4230707626","pt":1631535728745,"mc":[{"id":"1.187557247","rc":[{"batb":[[0,8.2,450.85],[1,8,437.59],[2,7.8,437.59]],"batl":[[1,11.5,332.6],[2,12,322.82]],"ltp":7.2,"tv":72651.92,"id":10350473},{"trd":[[1.14,8.94],[1.15,63.23]],"batb":[[0,1.12,21.44]],"ltp":1.14,"tv":42018.59,"id":9304761}],"tv":114670.52}]}
{"op":"mcm","clk":"4230707662","pt":1631535729163,"mc":[{"id":"1.187557247","rc":[{"batb":[[0,8.2,225.43],[1,8,218.79],[2,7.8,218.79]],"batl":[[1,11.5,91.46],[2,12,88.78]],"ltp":7.2,"tv":72651.92,"id":10350473}]}]}
{"op":"mcm","clk":"4230707805","pt":1631535730582,"mc":[{"id":"1.187557247","rc":[{"trd":[[9.2,2.78]],"ltp":9.2,"tv":72654.7,"id":10350473},{"trd":[[1.12,139.8],[1.13,52.88]],"batb":[[0,1.11,354.03],[1,1.1,2014.96],[2,1.09,1087.21]],"batl":[[0,1.12,269.99],[1,1.13,934.02],[2,1.18,518.14]],"ltp":1.12,"tv":42084.31,"id":9304761}],"tv":114739.02}]}
{"op":"mcm","clk":"4230707900","pt":1631535731580,"mc":[{"id":"1.187557247","rc":[{"batl":[[0,10.5,14.17],[1,11,4.02],[2,11.5,91.46]],"ltp":9.2,"tv":72654.7,"id":10350473},{"batl":[[2,1.16,65]],"ltp":1.12,"tv":42084.31,"id":9304761}]}]}
{"op":"mcm","clk":"4230708057","pt":1631535733354,"mc":[{"id":"1.187557247","rc":[{"batb":[[0,1.11,480.57]],"ltp":1.12,"tv":42084.31,"id":9304761}]}]}
{"op":"mcm","clk":"4230708209","pt":1631535734977,"mc":[{"id":"1.187557247","rc":[{"batb":[[0,8.4,15],[1,8.2,225.43],[2,8,218.79]],"ltp":9.2,"tv":72654.7,"id":10350473}]}]}
{"op":"mcm","clk":"4230708331","pt":1631535736396,"mc":[{"id":"1.187557247","rc":[{"trd":[[1.11,3654.93]],"batb":[[0,1.11,428.57]],"batl":[[2,1.15,652.1]],"ltp":1.11,"tv":42188.31,"id":9304761}],"tv":114843.02}]}
{"op":"mcm","clk":"4230708648","pt":1631535739692,"mc":[{"id":"1.187557247","rc":[{"trd":[[1.12,159.32]],"batb":[[1,1.1,2042.71]],"batl":[[0,1.12,305.15]],"ltp":1.12,"tv":42207.83,"id":9304761}],"tv":114862.54}]}
{"op":"mcm","clk":"4230708735","pt":1631535740578,"mc":[{"id":"1.187557247","rc":[{"batb":[[0,1.11,451.73]],"ltp":1.12,"tv":42207.83,"id":9304761}]}]}
{"op":"mcm","clk":"4230708826","pt":1631535741677,"mc":[{"id":"1.187557247","rc":[{"batb":[[0,7.6,4.34],[1,6.8,5.53],[2,6.4,2]],"batl":[[0,11,4.02],[1,15.5,2.61],[2,26,2]],"ltp":9.2,"tv":72654.7,"id":10350473},{"batb":[[0,1.1,1116.16],[1,1.09,1087.21],[2,1.08,2.21]],"batl":[[0,1.15,652.1],[1,1.16,613.72],[2,1.17,665.5]],"ltp":1.12,"tv":42207.83,"id":9304761}]}]}
{"op":"mcm","clk":"4230708886","pt":1631535742301,"mc":[{"id":"1.187557247","rc":[{"batb":[[0,6.8,5.53],[1,6.4,2],[2,1.28,720.76]],"batl":[[0,26,2],[1,990,0.01],[2,26,0]],"ltp":9.2,"tv":72654.7,"id":10350473},{"batb":[[0,1.08,2.65],[1,1.07,120.9],[2,1.06,4.3]],"batl":[[0,1.17,665.5],[1,1.18,11],[2,1.19,13]],"ltp":1.12,"tv":42207.83,"id":9304761}]}]}
{"op":"mcm","clk":"4230709106","pt":1631535744598,"mc":[{"id":"1.187557247","rc":[{"batb":[[0,1.08,734.47],[1,1.07,701.16]],"batl":[[0,1.16,884.78],[1,1.17,994.47],[2,1.18,11]],"ltp":1.12,"tv":42207.83,"id":9304761}]}]}
{"op":"mcm","clk":"4230709199","pt":1631535745490,"mc":[{"id":"1.187557247","rc":[{"batb":[[0,7.6,2],[1,7.4,2],[2,6.8,8.53]],"batl":[[0,15.5,2.55],[1,26,2],[2,990,0.01]],"ltp":9.2,"tv":72654.7,"id":10350473},{"batb":[[0,1.12,8.87],[1,1.08,734.47],[2,1.07,2113.9]],"batl":[[0,1.15,17],[1,1.16,1525.25],[2,1.17,1010.47]],"ltp":1.12,"tv":42207.83,"id":9304761}]}]}
{"op":"mcm","clk":"4230709292","pt":1631535746478,"mc":[{"id":"1.187557247","rc":[{"batl":[[0,1.15,17.25]],"ltp":1.12,"tv":42207.83,"id":9304761}]}]}
{"op":"mcm","clk":"4230709446","pt":1631535747690,"mc":[{"id":"1.187557247","rc":[{"batl":[[0,26,2],[1,990,0.01],[2,990,0]],"ltp":9.2,"tv":72654.7,"id":10350473},{"batb":[[1,1.08,2.65],[2,1.07,120.9]],"batl":[[0,1.15,17.69],[1,1.17,681.5],[2,1.18,11]],"ltp":1.12,"tv":42207.83,"id":9304761}]}]}
{"op":"mcm","clk":"4230709523","pt":1631535748315,"mc":[{"id":"1.187557247","rc":[{"batb":[[2,7.2,3]],"ltp":9.2,"tv":72654.7,"id":10350473},{"batb":[[0,1.12,5]],"batl":[[1,1.16,16],[2,1.17,681.5]],"ltp":1.12,"tv":42207.83,"id":9304761}]}]}
{"op":"mcm","clk":"4230709682","pt":1631535749740,"mc":[{"id":"1.187557247","rc":[{"trd":[[9.2,19.78]],"batb":[[0,9,21.51],[1,7.6,2],[2,7.4,2]],"batl":[[0,9.8,21.17],[1,26,2],[2,990,0.01]],"ltp":9.2,"tv":72671.7,"id":10350473},{"trd":[[1.12,308.96]],"batb":[[0,1.1,929.88],[1,1.09,356.76],[2,1.08,2.21]],"batl":[[0,1.12,798.28],[1,1.13,334.02],[2,1.15,17.48]],"ltp":1.12,"tv":42357.47,"id":9304761}],"tv":115029.18}]}
{"op":"mcm","clk":"4230709741","pt":1631535750318,"mc":[{"id":"1.187557247","rc":[{"batb":[[0,7.6,2],[1,7.4,2],[2,7.2,3]],"batl":[[0,15.5,2.75]],"ltp":9.2,"tv":72671.7,"id":10350473},{"batb":[[1,1.09,274.4]],"batl":[[1,1.13,314.52]],"ltp":1.12,"tv":42357.47,"id":9304761}]}]}
{"op":"mcm","clk":"4230709835","pt":1631535751319,"mc":[{"id":"1.187557247","rc":[{"batb":[[0,7.8,10],[1,7.6,2],[2,7.4,2]],"batl":[[0,12,10],[1,15.5,2.75],[2,26,2]],"ltp":9.2,"tv":72671.7,"id":10350473},{"batl":[[2,1.14,88.7]],"ltp":1.12,"tv":42357.47,"id":9304761}]}]}
{"op":"mcm","clk":"4230709966","pt":1631535752407,"mc":[{"id":"1.187557247","rc":[{"batb":[[1,7.6,7.64]],"ltp":9.2,"tv":72671.7,"id":10350473}]}]}
{"op":"mcm","clk":"4230710081","pt":1631535753505,"mc":[{"id":"1.187557247","rc":[{"batb":[[0,7.6,2],[1,7.4,2],[2,7.2,3]],"batl":[[0,26,2],[1,990,0.01],[2,26,0]],"ltp":9.2,"tv":72671.7,"id":10350473},{"batb":[[0,1.08,2.65],[1,1.07,120.9],[2,1.06,4.3]],"batl":[[0,1.15,17.69],[1,1.16,16],[2,1.17,681.5]],"ltp":1.12,"tv":42357.47,"id":9304761}]}]}
{"op":"mcm","clk":"4230710393","pt":1631535756692,"mc":[{"id":"1.187557247","rc":[{"batb":[[0,7.6,7.24]],"batl":[[0,15.5,2.87],[1,26,2],[2,990,0.01]],"ltp":9.2,"tv":72671.7,"id":10350473},{"batb":[[0,1.08,817.8],[1,1.07,1966.37],[2,1.06,1534.76]],"batl":[[0,1.15,714.19],[1,1.16,1364.31],[2,1.17,1087]],"ltp":1.12,"tv":42357.47,"id":9304761}]}]}
{"op":"mcm","clk":"4230710420","pt":1631535756901,"mc":[{"id":"1.187557247","rc":[{"batb":[[0,7.6,2],[1,7.2,3],[2,7,2]],"ltp":9.2,"tv":72671.7,"id":10350473},{"batl":[[0,1.16,1365],[1,1.17,1087],[2,1.39,17.83]],"ltp":1.12,"tv":42357.47,"id":9304761}]}]}
{"op":"mcm","clk":"4230710572","pt":1631535758620,"mc":[{"id":"1.187557247","rc":[{"batl":[[0,1.16,1365.24]],"ltp":1.12,"tv":42357.47,"id":9304761}]}]}
{"op":"mcm","clk":"4230710656","pt":1631535759510,"mc":[{"id":"1.187557247","rc":[{"batb":[[1,6.8,5.53],[2,1.28,720.76]],"ltp":9.2,"tv":72671.7,"id":10350473},{"batl":[[0,1.16,16.93],[1,1.17,665.5]],"ltp":1.12,"tv":42357.47,"id":9304761}]}]}
{"op":"mcm","clk":"4230710731","pt":1631535760350,"mc":[{"id":"1.187557247","rc":[{"batb":[[1,7.4,3],[2,6.8,5.53]],"ltp":9.2,"tv":72671.7,"id":10350473},{"batb":[[1,1.07,1847.69]],"batl":[[0,1.11,28.39],[1,1.15,17.93],[2,1.16,16]],"ltp":1.12,"tv":42357.47,"id":9304761}]}]}
{"op":"mcm","clk":"4230710866","pt":1631535761665,"mc":[{"id":"1.187557247","rc":[{"batb":[[0,11.5,315.53],[1,11,306.25],[2,10.5,306.25]],"batl":[[1,16,239.06],[2,16.5,232.02]],"ltp":9.2,"tv":72671.7,"id":10350473},{"trd":[[1.09,0.4],[1.1,0.5]],"batb":[[0,1.08,817.36]],"ltp":1.09,"tv":42358.36,"id":9304761}],"tv":115030.07}]}
{"op":"mcm","clk":"4230711000","pt":1631535762669,"mc":[{"id":"1.187557247","rc":[{"trd":[[10,2.13]],"batb":[[0,7.6,2],[1,7.4,3],[2,6.8,5.53]],"batl":[[1,26,2],[2,990,0.01]],"ltp":10.0,"tv":72673.83,"id":10350473},{"trd":[[1.11,3674.18]],"batb":[[0,1.08,2.21],[1,1.07,1351.54]],"batl":[[0,1.11,9.14]],"ltp":1.11,"tv":42377.61,"id":9304761}],"tv":115051.45}]}
{"op":"mcm","clk":"4230711099","pt":1631535763595,"mc":[{"id":"1.187557247","rc":[{"batb":[[0,7.8,3],[1,7.6,2],[2,7.4,3]],"batl":[[0,990,0.01],[1,26,0],[2,990,0]],"ltp":10.0,"tv":72673.83,"id":10350473},{"batb":[[1,1.07,2.22],[2,1.06,4.3]],"ltp":1.11,"tv":42377.61,"id":9304761}]}]}
{"op":"mcm","clk":"4230711301","pt":1631535765367,"mc":[{"id":"1.187557247","rc":[{"batb":[[2,1.06,665.71]],"batl":[[1,1.12,801.5],[2,1.13,454.91]],"ltp":1.11,"tv":42377.61,"id":9304761}]}]}
{"op":"mcm","clk":"4230711357","pt":1631535765893,"mc":[{"id":"1.187557247","rc":[{"batl":[[0,1.12,801.5],[1,1.13,454.91],[2,1.15,17.48]],"ltp":1.11,"tv":42377.61,"id":9304761}]}]}
{"op":"mcm","clk":"4230711812","pt":1631535770682,"mc":[{"id":"1.187557247","rc":[{"batb":[[0,1.1,3.87],[1,1.08,2.21],[2,1.07,2.22]],"ltp":1.11,"tv":42377.61,"id":9304761}]}]}
{"op":"mcm","clk":"4230712042","pt":1631535772704,"mc":[{"id":"1.187557247","rc":[{"batb":[[1,1.28,720.76],[2,1.2,2]],"ltp":10.0,"tv":72673.83,"id":10350473}]}]}
{"op":"mcm","clk":"4230712114","pt":1631535773389,"mc":[{"id":"1.187557247","rc":[{"trd":[[1.08,4.43],[1.1,8.23]],"batb":[[0,1.07,2.22],[1,1.06,665.71],[2,1.05,1000.88]],"batl":[[0,1.08,12.9],[1,1.12,801.5],[2,1.13,454.91]],"ltp":1.08,"tv":42389.77,"id":9304761}],"tv":115063.61}]}
{"op":"mcm","clk":"4230712434","pt":1631535776494,"mc":[{"id":"1.187557247","rc":[{"trd":[[1.08,30.23]],"batl":[[0,1.12,801.5],[1,1.13,454.91],[2,1.15,17.48]],"ltp":1.08,"tv":42415.58,"id":9304761}],"tv":115089.42}]}
{"op":"mcm","clk":"4230712857","pt":1631535779700,"mc":[{"id":"1.187557247","rc":[{"trd":[[9.2,19.81],[10,2.16],[11,0.02]],"batl":[[0,9.2,4.96],[1,990,0.01]],"ltp":9.2,"tv":72673.91,"id":10350473},{"trd":[[1.1,8.41],[1.11,3674.41],[1.12,309.19]],"batb":[[1,1.06,4.3],[2,1.05,324.55]],"batl":[[0,1.15,17.69],[1,1.23,29.71],[2,1.25,14.85]],"ltp":1.12,"tv":42416.22,"id":9304761}],"tv":115090.13}]}
{"op":"mcm","clk":"4230712907","pt":1631535780165,"mc":[{"id":"1.187557247","rc":[{"batb":[[0,1.11,3.9],[1,1.07,2.22],[2,1.06,4.3]],"ltp":1.12,"tv":42416.22,"id":9304761}]}]}
{"op":"mcm","clk":"4230713144","pt":1631535782475,"mc":[{"id":"1.187557247","rc":[{"trd":[[9.2,24.77]],"batb":[[1,7.6,2],[2,1.28,720.76]],"batl":[[0,990,0.01],[1,990,0]],"ltp":9.2,"tv":72678.87,"id":10350473},{"trd":[[1.11,3682.23],[1.12,349.97]],"batb":[[0,1.07,1321.14],[1,1.06,4.3],[2,1.05,324.55]],"batl":[[0,1.09,947.49],[1,1.1,344.06],[2,1.15,17.69]],"ltp":1.11,"tv":42464.81,"id":9304761}],"tv":115143.69}]}
{"op":"mcm","clk":"4230713285","pt":1631535783683,"mc":[{"id":"1.187557247","rc":[{"batl":[[0,1.09,949.7]],"ltp":1.11,"tv":42464.81,"id":9304761}]}]}
{"op":"mcm","clk":"4230713351","pt":1631535784311,"mc":[{"id":"1.187557247","rc":[{"trd":[[1.07,37.6]],"batb":[[0,1.07,1302.34]],"batl":[[2,1.12,88.45]],"ltp":1.07,"tv":42502.42,"id":9304761}],"tv":115181.29}]}
{"op":"mcm","clk":"4230713437","pt":1631535785113,"mc":[{"id":"1.187557247","rc":[{"batb":[[0,1.08,11.1],[1,1.07,1302.34],[2,1.06,4.3]],"ltp":1.07,"tv":42502.42,"id":9304761}]}]}
{"op":"mcm","clk":"4230713641","pt":1631535786624,"mc":[{"id":"1.187557247","rc":[{"batb":[[0,1.06,4.3],[1,1.05,324.55],[2,1.04,2.98]],"batl":[[0,1.09,2.21],[1,1.15,17.69],[2,1.23,29.71]],"ltp":1.07,"tv":42502.42,"id":9304761}]}]}
{"op":"mcm","clk":"4230713973","pt":1631535789717,"mc":[{"id":"1.187557247","rc":[{"batb":[[0,1.08,2.56],[1,1.06,658.99],[2,1.05,1007.67]],"batl":[[1,1.12,807.72],[2,1.13,448.52]],"ltp":1.07,"tv":42502.42,"id":9304761}]}]}
{"op":"mcm","clk":"4230714243","pt":1631535792179,"mc":[{"id":"1.187557247","rc":[{"batb":[[2,1.05,1010.18]],"ltp":1.07,"tv":42502.42,"id":9304761}]}]}
{"op":"mcm","clk":"4230714495","pt":1631535794552,"mc":[{"id":"1.187557247","rc":[{"batb":[[1,1.28,720.76],[2,1.2,2]],"ltp":9.2,"tv":72678.87,"id":10350473},{"trd":[[1.08,34.68]],"batb":[[0,1.06,659.32],[1,1.05,1010.18],[2,1.04,2.98]],"ltp":1.08,"tv":42506.86,"id":9304761}],"tv":115185.73}]}
{"op":"mcm","clk":"4230714685","pt":1631535796506,"mc":[{"id":"1.187557247","rc":[{"batb":[[0,1.06,661.5],[1,1.05,1012.37]],"ltp":1.08,"tv":42506.86,"id":9304761}]}]}
{"op":"mcm","clk":"4230714749","pt":1631535797232,"mc":[{"id":"1.187557247","rc":[{"batb":[[1,1.05,1014.55]],"ltp":1.08,"tv":42506.86,"id":9304761}]}]}
{"op":"mcm","clk":"4230715070","pt":1631535800633,"mc":[{"id":"1.187557247","rc":[{"batb":[[1,1.05,1014.8]],"ltp":1.08,"tv":42506.86,"id":9304761}]}]}
{"op":"mcm","clk":"4230715117","pt":1631535801101,"mc":[{"id":"1.187557247","rc":[{"batb":[[1,1.05,1014.55]],"batl":[[1,1.15,17.69],[2,1.23,29.71]],"ltp":1.08,"tv":42506.86,"id":9304761}]}]}
{"op":"mcm","clk":"4230715275","pt":1631535802719,"mc":[{"id":"1.187557247","rc":[{"trd":[[9.2,44.57],[12,0.2]],"ltp":9.2,"tv":72698.87,"id":10350473},{"trd":[[1.08,35.34],[1.09,2.61],[1.12,512.61]],"batb":[[0,1.06,661.17]],"batl":[[0,1.15,17.69],[1,1.23,29.71],[2,1.25,14.85]],"ltp":1.08,"tv":42672.37,"id":9304761}],"tv":115371.25}]}
{"op":"mcm","clk":"4230715378","pt":1631535803612,"mc":[{"id":"1.187557247","rc":[{"trd":[[11,0.05],[12.5,0.02]],"batb":[[0,14,257.14],[1,13.5,249.52],[2,13,249.57]],"batl":[[0,22,173.86],[1,23,168.74],[2,24,168.74]],"ltp":12.5,"tv":72698.92,"id":10350473},{"trd":[[1.09,2.8],[1.1,8.66]],"batb":[[0,1.06,658.99],[1,1.05,692.23]],"ltp":1.09,"tv":42672.82,"id":9304761}],"tv":115371.75}]}
{"op":"mcm","clk":"4230715485","pt":1631535804606,"mc":[{"id":"1.187557247","rc":[{"batb":[[0,14,128.56],[1,13.5,124.78],[2,13,124.78]],"batl":[[0,22,47.81],[1,23,46.4],[2,24,46.4]],"ltp":12.5,"tv":72698.92,"id":10350473},{"trd":[[1.07,75.14]],"batb":[[1,1.05,690.05]],"batl":[[0,1.07,888.36],[1,1.08,407.98],[2,1.15,17.69]],"ltp":1.07,"tv":42710.36,"id":9304761}],"tv":115409.28}]}
{"op":"mcm","clk":"4230715569","pt":1631535805443,"mc":[{"id":"1.187557247","rc":[{"batb":[[1,1.05,687.87]],"ltp":1.07,"tv":42710.36,"id":9304761}]}]}
{"op":"mcm","clk":"4230715663","pt":1631535806338,"mc":[{"id":"1.187557247","rc":[{"batb":[[0,1.06,802.56]],"batl":[[2,1.09,88.45]],"ltp":1.07,"tv":42710.36,"id":9304761}]}]}
{"op":"mcm","clk":"4230715788","pt":1631535807536,"mc":[{"id":"1.187557247","rc":[{"batl":[[0,19,11.26],[1,22,47.81],[2,23,46.4]],"ltp":12.5,"tv":72698.92,"id":10350473}]}]}
{"op":"mcm","clk":"4230715915","pt":1631535808631,"mc":[{"id":"1.187557247","rc":[{"trd":[[1.07,80.16]],"batl":[[0,1.07,885.85],[2,1.09,727.84]],"ltp":1.07,"tv":42715.38,"id":9304761}],"tv":115414.3}]}
{"op":"mcm","clk":"4230716017","pt":1631535809630,"mc":[{"id":"1.187557247","rc":[{"batb":[[0,14,134.18]],"ltp":12.5,"tv":72698.92,"id":10350473},{"batl":[[2,1.09,88.45]],"ltp":1.07,"tv":42715.38,"id":9304761}]}]}
{"op":"mcm","clk":"4230716102","pt":1631535810433,"mc":[{"id":"1.187557247","rc":[{"batb":[[2,1.04,2465.86]],"batl":[[2,1.09,1224.76]],"ltp":1.07,"tv":42715.38,"id":9304761}]}]}
{"op":"mcm","clk":"4230716143","pt":1631535810857,"mc":[{"id":"1.187557247","rc":[{"batl":[[2,1.09,88.45]],"ltp":1.07,"tv":42715.38,"id":9304761}]}]}
{"op":"mcm","clk":"4230716327","pt":1631535812731,"mc":[{"id":"1.187557247","rc":[{"trd":[[1.06,117.63]],"batb":[[0,1.06,743.75]],"ltp":1.06,"tv":42833.01,"id":9304761}],"tv":115531.93}]}
{"op":"mcm","clk":"4230716510","pt":1631535814521,"mc":[{"id":"1.187557247","rc":[{"trd":[[1.06,156.68]],"batb":[[0,1.06,724.22]],"batl":[[1,1.08,381.85]],"ltp":1.06,"tv":42872.06,"id":9304761}],"tv":115570.99}]}
{"op":"mcm","clk":"4230716541","pt":1631535814842,"mc":[{"id":"1.187557247","rc":[{"batl":[[1,1.08,322.81]],"ltp":1.06,"tv":42872.06,"id":9304761}]}]}
{"op":"mcm","clk":"4230716691","pt":1631535816250,"mc":[{"id":"1.187557247","rc":[{"batb":[[2,13,126.78]],"ltp":12.5,"tv":72698.92,"id":10350473},{"batl":[[0,1.07,922.81]],"ltp":1.06,"tv":42872.06,"id":9304761}]}]}
{"op":"mcm","clk":"4230716828","pt":1631535817613,"mc":[{"id":"1.187557247","rc":[{"batb":[[1,1.05,715.28]],"batl":[[2,1.09,1190.28]],"ltp":1.06,"tv":42872.06,"id":9304761}]}]}
{"op":"mcm","clk":"4230716859","pt":1631535817926,"mc":[{"id":"1.187557247","rc":[{"batb":[[1,1.05,775.9]],"batl":[[0,1.07,993.09],[2,1.09,88.45]],"ltp":1.06,"tv":42872.06,"id":9304761}]}]}
{"op":"mcm","clk":"4230716980","pt":1631535819258,"mc":[{"id":"1.187557247","rc":[{"batb":[[1,1.05,570.94]],"batl":[[0,1.07,792.18],[1,1.08,325.25]],"ltp":1.06,"tv":42872.06,"id":9304761}]}]}
{"op":"mcm","clk":"4230717104","pt":1631535820739,"mc":[{"id":"1.187557247","rc":[{"batb":[[0,13,2],[1,12.5,2],[2,1.28,720.76]],"batl":[[0,26,2.01],[1,55,2],[2,990,0.01]],"ltp":12.5,"tv":72698.92,"id":10350473},{"trd":[[1.06,202.46],[1.07,87.89]],"batb":[[0,1.05,4.75],[1,1.04,2465.86],[2,1.03,4232.04]],"batl":[[0,1.08,218.77],[1,1.1,1064.12],[2,1.11,883.5]],"ltp":1.07,"tv":42925.58,"id":9304761}],"tv":115624.5}]}
{"op":"mcm","clk":"4230717181","pt":1631535821761,"mc":[{"id":"1.187557247","rc":[{"batb":[[0,12,3.14],[1,1.28,720.76],[2,1.2,2]],"batl":[[0,55,2],[1,990,0.01],[2,990,0]],"ltp":12.5,"tv":72698.92,"id":10350473},{"batb":[[0,1.07,2.32],[1,1.05,4.75],[2,1.04,2.98]],"batl":[[1,1.09,1112.57],[2,1.1,1064.12]],"ltp":1.07,"tv":42925.58,"id":9304761}]}]}
{"op":"mcm","clk":"4230717262","pt":1631535822655,"mc":[{"id":"1.187557247","rc":[{"batl":[[0,1.08,2.44]],"ltp":1.07,"tv":42925.58,"id":9304761}]}]}
{"op":"mcm","clk":"4230717334","pt":1631535823646,"mc":[{"id":"1.187557247","rc":[{"batb":[[0,1.07,2.35],[2,1.04,1359.95]],"batl":[[0,1.09,2192.94],[1,1.14,15.46],[2,1.15,14.03]],"ltp":1.07,"tv":42925.58,"id":9304761}]}]}
{"op":"mcm","clk":"4230717424","pt":1631535824541,"mc":[{"id":"1.187557247","rc":[{"batb":[[2,1.04,2.98]],"batl":[[0,1.09,1112.57]],"ltp":1.07,"tv":42925.58,"id":9304761}]}]}
{"op":"mcm","clk":"4230717608","pt":1631535826544,"mc":[{"id":"1.187557247","rc":[{"batb":[[0,1.07,29.4]],"ltp":1.07,"tv":42925.58,"id":9304761}]}]}
{"op":"mcm","clk":"4230717708","pt":1631535827548,"mc":[{"id":"1.187557247","rc":[{"batb":[[0,12.5,15.7],[1,12,3.14],[2,1.28,720.76]],"batl":[[0,19,10],[1,55,2],[2,990,0.01]],"ltp":12.5,"tv":72698.92,"id":10350473},{"trd":[[1.07,146.64],[1.08,35.38]],"batb":[[0,1.06,262.36],[1,1.05,1083.94]],"batl":[[0,1.07,1200.68],[1,1.08,109.34],[2,1.09,1112.57]],"ltp":1.07,"tv":42984.37,"id":9304761}],"tv":115683.29}]}
{"op":"mcm","clk":"4230717827","pt":1631535828748,"mc":[{"id":"1.187557247","rc":[{"batl":[[0,26,2.01]],"ltp":12.5,"tv":72698.92,"id":10350473},{"batb":[[2,1.04,2388.36]],"ltp":1.07,"tv":42984.37,"id":9304761}]}]}
{"op":"mcm","clk":"4230717980","pt":1631535830260,"mc":[{"id":"1.187557247","rc":[{"batb":[[0,1.06,382.26]],"ltp":1.07,"tv":42984.37,"id":9304761}]}]}
{"op":"mcm","clk":"4230718070","pt":1631535831261,"mc":[{"id":"1.187557247","rc":[{"batb":[[0,12,3.14],[1,1.28,720.76],[2,1.2,2]],"ltp":12.5,"tv":72698.92,"id":10350473},{"batb":[[0,1.05,209.88],[1,1.04,2388.36],[2,1.03,4232.04]],"batl":[[0,1.09,1112.57],[1,1.14,16.16],[2,1.15,14.03]],"ltp":1.07,"tv":42984.37,"id":9304761}]}]}
{"op":"mcm","clk":"4230718188","pt":1631535832409,"mc":[{"id":"1.187557247","rc":[{"batl":[[0,1.06,100],[1,1.09,1112.57],[2,1.14,16.16]],"ltp":1.07,"tv":42984.37,"id":9304761}]}]}
{"op":"mcm","clk":"4230718446","pt":1631535834351,"mc":[{"id":"1.187557247","rc":[{"batb":[[1,1.04,3538.22]],"batl":[[1,1.09,2407.29],[2,1.1,1123.44]],"ltp":1.07,"tv":42984.37,"id":9304761}]}]}
{"op":"mcm","clk":"4230718565","pt":1631535835455,"mc":[{"id":"1.187557247","rc":[{"batl":[[1,1.09,1112.57]],"ltp":1.07,"tv":42984.37,"id":9304761}]}]}
{"op":"mcm","clk":"4230718675","pt":1631535836453,"mc":[{"id":"1.187557247","rc":[{"batl":[[0,1.06,560],[2,1.14,16.16]],"ltp":1.07,"tv":42984.37,"id":9304761}]}]}
{"op":"mcm","clk":"4230718923","pt":1631535838647,"mc":[{"id":"1.187557247","rc":[{"batb":[[0,17,138.24],[1,16.5,69.12],[2,16,69.12]],"ltp":12.5,"tv":72698.92,"id":10350473},{"batb":[[2,1.03,3496.46]],"batl":[[0,1.06,8701.64]],"ltp":1.07,"tv":42984.37,"id":9304761}]}]}
{"op":"mcm","clk":"4230719021","pt":1631535839543,"mc":[{"id":"1.187557247","rc":[{"batb":[[0,17,82.94],[1,16.5,41.47],[2,16,41.47]],"batl":[[0,23,8.61],[1,25,11.75],[2,26,7.89]],"ltp":12.5,"tv":72698.92,"id":10350473},{"trd":[[1.06,240.2]],"batb":[[0,1.05,324.07]],"batl":[[0,1.06,1977.34],[1,1.09,1114.96]],"ltp":1.06,"tv":43022.11,"id":9304761}],"tv":115721.03}]}
{"op":"mcm","clk":"4230719258","pt":1631535841576,"mc":[{"id":"1.187557247","rc":[{"trd":[[1.06,245.72]],"batl":[[0,1.06,1974.58]],"ltp":1.06,"tv":43027.62,"id":9304761}],"tv":115726.55}]}
{"op":"mcm","clk":"4230719395","pt":1631535842668,"mc":[{"id":"1.187557247","rc":[{"batb":[[0,17.5,15.7],[1,17,82.94],[2,16.5,41.47]],"ltp":12.5,"tv":72698.92,"id":10350473}]}]}
{"op":"mcm","clk":"4230719507","pt":1631535843669,"mc":[{"id":"1.187557247","rc":[{"batb":[[0,17.5,3.42]],"batl":[[0,25,11.75],[1,26,7.89],[2,27,5.88]],"ltp":12.5,"tv":72698.92,"id":10350473},{"batl":[[1,1.07,6.01],[2,1.09,1114.96]],"ltp":1.06,"tv":43027.62,"id":9304761}]}]}
{"op":"mcm","clk":"4230719587","pt":1631535844355,"mc":[{"id":"1.187557247","rc":[{"batl":[[0,1.06,1896.21]],"ltp":1.06,"tv":43027.62,"id":9304761}]}]}
{"op":"mcm","clk":"4230719640","pt":1631535844880,"mc":[{"id":"1.187557247","rc":[{"batl":[[0,1.06,1436.21]],"ltp":1.06,"tv":43027.62,"id":9304761}]}]}
{"op":"mcm","clk":"4230719809","pt":1631535846204,"mc":[{"id":"1.187557247","rc":[{"trd":[[1.05,18.19],[1.06,263.72]],"batb":[[0,1.05,314.97]],"batl":[[0,1.06,1427.21]],"ltp":1.06,"tv":43063.81,"id":9304761}],"tv":115762.73}]}
{"op":"mcm","clk":"4230720052","pt":1631535848468,"mc":[{"id":"1.187557247","rc":[{"trd":[[1.05,657.15]],"batb":[[0,1.04,3538.22],[1,1.03,3496.46],[2,1.02,6198.69]],"batl":[[0,1.05,140.52],[1,1.06,1427.21],[2,1.07,6.01]],"ltp":1.05,"tv":43702.77,"id":9304761}],"tv":116401.69}]}
{"op":"mcm","clk":"4230720257","pt":1631535850503,"mc":[{"id":"1.187557247","rc":[{"batl":[[1,1.06,1378.73]],"ltp":1.05,"tv":43702.77,"id":9304761}]}]}
{"op":"mcm","clk":"4230720344","pt":1631535851395,"mc":[{"id":"1.187557247","rc":[{"batb":[[0,1.04,3745.81]],"ltp":1.05,"tv":43702.77,"id":9304761}]}]}
{"op":"mcm","clk":"4230720467","pt":1631535852766,"mc":[{"id":"1.187557247","rc":[{"trd":[[1.04,17.04],[1.05,862.15]],"batb":[[0,1.04,3737.29]],"batl":[[0,1.05,38.02]],"ltp":1.05,"tv":43924.8,"id":9304761}],"tv":116623.73}]}
{"op":"mcm","clk":"4230720562","pt":1631535853656,"mc":[{"id":"1.187557247","rc":[{"batl":[[0,22,6.75],[1,25,11.75],[2,26,7.89]],"ltp":12.5,"tv":72698.92,"id":10350473},{"batl":[[0,1.05,75.36]],"ltp":1.05,"tv":43924.8,"id":9304761}]}]}
{"op":"mcm","clk":"4230720676","pt":1631535854549,"mc":[{"id":"1.187557247","rc":[{"batl":[[0,25,11.75],[1,26,7.89],[2,27,5.88]],"ltp":12.5,"tv":72698.92,"id":10350473},{"batb":[[0,1.04,3426.08]],"batl":[[0,1.05,37.34]],"ltp":1.05,"tv":43924.8,"id":9304761}]}]}
{"op":"mcm","clk":"4230720750","pt":1631535855377,"mc":[{"id":"1.187557247","rc":[{"batl":[[1,1.06,1380.96]],"ltp":1.05,"tv":43924.8,"id":9304761}]}]}
{"op":"mcm","clk":"4230720850","pt":1631535856677,"mc":[{"id":"1.187557247","rc":[{"trd":[[1.04,411.74]],"batb":[[0,1.04,3228.73]],"ltp":1.04,"tv":44319.5,"id":9304761}],"tv":117018.43}]}
{"op":"mcm","clk":"4230720949","pt":1631535857669,"mc":[{"id":"1.187557247","rc":[{"trd":[[21,1.61]],"ltp":21.0,"tv":72700.53,"id":10350473},{"trd":[[1.04,418.97],[1.05,904.49]],"batb":[[0,1.05,308.24],[1,1.04,3225.11],[2,1.03,3496.46]],"batl":[[0,1.06,1380.96],[1,1.07,6.01],[2,1.08,2.68]],"ltp":1.05,"tv":44369.08,"id":9304761}],"tv":117069.62}]}
{"op":"mcm","clk":"4230721086","pt":1631535858978,"mc":[{"id":"1.187557247","rc":[{"trd":[[1.05,1064.49]],"batb":[[0,1.05,228.24]],"ltp":1.05,"tv":44529.08,"id":9304761}],"tv":117229.62}]}
{"op":"mcm","clk":"4230721238","pt":1631535860654,"mc":[{"id":"1.187557247","rc":[{"batb":[[1,1.04,4523.27]],"ltp":1.05,"tv":44529.08,"id":9304761}]}]}
{"op":"mcm","clk":"4230721334","pt":1631535861670,"mc":[{"id":"1.187557247","rc":[{"batl":[[0,24,8.6],[1,25,11.75],[2,26,7.89]],"ltp":21.0,"tv":72700.53,"id":10350473}]}]}
{"op":"mcm","clk":"4230721447","pt":1631535862659,"mc":[{"id":"1.187557247","rc":[{"batb":[[0,1.05,269.55],[1,1.04,3264.18]],"ltp":1.05,"tv":44529.08,"id":9304761}]}]}
{"op":"mcm","clk":"4230721504","pt":1631535863243,"mc":[{"id":"1.187557247","rc":[{"batb":[[0,1.05,272.55]],"ltp":1.05,"tv":44529.08,"id":9304761}]}]}
{"op":"mcm","clk":"4230721820","pt":1631535866548,"mc":[{"id":"1.187557247","rc":[{"trd":[[1.05,1067.89]],"batb":[[0,1.05,270.85]],"ltp":1.05,"tv":44532.49,"id":9304761}],"tv":117233.02}]}
{"op":"mcm","clk":"4230721911","pt":1631535867479,"mc":[{"id":"1.187557247","rc":[{"trd":[[1.05,1072.67]],"batb":[[0,1.05,268.46]],"batl":[[1,1.07,2.23]],"ltp":1.05,"tv":44537.26,"id":9304761}],"tv":117237.8}]}
{"op":"mcm","clk":"4230722070","pt":1631535869153,"mc":[{"id":"1.187557247","rc":[{"trd":[[1.06,263.96]],"batl":[[0,1.06,1380.84]],"ltp":1.06,"tv":44537.5,"id":9304761}],"tv":117238.04}]}
{"op":"mcm","clk":"4230722315","pt":1631535871669,"mc":[{"id":"1.187557247","rc":[{"batb":[[0,1.05,265.46],[1,1.04,3105.01]],"ltp":1.06,"tv":44537.5,"id":9304761}]}]}
{"op":"mcm","clk":"4230722401","pt":1631535872553,"mc":[{"id":"1.187557247","rc":[{"trd":[[1.05,1100.21]],"batb":[[0,1.05,341.95]],"ltp":1.05,"tv":44565.04,"id":9304761}],"tv":117265.58}]}
{"op":"mcm","clk":"4230722492","pt":1631535873647,"mc":[{"id":"1.187557247","rc":[{"trd":[[1.06,268.74]],"batl":[[0,1.06,1378.45]],"ltp":1.06,"tv":44569.82,"id":9304761}],"tv":117270.36}]}
{"op":"mcm","clk":"4230722553","pt":1631535874480,"mc":[{"id":"1.187557247","rc":[{"trd":[[1.06,274.74]],"batb":[[0,1.05,503.68]],"batl":[[0,1.06,1375.45]],"ltp":1.06,"tv":44575.82,"id":9304761}],"tv":117276.36}]}
{"op":"mcm","clk":"4230722653","pt":1631535875885,"mc":[{"id":"1.187557247","rc":[{"trd":[[1.06,276.54]],"batl":[[0,1.06,1374.55]],"ltp":1.06,"tv":44577.62,"id":9304761}],"tv":117278.16}]}
{"op":"mcm","clk":"4230722877","pt":1631535878664,"mc":[{"id":"1.187557247","rc":[{"batb":[[1,1.04,3107.95]],"ltp":1.06,"tv":44577.62,"id":9304761}]}]}
{"op":"mcm","clk":"4230723259","pt":1631535883305,"mc":[{"id":"1.187557247","rc":[{"batb":[[1,1.04,2999.77]],"batl":[[0,1.06,1342.07]],"ltp":1.06,"tv":44577.62,"id":9304761}]}]}
{"op":"mcm","clk":"4230723532","pt":1631535886174,"mc":[{"id":"1.187557247","rc":[{"batb":[[0,1.05,624.61]],"ltp":1.06,"tv":44577.62,"id":9304761}]}]}
{"op":"mcm","clk":"4230723628","pt":1631535887367,"mc":[{"id":"1.187557247","rc":[{"trd":[[1.06,278.54]],"batl":[[0,1.06,1341.07]],"ltp":1.06,"tv":44579.62,"id":9304761}],"tv":117280.16}]}
{"op":"mcm","clk":"4230724307","pt":1631535896011,"mc":[{"id":"1.187557247","rc":[{"trd":[[1.06,284.54]],"batl":[[0,1.06,1338.07]],"ltp":1.06,"tv":44585.62,"id":9304761}],"tv":117286.16}]}
{"op":"mcm","clk":"4230725747","pt":1631535914410,"mc":[{"id":"1.187557247","rc":[{"trd":[[1.05,1129.96]],"batb":[[0,1.05,609.73]],"ltp":1.05,"tv":44615.38,"id":9304761}],"tv":117315.91}]}
{"op":"mcm","clk":"4230725880","pt":1631535916339,"mc":[{"id":"1.187557247","rc":[{"trd":[[1.05,1133.37]],"batb":[[0,1.05,608.03]],"ltp":1.05,"tv":44618.78,"id":9304761}],"tv":117319.32}]}
{"op":"mcm","clk":"4230726602","pt":1631535926675,"mc":[{"id":"1.187557247","rc":[{"batl":[[0,25,11.75],[1,26,7.89],[2,27,5.88]],"ltp":21.0,"tv":72700.53,"id":10350473},{"batl":[[0,1.06,1291.18]],"ltp":1.05,"tv":44618.78,"id":9304761}]}]}
{"op":"mcm","clk":"4230726835","pt":1631535929762,"mc":[{"id":"1.187557247","rc":[{"batl":[[0,23,8.6],[1,25,11.75],[2,26,7.89]],"ltp":21.0,"tv":72700.53,"id":10350473},{"batl":[[2,1.08,1201.1]],"ltp":1.05,"tv":44618.78,"id":9304761}]}]}
{"op":"mcm","clk":"4230727265","pt":1631535935377,"mc":[{"id":"1.187557247","rc":[{"batb":[[0,17,82.94],[1,16.5,41.47],[2,16,41.47]],"batl":[[0,25,11.75],[1,26,7.89],[2,27,5.88]],"ltp":21.0,"tv":72700.53,"id":10350473},{"batb":[[0,1.05,517.77]],"ltp":1.05,"tv":44618.78,"id":9304761}]}]}
{"op":"mcm","clk":"4230728492","pt":1631535951716,"mc":[{"id":"1.187557247","rc":[{"batb":[[0,13.5,2.94],[1,12,3.14],[2,11,3.68]],"batl":[[0,26,2.01],[1,36,2],[2,55,2]],"ltp":21.0,"tv":72700.53,"id":10350473}]}]}
{"op":"mcm","clk":"4230728529","pt":1631535952196,"mc":[{"id":"1.187557247","rc":[{"batb":[[0,11,3.68],[1,1.28,720.76],[2,1.2,2]],"batl":[[0,55,2],[1,990,0.01],[2,55,0]],"ltp":21.0,"tv":72700.53,"id":10350473},{"batb":[[0,1.04,2.94],[1,1.03,5.86],[2,1.02,6204.81]],"batl":[[0,1.06,2.23],[2,1.08,2.68]],"ltp":1.05,"tv":44618.78,"id":9304761}]}]}
{"op":"mcm","clk":"4230728769","pt":1631535955384,"mc":[{"id":"1.187557247","rc":[{"batb":[[0,13.5,4.52],[1,13,2],[2,11,5.68]],"batl":[[0,36,2],[1,55,2],[2,990,0.01]],"ltp":21.0,"tv":72700.53,"id":10350473},{"batb":[[1,1.03,4455.98]],"batl":[[2,1.08,2526.9]],"ltp":1.05,"tv":44618.78,"id":9304761}]}]}
{"op":"mcm","clk":"4230728969","pt":1631535958102,"mc":[{"id":"1.187557247","rc":[{"batb":[[0,13.5,2]],"ltp":21.0,"tv":72700.53,"id":10350473},{"batl":[[2,1.08,2.68]],"ltp":1.05,"tv":44618.78,"id":9304761}]}]}
{"op":"mcm","clk":"4230729092","pt":1631535959415,"mc":[{"id":"1.187557247","rc":[{"batb":[[2,1.02,4928.19]],"ltp":1.05,"tv":44618.78,"id":9304761}]}]}
{"op":"mcm","clk":"4230729205","pt":1631535960730,"mc":[{"id":"1.187557247","rc":[{"batb":[[0,21,111.9],[1,20,55.96],[2,19.5,274.14]],"ltp":21.0,"tv":72700.53,"id":10350473},{"trd":[[1.04,424.85]],"batb":[[0,1.03,4455.98],[1,1.02,4928.19],[2,1.01,140.99]],"batl":[[0,1.04,337.36],[1,1.05,8149.62],[2,1.06,2.23]],"ltp":1.04,"tv":44624.66,"id":9304761}],"tv":117325.19}]}
{"op":"mcm","clk":"4230729280","pt":1631535961723,"mc":[{"id":"1.187557247","rc":[{"batb":[[0,21,67.14],[1,20,43.58],[2,19.5,166.58]],"batl":[[0,32,6.51],[1,34,69.12],[2,36,36.56]],"ltp":21.0,"tv":72700.53,"id":10350473},{"trd":[[1.04,463.31]],"batl":[[0,1.04,318.13],[1,1.05,1075.29]],"ltp":1.04,"tv":44663.12,"id":9304761}],"tv":117363.65}]}
{"op":"mcm","clk":"4230729366","pt":1631535962619,"mc":[{"id":"1.187557247","rc":[{"batb":[[0,21,22.38],[1,20,11.2],[2,19.5,144.2]],"batl":[[1,34,8.64],[2,36,6.32]],"ltp":21.0,"tv":72700.53,"id":10350473}]}]}
{"op":"mcm","clk":"4230729403","pt":1631535963082,"mc":[{"id":"1.187557247","rc":[{"batb":[[2,1.01,3006.64]],"ltp":1.04,"tv":44663.12,"id":9304761}]}]}
{"op":"mcm","clk":"4230729460","pt":1631535963929,"mc":[{"id":"1.187557247","rc":[{"batb":[[0,1.03,4698.7]],"ltp":1.04,"tv":44663.12,"id":9304761}]}]}
{"op":"mcm","clk":"4230729575","pt":1631535965695,"mc":[{"id":"1.187557247","rc":[{"batb":[[0,22,10],[1,21,22.38],[2,20,11.2]],"ltp":21.0,"tv":72700.53,"id":10350473}]}]}
{"op":"mcm","clk":"4230729598","pt":1631535966023,"mc":[{"id":"1.187557247","rc":[{"batl":[[0,34,8.64],[1,36,6.32],[2,38,4.32]],"ltp":21.0,"tv":72700.53,"id":10350473},{"batl":[[1,1.05,1078.81]],"ltp":1.04,"tv":44663.12,"id":9304761}]}]}
{"op":"mcm","clk":"4230729702","pt":1631535967328,"mc":[{"id":"1.187557247","rc":[{"batb":[[2,1.01,13458.43]],"batl":[[2,1.06,1415.18]],"ltp":1.04,"tv":44663.12,"id":9304761}]}]}
{"op":"mcm","clk":"4230729791","pt":1631535968523,"mc":[{"id":"1.187557247","rc":[{"trd":[[1.04,663.31]],"batl":[[0,1.04,218.13]],"ltp":1.04,"tv":44863.12,"id":9304761}],"tv":117563.65}]}
{"op":"mcm","clk":"4230729856","pt":1631535969406,"mc":[{"id":"1.187557247","rc":[{"batl":[[1,1.05,1075.29]],"ltp":1.04,"tv":44863.12,"id":9304761}]}]}
{"op":"mcm","clk":"4230730027","pt":1631535971704,"mc":[{"id":"1.187557247","rc":[{"batl":[[0,1.04,270.22],[1,1.05,1144.7]],"ltp":1.04,"tv":44863.12,"id":9304761}]}]}
{"op":"mcm","clk":"4230730098","pt":1631535972649,"mc":[{"id":"1.187557247","rc":[{"trd":[[26,8]],"batb":[[0,17.5,2.18],[1,14,2],[2,13.5,2.62]],"batl":[[0,55,2],[1,110,2],[2,990,0.01]],"ltp":26.0,"tv":72708.53,"id":10350473},{"trd":[[1.04,863.31]],"batb":[[0,1.03,5.86]],"batl":[[0,1.06,1415.18],[1,1.07,1331.24],[2,1.08,1379.82]],"ltp":1.04,"tv":45063.12,"id":9304761}],"tv":117771.65}]}
{"op":"mcm","clk":"4230730123","pt":1631535972960,"mc":[{"id":"1.187557247","rc":[{"batb":[[0,14,2],[1,13.5,2.62],[2,1.28,720.76]],"batl":[[0,110,2],[1,990,0.01],[2,990,0]],"ltp":26.0,"tv":72708.53,"id":10350473},{"batb":[[1,1.02,12.08]],"batl":[[0,1.06,2.23],[1,1.07,2.23]],"ltp":1.04,"tv":45063.12,"id":9304761}]}]}
{"op":"mcm","clk":"4230730220","pt":1631535974521,"mc":[{"id":"1.187557247","rc":[{"batl":[[0,1.05,2.73],[1,1.06,2.23],[2,1.07,2.23]],"ltp":1.04,"tv":45063.12,"id":9304761}]}]}
{"op":"mcm","clk":"4230730291","pt":1631535975499,"mc":[{"id":"1.187557247","rc":[{"batb":[[1,1.02,1396.15]],"batl":[[1,1.06,816.86],[2,1.07,514.6]],"ltp":1.04,"tv":45063.12,"id":9304761}]}]}
{"op":"mcm","clk":"4230730363","pt":1631535976248,"mc":[{"id":"1.187557247","rc":[{"batb":[[0,17.5,5.18],[1,17,2],[2,14,2]],"batl":[[0,55,2],[1,110,2],[2,990,0.01]],"ltp":26.0,"tv":72708.53,"id":10350473},{"batb":[[1,1.02,6589.92]],"batl":[[1,1.06,2503.34],[2,1.07,2048.43]],"ltp":1.04,"tv":45063.12,"id":9304761}]}]}
{"op":"mcm","clk":"4230730747","pt":1631535981719,"mc":[{"id":"1.187557247","rc":[{"batl":[[2,990,0]],"ltp":26.0,"tv":72708.53,"id":10350473},{"batl":[[1,1.06,1688.71],[2,1.07,2.23]],"ltp":1.04,"tv":45063.12,"id":9304761}]}]}
{"op":"mcm","clk":"4230730967","pt":1631535984738,"mc":[{"id":"1.187557247","rc":[{"batb":[[0,27,52.22],[1,26,26.11],[2,25,116.07]],"ltp":26.0,"tv":72708.53,"id":10350473},{"trd":[[1.03,11.72]],"batb":[[0,1.02,6589.92],[1,1.01,10592.78],[2,1.01,0]],"batl":[[0,1.03,1364.77],[1,1.05,2.73],[2,1.06,1688.71]],"ltp":1.03,"tv":45074.84,"id":9304761}],"tv":117783.38}]}
{"op":"mcm","clk":"4230731027","pt":1631535985429,"mc":[{"id":"1.187557247","rc":[{"batb":[[0,27,17.4],[1,26,8.7],[2,25,98.66]],"batl":[[1,70,4.2],[2,75,2.1]],"ltp":26.0,"tv":72708.53,"id":10350473},{"batb":[[0,1.02,6609.53]],"ltp":1.03,"tv":45074.84,"id":9304761}]}]}
{"op":"mcm","clk":"4230731096","pt":1631535986407,"mc":[{"id":"1.187557247","rc":[{"batb":[[0,29,8.62],[1,27,17.4],[2,26,8.7]],"ltp":26.0,"tv":72708.53,"id":10350473}]}]}
{"op":"mcm","clk":"4230731196","pt":1631535987510,"mc":[{"id":"1.187557247","rc":[{"batb":[[0,1.02,6854.63]],"ltp":1.03,"tv":45074.84,"id":9304761}]}]}
{"op":"mcm","clk":"4230731364","pt":1631535989604,"mc":[{"id":"1.187557247","rc":[{"batl":[[0,1.03,1431.21]],"ltp":1.03,"tv":45074.84,"id":9304761}]}]}
{"op":"mcm","clk":"4230731447","pt":1631535990712,"mc":[{"id":"1.187557247","rc":[{"batb":[[2,26,10.7]],"ltp":26.0,"tv":72708.53,"id":10350473},{"batl":[[1,1.04,2374.13],[2,1.05,1964.97]],"ltp":1.03,"tv":45074.84,"id":9304761}]}]}
{"op":"mcm","clk":"4230731513","pt":1631535991604,"mc":[{"id":"1.187557247","rc":[{"trd":[[1.02,17.03],[1.03,411.72]],"batb":[[0,1.02,6846.12]],"batl":[[0,1.03,1231.21]],"ltp":1.03,"tv":45491.87,"id":9304761}],"tv":118200.41}]}
{"op":"mcm","clk":"4230731596","pt":1631535992703,"mc":[{"id":"1.187557247","rc":[{"batl":[[0,46,4.2],[1,55,2],[2,70,4.2]],"ltp":26.0,"tv":72708.53,"id":10350473}]}]}
{"op":"mcm","clk":"4230731717","pt":1631535994759,"mc":[{"id":"1.187557247","rc":[{"batb":[[0,27,17.4],[1,26,10.7],[2,25,98.66]],"ltp":26.0,"tv":72708.53,"id":10350473},{"batl":[[0,1.03,1164.77],[1,1.04,2377.12]],"ltp":1.03,"tv":45491.87,"id":9304761}]}]}
{"op":"mcm","clk":"4230731727","pt":1631535994962,"mc":[{"id":"1.187557247","rc":[{"batl":[[0,1.03,1329.34]],"ltp":1.03,"tv":45491.87,"id":9304761}]}]}
{"op":"mcm","clk":"4230731885","pt":1631535996746,"mc":[{"id":"1.187557247","rc":[{"batb":[[0,26,2],[1,21,2],[2,18,2]],"batl":[[2,110,2]],"ltp":26.0,"tv":72708.53,"id":10350473},{"trd":[[1.02,44.63]],"batb":[[0,1.02,6812.71]],"ltp":1.02,"tv":45519.47,"id":9304761}],"tv":118228.0}]}
{"op":"mcm","clk":"4230731938","pt":1631535997418,"mc":[{"id":"1.187557247","rc":[{"batb":[[0,21,2],[1,18,2],[2,13.5,2]],"batl":[[0,160,32.49],[1,55,0],[2,110,0]],"ltp":26.0,"tv":72708.53,"id":10350473},{"batb":[[0,1.01,140.99],[1,1.01,0]],"batl":[[0,1.04,2.99],[1,1.05,1964.97],[2,1.06,9.23]],"ltp":1.02,"tv":45519.47,"id":9304761}]}]}
{"op":"mcm","clk":"4230732008","pt":1631535998152,"mc":[{"id":"1.187557247","rc":[{"batb":[[2,1.28,720.76]],"ltp":26.0,"tv":72708.53,"id":10350473}]}]}
{"op":"mcm","clk":"4230732066","pt":1631535998832,"mc":[{"id":"1.187557247","rc":[{"batb":[[0,1.01,47.29]],"ltp":1.02,"tv":45519.47,"id":9304761}]}]}
{"op":"mcm","clk":"4230732187","pt":1631536000666,"mc":[{"id":"1.187557247","rc":[{"batb":[[0,26,2],[1,21,4],[2,20,2]],"batl":[[0,110,2],[1,160,32.49]],"ltp":26.0,"tv":72708.53,"id":10350473},{"batb":[[0,1.01,11969.3]],"batl":[[0,1.04,3100.97],[1,1.05,2883.84],[2,1.06,1723.69]],"ltp":1.02,"tv":45519.47,"id":9304761}]}]}
{"op":"mcm","clk":"4230732369","pt":1631536002618,"mc":[{"id":"1.187557247","rc":[{"batl":[[0,34,2],[1,110,2],[2,160,32.49]],"ltp":26.0,"tv":72708.53,"id":10350473}]}]}
{"op":"mcm","clk":"4230732553","pt":1631536004668,"mc":[{"id":"1.187557247","rc":[{"trd":[[34,0.12]],"batl":[[0,110,2],[1,160,32.49],[2,160,0]],"ltp":34.0,"tv":72708.65,"id":10350473},{"trd":[[1.03,415.7]],"batb":[[0,1.01,10571.53]],"ltp":1.03,"tv":45523.45,"id":9304761}],"tv":118232.1}]}
{"op":"mcm","clk":"4230732703","pt":1631536006764,"mc":[{"id":"1.187557247","rc":[{"batb":[[1,21,2]],"batl":[[1,160,0]],"ltp":34.0,"tv":72708.65,"id":10350473}]}]}
{"op":"mcm","clk":"4230732791","pt":1631536007760,"mc":[{"id":"1.187557247","rc":[{"batl":[[0,36,2.92],[1,38,12.36],[2,40,6.18]],"ltp":34.0,"tv":72708.65,"id":10350473},{"trd":[[1.04,901.77]],"batb":[[0,1.03,2503.28],[1,1.01,10571.53]],"batl":[[0,1.04,3081.74]],"ltp":1.04,"tv":45561.9,"id":9304761}],"tv":118270.56}]}
{"op":"mcm","clk":"4230732867","pt":1631536008752,"mc":[{"id":"1.187557247","rc":[{"trd":[[26,46.44]],"batb":[[0,22,13.35],[1,21,8.68],[2,20,8.68]],"batl":[[0,32,6.5],[1,36,2.92],[2,38,12.36]],"ltp":26.0,"tv":72747.09,"id":10350473},{"trd":[[1.04,1762.95]],"batb":[[0,1.03,1917.79]],"batl":[[0,1.04,2220.56]],"ltp":1.04,"tv":46423.08,"id":9304761}],"tv":119170.18}]}
{"op":"mcm","clk":"4230733024","pt":1631536010736,"mc":[{"id":"1.187557247","rc":[{"batl":[[0,36,2.92],[1,38,12.36],[2,40,6.18]],"ltp":26.0,"tv":72747.09,"id":10350473},{"batb":[[0,1.03,1675.07],[1,1.01,13638.55]],"ltp":1.04,"tv":46423.08,"id":9304761}]}]}
{"op":"mcm","clk":"4230733176","pt":1631536012574,"mc":[{"id":"1.187557247","rc":[{"trd":[[1.04,6203.69]],"batl":[[0,1.05,3309.49],[1,1.06,1723.69],[2,1.07,2.23]],"ltp":1.04,"tv":50863.82,"id":9304761}],"tv":123610.92}]}
{"op":"mcm","clk":"4230733324","pt":1631536014253,"mc":[{"id":"1.187557247","rc":[{"batb":[[1,1.02,4831.69],[2,1.01,13638.55]],"ltp":1.04,"tv":50863.82,"id":9304761}]}]}
{"op":"mcm","clk":"4230733529","pt":1631536016663,"mc":[{"id":"1.187557247","rc":[{"batb":[[0,23,4.07],[1,22,13.35],[2,21,8.68]],"batl":[[0,32,6.49],[1,36,2.92],[2,38,12.36]],"ltp":26.0,"tv":72747.09,"id":10350473},{"trd":[[1.03,433.6]],"batb":[[0,1.03,1912.72]],"batl":[[0,1.05,3495.67]],"ltp":1.03,"tv":50881.73,"id":9304761}],"tv":123628.82}]}
{"op":"mcm","clk":"4230733610","pt":1631536017653,"mc":[{"id":"1.187557247","rc":[{"batb":[[1,1.02,4837.62]],"ltp":1.03,"tv":50881.73,"id":9304761}]}]}
{"op":"mcm","clk":"4230733754","pt":1631536019480,"mc":[{"id":"1.187557247","rc":[{"batb":[[0,1.03,1901.06]],"ltp":1.03,"tv":50881.73,"id":9304761}]}]}
{"op":"mcm","clk":"4230733853","pt":1631536020585,"mc":[{"id":"1.187557247","rc":[{"batb":[[0,1.03,2603.59]],"ltp":1.03,"tv":50881.73,"id":9304761}]}]}
{"op":"mcm","clk":"4230734102","pt":1631536023679,"mc":[{"id":"1.187557247","rc":[{"batb":[[0,20,2],[1,17.5,2.18],[2,1.28,720.76]],"batl":[[0,110,2],[1,36,0],[2,38,0]],"ltp":26.0,"tv":72747.09,"id":10350473},{"batb":[[0,1.03,3.88],[1,1.02,5.93]],"batl":[[0,1.05,2.73],[1,1.06,9.23]],"ltp":1.03,"tv":50881.73,"id":9304761}]}]}
{"op":"mcm","clk":"4230734326","pt":1631536026353,"mc":[{"id":"1.187557247","rc":[{"batb":[[1,19.5,2],[2,17.5,2.18]],"ltp":26.0,"tv":72747.09,"id":10350473},{"batb":[[1,1.02,1390]],"batl":[[2,1.07,1321.62]],"ltp":1.03,"tv":50881.73,"id":9304761}]}]}
{"op":"mcm","clk":"4230734417","pt":1631536027356,"mc":[{"id":"1.187557247","rc":[{"batb":[[1,1.02,5.93]],"batl":[[2,1.07,2.23]],"ltp":1.03,"tv":50881.73,"id":9304761}]}]}
{"op":"mcm","clk":"4230734464","pt":1631536027978,"mc":[{"id":"1.187557247","rc":[{"trd":[[1.03,441.37]],"batb":[[0,1.02,5.93],[1,1.01,13638.55],[2,1.01,0]],"batl":[[0,1.03,81.29],[1,1.05,2.73],[2,1.06,9.23]],"ltp":1.03,"tv":50889.5,"id":9304761}],"tv":123636.59}]}
{"op":"mcm","clk":"4230734535","pt":1631536028867,"mc":[{"id":"1.187557247","rc":[{"trd":[[1.03,456.99]],"batl":[[0,1.03,73.48]],"ltp":1.03,"tv":50905.12,"id":9304761}],"tv":123652.21}]}
{"op":"mcm","clk":"4230734634","pt":1631536030064,"mc":[{"id":"1.187557247","rc":[{"trd":[[1.03,603.94]],"batb":[[0,1.03,1370.63],[1,1.02,5.93],[2,1.01,13638.55]],"batl":[[0,1.05,1347.25],[1,1.06,9.23],[2,1.07,2.23]],"ltp":1.03,"tv":51052.07,"id":9304761}],"tv":123799.16}]}
{"op":"mcm","clk":"4230734859","pt":1631536032671,"mc":[{"id":"1.187557247","rc":[{"trd":[[1.03,735.11]],"batb":[[0,1.03,1305.05]],"batl":[[0,1.05,1123.8]],"ltp":1.03,"tv":51183.24,"id":9304761}],"tv":123930.33}]}
{"op":"mcm","clk":"4230735008","pt":1631536034720,"mc":[{"id":"1.187557247","rc":[{"batb":[[2,1.01,13644.67]],"ltp":1.03,"tv":51183.24,"id":9304761}]}]}
{"op":"mcm","clk":"4230735085","pt":1631536035596,"mc":[{"id":"1.187557247","rc":[{"batb":[[0,1.03,1370.63]],"batl":[[0,1.04,225.6],[1,1.05,1123.8],[2,1.06,9.23]],"ltp":1.03,"tv":51183.24,"id":9304761}]}]}
{"op":"mcm","clk":"4230735317","pt":1631536038680,"mc":[{"id":"1.187557247","rc":[{"batb":[[1,17.5,2.18],[2,1.28,720.76]],"ltp":26.0,"tv":72747.09,"id":10350473},{"batb":[[0,1.02,5.93],[1,1.01,13644.67],[2,1.01,0]],"batl":[[0,1.04,3.49],[1,1.05,2.73]],"ltp":1.03,"tv":51183.24,"id":9304761}]}]}
{"op":"mcm","clk":"4230735576","pt":1631536041910,"mc":[{"id":"1.187557247","rc":[{"batb":[[1,19.5,2],[2,17.5,2.18]],"ltp":26.0,"tv":72747.09,"id":10350473}]}]}
{"op":"mcm","clk":"4230735806","pt":1631536044623,"mc":[{"id":"1.187557247","rc":[{"batl":[[0,32,8.7],[1,110,2]],"ltp":26.0,"tv":72747.09,"id":10350473},{"trd":[[1.04,6210.67]],"batb":[[0,1.04,524.73],[1,1.03,837.28],[2,1.02,5.93]],"batl":[[0,1.05,1347.25],[1,1.06,9.23],[2,1.07,2.23]],"ltp":1.04,"tv":51190.22,"id":9304761}],"tv":123937.31}]}
{"op":"mcm","clk":"4230735829","pt":1631536044836,"mc":[{"id":"1.187557247","rc":[{"batl":[[0,110,2],[1,110,0]],"ltp":26.0,"tv":72747.09,"id":10350473}]}]}
{"op":"mcm","clk":"4230735994","pt":1631536046728,"mc":[{"id":"1.187557247","rc":[{"batb":[[0,21,4.79],[1,20,2],[2,19.5,2]],"batl":[[0,29,6.83],[1,110,2]],"ltp":26.0,"tv":72747.09,"id":10350473},{"batb":[[1,1.03,866.93],[2,1.02,517.93]],"ltp":1.04,"tv":51190.22,"id":9304761}]}]}
{"op":"mcm","clk":"4230736071","pt":1631536047612,"mc":[{"id":"1.187557247","rc":[{"batb":[[1,1.03,837.28],[2,1.02,1029.93]],"ltp":1.04,"tv":51190.22,"id":9304761}]}]}
{"op":"mcm","clk":"4230736162","pt":1631536048602,"mc":[{"id":"1.187557247","rc":[{"batb":[[1,1.03,1349.28]],"batl":[[0,1.05,1442.88]],"ltp":1.04,"tv":51190.22,"id":9304761}]}]}
{"op":"mcm","clk":"4230736180","pt":1631536048819,"mc":[{"id":"1.187557247","rc":[{"batb":[[1,1.03,1861.28]],"ltp":1.04,"tv":51190.22,"id":9304761}]}]}
{"op":"mcm","clk":"4230736311","pt":1631536050523,"mc":[{"id":"1.187557247","rc":[{"batb":[[0,20,2],[1,19.5,2],[2,17.5,2.18]],"batl":[[0,110,2],[1,110,0]],"ltp":26.0,"tv":72747.09,"id":10350473},{"batb":[[0,1.03,1024],[1,1.02,1029.93],[2,1.01,14979.31]],"batl":[[0,1.05,2.73]],"ltp":1.04,"tv":51190.22,"id":9304761}]}]}
{"op":"mcm","clk":"4230736596","pt":1631536053699,"mc":[{"id":"1.187557247","rc":[{"batb":[[1,17.5,2.18],[2,1.28,720.76]],"ltp":26.0,"tv":72747.09,"id":10350473},{"batb":[[1,1.02,2414]],"batl":[[2,1.07,1321.62]],"ltp":1.04,"tv":51190.22,"id":9304761}]}]}
{"op":"mcm","clk":"4230736875","pt":1631536056912,"mc":[{"id":"1.187557247","rc":[{"batb":[[1,19.5,2],[2,17.5,2.18]],"ltp":26.0,"tv":72747.09,"id":10350473}]}]}
{"op":"mcm","clk":"4230736986","pt":1631536058427,"mc":[{"id":"1.187557247","rc":[{"trd":[[1.03,824.11]],"batb":[[0,1.03,979.5]],"batl":[[0,1.04,21.47],[1,1.05,2.73],[2,1.06,9.23]],"ltp":1.03,"tv":51279.22,"id":9304761}],"tv":124026.31}]}
{"op":"mcm","clk":"4230737053","pt":1631536059217,"mc":[{"id":"1.187557247","rc":[{"batb":[[0,1.03,984.04]],"ltp":1.03,"tv":51279.22,"id":9304761}]}]}
{"op":"mcm","clk":"4230737198","pt":1631536061122,"mc":[{"id":"1.187557247","rc":[{"trd":[[1.03,841.69]],"batb":[[0,1.03,975.25]],"ltp":1.03,"tv":51296.8,"id":9304761}],"tv":124043.89}]}
{"op":"mcm","clk":"4230737432","pt":1631536064114,"mc":[{"id":"1.187557247","rc":[{"batb":[[1,1.02,1029.93]],"batl":[[0,1.04,11.71]],"ltp":1.03,"tv":51296.8,"id":9304761}]}]}
{"op":"mcm","clk":"4230737653","pt":1631536066755,"mc":[{"id":"1.187557247","rc":[{"batb":[[0,17.5,2.18],[1,1.28,720.76],[2,1.2,2]],"ltp":26.0,"tv":72747.09,"id":10350473},{"trd":[[1.04,6234.1],[1.05,1138.83]],"batb":[[0,1.05,274.95],[1,1.03,4.54],[2,1.02,1029.93]],"batl":[[0,1.06,2.23],[1,1.07,1321.62],[2,1.08,2.68]],"ltp":1.05,"tv":51325.69,"id":9304761}],"tv":124072.79}]}
{"op":"mcm","clk":"4230737749","pt":1631536067708,"mc":[{"id":"1.187557247","rc":[{"batb":[[1,16.5,71.21],[2,16,35.6]],"batl":[[0,24,19.58],[1,25,9.8],[2,26,9.8]],"ltp":26.0,"tv":72747.09,"id":10350473},{"trd":[[1.06,289.01]],"batb":[[0,1.06,16.63],[1,1.05,1351.08],[2,1.03,4.54]],"batl":[[0,1.07,1321.62],[1,1.08,2.68],[2,1.09,2.39]],"ltp":1.06,"tv":51330.17,"id":9304761}],"tv":124077.26}]}
{"op":"mcm","clk":"4230737784","pt":1631536068123,"mc":[{"id":"1.187557247","rc":[{"batb":[[1,16.5,17.8],[2,16,8.9]],"ltp":26.0,"tv":72747.09,"id":10350473}]}]}
{"op":"mcm","clk":"4230738007","pt":1631536070647,"mc":[{"id":"1.187557247","rc":[{"batl":[[0,22,9.75],[1,24,19.58],[2,25,9.8]],"ltp":26.0,"tv":72747.09,"id":10350473},{"trd":[[1.05,1417.43],[1.06,322.27]],"batb":[[0,1.05,1380.43],[1,1.04,512],[2,1.03,1028.54]],"batl":[[0,1.07,1203.26]],"ltp":1.05,"tv":51642.03,"id":9304761}],"tv":124389.12}]}
{"op":"mcm","clk":"4230738034","pt":1631536071019,"mc":[{"id":"1.187557247","rc":[{"batb":[[1,1.04,1024]],"ltp":1.05,"tv":51642.03,"id":9304761}]}]}
{"op":"mcm","clk":"4230738258","pt":1631536073643,"mc":[{"id":"1.187557247","rc":[{"batb":[[0,1.05,1513.17]],"ltp":1.05,"tv":51642.03,"id":9304761}]}]}
{"op":"mcm","clk":"4230738294","pt":1631536074025,"mc":[{"id":"1.187557247","rc":[{"batl":[[0,1.07,1443.29]],"ltp":1.05,"tv":51642.03,"id":9304761}]}]}
{"op":"mcm","clk":"4230738573","pt":1631536077340,"mc":[{"id":"1.187557247","rc":[{"trd":[[1.07,580.62]],"batb":[[0,1.05,2682.37]],"batl":[[0,1.07,1226.27]],"ltp":1.07,"tv":52076.01,"id":9304761}],"tv":124823.11}]}
{"op":"mcm","clk":"4230738730","pt":1631536079139,"mc":[{"id":"1.187557247","rc":[{"batb":[[1,1.04,1027.36]],"ltp":1.07,"tv":52076.01,"id":9304761}]}]}
{"op":"mcm","clk":"4230738828","pt":1631536080251,"mc":[{"id":"1.187557247","rc":[{"batb":[[0,1.05,2684.99]],"batl":[[0,1.07,1441.06]],"ltp":1.07,"tv":52076.01,"id":9304761}]}]}
{"op":"mcm","clk":"4230739149","pt":1631536084033,"mc":[{"id":"1.187557247","rc":[{"trd":[[1.05,1422.94]],"batb":[[0,1.05,2682.24]],"ltp":1.05,"tv":52081.52,"id":9304761}],"tv":124828.61}]}
{"op":"mcm","clk":"4230739485","pt":1631536088351,"mc":[{"id":"1.187557247","rc":[{"batb":[[0,1.28,720.76],[1,1.2,2],[2,1.18,70]],"batl":[[0,110,2],[1,24,0],[2,25,0]],"ltp":26.0,"tv":72747.09,"id":10350473},{"batb":[[0,1.05,2.62]],"batl":[[0,1.08,2.68],[1,1.09,2.39],[2,1.14,1.16]],"ltp":1.05,"tv":52081.52,"id":9304761}]}]}
{"op":"mcm","clk":"4230739678","pt":1631536090574,"mc":[{"id":"1.187557247","rc":[{"batl":[[0,55,4.02],[1,110,2]],"ltp":26.0,"tv":72747.09,"id":10350473},{"batb":[[0,1.06,2.56],[1,1.05,2.62],[2,1.04,1027.36]],"ltp":1.05,"tv":52081.52,"id":9304761}]}]}
{"op":"mcm","clk":"4230739773","pt":1631536091539,"mc":[{"id":"1.187557247","rc":[{"batb":[[0,4.5,2],[1,4.4,3],[2,1.28,720.76]],"ltp":26.0,"tv":72747.09,"id":10350473},{"batl":[[2,1.1,981.9]],"ltp":1.05,"tv":52081.52,"id":9304761}]}]}
{"op":"mcm","clk":"4230739917","pt":1631536093266,"mc":[{"id":"1.187557247","rc":[{"batl":[[2,1.14,1.16]],"ltp":1.05,"tv":52081.52,"id":9304761}]}]}
{"op":"mcm","clk":"4230740013","pt":1631536094374,"mc":[{"id":"1.187557247","rc":[{"batb":[[0,11,3],[1,10.5,2],[2,4.5,2]],"ltp":26.0,"tv":72747.09,"id":10350473}]}]}
{"op":"mcm","clk":"4230740218","pt":1631536096658,"mc":[{"id":"1.187557247","rc":[{"batb":[[0,25,94],[1,24,47],[2,23,47]],"ltp":26.0,"tv":72747.09,"id":10350473},{"trd":[[1.04,8288.83],[1.05,1428.18],[1.06,327.4]],"batb":[[0,1.03,2399.17],[1,1.02,6267.12],[2,1.01,12107.53]],"batl":[[0,1.04,123.14],[1,1.05,276.63],[2,1.08,187.78]],"ltp":1.04,"tv":54146.6,"id":9304761}],"tv":126893.69}]}
{"op":"mcm","clk":"4230740305","pt":1631536097664,"mc":[{"id":"1.187557247","rc":[{"batb":[[0,25,56.4],[1,24,28.2],[2,23,28.2]],"batl":[[0,44,6.68],[1,46,3.34],[2,48,3.34]],"ltp":26.0,"tv":72747.09,"id":10350473},{"batb":[[0,1.03,2418.59]],"batl":[[1,1.05,311.07],[2,1.06,2.48]],"ltp":1.04,"tv":54146.6,"id":9304761}]}]}
{"op":"mcm","clk":"4230740385","pt":1631536098454,"mc":[{"id":"1.187557247","rc":[{"batl":[[0,36,6.18],[1,44,6.68],[2,46,3.34]],"ltp":26.0,"tv":72747.09,"id":10350473},{"batl":[[1,1.05,276.63],[2,1.06,3]],"ltp":1.04,"tv":54146.6,"id":9304761}]}]}
{"op":"mcm","clk":"4230740494","pt":1631536099455,"mc":[{"id":"1.187557247","rc":[{"batb":[[0,1.03,2599.22],[1,1.02,6273.24],[2,1.01,15174.55]],"batl":[[0,1.04,582.77],[1,1.05,838.96]],"ltp":1.04,"tv":54146.6,"id":9304761}]}]}
{"op":"mcm","clk":"4230740656","pt":1631536101578,"mc":[{"id":"1.187557247","rc":[{"batb":[[0,26,2.55],[1,25,56.4],[2,24,28.2]],"ltp":26.0,"tv":72747.09,"id":10350473},{"batl":[[0,1.04,646.49],[1,1.05,842.56]],"ltp":1.04,"tv":54146.6,"id":9304761}]}]}
{"op":"mcm","clk":"4230740741","pt":1631536102686,"mc":[{"id":"1.187557247","rc":[{"batl":[[0,1.04,1723.27]],"ltp":1.04,"tv":54146.6,"id":9304761}]}]}
{"op":"mcm","clk":"4230740834","pt":1631536103574,"mc":[{"id":"1.187557247","rc":[{"batl":[[0,1.04,1674.06],[2,1.06,5.49]],"ltp":1.04,"tv":54146.6,"id":9304761}]}]}
{"op":"mcm","clk":"4230740886","pt":1631536104261,"mc":[{"id":"1.187557247","rc":[{"batl":[[1,1.05,838.96]],"ltp":1.04,"tv":54146.6,"id":9304761}]}]}
{"op":"mcm","clk":"4230741059","pt":1631536106603,"mc":[{"id":"1.187557247","rc":[{"batl":[[1,1.05,887.7]],"ltp":1.04,"tv":54146.6,"id":9304761}]}]}
{"op":"mcm","clk":"4230741085","pt":1631536106875,"mc":[{"id":"1.187557247","rc":[{"trd":[[1.04,8318.83]],"batl":[[0,1.04,1659.06]],"ltp":1.04,"tv":54176.6,"id":9304761}],"tv":126923.69}]}
{"op":"mcm","clk":"4230741166","pt":1631536107974,"mc":[{"id":"1.187557247","rc":[{"batl":[[1,1.05,816.04]],"ltp":1.04,"tv":54176.6,"id":9304761}]}]}
{"op":"mcm","clk":"4230741556","pt":1631536112199,"mc":[{"id":"1.187557247","rc":[{"batl":[[1,1.05,819.16]],"ltp":1.04,"tv":54176.6,"id":9304761}]}]}
{"op":"mcm","clk":"4230741856","pt":1631536115692,"mc":[{"id":"1.187557247","rc":[{"batb":[[0,11.5,2],[1,1.28,720.76],[2,1.2,2]],"batl":[[0,55,4.02],[1,110,2],[2,46,0]],"ltp":26.0,"tv":72747.09,"id":10350473},{"batb":[[0,1.03,2399.17]],"batl":[[0,1.04,1595.34]],"ltp":1.04,"tv":54176.6,"id":9304761}]}]}
{"op":"mcm","clk":"4230741890","pt":1631536116031,"mc":[{"id":"1.187557247","rc":[{"batl":[[0,110,2],[1,110,0]],"ltp":26.0,"tv":72747.09,"id":10350473},{"batb":[[0,1.03,1028.54],[1,1.02,1036.05]],"batl":[[0,1.04,1076.78],[1,1.05,3.12],[2,1.06,2.49]],"ltp":1.04,"tv":54176.6,"id":9304761}]}]}
{"op":"mcm","clk":"4230742040","pt":1631536117715,"mc":[{"id":"1.187557247","rc":[{"trd":[[1.04,8319.13]],"batb":[[2,1.01,12107.53]],"batl":[[0,1.04,1076.63]],"ltp":1.04,"tv":54176.9,"id":9304761}],"tv":126924.0}]}
{"op":"mcm","clk":"4230742132","pt":1631536118701,"mc":[{"id":"1.187557247","rc":[{"batb":[[0,14,125.96],[1,11.5,2],[2,1.28,720.76]],"batl":[[0,36,2],[1,110,2]],"ltp":26.0,"tv":72747.09,"id":10350473},{"batb":[[2,1.01,13505.3]],"ltp":1.04,"tv":54176.9,"id":9304761}]}]}
{"op":"mcm","clk":"4230742165","pt":1631536119077,"mc":[{"id":"1.187557247","rc":[{"batb":[[0,11.5,2],[1,1.28,720.76],[2,1.2,2]],"ltp":26.0,"tv":72747.09,"id":10350473},{"batb":[[0,1.03,4.54]],"ltp":1.04,"tv":54176.9,"id":9304761}]}]}
{"op":"mcm","clk":"4230742757","pt":1631536126731,"mc":[{"id":"1.187557247","rc":[{"batb":[[2,1.01,12107.53]],"ltp":1.04,"tv":54176.9,"id":9304761}]}]}
{"op":"mcm","clk":"4230742993","pt":1631536129704,"mc":[{"id":"1.187557247","rc":[{"trd":[[1.04,9421.85]],"batb":[[0,1.03,818.45]],"batl":[[0,1.04,546.4],[1,1.05,1347.64]],"ltp":1.04,"tv":55279.62,"id":9304761}],"tv":128026.72}]}
{"op":"mcm","clk":"4230743014","pt":1631536130019,"mc":[{"id":"1.187557247","rc":[{"batl":[[0,1.04,525.27]],"ltp":1.04,"tv":55279.62,"id":9304761}]}]}
{"op":"mcm","clk":"4230743119","pt":1631536131590,"mc":[{"id":"1.187557247","rc":[{"trd":[[26,67.45]],"batb":[[0,19.5,10],[1,11.5,2],[2,1.28,720.76]],"batl":[[0,30,6.32],[1,36,2],[2,110,2]],"ltp":26.0,"tv":72768.1,"id":10350473},{"trd":[[1.04,9947.12]],"batb":[[0,1.04,22.7],[1,1.03,818.45],[2,1.02,1036.05]],"batl":[[0,1.05,1347.64],[1,1.06,2.49],[2,1.07,2.43]],"ltp":1.04,"tv":55804.89,"id":9304761}],"tv":128573.0}]}
{"op":"mcm","clk":"4230743274","pt":1631536133623,"mc":[{"id":"1.187557247","rc":[{"batl":[[0,36,2],[1,110,2],[2,110,0]],"ltp":26.0,"tv":72768.1,"id":10350473},{"batb":[[0,1.04,269.37],[1,1.03,1126.1]],"ltp":1.04,"tv":55804.89,"id":9304761}]}]}
{"op":"mcm","clk":"4230743365","pt":1631536134733,"mc":[{"id":"1.187557247","rc":[{"batb":[[0,1.04,305.4]],"batl":[[0,1.05,1489.5]],"ltp":1.04,"tv":55804.89,"id":9304761}]}]}
{"op":"mcm","clk":"4230743394","pt":1631536134994,"mc":[{"id":"1.187557247","rc":[{"batb":[[0,11.5,2],[1,1.28,720.76],[2,1.2,2]],"ltp":26.0,"tv":72768.1,"id":10350473},{"batb":[[0,1.04,36.03],[1,1.03,4.54]],"batl":[[0,1.05,3.12]],"ltp":1.04,"tv":55804.89,"id":9304761}]}]}
{"op":"mcm","clk":"4230743669","pt":1631536138234,"mc":[{"id":"1.187557247","rc":[{"batb":[[1,11,2],[2,1.28,720.76]],"ltp":26.0,"tv":72768.1,"id":10350473},{"batl":[[2,1.07,1062.97]],"ltp":1.04,"tv":55804.89,"id":9304761}]}]}
{"op":"mcm","clk":"4230743780","pt":1631536140034,"mc":[{"id":"1.187557247","rc":[{"batb":[[0,1.04,26.03]],"ltp":1.04,"tv":55804.89,"id":9304761}]}]}
{"op":"mcm","clk":"4230744027","pt":1631536143133,"mc":[{"id":"1.187557247","rc":[{"batb":[[1,1.03,14.54]],"ltp":1.04,"tv":55804.89,"id":9304761}]}]}
{"op":"mcm","clk":"4230744255","pt":1631536145938,"mc":[{"id":"1.187557247","rc":[{"trd":[[1.04,9999.19]],"batb":[[0,1.03,14.54],[1,1.02,1036.05],[2,1.01,12107.53]],"batl":[[0,1.04,1973.96],[1,1.05,3.12],[2,1.06,2.49]],"ltp":1.04,"tv":55856.96,"id":9304761}],"tv":128625.07}]}
{"op":"mcm","clk":"4230744390","pt":1631536147611,"mc":[{"id":"1.187557247","rc":[{"trd":[[21,1.77],[26,145.65]],"batl":[[0,19.5,228.6],[1,23,102.16],[2,24,51.08]],"ltp":21.0,"tv":72846.46,"id":10350473},{"trd":[[1.04,11992.02],[1.05,1431.3]],"batl":[[0,1.06,2.49],[1,1.07,1062.97],[2,1.08,259.13]],"ltp":1.05,"tv":57852.92,"id":9304761}],"tv":130699.38}]}
{"op":"mcm","clk":"4230744487","pt":1631536148741,"mc":[{"id":"1.187557247","rc":[{"batb":[[0,15.5,151.62],[1,15,75.8],[2,14.5,75.8]],"batl":[[1,23,20.44],[2,24,10.22]],"ltp":21.0,"tv":72846.46,"id":10350473},{"trd":[[1.06,332.37]],"batb":[[0,1.06,244.7],[1,1.05,1094.97],[2,1.04,1668.26]],"batl":[[0,1.07,1062.97],[1,1.08,259.13],[2,1.09,2.39]],"ltp":1.06,"tv":57857.9,"id":9304761}],"tv":130704.36}]}
{"op":"mcm","clk":"4230744549","pt":1631536149326,"mc":[{"id":"1.187557247","rc":[{"batb":[[0,15.5,18.95],[1,15,9.48],[2,14.5,9.48]],"ltp":21.0,"tv":72846.46,"id":10350473}]}]}
{"op":"mcm","clk":"4230744753","pt":1631536151628,"mc":[{"id":"1.187557247","rc":[{"batl":[[0,1.07,1156.77]],"ltp":1.06,"tv":57857.9,"id":9304761}]}]}
{"op":"mcm","clk":"4230744855","pt":1631536152724,"mc":[{"id":"1.187557247","rc":[{"batb":[[0,16,3.2],[1,15.5,18.95],[2,15,9.48]],"batl":[[0,19,9.49],[1,19.5,228.6],[2,23,20.44]],"ltp":21.0,"tv":72846.46,"id":10350473},{"batb":[[0,1.06,290.04]],"batl":[[1,1.08,1044.17]],"ltp":1.06,"tv":57857.9,"id":9304761}]}]}
{"op":"mcm","clk":"4230744873","pt":1631536152927,"mc":[{"id":"1.187557247","rc":[{"batl":[[1,1.08,259.13]],"ltp":1.06,"tv":57857.9,"id":9304761}]}]}
{"op":"mcm","clk":"4230745067","pt":1631536155729,"mc":[{"id":"1.187557247","rc":[{"batb":[[2,1.04,1672.1]],"ltp":1.06,"tv":57857.9,"id":9304761}]}]}
{"op":"mcm","clk":"4230745107","pt":1631536156255,"mc":[{"id":"1.187557247","rc":[{"batb":[[1,1.05,1097.88]],"ltp":1.06,"tv":57857.9,"id":9304761}]}]}
{"op":"mcm","clk":"4230745985","pt":1631536166920,"mc":[{"id":"1.187557247","rc":[{"trd":[[1.07,580.89]],"batl":[[0,1.07,1156.63]],"ltp":1.07,"tv":57858.17,"id":9304761}],"tv":130704.63}]}
{"op":"mcm","clk":"4230746148","pt":1631536169559,"mc":[{"id":"1.187557247","rc":[{"trd":[[1.06,332.61]],"batb":[[0,1.06,289.92]],"ltp":1.06,"tv":57858.4,"id":9304761}],"tv":130704.87}]}
{"op":"mcm","clk":"4230746229","pt":1631536170676,"mc":[{"id":"1.187557247","rc":[{"batb":[[1,11.5,2],[2,1.28,720.76]],"batl":[[1,26,22.24],[2,36,2]],"ltp":21.0,"tv":72846.46,"id":10350473}]}]}
{"op":"mcm","clk":"4230746257","pt":1631536170936,"mc":[{"id":"1.187557247","rc":[{"batb":[[0,11.5,2],[1,1.28,720.76],[2,1.2,2]],"batl":[[0,36,2],[1,55,3.09],[2,110,2]],"ltp":21.0,"tv":72846.46,"id":10350473},{"batb":[[0,1.05,2.91],[1,1.04,3.84],[2,1.03,14.54]],"batl":[[0,1.07,2.29],[1,1.08,2.68]],"ltp":1.06,"tv":57858.4,"id":9304761}]}]}
{"op":"mcm","clk":"4230746499","pt":1631536174077,"mc":[{"id":"1.187557247","rc":[{"batb":[[1,11,2],[2,1.28,720.76]],"ltp":21.0,"tv":72846.46,"id":10350473},{"batb":[[2,1.03,1385.17]],"ltp":1.06,"tv":57858.4,"id":9304761}]}]}
{"op":"mcm","clk":"4230746807","pt":1631536178265,"mc":[{"id":"1.187557247","rc":[{"trd":[[1.07,585.48]],"batb":[[0,1.07,97.71],[1,1.05,2.91],[2,1.04,3.84]],"batl":[[0,1.08,2.68],[1,1.09,2.39],[2,1.14,1.16]],"ltp":1.07,"tv":57862.99,"id":9304761}],"tv":130709.45}]}
{"op":"mcm","clk":"4230746914","pt":1631536179668,"mc":[{"id":"1.187557247","rc":[{"batb":[[0,23,102.16],[1,22,51.08],[2,21,51.08]],"ltp":21.0,"tv":72846.46,"id":10350473},{"trd":[[1.05,1437.12],[1.07,780.9]],"batb":[[0,1.04,3.84],[1,1.03,1385.17],[2,1.02,6261.93]],"batl":[[0,1.05,11703.6],[1,1.08,2.68],[2,1.09,2.39]],"ltp":1.05,"tv":58064.22,"id":9304761}],"tv":130910.69}]}
{"op":"mcm","clk":"4230747010","pt":1631536180626,"mc":[{"id":"1.187557247","rc":[{"batl":[[1,40,58.76],[2,42,29.38]],"ltp":21.0,"tv":72846.46,"id":10350473},{"trd":[[1.04,11999.7]],"batb":[[0,1.03,1404.59],[1,1.02,6261.93],[2,1.01,12107.53]],"batl":[[0,1.04,570.08],[1,1.05,1523.92],[2,1.07,365.56]],"ltp":1.04,"tv":58071.91,"id":9304761}],"tv":130918.37}]}
{"op":"mcm","clk":"4230747067","pt":1631536181266,"mc":[{"id":"1.187557247","rc":[{"batb":[[0,23,61.3],[1,22,30.65],[2,21,30.65]],"batl":[[0,34,5.36],[1,36,2],[2,40,7.35]],"ltp":21.0,"tv":72846.46,"id":10350473},{"batl":[[2,1.08,2.68]],"ltp":1.04,"tv":58071.91,"id":9304761}]}]}
{"op":"mcm","clk":"4230747190","pt":1631536182596,"mc":[{"id":"1.187557247","rc":[{"trd":[[1.04,12008.62]],"batl":[[0,1.04,565.62],[2,1.07,27]],"ltp":1.04,"tv":58080.83,"id":9304761}],"tv":130927.29}]}
{"op":"mcm","clk":"4230747236","pt":1631536183161,"mc":[{"id":"1.187557247","rc":[{"batb":[[0,1.03,1589.11],[2,1.01,15174.55]],"ltp":1.04,"tv":58080.83,"id":9304761}]}]}
{"op":"mcm","clk":"4230747357","pt":1631536184666,"mc":[{"id":"1.187557247","rc":[{"batb":[[0,24,10],[1,23,61.3],[2,22,30.65]],"ltp":21.0,"tv":72846.46,"id":10350473},{"batl":[[0,1.04,624.32],[1,1.05,2393.07]],"ltp":1.04,"tv":58080.83,"id":9304761}]}]}
{"op":"mcm","clk":"4230747430","pt":1631536185562,"mc":[{"id":"1.187557247","rc":[{"trd":[[1.03,863.03]],"batb":[[0,1.03,1578.44]],"batl":[[1,1.05,1523.92]],"ltp":1.03,"tv":58102.17,"id":9304761}],"tv":130948.63}]}
{"op":"mcm","clk":"4230747680","pt":1631536188564,"mc":[{"id":"1.187557247","rc":[{"batl":[[2,1.06,2.76]],"ltp":1.03,"tv":58102.17,"id":9304761}]}]}
{"op":"mcm","clk":"4230747753","pt":1631536189557,"mc":[{"id":"1.187557247","rc":[{"batb":[[0,1.03,3989.18]],"batl":[[1,1.05,1527.49]],"ltp":1.03,"tv":58102.17,"id":9304761}]}]}
{"op":"mcm","clk":"4230747811","pt":1631536190390,"mc":[{"id":"1.187557247","rc":[{"trd":[[1.04,12014.21]],"batl":[[0,1.04,621.53]],"ltp":1.04,"tv":58107.75,"id":9304761}],"tv":130954.22}]}
{"op":"mcm","clk":"4230748070","pt":1631536193495,"mc":[{"id":"1.187557247","rc":[{"batb":[[0,1.28,720.76],[1,1.2,2],[2,1.18,70]],"batl":[[0,36,2],[1,110,2],[2,40,0]],"ltp":21.0,"tv":72846.46,"id":10350473},{"batb":[[0,1.03,2414.61],[1,1.02,1036.05]],"batl":[[0,1.05,3.57],[1,1.06,2.76],[2,1.08,2.68]],"ltp":1.04,"tv":58107.75,"id":9304761}]}]}
{"op":"mcm","clk":"4230748223","pt":1631536195681,"mc":[{"id":"1.187557247","rc":[{"batb":[[2,1.01,12107.53]],"ltp":1.04,"tv":58107.75,"id":9304761}]}]}
{"op":"mcm","clk":"4230748255","pt":1631536196047,"mc":[{"id":"1.187557247","rc":[{"batb":[[2,1.01,13505.3]],"batl":[[2,1.07,823.2]],"ltp":1.04,"tv":58107.75,"id":9304761}]}]}
{"op":"mcm","clk":"4230748324","pt":1631536196993,"mc":[{"id":"1.187557247","rc":[{"batb":[[0,4.5,3],[1,4.4,2],[2,1.28,720.76]],"ltp":21.0,"tv":72846.46,"id":10350473},{"batb":[[0,1.03,3.87]],"ltp":1.04,"tv":58107.75,"id":9304761}]}]}
{"op":"mcm","clk":"4230748848","pt":1631536203299,"mc":[{"id":"1.187557247","rc":[{"batl":[[2,1.07,825.85]],"ltp":1.04,"tv":58107.75,"id":9304761}]}]}
{"op":"mcm","clk":"4230748909","pt":1631536203862,"mc":[{"id":"1.187557247","rc":[{"batl":[[0,1.04,4.09],[1,1.05,3.57],[2,1.06,2.76]],"ltp":1.04,"tv":58107.75,"id":9304761}]}]}
{"op":"mcm","clk":"4230749046","pt":1631536205395,"mc":[{"id":"1.187557247","rc":[{"batb":[[2,1.01,12107.53]],"ltp":1.04,"tv":58107.75,"id":9304761}]}]}
{"op":"mcm","clk":"4230749334","pt":1631536208602,"mc":[{"id":"1.187557247","rc":[{"batb":[[0,15,2],[1,14.5,2],[2,4.5,3]],"batl":[[0,17,276.48],[1,22,21.36],[2,23,10.68]],"ltp":21.0,"tv":72846.46,"id":10350473},{"trd":[[1.04,12022.38],[1.05,1444.26],[1.06,338.13]],"batb":[[0,1.06,537.33],[1,1.05,821.12],[2,1.04,1661.83]],"batl":[[0,1.07,825.85],[1,1.08,494.27],[2,1.09,2.39]],"ltp":1.06,"tv":58128.59,"id":9304761}],"tv":130975.06}]}
{"op":"mcm","clk":"4230749409","pt":1631536209494,"mc":[{"id":"1.187557247","rc":[{"batb":[[0,15.5,18.95],[1,15,9.48],[2,14.5,9.48]],"ltp":21.0,"tv":72846.46,"id":10350473},{"batb":[[2,1.04,1657.74]],"ltp":1.06,"tv":58128.59,"id":9304761}]}]}
{"op":"mcm","clk":"4230749575","pt":1631536211597,"mc":[{"id":"1.187557247","rc":[{"batl":[[1,21,10],[2,22,21.36]],"ltp":21.0,"tv":72846.46,"id":10350473},{"batb":[[0,1.06,596.74]],"batl":[[0,1.07,903.71]],"ltp":1.06,"tv":58128.59,"id":9304761}]}]}
{"op":"mcm","clk":"4230749957","pt":1631536216496,"mc":[{"id":"1.187557247","rc":[{"batb":[[0,15.5,23.36]],"ltp":21.0,"tv":72846.46,"id":10350473}]}]}
{"op":"mcm","clk":"4230750905","pt":1631536228325,"mc":[{"id":"1.187557247","rc":[{"trd":[[15.5,16.29]],"batb":[[0,15.5,7.07]],"ltp":15.5,"tv":72862.75,"id":10350473},{"trd":[[1.07,2823.7]],"batb":[[1,1.05,354.99]],"batl":[[0,1.08,494.27],[1,1.09,2.39],[2,1.14,1.16]],"ltp":1.07,"tv":60171.39,"id":9304761}],"tv":133034.15}]}
{"op":"mcm","clk":"4230751078","pt":1631536230413,"mc":[{"id":"1.187557247","rc":[{"batb":[[2,1.04,1662.14]],"ltp":1.07,"tv":60171.39,"id":9304761}]}]}
{"op":"mcm","clk":"4230751186","pt":1631536231618,"mc":[{"id":"1.187557247","rc":[{"batb":[[0,15.5,4.41],[1,4.5,3],[2,1.28,720.76]],"batl":[[0,21,10],[1,26,22.11],[2,36,2]],"ltp":15.5,"tv":72862.75,"id":10350473},{"batb":[[0,1.06,1039.6],[1,1.05,358.22]],"batl":[[0,1.07,365.82],[1,1.08,947.42],[2,1.09,2.39]],"ltp":1.07,"tv":60171.39,"id":9304761}]}]}
{"op":"mcm","clk":"4230751252","pt":1631536232354,"mc":[{"id":"1.187557247","rc":[{"batb":[[0,4.5,3],[1,1.28,720.76],[2,1.2,2]],"batl":[[0,36,2],[1,55,3.27],[2,110,2]],"ltp":15.5,"tv":72862.75,"id":10350473},{"batb":[[0,1.05,3.23],[1,1.04,4.4],[2,1.03,9.19]],"batl":[[0,1.08,2.68],[1,1.09,2.39],[2,1.14,1.16]],"ltp":1.07,"tv":60171.39,"id":9304761}]}]}
{"op":"mcm","clk":"4230751455","pt":1631536234750,"mc":[{"id":"1.187557247","rc":[{"batb":[[2,1.03,1379.82]],"batl":[[2,1.11,829.43]],"ltp":1.07,"tv":60171.39,"id":9304761}]}]}
{"op":"mcm","clk":"4230751482","pt":1631536235014,"mc":[{"id":"1.187557247","rc":[{"batb":[[1,4.4,2],[2,1.28,720.76]],"ltp":15.5,"tv":72862.75,"id":10350473}]}]}
{"op":"mcm","clk":"4230751728","pt":1631536237630,"mc":[{"id":"1.187557247","rc":[{"batb":[[2,1.03,3790.56]],"ltp":1.07,"tv":60171.39,"id":9304761}]}]}
{"op":"mcm","clk":"4230751764","pt":1631536237949,"mc":[{"id":"1.187557247","rc":[{"batb":[[0,10,2],[1,9.8,2],[2,4.5,3]],"ltp":15.5,"tv":72862.75,"id":10350473}]}]}
{"op":"mcm","clk":"4230751912","pt":1631536240071,"mc":[{"id":"1.187557247","rc":[{"batb":[[0,1.06,3.05],[1,1.05,3.23],[2,1.04,4.4]],"ltp":1.07,"tv":60171.39,"id":9304761}]}]}
{"op":"mcm","clk":"4230752055","pt":1631536241758,"mc":[{"id":"1.187557247","rc":[{"trd":[[1.05,1450.72],[1.06,344.23]],"batb":[[0,1.04,4.4],[1,1.03,3790.56],[2,1.02,7685.99]],"batl":[[0,1.05,19.08],[1,1.08,2.68],[2,1.09,2.39]],"ltp":1.05,"tv":60183.96,"id":9304761}],"tv":133046.71}]}
{"op":"mcm","clk":"4230752068","pt":1631536241951,"mc":[{"id":"1.187557247","rc":[{"batl":[[0,1.08,2.68],[1,1.09,2.39],[2,1.11,829.43]],"ltp":1.05,"tv":60183.96,"id":9304761}]}]}
{"op":"mcm","clk":"4230752254","pt":1631536244138,"mc":[{"id":"1.187557247","rc":[{"batl":[[2,1.14,1.16]],"ltp":1.05,"tv":60183.96,"id":9304761}]}]}
{"op":"mcm","clk":"4230752487","pt":1631536246652,"mc":[{"id":"1.187557247","rc":[{"batb":[[2,1.02,6409.37]],"ltp":1.05,"tv":60183.96,"id":9304761}]}]}
{"op":"mcm","clk":"4230752585","pt":1631536247649,"mc":[{"id":"1.187557247","rc":[{"batb":[[0,23,61.3],[1,22,30.65],[2,21,30.65]],"ltp":15.5,"tv":72862.75,"id":10350473},{"batl":[[0,1.05,3643.1],[1,1.07,365.56],[2,1.08,2.68]],"ltp":1.05,"tv":60183.96,"id":9304761}]}]}
{"op":"mcm","clk":"4230752665","pt":1631536248537,"mc":[{"id":"1.187557247","rc":[{"batb":[[0,23,20.44],[1,22,10.22],[2,21,10.22]],"batl":[[0,34,6.62],[1,36,2],[2,40,7.35]],"ltp":15.5,"tv":72862.75,"id":10350473},{"batb":[[1,1.03,3809.98]],"batl":[[0,1.05,3656.5]],"ltp":1.05,"tv":60183.96,"id":9304761}]}]}
{"op":"mcm","clk":"4230752759","pt":1631536249634,"mc":[{"id":"1.187557247","rc":[{"batl":[[1,1.07,368.46]],"ltp":1.05,"tv":60183.96,"id":9304761}]}]}
{"op":"mcm","clk":"4230752818","pt":1631536250375,"mc":[{"id":"1.187557247","rc":[{"batl":[[1,1.06,3.07],[2,1.07,372.46]],"ltp":1.05,"tv":60183.96,"id":9304761}]}]}
{"op":"mcm","clk":"4230752940","pt":1631536251676,"mc":[{"id":"1.187557247","rc":[{"batb":[[0,24,10],[1,23,20.44],[2,22,10.22]],"ltp":15.5,"tv":72862.75,"id":10350473},{"batl":[[1,1.06,6.85]],"ltp":1.05,"tv":60183.96,"id":9304761}]}]}
{"op":"mcm","clk":"4230752991","pt":1631536252202,"mc":[{"id":"1.187557247","rc":[{"batb":[[0,24,3.79]],"ltp":15.5,"tv":72862.75,"id":10350473},{"batl":[[2,1.07,6.9]],"ltp":1.05,"tv":60183.96,"id":9304761}]}]}
{"op":"mcm","clk":"4230753461","pt":1631536257556,"mc":[{"id":"1.187557247","rc":[{"trd":[[1.03,871.27],[1.04,12031.17]],"batb":[[0,1.03,3805.85],[1,1.02,6409.37],[2,1.01,15174.55]],"ltp":1.03,"tv":60201.0,"id":9304761}],"tv":133063.75}]}
{"op":"mcm","clk":"4230753511","pt":1631536258081,"mc":[{"id":"1.187557247","rc":[{"batb":[[0,10.5,3],[1,10,2],[2,1.28,720.76]],"batl":[[0,36,2],[1,110,2],[2,40,0]],"ltp":15.5,"tv":72862.75,"id":10350473},{"batb":[[0,1.03,2415.8],[1,1.02,1036.05]],"batl":[[0,1.06,6.85],[1,1.07,2.9],[2,1.08,2.68]],"ltp":1.03,"tv":60201.0,"id":9304761}]}]}
{"op":"mcm","clk":"4230753687","pt":1631536260108,"mc":[{"id":"1.187557247","rc":[{"batb":[[2,1.01,12107.53]],"batl":[[0,1.06,3.07]],"ltp":1.03,"tv":60201.0,"id":9304761}]}]}
{"op":"mcm","clk":"4230753796","pt":1631536261181,"mc":[{"id":"1.187557247","rc":[{"batb":[[1,1.28,720.76],[2,1.2,2]],"ltp":15.5,"tv":72862.75,"id":10350473},{"batb":[[2,1.01,13505.3]],"batl":[[2,1.08,1309.86]],"ltp":1.03,"tv":60201.0,"id":9304761}]}]}
{"op":"mcm","clk":"4230754065","pt":1631536264182,"mc":[{"id":"1.187557247","rc":[{"batb":[[0,13.5,2],[1,13,2],[2,10.5,3]],"ltp":15.5,"tv":72862.75,"id":10350473}]}]}
{"op":"mcm","clk":"4230754160","pt":1631536265472,"mc":[{"id":"1.187557247","rc":[{"batb":[[2,1.01,13605.3]],"ltp":1.03,"tv":60201.0,"id":9304761}]}]}
{"op":"mcm","clk":"4230754227","pt":1631536266207,"mc":[{"id":"1.187557247","rc":[{"batb":[[0,1.03,5.06]],"ltp":1.03,"tv":60201.0,"id":9304761}]}]}
{"op":"mcm","clk":"4230754416","pt":1631536268399,"mc":[{"id":"1.187557247","rc":[{"batl":[[0,1.05,4.09],[1,1.06,3.07],[2,1.07,2.9]],"ltp":1.03,"tv":60201.0,"id":9304761}]}]}
{"op":"mcm","clk":"4230754794","pt":1631536272924,"mc":[{"id":"1.187557247","rc":[{"batb":[[1,1.02,12.05]],"ltp":1.03,"tv":60201.0,"id":9304761}]}]}
{"op":"mcm","clk":"4230754933","pt":1631536274702,"mc":[{"id":"1.187557247","rc":[{"trd":[[1.03,881.4]],"batb":[[0,1.02,12.05],[1,1.01,13605.3],[2,1.01,0]],"ltp":1.03,"tv":60211.12,"id":9304761}],"tv":133073.87}]}
{"op":"mcm","clk":"4230755024","pt":1631536275712,"mc":[{"id":"1.187557247","rc":[{"trd":[[36,4]],"batb":[[0,40,35.26],[1,38,15.63],[2,36,17.63]],"batl":[[0,110,2],[1,120,9.79],[2,130,4.89]],"ltp":36.0,"tv":72866.75,"id":10350473},{"trd":[[1.02,68.73]],"batb":[[0,1.01,13605.3],[1,1.01,0]],"batl":[[0,1.02,1371.75],[1,1.05,4.09],[2,1.06,3.07]],"ltp":1.02,"tv":60235.22,"id":9304761}],"tv":133101.98}]}
{"op":"mcm","clk":"4230755079","pt":1631536276290,"mc":[{"id":"1.187557247","rc":[{"batb":[[2,36,19.63]],"batl":[[1,120,2.45],[2,130,1.22]],"ltp":36.0,"tv":72866.75,"id":10350473},{"batb":[[0,1.01,13625.1]],"batl":[[1,1.03,4],[2,1.05,4.09]],"ltp":1.02,"tv":60235.22,"id":9304761}]}]}
{"op":"mcm","clk":"4230755174","pt":1631536277424,"mc":[{"id":"1.187557247","rc":[{"batb":[[0,1.01,12089.1]],"ltp":1.02,"tv":60235.22,"id":9304761}]}]}
{"op":"mcm","clk":"4230755283","pt":1631536278530,"mc":[{"id":"1.187557247","rc":[{"batb":[[0,50,5],[1,42,2],[2,40,37.26]],"batl":[[0,85,2.62],[1,110,2],[2,120,2.45]],"ltp":36.0,"tv":72866.75,"id":10350473},{"batb":[[0,1.01,12336.62]],"batl":[[2,1.04,59]],"ltp":1.02,"tv":60235.22,"id":9304761}]}]}
{"op":"mcm","clk":"4230755609","pt":1631536281725,"mc":[{"id":"1.187557247","rc":[{"batl":[[0,1.02,1616.85]],"ltp":1.02,"tv":60235.22,"id":9304761}]}]}
{"op":"mcm","clk":"4230756176","pt":1631536288619,"mc":[{"id":"1.187557247","rc":[{"trd":[[1.02,80.65]],"batl":[[0,1.02,1610.89],[2,1.04,63.79]],"ltp":1.02,"tv":60247.14,"id":9304761}],"tv":133113.9}]}
{"op":"mcm","clk":"4230756200","pt":1631536288830,"mc":[{"id":"1.187557247","rc":[{"batl":[[1,1.03,9.04]],"ltp":1.02,"tv":60247.14,"id":9304761}]}]}
