{"op":"mcm","clk":"4230245703","pt":1631530790296,"mc":[{"id":"1.187557146","rc":[{"batl":[[0,1.07,214.81],[1,1.13,14.82],[2,1.15,14.82]],"ltp":1.01,"tv":3141.91,"id":8257797}]}]}
{"op":"mcm","clk":"4230245843","pt":1631530792214,"mc":[{"id":"1.187557146","rc":[{"batl":[[0,26,3.5],[1,34,47.72],[2,990,0.01]],"ltp":100.0,"tv":586.55,"id":19931652},{"batb":[[0,1.02,1076.45],[1,1.01,27.69]],"batl":[[0,1.05,229.5],[1,1.06,606.01],[2,1.07,214.81]],"ltp":1.01,"tv":3141.91,"id":8257797}]}]}
{"op":"mcm","clk":"4230245914","pt":1631530793100,"mc":[{"id":"1.187557146","rc":[{"batb":[[0,13.5,7.45],[1,11.5,11.89],[2,1.47,1.54]],"ltp":100.0,"tv":586.55,"id":19931652},{"batl":[[0,1.05,77.12]],"ltp":1.01,"tv":3141.91,"id":8257797}]}]}
{"op":"mcm","clk":"4230246067","pt":1631530795484,"mc":[{"id":"1.187557146","rc":[{"batb":[[1,1.01,3966.35]],"ltp":1.01,"tv":3141.91,"id":8257797}]}]}
{"op":"mcm","clk":"4230246305","pt":1631530798710,"mc":[{"id":"1.187557146","rc":[{"batb":[[0,1.04,124],[1,1.02,1076.45],[2,1.01,3966.35]],"ltp":1.01,"tv":3141.91,"id":8257797}]}]}
{"op":"mcm","clk":"4230246704","pt":1631530803221,"mc":[{"id":"1.187557146","rc":[{"batl":[[0,990,0.01],[1,34,0],[2,990,0]],"ltp":100.0,"tv":586.55,"id":19931652},{"batl":[[0,1.07,214.81],[1,1.1,50.85],[2,1.12,24.98]],"ltp":1.01,"tv":3141.91,"id":8257797}]}]}
{"op":"mcm","clk":"4230246790","pt":1631530804118,"mc":[{"id":"1.187557146","rc":[{"trd":[[1.66,1.67],[1.72,20.85],[1.76,20.54],[4.1,0.94],[4.5,12.1],[4.6,14.42],[4.7,51.58],[4.8,120.64],[4.9,36.13],[5,50.83],[5.1,23.92],[5.3,2.46],[5.4,3.87],[5.5,8.68],[5.6,29.56],[5.7,20.12],[5.8,15.97],[6.8,0.5],[7.2,11.59]],"batb":[[0,11.5,11.88],[1,1.47,1.54],[2,1.36,766.61]],"ltp":100.0,"tv":586.35,"id":19931652},{"trd":[[1.01,183.29],[1.02,2.89],[1.04,29.99],[1.05,8.52],[1.06,10.88],[1.15,4.66],[1.16,73.82],[1.17,8.74],[1.18,6.34],[1.19,2.17],[1.2,27.94],[1.21,281.45],[1.22,174.15],[1.23,232.45],[1.24,84.66],[1.25,237.03],[1.26,193.23],[1.27,539.98],[1.28,37.62],[1.29,45.84],[1.3,28.21],[1.31,6.74],[1.32,13.25],[1.33,13.57],[1.34,4.36],[1.35,341.41],[1.37,4.34],[1.4,5.1],[1.45,4.34],[1.5,4.34],[1.65,4.34],[2.1,8.8]],"batb":[[0,1.01,3930.94],[1,1.02,0],[2,1.01,0]],"batl":[[0,1.07,214.39],[1,1.13,14.81],[2,1.15,14.81]],"ltp":1.01,"tv":3140.59,"id":8257797}],"tv":3726.95}]}
{"op":"mcm","clk":"4230247782","pt":1631530815641,"mc":[{"id":"1.187557146","rc":[{"batb":[[0,1.06,2.17],[1,1.01,3930.94]],"ltp":1.01,"tv":3140.59,"id":8257797}]}]}
{"op":"mcm","clk":"4230248586","pt":1631530824844,"mc":[{"id":"1.187557146","rc":[{"batl":[[0,160,37.61],[1,990,0.01]],"ltp":100.0,"tv":586.35,"id":19931652}]}]}
{"op":"mcm","clk":"4230248900","pt":1631530829054,"mc":[{"id":"1.187557146","rc":[{"batl":[[0,990,0.01],[1,990,0]],"ltp":100.0,"tv":586.35,"id":19931652}]}]}
{"op":"mcm","clk":"4230248943","pt":1631530829635,"mc":[{"id":"1.187557146","rc":[{"batl":[[1,1.11,11.85],[2,1.13,14.81]],"ltp":1.01,"tv":3140.59,"id":8257797}]}]}
{"op":"mcm","clk":"4230249303","pt":1631530834256,"mc":[{"id":"1.187557146","rc":[{"batl":[[1,1.09,11.85],[2,1.11,11.85]],"ltp":1.01,"tv":3140.59,"id":8257797}]}]}
{"op":"mcm","clk":"4230249696","pt":1631530839346,"mc":[{"id":"1.187557146","rc":[{"batb":[[0,26,12.12],[1,25,1.6],[2,11.5,11.88]],"batl":[[0,50,22.36],[1,990,0.01]],"ltp":100.0,"tv":586.35,"id":19931652},{"batl":[[0,1.03,67.63],[1,1.04,303],[2,1.07,266.55]],"ltp":1.01,"tv":3140.59,"id":8257797}]}]}
{"op":"mcm","clk":"4230249769","pt":1631530840284,"mc":[{"id":"1.187557146","rc":[{"batb":[[2,18.5,6.03]],"ltp":100.0,"tv":586.35,"id":19931652}]}]}
{"op":"mcm","clk":"4230251008","pt":1631530856281,"mc":[{"id":"1.187557146","rc":[{"batl":[[2,1.07,214.39]],"ltp":1.01,"tv":3140.59,"id":8257797}]}]}
{"op":"mcm","clk":"4230251107","pt":1631530857780,"mc":[{"id":"1.187557146","rc":[{"batb":[[0,25,1.6],[1,14,7.2],[2,1.47,1.54]],"batl":[[0,990,0.01],[1,990,0]],"ltp":100.0,"tv":586.35,"id":19931652},{"batl":[[0,1.07,214.39],[1,1.09,11.85],[2,1.11,11.85]],"ltp":1.01,"tv":3140.59,"id":8257797}]}]}
{"op":"mcm","clk":"4230251166","pt":1631530858674,"mc":[{"id":"1.187557146","rc":[{"batl":[[0,1.02,48.54],[1,1.07,214.39],[2,1.09,11.85]],"ltp":1.01,"tv":3140.59,"id":8257797}]}]}
{"op":"mcm","clk":"4230252415","pt":1631530872716,"mc":[{"id":"1.187557146","rc":[{"batl":[[0,1.07,214.39],[1,1.09,11.85],[2,1.11,11.85]],"ltp":1.01,"tv":3140.59,"id":8257797}]}]}
{"op":"mcm","clk":"4230252548","pt":1631530874279,"mc":[{"id":"1.187557146","rc":[{"batb":[[2,11.5,11.38]],"batl":[[0,34,43.4],[1,990,0.01]],"ltp":100.0,"tv":586.35,"id":19931652},{"batb":[[0,1.02,1109.85],[1,1.01,27.63]],"batl":[[0,1.05,42.99],[1,1.06,606.01],[2,1.07,214.39]],"ltp":1.01,"tv":3140.59,"id":8257797}]}]}
{"op":"mcm","clk":"4230252636","pt":1631530875313,"mc":[{"id":"1.187557146","rc":[{"batb":[[1,1.01,3958.57]],"ltp":1.01,"tv":3140.59,"id":8257797}]}]}
{"op":"mcm","clk":"4230253137","pt":1631530881705,"mc":[{"id":"1.187557146","rc":[{"batb":[[0,1.04,320],[1,1.02,1109.85],[2,1.01,3958.57]],"ltp":1.01,"tv":3140.59,"id":8257797}]}]}
{"op":"mcm","clk":"4230253777","pt":1631530890809,"mc":[{"id":"1.187557146","rc":[{"batb":[[1,1.02,1055.13],[2,1.01,3930.94]],"ltp":1.01,"tv":3140.59,"id":8257797}]}]}
{"op":"mcm","clk":"4230254181","pt":1631530896212,"mc":[{"id":"1.187557146","rc":[{"batb":[[0,11.5,11.38],[1,1.47,1.54],[2,1.36,766.61]],"batl":[[0,990,0.01],[1,990,0]],"ltp":100.0,"tv":586.35,"id":19931652},{"batb":[[1,1.01,3930.94],[2,1.01,0]],"batl":[[0,1.07,214.39],[1,1.11,11.85],[2,1.13,14.81]],"ltp":1.01,"tv":3140.59,"id":8257797}]}]}
{"op":"mcm","clk":"4230254193","pt":1631530896416,"mc":[{"id":"1.187557146","rc":[{"batb":[[0,1.01,3930.94],[1,1.01,0]],"ltp":1.01,"tv":3140.59,"id":8257797}]}]}
{"op":"mcm","clk":"4230254855","pt":1631530905053,"mc":[{"id":"1.187557146","rc":[{"batb":[[0,1.02,405.73]],"ltp":1.01,"tv":3140.59,"id":8257797}]}]}
{"op":"mcm","clk":"4230255026","pt":1631530906259,"mc":[{"id":"1.187557146","rc":[{"batb":[[0,28,1.42],[1,26,12.12],[2,18.5,11.72]],"batl":[[0,50,20.7],[1,990,0.01]],"ltp":100.0,"tv":586.35,"id":19931652},{"batl":[[0,1.03,76.19],[1,1.04,303],[2,1.07,266.55]],"ltp":1.01,"tv":3140.59,"id":8257797}]}]}
{"op":"mcm","clk":"4230255093","pt":1631530906842,"mc":[{"id":"1.187557146","rc":[{"trd":[[1.02,7.23]],"batb":[[0,1.02,403.56]],"ltp":1.02,"tv":3144.93,"id":8257797}],"tv":3731.29}]}
{"op":"mcm","clk":"4230255225","pt":1631530908755,"mc":[{"id":"1.187557146","rc":[{"trd":[[1.02,104.31]],"batb":[[0,1.02,355.02]],"ltp":1.02,"tv":3242.01,"id":8257797}],"tv":3828.36}]}
{"op":"mcm","clk":"4230255336","pt":1631530910359,"mc":[{"id":"1.187557146","rc":[{"batl":[[0,50,21.35]],"ltp":100.0,"tv":586.35,"id":19931652},{"batl":[[2,1.05,1236.34]],"ltp":1.02,"tv":3242.01,"id":8257797}]}]}
{"op":"mcm","clk":"4230255350","pt":1631530910568,"mc":[{"id":"1.187557146","rc":[{"batl":[[0,50,20.7]],"ltp":100.0,"tv":586.35,"id":19931652},{"batl":[[2,1.07,266.55]],"ltp":1.02,"tv":3242.01,"id":8257797}]}]}
{"op":"mcm","clk":"4230255670","pt":1631530915169,"mc":[{"id":"1.187557146","rc":[{"batb":[[0,14,7.28],[1,1.47,1.54],[2,1.36,766.61]],"batl":[[0,990,0.01],[1,990,0]],"ltp":100.0,"tv":586.35,"id":19931652},{"batl":[[0,1.07,214.39],[1,1.11,11.85],[2,1.13,14.81]],"ltp":1.02,"tv":3242.01,"id":8257797}]}]}
{"op":"mcm","clk":"4230257238","pt":1631530935261,"mc":[{"id":"1.187557146","rc":[{"batl":[[0,27,7.4],[1,34,41.27],[2,990,0.01]],"ltp":100.0,"tv":586.35,"id":19931652},{"batl":[[0,1.05,46.86],[1,1.06,606.01],[2,1.07,214.39]],"ltp":1.02,"tv":3242.01,"id":8257797}]}]}
{"op":"mcm","clk":"4230257326","pt":1631530936288,"mc":[{"id":"1.187557146","rc":[{"batb":[[1,11.5,11.3],[2,1.47,1.54]],"batl":[[0,27,1.48]],"ltp":100.0,"tv":586.35,"id":19931652},{"batb":[[0,1.02,1090.27],[1,1.01,27.63]],"ltp":1.02,"tv":3242.01,"id":8257797}]}]}
{"op":"mcm","clk":"4230257384","pt":1631530937068,"mc":[{"id":"1.187557146","rc":[{"batb":[[1,1.01,3958.57]],"ltp":1.02,"tv":3242.01,"id":8257797}]}]}
{"op":"mcm","clk":"4230257622","pt":1631530940289,"mc":[{"id":"1.187557146","rc":[{"batl":[[0,27,1.98]],"ltp":100.0,"tv":586.35,"id":19931652},{"batl":[[1,1.06,1439.61]],"ltp":1.02,"tv":3242.01,"id":8257797}]}]}
{"op":"mcm","clk":"4230257638","pt":1631530940495,"mc":[{"id":"1.187557146","rc":[{"batl":[[0,27,1.48]],"ltp":100.0,"tv":586.35,"id":19931652},{"batl":[[1,1.06,606.01]],"ltp":1.02,"tv":3242.01,"id":8257797}]}]}
{"op":"mcm","clk":"4230258561","pt":1631530952216,"mc":[{"id":"1.187557146","rc":[{"batl":[[0,990,0.01],[1,34,0],[2,990,0]],"ltp":100.0,"tv":586.35,"id":19931652},{"batl":[[0,1.07,214.39],[1,1.1,50.74],[2,1.12,24.92]],"ltp":1.02,"tv":3242.01,"id":8257797}]}]}
{"op":"mcm","clk":"4230258591","pt":1631530952490,"mc":[{"id":"1.187557146","rc":[{"batb":[[0,11.5,11.3],[1,1.47,1.54],[2,1.36,766.61]],"ltp":100.0,"tv":586.35,"id":19931652},{"batb":[[0,1.01,3930.94],[1,1.01,0]],"batl":[[1,1.13,14.81],[2,1.15,14.81]],"ltp":1.02,"tv":3242.01,"id":8257797}]}]}
{"op":"mcm","clk":"4230258817","pt":1631530955311,"mc":[{"id":"1.187557146","rc":[{"batb":[[0,1.04,312],[1,1.01,3930.94]],"ltp":1.02,"tv":3242.01,"id":8257797}]}]}
{"op":"mcm","clk":"4230258834","pt":1631530955516,"mc":[{"id":"1.187557146","rc":[{"batb":[[0,1.01,3930.94],[1,1.01,0]],"ltp":1.02,"tv":3242.01,"id":8257797}]}]}
{"op":"mcm","clk":"4230259238","pt":1631530960417,"mc":[{"id":"1.187557146","rc":[{"batl":[[1,1.11,11.85],[2,1.13,14.81]],"ltp":1.02,"tv":3242.01,"id":8257797}]}]}
{"op":"mcm","clk":"4230259569","pt":1631530964038,"mc":[{"id":"1.187557146","rc":[{"batl":[[0,1.02,2.17],[1,1.07,214.39],[2,1.11,11.85]],"ltp":1.02,"tv":3242.01,"id":8257797}]}]}
{"op":"mcm","clk":"4230259996","pt":1631530969314,"mc":[{"id":"1.187557146","rc":[{"batl":[[0,1.07,214.39],[1,1.11,11.85],[2,1.13,14.81]],"ltp":1.02,"tv":3242.01,"id":8257797}]}]}
{"op":"mcm","clk":"4230260748","pt":1631530979231,"mc":[{"id":"1.187557146","rc":[{"batb":[[0,26,12.12],[1,11.5,11.3],[2,1.47,1.54]],"batl":[[0,50,19.09],[1,990,0.01]],"ltp":100.0,"tv":586.35,"id":19931652},{"batl":[[0,1.03,123.36],[1,1.04,303],[2,1.07,266.55]],"ltp":1.02,"tv":3242.01,"id":8257797}]}]}
{"op":"mcm","clk":"4230260819","pt":1631530980266,"mc":[{"id":"1.187557146","rc":[{"batb":[[1,18.5,11.88],[2,14,7.03]],"ltp":100.0,"tv":586.35,"id":19931652},{"trd":[[1.03,4.34]],"batl":[[0,1.03,121.19]],"ltp":1.03,"tv":3246.35,"id":8257797}],"tv":3832.7}]}
{"op":"mcm","clk":"4230260979","pt":1631530981636,"mc":[{"id":"1.187557146","rc":[{"trd":[[50,1.05]],"batl":[[0,50,18.1]],"ltp":50.0,"tv":587.34,"id":19931652},{"trd":[[1.02,152.84]],"ltp":1.02,"tv":3294.88,"id":8257797}],"tv":3882.23}]}
{"op":"mcm","clk":"4230262221","pt":1631530996379,"mc":[{"id":"1.187557146","rc":[{"batl":[[2,1.07,214.39]],"ltp":1.02,"tv":3294.88,"id":8257797}]}]}
{"op":"mcm","clk":"4230262934","pt":1631531004260,"mc":[{"id":"1.187557146","rc":[{"batb":[[0,18.5,11.88],[1,14,7.03],[2,1.47,1.54]],"batl":[[0,990,0.01],[1,990,0]],"ltp":50.0,"tv":587.34,"id":19931652},{"batl":[[0,1.03,36.67],[1,1.07,214.39],[2,1.09,11.85]],"ltp":1.02,"tv":3294.88,"id":8257797}]}]}
{"op":"mcm","clk":"4230262981","pt":1631531004880,"mc":[{"id":"1.187557146","rc":[{"batb":[[0,14,7.03],[1,1.47,1.54],[2,1.36,766.61]],"ltp":50.0,"tv":587.34,"id":19931652},{"batl":[[2,1.11,11.85]],"ltp":1.02,"tv":3294.88,"id":8257797}]}]}
{"op":"mcm","clk":"4230263160","pt":1631531007074,"mc":[{"id":"1.187557146","rc":[{"batl":[[0,1.02,4.26],[1,1.03,36.67],[2,1.07,214.39]],"ltp":1.02,"tv":3294.88,"id":8257797}]}]}
{"op":"mcm","clk":"4230264035","pt":1631531018196,"mc":[{"id":"1.187557146","rc":[{"trd":[[34,1.11],[50,1.14]],"batb":[[0,21,10.82],[1,14,7.03],[2,11.5,11.21]],"batl":[[0,34,36.54],[1,990,0.01]],"ltp":34.0,"tv":588.54,"id":19931652},{"trd":[[1.02,157.1],[1.03,41.01]],"batb":[[0,1.02,1123.15],[1,1.01,27.63]],"batl":[[0,1.05,267.14],[1,1.07,214.39],[2,1.09,51.21]],"ltp":1.03,"tv":3335.81,"id":8257797}],"tv":3924.36}]}
{"op":"mcm","clk":"4230264159","pt":1631531020075,"mc":[{"id":"1.187557146","rc":[{"batl":[[1,160,37.61],[2,990,0.01]],"ltp":34.0,"tv":588.54,"id":19931652}]}]}
{"op":"mcm","clk":"4230264640","pt":1631531026224,"mc":[{"id":"1.187557146","rc":[{"batb":[[0,1.04,305],[1,1.02,1123.15],[2,1.01,27.63]],"ltp":1.03,"tv":3335.81,"id":8257797}]}]}
{"op":"mcm","clk":"4230265103","pt":1631531031278,"mc":[{"id":"1.187557146","rc":[{"batb":[[0,11.5,11.21],[1,1.47,1.54],[2,1.36,766.61]],"batl":[[0,160,37.61],[1,990,0.01],[2,990,0]],"ltp":34.0,"tv":588.54,"id":19931652},{"batb":[[1,1.02,0],[2,1.01,0]],"batl":[[0,1.07,214.39],[1,1.11,11.85],[2,1.13,14.81]],"ltp":1.03,"tv":3335.81,"id":8257797}]}]}
{"op":"mcm","clk":"4230266256","pt":1631531044732,"mc":[{"id":"1.187557146","rc":[{"batb":[[0,1.06,2.17]],"ltp":1.03,"tv":3335.81,"id":8257797}]}]}
{"op":"mcm","clk":"4230266539","pt":1631531048221,"mc":[{"id":"1.187557146","rc":[{"batl":[[1,1.13,14.81],[2,1.15,14.81]],"ltp":1.03,"tv":3335.81,"id":8257797}]}]}
{"op":"mcm","clk":"4230266778","pt":1631531051134,"mc":[{"id":"1.187557146","rc":[{"batl":[[0,1.06,21.29],[1,1.07,214.39],[2,1.13,14.81]],"ltp":1.03,"tv":3335.81,"id":8257797}]}]}
{"op":"mcm","clk":"4230266860","pt":1631531052336,"mc":[{"id":"1.187557146","rc":[{"batl":[[0,990,0.01],[1,990,0]],"ltp":34.0,"tv":588.54,"id":19931652},{"batl":[[0,1.07,214.39],[1,1.13,14.81],[2,1.15,14.81]],"ltp":1.03,"tv":3335.81,"id":8257797}]}]}
{"op":"mcm","clk":"4230266925","pt":1631531053014,"mc":[{"id":"1.187557146","rc":[{"trd":[[16.5,3.12]],"batl":[[0,16.5,1.21],[1,21,4.42],[2,26,24.21]],"ltp":16.5,"tv":591.66,"id":19931652},{"trd":[[1.06,59.5]],"batb":[[0,1.04,605.22],[1,1.03,54.19],[2,1.01,27.63]],"batl":[[0,1.07,909.95],[1,1.11,50.28],[2,1.13,39.51]],"ltp":1.06,"tv":3384.43,"id":8257797}],"tv":3976.1}]}
{"op":"mcm","clk":"4230266987","pt":1631531053842,"mc":[{"id":"1.187557146","rc":[{"batb":[[1,10.5,15.06],[2,1.47,1.54]],"ltp":16.5,"tv":591.66,"id":19931652},{"batb":[[1,1.03,858.36],[2,1.02,1076.8]],"ltp":1.06,"tv":3384.43,"id":8257797}]}]}
{"op":"mcm","clk":"4230267147","pt":1631531056034,"mc":[{"id":"1.187557146","rc":[{"batb":[[1,1.03,900.95]],"ltp":1.06,"tv":3384.43,"id":8257797}]}]}
{"op":"mcm","clk":"4230267250","pt":1631531057236,"mc":[{"id":"1.187557146","rc":[{"batb":[[0,1.06,158],[1,1.04,605.22],[2,1.03,900.95]],"ltp":1.06,"tv":3384.43,"id":8257797}]}]}
{"op":"mcm","clk":"4230267638","pt":1631531061359,"mc":[{"id":"1.187557146","rc":[{"batb":[[1,1.05,405.73],[2,1.04,605.22]],"batl":[[1,1.08,21.29],[2,1.09,63.88]],"ltp":1.06,"tv":3384.43,"id":8257797}]}]}
{"op":"mcm","clk":"4230267783","pt":1631531063171,"mc":[{"id":"1.187557146","rc":[{"batl":[[1,26,24.21],[2,990,0.01]],"ltp":16.5,"tv":591.66,"id":19931652}]}]}
{"op":"mcm","clk":"4230267997","pt":1631531065961,"mc":[{"id":"1.187557146","rc":[{"batl":[[1,21,3.43],[2,26,24.21]],"ltp":16.5,"tv":591.66,"id":19931652},{"batb":[[1,1.05,474.43]],"batl":[[0,1.07,1008.1]],"ltp":1.06,"tv":3384.43,"id":8257797}]}]}
{"op":"mcm","clk":"4230268081","pt":1631531067222,"mc":[{"id":"1.187557146","rc":[{"trd":[[1.06,239.82]],"batb":[[0,1.06,67.84]],"ltp":1.06,"tv":3564.75,"id":8257797}],"tv":4156.42}]}
{"op":"mcm","clk":"4230268328","pt":1631531070262,"mc":[{"id":"1.187557146","rc":[{"batb":[[0,10.5,15.06],[1,1.47,1.54],[2,1.36,766.61]],"batl":[[0,990,0.01],[1,21,0],[2,26,0]],"ltp":16.5,"tv":591.66,"id":19931652},{"batb":[[0,1.05,405.73],[1,1.03,42.59],[2,1.02,1076.8]],"batl":[[0,1.07,214.39]],"ltp":1.06,"tv":3564.75,"id":8257797}]}]}
{"op":"mcm","clk":"4230268537","pt":1631531072658,"mc":[{"id":"1.187557146","rc":[{"batb":[[0,1.03,42.59],[1,1.02,1076.8],[2,1.01,4122.58]],"ltp":1.06,"tv":3564.75,"id":8257797}]}]}
{"op":"mcm","clk":"4230268731","pt":1631531075068,"mc":[{"id":"1.187557146","rc":[{"batb":[[0,1.03,448.32]],"ltp":1.06,"tv":3564.75,"id":8257797}]}]}
{"op":"mcm","clk":"4230270019","pt":1631531090776,"mc":[{"id":"1.187557146","rc":[{"batl":[[1,1.09,63.88],[2,1.13,14.81]],"ltp":1.06,"tv":3564.75,"id":8257797}]}]}
{"op":"mcm","clk":"4230270359","pt":1631531095285,"mc":[{"id":"1.187557146","rc":[{"batb":[[2,1.01,0]],"ltp":1.06,"tv":3564.75,"id":8257797}]}]}
{"op":"mcm","clk":"4230270443","pt":1631531096258,"mc":[{"id":"1.187557146","rc":[{"batl":[[0,26,3.95],[1,34,36.45],[2,990,0.01]],"ltp":16.5,"tv":591.66,"id":19931652},{"batb":[[1,1.02,1131.52],[2,1.01,27.63]],"batl":[[0,1.05,68.03],[1,1.07,909.95],[2,1.09,115.09]],"ltp":1.06,"tv":3564.75,"id":8257797}]}]}
{"op":"mcm","clk":"4230270531","pt":1631531097285,"mc":[{"id":"1.187557146","rc":[{"batb":[[0,14,6.95],[1,12,10.79],[2,1.47,1.54]],"ltp":16.5,"tv":591.66,"id":19931652}]}]}
{"op":"mcm","clk":"4230270595","pt":1631531098066,"mc":[{"id":"1.187557146","rc":[{"batl":[[1,1.06,42.59],[2,1.07,909.95]],"ltp":1.06,"tv":3564.75,"id":8257797}]}]}
{"op":"mcm","clk":"4230270685","pt":1631531099100,"mc":[{"id":"1.187557146","rc":[{"batl":[[2,160,37.61]],"ltp":16.5,"tv":591.66,"id":19931652},{"batl":[[1,1.06,127.77]],"ltp":1.06,"tv":3564.75,"id":8257797}]}]}
{"op":"mcm","clk":"4230271162","pt":1631531104207,"mc":[{"id":"1.187557146","rc":[{"batb":[[0,1.04,148],[1,1.03,448.32],[2,1.02,1131.52]],"ltp":1.06,"tv":3564.75,"id":8257797}]}]}
{"op":"mcm","clk":"4230272010","pt":1631531113286,"mc":[{"id":"1.187557146","rc":[{"batb":[[2,1.02,1076.8]],"ltp":1.06,"tv":3564.75,"id":8257797}]}]}
{"op":"mcm","clk":"4230272864","pt":1631531122106,"mc":[{"id":"1.187557146","rc":[{"batl":[[0,160,37.61],[1,990,0.01],[2,160,0]],"ltp":16.5,"tv":591.66,"id":19931652},{"batl":[[0,1.06,127.77],[1,1.07,214.39],[2,1.09,63.88]],"ltp":1.06,"tv":3564.75,"id":8257797}]}]}
{"op":"mcm","clk":"4230272958","pt":1631531123202,"mc":[{"id":"1.187557146","rc":[{"batb":[[0,12,10.79],[1,1.47,1.54],[2,1.36,766.61]],"ltp":16.5,"tv":591.66,"id":19931652},{"batb":[[0,1.03,448.32],[1,1.03,0],[2,1.02,0]],"ltp":1.06,"tv":3564.75,"id":8257797}]}]}
{"op":"mcm","clk":"4230273732","pt":1631531132055,"mc":[{"id":"1.187557146","rc":[{"batb":[[0,1.03,42.59]],"ltp":1.06,"tv":3564.75,"id":8257797}]}]}
{"op":"mcm","clk":"4230274015","pt":1631531135112,"mc":[{"id":"1.187557146","rc":[{"batb":[[1,1.02,405.73]],"ltp":1.06,"tv":3564.75,"id":8257797}]}]}
{"op":"mcm","clk":"4230275192","pt":1631531149138,"mc":[{"id":"1.187557146","rc":[{"batl":[[0,990,0.01],[1,990,0]],"ltp":16.5,"tv":591.66,"id":19931652}]}]}
{"op":"mcm","clk":"4230275250","pt":1631531149762,"mc":[{"id":"1.187557146","rc":[{"batl":[[0,1.07,214.39],[1,1.09,63.88],[2,1.13,14.81]],"ltp":1.06,"tv":3564.75,"id":8257797}]}]}
{"op":"mcm","clk":"4230275416","pt":1631531151340,"mc":[{"id":"1.187557146","rc":[{"trd":[[16.5,27.36]],"batb":[[0,17.5,7.49],[1,12,10.79],[2,10.5,14.64]],"batl":[[0,21,6.42],[1,26,22.95],[2,990,0.01]],"ltp":16.5,"tv":615.9,"id":19931652},{"batb":[[0,1.04,573.66],[1,1.03,920.36],[2,1.02,1509.73]],"batl":[[0,1.07,319.03],[2,1.11,50.28]],"ltp":1.06,"tv":3564.75,"id":8257797}],"tv":4180.66}]}
{"op":"mcm","clk":"4230275924","pt":1631531156667,"mc":[{"id":"1.187557146","rc":[{"batb":[[0,1.05,62],[1,1.04,573.66],[2,1.03,920.36]],"ltp":1.06,"tv":3564.75,"id":8257797}]}]}
{"op":"mcm","clk":"4230276123","pt":1631531158693,"mc":[{"id":"1.187557146","rc":[{"trd":[[17.5,25.38]],"batb":[[0,17.5,5.08]],"ltp":17.5,"tv":618.31,"id":19931652},{"trd":[[1.07,687.93]],"batl":[[0,1.09,63.88],[1,1.11,50.28],[2,1.13,39.51]],"ltp":1.07,"tv":4242.24,"id":8257797}],"tv":4860.55}]}
{"op":"mcm","clk":"4230276241","pt":1631531159893,"mc":[{"id":"1.187557146","rc":[{"batb":[[0,1.05,467.73]],"ltp":1.07,"tv":4242.24,"id":8257797}]}]}
{"op":"mcm","clk":"4230276925","pt":1631531167718,"mc":[{"id":"1.187557146","rc":[{"batb":[[2,1.03,866.17]],"batl":[[1,1.13,14.81],[2,1.15,14.81]],"ltp":1.07,"tv":4242.24,"id":8257797}]}]}
{"op":"mcm","clk":"4230277048","pt":1631531168874,"mc":[{"id":"1.187557146","rc":[{"batl":[[0,26,22.95],[1,990,0.01],[2,990,0]],"ltp":17.5,"tv":618.31,"id":19931652}]}]}
{"op":"mcm","clk":"4230277336","pt":1631531171905,"mc":[{"id":"1.187557146","rc":[{"trd":[[17.5,35.54]],"batb":[[0,12,10.79],[1,10.5,14.64],[2,1.47,1.54]],"batl":[[0,26,23.39]],"ltp":17.5,"tv":628.47,"id":19931652},{"batl":[[0,1.08,36.72],[1,1.09,63.88],[2,1.13,14.81]],"ltp":1.07,"tv":4242.24,"id":8257797}],"tv":4870.71}]}
{"op":"mcm","clk":"4230277919","pt":1631531178276,"mc":[{"id":"1.187557146","rc":[{"batb":[[0,10.5,14.64],[1,1.47,1.54],[2,1.36,766.61]],"batl":[[0,990,0.01],[1,990,0]],"ltp":17.5,"tv":628.47,"id":19931652},{"batb":[[0,1.05,405.73],[1,1.03,42.59],[2,1.02,1509.73]],"batl":[[0,1.09,63.88],[1,1.13,14.81],[2,1.15,14.81]],"ltp":1.07,"tv":4242.24,"id":8257797}]}]}
{"op":"mcm","clk":"4230279001","pt":1631531190249,"mc":[{"id":"1.187557146","rc":[{"batl":[[0,1.13,14.81],[1,1.15,14.81],[2,1.17,29.62]],"ltp":1.07,"tv":4242.24,"id":8257797}]}]}
{"op":"mcm","clk":"4230279156","pt":1631531192034,"mc":[{"id":"1.187557146","rc":[{"batb":[[0,13.5,15.36],[1,10.5,14.64],[2,1.47,1.54]],"batl":[[0,17.5,7.61],[1,19,2.1],[2,990,0.01]],"ltp":17.5,"tv":628.47,"id":19931652},{"batb":[[0,1.06,290.18],[1,1.05,405.73],[2,1.04,53.67]],"batl":[[0,1.08,224.76],[1,1.12,49.84],[2,1.13,14.81]],"ltp":1.07,"tv":4242.24,"id":8257797}]}]}
{"op":"mcm","clk":"4230279241","pt":1631531192805,"mc":[{"id":"1.187557146","rc":[{"batb":[[2,7.8,13.22]],"ltp":17.5,"tv":628.47,"id":19931652},{"batb":[[2,1.04,742.44]],"ltp":1.07,"tv":4242.24,"id":8257797}]}]}
{"op":"mcm","clk":"4230279424","pt":1631531195044,"mc":[{"id":"1.187557146","rc":[{"batb":[[0,1.07,405.73],[1,1.06,290.18],[2,1.05,405.73]],"ltp":1.07,"tv":4242.24,"id":8257797}]}]}
{"op":"mcm","clk":"4230279693","pt":1631531197851,"mc":[{"id":"1.187557146","rc":[{"batb":[[0,1.07,522.73]],"ltp":1.07,"tv":4242.24,"id":8257797}]}]}
{"op":"mcm","clk":"4230279901","pt":1631531200031,"mc":[{"id":"1.187557146","rc":[{"trd":[[13.5,8.32]],"batb":[[0,13.5,7.04]],"ltp":13.5,"tv":636.79,"id":19931652},{"trd":[[1.08,557.44]],"batl":[[0,1.12,49.84],[1,1.13,14.81],[2,1.14,24.48]],"ltp":1.08,"tv":4795.68,"id":8257797}],"tv":5432.47}]}
{"op":"mcm","clk":"4230280872","pt":1631531210255,"mc":[{"id":"1.187557146","rc":[{"batl":[[0,19,2.1],[1,990,0.01],[2,990,0]],"ltp":13.5,"tv":636.79,"id":19931652}]}]}
{"op":"mcm","clk":"4230281175","pt":1631531213140,"mc":[{"id":"1.187557146","rc":[{"batl":[[0,1.08,16.35],[1,1.12,49.84],[2,1.13,14.81]],"ltp":1.08,"tv":4795.68,"id":8257797}]}]}
{"op":"mcm","clk":"4230281865","pt":1631531219931,"mc":[{"id":"1.187557146","rc":[{"trd":[[1.08,559.42]],"batl":[[0,1.08,15.36]],"ltp":1.08,"tv":4797.66,"id":8257797}],"tv":5434.45}]}
{"op":"mcm","clk":"4230282012","pt":1631531221350,"mc":[{"id":"1.187557146","rc":[{"trd":[[13.5,15.36]],"batb":[[0,10.5,14.64],[1,7.8,13.22],[2,1.47,1.54]],"ltp":13.5,"tv":643.83,"id":19931652},{"trd":[[1.08,678.14]],"batl":[[0,1.12,49.84],[1,1.13,14.81],[2,1.14,24.48]],"ltp":1.08,"tv":4916.38,"id":8257797}],"tv":5560.22}]}
{"op":"mcm","clk":"4230283396","pt":1631531236180,"mc":[{"id":"1.187557146","rc":[{"batl":[[0,15,3.97],[1,19,2.1],[2,990,0.01]],"ltp":13.5,"tv":643.83,"id":19931652},{"batl":[[0,1.09,82.94],[1,1.12,49.84],[2,1.13,14.81]],"ltp":1.08,"tv":4916.38,"id":8257797}]}]}
{"op":"mcm","clk":"4230286806","pt":1631531279032,"mc":[{"id":"1.187557146","rc":[{"batl":[[1,1.13,14.81],[2,1.15,14.81]],"ltp":1.08,"tv":4916.38,"id":8257797}]}]}
{"op":"mcm","clk":"4230288882","pt":1631531304275,"mc":[{"id":"1.187557146","rc":[{"batb":[[0,7.8,13.22],[1,1.47,1.54],[2,1.36,766.61]],"batl":[[0,19,1.05],[1,990,0.01],[2,990,0]],"ltp":13.5,"tv":643.83,"id":19931652},{"batb":[[0,1.07,405.73],[1,1.05,405.73],[2,1.02,1391.32]],"batl":[[0,1.13,14.81],[1,1.15,14.81],[2,1.17,29.62]],"ltp":1.08,"tv":4916.38,"id":8257797}]}]}
{"op":"mcm","clk":"4230288905","pt":1631531304482,"mc":[{"id":"1.187557146","rc":[{"batl":[[0,990,0.01],[1,990,0]],"ltp":13.5,"tv":643.83,"id":19931652}]}]}
{"op":"mcm","clk":"4230289769","pt":1631531315310,"mc":[{"id":"1.187557146","rc":[{"batl":[[0,10,3.84],[1,12,54.02],[2,990,0.01]],"ltp":13.5,"tv":643.83,"id":19931652},{"batb":[[0,1.1,36.36],[1,1.07,457.89],[2,1.05,432.31]],"batl":[[0,1.16,48.12],[1,1.18,23.65],[2,1.23,29.62]],"ltp":1.08,"tv":4916.38,"id":8257797}]}]}
{"op":"mcm","clk":"4230289859","pt":1631531316299,"mc":[{"id":"1.187557146","rc":[{"batb":[[1,5.6,30.13],[2,1.47,1.54]],"ltp":13.5,"tv":643.83,"id":19931652},{"batb":[[1,1.08,419.32],[2,1.07,457.89]],"ltp":1.08,"tv":4916.38,"id":8257797}]}]}
{"op":"mcm","clk":"4230290107","pt":1631531319311,"mc":[{"id":"1.187557146","rc":[{"batb":[[0,1.11,405.73],[1,1.1,36.36],[2,1.08,419.32]],"ltp":1.08,"tv":4916.38,"id":8257797}]}]}
{"op":"mcm","clk":"4230290169","pt":1631531320092,"mc":[{"id":"1.187557146","rc":[{"trd":[[10,3.84]],"batl":[[0,12,54.02],[1,990,0.01],[2,990,0]],"ltp":10.0,"tv":647.67,"id":19931652},{"trd":[[1.11,846.04]],"batb":[[0,1.1,36.36],[1,1.08,419.32],[2,1.07,457.89]],"ltp":1.11,"tv":5762.42,"id":8257797}],"tv":6410.09}]}
{"op":"mcm","clk":"4230290338","pt":1631531322223,"mc":[{"id":"1.187557146","rc":[{"batl":[[0,990,0.01],[1,990,0]],"ltp":10.0,"tv":647.67,"id":19931652},{"batb":[[0,1.08,419.32],[1,1.07,405.73],[2,1.05,1007.89]],"batl":[[0,1.23,29.62],[1,1.25,14.81],[2,1.3,1241.76]],"ltp":1.11,"tv":5762.42,"id":8257797}]}]}
{"op":"mcm","clk":"4230290360","pt":1631531322536,"mc":[{"id":"1.187557146","rc":[{"batb":[[0,5.6,30.13],[1,1.47,1.54],[2,1.36,766.61]],"ltp":10.0,"tv":647.67,"id":19931652},{"batb":[[0,1.07,405.73],[1,1.05,1007.89],[2,1.03,1593.57]],"ltp":1.11,"tv":5762.42,"id":8257797}]}]}
{"op":"mcm","clk":"4230290600","pt":1631531325196,"mc":[{"id":"1.187557146","rc":[{"batb":[[0,6.8,2],[1,6.2,2],[2,5.6,30.13]],"batl":[[0,15.5,2],[1,990,0.01]],"ltp":10.0,"tv":647.67,"id":19931652},{"batb":[[0,1.07,775.8]],"batl":[[0,1.17,138.5],[1,1.18,131.25],[2,1.19,131.5]],"ltp":1.11,"tv":5762.42,"id":8257797}]}]}
{"op":"mcm","clk":"4230290629","pt":1631531325515,"mc":[{"id":"1.187557146","rc":[{"batb":[[0,6.2,2],[1,5.6,30.13],[2,1.47,1.54]],"ltp":10.0,"tv":647.67,"id":19931652},{"batl":[[0,1.19,131.5],[1,1.23,29.62],[2,1.25,14.81]],"ltp":1.11,"tv":5762.42,"id":8257797}]}]}
{"op":"mcm","clk":"4230291810","pt":1631531340026,"mc":[{"id":"1.187557146","rc":[{"batb":[[2,1.02,405.73]],"ltp":1.11,"tv":5762.42,"id":8257797}]}]}
{"op":"mcm","clk":"4230291965","pt":1631531341845,"mc":[{"id":"1.187557146","rc":[{"batl":[[0,7.2,4.45],[1,8.4,4.76],[2,11,108.17]],"ltp":10.0,"tv":647.67,"id":19931652},{"batb":[[0,1.12,49.84],[1,1.1,1107.06],[2,1.07,775.8]],"batl":[[0,1.18,38.26],[1,1.19,131.5],[2,1.21,46.13]],"ltp":1.11,"tv":5762.42,"id":8257797}]}]}
{"op":"mcm","clk":"4230292069","pt":1631531342846,"mc":[{"id":"1.187557146","rc":[{"batb":[[2,4.2,30.13]],"ltp":10.0,"tv":647.67,"id":19931652},{"batb":[[0,1.14,253.13],[1,1.12,49.84],[2,1.1,1454]],"ltp":1.11,"tv":5762.42,"id":8257797}]}]}
{"op":"mcm","clk":"4230292372","pt":1631531346246,"mc":[{"id":"1.187557146","rc":[{"batb":[[1,1.13,405.73],[2,1.12,49.84]],"ltp":1.11,"tv":5762.42,"id":8257797}]}]}
{"op":"mcm","clk":"4230292421","pt":1631531346761,"mc":[{"id":"1.187557146","rc":[{"trd":[[7.2,16.04]],"batl":[[0,8.4,4.76],[1,11,108.17],[2,15.5,2]],"ltp":7.2,"tv":652.12,"id":19931652},{"trd":[[1.16,101.45]],"ltp":1.16,"tv":5790.05,"id":8257797}],"tv":6442.17}]}
{"op":"mcm","clk":"4230292643","pt":1631531349052,"mc":[{"id":"1.187557146","rc":[{"batb":[[2,4.7,2.22]],"batl":[[1,9.4,2],[2,11,110.17]],"ltp":7.2,"tv":652.12,"id":19931652},{"batb":[[2,1.12,246.63]],"ltp":1.16,"tv":5790.05,"id":8257797}]}]}
{"op":"mcm","clk":"4230293041","pt":1631531354349,"mc":[{"id":"1.187557146","rc":[{"batb":[[0,4.7,2.22],[1,4.2,32.75],[2,1.47,1.54]],"batl":[[0,9.4,2],[1,11,2],[2,15.5,2]],"ltp":7.2,"tv":652.12,"id":19931652},{"batb":[[0,1.13,405.73],[1,1.12,196.79],[2,1.11,228.59]],"batl":[[0,1.27,82.5],[1,1.29,81.5],[2,1.3,1241.76]],"ltp":1.16,"tv":5790.05,"id":8257797}]}]}
{"op":"mcm","clk":"4230293071","pt":1631531354658,"mc":[{"id":"1.187557146","rc":[{"batb":[[0,4.2,32.75],[1,1.47,1.54],[2,1.36,766.61]],"ltp":7.2,"tv":652.12,"id":19931652},{"batl":[[0,1.3,1241.76],[1,1.31,82.5],[2,1.39,17.78]],"ltp":1.16,"tv":5790.05,"id":8257797}]}]}
{"op":"mcm","clk":"4230293379","pt":1631531357952,"mc":[{"id":"1.187557146","rc":[{"batb":[[0,4.7,2.22],[1,4.2,32.75],[2,1.47,1.54]],"ltp":7.2,"tv":652.12,"id":19931652},{"batl":[[0,1.27,82.5],[1,1.3,1241.76],[2,1.31,82.5]],"ltp":1.16,"tv":5790.05,"id":8257797}]}]}
{"op":"mcm","clk":"4230293412","pt":1631531358371,"mc":[{"id":"1.187557146","rc":[{"batb":[[0,4.2,32.75],[1,1.47,1.54],[2,1.36,766.61]],"ltp":7.2,"tv":652.12,"id":19931652},{"batl":[[0,1.3,1241.76],[1,1.31,82.5],[2,1.39,17.78]],"ltp":1.16,"tv":5790.05,"id":8257797}]}]}
{"op":"mcm","clk":"4230293685","pt":1631531361179,"mc":[{"id":"1.187557146","rc":[{"batl":[[0,1.29,89.5],[1,1.3,1241.76],[2,1.31,82.5]],"ltp":1.16,"tv":5790.05,"id":8257797}]}]}
{"op":"mcm","clk":"4230293743","pt":1631531361766,"mc":[{"id":"1.187557146","rc":[{"batl":[[0,1.3,1241.76],[1,1.31,82.5],[2,1.39,17.78]],"ltp":1.16,"tv":5790.05,"id":8257797}]}]}
{"op":"mcm","clk":"4230293982","pt":1631531364265,"mc":[{"id":"1.187557146","rc":[{"batb":[[0,1.16,21.29],[1,1.15,405.73],[2,1.12,196.79]],"ltp":1.16,"tv":5790.05,"id":8257797}]}]}
{"op":"mcm","clk":"4230294077","pt":1631531365260,"mc":[{"id":"1.187557146","rc":[{"batb":[[0,1.16,106.47]],"ltp":1.16,"tv":5790.05,"id":8257797}]}]}
{"op":"mcm","clk":"4230294423","pt":1631531369175,"mc":[{"id":"1.187557146","rc":[{"batl":[[0,1.28,21.29],[1,1.3,1241.76],[2,1.31,82.5]],"ltp":1.16,"tv":5790.05,"id":8257797}]}]}
{"op":"mcm","clk":"4230294524","pt":1631531370271,"mc":[{"id":"1.187557146","rc":[{"batl":[[0,1.28,127.77]],"ltp":1.16,"tv":5790.05,"id":8257797}]}]}
{"op":"mcm","clk":"4230294893","pt":1631531375263,"mc":[{"id":"1.187557146","rc":[{"batb":[[0,4.7,2.22],[1,4.2,32.75],[2,1.47,1.54]],"ltp":7.2,"tv":652.12,"id":19931652},{"batl":[[0,1.27,87.5],[1,1.28,127.77],[2,1.3,1241.76]],"ltp":1.16,"tv":5790.05,"id":8257797}]}]}
{"op":"mcm","clk":"4230294916","pt":1631531375573,"mc":[{"id":"1.187557146","rc":[{"batb":[[0,4.2,32.75],[1,1.47,1.54],[2,1.36,766.61]],"ltp":7.2,"tv":652.12,"id":19931652},{"batl":[[0,1.28,127.77],[1,1.3,1241.76],[2,1.31,82.5]],"ltp":1.16,"tv":5790.05,"id":8257797}]}]}
{"op":"mcm","clk":"4230295375","pt":1631531382182,"mc":[{"id":"1.187557146","rc":[{"batb":[[0,4.7,2.42],[1,4.2,32.75],[2,1.47,1.54]],"ltp":7.2,"tv":652.12,"id":19931652},{"batl":[[0,1.27,106.5],[1,1.28,127.77],[2,1.3,1241.76]],"ltp":1.16,"tv":5790.05,"id":8257797}]}]}
{"op":"mcm","clk":"4230295393","pt":1631531382390,"mc":[{"id":"1.187557146","rc":[{"batb":[[0,4.2,32.75],[1,1.47,1.54],[2,1.36,766.61]],"ltp":7.2,"tv":652.12,"id":19931652},{"batl":[[0,1.28,127.77],[1,1.3,1241.76],[2,1.31,82.5]],"ltp":1.16,"tv":5790.05,"id":8257797}]}]}
{"op":"mcm","clk":"4230295955","pt":1631531389305,"mc":[{"id":"1.187557146","rc":[{"batb":[[0,1.15,405.73],[1,1.12,196.79],[2,1.11,228.59]],"ltp":1.16,"tv":5790.05,"id":8257797}]}]}
{"op":"mcm","clk":"4230296119","pt":1631531391185,"mc":[{"id":"1.187557146","rc":[{"batb":[[0,7.4,5.4],[1,4.2,32.75],[2,1.47,1.54]],"batl":[[0,10,46.57]],"ltp":7.2,"tv":652.12,"id":19931652},{"batb":[[0,1.12,19.18],[1,1.1,568.28],[2,1.09,51.21]],"batl":[[0,1.13,32.14],[1,1.18,47.3],[2,1.2,23.26]],"ltp":1.16,"tv":5790.05,"id":8257797}]}]}
{"op":"mcm","clk":"4230296204","pt":1631531392218,"mc":[{"id":"1.187557146","rc":[{"batb":[[1,6.8,18.08],[2,4.8,21.92]],"ltp":7.2,"tv":652.12,"id":19931652}]}]}
{"op":"mcm","clk":"4230296280","pt":1631531393103,"mc":[{"id":"1.187557146","rc":[{"batl":[[2,1.19,63.88]],"ltp":1.16,"tv":5790.05,"id":8257797}]}]}
{"op":"mcm","clk":"4230296320","pt":1631531393625,"mc":[{"id":"1.187557146","rc":[{"batb":[[1,1.11,405.73],[2,1.1,568.28]],"batl":[[2,1.19,85.18]],"ltp":1.16,"tv":5790.05,"id":8257797}]}]}
{"op":"mcm","clk":"4230296543","pt":1631531396121,"mc":[{"id":"1.187557146","rc":[{"trd":[[1.12,38.36]],"batb":[[0,1.11,405.73],[1,1.1,568.28],[2,1.09,51.21]],"ltp":1.12,"tv":5828.41,"id":8257797}],"tv":6480.53}]}
{"op":"mcm","clk":"4230296693","pt":1631531397991,"mc":[{"id":"1.187557146","rc":[{"batb":[[2,5,2.01]],"batl":[[2,12.5,2]],"ltp":7.2,"tv":652.12,"id":19931652},{"batb":[[2,1.09,323.82]],"ltp":1.12,"tv":5828.41,"id":8257797}]}]}
{"op":"mcm","clk":"4230296776","pt":1631531399133,"mc":[{"id":"1.187557146","rc":[{"batb":[[0,1.11,554.73]],"ltp":1.12,"tv":5828.41,"id":8257797}]}]}
{"op":"mcm","clk":"4230297392","pt":1631531406232,"mc":[{"id":"1.187557146","rc":[{"batb":[[0,1.11,405.73]],"batl":[[0,1.18,47.3],[1,1.19,85.18],[2,1.2,23.26]],"ltp":1.12,"tv":5828.41,"id":8257797}]}]}
{"op":"mcm","clk":"4230297631","pt":1631531409042,"mc":[{"id":"1.187557146","rc":[{"batl":[[0,10,52.48]],"ltp":7.2,"tv":652.12,"id":19931652},{"batl":[[0,1.13,51.18],[1,1.18,47.3],[2,1.19,85.18]],"ltp":1.12,"tv":5828.41,"id":8257797}]}]}
{"op":"mcm","clk":"4230297755","pt":1631531410343,"mc":[{"id":"1.187557146","rc":[{"batb":[[0,6.8,18.08],[1,5,2.01],[2,4.8,21.92]],"ltp":7.2,"tv":652.12,"id":19931652}]}]}
{"op":"mcm","clk":"4230297844","pt":1631531411231,"mc":[{"id":"1.187557146","rc":[{"batb":[[0,4.8,21.92],[1,4.4,2.76],[2,4.2,2.62]],"batl":[[0,12.5,2],[1,13.5,2],[2,15.5,2]],"ltp":7.2,"tv":652.12,"id":19931652},{"batb":[[1,1.09,272.61],[2,1.08,324.81]],"batl":[[0,1.19,85.18],[1,1.28,127.77],[2,1.29,88.5]],"ltp":1.12,"tv":5828.41,"id":8257797}]}]}
{"op":"mcm","clk":"4230298656","pt":1631531420649,"mc":[{"id":"1.187557146","rc":[{"batl":[[0,13.5,2],[1,15.5,2],[2,18,2]],"ltp":7.2,"tv":652.12,"id":19931652},{"batb":[[1,1.08,324.81],[2,1.07,370.07]],"ltp":1.12,"tv":5828.41,"id":8257797}]}]}
{"op":"mcm","clk":"4230298777","pt":1631531422060,"mc":[{"id":"1.187557146","rc":[{"batb":[[0,1.08,324.81],[1,1.07,370.07],[2,1.06,938.79]],"ltp":1.12,"tv":5828.41,"id":8257797}]}]}
{"op":"mcm","clk":"4230298874","pt":1631531423150,"mc":[{"id":"1.187557146","rc":[{"batb":[[0,9.8,20.4],[1,4.8,21.92],[2,4.4,2.76]],"batl":[[1,15,53.16],[2,15.5,2]],"ltp":7.2,"tv":652.12,"id":19931652},{"batl":[[0,1.09,58.94],[1,1.19,85.18],[2,1.28,127.77]],"ltp":1.12,"tv":5828.41,"id":8257797}]}]}
{"op":"mcm","clk":"4230298971","pt":1631531424343,"mc":[{"id":"1.187557146","rc":[{"batb":[[0,9.8,4.08],[1,9,22.68],[2,5.8,27.36]],"ltp":7.2,"tv":652.12,"id":19931652},{"batl":[[1,1.14,48.96],[2,1.16,24.06]],"ltp":1.12,"tv":5828.41,"id":8257797}]}]}
{"op":"mcm","clk":"4230299135","pt":1631531426346,"mc":[{"id":"1.187557146","rc":[{"batb":[[0,1.08,730.54]],"batl":[[1,1.14,134.14]],"ltp":1.12,"tv":5828.41,"id":8257797}]}]}
{"op":"mcm","clk":"4230299291","pt":1631531428268,"mc":[{"id":"1.187557146","rc":[{"batb":[[0,1.08,847.54]],"batl":[[0,1.09,583.62]],"ltp":1.12,"tv":5828.41,"id":8257797}]}]}
{"op":"mcm","clk":"4230299376","pt":1631531429159,"mc":[{"id":"1.187557146","rc":[{"batl":[[0,1.09,58.94]],"ltp":1.12,"tv":5828.41,"id":8257797}]}]}
{"op":"mcm","clk":"4230299455","pt":1631531429945,"mc":[{"id":"1.187557146","rc":[{"batb":[[2,6,2.04]],"ltp":7.2,"tv":652.12,"id":19931652}]}]}
{"op":"mcm","clk":"4230300056","pt":1631531437282,"mc":[{"id":"1.187557146","rc":[{"batb":[[0,9,22.68],[1,6,2.04],[2,5.8,27.36]],"batl":[[0,21,2],[1,36,2],[2,990,0.01]],"ltp":7.2,"tv":652.12,"id":19931652},{"batb":[[0,1.08,405.73],[1,1.06,533.21],[2,1.05,527.65]],"batl":[[0,1.14,134.14],[1,1.16,24.06],[2,1.2,122.03]],"ltp":1.12,"tv":5828.41,"id":8257797}]}]}
{"op":"mcm","clk":"4230300159","pt":1631531438269,"mc":[{"id":"1.187557146","rc":[{"batb":[[0,5.8,27.36],[1,5.1,2.04],[2,4.4,2.76]],"batl":[[0,21,2.45]],"ltp":7.2,"tv":652.12,"id":19931652},{"batb":[[1,1.05,474.49],[2,1.04,539.12]],"batl":[[0,1.14,85.18],[1,1.22,112.75],[2,1.23,29.64]],"ltp":1.12,"tv":5828.41,"id":8257797}]}]}
{"op":"mcm","clk":"4230300563","pt":1631531443297,"mc":[{"id":"1.187557146","rc":[{"batb":[[0,1.09,106.47],[1,1.08,405.73],[2,1.05,474.49]],"ltp":1.12,"tv":5828.41,"id":8257797}]}]}
{"op":"mcm","clk":"4230300588","pt":1631531443559,"mc":[{"id":"1.187557146","rc":[{"batb":[[2,1.47,1.54]],"ltp":7.2,"tv":652.12,"id":19931652},{"batb":[[0,1.09,127.77]],"ltp":1.12,"tv":5828.41,"id":8257797}]}]}
{"op":"mcm","clk":"4230300720","pt":1631531444699,"mc":[{"id":"1.187557146","rc":[{"batb":[[1,1.05,474.49],[2,1.04,539.12]],"ltp":1.12,"tv":5828.41,"id":8257797}]}]}
{"op":"mcm","clk":"4230300873","pt":1631531446105,"mc":[{"id":"1.187557146","rc":[{"trd":[[12,4.1],[12.5,11.14]],"batb":[[0,15.5,1.31],[1,5.8,27.36],[2,5.1,2.04]],"batl":[[0,21,2],[1,26,22.28],[2,36,2]],"ltp":12.5,"tv":664.16,"id":19931652},{"trd":[[1.09,343.35]],"batb":[[0,1.05,474.49],[1,1.04,942.25],[2,1.03,1673.86]],"batl":[[0,1.06,132.03],[1,1.14,85.18],[2,1.22,112.75]],"ltp":1.09,"tv":5956.18,"id":8257797}],"tv":6620.34}]}
{"op":"mcm","clk":"4230300982","pt":1631531447261,"mc":[{"id":"1.187557146","rc":[{"batb":[[0,15.5,1.29],[1,13,8.7],[2,8.4,26.44]],"ltp":12.5,"tv":664.16,"id":19931652},{"batl":[[1,1.1,50.74],[2,1.12,24.92]],"ltp":1.09,"tv":5956.18,"id":8257797}]}]}
{"op":"mcm","clk":"4230301131","pt":1631531449274,"mc":[{"id":"1.187557146","rc":[{"batb":[[2,12.5,7.44]],"ltp":12.5,"tv":664.16,"id":19931652},{"trd":[[1.06,261.3]],"batb":[[0,1.05,880.22]],"batl":[[0,1.06,121.29]],"ltp":1.06,"tv":5977.66,"id":8257797}],"tv":6641.82}]}
{"op":"mcm","clk":"4230301166","pt":1631531449684,"mc":[{"id":"1.187557146","rc":[{"batb":[[2,12.5,13.74]],"ltp":12.5,"tv":664.16,"id":19931652}]}]}
{"op":"mcm","clk":"4230301292","pt":1631531451303,"mc":[{"id":"1.187557146","rc":[{"batb":[[2,12.5,2.61]],"ltp":12.5,"tv":664.16,"id":19931652}]}]}
{"op":"mcm","clk":"4230301317","pt":1631531451671,"mc":[{"id":"1.187557146","rc":[{"batb":[[2,8.4,26.44]],"ltp":12.5,"tv":664.16,"id":19931652},{"batl":[[1,1.07,130.15],[2,1.1,50.74]],"ltp":1.06,"tv":5977.66,"id":8257797}]}]}
{"op":"mcm","clk":"4230301382","pt":1631531452593,"mc":[{"id":"1.187557146","rc":[{"batb":[[2,12,2]],"ltp":12.5,"tv":664.16,"id":19931652},{"batl":[[2,1.09,307.5]],"ltp":1.06,"tv":5977.66,"id":8257797}]}]}
{"op":"mcm","clk":"4230301614","pt":1631531455182,"mc":[{"id":"1.187557146","rc":[{"batb":[[0,1.05,1053.22]],"ltp":1.06,"tv":5977.66,"id":8257797}]}]}
{"op":"mcm","clk":"4230301947","pt":1631531459776,"mc":[{"id":"1.187557146","rc":[{"batl":[[1,26,16.13]],"ltp":12.5,"tv":664.16,"id":19931652},{"batb":[[0,1.05,880.22]],"batl":[[0,1.07,130.15],[1,1.09,307.5],[2,1.1,295.99]],"ltp":1.06,"tv":5977.66,"id":8257797}]}]}
{"op":"mcm","clk":"4230302042","pt":1631531461122,"mc":[{"id":"1.187557146","rc":[{"batb":[[0,12,2],[1,10,2],[2,8.4,26.44]],"batl":[[0,36,2],[1,55,2],[2,990,0.01]],"ltp":12.5,"tv":664.16,"id":19931652},{"batb":[[0,1.05,405.73],[1,1.03,742.83],[2,1.02,1228.01]],"batl":[[2,1.1,245.25]],"ltp":1.06,"tv":5977.66,"id":8257797}]}]}
{"op":"mcm","clk":"4230302287","pt":1631531464291,"mc":[{"id":"1.187557146","rc":[{"batb":[[0,1.06,187.39],[1,1.05,405.73],[2,1.03,742.83]],"ltp":1.06,"tv":5977.66,"id":8257797}]}]}
{"op":"mcm","clk":"4230302303","pt":1631531464496,"mc":[{"id":"1.187557146","rc":[{"batb":[[0,1.06,234.24]],"ltp":1.06,"tv":5977.66,"id":8257797}]}]}
{"op":"mcm","clk":"4230302576","pt":1631531468228,"mc":[{"id":"1.187557146","rc":[{"batb":[[0,1.06,358.24]],"ltp":1.06,"tv":5977.66,"id":8257797}]}]}
{"op":"mcm","clk":"4230302776","pt":1631531470614,"mc":[{"id":"1.187557146","rc":[{"batb":[[0,10,2],[1,8.4,26.44],[2,5.1,2.04]],"ltp":12.5,"tv":664.16,"id":19931652},{"trd":[[1.07,948.24]],"batb":[[0,1.07,275.58],[1,1.06,234.24],[2,1.05,405.73]],"batl":[[0,1.11,205.5],[1,1.17,29.64],[2,1.19,14.83]],"ltp":1.07,"tv":6237.96,"id":8257797}],"tv":6902.13}]}
{"op":"mcm","clk":"4230302890","pt":1631531472018,"mc":[{"id":"1.187557146","rc":[{"batb":[[2,1.03,742.83]],"ltp":1.07,"tv":6237.96,"id":8257797}]}]}
{"op":"mcm","clk":"4230302946","pt":1631531472743,"mc":[{"id":"1.187557146","rc":[{"batb":[[0,1.06,234.24],[1,1.03,742.83],[2,1.02,1228.01]],"ltp":1.07,"tv":6237.96,"id":8257797}]}]}
{"op":"mcm","clk":"4230303171","pt":1631531475238,"mc":[{"id":"1.187557146","rc":[{"batl":[[0,1.1,46.85],[1,1.11,205.5],[2,1.17,29.64]],"ltp":1.07,"tv":6237.96,"id":8257797}]}]}
{"op":"mcm","clk":"4230303225","pt":1631531475823,"mc":[{"id":"1.187557146","rc":[{"batl":[[0,1.1,140.55]],"ltp":1.07,"tv":6237.96,"id":8257797}]}]}
{"op":"mcm","clk":"4230303332","pt":1631531477214,"mc":[{"id":"1.187557146","rc":[{"batb":[[0,12,2],[1,10,2],[2,8.4,26.44]],"ltp":12.5,"tv":664.16,"id":19931652},{"batl":[[0,1.09,278.5],[1,1.1,391.7]],"ltp":1.07,"tv":6237.96,"id":8257797}]}]}
{"op":"mcm","clk":"4230303388","pt":1631531477836,"mc":[{"id":"1.187557146","rc":[{"batb":[[0,1.03,742.83],[1,1.02,1228.01],[2,1.01,2265.59]],"ltp":1.07,"tv":6237.96,"id":8257797}]}]}
{"op":"mcm","clk":"4230303568","pt":1631531479934,"mc":[{"id":"1.187557146","rc":[{"batb":[[0,18.5,2.16],[1,12,2],[2,10,2]],"batl":[[1,50,43.2],[2,55,2]],"ltp":12.5,"tv":664.16,"id":19931652},{"batl":[[0,1.04,83.22],[1,1.07,52.16],[2,1.09,304.1]],"ltp":1.07,"tv":6237.96,"id":8257797}]}]}
{"op":"mcm","clk":"4230303690","pt":1631531481340,"mc":[{"id":"1.187557146","rc":[{"batb":[[1,18,6.86],[2,16,9.46]],"ltp":12.5,"tv":664.16,"id":19931652},{"batl":[[1,1.05,46.85],[2,1.07,52.16]],"ltp":1.07,"tv":6237.96,"id":8257797}]}]}
{"op":"mcm","clk":"4230303749","pt":1631531482029,"mc":[{"id":"1.187557146","rc":[{"batl":[[1,1.05,234.24]],"ltp":1.07,"tv":6237.96,"id":8257797}]}]}
{"op":"mcm","clk":"4230303832","pt":1631531482962,"mc":[{"id":"1.187557146","rc":[{"batb":[[0,1.03,1148.56]],"ltp":1.07,"tv":6237.96,"id":8257797}]}]}
{"op":"mcm","clk":"4230304104","pt":1631531486236,"mc":[{"id":"1.187557146","rc":[{"batb":[[0,21,2],[1,18.5,2.16],[2,18,6.86]],"ltp":12.5,"tv":664.16,"id":19931652},{"batl":[[1,1.05,812.94],[2,1.06,390.75]],"ltp":1.07,"tv":6237.96,"id":8257797}]}]}
{"op":"mcm","clk":"4230304190","pt":1631531487232,"mc":[{"id":"1.187557146","rc":[{"batb":[[0,1.03,1242.25]],"ltp":1.07,"tv":6237.96,"id":8257797}]}]}
{"op":"mcm","clk":"4230305289","pt":1631531501046,"mc":[{"id":"1.187557146","rc":[{"trd":[[1.03,2184.41]],"batb":[[0,1.03,170.55]],"ltp":1.03,"tv":8381.36,"id":8257797}],"tv":9045.53}]}
{"op":"mcm","clk":"4230305718","pt":1631531505949,"mc":[{"id":"1.187557146","rc":[{"trd":[[1.04,66.07]],"batl":[[0,1.04,65.18]],"ltp":1.04,"tv":8417.44,"id":8257797}],"tv":9081.61}]}
{"op":"mcm","clk":"4230306637","pt":1631531516190,"mc":[{"id":"1.187557146","rc":[{"batl":[[1,50,36.07]],"ltp":12.5,"tv":664.16,"id":19931652},{"batl":[[0,1.05,812.94],[1,1.06,390.75],[2,1.07,351.66]],"ltp":1.04,"tv":8417.44,"id":8257797}]}]}
{"op":"mcm","clk":"4230306712","pt":1631531516770,"mc":[{"id":"1.187557146","rc":[{"batl":[[2,1.07,299.5]],"ltp":1.04,"tv":8417.44,"id":8257797}]}]}
{"op":"mcm","clk":"4230306945","pt":1631531519053,"mc":[{"id":"1.187557146","rc":[{"batl":[[1,50,43.58]],"ltp":12.5,"tv":664.16,"id":19931652},{"batl":[[0,1.04,74.2],[1,1.05,812.94],[2,1.06,390.75]],"ltp":1.04,"tv":8417.44,"id":8257797}]}]}
{"op":"mcm","clk":"4230307390","pt":1631531522879,"mc":[{"id":"1.187557146","rc":[{"trd":[[1.03,2218.11]],"batb":[[0,1.03,153.7]],"ltp":1.03,"tv":8451.15,"id":8257797}],"tv":9115.31}]}
{"op":"mcm","clk":"4230308027","pt":1631531528880,"mc":[{"id":"1.187557146","rc":[{"trd":[[1.04,66.42]],"batl":[[0,1.04,74.03]],"ltp":1.04,"tv":8451.49,"id":8257797}],"tv":9115.65}]}
{"op":"mcm","clk":"4230308249","pt":1631531531209,"mc":[{"id":"1.187557146","rc":[{"batb":[[1,18,6.86],[2,17.5,2]],"batl":[[0,55,2],[1,110,2],[2,990,0.01]],"ltp":12.5,"tv":664.16,"id":19931652},{"batl":[[0,1.05,812.94],[1,1.06,390.75],[2,1.07,299.5]],"ltp":1.04,"tv":8451.49,"id":8257797}]}]}
{"op":"mcm","clk":"4230308286","pt":1631531531475,"mc":[{"id":"1.187557146","rc":[{"batb":[[1,17.5,2],[2,16,9.46]],"ltp":12.5,"tv":664.16,"id":19931652}]}]}
{"op":"mcm","clk":"4230308655","pt":1631531536008,"mc":[{"id":"1.187557146","rc":[{"batb":[[0,1.04,90.16],[1,1.03,153.7],[2,1.02,1228.01]],"ltp":1.04,"tv":8451.49,"id":8257797}]}]}
{"op":"mcm","clk":"4230309038","pt":1631531540277,"mc":[{"id":"1.187557146","rc":[{"batl":[[0,1.05,816.94]],"ltp":1.04,"tv":8451.49,"id":8257797}]}]}
{"op":"mcm","clk":"4230309046","pt":1631531540385,"mc":[{"id":"1.187557146","rc":[{"batl":[[0,1.05,812.94]],"ltp":1.04,"tv":8451.49,"id":8257797}]}]}
{"op":"mcm","clk":"4230309218","pt":1631531542210,"mc":[{"id":"1.187557146","rc":[{"trd":[[1.04,151.18]],"batb":[[0,1.03,153.7],[1,1.02,1228.01],[2,1.01,2265.59]],"batl":[[0,1.05,859.79]],"ltp":1.04,"tv":8536.25,"id":8257797}],"tv":9200.41}]}
{"op":"mcm","clk":"4230309260","pt":1631531542680,"mc":[{"id":"1.187557146","rc":[{"batl":[[0,1.04,93.7],[1,1.05,859.79],[2,1.06,390.75]],"ltp":1.04,"tv":8536.25,"id":8257797}]}]}
{"op":"mcm","clk":"4230309570","pt":1631531546484,"mc":[{"id":"1.187557146","rc":[{"batl":[[0,1.04,93.74]],"ltp":1.04,"tv":8536.25,"id":8257797}]}]}
{"op":"mcm","clk":"4230309916","pt":1631531550315,"mc":[{"id":"1.187557146","rc":[{"batb":[[0,17.5,2],[1,16,9.46],[2,1.47,1.54]],"ltp":12.5,"tv":664.16,"id":19931652},{"batb":[[0,1.03,60.01]],"batl":[[1,1.05,281.09],[2,1.13,14.83]],"ltp":1.04,"tv":8536.25,"id":8257797}]}]}
{"op":"mcm","clk":"4230310060","pt":1631531551987,"mc":[{"id":"1.187557146","rc":[{"batb":[[0,34,4.49],[1,21,9.52],[2,17.5,2]],"ltp":12.5,"tv":664.16,"id":19931652},{"trd":[[1.03,2338.13]],"batb":[[0,1.02,1682.07],[1,1.01,2265.59],[2,1.01,0]],"batl":[[0,1.03,542.36],[1,1.04,93.74],[2,1.05,281.09]],"ltp":1.03,"tv":8656.27,"id":8257797}],"tv":9320.43}]}
{"op":"mcm","clk":"4230310190","pt":1631531553286,"mc":[{"id":"1.187557146","rc":[{"batb":[[1,21,13.26],[2,18.5,6.28]],"ltp":12.5,"tv":664.16,"id":19931652}]}]}
{"op":"mcm","clk":"4230310286","pt":1631531554227,"mc":[{"id":"1.187557146","rc":[{"batl":[[0,1.03,776.6],[1,1.04,93.7],[2,1.06,52.66]],"ltp":1.03,"tv":8656.27,"id":8257797}]}]}
{"op":"mcm","clk":"4230310375","pt":1631531555322,"mc":[{"id":"1.187557146","rc":[{"batb":[[1,21,9.45]],"ltp":12.5,"tv":664.16,"id":19931652}]}]}
{"op":"mcm","clk":"4230310738","pt":1631531559294,"mc":[{"id":"1.187557146","rc":[{"batb":[[1,26,2],[2,21,11.45]],"ltp":12.5,"tv":664.16,"id":19931652},{"batl":[[1,1.04,747.83],[2,1.05,449.9]],"ltp":1.03,"tv":8656.27,"id":8257797}]}]}
{"op":"mcm","clk":"4230310959","pt":1631531561894,"mc":[{"id":"1.187557146","rc":[{"batl":[[0,1.03,683.74]],"ltp":1.03,"tv":8656.27,"id":8257797}]}]}
{"op":"mcm","clk":"4230311226","pt":1631531564909,"mc":[{"id":"1.187557146","rc":[{"batl":[[0,1.03,776.6]],"ltp":1.03,"tv":8656.27,"id":8257797}]}]}
{"op":"mcm","clk":"4230311349","pt":1631531566318,"mc":[{"id":"1.187557146","rc":[{"trd":[[1.02,157.19]],"batb":[[0,1.02,1682.03]],"ltp":1.02,"tv":8656.35,"id":8257797}],"tv":9320.51}]}
{"op":"mcm","clk":"4230311614","pt":1631531569035,"mc":[{"id":"1.187557146","rc":[{"trd":[[1.02,471.77]],"batb":[[0,1.02,1524.74]],"ltp":1.02,"tv":8970.93,"id":8257797}],"tv":9635.09}]}
{"op":"mcm","clk":"4230311870","pt":1631531571954,"mc":[{"id":"1.187557146","rc":[{"batb":[[0,26,2],[1,21,2],[2,18.5,6.28]],"batl":[[0,990,0.01],[1,110,0],[2,990,0]],"ltp":12.5,"tv":664.16,"id":19931652},{"batl":[[0,1.03,234.24]],"ltp":1.02,"tv":8970.93,"id":8257797}]}]}
{"op":"mcm","clk":"4230312311","pt":1631531577110,"mc":[{"id":"1.187557146","rc":[{"batl":[[0,1.02,18.04],[1,1.03,234.24],[2,1.04,747.83]],"ltp":1.02,"tv":8970.93,"id":8257797}]}]}
{"op":"mcm","clk":"4230313094","pt":1631531585146,"mc":[{"id":"1.187557146","rc":[{"batl":[[2,1.04,654.13]],"ltp":1.02,"tv":8970.93,"id":8257797}]}]}
{"op":"mcm","clk":"4230313391","pt":1631531588222,"mc":[{"id":"1.187557146","rc":[{"batl":[[0,1.02,111.74]],"ltp":1.02,"tv":8970.93,"id":8257797}]}]}
{"op":"mcm","clk":"4230314164","pt":1631531597166,"mc":[{"id":"1.187557146","rc":[{"batb":[[0,30,6.66],[1,26,2],[2,21,2]],"batl":[[0,100,14.89],[1,990,0.01]],"ltp":12.5,"tv":664.16,"id":19931652},{"batl":[[0,1.02,4005.22],[1,1.04,654.13],[2,1.09,11.86]],"ltp":1.02,"tv":8970.93,"id":8257797}]}]}
{"op":"mcm","clk":"4230314241","pt":1631531598055,"mc":[{"id":"1.187557146","rc":[{"batb":[[0,50,4.58],[1,30,1.34],[2,27,4.68]],"ltp":12.5,"tv":664.16,"id":19931652},{"batl":[[0,1.02,910.47],[2,1.05,53.16]],"ltp":1.02,"tv":8970.93,"id":8257797}]}]}
{"op":"mcm","clk":"4230314441","pt":1631531600090,"mc":[{"id":"1.187557146","rc":[{"trd":[[100,3.96]],"batl":[[0,100,12.54]],"ltp":100.0,"tv":666.51,"id":19931652},{"trd":[[1.01,417.54]],"ltp":1.01,"tv":9205.17,"id":8257797}],"tv":9871.68}]}
{"op":"mcm","clk":"4230314843","pt":1631531604544,"mc":[{"id":"1.187557146","rc":[{"batb":[[1,34,2],[2,30,1.34]],"ltp":100.0,"tv":666.51,"id":19931652},{"batl":[[1,1.03,826.5],[2,1.04,654.13]],"ltp":1.01,"tv":9205.17,"id":8257797}]}]}
{"op":"mcm","clk":"4230315177","pt":1631531608236,"mc":[{"id":"1.187557146","rc":[{"trd":[[100,4]],"batl":[[0,100,12.5]],"ltp":100.0,"tv":666.55,"id":19931652},{"trd":[[1.01,421.15]],"ltp":1.01,"tv":9208.79,"id":8257797}],"tv":9875.34}]}
{"op":"mcm","clk":"4230315227","pt":1631531608858,"mc":[{"id":"1.187557146","rc":[{"batb":[[0,1.01,405.73]],"ltp":1.01,"tv":9208.79,"id":8257797}]}]}
{"op":"mcm","clk":"4230315349","pt":1631531610149,"mc":[{"id":"1.187557146","rc":[{"trd":[[1.01,438.19]],"batb":[[0,1.01,397.21]],"ltp":1.01,"tv":9225.82,"id":8257797}],"tv":9892.38}]}
{"op":"mcm","clk":"4230315906","pt":1631531617270,"mc":[{"id":"1.187557146","rc":[{"batb":[[0,34,2],[1,27,4.68],[2,26,2]],"batl":[[0,990,0.01],[1,990,0]],"ltp":100.0,"tv":666.55,"id":19931652},{"batl":[[0,1.02,111.74]],"ltp":1.01,"tv":9225.82,"id":8257797}]}]}
{"op":"mcm","clk":"4230316002","pt":1631531618184,"mc":[{"id":"1.187557146","rc":[{"batb":[[1,26,2],[2,23,5.05]],"ltp":100.0,"tv":666.55,"id":19931652},{"trd":[[1.01,455.23]],"batb":[[0,1.01,388.69]],"ltp":1.01,"tv":9242.86,"id":8257797}],"tv":9909.42}]}
{"op":"mcm","clk":"4230317097","pt":1631531631296,"mc":[{"id":"1.187557146","rc":[{"batl":[[0,1.02,196.92]],"ltp":1.01,"tv":9242.86,"id":8257797}]}]}
{"op":"mcm","clk":"4230317116","pt":1631531631496,"mc":[{"id":"1.187557146","rc":[{"batl":[[0,1.02,282.09]],"ltp":1.01,"tv":9242.86,"id":8257797}]}]}
{"op":"mcm","clk":"4230317231","pt":1631531632802,"mc":[{"id":"1.187557146","rc":[{"batl":[[0,100,34.87],[1,990,0.01]],"ltp":100.0,"tv":666.55,"id":19931652},{"batl":[[1,1.03,1219.91]],"ltp":1.01,"tv":9242.86,"id":8257797}]}]}
{"op":"mcm","clk":"4230317565","pt":1631531637277,"mc":[{"id":"1.187557146","rc":[{"batb":[[0,1.01,644.23]],"ltp":1.01,"tv":9242.86,"id":8257797}]}]}
{"op":"mcm","clk":"4230318066","pt":1631531644118,"mc":[{"id":"1.187557146","rc":[{"batb":[[0,26,2],[1,21,2],[2,18.5,11.63]],"batl":[[0,990,0.01],[1,990,0]],"ltp":100.0,"tv":666.55,"id":19931652},{"batl":[[1,1.04,654.13],[2,1.05,480.5]],"ltp":1.01,"tv":9242.86,"id":8257797}]}]}
{"op":"mcm","clk":"4230318652","pt":1631531650903,"mc":[{"id":"1.187557146","rc":[{"batb":[[0,21,2],[1,18.5,11.63],[2,1.47,1.54]],"ltp":100.0,"tv":666.55,"id":19931652},{"trd":[[1.02,1035.96]],"batl":[[0,1.05,480.5],[1,1.06,392.25],[2,1.09,11.86]],"ltp":1.02,"tv":9807.06,"id":8257797}],"tv":10473.61}]}
{"op":"mcm","clk":"4230318814","pt":1631531653126,"mc":[{"id":"1.187557146","rc":[{"batl":[[0,1.02,18.75],[1,1.05,480.5],[2,1.06,392.25]],"ltp":1.02,"tv":9807.06,"id":8257797}]}]}
{"op":"mcm","clk":"4230318886","pt":1631531654213,"mc":[{"id":"1.187557146","rc":[{"batl":[[0,1.05,480.5],[1,1.06,392.25],[2,1.09,11.86]],"ltp":1.02,"tv":9807.06,"id":8257797}]}]}
{"op":"mcm","clk":"4230318977","pt":1631531655299,"mc":[{"id":"1.187557146","rc":[{"batl":[[0,50,5],[1,990,0.01]],"ltp":100.0,"tv":666.55,"id":19931652}]}]}
{"op":"mcm","clk":"4230319054","pt":1631531656291,"mc":[{"id":"1.187557146","rc":[{"batb":[[0,1.01,473.87]],"ltp":1.02,"tv":9807.06,"id":8257797}]}]}
{"op":"mcm","clk":"4230319073","pt":1631531656502,"mc":[{"id":"1.187557146","rc":[{"batb":[[0,1.01,644.23]],"ltp":1.02,"tv":9807.06,"id":8257797}]}]}
{"op":"mcm","clk":"4230319197","pt":1631531658006,"mc":[{"id":"1.187557146","rc":[{"batl":[[0,990,0.01],[1,990,0]],"ltp":100.0,"tv":666.55,"id":19931652}]}]}
{"op":"mcm","clk":"4230319431","pt":1631531661323,"mc":[{"id":"1.187557146","rc":[{"batb":[[0,1.01,814.58]],"ltp":1.02,"tv":9807.06,"id":8257797}]}]}
{"op":"mcm","clk":"4230319465","pt":1631531661737,"mc":[{"id":"1.187557146","rc":[{"batb":[[0,1.01,984.94]],"ltp":1.02,"tv":9807.06,"id":8257797}]}]}
{"op":"mcm","clk":"4230319563","pt":1631531663004,"mc":[{"id":"1.187557146","rc":[{"batl":[[0,1.03,340.72],[1,1.05,480.5],[2,1.06,392.25]],"ltp":1.02,"tv":9807.06,"id":8257797}]}]}
{"op":"mcm","clk":"4230319739","pt":1631531665037,"mc":[{"id":"1.187557146","rc":[{"batb":[[0,26,2],[1,21,2],[2,18.5,11.63]],"ltp":100.0,"tv":666.55,"id":19931652},{"batb":[[0,1.01,899.76]],"batl":[[1,1.04,597.13],[2,1.05,480.5]],"ltp":1.02,"tv":9807.06,"id":8257797}]}]}
{"op":"mcm","clk":"4230319849","pt":1631531666333,"mc":[{"id":"1.187557146","rc":[{"batb":[[0,1.01,729.4]],"ltp":1.02,"tv":9807.06,"id":8257797}]}]}
{"op":"mcm","clk":"4230320245","pt":1631531671233,"mc":[{"id":"1.187557146","rc":[{"batb":[[0,26,6.73]],"batl":[[0,50,23.87],[1,990,0.01]],"ltp":100.0,"tv":666.55,"id":19931652},{"batb":[[0,1.03,33.44],[1,1.01,729.4]],"batl":[[0,1.04,781.52],[1,1.05,480.5],[2,1.06,392.25]],"ltp":1.02,"tv":9807.06,"id":8257797}]}]}
{"op":"mcm","clk":"4230320413","pt":1631531673312,"mc":[{"id":"1.187557146","rc":[{"batb":[[1,1.02,255.54],[2,1.01,729.4]],"ltp":1.02,"tv":9807.06,"id":8257797}]}]}
{"op":"mcm","clk":"4230320564","pt":1631531675240,"mc":[{"id":"1.187557146","rc":[{"batb":[[0,21,2],[1,18.5,11.63],[2,16,9.54]],"batl":[[0,990,0.01],[1,990,0]],"ltp":100.0,"tv":666.55,"id":19931652},{"batb":[[0,1.02,340.72],[1,1.01,729.4],[2,1.01,0]],"batl":[[0,1.04,597.13]],"ltp":1.02,"tv":9807.06,"id":8257797}]}]}
{"op":"mcm","clk":"4230320646","pt":1631531676023,"mc":[{"id":"1.187557146","rc":[{"batb":[[0,16,9.54],[1,1.47,1.54],[2,1.36,766.61]],"ltp":100.0,"tv":666.55,"id":19931652},{"batb":[[0,1.02,425.89]],"batl":[[0,1.06,392.25],[1,1.11,11.86],[2,1.13,14.83]],"ltp":1.02,"tv":9807.06,"id":8257797}]}]}
{"op":"mcm","clk":"4230320822","pt":1631531678326,"mc":[{"id":"1.187557146","rc":[{"batb":[[0,17.5,2.02],[1,16,9.54],[2,1.47,1.54]],"ltp":100.0,"tv":666.55,"id":19931652}]}]}
{"op":"mcm","clk":"4230321043","pt":1631531680922,"mc":[{"id":"1.187557146","rc":[{"batb":[[0,1.04,1.93],[1,1.02,425.89],[2,1.01,729.4]],"ltp":1.02,"tv":9807.06,"id":8257797}]}]}
{"op":"mcm","clk":"4230321150","pt":1631531682216,"mc":[{"id":"1.187557146","rc":[{"batb":[[0,21,2],[1,17.5,2.02],[2,16,9.54]],"ltp":100.0,"tv":666.55,"id":19931652},{"batl":[[0,1.05,475.5],[1,1.06,392.25],[2,1.07,386.5]],"ltp":1.02,"tv":9807.06,"id":8257797}]}]}
{"op":"mcm","clk":"4230321166","pt":1631531682424,"mc":[{"id":"1.187557146","rc":[{"batb":[[0,17.5,2.02],[1,16,9.54],[2,1.47,1.54]],"ltp":100.0,"tv":666.55,"id":19931652},{"batl":[[0,1.06,392.25],[1,1.11,11.86],[2,1.13,14.83]],"ltp":1.02,"tv":9807.06,"id":8257797}]}]}
{"op":"mcm","clk":"4230321299","pt":1631531684238,"mc":[{"id":"1.187557146","rc":[{"batb":[[0,1.02,425.89],[1,1.01,729.4],[2,1.01,0]],"ltp":1.02,"tv":9807.06,"id":8257797}]}]}
{"op":"mcm","clk":"4230321564","pt":1631531687243,"mc":[{"id":"1.187557146","rc":[{"batl":[[0,1.04,85.18],[1,1.06,392.25],[2,1.09,11.88]],"ltp":1.02,"tv":9807.06,"id":8257797}]}]}
{"op":"mcm","clk":"4230321656","pt":1631531688334,"mc":[{"id":"1.187557146","rc":[{"batl":[[0,1.03,136],[1,1.04,340.72],[2,1.06,392.25]],"ltp":1.02,"tv":9807.06,"id":8257797}]}]}
{"op":"mcm","clk":"4230321724","pt":1631531689264,"mc":[{"id":"1.187557146","rc":[{"batb":[[0,21,2.2],[1,17.5,2.02],[2,16,9.54]],"ltp":100.0,"tv":666.55,"id":19931652},{"batl":[[2,1.05,453.1]],"ltp":1.02,"tv":9807.06,"id":8257797}]}]}
{"op":"mcm","clk":"4230322259","pt":1631531695962,"mc":[{"id":"1.187557146","rc":[{"batl":[[1,1.05,453.1],[2,1.06,392.25]],"ltp":1.02,"tv":9807.06,"id":8257797}]}]}
{"op":"mcm","clk":"4230322374","pt":1631531697158,"mc":[{"id":"1.187557146","rc":[{"trd":[[34,5.23]],"batb":[[0,21,8.12]],"batl":[[0,34,21.59],[1,36,1.12],[2,990,0.01]],"ltp":34.0,"tv":670.67,"id":19931652},{"trd":[[1.03,2474.13]],"batb":[[0,1.03,1.93],[1,1.02,425.89],[2,1.01,812.3]],"batl":[[0,1.05,623.9],[1,1.06,392.25],[2,1.07,385.5]],"ltp":1.03,"tv":9943.06,"id":8257797}],"tv":10613.73}]}
{"op":"mcm","clk":"4230322530","pt":1631531699283,"mc":[{"id":"1.187557146","rc":[{"batb":[[0,1.03,87.11]],"ltp":1.03,"tv":9943.06,"id":8257797}]}]}
{"op":"mcm","clk":"4230322610","pt":1631531700265,"mc":[{"id":"1.187557146","rc":[{"batb":[[0,21,5.92]],"batl":[[2,520,36.01]],"ltp":34.0,"tv":670.67,"id":19931652},{"batb":[[0,1.03,513.01]],"ltp":1.03,"tv":9943.06,"id":8257797}]}]}
{"op":"mcm","clk":"4230322803","pt":1631531702352,"mc":[{"id":"1.187557146","rc":[{"batl":[[0,1.04,340.72],[1,1.05,623.9],[2,1.06,392.25]],"ltp":1.03,"tv":9943.06,"id":8257797}]}]}
{"op":"mcm","clk":"4230323238","pt":1631531707258,"mc":[{"id":"1.187557146","rc":[{"trd":[[26,1.45]],"batl":[[0,34,18.66]],"ltp":26.0,"tv":672.12,"id":19931652},{"trd":[[1.04,187.34]],"batl":[[0,1.04,304.56],[1,1.05,571.43]],"ltp":1.04,"tv":9979.22,"id":8257797}],"tv":10651.34}]}
{"op":"mcm","clk":"4230323426","pt":1631531709185,"mc":[{"id":"1.187557146","rc":[{"batb":[[0,17.5,2.02],[1,14,13.47],[2,1.47,1.54]],"batl":[[0,520,36.01],[1,990,0.01],[2,520,0]],"ltp":26.0,"tv":672.12,"id":19931652},{"batb":[[2,1.01,729.4]],"batl":[[1,1.11,11.86],[2,1.13,14.83]],"ltp":1.04,"tv":9979.22,"id":8257797}]}]}
{"op":"mcm","clk":"4230324147","pt":1631531717695,"mc":[{"id":"1.187557146","rc":[{"trd":[[1.04,187.59]],"batl":[[0,1.04,304.43]],"ltp":1.04,"tv":9979.47,"id":8257797}],"tv":10651.59}]}
{"op":"mcm","clk":"4230324453","pt":1631531721278,"mc":[{"id":"1.187557146","rc":[{"batl":[[1,1.05,1254],[2,1.11,11.86]],"ltp":1.04,"tv":9979.47,"id":8257797}]}]}
{"op":"mcm","clk":"4230324476","pt":1631531721485,"mc":[{"id":"1.187557146","rc":[{"batl":[[1,1.11,11.86],[2,1.13,14.83]],"ltp":1.04,"tv":9979.47,"id":8257797}]}]}
{"op":"mcm","clk":"4230324562","pt":1631531722579,"mc":[{"id":"1.187557146","rc":[{"batb":[[0,1.03,511.07]],"ltp":1.04,"tv":9979.47,"id":8257797}]}]}
{"op":"mcm","clk":"4230324646","pt":1631531723466,"mc":[{"id":"1.187557146","rc":[{"trd":[[1.04,191.46]],"batl":[[0,1.04,302.5]],"ltp":1.04,"tv":9983.34,"id":8257797}],"tv":10655.46}]}
{"op":"mcm","clk":"4230324917","pt":1631531727108,"mc":[{"id":"1.187557146","rc":[{"batl":[[0,1.11,11.86],[1,1.13,14.83],[2,1.15,14.83]],"ltp":1.04,"tv":9983.34,"id":8257797}]}]}
{"op":"mcm","clk":"4230325004","pt":1631531728102,"mc":[{"id":"1.187557146","rc":[{"batb":[[0,21,9.61],[1,17.5,2.02],[2,14,13.47]],"batl":[[0,34,53.14],[1,38,1.06],[2,520,36.01]],"ltp":26.0,"tv":672.12,"id":19931652},{"batb":[[2,1.01,812.3]],"batl":[[0,1.05,192.1],[1,1.09,51.21],[2,1.11,37]],"ltp":1.04,"tv":9983.34,"id":8257797}]}]}
{"op":"mcm","clk":"4230325071","pt":1631531728884,"mc":[{"id":"1.187557146","rc":[{"batb":[[1,1.02,1525.12]],"ltp":1.04,"tv":9983.34,"id":8257797}]}]}
{"op":"mcm","clk":"4230325275","pt":1631531731182,"mc":[{"id":"1.187557146","rc":[{"batb":[[0,1.04,425.89],[1,1.03,511.07],[2,1.02,1525.12]],"ltp":1.04,"tv":9983.34,"id":8257797}]}]}
{"op":"mcm","clk":"4230325295","pt":1631531731387,"mc":[{"id":"1.187557146","rc":[{"batb":[[0,1.04,511.07]],"ltp":1.04,"tv":9983.34,"id":8257797}]}]}
{"op":"mcm","clk":"4230325425","pt":1631531733213,"mc":[{"id":"1.187557146","rc":[{"batb":[[0,1.04,681.43]],"ltp":1.04,"tv":9983.34,"id":8257797}]}]}
{"op":"mcm","clk":"4230325699","pt":1631531737188,"mc":[{"id":"1.187557146","rc":[{"batb":[[0,1.04,839.43]],"ltp":1.04,"tv":9983.34,"id":8257797}]}]}
{"op":"mcm","clk":"4230326296","pt":1631531745515,"mc":[{"id":"1.187557146","rc":[{"trd":[[1.05,22.98]],"batl":[[0,1.05,184.87]],"ltp":1.05,"tv":9997.8,"id":8257797}],"tv":10669.92}]}
{"op":"mcm","clk":"4230326761","pt":1631531751707,"mc":[{"id":"1.187557146","rc":[{"batl":[[2,990,0.01]],"ltp":26.0,"tv":672.12,"id":19931652}]}]}
{"op":"mcm","clk":"4230327060","pt":1631531755099,"mc":[{"id":"1.187557146","rc":[{"batl":[[2,160,37.61]],"ltp":26.0,"tv":672.12,"id":19931652}]}]}
{"op":"mcm","clk":"4230327121","pt":1631531755721,"mc":[{"id":"1.187557146","rc":[{"batb":[[0,21,5.92]],"batl":[[0,34,45.7]],"ltp":26.0,"tv":672.12,"id":19931652},{"batl":[[0,1.05,118.33]],"ltp":1.05,"tv":9997.8,"id":8257797}]}]}
{"op":"mcm","clk":"4230327343","pt":1631531758627,"mc":[{"id":"1.187557146","rc":[{"batb":[[0,21,9.43]],"batl":[[0,34,53.36]],"ltp":26.0,"tv":672.12,"id":19931652},{"batl":[[0,1.05,188.49]],"ltp":1.05,"tv":9997.8,"id":8257797}]}]}
{"op":"mcm","clk":"4230327657","pt":1631531762427,"mc":[{"id":"1.187557146","rc":[{"trd":[[1.04,208.5]],"batb":[[0,1.04,830.91]],"ltp":1.04,"tv":10014.84,"id":8257797}],"tv":10686.96}]}
{"op":"mcm","clk":"4230327918","pt":1631531765809,"mc":[{"id":"1.187557146","rc":[{"batb":[[1,1.02,1525.12],[2,1.01,812.3]],"ltp":1.04,"tv":10014.84,"id":8257797}]}]}
{"op":"mcm","clk":"4230328109","pt":1631531768240,"mc":[{"id":"1.187557146","rc":[{"trd":[[1.04,252.42]],"batb":[[0,1.04,808.95]],"ltp":1.04,"tv":10058.76,"id":8257797}],"tv":10730.88}]}
{"op":"mcm","clk":"4230328148","pt":1631531768705,"mc":[{"id":"1.187557146","rc":[{"trd":[[21,9.3]],"batb":[[0,17.5,2.29],[1,14,13.47],[2,9,23.1]],"ltp":21.0,"tv":681.28,"id":19931652},{"trd":[[1.04,256.42],[1.05,583.15]],"batb":[[0,1.04,806.95]],"batl":[[0,1.09,51.21],[1,1.11,37],[2,1.13,14.83]],"ltp":1.04,"tv":10622.93,"id":8257797}],"tv":11304.21}]}
{"op":"mcm","clk":"4230328655","pt":1631531775155,"mc":[{"id":"1.187557146","rc":[{"batl":[[0,1.06,340.72],[1,1.09,51.21],[2,1.11,37]],"ltp":1.04,"tv":10622.93,"id":8257797}]}]}
{"op":"mcm","clk":"4230328952","pt":1631531778841,"mc":[{"id":"1.187557146","rc":[{"batb":[[0,17.5,2.02]],"batl":[[0,34,45.7]],"ltp":21.0,"tv":681.28,"id":19931652},{"trd":[[1.05,583.24]],"ltp":1.05,"tv":10623.03,"id":8257797}],"tv":11304.31}]}
{"op":"mcm","clk":"4230329203","pt":1631531781847,"mc":[{"id":"1.187557146","rc":[{"batl":[[0,26,5.88],[1,34,45.7],[2,38,1.06]],"ltp":21.0,"tv":681.28,"id":19931652},{"batl":[[0,1.06,447.7]],"ltp":1.05,"tv":10623.03,"id":8257797}]}]}
{"op":"mcm","clk":"4230329349","pt":1631531783853,"mc":[{"id":"1.187557146","rc":[{"trd":[[1.04,524.42]],"batb":[[0,1.04,672.95]],"ltp":1.04,"tv":10891.03,"id":8257797}],"tv":11572.31}]}
{"op":"mcm","clk":"4230330673","pt":1631531800845,"mc":[{"id":"1.187557146","rc":[{"trd":[[1.06,1004.67]],"batl":[[0,1.06,76.01]],"ltp":1.06,"tv":11634.4,"id":8257797}],"tv":12315.68}]}
{"op":"mcm","clk":"4230331336","pt":1631531808966,"mc":[{"id":"1.187557146","rc":[{"batb":[[0,1.04,843.31]],"ltp":1.06,"tv":11634.4,"id":8257797}]}]}
{"op":"mcm","clk":"4230331487","pt":1631531811091,"mc":[{"id":"1.187557146","rc":[{"batl":[[0,34,45.7],[1,38,1.06],[2,160,37.61]],"ltp":21.0,"tv":681.28,"id":19931652},{"batl":[[0,1.09,51.21],[1,1.11,37],[2,1.13,14.83]],"ltp":1.06,"tv":11634.4,"id":8257797}]}]}
{"op":"mcm","clk":"4230331653","pt":1631531813277,"mc":[{"id":"1.187557146","rc":[{"batl":[[0,160,37.61],[1,990,0.01],[2,160,0]],"ltp":21.0,"tv":681.28,"id":19931652}]}]}
{"op":"mcm","clk":"4230331735","pt":1631531814259,"mc":[{"id":"1.187557146","rc":[{"batb":[[0,9,23.1],[1,1.47,1.54],[2,1.36,766.61]],"ltp":21.0,"tv":681.28,"id":19931652},{"batb":[[0,1.05,340.72],[1,1.04,843.31],[2,1.02,425.89]],"batl":[[0,1.11,11.86],[1,1.13,14.83],[2,1.15,14.83]],"ltp":1.06,"tv":11634.4,"id":8257797}]}]}
{"op":"mcm","clk":"4230331749","pt":1631531814467,"mc":[{"id":"1.187557146","rc":[{"batb":[[0,1.05,425.89],[1,1.04,685.31]],"ltp":1.06,"tv":11634.4,"id":8257797}]}]}
{"op":"mcm","clk":"4230331848","pt":1631531816082,"mc":[{"id":"1.187557146","rc":[{"batl":[[0,990,0.01],[1,990,0]],"ltp":21.0,"tv":681.28,"id":19931652},{"batb":[[0,1.05,511.07]],"ltp":1.06,"tv":11634.4,"id":8257797}]}]}
{"op":"mcm","clk":"4230331920","pt":1631531816900,"mc":[{"id":"1.187557146","rc":[{"batb":[[1,8.6,2.09],[2,1.47,1.54]],"ltp":21.0,"tv":681.28,"id":19931652},{"batl":[[1,1.13,203.33]],"ltp":1.06,"tv":11634.4,"id":8257797}]}]}
{"op":"mcm","clk":"4230332012","pt":1631531818089,"mc":[{"id":"1.187557146","rc":[{"batb":[[0,1.06,9.02],[1,1.05,511.07],[2,1.04,685.31]],"batl":[[0,1.13,203.33],[1,1.15,14.83],[2,1.17,29.64]],"ltp":1.06,"tv":11634.4,"id":8257797}]}]}
{"op":"mcm","clk":"4230332263","pt":1631531821512,"mc":[{"id":"1.187557146","rc":[{"batb":[[2,1.02,425.89]],"ltp":1.06,"tv":11634.4,"id":8257797}]}]}
{"op":"mcm","clk":"4230332417","pt":1631531823311,"mc":[{"id":"1.187557146","rc":[{"trd":[[1.06,1079.17]],"batb":[[0,1.06,56.95]],"ltp":1.06,"tv":11708.9,"id":8257797}],"tv":12390.18}]}
{"op":"mcm","clk":"4230332543","pt":1631531825287,"mc":[{"id":"1.187557146","rc":[{"batb":[[0,1.06,312.49]],"ltp":1.06,"tv":11708.9,"id":8257797}]}]}
{"op":"mcm","clk":"4230332635","pt":1631531826279,"mc":[{"id":"1.187557146","rc":[{"batb":[[0,1.06,653.2]],"ltp":1.06,"tv":11708.9,"id":8257797}]}]}
{"op":"mcm","clk":"4230332699","pt":1631531827000,"mc":[{"id":"1.187557146","rc":[{"batb":[[0,10,2.24],[1,9,23.1],[2,8.6,2.09]],"ltp":21.0,"tv":681.28,"id":19931652},{"batl":[[0,1.11,236.5],[1,1.13,203.33],[2,1.15,14.83]],"ltp":1.06,"tv":11708.9,"id":8257797}]}]}
{"op":"mcm","clk":"4230332758","pt":1631531827982,"mc":[{"id":"1.187557146","rc":[{"batb":[[0,9,23.1],[1,8.6,2.09],[2,1.47,1.54]],"ltp":21.0,"tv":681.28,"id":19931652},{"trd":[[1.06,1079.35]],"batb":[[0,1.06,653.11],[1,1.02,425.89],[2,1.01,340.72]],"batl":[[0,1.13,203.33],[1,1.15,14.83],[2,1.17,29.64]],"ltp":1.06,"tv":11709.08,"id":8257797}],"tv":12390.36}]}
{"op":"mcm","clk":"4230333157","pt":1631531834104,"mc":[{"id":"1.187557146","rc":[{"batb":[[0,10,2.35],[1,9,23.1],[2,8.6,2.09]],"ltp":21.0,"tv":681.28,"id":19931652},{"batl":[[0,1.11,231.5],[1,1.13,203.33],[2,1.15,14.83]],"ltp":1.06,"tv":11709.08,"id":8257797}]}]}
{"op":"mcm","clk":"4230333176","pt":1631531834413,"mc":[{"id":"1.187557146","rc":[{"batb":[[0,9,23.1],[1,8.6,2.09],[2,1.47,1.54]],"ltp":21.0,"tv":681.28,"id":19931652},{"batl":[[0,1.13,203.33],[1,1.15,14.83],[2,1.17,29.64]],"ltp":1.06,"tv":11709.08,"id":8257797}]}]}
{"op":"mcm","clk":"4230333332","pt":1631531836807,"mc":[{"id":"1.187557146","rc":[{"batl":[[0,12,4.11],[1,15,36.04],[2,15.5,2.58]],"ltp":21.0,"tv":681.28,"id":19931652},{"batb":[[1,1.05,53.16],[2,1.03,27.09]],"batl":[[0,1.11,61.18],[1,1.13,237.89],[2,1.15,24.27]],"ltp":1.06,"tv":11709.08,"id":8257797}]}]}
{"op":"mcm","clk":"4230333436","pt":1631531838105,"mc":[{"id":"1.187557146","rc":[{"batb":[[2,5.8,27.11]],"ltp":21.0,"tv":681.28,"id":19931652},{"batb":[[0,1.06,528.53],[2,1.03,951.93]],"ltp":1.06,"tv":11709.08,"id":8257797}]}]}
{"op":"mcm","clk":"4230333655","pt":1631531841312,"mc":[{"id":"1.187557146","rc":[{"batb":[[0,1.08,659.51],[1,1.06,528.53],[2,1.05,53.16]],"ltp":1.06,"tv":11709.08,"id":8257797}]}]}
{"op":"mcm","clk":"4230333687","pt":1631531841729,"mc":[{"id":"1.187557146","rc":[{"trd":[[12,8.21]],"batl":[[0,15,36.04],[1,15.5,2.58],[2,990,0.01]],"ltp":12.0,"tv":685.39,"id":19931652},{"trd":[[1.09,388.6]],"ltp":1.09,"tv":11754.33,"id":8257797}],"tv":12439.72}]}
{"op":"mcm","clk":"4230333858","pt":1631531844108,"mc":[{"id":"1.187557146","rc":[{"batb":[[0,1.09,143],[1,1.08,659.51],[2,1.06,528.53]],"ltp":1.09,"tv":11754.33,"id":8257797}]}]}
{"op":"mcm","clk":"4230333884","pt":1631531844522,"mc":[{"id":"1.187557146","rc":[{"trd":[[1.09,388.62]],"batb":[[0,1.09,142.99]],"ltp":1.09,"tv":11754.35,"id":8257797}],"tv":12439.74}]}
{"op":"mcm","clk":"4230334132","pt":1631531848302,"mc":[{"id":"1.187557146","rc":[{"batb":[[0,5.8,27.11],[1,5,5.43],[2,1.47,1.54]],"batl":[[0,990,0.01],[1,15.5,0],[2,990,0]],"ltp":12.0,"tv":685.39,"id":19931652},{"batb":[[0,1.08,659.51],[1,1.03,913.88],[2,1.02,2214.22]],"batl":[[0,1.19,14.83],[1,1.21,14.83],[2,1.23,237.14]],"ltp":1.09,"tv":11754.35,"id":8257797}]}]}
{"op":"mcm","clk":"4230334190","pt":1631531849137,"mc":[{"id":"1.187557146","rc":[{"batl":[[0,1.19,15.6],[2,1.23,29.64]],"ltp":1.09,"tv":11754.35,"id":8257797}]}]}
{"op":"mcm","clk":"4230334355","pt":1631531851333,"mc":[{"id":"1.187557146","rc":[{"batb":[[1,5.7,5.02],[2,5,5.43]],"ltp":12.0,"tv":685.39,"id":19931652},{"batl":[[1,1.21,211.33]],"ltp":1.09,"tv":11754.35,"id":8257797}]}]}
{"op":"mcm","clk":"4230334374","pt":1631531851644,"mc":[{"id":"1.187557146","rc":[{"batb":[[1,5,5.43],[2,1.47,1.54]],"ltp":12.0,"tv":685.39,"id":19931652},{"batl":[[1,1.21,14.83],[2,1.23,227.14]],"ltp":1.09,"tv":11754.35,"id":8257797}]}]}
{"op":"mcm","clk":"4230334550","pt":1631531854134,"mc":[{"id":"1.187557146","rc":[{"batl":[[0,1.19,14.83]],"ltp":1.09,"tv":11754.35,"id":8257797}]}]}
{"op":"mcm","clk":"4230334858","pt":1631531858229,"mc":[{"id":"1.187557146","rc":[{"batb":[[1,5.7,4.62],[2,5,5.43]],"ltp":12.0,"tv":685.39,"id":19931652},{"batl":[[1,1.21,231.33]],"ltp":1.09,"tv":11754.35,"id":8257797}]}]}
{"op":"mcm","clk":"4230334893","pt":1631531858744,"mc":[{"id":"1.187557146","rc":[{"batb":[[1,5,5.43],[2,1.47,1.54]],"ltp":12.0,"tv":685.39,"id":19931652},{"batl":[[1,1.21,14.83],[2,1.23,29.64]],"ltp":1.09,"tv":11754.35,"id":8257797}]}]}
{"op":"mcm","clk":"4230335002","pt":1631531860245,"mc":[{"id":"1.187557146","rc":[{"batb":[[2,1.02,0]],"ltp":1.09,"tv":11754.35,"id":8257797}]}]}
{"op":"mcm","clk":"4230335068","pt":1631531861229,"mc":[{"id":"1.187557146","rc":[{"batl":[[0,7.4,5.4],[1,7.6,4.12],[2,13.5,113.35]],"ltp":12.0,"tv":685.39,"id":19931652},{"batb":[[0,1.1,50.74],[1,1.08,2102.21],[2,1.03,913.88]],"batl":[[0,1.17,39.12],[1,1.19,46.91],[2,1.21,23.07]],"ltp":1.09,"tv":11754.35,"id":8257797}]}]}
{"op":"mcm","clk":"4230335122","pt":1631531861915,"mc":[{"id":"1.187557146","rc":[{"batb":[[2,4.1,32.47]],"ltp":12.0,"tv":685.39,"id":19931652},{"batb":[[0,1.13,267.61],[1,1.1,50.74],[2,1.08,2508.39]],"ltp":1.09,"tv":11754.35,"id":8257797}]}]}
{"op":"mcm","clk":"4230335215","pt":1631531863313,"mc":[{"id":"1.187557146","rc":[{"batb":[[1,1.12,340.72],[2,1.1,50.74]],"ltp":1.09,"tv":11754.35,"id":8257797}]}]}
{"op":"mcm","clk":"4230335285","pt":1631531864240,"mc":[{"id":"1.187557146","rc":[{"batb":[[1,1.12,766.61]],"ltp":1.09,"tv":11754.35,"id":8257797}]}]}
{"op":"mcm","clk":"4230335359","pt":1631531865234,"mc":[{"id":"1.187557146","rc":[{"batb":[[1,1.1,50.74],[2,1.08,1848.89]],"ltp":1.09,"tv":11754.35,"id":8257797}]}]}
{"op":"mcm","clk":"4230343132","pt":1631531866323,"mc":[{"id":"1.187557146","rc":[{"trd":[[7.4,5.4],[7.6,4.83]],"batl":[[0,13.5,113.35],[1,990,0.01],[2,13.5,0]],"ltp":7.6,"tv":694.91,"id":19931652},{"trd":[[1.15,66.66]],"batb":[[0,1.14,624.8],[1,1.13,267.61],[2,1.12,85.18]],"ltp":1.15,"tv":11816.35,"id":8257797}],"tv":12511.26}]}
{"op":"mcm","clk":"4230343204","pt":1631531867257,"mc":[{"id":"1.187557146","rc":[{"batb":[[0,1.15,99],[1,1.14,624.8],[2,1.13,267.61]],"ltp":1.15,"tv":11816.35,"id":8257797}]}]}
{"op":"mcm","clk":"4230343252","pt":1631531867821,"mc":[{"id":"1.187557146","rc":[{"batb":[[2,4.4,7.66]],"ltp":7.6,"tv":694.91,"id":19931652}]}]}
{"op":"mcm","clk":"4230343425","pt":1631531869638,"mc":[{"id":"1.187557146","rc":[{"trd":[[6.8,3.94]],"ltp":6.8,"tv":698.35,"id":19931652},{"trd":[[1.17,28.76]],"batl":[[0,1.17,19.1]],"ltp":1.17,"tv":11836.37,"id":8257797}],"tv":12534.73}]}
{"op":"mcm","clk":"4230343678","pt":1631531872952,"mc":[{"id":"1.187557146","rc":[{"trd":[[1.15,67.56]],"batb":[[0,1.15,98.55]],"ltp":1.15,"tv":11837.27,"id":8257797}],"tv":12535.63}]}
{"op":"mcm","clk":"4230343809","pt":1631531874755,"mc":[{"id":"1.187557146","rc":[{"batl":[[0,1.16,405.73],[1,1.17,19.1],[2,1.19,46.91]],"ltp":1.15,"tv":11837.27,"id":8257797}]}]}
{"op":"mcm","clk":"4230343908","pt":1631531876049,"mc":[{"id":"1.187557146","rc":[{"batl":[[1,1.19,46.91],[2,1.21,23.07]],"ltp":1.15,"tv":11837.27,"id":8257797}]}]}
{"op":"mcm","clk":"4230343981","pt":1631531877240,"mc":[{"id":"1.187557146","rc":[{"batb":[[0,4.4,7.66],[1,4.1,32.47],[2,4,7.4]],"batl":[[0,990,0.01],[1,990,0]],"ltp":6.8,"tv":698.35,"id":19931652},{"trd":[[1.16,130.38]],"batb":[[2,1.08,406.19]],"batl":[[0,1.16,391.26],[1,1.29,238.5],[2,1.31,208.5]],"ltp":1.16,"tv":11866.2,"id":8257797}],"tv":12564.56}]}
{"op":"mcm","clk":"4230344045","pt":1631531878328,"mc":[{"id":"1.187557146","rc":[{"batb":[[0,1.14,624.8],[1,1.08,406.19],[2,1.06,968.8]],"ltp":1.16,"tv":11866.2,"id":8257797}]}]}
{"op":"mcm","clk":"4230344118","pt":1631531879356,"mc":[{"id":"1.187557146","rc":[{"batb":[[1,4.1,39.91]],"ltp":6.8,"tv":698.35,"id":19931652},{"trd":[[1.16,471.1]],"batl":[[0,1.16,220.9],[2,1.3,216.75]],"ltp":1.16,"tv":12206.92,"id":8257797}],"tv":12905.28}]}
{"op":"mcm","clk":"4230344185","pt":1631531880242,"mc":[{"id":"1.187557146","rc":[{"trd":[[1.16,912.89]],"batb":[[0,1.16,34.64],[1,1.14,624.8],[2,1.08,406.19]],"batl":[[0,1.29,238.5],[1,1.3,216.75],[2,1.31,208.5]],"ltp":1.16,"tv":12648.72,"id":8257797}],"tv":13347.07}]}
{"op":"mcm","clk":"4230344241","pt":1631531880963,"mc":[{"id":"1.187557146","rc":[{"batb":[[0,4.1,39.91],[1,4,7.4],[2,1.47,1.54]],"ltp":6.8,"tv":698.35,"id":19931652},{"batb":[[0,1.14,624.8],[1,1.08,406.19],[2,1.06,968.8]],"batl":[[0,1.32,190.61],[1,1.33,206.5],[2,1.34,1125.11]],"ltp":1.16,"tv":12648.72,"id":8257797}]}]}
{"op":"mcm","clk":"4230344353","pt":1631531882162,"mc":[{"id":"1.187557146","rc":[{"batb":[[0,1.08,406.19],[1,1.06,968.8],[2,1.06,0]],"ltp":1.16,"tv":12648.72,"id":8257797}]}]}
{"op":"mcm","clk":"4230344445","pt":1631531883350,"mc":[{"id":"1.187557146","rc":[{"batl":[[0,1.32,191.11]],"ltp":1.16,"tv":12648.72,"id":8257797}]}]}
{"op":"mcm","clk":"4230344521","pt":1631531884235,"mc":[{"id":"1.187557146","rc":[{"trd":[[7.6,4.97]],"batl":[[0,990,0.02]],"ltp":7.6,"tv":698.49,"id":19931652},{"trd":[[1.15,68.52]],"batl":[[0,1.32,190.61]],"ltp":1.15,"tv":12649.67,"id":8257797}],"tv":13348.17}]}
{"op":"mcm","clk":"4230344640","pt":1631531885532,"mc":[{"id":"1.187557146","rc":[{"batb":[[0,1.14,226.68],[1,1.08,406.19],[2,1.06,968.8]],"ltp":1.15,"tv":12649.67,"id":8257797}]}]}
{"op":"mcm","clk":"4230344927","pt":1631531889264,"mc":[{"id":"1.187557146","rc":[{"batl":[[0,1.29,85.18],[1,1.32,190.61],[2,1.33,206.5]],"ltp":1.15,"tv":12649.67,"id":8257797}]}]}
{"op":"mcm","clk":"4230345003","pt":1631531890247,"mc":[{"id":"1.187557146","rc":[{"batl":[[0,990,0.01]],"ltp":7.6,"tv":698.49,"id":19931652},{"batl":[[0,1.29,511.07]],"ltp":1.15,"tv":12649.67,"id":8257797}]}]}
{"op":"mcm","clk":"4230345035","pt":1631531890660,"mc":[{"id":"1.187557146","rc":[{"batb":[[0,4.4,7.81],[1,4.1,39.91],[2,4,7.4]],"ltp":7.6,"tv":698.49,"id":19931652},{"batl":[[0,1.29,745.57]],"ltp":1.15,"tv":12649.67,"id":8257797}]}]}
{"op":"mcm","clk":"4230345132","pt":1631531891952,"mc":[{"id":"1.187557146","rc":[{"batb":[[0,1.08,406.19],[1,1.06,968.8],[2,1.06,0]],"ltp":1.15,"tv":12649.67,"id":8257797}]}]}
{"op":"mcm","clk":"4230345194","pt":1631531892780,"mc":[{"id":"1.187557146","rc":[{"batb":[[1,1.06,0]],"ltp":1.15,"tv":12649.67,"id":8257797}]}]}
{"op":"mcm","clk":"4230345288","pt":1631531893972,"mc":[{"id":"1.187557146","rc":[{"batb":[[0,9.2,22.62],[1,8.4,4.76],[2,4.4,7.81]],"batl":[[0,11,6.43],[1,12,39.04],[2,990,0.01]],"ltp":7.6,"tv":698.49,"id":19931652},{"batb":[[1,1.07,52.16],[2,1.05,26.58]],"batl":[[0,1.12,612.46],[1,1.15,48.53],[2,1.17,23.85]],"ltp":1.15,"tv":12649.67,"id":8257797}]}]}
{"op":"mcm","clk":"4230345399","pt":1631531895162,"mc":[{"id":"1.187557146","rc":[{"batb":[[2,7.6,13.97]],"ltp":7.6,"tv":698.49,"id":19931652}]}]}
{"op":"mcm","clk":"4230345678","pt":1631531898287,"mc":[{"id":"1.187557146","rc":[{"batb":[[0,1.1,141],[1,1.08,406.19],[2,1.07,52.16]],"ltp":1.15,"tv":12649.67,"id":8257797}]}]}
{"op":"mcm","clk":"4230345783","pt":1631531899270,"mc":[{"id":"1.187557146","rc":[{"trd":[[11,6.63]],"batl":[[0,12,39.04],[1,990,0.01],[2,990,0]],"ltp":11.0,"tv":704.92,"id":19931652},{"trd":[[1.1,348.3]],"batb":[[0,1.11,170.36]],"ltp":1.1,"tv":12995.97,"id":8257797}],"tv":13700.9}]}
{"op":"mcm","clk":"4230345846","pt":1631531900051,"mc":[{"id":"1.187557146","rc":[{"batb":[[0,1.11,255.54]],"ltp":1.1,"tv":12995.97,"id":8257797}]}]}
{"op":"mcm","clk":"4230346162","pt":1631531903280,"mc":[{"id":"1.187557146","rc":[{"batb":[[0,1.11,430.54]],"ltp":1.1,"tv":12995.97,"id":8257797}]}]}
{"op":"mcm","clk":"4230346167","pt":1631531903381,"mc":[{"id":"1.187557146","rc":[{"trd":[[9.2,2.76]],"batb":[[0,9.2,21.24]],"ltp":9.2,"tv":707.68,"id":19931652}],"tv":13703.66}]}
{"op":"mcm","clk":"4230346309","pt":1631531905159,"mc":[{"id":"1.187557146","rc":[{"trd":[[1.12,39.6]],"batl":[[0,1.12,611.84]],"ltp":1.12,"tv":12997.21,"id":8257797}],"tv":13704.9}]}
{"op":"mcm","clk":"4230346332","pt":1631531905367,"mc":[{"id":"1.187557146","rc":[{"trd":[[1.11,946.04]],"batb":[[0,1.11,380.54]],"ltp":1.11,"tv":13097.21,"id":8257797}],"tv":13804.9}]}
{"op":"mcm","clk":"4230346435","pt":1631531906496,"mc":[{"id":"1.187557146","rc":[{"trd":[[1.12,40.6]],"batl":[[0,1.12,611.34]],"ltp":1.12,"tv":13098.21,"id":8257797}],"tv":13805.9}]}
{"op":"mcm","clk":"4230346585","pt":1631531908262,"mc":[{"id":"1.187557146","rc":[{"batb":[[0,7.6,13.97],[1,4.7,22.51],[2,4.2,5.72]],"batl":[[0,990,0.01],[1,990,0]],"ltp":9.2,"tv":707.68,"id":19931652},{"batl":[[0,1.15,48.53],[1,1.17,23.85],[2,1.25,14.85]],"ltp":1.12,"tv":13098.21,"id":8257797}]}]}
{"op":"mcm","clk":"4230346647","pt":1631531908991,"mc":[{"id":"1.187557146","rc":[{"batb":[[0,4.7,22.51],[1,4.2,5.72],[2,1.47,1.54]],"ltp":9.2,"tv":707.68,"id":19931652},{"batb":[[1,1.04,767.6],[2,1.07,0]],"batl":[[0,1.25,14.85],[1,1.31,165.5],[2,1.39,17.78]],"ltp":1.12,"tv":13098.21,"id":8257797}]}]}
{"op":"mcm","clk":"4230346670","pt":1631531909404,"mc":[{"id":"1.187557146","rc":[{"batb":[[0,1.11,205.54]],"ltp":1.12,"tv":13098.21,"id":8257797}]}]}
{"op":"mcm","clk":"4230346846","pt":1631531911279,"mc":[{"id":"1.187557146","rc":[{"trd":[[1.11,952.8]],"batb":[[0,1.11,202.16]],"batl":[[0,1.12,255.54],[1,1.25,14.85],[2,1.31,165.5]],"ltp":1.11,"tv":13104.98,"id":8257797}],"tv":13812.67}]}
{"op":"mcm","clk":"4230346900","pt":1631531912001,"mc":[{"id":"1.187557146","rc":[{"batb":[[0,4.8,4.43],[1,4.7,22.51],[2,4.2,5.72]],"ltp":9.2,"tv":707.68,"id":19931652},{"batl":[[0,1.12,511.07],[2,1.26,166.75]],"ltp":1.11,"tv":13104.98,"id":8257797}]}]}
{"op":"mcm","clk":"4230347040","pt":1631531913573,"mc":[{"id":"1.187557146","rc":[{"trd":[[1.11,970.84]],"batb":[[0,1.11,193.13]],"ltp":1.11,"tv":13123.02,"id":8257797}],"tv":13830.71}]}
{"op":"mcm","clk":"4230347332","pt":1631531916896,"mc":[{"id":"1.187557146","rc":[{"trd":[[1.12,42.92]],"batb":[[0,1.04,767.6],[1,1.04,0]],"batl":[[0,1.12,509.91]],"ltp":1.12,"tv":13125.34,"id":8257797}],"tv":13833.03}]}
{"op":"mcm","clk":"4230347447","pt":1631531918190,"mc":[{"id":"1.187557146","rc":[{"batb":[[0,13,15.38],[1,4.8,4.43],[2,4.7,22.51]],"batl":[[0,21,17.54],[1,990,0.01]],"ltp":9.2,"tv":707.68,"id":19931652},{"batb":[[0,1.05,248.04],[1,1.04,767.6]],"batl":[[0,1.06,29.19],[1,1.12,509.91],[2,1.25,14.85]],"ltp":1.12,"tv":13125.34,"id":8257797}]}]}
{"op":"mcm","clk":"4230347542","pt":1631531919284,"mc":[{"id":"1.187557146","rc":[{"batb":[[0,15,14.05],[1,13,3.08],[2,11.5,12.13]],"batl":[[0,21,12.4]],"ltp":9.2,"tv":707.68,"id":19931652},{"batb":[[2,1.02,54.72]],"batl":[[0,1.07,595.5],[1,1.1,50.74],[2,1.12,534.84]],"ltp":1.12,"tv":13125.34,"id":8257797}]}]}
{"op":"mcm","clk":"4230347633","pt":1631531920272,"mc":[{"id":"1.187557146","rc":[{"trd":[[15,1.54]],"batb":[[0,15,13.28]],"ltp":15.0,"tv":709.23,"id":19931652}],"tv":13834.57}]}
{"op":"mcm","clk":"4230347726","pt":1631531921308,"mc":[{"id":"1.187557146","rc":[{"batl":[[0,21,17.54]],"ltp":15.0,"tv":709.23,"id":19931652},{"batl":[[0,1.06,114.37],[1,1.07,680.68],[2,1.1,50.74]],"ltp":1.12,"tv":13125.34,"id":8257797}]}]}
{"op":"mcm","clk":"4230347757","pt":1631531921685,"mc":[{"id":"1.187557146","rc":[{"batl":[[0,21,12.4]],"ltp":15.0,"tv":709.23,"id":19931652},{"batl":[[0,1.07,680.68],[1,1.1,50.74],[2,1.12,534.84]],"ltp":1.12,"tv":13125.34,"id":8257797}]}]}
{"op":"mcm","clk":"4230347898","pt":1631531923288,"mc":[{"id":"1.187557146","rc":[{"trd":[[1.07,950.22]],"batb":[[0,1.05,588.76]],"batl":[[0,1.07,679.69],[2,1.12,24.92]],"ltp":1.07,"tv":13127.32,"id":8257797}],"tv":13836.55}]}
{"op":"mcm","clk":"4230348055","pt":1631531925316,"mc":[{"id":"1.187557146","rc":[{"batl":[[0,21,17.54]],"ltp":15.0,"tv":709.23,"id":19931652},{"batb":[[0,1.05,687.76]],"batl":[[0,1.06,29.19],[1,1.07,679.69],[2,1.1,50.74]],"ltp":1.07,"tv":13127.32,"id":8257797}]}]}
{"op":"mcm","clk":"4230348231","pt":1631531927121,"mc":[{"id":"1.187557146","rc":[{"batl":[[1,1.07,1020.4]],"ltp":1.07,"tv":13127.32,"id":8257797}]}]}
{"op":"mcm","clk":"4230348634","pt":1631531930912,"mc":[{"id":"1.187557146","rc":[{"trd":[[1.05,688.69]],"batb":[[0,1.05,635.04]],"ltp":1.05,"tv":13232.76,"id":8257797}],"tv":13941.99}]}
{"op":"mcm","clk":"4230348813","pt":1631531932995,"mc":[{"id":"1.187557146","rc":[{"batb":[[0,6,24.18],[1,5.3,2.58],[2,4.8,4.43]],"batl":[[0,990,0.01],[1,990,0]],"ltp":15.0,"tv":709.23,"id":19931652},{"batb":[[0,1.06,9.02],[1,1.05,340.72],[2,1.01,4122.58]],"batl":[[0,1.07,425.89],[1,1.19,14.85],[2,1.23,142.21]],"ltp":1.05,"tv":13232.76,"id":8257797}]}]}
{"op":"mcm","clk":"4230349002","pt":1631531935330,"mc":[{"id":"1.187557146","rc":[{"trd":[[1.07,950.99]],"batb":[[0,1.06,9.14],[2,1.01,0]],"batl":[[0,1.07,425.51]],"ltp":1.07,"tv":13233.53,"id":8257797}],"tv":13942.76}]}
{"op":"mcm","clk":"4230349077","pt":1631531936229,"mc":[{"id":"1.187557146","rc":[{"batl":[[2,1.21,14.85]],"ltp":1.07,"tv":13233.53,"id":8257797}]}]}
{"op":"mcm","clk":"4230349511","pt":1631531941420,"mc":[{"id":"1.187557146","rc":[{"batb":[[0,1.05,340.83],[1,1.05,0]],"ltp":1.07,"tv":13233.53,"id":8257797}]}]}
{"op":"mcm","clk":"4230349602","pt":1631531942510,"mc":[{"id":"1.187557146","rc":[{"batb":[[0,1.06,218.12],[1,1.05,340.72]],"ltp":1.07,"tv":13233.53,"id":8257797}]}]}
{"op":"mcm","clk":"4230349930","pt":1631531946107,"mc":[{"id":"1.187557146","rc":[{"trd":[[1.07,972.25]],"batl":[[0,1.07,414.88]],"ltp":1.07,"tv":13254.79,"id":8257797}],"tv":13964.02}]}
{"op":"mcm","clk":"4230350313","pt":1631531951314,"mc":[{"id":"1.187557146","rc":[{"trd":[[1.07,989.41]],"batb":[[0,1.05,340.83],[1,1.05,0]],"batl":[[0,1.07,406.3]],"ltp":1.07,"tv":13271.95,"id":8257797}],"tv":13981.18}]}
{"op":"mcm","clk":"4230350405","pt":1631531952821,"mc":[{"id":"1.187557146","rc":[{"trd":[[1.07,990.18]],"batl":[[0,1.07,405.92]],"ltp":1.07,"tv":13272.72,"id":8257797}],"tv":13981.95}]}
{"op":"mcm","clk":"4230350597","pt":1631531955324,"mc":[{"id":"1.187557146","rc":[{"trd":[[1.06,1079.59]],"batb":[[0,1.05,340.72]],"batl":[[0,1.06,1.28],[1,1.07,405.92],[2,1.19,14.85]],"ltp":1.06,"tv":13272.96,"id":8257797}],"tv":13982.19}]}
{"op":"mcm","clk":"4230350797","pt":1631531957468,"mc":[{"id":"1.187557146","rc":[{"trd":[[1.07,995.06]],"batl":[[0,1.07,403.48],[1,1.19,14.85],[2,1.21,14.85]],"ltp":1.07,"tv":13277.83,"id":8257797}],"tv":13987.06}]}
{"op":"mcm","clk":"4230350931","pt":1631531959132,"mc":[{"id":"1.187557146","rc":[{"batl":[[1,1.17,29.71],[2,1.19,14.85]],"ltp":1.07,"tv":13277.83,"id":8257797}]}]}
{"op":"mcm","clk":"4230351458","pt":1631531965334,"mc":[{"id":"1.187557146","rc":[{"batl":[[0,8.2,551.4],[1,9.2,5.94],[2,9.4,2.27]],"ltp":15.0,"tv":709.23,"id":19931652},{"batl":[[0,1.14,41.45],[1,1.17,82.36]],"ltp":1.07,"tv":13277.83,"id":8257797}]}]}
{"op":"mcm","clk":"4230351554","pt":1631531966272,"mc":[{"id":"1.187557146","rc":[{"batl":[[0,9.2,5.94],[1,9.6,4.16],[2,10,62]],"ltp":15.0,"tv":709.23,"id":19931652},{"batb":[[0,1.12,290.54],[1,1.09,51.21],[2,1.07,26.08]],"batl":[[1,1.17,52.65],[2,1.18,47.3]],"ltp":1.07,"tv":13277.83,"id":8257797}]}]}
{"op":"mcm","clk":"4230351913","pt":1631531970579,"mc":[{"id":"1.187557146","rc":[{"trd":[[1.13,379.5]],"ltp":1.13,"tv":13657.34,"id":8257797}],"tv":14366.57}]}
{"op":"mcm","clk":"4230352185","pt":1631531973546,"mc":[{"id":"1.187557146","rc":[{"batb":[[0,1.12,435.54]],"ltp":1.13,"tv":13657.34,"id":8257797}]}]}
{"op":"mcm","clk":"4230352576","pt":1631531978292,"mc":[{"id":"1.187557146","rc":[{"batb":[[0,3.5,24.35],[1,3.25,5.73],[2,2.84,5.72]],"batl":[[0,990,0.01],[1,9.6,0],[2,10,0]],"ltp":15.0,"tv":709.23,"id":19931652},{"batb":[[0,1.06,968.8],[1,1.04,708.52],[2,1.07,0]],"batl":[[0,1.39,18.32],[1,1.4,940.5],[2,1.44,114.08]],"ltp":1.13,"tv":13657.34,"id":8257797}]}]}
{"op":"mcm","clk":"4230352646","pt":1631531979280,"mc":[{"id":"1.187557146","rc":[{"batb":[[0,1.04,708.52],[1,1.04,0]],"batl":[[0,1.16,170.36],[1,1.39,18.32]],"ltp":1.13,"tv":13657.34,"id":8257797}]}]}
{"op":"mcm","clk":"4230352704","pt":1631531979952,"mc":[{"id":"1.187557146","rc":[{"batl":[[0,1.16,425.89]],"ltp":1.13,"tv":13657.34,"id":8257797}]}]}
{"op":"mcm","clk":"4230352743","pt":1631531980368,"mc":[{"id":"1.187557146","rc":[{"batl":[[0,1.12,36.06],[1,1.16,425.89],[2,1.39,18.32]],"ltp":1.13,"tv":13657.34,"id":8257797}]}]}
{"op":"mcm","clk":"4230353244","pt":1631531986667,"mc":[{"id":"1.187557146","rc":[{"batb":[[1,2.84,5.72],[2,1.47,1.54]],"ltp":15.0,"tv":709.23,"id":19931652},{"batl":[[0,1.16,425.89],[1,1.39,18.32],[2,3.8,27.48]],"ltp":1.13,"tv":13657.34,"id":8257797}]}]}
{"op":"mcm","clk":"4230353361","pt":1631531988171,"mc":[{"id":"1.187557146","rc":[{"batl":[[0,1.39,18.32],[1,3.8,27.48],[2,8.8,7.23]],"ltp":1.13,"tv":13657.34,"id":8257797}]}]}
{"op":"mcm","clk":"4230353457","pt":1631531989260,"mc":[{"id":"1.187557146","rc":[{"trd":[[5.7,20.23]],"batl":[[0,4.8,3.4],[1,990,0.01]],"ltp":5.7,"tv":709.34,"id":19931652},{"trd":[[1.21,281.99]],"batl":[[0,1.39,17.78]],"ltp":1.21,"tv":13657.88,"id":8257797}],"tv":14367.22}]}
{"op":"mcm","clk":"4230353536","pt":1631531990300,"mc":[{"id":"1.187557146","rc":[{"batb":[[1,3.15,31.71],[2,2.84,5.72]],"batl":[[0,4.7,7.11],[1,5,46.76],[2,990,0.01]],"ltp":5.7,"tv":709.34,"id":19931652},{"trd":[[1.3,68.24]],"batb":[[0,1.3,138.45],[1,1.25,187.04],[2,1.22,158.24]],"batl":[[0,1.32,42.29],[1,1.34,20.83],[2,1.35,52.65]],"ltp":1.3,"tv":13697.91,"id":8257797}],"tv":14407.25}]}
{"op":"mcm","clk":"4230353766","pt":1631531992893,"mc":[{"id":"1.187557146","rc":[{"trd":[[1.3,88.78]],"batb":[[0,1.3,128.18]],"ltp":1.3,"tv":13718.45,"id":8257797}],"tv":14427.79}]}
{"op":"mcm","clk":"4230353887","pt":1631531994509,"mc":[{"id":"1.187557146","rc":[{"trd":[[1.3,177.58]],"batb":[[0,1.3,83.78]],"ltp":1.3,"tv":13807.25,"id":8257797}],"tv":14516.59}]}
{"op":"mcm","clk":"4230354297","pt":1631531999916,"mc":[{"id":"1.187557146","rc":[{"trd":[[4.1,2.08]],"batl":[[0,5,46.76],[1,990,0.01],[2,990,0]],"ltp":4.1,"tv":710.48,"id":19931652},{"trd":[[1.3,249.7],[1.32,16.8]],"batb":[[0,1.3,47.72]],"batl":[[0,1.32,38.74]],"ltp":1.3,"tv":13882.92,"id":8257797}],"tv":14593.41}]}
{"op":"mcm","clk":"4230354373","pt":1631532000800,"mc":[{"id":"1.187557146","rc":[{"trd":[[1.3,250.48]],"batb":[[0,1.3,47.33]],"ltp":1.3,"tv":13883.7,"id":8257797}],"tv":14594.18}]}
{"op":"mcm","clk":"4230354602","pt":1631532003309,"mc":[{"id":"1.187557146","rc":[{"trd":[[1.3,288.44]],"batb":[[0,1.3,28.35],[1,1.28,20.54],[2,1.25,187.04]],"ltp":1.3,"tv":13921.66,"id":8257797}],"tv":14632.14}]}
{"op":"mcm","clk":"4230354669","pt":1631532003992,"mc":[{"id":"1.187557146","rc":[{"trd":[[1.3,295.67]],"batb":[[0,1.3,24.74]],"ltp":1.3,"tv":13928.89,"id":8257797}],"tv":14639.37}]}
{"op":"mcm","clk":"4230354866","pt":1631532006189,"mc":[{"id":"1.187557146","rc":[{"trd":[[1.3,306.49]],"batb":[[0,1.3,19.33]],"ltp":1.3,"tv":13939.71,"id":8257797}],"tv":14650.19}]}
{"op":"mcm","clk":"4230354960","pt":1631532007285,"mc":[{"id":"1.187557146","rc":[{"trd":[[4.4,52.35]],"ltp":4.4,"tv":710.93,"id":19931652},{"trd":[[1.3,308.01]],"batb":[[0,1.3,17.8]],"batl":[[1,1.33,405.73],[2,1.34,20.83]],"ltp":1.3,"tv":13941.23,"id":8257797}],"tv":14652.16}]}
{"op":"mcm","clk":"4230355237","pt":1631532009989,"mc":[{"id":"1.187557146","rc":[{"batb":[[0,3.7,12.32],[1,3.5,24.35],[2,3.15,31.71]],"ltp":4.4,"tv":710.93,"id":19931652},{"trd":[[1.32,94.27],[1.33,825.03]],"batb":[[0,1.33,298.9],[1,1.3,17.8],[2,1.28,20.54]],"batl":[[0,1.34,20.83],[1,1.35,52.65],[2,1.37,315.5]],"ltp":1.33,"tv":14830.16,"id":8257797}],"tv":15541.09}]}
{"op":"mcm","clk":"4230355283","pt":1631532010404,"mc":[{"id":"1.187557146","rc":[{"batb":[[0,3.5,24.35],[1,3.15,31.71],[2,2.84,5.72]],"ltp":4.4,"tv":710.93,"id":19931652},{"batl":[[2,1.66,587.81]],"ltp":1.33,"tv":14830.16,"id":8257797}]}]}
{"op":"mcm","clk":"4230355499","pt":1631532012901,"mc":[{"id":"1.187557146","rc":[{"trd":[[1.33,926.6]],"batb":[[0,1.33,248.12],[2,1.25,187.04]],"ltp":1.33,"tv":14931.73,"id":8257797}],"tv":15642.66}]}
{"op":"mcm","clk":"4230355721","pt":1631532015613,"mc":[{"id":"1.187557146","rc":[{"trd":[[1.33,962.54]],"batb":[[0,1.33,230.15]],"ltp":1.33,"tv":14967.67,"id":8257797}],"tv":15678.6}]}
{"op":"mcm","clk":"4230355941","pt":1631532018229,"mc":[{"id":"1.187557146","rc":[{"batl":[[0,990,0.01],[1,990,0]],"ltp":4.4,"tv":710.93,"id":19931652},{"trd":[[1.33,964.7]],"batb":[[0,1.33,229.07],[2,1.23,523.6]],"batl":[[1,1.38,337.36]],"ltp":1.33,"tv":14969.83,"id":8257797}],"tv":15680.76}]}
{"op":"mcm","clk":"4230355994","pt":1631532018807,"mc":[{"id":"1.187557146","rc":[{"batb":[[0,3.15,31.71],[1,1.47,1.54],[2,1.01,105.7]],"ltp":4.4,"tv":710.93,"id":19931652},{"batb":[[1,1.23,523.6],[2,1.22,158.24]],"batl":[[0,1.38,337.36],[1,1.66,587.81],[2,3.8,27.48]],"ltp":1.33,"tv":14969.83,"id":8257797}]}]}
{"op":"mcm","clk":"4230356122","pt":1631532020322,"mc":[{"id":"1.187557146","rc":[{"batb":[[0,3.5,13.1],[1,3.15,31.71],[2,1.47,1.54]],"ltp":4.4,"tv":710.93,"id":19931652},{"batb":[[0,1.23,523.6],[1,1.22,158.24],[2,1.06,2973.46]],"batl":[[1,1.4,294.89],[2,1.66,587.81]],"ltp":1.33,"tv":14969.83,"id":8257797}]}]}
{"op":"mcm","clk":"4230356281","pt":1631532022043,"mc":[{"id":"1.187557146","rc":[{"batb":[[1,3.25,30.46]],"ltp":4.4,"tv":710.93,"id":19931652}]}]}
{"op":"mcm","clk":"4230356496","pt":1631532024805,"mc":[{"id":"1.187557146","rc":[{"batb":[[0,1.22,158.24],[1,1.06,2973.46],[2,1.06,0]],"batl":[[2,3.8,27.48]],"ltp":1.33,"tv":14969.83,"id":8257797}]}]}
{"op":"mcm","clk":"4230356546","pt":1631532025428,"mc":[{"id":"1.187557146","rc":[{"batl":[[0,1.4,294.89],[1,3.8,27.48],[2,8.8,7.23]],"ltp":1.33,"tv":14969.83,"id":8257797}]}]}
{"op":"mcm","clk":"4230356679","pt":1631532027348,"mc":[{"id":"1.187557146","rc":[{"batl":[[0,3.75,10.66],[1,4.1,53.62],[2,990,0.01]],"ltp":4.4,"tv":710.93,"id":19931652},{"batb":[[0,1.25,44.65],[1,1.23,22.69],[2,1.22,158.24]],"batl":[[0,1.37,40.74],[1,1.38,52.65],[2,1.39,20.08]],"ltp":1.33,"tv":14969.83,"id":8257797}]}]}
{"op":"mcm","clk":"4230356776","pt":1631532028338,"mc":[{"id":"1.187557146","rc":[{"batb":[[2,3,37.91]],"batl":[[1,3.85,14.46],[2,4.1,53.62]],"ltp":4.4,"tv":710.93,"id":19931652},{"batb":[[0,1.34,95.23],[1,1.28,492.6],[2,1.27,124.43]],"ltp":1.33,"tv":14969.83,"id":8257797}]}]}
{"op":"mcm","clk":"4230356921","pt":1631532030007,"mc":[{"id":"1.187557146","rc":[{"batl":[[1,3.85,20.47]],"ltp":4.4,"tv":710.93,"id":19931652},{"batl":[[0,1.37,51.66]],"ltp":1.33,"tv":14969.83,"id":8257797}]}]}
{"op":"mcm","clk":"4230357133","pt":1631532032151,"mc":[{"id":"1.187557146","rc":[{"trd":[[3.7,9.31]],"ltp":3.7,"tv":712.1,"id":19931652},{"trd":[[1.37,7.49]],"batl":[[0,1.37,48.51]],"ltp":1.37,"tv":14972.98,"id":8257797}],"tv":15685.08}]}
{"op":"mcm","clk":"4230357214","pt":1631532033241,"mc":[{"id":"1.187557146","rc":[{"batl":[[0,990,0.01],[1,3.85,0],[2,4.1,0]],"ltp":3.7,"tv":712.1,"id":19931652},{"batl":[[0,1.37,377.42],[1,1.39,20.08],[2,1.4,294.89]],"ltp":1.37,"tv":14972.98,"id":8257797}]}]}
{"op":"mcm","clk":"4230357262","pt":1631532033918,"mc":[{"id":"1.187557146","rc":[{"batb":[[1,3.35,12.67]],"ltp":3.7,"tv":712.1,"id":19931652},{"batb":[[0,1.28,492.6],[1,1.27,124.43],[2,1.06,2973.46]],"batl":[[0,1.37,339.83],[1,1.4,294.89],[2,1.42,287.75]],"ltp":1.37,"tv":14972.98,"id":8257797}]}]}
{"op":"mcm","clk":"4230357500","pt":1631532036631,"mc":[{"id":"1.187557146","rc":[{"batl":[[0,1.37,340.02]],"ltp":1.37,"tv":14972.98,"id":8257797}]}]}
{"op":"mcm","clk":"4230357594","pt":1631532037622,"mc":[{"id":"1.187557146","rc":[{"trd":[[3.7,89.24],[3.75,0.07]],"ltp":3.7,"tv":792.1,"id":19931652},{"trd":[[1.36,0.19],[1.37,223.36]],"batl":[[0,1.37,123.96]],"ltp":1.37,"tv":15189.04,"id":8257797}],"tv":15981.14}]}
{"op":"mcm","clk":"4230357707","pt":1631532039336,"mc":[{"id":"1.187557146","rc":[{"trd":[[1.37,223.39]],"batl":[[0,1.37,123.95]],"ltp":1.37,"tv":15189.08,"id":8257797}],"tv":15981.18}]}
{"op":"mcm","clk":"4230358109","pt":1631532044248,"mc":[{"id":"1.187557146","rc":[{"trd":[[3.7,103.7]],"ltp":3.7,"tv":806.56,"id":19931652},{"trd":[[1.37,262.45]],"batl":[[0,1.37,84.88]],"ltp":1.37,"tv":15228.14,"id":8257797}],"tv":16034.7}]}
{"op":"mcm","clk":"4230358127","pt":1631532044457,"mc":[{"id":"1.187557146","rc":[{"batb":[[0,3.35,12.67],[1,3,37.91],[2,1.47,1.54]],"ltp":3.7,"tv":806.56,"id":19931652},{"batl":[[1,1.42,287.75],[2,1.82,475.58]],"ltp":1.37,"tv":15228.14,"id":8257797}]}]}
{"op":"mcm","clk":"4230358259","pt":1631532046333,"mc":[{"id":"1.187557146","rc":[{"batl":[[0,1.42,287.75],[1,1.82,475.58],[2,3.8,27.48]],"ltp":1.37,"tv":15228.14,"id":8257797}]}]}
{"op":"mcm","clk":"4230358342","pt":1631532047268,"mc":[{"id":"1.187557146","rc":[{"batb":[[0,1.27,124.43],[1,1.06,2973.46],[2,1.06,0]],"ltp":1.37,"tv":15228.14,"id":8257797}]}]}
{"op":"mcm","clk":"4230358424","pt":1631532048148,"mc":[{"id":"1.187557146","rc":[{"trd":[[3.5,8.66]],"batb":[[0,3.4,4.19],[1,3.35,35.08],[2,3,37.91]],"batl":[[0,3.6,11.12],[1,3.7,42.03],[2,990,0.01]],"ltp":3.5,"tv":815.22,"id":19931652},{"batb":[[0,1.29,43.27],[1,1.27,146.41],[2,1.06,2973.46]],"batl":[[0,1.41,39.59],[1,1.42,287.75],[2,1.43,19.52]],"ltp":1.37,"tv":15228.14,"id":8257797}],"tv":16043.36}]}
{"op":"mcm","clk":"4230358517","pt":1631532049036,"mc":[{"id":"1.187557146","rc":[{"trd":[[1.39,4.34]],"batb":[[0,1.39,78.33],[1,1.34,97.49],[2,1.29,43.27]],"ltp":1.39,"tv":15232.48,"id":8257797}],"tv":16047.7}]}
{"op":"mcm","clk":"4230358812","pt":1631532052169,"mc":[{"id":"1.187557146","rc":[{"trd":[[3.6,41.73]],"batl":[[0,3.7,42.03],[1,990,0.01],[2,990,0]],"ltp":3.6,"tv":856.95,"id":19931652},{"trd":[[1.39,54.82]],"batb":[[0,1.39,27.85],[2,1.31,484.1]],"ltp":1.39,"tv":15282.95,"id":8257797}],"tv":16139.91}]}
{"op":"mcm","clk":"4230358918","pt":1631532053268,"mc":[{"id":"1.187557146","rc":[{"batb":[[0,1.39,139.85],[1,1.37,9.02],[2,1.34,97.49]],"ltp":1.39,"tv":15282.95,"id":8257797}]}]}
{"op":"mcm","clk":"4230359100","pt":1631532055154,"mc":[{"id":"1.187557146","rc":[{"batb":[[2,3.3,13.38]],"ltp":3.6,"tv":856.95,"id":19931652},{"batl":[[2,1.43,301.02]],"ltp":1.39,"tv":15282.95,"id":8257797}]}]}
{"op":"mcm","clk":"4230359116","pt":1631532055362,"mc":[{"id":"1.187557146","rc":[{"trd":[[1.41,17.03]],"batl":[[0,1.41,31.07]],"ltp":1.41,"tv":15299.99,"id":8257797}],"tv":16156.94}]}
{"op":"mcm","clk":"4230359326","pt":1631532058073,"mc":[{"id":"1.187557146","rc":[{"batb":[[0,3.35,35.08],[1,3.3,13.38],[2,3,37.91]],"ltp":3.6,"tv":856.95,"id":19931652}]}]}
{"op":"mcm","clk":"4230359351","pt":1631532058382,"mc":[{"id":"1.187557146","rc":[{"trd":[[1.41,21.23]],"batl":[[0,1.41,28.97]],"ltp":1.41,"tv":15304.19,"id":8257797}],"tv":16161.14}]}
{"op":"mcm","clk":"4230359576","pt":1631532061004,"mc":[{"id":"1.187557146","rc":[{"batl":[[0,3.55,4.08],[1,3.7,42.03],[2,990,0.01]],"ltp":3.6,"tv":856.95,"id":19931652},{"batl":[[0,1.41,41.64]],"ltp":1.41,"tv":15304.19,"id":8257797}]}]}
{"op":"mcm","clk":"4230359979","pt":1631532065280,"mc":[{"id":"1.187557146","rc":[{"batb":[[0,3.3,13.38],[1,2.86,43.6],[2,1.47,1.54]],"batl":[[0,990,0.01],[1,3.7,0],[2,990,0]],"ltp":3.6,"tv":856.95,"id":19931652},{"batb":[[0,1.37,9.02],[1,1.34,97.49],[2,1.31,484.1]],"batl":[[0,1.44,80.76],[1,1.82,475.58],[2,3.8,27.48]],"ltp":1.41,"tv":15304.19,"id":8257797}]}]}
{"op":"mcm","clk":"4230360221","pt":1631532068159,"mc":[{"id":"1.187557146","rc":[{"batb":[[0,3.35,14.47],[1,3.3,13.38],[2,2.88,42.59]],"ltp":3.6,"tv":856.95,"id":19931652},{"batb":[[2,1.33,99.33]],"batl":[[0,1.42,311.75],[1,1.43,313.5],[2,1.44,80.76]],"ltp":1.41,"tv":15304.19,"id":8257797}]}]}
{"op":"mcm","clk":"4230360273","pt":1631532068789,"mc":[{"id":"1.187557146","rc":[{"batb":[[0,3.3,13.38],[1,2.88,42.59],[2,1.47,1.54]],"ltp":3.6,"tv":856.95,"id":19931652},{"batb":[[1,1.33,99.33],[2,1.31,484.1]],"batl":[[0,1.43,313.5],[1,1.44,80.76],[2,1.82,475.58]],"ltp":1.41,"tv":15304.19,"id":8257797}]}]}
{"op":"mcm","clk":"4230360638","pt":1631532073098,"mc":[{"id":"1.187557146","rc":[{"batl":[[1,1.82,475.58],[2,3.8,27.48]],"ltp":1.41,"tv":15304.19,"id":8257797}]}]}
{"op":"mcm","clk":"4230360807","pt":1631532075182,"mc":[{"id":"1.187557146","rc":[{"batb":[[0,3.35,14.47],[1,3.3,13.38],[2,2.88,42.59]],"ltp":3.6,"tv":856.95,"id":19931652},{"batl":[[0,1.42,393.64],[1,1.43,313.5],[2,1.82,475.58]],"ltp":1.41,"tv":15304.19,"id":8257797}]}]}
{"op":"mcm","clk":"4230360821","pt":1631532075391,"mc":[{"id":"1.187557146","rc":[{"batb":[[0,3.3,13.38],[1,2.88,42.59],[2,1.47,1.54]],"ltp":3.6,"tv":856.95,"id":19931652},{"batl":[[0,1.42,81.89]],"ltp":1.41,"tv":15304.19,"id":8257797}]}]}
{"op":"mcm","clk":"4230361387","pt":1631532082311,"mc":[{"id":"1.187557146","rc":[{"batb":[[0,3.35,15.27],[1,3.3,13.38],[2,2.88,42.59]],"ltp":3.6,"tv":856.95,"id":19931652},{"batl":[[0,1.42,356.64]],"ltp":1.41,"tv":15304.19,"id":8257797}]}]}
{"op":"mcm","clk":"4230361414","pt":1631532082574,"mc":[{"id":"1.187557146","rc":[{"batb":[[0,3.3,13.38],[1,2.88,42.59],[2,1.47,1.54]],"ltp":3.6,"tv":856.95,"id":19931652},{"batl":[[0,1.42,81.89]],"ltp":1.41,"tv":15304.19,"id":8257797}]}]}
{"op":"mcm","clk":"4230361759","pt":1631532086319,"mc":[{"id":"1.187557146","rc":[{"batb":[[0,3.7,42.72],[1,3.4,21.94],[2,3.3,13.38]],"batl":[[0,3.9,4.08],[1,4.1,48.46],[2,990,0.01]],"ltp":3.6,"tv":856.95,"id":19931652},{"trd":[[1.37,280.49]],"batb":[[0,1.33,99.33],[1,1.06,2973.46],[2,1.31,0]],"batl":[[0,1.36,11.21],[1,1.37,346.5],[2,1.4,85.72]],"ltp":1.37,"tv":15322.23,"id":8257797}],"tv":16179.18}]}
{"op":"mcm","clk":"4230361821","pt":1631532087124,"mc":[{"id":"1.187557146","rc":[{"batb":[[2,3.35,28.79]],"ltp":3.6,"tv":856.95,"id":19931652},{"batb":[[1,1.25,180.72],[2,1.23,22.69]],"batl":[[1,1.37,387.24],[2,1.39,20.08]],"ltp":1.37,"tv":15322.23,"id":8257797}]}]}
{"op":"mcm","clk":"4230362077","pt":1631532090128,"mc":[{"id":"1.187557146","rc":[{"batb":[[1,1.25,692.78]],"ltp":1.37,"tv":15322.23,"id":8257797}]}]}
{"op":"mcm","clk":"4230362337","pt":1631532093298,"mc":[{"id":"1.187557146","rc":[{"batb":[[1,3.5,16.12],[2,3.4,21.94]],"ltp":3.6,"tv":856.95,"id":19931652}]}]}
{"op":"mcm","clk":"4230362434","pt":1631532094334,"mc":[{"id":"1.187557146","rc":[{"trd":[[3.75,4.13]],"ltp":3.75,"tv":861.01,"id":19931652},{"trd":[[1.36,11.39]],"batb":[[0,1.34,163],[1,1.33,99.33],[2,1.25,692.78]],"batl":[[0,1.37,387.25],[1,1.39,20.08],[2,1.4,333.27]],"ltp":1.36,"tv":15333.43,"id":8257797}],"tv":16194.44}]}
{"op":"mcm","clk":"4230362775","pt":1631532098308,"mc":[{"id":"1.187557146","rc":[{"batl":[[2,1.4,304.69]],"ltp":1.36,"tv":15333.43,"id":8257797}]}]}
{"op":"mcm","clk":"4230362869","pt":1631532099245,"mc":[{"id":"1.187557146","rc":[{"batb":[[0,3.35,12.47],[1,3.05,36.65],[2,1.47,1.54]],"batl":[[0,990,0.01],[1,4.1,0],[2,990,0]],"ltp":3.75,"tv":861.01,"id":19931652},{"batb":[[0,1.25,648.13],[1,1.06,2973.46],[2,1.25,0]],"batl":[[0,1.42,379.14],[1,1.82,475.58],[2,3.8,27.48]],"ltp":1.36,"tv":15333.43,"id":8257797}]}]}
{"op":"mcm","clk":"4230363391","pt":1631532105167,"mc":[{"id":"1.187557146","rc":[{"batb":[[0,1.26,2.89],[1,1.25,136.06],[2,1.06,2973.46]],"batl":[[0,1.42,297.25]],"ltp":1.36,"tv":15333.43,"id":8257797}]}]}
{"op":"mcm","clk":"4230363486","pt":1631532106256,"mc":[{"id":"1.187557146","rc":[{"trd":[[3.5,15.76]],"batb":[[0,3.5,8.91],[1,3.35,18.39],[2,3.05,36.65]],"batl":[[0,3.6,614.64],[1,3.8,52.64],[2,3.9,135.18]],"ltp":3.5,"tv":868.11,"id":19931652},{"trd":[[1.4,22.84]],"batl":[[0,1.4,260.67],[1,1.42,297.25],[2,1.43,52.65]],"ltp":1.4,"tv":15351.17,"id":8257797}],"tv":16219.28}]}
{"op":"mcm","clk":"4230363576","pt":1631532107245,"mc":[{"id":"1.187557146","rc":[{"batb":[[0,3.35,12.47],[1,3.05,36.65],[2,2.9,42.26]],"batl":[[0,3.8,10.52],[1,3.9,135.18],[2,990,0.01]],"ltp":3.5,"tv":868.11,"id":19931652},{"batb":[[0,1.39,82.68],[1,1.33,98.58],[2,1.3,42.94]],"batl":[[0,1.42,336.55],[1,1.43,52.65],[2,1.44,19.38]],"ltp":1.4,"tv":15351.17,"id":8257797}]}]}
{"op":"mcm","clk":"4230363764","pt":1631532109330,"mc":[{"id":"1.187557146","rc":[{"batb":[[0,3.35,18.39]],"batl":[[0,3.5,3.55],[1,3.8,10.52],[2,3.9,135.18]],"ltp":3.5,"tv":868.11,"id":19931652},{"batb":[[0,1.4,8.87],[1,1.39,82.68],[2,1.33,98.58]],"ltp":1.4,"tv":15351.17,"id":8257797}]}]}
{"op":"mcm","clk":"4230363929","pt":1631532111259,"mc":[{"id":"1.187557146","rc":[{"trd":[[3.35,39.05],[3.5,16.84]],"batb":[[0,3.35,1.35]],"batl":[[0,3.5,2.47]],"ltp":3.5,"tv":903.27,"id":19931652},{"trd":[[1.4,43.27]],"batb":[[0,1.39,82.68],[1,1.33,98.58],[2,1.31,484.1]],"ltp":1.4,"tv":15371.6,"id":8257797}],"tv":16274.87}]}
{"op":"mcm","clk":"4230364122","pt":1631532113337,"mc":[{"id":"1.187557146","rc":[{"batb":[[1,3.3,12.78],[2,3.25,14.13]],"ltp":3.5,"tv":903.27,"id":19931652},{"batb":[[0,1.4,155],[1,1.39,82.68],[2,1.33,98.58]],"batl":[[1,1.43,365.15],[2,1.44,312.21]],"ltp":1.4,"tv":15371.6,"id":8257797}]}]}
{"op":"mcm","clk":"4230364406","pt":1631532116330,"mc":[{"id":"1.187557146","rc":[{"batb":[[0,3.3,12.78],[1,3.25,14.13],[2,3.05,36.65]],"batl":[[0,3.8,10.52],[1,3.9,135.18],[2,990,0.01]],"ltp":3.5,"tv":903.27,"id":19931652}]}]}
{"op":"mcm","clk":"4230364441","pt":1631532116642,"mc":[{"id":"1.187557146","rc":[{"trd":[[1.4,43.43]],"batb":[[0,1.4,154.92]],"ltp":1.4,"tv":15371.76,"id":8257797}],"tv":16275.03}]}
{"op":"mcm","clk":"4230364583","pt":1631532118260,"mc":[{"id":"1.187557146","rc":[{"batb":[[0,3.25,14.13],[1,2.9,42.26],[2,1.47,1.54]],"batl":[[0,990,0.01],[1,3.9,0],[2,990,0]],"ltp":3.5,"tv":903.27,"id":19931652},{"batb":[[0,1.33,98.58],[1,1.31,484.1],[2,1.06,2973.46]],"batl":[[0,1.46,79.65],[1,1.82,475.58],[2,3.8,27.48]],"ltp":1.4,"tv":15371.76,"id":8257797}]}]}
{"op":"mcm","clk":"4230364670","pt":1631532119354,"mc":[{"id":"1.187557146","rc":[{"batl":[[0,3.55,3.84],[1,990,0.01]],"ltp":3.5,"tv":903.27,"id":19931652},{"batl":[[0,1.41,13.44],[1,1.46,79.65],[2,1.82,475.58]],"ltp":1.4,"tv":15371.76,"id":8257797}]}]}
{"op":"mcm","clk":"4230364685","pt":1631532119560,"mc":[{"id":"1.187557146","rc":[{"batl":[[0,990,0.01],[1,990,0]],"ltp":3.5,"tv":903.27,"id":19931652},{"batl":[[0,1.46,79.65],[1,1.82,475.58],[2,3.8,27.48]],"ltp":1.4,"tv":15371.76,"id":8257797}]}]}
{"op":"mcm","clk":"4230364830","pt":1631532121169,"mc":[{"id":"1.187557146","rc":[{"batl":[[0,1.44,279.92],[1,1.46,79.65],[2,1.82,475.58]],"ltp":1.4,"tv":15371.76,"id":8257797}]}]}
{"op":"mcm","clk":"4230365094","pt":1631532123948,"mc":[{"id":"1.187557146","rc":[{"trd":[[3.5,16.88]],"ltp":3.5,"tv":903.31,"id":19931652},{"trd":[[1.4,43.53]],"batl":[[0,1.44,279.83]],"ltp":1.4,"tv":15371.85,"id":8257797}],"tv":16275.16}]}
{"op":"mcm","clk":"4230366114","pt":1631532134273,"mc":[{"id":"1.187557146","rc":[{"batb":[[0,3.75,4.49],[1,3.55,40.19],[2,3.25,14.13]],"batl":[[0,3.9,5.63],[1,4,39.26],[2,990,0.01]],"ltp":3.5,"tv":903.31,"id":19931652},{"batl":[[0,1.38,52.65],[1,1.39,309.5],[2,1.4,28.58]],"ltp":1.4,"tv":15371.85,"id":8257797}]}]}
{"op":"mcm","clk":"4230366210","pt":1631532135310,"mc":[{"id":"1.187557146","rc":[{"batb":[[2,3.35,29.12]],"ltp":3.5,"tv":903.31,"id":19931652},{"batb":[[2,1.26,44.3]],"batl":[[0,1.38,93.1],[2,1.4,48.51]],"ltp":1.4,"tv":15371.85,"id":8257797}]}]}
{"op":"mcm","clk":"4230366576","pt":1631532139315,"mc":[{"id":"1.187557146","rc":[{"trd":[[3.9,6.38]],"batl":[[0,4,39.26],[1,990,0.01],[2,990,0]],"ltp":3.9,"tv":908.94,"id":19931652},{"trd":[[1.33,969.54],[1.34,20.75]],"batb":[[0,1.33,96.16]],"ltp":1.33,"tv":15393.08,"id":8257797}],"tv":16302.02}]}
{"op":"mcm","clk":"4230367095","pt":1631532144422,"mc":[{"id":"1.187557146","rc":[{"trd":[[3.75,5.68]],"batb":[[0,3.75,2.94]],"ltp":3.75,"tv":910.49,"id":19931652},{"trd":[[1.37,284.73]],"ltp":1.37,"tv":15397.32,"id":8257797}],"tv":16307.81}]}
{"op":"mcm","clk":"4230367415","pt":1631532147709,"mc":[{"id":"1.187557146","rc":[{"batb":[[0,1.33,149.16]],"ltp":1.37,"tv":15397.32,"id":8257797}]}]}
{"op":"mcm","clk":"4230367550","pt":1631532149312,"mc":[{"id":"1.187557146","rc":[{"batb":[[0,3.55,40.19],[1,3.35,29.12],[2,3.3,11.28]],"ltp":3.75,"tv":910.49,"id":19931652}]}]}
{"op":"mcm","clk":"4230367576","pt":1631532149622,"mc":[{"id":"1.187557146","rc":[{"batb":[[0,1.33,96.16]],"ltp":1.37,"tv":15397.32,"id":8257797}]}]}
{"op":"mcm","clk":"4230367711","pt":1631532151338,"mc":[{"id":"1.187557146","rc":[{"batb":[[2,1.25,141.09]],"batl":[[0,1.38,52.65],[2,1.4,28.58]],"ltp":1.37,"tv":15397.32,"id":8257797}]}]}
{"op":"mcm","clk":"4230367789","pt":1631532152227,"mc":[{"id":"1.187557146","rc":[{"batb":[[0,1.34,12.14],[1,1.33,96.16],[2,1.31,484.1]],"batl":[[0,1.36,18.95],[1,1.38,52.65],[2,1.39,309.5]],"ltp":1.37,"tv":15397.32,"id":8257797}]}]}
{"op":"mcm","clk":"4230368008","pt":1631532154622,"mc":[{"id":"1.187557146","rc":[{"batb":[[0,1.33,96.16],[1,1.31,484.1],[2,1.25,141.09]],"batl":[[0,1.38,52.65],[1,1.39,309.5],[2,1.4,28.58]],"ltp":1.37,"tv":15397.32,"id":8257797}]}]}
{"op":"mcm","clk":"4230368254","pt":1631532157544,"mc":[{"id":"1.187557146","rc":[{"batb":[[0,1.34,12.14],[1,1.33,96.16],[2,1.31,484.1]],"batl":[[0,1.36,18.95],[1,1.38,52.65],[2,1.39,309.5]],"ltp":1.37,"tv":15397.32,"id":8257797}]}]}
{"op":"mcm","clk":"4230368441","pt":1631532159326,"mc":[{"id":"1.187557146","rc":[{"batl":[[0,990,0.01],[1,990,0]],"ltp":3.75,"tv":910.49,"id":19931652},{"batb":[[0,1.33,96.16],[1,1.31,484.1],[2,1.25,141.09]],"batl":[[0,1.39,309.5],[1,1.43,250.5],[2,1.44,279.83]],"ltp":1.37,"tv":15397.32,"id":8257797}]}]}
{"op":"mcm","clk":"4230368480","pt":1631532159740,"mc":[{"id":"1.187557146","rc":[{"batb":[[0,3.15,12.03],[1,3,38.41],[2,1.47,1.54]],"ltp":3.75,"tv":910.49,"id":19931652},{"batb":[[0,1.31,484.1],[1,1.25,141.09],[2,1.06,2973.46]],"batl":[[0,1.46,329.4],[1,1.82,475.58],[2,3.8,27.48]],"ltp":1.37,"tv":15397.32,"id":8257797}]}]}
{"op":"mcm","clk":"4230368803","pt":1631532163337,"mc":[{"id":"1.187557146","rc":[{"batb":[[0,1.25,141.09],[1,1.06,2973.46],[2,1.06,0]],"ltp":1.37,"tv":15397.32,"id":8257797}]}]}
{"op":"mcm","clk":"4230369101","pt":1631532166920,"mc":[{"id":"1.187557146","rc":[{"batb":[[0,1.25,653.15]],"ltp":1.37,"tv":15397.32,"id":8257797}]}]}
{"op":"mcm","clk":"4230369190","pt":1631532168218,"mc":[{"id":"1.187557146","rc":[{"batl":[[0,4,65],[1,990,0.01]],"ltp":3.75,"tv":910.49,"id":19931652}]}]}
{"op":"mcm","clk":"4230369350","pt":1631532170242,"mc":[{"id":"1.187557146","rc":[{"batb":[[0,3.3,11.88],[1,3.15,12.03],[2,3,38.41]],"ltp":3.75,"tv":910.49,"id":19931652},{"batl":[[0,1.43,265.5],[1,1.46,329.4],[2,1.82,475.58]],"ltp":1.37,"tv":15397.32,"id":8257797}]}]}
{"op":"mcm","clk":"4230369366","pt":1631532170446,"mc":[{"id":"1.187557146","rc":[{"batb":[[0,3.15,12.03],[1,3,38.41],[2,1.47,1.54]],"ltp":3.75,"tv":910.49,"id":19931652},{"batl":[[0,1.46,329.4],[1,1.82,475.58],[2,3.8,27.48]],"ltp":1.37,"tv":15397.32,"id":8257797}]}]}
{"op":"mcm","clk":"4230369713","pt":1631532175120,"mc":[{"id":"1.187557146","rc":[{"batl":[[0,990,0.01],[1,990,0]],"ltp":3.75,"tv":910.49,"id":19931652}]}]}
{"op":"mcm","clk":"4230369870","pt":1631532177136,"mc":[{"id":"1.187557146","rc":[{"batb":[[0,3.3,11.38],[1,3.15,12.03],[2,3,38.41]],"ltp":3.75,"tv":910.49,"id":19931652},{"batl":[[0,1.43,253.5],[1,1.46,329.4],[2,1.82,475.58]],"ltp":1.37,"tv":15397.32,"id":8257797}]}]}
{"op":"mcm","clk":"4230369893","pt":1631532177447,"mc":[{"id":"1.187557146","rc":[{"batb":[[0,3.15,12.03],[1,3,38.41],[2,1.47,1.54]],"ltp":3.75,"tv":910.49,"id":19931652},{"batl":[[0,1.46,329.4],[1,1.82,475.58],[2,3.8,27.48]],"ltp":1.37,"tv":15397.32,"id":8257797}]}]}
{"op":"mcm","clk":"4230370444","pt":1631532183270,"mc":[{"id":"1.187557146","rc":[{"batl":[[0,1.46,330.14]],"ltp":1.37,"tv":15397.32,"id":8257797}]}]}
{"op":"mcm","clk":"4230370476","pt":1631532183639,"mc":[{"id":"1.187557146","rc":[{"batb":[[0,1.25,141.09]],"batl":[[1,3.8,27.48],[2,8.8,7.23]],"ltp":1.37,"tv":15397.32,"id":8257797}]}]}
{"op":"mcm","clk":"4230370639","pt":1631532185354,"mc":[{"id":"1.187557146","rc":[{"batb":[[0,4.3,9.3],[1,4.2,35.82],[2,4,35.82]],"batl":[[0,5.1,59.28],[1,990,0.01]],"ltp":3.75,"tv":910.49,"id":19931652},{"batb":[[0,1.26,14.98],[1,1.25,141.09],[2,1.19,46.91]],"batl":[[0,1.28,27.28],[1,1.3,95.59],[2,1.31,347.5]],"ltp":1.37,"tv":15397.32,"id":8257797}]}]}
{"op":"mcm","clk":"4230370799","pt":1631532187266,"mc":[{"id":"1.187557146","rc":[{"batb":[[2,1.2,538.19]],"ltp":1.37,"tv":15397.32,"id":8257797}]}]}
{"op":"mcm","clk":"4230370958","pt":1631532189341,"mc":[{"id":"1.187557146","rc":[{"batl":[[1,5.4,44.96],[2,990,0.01]],"ltp":3.75,"tv":910.49,"id":19931652},{"trd":[[1.26,322.57]],"batb":[[0,1.26,95.31]],"batl":[[0,1.28,118.13]],"ltp":1.26,"tv":15526.66,"id":8257797}],"tv":16437.15}]}
{"op":"mcm","clk":"4230370966","pt":1631532189446,"mc":[{"id":"1.187557146","rc":[{"batl":[[1,990,0.01],[2,990,0]],"ltp":3.75,"tv":910.49,"id":19931652}]}]}
{"op":"mcm","clk":"4230371475","pt":1631532195346,"mc":[{"id":"1.187557146","rc":[{"trd":[[1.26,324.43]],"batb":[[0,1.26,94.38]],"ltp":1.26,"tv":15528.52,"id":8257797}],"tv":16439.01}]}
{"op":"mcm","clk":"4230371877","pt":1631532199872,"mc":[{"id":"1.187557146","rc":[{"trd":[[1.28,37.86]],"batl":[[0,1.28,90.74]],"ltp":1.28,"tv":15528.75,"id":8257797}],"tv":16439.24}]}
{"op":"mcm","clk":"4230372045","pt":1631532201580,"mc":[{"id":"1.187557146","rc":[{"batl":[[1,1.3,52.65]],"ltp":1.28,"tv":15528.75,"id":8257797}]}]}
{"op":"mcm","clk":"4230372138","pt":1631532202467,"mc":[{"id":"1.187557146","rc":[{"batl":[[0,5,5.89],[1,5.1,59.28],[2,990,0.01]],"ltp":3.75,"tv":910.49,"id":19931652},{"batl":[[0,1.27,21.81],[1,1.28,90.74],[2,1.3,52.65]],"ltp":1.28,"tv":15528.75,"id":8257797}]}]}
{"op":"mcm","clk":"4230372364","pt":1631532205066,"mc":[{"id":"1.187557146","rc":[{"trd":[[1.27,583.6],[1.28,175.56]],"batl":[[0,1.28,21.88],[1,1.3,52.65],[2,1.31,347.5]],"ltp":1.28,"tv":15710.07,"id":8257797}],"tv":16620.56}]}
{"op":"mcm","clk":"4230372650","pt":1631532208288,"mc":[{"id":"1.187557146","rc":[{"batb":[[0,3.7,9.02],[1,3.5,10.46],[2,3.4,37.74]],"batl":[[0,990,0.01],[1,5.1,0],[2,990,0]],"ltp":3.75,"tv":910.49,"id":19931652},{"trd":[[1.26,341.47]],"batb":[[0,1.2,538.19],[1,1.14,248.7],[2,1.06,2973.46]],"batl":[[1,1.37,219.5],[2,1.4,227.49]],"ltp":1.26,"tv":15727.11,"id":8257797}],"tv":16637.6}]}
{"op":"mcm","clk":"4230372899","pt":1631532211199,"mc":[{"id":"1.187557146","rc":[{"batl":[[0,7,3.09],[1,7.4,3],[2,7.8,3]],"ltp":3.75,"tv":910.49,"id":19931652},{"batb":[[1,1.17,109],[2,1.16,113]],"ltp":1.26,"tv":15727.11,"id":8257797}]}]}
{"op":"mcm","clk":"4230373165","pt":1631532214127,"mc":[{"id":"1.187557146","rc":[{"batb":[[0,1.17,109],[1,1.16,113],[2,1.15,117]],"ltp":1.26,"tv":15727.11,"id":8257797}]}]}
{"op":"mcm","clk":"4230373261","pt":1631532215319,"mc":[{"id":"1.187557146","rc":[{"batb":[[0,3.6,20.25]],"batl":[[0,3.95,50.64],[1,4.1,50.83],[2,7,3.09]],"ltp":3.75,"tv":910.49,"id":19931652},{"batb":[[0,1.34,12.73],[1,1.17,109],[2,1.16,113]],"batl":[[0,1.36,18.17],[1,1.4,227.49],[2,1.41,203.5]],"ltp":1.26,"tv":15727.11,"id":8257797}]}]}
{"op":"mcm","clk":"4230373340","pt":1631532216207,"mc":[{"id":"1.187557146","rc":[{"batl":[[0,3.95,10.12],[2,6,3.09]],"ltp":3.75,"tv":910.49,"id":19931652},{"batb":[[0,1.33,101.34],[1,1.26,44.3],[2,1.24,167.44]],"batl":[[0,1.37,40.74],[1,1.39,20.08],[2,1.4,227.49]],"ltp":1.26,"tv":15727.11,"id":8257797}]}]}
{"op":"mcm","clk":"4230373365","pt":1631532216520,"mc":[{"id":"1.187557146","rc":[{"batl":[[2,6,3]],"ltp":3.75,"tv":910.49,"id":19931652}]}]}
{"op":"mcm","clk":"4230373504","pt":1631532218294,"mc":[{"id":"1.187557146","rc":[{"batl":[[2,4.5,6.22]],"ltp":3.75,"tv":910.49,"id":19931652},{"batb":[[0,1.34,12.73],[1,1.33,101.34],[2,1.26,44.3]],"batl":[[0,1.36,18.17],[1,1.37,40.74],[2,1.39,20.08]],"ltp":1.26,"tv":15727.11,"id":8257797}]}]}
{"op":"mcm","clk":"4230373538","pt":1631532218704,"mc":[{"id":"1.187557146","rc":[{"batl":[[2,6,3]],"ltp":3.75,"tv":910.49,"id":19931652}]}]}
{"op":"mcm","clk":"4230373654","pt":1631532220210,"mc":[{"id":"1.187557146","rc":[{"trd":[[1.33,973.48],[1.34,46.21]],"batb":[[0,1.33,99.37],[1,1.26,44.3],[2,1.25,512.06]],"batl":[[0,1.36,38.77]],"ltp":1.33,"tv":15756.51,"id":8257797}],"tv":16667.0}]}
{"op":"mcm","clk":"4230373988","pt":1631532224010,"mc":[{"id":"1.187557146","rc":[{"batl":[[0,1.34,8.52],[1,1.36,38.77],[2,1.37,40.74]],"ltp":1.33,"tv":15756.51,"id":8257797}]}]}
{"op":"mcm","clk":"4230374347","pt":1631532228957,"mc":[{"id":"1.187557146","rc":[{"batb":[[0,3.25,12.49],[1,3.05,36.82],[2,1.47,1.54]],"batl":[[0,6,3],[1,6.4,3],[2,6.6,3]],"ltp":3.75,"tv":910.49,"id":19931652},{"batb":[[0,1.25,512.06],[1,1.24,144.93],[2,1.2,100]],"batl":[[1,1.36,20.6],[2,1.44,221.58]],"ltp":1.33,"tv":15756.51,"id":8257797}]}]}
{"op":"mcm","clk":"4230375062","pt":1631532237357,"mc":[{"id":"1.187557146","rc":[{"batl":[[0,1.36,20.6],[1,1.37,4]],"ltp":1.33,"tv":15756.51,"id":8257797}]}]}
{"op":"mcm","clk":"4230375119","pt":1631532237934,"mc":[{"id":"1.187557146","rc":[{"batl":[[1,1.44,221.58],[2,1.66,587.81]],"ltp":1.33,"tv":15756.51,"id":8257797}]}]}
{"op":"mcm","clk":"4230375838","pt":1631532246240,"mc":[{"id":"1.187557146","rc":[{"batb":[[0,3.4,12.31],[1,3.25,12.49],[2,3.05,36.82]],"ltp":3.75,"tv":910.49,"id":19931652},{"batl":[[1,1.41,273.5],[2,1.44,221.58]],"ltp":1.33,"tv":15756.51,"id":8257797}]}]}
{"op":"mcm","clk":"4230375855","pt":1631532246449,"mc":[{"id":"1.187557146","rc":[{"batb":[[0,3.25,12.49],[1,3.05,36.82],[2,1.47,1.54]],"ltp":3.75,"tv":910.49,"id":19931652},{"batl":[[1,1.44,221.58],[2,1.66,587.81]],"ltp":1.33,"tv":15756.51,"id":8257797}]}]}
{"op":"mcm","clk":"4230376372","pt":1631532253160,"mc":[{"id":"1.187557146","rc":[{"batb":[[0,3.4,10.81],[1,3.25,12.49],[2,3.05,36.82]],"ltp":3.75,"tv":910.49,"id":19931652},{"batl":[[1,1.41,232.5],[2,1.44,221.58]],"ltp":1.33,"tv":15756.51,"id":8257797}]}]}
{"op":"mcm","clk":"4230376399","pt":1631532253469,"mc":[{"id":"1.187557146","rc":[{"batb":[[0,3.25,12.49],[1,3.05,36.82],[2,1.47,1.54]],"ltp":3.75,"tv":910.49,"id":19931652},{"batl":[[1,1.44,221.58],[2,1.66,587.81]],"ltp":1.33,"tv":15756.51,"id":8257797}]}]}
{"op":"mcm","clk":"4230376492","pt":1631532254665,"mc":[{"id":"1.187557146","rc":[{"batl":[[0,1.44,221.58],[1,1.66,587.81],[2,3.8,27.48]],"ltp":1.33,"tv":15756.51,"id":8257797}]}]}
{"op":"mcm","clk":"4230376919","pt":1631532260159,"mc":[{"id":"1.187557146","rc":[{"batb":[[0,3.4,11.96],[1,3.25,12.49],[2,3.05,36.82]],"ltp":3.75,"tv":910.49,"id":19931652},{"batl":[[0,1.41,240.5],[1,1.44,221.58],[2,1.66,587.81]],"ltp":1.33,"tv":15756.51,"id":8257797}]}]}
{"op":"mcm","clk":"4230376940","pt":1631532260465,"mc":[{"id":"1.187557146","rc":[{"batb":[[0,3.25,12.49],[1,3.05,36.82],[2,1.47,1.54]],"ltp":3.75,"tv":910.49,"id":19931652},{"batl":[[0,1.44,221.58],[1,1.66,587.81],[2,3.8,27.48]],"ltp":1.33,"tv":15756.51,"id":8257797}]}]}
{"op":"mcm","clk":"4230377194","pt":1631532263987,"mc":[{"id":"1.187557146","rc":[{"batb":[[0,1.24,144.93],[1,1.2,100],[2,1.19,103]],"batl":[[1,3.8,27.48],[2,8.8,7.23]],"ltp":1.33,"tv":15756.51,"id":8257797}]}]}
{"op":"mcm","clk":"4230377264","pt":1631532264870,"mc":[{"id":"1.187557146","rc":[{"batb":[[0,3.25,35.89]],"batl":[[0,4.1,238.99],[1,6,3],[2,6.4,3]],"ltp":3.75,"tv":910.49,"id":19931652},{"batb":[[0,1.39,11.83],[1,1.38,28.98],[2,1.31,42.61]],"batl":[[0,1.41,14.77],[1,1.44,260.34],[2,1.46,19.12]],"ltp":1.33,"tv":15756.51,"id":8257797}]}]}
{"op":"mcm","clk":"4230377331","pt":1631532266011,"mc":[{"id":"1.187557146","rc":[{"batb":[[2,2.64,21.67]],"ltp":3.75,"tv":910.49,"id":19931652},{"batb":[[0,1.39,94.26],[2,1.33,99.91]],"ltp":1.33,"tv":15756.51,"id":8257797}]}]}
{"op":"mcm","clk":"4230377419","pt":1631532267104,"mc":[{"id":"1.187557146","rc":[{"batl":[[1,1.42,19.72],[2,1.44,260.34]],"ltp":1.33,"tv":15756.51,"id":8257797}]}]}
{"op":"mcm","clk":"4230377587","pt":1631532269284,"mc":[{"id":"1.187557146","rc":[{"batb":[[0,1.39,201.26]],"ltp":1.33,"tv":15756.51,"id":8257797}]}]}
{"op":"mcm","clk":"4230378083","pt":1631532275690,"mc":[{"id":"1.187557146","rc":[{"trd":[[1.41,50.77]],"batb":[[0,1.41,6.01],[1,1.39,201.26],[2,1.38,28.98]],"batl":[[0,1.42,19.72],[1,1.44,260.34],[2,1.46,19.12]],"ltp":1.41,"tv":15786.05,"id":8257797}],"tv":16696.54}]}
{"op":"mcm","clk":"4230378389","pt":1631532279900,"mc":[{"id":"1.187557146","rc":[{"batl":[[0,3.5,15],[1,4.1,238.99],[2,6,3]],"ltp":3.75,"tv":910.49,"id":19931652}]}]}
{"op":"mcm","clk":"4230378474","pt":1631532281087,"mc":[{"id":"1.187557146","rc":[{"trd":[[1.41,51.54]],"batb":[[0,1.41,5.62]],"ltp":1.41,"tv":15786.82,"id":8257797}],"tv":16697.31}]}
{"op":"mcm","clk":"4230378560","pt":1631532282324,"mc":[{"id":"1.187557146","rc":[{"trd":[[1.41,55.14]],"batb":[[0,1.41,3.82]],"ltp":1.41,"tv":15790.42,"id":8257797}],"tv":16700.91}]}
{"op":"mcm","clk":"4230378855","pt":1631532286218,"mc":[{"id":"1.187557146","rc":[{"trd":[[3.35,41.04]],"ltp":3.35,"tv":912.48,"id":19931652},{"trd":[[1.42,13.94]],"batb":[[1,1.39,189.43]],"batl":[[0,1.42,10.4]],"ltp":1.42,"tv":15804.36,"id":8257797}],"tv":16716.84}]}
{"op":"mcm","clk":"4230379050","pt":1631532288797,"mc":[{"id":"1.187557146","rc":[{"batl":[[0,3.5,20.22]],"ltp":3.35,"tv":912.48,"id":19931652},{"batl":[[0,1.42,22.84]],"ltp":1.42,"tv":15804.36,"id":8257797}]}]}
{"op":"mcm","clk":"4230379164","pt":1631532290136,"mc":[{"id":"1.187557146","rc":[{"trd":[[1.41,62.79]],"batb":[[0,1.39,189.43],[1,1.38,28.98],[2,1.33,99.91]],"batl":[[0,1.41,4.71],[1,1.42,22.84],[2,1.44,260.34]],"ltp":1.41,"tv":15812.01,"id":8257797}],"tv":16724.49}]}
{"op":"mcm","clk":"4230379928","pt":1631532300231,"mc":[{"id":"1.187557146","rc":[{"batl":[[0,1.42,23.04],[1,1.44,260.34],[2,1.46,19.12]],"ltp":1.41,"tv":15812.01,"id":8257797}]}]}
{"op":"mcm","clk":"4230380033","pt":1631532301538,"mc":[{"id":"1.187557146","rc":[{"trd":[[3.5,36.88]],"batl":[[0,4.1,239.21],[1,6,3],[2,6.4,3]],"ltp":3.5,"tv":932.48,"id":19931652},{"trd":[[1.4,93.53]],"ltp":1.4,"tv":15862.01,"id":8257797}],"tv":16794.49}]}
{"op":"mcm","clk":"4230380307","pt":1631532305165,"mc":[{"id":"1.187557146","rc":[{"trd":[[3.5,37.1]],"batl":[[0,4,17.77],[1,4.1,238.99],[2,6,3]],"ltp":3.5,"tv":932.7,"id":19931652},{"trd":[[1.4,94.08]],"batl":[[0,1.42,23.42]],"ltp":1.4,"tv":15862.56,"id":8257797}],"tv":16795.26}]}
{"op":"mcm","clk":"4230380351","pt":1631532305842,"mc":[{"id":"1.187557146","rc":[{"trd":[[3.35,48.51],[3.4,0.08],[3.5,37.25]],"ltp":3.35,"tv":940.4,"id":19931652},{"trd":[[1.4,94.46],[1.41,62.99],[1.42,31.56]],"batl":[[0,1.42,5.22]],"ltp":1.42,"tv":15880.76,"id":8257797}],"tv":16821.17}]}
{"op":"mcm","clk":"4230380831","pt":1631532312357,"mc":[{"id":"1.187557146","rc":[{"batl":[[0,4.1,238.99],[1,6,3],[2,6.4,3]],"ltp":3.35,"tv":940.4,"id":19931652},{"batb":[[0,1.39,82.43]],"batl":[[0,1.44,260.34],[1,1.46,19.12],[2,1.89,441.29]],"ltp":1.42,"tv":15880.76,"id":8257797}]}]}
{"op":"mcm","clk":"4230381030","pt":1631532314638,"mc":[{"id":"1.187557146","rc":[{"batb":[[0,3.4,5.85],[1,3.25,35.89],[2,3.05,36.82]],"batl":[[0,3.55,7.06],[1,4.1,238.99],[2,6,3]],"ltp":3.35,"tv":940.4,"id":19931652}]}]}
{"op":"mcm","clk":"4230381100","pt":1631532315364,"mc":[{"id":"1.187557146","rc":[{"batb":[[0,3.25,35.89],[1,3.05,36.82],[2,2.64,21.67]],"batl":[[0,4.1,238.99],[1,6,3],[2,6.4,3]],"ltp":3.35,"tv":940.4,"id":19931652}]}]}
{"op":"mcm","clk":"4230381394","pt":1631532318284,"mc":[{"id":"1.187557146","rc":[{"batb":[[0,3.4,5.85],[1,3.25,35.89],[2,3.05,36.82]],"batl":[[0,3.55,7.06],[1,4.1,238.99],[2,6,3]],"ltp":3.35,"tv":940.4,"id":19931652}]}]}
{"op":"mcm","clk":"4230381483","pt":1631532319063,"mc":[{"id":"1.187557146","rc":[{"batb":[[0,3.25,35.89],[1,3.05,36.82],[2,2.64,21.67]],"batl":[[0,4.1,238.99],[1,6,3],[2,6.4,3]],"ltp":3.35,"tv":940.4,"id":19931652}]}]}
{"op":"mcm","clk":"4230381758","pt":1631532322277,"mc":[{"id":"1.187557146","rc":[{"batb":[[0,3.4,5.85],[1,3.25,35.89],[2,3.05,36.82]],"batl":[[0,3.55,7.06],[1,4.1,248.05],[2,6,3]],"ltp":3.35,"tv":940.4,"id":19931652}]}]}
{"op":"mcm","clk":"4230381844","pt":1631532323209,"mc":[{"id":"1.187557146","rc":[{"batl":[[1,4.1,238.99]],"ltp":3.35,"tv":940.4,"id":19931652},{"trd":[[1.39,56.68]],"batb":[[0,1.39,81.5]],"ltp":1.39,"tv":15882.62,"id":8257797}],"tv":16823.03}]}
{"op":"mcm","clk":"4230382199","pt":1631532327299,"mc":[{"id":"1.187557146","rc":[{"trd":[[3.25,71.88],[3.4,11.78]],"batb":[[0,3.05,36.82],[1,2.64,21.67],[2,1.47,1.54]],"ltp":3.25,"tv":1023.98,"id":19931652},{"trd":[[1.44,0.23]],"batl":[[0,1.44,260.11]],"ltp":1.44,"tv":15882.85,"id":8257797}],"tv":16906.84}]}
{"op":"mcm","clk":"4230382791","pt":1631532334814,"mc":[{"id":"1.187557146","rc":[{"trd":[[1.39,76.68]],"batb":[[0,1.39,71.5]],"ltp":1.39,"tv":15902.85,"id":8257797}],"tv":16926.84}]}
{"op":"mcm","clk":"4230382873","pt":1631532336115,"mc":[{"id":"1.187557146","rc":[{"trd":[[1.39,76.86]],"batb":[[0,1.39,71.4]],"ltp":1.39,"tv":15903.03,"id":8257797}],"tv":16927.02}]}
{"op":"mcm","clk":"4230382916","pt":1631532336939,"mc":[{"id":"1.187557146","rc":[{"batl":[[0,4.1,238.99],[1,6,3],[2,6.4,3]],"ltp":3.25,"tv":1023.98,"id":19931652}]}]}
{"op":"mcm","clk":"4230383143","pt":1631532339835,"mc":[{"id":"1.187557146","rc":[{"batb":[[0,3.35,4.58],[1,3.05,36.82],[2,2.64,21.67]],"batl":[[0,3.5,4.3],[1,4.1,238.99],[2,6,3]],"ltp":3.25,"tv":1023.98,"id":19931652},{"batb":[[0,1.4,10.75],[1,1.39,71.4],[2,1.38,28.98]],"ltp":1.39,"tv":15903.03,"id":8257797}]}]}
{"op":"mcm","clk":"4230383327","pt":1631532342625,"mc":[{"id":"1.187557146","rc":[{"trd":[[3.5,41.55]],"batl":[[0,4.1,238.99],[1,6,3],[2,6.4,3]],"ltp":3.5,"tv":1028.28,"id":19931652},{"trd":[[1.39,90.56],[1.4,126.71]],"batb":[[0,1.39,64.55],[1,1.38,28.98],[2,1.33,99.91]],"ltp":1.39,"tv":15948.98,"id":8257797}],"tv":16977.27}]}
{"op":"mcm","clk":"4230383580","pt":1631532345837,"mc":[{"id":"1.187557146","rc":[{"batb":[[0,1.39,175.55]],"ltp":1.39,"tv":15948.98,"id":8257797}]}]}
{"op":"mcm","clk":"4230383738","pt":1631532347862,"mc":[{"id":"1.187557146","rc":[{"trd":[[1.39,90.66]],"batb":[[0,1.39,175.51]],"ltp":1.39,"tv":15949.08,"id":8257797}],"tv":16977.37}]}
{"op":"mcm","clk":"4230384012","pt":1631532351847,"mc":[{"id":"1.187557146","rc":[{"batl":[[0,1.44,221.35],[1,1.89,441.29],[2,3.8,27.48]],"ltp":1.39,"tv":15949.08,"id":8257797}]}]}
{"op":"mcm","clk":"4230384107","pt":1631532353063,"mc":[{"id":"1.187557146","rc":[{"batb":[[0,3.05,36.82],[1,2.64,21.67],[2,1.47,1.54]],"ltp":3.5,"tv":1028.28,"id":19931652},{"batb":[[0,1.39,64.51]],"ltp":1.39,"tv":15949.08,"id":8257797}]}]}
{"op":"mcm","clk":"4230384198","pt":1631532354256,"mc":[{"id":"1.187557146","rc":[{"trd":[[1.39,110.66]],"batb":[[0,1.39,54.51]],"ltp":1.39,"tv":15969.08,"id":8257797}],"tv":16997.37}]}
{"op":"mcm","clk":"4230384306","pt":1631532355960,"mc":[{"id":"1.187557146","rc":[{"batb":[[1,2.92,13.19],[2,2.78,13.16]],"batl":[[0,3.55,4.17],[1,4.1,238.99],[2,6,3]],"ltp":3.5,"tv":1028.28,"id":19931652},{"batl":[[0,1.41,12.99],[1,1.44,221.35],[2,1.52,204.01]],"ltp":1.39,"tv":15969.08,"id":8257797}]}]}
{"op":"mcm","clk":"4230384642","pt":1631532360575,"mc":[{"id":"1.187557146","rc":[{"batb":[[1,2.96,13.63],[2,2.92,13.19]],"ltp":3.5,"tv":1028.28,"id":19931652},{"batl":[[2,1.51,219.5]],"ltp":1.39,"tv":15969.08,"id":8257797}]}]}
{"op":"mcm","clk":"4230384724","pt":1631532361462,"mc":[{"id":"1.187557146","rc":[{"batb":[[0,1.39,220.51]],"ltp":1.39,"tv":15969.08,"id":8257797}]}]}
{"op":"mcm","clk":"4230385158","pt":1631532367174,"mc":[{"id":"1.187557146","rc":[{"trd":[[1.39,119.68]],"batb":[[0,1.39,216]],"ltp":1.39,"tv":15978.1,"id":8257797}],"tv":17006.39}]}
{"op":"mcm","clk":"4230385397","pt":1631532370287,"mc":[{"id":"1.187557146","rc":[{"batb":[[1,2.8,12.18],[2,2.64,21.67]],"batl":[[0,6,3],[1,6.4,3],[2,6.6,3]],"ltp":3.5,"tv":1028.28,"id":19931652},{"batb":[[0,1.39,50],[1,1.33,99.91],[2,1.31,484.1]],"batl":[[0,1.89,441.29],[1,3.8,27.48],[2,8.8,7.23]],"ltp":1.39,"tv":15978.1,"id":8257797}]}]}
{"op":"mcm","clk":"4230385408","pt":1631532370392,"mc":[{"id":"1.187557146","rc":[{"batb":[[0,2.8,12.18],[1,2.64,21.42],[2,1.47,1.54]],"ltp":3.5,"tv":1028.28,"id":19931652},{"batb":[[0,1.33,99.91],[1,1.31,484.1],[2,1.2,100]],"ltp":1.39,"tv":15978.1,"id":8257797}]}]}
{"op":"mcm","clk":"4230385623","pt":1631532373659,"mc":[{"id":"1.187557146","rc":[{"batl":[[0,1.55,193.9],[1,1.89,441.29],[2,3.8,27.48]],"ltp":1.39,"tv":15978.1,"id":8257797}]}]}
{"op":"mcm","clk":"4230386516","pt":1631532386113,"mc":[{"id":"1.187557146","rc":[{"batb":[[0,2.96,11.88],[1,2.8,12.18],[2,2.64,21.42]],"ltp":3.5,"tv":1028.28,"id":19931652},{"batl":[[0,1.51,224.5],[1,1.55,193.9],[2,1.89,441.29]],"ltp":1.39,"tv":15978.1,"id":8257797}]}]}
{"op":"mcm","clk":"4230386599","pt":1631532387307,"mc":[{"id":"1.187557146","rc":[{"batb":[[0,2.8,12.18],[1,2.64,21.42],[2,1.47,1.54]],"ltp":3.5,"tv":1028.28,"id":19931652},{"batl":[[0,1.55,193.9],[1,1.89,441.29],[2,3.8,27.48]],"ltp":1.39,"tv":15978.1,"id":8257797}]}]}
{"op":"mcm","clk":"4230387362","pt":1631532397646,"mc":[{"id":"1.187557146","rc":[{"batb":[[1,1.2,100],[2,1.19,103]],"ltp":1.39,"tv":15978.1,"id":8257797}]}]}
{"op":"mcm","clk":"4230387469","pt":1631532399111,"mc":[{"id":"1.187557146","rc":[{"batb":[[0,2.96,5.22],[1,2.8,12.18],[2,2.64,21.42]],"batl":[[0,3.05,6.02],[1,6,3],[2,6.4,3]],"ltp":3.5,"tv":1028.28,"id":19931652},{"batb":[[0,1.48,186.98],[1,1.39,40.16],[2,1.37,20.37]],"batl":[[0,1.53,36.48],[1,1.55,211.9],[2,1.89,441.29]],"ltp":1.39,"tv":15978.1,"id":8257797}]}]}
{"op":"mcm","clk":"4230387536","pt":1631532400248,"mc":[{"id":"1.187557146","rc":[{"batb":[[0,1.49,60.5],[1,1.48,186.98],[2,1.4,77.91]],"ltp":1.39,"tv":15978.1,"id":8257797}]}]}
{"op":"mcm","clk":"4230387768","pt":1631532403351,"mc":[{"id":"1.187557146","rc":[{"trd":[[1.49,4]],"batb":[[0,1.49,58.5]],"ltp":1.49,"tv":15982.1,"id":8257797}],"tv":17010.39}]}
{"op":"mcm","clk":"4230387836","pt":1631532404238,"mc":[{"id":"1.187557146","rc":[{"trd":[[2.96,3.72]],"batb":[[0,2.96,2.74]],"ltp":2.96,"tv":1032.0,"id":19931652},{"trd":[[1.49,8.26],[1.52,2.41]],"batb":[[0,1.49,56.37],[2,1.44,1.7]],"ltp":1.52,"tv":15988.77,"id":8257797}],"tv":17020.78}]}
{"op":"mcm","clk":"4230388043","pt":1631532406954,"mc":[{"id":"1.187557146","rc":[{"batl":[[2,1.68,201.89]],"ltp":1.52,"tv":15988.77,"id":8257797}]}]}
{"op":"mcm","clk":"4230388341","pt":1631532410339,"mc":[{"id":"1.187557146","rc":[{"batb":[[0,2.34,14.22],[1,2.26,33.14],[2,1.47,1.54]],"batl":[[0,6,3],[1,6.4,3],[2,6.6,3]],"ltp":2.96,"tv":1032.0,"id":19931652},{"batb":[[0,1.44,1.7],[1,1.4,77.91],[2,1.38,454.63]],"batl":[[0,1.89,441.29],[1,3.8,27.48],[2,8.8,7.23]],"ltp":1.52,"tv":15988.77,"id":8257797}]}]}
{"op":"mcm","clk":"4230388401","pt":1631532410962,"mc":[{"id":"1.187557146","rc":[{"batl":[[0,1.49,9.02],[1,1.89,441.29],[2,3.8,27.48]],"ltp":1.52,"tv":15988.77,"id":8257797}]}]}
{"op":"mcm","clk":"4230388622","pt":1631532413355,"mc":[{"id":"1.187557146","rc":[{"batb":[[0,2.46,14.38],[1,2.34,14.22],[2,2.26,33.14]],"ltp":2.96,"tv":1032.0,"id":19931652},{"batb":[[1,1.41,76.74],[2,1.4,77.91]],"batl":[[0,1.49,10.82],[1,1.68,188.64],[2,1.74,190.25]],"ltp":1.52,"tv":15988.77,"id":8257797}]}]}
{"op":"mcm","clk":"4230388657","pt":1631532413771,"mc":[{"id":"1.187557146","rc":[{"trd":[[3,5.37]],"batb":[[0,2.34,14.22],[1,2.26,33.14],[2,1.47,1.54]],"batl":[[0,2.96,44.63],[1,6,3],[2,6.4,3]],"ltp":3.0,"tv":1037.37,"id":19931652},{"trd":[[1.49,19.08]],"batb":[[2,1.38,454.63]],"batl":[[0,1.74,190.25],[1,1.89,441.29],[2,3.8,27.48]],"ltp":1.49,"tv":15999.59,"id":8257797}],"tv":17036.97}]}
{"op":"mcm","clk":"4230388943","pt":1631532417068,"mc":[{"id":"1.187557146","rc":[{"batb":[[2,1.2,100]],"batl":[[1,3.8,27.48],[2,8.8,7.23]],"ltp":1.49,"tv":15999.59,"id":8257797}]}]}
{"op":"mcm","clk":"4230389014","pt":1631532417952,"mc":[{"id":"1.187557146","rc":[{"trd":[[2.96,7.72]],"batl":[[0,2.96,42.63]],"ltp":2.96,"tv":1041.37,"id":19931652}],"tv":17040.97}]}
{"op":"mcm","clk":"4230389098","pt":1631532419069,"mc":[{"id":"1.187557146","rc":[{"batl":[[0,2.56,10],[1,2.58,15.5],[2,2.96,42.63]],"ltp":2.96,"tv":1041.37,"id":19931652},{"batb":[[0,1.51,36.97],[1,1.49,18.73],[2,1.48,1012.45]],"batl":[[0,1.67,33.42],[1,1.68,11.49],[2,1.69,16.52]],"ltp":1.49,"tv":15999.59,"id":8257797}]}]}
{"op":"mcm","clk":"4230389185","pt":1631532419960,"mc":[{"id":"1.187557146","rc":[{"batb":[[2,1.94,52.22]],"batl":[[2,6,3]],"ltp":2.96,"tv":1041.37,"id":19931652},{"batb":[[0,1.66,41.09],[1,1.54,53.56],[2,1.51,36.97]],"ltp":1.49,"tv":15999.59,"id":8257797}]}]}
{"op":"mcm","clk":"4230389456","pt":1631532423158,"mc":[{"id":"1.187557146","rc":[{"trd":[[2.48,1.54]],"ltp":2.48,"tv":1042.91,"id":19931652},{"trd":[[1.66,4],[1.67,7.01]],"batb":[[0,1.66,39.09]],"batl":[[0,1.67,28.77]],"ltp":1.66,"tv":16010.6,"id":8257797}],"tv":17053.52}]}
{"op":"mcm","clk":"4230389528","pt":1631532423891,"mc":[{"id":"1.187557146","rc":[{"trd":[[1.66,4.19]],"batb":[[0,1.66,38.99]],"ltp":1.66,"tv":16010.79,"id":8257797}],"tv":17053.71}]}
{"op":"mcm","clk":"4230389574","pt":1631532424469,"mc":[{"id":"1.187557146","rc":[{"trd":[[1.66,10.64]],"batb":[[0,1.66,35.77]],"ltp":1.66,"tv":16017.24,"id":8257797}],"tv":17060.16}]}
{"op":"mcm","clk":"4230389751","pt":1631532426348,"mc":[{"id":"1.187557146","rc":[{"batb":[[2,2.08,17.06]],"ltp":2.48,"tv":1042.91,"id":19931652}]}]}
{"op":"mcm","clk":"4230389905","pt":1631532428283,"mc":[{"id":"1.187557146","rc":[{"trd":[[2.48,12.74]],"ltp":2.48,"tv":1054.11,"id":19931652},{"trd":[[1.67,23.64]],"batl":[[0,1.67,12.14]],"ltp":1.67,"tv":16033.88,"id":8257797}],"tv":17088.0}]}
{"op":"mcm","clk":"4230390393","pt":1631532434264,"mc":[{"id":"1.187557146","rc":[{"batb":[[0,2,55.09],[1,1.94,52.22],[2,1.47,1.54]],"batl":[[0,6,3],[1,6.4,3],[2,6.6,3]],"ltp":2.48,"tv":1054.11,"id":19931652},{"batb":[[0,1.54,53.56],[1,1.5,432.79],[2,1.44,1.7]],"batl":[[0,2.3,314.02],[1,3.8,27.48],[2,8.8,7.23]],"ltp":1.67,"tv":16033.88,"id":8257797}]}]}
{"op":"mcm","clk":"4230390637","pt":1631532437291,"mc":[{"id":"1.187557146","rc":[{"batl":[[0,1.99,143.5],[1,2.3,314.02],[2,3.8,27.48]],"ltp":1.67,"tv":16033.88,"id":8257797}]}]}
{"op":"mcm","clk":"4230390693","pt":1631532438170,"mc":[{"id":"1.187557146","rc":[{"trd":[[2.5,1.09]],"batl":[[0,2.48,40.91],[1,6,3],[2,6.4,3]],"ltp":2.5,"tv":1055.2,"id":19931652},{"trd":[[1.66,12.28]],"ltp":1.66,"tv":16035.51,"id":8257797}],"tv":17090.72}]}
{"op":"mcm","clk":"4230390769","pt":1631532439171,"mc":[{"id":"1.187557146","rc":[{"trd":[[2.48,12.8]],"batl":[[0,2.48,40.85]],"ltp":2.48,"tv":1055.26,"id":19931652},{"trd":[[1.67,23.74]],"ltp":1.67,"tv":16035.61,"id":8257797}],"tv":17090.87}]}
{"op":"mcm","clk":"4230390830","pt":1631532440004,"mc":[{"id":"1.187557146","rc":[{"batl":[[0,6,3],[1,6.4,3],[2,6.6,3]],"ltp":2.48,"tv":1055.26,"id":19931652}]}]}
{"op":"mcm","clk":"4230390917","pt":1631532441265,"mc":[{"id":"1.187557146","rc":[{"trd":[[1.54,4],[1.91,0.02]],"batb":[[0,1.54,51.56]],"ltp":1.54,"tv":16039.63,"id":8257797}],"tv":17094.89}]}
{"op":"mcm","clk":"4230391403","pt":1631532447287,"mc":[{"id":"1.187557146","rc":[{"batb":[[0,2.08,16.06],[1,2,55.09],[2,1.94,52.22]],"ltp":2.48,"tv":1055.26,"id":19931652}]}]}
{"op":"mcm","clk":"4230391453","pt":1631532447911,"mc":[{"id":"1.187557146","rc":[{"batb":[[0,2,55.09],[1,1.94,52.22],[2,1.47,1.54]],"ltp":2.48,"tv":1055.26,"id":19931652}]}]}
{"op":"mcm","clk":"4230391735","pt":1631532451203,"mc":[{"id":"1.187557146","rc":[{"batb":[[0,2.08,18.56],[1,2,55.09],[2,1.94,52.22]],"ltp":2.48,"tv":1055.26,"id":19931652}]}]}
{"op":"mcm","clk":"4230391811","pt":1631532451995,"mc":[{"id":"1.187557146","rc":[{"batb":[[0,2,55.09],[1,1.94,52.22],[2,1.47,1.54]],"ltp":2.48,"tv":1055.26,"id":19931652}]}]}
{"op":"mcm","clk":"4230392158","pt":1631532456213,"mc":[{"id":"1.187557146","rc":[{"batb":[[0,2.64,75.76],[1,2,55.09],[2,1.94,52.22]],"batl":[[0,2.84,4.89],[1,2.88,71.42],[2,6,3]],"ltp":2.48,"tv":1055.26,"id":19931652},{"batb":[[1,1.44,1.7],[2,1.2,100]],"batl":[[0,1.57,2002.74],[1,1.58,22.11],[2,1.99,143.5]],"ltp":1.54,"tv":16039.63,"id":8257797}]}]}
{"op":"mcm","clk":"4230392231","pt":1631532457316,"mc":[{"id":"1.187557146","rc":[{"batb":[[0,2.74,52.52],[1,2.64,15.16],[2,2.52,24.6]],"ltp":2.48,"tv":1055.26,"id":19931652},{"batb":[[2,1.43,72.55]],"batl":[[0,1.57,312.05],[2,1.59,17.55]],"ltp":1.54,"tv":16039.63,"id":8257797}]}]}
{"op":"mcm","clk":"4230392490","pt":1631532460318,"mc":[{"id":"1.187557146","rc":[{"batb":[[0,1.55,187],[1,1.54,51.56],[2,1.44,1.7]],"ltp":1.54,"tv":16039.63,"id":8257797}]}]}
{"op":"mcm","clk":"4230392572","pt":1631532461312,"mc":[{"id":"1.187557146","rc":[{"trd":[[2.74,2.66]],"batb":[[0,2.74,51.19]],"ltp":2.74,"tv":1057.93,"id":19931652},{"trd":[[1.57,4.66]],"batl":[[0,1.57,309.72]],"ltp":1.57,"tv":16044.29,"id":8257797}],"tv":17102.22}]}
{"op":"mcm","clk":"4230392800","pt":1631532464327,"mc":[{"id":"1.187557146","rc":[{"trd":[[2.74,62.66]],"batb":[[0,2.74,21.19]],"ltp":2.74,"tv":1117.93,"id":19931652}],"tv":17162.22}]}
{"op":"mcm","clk":"4230392972","pt":1631532466107,"mc":[{"id":"1.187557146","rc":[{"trd":[[1.57,624.11]],"batb":[[0,1.57,30.99],[1,1.55,187],[2,1.54,51.56]],"batl":[[0,1.58,22.11],[1,1.59,17.55],[2,1.8,176.57]],"ltp":1.57,"tv":16663.74,"id":8257797}],"tv":17781.67}]}
{"op":"mcm","clk":"4230393064","pt":1631532467309,"mc":[{"id":"1.187557146","rc":[{"trd":[[2.74,63.01]],"batb":[[0,2.74,21.02]],"ltp":2.74,"tv":1118.27,"id":19931652},{"trd":[[1.57,624.3],[1.58,7.02]],"batb":[[0,1.57,30.89]],"batl":[[0,1.58,18.6]],"ltp":1.58,"tv":16670.95,"id":8257797}],"tv":17789.22}]}
{"op":"mcm","clk":"4230393261","pt":1631532469702,"mc":[{"id":"1.187557146","rc":[{"trd":[[2.74,84.03]],"batb":[[0,2.64,15.16],[1,2.52,24.6],[2,2.24,16.77]],"ltp":2.74,"tv":1139.29,"id":19931652},{"trd":[[1.58,80.67]],"batb":[[0,1.58,125.27],[1,1.57,30.89],[2,1.55,187]],"batl":[[0,1.59,17.55],[1,1.8,176.57],[2,1.81,177.5]],"ltp":1.58,"tv":16744.6,"id":8257797}],"tv":17883.89}]}
{"op":"mcm","clk":"4230393387","pt":1631532471110,"mc":[{"id":"1.187557146","rc":[{"batb":[[0,2.52,24.6],[1,2.08,42.09],[2,1.47,1.54]],"batl":[[0,6,3],[1,6.4,3],[2,6.6,3]],"ltp":2.74,"tv":1139.29,"id":19931652},{"batl":[[1,2.1,368.32],[2,3.8,27.48]],"ltp":1.58,"tv":16744.6,"id":8257797}]}]}
{"op":"mcm","clk":"4230393487","pt":1631532472351,"mc":[{"id":"1.187557146","rc":[{"batb":[[0,2.08,42.09],[1,1.47,1.54],[2,1.01,105.7]],"ltp":2.74,"tv":1139.29,"id":19931652},{"batb":[[2,1.44,1.7]],"batl":[[0,2.1,368.32],[1,3.8,27.48],[2,8.8,7.23]],"ltp":1.58,"tv":16744.6,"id":8257797}]}]}
{"op":"mcm","clk":"4230393574","pt":1631532473343,"mc":[{"id":"1.187557146","rc":[{"batb":[[1,2.06,7.58],[2,1.47,1.54]],"ltp":2.74,"tv":1139.29,"id":19931652},{"batl":[[0,1.93,39.5],[1,2.1,368.32],[2,3.8,27.48]],"ltp":1.58,"tv":16744.6,"id":8257797}]}]}
{"op":"mcm","clk":"4230393673","pt":1631532474343,"mc":[{"id":"1.187557146","rc":[{"batl":[[0,1.91,41.5],[1,1.93,39.5],[2,2.1,368.32]],"ltp":1.58,"tv":16744.6,"id":8257797}]}]}
{"op":"mcm","clk":"4230393715","pt":1631532474861,"mc":[{"id":"1.187557146","rc":[{"batb":[[0,2.08,50.4]],"ltp":2.74,"tv":1139.29,"id":19931652}]}]}
{"op":"mcm","clk":"4230393858","pt":1631532476634,"mc":[{"id":"1.187557146","rc":[{"trd":[[1.58,80.83]],"batb":[[0,1.58,125.19]],"ltp":1.58,"tv":16744.76,"id":8257797}],"tv":17884.05}]}
{"op":"mcm","clk":"4230393992","pt":1631532478238,"mc":[{"id":"1.187557146","rc":[{"batb":[[0,2.2,8.22],[1,2.08,50.4],[2,2.06,7.58]],"ltp":2.74,"tv":1139.29,"id":19931652},{"batl":[[0,1.83,42.5],[1,1.91,41.5],[2,1.93,39.5]],"ltp":1.58,"tv":16744.76,"id":8257797}]}]}
{"op":"mcm","clk":"4230394013","pt":1631532478546,"mc":[{"id":"1.187557146","rc":[{"batb":[[0,2.08,50.4],[1,2.06,7.58],[2,1.47,1.54]],"ltp":2.74,"tv":1139.29,"id":19931652},{"batl":[[0,1.91,41.5],[1,1.93,39.5],[2,2.1,368.32]],"ltp":1.58,"tv":16744.76,"id":8257797}]}]}
{"op":"mcm","clk":"4230395111","pt":1631532491336,"mc":[{"id":"1.187557146","rc":[{"batb":[[0,1.57,30.89],[1,1.44,1.7],[2,1.43,72.55]],"ltp":1.58,"tv":16744.76,"id":8257797}]}]}
{"op":"mcm","clk":"4230395212","pt":1631532492325,"mc":[{"id":"1.187557146","rc":[{"batb":[[0,2.2,7.27],[1,2.08,50.4],[2,2.06,7.58]],"ltp":2.74,"tv":1139.29,"id":19931652},{"batl":[[0,1.83,44.5],[1,1.91,41.5],[2,1.93,39.5]],"ltp":1.58,"tv":16744.76,"id":8257797}]}]}
{"op":"mcm","clk":"4230395281","pt":1631532493046,"mc":[{"id":"1.187557146","rc":[{"batb":[[0,2.08,50.4],[1,2.06,7.58],[2,1.47,1.54]],"ltp":2.74,"tv":1139.29,"id":19931652},{"batl":[[0,1.91,41.5],[1,1.93,39.5],[2,3.8,27.48]],"ltp":1.58,"tv":16744.76,"id":8257797}]}]}
{"op":"mcm","clk":"4230395410","pt":1631532494342,"mc":[{"id":"1.187557146","rc":[{"batl":[[0,2.28,12.17],[1,2.34,216.07],[2,6,3]],"ltp":2.74,"tv":1139.29,"id":19931652},{"batb":[[0,1.72,292.73],[1,1.57,30.89],[2,1.44,1.7]],"batl":[[0,1.83,9.92],[1,1.91,41.5],[2,1.93,39.5]],"ltp":1.58,"tv":16744.76,"id":8257797}]}]}
{"op":"mcm","clk":"4230395513","pt":1631532495338,"mc":[{"id":"1.187557146","rc":[{"trd":[[2.28,12.17]],"batb":[[2,1.79,33.64]],"batl":[[0,6,3],[1,6.4,3],[2,6.6,3]],"ltp":2.28,"tv":1151.46,"id":19931652},{"trd":[[1.76,69.17],[1.78,39.59]],"batb":[[0,1.76,17.01],[1,1.72,199.71],[2,1.62,44.85]],"batl":[[0,1.78,15.68],[1,1.83,9.92],[2,1.91,41.5]],"ltp":1.76,"tv":16792.59,"id":8257797}],"tv":17944.05}]}
{"op":"mcm","clk":"4230395878","pt":1631532499279,"mc":[{"id":"1.187557146","rc":[{"trd":[[2.28,13.96]],"batl":[[0,2.68,110.42],[1,6,3],[2,6.4,3]],"ltp":2.28,"tv":1153.24,"id":19931652},{"trd":[[1.78,46.24]],"batl":[[0,1.78,11.22]],"ltp":1.78,"tv":16799.24,"id":8257797}],"tv":17952.49}]}
{"op":"mcm","clk":"4230395897","pt":1631532499444,"mc":[{"id":"1.187557146","rc":[{"batl":[[0,6,3],[1,6.4,3],[2,6.6,3]],"ltp":2.28,"tv":1153.24,"id":19931652}]}]}
{"op":"mcm","clk":"4230396081","pt":1631532501471,"mc":[{"id":"1.187557146","rc":[{"batb":[[2,1.91,47.39]],"ltp":2.28,"tv":1153.24,"id":19931652}]}]}
{"op":"mcm","clk":"4230396383","pt":1631532504761,"mc":[{"id":"1.187557146","rc":[{"batl":[[0,3.5,26.95],[1,6,3],[2,6.4,3]],"ltp":2.28,"tv":1153.24,"id":19931652},{"batl":[[1,1.91,41.5],[2,1.93,39.5]],"ltp":1.78,"tv":16799.24,"id":8257797}]}]}
{"op":"mcm","clk":"4230396620","pt":1631532507680,"mc":[{"id":"1.187557146","rc":[{"batb":[[0,1.76,28.98]],"batl":[[1,1.8,10.03],[2,1.91,41.5]],"ltp":1.78,"tv":16799.24,"id":8257797}]}]}
{"op":"mcm","clk":"4230396857","pt":1631532510660,"mc":[{"id":"1.187557146","rc":[{"trd":[[1.78,68.67]],"batb":[[0,1.79,78.94],[1,1.76,28.98],[2,1.72,199.71]],"batl":[[0,1.8,10.03],[1,1.91,41.5],[2,1.93,39.5]],"ltp":1.78,"tv":16821.67,"id":8257797}],"tv":17974.92}]}
{"op":"mcm","clk":"4230397716","pt":1631532521393,"mc":[{"id":"1.187557146","rc":[{"batl":[[0,6,3],[1,6.4,3],[2,6.6,3]],"ltp":2.28,"tv":1153.24,"id":19931652}]}]}
{"op":"mcm","clk":"4230397851","pt":1631532523155,"mc":[{"id":"1.187557146","rc":[{"batb":[[0,2.08,42.09],[1,1.8,47.73],[2,1.79,33.64]],"ltp":2.28,"tv":1153.24,"id":19931652},{"trd":[[1.8,20.06]],"batb":[[0,1.8,17.08],[1,1.79,78.94],[2,1.76,17.01]],"batl":[[0,2.42,290.48],[1,990,0.01],[2,1.93,0]],"ltp":1.8,"tv":16841.73,"id":8257797}],"tv":17994.98}]}
{"op":"mcm","clk":"4230397884","pt":1631532523570,"mc":[{"id":"1.187557146","rc":[{"batb":[[0,1.8,47.73],[1,1.79,33.64],[2,1.47,1.54]],"ltp":2.28,"tv":1153.24,"id":19931652},{"batb":[[2,1.62,44.85]],"ltp":1.8,"tv":16841.73,"id":8257797}]}]}
{"op":"mcm","clk":"4230398114","pt":1631532526272,"mc":[{"id":"1.187557146","rc":[{"batb":[[1,1.62,44.85],[2,1.57,30.89]],"ltp":1.8,"tv":16841.73,"id":8257797}]}]}
{"op":"mcm","clk":"4230398152","pt":1631532526710,"mc":[{"id":"1.187557146","rc":[{"batb":[[1,1.79,33.3]],"ltp":2.28,"tv":1153.24,"id":19931652},{"batb":[[1,1.61,45.19]],"batl":[[0,2.26,6.75],[1,2.42,290.48],[2,990,0.01]],"ltp":1.8,"tv":16841.73,"id":8257797}]}]}
{"op":"mcm","clk":"4230398845","pt":1631532535671,"mc":[{"id":"1.187557146","rc":[{"batl":[[0,2.24,3],[1,6,3],[2,6.4,3]],"ltp":2.28,"tv":1153.24,"id":19931652}]}]}
{"op":"mcm","clk":"4230398938","pt":1631532537070,"mc":[{"id":"1.187557146","rc":[{"batb":[[0,1.88,44.96],[1,1.8,47.73],[2,1.79,33.3]],"ltp":2.28,"tv":1153.24,"id":19931652},{"batl":[[0,2.14,7.75],[1,2.26,6.75],[2,2.42,290.48]],"ltp":1.8,"tv":16841.73,"id":8257797}]}]}
{"op":"mcm","clk":"4230399031","pt":1631532538310,"mc":[{"id":"1.187557146","rc":[{"batb":[[0,1.8,47.73],[1,1.79,33.3],[2,1.47,1.54]],"ltp":2.28,"tv":1153.24,"id":19931652},{"batl":[[0,2.26,6.75],[1,2.42,290.48],[2,990,0.01]],"ltp":1.8,"tv":16841.73,"id":8257797}]}]}
{"op":"mcm","clk":"4230399058","pt":1631532538681,"mc":[{"id":"1.187557146","rc":[{"batl":[[1,990,0.01],[2,990,0]],"ltp":1.8,"tv":16841.73,"id":8257797}]}]}
{"op":"mcm","clk":"4230399174","pt":1631532540223,"mc":[{"id":"1.187557146","rc":[{"trd":[[1.93,7.94]],"batb":[[0,1.98,20.25],[1,1.96,14.24],[2,1.8,47.73]],"batl":[[0,2,68.73],[1,2.24,3],[2,6,3]],"ltp":1.93,"tv":1161.19,"id":19931652},{"trd":[[2.08,7.37]],"batb":[[0,2,68.73],[1,1.9,21.06],[2,1.8,17.08]],"batl":[[0,2.12,6.07],[1,2.26,6.75],[2,990,0.01]],"ltp":2.08,"tv":16849.1,"id":8257797}],"tv":18010.29}]}
{"op":"mcm","clk":"4230399260","pt":1631532541320,"mc":[{"id":"1.187557146","rc":[{"trd":[[1.98,20.25]],"batb":[[0,1.96,14.24],[1,1.8,47.73],[2,1.79,33.3]],"ltp":1.98,"tv":1181.43,"id":19931652},{"trd":[[2.04,19.65]],"batb":[[0,2.04,22.19],[1,2,68.73],[2,1.9,21.06]],"ltp":2.04,"tv":16868.76,"id":8257797}],"tv":18050.19}]}
{"op":"mcm","clk":"4230399361","pt":1631532542420,"mc":[{"id":"1.187557146","rc":[{"batl":[[2,2.82,234.47]],"ltp":2.04,"tv":16868.76,"id":8257797}]}]}
{"op":"mcm","clk":"4230399495","pt":1631532544224,"mc":[{"id":"1.187557146","rc":[{"trd":[[1.96,4.34]],"batb":[[0,1.96,12.07]],"ltp":1.96,"tv":1185.77,"id":19931652}],"tv":18054.53}]}
{"op":"mcm","clk":"4230399565","pt":1631532545010,"mc":[{"id":"1.187557146","rc":[{"trd":[[1.96,7.55]],"batb":[[0,1.96,8.86]],"ltp":1.96,"tv":1188.99,"id":19931652},{"trd":[[2.06,192.3]],"ltp":2.06,"tv":16871.82,"id":8257797}],"tv":18060.81}]}
{"op":"mcm","clk":"4230399801","pt":1631532548319,"mc":[{"id":"1.187557146","rc":[{"trd":[[1.97,22.98]],"ltp":1.97,"tv":1211.97,"id":19931652},{"trd":[[2.04,41.84]],"batb":[[0,2,68.73],[1,1.9,21.06],[2,1.84,28.87]],"ltp":2.04,"tv":16894.0,"id":8257797}],"tv":18105.98}]}
{"op":"mcm","clk":"4230399878","pt":1631532549300,"mc":[{"id":"1.187557146","rc":[{"batb":[[1,1.8,80.7]],"ltp":1.97,"tv":1211.97,"id":19931652},{"batb":[[0,2.02,42.34],[1,2,68.73],[2,1.9,21.06]],"ltp":2.04,"tv":16894.0,"id":8257797}]}]}
{"op":"mcm","clk":"4230399893","pt":1631532549511,"mc":[{"id":"1.187557146","rc":[{"batb":[[2,1.7,40.25]],"ltp":1.97,"tv":1211.97,"id":19931652}]}]}
{"op":"mcm","clk":"4230399971","pt":1631532550394,"mc":[{"id":"1.187557146","rc":[{"batl":[[0,2.26,6.75],[1,2.82,234.47],[2,990,0.01]],"ltp":2.04,"tv":16894.0,"id":8257797}]}]}
{"op":"mcm","clk":"4230400177","pt":1631532553327,"mc":[{"id":"1.187557146","rc":[{"trd":[[1.96,14.87],[1.97,23.06]],"batb":[[0,1.96,1.54]],"ltp":1.96,"tv":1219.36,"id":19931652},{"trd":[[2.04,41.92],[2.06,199.26]],"batl":[[0,2.12,13.32],[1,2.26,6.75],[2,2.82,234.47]],"ltp":2.06,"tv":16901.04,"id":8257797}],"tv":18120.41}]}
{"op":"mcm","clk":"4230400256","pt":1631532554416,"mc":[{"id":"1.187557146","rc":[{"batb":[[0,1.96,26.54]],"ltp":1.96,"tv":1219.36,"id":19931652}]}]}
{"op":"mcm","clk":"4230400501","pt":1631532557322,"mc":[{"id":"1.187557146","rc":[{"batb":[[1,1.81,32.55],[2,1.8,80.7]],"ltp":1.96,"tv":1219.36,"id":19931652}]}]}
{"op":"mcm","clk":"4230400519","pt":1631532557528,"mc":[{"id":"1.187557146","rc":[{"batb":[[2,1.8,47.73]],"ltp":1.96,"tv":1219.36,"id":19931652}]}]}
{"op":"mcm","clk":"4230400607","pt":1631532558619,"mc":[{"id":"1.187557146","rc":[{"batl":[[0,2.06,8.76],[1,2.12,13.32],[2,2.26,6.75]],"ltp":2.06,"tv":16901.04,"id":8257797}]}]}
{"op":"mcm","clk":"4230400779","pt":1631532560327,"mc":[{"id":"1.187557146","rc":[{"batl":[[0,2.12,13.32],[1,2.26,6.75],[2,2.82,234.47]],"ltp":2.06,"tv":16901.04,"id":8257797}]}]}
{"op":"mcm","clk":"4230400945","pt":1631532562145,"mc":[{"id":"1.187557146","rc":[{"trd":[[2.02,57.15]],"batb":[[0,2.02,13.77]],"ltp":2.02,"tv":16958.19,"id":8257797}],"tv":18177.56}]}
{"op":"mcm","clk":"4230401095","pt":1631532564108,"mc":[{"id":"1.187557146","rc":[{"trd":[[2.02,75.02]],"batb":[[0,2.02,4.83]],"batl":[[0,2.26,6.75],[1,2.82,234.47],[2,990,0.01]],"ltp":2.02,"tv":16976.06,"id":8257797}],"tv":18195.43}]}
{"op":"mcm","clk":"4230401179","pt":1631532565451,"mc":[{"id":"1.187557146","rc":[{"batb":[[0,2.02,34.04]],"ltp":2.02,"tv":16976.06,"id":8257797}]}]}
{"op":"mcm","clk":"4230401243","pt":1631532566543,"mc":[{"id":"1.187557146","rc":[{"trd":[[1.96,28.67]],"batb":[[0,1.96,19.64]],"ltp":1.96,"tv":1233.16,"id":19931652},{"batl":[[0,2.08,6.98],[1,2.26,6.75],[2,2.82,234.47]],"ltp":2.02,"tv":16976.06,"id":8257797}],"tv":18209.23}]}
{"op":"mcm","clk":"4230401359","pt":1631532568311,"mc":[{"id":"1.187557146","rc":[{"trd":[[1.96,47.51]],"batb":[[0,1.96,10.22]],"ltp":1.96,"tv":1252.0,"id":19931652},{"trd":[[2.02,78.47]],"batb":[[0,2.02,32.31]],"ltp":2.02,"tv":16979.51,"id":8257797}],"tv":18231.52}]}
{"op":"mcm","clk":"4230401457","pt":1631532569651,"mc":[{"id":"1.187557146","rc":[{"trd":[[2.02,81.71]],"batb":[[0,2.02,30.69]],"ltp":2.02,"tv":16982.75,"id":8257797}],"tv":18234.76}]}
{"op":"mcm","clk":"4230401729","pt":1631532573350,"mc":[{"id":"1.187557146","rc":[{"trd":[[1.96,47.53]],"batb":[[0,1.96,10.21]],"ltp":1.96,"tv":1252.02,"id":19931652}],"tv":18234.78}]}
{"op":"mcm","clk":"4230401789","pt":1631532574230,"mc":[{"id":"1.187557146","rc":[{"batb":[[1,1.82,31.8]],"ltp":1.96,"tv":1252.02,"id":19931652},{"batb":[[0,2,112.75],[1,1.9,21.06],[2,1.81,30.29]],"ltp":2.02,"tv":16982.75,"id":8257797}]}]}
{"op":"mcm","clk":"4230401950","pt":1631532576629,"mc":[{"id":"1.187557146","rc":[{"batl":[[0,2.26,6.75],[1,2.82,234.47],[2,990,0.01]],"ltp":2.02,"tv":16982.75,"id":8257797}]}]}
{"op":"mcm","clk":"4230402126","pt":1631532579161,"mc":[{"id":"1.187557146","rc":[{"trd":[[1.96,67.95]],"batb":[[0,1.82,31.8],[1,1.8,47.73],[2,1.71,38.83]],"batl":[[0,1.86,7.83],[1,2,68.73],[2,2.24,3]],"ltp":1.96,"tv":1272.44,"id":19931652}],"tv":18255.2}]}
{"op":"mcm","clk":"4230402165","pt":1631532579631,"mc":[{"id":"1.187557146","rc":[{"trd":[[1.86,7.64]],"batl":[[0,1.98,8.27]],"ltp":1.86,"tv":1280.08,"id":19931652},{"trd":[[2.16,6.58]],"ltp":2.16,"tv":16989.33,"id":8257797}],"tv":18269.42}]}
{"op":"mcm","clk":"4230402361","pt":1631532582270,"mc":[{"id":"1.187557146","rc":[{"trd":[[1.86,8.02]],"batl":[[0,1.98,8.08]],"ltp":1.86,"tv":1280.46,"id":19931652},{"batb":[[0,2.02,8.75],[1,2,112.75],[2,1.9,21.06]],"ltp":2.16,"tv":16989.33,"id":8257797}],"tv":18269.8}]}
{"op":"mcm","clk":"4230402435","pt":1631532583059,"mc":[{"id":"1.187557146","rc":[{"batl":[[0,1.86,7.49],[1,1.98,8.08],[2,2,68.73]],"ltp":1.86,"tv":1280.46,"id":19931652}]}]}
{"op":"mcm","clk":"4230402694","pt":1631532586763,"mc":[{"id":"1.187557146","rc":[{"batb":[[0,2,112.75],[1,1.9,21.06],[2,1.81,30.29]],"ltp":2.16,"tv":16989.33,"id":8257797}]}]}
{"op":"mcm","clk":"4230402927","pt":1631532589879,"mc":[{"id":"1.187557146","rc":[{"batl":[[1,2,68.73],[2,2.24,3]],"ltp":1.86,"tv":1280.46,"id":19931652}]}]}
{"op":"mcm","clk":"4230403149","pt":1631532592743,"mc":[{"id":"1.187557146","rc":[{"trd":[[1.86,15.51]],"batl":[[0,1.96,7.21]],"ltp":1.86,"tv":1287.95,"id":19931652},{"trd":[[2.16,13.03]],"batl":[[0,2.08,6.69],[1,2.1,107.55],[2,2.26,6.75]],"ltp":2.16,"tv":16995.78,"id":8257797}],"tv":18283.74}]}
{"op":"mcm","clk":"4230403250","pt":1631532594251,"mc":[{"id":"1.187557146","rc":[{"batl":[[1,2.26,6.75],[2,2.82,234.47]],"ltp":2.16,"tv":16995.78,"id":8257797}]}]}
{"op":"mcm","clk":"4230403337","pt":1631532595853,"mc":[{"id":"1.187557146","rc":[{"batb":[[0,1.83,25],[1,1.82,31.8],[2,1.8,47.73]],"ltp":1.86,"tv":1287.95,"id":19931652}]}]}
{"op":"mcm","clk":"4230403562","pt":1631532599658,"mc":[{"id":"1.187557146","rc":[{"trd":[[2.08,20.75]],"batb":[[0,2.08,2.06],[1,2,112.75],[2,1.9,21.06]],"batl":[[0,2.26,6.75],[1,2.82,234.47],[2,990,0.01]],"ltp":2.08,"tv":17009.16,"id":8257797}],"tv":18297.12}]}
{"op":"mcm","clk":"4230404132","pt":1631532607105,"mc":[{"id":"1.187557146","rc":[{"batl":[[0,2.12,110],[1,2.26,6.75],[2,2.82,234.47]],"ltp":2.08,"tv":17009.16,"id":8257797}]}]}
{"op":"mcm","clk":"4230404358","pt":1631532609793,"mc":[{"id":"1.187557146","rc":[{"batl":[[0,2,68.73],[1,2.24,3],[2,990,0.01]],"ltp":1.86,"tv":1287.95,"id":19931652}]}]}
{"op":"mcm","clk":"4230404598","pt":1631532612922,"mc":[{"id":"1.187557146","rc":[{"trd":[[2.08,24.86]],"batb":[[0,2.06,7.04]],"batl":[[0,2.08,19.24],[1,2.12,123.32],[2,2.26,6.75]],"ltp":2.08,"tv":17013.27,"id":8257797}],"tv":18301.22}]}
{"op":"mcm","clk":"4230404746","pt":1631532614723,"mc":[{"id":"1.187557146","rc":[{"trd":[[2.06,199.44]],"batb":[[0,2.06,6.95]],"ltp":2.06,"tv":17013.45,"id":8257797}],"tv":18301.41}]}
{"op":"mcm","clk":"4230405144","pt":1631532619785,"mc":[{"id":"1.187557146","rc":[{"trd":[[2.08,59.84]],"batl":[[0,2.08,1.75]],"ltp":2.08,"tv":17048.43,"id":8257797}],"tv":18336.39}]}
{"op":"mcm","clk":"4230405242","pt":1631532621403,"mc":[{"id":"1.187557146","rc":[{"batl":[[0,1.95,98],[1,2,68.73],[2,2.24,3]],"ltp":1.86,"tv":1287.95,"id":19931652}]}]}
{"op":"mcm","clk":"4230405523","pt":1631532625315,"mc":[{"id":"1.187557146","rc":[{"trd":[[1.95,1.54]],"batl":[[0,1.95,97.23]],"ltp":1.95,"tv":1289.5,"id":19931652},{"batb":[[0,2,112.75],[1,1.9,21.06],[2,1.81,30.29]],"batl":[[1,2.12,110]],"ltp":2.08,"tv":17048.43,"id":8257797}],"tv":18337.93}]}
{"op":"mcm","clk":"4230405757","pt":1631532627832,"mc":[{"id":"1.187557146","rc":[{"batb":[[0,2.06,6.95],[1,2,112.75],[2,1.9,21.06]],"batl":[[1,2.12,123.41]],"ltp":2.08,"tv":17048.43,"id":8257797}]}]}
{"op":"mcm","clk":"4230405997","pt":1631532630719,"mc":[{"id":"1.187557146","rc":[{"batb":[[0,1.82,31.8],[1,1.8,47.73],[2,1.71,38.83]],"ltp":1.95,"tv":1289.5,"id":19931652},{"trd":[[2.06,213.34]],"batb":[[0,2,112.75],[1,1.9,21.06],[2,1.81,30.29]],"batl":[[0,2.06,815.13],[1,2.08,1.75],[2,2.12,123.41]],"ltp":2.06,"tv":17062.33,"id":8257797}],"tv":18351.83}]}
{"op":"mcm","clk":"4230406306","pt":1631532634227,"mc":[{"id":"1.187557146","rc":[{"trd":[[1.94,257.04]],"ltp":1.94,"tv":1546.46,"id":19931652},{"trd":[[2.06,455.34]],"batl":[[0,2.06,573.13]],"ltp":2.06,"tv":17304.32,"id":8257797}],"tv":18850.78}]}
{"op":"mcm","clk":"4230406358","pt":1631532634948,"mc":[{"id":"1.187557146","rc":[{"trd":[[1.95,1.78]],"batl":[[0,1.95,97.11]],"ltp":1.95,"tv":1546.69,"id":19931652}],"tv":18851.02}]}
{"op":"mcm","clk":"4230406596","pt":1631532638137,"mc":[{"id":"1.187557146","rc":[{"trd":[[1.94,266.25]],"ltp":1.94,"tv":1555.9,"id":19931652},{"trd":[[2.06,464.01]],"batl":[[0,2.06,564.46]],"ltp":2.06,"tv":17312.99,"id":8257797}],"tv":18868.9}]}
{"op":"mcm","clk":"4230406730","pt":1631532639646,"mc":[{"id":"1.187557146","rc":[{"trd":[[1.94,275.27]],"ltp":1.94,"tv":1564.92,"id":19931652},{"trd":[[2.06,472.5]],"batl":[[0,2.06,555.97]],"ltp":2.06,"tv":17321.49,"id":8257797}],"tv":18886.42}]}
{"op":"mcm","clk":"4230406845","pt":1631532640944,"mc":[{"id":"1.187557146","rc":[{"batl":[[2,2.12,110]],"ltp":2.06,"tv":17321.49,"id":8257797}]}]}
{"op":"mcm","clk":"4230406962","pt":1631532642243,"mc":[{"id":"1.187557146","rc":[{"trd":[[1.95,98.89]],"batl":[[0,2,68.73],[1,2.24,3],[2,990,0.01]],"ltp":1.95,"tv":1662.03,"id":19931652},{"trd":[[2.04,134.75]],"batl":[[0,2.04,7.17],[1,2.06,555.97],[2,2.08,1.75]],"ltp":2.04,"tv":17414.32,"id":8257797}],"tv":19076.36}]}
{"op":"mcm","clk":"4230407093","pt":1631532643853,"mc":[{"id":"1.187557146","rc":[{"trd":[[1.96,74.86]],"ltp":1.96,"tv":1668.94,"id":19931652},{"trd":[[2.04,141.39]],"batl":[[0,2.06,556.5],[1,2.08,8.73],[2,2.12,110]],"ltp":2.04,"tv":17420.96,"id":8257797}],"tv":19089.91}]}
{"op":"mcm","clk":"4230407244","pt":1631532646248,"mc":[{"id":"1.187557146","rc":[{"batb":[[0,2,299.75]],"ltp":2.04,"tv":17420.96,"id":8257797}]}]}
{"op":"mcm","clk":"4230407260","pt":1631532646452,"mc":[{"id":"1.187557146","rc":[{"batb":[[0,2,112.75]],"ltp":2.04,"tv":17420.96,"id":8257797}]}]}
{"op":"mcm","clk":"4230407434","pt":1631532648848,"mc":[{"id":"1.187557146","rc":[{"batb":[[0,1.95,45.08],[1,1.82,31.8],[2,1.8,47.73]],"ltp":1.96,"tv":1668.94,"id":19931652}]}]}
{"op":"mcm","clk":"4230407497","pt":1631532649524,"mc":[{"id":"1.187557146","rc":[{"batl":[[2,2.26,6.75]],"ltp":2.04,"tv":17420.96,"id":8257797}]}]}
{"op":"mcm","clk":"4230407779","pt":1631532652539,"mc":[{"id":"1.187557146","rc":[{"batb":[[1,1.89,9.02],[2,1.82,31.8]],"ltp":1.96,"tv":1668.94,"id":19931652}]}]}
{"op":"mcm","clk":"4230407902","pt":1631532653936,"mc":[{"id":"1.187557146","rc":[{"batl":[[1,2.08,1.75]],"ltp":2.04,"tv":17420.96,"id":8257797}]}]}
{"op":"mcm","clk":"4230408146","pt":1631532656950,"mc":[{"id":"1.187557146","rc":[{"batl":[[0,1.98,8.08],[1,2,68.73],[2,2.24,3]],"ltp":1.96,"tv":1668.94,"id":19931652},{"batl":[[0,2.06,563.08]],"ltp":2.04,"tv":17420.96,"id":8257797}]}]}
{"op":"mcm","clk":"4230408847","pt":1631532665083,"mc":[{"id":"1.187557146","rc":[{"trd":[[1.98,28.33]],"batl":[[0,2,68.73],[1,2.24,3],[2,990,0.01]],"ltp":1.98,"tv":1677.02,"id":19931652},{"trd":[[2.02,89.63]],"batl":[[0,2.02,24.08],[1,2.06,563.08],[2,2.08,1.75]],"ltp":2.02,"tv":17428.88,"id":8257797}],"tv":19105.91}]}
{"op":"mcm","clk":"4230408946","pt":1631532666175,"mc":[{"id":"1.187557146","rc":[{"trd":[[1.98,52.9]],"batl":[[0,1.98,158.43],[1,2,68.73],[2,2.24,3]],"ltp":1.98,"tv":1701.59,"id":19931652},{"trd":[[2.02,113.71]],"batl":[[0,2.06,563.08],[1,2.08,1.75],[2,2.26,6.75]],"ltp":2.02,"tv":17452.96,"id":8257797}],"tv":19154.56}]}
{"op":"mcm","clk":"4230409090","pt":1631532667980,"mc":[{"id":"1.187557146","rc":[{"batl":[[0,2.06,7.11]],"ltp":2.02,"tv":17452.96,"id":8257797}]}]}
{"op":"mcm","clk":"4230409342","pt":1631532671192,"mc":[{"id":"1.187557146","rc":[{"trd":[[1.98,211.33]],"batl":[[0,2,68.73],[1,2.24,3],[2,990,0.01]],"ltp":1.98,"tv":1860.02,"id":19931652},{"trd":[[2.02,269]],"batl":[[0,2.02,400.68],[1,2.06,7.11],[2,2.08,1.75]],"ltp":2.02,"tv":17608.25,"id":8257797}],"tv":19468.28}]}
{"op":"mcm","clk":"4230409676","pt":1631532675200,"mc":[{"id":"1.187557146","rc":[{"batl":[[0,2.08,2.28],[1,2.26,6.75],[2,2.82,234.47]],"ltp":2.02,"tv":17608.25,"id":8257797}]}]}
{"op":"mcm","clk":"4230409950","pt":1631532678215,"mc":[{"id":"1.187557146","rc":[{"trd":[[2,72.66]],"batl":[[0,2.24,3],[1,990,0.01],[2,990,0]],"ltp":2.0,"tv":1932.68,"id":19931652},{"trd":[[2,306.01]],"batb":[[0,1.9,21.06],[1,1.81,30.29],[2,1.78,31.36]],"batl":[[0,2,211.35],[1,2.04,7.77],[2,2.08,1.75]],"ltp":2.0,"tv":17914.26,"id":8257797}],"tv":19846.95}]}
{"op":"mcm","clk":"4230410183","pt":1631532680707,"mc":[{"id":"1.187557146","rc":[{"batl":[[0,2.04,7.77],[1,2.08,1.75],[2,2.26,6.75]],"ltp":2.0,"tv":17914.26,"id":8257797}]}]}
{"op":"mcm","clk":"4230410393","pt":1631532683195,"mc":[{"id":"1.187557146","rc":[{"batl":[[0,1.99,9.02],[1,2.24,3],[2,990,0.01]],"ltp":2.0,"tv":1932.68,"id":19931652}]}]}
{"op":"mcm","clk":"4230410482","pt":1631532684184,"mc":[{"id":"1.187557146","rc":[{"trd":[[1.98,311.33],[1.99,9.02]],"batl":[[0,2.24,3],[1,990,0.01],[2,990,0]],"ltp":1.99,"tv":2041.7,"id":19931652},{"trd":[[1.9,106.21],[2,314.98],[2.02,367.02]],"batb":[[0,1.81,30.29],[1,1.78,31.36],[2,1.77,407.82]],"batl":[[0,1.9,51.24],[1,2.04,7.77],[2,2.08,1.75]],"ltp":1.9,"tv":18127.46,"id":8257797}],"tv":20169.17}]}
{"op":"mcm","clk":"4230410741","pt":1631532687287,"mc":[{"id":"1.187557146","rc":[{"trd":[[1.9,208.69],[2.04,156.79]],"batb":[[1,1.77,407.82],[2,1.57,30.89]],"batl":[[0,2.08,1.82],[1,2.26,6.75],[2,2.82,234.47]],"ltp":2.04,"tv":18245.35,"id":8257797}],"tv":20287.06}]}
{"op":"mcm","clk":"4230410891","pt":1631532689302,"mc":[{"id":"1.187557146","rc":[{"batb":[[0,1.9,298.8],[1,1.81,30.29],[2,1.77,407.82]],"batl":[[0,2.08,1.75]],"ltp":2.04,"tv":18245.35,"id":8257797}]}]}
{"op":"mcm","clk":"4230410968","pt":1631532690285,"mc":[{"id":"1.187557146","rc":[{"batl":[[0,2.1,96.59],[1,2.24,3],[2,990,0.01]],"ltp":1.99,"tv":2041.7,"id":19931652},{"batb":[[0,1.9,352.58]],"ltp":2.04,"tv":18245.35,"id":8257797}]}]}
{"op":"mcm","clk":"4230411049","pt":1631532691318,"mc":[{"id":"1.187557146","rc":[{"batl":[[0,2.1,178.88]],"ltp":1.99,"tv":2041.7,"id":19931652},{"batb":[[0,1.9,114.5]],"ltp":2.04,"tv":18245.35,"id":8257797}]}]}
{"op":"mcm","clk":"4230411144","pt":1631532692303,"mc":[{"id":"1.187557146","rc":[{"batl":[[0,2,3.65],[1,2.1,25.55],[2,2.24,3]],"ltp":1.99,"tv":2041.7,"id":19931652},{"batb":[[0,2,3.65]],"batl":[[0,2.04,7.79],[1,2.08,1.75],[2,2.26,6.75]],"ltp":2.04,"tv":18245.35,"id":8257797}]}]}
{"op":"mcm","clk":"4230411164","pt":1631532692512,"mc":[{"id":"1.187557146","rc":[{"batl":[[1,2.24,3],[2,990,0.01]],"ltp":1.99,"tv":2041.7,"id":19931652}]}]}
{"op":"mcm","clk":"4230411289","pt":1631532694118,"mc":[{"id":"1.187557146","rc":[{"batb":[[1,1.9,33.11],[2,1.81,30.29]],"ltp":2.04,"tv":18245.35,"id":8257797}]}]}
{"op":"mcm","clk":"4230411394","pt":1631532695510,"mc":[{"id":"1.187557146","rc":[{"batb":[[1,1.81,30.29],[2,1.77,407.82]],"ltp":2.04,"tv":18245.35,"id":8257797}]}]}
{"op":"mcm","clk":"4230411487","pt":1631532696543,"mc":[{"id":"1.187557146","rc":[{"trd":[[2.04,172.35]],"batl":[[0,2.08,1.76],[1,2.26,6.75],[2,2.82,234.47]],"ltp":2.04,"tv":18260.91,"id":8257797}],"tv":20302.61}]}
{"op":"mcm","clk":"4230411629","pt":1631532698301,"mc":[{"id":"1.187557146","rc":[{"batl":[[0,2.24,3],[1,990,0.01],[2,990,0]],"ltp":1.99,"tv":2041.7,"id":19931652},{"batb":[[0,1.81,30.29],[1,1.77,407.82],[2,1.57,30.89]],"batl":[[0,2,90],[1,2.08,1.75],[2,2.26,6.75]],"ltp":2.04,"tv":18260.91,"id":8257797}]}]}
{"op":"mcm","clk":"4230411779","pt":1631532700430,"mc":[{"id":"1.187557146","rc":[{"trd":[[2,80.11]],"ltp":2.0,"tv":2049.15,"id":19931652},{"trd":[[2,322.43]],"batl":[[0,2,82.55],[1,2.06,7.2],[2,2.08,1.75]],"ltp":2.0,"tv":18268.36,"id":8257797}],"tv":20317.51}]}
{"op":"mcm","clk":"4230412007","pt":1631532703336,"mc":[{"id":"1.187557146","rc":[{"trd":[[2,82.28]],"ltp":2.0,"tv":2051.32,"id":19931652},{"trd":[[2,324.6]],"batl":[[0,2,80.38]],"ltp":2.0,"tv":18270.53,"id":8257797}],"tv":20321.85}]}
{"op":"mcm","clk":"4230412269","pt":1631532706342,"mc":[{"id":"1.187557146","rc":[{"trd":[[2,162.66]],"batb":[[0,1.89,9.02],[1,1.82,31.8],[2,1.8,47.73]],"batl":[[0,2,125.17],[1,2.24,3],[2,990,0.01]],"ltp":2.0,"tv":2131.71,"id":19931652},{"trd":[[2,404.98]],"batl":[[0,2.06,7.2],[1,2.08,1.75],[2,2.26,6.75]],"ltp":2.0,"tv":18350.91,"id":8257797}],"tv":20482.62}]}
{"op":"mcm","clk":"4230412346","pt":1631532707223,"mc":[{"id":"1.187557146","rc":[{"batl":[[0,2,375.8]],"ltp":2.0,"tv":2131.71,"id":19931652},{"batb":[[0,2,17.04],[1,1.81,30.29],[2,1.77,407.82]],"batl":[[0,2.08,1.75],[1,2.26,6.75],[2,2.82,234.47]],"ltp":2.0,"tv":18350.91,"id":8257797}]}]}
{"op":"mcm","clk":"4230412438","pt":1631532708257,"mc":[{"id":"1.187557146","rc":[{"batl":[[0,2,105.8]],"ltp":2.0,"tv":2131.71,"id":19931652}]}]}
{"op":"mcm","clk":"4230412493","pt":1631532708930,"mc":[{"id":"1.187557146","rc":[{"batb":[[0,1.91,9.02],[1,1.89,9.02],[2,1.82,31.8]],"batl":[[0,2,30]],"ltp":2.0,"tv":2131.71,"id":19931652},{"batb":[[0,1.81,30.29],[1,1.77,407.82],[2,1.57,30.89]],"ltp":2.0,"tv":18350.91,"id":8257797}]}]}
{"op":"mcm","clk":"4230412553","pt":1631532709653,"mc":[{"id":"1.187557146","rc":[{"batl":[[0,2,3.89]],"ltp":2.0,"tv":2131.71,"id":19931652},{"batb":[[0,2,3.89],[1,1.81,30.29],[2,1.77,407.82]],"batl":[[0,2.04,7.33],[1,2.08,1.75],[2,2.26,6.75]],"ltp":2.0,"tv":18350.91,"id":8257797}]}]}
{"op":"mcm","clk":"4230412628","pt":1631532710535,"mc":[{"id":"1.187557146","rc":[{"batl":[[0,2.24,3],[1,990,0.01],[2,990,0]],"ltp":2.0,"tv":2131.71,"id":19931652},{"batb":[[0,1.81,30.29],[1,1.77,407.82],[2,1.57,30.89]],"batl":[[0,2.08,1.75],[1,2.26,6.75],[2,2.82,234.47]],"ltp":2.0,"tv":18350.91,"id":8257797}]}]}
{"op":"mcm","clk":"4230412780","pt":1631532712340,"mc":[{"id":"1.187557146","rc":[{"batb":[[2,1.71,38.83]],"ltp":2.0,"tv":2131.71,"id":19931652},{"batl":[[1,2.82,234.47],[2,990,0.01]],"ltp":2.0,"tv":18350.91,"id":8257797}]}]}
{"op":"mcm","clk":"4230413027","pt":1631532715651,"mc":[{"id":"1.187557146","rc":[{"batb":[[2,1.73,37.91]],"ltp":2.0,"tv":2131.71,"id":19931652},{"batb":[[0,1.8,31.05]],"ltp":2.0,"tv":18350.91,"id":8257797}]}]}
{"op":"mcm","clk":"4230413163","pt":1631532717324,"mc":[{"id":"1.187557146","rc":[{"batl":[[0,2.06,248.18],[1,2.08,1.75],[2,2.82,234.47]],"ltp":2.0,"tv":18350.91,"id":8257797}]}]}
{"op":"mcm","clk":"4230413180","pt":1631532717533,"mc":[{"id":"1.187557146","rc":[{"batl":[[0,2.08,1.75],[1,2.82,234.47],[2,990,0.01]],"ltp":2.0,"tv":18350.91,"id":8257797}]}]}
{"op":"mcm","clk":"4230414027","pt":1631532727981,"mc":[{"id":"1.187557146","rc":[{"batb":[[0,2.16,17.28],[1,2.12,18.86],[2,1.91,9.02]],"batl":[[0,2.24,13.47],[1,2.28,100.71],[2,990,0.01]],"ltp":2.0,"tv":2131.71,"id":19931652},{"batb":[[2,1.67,33.42]],"batl":[[0,1.86,74.27],[1,1.88,29.69],[2,1.9,14.69]],"ltp":2.0,"tv":18350.91,"id":8257797}]}]}
{"op":"mcm","clk":"4230414103","pt":1631532728857,"mc":[{"id":"1.187557146","rc":[{"batb":[[2,2.04,45.1]],"ltp":2.0,"tv":2131.71,"id":19931652}]}]}
{"op":"mcm","clk":"4230414539","pt":1631532734897,"mc":[{"id":"1.187557146","rc":[{"trd":[[1.8,21.45]],"batb":[[0,1.8,30.35]],"ltp":1.8,"tv":18352.3,"id":8257797}],"tv":20484.01}]}
{"op":"mcm","clk":"4230414715","pt":1631532736973,"mc":[{"id":"1.187557146","rc":[{"batb":[[0,1.93,42.93],[1,1.91,9.02],[2,1.89,9.02]],"batl":[[0,2.24,3],[1,990,0.01],[2,990,0]],"ltp":2.0,"tv":2131.71,"id":19931652},{"batb":[[0,1.77,407.82],[1,1.61,45.52],[2,1.57,30.89]],"batl":[[0,2,6.91],[1,2.08,1.75],[2,2.82,234.47]],"ltp":1.8,"tv":18352.3,"id":8257797}]}]}
{"op":"mcm","clk":"4230414800","pt":1631532738061,"mc":[{"id":"1.187557146","rc":[{"batl":[[0,2.16,34.07],[1,2.24,3],[2,990,0.01]],"ltp":2.0,"tv":2131.71,"id":19931652}]}]}
{"op":"mcm","clk":"4230414900","pt":1631532739356,"mc":[{"id":"1.187557146","rc":[{"batl":[[0,2.16,17.04]],"ltp":2.0,"tv":2131.71,"id":19931652}]}]}
{"op":"mcm","clk":"4230414985","pt":1631532740187,"mc":[{"id":"1.187557146","rc":[{"batl":[[0,2.24,3],[1,990,0.01],[2,990,0]],"ltp":2.0,"tv":2131.71,"id":19931652},{"batb":[[0,1.86,8.12],[1,1.77,407.82],[2,1.61,45.35]],"batl":[[1,2.08,8.69]],"ltp":1.8,"tv":18352.3,"id":8257797}]}]}
{"op":"mcm","clk":"4230415302","pt":1631532744174,"mc":[{"id":"1.187557146","rc":[{"trd":[[1.86,4.68]],"batb":[[0,1.86,5.78]],"ltp":1.86,"tv":18356.98,"id":8257797}],"tv":20488.69}]}
{"op":"mcm","clk":"4230415547","pt":1631532747101,"mc":[{"id":"1.187557146","rc":[{"trd":[[2,405.17]],"batl":[[0,2,6.81]],"ltp":2.0,"tv":18357.16,"id":8257797}],"tv":20488.87}]}
{"op":"mcm","clk":"4230415804","pt":1631532750303,"mc":[{"id":"1.187557146","rc":[{"batb":[[0,1.99,44.51],[1,1.93,42.93],[2,1.91,9.02]],"ltp":2.0,"tv":2131.71,"id":19931652},{"batl":[[1,2.02,8.25],[2,2.08,8.69]],"ltp":2.0,"tv":18357.16,"id":8257797}]}]}
{"op":"mcm","clk":"4230415821","pt":1631532750512,"mc":[{"id":"1.187557146","rc":[{"batb":[[0,1.93,42.93],[1,1.91,9.02],[2,1.89,9.02]],"ltp":2.0,"tv":2131.71,"id":19931652},{"batl":[[1,2.08,8.69],[2,2.82,234.47]],"ltp":2.0,"tv":18357.16,"id":8257797}]}]}
{"op":"mcm","clk":"4230416568","pt":1631532759137,"mc":[{"id":"1.187557146","rc":[{"batb":[[0,1.77,407.82],[1,1.61,45.35],[2,1.57,30.89]],"ltp":2.0,"tv":18357.16,"id":8257797}]}]}
{"op":"mcm","clk":"4230416652","pt":1631532759809,"mc":[{"id":"1.187557146","rc":[{"batb":[[0,1.61,45.35],[1,1.57,30.89],[2,1.21,766.61]],"batl":[[2,990,0.01]],"ltp":2.0,"tv":18357.16,"id":8257797}]}]}
{"op":"mcm","clk":"4230416784","pt":1631532761036,"mc":[{"id":"1.187557146","rc":[{"trd":[[2.24,3]],"batb":[[0,2.48,16.12],[1,2.46,15.88],[2,2.4,98.04]],"batl":[[0,2.6,6.16]],"ltp":2.24,"tv":2134.71,"id":19931652},{"trd":[[1.8,25.18]],"batb":[[1,1.6,125.36],[2,1.57,30.89]],"batl":[[0,1.66,15.32],[1,1.68,101.86],[2,1.7,16.42]],"ltp":1.8,"tv":18360.89,"id":8257797}],"tv":20495.6}]}
{"op":"mcm","clk":"4230417796","pt":1631532771149,"mc":[{"id":"1.187557146","rc":[{"trd":[[2.5,1.15]],"batl":[[0,2.5,9.57],[1,2.6,6.16],[2,990,0.01]],"ltp":2.5,"tv":2134.77,"id":19931652},{"trd":[[1.66,42.83]],"batl":[[0,1.68,101.86],[1,1.7,16.42],[2,1.81,51.5]],"ltp":1.66,"tv":18391.44,"id":8257797}],"tv":20526.21}]}
{"op":"mcm","clk":"4230417920","pt":1631532772036,"mc":[{"id":"1.187557146","rc":[{"batl":[[0,2.5,29.7]],"ltp":2.5,"tv":2134.77,"id":19931652},{"batb":[[0,1.66,15.23],[1,1.61,45.35],[2,1.6,125.36]],"ltp":1.66,"tv":18391.44,"id":8257797}]}]}
{"op":"mcm","clk":"4230418047","pt":1631532773337,"mc":[{"id":"1.187557146","rc":[{"batl":[[0,2.5,20]],"ltp":2.5,"tv":2134.77,"id":19931652},{"batb":[[0,1.61,45.35],[1,1.6,125.36],[2,1.57,30.89]],"ltp":1.66,"tv":18391.44,"id":8257797}]}]}
{"op":"mcm","clk":"4230418101","pt":1631532774062,"mc":[{"id":"1.187557146","rc":[{"batl":[[0,2.6,6.16],[1,990,0.01],[2,990,0]],"ltp":2.5,"tv":2134.77,"id":19931652}]}]}
{"op":"mcm","clk":"4230418287","pt":1631532776249,"mc":[{"id":"1.187557146","rc":[{"batb":[[0,2.34,29.96],[1,2.22,6.84],[2,2.16,7.03]],"batl":[[0,990,0.01],[1,990,0]],"ltp":2.5,"tv":2134.77,"id":19931652},{"batb":[[1,1.57,30.89],[2,1.55,426.3]],"batl":[[0,1.68,33.22]],"ltp":1.66,"tv":18391.44,"id":8257797}]}]}
{"op":"mcm","clk":"4230418325","pt":1631532776760,"mc":[{"id":"1.187557146","rc":[{"batb":[[0,2.16,7.03],[1,2.12,40],[2,1.47,1.54]],"ltp":2.5,"tv":2134.77,"id":19931652},{"batb":[[0,1.57,30.89],[1,1.55,426.3],[2,1.45,67.36]],"batl":[[0,1.86,43.75],[1,2,11.42],[2,2.08,1.75]],"ltp":1.66,"tv":18391.44,"id":8257797}]}]}
{"op":"mcm","clk":"4230418455","pt":1631532778326,"mc":[{"id":"1.187557146","rc":[{"batl":[[0,2.48,48.1],[1,990,0.01]],"ltp":2.5,"tv":2134.77,"id":19931652},{"batb":[[0,1.68,22.42],[1,1.57,30.89],[2,1.55,426.3]],"ltp":1.66,"tv":18391.44,"id":8257797}]}]}
{"op":"mcm","clk":"4230418520","pt":1631532779157,"mc":[{"id":"1.187557146","rc":[{"batl":[[0,2.48,32]],"ltp":2.5,"tv":2134.77,"id":19931652},{"batb":[[0,1.57,30.89],[1,1.55,426.3],[2,1.45,67.36]],"ltp":1.66,"tv":18391.44,"id":8257797}]}]}
{"op":"mcm","clk":"4230418611","pt":1631532780346,"mc":[{"id":"1.187557146","rc":[{"batl":[[0,990,0.01],[1,990,0]],"ltp":2.5,"tv":2134.77,"id":19931652}]}]}
{"op":"mcm","clk":"4230419326","pt":1631532788061,"mc":[{"id":"1.187557146","rc":[{"batl":[[0,2.28,5.81],[1,990,0.01]],"ltp":2.5,"tv":2134.77,"id":19931652},{"batb":[[0,1.72,146.33],[1,1.69,23.66],[2,1.6,34.88]],"batl":[[0,1.8,31.01],[1,1.82,15.33],[2,1.83,17.94]],"ltp":1.66,"tv":18391.44,"id":8257797}]}]}
{"op":"mcm","clk":"4230419389","pt":1631532788838,"mc":[{"id":"1.187557146","rc":[{"batb":[[2,1.91,27.53]],"ltp":2.5,"tv":2134.77,"id":19931652},{"batb":[[0,1.74,34.81],[1,1.72,146.33],[2,1.69,23.66]],"ltp":1.66,"tv":18391.44,"id":8257797}]}]}
{"op":"mcm","clk":"4230419889","pt":1631532794340,"mc":[{"id":"1.187557146","rc":[{"trd":[[2.28,19.77]],"batb":[[2,2.02,7.24]],"batl":[[0,990,0.01],[1,990,0]],"ltp":2.28,"tv":2140.58,"id":19931652},{"trd":[[1.74,0.47],[1.78,76.11]],"batb":[[0,1.74,34.58]],"ltp":1.74,"tv":18399.35,"id":8257797}],"tv":20539.93}]}
{"op":"mcm","clk":"4230419903","pt":1631532794544,"mc":[{"id":"1.187557146","rc":[{"trd":[[1.8,61.06]],"batl":[[0,1.8,13.07]],"ltp":1.8,"tv":18435.23,"id":8257797}],"tv":20575.81}]}
{"op":"mcm","clk":"4230420302","pt":1631532799073,"mc":[{"id":"1.187557146","rc":[{"batb":[[0,1.97,47.17],[1,1.91,27.53],[2,1.47,1.54]],"ltp":2.28,"tv":2140.58,"id":19931652},{"batb":[[0,1.62,421.17],[1,1.57,30.89],[2,1.53,55.06]],"batl":[[0,2,11.42],[1,2.08,1.75],[2,2.42,290.48]],"ltp":1.8,"tv":18435.23,"id":8257797}]}]}
{"op":"mcm","clk":"4230420375","pt":1631532800058,"mc":[{"id":"1.187557146","rc":[{"batb":[[0,1.8,12.99],[1,1.62,421.17],[2,1.57,30.89]],"ltp":1.8,"tv":18435.23,"id":8257797}]}]}
{"op":"mcm","clk":"4230420494","pt":1631532801346,"mc":[{"id":"1.187557146","rc":[{"batl":[[0,2.24,14.74],[1,990,0.01]],"ltp":2.28,"tv":2140.58,"id":19931652}]}]}
{"op":"mcm","clk":"4230420552","pt":1631532802110,"mc":[{"id":"1.187557146","rc":[{"batb":[[0,2.02,7.74],[1,1.97,47.17],[2,1.91,27.53]],"ltp":2.28,"tv":2140.58,"id":19931652},{"batb":[[0,1.62,421.17],[1,1.57,30.89],[2,1.53,55.06]],"batl":[[0,1.98,44.25],[1,2,11.42],[2,2.04,7.38]],"ltp":1.8,"tv":18435.23,"id":8257797}]}]}
{"op":"mcm","clk":"4230420597","pt":1631532802644,"mc":[{"id":"1.187557146","rc":[{"batb":[[0,1.97,47.17],[1,1.91,27.53],[2,1.47,1.54]],"batl":[[0,990,0.01],[1,990,0]],"ltp":2.28,"tv":2140.58,"id":19931652},{"batl":[[0,2,11.42],[1,2.04,7.38],[2,2.08,1.75]],"ltp":1.8,"tv":18435.23,"id":8257797}]}]}
{"op":"mcm","clk":"4230421072","pt":1631532809106,"mc":[{"id":"1.187557146","rc":[{"batb":[[0,2.02,8.74],[1,1.97,47.17],[2,1.91,27.53]],"ltp":2.28,"tv":2140.58,"id":19931652},{"batl":[[0,1.98,44.25],[1,2,11.42],[2,2.04,7.38]],"ltp":1.8,"tv":18435.23,"id":8257797}]}]}
{"op":"mcm","clk":"4230421096","pt":1631532809367,"mc":[{"id":"1.187557146","rc":[{"batb":[[0,1.97,47.17],[1,1.91,27.53],[2,1.47,1.54]],"ltp":2.28,"tv":2140.58,"id":19931652},{"batl":[[0,2,11.42],[1,2.04,7.38],[2,2.08,1.75]],"ltp":1.8,"tv":18435.23,"id":8257797}]}]}
{"op":"mcm","clk":"4230421222","pt":1631532810975,"mc":[{"id":"1.187557146","rc":[{"batb":[[0,1.57,30.89],[1,1.53,55.06],[2,1.21,766.61]],"ltp":1.8,"tv":18435.23,"id":8257797}]}]}
{"op":"mcm","clk":"4230421296","pt":1631532811978,"mc":[{"id":"1.187557146","rc":[{"batb":[[0,2.72,15.09],[1,2.62,15.26],[2,1.97,47.17]],"batl":[[0,2.84,6.65],[1,3,50.97],[2,990,0.01]],"ltp":2.28,"tv":2140.58,"id":19931652},{"trd":[[1.57,686.08]],"batb":[[0,1.53,55.06],[1,1.5,101.93],[2,1.44,38.76]],"batl":[[0,1.58,96.23],[1,1.6,34.88],[2,1.62,17.23]],"ltp":1.57,"tv":18497.02,"id":8257797}],"tv":20637.6}]}
{"op":"mcm","clk":"4230421377","pt":1631532813009,"mc":[{"id":"1.187557146","rc":[{"batb":[[2,2.54,23.93]],"batl":[[2,6,3]],"ltp":2.28,"tv":2140.58,"id":19931652}]}]}
{"op":"mcm","clk":"4230421478","pt":1631532814307,"mc":[{"id":"1.187557146","rc":[{"batb":[[2,1.46,441.71]],"ltp":1.57,"tv":18497.02,"id":8257797}]}]}
{"op":"mcm","clk":"4230422040","pt":1631532821268,"mc":[{"id":"1.187557146","rc":[{"batb":[[1,2.54,23.93],[2,2.4,6.56]],"ltp":2.28,"tv":2140.58,"id":19931652}]}]}
{"op":"mcm","clk":"4230422078","pt":1631532821887,"mc":[{"id":"1.187557146","rc":[{"batb":[[0,2.3,6.08],[1,2.24,33.47],[2,1.47,1.54]],"batl":[[0,6,3],[1,6.4,3],[2,6.6,3]],"ltp":2.28,"tv":2140.58,"id":19931652},{"batb":[[0,1.46,441.71],[1,1.38,85.69],[2,1.21,766.61]],"batl":[[0,2,11.42],[1,2.08,1.75],[2,2.22,333.55]],"ltp":1.57,"tv":18497.02,"id":8257797}]}]}
{"op":"mcm","clk":"4230422178","pt":1631532822973,"mc":[{"id":"1.187557146","rc":[{"batb":[[0,1.46,441.98]],"ltp":1.57,"tv":18497.02,"id":8257797}]}]}
{"op":"mcm","clk":"4230422380","pt":1631532825204,"mc":[{"id":"1.187557146","rc":[{"batl":[[0,1.76,49.27],[1,2,11.42],[2,2.08,1.75]],"ltp":1.57,"tv":18497.02,"id":8257797}]}]}
{"op":"mcm","clk":"4230422397","pt":1631532825407,"mc":[{"id":"1.187557146","rc":[{"batb":[[0,1.46,441.71]],"ltp":1.57,"tv":18497.02,"id":8257797}]}]}
{"op":"mcm","clk":"4230422908","pt":1631532832007,"mc":[{"id":"1.187557146","rc":[{"batb":[[0,2.4,6.51],[1,2.3,6.08],[2,2.24,33.47]],"ltp":2.28,"tv":2140.58,"id":19931652},{"batl":[[0,1.71,50.5],[1,1.76,49.27],[2,2,11.42]],"ltp":1.57,"tv":18497.02,"id":8257797}]}]}
{"op":"mcm","clk":"4230422950","pt":1631532832412,"mc":[{"id":"1.187557146","rc":[{"batb":[[0,2.3,6.08],[1,2.24,33.47],[2,1.47,1.54]],"ltp":2.28,"tv":2140.58,"id":19931652},{"batl":[[0,1.76,49.27],[1,2,11.42],[2,2.08,1.75]],"ltp":1.57,"tv":18497.02,"id":8257797}]}]}
{"op":"mcm","clk":"4230423513","pt":1631532839105,"mc":[{"id":"1.187557146","rc":[{"batb":[[0,2.4,6.16],[1,2.3,6.08],[2,2.24,33.47]],"ltp":2.28,"tv":2140.58,"id":19931652},{"batl":[[0,1.71,47.5],[1,1.76,49.27],[2,2,11.42]],"ltp":1.57,"tv":18497.02,"id":8257797}]}]}
{"op":"mcm","clk":"4230423558","pt":1631532839824,"mc":[{"id":"1.187557146","rc":[{"batb":[[0,2.3,6.08],[1,2.24,33.47],[2,1.47,1.54]],"ltp":2.28,"tv":2140.58,"id":19931652},{"batl":[[0,1.76,49.27],[1,2,11.42],[2,2.08,1.75]],"ltp":1.57,"tv":18497.02,"id":8257797}]}]}
{"op":"mcm","clk":"4230423819","pt":1631532843036,"mc":[{"id":"1.187557146","rc":[{"batb":[[0,2.4,5.81],[1,2.3,6.08],[2,2.24,33.47]],"ltp":2.28,"tv":2140.58,"id":19931652},{"batl":[[0,1.71,50.5],[1,1.76,49.27],[2,2,11.42]],"ltp":1.57,"tv":18497.02,"id":8257797}]}]}
{"op":"mcm","clk":"4230423915","pt":1631532844218,"mc":[{"id":"1.187557146","rc":[{"batb":[[0,2.3,6.08],[1,2.24,33.47],[2,1.47,1.54]],"ltp":2.28,"tv":2140.58,"id":19931652},{"batb":[[0,1.75,2.17],[1,1.46,441.71],[2,1.38,85.69]],"batl":[[0,1.76,49.27],[1,2,11.42],[2,2.08,1.75]],"ltp":1.57,"tv":18497.02,"id":8257797}]}]}
{"op":"mcm","clk":"4230424149","pt":1631532847035,"mc":[{"id":"1.187557146","rc":[{"trd":[[2.34,1.62]],"ltp":2.34,"tv":2142.2,"id":19931652},{"trd":[[1.75,2.17]],"batb":[[0,1.38,85.69],[1,1.21,766.61],[2,1.2,100]],"ltp":1.75,"tv":18499.19,"id":8257797}],"tv":20641.39}]}
{"op":"mcm","clk":"4230424281","pt":1631532848336,"mc":[{"id":"1.187557146","rc":[{"batb":[[0,3.3,59.77],[1,2.3,6.08],[2,2.24,33.47]],"batl":[[0,3.85,75.99],[1,6,3],[2,6.4,3]],"ltp":2.34,"tv":2142.2,"id":19931652},{"trd":[[1.37,316.95],[1.38,171.38]],"batb":[[0,1.21,766.61],[1,1.2,100],[2,1.19,103]],"batl":[[0,1.4,5.74],[1,1.47,136.06],[2,1.76,49.27]],"ltp":1.37,"tv":18702.79,"id":8257797}],"tv":20844.99}]}
{"op":"mcm","clk":"4230424345","pt":1631532849269,"mc":[{"id":"1.187557146","rc":[{"batb":[[1,3.1,34.98],[2,2.68,20.84]],"ltp":2.34,"tv":2142.2,"id":19931652},{"batb":[[0,1.32,42.29],[1,1.31,108.03],[2,1.3,21.47]],"batl":[[1,1.45,38.49],[2,1.47,46.21]],"ltp":1.37,"tv":18702.79,"id":8257797}]}]}
{"op":"mcm","clk":"4230424497","pt":1631532850946,"mc":[{"id":"1.187557146","rc":[{"batb":[[0,1.34,471.85],[1,1.32,42.29],[2,1.31,108.03]],"ltp":1.37,"tv":18702.79,"id":8257797}]}]}
{"op":"mcm","clk":"4230424702","pt":1631532853157,"mc":[{"id":"1.187557146","rc":[{"batl":[[1,4.6,63],[2,6,3]],"ltp":2.34,"tv":2142.2,"id":19931652}]}]}
{"op":"mcm","clk":"4230424721","pt":1631532853364,"mc":[{"id":"1.187557146","rc":[{"batl":[[1,6,3],[2,6.4,3]],"ltp":2.34,"tv":2142.2,"id":19931652}]}]}
{"op":"mcm","clk":"4230425082","pt":1631532857273,"mc":[{"id":"1.187557146","rc":[{"batb":[[1,3.15,33.64],[2,3.1,34.98]],"ltp":2.34,"tv":2142.2,"id":19931652},{"batb":[[0,1.37,88.28],[1,1.34,471.85],[2,1.32,42.29]],"ltp":1.37,"tv":18702.79,"id":8257797}]}]}
{"op":"mcm","clk":"4230425152","pt":1631532857950,"mc":[{"id":"1.187557146","rc":[{"batb":[[2,2.72,20.08]],"ltp":2.34,"tv":2142.2,"id":19931652},{"trd":[[1.4,127.25]],"batl":[[0,1.4,5.47]],"ltp":1.4,"tv":18703.33,"id":8257797}],"tv":20845.53}]}
{"op":"mcm","clk":"4230425248","pt":1631532859045,"mc":[{"id":"1.187557146","rc":[{"batb":[[0,1.4,27.05],[1,1.37,88.28],[2,1.34,471.85]],"batl":[[0,1.45,38.49],[1,1.47,46.21],[2,1.76,49.27]],"ltp":1.4,"tv":18703.33,"id":8257797}]}]}
{"op":"mcm","clk":"4230425457","pt":1631532861281,"mc":[{"id":"1.187557146","rc":[{"batl":[[0,3.7,5.35],[1,3.85,75.99],[2,6,3]],"ltp":2.34,"tv":2142.2,"id":19931652},{"trd":[[1.4,154.73]],"batb":[[0,1.4,13.31]],"ltp":1.4,"tv":18730.81,"id":8257797}],"tv":20873.01}]}
{"op":"mcm","clk":"4230425701","pt":1631532864283,"mc":[{"id":"1.187557146","rc":[{"batb":[[0,1.37,88.28],[1,1.34,471.85],[2,1.32,42.29]],"ltp":1.4,"tv":18730.81,"id":8257797}]}]}
{"op":"mcm","clk":"4230426011","pt":1631532868181,"mc":[{"id":"1.187557146","rc":[{"batl":[[0,3.85,75.99],[1,6,3],[2,6.4,3]],"ltp":2.34,"tv":2142.2,"id":19931652},{"trd":[[1.37,356.95]],"batb":[[0,1.37,68.28]],"ltp":1.37,"tv":18770.81,"id":8257797}],"tv":20913.01}]}
{"op":"mcm","clk":"4230426273","pt":1631532871357,"mc":[{"id":"1.187557146","rc":[{"trd":[[1.38,199.72],[1.39,292.26]],"batl":[[0,1.39,285.39],[1,1.4,6.64],[2,1.45,38.49]],"ltp":1.39,"tv":18971.73,"id":8257797}],"tv":21113.93}]}
{"op":"mcm","clk":"4230426307","pt":1631532871786,"mc":[{"id":"1.187557146","rc":[{"trd":[[1.39,293.16]],"batl":[[0,1.39,284.94],[1,1.45,38.49],[2,1.47,46.21]],"ltp":1.39,"tv":18972.63,"id":8257797}],"tv":21114.83}]}
{"op":"mcm","clk":"4230426415","pt":1631532872984,"mc":[{"id":"1.187557146","rc":[{"trd":[[3.55,0.93]],"ltp":3.55,"tv":2143.13,"id":19931652},{"trd":[[1.39,295.53]],"batl":[[0,1.39,282.57]],"ltp":1.39,"tv":18975.0,"id":8257797}],"tv":21118.13}]}
{"op":"mcm","clk":"4230426471","pt":1631532873564,"mc":[{"id":"1.187557146","rc":[{"trd":[[3.55,1.87]],"ltp":3.55,"tv":2144.07,"id":19931652},{"trd":[[1.39,302.69]],"batl":[[0,1.39,277.79]],"ltp":1.39,"tv":18982.16,"id":8257797}],"tv":21126.23}]}
{"op":"mcm","clk":"4230426547","pt":1631532874503,"mc":[{"id":"1.187557146","rc":[{"batl":[[0,3.7,5.25],[1,3.85,75.99],[2,6,3]],"ltp":3.55,"tv":2144.07,"id":19931652},{"batl":[[0,1.39,291.78]],"ltp":1.39,"tv":18982.16,"id":8257797}]}]}
{"op":"mcm","clk":"4230426735","pt":1631532876277,"mc":[{"id":"1.187557146","rc":[{"trd":[[1.39,394.07]],"batl":[[0,1.39,246.09]],"ltp":1.39,"tv":19073.54,"id":8257797}],"tv":21217.61}]}
{"op":"mcm","clk":"4230426756","pt":1631532876487,"mc":[{"id":"1.187557146","rc":[{"trd":[[1.39,416.91]],"batl":[[0,1.39,234.67]],"ltp":1.39,"tv":19096.38,"id":8257797}],"tv":21240.45}]}
{"op":"mcm","clk":"4230426994","pt":1631532879306,"mc":[{"id":"1.187557146","rc":[{"batb":[[0,1.37,226.28]],"ltp":1.39,"tv":19096.38,"id":8257797}]}]}
{"op":"mcm","clk":"4230427009","pt":1631532879466,"mc":[{"id":"1.187557146","rc":[{"trd":[[1.37,357.27]],"batb":[[0,1.37,226.12]],"ltp":1.37,"tv":19096.7,"id":8257797}],"tv":21240.77}]}
{"op":"mcm","clk":"4230427157","pt":1631532881295,"mc":[{"id":"1.187557146","rc":[{"batl":[[0,3.85,75.99],[1,6,3],[2,6.4,3]],"ltp":3.55,"tv":2144.07,"id":19931652},{"trd":[[1.37,390.04]],"batb":[[0,1.37,209.74]],"batl":[[0,1.39,220.68]],"ltp":1.37,"tv":19129.47,"id":8257797}],"tv":21273.54}]}
{"op":"mcm","clk":"4230427269","pt":1631532882809,"mc":[{"id":"1.187557146","rc":[{"batl":[[0,1.45,38.49],[1,1.47,46.21],[2,1.76,49.27]],"ltp":1.37,"tv":19129.47,"id":8257797}]}]}
{"op":"mcm","clk":"4230427390","pt":1631532884184,"mc":[{"id":"1.187557146","rc":[{"batl":[[0,3.7,5.25],[1,3.85,75.99],[2,6,3]],"ltp":3.55,"tv":2144.07,"id":19931652},{"trd":[[1.39,444.89]],"batb":[[0,1.39,4.05],[1,1.37,51.74],[2,1.34,471.85]],"ltp":1.39,"tv":19157.45,"id":8257797}],"tv":21301.52}]}
{"op":"mcm","clk":"4230427477","pt":1631532885179,"mc":[{"id":"1.187557146","rc":[{"batb":[[0,1.39,8.56]],"ltp":1.39,"tv":19157.45,"id":8257797}]}]}
{"op":"mcm","clk":"4230427514","pt":1631532885694,"mc":[{"id":"1.187557146","rc":[{"trd":[[3.7,108.95],[3.85,37.28]],"batl":[[0,3.85,38.71],[1,6,3],[2,6.4,3]],"ltp":3.85,"tv":2186.6,"id":19931652},{"trd":[[1.35,447.73],[1.37,507.7],[1.39,462.01]],"batb":[[0,1.34,471.85],[1,1.3,111.21],[2,1.21,766.61]],"batl":[[0,1.47,27.22],[1,1.76,49.27],[2,1.95,415.52]],"ltp":1.35,"tv":19398.56,"id":8257797}],"tv":21585.16}]}
{"op":"mcm","clk":"4230427576","pt":1631532886484,"mc":[{"id":"1.187557146","rc":[{"batl":[[0,1.37,1.38],[1,1.47,27.22],[2,1.76,49.27]],"ltp":1.35,"tv":19398.56,"id":8257797}]}]}
{"op":"mcm","clk":"4230427697","pt":1631532887998,"mc":[{"id":"1.187557146","rc":[{"batl":[[1,1.38,4.51],[2,1.47,27.22]],"ltp":1.35,"tv":19398.56,"id":8257797}]}]}
{"op":"mcm","clk":"4230427890","pt":1631532890307,"mc":[{"id":"1.187557146","rc":[{"batb":[[0,1.35,111],[1,1.34,471.85],[2,1.3,111.21]],"ltp":1.35,"tv":19398.56,"id":8257797}]}]}
{"op":"mcm","clk":"4230428212","pt":1631532894020,"mc":[{"id":"1.187557146","rc":[{"batl":[[2,1.39,24.16]],"ltp":1.35,"tv":19398.56,"id":8257797}]}]}
{"op":"mcm","clk":"4230428514","pt":1631532897308,"mc":[{"id":"1.187557146","rc":[{"trd":[[3.7,109.46]],"batl":[[0,3.7,4.74],[1,3.85,38.71],[2,6,3]],"ltp":3.7,"tv":2187.11,"id":19931652},{"trd":[[1.37,509.08]],"batl":[[0,1.38,4.51],[1,1.39,38.16],[2,1.47,27.22]],"ltp":1.37,"tv":19399.93,"id":8257797}],"tv":21587.05}]}
{"op":"mcm","clk":"4230428533","pt":1631532897514,"mc":[{"id":"1.187557146","rc":[{"batl":[[0,3.85,38.71],[1,6,3],[2,6.4,3]],"ltp":3.7,"tv":2187.11,"id":19931652},{"batl":[[1,1.39,24.16]],"ltp":1.37,"tv":19399.93,"id":8257797}]}]}
{"op":"mcm","clk":"4230428821","pt":1631532900623,"mc":[{"id":"1.187557146","rc":[{"batl":[[0,3.7,4.74],[1,3.85,38.71],[2,6,3]],"ltp":3.7,"tv":2187.11,"id":19931652},{"batl":[[1,1.39,39.52]],"ltp":1.37,"tv":19399.93,"id":8257797}]}]}
{"op":"mcm","clk":"4230429445","pt":1631532907520,"mc":[{"id":"1.187557146","rc":[{"batl":[[0,3.85,38.71],[1,6,3],[2,6.4,3]],"ltp":3.7,"tv":2187.11,"id":19931652},{"batl":[[1,1.39,24.16]],"ltp":1.37,"tv":19399.93,"id":8257797}]}]}
{"op":"mcm","clk":"4230429580","pt":1631532909041,"mc":[{"id":"1.187557146","rc":[{"batb":[[2,2.78,5.16]],"ltp":3.7,"tv":2187.11,"id":19931652}]}]}
{"op":"mcm","clk":"4230429701","pt":1631532910553,"mc":[{"id":"1.187557146","rc":[{"batl":[[0,3.7,4.74],[1,3.85,38.71],[2,6,3]],"ltp":3.7,"tv":2187.11,"id":19931652},{"batl":[[1,1.39,39.52]],"ltp":1.37,"tv":19399.93,"id":8257797}]}]}
{"op":"mcm","clk":"4230429987","pt":1631532913547,"mc":[{"id":"1.187557146","rc":[{"trd":[[3.55,11.33],[3.6,43.46]],"ltp":3.55,"tv":2198.29,"id":19931652},{"trd":[[1.38,204.23],[1.39,486.16]],"batl":[[0,1.39,15.37],[1,1.47,27.22],[2,1.56,49.92]],"ltp":1.39,"tv":19428.59,"id":8257797}],"tv":21626.89}]}
{"op":"mcm","clk":"4230430348","pt":1631532917425,"mc":[{"id":"1.187557146","rc":[{"trd":[[3.55,11.44]],"ltp":3.55,"tv":2198.41,"id":19931652},{"trd":[[1.39,486.46]],"batl":[[0,1.39,15.07]],"ltp":1.39,"tv":19428.89,"id":8257797}],"tv":21627.31}]}
{"op":"mcm","clk":"4230430728","pt":1631532921650,"mc":[{"id":"1.187557146","rc":[{"trd":[[3.7,110.49]],"batl":[[0,3.7,3.71]],"ltp":3.7,"tv":2199.44,"id":19931652},{"trd":[[1.37,511.85]],"ltp":1.37,"tv":19431.66,"id":8257797}],"tv":21631.11}]}
{"op":"mcm","clk":"4230431051","pt":1631532925242,"mc":[{"id":"1.187557146","rc":[{"trd":[[1.39,486.65]],"batl":[[0,1.39,14.98]],"ltp":1.39,"tv":19431.85,"id":8257797}],"tv":21631.29}]}
{"op":"mcm","clk":"4230431263","pt":1631532927862,"mc":[{"id":"1.187557146","rc":[{"batl":[[0,3.85,38.71],[1,6,3],[2,6.4,3]],"ltp":3.7,"tv":2199.44,"id":19931652},{"batb":[[0,1.34,471.85],[1,1.3,111.21],[2,1.21,766.61]],"batl":[[0,1.47,27.22],[1,1.56,49.92],[2,1.62,44.25]],"ltp":1.39,"tv":19431.85,"id":8257797}]}]}
{"op":"mcm","clk":"4230431448","pt":1631532930159,"mc":[{"id":"1.187557146","rc":[{"batb":[[0,2.72,20.08],[1,2.6,5.09],[2,1.47,1.54]],"batl":[[0,6,3],[1,6.4,3],[2,6.6,3]],"ltp":3.7,"tv":2199.44,"id":19931652},{"batl":[[0,1.95,415.52],[1,2.08,1.75],[2,44,7.23]],"ltp":1.39,"tv":19431.85,"id":8257797}]}]}
{"op":"mcm","clk":"4230431763","pt":1631532933354,"mc":[{"id":"1.187557146","rc":[{"batb":[[0,2.76,19.33]],"ltp":3.7,"tv":2199.44,"id":19931652},{"batb":[[1,1.29,114.64]],"batl":[[0,1.62,44.25],[1,1.95,415.52],[2,2.08,1.75]],"ltp":1.39,"tv":19431.85,"id":8257797}]}]}
{"op":"mcm","clk":"4230432051","pt":1631532936274,"mc":[{"id":"1.187557146","rc":[{"trd":[[1.34,56.2]],"batb":[[0,1.34,466.86]],"batl":[[0,1.38,4.51],[1,1.62,44.25],[2,1.95,415.52]],"ltp":1.34,"tv":19441.83,"id":8257797}],"tv":21641.27}]}
{"op":"mcm","clk":"4230432856","pt":1631532944802,"mc":[{"id":"1.187557146","rc":[{"trd":[[1.34,60.2]],"batb":[[0,1.29,114.64],[1,1.21,766.61],[2,1.2,100]],"batl":[[2,2.08,1.75]],"ltp":1.34,"tv":19445.83,"id":8257797}],"tv":21645.27}]}
{"op":"mcm","clk":"4230432965","pt":1631532946167,"mc":[{"id":"1.187557146","rc":[{"trd":[[3.6,45.19]],"batb":[[0,3,3.85],[1,2.88,71.71],[2,2.76,19.33]],"batl":[[0,3.1,4.51],[1,3.2,1006.56],[2,3.35,59.7]],"ltp":3.6,"tv":2201.17,"id":19931652},{"trd":[[1.38,208.74]],"batb":[[0,1.45,144.76],[1,1.29,114.64],[2,1.21,766.61]],"batl":[[0,1.5,7.7]],"ltp":1.38,"tv":19450.34,"id":8257797}],"tv":21651.51}]}
{"op":"mcm","clk":"4230433073","pt":1631532947267,"mc":[{"id":"1.187557146","rc":[{"batl":[[1,3.35,11.94],[2,6,3]],"ltp":3.6,"tv":2201.17,"id":19931652},{"batb":[[0,1.46,65.86],[1,1.45,144.76],[2,1.4,39.87]],"batl":[[1,1.55,36.01],[2,1.57,17.78]],"ltp":1.38,"tv":19450.34,"id":8257797}]}]}
{"op":"mcm","clk":"4230433189","pt":1631532948476,"mc":[{"id":"1.187557146","rc":[{"batb":[[2,1.44,437.56]],"ltp":1.38,"tv":19450.34,"id":8257797}]}]}
{"op":"mcm","clk":"4230433434","pt":1631532951175,"mc":[{"id":"1.187557146","rc":[{"trd":[[3,7.67]],"batb":[[0,3,2.7]],"batl":[[2,3.8,74.54]],"ltp":3.0,"tv":2203.47,"id":19931652},{"trd":[[1.5,8.92]],"batl":[[0,1.5,5.41]],"ltp":1.5,"tv":19454.92,"id":8257797}],"tv":21658.4}]}
{"op":"mcm","clk":"4230433459","pt":1631532951488,"mc":[{"id":"1.187557146","rc":[{"batl":[[2,6,3]],"ltp":3.0,"tv":2203.47,"id":19931652}]}]}
{"op":"mcm","clk":"4230433978","pt":1631532957295,"mc":[{"id":"1.187557146","rc":[{"trd":[[3,15.74],[3.1,0.04]],"batb":[[0,2.88,71.71],[1,2.76,19.33],[2,2.6,5.09]],"batl":[[0,3,5.37],[1,3.1,4.47],[2,3.35,11.94]],"ltp":3.0,"tv":2211.58,"id":19931652},{"trd":[[1.47,0.09],[1.5,14.41]],"batb":[[0,1.5,10.81],[1,1.46,65.86],[2,1.45,144.76]],"batl":[[0,1.55,36.01],[1,1.57,17.78],[2,1.62,44.25]],"ltp":1.5,"tv":19460.5,"id":8257797}],"tv":21672.08}]}
{"op":"mcm","clk":"4230433991","pt":1631532957396,"mc":[{"id":"1.187557146","rc":[{"batb":[[0,1.5,21.7]],"ltp":1.5,"tv":19460.5,"id":8257797}]}]}
{"op":"mcm","clk":"4230434213","pt":1631532959344,"mc":[{"id":"1.187557146","rc":[{"batl":[[0,3.1,4.47],[1,3.35,11.94],[2,6,3]],"ltp":3.0,"tv":2211.58,"id":19931652},{"batb":[[0,1.5,10.89]],"ltp":1.5,"tv":19460.5,"id":8257797}]}]}
{"op":"mcm","clk":"4230434308","pt":1631532960293,"mc":[{"id":"1.187557146","rc":[{"batb":[[0,2.76,19.33],[1,2.34,30.13],[2,2.28,5.91]],"batl":[[0,6,3],[1,6.4,3],[2,6.6,3]],"ltp":3.0,"tv":2211.58,"id":19931652},{"trd":[[1.5,34.41]],"batb":[[0,1.46,65.86],[1,1.44,437.56],[2,1.4,39.87]],"batl":[[2,2.08,1.75]],"ltp":1.5,"tv":19480.5,"id":8257797}],"tv":21692.08}]}
{"op":"mcm","clk":"4230434335","pt":1631532960607,"mc":[{"id":"1.187557146","rc":[{"batb":[[0,2.34,30.13],[1,2.28,5.91],[2,1.47,1.54]],"ltp":3.0,"tv":2211.58,"id":19931652},{"batb":[[0,1.44,437.56],[1,1.37,86.2],[2,1.21,766.61]],"batl":[[0,1.77,42.5],[1,2.08,1.75],[2,2.16,350.64]],"ltp":1.5,"tv":19480.5,"id":8257797}]}]}
{"op":"mcm","clk":"4230434645","pt":1631532963804,"mc":[{"id":"1.187557146","rc":[{"batl":[[1,1.78,37.75],[2,2.08,1.75]],"ltp":1.5,"tv":19480.5,"id":8257797}]}]}
{"op":"mcm","clk":"4230434850","pt":1631532966144,"mc":[{"id":"1.187557146","rc":[{"batl":[[0,3,1.8],[1,6,3],[2,6.4,3]],"ltp":3.0,"tv":2211.58,"id":19931652}]}]}
{"op":"mcm","clk":"4230435805","pt":1631532977337,"mc":[{"id":"1.187557146","rc":[{"trd":[[2.36,1.6]],"batb":[[0,2.4,4.91],[1,2.34,30.13],[2,2.28,5.91]],"ltp":2.36,"tv":2213.18,"id":19931652},{"trd":[[1.74,2.64]],"batl":[[0,1.71,41.5],[1,1.77,42.5],[2,1.78,37.75]],"ltp":1.74,"tv":19482.67,"id":8257797}],"tv":21695.85}]}
{"op":"mcm","clk":"4230435846","pt":1631532977648,"mc":[{"id":"1.187557146","rc":[{"batb":[[0,2.34,30.13],[1,2.28,5.91],[2,1.47,1.54]],"ltp":2.36,"tv":2213.18,"id":19931652},{"batl":[[0,1.77,42.5],[1,1.78,37.75],[2,2.08,1.75]],"ltp":1.74,"tv":19482.67,"id":8257797}]}]}
{"op":"mcm","clk":"4230436312","pt":1631532982356,"mc":[{"id":"1.187557146","rc":[{"batb":[[0,2.4,95.97],[1,2.34,30.13],[2,2.28,5.91]],"batl":[[0,2.56,11.78],[1,2.72,127.96],[2,3,1.8]],"ltp":2.36,"tv":2213.18,"id":19931652},{"batb":[[0,1.6,75],[1,1.52,36.72],[2,1.5,18.61]],"batl":[[0,1.68,8.89],[1,1.7,32.83],[2,1.72,16.22]],"ltp":1.74,"tv":19482.67,"id":8257797}]}]}
{"op":"mcm","clk":"4230436401","pt":1631532983141,"mc":[{"id":"1.187557146","rc":[{"batb":[[0,1.62,45.02],[1,1.6,25],[2,1.52,36.72]],"ltp":1.74,"tv":19482.67,"id":8257797}]}]}
{"op":"mcm","clk":"4230436580","pt":1631532985373,"mc":[{"id":"1.187557146","rc":[{"batb":[[2,1.55,420.3]],"ltp":1.74,"tv":19482.67,"id":8257797}]}]}
{"op":"mcm","clk":"4230436777","pt":1631532987359,"mc":[{"id":"1.187557146","rc":[{"trd":[[2.46,1.31]],"ltp":2.46,"tv":2214.49,"id":19931652},{"trd":[[1.68,5.88]],"batl":[[0,1.68,4.99]],"ltp":1.68,"tv":19488.55,"id":8257797}],"tv":21703.04}]}
{"op":"mcm","clk":"4230437059","pt":1631532990349,"mc":[{"id":"1.187557146","rc":[{"trd":[[1.68,15.86]],"batb":[[0,1.68,39.47],[1,1.64,70],[2,1.62,45.02]],"batl":[[0,1.7,32.83],[1,1.72,16.22],[2,1.77,42.5]],"ltp":1.68,"tv":19498.53,"id":8257797}],"tv":21713.02}]}
{"op":"mcm","clk":"4230437156","pt":1631532991347,"mc":[{"id":"1.187557146","rc":[{"batb":[[0,1.68,89.81]],"ltp":1.68,"tv":19498.53,"id":8257797}]}]}
{"op":"mcm","clk":"4230437219","pt":1631532992073,"mc":[{"id":"1.187557146","rc":[{"batb":[[0,1.68,45.28]],"ltp":1.68,"tv":19498.53,"id":8257797}]}]}
{"op":"mcm","clk":"4230437325","pt":1631532993170,"mc":[{"id":"1.187557146","rc":[{"trd":[[1.68,23.66]],"batb":[[0,1.68,14.75]],"ltp":1.68,"tv":19506.33,"id":8257797}],"tv":21720.82}]}
{"op":"mcm","clk":"4230437429","pt":1631532994267,"mc":[{"id":"1.187557146","rc":[{"batb":[[0,1.68,4.85]],"ltp":1.68,"tv":19506.33,"id":8257797}]}]}
{"op":"mcm","clk":"4230437598","pt":1631532996189,"mc":[{"id":"1.187557146","rc":[{"batb":[[0,2.34,30.13],[1,2.02,45.94],[2,1.99,39.51]],"batl":[[0,3,1.8],[1,6,3],[2,6.4,3]],"ltp":2.46,"tv":2214.49,"id":19931652},{"batb":[[0,1.64,70],[1,1.62,45.02],[2,1.55,420.3]],"batl":[[2,2.02,8.75]],"ltp":1.68,"tv":19506.33,"id":8257797}]}]}
{"op":"mcm","clk":"4230437673","pt":1631532996968,"mc":[{"id":"1.187557146","rc":[{"batb":[[0,2.02,45.94],[1,1.99,39.51],[2,1.47,1.54]],"ltp":2.46,"tv":2214.49,"id":19931652},{"batb":[[0,1.7,30.78],[1,1.55,420.3],[2,1.5,59.25]],"batl":[[0,2.02,8.75],[1,2.08,1.75],[2,2.42,294.35]],"ltp":1.68,"tv":19506.33,"id":8257797}]}]}
{"op":"mcm","clk":"4230437782","pt":1631532998318,"mc":[{"id":"1.187557146","rc":[{"batb":[[0,1.55,420.3],[1,1.5,59.25],[2,1.21,766.7]],"ltp":1.68,"tv":19506.33,"id":8257797}]}]}
{"op":"mcm","clk":"4230437848","pt":1631532999167,"mc":[{"id":"1.187557146","rc":[{"batb":[[0,1.7,24.34],[1,1.55,420.3],[2,1.5,59.25]],"ltp":1.68,"tv":19506.33,"id":8257797}]}]}
{"op":"mcm","clk":"4230437961","pt":1631533000579,"mc":[{"id":"1.187557146","rc":[{"batb":[[0,1.55,420.3],[1,1.5,59.25],[2,1.21,766.7]],"ltp":1.68,"tv":19506.33,"id":8257797}]}]}
{"op":"mcm","clk":"4230438188","pt":1631533003285,"mc":[{"id":"1.187557146","rc":[{"batl":[[0,1.68,4.51],[1,2.02,8.75],[2,2.08,1.75]],"ltp":1.68,"tv":19506.33,"id":8257797}]}]}
{"op":"mcm","clk":"4230438220","pt":1631533003697,"mc":[{"id":"1.187557146","rc":[{"trd":[[2.46,3.11]],"ltp":2.46,"tv":2216.29,"id":19931652},{"trd":[[1.68,26.3]],"batl":[[0,1.68,1.87]],"ltp":1.68,"tv":19508.97,"id":8257797}],"tv":21725.26}]}
{"op":"mcm","clk":"4230438433","pt":1631533006098,"mc":[{"id":"1.187557146","rc":[{"trd":[[2.46,4.39]],"ltp":2.46,"tv":2217.57,"id":19931652},{"trd":[[1.68,28.17]],"batl":[[0,2.02,8.75],[1,2.08,1.75],[2,2.42,294.35]],"ltp":1.68,"tv":19510.84,"id":8257797}],"tv":21728.41}]}
{"op":"mcm","clk":"4230438826","pt":1631533010008,"mc":[{"id":"1.187557146","rc":[{"batb":[[0,2.06,7.58],[1,2.02,45.94],[2,1.99,39.51]],"ltp":2.46,"tv":2217.57,"id":19931652},{"batl":[[0,1.94,43.25],[1,2.02,8.75],[2,2.08,1.75]],"ltp":1.68,"tv":19510.84,"id":8257797}]}]}
{"op":"mcm","clk":"4230438868","pt":1631533010582,"mc":[{"id":"1.187557146","rc":[{"batb":[[0,2.02,45.94],[1,1.99,39.51],[2,1.47,1.54]],"ltp":2.46,"tv":2217.57,"id":19931652},{"batl":[[0,2.02,8.75],[1,2.08,1.75],[2,2.42,294.35]],"ltp":1.68,"tv":19510.84,"id":8257797}]}]}
{"op":"mcm","clk":"4230439203","pt":1631533014224,"mc":[{"id":"1.187557146","rc":[{"batb":[[0,2.06,7.58],[1,2.02,45.94],[2,1.99,39.51]],"ltp":2.46,"tv":2217.57,"id":19931652},{"batl":[[0,1.94,38.75],[1,2.02,8.75],[2,2.08,1.75]],"ltp":1.68,"tv":19510.84,"id":8257797}]}]}
{"op":"mcm","clk":"4230439224","pt":1631533014468,"mc":[{"id":"1.187557146","rc":[{"batb":[[0,2.02,45.94],[1,1.99,39.51],[2,1.47,1.54]],"ltp":2.46,"tv":2217.57,"id":19931652},{"batl":[[0,2.02,8.75],[1,2.08,1.75],[2,2.42,294.35]],"ltp":1.68,"tv":19510.84,"id":8257797}]}]}
{"op":"mcm","clk":"4230439778","pt":1631533020140,"mc":[{"id":"1.187557146","rc":[{"batb":[[0,1.96,2.17],[1,1.55,420.3],[2,1.5,59.25]],"ltp":1.68,"tv":19510.84,"id":8257797}]}]}
{"op":"mcm","clk":"4230439879","pt":1631533021253,"mc":[{"id":"1.187557146","rc":[{"trd":[[2.06,2.06]],"batb":[[0,2.06,6.02],[1,2.02,45.94],[2,1.99,39.51]],"ltp":2.06,"tv":2219.63,"id":19931652},{"trd":[[1.96,2.17]],"batb":[[0,1.55,420.3],[1,1.5,59.25],[2,1.21,766.7]],"batl":[[0,1.94,40.25],[1,2.02,8.75],[2,2.08,1.75]],"ltp":1.96,"tv":19513.01,"id":8257797}],"tv":21732.64}]}
{"op":"mcm","clk":"4230439903","pt":1631533021507,"mc":[{"id":"1.187557146","rc":[{"batb":[[0,2.02,45.94],[1,1.99,39.51],[2,1.47,1.54]],"ltp":2.06,"tv":2219.63,"id":19931652},{"batl":[[0,2.02,8.75],[1,2.08,1.75],[2,2.42,294.35]],"ltp":1.96,"tv":19513.01,"id":8257797}]}]}
{"op":"mcm","clk":"4230440351","pt":1631533025514,"mc":[{"id":"1.187557146","rc":[{"batb":[[0,1.5,59.25],[1,1.21,766.7],[2,1.2,100]],"batl":[[2,990,0.01]],"ltp":1.96,"tv":19513.01,"id":8257797}]}]}
{"op":"mcm","clk":"4230440499","pt":1631533026822,"mc":[{"id":"1.187557146","rc":[{"batb":[[0,2.68,13.11],[1,2.64,15.16],[2,2.02,45.94]],"batl":[[0,2.84,7.16],[1,3,1.8],[2,3.05,89.96]],"ltp":2.06,"tv":2219.63,"id":19931652},{"batb":[[1,1.43,39.03],[2,1.41,19.79]],"batl":[[0,1.58,147.7],[1,1.59,101.61],[2,1.61,17.33]],"ltp":1.96,"tv":19513.01,"id":8257797}]}]}
{"op":"mcm","clk":"4230440629","pt":1631533027934,"mc":[{"id":"1.187557146","rc":[{"trd":[[2.84,0.68]],"batb":[[2,2.62,21.92]],"batl":[[0,2.84,6.48]],"ltp":2.84,"tv":2220.31,"id":19931652},{"trd":[[1.54,5.26]],"ltp":1.54,"tv":19514.27,"id":8257797}],"tv":21734.58}]}
{"op":"mcm","clk":"4230440750","pt":1631533029236,"mc":[{"id":"1.187557146","rc":[{"batb":[[1,1.46,435.28],[2,1.43,39.03]],"ltp":1.54,"tv":19514.27,"id":8257797}]}]}
{"op":"mcm","clk":"4230441334","pt":1631533035129,"mc":[{"id":"1.187557146","rc":[{"batb":[[0,1.54,63],[1,1.5,59.25],[2,1.46,435.28]],"ltp":1.54,"tv":19514.27,"id":8257797}]}]}
{"op":"mcm","clk":"4230441463","pt":1631533036542,"mc":[{"id":"1.187557146","rc":[{"trd":[[1.54,15.68]],"batb":[[0,1.54,57.79]],"ltp":1.54,"tv":19524.69,"id":8257797}],"tv":21745.01}]}
{"op":"mcm","clk":"4230441604","pt":1631533038155,"mc":[{"id":"1.187557146","rc":[{"batl":[[0,3,1.8],[1,3.05,89.96],[2,6,3]],"ltp":2.84,"tv":2220.31,"id":19931652},{"batl":[[0,1.58,129.66]],"ltp":1.54,"tv":19524.69,"id":8257797}]}]}
{"op":"mcm","clk":"4230441874","pt":1631533041238,"mc":[{"id":"1.187557146","rc":[{"batb":[[0,2.18,36.82],[1,1.47,1.54],[2,1.25,20]],"batl":[[1,6,3],[2,6.4,3]],"ltp":2.84,"tv":2220.31,"id":19931652},{"batb":[[0,1.46,435.28],[1,1.39,82.76],[2,1.21,766.7]],"batl":[[0,2.08,1.75],[1,2.22,337.78],[2,990,0.01]],"ltp":1.54,"tv":19524.69,"id":8257797}]}]}
{"op":"mcm","clk":"4230442111","pt":1631533044257,"mc":[{"id":"1.187557146","rc":[{"batb":[[1,2.06,7.58],[2,1.47,1.54]],"ltp":2.84,"tv":2220.31,"id":19931652},{"batl":[[0,1.93,39.5],[1,2.08,1.75],[2,2.22,337.78]],"ltp":1.54,"tv":19524.69,"id":8257797}]}]}
{"op":"mcm","clk":"4230442323","pt":1631533047277,"mc":[{"id":"1.187557146","rc":[{"batb":[[0,1.58,2],[1,1.46,435.28],[2,1.39,82.76]],"ltp":1.54,"tv":19524.69,"id":8257797}]}]}
{"op":"mcm","clk":"4230442901","pt":1631533054187,"mc":[{"id":"1.187557146","rc":[{"batb":[[0,1.84,2.17],[1,1.58,2],[2,1.46,435.28]],"ltp":1.54,"tv":19524.69,"id":8257797}]}]}
{"op":"mcm","clk":"4230442954","pt":1631533054667,"mc":[{"id":"1.187557146","rc":[{"trd":[[1.84,4.34]],"batb":[[0,1.58,2],[1,1.46,435.28],[2,1.39,82.76]],"ltp":1.84,"tv":19529.03,"id":8257797}],"tv":21749.35}]}
{"op":"mcm","clk":"4230443107","pt":1631533056282,"mc":[{"id":"1.187557146","rc":[{"batb":[[1,1.39,82.76],[2,1.21,766.7]],"batl":[[2,990,0.01]],"ltp":1.84,"tv":19529.03,"id":8257797}]}]}
{"op":"mcm","clk":"4230443279","pt":1631533058191,"mc":[{"id":"1.187557146","rc":[{"batb":[[0,2.2,107.5],[1,2.18,36.82],[2,2.06,7.58]],"batl":[[0,2.44,16.4],[1,2.88,508.94],[2,3,1.8]],"ltp":2.84,"tv":2220.31,"id":19931652},{"batb":[[0,1.76,15.32],[1,1.7,37.66],[2,1.59,35.11]],"batl":[[0,1.79,31.18],[1,1.8,6.85],[2,1.81,15.42]],"ltp":1.84,"tv":19529.03,"id":8257797}]}]}
{"op":"mcm","clk":"4230443474","pt":1631533060492,"mc":[{"id":"1.187557146","rc":[{"batb":[[2,1.62,415.42]],"ltp":1.84,"tv":19529.03,"id":8257797}]}]}
{"op":"mcm","clk":"4230443631","pt":1631533062195,"mc":[{"id":"1.187557146","rc":[{"trd":[[2.26,1.51]],"ltp":2.26,"tv":2221.82,"id":19931652},{"trd":[[1.79,5.83]],"batl":[[0,1.79,27.31]],"ltp":1.79,"tv":19534.86,"id":8257797}],"tv":21756.69}]}
{"op":"mcm","clk":"4230443953","pt":1631533065620,"mc":[{"id":"1.187557146","rc":[{"trd":[[2.26,13.63]],"ltp":2.26,"tv":2233.94,"id":19931652},{"trd":[[1.79,21.14]],"batl":[[0,1.79,12.01]],"ltp":1.79,"tv":19550.17,"id":8257797}],"tv":21784.11}]}
{"op":"mcm","clk":"4230444159","pt":1631533068318,"mc":[{"id":"1.187557146","rc":[{"trd":[[1.79,45.15]],"batb":[[0,1.79,14.57],[1,1.76,15.32],[2,1.7,37.66]],"batl":[[0,1.8,6.85],[1,1.81,15.42],[2,1.93,39.5]],"ltp":1.79,"tv":19574.19,"id":8257797}],"tv":21808.13}]}
{"op":"mcm","clk":"4230444168","pt":1631533068421,"mc":[{"id":"1.187557146","rc":[{"trd":[[1.79,49.69]],"batb":[[0,1.79,12.3]],"ltp":1.79,"tv":19578.73,"id":8257797}],"tv":21812.67}]}
{"op":"mcm","clk":"4230444278","pt":1631533069822,"mc":[{"id":"1.187557146","rc":[{"batb":[[0,1.76,15.32],[1,1.7,37.66],[2,1.62,415.42]],"batl":[[2,1.9,27.05]],"ltp":1.79,"tv":19578.73,"id":8257797}]}]}
{"op":"mcm","clk":"4230444379","pt":1631533071102,"mc":[{"id":"1.187557146","rc":[{"batb":[[0,1.79,11.97],[1,1.76,15.32],[2,1.7,37.66]],"ltp":1.79,"tv":19578.73,"id":8257797}]}]}
{"op":"mcm","clk":"4230444579","pt":1631533073331,"mc":[{"id":"1.187557146","rc":[{"batb":[[0,2.18,36.82],[1,2.06,7.58],[2,1.91,43.39]],"batl":[[0,3,1.8],[1,6,3],[2,6.4,3]],"ltp":2.26,"tv":2233.94,"id":19931652},{"batb":[[0,1.7,37.66],[1,1.62,415.42],[2,1.59,35.11]],"batl":[[0,1.81,15.42],[1,1.9,27.05],[2,1.93,39.5]],"ltp":1.79,"tv":19578.73,"id":8257797}]}]}
{"op":"mcm","clk":"4230444651","pt":1631533074110,"mc":[{"id":"1.187557146","rc":[{"batb":[[0,1.89,28.37],[1,1.84,41.72],[2,1.47,1.54]],"ltp":2.26,"tv":2233.94,"id":19931652},{"batb":[[0,1.62,415.42],[1,1.58,2],[2,1.56,50.96]],"batl":[[0,1.9,27.05],[1,2.08,1.75],[2,2.1,7.85]],"ltp":1.79,"tv":19578.73,"id":8257797}]}]}
{"op":"mcm","clk":"4230444788","pt":1631533075318,"mc":[{"id":"1.187557146","rc":[{"batb":[[0,1.8,6.81],[1,1.62,415.42],[2,1.58,2]],"batl":[[2,2.2,6.63]],"ltp":1.79,"tv":19578.73,"id":8257797}]}]}
{"op":"mcm","clk":"4230444933","pt":1631533077119,"mc":[{"id":"1.187557146","rc":[{"batl":[[0,2.22,12.5],[1,2.24,5.5],[2,3,1.8]],"ltp":2.26,"tv":2233.94,"id":19931652}]}]}
{"op":"mcm","clk":"4230445031","pt":1631533078210,"mc":[{"id":"1.187557146","rc":[{"batl":[[0,2.22,25],[1,3,1.8],[2,6,3]],"ltp":2.26,"tv":2233.94,"id":19931652},{"batb":[[0,1.62,415.42],[1,1.58,2],[2,1.56,50.96]],"ltp":1.79,"tv":19578.73,"id":8257797}]}]}
{"op":"mcm","clk":"4230445070","pt":1631533078832,"mc":[{"id":"1.187557146","rc":[{"batl":[[0,3,1.8],[1,6,3],[2,6.4,3]],"ltp":2.26,"tv":2233.94,"id":19931652}]}]}
{"op":"mcm","clk":"4230445510","pt":1631533084349,"mc":[{"id":"1.187557146","rc":[{"batb":[[0,1.91,43.39],[1,1.89,28.37],[2,1.84,41.72]],"ltp":2.26,"tv":2233.94,"id":19931652}]}]}
{"op":"mcm","clk":"4230445576","pt":1631533085129,"mc":[{"id":"1.187557146","rc":[{"batb":[[0,1.89,28.56],[1,1.84,41.72],[2,1.47,1.54]],"ltp":2.26,"tv":2233.94,"id":19931652}]}]}
{"op":"mcm","clk":"4230445632","pt":1631533085748,"mc":[{"id":"1.187557146","rc":[{"batb":[[0,1.58,2],[1,1.56,50.96],[2,1.21,766.7]],"ltp":1.79,"tv":19578.73,"id":8257797}]}]}
{"op":"mcm","clk":"4230445811","pt":1631533087729,"mc":[{"id":"1.187557146","rc":[{"batb":[[0,2.52,13.74],[1,1.89,28.56],[2,1.84,41.72]],"batl":[[0,2.6,5.32],[1,2.78,85.19],[2,3,1.8]],"ltp":2.26,"tv":2233.94,"id":19931652},{"batb":[[2,1.49,37.46]],"batl":[[0,1.65,62.7],[1,1.66,160.17],[2,1.67,23.96]],"ltp":1.79,"tv":19578.73,"id":8257797}]}]}
{"op":"mcm","clk":"4230445895","pt":1631533088677,"mc":[{"id":"1.187557146","rc":[{"batb":[[1,2.46,26.19],[2,1.93,26.72]],"ltp":2.26,"tv":2233.94,"id":19931652}]}]}
{"op":"mcm","clk":"4230446023","pt":1631533090123,"mc":[{"id":"1.187557146","rc":[{"batb":[[2,1.52,425.22]],"ltp":1.79,"tv":19578.73,"id":8257797}]}]}
{"op":"mcm","clk":"4230446203","pt":1631533092148,"mc":[{"id":"1.187557146","rc":[{"trd":[[2.52,2.84]],"batb":[[0,2.52,12.32]],"ltp":2.52,"tv":2236.78,"id":19931652},{"trd":[[1.65,8.72]],"batl":[[0,1.65,60.51]],"ltp":1.65,"tv":19583.11,"id":8257797}],"tv":21819.89}]}
{"op":"mcm","clk":"4230446310","pt":1631533093345,"mc":[{"id":"1.187557146","rc":[{"batb":[[0,1.62,80],[1,1.58,2],[2,1.56,50.96]],"ltp":1.65,"tv":19583.11,"id":8257797}]}]}
{"op":"mcm","clk":"4230447380","pt":1631533100272,"mc":[{"id":"1.187557146","rc":[{"batb":[[0,2.46,26.19],[1,1.93,26.72],[2,1.72,38.84]],"batl":[[0,3,1.8],[1,6,3],[2,6.4,3]],"ltp":2.52,"tv":2236.78,"id":19931652},{"trd":[[1.62,70.44]],"batb":[[0,1.62,44.78]],"batl":[[0,1.9,27.05],[1,2.08,1.75],[2,2.36,307.28]],"ltp":1.62,"tv":19653.55,"id":8257797}],"tv":21890.33}]}
{"op":"mcm","clk":"4230447400","pt":1631533100585,"mc":[{"id":"1.187557146","rc":[{"batb":[[0,1.93,26.72],[1,1.72,38.84],[2,1.47,1.54]],"ltp":2.52,"tv":2236.78,"id":19931652},{"batb":[[2,1.52,425.22]],"ltp":1.62,"tv":19653.55,"id":8257797}]}]}
{"op":"mcm","clk":"4230447470","pt":1631533101361,"mc":[{"id":"1.187557146","rc":[{"batb":[[0,1.58,2],[1,1.52,425.22],[2,1.39,80.75]],"ltp":1.62,"tv":19653.55,"id":8257797}]}]}
