{"op":"mcm","clk":"4221413149","pt":1631434703218,"mc":[{"id":"1.187549048","marketDefinition":{"bspMarket":false,"turnInPlayEnabled":true,"persistenceEnabled":true,"marketBaseRate":5.0,"eventId":"30895085","eventTypeId":"2","numberOfWinners":1,"bettingType":"ODDS","marketType":"MATCH_ODDS","marketTime":"2021-09-12T09:30:00.000Z","suspendTime":"2021-09-12T09:30:00.000Z","bspReconciled":false,"complete":true,"inPlay":false,"crossMatching":false,"runnersVoidable":false,"numberOfActiveRunners":2,"betDelay":0,"status":"OPEN","runners":[{"status":"ACTIVE","sortPriority":1,"id":9626937,"name":"O Parres Azcoitia"},{"status":"ACTIVE","sortPriority":2,"id":9628072,"name":"A Moratelli"}],"regulators":["MR_INT"],"countryCode":"GB","discountAllowed":false,"timezone":"GMT","openDate":"2021-09-12T10:30:00.000Z","version":4027521563,"name":"Match Odds","eventName":"O Parres Azcoitia v A Moratelli"},"rc":[{"batb":[[0,1.01,25]],"ltp":0.0,"tv":0.0,"id":9626937},{"batb":[[0,1.01,25]],"ltp":0.0,"tv":0.0,"id":9628072}]}]}
{"op":"mcm","clk":"4221413348","pt":1631434705086,"mc":[{"id":"1.187549048","marketDefinition":{"bspMarket":false,"turnInPlayEnabled":true,"persistenceEnabled":true,"marketBaseRate":5.0,"eventId":"30895085","eventTypeId":"2","numberOfWinners":1,"bettingType":"ODDS","marketType":"MATCH_ODDS","marketTime":"2021-09-12T09:30:00.000Z","suspendTime":"2021-09-12T09:30:00.000Z","bspReconciled":false,"complete":true,"inPlay":false,"crossMatching":false,"runnersVoidable":false,"numberOfActiveRunners":2,"betDelay":0,"status":"OPEN","runners":[{"status":"ACTIVE","sortPriority":1,"id":9626937,"name":"O Parres Azcoitia"},{"status":"ACTIVE","sortPriority":2,"id":9628072,"name":"A Moratelli"}],"regulators":["MR_INT"],"countryCode":"GB","discountAllowed":true,"timezone":"GMT","openDate":"2021-09-12T10:30:00.000Z","version":4027521563,"name":"Match Odds","eventName":"O Parres Azcoitia v A Moratelli"}}]}
{"op":"mcm","clk":"4221414765","pt":1631434719159,"mc":[{"id":"1.187549048","marketDefinition":{"bspMarket":false,"turnInPlayEnabled":true,"persistenceEnabled":true,"marketBaseRate":5.0,"eventId":"30895085","eventTypeId":"2","numberOfWinners":1,"bettingType":"ODDS","marketType":"MATCH_ODDS","marketTime":"2019-09-17T14:35:00.000Z","suspendTime":"2019-09-17T14:35:00.000Z","bspReconciled":false,"complete":true,"inPlay":false,"crossMatching":false,"runnersVoidable":false,"numberOfActiveRunners":2,"betDelay":0,"status":"OPEN","runners":[{"status":"ACTIVE","sortPriority":1,"id":9626937,"name":"O Parres Azcoitia"},{"status":"ACTIVE","sortPriority":2,"id":9628072,"name":"A Moratelli"}],"regulators":["MR_INT"],"countryCode":"GB","discountAllowed":true,"timezone":"GMT","openDate":"2021-09-12T10:30:00.000Z","version":4027521982,"name":"Match Odds","eventName":"O Parres Azcoitia v A Moratelli"}}]}
{"op":"mcm","clk":"4221415055","pt":1631434722182,"mc":[{"id":"1.187549048","marketDefinition":{"bspMarket":false,"turnInPlayEnabled":true,"persistenceEnabled":true,"marketBaseRate":5.0,"eventId":"30895085","eventTypeId":"2","numberOfWinners":1,"bettingType":"ODDS","marketType":"MATCH_ODDS","marketTime":"2019-09-17T14:35:00.000Z","suspendTime":"2019-09-17T14:35:00.000Z","bspReconciled":false,"complete":true,"inPlay":false,"crossMatching":false,"runnersVoidable":false,"numberOfActiveRunners":2,"betDelay":0,"status":"OPEN","runners":[{"status":"ACTIVE","sortPriority":1,"id":9626937,"name":"O Parres Azcoitia"},{"status":"ACTIVE","sortPriority":2,"id":9628072,"name":"A Moratelli"}],"regulators":["MR_INT"],"countryCode":"GB","discountAllowed":true,"timezone":"GMT","openDate":"2019-09-17T14:35:00.000Z","version":4027521982,"name":"Match Odds","eventName":"O Parres Azcoitia v A Moratelli"}}]}
{"op":"mcm","clk":"4221579631","pt":1631436306927,"mc":[{"id":"1.187549048","rc":[{"batb":[[0,1.01,7]],"ltp":0.0,"tv":0.0,"id":9626937},{"batb":[[0,1.01,7]],"ltp":0.0,"tv":0.0,"id":9628072}]}]}
{"op":"mcm","clk":"4221693443","pt":1631437374690,"mc":[{"id":"1.187549048","rc":[{"batb":[[0,1.05,879.5],[1,1.01,7]],"ltp":0.0,"tv":0.0,"id":9626937},{"batb":[[0,1.05,879.5],[1,1.01,7]],"ltp":0.0,"tv":0.0,"id":9628072}]}]}
{"op":"mcm","clk":"4221817446","pt":1631438461405,"mc":[{"id":"1.187549048","marketDefinition":{"bspMarket":false,"turnInPlayEnabled":true,"persistenceEnabled":true,"marketBaseRate":5.0,"eventId":"30895085","eventTypeId":"2","numberOfWinners":1,"bettingType":"ODDS","marketType":"MATCH_ODDS","marketTime":"2021-09-12T14:35:00.000Z","suspendTime":"2021-09-12T14:35:00.000Z","bspReconciled":false,"complete":true,"inPlay":false,"crossMatching":false,"runnersVoidable":false,"numberOfActiveRunners":2,"betDelay":0,"status":"OPEN","runners":[{"status":"ACTIVE","sortPriority":1,"id":9626937,"name":"O Parres Azcoitia"},{"status":"ACTIVE","sortPriority":2,"id":9628072,"name":"A Moratelli"}],"regulators":["MR_INT"],"countryCode":"GB","discountAllowed":true,"timezone":"GMT","openDate":"2019-09-17T14:35:00.000Z","version":4027596294,"name":"Match Odds","eventName":"O Parres Azcoitia v A Moratelli"}}]}
{"op":"mcm","clk":"4221817783","pt":1631438464412,"mc":[{"id":"1.187549048","marketDefinition":{"bspMarket":false,"turnInPlayEnabled":true,"persistenceEnabled":true,"marketBaseRate":5.0,"eventId":"30895085","eventTypeId":"2","numberOfWinners":1,"bettingType":"ODDS","marketType":"MATCH_ODDS","marketTime":"2021-09-12T14:35:00.000Z","suspendTime":"2021-09-12T14:35:00.000Z","bspReconciled":false,"complete":true,"inPlay":false,"crossMatching":false,"runnersVoidable":false,"numberOfActiveRunners":2,"betDelay":0,"status":"OPEN","runners":[{"status":"ACTIVE","sortPriority":1,"id":9626937,"name":"O Parres Azcoitia"},{"status":"ACTIVE","sortPriority":2,"id":9628072,"name":"A Moratelli"}],"regulators":["MR_INT"],"countryCode":"GB","discountAllowed":true,"timezone":"GMT","openDate":"2021-09-12T14:35:00.000Z","version":4027596294,"name":"Match Odds","eventName":"O Parres Azcoitia v A Moratelli"}}]}
{"op":"mcm","clk":"4221836008","pt":1631438618236,"mc":[{"id":"1.187549048","marketDefinition":{"bspMarket":false,"turnInPlayEnabled":true,"persistenceEnabled":true,"marketBaseRate":5.0,"eventId":"30895085","eventTypeId":"2","numberOfWinners":1,"bettingType":"ODDS","marketType":"MATCH_ODDS","marketTime":"2021-09-12T11:30:00.000Z","suspendTime":"2021-09-12T11:30:00.000Z","bspReconciled":false,"complete":true,"inPlay":false,"crossMatching":false,"runnersVoidable":false,"numberOfActiveRunners":2,"betDelay":0,"status":"OPEN","runners":[{"status":"ACTIVE","sortPriority":1,"id":9626937,"name":"O Parres Azcoitia"},{"status":"ACTIVE","sortPriority":2,"id":9628072,"name":"A Moratelli"}],"regulators":["MR_INT"],"countryCode":"GB","discountAllowed":true,"timezone":"GMT","openDate":"2021-09-12T14:35:00.000Z","version":4027601098,"name":"Match Odds","eventName":"O Parres Azcoitia v A Moratelli"}}]}
{"op":"mcm","clk":"4221836245","pt":1631438620245,"mc":[{"id":"1.187549048","marketDefinition":{"bspMarket":false,"turnInPlayEnabled":true,"persistenceEnabled":true,"marketBaseRate":5.0,"eventId":"30895085","eventTypeId":"2","numberOfWinners":1,"bettingType":"ODDS","marketType":"MATCH_ODDS","marketTime":"2021-09-12T11:30:00.000Z","suspendTime":"2021-09-12T11:30:00.000Z","bspReconciled":false,"complete":true,"inPlay":false,"crossMatching":false,"runnersVoidable":false,"numberOfActiveRunners":2,"betDelay":0,"status":"OPEN","runners":[{"status":"ACTIVE","sortPriority":1,"id":9626937,"name":"O Parres Azcoitia"},{"status":"ACTIVE","sortPriority":2,"id":9628072,"name":"A Moratelli"}],"regulators":["MR_INT"],"countryCode":"GB","discountAllowed":true,"timezone":"GMT","openDate":"2021-09-12T11:30:00.000Z","version":4027601098,"name":"Match Odds","eventName":"O Parres Azcoitia v A Moratelli"}}]}
{"op":"mcm","clk":"4221893779","pt":1631439141852,"mc":[{"id":"1.187549048","rc":[{"batl":[[0,380,6.46]],"ltp":0.0,"tv":0.0,"id":9626937},{"batl":[[0,430,5.92]],"ltp":0.0,"tv":0.0,"id":9628072}]}]}
{"op":"mcm","clk":"4221895443","pt":1631439157814,"mc":[{"id":"1.187549048","rc":[{"batl":[[0,740,5.52]],"ltp":0.0,"tv":0.0,"id":9626937}]}]}
{"op":"mcm","clk":"4221930463","pt":1631439441996,"mc":[{"id":"1.187549048","rc":[{"batl":[[0,730,5.59]],"ltp":0.0,"tv":0.0,"id":9628072}]}]}
{"op":"mcm","clk":"4221930536","pt":1631439442516,"mc":[{"id":"1.187549048","rc":[{"batl":[[0,420,6.07]],"ltp":0.0,"tv":0.0,"id":9628072}]}]}
{"op":"mcm","clk":"4221938229","pt":1631439502680,"mc":[{"id":"1.187549048","rc":[{"batl":[[0,490,6.16],[1,740,5.52]],"ltp":0.0,"tv":0.0,"id":9626937},{"batl":[[0,390,6.16],[1,420,6.07]],"ltp":0.0,"tv":0.0,"id":9628072}]}]}
{"op":"mcm","clk":"4221965403","pt":1631439716882,"mc":[{"id":"1.187549048","rc":[{"batb":[[0,3,22.54],[1,1.05,879.5],[2,1.01,7]],"batl":[[0,270,15.17],[1,490,6.16]],"ltp":0.0,"tv":0.0,"id":9626937},{"batb":[[0,1.36,125.25],[1,1.05,879.5],[2,1.01,7]],"batl":[[0,320,7.96],[1,390,6.16]],"ltp":0.0,"tv":0.0,"id":9628072}]}]}
{"op":"mcm","clk":"4221966711","pt":1631439726504,"mc":[{"id":"1.187549048","marketDefinition":{"bspMarket":false,"turnInPlayEnabled":true,"persistenceEnabled":true,"marketBaseRate":5.0,"eventId":"30895085","eventTypeId":"2","numberOfWinners":1,"bettingType":"ODDS","marketType":"MATCH_ODDS","marketTime":"2021-09-12T11:30:00.000Z","suspendTime":"2021-09-12T11:30:00.000Z","bspReconciled":false,"complete":true,"inPlay":false,"crossMatching":true,"runnersVoidable":false,"numberOfActiveRunners":2,"betDelay":0,"status":"OPEN","runners":[{"status":"ACTIVE","sortPriority":1,"id":9626937,"name":"O Parres Azcoitia"},{"status":"ACTIVE","sortPriority":2,"id":9628072,"name":"A Moratelli"}],"regulators":["MR_INT"],"countryCode":"GB","discountAllowed":true,"timezone":"GMT","openDate":"2021-09-12T11:30:00.000Z","version":4027603293,"name":"Match Odds","eventName":"O Parres Azcoitia v A Moratelli"}}]}
{"op":"mcm","clk":"4222430636","pt":1631442601059,"mc":[{"id":"1.187549048","rc":[{"batb":[[0,3.05,6.25],[1,3,22.54],[2,1.05,879.5]],"ltp":0.0,"tv":0.0,"id":9626937},{"batb":[[0,1.37,34.62],[1,1.36,125.25],[2,1.05,879.5]],"ltp":0.0,"tv":0.0,"id":9628072}]}]}
{"op":"mcm","clk":"4222447325","pt":1631442688995,"mc":[{"id":"1.187549048","marketDefinition":{"bspMarket":false,"turnInPlayEnabled":true,"persistenceEnabled":true,"marketBaseRate":5.0,"eventId":"30895085","eventTypeId":"2","numberOfWinners":1,"bettingType":"ODDS","marketType":"MATCH_ODDS","marketTime":"2021-09-12T11:30:00.000Z","suspendTime":"2021-09-12T11:30:00.000Z","bspReconciled":false,"complete":true,"inPlay":true,"crossMatching":true,"runnersVoidable":false,"numberOfActiveRunners":2,"betDelay":5,"status":"OPEN","runners":[{"status":"ACTIVE","sortPriority":1,"id":9626937,"name":"O Parres Azcoitia"},{"status":"ACTIVE","sortPriority":2,"id":9628072,"name":"A Moratelli"}],"regulators":["MR_INT"],"countryCode":"GB","discountAllowed":true,"timezone":"GMT","openDate":"2021-09-12T11:30:00.000Z","version":4027768630,"name":"Match Odds","eventName":"O Parres Azcoitia v A Moratelli"},"rc":[{"batb":[[0,1.01,7],[1,3,0],[2,1.05,0]],"ltp":0.0,"tv":0.0,"id":9626937},{"batb":[[0,1.01,7],[1,1.36,0],[2,1.05,0]],"ltp":0.0,"tv":0.0,"id":9628072}]}]}
{"op":"mcm","clk":"4222610422","pt":1631443615320,"mc":[{"id":"1.187549048","marketDefinition":{"bspMarket":false,"turnInPlayEnabled":true,"persistenceEnabled":true,"marketBaseRate":5.0,"eventId":"30895085","eventTypeId":"2","numberOfWinners":1,"bettingType":"ODDS","marketType":"MATCH_ODDS","marketTime":"2021-09-12T10:46:54.000Z","suspendTime":"2021-09-12T10:46:54.000Z","bspReconciled":false,"complete":true,"inPlay":true,"crossMatching":true,"runnersVoidable":false,"numberOfActiveRunners":2,"betDelay":5,"status":"OPEN","runners":[{"status":"ACTIVE","sortPriority":1,"id":9626937,"name":"O Parres Azcoitia"},{"status":"ACTIVE","sortPriority":2,"id":9628072,"name":"A Moratelli"}],"regulators":["MR_INT"],"countryCode":"GB","discountAllowed":true,"timezone":"GMT","openDate":"2021-09-12T11:30:00.000Z","version":4027801601,"name":"Match Odds","eventName":"O Parres Azcoitia v A Moratelli"}}]}
{"op":"mcm","clk":"4222610732","pt":1631443617330,"mc":[{"id":"1.187549048","marketDefinition":{"bspMarket":false,"turnInPlayEnabled":true,"persistenceEnabled":true,"marketBaseRate":5.0,"eventId":"30895085","eventTypeId":"2","numberOfWinners":1,"bettingType":"ODDS","marketType":"MATCH_ODDS","marketTime":"2021-09-12T10:46:54.000Z","suspendTime":"2021-09-12T10:46:54.000Z","bspReconciled":false,"complete":true,"inPlay":true,"crossMatching":true,"runnersVoidable":false,"numberOfActiveRunners":2,"betDelay":5,"status":"OPEN","runners":[{"status":"ACTIVE","sortPriority":1,"id":9626937,"name":"O Parres Azcoitia"},{"status":"ACTIVE","sortPriority":2,"id":9628072,"name":"A Moratelli"}],"regulators":["MR_INT"],"countryCode":"GB","discountAllowed":true,"timezone":"GMT","openDate":"2021-09-12T10:46:54.000Z","version":4027801601,"name":"Match Odds","eventName":"O Parres Azcoitia v A Moratelli"}}]}
{"op":"mcm","clk":"4222645155","pt":1631443839100,"mc":[{"id":"1.187549048","rc":[{"batb":[[0,2.3,391.43],[1,1.01,7]],"batl":[[0,4.9,128.35]],"ltp":0.0,"tv":0.0,"id":9626937}]}]}
{"op":"mcm","clk":"4222650722","pt":1631443877655,"mc":[{"id":"1.187549048","rc":[{"batb":[[0,1.01,7],[1,1.01,0]],"ltp":0.0,"tv":0.0,"id":9626937}]}]}
{"op":"mcm","clk":"4222651514","pt":1631443883654,"mc":[{"id":"1.187549048","rc":[{"batb":[[0,2.52,387.74],[1,1.01,7]],"batl":[[0,6,107.93]],"ltp":0.0,"tv":0.0,"id":9626937}]}]}
{"op":"mcm","clk":"4222659280","pt":1631443942695,"mc":[{"id":"1.187549048","rc":[{"batl":[[0,5.5,116.95]],"ltp":0.0,"tv":0.0,"id":9626937}]}]}
{"op":"mcm","clk":"4222661530","pt":1631443959614,"mc":[{"id":"1.187549048","rc":[{"batl":[[0,6.6,100.58]],"ltp":0.0,"tv":0.0,"id":9626937}]}]}
{"op":"mcm","clk":"4222665334","pt":1631443987109,"mc":[{"id":"1.187549048","rc":[{"batl":[[0,6,107.93]],"ltp":0.0,"tv":0.0,"id":9626937}]}]}
{"op":"mcm","clk":"4222666671","pt":1631443997298,"mc":[{"id":"1.187549048","rc":[{"batl":[[0,5.5,116.95]],"ltp":0.0,"tv":0.0,"id":9626937}]}]}
{"op":"mcm","clk":"4222670748","pt":1631444027622,"mc":[{"id":"1.187549048","rc":[{"batl":[[0,6.6,100.58]],"ltp":0.0,"tv":0.0,"id":9626937}]}]}
{"op":"mcm","clk":"4222676681","pt":1631444067782,"mc":[{"id":"1.187549048","rc":[{"batb":[[0,1.01,7],[1,1.01,0]],"ltp":0.0,"tv":0.0,"id":9626937}]}]}
{"op":"mcm","clk":"4222677493","pt":1631444073287,"mc":[{"id":"1.187549048","rc":[{"batb":[[0,2.72,384.48],[1,1.01,7]],"ltp":0.0,"tv":0.0,"id":9626937}]}]}
{"op":"mcm","clk":"4222703341","pt":1631444250576,"mc":[{"id":"1.187549048","rc":[{"batl":[[0,6,107.93]],"ltp":0.0,"tv":0.0,"id":9626937}]}]}
{"op":"mcm","clk":"4222741571","pt":1631444485984,"mc":[{"id":"1.187549048","rc":[{"batl":[[0,5.5,116.95]],"ltp":0.0,"tv":0.0,"id":9626937}]}]}
{"op":"mcm","clk":"4222743023","pt":1631444493967,"mc":[{"id":"1.187549048","rc":[{"batb":[[0,1.01,7],[1,1.01,0]],"ltp":0.0,"tv":0.0,"id":9626937}]}]}
{"op":"mcm","clk":"4222743419","pt":1631444495882,"mc":[{"id":"1.187549048","rc":[{"batb":[[0,1.01,12]],"ltp":0.0,"tv":0.0,"id":9626937},{"batb":[[0,1.01,12]],"ltp":0.0,"tv":0.0,"id":9628072}]}]}
{"op":"mcm","clk":"4222747994","pt":1631444522718,"mc":[{"id":"1.187549048","rc":[{"batb":[[0,2.3,391.43],[1,1.01,12]],"batl":[[0,4.9,128.35]],"ltp":0.0,"tv":0.0,"id":9626937}]}]}
{"op":"mcm","clk":"4222756744","pt":1631444574148,"mc":[{"id":"1.187549048","rc":[{"batb":[[0,1.01,12],[1,1.01,0]],"ltp":0.0,"tv":0.0,"id":9626937}]}]}
{"op":"mcm","clk":"4222757955","pt":1631444580215,"mc":[{"id":"1.187549048","rc":[{"batb":[[0,2.52,387.74],[1,1.01,12]],"batl":[[0,6,107.93]],"ltp":0.0,"tv":0.0,"id":9626937}]}]}
{"op":"mcm","clk":"4222777491","pt":1631444689170,"mc":[{"id":"1.187549048","rc":[{"batb":[[0,1.01,12],[1,1.01,0]],"ltp":0.0,"tv":0.0,"id":9626937}]}]}
{"op":"mcm","clk":"4222778422","pt":1631444694664,"mc":[{"id":"1.187549048","rc":[{"batb":[[0,2.84,381.6],[1,1.01,12]],"batl":[[0,8.2,86.87]],"ltp":0.0,"tv":0.0,"id":9626937}]}]}
{"op":"mcm","clk":"4222788323","pt":1631444747189,"mc":[{"id":"1.187549048","rc":[{"batl":[[0,7.2,93.7]],"ltp":0.0,"tv":0.0,"id":9626937}]}]}
{"op":"mcm","clk":"4222794069","pt":1631444778029,"mc":[{"id":"1.187549048","rc":[{"batl":[[0,8.2,86.87]],"ltp":0.0,"tv":0.0,"id":9626937}]}]}
{"op":"mcm","clk":"4222800996","pt":1631444814288,"mc":[{"id":"1.187549048","rc":[{"batl":[[0,9.4,79.32]],"ltp":0.0,"tv":0.0,"id":9626937}]}]}
{"op":"mcm","clk":"4222805361","pt":1631444836631,"mc":[{"id":"1.187549048","rc":[{"batl":[[0,8.2,86.87]],"ltp":0.0,"tv":0.0,"id":9626937}]}]}
{"op":"mcm","clk":"4222812683","pt":1631444876438,"mc":[{"id":"1.187549048","rc":[{"batl":[[0,7.2,93.7]],"ltp":0.0,"tv":0.0,"id":9626937}]}]}
{"op":"mcm","clk":"4222817228","pt":1631444900660,"mc":[{"id":"1.187549048","rc":[{"batl":[[0,6.6,100.58]],"ltp":0.0,"tv":0.0,"id":9626937}]}]}
{"op":"mcm","clk":"4222830713","pt":1631444973986,"mc":[{"id":"1.187549048","rc":[{"batb":[[0,1.01,12],[1,1.01,0]],"ltp":0.0,"tv":0.0,"id":9626937}]}]}
{"op":"mcm","clk":"4222843041","pt":1631445043219,"mc":[{"id":"1.187549048","rc":[{"batl":[[0,8.2,86.87]],"ltp":0.0,"tv":0.0,"id":9626937}]}]}
{"op":"mcm","clk":"4222849259","pt":1631445077689,"mc":[{"id":"1.187549048","rc":[{"batl":[[0,7.2,93.7]],"ltp":0.0,"tv":0.0,"id":9626937}]}]}
{"op":"mcm","clk":"4222856701","pt":1631445117149,"mc":[{"id":"1.187549048","rc":[{"batl":[[0,6.6,100.58]],"ltp":0.0,"tv":0.0,"id":9626937}]}]}
{"op":"mcm","clk":"4222861683","pt":1631445143457,"mc":[{"id":"1.187549048","rc":[{"batl":[[0,6,107.93]],"ltp":0.0,"tv":0.0,"id":9626937}]}]}
{"op":"mcm","clk":"4222864812","pt":1631445160584,"mc":[{"id":"1.187549048","rc":[{"batb":[[0,2.38,388.6],[1,1.01,12]],"batl":[[0,5.3,120.74]],"ltp":0.0,"tv":0.0,"id":9626937}]}]}
{"op":"mcm","clk":"4222870586","pt":1631445191177,"mc":[{"id":"1.187549048","rc":[{"batl":[[0,4.2,150.47]],"ltp":0.0,"tv":0.0,"id":9626937}]}]}
{"op":"mcm","clk":"4222877450","pt":1631445229801,"mc":[{"id":"1.187549048","rc":[{"batl":[[0,5.3,120.74]],"ltp":0.0,"tv":0.0,"id":9626937}]}]}
{"op":"mcm","clk":"4222879327","pt":1631445239720,"mc":[{"id":"1.187549048","rc":[{"batb":[[0,1.01,12],[1,1.01,0]],"ltp":0.0,"tv":0.0,"id":9626937}]}]}
{"op":"mcm","clk":"4222914733","pt":1631445426377,"mc":[{"id":"1.187549048","rc":[{"batb":[[0,2.84,381.6],[1,1.01,12]],"batl":[[0,8.2,86.87]],"ltp":0.0,"tv":0.0,"id":9626937}]}]}
{"op":"mcm","clk":"4222920436","pt":1631445455864,"mc":[{"id":"1.187549048","rc":[{"batb":[[0,1.01,12],[1,1.01,0]],"ltp":0.0,"tv":0.0,"id":9626937}]}]}
{"op":"mcm","clk":"4222921511","pt":1631445461584,"mc":[{"id":"1.187549048","rc":[{"batb":[[0,3.1,379.94],[1,1.01,12]],"batl":[[0,10.5,73.52]],"ltp":0.0,"tv":0.0,"id":9626937}]}]}
{"op":"mcm","clk":"4222937067","pt":1631445488394,"mc":[{"id":"1.187549048","rc":[{"batl":[[0,12,68.9]],"ltp":0.0,"tv":0.0,"id":9626937}]}]}
{"op":"mcm","clk":"4222944921","pt":1631445530831,"mc":[{"id":"1.187549048","rc":[{"batl":[[0,10.5,73.52]],"ltp":0.0,"tv":0.0,"id":9626937}]}]}
{"op":"mcm","clk":"4222952819","pt":1631445572185,"mc":[{"id":"1.187549048","rc":[{"batl":[[0,12,68.9]],"ltp":0.0,"tv":0.0,"id":9626937}]}]}
{"op":"mcm","clk":"4222968130","pt":1631445651066,"mc":[{"id":"1.187549048","rc":[{"batl":[[0,10.5,73.52]],"ltp":0.0,"tv":0.0,"id":9626937}]}]}
{"op":"mcm","clk":"4222974736","pt":1631445685327,"mc":[{"id":"1.187549048","rc":[{"batl":[[0,9.4,79.32]],"ltp":0.0,"tv":0.0,"id":9626937}]}]}
{"op":"mcm","clk":"4222979549","pt":1631445711668,"mc":[{"id":"1.187549048","rc":[{"batl":[[0,8.2,86.87]],"ltp":0.0,"tv":0.0,"id":9626937}]}]}
{"op":"mcm","clk":"4222991251","pt":1631445774387,"mc":[{"id":"1.187549048","rc":[{"batl":[[0,9.4,79.32]],"ltp":0.0,"tv":0.0,"id":9626937}]}]}
{"op":"mcm","clk":"4222998155","pt":1631445811958,"mc":[{"id":"1.187549048","rc":[{"batl":[[0,8.2,86.87]],"ltp":0.0,"tv":0.0,"id":9626937}]}]}
{"op":"mcm","clk":"4223000373","pt":1631445824182,"mc":[{"id":"1.187549048","rc":[{"batl":[[0,11.5,8.68]],"ltp":0.0,"tv":0.0,"id":9628072}]}]}
{"op":"mcm","clk":"4223021111","pt":1631445930200,"mc":[{"id":"1.187549048","rc":[{"batl":[[0,10.5,73.52]],"ltp":0.0,"tv":0.0,"id":9626937}]}]}
{"op":"mcm","clk":"4223026124","pt":1631445957520,"mc":[{"id":"1.187549048","rc":[{"batl":[[0,8.2,86.87]],"ltp":0.0,"tv":0.0,"id":9626937}]}]}
{"op":"mcm","clk":"4223033009","pt":1631445993953,"mc":[{"id":"1.187549048","rc":[{"batl":[[0,10.5,73.52]],"ltp":0.0,"tv":0.0,"id":9626937}]}]}
{"op":"mcm","clk":"4223039801","pt":1631446030227,"mc":[{"id":"1.187549048","rc":[{"batl":[[0,8.2,86.87]],"ltp":0.0,"tv":0.0,"id":9626937}]}]}
{"op":"mcm","clk":"4223049348","pt":1631446081820,"mc":[{"id":"1.187549048","rc":[{"batl":[[0,10.5,73.52]],"ltp":0.0,"tv":0.0,"id":9626937}]}]}
{"op":"mcm","clk":"4223056629","pt":1631446121307,"mc":[{"id":"1.187549048","rc":[{"batl":[[0,8.2,86.87]],"ltp":0.0,"tv":0.0,"id":9626937}]}]}
{"op":"mcm","clk":"4223075537","pt":1631446209887,"mc":[{"id":"1.187549048","rc":[{"batl":[[0,10.5,73.52]],"ltp":0.0,"tv":0.0,"id":9626937}]}]}
{"op":"mcm","clk":"4223083432","pt":1631446248538,"mc":[{"id":"1.187549048","rc":[{"batl":[[0,9.4,79.32]],"ltp":0.0,"tv":0.0,"id":9626937}]}]}
{"op":"mcm","clk":"4223089574","pt":1631446279871,"mc":[{"id":"1.187549048","rc":[{"batb":[[0,1.01,12],[1,1.01,0]],"ltp":0.0,"tv":0.0,"id":9626937}]}]}
{"op":"mcm","clk":"4223090842","pt":1631446285974,"mc":[{"id":"1.187549048","rc":[{"batb":[[0,3.4,382.3],[1,1.01,12]],"batl":[[0,15.5,60.62]],"ltp":0.0,"tv":0.0,"id":9626937}]}]}
{"op":"mcm","clk":"4223100680","pt":1631446333171,"mc":[{"id":"1.187549048","rc":[{"trd":[[3.4,54.29]],"batb":[[0,3.4,328.01]],"ltp":3.4,"tv":54.29,"id":9626937},{"trd":[[1.42,130]],"ltp":1.42,"tv":130.0,"id":9628072}],"tv":184.29}]}
{"op":"mcm","clk":"4223120615","pt":1631446435199,"mc":[{"id":"1.187549048","rc":[{"batl":[[0,12,84.75]],"ltp":3.4,"tv":54.29,"id":9626937}]}]}
{"op":"mcm","clk":"4223125290","pt":1631446459266,"mc":[{"id":"1.187549048","rc":[{"batl":[[0,10.5,91.34]],"ltp":3.4,"tv":54.29,"id":9626937}]}]}
{"op":"mcm","clk":"4223130312","pt":1631446485246,"mc":[{"id":"1.187549048","rc":[{"trd":[[3.4,60.56]],"batb":[[0,3.4,321.74]],"ltp":3.4,"tv":60.56,"id":9626937},{"trd":[[1.42,145]],"ltp":1.42,"tv":145.0,"id":9628072}],"tv":205.56}]}
{"op":"mcm","clk":"4223133103","pt":1631446499807,"mc":[{"id":"1.187549048","rc":[{"batl":[[0,9.4,101.91]],"ltp":3.4,"tv":60.56,"id":9626937}]}]}
{"op":"mcm","clk":"4223141959","pt":1631446544185,"mc":[{"id":"1.187549048","rc":[{"batl":[[0,8.2,112.84]],"ltp":3.4,"tv":60.56,"id":9626937}]}]}
{"op":"mcm","clk":"4223158744","pt":1631446625976,"mc":[{"id":"1.187549048","rc":[{"batl":[[0,9.4,101.91]],"ltp":3.4,"tv":60.56,"id":9626937}]}]}
{"op":"mcm","clk":"4223163672","pt":1631446651148,"mc":[{"id":"1.187549048","rc":[{"batl":[[0,10.5,93.4]],"ltp":3.4,"tv":60.56,"id":9626937}]}]}
{"op":"mcm","clk":"4223167186","pt":1631446669365,"mc":[{"id":"1.187549048","rc":[{"batl":[[0,12,86.57]],"ltp":3.4,"tv":60.56,"id":9626937}]}]}
{"op":"mcm","clk":"4223182494","pt":1631446753063,"mc":[{"id":"1.187549048","rc":[{"batl":[[0,10.5,93.4]],"ltp":3.4,"tv":60.56,"id":9626937}]}]}
{"op":"mcm","clk":"4223186038","pt":1631446772093,"mc":[{"id":"1.187549048","rc":[{"batl":[[0,12,86.57]],"ltp":3.4,"tv":60.56,"id":9626937}]}]}
{"op":"mcm","clk":"4223192433","pt":1631446806694,"mc":[{"id":"1.187549048","rc":[{"batl":[[0,10.5,93.4]],"ltp":3.4,"tv":60.56,"id":9626937}]}]}
{"op":"mcm","clk":"4223199225","pt":1631446839968,"mc":[{"id":"1.187549048","rc":[{"batl":[[0,13.5,80.98]],"ltp":3.4,"tv":60.56,"id":9626937}]}]}
{"op":"mcm","clk":"4223206477","pt":1631446875304,"mc":[{"id":"1.187549048","rc":[{"batl":[[0,10.5,93.4]],"ltp":3.4,"tv":60.56,"id":9626937}]}]}
{"op":"mcm","clk":"4223212146","pt":1631446902682,"mc":[{"id":"1.187549048","rc":[{"batl":[[0,13.5,80.98]],"ltp":3.4,"tv":60.56,"id":9626937}]}]}
{"op":"mcm","clk":"4223218814","pt":1631446936055,"mc":[{"id":"1.187549048","rc":[{"batl":[[0,10.5,93.4]],"ltp":3.4,"tv":60.56,"id":9626937}]}]}
{"op":"mcm","clk":"4223224144","pt":1631446963458,"mc":[{"id":"1.187549048","rc":[{"batl":[[0,13.5,80.98]],"ltp":3.4,"tv":60.56,"id":9626937}]}]}
{"op":"mcm","clk":"4223231714","pt":1631446999840,"mc":[{"id":"1.187549048","rc":[{"batl":[[0,10.5,93.4]],"ltp":3.4,"tv":60.56,"id":9626937}]}]}
{"op":"mcm","clk":"4223233509","pt":1631447008926,"mc":[{"id":"1.187549048","rc":[{"batb":[[0,1.01,12],[1,1.01,0]],"ltp":3.4,"tv":60.56,"id":9626937}]}]}
{"op":"mcm","clk":"4223280381","pt":1631447251842,"mc":[{"id":"1.187549048","rc":[{"batb":[[0,3.1,313.14],[1,1.01,12]],"batl":[[0,10.5,93.4]],"ltp":3.4,"tv":60.56,"id":9626937}]}]}
{"op":"mcm","clk":"4223284169","pt":1631447272050,"mc":[{"id":"1.187549048","rc":[{"batl":[[0,9.4,101.91]],"ltp":3.4,"tv":60.56,"id":9626937}]}]}
{"op":"mcm","clk":"4223288491","pt":1631447294010,"mc":[{"id":"1.187549048","rc":[{"batb":[[0,1.01,12],[1,1.01,0]],"ltp":3.4,"tv":60.56,"id":9626937}]}]}
{"op":"mcm","clk":"4223289950","pt":1631447301311,"mc":[{"id":"1.187549048","rc":[{"batb":[[0,2.84,308.42],[1,1.01,12]],"batl":[[0,8.2,112.84]],"ltp":3.4,"tv":60.56,"id":9626937}]}]}
{"op":"mcm","clk":"4223292180","pt":1631447312662,"mc":[{"id":"1.187549048","rc":[{"batl":[[0,9.4,101.91]],"ltp":3.4,"tv":60.56,"id":9626937}]}]}
{"op":"mcm","clk":"4223297788","pt":1631447338828,"mc":[{"id":"1.187549048","rc":[{"batl":[[0,1.7,12.53],[1,11.5,8.68]],"ltp":1.42,"tv":145.0,"id":9628072}]}]}
{"op":"mcm","clk":"4223299666","pt":1631447349346,"mc":[{"id":"1.187549048","rc":[{"batl":[[0,8.2,112.84]],"ltp":3.4,"tv":60.56,"id":9626937}]}]}
{"op":"mcm","clk":"4223302158","pt":1631447362502,"mc":[{"id":"1.187549048","rc":[{"batl":[[0,11.5,8.68],[1,11.5,0]],"ltp":1.42,"tv":145.0,"id":9628072}]}]}
{"op":"mcm","clk":"4223306321","pt":1631447385228,"mc":[{"id":"1.187549048","rc":[{"batb":[[0,1.01,12],[1,1.01,0]],"ltp":3.4,"tv":60.56,"id":9626937}]}]}
{"op":"mcm","clk":"4223307306","pt":1631447390659,"mc":[{"id":"1.187549048","rc":[{"batb":[[0,3.1,313.14],[1,1.01,12]],"batl":[[0,10.5,93.4]],"ltp":3.4,"tv":60.56,"id":9626937}]}]}
{"op":"mcm","clk":"4223310126","pt":1631447406093,"mc":[{"id":"1.187549048","rc":[{"batl":[[0,1.49,14.3],[1,11.5,8.68]],"ltp":1.42,"tv":145.0,"id":9628072}]}]}
{"op":"mcm","clk":"4223312795","pt":1631447420338,"mc":[{"id":"1.187549048","rc":[{"batl":[[0,9.4,101.91]],"ltp":3.4,"tv":60.56,"id":9626937}]}]}
{"op":"mcm","clk":"4223317392","pt":1631447445780,"mc":[{"id":"1.187549048","rc":[{"batl":[[0,8.2,112.84]],"ltp":3.4,"tv":60.56,"id":9626937}]}]}
{"op":"mcm","clk":"4223329545","pt":1631447515820,"mc":[{"id":"1.187549048","rc":[{"batl":[[0,9.4,101.91]],"ltp":3.4,"tv":60.56,"id":9626937}]}]}
{"op":"mcm","clk":"4223335838","pt":1631447552180,"mc":[{"id":"1.187549048","rc":[{"batl":[[0,12,86.57]],"ltp":3.4,"tv":60.56,"id":9626937}]}]}
{"op":"mcm","clk":"4223345191","pt":1631447609411,"mc":[{"id":"1.187549048","rc":[{"batl":[[0,9.4,101.91]],"ltp":3.4,"tv":60.56,"id":9626937}]}]}
{"op":"mcm","clk":"4223349321","pt":1631447635568,"mc":[{"id":"1.187549048","rc":[{"batl":[[0,10.5,93.4]],"ltp":3.4,"tv":60.56,"id":9626937}]}]}
{"op":"mcm","clk":"4223352193","pt":1631447653068,"mc":[{"id":"1.187549048","rc":[{"batl":[[0,12,86.57]],"ltp":3.4,"tv":60.56,"id":9626937}]}]}
{"op":"mcm","clk":"4223356783","pt":1631447681504,"mc":[{"id":"1.187549048","rc":[{"batl":[[0,9.4,101.91]],"ltp":3.4,"tv":60.56,"id":9626937}]}]}
{"op":"mcm","clk":"4223362396","pt":1631447717701,"mc":[{"id":"1.187549048","rc":[{"batl":[[0,12,86.57]],"ltp":3.4,"tv":60.56,"id":9626937}]}]}
{"op":"mcm","clk":"4223368038","pt":1631447754038,"mc":[{"id":"1.187549048","rc":[{"batb":[[0,1.01,12],[1,1.01,0]],"ltp":3.4,"tv":60.56,"id":9626937}]}]}
{"op":"mcm","clk":"4223368980","pt":1631447759625,"mc":[{"id":"1.187549048","rc":[{"batb":[[0,3.5,323.38],[1,1.01,12]],"batl":[[0,18,68.96]],"ltp":3.4,"tv":60.56,"id":9626937}]}]}
{"op":"mcm","clk":"4223374951","pt":1631447796039,"mc":[{"id":"1.187549048","rc":[{"batl":[[0,34,53.23]],"ltp":3.4,"tv":60.56,"id":9626937}]}]}
{"op":"mcm","clk":"4223391488","pt":1631447902582,"mc":[{"id":"1.187549048","rc":[{"batl":[[0,26,58.4]],"ltp":3.4,"tv":60.56,"id":9626937}]}]}
{"op":"mcm","clk":"4223393566","pt":1631447916535,"mc":[{"id":"1.187549048","rc":[{"batb":[[0,1.01,12],[1,1.01,0]],"ltp":3.4,"tv":60.56,"id":9626937}]}]}
{"op":"mcm","clk":"4223394376","pt":1631447921989,"mc":[{"id":"1.187549048","rc":[{"batb":[[0,4,328.72],[1,1.01,12]],"batl":[[0,46,48.33]],"ltp":3.4,"tv":60.56,"id":9626937}]}]}
{"op":"mcm","clk":"4223399887","pt":1631447955596,"mc":[{"id":"1.187549048","rc":[{"batl":[[0,60,45.19]],"ltp":3.4,"tv":60.56,"id":9626937}]}]}
{"op":"mcm","clk":"4223407212","pt":1631448000041,"mc":[{"id":"1.187549048","rc":[{"batl":[[0,85,42.26]],"ltp":3.4,"tv":60.56,"id":9626937}]}]}
{"op":"mcm","clk":"4223412065","pt":1631448022807,"mc":[{"id":"1.187549048","rc":[{"batl":[[0,60,45.19]],"ltp":3.4,"tv":60.56,"id":9626937}]}]}
{"op":"mcm","clk":"4223417107","pt":1631448048249,"mc":[{"id":"1.187549048","rc":[{"batl":[[0,85,42.26]],"ltp":3.4,"tv":60.56,"id":9626937},{"batb":[[0,1.01,16.13]],"ltp":1.42,"tv":145.0,"id":9628072}]}]}
{"op":"mcm","clk":"4223424420","pt":1631448085534,"mc":[{"id":"1.187549048","rc":[{"batl":[[0,340,37.09]],"ltp":3.4,"tv":60.56,"id":9626937}]}]}
{"op":"mcm","clk":"4223426924","pt":1631448097878,"mc":[{"id":"1.187549048","rc":[{"batb":[[0,1.01,12]],"ltp":1.42,"tv":145.0,"id":9628072}]}]}
{"op":"mcm","clk":"4223436485","pt":1631448148244,"mc":[{"id":"1.187549048","rc":[{"batb":[[0,1.01,12],[1,1.01,0]],"ltp":3.4,"tv":60.56,"id":9626937}]}]}
{"op":"mcm","clk":"4223446029","pt":1631448197934,"mc":[{"id":"1.187549048","rc":[{"batb":[[0,4.6,336.37],[1,1.01,12]],"ltp":3.4,"tv":60.56,"id":9626937}]}]}
{"op":"mcm","clk":"4223469719","pt":1631448315227,"mc":[{"id":"1.187549048","rc":[{"batb":[[0,1.01,12],[1,1.01,0]],"ltp":3.4,"tv":60.56,"id":9626937}]}]}
{"op":"mcm","clk":"4223470532","pt":1631448319230,"mc":[{"id":"1.187549048","rc":[{"trd":[[1.01,24]],"batl":[[0,1.01,5.08],[1,1.49,14.3],[2,11.5,8.68]],"ltp":1.01,"tv":168.99,"id":9628072}],"tv":229.55}]}
{"op":"mcm","clk":"4223473962","pt":1631448336968,"mc":[{"id":"1.187549048","rc":[{"batb":[[0,4.8,330.69],[1,1.01,12]],"ltp":3.4,"tv":60.56,"id":9626937}]}]}
{"op":"mcm","clk":"4223476642","pt":1631448350804,"mc":[{"id":"1.187549048","rc":[{"batb":[[0,1.01,12],[1,1.01,0]],"ltp":3.4,"tv":60.56,"id":9626937}]}]}
{"op":"mcm","clk":"4223510204","pt":1631448534624,"mc":[{"id":"1.187549048","marketDefinition":{"bspMarket":false,"turnInPlayEnabled":true,"persistenceEnabled":true,"marketBaseRate":5.0,"eventId":"30895085","eventTypeId":"2","numberOfWinners":1,"bettingType":"ODDS","marketType":"MATCH_ODDS","marketTime":"2021-09-12T10:46:54.000Z","suspendTime":"2021-09-12T10:46:54.000Z","bspReconciled":false,"complete":true,"inPlay":true,"crossMatching":true,"runnersVoidable":false,"numberOfActiveRunners":2,"betDelay":5,"status":"SUSPENDED","runners":[{"status":"ACTIVE","sortPriority":1,"id":9626937,"name":"O Parres Azcoitia"},{"status":"ACTIVE","sortPriority":2,"id":9628072,"name":"A Moratelli"}],"regulators":["MR_INT"],"countryCode":"GB","discountAllowed":true,"timezone":"GMT","openDate":"2021-09-12T10:46:54.000Z","version":4028073444,"name":"Match Odds","eventName":"O Parres Azcoitia v A Moratelli"}}]}
{"op":"mcm","clk":"4223510856","pt":1631448538416,"mc":[{"id":"1.187549048","tv":0.0}]}
{"op":"mcm","clk":"4223511077","pt":1631448539634,"mc":[{"id":"1.187549048","marketDefinition":{"bspMarket":false,"turnInPlayEnabled":true,"persistenceEnabled":true,"marketBaseRate":5.0,"eventId":"30895085","eventTypeId":"2","numberOfWinners":1,"bettingType":"ODDS","marketType":"MATCH_ODDS","marketTime":"2021-09-12T10:46:54.000Z","suspendTime":"2021-09-12T10:46:54.000Z","bspReconciled":false,"complete":true,"inPlay":true,"crossMatching":false,"runnersVoidable":false,"numberOfActiveRunners":0,"betDelay":5,"status":"CLOSED","settledTime":"2021-09-12T12:08:57.000Z","runners":[{"status":"LOSER","sortPriority":1,"id":9626937,"name":"O Parres Azcoitia"},{"status":"WINNER","sortPriority":2,"id":9628072,"name":"A Moratelli"}],"regulators":["MR_INT"],"countryCode":"GB","discountAllowed":true,"timezone":"GMT","openDate":"2021-09-12T10:46:54.000Z","version":4028073620,"name":"Match Odds","eventName":"O Parres Azcoitia v A Moratelli"}}]}
