{"op":"mcm","clk":"4229490605","pt":1631518387207,"mc":[{"id":"1.187594229","marketDefinition":{"bspMarket":false,"turnInPlayEnabled":true,"persistenceEnabled":true,"marketBaseRate":5.0,"eventId":"30897689","eventTypeId":"2","numberOfWinners":1,"bettingType":"ODDS","marketType":"MATCH_ODDS","marketTime":"2021-09-13T06:00:00.000Z","suspendTime":"2021-09-13T06:00:00.000Z","bspReconciled":false,"complete":true,"inPlay":false,"crossMatching":false,"runnersVoidable":false,"numberOfActiveRunners":2,"betDelay":0,"status":"OPEN","runners":[{"status":"ACTIVE","sortPriority":1,"id":11809898,"name":"O Gadecki"},{"status":"ACTIVE","sortPriority":2,"id":11772893,"name":"J Garland"}],"regulators":["MR_INT"],"countryCode":"GB","discountAllowed":false,"timezone":"GMT","openDate":"2021-09-13T09:00:00.000Z","version":4030164795,"name":"Match Odds","eventName":"O Gadecki v J Garland"},"rc":[{"batb":[[0,1.01,25]],"ltp":0.0,"tv":0.0,"id":11772893},{"batb":[[0,1.01,25]],"ltp":0.0,"tv":0.0,"id":11809898}]}]}
{"op":"mcm","clk":"4229490650","pt":1631518388646,"mc":[{"id":"1.187594229","marketDefinition":{"bspMarket":false,"turnInPlayEnabled":true,"persistenceEnabled":true,"marketBaseRate":5.0,"eventId":"30897689","eventTypeId":"2","numberOfWinners":1,"bettingType":"ODDS","marketType":"MATCH_ODDS","marketTime":"2021-09-13T06:00:00.000Z","suspendTime":"2021-09-13T06:00:00.000Z","bspReconciled":false,"complete":true,"inPlay":false,"crossMatching":false,"runnersVoidable":false,"numberOfActiveRunners":2,"betDelay":0,"status":"OPEN","runners":[{"status":"ACTIVE","sortPriority":1,"id":11809898,"name":"O Gadecki"},{"status":"ACTIVE","sortPriority":2,"id":11772893,"name":"J Garland"}],"regulators":["MR_INT"],"countryCode":"GB","discountAllowed":true,"timezone":"GMT","openDate":"2021-09-13T09:00:00.000Z","version":4030164795,"name":"Match Odds","eventName":"O Gadecki v J Garland"}}]}
{"op":"mcm","clk":"4229516845","pt":1631519109885,"mc":[{"id":"1.187594229","rc":[{"batb":[[0,1.05,880.88],[1,1.01,25]],"ltp":0.0,"tv":0.0,"id":11772893},{"batb":[[0,1.05,880.88],[1,1.01,25]],"ltp":0.0,"tv":0.0,"id":11809898}]}]}
{"op":"mcm","clk":"4229517229","pt":1631519121490,"mc":[{"id":"1.187594229","rc":[{"batb":[[1,1.01,7]],"ltp":0.0,"tv":0.0,"id":11772893},{"batb":[[1,1.01,7]],"ltp":0.0,"tv":0.0,"id":11809898}]}]}
{"op":"mcm","clk":"4229675057","pt":1631522361583,"mc":[{"id":"1.187594229","rc":[{"batl":[[0,2.16,2.66]],"ltp":0.0,"tv":0.0,"id":11809898}]}]}
{"op":"mcm","clk":"4229675291","pt":1631522366726,"mc":[{"id":"1.187594229","rc":[{"batb":[[0,1.16,15.97],[1,1.05,880.88],[2,1.01,7]],"ltp":0.0,"tv":0.0,"id":11809898}]}]}
{"op":"mcm","clk":"4229685225","pt":1631522603839,"mc":[{"id":"1.187594229","rc":[{"batb":[[1,1.01,7],[2,1.01,0]],"ltp":0.0,"tv":0.0,"id":11809898}]}]}
{"op":"mcm","clk":"4229685832","pt":1631522615873,"mc":[{"id":"1.187594229","rc":[{"batb":[[0,1.18,246.65],[1,1.16,15.97],[2,1.01,7]],"ltp":0.0,"tv":0.0,"id":11809898}]}]}
{"op":"mcm","clk":"4229693160","pt":1631522762133,"mc":[{"id":"1.187594229","marketDefinition":{"bspMarket":false,"turnInPlayEnabled":true,"persistenceEnabled":true,"marketBaseRate":5.0,"eventId":"30897689","eventTypeId":"2","numberOfWinners":1,"bettingType":"ODDS","marketType":"MATCH_ODDS","marketTime":"2021-09-13T09:30:00.000Z","suspendTime":"2021-09-13T09:30:00.000Z","bspReconciled":false,"complete":true,"inPlay":false,"crossMatching":false,"runnersVoidable":false,"numberOfActiveRunners":2,"betDelay":0,"status":"OPEN","runners":[{"status":"ACTIVE","sortPriority":1,"id":11809898,"name":"O Gadecki"},{"status":"ACTIVE","sortPriority":2,"id":11772893,"name":"J Garland"}],"regulators":["MR_INT"],"countryCode":"GB","discountAllowed":true,"timezone":"GMT","openDate":"2021-09-13T09:00:00.000Z","version":4030340784,"name":"Match Odds","eventName":"O Gadecki v J Garland"}}]}
{"op":"mcm","clk":"4229693275","pt":1631522764139,"mc":[{"id":"1.187594229","marketDefinition":{"bspMarket":false,"turnInPlayEnabled":true,"persistenceEnabled":true,"marketBaseRate":5.0,"eventId":"30897689","eventTypeId":"2","numberOfWinners":1,"bettingType":"ODDS","marketType":"MATCH_ODDS","marketTime":"2021-09-13T09:30:00.000Z","suspendTime":"2021-09-13T09:30:00.000Z","bspReconciled":false,"complete":true,"inPlay":false,"crossMatching":false,"runnersVoidable":false,"numberOfActiveRunners":2,"betDelay":0,"status":"OPEN","runners":[{"status":"ACTIVE","sortPriority":1,"id":11809898,"name":"O Gadecki"},{"status":"ACTIVE","sortPriority":2,"id":11772893,"name":"J Garland"}],"regulators":["MR_INT"],"countryCode":"GB","discountAllowed":true,"timezone":"GMT","openDate":"2021-09-13T09:30:00.000Z","version":4030340784,"name":"Match Odds","eventName":"O Gadecki v J Garland"}}]}
{"op":"mcm","clk":"4229735517","pt":1631523638955,"mc":[{"id":"1.187594229","rc":[{"batb":[[0,1.05,880.36]],"ltp":0.0,"tv":0.0,"id":11772893},{"batb":[[0,1.18,246.5],[1,1.16,15.98]],"batl":[[0,2,100],[1,2.16,2.66]],"ltp":0.0,"tv":0.0,"id":11809898}]}]}
{"op":"mcm","clk":"4229735705","pt":1631523642545,"mc":[{"id":"1.187594229","marketDefinition":{"bspMarket":false,"turnInPlayEnabled":true,"persistenceEnabled":true,"marketBaseRate":5.0,"eventId":"30897689","eventTypeId":"2","numberOfWinners":1,"bettingType":"ODDS","marketType":"MATCH_ODDS","marketTime":"2021-09-13T09:30:00.000Z","suspendTime":"2021-09-13T09:30:00.000Z","bspReconciled":false,"complete":true,"inPlay":false,"crossMatching":true,"runnersVoidable":false,"numberOfActiveRunners":2,"betDelay":0,"status":"OPEN","runners":[{"status":"ACTIVE","sortPriority":1,"id":11809898,"name":"O Gadecki"},{"status":"ACTIVE","sortPriority":2,"id":11772893,"name":"J Garland"}],"regulators":["MR_INT"],"countryCode":"GB","discountAllowed":true,"timezone":"GMT","openDate":"2021-09-13T09:30:00.000Z","version":4030340784,"name":"Match Odds","eventName":"O Gadecki v J Garland"}}]}
{"op":"mcm","clk":"4229743019","pt":1631523785914,"mc":[{"id":"1.187594229","rc":[{"batb":[[0,2.5,27.84],[1,1.05,880.36],[2,1.01,7]],"ltp":0.0,"tv":0.0,"id":11772893},{"batb":[[0,1.53,78.8],[1,1.18,246.5],[2,1.16,15.98]],"ltp":0.0,"tv":0.0,"id":11809898}]}]}
{"op":"mcm","clk":"4229743086","pt":1631523787098,"mc":[{"id":"1.187594229","rc":[{"batb":[[0,2.52,8.42],[1,2.5,27.84],[2,1.05,880.36]],"ltp":0.0,"tv":0.0,"id":11772893},{"batb":[[0,1.54,23.71],[1,1.53,78.8],[2,1.18,246.5]],"ltp":0.0,"tv":0.0,"id":11809898}]}]}
{"op":"mcm","clk":"4229755790","pt":1631524011715,"mc":[{"id":"1.187594229","rc":[{"batb":[[2,1.01,7]],"ltp":0.0,"tv":0.0,"id":11772893}]}]}
{"op":"mcm","clk":"4229756110","pt":1631524017650,"mc":[{"id":"1.187594229","rc":[{"batl":[[2,2.4,44.02]],"ltp":0.0,"tv":0.0,"id":11809898}]}]}
{"op":"mcm","clk":"4229799518","pt":1631524739347,"mc":[{"id":"1.187594229","rc":[{"batb":[[2,2.44,2.66]],"ltp":0.0,"tv":0.0,"id":11772893},{"batb":[[2,1.5,2.66]],"ltp":0.0,"tv":0.0,"id":11809898}]}]}
{"op":"mcm","clk":"4229801744","pt":1631524779510,"mc":[{"id":"1.187594229","rc":[{"batl":[[0,1.65,100]],"ltp":0.0,"tv":0.0,"id":11809898}]}]}
{"op":"mcm","clk":"4229839122","pt":1631525461435,"mc":[{"id":"1.187594229","marketDefinition":{"bspMarket":false,"turnInPlayEnabled":true,"persistenceEnabled":true,"marketBaseRate":5.0,"eventId":"30897689","eventTypeId":"2","numberOfWinners":1,"bettingType":"ODDS","marketType":"MATCH_ODDS","marketTime":"2021-09-13T09:30:00.000Z","suspendTime":"2021-09-13T09:30:00.000Z","bspReconciled":false,"complete":true,"inPlay":true,"crossMatching":true,"runnersVoidable":false,"numberOfActiveRunners":2,"betDelay":5,"status":"OPEN","runners":[{"status":"ACTIVE","sortPriority":1,"id":11809898,"name":"O Gadecki"},{"status":"ACTIVE","sortPriority":2,"id":11772893,"name":"J Garland"}],"regulators":["MR_INT"],"countryCode":"GB","discountAllowed":true,"timezone":"GMT","openDate":"2021-09-13T09:30:00.000Z","version":4030506497,"name":"Match Odds","eventName":"O Gadecki v J Garland"},"rc":[{"batb":[[0,1.01,7],[1,2.5,0],[2,2.44,0]],"ltp":0.0,"tv":0.0,"id":11772893},{"batb":[[0,1.01,7],[1,1.53,0],[2,1.5,0]],"batl":[[1,2.16,0],[2,2.4,0]],"ltp":0.0,"tv":0.0,"id":11809898}]}]}
{"op":"mcm","clk":"4229881534","pt":1631526086028,"mc":[{"id":"1.187594229","marketDefinition":{"bspMarket":false,"turnInPlayEnabled":true,"persistenceEnabled":true,"marketBaseRate":5.0,"eventId":"30897689","eventTypeId":"2","numberOfWinners":1,"bettingType":"ODDS","marketType":"MATCH_ODDS","marketTime":"2021-09-13T09:40:00.000Z","suspendTime":"2021-09-13T09:40:00.000Z","bspReconciled":false,"complete":true,"inPlay":true,"crossMatching":true,"runnersVoidable":false,"numberOfActiveRunners":2,"betDelay":5,"status":"OPEN","runners":[{"status":"ACTIVE","sortPriority":1,"id":11809898,"name":"O Gadecki"},{"status":"ACTIVE","sortPriority":2,"id":11772893,"name":"J Garland"}],"regulators":["MR_INT"],"countryCode":"GB","discountAllowed":true,"timezone":"GMT","openDate":"2021-09-13T09:30:00.000Z","version":4030511776,"name":"Match Odds","eventName":"O Gadecki v J Garland"}}]}
{"op":"mcm","clk":"4229881989","pt":1631526089043,"mc":[{"id":"1.187594229","marketDefinition":{"bspMarket":false,"turnInPlayEnabled":true,"persistenceEnabled":true,"marketBaseRate":5.0,"eventId":"30897689","eventTypeId":"2","numberOfWinners":1,"bettingType":"ODDS","marketType":"MATCH_ODDS","marketTime":"2021-09-13T09:40:00.000Z","suspendTime":"2021-09-13T09:40:00.000Z","bspReconciled":false,"complete":true,"inPlay":true,"crossMatching":true,"runnersVoidable":false,"numberOfActiveRunners":2,"betDelay":5,"status":"OPEN","runners":[{"status":"ACTIVE","sortPriority":1,"id":11809898,"name":"O Gadecki"},{"status":"ACTIVE","sortPriority":2,"id":11772893,"name":"J Garland"}],"regulators":["MR_INT"],"countryCode":"GB","discountAllowed":true,"timezone":"GMT","openDate":"2021-09-13T09:40:00.000Z","version":4030511776,"name":"Match Odds","eventName":"O Gadecki v J Garland"}}]}
{"op":"mcm","clk":"4229907292","pt":1631526436794,"mc":[{"id":"1.187594229","marketDefinition":{"bspMarket":false,"turnInPlayEnabled":true,"persistenceEnabled":true,"marketBaseRate":5.0,"eventId":"30897689","eventTypeId":"2","numberOfWinners":1,"bettingType":"ODDS","marketType":"MATCH_ODDS","marketTime":"2021-09-13T09:47:15.000Z","suspendTime":"2021-09-13T09:47:15.000Z","bspReconciled":false,"complete":true,"inPlay":true,"crossMatching":true,"runnersVoidable":false,"numberOfActiveRunners":2,"betDelay":5,"status":"OPEN","runners":[{"status":"ACTIVE","sortPriority":1,"id":11809898,"name":"O Gadecki"},{"status":"ACTIVE","sortPriority":2,"id":11772893,"name":"J Garland"}],"regulators":["MR_INT"],"countryCode":"GB","discountAllowed":true,"timezone":"GMT","openDate":"2021-09-13T09:40:00.000Z","version":4030514889,"name":"Match Odds","eventName":"O Gadecki v J Garland"}}]}
{"op":"mcm","clk":"4229907369","pt":1631526437798,"mc":[{"id":"1.187594229","marketDefinition":{"bspMarket":false,"turnInPlayEnabled":true,"persistenceEnabled":true,"marketBaseRate":5.0,"eventId":"30897689","eventTypeId":"2","numberOfWinners":1,"bettingType":"ODDS","marketType":"MATCH_ODDS","marketTime":"2021-09-13T09:47:15.000Z","suspendTime":"2021-09-13T09:47:15.000Z","bspReconciled":false,"complete":true,"inPlay":true,"crossMatching":true,"runnersVoidable":false,"numberOfActiveRunners":2,"betDelay":5,"status":"OPEN","runners":[{"status":"ACTIVE","sortPriority":1,"id":11809898,"name":"O Gadecki"},{"status":"ACTIVE","sortPriority":2,"id":11772893,"name":"J Garland"}],"regulators":["MR_INT"],"countryCode":"GB","discountAllowed":true,"timezone":"GMT","openDate":"2021-09-13T09:47:15.000Z","version":4030514889,"name":"Match Odds","eventName":"O Gadecki v J Garland"}}]}
{"op":"mcm","clk":"4229931403","pt":1631526679254,"mc":[{"id":"1.187594229","rc":[{"batb":[[0,1.25,513.07],[1,1.01,7]],"batl":[[1,1.77,508.52]],"ltp":0.0,"tv":0.0,"id":11809898}]}]}
{"op":"mcm","clk":"4229932722","pt":1631526697991,"mc":[{"id":"1.187594229","rc":[{"batb":[[0,1.01,7],[1,1.01,0]],"ltp":0.0,"tv":0.0,"id":11809898}]}]}
{"op":"mcm","clk":"4229933074","pt":1631526703474,"mc":[{"id":"1.187594229","rc":[{"batb":[[0,1.31,485.05],[1,1.01,7]],"ltp":0.0,"tv":0.0,"id":11809898}]}]}
{"op":"mcm","clk":"4229935689","pt":1631526739556,"mc":[{"id":"1.187594229","rc":[{"batb":[[0,1.01,7],[1,1.01,0]],"ltp":0.0,"tv":0.0,"id":11809898}]}]}
{"op":"mcm","clk":"4229936059","pt":1631526744870,"mc":[{"id":"1.187594229","rc":[{"batb":[[0,1.25,513.07],[1,1.01,7]],"ltp":0.0,"tv":0.0,"id":11809898}]}]}
{"op":"mcm","clk":"4229937956","pt":1631526772123,"mc":[{"id":"1.187594229","rc":[{"batb":[[0,1.01,7],[1,1.01,0]],"ltp":0.0,"tv":0.0,"id":11809898}]}]}
{"op":"mcm","clk":"4229938405","pt":1631526778454,"mc":[{"id":"1.187594229","rc":[{"batb":[[0,1.31,485.05],[1,1.01,7]],"ltp":0.0,"tv":0.0,"id":11809898}]}]}
{"op":"mcm","clk":"4229941689","pt":1631526832201,"mc":[{"id":"1.187594229","rc":[{"batb":[[0,1.01,7],[1,1.01,0]],"ltp":0.0,"tv":0.0,"id":11809898}]}]}
{"op":"mcm","clk":"4229941960","pt":1631526838315,"mc":[{"id":"1.187594229","rc":[{"batb":[[0,1.23,524.63],[1,1.01,7]],"ltp":0.0,"tv":0.0,"id":11809898}]}]}
{"op":"mcm","clk":"4229944139","pt":1631526878976,"mc":[{"id":"1.187594229","rc":[{"batb":[[0,1.01,7],[1,1.01,0]],"ltp":0.0,"tv":0.0,"id":11809898}]}]}
{"op":"mcm","clk":"4229944482","pt":1631526884595,"mc":[{"id":"1.187594229","rc":[{"batb":[[0,1.28,493.56],[1,1.01,7]],"ltp":0.0,"tv":0.0,"id":11809898}]}]}
{"op":"mcm","clk":"4229947417","pt":1631526935012,"mc":[{"id":"1.187594229","rc":[{"batb":[[0,1.01,7],[1,1.01,0]],"ltp":0.0,"tv":0.0,"id":11809898}]}]}
{"op":"mcm","clk":"4229947715","pt":1631526940388,"mc":[{"id":"1.187594229","rc":[{"batb":[[0,1.23,524.63],[1,1.01,7]],"ltp":0.0,"tv":0.0,"id":11809898}]}]}
{"op":"mcm","clk":"4229948851","pt":1631526961436,"mc":[{"id":"1.187594229","rc":[{"batb":[[0,1.01,7],[1,1.01,0]],"batl":[[1,1.77,0]],"ltp":0.0,"tv":0.0,"id":11809898}]}]}
{"op":"mcm","clk":"4229949164","pt":1631526967065,"mc":[{"id":"1.187594229","rc":[{"batb":[[0,1.2,539.24],[1,1.01,7]],"batl":[[1,1.66,588.96]],"ltp":0.0,"tv":0.0,"id":11809898}]}]}
{"op":"mcm","clk":"4229951724","pt":1631527013297,"mc":[{"id":"1.187594229","rc":[{"batb":[[0,1.01,7],[1,1.01,0]],"ltp":0.0,"tv":0.0,"id":11809898}]}]}
{"op":"mcm","clk":"4229952070","pt":1631527018719,"mc":[{"id":"1.187594229","rc":[{"batb":[[0,1.22,531.25],[1,1.01,7]],"ltp":0.0,"tv":0.0,"id":11809898}]}]}
{"op":"mcm","clk":"4229956642","pt":1631527092523,"mc":[{"id":"1.187594229","rc":[{"batb":[[0,1.01,7],[1,1.01,0]],"ltp":0.0,"tv":0.0,"id":11809898}]}]}
{"op":"mcm","clk":"4229957024","pt":1631527098838,"mc":[{"id":"1.187594229","rc":[{"batb":[[0,1.18,558.4],[1,1.01,7]],"ltp":0.0,"tv":0.0,"id":11809898}]}]}
{"op":"mcm","clk":"4229959111","pt":1631527126074,"mc":[{"id":"1.187594229","rc":[{"batb":[[0,1.01,7],[1,1.01,0]],"ltp":0.0,"tv":0.0,"id":11809898}]}]}
{"op":"mcm","clk":"4229959519","pt":1631527131983,"mc":[{"id":"1.187594229","rc":[{"batb":[[0,1.2,539.24],[1,1.01,7]],"ltp":0.0,"tv":0.0,"id":11809898}]}]}
{"op":"mcm","clk":"4229966710","pt":1631527227584,"mc":[{"id":"1.187594229","rc":[{"batb":[[0,1.01,7],[1,1.01,0]],"batl":[[1,1.66,0]],"ltp":0.0,"tv":0.0,"id":11809898}]}]}
{"op":"mcm","clk":"4229967126","pt":1631527233394,"mc":[{"id":"1.187594229","rc":[{"batb":[[0,1.14,620.09],[1,1.01,7]],"batl":[[0,1.55,701.66],[1,1.65,100]],"ltp":0.0,"tv":0.0,"id":11809898}]}]}
{"op":"mcm","clk":"4229978894","pt":1631527404155,"mc":[{"id":"1.187594229","rc":[{"batb":[[0,1.01,7],[1,1.01,0]],"ltp":0.0,"tv":0.0,"id":11809898}]}]}
{"op":"mcm","clk":"4229979256","pt":1631527409636,"mc":[{"id":"1.187594229","rc":[{"batb":[[0,1.16,585.23],[1,1.01,7]],"ltp":0.0,"tv":0.0,"id":11809898}]}]}
{"op":"mcm","clk":"4229981549","pt":1631527442862,"mc":[{"id":"1.187594229","rc":[{"batb":[[0,1.01,7],[1,1.01,0]],"ltp":0.0,"tv":0.0,"id":11809898}]}]}
{"op":"mcm","clk":"4229981991","pt":1631527448877,"mc":[{"id":"1.187594229","rc":[{"batb":[[0,1.14,620.09],[1,1.01,7]],"ltp":0.0,"tv":0.0,"id":11809898}]}]}
{"op":"mcm","clk":"4229983813","pt":1631527476389,"mc":[{"id":"1.187594229","rc":[{"batb":[[0,1.01,7],[1,1.01,0]],"ltp":0.0,"tv":0.0,"id":11809898}]}]}
{"op":"mcm","clk":"4229984175","pt":1631527482281,"mc":[{"id":"1.187594229","rc":[{"batb":[[0,1.16,585.23],[1,1.01,7]],"ltp":0.0,"tv":0.0,"id":11809898}]}]}
{"op":"mcm","clk":"4229985807","pt":1631527506919,"mc":[{"id":"1.187594229","rc":[{"batb":[[0,1.01,7],[1,1.01,0]],"ltp":0.0,"tv":0.0,"id":11809898}]}]}
{"op":"mcm","clk":"4229986293","pt":1631527512818,"mc":[{"id":"1.187594229","rc":[{"batb":[[0,1.14,620.09],[1,1.01,7]],"ltp":0.0,"tv":0.0,"id":11809898}]}]}
{"op":"mcm","clk":"4229988493","pt":1631527547521,"mc":[{"id":"1.187594229","rc":[{"batb":[[0,1.01,7],[1,1.01,0]],"ltp":0.0,"tv":0.0,"id":11809898}]}]}
{"op":"mcm","clk":"4229988873","pt":1631527553312,"mc":[{"id":"1.187594229","rc":[{"batb":[[0,1.16,585.23],[1,1.01,7]],"ltp":0.0,"tv":0.0,"id":11809898}]}]}
{"op":"mcm","clk":"4229990263","pt":1631527573926,"mc":[{"id":"1.187594229","rc":[{"batb":[[0,1.01,7],[1,1.01,0]],"ltp":0.0,"tv":0.0,"id":11809898}]}]}
{"op":"mcm","clk":"4229990636","pt":1631527579625,"mc":[{"id":"1.187594229","rc":[{"batb":[[0,1.18,558.4],[1,1.01,7]],"ltp":0.0,"tv":0.0,"id":11809898}]}]}
{"op":"mcm","clk":"4229991274","pt":1631527589148,"mc":[{"id":"1.187594229","rc":[{"batb":[[0,1.01,7],[1,1.01,0]],"ltp":0.0,"tv":0.0,"id":11809898}]}]}
{"op":"mcm","clk":"4229991631","pt":1631527594836,"mc":[{"id":"1.187594229","rc":[{"batb":[[0,1.2,539.24],[1,1.01,7]],"ltp":0.0,"tv":0.0,"id":11809898}]}]}
{"op":"mcm","clk":"4229994100","pt":1631527632822,"mc":[{"id":"1.187594229","rc":[{"batb":[[0,1.01,7],[1,1.01,0]],"batl":[[0,1.65,100],[1,1.65,0]],"ltp":0.0,"tv":0.0,"id":11809898}]}]}
{"op":"mcm","clk":"4229994478","pt":1631527638407,"mc":[{"id":"1.187594229","rc":[{"batb":[[0,1.22,531.25],[1,1.01,7]],"batl":[[1,1.71,550.62]],"ltp":0.0,"tv":0.0,"id":11809898}]}]}
{"op":"mcm","clk":"4229997561","pt":1631527681357,"mc":[{"id":"1.187594229","rc":[{"batb":[[0,1.01,7],[1,1.01,0]],"batl":[[1,1.71,0]],"ltp":0.0,"tv":0.0,"id":11809898}]}]}
{"op":"mcm","clk":"4229997958","pt":1631527686771,"mc":[{"id":"1.187594229","rc":[{"batb":[[0,1.16,585.23],[1,1.01,7]],"batl":[[0,1.58,660.85],[1,1.65,100]],"ltp":0.0,"tv":0.0,"id":11809898}]}]}
{"op":"mcm","clk":"4229999475","pt":1631527706904,"mc":[{"id":"1.187594229","rc":[{"batb":[[0,1.01,7],[1,1.01,0]],"ltp":0.0,"tv":0.0,"id":11809898}]}]}
{"op":"mcm","clk":"4230000028","pt":1631527713285,"mc":[{"id":"1.187594229","rc":[{"batb":[[0,1.18,558.4],[1,1.01,7]],"ltp":0.0,"tv":0.0,"id":11809898}]}]}
{"op":"mcm","clk":"4230001775","pt":1631527736240,"mc":[{"id":"1.187594229","rc":[{"batb":[[0,1.01,7],[1,1.01,0]],"ltp":0.0,"tv":0.0,"id":11809898}]}]}
{"op":"mcm","clk":"4230002292","pt":1631527741548,"mc":[{"id":"1.187594229","rc":[{"batb":[[0,1.22,531.25],[1,1.01,7]],"ltp":0.0,"tv":0.0,"id":11809898}]}]}
{"op":"mcm","clk":"4230006742","pt":1631527796199,"mc":[{"id":"1.187594229","rc":[{"batb":[[0,1.01,7],[1,1.01,0]],"ltp":0.0,"tv":0.0,"id":11809898}]}]}
{"op":"mcm","clk":"4230007192","pt":1631527802540,"mc":[{"id":"1.187594229","rc":[{"batb":[[0,1.18,558.4],[1,1.01,7]],"ltp":0.0,"tv":0.0,"id":11809898}]}]}
{"op":"mcm","clk":"4230013030","pt":1631527882713,"mc":[{"id":"1.187594229","rc":[{"batb":[[0,1.01,7],[1,1.01,0]],"ltp":0.0,"tv":0.0,"id":11809898}]}]}
{"op":"mcm","clk":"4230013454","pt":1631527888552,"mc":[{"id":"1.187594229","rc":[{"batb":[[0,1.14,620.09],[1,1.01,7]],"ltp":0.0,"tv":0.0,"id":11809898}]}]}
{"op":"mcm","clk":"4230016080","pt":1631527923400,"mc":[{"id":"1.187594229","rc":[{"trd":[[1.14,300.08]],"batb":[[0,1.14,470.01]],"ltp":1.14,"tv":300.08,"id":11809898}],"tv":300.08}]}
{"op":"mcm","clk":"4230016979","pt":1631527933807,"mc":[{"id":"1.187594229","rc":[{"batb":[[0,1.01,7],[1,1.01,0]],"batl":[[0,1.65,100],[1,1.65,0]],"ltp":1.14,"tv":300.08,"id":11809898}]}]}
{"op":"mcm","clk":"4230040311","pt":1631528115506,"mc":[{"id":"1.187594229","rc":[{"batb":[[0,1.16,436.93],[1,1.01,7]],"batl":[[0,1.58,768.21],[1,1.65,100]],"ltp":1.14,"tv":300.08,"id":11809898}]}]}
{"op":"mcm","clk":"4230041865","pt":1631528136902,"mc":[{"id":"1.187594229","rc":[{"batb":[[0,1.01,7],[1,1.01,0]],"ltp":1.14,"tv":300.08,"id":11809898}]}]}
{"op":"mcm","clk":"4230042298","pt":1631528142929,"mc":[{"id":"1.187594229","rc":[{"batb":[[0,1.18,413.59],[1,1.01,7]],"ltp":1.14,"tv":300.08,"id":11809898}]}]}
{"op":"mcm","clk":"4230047035","pt":1631528208373,"mc":[{"id":"1.187594229","rc":[{"batb":[[0,1.01,7],[1,1.01,0]],"ltp":1.14,"tv":300.08,"id":11809898}]}]}
{"op":"mcm","clk":"4230047473","pt":1631528214181,"mc":[{"id":"1.187594229","rc":[{"batb":[[0,1.14,467.77],[1,1.01,7]],"ltp":1.14,"tv":300.08,"id":11809898}]}]}
{"op":"mcm","clk":"4230050779","pt":1631528262536,"mc":[{"id":"1.187594229","rc":[{"batb":[[0,1.01,7],[1,1.01,0]],"ltp":1.14,"tv":300.08,"id":11809898}]}]}
{"op":"mcm","clk":"4230051186","pt":1631528268885,"mc":[{"id":"1.187594229","rc":[{"batb":[[0,1.16,436.93],[1,1.01,7]],"ltp":1.14,"tv":300.08,"id":11809898}]}]}
{"op":"mcm","clk":"4230054635","pt":1631528318703,"mc":[{"id":"1.187594229","rc":[{"batb":[[0,1.01,7],[1,1.01,0]],"ltp":1.14,"tv":300.08,"id":11809898}]}]}
{"op":"mcm","clk":"4230055100","pt":1631528324611,"mc":[{"id":"1.187594229","rc":[{"batb":[[0,1.14,467.77],[1,1.01,7]],"ltp":1.14,"tv":300.08,"id":11809898}]}]}
{"op":"mcm","clk":"4230055121","pt":1631528324921,"mc":[{"id":"1.187594229","rc":[{"batb":[[0,3.05,13.25],[1,1.01,7]],"ltp":0.0,"tv":0.0,"id":11772893}]}]}
{"op":"mcm","clk":"4230056726","pt":1631528352448,"mc":[{"id":"1.187594229","rc":[{"batb":[[0,1.01,7],[1,1.01,0]],"batl":[[0,1.65,100],[1,1.65,0]],"ltp":1.14,"tv":300.08,"id":11809898}]}]}
{"op":"mcm","clk":"4230057053","pt":1631528358482,"mc":[{"id":"1.187594229","rc":[{"batb":[[0,1.1,570.93],[1,1.01,7]],"batl":[[0,1.48,912.11],[1,1.65,100]],"ltp":1.14,"tv":300.08,"id":11809898}]}]}
{"op":"mcm","clk":"4230058808","pt":1631528390781,"mc":[{"id":"1.187594229","rc":[{"batb":[[0,3.45,11.04],[1,3.05,13.25],[2,1.01,7]],"ltp":0.0,"tv":0.0,"id":11772893}]}]}
{"op":"mcm","clk":"4230059599","pt":1631528402620,"mc":[{"id":"1.187594229","rc":[{"batb":[[1,1.01,7],[2,1.01,0]],"ltp":0.0,"tv":0.0,"id":11772893}]}]}
{"op":"mcm","clk":"4230062365","pt":1631528439992,"mc":[{"id":"1.187594229","rc":[{"batb":[[0,3.8,9.87],[1,3.45,11.04],[2,1.01,7]],"ltp":0.0,"tv":0.0,"id":11772893}]}]}
{"op":"mcm","clk":"4230062990","pt":1631528449864,"mc":[{"id":"1.187594229","rc":[{"batb":[[1,1.01,7],[2,1.01,0]],"ltp":0.0,"tv":0.0,"id":11772893}]}]}
{"op":"mcm","clk":"4230064275","pt":1631528469787,"mc":[{"id":"1.187594229","rc":[{"batb":[[0,1.01,7],[1,1.01,0]],"ltp":1.14,"tv":300.08,"id":11809898}]}]}
{"op":"mcm","clk":"4230064599","pt":1631528475098,"mc":[{"id":"1.187594229","rc":[{"batb":[[0,1.12,505.87],[1,1.01,7]],"ltp":1.14,"tv":300.08,"id":11809898}]}]}
{"op":"mcm","clk":"4230065485","pt":1631528488131,"mc":[{"id":"1.187594229","rc":[{"batb":[[0,1.01,7],[1,1.01,0]],"ltp":1.14,"tv":300.08,"id":11809898}]}]}
{"op":"mcm","clk":"4230065870","pt":1631528493751,"mc":[{"id":"1.187594229","rc":[{"batb":[[0,1.09,603.03],[1,1.01,7]],"ltp":1.14,"tv":300.08,"id":11809898}]}]}
{"op":"mcm","clk":"4230068255","pt":1631528530075,"mc":[{"id":"1.187594229","rc":[{"batb":[[0,1.01,7],[1,1.01,0]],"ltp":1.14,"tv":300.08,"id":11809898}]}]}
{"op":"mcm","clk":"4230068711","pt":1631528536288,"mc":[{"id":"1.187594229","rc":[{"batb":[[0,1.1,570.93],[1,1.01,7]],"ltp":1.14,"tv":300.08,"id":11809898}]}]}
{"op":"mcm","clk":"4230069245","pt":1631528544510,"mc":[{"id":"1.187594229","rc":[{"batb":[[0,1.01,7],[1,1.01,0]],"ltp":1.14,"tv":300.08,"id":11809898}]}]}
{"op":"mcm","clk":"4230069585","pt":1631528550411,"mc":[{"id":"1.187594229","rc":[{"batb":[[0,1.08,650.14],[1,1.01,7]],"ltp":1.14,"tv":300.08,"id":11809898}]}]}
{"op":"mcm","clk":"4230071052","pt":1631528570719,"mc":[{"id":"1.187594229","rc":[{"batb":[[0,1.09,80.99],[1,1.08,650.14],[2,1.01,7]],"ltp":1.14,"tv":300.08,"id":11809898}]}]}
{"op":"mcm","clk":"4230071176","pt":1631528572011,"mc":[{"id":"1.187594229","rc":[{"batb":[[1,1.01,7],[2,1.01,0]],"batl":[[0,1.65,100],[1,1.65,0]],"ltp":1.14,"tv":300.08,"id":11809898}]}]}
{"op":"mcm","clk":"4230071613","pt":1631528578013,"mc":[{"id":"1.187594229","rc":[{"batb":[[1,1.06,822.27],[2,1.01,7]],"batl":[[0,1.41,1036.84],[1,1.65,100]],"ltp":1.14,"tv":300.08,"id":11809898}]}]}
{"op":"mcm","clk":"4230071973","pt":1631528582907,"mc":[{"id":"1.187594229","rc":[{"batb":[[0,1.06,822.27],[1,1.01,7],[2,1.01,0]],"ltp":1.14,"tv":300.08,"id":11809898}]}]}
{"op":"mcm","clk":"4230086742","pt":1631528789842,"mc":[{"id":"1.187594229","rc":[{"batb":[[0,1.07,80.99],[1,1.06,822.27],[2,1.01,7]],"ltp":1.14,"tv":300.08,"id":11809898}]}]}
{"op":"mcm","clk":"4230089136","pt":1631528822263,"mc":[{"id":"1.187594229","rc":[{"batb":[[0,1.01,7],[1,1.01,0]],"ltp":0.0,"tv":0.0,"id":11772893}]}]}
{"op":"mcm","clk":"4230089524","pt":1631528827668,"mc":[{"id":"1.187594229","rc":[{"batb":[[0,4.1,8.83],[1,1.01,7]],"ltp":0.0,"tv":0.0,"id":11772893}]}]}
{"op":"mcm","clk":"4230097833","pt":1631528938167,"mc":[{"id":"1.187594229","rc":[{"trd":[[1.07,127.39]],"batb":[[0,1.07,17.3]],"ltp":1.07,"tv":427.46,"id":11809898}],"tv":427.46}]}
{"op":"mcm","clk":"4230101064","pt":1631528982911,"mc":[{"id":"1.187594229","rc":[{"batb":[[0,1.06,822.27],[1,1.01,7],[2,1.01,0]],"ltp":1.07,"tv":427.46,"id":11809898}]}]}
{"op":"mcm","clk":"4230103370","pt":1631529011722,"mc":[{"id":"1.187594229","rc":[{"batl":[[0,1.15,57.43],[1,1.41,1036.84],[2,1.65,100]],"ltp":1.07,"tv":427.46,"id":11809898}]}]}
{"op":"mcm","clk":"4230104423","pt":1631529021947,"mc":[{"id":"1.187594229","rc":[{"batb":[[0,1.01,7],[1,1.01,0]],"batl":[[1,1.65,100],[2,1.65,0]],"ltp":1.07,"tv":427.46,"id":11809898}]}]}
{"op":"mcm","clk":"4230105808","pt":1631529036964,"mc":[{"id":"1.187594229","rc":[{"batb":[[0,1.01,7],[1,1.01,0]],"ltp":0.0,"tv":0.0,"id":11772893}]}]}
{"op":"mcm","clk":"4230106361","pt":1631529043087,"mc":[{"id":"1.187594229","rc":[{"batl":[[0,1.65,100],[1,1.65,0]],"ltp":1.07,"tv":427.46,"id":11809898}]}]}
{"op":"mcm","clk":"4230106839","pt":1631529048464,"mc":[{"id":"1.187594229","rc":[{"batl":[[0,1.18,57.43],[1,1.65,100]],"ltp":1.07,"tv":427.46,"id":11809898}]}]}
{"op":"mcm","clk":"4230110691","pt":1631529090810,"mc":[{"id":"1.187594229","rc":[{"batl":[[0,1.65,100],[1,1.65,0]],"ltp":1.07,"tv":427.46,"id":11809898}]}]}
{"op":"mcm","clk":"4230111440","pt":1631529099913,"mc":[{"id":"1.187594229","rc":[{"batb":[[0,1.05,914.12],[1,1.01,7]],"batl":[[0,1.38,1110.89],[1,1.65,100]],"ltp":1.07,"tv":427.46,"id":11809898}]}]}
{"op":"mcm","clk":"4230116434","pt":1631529156795,"mc":[{"id":"1.187594229","rc":[{"batl":[[0,1.12,58.91],[1,1.38,1110.89],[2,1.65,100]],"ltp":1.07,"tv":427.46,"id":11809898}]}]}
{"op":"mcm","clk":"4230119901","pt":1631529200743,"mc":[{"id":"1.187594229","rc":[{"batb":[[0,1.01,7],[1,1.01,0]],"ltp":1.07,"tv":427.46,"id":11809898}]}]}
{"op":"mcm","clk":"4230120337","pt":1631529206533,"mc":[{"id":"1.187594229","rc":[{"batb":[[0,1.04,1083.53],[1,1.01,7]],"ltp":1.07,"tv":427.46,"id":11809898}]}]}
{"op":"mcm","clk":"4230121663","pt":1631529226056,"mc":[{"id":"1.187594229","rc":[{"batl":[[0,1.38,1110.89],[1,1.65,100],[2,1.65,0]],"ltp":1.07,"tv":427.46,"id":11809898}]}]}
{"op":"mcm","clk":"4230122046","pt":1631529231338,"mc":[{"id":"1.187594229","rc":[{"batl":[[0,1.1,58.91],[1,1.38,1110.89],[2,1.65,100]],"ltp":1.07,"tv":427.46,"id":11809898}]}]}
{"op":"mcm","clk":"4230123765","pt":1631529252694,"mc":[{"id":"1.187594229","rc":[{"batb":[[0,1.01,7],[1,1.01,0]],"ltp":1.07,"tv":427.46,"id":11809898}]}]}
{"op":"mcm","clk":"4230124191","pt":1631529258354,"mc":[{"id":"1.187594229","rc":[{"batb":[[0,1.03,1382.11],[1,1.01,7]],"ltp":1.07,"tv":427.46,"id":11809898}]}]}
{"op":"mcm","clk":"4230128497","pt":1631529314836,"mc":[{"id":"1.187594229","rc":[{"batl":[[0,1.38,1110.89],[1,1.65,100],[2,1.65,0]],"ltp":1.07,"tv":427.46,"id":11809898}]}]}
{"op":"mcm","clk":"4230128926","pt":1631529320140,"mc":[{"id":"1.187594229","rc":[{"batl":[[0,1.08,60.37],[1,1.38,1110.89],[2,1.65,100]],"ltp":1.07,"tv":427.46,"id":11809898}]}]}
{"op":"mcm","clk":"4230134509","pt":1631529392837,"mc":[{"id":"1.187594229","rc":[{"batl":[[0,1.38,1110.89],[1,1.65,100],[2,1.65,0]],"ltp":1.07,"tv":427.46,"id":11809898}]}]}
{"op":"mcm","clk":"4230134909","pt":1631529398132,"mc":[{"id":"1.187594229","rc":[{"trd":[[1.03,120.75]],"batb":[[0,1.03,1321.74]],"ltp":1.03,"tv":548.21,"id":11809898}],"tv":548.21}]}
{"op":"mcm","clk":"4230134981","pt":1631529398965,"mc":[{"id":"1.187594229","rc":[{"batb":[[0,1.01,7],[1,1.01,0]],"batl":[[0,1.65,100],[1,1.65,0]],"ltp":1.03,"tv":548.21,"id":11809898}]}]}
{"op":"mcm","clk":"4230137222","pt":1631529429786,"mc":[{"id":"1.187594229","rc":[{"batb":[[0,3.05,13.25],[1,1.01,7]],"ltp":0.0,"tv":0.0,"id":11772893}]}]}
{"op":"mcm","clk":"4230139191","pt":1631529457013,"mc":[{"id":"1.187594229","rc":[{"batl":[[0,1.4,768.11],[1,1.65,100]],"ltp":1.03,"tv":548.21,"id":11809898}]}]}
{"op":"mcm","clk":"4230139363","pt":1631529459498,"mc":[{"id":"1.187594229","rc":[{"batl":[[0,1.38,14.51],[1,1.4,768.11],[2,1.65,100]],"ltp":1.03,"tv":548.21,"id":11809898}]}]}
{"op":"mcm","clk":"4230140354","pt":1631529472942,"mc":[{"id":"1.187594229","rc":[{"batb":[[0,1.01,7],[1,1.01,0]],"ltp":0.0,"tv":0.0,"id":11772893}]}]}
{"op":"mcm","clk":"4230140741","pt":1631529478212,"mc":[{"id":"1.187594229","rc":[{"batb":[[0,4.1,8.83],[1,1.01,7]],"ltp":0.0,"tv":0.0,"id":11772893}]}]}
{"op":"mcm","clk":"4230145870","pt":1631529540088,"mc":[{"id":"1.187594229","rc":[{"batl":[[0,1.32,66.57],[1,1.38,14.51],[2,1.4,768.11]],"ltp":1.03,"tv":548.21,"id":11809898}]}]}
{"op":"mcm","clk":"4230147947","pt":1631529563907,"mc":[{"id":"1.187594229","rc":[{"batb":[[0,1.01,7],[1,1.01,0]],"ltp":0.0,"tv":0.0,"id":11772893}]}]}
{"op":"mcm","clk":"4230148402","pt":1631529569218,"mc":[{"id":"1.187594229","rc":[{"batb":[[0,4.3,8.83],[1,1.01,7]],"ltp":0.0,"tv":0.0,"id":11772893}]}]}
{"op":"mcm","clk":"4230149149","pt":1631529580106,"mc":[{"id":"1.187594229","rc":[{"batl":[[0,1.38,14.51],[1,1.4,768.11],[2,1.65,100]],"ltp":1.03,"tv":548.21,"id":11809898}]}]}
{"op":"mcm","clk":"4230149531","pt":1631529585237,"mc":[{"id":"1.187594229","rc":[{"batl":[[0,1.3,66.57],[1,1.38,14.51],[2,1.4,768.11]],"ltp":1.03,"tv":548.21,"id":11809898}]}]}
{"op":"mcm","clk":"4230151236","pt":1631529606852,"mc":[{"id":"1.187594229","rc":[{"batb":[[0,1.01,7],[1,1.01,0]],"ltp":0.0,"tv":0.0,"id":11772893}]}]}
{"op":"mcm","clk":"4230151642","pt":1631529612140,"mc":[{"id":"1.187594229","rc":[{"batb":[[0,4.8,7.37],[1,1.01,7]],"ltp":0.0,"tv":0.0,"id":11772893}]}]}
{"op":"mcm","clk":"4230152581","pt":1631529623274,"mc":[{"id":"1.187594229","rc":[{"batl":[[0,1.38,14.51],[1,1.4,768.11],[2,1.65,100]],"ltp":1.03,"tv":548.21,"id":11809898}]}]}
{"op":"mcm","clk":"4230152914","pt":1631529628384,"mc":[{"id":"1.187594229","rc":[{"batl":[[0,1.24,66.57],[1,1.38,14.51],[2,1.4,768.11]],"ltp":1.03,"tv":548.21,"id":11809898}]}]}
{"op":"mcm","clk":"4230155545","pt":1631529661949,"mc":[{"id":"1.187594229","rc":[{"batb":[[0,1.01,7],[1,1.01,0]],"ltp":0.0,"tv":0.0,"id":11772893}]}]}
{"op":"mcm","clk":"4230156040","pt":1631529667245,"mc":[{"id":"1.187594229","rc":[{"batb":[[0,5.2,7.37],[1,1.01,7]],"ltp":0.0,"tv":0.0,"id":11772893}]}]}
{"op":"mcm","clk":"4230156640","pt":1631529674758,"mc":[{"id":"1.187594229","rc":[{"trd":[[1.01,14.01]],"batl":[[0,1.01,7674.14],[1,1.24,66.57],[2,1.38,14.51]],"ltp":1.01,"tv":562.22,"id":11809898}],"tv":562.22}]}
{"op":"mcm","clk":"4230156899","pt":1631529678243,"mc":[{"id":"1.187594229","rc":[{"batl":[[1,1.38,14.51],[2,1.4,768.11]],"ltp":1.01,"tv":562.22,"id":11809898}]}]}
{"op":"mcm","clk":"4230157306","pt":1631529683382,"mc":[{"id":"1.187594229","rc":[{"batl":[[1,1.23,66.57],[2,1.38,14.51]],"ltp":1.01,"tv":562.22,"id":11809898}]}]}
{"op":"mcm","clk":"4230158074","pt":1631529693958,"mc":[{"id":"1.187594229","rc":[{"batb":[[0,1.01,7],[1,1.01,0]],"ltp":0.0,"tv":0.0,"id":11772893}]}]}
{"op":"mcm","clk":"4230158435","pt":1631529699263,"mc":[{"id":"1.187594229","rc":[{"batb":[[0,6.2,7.37],[1,1.01,7]],"ltp":0.0,"tv":0.0,"id":11772893}]}]}
{"op":"mcm","clk":"4230158849","pt":1631529704346,"mc":[{"id":"1.187594229","marketDefinition":{"bspMarket":false,"turnInPlayEnabled":true,"persistenceEnabled":true,"marketBaseRate":5.0,"eventId":"30897689","eventTypeId":"2","numberOfWinners":1,"bettingType":"ODDS","marketType":"MATCH_ODDS","marketTime":"2021-09-13T09:47:15.000Z","suspendTime":"2021-09-13T09:47:15.000Z","bspReconciled":false,"complete":true,"inPlay":true,"crossMatching":true,"runnersVoidable":false,"numberOfActiveRunners":2,"betDelay":5,"status":"SUSPENDED","runners":[{"status":"ACTIVE","sortPriority":1,"id":11809898,"name":"O Gadecki"},{"status":"ACTIVE","sortPriority":2,"id":11772893,"name":"J Garland"}],"regulators":["MR_INT"],"countryCode":"GB","discountAllowed":true,"timezone":"GMT","openDate":"2021-09-13T09:47:15.000Z","version":4030552034,"name":"Match Odds","eventName":"O Gadecki v J Garland"}}]}
{"op":"mcm","clk":"4230171309","pt":1631529859049,"mc":[{"id":"1.187594229","rc":[{"batl":[[0,1.65,100],[1,1.23,0],[2,1.38,0]],"ltp":1.01,"tv":562.22,"id":11809898}]}]}
{"op":"mcm","clk":"4230174664","pt":1631529899597,"mc":[{"id":"1.187594229","tv":0.0}]}
{"op":"mcm","clk":"4230174748","pt":1631529900342,"mc":[{"id":"1.187594229","marketDefinition":{"bspMarket":false,"turnInPlayEnabled":true,"persistenceEnabled":true,"marketBaseRate":5.0,"eventId":"30897689","eventTypeId":"2","numberOfWinners":1,"bettingType":"ODDS","marketType":"MATCH_ODDS","marketTime":"2021-09-13T09:47:15.000Z","suspendTime":"2021-09-13T09:47:15.000Z","bspReconciled":false,"complete":true,"inPlay":true,"crossMatching":false,"runnersVoidable":false,"numberOfActiveRunners":0,"betDelay":5,"status":"CLOSED","settledTime":"2021-09-13T10:44:58.000Z","runners":[{"status":"WINNER","sortPriority":1,"id":11809898,"name":"O Gadecki"},{"status":"LOSER","sortPriority":2,"id":11772893,"name":"J Garland"}],"regulators":["MR_INT"],"countryCode":"GB","discountAllowed":true,"timezone":"GMT","openDate":"2021-09-13T09:47:15.000Z","version":4030553629,"name":"Match Odds","eventName":"O Gadecki v J Garland"}}]}
