{"op":"mcm","clk":"4206015901","pt":1631432584138,"mc":[{"id":"1.187548829","marketDefinition":{"bspMarket":false,"turnInPlayEnabled":true,"persistenceEnabled":true,"marketBaseRate":5.0,"eventId":"30894999","eventTypeId":"2","numberOfWinners":1,"bettingType":"ODDS","marketType":"MATCH_ODDS","marketTime":"2021-09-12T11:30:00.000Z","suspendTime":"2021-09-12T11:30:00.000Z","bspReconciled":false,"complete":true,"inPlay":false,"crossMatching":false,"runnersVoidable":false,"numberOfActiveRunners":2,"betDelay":0,"status":"OPEN","runners":[{"status":"ACTIVE","sortPriority":1,"id":9626703,"name":"M Di Giuseppe"},{"status":"ACTIVE","sortPriority":2,"id":9589287,"name":"A Carreras"}],"regulators":["MR_INT"],"countryCode":"GB","discountAllowed":false,"timezone":"GMT","openDate":"2021-09-12T12:30:00.000Z","version":4027491841,"name":"Match Odds","eventName":"M Di Giuseppe v A Carreras"},"rc":[{"batb":[[0,1.01,25]],"ltp":0.0,"tv":0.0,"id":9626703},{"batb":[[0,1.01,25]],"ltp":0.0,"tv":0.0,"id":9589287}]}]}
{"op":"mcm","clk":"4206016029","pt":1631432585965,"mc":[{"id":"1.187548829","marketDefinition":{"bspMarket":false,"turnInPlayEnabled":true,"persistenceEnabled":true,"marketBaseRate":5.0,"eventId":"30894999","eventTypeId":"2","numberOfWinners":1,"bettingType":"ODDS","marketType":"MATCH_ODDS","marketTime":"2021-09-12T11:30:00.000Z","suspendTime":"2021-09-12T11:30:00.000Z","bspReconciled":false,"complete":true,"inPlay":false,"crossMatching":false,"runnersVoidable":false,"numberOfActiveRunners":2,"betDelay":0,"status":"OPEN","runners":[{"status":"ACTIVE","sortPriority":1,"id":9626703,"name":"M Di Giuseppe"},{"status":"ACTIVE","sortPriority":2,"id":9589287,"name":"A Carreras"}],"regulators":["MR_INT"],"countryCode":"GB","discountAllowed":true,"timezone":"GMT","openDate":"2021-09-12T12:30:00.000Z","version":4027491841,"name":"Match Odds","eventName":"M Di Giuseppe v A Carreras"}}]}
{"op":"mcm","clk":"4206024182","pt":1631432707626,"mc":[{"id":"1.187548829","rc":[{"batb":[[0,1.01,7]],"ltp":0.0,"tv":0.0,"id":9626703},{"batb":[[0,1.01,7]],"ltp":0.0,"tv":0.0,"id":9589287}]}]}
{"op":"mcm","clk":"4206119935","pt":1631434093657,"mc":[{"id":"1.187548829","rc":[{"batl":[[0,490,6.16]],"ltp":0.0,"tv":0.0,"id":9626703},{"batl":[[0,490,6.16]],"ltp":0.0,"tv":0.0,"id":9589287}]}]}
{"op":"mcm","clk":"4206138655","pt":1631434340516,"mc":[{"id":"1.187548829","rc":[{"batl":[[1,990,2.2]],"ltp":0.0,"tv":0.0,"id":9626703},{"batl":[[1,990,2.2]],"ltp":0.0,"tv":0.0,"id":9589287}]}]}
{"op":"mcm","clk":"4206258834","pt":1631435897863,"mc":[{"id":"1.187548829","rc":[{"batb":[[0,1.73,46.32],[1,1.01,7]],"ltp":0.0,"tv":0.0,"id":9626703},{"batb":[[0,2,33.81],[1,1.01,7]],"ltp":0.0,"tv":0.0,"id":9589287}]}]}
{"op":"mcm","clk":"4206260424","pt":1631435916384,"mc":[{"id":"1.187548829","marketDefinition":{"bspMarket":false,"turnInPlayEnabled":true,"persistenceEnabled":true,"marketBaseRate":5.0,"eventId":"30894999","eventTypeId":"2","numberOfWinners":1,"bettingType":"ODDS","marketType":"MATCH_ODDS","marketTime":"2021-09-12T11:30:00.000Z","suspendTime":"2021-09-12T11:30:00.000Z","bspReconciled":false,"complete":true,"inPlay":false,"crossMatching":true,"runnersVoidable":false,"numberOfActiveRunners":2,"betDelay":0,"status":"OPEN","runners":[{"status":"ACTIVE","sortPriority":1,"id":9626703,"name":"M Di Giuseppe"},{"status":"ACTIVE","sortPriority":2,"id":9589287,"name":"A Carreras"}],"regulators":["MR_INT"],"countryCode":"GB","discountAllowed":true,"timezone":"GMT","openDate":"2021-09-12T12:30:00.000Z","version":4027491841,"name":"Match Odds","eventName":"M Di Giuseppe v A Carreras"}}]}
{"op":"mcm","clk":"4206447466","pt":1631437690683,"mc":[{"id":"1.187548829","rc":[{"batb":[[1,1.05,879.5],[2,1.01,7]],"ltp":0.0,"tv":0.0,"id":9626703},{"batb":[[1,1.05,879.5],[2,1.01,7]],"ltp":0.0,"tv":0.0,"id":9589287}]}]}
{"op":"mcm","clk":"4206570817","pt":1631439003822,"mc":[{"id":"1.187548829","rc":[{"batb":[[0,1.73,61.77]],"ltp":0.0,"tv":0.0,"id":9626703},{"batb":[[0,2,45.09]],"ltp":0.0,"tv":0.0,"id":9589287}]}]}
{"op":"mcm","clk":"4207010212","pt":1631442582127,"mc":[{"id":"1.187548829","rc":[{"batb":[[0,1.75,25.62],[1,1.73,61.77],[2,1.05,879.5]],"ltp":0.0,"tv":0.0,"id":9626703}]}]}
{"op":"mcm","clk":"4207012515","pt":1631442600842,"mc":[{"id":"1.187548829","rc":[{"batb":[[0,1.76,16.86],[1,1.75,25.62],[2,1.73,61.77]],"ltp":0.0,"tv":0.0,"id":9626703},{"batb":[[0,2.02,12.56],[1,2,45.09],[2,1.05,879.5]],"ltp":0.0,"tv":0.0,"id":9589287}]}]}
{"op":"mcm","clk":"4207106734","pt":1631443297948,"mc":[{"id":"1.187548829","rc":[{"batb":[[1,1.73,61.77],[2,1.05,879.5]],"ltp":0.0,"tv":0.0,"id":9626703}]}]}
{"op":"mcm","clk":"4207106744","pt":1631443298061,"mc":[{"id":"1.187548829","rc":[{"batb":[[0,1.77,25.62],[1,1.76,16.86],[2,1.73,61.77]],"ltp":0.0,"tv":0.0,"id":9626703}]}]}
{"op":"mcm","clk":"4207106873","pt":1631443298960,"mc":[{"id":"1.187548829","rc":[{"batb":[[0,1.78,16.42],[1,1.77,25.62],[2,1.76,16.86]],"ltp":0.0,"tv":0.0,"id":9626703}]}]}
{"op":"mcm","clk":"4207160877","pt":1631443740255,"mc":[{"id":"1.187548829","rc":[{"batb":[[1,1.76,16.86],[2,1.73,61.77]],"ltp":0.0,"tv":0.0,"id":9626703}]}]}
{"op":"mcm","clk":"4207160983","pt":1631443741250,"mc":[{"id":"1.187548829","rc":[{"batb":[[0,1.74,17.31],[1,1.73,61.77],[2,1.42,97.62]],"ltp":0.0,"tv":0.0,"id":9626703}]}]}
{"op":"mcm","clk":"4207162767","pt":1631443758389,"mc":[{"id":"1.187548829","rc":[{"batb":[[0,1.78,24.77],[1,1.74,17.31],[2,1.73,61.77]],"ltp":0.0,"tv":0.0,"id":9626703}]}]}
{"op":"mcm","clk":"4207162867","pt":1631443759288,"mc":[{"id":"1.187548829","rc":[{"batb":[[0,1.79,16.22],[1,1.78,24.77],[2,1.74,17.31]],"ltp":0.0,"tv":0.0,"id":9626703}]}]}
{"op":"mcm","clk":"4207164072","pt":1631443769506,"mc":[{"id":"1.187548829","rc":[{"batb":[[1,1.74,17.31],[2,1.73,61.77]],"ltp":0.0,"tv":0.0,"id":9626703}]}]}
{"op":"mcm","clk":"4207164157","pt":1631443770414,"mc":[{"id":"1.187548829","rc":[{"batb":[[0,1.74,17.31],[1,1.73,61.77],[2,1.42,97.62]],"ltp":0.0,"tv":0.0,"id":9626703}]}]}
{"op":"mcm","clk":"4207165647","pt":1631443783924,"mc":[{"id":"1.187548829","rc":[{"batb":[[0,1.79,24.77],[1,1.74,17.31],[2,1.73,61.77]],"ltp":0.0,"tv":0.0,"id":9626703}]}]}
{"op":"mcm","clk":"4207165704","pt":1631443784343,"mc":[{"id":"1.187548829","rc":[{"batb":[[0,1.8,16.01],[1,1.79,24.77],[2,1.74,17.31]],"ltp":0.0,"tv":0.0,"id":9626703}]}]}
{"op":"mcm","clk":"4207166440","pt":1631443790365,"mc":[{"id":"1.187548829","rc":[{"batb":[[1,1.74,17.31],[2,1.73,61.77]],"ltp":0.0,"tv":0.0,"id":9626703}]}]}
{"op":"mcm","clk":"4207166557","pt":1631443791365,"mc":[{"id":"1.187548829","rc":[{"batb":[[0,1.74,17.31],[1,1.73,61.77],[2,1.42,97.62]],"ltp":0.0,"tv":0.0,"id":9626703}]}]}
{"op":"mcm","clk":"4207168149","pt":1631443805175,"mc":[{"id":"1.187548829","rc":[{"batb":[[0,1.8,24.77],[1,1.74,17.31],[2,1.73,61.77]],"ltp":0.0,"tv":0.0,"id":9626703}]}]}
{"op":"mcm","clk":"4207168304","pt":1631443806398,"mc":[{"id":"1.187548829","rc":[{"batb":[[0,1.81,15.82],[1,1.8,24.77],[2,1.74,17.31]],"ltp":0.0,"tv":0.0,"id":9626703}]}]}
{"op":"mcm","clk":"4207168962","pt":1631443812370,"mc":[{"id":"1.187548829","rc":[{"batb":[[0,1.74,17.31],[1,1.73,61.77],[2,1.42,97.62]],"ltp":0.0,"tv":0.0,"id":9626703}]}]}
{"op":"mcm","clk":"4207170293","pt":1631443824323,"mc":[{"id":"1.187548829","rc":[{"batb":[[0,1.81,23.91],[1,1.74,17.31],[2,1.73,61.77]],"ltp":0.0,"tv":0.0,"id":9626703}]}]}
{"op":"mcm","clk":"4207170428","pt":1631443825290,"mc":[{"id":"1.187548829","rc":[{"batb":[[0,1.82,15.62],[1,1.81,23.91],[2,1.74,17.31]],"ltp":0.0,"tv":0.0,"id":9626703}]}]}
{"op":"mcm","clk":"4207171061","pt":1631443831221,"mc":[{"id":"1.187548829","rc":[{"batb":[[1,1.74,17.31],[2,1.73,61.77]],"ltp":0.0,"tv":0.0,"id":9626703}]}]}
{"op":"mcm","clk":"4207171201","pt":1631443832409,"mc":[{"id":"1.187548829","rc":[{"batb":[[0,1.74,17.31],[1,1.73,61.77],[2,1.42,97.62]],"ltp":0.0,"tv":0.0,"id":9626703}]}]}
{"op":"mcm","clk":"4207172667","pt":1631443844625,"mc":[{"id":"1.187548829","rc":[{"batb":[[0,1.82,23.06],[1,1.74,17.31],[2,1.73,61.77]],"ltp":0.0,"tv":0.0,"id":9626703}]}]}
{"op":"mcm","clk":"4207172737","pt":1631443845344,"mc":[{"id":"1.187548829","rc":[{"batb":[[0,1.83,15.43],[1,1.82,23.06],[2,1.74,17.31]],"ltp":0.0,"tv":0.0,"id":9626703}]}]}
{"op":"mcm","clk":"4207173446","pt":1631443851421,"mc":[{"id":"1.187548829","rc":[{"batb":[[0,1.74,17.31],[1,1.73,61.77],[2,1.42,97.62]],"ltp":0.0,"tv":0.0,"id":9626703}]}]}
{"op":"mcm","clk":"4207175614","pt":1631443868570,"mc":[{"id":"1.187548829","rc":[{"batb":[[0,1.74,42.93]],"ltp":0.0,"tv":0.0,"id":9626703}]}]}
{"op":"mcm","clk":"4207196499","pt":1631444038836,"mc":[{"id":"1.187548829","rc":[{"batb":[[2,1.01,7]],"ltp":0.0,"tv":0.0,"id":9626703}]}]}
{"op":"mcm","clk":"4207197595","pt":1631444047649,"mc":[{"id":"1.187548829","rc":[{"batb":[[2,1.05,879.5]],"ltp":0.0,"tv":0.0,"id":9626703}]}]}
{"op":"mcm","clk":"4207218673","pt":1631444220785,"mc":[{"id":"1.187548829","rc":[{"batb":[[1,1.73,64.43]],"ltp":0.0,"tv":0.0,"id":9626703},{"batb":[[1,2,47.75]],"ltp":0.0,"tv":0.0,"id":9589287}]}]}
{"op":"mcm","clk":"4207886316","pt":1631448000312,"mc":[{"id":"1.187548829","rc":[{"batb":[[0,1.74,25.62]],"ltp":0.0,"tv":0.0,"id":9626703},{"batb":[[0,2,47.75],[1,1.05,879.5],[2,1.02,108.45]],"ltp":0.0,"tv":0.0,"id":9589287}]}]}
{"op":"mcm","clk":"4208265588","pt":1631449886237,"mc":[{"id":"1.187548829","marketDefinition":{"bspMarket":false,"turnInPlayEnabled":true,"persistenceEnabled":true,"marketBaseRate":5.0,"eventId":"30894999","eventTypeId":"2","numberOfWinners":1,"bettingType":"ODDS","marketType":"MATCH_ODDS","marketTime":"2021-09-12T11:30:00.000Z","suspendTime":"2021-09-12T11:30:00.000Z","bspReconciled":false,"complete":true,"inPlay":true,"crossMatching":true,"runnersVoidable":false,"numberOfActiveRunners":2,"betDelay":5,"status":"OPEN","runners":[{"status":"ACTIVE","sortPriority":1,"id":9626703,"name":"M Di Giuseppe"},{"status":"ACTIVE","sortPriority":2,"id":9589287,"name":"A Carreras"}],"regulators":["MR_INT"],"countryCode":"GB","discountAllowed":true,"timezone":"GMT","openDate":"2021-09-12T12:30:00.000Z","version":4028135650,"name":"Match Odds","eventName":"M Di Giuseppe v A Carreras"},"rc":[{"batb":[[0,1.01,12],[1,1.73,0],[2,1.05,0]],"ltp":0.0,"tv":0.0,"id":9626703},{"batb":[[0,1.01,12],[1,1.05,0],[2,1.02,0]],"ltp":0.0,"tv":0.0,"id":9589287}]}]}
{"op":"mcm","clk":"4208434993","pt":1631450669680,"mc":[{"id":"1.187548829","rc":[{"batl":[[0,1.9,0.53]],"ltp":0.0,"tv":0.0,"id":9626703}]}]}
{"op":"mcm","clk":"4208447323","pt":1631450723963,"mc":[{"id":"1.187548829","rc":[{"batl":[[0,1.85,0.53]],"ltp":0.0,"tv":0.0,"id":9626703}]}]}
{"op":"mcm","clk":"4208517760","pt":1631451092489,"mc":[{"id":"1.187548829","marketDefinition":{"bspMarket":false,"turnInPlayEnabled":true,"persistenceEnabled":true,"marketBaseRate":5.0,"eventId":"30894999","eventTypeId":"2","numberOfWinners":1,"bettingType":"ODDS","marketType":"MATCH_ODDS","marketTime":"2021-09-12T12:51:32.000Z","suspendTime":"2021-09-12T12:51:32.000Z","bspReconciled":false,"complete":true,"inPlay":true,"crossMatching":true,"runnersVoidable":false,"numberOfActiveRunners":2,"betDelay":5,"status":"OPEN","runners":[{"status":"ACTIVE","sortPriority":1,"id":9626703,"name":"M Di Giuseppe"},{"status":"ACTIVE","sortPriority":2,"id":9589287,"name":"A Carreras"}],"regulators":["MR_INT"],"countryCode":"GB","discountAllowed":true,"timezone":"GMT","openDate":"2021-09-12T12:30:00.000Z","version":4028190649,"name":"Match Odds","eventName":"M Di Giuseppe v A Carreras"}}]}
{"op":"mcm","clk":"4208518259","pt":1631451095507,"mc":[{"id":"1.187548829","marketDefinition":{"bspMarket":false,"turnInPlayEnabled":true,"persistenceEnabled":true,"marketBaseRate":5.0,"eventId":"30894999","eventTypeId":"2","numberOfWinners":1,"bettingType":"ODDS","marketType":"MATCH_ODDS","marketTime":"2021-09-12T12:51:32.000Z","suspendTime":"2021-09-12T12:51:32.000Z","bspReconciled":false,"complete":true,"inPlay":true,"crossMatching":true,"runnersVoidable":false,"numberOfActiveRunners":2,"betDelay":5,"status":"OPEN","runners":[{"status":"ACTIVE","sortPriority":1,"id":9626703,"name":"M Di Giuseppe"},{"status":"ACTIVE","sortPriority":2,"id":9589287,"name":"A Carreras"}],"regulators":["MR_INT"],"countryCode":"GB","discountAllowed":true,"timezone":"GMT","openDate":"2021-09-12T12:51:32.000Z","version":4028190649,"name":"Match Odds","eventName":"M Di Giuseppe v A Carreras"}}]}
{"op":"mcm","clk":"4208553356","pt":1631451301134,"mc":[{"id":"1.187548829","rc":[{"batb":[[0,1.62,422.28],[1,1.01,12]],"batl":[[0,2.6,261.82]],"ltp":0.0,"tv":0.0,"id":9626703}]}]}
{"op":"mcm","clk":"4208556518","pt":1631451319721,"mc":[{"id":"1.187548829","rc":[{"batb":[[0,1.01,12],[1,1.01,0]],"ltp":0.0,"tv":0.0,"id":9626703}]}]}
{"op":"mcm","clk":"4208557514","pt":1631451325452,"mc":[{"id":"1.187548829","rc":[{"batb":[[0,1.67,416.52],[1,1.01,12]],"ltp":0.0,"tv":0.0,"id":9626703}]}]}
{"op":"mcm","clk":"4208560886","pt":1631451345105,"mc":[{"id":"1.187548829","rc":[{"batb":[[0,1.01,12],[1,1.01,0]],"ltp":0.0,"tv":0.0,"id":9626703}]}]}
{"op":"mcm","clk":"4208561766","pt":1631451350676,"mc":[{"id":"1.187548829","rc":[{"batb":[[0,1.74,410.95],[1,1.01,12]],"batl":[[0,2.92,224.9]],"ltp":0.0,"tv":0.0,"id":9626703}]}]}
{"op":"mcm","clk":"4208565888","pt":1631451376855,"mc":[{"id":"1.187548829","rc":[{"batl":[[0,2.72,245.53]],"ltp":0.0,"tv":0.0,"id":9626703}]}]}
{"op":"mcm","clk":"4208567083","pt":1631451384710,"mc":[{"id":"1.187548829","rc":[{"batb":[[0,1.01,12],[1,1.01,0]],"ltp":0.0,"tv":0.0,"id":9626703}]}]}
{"op":"mcm","clk":"4208567909","pt":1631451390294,"mc":[{"id":"1.187548829","rc":[{"batb":[[0,1.58,423.33],[1,1.01,12]],"batl":[[0,2.5,279.07]],"ltp":0.0,"tv":0.0,"id":9626703}]}]}
{"op":"mcm","clk":"4208569278","pt":1631451399026,"mc":[{"id":"1.187548829","rc":[{"batb":[[0,1.01,12],[1,1.01,0]],"ltp":0.0,"tv":0.0,"id":9626703}]}]}
{"op":"mcm","clk":"4208570107","pt":1631451404430,"mc":[{"id":"1.187548829","rc":[{"batb":[[0,1.62,422.28],[1,1.01,12]],"ltp":0.0,"tv":0.0,"id":9626703}]}]}
{"op":"mcm","clk":"4208586150","pt":1631451504826,"mc":[{"id":"1.187548829","rc":[{"batb":[[0,1.01,12],[1,1.01,0]],"ltp":0.0,"tv":0.0,"id":9626703}]}]}
{"op":"mcm","clk":"4208587019","pt":1631451510607,"mc":[{"id":"1.187548829","rc":[{"batb":[[0,1.46,442.88],[1,1.01,12]],"batl":[[0,2.22,334.44]],"ltp":0.0,"tv":0.0,"id":9626703}]}]}
{"op":"mcm","clk":"4208591829","pt":1631451541187,"mc":[{"id":"1.187548829","rc":[{"batl":[[0,2.1,369.3]],"ltp":0.0,"tv":0.0,"id":9626703}]}]}
{"op":"mcm","clk":"4208600477","pt":1631451597237,"mc":[{"id":"1.187548829","rc":[{"batb":[[0,1.01,12],[1,1.01,0]],"ltp":0.0,"tv":0.0,"id":9626703}]}]}
{"op":"mcm","clk":"4208601448","pt":1631451602865,"mc":[{"id":"1.187548829","rc":[{"batb":[[0,1.38,455.84],[1,1.01,12]],"ltp":0.0,"tv":0.0,"id":9626703}]}]}
{"op":"mcm","clk":"4208614527","pt":1631451672852,"mc":[{"id":"1.187548829","rc":[{"trd":[[1.38,80]],"batb":[[0,1.38,415.83]],"ltp":1.38,"tv":80.0,"id":9626703}],"tv":80.0}]}
{"op":"mcm","clk":"4208614703","pt":1631451673761,"mc":[{"id":"1.187548829","rc":[{"batb":[[0,1.01,12],[1,1.01,0]],"ltp":1.38,"tv":80.0,"id":9626703}]}]}
{"op":"mcm","clk":"4208615772","pt":1631451679546,"mc":[{"id":"1.187548829","rc":[{"batb":[[0,1.44,443.37],[1,1.01,12]],"ltp":1.38,"tv":80.0,"id":9626703}]}]}
{"op":"mcm","clk":"4208620375","pt":1631451702197,"mc":[{"id":"1.187548829","rc":[{"batb":[[0,1.01,12],[1,1.01,0]],"ltp":1.38,"tv":80.0,"id":9626703}]}]}
{"op":"mcm","clk":"4208621656","pt":1631451708186,"mc":[{"id":"1.187548829","rc":[{"batb":[[0,1.5,397.22],[1,1.01,12]],"batl":[[0,2.3,338.84]],"ltp":1.38,"tv":80.0,"id":9626703}]}]}
{"op":"mcm","clk":"4208626140","pt":1631451730771,"mc":[{"id":"1.187548829","rc":[{"batb":[[0,1.01,12],[1,1.01,0]],"ltp":1.38,"tv":80.0,"id":9626703}]}]}
{"op":"mcm","clk":"4208627358","pt":1631451736453,"mc":[{"id":"1.187548829","rc":[{"batb":[[0,1.55,391.99],[1,1.01,12]],"ltp":1.38,"tv":80.0,"id":9626703}]}]}
{"op":"mcm","clk":"4208686242","pt":1631451998315,"mc":[{"id":"1.187548829","rc":[{"batb":[[0,1.01,12],[1,1.01,0]],"ltp":1.38,"tv":80.0,"id":9626703}]}]}
{"op":"mcm","clk":"4208687346","pt":1631452003695,"mc":[{"id":"1.187548829","rc":[{"batb":[[0,1.67,383.76],[1,1.01,12]],"batl":[[0,2.72,265.79]],"ltp":1.38,"tv":80.0,"id":9626703}]}]}
{"op":"mcm","clk":"4208690901","pt":1631452021668,"mc":[{"id":"1.187548829","rc":[{"batb":[[0,1.01,12],[1,1.01,0]],"ltp":1.38,"tv":80.0,"id":9626703}]}]}
{"op":"mcm","clk":"4208691982","pt":1631452027266,"mc":[{"id":"1.187548829","rc":[{"batb":[[0,1.74,379.62],[1,1.01,12]],"ltp":1.38,"tv":80.0,"id":9626703}]}]}
{"op":"mcm","clk":"4208702590","pt":1631452078089,"mc":[{"id":"1.187548829","rc":[{"batb":[[0,1.01,12],[1,1.01,0]],"ltp":1.38,"tv":80.0,"id":9626703}]}]}
{"op":"mcm","clk":"4208717540","pt":1631452146367,"mc":[{"id":"1.187548829","rc":[{"batb":[[0,1.86,375.99],[1,1.01,12]],"batl":[[0,3.3,211.99]],"ltp":1.38,"tv":80.0,"id":9626703}]}]}
{"op":"mcm","clk":"4208720594","pt":1631452159491,"mc":[{"id":"1.187548829","rc":[{"batb":[[0,1.01,12],[1,1.01,0]],"ltp":1.38,"tv":80.0,"id":9626703}]}]}
{"op":"mcm","clk":"4208722087","pt":1631452165631,"mc":[{"id":"1.187548829","rc":[{"batb":[[0,1.97,373.9],[1,1.01,12]],"batl":[[0,3.65,188.46]],"ltp":1.38,"tv":80.0,"id":9626703}]}]}
{"op":"mcm","clk":"4208740213","pt":1631452242439,"mc":[{"id":"1.187548829","rc":[{"batl":[[0,3.45,199.41]],"ltp":1.38,"tv":80.0,"id":9626703}]}]}
{"op":"mcm","clk":"4208741949","pt":1631452249761,"mc":[{"id":"1.187548829","rc":[{"batb":[[0,1.01,12],[1,1.01,0]],"ltp":1.38,"tv":80.0,"id":9626703}]}]}
{"op":"mcm","clk":"4208743186","pt":1631452255550,"mc":[{"id":"1.187548829","rc":[{"batb":[[0,1.74,379.62],[1,1.01,12]],"batl":[[0,2.92,243.87]],"ltp":1.38,"tv":80.0,"id":9626703}]}]}
{"op":"mcm","clk":"4208744180","pt":1631452259952,"mc":[{"id":"1.187548829","rc":[{"batb":[[0,1.01,12],[1,1.01,0]],"ltp":1.38,"tv":80.0,"id":9626703}]}]}
{"op":"mcm","clk":"4208745465","pt":1631452265664,"mc":[{"id":"1.187548829","rc":[{"batb":[[0,1.92,373.24],[1,1.01,12]],"batl":[[0,3.45,199.41]],"ltp":1.38,"tv":80.0,"id":9626703}]}]}
{"op":"mcm","clk":"4208748342","pt":1631452278198,"mc":[{"id":"1.187548829","rc":[{"batb":[[0,1.01,12],[1,1.01,0]],"ltp":1.38,"tv":80.0,"id":9626703}]}]}
{"op":"mcm","clk":"4208749673","pt":1631452283908,"mc":[{"id":"1.187548829","rc":[{"batb":[[0,1.74,379.62],[1,1.01,12]],"batl":[[0,2.92,243.87]],"ltp":1.38,"tv":80.0,"id":9626703}]}]}
{"op":"mcm","clk":"4208754301","pt":1631452304533,"mc":[{"id":"1.187548829","rc":[{"batb":[[0,1.01,12],[1,1.01,0]],"ltp":1.38,"tv":80.0,"id":9626703}]}]}
{"op":"mcm","clk":"4208792361","pt":1631452477305,"mc":[{"id":"1.187548829","rc":[{"batb":[[0,1.58,388.65],[1,1.01,12]],"batl":[[0,2.5,301.24]],"ltp":1.38,"tv":80.0,"id":9626703}]}]}
{"op":"mcm","clk":"4208800049","pt":1631452514116,"mc":[{"id":"1.187548829","rc":[{"batb":[[0,1.01,12],[1,1.01,0]],"ltp":1.38,"tv":80.0,"id":9626703}]}]}
{"op":"mcm","clk":"4208801294","pt":1631452520435,"mc":[{"id":"1.187548829","rc":[{"batb":[[0,1.62,388.35],[1,1.01,12]],"ltp":1.38,"tv":80.0,"id":9626703}]}]}
{"op":"mcm","clk":"4208812261","pt":1631452574802,"mc":[{"id":"1.187548829","rc":[{"batb":[[0,1.01,12],[1,1.01,0]],"ltp":1.38,"tv":80.0,"id":9626703}]}]}
{"op":"mcm","clk":"4208813463","pt":1631452580585,"mc":[{"id":"1.187548829","rc":[{"batb":[[0,1.67,383.76],[1,1.01,12]],"ltp":1.38,"tv":80.0,"id":9626703}]}]}
{"op":"mcm","clk":"4208827341","pt":1631452649707,"mc":[{"id":"1.187548829","rc":[{"batb":[[0,1.01,12],[1,1.01,0]],"ltp":1.38,"tv":80.0,"id":9626703}]}]}
{"op":"mcm","clk":"4208828420","pt":1631452655448,"mc":[{"id":"1.187548829","rc":[{"batb":[[0,1.46,404.9],[1,1.01,12]],"batl":[[0,2.22,359.34]],"ltp":1.38,"tv":80.0,"id":9626703}]}]}
{"op":"mcm","clk":"4208843060","pt":1631452680063,"mc":[{"id":"1.187548829","rc":[{"batb":[[0,1.01,12],[1,1.01,0]],"ltp":1.38,"tv":80.0,"id":9626703}]}]}
{"op":"mcm","clk":"4208844227","pt":1631452685953,"mc":[{"id":"1.187548829","rc":[{"batl":[[0,2.5,301.24]],"ltp":1.38,"tv":80.0,"id":9626703}]}]}
{"op":"mcm","clk":"4208844246","pt":1631452686051,"mc":[{"id":"1.187548829","rc":[{"batb":[[0,1.58,388.65],[1,1.01,12]],"ltp":1.38,"tv":80.0,"id":9626703}]}]}
{"op":"mcm","clk":"4208848126","pt":1631452706400,"mc":[{"id":"1.187548829","rc":[{"batb":[[0,1.01,12],[1,1.01,0]],"ltp":1.38,"tv":80.0,"id":9626703}]}]}
{"op":"mcm","clk":"4208849259","pt":1631452712215,"mc":[{"id":"1.187548829","rc":[{"batb":[[0,1.46,404.9],[1,1.01,12]],"batl":[[0,2.22,359.34]],"ltp":1.38,"tv":80.0,"id":9626703}]}]}
{"op":"mcm","clk":"4208853419","pt":1631452733752,"mc":[{"id":"1.187548829","rc":[{"batb":[[0,1.01,12],[1,1.01,0]],"ltp":1.38,"tv":80.0,"id":9626703}]}]}
{"op":"mcm","clk":"4208854512","pt":1631452739365,"mc":[{"id":"1.187548829","rc":[{"batb":[[0,1.58,388.65],[1,1.01,12]],"batl":[[0,2.5,301.24]],"ltp":1.38,"tv":80.0,"id":9626703}]}]}
{"op":"mcm","clk":"4208857307","pt":1631452754013,"mc":[{"id":"1.187548829","rc":[{"batb":[[0,1.01,12],[1,1.01,0]],"ltp":1.38,"tv":80.0,"id":9626703}]}]}
{"op":"mcm","clk":"4208858348","pt":1631452759598,"mc":[{"id":"1.187548829","rc":[{"batb":[[0,1.46,404.9],[1,1.01,12]],"batl":[[0,2.22,359.34]],"ltp":1.38,"tv":80.0,"id":9626703}]}]}
{"op":"mcm","clk":"4208863014","pt":1631452782435,"mc":[{"id":"1.187548829","rc":[{"batb":[[0,1.01,12],[1,1.01,0]],"ltp":1.38,"tv":80.0,"id":9626703}]}]}
{"op":"mcm","clk":"4208864343","pt":1631452788945,"mc":[{"id":"1.187548829","rc":[{"batb":[[0,1.38,415.73],[1,1.01,12]],"batl":[[0,2.04,416.53]],"ltp":1.38,"tv":80.0,"id":9626703}]}]}
{"op":"mcm","clk":"4208884541","pt":1631452901835,"mc":[{"id":"1.187548829","rc":[{"batb":[[0,1.01,12],[1,1.01,0]],"ltp":1.38,"tv":80.0,"id":9626703}]}]}
{"op":"mcm","clk":"4208885755","pt":1631452907786,"mc":[{"id":"1.187548829","rc":[{"batb":[[0,1.44,405.03],[1,1.01,12]],"ltp":1.38,"tv":80.0,"id":9626703}]}]}
{"op":"mcm","clk":"4208889528","pt":1631452928136,"mc":[{"id":"1.187548829","rc":[{"batb":[[0,1.01,12],[1,1.01,0]],"ltp":1.38,"tv":80.0,"id":9626703}]}]}
{"op":"mcm","clk":"4208890583","pt":1631452933935,"mc":[{"id":"1.187548829","rc":[{"batb":[[0,1.38,415.73],[1,1.01,12]],"ltp":1.38,"tv":80.0,"id":9626703}]}]}
{"op":"mcm","clk":"4208893681","pt":1631452950368,"mc":[{"id":"1.187548829","rc":[{"batb":[[0,1.01,12],[1,1.01,0]],"ltp":1.38,"tv":80.0,"id":9626703}]}]}
{"op":"mcm","clk":"4208894741","pt":1631452955869,"mc":[{"id":"1.187548829","rc":[{"batb":[[0,1.46,404.9],[1,1.01,12]],"ltp":1.38,"tv":80.0,"id":9626703}]}]}
{"op":"mcm","clk":"4208898044","pt":1631452974624,"mc":[{"id":"1.187548829","rc":[{"batb":[[0,1.01,12],[1,1.01,0]],"ltp":1.38,"tv":80.0,"id":9626703}]}]}
{"op":"mcm","clk":"4208899038","pt":1631452980433,"mc":[{"id":"1.187548829","rc":[{"batb":[[0,1.38,415.73],[1,1.01,12]],"ltp":1.38,"tv":80.0,"id":9626703}]}]}
{"op":"mcm","clk":"4208901565","pt":1631452994836,"mc":[{"id":"1.187548829","rc":[{"batb":[[0,1.01,12],[1,1.01,0]],"ltp":1.38,"tv":80.0,"id":9626703}]}]}
{"op":"mcm","clk":"4208902534","pt":1631453000553,"mc":[{"id":"1.187548829","rc":[{"batb":[[0,1.46,404.9],[1,1.01,12]],"ltp":1.38,"tv":80.0,"id":9626703}]}]}
{"op":"mcm","clk":"4208907026","pt":1631453025179,"mc":[{"id":"1.187548829","rc":[{"batb":[[0,1.01,12],[1,1.01,0]],"ltp":1.38,"tv":80.0,"id":9626703}]}]}
{"op":"mcm","clk":"4208908070","pt":1631453030763,"mc":[{"id":"1.187548829","rc":[{"batb":[[0,1.38,415.73],[1,1.01,12]],"ltp":1.38,"tv":80.0,"id":9626703}]}]}
{"op":"mcm","clk":"4208913503","pt":1631453059538,"mc":[{"id":"1.187548829","rc":[{"batb":[[0,1.01,12],[1,1.01,0]],"ltp":1.38,"tv":80.0,"id":9626703}]}]}
{"op":"mcm","clk":"4208914625","pt":1631453065253,"mc":[{"id":"1.187548829","rc":[{"batb":[[0,1.46,404.9],[1,1.01,12]],"ltp":1.38,"tv":80.0,"id":9626703}]}]}
{"op":"mcm","clk":"4208920672","pt":1631453096083,"mc":[{"id":"1.187548829","rc":[{"trd":[[1.46,28.92]],"batb":[[0,1.46,390.44]],"ltp":1.46,"tv":108.92,"id":9626703}],"tv":108.92}]}
{"op":"mcm","clk":"4208921092","pt":1631453098092,"mc":[{"id":"1.187548829","rc":[{"batb":[[0,1.01,12],[1,1.01,0]],"ltp":1.46,"tv":108.92,"id":9626703}]}]}
{"op":"mcm","clk":"4208922212","pt":1631453103796,"mc":[{"id":"1.187548829","rc":[{"batb":[[0,1.5,383.02],[1,1.01,12]],"batl":[[0,2.3,348.03]],"ltp":1.46,"tv":108.92,"id":9626703}]}]}
{"op":"mcm","clk":"4208925313","pt":1631453119397,"mc":[{"id":"1.187548829","rc":[{"batb":[[0,1.01,12],[1,1.01,0]],"ltp":1.46,"tv":108.92,"id":9626703}]}]}
{"op":"mcm","clk":"4208926466","pt":1631453124935,"mc":[{"id":"1.187548829","rc":[{"batb":[[0,1.58,375.22],[1,1.01,12]],"ltp":1.46,"tv":108.92,"id":9626703}]}]}
{"op":"mcm","clk":"4208931334","pt":1631453147642,"mc":[{"id":"1.187548829","rc":[{"batb":[[0,1.01,12],[1,1.01,0]],"ltp":1.46,"tv":108.92,"id":9626703}]}]}
{"op":"mcm","clk":"4208932473","pt":1631453153151,"mc":[{"id":"1.187548829","rc":[{"batb":[[0,1.67,371.07],[1,1.01,12]],"batl":[[0,2.72,273.54]],"ltp":1.46,"tv":108.92,"id":9626703}]}]}
{"op":"mcm","clk":"4208936714","pt":1631453175001,"mc":[{"id":"1.187548829","rc":[{"batb":[[0,1.01,12],[1,1.01,0]],"ltp":1.46,"tv":108.92,"id":9626703}]}]}
{"op":"mcm","clk":"4208938002","pt":1631453181477,"mc":[{"id":"1.187548829","rc":[{"batb":[[0,1.77,366.24],[1,1.01,12]],"ltp":1.46,"tv":108.92,"id":9626703}]}]}
{"op":"mcm","clk":"4208940049","pt":1631453192279,"mc":[{"id":"1.187548829","rc":[{"batb":[[0,1.01,12],[1,1.01,0]],"ltp":1.46,"tv":108.92,"id":9626703}]}]}
{"op":"mcm","clk":"4208941212","pt":1631453198607,"mc":[{"id":"1.187548829","rc":[{"batb":[[0,1.86,364.69],[1,1.01,12]],"batl":[[0,3.3,218.46]],"ltp":1.46,"tv":108.92,"id":9626703}]}]}
{"op":"mcm","clk":"4208942451","pt":1631453204801,"mc":[{"id":"1.187548829","rc":[{"batl":[[0,1.96,2.36]],"ltp":0.0,"tv":0.0,"id":9589287}]}]}
{"op":"mcm","clk":"4208942783","pt":1631453206591,"mc":[{"id":"1.187548829","rc":[{"batl":[[0,1.96,7.13]],"ltp":0.0,"tv":0.0,"id":9589287}]}]}
{"op":"mcm","clk":"4208945937","pt":1631453223657,"mc":[{"id":"1.187548829","rc":[{"batb":[[0,1.01,12],[1,1.01,0]],"ltp":1.46,"tv":108.92,"id":9626703}]}]}
{"op":"mcm","clk":"4208949658","pt":1631453243755,"mc":[{"id":"1.187548829","rc":[{"trd":[[2.04,2.76]],"ltp":2.04,"tv":111.67,"id":9626703},{"trd":[[1.96,2.87]],"batl":[[0,1.96,4.26]],"ltp":1.96,"tv":2.86,"id":9589287}],"tv":114.54}]}
{"op":"mcm","clk":"4208971729","pt":1631453361225,"mc":[{"id":"1.187548829","rc":[{"batb":[[0,1.82,366.34],[1,1.01,12]],"batl":[[0,3.15,227.96]],"ltp":2.04,"tv":111.67,"id":9626703}]}]}
{"op":"mcm","clk":"4208976168","pt":1631453385262,"mc":[{"id":"1.187548829","rc":[{"batl":[[0,2.82,262.21]],"ltp":2.04,"tv":111.67,"id":9626703}]}]}
{"op":"mcm","clk":"4208981775","pt":1631453413500,"mc":[{"id":"1.187548829","rc":[{"batl":[[0,3.15,227.96]],"ltp":2.04,"tv":111.67,"id":9626703}]}]}
{"op":"mcm","clk":"4208988430","pt":1631453447348,"mc":[{"id":"1.187548829","rc":[{"batb":[[0,1.01,12],[1,1.01,0]],"ltp":2.04,"tv":111.67,"id":9626703}]}]}
{"op":"mcm","clk":"4208989481","pt":1631453452872,"mc":[{"id":"1.187548829","rc":[{"batb":[[0,1.97,363.24],[1,1.01,12]],"batl":[[0,3.65,194.29]],"ltp":2.04,"tv":111.67,"id":9626703}]}]}
{"op":"mcm","clk":"4208996167","pt":1631453487730,"mc":[{"id":"1.187548829","rc":[{"batb":[[0,1.01,12],[1,1.01,0]],"ltp":2.04,"tv":111.67,"id":9626703}]}]}
{"op":"mcm","clk":"4208997194","pt":1631453493256,"mc":[{"id":"1.187548829","rc":[{"batb":[[0,2.22,357.45],[1,1.01,12]],"batl":[[0,4.6,155.23]],"ltp":2.04,"tv":111.67,"id":9626703}]}]}
{"op":"mcm","clk":"4209005698","pt":1631453538408,"mc":[{"id":"1.187548829","rc":[{"batb":[[0,1.01,12],[1,1.01,0]],"ltp":2.04,"tv":111.67,"id":9626703}]}]}
{"op":"mcm","clk":"4209006883","pt":1631453544510,"mc":[{"id":"1.187548829","rc":[{"batb":[[0,2.52,358.54],[1,1.01,12]],"batl":[[0,6,120.71]],"ltp":2.04,"tv":111.67,"id":9626703}]}]}
{"op":"mcm","clk":"4209018925","pt":1631453612787,"mc":[{"id":"1.187548829","rc":[{"trd":[[6,20]],"batl":[[0,6,100.71]],"ltp":6.0,"tv":131.67,"id":9626703},{"trd":[[1.2,100]],"ltp":1.2,"tv":102.86,"id":9589287}],"tv":234.54}]}
{"op":"mcm","clk":"4209032303","pt":1631453683864,"mc":[{"id":"1.187548829","rc":[{"batl":[[0,5.5,108.98]],"ltp":6.0,"tv":131.67,"id":9626703}]}]}
{"op":"mcm","clk":"4209040598","pt":1631453727758,"mc":[{"id":"1.187548829","rc":[{"batb":[[0,1.01,12],[1,1.01,0]],"ltp":6.0,"tv":131.67,"id":9626703}]}]}
{"op":"mcm","clk":"4209041778","pt":1631453733743,"mc":[{"id":"1.187548829","rc":[{"batb":[[0,2.72,401.45],[1,1.01,12]],"batl":[[0,7.2,87.62]],"ltp":6.0,"tv":131.67,"id":9626703}]}]}
{"op":"mcm","clk":"4209042791","pt":1631453739059,"mc":[{"id":"1.187548829","rc":[{"batl":[[0,11.5,8.68]],"ltp":1.2,"tv":102.86,"id":9589287}]}]}
{"op":"mcm","clk":"4209047575","pt":1631453763872,"mc":[{"id":"1.187548829","rc":[{"batl":[[0,8.2,81.39]],"ltp":6.0,"tv":131.67,"id":9626703}]}]}
{"op":"mcm","clk":"4209053831","pt":1631453797216,"mc":[{"id":"1.187548829","rc":[{"batl":[[0,7.2,87.62]],"ltp":6.0,"tv":131.67,"id":9626703}]}]}
{"op":"mcm","clk":"4209058215","pt":1631453821382,"mc":[{"id":"1.187548829","rc":[{"batl":[[0,6,100.65]],"ltp":6.0,"tv":131.67,"id":9626703}]}]}
{"op":"mcm","clk":"4209062391","pt":1631453843587,"mc":[{"id":"1.187548829","rc":[{"batl":[[0,5.3,112.48]],"ltp":6.0,"tv":131.67,"id":9626703}]}]}
{"op":"mcm","clk":"4209067066","pt":1631453868325,"mc":[{"id":"1.187548829","rc":[{"batb":[[0,1.01,12],[1,1.01,0]],"ltp":6.0,"tv":131.67,"id":9626703}]}]}
{"op":"mcm","clk":"4209068132","pt":1631453873763,"mc":[{"id":"1.187548829","rc":[{"batb":[[0,2.22,411.12],[1,1.01,12]],"batl":[[0,4.6,128.76]],"ltp":6.0,"tv":131.67,"id":9626703}]}]}
{"op":"mcm","clk":"4209068906","pt":1631453877439,"mc":[{"id":"1.187548829","rc":[{"batb":[[0,1.01,12],[1,1.01,0]],"ltp":6.0,"tv":131.67,"id":9626703}]}]}
{"op":"mcm","clk":"4209094813","pt":1631454018240,"mc":[{"id":"1.187548829","rc":[{"batl":[[0,3.9,149.87]],"ltp":6.0,"tv":131.67,"id":9626703}]}]}
{"op":"mcm","clk":"4209096907","pt":1631454030047,"mc":[{"id":"1.187548829","rc":[{"batl":[[0,4.6,128.76]],"ltp":6.0,"tv":131.67,"id":9626703}]}]}
{"op":"mcm","clk":"4209132486","pt":1631454218630,"mc":[{"id":"1.187548829","rc":[{"batb":[[0,2.84,397.91],[1,1.01,12]],"batl":[[0,8.2,81.39]],"ltp":6.0,"tv":131.67,"id":9626703}]}]}
{"op":"mcm","clk":"4209136710","pt":1631454239879,"mc":[{"id":"1.187548829","rc":[{"batl":[[0,9.4,74.54]],"ltp":6.0,"tv":131.67,"id":9626703}]}]}
{"op":"mcm","clk":"4209161319","pt":1631454369146,"mc":[{"id":"1.187548829","rc":[{"batl":[[0,8.2,81.39]],"ltp":6.0,"tv":131.67,"id":9626703}]}]}
{"op":"mcm","clk":"4209172977","pt":1631454430612,"mc":[{"id":"1.187548829","rc":[{"batl":[[0,7.2,87.62]],"ltp":6.0,"tv":131.67,"id":9626703}]}]}
{"op":"mcm","clk":"4209176854","pt":1631454451946,"mc":[{"id":"1.187548829","rc":[{"batl":[[0,8.2,81.39]],"ltp":6.0,"tv":131.67,"id":9626703}]}]}
{"op":"mcm","clk":"4209182088","pt":1631454478984,"mc":[{"id":"1.187548829","rc":[{"batl":[[0,9.4,74.54]],"ltp":6.0,"tv":131.67,"id":9626703}]}]}
{"op":"mcm","clk":"4209187718","pt":1631454510310,"mc":[{"id":"1.187548829","rc":[{"batl":[[0,7.2,87.62]],"ltp":6.0,"tv":131.67,"id":9626703}]}]}
{"op":"mcm","clk":"4209198950","pt":1631454570860,"mc":[{"id":"1.187548829","rc":[{"batl":[[0,9.4,74.54]],"ltp":6.0,"tv":131.67,"id":9626703}]}]}
{"op":"mcm","clk":"4209205068","pt":1631454601221,"mc":[{"id":"1.187548829","rc":[{"batl":[[0,7.2,87.62]],"ltp":6.0,"tv":131.67,"id":9626703}]}]}
{"op":"mcm","clk":"4209207337","pt":1631454612632,"mc":[{"id":"1.187548829","rc":[{"batl":[[0,6,100.65]],"ltp":6.0,"tv":131.67,"id":9626703}]}]}
{"op":"mcm","clk":"4209214297","pt":1631454650571,"mc":[{"id":"1.187548829","rc":[{"batl":[[0,7.2,87.62]],"ltp":6.0,"tv":131.67,"id":9626703}]}]}
{"op":"mcm","clk":"4209217386","pt":1631454668193,"mc":[{"id":"1.187548829","rc":[{"batl":[[0,6,100.65]],"ltp":6.0,"tv":131.67,"id":9626703}]}]}
{"op":"mcm","clk":"4209221803","pt":1631454693639,"mc":[{"id":"1.187548829","rc":[{"batb":[[0,1.01,12],[1,1.01,0]],"ltp":6.0,"tv":131.67,"id":9626703}]}]}
{"op":"mcm","clk":"4209222833","pt":1631454699442,"mc":[{"id":"1.187548829","rc":[{"batb":[[0,2.38,407.67],[1,1.01,12]],"batl":[[0,5.3,112.48]],"ltp":6.0,"tv":131.67,"id":9626703}]}]}
{"op":"mcm","clk":"4209226399","pt":1631454719963,"mc":[{"id":"1.187548829","rc":[{"batb":[[0,1.01,12],[1,1.01,0]],"ltp":6.0,"tv":131.67,"id":9626703}]}]}
{"op":"mcm","clk":"4209227620","pt":1631454726851,"mc":[{"id":"1.187548829","rc":[{"batb":[[0,2.52,405.91],[1,1.01,12]],"batl":[[0,6,100.65]],"ltp":6.0,"tv":131.67,"id":9626703}]}]}
{"op":"mcm","clk":"4209229749","pt":1631454739326,"mc":[{"id":"1.187548829","rc":[{"batb":[[0,1.01,12],[1,1.01,0]],"ltp":6.0,"tv":131.67,"id":9626703}]}]}
{"op":"mcm","clk":"4209230841","pt":1631454745701,"mc":[{"id":"1.187548829","rc":[{"batb":[[0,2.72,401.45],[1,1.01,12]],"batl":[[0,7.2,87.62]],"ltp":6.0,"tv":131.67,"id":9626703}]}]}
{"op":"mcm","clk":"4209236703","pt":1631454780724,"mc":[{"id":"1.187548829","rc":[{"batl":[[0,6,100.65]],"ltp":6.0,"tv":131.67,"id":9626703}]}]}
{"op":"mcm","clk":"4209241986","pt":1631454811317,"mc":[{"id":"1.187548829","rc":[{"batl":[[0,7.2,87.62]],"ltp":6.0,"tv":131.67,"id":9626703}]}]}
{"op":"mcm","clk":"4209247679","pt":1631454847670,"mc":[{"id":"1.187548829","rc":[{"batb":[[0,1.01,12],[1,1.01,0]],"ltp":6.0,"tv":131.67,"id":9626703}]}]}
{"op":"mcm","clk":"4209248619","pt":1631454853658,"mc":[{"id":"1.187548829","rc":[{"batb":[[0,2.98,396.1],[1,1.01,12]],"batl":[[0,9.4,74.54]],"ltp":6.0,"tv":131.67,"id":9626703}]}]}
{"op":"mcm","clk":"4209265580","pt":1631454968812,"mc":[{"id":"1.187548829","rc":[{"batl":[[0,12,65.12]],"ltp":6.0,"tv":131.67,"id":9626703}]}]}
{"op":"mcm","clk":"4209268217","pt":1631454985117,"mc":[{"id":"1.187548829","rc":[{"batb":[[0,1.01,12],[1,1.01,0]],"ltp":6.0,"tv":131.67,"id":9626703}]}]}
{"op":"mcm","clk":"4209269117","pt":1631454990954,"mc":[{"id":"1.187548829","rc":[{"batb":[[0,3.3,393.42],[1,1.01,12]],"ltp":6.0,"tv":131.67,"id":9626703}]}]}
{"op":"mcm","clk":"4209269936","pt":1631454995938,"mc":[{"id":"1.187548829","rc":[{"batl":[[0,15.5,57.69]],"ltp":6.0,"tv":131.67,"id":9626703}]}]}
{"op":"mcm","clk":"4209275019","pt":1631455028149,"mc":[{"id":"1.187548829","rc":[{"batl":[[0,21,52.1]],"ltp":6.0,"tv":131.67,"id":9626703}]}]}
{"op":"mcm","clk":"4209278793","pt":1631455051387,"mc":[{"id":"1.187548829","rc":[{"batl":[[0,18,54.57]],"ltp":6.0,"tv":131.67,"id":9626703}]}]}
{"op":"mcm","clk":"4209280650","pt":1631455063198,"mc":[{"id":"1.187548829","rc":[{"batb":[[0,1.01,12],[1,1.01,0]],"ltp":6.0,"tv":131.67,"id":9626703}]}]}
{"op":"mcm","clk":"4209281606","pt":1631455069523,"mc":[{"id":"1.187548829","rc":[{"batb":[[0,3.7,389.95],[1,1.01,12]],"batl":[[0,23,50.07]],"ltp":6.0,"tv":131.67,"id":9626703}]}]}
{"op":"mcm","clk":"4209291074","pt":1631455129785,"mc":[{"id":"1.187548829","rc":[{"batl":[[0,18,54.57]],"ltp":6.0,"tv":131.67,"id":9626703}]}]}
{"op":"mcm","clk":"4209292441","pt":1631455137903,"mc":[{"id":"1.187548829","rc":[{"batl":[[0,13.5,61.74]],"ltp":6.0,"tv":131.67,"id":9626703}]}]}
{"op":"mcm","clk":"4209296032","pt":1631455159290,"mc":[{"id":"1.187548829","rc":[{"batl":[[0,12,65.12]],"ltp":6.0,"tv":131.67,"id":9626703}]}]}
{"op":"mcm","clk":"4209303039","pt":1631455200709,"mc":[{"id":"1.187548829","rc":[{"batl":[[0,10.5,69.28]],"ltp":6.0,"tv":131.67,"id":9626703}]}]}
{"op":"mcm","clk":"4209323697","pt":1631455309502,"mc":[{"id":"1.187548829","rc":[{"batl":[[0,12,65.12]],"ltp":6.0,"tv":131.67,"id":9626703}]}]}
{"op":"mcm","clk":"4209327085","pt":1631455325717,"mc":[{"id":"1.187548829","rc":[{"batl":[[0,15.5,57.69]],"ltp":6.0,"tv":131.67,"id":9626703}]}]}
{"op":"mcm","clk":"4209331653","pt":1631455349030,"mc":[{"id":"1.187548829","rc":[{"batl":[[0,21,52.1]],"ltp":6.0,"tv":131.67,"id":9626703}]}]}
{"op":"mcm","clk":"4209336546","pt":1631455373163,"mc":[{"id":"1.187548829","rc":[{"batl":[[0,34,45.41]],"ltp":6.0,"tv":131.67,"id":9626703}]}]}
{"op":"mcm","clk":"4209343245","pt":1631455408412,"mc":[{"id":"1.187548829","rc":[{"batl":[[0,46,42.6]],"ltp":6.0,"tv":131.67,"id":9626703}]}]}
{"op":"mcm","clk":"4209349980","pt":1631455441320,"mc":[{"id":"1.187548829","rc":[{"batb":[[0,1.01,12],[1,1.01,0]],"ltp":6.0,"tv":131.67,"id":9626703}]}]}
{"op":"mcm","clk":"4209351140","pt":1631455446856,"mc":[{"id":"1.187548829","rc":[{"batl":[[0,85,39.17]],"ltp":6.0,"tv":131.67,"id":9626703}]}]}
{"op":"mcm","clk":"4209351165","pt":1631455446990,"mc":[{"id":"1.187548829","rc":[{"batb":[[0,4.2,388.81],[1,1.01,12]],"ltp":6.0,"tv":131.67,"id":9626703}]}]}
{"op":"mcm","clk":"4209352860","pt":1631455455462,"mc":[{"id":"1.187548829","rc":[{"batb":[[0,1.01,12],[1,1.01,0]],"ltp":6.0,"tv":131.67,"id":9626703}]}]}
{"op":"mcm","clk":"4209356357","pt":1631455472977,"mc":[{"id":"1.187548829","rc":[{"batb":[[0,4,392.22],[1,1.01,12]],"batl":[[0,46,42.6]],"ltp":6.0,"tv":131.67,"id":9626703}]}]}
{"op":"mcm","clk":"4209358193","pt":1631455482797,"mc":[{"id":"1.187548829","rc":[{"batb":[[0,1.01,12],[1,1.01,0]],"ltp":6.0,"tv":131.67,"id":9626703}]}]}
{"op":"mcm","clk":"4209360380","pt":1631455494159,"mc":[{"id":"1.187548829","rc":[{"batb":[[0,3.75,392.14],[1,1.01,12]],"batl":[[0,26,48.39]],"ltp":6.0,"tv":131.67,"id":9626703}]}]}
{"op":"mcm","clk":"4209366048","pt":1631455522447,"mc":[{"id":"1.187548829","rc":[{"batl":[[0,46,42.6]],"ltp":6.0,"tv":131.67,"id":9626703}]}]}
{"op":"mcm","clk":"4209367381","pt":1631455529246,"mc":[{"id":"1.187548829","rc":[{"batb":[[0,1.01,12],[1,1.01,0]],"ltp":6.0,"tv":131.67,"id":9626703}]}]}
{"op":"mcm","clk":"4209370654","pt":1631455546579,"mc":[{"id":"1.187548829","rc":[{"batb":[[0,3.7,389.95],[1,1.01,12]],"batl":[[0,23,50.07]],"ltp":6.0,"tv":131.67,"id":9626703}]}]}
{"op":"mcm","clk":"4209382270","pt":1631455604847,"mc":[{"id":"1.187548829","rc":[{"batl":[[0,46,42.6]],"ltp":6.0,"tv":131.67,"id":9626703}]}]}
{"op":"mcm","clk":"4209383834","pt":1631455612217,"mc":[{"id":"1.187548829","rc":[{"batb":[[0,1.01,12],[1,1.01,0]],"ltp":6.0,"tv":131.67,"id":9626703}]}]}
{"op":"mcm","clk":"4209385943","pt":1631455622295,"mc":[{"id":"1.187548829","rc":[{"batb":[[0,4.4,384.58],[1,1.01,12]],"batl":[[0,340,36.27]],"ltp":6.0,"tv":131.67,"id":9626703}]}]}
{"op":"mcm","clk":"4209389365","pt":1631455638471,"mc":[{"id":"1.187548829","rc":[{"batb":[[0,1.01,12],[1,1.01,0]],"ltp":6.0,"tv":131.67,"id":9626703}]}]}
{"op":"mcm","clk":"4209391890","pt":1631455650223,"mc":[{"id":"1.187548829","rc":[{"batb":[[0,4,392.22],[1,1.01,12]],"batl":[[0,46,42.6]],"ltp":6.0,"tv":131.67,"id":9626703}]}]}
{"op":"mcm","clk":"4209392826","pt":1631455654630,"mc":[{"id":"1.187548829","rc":[{"batb":[[0,1.01,12],[1,1.01,0]],"ltp":6.0,"tv":131.67,"id":9626703}]}]}
{"op":"mcm","clk":"4209395444","pt":1631455666558,"mc":[{"id":"1.187548829","rc":[{"batb":[[0,4.4,384.58],[1,1.01,12]],"batl":[[0,340,36.27]],"ltp":6.0,"tv":131.67,"id":9626703}]}]}
{"op":"mcm","clk":"4209397725","pt":1631455676851,"mc":[{"id":"1.187548829","rc":[{"batb":[[0,1.01,12],[1,1.01,0]],"ltp":6.0,"tv":131.67,"id":9626703}]}]}
{"op":"mcm","clk":"4209400934","pt":1631455690781,"mc":[{"id":"1.187548829","rc":[{"batb":[[0,4,392.22],[1,1.01,12]],"batl":[[0,46,42.6]],"ltp":6.0,"tv":131.67,"id":9626703}]}]}
{"op":"mcm","clk":"4209402580","pt":1631455698194,"mc":[{"id":"1.187548829","rc":[{"batb":[[0,1.01,12],[1,1.01,0]],"ltp":6.0,"tv":131.67,"id":9626703}]}]}
{"op":"mcm","clk":"4209406267","pt":1631455715902,"mc":[{"id":"1.187548829","rc":[{"batl":[[0,340,36.27]],"ltp":6.0,"tv":131.67,"id":9626703}]}]}
{"op":"mcm","clk":"4209406277","pt":1631455716004,"mc":[{"id":"1.187548829","rc":[{"batb":[[0,4.4,384.58],[1,1.01,12]],"ltp":6.0,"tv":131.67,"id":9626703}]}]}
{"op":"mcm","clk":"4209409893","pt":1631455733515,"mc":[{"id":"1.187548829","rc":[{"batb":[[0,1.01,12],[1,1.01,0]],"ltp":6.0,"tv":131.67,"id":9626703}]}]}
{"op":"mcm","clk":"4209430147","pt":1631455826678,"mc":[{"id":"1.187548829","marketDefinition":{"bspMarket":false,"turnInPlayEnabled":true,"persistenceEnabled":true,"marketBaseRate":5.0,"eventId":"30894999","eventTypeId":"2","numberOfWinners":1,"bettingType":"ODDS","marketType":"MATCH_ODDS","marketTime":"2021-09-12T12:51:32.000Z","suspendTime":"2021-09-12T12:51:32.000Z","bspReconciled":false,"complete":true,"inPlay":true,"crossMatching":true,"runnersVoidable":false,"numberOfActiveRunners":2,"betDelay":5,"status":"SUSPENDED","runners":[{"status":"ACTIVE","sortPriority":1,"id":9626703,"name":"M Di Giuseppe"},{"status":"ACTIVE","sortPriority":2,"id":9589287,"name":"A Carreras"}],"regulators":["MR_INT"],"countryCode":"GB","discountAllowed":true,"timezone":"GMT","openDate":"2021-09-12T12:51:32.000Z","version":4028543055,"name":"Match Odds","eventName":"M Di Giuseppe v A Carreras"}}]}
{"op":"mcm","clk":"4209431137","pt":1631455831570,"mc":[{"id":"1.187548829","tv":0.0}]}
{"op":"mcm","clk":"4209431361","pt":1631455832715,"mc":[{"id":"1.187548829","marketDefinition":{"bspMarket":false,"turnInPlayEnabled":true,"persistenceEnabled":true,"marketBaseRate":5.0,"eventId":"30894999","eventTypeId":"2","numberOfWinners":1,"bettingType":"ODDS","marketType":"MATCH_ODDS","marketTime":"2021-09-12T12:51:32.000Z","suspendTime":"2021-09-12T12:51:32.000Z","bspReconciled":false,"complete":true,"inPlay":true,"crossMatching":false,"runnersVoidable":false,"numberOfActiveRunners":0,"betDelay":5,"status":"CLOSED","settledTime":"2021-09-12T14:10:30.000Z","runners":[{"status":"LOSER","sortPriority":1,"id":9626703,"name":"M Di Giuseppe"},{"status":"WINNER","sortPriority":2,"id":9589287,"name":"A Carreras"}],"regulators":["MR_INT"],"countryCode":"GB","discountAllowed":true,"timezone":"GMT","openDate":"2021-09-12T12:51:32.000Z","version":4028543083,"name":"Match Odds","eventName":"M Di Giuseppe v A Carreras"}}]}
