{"op":"mcm","clk":"4224628877","pt":1631436373680,"mc":[{"id":"1.187551081","marketDefinition":{"bspMarket":false,"turnInPlayEnabled":true,"persistenceEnabled":true,"marketBaseRate":5.0,"eventId":"30895117","eventTypeId":"2","numberOfWinners":1,"bettingType":"ODDS","marketType":"MATCH_ODDS","marketTime":"2021-09-12T13:30:00.000Z","suspendTime":"2021-09-12T13:30:00.000Z","bspReconciled":false,"complete":true,"inPlay":false,"crossMatching":false,"runnersVoidable":false,"numberOfActiveRunners":2,"betDelay":0,"status":"OPEN","runners":[{"status":"ACTIVE","sortPriority":1,"id":7445998,"name":"Ekaterina Yashina"},{"status":"ACTIVE","sortPriority":2,"id":9629022,"name":"Susan Bandecchi"}],"regulators":["MR_INT"],"discountAllowed":false,"timezone":"UTC","openDate":"2021-09-12T13:30:00.000Z","version":4027558904,"name":"Match Odds","eventName":"Eka Yashina v Bandecchi"}}]}
{"op":"mcm","clk":"4224628995","pt":1631436374671,"mc":[{"id":"1.187551081","marketDefinition":{"bspMarket":false,"turnInPlayEnabled":true,"persistenceEnabled":true,"marketBaseRate":5.0,"eventId":"30895117","eventTypeId":"2","numberOfWinners":1,"bettingType":"ODDS","marketType":"MATCH_ODDS","marketTime":"2021-09-12T13:30:00.000Z","suspendTime":"2021-09-12T13:30:00.000Z","bspReconciled":false,"complete":true,"inPlay":false,"crossMatching":false,"runnersVoidable":false,"numberOfActiveRunners":2,"betDelay":0,"status":"OPEN","runners":[{"status":"ACTIVE","sortPriority":1,"id":7445998,"name":"Ekaterina Yashina"},{"status":"ACTIVE","sortPriority":2,"id":9629022,"name":"Susan Bandecchi"}],"regulators":["MR_INT"],"discountAllowed":false,"timezone":"UTC","openDate":"2021-09-12T13:30:00.000Z","version":4027558904,"name":"Match Odds","eventName":"Eka Yashina v Bandecchi"}}]}
{"op":"mcm","clk":"4224629231","pt":1631436376682,"mc":[{"id":"1.187551081","marketDefinition":{"bspMarket":false,"turnInPlayEnabled":true,"persistenceEnabled":true,"marketBaseRate":5.0,"eventId":"30895117","eventTypeId":"2","numberOfWinners":1,"bettingType":"ODDS","marketType":"MATCH_ODDS","marketTime":"2021-09-12T13:30:00.000Z","suspendTime":"2021-09-12T13:30:00.000Z","bspReconciled":false,"complete":true,"inPlay":false,"crossMatching":false,"runnersVoidable":false,"numberOfActiveRunners":2,"betDelay":0,"status":"OPEN","runners":[{"status":"ACTIVE","sortPriority":1,"id":7445998,"name":"Ekaterina Yashina"},{"status":"ACTIVE","sortPriority":2,"id":9629022,"name":"Susan Bandecchi"}],"regulators":["MR_INT"],"discountAllowed":true,"timezone":"UTC","openDate":"2021-09-12T13:30:00.000Z","version":4027558904,"name":"Match Odds","eventName":"Eka Yashina v Bandecchi"}}]}
{"op":"mcm","clk":"4224634117","pt":1631436424268,"mc":[{"id":"1.187551081","rc":[{"batb":[[0,1.01,25]],"ltp":0.0,"tv":0.0,"id":7445998},{"batb":[[0,1.01,25]],"ltp":0.0,"tv":0.0,"id":9629022}]}]}
{"op":"mcm","clk":"4224793561","pt":1631437939613,"mc":[{"id":"1.187551081","rc":[{"batl":[[0,990,2.2]],"ltp":0.0,"tv":0.0,"id":7445998},{"batl":[[0,990,2.2]],"ltp":0.0,"tv":0.0,"id":9629022}]}]}
{"op":"mcm","clk":"4224924025","pt":1631439073636,"mc":[{"id":"1.187551081","rc":[{"batl":[[0,2,80],[1,990,2.2]],"ltp":0.0,"tv":0.0,"id":9629022}]}]}
{"op":"mcm","clk":"4225075828","pt":1631440317728,"mc":[{"id":"1.187551081","rc":[{"batl":[[0,95,48.37],[1,990,2.2]],"ltp":0.0,"tv":0.0,"id":7445998},{"batl":[[1,29,48.37],[2,990,2.2]],"ltp":0.0,"tv":0.0,"id":9629022}]}]}
{"op":"mcm","clk":"4225077004","pt":1631440326604,"mc":[{"id":"1.187551081","marketDefinition":{"bspMarket":false,"turnInPlayEnabled":true,"persistenceEnabled":true,"marketBaseRate":5.0,"eventId":"30895117","eventTypeId":"2","numberOfWinners":1,"bettingType":"ODDS","marketType":"MATCH_ODDS","marketTime":"2021-09-12T13:30:00.000Z","suspendTime":"2021-09-12T13:30:00.000Z","bspReconciled":false,"complete":true,"inPlay":false,"crossMatching":true,"runnersVoidable":false,"numberOfActiveRunners":2,"betDelay":0,"status":"OPEN","runners":[{"status":"ACTIVE","sortPriority":1,"id":7445998,"name":"Ekaterina Yashina"},{"status":"ACTIVE","sortPriority":2,"id":9629022,"name":"Susan Bandecchi"}],"regulators":["MR_INT"],"discountAllowed":true,"timezone":"UTC","openDate":"2021-09-12T13:30:00.000Z","version":4027558904,"name":"Match Odds","eventName":"Eka Yashina v Bandecchi"}}]}
{"op":"mcm","clk":"4225173166","pt":1631441050039,"mc":[{"id":"1.187551081","rc":[{"batb":[[0,3.75,12.29],[1,1.01,25]],"ltp":0.0,"tv":0.0,"id":7445998},{"batb":[[0,1.25,135.27],[1,1.01,25]],"ltp":0.0,"tv":0.0,"id":9629022}]}]}
{"op":"mcm","clk":"4225190434","pt":1631441161333,"mc":[{"id":"1.187551081","rc":[{"batb":[[0,4,11.27]],"ltp":0.0,"tv":0.0,"id":7445998},{"batb":[[0,1.22,153.72]],"ltp":0.0,"tv":0.0,"id":9629022}]}]}
{"op":"mcm","clk":"4225223532","pt":1631441384201,"mc":[{"id":"1.187551081","rc":[{"batb":[[0,4.5,10]],"ltp":0.0,"tv":0.0,"id":7445998},{"batb":[[0,1.2,169.09]],"ltp":0.0,"tv":0.0,"id":9629022}]}]}
{"op":"mcm","clk":"4225267561","pt":1631441682703,"mc":[{"id":"1.187551081","rc":[{"batb":[[0,5,10]],"ltp":0.0,"tv":0.0,"id":7445998},{"batb":[[0,1.17,198.93]],"ltp":0.0,"tv":0.0,"id":9629022}]}]}
{"op":"mcm","clk":"4225316570","pt":1631442006689,"mc":[{"id":"1.187551081","rc":[{"batb":[[0,5.5,10]],"ltp":0.0,"tv":0.0,"id":7445998},{"batb":[[0,1.14,241.56]],"ltp":0.0,"tv":0.0,"id":9629022}]}]}
{"op":"mcm","clk":"4225347475","pt":1631442218145,"mc":[{"id":"1.187551081","rc":[{"batl":[[0,1.99,3.42],[1,2,80],[2,29,48.37]],"ltp":0.0,"tv":0.0,"id":9629022}]}]}
{"op":"mcm","clk":"4225357083","pt":1631442284830,"mc":[{"id":"1.187551081","rc":[{"batb":[[0,6,10]],"ltp":0.0,"tv":0.0,"id":7445998},{"batb":[[0,1.13,260.15]],"ltp":0.0,"tv":0.0,"id":9629022}]}]}
{"op":"mcm","clk":"4225396137","pt":1631442583924,"mc":[{"id":"1.187551081","rc":[{"batb":[[0,6.4,10]],"ltp":0.0,"tv":0.0,"id":7445998},{"batb":[[0,1.11,307.45]],"ltp":0.0,"tv":0.0,"id":9629022}]}]}
{"op":"mcm","clk":"4225491503","pt":1631443181342,"mc":[{"id":"1.187551081","rc":[{"trd":[[6.4,3.79]],"batb":[[0,6.4,6.21]],"ltp":6.4,"tv":3.79,"id":7445998},{"trd":[[1.19,20.38]],"ltp":1.19,"tv":20.37,"id":9629022}],"tv":24.16}]}
{"op":"mcm","clk":"4225492257","pt":1631443185905,"mc":[{"id":"1.187551081","rc":[{"batb":[[0,6.4,10]],"ltp":6.4,"tv":3.79,"id":7445998}]}]}
{"op":"mcm","clk":"4225495719","pt":1631443208722,"mc":[{"id":"1.187551081","rc":[{"trd":[[6.4,7.58]],"batb":[[0,6.4,6.21]],"ltp":6.4,"tv":7.58,"id":7445998},{"trd":[[1.19,40.75]],"ltp":1.19,"tv":40.75,"id":9629022}],"tv":48.33}]}
{"op":"mcm","clk":"4225496126","pt":1631443211236,"mc":[{"id":"1.187551081","rc":[{"batb":[[0,6.4,10]],"ltp":6.4,"tv":7.58,"id":7445998}]}]}
{"op":"mcm","clk":"4225501861","pt":1631443247218,"mc":[{"id":"1.187551081","rc":[{"trd":[[6.4,11.37]],"batb":[[0,6.4,6.21]],"ltp":6.4,"tv":11.37,"id":7445998},{"trd":[[1.19,61.13]],"ltp":1.19,"tv":61.13,"id":9629022}],"tv":72.5}]}
{"op":"mcm","clk":"4225502685","pt":1631443251741,"mc":[{"id":"1.187551081","rc":[{"batb":[[0,6.4,10]],"ltp":6.4,"tv":11.37,"id":7445998}]}]}
{"op":"mcm","clk":"4225510271","pt":1631443297733,"mc":[{"id":"1.187551081","rc":[{"trd":[[6.4,13.26]],"batb":[[0,6.4,8.11]],"ltp":6.4,"tv":13.26,"id":7445998},{"trd":[[1.19,71.32]],"ltp":1.19,"tv":71.32,"id":9629022}],"tv":84.58}]}
{"op":"mcm","clk":"4225511054","pt":1631443302350,"mc":[{"id":"1.187551081","rc":[{"batb":[[0,6.4,10]],"ltp":6.4,"tv":13.26,"id":7445998}]}]}
{"op":"mcm","clk":"4225519435","pt":1631443352363,"mc":[{"id":"1.187551081","rc":[{"trd":[[6.4,14.09]],"batb":[[0,6.4,9.17]],"ltp":6.4,"tv":14.09,"id":7445998},{"trd":[[1.19,75.8]],"ltp":1.19,"tv":75.8,"id":9629022}],"tv":89.89}]}
{"op":"mcm","clk":"4225519516","pt":1631443352838,"mc":[{"id":"1.187551081","rc":[{"batb":[[0,6.4,10]],"ltp":6.4,"tv":14.09,"id":7445998}]}]}
{"op":"mcm","clk":"4225524383","pt":1631443383133,"mc":[{"id":"1.187551081","rc":[{"batb":[[0,5.5,10]],"ltp":6.4,"tv":14.09,"id":7445998},{"batb":[[0,1.14,241.56]],"ltp":1.19,"tv":75.8,"id":9629022}]}]}
{"op":"mcm","clk":"4225526616","pt":1631443398377,"mc":[{"id":"1.187551081","rc":[{"batb":[[0,5,10]],"ltp":6.4,"tv":14.09,"id":7445998},{"batb":[[0,1.17,198.93]],"ltp":1.19,"tv":75.8,"id":9629022}]}]}
{"op":"mcm","clk":"4225534029","pt":1631443445454,"mc":[{"id":"1.187551081","rc":[{"batb":[[0,1.24,19.64],[1,1.17,198.93],[2,1.01,25]],"ltp":1.19,"tv":75.8,"id":9629022}]}]}
{"op":"mcm","clk":"4225534648","pt":1631443449482,"mc":[{"id":"1.187551081","rc":[{"trd":[[5,4.91]],"batb":[[0,5,5.09]],"ltp":5.0,"tv":19.0,"id":7445998},{"trd":[[1.25,19.64]],"batb":[[0,1.17,198.93],[1,1.01,25],[2,1.01,0]],"ltp":1.25,"tv":95.44,"id":9629022}],"tv":114.44}]}
{"op":"mcm","clk":"4225535385","pt":1631443454076,"mc":[{"id":"1.187551081","rc":[{"batb":[[0,5,10]],"ltp":5.0,"tv":19.0,"id":7445998}]}]}
{"op":"mcm","clk":"4225538045","pt":1631443471136,"mc":[{"id":"1.187551081","rc":[{"trd":[[5,9.82]],"batb":[[0,5,5.09]],"ltp":5.0,"tv":23.91,"id":7445998},{"trd":[[1.25,39.29]],"ltp":1.25,"tv":115.09,"id":9629022}],"tv":139.0}]}
{"op":"mcm","clk":"4225538593","pt":1631443474339,"mc":[{"id":"1.187551081","rc":[{"batb":[[0,5,10]],"ltp":5.0,"tv":23.91,"id":7445998}]}]}
{"op":"mcm","clk":"4225541347","pt":1631443491719,"mc":[{"id":"1.187551081","rc":[{"trd":[[5,12.28]],"batb":[[0,5,7.54]],"ltp":5.0,"tv":26.36,"id":7445998},{"trd":[[1.25,49.11]],"ltp":1.25,"tv":124.91,"id":9629022}],"tv":151.28}]}
{"op":"mcm","clk":"4225541824","pt":1631443494602,"mc":[{"id":"1.187551081","rc":[{"batb":[[0,5,10]],"ltp":5.0,"tv":26.36,"id":7445998}]}]}
{"op":"mcm","clk":"4225586105","pt":1631443700243,"mc":[{"id":"1.187551081","rc":[{"trd":[[5,31.06]],"batb":[[0,1.01,25.61],[1,1.01,0]],"ltp":5.0,"tv":45.15,"id":7445998}],"tv":170.06}]}
{"op":"mcm","clk":"4225586419","pt":1631443702172,"mc":[{"id":"1.187551081","rc":[{"batb":[[0,1.01,25]],"ltp":5.0,"tv":45.15,"id":7445998}]}]}
{"op":"mcm","clk":"4225595054","pt":1631443756536,"mc":[{"id":"1.187551081","rc":[{"batb":[[0,1.02,15.37],[1,1.01,25]],"ltp":5.0,"tv":45.15,"id":7445998}]}]}
{"op":"mcm","clk":"4225604162","pt":1631443813698,"mc":[{"id":"1.187551081","rc":[{"batb":[[0,1.22,153.72]],"ltp":1.25,"tv":124.91,"id":9629022}]}]}
{"op":"mcm","clk":"4225617935","pt":1631443904751,"mc":[{"id":"1.187551081","rc":[{"batb":[[0,1.25,135.27]],"ltp":1.25,"tv":124.91,"id":9629022}]}]}
{"op":"mcm","clk":"4225624997","pt":1631443956285,"mc":[{"id":"1.187551081","rc":[{"batb":[[0,1.28,28.1],[1,1.25,135.27],[2,1.01,25]],"ltp":1.25,"tv":124.91,"id":9629022}]}]}
{"op":"mcm","clk":"4225675564","pt":1631444361741,"mc":[{"id":"1.187551081","marketDefinition":{"bspMarket":false,"turnInPlayEnabled":true,"persistenceEnabled":true,"marketBaseRate":5.0,"eventId":"30895117","eventTypeId":"2","numberOfWinners":1,"bettingType":"ODDS","marketType":"MATCH_ODDS","marketTime":"2021-09-12T13:30:00.000Z","suspendTime":"2021-09-12T13:30:00.000Z","bspReconciled":false,"complete":true,"inPlay":false,"crossMatching":true,"runnersVoidable":false,"numberOfActiveRunners":2,"betDelay":0,"status":"OPEN","runners":[{"status":"ACTIVE","sortPriority":1,"id":7445998,"name":"Ekaterina Yashina"},{"status":"ACTIVE","sortPriority":2,"id":9629022,"name":"Susan Bandecchi"}],"regulators":["MR_INT"],"discountAllowed":true,"timezone":"UTC","openDate":"2021-09-12T13:30:00.000Z","version":4027818302,"name":"Match Odds","eventName":"Eka Yashina v Bandecchi"}}]}
{"op":"mcm","clk":"4225694170","pt":1631444490817,"mc":[{"id":"1.187551081","rc":[{"batb":[[1,1.01,30]],"ltp":5.0,"tv":45.15,"id":7445998},{"batb":[[2,1.01,30]],"ltp":1.25,"tv":124.91,"id":9629022}]}]}
{"op":"mcm","clk":"4225875576","pt":1631445591715,"mc":[{"id":"1.187551081","rc":[{"batl":[[0,1.98,43.98],[1,1.99,3.42],[2,2,80]],"ltp":1.25,"tv":124.91,"id":9629022}]}]}
{"op":"mcm","clk":"4225876458","pt":1631445597107,"mc":[{"id":"1.187551081","rc":[{"batb":[[0,1.01,30],[1,1.01,0]],"ltp":5.0,"tv":45.15,"id":7445998},{"batl":[[1,2,80],[2,29,48.37]],"ltp":1.25,"tv":124.91,"id":9629022}]}]}
{"op":"mcm","clk":"4225877968","pt":1631445605753,"mc":[{"id":"1.187551081","rc":[{"batb":[[2,1.05,879.5]],"ltp":1.25,"tv":124.91,"id":9629022}]}]}
{"op":"mcm","clk":"4225946353","pt":1631446021657,"mc":[{"id":"1.187551081","rc":[{"batl":[[0,1.79,58.1],[1,1.98,43.98],[2,2,80]],"ltp":1.25,"tv":124.91,"id":9629022}]}]}
{"op":"mcm","clk":"4225963223","pt":1631446125915,"mc":[{"id":"1.187551081","rc":[{"batl":[[0,1.76,43.98],[1,1.79,58.1]],"ltp":1.25,"tv":124.91,"id":9629022}]}]}
{"op":"mcm","clk":"4225977432","pt":1631446203825,"mc":[{"id":"1.187551081","rc":[{"batb":[[0,3.75,13.87],[1,1.01,30]],"ltp":5.0,"tv":45.15,"id":7445998},{"batb":[[1,1.25,180.37]],"ltp":1.25,"tv":124.91,"id":9629022}]}]}
{"op":"mcm","clk":"4226016606","pt":1631446437871,"mc":[{"id":"1.187551081","rc":[{"batl":[[0,1.69,58.1],[1,1.76,43.98]],"ltp":1.25,"tv":124.91,"id":9629022}]}]}
{"op":"mcm","clk":"4226089429","pt":1631446910962,"mc":[{"id":"1.187551081","rc":[{"batl":[[0,1.67,43.98],[1,1.69,58.1]],"ltp":1.25,"tv":124.91,"id":9629022}]}]}
{"op":"mcm","clk":"4226160076","pt":1631447372758,"mc":[{"id":"1.187551081","rc":[{"batl":[[1,2,80],[2,29,48.37]],"ltp":1.25,"tv":124.91,"id":9629022}]}]}
{"op":"mcm","clk":"4226274193","pt":1631448205368,"mc":[{"id":"1.187551081","marketDefinition":{"bspMarket":false,"turnInPlayEnabled":true,"persistenceEnabled":true,"marketBaseRate":5.0,"eventId":"30895117","eventTypeId":"2","numberOfWinners":1,"bettingType":"ODDS","marketType":"MATCH_ODDS","marketTime":"2021-09-12T13:30:00.000Z","suspendTime":"2021-09-12T13:30:00.000Z","bspReconciled":false,"complete":true,"inPlay":false,"crossMatching":true,"runnersVoidable":false,"numberOfActiveRunners":2,"betDelay":0,"status":"OPEN","runners":[{"status":"ACTIVE","sortPriority":1,"id":7445998,"name":"Ekaterina Yashina"},{"status":"ACTIVE","sortPriority":2,"id":9629022,"name":"Susan Bandecchi"}],"regulators":["MR_INT"],"discountAllowed":true,"timezone":"UTC","openDate":"2021-09-12T13:30:00.000Z","version":4028047960,"name":"Match Odds","eventName":"Eka Yashina v Bandecchi"}}]}
{"op":"mcm","clk":"4226278662","pt":1631448229352,"mc":[{"id":"1.187551081","rc":[{"batb":[[0,4,12.71]],"ltp":5.0,"tv":45.15,"id":7445998},{"batb":[[1,1.22,204.96]],"ltp":1.25,"tv":124.91,"id":9629022}]}]}
{"op":"mcm","clk":"4226282962","pt":1631448254608,"mc":[{"id":"1.187551081","rc":[{"trd":[[4.6,7.82]],"batb":[[0,5,2.18]],"ltp":4.6,"tv":52.97,"id":7445998},{"trd":[[1.28,28.1]],"batb":[[0,1.17,265.25],[1,1.05,879.5],[2,1.01,30]],"ltp":1.28,"tv":153.0,"id":9629022}],"tv":205.98}]}
{"op":"mcm","clk":"4226283838","pt":1631448259715,"mc":[{"id":"1.187551081","rc":[{"batb":[[0,5,10]],"ltp":4.6,"tv":52.97,"id":7445998}]}]}
{"op":"mcm","clk":"4226300635","pt":1631448354680,"mc":[{"id":"1.187551081","rc":[{"batb":[[0,1.18,29.05],[1,1.17,265.25],[2,1.05,879.5]],"ltp":1.28,"tv":153.0,"id":9629022}]}]}
{"op":"mcm","clk":"4226314984","pt":1631448435552,"mc":[{"id":"1.187551081","rc":[{"trd":[[6.6,5.2],[7,12.86]],"ltp":7.0,"tv":71.03,"id":7445998},{"trd":[[1.17,76.96],[1.18,29.05]],"batb":[[0,1.17,188.29],[1,1.05,879.5],[2,1.01,30]],"ltp":1.17,"tv":259.01,"id":9629022}],"tv":330.05}]}
{"op":"mcm","clk":"4226315179","pt":1631448436621,"mc":[{"id":"1.187551081","rc":[{"trd":[[7,30.92]],"batb":[[0,5,11.27]],"batl":[[0,7.2,17.55],[1,95,48.37],[2,990,2.2]],"ltp":7.0,"tv":89.09,"id":7445998},{"trd":[[1.17,185.01]],"batb":[[0,1.17,265.25]],"ltp":1.17,"tv":367.06,"id":9629022}],"tv":456.16}]}
{"op":"mcm","clk":"4226315478","pt":1631448438281,"mc":[{"id":"1.187551081","rc":[{"trd":[[1.17,661.42]],"batb":[[0,1.17,27.05]],"ltp":1.17,"tv":843.47,"id":9629022}],"tv":932.57}]}
{"op":"mcm","clk":"4226316055","pt":1631448441844,"mc":[{"id":"1.187551081","rc":[{"batl":[[0,95,48.37],[1,990,2.2],[2,990,0]],"ltp":7.0,"tv":89.09,"id":7445998},{"batb":[[0,1.09,500]],"ltp":1.17,"tv":843.47,"id":9629022}]}]}
{"op":"mcm","clk":"4226322321","pt":1631448477862,"mc":[{"id":"1.187551081","rc":[{"batb":[[0,1.1,439.75],[1,1.09,500]],"ltp":1.17,"tv":843.47,"id":9629022}]}]}
{"op":"mcm","clk":"4226338256","pt":1631448570738,"mc":[{"id":"1.187551081","rc":[{"batb":[[0,1.11,29.05],[1,1.1,439.75],[2,1.09,500]],"ltp":1.17,"tv":843.47,"id":9629022}]}]}
{"op":"mcm","clk":"4226346491","pt":1631448618920,"mc":[{"id":"1.187551081","rc":[{"batb":[[0,5.5,10.02]],"ltp":7.0,"tv":89.09,"id":7445998},{"batb":[[0,1.14,322.09],[1,1.11,29.05],[2,1.1,439.75]],"ltp":1.17,"tv":843.47,"id":9629022}]}]}
{"op":"mcm","clk":"4226351125","pt":1631448644274,"mc":[{"id":"1.187551081","rc":[{"batb":[[0,6,10]],"ltp":7.0,"tv":89.09,"id":7445998},{"batb":[[0,1.13,346.86]],"ltp":1.17,"tv":843.47,"id":9629022}]}]}
{"op":"mcm","clk":"4226358501","pt":1631448684723,"mc":[{"id":"1.187551081","rc":[{"batb":[[0,5.5,10.02]],"ltp":7.0,"tv":89.09,"id":7445998},{"batb":[[0,1.14,322.09]],"ltp":1.17,"tv":843.47,"id":9629022}]}]}
{"op":"mcm","clk":"4226363829","pt":1631448714654,"mc":[{"id":"1.187551081","rc":[{"batl":[[0,1.22,29.05],[1,1.67,43.98],[2,2,80]],"ltp":1.17,"tv":843.47,"id":9629022}]}]}
{"op":"mcm","clk":"4226443295","pt":1631449148811,"mc":[{"id":"1.187551081","rc":[{"batb":[[2,1.07,615.65]],"ltp":1.17,"tv":843.47,"id":9629022}]}]}
{"op":"mcm","clk":"4226501422","pt":1631449521863,"mc":[{"id":"1.187551081","rc":[{"batl":[[0,1.2,29.05]],"ltp":1.17,"tv":843.47,"id":9629022}]}]}
{"op":"mcm","clk":"4226524064","pt":1631449675509,"mc":[{"id":"1.187551081","rc":[{"batb":[[0,7.6,51.45],[1,5.5,10.02],[2,1.01,30]],"ltp":7.0,"tv":89.09,"id":7445998},{"batb":[[2,1.1,262.25]],"ltp":1.17,"tv":843.47,"id":9629022}]}]}
{"op":"mcm","clk":"4226540207","pt":1631449800605,"mc":[{"id":"1.187551081","rc":[{"batb":[[1,7.2,4.13],[2,5.5,10.02]],"ltp":7.0,"tv":89.09,"id":7445998},{"batb":[[1,1.11,114.46]],"ltp":1.17,"tv":843.47,"id":9629022}]}]}
{"op":"mcm","clk":"4226553285","pt":1631449893865,"mc":[{"id":"1.187551081","rc":[{"batl":[[0,1.18,29.05]],"ltp":1.17,"tv":843.47,"id":9629022}]}]}
{"op":"mcm","clk":"4226629108","pt":1631450385918,"mc":[{"id":"1.187551081","rc":[{"batl":[[1,1.4,43.98]],"ltp":1.17,"tv":843.47,"id":9629022}]}]}
{"op":"mcm","clk":"4226721334","pt":1631450920023,"mc":[{"id":"1.187551081","rc":[{"trd":[[1.14,6]],"batb":[[0,1.14,319.09]],"ltp":1.14,"tv":849.47,"id":9629022}],"tv":938.57}]}
{"op":"mcm","clk":"4226721444","pt":1631450920727,"mc":[{"id":"1.187551081","rc":[{"batb":[[0,1.14,322.09]],"ltp":1.14,"tv":849.47,"id":9629022}]}]}
{"op":"mcm","clk":"4226743550","pt":1631451067246,"mc":[{"id":"1.187551081","rc":[{"batl":[[0,1.17,2],[1,1.18,29.05],[2,1.4,43.98]],"ltp":1.14,"tv":849.47,"id":9629022}]}]}
{"op":"mcm","clk":"4226755412","pt":1631451156989,"mc":[{"id":"1.187551081","rc":[{"trd":[[1.14,16]],"batb":[[0,1.14,317.09]],"ltp":1.14,"tv":859.47,"id":9629022}],"tv":948.57}]}
{"op":"mcm","clk":"4226755599","pt":1631451158368,"mc":[{"id":"1.187551081","rc":[{"batb":[[0,1.14,322.09]],"ltp":1.14,"tv":859.47,"id":9629022}]}]}
{"op":"mcm","clk":"4226828264","pt":1631451694351,"mc":[{"id":"1.187551081","rc":[{"batb":[[1,1.13,20.71],[2,1.11,114.46]],"ltp":1.14,"tv":859.47,"id":9629022}]}]}
{"op":"mcm","clk":"4226997499","pt":1631452611332,"mc":[{"id":"1.187551081","rc":[{"batb":[[1,1.13,32.19]],"batl":[[2,1.28,11.48]],"ltp":1.14,"tv":859.47,"id":9629022}]}]}
{"op":"mcm","clk":"4227006687","pt":1631452659594,"mc":[{"id":"1.187551081","rc":[{"batb":[[0,1.15,48.44],[1,1.14,322.09],[2,1.13,32.19]],"ltp":1.14,"tv":859.47,"id":9629022}]}]}
{"op":"mcm","clk":"4227006984","pt":1631452661281,"mc":[{"id":"1.187551081","rc":[{"batb":[[2,1.01,30]],"ltp":7.0,"tv":89.09,"id":7445998},{"trd":[[1.15,96.87]],"batb":[[0,1.13,32.2],[1,1.11,114.46],[2,1.1,262.25]],"ltp":1.15,"tv":956.34,"id":9629022}],"tv":1045.44}]}
{"op":"mcm","clk":"4227007140","pt":1631452662190,"mc":[{"id":"1.187551081","rc":[{"batb":[[1,7.4,4.01],[2,7.2,4.13]],"ltp":7.0,"tv":89.09,"id":7445998},{"batb":[[1,1.11,29.05],[2,1.1,347.66]],"ltp":1.15,"tv":956.34,"id":9629022}]}]}
{"op":"mcm","clk":"4227007774","pt":1631452665996,"mc":[{"id":"1.187551081","rc":[{"batb":[[0,1.14,322.1],[1,1.13,32.19],[2,1.11,29.05]],"ltp":1.15,"tv":956.34,"id":9629022}]}]}
{"op":"mcm","clk":"4227007957","pt":1631452667192,"mc":[{"id":"1.187551081","rc":[{"batb":[[1,7.2,4.13],[2,5.5,10.02]],"ltp":7.0,"tv":89.09,"id":7445998},{"batb":[[2,1.11,114.46]],"ltp":1.15,"tv":956.34,"id":9629022}]}]}
{"op":"mcm","clk":"4227009798","pt":1631452678710,"mc":[{"id":"1.187551081","rc":[{"batb":[[0,1.14,322.09]],"ltp":1.15,"tv":956.34,"id":9629022}]}]}
{"op":"mcm","clk":"4227022076","pt":1631452747132,"mc":[{"id":"1.187551081","rc":[{"batb":[[2,6.4,10]],"ltp":7.0,"tv":89.09,"id":7445998},{"batb":[[0,1.13,32.19],[1,1.11,524.39],[2,1.1,347.66]],"ltp":1.15,"tv":956.34,"id":9629022}]}]}
{"op":"mcm","clk":"4227022429","pt":1631452749332,"mc":[{"id":"1.187551081","rc":[{"batb":[[1,7.4,4.01],[2,7.2,4.13]],"ltp":7.0,"tv":89.09,"id":7445998},{"batb":[[1,1.11,438.98]],"ltp":1.15,"tv":956.34,"id":9629022}]}]}
{"op":"mcm","clk":"4227023642","pt":1631452755969,"mc":[{"id":"1.187551081","rc":[{"batl":[[0,1.17,49.57]],"ltp":1.15,"tv":956.34,"id":9629022}]}]}
{"op":"mcm","clk":"4227026988","pt":1631452774368,"mc":[{"id":"1.187551081","rc":[{"batb":[[1,6.4,10],[2,1.01,30]],"ltp":7.0,"tv":89.09,"id":7445998},{"batb":[[2,1.1,262.25]],"ltp":1.15,"tv":956.34,"id":9629022}]}]}
{"op":"mcm","clk":"4227027165","pt":1631452775258,"mc":[{"id":"1.187551081","rc":[{"batb":[[1,7.4,4.01],[2,6.4,10]],"ltp":7.0,"tv":89.09,"id":7445998},{"batb":[[2,1.1,347.66]],"ltp":1.15,"tv":956.34,"id":9629022}]}]}
{"op":"mcm","clk":"4227037964","pt":1631452843222,"mc":[{"id":"1.187551081","rc":[{"batb":[[1,6.4,10],[2,5.7,31.91]],"ltp":7.0,"tv":89.09,"id":7445998},{"batb":[[2,1.1,262.25]],"ltp":1.15,"tv":956.34,"id":9629022}]}]}
{"op":"mcm","clk":"4227038107","pt":1631452844311,"mc":[{"id":"1.187551081","rc":[{"batb":[[1,7.4,4.01],[2,6.4,10]],"ltp":7.0,"tv":89.09,"id":7445998},{"batb":[[2,1.1,347.66]],"ltp":1.15,"tv":956.34,"id":9629022}]}]}
{"op":"mcm","clk":"4227053056","pt":1631452938749,"mc":[{"id":"1.187551081","rc":[{"trd":[[7.6,1.53]],"batb":[[0,7.6,49.92]],"ltp":7.6,"tv":90.62,"id":7445998},{"trd":[[1.16,10]],"ltp":1.16,"tv":966.34,"id":9629022}],"tv":1056.97}]}
{"op":"mcm","clk":"4227054704","pt":1631452949359,"mc":[{"id":"1.187551081","rc":[{"batl":[[0,14,7.23],[1,95,48.37],[2,990,2.2]],"ltp":7.6,"tv":90.62,"id":7445998}]}]}
{"op":"mcm","clk":"4227055682","pt":1631452955325,"mc":[{"id":"1.187551081","rc":[{"trd":[[8,4.24]],"batl":[[0,8,12.6],[1,14,7.23],[2,95,48.37]],"ltp":8.0,"tv":94.86,"id":7445998},{"batb":[[1,1.11,524.39]],"ltp":1.16,"tv":966.34,"id":9629022}],"tv":1061.21}]}
{"op":"mcm","clk":"4227066208","pt":1631453019718,"mc":[{"id":"1.187551081","rc":[{"batb":[[1,1.11,495.33]],"ltp":1.16,"tv":966.34,"id":9629022}]}]}
{"op":"mcm","clk":"4227102893","pt":1631453247640,"mc":[{"id":"1.187551081","rc":[{"trd":[[8,16.84]],"batb":[[0,8.2,3.56],[1,7.6,49.92],[2,7.4,4.01]],"batl":[[0,14,7.23],[1,95,48.37],[2,990,2.2]],"ltp":8.0,"tv":107.46,"id":7445998},{"trd":[[1.13,188.3],[1.14,104.42]],"batb":[[0,1.11,417.77],[1,1.1,262.25],[2,1.08,85.4]],"batl":[[0,1.13,224.76],[1,1.17,49.57],[2,1.18,29.05]],"ltp":1.13,"tv":1243.07,"id":9629022}],"tv":1350.53}]}
{"op":"mcm","clk":"4227102938","pt":1631453247947,"mc":[{"id":"1.187551081","rc":[{"batb":[[1,7.8,2.66],[2,7.6,49.92]],"ltp":8.0,"tv":107.46,"id":7445998}]}]}
{"op":"mcm","clk":"4227107881","pt":1631453279493,"mc":[{"id":"1.187551081","rc":[{"batb":[[1,8,42.17],[2,7.8,2.66]],"ltp":8.0,"tv":107.46,"id":7445998}]}]}
{"op":"mcm","clk":"4227117565","pt":1631453340183,"mc":[{"id":"1.187551081","rc":[{"batb":[[0,1.11,409.93]],"ltp":1.13,"tv":1243.07,"id":9629022}]}]}
{"op":"mcm","clk":"4227126443","pt":1631453395139,"mc":[{"id":"1.187551081","rc":[{"batl":[[0,10.5,2],[1,14,7.23],[2,95,48.37]],"ltp":8.0,"tv":107.46,"id":7445998},{"batl":[[0,1.13,226.76]],"ltp":1.13,"tv":1243.07,"id":9629022}]}]}
{"op":"mcm","clk":"4227161728","pt":1631453609017,"mc":[{"id":"1.187551081","rc":[{"batl":[[0,1.13,2]],"ltp":1.13,"tv":1243.07,"id":9629022}]}]}
{"op":"mcm","clk":"4227161947","pt":1631453610299,"mc":[{"id":"1.187551081","rc":[{"batb":[[0,8.4,2.66]],"ltp":8.0,"tv":107.46,"id":7445998},{"trd":[[1.11,449.5]],"batb":[[0,1.11,185.19],[2,1.09,85.4]],"ltp":1.11,"tv":1692.56,"id":9629022}],"tv":1800.02}]}
{"op":"mcm","clk":"4227162154","pt":1631453611598,"mc":[{"id":"1.187551081","rc":[{"batb":[[0,1.11,409.93],[2,1.08,85.4]],"ltp":1.11,"tv":1692.56,"id":9629022}]}]}
{"op":"mcm","clk":"4227162332","pt":1631453612791,"mc":[{"id":"1.187551081","rc":[{"batb":[[1,8,45.84]],"ltp":8.0,"tv":107.46,"id":7445998}]}]}
{"op":"mcm","clk":"4227169829","pt":1631453659059,"mc":[{"id":"1.187551081","marketDefinition":{"bspMarket":false,"turnInPlayEnabled":true,"persistenceEnabled":true,"marketBaseRate":5.0,"eventId":"30895117","eventTypeId":"2","numberOfWinners":1,"bettingType":"ODDS","marketType":"MATCH_ODDS","marketTime":"2021-09-12T14:00:00.000Z","suspendTime":"2021-09-12T14:00:00.000Z","bspReconciled":false,"complete":true,"inPlay":false,"crossMatching":true,"runnersVoidable":false,"numberOfActiveRunners":2,"betDelay":0,"status":"OPEN","runners":[{"status":"ACTIVE","sortPriority":1,"id":7445998,"name":"Ekaterina Yashina"},{"status":"ACTIVE","sortPriority":2,"id":9629022,"name":"Susan Bandecchi"}],"regulators":["MR_INT"],"discountAllowed":true,"timezone":"UTC","openDate":"2021-09-12T13:30:00.000Z","version":4028400882,"name":"Match Odds","eventName":"Eka Yashina v Bandecchi"},"rc":[{"batb":[[0,1.11,420.48],[1,1.1,272.89]],"ltp":1.11,"tv":1692.56,"id":9629022}]}]}
{"op":"mcm","clk":"4227170275","pt":1631453661764,"mc":[{"id":"1.187551081","marketDefinition":{"bspMarket":false,"turnInPlayEnabled":true,"persistenceEnabled":true,"marketBaseRate":5.0,"eventId":"30895117","eventTypeId":"2","numberOfWinners":1,"bettingType":"ODDS","marketType":"MATCH_ODDS","marketTime":"2021-09-12T14:00:00.000Z","suspendTime":"2021-09-12T14:00:00.000Z","bspReconciled":false,"complete":true,"inPlay":false,"crossMatching":true,"runnersVoidable":false,"numberOfActiveRunners":2,"betDelay":0,"status":"OPEN","runners":[{"status":"ACTIVE","sortPriority":1,"id":7445998,"name":"Ekaterina Yashina"},{"status":"ACTIVE","sortPriority":2,"id":9629022,"name":"Susan Bandecchi"}],"regulators":["MR_INT"],"discountAllowed":true,"timezone":"UTC","openDate":"2021-09-12T14:00:00.000Z","version":4028400882,"name":"Match Odds","eventName":"Eka Yashina v Bandecchi"}}]}
{"op":"mcm","clk":"4227174935","pt":1631453691039,"mc":[{"id":"1.187551081","rc":[{"batl":[[2,1.18,39.85]],"ltp":1.11,"tv":1692.56,"id":9629022}]}]}
{"op":"mcm","clk":"4227388241","pt":1631455140314,"mc":[{"id":"1.187551081","rc":[{"batb":[[0,1.11,409.93],[1,1.1,262.25]],"ltp":1.11,"tv":1692.56,"id":9629022}]}]}
{"op":"mcm","clk":"4227486398","pt":1631455756228,"mc":[{"id":"1.187551081","marketDefinition":{"bspMarket":false,"turnInPlayEnabled":true,"persistenceEnabled":true,"marketBaseRate":5.0,"eventId":"30895117","eventTypeId":"2","numberOfWinners":1,"bettingType":"ODDS","marketType":"MATCH_ODDS","marketTime":"2021-09-12T14:30:00.000Z","suspendTime":"2021-09-12T14:30:00.000Z","bspReconciled":false,"complete":true,"inPlay":false,"crossMatching":true,"runnersVoidable":false,"numberOfActiveRunners":2,"betDelay":0,"status":"OPEN","runners":[{"status":"ACTIVE","sortPriority":1,"id":7445998,"name":"Ekaterina Yashina"},{"status":"ACTIVE","sortPriority":2,"id":9629022,"name":"Susan Bandecchi"}],"regulators":["MR_INT"],"discountAllowed":true,"timezone":"UTC","openDate":"2021-09-12T14:00:00.000Z","version":4028541101,"name":"Match Odds","eventName":"Eka Yashina v Bandecchi"}}]}
{"op":"mcm","clk":"4227487116","pt":1631455759251,"mc":[{"id":"1.187551081","marketDefinition":{"bspMarket":false,"turnInPlayEnabled":true,"persistenceEnabled":true,"marketBaseRate":5.0,"eventId":"30895117","eventTypeId":"2","numberOfWinners":1,"bettingType":"ODDS","marketType":"MATCH_ODDS","marketTime":"2021-09-12T14:30:00.000Z","suspendTime":"2021-09-12T14:30:00.000Z","bspReconciled":false,"complete":true,"inPlay":false,"crossMatching":true,"runnersVoidable":false,"numberOfActiveRunners":2,"betDelay":0,"status":"OPEN","runners":[{"status":"ACTIVE","sortPriority":1,"id":7445998,"name":"Ekaterina Yashina"},{"status":"ACTIVE","sortPriority":2,"id":9629022,"name":"Susan Bandecchi"}],"regulators":["MR_INT"],"discountAllowed":true,"timezone":"UTC","openDate":"2021-09-12T14:30:00.000Z","version":4028541101,"name":"Match Odds","eventName":"Eka Yashina v Bandecchi"}}]}
{"op":"mcm","clk":"4227630982","pt":1631456549654,"mc":[{"id":"1.187551081","rc":[{"batl":[[1,95,48.37],[2,990,2.2]],"ltp":8.0,"tv":107.46,"id":7445998}]}]}
{"op":"mcm","clk":"4227631097","pt":1631456550257,"mc":[{"id":"1.187551081","rc":[{"batl":[[1,16,7.23],[2,95,48.37]],"ltp":8.0,"tv":107.46,"id":7445998}]}]}
{"op":"mcm","clk":"4227724216","pt":1631457090364,"mc":[{"id":"1.187551081","rc":[{"batb":[[0,8.6,34],[1,8.4,2.66],[2,8,45.84]],"ltp":8.0,"tv":107.46,"id":7445998},{"batb":[[1,1.1,1293.9]],"ltp":1.11,"tv":1692.56,"id":9629022}]}]}
{"op":"mcm","clk":"4227754154","pt":1631457265785,"mc":[{"id":"1.187551081","marketDefinition":{"bspMarket":false,"turnInPlayEnabled":true,"persistenceEnabled":true,"marketBaseRate":5.0,"eventId":"30895117","eventTypeId":"2","numberOfWinners":1,"bettingType":"ODDS","marketType":"MATCH_ODDS","marketTime":"2021-09-12T15:00:00.000Z","suspendTime":"2021-09-12T15:00:00.000Z","bspReconciled":false,"complete":true,"inPlay":false,"crossMatching":true,"runnersVoidable":false,"numberOfActiveRunners":2,"betDelay":0,"status":"OPEN","runners":[{"status":"ACTIVE","sortPriority":1,"id":7445998,"name":"Ekaterina Yashina"},{"status":"ACTIVE","sortPriority":2,"id":9629022,"name":"Susan Bandecchi"}],"regulators":["MR_INT"],"discountAllowed":true,"timezone":"UTC","openDate":"2021-09-12T14:30:00.000Z","version":4028644428,"name":"Match Odds","eventName":"Eka Yashina v Bandecchi"}}]}
{"op":"mcm","clk":"4227754749","pt":1631457268787,"mc":[{"id":"1.187551081","marketDefinition":{"bspMarket":false,"turnInPlayEnabled":true,"persistenceEnabled":true,"marketBaseRate":5.0,"eventId":"30895117","eventTypeId":"2","numberOfWinners":1,"bettingType":"ODDS","marketType":"MATCH_ODDS","marketTime":"2021-09-12T15:00:00.000Z","suspendTime":"2021-09-12T15:00:00.000Z","bspReconciled":false,"complete":true,"inPlay":false,"crossMatching":true,"runnersVoidable":false,"numberOfActiveRunners":2,"betDelay":0,"status":"OPEN","runners":[{"status":"ACTIVE","sortPriority":1,"id":7445998,"name":"Ekaterina Yashina"},{"status":"ACTIVE","sortPriority":2,"id":9629022,"name":"Susan Bandecchi"}],"regulators":["MR_INT"],"discountAllowed":true,"timezone":"UTC","openDate":"2021-09-12T15:00:00.000Z","version":4028644428,"name":"Match Odds","eventName":"Eka Yashina v Bandecchi"}}]}
{"op":"mcm","clk":"4227761449","pt":1631457304849,"mc":[{"id":"1.187551081","rc":[{"batb":[[2,8,3.66]],"ltp":8.0,"tv":107.46,"id":7445998},{"batb":[[1,1.1,1031.65]],"ltp":1.11,"tv":1692.56,"id":9629022}]}]}
{"op":"mcm","clk":"4227785488","pt":1631457442387,"mc":[{"id":"1.187551081","rc":[{"batb":[[0,1.1,1482.57],[1,1.08,85.4],[2,1.07,2142.86]],"ltp":1.11,"tv":1692.56,"id":9629022}]}]}
{"op":"mcm","clk":"4227785542","pt":1631457442690,"mc":[{"id":"1.187551081","rc":[{"batb":[[2,8.2,3.56]],"ltp":8.0,"tv":107.46,"id":7445998}]}]}
{"op":"mcm","clk":"4227787771","pt":1631457454411,"mc":[{"id":"1.187551081","marketDefinition":{"bspMarket":false,"turnInPlayEnabled":true,"persistenceEnabled":true,"marketBaseRate":5.0,"eventId":"30895117","eventTypeId":"2","numberOfWinners":1,"bettingType":"ODDS","marketType":"MATCH_ODDS","marketTime":"2021-09-12T15:00:00.000Z","suspendTime":"2021-09-12T15:00:00.000Z","bspReconciled":false,"complete":true,"inPlay":true,"crossMatching":true,"runnersVoidable":false,"numberOfActiveRunners":2,"betDelay":3,"status":"OPEN","runners":[{"status":"ACTIVE","sortPriority":1,"id":7445998,"name":"Ekaterina Yashina"},{"status":"ACTIVE","sortPriority":2,"id":9629022,"name":"Susan Bandecchi"}],"regulators":["MR_INT"],"discountAllowed":true,"timezone":"UTC","openDate":"2021-09-12T15:00:00.000Z","version":4028658901,"name":"Match Odds","eventName":"Eka Yashina v Bandecchi"},"rc":[{"batb":[[0,1.01,30],[1,8.4,0],[2,8.2,0]],"ltp":8.0,"tv":107.46,"id":7445998},{"batb":[[0,1.01,30],[1,1.08,0],[2,1.07,0]],"batl":[[0,1.17,47.57],[1,1.18,39.85],[2,1.21,80]],"ltp":1.11,"tv":1692.56,"id":9629022}]}]}
{"op":"mcm","clk":"4227788348","pt":1631457457623,"mc":[{"id":"1.187551081","rc":[{"batl":[[0,11,2]],"ltp":8.0,"tv":107.46,"id":7445998},{"batl":[[0,1.14,15],[1,1.17,47.57],[2,1.18,39.85]],"ltp":1.11,"tv":1692.56,"id":9629022}]}]}
{"op":"mcm","clk":"4227788519","pt":1631457458624,"mc":[{"id":"1.187551081","rc":[{"batl":[[1,1.17,62.57]],"ltp":1.11,"tv":1692.56,"id":9629022}]}]}
{"op":"mcm","clk":"4227789046","pt":1631457461302,"mc":[{"id":"1.187551081","rc":[{"batb":[[0,1.8,11.86],[1,1.01,502.85]],"ltp":8.0,"tv":107.46,"id":7445998}]}]}
{"op":"mcm","clk":"4227789590","pt":1631457464531,"mc":[{"id":"1.187551081","rc":[{"batb":[[0,2.2,42.66],[1,2,11.86],[2,1.8,11.86]],"ltp":8.0,"tv":107.46,"id":7445998}]}]}
{"op":"mcm","clk":"4227790182","pt":1631457467811,"mc":[{"id":"1.187551081","rc":[{"batb":[[0,3,5.93],[1,2.6,3.71],[2,2.2,42.66]],"ltp":8.0,"tv":107.46,"id":7445998}]}]}
{"op":"mcm","clk":"4227790752","pt":1631457471271,"mc":[{"id":"1.187551081","rc":[{"batl":[[1,1.17,47.57]],"ltp":1.11,"tv":1692.56,"id":9629022}]}]}
{"op":"mcm","clk":"4227791305","pt":1631457474434,"mc":[{"id":"1.187551081","rc":[{"batb":[[0,7.6,44.63],[1,6.8,57.7],[2,3,5.93]],"ltp":8.0,"tv":107.46,"id":7445998},{"batb":[[0,1.12,875.23],[1,1.1,1023.28],[2,1.01,30]],"ltp":1.11,"tv":1692.56,"id":9629022}]}]}
{"op":"mcm","clk":"4227791531","pt":1631457475639,"mc":[{"id":"1.187551081","rc":[{"batl":[[0,9,2],[1,11,2]],"ltp":8.0,"tv":107.46,"id":7445998}]}]}
{"op":"mcm","clk":"4227791915","pt":1631457477649,"mc":[{"id":"1.187551081","rc":[{"batb":[[0,8,2],[1,7.8,2],[2,7.6,44.63]],"batl":[[1,9.4,2],[2,11,2]],"ltp":8.0,"tv":107.46,"id":7445998},{"trd":[[1.12,1.71]],"batb":[[0,1.12,891.38],[1,1.11,14],[2,1.1,1039.28]],"ltp":1.12,"tv":1694.27,"id":9629022}],"tv":1801.73}]}
{"op":"mcm","clk":"4227792411","pt":1631457480657,"mc":[{"id":"1.187551081","rc":[{"batl":[[0,8.2,3],[1,9,2],[2,9.4,2]],"ltp":8.0,"tv":107.46,"id":7445998}]}]}
{"op":"mcm","clk":"4227792460","pt":1631457480922,"mc":[{"id":"1.187551081","rc":[{"batl":[[0,9,2],[1,9.4,2],[2,11,2]],"ltp":8.0,"tv":107.46,"id":7445998}]}]}
{"op":"mcm","clk":"4227792758","pt":1631457482658,"mc":[{"id":"1.187551081","rc":[{"batb":[[2,6.8,57.7]],"ltp":8.0,"tv":107.46,"id":7445998},{"batb":[[0,1.1,1023.28],[1,1.09,15],[2,1.01,30]],"ltp":1.12,"tv":1694.27,"id":9629022}]}]}
{"op":"mcm","clk":"4227793950","pt":1631457489463,"mc":[{"id":"1.187551081","rc":[{"batb":[[1,6.8,57.7],[2,3,5.93]],"ltp":8.0,"tv":107.46,"id":7445998}]}]}
{"op":"mcm","clk":"4227794530","pt":1631457492646,"mc":[{"id":"1.187551081","rc":[{"batb":[[1,7.8,2],[2,6.8,57.7]],"ltp":8.0,"tv":107.46,"id":7445998}]}]}
{"op":"mcm","clk":"4227795578","pt":1631457498456,"mc":[{"id":"1.187551081","rc":[{"batl":[[0,8.4,1091.34],[1,9.6,2.24]],"ltp":8.0,"tv":107.46,"id":7445998}]}]}
{"op":"mcm","clk":"4227795804","pt":1631457499626,"mc":[{"id":"1.187551081","rc":[{"batb":[[0,6.8,57.7],[1,6.2,69.34],[2,3,5.93]],"ltp":8.0,"tv":107.46,"id":7445998},{"trd":[[1.14,134.42]],"batb":[[0,1.14,733.12],[1,1.12,861.58],[2,1.1,1023.28]],"batl":[[0,1.17,47.57],[1,1.18,39.85],[2,1.21,80]],"ltp":1.14,"tv":1724.27,"id":9629022}],"tv":1831.73}]}
{"op":"mcm","clk":"4227795838","pt":1631457499839,"mc":[{"id":"1.187551081","rc":[{"batb":[[2,1.01,30]],"ltp":1.14,"tv":1724.27,"id":9629022}]}]}
{"op":"mcm","clk":"4227796530","pt":1631457503473,"mc":[{"id":"1.187551081","rc":[{"batb":[[0,6.8,60.7],[1,6.6,2],[2,6.2,69.34]],"batl":[[0,7.4,12.05],[1,8.2,2],[2,11,2]],"ltp":8.0,"tv":107.46,"id":7445998},{"batb":[[0,1.14,748.12],[1,1.13,20],[2,1.12,861.58]],"batl":[[0,1.17,60.57],[1,1.18,256.8]],"ltp":1.14,"tv":1724.27,"id":9629022}]}]}
{"op":"mcm","clk":"4227796561","pt":1631457503720,"mc":[{"id":"1.187551081","rc":[{"batl":[[0,8.2,2],[1,11,2],[2,11,0]],"ltp":8.0,"tv":107.46,"id":7445998},{"batl":[[1,1.18,39.85]],"ltp":1.14,"tv":1724.27,"id":9629022}]}]}
{"op":"mcm","clk":"4227797065","pt":1631457506658,"mc":[{"id":"1.187551081","rc":[{"batb":[[0,6.8,3],[2,6.2,69.17]],"batl":[[0,11,2],[1,11,0]],"ltp":8.0,"tv":107.46,"id":7445998},{"batb":[[0,1.12,861.58],[1,1.01,502.85],[2,1.12,0]],"ltp":1.14,"tv":1724.27,"id":9629022}]}]}
{"op":"mcm","clk":"4227797615","pt":1631457509664,"mc":[{"id":"1.187551081","rc":[{"batb":[[0,7.2,3],[1,6.8,3],[2,6.6,2]],"ltp":8.0,"tv":107.46,"id":7445998},{"batl":[[0,1.16,14],[1,1.17,60.57],[2,1.18,39.85]],"ltp":1.14,"tv":1724.27,"id":9629022}]}]}
{"op":"mcm","clk":"4227798084","pt":1631457512389,"mc":[{"id":"1.187551081","rc":[{"batl":[[1,1.17,1366.87]],"ltp":1.14,"tv":1724.27,"id":9629022}]}]}
{"op":"mcm","clk":"4227798171","pt":1631457512869,"mc":[{"id":"1.187551081","rc":[{"batb":[[1,7,2],[2,6.8,3]],"ltp":8.0,"tv":107.46,"id":7445998},{"batl":[[0,1.16,29.39],[1,1.17,60.57]],"ltp":1.14,"tv":1724.27,"id":9629022}]}]}
{"op":"mcm","clk":"4227799488","pt":1631457521007,"mc":[{"id":"1.187551081","rc":[{"batb":[[2,6.2,69.17]],"ltp":8.0,"tv":107.46,"id":7445998},{"batl":[[0,1.16,14]],"ltp":1.14,"tv":1724.27,"id":9629022}]}]}
{"op":"mcm","clk":"4227799912","pt":1631457523532,"mc":[{"id":"1.187551081","rc":[{"batl":[[1,1.17,47.57]],"ltp":1.14,"tv":1724.27,"id":9629022}]}]}
{"op":"mcm","clk":"4227800094","pt":1631457524601,"mc":[{"id":"1.187551081","rc":[{"batb":[[0,1.15,668.48],[1,1.14,737.48],[2,1.12,861.58]],"ltp":1.14,"tv":1724.27,"id":9629022}]}]}
{"op":"mcm","clk":"4227800108","pt":1631457524712,"mc":[{"id":"1.187551081","rc":[{"batb":[[2,1.01,502.85]],"ltp":1.14,"tv":1724.27,"id":9629022}]}]}
{"op":"mcm","clk":"4227800609","pt":1631457527619,"mc":[{"id":"1.187551081","rc":[{"batl":[[0,9.4,2],[1,11,2]],"ltp":8.0,"tv":107.46,"id":7445998},{"batb":[[2,1.12,15]],"ltp":1.14,"tv":1724.27,"id":9629022}]}]}
{"op":"mcm","clk":"4227800769","pt":1631457528480,"mc":[{"id":"1.187551081","rc":[{"trd":[[6.8,5.71],[7.2,8.26]],"batb":[[0,6.2,69.17],[1,5.9,80.56],[2,3,5.93]],"ltp":6.8,"tv":121.43,"id":7445998},{"trd":[[1.16,24],[1.17,694.61]],"batl":[[0,1.17,14.39],[1,1.18,39.85],[2,1.21,80]],"ltp":1.17,"tv":1771.45,"id":9629022}],"tv":1892.89}]}
{"op":"mcm","clk":"4227800969","pt":1631457529717,"mc":[{"id":"1.187551081","rc":[{"batl":[[1,1.18,10.8]],"ltp":1.17,"tv":1771.45,"id":9629022}]}]}
{"op":"mcm","clk":"4227801271","pt":1631457531497,"mc":[{"id":"1.187551081","rc":[{"batb":[[0,6.8,2],[1,6.6,3],[2,6.2,69.17]],"ltp":6.8,"tv":121.43,"id":7445998},{"batl":[[0,1.17,28.39]],"ltp":1.17,"tv":1771.45,"id":9629022}]}]}
{"op":"mcm","clk":"4227801491","pt":1631457532924,"mc":[{"id":"1.187551081","rc":[{"trd":[[1.15,156.48]],"batb":[[0,1.15,638.67]],"ltp":1.15,"tv":1831.07,"id":9629022}],"tv":1952.5}]}
{"op":"mcm","clk":"4227801863","pt":1631457535129,"mc":[{"id":"1.187551081","rc":[{"batb":[[0,6.6,3],[1,5.9,80.22],[2,3,5.93]],"ltp":6.8,"tv":121.43,"id":7445998},{"batb":[[0,1.14,737.48],[1,1.12,15],[2,1.11,16]],"batl":[[0,1.17,14.39]],"ltp":1.15,"tv":1831.07,"id":9629022}]}]}
{"op":"mcm","clk":"4227802400","pt":1631457538336,"mc":[{"id":"1.187551081","rc":[{"batb":[[1,6.4,2],[2,5.9,80.22]],"ltp":6.8,"tv":121.43,"id":7445998}]}]}
{"op":"mcm","clk":"4227803959","pt":1631457547352,"mc":[{"id":"1.187551081","rc":[{"batl":[[1,11,0]],"ltp":6.8,"tv":121.43,"id":7445998},{"batb":[[2,1.01,502.85]],"ltp":1.15,"tv":1831.07,"id":9629022}]}]}
{"op":"mcm","clk":"4227804164","pt":1631457548638,"mc":[{"id":"1.187551081","rc":[{"batb":[[0,6.8,58.78],[1,6.6,3],[2,6.4,2]],"ltp":6.8,"tv":121.43,"id":7445998},{"batb":[[1,1.12,863.52]],"ltp":1.15,"tv":1831.07,"id":9629022}]}]}
{"op":"mcm","clk":"4227804676","pt":1631457551663,"mc":[{"id":"1.187551081","rc":[{"batb":[[0,6.8,60.78],[2,6.2,72.27]],"ltp":6.8,"tv":121.43,"id":7445998},{"batl":[[0,1.17,30.39]],"ltp":1.15,"tv":1831.07,"id":9629022}]}]}
{"op":"mcm","clk":"4227804804","pt":1631457552353,"mc":[{"id":"1.187551081","rc":[{"batb":[[1,6.2,72.27],[2,3,5.93]],"ltp":6.8,"tv":121.43,"id":7445998}]}]}
{"op":"mcm","clk":"4227805287","pt":1631457554979,"mc":[{"id":"1.187551081","rc":[{"batb":[[1,6.6,3],[2,6.2,72.27]],"ltp":6.8,"tv":121.43,"id":7445998}]}]}
{"op":"mcm","clk":"4227807000","pt":1631457563549,"mc":[{"id":"1.187551081","rc":[{"batb":[[0,6.8,2]],"ltp":6.8,"tv":121.43,"id":7445998},{"batb":[[0,1.12,863.52],[1,1.01,502.85],[2,1.01,0]],"ltp":1.15,"tv":1831.07,"id":9629022}]}]}
{"op":"mcm","clk":"4227807044","pt":1631457563764,"mc":[{"id":"1.187551081","rc":[{"batb":[[0,6.2,72.27],[1,3,5.93],[2,2.6,3.71]],"ltp":6.8,"tv":121.43,"id":7445998},{"batl":[[0,1.17,14.39]],"ltp":1.15,"tv":1831.07,"id":9629022}]}]}
{"op":"mcm","clk":"4227807516","pt":1631457565871,"mc":[{"id":"1.187551081","rc":[{"trd":[[6.8,8.19]],"batl":[[0,9.4,2.28]],"ltp":6.8,"tv":123.9,"id":7445998},{"trd":[[1.17,708.99]],"batl":[[0,1.18,10.8],[1,1.21,80],[2,1.39,19.07]],"ltp":1.17,"tv":1845.46,"id":9629022}],"tv":1969.36}]}
{"op":"mcm","clk":"4227807769","pt":1631457566952,"mc":[{"id":"1.187551081","rc":[{"batb":[[0,6.2,74.27],[1,6,2],[2,3,5.93]],"ltp":6.8,"tv":123.9,"id":7445998},{"batb":[[1,1.11,21],[2,1.01,502.85]],"ltp":1.17,"tv":1845.46,"id":9629022}]}]}
{"op":"mcm","clk":"4227808334","pt":1631457569399,"mc":[{"id":"1.187551081","rc":[{"trd":[[6.8,8.47]],"batl":[[0,9.4,2]],"ltp":6.8,"tv":124.18,"id":7445998},{"trd":[[1.17,710.62]],"ltp":1.17,"tv":1847.09,"id":9629022}],"tv":1971.27}]}
{"op":"mcm","clk":"4227810971","pt":1631457582692,"mc":[{"id":"1.187551081","rc":[{"batb":[[1,3,5.93],[2,2.6,3.71]],"ltp":6.8,"tv":124.18,"id":7445998},{"batb":[[1,1.01,502.85],[2,1.01,0]],"ltp":1.17,"tv":1847.09,"id":9629022}]}]}
{"op":"mcm","clk":"4227811572","pt":1631457585922,"mc":[{"id":"1.187551081","rc":[{"batb":[[1,6,2],[2,3,5.93]],"ltp":6.8,"tv":124.18,"id":7445998},{"batb":[[1,1.11,9],[2,1.01,502.85]],"ltp":1.17,"tv":1847.09,"id":9629022}]}]}
{"op":"mcm","clk":"4227812056","pt":1631457588382,"mc":[{"id":"1.187551081","rc":[{"batb":[[0,1.13,55.61],[1,1.12,863.52],[2,1.11,9]],"ltp":1.17,"tv":1847.09,"id":9629022}]}]}
{"op":"mcm","clk":"4227812680","pt":1631457591581,"mc":[{"id":"1.187551081","rc":[{"batl":[[0,8.8,3],[1,9.4,2]],"ltp":6.8,"tv":124.18,"id":7445998},{"batb":[[0,1.13,67.61]],"ltp":1.17,"tv":1847.09,"id":9629022}]}]}
{"op":"mcm","clk":"4227813626","pt":1631457596653,"mc":[{"id":"1.187551081","rc":[{"batb":[[2,5.4,48.23]],"ltp":6.8,"tv":124.18,"id":7445998},{"batb":[[0,1.16,650.23],[1,1.14,739.83],[2,1.13,67.61]],"ltp":1.17,"tv":1847.09,"id":9629022}]}]}
{"op":"mcm","clk":"4227813950","pt":1631457598465,"mc":[{"id":"1.187551081","rc":[{"batl":[[0,1.18,23.8]],"ltp":1.17,"tv":1847.09,"id":9629022}]}]}
{"op":"mcm","clk":"4227813990","pt":1631457598670,"mc":[{"id":"1.187551081","rc":[{"batb":[[1,5.4,48.23],[2,3,5.93]],"ltp":6.8,"tv":124.18,"id":7445998}]}]}
{"op":"mcm","clk":"4227814597","pt":1631457601870,"mc":[{"id":"1.187551081","rc":[{"batb":[[0,6.4,3],[1,6.2,74.27],[2,5.4,48.23]],"ltp":6.8,"tv":124.18,"id":7445998}]}]}
{"op":"mcm","clk":"4227815033","pt":1631457604157,"mc":[{"id":"1.187551081","rc":[{"batl":[[1,9.4,0]],"ltp":6.8,"tv":124.18,"id":7445998},{"trd":[[1.18,107.43]],"batb":[[0,1.18,10.81],[1,1.16,650.23],[2,1.14,739.83]],"batl":[[0,1.21,80],[1,1.39,19.07],[2,3.8,27.47]],"ltp":1.18,"tv":1925.46,"id":9629022}],"tv":2049.65}]}
{"op":"mcm","clk":"4227815600","pt":1631457607083,"mc":[{"id":"1.187551081","rc":[{"batl":[[0,1.19,13],[1,1.21,80],[2,1.39,19.07]],"ltp":1.18,"tv":1925.46,"id":9629022}]}]}
{"op":"mcm","clk":"4227816684","pt":1631457612998,"mc":[{"id":"1.187551081","rc":[{"batb":[[0,1.18,20.81]],"ltp":1.18,"tv":1925.46,"id":9629022}]}]}
{"op":"mcm","clk":"4227818904","pt":1631457625186,"mc":[{"id":"1.187551081","rc":[{"batb":[[1,6.2,72.27]],"ltp":6.8,"tv":124.18,"id":7445998},{"batb":[[0,1.18,10]],"ltp":1.18,"tv":1925.46,"id":9629022}]}]}
{"op":"mcm","clk":"4227819529","pt":1631457628400,"mc":[{"id":"1.187551081","rc":[{"batb":[[1,6.2,75.27]],"ltp":6.8,"tv":124.18,"id":7445998}]}]}
{"op":"mcm","clk":"4227821402","pt":1631457638490,"mc":[{"id":"1.187551081","rc":[{"trd":[[1.18,115.43]],"batb":[[0,1.18,6]],"ltp":1.18,"tv":1933.46,"id":9629022}],"tv":2057.65}]}
{"op":"mcm","clk":"4227822183","pt":1631457642508,"mc":[{"id":"1.187551081","rc":[{"batb":[[1,6.2,72.27]],"ltp":6.8,"tv":124.18,"id":7445998}]}]}
{"op":"mcm","clk":"4227822377","pt":1631457643586,"mc":[{"id":"1.187551081","rc":[{"batb":[[0,5.4,48.23],[1,3,5.93],[2,2.6,3.71]],"ltp":6.8,"tv":124.18,"id":7445998},{"batb":[[1,1.14,739.83],[2,1.13,12]],"batl":[[0,1.21,80],[1,1.39,19.07],[2,3.8,27.47]],"ltp":1.18,"tv":1933.46,"id":9629022}]}]}
{"op":"mcm","clk":"4227822760","pt":1631457645628,"mc":[{"id":"1.187551081","rc":[{"batb":[[0,6.2,2],[1,5.4,48.23],[2,3,5.93]],"ltp":6.8,"tv":124.18,"id":7445998},{"batb":[[0,1.18,6.05]],"ltp":1.18,"tv":1933.46,"id":9629022}]}]}
{"op":"mcm","clk":"4227822810","pt":1631457645917,"mc":[{"id":"1.187551081","rc":[{"batb":[[0,5.4,48.23],[1,3,5.93],[2,2.6,3.71]],"ltp":6.8,"tv":124.18,"id":7445998}]}]}
{"op":"mcm","clk":"4227822985","pt":1631457646832,"mc":[{"id":"1.187551081","rc":[{"batb":[[0,5.7,2],[1,5.6,2],[2,5.4,48.23]],"ltp":6.8,"tv":124.18,"id":7445998},{"batl":[[0,1.21,87]],"ltp":1.18,"tv":1933.46,"id":9629022}]}]}
{"op":"mcm","clk":"4227823316","pt":1631457648622,"mc":[{"id":"1.187551081","rc":[{"batl":[[0,7.6,190.93],[1,8.8,3]],"ltp":6.8,"tv":124.18,"id":7445998}]}]}
{"op":"mcm","clk":"4227823370","pt":1631457648915,"mc":[{"id":"1.187551081","rc":[{"batl":[[0,8.8,3],[1,8.8,0]],"ltp":6.8,"tv":124.18,"id":7445998}]}]}
{"op":"mcm","clk":"4227823936","pt":1631457651825,"mc":[{"id":"1.187551081","rc":[{"batb":[[1,1.15,48.2],[2,1.14,739.83]],"ltp":1.18,"tv":1933.46,"id":9629022}]}]}
{"op":"mcm","clk":"4227825269","pt":1631457659537,"mc":[{"id":"1.187551081","rc":[{"batb":[[1,5.4,48.23],[2,4.7,66.57]],"ltp":6.8,"tv":124.18,"id":7445998},{"batb":[[0,1.19,534.47],[1,1.18,6],[2,1.16,624.77]],"ltp":1.18,"tv":1933.46,"id":9629022}]}]}
{"op":"mcm","clk":"4227825777","pt":1631457662525,"mc":[{"id":"1.187551081","rc":[{"batl":[[0,7.8,3],[1,8.8,3]],"ltp":6.8,"tv":124.18,"id":7445998}]}]}
{"op":"mcm","clk":"4227825940","pt":1631457663246,"mc":[{"id":"1.187551081","rc":[{"batb":[[1,5.6,3],[2,5.4,48.23]],"ltp":6.8,"tv":124.18,"id":7445998}]}]}
{"op":"mcm","clk":"4227826365","pt":1631457665637,"mc":[{"id":"1.187551081","rc":[{"batb":[[0,5.8,2],[1,5.7,2],[2,5.6,3]],"ltp":6.8,"tv":124.18,"id":7445998},{"trd":[[1.19,101.81]],"batb":[[0,1.19,521.47]],"ltp":1.19,"tv":1959.47,"id":9629022}],"tv":2083.65}]}
{"op":"mcm","clk":"4227826496","pt":1631457666455,"mc":[{"id":"1.187551081","rc":[{"batb":[[0,5.9,2],[1,5.8,2],[2,5.7,2]],"ltp":6.8,"tv":124.18,"id":7445998},{"batl":[[0,1.2,12],[1,1.21,87],[2,1.39,19.07]],"ltp":1.19,"tv":1959.47,"id":9629022}]}]}
{"op":"mcm","clk":"4227827030","pt":1631457669462,"mc":[{"id":"1.187551081","rc":[{"batb":[[0,6.2,2],[1,6,3],[2,5.9,2]],"ltp":6.8,"tv":124.18,"id":7445998}]}]}
{"op":"mcm","clk":"4227827118","pt":1631457669946,"mc":[{"id":"1.187551081","rc":[{"batb":[[0,4.7,66.4],[1,3,5.93],[2,2.6,3.71]],"ltp":6.8,"tv":124.18,"id":7445998},{"batb":[[0,1.18,6],[1,1.16,624.77],[2,1.15,48.2]],"batl":[[0,1.21,80],[1,1.39,19.07],[2,3.8,27.47]],"ltp":1.19,"tv":1959.47,"id":9629022}]}]}
{"op":"mcm","clk":"4227827738","pt":1631457673245,"mc":[{"id":"1.187551081","rc":[{"batl":[[0,7.4,2]],"ltp":6.8,"tv":124.18,"id":7445998}]}]}
{"op":"mcm","clk":"4227831333","pt":1631457694489,"mc":[{"id":"1.187551081","rc":[{"trd":[[5.7,16.98]],"ltp":5.7,"tv":141.16,"id":7445998},{"trd":[[1.21,80]],"batl":[[0,1.39,1.28],[1,3.8,27.47],[2,8.8,7.23]],"ltp":1.21,"tv":2039.47,"id":9629022}],"tv":2180.63}]}
{"op":"mcm","clk":"4227831518","pt":1631457695599,"mc":[{"id":"1.187551081","rc":[{"batb":[[0,4.1,90.35]],"ltp":5.7,"tv":141.16,"id":7445998},{"batb":[[0,1.22,432.84],[1,1.2,500.92],[2,1.18,6]],"ltp":1.21,"tv":2039.47,"id":9629022}]}]}
{"op":"mcm","clk":"4227831618","pt":1631457696085,"mc":[{"id":"1.187551081","rc":[{"batb":[[0,1.2,500.92],[1,1.18,6],[2,1.15,48.2]],"ltp":1.21,"tv":2039.47,"id":9629022}]}]}
{"op":"mcm","clk":"4227831799","pt":1631457697304,"mc":[{"id":"1.187551081","rc":[{"batb":[[0,4.7,2],[1,4.6,3],[2,4.1,90.35]],"ltp":5.7,"tv":141.16,"id":7445998},{"batl":[[0,1.28,6],[1,1.39,1.28],[2,3.8,27.47]],"ltp":1.21,"tv":2039.47,"id":9629022}]}]}
{"op":"mcm","clk":"4227832069","pt":1631457698901,"mc":[{"id":"1.187551081","rc":[{"batb":[[2,4.1,93.35]],"ltp":5.7,"tv":141.16,"id":7445998},{"batl":[[1,1.33,10],[2,1.39,1.28]],"ltp":1.21,"tv":2039.47,"id":9629022}]}]}
{"op":"mcm","clk":"4227833222","pt":1631457705376,"mc":[{"id":"1.187551081","rc":[{"batb":[[0,4.1,90.35],[1,3.8,56.52],[2,2.6,3.71]],"ltp":5.7,"tv":141.16,"id":7445998},{"batb":[[0,1.27,351.11],[1,1.24,391.64],[2,1.18,6]],"batl":[[0,1.39,1.28],[1,3.8,27.47],[2,8.8,7.23]],"ltp":1.21,"tv":2039.47,"id":9629022}]}]}
{"op":"mcm","clk":"4227834580","pt":1631457713599,"mc":[{"id":"1.187551081","rc":[{"batb":[[0,3.8,56.52],[1,2.6,3.71],[2,2.2,42.66]],"ltp":5.7,"tv":141.16,"id":7445998},{"batb":[[0,1.24,391.64],[1,1.18,6],[2,1.15,48.2]],"ltp":1.21,"tv":2039.47,"id":9629022}]}]}
{"op":"mcm","clk":"4227834754","pt":1631457714509,"mc":[{"id":"1.187551081","rc":[{"trd":[[4.7,2]],"ltp":4.7,"tv":143.16,"id":7445998},{"trd":[[1.27,7.4]],"batl":[[0,1.27,1.84],[1,1.39,1.28],[2,3.8,27.47]],"ltp":1.27,"tv":2046.86,"id":9629022}],"tv":2190.03}]}
{"op":"mcm","clk":"4227835096","pt":1631457716407,"mc":[{"id":"1.187551081","rc":[{"batb":[[1,1.2,1.76],[2,1.18,6]],"ltp":1.27,"tv":2046.86,"id":9629022}]}]}
{"op":"mcm","clk":"4227835634","pt":1631457719726,"mc":[{"id":"1.187551081","rc":[{"batl":[[0,1.27,30.89]],"ltp":1.27,"tv":2046.86,"id":9629022}]}]}
{"op":"mcm","clk":"4227837007","pt":1631457727634,"mc":[{"id":"1.187551081","rc":[{"batb":[[0,4.4,77.04],[1,3.9,105.43],[2,3.8,56.52]],"ltp":4.7,"tv":143.16,"id":7445998},{"batb":[[1,1.21,466.42],[2,1.2,1.76]],"ltp":1.27,"tv":2046.86,"id":9629022}]}]}
{"op":"mcm","clk":"4227837049","pt":1631457727966,"mc":[{"id":"1.187551081","rc":[{"batb":[[2,2.6,3.71]],"ltp":4.7,"tv":143.16,"id":7445998}]}]}
{"op":"mcm","clk":"4227837291","pt":1631457729450,"mc":[{"id":"1.187551081","rc":[{"batb":[[0,3.9,105.43],[1,2.6,3.71],[2,2.2,42.66]],"ltp":4.7,"tv":143.16,"id":7445998},{"batb":[[0,1.21,466.42],[1,1.2,1.76],[2,1.18,6]],"batl":[[0,1.27,29.05]],"ltp":1.27,"tv":2046.86,"id":9629022}]}]}
{"op":"mcm","clk":"4227837655","pt":1631457731653,"mc":[{"id":"1.187551081","rc":[{"batl":[[0,4.8,12.1]],"ltp":4.7,"tv":143.16,"id":7445998},{"batl":[[1,1.3,202.75],[2,1.39,1.28]],"ltp":1.27,"tv":2046.86,"id":9629022}]}]}
{"op":"mcm","clk":"4227837677","pt":1631457731787,"mc":[{"id":"1.187551081","rc":[{"batl":[[1,1.39,1.28],[2,3.8,27.47]],"ltp":1.27,"tv":2046.86,"id":9629022}]}]}
{"op":"mcm","clk":"4227838186","pt":1631457734739,"mc":[{"id":"1.187551081","rc":[{"batl":[[0,1.39,1.28],[1,3.8,27.47],[2,8.8,7.23]],"ltp":1.27,"tv":2046.86,"id":9629022}]}]}
{"op":"mcm","clk":"4227838688","pt":1631457737970,"mc":[{"id":"1.187551081","rc":[{"batl":[[0,1.33,29.05],[1,1.39,1.28],[2,3.8,27.47]],"ltp":1.27,"tv":2046.86,"id":9629022}]}]}
{"op":"mcm","clk":"4227839127","pt":1631457740462,"mc":[{"id":"1.187551081","rc":[{"batb":[[1,3.55,65.65],[2,2.6,3.71]],"ltp":4.7,"tv":143.16,"id":7445998},{"batb":[[0,1.29,314.94],[1,1.25,374.56],[2,1.21,466.42]],"ltp":1.27,"tv":2046.86,"id":9629022}]}]}
{"op":"mcm","clk":"4227839333","pt":1631457741543,"mc":[{"id":"1.187551081","rc":[{"batl":[[0,5.5,116.95]],"ltp":4.7,"tv":143.16,"id":7445998},{"batb":[[2,1.2,1.76]],"ltp":1.27,"tv":2046.86,"id":9629022}]}]}
{"op":"mcm","clk":"4227839840","pt":1631457744695,"mc":[{"id":"1.187551081","rc":[{"batb":[[2,2.42,388.03]],"ltp":4.7,"tv":143.16,"id":7445998}]}]}
{"op":"mcm","clk":"4227841223","pt":1631457752485,"mc":[{"id":"1.187551081","rc":[{"batb":[[2,2.2,42.66]],"ltp":4.7,"tv":143.16,"id":7445998}]}]}
{"op":"mcm","clk":"4227841805","pt":1631457755822,"mc":[{"id":"1.187551081","rc":[{"batl":[[0,1.39,1.28],[1,3.8,27.47],[2,8.8,7.23]],"ltp":1.27,"tv":2046.86,"id":9629022}]}]}
{"op":"mcm","clk":"4227842312","pt":1631457758913,"mc":[{"id":"1.187551081","rc":[{"trd":[[1.29,58.1]],"batb":[[0,1.29,285.89]],"ltp":1.29,"tv":2104.96,"id":9629022}],"tv":2248.13}]}
{"op":"mcm","clk":"4227844353","pt":1631457770927,"mc":[{"id":"1.187551081","rc":[{"batb":[[0,3.55,65.65],[1,2.2,42.66],[2,2,11.86]],"ltp":4.7,"tv":143.16,"id":7445998},{"batb":[[0,1.25,374.56],[1,1.2,1.76],[2,1.18,6]],"ltp":1.29,"tv":2104.96,"id":9629022}]}]}
{"op":"mcm","clk":"4227844789","pt":1631457773626,"mc":[{"id":"1.187551081","rc":[{"batb":[[0,3.6,65.32],[1,3.55,65.65],[2,2.2,42.66]],"ltp":4.7,"tv":143.16,"id":7445998}]}]}
{"op":"mcm","clk":"4227844848","pt":1631457773950,"mc":[{"id":"1.187551081","rc":[{"batb":[[1,2.2,42.66],[2,2,11.86]],"ltp":4.7,"tv":143.16,"id":7445998}]}]}
{"op":"mcm","clk":"4227845719","pt":1631457779377,"mc":[{"id":"1.187551081","rc":[{"trd":[[1.25,67.67]],"batb":[[0,1.25,365.28]],"ltp":1.25,"tv":2123.52,"id":9629022}],"tv":2266.69}]}
{"op":"mcm","clk":"4227847493","pt":1631457789460,"mc":[{"id":"1.187551081","rc":[{"batb":[[0,4.3,81.64],[1,3.9,105.68],[2,3.6,65.32]],"ltp":4.7,"tv":143.16,"id":7445998},{"batb":[[1,1.22,451.43],[2,1.2,1.76]],"ltp":1.25,"tv":2123.52,"id":9629022}]}]}
{"op":"mcm","clk":"4227847570","pt":1631457789788,"mc":[{"id":"1.187551081","rc":[{"batb":[[2,2.2,42.66]],"ltp":4.7,"tv":143.16,"id":7445998}]}]}
{"op":"mcm","clk":"4227847846","pt":1631457791607,"mc":[{"id":"1.187551081","rc":[{"batb":[[2,2.6,3.71]],"batl":[[0,6,107.93]],"ltp":4.7,"tv":143.16,"id":7445998}]}]}
{"op":"mcm","clk":"4227848915","pt":1631457798176,"mc":[{"id":"1.187551081","rc":[{"batb":[[0,3.9,105.68],[1,2.6,3.71],[2,2.52,387.74]],"ltp":4.7,"tv":143.16,"id":7445998},{"batb":[[0,1.22,451.43],[1,1.21,30.79]],"ltp":1.25,"tv":2123.52,"id":9629022}]}]}
{"op":"mcm","clk":"4227849948","pt":1631457804702,"mc":[{"id":"1.187551081","rc":[{"batb":[[1,1.2,1.76],[2,1.18,6]],"ltp":1.25,"tv":2123.52,"id":9629022}]}]}
{"op":"mcm","clk":"4227850392","pt":1631457807531,"mc":[{"id":"1.187551081","rc":[{"batb":[[2,1.05,474.41]],"ltp":1.25,"tv":2123.52,"id":9629022}]}]}
{"op":"mcm","clk":"4227850450","pt":1631457807910,"mc":[{"id":"1.187551081","rc":[{"batb":[[0,1.23,30.79],[1,1.22,451.43],[2,1.2,1.76]],"ltp":1.25,"tv":2123.52,"id":9629022}]}]}
{"op":"mcm","clk":"4227851451","pt":1631457814326,"mc":[{"id":"1.187551081","rc":[{"trd":[[1.23,2.76]],"batb":[[0,1.23,29.42]],"ltp":1.23,"tv":2126.28,"id":9629022}],"tv":2269.45}]}
{"op":"mcm","clk":"4227852616","pt":1631457821548,"mc":[{"id":"1.187551081","rc":[{"trd":[[3.9,0.75]],"batb":[[0,3.9,104.93]],"ltp":3.9,"tv":143.91,"id":7445998},{"trd":[[1.35,2.17]],"ltp":1.35,"tv":2128.45,"id":9629022}],"tv":2272.37}]}
{"op":"mcm","clk":"4227852774","pt":1631457822528,"mc":[{"id":"1.187551081","rc":[{"batb":[[0,4.9,62.38],[1,4.4,79.13],[2,3.9,104.93]],"ltp":3.9,"tv":143.91,"id":7445998}]}]}
{"op":"mcm","clk":"4227852815","pt":1631457822847,"mc":[{"id":"1.187551081","rc":[{"batb":[[2,2.6,3.71]],"ltp":3.9,"tv":143.91,"id":7445998}]}]}
{"op":"mcm","clk":"4227854496","pt":1631457833131,"mc":[{"id":"1.187551081","rc":[{"batb":[[0,4.4,79.13],[1,2.6,3.71],[2,2.52,387.74]],"ltp":3.9,"tv":143.91,"id":7445998},{"batb":[[0,1.2,1.76],[1,1.19,529.56],[2,1.05,474.41]],"ltp":1.35,"tv":2128.45,"id":9629022}]}]}
{"op":"mcm","clk":"4227854876","pt":1631457835552,"mc":[{"id":"1.187551081","rc":[{"batl":[[0,4.8,50],[1,6,107.93]],"ltp":3.9,"tv":143.91,"id":7445998}]}]}
{"op":"mcm","clk":"4227855559","pt":1631457839733,"mc":[{"id":"1.187551081","rc":[{"batl":[[0,6,107.93],[1,6,0]],"ltp":3.9,"tv":143.91,"id":7445998}]}]}
{"op":"mcm","clk":"4227855940","pt":1631457842160,"mc":[{"id":"1.187551081","rc":[{"trd":[[6,0.38]],"batl":[[0,6,107.55]],"ltp":6.0,"tv":144.29,"id":7445998},{"trd":[[1.2,5.37]],"batb":[[0,1.19,529.56],[1,1.05,474.41],[2,1.03,494.18]],"ltp":1.2,"tv":2133.82,"id":9629022}],"tv":2278.12}]}
{"op":"mcm","clk":"4227856142","pt":1631457843472,"mc":[{"id":"1.187551081","rc":[{"batb":[[2,2.2,42.66]],"ltp":6.0,"tv":144.29,"id":7445998}]}]}
{"op":"mcm","clk":"4227856587","pt":1631457846382,"mc":[{"id":"1.187551081","rc":[{"batb":[[0,5.4,48.99],[1,5,58.7],[2,4.4,79.13]],"ltp":6.0,"tv":144.29,"id":7445998},{"trd":[[1.25,87.67]],"batb":[[1,1.17,591.27],[2,1.05,474.41]],"batl":[[0,1.25,40.88],[1,1.39,1.28],[2,3.8,27.47]],"ltp":1.25,"tv":2153.82,"id":9629022}],"tv":2298.12}]}
{"op":"mcm","clk":"4227856773","pt":1631457847472,"mc":[{"id":"1.187551081","rc":[{"batl":[[0,7.8,89.36]],"ltp":6.0,"tv":144.29,"id":7445998}]}]}
{"op":"mcm","clk":"4227857099","pt":1631457849355,"mc":[{"id":"1.187551081","rc":[{"batl":[[0,1.39,1.28],[1,3.8,27.47],[2,8.8,7.23]],"ltp":1.25,"tv":2153.82,"id":9629022}]}]}
{"op":"mcm","clk":"4227857232","pt":1631457850176,"mc":[{"id":"1.187551081","rc":[{"batb":[[0,1.21,29.05],[1,1.19,529.56],[2,1.17,591.27]],"ltp":1.25,"tv":2153.82,"id":9629022}]}]}
{"op":"mcm","clk":"4227858496","pt":1631457857811,"mc":[{"id":"1.187551081","rc":[{"trd":[[1.19,125.47],[1.21,138.1]],"batb":[[0,1.19,517.73],[1,1.17,591.27],[2,1.05,474.41]],"ltp":1.19,"tv":2235.58,"id":9629022}],"tv":2379.88}]}
{"op":"mcm","clk":"4227858801","pt":1631457859176,"mc":[{"id":"1.187551081","rc":[{"batl":[[0,1.21,28.92],[1,1.39,1.28],[2,3.8,27.47]],"ltp":1.19,"tv":2235.58,"id":9629022}]}]}
{"op":"mcm","clk":"4227859281","pt":1631457861865,"mc":[{"id":"1.187551081","rc":[{"batb":[[0,5,58.53],[1,3,5.93],[2,2.8,381.52]],"ltp":6.0,"tv":144.29,"id":7445998},{"batb":[[0,1.17,591.27],[1,1.05,474.41],[2,1.03,494.18]],"ltp":1.19,"tv":2235.58,"id":9629022}]}]}
{"op":"mcm","clk":"4227859800","pt":1631457864584,"mc":[{"id":"1.187551081","rc":[{"trd":[[5.7,19.55]],"ltp":5.7,"tv":146.86,"id":7445998},{"trd":[[1.21,150.2]],"batl":[[0,1.21,16.82]],"ltp":1.21,"tv":2247.69,"id":9629022}],"tv":2394.55}]}
{"op":"mcm","clk":"4227860440","pt":1631457868594,"mc":[{"id":"1.187551081","rc":[{"batl":[[0,1.39,1.28],[1,3.8,27.47],[2,8.8,7.23]],"ltp":1.21,"tv":2247.69,"id":9629022}]}]}
{"op":"mcm","clk":"4227861295","pt":1631457873709,"mc":[{"id":"1.187551081","rc":[{"trd":[[5,31.19]],"batb":[[0,5,58.41]],"ltp":5.0,"tv":146.98,"id":7445998},{"trd":[[1.25,88.17]],"ltp":1.25,"tv":2248.19,"id":9629022}],"tv":2395.18}]}
{"op":"mcm","clk":"4227863194","pt":1631457884628,"mc":[{"id":"1.187551081","rc":[{"batb":[[1,4.5,73.69],[2,3,5.93]],"ltp":5.0,"tv":146.98,"id":7445998},{"batb":[[0,1.21,470.86],[1,1.18,561.46],[2,1.05,474.41]],"ltp":1.25,"tv":2248.19,"id":9629022}]}]}
{"op":"mcm","clk":"4227863499","pt":1631457886520,"mc":[{"id":"1.187551081","rc":[{"batl":[[0,7.2,91.36]],"ltp":5.0,"tv":146.98,"id":7445998}]}]}
{"op":"mcm","clk":"4227865045","pt":1631457895432,"mc":[{"id":"1.187551081","rc":[{"batb":[[0,4.5,73.69],[1,3,5.93],[2,2.8,381.52]],"ltp":5.0,"tv":146.98,"id":7445998},{"batb":[[0,1.18,561.46],[1,1.05,474.41],[2,1.03,494.18]],"ltp":1.25,"tv":2248.19,"id":9629022}]}]}
{"op":"mcm","clk":"4227868491","pt":1631457915175,"mc":[{"id":"1.187551081","rc":[{"batb":[[0,5.7,44.72],[1,4.9,61.55],[2,4.5,73.69]],"ltp":5.0,"tv":146.98,"id":7445998},{"batb":[[1,1.16,649.97],[2,1.05,474.41]],"ltp":1.25,"tv":2248.19,"id":9629022}]}]}
{"op":"mcm","clk":"4227868726","pt":1631457916550,"mc":[{"id":"1.187551081","rc":[{"batl":[[0,8.6,81.32]],"ltp":5.0,"tv":146.98,"id":7445998}]}]}
{"op":"mcm","clk":"4227870201","pt":1631457925888,"mc":[{"id":"1.187551081","rc":[{"trd":[[5.7,20.04]],"batb":[[0,5.7,44.47]],"ltp":5.7,"tv":147.47,"id":7445998}],"tv":2395.67}]}
{"op":"mcm","clk":"4227870351","pt":1631457926796,"mc":[{"id":"1.187551081","rc":[{"batb":[[2,3,5.93]],"ltp":5.7,"tv":147.47,"id":7445998}]}]}
{"op":"mcm","clk":"4227871240","pt":1631457932400,"mc":[{"id":"1.187551081","rc":[{"batb":[[2,1.03,494.18]],"batl":[[0,1.2,21.69],[1,1.39,1.28],[2,3.8,27.47]],"ltp":1.25,"tv":2248.19,"id":9629022}]}]}
{"op":"mcm","clk":"4227872198","pt":1631457938653,"mc":[{"id":"1.187551081","rc":[{"trd":[[5.7,51.36],[6,4.72]],"batb":[[0,5.7,28.81]],"ltp":5.7,"tv":183.13,"id":7445998},{"trd":[[1.2,27.06]],"batl":[[0,1.39,1.28],[1,3.8,27.47],[2,8.8,7.23]],"ltp":1.2,"tv":2269.88,"id":9629022}],"tv":2453.02}]}
{"op":"mcm","clk":"4227872655","pt":1631457941494,"mc":[{"id":"1.187551081","rc":[{"batb":[[1,5.6,45.3],[2,4.9,61.55]],"ltp":5.7,"tv":183.13,"id":7445998},{"batb":[[0,1.2,100],[1,1.18,561.46],[2,1.16,649.97]],"ltp":1.2,"tv":2269.88,"id":9629022}]}]}
{"op":"mcm","clk":"4227872718","pt":1631457941810,"mc":[{"id":"1.187551081","rc":[{"batb":[[0,5.6,45.3],[1,4.8,62.38],[2,3,5.93]],"ltp":5.7,"tv":183.13,"id":7445998},{"batb":[[1,1.18,556.77],[2,1.16,644.62]],"ltp":1.2,"tv":2269.88,"id":9629022}]}]}
{"op":"mcm","clk":"4227875458","pt":1631457960040,"mc":[{"id":"1.187551081","rc":[{"trd":[[5.6,21.79]],"batb":[[0,5.6,23.52]],"ltp":5.6,"tv":204.92,"id":7445998},{"trd":[[1.22,100]],"ltp":1.22,"tv":2369.88,"id":9629022}],"tv":2574.8}]}
{"op":"mcm","clk":"4227876062","pt":1631457964135,"mc":[{"id":"1.187551081","rc":[{"batb":[[0,5.5,46.14]],"ltp":5.6,"tv":204.92,"id":7445998},{"batb":[[1,1.18,550.49],[2,1.16,637.5]],"ltp":1.22,"tv":2369.88,"id":9629022}]}]}
{"op":"mcm","clk":"4227876242","pt":1631457965359,"mc":[{"id":"1.187551081","rc":[{"batb":[[0,1.18,550.49],[1,1.16,637.5],[2,1.05,474.41]],"ltp":1.22,"tv":2369.88,"id":9629022}]}]}
{"op":"mcm","clk":"4227885639","pt":1631458029750,"mc":[{"id":"1.187551081","rc":[{"batb":[[0,4.8,62.38],[1,3,5.93],[2,2.6,3.71]],"ltp":5.6,"tv":204.92,"id":7445998},{"batb":[[0,1.16,637.5],[1,1.05,474.41],[2,1.03,494.18]],"ltp":1.22,"tv":2369.88,"id":9629022}]}]}
{"op":"mcm","clk":"4227887354","pt":1631458041708,"mc":[{"id":"1.187551081","rc":[{"trd":[[4.8,0.53]],"batb":[[0,4.8,61.86]],"ltp":4.8,"tv":205.45,"id":7445998},{"trd":[[1.27,9.4]],"ltp":1.27,"tv":2371.88,"id":9629022}],"tv":2577.33}]}
{"op":"mcm","clk":"4227889098","pt":1631458054954,"mc":[{"id":"1.187551081","rc":[{"trd":[[4.8,9.55]],"batb":[[0,4.8,57.35]],"ltp":4.8,"tv":214.47,"id":7445998}],"tv":2586.35}]}
{"op":"mcm","clk":"4227889442","pt":1631458057552,"mc":[{"id":"1.187551081","rc":[{"batb":[[1,4.1,89.35],[2,3,5.93]],"ltp":4.8,"tv":214.47,"id":7445998},{"batb":[[0,1.22,446.32],[1,1.19,526.88],[2,1.05,474.41]],"ltp":1.27,"tv":2371.88,"id":9629022}]}]}
{"op":"mcm","clk":"4227889705","pt":1631458059267,"mc":[{"id":"1.187551081","rc":[{"batl":[[0,7.2,91.74]],"ltp":4.8,"tv":214.47,"id":7445998}]}]}
{"op":"mcm","clk":"4227889873","pt":1631458060359,"mc":[{"id":"1.187551081","rc":[{"trd":[[1.22,175.8]],"batb":[[0,1.22,408.42]],"ltp":1.22,"tv":2447.68,"id":9629022}],"tv":2662.15}]}
{"op":"mcm","clk":"4227891675","pt":1631458072990,"mc":[{"id":"1.187551081","rc":[{"batb":[[0,4.1,89.01],[1,3,5.93],[2,2.6,3.71]],"ltp":4.8,"tv":214.47,"id":7445998},{"batb":[[0,1.19,526.88],[1,1.05,474.41],[2,1.03,494.18]],"ltp":1.22,"tv":2447.68,"id":9629022}]}]}
{"op":"mcm","clk":"4227892754","pt":1631458080469,"mc":[{"id":"1.187551081","rc":[{"batl":[[0,4.8,2.16]],"ltp":4.8,"tv":214.47,"id":7445998}]}]}
{"op":"mcm","clk":"4227892880","pt":1631458081285,"mc":[{"id":"1.187551081","rc":[{"batb":[[1,2.6,3.71],[2,2.2,42.66]],"batl":[[1,6.6,98.5]],"ltp":4.8,"tv":214.47,"id":7445998}]}]}
{"op":"mcm","clk":"4227894384","pt":1631458091426,"mc":[{"id":"1.187551081","rc":[{"batl":[[1,6.6,0]],"ltp":4.8,"tv":214.47,"id":7445998}]}]}
{"op":"mcm","clk":"4227894679","pt":1631458093573,"mc":[{"id":"1.187551081","rc":[{"trd":[[4.1,17.59]],"batb":[[0,4.1,80.22],[1,3.7,59.37],[2,2.6,3.71]],"ltp":4.1,"tv":232.06,"id":7445998},{"batb":[[0,1.27,354.63],[1,1.23,421.62],[2,1.19,526.88]],"ltp":1.22,"tv":2447.68,"id":9629022}],"tv":2679.74}]}
{"op":"mcm","clk":"4227894746","pt":1631458094010,"mc":[{"id":"1.187551081","rc":[{"batb":[[2,1.05,474.41]],"ltp":1.22,"tv":2447.68,"id":9629022}]}]}
{"op":"mcm","clk":"4227894969","pt":1631458095511,"mc":[{"id":"1.187551081","rc":[{"batl":[[1,6,106.05]],"ltp":4.1,"tv":232.06,"id":7445998}]}]}
{"op":"mcm","clk":"4227896363","pt":1631458105341,"mc":[{"id":"1.187551081","rc":[{"batb":[[0,3.7,59.37],[1,2.6,3.71],[2,2.2,42.66]],"ltp":4.1,"tv":232.06,"id":7445998},{"batb":[[0,1.23,420.11],[1,1.05,474.41],[2,1.03,494.18]],"ltp":1.22,"tv":2447.68,"id":9629022}]}]}
{"op":"mcm","clk":"4227898219","pt":1631458118960,"mc":[{"id":"1.187551081","rc":[{"batb":[[1,2.2,42.66],[2,2,11.86]],"ltp":4.1,"tv":232.06,"id":7445998},{"batb":[[0,1.33,79.16],[1,1.23,420.11],[2,1.05,474.41]],"ltp":1.22,"tv":2447.68,"id":9629022}]}]}
{"op":"mcm","clk":"4227898621","pt":1631458121986,"mc":[{"id":"1.187551081","rc":[{"batb":[[2,1.11,269.55]],"ltp":1.22,"tv":2447.68,"id":9629022}]}]}
{"op":"mcm","clk":"4227898738","pt":1631458122791,"mc":[{"id":"1.187551081","rc":[{"batl":[[1,6,0]],"ltp":4.1,"tv":232.06,"id":7445998}]}]}
{"op":"mcm","clk":"4227899050","pt":1631458125080,"mc":[{"id":"1.187551081","rc":[{"batb":[[1,3.35,74.53],[2,2.2,42.66]],"ltp":4.1,"tv":232.06,"id":7445998},{"batb":[[1,1.32,285.38],[2,1.29,325.57]],"ltp":1.22,"tv":2447.68,"id":9629022}]}]}
{"op":"mcm","clk":"4227899242","pt":1631458126460,"mc":[{"id":"1.187551081","rc":[{"batb":[[2,2.38,400.04]],"batl":[[1,5.3,119.17]],"ltp":4.1,"tv":232.06,"id":7445998}]}]}
{"op":"mcm","clk":"4227900092","pt":1631458132479,"mc":[{"id":"1.187551081","rc":[{"trd":[[3.7,3.92]],"batb":[[0,3.7,55.45]],"ltp":3.7,"tv":235.98,"id":7445998},{"trd":[[1.38,10.52]],"ltp":1.38,"tv":2458.2,"id":9629022}],"tv":2694.19}]}
{"op":"mcm","clk":"4227900927","pt":1631458138500,"mc":[{"id":"1.187551081","rc":[{"trd":[[3.7,7.85]],"batb":[[0,3.7,51.52]],"ltp":3.7,"tv":239.91,"id":7445998},{"trd":[[1.38,21.04]],"ltp":1.38,"tv":2468.72,"id":9629022}],"tv":2708.63}]}
{"op":"mcm","clk":"4227901038","pt":1631458139092,"mc":[{"id":"1.187551081","rc":[{"batb":[[0,3.35,74.53],[1,2.38,400.04],[2,2.2,42.66]],"ltp":3.7,"tv":239.91,"id":7445998},{"batb":[[1,1.29,325.07],[2,1.22,1.87]],"ltp":1.38,"tv":2468.72,"id":9629022}]}]}
{"op":"mcm","clk":"4227901151","pt":1631458139794,"mc":[{"id":"1.187551081","rc":[{"batb":[[0,1.29,325.07],[1,1.22,1.87],[2,1.11,269.55]],"ltp":1.38,"tv":2468.72,"id":9629022}]}]}
{"op":"mcm","clk":"4227901550","pt":1631458142582,"mc":[{"id":"1.187551081","rc":[{"batb":[[0,1.38,10.52],[1,1.29,325.07],[2,1.22,1.87]],"ltp":1.38,"tv":2468.72,"id":9629022}]}]}
{"op":"mcm","clk":"4227901638","pt":1631458143011,"mc":[{"id":"1.187551081","rc":[{"trd":[[1.39,2.56]],"batb":[[0,1.39,8.97],[1,1.38,10.52],[2,1.29,325.07]],"batl":[[0,3.8,27.47],[1,8.8,7.23],[2,44,7.23]],"ltp":1.39,"tv":2471.28,"id":9629022}],"tv":2711.19}]}
{"op":"mcm","clk":"4227901735","pt":1631458143811,"mc":[{"id":"1.187551081","rc":[{"batb":[[0,1.39,19.22]],"ltp":1.39,"tv":2471.28,"id":9629022}]}]}
{"op":"mcm","clk":"4227901968","pt":1631458145612,"mc":[{"id":"1.187551081","rc":[{"trd":[[1.39,6.24]],"batb":[[0,1.39,17.38]],"ltp":1.39,"tv":2474.96,"id":9629022}],"tv":2714.87}]}
{"op":"mcm","clk":"4227902571","pt":1631458150402,"mc":[{"id":"1.187551081","rc":[{"batb":[[1,1.38,15.52]],"ltp":1.39,"tv":2474.96,"id":9629022}]}]}
{"op":"mcm","clk":"4227902924","pt":1631458153346,"mc":[{"id":"1.187551081","rc":[{"batb":[[0,1.38,5],[1,1.29,325.07],[2,1.22,1.87]],"ltp":1.39,"tv":2474.96,"id":9629022}]}]}
{"op":"mcm","clk":"4227903427","pt":1631458157332,"mc":[{"id":"1.187551081","rc":[{"batb":[[0,1.29,325.07],[1,1.22,1.87],[2,1.15,355.81]],"ltp":1.39,"tv":2474.96,"id":9629022}]}]}
{"op":"mcm","clk":"4227903807","pt":1631458160412,"mc":[{"id":"1.187551081","rc":[{"trd":[[3.35,2.13]],"batb":[[0,3.35,72.39]],"ltp":3.35,"tv":242.04,"id":7445998},{"trd":[[1.43,5]],"ltp":1.43,"tv":2479.96,"id":9629022}],"tv":2722.01}]}
{"op":"mcm","clk":"4227905493","pt":1631458174340,"mc":[{"id":"1.187551081","rc":[{"batl":[[1,5.3,0]],"ltp":3.35,"tv":242.04,"id":7445998}]}]}
{"op":"mcm","clk":"4227905781","pt":1631458176569,"mc":[{"id":"1.187551081","rc":[{"batb":[[1,3.05,95.71],[2,2.38,400.04]],"ltp":3.35,"tv":242.04,"id":7445998},{"batb":[[0,1.37,241.33],[1,1.32,289.06],[2,1.22,1.87]],"ltp":1.43,"tv":2479.96,"id":9629022}]}]}
{"op":"mcm","clk":"4227905986","pt":1631458178176,"mc":[{"id":"1.187551081","rc":[{"batl":[[1,4.9,124.71]],"ltp":3.35,"tv":242.04,"id":7445998}]}]}
{"op":"mcm","clk":"4227907388","pt":1631458189661,"mc":[{"id":"1.187551081","rc":[{"batb":[[0,3.05,95.71],[1,2.38,400.04],[2,2.2,42.66]],"ltp":3.35,"tv":242.04,"id":7445998},{"batb":[[0,1.32,289.06],[1,1.22,1.87],[2,1.15,355.81]],"ltp":1.43,"tv":2479.96,"id":9629022}]}]}
{"op":"mcm","clk":"4227907463","pt":1631458190404,"mc":[{"id":"1.187551081","rc":[{"batb":[[0,3.75,12],[1,3.05,95.71],[2,2.38,400.04]],"ltp":3.35,"tv":242.04,"id":7445998}]}]}
{"op":"mcm","clk":"4227907622","pt":1631458191769,"mc":[{"id":"1.187551081","rc":[{"batl":[[0,1.4,2],[1,3.8,27.47],[2,8.8,7.23]],"ltp":1.43,"tv":2479.96,"id":9629022}]}]}
{"op":"mcm","clk":"4227908180","pt":1631458196689,"mc":[{"id":"1.187551081","rc":[{"trd":[[1.37,0.01]],"ltp":1.37,"tv":2479.97,"id":9629022}],"tv":2722.02}]}
{"op":"mcm","clk":"4227909421","pt":1631458206718,"mc":[{"id":"1.187551081","rc":[{"trd":[[3.75,12]],"batb":[[0,3.05,95.71],[1,2.38,400.04],[2,2.2,42.66]],"ltp":3.75,"tv":254.04,"id":7445998},{"trd":[[1.37,32.86]],"batb":[[0,1.37,41.91],[1,1.32,289.06],[2,1.22,1.87]],"ltp":1.37,"tv":2512.82,"id":9629022}],"tv":2766.86}]}
{"op":"mcm","clk":"4227909703","pt":1631458208908,"mc":[{"id":"1.187551081","rc":[{"trd":[[3.75,27.31],[4.2,4.69]],"ltp":4.2,"tv":274.04,"id":7445998},{"trd":[[1.32,14.92],[1.37,74.77]],"batb":[[0,1.32,274.14],[1,1.22,1.87],[2,1.15,355.81]],"ltp":1.32,"tv":2569.65,"id":9629022}],"tv":2843.7}]}
{"op":"mcm","clk":"4227911278","pt":1631458221836,"mc":[{"id":"1.187551081","rc":[{"batl":[[1,4.9,0]],"ltp":4.2,"tv":274.04,"id":7445998}]}]}
{"op":"mcm","clk":"4227911616","pt":1631458224437,"mc":[{"id":"1.187551081","rc":[{"batb":[[1,2.82,47.06],[2,2.38,400.04]],"ltp":4.2,"tv":274.04,"id":7445998},{"trd":[[1.4,4]],"batb":[[0,1.43,198.55],[1,1.37,242.59],[2,1.32,274.14]],"batl":[[0,3.8,27.47],[1,8.8,7.23],[2,44,7.23]],"ltp":1.4,"tv":2573.65,"id":9629022}],"tv":2847.7}]}
{"op":"mcm","clk":"4227911753","pt":1631458225532,"mc":[{"id":"1.187551081","rc":[{"batb":[[0,3.05,95.46]],"batl":[[0,4.2,146.16],[1,4.8,2.16]],"ltp":4.2,"tv":274.04,"id":7445998},{"batb":[[2,1.22,1.87]],"ltp":1.4,"tv":2573.65,"id":9629022}]}]}
{"op":"mcm","clk":"4227911868","pt":1631458226742,"mc":[{"id":"1.187551081","rc":[{"batb":[[1,1.4,25],[2,1.37,242.59]],"ltp":1.4,"tv":2573.65,"id":9629022}]}]}
{"op":"mcm","clk":"4227912422","pt":1631458231142,"mc":[{"id":"1.187551081","rc":[{"batb":[[1,1.37,242.59],[2,1.22,1.87]],"ltp":1.4,"tv":2573.65,"id":9629022}]}]}
{"op":"mcm","clk":"4227913399","pt":1631458239644,"mc":[{"id":"1.187551081","rc":[{"batb":[[0,2.82,47.06],[1,2.38,400.04],[2,2.2,42.66]],"ltp":4.2,"tv":274.04,"id":7445998},{"batb":[[0,1.49,25]],"ltp":1.4,"tv":2573.65,"id":9629022}]}]}
{"op":"mcm","clk":"4227913429","pt":1631458239962,"mc":[{"id":"1.187551081","rc":[{"batb":[[2,2,11.86]],"ltp":4.2,"tv":274.04,"id":7445998}]}]}
{"op":"mcm","clk":"4227914423","pt":1631458248069,"mc":[{"id":"1.187551081","rc":[{"batb":[[0,1.37,242.59],[1,1.22,1.87],[2,1.15,355.81]],"ltp":1.4,"tv":2573.65,"id":9629022}]}]}
{"op":"mcm","clk":"4227915039","pt":1631458253242,"mc":[{"id":"1.187551081","rc":[{"batl":[[0,4.8,2.16],[1,4.8,0]],"ltp":4.2,"tv":274.04,"id":7445998}]}]}
{"op":"mcm","clk":"4227915294","pt":1631458255588,"mc":[{"id":"1.187551081","rc":[{"batb":[[0,3.35,74.36],[1,3,97.22],[2,2.82,47.06]],"ltp":4.2,"tv":274.04,"id":7445998},{"batb":[[1,1.31,296.43],[2,1.22,1.87]],"ltp":1.4,"tv":2573.65,"id":9629022}]}]}
{"op":"mcm","clk":"4227915370","pt":1631458256283,"mc":[{"id":"1.187551081","rc":[{"batb":[[2,2.38,400.04]],"ltp":4.2,"tv":274.04,"id":7445998}]}]}
{"op":"mcm","clk":"4227915536","pt":1631458257680,"mc":[{"id":"1.187551081","rc":[{"batl":[[1,4.9,124.71]],"ltp":4.2,"tv":274.04,"id":7445998}]}]}
{"op":"mcm","clk":"4227916691","pt":1631458267636,"mc":[{"id":"1.187551081","rc":[{"trd":[[3.35,12.81]],"batb":[[0,3.35,63.69]],"ltp":3.35,"tv":284.71,"id":7445998},{"trd":[[1.43,30]],"ltp":1.43,"tv":2598.65,"id":9629022}],"tv":2883.37}]}
{"op":"mcm","clk":"4227916973","pt":1631458269757,"mc":[{"id":"1.187551081","rc":[{"batb":[[0,3,97.22],[1,2.38,400.04],[2,2,11.86]],"ltp":3.35,"tv":284.71,"id":7445998},{"batb":[[0,1.31,296.43],[1,1.22,1.87],[2,1.15,355.81]],"ltp":1.43,"tv":2598.65,"id":9629022}]}]}
{"op":"mcm","clk":"4227917302","pt":1631458272657,"mc":[{"id":"1.187551081","rc":[{"batb":[[1,2.94,105.09],[2,2.38,400.04]],"ltp":3.35,"tv":284.71,"id":7445998},{"batb":[[0,1.33,280.19],[1,1.31,296.43],[2,1.22,1.87]],"ltp":1.43,"tv":2598.65,"id":9629022}]}]}
{"op":"mcm","clk":"4227917330","pt":1631458272943,"mc":[{"id":"1.187551081","rc":[{"batb":[[0,2.94,105.09],[1,2.38,400.04],[2,2,11.86]],"ltp":3.35,"tv":284.71,"id":7445998},{"batb":[[1,1.22,1.87],[2,1.15,355.81]],"ltp":1.43,"tv":2598.65,"id":9629022}]}]}
{"op":"mcm","clk":"4227917808","pt":1631458277127,"mc":[{"id":"1.187551081","rc":[{"batb":[[1,1.15,355.81],[2,1.13,1.28]],"ltp":1.43,"tv":2598.65,"id":9629022}]}]}
{"op":"mcm","clk":"4227918188","pt":1631458280331,"mc":[{"id":"1.187551081","rc":[{"batl":[[1,4.9,0]],"ltp":3.35,"tv":284.71,"id":7445998}]}]}
{"op":"mcm","clk":"4227918599","pt":1631458283433,"mc":[{"id":"1.187551081","rc":[{"batb":[[1,2.66,54.09],[2,2.38,400.04]],"ltp":3.35,"tv":284.71,"id":7445998},{"batb":[[0,1.46,185.9],[1,1.39,229.11],[2,1.15,355.81]],"ltp":1.43,"tv":2598.65,"id":9629022}]}]}
{"op":"mcm","clk":"4227918651","pt":1631458283962,"mc":[{"id":"1.187551081","rc":[{"batl":[[0,4.2,146.16],[1,4.8,2.16]],"ltp":3.35,"tv":284.71,"id":7445998}]}]}
{"op":"mcm","clk":"4227918991","pt":1631458287051,"mc":[{"id":"1.187551081","rc":[{"trd":[[1.46,225.12]],"batb":[[0,1.46,73.34]],"ltp":1.46,"tv":2823.77,"id":9629022}],"tv":3108.49}]}
{"op":"mcm","clk":"4227919598","pt":1631458291868,"mc":[{"id":"1.187551081","rc":[{"batb":[[0,2.66,54.09],[1,2.38,400.04],[2,2,11.86]],"ltp":3.35,"tv":284.71,"id":7445998},{"batb":[[0,1.39,229.11],[1,1.15,355.81],[2,1.13,1.28]],"ltp":1.46,"tv":2823.77,"id":9629022}]}]}
{"op":"mcm","clk":"4227919790","pt":1631458293350,"mc":[{"id":"1.187551081","rc":[{"batb":[[0,2.66,57.3]],"ltp":3.35,"tv":284.71,"id":7445998}]}]}
{"op":"mcm","clk":"4227920158","pt":1631458295663,"mc":[{"id":"1.187551081","rc":[{"batb":[[0,2.7,53.17],[1,2.66,3.21],[2,2.38,400.04]],"ltp":3.35,"tv":284.71,"id":7445998},{"batb":[[0,1.38,230.2]],"ltp":1.46,"tv":2823.77,"id":9629022}]}]}
{"op":"mcm","clk":"4227920472","pt":1631458298574,"mc":[{"id":"1.187551081","rc":[{"batl":[[0,2.94,19.29],[1,4.2,146.16],[2,4.8,2.16]],"ltp":3.35,"tv":284.71,"id":7445998}]}]}
{"op":"mcm","clk":"4227920880","pt":1631458301796,"mc":[{"id":"1.187551081","rc":[{"batb":[[1,1.2,444.76],[2,1.15,355.81]],"ltp":1.46,"tv":2823.77,"id":9629022}]}]}
{"op":"mcm","clk":"4227921070","pt":1631458303304,"mc":[{"id":"1.187551081","rc":[{"batl":[[0,4.2,146.16],[1,4.8,2.16],[2,4.8,0]],"ltp":3.35,"tv":284.71,"id":7445998}]}]}
{"op":"mcm","clk":"4227921273","pt":1631458305090,"mc":[{"id":"1.187551081","rc":[{"batb":[[1,1.25,166.05],[2,1.2,444.76]],"ltp":1.46,"tv":2823.77,"id":9629022}]}]}
{"op":"mcm","clk":"4227923470","pt":1631458322825,"mc":[{"id":"1.187551081","rc":[{"batl":[[0,4.8,2.16],[1,4.8,0]],"ltp":3.35,"tv":284.71,"id":7445998}]}]}
{"op":"mcm","clk":"4227923709","pt":1631458324633,"mc":[{"id":"1.187551081","rc":[{"batl":[[0,1.42,4685.76],[1,3.8,27.47],[2,8.8,7.23]],"ltp":1.46,"tv":2823.77,"id":9629022}]}]}
{"op":"mcm","clk":"4227923736","pt":1631458324835,"mc":[{"id":"1.187551081","rc":[{"batb":[[1,1.2,444.76],[2,1.15,355.81]],"batl":[[0,3.8,27.47],[1,8.8,7.23],[2,44,7.23]],"ltp":1.46,"tv":2823.77,"id":9629022}]}]}
{"op":"mcm","clk":"4227923927","pt":1631458326441,"mc":[{"id":"1.187551081","rc":[{"batb":[[0,3.3,79.72],[1,2.9,44.3],[2,2.66,3.21]],"ltp":3.35,"tv":284.71,"id":7445998},{"batb":[[1,1.31,297.19],[2,1.2,444.76]],"ltp":1.46,"tv":2823.77,"id":9629022}]}]}
{"op":"mcm","clk":"4227924009","pt":1631458327136,"mc":[{"id":"1.187551081","rc":[{"batl":[[1,4.9,124.71]],"ltp":3.35,"tv":284.71,"id":7445998}]}]}
{"op":"mcm","clk":"4227924267","pt":1631458329543,"mc":[{"id":"1.187551081","rc":[{"batl":[[0,3.75,27.58],[1,4.8,2.16],[2,4.9,124.71]],"ltp":3.35,"tv":284.71,"id":7445998},{"batl":[[0,1.4,95.5],[1,3.8,27.47],[2,8.8,7.23]],"ltp":1.46,"tv":2823.77,"id":9629022}]}]}
{"op":"mcm","clk":"4227924284","pt":1631458329747,"mc":[{"id":"1.187551081","rc":[{"batl":[[0,4.8,2.16],[1,4.9,124.71],[2,4.9,0]],"ltp":3.35,"tv":284.71,"id":7445998},{"batl":[[0,3.8,27.47],[1,8.8,7.23],[2,44,7.23]],"ltp":1.46,"tv":2823.77,"id":9629022}]}]}
{"op":"mcm","clk":"4227924807","pt":1631458334541,"mc":[{"id":"1.187551081","rc":[{"trd":[[1.38,31.04]],"batb":[[0,1.38,225.2]],"ltp":1.38,"tv":2833.77,"id":9629022}],"tv":3118.49}]}
{"op":"mcm","clk":"4227926434","pt":1631458348563,"mc":[{"id":"1.187551081","rc":[{"batb":[[0,2.9,44.3],[1,2.66,3.21],[2,2.38,400.04]],"ltp":3.35,"tv":284.71,"id":7445998},{"batb":[[0,1.31,297.19],[1,1.2,444.76],[2,1.15,355.81]],"ltp":1.38,"tv":2833.77,"id":9629022}]}]}
{"op":"mcm","clk":"4227927151","pt":1631458355396,"mc":[{"id":"1.187551081","rc":[{"batl":[[2,810,0.07]],"ltp":3.35,"tv":284.71,"id":7445998}]}]}
{"op":"mcm","clk":"4227927271","pt":1631458356289,"mc":[{"id":"1.187551081","rc":[{"batl":[[1,810,0.07],[2,810,0]],"ltp":3.35,"tv":284.71,"id":7445998}]}]}
{"op":"mcm","clk":"4227927568","pt":1631458358305,"mc":[{"id":"1.187551081","rc":[{"batb":[[1,1.15,355.81],[2,1.13,1.28]],"ltp":1.38,"tv":2833.77,"id":9629022}]}]}
{"op":"mcm","clk":"4227927706","pt":1631458359199,"mc":[{"id":"1.187551081","rc":[{"batb":[[0,3.8,56.36],[1,3.3,80.05],[2,2.66,3.21]],"ltp":3.35,"tv":284.71,"id":7445998},{"batb":[[1,1.25,384.61],[2,1.15,355.81]],"ltp":1.38,"tv":2833.77,"id":9629022}]}]}
{"op":"mcm","clk":"4227927871","pt":1631458360517,"mc":[{"id":"1.187551081","rc":[{"trd":[[3.8,85.4]],"batb":[[0,3.8,13.65]],"batl":[[1,5.5,113.67],[2,810,0.07]],"ltp":3.8,"tv":370.12,"id":7445998}],"tv":3203.89}]}
{"op":"mcm","clk":"4227929999","pt":1631458379666,"mc":[{"id":"1.187551081","rc":[{"batb":[[0,3.3,80.05],[1,2.66,3.21],[2,2.38,400.04]],"ltp":3.8,"tv":370.12,"id":7445998},{"batb":[[0,1.25,384.61],[1,1.15,355.81],[2,1.13,1.28]],"ltp":1.38,"tv":2833.77,"id":9629022}]}]}
{"op":"mcm","clk":"4227930277","pt":1631458382572,"mc":[{"id":"1.187551081","rc":[{"batb":[[1,3.25,81.81],[2,2.66,3.21]],"ltp":3.8,"tv":370.12,"id":7445998},{"batb":[[0,1.26,378.75],[1,1.25,384.61],[2,1.15,355.81]],"ltp":1.38,"tv":2833.77,"id":9629022}]}]}
{"op":"mcm","clk":"4227930316","pt":1631458382952,"mc":[{"id":"1.187551081","rc":[{"batb":[[0,3.25,81.81],[1,2.66,3.21],[2,2.38,400.04]],"ltp":3.8,"tv":370.12,"id":7445998},{"batb":[[1,1.15,355.81],[2,1.13,1.28]],"ltp":1.38,"tv":2833.77,"id":9629022}]}]}
{"op":"mcm","clk":"4227931663","pt":1631458395963,"mc":[{"id":"1.187551081","rc":[{"batb":[[2,2.2,42.66]],"batl":[[1,810,0.07],[2,810,0]],"ltp":3.8,"tv":370.12,"id":7445998}]}]}
{"op":"mcm","clk":"4227931823","pt":1631458397288,"mc":[{"id":"1.187551081","rc":[{"batb":[[0,4.3,80.89],[1,3.8,54.93],[2,2.66,3.21]],"ltp":3.8,"tv":370.12,"id":7445998},{"batb":[[1,1.22,460.14],[2,1.15,355.81]],"ltp":1.38,"tv":2833.77,"id":9629022}]}]}
{"op":"mcm","clk":"4227932057","pt":1631458399596,"mc":[{"id":"1.187551081","rc":[{"batl":[[1,6.6,97.86],[2,810,0.07]],"ltp":3.8,"tv":370.12,"id":7445998}]}]}
{"op":"mcm","clk":"4227932212","pt":1631458401002,"mc":[{"id":"1.187551081","rc":[{"batb":[[2,1.13,1.28]],"ltp":1.38,"tv":2833.77,"id":9629022}]}]}
{"op":"mcm","clk":"4227932496","pt":1631458403576,"mc":[{"id":"1.187551081","rc":[{"trd":[[4.3,1.3]],"batb":[[0,4.3,80.24]],"ltp":4.3,"tv":371.42,"id":7445998}],"tv":3205.19}]}
{"op":"mcm","clk":"4227933981","pt":1631458417240,"mc":[{"id":"1.187551081","rc":[{"trd":[[4.8,10.91]],"batl":[[0,4.8,1.48]],"ltp":4.8,"tv":372.78,"id":7445998},{"trd":[[1.26,5.2]],"batb":[[0,1.26,376.15]],"ltp":1.26,"tv":2838.97,"id":9629022}],"tv":3211.75}]}
{"op":"mcm","clk":"4227935389","pt":1631458429822,"mc":[{"id":"1.187551081","rc":[{"trd":[[4.3,16.53]],"batb":[[0,4.3,65.01]],"ltp":4.3,"tv":388.01,"id":7445998},{"trd":[[1.31,50]],"ltp":1.31,"tv":2888.97,"id":9629022}],"tv":3276.99}]}
{"op":"mcm","clk":"4227935496","pt":1631458430834,"mc":[{"id":"1.187551081","rc":[{"batb":[[1,1.22,457.38]],"ltp":1.31,"tv":2888.97,"id":9629022}]}]}
{"op":"mcm","clk":"4227941030","pt":1631458477679,"mc":[{"id":"1.187551081","rc":[{"batl":[[0,1.3,9.24],[1,3.8,27.47],[2,8.8,7.23]],"ltp":1.31,"tv":2888.97,"id":9629022}]}]}
{"op":"mcm","clk":"4227941343","pt":1631458480821,"mc":[{"id":"1.187551081","rc":[{"batb":[[1,1.24,97.21],[2,1.22,457.38]],"batl":[[1,1.33,90.63],[2,3.8,27.47]],"ltp":1.31,"tv":2888.97,"id":9629022}]}]}
{"op":"mcm","clk":"4227942635","pt":1631458492329,"mc":[{"id":"1.187551081","rc":[{"trd":[[1.3,10]],"batl":[[0,1.3,4.24]],"ltp":1.3,"tv":2898.97,"id":9629022}],"tv":3286.99}]}
{"op":"mcm","clk":"4227942983","pt":1631458495532,"mc":[{"id":"1.187551081","rc":[{"batb":[[1,1.25,95.5],[2,1.24,97.21]],"batl":[[1,1.32,90.43],[2,1.33,90.63]],"ltp":1.3,"tv":2898.97,"id":9629022}]}]}
{"op":"mcm","clk":"4227943318","pt":1631458498727,"mc":[{"id":"1.187551081","rc":[{"batl":[[1,1.31,91.12],[2,1.32,90.43]],"ltp":1.3,"tv":2898.97,"id":9629022}]}]}
{"op":"mcm","clk":"4227943648","pt":1631458501817,"mc":[{"id":"1.187551081","rc":[{"batl":[[0,1.27,2],[1,1.3,4.24],[2,1.31,91.12]],"ltp":1.3,"tv":2898.97,"id":9629022}]}]}
{"op":"mcm","clk":"4227944058","pt":1631458505044,"mc":[{"id":"1.187551081","rc":[{"trd":[[1.27,13.4]],"batb":[[0,1.27,91.96],[1,1.26,376.15],[2,1.25,95.5]],"batl":[[0,1.3,94.08],[1,1.31,91.12],[2,1.32,90.43]],"ltp":1.27,"tv":2902.97,"id":9629022}],"tv":3290.99}]}
{"op":"mcm","clk":"4227944417","pt":1631458508231,"mc":[{"id":"1.187551081","rc":[{"batb":[[1,1.26,468.99]],"batl":[[0,1.29,90.53],[1,1.3,94.08],[2,1.31,91.12]],"ltp":1.27,"tv":2902.97,"id":9629022}]}]}
{"op":"mcm","clk":"4227944757","pt":1631458511356,"mc":[{"id":"1.187551081","rc":[{"trd":[[1.27,93.4]],"batb":[[0,1.27,51.96]],"ltp":1.27,"tv":2982.97,"id":9629022}],"tv":3370.99}]}
{"op":"mcm","clk":"4227945081","pt":1631458514129,"mc":[{"id":"1.187551081","rc":[{"batb":[[0,1.26,376.15],[1,1.22,457.38],[2,1.13,1.28]],"batl":[[0,3.8,27.47],[1,8.8,7.23],[2,44,7.23]],"ltp":1.27,"tv":2982.97,"id":9629022}]}]}
{"op":"mcm","clk":"4227945630","pt":1631458519351,"mc":[{"id":"1.187551081","rc":[{"trd":[[4.8,13.87]],"batb":[[0,4.8,1.24],[1,4.3,65.01],[2,3.8,54.93]],"batl":[[0,6.6,97.86],[1,810,0.07],[2,810,0]],"ltp":4.8,"tv":390.97,"id":7445998}],"tv":3373.95}]}
{"op":"mcm","clk":"4227946475","pt":1631458526980,"mc":[{"id":"1.187551081","rc":[{"batb":[[0,4.3,65.01],[1,3.8,54.93],[2,2.66,3.21]],"ltp":4.8,"tv":390.97,"id":7445998}]}]}
{"op":"mcm","clk":"4227946578","pt":1631458527880,"mc":[{"id":"1.187551081","rc":[{"batb":[[0,3.8,54.93],[1,2.66,3.21],[2,2.62,380.45]],"ltp":4.8,"tv":390.97,"id":7445998},{"batb":[[0,1.22,457.38],[1,1.13,1.28],[2,1.11,269.55]],"ltp":1.27,"tv":2982.97,"id":9629022}]}]}
{"op":"mcm","clk":"4227946804","pt":1631458530061,"mc":[{"id":"1.187551081","rc":[{"batb":[[0,4.9,1.24],[1,3.8,54.93],[2,2.66,3.21]],"ltp":4.8,"tv":390.97,"id":7445998}]}]}
{"op":"mcm","clk":"4227947785","pt":1631458538475,"mc":[{"id":"1.187551081","rc":[{"batl":[[0,810,0.07],[1,810,0]],"ltp":4.8,"tv":390.97,"id":7445998}]}]}
{"op":"mcm","clk":"4227948133","pt":1631458541575,"mc":[{"id":"1.187551081","rc":[{"batb":[[0,4.9,61.7],[1,4.3,83.4]],"ltp":4.8,"tv":390.97,"id":7445998},{"batb":[[1,1.19,543.38],[2,1.13,1.28]],"ltp":1.27,"tv":2982.97,"id":9629022}]}]}
{"op":"mcm","clk":"4227948205","pt":1631458542277,"mc":[{"id":"1.187551081","rc":[{"batl":[[0,7.8,87.04],[1,810,0.07]],"ltp":4.8,"tv":390.97,"id":7445998}]}]}
{"op":"mcm","clk":"4227948538","pt":1631458545300,"mc":[{"id":"1.187551081","rc":[{"trd":[[5.6,22.35]],"ltp":5.6,"tv":391.53,"id":7445998},{"trd":[[1.22,183.44]],"batb":[[0,1.22,452.26]],"batl":[[0,1.29,40],[1,3.8,27.47],[2,8.8,7.23]],"ltp":1.22,"tv":2990.61,"id":9629022}],"tv":3382.15}]}
{"op":"mcm","clk":"4227948937","pt":1631458548499,"mc":[{"id":"1.187551081","rc":[{"batb":[[2,3,5.93]],"ltp":5.6,"tv":391.53,"id":7445998},{"batb":[[2,1.17,93.74]],"batl":[[1,1.33,87.9],[2,1.34,87.51]],"ltp":1.22,"tv":2990.61,"id":9629022}]}]}
{"op":"mcm","clk":"4227949262","pt":1631458551103,"mc":[{"id":"1.187551081","rc":[{"batb":[[1,1.19,635.55]],"ltp":1.22,"tv":2990.61,"id":9629022}]}]}
{"op":"mcm","clk":"4227949760","pt":1631458555524,"mc":[{"id":"1.187551081","rc":[{"batb":[[0,4.9,1.24]],"ltp":5.6,"tv":391.53,"id":7445998},{"batb":[[0,1.19,543.38],[1,1.13,1.28],[2,1.05,474.41]],"batl":[[1,3.8,27.47],[2,8.8,7.23]],"ltp":1.22,"tv":2990.61,"id":9629022}]}]}
{"op":"mcm","clk":"4227951242","pt":1631458566517,"mc":[{"id":"1.187551081","rc":[{"trd":[[4.9,2.48]],"batb":[[0,4.3,83.4],[1,2.66,3.21],[2,2.62,380.45]],"batl":[[0,810,0.07],[1,810,0]],"ltp":4.9,"tv":394.01,"id":7445998}],"tv":3384.63}]}
{"op":"mcm","clk":"4227951400","pt":1631458567631,"mc":[{"id":"1.187551081","rc":[{"batb":[[1,3.7,58.37],[2,2.66,3.21]],"ltp":4.9,"tv":394.01,"id":7445998},{"batb":[[0,1.26,371.13],[1,1.22,459.89],[2,1.13,1.28]],"ltp":1.22,"tv":2990.61,"id":9629022}]}]}
{"op":"mcm","clk":"4227951604","pt":1631458569432,"mc":[{"id":"1.187551081","rc":[{"batl":[[0,6.6,97.86],[1,810,0.07]],"ltp":4.9,"tv":394.01,"id":7445998}]}]}
{"op":"mcm","clk":"4227951743","pt":1631458570605,"mc":[{"id":"1.187551081","rc":[{"batb":[[1,1.22,550.13]],"batl":[[1,1.34,87.82],[2,3.8,27.47]],"ltp":1.22,"tv":2990.61,"id":9629022}]}]}
{"op":"mcm","clk":"4227951833","pt":1631458571402,"mc":[{"id":"1.187551081","rc":[{"trd":[[4.9,3.13]],"ltp":4.9,"tv":394.67,"id":7445998},{"trd":[[1.26,12.79]],"batb":[[0,1.26,366.06]],"ltp":1.26,"tv":2998.19,"id":9629022}],"tv":3392.87}]}
{"op":"mcm","clk":"4227952276","pt":1631458574431,"mc":[{"id":"1.187551081","rc":[{"batl":[[1,1.33,92.25],[2,1.34,87.82]],"ltp":1.26,"tv":2998.19,"id":9629022}]}]}
{"op":"mcm","clk":"4227952682","pt":1631458577573,"mc":[{"id":"1.187551081","rc":[{"batb":[[1,1.23,95.19],[2,1.22,550.13]],"ltp":1.26,"tv":2998.19,"id":9629022}]}]}
{"op":"mcm","clk":"4227952998","pt":1631458579977,"mc":[{"id":"1.187551081","rc":[{"batb":[[0,3.7,58.37],[1,2.66,3.21],[2,2.62,380.45]],"ltp":4.9,"tv":394.67,"id":7445998},{"batb":[[0,1.22,459.89],[1,1.13,1.28],[2,1.05,474.41]],"batl":[[1,3.8,27.47],[2,8.8,7.23]],"ltp":1.26,"tv":2998.19,"id":9629022}]}]}
{"op":"mcm","clk":"4227953404","pt":1631458583194,"mc":[{"id":"1.187551081","rc":[{"batb":[[0,3.75,57.86]],"ltp":4.9,"tv":394.67,"id":7445998},{"batb":[[0,1.21,462.99]],"ltp":1.26,"tv":2998.19,"id":9629022}]}]}
{"op":"mcm","clk":"4227953880","pt":1631458587293,"mc":[{"id":"1.187551081","rc":[{"batb":[[0,4.9,60.04],[1,4.2,84.99],[2,2.66,3.21]],"ltp":4.9,"tv":394.67,"id":7445998},{"batb":[[1,1.18,559.71],[2,1.13,1.28]],"ltp":1.26,"tv":2998.19,"id":9629022}]}]}
{"op":"mcm","clk":"4227954174","pt":1631458589993,"mc":[{"id":"1.187551081","rc":[{"trd":[[4.9,7.27]],"batb":[[0,4.9,57.97]],"ltp":4.9,"tv":398.8,"id":7445998}],"tv":3397.0}]}
{"op":"mcm","clk":"4227955198","pt":1631458598822,"mc":[{"id":"1.187551081","rc":[{"batb":[[0,4.2,84.99],[1,2.66,3.21],[2,2.62,380.45]],"ltp":4.9,"tv":398.8,"id":7445998},{"batb":[[0,1.18,559.2],[1,1.13,1.28],[2,1.05,474.41]],"ltp":1.26,"tv":2998.19,"id":9629022}]}]}
{"op":"mcm","clk":"4227956444","pt":1631458608151,"mc":[{"id":"1.187551081","rc":[{"batb":[[2,2.6,3.71]],"batl":[[0,810,0.07],[1,810,0]],"ltp":4.9,"tv":398.8,"id":7445998}]}]}
{"op":"mcm","clk":"4227956923","pt":1631458611642,"mc":[{"id":"1.187551081","rc":[{"batb":[[0,5.6,44.97],[1,5,57.61],[2,4.2,84.99]],"ltp":4.9,"tv":398.8,"id":7445998},{"batb":[[1,1.16,640.51],[2,1.13,1.28]],"ltp":1.26,"tv":2998.19,"id":9629022}]}]}
{"op":"mcm","clk":"4227956954","pt":1631458611845,"mc":[{"id":"1.187551081","rc":[{"batl":[[0,8.6,81.16],[1,810,0.07]],"ltp":4.9,"tv":398.8,"id":7445998}]}]}
{"op":"mcm","clk":"4227958367","pt":1631458623043,"mc":[{"id":"1.187551081","rc":[{"batl":[[0,1.21,100],[1,1.29,40],[2,3.8,27.47]],"ltp":1.26,"tv":2998.19,"id":9629022}]}]}
{"op":"mcm","clk":"4227958685","pt":1631458625468,"mc":[{"id":"1.187551081","rc":[{"batb":[[0,5,57.61],[1,4.2,84.99],[2,3,5.93]],"ltp":4.9,"tv":398.8,"id":7445998},{"batb":[[0,1.16,640.51],[1,1.13,1.28],[2,1.05,474.41]],"ltp":1.26,"tv":2998.19,"id":9629022}]}]}
{"op":"mcm","clk":"4227958807","pt":1631458626364,"mc":[{"id":"1.187551081","rc":[{"batb":[[1,3,5.93],[2,2.9,377.47]],"ltp":4.9,"tv":398.8,"id":7445998}]}]}
{"op":"mcm","clk":"4227960753","pt":1631458642481,"mc":[{"id":"1.187551081","rc":[{"batl":[[0,810,0.07],[1,810,0]],"ltp":4.9,"tv":398.8,"id":7445998}]}]}
{"op":"mcm","clk":"4227960981","pt":1631458644282,"mc":[{"id":"1.187551081","rc":[{"trd":[[5.7,72.59]],"ltp":5.7,"tv":420.03,"id":7445998},{"trd":[[1.21,250.2]],"batl":[[0,1.29,40],[1,3.8,27.47],[2,8.8,7.23]],"ltp":1.21,"tv":3098.19,"id":9629022}],"tv":3518.23}]}
{"op":"mcm","clk":"4227961131","pt":1631458645505,"mc":[{"id":"1.187551081","rc":[{"batb":[[1,4.2,85.92],[2,3,5.93]],"ltp":5.7,"tv":420.03,"id":7445998},{"batb":[[0,1.21,476.05],[1,1.17,586.17],[2,1.13,1.28]],"ltp":1.21,"tv":3098.19,"id":9629022}]}]}
{"op":"mcm","clk":"4227961204","pt":1631458646092,"mc":[{"id":"1.187551081","rc":[{"batl":[[0,7.8,87.04],[1,810,0.07]],"ltp":5.7,"tv":420.03,"id":7445998}]}]}
{"op":"mcm","clk":"4227962267","pt":1631458655495,"mc":[{"id":"1.187551081","rc":[{"trd":[[5,37.94]],"batb":[[0,5,52.86]],"ltp":5.0,"tv":426.78,"id":7445998},{"trd":[[1.25,99.17]],"batb":[[0,1.24,9],[1,1.21,476.05],[2,1.17,586.17]],"ltp":1.25,"tv":3109.19,"id":9629022}],"tv":3535.98}]}
{"op":"mcm","clk":"4227962329","pt":1631458656014,"mc":[{"id":"1.187551081","rc":[{"batl":[[1,810,0]],"ltp":5.0,"tv":426.78,"id":7445998}]}]}
{"op":"mcm","clk":"4227962611","pt":1631458658605,"mc":[{"id":"1.187551081","rc":[{"batb":[[1,1.23,96.71],[2,1.21,476.05]],"batl":[[0,1.29,136.16]],"ltp":1.25,"tv":3109.19,"id":9629022}]}]}
{"op":"mcm","clk":"4227962692","pt":1631458659508,"mc":[{"id":"1.187551081","rc":[{"trd":[[5,42.75]],"batb":[[0,5,50.46]],"ltp":5.0,"tv":431.59,"id":7445998}],"tv":3540.79}]}
{"op":"mcm","clk":"4227962792","pt":1631458660534,"mc":[{"id":"1.187551081","rc":[{"batb":[[0,4.2,85.92],[1,3,5.93],[2,2.9,377.47]],"ltp":5.0,"tv":431.59,"id":7445998},{"batb":[[1,1.17,584.16],[2,1.13,1.28]],"batl":[[0,1.29,40]],"ltp":1.25,"tv":3109.19,"id":9629022}]}]}
{"op":"mcm","clk":"4227962963","pt":1631458662022,"mc":[{"id":"1.187551081","rc":[{"batb":[[0,1.17,584.16],[1,1.13,1.28],[2,1.05,474.41]],"ltp":1.25,"tv":3109.19,"id":9629022}]}]}
{"op":"mcm","clk":"4227963145","pt":1631458663607,"mc":[{"id":"1.187551081","rc":[{"batl":[[0,5.1,3],[1,7.8,87.04]],"ltp":5.0,"tv":431.59,"id":7445998}]}]}
{"op":"mcm","clk":"4227963391","pt":1631458665418,"mc":[{"id":"1.187551081","rc":[{"batb":[[0,4.4,2],[1,4.3,2],[2,4.2,85.92]],"batl":[[0,7,3]],"ltp":5.0,"tv":431.59,"id":7445998},{"batb":[[0,1.17,596.16],[1,1.16,16],[2,1.13,1.28]],"batl":[[0,1.29,49]],"ltp":1.25,"tv":3109.19,"id":9629022}]}]}
{"op":"mcm","clk":"4227963575","pt":1631458667109,"mc":[{"id":"1.187551081","rc":[{"batl":[[1,7.2,91.22]],"ltp":5.0,"tv":431.59,"id":7445998}]}]}
{"op":"mcm","clk":"4227963697","pt":1631458668331,"mc":[{"id":"1.187551081","rc":[{"trd":[[4.3,18.53],[4.4,2]],"batb":[[0,4.2,85.92],[1,3,5.93],[2,2.9,377.47]],"ltp":4.3,"tv":435.59,"id":7445998},{"trd":[[1.29,156.1],[1.3,16.77],[1.31,56.56]],"batb":[[0,1.31,214.27],[1,1.3,359.49],[2,1.17,596.16]],"batl":[[0,1.34,330.07],[1,1.35,287.39],[2,3.8,27.47]],"ltp":1.31,"tv":3220.52,"id":9629022}],"tv":3656.12}]}
{"op":"mcm","clk":"4227963742","pt":1631458668711,"mc":[{"id":"1.187551081","rc":[{"batb":[[1,2.9,377.47],[2,2.2,42.66]],"ltp":4.3,"tv":435.59,"id":7445998}]}]}
{"op":"mcm","clk":"4227963873","pt":1631458669822,"mc":[{"id":"1.187551081","rc":[{"batb":[[0,1.17,596.16],[1,1.16,16],[2,1.13,1.28]],"batl":[[0,3.8,27.47],[1,8.8,7.23],[2,44,7.23]],"ltp":1.31,"tv":3220.52,"id":9629022}]}]}
{"op":"mcm","clk":"4227964056","pt":1631458671538,"mc":[{"id":"1.187551081","rc":[{"batb":[[0,4.2,87.92],[1,4.1,2],[2,2.9,377.47]],"ltp":4.3,"tv":435.59,"id":7445998},{"batb":[[0,1.28,87.34],[1,1.17,596.16],[2,1.16,16]],"batl":[[0,1.32,7],[1,1.34,88.73],[2,3.8,27.47]],"ltp":1.31,"tv":3220.52,"id":9629022}]}]}
{"op":"mcm","clk":"4227964140","pt":1631458672333,"mc":[{"id":"1.187551081","rc":[{"batb":[[0,1.17,596.16],[1,1.16,16],[2,1.13,1.28]],"batl":[[1,3.8,27.47],[2,8.8,7.23]],"ltp":1.31,"tv":3220.52,"id":9629022}]}]}
{"op":"mcm","clk":"4227964182","pt":1631458672736,"mc":[{"id":"1.187551081","rc":[{"batb":[[0,1.25,324.14],[1,1.24,474.09],[2,1.17,596.16]],"batl":[[1,1.4,335.66],[2,1.41,235.74]],"ltp":1.31,"tv":3220.52,"id":9629022}]}]}
{"op":"mcm","clk":"4227966235","pt":1631458690654,"mc":[{"id":"1.187551081","rc":[{"batl":[[0,4.9,1517.22],[1,5.4,6.5],[2,7,3]],"ltp":4.3,"tv":435.59,"id":7445998}]}]}
{"op":"mcm","clk":"4227966358","pt":1631458691654,"mc":[{"id":"1.187551081","rc":[{"batb":[[1,2.9,377.47],[2,2.2,42.66]],"batl":[[0,7,3],[1,7.2,91.22],[2,7,0]],"ltp":4.3,"tv":435.59,"id":7445998},{"trd":[[1.25,695.29]],"batb":[[0,1.25,26.08]],"ltp":1.25,"tv":3816.65,"id":9629022}],"tv":4252.24}]}
{"op":"mcm","clk":"4227966477","pt":1631458692550,"mc":[{"id":"1.187551081","rc":[{"batb":[[0,1.24,474.09],[1,1.17,596.16],[2,1.13,1.28]],"batl":[[1,1.4,246.33],[2,3.8,27.47]],"ltp":1.25,"tv":3816.65,"id":9629022}]}]}
{"op":"mcm","clk":"4227966658","pt":1631458694109,"mc":[{"id":"1.187551081","rc":[{"batb":[[1,4.1,3],[2,2.9,377.47]],"ltp":4.3,"tv":435.59,"id":7445998}]}]}
{"op":"mcm","clk":"4227966849","pt":1631458695487,"mc":[{"id":"1.187551081","rc":[{"batb":[[0,1.24,634.91],[1,1.23,483.1],[2,1.17,596.16]],"batl":[[1,1.39,238.64],[2,1.4,246.33]],"ltp":1.25,"tv":3816.65,"id":9629022}]}]}
{"op":"mcm","clk":"4227967277","pt":1631458699579,"mc":[{"id":"1.187551081","rc":[{"trd":[[1.24,62.84]],"batb":[[0,1.24,603.49]],"ltp":1.24,"tv":3879.49,"id":9629022}],"tv":4315.08}]}
{"op":"mcm","clk":"4227967305","pt":1631458699901,"mc":[{"id":"1.187551081","rc":[{"batl":[[0,1.25,12.31],[1,1.32,7],[2,1.39,238.64]],"ltp":1.24,"tv":3879.49,"id":9629022}]}]}
{"op":"mcm","clk":"4227967669","pt":1631458703286,"mc":[{"id":"1.187551081","rc":[{"batb":[[2,3,5.93]],"ltp":4.3,"tv":435.59,"id":7445998}]}]}
{"op":"mcm","clk":"4227968372","pt":1631458710476,"mc":[{"id":"1.187551081","rc":[{"batb":[[0,4.2,85.92],[1,3,5.93],[2,2.9,377.47]],"ltp":4.3,"tv":435.59,"id":7445998},{"batl":[[1,3.8,27.47],[2,8.8,7.23]],"ltp":1.24,"tv":3879.49,"id":9629022}]}]}
{"op":"mcm","clk":"4227968463","pt":1631458711325,"mc":[{"id":"1.187551081","rc":[{"batl":[[1,7.2,0]],"ltp":4.3,"tv":435.59,"id":7445998}]}]}
{"op":"mcm","clk":"4227968740","pt":1631458713506,"mc":[{"id":"1.187551081","rc":[{"trd":[[5,44.75]],"batb":[[1,3.9,2],[2,3.85,3]],"ltp":5.0,"tv":437.59,"id":7445998},{"trd":[[1.25,711.92]],"batb":[[0,1.25,6.69],[1,1.24,612.49],[2,1.23,483.1]],"batl":[[0,1.27,332.67],[1,1.28,382.35],[2,3.8,27.47]],"ltp":1.25,"tv":3896.11,"id":9629022}],"tv":4333.7}]}
{"op":"mcm","clk":"4227968841","pt":1631458714412,"mc":[{"id":"1.187551081","rc":[{"trd":[[5.2,85.58]],"batb":[[0,4.9,58.95],[1,4.2,85.92],[2,3.9,2]],"ltp":5.2,"tv":523.17,"id":7445998},{"trd":[[1.24,421.73]],"batb":[[0,1.24,244.6],[1,1.23,483.1],[2,1.17,596.16]],"ltp":1.24,"tv":4255.0,"id":9629022}],"tv":4778.17}]}
{"op":"mcm","clk":"4227968993","pt":1631458715628,"mc":[{"id":"1.187551081","rc":[{"batl":[[1,9.8,74.69]],"ltp":5.2,"tv":523.17,"id":7445998}]}]}
{"op":"mcm","clk":"4227969201","pt":1631458717413,"mc":[{"id":"1.187551081","rc":[{"batb":[[0,1.24,384.43],[1,1.23,511.2]],"batl":[[0,1.27,560.44]],"ltp":1.24,"tv":4255.0,"id":9629022}]}]}
{"op":"mcm","clk":"4227969329","pt":1631458718440,"mc":[{"id":"1.187551081","rc":[{"trd":[[1.24,868.03]],"batb":[[0,1.17,12],[1,1.14,740.75],[2,1.13,1.28]],"batl":[[0,3.8,27.47],[1,8.8,7.23],[2,44,7.23]],"ltp":1.24,"tv":4701.3,"id":9629022}],"tv":5224.47}]}
{"op":"mcm","clk":"4227969560","pt":1631458720437,"mc":[{"id":"1.187551081","rc":[{"batb":[[2,4.1,53.81]],"batl":[[0,5.9,43],[1,6,45.28],[2,6.2,51.35]],"ltp":5.2,"tv":523.17,"id":7445998},{"batb":[[0,1.2,185.97],[1,1.19,180.96],[2,1.18,307.88]],"batl":[[0,1.32,167.72],[1,1.33,177.36],[2,1.34,200.13]],"ltp":1.24,"tv":4701.3,"id":9629022}]}]}
{"op":"mcm","clk":"4227969723","pt":1631458721614,"mc":[{"id":"1.187551081","rc":[{"batb":[[0,4.7,65.57],[1,4.1,53.81],[2,4,54.16]],"ltp":5.2,"tv":523.17,"id":7445998},{"batb":[[2,1.18,319.88]],"ltp":1.24,"tv":4701.3,"id":9629022}]}]}
{"op":"mcm","clk":"4227969842","pt":1631458722512,"mc":[{"id":"1.187551081","rc":[{"batb":[[0,1.2,512.2],[1,1.19,824.48],[2,1.18,307.88]],"batl":[[0,1.31,460.37],[1,1.32,496.46],[2,1.33,177.36]],"ltp":1.24,"tv":4701.3,"id":9629022}]}]}
{"op":"mcm","clk":"4227969960","pt":1631458723446,"mc":[{"id":"1.187551081","rc":[{"trd":[[5.9,1.03]],"batl":[[0,5.9,42.49]],"ltp":5.9,"tv":524.2,"id":7445998},{"trd":[[1.2,31.9]],"batb":[[0,1.2,509.78]],"ltp":1.2,"tv":4706.13,"id":9629022}],"tv":5230.33}]}
{"op":"mcm","clk":"4227970222","pt":1631458725616,"mc":[{"id":"1.187551081","rc":[{"batb":[[1,3.9,2],[2,3.85,3]],"ltp":5.9,"tv":524.2,"id":7445998},{"batl":[[0,3.8,27.47],[1,8.8,7.23],[2,44,7.23]],"ltp":1.2,"tv":4706.13,"id":9629022}]}]}
{"op":"mcm","clk":"4227970364","pt":1631458726525,"mc":[{"id":"1.187551081","rc":[{"batb":[[2,3,5.93]],"ltp":5.9,"tv":524.2,"id":7445998}]}]}
{"op":"mcm","clk":"4227970632","pt":1631458728540,"mc":[{"id":"1.187551081","rc":[{"batl":[[0,6,45.28],[1,6.2,51.35],[2,6.2,0]],"ltp":5.9,"tv":524.2,"id":7445998},{"batl":[[0,1.22,5376.67],[1,1.23,491.57],[2,3.8,27.47]],"ltp":1.2,"tv":4706.13,"id":9629022}]}]}
{"op":"mcm","clk":"4227970742","pt":1631458729518,"mc":[{"id":"1.187551081","rc":[{"trd":[[6,115.65]],"batb":[[0,5.5,46.89]],"batl":[[0,6.2,51.35],[1,6.2,0]],"ltp":6.0,"tv":635.13,"id":7445998},{"trd":[[1.2,138.57]],"batb":[[0,1.2,382.79]],"batl":[[0,1.22,444.71]],"ltp":1.2,"tv":4812.81,"id":9629022}],"tv":5447.94}]}
{"op":"mcm","clk":"4227970960","pt":1631458731440,"mc":[{"id":"1.187551081","rc":[{"batb":[[1,4.8,2],[2,4.7,2]],"batl":[[1,11.5,69.66]],"ltp":6.0,"tv":635.13,"id":7445998}]}]}
{"op":"mcm","clk":"4227971087","pt":1631458732555,"mc":[{"id":"1.187551081","rc":[{"batl":[[0,1.22,467.1]],"ltp":1.2,"tv":4812.81,"id":9629022}]}]}
{"op":"mcm","clk":"4227971210","pt":1631458733458,"mc":[{"id":"1.187551081","rc":[{"trd":[[1.2,556.75]],"batb":[[0,1.2,173.7]],"batl":[[2,1.28,103.05]],"ltp":1.2,"tv":5230.99,"id":9629022}],"tv":5866.12}]}
{"op":"mcm","clk":"4227971469","pt":1631458735652,"mc":[{"id":"1.187551081","rc":[{"batl":[[2,1.26,118.24]],"ltp":1.2,"tv":5230.99,"id":9629022}]}]}
{"op":"mcm","clk":"4227971675","pt":1631458737654,"mc":[{"id":"1.187551081","rc":[{"batl":[[0,11.5,69.66],[1,11.5,0]],"ltp":6.0,"tv":635.13,"id":7445998},{"batb":[[0,1.15,690.59],[1,1.13,1.28],[2,1.12,876.24]],"batl":[[0,3.8,27.47],[1,8.8,7.23],[2,44,7.23]],"ltp":1.2,"tv":5230.99,"id":9629022}]}]}
{"op":"mcm","clk":"4227971702","pt":1631458737854,"mc":[{"id":"1.187551081","rc":[{"batb":[[0,1.13,1.28],[1,1.12,876.24],[2,1.05,474.41]],"ltp":1.2,"tv":5230.99,"id":9629022}]}]}
{"op":"mcm","clk":"4227972035","pt":1631458740642,"mc":[{"id":"1.187551081","rc":[{"batb":[[0,1.16,615.68],[1,1.15,580.27],[2,1.13,1.28]],"batl":[[0,1.26,421.38],[1,1.27,407.54],[2,3.8,27.47]],"ltp":1.2,"tv":5230.99,"id":9629022}]}]}
{"op":"mcm","clk":"4227972085","pt":1631458741194,"mc":[{"id":"1.187551081","rc":[{"batb":[[0,5.3,51]],"batl":[[0,9.4,2],[1,11.5,69.66]],"ltp":6.0,"tv":635.13,"id":7445998},{"batb":[[2,1.13,831.13]],"batl":[[1,1.27,415.54]],"ltp":1.2,"tv":5230.99,"id":9629022}]}]}
{"op":"mcm","clk":"4227972335","pt":1631458743251,"mc":[{"id":"1.187551081","rc":[{"batb":[[2,3.15,375.55]],"ltp":6.0,"tv":635.13,"id":7445998},{"batl":[[0,1.27,8],[1,3.8,27.47],[2,8.8,7.23]],"ltp":1.2,"tv":5230.99,"id":9629022}]}]}
{"op":"mcm","clk":"4227972507","pt":1631458744658,"mc":[{"id":"1.187551081","rc":[{"batl":[[1,11.5,0]],"ltp":6.0,"tv":635.13,"id":7445998},{"batl":[[0,1.24,12],[1,1.27,8],[2,3.8,27.47]],"ltp":1.2,"tv":5230.99,"id":9629022}]}]}
{"op":"mcm","clk":"4227972712","pt":1631458746304,"mc":[{"id":"1.187551081","rc":[{"batl":[[0,1.18,477.42],[1,1.19,617.05],[2,1.24,12]],"ltp":1.2,"tv":5230.99,"id":9629022}]}]}
{"op":"mcm","clk":"4227972899","pt":1631458747592,"mc":[{"id":"1.187551081","rc":[{"trd":[[7.2,14.26]],"batb":[[0,7.2,45.74],[1,6.2,69.92],[2,5.4,2]],"ltp":7.2,"tv":641.13,"id":7445998},{"batb":[[0,1.16,587.32]],"batl":[[2,1.23,12]],"ltp":1.2,"tv":5230.99,"id":9629022}],"tv":5872.12}]}
{"op":"mcm","clk":"4227973103","pt":1631458749089,"mc":[{"id":"1.187551081","rc":[{"batl":[[1,14,62.31]],"ltp":7.2,"tv":641.13,"id":7445998}]}]}
{"op":"mcm","clk":"4227973254","pt":1631458750163,"mc":[{"id":"1.187551081","rc":[{"batb":[[1,1.15,608.88]],"batl":[[0,1.18,505.35]],"ltp":1.2,"tv":5230.99,"id":9629022}]}]}
{"op":"mcm","clk":"4227973418","pt":1631458751297,"mc":[{"id":"1.187551081","rc":[{"trd":[[1.16,419.6]],"batb":[[0,1.16,389.52]],"batl":[[1,1.19,595.75]],"ltp":1.16,"tv":5626.59,"id":9629022}],"tv":6267.72}]}
{"op":"mcm","clk":"4227973642","pt":1631458752999,"mc":[{"id":"1.187551081","rc":[{"batl":[[0,8.8,30.45],[1,9,39.23],[2,9.2,44.41]],"ltp":7.2,"tv":641.13,"id":7445998},{"batb":[[2,1.13,1087.31]],"ltp":1.16,"tv":5626.59,"id":9629022}]}]}
{"op":"mcm","clk":"4227973777","pt":1631458754069,"mc":[{"id":"1.187551081","rc":[{"batb":[[0,1.16,476.88],[1,1.15,717.73]],"batl":[[0,1.18,611.41]],"ltp":1.16,"tv":5626.59,"id":9629022}]}]}
{"op":"mcm","clk":"4227973962","pt":1631458755513,"mc":[{"id":"1.187551081","rc":[{"trd":[[1.16,819.6]],"batb":[[0,1.16,276.88]],"batl":[[1,1.19,486.66]],"ltp":1.16,"tv":6026.59,"id":9629022}],"tv":6667.72}]}
{"op":"mcm","clk":"4227974077","pt":1631458756396,"mc":[{"id":"1.187551081","rc":[{"trd":[[1.16,996.17]],"batb":[[0,1.16,188.6]],"batl":[[1,1.19,439.11]],"ltp":1.16,"tv":6203.15,"id":9629022}],"tv":6844.29}]}
{"op":"mcm","clk":"4227974329","pt":1631458758628,"mc":[{"id":"1.187551081","rc":[{"batb":[[0,1.16,279.21],[1,1.15,830.62],[2,1.13,1267.36]],"batl":[[0,1.18,679.98],[2,1.21,168.15]],"ltp":1.16,"tv":6203.15,"id":9629022}]}]}
{"op":"mcm","clk":"4227974434","pt":1631458759420,"mc":[{"id":"1.187551081","rc":[{"trd":[[7.2,20.26]],"batb":[[0,7.2,42.73]],"ltp":7.2,"tv":647.13,"id":7445998},{"batb":[[0,1.16,318.71],[1,1.15,863.87]],"batl":[[0,1.18,727.93]],"ltp":1.16,"tv":6203.15,"id":9629022}],"tv":6850.29}]}
{"op":"mcm","clk":"4227974499","pt":1631458759937,"mc":[{"id":"1.187551081","rc":[{"batb":[[0,6.2,69.92],[1,5.4,2],[2,5.3,35.69]],"ltp":7.2,"tv":647.13,"id":7445998},{"batb":[[0,1.13,257.47],[1,1.12,333.1],[2,1.11,289.89]],"batl":[[0,1.23,12],[1,1.24,174.67],[2,1.25,182.12]],"ltp":1.16,"tv":6203.15,"id":9629022}]}]}
{"op":"mcm","clk":"4227974869","pt":1631458763490,"mc":[{"id":"1.187551081","rc":[{"batb":[[1,6,72.18],[2,5.4,2]],"ltp":7.2,"tv":647.13,"id":7445998},{"batb":[[0,1.13,971.16],[1,1.12,846.53],[2,1.11,1300.52]],"batl":[[0,1.2,11],[1,1.21,630.84],[2,1.22,506.71]],"ltp":1.16,"tv":6203.15,"id":9629022}]}]}
{"op":"mcm","clk":"4227974961","pt":1631458764279,"mc":[{"id":"1.187551081","rc":[{"batb":[[0,6,72.18],[1,5.4,2],[2,5.3,35.69]],"batl":[[0,9.4,2],[1,14,62.31],[2,9.2,0]],"ltp":7.2,"tv":647.13,"id":7445998},{"batb":[[0,1.13,1.28],[1,1.12,22],[2,1.11,1010.63]],"ltp":1.16,"tv":6203.15,"id":9629022}]}]}
{"op":"mcm","clk":"4227975150","pt":1631458766241,"mc":[{"id":"1.187551081","rc":[{"batl":[[1,14,0]],"ltp":7.2,"tv":647.13,"id":7445998},{"batl":[[0,1.21,630.84],[1,1.22,506.71],[2,1.23,12]],"ltp":1.16,"tv":6203.15,"id":9629022}]}]}
{"op":"mcm","clk":"4227975251","pt":1631458767278,"mc":[{"id":"1.187551081","rc":[{"batb":[[0,1.19,248.72],[1,1.18,695.11],[2,1.13,1.28]],"ltp":1.16,"tv":6203.15,"id":9629022}]}]}
{"op":"mcm","clk":"4227975323","pt":1631458768109,"mc":[{"id":"1.187551081","rc":[{"batb":[[2,1.16,650.64]],"ltp":1.16,"tv":6203.15,"id":9629022}]}]}
{"op":"mcm","clk":"4227975432","pt":1631458769197,"mc":[{"id":"1.187551081","rc":[{"batl":[[0,9.2,2],[1,9.4,2]],"ltp":7.2,"tv":647.13,"id":7445998}]}]}
{"op":"mcm","clk":"4227975583","pt":1631458770394,"mc":[{"id":"1.187551081","rc":[{"batl":[[2,11.5,69.66]],"ltp":7.2,"tv":647.13,"id":7445998}]}]}
{"op":"mcm","clk":"4227975803","pt":1631458772411,"mc":[{"id":"1.187551081","rc":[{"trd":[[6.4,15.06]],"ltp":6.4,"tv":648.1,"id":7445998},{"trd":[[1.19,263.74]],"batb":[[0,1.19,176.97],[2,1.16,833.08]],"ltp":1.19,"tv":6341.43,"id":9629022}],"tv":6989.54}]}
{"op":"mcm","clk":"4227975998","pt":1631458773970,"mc":[{"id":"1.187551081","rc":[{"batl":[[0,7.8,29.77],[1,8,32.83],[2,8.2,34.92]],"ltp":6.4,"tv":648.1,"id":7445998}]}]}
{"op":"mcm","clk":"4227976320","pt":1631458776601,"mc":[{"id":"1.187551081","rc":[{"trd":[[1.19,336.04]],"batb":[[0,1.19,140.82]],"ltp":1.19,"tv":6413.73,"id":9629022}],"tv":7061.84}]}
{"op":"mcm","clk":"4227976376","pt":1631458777092,"mc":[{"id":"1.187551081","rc":[{"batb":[[0,1.18,695.11],[1,1.16,833.08],[2,1.15,257.2]],"ltp":1.19,"tv":6413.73,"id":9629022}]}]}
{"op":"mcm","clk":"4227976751","pt":1631458780312,"mc":[{"id":"1.187551081","rc":[{"batl":[[0,6.4,3],[1,7.8,29.77],[2,8,32.83]],"ltp":6.4,"tv":648.1,"id":7445998},{"batb":[[0,1.19,13],[1,1.18,864.79],[2,1.17,508.87]],"batl":[[2,1.23,191]],"ltp":1.19,"tv":6413.73,"id":9629022}]}]}
{"op":"mcm","clk":"4227976910","pt":1631458781587,"mc":[{"id":"1.187551081","rc":[{"batl":[[1,1.22,475.16]],"ltp":1.19,"tv":6413.73,"id":9629022}]}]}
{"op":"mcm","clk":"4227977300","pt":1631458784612,"mc":[{"id":"1.187551081","rc":[{"trd":[[6.4,23.06]],"batb":[[0,5.4,2],[1,5.1,54.35],[2,4.5,39.78]],"batl":[[0,7.8,29.77],[1,8,32.83],[2,8.2,34.92]],"ltp":6.4,"tv":656.1,"id":7445998},{"trd":[[1.19,346.8]],"batb":[[0,1.19,2.24],[1,1.18,12],[2,1.17,188.18]],"batl":[[0,1.23,191],[1,1.24,170.67],[2,1.28,186.87]],"ltp":1.19,"tv":6424.49,"id":9629022}],"tv":7080.6}]}
{"op":"mcm","clk":"4227977317","pt":1631458784703,"mc":[{"id":"1.187551081","rc":[{"batb":[[2,1.15,257.2]],"batl":[[0,1.23,12],[1,1.28,186.87],[2,1.29,156.83]],"ltp":1.19,"tv":6424.49,"id":9629022}]}]}
{"op":"mcm","clk":"4227977880","pt":1631458789220,"mc":[{"id":"1.187551081","rc":[{"batb":[[0,5.1,54.35],[1,4.5,39.78],[2,4.4,50.98]],"ltp":6.4,"tv":656.1,"id":7445998},{"batb":[[0,1.15,257.2],[1,1.14,282.89],[2,1.13,322.49]],"batl":[[0,1.28,186.87],[1,1.29,156.83],[2,1.3,193.08]],"ltp":1.19,"tv":6424.49,"id":9629022}]}]}
{"op":"mcm","clk":"4227978001","pt":1631458790113,"mc":[{"id":"1.187551081","rc":[{"batb":[[0,1.18,287.15],[1,1.17,748.4],[2,1.15,257.2]],"batl":[[0,1.2,598.13],[1,1.21,548.55],[2,1.28,186.87]],"ltp":1.19,"tv":6424.49,"id":9629022}]}]}
{"op":"mcm","clk":"4227978265","pt":1631458792418,"mc":[{"id":"1.187551081","rc":[{"batb":[[0,5.1,57.35],[1,5,3],[2,4.5,39.78]],"ltp":6.4,"tv":656.1,"id":7445998},{"batl":[[2,1.25,11]],"ltp":1.19,"tv":6424.49,"id":9629022}]}]}
{"op":"mcm","clk":"4227978443","pt":1631458794011,"mc":[{"id":"1.187551081","rc":[{"batb":[[0,1.15,257.2],[1,1.14,282.89],[2,1.13,322.49]],"batl":[[0,1.25,11],[1,1.28,196.87],[2,1.29,156.83]],"ltp":1.19,"tv":6424.49,"id":9629022}]}]}
{"op":"mcm","clk":"4227978765","pt":1631458797020,"mc":[{"id":"1.187551081","rc":[{"batb":[[0,1.15,498.1],[1,1.14,1215.88]],"batl":[[0,1.25,357.01],[1,1.26,436.32],[2,1.28,196.87]],"ltp":1.19,"tv":6424.49,"id":9629022}]}]}
{"op":"mcm","clk":"4227980598","pt":1631458810328,"mc":[{"id":"1.187551081","rc":[{"batb":[[1,4.5,39.78],[2,4.4,50.98]],"batl":[[0,12.5,65.62],[1,8,0],[2,8.2,0]],"ltp":6.4,"tv":656.1,"id":7445998},{"batb":[[0,1.13,1.28],[1,1.12,862.17],[2,1.03,494.18]],"batl":[[2,1.28,186.87]],"ltp":1.19,"tv":6424.49,"id":9629022}]}]}
{"op":"mcm","clk":"4227981030","pt":1631458813525,"mc":[{"id":"1.187551081","rc":[{"batb":[[0,5.1,54.35],[1,5,2],[2,4.5,39.78]],"ltp":6.4,"tv":656.1,"id":7445998},{"batb":[[0,1.23,252.06],[1,1.22,621.56],[2,1.13,1.28]],"batl":[[0,1.25,346.01]],"ltp":1.19,"tv":6424.49,"id":9629022}]}]}
{"op":"mcm","clk":"4227981143","pt":1631458814375,"mc":[{"id":"1.187551081","rc":[{"batb":[[1,4.5,39.78],[2,4.4,50.98]],"ltp":6.4,"tv":656.1,"id":7445998},{"batb":[[2,1.21,494.47]],"ltp":1.19,"tv":6424.49,"id":9629022}]}]}
{"op":"mcm","clk":"4227981287","pt":1631458815543,"mc":[{"id":"1.187551081","rc":[{"batl":[[0,9.8,74.69]],"ltp":6.4,"tv":656.1,"id":7445998}]}]}
{"op":"mcm","clk":"4227981388","pt":1631458816242,"mc":[{"id":"1.187551081","rc":[{"batl":[[0,5.3,3],[1,5.5,3],[2,9.2,2]],"ltp":6.4,"tv":656.1,"id":7445998}]}]}
{"op":"mcm","clk":"4227981509","pt":1631458817253,"mc":[{"id":"1.187551081","rc":[{"batb":[[2,1.21,687.07]],"batl":[[2,1.27,183.5]],"ltp":1.19,"tv":6424.49,"id":9629022}]}]}
{"op":"mcm","clk":"4227981600","pt":1631458818175,"mc":[{"id":"1.187551081","rc":[{"trd":[[5.3,1.3]],"batl":[[0,5.3,2.35]],"ltp":5.3,"tv":657.4,"id":7445998},{"trd":[[1.23,121.17]],"batb":[[0,1.23,192.85]],"ltp":1.23,"tv":6542.91,"id":9629022}],"tv":7200.31}]}
{"op":"mcm","clk":"4227981823","pt":1631458820145,"mc":[{"id":"1.187551081","rc":[{"batl":[[2,6.8,30.54]],"ltp":5.3,"tv":657.4,"id":7445998}]}]}
{"op":"mcm","clk":"4227981955","pt":1631458821177,"mc":[{"id":"1.187551081","rc":[{"batb":[[0,1.23,218.09]],"batl":[[0,1.25,376.67]],"ltp":1.23,"tv":6542.91,"id":9629022}]}]}
{"op":"mcm","clk":"4227982406","pt":1631458824949,"mc":[{"id":"1.187551081","rc":[{"batb":[[1,1.22,551.13]],"ltp":1.23,"tv":6542.91,"id":9629022}]}]}
{"op":"mcm","clk":"4227982684","pt":1631458827557,"mc":[{"id":"1.187551081","rc":[{"trd":[[5.3,3.16]],"batl":[[0,5.3,1.42]],"ltp":5.3,"tv":659.26,"id":7445998}],"tv":7202.17}]}
{"op":"mcm","clk":"4227982699","pt":1631458827789,"mc":[{"id":"1.187551081","rc":[{"batl":[[1,6.8,30.54],[2,7,42.39]],"ltp":5.3,"tv":659.26,"id":7445998}]}]}
{"op":"mcm","clk":"4227983031","pt":1631458831444,"mc":[{"id":"1.187551081","rc":[{"batb":[[1,1.22,729.15]],"batl":[[1,1.26,608.69]],"ltp":1.23,"tv":6542.91,"id":9629022}]}]}
{"op":"mcm","clk":"4227983658","pt":1631458836081,"mc":[{"id":"1.187551081","rc":[{"batb":[[0,4.2,84.49],[1,3.95,55.45],[2,3.9,56.16]],"batl":[[0,6.8,30.54],[1,7,42.39],[2,7.2,46.07]],"ltp":5.3,"tv":659.26,"id":7445998},{"batb":[[0,1.17,198.32],[1,1.16,220.73],[2,1.15,950.21]],"batl":[[0,1.34,166.93],[1,1.35,156.93],[2,1.36,204.22]],"ltp":1.23,"tv":6542.91,"id":9629022}]}]}
{"op":"mcm","clk":"4227984023","pt":1631458839290,"mc":[{"id":"1.187551081","rc":[{"batb":[[0,4.2,87.49],[1,4.1,3],[2,3.95,55.45]],"batl":[[0,6.8,33.54]],"ltp":5.3,"tv":659.26,"id":7445998},{"batb":[[0,1.17,941.76],[1,1.16,694.97]],"batl":[[0,1.31,289.69],[1,1.32,349.93],[2,1.34,166.93]],"ltp":1.23,"tv":6542.91,"id":9629022}]}]}
{"op":"mcm","clk":"4227984164","pt":1631458840461,"mc":[{"id":"1.187551081","rc":[{"batb":[[0,1.17,214.32],[1,1.16,237.73]],"batl":[[0,1.31,8],[1,1.32,10]],"ltp":1.23,"tv":6542.91,"id":9629022}]}]}
{"op":"mcm","clk":"4227984529","pt":1631458843394,"mc":[{"id":"1.187551081","rc":[{"batb":[[0,1.23,209.55],[1,1.22,551.14],[2,1.17,214.32]],"batl":[[0,1.25,387.82],[1,1.26,436.36],[2,1.31,8]],"ltp":1.23,"tv":6542.91,"id":9629022}]}]}
{"op":"mcm","clk":"4227984950","pt":1631458846628,"mc":[{"id":"1.187551081","rc":[{"batb":[[1,1.22,717.77]],"batl":[[1,1.26,597.7]],"ltp":1.23,"tv":6542.91,"id":9629022}]}]}
{"op":"mcm","clk":"4227984973","pt":1631458846824,"mc":[{"id":"1.187551081","rc":[{"batb":[[0,1.17,214.32],[1,1.16,237.73],[2,1.15,950.21]],"batl":[[0,1.31,8],[1,1.32,10],[2,1.34,166.93]],"ltp":1.23,"tv":6542.91,"id":9629022}]}]}
{"op":"mcm","clk":"4227985430","pt":1631458850254,"mc":[{"id":"1.187551081","rc":[{"batb":[[0,1.17,941.76],[1,1.16,694.97]],"batl":[[0,1.23,4],[1,1.31,289.69],[2,1.32,349.93]],"ltp":1.23,"tv":6542.91,"id":9629022}]}]}
{"op":"mcm","clk":"4227985651","pt":1631458851912,"mc":[{"id":"1.187551081","rc":[{"batb":[[1,3.95,55.45],[2,3.9,56.16]],"ltp":5.3,"tv":659.26,"id":7445998},{"batb":[[0,1.17,214.32],[1,1.16,220.73]],"batl":[[1,1.31,8],[2,1.34,166.93]],"ltp":1.23,"tv":6542.91,"id":9629022}]}]}
{"op":"mcm","clk":"4227985981","pt":1631458854633,"mc":[{"id":"1.187551081","rc":[{"batb":[[0,1.21,733.48],[1,1.2,411.66],[2,1.17,214.32]],"batl":[[0,1.24,488.98],[1,1.25,455.06],[2,1.31,8]],"ltp":1.23,"tv":6542.91,"id":9629022}]}]}
{"op":"mcm","clk":"4227986034","pt":1631458855035,"mc":[{"id":"1.187551081","rc":[{"batb":[[1,4.1,3],[2,3.95,55.45]],"ltp":5.3,"tv":659.26,"id":7445998}]}]}
{"op":"mcm","clk":"4227986173","pt":1631458856228,"mc":[{"id":"1.187551081","rc":[{"batb":[[0,1.17,214.32],[1,1.16,225.73],[2,1.15,950.21]],"batl":[[0,1.31,8],[1,1.34,166.93],[2,1.35,156.93]],"ltp":1.23,"tv":6542.91,"id":9629022}]}]}
{"op":"mcm","clk":"4227986529","pt":1631458859168,"mc":[{"id":"1.187551081","rc":[{"batb":[[0,1.17,941.76],[1,1.16,682.97]],"batl":[[0,1.31,289.69],[1,1.32,339.93],[2,1.34,166.93]],"ltp":1.23,"tv":6542.91,"id":9629022}]}]}
{"op":"mcm","clk":"4227987565","pt":1631458866660,"mc":[{"id":"1.187551081","rc":[{"batb":[[1,3.95,55.45],[2,3.9,56.16]],"batl":[[0,6.8,3],[1,9.8,74.69],[2,7.2,0]],"ltp":5.3,"tv":659.26,"id":7445998},{"batb":[[0,1.17,16],[1,1.15,685.98],[2,1.13,1.28]],"ltp":1.23,"tv":6542.91,"id":9629022}]}]}
{"op":"mcm","clk":"4227987740","pt":1631458868059,"mc":[{"id":"1.187551081","rc":[{"batl":[[1,9.8,0]],"ltp":5.3,"tv":659.26,"id":7445998}]}]}
{"op":"mcm","clk":"4227987923","pt":1631458869476,"mc":[{"id":"1.187551081","rc":[{"batb":[[0,4.2,84.49]],"ltp":5.3,"tv":659.26,"id":7445998},{"batb":[[0,1.28,7984.27],[1,1.27,435.37],[2,1.17,16]],"batl":[[0,1.31,281.69]],"ltp":1.23,"tv":6542.91,"id":9629022}]}]}
{"op":"mcm","clk":"4227988116","pt":1631458870648,"mc":[{"id":"1.187551081","rc":[{"batb":[[0,1.28,580.04],[1,1.27,803.15],[2,1.21,492.55]],"ltp":1.23,"tv":6542.91,"id":9629022}]}]}
{"op":"mcm","clk":"4227988384","pt":1631458872385,"mc":[{"id":"1.187551081","rc":[{"batl":[[0,4.5,3],[1,6.6,2],[2,6.8,3]],"ltp":5.3,"tv":659.26,"id":7445998}]}]}
{"op":"mcm","clk":"4227988711","pt":1631458874518,"mc":[{"id":"1.187551081","rc":[{"trd":[[4.5,1.64]],"batl":[[0,4.5,2.18]],"ltp":4.5,"tv":660.9,"id":7445998},{"trd":[[1.28,61.38]],"batb":[[0,1.28,563.4],[1,1.27,963.22]],"batl":[[1,1.32,493.94]],"ltp":1.28,"tv":6576.19,"id":9629022}],"tv":7237.09}]}
{"op":"mcm","clk":"4227988819","pt":1631458875302,"mc":[{"id":"1.187551081","rc":[{"batb":[[0,1.29,8],[1,1.28,571.4],[2,1.27,963.22]],"ltp":1.28,"tv":6576.19,"id":9629022}]}]}
{"op":"mcm","clk":"4227988971","pt":1631458876513,"mc":[{"id":"1.187551081","rc":[{"batb":[[0,4.2,192.96]],"batl":[[1,5.3,46.96],[2,5.4,39.3]],"ltp":4.5,"tv":660.9,"id":7445998},{"batl":[[1,1.32,839.05]],"ltp":1.28,"tv":6576.19,"id":9629022}]}]}
{"op":"mcm","clk":"4227989200","pt":1631458878017,"mc":[{"id":"1.187551081","rc":[{"batl":[[1,4.6,114.44],[2,5.3,46.96]],"ltp":4.5,"tv":660.9,"id":7445998},{"batb":[[2,1.27,1377.73]],"ltp":1.28,"tv":6576.19,"id":9629022}]}]}
{"op":"mcm","clk":"4227989621","pt":1631458881302,"mc":[{"id":"1.187551081","rc":[{"batb":[[1,1.28,678.49]],"ltp":1.28,"tv":6576.19,"id":9629022}]}]}
{"op":"mcm","clk":"4227989741","pt":1631458882107,"mc":[{"id":"1.187551081","rc":[{"batb":[[0,3.6,62.47],[1,3.45,61.95],[2,3.4,60.33]],"batl":[[0,5.3,46.96],[1,5.4,39.3],[2,5.5,52.21]],"ltp":4.5,"tv":660.9,"id":7445998},{"batb":[[0,1.23,184.88],[1,1.22,233.09],[2,1.21,762.6]],"batl":[[0,1.41,145.37],[1,1.42,139.73],[2,1.43,185.69]],"ltp":1.28,"tv":6576.19,"id":9629022}]}]}
{"op":"mcm","clk":"4227989820","pt":1631458882722,"mc":[{"id":"1.187551081","rc":[{"batb":[[0,4.6,2],[1,3.6,62.47],[2,3.45,61.95]],"ltp":4.5,"tv":660.9,"id":7445998}]}]}
{"op":"mcm","clk":"4227990252","pt":1631458885629,"mc":[{"id":"1.187551081","rc":[{"batb":[[1,3.6,64.47],[2,3.55,3]],"batl":[[0,6.6,2],[1,7.2,91.22],[2,5.5,0]],"ltp":4.5,"tv":660.9,"id":7445998},{"batb":[[0,1.22,687.44],[1,1.21,941.16],[2,1.18,13]],"batl":[[0,1.38,338.83],[1,1.39,271.01],[2,1.41,145.37]],"ltp":1.28,"tv":6576.19,"id":9629022}]}]}
{"op":"mcm","clk":"4227990291","pt":1631458885902,"mc":[{"id":"1.187551081","rc":[{"batb":[[0,3.6,64.47],[1,3.55,3],[2,3.45,61.95]],"ltp":4.5,"tv":660.9,"id":7445998},{"batb":[[0,1.21,492.55],[1,1.18,13],[2,1.13,1.28]],"ltp":1.28,"tv":6576.19,"id":9629022}]}]}
{"op":"mcm","clk":"4227990637","pt":1631458888533,"mc":[{"id":"1.187551081","rc":[{"batb":[[0,3.6,62.47],[1,3.45,61.95],[2,3.4,60.33]],"batl":[[1,7.2,0]],"ltp":4.5,"tv":660.9,"id":7445998},{"batb":[[0,1.34,7168.46],[1,1.21,492.55],[2,1.18,13]],"batl":[[1,1.39,264.01]],"ltp":1.28,"tv":6576.19,"id":9629022}]}]}
{"op":"mcm","clk":"4227990770","pt":1631458889484,"mc":[{"id":"1.187551081","rc":[{"batl":[[1,1000,0.07]],"ltp":4.5,"tv":660.9,"id":7445998},{"batb":[[0,1.35,187.22],[1,1.34,665.33],[2,1.29,336.29]],"ltp":1.28,"tv":6576.19,"id":9629022}]}]}
{"op":"mcm","clk":"4227990821","pt":1631458889705,"mc":[{"id":"1.187551081","rc":[{"batl":[[1,1000,0]],"ltp":4.5,"tv":660.9,"id":7445998}]}]}
{"op":"mcm","clk":"4227991080","pt":1631458891638,"mc":[{"id":"1.187551081","rc":[{"batb":[[2,3.4,63.33]],"batl":[[0,5.7,3],[1,6.6,2]],"ltp":4.5,"tv":660.9,"id":7445998},{"batb":[[0,1.35,194.22],[1,1.34,673.33]],"ltp":1.28,"tv":6576.19,"id":9629022}]}]}
{"op":"mcm","clk":"4227991177","pt":1631458892243,"mc":[{"id":"1.187551081","rc":[{"batl":[[0,3.85,3],[1,3.9,2],[2,5.7,3]],"ltp":4.5,"tv":660.9,"id":7445998}]}]}
{"op":"mcm","clk":"4227991439","pt":1631458893416,"mc":[{"id":"1.187551081","rc":[{"batl":[[2,4.6,65.77]],"ltp":4.5,"tv":660.9,"id":7445998},{"batb":[[1,1.34,819.29]],"batl":[[1,1.39,404.72]],"ltp":1.28,"tv":6576.19,"id":9629022}]}]}
{"op":"mcm","clk":"4227991482","pt":1631458893745,"mc":[{"id":"1.187551081","rc":[{"batl":[[2,5.7,3]],"ltp":4.5,"tv":660.9,"id":7445998}]}]}
{"op":"mcm","clk":"4227992646","pt":1631458900532,"mc":[{"id":"1.187551081","rc":[{"batb":[[0,3.6,170.08]],"ltp":4.5,"tv":660.9,"id":7445998},{"batb":[[1,1.34,751.13]],"batl":[[1,1.39,683.42]],"ltp":1.28,"tv":6576.19,"id":9629022}]}]}
{"op":"mcm","clk":"4227993105","pt":1631458903315,"mc":[{"id":"1.187551081","rc":[{"batl":[[1,6,104.94],[2,810,0.07]],"ltp":4.5,"tv":660.9,"id":7445998},{"batb":[[0,1.35,343.88],[1,1.34,743.13]],"batl":[[0,1.38,485.24]],"ltp":1.28,"tv":6576.19,"id":9629022}]}]}
{"op":"mcm","clk":"4227993670","pt":1631458906547,"mc":[{"id":"1.187551081","rc":[{"batl":[[1,3.9,116.15],[2,6,104.94]],"ltp":4.5,"tv":660.9,"id":7445998},{"batb":[[1,1.34,1081.18]],"ltp":1.28,"tv":6576.19,"id":9629022}]}]}
{"op":"mcm","clk":"4227993827","pt":1631458907444,"mc":[{"id":"1.187551081","rc":[{"trd":[[3.85,4]],"batl":[[0,3.85,1]],"ltp":3.85,"tv":664.9,"id":7445998}],"tv":7241.09}]}
{"op":"mcm","clk":"4227994283","pt":1631458910157,"mc":[{"id":"1.187551081","rc":[{"trd":[[3.85,6],[3.9,0.84]],"batl":[[0,3.9,116.11],[1,6,104.94],[2,810,0.07]],"ltp":3.9,"tv":666.99,"id":7445998},{"trd":[[1.35,8.01]],"batb":[[0,1.35,340.96]],"ltp":1.35,"tv":6582.03,"id":9629022}],"tv":7249.02}]}
{"op":"mcm","clk":"4227994817","pt":1631458913345,"mc":[{"id":"1.187551081","rc":[{"batl":[[0,3.85,2],[1,3.9,116.11],[2,6,104.94]],"ltp":3.9,"tv":666.99,"id":7445998}]}]}
{"op":"mcm","clk":"4227995508","pt":1631458917658,"mc":[{"id":"1.187551081","rc":[{"trd":[[3.85,8]],"batl":[[0,3.9,116.11],[1,6,104.94],[2,810,0.07]],"ltp":3.85,"tv":668.99,"id":7445998},{"trd":[[1.35,695.63]],"batb":[[0,1.34,1081.18],[1,1.29,336.29],[2,1.15,355.81]],"batl":[[0,1.35,153.34],[1,1.38,485.24],[2,1.39,683.42]],"ltp":1.35,"tv":7269.65,"id":9629022}],"tv":7938.64}]}
{"op":"mcm","clk":"4227995657","pt":1631458918660,"mc":[{"id":"1.187551081","rc":[{"batl":[[0,1.35,164.77],[1,1.38,422.54],[2,1.39,419.41]],"ltp":1.35,"tv":7269.65,"id":9629022}]}]}
{"op":"mcm","clk":"4227995905","pt":1631458920269,"mc":[{"id":"1.187551081","rc":[{"trd":[[1.35,895.63]],"batl":[[0,1.35,64.77]],"ltp":1.35,"tv":7469.65,"id":9629022}],"tv":8138.64}]}
{"op":"mcm","clk":"4227996068","pt":1631458921471,"mc":[{"id":"1.187551081","rc":[{"batb":[[0,3.6,62.47]],"batl":[[0,6,104.94],[1,810,0.07],[2,810,0]],"ltp":3.85,"tv":668.99,"id":7445998},{"trd":[[1.35,911.63]],"batb":[[0,1.34,834.59],[1,1.33,338.12],[2,1.29,336.29]],"batl":[[0,1.35,56.77],[1,1.37,338.91],[2,1.38,422.54]],"ltp":1.35,"tv":7485.65,"id":9629022}],"tv":8154.64}]}
{"op":"mcm","clk":"4227996548","pt":1631458924660,"mc":[{"id":"1.187551081","rc":[{"batb":[[0,3.65,61.71],[1,3.6,62.47],[2,3.45,61.95]],"ltp":3.85,"tv":668.99,"id":7445998},{"batl":[[1,1.36,179.16],[2,1.37,338.91]],"ltp":1.35,"tv":7485.65,"id":9629022}]}]}
{"op":"mcm","clk":"4227996636","pt":1631458925262,"mc":[{"id":"1.187551081","rc":[{"batb":[[1,3.4,3],[2,3.35,3]],"ltp":3.85,"tv":668.99,"id":7445998}]}]}
{"op":"mcm","clk":"4227997024","pt":1631458927783,"mc":[{"id":"1.187551081","rc":[{"trd":[[3.85,10]],"ltp":3.85,"tv":670.99,"id":7445998},{"trd":[[1.35,917.33]],"batl":[[0,1.35,51.07]],"ltp":1.35,"tv":7491.35,"id":9629022}],"tv":8162.34}]}
{"op":"mcm","clk":"4227997642","pt":1631458932686,"mc":[{"id":"1.187551081","rc":[{"trd":[[1.35,926.89]],"batl":[[0,1.35,46.29]],"ltp":1.35,"tv":7500.91,"id":9629022}],"tv":8171.9}]}
{"op":"mcm","clk":"4227998100","pt":1631458936077,"mc":[{"id":"1.187551081","rc":[{"batb":[[2,3.15,88.26]],"ltp":3.85,"tv":670.99,"id":7445998},{"trd":[[1.35,940.89]],"batl":[[0,1.35,39.29]],"ltp":1.35,"tv":7514.91,"id":9629022}],"tv":8185.9}]}
{"op":"mcm","clk":"4227998219","pt":1631458936888,"mc":[{"id":"1.187551081","rc":[{"trd":[[1.35,996.61]],"batb":[[0,1.35,35.46],[1,1.34,834.59],[2,1.33,338.12]],"batl":[[0,1.36,179.16],[1,1.37,338.91],[2,1.38,422.54]],"ltp":1.35,"tv":7570.63,"id":9629022}],"tv":8241.62}]}
{"op":"mcm","clk":"4227998537","pt":1631458939578,"mc":[{"id":"1.187551081","rc":[{"batb":[[2,3.35,2]],"ltp":3.85,"tv":670.99,"id":7445998},{"batl":[[0,1.37,338.91],[1,1.38,422.54],[2,1.39,140.71]],"ltp":1.35,"tv":7570.63,"id":9629022}]}]}
{"op":"mcm","clk":"4227998598","pt":1631458940076,"mc":[{"id":"1.187551081","rc":[{"batb":[[0,1.35,71.96]],"ltp":1.35,"tv":7570.63,"id":9629022}]}]}
{"op":"mcm","clk":"4227998942","pt":1631458942452,"mc":[{"id":"1.187551081","rc":[{"batl":[[0,3.85,3],[1,6,104.94],[2,810,0.07]],"ltp":3.85,"tv":670.99,"id":7445998}]}]}
{"op":"mcm","clk":"4227999697","pt":1631458947666,"mc":[{"id":"1.187551081","rc":[{"trd":[[1.37,94.29]],"batl":[[0,1.37,329.15]],"ltp":1.37,"tv":7590.15,"id":9629022}],"tv":8261.14}]}
{"op":"mcm","clk":"4228002256","pt":1631458966022,"mc":[{"id":"1.187551081","rc":[{"batb":[[2,3.15,88.26]],"ltp":3.85,"tv":670.99,"id":7445998},{"batb":[[0,1.35,36.5]],"ltp":1.37,"tv":7590.15,"id":9629022}]}]}
{"op":"mcm","clk":"4228002713","pt":1631458969169,"mc":[{"id":"1.187551081","rc":[{"batb":[[2,3.35,3]],"ltp":3.85,"tv":670.99,"id":7445998},{"trd":[[1.37,165.21]],"batl":[[0,1.37,293.69]],"ltp":1.37,"tv":7661.07,"id":9629022}],"tv":8332.07}]}
{"op":"mcm","clk":"4228003212","pt":1631458972897,"mc":[{"id":"1.187551081","rc":[{"trd":[[1.35,1000.03]],"batb":[[0,1.35,34.79]],"ltp":1.35,"tv":7664.49,"id":9629022}],"tv":8335.48}]}
{"op":"mcm","clk":"4228003571","pt":1631458975196,"mc":[{"id":"1.187551081","rc":[{"trd":[[3.7,42.01]],"ltp":3.7,"tv":705.15,"id":7445998},{"trd":[[1.37,257.47]],"batl":[[0,1.37,201.43]],"ltp":1.37,"tv":7756.75,"id":9629022}],"tv":8461.91}]}
{"op":"mcm","clk":"4228004070","pt":1631458978880,"mc":[{"id":"1.187551081","rc":[{"batb":[[2,3.35,7.27]],"batl":[[1,4.4,2.59],[2,4.8,2.17]],"ltp":3.7,"tv":705.15,"id":7445998}]}]}
{"op":"mcm","clk":"4228008482","pt":1631459009649,"mc":[{"id":"1.187551081","rc":[{"batb":[[0,3.35,7.27],[1,3.2,4.02],[2,3.15,88.26]],"batl":[[0,4.4,2.59],[1,4.8,2.17],[2,6,104.94]],"ltp":3.7,"tv":705.15,"id":7445998},{"batb":[[0,1.3,86.08],[1,1.29,336.29],[2,1.27,102.87]],"batl":[[0,1.42,65.75],[1,1.45,59.9],[2,2,30]],"ltp":1.37,"tv":7756.75,"id":9629022}]}]}
{"op":"mcm","clk":"4228008534","pt":1631459010039,"mc":[{"id":"1.187551081","rc":[{"batb":[[0,3.35,3]],"batl":[[0,4.8,2.17],[1,6,104.94],[2,810,0.07]],"ltp":3.7,"tv":705.15,"id":7445998},{"batb":[[0,1.29,336.29],[1,1.27,102.87],[2,1.15,355.81]],"batl":[[0,1.45,59.9],[1,2,30],[2,3.8,27.47]],"ltp":1.37,"tv":7756.75,"id":9629022}]}]}
{"op":"mcm","clk":"4228008894","pt":1631459012646,"mc":[{"id":"1.187551081","rc":[{"batb":[[0,1.3,188.38],[1,1.29,730.43],[2,1.27,102.87]],"batl":[[0,1.45,217.92],[1,1.46,215.33],[2,2,30]],"ltp":1.37,"tv":7756.75,"id":9629022}]}]}
{"op":"mcm","clk":"4228009040","pt":1631459013661,"mc":[{"id":"1.187551081","rc":[{"batb":[[1,3.3,3],[2,3.2,4.02]],"batl":[[0,4.4,3],[1,4.5,3],[2,4.8,2.17]],"ltp":3.7,"tv":705.15,"id":7445998},{"batb":[[1,1.29,737.43],[2,1.28,7]],"batl":[[0,1.43,5],[1,1.45,217.92],[2,1.46,215.33]],"ltp":1.37,"tv":7756.75,"id":9629022}]}]}
{"op":"mcm","clk":"4228009294","pt":1631459015369,"mc":[{"id":"1.187551081","rc":[{"batl":[[1,1.45,59.9],[2,2,30]],"ltp":1.37,"tv":7756.75,"id":9629022}]}]}
{"op":"mcm","clk":"4228009721","pt":1631459018371,"mc":[{"id":"1.187551081","rc":[{"batl":[[0,1.32,172.93],[1,1.33,331.93],[2,1.43,5]],"ltp":1.37,"tv":7756.75,"id":9629022}]}]}
{"op":"mcm","clk":"4228009892","pt":1631459019545,"mc":[{"id":"1.187551081","rc":[{"batb":[[0,4,94.88],[1,3.55,64.65],[2,3.35,3]],"ltp":3.7,"tv":705.15,"id":7445998}]}]}
{"op":"mcm","clk":"4228009951","pt":1631459020044,"mc":[{"id":"1.187551081","rc":[{"batb":[[2,3.4,3]],"batl":[[0,4.3,2],[1,4.4,3],[2,4.5,3]],"ltp":3.7,"tv":705.15,"id":7445998},{"batl":[[2,1.41,7]],"ltp":1.37,"tv":7756.75,"id":9629022}]}]}
{"op":"mcm","clk":"4228010404","pt":1631459023245,"mc":[{"id":"1.187551081","rc":[{"trd":[[4.3,20.27]],"batl":[[0,4.3,1.13]],"ltp":4.3,"tv":706.88,"id":7445998},{"trd":[[1.3,22.55]],"batb":[[0,1.3,185.49],[1,1.29,812.65]],"batl":[[1,1.33,422]],"ltp":1.3,"tv":7762.53,"id":9629022}],"tv":8469.42}]}
{"op":"mcm","clk":"4228010724","pt":1631459025558,"mc":[{"id":"1.187551081","rc":[{"batb":[[2,3.45,64.65]],"batl":[[1,4.7,46.22],[2,4.8,47.68]],"ltp":4.3,"tv":706.88,"id":7445998},{"batb":[[2,1.27,265.13]],"batl":[[2,1.41,131.77]],"ltp":1.3,"tv":7762.53,"id":9629022}]}]}
{"op":"mcm","clk":"4228010837","pt":1631459026244,"mc":[{"id":"1.187551081","rc":[{"batb":[[1,3.75,2.71],[2,3.55,68.04]],"batl":[[0,4.5,2.31]],"ltp":4.3,"tv":706.88,"id":7445998},{"batb":[[1,1.29,906.46]],"batl":[[2,1.36,68.32]],"ltp":1.3,"tv":7762.53,"id":9629022}]}]}
{"op":"mcm","clk":"4228011204","pt":1631459028347,"mc":[{"id":"1.187551081","rc":[{"batl":[[0,1.32,267.51]],"ltp":1.3,"tv":7762.53,"id":9629022}]}]}
{"op":"mcm","clk":"4228011272","pt":1631459028773,"mc":[{"id":"1.187551081","rc":[{"batl":[[1,4.6,3],[2,4.7,46.22]],"ltp":4.3,"tv":706.88,"id":7445998}]}]}
{"op":"mcm","clk":"4228011493","pt":1631459030178,"mc":[{"id":"1.187551081","rc":[{"batl":[[1,1.33,419.98]],"ltp":1.3,"tv":7762.53,"id":9629022}]}]}
{"op":"mcm","clk":"4228011685","pt":1631459031597,"mc":[{"id":"1.187551081","rc":[{"batl":[[1,4.6,5.41]],"ltp":4.3,"tv":706.88,"id":7445998},{"batb":[[2,1.28,89.41]],"ltp":1.3,"tv":7762.53,"id":9629022}]}]}
{"op":"mcm","clk":"4228011970","pt":1631459033520,"mc":[{"id":"1.187551081","rc":[{"batl":[[0,4.6,2.41],[1,4.7,46.22],[2,4.8,47.68]],"ltp":4.3,"tv":706.88,"id":7445998},{"batb":[[0,1.29,336.29],[1,1.28,89.41],[2,1.27,265.13]],"batl":[[0,1.36,68.32],[1,1.39,59.5],[2,1.41,131.77]],"ltp":1.3,"tv":7762.53,"id":9629022}]}]}
{"op":"mcm","clk":"4228012058","pt":1631459034067,"mc":[{"id":"1.187551081","rc":[{"batb":[[0,3.55,68.04],[1,3.45,64.65],[2,3.4,59.12]],"batl":[[0,4.7,46.22],[1,4.8,47.68],[2,4.9,50.59]],"ltp":4.3,"tv":706.88,"id":7445998},{"batb":[[0,1.27,265.13],[1,1.26,320.68],[2,1.25,265.06]],"batl":[[0,1.39,59.5],[1,1.41,131.77],[2,1.42,153.02]],"ltp":1.3,"tv":7762.53,"id":9629022}]}]}
{"op":"mcm","clk":"4228012610","pt":1631459037601,"mc":[{"id":"1.187551081","rc":[{"batb":[[0,3.75,3],[1,3.7,3],[2,3.55,71.04]],"batl":[[1,4.8,45.51]],"ltp":4.3,"tv":706.88,"id":7445998},{"batb":[[0,1.27,162.26]],"batl":[[0,1.36,7],[1,1.37,8],[2,1.39,67.5]],"ltp":1.3,"tv":7762.53,"id":9629022}]}]}
{"op":"mcm","clk":"4228012712","pt":1631459038184,"mc":[{"id":"1.187551081","rc":[{"batl":[[0,4.7,46.31]],"ltp":4.3,"tv":706.88,"id":7445998}]}]}
{"op":"mcm","clk":"4228013029","pt":1631459040441,"mc":[{"id":"1.187551081","rc":[{"trd":[[4.1,17.68]],"batl":[[0,4.7,46.22]],"ltp":4.1,"tv":706.98,"id":7445998},{"trd":[[1.32,15.21]],"batb":[[0,1.3,186.79],[1,1.29,482.36],[2,1.27,162.26]],"batl":[[0,1.32,174.21],[1,1.33,329.9],[2,1.35,97.68]],"ltp":1.32,"tv":7762.82,"id":9629022}],"tv":8469.8}]}
{"op":"mcm","clk":"4228013459","pt":1631459043076,"mc":[{"id":"1.187551081","rc":[{"batb":[[0,1.3,273.41]],"batl":[[1,1.33,428.39]],"ltp":1.32,"tv":7762.82,"id":9629022}]}]}
{"op":"mcm","clk":"4228013972","pt":1631459046187,"mc":[{"id":"1.187551081","rc":[{"batl":[[0,1.32,273.45]],"ltp":1.32,"tv":7762.82,"id":9629022}]}]}
{"op":"mcm","clk":"4228014126","pt":1631459047216,"mc":[{"id":"1.187551081","rc":[{"batb":[[0,1.27,162.26],[1,1.26,320.68],[2,1.25,265.06]],"batl":[[0,1.36,7],[1,1.37,8],[2,1.39,67.5]],"ltp":1.32,"tv":7762.82,"id":9629022}]}]}
{"op":"mcm","clk":"4228014617","pt":1631459050310,"mc":[{"id":"1.187551081","rc":[{"batb":[[1,3.55,68.04],[2,3.45,64.65]],"ltp":4.1,"tv":706.98,"id":7445998},{"batb":[[1,1.26,661.02],[2,1.25,741.56]],"batl":[[1,1.39,430.37],[2,1.4,256.24]],"ltp":1.32,"tv":7762.82,"id":9629022}]}]}
{"op":"mcm","clk":"4228014691","pt":1631459050813,"mc":[{"id":"1.187551081","rc":[{"batb":[[1,1.26,320.68],[2,1.25,265.06]],"batl":[[1,1.39,59.5],[2,1.41,124.77]],"ltp":1.32,"tv":7762.82,"id":9629022}]}]}
{"op":"mcm","clk":"4228015111","pt":1631459053521,"mc":[{"id":"1.187551081","rc":[{"batb":[[1,3.7,3],[2,3.55,68.04]],"ltp":4.1,"tv":706.98,"id":7445998}]}]}
{"op":"mcm","clk":"4228015332","pt":1631459054804,"mc":[{"id":"1.187551081","rc":[{"batb":[[0,1.31,229.09],[1,1.3,378.49],[2,1.27,162.26]],"batl":[[0,1.34,427.18],[1,1.35,302.93],[2,1.36,7]],"ltp":1.32,"tv":7762.82,"id":9629022}]}]}
{"op":"mcm","clk":"4228015821","pt":1631459057919,"mc":[{"id":"1.187551081","rc":[{"batb":[[0,1.31,294.71]],"batl":[[0,1.34,510.62]],"ltp":1.32,"tv":7762.82,"id":9629022}]}]}
{"op":"mcm","clk":"4228016225","pt":1631459060541,"mc":[{"id":"1.187551081","rc":[{"batb":[[0,1.31,65.62],[1,1.27,162.26],[2,1.26,320.68]],"batl":[[0,1.34,83.44],[1,1.36,7],[2,1.39,59.5]],"ltp":1.32,"tv":7762.82,"id":9629022}]}]}
{"op":"mcm","clk":"4228016253","pt":1631459060732,"mc":[{"id":"1.187551081","rc":[{"batb":[[0,1.27,162.26],[1,1.26,320.68],[2,1.25,265.06]],"batl":[[0,1.36,7],[1,1.39,59.5],[2,1.41,124.77]],"ltp":1.32,"tv":7762.82,"id":9629022}]}]}
{"op":"mcm","clk":"4228016707","pt":1631459063443,"mc":[{"id":"1.187551081","rc":[{"batb":[[1,1.26,661.02],[2,1.25,741.56]],"batl":[[1,1.39,430.37],[2,1.4,256.24]],"ltp":1.32,"tv":7762.82,"id":9629022}]}]}
{"op":"mcm","clk":"4228017432","pt":1631459067827,"mc":[{"id":"1.187551081","rc":[{"batb":[[1,3.55,68.04],[2,3.45,64.65]],"ltp":4.1,"tv":706.98,"id":7445998}]}]}
{"op":"mcm","clk":"4228017990","pt":1631459071045,"mc":[{"id":"1.187551081","rc":[{"batb":[[1,3.7,3],[2,3.55,68.04]],"ltp":4.1,"tv":706.98,"id":7445998}]}]}
{"op":"mcm","clk":"4228019688","pt":1631459081157,"mc":[{"id":"1.187551081","rc":[{"batl":[[1,1.39,59.5],[2,2,30]],"ltp":1.32,"tv":7762.82,"id":9629022}]}]}
{"op":"mcm","clk":"4228020054","pt":1631459083063,"mc":[{"id":"1.187551081","rc":[{"batb":[[1,3.55,68.04],[2,2.2,42.66]],"ltp":4.1,"tv":706.98,"id":7445998}]}]}
{"op":"mcm","clk":"4228020226","pt":1631459084180,"mc":[{"id":"1.187551081","rc":[{"batl":[[0,1.29,535.51],[1,1.3,364.99],[2,1.36,7]],"ltp":1.32,"tv":7762.82,"id":9629022}]}]}
{"op":"mcm","clk":"4228020410","pt":1631459085374,"mc":[{"id":"1.187551081","rc":[{"batb":[[0,4.6,71.43],[1,4,94.12],[2,3.75,3]],"ltp":4.1,"tv":706.98,"id":7445998}]}]}
{"op":"mcm","clk":"4228020597","pt":1631459086570,"mc":[{"id":"1.187551081","rc":[{"batb":[[2,3.8,2]],"ltp":4.1,"tv":706.98,"id":7445998},{"batb":[[0,1.27,170.26],[1,1.26,668.02]],"batl":[[2,1.35,9]],"ltp":1.32,"tv":7762.82,"id":9629022}]}]}
{"op":"mcm","clk":"4228020901","pt":1631459088399,"mc":[{"id":"1.187551081","rc":[{"batb":[[0,1.27,230.91]],"batl":[[0,1.29,617.2]],"ltp":1.32,"tv":7762.82,"id":9629022}]}]}
{"op":"mcm","clk":"4228021024","pt":1631459089216,"mc":[{"id":"1.187551081","rc":[{"trd":[[4.7,3.62]],"batl":[[0,4.7,45.41]],"ltp":4.7,"tv":708.6,"id":7445998},{"trd":[[1.27,99.15]],"batb":[[0,1.27,228.03]],"ltp":1.27,"tv":7768.58,"id":9629022}],"tv":8477.18}]}
{"op":"mcm","clk":"4228021365","pt":1631459091183,"mc":[{"id":"1.187551081","rc":[{"batb":[[2,3.85,44.69]],"ltp":4.7,"tv":708.6,"id":7445998}]}]}
{"op":"mcm","clk":"4228022236","pt":1631459096694,"mc":[{"id":"1.187551081","rc":[{"trd":[[4.7,6.37]],"batl":[[0,4.7,44.03]],"ltp":4.7,"tv":711.35,"id":7445998}],"tv":8479.93}]}
{"op":"mcm","clk":"4228022657","pt":1631459099325,"mc":[{"id":"1.187551081","rc":[{"batb":[[0,4,94.12],[1,3.85,44.69],[2,3.8,63.66]],"batl":[[0,5,4.31],[1,5.1,45.26],[2,5.2,47.09]],"ltp":4.7,"tv":711.35,"id":7445998},{"batb":[[0,1.24,155.01],[1,1.23,206.62],[2,1.22,753.13]],"batl":[[0,1.35,9],[1,1.36,152.14],[2,1.37,164.7]],"ltp":1.27,"tv":7768.58,"id":9629022}]}]}
{"op":"mcm","clk":"4228022871","pt":1631459100622,"mc":[{"id":"1.187551081","rc":[{"trd":[[5,51.12]],"batb":[[0,4,97.3]],"batl":[[0,5.1,45.26],[1,5.2,47.09],[2,5.3,63.29]],"ltp":5.0,"tv":717.73,"id":7445998},{"trd":[[1.25,957.06]],"batl":[[0,1.25,206.29],[1,1.33,80.5],[2,1.35,9]],"ltp":1.25,"tv":8013.72,"id":9629022}],"tv":8731.45}]}
{"op":"mcm","clk":"4228023176","pt":1631459102599,"mc":[{"id":"1.187551081","rc":[{"trd":[[5,53.57]],"batb":[[0,4,100.3],[1,3.95,2],[2,3.85,44.69]],"ltp":5.0,"tv":720.18,"id":7445998},{"trd":[[1.25,1172.81]],"batl":[[0,1.25,93.51],[2,1.34,8]],"ltp":1.25,"tv":8229.47,"id":9629022}],"tv":8949.66}]}
{"op":"mcm","clk":"4228023320","pt":1631459103609,"mc":[{"id":"1.187551081","rc":[{"batb":[[0,4.2,2.77],[1,4,100.3],[2,3.95,2]],"batl":[[0,5.1,48.26]],"ltp":5.0,"tv":720.18,"id":7445998},{"trd":[[1.25,1359.83]],"batb":[[0,1.24,163.01],[1,1.23,215.62]],"batl":[[0,1.31,100.5]],"ltp":1.25,"tv":8416.49,"id":9629022}],"tv":9136.68}]}
{"op":"mcm","clk":"4228023483","pt":1631459104525,"mc":[{"id":"1.187551081","rc":[{"batb":[[0,4,100.3],[1,3.95,2],[2,3.85,44.69]],"ltp":5.0,"tv":720.18,"id":7445998},{"batb":[[0,1.27,229.24],[1,1.26,451.88],[2,1.24,163.01]],"batl":[[0,1.29,220.39],[1,1.3,370.61],[2,1.31,7]],"ltp":1.25,"tv":8416.49,"id":9629022}]}]}
{"op":"mcm","clk":"4228023813","pt":1631459106510,"mc":[{"id":"1.187551081","rc":[{"batb":[[0,4.2,2],[1,4.1,3],[2,4,100.3]],"ltp":5.0,"tv":720.18,"id":7445998}]}]}
{"op":"mcm","clk":"4228023933","pt":1631459107208,"mc":[{"id":"1.187551081","rc":[{"batb":[[0,4.2,5.62]],"ltp":5.0,"tv":720.18,"id":7445998},{"batl":[[2,1.31,111.5]],"ltp":1.25,"tv":8416.49,"id":9629022}]}]}
{"op":"mcm","clk":"4228024287","pt":1631459109628,"mc":[{"id":"1.187551081","rc":[{"batb":[[0,1.27,328.72]],"batl":[[0,1.29,329.61]],"ltp":1.25,"tv":8416.49,"id":9629022}]}]}
{"op":"mcm","clk":"4228024424","pt":1631459110523,"mc":[{"id":"1.187551081","rc":[{"batb":[[0,4.2,2]],"ltp":5.0,"tv":720.18,"id":7445998},{"batb":[[0,1.24,163.01],[1,1.23,215.62],[2,1.22,753.13]],"batl":[[0,1.31,7],[1,1.33,80.5],[2,1.34,8]],"ltp":1.25,"tv":8416.49,"id":9629022}]}]}
{"op":"mcm","clk":"4228024910","pt":1631459113662,"mc":[{"id":"1.187551081","rc":[{"batb":[[0,1.24,170.05],[1,1.23,856.88],[2,1.22,1238.99]],"batl":[[1,1.33,494.97],[2,1.34,322.31]],"ltp":1.25,"tv":8416.49,"id":9629022}]}]}
{"op":"mcm","clk":"4228025012","pt":1631459114353,"mc":[{"id":"1.187551081","rc":[{"batb":[[2,4,97.3]],"ltp":5.0,"tv":720.18,"id":7445998},{"batl":[[2,1.34,314.31]],"ltp":1.25,"tv":8416.49,"id":9629022}]}]}
{"op":"mcm","clk":"4228025325","pt":1631459116177,"mc":[{"id":"1.187551081","rc":[{"batb":[[0,4.2,12]],"batl":[[0,5,31.38],[1,5.1,48.26],[2,5.2,47.09]],"ltp":5.0,"tv":720.18,"id":7445998},{"batb":[[0,1.25,125.53],[1,1.24,170.05],[2,1.23,847.88]],"ltp":1.25,"tv":8416.49,"id":9629022}]}]}
{"op":"mcm","clk":"4228025827","pt":1631459119560,"mc":[{"id":"1.187551081","rc":[{"batb":[[1,4,97.3],[2,3.85,44.69]],"ltp":5.0,"tv":720.18,"id":7445998}]}]}
{"op":"mcm","clk":"4228026379","pt":1631459122953,"mc":[{"id":"1.187551081","rc":[{"batb":[[1,4.1,3],[2,4,97.3]],"ltp":5.0,"tv":720.18,"id":7445998},{"batb":[[1,1.24,163.01]],"ltp":1.25,"tv":8416.49,"id":9629022}]}]}
{"op":"mcm","clk":"4228026669","pt":1631459124565,"mc":[{"id":"1.187551081","rc":[{"batb":[[0,4.2,15.57]],"ltp":5.0,"tv":720.18,"id":7445998},{"batl":[[0,1.31,114.5]],"ltp":1.25,"tv":8416.49,"id":9629022}]}]}
{"op":"mcm","clk":"4228026826","pt":1631459125655,"mc":[{"id":"1.187551081","rc":[{"batb":[[0,4.2,12]],"batl":[[0,5.1,3],[1,7.8,87.04],[2,810,0.07]],"ltp":5.0,"tv":720.18,"id":7445998},{"batb":[[0,1.24,8],[1,1.22,474.29],[2,1.13,1.28]],"batl":[[0,1.31,7]],"ltp":1.25,"tv":8416.49,"id":9629022}]}]}
{"op":"mcm","clk":"4228026959","pt":1631459126472,"mc":[{"id":"1.187551081","rc":[{"batb":[[1,1.23,7.04],[2,1.22,474.29]],"ltp":1.25,"tv":8416.49,"id":9629022}]}]}
{"op":"mcm","clk":"4228027138","pt":1631459127583,"mc":[{"id":"1.187551081","rc":[{"batb":[[0,4,97.3],[1,3.85,44.69],[2,3.8,61.66]],"batl":[[1,810,0.07],[2,810,0]],"ltp":5.0,"tv":720.18,"id":7445998},{"batl":[[0,1.33,494.97],[1,1.34,314.31],[2,1.36,152.14]],"ltp":1.25,"tv":8416.49,"id":9629022}]}]}
{"op":"mcm","clk":"4228027232","pt":1631459128185,"mc":[{"id":"1.187551081","rc":[{"batb":[[0,1.3,281.82],[1,1.29,395.73],[2,1.24,8]],"ltp":1.25,"tv":8416.49,"id":9629022}]}]}
{"op":"mcm","clk":"4228027423","pt":1631459129373,"mc":[{"id":"1.187551081","rc":[{"batl":[[0,5,15],[1,5.1,3],[2,810,0.07]],"ltp":5.0,"tv":720.18,"id":7445998},{"batb":[[1,1.29,736.88],[2,1.24,426.77]],"ltp":1.25,"tv":8416.49,"id":9629022}]}]}
{"op":"mcm","clk":"4228027610","pt":1631459130587,"mc":[{"id":"1.187551081","rc":[{"batl":[[0,4.3,2],[1,5,17],[2,5.1,3]],"ltp":5.0,"tv":720.18,"id":7445998},{"batb":[[0,1.31,9],[1,1.3,288.82],[2,1.29,736.88]],"ltp":1.25,"tv":8416.49,"id":9629022}]}]}
{"op":"mcm","clk":"4228027703","pt":1631459131188,"mc":[{"id":"1.187551081","rc":[{"batl":[[1,5,2]],"ltp":5.0,"tv":720.18,"id":7445998}]}]}
{"op":"mcm","clk":"4228027886","pt":1631459132384,"mc":[{"id":"1.187551081","rc":[{"batb":[[0,1.31,54.13],[1,1.3,377.2]],"batl":[[0,1.33,594.71]],"ltp":1.25,"tv":8416.49,"id":9629022}]}]}
{"op":"mcm","clk":"4228028050","pt":1631459133298,"mc":[{"id":"1.187551081","rc":[{"trd":[[4.3,21.97]],"batl":[[0,4.3,1.15]],"ltp":4.3,"tv":721.88,"id":7445998},{"trd":[[1.31,62.26]],"batb":[[0,1.31,51.28]],"ltp":1.31,"tv":8422.19,"id":9629022}],"tv":9144.08}]}
{"op":"mcm","clk":"4228028237","pt":1631459134297,"mc":[{"id":"1.187551081","rc":[{"batl":[[0,4.2,5.75],[1,4.3,1.15],[2,5,2]],"ltp":4.3,"tv":721.88,"id":7445998},{"batb":[[0,1.31,140.62]],"ltp":1.31,"tv":8422.19,"id":9629022}]}]}
{"op":"mcm","clk":"4228028387","pt":1631459135195,"mc":[{"id":"1.187551081","rc":[{"batl":[[2,4.6,2.11]],"ltp":4.3,"tv":721.88,"id":7445998}]}]}
{"op":"mcm","clk":"4228030248","pt":1631459146604,"mc":[{"id":"1.187551081","rc":[{"batb":[[0,3.5,67.83],[1,3.4,60.28],[2,3.35,59.63]],"batl":[[0,4.8,41.99],[1,4.9,49.89],[2,5,62.85]],"ltp":4.3,"tv":721.88,"id":7445998},{"batb":[[0,1.26,154.02],[1,1.25,201.41],[2,1.24,644.09]],"batl":[[0,1.41,92.5],[1,1.42,106.56],[2,1.43,161.98]],"ltp":1.31,"tv":8422.19,"id":9629022}]}]}
{"op":"mcm","clk":"4228030730","pt":1631459149620,"mc":[{"id":"1.187551081","rc":[{"batb":[[0,3.6,3],[1,3.55,3],[2,3.5,67.83]],"batl":[[1,4.9,52.24]],"ltp":4.3,"tv":721.88,"id":7445998},{"batb":[[0,1.26,452.28],[1,1.25,674.64]],"batl":[[0,1.31,11.43],[1,1.37,87.82],[2,1.38,6]],"ltp":1.31,"tv":8422.19,"id":9629022}]}]}
{"op":"mcm","clk":"4228030883","pt":1631459150597,"mc":[{"id":"1.187551081","rc":[{"trd":[[4.2,8.26]],"batb":[[2,3.5,70.83]],"ltp":4.2,"tv":725.45,"id":7445998},{"trd":[[1.31,73.69]],"batb":[[0,1.26,461.28]],"batl":[[0,1.38,6],[1,1.4,301.68],[2,1.41,349.47]],"ltp":1.31,"tv":8433.63,"id":9629022}],"tv":9159.08}]}
{"op":"mcm","clk":"4228031028","pt":1631459151412,"mc":[{"id":"1.187551081","rc":[{"batl":[[1,1.4,6],[2,1.41,100.5]],"ltp":1.31,"tv":8433.63,"id":9629022}]}]}
{"op":"mcm","clk":"4228031436","pt":1631459153625,"mc":[{"id":"1.187551081","rc":[{"batl":[[0,4.6,2.71],[1,4.8,41.99],[2,4.9,52.24]],"ltp":4.2,"tv":725.45,"id":7445998},{"trd":[[1.31,79.57]],"batb":[[0,1.28,92.66],[1,1.26,461.28],[2,1.25,674.64]],"batl":[[0,1.37,6],[1,1.38,6],[2,1.4,6]],"ltp":1.31,"tv":8439.51,"id":9629022}],"tv":9164.96}]}
{"op":"mcm","clk":"4228031617","pt":1631459154603,"mc":[{"id":"1.187551081","rc":[{"batb":[[0,4.6,69.75],[1,4.3,11.88],[2,4.1,91]],"batl":[[0,4.7,39.52],[1,4.8,43.99]],"ltp":4.2,"tv":725.45,"id":7445998},{"trd":[[1.28,246.7]],"batb":[[0,1.26,461.28],[1,1.25,674.64],[2,1.24,644.09]],"batl":[[0,1.28,194.54],[1,1.29,385.1],[2,1.3,118.85]],"ltp":1.28,"tv":8624.83,"id":9629022}],"tv":9350.28}]}
{"op":"mcm","clk":"4228031697","pt":1631459155038,"mc":[{"id":"1.187551081","rc":[{"batl":[[0,4.8,43.99],[1,4.9,52.24],[2,5,62.85]],"ltp":4.2,"tv":725.45,"id":7445998}]}]}
{"op":"mcm","clk":"4228032100","pt":1631459157132,"mc":[{"id":"1.187551081","rc":[{"batb":[[0,1.26,513.38]],"batl":[[0,1.28,236]],"ltp":1.28,"tv":8624.83,"id":9629022}]}]}
{"op":"mcm","clk":"4228032400","pt":1631459158551,"mc":[{"id":"1.187551081","rc":[{"batl":[[0,4.8,57.75]],"ltp":4.2,"tv":725.45,"id":7445998},{"batb":[[0,1.26,627.82]],"batl":[[0,1.28,312.45]],"ltp":1.28,"tv":8624.83,"id":9629022}]}]}
{"op":"mcm","clk":"4228032747","pt":1631459160360,"mc":[{"id":"1.187551081","rc":[{"batb":[[2,4.1,95.64]],"batl":[[2,5,64.85]],"ltp":4.2,"tv":725.45,"id":7445998},{"batb":[[1,1.25,787.13]],"ltp":1.28,"tv":8624.83,"id":9629022}]}]}
{"op":"mcm","clk":"4228032811","pt":1631459160719,"mc":[{"id":"1.187551081","rc":[{"batb":[[2,1.24,814.23]],"ltp":1.28,"tv":8624.83,"id":9629022}]}]}
{"op":"mcm","clk":"4228034991","pt":1631459173247,"mc":[{"id":"1.187551081","rc":[{"batb":[[2,4.1,95.33]],"ltp":4.2,"tv":725.45,"id":7445998},{"batb":[[1,1.25,781.13]],"ltp":1.28,"tv":8624.83,"id":9629022}]}]}
{"op":"mcm","clk":"4228035236","pt":1631459174643,"mc":[{"id":"1.187551081","rc":[{"batb":[[1,1.25,787.28]],"ltp":1.28,"tv":8624.83,"id":9629022}]}]}
{"op":"mcm","clk":"4228035463","pt":1631459176054,"mc":[{"id":"1.187551081","rc":[{"batb":[[1,4.5,115.14],[2,4.3,11.88]],"ltp":4.2,"tv":725.45,"id":7445998},{"batl":[[0,1.28,717.27]],"ltp":1.28,"tv":8624.83,"id":9629022}]}]}
{"op":"mcm","clk":"4228035714","pt":1631459177634,"mc":[{"id":"1.187551081","rc":[{"batb":[[0,4.1,90.69],[1,3.9,59.84],[2,3.85,70.1]],"batl":[[0,5,2],[1,5.1,42.87],[2,5.2,48.01]],"ltp":4.2,"tv":725.45,"id":7445998},{"batb":[[0,1.25,118.65],[1,1.24,170.14],[2,1.23,249.14]],"batl":[[0,1.35,264.56],[1,1.36,178.46],[2,1.37,188.13]],"ltp":1.28,"tv":8624.83,"id":9629022}]}]}
{"op":"mcm","clk":"4228036335","pt":1631459181170,"mc":[{"id":"1.187551081","rc":[{"batb":[[0,4.1,93.69],[1,4,3],[2,3.9,59.84]],"batl":[[0,5,4]],"ltp":4.2,"tv":725.45,"id":7445998},{"batb":[[0,1.25,126.65],[1,1.24,180.14]],"batl":[[0,1.33,9],[1,1.35,264.56],[2,1.36,178.46]],"ltp":1.28,"tv":8624.83,"id":9629022}]}]}
{"op":"mcm","clk":"4228036563","pt":1631459182649,"mc":[{"id":"1.187551081","rc":[{"batb":[[0,1.26,573.94],[1,1.25,607.06],[2,1.24,180.14]],"batl":[[0,1.29,317.75],[1,1.3,367.92],[2,1.33,9]],"ltp":1.28,"tv":8624.83,"id":9629022}]}]}
{"op":"mcm","clk":"4228036731","pt":1631459183646,"mc":[{"id":"1.187551081","rc":[{"batl":[[0,4.8,20.27],[1,5,4],[2,5.1,42.87]],"ltp":4.2,"tv":725.45,"id":7445998},{"batb":[[0,1.27,20.87],[1,1.26,573.94],[2,1.25,607.06]],"batl":[[0,1.28,21.59],[1,1.29,317.75],[2,1.3,367.92]],"ltp":1.28,"tv":8624.83,"id":9629022}]}]}
{"op":"mcm","clk":"4228036851","pt":1631459184361,"mc":[{"id":"1.187551081","rc":[{"batb":[[0,4.2,18.17],[1,4.1,98.23],[2,4,3]],"batl":[[0,4.9,2.45]],"ltp":4.2,"tv":725.45,"id":7445998},{"batb":[[0,1.26,682.42],[1,1.25,607.06],[2,1.24,180.14]],"batl":[[0,1.29,317.75],[1,1.3,367.92],[2,1.31,51.89]],"ltp":1.28,"tv":8624.83,"id":9629022}]}]}
{"op":"mcm","clk":"4228037330","pt":1631459187272,"mc":[{"id":"1.187551081","rc":[{"batl":[[0,4.8,19.65],[1,4.9,2.45],[2,5,4]],"ltp":4.2,"tv":725.45,"id":7445998},{"batb":[[0,1.27,83.87],[1,1.26,842.18],[2,1.25,607.06]],"batl":[[0,1.29,473.79]],"ltp":1.28,"tv":8624.83,"id":9629022}]}]}
{"op":"mcm","clk":"4228037848","pt":1631459190473,"mc":[{"id":"1.187551081","rc":[{"batb":[[1,4.1,93.69]],"batl":[[0,5,4],[1,5.1,42.87],[2,5.2,48.01]],"ltp":4.2,"tv":725.45,"id":7445998},{"batb":[[0,1.27,239.43],[1,1.26,159.76],[2,1.25,126.65]],"batl":[[0,1.31,51.89],[1,1.32,8],[2,1.33,9]],"ltp":1.28,"tv":8624.83,"id":9629022}]}]}
{"op":"mcm","clk":"4228038089","pt":1631459191710,"mc":[{"id":"1.187551081","rc":[{"batb":[[0,4.1,93.69],[1,4,3],[2,3.9,59.84]],"ltp":4.2,"tv":725.45,"id":7445998},{"batb":[[0,1.25,126.65],[1,1.24,180.14],[2,1.23,249.14]],"batl":[[0,1.32,8],[1,1.33,9],[2,1.35,273.56]],"ltp":1.28,"tv":8624.83,"id":9629022}]}]}
{"op":"mcm","clk":"4228038395","pt":1631459193389,"mc":[{"id":"1.187551081","rc":[{"batb":[[1,3.9,59.84],[2,3.85,70.1]],"batl":[[0,4.9,2.35],[1,5,4],[2,5.1,42.87]],"ltp":4.2,"tv":725.45,"id":7445998},{"batb":[[0,1.26,87.98],[1,1.25,126.65],[2,1.24,176.3]],"batl":[[0,1.32,230.53],[1,1.33,328.33]],"ltp":1.28,"tv":8624.83,"id":9629022}]}]}
{"op":"mcm","clk":"4228038532","pt":1631459194084,"mc":[{"id":"1.187551081","rc":[{"batb":[[0,4.1,98.13]],"batl":[[0,5,4],[1,5.1,42.87],[2,5.2,48.01]],"ltp":4.2,"tv":725.45,"id":7445998},{"batb":[[0,1.25,126.65],[1,1.24,176.3],[2,1.23,806.88]],"batl":[[0,1.32,372.64]],"ltp":1.28,"tv":8624.83,"id":9629022}]}]}
{"op":"mcm","clk":"4228038889","pt":1631459196181,"mc":[{"id":"1.187551081","rc":[{"batb":[[1,4,2],[2,3.9,59.84]],"ltp":4.2,"tv":725.45,"id":7445998},{"batb":[[1,1.24,186.3]],"batl":[[2,1.35,264.56]],"ltp":1.28,"tv":8624.83,"id":9629022}]}]}
{"op":"mcm","clk":"4228039291","pt":1631459198897,"mc":[{"id":"1.187551081","rc":[{"batl":[[1,7.8,87.04],[2,5.2,0]],"ltp":4.2,"tv":725.45,"id":7445998},{"batb":[[1,1.24,16.16],[2,1.23,7.04]],"ltp":1.28,"tv":8624.83,"id":9629022}]}]}
{"op":"mcm","clk":"4228039523","pt":1631459200510,"mc":[{"id":"1.187551081","rc":[{"batl":[[0,4.9,2.45],[1,5,4]],"ltp":4.2,"tv":725.45,"id":7445998},{"batb":[[0,1.26,87.98],[1,1.25,126.65],[2,1.24,16.16]],"ltp":1.28,"tv":8624.83,"id":9629022}]}]}
{"op":"mcm","clk":"4228039634","pt":1631459201201,"mc":[{"id":"1.187551081","rc":[{"batb":[[0,4.1,95.13],[1,3.9,59.84],[2,3.85,70.1]],"batl":[[0,5,4],[1,5,0]],"ltp":4.2,"tv":725.45,"id":7445998},{"batb":[[0,1.25,126.65],[1,1.24,16.16],[2,1.23,7.04]],"batl":[[0,1.32,364.64]],"ltp":1.28,"tv":8624.83,"id":9629022}]}]}
{"op":"mcm","clk":"4228039731","pt":1631459201790,"mc":[{"id":"1.187551081","rc":[{"batb":[[0,1.29,527.94],[1,1.28,416.84],[2,1.25,126.65]],"ltp":1.28,"tv":8624.83,"id":9629022}]}]}
{"op":"mcm","clk":"4228040018","pt":1631459203490,"mc":[{"id":"1.187551081","rc":[{"batl":[[0,4.9,20],[1,5,4]],"ltp":4.2,"tv":725.45,"id":7445998},{"batb":[[1,1.28,766.95]],"ltp":1.28,"tv":8624.83,"id":9629022}]}]}
{"op":"mcm","clk":"4228040192","pt":1631459204405,"mc":[{"id":"1.187551081","rc":[{"batl":[[0,4.9,3],[2,7.2,91.22]],"ltp":4.2,"tv":725.45,"id":7445998},{"batb":[[2,1.26,10]],"ltp":1.28,"tv":8624.83,"id":9629022}]}]}
{"op":"mcm","clk":"4228040349","pt":1631459205274,"mc":[{"id":"1.187551081","rc":[{"batb":[[0,4.1,90.69]],"batl":[[0,4.4,3],[1,4.9,3],[2,5,4]],"ltp":4.2,"tv":725.45,"id":7445998},{"batb":[[0,1.3,9],[1,1.29,535.94],[2,1.28,766.95]],"batl":[[0,1.32,222.53]],"ltp":1.28,"tv":8624.83,"id":9629022}]}]}
{"op":"mcm","clk":"4228040565","pt":1631459206602,"mc":[{"id":"1.187551081","rc":[{"trd":[[4.4,5.28]],"batl":[[0,4.4,1.36]],"ltp":4.4,"tv":728.73,"id":7445998},{"trd":[[1.3,33.69]],"batb":[[0,1.3,165.75],[1,1.29,671.95]],"batl":[[0,1.32,356.05]],"ltp":1.3,"tv":8635.97,"id":9629022}],"tv":9364.7}]}
{"op":"mcm","clk":"4228040608","pt":1631459207184,"mc":[{"id":"1.187551081","rc":[{"batb":[[0,1.3,59.05]],"ltp":1.3,"tv":8635.97,"id":9629022}]}]}
{"op":"mcm","clk":"4228040905","pt":1631459208502,"mc":[{"id":"1.187551081","rc":[{"batl":[[0,4.3,3],[1,4.4,1.36],[2,4.9,3]],"ltp":4.4,"tv":728.73,"id":7445998},{"batb":[[0,1.3,152.97]],"ltp":1.3,"tv":8635.97,"id":9629022}]}]}
{"op":"mcm","clk":"4228041345","pt":1631459211131,"mc":[{"id":"1.187551081","rc":[{"batl":[[0,4.3,9.8]],"ltp":4.4,"tv":728.73,"id":7445998}]}]}
{"op":"mcm","clk":"4228042213","pt":1631459216613,"mc":[{"id":"1.187551081","rc":[{"batb":[[1,3.7,5.42],[2,3.5,5.72]],"batl":[[0,4.3,3],[1,5,34.67],[2,5.1,49.18]],"ltp":4.4,"tv":728.73,"id":7445998},{"batb":[[0,1.3,135.82],[1,1.29,663.95]],"batl":[[2,1.37,135.5]],"ltp":1.3,"tv":8635.97,"id":9629022}]}]}
{"op":"mcm","clk":"4228042297","pt":1631459217122,"mc":[{"id":"1.187551081","rc":[{"batb":[[0,3.5,5.72],[1,3.45,69.67],[2,3.4,46.14]],"batl":[[0,5,34.67],[1,5.1,49.18],[2,5.2,60.22]],"ltp":4.4,"tv":728.73,"id":7445998},{"batb":[[0,1.25,208.68],[1,1.24,177.15],[2,1.23,675.82]],"batl":[[0,1.4,129.94],[1,1.42,136.47],[2,1.43,164.03]],"ltp":1.3,"tv":8635.97,"id":9629022}]}]}
{"op":"mcm","clk":"4228042708","pt":1631459219619,"mc":[{"id":"1.187551081","rc":[{"batb":[[1,1.24,830.57],[2,1.23,1140.25]],"batl":[[0,1.3,7.92],[1,1.4,129.94],[2,1.41,350.6]],"ltp":1.3,"tv":8635.97,"id":9629022}]}]}
{"op":"mcm","clk":"4228042806","pt":1631459220335,"mc":[{"id":"1.187551081","rc":[{"trd":[[4.3,24.36]],"batb":[[0,3.7,5.42],[1,3.5,8.4],[2,3.45,71.67]],"batl":[[0,4.1,135.38],[1,5,34.67],[2,5.1,49.18]],"ltp":4.3,"tv":731.13,"id":7445998},{"trd":[[1.3,41.6]],"batl":[[0,1.37,134.5],[1,1.38,8],[2,1.4,136.94]],"ltp":1.3,"tv":8643.88,"id":9629022}],"tv":9375.01}]}
{"op":"mcm","clk":"4228042855","pt":1631459220710,"mc":[{"id":"1.187551081","rc":[{"batb":[[0,3.5,8.4],[1,3.45,71.67],[2,3.4,46.14]],"ltp":4.3,"tv":731.13,"id":7445998},{"batl":[[0,1.38,8],[1,1.4,136.94],[2,1.41,350.6]],"ltp":1.3,"tv":8643.88,"id":9629022}]}]}
{"op":"mcm","clk":"4228043202","pt":1631459222935,"mc":[{"id":"1.187551081","rc":[{"trd":[[4.1,18.31]],"batl":[[0,4.1,135.06]],"ltp":4.1,"tv":731.76,"id":7445998}],"tv":9375.64}]}
{"op":"mcm","clk":"4228043431","pt":1631459224346,"mc":[{"id":"1.187551081","rc":[{"batb":[[0,3.6,3],[1,3.55,3],[2,3.5,8.4]],"ltp":4.1,"tv":731.76,"id":7445998}]}]}
{"op":"mcm","clk":"4228043933","pt":1631459227532,"mc":[{"id":"1.187551081","rc":[{"batb":[[0,3.7,5.32],[1,3.6,3],[2,3.55,3]],"batl":[[0,5,34.67],[1,5.1,49.18],[2,5.2,60.22]],"ltp":4.1,"tv":731.76,"id":7445998},{"batl":[[0,1.37,124.5],[1,1.38,8],[2,1.4,136.94]],"ltp":1.3,"tv":8643.88,"id":9629022}]}]}
{"op":"mcm","clk":"4228043988","pt":1631459227944,"mc":[{"id":"1.187551081","rc":[{"batb":[[0,3.6,3],[1,3.55,3],[2,3.5,8.4]],"ltp":4.1,"tv":731.76,"id":7445998},{"batl":[[0,1.38,8],[1,1.4,136.94],[2,1.41,350.6]],"ltp":1.3,"tv":8643.88,"id":9629022}]}]}
{"op":"mcm","clk":"4228044366","pt":1631459230256,"mc":[{"id":"1.187551081","rc":[{"batb":[[1,1.24,743.55]],"batl":[[2,1.41,250.88]],"ltp":1.3,"tv":8643.88,"id":9629022}]}]}
{"op":"mcm","clk":"4228044871","pt":1631459233447,"mc":[{"id":"1.187551081","rc":[{"batb":[[2,3.5,5.4]],"ltp":4.1,"tv":731.76,"id":7445998},{"batb":[[2,1.23,1210.06]],"batl":[[1,1.4,300.87]],"ltp":1.3,"tv":8643.88,"id":9629022}]}]}
{"op":"mcm","clk":"4228045070","pt":1631459234628,"mc":[{"id":"1.187551081","rc":[{"batb":[[0,3.7,5.62],[1,3.6,3],[2,3.55,3]],"ltp":4.1,"tv":731.76,"id":7445998},{"batl":[[0,1.37,142.5],[1,1.38,8],[2,1.4,300.87]],"ltp":1.3,"tv":8643.88,"id":9629022}]}]}
{"op":"mcm","clk":"4228045181","pt":1631459235254,"mc":[{"id":"1.187551081","rc":[{"batb":[[0,3.6,3],[1,3.5,5.4],[2,3.45,69.67]],"ltp":4.1,"tv":731.76,"id":7445998},{"batl":[[0,1.38,8],[1,1.4,300.87],[2,1.41,250.88]],"ltp":1.3,"tv":8643.88,"id":9629022}]}]}
{"op":"mcm","clk":"4228045501","pt":1631459237057,"mc":[{"id":"1.187551081","rc":[{"batl":[[0,7.2,91.22],[1,5.1,0],[2,5.2,0]],"ltp":4.1,"tv":731.76,"id":7445998},{"batb":[[0,1.25,6.16],[1,1.24,6.16],[2,1.23,453.95]],"ltp":1.3,"tv":8643.88,"id":9629022}]}]}
{"op":"mcm","clk":"4228045718","pt":1631459238566,"mc":[{"id":"1.187551081","rc":[{"batb":[[1,3.55,3],[2,3.5,5.4]],"ltp":4.1,"tv":731.76,"id":7445998}]}]}
{"op":"mcm","clk":"4228045970","pt":1631459240343,"mc":[{"id":"1.187551081","rc":[{"batb":[[0,3.5,5.4],[1,3.45,69.67],[2,3.4,46.14]],"ltp":4.1,"tv":731.76,"id":7445998},{"batb":[[0,1.37,315.78],[1,1.36,302.01],[2,1.25,6.16]],"batl":[[0,1.4,300.87],[1,1.41,250.88],[2,1.42,136.47]],"ltp":1.3,"tv":8643.88,"id":9629022}]}]}
{"op":"mcm","clk":"4228046160","pt":1631459241557,"mc":[{"id":"1.187551081","rc":[{"batb":[[0,3.5,73.56],[1,3.4,46.14],[2,3.35,67.46]],"batl":[[0,4.1,55.52]],"ltp":4.1,"tv":731.76,"id":7445998},{"batb":[[1,1.36,560.93],[2,1.32,30.8]],"ltp":1.3,"tv":8643.88,"id":9629022}]}]}
{"op":"mcm","clk":"4228046270","pt":1631459242201,"mc":[{"id":"1.187551081","rc":[{"batl":[[0,4.1,5],[1,5.5,113.67]],"ltp":4.1,"tv":731.76,"id":7445998},{"batb":[[2,1.28,353.63]],"ltp":1.3,"tv":8643.88,"id":9629022}]}]}
{"op":"mcm","clk":"4228046467","pt":1631459243491,"mc":[{"id":"1.187551081","rc":[{"batl":[[0,3.6,2],[1,3.7,3],[2,5.5,113.67]],"ltp":4.1,"tv":731.76,"id":7445998},{"batb":[[0,1.38,9],[1,1.37,323.78],[2,1.36,560.93]],"ltp":1.3,"tv":8643.88,"id":9629022}]}]}
{"op":"mcm","clk":"4228046602","pt":1631459244390,"mc":[{"id":"1.187551081","rc":[{"trd":[[3.6,2.14]],"batl":[[0,3.7,3.93],[1,5.5,113.67],[2,5.5,0]],"ltp":3.6,"tv":733.9,"id":7445998},{"trd":[[1.38,36.54]],"batb":[[0,1.38,6.25],[1,1.37,425.11]],"batl":[[0,1.4,407.92]],"ltp":1.38,"tv":8649.39,"id":9629022}],"tv":9383.29}]}
{"op":"mcm","clk":"4228046930","pt":1631459246511,"mc":[{"id":"1.187551081","rc":[{"batl":[[2,1000,2.17]],"ltp":3.6,"tv":733.9,"id":7445998},{"batb":[[0,1.38,104.13]],"ltp":1.38,"tv":8649.39,"id":9629022}]}]}
{"op":"mcm","clk":"4228047007","pt":1631459246995,"mc":[{"id":"1.187551081","rc":[{"batl":[[0,3.6,5.58],[1,3.7,3],[2,4.4,47.74]],"ltp":3.6,"tv":733.9,"id":7445998}]}]}
{"op":"mcm","clk":"4228047223","pt":1631459248389,"mc":[{"id":"1.187551081","rc":[{"batb":[[0,1.39,54.54],[1,1.38,104.13],[2,1.37,425.11]],"ltp":1.38,"tv":8649.39,"id":9629022}]}]}
{"op":"mcm","clk":"4228047849","pt":1631459252385,"mc":[{"id":"1.187551081","rc":[{"trd":[[1.39,30.76]],"batb":[[0,1.39,8.55]],"ltp":1.39,"tv":8673.91,"id":9629022}],"tv":9407.81}]}
{"op":"mcm","clk":"4228048350","pt":1631459255618,"mc":[{"id":"1.187551081","rc":[{"trd":[[1.39,47.86]],"batb":[[0,1.38,104.13],[1,1.37,425.11],[2,1.36,560.93]],"batl":[[0,1.39,95.66],[1,1.4,407.92],[2,1.41,250.88]],"ltp":1.39,"tv":8691.01,"id":9629022}],"tv":9424.91}]}
{"op":"mcm","clk":"4228048393","pt":1631459255905,"mc":[{"id":"1.187551081","rc":[{"batl":[[1,4.4,47.74],[2,4.5,43.91]],"ltp":3.6,"tv":733.9,"id":7445998},{"batb":[[1,1.37,417.11]],"ltp":1.39,"tv":8691.01,"id":9629022}]}]}
{"op":"mcm","clk":"4228049004","pt":1631459259981,"mc":[{"id":"1.187551081","rc":[{"trd":[[3.5,171.12],[3.55,37.46]],"batb":[[0,3.4,46.14],[1,3.35,67.46],[2,3.3,69.11]],"ltp":3.5,"tv":942.47,"id":7445998},{"trd":[[1.39,143.52],[1.4,63.99]],"batb":[[0,1.38,156.57]],"batl":[[0,1.4,347.93],[1,1.41,250.88],[2,1.42,136.47]],"ltp":1.4,"tv":8846.66,"id":9629022}],"tv":9789.14}]}
{"op":"mcm","clk":"4228049267","pt":1631459261698,"mc":[{"id":"1.187551081","rc":[{"batb":[[1,1.37,365.34]],"ltp":1.4,"tv":8846.66,"id":9629022}]}]}
{"op":"mcm","clk":"4228049778","pt":1631459264608,"mc":[{"id":"1.187551081","rc":[{"batl":[[0,1.4,398.63]],"ltp":1.4,"tv":8846.66,"id":9629022}]}]}
{"op":"mcm","clk":"4228049883","pt":1631459265238,"mc":[{"id":"1.187551081","rc":[{"batl":[[0,4.4,47.74],[1,4.5,43.91],[2,4.6,64.1]],"ltp":3.5,"tv":942.47,"id":7445998},{"batb":[[1,1.37,334.6]],"ltp":1.4,"tv":8846.66,"id":9629022}]}]}
{"op":"mcm","clk":"4228050074","pt":1631459266410,"mc":[{"id":"1.187551081","rc":[{"batb":[[0,2.88,44.63],[1,2.84,69.29],[2,2.82,83.78]],"ltp":3.5,"tv":942.47,"id":7445998},{"batb":[[0,1.38,6.25],[1,1.3,139.23],[2,1.29,213.57]],"batl":[[0,1.55,226.44],[1,1.56,115.45],[2,1.57,134.64]],"ltp":1.4,"tv":8846.66,"id":9629022}]}]}
{"op":"mcm","clk":"4228050400","pt":1631459268453,"mc":[{"id":"1.187551081","rc":[{"batl":[[0,3.6,15.08],[1,4.4,47.74],[2,4.5,43.91]],"ltp":3.5,"tv":942.47,"id":7445998},{"batb":[[0,1.3,139.23],[1,1.29,213.57],[2,1.28,594.59]],"ltp":1.4,"tv":8846.66,"id":9629022}]}]}
{"op":"mcm","clk":"4228050588","pt":1631459269637,"mc":[{"id":"1.187551081","rc":[{"batb":[[0,2.9,2],[1,2.88,3],[2,2.86,45.05]],"batl":[[0,4.4,47.74],[1,4.5,43.91],[2,4.6,64.1]],"ltp":3.5,"tv":942.47,"id":7445998},{"batb":[[1,1.29,707.71],[2,1.28,1008.75]],"batl":[[0,1.53,217.81],[1,1.54,261.01],[2,1.55,226.44]],"ltp":1.4,"tv":8846.66,"id":9629022}]}]}
{"op":"mcm","clk":"4228050885","pt":1631459271518,"mc":[{"id":"1.187551081","rc":[{"batb":[[2,2.86,47.05]],"batl":[[0,4.4,50.74]],"ltp":3.5,"tv":942.47,"id":7445998},{"batb":[[0,1.3,148.23],[1,1.29,716.71]],"ltp":1.4,"tv":8846.66,"id":9629022}]}]}
{"op":"mcm","clk":"4228051199","pt":1631459273455,"mc":[{"id":"1.187551081","rc":[{"batl":[[0,1.53,7],[1,1.54,6],[2,1.61,87.5]],"ltp":1.4,"tv":8846.66,"id":9629022}]}]}
{"op":"mcm","clk":"4228051464","pt":1631459275049,"mc":[{"id":"1.187551081","rc":[{"batb":[[0,1.3,9]],"ltp":1.4,"tv":8846.66,"id":9629022}]}]}
{"op":"mcm","clk":"4228051600","pt":1631459276025,"mc":[{"id":"1.187551081","rc":[{"batb":[[0,3.9,14.56],[1,2.9,2],[2,2.88,3]],"ltp":3.5,"tv":942.47,"id":7445998},{"batl":[[0,1.32,261.98],[1,1.33,330.3],[2,1.34,127.75]],"ltp":1.4,"tv":8846.66,"id":9629022}]}]}
{"op":"mcm","clk":"4228051749","pt":1631459277037,"mc":[{"id":"1.187551081","rc":[{"batb":[[0,4.1,91.27],[1,3.9,14.56],[2,3.45,69.59]],"ltp":3.5,"tv":942.47,"id":7445998}]}]}
{"op":"mcm","clk":"4228051886","pt":1631459278049,"mc":[{"id":"1.187551081","rc":[{"batb":[[2,3.45,79.59]],"batl":[[0,4.3,14.98],[1,4.4,50.74],[2,4.5,43.91]],"ltp":3.5,"tv":942.47,"id":7445998},{"batb":[[0,1.3,65.98]],"ltp":1.4,"tv":8846.66,"id":9629022}]}]}
{"op":"mcm","clk":"4228052038","pt":1631459279030,"mc":[{"id":"1.187551081","rc":[{"batl":[[0,4.3,16.98]],"ltp":3.5,"tv":942.47,"id":7445998}]}]}
{"op":"mcm","clk":"4228052279","pt":1631459280549,"mc":[{"id":"1.187551081","rc":[{"trd":[[4.3,26.11]],"batl":[[0,4.3,6.78]],"ltp":4.3,"tv":944.22,"id":7445998},{"trd":[[1.3,47.08]],"batb":[[0,1.3,63.24]],"ltp":1.3,"tv":8852.14,"id":9629022}],"tv":9796.36}]}
{"op":"mcm","clk":"4228052402","pt":1631459281250,"mc":[{"id":"1.187551081","rc":[{"batb":[[0,1.3,161.22]],"batl":[[0,1.32,338.79]],"ltp":1.3,"tv":8852.14,"id":9629022}]}]}
{"op":"mcm","clk":"4228052713","pt":1631459283392,"mc":[{"id":"1.187551081","rc":[{"batb":[[2,3.55,3.99]],"ltp":4.3,"tv":944.22,"id":7445998},{"batb":[[1,1.29,707.71]],"ltp":1.3,"tv":8852.14,"id":9629022}]}]}
{"op":"mcm","clk":"4228053488","pt":1631459288311,"mc":[{"id":"1.187551081","rc":[{"batb":[[0,4.1,194.61]],"ltp":4.3,"tv":944.22,"id":7445998},{"batl":[[1,1.33,648.86]],"ltp":1.3,"tv":8852.14,"id":9629022}]}]}
{"op":"mcm","clk":"4228053866","pt":1631459290592,"mc":[{"id":"1.187551081","rc":[{"batb":[[0,3.45,69.59],[1,3.35,46.18],[2,3.3,58.33]],"batl":[[0,4.9,40.99],[1,5,52.79],[2,5.1,48.76]],"ltp":4.3,"tv":944.22,"id":7445998},{"batb":[[0,1.25,153.57],[1,1.24,177.39],[2,1.23,644.49]],"batl":[[0,1.43,212.63],[1,1.44,122.01],[2,1.45,155.75]],"ltp":1.3,"tv":8852.14,"id":9629022}]}]}
{"op":"mcm","clk":"4228054445","pt":1631459294288,"mc":[{"id":"1.187551081","rc":[{"batb":[[0,3.45,72.59],[1,3.4,2],[2,3.35,46.18]],"ltp":4.3,"tv":944.22,"id":7445998},{"batb":[[0,1.25,165.57],[1,1.24,186.39]],"ltp":1.3,"tv":8852.14,"id":9629022}]}]}
{"op":"mcm","clk":"4228054781","pt":1631459296397,"mc":[{"id":"1.187551081","rc":[{"batb":[[0,3.5,63.09],[1,3.45,72.59],[2,3.4,2]],"batl":[[0,4.8,40.97],[1,4.9,40.99],[2,5,52.79]],"ltp":4.3,"tv":944.22,"id":7445998},{"batb":[[0,1.31,280.88],[1,1.3,381.27],[2,1.26,164.59]],"batl":[[0,1.34,384],[1,1.35,305.17],[2,1.41,175.97]],"ltp":1.3,"tv":8852.14,"id":9629022}]}]}
{"op":"mcm","clk":"4228054957","pt":1631459297505,"mc":[{"id":"1.187551081","rc":[{"batb":[[0,3.55,3.99],[1,3.5,63.09],[2,3.45,72.59]],"batl":[[0,4.9,40.99],[1,5,52.79],[2,5.1,48.76]],"ltp":4.3,"tv":944.22,"id":7445998},{"batb":[[2,1.25,165.57]],"batl":[[2,1.39,96.5]],"ltp":1.3,"tv":8852.14,"id":9629022}]}]}
{"op":"mcm","clk":"4228055021","pt":1631459297986,"mc":[{"id":"1.187551081","rc":[{"batb":[[1,3.45,72.59],[2,3.4,2]],"ltp":4.3,"tv":944.22,"id":7445998}]}]}
{"op":"mcm","clk":"4228055387","pt":1631459300329,"mc":[{"id":"1.187551081","rc":[{"batl":[[0,4.7,46.03],[1,4.9,40.99],[2,5,52.79]],"ltp":4.3,"tv":944.22,"id":7445998},{"batb":[[0,1.32,151.66],[1,1.31,280.88],[2,1.3,381.27]],"batl":[[0,1.33,89.46],[1,1.34,384],[2,1.35,305.17]],"ltp":1.3,"tv":8852.14,"id":9629022}]}]}
{"op":"mcm","clk":"4228055602","pt":1631459301509,"mc":[{"id":"1.187551081","rc":[{"batl":[[0,4.9,40.99],[1,5,52.79],[2,5.1,48.76]],"ltp":4.3,"tv":944.22,"id":7445998},{"batb":[[0,1.25,165.57],[1,1.24,186.39],[2,1.23,644.49]],"batl":[[0,1.39,96.5],[1,1.4,8],[2,1.43,218.63]],"ltp":1.3,"tv":8852.14,"id":9629022}]}]}
{"op":"mcm","clk":"4228055691","pt":1631459302092,"mc":[{"id":"1.187551081","rc":[{"batb":[[0,3.45,72.59],[1,3.4,2],[2,3.35,46.18]],"ltp":4.3,"tv":944.22,"id":7445998},{"batl":[[0,1.4,8],[1,1.43,218.63],[2,1.44,122.01]],"ltp":1.3,"tv":8852.14,"id":9629022}]}]}
{"op":"mcm","clk":"4228056023","pt":1631459304403,"mc":[{"id":"1.187551081","rc":[{"batb":[[1,1.24,786.83],[2,1.23,1162.34]],"batl":[[1,1.41,376.1],[2,1.42,242.05]],"ltp":1.3,"tv":8852.14,"id":9629022}]}]}
{"op":"mcm","clk":"4228056182","pt":1631459305488,"mc":[{"id":"1.187551081","rc":[{"batb":[[0,3.5,2],[1,3.45,69.59]],"ltp":4.3,"tv":944.22,"id":7445998},{"batb":[[1,1.24,777.83]],"ltp":1.3,"tv":8852.14,"id":9629022}]}]}
{"op":"mcm","clk":"4228056392","pt":1631459307092,"mc":[{"id":"1.187551081","rc":[{"batb":[[2,3.3,4.18]],"batl":[[0,5.1,48.76],[1,880,0.01],[2,5.1,0]],"ltp":4.3,"tv":944.22,"id":7445998},{"batb":[[0,1.25,18.16]],"batl":[[1,1.43,6],[2,1.53,7]],"ltp":1.3,"tv":8852.14,"id":9629022}]}]}
{"op":"mcm","clk":"4228056625","pt":1631459309014,"mc":[{"id":"1.187551081","rc":[{"batb":[[1,3.45,72.59]],"ltp":4.3,"tv":944.22,"id":7445998},{"batb":[[1,1.24,786.83]],"batl":[[1,2,30],[2,3.8,27.47]],"ltp":1.3,"tv":8852.14,"id":9629022}]}]}
{"op":"mcm","clk":"4228056807","pt":1631459310307,"mc":[{"id":"1.187551081","rc":[{"batb":[[0,4.3,12.28],[1,3.5,2],[2,3.45,72.59]],"batl":[[0,5,2],[1,5.1,50.76],[2,880,0.01]],"ltp":4.3,"tv":944.22,"id":7445998},{"batl":[[0,1.27,414.41],[1,1.28,401.3],[2,1.3,122.25]],"ltp":1.3,"tv":8852.14,"id":9629022}]}]}
{"op":"mcm","clk":"4228056931","pt":1631459311343,"mc":[{"id":"1.187551081","rc":[{"batb":[[0,4.8,64.23],[1,4.3,12.28],[2,4.1,93.45]],"batl":[[0,5,16.13]],"ltp":4.3,"tv":944.22,"id":7445998},{"batb":[[0,1.25,74.7]],"ltp":1.3,"tv":8852.14,"id":9629022}]}]}
{"op":"mcm","clk":"4228057211","pt":1631459313148,"mc":[{"id":"1.187551081","rc":[{"batl":[[2,7.2,91.22]],"ltp":4.3,"tv":944.22,"id":7445998}]}]}
{"op":"mcm","clk":"4228057386","pt":1631459314352,"mc":[{"id":"1.187551081","rc":[{"batb":[[0,1.25,191.2]],"batl":[[0,1.27,514.21]],"ltp":1.3,"tv":8852.14,"id":9629022}]}]}
{"op":"mcm","clk":"4228057831","pt":1631459317550,"mc":[{"id":"1.187551081","rc":[{"batl":[[2,5.9,40.87]],"ltp":4.3,"tv":944.22,"id":7445998},{"trd":[[1.25,1599.83]],"batb":[[0,1.25,71.2]],"ltp":1.25,"tv":9092.13,"id":9629022}],"tv":10036.36}]}
{"op":"mcm","clk":"4228058273","pt":1631459320457,"mc":[{"id":"1.187551081","rc":[{"trd":[[5,54.96]],"batl":[[0,5,7.86]],"ltp":5.0,"tv":945.6,"id":7445998},{"trd":[[1.25,1605.09]],"batb":[[0,1.25,68.57]],"ltp":1.25,"tv":9097.39,"id":9629022}],"tv":10042.99}]}
{"op":"mcm","clk":"4228058403","pt":1631459321271,"mc":[{"id":"1.187551081","rc":[{"batb":[[0,1.25,119.46]],"ltp":1.25,"tv":9097.39,"id":9629022}]}]}
{"op":"mcm","clk":"4228058714","pt":1631459323501,"mc":[{"id":"1.187551081","rc":[{"batl":[[1,5.1,48.76]],"ltp":5.0,"tv":945.6,"id":7445998},{"batb":[[1,1.24,946.58]],"batl":[[0,1.26,157.21],[1,1.27,514.21],[2,1.28,401.3]],"ltp":1.25,"tv":9097.39,"id":9629022}]}]}
{"op":"mcm","clk":"4228060371","pt":1631459334341,"mc":[{"id":"1.187551081","rc":[{"trd":[[4.7,42.41],[4.8,183.6]],"batb":[[0,4.3,12.28],[1,4.1,93.45],[2,4,3.43]],"ltp":4.7,"tv":1151.37,"id":7445998},{"trd":[[1.26,170],[1.27,232.53]],"batl":[[0,1.27,380.83],[1,1.28,401.3],[2,1.3,122.25]],"ltp":1.27,"tv":9387.98,"id":9629022}],"tv":10539.35}]}
{"op":"mcm","clk":"4228060457","pt":1631459334828,"mc":[{"id":"1.187551081","rc":[{"batb":[[1,1.24,843.4],[2,1.23,644.49]],"ltp":1.27,"tv":9387.98,"id":9629022}]}]}
{"op":"mcm","clk":"4228060833","pt":1631459337549,"mc":[{"id":"1.187551081","rc":[{"batb":[[0,4.4,22.56],[1,4.3,12.28],[2,4.1,93.45]],"ltp":4.7,"tv":1151.37,"id":7445998}]}]}
{"op":"mcm","clk":"4228060870","pt":1631459337827,"mc":[{"id":"1.187551081","rc":[{"batb":[[0,1.25,296.01]],"batl":[[0,1.27,440.5]],"ltp":1.27,"tv":9387.98,"id":9629022}]}]}
{"op":"mcm","clk":"4228062232","pt":1631459347539,"mc":[{"id":"1.187551081","rc":[{"batb":[[0,1.25,119.46],[1,1.24,346.14]],"batl":[[0,1.3,122.25],[1,1.33,91.5],[2,1.34,40]],"ltp":1.27,"tv":9387.98,"id":9629022}]}]}
{"op":"mcm","clk":"4228062285","pt":1631459347857,"mc":[{"id":"1.187551081","rc":[{"batl":[[2,1.35,135.74]],"ltp":1.27,"tv":9387.98,"id":9629022}]}]}
{"op":"mcm","clk":"4228062512","pt":1631459349273,"mc":[{"id":"1.187551081","rc":[{"batb":[[0,4.1,93.45],[1,4,3.43],[2,3.85,58.34]],"batl":[[0,5.9,40.87],[1,6,48.3],[2,6.2,53.01]],"ltp":4.7,"tv":1151.37,"id":7445998},{"batb":[[0,1.24,6.16],[1,1.23,7.04],[2,1.2,214.37]],"batl":[[0,1.33,91.5],[1,1.35,135.74],[2,1.36,179.07]],"ltp":1.27,"tv":9387.98,"id":9629022}]}]}
{"op":"mcm","clk":"4228062704","pt":1631459350459,"mc":[{"id":"1.187551081","rc":[{"batb":[[0,1.26,110.86],[1,1.24,6.16],[2,1.23,7.04]],"batl":[[0,1.32,174.19],[1,1.33,421.68],[2,1.35,135.74]],"ltp":1.27,"tv":9387.98,"id":9629022}]}]}
{"op":"mcm","clk":"4228062829","pt":1631459351377,"mc":[{"id":"1.187551081","rc":[{"batb":[[1,3.85,58.34],[2,3.8,56.85]],"ltp":4.7,"tv":1151.37,"id":7445998},{"batb":[[0,1.24,6.16],[1,1.23,7.04],[2,1.2,214.37]],"batl":[[0,1.35,135.74],[1,1.36,179.07],[2,1.37,248.93]],"ltp":1.27,"tv":9387.98,"id":9629022}]}]}
{"op":"mcm","clk":"4228062984","pt":1631459352471,"mc":[{"id":"1.187551081","rc":[{"batb":[[0,3.95,99.82]],"batl":[[0,5.9,43.87]],"ltp":4.7,"tv":1151.37,"id":7445998},{"batl":[[0,1.33,8],[1,1.35,135.74],[2,1.36,179.07]],"ltp":1.27,"tv":9387.98,"id":9629022}]}]}
{"op":"mcm","clk":"4228063291","pt":1631459354573,"mc":[{"id":"1.187551081","rc":[{"batb":[[0,4,3.43],[1,3.95,99.82],[2,3.85,58.34]],"ltp":4.7,"tv":1151.37,"id":7445998},{"batl":[[0,1.33,101.5],[1,1.34,5],[2,1.35,135.74]],"ltp":1.27,"tv":9387.98,"id":9629022}]}]}
{"op":"mcm","clk":"4228063458","pt":1631459355659,"mc":[{"id":"1.187551081","rc":[{"batb":[[0,4.2,49.75],[1,4,2],[2,3.95,102.82]],"batl":[[0,5.8,33.23],[1,5.9,43.87],[2,6,48.3]],"ltp":4.7,"tv":1151.37,"id":7445998},{"batb":[[0,1.24,209.76],[1,1.23,530.4]],"batl":[[0,1.26,383.37],[1,1.27,418.53],[2,1.33,195.97]],"ltp":1.27,"tv":9387.98,"id":9629022}]}]}
{"op":"mcm","clk":"4228063488","pt":1631459355868,"mc":[{"id":"1.187551081","rc":[{"batb":[[0,4,2],[1,3.95,102.82],[2,3.85,58.34]],"ltp":4.7,"tv":1151.37,"id":7445998}]}]}
{"op":"mcm","clk":"4228063906","pt":1631459358658,"mc":[{"id":"1.187551081","rc":[{"batb":[[0,4,5.68],[2,3.9,2]],"ltp":4.7,"tv":1151.37,"id":7445998},{"batb":[[0,1.24,320.34]],"batl":[[2,1.33,288.47]],"ltp":1.27,"tv":9387.98,"id":9629022}]}]}
{"op":"mcm","clk":"4228064050","pt":1631459359475,"mc":[{"id":"1.187551081","rc":[{"batl":[[0,5.9,43.87],[1,6,48.3],[2,6.2,53.01]],"ltp":4.7,"tv":1151.37,"id":7445998},{"batb":[[0,1.24,116.74],[1,1.23,7.04]],"batl":[[0,1.33,100.5],[1,1.34,5],[2,1.35,135.74]],"ltp":1.27,"tv":9387.98,"id":9629022}]}]}
{"op":"mcm","clk":"4228064102","pt":1631459359770,"mc":[{"id":"1.187551081","rc":[{"batb":[[0,4,2]],"ltp":4.7,"tv":1151.37,"id":7445998},{"batb":[[0,1.24,6.16]],"batl":[[0,1.33,8]],"ltp":1.27,"tv":9387.98,"id":9629022}]}]}
{"op":"mcm","clk":"4228064563","pt":1631459362479,"mc":[{"id":"1.187551081","rc":[{"batb":[[2,1.2,480.22]],"batl":[[0,1.32,174.19],[1,1.33,338.18],[2,1.34,5]],"ltp":1.27,"tv":9387.98,"id":9629022}]}]}
{"op":"mcm","clk":"4228064687","pt":1631459363380,"mc":[{"id":"1.187551081","rc":[{"batb":[[0,4,5.29]],"ltp":4.7,"tv":1151.37,"id":7445998},{"batl":[[1,1.33,427.68]],"ltp":1.27,"tv":9387.98,"id":9629022}]}]}
{"op":"mcm","clk":"4228065105","pt":1631459366085,"mc":[{"id":"1.187551081","rc":[{"batl":[[0,5.9,3],[1,880,0.01],[2,6.2,0]],"ltp":4.7,"tv":1151.37,"id":7445998},{"batb":[[2,1.19,560.54]],"batl":[[1,1.33,419.68]],"ltp":1.27,"tv":9387.98,"id":9629022}]}]}
{"op":"mcm","clk":"4228065499","pt":1631459368598,"mc":[{"id":"1.187551081","rc":[{"batl":[[0,4.4,271.74],[1,5.9,3],[2,880,0.01]],"ltp":4.7,"tv":1151.37,"id":7445998}]}]}
{"op":"mcm","clk":"4228065659","pt":1631459369601,"mc":[{"id":"1.187551081","rc":[{"batb":[[0,4,3.29],[1,3.95,99.82],[2,3.85,58.34]],"batl":[[0,5.9,3],[1,880,0.01],[2,880,0]],"ltp":4.7,"tv":1151.37,"id":7445998},{"batb":[[0,1.3,515.57],[1,1.29,394.46],[2,1.24,435.48]],"batl":[[2,1.35,135.74]],"ltp":1.27,"tv":9387.98,"id":9629022}]}]}
{"op":"mcm","clk":"4228065825","pt":1631459370575,"mc":[{"id":"1.187551081","rc":[{"batl":[[0,4.9,15],[1,5.9,3]],"ltp":4.7,"tv":1151.37,"id":7445998}]}]}
{"op":"mcm","clk":"4228065981","pt":1631459371559,"mc":[{"id":"1.187551081","rc":[{"batl":[[0,4.3,3],[1,4.9,15],[2,5.9,3]],"ltp":4.7,"tv":1151.37,"id":7445998},{"batb":[[0,1.3,524.57],[1,1.29,402.46],[2,1.25,8]],"ltp":1.27,"tv":9387.98,"id":9629022}]}]}
{"op":"mcm","clk":"4228066025","pt":1631459371881,"mc":[{"id":"1.187551081","rc":[{"batl":[[1,5.8,2]],"ltp":4.7,"tv":1151.37,"id":7445998}]}]}
{"op":"mcm","clk":"4228066310","pt":1631459373609,"mc":[{"id":"1.187551081","rc":[{"trd":[[4.3,27.77]],"batl":[[0,4.3,2.17],[1,5.1,64.09],[2,5.8,2]],"ltp":4.3,"tv":1153.03,"id":7445998},{"trd":[[1.3,103]],"batb":[[0,1.3,551.89]],"ltp":1.3,"tv":9443.9,"id":9629022}],"tv":10596.93}]}
{"op":"mcm","clk":"4228066426","pt":1631459374388,"mc":[{"id":"1.187551081","rc":[{"batl":[[1,5.8,2],[2,5.9,3]],"ltp":4.3,"tv":1153.03,"id":7445998},{"batb":[[1,1.29,494.89]],"ltp":1.3,"tv":9443.9,"id":9629022}]}]}
{"op":"mcm","clk":"4228066617","pt":1631459375517,"mc":[{"id":"1.187551081","rc":[{"batl":[[1,4.8,2.02],[2,5,2]],"ltp":4.3,"tv":1153.03,"id":7445998},{"batb":[[2,1.27,93.87]],"ltp":1.3,"tv":9443.9,"id":9629022}]}]}
{"op":"mcm","clk":"4228066766","pt":1631459376405,"mc":[{"id":"1.187551081","rc":[{"batl":[[2,5,49.83]],"ltp":4.3,"tv":1153.03,"id":7445998},{"batb":[[0,1.3,391.7]],"ltp":1.3,"tv":9443.9,"id":9629022}]}]}
{"op":"mcm","clk":"4228067041","pt":1631459378399,"mc":[{"id":"1.187551081","rc":[{"batl":[[2,4.9,15]],"ltp":4.3,"tv":1153.03,"id":7445998}]}]}
{"op":"mcm","clk":"4228067228","pt":1631459379516,"mc":[{"id":"1.187551081","rc":[{"batb":[[0,3.5,74.74],[1,3.45,61.73],[2,3.4,65.85]],"batl":[[0,5,49.83],[1,5.1,42.1],[2,5.2,62.11]],"ltp":4.3,"tv":1153.03,"id":7445998},{"batb":[[0,1.25,261.35],[1,1.24,623.65],[2,1.23,269.68]],"batl":[[0,1.4,95.64],[1,1.41,134.41],[2,1.42,138.11]],"ltp":1.3,"tv":9443.9,"id":9629022}]}]}
{"op":"mcm","clk":"4228067565","pt":1631459381615,"mc":[{"id":"1.187551081","rc":[{"batb":[[0,1.3,104.89],[1,1.25,261.35],[2,1.24,623.65]],"ltp":1.3,"tv":9443.9,"id":9629022}]}]}
{"op":"mcm","clk":"4228067722","pt":1631459382629,"mc":[{"id":"1.187551081","rc":[{"batl":[[0,4.8,2.27],[1,5,49.83],[2,5.1,42.1]],"ltp":4.3,"tv":1153.03,"id":7445998},{"batb":[[0,1.27,88.87]],"ltp":1.3,"tv":9443.9,"id":9629022}]}]}
{"op":"mcm","clk":"4228067835","pt":1631459383321,"mc":[{"id":"1.187551081","rc":[{"batb":[[1,3.45,63.73]],"batl":[[0,5,49.83],[1,5.1,42.1],[2,5.2,62.11]],"ltp":4.3,"tv":1153.03,"id":7445998},{"batb":[[0,1.25,261.35],[1,1.24,623.65],[2,1.23,269.68]],"batl":[[0,1.38,7],[1,1.4,103.64],[2,1.41,134.41]],"ltp":1.3,"tv":9443.9,"id":9629022}]}]}
{"op":"mcm","clk":"4228068011","pt":1631459384464,"mc":[{"id":"1.187551081","rc":[{"batb":[[0,1.28,529.09],[1,1.27,438.11],[2,1.25,261.35]],"batl":[[0,1.31,269.79],[1,1.32,342.14],[2,1.38,7]],"ltp":1.3,"tv":9443.9,"id":9629022}]}]}
{"op":"mcm","clk":"4228068308","pt":1631459386225,"mc":[{"id":"1.187551081","rc":[{"batb":[[0,3.7,3.82],[1,3.6,3],[2,3.55,3]],"batl":[[0,4.8,2.22],[1,5,49.83],[2,5.1,42.1]],"ltp":4.3,"tv":1153.03,"id":7445998},{"batb":[[1,1.27,527.98]],"batl":[[2,1.36,112.76]],"ltp":1.3,"tv":9443.9,"id":9629022}]}]}
{"op":"mcm","clk":"4228068634","pt":1631459388326,"mc":[{"id":"1.187551081","rc":[{"batb":[[0,1.28,633.23]],"ltp":1.3,"tv":9443.9,"id":9629022}]}]}
{"op":"mcm","clk":"4228068831","pt":1631459389617,"mc":[{"id":"1.187551081","rc":[{"batb":[[0,3.75,19.1],[1,3.7,3.82],[2,3.6,3]],"batl":[[0,4.7,11.1],[1,4.8,2.22],[2,5,49.83]],"ltp":4.3,"tv":1153.03,"id":7445998},{"batb":[[0,1.29,77.58],[1,1.28,633.23],[2,1.27,527.98]],"ltp":1.3,"tv":9443.9,"id":9629022}]}]}
{"op":"mcm","clk":"4228069107","pt":1631459391529,"mc":[{"id":"1.187551081","rc":[{"batb":[[0,3.6,3],[1,3.55,3],[2,3.5,74.74]],"batl":[[0,5,49.83],[1,5.1,42.1],[2,5.2,62.11]],"ltp":4.3,"tv":1153.03,"id":7445998},{"batb":[[0,1.25,261.35],[1,1.24,623.65],[2,1.23,269.68]],"batl":[[0,1.38,7],[1,1.4,103.64],[2,1.41,134.41]],"ltp":1.3,"tv":9443.9,"id":9629022}]}]}
{"op":"mcm","clk":"4228069246","pt":1631459392526,"mc":[{"id":"1.187551081","rc":[{"batb":[[0,1.29,107.74],[1,1.25,261.35],[2,1.24,623.65]],"ltp":1.3,"tv":9443.9,"id":9629022}]}]}
{"op":"mcm","clk":"4228069271","pt":1631459392720,"mc":[{"id":"1.187551081","rc":[{"batb":[[0,1.25,261.35],[1,1.24,623.65],[2,1.23,269.68]],"ltp":1.3,"tv":9443.9,"id":9629022}]}]}
{"op":"mcm","clk":"4228069556","pt":1631459394648,"mc":[{"id":"1.187551081","rc":[{"batb":[[0,3.7,4.42],[1,3.6,3],[2,3.55,3]],"ltp":4.3,"tv":1153.03,"id":7445998},{"batb":[[1,1.24,1131.87],[2,1.23,802.24]],"batl":[[0,1.37,96.5],[1,1.38,273.5],[2,1.39,266.47]],"ltp":1.3,"tv":9443.9,"id":9629022}]}]}
{"op":"mcm","clk":"4228069616","pt":1631459395043,"mc":[{"id":"1.187551081","rc":[{"batb":[[0,3.6,3],[1,3.55,3],[2,3.5,72.74]],"ltp":4.3,"tv":1153.03,"id":7445998},{"batl":[[0,1.38,273.5],[1,1.39,266.47],[2,1.4,95.64]],"ltp":1.3,"tv":9443.9,"id":9629022}]}]}
{"op":"mcm","clk":"4228070128","pt":1631459398643,"mc":[{"id":"1.187551081","rc":[{"batb":[[1,3.5,72.74],[2,3.45,61.73]],"ltp":4.3,"tv":1153.03,"id":7445998}]}]}
{"op":"mcm","clk":"4228070714","pt":1631459402570,"mc":[{"id":"1.187551081","rc":[{"batb":[[1,3.55,2],[2,3.5,72.74]],"ltp":4.3,"tv":1153.03,"id":7445998},{"batl":[[0,1.38,7],[1,1.4,95.64],[2,2,30]],"ltp":1.3,"tv":9443.9,"id":9629022}]}]}
{"op":"mcm","clk":"4228070758","pt":1631459402852,"mc":[{"id":"1.187551081","rc":[{"batl":[[1,2,30],[2,3.8,27.47]],"ltp":1.3,"tv":9443.9,"id":9629022}]}]}
{"op":"mcm","clk":"4228071179","pt":1631459405559,"mc":[{"id":"1.187551081","rc":[{"batb":[[0,4.4,12.26],[1,3.7,4.22],[2,3.6,3]],"batl":[[0,4.8,2.47],[1,5,49.83],[2,5.1,42.1]],"ltp":4.3,"tv":1153.03,"id":7445998},{"trd":[[1.27,428.27]],"batl":[[0,1.27,397.4],[1,1.28,398.88],[2,1.29,126.5]],"ltp":1.27,"tv":9639.64,"id":9629022}],"tv":10792.67}]}
{"op":"mcm","clk":"4228071372","pt":1631459406647,"mc":[{"id":"1.187551081","rc":[{"batb":[[0,4.7,67.24],[1,4.4,12.26],[2,4,15]],"batl":[[0,5,63.94],[1,5.1,42.1],[2,5.2,62.11]],"ltp":4.3,"tv":1153.03,"id":7445998},{"batb":[[0,1.25,312.79]],"ltp":1.27,"tv":9639.64,"id":9629022}]}]}
{"op":"mcm","clk":"4228071719","pt":1631459408954,"mc":[{"id":"1.187551081","rc":[{"batb":[[1,1.24,1187.44]],"batl":[[0,1.27,441.19]],"ltp":1.27,"tv":9639.64,"id":9629022}]}]}
{"op":"mcm","clk":"4228072008","pt":1631459410584,"mc":[{"id":"1.187551081","rc":[{"trd":[[5,56.33]],"batl":[[0,5,63.25]],"ltp":5.0,"tv":1154.4,"id":7445998},{"trd":[[1.25,1610.32]],"batb":[[0,1.25,426.67]],"ltp":1.25,"tv":9644.88,"id":9629022}],"tv":10799.29}]}
{"op":"mcm","clk":"4228072170","pt":1631459411469,"mc":[{"id":"1.187551081","rc":[{"batb":[[0,4.7,158.62]],"ltp":5.0,"tv":1154.4,"id":7445998},{"trd":[[1.27,463.23]],"batl":[[0,1.27,423.71],[1,1.28,734.43]],"ltp":1.27,"tv":9679.84,"id":9629022}],"tv":10834.25}]}
{"op":"mcm","clk":"4228072351","pt":1631459412585,"mc":[{"id":"1.187551081","rc":[{"batb":[[2,4,20.36]],"ltp":5.0,"tv":1154.4,"id":7445998}]}]}
{"op":"mcm","clk":"4228073519","pt":1631459420194,"mc":[{"id":"1.187551081","rc":[{"trd":[[1.27,470.59]],"batb":[[1,1.24,1178.44]],"batl":[[0,1.27,420.03]],"ltp":1.27,"tv":9687.2,"id":9629022}],"tv":10841.61}]}
{"op":"mcm","clk":"4228073950","pt":1631459422794,"mc":[{"id":"1.187551081","rc":[{"batl":[[0,1.27,481.03]],"ltp":1.27,"tv":9687.2,"id":9629022}]}]}
{"op":"mcm","clk":"4228074482","pt":1631459426501,"mc":[{"id":"1.187551081","rc":[{"batb":[[0,3.9,103.33],[1,3.75,57.96],[2,3.7,66.82]],"batl":[[0,6,42.88],[1,6.2,43.98],[2,6.4,49.54]],"ltp":5.0,"tv":1154.4,"id":7445998},{"batb":[[0,1.24,6.16],[1,1.23,7.04],[2,1.21,9.67]],"batl":[[0,1.36,8],[1,1.37,237.37],[2,1.38,142.96]],"ltp":1.27,"tv":9687.2,"id":9629022}]}]}
{"op":"mcm","clk":"4228074869","pt":1631459429180,"mc":[{"id":"1.187551081","rc":[{"batl":[[0,1.33,282.74],[1,1.34,315.94],[2,1.36,8]],"ltp":1.27,"tv":9687.2,"id":9629022}]}]}
{"op":"mcm","clk":"4228074951","pt":1631459429878,"mc":[{"id":"1.187551081","rc":[{"batb":[[0,4,5.36],[1,3.9,105.33],[2,3.85,2]],"ltp":5.0,"tv":1154.4,"id":7445998},{"batl":[[0,1.33,430.24],[2,1.35,7]],"ltp":1.27,"tv":9687.2,"id":9629022}]}]}
{"op":"mcm","clk":"4228075465","pt":1631459433198,"mc":[{"id":"1.187551081","rc":[{"batb":[[0,1.3,6677.52],[1,1.24,6.16],[2,1.23,7.04]],"ltp":1.27,"tv":9687.2,"id":9629022}]}]}
{"op":"mcm","clk":"4228075957","pt":1631459436652,"mc":[{"id":"1.187551081","rc":[{"batb":[[1,3.9,103.33],[2,3.75,57.96]],"ltp":5.0,"tv":1154.4,"id":7445998},{"batb":[[0,1.3,422.85],[1,1.29,397.81],[2,1.24,6.16]],"batl":[[2,1.37,237.37]],"ltp":1.27,"tv":9687.2,"id":9629022}]}]}
{"op":"mcm","clk":"4228076081","pt":1631459437505,"mc":[{"id":"1.187551081","rc":[{"batl":[[0,4.9,5]],"ltp":5.0,"tv":1154.4,"id":7445998},{"batb":[[0,1.31,43.39],[1,1.3,742.48],[2,1.29,397.81]],"ltp":1.27,"tv":9687.2,"id":9629022}]}]}
{"op":"mcm","clk":"4228076362","pt":1631459439415,"mc":[{"id":"1.187551081","rc":[{"batl":[[0,4.3,2],[1,4.9,5]],"ltp":5.0,"tv":1154.4,"id":7445998},{"batb":[[0,1.31,53.39],[1,1.3,750.48]],"ltp":1.27,"tv":9687.2,"id":9629022}]}]}
{"op":"mcm","clk":"4228076512","pt":1631459440384,"mc":[{"id":"1.187551081","rc":[{"batb":[[0,3.9,103.33],[1,3.75,57.96],[2,3.7,66.82]],"batl":[[0,4.2,3],[1,4.3,2]],"ltp":5.0,"tv":1154.4,"id":7445998},{"batb":[[0,1.31,214.24]],"batl":[[0,1.33,342.12]],"ltp":1.27,"tv":9687.2,"id":9629022}]}]}
{"op":"mcm","clk":"4228076629","pt":1631459441202,"mc":[{"id":"1.187551081","rc":[{"trd":[[4.2,9.96]],"batl":[[0,4.2,2.15]],"ltp":4.2,"tv":1156.1,"id":7445998},{"trd":[[1.31,85.11]],"batb":[[0,1.31,211.47]],"ltp":1.31,"tv":9692.74,"id":9629022}],"tv":10848.84}]}
{"op":"mcm","clk":"4228076942","pt":1631459443221,"mc":[{"id":"1.187551081","rc":[{"batl":[[0,4.2,12.15],[2,5.1,43.74]],"ltp":4.2,"tv":1156.1,"id":7445998}]}]}
{"op":"mcm","clk":"4228077108","pt":1631459444521,"mc":[{"id":"1.187551081","rc":[{"batb":[[0,3.7,4.22],[1,3.65,3],[2,3.5,5.98]],"batl":[[0,4.2,2.15]],"ltp":4.2,"tv":1156.1,"id":7445998},{"batb":[[0,1.31,10],[1,1.3,8],[2,1.24,587.37]],"batl":[[0,1.37,102.5],[1,1.4,139.34],[2,1.42,116.07]],"ltp":1.31,"tv":9692.74,"id":9629022}]}]}
{"op":"mcm","clk":"4228077198","pt":1631459445217,"mc":[{"id":"1.187551081","rc":[{"trd":[[3.5,183.5],[3.65,6]],"batb":[[0,3.35,140.38],[1,3.3,65.13],[2,3.25,74.35]],"batl":[[0,5.1,43.74],[1,5.2,41.67],[2,5.3,48.04]],"ltp":3.5,"tv":1174.48,"id":7445998},{"trd":[[1.4,65.04]],"batb":[[0,1.24,587.37],[1,1.23,226.33],[2,1.22,206.3]],"batl":[[0,1.4,138.29],[1,1.42,116.07],[2,1.43,129.63]],"ltp":1.4,"tv":9693.79,"id":9629022}],"tv":10868.27}]}
{"op":"mcm","clk":"4228077311","pt":1631459446111,"mc":[{"id":"1.187551081","rc":[{"batb":[[0,1.32,100],[1,1.24,587.37],[2,1.23,226.33]],"ltp":1.4,"tv":9693.79,"id":9629022}]}]}
{"op":"mcm","clk":"4228077454","pt":1631459447118,"mc":[{"id":"1.187551081","rc":[{"batb":[[1,1.24,1033.16],[2,1.23,755.62]],"batl":[[0,1.4,453.71],[1,1.41,248.61],[2,1.42,116.07]],"ltp":1.4,"tv":9693.79,"id":9629022}]}]}
{"op":"mcm","clk":"4228077652","pt":1631459448539,"mc":[{"id":"1.187551081","rc":[{"batb":[[0,3.5,8.44],[1,3.45,3],[2,3.35,140.38]],"batl":[[0,5.1,45.74]],"ltp":3.5,"tv":1174.48,"id":7445998},{"batb":[[1,1.24,1043.16],[2,1.23,767.62]],"batl":[[0,1.4,460.71]],"ltp":1.4,"tv":9693.79,"id":9629022}]}]}
{"op":"mcm","clk":"4228078155","pt":1631459451622,"mc":[{"id":"1.187551081","rc":[{"batb":[[0,3.7,5.22],[1,3.5,8.44],[2,3.45,3]],"ltp":3.5,"tv":1174.48,"id":7445998},{"batl":[[0,1.37,142.5],[1,1.4,460.71],[2,1.41,248.61]],"ltp":1.4,"tv":9693.79,"id":9629022}]}]}
{"op":"mcm","clk":"4228078243","pt":1631459452109,"mc":[{"id":"1.187551081","rc":[{"batb":[[0,3.5,8.44],[1,3.45,3],[2,3.35,74.36]],"batl":[[0,5.1,43.74]],"ltp":3.5,"tv":1174.48,"id":7445998},{"batb":[[1,1.24,1033.16],[2,1.23,755.62]],"batl":[[0,1.4,145.29],[1,2,30],[2,3.8,27.47]],"ltp":1.4,"tv":9693.79,"id":9629022}]}]}
{"op":"mcm","clk":"4228078448","pt":1631459453632,"mc":[{"id":"1.187551081","rc":[{"trd":[[1.32,215.21]],"batb":[[0,1.24,1033.16],[1,1.23,755.62],[2,1.22,206.3]],"ltp":1.32,"tv":9893.79,"id":9629022}],"tv":11068.27}]}
{"op":"mcm","clk":"4228078683","pt":1631459455136,"mc":[{"id":"1.187551081","rc":[{"batl":[[0,1.27,547.71],[1,1.28,396.39],[2,1.4,145.29]],"ltp":1.32,"tv":9893.79,"id":9629022}]}]}
{"op":"mcm","clk":"4228078907","pt":1631459456520,"mc":[{"id":"1.187551081","rc":[{"batb":[[0,4.7,66.99],[1,3.75,56.77],[2,3.5,8.44]],"ltp":3.5,"tv":1174.48,"id":7445998}]}]}
{"op":"mcm","clk":"4228078968","pt":1631459456946,"mc":[{"id":"1.187551081","rc":[{"batb":[[1,4,42.2],[2,3.75,56.77]],"batl":[[0,5.1,56.94]],"ltp":3.5,"tv":1174.48,"id":7445998},{"batb":[[0,1.25,8],[1,1.24,1099.77],[2,1.23,755.62]],"batl":[[2,1.33,185.84]],"ltp":1.32,"tv":9893.79,"id":9629022}]}]}
{"op":"mcm","clk":"4228079340","pt":1631459459337,"mc":[{"id":"1.187551081","rc":[{"trd":[[5,57.03]],"ltp":5.0,"tv":1175.18,"id":7445998},{"trd":[[1.25,1618.57]],"batb":[[0,1.25,161.4]],"batl":[[0,1.27,596.72]],"ltp":1.25,"tv":9902.04,"id":9629022}],"tv":11077.22}]}
{"op":"mcm","clk":"4228079491","pt":1631459460331,"mc":[{"id":"1.187551081","rc":[{"trd":[[1.25,1628.99]],"batb":[[0,1.25,156.19]],"ltp":1.25,"tv":9912.46,"id":9629022}],"tv":11087.64}]}
{"op":"mcm","clk":"4228079836","pt":1631459462543,"mc":[{"id":"1.187551081","rc":[{"batb":[[1,4,46.6]],"ltp":5.0,"tv":1175.18,"id":7445998},{"batl":[[2,1.33,316.34]],"ltp":1.25,"tv":9912.46,"id":9629022}]}]}
{"op":"mcm","clk":"4228079984","pt":1631459463528,"mc":[{"id":"1.187551081","rc":[{"batb":[[1,1.24,1283.03]],"batl":[[0,1.26,67.21],[1,1.27,596.72],[2,1.28,396.39]],"ltp":1.25,"tv":9912.46,"id":9629022}]}]}
{"op":"mcm","clk":"4228081021","pt":1631459470158,"mc":[{"id":"1.187551081","rc":[{"trd":[[4.8,183.75]],"ltp":4.8,"tv":1175.33,"id":7445998},{"trd":[[1.26,170.59]],"batl":[[0,1.26,66.62]],"ltp":1.26,"tv":9913.05,"id":9629022}],"tv":11088.38}]}
{"op":"mcm","clk":"4228081416","pt":1631459472646,"mc":[{"id":"1.187551081","rc":[{"batb":[[0,3.75,56.77],[1,3.7,4.42],[2,2.2,42.66]],"ltp":4.8,"tv":1175.33,"id":7445998},{"batb":[[0,1.24,6.16],[1,1.23,7.04],[2,1.21,9.67]],"batl":[[0,1.37,121.5],[1,2,30],[2,3.8,27.47]],"ltp":1.26,"tv":9913.05,"id":9629022}]}]}
{"op":"mcm","clk":"4228081867","pt":1631459475566,"mc":[{"id":"1.187551081","rc":[{"batl":[[0,1.35,437.22],[1,1.36,292.01],[2,1.37,121.5]],"ltp":1.26,"tv":9913.05,"id":9629022}]}]}
{"op":"mcm","clk":"4228082384","pt":1631459479438,"mc":[{"id":"1.187551081","rc":[{"batb":[[0,4,4.29],[1,3.75,56.77],[2,3.7,4.42]],"ltp":4.8,"tv":1175.33,"id":7445998},{"batl":[[0,1.33,132.5],[1,1.35,437.22],[2,1.36,292.01]],"ltp":1.26,"tv":9913.05,"id":9629022}]}]}
{"op":"mcm","clk":"4228082423","pt":1631459479764,"mc":[{"id":"1.187551081","rc":[{"batb":[[0,3.75,56.77],[1,3.7,4.42],[2,2.2,42.66]],"ltp":4.8,"tv":1175.33,"id":7445998},{"batl":[[0,1.35,437.22],[1,1.36,292.01],[2,1.37,121.5]],"ltp":1.26,"tv":9913.05,"id":9629022}]}]}
{"op":"mcm","clk":"4228082920","pt":1631459483277,"mc":[{"id":"1.187551081","rc":[{"trd":[[1.21,269.55],[1.23,135.25],[1.24,880.35]],"batb":[[0,1.18,6.16],[1,1.17,673.37],[2,1.16,1167.06]],"batl":[[0,2,30],[1,3.8,27.47],[2,8.8,7.23]],"ltp":1.21,"tv":9958.78,"id":9629022}],"tv":11134.12}]}
{"op":"mcm","clk":"4228083318","pt":1631459486075,"mc":[{"id":"1.187551081","rc":[{"batb":[[0,6.2,14.17],[1,3.75,56.77],[2,3.7,4.42]],"batl":[[0,7,2]],"ltp":4.8,"tv":1175.33,"id":7445998},{"batl":[[0,1.19,550.88],[1,1.2,598.25],[2,1.39,17.79]],"ltp":1.21,"tv":9958.78,"id":9629022}]}]}
{"op":"mcm","clk":"4228083503","pt":1631459487490,"mc":[{"id":"1.187551081","rc":[{"batb":[[0,6.2,85.26],[1,5.2,48.08],[2,4.7,67.41]],"batl":[[1,7.8,5]],"ltp":4.8,"tv":1175.33,"id":7445998},{"batl":[[2,1.24,150]],"ltp":1.21,"tv":9958.78,"id":9629022}]}]}
{"op":"mcm","clk":"4228083672","pt":1631459488573,"mc":[{"id":"1.187551081","rc":[{"batl":[[1,11.5,69.66]],"ltp":4.8,"tv":1175.33,"id":7445998}]}]}
{"op":"mcm","clk":"4228083759","pt":1631459489073,"mc":[{"id":"1.187551081","rc":[{"batl":[[0,6.8,3],[1,7,2],[2,11.5,69.66]],"ltp":4.8,"tv":1175.33,"id":7445998},{"batb":[[0,1.18,20.16],[1,1.17,685.37]],"ltp":1.21,"tv":9958.78,"id":9629022}]}]}
{"op":"mcm","clk":"4228083942","pt":1631459490287,"mc":[{"id":"1.187551081","rc":[{"trd":[[6.6,5.63]],"ltp":6.6,"tv":1175.77,"id":7445998},{"trd":[[1.18,122.91]],"batb":[[0,1.18,15.2]],"ltp":1.18,"tv":9966.26,"id":9629022}],"tv":11142.04}]}
{"op":"mcm","clk":"4228084131","pt":1631459491481,"mc":[{"id":"1.187551081","rc":[{"batl":[[0,6.8,13]],"ltp":6.6,"tv":1175.77,"id":7445998},{"trd":[[1.17,853.62],[1.18,153.3]],"batb":[[0,1.17,854.5],[1,1.16,1167.06],[2,1.13,1.28]],"batl":[[0,1.19,702.17]],"ltp":1.17,"tv":10139.65,"id":9629022}],"tv":11315.43}]}
{"op":"mcm","clk":"4228084304","pt":1631459492513,"mc":[{"id":"1.187551081","rc":[{"batb":[[2,4.7,71.13]],"batl":[[0,6.6,2],[1,6.8,13],[2,7,2]],"ltp":6.6,"tv":1175.77,"id":7445998}]}]}
{"op":"mcm","clk":"4228084587","pt":1631459494291,"mc":[{"id":"1.187551081","rc":[{"batb":[[0,1.17,966.07],[1,1.16,1206.91]],"batl":[[0,1.19,740.99]],"ltp":1.17,"tv":10139.65,"id":9629022}]}]}
{"op":"mcm","clk":"4228084733","pt":1631459495275,"mc":[{"id":"1.187551081","rc":[{"trd":[[1.19,390.18]],"batl":[[0,1.19,719.3]],"ltp":1.19,"tv":10183.03,"id":9629022}],"tv":11358.81}]}
{"op":"mcm","clk":"4228084916","pt":1631459496277,"mc":[{"id":"1.187551081","rc":[{"batb":[[0,5.2,48.08],[1,4.7,71.13],[2,4.2,3.77]],"ltp":6.6,"tv":1175.77,"id":7445998},{"batb":[[0,1.17,91.58],[1,1.13,1.28],[2,1.1,1125.94]],"batl":[[0,1.24,150],[1,1.27,122.5],[2,1.29,113.5]],"ltp":1.19,"tv":10183.03,"id":9629022}]}]}
{"op":"mcm","clk":"4228085076","pt":1631459497473,"mc":[{"id":"1.187551081","rc":[{"batb":[[0,6.2,77.53],[1,5.2,48.08],[2,4.7,71.13]],"ltp":6.6,"tv":1175.77,"id":7445998},{"batl":[[0,1.19,403.96],[1,1.24,150],[2,1.27,122.5]],"ltp":1.19,"tv":10183.03,"id":9629022}]}]}
{"op":"mcm","clk":"4228085132","pt":1631459497899,"mc":[{"id":"1.187551081","rc":[{"batb":[[0,5.2,48.08],[1,4.7,71.13],[2,4.2,3.77]],"batl":[[0,11.5,69.66],[1,6.8,0],[2,7,0]],"ltp":6.6,"tv":1175.77,"id":7445998},{"batb":[[0,1.13,1.28],[1,1.1,1125.94],[2,1.03,494.18]],"batl":[[0,1.24,150],[1,1.27,122.5],[2,1.29,113.5]],"ltp":1.19,"tv":10183.03,"id":9629022}]}]}
{"op":"mcm","clk":"4228085398","pt":1631459499499,"mc":[{"id":"1.187551081","rc":[{"batb":[[0,5.3,2],[1,5.2,50.08],[2,4.7,71.13]],"ltp":6.6,"tv":1175.77,"id":7445998},{"batb":[[1,1.11,851.42],[2,1.1,1521.14]],"batl":[[0,1.23,11],[1,1.24,150],[2,1.26,233.09]],"ltp":1.19,"tv":10183.03,"id":9629022}]}]}
{"op":"mcm","clk":"4228085447","pt":1631459499767,"mc":[{"id":"1.187551081","rc":[{"batb":[[0,4.7,71.13],[1,4.2,3.77],[2,3.15,375.55]],"ltp":6.6,"tv":1175.77,"id":7445998},{"batl":[[0,1.26,233.09],[1,1.27,544.32],[2,1.29,113.5]],"ltp":1.19,"tv":10183.03,"id":9629022}]}]}
{"op":"mcm","clk":"4228085678","pt":1631459501280,"mc":[{"id":"1.187551081","rc":[{"batl":[[0,11,3],[1,11.5,69.66]],"ltp":6.6,"tv":1175.77,"id":7445998},{"batb":[[0,1.14,6.4],[1,1.13,1.28],[2,1.11,851.42]],"ltp":1.19,"tv":10183.03,"id":9629022}]}]}
{"op":"mcm","clk":"4228085829","pt":1631459502291,"mc":[{"id":"1.187551081","rc":[{"batb":[[2,1.1,1145.94]],"ltp":1.19,"tv":10183.03,"id":9629022}]}]}
{"op":"mcm","clk":"4228086032","pt":1631459503603,"mc":[{"id":"1.187551081","rc":[{"batb":[[0,4.8,3],[1,4.7,74.13],[2,4.2,3.77]],"ltp":6.6,"tv":1175.77,"id":7445998},{"batb":[[0,1.24,7878.64],[1,1.14,6.4],[2,1.13,1.28]],"batl":[[0,1.26,241.09]],"ltp":1.19,"tv":10183.03,"id":9629022}]}]}
{"op":"mcm","clk":"4228086175","pt":1631459504607,"mc":[{"id":"1.187551081","rc":[{"batb":[[0,4.7,71.13],[1,4.2,3.77],[2,3.15,375.55]],"batl":[[0,7.8,15],[1,11,3]],"ltp":6.6,"tv":1175.77,"id":7445998},{"batb":[[0,1.14,6.4],[1,1.13,1.28],[2,1.1,1145.94]],"batl":[[0,1.26,233.09]],"ltp":1.19,"tv":10183.03,"id":9629022}]}]}
{"op":"mcm","clk":"4228086300","pt":1631459505492,"mc":[{"id":"1.187551081","rc":[{"batb":[[0,1.24,338.51],[1,1.23,527.46],[2,1.13,1.28]],"ltp":1.19,"tv":10183.03,"id":9629022}]}]}
{"op":"mcm","clk":"4228086423","pt":1631459506406,"mc":[{"id":"1.187551081","rc":[{"trd":[[5.2,133.66]],"batb":[[2,3.75,56.52]],"ltp":5.2,"tv":1223.85,"id":7445998},{"trd":[[1.24,1485.2]],"batb":[[0,1.24,363.92],[2,1.16,657.18]],"ltp":1.24,"tv":10787.88,"id":9629022}],"tv":12011.74}]}
{"op":"mcm","clk":"4228086572","pt":1631459507585,"mc":[{"id":"1.187551081","rc":[{"batl":[[1,10,3],[2,11,3]],"ltp":5.2,"tv":1223.85,"id":7445998}]}]}
{"op":"mcm","clk":"4228086695","pt":1631459508496,"mc":[{"id":"1.187551081","rc":[{"batl":[[0,5.1,2],[1,7.2,91.22],[2,7.6,2]],"ltp":5.2,"tv":1223.85,"id":7445998}]}]}
{"op":"mcm","clk":"4228086836","pt":1631459509410,"mc":[{"id":"1.187551081","rc":[{"batb":[[0,1.24,596.93]],"batl":[[0,1.26,384.11]],"ltp":1.24,"tv":10787.88,"id":9629022}]}]}
{"op":"mcm","clk":"4228087000","pt":1631459510304,"mc":[{"id":"1.187551081","rc":[{"trd":[[5.1,1.38]],"batl":[[0,5.1,1.31]],"ltp":5.1,"tv":1225.22,"id":7445998},{"trd":[[1.24,1490.59]],"batb":[[0,1.24,594.24],[1,1.23,680.34],[2,1.22,445.06]],"batl":[[0,1.26,562.69]],"ltp":1.24,"tv":10793.28,"id":9629022}],"tv":12018.51}]}
{"op":"mcm","clk":"4228087346","pt":1631459512301,"mc":[{"id":"1.187551081","rc":[{"batb":[[2,4,4.36]],"ltp":5.1,"tv":1225.22,"id":7445998},{"batb":[[0,1.25,71.22],[1,1.24,594.24],[2,1.23,680.34]],"ltp":1.24,"tv":10793.28,"id":9629022}]}]}
{"op":"mcm","clk":"4228087639","pt":1631459514499,"mc":[{"id":"1.187551081","rc":[{"batl":[[0,5,15],[1,5.1,1.31],[2,7.2,91.22]],"ltp":5.1,"tv":1225.22,"id":7445998}]}]}
{"op":"mcm","clk":"4228087710","pt":1631459514986,"mc":[{"id":"1.187551081","rc":[{"batl":[[0,5.1,1.31],[1,7.2,91.22],[2,7.6,2]],"ltp":5.1,"tv":1225.22,"id":7445998}]}]}
{"op":"mcm","clk":"4228087813","pt":1631459515713,"mc":[{"id":"1.187551081","rc":[{"trd":[[1.26,180.15]],"batl":[[0,1.26,557.91]],"ltp":1.26,"tv":10802.84,"id":9629022}],"tv":12028.07}]}
{"op":"mcm","clk":"4228088693","pt":1631459521621,"mc":[{"id":"1.187551081","rc":[{"batl":[[0,5,13.12],[1,5.1,1.31],[2,7.2,91.22]],"ltp":5.1,"tv":1225.22,"id":7445998}]}]}
{"op":"mcm","clk":"4228088804","pt":1631459522346,"mc":[{"id":"1.187551081","rc":[{"batl":[[0,5.1,1.31],[1,7.2,91.22],[2,7.2,0]],"ltp":5.1,"tv":1225.22,"id":7445998}]}]}
{"op":"mcm","clk":"4228089284","pt":1631459525512,"mc":[{"id":"1.187551081","rc":[{"batl":[[0,4.9,12.38],[1,5.1,1.31],[2,7.2,91.22]],"ltp":5.1,"tv":1225.22,"id":7445998}]}]}
{"op":"mcm","clk":"4228089313","pt":1631459525723,"mc":[{"id":"1.187551081","rc":[{"batl":[[0,5.1,1.31],[1,7.2,91.22],[2,7.2,0]],"ltp":5.1,"tv":1225.22,"id":7445998}]}]}
{"op":"mcm","clk":"4228089758","pt":1631459528450,"mc":[{"id":"1.187551081","rc":[{"batb":[[0,4,4.36],[1,3.75,56.52],[2,3.7,4.12]],"batl":[[0,7.2,91.22],[1,7.2,0]],"ltp":5.1,"tv":1225.22,"id":7445998},{"batb":[[0,1.16,657.18],[1,1.15,14],[2,1.13,1.28]],"batl":[[0,1.33,113.5],[1,1.37,111.5],[2,2,30]],"ltp":1.26,"tv":10802.84,"id":9629022}]}]}
{"op":"mcm","clk":"4228089850","pt":1631459529043,"mc":[{"id":"1.187551081","rc":[{"batb":[[0,3.75,56.52],[1,3.7,4.12],[2,3.15,375.55]],"ltp":5.1,"tv":1225.22,"id":7445998},{"batl":[[0,1.37,111.5],[1,2,30],[2,3.8,27.47]],"ltp":1.26,"tv":10802.84,"id":9629022}]}]}
{"op":"mcm","clk":"4228090244","pt":1631459531648,"mc":[{"id":"1.187551081","rc":[{"batl":[[0,1.34,393.65],[1,1.35,306.23],[2,1.37,111.5]],"ltp":1.26,"tv":10802.84,"id":9629022}]}]}
{"op":"mcm","clk":"4228090419","pt":1631459532629,"mc":[{"id":"1.187551081","rc":[{"batb":[[0,3.8,55.94],[1,3.75,56.52],[2,3.7,4.12]],"batl":[[0,7.2,3]],"ltp":5.1,"tv":1225.22,"id":7445998},{"batb":[[0,1.16,669.18]],"ltp":1.26,"tv":10802.84,"id":9629022}]}]}
{"op":"mcm","clk":"4228090540","pt":1631459533494,"mc":[{"id":"1.187551081","rc":[{"batl":[[0,4.2,1668.06],[1,4.6,7.22],[2,7.2,3]],"ltp":5.1,"tv":1225.22,"id":7445998}]}]}
{"op":"mcm","clk":"4228090637","pt":1631459534196,"mc":[{"id":"1.187551081","rc":[{"batl":[[0,7.2,3],[1,4.6,0],[2,7.2,0]],"ltp":5.1,"tv":1225.22,"id":7445998},{"batb":[[0,1.31,274.94],[1,1.3,382.54],[2,1.17,6.16]],"ltp":1.26,"tv":10802.84,"id":9629022}]}]}
{"op":"mcm","clk":"4228090822","pt":1631459535610,"mc":[{"id":"1.187551081","rc":[{"batl":[[0,4.5,47.86],[1,7,2],[2,7.2,3]],"ltp":5.1,"tv":1225.22,"id":7445998},{"batb":[[0,1.32,299.03],[1,1.31,274.94],[2,1.3,382.54]],"ltp":1.26,"tv":10802.84,"id":9629022}]}]}
{"op":"mcm","clk":"4228090974","pt":1631459536623,"mc":[{"id":"1.187551081","rc":[{"batl":[[0,4.1,3],[1,4.5,15],[2,6,104.94]],"ltp":5.1,"tv":1225.22,"id":7445998}]}]}
{"op":"mcm","clk":"4228091095","pt":1631459537427,"mc":[{"id":"1.187551081","rc":[{"batl":[[1,4.2,2],[2,4.5,3]],"ltp":5.1,"tv":1225.22,"id":7445998},{"batb":[[0,1.32,307.03],[1,1.31,284.94]],"ltp":1.26,"tv":10802.84,"id":9629022}]}]}
{"op":"mcm","clk":"4228091285","pt":1631459538619,"mc":[{"id":"1.187551081","rc":[{"batb":[[0,1.32,497.18]],"batl":[[0,1.34,496.34]],"ltp":1.26,"tv":10802.84,"id":9629022}]}]}
{"op":"mcm","clk":"4228091442","pt":1631459539508,"mc":[{"id":"1.187551081","rc":[{"trd":[[4.1,20.17]],"batl":[[0,4.1,2.07]],"ltp":4.1,"tv":1227.08,"id":7445998},{"trd":[[1.33,5.72]],"ltp":1.33,"tv":10808.56,"id":9629022}],"tv":12035.65}]}
{"op":"mcm","clk":"4228091513","pt":1631459540039,"mc":[{"id":"1.187551081","rc":[{"batl":[[0,4,15],[1,4.1,2.07],[2,4.2,2]],"ltp":4.1,"tv":1227.08,"id":7445998}]}]}
{"op":"mcm","clk":"4228091941","pt":1631459542631,"mc":[{"id":"1.187551081","rc":[{"trd":[[1.34,113.76]],"batl":[[0,1.34,439.46]],"ltp":1.34,"tv":10922.32,"id":9629022}],"tv":12149.41}]}
{"op":"mcm","clk":"4228092094","pt":1631459543627,"mc":[{"id":"1.187551081","rc":[{"trd":[[4,0.98]],"batl":[[0,4,14.02]],"ltp":4.0,"tv":1228.06,"id":7445998},{"trd":[[1.33,8.67]],"ltp":1.33,"tv":10925.27,"id":9629022}],"tv":12153.33}]}
{"op":"mcm","clk":"4228092242","pt":1631459544637,"mc":[{"id":"1.187551081","rc":[{"batb":[[0,3.55,5.19],[1,3.5,5.7],[2,3.35,5.07]],"batl":[[0,4.1,2.07],[1,4.2,2],[2,4.5,3]],"ltp":4.0,"tv":1228.06,"id":7445998},{"batb":[[0,1.32,8],[1,1.31,10],[2,1.28,8]],"batl":[[0,1.39,115.5],[1,1.4,117.69],[2,1.42,109.25]],"ltp":1.33,"tv":10925.27,"id":9629022}]}]}
{"op":"mcm","clk":"4228092413","pt":1631459545648,"mc":[{"id":"1.187551081","rc":[{"batb":[[0,3.35,5.07],[1,3.2,61.07],[2,3.15,158.85]],"batl":[[0,5.1,43.6],[1,5.2,47.67],[2,5.3,45.78]],"ltp":4.0,"tv":1228.06,"id":7445998},{"batb":[[0,1.24,172.05],[1,1.23,647.91],[2,1.22,247.06]],"batl":[[0,1.42,109.25],[1,1.46,127.95],[2,1.47,171.34]],"ltp":1.33,"tv":10925.27,"id":9629022}]}]}
{"op":"mcm","clk":"4228092676","pt":1631459547468,"mc":[{"id":"1.187551081","rc":[{"batb":[[1,1.23,1268.65],[2,1.22,752.22]],"batl":[[0,1.42,277.31],[1,1.43,236.95],[2,1.46,127.95]],"ltp":1.33,"tv":10925.27,"id":9629022}]}]}
{"op":"mcm","clk":"4228092839","pt":1631459548434,"mc":[{"id":"1.187551081","rc":[{"batb":[[0,3.4,2],[1,3.35,7.07],[2,3.2,61.07]],"ltp":4.0,"tv":1228.06,"id":7445998},{"batl":[[0,1.41,6],[1,1.42,277.31],[2,1.43,236.95]],"ltp":1.33,"tv":10925.27,"id":9629022}]}]}
{"op":"mcm","clk":"4228092921","pt":1631459548980,"mc":[{"id":"1.187551081","rc":[{"batb":[[2,3.3,3]],"batl":[[0,5.1,46.6]],"ltp":4.0,"tv":1228.06,"id":7445998},{"batb":[[0,1.24,184.05],[1,1.23,1280.65]],"batl":[[1,1.42,283.31]],"ltp":1.33,"tv":10925.27,"id":9629022}]}]}
{"op":"mcm","clk":"4228093325","pt":1631459551653,"mc":[{"id":"1.187551081","rc":[{"batb":[[0,3.55,5.99],[1,3.4,2],[2,3.35,7.07]],"ltp":4.0,"tv":1228.06,"id":7445998},{"batl":[[0,1.39,128.5],[1,1.41,6],[2,1.42,283.31]],"ltp":1.33,"tv":10925.27,"id":9629022}]}]}
{"op":"mcm","clk":"4228093369","pt":1631459551868,"mc":[{"id":"1.187551081","rc":[{"batb":[[0,3.4,2],[1,3.35,7.07],[2,3.3,3]],"ltp":4.0,"tv":1228.06,"id":7445998},{"batl":[[0,1.41,6],[1,1.42,283.31],[2,1.43,236.95]],"ltp":1.33,"tv":10925.27,"id":9629022}]}]}
{"op":"mcm","clk":"4228094973","pt":1631459562365,"mc":[{"id":"1.187551081","rc":[{"batb":[[1,3.35,5.07],[2,3.2,61.07]],"ltp":4.0,"tv":1228.06,"id":7445998},{"batb":[[1,1.23,1268.65]],"batl":[[1,1.42,277.31]],"ltp":1.33,"tv":10925.27,"id":9629022}]}]}
{"op":"mcm","clk":"4228095451","pt":1631459565597,"mc":[{"id":"1.187551081","rc":[{"batb":[[0,3.55,5.79],[1,3.4,2],[2,3.35,7.07]],"ltp":4.0,"tv":1228.06,"id":7445998},{"batb":[[1,1.23,1279.65]],"batl":[[0,1.39,122.5],[1,1.41,6],[2,1.42,277.31]],"ltp":1.33,"tv":10925.27,"id":9629022}]}]}
{"op":"mcm","clk":"4228095504","pt":1631459565884,"mc":[{"id":"1.187551081","rc":[{"batb":[[0,3.4,2],[1,3.35,7.07],[2,3.2,61.07]],"ltp":4.0,"tv":1228.06,"id":7445998},{"batl":[[0,1.41,6],[1,1.42,277.31],[2,1.43,236.95]],"ltp":1.33,"tv":10925.27,"id":9629022}]}]}
{"op":"mcm","clk":"4228096013","pt":1631459569390,"mc":[{"id":"1.187551081","rc":[{"batb":[[2,3.15,86.25]],"batl":[[0,5.1,43.6]],"ltp":4.0,"tv":1228.06,"id":7445998},{"batb":[[0,1.24,172.05]],"batl":[[1,1.42,109.25],[2,2,30]],"ltp":1.33,"tv":10925.27,"id":9629022}]}]}
{"op":"mcm","clk":"4228096348","pt":1631459571624,"mc":[{"id":"1.187551081","rc":[{"batl":[[0,5.2,47.67],[1,5.3,45.78],[2,5.3,0]],"ltp":4.0,"tv":1228.06,"id":7445998},{"batb":[[0,1.23,1279.65],[1,1.22,752.22],[2,1.17,6.16]],"ltp":1.33,"tv":10925.27,"id":9629022}]}]}
{"op":"mcm","clk":"4228096436","pt":1631459572106,"mc":[{"id":"1.187551081","rc":[{"batb":[[0,4.7,16.42],[1,3.4,2],[2,3.35,7.07]],"ltp":4.0,"tv":1228.06,"id":7445998},{"batl":[[0,1.26,463.6],[1,1.27,602.59],[2,1.41,6]],"ltp":1.33,"tv":10925.27,"id":9629022}]}]}
{"op":"mcm","clk":"4228096665","pt":1631459573638,"mc":[{"id":"1.187551081","rc":[{"batb":[[0,4.7,82.99],[1,3.95,10],[2,3.8,55.85]],"ltp":4.0,"tv":1228.06,"id":7445998},{"batl":[[2,1.34,30]],"ltp":1.33,"tv":10925.27,"id":9629022}]}]}
{"op":"mcm","clk":"4228096812","pt":1631459574643,"mc":[{"id":"1.187551081","rc":[{"batl":[[2,7.2,91.22]],"ltp":4.0,"tv":1228.06,"id":7445998}]}]}
{"op":"mcm","clk":"4228096845","pt":1631459574798,"mc":[{"id":"1.187551081","rc":[{"batl":[[0,5.1,3],[1,5.2,47.67],[2,5.3,45.78]],"ltp":4.0,"tv":1228.06,"id":7445998},{"batb":[[0,1.24,7],[1,1.23,1279.65],[2,1.22,752.22]],"ltp":1.33,"tv":10925.27,"id":9629022}]}]}
{"op":"mcm","clk":"4228097100","pt":1631459576419,"mc":[{"id":"1.187551081","rc":[{"batb":[[0,1.24,189.21]],"batl":[[0,1.25,82.25],[1,1.26,545.27],[2,1.27,602.59]],"ltp":1.33,"tv":10925.27,"id":9629022}]}]}
{"op":"mcm","clk":"4228097525","pt":1631459579158,"mc":[{"id":"1.187551081","rc":[{"batb":[[1,4.1,4.74],[2,3.95,10]],"ltp":4.0,"tv":1228.06,"id":7445998}]}]}
{"op":"mcm","clk":"4228097723","pt":1631459580308,"mc":[{"id":"1.187551081","rc":[{"trd":[[5,75.42]],"ltp":5.0,"tv":1246.45,"id":7445998},{"trd":[[1.25,1719.93]],"batb":[[0,1.25,79.41],[1,1.24,189.21],[2,1.23,1279.65]],"batl":[[0,1.26,545.27],[1,1.27,602.59],[2,1.32,120.61]],"ltp":1.25,"tv":11016.21,"id":9629022}],"tv":12262.66}]}
{"op":"mcm","clk":"4228098887","pt":1631459587341,"mc":[{"id":"1.187551081","rc":[{"batb":[[2,1.23,1268.65]],"ltp":1.25,"tv":11016.21,"id":9629022}]}]}
{"op":"mcm","clk":"4228099630","pt":1631459591594,"mc":[{"id":"1.187551081","rc":[{"trd":[[1.25,1747.47]],"batb":[[0,1.25,65.64]],"ltp":1.25,"tv":11043.75,"id":9629022}],"tv":12290.2}]}
{"op":"mcm","clk":"4228099658","pt":1631459591822,"mc":[{"id":"1.187551081","rc":[{"batl":[[0,1.26,463.6]],"ltp":1.25,"tv":11043.75,"id":9629022}]}]}
{"op":"mcm","clk":"4228100853","pt":1631459599102,"mc":[{"id":"1.187551081","rc":[{"batb":[[0,4.7,66.57]],"ltp":5.0,"tv":1246.45,"id":7445998},{"batl":[[1,1.27,420.09]],"ltp":1.25,"tv":11043.75,"id":9629022}]}]}
