{"op":"mcm","clk":"4231987682","pt":1631550428251,"mc":[{"id":"1.187560634","rc":[{"batb":[[0,4.4,2.56],[1,3.8,38.75],[2,1.01,105.79]],"ltp":5.0,"tv":4475.25,"id":9629296},{"batl":[[0,1.29,93.5],[1,1.66,2.88],[2,3,5.2]],"ltp":1.26,"tv":8539.53,"id":12343905}]}]}
{"op":"mcm","clk":"4231987923","pt":1631550431655,"mc":[{"id":"1.187560634","rc":[{"batb":[[0,4.8,28.34],[1,4.7,27.5],[2,4.6,27.5]],"batl":[[0,5.3,6.91],[1,5.4,2.04],[2,5.5,64.4]],"ltp":5.0,"tv":4475.25,"id":9629296},{"batb":[[2,1.21,48.84]],"batl":[[0,1.25,9.94],[1,1.26,491.63],[2,1.27,190.53]],"ltp":1.26,"tv":8539.53,"id":12343905}]}]}
{"op":"mcm","clk":"4231988097","pt":1631550433445,"mc":[{"id":"1.187560634","rc":[{"trd":[[1.23,8.8]],"batb":[[0,1.23,443.49]],"ltp":1.23,"tv":8545.07,"id":12343905}],"tv":13020.33}]}
{"op":"mcm","clk":"4231988831","pt":1631550443475,"mc":[{"id":"1.187560634","rc":[{"batb":[[0,1.23,433.94]],"batl":[[1,1.26,324.19]],"ltp":1.23,"tv":8545.07,"id":12343905}]}]}
{"op":"mcm","clk":"4231989080","pt":1631550446669,"mc":[{"id":"1.187560634","rc":[{"batb":[[0,1.24,9.55],[1,1.23,433.94],[2,1.22,235.2]],"ltp":1.23,"tv":8545.07,"id":12343905}]}]}
{"op":"mcm","clk":"4231989677","pt":1631550454670,"mc":[{"id":"1.187560634","rc":[{"trd":[[5,1.37]],"ltp":5.0,"tv":4476.6,"id":9629296},{"trd":[[1.25,149.24]],"batl":[[0,1.25,4.54]],"ltp":1.25,"tv":8550.47,"id":12343905}],"tv":13027.08}]}
{"op":"mcm","clk":"4231989765","pt":1631550455876,"mc":[{"id":"1.187560634","rc":[{"trd":[[1.25,150.74]],"batl":[[0,1.25,3.79]],"ltp":1.25,"tv":8551.97,"id":12343905}],"tv":13028.58}]}
{"op":"mcm","clk":"4231990400","pt":1631550464905,"mc":[{"id":"1.187560634","rc":[{"batl":[[0,5.4,2.04],[1,5.5,64.4],[2,5.7,23.86]],"ltp":5.0,"tv":4476.6,"id":9629296},{"batl":[[0,1.26,324.19],[1,1.27,190.53],[2,1.28,99.34]],"ltp":1.25,"tv":8551.97,"id":12343905}]}]}
{"op":"mcm","clk":"4231990809","pt":1631550470913,"mc":[{"id":"1.187560634","rc":[{"batb":[[0,1.24,23.42]],"batl":[[0,1.25,6.87],[1,1.26,324.19],[2,1.27,190.53]],"ltp":1.25,"tv":8551.97,"id":12343905}]}]}
{"op":"mcm","clk":"4231991412","pt":1631550479307,"mc":[{"id":"1.187560634","rc":[{"trd":[[1.25,153.71]],"batl":[[0,1.25,5.38]],"ltp":1.25,"tv":8554.95,"id":12343905}],"tv":13031.56}]}
{"op":"mcm","clk":"4231992205","pt":1631550489559,"mc":[{"id":"1.187560634","rc":[{"batb":[[0,1.24,9.55]],"batl":[[0,1.26,324.19],[1,1.27,190.53],[2,1.28,99.34]],"ltp":1.25,"tv":8554.95,"id":12343905}]}]}
{"op":"mcm","clk":"4231992393","pt":1631550492444,"mc":[{"id":"1.187560634","rc":[{"batb":[[0,1.24,24.92]],"batl":[[0,1.26,361.92]],"ltp":1.25,"tv":8554.95,"id":12343905}]}]}
{"op":"mcm","clk":"4231992967","pt":1631550500075,"mc":[{"id":"1.187560634","rc":[{"trd":[[4.8,56.29]],"batb":[[0,4.8,27.41]],"ltp":4.8,"tv":4478.46,"id":9629296}],"tv":13033.42}]}
{"op":"mcm","clk":"4231993949","pt":1631550512389,"mc":[{"id":"1.187560634","rc":[{"trd":[[4.8,63.37]],"batb":[[0,4.8,23.87]],"ltp":4.8,"tv":4485.54,"id":9629296}],"tv":13040.49}]}
{"op":"mcm","clk":"4231994066","pt":1631550513653,"mc":[{"id":"1.187560634","rc":[{"trd":[[1.26,718.11]],"batb":[[0,1.24,15.37]],"batl":[[0,1.26,361.85]],"ltp":1.26,"tv":8555.09,"id":12343905}],"tv":13040.63}]}
{"op":"mcm","clk":"4231994227","pt":1631550515582,"mc":[{"id":"1.187560634","rc":[{"batl":[[0,5.2,2.62],[1,5.4,2.04],[2,5.5,64.4]],"ltp":4.8,"tv":4485.54,"id":9629296},{"trd":[[1.24,13.86]],"batb":[[0,1.24,8.44]],"ltp":1.24,"tv":8568.95,"id":12343905}],"tv":13054.5}]}
{"op":"mcm","clk":"4231994291","pt":1631550516376,"mc":[{"id":"1.187560634","rc":[{"trd":[[1.26,737.21]],"batl":[[0,1.26,352.3]],"ltp":1.26,"tv":8588.04,"id":12343905}],"tv":13073.59}]}
{"op":"mcm","clk":"4231994858","pt":1631550524587,"mc":[{"id":"1.187560634","rc":[{"batb":[[0,4.4,2.56],[1,4,33.38],[2,1.01,105.79]],"batl":[[0,7,2],[1,990,0.01],[2,5.5,0]],"ltp":4.8,"tv":4485.54,"id":9629296},{"batb":[[0,1.17,144.97],[1,1.15,230.92],[2,1.1,2]],"batl":[[0,1.29,93.5],[1,1.66,2.88],[2,3,5.2]],"ltp":1.26,"tv":8588.04,"id":12343905}]}]}
{"op":"mcm","clk":"4231995026","pt":1631550527561,"mc":[{"id":"1.187560634","rc":[{"batb":[[0,4.5,2.58],[1,4.4,2.56],[2,4,33.38]],"ltp":4.8,"tv":4485.54,"id":9629296},{"batb":[[0,1.18,394.66],[1,1.17,329.74],[2,1.15,230.92]],"batl":[[0,1.28,94.59],[1,1.29,93.5],[2,1.3,181.95]],"ltp":1.26,"tv":8588.04,"id":12343905}]}]}
{"op":"mcm","clk":"4231995057","pt":1631550528290,"mc":[{"id":"1.187560634","rc":[{"batb":[[0,4.4,2.56],[1,4,33.38],[2,1.01,105.79]],"ltp":4.8,"tv":4485.54,"id":9629296},{"batl":[[0,1.29,93.5],[1,1.3,181.95],[2,1.31,160.79]],"ltp":1.26,"tv":8588.04,"id":12343905}]}]}
{"op":"mcm","clk":"4231995073","pt":1631550528702,"mc":[{"id":"1.187560634","rc":[{"batb":[[0,1.17,144.97],[1,1.15,230.92],[2,1.1,2]],"ltp":1.26,"tv":8588.04,"id":12343905}]}]}
{"op":"mcm","clk":"4231995236","pt":1631550531482,"mc":[{"id":"1.187560634","rc":[{"batb":[[0,4.5,6.53],[1,4.4,2.56],[2,4,33.38]],"batl":[[0,4.7,3.69],[1,5,39.2],[2,6.4,2]],"ltp":4.8,"tv":4485.54,"id":9629296},{"batb":[[0,1.27,3656.19],[1,1.26,215.88],[2,1.25,366.31]],"batl":[[1,1.3,381.65]],"ltp":1.26,"tv":8588.04,"id":12343905}]}]}
{"op":"mcm","clk":"4231995299","pt":1631550532489,"mc":[{"id":"1.187560634","rc":[{"batl":[[1,4.8,5.07],[2,5,39.2]],"ltp":4.8,"tv":4485.54,"id":9629296},{"batb":[[0,1.27,538.08],[1,1.26,316.11],[2,1.25,261.55]],"ltp":1.26,"tv":8588.04,"id":12343905}]}]}
{"op":"mcm","clk":"4231995533","pt":1631550536513,"mc":[{"id":"1.187560634","rc":[{"batl":[[1,1.3,607.36]],"ltp":1.26,"tv":8588.04,"id":12343905}]}]}
{"op":"mcm","clk":"4231995545","pt":1631550536720,"mc":[{"id":"1.187560634","rc":[{"batl":[[1,1.3,381.65]],"ltp":1.26,"tv":8588.04,"id":12343905}]}]}
{"op":"mcm","clk":"4231995680","pt":1631550538337,"mc":[{"id":"1.187560634","rc":[{"batb":[[2,4.2,2.82]],"ltp":4.8,"tv":4485.54,"id":9629296},{"batl":[[2,1.31,233.29]],"ltp":1.26,"tv":8588.04,"id":12343905}]}]}
{"op":"mcm","clk":"4231996093","pt":1631550543518,"mc":[{"id":"1.187560634","rc":[{"batb":[[0,4.2,2.82],[1,4.1,3.04],[2,4,33.38]],"batl":[[0,5.2,2.03],[1,5.6,2.06],[2,6.4,2]],"ltp":4.8,"tv":4485.54,"id":9629296},{"batb":[[0,1.24,155.93],[1,1.23,148.8],[2,1.22,118.34]],"batl":[[0,1.31,72.5],[1,1.32,82.61],[2,1.35,43.77]],"ltp":1.26,"tv":8588.04,"id":12343905}]}]}
{"op":"mcm","clk":"4231996154","pt":1631550544402,"mc":[{"id":"1.187560634","rc":[{"batb":[[0,4.1,3.04],[1,3.75,40.35],[2,1.01,105.79]],"batl":[[0,5.6,2.06],[1,7,2],[2,990,0.01]],"ltp":4.8,"tv":4485.54,"id":9629296},{"batb":[[0,1.22,118.34],[1,1.19,186.72],[2,1.17,144.97]],"batl":[[0,1.32,82.61],[1,1.66,2.88],[2,3,5.2]],"ltp":1.26,"tv":8588.04,"id":12343905}]}]}
{"op":"mcm","clk":"4231996298","pt":1631550546553,"mc":[{"id":"1.187560634","rc":[{"batb":[[0,1.22,422.09],[1,1.21,257.27],[2,1.19,186.72]],"batl":[[1,1.33,112.91],[2,1.34,144.65]],"ltp":1.26,"tv":8588.04,"id":12343905}]}]}
{"op":"mcm","clk":"4231996575","pt":1631550550591,"mc":[{"id":"1.187560634","rc":[{"batb":[[0,4.2,2.67],[1,4.1,3.04],[2,3.75,40.35]],"batl":[[0,5.2,2.03],[1,5.6,2.06],[2,7,2]],"ltp":4.8,"tv":4485.54,"id":9629296},{"batb":[[0,1.24,103.27],[1,1.22,422.09],[2,1.21,257.27]],"batl":[[0,1.31,76.5],[1,1.32,82.61],[2,1.33,112.91]],"ltp":1.26,"tv":8588.04,"id":12343905}]}]}
{"op":"mcm","clk":"4231996593","pt":1631550550903,"mc":[{"id":"1.187560634","rc":[{"batb":[[0,4.1,3.04],[1,3.75,40.35],[2,1.01,105.79]],"batl":[[0,5.6,2.06],[1,7,2],[2,990,0.01]],"ltp":4.8,"tv":4485.54,"id":9629296},{"batb":[[0,1.22,422.09],[1,1.21,257.27],[2,1.19,186.72]],"batl":[[0,1.32,82.61],[1,1.33,112.91],[2,1.34,144.65]],"ltp":1.26,"tv":8588.04,"id":12343905}]}]}
{"op":"mcm","clk":"4231996916","pt":1631550555504,"mc":[{"id":"1.187560634","rc":[{"batb":[[0,1.22,118.34],[1,1.19,186.72],[2,1.17,144.97]],"ltp":1.26,"tv":8588.04,"id":12343905}]}]}
{"op":"mcm","clk":"4231997135","pt":1631550558609,"mc":[{"id":"1.187560634","rc":[{"batb":[[0,4.2,5.18],[1,4.1,3.04],[2,3.9,34.88]],"batl":[[0,4.4,6.69],[1,4.5,54.03],[2,5.6,2.06]],"ltp":4.8,"tv":4485.54,"id":9629296},{"batb":[[0,1.3,3737.72],[1,1.29,344.63],[2,1.28,102.34]],"batl":[[1,1.33,304.82]],"ltp":1.26,"tv":8588.04,"id":12343905}]}]}
{"op":"mcm","clk":"4231997197","pt":1631550559302,"mc":[{"id":"1.187560634","rc":[{"batb":[[0,1.3,483.81]],"ltp":1.26,"tv":8588.04,"id":12343905}]}]}
{"op":"mcm","clk":"4231997699","pt":1631550565313,"mc":[{"id":"1.187560634","rc":[{"batl":[[2,4.8,2.17]],"ltp":4.8,"tv":4485.54,"id":9629296}]}]}
{"op":"mcm","clk":"4231997958","pt":1631550568505,"mc":[{"id":"1.187560634","rc":[{"batb":[[2,4,2.68]],"ltp":4.8,"tv":4485.54,"id":9629296},{"batl":[[1,1.33,370.32]],"ltp":1.26,"tv":8588.04,"id":12343905}]}]}
{"op":"mcm","clk":"4231998140","pt":1631550570645,"mc":[{"id":"1.187560634","rc":[{"batb":[[0,3.6,22.56],[1,1.01,105.79],[2,4,0]],"batl":[[0,4.9,2.15],[1,7,2],[2,990,0.01]],"ltp":4.8,"tv":4485.54,"id":9629296},{"batb":[[0,1.26,88.98],[1,1.22,156.1],[2,1.17,144.97]],"batl":[[0,1.33,65.5],[1,1.66,2.88],[2,3,5.2]],"ltp":1.26,"tv":8588.04,"id":12343905}]}]}
{"op":"mcm","clk":"4231998364","pt":1631550573638,"mc":[{"id":"1.187560634","rc":[{"batb":[[0,4.1,2.44],[1,4,2.93],[2,3.6,22.56]],"ltp":4.8,"tv":4485.54,"id":9629296},{"batb":[[0,1.26,365.59],[1,1.25,220.41],[2,1.22,156.1]],"batl":[[0,1.32,77.86],[1,1.33,65.5],[2,1.36,158.28]],"ltp":1.26,"tv":8588.04,"id":12343905}]}]}
{"op":"mcm","clk":"4231998406","pt":1631550574268,"mc":[{"id":"1.187560634","rc":[{"batb":[[0,4,2.93],[1,3.6,22.56],[2,1.01,105.79]],"ltp":4.8,"tv":4485.54,"id":9629296},{"batl":[[0,1.33,65.5],[1,1.36,158.28],[2,1.37,129.58]],"ltp":1.26,"tv":8588.04,"id":12343905}]}]}
{"op":"mcm","clk":"4231998484","pt":1631550575457,"mc":[{"id":"1.187560634","rc":[{"batb":[[0,1.26,88.98],[1,1.22,156.1],[2,1.17,144.97]],"ltp":1.26,"tv":8588.04,"id":12343905}]}]}
{"op":"mcm","clk":"4231998602","pt":1631550577557,"mc":[{"id":"1.187560634","rc":[{"batl":[[0,4.8,2.12],[1,4.9,2.15],[2,7,2]],"ltp":4.8,"tv":4485.54,"id":9629296},{"batb":[[0,1.27,94.87],[1,1.26,88.98],[2,1.22,156.1]],"ltp":1.26,"tv":8588.04,"id":12343905}]}]}
{"op":"mcm","clk":"4231998694","pt":1631550578655,"mc":[{"id":"1.187560634","rc":[{"batb":[[0,4,7.78],[1,3.65,37.26],[2,3.6,58.72]],"batl":[[0,4.2,8.38],[1,4.3,64.8],[2,4.9,2.15]],"ltp":4.8,"tv":4485.54,"id":9629296},{"trd":[[1.33,437.9]],"batb":[[0,1.32,262.9],[1,1.31,100],[2,1.3,100]],"batl":[[0,1.35,167.23]],"ltp":1.33,"tv":8719.04,"id":12343905}],"tv":13204.59}]}
{"op":"mcm","clk":"4231998908","pt":1631550581660,"mc":[{"id":"1.187560634","rc":[{"batb":[[0,1.32,326.72],[1,1.31,268.95]],"batl":[[1,1.36,193.72]],"ltp":1.33,"tv":8719.04,"id":12343905}]}]}
{"op":"mcm","clk":"4231999152","pt":1631550584868,"mc":[{"id":"1.187560634","rc":[{"batb":[[1,3.9,2.76],[2,3.65,37.26]],"batl":[[2,4.4,2.59]],"ltp":4.8,"tv":4485.54,"id":9629296},{"batb":[[2,1.3,187.58]],"batl":[[0,1.34,65.25],[1,1.35,167.23],[2,1.36,193.72]],"ltp":1.33,"tv":8719.04,"id":12343905}]}]}
{"op":"mcm","clk":"4231999463","pt":1631550589536,"mc":[{"id":"1.187560634","rc":[{"trd":[[4,4.34]],"batb":[[0,4,5.61]],"ltp":4.0,"tv":4489.88,"id":9629296}],"tv":13208.93}]}
{"op":"mcm","clk":"4231999957","pt":1631550596650,"mc":[{"id":"1.187560634","rc":[{"batb":[[0,3.9,3.52],[1,3.6,22.56],[2,3.45,24.91]],"batl":[[0,4.4,2.59],[1,4.5,3.01],[2,4.9,2.15]],"ltp":4.0,"tv":4489.88,"id":9629296},{"batb":[[0,1.32,223.7],[1,1.31,168.95],[2,1.3,87.58]],"batl":[[1,1.36,193.72],[2,1.37,129.58]],"ltp":1.33,"tv":8719.04,"id":12343905}]}]}
{"op":"mcm","clk":"4232000004","pt":1631550597373,"mc":[{"id":"1.187560634","rc":[{"batb":[[0,3.45,24.91],[1,1.01,105.79],[2,3.45,0]],"batl":[[0,4.5,3.01],[1,7,2],[2,990,0.01]],"ltp":4.0,"tv":4489.88,"id":9629296},{"batb":[[0,1.29,90.81],[1,1.26,134.38],[2,1.17,144.97]],"batl":[[1,1.37,95.93],[2,1.66,2.88]],"ltp":1.33,"tv":8719.04,"id":12343905}]}]}
{"op":"mcm","clk":"4232000230","pt":1631550600587,"mc":[{"id":"1.187560634","rc":[{"batb":[[0,3.9,2.76],[1,3.45,24.91],[2,1.01,105.79]],"ltp":4.0,"tv":4489.88,"id":9629296},{"batb":[[0,1.3,132.11],[1,1.29,272.67],[2,1.26,134.38]],"batl":[[2,1.38,126.58]],"ltp":1.33,"tv":8719.04,"id":12343905}]}]}
{"op":"mcm","clk":"4232000421","pt":1631550602675,"mc":[{"id":"1.187560634","rc":[{"batl":[[1,1.66,2.88],[2,3,5.2]],"ltp":1.33,"tv":8719.04,"id":12343905}]}]}
{"op":"mcm","clk":"4232000653","pt":1631550605602,"mc":[{"id":"1.187560634","rc":[{"batb":[[0,4.1,36.6],[1,4,18.3],[2,3.95,18.3]],"batl":[[0,4.4,6.46],[1,4.5,52.94],[2,7,2]],"ltp":4.0,"tv":4489.88,"id":9629296},{"batl":[[0,1.31,12.27],[1,1.33,380.61],[2,1.34,209.49]],"ltp":1.33,"tv":8719.04,"id":12343905}]}]}
{"op":"mcm","clk":"4232000719","pt":1631550606582,"mc":[{"id":"1.187560634","rc":[{"batb":[[0,4.1,21.96],[1,4,10.98],[2,3.95,10.98]],"ltp":4.0,"tv":4489.88,"id":9629296},{"batb":[[2,1.28,117.2]],"ltp":1.33,"tv":8719.04,"id":12343905}]}]}
{"op":"mcm","clk":"4232000731","pt":1631550606792,"mc":[{"id":"1.187560634","rc":[{"batb":[[0,4.1,7.32],[1,4,3.66],[2,3.95,3.66]],"ltp":4.0,"tv":4489.88,"id":9629296},{"batb":[[2,1.28,23.44]],"ltp":1.33,"tv":8719.04,"id":12343905}]}]}
{"op":"mcm","clk":"4232001228","pt":1631550612588,"mc":[{"id":"1.187560634","rc":[{"batb":[[0,3.9,2.76],[1,3.6,22.23],[2,1.01,105.79]],"batl":[[0,4.8,2.52],[1,7,2],[2,990,0.01]],"ltp":4.0,"tv":4489.88,"id":9629296},{"batb":[[0,1.27,142.4],[1,1.22,158.45],[2,1.17,144.97]],"batl":[[0,1.34,65.25],[1,1.39,42.51],[2,1.66,2.88]],"ltp":1.33,"tv":8719.04,"id":12343905}]}]}
{"op":"mcm","clk":"4232001238","pt":1631550612691,"mc":[{"id":"1.187560634","rc":[{"batb":[[0,1.27,95.87]],"batl":[[1,1.66,2.88],[2,3,5.2]],"ltp":1.33,"tv":8719.04,"id":12343905}]}]}
{"op":"mcm","clk":"4232001469","pt":1631550615596,"mc":[{"id":"1.187560634","rc":[{"batb":[[0,4,2.68],[1,3.9,2.76],[2,3.6,22.23]],"ltp":4.0,"tv":4489.88,"id":9629296},{"batb":[[1,1.26,240.39],[2,1.25,220.4]],"batl":[[0,1.33,74.5],[1,1.34,65.25],[2,1.35,102.67]],"ltp":1.33,"tv":8719.04,"id":12343905}]}]}
{"op":"mcm","clk":"4232001496","pt":1631550616076,"mc":[{"id":"1.187560634","rc":[{"batb":[[0,3.9,2.76],[1,3.6,22.23],[2,1.01,105.79]],"ltp":4.0,"tv":4489.88,"id":9629296},{"batb":[[1,1.22,158.45],[2,1.17,144.97]],"batl":[[0,1.34,65.25],[1,1.35,102.67],[2,1.36,135.38]],"ltp":1.33,"tv":8719.04,"id":12343905}]}]}
{"op":"mcm","clk":"4232001567","pt":1631550617009,"mc":[{"id":"1.187560634","rc":[{"trd":[[1.27,220.77]],"batb":[[0,1.27,90.13]],"ltp":1.27,"tv":8730.52,"id":12343905}],"tv":13220.4}]}
{"op":"mcm","clk":"4232001790","pt":1631550619492,"mc":[{"id":"1.187560634","rc":[{"batb":[[0,3.9,49.07]],"batl":[[0,4.2,7.22],[1,4.3,67.54],[2,4.6,2.81]],"ltp":4.0,"tv":4489.88,"id":9629296},{"batb":[[0,1.32,411.04],[1,1.31,364.79],[2,1.3,100.76]],"batl":[[0,1.33,11.84],[1,1.34,65.25],[2,1.35,102.67]],"ltp":1.27,"tv":8730.52,"id":12343905}]}]}
{"op":"mcm","clk":"4232001863","pt":1631550620188,"mc":[{"id":"1.187560634","rc":[{"batb":[[2,3.15,31.54]],"ltp":4.0,"tv":4489.88,"id":9629296}]}]}
{"op":"mcm","clk":"4232002305","pt":1631550626320,"mc":[{"id":"1.187560634","rc":[{"batb":[[2,3.4,3.41]],"ltp":4.0,"tv":4489.88,"id":9629296}]}]}
{"op":"mcm","clk":"4232002671","pt":1631550631008,"mc":[{"id":"1.187560634","rc":[{"batb":[[0,1.32,176.03]],"ltp":1.27,"tv":8730.52,"id":12343905}]}]}
{"op":"mcm","clk":"4232002765","pt":1631550632005,"mc":[{"id":"1.187560634","rc":[{"trd":[[1.32,80.25]],"batb":[[0,1.32,170.06]],"ltp":1.32,"tv":8742.45,"id":12343905}],"tv":13232.34}]}
{"op":"mcm","clk":"4232003165","pt":1631550637019,"mc":[{"id":"1.187560634","rc":[{"trd":[[1.32,80.45]],"batb":[[0,1.32,169.96]],"ltp":1.32,"tv":8742.65,"id":12343905}],"tv":13232.54}]}
{"op":"mcm","clk":"4232003348","pt":1631550639338,"mc":[{"id":"1.187560634","rc":[{"batb":[[0,1.32,136.2]],"ltp":1.32,"tv":8742.65,"id":12343905}]}]}
{"op":"mcm","clk":"4232003528","pt":1631550641630,"mc":[{"id":"1.187560634","rc":[{"batb":[[1,1.31,260.97],[2,1.29,45.81]],"ltp":1.32,"tv":8742.65,"id":12343905}]}]}
{"op":"mcm","clk":"4232003613","pt":1631550642586,"mc":[{"id":"1.187560634","rc":[{"batb":[[0,3.25,3.37],[1,3.15,31.54],[2,1.01,105.79]],"batl":[[0,4.8,2.52],[1,4.9,2.65],[2,7,2]],"ltp":4.0,"tv":4489.88,"id":9629296},{"batb":[[0,1.27,90.13],[1,1.26,92.48],[2,1.24,144.36]],"batl":[[0,1.44,59.58],[1,1.66,2.88],[2,3,5.2]],"ltp":1.32,"tv":8742.65,"id":12343905}]}]}
{"op":"mcm","clk":"4232003633","pt":1631550642787,"mc":[{"id":"1.187560634","rc":[{"batl":[[0,4.9,2.65],[1,7,2],[2,990,0.01]],"ltp":4.0,"tv":4489.88,"id":9629296},{"batb":[[0,1.26,92.48],[1,1.24,144.36],[2,1.17,144.97]],"ltp":1.32,"tv":8742.65,"id":12343905}]}]}
{"op":"mcm","clk":"4232003870","pt":1631550645676,"mc":[{"id":"1.187560634","rc":[{"batb":[[0,1.28,130.63],[1,1.27,199.26],[2,1.26,92.48]],"ltp":1.32,"tv":8742.65,"id":12343905}]}]}
{"op":"mcm","clk":"4232004034","pt":1631550647558,"mc":[{"id":"1.187560634","rc":[{"batb":[[0,4.3,20.93],[1,4.2,10.46],[2,4.1,39.73]],"batl":[[0,4.7,8.91],[1,4.8,55.35],[2,4.9,2.65]],"ltp":4.0,"tv":4489.88,"id":9629296},{"batl":[[0,1.29,13.99],[1,1.31,427.87],[2,1.32,155.4]],"ltp":1.32,"tv":8742.65,"id":12343905}]}]}
{"op":"mcm","clk":"4232004112","pt":1631550648503,"mc":[{"id":"1.187560634","rc":[{"batl":[[1,4.8,61.59],[2,4.9,5.77]],"ltp":4.0,"tv":4489.88,"id":9629296}]}]}
{"op":"mcm","clk":"4232004731","pt":1631550656671,"mc":[{"id":"1.187560634","rc":[{"batb":[[0,4,34.89],[1,3.75,2.83],[2,3.5,24.33]],"batl":[[0,5.4,2.34],[1,7,2],[2,990,0.01]],"ltp":4.0,"tv":4489.88,"id":9629296},{"batb":[[0,1.24,144.36],[1,1.23,116.63],[2,1.21,165.66]],"batl":[[0,1.36,70.57],[1,1.44,59.58],[2,1.66,2.88]],"ltp":1.32,"tv":8742.65,"id":12343905}]}]}
{"op":"mcm","clk":"4232004760","pt":1631550657097,"mc":[{"id":"1.187560634","rc":[{"batb":[[0,3.75,2.83],[1,3.5,24.33],[2,1.01,105.79]],"ltp":4.0,"tv":4489.88,"id":9629296},{"batb":[[0,1.23,116.63],[1,1.21,165.66],[2,1.17,144.97]],"batl":[[1,1.66,2.88],[2,3,5.2]],"ltp":1.32,"tv":8742.65,"id":12343905}]}]}
{"op":"mcm","clk":"4232004809","pt":1631550657679,"mc":[{"id":"1.187560634","rc":[{"batb":[[0,1.29,10.05],[1,1.23,116.63],[2,1.21,165.66]],"ltp":1.32,"tv":8742.65,"id":12343905}]}]}
{"op":"mcm","clk":"4232005113","pt":1631550661507,"mc":[{"id":"1.187560634","rc":[{"batl":[[0,4.7,130.48],[1,5.4,2.34],[2,7,2]],"ltp":4.0,"tv":4489.88,"id":9629296}]}]}
{"op":"mcm","clk":"4232005200","pt":1631550662497,"mc":[{"id":"1.187560634","rc":[{"batl":[[0,4.6,19.26]],"ltp":4.0,"tv":4489.88,"id":9629296},{"batb":[[0,1.29,160.13],[1,1.28,211.89],[2,1.23,116.63]],"batl":[[0,1.3,20.55],[1,1.32,178.64],[2,1.33,150.24]],"ltp":1.32,"tv":8742.65,"id":12343905}]}]}
{"op":"mcm","clk":"4232005264","pt":1631550663284,"mc":[{"id":"1.187560634","rc":[{"batb":[[0,3.9,2.86],[1,3.75,2.83],[2,3.5,24.33]],"batl":[[0,5,2.58]],"ltp":4.0,"tv":4489.88,"id":9629296},{"batb":[[1,1.28,190.98],[2,1.25,90.09]],"batl":[[0,1.32,178.64],[1,1.33,150.24],[2,1.34,74.75]],"ltp":1.32,"tv":8742.65,"id":12343905}]}]}
{"op":"mcm","clk":"4232005610","pt":1631550667326,"mc":[{"id":"1.187560634","rc":[{"batb":[[0,3.75,2.83],[1,3.5,24.33],[2,1.01,105.79]],"batl":[[0,5.4,2.34],[1,7,2],[2,990,0.01]],"ltp":4.0,"tv":4489.88,"id":9629296},{"batb":[[0,1.29,10.05],[1,1.23,116.63],[2,1.21,165.66]],"batl":[[0,1.36,70.57],[1,1.66,2.88],[2,3,5.2]],"ltp":1.32,"tv":8742.65,"id":12343905}]}]}
{"op":"mcm","clk":"4232005911","pt":1631550670598,"mc":[{"id":"1.187560634","rc":[{"batb":[[0,3.9,3.06],[1,3.75,2.83],[2,3.5,24.33]],"batl":[[0,5,2.72],[1,5.4,2.34],[2,7,2]],"ltp":4.0,"tv":4489.88,"id":9629296},{"trd":[[1.29,467.16]],"batb":[[0,1.29,5.75],[1,1.25,234.94],[2,1.24,229.9]],"batl":[[0,1.34,77.25],[1,1.36,70.57],[2,1.37,155.15]],"ltp":1.29,"tv":8751.25,"id":12343905}],"tv":13241.13}]}
{"op":"mcm","clk":"4232005940","pt":1631550670909,"mc":[{"id":"1.187560634","rc":[{"batb":[[0,3.75,2.83],[1,3.5,24.33],[2,1.01,105.79]],"batl":[[0,5.4,2.34],[1,7,2],[2,990,0.01]],"ltp":4.0,"tv":4489.88,"id":9629296},{"batb":[[1,1.25,136.05]],"batl":[[0,1.36,70.57],[1,1.37,155.15],[2,1.38,126.37]],"ltp":1.29,"tv":8751.25,"id":12343905}]}]}
{"op":"mcm","clk":"4232006940","pt":1631550682269,"mc":[{"id":"1.187560634","rc":[{"batb":[[1,1.23,116.63],[2,1.21,165.66]],"ltp":1.29,"tv":8751.25,"id":12343905}]}]}
{"op":"mcm","clk":"4232007133","pt":1631550684637,"mc":[{"id":"1.187560634","rc":[{"batb":[[0,3.9,2.96],[1,3.75,2.83],[2,3.5,24.33]],"batl":[[0,5,2.63],[1,5.4,2.34],[2,7,2]],"ltp":4.0,"tv":4489.88,"id":9629296},{"batb":[[1,1.25,99.33],[2,1.23,116.63]],"batl":[[0,1.34,71.25],[1,1.36,70.57],[2,1.37,155.15]],"ltp":1.29,"tv":8751.25,"id":12343905}]}]}
{"op":"mcm","clk":"4232007216","pt":1631550685415,"mc":[{"id":"1.187560634","rc":[{"batb":[[0,3.9,4.57],[2,3.55,38.3]],"batl":[[0,4.2,71.83]],"ltp":4.0,"tv":4489.88,"id":9629296},{"batb":[[0,1.34,91.82],[1,1.33,458.19],[2,1.32,190.4]],"batl":[[0,1.36,70.57],[1,1.37,363.29],[2,1.38,126.37]],"ltp":1.29,"tv":8751.25,"id":12343905}]}]}
{"op":"mcm","clk":"4232007842","pt":1631550692046,"mc":[{"id":"1.187560634","rc":[{"batl":[[1,4.6,2.76],[2,4.9,2.35]],"ltp":4.0,"tv":4489.88,"id":9629296}]}]}
{"op":"mcm","clk":"4232007985","pt":1631550693633,"mc":[{"id":"1.187560634","rc":[{"trd":[[1.34,212.44]],"batb":[[0,1.34,52.6]],"ltp":1.34,"tv":8829.69,"id":12343905}],"tv":13319.57}]}
{"op":"mcm","clk":"4232008030","pt":1631550694156,"mc":[{"id":"1.187560634","rc":[{"batb":[[0,1.33,458.19],[1,1.32,190.4],[2,1.31,99.26]],"ltp":1.34,"tv":8829.69,"id":12343905}]}]}
{"op":"mcm","clk":"4232008314","pt":1631550697152,"mc":[{"id":"1.187560634","rc":[{"trd":[[3.9,22.28]],"batb":[[0,3.75,2.83],[1,3.55,38.3],[2,3.5,61.51]],"batl":[[0,3.9,17.81],[1,4.2,71.83],[2,4.6,2.76]],"ltp":3.9,"tv":4499.02,"id":9629296},{"batb":[[0,1.33,342.25],[1,1.32,353.76]],"batl":[[1,1.37,384.51]],"ltp":1.34,"tv":8829.69,"id":12343905}],"tv":13328.71}]}
{"op":"mcm","clk":"4232008481","pt":1631550699042,"mc":[{"id":"1.187560634","rc":[{"batl":[[0,4.2,71.83],[1,4.6,2.76],[2,4.9,2.35]],"ltp":3.9,"tv":4499.02,"id":9629296}]}]}
{"op":"mcm","clk":"4232008751","pt":1631550702256,"mc":[{"id":"1.187560634","rc":[{"batb":[[0,1.35,28.88],[1,1.33,342.25],[2,1.32,353.76]],"ltp":1.34,"tv":8829.69,"id":12343905}]}]}
{"op":"mcm","clk":"4232009066","pt":1631550706504,"mc":[{"id":"1.187560634","rc":[{"batb":[[0,3.5,24.33],[1,2.96,37.41],[2,1.01,105.79]],"batl":[[0,4.6,2.76],[1,4.9,2.35],[2,5,2.35]],"ltp":3.9,"tv":4499.02,"id":9629296},{"batb":[[1,1.3,112.99],[2,1.29,5.75]],"batl":[[0,1.66,2.88],[1,3,5.2],[2,8.8,7.22]],"ltp":1.34,"tv":8829.69,"id":12343905}]}]}
{"op":"mcm","clk":"4232009119","pt":1631550707231,"mc":[{"id":"1.187560634","rc":[{"batb":[[0,2.96,37.41],[1,1.01,105.79],[2,1.01,0]],"batl":[[0,5,2.35],[1,5.4,2.34],[2,7,2]],"ltp":3.9,"tv":4499.02,"id":9629296},{"batb":[[0,1.29,5.75],[1,1.25,253.55],[2,1.23,116.63]],"ltp":1.34,"tv":8829.69,"id":12343905}]}]}
{"op":"mcm","clk":"4232009279","pt":1631550709339,"mc":[{"id":"1.187560634","rc":[{"batb":[[1,1.28,237.31],[2,1.27,201.88]],"batl":[[0,1.47,87.7],[1,1.48,94.41],[2,1.66,2.88]],"ltp":1.34,"tv":8829.69,"id":12343905}]}]}
{"op":"mcm","clk":"4232009369","pt":1631550710340,"mc":[{"id":"1.187560634","rc":[{"batl":[[0,4.6,2.61],[1,5,2.35],[2,5.4,2.34]],"ltp":3.9,"tv":4499.02,"id":9629296},{"batb":[[0,1.36,28.88],[1,1.29,5.75],[2,1.28,324.47]],"ltp":1.34,"tv":8829.69,"id":12343905}]}]}
{"op":"mcm","clk":"4232009463","pt":1631550711604,"mc":[{"id":"1.187560634","rc":[{"batl":[[0,3.75,17.33],[1,4.6,2.61],[2,5,2.35]],"ltp":3.9,"tv":4499.02,"id":9629296}]}]}
{"op":"mcm","clk":"4232009494","pt":1631550711917,"mc":[{"id":"1.187560634","rc":[{"trd":[[3.75,27.08]],"batl":[[0,4.6,2.61],[1,5,2.35],[2,5.4,2.34]],"ltp":3.75,"tv":4516.35,"id":9629296},{"trd":[[1.36,178.67]],"batb":[[0,1.29,5.75],[1,1.28,324.47],[2,1.27,201.88]],"batl":[[0,1.35,43.29],[1,1.47,87.7],[2,1.48,94.41]],"ltp":1.36,"tv":8935.28,"id":12343905}],"tv":13451.63}]}
{"op":"mcm","clk":"4232009639","pt":1631550713640,"mc":[{"id":"1.187560634","rc":[{"batl":[[1,1.66,2.88],[2,3,5.2]],"ltp":1.36,"tv":8935.28,"id":12343905}]}]}
{"op":"mcm","clk":"4232009867","pt":1631550716616,"mc":[{"id":"1.187560634","rc":[{"batb":[[0,4.1,36.6],[1,4,68.3],[2,3.95,18.3]],"batl":[[0,4.5,5.31],[1,4.6,2.61],[2,4.8,68.17]],"ltp":3.75,"tv":4516.35,"id":9629296},{"batl":[[0,1.3,13.02],[1,1.31,118.21],[2,1.32,157.43]],"ltp":1.36,"tv":8935.28,"id":12343905}]}]}
{"op":"mcm","clk":"4232009967","pt":1631550717611,"mc":[{"id":"1.187560634","rc":[{"batb":[[0,4.1,21.96],[1,4,40.98],[2,3.95,10.98]],"ltp":3.75,"tv":4516.35,"id":9629296},{"batb":[[1,1.28,441.67],[2,1.27,260.48]],"ltp":1.36,"tv":8935.28,"id":12343905}]}]}
{"op":"mcm","clk":"4232009977","pt":1631550717715,"mc":[{"id":"1.187560634","rc":[{"batb":[[0,4.1,7.32],[1,4,33.66],[2,3.95,3.66]],"ltp":3.75,"tv":4516.35,"id":9629296},{"batb":[[1,1.28,347.91],[2,1.27,213.6]],"ltp":1.36,"tv":8935.28,"id":12343905}]}]}
{"op":"mcm","clk":"4232010742","pt":1631550726428,"mc":[{"id":"1.187560634","rc":[{"trd":[[1.28,257.21],[1.29,478.67]],"batb":[[0,1.28,340.39],[1,1.27,213.6],[2,1.26,98.7]],"ltp":1.28,"tv":8961.82,"id":12343905}],"tv":13478.17}]}
{"op":"mcm","clk":"4232011422","pt":1631550734971,"mc":[{"id":"1.187560634","rc":[{"trd":[[1.28,264.63]],"batb":[[0,1.28,336.68]],"ltp":1.28,"tv":8969.24,"id":12343905}],"tv":13485.59}]}
{"op":"mcm","clk":"4232011657","pt":1631550737674,"mc":[{"id":"1.187560634","rc":[{"batb":[[0,4.1,3.66],[1,4,6.83],[2,3.95,1.83]],"ltp":3.75,"tv":4516.35,"id":9629296},{"batb":[[0,1.28,324.96],[1,1.27,207.74],[2,1.26,92.84]],"ltp":1.28,"tv":8969.24,"id":12343905}]}]}
{"op":"mcm","clk":"4232011730","pt":1631550738472,"mc":[{"id":"1.187560634","rc":[{"batb":[[0,3.7,3.22],[1,3.35,27.01],[2,1.01,105.79]],"batl":[[0,5.2,2.38],[1,7,2],[2,990,0.01]],"ltp":3.75,"tv":4516.35,"id":9629296},{"batb":[[0,1.24,100.77],[1,1.22,162.39],[2,1.17,144.97]],"batl":[[0,1.37,76.58],[1,1.66,2.88],[2,3,5.2]],"ltp":1.28,"tv":8969.24,"id":12343905}]}]}
{"op":"mcm","clk":"4232012012","pt":1631550741467,"mc":[{"id":"1.187560634","rc":[{"batb":[[0,3.85,3.17],[1,3.7,3.22],[2,3.35,27.01]],"batl":[[0,4.9,2.85],[1,5.2,2.38],[2,7,2]],"ltp":3.75,"tv":4516.35,"id":9629296},{"batb":[[0,1.26,103.98],[1,1.24,100.77],[2,1.22,162.39]],"batl":[[0,1.35,71.38],[1,1.37,76.5],[2,1.66,2.88]],"ltp":1.28,"tv":8969.24,"id":12343905}]}]}
{"op":"mcm","clk":"4232012025","pt":1631550741767,"mc":[{"id":"1.187560634","rc":[{"batb":[[0,3.7,3.22],[1,3.35,27.01],[2,1.01,105.79]],"batl":[[0,5.2,2.38],[1,7,2],[2,990,0.01]],"ltp":3.75,"tv":4516.35,"id":9629296},{"batb":[[0,1.24,100.77],[1,1.22,162.39],[2,1.17,144.97]],"batl":[[0,1.37,76.58],[1,1.66,2.88],[2,3,5.2]],"ltp":1.28,"tv":8969.24,"id":12343905}]}]}
{"op":"mcm","clk":"4232012221","pt":1631550743541,"mc":[{"id":"1.187560634","rc":[{"batl":[[0,4.6,132.44],[1,5.2,2.38],[2,7,2]],"ltp":3.75,"tv":4516.35,"id":9629296}]}]}
{"op":"mcm","clk":"4232012300","pt":1631550744583,"mc":[{"id":"1.187560634","rc":[{"batl":[[0,5.2,2.38],[1,7,2],[2,990,0.01]],"ltp":3.75,"tv":4516.35,"id":9629296},{"trd":[[1.28,264.79]],"batb":[[0,1.3,99.75],[1,1.29,182.5],[2,1.24,100.77]],"batl":[[0,1.33,208.93],[1,1.34,144.77],[2,1.37,76.5]],"ltp":1.28,"tv":8969.4,"id":12343905}],"tv":13485.75}]}
{"op":"mcm","clk":"4232012338","pt":1631550744966,"mc":[{"id":"1.187560634","rc":[{"batb":[[0,3.85,2.97],[1,3.7,3.22],[2,3.35,27.01]],"batl":[[0,4.9,2.85],[1,5.2,2.38],[2,7,2]],"ltp":3.75,"tv":4516.35,"id":9629296},{"batb":[[2,1.26,92.98]],"batl":[[2,1.35,71.3]],"ltp":1.28,"tv":8969.4,"id":12343905}]}]}
{"op":"mcm","clk":"4232012712","pt":1631550748158,"mc":[{"id":"1.187560634","rc":[{"batb":[[0,3.7,3.22],[1,3.35,27.01],[2,1.01,105.79]],"batl":[[0,5.2,2.38],[1,7,2],[2,990,0.01]],"ltp":3.75,"tv":4516.35,"id":9629296},{"batb":[[0,1.24,100.77],[1,1.22,162.39],[2,1.17,144.97]],"batl":[[0,1.37,76.5],[1,1.66,2.88],[2,3,5.2]],"ltp":1.28,"tv":8969.4,"id":12343905}]}]}
{"op":"mcm","clk":"4232012956","pt":1631550751544,"mc":[{"id":"1.187560634","rc":[{"batb":[[0,1.25,122.47],[1,1.24,331],[2,1.22,162.39]],"batl":[[1,1.39,182.43],[2,1.4,118.45]],"ltp":1.28,"tv":8969.4,"id":12343905}]}]}
{"op":"mcm","clk":"4232013751","pt":1631550761598,"mc":[{"id":"1.187560634","rc":[{"batb":[[0,3.85,3.37],[1,3.7,3.22],[2,3.35,27.01]],"batl":[[0,4.9,2.65],[1,5.2,2.38],[2,7,2]],"ltp":3.75,"tv":4516.35,"id":9629296},{"batb":[[0,1.26,90.48],[1,1.25,122.47],[2,1.24,331]],"batl":[[0,1.35,72.7],[1,1.37,76.5],[2,1.66,2.88]],"ltp":1.28,"tv":8969.4,"id":12343905}]}]}
{"op":"mcm","clk":"4232013773","pt":1631550761862,"mc":[{"id":"1.187560634","rc":[{"batb":[[0,3.7,3.22],[1,3.35,27.01],[2,1.01,105.79]],"batl":[[0,5.2,2.38],[1,7,2],[2,990,0.01]],"ltp":3.75,"tv":4516.35,"id":9629296},{"batb":[[0,1.25,122.47],[1,1.24,331],[2,1.22,162.39]],"batl":[[0,1.37,76.5],[1,1.66,2.88],[2,3,5.2]],"ltp":1.28,"tv":8969.4,"id":12343905}]}]}
{"op":"mcm","clk":"4232013923","pt":1631550763598,"mc":[{"id":"1.187560634","rc":[{"batl":[[0,1.27,950.65],[1,1.37,76.5],[2,1.66,2.88]],"ltp":1.28,"tv":8969.4,"id":12343905}]}]}
{"op":"mcm","clk":"4232013984","pt":1631550764180,"mc":[{"id":"1.187560634","rc":[{"batb":[[0,4.5,30.22],[1,4.4,29.34],[2,4.3,29.34]],"batl":[[0,5,5.37],[1,5.2,2.38],[2,5.3,82.75]],"ltp":3.75,"tv":4516.35,"id":9629296},{"batb":[[2,1.22,210.82]],"batl":[[0,1.27,288.76],[1,1.28,458.55],[2,1.32,44.76]],"ltp":1.28,"tv":8969.4,"id":12343905}]}]}
{"op":"mcm","clk":"4232014637","pt":1631550771892,"mc":[{"id":"1.187560634","rc":[{"batb":[[1,4.4,31.95],[2,4.3,31.92]],"ltp":3.75,"tv":4516.35,"id":9629296},{"batb":[[2,1.23,113.63]],"batl":[[2,1.29,80.5]],"ltp":1.28,"tv":8969.4,"id":12343905}]}]}
{"op":"mcm","clk":"4232014916","pt":1631550775712,"mc":[{"id":"1.187560634","rc":[{"batl":[[0,1.27,135.33]],"ltp":1.28,"tv":8969.4,"id":12343905}]}]}
{"op":"mcm","clk":"4232015607","pt":1631550783915,"mc":[{"id":"1.187560634","rc":[{"trd":[[1.27,299.21]],"batl":[[0,1.27,96.11]],"ltp":1.27,"tv":9047.84,"id":12343905}],"tv":13564.19}]}
{"op":"mcm","clk":"4232015731","pt":1631550785588,"mc":[{"id":"1.187560634","rc":[{"batb":[[0,4.3,2.58],[1,3.85,37.91],[2,3.7,3.22]],"batl":[[0,5.4,2.49],[1,7,2],[2,990,0.01]],"ltp":3.75,"tv":4516.35,"id":9629296},{"batb":[[0,1.23,113.63],[1,1.2,180.68],[2,1.17,144.97]],"batl":[[0,1.3,88.25],[1,1.37,76.5],[2,1.66,2.88]],"ltp":1.27,"tv":9047.84,"id":12343905}]}]}
{"op":"mcm","clk":"4232015980","pt":1631550788614,"mc":[{"id":"1.187560634","rc":[{"batb":[[0,4.4,2.41],[1,4.3,2.58],[2,3.85,37.91]],"batl":[[0,5.2,2.43],[1,5.4,2.49],[2,7,2]],"ltp":3.75,"tv":4516.35,"id":9629296},{"batb":[[0,1.24,115.52],[1,1.23,269.4],[2,1.22,256.2]],"batl":[[0,1.29,89.5],[1,1.3,88.25],[2,1.31,126.17]],"ltp":1.27,"tv":9047.84,"id":12343905}]}]}
{"op":"mcm","clk":"4232016001","pt":1631550788924,"mc":[{"id":"1.187560634","rc":[{"batb":[[0,4.3,2.58],[1,3.85,37.91],[2,3.7,3.22]],"batl":[[0,5.4,2.49],[1,7,2],[2,990,0.01]],"ltp":3.75,"tv":4516.35,"id":9629296},{"batb":[[0,1.23,269.4],[1,1.22,256.2],[2,1.2,180.68]],"batl":[[0,1.3,88.25],[1,1.31,126.17],[2,1.32,157.31]],"ltp":1.27,"tv":9047.84,"id":12343905}]}]}
{"op":"mcm","clk":"4232016249","pt":1631550791639,"mc":[{"id":"1.187560634","rc":[{"batb":[[0,1.23,113.63],[1,1.2,180.68],[2,1.17,144.97]],"ltp":1.27,"tv":9047.84,"id":12343905}]}]}
{"op":"mcm","clk":"4232016491","pt":1631550794625,"mc":[{"id":"1.187560634","rc":[{"batl":[[0,4.6,8.61],[1,4.7,57.88],[2,4.8,56.18]],"ltp":3.75,"tv":4516.35,"id":9629296},{"batb":[[0,1.28,2921.45],[1,1.27,201.71],[2,1.26,272.62]],"batl":[[1,1.31,340.63]],"ltp":1.27,"tv":9047.84,"id":12343905}]}]}
{"op":"mcm","clk":"4232016576","pt":1631550795616,"mc":[{"id":"1.187560634","rc":[{"batl":[[1,4.7,28.94],[2,4.8,28.1]],"ltp":3.75,"tv":4516.35,"id":9629296},{"batb":[[0,1.28,532.02]],"ltp":1.27,"tv":9047.84,"id":12343905}]}]}
{"op":"mcm","clk":"4232016737","pt":1631550797544,"mc":[{"id":"1.187560634","rc":[{"batl":[[0,4.4,5.93],[1,4.6,8.61],[2,4.7,28.94]],"ltp":3.75,"tv":4516.35,"id":9629296},{"batl":[[1,1.31,353.52]],"ltp":1.27,"tv":9047.84,"id":12343905}]}]}
{"op":"mcm","clk":"4232016912","pt":1631550799642,"mc":[{"id":"1.187560634","rc":[{"batb":[[2,3.3,28.35]],"ltp":3.75,"tv":4516.35,"id":9629296}]}]}
{"op":"mcm","clk":"4232017508","pt":1631550806551,"mc":[{"id":"1.187560634","rc":[{"batb":[[0,3.85,37.91],[1,3.3,28.35],[2,1.01,105.79]],"batl":[[0,5.4,2.49],[1,7,2],[2,990,0.01]],"ltp":3.75,"tv":4516.35,"id":9629296},{"batb":[[0,1.25,136.14],[1,1.23,113.63],[2,1.21,164.4]],"batl":[[0,1.66,2.88],[1,3,5.2],[2,8.8,7.22]],"ltp":1.27,"tv":9047.84,"id":12343905}]}]}
{"op":"mcm","clk":"4232017525","pt":1631550806712,"mc":[{"id":"1.187560634","rc":[{"batb":[[0,3.3,28.35],[1,1.01,105.79],[2,1.01,0]],"ltp":3.75,"tv":4516.35,"id":9629296},{"batb":[[0,1.23,113.63],[1,1.21,164.4],[2,1.17,144.97]],"ltp":1.27,"tv":9047.84,"id":12343905}]}]}
{"op":"mcm","clk":"4232017748","pt":1631550809115,"mc":[{"id":"1.187560634","rc":[{"batb":[[0,1.24,221.92],[1,1.23,358.35],[2,1.21,164.4]],"batl":[[0,1.4,172.02],[1,1.41,114.84],[2,1.66,2.88]],"ltp":1.27,"tv":9047.84,"id":12343905}]}]}
{"op":"mcm","clk":"4232018360","pt":1631550815961,"mc":[{"id":"1.187560634","rc":[{"batl":[[1,990,0.01],[2,990,0]],"ltp":3.75,"tv":4516.35,"id":9629296},{"batl":[[0,1.66,2.88],[1,3,5.2],[2,8.8,7.22]],"ltp":1.27,"tv":9047.84,"id":12343905}]}]}
{"op":"mcm","clk":"4232018606","pt":1631550818629,"mc":[{"id":"1.187560634","rc":[{"batl":[[0,5,3.56],[1,5.4,2.49],[2,5.5,114.04]],"ltp":3.75,"tv":4516.35,"id":9629296},{"batb":[[0,1.25,14.24],[1,1.24,221.92],[2,1.23,358.35]],"batl":[[0,1.27,2528.9],[1,1.28,390.87],[2,1.29,207.88]],"ltp":1.27,"tv":9047.84,"id":12343905}]}]}
{"op":"mcm","clk":"4232018690","pt":1631550819669,"mc":[{"id":"1.187560634","rc":[{"batb":[[0,4.3,28.85],[1,3.9,36.74],[2,3.3,28.35]],"batl":[[2,5.5,89.3]],"ltp":3.75,"tv":4516.35,"id":9629296},{"batl":[[0,1.27,758.03],[1,1.28,286.93],[2,1.29,103.94]],"ltp":1.27,"tv":9047.84,"id":12343905}]}]}
{"op":"mcm","clk":"4232018710","pt":1631550819832,"mc":[{"id":"1.187560634","rc":[{"batb":[[2,1.01,105.79]],"ltp":3.75,"tv":4516.35,"id":9629296}]}]}
{"op":"mcm","clk":"4232018921","pt":1631550822246,"mc":[{"id":"1.187560634","rc":[{"batl":[[0,1.27,715.21]],"ltp":1.27,"tv":9047.84,"id":12343905}]}]}
{"op":"mcm","clk":"4232019183","pt":1631550825265,"mc":[{"id":"1.187560634","rc":[{"batb":[[1,1.24,265.83]],"ltp":1.27,"tv":9047.84,"id":12343905}]}]}
{"op":"mcm","clk":"4232019534","pt":1631550829643,"mc":[{"id":"1.187560634","rc":[{"trd":[[5,4.93]],"batl":[[0,5.4,2.49],[1,5.5,89.3],[2,5.6,24]],"ltp":5.0,"tv":4519.91,"id":9629296},{"trd":[[1.24,20.29],[1.25,196.41]],"batb":[[0,1.24,262.62],[1,1.23,358.35],[2,1.21,213.24]],"ltp":1.24,"tv":9096.96,"id":12343905}],"tv":13616.87}]}
{"op":"mcm","clk":"4232019608","pt":1631550830580,"mc":[{"id":"1.187560634","rc":[{"batl":[[0,1.27,568.91]],"ltp":1.24,"tv":9096.96,"id":12343905}]}]}
{"op":"mcm","clk":"4232019786","pt":1631550832769,"mc":[{"id":"1.187560634","rc":[{"trd":[[1.27,300.21]],"batl":[[0,1.27,568.41]],"ltp":1.27,"tv":9097.96,"id":12343905}],"tv":13617.87}]}
{"op":"mcm","clk":"4232020024","pt":1631550835686,"mc":[{"id":"1.187560634","rc":[{"batb":[[0,1.25,4.77],[1,1.24,262.62],[2,1.23,358.35]],"ltp":1.27,"tv":9097.96,"id":12343905}]}]}
{"op":"mcm","clk":"4232020385","pt":1631550839753,"mc":[{"id":"1.187560634","rc":[{"batl":[[0,1.27,546.91]],"ltp":1.27,"tv":9097.96,"id":12343905}]}]}
{"op":"mcm","clk":"4232020492","pt":1631550841182,"mc":[{"id":"1.187560634","rc":[{"trd":[[1.24,155.17],[1.25,205.96]],"batb":[[0,1.24,195.16],[1,1.23,358.35],[2,1.21,213.24]],"ltp":1.24,"tv":9242.39,"id":12343905}],"tv":13762.3}]}
{"op":"mcm","clk":"4232020652","pt":1631550842764,"mc":[{"id":"1.187560634","rc":[{"batl":[[0,5.1,4.08],[1,5.4,2.49],[2,5.5,89.3]],"ltp":5.0,"tv":4519.91,"id":9629296},{"batl":[[0,1.26,25.72],[1,1.27,546.91],[2,1.28,286.93]],"ltp":1.24,"tv":9242.39,"id":12343905}]}]}
{"op":"mcm","clk":"4232020763","pt":1631550844172,"mc":[{"id":"1.187560634","rc":[{"batb":[[0,1.24,226.78]],"batl":[[1,1.27,585.09]],"ltp":1.24,"tv":9242.39,"id":12343905}]}]}
{"op":"mcm","clk":"4232020870","pt":1631550845477,"mc":[{"id":"1.187560634","rc":[{"trd":[[4.8,65.07]],"ltp":4.8,"tv":4521.61,"id":9629296},{"trd":[[1.26,743.71]],"batl":[[0,1.26,19.22]],"ltp":1.26,"tv":9248.89,"id":12343905}],"tv":13770.51}]}
{"op":"mcm","clk":"4232021689","pt":1631550855590,"mc":[{"id":"1.187560634","rc":[{"trd":[[5.1,5.08]],"batl":[[0,5.4,2.49],[1,5.5,89.3],[2,5.6,24]],"ltp":5.1,"tv":4526.69,"id":9629296},{"trd":[[1.24,629.47]],"batb":[[0,1.23,358.35],[1,1.21,213.24],[2,1.16,226.64]],"batl":[[0,1.24,474.45],[1,1.27,559.71],[2,1.28,103.94]],"ltp":1.24,"tv":9723.19,"id":12343905}],"tv":14249.88}]}
{"op":"mcm","clk":"4232021700","pt":1631550855699,"mc":[{"id":"1.187560634","rc":[{"batl":[[0,1.24,474.53]],"ltp":1.24,"tv":9723.19,"id":12343905}]}]}
{"op":"mcm","clk":"4232021964","pt":1631550858588,"mc":[{"id":"1.187560634","rc":[{"trd":[[1.24,867.68]],"batl":[[0,1.24,355.46],[1,1.26,184.74],[2,1.27,559.71]],"ltp":1.24,"tv":9961.4,"id":12343905}],"tv":14488.09}]}
{"op":"mcm","clk":"4232022231","pt":1631550861512,"mc":[{"id":"1.187560634","rc":[{"batb":[[0,1.23,404.19],[1,1.22,264.85],[2,1.21,213.24]],"batl":[[1,1.26,239.94]],"ltp":1.24,"tv":9961.4,"id":12343905}]}]}
{"op":"mcm","clk":"4232022401","pt":1631550863547,"mc":[{"id":"1.187560634","rc":[{"batl":[[0,1.26,240.02],[1,1.27,559.71],[2,1.28,103.94]],"ltp":1.24,"tv":9961.4,"id":12343905}]}]}
{"op":"mcm","clk":"4232022604","pt":1631550865436,"mc":[{"id":"1.187560634","rc":[{"trd":[[5.1,8.87]],"ltp":5.1,"tv":4530.48,"id":9629296},{"trd":[[1.23,438.27],[1.24,883.29]],"batb":[[0,1.23,189.4]],"batl":[[0,1.26,204.21]],"ltp":1.23,"tv":10406.49,"id":12343905}],"tv":14936.97}]}
{"op":"mcm","clk":"4232022706","pt":1631550866636,"mc":[{"id":"1.187560634","rc":[{"trd":[[1.23,816.97]],"batb":[[0,1.22,264.85],[1,1.21,213.24],[2,1.16,226.64]],"batl":[[0,1.23,166.09],[1,1.26,204.21],[2,1.27,559.71]],"ltp":1.23,"tv":10785.18,"id":12343905}],"tv":15315.67}]}
{"op":"mcm","clk":"4232022753","pt":1631550867211,"mc":[{"id":"1.187560634","rc":[{"batl":[[2,1.27,364.11]],"ltp":1.23,"tv":10785.18,"id":12343905}]}]}
{"op":"mcm","clk":"4232022810","pt":1631550867938,"mc":[{"id":"1.187560634","rc":[{"trd":[[5.3,15.14]],"batb":[[0,5,3.45],[1,4.3,28.85],[2,3.9,36.74]],"ltp":5.3,"tv":4535.62,"id":9629296},{"trd":[[1.23,839.1]],"batl":[[0,1.23,143.95],[1,1.25,13.81],[2,1.26,204.21]],"ltp":1.23,"tv":10807.31,"id":12343905}],"tv":15342.94}]}
{"op":"mcm","clk":"4232022920","pt":1631550869144,"mc":[{"id":"1.187560634","rc":[{"batb":[[0,4.3,28.85],[1,3.9,36.74],[2,1.01,105.79]],"ltp":5.3,"tv":4535.62,"id":9629296},{"trd":[[1.23,929.59]],"batl":[[0,1.23,98.72],[1,1.26,209.62],[2,1.27,364.11]],"ltp":1.23,"tv":10897.81,"id":12343905}],"tv":15433.43}]}
{"op":"mcm","clk":"4232023035","pt":1631550870356,"mc":[{"id":"1.187560634","rc":[{"trd":[[1.23,1127.1]],"batl":[[0,1.25,152.6]],"ltp":1.23,"tv":11095.31,"id":12343905}],"tv":15630.94}]}
{"op":"mcm","clk":"4232023202","pt":1631550872242,"mc":[{"id":"1.187560634","rc":[{"batl":[[1,5.5,96.62]],"ltp":5.3,"tv":4535.62,"id":9629296},{"batl":[[0,1.24,21.96],[1,1.25,177.21],[2,1.26,209.62]],"ltp":1.23,"tv":11095.31,"id":12343905}]}]}
{"op":"mcm","clk":"4232023288","pt":1631550873333,"mc":[{"id":"1.187560634","rc":[{"batb":[[0,1.22,326.5],[1,1.21,447.57]],"batl":[[1,1.25,220.41]],"ltp":1.23,"tv":11095.31,"id":12343905}]}]}
{"op":"mcm","clk":"4232023681","pt":1631550878144,"mc":[{"id":"1.187560634","rc":[{"batb":[[0,4.4,9.41],[1,4.3,28.85],[2,3.9,36.74]],"batl":[[1,5.5,89.3]],"ltp":5.3,"tv":4535.62,"id":9629296},{"batl":[[0,1.25,220.41],[1,1.26,209.62],[2,1.27,364.11]],"ltp":1.23,"tv":11095.31,"id":12343905}]}]}
{"op":"mcm","clk":"4232023828","pt":1631550880080,"mc":[{"id":"1.187560634","rc":[{"trd":[[5,6.64]],"ltp":5.0,"tv":4537.33,"id":9629296},{"trd":[[1.25,212.78]],"batl":[[0,1.25,213.59]],"ltp":1.25,"tv":11102.13,"id":12343905}],"tv":15639.46}]}
{"op":"mcm","clk":"4232023915","pt":1631550881131,"mc":[{"id":"1.187560634","rc":[{"batl":[[1,5.5,96.62]],"ltp":5.0,"tv":4537.33,"id":9629296},{"batl":[[0,1.24,21.96],[1,1.25,213.59],[2,1.26,209.62]],"ltp":1.25,"tv":11102.13,"id":12343905}]}]}
{"op":"mcm","clk":"4232024337","pt":1631550887131,"mc":[{"id":"1.187560634","rc":[{"trd":[[1.24,885.09]],"batl":[[0,1.24,21.06]],"ltp":1.24,"tv":11103.93,"id":12343905}],"tv":15641.26}]}
{"op":"mcm","clk":"4232025138","pt":1631550897264,"mc":[{"id":"1.187560634","rc":[{"batl":[[1,5.5,89.3]],"ltp":5.0,"tv":4537.33,"id":9629296},{"trd":[[1.24,927.2]],"batb":[[0,1.24,14],[1,1.22,326.5],[2,1.21,447.57]],"batl":[[0,1.25,213.59],[1,1.26,209.62],[2,1.27,364.11]],"ltp":1.24,"tv":11146.04,"id":12343905}],"tv":15683.37}]}
{"op":"mcm","clk":"4232025381","pt":1631550900469,"mc":[{"id":"1.187560634","rc":[{"batb":[[0,5,3.45]],"batl":[[0,5.3,5.14],[1,5.4,2.49],[2,5.5,89.3]],"ltp":5.0,"tv":4537.33,"id":9629296},{"trd":[[1.24,955.2]],"batb":[[0,1.22,326.5],[1,1.21,447.57],[2,1.16,226.64]],"batl":[[0,1.25,227.4]],"ltp":1.24,"tv":11174.04,"id":12343905}],"tv":15711.37}]}
{"op":"mcm","clk":"4232025857","pt":1631550905884,"mc":[{"id":"1.187560634","rc":[{"batb":[[1,1.21,398.73]],"ltp":1.24,"tv":11174.04,"id":12343905}]}]}
{"op":"mcm","clk":"4232025937","pt":1631550906879,"mc":[{"id":"1.187560634","rc":[{"batb":[[0,4.3,28.85],[1,3.9,36.74],[2,1.01,105.79]],"batl":[[0,5.4,2.49],[1,5.5,89.3],[2,5.6,24]],"ltp":5.0,"tv":4537.33,"id":9629296},{"batl":[[0,1.25,213.59]],"ltp":1.24,"tv":11174.04,"id":12343905}]}]}
{"op":"mcm","clk":"4232026091","pt":1631550909074,"mc":[{"id":"1.187560634","rc":[{"batb":[[0,4.4,2.76],[1,4.3,28.85],[2,4.2,2.52]],"ltp":5.0,"tv":4537.33,"id":9629296},{"batb":[[2,1.18,119.86]],"batl":[[0,1.25,213.98]],"ltp":1.24,"tv":11174.04,"id":12343905}]}]}
{"op":"mcm","clk":"4232026207","pt":1631550910496,"mc":[{"id":"1.187560634","rc":[{"trd":[[5.3,15.23]],"ltp":5.3,"tv":4537.42,"id":9629296},{"trd":[[1.23,1127.48]],"batl":[[0,1.25,213.59]],"ltp":1.23,"tv":11174.43,"id":12343905}],"tv":15711.85}]}
{"op":"mcm","clk":"4232026373","pt":1631550912586,"mc":[{"id":"1.187560634","rc":[{"batb":[[0,4.2,2.52],[1,3.9,36.74],[2,1.01,105.79]],"batl":[[0,7.8,2],[1,990,0.01],[2,5.6,0]],"ltp":5.3,"tv":4537.42,"id":9629296},{"batb":[[0,1.16,226.64],[1,1.15,162.03],[2,1.1,2]],"batl":[[0,1.31,80.5],[1,1.66,2.88],[2,3,5.2]],"ltp":1.23,"tv":11174.43,"id":12343905}]}]}
{"op":"mcm","clk":"4232026635","pt":1631550915299,"mc":[{"id":"1.187560634","rc":[{"batb":[[0,4.4,2.76],[1,4.2,2.52],[2,3.9,36.74]],"ltp":5.3,"tv":4537.42,"id":9629296},{"batb":[[0,1.17,297.27],[1,1.16,514.63],[2,1.15,162.03]],"batl":[[0,1.29,292.34],[1,1.3,176.3],[2,1.31,80.5]],"ltp":1.23,"tv":11174.43,"id":12343905}]}]}
{"op":"mcm","clk":"4232026731","pt":1631550916322,"mc":[{"id":"1.187560634","rc":[{"batl":[[0,7,2],[1,7.8,2],[2,990,0.01]],"ltp":5.3,"tv":4537.42,"id":9629296},{"batb":[[0,1.17,442.24]],"ltp":1.23,"tv":11174.43,"id":12343905}]}]}
{"op":"mcm","clk":"4232026916","pt":1631550918414,"mc":[{"id":"1.187560634","rc":[{"batl":[[0,7.8,2],[1,990,0.01],[2,990,0]],"ltp":5.3,"tv":4537.42,"id":9629296},{"batb":[[0,1.16,226.64],[1,1.15,162.03],[2,1.1,2]],"ltp":1.23,"tv":11174.43,"id":12343905}]}]}
{"op":"mcm","clk":"4232027170","pt":1631550921489,"mc":[{"id":"1.187560634","rc":[{"batb":[[1,4.3,31.64],[2,4.2,33.22]],"batl":[[0,4.8,46.5],[1,4.9,3.25],[2,5,27.2]],"ltp":5.3,"tv":4537.42,"id":9629296},{"batb":[[0,1.26,548.19],[1,1.25,230.3],[2,1.24,47.66]],"batl":[[2,1.31,319.46]],"ltp":1.23,"tv":11174.43,"id":12343905}]}]}
{"op":"mcm","clk":"4232027253","pt":1631550922387,"mc":[{"id":"1.187560634","rc":[{"batb":[[1,1.25,369.46]],"ltp":1.23,"tv":11174.43,"id":12343905}]}]}
{"op":"mcm","clk":"4232027419","pt":1631550924303,"mc":[{"id":"1.187560634","rc":[{"batb":[[0,4.5,6.05]],"batl":[[0,4.7,4.29],[1,4.8,46.5],[2,4.9,3.25]],"ltp":5.3,"tv":4537.42,"id":9629296},{"batl":[[0,1.29,208.84]],"ltp":1.23,"tv":11174.43,"id":12343905}]}]}
{"op":"mcm","clk":"4232028031","pt":1631550931611,"mc":[{"id":"1.187560634","rc":[{"batb":[[0,4.1,2.84],[1,3.9,36.74],[2,3.6,22.23]],"batl":[[0,5.4,2.04],[1,5.8,2.02],[2,7.8,2]],"ltp":5.3,"tv":4537.42,"id":9629296},{"batb":[[0,1.25,139.16],[1,1.24,47.66],[2,1.23,108.63]],"batl":[[0,1.32,82.86],[1,1.36,43.45],[2,1.66,2.88]],"ltp":1.23,"tv":11174.43,"id":12343905}]}]}
{"op":"mcm","clk":"4232028085","pt":1631550932142,"mc":[{"id":"1.187560634","rc":[{"batb":[[1,3.6,22.23],[2,1.01,105.79]],"batl":[[0,5.8,2.02],[1,7.8,2],[2,990,0.01]],"ltp":5.3,"tv":4537.42,"id":9629296},{"batb":[[0,1.21,111.69],[1,1.2,178.66],[2,1.15,162.03]],"batl":[[1,1.66,2.88],[2,3,5.2]],"ltp":1.23,"tv":11174.43,"id":12343905}]}]}
{"op":"mcm","clk":"4232028454","pt":1631550936554,"mc":[{"id":"1.187560634","rc":[{"batb":[[0,1.25,215.73],[1,1.24,242.13],[2,1.21,111.69]],"batl":[[0,1.28,230.57],[1,1.29,183.37],[2,1.32,82.86]],"ltp":1.23,"tv":11174.43,"id":12343905}]}]}
{"op":"mcm","clk":"4232028591","pt":1631550938229,"mc":[{"id":"1.187560634","rc":[{"batb":[[0,4.2,2.62],[1,4.1,2.84],[2,3.6,22.23]],"ltp":5.3,"tv":4537.42,"id":9629296},{"batl":[[2,1.31,74.5]],"ltp":1.23,"tv":11174.43,"id":12343905}]}]}
{"op":"mcm","clk":"4232028642","pt":1631550938909,"mc":[{"id":"1.187560634","rc":[{"batl":[[0,5.4,2.04],[1,5.8,2.02],[2,7.8,2]],"ltp":5.3,"tv":4537.42,"id":9629296},{"batb":[[2,1.23,101.63]],"ltp":1.23,"tv":11174.43,"id":12343905}]}]}
{"op":"mcm","clk":"4232029130","pt":1631550944320,"mc":[{"id":"1.187560634","rc":[{"batb":[[0,4.1,2.84],[1,3.6,22.23],[2,1.01,105.79]],"batl":[[0,5.8,2.27],[1,7.8,2],[2,990,0.01]],"ltp":5.3,"tv":4537.42,"id":9629296},{"batb":[[0,1.21,111.69],[1,1.2,178.66],[2,1.15,162.03]],"batl":[[0,1.32,82.86],[1,1.66,2.88],[2,3,5.2]],"ltp":1.23,"tv":11174.43,"id":12343905}]}]}
{"op":"mcm","clk":"4232029390","pt":1631550947530,"mc":[{"id":"1.187560634","rc":[{"batb":[[0,4.2,2.52],[1,4.1,2.84],[2,3.6,22.23]],"batl":[[0,5.4,2.29],[1,5.8,2.02],[2,7.8,2]],"ltp":5.3,"tv":4537.42,"id":9629296},{"batb":[[0,1.23,109.63],[1,1.21,391.69],[2,1.2,464.56]],"batl":[[0,1.31,83.5],[1,1.32,198.67],[2,1.33,158.12]],"ltp":1.23,"tv":11174.43,"id":12343905}]}]}
{"op":"mcm","clk":"4232029400","pt":1631550947739,"mc":[{"id":"1.187560634","rc":[{"batb":[[0,4.1,2.84],[1,3.6,22.23],[2,1.01,105.79]],"batl":[[0,5.8,2.27],[1,7.8,2],[2,990,0.01]],"ltp":5.3,"tv":4537.42,"id":9629296},{"batb":[[0,1.21,391.69],[1,1.2,464.56],[2,1.15,162.03]],"batl":[[0,1.32,198.67],[1,1.33,158.12],[2,1.66,2.88]],"ltp":1.23,"tv":11174.43,"id":12343905}]}]}
{"op":"mcm","clk":"4232029744","pt":1631550951952,"mc":[{"id":"1.187560634","rc":[{"trd":[[4.5,0.25]],"batl":[[0,5.8,2.02]],"ltp":4.5,"tv":4537.67,"id":9629296},{"trd":[[1.28,265.67]],"batl":[[0,1.32,198.69]],"ltp":1.28,"tv":11175.31,"id":12343905}],"tv":15712.98}]}
{"op":"mcm","clk":"4232029870","pt":1631550953534,"mc":[{"id":"1.187560634","rc":[{"trd":[[4.1,22.83],[4.7,38.08]],"batb":[[0,3.6,22.23],[1,1.01,105.79],[2,1.01,0]],"ltp":4.1,"tv":4560.51,"id":9629296},{"trd":[[1.27,300.23],[1.32,133.72]],"batl":[[0,1.32,145.4]],"ltp":1.32,"tv":11228.6,"id":12343905}],"tv":15789.11}]}
{"op":"mcm","clk":"4232029942","pt":1631550954432,"mc":[{"id":"1.187560634","rc":[{"batb":[[0,4.2,2.42],[1,3.6,22.23],[2,1.01,105.79]],"batl":[[0,5.4,2],[1,5.8,2.02],[2,7.8,2]],"ltp":4.1,"tv":4560.51,"id":9629296},{"batb":[[0,1.23,103.63],[1,1.21,391.69],[2,1.2,464.56]],"batl":[[0,1.31,80.5],[1,1.32,145.4],[2,1.33,158.12]],"ltp":1.32,"tv":11228.6,"id":12343905}]}]}
{"op":"mcm","clk":"4232030003","pt":1631550955064,"mc":[{"id":"1.187560634","rc":[{"batb":[[0,3.6,22.23],[1,1.01,105.79],[2,1.01,0]],"batl":[[0,5.8,2.02],[1,7.8,2],[2,990,0.01]],"ltp":4.1,"tv":4560.51,"id":9629296},{"batb":[[0,1.21,391.69],[1,1.2,464.56],[2,1.15,162.03]],"batl":[[0,1.32,145.4],[1,1.33,158.12],[2,1.66,2.88]],"ltp":1.32,"tv":11228.6,"id":12343905}]}]}
{"op":"mcm","clk":"4232030153","pt":1631550956741,"mc":[{"id":"1.187560634","rc":[{"batb":[[0,4.1,2.54],[1,3.6,22.23],[2,1.01,105.79]],"ltp":4.1,"tv":4560.51,"id":9629296},{"batl":[[0,1.32,29.59],[1,1.66,2.88],[2,3,5.2]],"ltp":1.32,"tv":11228.6,"id":12343905}]}]}
{"op":"mcm","clk":"4232030377","pt":1631550959669,"mc":[{"id":"1.187560634","rc":[{"batb":[[0,5.2,26.16],[1,5.1,25.38],[2,5,25.38]],"batl":[[0,5.5,4.8],[1,5.7,56.75],[2,5.8,2.02]],"ltp":4.1,"tv":4560.51,"id":9629296},{"batl":[[0,1.24,2057.9],[1,1.25,217.79],[2,1.26,278.73]],"ltp":1.32,"tv":11228.6,"id":12343905}]}]}
{"op":"mcm","clk":"4232030480","pt":1631550960668,"mc":[{"id":"1.187560634","rc":[{"batb":[[1,1.2,513.81]],"batl":[[0,1.24,469.09]],"ltp":1.32,"tv":11228.6,"id":12343905}]}]}
{"op":"mcm","clk":"4232031175","pt":1631550969485,"mc":[{"id":"1.187560634","rc":[{"batb":[[0,4.2,2.92],[1,4,34.64],[2,1.01,105.79]],"batl":[[0,9.4,2],[1,990,0.01],[2,5.8,0]],"ltp":4.1,"tv":4560.51,"id":9629296},{"batb":[[0,1.14,263.22],[1,1.12,215.04],[2,1.1,2]],"batl":[[0,1.31,76.5],[1,1.66,2.88],[2,3,5.2]],"ltp":1.32,"tv":11228.6,"id":12343905}]}]}
{"op":"mcm","clk":"4232031511","pt":1631550973676,"mc":[{"id":"1.187560634","rc":[{"batl":[[0,1.25,523.26],[1,1.31,76.5],[2,1.66,2.88]],"ltp":1.32,"tv":11228.6,"id":12343905}]}]}
{"op":"mcm","clk":"4232031568","pt":1631550974258,"mc":[{"id":"1.187560634","rc":[{"batb":[[0,1.2,208.71],[1,1.19,319.89],[2,1.14,263.22]],"batl":[[0,1.22,157.08],[1,1.23,244.38],[2,1.31,76.5]],"ltp":1.32,"tv":11228.6,"id":12343905}]}]}
{"op":"mcm","clk":"4232031776","pt":1631550976468,"mc":[{"id":"1.187560634","rc":[{"batb":[[0,4.4,2.41],[1,4.2,2.92],[2,4,34.64]],"batl":[[0,7.8,2],[1,9.4,2],[2,990,0.01]],"ltp":4.1,"tv":4560.51,"id":9629296},{"batb":[[2,1.15,170.43]],"batl":[[2,1.29,87.5]],"ltp":1.32,"tv":11228.6,"id":12343905}]}]}
{"op":"mcm","clk":"4232032049","pt":1631550979470,"mc":[{"id":"1.187560634","rc":[{"batb":[[0,4.2,2.92],[1,4,34.64],[2,1.01,105.79]],"batl":[[0,9.4,2],[1,990,0.01],[2,990,0]],"ltp":4.1,"tv":4560.51,"id":9629296},{"batb":[[0,1.14,263.22],[1,1.12,215.04],[2,1.1,2]],"batl":[[0,1.31,76.5],[1,1.66,2.88],[2,3,5.2]],"ltp":1.32,"tv":11228.6,"id":12343905}]}]}
{"op":"mcm","clk":"4232032312","pt":1631550982494,"mc":[{"id":"1.187560634","rc":[{"batb":[[0,1.15,325.07],[1,1.14,533.43],[2,1.12,215.04]],"batl":[[0,1.28,140.59],[1,1.29,185.1],[2,1.31,76.5]],"ltp":1.32,"tv":11228.6,"id":12343905}]}]}
{"op":"mcm","clk":"4232032331","pt":1631550982697,"mc":[{"id":"1.187560634","rc":[{"batb":[[0,4.4,2.51],[1,4.2,2.92],[2,4,34.64]],"batl":[[0,7.8,2],[1,9.4,2],[2,990,0.01]],"ltp":4.1,"tv":4560.51,"id":9629296},{"batb":[[0,1.15,492.1]],"batl":[[1,1.29,281.6]],"ltp":1.32,"tv":11228.6,"id":12343905}]}]}
{"op":"mcm","clk":"4232032582","pt":1631550985573,"mc":[{"id":"1.187560634","rc":[{"batl":[[0,1.28,140.67]],"ltp":1.32,"tv":11228.6,"id":12343905}]}]}
{"op":"mcm","clk":"4232032763","pt":1631550987604,"mc":[{"id":"1.187560634","rc":[{"batl":[[0,1.29,96.58],[1,1.31,76.5],[2,1.66,2.88]],"ltp":1.32,"tv":11228.6,"id":12343905}]}]}
{"op":"mcm","clk":"4232032784","pt":1631550987811,"mc":[{"id":"1.187560634","rc":[{"batb":[[0,4.2,2.92],[1,4,34.64],[2,1.01,105.79]],"ltp":4.1,"tv":4560.51,"id":9629296},{"batl":[[0,1.31,76.58],[1,1.66,2.88],[2,3,5.2]],"ltp":1.32,"tv":11228.6,"id":12343905}]}]}
{"op":"mcm","clk":"4232033013","pt":1631550990598,"mc":[{"id":"1.187560634","rc":[{"batb":[[0,6.8,3.8],[1,6.6,41.22],[2,6.4,40]],"batl":[[0,7.2,4.41],[1,7.6,51.27],[2,7.8,2]],"ltp":4.1,"tv":4560.51,"id":9629296},{"batl":[[0,1.17,241.75],[1,1.18,322.26],[2,1.31,76.58]],"ltp":1.32,"tv":11228.6,"id":12343905}]}]}
{"op":"mcm","clk":"4232033084","pt":1631550991386,"mc":[{"id":"1.187560634","rc":[{"batb":[[1,6.6,20.62],[2,6.4,20]],"ltp":4.1,"tv":4560.51,"id":9629296},{"batb":[[1,1.14,585.26]],"batl":[[2,1.23,48.12]],"ltp":1.32,"tv":11228.6,"id":12343905}]}]}
{"op":"mcm","clk":"4232033108","pt":1631550991697,"mc":[{"id":"1.187560634","rc":[{"batl":[[2,1.23,48.04]],"ltp":1.32,"tv":11228.6,"id":12343905}]}]}
{"op":"mcm","clk":"4232033410","pt":1631550995612,"mc":[{"id":"1.187560634","rc":[{"batl":[[0,1.17,241.83],[2,1.2,358.96]],"ltp":1.32,"tv":11228.6,"id":12343905}]}]}
{"op":"mcm","clk":"4232033420","pt":1631550995712,"mc":[{"id":"1.187560634","rc":[{"batl":[[2,1.23,48.04]],"ltp":1.32,"tv":11228.6,"id":12343905}]}]}
{"op":"mcm","clk":"4232033838","pt":1631551000827,"mc":[{"id":"1.187560634","rc":[{"trd":[[1.17,7.16]],"batl":[[0,1.17,238.25]],"ltp":1.17,"tv":11235.76,"id":12343905}],"tv":15796.27}]}
{"op":"mcm","clk":"4232034043","pt":1631551003097,"mc":[{"id":"1.187560634","rc":[{"trd":[[1.17,8.08]],"batl":[[0,1.17,237.79]],"ltp":1.17,"tv":11236.68,"id":12343905}],"tv":15797.19}]}
{"op":"mcm","clk":"4232034176","pt":1631551004508,"mc":[{"id":"1.187560634","rc":[{"batb":[[0,4.7,22.65],[1,1.01,105.79],[2,6.4,0]],"batl":[[0,13.5,2],[1,21,2],[2,990,0.01]],"ltp":4.1,"tv":4560.51,"id":9629296},{"batb":[[0,1.14,51.83],[1,1.1,2],[2,1.08,2.06]],"batl":[[0,1.23,48.12],[1,1.39,17.93],[2,1.66,2.88]],"ltp":1.17,"tv":11236.68,"id":12343905}]}]}
{"op":"mcm","clk":"4232034212","pt":1631551004918,"mc":[{"id":"1.187560634","rc":[{"batl":[[0,21,2],[1,990,0.01],[2,990,0]],"ltp":4.1,"tv":4560.51,"id":9629296},{"batb":[[0,1.1,2],[1,1.06,925.19],[2,1.05,564.69]],"batl":[[0,1.39,18.01],[1,1.66,2.88],[2,3,5.2]],"ltp":1.17,"tv":11236.68,"id":12343905}]}]}
{"op":"mcm","clk":"4232034571","pt":1631551009426,"mc":[{"id":"1.187560634","rc":[{"batb":[[0,1.14,163.78],[1,1.13,438.2],[2,1.1,2]],"batl":[[0,1.16,439.12],[1,1.17,147.5],[2,1.39,17.93]],"ltp":1.17,"tv":11236.68,"id":12343905}]}]}
{"op":"mcm","clk":"4232034761","pt":1631551011613,"mc":[{"id":"1.187560634","rc":[{"trd":[[7.2,0.45]],"batl":[[0,13.5,2],[1,21,2],[2,990,0.01]],"ltp":7.2,"tv":4560.96,"id":9629296},{"trd":[[1.16,2.79]],"batl":[[0,1.16,436.33],[1,1.17,147.42]],"ltp":1.16,"tv":11239.47,"id":12343905}],"tv":15800.43}]}
{"op":"mcm","clk":"4232034839","pt":1631551012608,"mc":[{"id":"1.187560634","rc":[{"batl":[[0,21,2],[1,990,0.01],[2,990,0]],"ltp":7.2,"tv":4560.96,"id":9629296},{"batb":[[0,1.1,2],[1,1.06,925.19],[2,1.05,564.69]],"batl":[[0,1.39,17.93],[1,1.66,2.88],[2,3,5.2]],"ltp":1.16,"tv":11239.47,"id":12343905}]}]}
{"op":"mcm","clk":"4232035044","pt":1631551015239,"mc":[{"id":"1.187560634","rc":[{"batb":[[1,1.08,631.37],[2,1.06,925.19]],"batl":[[0,1.22,121.07],[1,1.23,245.26],[2,1.39,17.93]],"ltp":1.16,"tv":11239.47,"id":12343905}]}]}
{"op":"mcm","clk":"4232035122","pt":1631551016129,"mc":[{"id":"1.187560634","rc":[{"batl":[[0,13.5,2],[1,21,2],[2,990,0.01]],"ltp":7.2,"tv":4560.96,"id":9629296},{"batb":[[1,1.08,633.43]],"ltp":1.16,"tv":11239.47,"id":12343905}]}]}
{"op":"mcm","clk":"4232035992","pt":1631551026262,"mc":[{"id":"1.187560634","rc":[{"batl":[[2,1.39,18.16]],"ltp":1.16,"tv":11239.47,"id":12343905}]}]}
{"op":"mcm","clk":"4232036040","pt":1631551026845,"mc":[{"id":"1.187560634","rc":[{"batb":[[1,1.08,2.06]],"ltp":1.16,"tv":11239.47,"id":12343905}]}]}
{"op":"mcm","clk":"4232036280","pt":1631551029618,"mc":[{"id":"1.187560634","rc":[{"batb":[[0,5,36.64],[1,4.7,22.65],[2,1.01,105.79]],"batl":[[0,5.7,4.02],[1,6,56.11],[2,6.2,44.76]],"ltp":7.2,"tv":4560.96,"id":9629296},{"trd":[[1.16,2.95]],"batb":[[0,1.2,4139.44],[1,1.1,2],[2,1.08,2.06]],"batl":[[0,1.22,120.99],[1,1.23,280.54],[2,1.25,146.57]],"ltp":1.16,"tv":11239.63,"id":12343905}],"tv":15800.59}]}
{"op":"mcm","clk":"4232036366","pt":1631551030670,"mc":[{"id":"1.187560634","rc":[{"batb":[[0,5.3,28.3],[1,5.2,14.16],[2,5.1,14.16]],"batl":[[1,5.8,5.27],[2,6,36.11]],"ltp":7.2,"tv":4560.96,"id":9629296},{"batb":[[0,1.21,75.69],[1,1.2,724.97],[2,1.19,370.72]],"ltp":1.16,"tv":11239.63,"id":12343905}]}]}
{"op":"mcm","clk":"4232036399","pt":1631551031041,"mc":[{"id":"1.187560634","rc":[{"batb":[[0,5.3,5.66],[1,5.2,2.84],[2,5.1,2.84]],"ltp":7.2,"tv":4560.96,"id":9629296}]}]}
{"op":"mcm","clk":"4232037086","pt":1631551040634,"mc":[{"id":"1.187560634","rc":[{"batb":[[0,4.7,22.65],[1,4,34.14],[2,1.01,105.79]],"batl":[[0,5.8,5.27],[1,10.5,2],[2,13.5,2]],"ltp":7.2,"tv":4560.96,"id":9629296},{"batb":[[1,1.19,49.66],[2,1.18,192.92]],"batl":[[0,1.29,45.81],[1,1.66,3.11],[2,3,5.2]],"ltp":1.16,"tv":11239.63,"id":12343905}]}]}
{"op":"mcm","clk":"4232037140","pt":1631551041265,"mc":[{"id":"1.187560634","rc":[{"batb":[[0,4,34.14],[1,1.01,105.79],[2,1.01,0]],"batl":[[0,13.5,2],[1,15.5,2],[2,21,2]],"ltp":7.2,"tv":4560.96,"id":9629296},{"batb":[[0,1.1,337.1],[1,1.08,2.06],[2,1.07,358.07]],"batl":[[0,1.66,3.11],[1,3,5.2],[2,3.8,27.43]],"ltp":1.16,"tv":11239.63,"id":12343905}]}]}
{"op":"mcm","clk":"4232037316","pt":1631551043647,"mc":[{"id":"1.187560634","rc":[{"batb":[[0,5,6.03],[1,4,34.14],[2,1.01,105.79]],"ltp":7.2,"tv":4560.96,"id":9629296},{"batb":[[0,1.12,543.16],[1,1.1,337.1],[2,1.08,2.06]],"batl":[[0,1.28,104.41],[1,1.29,185.7],[2,1.66,3.11]],"ltp":1.16,"tv":11239.63,"id":12343905}]}]}
{"op":"mcm","clk":"4232037383","pt":1631551044582,"mc":[{"id":"1.187560634","rc":[{"batb":[[0,4,34.59],[1,1.01,105.79],[2,1.01,0]],"batl":[[0,10.5,2],[1,13.5,2],[2,15.5,2]],"ltp":7.2,"tv":4560.96,"id":9629296},{"batb":[[1,1.11,258.59],[2,1.1,337.1]],"ltp":1.16,"tv":11239.63,"id":12343905}]}]}
{"op":"mcm","clk":"4232038140","pt":1631551055685,"mc":[{"id":"1.187560634","rc":[{"batb":[[0,4,34.14]],"ltp":7.2,"tv":4560.96,"id":9629296}]}]}
{"op":"mcm","clk":"4232038805","pt":1631551065463,"mc":[{"id":"1.187560634","rc":[{"batl":[[0,13.5,2],[1,15.5,2],[2,21,2]],"ltp":7.2,"tv":4560.96,"id":9629296},{"batb":[[0,1.1,337.1],[1,1.09,271.61],[2,1.08,2.06]],"ltp":1.16,"tv":11239.63,"id":12343905}]}]}
{"op":"mcm","clk":"4232038986","pt":1631551068385,"mc":[{"id":"1.187560634","rc":[{"batb":[[0,4.5,5.97],[1,4,34.14],[2,1.01,105.79]],"batl":[[0,4.7,4.36],[1,4.8,41.66],[2,4.9,24.61]],"ltp":7.2,"tv":4560.96,"id":9629296},{"batb":[[0,1.26,473.41],[1,1.25,460.94],[2,1.1,337.1]],"batl":[[2,1.31,210.34]],"ltp":1.16,"tv":11239.63,"id":12343905}]}]}
{"op":"mcm","clk":"4232039044","pt":1631551069276,"mc":[{"id":"1.187560634","rc":[{"batb":[[1,4.4,6.82],[2,4.3,3.4]],"ltp":7.2,"tv":4560.96,"id":9629296},{"batb":[[2,1.24,146.54]],"ltp":1.16,"tv":11239.63,"id":12343905}]}]}
{"op":"mcm","clk":"4232039829","pt":1631551080485,"mc":[{"id":"1.187560634","rc":[{"trd":[[4.7,38.57]],"batl":[[0,4.7,3.87]],"ltp":4.7,"tv":4561.45,"id":9629296},{"trd":[[1.27,302.03]],"batb":[[0,1.26,196.4]],"ltp":1.27,"tv":11241.44,"id":12343905}],"tv":15802.89}]}
{"op":"mcm","clk":"4232040167","pt":1631551084620,"mc":[{"id":"1.187560634","rc":[{"trd":[[4.7,39.92]],"batb":[[0,4.1,2.99],[1,4,34.14],[2,3.9,3.26]],"batl":[[0,5.6,2.01],[1,6,2.01],[2,13.5,2]],"ltp":4.7,"tv":4562.8,"id":9629296},{"trd":[[1.27,307.03]],"batb":[[0,1.25,47.27],[1,1.24,146.54],[2,1.22,123.84]],"batl":[[0,1.32,77.36],[1,1.34,73.75],[2,1.36,43.68]],"ltp":1.27,"tv":11246.44,"id":12343905}],"tv":15809.24}]}
{"op":"mcm","clk":"4232040214","pt":1631551085195,"mc":[{"id":"1.187560634","rc":[{"batb":[[0,3.9,3.71],[1,3.6,22.14],[2,1.01,105.79]],"batl":[[0,6,2.01],[1,13.5,2],[2,15.5,2]],"ltp":4.7,"tv":4562.8,"id":9629296},{"batb":[[0,1.2,115.07],[1,1.18,201.06],[2,1.1,2]],"batl":[[0,1.34,73.75],[1,1.66,3.11],[2,3,5.2]],"ltp":1.27,"tv":11246.44,"id":12343905}]}]}
{"op":"mcm","clk":"4232040459","pt":1631551088504,"mc":[{"id":"1.187560634","rc":[{"batl":[[0,5.6,2.01],[1,6,2.01],[2,13.5,2]],"ltp":4.7,"tv":4562.8,"id":9629296},{"batb":[[0,1.22,106.84],[1,1.2,115.07],[2,1.18,201.06]],"ltp":1.27,"tv":11246.44,"id":12343905}]}]}
{"op":"mcm","clk":"4232040545","pt":1631551089609,"mc":[{"id":"1.187560634","rc":[{"batl":[[0,6,2.01],[1,13.5,2],[2,15.5,2]],"ltp":4.7,"tv":4562.8,"id":9629296},{"batb":[[0,1.2,115.07],[1,1.18,201.06],[2,1.1,2]],"batl":[[0,1.29,483.49],[1,1.34,73.75],[2,1.66,3.11]],"ltp":1.27,"tv":11246.44,"id":12343905}]}]}
{"op":"mcm","clk":"4232040610","pt":1631551090607,"mc":[{"id":"1.187560634","rc":[{"batl":[[0,4.9,19.15],[1,6,2.01],[2,13.5,2]],"ltp":4.7,"tv":4562.8,"id":9629296},{"batb":[[0,1.25,18.65],[1,1.24,298.43],[2,1.23,253.51]],"batl":[[0,1.27,182.4],[1,1.28,212.87],[2,1.34,73.75]],"ltp":1.27,"tv":11246.44,"id":12343905}]}]}
{"op":"mcm","clk":"4232040687","pt":1631551091601,"mc":[{"id":"1.187560634","rc":[{"batb":[[0,4.1,3.29],[1,3.9,3.26],[2,3.6,22.14]],"batl":[[0,6,2.01],[1,13.5,2],[2,15.5,2]],"ltp":4.7,"tv":4562.8,"id":9629296},{"batb":[[0,1.24,298.43],[1,1.23,253.51],[2,1.2,115.07]],"batl":[[1,1.28,192.28],[2,1.32,81.86]],"ltp":1.27,"tv":11246.44,"id":12343905}]}]}
{"op":"mcm","clk":"4232040752","pt":1631551092439,"mc":[{"id":"1.187560634","rc":[{"batb":[[0,3.9,3.71],[1,3.6,22.14],[2,1.01,105.79]],"ltp":4.7,"tv":4562.8,"id":9629296},{"batb":[[0,1.2,115.07],[1,1.18,201.06],[2,1.1,2]],"batl":[[0,1.34,73.75],[1,1.66,3.11],[2,3,5.2]],"ltp":1.27,"tv":11246.44,"id":12343905}]}]}
{"op":"mcm","clk":"4232040982","pt":1631551095606,"mc":[{"id":"1.187560634","rc":[{"batb":[[0,4.1,2.89],[1,3.9,3.26],[2,3.6,22.14]],"batl":[[0,5.6,2.01],[1,6,2.01],[2,13.5,2]],"ltp":4.7,"tv":4562.8,"id":9629296},{"batb":[[0,1.22,103.34],[1,1.2,115.07],[2,1.18,201.06]],"batl":[[0,1.32,81.11],[1,1.33,171.02],[2,1.34,225.21]],"ltp":1.27,"tv":11246.44,"id":12343905}]}]}
{"op":"mcm","clk":"4232041005","pt":1631551095922,"mc":[{"id":"1.187560634","rc":[{"batb":[[0,3.9,3.71],[1,3.6,22.14],[2,1.01,105.79]],"batl":[[0,6,2.01],[1,13.5,2],[2,15.5,2]],"ltp":4.7,"tv":4562.8,"id":9629296},{"batb":[[0,1.2,115.07],[1,1.18,201.06],[2,1.1,2]],"batl":[[0,1.33,171.02],[1,1.34,225.21],[2,1.66,3.11]],"ltp":1.27,"tv":11246.44,"id":12343905}]}]}
{"op":"mcm","clk":"4232041198","pt":1631551098592,"mc":[{"id":"1.187560634","rc":[{"trd":[[4.7,40.37]],"batb":[[0,4.1,4.2],[1,3.9,3.26],[2,3.6,22.14]],"batl":[[0,4.3,64.67],[1,6,2.01],[2,13.5,2]],"ltp":4.7,"tv":4563.25,"id":9629296},{"trd":[[1.28,267.32]],"batb":[[0,1.31,12.87],[1,1.3,2266.4],[2,1.29,294.27]],"batl":[[2,1.35,151.76]],"ltp":1.28,"tv":11248.09,"id":12343905}],"tv":15811.34}]}
{"op":"mcm","clk":"4232041272","pt":1631551099529,"mc":[{"id":"1.187560634","rc":[{"batb":[[1,1.3,343.51],[2,1.29,248.13]],"batl":[[1,1.34,247.59],[2,1.35,162.96]],"ltp":1.28,"tv":11248.09,"id":12343905}]}]}
{"op":"mcm","clk":"4232041891","pt":1631551105495,"mc":[{"id":"1.187560634","rc":[{"batl":[[1,4.9,2.35],[2,5.2,2.03]],"ltp":4.7,"tv":4563.25,"id":9629296}]}]}
{"op":"mcm","clk":"4232042028","pt":1631551107321,"mc":[{"id":"1.187560634","rc":[{"trd":[[1.3,106.48],[1.31,34.36]],"batb":[[0,1.3,341.27],[1,1.29,248.13],[2,1.28,140.46]],"ltp":1.3,"tv":11278.3,"id":12343905}],"tv":15841.55}]}
{"op":"mcm","clk":"4232042303","pt":1631551110612,"mc":[{"id":"1.187560634","rc":[{"batb":[[0,1.3,184.19]],"batl":[[0,1.32,5.97],[1,1.33,171.02],[2,1.34,247.59]],"ltp":1.3,"tv":11278.3,"id":12343905}]}]}
{"op":"mcm","clk":"4232042734","pt":1631551115645,"mc":[{"id":"1.187560634","rc":[{"batb":[[0,4.1,17.17]],"ltp":4.7,"tv":4563.25,"id":9629296},{"trd":[[1.3,115.6]],"batb":[[0,1.3,179.63]],"ltp":1.3,"tv":11287.42,"id":12343905}],"tv":15850.67}]}
{"op":"mcm","clk":"4232042765","pt":1631551115914,"mc":[{"id":"1.187560634","rc":[{"batb":[[0,4.1,4.2]],"ltp":4.7,"tv":4563.25,"id":9629296}]}]}
{"op":"mcm","clk":"4232042904","pt":1631551117636,"mc":[{"id":"1.187560634","rc":[{"batb":[[0,3.9,3.26],[1,3.6,22.14],[2,3.4,3.46]],"ltp":4.7,"tv":4563.25,"id":9629296},{"batb":[[0,1.3,180.62]],"batl":[[0,1.33,171.02],[1,1.34,247.59],[2,1.35,162.96]],"ltp":1.3,"tv":11287.42,"id":12343905}]}]}
{"op":"mcm","clk":"4232043137","pt":1631551120451,"mc":[{"id":"1.187560634","rc":[{"batl":[[0,4.3,69.27]],"ltp":4.7,"tv":4563.25,"id":9629296},{"trd":[[1.3,233.62],[1.32,135.7]],"batb":[[0,1.3,120.62]],"batl":[[0,1.32,20.63],[1,1.33,171.02],[2,1.34,247.59]],"ltp":1.3,"tv":11407.42,"id":12343905}],"tv":15970.67}]}
{"op":"mcm","clk":"4232043184","pt":1631551121028,"mc":[{"id":"1.187560634","rc":[{"trd":[[4.3,23.26]],"batl":[[0,4.3,63.35]],"ltp":4.3,"tv":4575.08,"id":9629296}],"tv":15982.51}]}
{"op":"mcm","clk":"4232043372","pt":1631551123220,"mc":[{"id":"1.187560634","rc":[{"batb":[[0,1.3,138.74]],"batl":[[1,1.33,192.89]],"ltp":1.3,"tv":11407.42,"id":12343905}]}]}
{"op":"mcm","clk":"4232043483","pt":1631551124640,"mc":[{"id":"1.187560634","rc":[{"batl":[[0,4.9,2.35],[1,5.2,2.03],[2,6,2.01]],"ltp":4.3,"tv":4575.08,"id":9629296},{"batb":[[1,1.29,236.59],[2,1.28,128.92]],"batl":[[0,1.33,192.89],[1,1.34,225.21],[2,1.41,104.64]],"ltp":1.3,"tv":11407.42,"id":12343905}]}]}
{"op":"mcm","clk":"4232043539","pt":1631551125362,"mc":[{"id":"1.187560634","rc":[{"batb":[[0,3.25,3.69],[1,3.05,34.14],[2,1.01,105.79]],"batl":[[0,5.2,2.03],[1,6,2.01],[2,13.5,2]],"ltp":4.3,"tv":4575.08,"id":9629296},{"batb":[[0,1.28,6.96],[1,1.24,239.97],[2,1.2,115.07]],"batl":[[0,1.44,55.06],[1,1.66,2.88],[2,3,5.2]],"ltp":1.3,"tv":11407.42,"id":12343905}]}]}
{"op":"mcm","clk":"4232043780","pt":1631551128655,"mc":[{"id":"1.187560634","rc":[{"batb":[[0,3.4,3.46],[1,3.25,3.69],[2,3.05,34.14]],"batl":[[0,4.9,2.05],[1,5.2,2.03],[2,6,2.01]],"ltp":4.3,"tv":4575.08,"id":9629296},{"batb":[[1,1.26,173.2],[2,1.25,227.83]],"batl":[[0,1.41,65.73],[1,1.42,161.21],[2,1.43,112.59]],"ltp":1.3,"tv":11407.42,"id":12343905}]}]}
{"op":"mcm","clk":"4232043848","pt":1631551129450,"mc":[{"id":"1.187560634","rc":[{"batb":[[0,3.25,3.69],[1,3.05,34.14],[2,1.01,105.79]],"batl":[[0,5.2,2.03],[1,6,2.01],[2,13.5,2]],"ltp":4.3,"tv":4575.08,"id":9629296},{"batb":[[1,1.24,239.97],[2,1.2,115.07]],"batl":[[0,1.42,161.44],[1,1.43,112.59],[2,1.44,54.83]],"ltp":1.3,"tv":11407.42,"id":12343905}]}]}
{"op":"mcm","clk":"4232044131","pt":1631551132662,"mc":[{"id":"1.187560634","rc":[{"trd":[[3.85,2.17]],"batl":[[0,3.6,38.09],[1,3.65,8.5],[2,4.4,386.18]],"ltp":3.85,"tv":4575.16,"id":9629296},{"trd":[[1.35,25.12]],"batb":[[0,1.38,242.08],[1,1.37,249.23],[2,1.36,32.84]],"batl":[[0,1.4,5.94],[1,1.42,161.21],[2,1.43,112.59]],"ltp":1.35,"tv":11407.65,"id":12343905}],"tv":15982.82}]}
{"op":"mcm","clk":"4232044207","pt":1631551133554,"mc":[{"id":"1.187560634","rc":[{"batb":[[0,3.4,8.82],[1,3.35,4.42],[2,3.3,4.42]],"batl":[[2,4.1,1.8]],"ltp":3.85,"tv":4575.16,"id":9629296},{"batb":[[1,1.37,293.09],[2,1.36,10.94]],"ltp":1.35,"tv":11407.65,"id":12343905}]}]}
{"op":"mcm","clk":"4232044260","pt":1631551134276,"mc":[{"id":"1.187560634","rc":[{"batl":[[2,3.85,18.05]],"ltp":3.85,"tv":4575.16,"id":9629296}]}]}
{"op":"mcm","clk":"4232044550","pt":1631551138083,"mc":[{"id":"1.187560634","rc":[{"batl":[[2,4.1,1.8]],"ltp":3.85,"tv":4575.16,"id":9629296}]}]}
{"op":"mcm","clk":"4232044628","pt":1631551139183,"mc":[{"id":"1.187560634","rc":[{"trd":[[1.38,132.78]],"batb":[[0,1.38,218.08]],"ltp":1.38,"tv":11455.65,"id":12343905}],"tv":16030.82}]}
{"op":"mcm","clk":"4232044825","pt":1631551141783,"mc":[{"id":"1.187560634","rc":[{"trd":[[1.38,141.31]],"batb":[[0,1.38,213.81]],"ltp":1.38,"tv":11464.19,"id":12343905}],"tv":16039.35}]}
{"op":"mcm","clk":"4232045063","pt":1631551144875,"mc":[{"id":"1.187560634","rc":[{"batb":[[0,1.39,200],[1,1.38,213.81],[2,1.37,293.09]],"batl":[[1,1.42,133.73]],"ltp":1.38,"tv":11464.19,"id":12343905}]}]}
{"op":"mcm","clk":"4232045206","pt":1631551146648,"mc":[{"id":"1.187560634","rc":[{"trd":[[3.5,22.38]],"batl":[[0,3.5,15.67],[1,3.6,38.09],[2,3.65,8.5]],"ltp":3.5,"tv":4577.54,"id":9629296},{"trd":[[1.4,5.94]],"batl":[[0,1.42,133.73],[1,1.43,112.59],[2,1.44,54.83]],"ltp":1.4,"tv":11470.13,"id":12343905}],"tv":16047.67}]}
{"op":"mcm","clk":"4232045257","pt":1631551147481,"mc":[{"id":"1.187560634","rc":[{"batb":[[0,3.05,34.14],[1,2.56,22.06],[2,1.01,105.79]],"batl":[[1,4.1,1.8],[2,4.3,4.45]],"ltp":3.5,"tv":4577.54,"id":9629296},{"batb":[[1,1.37,130.78],[2,1.31,84.87]],"batl":[[0,1.5,39.39],[1,1.66,2.88],[2,3,5.2]],"ltp":1.4,"tv":11470.13,"id":12343905}]}]}
{"op":"mcm","clk":"4232045295","pt":1631551147962,"mc":[{"id":"1.187560634","rc":[{"batb":[[0,2.56,22.06],[1,1.01,105.79],[2,1.01,0]],"ltp":3.5,"tv":4577.54,"id":9629296},{"batb":[[1,1.31,84.87],[2,1.3,112.82]],"batl":[[0,1.66,2.88],[1,3,5.2],[2,3.8,27.43]],"ltp":1.4,"tv":11470.13,"id":12343905}]}]}
{"op":"mcm","clk":"4232045367","pt":1631551148688,"mc":[{"id":"1.187560634","rc":[{"batl":[[0,4.1,1.8],[1,4.3,4.45],[2,4.6,4.41]],"ltp":3.5,"tv":4577.54,"id":9629296}]}]}
{"op":"mcm","clk":"4232045542","pt":1631551150582,"mc":[{"id":"1.187560634","rc":[{"batb":[[0,2.78,4.66],[1,2.68,4.86],[2,2.62,5.54]],"ltp":3.5,"tv":4577.54,"id":9629296},{"batl":[[0,1.56,47.42],[1,1.59,43.5],[2,1.61,40.5]],"ltp":1.4,"tv":11470.13,"id":12343905}]}]}
{"op":"mcm","clk":"4232045568","pt":1631551150895,"mc":[{"id":"1.187560634","rc":[{"batb":[[0,2.68,4.86],[1,2.62,5.54],[2,2.56,22.06]],"ltp":3.5,"tv":4577.54,"id":9629296},{"batl":[[0,1.59,43.5],[1,1.61,40.5],[2,1.66,2.88]],"ltp":1.4,"tv":11470.13,"id":12343905}]}]}
{"op":"mcm","clk":"4232045698","pt":1631551152297,"mc":[{"id":"1.187560634","rc":[{"batb":[[0,1.41,123.41],[1,1.4,126.08],[2,1.39,200]],"batl":[[0,1.45,168.24],[1,1.46,102.81],[2,1.59,43.5]],"ltp":1.4,"tv":11470.13,"id":12343905}]}]}
{"op":"mcm","clk":"4232045788","pt":1631551153292,"mc":[{"id":"1.187560634","rc":[{"batb":[[0,2.84,4.97],[1,2.68,4.86],[2,2.62,5.54]],"ltp":3.5,"tv":4577.54,"id":9629296},{"batl":[[2,1.54,47.25]],"ltp":1.4,"tv":11470.13,"id":12343905}]}]}
{"op":"mcm","clk":"4232046182","pt":1631551157594,"mc":[{"id":"1.187560634","rc":[{"batb":[[2,1.31,84.87]],"ltp":1.4,"tv":11470.13,"id":12343905}]}]}
{"op":"mcm","clk":"4232046349","pt":1631551159477,"mc":[{"id":"1.187560634","rc":[{"batb":[[0,2.68,4.86],[1,2.62,5.54],[2,2.56,22.06]],"batl":[[1,4.3,2.45]],"ltp":3.5,"tv":4577.54,"id":9629296},{"batb":[[0,1.31,80.79],[1,1.3,112.82],[2,1.28,105.28]],"batl":[[0,1.59,43.5],[1,1.61,40.5],[2,1.66,2.88]],"ltp":1.4,"tv":11470.13,"id":12343905}]}]}
{"op":"mcm","clk":"4232046428","pt":1631551159798,"mc":[{"id":"1.187560634","rc":[{"batl":[[1,4.6,4.41],[2,990,0.01]],"ltp":3.5,"tv":4577.54,"id":9629296},{"batb":[[0,1.3,112.82],[1,1.28,105.28],[2,1.1,2]],"ltp":1.4,"tv":11470.13,"id":12343905}]}]}
{"op":"mcm","clk":"4232046707","pt":1631551162208,"mc":[{"id":"1.187560634","rc":[{"batb":[[0,1.32,114.71],[1,1.31,174.76],[2,1.3,112.82]],"batl":[[0,1.56,95.77],[1,1.57,77.55],[2,1.59,43.5]],"ltp":1.4,"tv":11470.13,"id":12343905}]}]}
{"op":"mcm","clk":"4232046795","pt":1631551162998,"mc":[{"id":"1.187560634","rc":[{"batl":[[1,4.3,4.65],[2,4.6,4.41]],"ltp":3.5,"tv":4577.54,"id":9629296},{"batb":[[1,1.31,271.92]],"ltp":1.4,"tv":11470.13,"id":12343905}]}]}
{"op":"mcm","clk":"4232047666","pt":1631551171201,"mc":[{"id":"1.187560634","rc":[{"batl":[[0,2.96,19.49],[1,4.1,1.8],[2,4.3,4.65]],"ltp":3.5,"tv":4577.54,"id":9629296}]}]}
{"op":"mcm","clk":"4232047732","pt":1631551171724,"mc":[{"id":"1.187560634","rc":[{"batl":[[0,1.59,43.5],[1,1.61,40.5],[2,1.66,2.88]],"ltp":1.4,"tv":11470.13,"id":12343905}]}]}
{"op":"mcm","clk":"4232047980","pt":1631551174617,"mc":[{"id":"1.187560634","rc":[{"trd":[[2.96,21.61]],"batb":[[0,3.6,55.56],[1,2.68,4.86],[2,2.62,5.54]],"batl":[[0,4.1,1.8],[1,4.2,70.07]],"ltp":2.96,"tv":4597.03,"id":9629296},{"trd":[[1.51,78.62]],"batb":[[0,1.32,130.09]],"batl":[[0,1.34,23.64],[1,1.35,180.31],[2,1.36,251.1]],"ltp":1.51,"tv":11508.37,"id":12343905}],"tv":16105.4}]}
{"op":"mcm","clk":"4232048053","pt":1631551175400,"mc":[{"id":"1.187560634","rc":[{"batb":[[1,3.5,24.33],[2,2.88,40.01]],"batl":[[1,4.2,105.79],[2,4.3,22.51]],"ltp":2.96,"tv":4597.03,"id":9629296},{"batb":[[2,1.3,158.27]],"batl":[[2,1.36,162.88]],"ltp":1.51,"tv":11508.37,"id":12343905}]}]}
{"op":"mcm","clk":"4232048086","pt":1631551175817,"mc":[{"id":"1.187560634","rc":[{"batl":[[1,4.2,77.21],[2,4.3,8.23]],"ltp":2.96,"tv":4597.03,"id":9629296}]}]}
{"op":"mcm","clk":"4232048670","pt":1631551182737,"mc":[{"id":"1.187560634","rc":[{"batb":[[2,3.15,3.83]],"ltp":2.96,"tv":4597.03,"id":9629296}]}]}
{"op":"mcm","clk":"4232048957","pt":1631551186830,"mc":[{"id":"1.187560634","rc":[{"trd":[[3.9,24.99]],"ltp":3.9,"tv":4599.74,"id":9629296},{"trd":[[1.34,220.33]],"batl":[[0,1.34,15.75]],"ltp":1.34,"tv":11516.26,"id":12343905}],"tv":16116.0}]}
{"op":"mcm","clk":"4232049055","pt":1631551188129,"mc":[{"id":"1.187560634","rc":[{"trd":[[1.34,251.83]],"batb":[[0,1.34,29.33],[1,1.32,130.09],[2,1.31,271.92]],"batl":[[0,1.35,180.31],[1,1.36,162.88],[2,1.37,11.02]],"ltp":1.34,"tv":11547.76,"id":12343905}],"tv":16147.5}]}
{"op":"mcm","clk":"4232049514","pt":1631551193908,"mc":[{"id":"1.187560634","rc":[{"batl":[[0,4.2,77.21],[1,4.3,8.23],[2,4.4,3.58]],"ltp":3.9,"tv":4599.74,"id":9629296}]}]}
{"op":"mcm","clk":"4232049715","pt":1631551196628,"mc":[{"id":"1.187560634","rc":[{"batb":[[0,3.1,3.64],[1,3,5],[2,2.96,4.63]],"batl":[[0,4.6,2],[1,4.8,2.02],[2,5,2]],"ltp":3.9,"tv":4599.74,"id":9629296},{"batb":[[1,1.28,11.62],[2,1.27,81.87]],"batl":[[0,1.47,55.5],[1,1.5,46.79],[2,1.51,46.5]],"ltp":1.34,"tv":11547.76,"id":12343905}]}]}
{"op":"mcm","clk":"4232049730","pt":1631551196934,"mc":[{"id":"1.187560634","rc":[{"batb":[[0,2.96,4.63],[1,2.88,40.01],[2,1.01,105.79]],"batl":[[0,5.2,2.03],[1,990,0.01],[2,5,0]],"ltp":3.9,"tv":4599.74,"id":9629296},{"batb":[[1,1.28,6.96],[2,1.25,141.42]],"batl":[[0,1.51,46.5],[1,1.66,2.88],[2,3,5.2]],"ltp":1.34,"tv":11547.76,"id":12343905}]}]}
{"op":"mcm","clk":"4232049903","pt":1631551199647,"mc":[{"id":"1.187560634","rc":[{"trd":[[1.34,310.48]],"batb":[[0,1.28,6.96],[1,1.26,239.15],[2,1.25,372.22]],"batl":[[0,1.34,141.22],[1,1.46,90.83],[2,1.47,100.53]],"ltp":1.34,"tv":11606.4,"id":12343905}],"tv":16206.15}]}
{"op":"mcm","clk":"4232049973","pt":1631551200431,"mc":[{"id":"1.187560634","rc":[{"batb":[[0,3.1,3.84],[1,2.96,4.63],[2,2.88,40.01]],"ltp":3.9,"tv":4599.74,"id":9629296},{"batl":[[2,1.47,155.03]],"ltp":1.34,"tv":11606.4,"id":12343905}]}]}
{"op":"mcm","clk":"4232050075","pt":1631551201647,"mc":[{"id":"1.187560634","rc":[{"batl":[[0,1.32,36.1],[1,1.34,141.22],[2,1.47,54.5]],"ltp":1.34,"tv":11606.4,"id":12343905}]}]}
{"op":"mcm","clk":"4232050225","pt":1631551203638,"mc":[{"id":"1.187560634","rc":[{"batl":[[0,4.8,2.12],[1,5.2,2.03],[2,990,0.01]],"ltp":3.9,"tv":4599.74,"id":9629296},{"batb":[[1,1.27,99.87],[2,1.26,239.15]],"batl":[[0,1.34,141.22],[1,1.47,54.5],[2,1.51,46.5]],"ltp":1.34,"tv":11606.4,"id":12343905}]}]}
{"op":"mcm","clk":"4232050288","pt":1631551204631,"mc":[{"id":"1.187560634","rc":[{"batl":[[0,4.7,7]],"ltp":3.9,"tv":4599.74,"id":9629296},{"batb":[[1,1.26,438.72],[2,1.25,372.22]],"batl":[[0,1.29,204.29],[1,1.3,176.68],[2,1.31,497.81]],"ltp":1.34,"tv":11606.4,"id":12343905}]}]}
{"op":"mcm","clk":"4232050366","pt":1631551205625,"mc":[{"id":"1.187560634","rc":[{"batb":[[0,3.95,35.9],[1,3.35,27.18],[2,3.1,3.84]],"batl":[[1,4.8,18.74],[2,4.9,9.37]],"ltp":3.9,"tv":4599.74,"id":9629296},{"batl":[[2,1.31,406.21]],"ltp":1.34,"tv":11606.4,"id":12343905}]}]}
{"op":"mcm","clk":"4232050373","pt":1631551205728,"mc":[{"id":"1.187560634","rc":[{"batl":[[1,4.8,6.24],[2,4.9,3.12]],"ltp":3.9,"tv":4599.74,"id":9629296}]}]}
{"op":"mcm","clk":"4232050859","pt":1631551212629,"mc":[{"id":"1.187560634","rc":[{"batb":[[1,3.85,2.77],[2,3.7,3.22]],"ltp":3.9,"tv":4599.74,"id":9629296}]}]}
{"op":"mcm","clk":"4232051132","pt":1631551216039,"mc":[{"id":"1.187560634","rc":[{"trd":[[4.4,3.61]],"ltp":4.4,"tv":4603.35,"id":9629296},{"trd":[[1.28,267.48],[1.29,490.99]],"batb":[[0,1.28,6.88]],"batl":[[0,1.29,191.97]],"ltp":1.29,"tv":11618.88,"id":12343905}],"tv":16222.24}]}
{"op":"mcm","clk":"4232051355","pt":1631551218443,"mc":[{"id":"1.187560634","rc":[{"trd":[[1.28,267.64]],"batb":[[0,1.28,6.8]],"ltp":1.28,"tv":11619.04,"id":12343905}],"tv":16222.4}]}
{"op":"mcm","clk":"4232051622","pt":1631551222329,"mc":[{"id":"1.187560634","rc":[{"trd":[[1.28,281.24]],"batb":[[0,1.26,438.72],[1,1.25,372.22],[2,1.24,106.02]],"batl":[[0,1.28,65.4],[1,1.29,191.97],[2,1.3,176.68]],"ltp":1.28,"tv":11632.64,"id":12343905}],"tv":16236.0}]}
{"op":"mcm","clk":"4232051879","pt":1631551225471,"mc":[{"id":"1.187560634","rc":[{"batb":[[0,3.85,2.77],[1,3.7,3.22],[2,3.35,27.18]],"batl":[[0,5.6,2],[1,990,0.01],[2,4.9,0]],"ltp":4.4,"tv":4603.35,"id":9629296},{"batb":[[0,1.23,2.69],[1,1.22,114.84],[2,1.21,171.28]],"batl":[[0,1.35,79.5],[1,1.37,64.5],[2,1.47,54.5]],"ltp":1.28,"tv":11632.64,"id":12343905}]}]}
{"op":"mcm","clk":"4232051968","pt":1631551226364,"mc":[{"id":"1.187560634","rc":[{"batb":[[0,3.7,3.22],[1,3.6,2.89]],"batl":[[1,5.8,2.02],[2,990,0.01]],"ltp":4.4,"tv":4603.35,"id":9629296},{"batb":[[2,1.21,297.97]],"batl":[[0,1.37,64.58],[1,1.38,74.25],[2,1.66,2.88]],"ltp":1.28,"tv":11632.64,"id":12343905}]}]}
{"op":"mcm","clk":"4232052245","pt":1631551229973,"mc":[{"id":"1.187560634","rc":[{"trd":[[1.28,281.4]],"batb":[[0,1.28,105.26],[1,1.27,207.35],[2,1.23,2.69]],"batl":[[0,1.3,91.09],[1,1.31,171.26],[2,1.37,64.5]],"ltp":1.28,"tv":11632.8,"id":12343905}],"tv":16236.16}]}
{"op":"mcm","clk":"4232052457","pt":1631551232554,"mc":[{"id":"1.187560634","rc":[{"batb":[[0,3.85,2.97],[1,3.7,3.22],[2,3.6,2.89]],"batl":[[0,5.2,2.03],[1,5.6,2],[2,5.8,2.02]],"ltp":4.4,"tv":4603.35,"id":9629296},{"batb":[[0,1.27,207.35],[1,1.24,98.52]],"batl":[[2,1.35,71.5]],"ltp":1.28,"tv":11632.8,"id":12343905}]}]}
{"op":"mcm","clk":"4232052658","pt":1631551235140,"mc":[{"id":"1.187560634","rc":[{"batb":[[0,1.27,286.56],[1,1.26,221.5],[2,1.24,98.52]],"batl":[[0,1.3,117.52]],"ltp":1.28,"tv":11632.8,"id":12343905}]}]}
{"op":"mcm","clk":"4232052782","pt":1631551236614,"mc":[{"id":"1.187560634","rc":[{"batb":[[0,3.7,3.22],[1,3.6,2.89],[2,3.35,27.18]],"batl":[[0,5.6,2],[1,5.8,2.02],[2,990,0.01]],"ltp":4.4,"tv":4603.35,"id":9629296},{"batb":[[0,1.23,2.69],[1,1.22,114.84],[2,1.21,297.97]],"batl":[[0,1.28,35.18],[1,1.37,64.5],[2,1.38,74.25]],"ltp":1.28,"tv":11632.8,"id":12343905}]}]}
{"op":"mcm","clk":"4232053030","pt":1631551239645,"mc":[{"id":"1.187560634","rc":[{"batb":[[1,1.22,418.14],[2,1.21,555.7]],"batl":[[1,1.37,261.58],[2,1.38,205.89]],"ltp":1.28,"tv":11632.8,"id":12343905}]}]}
{"op":"mcm","clk":"4232053173","pt":1631551241382,"mc":[{"id":"1.187560634","rc":[{"batl":[[0,4.7,2.52],[1,5.6,2],[2,5.8,2.02]],"ltp":4.4,"tv":4603.35,"id":9629296},{"batb":[[1,1.22,114.84],[2,1.21,297.97]],"ltp":1.28,"tv":11632.8,"id":12343905}]}]}
{"op":"mcm","clk":"4232053456","pt":1631551244539,"mc":[{"id":"1.187560634","rc":[{"batb":[[2,3.55,38.3]],"batl":[[0,3.85,7.38],[1,4.1,5.75],[2,4.4,40]],"ltp":4.4,"tv":4603.35,"id":9629296},{"batb":[[0,1.33,3922.47],[1,1.32,269.23],[2,1.31,144.37]],"batl":[[0,1.37,273.37],[1,1.38,205.89],[2,1.39,181.88]],"ltp":1.28,"tv":11632.8,"id":12343905}]}]}
{"op":"mcm","clk":"4232053533","pt":1631551245425,"mc":[{"id":"1.187560634","rc":[{"batb":[[0,1.33,669.94],[1,1.32,373.33]],"ltp":1.28,"tv":11632.8,"id":12343905}]}]}
{"op":"mcm","clk":"4232054137","pt":1631551253523,"mc":[{"id":"1.187560634","rc":[{"batb":[[0,1.36,100],[1,1.33,669.94],[2,1.32,373.33]],"ltp":1.28,"tv":11632.8,"id":12343905}]}]}
{"op":"mcm","clk":"4232054325","pt":1631551256150,"mc":[{"id":"1.187560634","rc":[{"batb":[[1,1.33,383.94]],"ltp":1.28,"tv":11632.8,"id":12343905}]}]}
{"op":"mcm","clk":"4232054441","pt":1631551257633,"mc":[{"id":"1.187560634","rc":[{"trd":[[3.85,6.86]],"batl":[[0,3.85,2.69]],"ltp":3.85,"tv":4608.04,"id":9629296},{"trd":[[1.35,38.47]],"batb":[[0,1.33,383.94],[1,1.32,373.33],[2,1.31,144.37]],"ltp":1.35,"tv":11646.15,"id":12343905}],"tv":16254.2}]}
{"op":"mcm","clk":"4232054663","pt":1631551260516,"mc":[{"id":"1.187560634","rc":[{"trd":[[1.37,403.24]],"batb":[[0,1.33,317.02],[1,1.32,203.36]],"batl":[[0,1.36,6.96],[1,1.37,173.37],[2,1.38,205.89]],"ltp":1.37,"tv":11846.15,"id":12343905}],"tv":16454.2}]}
{"op":"mcm","clk":"4232054750","pt":1631551261462,"mc":[{"id":"1.187560634","rc":[{"batb":[[2,1.31,99.26]],"ltp":1.37,"tv":11846.15,"id":12343905}]}]}
{"op":"mcm","clk":"4232054923","pt":1631551263350,"mc":[{"id":"1.187560634","rc":[{"batb":[[0,1.34,86.46],[1,1.33,317.02],[2,1.32,203.36]],"batl":[[1,1.37,189.25]],"ltp":1.37,"tv":11846.15,"id":12343905}]}]}
{"op":"mcm","clk":"4232055012","pt":1631551264660,"mc":[{"id":"1.187560634","rc":[{"batb":[[0,3.35,27.18],[1,2.64,20.63],[2,1.01,105.79]],"batl":[[0,4.4,40],[1,4.7,2.52],[2,4.8,2.27]],"ltp":3.85,"tv":4608.04,"id":9629296},{"batb":[[0,1.32,104.1],[1,1.27,101.87],[2,1.24,263.36]],"batl":[[1,1.66,2.88],[2,3,5.2]],"ltp":1.37,"tv":11846.15,"id":12343905}]}]}
{"op":"mcm","clk":"4232055019","pt":1631551264760,"mc":[{"id":"1.187560634","rc":[{"batb":[[0,2.64,20.63],[1,1.01,105.79],[2,1.01,0]],"ltp":3.85,"tv":4608.04,"id":9629296},{"batb":[[0,1.27,101.87],[1,1.24,263.36],[2,1.23,2.69]],"ltp":1.37,"tv":11846.15,"id":12343905}]}]}
{"op":"mcm","clk":"4232055413","pt":1631551269670,"mc":[{"id":"1.187560634","rc":[{"trd":[[1.36,192.59]],"batb":[[0,1.36,196.18],[1,1.35,151.03],[2,1.27,101.87]],"batl":[[0,1.4,165.48],[1,1.41,119.55],[2,1.66,2.88]],"ltp":1.36,"tv":11860.07,"id":12343905}],"tv":16468.12}]}
{"op":"mcm","clk":"4232055508","pt":1631551270934,"mc":[{"id":"1.187560634","rc":[{"batb":[[0,1.36,241.26]],"ltp":1.36,"tv":11860.07,"id":12343905}]}]}
{"op":"mcm","clk":"4232055986","pt":1631551276377,"mc":[{"id":"1.187560634","rc":[{"batb":[[0,1.36,45.08],[1,1.27,101.87],[2,1.24,263.36]],"batl":[[0,1.66,2.88],[1,3,5.2],[2,3.8,27.43]],"ltp":1.36,"tv":11860.07,"id":12343905}]}]}
{"op":"mcm","clk":"4232056094","pt":1631551277633,"mc":[{"id":"1.187560634","rc":[{"batb":[[0,1.36,45.53]],"ltp":1.36,"tv":11860.07,"id":12343905}]}]}
{"op":"mcm","clk":"4232056243","pt":1631551279362,"mc":[{"id":"1.187560634","rc":[{"batb":[[2,1.26,174.79]],"batl":[[0,1.53,90.36],[1,1.54,83.61],[2,1.66,2.88]],"ltp":1.36,"tv":11860.07,"id":12343905}]}]}
{"op":"mcm","clk":"4232056644","pt":1631551284268,"mc":[{"id":"1.187560634","rc":[{"batb":[[0,1.36,45.08]],"ltp":1.36,"tv":11860.07,"id":12343905}]}]}
{"op":"mcm","clk":"4232056817","pt":1631551286251,"mc":[{"id":"1.187560634","rc":[{"batb":[[1,1.9,3],[2,1.01,105.79]],"ltp":3.85,"tv":4608.04,"id":9629296}]}]}
{"op":"mcm","clk":"4232057173","pt":1631551290587,"mc":[{"id":"1.187560634","rc":[{"batl":[[0,1.66,2.88],[1,3,5.2],[2,3.8,27.43]],"ltp":1.36,"tv":11860.07,"id":12343905}]}]}
{"op":"mcm","clk":"4232057402","pt":1631551293570,"mc":[{"id":"1.187560634","rc":[{"trd":[[4.4,43.61]],"batb":[[0,4.4,6.82],[1,4.3,3.4],[2,4.2,3.4]],"batl":[[0,4.7,2.52],[1,4.8,7.13],[2,5,30.89]],"ltp":4.4,"tv":4648.04,"id":9629296},{"trd":[[1.29,627.42],[1.36,282.75]],"batb":[[0,1.26,174.79],[1,1.25,353.19],[2,1.24,311.02]],"batl":[[0,1.28,14.61],[1,1.29,243.21],[2,1.3,175.81]],"ltp":1.29,"tv":12086.66,"id":12343905}],"tv":16734.71}]}
{"op":"mcm","clk":"4232057490","pt":1631551294579,"mc":[{"id":"1.187560634","rc":[{"batl":[[2,4.9,6.12]],"ltp":4.4,"tv":4648.04,"id":9629296}]}]}
{"op":"mcm","clk":"4232058118","pt":1631551302098,"mc":[{"id":"1.187560634","rc":[{"trd":[[4.7,40.77]],"batl":[[0,4.7,2.11]],"ltp":4.7,"tv":4648.44,"id":9629296},{"trd":[[1.27,308.52]],"ltp":1.27,"tv":12088.15,"id":12343905}],"tv":16736.6}]}
{"op":"mcm","clk":"4232058592","pt":1631551306606,"mc":[{"id":"1.187560634","rc":[{"trd":[[1.28,282.3]],"batl":[[0,1.28,14.16]],"ltp":1.28,"tv":12089.05,"id":12343905}],"tv":16737.5}]}
{"op":"mcm","clk":"4232058696","pt":1631551307803,"mc":[{"id":"1.187560634","rc":[{"trd":[[1.28,283.2]],"batl":[[0,1.28,13.71]],"ltp":1.28,"tv":12089.95,"id":12343905}],"tv":16738.4}]}
{"op":"mcm","clk":"4232058998","pt":1631551310896,"mc":[{"id":"1.187560634","rc":[{"trd":[[4.7,42.89]],"batl":[[0,4.8,7.13],[1,4.9,6.12],[2,5,33.95]],"ltp":4.7,"tv":4650.56,"id":9629296},{"trd":[[1.26,771.72],[1.27,316.34]],"batb":[[0,1.26,160.78],[2,1.24,263.36]],"ltp":1.26,"tv":12125.78,"id":12343905}],"tv":16776.34}]}
{"op":"mcm","clk":"4232059328","pt":1631551315086,"mc":[{"id":"1.187560634","rc":[{"trd":[[4.5,0.31]],"ltp":4.5,"tv":4650.62,"id":9629296},{"trd":[[1.28,283.41]],"batl":[[0,1.28,13.5]],"ltp":1.28,"tv":12125.99,"id":12343905}],"tv":16776.61}]}
{"op":"mcm","clk":"4232059441","pt":1631551316502,"mc":[{"id":"1.187560634","rc":[{"batb":[[0,3.95,35.57],[1,3.25,28.69],[2,1.9,3]],"batl":[[0,5.2,2.18],[1,5.4,2.44],[2,5.6,2]],"ltp":4.5,"tv":4650.62,"id":9629296},{"batb":[[0,1.24,263.36],[1,1.23,106.63],[2,1.22,114.84]],"batl":[[0,1.66,2.88],[1,3,5.2],[2,3.8,27.43]],"ltp":1.28,"tv":12125.99,"id":12343905}]}]}
{"op":"mcm","clk":"4232059506","pt":1631551317177,"mc":[{"id":"1.187560634","rc":[{"batb":[[0,3.25,28.69],[1,1.9,3],[2,1.01,105.79]],"batl":[[0,6,2.36],[1,990,0.01],[2,5.6,0]],"ltp":4.5,"tv":4650.62,"id":9629296},{"batb":[[0,1.2,307.4],[1,1.1,2],[2,1.01,105.79]],"ltp":1.28,"tv":12125.99,"id":12343905}]}]}
{"op":"mcm","clk":"4232059629","pt":1631551318587,"mc":[{"id":"1.187560634","rc":[{"batl":[[0,1.66,3.27]],"ltp":1.28,"tv":12125.99,"id":12343905}]}]}
{"op":"mcm","clk":"4232059721","pt":1631551319592,"mc":[{"id":"1.187560634","rc":[{"batb":[[0,4,10.53],[1,3.25,28.69],[2,1.9,3]],"ltp":4.5,"tv":4650.62,"id":9629296},{"batb":[[0,1.21,354.71],[1,1.2,517.95],[2,1.1,2]],"batl":[[0,1.38,197.04],[1,1.39,127.26],[2,1.66,2.88]],"ltp":1.28,"tv":12125.99,"id":12343905}]}]}
{"op":"mcm","clk":"4232059816","pt":1631551320386,"mc":[{"id":"1.187560634","rc":[{"batb":[[0,3.25,28.69],[1,1.9,3],[2,1.01,105.79]],"batl":[[0,5.6,2.26],[1,6,2.36],[2,990,0.01]],"ltp":4.5,"tv":4650.62,"id":9629296},{"batb":[[0,1.22,117.84],[1,1.21,354.71],[2,1.2,517.95]],"batl":[[0,1.66,3.27],[1,3,5.2],[2,3.8,27.43]],"ltp":1.28,"tv":12125.99,"id":12343905}]}]}
{"op":"mcm","clk":"4232059914","pt":1631551321276,"mc":[{"id":"1.187560634","rc":[{"batl":[[0,6,2.36],[1,990,0.01],[2,990,0]],"ltp":4.5,"tv":4650.62,"id":9629296},{"batb":[[0,1.21,354.71],[1,1.2,517.95],[2,1.1,2]],"batl":[[0,1.66,2.88]],"ltp":1.28,"tv":12125.99,"id":12343905}]}]}
{"op":"mcm","clk":"4232060030","pt":1631551322598,"mc":[{"id":"1.187560634","rc":[{"batb":[[0,5.1,39.22],[1,5,26.2],[2,3.25,28.69]],"batl":[[0,5.5,3.97],[1,6,2.36],[2,990,0.01]],"ltp":4.5,"tv":4650.62,"id":9629296},{"batb":[[0,1.21,586.28]],"batl":[[0,1.24,155.75],[1,1.25,3232.77],[2,1.26,60.48]],"ltp":1.28,"tv":12125.99,"id":12343905}]}]}
{"op":"mcm","clk":"4232060111","pt":1631551323594,"mc":[{"id":"1.187560634","rc":[{"batb":[[2,4.5,25.58]],"batl":[[1,5.8,25.86],[2,5.9,12.92]],"ltp":4.5,"tv":4650.62,"id":9629296},{"batb":[[2,1.19,49.66]],"batl":[[0,1.24,290.71],[1,1.25,336.65],[2,1.26,12.1]],"ltp":1.28,"tv":12125.99,"id":12343905}]}]}
{"op":"mcm","clk":"4232060141","pt":1631551324007,"mc":[{"id":"1.187560634","rc":[{"batl":[[1,5.8,5.18],[2,5.9,2.58]],"ltp":4.5,"tv":4650.62,"id":9629296}]}]}
{"op":"mcm","clk":"4232060256","pt":1631551325318,"mc":[{"id":"1.187560634","rc":[{"batl":[[0,5.8,5.18],[1,5.9,2.58],[2,6,4.94]],"ltp":4.5,"tv":4650.62,"id":9629296},{"batl":[[0,1.24,255.92]],"ltp":1.28,"tv":12125.99,"id":12343905}]}]}
{"op":"mcm","clk":"4232060457","pt":1631551327588,"mc":[{"id":"1.187560634","rc":[{"batl":[[2,1.26,308.45]],"ltp":1.28,"tv":12125.99,"id":12343905}]}]}
{"op":"mcm","clk":"4232060504","pt":1631551328214,"mc":[{"id":"1.187560634","rc":[{"batl":[[0,5.5,3.97],[1,5.8,5.18],[2,5.9,2.58]],"ltp":4.5,"tv":4650.62,"id":9629296},{"batl":[[0,1.24,290.71],[2,1.26,12.1]],"ltp":1.28,"tv":12125.99,"id":12343905}]}]}
{"op":"mcm","clk":"4232061028","pt":1631551334636,"mc":[{"id":"1.187560634","rc":[{"trd":[[5.5,82.55]],"batl":[[0,5.8,5.18],[1,5.9,2.58],[2,6,4.94]],"ltp":5.5,"tv":4654.59,"id":9629296},{"trd":[[1.22,119.06]],"batl":[[0,1.22,94.81],[1,1.24,290.71],[2,1.25,336.65]],"ltp":1.22,"tv":12143.87,"id":12343905}],"tv":16798.46}]}
{"op":"mcm","clk":"4232061371","pt":1631551338929,"mc":[{"id":"1.187560634","rc":[{"trd":[[1.22,134.99]],"batl":[[0,1.22,86.84]],"ltp":1.22,"tv":12159.8,"id":12343905}],"tv":16814.4}]}
{"op":"mcm","clk":"4232061789","pt":1631551343654,"mc":[{"id":"1.187560634","rc":[{"trd":[[1.24,973.24]],"batl":[[0,1.24,281.69],[1,1.25,336.65],[2,1.26,12.1]],"ltp":1.24,"tv":12177.84,"id":12343905}],"tv":16832.44}]}
{"op":"mcm","clk":"4232061871","pt":1631551344641,"mc":[{"id":"1.187560634","rc":[{"batl":[[0,1.24,246.9]],"ltp":1.24,"tv":12177.84,"id":12343905}]}]}
{"op":"mcm","clk":"4232062022","pt":1631551346333,"mc":[{"id":"1.187560634","rc":[{"trd":[[1.21,218.9]],"batb":[[0,1.21,498.73]],"ltp":1.21,"tv":12352.94,"id":12343905}],"tv":17007.54}]}
{"op":"mcm","clk":"4232062284","pt":1631551349645,"mc":[{"id":"1.187560634","rc":[{"batb":[[0,1.21,541.63],[1,1.2,562.99]],"batl":[[0,1.24,290.49]],"ltp":1.21,"tv":12352.94,"id":12343905}]}]}
{"op":"mcm","clk":"4232062362","pt":1631551350550,"mc":[{"id":"1.187560634","rc":[{"batl":[[0,5.7,6.68],[1,5.8,5.18],[2,5.9,2.58]],"ltp":5.5,"tv":4654.59,"id":9629296},{"batl":[[0,1.23,23.93],[1,1.24,290.49],[2,1.25,336.65]],"ltp":1.21,"tv":12352.94,"id":12343905}]}]}
{"op":"mcm","clk":"4232064145","pt":1631551372862,"mc":[{"id":"1.187560634","rc":[{"trd":[[5.3,16.04]],"ltp":5.3,"tv":4655.4,"id":9629296},{"trd":[[1.23,1130.97]],"batl":[[0,1.23,20.44]],"ltp":1.23,"tv":12356.43,"id":12343905}],"tv":17011.84}]}
{"op":"mcm","clk":"4232065029","pt":1631551383068,"mc":[{"id":"1.187560634","rc":[{"batl":[[0,5.8,5.18],[1,5.9,2.58],[2,6,4.94]],"ltp":5.3,"tv":4655.4,"id":9629296},{"batl":[[0,1.24,290.49],[1,1.25,336.65],[2,1.26,12.1]],"ltp":1.23,"tv":12356.43,"id":12343905}]}]}
{"op":"mcm","clk":"4232065307","pt":1631551385970,"mc":[{"id":"1.187560634","rc":[{"batl":[[0,5.7,7.43],[1,5.8,5.18],[2,5.9,2.58]],"ltp":5.3,"tv":4655.4,"id":9629296},{"batl":[[0,1.23,20.44],[1,1.24,290.49],[2,1.25,336.65]],"ltp":1.23,"tv":12356.43,"id":12343905}]}]}
{"op":"mcm","clk":"4232065958","pt":1631551393742,"mc":[{"id":"1.187560634","rc":[{"trd":[[5.1,20.49],[5.3,20.78]],"batb":[[0,5.1,33.41]],"ltp":5.1,"tv":4671.76,"id":9629296},{"trd":[[1.23,1151.41]],"batl":[[0,1.24,290.49],[1,1.25,336.65],[2,1.26,12.1]],"ltp":1.23,"tv":12376.87,"id":12343905}],"tv":17048.64}]}
{"op":"mcm","clk":"4232066687","pt":1631551402346,"mc":[{"id":"1.187560634","rc":[{"trd":[[1.21,220.38],[1.24,973.64]],"batb":[[0,1.21,540.89]],"batl":[[0,1.24,290.29]],"ltp":1.21,"tv":12378.75,"id":12343905}],"tv":17050.52}]}
{"op":"mcm","clk":"4232066835","pt":1631551404367,"mc":[{"id":"1.187560634","rc":[{"batl":[[0,5.8,5.18],[1,5.9,2.58],[2,6,4.94]],"ltp":5.1,"tv":4671.76,"id":9629296},{"trd":[[1.24,974.02]],"batl":[[0,1.24,290.1]],"ltp":1.24,"tv":12379.13,"id":12343905}],"tv":17050.89}]}
{"op":"mcm","clk":"4232067017","pt":1631551406871,"mc":[{"id":"1.187560634","rc":[{"batl":[[0,5.5,5.35],[1,5.8,5.18],[2,5.9,2.58]],"ltp":5.1,"tv":4671.76,"id":9629296},{"batl":[[0,1.24,318.76]],"ltp":1.24,"tv":12379.13,"id":12343905}]}]}
{"op":"mcm","clk":"4232067285","pt":1631551409947,"mc":[{"id":"1.187560634","rc":[{"batb":[[2,1.14,259.52]],"ltp":1.24,"tv":12379.13,"id":12343905}]}]}
{"op":"mcm","clk":"4232067499","pt":1631551412673,"mc":[{"id":"1.187560634","rc":[{"batb":[[0,4.5,25.58],[1,4,34.47],[2,1.9,3]],"batl":[[0,6,2.36],[1,990,0.01],[2,5.9,0]],"ltp":5.1,"tv":4671.76,"id":9629296},{"batb":[[0,1.2,307.4],[1,1.14,259.52],[2,1.1,2]],"batl":[[0,1.66,2.88],[1,3,5.2],[2,3.8,27.43]],"ltp":1.24,"tv":12379.13,"id":12343905}]}]}
{"op":"mcm","clk":"4232067564","pt":1631551413356,"mc":[{"id":"1.187560634","rc":[{"batb":[[0,4,34.47],[1,1.9,3],[2,1.01,105.79]],"batl":[[0,9.4,2]],"ltp":5.1,"tv":4671.76,"id":9629296},{"batb":[[0,1.23,25],[2,1.12,211.54]],"ltp":1.24,"tv":12379.13,"id":12343905}]}]}
{"op":"mcm","clk":"4232067747","pt":1631551415573,"mc":[{"id":"1.187560634","rc":[{"batb":[[1,1.15,388.7],[2,1.14,465.54]],"batl":[[0,1.28,140.93],[1,1.29,186.25],[2,1.66,2.88]],"ltp":1.24,"tv":12379.13,"id":12343905}]}]}
{"op":"mcm","clk":"4232067837","pt":1631551416570,"mc":[{"id":"1.187560634","rc":[{"batl":[[0,7.8,2],[1,9.4,2],[2,990,0.01]],"ltp":5.1,"tv":4671.76,"id":9629296},{"batb":[[1,1.15,190.23],[2,1.14,259.52]],"ltp":1.24,"tv":12379.13,"id":12343905}]}]}
{"op":"mcm","clk":"4232067861","pt":1631551416876,"mc":[{"id":"1.187560634","rc":[{"batl":[[0,9.4,2],[1,990,0.01],[2,990,0]],"ltp":5.1,"tv":4671.76,"id":9629296},{"batb":[[1,1.14,259.52],[2,1.12,211.54]],"ltp":1.24,"tv":12379.13,"id":12343905}]}]}
{"op":"mcm","clk":"4232068086","pt":1631551419673,"mc":[{"id":"1.187560634","rc":[{"batb":[[0,4.3,31.64],[1,4.2,30.7],[2,4.1,30.7]],"batl":[[0,4.8,6.97],[1,5,29.06],[2,9.4,2]],"ltp":5.1,"tv":4671.76,"id":9629296},{"batb":[[0,1.26,87.98],[1,1.25,648.48],[2,1.24,109.68]],"batl":[[0,1.28,155.9],[2,1.3,244.03]],"ltp":1.24,"tv":12379.13,"id":12343905}]}]}
{"op":"mcm","clk":"4232068164","pt":1631551420469,"mc":[{"id":"1.187560634","rc":[{"batb":[[2,1.24,255.21]],"ltp":1.24,"tv":12379.13,"id":12343905}]}]}
{"op":"mcm","clk":"4232068628","pt":1631551425760,"mc":[{"id":"1.187560634","rc":[{"batb":[[1,4.2,33.37]],"batl":[[2,5.6,2.16]],"ltp":5.1,"tv":4671.76,"id":9629296}]}]}
{"op":"mcm","clk":"4232068945","pt":1631551430585,"mc":[{"id":"1.187560634","rc":[{"batb":[[0,4,2.68],[1,3.65,43.37],[2,1.9,3]],"batl":[[0,5.6,2.16],[1,6,2.36],[2,9.4,2]],"ltp":5.1,"tv":4671.76,"id":9629296},{"batb":[[0,1.23,25],[1,1.22,106.84],[2,1.2,129.02]],"batl":[[0,1.33,76.5],[1,1.66,2.88],[2,3,5.2]],"ltp":1.24,"tv":12379.13,"id":12343905}]}]}
{"op":"mcm","clk":"4232068971","pt":1631551430951,"mc":[{"id":"1.187560634","rc":[{"batl":[[0,6,2.36],[1,9.4,2],[2,990,0.01]],"ltp":5.1,"tv":4671.76,"id":9629296},{"batb":[[1,1.2,129.02],[2,1.18,194.01]],"ltp":1.24,"tv":12379.13,"id":12343905}]}]}
{"op":"mcm","clk":"4232069152","pt":1631551433642,"mc":[{"id":"1.187560634","rc":[{"batb":[[1,1.2,345.86],[2,1.19,322.15]],"batl":[[0,1.32,129.55],[1,1.33,235.37],[2,1.66,2.88]],"ltp":1.24,"tv":12379.13,"id":12343905}]}]}
{"op":"mcm","clk":"4232069463","pt":1631551437540,"mc":[{"id":"1.187560634","rc":[{"batb":[[0,4.2,2.77],[1,4,2.68],[2,3.65,43.37]],"batl":[[0,5.6,2.26],[1,6,2.36],[2,9.4,2]],"ltp":5.1,"tv":4671.76,"id":9629296},{"batb":[[1,1.22,110.84],[2,1.2,345.86]],"batl":[[0,1.31,83.5],[1,1.32,129.55],[2,1.33,235.37]],"ltp":1.24,"tv":12379.13,"id":12343905}]}]}
{"op":"mcm","clk":"4232069493","pt":1631551437855,"mc":[{"id":"1.187560634","rc":[{"batb":[[0,4,2.68],[1,3.65,43.37],[2,1.9,3]],"batl":[[0,6,2.36],[1,9.4,2],[2,990,0.01]],"ltp":5.1,"tv":4671.76,"id":9629296},{"batb":[[1,1.2,345.86],[2,1.19,322.15]],"batl":[[0,1.32,129.55],[1,1.33,235.37],[2,1.66,2.88]],"ltp":1.24,"tv":12379.13,"id":12343905}]}]}
{"op":"mcm","clk":"4232069855","pt":1631551442317,"mc":[{"id":"1.187560634","rc":[{"batb":[[0,1.2,345.86],[1,1.19,322.15],[2,1.18,194.01]],"ltp":1.24,"tv":12379.13,"id":12343905}]}]}
{"op":"mcm","clk":"4232069923","pt":1631551443059,"mc":[{"id":"1.187560634","rc":[{"batb":[[0,1.2,129.02],[1,1.18,194.01],[2,1.12,211.54]],"batl":[[0,1.33,76.5],[1,1.66,2.88],[2,3,5.2]],"ltp":1.24,"tv":12379.13,"id":12343905}]}]}
{"op":"mcm","clk":"4232070058","pt":1631551444539,"mc":[{"id":"1.187560634","rc":[{"batb":[[0,4.2,2.27],[1,4,2.68],[2,3.65,43.37]],"batl":[[0,5.6,2.01],[1,6,2.36],[2,9.4,2]],"ltp":5.1,"tv":4671.76,"id":9629296},{"batb":[[0,1.22,101.84],[1,1.2,129.02],[2,1.18,194.01]],"batl":[[0,1.31,87.5],[1,1.33,76.5],[2,1.66,2.88]],"ltp":1.24,"tv":12379.13,"id":12343905}]}]}
{"op":"mcm","clk":"4232070087","pt":1631551444854,"mc":[{"id":"1.187560634","rc":[{"batb":[[0,4,2.68],[1,3.65,43.37],[2,1.9,3]],"batl":[[0,6,2.36],[1,9.4,2],[2,990,0.01]],"ltp":5.1,"tv":4671.76,"id":9629296},{"batb":[[0,1.2,129.02],[1,1.18,194.01],[2,1.12,211.54]],"batl":[[0,1.33,76.5],[1,1.66,2.88],[2,3,5.2]],"ltp":1.24,"tv":12379.13,"id":12343905}]}]}
{"op":"mcm","clk":"4232070237","pt":1631551446654,"mc":[{"id":"1.187560634","rc":[{"batb":[[0,1.24,291.72],[1,1.23,258.34],[2,1.2,129.02]],"batl":[[0,1.27,192.66],[1,1.28,193.39],[2,1.33,76.5]],"ltp":1.24,"tv":12379.13,"id":12343905}]}]}
{"op":"mcm","clk":"4232070350","pt":1631551448126,"mc":[{"id":"1.187560634","rc":[{"batb":[[0,4.2,2.72],[1,4,2.68],[2,3.65,43.37]],"batl":[[0,5.6,2.06],[1,6,2.36],[2,9.4,2]],"ltp":5.1,"tv":4671.76,"id":9629296},{"batb":[[2,1.22,115.34]],"batl":[[2,1.31,80.5]],"ltp":1.24,"tv":12379.13,"id":12343905}]}]}
{"op":"mcm","clk":"4232070636","pt":1631551451330,"mc":[{"id":"1.187560634","rc":[{"batb":[[0,4,2.68],[1,3.65,43.37],[2,1.9,3]],"batl":[[0,6,2.36],[1,9.4,2],[2,990,0.01]],"ltp":5.1,"tv":4671.76,"id":9629296},{"batb":[[0,1.2,129.02],[1,1.18,194.01],[2,1.12,211.54]],"batl":[[0,1.33,76.5],[1,1.66,2.88],[2,3,5.2]],"ltp":1.24,"tv":12379.13,"id":12343905}]}]}
{"op":"mcm","clk":"4232070887","pt":1631551454544,"mc":[{"id":"1.187560634","rc":[{"batb":[[0,4.2,2.57],[1,4,2.68],[2,3.65,43.37]],"batl":[[0,5.6,2.06],[1,6,2.36],[2,9.4,2]],"ltp":5.1,"tv":4671.76,"id":9629296},{"batb":[[0,1.22,112.34],[1,1.2,345.86],[2,1.19,322.15]],"batl":[[0,1.31,89.5],[1,1.32,129.55],[2,1.33,235.37]],"ltp":1.24,"tv":12379.13,"id":12343905}]}]}
{"op":"mcm","clk":"4232070905","pt":1631551454762,"mc":[{"id":"1.187560634","rc":[{"batb":[[0,4,2.68],[1,3.65,43.37],[2,1.9,3]],"batl":[[0,6,2.36],[1,9.4,2],[2,990,0.01]],"ltp":5.1,"tv":4671.76,"id":9629296},{"batb":[[0,1.2,345.86],[1,1.19,322.15],[2,1.18,194.01]],"batl":[[0,1.32,129.55],[1,1.33,235.37],[2,1.66,2.88]],"ltp":1.24,"tv":12379.13,"id":12343905}]}]}
{"op":"mcm","clk":"4232071020","pt":1631551455963,"mc":[{"id":"1.187560634","rc":[{"batl":[[0,1.66,2.88],[1,3,5.2],[2,3.8,27.43]],"ltp":1.24,"tv":12379.13,"id":12343905}]}]}
{"op":"mcm","clk":"4232071254","pt":1631551458655,"mc":[{"id":"1.187560634","rc":[{"batb":[[0,5.4,50.36],[1,5.3,48.88],[2,5.2,48.88]],"batl":[[0,5.7,3.64],[1,6,2.36],[2,6.2,72.1]],"ltp":5.1,"tv":4671.76,"id":9629296},{"batl":[[0,1.22,1817.04],[1,1.23,36.24],[2,1.24,247.25]],"ltp":1.24,"tv":12379.13,"id":12343905}]}]}
{"op":"mcm","clk":"4232071334","pt":1631551459501,"mc":[{"id":"1.187560634","rc":[{"batb":[[0,5.4,25.18],[1,5.3,24.44],[2,5.2,24.44]],"ltp":5.1,"tv":4671.76,"id":9629296},{"batb":[[2,1.18,244.09]],"batl":[[0,1.22,297.22],[1,1.23,282.36]],"ltp":1.24,"tv":12379.13,"id":12343905}]}]}
{"op":"mcm","clk":"4232071674","pt":1631551463566,"mc":[{"id":"1.187560634","rc":[{"batl":[[2,1.24,487.96]],"ltp":1.24,"tv":12379.13,"id":12343905}]}]}
{"op":"mcm","clk":"4232071693","pt":1631551463785,"mc":[{"id":"1.187560634","rc":[{"batl":[[2,1.24,247.25]],"ltp":1.24,"tv":12379.13,"id":12343905}]}]}
{"op":"mcm","clk":"4232072206","pt":1631551470666,"mc":[{"id":"1.187560634","rc":[{"batl":[[0,1.22,153.01]],"ltp":1.24,"tv":12379.13,"id":12343905}]}]}
{"op":"mcm","clk":"4232072258","pt":1631551471558,"mc":[{"id":"1.187560634","rc":[{"batb":[[0,4.7,22.48],[1,4.5,5.44],[2,4.3,5.98]],"batl":[[0,9.4,2],[1,12.5,2],[2,990,0.01]],"ltp":5.1,"tv":4671.76,"id":9629296},{"trd":[[1.22,184.99]],"batb":[[0,1.18,244.09],[1,1.12,211.54],[2,1.11,316.23]],"batl":[[0,1.28,52],[1,1.3,5.85],[2,1.66,2.88]],"ltp":1.22,"tv":12429.13,"id":12343905}],"tv":17100.89}]}
{"op":"mcm","clk":"4232072337","pt":1631551472293,"mc":[{"id":"1.187560634","rc":[{"batb":[[0,4.1,32.29],[1,1.9,3],[2,1.01,105.79]],"batl":[[0,12.5,2],[1,990,0.01],[2,990,0]],"ltp":5.1,"tv":4671.76,"id":9629296},{"batb":[[0,1.11,316.23],[1,1.1,2],[2,1.09,266.61]],"batl":[[0,1.66,2.88],[1,3,5.2],[2,3.8,27.43]],"ltp":1.22,"tv":12429.13,"id":12343905}]}]}
{"op":"mcm","clk":"4232072507","pt":1631551474600,"mc":[{"id":"1.187560634","rc":[{"batb":[[0,1.13,325.26],[1,1.12,280.65],[2,1.11,316.23]],"batl":[[0,1.28,246.65],[1,1.29,183.96],[2,1.66,2.88]],"ltp":1.22,"tv":12429.13,"id":12343905}]}]}
{"op":"mcm","clk":"4232072598","pt":1631551475672,"mc":[{"id":"1.187560634","rc":[{"batb":[[0,1.11,316.23],[1,1.1,2],[2,1.09,266.61]],"batl":[[0,1.21,142.39],[1,1.66,2.88],[2,3,5.2]],"ltp":1.22,"tv":12429.13,"id":12343905}]}]}
{"op":"mcm","clk":"4232072705","pt":1631551477356,"mc":[{"id":"1.187560634","rc":[{"batl":[[0,1.66,2.88],[1,3,5.2],[2,3.8,27.43]],"ltp":1.22,"tv":12429.13,"id":12343905}]}]}
{"op":"mcm","clk":"4232072788","pt":1631551478556,"mc":[{"id":"1.187560634","rc":[{"batb":[[0,1.19,88.74],[1,1.18,338.13],[2,1.11,316.23]],"batl":[[0,1.21,300.56],[1,1.22,254.71],[2,1.66,2.88]],"ltp":1.22,"tv":12429.13,"id":12343905}]}]}
{"op":"mcm","clk":"4232072815","pt":1631551479082,"mc":[{"id":"1.187560634","rc":[{"batb":[[0,4.5,5.64],[1,4.3,5.18],[2,4.1,32.29]],"batl":[[0,9.4,2],[1,12.5,2],[2,990,0.01]],"ltp":5.1,"tv":4671.76,"id":9629296},{"batb":[[2,1.12,225.79]],"batl":[[2,1.28,5.84]],"ltp":1.22,"tv":12429.13,"id":12343905}]}]}
{"op":"mcm","clk":"4232073005","pt":1631551481982,"mc":[{"id":"1.187560634","rc":[{"batb":[[0,4.1,32.29],[1,1.9,3],[2,1.01,105.79]],"batl":[[0,12.5,2],[1,990,0.01],[2,990,0]],"ltp":5.1,"tv":4671.76,"id":9629296},{"batb":[[0,1.11,316.23],[1,1.1,224.34],[2,1.09,266.61]],"batl":[[0,1.66,2.88],[1,3,5.2],[2,3.8,27.43]],"ltp":1.22,"tv":12429.13,"id":12343905}]}]}
{"op":"mcm","clk":"4232073171","pt":1631551484608,"mc":[{"id":"1.187560634","rc":[{"batb":[[0,1.13,325.26],[1,1.12,280.65],[2,1.11,316.23]],"batl":[[0,1.28,246.65],[1,1.29,183.96],[2,1.66,2.88]],"ltp":1.22,"tv":12429.13,"id":12343905}]}]}
{"op":"mcm","clk":"4232073228","pt":1631551485508,"mc":[{"id":"1.187560634","rc":[{"batb":[[0,4.5,5.38],[1,4.3,5.88],[2,4.1,32.29]],"batl":[[0,9.4,2],[1,12.5,2],[2,990,0.01]],"ltp":5.1,"tv":4671.76,"id":9629296},{"batb":[[1,1.12,492.44]],"batl":[[0,1.28,253.24],[2,1.3,6.65]],"ltp":1.22,"tv":12429.13,"id":12343905}]}]}
{"op":"mcm","clk":"4232073519","pt":1631551489991,"mc":[{"id":"1.187560634","rc":[{"batb":[[0,4.1,32.29],[1,1.9,3],[2,1.01,105.79]],"ltp":5.1,"tv":4671.76,"id":9629296},{"batl":[[0,1.66,2.88],[1,3,5.2],[2,3.8,27.43]],"ltp":1.22,"tv":12429.13,"id":12343905}]}]}
{"op":"mcm","clk":"4232073695","pt":1631551492525,"mc":[{"id":"1.187560634","rc":[{"batb":[[0,7.4,36.76],[1,7.2,35.68],[2,7,35.68]],"batl":[[0,9.2,68.72],[1,9.4,2],[2,9.6,28.34]],"ltp":5.1,"tv":4671.76,"id":9629296},{"batb":[[0,1.14,29.26],[1,1.13,325.26],[2,1.12,492.44]],"batl":[[0,1.15,2735.04],[1,1.17,435.32],[2,1.66,2.88]],"ltp":1.22,"tv":12429.13,"id":12343905}]}]}
{"op":"mcm","clk":"4232073779","pt":1631551493631,"mc":[{"id":"1.187560634","rc":[{"batb":[[0,7.4,18.38],[1,7.2,17.84],[2,7,17.84]],"batl":[[2,9.6,14.18]],"ltp":5.1,"tv":4671.76,"id":9629296},{"batl":[[0,1.15,598.68],[1,1.16,229.76],[2,1.17,435.32]],"ltp":1.22,"tv":12429.13,"id":12343905}]}]}
{"op":"mcm","clk":"4232074061","pt":1631551497527,"mc":[{"id":"1.187560634","rc":[{"batl":[[2,1.17,770.99]],"ltp":1.22,"tv":12429.13,"id":12343905}]}]}
{"op":"mcm","clk":"4232074074","pt":1631551497728,"mc":[{"id":"1.187560634","rc":[{"batl":[[2,1.17,435.32]],"ltp":1.22,"tv":12429.13,"id":12343905}]}]}
{"op":"mcm","clk":"4232074700","pt":1631551504629,"mc":[{"id":"1.187560634","rc":[{"batb":[[0,6.4,21.22],[1,5,19.38],[2,1.9,3]],"batl":[[0,9.4,2],[1,12.5,2],[2,26,2]],"ltp":5.1,"tv":4671.76,"id":9629296},{"batb":[[0,1.13,325.26],[1,1.12,492.44],[2,1.11,369.46]],"batl":[[0,1.15,361.18],[2,1.2,49.24]],"ltp":1.22,"tv":12429.13,"id":12343905}]}]}
{"op":"mcm","clk":"4232074767","pt":1631551505323,"mc":[{"id":"1.187560634","rc":[{"batb":[[0,5,19.38],[1,1.9,3],[2,1.01,105.79]],"batl":[[0,990,0.01],[1,12.5,0],[2,26,0]],"ltp":5.1,"tv":4671.76,"id":9629296},{"batb":[[0,1.1,2],[1,1.03,811.62],[2,1.02,1255.88]],"batl":[[0,1.39,17.93],[1,1.66,2.88],[2,3,5.2]],"ltp":1.22,"tv":12429.13,"id":12343905}]}]}
{"op":"mcm","clk":"4232074959","pt":1631551507533,"mc":[{"id":"1.187560634","rc":[{"batb":[[0,1.15,25.45],[1,1.1,2],[2,1.03,811.62]],"ltp":1.22,"tv":12429.13,"id":12343905}]}]}
{"op":"mcm","clk":"4232075064","pt":1631551508642,"mc":[{"id":"1.187560634","rc":[{"batl":[[0,26,2],[1,990,0.01]],"ltp":5.1,"tv":4671.76,"id":9629296},{"batb":[[2,1.04,632.37]],"ltp":1.22,"tv":12429.13,"id":12343905}]}]}
{"op":"mcm","clk":"4232075092","pt":1631551508947,"mc":[{"id":"1.187560634","rc":[{"batl":[[0,990,0.01],[1,990,0]],"ltp":5.1,"tv":4671.76,"id":9629296},{"batb":[[2,1.03,811.62]],"ltp":1.22,"tv":12429.13,"id":12343905}]}]}
{"op":"mcm","clk":"4232075184","pt":1631551510328,"mc":[{"id":"1.187560634","rc":[{"trd":[[1.15,50.9]],"batb":[[0,1.11,609.22]],"batl":[[0,1.13,264.16],[1,1.14,330.99],[2,1.39,17.93]],"ltp":1.15,"tv":12480.03,"id":12343905}],"tv":17151.79}]}
{"op":"mcm","clk":"4232075343","pt":1631551512133,"mc":[{"id":"1.187560634","rc":[{"batl":[[0,26,2],[1,990,0.01]],"ltp":5.1,"tv":4671.76,"id":9629296},{"batb":[[2,1.04,599.12]],"ltp":1.15,"tv":12480.03,"id":12343905}]}]}
{"op":"mcm","clk":"4232075464","pt":1631551513439,"mc":[{"id":"1.187560634","rc":[{"trd":[[1.13,329.68]],"batl":[[0,1.13,99.32]],"ltp":1.13,"tv":12809.71,"id":12343905}],"tv":17481.47}]}
{"op":"mcm","clk":"4232075574","pt":1631551514547,"mc":[{"id":"1.187560634","rc":[{"batl":[[0,990,0.01],[1,990,0]],"ltp":5.1,"tv":4671.76,"id":9629296},{"batb":[[0,1.1,2],[1,1.03,811.62],[2,1.02,1255.88]],"batl":[[0,1.39,17.93],[1,1.66,2.88],[2,3,5.2]],"ltp":1.13,"tv":12809.71,"id":12343905}]}]}
{"op":"mcm","clk":"4232075810","pt":1631551517362,"mc":[{"id":"1.187560634","rc":[{"batb":[[1,1.06,106.35],[2,1.05,542.04]],"batl":[[0,1.21,156.93],[1,1.22,256.11],[2,1.39,17.93]],"ltp":1.13,"tv":12809.71,"id":12343905}]}]}
{"op":"mcm","clk":"4232075853","pt":1631551517841,"mc":[{"id":"1.187560634","rc":[{"batl":[[0,26,2],[1,990,0.01]],"ltp":5.1,"tv":4671.76,"id":9629296}]}]}
{"op":"mcm","clk":"4232076016","pt":1631551519848,"mc":[{"id":"1.187560634","rc":[{"batb":[[1,1.08,81.58],[2,1.06,106.35]],"ltp":1.13,"tv":12809.71,"id":12343905}]}]}
{"op":"mcm","clk":"4232076580","pt":1631551526563,"mc":[{"id":"1.187560634","rc":[{"batl":[[0,1.39,17.93],[1,1.66,2.88],[2,3,5.2]],"ltp":1.13,"tv":12809.71,"id":12343905}]}]}
{"op":"mcm","clk":"4232076834","pt":1631551529574,"mc":[{"id":"1.187560634","rc":[{"batb":[[0,14.5,2.06],[1,14,1.04],[2,13.5,1.04]],"batl":[[0,26,45.77]],"ltp":5.1,"tv":4671.76,"id":9629296},{"trd":[[1.08,163.21],[1.1,4]],"batb":[[0,1.06,106.35],[1,1.05,542.04],[2,1.04,1778.07]],"batl":[[0,1.07,3772.96],[1,1.09,1001.14],[2,1.11,53.23]],"ltp":1.08,"tv":12976.92,"id":12343905}],"tv":17648.68}]}
{"op":"mcm","clk":"4232076899","pt":1631551530275,"mc":[{"id":"1.187560634","rc":[{"batl":[[0,19.5,7.68],[1,26,45.77],[2,990,0.01]],"ltp":5.1,"tv":4671.76,"id":9629296},{"batl":[[0,1.07,950.18]],"ltp":1.08,"tv":12976.92,"id":12343905}]}]}
{"op":"mcm","clk":"4232076926","pt":1631551530769,"mc":[{"id":"1.187560634","rc":[{"batl":[[0,19.5,1.54]],"ltp":5.1,"tv":4671.76,"id":9629296}]}]}
{"op":"mcm","clk":"4232077233","pt":1631551534450,"mc":[{"id":"1.187560634","rc":[{"trd":[[1.06,24.4]],"batb":[[0,1.06,94.15]],"ltp":1.06,"tv":13001.32,"id":12343905}],"tv":17673.09}]}
{"op":"mcm","clk":"4232077305","pt":1631551535453,"mc":[{"id":"1.187560634","rc":[{"trd":[[1.06,48.8]],"batb":[[0,1.05,542.04],[1,1.04,1778.07],[2,1.03,868.99]],"batl":[[0,1.06,12.2],[1,1.07,950.18],[2,1.09,1001.14]],"ltp":1.06,"tv":13025.72,"id":12343905}],"tv":17697.49}]}
{"op":"mcm","clk":"4232077385","pt":1631551536554,"mc":[{"id":"1.187560634","rc":[{"trd":[[1.06,73.2],[1.07,9.54]],"batl":[[0,1.07,963.71],[1,1.09,1001.14],[2,1.11,53.23]],"ltp":1.07,"tv":13059.66,"id":12343905}],"tv":17731.42}]}
{"op":"mcm","clk":"4232077462","pt":1631551537554,"mc":[{"id":"1.187560634","rc":[{"batl":[[0,1.07,969.81],[1,1.08,6.1],[2,1.09,1001.14]],"ltp":1.07,"tv":13059.66,"id":12343905}]}]}
{"op":"mcm","clk":"4232077512","pt":1631551538277,"mc":[{"id":"1.187560634","rc":[{"batb":[[0,1.05,649.41]],"ltp":1.07,"tv":13059.66,"id":12343905}]}]}
{"op":"mcm","clk":"4232077581","pt":1631551539280,"mc":[{"id":"1.187560634","rc":[{"trd":[[15,59.44]],"ltp":15.0,"tv":4731.2,"id":9629296},{"trd":[[1.07,843.29]],"batl":[[0,1.07,136.06]],"ltp":1.07,"tv":13893.41,"id":12343905}],"tv":18624.61}]}
{"op":"mcm","clk":"4232077627","pt":1631551539857,"mc":[{"id":"1.187560634","rc":[{"batb":[[0,1.05,259.43]],"ltp":1.07,"tv":13893.41,"id":12343905}]}]}
{"op":"mcm","clk":"4232077766","pt":1631551541480,"mc":[{"id":"1.187560634","rc":[{"batb":[[0,7.8,12.67],[1,1.9,3],[2,1.01,105.79]],"batl":[[0,990,0.01],[1,26,0],[2,990,0]],"ltp":15.0,"tv":4731.2,"id":9629296},{"batb":[[0,1.01,105.79],[1,1.04,0],[2,1.03,0]],"batl":[[0,1.06,6.1],[1,1.07,24.4],[2,1.08,6.1]],"ltp":1.07,"tv":13893.41,"id":12343905}]}]}
{"op":"mcm","clk":"4232077800","pt":1631551541950,"mc":[{"id":"1.187560634","rc":[{"batb":[[0,1.01,12]],"ltp":1.07,"tv":13893.41,"id":12343905}]}]}
{"op":"mcm","clk":"4232077889","pt":1631551543056,"mc":[{"id":"1.187560634","rc":[{"trd":[[1.06,85.4]],"batl":[[0,1.06,11.93]],"ltp":1.06,"tv":13905.61,"id":12343905}],"tv":18636.81}]}
{"op":"mcm","clk":"4232077942","pt":1631551543886,"mc":[{"id":"1.187560634","rc":[{"batl":[[1,1.12,228.81],[2,1.13,376.64]],"ltp":1.06,"tv":13905.61,"id":12343905}]}]}
{"op":"mcm","clk":"4232078050","pt":1631551545384,"mc":[{"id":"1.187560634","rc":[{"batl":[[0,1.06,11.75]],"ltp":1.06,"tv":13905.61,"id":12343905}]}]}
{"op":"mcm","clk":"4232078136","pt":1631551546492,"mc":[{"id":"1.187560634","rc":[{"trd":[[1.06,104.94]],"batl":[[0,1.06,1.98]],"ltp":1.06,"tv":13925.15,"id":12343905}],"tv":18656.35}]}
{"op":"mcm","clk":"4232078334","pt":1631551549166,"mc":[{"id":"1.187560634","rc":[{"batl":[[1,1.12,234.91]],"ltp":1.06,"tv":13925.15,"id":12343905}]}]}
{"op":"mcm","clk":"4232078421","pt":1631551550269,"mc":[{"id":"1.187560634","rc":[{"batl":[[1,1.11,6.1],[2,1.12,234.91]],"ltp":1.06,"tv":13925.15,"id":12343905}]}]}
{"op":"mcm","clk":"4232078519","pt":1631551551569,"mc":[{"id":"1.187560634","rc":[{"trd":[[1.06,105.1]],"batl":[[0,1.06,1.9],[2,1.12,241.01]],"ltp":1.06,"tv":13925.31,"id":12343905}],"tv":18656.51}]}
{"op":"mcm","clk":"4232078606","pt":1631551552678,"mc":[{"id":"1.187560634","rc":[{"trd":[[1.06,105.26]],"batl":[[0,1.06,1.82]],"ltp":1.06,"tv":13925.47,"id":12343905}],"tv":18656.67}]}
{"op":"mcm","clk":"4232078693","pt":1631551553866,"mc":[{"id":"1.187560634","rc":[{"batl":[[2,1.12,12.2]],"ltp":1.06,"tv":13925.47,"id":12343905}]}]}
{"op":"mcm","clk":"4232078806","pt":1631551555125,"mc":[{"id":"1.187560634","marketDefinition":{"bspMarket":false,"turnInPlayEnabled":true,"persistenceEnabled":true,"marketBaseRate":5.0,"eventId":"30896276","eventTypeId":"2","numberOfWinners":1,"bettingType":"ODDS","marketType":"MATCH_ODDS","marketTime":"2021-09-13T14:55:00.000Z","suspendTime":"2021-09-13T14:55:00.000Z","bspReconciled":false,"complete":true,"inPlay":true,"crossMatching":true,"runnersVoidable":false,"numberOfActiveRunners":2,"betDelay":3,"status":"SUSPENDED","runners":[{"status":"ACTIVE","sortPriority":1,"id":9629296,"name":"Gijs Brouwer"},{"status":"ACTIVE","sortPriority":2,"id":12343905,"name":"Rinky Hijikata"}],"regulators":["MR_INT"],"countryCode":"US","discountAllowed":true,"timezone":"UTC","openDate":"2021-09-13T14:55:00.000Z","version":4030940899,"name":"Match Odds","eventName":"Brouwer v Ri Hijikata"},"rc":[{"batb":[[0,1.9,3],[1,1.01,105.79],[2,1.01,0]],"ltp":15.0,"tv":4731.2,"id":9629296},{"batl":[[1,1.12,12.2],[2,1.13,12.2]],"ltp":1.06,"tv":13925.47,"id":12343905}]}]}
{"op":"mcm","clk":"4232078997","pt":1631551557263,"mc":[{"id":"1.187560634","rc":[{"batl":[[1,1.66,2.88],[2,3,5.2]],"ltp":1.06,"tv":13925.47,"id":12343905}]}]}
{"op":"mcm","clk":"4232082226","pt":1631551600095,"mc":[{"id":"1.187560634","tv":0.0}]}
{"op":"mcm","clk":"4232082441","pt":1631551603081,"mc":[{"id":"1.187560634","marketDefinition":{"bspMarket":false,"turnInPlayEnabled":true,"persistenceEnabled":true,"marketBaseRate":5.0,"eventId":"30896276","eventTypeId":"2","numberOfWinners":1,"bettingType":"ODDS","marketType":"MATCH_ODDS","marketTime":"2021-09-13T14:55:00.000Z","suspendTime":"2021-09-13T14:55:00.000Z","bspReconciled":false,"complete":true,"inPlay":true,"crossMatching":false,"runnersVoidable":false,"numberOfActiveRunners":0,"betDelay":3,"status":"CLOSED","settledTime":"2021-09-13T16:46:33.000Z","runners":[{"status":"LOSER","sortPriority":1,"id":9629296,"name":"Gijs Brouwer"},{"status":"WINNER","sortPriority":2,"id":12343905,"name":"Rinky Hijikata"}],"regulators":["MR_INT"],"countryCode":"US","discountAllowed":true,"timezone":"UTC","openDate":"2021-09-13T14:55:00.000Z","version":4030942155,"name":"Match Odds","eventName":"Brouwer v Ri Hijikata"}}]}
