{"op":"mcm","clk":"4233790008","pt":1631538817910,"mc":[{"id":"1.187557653","rc":[{"batl":[[0,2.46,9.7],[1,2.54,3.94]],"ltp":2.42,"tv":4419.08,"id":9632596},{"batb":[[0,1.68,246.88]],"batl":[[2,1.72,11.03]],"ltp":1.69,"tv":5705.07,"id":9433864}]}]}
{"op":"mcm","clk":"4233790793","pt":1631538824097,"mc":[{"id":"1.187557653","rc":[{"trd":[[2.44,0.54]],"ltp":2.44,"tv":4419.62,"id":9632596},{"trd":[[1.69,746.43]],"batl":[[0,1.69,41.5]],"ltp":1.69,"tv":5705.85,"id":9433864}],"tv":10125.48}]}
{"op":"mcm","clk":"4233792135","pt":1631538837304,"mc":[{"id":"1.187557653","rc":[{"trd":[[1.69,774.3]],"batl":[[0,1.69,27.56]],"ltp":1.69,"tv":5733.72,"id":9433864}],"tv":10153.35}]}
{"op":"mcm","clk":"4233793532","pt":1631538851032,"mc":[{"id":"1.187557653","rc":[{"trd":[[2.46,11.96]],"batl":[[0,2.46,3.72]],"ltp":2.46,"tv":4431.58,"id":9632596}],"tv":10165.31}]}
{"op":"mcm","clk":"4233793732","pt":1631538853172,"mc":[{"id":"1.187557653","rc":[{"batl":[[1,1.72,11.03],[2,1.76,1.16]],"ltp":1.69,"tv":5733.72,"id":9433864}]}]}
{"op":"mcm","clk":"4233793922","pt":1631538854947,"mc":[{"id":"1.187557653","rc":[{"batl":[[0,1.72,11.03],[1,1.76,1.16],[2,1.78,73.04]],"ltp":1.69,"tv":5733.72,"id":9433864}]}]}
{"op":"mcm","clk":"4233794049","pt":1631538856141,"mc":[{"id":"1.187557653","rc":[{"batb":[[0,1.69,6.97],[1,1.68,246.88],[2,1.67,8.88]],"ltp":1.69,"tv":5733.72,"id":9433864}]}]}
{"op":"mcm","clk":"4233794314","pt":1631538858172,"mc":[{"id":"1.187557653","rc":[{"trd":[[1.68,29.05],[1.69,788.24]],"batb":[[0,1.68,243.85],[1,1.67,8.88],[2,1.57,49.36]],"ltp":1.68,"tv":5753.72,"id":9433864}],"tv":10185.3}]}
{"op":"mcm","clk":"4233794640","pt":1631538861287,"mc":[{"id":"1.187557653","rc":[{"batl":[[0,2.54,3.94],[1,2.54,0]],"ltp":2.46,"tv":4431.58,"id":9632596},{"batl":[[0,1.76,1.16],[1,1.78,73.04],[2,1.92,215.66]],"ltp":1.68,"tv":5753.72,"id":9433864}]}]}
{"op":"mcm","clk":"4233794667","pt":1631538861598,"mc":[{"id":"1.187557653","rc":[{"batb":[[0,1.68,5.85]],"ltp":1.68,"tv":5753.72,"id":9433864}]}]}
{"op":"mcm","clk":"4233794818","pt":1631538863055,"mc":[{"id":"1.187557653","rc":[{"batb":[[0,1.68,6.22]],"ltp":1.68,"tv":5753.72,"id":9433864}]}]}
{"op":"mcm","clk":"4233794921","pt":1631538864199,"mc":[{"id":"1.187557653","rc":[{"batb":[[0,2.42,6.08],[1,2.3,13.04],[2,2.28,6.52]],"ltp":2.46,"tv":4431.58,"id":9632596},{"batb":[[0,1.68,15.37]],"ltp":1.68,"tv":5753.72,"id":9433864}]}]}
{"op":"mcm","clk":"4233795342","pt":1631538868679,"mc":[{"id":"1.187557653","rc":[{"batb":[[0,1.68,15]],"ltp":1.68,"tv":5753.72,"id":9433864}]}]}
{"op":"mcm","clk":"4233795998","pt":1631538875196,"mc":[{"id":"1.187557653","rc":[{"trd":[[2.42,12.24]],"batb":[[0,2.42,5.82]],"ltp":2.42,"tv":4431.84,"id":9632596},{"trd":[[1.71,224.84]],"ltp":1.71,"tv":5754.09,"id":9433864}],"tv":10185.93}]}
{"op":"mcm","clk":"4233796798","pt":1631538883935,"mc":[{"id":"1.187557653","rc":[{"batb":[[0,1.9,27.77],[1,1.85,36.57],[2,1.01,113.68]],"ltp":2.42,"tv":4431.84,"id":9632596},{"batb":[[0,1.57,49.36],[1,1.46,2],[2,1.23,2]],"batl":[[1,2.02,2.13],[2,2.18,7.25]],"ltp":1.71,"tv":5754.09,"id":9433864}]}]}
{"op":"mcm","clk":"4233796938","pt":1631538885504,"mc":[{"id":"1.187557653","rc":[{"batb":[[0,1.71,6.97],[1,1.57,49.36],[2,1.46,2]],"ltp":1.71,"tv":5754.09,"id":9433864}]}]}
{"op":"mcm","clk":"4233797082","pt":1631538887201,"mc":[{"id":"1.187557653","rc":[{"batb":[[0,1.91,27.27]],"ltp":2.42,"tv":4431.84,"id":9632596},{"batb":[[1,1.56,51.12]],"ltp":1.71,"tv":5754.09,"id":9433864}]}]}
{"op":"mcm","clk":"4233797809","pt":1631538895251,"mc":[{"id":"1.187557653","rc":[{"batb":[[0,1.95,35.51],[1,1.91,27.27],[2,1.85,36.57]],"ltp":2.42,"tv":4431.84,"id":9632596},{"batl":[[2,2.06,7.25]],"ltp":1.71,"tv":5754.09,"id":9433864}]}]}
{"op":"mcm","clk":"4233797840","pt":1631538895514,"mc":[{"id":"1.187557653","rc":[{"batb":[[0,1.91,27.27],[1,1.85,36.57],[2,1.01,113.68]],"ltp":2.42,"tv":4431.84,"id":9632596},{"batl":[[2,2.18,7.25]],"ltp":1.71,"tv":5754.09,"id":9433864}]}]}
{"op":"mcm","clk":"4233798022","pt":1631538897444,"mc":[{"id":"1.187557653","rc":[{"trd":[[1.71,238.77]],"batb":[[0,1.56,51.12],[1,1.46,2],[2,1.23,2]],"batl":[[0,1.64,447.61],[1,1.76,1.16],[2,2.02,2.13]],"ltp":1.71,"tv":5768.02,"id":9433864}],"tv":10199.87}]}
{"op":"mcm","clk":"4233798206","pt":1631538899046,"mc":[{"id":"1.187557653","rc":[{"batb":[[0,1.95,37.51],[1,1.91,27.27],[2,1.85,36.57]],"ltp":2.42,"tv":4431.84,"id":9632596}]}]}
{"op":"mcm","clk":"4233799263","pt":1631538909271,"mc":[{"id":"1.187557653","rc":[{"batb":[[0,2.62,76.34],[1,2.54,59.06],[2,2.52,29.54]],"batl":[[0,2.72,97.06],[1,2.78,10.67]],"ltp":2.42,"tv":4431.84,"id":9632596},{"batl":[[0,1.6,17.06],[1,1.64,447.61],[2,1.67,5.99]],"ltp":1.71,"tv":5768.02,"id":9433864}]}]}
{"op":"mcm","clk":"4233799360","pt":1631538910262,"mc":[{"id":"1.187557653","rc":[{"trd":[[2.62,15.26]],"batb":[[0,2.54,59.06],[1,2.52,29.54],[2,2.5,44.26]],"batl":[[1,2.78,14.27]],"ltp":2.62,"tv":4447.1,"id":9632596},{"trd":[[1.6,40.37],[1.62,90.3],[1.64,90.33]],"batb":[[0,1.61,33.72],[1,1.59,17.08],[2,1.56,51.12]],"batl":[[0,1.64,434.53],[1,1.66,57.25]],"ltp":1.64,"tv":5852.99,"id":9433864}],"tv":10300.1}]}
{"op":"mcm","clk":"4233799411","pt":1631538911083,"mc":[{"id":"1.187557653","rc":[{"batb":[[0,2.54,35.44],[1,2.52,17.72],[2,2.5,32.44]],"ltp":2.62,"tv":4447.1,"id":9632596},{"trd":[[1.64,195.73]],"batl":[[0,1.64,381.83]],"ltp":1.64,"tv":5958.39,"id":9433864}],"tv":10405.5}]}
{"op":"mcm","clk":"4233800284","pt":1631538919711,"mc":[{"id":"1.187557653","rc":[{"batl":[[1,2.78,3.6]],"ltp":2.62,"tv":4447.1,"id":9632596}]}]}
{"op":"mcm","clk":"4233800358","pt":1631538920601,"mc":[{"id":"1.187557653","rc":[{"batl":[[0,1.66,57.25],[1,1.67,5.99],[2,1.68,133.78]],"ltp":1.64,"tv":5958.39,"id":9433864}]}]}
{"op":"mcm","clk":"4233800547","pt":1631538922593,"mc":[{"id":"1.187557653","rc":[{"batl":[[0,2.72,107.05]],"ltp":2.62,"tv":4447.1,"id":9632596},{"batl":[[0,1.62,17.33],[1,1.66,57.25],[2,1.67,5.99]],"ltp":1.64,"tv":5958.39,"id":9433864}]}]}
{"op":"mcm","clk":"4233801664","pt":1631538933112,"mc":[{"id":"1.187557653","rc":[{"batb":[[0,2.2,6.97],[1,2.14,38.65],[2,1.01,113.68]],"ltp":2.62,"tv":4447.1,"id":9632596},{"batb":[[0,1.47,64.08],[1,1.46,2],[2,1.23,2]],"batl":[[0,1.76,1.16],[1,2.02,2.13],[2,1.67,0]],"ltp":1.64,"tv":5958.39,"id":9433864}]}]}
{"op":"mcm","clk":"4233801691","pt":1631538933320,"mc":[{"id":"1.187557653","rc":[{"batb":[[1,2.14,38.32]],"ltp":2.62,"tv":4447.1,"id":9632596}]}]}
{"op":"mcm","clk":"4233802073","pt":1631538936111,"mc":[{"id":"1.187557653","rc":[{"batb":[[0,2.28,6.66],[1,2.2,6.97],[2,2.14,38.32]],"ltp":2.62,"tv":4447.1,"id":9632596},{"batl":[[1,1.77,43.5],[2,1.82,44.75]],"ltp":1.64,"tv":5958.39,"id":9433864}]}]}
{"op":"mcm","clk":"4233802129","pt":1631538936531,"mc":[{"id":"1.187557653","rc":[{"batb":[[0,2.2,6.97],[1,2.14,38.32],[2,1.01,113.68]],"ltp":2.62,"tv":4447.1,"id":9632596},{"batl":[[1,1.82,44.75],[2,2.02,2.13]],"ltp":1.64,"tv":5958.39,"id":9433864}]}]}
{"op":"mcm","clk":"4233802611","pt":1631538940921,"mc":[{"id":"1.187557653","rc":[{"trd":[[2.32,6.91]],"batb":[[2,1.99,27.29]],"batl":[[0,2.38,37.82],[1,2.4,18.91],[2,2.42,18.91]],"ltp":2.32,"tv":4453.21,"id":9632596},{"trd":[[1.76,112.09]],"batb":[[0,1.76,21.63],[1,1.74,15.6],[2,1.73,69.36]],"batl":[[0,1.82,44.75],[1,1.86,162.37]],"ltp":1.76,"tv":5968.77,"id":9433864}],"tv":10421.98}]}
{"op":"mcm","clk":"4233802741","pt":1631538942130,"mc":[{"id":"1.187557653","rc":[{"batb":[[0,2.24,13.4],[1,2.22,6.7],[2,2.2,13.67]],"batl":[[0,2.38,12.6],[1,2.4,6.3],[2,2.42,6.3]],"ltp":2.32,"tv":4453.21,"id":9632596},{"batl":[[0,1.81,5.52],[1,1.82,44.75],[2,1.86,162.37]],"ltp":1.76,"tv":5968.77,"id":9433864}]}]}
{"op":"mcm","clk":"4233803964","pt":1631538954042,"mc":[{"id":"1.187557653","rc":[{"trd":[[1.76,139.75]],"batb":[[0,1.76,7.8],[1,1.74,27.11]],"batl":[[0,1.78,13.93],[1,1.81,5.52],[2,1.82,44.75]],"ltp":1.76,"tv":5996.43,"id":9433864}],"tv":10449.64}]}
{"op":"mcm","clk":"4233804224","pt":1631538956283,"mc":[{"id":"1.187557653","rc":[{"trd":[[2.38,12.6],[2.4,148.82],[2.42,18.54],[2.46,16.03]],"batl":[[0,2.78,566.21],[1,2.4,0],[2,2.42,0]],"ltp":2.46,"tv":4482.48,"id":9632596},{"trd":[[1.68,35.01],[1.7,1041.14],[1.71,247.61],[1.72,97.11],[1.73,196.5],[1.74,144.89],[1.76,155.36]],"batb":[[0,1.57,50.45],[1,1.55,391.98],[2,1.46,2]],"batl":[[0,1.62,199.88],[1,1.78,13.93],[2,1.81,5.52]],"ltp":1.68,"tv":6318.64,"id":9433864}],"tv":10801.12}]}
{"op":"mcm","clk":"4233804264","pt":1631538956651,"mc":[{"id":"1.187557653","rc":[{"batb":[[2,2.2,6.7]],"ltp":2.46,"tv":4482.48,"id":9632596}]}]}
{"op":"mcm","clk":"4233804604","pt":1631538959689,"mc":[{"id":"1.187557653","rc":[{"trd":[[1.62,490.05]],"batl":[[0,1.78,13.93],[1,1.81,5.52],[2,1.82,44.75]],"ltp":1.62,"tv":6718.39,"id":9433864}],"tv":11200.88}]}
{"op":"mcm","clk":"4233804770","pt":1631538961156,"mc":[{"id":"1.187557653","rc":[{"batb":[[0,1.62,10.06],[1,1.57,50.45],[2,1.55,391.98]],"ltp":1.62,"tv":6718.39,"id":9433864}]}]}
{"op":"mcm","clk":"4233804913","pt":1631538962258,"mc":[{"id":"1.187557653","rc":[{"batb":[[0,2.14,38.32],[1,1.99,27.29],[2,1.97,13.78]],"ltp":2.46,"tv":4482.48,"id":9632596},{"batb":[[0,1.57,50.45],[1,1.55,391.98],[2,1.46,2]],"batl":[[1,1.82,44.75],[2,1.86,162.37]],"ltp":1.62,"tv":6718.39,"id":9433864}]}]}
{"op":"mcm","clk":"4233805035","pt":1631538963193,"mc":[{"id":"1.187557653","rc":[{"batb":[[0,1.83,31.12],[1,1.8,38.98],[2,1.01,113.68]],"ltp":2.46,"tv":4482.48,"id":9632596},{"batl":[[0,2.02,2.13],[1,2.42,312.67],[2,1.86,0]],"ltp":1.62,"tv":6718.39,"id":9433864}]}]}
{"op":"mcm","clk":"4233805491","pt":1631538966108,"mc":[{"id":"1.187557653","rc":[{"batb":[[0,1.84,30.54]],"ltp":2.46,"tv":4482.48,"id":9632596},{"batb":[[0,1.56,51.28]],"ltp":1.62,"tv":6718.39,"id":9433864}]}]}
{"op":"mcm","clk":"4233806872","pt":1631538975511,"mc":[{"id":"1.187557653","rc":[{"batb":[[1,1.46,2],[2,1.23,2]],"batl":[[1,2.42,0]],"ltp":1.62,"tv":6718.39,"id":9433864}]}]}
{"op":"mcm","clk":"4233807075","pt":1631538976929,"mc":[{"id":"1.187557653","rc":[{"batb":[[0,2.48,48.38],[1,2.46,93.48],[2,1.84,30.54]],"batl":[[0,2.72,105.95]],"ltp":2.46,"tv":4482.48,"id":9632596},{"batb":[[0,1.6,33.93],[1,1.58,17.18],[2,1.56,51.28]],"batl":[[0,1.62,19.31],[1,1.67,5.99],[2,1.71,52.63]],"ltp":1.62,"tv":6718.39,"id":9433864}]}]}
{"op":"mcm","clk":"4233807229","pt":1631538978035,"mc":[{"id":"1.187557653","rc":[{"batb":[[1,2.46,119.5],[2,2.1,40.49]],"batl":[[1,2.78,3.6],[2,2.96,10.14]],"ltp":2.46,"tv":4482.48,"id":9632596},{"batl":[[2,1.71,17.54]],"ltp":1.62,"tv":6718.39,"id":9433864}]}]}
{"op":"mcm","clk":"4233807960","pt":1631538983308,"mc":[{"id":"1.187557653","rc":[{"batb":[[2,2.28,6.91]],"ltp":2.46,"tv":4482.48,"id":9632596}]}]}
{"op":"mcm","clk":"4233810136","pt":1631539001264,"mc":[{"id":"1.187557653","rc":[{"batb":[[0,2.46,119.5],[1,2.28,6.91],[2,2.18,7.36]],"batl":[[1,2.78,0],[2,2.96,0]],"ltp":2.46,"tv":4482.48,"id":9632596},{"batl":[[1,1.78,42.25],[2,1.8,30.17]],"ltp":1.62,"tv":6718.39,"id":9433864}]}]}
{"op":"mcm","clk":"4233810227","pt":1631539001945,"mc":[{"id":"1.187557653","rc":[{"batb":[[0,2.18,7.36],[1,2.1,40.49],[2,1.01,113.68]],"ltp":2.46,"tv":4482.48,"id":9632596},{"batb":[[0,1.46,68.84],[1,1.44,405.06],[2,1.23,2]],"batl":[[0,1.84,39.28],[1,2.02,2.13],[2,2.16,372.36]],"ltp":1.62,"tv":6718.39,"id":9433864}]}]}
{"op":"mcm","clk":"4233811849","pt":1631539015255,"mc":[{"id":"1.187557653","rc":[{"batb":[[0,2.52,20.49],[1,2.28,6.91],[2,2.18,7.36]],"batl":[[0,2.68,21.64]],"ltp":2.46,"tv":4482.48,"id":9632596},{"batl":[[0,1.65,20.5],[1,1.78,40.25],[2,1.84,39.28]],"ltp":1.62,"tv":6718.39,"id":9433864}]}]}
{"op":"mcm","clk":"4233811878","pt":1631539015463,"mc":[{"id":"1.187557653","rc":[{"batb":[[0,2.18,7.36],[1,2.1,40.49],[2,1.01,113.68]],"ltp":2.46,"tv":4482.48,"id":9632596},{"batl":[[0,1.84,39.28],[1,2.02,2.13],[2,2.16,372.36]],"ltp":1.62,"tv":6718.39,"id":9433864}]}]}
{"op":"mcm","clk":"4233812707","pt":1631539022283,"mc":[{"id":"1.187557653","rc":[{"batb":[[0,2.28,7.16],[1,2.18,7.36],[2,2.1,40.49]],"ltp":2.46,"tv":4482.48,"id":9632596},{"batl":[[0,1.78,44.25],[1,1.84,39.28],[2,2.02,2.13]],"ltp":1.62,"tv":6718.39,"id":9433864}]}]}
{"op":"mcm","clk":"4233812734","pt":1631539022492,"mc":[{"id":"1.187557653","rc":[{"batb":[[0,2.18,7.36],[1,2.1,40.49],[2,1.01,113.68]],"ltp":2.46,"tv":4482.48,"id":9632596},{"batl":[[0,1.84,39.28],[1,2.02,2.13],[2,2.16,372.36]],"ltp":1.62,"tv":6718.39,"id":9433864}]}]}
{"op":"mcm","clk":"4233813524","pt":1631539029101,"mc":[{"id":"1.187557653","rc":[{"batb":[[0,2.28,7.16],[1,2.18,7.36],[2,2.1,40.49]],"ltp":2.46,"tv":4482.48,"id":9632596},{"batb":[[1,1.23,2],[2,1.19,1]],"batl":[[0,1.78,43.75],[1,1.84,39.28],[2,2.02,2.13]],"ltp":1.62,"tv":6718.39,"id":9433864}]}]}
{"op":"mcm","clk":"4233813677","pt":1631539030087,"mc":[{"id":"1.187557653","rc":[{"batb":[[0,2.88,11.71],[1,2.82,53.2],[2,2.8,26.6]],"batl":[[0,3.05,106.13]],"ltp":2.46,"tv":4482.48,"id":9632596},{"batb":[[0,1.51,35.96],[1,1.49,18.22],[2,1.46,68.84]],"batl":[[0,1.52,18.72],[1,1.53,65.5],[2,1.58,181.19]],"ltp":1.62,"tv":6718.39,"id":9433864}]}]}
{"op":"mcm","clk":"4233813815","pt":1631539031091,"mc":[{"id":"1.187557653","rc":[{"batb":[[1,2.82,31.92],[2,2.8,15.96]],"batl":[[1,3.1,3.23]],"ltp":2.46,"tv":4482.48,"id":9632596},{"batb":[[1,1.49,38.36],[2,1.48,10.06]],"ltp":1.62,"tv":6718.39,"id":9433864}]}]}
{"op":"mcm","clk":"4233814677","pt":1631539038790,"mc":[{"id":"1.187557653","rc":[{"trd":[[1.49,35.9],[1.51,81.54]],"batb":[[0,1.49,22.63],[1,1.48,10.06],[2,1.47,10.06]],"ltp":1.49,"tv":6821.77,"id":9433864}],"tv":11304.26}]}
{"op":"mcm","clk":"4233815218","pt":1631539043299,"mc":[{"id":"1.187557653","rc":[{"trd":[[1.52,20.52]],"batl":[[0,1.52,18.25]],"ltp":1.52,"tv":6822.71,"id":9433864}],"tv":11305.2}]}
{"op":"mcm","clk":"4233816338","pt":1631539053204,"mc":[{"id":"1.187557653","rc":[{"batb":[[0,2.78,18.91],[1,2.6,5.54],[2,2.48,25.27]],"ltp":2.46,"tv":4482.48,"id":9632596},{"batb":[[0,1.46,68.84],[1,1.4,79.89],[2,1.38,415.78]],"batl":[[0,1.62,53.75],[1,2.02,2.13],[2,2.04,414.74]],"ltp":1.52,"tv":6822.71,"id":9433864}]}]}
{"op":"mcm","clk":"4233816366","pt":1631539053412,"mc":[{"id":"1.187557653","rc":[{"batb":[[0,2.6,5.54],[1,2.48,25.27],[2,1.01,113.68]],"ltp":2.46,"tv":4482.48,"id":9632596},{"batb":[[0,1.46,2]],"ltp":1.52,"tv":6822.71,"id":9433864}]}]}
{"op":"mcm","clk":"4233816651","pt":1631539056145,"mc":[{"id":"1.187557653","rc":[{"batl":[[0,5,287.39]],"ltp":2.46,"tv":4482.48,"id":9632596}]}]}
{"op":"mcm","clk":"4233816849","pt":1631539058242,"mc":[{"id":"1.187557653","rc":[{"batb":[[0,2.92,20.19],[1,2.6,5.54],[2,2.48,25.27]],"batl":[[0,3,20.99]],"ltp":2.46,"tv":4482.48,"id":9632596},{"batl":[[0,1.52,21.51],[1,1.62,53.75],[2,2.02,2.13]],"ltp":1.52,"tv":6822.71,"id":9433864}]}]}
{"op":"mcm","clk":"4233816890","pt":1631539058523,"mc":[{"id":"1.187557653","rc":[{"batb":[[0,2.6,5.54],[1,2.48,25.27],[2,1.01,113.68]],"ltp":2.46,"tv":4482.48,"id":9632596},{"batl":[[0,1.62,53.75],[1,2.02,2.13],[2,2.04,414.74]],"ltp":1.52,"tv":6822.71,"id":9433864}]}]}
{"op":"mcm","clk":"4233817046","pt":1631539060042,"mc":[{"id":"1.187557653","rc":[{"batb":[[0,2.68,5.61],[1,2.6,5.54],[2,2.48,25.27]],"ltp":2.46,"tv":4482.48,"id":9632596},{"batl":[[0,1.59,49.5],[1,1.62,53.75],[2,2.02,2.13]],"ltp":1.52,"tv":6822.71,"id":9433864}]}]}
{"op":"mcm","clk":"4233817095","pt":1631539060354,"mc":[{"id":"1.187557653","rc":[{"batb":[[0,2.6,5.54],[1,2.48,25.27],[2,1.01,113.68]],"ltp":2.46,"tv":4482.48,"id":9632596},{"batl":[[0,1.62,53.75],[1,2.02,2.13],[2,2.04,414.74]],"ltp":1.52,"tv":6822.71,"id":9433864}]}]}
{"op":"mcm","clk":"4233817767","pt":1631539067138,"mc":[{"id":"1.187557653","rc":[{"batb":[[0,2.68,4.86],[1,2.6,5.54],[2,2.48,25.27]],"ltp":2.46,"tv":4482.48,"id":9632596},{"batl":[[0,1.59,48.5],[1,1.62,53.75],[2,2.02,2.13]],"ltp":1.52,"tv":6822.71,"id":9433864}]}]}
{"op":"mcm","clk":"4233817795","pt":1631539067443,"mc":[{"id":"1.187557653","rc":[{"batb":[[0,2.6,5.54],[1,2.48,25.27],[2,1.01,113.68]],"ltp":2.46,"tv":4482.48,"id":9632596},{"batl":[[0,1.62,53.75],[1,2.02,2.13],[2,2.04,414.74]],"ltp":1.52,"tv":6822.71,"id":9433864}]}]}
{"op":"mcm","clk":"4233818971","pt":1631539078277,"mc":[{"id":"1.187557653","rc":[{"batb":[[0,2.68,5.36],[1,2.6,5.54],[2,2.48,25.27]],"ltp":2.46,"tv":4482.48,"id":9632596},{"batl":[[0,1.59,56.5],[1,1.62,53.75],[2,2.02,2.13]],"ltp":1.52,"tv":6822.71,"id":9433864}]}]}
{"op":"mcm","clk":"4233819003","pt":1631539078591,"mc":[{"id":"1.187557653","rc":[{"batb":[[0,2.6,5.54],[1,2.48,25.27],[2,1.01,113.68]],"ltp":2.46,"tv":4482.48,"id":9632596},{"batl":[[0,1.62,53.75],[1,2.02,2.13],[2,2.04,414.74]],"ltp":1.52,"tv":6822.71,"id":9433864}]}]}
{"op":"mcm","clk":"4233819690","pt":1631539084204,"mc":[{"id":"1.187557653","rc":[{"batb":[[0,3,48.5],[1,2.98,67.12],[2,2.6,28.21]],"batl":[[0,3.2,70.2]],"ltp":2.46,"tv":4482.48,"id":9632596},{"batb":[[1,1.45,12.8],[2,1.44,37.7]],"batl":[[0,1.47,13.03],[1,1.49,83.64],[2,1.5,10.06]],"ltp":1.52,"tv":6822.71,"id":9433864}]}]}
{"op":"mcm","clk":"4233819756","pt":1631539084676,"mc":[{"id":"1.187557653","rc":[{"batl":[[1,3.25,3.08],[2,3.3,9.08]],"ltp":2.46,"tv":4482.48,"id":9632596}]}]}
{"op":"mcm","clk":"4233820405","pt":1631539090693,"mc":[{"id":"1.187557653","rc":[{"batb":[[2,2.66,5.31]],"ltp":2.46,"tv":4482.48,"id":9632596}]}]}
{"op":"mcm","clk":"4233820638","pt":1631539093023,"mc":[{"id":"1.187557653","rc":[{"trd":[[1.47,9.56]],"batl":[[0,1.47,8.25]],"ltp":1.47,"tv":6832.27,"id":9433864}],"tv":11314.75}]}
{"op":"mcm","clk":"4233821036","pt":1631539096824,"mc":[{"id":"1.187557653","rc":[{"trd":[[1.47,26.06]],"batb":[[0,1.47,9.64],[1,1.46,2],[2,1.45,12.8]],"batl":[[0,1.49,83.64],[1,1.5,10.06],[2,1.51,10.06]],"ltp":1.47,"tv":6848.77,"id":9433864}],"tv":11331.25}]}
{"op":"mcm","clk":"4233821658","pt":1631539103235,"mc":[{"id":"1.187557653","rc":[{"batb":[[2,1.44,37.7]],"ltp":1.47,"tv":6848.77,"id":9433864}]}]}
{"op":"mcm","clk":"4233821940","pt":1631539106139,"mc":[{"id":"1.187557653","rc":[{"trd":[[1.49,41.85]],"batb":[[1,1.46,14.73]],"batl":[[0,1.48,12.2],[1,1.49,80.67],[2,1.5,10.06]],"ltp":1.49,"tv":6854.71,"id":9433864}],"tv":11337.2}]}
{"op":"mcm","clk":"4233822047","pt":1631539107036,"mc":[{"id":"1.187557653","rc":[{"batb":[[1,1.46,2]],"batl":[[0,1.49,80.67],[1,1.5,10.06],[2,1.51,10.06]],"ltp":1.49,"tv":6854.71,"id":9433864}]}]}
{"op":"mcm","clk":"4233822164","pt":1631539108246,"mc":[{"id":"1.187557653","rc":[{"trd":[[1.47,27.45],[1.49,81.85]],"batb":[[0,1.47,8.94]],"batl":[[0,1.49,60.67]],"ltp":1.47,"tv":6896.1,"id":9433864}],"tv":11378.59}]}
{"op":"mcm","clk":"4233822380","pt":1631539109934,"mc":[{"id":"1.187557653","rc":[{"batb":[[1,1.46,14.73]],"batl":[[0,1.48,12.2],[1,1.49,60.67],[2,1.5,10.06]],"ltp":1.47,"tv":6896.1,"id":9433864}]}]}
{"op":"mcm","clk":"4233822672","pt":1631539112652,"mc":[{"id":"1.187557653","rc":[{"trd":[[1.48,2.14]],"batl":[[0,1.48,11.13]],"ltp":1.48,"tv":6898.24,"id":9433864}],"tv":11380.73}]}
{"op":"mcm","clk":"4233823628","pt":1631539120848,"mc":[{"id":"1.187557653","rc":[{"batb":[[2,1.4,79.89]],"ltp":1.48,"tv":6898.24,"id":9433864}]}]}
{"op":"mcm","clk":"4233823874","pt":1631539122867,"mc":[{"id":"1.187557653","rc":[{"batb":[[1,1.46,2]],"batl":[[0,1.49,60.67],[1,1.5,10.06],[2,1.51,10.06]],"ltp":1.48,"tv":6898.24,"id":9433864}]}]}
{"op":"mcm","clk":"4233824183","pt":1631539125889,"mc":[{"id":"1.187557653","rc":[{"batb":[[1,1.46,15.82]],"batl":[[0,1.48,11.13],[1,1.49,60.67],[2,1.5,10.06]],"ltp":1.48,"tv":6898.24,"id":9433864}]}]}
{"op":"mcm","clk":"4233826433","pt":1631539145090,"mc":[{"id":"1.187557653","rc":[{"batb":[[0,2.6,22.67],[1,2.56,5.08],[2,1.01,113.68]],"ltp":2.46,"tv":4482.48,"id":9632596},{"batb":[[1,1.46,2],[2,1.38,415.78]],"batl":[[0,1.64,47.43],[1,2.02,2.13],[2,2.04,414.74]],"ltp":1.48,"tv":6898.24,"id":9433864}]}]}
{"op":"mcm","clk":"4233827162","pt":1631539152213,"mc":[{"id":"1.187557653","rc":[{"batb":[[0,3.75,4.46],[1,3.7,9.62],[2,3.6,41.68]],"batl":[[0,4,77.44]],"ltp":2.46,"tv":4482.48,"id":9632596},{"trd":[[1.46,300.15],[1.47,45.33]],"batb":[[0,1.35,12.13],[1,1.29,115.03],[2,1.23,2]],"batl":[[0,1.37,78.5],[1,1.38,144.92],[2,1.41,239.32]],"ltp":1.46,"tv":6920.13,"id":9433864}],"tv":11402.61}]}
{"op":"mcm","clk":"4233827268","pt":1631539153212,"mc":[{"id":"1.187557653","rc":[{"batb":[[2,3.6,31.93]],"batl":[[0,4,117.44],[1,4.1,18.76],[2,4.2,18.76]],"ltp":2.46,"tv":4482.48,"id":9632596},{"batb":[[1,1.33,40.82],[2,1.31,20.72]],"ltp":1.46,"tv":6920.13,"id":9433864}]}]}
{"op":"mcm","clk":"4233827290","pt":1631539153418,"mc":[{"id":"1.187557653","rc":[{"batl":[[0,4,87.44],[1,4.1,3.76],[2,4.2,3.76]],"ltp":2.46,"tv":4482.48,"id":9632596}]}]}
{"op":"mcm","clk":"4233828336","pt":1631539162203,"mc":[{"id":"1.187557653","rc":[{"batb":[[0,3.7,9.62],[1,3.6,23.59],[2,3.05,4.69]],"ltp":2.46,"tv":4482.48,"id":9632596},{"batb":[[0,1.33,40.82],[1,1.31,20.72],[2,1.29,115.03]],"batl":[[1,1.47,36.94],[2,1.48,53.24]],"ltp":1.46,"tv":6920.13,"id":9433864}]}]}
{"op":"mcm","clk":"4233828399","pt":1631539162722,"mc":[{"id":"1.187557653","rc":[{"batb":[[0,3,37.81],[1,2.92,4.44],[2,1.01,113.68]],"ltp":2.46,"tv":4482.48,"id":9632596},{"batb":[[0,1.23,2],[1,1.2,176.27],[2,1.19,1]],"batl":[[0,1.52,49.51],[1,2.02,2.13],[2,1.48,0]],"ltp":1.46,"tv":6920.13,"id":9433864}]}]}
{"op":"mcm","clk":"4233828925","pt":1631539168126,"mc":[{"id":"1.187557653","rc":[{"batb":[[0,1.23,2.08]],"ltp":1.46,"tv":6920.13,"id":9433864}]}]}
{"op":"mcm","clk":"4233829042","pt":1631539169228,"mc":[{"id":"1.187557653","rc":[{"batb":[[0,3.05,3.89],[1,3,37.81],[2,2.92,4.44]],"ltp":2.46,"tv":4482.48,"id":9632596},{"batl":[[0,1.48,52.49],[1,1.52,49.51],[2,2.02,2.13]],"ltp":1.46,"tv":6920.13,"id":9433864}]}]}
{"op":"mcm","clk":"4233829075","pt":1631539169536,"mc":[{"id":"1.187557653","rc":[{"batb":[[0,3,37.81],[1,2.92,4.44],[2,1.01,113.68]],"ltp":2.46,"tv":4482.48,"id":9632596},{"batl":[[0,1.52,49.51],[1,2.02,2.13],[2,2.02,0]],"ltp":1.46,"tv":6920.13,"id":9433864}]}]}
{"op":"mcm","clk":"4233830212","pt":1631539180161,"mc":[{"id":"1.187557653","rc":[{"batb":[[0,3.05,3.69],[1,3,37.81],[2,2.92,4.44]],"batl":[[0,5.1,5.69],[1,5.3,64.02]],"ltp":2.46,"tv":4482.48,"id":9632596},{"trd":[[1.37,25.16]],"batb":[[0,1.23,2],[1,1.22,44.51],[2,1.2,198.89]],"batl":[[0,1.26,180.01],[1,1.27,23.62],[2,1.28,11.82]],"ltp":1.37,"tv":6920.29,"id":9433864}],"tv":11402.77}]}
{"op":"mcm","clk":"4233830321","pt":1631539181051,"mc":[{"id":"1.187557653","rc":[{"batb":[[0,4.6,25.85],[1,3.75,42.92],[2,3.05,3.69]],"batl":[[1,5.3,69.68],[2,5.4,2.84]],"ltp":2.46,"tv":4482.48,"id":9632596},{"batb":[[0,1.23,10.13]],"ltp":1.37,"tv":6920.29,"id":9433864}]}]}
{"op":"mcm","clk":"4233830779","pt":1631539185182,"mc":[{"id":"1.187557653","rc":[{"trd":[[5.1,2.43]],"batl":[[0,5.1,3.26]],"ltp":5.1,"tv":4484.91,"id":9632596},{"trd":[[1.24,42.92]],"ltp":1.24,"tv":6930.29,"id":9433864}],"tv":11415.2}]}
{"op":"mcm","clk":"4233831067","pt":1631539187971,"mc":[{"id":"1.187557653","rc":[{"batb":[[1,3.9,2.96],[2,3.75,42.92]],"ltp":5.1,"tv":4484.91,"id":9632596}]}]}
{"op":"mcm","clk":"4233831685","pt":1631539193192,"mc":[{"id":"1.187557653","rc":[{"batb":[[0,3.75,42.92],[1,3.7,3.02],[2,1.01,113.68]],"ltp":5.1,"tv":4484.91,"id":9632596},{"batb":[[0,1.23,2],[1,1.19,1],[2,1.18,511.37]],"batl":[[0,1.62,655.89],[1,2.02,2.13],[2,1.28,0]],"ltp":1.24,"tv":6930.29,"id":9433864}]}]}
{"op":"mcm","clk":"4233832016","pt":1631539196089,"mc":[{"id":"1.187557653","rc":[{"batb":[[0,3.9,3.16],[1,3.75,42.92],[2,3.7,3.02]],"ltp":5.1,"tv":4484.91,"id":9632596},{"batl":[[0,1.24,93],[1,1.34,75.75],[2,1.37,63.5]],"ltp":1.24,"tv":6930.29,"id":9433864}]}]}
{"op":"mcm","clk":"4233832113","pt":1631539197086,"mc":[{"id":"1.187557653","rc":[{"batb":[[0,3.75,42.92],[1,3.7,3.02],[2,1.01,113.68]],"ltp":5.1,"tv":4484.91,"id":9632596},{"batl":[[0,1.24,93.08],[1,1.37,63.5],[2,1.62,655.89]],"ltp":1.24,"tv":6930.29,"id":9433864}]}]}
{"op":"mcm","clk":"4233832312","pt":1631539198677,"mc":[{"id":"1.187557653","rc":[{"trd":[[5.1,2.44]],"ltp":5.1,"tv":4484.92,"id":9632596},{"trd":[[1.24,42.96]],"batl":[[0,1.24,93.04]],"ltp":1.24,"tv":6930.33,"id":9433864}],"tv":11415.25}]}
{"op":"mcm","clk":"4233832451","pt":1631539199990,"mc":[{"id":"1.187557653","rc":[{"batl":[[0,1.37,63.58],[1,1.62,655.89],[2,2.02,2.13]],"ltp":1.24,"tv":6930.33,"id":9433864}]}]}
{"op":"mcm","clk":"4233832568","pt":1631539201105,"mc":[{"id":"1.187557653","rc":[{"batb":[[2,1.13,266.04]],"batl":[[1,2.02,2.13],[2,2.02,0]],"ltp":1.24,"tv":6930.33,"id":9433864}]}]}
{"op":"mcm","clk":"4233832810","pt":1631539203273,"mc":[{"id":"1.187557653","rc":[{"batb":[[0,6.4,32.8],[1,6.2,7.03],[2,6,7.03]],"batl":[[0,7.2,6.94],[1,7.6,98.17],[2,7.8,9.86]],"ltp":5.1,"tv":4484.92,"id":9632596},{"trd":[[1.19,2],[1.23,37.18]],"batb":[[0,1.14,56.4],[1,1.13,266.04],[2,1.12,24.24]],"batl":[[0,1.18,40.13],[1,1.2,8.33],[2,1.25,43.52]],"ltp":1.19,"tv":6936.33,"id":9433864}],"tv":11421.25}]}
{"op":"mcm","clk":"4233832869","pt":1631539203907,"mc":[{"id":"1.187557653","rc":[{"batb":[[0,6.4,23.42],[1,6.2,2.34],[2,6,2.34]],"batl":[[1,7.6,82.37],[2,7.8,1.98]],"ltp":5.1,"tv":4484.92,"id":9632596}]}]}
{"op":"mcm","clk":"4233832999","pt":1631539205218,"mc":[{"id":"1.187557653","rc":[{"batb":[[1,1.13,855.84]],"batl":[[2,1.25,43.44]],"ltp":1.19,"tv":6936.33,"id":9433864}]}]}
{"op":"mcm","clk":"4233833176","pt":1631539206795,"mc":[{"id":"1.187557653","rc":[{"batb":[[0,1.16,66],[1,1.14,56.4],[2,1.13,855.84]],"ltp":1.19,"tv":6936.33,"id":9433864}]}]}
{"op":"mcm","clk":"4233833294","pt":1631539207792,"mc":[{"id":"1.187557653","rc":[{"batl":[[0,1.18,40.21]],"ltp":1.19,"tv":6936.33,"id":9433864}]}]}
{"op":"mcm","clk":"4233833532","pt":1631539209697,"mc":[{"id":"1.187557653","rc":[{"batl":[[2,1.22,108.25]],"ltp":1.19,"tv":6936.33,"id":9433864}]}]}
{"op":"mcm","clk":"4233833786","pt":1631539211701,"mc":[{"id":"1.187557653","rc":[{"trd":[[6.4,0.02]],"batb":[[0,6.4,23.41]],"ltp":6.4,"tv":4484.94,"id":9632596}],"tv":11421.27}]}
{"op":"mcm","clk":"4233833892","pt":1631539212744,"mc":[{"id":"1.187557653","rc":[{"trd":[[1.16,0.08]],"batb":[[0,1.16,65.96]],"ltp":1.16,"tv":6936.41,"id":9433864}],"tv":11421.35}]}
{"op":"mcm","clk":"4233834286","pt":1631539216299,"mc":[{"id":"1.187557653","rc":[{"trd":[[1.16,12.02]],"batb":[[0,1.16,59.99]],"ltp":1.16,"tv":6948.35,"id":9433864}],"tv":11433.29}]}
{"op":"mcm","clk":"4233834644","pt":1631539219724,"mc":[{"id":"1.187557653","rc":[{"batb":[[1,1.14,8.77]],"ltp":1.16,"tv":6948.35,"id":9433864}]}]}
{"op":"mcm","clk":"4233835000","pt":1631539223129,"mc":[{"id":"1.187557653","rc":[{"trd":[[7.2,5.86]],"batb":[[0,5.9,27.77],[1,5.5,2.12],[2,5.1,22.12]],"batl":[[0,9.4,2],[1,11,2],[2,7.8,0]],"ltp":7.2,"tv":4490.8,"id":9632596},{"trd":[[1.16,168.38]],"batb":[[0,1.13,855.84],[1,1.12,192.79],[2,1.11,242.59]],"batl":[[0,1.22,108.33],[1,1.23,97.5],[2,1.24,105.48]],"ltp":1.16,"tv":7104.71,"id":9433864}],"tv":11595.52}]}
{"op":"mcm","clk":"4233835110","pt":1631539224019,"mc":[{"id":"1.187557653","rc":[{"batb":[[0,5.1,22.12],[1,3.7,3.02],[2,1.01,113.68]],"ltp":7.2,"tv":4490.8,"id":9632596},{"batb":[[0,1.13,589.81]],"batl":[[0,1.24,105.56],[1,1.37,63.5],[2,1.53,758.88]],"ltp":1.16,"tv":7104.71,"id":9433864}]}]}
{"op":"mcm","clk":"4233835176","pt":1631539224539,"mc":[{"id":"1.187557653","rc":[{"batl":[[0,1.16,169],[1,1.24,105.56],[2,1.37,63.5]],"ltp":1.16,"tv":7104.71,"id":9433864}]}]}
{"op":"mcm","clk":"4233835259","pt":1631539225325,"mc":[{"id":"1.187557653","rc":[{"batl":[[1,1.24,105.48]],"ltp":1.16,"tv":7104.71,"id":9433864}]}]}
{"op":"mcm","clk":"4233835430","pt":1631539227214,"mc":[{"id":"1.187557653","rc":[{"batb":[[0,5.5,2.12],[1,5.1,22.12],[2,3.7,3.02]],"ltp":7.2,"tv":4490.8,"id":9632596},{"batl":[[0,1.14,13.73],[1,1.16,169],[2,1.22,117.25]],"ltp":1.16,"tv":7104.71,"id":9433864}]}]}
{"op":"mcm","clk":"4233835492","pt":1631539227944,"mc":[{"id":"1.187557653","rc":[{"trd":[[1.14,0.02]],"batl":[[0,1.14,13.72]],"ltp":1.14,"tv":7104.73,"id":9433864}],"tv":11595.53}]}
{"op":"mcm","clk":"4233835532","pt":1631539228417,"mc":[{"id":"1.187557653","rc":[{"batl":[[1,1.16,169.08]],"ltp":1.14,"tv":7104.73,"id":9433864}]}]}
{"op":"mcm","clk":"4233835708","pt":1631539230035,"mc":[{"id":"1.187557653","rc":[{"batl":[[1,1.16,211.58]],"ltp":1.14,"tv":7104.73,"id":9433864}]}]}
{"op":"mcm","clk":"4233835979","pt":1631539233136,"mc":[{"id":"1.187557653","rc":[{"batl":[[0,1.14,13.8]],"ltp":1.14,"tv":7104.73,"id":9433864}]}]}
{"op":"mcm","clk":"4233836034","pt":1631539233608,"mc":[{"id":"1.187557653","rc":[{"batb":[[2,1.01,113.68]],"batl":[[0,11,2],[1,11,0]],"ltp":7.2,"tv":4490.8,"id":9632596},{"batb":[[1,1.1,618.94],[2,1.01,113.68]],"batl":[[0,1.16,169.08],[1,1.22,117.25],[2,1.24,105.48]],"ltp":1.14,"tv":7104.73,"id":9433864}]}]}
{"op":"mcm","clk":"4233836347","pt":1631539236127,"mc":[{"id":"1.187557653","rc":[{"batb":[[0,8.2,3.66],[1,8,6.47],[2,7.8,1.82]],"batl":[[0,9.2,37.6],[1,11,2]],"ltp":7.2,"tv":4490.8,"id":9632596},{"batb":[[0,1.12,28.69],[1,1.1,668.31],[2,1.08,25.14]],"batl":[[0,1.13,36.52],[1,1.14,94.83],[2,1.15,182.62]],"ltp":1.14,"tv":7104.73,"id":9433864}]}]}
{"op":"mcm","clk":"4233836465","pt":1631539237121,"mc":[{"id":"1.187557653","rc":[{"batl":[[1,9.8,3.06],[2,10,1.54]],"ltp":7.2,"tv":4490.8,"id":9632596},{"batb":[[1,1.1,677.4]],"batl":[[0,1.13,92.83],[1,1.14,94.75]],"ltp":1.14,"tv":7104.73,"id":9433864}]}]}
{"op":"mcm","clk":"4233836770","pt":1631539240035,"mc":[{"id":"1.187557653","rc":[{"batb":[[2,1.08,806.21]],"batl":[[0,1.13,92.91]],"ltp":1.14,"tv":7104.73,"id":9433864}]}]}
{"op":"mcm","clk":"4233836873","pt":1631539241152,"mc":[{"id":"1.187557653","rc":[{"batl":[[0,1.13,50.32]],"ltp":1.14,"tv":7104.73,"id":9433864}]}]}
{"op":"mcm","clk":"4233836953","pt":1631539241858,"mc":[{"id":"1.187557653","rc":[{"batl":[[0,1.13,135.79]],"ltp":1.14,"tv":7104.73,"id":9433864}]}]}
{"op":"mcm","clk":"4233837089","pt":1631539243071,"mc":[{"id":"1.187557653","rc":[{"batb":[[0,1.12,129.69]],"ltp":1.14,"tv":7104.73,"id":9433864}]}]}
{"op":"mcm","clk":"4233837233","pt":1631539244223,"mc":[{"id":"1.187557653","rc":[{"trd":[[1.12,89.16]],"batb":[[0,1.12,85.11]],"ltp":1.12,"tv":7193.89,"id":9433864}],"tv":11684.69}]}
{"op":"mcm","clk":"4233837265","pt":1631539244538,"mc":[{"id":"1.187557653","rc":[{"trd":[[1.12,93.16]],"batb":[[0,1.12,83.11]],"ltp":1.12,"tv":7197.89,"id":9433864}],"tv":11688.69}]}
{"op":"mcm","clk":"4233837491","pt":1631539246839,"mc":[{"id":"1.187557653","rc":[{"trd":[[1.13,11.62]],"batl":[[0,1.13,129.98]],"ltp":1.13,"tv":7209.5,"id":9433864}],"tv":11700.31}]}
{"op":"mcm","clk":"4233837810","pt":1631539249971,"mc":[{"id":"1.187557653","rc":[{"batl":[[0,1.13,116.25]],"ltp":1.13,"tv":7209.5,"id":9433864}]}]}
{"op":"mcm","clk":"4233837902","pt":1631539250756,"mc":[{"id":"1.187557653","rc":[{"trd":[[9.2,21.34]],"batl":[[0,9.2,16.26]],"ltp":9.2,"tv":4512.14,"id":9632596},{"trd":[[1.12,434.7]],"batb":[[0,1.1,677.4],[1,1.08,806.21],[2,1.06,506.22]],"ltp":1.12,"tv":7551.04,"id":9433864}],"tv":12063.18}]}
{"op":"mcm","clk":"4233838139","pt":1631539253064,"mc":[{"id":"1.187557653","rc":[{"trd":[[9.2,37.6],[9.8,1.55]],"batl":[[0,9.8,1.51],[1,10,1.54],[2,10.5,1.54]],"ltp":9.8,"tv":4529.95,"id":9632596},{"trd":[[1.11,13.72],[1.12,568.26]],"batl":[[0,1.12,35.44],[1,1.13,116.25],[2,1.14,94.75]],"ltp":1.11,"tv":7698.32,"id":9433864}],"tv":12228.28}]}
{"op":"mcm","clk":"4233838225","pt":1631539253745,"mc":[{"id":"1.187557653","rc":[{"trd":[[1.12,571.97]],"batl":[[0,1.12,126.61],[1,1.13,85.54]],"ltp":1.12,"tv":7702.04,"id":9433864}],"tv":12231.99}]}
{"op":"mcm","clk":"4233838321","pt":1631539254790,"mc":[{"id":"1.187557653","rc":[{"trd":[[1.12,825.19]],"batb":[[0,1.12,3.39],[1,1.1,677.4],[2,1.08,806.21]],"batl":[[0,1.13,85.54],[1,1.14,94.75],[2,1.15,182.62]],"ltp":1.12,"tv":7955.26,"id":9433864}],"tv":12485.21}]}
{"op":"mcm","clk":"4233838454","pt":1631539255999,"mc":[{"id":"1.187557653","rc":[{"batl":[[0,1.14,94.83],[1,1.15,182.62],[2,1.2,45.25]],"ltp":1.12,"tv":7955.26,"id":9433864}]}]}
{"op":"mcm","clk":"4233838667","pt":1631539258010,"mc":[{"id":"1.187557653","rc":[{"trd":[[1.12,831.97]],"batb":[[0,1.1,677.4],[1,1.08,806.21],[2,1.06,506.22]],"ltp":1.12,"tv":7962.04,"id":9433864}],"tv":12491.99}]}
{"op":"mcm","clk":"4233838894","pt":1631539259997,"mc":[{"id":"1.187557653","rc":[{"batl":[[1,10,9.7]],"ltp":9.8,"tv":4529.95,"id":9632596},{"batb":[[0,1.12,126.61],[1,1.1,677.4],[2,1.08,806.21]],"batl":[[0,1.13,59.19],[1,1.14,94.75],[2,1.15,182.62]],"ltp":1.12,"tv":7962.04,"id":9433864}]}]}
{"op":"mcm","clk":"4233838951","pt":1631539260361,"mc":[{"id":"1.187557653","rc":[{"trd":[[9.4,0.42]],"ltp":9.4,"tv":4530.37,"id":9632596},{"trd":[[1.12,835.47]],"batb":[[0,1.12,123.11]],"ltp":1.12,"tv":7965.54,"id":9433864}],"tv":12495.91}]}
{"op":"mcm","clk":"4233839170","pt":1631539262506,"mc":[{"id":"1.187557653","rc":[{"batb":[[1,1.11,5.15],[2,1.1,677.4]],"ltp":1.12,"tv":7965.54,"id":9433864}]}]}
{"op":"mcm","clk":"4233839397","pt":1631539264496,"mc":[{"id":"1.187557653","rc":[{"trd":[[9.4,0.87]],"ltp":9.4,"tv":4530.82,"id":9632596},{"trd":[[1.12,839.25]],"batb":[[0,1.12,119.33]],"ltp":1.12,"tv":7969.32,"id":9433864}],"tv":12500.14}]}
{"op":"mcm","clk":"4233839785","pt":1631539267881,"mc":[{"id":"1.187557653","rc":[{"trd":[[1.12,839.83]],"batb":[[0,1.12,119.04]],"ltp":1.12,"tv":7969.9,"id":9433864}],"tv":12500.72}]}
{"op":"mcm","clk":"4233840098","pt":1631539270610,"mc":[{"id":"1.187557653","rc":[{"batb":[[1,1.1,677.4],[2,1.08,806.21]],"ltp":1.12,"tv":7969.9,"id":9433864}]}]}
{"op":"mcm","clk":"4233840513","pt":1631539273995,"mc":[{"id":"1.187557653","rc":[{"trd":[[1.12,1088.12]],"batb":[[0,1.1,677.4],[1,1.08,806.21],[2,1.06,506.22]],"batl":[[0,1.12,20.39],[1,1.13,59.19],[2,1.14,94.75]],"ltp":1.12,"tv":8218.19,"id":9433864}],"tv":12749.01}]}
{"op":"mcm","clk":"4233840668","pt":1631539275199,"mc":[{"id":"1.187557653","rc":[{"trd":[[1.12,1091.22]],"batl":[[0,1.12,46.95]],"ltp":1.12,"tv":8221.28,"id":9433864}],"tv":12752.1}]}
{"op":"mcm","clk":"4233840784","pt":1631539276194,"mc":[{"id":"1.187557653","rc":[{"batl":[[1,1.13,59.11]],"ltp":1.12,"tv":8221.28,"id":9433864}]}]}
{"op":"mcm","clk":"4233840954","pt":1631539277823,"mc":[{"id":"1.187557653","rc":[{"batb":[[0,1.11,98],[1,1.1,677.4],[2,1.08,806.21]],"ltp":1.12,"tv":8221.28,"id":9433864}]}]}
{"op":"mcm","clk":"4233841114","pt":1631539279323,"mc":[{"id":"1.187557653","rc":[{"batl":[[0,1.12,47.03]],"ltp":1.12,"tv":8221.28,"id":9433864}]}]}
{"op":"mcm","clk":"4233841291","pt":1631539280831,"mc":[{"id":"1.187557653","rc":[{"batl":[[0,1.12,18.93]],"ltp":1.12,"tv":8221.28,"id":9433864}]}]}
{"op":"mcm","clk":"4233841675","pt":1631539283910,"mc":[{"id":"1.187557653","rc":[{"trd":[[1.11,69.93]],"batb":[[0,1.11,69.9]],"ltp":1.11,"tv":8277.49,"id":9433864}],"tv":12808.31}]}
{"op":"mcm","clk":"4233842201","pt":1631539288811,"mc":[{"id":"1.187557653","rc":[{"batl":[[0,1.13,59.19],[1,1.14,94.75],[2,1.15,182.62]],"ltp":1.11,"tv":8277.49,"id":9433864}]}]}
{"op":"mcm","clk":"4233842501","pt":1631539291531,"mc":[{"id":"1.187557653","rc":[{"trd":[[1.11,75.03]],"batb":[[0,1.11,67.35]],"ltp":1.11,"tv":8282.59,"id":9433864}],"tv":12813.41}]}
{"op":"mcm","clk":"4233844728","pt":1631539313080,"mc":[{"id":"1.187557653","rc":[{"trd":[[1.12,1091.38],[1.13,15.17]],"batl":[[0,1.13,57.33]],"ltp":1.13,"tv":8286.31,"id":9433864}],"tv":12817.13}]}
{"op":"mcm","clk":"4233845848","pt":1631539323208,"mc":[{"id":"1.187557653","rc":[{"batl":[[1,10,1.54]],"ltp":9.4,"tv":4530.82,"id":9632596},{"batb":[[1,1.1,628.03],[2,1.08,781.08]],"batl":[[0,1.14,94.75],[1,1.15,182.62],[2,1.22,117.25]],"ltp":1.13,"tv":8286.31,"id":9433864}]}]}
{"op":"mcm","clk":"4233846167","pt":1631539326091,"mc":[{"id":"1.187557653","rc":[{"batl":[[1,10,9.9]],"ltp":9.4,"tv":4530.82,"id":9632596},{"batl":[[0,1.13,57.33],[1,1.14,94.75],[2,1.15,182.62]],"ltp":1.13,"tv":8286.31,"id":9433864}]}]}
{"op":"mcm","clk":"4233846201","pt":1631539326411,"mc":[{"id":"1.187557653","rc":[{"batb":[[2,1.08,1112.14]],"ltp":1.13,"tv":8286.31,"id":9433864}]}]}
{"op":"mcm","clk":"4233847591","pt":1631539340214,"mc":[{"id":"1.187557653","rc":[{"batb":[[0,8,4.65],[1,7,18.41],[2,5.5,2.12]],"batl":[[0,10,8.36],[1,11,2],[2,13.5,2]],"ltp":9.4,"tv":4530.82,"id":9632596},{"batb":[[0,1.1,618.94],[1,1.08,1112.14],[2,1.06,927.3]],"batl":[[2,1.22,117.25]],"ltp":1.13,"tv":8286.31,"id":9433864}]}]}
{"op":"mcm","clk":"4233847660","pt":1631539340935,"mc":[{"id":"1.187557653","rc":[{"batb":[[0,5.2,18.99],[1,4.4,2.66],[2,1.01,113.68]],"batl":[[0,13.5,2],[1,18,2],[2,13.5,0]],"ltp":9.4,"tv":4530.82,"id":9632596},{"batb":[[0,1.08,1112.14],[1,1.06,927.3],[2,1.01,115.38]],"batl":[[0,1.29,87.5],[1,1.45,888.31],[2,1.22,0]],"ltp":1.13,"tv":8286.31,"id":9433864}]}]}
{"op":"mcm","clk":"4233847870","pt":1631539343036,"mc":[{"id":"1.187557653","rc":[{"batb":[[0,1.12,195],[1,1.08,1112.14],[2,1.06,927.3]],"ltp":1.13,"tv":8286.31,"id":9433864}]}]}
{"op":"mcm","clk":"4233847982","pt":1631539344129,"mc":[{"id":"1.187557653","rc":[{"batb":[[1,5,2.2],[2,4.4,2.66]],"ltp":9.4,"tv":4530.82,"id":9632596},{"batb":[[0,1.08,1112.14],[1,1.06,927.3],[2,1.01,115.38]],"batl":[[0,1.25,102.86],[1,1.29,87.5],[2,1.45,888.31]],"ltp":1.13,"tv":8286.31,"id":9433864}]}]}
{"op":"mcm","clk":"4233848031","pt":1631539344648,"mc":[{"id":"1.187557653","rc":[{"batb":[[1,4.4,2.66],[2,1.01,113.68]],"ltp":9.4,"tv":4530.82,"id":9632596},{"batl":[[0,1.29,87.5],[1,1.45,888.31],[2,1.45,0]],"ltp":1.13,"tv":8286.31,"id":9433864}]}]}
{"op":"mcm","clk":"4233848705","pt":1631539351261,"mc":[{"id":"1.187557653","rc":[{"batb":[[1,5,2.15],[2,4.4,2.66]],"ltp":9.4,"tv":4530.82,"id":9632596},{"batl":[[0,1.25,95.62],[1,1.29,87.5],[2,1.45,888.31]],"ltp":1.13,"tv":8286.31,"id":9433864}]}]}
{"op":"mcm","clk":"4233848742","pt":1631539351633,"mc":[{"id":"1.187557653","rc":[{"batb":[[1,4.4,2.66],[2,1.01,113.68]],"ltp":9.4,"tv":4530.82,"id":9632596},{"batl":[[0,1.29,87.5],[1,1.45,888.31],[2,1.45,0]],"ltp":1.13,"tv":8286.31,"id":9433864}]}]}
{"op":"mcm","clk":"4233849204","pt":1631539356166,"mc":[{"id":"1.187557653","rc":[{"batb":[[0,10.5,14.28],[1,10,27.14],[2,9.8,7.14]],"batl":[[0,13.5,25.61]],"ltp":9.4,"tv":4530.82,"id":9632596},{"batb":[[0,1.08,549.36]],"batl":[[0,1.09,28.25],[1,1.11,588.6],[2,1.12,8.93]],"ltp":1.13,"tv":8286.31,"id":9433864}]}]}
{"op":"mcm","clk":"4233849316","pt":1631539357258,"mc":[{"id":"1.187557653","rc":[{"batb":[[0,10.5,2.86],[1,10,24.75],[2,9.8,1.42]],"batl":[[1,14,10.72],[2,14.5,5.36]],"ltp":9.4,"tv":4530.82,"id":9632596},{"batb":[[1,1.07,9.35],[2,1.06,978.53]],"batl":[[1,1.11,677.1]],"ltp":1.13,"tv":8286.31,"id":9433864}]}]}
{"op":"mcm","clk":"4233849329","pt":1631539357466,"mc":[{"id":"1.187557653","rc":[{"batl":[[1,14,2.14],[2,14.5,1.08]],"ltp":9.4,"tv":4530.82,"id":9632596}]}]}
{"op":"mcm","clk":"4233849500","pt":1631539359294,"mc":[{"id":"1.187557653","rc":[{"batb":[[2,1.06,1892.89]],"ltp":1.13,"tv":8286.31,"id":9433864}]}]}
{"op":"mcm","clk":"4233849706","pt":1631539361178,"mc":[{"id":"1.187557653","rc":[{"batl":[[0,1.09,71.12]],"ltp":1.13,"tv":8286.31,"id":9433864}]}]}
{"op":"mcm","clk":"4233850172","pt":1631539365761,"mc":[{"id":"1.187557653","rc":[{"batb":[[0,1.08,691.36]],"ltp":1.13,"tv":8286.31,"id":9433864}]}]}
{"op":"mcm","clk":"4233850535","pt":1631539369162,"mc":[{"id":"1.187557653","rc":[{"batb":[[0,7.2,2],[1,6.6,21.08],[2,6.2,2.02]],"batl":[[0,18,2],[1,21,2],[2,14.5,0]],"ltp":9.4,"tv":4530.82,"id":9632596},{"batb":[[0,1.08,142],[1,1.06,1335.44],[2,1.05,551.89]],"batl":[[0,1.09,42.87],[1,1.16,138.47],[2,1.18,119.75]],"ltp":1.13,"tv":8286.31,"id":9433864}]}]}
{"op":"mcm","clk":"4233850612","pt":1631539369893,"mc":[{"id":"1.187557653","rc":[{"batb":[[0,1.06,1335.44],[1,1.05,551.89],[2,1.04,621.12]],"ltp":1.13,"tv":8286.31,"id":9433864}]}]}
{"op":"mcm","clk":"4233850935","pt":1631539373084,"mc":[{"id":"1.187557653","rc":[{"batl":[[0,1.16,138.47],[1,1.18,119.75],[2,1.19,141.5]],"ltp":1.13,"tv":8286.31,"id":9433864}]}]}
{"op":"mcm","clk":"4233850983","pt":1631539373561,"mc":[{"id":"1.187557653","rc":[{"batb":[[0,6.6,21.08],[1,6.2,2.02],[2,4.4,2.66]],"ltp":9.4,"tv":4530.82,"id":9632596},{"batl":[[0,1.19,141.5],[1,1.29,87.5],[2,1.45,888.31]],"ltp":1.13,"tv":8286.31,"id":9433864}]}]}
{"op":"mcm","clk":"4233851445","pt":1631539378097,"mc":[{"id":"1.187557653","rc":[{"batb":[[0,1.07,105],[1,1.06,1335.44],[2,1.05,551.89]],"batl":[[1,1.2,121.28],[2,1.29,87.5]],"ltp":1.13,"tv":8286.31,"id":9433864}]}]}
{"op":"mcm","clk":"4233851468","pt":1631539378308,"mc":[{"id":"1.187557653","rc":[{"batb":[[0,1.06,1335.44],[1,1.05,551.89],[2,1.04,621.12]],"ltp":1.13,"tv":8286.31,"id":9433864}]}]}
{"op":"mcm","clk":"4233851642","pt":1631539380187,"mc":[{"id":"1.187557653","rc":[{"batb":[[0,7.2,2],[1,6.6,21.08],[2,6.2,2.02]],"ltp":9.4,"tv":4530.82,"id":9632596},{"batl":[[0,1.16,169.97],[1,1.18,152.75],[2,1.19,141.5]],"ltp":1.13,"tv":8286.31,"id":9433864}]}]}
{"op":"mcm","clk":"4233851700","pt":1631539380705,"mc":[{"id":"1.187557653","rc":[{"batb":[[0,6.6,21.08],[1,6.2,2.02],[2,4.4,2.66]],"ltp":9.4,"tv":4530.82,"id":9632596},{"batl":[[0,1.19,141.5],[1,1.29,87.5],[2,1.45,888.31]],"ltp":1.13,"tv":8286.31,"id":9433864}]}]}
{"op":"mcm","clk":"4233852333","pt":1631539387007,"mc":[{"id":"1.187557653","rc":[{"batb":[[0,7.2,2],[1,6.6,21.08],[2,6.2,2.02]],"ltp":9.4,"tv":4530.82,"id":9632596},{"batl":[[0,1.16,163.97],[1,1.18,139.75],[2,1.19,141.5]],"ltp":1.13,"tv":8286.31,"id":9433864}]}]}
{"op":"mcm","clk":"4233852371","pt":1631539387421,"mc":[{"id":"1.187557653","rc":[{"batb":[[0,6.6,21.08],[1,6.2,2.02],[2,4.4,2.66]],"ltp":9.4,"tv":4530.82,"id":9632596},{"batl":[[0,1.19,141.5],[1,1.29,87.5],[2,1.45,888.31]],"ltp":1.13,"tv":8286.31,"id":9433864}]}]}
{"op":"mcm","clk":"4233852739","pt":1631539391225,"mc":[{"id":"1.187557653","rc":[{"batb":[[2,1.01,113.68]],"ltp":9.4,"tv":4530.82,"id":9632596},{"batb":[[0,1.06,421.08]],"batl":[[1,1.29,0],[2,1.45,0]],"ltp":1.13,"tv":8286.31,"id":9433864}]}]}
{"op":"mcm","clk":"4233852930","pt":1631539393212,"mc":[{"id":"1.187557653","rc":[{"batb":[[0,14.5,2.06],[1,14,1.04],[2,13.5,30.43]],"batl":[[1,21,32.33]],"ltp":9.4,"tv":4530.82,"id":9632596},{"batb":[[0,1.06,452.5],[1,1.05,1158.54]],"batl":[[0,1.07,100.71],[1,1.08,427.33],[2,1.09,9.17]],"ltp":1.13,"tv":8286.31,"id":9433864}]}]}
{"op":"mcm","clk":"4233853029","pt":1631539394204,"mc":[{"id":"1.187557653","rc":[{"batb":[[1,1.05,1187.12],[2,1.04,645.02]],"ltp":1.13,"tv":8286.31,"id":9433864}]}]}
{"op":"mcm","clk":"4233853081","pt":1631539394723,"mc":[{"id":"1.187557653","rc":[{"batb":[[2,1.04,1867.1]],"ltp":1.13,"tv":8286.31,"id":9433864}]}]}
{"op":"mcm","clk":"4233853339","pt":1631539397028,"mc":[{"id":"1.187557653","rc":[{"trd":[[1.07,4]],"batl":[[0,1.07,98.71]],"ltp":1.07,"tv":8290.31,"id":9433864}],"tv":12821.13}]}
{"op":"mcm","clk":"4233853550","pt":1631539399211,"mc":[{"id":"1.187557653","rc":[{"trd":[[1.07,4.38]],"batl":[[0,1.07,98.52]],"ltp":1.07,"tv":8290.69,"id":9433864}],"tv":12821.51}]}
{"op":"mcm","clk":"4233853572","pt":1631539399522,"mc":[{"id":"1.187557653","rc":[{"batl":[[2,26,2]],"ltp":9.4,"tv":4530.82,"id":9632596}]}]}
{"op":"mcm","clk":"4233853730","pt":1631539401035,"mc":[{"id":"1.187557653","rc":[{"batb":[[0,1.06,545.5]],"ltp":1.07,"tv":8290.69,"id":9433864}]}]}
{"op":"mcm","clk":"4233854325","pt":1631539407268,"mc":[{"id":"1.187557653","rc":[{"batb":[[0,1.06,514.08]],"batl":[[0,1.08,427.33],[1,1.09,9.17],[2,1.11,206.5]],"ltp":1.07,"tv":8290.69,"id":9433864}]}]}
{"op":"mcm","clk":"4233854656","pt":1631539410142,"mc":[{"id":"1.187557653","rc":[{"batb":[[0,1.06,547.71]],"batl":[[0,1.07,98.52],[1,1.08,427.33],[2,1.09,9.17]],"ltp":1.07,"tv":8290.69,"id":9433864}]}]}
{"op":"mcm","clk":"4233854679","pt":1631539410349,"mc":[{"id":"1.187557653","rc":[{"batb":[[0,1.06,514.08]],"batl":[[0,1.08,427.33],[1,1.09,9.17],[2,1.11,206.5]],"ltp":1.07,"tv":8290.69,"id":9433864}]}]}
{"op":"mcm","clk":"4233854983","pt":1631539413264,"mc":[{"id":"1.187557653","rc":[{"batb":[[0,1.06,547.71]],"batl":[[0,1.07,98.52],[1,1.08,427.33],[2,1.09,9.17]],"ltp":1.07,"tv":8290.69,"id":9433864}]}]}
{"op":"mcm","clk":"4233855308","pt":1631539416279,"mc":[{"id":"1.187557653","rc":[{"batb":[[0,10,2],[1,8.8,25.18],[2,8.6,2]],"batl":[[0,26,2],[1,21,0],[2,26,0]],"ltp":9.4,"tv":4530.82,"id":9632596},{"batb":[[0,1.06,93],[1,1.04,1843.2],[2,1.03,787.83]],"batl":[[0,1.11,206.5],[1,1.12,228.96],[2,1.13,175.5]],"ltp":1.07,"tv":8290.69,"id":9433864}]}]}
{"op":"mcm","clk":"4233855379","pt":1631539416858,"mc":[{"id":"1.187557653","rc":[{"batb":[[0,8.8,25.18],[1,8.6,2],[2,6.2,2.02]],"ltp":9.4,"tv":4530.82,"id":9632596},{"batb":[[0,1.04,1843.2],[1,1.03,787.83],[2,1.02,1112.51]],"batl":[[0,1.13,175.5],[1,1.19,141.5],[2,1.37,1063.54]],"ltp":1.07,"tv":8290.69,"id":9433864}]}]}
{"op":"mcm","clk":"4233855629","pt":1631539419247,"mc":[{"id":"1.187557653","rc":[{"batl":[[0,21,2],[1,26,2]],"ltp":9.4,"tv":4530.82,"id":9632596},{"batb":[[0,1.05,2.09],[1,1.04,1843.2],[2,1.03,787.83]],"ltp":1.07,"tv":8290.69,"id":9433864}]}]}
{"op":"mcm","clk":"4233855691","pt":1631539419870,"mc":[{"id":"1.187557653","rc":[{"batl":[[0,26,2],[1,26,0]],"ltp":9.4,"tv":4530.82,"id":9632596},{"batb":[[0,1.04,1843.2],[1,1.03,787.83],[2,1.02,1112.51]],"ltp":1.07,"tv":8290.69,"id":9433864}]}]}
{"op":"mcm","clk":"4233855890","pt":1631539421845,"mc":[{"id":"1.187557653","rc":[{"batb":[[0,1.08,1.86],[1,1.04,1843.2],[2,1.03,787.83]],"ltp":1.07,"tv":8290.69,"id":9433864}]}]}
{"op":"mcm","clk":"4233856000","pt":1631539423091,"mc":[{"id":"1.187557653","rc":[{"batb":[[0,10,2],[1,8.8,25.18],[2,8.6,2]],"batl":[[0,21,2],[1,26,2]],"ltp":9.4,"tv":4530.82,"id":9632596},{"batb":[[1,1.05,2.09],[2,1.04,1843.2]],"batl":[[0,1.11,205.5],[1,1.12,197.21],[2,1.13,175.5]],"ltp":1.07,"tv":8290.69,"id":9433864}]}]}
{"op":"mcm","clk":"4233856046","pt":1631539423558,"mc":[{"id":"1.187557653","rc":[{"batb":[[0,8.8,25.18],[1,8.6,2],[2,6.2,2.02]],"ltp":9.4,"tv":4530.82,"id":9632596},{"batb":[[2,1.04,621.12]],"batl":[[0,1.13,175.5],[1,1.19,141.5],[2,1.37,1063.54]],"ltp":1.07,"tv":8290.69,"id":9433864}]}]}
{"op":"mcm","clk":"4233856203","pt":1631539425068,"mc":[{"id":"1.187557653","rc":[{"batl":[[0,13.5,23.93],[1,14,15],[2,14.5,3.22]],"ltp":9.4,"tv":4530.82,"id":9632596},{"batb":[[0,1.08,223.74],[1,1.07,9.35],[2,1.06,51.22]],"batl":[[0,1.09,27.64],[1,1.11,610.08],[2,1.13,175.5]],"ltp":1.07,"tv":8290.69,"id":9433864}]}]}
{"op":"mcm","clk":"4233856311","pt":1631539426060,"mc":[{"id":"1.187557653","rc":[{"batb":[[0,10.5,2.86],[1,10,1.42],[2,9.8,1.42]],"batl":[[1,14,10.71],[2,14.5,1.08]],"ltp":9.4,"tv":4530.82,"id":9632596},{"batb":[[2,1.06,553.18]],"batl":[[2,1.12,8.93]],"ltp":1.07,"tv":8290.69,"id":9433864}]}]}
{"op":"mcm","clk":"4233856406","pt":1631539427059,"mc":[{"id":"1.187557653","rc":[{"batb":[[2,1.06,1467.54]],"ltp":1.07,"tv":8290.69,"id":9433864}]}]}
{"op":"mcm","clk":"4233856713","pt":1631539429883,"mc":[{"id":"1.187557653","rc":[{"batb":[[0,1.08,221.88]],"ltp":1.07,"tv":8290.69,"id":9433864}]}]}
{"op":"mcm","clk":"4233857014","pt":1631539432706,"mc":[{"id":"1.187557653","rc":[{"batb":[[0,1.08,318.88]],"ltp":1.07,"tv":8290.69,"id":9433864}]}]}
{"op":"mcm","clk":"4233857361","pt":1631539435774,"mc":[{"id":"1.187557653","rc":[{"trd":[[1.09,3.72]],"batl":[[0,1.09,25.78]],"ltp":1.09,"tv":8294.4,"id":9433864}],"tv":12825.23}]}
{"op":"mcm","clk":"4233858474","pt":1631539446143,"mc":[{"id":"1.187557653","rc":[{"batb":[[0,8.8,25.18],[1,7.2,2],[2,6.2,26.03]],"batl":[[0,21,2],[1,26,2],[2,36,2]],"ltp":9.4,"tv":4530.82,"id":9632596},{"batb":[[0,1.08,97],[1,1.06,1416.32],[2,1.05,2.09]],"batl":[[0,1.16,156.97],[1,1.18,153.75],[2,1.19,141.5]],"ltp":1.09,"tv":8294.4,"id":9433864}]}]}
{"op":"mcm","clk":"4233858564","pt":1631539446833,"mc":[{"id":"1.187557653","rc":[{"batb":[[0,6.2,26.03],[1,1.01,113.68],[2,6.2,0]],"ltp":9.4,"tv":4530.82,"id":9632596},{"batb":[[0,1.06,914.36],[1,1.05,2.09],[2,1.04,621.12]],"batl":[[0,1.19,141.5],[1,1.37,1063.54],[2,1.19,0]],"ltp":1.09,"tv":8294.4,"id":9433864}]}]}
{"op":"mcm","clk":"4233859299","pt":1631539453249,"mc":[{"id":"1.187557653","rc":[{"batb":[[0,7.2,2],[1,6.2,26.03],[2,1.01,113.68]],"ltp":9.4,"tv":4530.82,"id":9632596},{"batl":[[0,1.16,148.22],[1,1.18,158.75],[2,1.19,141.5]],"ltp":1.09,"tv":8294.4,"id":9433864}]}]}
{"op":"mcm","clk":"4233859321","pt":1631539453459,"mc":[{"id":"1.187557653","rc":[{"batb":[[0,6.2,26.03],[1,1.01,113.68],[2,1.01,0]],"ltp":9.4,"tv":4530.82,"id":9632596},{"batl":[[0,1.19,141.5],[1,1.37,1063.54],[2,1.19,0]],"ltp":1.09,"tv":8294.4,"id":9433864}]}]}
{"op":"mcm","clk":"4233859876","pt":1631539458254,"mc":[{"id":"1.187557653","rc":[{"batb":[[0,1.05,2.09],[1,1.04,621.12],[2,1.03,1627.44]],"ltp":1.09,"tv":8294.4,"id":9433864}]}]}
{"op":"mcm","clk":"4233859999","pt":1631539459248,"mc":[{"id":"1.187557653","rc":[{"batb":[[0,13,15.38],[1,11,78.49],[2,6.2,26.03]],"batl":[[0,21,24.64]],"ltp":9.4,"tv":4530.82,"id":9632596},{"batb":[[0,1.05,323.56]],"batl":[[0,1.06,39.71],[1,1.07,140.2],[2,1.08,70.1]],"ltp":1.09,"tv":8294.4,"id":9433864}]}]}
{"op":"mcm","clk":"4233860111","pt":1631539460238,"mc":[{"id":"1.187557653","rc":[{"batb":[[0,15,2.44],[1,13,15.38],[2,12.5,10.37]],"batl":[[1,23,6.52],[2,26,2]],"ltp":9.4,"tv":4530.82,"id":9632596},{"batb":[[1,1.04,630.74]],"batl":[[1,1.07,131.54],[2,1.08,14.02]],"ltp":1.09,"tv":8294.4,"id":9433864}]}]}
{"op":"mcm","clk":"4233860137","pt":1631539460447,"mc":[{"id":"1.187557653","rc":[{"batl":[[1,23,1.3]],"ltp":9.4,"tv":4530.82,"id":9632596}]}]}
{"op":"mcm","clk":"4233860345","pt":1631539462432,"mc":[{"id":"1.187557653","rc":[{"batb":[[2,1.03,3159.02]],"ltp":1.09,"tv":8294.4,"id":9433864}]}]}
{"op":"mcm","clk":"4233860900","pt":1631539467543,"mc":[{"id":"1.187557653","rc":[{"batb":[[0,1.05,423.56]],"ltp":1.09,"tv":8294.4,"id":9433864}]}]}
{"op":"mcm","clk":"4233861589","pt":1631539473790,"mc":[{"id":"1.187557653","rc":[{"trd":[[1.06,5.78]],"batl":[[0,1.06,36.82]],"ltp":1.06,"tv":8300.18,"id":9433864}],"tv":12831.01}]}
{"op":"mcm","clk":"4233862134","pt":1631539478903,"mc":[{"id":"1.187557653","rc":[{"trd":[[1.06,19.12]],"batl":[[0,1.06,30.15]],"ltp":1.06,"tv":8313.52,"id":9433864}],"tv":12844.35}]}
{"op":"mcm","clk":"4233862396","pt":1631539481202,"mc":[{"id":"1.187557653","rc":[{"batb":[[1,12.5,10.37],[2,12,2]],"batl":[[0,21,2],[1,26,2],[2,36,2]],"ltp":9.4,"tv":4530.82,"id":9632596},{"trd":[[1.06,19.5]],"batb":[[0,1.05,102.09],[1,1.04,621.12]],"batl":[[0,1.07,103.5],[1,1.09,248.5],[2,1.1,242.75]],"ltp":1.06,"tv":8313.9,"id":9433864}],"tv":12844.72}]}
{"op":"mcm","clk":"4233862504","pt":1631539482089,"mc":[{"id":"1.187557653","rc":[{"batb":[[0,11,2],[1,9.4,22.25],[2,6.2,2.02]],"batl":[[0,26,2],[1,36,2],[2,36,0]],"ltp":9.4,"tv":4530.82,"id":9632596},{"batb":[[0,1.05,100],[2,1.03,2319.41]],"batl":[[0,1.1,242.75],[1,1.19,141.5],[2,1.37,1063.54]],"ltp":1.06,"tv":8313.9,"id":9433864}]}]}
{"op":"mcm","clk":"4233862628","pt":1631539483287,"mc":[{"id":"1.187557653","rc":[{"batl":[[0,36,2],[1,36,0]],"ltp":9.4,"tv":4530.82,"id":9632596},{"batb":[[0,1.03,2319.41],[1,1.02,1305.2],[2,1.01,115.38]],"ltp":1.06,"tv":8313.9,"id":9433864}]}]}
{"op":"mcm","clk":"4233862864","pt":1631539485283,"mc":[{"id":"1.187557653","rc":[{"batb":[[0,12,2],[1,11,2],[2,9.4,22.25]],"ltp":9.4,"tv":4530.82,"id":9632596},{"batl":[[0,1.09,270.5],[1,1.1,242.75],[2,1.11,221.5]],"ltp":1.06,"tv":8313.9,"id":9433864}]}]}
{"op":"mcm","clk":"4233862887","pt":1631539485488,"mc":[{"id":"1.187557653","rc":[{"batb":[[0,11,2],[1,9.4,22.25],[2,6.2,2.02]],"ltp":9.4,"tv":4530.82,"id":9632596},{"batl":[[0,1.1,242.75],[1,1.19,141.5],[2,1.37,1063.54]],"ltp":1.06,"tv":8313.9,"id":9433864}]}]}
{"op":"mcm","clk":"4233863329","pt":1631539489100,"mc":[{"id":"1.187557653","rc":[{"batb":[[0,12,2],[1,11,2],[2,9.4,22.25]],"ltp":9.4,"tv":4530.82,"id":9632596},{"batb":[[0,1.03,787.83]],"batl":[[0,1.09,275.5],[1,1.1,242.75],[2,1.19,141.5]],"ltp":1.06,"tv":8313.9,"id":9433864}]}]}
{"op":"mcm","clk":"4233863441","pt":1631539490093,"mc":[{"id":"1.187557653","rc":[{"batb":[[1,11,30.62]],"batl":[[0,15,42.36],[1,15.5,7.74],[2,16,5.63]],"ltp":9.4,"tv":4530.82,"id":9632596},{"batb":[[0,1.06,9.43],[1,1.05,51.71],[2,1.03,814.19]],"batl":[[1,1.1,529],[2,1.14,47.63]],"ltp":1.06,"tv":8313.9,"id":9433864}]}]}
{"op":"mcm","clk":"4233863571","pt":1631539491088,"mc":[{"id":"1.187557653","rc":[{"batb":[[0,1.06,548.62]],"batl":[[0,1.09,303.02],[1,1.1,542.76],[2,1.11,22.77]],"ltp":1.06,"tv":8313.9,"id":9433864}]}]}
{"op":"mcm","clk":"4233863825","pt":1631539493116,"mc":[{"id":"1.187557653","rc":[{"batb":[[1,1.05,1061.49]],"ltp":1.06,"tv":8313.9,"id":9433864}]}]}
{"op":"mcm","clk":"4233864058","pt":1631539495002,"mc":[{"id":"1.187557653","rc":[{"trd":[[12,5.06]],"batb":[[0,11,30.62],[1,9.4,22.25],[2,6.2,2.02]],"ltp":12.0,"tv":4535.88,"id":9632596},{"trd":[[1.09,15.39]],"batl":[[0,1.09,291.35]],"ltp":1.09,"tv":8325.57,"id":9433864}],"tv":12861.45}]}
{"op":"mcm","clk":"4233864182","pt":1631539496093,"mc":[{"id":"1.187557653","rc":[{"batl":[[0,15,50.59]],"ltp":12.0,"tv":4535.88,"id":9632596},{"batl":[[0,1.09,378.01]],"ltp":1.09,"tv":8325.57,"id":9433864}]}]}
{"op":"mcm","clk":"4233864204","pt":1631539496297,"mc":[{"id":"1.187557653","rc":[{"batb":[[2,7.2,2]],"ltp":12.0,"tv":4535.88,"id":9632596}]}]}
{"op":"mcm","clk":"4233864452","pt":1631539498800,"mc":[{"id":"1.187557653","rc":[{"batb":[[0,1.07,86],[1,1.06,548.62],[2,1.05,1061.49]],"ltp":1.09,"tv":8325.57,"id":9433864}]}]}
{"op":"mcm","clk":"4233864855","pt":1631539502717,"mc":[{"id":"1.187557653","rc":[{"trd":[[1.09,17.4]],"batb":[[0,1.06,548.62],[1,1.05,1061.49],[2,1.03,814.19]],"batl":[[0,1.09,377]],"ltp":1.09,"tv":8327.59,"id":9433864}],"tv":12863.47}]}
{"op":"mcm","clk":"4233865169","pt":1631539505649,"mc":[{"id":"1.187557653","rc":[{"batb":[[0,1.08,359],[1,1.06,548.62],[2,1.05,1061.49]],"ltp":1.09,"tv":8327.59,"id":9433864}]}]}
{"op":"mcm","clk":"4233865582","pt":1631539509167,"mc":[{"id":"1.187557653","rc":[{"batl":[[1,36,2],[2,16,0]],"ltp":12.0,"tv":4535.88,"id":9632596},{"batb":[[1,1.06,539.19]],"batl":[[0,1.09,349.48],[1,1.1,529],[2,1.14,47.63]],"ltp":1.09,"tv":8327.59,"id":9433864}]}]}
{"op":"mcm","clk":"4233865702","pt":1631539510022,"mc":[{"id":"1.187557653","rc":[{"batb":[[0,6.2,2.02],[1,6,26.1],[2,1.01,113.68]],"batl":[[0,21,2]],"ltp":12.0,"tv":4535.88,"id":9632596},{"batb":[[0,1.05,1011.88],[1,1.04,653.87],[2,1.03,787.83]],"batl":[[0,1.19,141.5],[1,1.37,1063.54],[2,1.14,0]],"ltp":1.09,"tv":8327.59,"id":9433864}]}]}
{"op":"mcm","clk":"4233866123","pt":1631539513720,"mc":[{"id":"1.187557653","rc":[{"batb":[[0,1.09,1.01],[1,1.05,1011.88],[2,1.04,653.87]],"ltp":1.09,"tv":8327.59,"id":9433864}]}]}
{"op":"mcm","clk":"4233866872","pt":1631539520778,"mc":[{"id":"1.187557653","rc":[{"batl":[[0,36,2],[1,36,0]],"ltp":12.0,"tv":4535.88,"id":9632596},{"batb":[[1,1.05,1009.79]],"batl":[[0,1.37,1063.54],[1,1.37,0]],"ltp":1.09,"tv":8327.59,"id":9433864}]}]}
{"op":"mcm","clk":"4233867121","pt":1631539523081,"mc":[{"id":"1.187557653","rc":[{"batb":[[0,17.5,8.56],[1,17,4.28],[2,16.5,4.28]],"batl":[[0,26,5.25],[1,34,70.34],[2,36,2]],"ltp":12.0,"tv":4535.88,"id":9632596},{"trd":[[1.09,19.42]],"batb":[[0,1.04,653.87],[1,1.03,787.83],[2,1.02,2416.87]],"batl":[[0,1.05,37.28],[1,1.06,4458.02],[2,1.07,33.34]],"ltp":1.09,"tv":8329.6,"id":9433864}],"tv":12865.48}]}
{"op":"mcm","clk":"4233867257","pt":1631539524183,"mc":[{"id":"1.187557653","rc":[{"batb":[[0,17.5,3.9],[1,16.5,1.72],[2,15,13.34]],"batl":[[1,32,4.7],[2,34,70.34]],"ltp":12.0,"tv":4535.88,"id":9632596},{"batb":[[1,1.03,797.54]],"batl":[[1,1.06,801.27],[2,1.07,9.35]],"ltp":1.09,"tv":8329.6,"id":9433864}]}]}
{"op":"mcm","clk":"4233867271","pt":1631539524291,"mc":[{"id":"1.187557653","rc":[{"batl":[[1,34,71.28],[2,36,2]],"ltp":12.0,"tv":4535.88,"id":9632596}]}]}
{"op":"mcm","clk":"4233867449","pt":1631539526162,"mc":[{"id":"1.187557653","rc":[{"batb":[[2,1.02,4538.62]],"ltp":1.09,"tv":8329.6,"id":9433864}]}]}
{"op":"mcm","clk":"4233867786","pt":1631539529389,"mc":[{"id":"1.187557653","rc":[{"batb":[[0,1.04,780.87]],"ltp":1.09,"tv":8329.6,"id":9433864}]}]}
{"op":"mcm","clk":"4233867893","pt":1631539530479,"mc":[{"id":"1.187557653","rc":[{"batb":[[2,15,15.34]],"ltp":12.0,"tv":4535.88,"id":9632596},{"trd":[[1.05,2.66]],"batl":[[0,1.05,35.95],[2,1.07,372.85]],"ltp":1.05,"tv":8332.26,"id":9433864}],"tv":12868.14}]}
{"op":"mcm","clk":"4233868092","pt":1631539532368,"mc":[{"id":"1.187557653","rc":[{"trd":[[26,5.25]],"batl":[[0,34,71.28],[1,36,2],[2,55,2]],"ltp":26.0,"tv":4541.13,"id":9632596},{"trd":[[1.04,1692.99]],"batb":[[0,1.03,797.54],[1,1.02,4538.62],[2,1.01,2946.04]],"batl":[[0,1.04,211.62],[1,1.05,35.95],[2,1.06,801.27]],"ltp":1.04,"tv":10025.25,"id":9433864}],"tv":14566.38}]}
{"op":"mcm","clk":"4233868356","pt":1631539534959,"mc":[{"id":"1.187557653","rc":[{"trd":[[1.04,1703.65]],"batl":[[0,1.04,206.29]],"ltp":1.04,"tv":10035.91,"id":9433864}],"tv":14577.04}]}
{"op":"mcm","clk":"4233868548","pt":1631539536980,"mc":[{"id":"1.187557653","rc":[{"trd":[[1.04,1723.65]],"batl":[[0,1.04,196.29]],"ltp":1.04,"tv":10055.91,"id":9433864}],"tv":14597.04}]}
{"op":"mcm","clk":"4233868811","pt":1631539540118,"mc":[{"id":"1.187557653","rc":[{"trd":[[1.04,1728.99]],"batl":[[0,1.04,193.62]],"ltp":1.04,"tv":10061.25,"id":9433864}],"tv":14602.38}]}
{"op":"mcm","clk":"4233868837","pt":1631539540476,"mc":[{"id":"1.187557653","rc":[{"batl":[[1,1.06,801.27],[2,1.07,372.85]],"ltp":1.04,"tv":10061.25,"id":9433864}]}]}
{"op":"mcm","clk":"4233869192","pt":1631539544481,"mc":[{"id":"1.187557653","rc":[{"trd":[[1.03,5.58]],"batb":[[0,1.03,794.75]],"ltp":1.03,"tv":10066.83,"id":9433864}],"tv":14607.96}]}
{"op":"mcm","clk":"4233869384","pt":1631539546714,"mc":[{"id":"1.187557653","rc":[{"batb":[[0,21,5.08],[1,17.5,3.9],[2,16.5,1.72]],"batl":[[0,34,81.24]],"ltp":26.0,"tv":4541.13,"id":9632596},{"batl":[[1,1.05,101.56],[2,1.06,801.27]],"ltp":1.03,"tv":10066.83,"id":9433864}]}]}
{"op":"mcm","clk":"4233869519","pt":1631539548075,"mc":[{"id":"1.187557653","rc":[{"batb":[[0,1.04,1.33],[1,1.03,794.75],[2,1.02,4538.62]],"batl":[[0,1.05,101.56],[1,1.06,801.27],[2,1.07,372.85]],"ltp":1.03,"tv":10066.83,"id":9433864}]}]}
{"op":"mcm","clk":"4233869729","pt":1631539550520,"mc":[{"id":"1.187557653","rc":[{"trd":[[1.03,390.16],[1.04,1731.65]],"batb":[[0,1.03,602.46],[1,1.02,4538.62],[2,1.01,2946.04]],"ltp":1.03,"tv":10454.07,"id":9433864}],"tv":14995.2}]}
{"op":"mcm","clk":"4233870094","pt":1631539554284,"mc":[{"id":"1.187557653","rc":[{"batb":[[0,14.5,13.22],[1,13.5,2],[2,11.5,11.96]],"batl":[[0,110,2],[1,36,0],[2,55,0]],"ltp":26.0,"tv":4541.13,"id":9632596},{"batb":[[0,1.02,3233.42],[1,1.01,115.38],[2,1.01,0]],"batl":[[0,1.08,301.94],[1,1.09,256.5],[2,1.37,1063.54]],"ltp":1.03,"tv":10454.07,"id":9433864}]}]}
{"op":"mcm","clk":"4233870125","pt":1631539554596,"mc":[{"id":"1.187557653","rc":[{"batb":[[0,13.5,2],[1,11.5,11.96],[2,1.01,113.68]],"ltp":26.0,"tv":4541.13,"id":9632596},{"batb":[[0,1.02,2121.75]],"batl":[[1,1.37,1063.54],[2,1.37,0]],"ltp":1.03,"tv":10454.07,"id":9433864}]}]}
{"op":"mcm","clk":"4233870304","pt":1631539556621,"mc":[{"id":"1.187557653","rc":[{"trd":[[1.02,132.02]],"batb":[[0,1.05,1.33],[1,1.02,2055.74],[2,1.01,115.38]],"ltp":1.02,"tv":10586.09,"id":9433864}],"tv":15127.22}]}
{"op":"mcm","clk":"4233870495","pt":1631539558604,"mc":[{"id":"1.187557653","rc":[{"batb":[[0,1.02,2055.74],[1,1.01,115.38],[2,1.01,0]],"ltp":1.02,"tv":10586.09,"id":9433864}]}]}
{"op":"mcm","clk":"4233870793","pt":1631539561013,"mc":[{"id":"1.187557653","rc":[{"batb":[[0,15,2.85],[1,13.5,2],[2,11.5,11.96]],"ltp":26.0,"tv":4541.13,"id":9632596},{"batl":[[0,1.07,375.5],[1,1.08,301.94],[2,1.37,1063.54]],"ltp":1.02,"tv":10586.09,"id":9433864}]}]}
{"op":"mcm","clk":"4233870901","pt":1631539562039,"mc":[{"id":"1.187557653","rc":[{"batb":[[0,13.5,2],[1,11.5,11.96],[2,1.01,113.68]],"ltp":26.0,"tv":4541.13,"id":9632596},{"batl":[[0,1.08,301.94],[1,1.37,1063.54],[2,1.37,0]],"ltp":1.02,"tv":10586.09,"id":9433864}]}]}
{"op":"mcm","clk":"4233871535","pt":1631539567233,"mc":[{"id":"1.187557653","rc":[{"batb":[[0,1.01,115.38],[1,1.01,0]],"ltp":1.02,"tv":10586.09,"id":9433864}]}]}
{"op":"mcm","clk":"4233871651","pt":1631539568219,"mc":[{"id":"1.187557653","rc":[{"batb":[[0,15,2.47],[1,13.5,2],[2,11.5,11.96]],"ltp":26.0,"tv":4541.13,"id":9632596},{"batb":[[0,1.01,21.7]],"batl":[[0,1.07,366.5],[1,1.08,301.94],[2,1.37,1063.54]],"ltp":1.02,"tv":10586.09,"id":9433864}]}]}
{"op":"mcm","clk":"4233871700","pt":1631539568640,"mc":[{"id":"1.187557653","rc":[{"batb":[[0,15,32.76]],"batl":[[0,21,23.67],[1,23,8.7],[2,25,1.2]],"ltp":26.0,"tv":4541.13,"id":9632596},{"batb":[[0,1.05,473.37],[1,1.04,9.62],[2,1.02,53.23]],"batl":[[0,1.06,127.91],[1,1.07,366.5],[2,1.08,301.94]],"ltp":1.02,"tv":10586.09,"id":9433864}]}]}
{"op":"mcm","clk":"4233871827","pt":1631539569737,"mc":[{"id":"1.187557653","rc":[{"batb":[[1,14.5,2.06],[2,14,1.04]],"ltp":26.0,"tv":4541.13,"id":9632596},{"batb":[[1,1.04,784.31],[2,1.02,1150.18]],"ltp":1.02,"tv":10586.09,"id":9433864}]}]}
{"op":"mcm","clk":"4233871958","pt":1631539570934,"mc":[{"id":"1.187557653","rc":[{"batb":[[2,1.03,1435.61]],"ltp":1.02,"tv":10586.09,"id":9433864}]}]}
{"op":"mcm","clk":"4233872253","pt":1631539573844,"mc":[{"id":"1.187557653","rc":[{"batb":[[0,1.05,622.37]],"ltp":1.02,"tv":10586.09,"id":9433864}]}]}
{"op":"mcm","clk":"4233872820","pt":1631539579160,"mc":[{"id":"1.187557653","rc":[{"batb":[[0,11.5,11.96],[1,11,3.24],[2,9.8,19.24]],"ltp":26.0,"tv":4541.13,"id":9632596},{"batb":[[0,1.05,149],[1,1.04,774.69]],"batl":[[0,1.1,273.25],[1,1.11,314.41],[2,1.13,24.02]],"ltp":1.02,"tv":10586.09,"id":9433864}]}]}
{"op":"mcm","clk":"4233872892","pt":1631539579940,"mc":[{"id":"1.187557653","rc":[{"batb":[[0,11,3.24],[1,9.8,19.24],[2,1.01,113.68]],"ltp":26.0,"tv":4541.13,"id":9632596},{"batb":[[0,1.06,25],[1,1.03,1435.61],[2,1.02,1096.94]],"batl":[[1,1.37,1063.54],[2,1.13,0]],"ltp":1.02,"tv":10586.09,"id":9433864}]}]}
{"op":"mcm","clk":"4233872993","pt":1631539581032,"mc":[{"id":"1.187557653","rc":[{"batb":[[2,1.02,1100.56]],"ltp":1.02,"tv":10586.09,"id":9433864}]}]}
{"op":"mcm","clk":"4233873220","pt":1631539583044,"mc":[{"id":"1.187557653","rc":[{"batl":[[1,1.11,275.5],[2,1.37,1063.54]],"ltp":1.02,"tv":10586.09,"id":9433864}]}]}
{"op":"mcm","clk":"4233873290","pt":1631539583770,"mc":[{"id":"1.187557653","rc":[{"batl":[[1,1.37,1063.54],[2,1.37,0]],"ltp":1.02,"tv":10586.09,"id":9433864}]}]}
{"op":"mcm","clk":"4233873701","pt":1631539587149,"mc":[{"id":"1.187557653","rc":[{"batb":[[2,1.02,1096.94]],"ltp":1.02,"tv":10586.09,"id":9433864}]}]}
{"op":"mcm","clk":"4233873950","pt":1631539589281,"mc":[{"id":"1.187557653","rc":[{"batb":[[0,12,3.14],[1,11,3.24],[2,9.8,19.24]],"ltp":26.0,"tv":4541.13,"id":9632596},{"batl":[[0,1.09,304.5],[1,1.1,273.25],[2,1.37,1063.54]],"ltp":1.02,"tv":10586.09,"id":9433864}]}]}
{"op":"mcm","clk":"4233874022","pt":1631539589958,"mc":[{"id":"1.187557653","rc":[{"batb":[[0,11,3.24],[1,9.8,19.24],[2,1.01,113.68]],"ltp":26.0,"tv":4541.13,"id":9632596},{"batl":[[0,1.1,273.25],[1,1.37,1063.54],[2,1.37,0]],"ltp":1.02,"tv":10586.09,"id":9433864}]}]}
{"op":"mcm","clk":"4233874329","pt":1631539592759,"mc":[{"id":"1.187557653","rc":[{"batb":[[0,12,3.54],[1,11,3.24],[2,9.8,19.24]],"ltp":26.0,"tv":4541.13,"id":9632596},{"batl":[[0,1.09,344.5],[1,1.1,273.25],[2,1.37,1063.54]],"ltp":1.02,"tv":10586.09,"id":9433864}]}]}
{"op":"mcm","clk":"4233874464","pt":1631539594117,"mc":[{"id":"1.187557653","rc":[{"batb":[[1,1.02,1096.94],[2,1.01,25.32]],"ltp":1.02,"tv":10586.09,"id":9433864}]}]}
{"op":"mcm","clk":"4233874581","pt":1631539595202,"mc":[{"id":"1.187557653","rc":[{"batl":[[0,17.5,68.99],[1,19,4.73]],"ltp":26.0,"tv":4541.13,"id":9632596},{"batb":[[0,1.06,138.21],[1,1.05,9.52],[2,1.04,52.21]],"batl":[[0,1.07,77.79],[1,1.09,897.98],[2,1.1,273.25]],"ltp":1.02,"tv":10586.09,"id":9433864}]}]}
{"op":"mcm","clk":"4233874696","pt":1631539596090,"mc":[{"id":"1.187557653","rc":[{"batb":[[0,13.5,2.22],[1,13,1.12],[2,12.5,1.12]],"batl":[[1,19,1.58]],"ltp":26.0,"tv":4541.13,"id":9632596},{"batb":[[1,1.05,595.97],[2,1.04,793.1]],"batl":[[2,1.1,282.34]],"ltp":1.02,"tv":10586.09,"id":9433864}]}]}
{"op":"mcm","clk":"4233874811","pt":1631539597069,"mc":[{"id":"1.187557653","rc":[{"batb":[[2,1.04,1945.52]],"ltp":1.02,"tv":10586.09,"id":9433864}]}]}
{"op":"mcm","clk":"4233875338","pt":1631539602474,"mc":[{"id":"1.187557653","rc":[{"batb":[[0,1.06,239.21]],"ltp":1.02,"tv":10586.09,"id":9433864}]}]}
{"op":"mcm","clk":"4233876501","pt":1631539612126,"mc":[{"id":"1.187557653","rc":[{"batb":[[2,1.04,1893.31]],"ltp":1.02,"tv":10586.09,"id":9433864}]}]}
{"op":"mcm","clk":"4233876747","pt":1631539614208,"mc":[{"id":"1.187557653","rc":[{"batb":[[0,11,3.24],[1,10,3.37],[2,9.8,19.24]],"ltp":26.0,"tv":4541.13,"id":9632596},{"batb":[[0,1.06,126],[1,1.05,586.45]],"batl":[[0,1.09,344.5],[1,1.1,273.25],[2,1.11,293.5]],"ltp":1.02,"tv":10586.09,"id":9433864}]}]}
{"op":"mcm","clk":"4233876817","pt":1631539614829,"mc":[{"id":"1.187557653","rc":[{"batb":[[0,10,3.37],[1,8.6,26.77],[2,1.01,113.68]],"ltp":26.0,"tv":4541.13,"id":9632596},{"batb":[[0,1.04,1893.31],[1,1.01,28.93],[2,1.04,0]],"batl":[[0,1.37,1063.54],[1,1.1,0],[2,1.11,0]],"ltp":1.02,"tv":10586.09,"id":9433864}]}]}
{"op":"mcm","clk":"4233877070","pt":1631539617106,"mc":[{"id":"1.187557653","rc":[{"batb":[[0,11.5,170.83],[1,10,3.37],[2,8.6,26.77]],"ltp":26.0,"tv":4541.13,"id":9632596}]}]}
{"op":"mcm","clk":"4233877164","pt":1631539618039,"mc":[{"id":"1.187557653","rc":[{"batb":[[0,11,4.48]],"ltp":26.0,"tv":4541.13,"id":9632596},{"batb":[[1,1.01,27.23]],"batl":[[0,1.1,343.15],[1,1.11,288.5],[2,1.37,1063.54]],"ltp":1.02,"tv":10586.09,"id":9433864}]}]}
{"op":"mcm","clk":"4233877246","pt":1631539618920,"mc":[{"id":"1.187557653","rc":[{"batb":[[0,1.04,740.89]],"ltp":1.02,"tv":10586.09,"id":9433864}]}]}
{"op":"mcm","clk":"4233877383","pt":1631539620113,"mc":[{"id":"1.187557653","rc":[{"batb":[[0,11,26.08]],"batl":[[0,15,67.21],[1,15.5,381.3],[2,16,12.5]],"ltp":26.0,"tv":4541.13,"id":9632596},{"batb":[[0,1.06,9.43],[1,1.04,740.89],[2,1.01,27.23]],"batl":[[0,1.08,36.69],[1,1.1,559.2],[2,1.11,288.5]],"ltp":1.02,"tv":10586.09,"id":9433864}]}]}
{"op":"mcm","clk":"4233877521","pt":1631539621209,"mc":[{"id":"1.187557653","rc":[{"batb":[[0,12.5,12],[1,12,6],[2,11.5,6]],"batl":[[1,16,7.5],[2,17,5.29]],"ltp":26.0,"tv":4541.13,"id":9632596},{"batb":[[0,1.07,484.22],[1,1.06,548.95],[2,1.05,51.71]],"batl":[[2,1.11,297.51]],"ltp":1.02,"tv":10586.09,"id":9433864}]}]}
{"op":"mcm","clk":"4233877627","pt":1631539622204,"mc":[{"id":"1.187557653","rc":[{"batb":[[0,12.5,2.4],[1,12,1.2],[2,11.5,1.2]],"batl":[[2,17,1.76]],"ltp":26.0,"tv":4541.13,"id":9632596},{"batb":[[2,1.05,1015.39]],"ltp":1.02,"tv":10586.09,"id":9433864}]}]}
{"op":"mcm","clk":"4233878207","pt":1631539627247,"mc":[{"id":"1.187557653","rc":[{"batb":[[0,10,3.37],[1,8.6,26.77],[2,8.2,12.47]],"batl":[[0,15.5,2],[1,18,2],[2,17,0]],"ltp":26.0,"tv":4541.13,"id":9632596},{"batb":[[0,1.07,940.29],[1,1.06,970.6],[2,1.05,1487.28]],"batl":[[0,1.14,47.63],[1,1.16,23.41],[2,1.37,1063.54]],"ltp":1.02,"tv":10586.09,"id":9433864}]}]}
{"op":"mcm","clk":"4233878268","pt":1631539627923,"mc":[{"id":"1.187557653","rc":[{"batb":[[1,8.2,12.47],[2,1.01,113.68]],"batl":[[0,18,2],[1,18,0]],"ltp":26.0,"tv":4541.13,"id":9632596},{"batb":[[0,1.06,970.6],[1,1.05,1435.57],[2,1.01,27.23]],"batl":[[0,1.37,1063.54],[1,1.16,0],[2,1.37,0]],"ltp":1.02,"tv":10586.09,"id":9433864}]}]}
{"op":"mcm","clk":"4233878614","pt":1631539631241,"mc":[{"id":"1.187557653","rc":[{"batl":[[0,1.11,322.5],[1,1.37,1063.54]],"ltp":1.02,"tv":10586.09,"id":9433864}]}]}
{"op":"mcm","clk":"4233878873","pt":1631539633939,"mc":[{"id":"1.187557653","rc":[{"batb":[[0,11,4.48],[1,10,3.37],[2,8.2,12.47]],"ltp":26.0,"tv":4541.13,"id":9632596},{"batl":[[0,1.1,338.75],[1,1.11,322.5],[2,1.12,288.46]],"ltp":1.02,"tv":10586.09,"id":9433864}]}]}
{"op":"mcm","clk":"4233878942","pt":1631539634717,"mc":[{"id":"1.187557653","rc":[{"batb":[[0,10,3.37],[1,8.2,12.47],[2,1.01,113.68]],"ltp":26.0,"tv":4541.13,"id":9632596},{"batl":[[0,1.11,322.5],[1,1.37,1063.54],[2,1.12,0]],"ltp":1.02,"tv":10586.09,"id":9433864}]}]}
{"op":"mcm","clk":"4233879240","pt":1631539637960,"mc":[{"id":"1.187557653","rc":[{"batl":[[0,15.5,2],[1,18,2]],"ltp":26.0,"tv":4541.13,"id":9632596},{"batb":[[0,1.07,340.07],[1,1.06,970.6],[2,1.05,1435.57]],"ltp":1.02,"tv":10586.09,"id":9433864}]}]}
{"op":"mcm","clk":"4233879416","pt":1631539639565,"mc":[{"id":"1.187557653","rc":[{"batl":[[0,18,2],[1,18,0]],"ltp":26.0,"tv":4541.13,"id":9632596},{"batb":[[0,1.06,970.6],[1,1.05,1435.57],[2,1.01,27.23]],"ltp":1.02,"tv":10586.09,"id":9433864}]}]}
{"op":"mcm","clk":"4233879596","pt":1631539641072,"mc":[{"id":"1.187557653","rc":[{"batb":[[0,11,4.48],[1,10,3.37],[2,8.2,12.47]],"ltp":26.0,"tv":4541.13,"id":9632596},{"batl":[[0,1.1,364.95],[1,1.11,322.5],[2,1.12,297.71]],"ltp":1.02,"tv":10586.09,"id":9433864}]}]}
{"op":"mcm","clk":"4233879645","pt":1631539641436,"mc":[{"id":"1.187557653","rc":[{"batl":[[2,1.37,1063.54]],"ltp":1.02,"tv":10586.09,"id":9433864}]}]}
{"op":"mcm","clk":"4233879829","pt":1631539643256,"mc":[{"id":"1.187557653","rc":[{"batb":[[0,13,6.92],[1,12.5,19.46],[2,12,15.85]],"batl":[[0,15,35.98],[1,15.5,2],[2,17.5,7.62]],"ltp":26.0,"tv":4541.13,"id":9632596},{"batb":[[0,1.07,353.07],[1,1.06,970.6],[2,1.05,1435.57]],"batl":[[0,1.09,742.63],[1,1.1,374.04],[2,1.11,322.5]],"ltp":1.02,"tv":10586.09,"id":9433864}]}]}
{"op":"mcm","clk":"4233879925","pt":1631539644144,"mc":[{"id":"1.187557653","rc":[{"batb":[[0,13,2.3],[1,12.5,17.16],[2,12,1.16]],"batl":[[1,17.5,7.62],[2,18,2]],"ltp":26.0,"tv":4541.13,"id":9632596},{"batb":[[0,1.06,1112.12],[1,1.05,1515.85],[2,1.04,792.92]],"batl":[[0,1.09,329.13]],"ltp":1.02,"tv":10586.09,"id":9433864}]}]}
{"op":"mcm","clk":"4233879941","pt":1631539644351,"mc":[{"id":"1.187557653","rc":[{"batb":[[0,1.06,998.9],[1,1.05,1459.25],[2,1.04,736.32]],"ltp":1.02,"tv":10586.09,"id":9433864}]}]}
{"op":"mcm","clk":"4233880289","pt":1631539648182,"mc":[{"id":"1.187557653","rc":[{"batb":[[0,1.07,84],[1,1.06,998.9],[2,1.05,1459.25]],"ltp":1.02,"tv":10586.09,"id":9433864}]}]}
{"op":"mcm","clk":"4233880841","pt":1631539654208,"mc":[{"id":"1.187557653","rc":[{"batb":[[0,11,4.48],[1,10,3.37],[2,9.4,22.25]],"batl":[[0,18,2],[1,17.5,0],[2,18,0]],"ltp":26.0,"tv":4541.13,"id":9632596},{"batb":[[1,1.06,970.6],[2,1.05,1435.57]],"batl":[[0,1.1,364.95],[1,1.11,322.5],[2,1.12,287.46]],"ltp":1.02,"tv":10586.09,"id":9433864}]}]}
{"op":"mcm","clk":"4233880945","pt":1631539654885,"mc":[{"id":"1.187557653","rc":[{"batb":[[0,10,3.37],[1,8.2,12.13],[2,1.01,113.68]],"ltp":26.0,"tv":4541.13,"id":9632596},{"batb":[[0,1.05,963.68],[1,1.04,669.95],[2,1.01,27.23]],"batl":[[0,1.37,1063.54],[1,1.11,0],[2,1.12,0]],"ltp":1.02,"tv":10586.09,"id":9433864}]}]}
{"op":"mcm","clk":"4233881294","pt":1631539658264,"mc":[{"id":"1.187557653","rc":[{"batl":[[0,1.11,292.5],[1,1.37,1063.54]],"ltp":1.02,"tv":10586.09,"id":9433864}]}]}
{"op":"mcm","clk":"4233881577","pt":1631539661092,"mc":[{"id":"1.187557653","rc":[{"batb":[[0,11,4.48],[1,10,3.37],[2,8.2,12.13]],"ltp":26.0,"tv":4541.13,"id":9632596},{"batl":[[0,1.1,340.65],[1,1.11,292.5],[2,1.37,1063.54]],"ltp":1.02,"tv":10586.09,"id":9433864}]}]}
{"op":"mcm","clk":"4233881611","pt":1631539661504,"mc":[{"id":"1.187557653","rc":[{"batb":[[0,10,3.37],[1,8.2,12.13],[2,1.01,113.68]],"ltp":26.0,"tv":4541.13,"id":9632596},{"batl":[[0,1.11,292.5],[1,1.37,1063.54],[2,1.37,0]],"ltp":1.02,"tv":10586.09,"id":9433864}]}]}
{"op":"mcm","clk":"4233881883","pt":1631539664288,"mc":[{"id":"1.187557653","rc":[{"batl":[[1,1.12,304.71],[2,1.37,1063.54]],"ltp":1.02,"tv":10586.09,"id":9433864}]}]}
{"op":"mcm","clk":"4233881928","pt":1631539664692,"mc":[{"id":"1.187557653","rc":[{"batb":[[0,11,4.48],[1,10,3.37],[2,8.2,12.13]],"ltp":26.0,"tv":4541.13,"id":9632596},{"batb":[[0,1.04,669.95],[1,1.01,27.23],[2,1.01,0]],"batl":[[0,1.1,348.05],[1,1.11,292.5]],"ltp":1.02,"tv":10586.09,"id":9433864}]}]}
{"op":"mcm","clk":"4233882051","pt":1631539666010,"mc":[{"id":"1.187557653","rc":[{"batb":[[0,14,14.28],[1,13.5,33.92],[2,13,1.12]],"batl":[[0,17.5,28.78],[1,21,4.07]],"ltp":26.0,"tv":4541.13,"id":9632596},{"batb":[[0,1.05,81.32],[1,1.04,669.95],[2,1.03,52.71]],"batl":[[0,1.08,689.15],[1,1.09,9.17],[2,1.1,348.05]],"ltp":1.02,"tv":10586.09,"id":9433864}]}]}
{"op":"mcm","clk":"4233882178","pt":1631539666993,"mc":[{"id":"1.187557653","rc":[{"batl":[[2,22,1.36]],"ltp":26.0,"tv":4541.13,"id":9632596},{"batb":[[1,1.04,679.57]],"ltp":1.02,"tv":10586.09,"id":9433864}]}]}
{"op":"mcm","clk":"4233882343","pt":1631539668709,"mc":[{"id":"1.187557653","rc":[{"batb":[[1,1.04,1831.98]],"ltp":1.02,"tv":10586.09,"id":9433864}]}]}
{"op":"mcm","clk":"4233882686","pt":1631539672201,"mc":[{"id":"1.187557653","rc":[{"trd":[[1.06,19.54]],"batb":[[0,1.06,79],[1,1.05,81.32],[2,1.04,1831.98]],"ltp":1.06,"tv":10586.13,"id":9433864}],"tv":15127.26}]}
{"op":"mcm","clk":"4233883834","pt":1631539684141,"mc":[{"id":"1.187557653","rc":[{"batb":[[0,11,4.48],[1,10,3.37],[2,9.2,3.37]],"ltp":26.0,"tv":4541.13,"id":9632596},{"batb":[[1,1.04,1152.42],[2,1.02,1102.55]],"batl":[[0,1.1,348.05],[1,1.11,292.5],[2,1.12,240.71]],"ltp":1.06,"tv":10586.13,"id":9433864}]}]}
{"op":"mcm","clk":"4233883894","pt":1631539684816,"mc":[{"id":"1.187557653","rc":[{"batb":[[0,9.2,3.37],[1,8.6,28.03],[2,1.01,113.68]],"ltp":26.0,"tv":4541.13,"id":9632596},{"batb":[[0,1.04,1152.42],[1,1.02,1102.55],[2,1.01,27.23]],"batl":[[0,1.12,240.71],[1,1.37,1063.54],[2,1.12,0]],"ltp":1.06,"tv":10586.13,"id":9433864}]}]}
{"op":"mcm","clk":"4233884479","pt":1631539691119,"mc":[{"id":"1.187557653","rc":[{"batb":[[0,11,3.39],[1,9.2,3.37],[2,8.6,28.03]],"ltp":26.0,"tv":4541.13,"id":9632596},{"batl":[[0,1.1,293.85],[1,1.11,298.5],[2,1.12,240.71]],"ltp":1.06,"tv":10586.13,"id":9433864}]}]}
{"op":"mcm","clk":"4233884519","pt":1631539691428,"mc":[{"id":"1.187557653","rc":[{"batb":[[0,9.2,3.37],[1,8.6,28.03],[2,1.01,113.68]],"ltp":26.0,"tv":4541.13,"id":9632596},{"batl":[[0,1.12,240.71],[1,1.37,1063.54],[2,1.12,0]],"ltp":1.06,"tv":10586.13,"id":9433864}]}]}
{"op":"mcm","clk":"4233884762","pt":1631539694032,"mc":[{"id":"1.187557653","rc":[{"batb":[[0,1.02,1102.55],[1,1.01,27.23],[2,1.01,0]],"ltp":1.06,"tv":10586.13,"id":9433864}]}]}
{"op":"mcm","clk":"4233884881","pt":1631539695238,"mc":[{"id":"1.187557653","rc":[{"batb":[[0,21,5.69],[1,18,8.32],[2,17.5,4.16]],"batl":[[0,34,76]],"ltp":26.0,"tv":4541.13,"id":9632596},{"batb":[[1,1.01,107.86]],"batl":[[0,1.05,113.87],[1,1.06,912.36],[2,1.07,9.35]],"ltp":1.06,"tv":10586.13,"id":9433864}]}]}
{"op":"mcm","clk":"4233884947","pt":1631539695873,"mc":[{"id":"1.187557653","rc":[{"batb":[[1,18,1.66],[2,17,1.68]],"batl":[[0,34,76.88]],"ltp":26.0,"tv":4541.13,"id":9632596},{"batb":[[0,1.03,9.71],[1,1.02,1102.55],[2,1.01,107.86]],"ltp":1.06,"tv":10586.13,"id":9433864}]}]}
{"op":"mcm","clk":"4233885210","pt":1631539698053,"mc":[{"id":"1.187557653","rc":[{"batb":[[1,1.02,3169.17]],"ltp":1.06,"tv":10586.13,"id":9433864}]}]}
{"op":"mcm","clk":"4233886080","pt":1631539707272,"mc":[{"id":"1.187557653","rc":[{"batb":[[1,14.5,13.39],[2,13.5,2.52]],"batl":[[0,34,76]],"ltp":26.0,"tv":4541.13,"id":9632596},{"batb":[[0,1.02,3169.17],[1,1.01,107.86],[2,1.01,0]],"batl":[[2,1.08,300.94]],"ltp":1.06,"tv":10586.13,"id":9433864}]}]}
{"op":"mcm","clk":"4233886180","pt":1631539708210,"mc":[{"id":"1.187557653","rc":[{"batb":[[0,11,2.74],[1,10.5,15.48],[2,9.2,3.37]],"ltp":26.0,"tv":4541.13,"id":9632596},{"batb":[[0,1.02,2066.62],[1,1.01,27.23]],"batl":[[0,1.1,268.15],[1,1.12,240.71],[2,1.37,1063.54]],"ltp":1.06,"tv":10586.13,"id":9433864}]}]}
{"op":"mcm","clk":"4233886326","pt":1631539709363,"mc":[{"id":"1.187557653","rc":[{"batb":[[0,1.01,27.23],[1,1.01,0]],"batl":[[2,1.37,0]],"ltp":1.06,"tv":10586.13,"id":9433864}]}]}
{"op":"mcm","clk":"4233886565","pt":1631539711405,"mc":[{"id":"1.187557653","rc":[{"batb":[[0,13.5,2.62],[1,11,2.74],[2,10.5,15.48]],"ltp":26.0,"tv":4541.13,"id":9632596},{"batl":[[0,1.08,292.44],[1,1.09,244.5],[2,1.1,268.15]],"ltp":1.06,"tv":10586.13,"id":9433864}]}]}
{"op":"mcm","clk":"4233886716","pt":1631539713166,"mc":[{"id":"1.187557653","rc":[{"batb":[[1,13,2.49],[2,11.5,2.52]],"ltp":26.0,"tv":4541.13,"id":9632596}]}]}
{"op":"mcm","clk":"4233886812","pt":1631539714205,"mc":[{"id":"1.187557653","rc":[{"batb":[[0,13.5,19.83]],"batl":[[0,16.5,12.12],[1,21,42.88],[2,22,1.36]],"ltp":26.0,"tv":4541.13,"id":9632596},{"batb":[[0,1.05,857.64],[1,1.04,9.62],[2,1.03,52.71]],"batl":[[0,1.08,507.55]],"ltp":1.06,"tv":10586.13,"id":9433864}]}]}
{"op":"mcm","clk":"4233886890","pt":1631539714888,"mc":[{"id":"1.187557653","rc":[{"batb":[[0,14,2.14],[1,13.5,20.91],[2,13,3.57]],"ltp":26.0,"tv":4541.13,"id":9632596},{"batb":[[1,1.04,676.55]],"batl":[[1,1.09,253.67]],"ltp":1.06,"tv":10586.13,"id":9433864}]}]}
{"op":"mcm","clk":"4233886961","pt":1631539715677,"mc":[{"id":"1.187557653","rc":[{"batb":[[1,1.04,1828.97]],"ltp":1.06,"tv":10586.13,"id":9433864}]}]}
{"op":"mcm","clk":"4233887284","pt":1631539718705,"mc":[{"id":"1.187557653","rc":[{"batb":[[1,13.5,18.29],[2,13,1.08]],"ltp":26.0,"tv":4541.13,"id":9632596}]}]}
{"op":"mcm","clk":"4233887937","pt":1631539725118,"mc":[{"id":"1.187557653","rc":[{"batb":[[0,10.5,15.48],[1,9.2,3.37],[2,8.4,28.86]],"ltp":26.0,"tv":4541.13,"id":9632596},{"batb":[[0,1.04,1819.35],[1,1.03,52.71],[2,1.02,1103.05]],"batl":[[0,1.12,289.19],[1,1.14,23.81],[2,1.37,1112.19]],"ltp":1.06,"tv":10586.13,"id":9433864}]}]}
{"op":"mcm","clk":"4233887962","pt":1631539725431,"mc":[{"id":"1.187557653","rc":[{"batb":[[0,9.2,3.37],[1,8.4,28.86],[2,1.01,113.68]],"ltp":26.0,"tv":4541.13,"id":9632596},{"batb":[[0,1.04,1152.42],[1,1.02,1103.05],[2,1.01,27.23]],"batl":[[0,1.12,240.71],[1,1.37,1112.19],[2,1.37,0]],"ltp":1.06,"tv":10586.13,"id":9433864}]}]}
{"op":"mcm","clk":"4233888467","pt":1631539729829,"mc":[{"id":"1.187557653","rc":[{"batb":[[0,1.08,10],[1,1.04,1152.42],[2,1.02,1103.05]],"ltp":1.06,"tv":10586.13,"id":9433864}]}]}
{"op":"mcm","clk":"4233888976","pt":1631539734835,"mc":[{"id":"1.187557653","rc":[{"trd":[[9.2,50.71]],"batb":[[0,8.4,28.86],[1,1.01,113.68],[2,1.01,0]],"ltp":9.2,"tv":4554.24,"id":9632596},{"trd":[[1.12,1143.73]],"batl":[[0,1.12,188.36]],"ltp":1.12,"tv":10638.48,"id":9433864}],"tv":15192.72}]}
{"op":"mcm","clk":"4233889068","pt":1631539735619,"mc":[{"id":"1.187557653","rc":[{"batb":[[0,11,3.24],[1,8.4,28.86],[2,1.01,113.68]],"ltp":9.2,"tv":4554.24,"id":9632596},{"batl":[[0,1.1,297.65],[1,1.11,263.5],[2,1.12,188.36]],"ltp":1.12,"tv":10638.48,"id":9433864}]}]}
{"op":"mcm","clk":"4233889210","pt":1631539736833,"mc":[{"id":"1.187557653","rc":[{"batb":[[1,1.02,1103.05],[2,1.01,27.23]],"ltp":1.12,"tv":10638.48,"id":9433864}]}]}
{"op":"mcm","clk":"4233889337","pt":1631539738028,"mc":[{"id":"1.187557653","rc":[{"batb":[[1,9.2,3.32],[2,8.4,28.86]],"ltp":9.2,"tv":4554.24,"id":9632596},{"batl":[[0,1.1,302.98]],"ltp":1.12,"tv":10638.48,"id":9433864}]}]}
{"op":"mcm","clk":"4233889461","pt":1631539739322,"mc":[{"id":"1.187557653","rc":[{"batb":[[1,10,4.48],[2,9.2,3.32]],"ltp":9.2,"tv":4554.24,"id":9632596}]}]}
{"op":"mcm","clk":"4233889644","pt":1631539740941,"mc":[{"id":"1.187557653","rc":[{"batl":[[0,48,65.13]],"ltp":9.2,"tv":4554.24,"id":9632596}]}]}
{"op":"mcm","clk":"4233891446","pt":1631539759562,"mc":[{"id":"1.187557653","rc":[{"batb":[[0,9.2,3.32],[1,8.4,28.86],[2,1.01,113.68]],"ltp":9.2,"tv":4554.24,"id":9632596},{"batl":[[0,1.1,5.33],[1,1.11,0],[2,1.12,0]],"ltp":1.12,"tv":10638.48,"id":9433864}]}]}
{"op":"mcm","clk":"4233891799","pt":1631539763091,"mc":[{"id":"1.187557653","rc":[{"batb":[[0,10,4.48],[1,9.2,3.32],[2,8.4,28.86]],"ltp":9.2,"tv":4554.24,"id":9632596},{"batl":[[1,1.11,337.5],[2,1.12,267.21]],"ltp":1.12,"tv":10638.48,"id":9433864}]}]}
{"op":"mcm","clk":"4233891839","pt":1631539763360,"mc":[{"id":"1.187557653","rc":[{"batb":[[0,9.2,3.32],[1,8.4,28.86],[2,1.01,113.68]],"ltp":9.2,"tv":4554.24,"id":9632596},{"batl":[[1,1.12,267.21],[2,1.12,0]],"ltp":1.12,"tv":10638.48,"id":9433864}]}]}
{"op":"mcm","clk":"4233892392","pt":1631539768992,"mc":[{"id":"1.187557653","rc":[{"trd":[[13.5,0.86]],"batl":[[0,13.5,16.29],[1,15,5.03]],"ltp":13.5,"tv":4555.1,"id":9632596},{"trd":[[1.08,30.76]],"batb":[[0,1.08,214.35],[1,1.05,51.71],[2,1.03,26.36]],"batl":[[1,1.11,658.78],[2,1.12,267.21]],"ltp":1.08,"tv":10669.24,"id":9433864}],"tv":15224.34}]}
{"op":"mcm","clk":"4233892504","pt":1631539770083,"mc":[{"id":"1.187557653","rc":[{"batb":[[2,5.5,32.71]],"ltp":13.5,"tv":4555.1,"id":9632596},{"batb":[[1,1.07,463.56],[2,1.05,51.71]],"batl":[[1,1.11,667.79],[2,1.12,293.99]],"ltp":1.08,"tv":10669.24,"id":9433864}]}]}
{"op":"mcm","clk":"4233892590","pt":1631539771008,"mc":[{"id":"1.187557653","rc":[{"trd":[[1.08,46.32]],"batb":[[0,1.08,206.57],[2,1.05,1015.39]],"ltp":1.08,"tv":10684.8,"id":9433864}],"tv":15239.9}]}
{"op":"mcm","clk":"4233893125","pt":1631539776329,"mc":[{"id":"1.187557653","rc":[{"batb":[[0,1.08,285.57]],"ltp":1.08,"tv":10684.8,"id":9433864}]}]}
{"op":"mcm","clk":"4233893370","pt":1631539778927,"mc":[{"id":"1.187557653","rc":[{"batl":[[1,15,0]],"ltp":13.5,"tv":4555.1,"id":9632596}]}]}
{"op":"mcm","clk":"4233893500","pt":1631539780021,"mc":[{"id":"1.187557653","rc":[{"trd":[[1.1,10.66]],"batb":[[0,1.1,4.67],[1,1.08,285.57],[2,1.07,463.56]],"batl":[[0,1.11,667.79],[1,1.12,293.99],[2,1.13,13.4]],"ltp":1.1,"tv":10695.46,"id":9433864}],"tv":15250.56}]}
{"op":"mcm","clk":"4233893714","pt":1631539782106,"mc":[{"id":"1.187557653","rc":[{"batb":[[0,9.6,198.42],[1,9.2,3.32],[2,8.4,28.86]],"batl":[[1,15,6.53]],"ltp":13.5,"tv":4555.1,"id":9632596},{"trd":[[1.08,49.72],[1.1,20]],"batb":[[0,1.08,283.87],[1,1.07,463.56],[2,1.05,1015.39]],"batl":[[0,1.09,119.98],[1,1.11,667.79],[2,1.12,293.99]],"ltp":1.08,"tv":10708.2,"id":9433864}],"tv":15263.31}]}
{"op":"mcm","clk":"4233893732","pt":1631539782313,"mc":[{"id":"1.187557653","rc":[{"batb":[[0,9.2,3.32],[1,8.4,28.86],[2,5.5,32.71]],"ltp":13.5,"tv":4555.1,"id":9632596}]}]}
{"op":"mcm","clk":"4233894329","pt":1631539788430,"mc":[{"id":"1.187557653","rc":[{"batb":[[0,9.4,292.75],[1,9.2,3.32],[2,8.4,28.86]],"ltp":13.5,"tv":4555.1,"id":9632596}]}]}
{"op":"mcm","clk":"4233894683","pt":1631539792029,"mc":[{"id":"1.187557653","rc":[{"batl":[[1,15,0]],"ltp":13.5,"tv":4555.1,"id":9632596},{"batl":[[0,1.11,667.79],[1,1.12,293.99],[2,1.13,13.4]],"ltp":1.08,"tv":10708.2,"id":9433864}]}]}
{"op":"mcm","clk":"4233894732","pt":1631539792548,"mc":[{"id":"1.187557653","rc":[{"batb":[[0,9.2,3.32],[1,8.4,28.86],[2,5.5,32.71]],"ltp":13.5,"tv":4555.1,"id":9632596}]}]}
{"op":"mcm","clk":"4233894980","pt":1631539795166,"mc":[{"id":"1.187557653","rc":[{"batl":[[1,15,6.88]],"ltp":13.5,"tv":4555.1,"id":9632596},{"trd":[[1.09,48.32]],"batl":[[0,1.09,105.48],[1,1.11,667.79],[2,1.12,293.99]],"ltp":1.09,"tv":10737.11,"id":9433864}],"tv":15292.21}]}
{"op":"mcm","clk":"4233895573","pt":1631539801339,"mc":[{"id":"1.187557653","rc":[{"batb":[[0,9.4,356.98],[1,9.2,3.32],[2,8.4,28.86]],"ltp":13.5,"tv":4555.1,"id":9632596}]}]}
{"op":"mcm","clk":"4233896137","pt":1631539805953,"mc":[{"id":"1.187557653","rc":[{"batb":[[0,9.2,3.32],[1,8.4,28.86],[2,5.5,32.71]],"batl":[[1,15,0]],"ltp":13.5,"tv":4555.1,"id":9632596},{"batl":[[0,1.11,667.79],[1,1.12,293.99],[2,1.13,13.4]],"ltp":1.09,"tv":10737.11,"id":9433864}]}]}
{"op":"mcm","clk":"4233896431","pt":1631539808253,"mc":[{"id":"1.187557653","rc":[{"batl":[[1,15,7.94]],"ltp":13.5,"tv":4555.1,"id":9632596},{"batl":[[0,1.09,105.48],[1,1.11,667.79],[2,1.12,293.99]],"ltp":1.09,"tv":10737.11,"id":9433864}]}]}
{"op":"mcm","clk":"4233897197","pt":1631539815097,"mc":[{"id":"1.187557653","rc":[{"batb":[[0,9.4,337.94],[1,9.2,3.32],[2,8.4,28.86]],"ltp":13.5,"tv":4555.1,"id":9632596}]}]}
{"op":"mcm","clk":"4233897338","pt":1631539816511,"mc":[{"id":"1.187557653","rc":[{"trd":[[12,7.45]],"ltp":12.0,"tv":4557.49,"id":9632596},{"trd":[[1.08,51.52],[1.09,74.63]],"batb":[[0,1.08,282.97]],"batl":[[0,1.09,79.17]],"ltp":1.09,"tv":10765.22,"id":9433864}],"tv":15322.71}]}
{"op":"mcm","clk":"4233897721","pt":1631539820116,"mc":[{"id":"1.187557653","rc":[{"trd":[[12,9.84]],"ltp":12.0,"tv":4559.88,"id":9632596},{"trd":[[1.09,100.94]],"batl":[[0,1.09,52.86]],"ltp":1.09,"tv":10791.53,"id":9433864}],"tv":15351.41}]}
{"op":"mcm","clk":"4233897970","pt":1631539822685,"mc":[{"id":"1.187557653","rc":[{"trd":[[1.09,206.66]],"batb":[[0,1.1,2918.64],[1,1.08,282.97],[2,1.07,463.56]],"batl":[[0,1.11,667.79],[1,1.12,293.99],[2,1.13,13.4]],"ltp":1.09,"tv":10897.25,"id":9433864}],"tv":15457.13}]}
{"op":"mcm","clk":"4233898107","pt":1631539823903,"mc":[{"id":"1.187557653","rc":[{"trd":[[10,2]],"batb":[[0,9.2,3.32],[1,8.4,28.86],[2,5.5,32.71]],"ltp":10.0,"tv":4561.88,"id":9632596},{"trd":[[1.11,93.05]],"batl":[[0,1.11,649.77]],"ltp":1.11,"tv":10915.27,"id":9433864}],"tv":15477.15}]}
{"op":"mcm","clk":"4233898431","pt":1631539826728,"mc":[{"id":"1.187557653","rc":[{"batl":[[1,15,0]],"ltp":10.0,"tv":4561.88,"id":9632596}]}]}
{"op":"mcm","clk":"4233898723","pt":1631539829595,"mc":[{"id":"1.187557653","rc":[{"trd":[[11,4.22]],"batl":[[0,13.5,20.51]],"ltp":11.0,"tv":4566.1,"id":9632596},{"trd":[[1.1,146.5]],"batb":[[0,1.1,2834.29],[1,1.08,335.67]],"ltp":1.1,"tv":11041.77,"id":9433864}],"tv":15607.87}]}
{"op":"mcm","clk":"4233898803","pt":1631539830327,"mc":[{"id":"1.187557653","rc":[{"batl":[[0,13.5,16.29]],"ltp":11.0,"tv":4566.1,"id":9632596},{"batb":[[1,1.08,282.97]],"ltp":1.1,"tv":11041.77,"id":9433864}]}]}
{"op":"mcm","clk":"4233898944","pt":1631539831843,"mc":[{"id":"1.187557653","rc":[{"batl":[[0,13.5,16.74]],"ltp":11.0,"tv":4566.1,"id":9632596}]}]}
{"op":"mcm","clk":"4233899090","pt":1631539833251,"mc":[{"id":"1.187557653","rc":[{"batl":[[0,12,7.43],[1,13.5,16.29]],"ltp":11.0,"tv":4566.1,"id":9632596},{"batl":[[0,1.11,719.44]],"ltp":1.1,"tv":11041.77,"id":9433864}]}]}
{"op":"mcm","clk":"4233899148","pt":1631539833725,"mc":[{"id":"1.187557653","rc":[{"batl":[[0,13.5,16.74],[1,13.5,0]],"ltp":11.0,"tv":4566.1,"id":9632596},{"trd":[[1.11,1392.59]],"batb":[[0,1.11,2321.73],[1,1.1,2834.29],[2,1.08,282.97]],"batl":[[0,1.12,293.99],[1,1.13,13.4],[2,1.14,61.03]],"ltp":1.11,"tv":12341.31,"id":9433864}],"tv":16907.41}]}
{"op":"mcm","clk":"4233899487","pt":1631539837127,"mc":[{"id":"1.187557653","rc":[{"batb":[[1,5.5,32.71],[2,1.01,113.68]],"batl":[[0,12,0.45]],"ltp":11.0,"tv":4566.1,"id":9632596},{"trd":[[1.11,1531.93]],"batb":[[0,1.11,2252.06],[2,1.08,79]],"batl":[[2,1.14,13.4]],"ltp":1.11,"tv":12480.65,"id":9433864}],"tv":17046.75}]}
{"op":"mcm","clk":"4233899831","pt":1631539840416,"mc":[{"id":"1.187557653","rc":[{"trd":[[1.11,1533.73]],"batb":[[0,1.11,2251.16]],"ltp":1.11,"tv":12482.45,"id":9433864}],"tv":17048.55}]}
{"op":"mcm","clk":"4233899969","pt":1631539841977,"mc":[{"id":"1.187557653","rc":[{"batb":[[1,1.08,79],[2,1.05,963.68]],"ltp":1.11,"tv":12482.45,"id":9433864}]}]}
{"op":"mcm","clk":"4233900136","pt":1631539843756,"mc":[{"id":"1.187557653","rc":[{"batb":[[0,1.08,79],[1,1.05,963.68],[2,1.03,891.9]],"ltp":1.11,"tv":12482.45,"id":9433864}]}]}
{"op":"mcm","clk":"4233901594","pt":1631539858161,"mc":[{"id":"1.187557653","rc":[{"batl":[[0,610,5.02]],"ltp":11.0,"tv":4566.1,"id":9632596}]}]}
{"op":"mcm","clk":"4233901682","pt":1631539859092,"mc":[{"id":"1.187557653","rc":[{"batb":[[1,5.5,37.65],[2,4.8,4.78]],"ltp":11.0,"tv":4566.1,"id":9632596},{"batl":[[0,1.09,50],[1,1.12,293.99],[2,1.13,13.4]],"ltp":1.11,"tv":12482.45,"id":9433864}]}]}
{"op":"mcm","clk":"4233902014","pt":1631539862390,"mc":[{"id":"1.187557653","rc":[{"batl":[[0,930,3.29]],"ltp":11.0,"tv":4566.1,"id":9632596}]}]}
{"op":"mcm","clk":"4233902257","pt":1631539865203,"mc":[{"id":"1.187557653","rc":[{"batb":[[0,9.8,202.28],[1,9.2,3.32],[2,5.5,37.65]],"ltp":11.0,"tv":4566.1,"id":9632596},{"batl":[[0,1.12,267.21],[1,1.22,182.25],[2,1.26,163.25]],"ltp":1.11,"tv":12482.45,"id":9433864}]}]}
{"op":"mcm","clk":"4233902325","pt":1631539865887,"mc":[{"id":"1.187557653","rc":[{"batb":[[0,5.5,32.71],[1,4.1,4.04],[2,3.55,4.59]],"ltp":11.0,"tv":4566.1,"id":9632596},{"batb":[[0,1.05,963.68],[1,1.03,891.9],[2,1.01,27.23]],"batl":[[0,1.32,120.11],[1,1.38,1073.04],[2,1.39,98.5]],"ltp":1.11,"tv":12482.45,"id":9433864}]}]}
{"op":"mcm","clk":"4233902409","pt":1631539866680,"mc":[{"id":"1.187557653","rc":[{"batb":[[0,1.03,891.9],[1,1.01,27.23],[2,1.01,0]],"batl":[[1,1.39,98.5],[2,1.39,0]],"ltp":1.11,"tv":12482.45,"id":9433864}]}]}
{"op":"mcm","clk":"4233903031","pt":1631539872512,"mc":[{"id":"1.187557653","rc":[{"batb":[[0,1.03,892.8]],"ltp":1.11,"tv":12482.45,"id":9433864}]}]}
{"op":"mcm","clk":"4233903128","pt":1631539873505,"mc":[{"id":"1.187557653","rc":[{"batb":[[1,3.55,4.59],[2,1.01,113.68]],"ltp":11.0,"tv":4566.1,"id":9632596}]}]}
{"op":"mcm","clk":"4233903232","pt":1631539874700,"mc":[{"id":"1.187557653","rc":[{"batb":[[0,1.04,8.68],[1,1.03,891.9],[2,1.01,27.23]],"ltp":1.11,"tv":12482.45,"id":9433864}]}]}
{"op":"mcm","clk":"4233903386","pt":1631539876212,"mc":[{"id":"1.187557653","rc":[{"batb":[[0,18.5,4.87],[1,18,2.44],[2,17.5,2.44]],"batl":[[0,21,4.2],[1,26,31.11]],"ltp":11.0,"tv":4566.1,"id":9632596},{"trd":[[1.09,208.46]],"batb":[[0,1.05,83.96],[1,1.04,785.59],[2,1.03,891.9]],"batl":[[0,1.07,99.33],[1,1.14,275.25]],"ltp":1.09,"tv":12484.25,"id":9433864}],"tv":17050.35}]}
{"op":"mcm","clk":"4233903469","pt":1631539877142,"mc":[{"id":"1.187557653","rc":[{"batl":[[2,28,5.36]],"ltp":11.0,"tv":4566.1,"id":9632596},{"batl":[[1,1.09,49.81],[2,1.11,24.46]],"ltp":1.09,"tv":12484.25,"id":9433864}]}]}
{"op":"mcm","clk":"4233903569","pt":1631539878129,"mc":[{"id":"1.187557653","rc":[{"batb":[[0,18.5,1.62],[1,17.5,1.64],[2,15.5,7.74]],"batl":[[2,28,1.08]],"ltp":11.0,"tv":4566.1,"id":9632596}]}]}
{"op":"mcm","clk":"4233904428","pt":1631539886427,"mc":[{"id":"1.187557653","rc":[{"trd":[[1.05,103.06]],"batb":[[0,1.05,33.76]],"ltp":1.05,"tv":12584.65,"id":9433864}],"tv":17150.75}]}
{"op":"mcm","clk":"4233904793","pt":1631539889866,"mc":[{"id":"1.187557653","rc":[{"batb":[[1,1.04,777.81]],"ltp":1.05,"tv":12584.65,"id":9433864}]}]}
{"op":"mcm","clk":"4233905542","pt":1631539897248,"mc":[{"id":"1.187557653","rc":[{"batb":[[0,13,9.37],[1,7.8,13.55],[2,1.01,113.68]],"ltp":11.0,"tv":4566.1,"id":9632596},{"batb":[[0,1.03,891.9],[1,1.02,2066.62],[2,1.01,107.86]],"batl":[[0,1.09,49.81],[1,1.11,24.46],[2,1.15,182.3]],"ltp":1.05,"tv":12584.65,"id":9433864}]}]}
{"op":"mcm","clk":"4233905596","pt":1631539897764,"mc":[{"id":"1.187557653","rc":[{"batb":[[0,9.2,2]],"ltp":11.0,"tv":4566.1,"id":9632596},{"batb":[[0,1.02,2066.62],[1,1.01,27.23],[2,1.01,0]],"batl":[[0,1.12,228.96],[1,1.34,1214.83],[2,1.15,0]],"ltp":1.05,"tv":12584.65,"id":9433864}]}]}
{"op":"mcm","clk":"4233905729","pt":1631539899167,"mc":[{"id":"1.187557653","rc":[{"batb":[[0,1.01,27.23],[1,1.01,0]],"batl":[[1,1.34,0]],"ltp":1.05,"tv":12584.65,"id":9433864}]}]}
{"op":"mcm","clk":"4233905814","pt":1631539900050,"mc":[{"id":"1.187557653","rc":[{"batb":[[0,1.04,94],[1,1.01,27.23]],"batl":[[0,1.05,22.2],[1,1.12,228.96]],"ltp":1.05,"tv":12584.65,"id":9433864}]}]}
{"op":"mcm","clk":"4233905929","pt":1631539901140,"mc":[{"id":"1.187557653","rc":[{"trd":[[1.05,105.38]],"batb":[[0,1.01,27.23],[1,1.01,0]],"batl":[[0,1.05,21.04]],"ltp":1.05,"tv":12586.97,"id":9433864}],"tv":17153.07}]}
{"op":"mcm","clk":"4233906018","pt":1631539902176,"mc":[{"id":"1.187557653","rc":[{"trd":[[19.5,1.14],[21,1.05]],"ltp":19.5,"tv":4568.29,"id":9632596},{"trd":[[1.05,147.67]],"batl":[[0,1.12,228.96],[1,1.12,0]],"ltp":1.05,"tv":12629.26,"id":9433864}],"tv":17197.55}]}
{"op":"mcm","clk":"4233906210","pt":1631539904163,"mc":[{"id":"1.187557653","rc":[{"batb":[[0,1.03,1458.09],[1,1.01,27.23]],"batl":[[1,1.35,1160.37]],"ltp":1.05,"tv":12629.26,"id":9433864}]}]}
{"op":"mcm","clk":"4233906846","pt":1631539910310,"mc":[{"id":"1.187557653","rc":[{"batb":[[0,1.01,27.23],[1,1.01,0]],"batl":[[1,1.35,0]],"ltp":1.05,"tv":12629.26,"id":9433864}]}]}
{"op":"mcm","clk":"4233908102","pt":1631539921981,"mc":[{"id":"1.187557653","rc":[{"batl":[[1,1.15,149.5],[2,1.17,147.5]],"ltp":1.05,"tv":12629.26,"id":9433864}]}]}
{"op":"mcm","clk":"4233908139","pt":1631539922309,"mc":[{"id":"1.187557653","rc":[{"batl":[[1,1.15,0],[2,1.17,0]],"ltp":1.05,"tv":12629.26,"id":9433864}]}]}
{"op":"mcm","clk":"4233908860","pt":1631539929206,"mc":[{"id":"1.187557653","rc":[{"batl":[[0,1.15,161.7],[1,1.17,160.5],[2,1.19,116.5]],"ltp":1.05,"tv":12629.26,"id":9433864}]}]}
{"op":"mcm","clk":"4233909050","pt":1631539931222,"mc":[{"id":"1.187557653","rc":[{"batb":[[0,30,5],[1,24,8.34],[2,9.2,2]],"batl":[[0,50,3.51],[1,100,56.62]],"ltp":19.5,"tv":4568.29,"id":9632596},{"batl":[[0,1.03,3891.34],[1,1.04,34.62],[2,1.07,932.24]],"ltp":1.05,"tv":12629.26,"id":9433864}]}]}
{"op":"mcm","clk":"4233909160","pt":1631539932215,"mc":[{"id":"1.187557653","rc":[{"trd":[[50,5.94]],"batb":[[0,30,3],[1,24,5],[2,21,7.47]],"batl":[[0,100,56.62],[1,100,0]],"ltp":50.0,"tv":4574.23,"id":9632596},{"trd":[[1.02,184.96]],"batl":[[0,1.02,292.81],[1,1.03,141.34],[2,1.04,9.62]],"ltp":1.02,"tv":12682.2,"id":9433864}],"tv":17256.43}]}
{"op":"mcm","clk":"4233909370","pt":1631539934308,"mc":[{"id":"1.187557653","rc":[{"trd":[[1.02,188.96]],"batl":[[0,1.02,290.81]],"ltp":1.02,"tv":12686.2,"id":9433864}],"tv":17260.43}]}
{"op":"mcm","clk":"4233909827","pt":1631539938641,"mc":[{"id":"1.187557653","rc":[{"batb":[[1,26,2],[2,24,5]],"ltp":50.0,"tv":4574.23,"id":9632596},{"batl":[[2,1.04,567.25]],"ltp":1.02,"tv":12686.2,"id":9433864}]}]}
{"op":"mcm","clk":"4233909954","pt":1631539939843,"mc":[{"id":"1.187557653","rc":[{"trd":[[1.02,205.44]],"batl":[[0,1.02,282.57]],"ltp":1.02,"tv":12702.67,"id":9433864}],"tv":17276.91}]}
{"op":"mcm","clk":"4233910083","pt":1631539941516,"mc":[{"id":"1.187557653","rc":[{"batl":[[1,1.04,567.25],[2,1.05,532.1]],"ltp":1.02,"tv":12702.67,"id":9433864}]}]}
{"op":"mcm","clk":"4233910363","pt":1631539944122,"mc":[{"id":"1.187557653","rc":[{"trd":[[1.02,216.1]],"batl":[[0,1.02,277.24]],"ltp":1.02,"tv":12713.33,"id":9433864}],"tv":17287.57}]}
{"op":"mcm","clk":"4233910394","pt":1631539944438,"mc":[{"id":"1.187557653","rc":[{"batl":[[0,100,66.67]],"ltp":50.0,"tv":4574.23,"id":9632596},{"batl":[[1,1.03,311.97],[2,1.04,567.25]],"ltp":1.02,"tv":12713.33,"id":9433864}]}]}
{"op":"mcm","clk":"4233911185","pt":1631539952226,"mc":[{"id":"1.187557653","rc":[{"batb":[[0,26,2],[1,21,7.47],[2,17.5,2]],"ltp":50.0,"tv":4574.23,"id":9632596},{"batl":[[2,1.04,557.63]],"ltp":1.02,"tv":12713.33,"id":9433864}]}]}
{"op":"mcm","clk":"4233911241","pt":1631539952742,"mc":[{"id":"1.187557653","rc":[{"batb":[[0,17.5,2],[1,13,9.29],[2,1.01,113.68]],"ltp":50.0,"tv":4574.23,"id":9632596},{"batl":[[0,1.06,378.25],[1,1.29,1386.9],[2,1.04,0]],"ltp":1.02,"tv":12713.33,"id":9433864}]}]}
{"op":"mcm","clk":"4233911355","pt":1631539953961,"mc":[{"id":"1.187557653","rc":[{"batl":[[1,1.29,0]],"ltp":1.02,"tv":12713.33,"id":9433864}]}]}
{"op":"mcm","clk":"4233911707","pt":1631539957262,"mc":[{"id":"1.187557653","rc":[{"batb":[[0,1.01,28]],"ltp":1.02,"tv":12713.33,"id":9433864}]}]}
{"op":"mcm","clk":"4233911867","pt":1631539959028,"mc":[{"id":"1.187557653","rc":[{"batb":[[0,29,2],[1,28,2],[2,27,2]],"ltp":50.0,"tv":4574.23,"id":9632596}]}]}
{"op":"mcm","clk":"4233911965","pt":1631539960071,"mc":[{"id":"1.187557653","rc":[{"batb":[[0,17.5,2],[1,13,9.29],[2,1.01,113.68]],"ltp":50.0,"tv":4574.23,"id":9632596}]}]}
{"op":"mcm","clk":"4233912272","pt":1631539963277,"mc":[{"id":"1.187557653","rc":[{"batl":[[0,1.04,632.88],[1,1.05,485.7]],"ltp":1.02,"tv":12713.33,"id":9433864}]}]}
{"op":"mcm","clk":"4233912370","pt":1631539964278,"mc":[{"id":"1.187557653","rc":[{"batb":[[0,100,2],[1,36,1.12],[2,17.5,2]],"batl":[[0,490,12.73]],"ltp":50.0,"tv":4574.23,"id":9632596},{"trd":[[1.01,54.45],[1.02,217.64]],"batl":[[0,1.01,227.5],[1,1.03,941.95],[2,1.04,632.88]],"ltp":1.01,"tv":12769.32,"id":9433864}],"tv":17343.56}]}
{"op":"mcm","clk":"4233912456","pt":1631539965066,"mc":[{"id":"1.187557653","rc":[{"batb":[[2,25,7.53]],"ltp":50.0,"tv":4574.23,"id":9632596}]}]}
{"op":"mcm","clk":"4233912842","pt":1631539969186,"mc":[{"id":"1.187557653","rc":[{"trd":[[1.01,58.45]],"batl":[[0,1.01,225.5]],"ltp":1.01,"tv":12773.32,"id":9433864}],"tv":17347.56}]}
{"op":"mcm","clk":"4233914171","pt":1631539984015,"mc":[{"id":"1.187557653","rc":[{"batl":[[0,1.01,310.66]],"ltp":1.01,"tv":12773.32,"id":9433864}]}]}
{"op":"mcm","clk":"4233914737","pt":1631539989989,"mc":[{"id":"1.187557653","rc":[{"batb":[[0,36,1.12],[1,25,7.53],[2,1.01,113.68]],"ltp":50.0,"tv":4574.23,"id":9632596},{"batl":[[0,1.01,85.16],[1,1.03,9.71]],"ltp":1.01,"tv":12773.32,"id":9433864}]}]}
{"op":"mcm","clk":"4233914925","pt":1631539991701,"mc":[{"id":"1.187557653","rc":[{"trd":[[1.01,60.77]],"batl":[[0,1.01,84.01]],"ltp":1.01,"tv":12775.64,"id":9433864}],"tv":17349.88}]}
{"op":"mcm","clk":"4233915056","pt":1631539993108,"mc":[{"id":"1.187557653","rc":[{"batb":[[1,1.01,113.68],[2,1.01,0]],"ltp":50.0,"tv":4574.23,"id":9632596}]}]}
{"op":"mcm","clk":"4233915126","pt":1631539993857,"mc":[{"id":"1.187557653","marketDefinition":{"bspMarket":false,"turnInPlayEnabled":true,"persistenceEnabled":true,"marketBaseRate":5.0,"eventId":"30896062","eventTypeId":"2","numberOfWinners":1,"bettingType":"ODDS","marketType":"MATCH_ODDS","marketTime":"2021-09-13T10:58:00.000Z","suspendTime":"2021-09-13T10:58:00.000Z","bspReconciled":false,"complete":true,"inPlay":true,"crossMatching":true,"runnersVoidable":false,"numberOfActiveRunners":2,"betDelay":3,"status":"SUSPENDED","runners":[{"status":"ACTIVE","sortPriority":1,"id":9433864,"name":"Vitaliy Sachko"},{"status":"ACTIVE","sortPriority":2,"id":9632596,"name":"Bogdan Bobrov"}],"regulators":["MR_INT"],"countryCode":"PL","discountAllowed":true,"timezone":"UTC","openDate":"2021-09-13T10:58:00.000Z","version":4030716464,"name":"Match Odds","eventName":"Vi Sachko v Bobrov"},"rc":[{"batl":[[2,1.04,0]],"ltp":1.01,"tv":12775.64,"id":9433864}]}]}
{"op":"mcm","clk":"4233919739","pt":1631540044491,"mc":[{"id":"1.187557653","rc":[{"batl":[[0,1.03,9.71],[1,1.03,0]],"ltp":1.01,"tv":12775.64,"id":9433864}]}]}
{"op":"mcm","clk":"4233920742","pt":1631540055285,"mc":[{"id":"1.187557653","rc":[{"batb":[[0,1.01,114.24],[1,1.01,0]],"ltp":50.0,"tv":4574.23,"id":9632596}]}]}
{"op":"mcm","clk":"4233920752","pt":1631540055391,"mc":[{"id":"1.187557653","rc":[{"batb":[[0,1.01,113.68]],"ltp":50.0,"tv":4574.23,"id":9632596}]}]}
{"op":"mcm","clk":"4233924693","pt":1631540095288,"mc":[{"id":"1.187557653","tv":0.0}]}
{"op":"mcm","clk":"4233924935","pt":1631540097446,"mc":[{"id":"1.187557653","marketDefinition":{"bspMarket":false,"turnInPlayEnabled":true,"persistenceEnabled":true,"marketBaseRate":5.0,"eventId":"30896062","eventTypeId":"2","numberOfWinners":1,"bettingType":"ODDS","marketType":"MATCH_ODDS","marketTime":"2021-09-13T10:58:00.000Z","suspendTime":"2021-09-13T10:58:00.000Z","bspReconciled":false,"complete":true,"inPlay":true,"crossMatching":false,"runnersVoidable":false,"numberOfActiveRunners":0,"betDelay":3,"status":"CLOSED","settledTime":"2021-09-13T13:34:48.000Z","runners":[{"status":"WINNER","sortPriority":1,"id":9433864,"name":"Vitaliy Sachko"},{"status":"LOSER","sortPriority":2,"id":9632596,"name":"Bogdan Bobrov"}],"regulators":["MR_INT"],"countryCode":"PL","discountAllowed":true,"timezone":"UTC","openDate":"2021-09-13T10:58:00.000Z","version":4030718974,"name":"Match Odds","eventName":"Vi Sachko v Bobrov"}}]}
