{"op":"mcm","clk":"4232373727","pt":1631518765810,"mc":[{"id":"1.187595436","marketDefinition":{"bspMarket":false,"turnInPlayEnabled":true,"persistenceEnabled":true,"marketBaseRate":5.0,"eventId":"30897919","eventTypeId":"2","numberOfWinners":1,"bettingType":"ODDS","marketType":"MATCH_ODDS","marketTime":"2021-09-13T08:00:00.000Z","suspendTime":"2021-09-13T08:00:00.000Z","bspReconciled":false,"complete":true,"inPlay":false,"crossMatching":false,"runnersVoidable":false,"numberOfActiveRunners":2,"betDelay":0,"status":"OPEN","runners":[{"status":"ACTIVE","sortPriority":1,"id":9638604,"name":"J Fourlis"},{"status":"ACTIVE","sortPriority":2,"id":9637020,"name":"A Prisacariu"}],"regulators":["MR_INT"],"countryCode":"GB","discountAllowed":false,"timezone":"GMT","openDate":"2021-09-13T11:00:00.000Z","version":4030167322,"name":"Match Odds","eventName":"J Fourlis v A Prisacariu"},"rc":[{"batb":[[0,1.01,25]],"ltp":0.0,"tv":0.0,"id":9638604},{"batb":[[0,1.01,25]],"ltp":0.0,"tv":0.0,"id":9637020}]}]}
{"op":"mcm","clk":"4232373855","pt":1631518767640,"mc":[{"id":"1.187595436","marketDefinition":{"bspMarket":false,"turnInPlayEnabled":true,"persistenceEnabled":true,"marketBaseRate":5.0,"eventId":"30897919","eventTypeId":"2","numberOfWinners":1,"bettingType":"ODDS","marketType":"MATCH_ODDS","marketTime":"2021-09-13T08:00:00.000Z","suspendTime":"2021-09-13T08:00:00.000Z","bspReconciled":false,"complete":true,"inPlay":false,"crossMatching":false,"runnersVoidable":false,"numberOfActiveRunners":2,"betDelay":0,"status":"OPEN","runners":[{"status":"ACTIVE","sortPriority":1,"id":9638604,"name":"J Fourlis"},{"status":"ACTIVE","sortPriority":2,"id":9637020,"name":"A Prisacariu"}],"regulators":["MR_INT"],"countryCode":"GB","discountAllowed":true,"timezone":"GMT","openDate":"2021-09-13T11:00:00.000Z","version":4030167322,"name":"Match Odds","eventName":"J Fourlis v A Prisacariu"}}]}
{"op":"mcm","clk":"4232396402","pt":1631519123392,"mc":[{"id":"1.187595436","rc":[{"batb":[[0,1.01,7]],"ltp":0.0,"tv":0.0,"id":9638604},{"batb":[[0,1.01,7]],"ltp":0.0,"tv":0.0,"id":9637020}]}]}
{"op":"mcm","clk":"4232601265","pt":1631522310474,"mc":[{"id":"1.187595436","rc":[{"batl":[[0,2.4,2.66]],"ltp":0.0,"tv":0.0,"id":9638604}]}]}
{"op":"mcm","clk":"4232601479","pt":1631522314177,"mc":[{"id":"1.187595436","rc":[{"batb":[[0,1.32,7.99],[1,1.01,7]],"ltp":0.0,"tv":0.0,"id":9638604}]}]}
{"op":"mcm","clk":"4232642921","pt":1631523098634,"mc":[{"id":"1.187595436","rc":[{"batb":[[0,1.34,132.13],[1,1.32,7.99],[2,1.01,7]],"ltp":0.0,"tv":0.0,"id":9638604},{"batb":[[0,1.05,880.88],[1,1.01,7]],"ltp":0.0,"tv":0.0,"id":9637020}]}]}
{"op":"mcm","clk":"4232673416","pt":1631523785964,"mc":[{"id":"1.187595436","rc":[{"batb":[[0,1.67,62.33],[1,1.34,132.05],[2,1.32,7.99]],"batl":[[0,2.4,2.66]],"ltp":0.0,"tv":0.0,"id":9638604},{"batb":[[0,2.1,37.97],[1,1.05,880.36],[2,1.01,7]],"ltp":0.0,"tv":0.0,"id":9637020}]}]}
{"op":"mcm","clk":"4232675398","pt":1631523821547,"mc":[{"id":"1.187595436","marketDefinition":{"bspMarket":false,"turnInPlayEnabled":true,"persistenceEnabled":true,"marketBaseRate":5.0,"eventId":"30897919","eventTypeId":"2","numberOfWinners":1,"bettingType":"ODDS","marketType":"MATCH_ODDS","marketTime":"2021-09-13T08:00:00.000Z","suspendTime":"2021-09-13T08:00:00.000Z","bspReconciled":false,"complete":true,"inPlay":false,"crossMatching":true,"runnersVoidable":false,"numberOfActiveRunners":2,"betDelay":0,"status":"OPEN","runners":[{"status":"ACTIVE","sortPriority":1,"id":9638604,"name":"J Fourlis"},{"status":"ACTIVE","sortPriority":2,"id":9637020,"name":"A Prisacariu"}],"regulators":["MR_INT"],"countryCode":"GB","discountAllowed":true,"timezone":"GMT","openDate":"2021-09-13T11:00:00.000Z","version":4030167322,"name":"Match Odds","eventName":"J Fourlis v A Prisacariu"}}]}
{"op":"mcm","clk":"4232737437","pt":1631524803818,"mc":[{"id":"1.187595436","rc":[{"batb":[[1,1.66,2.66],[2,1.34,132.05]],"ltp":0.0,"tv":0.0,"id":9638604},{"batb":[[1,2.08,2.66],[2,1.05,880.36]],"ltp":0.0,"tv":0.0,"id":9637020}]}]}
{"op":"mcm","clk":"4232784515","pt":1631525695696,"mc":[{"id":"1.187595436","rc":[{"batb":[[2,1.01,7]],"ltp":0.0,"tv":0.0,"id":9637020}]}]}
{"op":"mcm","clk":"4232784788","pt":1631525701716,"mc":[{"id":"1.187595436","rc":[{"batl":[[1,2.8,44.02]],"ltp":0.0,"tv":0.0,"id":9638604}]}]}
{"op":"mcm","clk":"4233105737","pt":1631530658634,"mc":[{"id":"1.187595436","marketDefinition":{"bspMarket":false,"turnInPlayEnabled":true,"persistenceEnabled":true,"marketBaseRate":5.0,"eventId":"30897919","eventTypeId":"2","numberOfWinners":1,"bettingType":"ODDS","marketType":"MATCH_ODDS","marketTime":"2021-09-13T11:10:00.000Z","suspendTime":"2021-09-13T11:10:00.000Z","bspReconciled":false,"complete":true,"inPlay":false,"crossMatching":true,"runnersVoidable":false,"numberOfActiveRunners":2,"betDelay":0,"status":"OPEN","runners":[{"status":"ACTIVE","sortPriority":1,"id":9638604,"name":"J Fourlis"},{"status":"ACTIVE","sortPriority":2,"id":9637020,"name":"A Prisacariu"}],"regulators":["MR_INT"],"countryCode":"GB","discountAllowed":true,"timezone":"GMT","openDate":"2021-09-13T11:00:00.000Z","version":4030567225,"name":"Match Odds","eventName":"J Fourlis v A Prisacariu"}}]}
{"op":"mcm","clk":"4233107240","pt":1631530679736,"mc":[{"id":"1.187595436","marketDefinition":{"bspMarket":false,"turnInPlayEnabled":true,"persistenceEnabled":true,"marketBaseRate":5.0,"eventId":"30897919","eventTypeId":"2","numberOfWinners":1,"bettingType":"ODDS","marketType":"MATCH_ODDS","marketTime":"2021-09-13T11:10:00.000Z","suspendTime":"2021-09-13T11:10:00.000Z","bspReconciled":false,"complete":true,"inPlay":false,"crossMatching":true,"runnersVoidable":false,"numberOfActiveRunners":2,"betDelay":0,"status":"OPEN","runners":[{"status":"ACTIVE","sortPriority":1,"id":9638604,"name":"J Fourlis"},{"status":"ACTIVE","sortPriority":2,"id":9637020,"name":"A Prisacariu"}],"regulators":["MR_INT"],"countryCode":"GB","discountAllowed":true,"timezone":"GMT","openDate":"2021-09-13T11:10:00.000Z","version":4030567225,"name":"Match Odds","eventName":"J Fourlis v A Prisacariu"}}]}
{"op":"mcm","clk":"4233144009","pt":1631531143180,"mc":[{"id":"1.187595436","marketDefinition":{"bspMarket":false,"turnInPlayEnabled":true,"persistenceEnabled":true,"marketBaseRate":5.0,"eventId":"30897919","eventTypeId":"2","numberOfWinners":1,"bettingType":"ODDS","marketType":"MATCH_ODDS","marketTime":"2021-09-13T11:20:00.000Z","suspendTime":"2021-09-13T11:20:00.000Z","bspReconciled":false,"complete":true,"inPlay":false,"crossMatching":true,"runnersVoidable":false,"numberOfActiveRunners":2,"betDelay":0,"status":"OPEN","runners":[{"status":"ACTIVE","sortPriority":1,"id":9638604,"name":"J Fourlis"},{"status":"ACTIVE","sortPriority":2,"id":9637020,"name":"A Prisacariu"}],"regulators":["MR_INT"],"countryCode":"GB","discountAllowed":true,"timezone":"GMT","openDate":"2021-09-13T11:10:00.000Z","version":4030575246,"name":"Match Odds","eventName":"J Fourlis v A Prisacariu"}}]}
{"op":"mcm","clk":"4233144212","pt":1631531145179,"mc":[{"id":"1.187595436","marketDefinition":{"bspMarket":false,"turnInPlayEnabled":true,"persistenceEnabled":true,"marketBaseRate":5.0,"eventId":"30897919","eventTypeId":"2","numberOfWinners":1,"bettingType":"ODDS","marketType":"MATCH_ODDS","marketTime":"2021-09-13T11:20:00.000Z","suspendTime":"2021-09-13T11:20:00.000Z","bspReconciled":false,"complete":true,"inPlay":false,"crossMatching":true,"runnersVoidable":false,"numberOfActiveRunners":2,"betDelay":0,"status":"OPEN","runners":[{"status":"ACTIVE","sortPriority":1,"id":9638604,"name":"J Fourlis"},{"status":"ACTIVE","sortPriority":2,"id":9637020,"name":"A Prisacariu"}],"regulators":["MR_INT"],"countryCode":"GB","discountAllowed":true,"timezone":"GMT","openDate":"2021-09-13T11:20:00.000Z","version":4030575246,"name":"Match Odds","eventName":"J Fourlis v A Prisacariu"}}]}
{"op":"mcm","clk":"4233192781","pt":1631531752487,"mc":[{"id":"1.187595436","marketDefinition":{"bspMarket":false,"turnInPlayEnabled":true,"persistenceEnabled":true,"marketBaseRate":5.0,"eventId":"30897919","eventTypeId":"2","numberOfWinners":1,"bettingType":"ODDS","marketType":"MATCH_ODDS","marketTime":"2021-09-13T11:30:00.000Z","suspendTime":"2021-09-13T11:30:00.000Z","bspReconciled":false,"complete":true,"inPlay":false,"crossMatching":true,"runnersVoidable":false,"numberOfActiveRunners":2,"betDelay":0,"status":"OPEN","runners":[{"status":"ACTIVE","sortPriority":1,"id":9638604,"name":"J Fourlis"},{"status":"ACTIVE","sortPriority":2,"id":9637020,"name":"A Prisacariu"}],"regulators":["MR_INT"],"countryCode":"GB","discountAllowed":true,"timezone":"GMT","openDate":"2021-09-13T11:20:00.000Z","version":4030581719,"name":"Match Odds","eventName":"J Fourlis v A Prisacariu"}}]}
{"op":"mcm","clk":"4233193034","pt":1631531755505,"mc":[{"id":"1.187595436","marketDefinition":{"bspMarket":false,"turnInPlayEnabled":true,"persistenceEnabled":true,"marketBaseRate":5.0,"eventId":"30897919","eventTypeId":"2","numberOfWinners":1,"bettingType":"ODDS","marketType":"MATCH_ODDS","marketTime":"2021-09-13T11:30:00.000Z","suspendTime":"2021-09-13T11:30:00.000Z","bspReconciled":false,"complete":true,"inPlay":false,"crossMatching":true,"runnersVoidable":false,"numberOfActiveRunners":2,"betDelay":0,"status":"OPEN","runners":[{"status":"ACTIVE","sortPriority":1,"id":9638604,"name":"J Fourlis"},{"status":"ACTIVE","sortPriority":2,"id":9637020,"name":"A Prisacariu"}],"regulators":["MR_INT"],"countryCode":"GB","discountAllowed":true,"timezone":"GMT","openDate":"2021-09-13T11:30:00.000Z","version":4030581719,"name":"Match Odds","eventName":"J Fourlis v A Prisacariu"}}]}
{"op":"mcm","clk":"4233234196","pt":1631532325326,"mc":[{"id":"1.187595436","rc":[{"batb":[[1,1.66,2.66],[2,1.34,131.93]],"batl":[[0,2.4,2.66],[1,2.8,43.98]],"ltp":0.0,"tv":0.0,"id":9638604},{"trd":[[2.1,5.32]],"batb":[[0,2.1,35.31],[1,2.08,2.66]],"ltp":2.1,"tv":5.31,"id":9637020}],"tv":5.31}]}
{"op":"mcm","clk":"4233234283","pt":1631532326885,"mc":[{"id":"1.187595436","rc":[{"batb":[[0,2.1,37.97]],"ltp":2.1,"tv":5.31,"id":9637020}]}]}
{"op":"mcm","clk":"4233249790","pt":1631532550031,"mc":[{"id":"1.187595436","rc":[{"batl":[[0,3.95,3.28]],"ltp":2.1,"tv":5.31,"id":9637020}]}]}
{"op":"mcm","clk":"4233257409","pt":1631532650985,"mc":[{"id":"1.187595436","marketDefinition":{"bspMarket":false,"turnInPlayEnabled":true,"persistenceEnabled":true,"marketBaseRate":5.0,"eventId":"30897919","eventTypeId":"2","numberOfWinners":1,"bettingType":"ODDS","marketType":"MATCH_ODDS","marketTime":"2021-09-13T11:30:00.000Z","suspendTime":"2021-09-13T11:30:00.000Z","bspReconciled":false,"complete":true,"inPlay":true,"crossMatching":true,"runnersVoidable":false,"numberOfActiveRunners":2,"betDelay":5,"status":"OPEN","runners":[{"status":"ACTIVE","sortPriority":1,"id":9638604,"name":"J Fourlis"},{"status":"ACTIVE","sortPriority":2,"id":9637020,"name":"A Prisacariu"}],"regulators":["MR_INT"],"countryCode":"GB","discountAllowed":true,"timezone":"GMT","openDate":"2021-09-13T11:30:00.000Z","version":4030592047,"name":"Match Odds","eventName":"J Fourlis v A Prisacariu"},"rc":[{"batb":[[0,1.01,7],[1,1.66,0],[2,1.34,0]],"ltp":0.0,"tv":0.0,"id":9638604},{"batb":[[0,1.01,7],[1,2.08,0],[2,1.01,0]],"ltp":2.1,"tv":5.31,"id":9637020}]}]}
{"op":"mcm","clk":"4233303859","pt":1631533189439,"mc":[{"id":"1.187595436","marketDefinition":{"bspMarket":false,"turnInPlayEnabled":true,"persistenceEnabled":true,"marketBaseRate":5.0,"eventId":"30897919","eventTypeId":"2","numberOfWinners":1,"bettingType":"ODDS","marketType":"MATCH_ODDS","marketTime":"2021-09-13T11:39:48.000Z","suspendTime":"2021-09-13T11:39:48.000Z","bspReconciled":false,"complete":true,"inPlay":true,"crossMatching":true,"runnersVoidable":false,"numberOfActiveRunners":2,"betDelay":5,"status":"OPEN","runners":[{"status":"ACTIVE","sortPriority":1,"id":9638604,"name":"J Fourlis"},{"status":"ACTIVE","sortPriority":2,"id":9637020,"name":"A Prisacariu"}],"regulators":["MR_INT"],"countryCode":"GB","discountAllowed":true,"timezone":"GMT","openDate":"2021-09-13T11:30:00.000Z","version":4030602965,"name":"Match Odds","eventName":"J Fourlis v A Prisacariu"}}]}
{"op":"mcm","clk":"4233304046","pt":1631533192455,"mc":[{"id":"1.187595436","marketDefinition":{"bspMarket":false,"turnInPlayEnabled":true,"persistenceEnabled":true,"marketBaseRate":5.0,"eventId":"30897919","eventTypeId":"2","numberOfWinners":1,"bettingType":"ODDS","marketType":"MATCH_ODDS","marketTime":"2021-09-13T11:39:48.000Z","suspendTime":"2021-09-13T11:39:48.000Z","bspReconciled":false,"complete":true,"inPlay":true,"crossMatching":true,"runnersVoidable":false,"numberOfActiveRunners":2,"betDelay":5,"status":"OPEN","runners":[{"status":"ACTIVE","sortPriority":1,"id":9638604,"name":"J Fourlis"},{"status":"ACTIVE","sortPriority":2,"id":9637020,"name":"A Prisacariu"}],"regulators":["MR_INT"],"countryCode":"GB","discountAllowed":true,"timezone":"GMT","openDate":"2021-09-13T11:39:48.000Z","version":4030602965,"name":"Match Odds","eventName":"J Fourlis v A Prisacariu"}}]}
{"op":"mcm","clk":"4233319113","pt":1631533418981,"mc":[{"id":"1.187595436","rc":[{"batb":[[0,1.46,441.71],[1,1.01,7]],"batl":[[0,2.22,333.55]],"ltp":0.0,"tv":0.0,"id":9638604}]}]}
{"op":"mcm","clk":"4233325561","pt":1631533500017,"mc":[{"id":"1.187595436","rc":[{"batb":[[0,1.01,7],[1,1.01,0]],"ltp":0.0,"tv":0.0,"id":9638604}]}]}
{"op":"mcm","clk":"4233326201","pt":1631533506529,"mc":[{"id":"1.187595436","rc":[{"batb":[[0,1.52,431.36],[1,1.01,7]],"batl":[[0,2.36,303.3]],"ltp":0.0,"tv":0.0,"id":9638604}]}]}
{"op":"mcm","clk":"4233328912","pt":1631533539298,"mc":[{"id":"1.187595436","rc":[{"batl":[[0,2.22,333.55]],"ltp":0.0,"tv":0.0,"id":9638604}]}]}
{"op":"mcm","clk":"4233335943","pt":1631533626021,"mc":[{"id":"1.187595436","rc":[{"batb":[[0,1.01,7],[1,1.01,0]],"ltp":0.0,"tv":0.0,"id":9638604}]}]}
{"op":"mcm","clk":"4233336405","pt":1631533631914,"mc":[{"id":"1.187595436","rc":[{"batb":[[0,1.4,457.22],[1,1.01,7]],"batl":[[0,2.1,368.32]],"ltp":0.0,"tv":0.0,"id":9638604}]}]}
{"op":"mcm","clk":"4233338218","pt":1631533653662,"mc":[{"id":"1.187595436","rc":[{"batb":[[0,1.01,7],[1,1.01,0]],"ltp":0.0,"tv":0.0,"id":9638604}]}]}
{"op":"mcm","clk":"4233338689","pt":1631533659479,"mc":[{"id":"1.187595436","rc":[{"batb":[[0,1.5,432.79],[1,1.01,7]],"batl":[[0,2.3,314.02]],"ltp":0.0,"tv":0.0,"id":9638604}]}]}
{"op":"mcm","clk":"4233341597","pt":1631533695143,"mc":[{"id":"1.187595436","rc":[{"batl":[[0,2.16,347.55]],"ltp":0.0,"tv":0.0,"id":9638604}]}]}
{"op":"mcm","clk":"4233345830","pt":1631533751167,"mc":[{"id":"1.187595436","rc":[{"batb":[[0,1.01,7],[1,1.01,0]],"ltp":0.0,"tv":0.0,"id":9638604}]}]}
{"op":"mcm","clk":"4233346269","pt":1631533757466,"mc":[{"id":"1.187595436","rc":[{"batb":[[0,1.55,426.3],[1,1.01,7]],"batl":[[0,2.42,290.48]],"ltp":0.0,"tv":0.0,"id":9638604}]}]}
{"op":"mcm","clk":"4233349318","pt":1631533798247,"mc":[{"id":"1.187595436","rc":[{"batl":[[0,2.3,314.02]],"ltp":0.0,"tv":0.0,"id":9638604}]}]}
{"op":"mcm","clk":"4233354524","pt":1631533864155,"mc":[{"id":"1.187595436","rc":[{"batb":[[0,1.01,7],[1,1.01,0]],"ltp":0.0,"tv":0.0,"id":9638604}]}]}
{"op":"mcm","clk":"4233354966","pt":1631533870340,"mc":[{"id":"1.187595436","rc":[{"batb":[[0,1.62,421.17],[1,1.01,7]],"batl":[[0,2.6,261.12]],"ltp":0.0,"tv":0.0,"id":9638604}]}]}
{"op":"mcm","clk":"4233357423","pt":1631533898903,"mc":[{"id":"1.187595436","rc":[{"batb":[[0,1.01,7],[1,1.01,0]],"ltp":0.0,"tv":0.0,"id":9638604}]}]}
{"op":"mcm","clk":"4233357898","pt":1631533904503,"mc":[{"id":"1.187595436","rc":[{"batb":[[0,1.67,415.42],[1,1.01,7]],"ltp":0.0,"tv":0.0,"id":9638604}]}]}
{"op":"mcm","clk":"4233360878","pt":1631533943370,"mc":[{"id":"1.187595436","rc":[{"batb":[[0,1.01,7],[1,1.01,0]],"ltp":0.0,"tv":0.0,"id":9638604}]}]}
{"op":"mcm","clk":"4233361290","pt":1631533949306,"mc":[{"id":"1.187595436","rc":[{"batb":[[0,1.74,409.86],[1,1.01,7]],"batl":[[0,2.92,224.31]],"ltp":0.0,"tv":0.0,"id":9638604}]}]}
{"op":"mcm","clk":"4233368856","pt":1631534060271,"mc":[{"id":"1.187595436","rc":[{"batb":[[0,1.01,7],[1,1.01,0]],"ltp":0.0,"tv":0.0,"id":9638604}]}]}
{"op":"mcm","clk":"4233369294","pt":1631534066279,"mc":[{"id":"1.187595436","rc":[{"batb":[[0,1.82,406.77],[1,1.01,7]],"ltp":0.0,"tv":0.0,"id":9638604}]}]}
{"op":"mcm","clk":"4233376795","pt":1631534182384,"mc":[{"id":"1.187595436","rc":[{"batl":[[0,3.3,194.57]],"ltp":0.0,"tv":0.0,"id":9638604}]}]}
{"op":"mcm","clk":"4233378550","pt":1631534208597,"mc":[{"id":"1.187595436","rc":[{"batl":[[0,2.92,224.31]],"ltp":0.0,"tv":0.0,"id":9638604}]}]}
{"op":"mcm","clk":"4233379694","pt":1631534224142,"mc":[{"id":"1.187595436","rc":[{"batb":[[0,1.01,7],[1,1.01,0]],"ltp":0.0,"tv":0.0,"id":9638604}]}]}
{"op":"mcm","clk":"4233380086","pt":1631534230257,"mc":[{"id":"1.187595436","rc":[{"batb":[[0,1.67,415.42],[1,1.01,7]],"batl":[[0,2.72,244.88]],"ltp":0.0,"tv":0.0,"id":9638604}]}]}
{"op":"mcm","clk":"4233382601","pt":1631534269099,"mc":[{"id":"1.187595436","rc":[{"batb":[[0,1.01,7],[1,1.01,0]],"ltp":0.0,"tv":0.0,"id":9638604}]}]}
{"op":"mcm","clk":"4233382943","pt":1631534274902,"mc":[{"id":"1.187595436","rc":[{"batb":[[0,1.77,407.82],[1,1.01,7]],"ltp":0.0,"tv":0.0,"id":9638604}]}]}
{"op":"mcm","clk":"4233387878","pt":1631534350119,"mc":[{"id":"1.187595436","rc":[{"batb":[[0,1.01,7],[1,1.01,0]],"ltp":0.0,"tv":0.0,"id":9638604}]}]}
{"op":"mcm","clk":"4233388312","pt":1631534356446,"mc":[{"id":"1.187595436","rc":[{"batb":[[0,1.58,422.21],[1,1.01,7]],"batl":[[0,2.5,278.33]],"ltp":0.0,"tv":0.0,"id":9638604}]}]}
{"op":"mcm","clk":"4233389958","pt":1631534378868,"mc":[{"id":"1.187595436","rc":[{"batb":[[0,1.01,7],[1,1.01,0]],"ltp":0.0,"tv":0.0,"id":9638604}]}]}
{"op":"mcm","clk":"4233390403","pt":1631534384876,"mc":[{"id":"1.187595436","rc":[{"batb":[[0,1.67,415.42],[1,1.01,7]],"ltp":0.0,"tv":0.0,"id":9638604}]}]}
{"op":"mcm","clk":"4233391594","pt":1631534400825,"mc":[{"id":"1.187595436","rc":[{"trd":[[1.67,0.03]],"batb":[[0,1.67,415.4]],"ltp":1.67,"tv":0.03,"id":9638604}],"tv":5.35}]}
{"op":"mcm","clk":"4233395120","pt":1631534441357,"mc":[{"id":"1.187595436","rc":[{"batb":[[0,1.01,7],[1,1.01,0]],"ltp":1.67,"tv":0.03,"id":9638604}]}]}
{"op":"mcm","clk":"4233395599","pt":1631534447013,"mc":[{"id":"1.187595436","rc":[{"batb":[[0,1.52,431.35],[1,1.01,7]],"batl":[[0,2.36,303.31]],"ltp":1.67,"tv":0.03,"id":9638604}]}]}
{"op":"mcm","clk":"4233397664","pt":1631534471027,"mc":[{"id":"1.187595436","rc":[{"batb":[[0,1.01,7],[1,1.01,0]],"ltp":1.67,"tv":0.03,"id":9638604}]}]}
{"op":"mcm","clk":"4233398122","pt":1631534476336,"mc":[{"id":"1.187595436","rc":[{"batb":[[0,1.44,442.18],[1,1.01,7]],"batl":[[0,2.16,347.56]],"ltp":1.67,"tv":0.03,"id":9638604}]}]}
{"op":"mcm","clk":"4233402872","pt":1631534530472,"mc":[{"id":"1.187595436","rc":[{"batb":[[0,1.01,7],[1,1.01,0]],"ltp":1.67,"tv":0.03,"id":9638604}]}]}
{"op":"mcm","clk":"4233403404","pt":1631534536457,"mc":[{"id":"1.187595436","rc":[{"batb":[[0,1.5,432.78],[1,1.01,7]],"ltp":1.67,"tv":0.03,"id":9638604}]}]}
{"op":"mcm","clk":"4233405501","pt":1631534560222,"mc":[{"id":"1.187595436","rc":[{"batb":[[0,1.01,7],[1,1.01,0]],"ltp":1.67,"tv":0.03,"id":9638604}]}]}
{"op":"mcm","clk":"4233406004","pt":1631534566017,"mc":[{"id":"1.187595436","rc":[{"batb":[[0,1.58,422.19],[1,1.01,7]],"batl":[[0,2.5,278.34]],"ltp":1.67,"tv":0.03,"id":9638604}]}]}
{"op":"mcm","clk":"4233410287","pt":1631534609813,"mc":[{"id":"1.187595436","rc":[{"batl":[[0,2.3,314.03]],"ltp":1.67,"tv":0.03,"id":9638604}]}]}
{"op":"mcm","clk":"4233416833","pt":1631534671878,"mc":[{"id":"1.187595436","rc":[{"batb":[[0,1.01,7],[1,1.01,0]],"ltp":1.67,"tv":0.03,"id":9638604}]}]}
{"op":"mcm","clk":"4233417450","pt":1631534677939,"mc":[{"id":"1.187595436","rc":[{"batb":[[0,1.67,415.4],[1,1.01,7]],"batl":[[0,2.72,244.89]],"ltp":1.67,"tv":0.03,"id":9638604}]}]}
{"op":"mcm","clk":"4233419875","pt":1631534702789,"mc":[{"id":"1.187595436","rc":[{"batb":[[0,1.01,7],[1,1.01,0]],"ltp":1.67,"tv":0.03,"id":9638604}]}]}
{"op":"mcm","clk":"4233420562","pt":1631534708312,"mc":[{"id":"1.187595436","rc":[{"batb":[[0,1.74,409.85],[1,1.01,7]],"ltp":1.67,"tv":0.03,"id":9638604}]}]}
{"op":"mcm","clk":"4233432847","pt":1631534823550,"mc":[{"id":"1.187595436","rc":[{"batb":[[0,1.01,7],[1,1.01,0]],"ltp":1.67,"tv":0.03,"id":9638604}]}]}
{"op":"mcm","clk":"4233433527","pt":1631534829686,"mc":[{"id":"1.187595436","rc":[{"batb":[[0,1.86,404.11],[1,1.01,7]],"batl":[[0,3.3,194.57]],"ltp":1.67,"tv":0.03,"id":9638604}]}]}
{"op":"mcm","clk":"4233435858","pt":1631534853718,"mc":[{"id":"1.187595436","rc":[{"batl":[[0,3,216.41]],"ltp":1.67,"tv":0.03,"id":9638604}]}]}
{"op":"mcm","clk":"4233442101","pt":1631534916225,"mc":[{"id":"1.187595436","rc":[{"batb":[[0,1.01,7],[1,1.01,0]],"ltp":1.67,"tv":0.03,"id":9638604}]}]}
{"op":"mcm","clk":"4233442646","pt":1631534921816,"mc":[{"id":"1.187595436","rc":[{"batb":[[0,2.04,399.52],[1,1.01,7]],"batl":[[0,3.9,160.43]],"ltp":1.67,"tv":0.03,"id":9638604}]}]}
{"op":"mcm","clk":"4233445791","pt":1631534954072,"mc":[{"id":"1.187595436","rc":[{"batb":[[0,1.01,7],[1,1.01,0]],"ltp":1.67,"tv":0.03,"id":9638604}]}]}
{"op":"mcm","clk":"4233460268","pt":1631535115679,"mc":[{"id":"1.187595436","rc":[{"batb":[[0,2.42,386.98],[1,1.01,7]],"batl":[[0,5.5,116.65]],"ltp":1.67,"tv":0.03,"id":9638604}]}]}
{"op":"mcm","clk":"4233479281","pt":1631535307831,"mc":[{"id":"1.187595436","rc":[{"batb":[[0,1.01,7],[1,1.01,0]],"ltp":1.67,"tv":0.03,"id":9638604}]}]}
{"op":"mcm","clk":"4233479888","pt":1631535313597,"mc":[{"id":"1.187595436","rc":[{"batb":[[0,2.62,384.48],[1,1.01,7]],"batl":[[0,6.6,100.32]],"ltp":1.67,"tv":0.03,"id":9638604}]}]}
{"op":"mcm","clk":"4233490341","pt":1631535424322,"mc":[{"id":"1.187595436","rc":[{"batb":[[0,1.01,7],[1,1.01,0]],"ltp":1.67,"tv":0.03,"id":9638604}]}]}
{"op":"mcm","clk":"4233490943","pt":1631535430251,"mc":[{"id":"1.187595436","rc":[{"batb":[[0,2.84,380.59],[1,1.01,7]],"batl":[[0,8.2,86.64]],"ltp":1.67,"tv":0.03,"id":9638604}]}]}
{"op":"mcm","clk":"4233492085","pt":1631535441675,"mc":[{"id":"1.187595436","rc":[{"batb":[[0,1.01,7],[1,1.01,0]],"ltp":1.67,"tv":0.03,"id":9638604}]}]}
{"op":"mcm","clk":"4233535898","pt":1631535740542,"mc":[{"id":"1.187595436","rc":[{"batb":[[0,2.98,379.44],[1,1.01,7]],"batl":[[0,9.4,79.12]],"ltp":1.67,"tv":0.03,"id":9638604}]}]}
{"op":"mcm","clk":"4233537220","pt":1631535754769,"mc":[{"id":"1.187595436","rc":[{"batl":[[0,8.2,86.64]],"ltp":1.67,"tv":0.03,"id":9638604}]}]}
{"op":"mcm","clk":"4233538209","pt":1631535765785,"mc":[{"id":"1.187595436","rc":[{"batl":[[0,10.5,73.32]],"ltp":1.67,"tv":0.03,"id":9638604}]}]}
{"op":"mcm","clk":"4233540530","pt":1631535786834,"mc":[{"id":"1.187595436","rc":[{"batb":[[0,1.01,7],[1,1.01,0]],"ltp":1.67,"tv":0.03,"id":9638604}]}]}
{"op":"mcm","clk":"4233541114","pt":1631535792229,"mc":[{"id":"1.187595436","rc":[{"batb":[[0,3.3,378.07],[1,1.01,7]],"batl":[[0,13.5,64.97]],"ltp":1.67,"tv":0.03,"id":9638604}]}]}
{"op":"mcm","clk":"4233543683","pt":1631535821773,"mc":[{"id":"1.187595436","rc":[{"batl":[[0,10.5,73.32]],"ltp":1.67,"tv":0.03,"id":9638604}]}]}
{"op":"mcm","clk":"4233547804","pt":1631535867537,"mc":[{"id":"1.187595436","rc":[{"batl":[[0,13.5,64.97]],"ltp":1.67,"tv":0.03,"id":9638604}]}]}
{"op":"mcm","clk":"4233553693","pt":1631535947606,"mc":[{"id":"1.187595436","rc":[{"batl":[[0,10.5,73.32]],"ltp":1.67,"tv":0.03,"id":9638604}]}]}
{"op":"mcm","clk":"4233555438","pt":1631535968150,"mc":[{"id":"1.187595436","rc":[{"batl":[[0,13.5,64.97]],"ltp":1.67,"tv":0.03,"id":9638604}]}]}
{"op":"mcm","clk":"4233557007","pt":1631535988611,"mc":[{"id":"1.187595436","rc":[{"batl":[[0,18,56.98]],"ltp":1.67,"tv":0.03,"id":9638604}]}]}
{"op":"mcm","clk":"4233559675","pt":1631536020640,"mc":[{"id":"1.187595436","rc":[{"batb":[[0,1.01,7],[1,1.01,0]],"ltp":1.67,"tv":0.03,"id":9638604}]}]}
{"op":"mcm","clk":"4233560135","pt":1631536026144,"mc":[{"id":"1.187595436","rc":[{"batb":[[0,3.7,375.92],[1,1.01,7]],"batl":[[0,23,51.95]],"ltp":1.67,"tv":0.03,"id":9638604}]}]}
{"op":"mcm","clk":"4233562037","pt":1631536049638,"mc":[{"id":"1.187595436","rc":[{"batl":[[0,34,46.71]],"ltp":1.67,"tv":0.03,"id":9638604}]}]}
{"op":"mcm","clk":"4233565238","pt":1631536086083,"mc":[{"id":"1.187595436","rc":[{"batl":[[0,46,43.55]],"ltp":1.67,"tv":0.03,"id":9638604}]}]}
{"op":"mcm","clk":"4233567683","pt":1631536115677,"mc":[{"id":"1.187595436","rc":[{"batl":[[0,34,46.71]],"ltp":1.67,"tv":0.03,"id":9638604}]}]}
{"op":"mcm","clk":"4233571480","pt":1631536164358,"mc":[{"id":"1.187595436","rc":[{"batl":[[0,46,43.55]],"ltp":1.67,"tv":0.03,"id":9638604}]}]}
{"op":"mcm","clk":"4233573132","pt":1631536184476,"mc":[{"id":"1.187595436","rc":[{"batb":[[0,1.01,7],[1,1.01,0]],"ltp":1.67,"tv":0.03,"id":9638604}]}]}
{"op":"mcm","clk":"4233573597","pt":1631536190117,"mc":[{"id":"1.187595436","rc":[{"batb":[[0,4.2,376.06],[1,1.01,7]],"batl":[[0,85,39.67]],"ltp":1.67,"tv":0.03,"id":9638604}]}]}
{"op":"mcm","clk":"4233576306","pt":1631536222572,"mc":[{"id":"1.187595436","rc":[{"batl":[[0,170,37.49]],"ltp":1.67,"tv":0.03,"id":9638604}]}]}
{"op":"mcm","clk":"4233587018","pt":1631536345583,"mc":[{"id":"1.187595436","rc":[{"batl":[[0,340,36.38]],"ltp":1.67,"tv":0.03,"id":9638604}]}]}
{"op":"mcm","clk":"4233588235","pt":1631536359614,"mc":[{"id":"1.187595436","rc":[{"batb":[[0,12,2],[1,4.2,376.06],[2,1.01,7]],"ltp":1.67,"tv":0.03,"id":9638604}]}]}
{"op":"mcm","clk":"4233589891","pt":1631536377245,"mc":[{"id":"1.187595436","rc":[{"batl":[[0,170,37.49]],"ltp":1.67,"tv":0.03,"id":9638604}]}]}
{"op":"mcm","clk":"4233600515","pt":1631536494637,"mc":[{"id":"1.187595436","rc":[{"batl":[[0,60,41.54]],"ltp":1.67,"tv":0.03,"id":9638604}]}]}
{"op":"mcm","clk":"4233603205","pt":1631536522997,"mc":[{"id":"1.187595436","rc":[{"batl":[[0,170,37.49]],"ltp":1.67,"tv":0.03,"id":9638604}]}]}
{"op":"mcm","clk":"4233606929","pt":1631536562566,"mc":[{"id":"1.187595436","rc":[{"batl":[[0,60,41.54]],"ltp":1.67,"tv":0.03,"id":9638604}]}]}
{"op":"mcm","clk":"4233609804","pt":1631536593795,"mc":[{"id":"1.187595436","rc":[{"batl":[[0,170,37.49]],"ltp":1.67,"tv":0.03,"id":9638604}]}]}
{"op":"mcm","clk":"4233612378","pt":1631536622036,"mc":[{"id":"1.187595436","rc":[{"batl":[[0,60,41.54]],"ltp":1.67,"tv":0.03,"id":9638604}]}]}
{"op":"mcm","clk":"4233615840","pt":1631536661769,"mc":[{"id":"1.187595436","rc":[{"batl":[[0,170,37.49]],"ltp":1.67,"tv":0.03,"id":9638604}]}]}
{"op":"mcm","clk":"4233619042","pt":1631536697218,"mc":[{"id":"1.187595436","rc":[{"batl":[[0,60,41.54]],"ltp":1.67,"tv":0.03,"id":9638604}]}]}
{"op":"mcm","clk":"4233621534","pt":1631536724537,"mc":[{"id":"1.187595436","rc":[{"batl":[[0,46,43.55]],"ltp":1.67,"tv":0.03,"id":9638604}]}]}
{"op":"mcm","clk":"4233625570","pt":1631536769159,"mc":[{"id":"1.187595436","rc":[{"batl":[[0,60,41.54]],"ltp":1.67,"tv":0.03,"id":9638604}]}]}
{"op":"mcm","clk":"4233627155","pt":1631536786577,"mc":[{"id":"1.187595436","rc":[{"batl":[[0,46,43.55]],"ltp":1.67,"tv":0.03,"id":9638604}]}]}
{"op":"mcm","clk":"4233629757","pt":1631536818715,"mc":[{"id":"1.187595436","rc":[{"batl":[[0,85,39.67]],"ltp":1.67,"tv":0.03,"id":9638604}]}]}
{"op":"mcm","clk":"4233632551","pt":1631536854993,"mc":[{"id":"1.187595436","rc":[{"batl":[[0,60,41.54]],"ltp":1.67,"tv":0.03,"id":9638604}]}]}
{"op":"mcm","clk":"4233637657","pt":1631536909885,"mc":[{"id":"1.187595436","rc":[{"batl":[[0,46,43.55]],"ltp":1.67,"tv":0.03,"id":9638604}]}]}
{"op":"mcm","clk":"4233638355","pt":1631536918002,"mc":[{"id":"1.187595436","rc":[{"batl":[[0,34,46.71]],"ltp":1.67,"tv":0.03,"id":9638604}]}]}
{"op":"mcm","clk":"4233640459","pt":1631536942130,"mc":[{"id":"1.187595436","rc":[{"batl":[[0,60,41.54]],"ltp":1.67,"tv":0.03,"id":9638604}]}]}
{"op":"mcm","clk":"4233642294","pt":1631536963284,"mc":[{"id":"1.187595436","rc":[{"batl":[[0,85,39.67]],"ltp":1.67,"tv":0.03,"id":9638604}]}]}
{"op":"mcm","clk":"4233643689","pt":1631536982532,"mc":[{"id":"1.187595436","rc":[{"batl":[[0,34,46.71]],"ltp":1.67,"tv":0.03,"id":9638604}]}]}
{"op":"mcm","clk":"4233645570","pt":1631537007069,"mc":[{"id":"1.187595436","rc":[{"batl":[[0,60,41.54]],"ltp":1.67,"tv":0.03,"id":9638604}]}]}
{"op":"mcm","clk":"4233646153","pt":1631537014384,"mc":[{"id":"1.187595436","rc":[{"batb":[[1,1.01,7],[2,1.01,0]],"ltp":1.67,"tv":0.03,"id":9638604}]}]}
{"op":"mcm","clk":"4233659968","pt":1631537190070,"mc":[{"id":"1.187595436","rc":[{"batb":[[1,3.4,381.29],[2,1.01,7]],"batl":[[0,15.5,60.46]],"ltp":1.67,"tv":0.03,"id":9638604}]}]}
{"op":"mcm","clk":"4233661100","pt":1631537205597,"mc":[{"id":"1.187595436","rc":[{"trd":[[12,3.98]],"batb":[[0,3.4,381.3],[1,1.01,7],[2,1.01,0]],"ltp":12.0,"tv":4.01,"id":9638604}],"tv":9.33}]}
{"op":"mcm","clk":"4233661511","pt":1631537211121,"mc":[{"id":"1.187595436","rc":[{"batl":[[0,13.5,64.97]],"ltp":12.0,"tv":4.01,"id":9638604}]}]}
{"op":"mcm","clk":"4233667992","pt":1631537296500,"mc":[{"id":"1.187595436","rc":[{"trd":[[12,4]],"batb":[[0,3.4,381.29]],"ltp":12.0,"tv":4.03,"id":9638604}],"tv":9.35}]}
{"op":"mcm","clk":"4233670048","pt":1631537326538,"mc":[{"id":"1.187595436","rc":[{"batl":[[0,13.5,64.96]],"ltp":12.0,"tv":4.03,"id":9638604}]}]}
{"op":"mcm","clk":"4233672420","pt":1631537359584,"mc":[{"id":"1.187595436","rc":[{"batl":[[0,21,54.22]],"ltp":12.0,"tv":4.03,"id":9638604}]}]}
{"op":"mcm","clk":"4233676184","pt":1631537410456,"mc":[{"id":"1.187595436","rc":[{"batl":[[0,15.5,60.45]],"ltp":12.0,"tv":4.03,"id":9638604}]}]}
{"op":"mcm","clk":"4233678574","pt":1631537442730,"mc":[{"id":"1.187595436","rc":[{"batl":[[0,21,54.22]],"ltp":12.0,"tv":4.03,"id":9638604}]}]}
{"op":"mcm","clk":"4233681134","pt":1631537478052,"mc":[{"id":"1.187595436","rc":[{"batl":[[0,15.5,60.45]],"ltp":12.0,"tv":4.03,"id":9638604}]}]}
{"op":"mcm","clk":"4233683365","pt":1631537514520,"mc":[{"id":"1.187595436","rc":[{"batl":[[0,10.5,73.31]],"ltp":12.0,"tv":4.03,"id":9638604}]}]}
{"op":"mcm","clk":"4233686052","pt":1631537552860,"mc":[{"id":"1.187595436","rc":[{"batl":[[0,15.5,60.45]],"ltp":12.0,"tv":4.03,"id":9638604}]}]}
{"op":"mcm","clk":"4233686711","pt":1631537563487,"mc":[{"id":"1.187595436","rc":[{"trd":[[3.4,5.02]],"batb":[[0,3.4,378.77]],"ltp":3.4,"tv":9.05,"id":9638604}],"tv":14.37}]}
{"op":"mcm","clk":"4233690228","pt":1631537625413,"mc":[{"id":"1.187595436","rc":[{"batl":[[0,10.5,74.14]],"ltp":3.4,"tv":9.05,"id":9638604}]}]}
{"op":"mcm","clk":"4233692300","pt":1631537658881,"mc":[{"id":"1.187595436","rc":[{"batl":[[0,8.2,87.71]],"ltp":3.4,"tv":9.05,"id":9638604}]}]}
{"op":"mcm","clk":"4233694236","pt":1631537687753,"mc":[{"id":"1.187595436","rc":[{"batb":[[0,1.01,7],[1,1.01,0]],"ltp":3.4,"tv":9.05,"id":9638604}]}]}
{"op":"mcm","clk":"4233694605","pt":1631537694161,"mc":[{"id":"1.187595436","rc":[{"batb":[[0,2.72,380.32],[1,1.01,7]],"batl":[[0,7.2,94.64]],"ltp":3.4,"tv":9.05,"id":9638604}]}]}
{"op":"mcm","clk":"4233697160","pt":1631537734639,"mc":[{"id":"1.187595436","rc":[{"batl":[[0,8.2,87.71]],"ltp":3.4,"tv":9.05,"id":9638604}]}]}
{"op":"mcm","clk":"4233699696","pt":1631537776113,"mc":[{"id":"1.187595436","rc":[{"batl":[[0,6.6,101.63]],"ltp":3.4,"tv":9.05,"id":9638604}]}]}
{"op":"mcm","clk":"4233702295","pt":1631537818571,"mc":[{"id":"1.187595436","rc":[{"batl":[[0,8.2,87.71]],"ltp":3.4,"tv":9.05,"id":9638604}]}]}
{"op":"mcm","clk":"4233703647","pt":1631537841835,"mc":[{"id":"1.187595436","rc":[{"batl":[[0,7.2,94.64]],"ltp":3.4,"tv":9.05,"id":9638604}]}]}
{"op":"mcm","clk":"4233704114","pt":1631537850150,"mc":[{"id":"1.187595436","rc":[{"batb":[[0,1.01,7],[1,1.01,0]],"ltp":3.4,"tv":9.05,"id":9638604}]}]}
{"op":"mcm","clk":"4233704462","pt":1631537856022,"mc":[{"id":"1.187595436","rc":[{"batb":[[0,3.1,376.19],[1,1.01,7]],"batl":[[0,10.5,74.14]],"ltp":3.4,"tv":9.05,"id":9638604}]}]}
{"op":"mcm","clk":"4233705993","pt":1631537880991,"mc":[{"id":"1.187595436","rc":[{"batl":[[0,8.2,87.71]],"ltp":3.4,"tv":9.05,"id":9638604}]}]}
{"op":"mcm","clk":"4233707275","pt":1631537901234,"mc":[{"id":"1.187595436","rc":[{"batl":[[0,10.5,74.14]],"ltp":3.4,"tv":9.05,"id":9638604}]}]}
{"op":"mcm","clk":"4233708810","pt":1631537926666,"mc":[{"id":"1.187595436","rc":[{"batl":[[0,9.4,80.04]],"ltp":3.4,"tv":9.05,"id":9638604}]}]}
{"op":"mcm","clk":"4233709755","pt":1631537940883,"mc":[{"id":"1.187595436","rc":[{"batl":[[0,13.5,65.61]],"ltp":3.4,"tv":9.05,"id":9638604}]}]}
{"op":"mcm","clk":"4233716442","pt":1631538044966,"mc":[{"id":"1.187595436","rc":[{"trd":[[3.4,5.02]],"batb":[[0,3.1,376.13]],"ltp":3.4,"tv":9.05,"id":9638604},{"trd":[[2.1,5.32]],"ltp":2.1,"tv":5.32,"id":9637020}],"tv":14.37}]}
{"op":"mcm","clk":"4233716848","pt":1631538050999,"mc":[{"id":"1.187595436","rc":[{"batl":[[0,10.5,74.13]],"ltp":3.4,"tv":9.05,"id":9638604}]}]}
{"op":"mcm","clk":"4233719893","pt":1631538091564,"mc":[{"id":"1.187595436","rc":[{"batb":[[0,1.01,7],[1,1.01,0]],"ltp":3.4,"tv":9.05,"id":9638604}]}]}
{"op":"mcm","clk":"4233720366","pt":1631538097257,"mc":[{"id":"1.187595436","rc":[{"batb":[[0,3.4,378.73],[1,1.01,7]],"batl":[[0,15.5,61]],"ltp":3.4,"tv":9.05,"id":9638604}]}]}
{"op":"mcm","clk":"4233723672","pt":1631538133571,"mc":[{"id":"1.187595436","rc":[{"batl":[[0,21,54.63]],"ltp":3.4,"tv":9.05,"id":9638604}]}]}
{"op":"mcm","clk":"4233726195","pt":1631538162616,"mc":[{"id":"1.187595436","rc":[{"batb":[[0,1.01,7],[1,1.01,0]],"ltp":3.4,"tv":9.05,"id":9638604}]}]}
{"op":"mcm","clk":"4233726696","pt":1631538168620,"mc":[{"id":"1.187595436","rc":[{"batb":[[0,3.9,372.89],[1,1.01,7]],"ltp":3.4,"tv":9.05,"id":9638604}]}]}
{"op":"mcm","clk":"4233730356","pt":1631538211602,"mc":[{"id":"1.187595436","rc":[{"batl":[[0,10.5,74.13]],"ltp":3.4,"tv":9.05,"id":9638604}]}]}
{"op":"mcm","clk":"4233733169","pt":1631538241732,"mc":[{"id":"1.187595436","rc":[{"batl":[[0,15.5,61]],"ltp":3.4,"tv":9.05,"id":9638604}]}]}
{"op":"mcm","clk":"4233735959","pt":1631538273304,"mc":[{"id":"1.187595436","rc":[{"batl":[[0,23,52.32]],"ltp":3.4,"tv":9.05,"id":9638604}]}]}
{"op":"mcm","clk":"4233738179","pt":1631538296492,"mc":[{"id":"1.187595436","rc":[{"batb":[[0,1.01,7],[1,1.01,0]],"ltp":3.4,"tv":9.05,"id":9638604}]}]}
{"op":"mcm","clk":"4233740406","pt":1631538319900,"mc":[{"id":"1.187595436","rc":[{"batb":[[0,3.4,378.73],[1,1.01,7]],"batl":[[0,15.5,61]],"ltp":3.4,"tv":9.05,"id":9638604}]}]}
{"op":"mcm","clk":"4233742747","pt":1631538346030,"mc":[{"id":"1.187595436","rc":[{"batl":[[0,10.5,74.13]],"ltp":3.4,"tv":9.05,"id":9638604}]}]}
{"op":"mcm","clk":"4233745709","pt":1631538377402,"mc":[{"id":"1.187595436","rc":[{"batl":[[0,8.2,87.69]],"ltp":3.4,"tv":9.05,"id":9638604}]}]}
{"op":"mcm","clk":"4233748350","pt":1631538406470,"mc":[{"id":"1.187595436","rc":[{"batl":[[0,5,25.55],[1,8.2,87.69]],"ltp":3.4,"tv":9.05,"id":9638604}]}]}
{"op":"mcm","clk":"4233751112","pt":1631538437741,"mc":[{"id":"1.187595436","rc":[{"batb":[[0,1.01,7],[1,1.01,0]],"batl":[[1,8.2,0]],"ltp":3.4,"tv":9.05,"id":9638604}]}]}
{"op":"mcm","clk":"4233751594","pt":1631538443427,"mc":[{"id":"1.187595436","rc":[{"batb":[[0,2.52,383.24],[1,1.01,7]],"batl":[[1,6,109.05]],"ltp":3.4,"tv":9.05,"id":9638604}]}]}
{"op":"mcm","clk":"4233752446","pt":1631538453052,"mc":[{"id":"1.187595436","rc":[{"batl":[[0,1.5,57.65]],"ltp":2.1,"tv":5.32,"id":9637020}]}]}
{"op":"mcm","clk":"4233752594","pt":1631538454471,"mc":[{"id":"1.187595436","rc":[{"batb":[[0,1.26,57.65],[1,1.01,7]],"ltp":2.1,"tv":5.32,"id":9637020}]}]}
{"op":"mcm","clk":"4233752694","pt":1631538455562,"mc":[{"id":"1.187595436","rc":[{"batb":[[0,1.26,172.95]],"ltp":2.1,"tv":5.32,"id":9637020}]}]}
{"op":"mcm","clk":"4233753049","pt":1631538459152,"mc":[{"id":"1.187595436","rc":[{"batb":[[0,1.01,7],[1,1.01,0]],"batl":[[1,6,0]],"ltp":3.4,"tv":9.05,"id":9638604}]}]}
{"op":"mcm","clk":"4233753315","pt":1631538461743,"mc":[{"id":"1.187595436","rc":[{"batb":[[0,1.01,7],[1,1.01,0]],"ltp":2.1,"tv":5.32,"id":9637020}]}]}
{"op":"mcm","clk":"4233753614","pt":1631538464654,"mc":[{"id":"1.187595436","rc":[{"batb":[[0,2.72,380.25],[1,1.01,7]],"batl":[[1,7.2,94.63]],"ltp":3.4,"tv":9.05,"id":9638604}]}]}
{"op":"mcm","clk":"4233753880","pt":1631538467788,"mc":[{"id":"1.187595436","rc":[{"batl":[[0,1.4,255.49],[1,1.5,57.65]],"ltp":2.1,"tv":5.32,"id":9637020}]}]}
{"op":"mcm","clk":"4233754143","pt":1631538470558,"mc":[{"id":"1.187595436","rc":[{"batl":[[1,1.5,0]],"ltp":2.1,"tv":5.32,"id":9637020}]}]}
{"op":"mcm","clk":"4233754713","pt":1631538477317,"mc":[{"id":"1.187595436","rc":[{"batl":[[0,1.36,57.65],[1,1.4,255.49]],"ltp":2.1,"tv":5.32,"id":9637020}]}]}
{"op":"mcm","clk":"4233756504","pt":1631538497347,"mc":[{"id":"1.187595436","rc":[{"batb":[[0,1.01,7],[1,1.01,0]],"batl":[[1,7.2,0]],"ltp":3.4,"tv":9.05,"id":9638604},{"batl":[[0,1.4,255.49],[1,1.4,0]],"ltp":2.1,"tv":5.32,"id":9637020}]}]}
{"op":"mcm","clk":"4233757009","pt":1631538503454,"mc":[{"id":"1.187595436","rc":[{"trd":[[5,25.06]],"batb":[[0,3.1,376.13],[1,1.01,7]],"batl":[[0,10.5,74.62]],"ltp":5.0,"tv":34.11,"id":9638604},{"trd":[[1.25,100.23]],"ltp":1.25,"tv":105.55,"id":9637020}],"tv":139.66}]}
{"op":"mcm","clk":"4233757099","pt":1631538504350,"mc":[{"id":"1.187595436","rc":[{"trd":[[5,25.55]],"batl":[[0,10.5,74.13]],"ltp":5.0,"tv":34.6,"id":9638604},{"trd":[[1.25,102.21]],"batl":[[0,1.25,274.81]],"ltp":1.25,"tv":107.52,"id":9637020}],"tv":142.13}]}
{"op":"mcm","clk":"4233757156","pt":1631538505082,"mc":[{"id":"1.187595436","rc":[{"batl":[[0,1.23,255.49],[1,1.25,291.84]],"ltp":1.25,"tv":107.52,"id":9637020}]}]}
{"op":"mcm","clk":"4233757262","pt":1631538506440,"mc":[{"id":"1.187595436","rc":[{"batl":[[1,1.25,338.68]],"ltp":1.25,"tv":107.52,"id":9637020}]}]}
{"op":"mcm","clk":"4233757323","pt":1631538507271,"mc":[{"id":"1.187595436","rc":[{"batl":[[1,1.25,332.72]],"ltp":1.25,"tv":107.52,"id":9637020}]}]}
{"op":"mcm","clk":"4233757448","pt":1631538508574,"mc":[{"id":"1.187595436","rc":[{"batl":[[1,1.25,253.52]],"ltp":1.25,"tv":107.52,"id":9637020}]}]}
{"op":"mcm","clk":"4233757529","pt":1631538509466,"mc":[{"id":"1.187595436","rc":[{"batl":[[0,1.25,253.52],[1,1.25,0]],"ltp":1.25,"tv":107.52,"id":9637020}]}]}
{"op":"mcm","clk":"4233757779","pt":1631538512181,"mc":[{"id":"1.187595436","rc":[{"batb":[[0,1.12,255.49],[1,1.01,7]],"ltp":1.25,"tv":107.52,"id":9637020}]}]}
{"op":"mcm","clk":"4233758078","pt":1631538515169,"mc":[{"id":"1.187595436","rc":[{"batl":[[0,9.4,80.03]],"ltp":5.0,"tv":34.6,"id":9638604},{"batb":[[0,1.23,2.01],[1,1.12,255.49],[2,1.01,7]],"ltp":1.25,"tv":107.52,"id":9637020}]}]}
{"op":"mcm","clk":"4233758603","pt":1631538521172,"mc":[{"id":"1.187595436","rc":[{"batl":[[0,1.28,255.49]],"ltp":1.25,"tv":107.52,"id":9637020}]}]}
{"op":"mcm","clk":"4233759108","pt":1631538527282,"mc":[{"id":"1.187595436","rc":[{"batl":[[0,7.2,94.63]],"ltp":5.0,"tv":34.6,"id":9638604},{"batb":[[0,1.28,1.93],[1,1.23,2.01],[2,1.12,255.49]],"ltp":1.25,"tv":107.52,"id":9637020}]}]}
{"op":"mcm","clk":"4233759252","pt":1631538528881,"mc":[{"id":"1.187595436","rc":[{"batl":[[0,1.42,255.49]],"ltp":1.25,"tv":107.52,"id":9637020}]}]}
{"op":"mcm","clk":"4233759557","pt":1631538532391,"mc":[{"id":"1.187595436","rc":[{"batb":[[1,1.12,255.49],[2,1.01,7]],"ltp":1.25,"tv":107.52,"id":9637020}]}]}
{"op":"mcm","clk":"4233761234","pt":1631538550828,"mc":[{"id":"1.187595436","rc":[{"batb":[[0,1.12,255.49],[1,1.01,7],[2,1.01,0]],"ltp":1.25,"tv":107.52,"id":9637020}]}]}
{"op":"mcm","clk":"4233761511","pt":1631538553706,"mc":[{"id":"1.187595436","rc":[{"batl":[[0,1.24,255.49],[1,1.42,255.49]],"ltp":1.25,"tv":107.52,"id":9637020}]}]}
{"op":"mcm","clk":"4233761717","pt":1631538555741,"mc":[{"id":"1.187595436","rc":[{"batl":[[0,10.5,74.13]],"ltp":5.0,"tv":34.6,"id":9638604}]}]}
{"op":"mcm","clk":"4233762002","pt":1631538558215,"mc":[{"id":"1.187595436","rc":[{"batb":[[0,1.2,2.06],[1,1.12,255.49],[2,1.01,7]],"ltp":1.25,"tv":107.52,"id":9637020}]}]}
{"op":"mcm","clk":"4233763733","pt":1631538578085,"mc":[{"id":"1.187595436","rc":[{"batb":[[0,1.01,7],[1,1.01,0]],"ltp":5.0,"tv":34.6,"id":9638604}]}]}
{"op":"mcm","clk":"4233763924","pt":1631538580400,"mc":[{"id":"1.187595436","rc":[{"batb":[[0,1.12,255.49],[1,1.01,7],[2,1.01,0]],"ltp":1.25,"tv":107.52,"id":9637020}]}]}
{"op":"mcm","clk":"4233764083","pt":1631538582487,"mc":[{"id":"1.187595436","rc":[{"batl":[[1,1.42,0]],"ltp":1.25,"tv":107.52,"id":9637020}]}]}
{"op":"mcm","clk":"4233764153","pt":1631538583269,"mc":[{"id":"1.187595436","rc":[{"batb":[[0,1.01,7],[1,1.01,0]],"ltp":1.25,"tv":107.52,"id":9637020}]}]}
{"op":"mcm","clk":"4233764263","pt":1631538584471,"mc":[{"id":"1.187595436","rc":[{"batb":[[0,3.4,378.73],[1,1.01,7]],"batl":[[0,15.5,61]],"ltp":5.0,"tv":34.6,"id":9638604}]}]}
{"op":"mcm","clk":"4233764386","pt":1631538585984,"mc":[{"id":"1.187595436","rc":[{"batl":[[0,1.16,255.49],[1,1.24,255.49]],"ltp":1.25,"tv":107.52,"id":9637020}]}]}
{"op":"mcm","clk":"4233764680","pt":1631538588977,"mc":[{"id":"1.187595436","rc":[{"batb":[[0,1.08,255.49],[1,1.01,7]],"ltp":1.25,"tv":107.52,"id":9637020}]}]}
{"op":"mcm","clk":"4233765627","pt":1631538599607,"mc":[{"id":"1.187595436","rc":[{"batb":[[0,1.09,115.3],[1,1.08,255.49],[2,1.01,7]],"ltp":1.25,"tv":107.52,"id":9637020}]}]}
{"op":"mcm","clk":"4233765708","pt":1631538600398,"mc":[{"id":"1.187595436","rc":[{"batb":[[0,1.09,172.95]],"ltp":1.25,"tv":107.52,"id":9637020}]}]}
{"op":"mcm","clk":"4233770860","pt":1631538650106,"mc":[{"id":"1.187595436","rc":[{"batb":[[0,1.09,230.6]],"ltp":1.25,"tv":107.52,"id":9637020}]}]}
{"op":"mcm","clk":"4233775440","pt":1631538699482,"mc":[{"id":"1.187595436","rc":[{"batl":[[0,1.24,255.49],[1,1.24,0]],"ltp":1.25,"tv":107.52,"id":9637020}]}]}
{"op":"mcm","clk":"4233775861","pt":1631538704585,"mc":[{"id":"1.187595436","rc":[{"batl":[[0,12,69.43]],"ltp":5.0,"tv":34.6,"id":9638604}]}]}
{"op":"mcm","clk":"4233776044","pt":1631538706682,"mc":[{"id":"1.187595436","rc":[{"batb":[[0,1.2,2.06],[1,1.09,230.6],[2,1.08,255.49]],"ltp":1.25,"tv":107.52,"id":9637020}]}]}
{"op":"mcm","clk":"4233780283","pt":1631538733824,"mc":[{"id":"1.187595436","rc":[{"batb":[[1,1.08,255.49],[2,1.01,7]],"ltp":1.25,"tv":107.52,"id":9637020}]}]}
{"op":"mcm","clk":"4233783912","pt":1631538751875,"mc":[{"id":"1.187595436","rc":[{"batl":[[0,9.4,80.03]],"ltp":5.0,"tv":34.6,"id":9638604}]}]}
{"op":"mcm","clk":"4233786496","pt":1631538779717,"mc":[{"id":"1.187595436","rc":[{"batb":[[0,1.01,7],[1,1.01,0]],"ltp":5.0,"tv":34.6,"id":9638604}]}]}
{"op":"mcm","clk":"4233792644","pt":1631538842519,"mc":[{"id":"1.187595436","rc":[{"batb":[[0,1.08,255.49],[1,1.01,7],[2,1.01,0]],"ltp":1.25,"tv":107.52,"id":9637020}]}]}
{"op":"mcm","clk":"4233793096","pt":1631538846867,"mc":[{"id":"1.187595436","rc":[{"batl":[[0,1.2,255.49]],"ltp":1.25,"tv":107.52,"id":9637020}]}]}
{"op":"mcm","clk":"4233798172","pt":1631538898732,"mc":[{"id":"1.187595436","rc":[{"batl":[[0,1.3,255.49]],"ltp":1.25,"tv":107.52,"id":9637020}]}]}
{"op":"mcm","clk":"4233798317","pt":1631538900029,"mc":[{"id":"1.187595436","rc":[{"batb":[[0,1.2,2.17],[1,1.08,255.49],[2,1.01,7]],"ltp":1.25,"tv":107.52,"id":9637020}]}]}
{"op":"mcm","clk":"4233802279","pt":1631538937795,"mc":[{"id":"1.187595436","rc":[{"batb":[[0,2.84,377.52],[1,1.01,7]],"batl":[[0,8.2,87.69]],"ltp":5.0,"tv":34.6,"id":9638604}]}]}
{"op":"mcm","clk":"4233802394","pt":1631538938829,"mc":[{"id":"1.187595436","rc":[{"batb":[[1,1.01,7],[2,1.01,0]],"ltp":1.25,"tv":107.52,"id":9637020}]}]}
{"op":"mcm","clk":"4233802561","pt":1631538940302,"mc":[{"id":"1.187595436","rc":[{"batl":[[0,1.34,255.49]],"ltp":1.25,"tv":107.52,"id":9637020}]}]}
{"op":"mcm","clk":"4233802589","pt":1631538940715,"mc":[{"id":"1.187595436","rc":[{"batl":[[1,1.35,255.49]],"ltp":1.25,"tv":107.52,"id":9637020}]}]}
{"op":"mcm","clk":"4233802792","pt":1631538942612,"mc":[{"id":"1.187595436","rc":[{"batb":[[1,1.17,255.49],[2,1.16,255.49]],"ltp":1.25,"tv":107.52,"id":9637020}]}]}
{"op":"mcm","clk":"4233803543","pt":1631538949523,"mc":[{"id":"1.187595436","rc":[{"batb":[[0,1.17,255.49],[1,1.16,255.49],[2,1.01,7]],"ltp":1.25,"tv":107.52,"id":9637020}]}]}
{"op":"mcm","clk":"4233806174","pt":1631538970715,"mc":[{"id":"1.187595436","rc":[{"batb":[[1,1.01,7],[2,1.01,0]],"ltp":1.25,"tv":107.52,"id":9637020}]}]}
{"op":"mcm","clk":"4233806873","pt":1631538975511,"mc":[{"id":"1.187595436","rc":[{"batl":[[1,1.35,0]],"ltp":1.25,"tv":107.52,"id":9637020}]}]}
{"op":"mcm","clk":"4233807413","pt":1631538979503,"mc":[{"id":"1.187595436","rc":[{"batl":[[0,9.4,80.03]],"ltp":5.0,"tv":34.6,"id":9638604}]}]}
{"op":"mcm","clk":"4233807450","pt":1631538979745,"mc":[{"id":"1.187595436","rc":[{"batl":[[0,1.28,255.49]],"ltp":1.25,"tv":107.52,"id":9637020}]}]}
{"op":"mcm","clk":"4233812233","pt":1631539018392,"mc":[{"id":"1.187595436","rc":[{"batb":[[0,1.01,7],[1,1.01,0]],"ltp":5.0,"tv":34.6,"id":9638604}]}]}
{"op":"mcm","clk":"4233812397","pt":1631539019643,"mc":[{"id":"1.187595436","rc":[{"batb":[[0,1.01,7],[1,1.01,0]],"ltp":1.25,"tv":107.52,"id":9637020}]}]}
{"op":"mcm","clk":"4233812846","pt":1631539023291,"mc":[{"id":"1.187595436","rc":[{"batl":[[0,1.17,255.49],[1,1.28,255.49]],"ltp":1.25,"tv":107.52,"id":9637020}]}]}
{"op":"mcm","clk":"4233812948","pt":1631539024182,"mc":[{"id":"1.187595436","rc":[{"batb":[[0,3.2,376.77],[1,1.01,7]],"batl":[[0,12,69.43]],"ltp":5.0,"tv":34.6,"id":9638604}]}]}
{"op":"mcm","clk":"4233813075","pt":1631539025375,"mc":[{"id":"1.187595436","rc":[{"batb":[[0,1.11,255.49],[1,1.01,7]],"batl":[[0,1.28,255.49],[1,1.28,0]],"ltp":1.25,"tv":107.52,"id":9637020}]}]}
{"op":"mcm","clk":"4233813284","pt":1631539027099,"mc":[{"id":"1.187595436","rc":[{"batl":[[0,1.22,255.49],[1,1.28,255.49]],"ltp":1.25,"tv":107.52,"id":9637020}]}]}
{"op":"mcm","clk":"4233817871","pt":1631539068169,"mc":[{"id":"1.187595436","rc":[{"batb":[[0,1.01,7],[1,1.01,0]],"ltp":1.25,"tv":107.52,"id":9637020}]}]}
{"op":"mcm","clk":"4233817949","pt":1631539068961,"mc":[{"id":"1.187595436","rc":[{"batl":[[0,15.5,61]],"ltp":5.0,"tv":34.6,"id":9638604}]}]}
{"op":"mcm","clk":"4233818460","pt":1631539073768,"mc":[{"id":"1.187595436","rc":[{"batb":[[0,1.08,255.49],[1,1.01,7]],"ltp":1.25,"tv":107.52,"id":9637020}]}]}
{"op":"mcm","clk":"4233821633","pt":1631539103028,"mc":[{"id":"1.187595436","rc":[{"batl":[[0,13.5,65.6]],"ltp":5.0,"tv":34.6,"id":9638604}]}]}
{"op":"mcm","clk":"4233826678","pt":1631539147293,"mc":[{"id":"1.187595436","rc":[{"batl":[[0,1.28,255.49],[1,1.28,0]],"ltp":1.25,"tv":107.52,"id":9637020}]}]}
{"op":"mcm","clk":"4233827232","pt":1631539152897,"mc":[{"id":"1.187595436","rc":[{"batl":[[0,10.5,74.13]],"ltp":5.0,"tv":34.6,"id":9638604}]}]}
{"op":"mcm","clk":"4233828368","pt":1631539162413,"mc":[{"id":"1.187595436","rc":[{"batl":[[0,1.24,255.49],[1,1.28,255.49]],"ltp":1.25,"tv":107.52,"id":9637020}]}]}
{"op":"mcm","clk":"4233830490","pt":1631539182462,"mc":[{"id":"1.187595436","rc":[{"trd":[[5.1,12.77]],"ltp":5.1,"tv":47.38,"id":9638604},{"trd":[[1.24,52.54]],"batl":[[0,1.24,202.96]],"ltp":1.24,"tv":160.06,"id":9637020}],"tv":207.44}]}
{"op":"mcm","clk":"4233830886","pt":1631539186178,"mc":[{"id":"1.187595436","rc":[{"batl":[[0,7.2,94.63]],"ltp":5.1,"tv":47.38,"id":9638604},{"batl":[[0,1.28,255.49],[1,1.28,0]],"ltp":1.24,"tv":160.06,"id":9637020}]}]}
{"op":"mcm","clk":"4233831454","pt":1631539191292,"mc":[{"id":"1.187595436","rc":[{"batb":[[0,1.24,54.53],[1,1.08,255.49],[2,1.01,7]],"ltp":1.24,"tv":160.06,"id":9637020}]}]}
{"op":"mcm","clk":"4233831639","pt":1631539192769,"mc":[{"id":"1.187595436","rc":[{"batl":[[0,1.44,255.49]],"ltp":1.24,"tv":160.06,"id":9637020}]}]}
{"op":"mcm","clk":"4233831842","pt":1631539194501,"mc":[{"id":"1.187595436","rc":[{"batb":[[0,1.3,52.01],[1,1.24,54.53],[2,1.08,255.49]],"ltp":1.24,"tv":160.06,"id":9637020}]}]}
{"op":"mcm","clk":"4233833106","pt":1631539206218,"mc":[{"id":"1.187595436","rc":[{"batb":[[0,1.01,7],[1,1.01,0]],"ltp":5.1,"tv":47.38,"id":9638604}]}]}
{"op":"mcm","clk":"4233833835","pt":1631539212222,"mc":[{"id":"1.187595436","rc":[{"batb":[[0,2.42,383.37],[1,1.01,7]],"batl":[[0,5.5,118.2]],"ltp":5.1,"tv":47.38,"id":9638604}]}]}
{"op":"mcm","clk":"4233834013","pt":1631539213901,"mc":[{"id":"1.187595436","rc":[{"batb":[[0,1.36,255.49],[1,1.3,52.01],[2,1.24,54.53]],"ltp":1.24,"tv":160.06,"id":9637020}]}]}
{"op":"mcm","clk":"4233834105","pt":1631539214730,"mc":[{"id":"1.187595436","rc":[{"batb":[[0,1.42,47.62],[1,1.36,255.49],[2,1.3,52.01]],"ltp":1.24,"tv":160.06,"id":9637020}]}]}
{"op":"mcm","clk":"4233834314","pt":1631539216615,"mc":[{"id":"1.187595436","rc":[{"batl":[[0,1.55,255.49]],"ltp":1.24,"tv":160.06,"id":9637020}]}]}
{"op":"mcm","clk":"4233835153","pt":1631539224331,"mc":[{"id":"1.187595436","rc":[{"batb":[[1,1.3,52.01],[2,1.22,1.81]],"ltp":1.24,"tv":160.06,"id":9637020}]}]}
{"op":"mcm","clk":"4233836272","pt":1631539235551,"mc":[{"id":"1.187595436","rc":[{"trd":[[1.42,4]],"batb":[[0,1.42,45.61]],"ltp":1.42,"tv":164.06,"id":9637020}],"tv":211.45}]}
{"op":"mcm","clk":"4233838453","pt":1631539255999,"mc":[{"id":"1.187595436","rc":[{"batb":[[0,1.01,7],[1,1.01,0]],"ltp":5.1,"tv":47.38,"id":9638604}]}]}
{"op":"mcm","clk":"4233839127","pt":1631539262090,"mc":[{"id":"1.187595436","rc":[{"batb":[[0,2.04,395.2],[1,1.01,7]],"batl":[[0,3.9,162.6]],"ltp":5.1,"tv":47.38,"id":9638604}]}]}
{"op":"mcm","clk":"4233839204","pt":1631539262767,"mc":[{"id":"1.187595436","rc":[{"batb":[[0,1.47,255.49],[1,1.42,45.61],[2,1.3,52.01]],"ltp":1.42,"tv":164.06,"id":9637020}]}]}
{"op":"mcm","clk":"4233839481","pt":1631539265169,"mc":[{"id":"1.187595436","rc":[{"batb":[[1,1.3,52.01],[2,1.22,1.81]],"ltp":1.42,"tv":164.06,"id":9637020}]}]}
{"op":"mcm","clk":"4233839647","pt":1631539266476,"mc":[{"id":"1.187595436","rc":[{"batb":[[0,1.56,41.53],[1,1.47,255.49],[2,1.3,52.01]],"ltp":1.42,"tv":164.06,"id":9637020}]}]}
{"op":"mcm","clk":"4233839854","pt":1631539268666,"mc":[{"id":"1.187595436","rc":[{"batl":[[0,1.7,255.49]],"ltp":1.42,"tv":164.06,"id":9637020}]}]}
{"op":"mcm","clk":"4233840506","pt":1631539273894,"mc":[{"id":"1.187595436","rc":[{"batb":[[1,1.3,52.01],[2,1.22,1.81]],"ltp":1.42,"tv":164.06,"id":9637020}]}]}
{"op":"mcm","clk":"4233840669","pt":1631539275199,"mc":[{"id":"1.187595436","rc":[{"batb":[[1,1.22,1.81],[2,1.08,255.49]],"ltp":1.42,"tv":164.06,"id":9637020}]}]}
{"op":"mcm","clk":"4233841676","pt":1631539283911,"mc":[{"id":"1.187595436","rc":[{"batl":[[0,2.7,42.58],[1,3.9,162.6]],"ltp":5.1,"tv":47.38,"id":9638604}]}]}
{"op":"mcm","clk":"4233842202","pt":1631539288811,"mc":[{"id":"1.187595436","rc":[{"batb":[[0,1.22,1.81],[1,1.08,255.49],[2,1.01,7]],"ltp":1.42,"tv":164.06,"id":9637020}]}]}
{"op":"mcm","clk":"4233842547","pt":1631539291951,"mc":[{"id":"1.187595436","rc":[{"batb":[[0,1.61,40.23],[1,1.22,1.81],[2,1.08,255.49]],"ltp":1.42,"tv":164.06,"id":9637020}]}]}
{"op":"mcm","clk":"4233848159","pt":1631539345949,"mc":[{"id":"1.187595436","rc":[{"trd":[[1.61,12]],"batb":[[0,1.61,34.23]],"ltp":1.61,"tv":176.07,"id":9637020}],"tv":223.45}]}
{"op":"mcm","clk":"4233850472","pt":1631539368585,"mc":[{"id":"1.187595436","rc":[{"batb":[[1,1.08,255.49],[2,1.01,7]],"ltp":1.61,"tv":176.07,"id":9637020}]}]}
{"op":"mcm","clk":"4233850715","pt":1631539370779,"mc":[{"id":"1.187595436","rc":[{"batl":[[1,3.9,0]],"ltp":5.1,"tv":47.38,"id":9638604}]}]}
{"op":"mcm","clk":"4233851279","pt":1631539376483,"mc":[{"id":"1.187595436","rc":[{"batl":[[0,3.65,175.09]],"ltp":5.1,"tv":47.38,"id":9638604}]}]}
{"op":"mcm","clk":"4233851475","pt":1631539378360,"mc":[{"id":"1.187595436","rc":[{"trd":[[1.7,40]],"batb":[[0,1.7,12.42],[1,1.61,34.23],[2,1.08,255.49]],"ltp":1.7,"tv":216.06,"id":9637020}],"tv":263.45}]}
{"op":"mcm","clk":"4233851536","pt":1631539379085,"mc":[{"id":"1.187595436","rc":[{"batb":[[1,1.08,255.49],[2,1.01,7]],"ltp":1.7,"tv":216.06,"id":9637020}]}]}
{"op":"mcm","clk":"4233851624","pt":1631539379979,"mc":[{"id":"1.187595436","rc":[{"batl":[[0,1.8,255.49]],"ltp":1.7,"tv":216.06,"id":9637020}]}]}
{"op":"mcm","clk":"4233853096","pt":1631539394827,"mc":[{"id":"1.187595436","rc":[{"trd":[[2.24,10.71]],"ltp":2.24,"tv":58.09,"id":9638604},{"trd":[[1.8,13.33]],"batl":[[0,1.8,242.16]],"ltp":1.8,"tv":229.39,"id":9637020}],"tv":287.48}]}
{"op":"mcm","clk":"4233854920","pt":1631539412642,"mc":[{"id":"1.187595436","rc":[{"batb":[[1,1.37,25],[2,1.08,255.49]],"ltp":1.8,"tv":229.39,"id":9637020}]}]}
{"op":"mcm","clk":"4233855617","pt":1631539419141,"mc":[{"id":"1.187595436","rc":[{"trd":[[1.7,50]],"batb":[[0,1.7,7.42]],"ltp":1.7,"tv":239.39,"id":9637020}],"tv":297.48}]}
{"op":"mcm","clk":"4233856113","pt":1631539424285,"mc":[{"id":"1.187595436","rc":[{"batb":[[0,1.37,25],[1,1.08,255.49],[2,1.01,7]],"ltp":1.7,"tv":239.39,"id":9637020}]}]}
{"op":"mcm","clk":"4233856704","pt":1631539429777,"mc":[{"id":"1.187595436","rc":[{"batl":[[0,1.7,255.49],[1,1.8,242.16]],"ltp":1.7,"tv":239.39,"id":9637020}]}]}
{"op":"mcm","clk":"4233856946","pt":1631539432087,"mc":[{"id":"1.187595436","rc":[{"batb":[[0,1.6,22.88],[1,1.37,25],[2,1.08,255.49]],"ltp":1.7,"tv":239.39,"id":9637020}]}]}
{"op":"mcm","clk":"4233860890","pt":1631539467483,"mc":[{"id":"1.187595436","rc":[{"batb":[[0,1.01,7],[1,1.01,0]],"ltp":2.24,"tv":58.09,"id":9638604},{"batb":[[0,1.37,25],[1,1.08,255.49],[2,1.01,7]],"ltp":1.7,"tv":239.39,"id":9637020}]}]}
{"op":"mcm","clk":"4233861550","pt":1631539473378,"mc":[{"id":"1.187595436","rc":[{"batl":[[0,1.6,255.49],[1,1.7,255.49],[2,1.8,242.16]],"ltp":1.7,"tv":239.39,"id":9637020}]}]}
{"op":"mcm","clk":"4233861590","pt":1631539473790,"mc":[{"id":"1.187595436","rc":[{"batb":[[0,2.3,386.58],[1,1.01,7]],"batl":[[0,4.9,129.75]],"ltp":2.24,"tv":58.09,"id":9638604}]}]}
{"op":"mcm","clk":"4233862205","pt":1631539479587,"mc":[{"id":"1.187595436","rc":[{"batl":[[1,1.7,0],[2,1.8,0]],"ltp":1.7,"tv":239.39,"id":9637020}]}]}
{"op":"mcm","clk":"4233862409","pt":1631539481303,"mc":[{"id":"1.187595436","rc":[{"batb":[[0,1.44,25.42],[1,1.37,25],[2,1.08,255.49]],"ltp":1.7,"tv":239.39,"id":9637020}]}]}
{"op":"mcm","clk":"4233862888","pt":1631539485488,"mc":[{"id":"1.187595436","rc":[{"batl":[[0,1.5,255.49]],"ltp":1.7,"tv":239.39,"id":9637020}]}]}
{"op":"mcm","clk":"4233868864","pt":1631539540784,"mc":[{"id":"1.187595436","rc":[{"batb":[[0,1.01,7],[1,1.01,0]],"ltp":2.24,"tv":58.09,"id":9638604},{"batb":[[0,1.37,25],[1,1.08,255.49],[2,1.01,7]],"ltp":1.7,"tv":239.39,"id":9637020}]}]}
{"op":"mcm","clk":"4233869385","pt":1631539546714,"mc":[{"id":"1.187595436","rc":[{"batb":[[0,2.52,383.24],[1,1.01,7]],"batl":[[0,6,109.05]],"ltp":2.24,"tv":58.09,"id":9638604}]}]}
{"op":"mcm","clk":"4233869774","pt":1631539550996,"mc":[{"id":"1.187595436","rc":[{"batl":[[0,1.45,255.49],[1,1.5,255.49]],"ltp":1.7,"tv":239.39,"id":9637020}]}]}
{"op":"mcm","clk":"4233869870","pt":1631539552094,"mc":[{"id":"1.187595436","rc":[{"batb":[[0,1.37,51.72]],"ltp":1.7,"tv":239.39,"id":9637020}]}]}
{"op":"mcm","clk":"4233873756","pt":1631539587564,"mc":[{"id":"1.187595436","rc":[{"batl":[[0,3.7,42.58],[1,6,109.05]],"ltp":2.24,"tv":58.09,"id":9638604}]}]}
{"op":"mcm","clk":"4233873980","pt":1631539589594,"mc":[{"id":"1.187595436","rc":[{"batl":[[0,6,109.05],[1,6,0]],"ltp":2.24,"tv":58.09,"id":9638604}]}]}
{"op":"mcm","clk":"4233876861","pt":1631539615192,"mc":[{"id":"1.187595436","rc":[{"batl":[[0,1.5,255.49],[1,1.5,0]],"ltp":1.7,"tv":239.39,"id":9637020}]}]}
{"op":"mcm","clk":"4233877558","pt":1631539621522,"mc":[{"id":"1.187595436","rc":[{"batl":[[0,5.3,122.04]],"ltp":2.24,"tv":58.09,"id":9638604},{"batb":[[0,1.45,25.24],[1,1.37,51.72],[2,1.08,255.49]],"ltp":1.7,"tv":239.39,"id":9637020}]}]}
{"op":"mcm","clk":"4233881794","pt":1631539663492,"mc":[{"id":"1.187595436","rc":[{"trd":[[3.25,9.46]],"ltp":3.25,"tv":67.55,"id":9638604},{"trd":[[1.45,21.21]],"batb":[[0,1.45,4.04]],"ltp":1.45,"tv":260.6,"id":9637020}],"tv":328.15}]}
{"op":"mcm","clk":"4233882012","pt":1631539665583,"mc":[{"id":"1.187595436","rc":[{"batb":[[0,1.01,7],[1,1.01,0]],"ltp":3.25,"tv":67.55,"id":9638604}]}]}
{"op":"mcm","clk":"4233882122","pt":1631539666617,"mc":[{"id":"1.187595436","rc":[{"batb":[[0,3.25,11.24],[1,1.01,7]],"ltp":3.25,"tv":67.55,"id":9638604},{"batb":[[0,1.37,51.72],[1,1.08,255.49],[2,1.01,7]],"ltp":1.45,"tv":260.6,"id":9637020}]}]}
{"op":"mcm","clk":"4233882231","pt":1631539667508,"mc":[{"id":"1.187595436","rc":[{"batb":[[0,3.25,30.05]],"ltp":3.25,"tv":67.55,"id":9638604},{"batb":[[0,1.37,25]],"ltp":1.45,"tv":260.6,"id":9637020}]}]}
{"op":"mcm","clk":"4233882313","pt":1631539668402,"mc":[{"id":"1.187595436","rc":[{"batb":[[0,3.25,22.48]],"ltp":3.25,"tv":67.55,"id":9638604}]}]}
{"op":"mcm","clk":"4233882356","pt":1631539668818,"mc":[{"id":"1.187595436","rc":[{"batb":[[0,3.25,11.24]],"ltp":3.25,"tv":67.55,"id":9638604}]}]}
{"op":"mcm","clk":"4233882439","pt":1631539669702,"mc":[{"id":"1.187595436","rc":[{"batb":[[0,1.01,7],[1,1.01,0]],"ltp":3.25,"tv":67.55,"id":9638604}]}]}
{"op":"mcm","clk":"4233882700","pt":1631539672405,"mc":[{"id":"1.187595436","rc":[{"trd":[[3.75,9.13]],"batb":[[0,2.72,380.41],[1,1.01,7]],"batl":[[0,7.2,94.63]],"ltp":3.75,"tv":76.68,"id":9638604},{"trd":[[1.37,25]],"batb":[[0,1.08,255.49],[1,1.01,7],[2,1.01,0]],"ltp":1.37,"tv":285.6,"id":9637020}],"tv":362.28}]}
{"op":"mcm","clk":"4233882803","pt":1631539673502,"mc":[{"id":"1.187595436","rc":[{"batb":[[0,3.75,48.73],[1,2.72,380.25],[2,1.01,7]],"ltp":3.75,"tv":76.68,"id":9638604}]}]}
{"op":"mcm","clk":"4233882928","pt":1631539674596,"mc":[{"id":"1.187595436","rc":[{"batb":[[0,3.75,29.37]],"ltp":3.75,"tv":76.68,"id":9638604},{"batl":[[0,1.4,255.49],[1,1.5,255.49]],"ltp":1.37,"tv":285.6,"id":9637020}]}]}
{"op":"mcm","clk":"4233883014","pt":1631539675483,"mc":[{"id":"1.187595436","rc":[{"batb":[[0,3.75,15.32]],"ltp":3.75,"tv":76.68,"id":9638604},{"batl":[[0,1.37,5.4],[1,1.4,255.49],[2,1.5,255.49]],"ltp":1.37,"tv":285.6,"id":9637020}]}]}
{"op":"mcm","clk":"4233883118","pt":1631539676629,"mc":[{"id":"1.187595436","rc":[{"batb":[[0,3.75,18.23]],"ltp":3.75,"tv":76.68,"id":9638604}]}]}
{"op":"mcm","clk":"4233883289","pt":1631539678190,"mc":[{"id":"1.187595436","rc":[{"batb":[[0,2.72,380.25],[1,1.01,7],[2,1.01,0]],"ltp":3.75,"tv":76.68,"id":9638604},{"batl":[[0,1.4,255.49],[1,1.5,255.49],[2,1.5,0]],"ltp":1.37,"tv":285.6,"id":9637020}]}]}
{"op":"mcm","clk":"4233883634","pt":1631539682107,"mc":[{"id":"1.187595436","rc":[{"batb":[[0,1.2,57.65],[1,1.08,255.49],[2,1.01,7]],"ltp":1.37,"tv":285.6,"id":9637020}]}]}
{"op":"mcm","clk":"4233883703","pt":1631539682936,"mc":[{"id":"1.187595436","rc":[{"batb":[[0,1.2,115.3]],"ltp":1.37,"tv":285.6,"id":9637020}]}]}
{"op":"mcm","clk":"4233884204","pt":1631539688246,"mc":[{"id":"1.187595436","rc":[{"batb":[[0,1.3,4.51],[1,1.2,115.3],[2,1.08,255.49]],"ltp":1.37,"tv":285.6,"id":9637020}]}]}
{"op":"mcm","clk":"4233884409","pt":1631539690451,"mc":[{"id":"1.187595436","rc":[{"batb":[[1,1.2,230.6]],"batl":[[1,1.5,0]],"ltp":1.37,"tv":285.6,"id":9637020}]}]}
{"op":"mcm","clk":"4233889338","pt":1631539738028,"mc":[{"id":"1.187595436","rc":[{"batb":[[1,1.08,255.49],[2,1.01,7]],"ltp":1.37,"tv":285.6,"id":9637020}]}]}
{"op":"mcm","clk":"4233890036","pt":1631539744955,"mc":[{"id":"1.187595436","rc":[{"batb":[[0,1.01,7],[1,1.01,0]],"ltp":3.75,"tv":76.68,"id":9638604}]}]}
{"op":"mcm","clk":"4233890198","pt":1631539746835,"mc":[{"id":"1.187595436","rc":[{"batb":[[0,1.08,255.49],[1,1.01,7],[2,1.01,0]],"ltp":1.37,"tv":285.6,"id":9637020}]}]}
{"op":"mcm","clk":"4233890602","pt":1631539750948,"mc":[{"id":"1.187595436","rc":[{"batb":[[0,3.1,376.13],[1,1.01,7]],"batl":[[0,10.5,74.13]],"ltp":3.75,"tv":76.68,"id":9638604}]}]}
{"op":"mcm","clk":"4233890755","pt":1631539752557,"mc":[{"id":"1.187595436","rc":[{"batl":[[0,1.3,31]],"ltp":1.37,"tv":285.6,"id":9637020}]}]}
{"op":"mcm","clk":"4233890831","pt":1631539753448,"mc":[{"id":"1.187595436","rc":[{"batl":[[0,1.3,286.49]],"ltp":1.37,"tv":285.6,"id":9637020}]}]}
{"op":"mcm","clk":"4233890913","pt":1631539754274,"mc":[{"id":"1.187595436","rc":[{"batl":[[0,1.24,255.49],[1,1.3,255.49]],"ltp":1.37,"tv":285.6,"id":9637020}]}]}
{"op":"mcm","clk":"4233891438","pt":1631539759457,"mc":[{"id":"1.187595436","rc":[{"batb":[[0,1.12,57.65],[1,1.08,255.49],[2,1.01,7]],"ltp":1.37,"tv":285.6,"id":9637020}]}]}
{"op":"mcm","clk":"4233891473","pt":1631539759878,"mc":[{"id":"1.187595436","rc":[{"batb":[[0,1.12,172.95]],"ltp":1.37,"tv":285.6,"id":9637020}]}]}
{"op":"mcm","clk":"4233892548","pt":1631539770593,"mc":[{"id":"1.187595436","rc":[{"batb":[[0,1.12,230.6]],"ltp":1.37,"tv":285.6,"id":9637020}]}]}
{"op":"mcm","clk":"4233893838","pt":1631539783408,"mc":[{"id":"1.187595436","rc":[{"batb":[[0,1.01,7],[1,1.01,0]],"ltp":3.75,"tv":76.68,"id":9638604}]}]}
{"op":"mcm","clk":"4233893920","pt":1631539784300,"mc":[{"id":"1.187595436","rc":[{"batb":[[1,1.01,7],[2,1.01,0]],"ltp":1.37,"tv":285.6,"id":9637020}]}]}
{"op":"mcm","clk":"4233894225","pt":1631539787432,"mc":[{"id":"1.187595436","rc":[{"batl":[[1,1.3,0]],"ltp":1.37,"tv":285.6,"id":9637020}]}]}
{"op":"mcm","clk":"4233894424","pt":1631539789319,"mc":[{"id":"1.187595436","rc":[{"batb":[[0,3.5,378.9],[1,1.01,7]],"batl":[[0,18,57.46]],"ltp":3.75,"tv":76.68,"id":9638604}]}]}
{"op":"mcm","clk":"4233894584","pt":1631539790935,"mc":[{"id":"1.187595436","rc":[{"batl":[[0,1.15,255.49],[1,1.24,255.49]],"ltp":1.37,"tv":285.6,"id":9637020}]}]}
{"op":"mcm","clk":"4233895557","pt":1631539801234,"mc":[{"id":"1.187595436","rc":[{"batb":[[0,1.01,7],[1,1.01,0]],"ltp":1.37,"tv":285.6,"id":9637020}]}]}
{"op":"mcm","clk":"4233895969","pt":1631539804744,"mc":[{"id":"1.187595436","rc":[{"batb":[[0,1.01,7],[1,1.01,0]],"ltp":3.75,"tv":76.68,"id":9638604}]}]}
{"op":"mcm","clk":"4233897553","pt":1631539818702,"mc":[{"id":"1.187595436","rc":[{"batb":[[0,1.13,5.19],[1,1.01,7]],"ltp":1.37,"tv":285.6,"id":9637020}]}]}
{"op":"mcm","clk":"4233899658","pt":1631539838643,"mc":[{"id":"1.187595436","rc":[{"batb":[[0,1.01,7],[1,1.01,0]],"ltp":1.37,"tv":285.6,"id":9637020}]}]}
{"op":"mcm","clk":"4233899898","pt":1631539841140,"mc":[{"id":"1.187595436","rc":[{"batl":[[1,1.24,0]],"ltp":1.37,"tv":285.6,"id":9637020}]}]}
{"op":"mcm","clk":"4233900056","pt":1631539842866,"mc":[{"id":"1.187595436","rc":[{"batb":[[0,3.9,372.89],[1,1.01,7]],"batl":[[0,34,46.97]],"ltp":3.75,"tv":76.68,"id":9638604}]}]}
{"op":"mcm","clk":"4233900207","pt":1631539844535,"mc":[{"id":"1.187595436","rc":[{"batl":[[0,1.13,255.49],[1,1.15,255.49]],"ltp":1.37,"tv":285.6,"id":9637020}]}]}
{"op":"mcm","clk":"4233900280","pt":1631539845261,"mc":[{"id":"1.187595436","rc":[{"batb":[[0,1.04,115.3],[1,1.01,7]],"ltp":1.37,"tv":285.6,"id":9637020}]}]}
{"op":"mcm","clk":"4233900366","pt":1631539846162,"mc":[{"id":"1.187595436","rc":[{"batb":[[0,1.04,172.95],[1,1.03,57.65],[2,1.01,7]],"ltp":1.37,"tv":285.6,"id":9637020}]}]}
{"op":"mcm","clk":"4233900505","pt":1631539847579,"mc":[{"id":"1.187595436","rc":[{"batb":[[0,1.04,428.44],[1,1.03,115.3],[2,1.02,115.3]],"ltp":1.37,"tv":285.6,"id":9637020}]}]}
{"op":"mcm","clk":"4233902612","pt":1631539868709,"mc":[{"id":"1.187595436","rc":[{"batb":[[0,1.01,7],[1,1.01,0]],"ltp":3.75,"tv":76.68,"id":9638604}]}]}
{"op":"mcm","clk":"4233903807","pt":1631539880529,"mc":[{"id":"1.187595436","rc":[{"trd":[[1.04,4]],"batb":[[0,1.04,426.44]],"ltp":1.04,"tv":289.6,"id":9637020}],"tv":366.28}]}
{"op":"mcm","clk":"4233903898","pt":1631539881258,"mc":[{"id":"1.187595436","rc":[{"batb":[[0,1.04,255.49],[1,1.01,7],[2,1.02,0]],"ltp":1.04,"tv":289.6,"id":9637020}]}]}
{"op":"mcm","clk":"4233904409","pt":1631539886217,"mc":[{"id":"1.187595436","rc":[{"batl":[[0,1.15,255.49],[1,1.15,0]],"ltp":1.04,"tv":289.6,"id":9637020}]}]}
{"op":"mcm","clk":"4233904827","pt":1631539890126,"mc":[{"id":"1.187595436","rc":[{"batb":[[0,3.5,378.9],[1,1.01,7]],"batl":[[0,18,57.46]],"ltp":3.75,"tv":76.68,"id":9638604}]}]}
{"op":"mcm","clk":"4233905084","pt":1631539892537,"mc":[{"id":"1.187595436","rc":[{"batb":[[0,1.07,230.6],[1,1.04,255.49],[2,1.01,7]],"ltp":1.04,"tv":289.6,"id":9637020}]}]}
{"op":"mcm","clk":"4233905102","pt":1631539892745,"mc":[{"id":"1.187595436","rc":[{"batb":[[0,1.07,288.25]],"ltp":1.04,"tv":289.6,"id":9637020}]}]}
{"op":"mcm","clk":"4233906006","pt":1631539902074,"mc":[{"id":"1.187595436","rc":[{"batb":[[0,1.01,7],[1,1.01,0]],"ltp":3.75,"tv":76.68,"id":9638604}]}]}
{"op":"mcm","clk":"4233907589","pt":1631539917685,"mc":[{"id":"1.187595436","rc":[{"batb":[[0,1.04,255.49],[1,1.01,7],[2,1.01,0]],"ltp":1.04,"tv":289.6,"id":9637020}]}]}
{"op":"mcm","clk":"4233908066","pt":1631539921601,"mc":[{"id":"1.187595436","rc":[{"batb":[[0,4,376.78],[1,1.01,7]],"batl":[[0,46,43.74]],"ltp":3.75,"tv":76.68,"id":9638604}]}]}
{"op":"mcm","clk":"4233908959","pt":1631539930194,"mc":[{"id":"1.187595436","rc":[{"batb":[[0,1.01,7],[1,1.01,0]],"ltp":1.04,"tv":289.6,"id":9637020}]}]}
{"op":"mcm","clk":"4233910129","pt":1631539942031,"mc":[{"id":"1.187595436","rc":[{"trd":[[46,0.19]],"batl":[[0,46,43.55]],"ltp":46.0,"tv":76.86,"id":9638604},{"trd":[[1.02,8.52]],"ltp":1.02,"tv":298.11,"id":9637020}],"tv":374.98}]}
{"op":"mcm","clk":"4233910320","pt":1631539943745,"mc":[{"id":"1.187595436","rc":[{"batb":[[0,1.01,7],[1,1.01,0]],"ltp":46.0,"tv":76.86,"id":9638604}]}]}
{"op":"mcm","clk":"4233911164","pt":1631539952058,"mc":[{"id":"1.187595436","rc":[{"batb":[[0,4.1,377.53],[1,1.01,7]],"batl":[[0,60,41.53]],"ltp":46.0,"tv":76.86,"id":9638604}]}]}
{"op":"mcm","clk":"4233911271","pt":1631539953051,"mc":[{"id":"1.187595436","rc":[{"batb":[[0,1.01,7],[1,1.01,0]],"ltp":46.0,"tv":76.86,"id":9638604}]}]}
{"op":"mcm","clk":"4233912476","pt":1631539965275,"mc":[{"id":"1.187595436","rc":[{"batb":[[0,3.6,379.33],[1,1.01,7]],"batl":[[0,21,54.21]],"ltp":46.0,"tv":76.86,"id":9638604}]}]}
{"op":"mcm","clk":"4233912694","pt":1631539967570,"mc":[{"id":"1.187595436","rc":[{"batb":[[0,1.07,200],[1,1.01,7]],"ltp":1.02,"tv":298.11,"id":9637020}]}]}
{"op":"mcm","clk":"4233912730","pt":1631539967988,"mc":[{"id":"1.187595436","rc":[{"batb":[[0,1.07,400]],"ltp":1.02,"tv":298.11,"id":9637020}]}]}
{"op":"mcm","clk":"4233918425","pt":1631540031066,"mc":[{"id":"1.187595436","rc":[{"batb":[[0,1.01,7],[1,1.01,0]],"ltp":46.0,"tv":76.86,"id":9638604}]}]}
{"op":"mcm","clk":"4233919765","pt":1631540044699,"mc":[{"id":"1.187595436","rc":[{"batb":[[0,1.01,7],[1,1.01,0]],"ltp":1.02,"tv":298.11,"id":9637020}]}]}
{"op":"mcm","clk":"4233920168","pt":1631540049019,"mc":[{"id":"1.187595436","rc":[{"batb":[[0,3.2,379.43],[1,1.01,7]],"batl":[[0,12,68.7]],"ltp":46.0,"tv":76.86,"id":9638604}]}]}
{"op":"mcm","clk":"4233921720","pt":1631540064412,"mc":[{"id":"1.187595436","rc":[{"batb":[[0,1.01,7],[1,1.01,0]],"ltp":46.0,"tv":76.86,"id":9638604}]}]}
{"op":"mcm","clk":"4233923384","pt":1631540082545,"mc":[{"id":"1.187595436","rc":[{"batl":[[0,26,50.05]],"ltp":46.0,"tv":76.86,"id":9638604}]}]}
{"op":"mcm","clk":"4233923394","pt":1631540082690,"mc":[{"id":"1.187595436","rc":[{"batb":[[0,3.75,378.18],[1,1.01,7]],"ltp":46.0,"tv":76.86,"id":9638604}]}]}
{"op":"mcm","clk":"4233924971","pt":1631540097766,"mc":[{"id":"1.187595436","rc":[{"batb":[[0,1.01,7],[1,1.01,0]],"ltp":46.0,"tv":76.86,"id":9638604}]}]}
{"op":"mcm","clk":"4233925484","pt":1631540102568,"mc":[{"id":"1.187595436","rc":[{"trd":[[1.01,14]],"batl":[[0,1.01,1.52]],"ltp":1.01,"tv":312.11,"id":9637020}],"tv":388.98}]}
{"op":"mcm","clk":"4233926283","pt":1631540110475,"mc":[{"id":"1.187595436","rc":[{"batb":[[0,4.4,378.65],[1,1.01,7]],"ltp":46.0,"tv":76.86,"id":9638604}]}]}
{"op":"mcm","clk":"4233926356","pt":1631540111271,"mc":[{"id":"1.187595436","rc":[{"batb":[[0,1.01,100]],"batl":[[0,1.09,255.49]],"ltp":1.01,"tv":312.11,"id":9637020}]}]}
{"op":"mcm","clk":"4233926470","pt":1631540112370,"mc":[{"id":"1.187595436","rc":[{"batb":[[0,1.01,400]],"ltp":1.01,"tv":312.11,"id":9637020}]}]}
{"op":"mcm","clk":"4233926583","pt":1631540113679,"mc":[{"id":"1.187595436","rc":[{"batb":[[0,1.01,500]],"ltp":1.01,"tv":312.11,"id":9637020}]}]}
{"op":"mcm","clk":"4233926776","pt":1631540115478,"mc":[{"id":"1.187595436","rc":[{"batb":[[0,1.01,600]],"ltp":1.01,"tv":312.11,"id":9637020}]}]}
{"op":"mcm","clk":"4233927875","pt":1631540126221,"mc":[{"id":"1.187595436","rc":[{"trd":[[1.01,1213.12]],"batb":[[0,1.01,0.44]],"ltp":1.01,"tv":1511.23,"id":9637020}],"tv":1588.1}]}
{"op":"mcm","clk":"4233928933","pt":1631540136447,"mc":[{"id":"1.187595436","rc":[{"batb":[[0,1.01,7],[1,1.01,0]],"ltp":46.0,"tv":76.86,"id":9638604}]}]}
{"op":"mcm","clk":"4233929111","pt":1631540138128,"mc":[{"id":"1.187595436","rc":[{"batb":[[0,1.01,400.44]],"ltp":1.01,"tv":1511.23,"id":9637020}]}]}
{"op":"mcm","clk":"4233931017","pt":1631540155949,"mc":[{"id":"1.187595436","rc":[{"batb":[[0,4.5,379.16],[1,1.01,7]],"ltp":46.0,"tv":76.86,"id":9638604}]}]}
{"op":"mcm","clk":"4233931216","pt":1631540157740,"mc":[{"id":"1.187595436","rc":[{"batb":[[0,1.01,7],[1,1.01,0]],"ltp":46.0,"tv":76.86,"id":9638604}]}]}
{"op":"mcm","clk":"4233931365","pt":1631540159207,"mc":[{"id":"1.187595436","rc":[{"batl":[[0,1.1,2]],"ltp":1.01,"tv":1511.23,"id":9637020}]}]}
{"op":"mcm","clk":"4233931478","pt":1631540160154,"mc":[{"id":"1.187595436","rc":[{"batl":[[0,1.1,10]],"ltp":1.01,"tv":1511.23,"id":9637020}]}]}
{"op":"mcm","clk":"4233931773","pt":1631540162487,"mc":[{"id":"1.187595436","rc":[{"batl":[[0,1.1,16]],"ltp":1.01,"tv":1511.23,"id":9637020}]}]}
{"op":"mcm","clk":"4233933433","pt":1631540177101,"mc":[{"id":"1.187595436","rc":[{"batl":[[0,1.01,600]],"ltp":1.01,"tv":1511.23,"id":9637020}]}]}
{"op":"mcm","clk":"4233934729","pt":1631540189624,"mc":[{"id":"1.187595436","rc":[{"batl":[[1,1.09,43.55]],"ltp":1.01,"tv":1511.23,"id":9637020}]}]}
{"op":"mcm","clk":"4233936968","pt":1631540212100,"mc":[{"id":"1.187595436","marketDefinition":{"bspMarket":false,"turnInPlayEnabled":true,"persistenceEnabled":true,"marketBaseRate":5.0,"eventId":"30897919","eventTypeId":"2","numberOfWinners":1,"bettingType":"ODDS","marketType":"MATCH_ODDS","marketTime":"2021-09-13T11:39:48.000Z","suspendTime":"2021-09-13T11:39:48.000Z","bspReconciled":false,"complete":true,"inPlay":true,"crossMatching":true,"runnersVoidable":false,"numberOfActiveRunners":2,"betDelay":5,"status":"SUSPENDED","runners":[{"status":"ACTIVE","sortPriority":1,"id":9638604,"name":"J Fourlis"},{"status":"ACTIVE","sortPriority":2,"id":9637020,"name":"A Prisacariu"}],"regulators":["MR_INT"],"countryCode":"GB","discountAllowed":true,"timezone":"GMT","openDate":"2021-09-13T11:39:48.000Z","version":4030720962,"name":"Match Odds","eventName":"J Fourlis v A Prisacariu"}}]}
{"op":"mcm","clk":"4233937747","pt":1631540219993,"mc":[{"id":"1.187595436","tv":0.0}]}
{"op":"mcm","clk":"4233937875","pt":1631540221152,"mc":[{"id":"1.187595436","marketDefinition":{"bspMarket":false,"turnInPlayEnabled":true,"persistenceEnabled":true,"marketBaseRate":5.0,"eventId":"30897919","eventTypeId":"2","numberOfWinners":1,"bettingType":"ODDS","marketType":"MATCH_ODDS","marketTime":"2021-09-13T11:39:48.000Z","suspendTime":"2021-09-13T11:39:48.000Z","bspReconciled":false,"complete":true,"inPlay":true,"crossMatching":false,"runnersVoidable":false,"numberOfActiveRunners":0,"betDelay":5,"status":"CLOSED","settledTime":"2021-09-13T13:36:56.000Z","runners":[{"status":"LOSER","sortPriority":1,"id":9638604,"name":"J Fourlis"},{"status":"WINNER","sortPriority":2,"id":9637020,"name":"A Prisacariu"}],"regulators":["MR_INT"],"countryCode":"GB","discountAllowed":true,"timezone":"GMT","openDate":"2021-09-13T11:39:48.000Z","version":4030721054,"name":"Match Odds","eventName":"J Fourlis v A Prisacariu"}}]}
