{"op":"mcm","clk":"4233696246","pt":1631537719181,"mc":[{"id":"1.187557759","rc":[{"batb":[[0,1.5,288.58],[1,1.47,59.67],[2,1.45,67.7]],"ltp":1.62,"tv":4864.37,"id":9634485}]}]}
{"op":"mcm","clk":"4233696374","pt":1631537721792,"mc":[{"id":"1.187557759","rc":[{"batb":[[0,1.72,11.17],[1,1.71,87.72],[2,1.7,43.86]],"batl":[[2,1.83,472.17]],"ltp":1.62,"tv":4864.37,"id":9634485},{"batb":[[0,2.32,10.09],[1,2.28,6.66],[2,2.2,33.56]],"batl":[[0,2.4,301.53],[1,2.5,80],[2,2.68,3.73]],"ltp":2.5,"tv":1401.16,"id":9712888}]}]}
{"op":"mcm","clk":"4233696437","pt":1631537722786,"mc":[{"id":"1.187557759","rc":[{"trd":[[1.72,290.03]],"batb":[[0,1.72,82.56],[1,1.71,65.73],[2,1.7,124.87]],"batl":[[1,1.79,83.8],[2,1.8,138.99]],"ltp":1.72,"tv":4876.07,"id":9634485},{"batl":[[1,2.42,11.25],[2,2.5,80]],"ltp":2.5,"tv":1401.16,"id":9712888}],"tv":6277.23}]}
{"op":"mcm","clk":"4233696481","pt":1631537723492,"mc":[{"id":"1.187557759","rc":[{"batl":[[1,1.79,16.76],[2,1.8,105.47]],"ltp":1.72,"tv":4876.07,"id":9634485}]}]}
{"op":"mcm","clk":"4233696701","pt":1631537726794,"mc":[{"id":"1.187557759","rc":[{"batl":[[0,1.74,14.78],[1,1.78,140.05],[2,1.79,16.76]],"ltp":1.72,"tv":4876.07,"id":9634485},{"batl":[[2,2.46,68.09]],"ltp":2.5,"tv":1401.16,"id":9712888}]}]}
{"op":"mcm","clk":"4233696717","pt":1631537727001,"mc":[{"id":"1.187557759","rc":[{"batl":[[0,1.78,140.05],[1,1.79,16.76],[2,1.8,105.47]],"ltp":1.72,"tv":4876.07,"id":9634485},{"batl":[[2,2.5,80]],"ltp":2.5,"tv":1401.16,"id":9712888}]}]}
{"op":"mcm","clk":"4233696860","pt":1631537729503,"mc":[{"id":"1.187557759","rc":[{"batb":[[2,2.2,40.88]],"ltp":2.5,"tv":1401.16,"id":9712888}]}]}
{"op":"mcm","clk":"4233696911","pt":1631537730441,"mc":[{"id":"1.187557759","rc":[{"batb":[[2,2.22,6.84]],"ltp":2.5,"tv":1401.16,"id":9712888}]}]}
{"op":"mcm","clk":"4233697081","pt":1631537733020,"mc":[{"id":"1.187557759","rc":[{"batb":[[0,1.72,77.24]],"ltp":1.72,"tv":4876.07,"id":9634485},{"batb":[[0,2.28,6.66],[1,2.22,6.84],[2,2.2,40.88]],"ltp":2.5,"tv":1401.16,"id":9712888}]}]}
{"op":"mcm","clk":"4233697249","pt":1631537735948,"mc":[{"id":"1.187557759","rc":[{"batl":[[0,1.74,7.95],[1,1.78,140.05],[2,1.79,16.76]],"ltp":1.72,"tv":4876.07,"id":9634485},{"batl":[[0,2.4,308.14]],"ltp":2.5,"tv":1401.16,"id":9712888}]}]}
{"op":"mcm","clk":"4233697419","pt":1631537738516,"mc":[{"id":"1.187557759","rc":[{"batb":[[0,1.61,48.09],[1,1.6,45.79],[2,1.55,52.64]],"batl":[[0,1.84,29.78],[1,1.85,30.5],[2,2.22,429.66]],"ltp":1.72,"tv":4876.07,"id":9634485},{"batb":[[0,2.18,6.47],[1,2.06,40.75],[2,1.7,16.97]],"batl":[[0,2.64,5.43],[1,2.68,5.14],[2,3.15,3.7]],"ltp":2.5,"tv":1401.16,"id":9712888}]}]}
{"op":"mcm","clk":"4233697609","pt":1631537741730,"mc":[{"id":"1.187557759","rc":[{"batb":[[0,1.64,41.82],[1,1.61,48.09],[2,1.6,45.79]],"batl":[[0,1.82,31.75],[1,1.84,29.78],[2,1.85,30.5]],"ltp":1.72,"tv":4876.07,"id":9634485},{"batb":[[1,2.16,8.03],[2,2.06,40.75]],"batl":[[0,2.58,5.75],[1,2.64,5.43],[2,2.68,5.14]],"ltp":2.5,"tv":1401.16,"id":9712888}]}]}
{"op":"mcm","clk":"4233697675","pt":1631537742732,"mc":[{"id":"1.187557759","rc":[{"batb":[[0,1.69,107.89],[1,1.67,123.73],[2,1.61,48.09]],"batl":[[0,1.75,114.69],[1,1.77,102.61],[2,1.84,29.78]],"ltp":1.72,"tv":4876.07,"id":9634485},{"batb":[[0,2.34,21.72],[1,2.18,6.47],[2,2.16,8.03]],"batl":[[0,2.4,18.39]],"ltp":2.5,"tv":1401.16,"id":9712888}]}]}
{"op":"mcm","clk":"4233697694","pt":1631537743043,"mc":[{"id":"1.187557759","rc":[{"batl":[[0,1.75,93.03]],"ltp":1.72,"tv":4876.07,"id":9634485},{"batb":[[0,2.18,6.47],[1,2.16,8.03],[2,2.06,40.75]],"batl":[[0,2.64,5.43],[1,2.68,5.14],[2,3.15,3.7]],"ltp":2.5,"tv":1401.16,"id":9712888}]}]}
{"op":"mcm","clk":"4233697818","pt":1631537745240,"mc":[{"id":"1.187557759","rc":[{"batb":[[2,1.64,43.32]],"batl":[[2,1.82,29.25]],"ltp":1.72,"tv":4876.07,"id":9634485},{"batl":[[0,2.58,5.44],[1,2.64,5.43],[2,2.68,5.14]],"ltp":2.5,"tv":1401.16,"id":9712888}]}]}
{"op":"mcm","clk":"4233697923","pt":1631537747233,"mc":[{"id":"1.187557759","rc":[{"batb":[[0,1.61,48.09],[1,1.6,45.79],[2,1.55,52.64]],"batl":[[0,1.84,29.78],[1,1.85,30.5],[2,2.22,429.66]],"ltp":1.72,"tv":4876.07,"id":9634485},{"batl":[[0,2.64,5.43],[1,2.68,5.14],[2,3.15,3.7]],"ltp":2.5,"tv":1401.16,"id":9712888}]}]}
{"op":"mcm","clk":"4233698139","pt":1631537750742,"mc":[{"id":"1.187557759","rc":[{"batb":[[1,1.6,139.96],[2,1.59,74.47]],"ltp":1.72,"tv":4876.07,"id":9634485}]}]}
{"op":"mcm","clk":"4233698208","pt":1631537751848,"mc":[{"id":"1.187557759","rc":[{"batb":[[0,2.2,6.97],[1,2.18,6.47],[2,2.16,8.03]],"ltp":2.5,"tv":1401.16,"id":9712888}]}]}
{"op":"mcm","clk":"4233698234","pt":1631537752263,"mc":[{"id":"1.187557759","rc":[{"trd":[[1.61,63.64]],"batb":[[0,1.61,41.88],[1,1.6,584.61]],"batl":[[0,1.64,18.3],[1,1.65,113.32],[2,1.66,72.55]],"ltp":1.61,"tv":4888.49,"id":9634485},{"batb":[[0,2.6,6.75],[1,2.32,933.6],[2,2.18,6.47]],"ltp":2.5,"tv":1401.16,"id":9712888}],"tv":6289.65}]}
{"op":"mcm","clk":"4233698305","pt":1631537753358,"mc":[{"id":"1.187557759","rc":[{"batb":[[1,2.42,25.19],[2,2.32,933.6]],"batl":[[2,2.74,10.94]],"ltp":2.5,"tv":1401.16,"id":9712888}]}]}
{"op":"mcm","clk":"4233699324","pt":1631537769697,"mc":[{"id":"1.187557759","rc":[{"batb":[[1,1.6,139.96]],"batl":[[0,1.64,9.15],[1,1.65,108.75],[2,1.66,67.98]],"ltp":1.61,"tv":4888.49,"id":9634485},{"batb":[[0,2.42,25.19],[1,2.18,40.78],[2,2.16,8.03]],"batl":[[2,2.74,5.47]],"ltp":2.5,"tv":1401.16,"id":9712888}]}]}
{"op":"mcm","clk":"4233699350","pt":1631537770114,"mc":[{"id":"1.187557759","rc":[{"batb":[[0,1.5,288.58],[1,1.45,56.01],[2,1.41,75.9]],"batl":[[0,2.22,429.66],[1,1.65,0],[2,1.66,0]],"ltp":1.61,"tv":4888.49,"id":9634485},{"batb":[[0,2.18,34.31],[1,1.7,16.97],[2,1.6,99.04]],"batl":[[0,3.25,4.1],[1,3.6,3.21],[2,2.74,0]],"ltp":2.5,"tv":1401.16,"id":9712888}]}]}
{"op":"mcm","clk":"4233699516","pt":1631537773112,"mc":[{"id":"1.187557759","rc":[{"batb":[[1,1.8,11.88],[2,1.7,16.97]],"ltp":2.5,"tv":1401.16,"id":9712888}]}]}
{"op":"mcm","clk":"4233699592","pt":1631537774314,"mc":[{"id":"1.187557759","rc":[{"batb":[[0,1.41,75.9],[1,1.39,61.91],[2,1.3,198.07]],"ltp":1.61,"tv":4888.49,"id":9634485},{"batl":[[0,3.6,3.21],[1,3.6,0]],"ltp":2.5,"tv":1401.16,"id":9712888}]}]}
{"op":"mcm","clk":"4233699672","pt":1631537775694,"mc":[{"id":"1.187557759","rc":[{"batb":[[0,1.57,84.95],[1,1.56,80.04],[2,1.41,75.9]],"batl":[[0,1.61,65.09],[1,1.62,69.3]],"ltp":1.61,"tv":4888.49,"id":9634485}]}]}
{"op":"mcm","clk":"4233699817","pt":1631537778095,"mc":[{"id":"1.187557759","rc":[{"batl":[[2,2.1,467.37]],"ltp":1.61,"tv":4888.49,"id":9634485}]}]}
{"op":"mcm","clk":"4233699962","pt":1631537780399,"mc":[{"id":"1.187557759","rc":[{"batb":[[0,1.41,75.9],[1,1.4,306.86],[2,1.39,61.91]],"batl":[[0,2.1,467.37],[1,1.62,0],[2,2.1,0]],"ltp":1.61,"tv":4888.49,"id":9634485}]}]}
{"op":"mcm","clk":"4233700134","pt":1631537783529,"mc":[{"id":"1.187557759","rc":[{"batb":[[0,1.45,157.16],[1,1.44,111.56],[2,1.41,75.9]],"ltp":1.61,"tv":4888.49,"id":9634485}]}]}
{"op":"mcm","clk":"4233700234","pt":1631537785306,"mc":[{"id":"1.187557759","rc":[{"batb":[[0,1.46,14.78],[1,1.45,157.16],[2,1.44,111.56]],"batl":[[0,1.48,16.5],[1,1.49,89.99],[2,1.5,92.68]],"ltp":1.61,"tv":4888.49,"id":9634485},{"batb":[[0,2.98,97.32],[1,2.96,15.11],[2,2.94,15.11]],"batl":[[0,3.2,268.46],[1,3.6,3.21]],"ltp":2.5,"tv":1401.16,"id":9712888}]}]}
{"op":"mcm","clk":"4233700325","pt":1631537786731,"mc":[{"id":"1.187557759","rc":[{"batb":[[1,1.45,219.22],[2,1.44,163.28]],"ltp":1.61,"tv":4888.49,"id":9634485},{"batl":[[1,3.55,2.82],[2,3.6,3.21]],"ltp":2.5,"tv":1401.16,"id":9712888}]}]}
{"op":"mcm","clk":"4233700404","pt":1631537787724,"mc":[{"id":"1.187557759","rc":[{"batb":[[1,1.45,177.84],[2,1.44,121.9]],"ltp":1.61,"tv":4888.49,"id":9634485},{"batb":[[0,2.98,77.18],[1,2.96,5.04],[2,2.94,5.04]],"ltp":2.5,"tv":1401.16,"id":9712888}]}]}
{"op":"mcm","clk":"4233700534","pt":1631537789701,"mc":[{"id":"1.187557759","rc":[{"batb":[[0,1.47,103],[1,1.46,14.78],[2,1.45,177.84]],"ltp":1.61,"tv":4888.49,"id":9634485}]}]}
{"op":"mcm","clk":"4233700862","pt":1631537794814,"mc":[{"id":"1.187557759","rc":[{"trd":[[1.48,13.9]],"batl":[[0,1.48,9.55]],"ltp":1.48,"tv":4902.39,"id":9634485}],"tv":6303.56}]}
{"op":"mcm","clk":"4233701341","pt":1631537802632,"mc":[{"id":"1.187557759","rc":[{"trd":[[1.48,14.01]],"batl":[[0,1.48,9.44]],"ltp":1.48,"tv":4902.5,"id":9634485},{"trd":[[3.05,0.06]],"ltp":3.05,"tv":1401.22,"id":9712888}],"tv":6303.72}]}
{"op":"mcm","clk":"4233701482","pt":1631537805140,"mc":[{"id":"1.187557759","rc":[{"batb":[[1,1.45,177.84],[2,1.44,121.9]],"batl":[[0,1.49,89.99],[1,1.5,92.68],[2,1.95,515.54]],"ltp":1.48,"tv":4902.5,"id":9634485}]}]}
{"op":"mcm","clk":"4233701584","pt":1631537806773,"mc":[{"id":"1.187557759","rc":[{"batb":[[1,1.34,323.42],[2,1.29,78.81]],"batl":[[0,1.95,515.54],[1,880,0.01],[2,1.95,0]],"ltp":1.48,"tv":4902.5,"id":9634485},{"batb":[[0,2.44,25.1],[1,1.8,11.88],[2,1.7,16.97]],"batl":[[0,4.5,2.43],[1,5.4,2.04],[2,3.6,0]],"ltp":3.05,"tv":1401.22,"id":9712888}]}]}
{"op":"mcm","clk":"4233701619","pt":1631537807349,"mc":[{"id":"1.187557759","rc":[{"batb":[[0,1.34,323.42],[1,1.29,78.81],[2,1.27,124.94]],"ltp":1.48,"tv":4902.5,"id":9634485}]}]}
{"op":"mcm","clk":"4233701758","pt":1631537809651,"mc":[{"id":"1.187557759","rc":[{"batl":[[1,5.2,2.03],[2,5.4,2.04]],"ltp":3.05,"tv":1401.22,"id":9712888}]}]}
{"op":"mcm","clk":"4233701887","pt":1631537811749,"mc":[{"id":"1.187557759","rc":[{"batl":[[0,1.49,367.05],[1,1.95,515.54],[2,880,0.01]],"ltp":1.48,"tv":4902.5,"id":9634485}]}]}
{"op":"mcm","clk":"4233701945","pt":1631537812672,"mc":[{"id":"1.187557759","rc":[{"batb":[[0,1.42,135.09],[1,1.41,122.31],[2,1.34,323.42]],"batl":[[0,1.46,143.59],[1,1.47,100.22],[2,1.95,515.54]],"ltp":1.48,"tv":4902.5,"id":9634485}]}]}
{"op":"mcm","clk":"4233702134","pt":1631537816266,"mc":[{"id":"1.187557759","rc":[{"batb":[[0,1.42,232.09]],"ltp":1.48,"tv":4902.5,"id":9634485}]}]}
{"op":"mcm","clk":"4233702356","pt":1631537819354,"mc":[{"id":"1.187557759","rc":[{"batb":[[0,1.34,323.42],[1,1.29,78.81],[2,1.27,124.94]],"batl":[[0,1.95,515.54],[1,880,0.01],[2,1.95,0]],"ltp":1.48,"tv":4902.5,"id":9634485}]}]}
{"op":"mcm","clk":"4233702569","pt":1631537822461,"mc":[{"id":"1.187557759","rc":[{"batb":[[1,1.3,227.52],[2,1.29,270.97]],"batl":[[0,1.64,112.8],[1,1.65,64.73],[2,1.95,515.54]],"ltp":1.48,"tv":4902.5,"id":9634485}]}]}
{"op":"mcm","clk":"4233702785","pt":1631537826367,"mc":[{"id":"1.187557759","rc":[{"batb":[[1,1.29,78.81],[2,1.27,124.94]],"ltp":1.48,"tv":4902.5,"id":9634485}]}]}
{"op":"mcm","clk":"4233702915","pt":1631537828760,"mc":[{"id":"1.187557759","rc":[{"batb":[[0,1.29,78.81],[1,1.27,124.94],[2,1.24,104.02]],"batl":[[2,880,0.01]],"ltp":1.48,"tv":4902.5,"id":9634485}]}]}
{"op":"mcm","clk":"4233702963","pt":1631537829798,"mc":[{"id":"1.187557759","rc":[{"batb":[[0,1.6,49.29],[1,1.59,92.2],[2,1.58,76.25]],"batl":[[0,1.62,14.57],[1,1.64,112.8],[2,1.65,64.73]],"ltp":1.48,"tv":4902.5,"id":9634485},{"batl":[[0,2.64,15.16],[1,2.68,9.89],[2,2.72,331.23]],"ltp":3.05,"tv":1401.22,"id":9712888}]}]}
{"op":"mcm","clk":"4233702992","pt":1631537830481,"mc":[{"id":"1.187557759","rc":[{"trd":[[1.6,12.5]],"batb":[[0,1.6,43.04]],"ltp":1.6,"tv":4915.0,"id":9634485},{"batb":[[0,2.54,11.82],[1,2.52,5.9],[2,2.5,5.9]],"ltp":3.05,"tv":1401.22,"id":9712888}],"tv":6316.22}]}
{"op":"mcm","clk":"4233703340","pt":1631537836197,"mc":[{"id":"1.187557759","rc":[{"batb":[[0,1.61,107],[1,1.6,43.04],[2,1.59,92.2]],"ltp":1.6,"tv":4915.0,"id":9634485}]}]}
{"op":"mcm","clk":"4233704531","pt":1631537857167,"mc":[{"id":"1.187557759","rc":[{"batb":[[1,1.59,92.2],[2,1.58,76.25]],"ltp":1.6,"tv":4915.0,"id":9634485}]}]}
{"op":"mcm","clk":"4233705019","pt":1631537865771,"mc":[{"id":"1.187557759","rc":[{"batb":[[1,1.55,52.8],[2,1.45,47.01]],"batl":[[0,1.78,34.25],[1,2.16,443.34],[2,880,0.01]],"ltp":1.6,"tv":4915.0,"id":9634485},{"batb":[[0,2.44,25.1],[1,2.28,7.16],[2,2.18,34.14]],"batl":[[0,3.25,3.54],[1,3.3,3.45],[2,3.5,3.17]],"ltp":3.05,"tv":1401.22,"id":9712888}]}]}
{"op":"mcm","clk":"4233705077","pt":1631537866688,"mc":[{"id":"1.187557759","rc":[{"batb":[[0,1.44,356.42],[1,1.41,76.74],[2,1.4,60.56]],"ltp":1.6,"tv":4915.0,"id":9634485},{"batb":[[0,2.28,7.16],[1,2.18,34.14],[2,1.8,11.88]],"batl":[[0,3.3,3.45],[1,3.5,3.17],[2,3.65,2.7]],"ltp":3.05,"tv":1401.22,"id":9712888}]}]}
{"op":"mcm","clk":"4233705177","pt":1631537868786,"mc":[{"id":"1.187557759","rc":[{"batl":[[0,1.77,87.88],[1,1.78,34.25],[2,1.79,98.91]],"ltp":1.6,"tv":4915.0,"id":9634485}]}]}
{"op":"mcm","clk":"4233705225","pt":1631537869478,"mc":[{"id":"1.187557759","rc":[{"batb":[[0,1.41,76.74],[1,1.4,60.56],[2,1.24,104.02]],"ltp":1.6,"tv":4915.0,"id":9634485},{"batl":[[0,3.5,3.17],[1,5.2,2.03],[2,5.4,2.04]],"ltp":3.05,"tv":1401.22,"id":9712888}]}]}
{"op":"mcm","clk":"4233705305","pt":1631537870777,"mc":[{"id":"1.187557759","rc":[{"batb":[[0,1.72,41.84],[1,1.41,76.74],[2,1.4,60.56]],"ltp":1.6,"tv":4915.0,"id":9634485},{"batb":[[0,2.36,6.55],[1,2.28,7.16],[2,2.18,34.14]],"batl":[[0,2.4,9.99],[1,2.42,386.27],[2,2.44,1367]],"ltp":3.05,"tv":1401.22,"id":9712888}]}]}
{"op":"mcm","clk":"4233705377","pt":1631537871796,"mc":[{"id":"1.187557759","rc":[{"trd":[[1.72,301.73]],"batb":[[0,1.72,35.99],[1,1.71,101.53],[2,1.69,118.6]],"ltp":1.72,"tv":4926.7,"id":9634485},{"batb":[[1,2.28,72.96],[2,2.26,32.9]],"batl":[[1,2.42,336.69],[2,2.44,88.16]],"ltp":3.05,"tv":1401.22,"id":9712888}],"tv":6327.92}]}
{"op":"mcm","clk":"4233705428","pt":1631537872666,"mc":[{"id":"1.187557759","rc":[{"batb":[[1,2.28,20.32],[2,2.26,6.58]],"ltp":3.05,"tv":1401.22,"id":9712888}]}]}
{"op":"mcm","clk":"4233705643","pt":1631537875690,"mc":[{"id":"1.187557759","rc":[{"batl":[[0,1.74,9.06],[1,1.77,87.88],[2,1.78,34.25]],"ltp":1.72,"tv":4926.7,"id":9634485}]}]}
{"op":"mcm","clk":"4233705662","pt":1631537875892,"mc":[{"id":"1.187557759","rc":[{"batl":[[0,1.77,87.88],[1,1.78,34.25],[2,1.79,98.91]],"ltp":1.72,"tv":4926.7,"id":9634485}]}]}
{"op":"mcm","clk":"4233706159","pt":1631537883792,"mc":[{"id":"1.187557759","rc":[{"trd":[[1.72,302.01]],"batb":[[0,1.72,35.85]],"ltp":1.72,"tv":4926.98,"id":9634485}],"tv":6328.2}]}
{"op":"mcm","clk":"4233706202","pt":1631537884415,"mc":[{"id":"1.187557759","rc":[{"batb":[[0,1.58,39.06],[1,1.54,54.06],[2,1.5,285.57]],"batl":[[0,1.85,31.5],[1,2.16,443.34],[2,880,0.01]],"ltp":1.72,"tv":4926.98,"id":9634485},{"batb":[[0,2.16,7.53],[1,2.02,42.59],[2,1.7,16.97]],"batl":[[0,2.74,5.75],[1,3.5,3.17],[2,5.2,2.03]],"ltp":3.05,"tv":1401.22,"id":9712888}]}]}
{"op":"mcm","clk":"4233706438","pt":1631537887698,"mc":[{"id":"1.187557759","rc":[{"batb":[[0,1.62,37.54],[1,1.58,125.23],[2,1.57,78.09]],"batl":[[0,1.82,28.25],[1,1.85,31.5],[2,1.89,85.79]],"ltp":1.72,"tv":4926.98,"id":9634485},{"batl":[[0,2.62,5.75],[1,2.74,5.75],[2,3.5,3.17]],"ltp":3.05,"tv":1401.22,"id":9712888}]}]}
{"op":"mcm","clk":"4233706465","pt":1631537888105,"mc":[{"id":"1.187557759","rc":[{"batb":[[0,1.58,125.23],[1,1.57,78.09],[2,1.54,54.06]],"batl":[[0,1.85,31.5],[1,1.89,85.79],[2,1.91,80.49]],"ltp":1.72,"tv":4926.98,"id":9634485},{"batl":[[0,2.74,5.75],[1,3.5,3.17],[2,5.2,2.03]],"ltp":3.05,"tv":1401.22,"id":9712888}]}]}
{"op":"mcm","clk":"4233706628","pt":1631537890798,"mc":[{"id":"1.187557759","rc":[{"batb":[[0,1.58,39.06],[1,1.54,54.06],[2,1.5,285.57]],"ltp":1.72,"tv":4926.98,"id":9634485},{"batb":[[0,2.2,6.72],[1,2.16,7.53],[2,2.02,42.59]],"ltp":3.05,"tv":1401.22,"id":9712888}]}]}
{"op":"mcm","clk":"4233706675","pt":1631537891631,"mc":[{"id":"1.187557759","rc":[{"batb":[[2,1.4,60.56]],"ltp":1.72,"tv":4926.98,"id":9634485},{"batb":[[0,2.16,7.53],[1,2.02,42.59],[2,1.7,16.97]],"ltp":3.05,"tv":1401.22,"id":9712888}]}]}
{"op":"mcm","clk":"4233706754","pt":1631537892797,"mc":[{"id":"1.187557759","rc":[{"batb":[[0,1.81,110.5],[1,1.58,39.06],[2,1.54,54.06]],"batl":[[1,1.86,17.52],[2,1.89,85.79]],"ltp":1.72,"tv":4926.98,"id":9634485},{"batl":[[0,2.24,448.12],[1,2.26,33.48],[2,2.28,1360.14]],"ltp":3.05,"tv":1401.22,"id":9712888}]}]}
{"op":"mcm","clk":"4233706823","pt":1631537893798,"mc":[{"id":"1.187557759","rc":[{"trd":[[1.82,11.04]],"batb":[[0,1.82,88.66],[1,1.81,110.5],[2,1.8,95.64]],"ltp":1.82,"tv":4938.02,"id":9634485},{"batb":[[1,2.12,70.76],[2,2.1,35.38]],"batl":[[0,2.24,394.56],[1,2.26,6.7],[2,2.28,6.7]],"ltp":3.05,"tv":1401.22,"id":9712888}],"tv":6339.24}]}
{"op":"mcm","clk":"4233706866","pt":1631537894418,"mc":[{"id":"1.187557759","rc":[{"batb":[[1,2.12,14.16],[2,2.1,7.08]],"ltp":3.05,"tv":1401.22,"id":9712888}]}]}
{"op":"mcm","clk":"4233707063","pt":1631537897826,"mc":[{"id":"1.187557759","rc":[{"batl":[[0,1.84,9.8],[1,1.85,31.5],[2,1.86,17.52]],"ltp":1.82,"tv":4938.02,"id":9634485},{"batl":[[2,2.28,78.21]],"ltp":3.05,"tv":1401.22,"id":9712888}]}]}
{"op":"mcm","clk":"4233707071","pt":1631537898034,"mc":[{"id":"1.187557759","rc":[{"batl":[[0,1.85,31.5],[1,1.86,17.52],[2,1.89,85.79]],"ltp":1.82,"tv":4938.02,"id":9634485},{"batl":[[2,2.28,6.7]],"ltp":3.05,"tv":1401.22,"id":9712888}]}]}
{"op":"mcm","clk":"4233707328","pt":1631537901444,"mc":[{"id":"1.187557759","rc":[{"trd":[[2.16,20.35]],"batb":[[0,2.16,7.39]],"ltp":2.16,"tv":1401.49,"id":9712888}],"tv":6339.52}]}
{"op":"mcm","clk":"4233707869","pt":1631537910561,"mc":[{"id":"1.187557759","rc":[{"trd":[[1.82,11.38]],"batb":[[0,1.82,88.49]],"ltp":1.82,"tv":4938.36,"id":9634485}],"tv":6339.85}]}
{"op":"mcm","clk":"4233708027","pt":1631537912828,"mc":[{"id":"1.187557759","rc":[{"trd":[[1.82,11.83]],"batb":[[0,1.82,88.1]],"ltp":1.82,"tv":4938.81,"id":9634485},{"trd":[[2.22,0.27]],"ltp":2.22,"tv":1401.76,"id":9712888}],"tv":6340.58}]}
{"op":"mcm","clk":"4233708816","pt":1631537926772,"mc":[{"id":"1.187557759","rc":[{"batb":[[0,1.68,34.11],[1,1.66,40.84],[2,1.55,285.97]],"batl":[[0,2.12,7.96],[1,2.42,382.9],[2,1.89,0]],"ltp":1.82,"tv":4938.81,"id":9634485},{"batb":[[0,1.9,28.56],[1,1.84,29.04],[2,1.6,99.04]],"batl":[[0,2.48,6.24],[1,5.2,2.03],[2,5.4,2.04]],"ltp":2.22,"tv":1401.76,"id":9712888}]}]}
{"op":"mcm","clk":"4233709072","pt":1631537931381,"mc":[{"id":"1.187557759","rc":[{"batb":[[0,1.86,66.46],[1,1.84,88.96],[2,1.68,34.11]],"batl":[[0,1.92,56.88],[1,1.94,76.74],[2,2.12,7.96]],"ltp":1.82,"tv":4938.81,"id":9634485}]}]}
{"op":"mcm","clk":"4233709220","pt":1631537933690,"mc":[{"id":"1.187557759","rc":[{"batb":[[2,1.72,34.09]],"ltp":1.82,"tv":4938.81,"id":9634485},{"batl":[[0,2.4,6.59],[1,2.48,6.24],[2,5.2,2.03]],"ltp":2.22,"tv":1401.76,"id":9712888}]}]}
{"op":"mcm","clk":"4233709272","pt":1631537934370,"mc":[{"id":"1.187557759","rc":[{"trd":[[1.86,497.79]],"batb":[[0,1.86,59.52]],"ltp":1.86,"tv":4945.75,"id":9634485},{"trd":[[2.18,16.48]],"ltp":2.18,"tv":1407.69,"id":9712888}],"tv":6353.44}]}
{"op":"mcm","clk":"4233709599","pt":1631537938675,"mc":[{"id":"1.187557759","rc":[{"batb":[[0,1.68,34.11],[1,1.66,40.84],[2,1.55,285.97]],"batl":[[0,2.12,7.96],[1,2.42,382.9],[2,2.12,0]],"ltp":1.86,"tv":4945.75,"id":9634485},{"batl":[[0,2.48,6.24],[1,5.2,2.03],[2,5.4,2.04]],"ltp":2.18,"tv":1407.69,"id":9712888}]}]}
{"op":"mcm","clk":"4233709792","pt":1631537941410,"mc":[{"id":"1.187557759","rc":[{"batb":[[0,1.71,94.83],[1,1.69,118.59],[2,1.68,34.11]],"batl":[[0,2.1,95.89],[1,2.12,66.92],[2,2.42,382.9]],"ltp":1.86,"tv":4945.75,"id":9634485}]}]}
{"op":"mcm","clk":"4233709998","pt":1631537945395,"mc":[{"id":"1.187557759","rc":[{"batb":[[0,1.72,36.09],[1,1.71,94.83],[2,1.69,118.59]],"ltp":1.86,"tv":4945.75,"id":9634485},{"batl":[[0,2.4,6.69],[1,2.48,6.24],[2,5.2,2.03]],"ltp":2.18,"tv":1407.69,"id":9712888}]}]}
{"op":"mcm","clk":"4233710059","pt":1631537946388,"mc":[{"id":"1.187557759","rc":[{"batb":[[0,1.71,94.83],[1,1.69,118.59],[2,1.68,34.11]],"batl":[[0,2.12,7.96],[1,2.42,382.9],[2,2.42,0]],"ltp":1.86,"tv":4945.75,"id":9634485},{"batl":[[0,2.48,6.24],[1,5.2,2.03],[2,5.4,2.04]],"ltp":2.18,"tv":1407.69,"id":9712888}]}]}
{"op":"mcm","clk":"4233710144","pt":1631537947595,"mc":[{"id":"1.187557759","rc":[{"batl":[[0,2.04,8.63],[1,2.12,7.96]],"ltp":1.86,"tv":4945.75,"id":9634485},{"batb":[[0,1.97,28.17],[1,1.9,28.56],[2,1.84,29.04]],"ltp":2.18,"tv":1407.69,"id":9712888}]}]}
{"op":"mcm","clk":"4233710205","pt":1631537948806,"mc":[{"id":"1.187557759","rc":[{"batl":[[0,1.83,7.92]],"ltp":1.86,"tv":4945.75,"id":9634485},{"batb":[[0,1.9,28.56],[1,1.84,29.04],[2,1.6,99.04]],"ltp":2.18,"tv":1407.69,"id":9712888}]}]}
{"op":"mcm","clk":"4233710241","pt":1631537949334,"mc":[{"id":"1.187557759","rc":[{"trd":[[1.71,78.94]],"batb":[[0,1.71,88.98]],"batl":[[0,1.76,17.04],[1,1.77,102.85],[2,1.78,8.52]],"ltp":1.71,"tv":4957.45,"id":9634485},{"batb":[[0,2.36,8.53],[1,2.24,279.08],[2,1.9,28.56]],"batl":[[0,2.42,303.9],[1,2.48,6.24],[2,5.2,2.03]],"ltp":2.18,"tv":1407.69,"id":9712888}],"tv":6365.14}]}
{"op":"mcm","clk":"4233710309","pt":1631537950333,"mc":[{"id":"1.187557759","rc":[{"batb":[[2,1.68,51.97]],"ltp":1.71,"tv":4957.45,"id":9634485},{"batb":[[2,2.2,33.64]],"batl":[[2,2.68,3.73]],"ltp":2.18,"tv":1407.69,"id":9712888}]}]}
{"op":"mcm","clk":"4233710727","pt":1631537957131,"mc":[{"id":"1.187557759","rc":[{"batb":[[2,2.2,40.46]],"batl":[[2,2.54,6.25]],"ltp":2.18,"tv":1407.69,"id":9712888}]}]}
{"op":"mcm","clk":"4233710934","pt":1631537959514,"mc":[{"id":"1.187557759","rc":[{"trd":[[1.71,246.13]],"batb":[[0,1.68,51.97],[1,1.67,8.92],[2,1.66,49.76]],"batl":[[1,1.77,8.52]],"ltp":1.71,"tv":5124.64,"id":9634485}],"tv":6532.33}]}
{"op":"mcm","clk":"4233711175","pt":1631537962446,"mc":[{"id":"1.187557759","rc":[{"batb":[[0,1.7,104.15],[1,1.68,173.29],[2,1.67,8.92]],"batl":[[0,1.76,108.51],[2,1.78,109.44]],"ltp":1.71,"tv":5124.64,"id":9634485}]}]}
{"op":"mcm","clk":"4233712251","pt":1631537981664,"mc":[{"id":"1.187557759","rc":[{"batb":[[0,1.62,37.54],[1,1.58,48.79],[2,1.55,285.97]],"batl":[[0,1.87,25.73],[1,2.3,407.85],[2,1.78,0]],"ltp":1.71,"tv":5124.64,"id":9634485},{"batb":[[0,2.14,8.82],[1,2,44.18],[2,1.7,16.97]],"batl":[[0,2.62,5.25],[1,5.2,2.03],[2,5.4,2.04]],"ltp":2.18,"tv":1407.69,"id":9712888}]}]}
{"op":"mcm","clk":"4233712401","pt":1631537984380,"mc":[{"id":"1.187557759","rc":[{"batb":[[0,1.62,145.07],[1,1.61,71.26],[2,1.58,48.79]],"batl":[[1,1.91,86.11],[2,1.93,78.05]],"ltp":1.71,"tv":5124.64,"id":9634485}]}]}
{"op":"mcm","clk":"4233712734","pt":1631537989454,"mc":[{"id":"1.187557759","rc":[{"batl":[[1,2.3,407.85],[2,1.93,0]],"ltp":1.71,"tv":5124.64,"id":9634485}]}]}
{"op":"mcm","clk":"4233712857","pt":1631537991178,"mc":[{"id":"1.187557759","rc":[{"batl":[[1,2.3,0]],"ltp":1.71,"tv":5124.64,"id":9634485}]}]}
{"op":"mcm","clk":"4233712933","pt":1631537992379,"mc":[{"id":"1.187557759","rc":[{"batb":[[0,1.62,157.37]],"batl":[[0,1.64,6.1],[1,1.66,19.63],[2,1.67,79.36]],"ltp":1.71,"tv":5124.64,"id":9634485},{"batb":[[0,2.5,12],[1,2.48,86.64],[2,2.46,6]],"batl":[[0,2.6,262.61],[1,2.62,5.25],[2,5.2,2.03]],"ltp":2.18,"tv":1407.69,"id":9712888}]}]}
{"op":"mcm","clk":"4233712988","pt":1631537993577,"mc":[{"id":"1.187557759","rc":[{"batl":[[2,2.68,11.2]],"ltp":2.18,"tv":1407.69,"id":9712888}]}]}
{"op":"mcm","clk":"4233713291","pt":1631537999179,"mc":[{"id":"1.187557759","rc":[{"batb":[[2,1.59,43.11]],"ltp":1.71,"tv":5124.64,"id":9634485}]}]}
{"op":"mcm","clk":"4233713367","pt":1631538000291,"mc":[{"id":"1.187557759","rc":[{"batb":[[0,1.62,159.37]],"ltp":1.71,"tv":5124.64,"id":9634485}]}]}
{"op":"mcm","clk":"4233713703","pt":1631538003890,"mc":[{"id":"1.187557759","rc":[{"trd":[[1.28,8.27],[1.35,77.51],[1.37,4.14],[1.39,14.38],[1.4,29.86],[1.48,14.01],[1.49,481.87],[1.5,13.9],[1.53,3.12],[1.61,63.64],[1.64,97.09],[1.66,291.59],[1.67,42.97],[1.68,679.26],[1.69,321.75],[1.7,269.19],[1.71,246.12],[1.72,302.15],[1.75,177.12],[1.77,17.02],[1.86,497.72],[1.88,4.15],[1.9,222.36],[2.06,7.25]],"batb":[[0,1.62,146.72]],"ltp":1.71,"tv":5124.78,"id":9634485},{"trd":[[1.76,7.23],[1.89,8.79],[1.94,7.69],[1.97,46.45],[2,8.46],[2.04,66.25],[2.06,42.13],[2.1,330.08],[2.12,46.48],[2.14,11.32],[2.18,16.48],[2.2,34.6],[2.46,48.05],[2.48,343.27],[2.5,17.3],[2.56,52.54],[2.58,23.24],[2.6,31.3],[2.92,1.38],[3.65,132]],"ltp":2.18,"tv":1408.08,"id":9712888}],"tv":6532.86}]}
{"op":"mcm","clk":"4233713987","pt":1631538007810,"mc":[{"id":"1.187557759","rc":[{"batb":[[0,1.62,2],[1,1.52,55.97],[2,1.44,294.47]],"batl":[[0,1.73,38.5],[1,1.77,34.5],[2,1.87,25.73]],"ltp":1.71,"tv":5124.78,"id":9634485},{"batb":[[0,2.36,6.68],[1,2.28,6.16],[2,2.18,34.47]],"batl":[[0,2.76,5.27],[1,5.2,2.03],[2,5.4,2.04]],"ltp":2.18,"tv":1408.08,"id":9712888}]}]}
{"op":"mcm","clk":"4233714003","pt":1631538008077,"mc":[{"id":"1.187557759","rc":[{"batl":[[0,1.77,34.5],[1,2.16,445.57],[2,1.87,0]],"ltp":1.71,"tv":5124.78,"id":9634485},{"batb":[[0,2.28,6.16],[1,2.18,34.47],[2,1.7,16.96]],"ltp":2.18,"tv":1408.08,"id":9712888}]}]}
{"op":"mcm","clk":"4233714182","pt":1631538010819,"mc":[{"id":"1.187557759","rc":[{"batb":[[1,1.57,79.43],[2,1.56,80.24]],"batl":[[0,1.76,61.14],[1,1.77,34.5],[2,1.78,101.08]],"ltp":1.71,"tv":5124.78,"id":9634485}]}]}
{"op":"mcm","clk":"4233714242","pt":1631538011591,"mc":[{"id":"1.187557759","rc":[{"batb":[[1,1.57,125]],"ltp":1.71,"tv":5124.78,"id":9634485}]}]}
{"op":"mcm","clk":"4233714435","pt":1631538014614,"mc":[{"id":"1.187557759","rc":[{"batb":[[1,1.59,44.11],[2,1.57,125]],"ltp":1.71,"tv":5124.78,"id":9634485},{"batl":[[0,2.7,5.45],[1,2.76,5.27],[2,5.2,2.03]],"ltp":2.18,"tv":1408.08,"id":9712888}]}]}
{"op":"mcm","clk":"4233714503","pt":1631538015628,"mc":[{"id":"1.187557759","rc":[{"batb":[[1,1.57,125],[2,1.56,80.24]],"ltp":1.71,"tv":5124.78,"id":9634485},{"batl":[[0,2.76,5.27],[1,5.2,2.03],[2,5.4,2.04]],"ltp":2.18,"tv":1408.08,"id":9712888}]}]}
{"op":"mcm","clk":"4233714626","pt":1631538017534,"mc":[{"id":"1.187557759","rc":[{"batl":[[0,1.77,34.5],[1,2.16,445.57],[2,1.78,0]],"ltp":1.71,"tv":5124.78,"id":9634485}]}]}
{"op":"mcm","clk":"4233714793","pt":1631538020536,"mc":[{"id":"1.187557759","rc":[{"trd":[[1.62,32.94]],"batb":[[0,1.57,125],[1,1.56,80.24],[2,1.52,55.97]],"batl":[[0,1.59,4.29],[1,1.6,17.3],[2,1.61,71.25]],"ltp":1.62,"tv":5128.78,"id":9634485},{"batb":[[0,2.66,56.4],[1,2.64,43.36],[2,2.62,28.2]],"batl":[[1,2.78,375.97],[2,5.2,2.03]],"ltp":2.18,"tv":1408.08,"id":9712888}],"tv":6536.86}]}
{"op":"mcm","clk":"4233714861","pt":1631538021736,"mc":[{"id":"1.187557759","rc":[{"batb":[[2,1.54,19.48]],"ltp":1.62,"tv":5128.78,"id":9634485},{"batb":[[0,2.66,33.84],[1,2.64,32.08],[2,2.62,16.92]],"batl":[[2,3.05,3.28]],"ltp":2.18,"tv":1408.08,"id":9712888}]}]}
{"op":"mcm","clk":"4233715253","pt":1631538028448,"mc":[{"id":"1.187557759","rc":[{"batb":[[1,1.56,120.07],[2,1.55,38.79]],"ltp":1.62,"tv":5128.78,"id":9634485},{"batl":[[2,2.8,4.42]],"ltp":2.18,"tv":1408.08,"id":9712888}]}]}
{"op":"mcm","clk":"4233716312","pt":1631538042784,"mc":[{"id":"1.187557759","rc":[{"trd":[[1.59,13.82]],"batl":[[0,1.59,3.67]],"ltp":1.59,"tv":5130.02,"id":9634485}],"tv":6538.1}]}
{"op":"mcm","clk":"4233716364","pt":1631538043664,"mc":[{"id":"1.187557759","rc":[{"batb":[[0,1.49,60.57],[1,1.44,294.47],[2,1.3,197.93]],"batl":[[0,1.66,41.25],[1,2.16,445.57],[2,1.61,0]],"ltp":1.59,"tv":5130.02,"id":9634485},{"batb":[[0,2.5,7.36],[1,2.36,27.27],[2,1.8,11.87]],"batl":[[0,2.82,4.25],[1,5.2,2.03],[2,5.4,2.04]],"ltp":2.18,"tv":1408.08,"id":9712888}]}]}
{"op":"mcm","clk":"4233716568","pt":1631538046794,"mc":[{"id":"1.187557759","rc":[{"batb":[[0,1.56,45.83],[1,1.55,40.99],[2,1.54,86.94]],"batl":[[0,1.66,103.84],[1,1.67,62.38],[2,2.16,445.57]],"ltp":1.59,"tv":5130.02,"id":9634485},{"batl":[[0,2.8,4.67],[1,2.82,4.25],[2,5.2,2.03]],"ltp":2.18,"tv":1408.08,"id":9712888}]}]}
{"op":"mcm","clk":"4233716591","pt":1631538047195,"mc":[{"id":"1.187557759","rc":[{"batb":[[0,1.55,40.99],[1,1.54,86.94],[2,1.53,86.61]],"ltp":1.59,"tv":5130.02,"id":9634485},{"batl":[[0,2.82,4.25],[1,5.2,2.03],[2,5.4,2.04]],"ltp":2.18,"tv":1408.08,"id":9712888}]}]}
{"op":"mcm","clk":"4233716665","pt":1631538048202,"mc":[{"id":"1.187557759","rc":[{"batl":[[0,1.66,41.25],[1,2.16,445.57],[2,2.16,0]],"ltp":1.59,"tv":5130.02,"id":9634485},{"batl":[[1,5.2,0],[2,5.4,0]],"ltp":2.18,"tv":1408.08,"id":9712888}]}]}
{"op":"mcm","clk":"4233716833","pt":1631538050794,"mc":[{"id":"1.187557759","rc":[{"batb":[[1,1.54,99.03]],"batl":[[0,1.57,6.37],[1,1.6,1962.12],[2,1.62,453.01]],"ltp":1.59,"tv":5130.02,"id":9634485},{"batb":[[0,2.78,5.31],[1,2.74,54.74],[2,2.72,27.38]],"batl":[[1,2.84,274.23]],"ltp":2.18,"tv":1408.08,"id":9712888}]}]}
{"op":"mcm","clk":"4233716908","pt":1631538051797,"mc":[{"id":"1.187557759","rc":[{"batl":[[1,1.58,83.1],[2,1.59,74.36]],"ltp":1.59,"tv":5130.02,"id":9634485},{"batb":[[1,2.74,32.84],[2,2.72,16.43]],"batl":[[2,2.96,50.68]],"ltp":2.18,"tv":1408.08,"id":9712888}]}]}
{"op":"mcm","clk":"4233716945","pt":1631538052515,"mc":[{"id":"1.187557759","rc":[{"batb":[[1,2.74,10.94],[2,2.72,5.48]],"batl":[[2,2.96,10.14]],"ltp":2.18,"tv":1408.08,"id":9712888}]}]}
{"op":"mcm","clk":"4233717147","pt":1631538055796,"mc":[{"id":"1.187557759","rc":[{"batl":[[0,2.82,65.94]],"ltp":2.18,"tv":1408.08,"id":9712888}]}]}
{"op":"mcm","clk":"4233717191","pt":1631538056314,"mc":[{"id":"1.187557759","rc":[{"batb":[[0,1.55,136.99]],"ltp":1.59,"tv":5130.02,"id":9634485},{"batl":[[0,2.82,4.25]],"ltp":2.18,"tv":1408.08,"id":9712888}]}]}
{"op":"mcm","clk":"4233718204","pt":1631538069325,"mc":[{"id":"1.187557759","rc":[{"batl":[[0,1.56,228.19],[1,1.57,6.37],[2,1.58,83.1]],"ltp":1.59,"tv":5130.02,"id":9634485}]}]}
{"op":"mcm","clk":"4233719975","pt":1631538092656,"mc":[{"id":"1.187557759","rc":[{"batl":[[0,2.82,4.34]],"ltp":2.18,"tv":1408.08,"id":9712888}]}]}
{"op":"mcm","clk":"4233720403","pt":1631538097568,"mc":[{"id":"1.187557759","rc":[{"trd":[[2.78,3.4]],"batb":[[0,2.78,3.61]],"ltp":2.78,"tv":1411.49,"id":9712888}],"tv":6541.51}]}
{"op":"mcm","clk":"4233720452","pt":1631538098271,"mc":[{"id":"1.187557759","rc":[{"trd":[[1.55,13.9]],"batb":[[0,1.55,136.53]],"ltp":1.55,"tv":5130.94,"id":9634485}],"tv":6542.43}]}
{"op":"mcm","clk":"4233720495","pt":1631538098892,"mc":[{"id":"1.187557759","rc":[{"trd":[[1.56,11.39]],"batl":[[0,1.56,216.8]],"ltp":1.56,"tv":5142.33,"id":9634485},{"trd":[[2.78,17.01]],"batb":[[0,2.74,10.94],[1,2.72,5.48],[2,2.7,49.93]],"ltp":2.78,"tv":1425.1,"id":9712888}],"tv":6567.43}]}
{"op":"mcm","clk":"4233720831","pt":1631538103402,"mc":[{"id":"1.187557759","rc":[{"batl":[[0,1.57,6.37],[1,1.58,83.1],[2,1.59,74.36]],"ltp":1.56,"tv":5142.33,"id":9634485}]}]}
{"op":"mcm","clk":"4233721100","pt":1631538106590,"mc":[{"id":"1.187557759","rc":[{"trd":[[1.55,286.96]],"batb":[[0,1.54,99.03],[1,1.53,86.61],[2,1.49,60.57]],"batl":[[0,1.55,81.67],[1,1.57,6.37],[2,1.58,83.1]],"ltp":1.55,"tv":5415.38,"id":9634485},{"batl":[[0,2.82,4.25]],"ltp":2.78,"tv":1425.1,"id":9712888}],"tv":6840.48}]}
{"op":"mcm","clk":"4233721208","pt":1631538107688,"mc":[{"id":"1.187557759","rc":[{"batb":[[0,1.54,86.94]],"ltp":1.55,"tv":5415.38,"id":9634485}]}]}
{"op":"mcm","clk":"4233721379","pt":1631538109618,"mc":[{"id":"1.187557759","rc":[{"trd":[[1.55,291.3]],"batl":[[0,1.55,79.5]],"ltp":1.55,"tv":5419.72,"id":9634485}],"tv":6844.82}]}
{"op":"mcm","clk":"4233721493","pt":1631538110714,"mc":[{"id":"1.187557759","rc":[{"batl":[[2,1.58,99.94]],"ltp":1.55,"tv":5419.72,"id":9634485},{"batl":[[1,2.84,284.07]],"ltp":2.78,"tv":1425.1,"id":9712888}]}]}
{"op":"mcm","clk":"4233721516","pt":1631538110976,"mc":[{"id":"1.187557759","rc":[{"batl":[[2,1.58,83.1]],"ltp":1.55,"tv":5419.72,"id":9634485},{"batl":[[1,2.84,274.23]],"ltp":2.78,"tv":1425.1,"id":9712888}]}]}
{"op":"mcm","clk":"4233721777","pt":1631538113903,"mc":[{"id":"1.187557759","rc":[{"batl":[[2,1.58,99.94]],"ltp":1.55,"tv":5419.72,"id":9634485},{"batl":[[1,2.84,284.07]],"ltp":2.78,"tv":1425.1,"id":9712888}]}]}
{"op":"mcm","clk":"4233722217","pt":1631538118494,"mc":[{"id":"1.187557759","rc":[{"trd":[[1.55,291.47]],"batl":[[0,1.55,79.33]],"ltp":1.55,"tv":5419.89,"id":9634485},{"trd":[[2.8,0.09]],"ltp":2.8,"tv":1425.19,"id":9712888}],"tv":6845.09}]}
{"op":"mcm","clk":"4233722298","pt":1631538119430,"mc":[{"id":"1.187557759","rc":[{"batl":[[0,1.57,6.37],[1,1.58,99.94],[2,1.59,74.36]],"ltp":1.55,"tv":5419.89,"id":9634485}]}]}
{"op":"mcm","clk":"4233722447","pt":1631538120532,"mc":[{"id":"1.187557759","rc":[{"batb":[[0,1.54,186.94]],"ltp":1.55,"tv":5419.89,"id":9634485}]}]}
{"op":"mcm","clk":"4233722712","pt":1631538122627,"mc":[{"id":"1.187557759","rc":[{"trd":[[1.54,160.02]],"batb":[[0,1.54,106.93]],"ltp":1.54,"tv":5579.92,"id":9634485}],"tv":7005.11}]}
{"op":"mcm","clk":"4233722756","pt":1631538123042,"mc":[{"id":"1.187557759","rc":[{"batb":[[0,1.54,100]],"ltp":1.54,"tv":5579.92,"id":9634485}]}]}
{"op":"mcm","clk":"4233722982","pt":1631538125952,"mc":[{"id":"1.187557759","rc":[{"batb":[[1,1.53,129.64],[2,1.52,89.34]],"batl":[[1,1.58,143.02]],"ltp":1.54,"tv":5579.92,"id":9634485}]}]}
{"op":"mcm","clk":"4233725351","pt":1631538152697,"mc":[{"id":"1.187557759","rc":[{"batl":[[0,1.58,126.18],[1,1.59,74.36],[2,1.67,43]],"ltp":1.54,"tv":5579.92,"id":9634485},{"batb":[[0,2.58,21.33],[1,2.48,19.27],[2,2.4,20.17]],"batl":[[0,3.3,3.65],[1,3.5,3.51],[2,2.96,0]],"ltp":2.8,"tv":1425.19,"id":9712888}]}]}
{"op":"mcm","clk":"4233725449","pt":1631538153601,"mc":[{"id":"1.187557759","rc":[{"batb":[[0,1.4,59.01],[1,1.39,80.9],[2,1.38,301.29]],"batl":[[0,1.71,39.5],[1,2.04,492.16],[2,1.67,0]],"ltp":1.54,"tv":5579.92,"id":9634485},{"batb":[[0,2.4,5.91],[1,2.36,27.27],[2,1.8,11.87]],"batl":[[0,3.5,3.51],[1,3.5,0]],"ltp":2.8,"tv":1425.19,"id":9712888}]}]}
{"op":"mcm","clk":"4233725630","pt":1631538155795,"mc":[{"id":"1.187557759","rc":[{"batb":[[0,1.43,85.94],[1,1.42,118.79],[2,1.4,59.01]],"batl":[[0,1.67,111.51],[1,1.69,120.45],[2,1.71,39.5]],"ltp":1.54,"tv":5579.92,"id":9634485}]}]}
{"op":"mcm","clk":"4233725718","pt":1631538156782,"mc":[{"id":"1.187557759","rc":[{"batb":[[0,1.4,59.01],[1,1.39,80.9],[2,1.38,301.29]],"batl":[[0,1.71,39.5],[1,2.04,492.16],[2,1.71,0]],"ltp":1.54,"tv":5579.92,"id":9634485}]}]}
{"op":"mcm","clk":"4233725983","pt":1631538159809,"mc":[{"id":"1.187557759","rc":[{"batl":[[0,1.67,6.53],[1,1.71,39.5],[2,2.04,492.16]],"ltp":1.54,"tv":5579.92,"id":9634485},{"batb":[[0,2.48,12.76],[1,2.4,5.91],[2,2.36,27.27]],"ltp":2.8,"tv":1425.19,"id":9712888}]}]}
{"op":"mcm","clk":"4233726047","pt":1631538160392,"mc":[{"id":"1.187557759","rc":[{"batb":[[0,1.51,110.76],[1,1.5,94.16],[2,1.44,56.42]],"batl":[[0,1.55,82.91],[1,1.56,80.07],[2,1.71,39.5]],"ltp":1.54,"tv":5579.92,"id":9634485},{"batb":[[0,2.4,5.91],[1,2.36,27.27],[2,1.8,11.87]],"batl":[[0,3.3,3.55],[1,3.5,3.51]],"ltp":2.8,"tv":1425.19,"id":9712888}]}]}
{"op":"mcm","clk":"4233726275","pt":1631538163616,"mc":[{"id":"1.187557759","rc":[{"batl":[[2,1.67,36.5]],"ltp":1.54,"tv":5579.92,"id":9634485},{"batb":[[0,2.48,5.76],[1,2.4,20.37],[2,2.36,27.27]],"ltp":2.8,"tv":1425.19,"id":9712888}]}]}
{"op":"mcm","clk":"4233726305","pt":1631538163922,"mc":[{"id":"1.187557759","rc":[{"batl":[[2,1.71,39.5]],"ltp":1.54,"tv":5579.92,"id":9634485},{"batb":[[0,2.4,5.91],[1,2.36,27.27],[2,1.8,11.87]],"ltp":2.8,"tv":1425.19,"id":9712888}]}]}
{"op":"mcm","clk":"4233726544","pt":1631538166729,"mc":[{"id":"1.187557759","rc":[{"batb":[[0,1.4,59.01],[1,1.39,80.9],[2,1.38,301.29]],"batl":[[0,1.67,6.5],[1,1.71,39.5],[2,2.04,492.16]],"ltp":1.54,"tv":5579.92,"id":9634485},{"batb":[[0,2.48,13.76],[1,2.4,5.91],[2,2.36,27.27]],"batl":[[0,3.5,3.51],[1,3.5,0]],"ltp":2.8,"tv":1425.19,"id":9712888}]}]}
{"op":"mcm","clk":"4233726629","pt":1631538167722,"mc":[{"id":"1.187557759","rc":[{"batl":[[0,1.71,39.5],[1,2.04,492.16],[2,2.04,0]],"ltp":1.54,"tv":5579.92,"id":9634485},{"batb":[[0,2.4,5.91],[1,2.36,27.27],[2,1.8,11.87]],"ltp":2.8,"tv":1425.19,"id":9712888}]}]}
{"op":"mcm","clk":"4233726774","pt":1631538169406,"mc":[{"id":"1.187557759","rc":[{"batb":[[0,1.43,85.94],[1,1.42,118.79],[2,1.4,59.01]],"batl":[[0,1.67,111.51],[1,1.69,120.45],[2,1.71,39.5]],"ltp":1.54,"tv":5579.92,"id":9634485}]}]}
{"op":"mcm","clk":"4233726897","pt":1631538170611,"mc":[{"id":"1.187557759","rc":[{"batl":[[2,1.71,46]],"ltp":1.54,"tv":5579.92,"id":9634485},{"batb":[[0,2.4,19.37]],"ltp":2.8,"tv":1425.19,"id":9712888}]}]}
{"op":"mcm","clk":"4233727754","pt":1631538180751,"mc":[{"id":"1.187557759","rc":[{"batb":[[0,1.44,61.17],[1,1.43,85.94],[2,1.42,118.79]],"ltp":1.54,"tv":5579.92,"id":9634485},{"batl":[[0,3.3,3.65],[1,3.5,3.51]],"ltp":2.8,"tv":1425.19,"id":9712888}]}]}
{"op":"mcm","clk":"4233727816","pt":1631538181338,"mc":[{"id":"1.187557759","rc":[{"batb":[[0,1.43,85.94],[1,1.42,118.79],[2,1.4,59.01]],"batl":[[0,1.67,147.01]],"ltp":1.54,"tv":5579.92,"id":9634485},{"batb":[[0,2.48,6.76],[1,2.4,19.37],[2,2.36,27.27]],"batl":[[0,3.5,3.51],[1,3.5,0]],"ltp":2.8,"tv":1425.19,"id":9712888}]}]}
{"op":"mcm","clk":"4233727960","pt":1631538182854,"mc":[{"id":"1.187557759","rc":[{"batl":[[0,1.67,111.51]],"ltp":1.54,"tv":5579.92,"id":9634485},{"batb":[[0,2.4,19.37],[1,2.36,27.27],[2,1.8,11.87]],"ltp":2.8,"tv":1425.19,"id":9712888}]}]}
{"op":"mcm","clk":"4233728371","pt":1631538187770,"mc":[{"id":"1.187557759","rc":[{"batb":[[0,1.44,59.67],[1,1.43,85.94],[2,1.42,118.79]],"ltp":1.54,"tv":5579.92,"id":9634485},{"batl":[[0,3.3,3.85],[1,3.5,3.51]],"ltp":2.8,"tv":1425.19,"id":9712888}]}]}
{"op":"mcm","clk":"4233728394","pt":1631538188041,"mc":[{"id":"1.187557759","rc":[{"batb":[[0,1.43,85.94],[1,1.42,118.79],[2,1.4,59.01]],"ltp":1.54,"tv":5579.92,"id":9634485},{"batl":[[0,3.5,3.51],[1,3.5,0]],"ltp":2.8,"tv":1425.19,"id":9712888}]}]}
{"op":"mcm","clk":"4233728603","pt":1631538190846,"mc":[{"id":"1.187557759","rc":[{"batl":[[0,1.67,118.1]],"ltp":1.54,"tv":5579.92,"id":9634485},{"batb":[[0,2.48,12.76],[1,2.4,19.37],[2,2.36,27.27]],"ltp":2.8,"tv":1425.19,"id":9712888}]}]}
{"op":"mcm","clk":"4233728662","pt":1631538191566,"mc":[{"id":"1.187557759","rc":[{"batl":[[0,1.67,111.51]],"ltp":1.54,"tv":5579.92,"id":9634485},{"batb":[[0,2.4,19.37],[1,2.36,27.27],[2,1.8,11.87]],"ltp":2.8,"tv":1425.19,"id":9712888}]}]}
{"op":"mcm","clk":"4233729032","pt":1631538195750,"mc":[{"id":"1.187557759","rc":[{"batb":[[0,1.4,59.01],[1,1.39,80.9],[2,1.38,301.29]],"ltp":1.54,"tv":5579.92,"id":9634485}]}]}
{"op":"mcm","clk":"4233729102","pt":1631538196586,"mc":[{"id":"1.187557759","rc":[{"batl":[[0,1.67,145.01]],"ltp":1.54,"tv":5579.92,"id":9634485},{"batb":[[0,2.48,6.51],[1,2.4,19.37],[2,2.36,27.27]],"ltp":2.8,"tv":1425.19,"id":9712888}]}]}
{"op":"mcm","clk":"4233729148","pt":1631538197056,"mc":[{"id":"1.187557759","rc":[{"batb":[[2,1.2,385.96]],"batl":[[0,1.67,111.51]],"ltp":1.54,"tv":5579.92,"id":9634485},{"batb":[[0,2.4,19.37],[1,2.36,27.27],[2,1.8,11.87]],"ltp":2.8,"tv":1425.19,"id":9712888}]}]}
{"op":"mcm","clk":"4233729310","pt":1631538198770,"mc":[{"id":"1.187557759","rc":[{"batb":[[0,1.62,94.36],[1,1.61,71.35],[2,1.59,125.78]],"ltp":1.54,"tv":5579.92,"id":9634485},{"batb":[[0,2.5,8.28],[1,2.4,19.37],[2,2.36,27.27]],"batl":[[0,2.6,307.09],[1,2.62,61.49],[2,2.64,28.62]],"ltp":2.8,"tv":1425.19,"id":9712888}]}]}
{"op":"mcm","clk":"4233729367","pt":1631538199755,"mc":[{"id":"1.187557759","rc":[{"batl":[[0,1.65,6.06],[1,1.67,111.51],[2,1.69,209.21]],"ltp":1.54,"tv":5579.92,"id":9634485},{"batl":[[1,2.62,15.69],[2,2.64,5.72]],"ltp":2.8,"tv":1425.19,"id":9712888}]}]}
{"op":"mcm","clk":"4233729425","pt":1631538200588,"mc":[{"id":"1.187557759","rc":[{"batl":[[2,1.69,138.21]],"ltp":1.54,"tv":5579.92,"id":9634485}]}]}
{"op":"mcm","clk":"4233729930","pt":1631538206487,"mc":[{"id":"1.187557759","rc":[{"trd":[[1.62,40.94]],"batb":[[0,1.62,90.36]],"ltp":1.62,"tv":5587.92,"id":9634485}],"tv":7013.11}]}
{"op":"mcm","clk":"4233731220","pt":1631538220798,"mc":[{"id":"1.187557759","rc":[{"batb":[[0,1.62,74.82],[2,1.58,49.19]],"batl":[[0,1.67,111.51],[1,1.69,120.45],[2,1.71,46]],"ltp":1.62,"tv":5587.92,"id":9634485},{"batb":[[0,2.4,19.37],[1,2.36,27.27],[2,2.34,6.22]],"batl":[[0,2.82,4.86],[1,2.94,4.75],[2,3.3,4.05]],"ltp":2.8,"tv":1425.19,"id":9712888}]}]}
{"op":"mcm","clk":"4233731288","pt":1631538221322,"mc":[{"id":"1.187557759","rc":[{"batb":[[0,1.52,47.24],[1,1.47,63.83],[2,1.44,354.18]],"batl":[[0,1.74,29.75],[1,2.04,492.16],[2,1.71,0]],"ltp":1.62,"tv":5587.92,"id":9634485},{"batb":[[0,2.34,6.22],[1,2.2,33.21],[2,1.8,11.87]],"batl":[[0,2.94,4.75],[1,3.3,4.05],[2,3.5,3.51]],"ltp":2.8,"tv":1425.19,"id":9712888}]}]}
{"op":"mcm","clk":"4233731488","pt":1631538223826,"mc":[{"id":"1.187557759","rc":[{"batb":[[1,1.51,132.6],[2,1.5,94.29]],"batl":[[1,1.75,70.98],[2,1.77,103.16]],"ltp":1.62,"tv":5587.92,"id":9634485}]}]}
{"op":"mcm","clk":"4233731574","pt":1631538224812,"mc":[{"id":"1.187557759","rc":[{"batb":[[1,1.47,63.83],[2,1.44,354.18]],"batl":[[1,2.04,492.16],[2,1.77,0]],"ltp":1.62,"tv":5587.92,"id":9634485}]}]}
{"op":"mcm","clk":"4233731636","pt":1631538225648,"mc":[{"id":"1.187557759","rc":[{"batb":[[0,1.59,135.94],[1,1.58,76.8],[2,1.52,47.24]],"batl":[[0,1.64,72.94],[1,1.65,84.11],[2,1.74,29.75]],"ltp":1.62,"tv":5587.92,"id":9634485},{"batb":[[0,2.56,18.83],[1,2.34,6.22],[2,2.2,33.21]],"batl":[[0,2.64,21.43],[1,2.94,4.75],[2,3.3,4.05]],"ltp":2.8,"tv":1425.19,"id":9712888}]}]}
{"op":"mcm","clk":"4233731667","pt":1631538226013,"mc":[{"id":"1.187557759","rc":[{"batl":[[1,1.65,65.21]],"ltp":1.62,"tv":5587.92,"id":9634485},{"batb":[[0,2.34,6.22],[1,2.2,33.21],[2,1.8,11.87]],"batl":[[0,2.94,4.75],[1,3.3,4.05],[2,3.5,3.51]],"ltp":2.8,"tv":1425.19,"id":9712888}]}]}
{"op":"mcm","clk":"4233731818","pt":1631538227823,"mc":[{"id":"1.187557759","rc":[{"batb":[[2,1.55,46.59]],"ltp":1.62,"tv":5587.92,"id":9634485},{"batl":[[0,2.82,4.75],[1,2.94,4.75],[2,3.3,4.05]],"ltp":2.8,"tv":1425.19,"id":9712888}]}]}
{"op":"mcm","clk":"4233732012","pt":1631538229664,"mc":[{"id":"1.187557759","rc":[{"batb":[[0,1.55,46.59],[1,1.52,47.24],[2,1.47,63.83]],"batl":[[0,1.74,29.75],[1,2.04,492.16],[2,1.74,0]],"ltp":1.62,"tv":5587.92,"id":9634485}]}]}
{"op":"mcm","clk":"4233732048","pt":1631538229927,"mc":[{"id":"1.187557759","rc":[{"batb":[[0,1.52,47.24],[1,1.47,63.83],[2,1.44,354.18]],"ltp":1.62,"tv":5587.92,"id":9634485},{"batl":[[0,2.94,4.75],[1,3.3,4.05],[2,3.5,3.51]],"ltp":2.8,"tv":1425.19,"id":9712888}]}]}
{"op":"mcm","clk":"4233732218","pt":1631538231649,"mc":[{"id":"1.187557759","rc":[{"batl":[[0,1.71,38.5],[1,1.74,29.75],[2,2.04,492.16]],"ltp":1.62,"tv":5587.92,"id":9634485},{"batb":[[0,2.4,6.51],[1,2.34,6.22],[2,2.2,33.21]],"ltp":2.8,"tv":1425.19,"id":9712888}]}]}
{"op":"mcm","clk":"4233732338","pt":1631538232649,"mc":[{"id":"1.187557759","rc":[{"batb":[[1,1.51,131.67],[2,1.5,94.29]],"batl":[[0,1.74,29.75],[1,1.75,71.98],[2,1.77,103.16]],"ltp":1.62,"tv":5587.92,"id":9634485},{"batb":[[0,2.34,6.22],[1,2.2,33.21],[2,1.8,11.87]],"ltp":2.8,"tv":1425.19,"id":9712888}]}]}
{"op":"mcm","clk":"4233732888","pt":1631538238651,"mc":[{"id":"1.187557759","rc":[{"batl":[[0,1.71,37.5],[1,1.74,29.75],[2,2.04,492.16]],"ltp":1.62,"tv":5587.92,"id":9634485},{"batb":[[0,2.4,6.11],[1,2.34,6.22],[2,2.2,33.21]],"ltp":2.8,"tv":1425.19,"id":9712888}]}]}
{"op":"mcm","clk":"4233732979","pt":1631538239745,"mc":[{"id":"1.187557759","rc":[{"batl":[[0,1.74,29.75],[1,2.04,492.16],[2,2.04,0]],"ltp":1.62,"tv":5587.92,"id":9634485},{"batb":[[0,2.34,6.22],[1,2.2,33.21],[2,1.8,11.87]],"ltp":2.8,"tv":1425.19,"id":9712888}]}]}
{"op":"mcm","clk":"4233733067","pt":1631538240734,"mc":[{"id":"1.187557759","rc":[{"trd":[[1.55,304.37]],"batl":[[0,1.56,178.15],[1,1.57,94.01],[2,1.58,9.62]],"ltp":1.55,"tv":5600.82,"id":9634485},{"batb":[[0,2.74,10.02],[1,2.66,75.18],[2,2.34,6.22]],"batl":[[0,2.88,6.23],[1,2.92,258.66],[2,2.94,4.75]],"ltp":2.8,"tv":1425.19,"id":9712888}],"tv":7026.01}]}
{"op":"mcm","clk":"4233733178","pt":1631538241837,"mc":[{"id":"1.187557759","rc":[{"batb":[[2,1.5,114.29]],"ltp":1.55,"tv":5600.82,"id":9634485},{"batb":[[2,2.64,19.99]],"ltp":2.8,"tv":1425.19,"id":9712888}]}]}
{"op":"mcm","clk":"4233734865","pt":1631538260551,"mc":[{"id":"1.187557759","rc":[{"batb":[[0,1.53,81],[1,1.52,47.24],[2,1.51,131.67]],"ltp":1.55,"tv":5600.82,"id":9634485}]}]}
{"op":"mcm","clk":"4233735400","pt":1631538266705,"mc":[{"id":"1.187557759","rc":[{"batb":[[1,1.38,301.29],[2,1.36,155.11]],"batl":[[0,1.57,6.5],[1,1.67,39.5],[2,2.04,492.16]],"ltp":1.55,"tv":5600.82,"id":9634485},{"batb":[[1,2.48,5.76],[2,2.38,26.77]],"batl":[[0,3.8,3.17],[1,2.92,0],[2,2.94,0]],"ltp":2.8,"tv":1425.19,"id":9712888}]}]}
{"op":"mcm","clk":"4233735459","pt":1631538267377,"mc":[{"id":"1.187557759","rc":[{"batb":[[0,1.38,301.29],[1,1.36,155.11],[2,1.2,385.96]],"ltp":1.55,"tv":5600.82,"id":9634485}]}]}
{"op":"mcm","clk":"4233735665","pt":1631538269622,"mc":[{"id":"1.187557759","rc":[{"batb":[[0,1.39,177.67],[1,1.38,437.7],[2,1.36,155.11]],"batl":[[0,1.66,96.44],[1,1.67,101.94]],"ltp":1.55,"tv":5600.82,"id":9634485},{"batb":[[0,2.48,5.76],[1,2.38,26.77],[2,1.8,11.87]],"ltp":2.8,"tv":1425.19,"id":9712888}]}]}
{"op":"mcm","clk":"4233735713","pt":1631538270178,"mc":[{"id":"1.187557759","rc":[{"batl":[[0,1.64,125],[1,1.66,96.44],[2,1.67,101.94]],"ltp":1.55,"tv":5600.82,"id":9634485}]}]}
{"op":"mcm","clk":"4233735999","pt":1631538273727,"mc":[{"id":"1.187557759","rc":[{"batl":[[2,1.67,108.44]],"ltp":1.55,"tv":5600.82,"id":9634485},{"batb":[[0,2.48,18.52]],"ltp":2.8,"tv":1425.19,"id":9712888}]}]}
{"op":"mcm","clk":"4233736303","pt":1631538276842,"mc":[{"id":"1.187557759","rc":[{"batb":[[0,1.41,64.89],[1,1.39,177.67],[2,1.38,437.7]],"batl":[[0,1.64,160.18]],"ltp":1.55,"tv":5600.82,"id":9634485},{"batb":[[0,2.56,4.83],[1,2.48,18.52],[2,2.38,26.77]],"batl":[[0,3.45,3.5],[1,3.8,3.17]],"ltp":2.8,"tv":1425.19,"id":9712888}]}]}
{"op":"mcm","clk":"4233736335","pt":1631538277256,"mc":[{"id":"1.187557759","rc":[{"batb":[[0,1.39,177.67],[1,1.38,437.7],[2,1.36,155.11]],"batl":[[0,1.64,125]],"ltp":1.55,"tv":5600.82,"id":9634485},{"batb":[[0,2.48,18.52],[1,2.38,26.77],[2,1.8,11.87]],"batl":[[0,3.8,3.17],[1,3.8,0]],"ltp":2.8,"tv":1425.19,"id":9712888}]}]}
{"op":"mcm","clk":"4233736712","pt":1631538280841,"mc":[{"id":"1.187557759","rc":[{"batl":[[1,1.67,46],[2,2.04,492.16]],"ltp":1.55,"tv":5600.82,"id":9634485}]}]}
{"op":"mcm","clk":"4233736747","pt":1631538281255,"mc":[{"id":"1.187557759","rc":[{"batb":[[1,1.38,136.41]],"batl":[[2,2.04,0]],"ltp":1.55,"tv":5600.82,"id":9634485}]}]}
{"op":"mcm","clk":"4233736904","pt":1631538282834,"mc":[{"id":"1.187557759","rc":[{"batb":[[0,1.4,341.29],[1,1.39,177.67],[2,1.38,136.41]],"batl":[[0,1.43,145.12],[1,1.44,255.84],[2,1.45,20.68]],"ltp":1.55,"tv":5600.82,"id":9634485},{"batb":[[0,3.3,5.85],[1,2.48,18.52],[2,2.38,26.77]],"batl":[[0,3.4,4.84],[1,3.5,136.52],[2,3.8,3.17]],"ltp":2.8,"tv":1425.19,"id":9712888}]}]}
{"op":"mcm","clk":"4233737002","pt":1631538283647,"mc":[{"id":"1.187557759","rc":[{"batb":[[0,1.4,448.43],[1,1.39,231.25],[2,1.38,189.99]],"batl":[[2,1.45,26.38]],"ltp":1.55,"tv":5600.82,"id":9634485},{"batb":[[1,3.2,7.67],[2,3.1,33.05]],"batl":[[2,3.75,2.67]],"ltp":2.8,"tv":1425.19,"id":9712888}]}]}
{"op":"mcm","clk":"4233737041","pt":1631538283961,"mc":[{"id":"1.187557759","rc":[{"batb":[[0,1.4,362.71],[1,1.39,188.39],[2,1.38,147.13]],"ltp":1.55,"tv":5600.82,"id":9634485}]}]}
{"op":"mcm","clk":"4233737723","pt":1631538290834,"mc":[{"id":"1.187557759","rc":[{"batb":[[0,1.41,235],[1,1.4,362.71],[2,1.39,188.39]],"ltp":1.55,"tv":5600.82,"id":9634485}]}]}
{"op":"mcm","clk":"4233737959","pt":1631538293860,"mc":[{"id":"1.187557759","rc":[{"batb":[[2,1.39,167.98]],"ltp":1.55,"tv":5600.82,"id":9634485}]}]}
{"op":"mcm","clk":"4233738218","pt":1631538296865,"mc":[{"id":"1.187557759","rc":[{"batl":[[0,1.43,164.97]],"ltp":1.55,"tv":5600.82,"id":9634485}]}]}
{"op":"mcm","clk":"4233738574","pt":1631538301367,"mc":[{"id":"1.187557759","rc":[{"trd":[[1.43,86.5]],"batb":[[2,1.39,141.31]],"batl":[[0,1.43,78.47]],"ltp":1.43,"tv":5687.32,"id":9634485},{"trd":[[3.3,49.18]],"batb":[[0,3.2,7.67],[1,3.1,33.05],[2,2.84,14.44]],"ltp":3.3,"tv":1474.37,"id":9712888}],"tv":7161.69}]}
{"op":"mcm","clk":"4233738788","pt":1631538303584,"mc":[{"id":"1.187557759","rc":[{"batb":[[1,1.28,426.66],[2,1.25,139.04]],"batl":[[0,1.45,5.7],[1,1.52,67],[2,1.58,42.25]],"ltp":1.43,"tv":5687.32,"id":9634485},{"batb":[[1,2.72,4.59],[2,2.7,19.07]],"batl":[[0,4.6,2.26],[1,5.4,2.14],[2,3.75,0]],"ltp":3.3,"tv":1474.37,"id":9712888}]}]}
{"op":"mcm","clk":"4233738927","pt":1631538304562,"mc":[{"id":"1.187557759","rc":[{"batb":[[0,1.28,426.66],[1,1.25,139.04],[2,1.23,105.63]],"ltp":1.43,"tv":5687.32,"id":9634485}]}]}
{"op":"mcm","clk":"4233739199","pt":1631538306769,"mc":[{"id":"1.187557759","rc":[{"batl":[[2,1.54,6.38]],"ltp":1.43,"tv":5687.32,"id":9634485},{"batb":[[1,2.84,10.72],[2,2.72,16.18]],"ltp":3.3,"tv":1474.37,"id":9712888}]}]}
{"op":"mcm","clk":"4233739313","pt":1631538307678,"mc":[{"id":"1.187557759","rc":[{"batl":[[2,1.58,42.25]],"ltp":1.43,"tv":5687.32,"id":9634485},{"batb":[[1,2.72,4.59],[2,2.7,19.07]],"ltp":3.3,"tv":1474.37,"id":9712888}]}]}
{"op":"mcm","clk":"4233739426","pt":1631538308693,"mc":[{"id":"1.187557759","rc":[{"batb":[[0,1.37,144.13],[1,1.36,145.62],[2,1.28,426.66]],"batl":[[0,1.4,84.3],[1,1.41,120.93],[2,1.45,5.7]],"ltp":1.43,"tv":5687.32,"id":9634485}]}]}
{"op":"mcm","clk":"4233739594","pt":1631538310702,"mc":[{"id":"1.187557759","rc":[{"batl":[[2,1.52,67]],"ltp":1.43,"tv":5687.32,"id":9634485},{"batb":[[0,2.84,10.97],[1,2.72,14.68]],"ltp":3.3,"tv":1474.37,"id":9712888}]}]}
{"op":"mcm","clk":"4233739615","pt":1631538310874,"mc":[{"id":"1.187557759","rc":[{"batb":[[0,2.84,15.69]],"ltp":3.3,"tv":1474.37,"id":9712888}]}]}
{"op":"mcm","clk":"4233740057","pt":1631538315778,"mc":[{"id":"1.187557759","rc":[{"batb":[[0,1.28,426.66],[1,1.25,139.04],[2,1.23,105.63]],"batl":[[0,1.52,67],[1,1.54,52.63],[2,1.58,48.5]],"ltp":1.43,"tv":5687.32,"id":9634485}]}]}
{"op":"mcm","clk":"4233740111","pt":1631538316406,"mc":[{"id":"1.187557759","rc":[{"batl":[[1,1.58,42.25],[2,1.82,585.75]],"ltp":1.43,"tv":5687.32,"id":9634485},{"batb":[[0,2.72,4.59],[1,2.7,19.07],[2,2,11.86]],"ltp":3.3,"tv":1474.37,"id":9712888}]}]}
{"op":"mcm","clk":"4233740213","pt":1631538317813,"mc":[{"id":"1.187557759","rc":[{"batl":[[0,1.58,42.25],[1,1.82,585.75],[2,1.82,0]],"ltp":1.43,"tv":5687.32,"id":9634485}]}]}
{"op":"mcm","clk":"4233740287","pt":1631538318700,"mc":[{"id":"1.187557759","rc":[{"batb":[[0,1.28,567.75],[1,1.27,209.02],[2,1.25,139.04]],"batl":[[0,1.54,122.43],[1,1.55,81.78],[2,1.58,42.25]],"ltp":1.43,"tv":5687.32,"id":9634485}]}]}
{"op":"mcm","clk":"4233740372","pt":1631538319589,"mc":[{"id":"1.187557759","rc":[{"batl":[[2,1.58,49]],"ltp":1.43,"tv":5687.32,"id":9634485},{"batb":[[0,2.72,16.43]],"ltp":3.3,"tv":1474.37,"id":9712888}]}]}
{"op":"mcm","clk":"4233740640","pt":1631538322819,"mc":[{"id":"1.187557759","rc":[{"batl":[[0,1.54,182.93]],"ltp":1.43,"tv":5687.32,"id":9634485},{"batb":[[0,2.84,15.19],[1,2.72,16.43],[2,2.7,19.07]],"ltp":3.3,"tv":1474.37,"id":9712888}]}]}
{"op":"mcm","clk":"4233740686","pt":1631538323339,"mc":[{"id":"1.187557759","rc":[{"batl":[[0,1.54,122.43]],"ltp":1.43,"tv":5687.32,"id":9634485},{"batb":[[0,2.72,16.43],[1,2.7,19.07],[2,2,11.86]],"ltp":3.3,"tv":1474.37,"id":9712888}]}]}
{"op":"mcm","clk":"4233740790","pt":1631538324429,"mc":[{"id":"1.187557759","rc":[{"batl":[[0,1.58,42.25],[1,1.82,585.75],[2,1.58,0]],"ltp":1.43,"tv":5687.32,"id":9634485},{"batb":[[0,2.72,4.59]],"ltp":3.3,"tv":1474.37,"id":9712888}]}]}
{"op":"mcm","clk":"4233740861","pt":1631538325208,"mc":[{"id":"1.187557759","rc":[{"batb":[[0,1.28,141.09]],"batl":[[1,1.82,0]],"ltp":1.43,"tv":5687.32,"id":9634485},{"batl":[[0,5.4,2.14],[1,5.4,0]],"ltp":3.3,"tv":1474.37,"id":9712888}]}]}
{"op":"mcm","clk":"4233740993","pt":1631538326818,"mc":[{"id":"1.187557759","rc":[{"batb":[[0,1.31,13.68],[1,1.28,141.09],[2,1.27,209.02]],"batl":[[0,1.33,2825.16],[1,1.34,56.4],[2,1.35,56.4]],"ltp":1.43,"tv":5687.32,"id":9634485},{"batb":[[0,4.1,48.78],[1,3.2,1500.49],[2,2.84,4.72]],"batl":[[0,4.5,259.19],[1,5.4,2.14]],"ltp":3.3,"tv":1474.37,"id":9712888}]}]}
{"op":"mcm","clk":"4233741092","pt":1631538327814,"mc":[{"id":"1.187557759","rc":[{"trd":[[1.31,27.36]],"batb":[[0,1.29,116.28],[1,1.28,199.23],[2,1.27,267.16]],"batl":[[0,1.31,215.11],[1,1.32,163.17],[2,1.33,145.86]],"ltp":1.31,"tv":5714.68,"id":9634485},{"batb":[[0,4.1,9.76],[2,2.72,4.59]],"batl":[[1,4.8,2.08],[2,5.4,2.14]],"ltp":3.3,"tv":1474.37,"id":9712888}],"tv":7189.05}]}
{"op":"mcm","clk":"4233741145","pt":1631538328438,"mc":[{"id":"1.187557759","rc":[{"batb":[[0,1.29,23.26],[1,1.28,152.71],[2,1.27,220.64]],"batl":[[2,1.33,55.64]],"ltp":1.31,"tv":5714.68,"id":9634485},{"batb":[[1,3.9,36.56],[2,3.3,27.11]],"ltp":3.3,"tv":1474.37,"id":9712888}]}]}
{"op":"mcm","clk":"4233741369","pt":1631538330846,"mc":[{"id":"1.187557759","rc":[{"trd":[[1.31,27.42]],"batl":[[0,1.31,215.05]],"ltp":1.31,"tv":5714.74,"id":9634485},{"trd":[[4.2,0.02]],"ltp":4.2,"tv":1474.39,"id":9712888}],"tv":7189.13}]}
{"op":"mcm","clk":"4233741451","pt":1631538331850,"mc":[{"id":"1.187557759","rc":[{"batb":[[0,1.29,317.26]],"batl":[[2,1.33,104.02]],"ltp":1.31,"tv":5714.74,"id":9634485},{"batl":[[0,4.3,34.43],[1,4.5,259.19],[2,4.8,2.08]],"ltp":4.2,"tv":1474.39,"id":9712888}]}]}
{"op":"mcm","clk":"4233741471","pt":1631538332014,"mc":[{"id":"1.187557759","rc":[{"batl":[[2,1.33,55.64]],"ltp":1.31,"tv":5714.74,"id":9634485},{"batl":[[0,4.5,259.19],[1,4.8,2.08],[2,5.4,2.14]],"ltp":4.2,"tv":1474.39,"id":9712888}]}]}
{"op":"mcm","clk":"4233741704","pt":1631538334624,"mc":[{"id":"1.187557759","rc":[{"batb":[[2,3.5,3.24]],"ltp":4.2,"tv":1474.39,"id":9712888}]}]}
{"op":"mcm","clk":"4233741760","pt":1631538335143,"mc":[{"id":"1.187557759","rc":[{"trd":[[1.31,27.6]],"batl":[[0,1.31,214.87]],"ltp":1.31,"tv":5714.92,"id":9634485},{"trd":[[4.2,0.07]],"ltp":4.2,"tv":1474.45,"id":9712888}],"tv":7189.37}]}
{"op":"mcm","clk":"4233741984","pt":1631538337761,"mc":[{"id":"1.187557759","rc":[{"batl":[[2,1.33,30.08]],"ltp":1.31,"tv":5714.92,"id":9634485}]}]}
{"op":"mcm","clk":"4233742209","pt":1631538340224,"mc":[{"id":"1.187557759","rc":[{"batl":[[1,1.32,183.3]],"ltp":1.31,"tv":5714.92,"id":9634485},{"batl":[[0,4.3,4.49],[1,4.5,259.19],[2,4.8,2.08]],"ltp":4.2,"tv":1474.45,"id":9712888}]}]}
{"op":"mcm","clk":"4233742352","pt":1631538341844,"mc":[{"id":"1.187557759","rc":[{"batl":[[2,1.33,22.56]],"ltp":1.31,"tv":5714.92,"id":9634485},{"batl":[[2,5.4,2.14]],"ltp":4.2,"tv":1474.45,"id":9712888}]}]}
{"op":"mcm","clk":"4233742410","pt":1631538342473,"mc":[{"id":"1.187557759","rc":[{"batb":[[0,1.29,294],[1,1.22,372.57],[2,1.2,113.62]],"batl":[[0,1.39,67],[1,1.42,67],[2,1.44,53.58]],"ltp":1.31,"tv":5714.92,"id":9634485},{"batb":[[0,3.3,27.11],[1,3.25,3.69],[2,2.72,4.59]],"batl":[[0,6,2.01],[1,7,2],[2,5.4,0]],"ltp":4.2,"tv":1474.45,"id":9712888}]}]}
{"op":"mcm","clk":"4233742493","pt":1631538343361,"mc":[{"id":"1.187557759","rc":[{"batb":[[0,1.22,372.57],[1,1.2,113.62],[2,1.17,377.98]],"ltp":1.31,"tv":5714.92,"id":9634485}]}]}
{"op":"mcm","clk":"4233742591","pt":1631538344462,"mc":[{"id":"1.187557759","rc":[{"batl":[[2,1.43,67.5]],"ltp":1.31,"tv":5714.92,"id":9634485},{"batb":[[0,3.3,30.89]],"batl":[[2,7.4,2]],"ltp":4.2,"tv":1474.45,"id":9712888}]}]}
{"op":"mcm","clk":"4233742704","pt":1631538345663,"mc":[{"id":"1.187557759","rc":[{"batb":[[2,1.19,315.94]],"batl":[[0,1.38,86.53],[1,1.39,195.85],[2,1.4,65.89]],"ltp":1.31,"tv":5714.92,"id":9634485},{"batb":[[0,3.5,3.04],[1,3.3,30.89],[2,3.25,3.69]],"ltp":4.2,"tv":1474.45,"id":9712888}]}]}
{"op":"mcm","clk":"4233743357","pt":1631538352573,"mc":[{"id":"1.187557759","rc":[{"batb":[[1,1.19,315.94],[2,1.18,266.84]],"batl":[[0,1.39,67],[1,1.42,67],[2,1.71,659.22]],"ltp":1.31,"tv":5714.92,"id":9634485},{"batb":[[0,3.3,30.89],[1,3.25,3.69],[2,2,11.86]],"batl":[[0,7,2],[1,7.4,2],[2,7.4,0]],"ltp":4.2,"tv":1474.45,"id":9712888}]}]}
{"op":"mcm","clk":"4233743562","pt":1631538354549,"mc":[{"id":"1.187557759","rc":[{"batb":[[0,1.19,315.94],[1,1.18,266.84],[2,1.17,377.98]],"batl":[[2,880,0.01]],"ltp":1.31,"tv":5714.92,"id":9634485}]}]}
{"op":"mcm","clk":"4233743699","pt":1631538355792,"mc":[{"id":"1.187557759","rc":[{"trd":[[1.22,36]],"batb":[[0,1.2,811.87],[1,1.19,315.94],[2,1.18,255.85]],"batl":[[0,1.22,260.02],[1,1.25,8],[2,1.31,43.88]],"ltp":1.22,"tv":5750.92,"id":9634485},{"batb":[[0,5.3,4.7],[1,5.1,5.88],[2,5,2.94]],"batl":[[0,6,152.79],[1,7,2],[2,7.4,2]],"ltp":4.2,"tv":1474.45,"id":9712888}],"tv":7225.37}]}
{"op":"mcm","clk":"4233743778","pt":1631538356673,"mc":[{"id":"1.187557759","rc":[{"batb":[[2,1.18,264.32]],"ltp":1.22,"tv":5750.92,"id":9634485},{"batb":[[2,5,22.01]],"batl":[[0,5.8,5.18],[1,5.9,2.58],[2,6,155.37]],"ltp":4.2,"tv":1474.45,"id":9712888}]}]}
{"op":"mcm","clk":"4233743962","pt":1631538358712,"mc":[{"id":"1.187557759","rc":[{"batl":[[0,1.22,337.64],[1,1.23,225.34],[2,1.25,8]],"ltp":1.22,"tv":5750.92,"id":9634485}]}]}
{"op":"mcm","clk":"4233744216","pt":1631538361267,"mc":[{"id":"1.187557759","rc":[{"batb":[[0,1.2,950.87]],"ltp":1.22,"tv":5750.92,"id":9634485}]}]}
{"op":"mcm","clk":"4233744610","pt":1631538365598,"mc":[{"id":"1.187557759","rc":[{"batb":[[0,5.1,5.88],[1,5,22.01],[2,4.9,43.76]],"ltp":4.2,"tv":1474.45,"id":9712888}]}]}
{"op":"mcm","clk":"4233744920","pt":1631538368781,"mc":[{"id":"1.187557759","rc":[{"batl":[[1,1.23,255.97]],"ltp":1.22,"tv":5750.92,"id":9634485},{"batl":[[0,5.7,5.1],[1,5.8,5.18],[2,5.9,2.58]],"ltp":4.2,"tv":1474.45,"id":9712888}]}]}
{"op":"mcm","clk":"4233745098","pt":1631538370613,"mc":[{"id":"1.187557759","rc":[{"trd":[[1.22,76]],"batb":[[2,1.18,252.86]],"batl":[[0,1.22,317.64]],"ltp":1.22,"tv":5790.92,"id":9634485}],"tv":7265.37}]}
{"op":"mcm","clk":"4233745149","pt":1631538371288,"mc":[{"id":"1.187557759","rc":[{"batb":[[0,1.2,811.87]],"ltp":1.22,"tv":5790.92,"id":9634485}]}]}
{"op":"mcm","clk":"4233745303","pt":1631538372805,"mc":[{"id":"1.187557759","rc":[{"trd":[[1.22,86]],"batl":[[0,1.22,312.64]],"ltp":1.22,"tv":5800.92,"id":9634485}],"tv":7275.37}]}
{"op":"mcm","clk":"4233745362","pt":1631538373484,"mc":[{"id":"1.187557759","rc":[{"batb":[[1,1.19,336.73]],"batl":[[1,1.23,266.93]],"ltp":1.22,"tv":5800.92,"id":9634485}]}]}
{"op":"mcm","clk":"4233745437","pt":1631538374436,"mc":[{"id":"1.187557759","rc":[{"batb":[[0,1.21,178],[1,1.2,811.87],[2,1.19,336.73]],"ltp":1.22,"tv":5800.92,"id":9634485}]}]}
{"op":"mcm","clk":"4233745623","pt":1631538376303,"mc":[{"id":"1.187557759","rc":[{"batl":[[0,1.22,323.82]],"ltp":1.22,"tv":5800.92,"id":9634485}]}]}
{"op":"mcm","clk":"4233745734","pt":1631538377717,"mc":[{"id":"1.187557759","rc":[{"trd":[[1.21,4],[1.22,86.9]],"batb":[[0,1.21,176]],"batl":[[0,1.22,323.37]],"ltp":1.21,"tv":5805.82,"id":9634485}],"tv":7280.27}]}
{"op":"mcm","clk":"4233745920","pt":1631538380015,"mc":[{"id":"1.187557759","rc":[{"trd":[[1.22,87.07]],"batl":[[0,1.22,323.2]],"ltp":1.22,"tv":5805.99,"id":9634485},{"trd":[[5.5,0.04]],"ltp":5.5,"tv":1474.48,"id":9712888}],"tv":7280.47}]}
{"op":"mcm","clk":"4233748548","pt":1631538408687,"mc":[{"id":"1.187557759","rc":[{"trd":[[1.22,129.14]],"batl":[[0,1.22,281.13]],"ltp":1.22,"tv":5848.06,"id":9634485},{"trd":[[5.5,9.37]],"ltp":5.5,"tv":1483.81,"id":9712888}],"tv":7331.88}]}
{"op":"mcm","clk":"4233748853","pt":1631538412261,"mc":[{"id":"1.187557759","rc":[{"trd":[[1.22,129.52]],"batb":[[2,1.19,363.82]],"batl":[[0,1.22,300.04]],"ltp":1.22,"tv":5848.44,"id":9634485}],"tv":7332.26}]}
{"op":"mcm","clk":"4233749320","pt":1631538417567,"mc":[{"id":"1.187557759","rc":[{"trd":[[1.22,209.52]],"batl":[[0,1.22,260.04]],"ltp":1.22,"tv":5928.44,"id":9634485}],"tv":7412.26}]}
{"op":"mcm","clk":"4233749529","pt":1631538419782,"mc":[{"id":"1.187557759","rc":[{"trd":[[1.22,213]],"batl":[[0,1.22,258.3]],"ltp":1.22,"tv":5931.92,"id":9634485}],"tv":7415.74}]}
{"op":"mcm","clk":"4233749609","pt":1631538420586,"mc":[{"id":"1.187557759","rc":[{"batb":[[2,1.19,385.4]],"batl":[[0,1.22,277.51]],"ltp":1.22,"tv":5931.92,"id":9634485}]}]}
{"op":"mcm","clk":"4233749744","pt":1631538422081,"mc":[{"id":"1.187557759","rc":[{"batb":[[0,1.21,179.61]],"batl":[[0,1.22,364.23]],"ltp":1.22,"tv":5931.92,"id":9634485}]}]}
{"op":"mcm","clk":"4233749945","pt":1631538424404,"mc":[{"id":"1.187557759","rc":[{"batb":[[0,1.21,176]],"ltp":1.22,"tv":5931.92,"id":9634485}]}]}
{"op":"mcm","clk":"4233752773","pt":1631538456338,"mc":[{"id":"1.187557759","rc":[{"trd":[[1.22,213.08]],"batl":[[0,1.22,364.15]],"ltp":1.22,"tv":5932.0,"id":9634485},{"trd":[[5.5,9.39]],"ltp":5.5,"tv":1483.83,"id":9712888}],"tv":7415.84}]}
{"op":"mcm","clk":"4233754562","pt":1631538475389,"mc":[{"id":"1.187557759","rc":[{"trd":[[1.21,380.02]],"batb":[[0,1.2,811.87],[1,1.19,385.4],[2,1.18,203.77]],"batl":[[0,1.21,644.09],[1,1.22,364.15],[2,1.23,266.93]],"ltp":1.21,"tv":6308.02,"id":9634485},{"trd":[[5.7,5.1]],"batl":[[0,5.8,5.18],[1,5.9,2.58],[2,6,155.37]],"ltp":5.7,"tv":1488.93,"id":9712888}],"tv":7796.96}]}
{"op":"mcm","clk":"4233754902","pt":1631538479301,"mc":[{"id":"1.187557759","rc":[{"batb":[[0,1.2,1039.87]],"ltp":1.21,"tv":6308.02,"id":9634485}]}]}
{"op":"mcm","clk":"4233754987","pt":1631538480344,"mc":[{"id":"1.187557759","rc":[{"batl":[[1,1.22,277.43]],"ltp":1.21,"tv":6308.02,"id":9634485}]}]}
{"op":"mcm","clk":"4233755157","pt":1631538482010,"mc":[{"id":"1.187557759","rc":[{"batl":[[0,1.22,277.43],[1,1.23,266.93],[2,1.25,8]],"ltp":1.21,"tv":6308.02,"id":9634485}]}]}
{"op":"mcm","clk":"4233755289","pt":1631538483384,"mc":[{"id":"1.187557759","rc":[{"batl":[[0,1.21,86.72],[1,1.22,277.43],[2,1.23,266.93]],"ltp":1.21,"tv":6308.02,"id":9634485}]}]}
{"op":"mcm","clk":"4233755508","pt":1631538485634,"mc":[{"id":"1.187557759","rc":[{"trd":[[1.2,1288.18]],"batb":[[0,1.2,395.78]],"batl":[[2,1.23,236.3]],"ltp":1.2,"tv":7596.2,"id":9634485}],"tv":9085.14}]}
{"op":"mcm","clk":"4233755740","pt":1631538488509,"mc":[{"id":"1.187557759","rc":[{"batb":[[0,1.2,418.87]],"batl":[[1,1.22,301.25]],"ltp":1.2,"tv":7596.2,"id":9634485},{"batl":[[2,6,159.99]],"ltp":5.7,"tv":1488.93,"id":9712888}]}]}
{"op":"mcm","clk":"4233756350","pt":1631538495769,"mc":[{"id":"1.187557759","rc":[{"trd":[[1.21,380.11]],"batb":[[0,1.2,275.91],[1,1.17,215.01],[2,1.15,244.2]],"batl":[[0,1.21,86.64],[1,1.28,75],[2,1.3,67]],"ltp":1.21,"tv":7596.29,"id":9634485},{"trd":[[5.7,5.12]],"batb":[[0,5,19.07],[1,4.4,25.77],[2,1.01,115.38]],"batl":[[0,7,2],[1,990,0.01],[2,6,0]],"ltp":5.7,"tv":1488.95,"id":9712888}],"tv":9085.25}]}
{"op":"mcm","clk":"4233756403","pt":1631538496406,"mc":[{"id":"1.187557759","rc":[{"trd":[[1.21,383.52]],"batb":[[0,1.15,244.2],[1,1.14,431.42],[2,1.01,115.38]],"batl":[[0,1.21,84.93]],"ltp":1.21,"tv":7599.7,"id":9634485},{"batb":[[0,4.4,25.77],[1,1.01,115.38],[2,1.01,0]],"ltp":5.7,"tv":1488.95,"id":9712888}],"tv":9088.65}]}
{"op":"mcm","clk":"4233756612","pt":1631538498652,"mc":[{"id":"1.187557759","rc":[{"batb":[[0,1.17,342.82],[1,1.16,248.27],[2,1.15,244.2]],"batl":[[1,1.26,206.03],[2,1.27,199.45]],"ltp":1.21,"tv":7599.7,"id":9634485}]}]}
{"op":"mcm","clk":"4233756731","pt":1631538500359,"mc":[{"id":"1.187557759","rc":[{"trd":[[1.21,400.55]],"batl":[[0,1.21,76.42]],"ltp":1.21,"tv":7616.73,"id":9634485}],"tv":9105.68}]}
{"op":"mcm","clk":"4233756922","pt":1631538502776,"mc":[{"id":"1.187557759","rc":[{"trd":[[1.21,404.88]],"batl":[[0,1.21,74.25]],"ltp":1.21,"tv":7621.06,"id":9634485}],"tv":9110.02}]}
{"op":"mcm","clk":"4233757107","pt":1631538504452,"mc":[{"id":"1.187557759","rc":[{"batl":[[1,1.25,75],[2,1.26,206.03]],"ltp":1.21,"tv":7621.06,"id":9634485}]}]}
{"op":"mcm","clk":"4233757540","pt":1631538509569,"mc":[{"id":"1.187557759","rc":[{"batl":[[2,1.28,75]],"ltp":1.21,"tv":7621.06,"id":9634485}]}]}
{"op":"mcm","clk":"4233757805","pt":1631538512449,"mc":[{"id":"1.187557759","rc":[{"batb":[[0,1.18,916.06],[1,1.17,342.82],[2,1.16,248.27]],"batl":[[0,1.19,129.8],[1,1.2,287.12],[2,1.21,74.25]],"ltp":1.21,"tv":7621.06,"id":9634485},{"batb":[[0,6.2,3.41],[1,6,22.66],[2,5.9,22]],"batl":[[1,7.6,17.88],[2,7.8,17.36]],"ltp":5.7,"tv":1488.95,"id":9712888}]}]}
{"op":"mcm","clk":"4233757881","pt":1631538513281,"mc":[{"id":"1.187557759","rc":[{"batb":[[2,1.16,256.89]],"ltp":1.21,"tv":7621.06,"id":9634485}]}]}
{"op":"mcm","clk":"4233758294","pt":1631538517573,"mc":[{"id":"1.187557759","rc":[{"trd":[[1.19,110.56]],"batb":[[2,1.16,194.1]],"batl":[[0,1.2,287.12],[1,1.21,74.25],[2,1.23,8.13]],"ltp":1.19,"tv":7731.62,"id":9634485},{"trd":[[6.2,28.04]],"batb":[[0,6,22.66],[1,5.9,22],[2,5.8,22]],"ltp":6.2,"tv":1516.99,"id":9712888}],"tv":9248.62}]}
{"op":"mcm","clk":"4233758407","pt":1631538518676,"mc":[{"id":"1.187557759","rc":[{"batb":[[1,1.17,485.79],[2,1.16,342.13]],"batl":[[2,1.23,106.63]],"ltp":1.19,"tv":7731.62,"id":9634485},{"batl":[[1,7.4,2],[2,7.6,17.88]],"ltp":6.2,"tv":1516.99,"id":9712888}]}]}
{"op":"mcm","clk":"4233758554","pt":1631538520493,"mc":[{"id":"1.187557759","rc":[{"batb":[[0,1.18,1067.06],[1,1.17,548.04]],"batl":[[0,1.2,355.27],[1,1.21,291.41]],"ltp":1.19,"tv":7731.62,"id":9634485}]}]}
{"op":"mcm","clk":"4233758909","pt":1631538524781,"mc":[{"id":"1.187557759","rc":[{"batb":[[0,1.18,916.06],[1,1.17,496.52],[2,1.16,156.65]],"batl":[[0,1.2,314.32]],"ltp":1.19,"tv":7731.62,"id":9634485}]}]}
{"op":"mcm","clk":"4233759151","pt":1631538527700,"mc":[{"id":"1.187557759","rc":[{"batb":[[0,1.19,381],[1,1.18,977.13],[2,1.17,496.52]],"batl":[[1,1.21,332.02]],"ltp":1.19,"tv":7731.62,"id":9634485}]}]}
{"op":"mcm","clk":"4233759405","pt":1631538530406,"mc":[{"id":"1.187557759","rc":[{"batl":[[0,1.2,328.28]],"ltp":1.19,"tv":7731.62,"id":9634485},{"batl":[[0,6.4,5.17],[1,7,2],[2,7.4,2]],"ltp":6.2,"tv":1516.99,"id":9712888}]}]}
{"op":"mcm","clk":"4233759820","pt":1631538535107,"mc":[{"id":"1.187557759","rc":[{"batl":[[2,1.22,82]],"ltp":1.19,"tv":7731.62,"id":9634485}]}]}
{"op":"mcm","clk":"4233760120","pt":1631538538786,"mc":[{"id":"1.187557759","rc":[{"batb":[[1,1.17,142.97],[2,1.16,148.03]],"batl":[[0,1.21,74.25],[1,1.22,82],[2,1.24,109.73]],"ltp":1.19,"tv":7731.62,"id":9634485},{"batb":[[0,5,2.05],[1,4.9,20.58],[2,1.01,115.38]],"batl":[[0,7,2],[1,7.4,2],[2,990,0.01]],"ltp":6.2,"tv":1516.99,"id":9712888}]}]}
{"op":"mcm","clk":"4233760196","pt":1631538539725,"mc":[{"id":"1.187557759","rc":[{"batb":[[0,1.16,148.03],[1,1.13,915.8],[2,1.01,115.38]],"batl":[[2,1.25,166.46]],"ltp":1.19,"tv":7731.62,"id":9634485},{"batl":[[0,7.4,2],[1,990,0.01],[2,990,0]],"ltp":6.2,"tv":1516.99,"id":9712888}]}]}
{"op":"mcm","clk":"4233760367","pt":1631538541510,"mc":[{"id":"1.187557759","rc":[{"batb":[[0,1.16,327.85],[1,1.15,412.13],[2,1.13,915.8]],"batl":[[2,1.23,190.58]],"ltp":1.19,"tv":7731.62,"id":9634485}]}]}
{"op":"mcm","clk":"4233760556","pt":1631538543510,"mc":[{"id":"1.187557759","rc":[{"batl":[[2,1.25,166.46]],"ltp":1.19,"tv":7731.62,"id":9634485}]}]}
{"op":"mcm","clk":"4233760748","pt":1631538545601,"mc":[{"id":"1.187557759","rc":[{"batb":[[2,1.13,277.25]],"batl":[[2,1.23,111.5]],"ltp":1.19,"tv":7731.62,"id":9634485},{"batb":[[0,5.3,2.08],[1,5,2.05],[2,4.9,20.58]],"ltp":6.2,"tv":1516.99,"id":9712888}]}]}
{"op":"mcm","clk":"4233760834","pt":1631538546538,"mc":[{"id":"1.187557759","rc":[{"batb":[[0,1.16,377.41]],"batl":[[0,1.18,343.77],[1,1.19,270.47],[2,1.2,681.19]],"ltp":1.19,"tv":7731.62,"id":9634485},{"batb":[[0,6.4,21.26],[1,6.2,20.62],[2,6,156.86]],"batl":[[0,7.2,142.49],[1,7.4,2],[2,8,17]],"ltp":6.2,"tv":1516.99,"id":9712888}]}]}
{"op":"mcm","clk":"4233760917","pt":1631538547322,"mc":[{"id":"1.187557759","rc":[{"batb":[[1,1.15,420.83]],"ltp":1.19,"tv":7731.62,"id":9634485}]}]}
{"op":"mcm","clk":"4233761025","pt":1631538548630,"mc":[{"id":"1.187557759","rc":[{"batl":[[2,1.2,763.19]],"ltp":1.19,"tv":7731.62,"id":9634485}]}]}
{"op":"mcm","clk":"4233761189","pt":1631538550301,"mc":[{"id":"1.187557759","rc":[{"batb":[[0,1.17,321],[1,1.16,377.41],[2,1.15,420.83]],"ltp":1.19,"tv":7731.62,"id":9634485}]}]}
{"op":"mcm","clk":"4233761384","pt":1631538552396,"mc":[{"id":"1.187557759","rc":[{"batb":[[2,1.15,573.06]],"batl":[[2,1.2,880.42]],"ltp":1.19,"tv":7731.62,"id":9634485},{"batb":[[2,6,158.86]],"batl":[[2,7.8,2]],"ltp":6.2,"tv":1516.99,"id":9712888}]}]}
{"op":"mcm","clk":"4233761869","pt":1631538557051,"mc":[{"id":"1.187557759","rc":[{"batb":[[2,1.15,532.08]],"batl":[[0,1.18,298.33]],"ltp":1.19,"tv":7731.62,"id":9634485}]}]}
{"op":"mcm","clk":"4233762191","pt":1631538559934,"mc":[{"id":"1.187557759","rc":[{"batb":[[1,1.16,423.68]],"batl":[[1,1.19,294.33]],"ltp":1.19,"tv":7731.62,"id":9634485}]}]}
{"op":"mcm","clk":"4233762399","pt":1631538562427,"mc":[{"id":"1.187557759","rc":[{"batb":[[1,1.16,148.03],[2,1.15,294.06]],"batl":[[0,1.2,82],[1,1.21,195.75],[2,1.22,82]],"ltp":1.19,"tv":7731.62,"id":9634485},{"batb":[[0,5.7,2],[1,5.3,33.21],[2,5,2.05]],"batl":[[0,7.4,2],[1,7.8,2],[2,990,0.01]],"ltp":6.2,"tv":1516.99,"id":9712888}]}]}
{"op":"mcm","clk":"4233762490","pt":1631538563630,"mc":[{"id":"1.187557759","rc":[{"batb":[[0,1.15,294.06],[1,1.11,1000.76],[2,1.01,115.38]],"ltp":1.19,"tv":7731.62,"id":9634485},{"batl":[[0,7.8,2],[1,990,0.01],[2,990,0]],"ltp":6.2,"tv":1516.99,"id":9712888}]}]}
{"op":"mcm","clk":"4233762655","pt":1631538565656,"mc":[{"id":"1.187557759","rc":[{"batb":[[1,1.14,441.39],[2,1.11,1000.76]],"batl":[[0,1.2,336.9],[1,1.21,461.76]],"ltp":1.19,"tv":7731.62,"id":9634485},{"batb":[[0,6,2],[1,5.7,2],[2,5.3,33.21]],"ltp":6.2,"tv":1516.99,"id":9712888}]}]}
{"op":"mcm","clk":"4233762709","pt":1631538566433,"mc":[{"id":"1.187557759","rc":[{"batb":[[0,1.15,152.23],[1,1.11,1000.76],[2,1.01,115.38]],"ltp":1.19,"tv":7731.62,"id":9634485}]}]}
{"op":"mcm","clk":"4233762835","pt":1631538567838,"mc":[{"id":"1.187557759","rc":[{"batl":[[0,1.2,254.9]],"ltp":1.19,"tv":7731.62,"id":9634485}]}]}
{"op":"mcm","clk":"4233762863","pt":1631538568149,"mc":[{"id":"1.187557759","rc":[{"batb":[[1,1.11,307.11]],"batl":[[0,1.2,144.92]],"ltp":1.19,"tv":7731.62,"id":9634485},{"batb":[[0,5.7,2],[1,5.3,33.21],[2,5,2.05]],"ltp":6.2,"tv":1516.99,"id":9712888}]}]}
{"op":"mcm","clk":"4233762992","pt":1631538569556,"mc":[{"id":"1.187557759","rc":[{"batb":[[0,1.19,36.81],[1,1.18,1360.69],[2,1.17,320.82]],"batl":[[0,1.2,154.43],[2,1.22,1044.8]],"ltp":1.19,"tv":7731.62,"id":9634485},{"batl":[[0,6.4,16.06],[1,6.6,25.21],[2,6.8,7.03]],"ltp":6.2,"tv":1516.99,"id":9712888}]}]}
{"op":"mcm","clk":"4233763081","pt":1631538570555,"mc":[{"id":"1.187557759","rc":[{"batb":[[1,5.6,5.36],[2,5.5,2.68]],"ltp":6.2,"tv":1516.99,"id":9712888}]}]}
{"op":"mcm","clk":"4233763570","pt":1631538575990,"mc":[{"id":"1.187557759","rc":[{"batb":[[2,1.17,449.79]],"batl":[[2,1.22,1157.55]],"ltp":1.19,"tv":7731.62,"id":9634485},{"batb":[[2,5.5,4.68]],"ltp":6.2,"tv":1516.99,"id":9712888}]}]}
{"op":"mcm","clk":"4233763689","pt":1631538577458,"mc":[{"id":"1.187557759","rc":[{"batb":[[0,1.19,163.81]],"ltp":1.19,"tv":7731.62,"id":9634485}]}]}
{"op":"mcm","clk":"4233764456","pt":1631538586820,"mc":[{"id":"1.187557759","rc":[{"batb":[[0,1.19,145.71],[1,1.18,323.06],[2,1.17,441.24]],"batl":[[0,1.2,144.92],[2,1.22,194.75]],"ltp":1.19,"tv":7731.62,"id":9634485},{"batb":[[1,5.5,2],[2,5.3,35.29]],"batl":[[0,6.4,2],[1,7,2],[2,7.4,2]],"ltp":6.2,"tv":1516.99,"id":9712888}]}]}
{"op":"mcm","clk":"4233764553","pt":1631538587712,"mc":[{"id":"1.187557759","rc":[{"batb":[[0,1.19,127],[1,1.17,128.97],[2,1.16,160.53]],"batl":[[0,1.21,74.25],[1,1.22,82],[2,1.23,103.5]],"ltp":1.19,"tv":7731.62,"id":9634485},{"batb":[[0,5.3,2.08],[1,4.7,22.09],[2,1.01,115.38]],"batl":[[0,7,2],[1,7.4,2],[2,7.8,2]],"ltp":6.2,"tv":1516.99,"id":9712888}]}]}
{"op":"mcm","clk":"4233764656","pt":1631538588710,"mc":[{"id":"1.187557759","rc":[{"batb":[[0,1.16,160.53],[1,1.13,913.54],[2,1.01,115.38]],"ltp":1.19,"tv":7731.62,"id":9634485},{"batl":[[0,7.4,2],[1,990,0.01],[2,7.8,0]],"ltp":6.2,"tv":1516.99,"id":9712888}]}]}
{"op":"mcm","clk":"4233764980","pt":1631538592102,"mc":[{"id":"1.187557759","rc":[{"batb":[[0,1.19,175.41],[1,1.18,332.28],[2,1.17,142.97]],"batl":[[0,1.21,277.45],[1,1.22,332.17]],"ltp":1.19,"tv":7731.62,"id":9634485},{"batl":[[0,7,2],[1,7.4,2],[2,990,0.01]],"ltp":6.2,"tv":1516.99,"id":9712888}]}]}
{"op":"mcm","clk":"4233765164","pt":1631538594100,"mc":[{"id":"1.187557759","rc":[{"batl":[[1,1.22,453.42]],"ltp":1.19,"tv":7731.62,"id":9634485},{"batb":[[0,5.5,2.12],[1,5.3,2.08],[2,4.7,22.09]],"ltp":6.2,"tv":1516.99,"id":9712888}]}]}
{"op":"mcm","clk":"4233765283","pt":1631538595305,"mc":[{"id":"1.187557759","rc":[{"trd":[[1.19,110.72]],"batb":[[0,1.19,325.33]],"ltp":1.19,"tv":7731.78,"id":9634485}],"tv":9248.78}]}
{"op":"mcm","clk":"4233765599","pt":1631538599188,"mc":[{"id":"1.187557759","rc":[{"trd":[[1.21,415.51]],"batb":[[0,1.19,150],[1,1.17,142.97],[2,1.16,160.53]],"batl":[[0,1.21,68.94],[1,1.22,82]],"ltp":1.21,"tv":7742.4,"id":9634485},{"batb":[[0,5.3,2.08],[1,4.7,22.09],[2,1.01,115.38]],"ltp":6.2,"tv":1516.99,"id":9712888}],"tv":9259.4}]}
{"op":"mcm","clk":"4233765722","pt":1631538600609,"mc":[{"id":"1.187557759","rc":[{"batb":[[0,1.16,160.53],[1,1.13,913.54],[2,1.01,115.38]],"ltp":1.21,"tv":7742.4,"id":9634485},{"batl":[[0,7.4,2],[1,990,0.01],[2,990,0]],"ltp":6.2,"tv":1516.99,"id":9712888}]}]}
{"op":"mcm","clk":"4233765785","pt":1631538601400,"mc":[{"id":"1.187557759","rc":[{"batl":[[0,1.21,69.02]],"ltp":1.21,"tv":7742.4,"id":9634485}]}]}
{"op":"mcm","clk":"4233765910","pt":1631538602718,"mc":[{"id":"1.187557759","rc":[{"batb":[[0,1.16,421.71],[1,1.15,335.75],[2,1.13,913.54]],"ltp":1.21,"tv":7742.4,"id":9634485}]}]}
{"op":"mcm","clk":"4233766020","pt":1631538603825,"mc":[{"id":"1.187557759","rc":[{"batb":[[0,1.17,149.97],[1,1.16,421.71],[2,1.15,335.75]],"ltp":1.21,"tv":7742.4,"id":9634485},{"batl":[[0,7,2],[1,7.4,2],[2,990,0.01]],"ltp":6.2,"tv":1516.99,"id":9712888}]}]}
{"op":"mcm","clk":"4233766057","pt":1631538604143,"mc":[{"id":"1.187557759","rc":[{"batb":[[0,1.16,421.71],[1,1.15,335.75],[2,1.13,913.54]],"ltp":1.21,"tv":7742.4,"id":9634485},{"batl":[[0,7.4,2],[1,990,0.01],[2,990,0]],"ltp":6.2,"tv":1516.99,"id":9712888}]}]}
{"op":"mcm","clk":"4233766543","pt":1631538608708,"mc":[{"id":"1.187557759","rc":[{"batb":[[0,1.16,160.53],[1,1.13,913.54],[2,1.01,115.38]],"ltp":1.21,"tv":7742.4,"id":9634485}]}]}
{"op":"mcm","clk":"4233766656","pt":1631538609807,"mc":[{"id":"1.187557759","rc":[{"batl":[[1,1.22,207.75]],"ltp":1.21,"tv":7742.4,"id":9634485},{"batb":[[0,5.5,2.12],[1,5.3,2.08],[2,4.7,22.09]],"ltp":6.2,"tv":1516.99,"id":9712888}]}]}
{"op":"mcm","clk":"4233766741","pt":1631538610641,"mc":[{"id":"1.187557759","rc":[{"batb":[[1,1.13,274.99]],"batl":[[1,1.23,103.5],[2,1.24,143.78]],"ltp":1.21,"tv":7742.4,"id":9634485},{"batb":[[0,5.3,2.08],[1,4.7,22.09],[2,1.01,115.38]],"ltp":6.2,"tv":1516.99,"id":9712888}]}]}
{"op":"mcm","clk":"4233766839","pt":1631538611736,"mc":[{"id":"1.187557759","rc":[{"trd":[[1.19,110.88],[1.21,553.38]],"batb":[[0,1.22,200.83],[1,1.21,351.55],[2,1.2,117.41]],"batl":[[0,1.23,103.5],[1,1.24,166.49],[2,1.25,291.57]],"ltp":1.21,"tv":7880.44,"id":9634485},{"batb":[[1,4.8,28.34],[2,4.7,49.59]],"batl":[[0,5.5,7.01],[1,5.7,232.76],[2,5.8,2]],"ltp":6.2,"tv":1516.99,"id":9712888}],"tv":9397.44}]}
{"op":"mcm","clk":"4233766961","pt":1631538612742,"mc":[{"id":"1.187557759","rc":[{"batb":[[1,1.21,332.86]],"ltp":1.21,"tv":7880.44,"id":9634485},{"batl":[[2,7.4,2]],"ltp":6.2,"tv":1516.99,"id":9712888}]}]}
{"op":"mcm","clk":"4233767032","pt":1631538613422,"mc":[{"id":"1.187557759","rc":[{"batl":[[2,1.25,216.57]],"ltp":1.21,"tv":7880.44,"id":9634485}]}]}
{"op":"mcm","clk":"4233767161","pt":1631538614415,"mc":[{"id":"1.187557759","rc":[{"batb":[[0,5.3,7.21]],"ltp":6.2,"tv":1516.99,"id":9712888}]}]}
{"op":"mcm","clk":"4233767364","pt":1631538616508,"mc":[{"id":"1.187557759","rc":[{"batb":[[0,1.22,348.83]],"ltp":1.21,"tv":7880.44,"id":9634485}]}]}
{"op":"mcm","clk":"4233767498","pt":1631538618134,"mc":[{"id":"1.187557759","rc":[{"batl":[[2,6.6,2]],"ltp":6.2,"tv":1516.99,"id":9712888}]}]}
{"op":"mcm","clk":"4233769106","pt":1631538636550,"mc":[{"id":"1.187557759","rc":[{"batb":[[0,1.22,148],[1,1.18,325.62],[2,1.16,744.51]],"batl":[[0,1.26,125],[1,1.29,83.5],[2,1.31,78.5]],"ltp":1.21,"tv":7880.44,"id":9634485},{"batb":[[0,4.7,22.09],[1,4.4,2.61],[2,4.2,2.62]],"batl":[[0,6.6,2],[1,7.4,2],[2,990,0.01]],"ltp":6.2,"tv":1516.99,"id":9712888}]}]}
{"op":"mcm","clk":"4233769187","pt":1631538637489,"mc":[{"id":"1.187557759","rc":[{"batb":[[0,1.16,744.51],[1,1.15,238.6],[2,1.01,115.38]],"ltp":1.21,"tv":7880.44,"id":9634485},{"batb":[[0,4.4,2.61],[1,4.2,2.62],[2,4,33.8]],"batl":[[0,7.4,2],[1,990,0.01],[2,990,0]],"ltp":6.2,"tv":1516.99,"id":9712888}]}]}
{"op":"mcm","clk":"4233769371","pt":1631538639575,"mc":[{"id":"1.187557759","rc":[{"batb":[[0,1.18,274.61],[1,1.17,312.01],[2,1.16,744.51]],"batl":[[2,1.31,221.53]],"ltp":1.21,"tv":7880.44,"id":9634485}]}]}
{"op":"mcm","clk":"4233769784","pt":1631538640704,"mc":[{"id":"1.187557759","rc":[{"batb":[[0,1.18,137.86],[1,1.16,744.51],[2,1.15,238.6]],"batl":[[2,1.31,78.5]],"ltp":1.21,"tv":7880.44,"id":9634485},{"batl":[[0,6.6,2],[1,7.4,2],[2,990,0.01]],"ltp":6.2,"tv":1516.99,"id":9712888}]}]}
{"op":"mcm","clk":"4233769885","pt":1631538641035,"mc":[{"id":"1.187557759","rc":[{"batb":[[0,1.16,744.51],[1,1.15,238.6],[2,1.01,115.38]],"ltp":1.21,"tv":7880.44,"id":9634485},{"batl":[[0,7.4,2],[1,990,0.01],[2,990,0]],"ltp":6.2,"tv":1516.99,"id":9712888}]}]}
{"op":"mcm","clk":"4233770136","pt":1631538642280,"mc":[{"id":"1.187557759","rc":[{"batb":[[0,1.23,207.84],[1,1.22,263.28],[2,1.16,744.51]],"batl":[[0,1.26,404.04],[1,1.27,194.48],[2,1.29,83.5]],"ltp":1.21,"tv":7880.44,"id":9634485}]}]}
{"op":"mcm","clk":"4233770332","pt":1631538644261,"mc":[{"id":"1.187557759","rc":[{"batb":[[2,1.18,134.86]],"ltp":1.21,"tv":7880.44,"id":9634485},{"batl":[[0,6.6,2],[1,7.4,2],[2,990,0.01]],"ltp":6.2,"tv":1516.99,"id":9712888}]}]}
{"op":"mcm","clk":"4233770798","pt":1631538649486,"mc":[{"id":"1.187557759","rc":[{"batb":[[0,1.16,744.51],[1,1.15,238.6],[2,1.01,115.38]],"batl":[[0,1.26,125],[1,1.29,83.5],[2,1.31,78.5]],"ltp":1.21,"tv":7880.44,"id":9634485},{"batl":[[0,7.4,2],[1,990,0.01],[2,990,0]],"ltp":6.2,"tv":1516.99,"id":9712888}]}]}
{"op":"mcm","clk":"4233771073","pt":1631538652717,"mc":[{"id":"1.187557759","rc":[{"batb":[[0,1.18,399.47],[1,1.17,312.01],[2,1.16,744.51]],"batl":[[2,1.31,221.53]],"ltp":1.21,"tv":7880.44,"id":9634485},{"batl":[[0,6.6,2],[1,7.4,2],[2,990,0.01]],"ltp":6.2,"tv":1516.99,"id":9712888}]}]}
{"op":"mcm","clk":"4233771254","pt":1631538654700,"mc":[{"id":"1.187557759","rc":[{"batl":[[0,1.29,83.5],[1,1.31,221.53],[2,1.32,160.5]],"ltp":1.21,"tv":7880.44,"id":9634485}]}]}
{"op":"mcm","clk":"4233771284","pt":1631538655012,"mc":[{"id":"1.187557759","rc":[{"batl":[[0,1.31,221.53],[1,1.32,160.5],[2,1.49,772.05]],"ltp":1.21,"tv":7880.44,"id":9634485},{"batb":[[0,4.2,2.62],[1,4,33.8],[2,1.01,115.38]],"ltp":6.2,"tv":1516.99,"id":9712888}]}]}
{"op":"mcm","clk":"4233771593","pt":1631538657586,"mc":[{"id":"1.187557759","rc":[{"batl":[[0,1.31,78.5],[1,1.49,772.05],[2,3.8,27.46]],"ltp":1.21,"tv":7880.44,"id":9634485}]}]}
{"op":"mcm","clk":"4233771772","pt":1631538659410,"mc":[{"id":"1.187557759","rc":[{"batb":[[2,1.16,160.53]],"ltp":1.21,"tv":7880.44,"id":9634485}]}]}
{"op":"mcm","clk":"4233771915","pt":1631538660700,"mc":[{"id":"1.187557759","rc":[{"batb":[[0,1.18,1280.42]],"batl":[[0,1.2,156.95],[1,1.21,266.01],[2,1.22,1004.22]],"ltp":1.21,"tv":7880.44,"id":9634485},{"batb":[[0,5.9,23.04],[1,5.8,22.36],[2,5.7,22.36]],"batl":[[0,6.4,5.82],[1,6.6,2],[2,7.2,18.88]],"ltp":6.2,"tv":1516.99,"id":9712888}]}]}
{"op":"mcm","clk":"4233772025","pt":1631538661802,"mc":[{"id":"1.187557759","rc":[{"batb":[[2,1.16,169.15]],"ltp":1.21,"tv":7880.44,"id":9634485}]}]}
{"op":"mcm","clk":"4233772689","pt":1631538668635,"mc":[{"id":"1.187557759","rc":[{"batb":[[0,1.19,167],[1,1.18,1280.42],[2,1.17,312.01]],"ltp":1.21,"tv":7880.44,"id":9634485}]}]}
{"op":"mcm","clk":"4233773614","pt":1631538678851,"mc":[{"id":"1.187557759","rc":[{"batb":[[1,1.16,160.53],[2,1.15,174.23]],"batl":[[0,1.23,97],[1,1.25,203.1],[2,1.3,67]],"ltp":1.21,"tv":7880.44,"id":9634485},{"batb":[[0,5,2.3],[1,4.7,22.92],[2,4.2,2.62]],"batl":[[0,7.4,2],[1,8.2,2],[2,990,0.01]],"ltp":6.2,"tv":1516.99,"id":9712888}]}]}
{"op":"mcm","clk":"4233773692","pt":1631538679754,"mc":[{"id":"1.187557759","rc":[{"batb":[[0,1.14,201.82],[1,1.13,919.57],[2,1.01,115.38]],"ltp":1.21,"tv":7880.44,"id":9634485},{"batl":[[0,8.2,2],[1,990,0.01],[2,990,0]],"ltp":6.2,"tv":1516.99,"id":9712888}]}]}
{"op":"mcm","clk":"4233773789","pt":1631538680746,"mc":[{"id":"1.187557759","rc":[{"batb":[[0,6.4,41.83],[1,5,2.3],[2,4.7,22.92]],"ltp":6.2,"tv":1516.99,"id":9712888}]}]}
{"op":"mcm","clk":"4233773873","pt":1631538681536,"mc":[{"id":"1.187557759","rc":[{"batb":[[0,1.16,105.54],[1,1.15,406.57],[2,1.14,201.82]],"batl":[[1,1.25,431.43],[2,1.26,204.65]],"ltp":1.21,"tv":7880.44,"id":9634485}]}]}
{"op":"mcm","clk":"4233773992","pt":1631538682847,"mc":[{"id":"1.187557759","rc":[{"batl":[[1,1.24,88.48],[2,1.25,97]],"ltp":1.21,"tv":7880.44,"id":9634485}]}]}
{"op":"mcm","clk":"4233774050","pt":1631538683526,"mc":[{"id":"1.187557759","rc":[{"batl":[[0,1.23,97.19]],"ltp":1.21,"tv":7880.44,"id":9634485}]}]}
{"op":"mcm","clk":"4233774221","pt":1631538685830,"mc":[{"id":"1.187557759","rc":[{"batb":[[0,1.16,155.1]],"batl":[[0,1.18,3106.92],[1,1.19,207.17],[2,1.2,8.52]],"ltp":1.21,"tv":7880.44,"id":9634485},{"batb":[[0,6.8,4.43],[1,6.4,197.76],[2,6.2,20.62]],"batl":[[0,7.2,3.83],[1,7.6,189.1],[2,8,17]],"ltp":6.2,"tv":1516.99,"id":9712888}]}]}
{"op":"mcm","clk":"4233774304","pt":1631538686762,"mc":[{"id":"1.187557759","rc":[{"batb":[[2,1.14,210.59]],"batl":[[0,1.18,595.63]],"ltp":1.21,"tv":7880.44,"id":9634485}]}]}
{"op":"mcm","clk":"4233775009","pt":1631538694461,"mc":[{"id":"1.187557759","rc":[{"batb":[[0,1.16,271.1]],"ltp":1.21,"tv":7880.44,"id":9634485},{"batb":[[1,6.4,155.93]],"ltp":6.2,"tv":1516.99,"id":9712888}]}]}
{"op":"mcm","clk":"4233775167","pt":1631538696358,"mc":[{"id":"1.187557759","rc":[{"batb":[[0,1.16,155.1]],"ltp":1.21,"tv":7880.44,"id":9634485}]}]}
{"op":"mcm","clk":"4233775262","pt":1631538697598,"mc":[{"id":"1.187557759","rc":[{"trd":[[1.16,155.1]],"batb":[[0,1.15,406.57],[1,1.14,210.59],[2,1.13,281.01]],"batl":[[0,1.18,374.81]],"ltp":1.16,"tv":8035.54,"id":9634485},{"trd":[[7.2,7.66],[7.4,24.31]],"batb":[[0,7.4,13.69],[1,6.8,4.43],[2,6.4,155.93]],"batl":[[0,7.6,189.1],[1,8,17],[2,8.2,18.5]],"ltp":7.4,"tv":1548.96,"id":9712888}],"tv":9584.51}]}
{"op":"mcm","clk":"4233775289","pt":1631538697871,"mc":[{"id":"1.187557759","rc":[{"batl":[[0,1.18,321.55],[1,1.2,8.52],[2,1.24,88.48]],"ltp":1.16,"tv":8035.54,"id":9634485}]}]}
{"op":"mcm","clk":"4233775437","pt":1631538699482,"mc":[{"id":"1.187557759","rc":[{"trd":[[1.16,242.42]],"batb":[[0,1.17,332.68],[1,1.15,406.57],[2,1.14,210.59]],"ltp":1.16,"tv":8122.86,"id":9634485},{"trd":[[7.4,38]],"batb":[[0,6.8,4.43],[1,6.4,155.93],[2,6.2,20.62]],"ltp":7.4,"tv":1562.65,"id":9712888}],"tv":9685.52}]}
{"op":"mcm","clk":"4233775541","pt":1631538700775,"mc":[{"id":"1.187557759","rc":[{"trd":[[1.17,223.08]],"batb":[[0,1.17,221.14],[1,1.15,454.05],[2,1.14,356.78]],"ltp":1.17,"tv":8345.94,"id":9634485}],"tv":9908.6}]}
{"op":"mcm","clk":"4233775558","pt":1631538701085,"mc":[{"id":"1.187557759","rc":[{"batb":[[1,1.15,406.57],[2,1.14,210.59]],"ltp":1.17,"tv":8345.94,"id":9634485}]}]}
{"op":"mcm","clk":"4233775800","pt":1631538704008,"mc":[{"id":"1.187557759","rc":[{"batb":[[1,1.16,109.38],[2,1.15,406.57]],"batl":[[0,1.18,371.05],[1,1.19,210.9],[2,1.2,8.52]],"ltp":1.17,"tv":8345.94,"id":9634485}]}]}
{"op":"mcm","clk":"4233776116","pt":1631538707713,"mc":[{"id":"1.187557759","rc":[{"batb":[[0,6.4,155.93],[1,6.2,20.62],[2,6,20.62]],"ltp":7.4,"tv":1562.65,"id":9712888}]}]}
{"op":"mcm","clk":"4233776260","pt":1631538709592,"mc":[{"id":"1.187557759","rc":[{"batl":[[0,7.6,190]],"ltp":7.4,"tv":1562.65,"id":9712888}]}]}
{"op":"mcm","clk":"4233776341","pt":1631538710588,"mc":[{"id":"1.187557759","rc":[{"trd":[[1.17,301.28]],"batb":[[0,1.17,182.04]],"ltp":1.17,"tv":8424.14,"id":9634485},{"batl":[[0,7.6,197.46]],"ltp":7.4,"tv":1562.65,"id":9712888}],"tv":9986.8}]}
{"op":"mcm","clk":"4233776546","pt":1631538712826,"mc":[{"id":"1.187557759","rc":[{"trd":[[1.18,40]],"batl":[[0,1.18,351.05]],"ltp":1.18,"tv":8464.14,"id":9634485}],"tv":10026.8}]}
{"op":"mcm","clk":"4233776647","pt":1631538713726,"mc":[{"id":"1.187557759","rc":[{"trd":[[1.18,132.44]],"batl":[[0,1.18,304.83]],"ltp":1.18,"tv":8556.58,"id":9634485}],"tv":10119.24}]}
{"op":"mcm","clk":"4233776913","pt":1631538716304,"mc":[{"id":"1.187557759","rc":[{"batb":[[0,1.17,370],[1,1.16,120.63]],"batl":[[1,1.19,221.87]],"ltp":1.18,"tv":8556.58,"id":9634485}]}]}
{"op":"mcm","clk":"4233776992","pt":1631538717132,"mc":[{"id":"1.187557759","rc":[{"batb":[[1,1.16,146.63]],"batl":[[0,1.18,334.45],[1,1.19,247.19]],"ltp":1.18,"tv":8556.58,"id":9634485}]}]}
{"op":"mcm","clk":"4233777573","pt":1631538720726,"mc":[{"id":"1.187557759","rc":[{"batl":[[0,7.6,190]],"ltp":7.4,"tv":1562.65,"id":9712888}]}]}
{"op":"mcm","clk":"4233778228","pt":1631538723739,"mc":[{"id":"1.187557759","rc":[{"batb":[[1,1.14,210.59],[2,1.13,281.01]],"batl":[[0,1.18,40.55],[1,1.2,8.52],[2,1.24,88.48]],"ltp":1.18,"tv":8556.58,"id":9634485},{"batl":[[0,7.2,6.36],[1,7.6,190],[2,8,17]],"ltp":7.4,"tv":1562.65,"id":9712888}]}]}
{"op":"mcm","clk":"4233778713","pt":1631538725823,"mc":[{"id":"1.187557759","rc":[{"batb":[[2,1.13,475.25]],"batl":[[1,1.2,151],[2,1.21,264.71]],"ltp":1.18,"tv":8556.58,"id":9634485}]}]}
{"op":"mcm","clk":"4233779333","pt":1631538729237,"mc":[{"id":"1.187557759","rc":[{"batl":[[1,7.6,189.1]],"ltp":7.4,"tv":1562.65,"id":9712888}]}]}
{"op":"mcm","clk":"4233782737","pt":1631538745746,"mc":[{"id":"1.187557759","rc":[{"batb":[[2,1.13,670.98]],"batl":[[1,1.19,134.5],[2,1.2,279.08]],"ltp":1.18,"tv":8556.58,"id":9634485},{"batb":[[1,6.2,22.64],[2,6,22.66]],"ltp":7.4,"tv":1562.65,"id":9712888}]}]}
{"op":"mcm","clk":"4233783049","pt":1631538747091,"mc":[{"id":"1.187557759","rc":[{"batl":[[2,1.2,279.3]],"ltp":1.18,"tv":8556.58,"id":9634485}]}]}
{"op":"mcm","clk":"4233784628","pt":1631538758582,"mc":[{"id":"1.187557759","rc":[{"batb":[[1,1.13,389.97],[2,1.12,628.83]],"batl":[[0,1.2,270.97],[1,1.21,264.71],[2,1.39,17.79]],"ltp":1.18,"tv":8556.58,"id":9634485},{"batb":[[0,6,2.04],[1,5.3,33.46],[2,1.01,115.38]],"batl":[[0,8.8,2],[1,9.4,2],[2,990,0.01]],"ltp":7.4,"tv":1562.65,"id":9712888}]}]}
{"op":"mcm","clk":"4233784722","pt":1631538759572,"mc":[{"id":"1.187557759","rc":[{"batb":[[0,1.13,194.24],[1,1.12,628.83],[2,1.11,693.65]],"ltp":1.18,"tv":8556.58,"id":9634485},{"batl":[[0,9.4,2],[1,990,0.01],[2,990,0]],"ltp":7.4,"tv":1562.65,"id":9712888}]}]}
{"op":"mcm","clk":"4233784839","pt":1631538760877,"mc":[{"id":"1.187557759","rc":[{"batb":[[0,1.12,209.79],[1,1.11,693.65],[2,1.1,350.12]],"ltp":1.18,"tv":8556.58,"id":9634485}]}]}
{"op":"mcm","clk":"4233784984","pt":1631538762385,"mc":[{"id":"1.187557759","rc":[{"batb":[[1,1.1,350.12],[2,1.01,115.38]],"ltp":1.18,"tv":8556.58,"id":9634485}]}]}
{"op":"mcm","clk":"4233785090","pt":1631538763686,"mc":[{"id":"1.187557759","rc":[{"batb":[[0,1.19,20.03],[1,1.18,741.91],[2,1.17,170.94]],"batl":[[0,1.2,279.3]],"ltp":1.18,"tv":8556.58,"id":9634485},{"batb":[[1,5.7,157.93],[2,5.3,33.46]],"batl":[[0,6.4,23.44],[1,6.6,639.86],[2,6.8,11.72]],"ltp":7.4,"tv":1562.65,"id":9712888}]}]}
{"op":"mcm","clk":"4233785209","pt":1631538764782,"mc":[{"id":"1.187557759","rc":[{"batb":[[1,1.18,1064.5],[2,1.17,434.52]],"batl":[[2,1.22,8.2]],"ltp":1.18,"tv":8556.58,"id":9634485},{"batb":[[2,5.6,26.8]],"batl":[[0,6.4,14.06],[1,6.6,7.03],[2,6.8,7.03]],"ltp":7.4,"tv":1562.65,"id":9712888}]}]}
{"op":"mcm","clk":"4233785228","pt":1631538764994,"mc":[{"id":"1.187557759","rc":[{"batb":[[2,5.6,5.36]],"batl":[[0,6.4,4.68],[1,6.6,2.34],[2,6.8,2.34]],"ltp":7.4,"tv":1562.65,"id":9712888}]}]}
{"op":"mcm","clk":"4233785549","pt":1631538768688,"mc":[{"id":"1.187557759","rc":[{"batl":[[2,1.22,203.21]],"ltp":1.18,"tv":8556.58,"id":9634485},{"batl":[[0,6.4,34.86]],"ltp":7.4,"tv":1562.65,"id":9712888}]}]}
{"op":"mcm","clk":"4233785567","pt":1631538768895,"mc":[{"id":"1.187557759","rc":[{"batl":[[2,1.22,8.2]],"ltp":1.18,"tv":8556.58,"id":9634485},{"batl":[[0,6.4,4.68]],"ltp":7.4,"tv":1562.65,"id":9712888}]}]}
{"op":"mcm","clk":"4233785833","pt":1631538771918,"mc":[{"id":"1.187557759","rc":[{"batl":[[1,1.21,404.21],[2,1.22,116.45]],"ltp":1.18,"tv":8556.58,"id":9634485},{"batb":[[1,5.7,159.95]],"ltp":7.4,"tv":1562.65,"id":9712888}]}]}
{"op":"mcm","clk":"4233786027","pt":1631538774513,"mc":[{"id":"1.187557759","rc":[{"batb":[[0,1.19,205.03]],"ltp":1.18,"tv":8556.58,"id":9634485}]}]}
{"op":"mcm","clk":"4233786607","pt":1631538781027,"mc":[{"id":"1.187557759","rc":[{"batb":[[1,1.18,1015.78]],"ltp":1.18,"tv":8556.58,"id":9634485}]}]}
{"op":"mcm","clk":"4233786754","pt":1631538782738,"mc":[{"id":"1.187557759","rc":[{"batb":[[0,1.19,185],[1,1.16,142.78],[2,1.15,175.03]],"batl":[[0,1.22,108.66],[1,1.39,17.79],[2,3.8,27.46]],"ltp":1.18,"tv":8556.58,"id":9634485},{"batb":[[0,5.5,2.12],[1,5,19.66],[2,1.01,115.38]],"batl":[[0,7.4,2],[1,7.8,2],[2,9.4,2]],"ltp":7.4,"tv":1562.65,"id":9712888}]}]}
{"op":"mcm","clk":"4233786866","pt":1631538783843,"mc":[{"id":"1.187557759","rc":[{"trd":[[1.2,1288.59]],"batb":[[0,1.15,175.03],[1,1.12,498.33],[2,1.01,115.38]],"batl":[[0,1.22,108.25]],"ltp":1.2,"tv":8556.99,"id":9634485},{"trd":[[6,0.08]],"batl":[[0,7.8,2.32],[1,9.4,2],[2,990,0.01]],"ltp":6.0,"tv":1562.73,"id":9712888}],"tv":10119.72}]}
{"op":"mcm","clk":"4233786999","pt":1631538785340,"mc":[{"id":"1.187557759","rc":[{"batb":[[0,1.15,552.58],[1,1.14,223.36],[2,1.12,498.33]],"batl":[[1,1.23,267.89],[2,1.24,222.86]],"ltp":1.2,"tv":8556.99,"id":9634485}]}]}
{"op":"mcm","clk":"4233787133","pt":1631538786845,"mc":[{"id":"1.187557759","rc":[{"batb":[[0,1.16,154.03],[1,1.15,552.58],[2,1.14,223.36]],"ltp":1.2,"tv":8556.99,"id":9634485},{"batl":[[0,7.4,2.32],[1,7.8,2],[2,9.4,2]],"ltp":6.0,"tv":1562.73,"id":9712888}]}]}
{"op":"mcm","clk":"4233787164","pt":1631538787156,"mc":[{"id":"1.187557759","rc":[{"batb":[[0,1.15,552.58],[1,1.14,223.36],[2,1.12,498.33]],"ltp":1.2,"tv":8556.99,"id":9634485},{"batl":[[0,7.8,2.32],[1,9.4,2],[2,990,0.01]],"ltp":6.0,"tv":1562.73,"id":9712888}]}]}
{"op":"mcm","clk":"4233787515","pt":1631538791359,"mc":[{"id":"1.187557759","rc":[{"batl":[[1,1.39,17.79],[2,3.8,27.46]],"ltp":1.2,"tv":8556.99,"id":9634485}]}]}
{"op":"mcm","clk":"4233787766","pt":1631538793755,"mc":[{"id":"1.187557759","rc":[{"batb":[[0,1.16,178.03],[1,1.15,552.58],[2,1.14,223.36]],"batl":[[0,1.21,125.5],[1,1.22,108.25],[2,1.39,17.79]],"ltp":1.2,"tv":8556.99,"id":9634485},{"batb":[[0,5.7,2.02],[1,5.5,2.12],[2,5,19.66]],"batl":[[0,7.4,2.32],[1,7.8,2],[2,9.4,2]],"ltp":6.0,"tv":1562.73,"id":9712888}]}]}
{"op":"mcm","clk":"4233787861","pt":1631538794751,"mc":[{"id":"1.187557759","rc":[{"trd":[[1.2,1290.19]],"batb":[[0,1.15,602.57],[1,1.14,223.36],[2,1.13,25.44]],"batl":[[0,1.17,439.54],[1,1.18,315.28],[2,1.2,8.33]],"ltp":1.2,"tv":8558.59,"id":9634485},{"trd":[[6,0.4]],"batb":[[0,6.6,20.62],[1,6.4,218.29],[2,6.2,20]],"batl":[[0,7.6,122.94],[2,8.4,16.18]],"ltp":6.0,"tv":1563.05,"id":9712888}],"tv":10121.64}]}
{"op":"mcm","clk":"4233787895","pt":1631538795164,"mc":[{"id":"1.187557759","rc":[{"batb":[[1,1.14,232.13]],"ltp":1.2,"tv":8558.59,"id":9634485}]}]}
{"op":"mcm","clk":"4233788013","pt":1631538796571,"mc":[{"id":"1.187557759","rc":[{"batl":[[2,1.2,105.33]],"ltp":1.2,"tv":8558.59,"id":9634485}]}]}
{"op":"mcm","clk":"4233788356","pt":1631538800278,"mc":[{"id":"1.187557759","rc":[{"batb":[[0,1.16,280],[1,1.15,602.57],[2,1.14,232.13]],"ltp":1.2,"tv":8558.59,"id":9634485}]}]}
{"op":"mcm","clk":"4233788420","pt":1631538800955,"mc":[{"id":"1.187557759","rc":[{"batl":[[2,1.19,151.5]],"ltp":1.2,"tv":8558.59,"id":9634485},{"batb":[[2,6.2,22]],"ltp":6.0,"tv":1563.05,"id":9712888}]}]}
{"op":"mcm","clk":"4233788695","pt":1631538803857,"mc":[{"id":"1.187557759","rc":[{"batl":[[2,1.19,276.5]],"ltp":1.2,"tv":8558.59,"id":9634485}]}]}
{"op":"mcm","clk":"4233788898","pt":1631538806185,"mc":[{"id":"1.187557759","rc":[{"batl":[[0,1.17,190.85]],"ltp":1.2,"tv":8558.59,"id":9634485}]}]}
{"op":"mcm","clk":"4233789058","pt":1631538808094,"mc":[{"id":"1.187557759","rc":[{"trd":[[1.17,302.18]],"batl":[[0,1.17,189.95]],"ltp":1.17,"tv":8559.49,"id":9634485},{"trd":[[6.8,0.15]],"ltp":6.8,"tv":1563.21,"id":9712888}],"tv":10122.7}]}
{"op":"mcm","clk":"4233789299","pt":1631538810799,"mc":[{"id":"1.187557759","rc":[{"batb":[[1,1.15,225.02],[2,1.13,25.44]],"batl":[[0,1.19,276.5],[1,1.2,216.93],[2,1.22,108.25]],"ltp":1.17,"tv":8559.49,"id":9634485},{"batb":[[0,6.2,2],[1,6,26.43],[2,5.5,2.12]],"batl":[[0,7.8,2],[1,9.4,2],[2,11,2]],"ltp":6.8,"tv":1563.21,"id":9712888}]}]}
{"op":"mcm","clk":"4233789391","pt":1631538811795,"mc":[{"id":"1.187557759","rc":[{"batb":[[0,1.1,273.74],[1,1.09,369.78],[2,1.01,115.38]],"batl":[[0,1.19,125]],"ltp":1.17,"tv":8559.49,"id":9634485},{"batb":[[0,6,2],[1,5.5,2.12],[2,5.3,33.3]],"batl":[[0,11,2.04],[1,990,0.01],[2,11,0]],"ltp":6.8,"tv":1563.21,"id":9712888}]}]}
{"op":"mcm","clk":"4233789559","pt":1631538813712,"mc":[{"id":"1.187557759","rc":[{"batb":[[0,1.12,293.48],[1,1.11,324.43],[2,1.1,273.74]],"batl":[[1,1.2,386.19],[2,1.21,263.85]],"ltp":1.17,"tv":8559.49,"id":9634485}]}]}
{"op":"mcm","clk":"4233789669","pt":1631538814802,"mc":[{"id":"1.187557759","rc":[{"batb":[[0,1.1,273.74],[1,1.09,369.78],[2,1.01,115.38]],"batl":[[0,1.19,125.5],[1,1.2,289.19]],"ltp":1.17,"tv":8559.49,"id":9634485},{"batb":[[0,6.2,2],[1,6,2],[2,5.5,2.12]],"ltp":6.8,"tv":1563.21,"id":9712888}]}]}
{"op":"mcm","clk":"4233789747","pt":1631538815784,"mc":[{"id":"1.187557759","rc":[{"batb":[[0,1.19,17.49],[1,1.18,263.99],[2,1.17,342.01]],"batl":[[0,1.2,298.72],[1,1.21,263.85],[2,1.22,108.25]],"ltp":1.17,"tv":8559.49,"id":9634485},{"batb":[[0,6,2],[1,5.7,166.83]],"batl":[[0,6.6,24.72],[1,6.8,11.4],[2,7,11.36]],"ltp":6.8,"tv":1563.21,"id":9712888}]}]}
{"op":"mcm","clk":"4233789863","pt":1631538816842,"mc":[{"id":"1.187557759","rc":[{"batb":[[1,1.18,312.71]],"batl":[[2,1.22,116.45]],"ltp":1.17,"tv":8559.49,"id":9634485},{"batb":[[1,5.8,5.18],[2,5.7,169.41]],"batl":[[0,6.6,15.63],[1,6.8,7.76],[2,7,6.82]],"ltp":6.8,"tv":1563.21,"id":9712888}]}]}
{"op":"mcm","clk":"4233790049","pt":1631538818226,"mc":[{"id":"1.187557759","rc":[{"batb":[[0,1.18,312.71],[1,1.17,342.01],[2,1.16,33.4]],"batl":[[0,1.2,289.19]],"ltp":1.17,"tv":8559.49,"id":9634485}]}]}
{"op":"mcm","clk":"4233790203","pt":1631538819186,"mc":[{"id":"1.187557759","rc":[{"batl":[[1,1.21,388.85]],"ltp":1.17,"tv":8559.49,"id":9634485}]}]}
{"op":"mcm","clk":"4233790381","pt":1631538820720,"mc":[{"id":"1.187557759","rc":[{"batl":[[2,1.22,315.11]],"ltp":1.17,"tv":8559.49,"id":9634485},{"batl":[[0,6.4,28.55],[1,6.6,15.63],[2,6.8,7.76]],"ltp":6.8,"tv":1563.21,"id":9712888}]}]}
{"op":"mcm","clk":"4233790480","pt":1631538821517,"mc":[{"id":"1.187557759","rc":[{"batb":[[0,1.19,17.49],[1,1.18,312.71],[2,1.17,342.01]],"batl":[[0,1.2,298.72],[2,1.22,116.45]],"ltp":1.17,"tv":8559.49,"id":9634485},{"batl":[[0,6.6,15.63],[1,6.8,7.76],[2,7,6.82]],"ltp":6.8,"tv":1563.21,"id":9712888}]}]}
{"op":"mcm","clk":"4233790626","pt":1631538822421,"mc":[{"id":"1.187557759","rc":[{"batb":[[1,1.18,405.71]],"ltp":1.17,"tv":8559.49,"id":9634485}]}]}
{"op":"mcm","clk":"4233790688","pt":1631538822999,"mc":[{"id":"1.187557759","rc":[{"batl":[[1,1.21,509.35]],"ltp":1.17,"tv":8559.49,"id":9634485},{"batb":[[2,5.7,171.43]],"ltp":6.8,"tv":1563.21,"id":9712888}]}]}
{"op":"mcm","clk":"4233790832","pt":1631538824513,"mc":[{"id":"1.187557759","rc":[{"batl":[[1,6.8,6.86]],"ltp":6.8,"tv":1563.21,"id":9712888}]}]}
{"op":"mcm","clk":"4233790912","pt":1631538825402,"mc":[{"id":"1.187557759","rc":[{"batb":[[1,1.18,312.71]],"ltp":1.17,"tv":8559.49,"id":9634485}]}]}
{"op":"mcm","clk":"4233791121","pt":1631538827795,"mc":[{"id":"1.187557759","rc":[{"batb":[[0,1.18,263.99],[1,1.17,342.01],[2,1.16,138.28]],"batl":[[0,1.2,289.19],[2,1.22,108.25]],"ltp":1.17,"tv":8559.49,"id":9634485},{"batb":[[1,5.7,2.02],[2,5.5,2.12]],"batl":[[0,6.6,2],[1,7.4,2.04],[2,7.8,2]],"ltp":6.8,"tv":1563.21,"id":9712888}]}]}
{"op":"mcm","clk":"4233791238","pt":1631538828733,"mc":[{"id":"1.187557759","rc":[{"batb":[[0,1.15,152.83],[1,1.12,297.08],[2,1.1,273.74]],"batl":[[0,1.21,125],[1,1.22,108.25],[2,1.23,97]],"ltp":1.17,"tv":8559.49,"id":9634485},{"batb":[[0,5.5,2.12],[1,4.9,20.5],[2,1.01,115.38]],"batl":[[0,7.8,2.04],[1,11,2],[2,990,0.01]],"ltp":6.8,"tv":1563.21,"id":9712888}]}]}
{"op":"mcm","clk":"4233791557","pt":1631538831714,"mc":[{"id":"1.187557759","rc":[{"batb":[[0,1.15,354.63],[1,1.14,400.65],[2,1.12,297.08]],"batl":[[2,1.23,311.77]],"ltp":1.17,"tv":8559.49,"id":9634485}]}]}
{"op":"mcm","clk":"4233792259","pt":1631538838546,"mc":[{"id":"1.187557759","rc":[{"batb":[[0,1.16,164.28],[1,1.15,354.63],[2,1.14,400.65]],"batl":[[0,1.21,252.5]],"ltp":1.17,"tv":8559.49,"id":9634485},{"batb":[[0,5.7,2],[1,5.5,2.12],[2,4.9,20.5]],"batl":[[0,7.4,2.04],[1,7.8,2],[2,11,2]],"ltp":6.8,"tv":1563.21,"id":9712888}]}]}
{"op":"mcm","clk":"4233792286","pt":1631538838859,"mc":[{"id":"1.187557759","rc":[{"batb":[[0,1.15,354.63],[1,1.14,400.65],[2,1.12,297.08]],"batl":[[0,1.21,125]],"ltp":1.17,"tv":8559.49,"id":9634485},{"batb":[[0,5.5,2.12],[1,4.9,20.5],[2,1.01,115.38]],"batl":[[0,7.8,2.04],[1,11,2],[2,990,0.01]],"ltp":6.8,"tv":1563.21,"id":9712888}]}]}
{"op":"mcm","clk":"4233792520","pt":1631538841209,"mc":[{"id":"1.187557759","rc":[{"batb":[[0,1.15,152.83],[1,1.12,297.08],[2,1.1,273.74]],"ltp":1.17,"tv":8559.49,"id":9634485}]}]}
{"op":"mcm","clk":"4233792618","pt":1631538842364,"mc":[{"id":"1.187557759","rc":[{"batl":[[0,1.22,108.25],[1,1.23,311.77],[2,1.24,224.31]],"ltp":1.17,"tv":8559.49,"id":9634485}]}]}
{"op":"mcm","clk":"4233792908","pt":1631538844841,"mc":[{"id":"1.187557759","rc":[{"batb":[[0,1.21,99.81],[1,1.2,1203.02],[2,1.18,32.83]],"batl":[[1,1.23,335.54],[2,1.24,874.05]],"ltp":1.17,"tv":8559.49,"id":9634485},{"batb":[[1,5.1,26.66],[2,5,25.88]],"batl":[[0,5.7,6.54],[1,6,132.55],[2,6.2,22]],"ltp":6.8,"tv":1563.21,"id":9712888}]}]}
{"op":"mcm","clk":"4233793500","pt":1631538850774,"mc":[{"id":"1.187557759","rc":[{"batb":[[2,1.18,156.19]],"batl":[[1,1.23,447.04],[2,1.24,981.53]],"ltp":1.17,"tv":8559.49,"id":9634485},{"batb":[[1,5.3,2.08],[2,5.1,28.7]],"ltp":6.8,"tv":1563.21,"id":9712888}]}]}
{"op":"mcm","clk":"4233793640","pt":1631538852336,"mc":[{"id":"1.187557759","rc":[{"batb":[[0,1.21,261.81]],"ltp":1.17,"tv":8559.49,"id":9634485}]}]}
{"op":"mcm","clk":"4233794025","pt":1631538855986,"mc":[{"id":"1.187557759","rc":[{"batb":[[1,1.2,895.78]],"ltp":1.17,"tv":8559.49,"id":9634485}]}]}
{"op":"mcm","clk":"4233794349","pt":1631538858466,"mc":[{"id":"1.187557759","rc":[{"batb":[[0,1.21,162],[1,1.18,123.36],[2,1.16,165.78]],"batl":[[0,1.23,97],[1,1.24,107.48],[2,3.8,27.46]],"ltp":1.17,"tv":8559.49,"id":9634485},{"batb":[[0,5.1,2.04],[1,4.6,23.93],[2,1.01,115.38]],"batl":[[0,6.6,2],[1,7.4,2],[2,7.8,2]],"ltp":6.8,"tv":1563.21,"id":9712888}]}]}
{"op":"mcm","clk":"4233794460","pt":1631538859566,"mc":[{"id":"1.187557759","rc":[{"batb":[[0,1.16,165.78],[1,1.15,388.08],[2,1.1,273.74]],"ltp":1.17,"tv":8559.49,"id":9634485},{"batl":[[0,7.4,2],[1,7.8,2],[2,11,2]],"ltp":6.8,"tv":1563.21,"id":9712888}]}]}
{"op":"mcm","clk":"4233794674","pt":1631538861650,"mc":[{"id":"1.187557759","rc":[{"batl":[[0,1.23,204.5]],"ltp":1.17,"tv":8559.49,"id":9634485},{"batb":[[0,5.3,2.28],[1,5.1,2.04],[2,4.6,23.93]],"ltp":6.8,"tv":1563.21,"id":9712888}]}]}
{"op":"mcm","clk":"4233794786","pt":1631538862796,"mc":[{"id":"1.187557759","rc":[{"batb":[[0,1.18,149.36],[1,1.17,165.97],[2,1.16,165.78]],"batl":[[0,1.23,97],[1,1.24,648.43]],"ltp":1.17,"tv":8559.49,"id":9634485},{"batb":[[0,5.1,2.04],[1,4.6,23.93],[2,1.01,115.38]],"batl":[[0,6.6,2],[1,7.4,2],[2,7.8,2]],"ltp":6.8,"tv":1563.21,"id":9712888}]}]}
{"op":"mcm","clk":"4233794843","pt":1631538863366,"mc":[{"id":"1.187557759","rc":[{"batb":[[0,1.2,254.42],[1,1.19,313.22]],"batl":[[0,1.22,98.55],[1,1.23,336.17],[2,1.24,107.48]],"ltp":1.17,"tv":8559.49,"id":9634485},{"batl":[[0,7.4,2],[1,7.8,2],[2,11,2]],"ltp":6.8,"tv":1563.21,"id":9712888}]}]}
{"op":"mcm","clk":"4233795026","pt":1631538865186,"mc":[{"id":"1.187557759","rc":[{"batl":[[1,1.23,458.67]],"ltp":1.17,"tv":8559.49,"id":9634485},{"batb":[[0,5.3,2.08],[1,5.1,2.04],[2,4.6,23.93]],"ltp":6.8,"tv":1563.21,"id":9712888}]}]}
{"op":"mcm","clk":"4233795132","pt":1631538866279,"mc":[{"id":"1.187557759","rc":[{"batb":[[2,1.18,140.36]],"ltp":1.17,"tv":8559.49,"id":9634485},{"batl":[[0,6.6,2.01],[1,7.4,2],[2,7.8,2]],"ltp":6.8,"tv":1563.21,"id":9712888}]}]}
{"op":"mcm","clk":"4233795327","pt":1631538868576,"mc":[{"id":"1.187557759","rc":[{"batb":[[0,1.18,140.36],[1,1.16,165.78],[2,1.15,388.08]],"batl":[[0,1.23,219.5],[1,1.24,107.48],[2,1.26,108]],"ltp":1.17,"tv":8559.49,"id":9634485}]}]}
{"op":"mcm","clk":"4233795421","pt":1631538869511,"mc":[{"id":"1.187557759","rc":[{"batb":[[0,1.2,84]],"batl":[[0,1.23,97]],"ltp":1.17,"tv":8559.49,"id":9634485},{"batb":[[0,5.1,2.04],[1,4.6,23.93],[2,1.01,115.38]],"batl":[[0,7.4,2],[1,7.8,2],[2,11,2]],"ltp":6.8,"tv":1563.21,"id":9712888}]}]}
{"op":"mcm","clk":"4233795474","pt":1631538869987,"mc":[{"id":"1.187557759","rc":[{"batb":[[0,1.16,165.78],[1,1.15,388.08],[2,1.1,273.74]],"ltp":1.17,"tv":8559.49,"id":9634485}]}]}
{"op":"mcm","clk":"4233795640","pt":1631538871705,"mc":[{"id":"1.187557759","rc":[{"trd":[[1.23,0.4]],"batb":[[0,1.18,326.14],[1,1.17,259.8],[2,1.16,165.78]],"batl":[[0,1.23,96.6],[2,1.25,214.61]],"ltp":1.23,"tv":8559.89,"id":9634485},{"trd":[[5.3,0.09]],"ltp":5.3,"tv":1563.3,"id":9712888}],"tv":10123.19}]}
{"op":"mcm","clk":"4233795706","pt":1631538872284,"mc":[{"id":"1.187557759","rc":[{"batb":[[0,1.18,454],[1,1.17,417.77]],"batl":[[2,1.26,108]],"ltp":1.23,"tv":8559.89,"id":9634485},{"batl":[[0,6.6,2],[1,7.4,2],[2,7.8,2]],"ltp":5.3,"tv":1563.3,"id":9712888}]}]}
{"op":"mcm","clk":"4233795765","pt":1631538872909,"mc":[{"id":"1.187557759","rc":[{"batl":[[0,1.21,212.91],[1,1.23,96.6],[2,1.24,107.48]],"ltp":1.23,"tv":8559.89,"id":9634485}]}]}
{"op":"mcm","clk":"4233796046","pt":1631538875716,"mc":[{"id":"1.187557759","rc":[{"batb":[[0,1.18,1416.91],[2,1.16,190.56]],"batl":[[0,1.2,308.25],[1,1.21,521.46],[2,1.22,8.2]],"ltp":1.23,"tv":8559.89,"id":9634485},{"batb":[[0,5.9,23.04],[1,5.8,22.36],[2,5.7,154.95]],"batl":[[0,6.2,3.72],[1,6.6,2],[2,7.2,18.88]],"ltp":5.3,"tv":1563.3,"id":9712888}]}]}
{"op":"mcm","clk":"4233796115","pt":1631538876402,"mc":[{"id":"1.187557759","rc":[{"batb":[[2,1.16,199.18]],"ltp":1.23,"tv":8559.89,"id":9634485}]}]}
{"op":"mcm","clk":"4233796498","pt":1631538880293,"mc":[{"id":"1.187557759","rc":[{"batb":[[0,1.19,191],[1,1.18,1416.91],[2,1.17,417.77]],"ltp":1.23,"tv":8559.89,"id":9634485}]}]}
{"op":"mcm","clk":"4233797081","pt":1631538887201,"mc":[{"id":"1.187557759","rc":[{"batl":[[0,1.2,94.79]],"ltp":1.23,"tv":8559.89,"id":9634485}]}]}
{"op":"mcm","clk":"4233797534","pt":1631538892340,"mc":[{"id":"1.187557759","rc":[{"batb":[[1,1.18,1368.19]],"ltp":1.23,"tv":8559.89,"id":9634485}]}]}
{"op":"mcm","clk":"4233797849","pt":1631538895664,"mc":[{"id":"1.187557759","rc":[{"batb":[[1,1.16,165.78],[2,1.15,152.83]],"batl":[[0,1.21,212.91],[1,1.23,193.1],[2,1.24,107.48]],"ltp":1.23,"tv":8559.89,"id":9634485},{"batb":[[0,5.3,2.08],[1,5.1,2.04],[2,4.8,21.08]],"batl":[[0,7.4,2],[1,7.8,2],[2,8.2,2]],"ltp":5.3,"tv":1563.3,"id":9712888}]}]}
{"op":"mcm","clk":"4233797923","pt":1631538896447,"mc":[{"id":"1.187557759","rc":[{"batb":[[0,1.16,165.78],[1,1.15,152.83],[2,1.14,196.32]],"ltp":1.23,"tv":8559.89,"id":9634485}]}]}
{"op":"mcm","clk":"4233797968","pt":1631538896853,"mc":[{"id":"1.187557759","rc":[{"batb":[[0,1.14,196.32],[1,1.12,300.76],[2,1.1,273.74]],"ltp":1.23,"tv":8559.89,"id":9634485},{"batl":[[0,8.2,2],[1,11,2],[2,990,0.01]],"ltp":5.3,"tv":1563.3,"id":9712888}]}]}
{"op":"mcm","clk":"4233798120","pt":1631538898267,"mc":[{"id":"1.187557759","rc":[{"batb":[[0,1.15,112.58],[1,1.14,634.26],[2,1.12,300.76]],"batl":[[2,1.24,376.23]],"ltp":1.23,"tv":8559.89,"id":9634485}]}]}
{"op":"mcm","clk":"4233798298","pt":1631538899829,"mc":[{"id":"1.187557759","rc":[{"batb":[[0,1.2,210.52],[1,1.15,112.58],[2,1.14,634.26]],"batl":[[2,1.24,107.48]],"ltp":1.23,"tv":8559.89,"id":9634485}]}]}
{"op":"mcm","clk":"4233798385","pt":1631538900760,"mc":[{"id":"1.187557759","rc":[{"batb":[[0,1.2,210.71],[1,1.16,151.28],[2,1.15,277.21]],"ltp":1.23,"tv":8559.89,"id":9634485},{"batl":[[0,7.4,2],[1,8.2,2],[2,11,2]],"ltp":5.3,"tv":1563.3,"id":9712888}]}]}
{"op":"mcm","clk":"4233798579","pt":1631538902655,"mc":[{"id":"1.187557759","rc":[{"trd":[[1.2,1711.61]],"batb":[[0,1.16,151.28],[1,1.15,277.21],[2,1.14,634.26]],"batl":[[0,1.17,2870.74],[1,1.18,1161.11],[2,1.19,8.4]],"ltp":1.2,"tv":8981.3,"id":9634485},{"batb":[[0,6.6,41.22],[1,6.4,40],[2,6.2,40]],"batl":[[1,7.6,5.85],[2,8,151.29]],"ltp":5.3,"tv":1563.3,"id":9712888}],"tv":10544.61}]}
{"op":"mcm","clk":"4233798711","pt":1631538903755,"mc":[{"id":"1.187557759","rc":[{"batb":[[0,1.15,112.58],[1,1.14,684.69],[2,1.13,8.85]],"batl":[[0,1.17,696.27],[1,1.18,1338.24]],"ltp":1.2,"tv":8981.3,"id":9634485},{"batb":[[0,6.6,20.62],[1,6.4,20],[2,6.2,42.84]],"batl":[[0,7.6,5.85],[1,8,151.29],[2,8.2,2]],"ltp":5.3,"tv":1563.3,"id":9712888}]}]}
{"op":"mcm","clk":"4233799104","pt":1631538907651,"mc":[{"id":"1.187557759","rc":[{"batl":[[2,1.19,275.11]],"ltp":1.2,"tv":8981.3,"id":9634485},{"batl":[[0,7.4,22.29],[1,7.6,5.85],[2,8,151.29]],"ltp":5.3,"tv":1563.3,"id":9712888}]}]}
{"op":"mcm","clk":"4233799128","pt":1631538907875,"mc":[{"id":"1.187557759","rc":[{"batl":[[2,1.19,8.4]],"ltp":1.2,"tv":8981.3,"id":9634485},{"batl":[[0,7.6,5.85],[1,8,151.29],[2,8.2,2]],"ltp":5.3,"tv":1563.3,"id":9712888}]}]}
{"op":"mcm","clk":"4233799406","pt":1631538910978,"mc":[{"id":"1.187557759","rc":[{"batb":[[0,1.15,248.58]],"ltp":1.2,"tv":8981.3,"id":9634485}]}]}
{"op":"mcm","clk":"4233799548","pt":1631538912491,"mc":[{"id":"1.187557759","rc":[{"trd":[[1.17,302.4]],"batl":[[0,1.17,696.05]],"ltp":1.17,"tv":8981.52,"id":9634485},{"trd":[[6.8,0.19]],"ltp":6.8,"tv":1563.34,"id":9712888}],"tv":10544.86}]}
{"op":"mcm","clk":"4233799783","pt":1631538914680,"mc":[{"id":"1.187557759","rc":[{"batl":[[0,1.17,455.71]],"ltp":1.17,"tv":8981.52,"id":9634485}]}]}
{"op":"mcm","clk":"4233800188","pt":1631538918784,"mc":[{"id":"1.187557759","rc":[{"batb":[[0,1.15,136],[1,1.14,246.75],[2,1.12,326.42]],"batl":[[0,1.2,225.38],[1,1.21,338.41],[2,1.23,193.1]],"ltp":1.17,"tv":8981.52,"id":9634485},{"batb":[[0,6.2,22.84],[1,6,2.04],[2,5.7,2.12]],"batl":[[0,8.2,2],[1,10.5,2],[2,11,2]],"ltp":6.8,"tv":1563.34,"id":9712888}]}]}
{"op":"mcm","clk":"4233800271","pt":1631538919562,"mc":[{"id":"1.187557759","rc":[{"batb":[[0,1.09,243.61],[1,1.08,415.7],[2,1.01,115.38]],"batl":[[0,1.2,108]],"ltp":1.17,"tv":8981.52,"id":9634485},{"batb":[[0,5.7,2.12],[1,5.3,35.46],[2,5.1,2.04]],"batl":[[0,12.5,2],[1,990,0.01],[2,11,0]],"ltp":6.8,"tv":1563.34,"id":9712888}]}]}
{"op":"mcm","clk":"4233800469","pt":1631538921796,"mc":[{"id":"1.187557759","rc":[{"batb":[[0,1.11,94.54],[1,1.1,530.8],[2,1.09,243.61]],"batl":[[0,1.2,266.65],[1,1.21,602.68]],"ltp":1.17,"tv":8981.52,"id":9634485},{"batl":[[0,12.5,2.09]],"ltp":6.8,"tv":1563.34,"id":9712888}]}]}
{"op":"mcm","clk":"4233800567","pt":1631538922788,"mc":[{"id":"1.187557759","rc":[{"batb":[[0,1.11,201.59],[1,1.1,261.14]],"batl":[[0,1.2,241.13],[1,1.21,338.41]],"ltp":1.17,"tv":8981.52,"id":9634485},{"batb":[[0,6,2],[1,5.7,2.12],[2,5.3,35.46]],"batl":[[0,10.5,2.09],[1,12.5,2],[2,990,0.01]],"ltp":6.8,"tv":1563.34,"id":9712888}]}]}
{"op":"mcm","clk":"4233800643","pt":1631538923481,"mc":[{"id":"1.187557759","rc":[{"trd":[[1.17,302.94]],"batb":[[0,1.14,187.8],[1,1.13,420.11]],"batl":[[0,1.16,393.07],[1,1.17,198.48],[2,1.2,108]],"ltp":1.17,"tv":8982.06,"id":9634485},{"trd":[[6.8,0.28]],"batb":[[0,5.7,2.12],[1,5.3,35.46],[2,5.1,2.04]],"batl":[[0,12.5,2],[1,990,0.01],[2,990,0]],"ltp":6.8,"tv":1563.43,"id":9712888}],"tv":10545.5}]}
{"op":"mcm","clk":"4233800965","pt":1631538926698,"mc":[{"id":"1.187557759","rc":[{"batb":[[0,1.09,243.61],[1,1.08,415.7],[2,1.01,115.38]],"batl":[[0,1.2,108],[1,1.21,338.41],[2,1.23,193.1]],"ltp":1.17,"tv":8982.06,"id":9634485}]}]}
{"op":"mcm","clk":"4233801246","pt":1631538929519,"mc":[{"id":"1.187557759","rc":[{"batb":[[0,1.11,94.86],[1,1.1,530.48],[2,1.09,243.61]],"batl":[[2,1.23,96.6]],"ltp":1.17,"tv":8982.06,"id":9634485},{"batb":[[1,5.3,33.38],[2,1.01,115.38]],"ltp":6.8,"tv":1563.43,"id":9712888}]}]}
{"op":"mcm","clk":"4233801376","pt":1631538930725,"mc":[{"id":"1.187557759","rc":[{"batb":[[1,1.1,803.92]],"ltp":1.17,"tv":8982.06,"id":9634485}]}]}
{"op":"mcm","clk":"4233801502","pt":1631538931797,"mc":[{"id":"1.187557759","rc":[{"batb":[[1,1.1,1785.52]],"batl":[[0,1.12,226.1],[1,1.13,385.47],[2,1.14,1760.59]],"ltp":1.17,"tv":8982.06,"id":9634485},{"batb":[[0,8.4,17.86],[1,8.2,33.32],[2,8,8.92]],"batl":[[0,10,5.24],[1,11,92.93],[2,12.5,2]],"ltp":6.8,"tv":1563.43,"id":9712888}]}]}
{"op":"mcm","clk":"4233801616","pt":1631538932693,"mc":[{"id":"1.187557759","rc":[{"batb":[[1,1.1,1794.61]],"ltp":1.17,"tv":8982.06,"id":9634485},{"batb":[[0,8.4,3.58],[1,8.2,26.18],[2,8,1.78]],"batl":[[1,10.5,14.28],[2,11,100.07]],"ltp":6.8,"tv":1563.43,"id":9712888}]}]}
{"op":"mcm","clk":"4233801643","pt":1631538932907,"mc":[{"id":"1.187557759","rc":[{"batl":[[1,10.5,2.86],[2,11,94.35]],"ltp":6.8,"tv":1563.43,"id":9712888}]}]}
{"op":"mcm","clk":"4233802505","pt":1631538939822,"mc":[{"id":"1.187557759","rc":[{"batb":[[0,1.11,239.86],[1,1.1,1757.93]],"batl":[[0,1.12,190.1]],"ltp":1.17,"tv":8982.06,"id":9634485}]}]}
{"op":"mcm","clk":"4233802806","pt":1631538942714,"mc":[{"id":"1.187557759","rc":[{"batb":[[0,1.11,276.2]],"batl":[[1,1.13,421.15]],"ltp":1.17,"tv":8982.06,"id":9634485}]}]}
{"op":"mcm","clk":"4233803141","pt":1631538945849,"mc":[{"id":"1.187557759","rc":[{"trd":[[10,10]],"batl":[[0,10.5,3.1],[1,11,94.35],[2,11.5,1.42]],"ltp":10.0,"tv":1573.43,"id":9712888}],"tv":10555.5}]}
{"op":"mcm","clk":"4233803226","pt":1631538946630,"mc":[{"id":"1.187557759","rc":[{"batb":[[1,1.1,1742.36]],"batl":[[0,1.12,174.82]],"ltp":1.17,"tv":8982.06,"id":9634485}]}]}
{"op":"mcm","clk":"4233803261","pt":1631538947046,"mc":[{"id":"1.187557759","rc":[{"trd":[[1.11,4]],"batb":[[0,1.11,274.2]],"ltp":1.11,"tv":8986.06,"id":9634485}],"tv":10559.5}]}
{"op":"mcm","clk":"4233803430","pt":1631538948626,"mc":[{"id":"1.187557759","rc":[{"trd":[[1.12,7.94]],"batl":[[0,1.12,170.85]],"ltp":1.12,"tv":8994.0,"id":9634485}],"tv":10567.44}]}
{"op":"mcm","clk":"4233803541","pt":1631538949523,"mc":[{"id":"1.187557759","rc":[{"batb":[[0,1.11,289.63],[1,1.1,1690.1]],"batl":[[1,1.13,436.3]],"ltp":1.12,"tv":8994.0,"id":9634485}]}]}
{"op":"mcm","clk":"4233803977","pt":1631538954145,"mc":[{"id":"1.187557759","rc":[{"trd":[[1.12,15.33]],"batl":[[0,1.12,163.46]],"ltp":1.12,"tv":9001.39,"id":9634485},{"trd":[[9.2,0.9]],"ltp":9.2,"tv":1574.33,"id":9712888}],"tv":10575.73}]}
{"op":"mcm","clk":"4233804244","pt":1631538956439,"mc":[{"id":"1.187557759","rc":[{"trd":[[1.11,4.16],[1.12,15.71]],"batb":[[0,1.11,289.55]],"batl":[[0,1.12,163.27]],"ltp":1.11,"tv":9001.93,"id":9634485},{"batl":[[0,10.5,2.86]],"ltp":9.2,"tv":1574.33,"id":9712888}],"tv":10576.26}]}
{"op":"mcm","clk":"4233804504","pt":1631538958958,"mc":[{"id":"1.187557759","rc":[{"batb":[[1,1.1,1736.03]],"batl":[[0,1.12,220.88]],"ltp":1.11,"tv":9001.93,"id":9634485},{"batl":[[1,11,98.94]],"ltp":9.2,"tv":1574.33,"id":9712888}]}]}
{"op":"mcm","clk":"4233805554","pt":1631538966477,"mc":[{"id":"1.187557759","rc":[{"batb":[[1,1.1,1715.51]],"ltp":1.11,"tv":9001.93,"id":9634485}]}]}
{"op":"mcm","clk":"4233806021","pt":1631538969712,"mc":[{"id":"1.187557759","rc":[{"trd":[[1.12,16.45]],"batb":[[0,1.11,145],[1,1.1,1257.8]],"batl":[[0,1.12,57.24],[1,1.14,1760.59],[2,1.15,8.7]],"ltp":1.12,"tv":9002.67,"id":9634485}],"tv":10577.0}]}
{"op":"mcm","clk":"4233806129","pt":1631538970395,"mc":[{"id":"1.187557759","rc":[{"batb":[[0,1.07,906.17],[1,1.06,378.58],[2,1.04,1266.91]],"batl":[[0,1.17,127],[1,1.18,137.25],[2,1.19,147.5]],"ltp":1.12,"tv":9002.67,"id":9634485},{"batb":[[0,6.2,2],[1,6,23.26],[2,5.7,2.12]],"batl":[[0,18,2],[1,26,2],[2,990,0.01]],"ltp":9.2,"tv":1574.33,"id":9712888}]}]}
{"op":"mcm","clk":"4233806332","pt":1631538971819,"mc":[{"id":"1.187557759","rc":[{"batb":[[1,1.06,1028.41]],"batl":[[0,1.17,527.91],[1,1.18,323.48]],"ltp":1.12,"tv":9002.67,"id":9634485}]}]}
{"op":"mcm","clk":"4233806367","pt":1631538971972,"mc":[{"id":"1.187557759","rc":[{"batb":[[1,1.06,378.58]],"batl":[[0,1.17,127],[1,1.18,137.25]],"ltp":1.12,"tv":9002.67,"id":9634485}]}]}
{"op":"mcm","clk":"4233806635","pt":1631538973804,"mc":[{"id":"1.187557759","rc":[{"batb":[[0,1.04,1266.91],[1,1.01,115.38],[2,1.04,0]],"ltp":1.12,"tv":9002.67,"id":9634485},{"batl":[[0,26,2],[1,990,0.01],[2,990,0]],"ltp":9.2,"tv":1574.33,"id":9712888}]}]}
{"op":"mcm","clk":"4233806773","pt":1631538974779,"mc":[{"id":"1.187557759","rc":[{"batb":[[0,1.1,227.8],[1,1.09,402.05],[2,1.04,1266.91]],"batl":[[0,1.11,150.68],[1,1.12,484.39],[2,1.17,127]],"ltp":1.12,"tv":9002.67,"id":9634485},{"batb":[[0,9.4,19.11],[1,6.2,2],[2,6,23.26]],"ltp":9.2,"tv":1574.33,"id":9712888}]}]}
{"op":"mcm","clk":"4233806841","pt":1631538975300,"mc":[{"id":"1.187557759","rc":[{"batl":[[1,1.12,465.68]],"ltp":1.12,"tv":9002.67,"id":9634485},{"batb":[[0,6.2,2],[1,6,23.26],[2,5.7,2.12]],"ltp":9.2,"tv":1574.33,"id":9712888}]}]}
{"op":"mcm","clk":"4233807189","pt":1631538977725,"mc":[{"id":"1.187557759","rc":[{"batb":[[2,1.06,1394.21]],"batl":[[2,1.17,273.5]],"ltp":1.12,"tv":9002.67,"id":9634485},{"batb":[[0,6.8,2],[1,6.2,2],[2,6,23.26]],"batl":[[0,18,2],[1,26,2],[2,990,0.01]],"ltp":9.2,"tv":1574.33,"id":9712888}]}]}
{"op":"mcm","clk":"4233807571","pt":1631538980528,"mc":[{"id":"1.187557759","rc":[{"batb":[[0,1.06,1394.21],[1,1.04,1266.91],[2,1.02,1066.3]],"batl":[[0,1.17,127],[1,1.18,137.25],[2,1.19,147.5]],"ltp":1.12,"tv":9002.67,"id":9634485},{"batb":[[0,6.2,2],[1,6,23.26],[2,5.7,2.12]],"ltp":9.2,"tv":1574.33,"id":9712888}]}]}
{"op":"mcm","clk":"4233808013","pt":1631538983722,"mc":[{"id":"1.187557759","rc":[{"batb":[[0,1.06,2044.04]],"batl":[[0,1.17,679.41],[1,1.18,323.48]],"ltp":1.12,"tv":9002.67,"id":9634485},{"batb":[[0,6.8,2],[1,6.2,2],[2,6,23.26]],"ltp":9.2,"tv":1574.33,"id":9712888}]}]}
{"op":"mcm","clk":"4233808799","pt":1631538990756,"mc":[{"id":"1.187557759","rc":[{"batl":[[0,1.17,127],[1,1.2,108],[2,1.21,212.91]],"ltp":1.12,"tv":9002.67,"id":9634485},{"batb":[[0,6.2,2],[1,6,23.26],[2,1.01,115.38]],"ltp":9.2,"tv":1574.33,"id":9712888}]}]}
{"op":"mcm","clk":"4233808935","pt":1631538991859,"mc":[{"id":"1.187557759","rc":[{"batb":[[0,1.06,1075.41]],"ltp":1.12,"tv":9002.67,"id":9634485}]}]}
{"op":"mcm","clk":"4233809141","pt":1631538993444,"mc":[{"id":"1.187557759","rc":[{"batb":[[1,1.05,54.75],[2,1.04,1266.91]],"batl":[[0,1.08,637.8],[1,1.09,2049.75],[2,1.1,9.09]],"ltp":1.12,"tv":9002.67,"id":9634485},{"batb":[[0,12.5,7.2],[1,12,13.6],[2,11.5,3.6]],"batl":[[0,17.5,123.86],[1,18,2],[2,26,2]],"ltp":9.2,"tv":1574.33,"id":9712888}]}]}
{"op":"mcm","clk":"4233809272","pt":1631538994441,"mc":[{"id":"1.187557759","rc":[{"batb":[[0,1.06,1076.71],[1,1.05,64.27]],"ltp":1.12,"tv":9002.67,"id":9634485},{"batb":[[0,12.5,2.4],[1,12,11.2],[2,11.5,1.2]],"batl":[[0,17,1.76],[1,17.5,124.74],[2,18,2.88]],"ltp":9.2,"tv":1574.33,"id":9712888}]}]}
{"op":"mcm","clk":"4233809952","pt":1631538999636,"mc":[{"id":"1.187557759","rc":[{"batb":[[0,1.06,1149.71]],"ltp":1.12,"tv":9002.67,"id":9634485}]}]}
{"op":"mcm","clk":"4233810062","pt":1631539000532,"mc":[{"id":"1.187557759","rc":[{"batb":[[1,1.05,627.36]],"ltp":1.12,"tv":9002.67,"id":9634485}]}]}
{"op":"mcm","clk":"4233810160","pt":1631539001419,"mc":[{"id":"1.187557759","rc":[{"batb":[[0,1.06,1076.71]],"ltp":1.12,"tv":9002.67,"id":9634485}]}]}
{"op":"mcm","clk":"4233810316","pt":1631539002626,"mc":[{"id":"1.187557759","rc":[{"trd":[[1.08,285.9]],"batl":[[0,1.08,351.9]],"ltp":1.08,"tv":9288.57,"id":9634485},{"trd":[[13.5,22.87]],"ltp":13.5,"tv":1597.2,"id":9712888}],"tv":10885.78}]}
{"op":"mcm","clk":"4233810510","pt":1631539004451,"mc":[{"id":"1.187557759","rc":[{"trd":[[1.08,286.82]],"batb":[[0,1.07,253],[1,1.06,1076.71],[2,1.05,627.36]],"batl":[[0,1.08,351.44]],"ltp":1.08,"tv":9289.49,"id":9634485}],"tv":10886.7}]}
{"op":"mcm","clk":"4233810684","pt":1631539005655,"mc":[{"id":"1.187557759","rc":[{"batl":[[0,1.08,637.34]],"ltp":1.08,"tv":9289.49,"id":9634485}]}]}
{"op":"mcm","clk":"4233810818","pt":1631539006654,"mc":[{"id":"1.187557759","rc":[{"batb":[[1,1.06,1075.41]],"ltp":1.08,"tv":9289.49,"id":9634485}]}]}
{"op":"mcm","clk":"4233811064","pt":1631539008755,"mc":[{"id":"1.187557759","rc":[{"trd":[[1.08,326.82]],"batl":[[0,1.08,617.34]],"ltp":1.08,"tv":9329.49,"id":9634485}],"tv":10926.7}]}
{"op":"mcm","clk":"4233811200","pt":1631539009847,"mc":[{"id":"1.187557759","rc":[{"trd":[[1.08,329.42]],"batl":[[0,1.08,616.04]],"ltp":1.08,"tv":9332.09,"id":9634485}],"tv":10929.3}]}
{"op":"mcm","clk":"4233811433","pt":1631539011851,"mc":[{"id":"1.187557759","rc":[{"trd":[[1.08,592.56]],"batl":[[0,1.08,504.93]],"ltp":1.08,"tv":9595.23,"id":9634485}],"tv":11192.44}]}
{"op":"mcm","clk":"4233811461","pt":1631539012065,"mc":[{"id":"1.187557759","rc":[{"trd":[[1.08,596.42]],"batl":[[0,1.08,503]],"ltp":1.08,"tv":9599.09,"id":9634485}],"tv":11196.3}]}
{"op":"mcm","clk":"4233811794","pt":1631539014782,"mc":[{"id":"1.187557759","rc":[{"batl":[[0,1.08,602.01]],"ltp":1.08,"tv":9599.09,"id":9634485}]}]}
{"op":"mcm","clk":"4233811818","pt":1631539014940,"mc":[{"id":"1.187557759","rc":[{"trd":[[1.08,596.8]],"batl":[[0,1.08,601.82]],"ltp":1.08,"tv":9599.47,"id":9634485}],"tv":11196.68}]}
{"op":"mcm","clk":"4233811975","pt":1631539016367,"mc":[{"id":"1.187557759","rc":[{"trd":[[1.08,696.8]],"batl":[[0,1.08,551.82]],"ltp":1.08,"tv":9699.47,"id":9634485}],"tv":11296.68}]}
{"op":"mcm","clk":"4233812351","pt":1631539019382,"mc":[{"id":"1.187557759","rc":[{"batl":[[0,1.08,575.14]],"ltp":1.08,"tv":9699.47,"id":9634485}]}]}
{"op":"mcm","clk":"4233812900","pt":1631539023758,"mc":[{"id":"1.187557759","rc":[{"batb":[[2,1.05,617.84]],"batl":[[2,1.11,232.5]],"ltp":1.08,"tv":9699.47,"id":9634485}]}]}
{"op":"mcm","clk":"4233812999","pt":1631539024694,"mc":[{"id":"1.187557759","rc":[{"batb":[[1,1.06,425.58],[2,1.05,563.09]],"batl":[[0,1.13,171.5],[1,1.21,14.82],[2,1.23,29.65]],"ltp":1.08,"tv":9699.47,"id":9634485},{"batb":[[0,8.8,23.34],[1,8.6,2],[2,1.01,115.38]],"batl":[[0,18,2],[1,21,2],[2,26,2]],"ltp":13.5,"tv":1597.2,"id":9712888}]}]}
{"op":"mcm","clk":"4233813091","pt":1631539025486,"mc":[{"id":"1.187557759","rc":[{"batb":[[0,1.05,563.09],[1,1.03,2474.74],[2,1.02,1066.3]],"ltp":1.08,"tv":9699.47,"id":9634485},{"batl":[[0,21,2],[1,990,0.01],[2,26,0]],"ltp":13.5,"tv":1597.2,"id":9712888}]}]}
{"op":"mcm","clk":"4233813345","pt":1631539027685,"mc":[{"id":"1.187557759","rc":[{"batb":[[0,1.05,1219.11]],"batl":[[0,1.1,271.21],[1,1.11,604.29],[2,1.13,171.5]],"ltp":1.08,"tv":9699.47,"id":9634485},{"batb":[[0,10,2],[1,8.8,23.34],[2,8.6,2]],"ltp":13.5,"tv":1597.2,"id":9712888}]}]}
{"op":"mcm","clk":"4233813488","pt":1631539028799,"mc":[{"id":"1.187557759","rc":[{"batb":[[0,1.06,368.58],[1,1.05,1219.11],[2,1.04,703.87]],"batl":[[0,1.21,14.82],[1,1.23,29.65],[2,1.25,14.82]],"ltp":1.08,"tv":9699.47,"id":9634485},{"batb":[[0,8.8,23.34],[1,8.6,2],[2,1.01,115.38]],"batl":[[0,18,2],[1,21,2],[2,990,0.01]],"ltp":13.5,"tv":1597.2,"id":9712888}]}]}
{"op":"mcm","clk":"4233813759","pt":1631539030717,"mc":[{"id":"1.187557759","rc":[{"trd":[[1.06,110.06]],"batb":[[0,1.06,313.55],[1,1.05,2260.75]],"batl":[[0,1.07,5694.55],[1,1.09,9.17],[2,1.11,51.79]],"ltp":1.06,"tv":9809.53,"id":9634485},{"batb":[[0,15,10],[1,14.5,18.8],[2,14,5]],"batl":[[1,21,59.29]],"ltp":13.5,"tv":1597.2,"id":9712888}],"tv":11406.74}]}
{"op":"mcm","clk":"4233813897","pt":1631539031778,"mc":[{"id":"1.187557759","rc":[{"batb":[[1,1.05,2346.47],[2,1.04,756.35]],"batl":[[0,1.07,2724.91]],"ltp":1.06,"tv":9809.53,"id":9634485},{"batb":[[0,15,6],[1,14.5,11.28],[2,14,3]],"ltp":13.5,"tv":1597.2,"id":9712888}]}]}
{"op":"mcm","clk":"4233813911","pt":1631539031919,"mc":[{"id":"1.187557759","rc":[{"batb":[[1,1.05,2289.33],[2,1.04,727.77]],"ltp":1.06,"tv":9809.53,"id":9634485}]}]}
{"op":"mcm","clk":"4233814338","pt":1631539035683,"mc":[{"id":"1.187557759","rc":[{"trd":[[1.07,1752.42]],"batl":[[0,1.07,1848.7]],"ltp":1.07,"tv":11561.95,"id":9634485}],"tv":13159.16}]}
{"op":"mcm","clk":"4233814497","pt":1631539037103,"mc":[{"id":"1.187557759","rc":[{"batl":[[1,1.09,280.67],[2,1.1,215.55]],"ltp":1.07,"tv":11561.95,"id":9634485},{"batl":[[2,26,2]],"ltp":13.5,"tv":1597.2,"id":9712888}]}]}
{"op":"mcm","clk":"4233814743","pt":1631539039308,"mc":[{"id":"1.187557759","rc":[{"batb":[[0,1.06,423.55]],"ltp":1.07,"tv":11561.95,"id":9634485}]}]}
{"op":"mcm","clk":"4233814924","pt":1631539040732,"mc":[{"id":"1.187557759","rc":[{"trd":[[1.06,140.06]],"batb":[[0,1.06,408.55]],"ltp":1.06,"tv":11591.95,"id":9634485},{"batl":[[1,21,54.08]],"ltp":13.5,"tv":1597.2,"id":9712888}],"tv":13189.16}]}
{"op":"mcm","clk":"4233815273","pt":1631539043719,"mc":[{"id":"1.187557759","rc":[{"batb":[[1,1.05,2369.29]],"batl":[[0,1.07,1962.93]],"ltp":1.06,"tv":11591.95,"id":9634485},{"batl":[[1,21,58.08]],"ltp":13.5,"tv":1597.2,"id":9712888}]}]}
{"op":"mcm","clk":"4233815420","pt":1631539044820,"mc":[{"id":"1.187557759","rc":[{"trd":[[1.07,1805.04]],"batb":[[0,1.06,110],[1,1.04,703.87],[2,1.03,914.83]],"batl":[[0,1.09,271.5],[1,1.1,215.55],[2,1.11,232.5]],"ltp":1.07,"tv":11644.57,"id":9634485},{"batb":[[0,11,2],[1,10,15.48],[2,1.01,115.38]],"batl":[[0,26,2],[1,990,0.01],[2,26,0]],"ltp":13.5,"tv":1597.2,"id":9712888}],"tv":13241.78}]}
{"op":"mcm","clk":"4233815517","pt":1631539045713,"mc":[{"id":"1.187557759","rc":[{"batb":[[0,1.04,703.87],[1,1.02,4382.27],[2,1.01,115.38]],"batl":[[0,1.1,215.55],[1,1.19,14.82],[2,1.21,14.82]],"ltp":1.07,"tv":11644.57,"id":9634485}]}]}
{"op":"mcm","clk":"4233815704","pt":1631539047527,"mc":[{"id":"1.187557759","rc":[{"batb":[[0,1.04,1366.2]],"batl":[[0,1.08,199.33],[1,1.09,434.44],[2,1.1,215.55]],"ltp":1.07,"tv":11644.57,"id":9634485}]}]}
{"op":"mcm","clk":"4233815778","pt":1631539048319,"mc":[{"id":"1.187557759","rc":[{"batl":[[1,1.09,699.94]],"ltp":1.07,"tv":11644.57,"id":9634485},{"batb":[[0,12,2],[1,11,2],[2,10,15.48]],"ltp":13.5,"tv":1597.2,"id":9712888}]}]}
{"op":"mcm","clk":"4233815842","pt":1631539048893,"mc":[{"id":"1.187557759","rc":[{"batb":[[1,1.03,791.83],[2,1.02,4382.27]],"ltp":1.07,"tv":11644.57,"id":9634485}]}]}
{"op":"mcm","clk":"4233817248","pt":1631539061833,"mc":[{"id":"1.187557759","rc":[{"batl":[[0,1.09,265.5],[1,1.1,215.55],[2,1.19,14.82]],"ltp":1.07,"tv":11644.57,"id":9634485}]}]}
{"op":"mcm","clk":"4233817265","pt":1631539062048,"mc":[{"id":"1.187557759","rc":[{"batb":[[0,1.05,499.09],[1,1.04,1366.2],[2,1.03,791.83]],"ltp":1.07,"tv":11644.57,"id":9634485},{"batl":[[0,21,2],[1,26,2],[2,990,0.01]],"ltp":13.5,"tv":1597.2,"id":9712888}]}]}
{"op":"mcm","clk":"4233817510","pt":1631539064654,"mc":[{"id":"1.187557759","rc":[{"batb":[[1,1.04,3001.48]],"batl":[[0,1.06,4809.73],[1,1.07,3481.37],[2,1.08,9.26]],"ltp":1.07,"tv":11644.57,"id":9634485},{"batb":[[0,17.5,2],[1,16.5,1.82],[2,15.5,1.8]],"batl":[[1,26,67.41]],"ltp":13.5,"tv":1597.2,"id":9712888}]}]}
{"op":"mcm","clk":"4233817621","pt":1631539065761,"mc":[{"id":"1.187557759","rc":[{"batb":[[2,1.03,801.54]],"batl":[[0,1.06,1133.86]],"ltp":1.07,"tv":11644.57,"id":9634485},{"batl":[[1,24,1.24],[2,26,67.41]],"ltp":13.5,"tv":1597.2,"id":9712888}]}]}
{"op":"mcm","clk":"4233818148","pt":1631539070953,"mc":[{"id":"1.187557759","rc":[{"batl":[[1,1.07,3887.87],[2,1.08,316.95]],"ltp":1.07,"tv":11644.57,"id":9634485}]}]}
{"op":"mcm","clk":"4233818345","pt":1631539072675,"mc":[{"id":"1.187557759","rc":[{"batb":[[0,1.05,658.09]],"ltp":1.07,"tv":11644.57,"id":9634485}]}]}
{"op":"mcm","clk":"4233818754","pt":1631539076484,"mc":[{"id":"1.187557759","rc":[{"batl":[[0,1.06,812.46]],"ltp":1.07,"tv":11644.57,"id":9634485}]}]}
{"op":"mcm","clk":"4233818807","pt":1631539076965,"mc":[{"id":"1.187557759","rc":[{"trd":[[1.06,140.36]],"batl":[[0,1.06,812.31]],"ltp":1.06,"tv":11644.87,"id":9634485}],"tv":13242.08}]}
{"op":"mcm","clk":"4233820045","pt":1631539087212,"mc":[{"id":"1.187557759","rc":[{"batb":[[1,1.04,2909.57]],"batl":[[0,1.06,665.58]],"ltp":1.06,"tv":11644.87,"id":9634485},{"batl":[[2,26,63.73]],"ltp":13.5,"tv":1597.2,"id":9712888}]}]}
{"op":"mcm","clk":"4233820348","pt":1631539090071,"mc":[{"id":"1.187557759","rc":[{"batb":[[1,1.04,3001.55]],"batl":[[0,1.06,812.31]],"ltp":1.06,"tv":11644.87,"id":9634485},{"batl":[[2,26,67.41]],"ltp":13.5,"tv":1597.2,"id":9712888}]}]}
{"op":"mcm","clk":"4233820714","pt":1631539093803,"mc":[{"id":"1.187557759","rc":[{"batb":[[0,1.05,159],[1,1.04,1003.97],[2,1.03,791.83]],"batl":[[0,1.08,307.69],[1,1.17,29.65],[2,1.19,14.82]],"ltp":1.06,"tv":11644.87,"id":9634485},{"batb":[[0,13.5,2],[1,12,10.21],[2,1.01,115.38]],"batl":[[0,26,2],[1,36,2],[2,990,0.01]],"ltp":13.5,"tv":1597.2,"id":9712888}]}]}
{"op":"mcm","clk":"4233820772","pt":1631539094395,"mc":[{"id":"1.187557759","rc":[{"batb":[[0,1.04,1003.97],[1,1.03,791.83],[2,1.02,3280.14]],"ltp":1.06,"tv":11644.87,"id":9634485}]}]}
{"op":"mcm","clk":"4233821290","pt":1631539099599,"mc":[{"id":"1.187557759","rc":[{"batl":[[0,1.06,21.75],[1,1.08,307.69],[2,1.17,29.65]],"ltp":1.06,"tv":11644.87,"id":9634485}]}]}
{"op":"mcm","clk":"4233821364","pt":1631539100285,"mc":[{"id":"1.187557759","rc":[{"batb":[[0,1.04,1366.2]],"batl":[[0,1.06,649.83],[1,1.07,372.5],[2,1.08,307.69]],"ltp":1.06,"tv":11644.87,"id":9634485},{"batb":[[0,15,2],[1,13.5,2],[2,12,10.21]],"ltp":13.5,"tv":1597.2,"id":9712888}]}]}
{"op":"mcm","clk":"4233821587","pt":1631539102603,"mc":[{"id":"1.187557759","rc":[{"batb":[[0,1.04,1417.2]],"ltp":1.06,"tv":11644.87,"id":9634485}]}]}
{"op":"mcm","clk":"4233822002","pt":1631539106615,"mc":[{"id":"1.187557759","rc":[{"batb":[[0,1.04,1003.97]],"batl":[[0,1.07,372.5],[1,1.08,307.69],[2,1.09,268.5]],"ltp":1.06,"tv":11644.87,"id":9634485}]}]}
{"op":"mcm","clk":"4233822034","pt":1631539106931,"mc":[{"id":"1.187557759","rc":[{"batl":[[0,1.08,307.69],[1,1.17,29.65],[2,1.19,14.82]],"ltp":1.06,"tv":11644.87,"id":9634485},{"batb":[[0,13.5,2],[1,12,10.21],[2,1.01,115.38]],"ltp":13.5,"tv":1597.2,"id":9712888}]}]}
{"op":"mcm","clk":"4233822334","pt":1631539109619,"mc":[{"id":"1.187557759","rc":[{"batb":[[0,1.05,258],[1,1.04,1003.97],[2,1.03,1157.57]],"batl":[[0,1.07,643.76],[1,1.08,307.69],[2,1.17,29.65]],"ltp":1.06,"tv":11644.87,"id":9634485}]}]}
{"op":"mcm","clk":"4233822401","pt":1631539110145,"mc":[{"id":"1.187557759","rc":[{"batl":[[0,1.07,961.26],[2,1.09,294.5]],"ltp":1.06,"tv":11644.87,"id":9634485},{"batb":[[0,15,2],[1,13.5,2],[2,12,10.21]],"ltp":13.5,"tv":1597.2,"id":9712888}]}]}
{"op":"mcm","clk":"4233823115","pt":1631539116414,"mc":[{"id":"1.187557759","rc":[{"batb":[[0,1.04,1003.97],[1,1.03,1157.57],[2,1.02,3280.14]],"ltp":1.06,"tv":11644.87,"id":9634485}]}]}
{"op":"mcm","clk":"4233823192","pt":1631539117261,"mc":[{"id":"1.187557759","rc":[{"trd":[[1.04,2.54]],"batb":[[0,1.04,1002.7]],"ltp":1.04,"tv":11647.41,"id":9634485}],"tv":13244.62}]}
{"op":"mcm","clk":"4233823795","pt":1631539122232,"mc":[{"id":"1.187557759","rc":[{"trd":[[15,0.72]],"batb":[[0,15,1.64]],"ltp":15.0,"tv":1597.92,"id":9712888}],"tv":13245.34}]}
{"op":"mcm","clk":"4233823902","pt":1631539123131,"mc":[{"id":"1.187557759","rc":[{"batl":[[0,1.06,6.57],[1,1.07,961.26],[2,1.08,307.69]],"ltp":1.04,"tv":11647.41,"id":9634485}]}]}
{"op":"mcm","clk":"4233824050","pt":1631539124663,"mc":[{"id":"1.187557759","rc":[{"batl":[[1,1.07,317.5],[2,1.17,29.65]],"ltp":1.04,"tv":11647.41,"id":9634485}]}]}
{"op":"mcm","clk":"4233824206","pt":1631539126060,"mc":[{"id":"1.187557759","rc":[{"batb":[[2,1.02,1066.3]],"ltp":1.04,"tv":11647.41,"id":9634485}]}]}
{"op":"mcm","clk":"4233824404","pt":1631539127684,"mc":[{"id":"1.187557759","rc":[{"batb":[[2,1.02,1122.66]],"batl":[[0,1.05,1047.72],[1,1.06,3500.19],[2,1.07,326.85]],"ltp":1.04,"tv":11647.41,"id":9634485},{"batb":[[0,18.5,4.87],[1,18,2.44],[2,17.5,4.44]],"batl":[[1,34,169.88],[2,36,2]],"ltp":15.0,"tv":1597.92,"id":9712888}]}]}
{"op":"mcm","clk":"4233824513","pt":1631539128475,"mc":[{"id":"1.187557759","rc":[{"batb":[[1,1.03,1167.28]],"ltp":1.04,"tv":11647.41,"id":9634485},{"batb":[[0,18.5,1.62],[1,17.5,3.64],[2,16.5,7.27]],"batl":[[1,28,1.08],[2,34,169.88]],"ltp":15.0,"tv":1597.92,"id":9712888}]}]}
{"op":"mcm","clk":"4233824855","pt":1631539131253,"mc":[{"id":"1.187557759","rc":[{"batb":[[0,1.04,1125.7]],"ltp":1.04,"tv":11647.41,"id":9634485}]}]}
{"op":"mcm","clk":"4233825683","pt":1631539138592,"mc":[{"id":"1.187557759","rc":[{"trd":[[1.05,0.38]],"batl":[[0,1.05,1047.53]],"ltp":1.05,"tv":11647.79,"id":9634485}],"tv":13245.71}]}
{"op":"mcm","clk":"4233825778","pt":1631539139493,"mc":[{"id":"1.187557759","rc":[{"trd":[[1.05,1.92]],"batl":[[0,1.05,720.49]],"ltp":1.05,"tv":11649.33,"id":9634485}],"tv":13247.26}]}
{"op":"mcm","clk":"4233826385","pt":1631539144711,"mc":[{"id":"1.187557759","rc":[{"trd":[[1.04,11.21]],"batb":[[0,1.04,1121.36],[2,1.02,1066.3]],"ltp":1.04,"tv":11658.01,"id":9634485}],"tv":13255.93}]}
{"op":"mcm","clk":"4233826493","pt":1631539145611,"mc":[{"id":"1.187557759","rc":[{"trd":[[1.05,55.15]],"batl":[[0,1.05,693.87]],"ltp":1.05,"tv":11711.24,"id":9634485}],"tv":13309.17}]}
{"op":"mcm","clk":"4233826820","pt":1631539148607,"mc":[{"id":"1.187557759","rc":[{"batb":[[0,1.04,123],[1,1.03,365.74],[2,1.01,4237.26]],"batl":[[0,1.06,6.57],[1,1.07,317.5],[2,1.08,268.94]],"ltp":1.05,"tv":11711.24,"id":9634485},{"batb":[[0,15.5,9.96],[1,15,1.64],[2,14,13.39]],"batl":[[0,36,2],[1,990,0.01],[2,34,0]],"ltp":15.0,"tv":1597.92,"id":9712888}]}]}
{"op":"mcm","clk":"4233826885","pt":1631539149287,"mc":[{"id":"1.187557759","rc":[{"batb":[[0,1.03,365.74],[1,1.01,4237.26],[2,1.01,0]],"ltp":1.05,"tv":11711.24,"id":9634485},{"batb":[[0,15,1.64],[1,14,13.39],[2,13.5,2]],"ltp":15.0,"tv":1597.92,"id":9712888}]}]}
{"op":"mcm","clk":"4233827030","pt":1631539150800,"mc":[{"id":"1.187557759","rc":[{"batb":[[0,1.03,177.32]],"ltp":1.05,"tv":11711.24,"id":9634485}]}]}
{"op":"mcm","clk":"4233827334","pt":1631539153793,"mc":[{"id":"1.187557759","rc":[{"trd":[[1.06,153.5],[1.07,1808.94]],"batb":[[0,1.04,486.71],[1,1.03,177.32],[2,1.01,4237.26]],"batl":[[0,1.05,656.02],[1,1.06,19.25],[2,1.07,315.55]],"ltp":1.07,"tv":11728.28,"id":9634485}],"tv":13326.21}]}
{"op":"mcm","clk":"4233827347","pt":1631539154002,"mc":[{"id":"1.187557759","rc":[{"batl":[[1,1.07,315.55],[2,1.08,268.94]],"ltp":1.07,"tv":11728.28,"id":9634485}]}]}
{"op":"mcm","clk":"4233827547","pt":1631539155728,"mc":[{"id":"1.187557759","rc":[{"batl":[[1,1.06,440.25],[2,1.07,315.55]],"ltp":1.07,"tv":11728.28,"id":9634485},{"batb":[[0,17.5,2],[1,15,1.64],[2,14,13.39]],"ltp":15.0,"tv":1597.92,"id":9712888}]}]}
{"op":"mcm","clk":"4233827928","pt":1631539158898,"mc":[{"id":"1.187557759","rc":[{"batb":[[0,1.04,580.71]],"ltp":1.07,"tv":11728.28,"id":9634485}]}]}
{"op":"mcm","clk":"4233828188","pt":1631539160835,"mc":[{"id":"1.187557759","rc":[{"batb":[[0,1.04,94]],"batl":[[0,1.06,440.25],[1,1.07,315.55],[2,1.08,268.94]],"ltp":1.07,"tv":11728.28,"id":9634485}]}]}
{"op":"mcm","clk":"4233828257","pt":1631539161415,"mc":[{"id":"1.187557759","rc":[{"batb":[[0,1.03,177.32],[1,1.01,4237.26],[2,1.01,0]],"batl":[[0,1.07,315.55],[1,1.08,268.94],[2,1.15,14.82]],"ltp":1.07,"tv":11728.28,"id":9634485},{"batb":[[0,15,1.64],[1,14,13.39],[2,13.5,2]],"ltp":15.0,"tv":1597.92,"id":9712888}]}]}
{"op":"mcm","clk":"4233828502","pt":1631539163827,"mc":[{"id":"1.187557759","rc":[{"batb":[[0,1.03,668.76]],"batl":[[0,1.06,649.83],[1,1.07,315.55],[2,1.08,268.94]],"ltp":1.07,"tv":11728.28,"id":9634485}]}]}
{"op":"mcm","clk":"4233828546","pt":1631539164315,"mc":[{"id":"1.187557759","rc":[{"batl":[[0,1.06,1063.58]],"ltp":1.07,"tv":11728.28,"id":9634485},{"batb":[[0,17.5,2],[1,15,1.64],[2,14,13.39]],"ltp":15.0,"tv":1597.92,"id":9712888}]}]}
{"op":"mcm","clk":"4233828865","pt":1631539167608,"mc":[{"id":"1.187557759","rc":[{"batl":[[0,1.06,413.75],[1,1.15,14.82],[2,1.17,29.65]],"ltp":1.07,"tv":11728.28,"id":9634485}]}]}
{"op":"mcm","clk":"4233828974","pt":1631539168545,"mc":[{"id":"1.187557759","rc":[{"batb":[[1,1.01,115.38]],"ltp":1.07,"tv":11728.28,"id":9634485}]}]}
{"op":"mcm","clk":"4233829222","pt":1631539170743,"mc":[{"id":"1.187557759","rc":[{"batb":[[1,1.01,200.77]],"batl":[[0,1.04,160.67],[1,1.05,2281.44],[2,1.06,413.75]],"ltp":1.07,"tv":11728.28,"id":9634485},{"batb":[[0,21,78.28],[1,17.5,2],[2,17,7.06]],"batl":[[0,34,128.1],[1,36,2],[2,990,0.01]],"ltp":15.0,"tv":1597.92,"id":9712888}]}]}
{"op":"mcm","clk":"4233829302","pt":1631539171529,"mc":[{"id":"1.187557759","rc":[{"batb":[[1,1.02,9.8],[2,1.01,200.77]],"ltp":1.07,"tv":11728.28,"id":9634485},{"batl":[[0,34,128.54]],"ltp":15.0,"tv":1597.92,"id":9712888}]}]}
{"op":"mcm","clk":"4233829441","pt":1631539172635,"mc":[{"id":"1.187557759","rc":[{"batb":[[2,1.01,4131.03]],"ltp":1.07,"tv":11728.28,"id":9634485},{"batb":[[0,21,75.42]],"batl":[[0,34,128.98]],"ltp":15.0,"tv":1597.92,"id":9712888}]}]}
{"op":"mcm","clk":"4233829805","pt":1631539175631,"mc":[{"id":"1.187557759","rc":[{"trd":[[1.04,109.71]],"batl":[[0,1.04,62.17]],"ltp":1.04,"tv":11826.78,"id":9634485},{"trd":[[26,3.94]],"ltp":26.0,"tv":1601.86,"id":9712888}],"tv":13428.65}]}
{"op":"mcm","clk":"4233830073","pt":1631539178845,"mc":[{"id":"1.187557759","rc":[{"trd":[[1.03,4.68]],"batb":[[0,1.03,666.42]],"batl":[[0,1.04,104.97],[1,1.05,2336.6]],"ltp":1.03,"tv":11831.46,"id":9634485}],"tv":13433.33}]}
{"op":"mcm","clk":"4233830297","pt":1631539180845,"mc":[{"id":"1.187557759","rc":[{"trd":[[1.03,659.86],[1.04,409.71]],"batb":[[0,1.03,338.83]],"batl":[[0,1.05,2336.6],[1,1.06,413.75],[2,1.07,9.35]],"ltp":1.03,"tv":12786.64,"id":9634485}],"tv":14388.5}]}
{"op":"mcm","clk":"4233830373","pt":1631539181464,"mc":[{"id":"1.187557759","rc":[{"batl":[[0,1.05,2215.08]],"ltp":1.03,"tv":12786.64,"id":9634485}]}]}
{"op":"mcm","clk":"4233830487","pt":1631539182462,"mc":[{"id":"1.187557759","rc":[{"batl":[[0,1.05,1885.79]],"ltp":1.03,"tv":12786.64,"id":9634485},{"batl":[[0,34,129.88]],"ltp":26.0,"tv":1601.86,"id":9712888}]}]}
{"op":"mcm","clk":"4233830625","pt":1631539183766,"mc":[{"id":"1.187557759","rc":[{"trd":[[1.05,2053.81]],"batl":[[0,1.05,990.44]],"ltp":1.05,"tv":14785.3,"id":9634485}],"tv":16387.16}]}
{"op":"mcm","clk":"4233830683","pt":1631539184351,"mc":[{"id":"1.187557759","rc":[{"trd":[[1.04,432.21]],"batb":[[0,1.03,669.93]],"batl":[[0,1.04,205.17],[1,1.05,886.46],[2,1.06,413.75]],"ltp":1.04,"tv":14807.8,"id":9634485},{"trd":[[26,4.84]],"batl":[[0,34,128.98]],"ltp":26.0,"tv":1602.76,"id":9712888}],"tv":16410.56}]}
{"op":"mcm","clk":"4233830837","pt":1631539185761,"mc":[{"id":"1.187557759","rc":[{"trd":[[1.04,842.55]],"batb":[[0,1.04,303.83],[1,1.03,669.93],[2,1.02,9.8]],"batl":[[0,1.05,886.46],[1,1.06,413.75],[2,1.07,9.35]],"ltp":1.04,"tv":15218.14,"id":9634485}],"tv":16820.9}]}
{"op":"mcm","clk":"4233831018","pt":1631539187556,"mc":[{"id":"1.187557759","rc":[{"batl":[[0,1.05,898.77]],"ltp":1.04,"tv":15218.14,"id":9634485}]}]}
{"op":"mcm","clk":"4233831157","pt":1631539188652,"mc":[{"id":"1.187557759","rc":[{"trd":[[1.04,1046.27]],"batb":[[0,1.04,201.97]],"batl":[[0,1.05,1011.07]],"ltp":1.04,"tv":15421.86,"id":9634485}],"tv":17024.62}]}
{"op":"mcm","clk":"4233831524","pt":1631539191873,"mc":[{"id":"1.187557759","rc":[{"batl":[[0,1.05,1111.96]],"ltp":1.04,"tv":15421.86,"id":9634485}]}]}
{"op":"mcm","clk":"4233831818","pt":1631539194291,"mc":[{"id":"1.187557759","rc":[{"trd":[[1.04,1450.21]],"batb":[[0,1.03,669.93],[1,1.02,9.8],[2,1.01,4131.03]],"batl":[[0,1.04,298.03],[1,1.05,1111.96],[2,1.06,413.75]],"ltp":1.04,"tv":15825.8,"id":9634485},{"batb":[[0,21,71.46]],"batl":[[0,34,121.33]],"ltp":26.0,"tv":1602.76,"id":9712888}],"tv":17428.56}]}
{"op":"mcm","clk":"4233831914","pt":1631539194979,"mc":[{"id":"1.187557759","rc":[{"trd":[[1.04,1452.07]],"batl":[[0,1.04,297.1]],"ltp":1.04,"tv":15827.66,"id":9634485}],"tv":17430.42}]}
{"op":"mcm","clk":"4233832076","pt":1631539196670,"mc":[{"id":"1.187557759","rc":[{"batl":[[0,1.04,2304.29]],"ltp":1.04,"tv":15827.66,"id":9634485}]}]}
{"op":"mcm","clk":"4233832150","pt":1631539197403,"mc":[{"id":"1.187557759","rc":[{"trd":[[1.04,2066.13]],"batl":[[0,1.04,1997.26],[1,1.05,1137.44]],"ltp":1.04,"tv":16441.72,"id":9634485}],"tv":18044.48}]}
{"op":"mcm","clk":"4233832594","pt":1631539201313,"mc":[{"id":"1.187557759","rc":[{"trd":[[1.04,3238.67]],"batl":[[0,1.04,1410.99]],"ltp":1.04,"tv":17614.26,"id":9634485}],"tv":19217.02}]}
{"op":"mcm","clk":"4233835707","pt":1631539230035,"mc":[{"id":"1.187557759","rc":[{"trd":[[1.04,3248.33]],"batl":[[0,1.04,1401.33]],"ltp":1.04,"tv":17623.92,"id":9634485},{"trd":[[26,5.23]],"ltp":26.0,"tv":1603.15,"id":9712888}],"tv":19227.07}]}
{"op":"mcm","clk":"4233835989","pt":1631539233241,"mc":[{"id":"1.187557759","rc":[{"trd":[[1.04,4192.15]],"batl":[[0,1.04,929.42]],"ltp":1.04,"tv":18567.74,"id":9634485}],"tv":20170.89}]}
{"op":"mcm","clk":"4233837765","pt":1631539249558,"mc":[{"id":"1.187557759","rc":[{"batl":[[0,1.04,930.41]],"ltp":1.04,"tv":18567.74,"id":9634485}]}]}
{"op":"mcm","clk":"4233838624","pt":1631539257462,"mc":[{"id":"1.187557759","rc":[{"batb":[[2,1.01,4045.65]],"ltp":1.04,"tv":18567.74,"id":9634485}]}]}
{"op":"mcm","clk":"4233839660","pt":1631539266581,"mc":[{"id":"1.187557759","rc":[{"batb":[[0,1.01,4045.65],[1,1.02,0],[2,1.01,0]],"batl":[[1,1.05,278.82]],"ltp":1.04,"tv":18567.74,"id":9634485},{"batb":[[0,17.5,2],[1,16.5,8.11],[2,15,1.64]],"batl":[[0,990,0.01],[1,36,0],[2,990,0]],"ltp":26.0,"tv":1603.15,"id":9712888}]}]}
{"op":"mcm","clk":"4233839691","pt":1631539266891,"mc":[{"id":"1.187557759","rc":[{"batb":[[1,15,1.64],[2,14.5,11.71]],"ltp":26.0,"tv":1603.15,"id":9712888}]}]}
{"op":"mcm","clk":"4233839812","pt":1631539268193,"mc":[{"id":"1.187557759","rc":[{"trd":[[1.04,4193.55]],"batl":[[0,1.04,929.71]],"ltp":1.04,"tv":18569.13,"id":9634485}],"tv":20172.29}]}
{"op":"mcm","clk":"4233840379","pt":1631539272797,"mc":[{"id":"1.187557759","rc":[{"batb":[[0,1.03,669.93],[1,1.01,4045.65]],"batl":[[0,1.04,1256],[1,1.05,333.97]],"ltp":1.04,"tv":18569.13,"id":9634485}]}]}
{"op":"mcm","clk":"4233841134","pt":1631539279432,"mc":[{"id":"1.187557759","rc":[{"batb":[[0,1.01,4045.65],[1,1.01,0]],"batl":[[0,1.04,929.71],[1,1.05,278.82]],"ltp":1.04,"tv":18569.13,"id":9634485}]}]}
{"op":"mcm","clk":"4233841470","pt":1631539282341,"mc":[{"id":"1.187557759","rc":[{"batb":[[0,1.02,676.49],[1,1.01,4045.65]],"batl":[[2,1.06,788.51]],"ltp":1.04,"tv":18569.13,"id":9634485}]}]}
{"op":"mcm","clk":"4233841959","pt":1631539286723,"mc":[{"id":"1.187557759","rc":[{"batl":[[1,1.05,244.01]],"ltp":1.04,"tv":18569.13,"id":9634485}]}]}
{"op":"mcm","clk":"4233842310","pt":1631539289747,"mc":[{"id":"1.187557759","rc":[{"batl":[[2,1.06,823]],"ltp":1.04,"tv":18569.13,"id":9634485}]}]}
{"op":"mcm","clk":"4233842771","pt":1631539293733,"mc":[{"id":"1.187557759","rc":[{"batb":[[0,1.01,4045.65],[1,1.01,0]],"batl":[[2,1.06,409.25]],"ltp":1.04,"tv":18569.13,"id":9634485},{"batb":[[0,15,1.64],[1,14.5,11.71],[2,1.01,115.38]],"ltp":26.0,"tv":1603.15,"id":9712888}]}]}
{"op":"mcm","clk":"4233842960","pt":1631539295521,"mc":[{"id":"1.187557759","rc":[{"batb":[[0,1.01,115.38]],"ltp":1.04,"tv":18569.13,"id":9634485}]}]}
{"op":"mcm","clk":"4233843068","pt":1631539296615,"mc":[{"id":"1.187557759","rc":[{"trd":[[1.04,5123.26]],"batb":[[0,1.04,2256.64],[1,1.03,9.71],[2,1.02,56.36]],"batl":[[0,1.05,244.01],[1,1.06,2047.33],[2,1.1,52.26]],"ltp":1.04,"tv":19498.84,"id":9634485},{"trd":[[26,42.42]],"batl":[[0,26,26.54],[1,32,7.18],[2,990,0.01]],"ltp":26.0,"tv":1640.34,"id":9712888}],"tv":21139.19}]}
{"op":"mcm","clk":"4233843182","pt":1631539297763,"mc":[{"id":"1.187557759","rc":[{"batl":[[2,1.08,9.26]],"ltp":1.04,"tv":19498.84,"id":9634485},{"batb":[[0,18,1.66],[1,17,1.68],[2,15,1.64]],"ltp":26.0,"tv":1640.34,"id":9712888}]}]}
{"op":"mcm","clk":"4233843702","pt":1631539302555,"mc":[{"id":"1.187557759","rc":[{"batb":[[0,1.04,2495.64]],"ltp":1.04,"tv":19498.84,"id":9634485}]}]}
{"op":"mcm","clk":"4233843737","pt":1631539302971,"mc":[{"id":"1.187557759","rc":[{"batl":[[1,1.06,2465.58],[2,1.07,334.5]],"ltp":1.04,"tv":19498.84,"id":9634485},{"batb":[[1,17.5,2.84],[2,15,2.48]],"ltp":26.0,"tv":1640.34,"id":9712888}]}]}
{"op":"mcm","clk":"4233843980","pt":1631539305578,"mc":[{"id":"1.187557759","rc":[{"batl":[[0,1.05,213.12]],"ltp":1.04,"tv":19498.84,"id":9634485}]}]}
{"op":"mcm","clk":"4233844266","pt":1631539308484,"mc":[{"id":"1.187557759","rc":[{"batl":[[1,1.06,2496.17]],"ltp":1.04,"tv":19498.84,"id":9634485}]}]}
{"op":"mcm","clk":"4233845111","pt":1631539316699,"mc":[{"id":"1.187557759","rc":[{"batb":[[0,1.04,239],[1,1.01,4237.26],[2,1.02,0]],"batl":[[0,1.06,827.5],[1,1.07,334.5],[2,1.08,326.19]],"ltp":1.04,"tv":19498.84,"id":9634485},{"batb":[[0,17.5,2],[1,15,1.64],[2,14.5,11.71]],"batl":[[0,990,0.01],[1,32,0],[2,990,0]],"ltp":26.0,"tv":1640.34,"id":9712888}]}]}
{"op":"mcm","clk":"4233845185","pt":1631539317384,"mc":[{"id":"1.187557759","rc":[{"batb":[[0,1.01,4237.26],[1,1.01,0]],"ltp":1.04,"tv":19498.84,"id":9634485},{"batb":[[2,13.5,7.53]],"ltp":26.0,"tv":1640.34,"id":9712888}]}]}
{"op":"mcm","clk":"4233845463","pt":1631539319833,"mc":[{"id":"1.187557759","rc":[{"batl":[[1,1.07,582.23]],"ltp":1.04,"tv":19498.84,"id":9634485}]}]}
{"op":"mcm","clk":"4233845472","pt":1631539319940,"mc":[{"id":"1.187557759","rc":[{"batl":[[0,1.06,409.25],[1,1.07,247.73],[2,1.11,3.53]],"ltp":1.04,"tv":19498.84,"id":9634485},{"batb":[[0,15,1.64],[1,13.5,7.53],[2,1.01,115.38]],"ltp":26.0,"tv":1640.34,"id":9712888}]}]}
{"op":"mcm","clk":"4233845590","pt":1631539321016,"mc":[{"id":"1.187557759","rc":[{"batb":[[0,1.01,115.38]],"ltp":1.04,"tv":19498.84,"id":9634485}]}]}
{"op":"mcm","clk":"4233845777","pt":1631539322630,"mc":[{"id":"1.187557759","rc":[{"batb":[[0,1.05,1080.23],[1,1.04,294.35],[2,1.03,55.81]],"batl":[[1,1.07,2796.67],[2,1.11,55.32]],"ltp":1.04,"tv":19498.84,"id":9634485},{"batl":[[0,21,29.54],[1,25,3.6],[2,990,0.01]],"ltp":26.0,"tv":1640.34,"id":9712888}]}]}
{"op":"mcm","clk":"4233845909","pt":1631539323831,"mc":[{"id":"1.187557759","rc":[{"batl":[[2,1.08,9.26]],"ltp":1.04,"tv":19498.84,"id":9634485},{"batb":[[0,17,5.29],[1,16,1.76],[2,15,1.64]],"batl":[[1,25,1.2]],"ltp":26.0,"tv":1640.34,"id":9712888}]}]}
{"op":"mcm","clk":"4233846012","pt":1631539324781,"mc":[{"id":"1.187557759","rc":[{"batb":[[0,17,1.76]],"ltp":26.0,"tv":1640.34,"id":9712888}]}]}
{"op":"mcm","clk":"4233846360","pt":1631539327714,"mc":[{"id":"1.187557759","rc":[{"trd":[[1.05,2076.54]],"batb":[[0,1.05,1068.87]],"ltp":1.05,"tv":19521.56,"id":9634485}],"tv":21161.91}]}
{"op":"mcm","clk":"4233846421","pt":1631539328296,"mc":[{"id":"1.187557759","rc":[{"batb":[[0,1.05,1226.87]],"ltp":1.05,"tv":19521.56,"id":9634485}]}]}
{"op":"mcm","clk":"4233846548","pt":1631539329504,"mc":[{"id":"1.187557759","rc":[{"batl":[[1,1.07,3117.17],[2,1.08,346.45]],"ltp":1.05,"tv":19521.56,"id":9634485}]}]}
{"op":"mcm","clk":"4233847611","pt":1631539340425,"mc":[{"id":"1.187557759","rc":[{"trd":[[1.05,2079.94]],"batb":[[0,1.05,1225.17]],"ltp":1.05,"tv":19524.97,"id":9634485}],"tv":21165.31}]}
{"op":"mcm","clk":"4233847939","pt":1631539343718,"mc":[{"id":"1.187557759","rc":[{"batb":[[0,1.05,158],[1,1.04,169.35],[2,1.02,2213.84]],"batl":[[0,1.07,568.23],[1,1.08,337.19],[2,1.09,269.5]],"ltp":1.05,"tv":19524.97,"id":9634485},{"batb":[[0,15,1.64],[1,13.5,2],[2,12.5,9.29]],"batl":[[0,990,0.01],[1,25,0],[2,990,0]],"ltp":26.0,"tv":1640.34,"id":9712888}]}]}
{"op":"mcm","clk":"4233848008","pt":1631539344439,"mc":[{"id":"1.187557759","rc":[{"batb":[[0,1.04,169.35],[1,1.02,2213.84],[2,1.01,21.7]],"ltp":1.05,"tv":19524.97,"id":9634485}]}]}
{"op":"mcm","clk":"4233848142","pt":1631539345743,"mc":[{"id":"1.187557759","rc":[{"batl":[[0,1.07,97.18],[2,1.11,3.53]],"ltp":1.05,"tv":19524.97,"id":9634485},{"batb":[[0,13.5,2],[1,12.5,9.29],[2,1.01,115.38]],"ltp":26.0,"tv":1640.34,"id":9712888}]}]}
{"op":"mcm","clk":"4233848203","pt":1631539346421,"mc":[{"id":"1.187557759","rc":[{"batb":[[0,1.04,352.1]],"ltp":1.05,"tv":19524.97,"id":9634485}]}]}
{"op":"mcm","clk":"4233848419","pt":1631539348551,"mc":[{"id":"1.187557759","rc":[{"batb":[[0,1.05,308.41],[1,1.04,352.1],[2,1.02,2213.84]],"batl":[[0,1.06,552.86],[1,1.07,116.11],[2,1.08,337.19]],"ltp":1.05,"tv":19524.97,"id":9634485}]}]}
{"op":"mcm","clk":"4233848511","pt":1631539349334,"mc":[{"id":"1.187557759","rc":[{"batb":[[0,1.05,484.41]],"batl":[[1,1.07,407.68]],"ltp":1.05,"tv":19524.97,"id":9634485},{"batb":[[0,15,2],[1,13.5,2],[2,12.5,9.29]],"ltp":26.0,"tv":1640.34,"id":9712888}]}]}
{"op":"mcm","clk":"4233848808","pt":1631539352366,"mc":[{"id":"1.187557759","rc":[{"batb":[[0,1.04,352.1],[1,1.02,2213.84],[2,1.01,21.7]],"batl":[[0,1.07,97.18],[1,1.08,337.19],[2,1.11,3.53]],"ltp":1.05,"tv":19524.97,"id":9634485},{"batb":[[0,13.5,2],[1,12.5,9.29],[2,1.01,115.38]],"ltp":26.0,"tv":1640.34,"id":9712888}]}]}
{"op":"mcm","clk":"4233849141","pt":1631539355439,"mc":[{"id":"1.187557759","rc":[{"batb":[[0,1.04,663.48]],"batl":[[0,1.07,990.38],[2,1.09,282.5]],"ltp":1.05,"tv":19524.97,"id":9634485},{"batb":[[0,15,2],[1,13.5,2],[2,12.5,9.29]],"ltp":26.0,"tv":1640.34,"id":9712888}]}]}
{"op":"mcm","clk":"4233849338","pt":1631539357571,"mc":[{"id":"1.187557759","rc":[{"trd":[[1.04,5728.7],[1.06,153.69]],"batb":[[0,1.04,360.76]],"ltp":1.04,"tv":20130.6,"id":9634485}],"tv":21770.94}]}
{"op":"mcm","clk":"4233849548","pt":1631539359666,"mc":[{"id":"1.187557759","rc":[{"batb":[[0,1.02,2213.84],[1,1.01,21.7],[2,1.01,0]],"ltp":1.04,"tv":20130.6,"id":9634485}]}]}
{"op":"mcm","clk":"4233849764","pt":1631539361751,"mc":[{"id":"1.187557759","rc":[{"batb":[[0,1.01,21.7],[1,1.01,0]],"ltp":1.04,"tv":20130.6,"id":9634485}]}]}
{"op":"mcm","clk":"4233849880","pt":1631539362846,"mc":[{"id":"1.187557759","rc":[{"batb":[[0,1.05,2506.93],[1,1.04,52.48],[2,1.03,98.67]],"batl":[[0,1.07,1948.47],[1,1.08,390.5]],"ltp":1.04,"tv":20130.6,"id":9634485},{"batl":[[0,17.5,7.11],[1,21,82.49],[2,990,0.01]],"ltp":26.0,"tv":1640.34,"id":9712888}]}]}
{"op":"mcm","clk":"4233849965","pt":1631539363778,"mc":[{"id":"1.187557759","rc":[{"batb":[[0,1.05,2449.79],[1,1.04,23.9],[2,1.03,70.09]],"batl":[[2,1.09,291.67]],"ltp":1.04,"tv":20130.6,"id":9634485},{"batb":[[0,15,4],[1,14.5,1],[2,14,1]],"ltp":26.0,"tv":1640.34,"id":9712888}]}]}
{"op":"mcm","clk":"4233850037","pt":1631539364561,"mc":[{"id":"1.187557759","rc":[{"trd":[[1.06,271.07]],"batl":[[0,1.06,828.79],[1,1.07,1948.47],[2,1.08,390.5]],"ltp":1.06,"tv":20247.98,"id":9634485},{"trd":[[17.5,7.11]],"batl":[[0,21,82.49],[1,990,0.01],[2,990,0]],"ltp":17.5,"tv":1647.45,"id":9712888}],"tv":21895.43}]}
{"op":"mcm","clk":"4233850119","pt":1631539365287,"mc":[{"id":"1.187557759","rc":[{"batb":[[2,1.03,1663.39]],"ltp":1.06,"tv":20247.98,"id":9634485}]}]}
{"op":"mcm","clk":"4233850217","pt":1631539366281,"mc":[{"id":"1.187557759","rc":[{"trd":[[1.06,1437.36]],"batl":[[0,1.06,245.65]],"ltp":1.06,"tv":21414.27,"id":9634485}],"tv":23061.73}]}
{"op":"mcm","clk":"4233850765","pt":1631539371302,"mc":[{"id":"1.187557759","rc":[{"batb":[[0,1.05,2746.79]],"ltp":1.06,"tv":21414.27,"id":9634485}]}]}
{"op":"mcm","clk":"4233851106","pt":1631539374762,"mc":[{"id":"1.187557759","rc":[{"batl":[[2,1.08,350.3]],"ltp":1.06,"tv":21414.27,"id":9634485}]}]}
{"op":"mcm","clk":"4233851396","pt":1631539377683,"mc":[{"id":"1.187557759","rc":[{"batb":[[0,1.05,2832.51]],"batl":[[1,1.07,2056.98]],"ltp":1.06,"tv":21414.27,"id":9634485},{"batl":[[0,21,86.78]],"ltp":17.5,"tv":1647.45,"id":9712888}]}]}
{"op":"mcm","clk":"4233851796","pt":1631539381804,"mc":[{"id":"1.187557759","rc":[{"batb":[[0,1.05,954.16],[1,1.03,1649.11],[2,1.02,1010.78]],"batl":[[1,1.07,990.38]],"ltp":1.06,"tv":21414.27,"id":9634485},{"batb":[[0,15,2],[1,13.5,2],[2,12.5,9.29]],"batl":[[0,990,0.01],[1,990,0]],"ltp":17.5,"tv":1647.45,"id":9712888}]}]}
{"op":"mcm","clk":"4233851839","pt":1631539382277,"mc":[{"id":"1.187557759","rc":[{"batb":[[0,1.05,750.78],[1,1.03,1593.3]],"batl":[[1,1.07,762.75]],"ltp":1.06,"tv":21414.27,"id":9634485},{"batb":[[2,12,10.29]],"ltp":17.5,"tv":1647.45,"id":9712888}]}]}
{"op":"mcm","clk":"4233851970","pt":1631539383518,"mc":[{"id":"1.187557759","rc":[{"batb":[[0,1.05,453.78]],"ltp":1.06,"tv":21414.27,"id":9634485}]}]}
{"op":"mcm","clk":"4233852300","pt":1631539386697,"mc":[{"id":"1.187557759","rc":[{"batb":[[0,1.05,657.16]],"batl":[[1,1.07,990.38]],"ltp":1.06,"tv":21414.27,"id":9634485}]}]}
{"op":"mcm","clk":"4233852421","pt":1631539387895,"mc":[{"id":"1.187557759","rc":[{"batl":[[0,1.06,247.39]],"ltp":1.06,"tv":21414.27,"id":9634485}]}]}
{"op":"mcm","clk":"4233852590","pt":1631539389608,"mc":[{"id":"1.187557759","rc":[{"trd":[[1.06,1519.91]],"batl":[[0,1.06,164.84]],"ltp":1.06,"tv":21496.82,"id":9634485},{"trd":[[17.5,12.11]],"ltp":17.5,"tv":1652.45,"id":9712888}],"tv":23149.28}]}
{"op":"mcm","clk":"4233852680","pt":1631539390498,"mc":[{"id":"1.187557759","rc":[{"batb":[[0,1.05,453.78]],"batl":[[1,1.07,762.75]],"ltp":1.06,"tv":21496.82,"id":9634485}]}]}
{"op":"mcm","clk":"4233852838","pt":1631539392325,"mc":[{"id":"1.187557759","rc":[{"batl":[[1,1.07,538.89]],"ltp":1.06,"tv":21496.82,"id":9634485}]}]}
{"op":"mcm","clk":"4233852918","pt":1631539393107,"mc":[{"id":"1.187557759","rc":[{"batb":[[1,1.04,205.33],[2,1.03,1593.3]],"ltp":1.06,"tv":21496.82,"id":9634485}]}]}
{"op":"mcm","clk":"4233853028","pt":1631539394204,"mc":[{"id":"1.187557759","rc":[{"batb":[[2,1.02,1010.78]],"ltp":1.06,"tv":21496.82,"id":9634485}]}]}
{"op":"mcm","clk":"4233853163","pt":1631539395301,"mc":[{"id":"1.187557759","rc":[{"batb":[[0,1.05,1262.55],[2,1.03,55.81]],"batl":[[0,1.06,698.49],[1,1.07,2814.34],[2,1.08,359.56]],"ltp":1.06,"tv":21496.82,"id":9634485},{"batb":[[0,17.5,2],[1,16.5,1.82],[2,15.5,1.8]],"batl":[[0,21,44.72],[1,990,0.01]],"ltp":17.5,"tv":1652.45,"id":9712888}]}]}
{"op":"mcm","clk":"4233853284","pt":1631539396529,"mc":[{"id":"1.187557759","rc":[{"batb":[[1,1.04,243.79],[2,1.03,70.23]],"ltp":1.06,"tv":21496.82,"id":9634485}]}]}
{"op":"mcm","clk":"4233853384","pt":1631539397502,"mc":[{"id":"1.187557759","rc":[{"trd":[[1.05,2085.72]],"batb":[[0,1.05,1259.66]],"ltp":1.05,"tv":21502.6,"id":9634485}],"tv":23155.06}]}
{"op":"mcm","clk":"4233853790","pt":1631539401715,"mc":[{"id":"1.187557759","rc":[{"trd":[[1.05,2121.8]],"batb":[[0,1.05,1583.62]],"ltp":1.05,"tv":21538.68,"id":9634485}],"tv":23191.14}]}
{"op":"mcm","clk":"4233854704","pt":1631539410558,"mc":[{"id":"1.187557759","rc":[{"batb":[[0,1.05,1597.25]],"ltp":1.05,"tv":21538.68,"id":9634485}]}]}
{"op":"mcm","clk":"4233854927","pt":1631539412745,"mc":[{"id":"1.187557759","rc":[{"batb":[[0,1.05,355.63],[1,1.04,205.33],[2,1.03,55.81]],"batl":[[0,1.06,164.84],[1,1.07,538.89],[2,1.08,350.3]],"ltp":1.05,"tv":21538.68,"id":9634485},{"batb":[[0,15,2],[1,13.5,2],[2,12,9.54]],"batl":[[0,990,0.01],[1,990,0]],"ltp":17.5,"tv":1652.45,"id":9712888}]}]}
{"op":"mcm","clk":"4233854993","pt":1631539413370,"mc":[{"id":"1.187557759","rc":[{"batb":[[0,1.05,13.63],[2,1.02,3224.61]],"ltp":1.05,"tv":21538.68,"id":9634485}]}]}
{"op":"mcm","clk":"4233855209","pt":1631539415446,"mc":[{"id":"1.187557759","rc":[{"batb":[[1,1.04,663.48]],"batl":[[1,1.07,990.38]],"ltp":1.05,"tv":21538.68,"id":9634485}]}]}
{"op":"mcm","clk":"4233855404","pt":1631539417065,"mc":[{"id":"1.187557759","rc":[{"batl":[[1,1.07,345.5]],"ltp":1.05,"tv":21538.68,"id":9634485}]}]}
{"op":"mcm","clk":"4233855531","pt":1631539418465,"mc":[{"id":"1.187557759","rc":[{"batb":[[2,1.02,1010.78]],"ltp":1.05,"tv":21538.68,"id":9634485}]}]}
{"op":"mcm","clk":"4233855790","pt":1631539420753,"mc":[{"id":"1.187557759","rc":[{"trd":[[1.05,2149.06]],"batb":[[0,1.04,2147.62],[1,1.02,56.36],[2,1.01,50.17]],"batl":[[0,1.05,203.22],[1,1.06,2673.14],[2,1.07,345.5]],"ltp":1.05,"tv":21565.94,"id":9634485},{"batb":[[0,18.5,4.87],[1,18,2.44],[2,17.5,4.44]],"batl":[[0,26,65.82],[1,990,0.01]],"ltp":17.5,"tv":1652.45,"id":9712888}],"tv":23218.39}]}
{"op":"mcm","clk":"4233855846","pt":1631539421271,"mc":[{"id":"1.187557759","rc":[{"batb":[[1,1.03,9.71],[2,1.02,56.36]],"ltp":1.05,"tv":21565.94,"id":9634485},{"batl":[[1,28,1.08],[2,990,0.01]],"ltp":17.5,"tv":1652.45,"id":9712888}]}]}
{"op":"mcm","clk":"4233856016","pt":1631539423299,"mc":[{"id":"1.187557759","rc":[{"batl":[[1,1.06,2686.19]],"ltp":1.05,"tv":21565.94,"id":9634485}]}]}
{"op":"mcm","clk":"4233856423","pt":1631539427267,"mc":[{"id":"1.187557759","rc":[{"batb":[[0,1.04,2339.62]],"ltp":1.05,"tv":21565.94,"id":9634485}]}]}
{"op":"mcm","clk":"4233856735","pt":1631539430091,"mc":[{"id":"1.187557759","rc":[{"batl":[[0,1.05,199.49]],"ltp":1.05,"tv":21565.94,"id":9634485},{"batl":[[0,26,59.37]],"ltp":17.5,"tv":1652.45,"id":9712888}]}]}
{"op":"mcm","clk":"4233857134","pt":1631539433590,"mc":[{"id":"1.187557759","rc":[{"batb":[[0,1.04,192],[1,1.01,4143.58],[2,1.02,0]],"batl":[[0,1.06,290.08],[1,1.07,345.5],[2,1.08,350.3]],"ltp":1.05,"tv":21565.94,"id":9634485},{"batb":[[0,15,2],[1,13.5,2],[2,13,8.2]],"batl":[[0,990,0.01],[1,28,0],[2,990,0]],"ltp":17.5,"tv":1652.45,"id":9712888}]}]}
{"op":"mcm","clk":"4233857228","pt":1631539434427,"mc":[{"id":"1.187557759","rc":[{"batb":[[0,1.01,4143.58],[1,1.01,0]],"ltp":1.05,"tv":21565.94,"id":9634485}]}]}
{"op":"mcm","clk":"4233857474","pt":1631539436820,"mc":[{"id":"1.187557759","rc":[{"batb":[[0,1.03,383],[1,1.02,550],[2,1.01,5193.58]],"batl":[[0,1.06,383.08],[1,1.07,444.5],[2,1.08,448.3]],"ltp":1.05,"tv":21565.94,"id":9634485},{"batb":[[0,17.5,2],[1,15,5],[2,13.5,5]],"batl":[[0,36,2],[1,55,2],[2,110,2]],"ltp":17.5,"tv":1652.45,"id":9712888}]}]}
{"op":"mcm","clk":"4233857601","pt":1631539438236,"mc":[{"id":"1.187557759","rc":[{"batb":[[0,1.04,663.48],[1,1.03,383],[2,1.02,550]],"batl":[[0,1.05,487.63],[1,1.06,425.77],[2,1.07,444.5]],"ltp":1.05,"tv":21565.94,"id":9634485}]}]}
{"op":"mcm","clk":"4233857761","pt":1631539439534,"mc":[{"id":"1.187557759","rc":[{"batb":[[0,1.04,874.48]],"ltp":1.05,"tv":21565.94,"id":9634485}]}]}
{"op":"mcm","clk":"4233858080","pt":1631539442528,"mc":[{"id":"1.187557759","rc":[{"batb":[[0,1.04,211]],"batl":[[0,1.06,383.08],[1,1.07,444.5],[2,1.08,448.3]],"ltp":1.05,"tv":21565.94,"id":9634485}]}]}
{"op":"mcm","clk":"4233858320","pt":1631539444736,"mc":[{"id":"1.187557759","rc":[{"batb":[[0,1.03,383],[1,1.02,550],[2,1.01,5193.58]],"batl":[[0,1.06,257.84],[2,1.08,111.11]],"ltp":1.05,"tv":21565.94,"id":9634485}]}]}
{"op":"mcm","clk":"4233858425","pt":1631539445728,"mc":[{"id":"1.187557759","rc":[{"batb":[[0,1.03,1052.93]],"ltp":1.05,"tv":21565.94,"id":9634485}]}]}
{"op":"mcm","clk":"4233858461","pt":1631539446043,"mc":[{"id":"1.187557759","rc":[{"batb":[[2,1.01,1071.7]],"batl":[[2,1.08,13.11]],"ltp":1.05,"tv":21565.94,"id":9634485},{"batb":[[2,13.5,2]],"ltp":17.5,"tv":1652.45,"id":9712888}]}]}
{"op":"mcm","clk":"4233858694","pt":1631539447734,"mc":[{"id":"1.187557759","rc":[{"batb":[[2,1.01,1157.09]],"batl":[[0,1.04,539.76],[1,1.05,437.36],[2,1.06,3771.28]],"ltp":1.05,"tv":21565.94,"id":9634485},{"batb":[[0,24,3.74],[1,21,2],[2,18.5,6.49]],"batl":[[0,34,76.36],[1,36,2],[2,55,2]],"ltp":17.5,"tv":1652.45,"id":9712888}]}]}
{"op":"mcm","clk":"4233858774","pt":1631539448456,"mc":[{"id":"1.187557759","rc":[{"batb":[[1,1.02,559.8]],"ltp":1.05,"tv":21565.94,"id":9634485}]}]}
{"op":"mcm","clk":"4233858844","pt":1631539449035,"mc":[{"id":"1.187557759","rc":[{"batl":[[1,1.05,536.36]],"ltp":1.05,"tv":21565.94,"id":9634485},{"batb":[[1,21,4]],"ltp":17.5,"tv":1652.45,"id":9712888}]}]}
{"op":"mcm","clk":"4233858998","pt":1631539450345,"mc":[{"id":"1.187557759","rc":[{"batb":[[2,1.01,5087.35]],"ltp":1.05,"tv":21565.94,"id":9634485}]}]}
{"op":"mcm","clk":"4233859535","pt":1631539455438,"mc":[{"id":"1.187557759","rc":[{"batl":[[2,1.06,4165.53]],"ltp":1.05,"tv":21565.94,"id":9634485}]}]}
{"op":"mcm","clk":"4233860047","pt":1631539459664,"mc":[{"id":"1.187557759","rc":[{"trd":[[1.04,5749.88]],"batl":[[0,1.04,529.17],[1,1.05,272.45]],"ltp":1.04,"tv":21587.12,"id":9634485}],"tv":23239.57}]}
{"op":"mcm","clk":"4233860450","pt":1631539463573,"mc":[{"id":"1.187557759","rc":[{"batb":[[1,1.02,550]],"batl":[[0,1.04,502.39],[2,1.06,652.09]],"ltp":1.04,"tv":21587.12,"id":9634485},{"batb":[[0,21,4],[1,17.5,4],[2,17,7.03]],"batl":[[0,36,2],[1,55,2],[2,110,2]],"ltp":17.5,"tv":1652.45,"id":9712888}]}]}
{"op":"mcm","clk":"4233860551","pt":1631539464390,"mc":[{"id":"1.187557759","rc":[{"trd":[[1.04,5750.26]],"batb":[[0,1.02,550],[1,1.01,5001.97],[2,1.01,0]],"batl":[[0,1.05,159.55],[1,1.06,652.09],[2,1.07,444.5]],"ltp":1.04,"tv":21587.5,"id":9634485},{"batb":[[0,17.5,4],[1,15,5],[2,14.5,12.05]],"batl":[[0,55,2],[1,110,2],[2,990,0.01]],"ltp":17.5,"tv":1652.45,"id":9712888}],"tv":23239.95}]}
{"op":"mcm","clk":"4233860873","pt":1631539467275,"mc":[{"id":"1.187557759","rc":[{"batb":[[0,1.02,1226.49]],"batl":[[0,1.05,231.87],[1,1.06,1073.36]],"ltp":1.04,"tv":21587.5,"id":9634485}]}]}
{"op":"mcm","clk":"4233861114","pt":1631539469466,"mc":[{"id":"1.187557759","rc":[{"batb":[[0,1.02,550]],"ltp":1.04,"tv":21587.5,"id":9634485}]}]}
{"op":"mcm","clk":"4233861350","pt":1631539471664,"mc":[{"id":"1.187557759","rc":[{"batb":[[1,1.01,1071.7]],"batl":[[0,1.05,231.96]],"ltp":1.04,"tv":21587.5,"id":9634485}]}]}
{"op":"mcm","clk":"4233861465","pt":1631539472696,"mc":[{"id":"1.187557759","rc":[{"batb":[[0,1.04,1008.48],[1,1.03,9.71],[2,1.02,56.36]],"batl":[[1,1.06,3018.84],[2,1.07,345.5]],"ltp":1.04,"tv":21587.5,"id":9634485},{"batb":[[0,17.5,2],[1,15,2]],"batl":[[0,25,1.6],[1,29,5.16],[2,34,261]],"ltp":17.5,"tv":1652.45,"id":9712888}]}]}
{"op":"mcm","clk":"4233861557","pt":1631539473477,"mc":[{"id":"1.187557759","rc":[{"batb":[[0,19,1.58],[1,17.5,2],[2,15,2]],"batl":[[1,29,3.1]],"ltp":17.5,"tv":1652.45,"id":9712888}]}]}
{"op":"mcm","clk":"4233861598","pt":1631539473895,"mc":[{"id":"1.187557759","rc":[{"batb":[[0,1.04,1308.48],[1,1.03,392.71]],"ltp":1.04,"tv":21587.5,"id":9634485},{"batl":[[1,26,2],[2,29,3.1]],"ltp":17.5,"tv":1652.45,"id":9712888}]}]}
{"op":"mcm","clk":"4233861810","pt":1631539475775,"mc":[{"id":"1.187557759","rc":[{"batb":[[0,1.04,1397.32]],"batl":[[1,1.06,3165.74]],"ltp":1.04,"tv":21587.5,"id":9634485},{"batl":[[1,26,5.55]],"ltp":17.5,"tv":1652.45,"id":9712888}]}]}
{"op":"mcm","clk":"4233861817","pt":1631539475879,"mc":[{"id":"1.187557759","rc":[{"batb":[[0,1.04,1097.32],[1,1.03,9.71]],"ltp":1.04,"tv":21587.5,"id":9634485},{"batl":[[1,26,3.55]],"ltp":17.5,"tv":1652.45,"id":9712888}]}]}
{"op":"mcm","clk":"4233862288","pt":1631539480270,"mc":[{"id":"1.187557759","rc":[{"batb":[[0,1.04,1294.32]],"ltp":1.04,"tv":21587.5,"id":9634485}]}]}
{"op":"mcm","clk":"4233862555","pt":1631539482710,"mc":[{"id":"1.187557759","rc":[{"batb":[[0,1.04,860.48],[1,1.02,56.36],[2,1.01,4172.04]],"batl":[[1,1.06,980.36]],"ltp":1.04,"tv":21587.5,"id":9634485},{"batb":[[0,17.5,2],[1,15,2],[2,14.5,12.05]],"batl":[[0,990,0.01],[1,26,0],[2,29,0]],"ltp":17.5,"tv":1652.45,"id":9712888}]}]}
{"op":"mcm","clk":"4233862639","pt":1631539483388,"mc":[{"id":"1.187557759","rc":[{"batb":[[0,1.01,4143.58],[1,1.02,0],[2,1.01,0]],"batl":[[0,1.06,714.6],[1,1.07,345.5],[2,1.08,295.55]],"ltp":1.04,"tv":21587.5,"id":9634485},{"batb":[[2,13.5,2]],"ltp":17.5,"tv":1652.45,"id":9712888}]}]}
{"op":"mcm","clk":"4233862924","pt":1631539485804,"mc":[{"id":"1.187557759","rc":[{"batb":[[0,1.03,669.93],[1,1.01,4143.58]],"batl":[[0,1.06,696.49],[1,1.07,836.4]],"ltp":1.04,"tv":21587.5,"id":9634485}]}]}
{"op":"mcm","clk":"4233862952","pt":1631539486009,"mc":[{"id":"1.187557759","rc":[{"batb":[[0,1.01,4143.58],[1,1.01,0]],"batl":[[1,1.07,345.5]],"ltp":1.04,"tv":21587.5,"id":9634485}]}]}
{"op":"mcm","clk":"4233863256","pt":1631539488519,"mc":[{"id":"1.187557759","rc":[{"batb":[[0,1.04,663.48],[1,1.01,4143.58]],"batl":[[0,1.05,539.53],[1,1.06,696.4],[2,1.07,345.5]],"ltp":1.04,"tv":21587.5,"id":9634485}]}]}
{"op":"mcm","clk":"4233863302","pt":1631539488896,"mc":[{"id":"1.187557759","rc":[{"batl":[[0,1.05,518.63]],"ltp":1.04,"tv":21587.5,"id":9634485}]}]}
{"op":"mcm","clk":"4233863531","pt":1631539490815,"mc":[{"id":"1.187557759","rc":[{"trd":[[1.04,5765.04]],"batb":[[0,1.04,656.09]],"ltp":1.04,"tv":21602.28,"id":9634485}],"tv":23254.73}]}
{"op":"mcm","clk":"4233863586","pt":1631539491234,"mc":[{"id":"1.187557759","rc":[{"batb":[[0,1.01,4143.58],[1,1.01,0]],"batl":[[0,1.06,696.49],[1,1.07,345.5],[2,1.08,295.55]],"ltp":1.04,"tv":21602.28,"id":9634485}]}]}
{"op":"mcm","clk":"4233863969","pt":1631539494313,"mc":[{"id":"1.187557759","rc":[{"batb":[[0,1.03,669.93],[1,1.01,4143.58]],"batl":[[0,1.06,718.61],[1,1.07,832.43]],"ltp":1.04,"tv":21602.28,"id":9634485}]}]}
{"op":"mcm","clk":"4233864805","pt":1631539502242,"mc":[{"id":"1.187557759","rc":[{"batl":[[0,1.06,559.18],[1,1.07,345.5],[2,1.08,13.11]],"ltp":1.04,"tv":21602.28,"id":9634485},{"batb":[[2,13,8.28]],"ltp":17.5,"tv":1652.45,"id":9712888}]}]}
{"op":"mcm","clk":"4233864890","pt":1631539503030,"mc":[{"id":"1.187557759","rc":[{"batb":[[1,1.01,21.7]],"ltp":1.04,"tv":21602.28,"id":9634485}]}]}
{"op":"mcm","clk":"4233865090","pt":1631539504810,"mc":[{"id":"1.187557759","rc":[{"batl":[[0,1.04,766.03],[1,1.05,4935.67],[2,1.06,568.52]],"ltp":1.04,"tv":21602.28,"id":9634485},{"batb":[[0,23,6.52],[1,21,85.79],[2,17.5,2]],"batl":[[0,34,71.55],[1,990,0.01]],"ltp":17.5,"tv":1652.45,"id":9712888}]}]}
{"op":"mcm","clk":"4233865182","pt":1631539505710,"mc":[{"id":"1.187557759","rc":[{"batb":[[1,1.02,9.8],[2,1.01,107.09]],"batl":[[0,1.04,612.19],[1,1.05,2102.32]],"ltp":1.04,"tv":21602.28,"id":9634485},{"batb":[[1,21,87.79]],"ltp":17.5,"tv":1652.45,"id":9712888}]}]}
{"op":"mcm","clk":"4233865338","pt":1631539507115,"mc":[{"id":"1.187557759","rc":[{"batb":[[2,1.01,4037.35]],"ltp":1.04,"tv":21602.28,"id":9634485}]}]}
{"op":"mcm","clk":"4233865661","pt":1631539509751,"mc":[{"id":"1.187557759","rc":[{"batl":[[2,1.06,1409.05]],"ltp":1.04,"tv":21602.28,"id":9634485},{"batl":[[0,28,5.87],[1,34,71.55],[2,990,0.01]],"ltp":17.5,"tv":1652.45,"id":9712888}]}]}
{"op":"mcm","clk":"4233865691","pt":1631539509961,"mc":[{"id":"1.187557759","rc":[{"batl":[[2,1.06,568.52]],"ltp":1.04,"tv":21602.28,"id":9634485},{"batl":[[0,34,71.55],[1,990,0.01],[2,990,0]],"ltp":17.5,"tv":1652.45,"id":9712888}]}]}
{"op":"mcm","clk":"4233866432","pt":1631539516755,"mc":[{"id":"1.187557759","rc":[{"batl":[[1,1.05,1853.56]],"ltp":1.04,"tv":21602.28,"id":9634485}]}]}
{"op":"mcm","clk":"4233867612","pt":1631539527568,"mc":[{"id":"1.187557759","rc":[{"batb":[[0,1.01,3951.97],[1,1.02,0],[2,1.01,0]],"batl":[[0,1.05,123.88],[1,1.06,559.09],[2,1.07,345.5]],"ltp":1.04,"tv":21602.28,"id":9634485},{"batb":[[0,17.5,2],[1,15,2],[2,14.5,12.05]],"batl":[[0,990,0.01],[1,990,0]],"ltp":17.5,"tv":1652.45,"id":9712888}]}]}
{"op":"mcm","clk":"4233867891","pt":1631539530479,"mc":[{"id":"1.187557759","rc":[{"batb":[[0,1.02,676.49],[1,1.01,3951.97]],"batl":[[0,1.05,744.01],[1,1.06,945.35]],"ltp":1.04,"tv":21602.28,"id":9634485},{"batb":[[0,21,2],[1,17.5,2],[2,15,2]],"ltp":17.5,"tv":1652.45,"id":9712888}]}]}
{"op":"mcm","clk":"4233867996","pt":1631539531477,"mc":[{"id":"1.187557759","rc":[{"batl":[[0,1.03,1.38],[1,1.05,744.01],[2,1.06,945.35]],"ltp":1.04,"tv":21602.28,"id":9634485}]}]}
{"op":"mcm","clk":"4233868201","pt":1631539533406,"mc":[{"id":"1.187557759","rc":[{"batb":[[0,1.01,3951.97],[1,1.01,0]],"batl":[[1,1.05,267.31]],"ltp":1.04,"tv":21602.28,"id":9634485},{"batb":[[0,17.5,2],[1,15,2],[2,14.5,12.05]],"ltp":17.5,"tv":1652.45,"id":9712888}]}]}
{"op":"mcm","clk":"4233868326","pt":1631539534699,"mc":[{"id":"1.187557759","rc":[{"batb":[[0,1.01,21.7]],"ltp":1.04,"tv":21602.28,"id":9634485}]}]}
{"op":"mcm","clk":"4233868503","pt":1631539536466,"mc":[{"id":"1.187557759","rc":[{"trd":[[1.03,662.62]],"batb":[[0,1.04,2328.14],[1,1.03,9.71],[2,1.02,56.36]],"batl":[[0,1.05,267.31],[1,1.06,3249.47],[2,1.07,345.5]],"ltp":1.03,"tv":21605.04,"id":9634485},{"batl":[[0,24,8.34],[1,26,52.84],[2,29,1.04]],"ltp":17.5,"tv":1652.45,"id":9712888}],"tv":23257.49}]}
{"op":"mcm","clk":"4233868609","pt":1631539537657,"mc":[{"id":"1.187557759","rc":[{"batb":[[0,1.04,2628.14],[1,1.03,392.71],[2,1.02,606.36]],"batl":[[1,1.06,3342.47],[2,1.07,440.5]],"ltp":1.03,"tv":21605.04,"id":9634485},{"batb":[[0,19,1.58],[1,17.5,4],[2,15,5]],"batl":[[1,26,54.84]],"ltp":17.5,"tv":1652.45,"id":9712888}]}]}
{"op":"mcm","clk":"4233868676","pt":1631539538494,"mc":[{"id":"1.187557759","rc":[{"batb":[[0,1.04,2328.14],[1,1.03,9.71],[2,1.02,56.36]],"batl":[[1,1.06,3249.47],[2,1.07,345.5]],"ltp":1.03,"tv":21605.04,"id":9634485},{"batb":[[1,17.5,2],[2,15,2]],"batl":[[1,26,52.84]],"ltp":17.5,"tv":1652.45,"id":9712888}]}]}
{"op":"mcm","clk":"4233868729","pt":1631539538964,"mc":[{"id":"1.187557759","rc":[{"trd":[[1.04,5775.8]],"batb":[[0,1.04,2322.76]],"ltp":1.04,"tv":21615.8,"id":9634485}],"tv":23268.25}]}
{"op":"mcm","clk":"4233868821","pt":1631539540319,"mc":[{"id":"1.187557759","rc":[{"batb":[[0,1.04,2662.76]],"ltp":1.04,"tv":21615.8,"id":9634485}]}]}
{"op":"mcm","clk":"4233869518","pt":1631539548075,"mc":[{"id":"1.187557759","rc":[{"batb":[[0,1.04,2324.52]],"ltp":1.04,"tv":21615.8,"id":9634485}]}]}
{"op":"mcm","clk":"4233870031","pt":1631539553711,"mc":[{"id":"1.187557759","rc":[{"batb":[[0,1.04,340],[1,1.01,4118.71],[2,1.02,0]],"batl":[[0,1.06,748.04],[1,1.07,345.5],[2,1.08,321.05]],"ltp":1.04,"tv":21615.8,"id":9634485},{"batb":[[0,17.5,2],[1,15,2],[2,14.5,12.05]],"batl":[[0,990,0.01],[1,26,0],[2,29,0]],"ltp":17.5,"tv":1652.45,"id":9712888}]}]}
{"op":"mcm","clk":"4233870103","pt":1631539554387,"mc":[{"id":"1.187557759","rc":[{"batb":[[0,1.01,4118.71],[1,1.01,0]],"ltp":1.04,"tv":21615.8,"id":9634485},{"batb":[[2,13,8.28]],"ltp":17.5,"tv":1652.45,"id":9712888}]}]}
{"op":"mcm","clk":"4233870302","pt":1631539556621,"mc":[{"id":"1.187557759","rc":[{"batb":[[0,1.03,669.93],[1,1.01,4118.71]],"batl":[[1,1.07,803.28]],"ltp":1.04,"tv":21615.8,"id":9634485}]}]}
{"op":"mcm","clk":"4233871472","pt":1631539566613,"mc":[{"id":"1.187557759","rc":[{"batb":[[0,1.01,4118.71],[1,1.01,0]],"ltp":1.04,"tv":21615.8,"id":9634485}]}]}
{"op":"mcm","clk":"4233871650","pt":1631539568219,"mc":[{"id":"1.187557759","rc":[{"batb":[[0,1.01,21.7]],"ltp":1.04,"tv":21615.8,"id":9634485}]}]}
{"op":"mcm","clk":"4233871825","pt":1631539569737,"mc":[{"id":"1.187557759","rc":[{"trd":[[1.05,2149.24]],"batb":[[0,1.05,6068.99],[1,1.04,9.62],[2,1.03,55.81]],"batl":[[0,1.06,747.95],[1,1.07,2517.87]],"ltp":1.05,"tv":21615.98,"id":9634485},{"batl":[[0,21,59.23],[1,23,3.91],[2,25,4.8]],"ltp":17.5,"tv":1652.45,"id":9712888}],"tv":23268.44}]}
{"op":"mcm","clk":"4233871923","pt":1631539570623,"mc":[{"id":"1.187557759","rc":[{"batb":[[0,1.05,2183.38]],"batl":[[2,1.08,330.31]],"ltp":1.05,"tv":21615.98,"id":9634485},{"batb":[[1,16,1.88],[2,15,3.88]],"ltp":17.5,"tv":1652.45,"id":9712888}]}]}
{"op":"mcm","clk":"4233872160","pt":1631539572963,"mc":[{"id":"1.187557759","rc":[{"batl":[[0,1.06,353.7]],"ltp":1.05,"tv":21615.98,"id":9634485},{"batb":[[0,16,1.88],[1,15,3.88],[2,13,8.28]],"ltp":17.5,"tv":1652.45,"id":9712888}]}]}
{"op":"mcm","clk":"4233872424","pt":1631539575355,"mc":[{"id":"1.187557759","rc":[{"batb":[[0,1.05,2374.38]],"ltp":1.05,"tv":21615.98,"id":9634485}]}]}
{"op":"mcm","clk":"4233872881","pt":1631539579836,"mc":[{"id":"1.187557759","rc":[{"batl":[[0,1.06,335.92]],"ltp":1.05,"tv":21615.98,"id":9634485}]}]}
{"op":"mcm","clk":"4233873021","pt":1631539581460,"mc":[{"id":"1.187557759","rc":[{"batb":[[0,1.05,2032.8]],"ltp":1.05,"tv":21615.98,"id":9634485}]}]}
{"op":"mcm","clk":"4233873187","pt":1631539582784,"mc":[{"id":"1.187557759","rc":[{"batl":[[1,1.07,2535.49]],"ltp":1.05,"tv":21615.98,"id":9634485}]}]}
{"op":"mcm","clk":"4233873839","pt":1631539588291,"mc":[{"id":"1.187557759","rc":[{"trd":[[1.05,2156.96]],"batb":[[0,1.05,2028.94]],"ltp":1.05,"tv":21623.71,"id":9634485}],"tv":23276.16}]}
{"op":"mcm","clk":"4233873990","pt":1631539589644,"mc":[{"id":"1.187557759","rc":[{"trd":[[1.05,2439.44]],"batb":[[0,1.05,1887.7]],"ltp":1.05,"tv":21906.18,"id":9634485}],"tv":23558.64}]}
{"op":"mcm","clk":"4233875176","pt":1631539600707,"mc":[{"id":"1.187557759","rc":[{"batb":[[0,1.05,191],[1,1.02,3151.35],[2,1.01,21.7]],"batl":[[0,1.06,164.84],[1,1.08,13.11],[2,1.09,260.5]],"ltp":1.05,"tv":21906.18,"id":9634485},{"batb":[[0,13,8.28],[1,12,2],[2,11,2]],"batl":[[0,990,0.01],[1,23,0],[2,25,0]],"ltp":17.5,"tv":1652.45,"id":9712888}]}]}
{"op":"mcm","clk":"4233875230","pt":1631539601280,"mc":[{"id":"1.187557759","rc":[{"batb":[[0,1.02,2194.87],[1,1.01,21.7],[2,1.01,0]],"ltp":1.05,"tv":21906.18,"id":9634485},{"batb":[[0,12,2],[1,11,2],[2,10,15.9]],"ltp":17.5,"tv":1652.45,"id":9712888}]}]}
{"op":"mcm","clk":"4233875292","pt":1631539601902,"mc":[{"id":"1.187557759","rc":[{"trd":[[1.06,1523.32]],"batl":[[0,1.06,163.14]],"ltp":1.06,"tv":21909.59,"id":9634485}],"tv":23562.04}]}
{"op":"mcm","clk":"4233875433","pt":1631539603523,"mc":[{"id":"1.187557759","rc":[{"batb":[[0,1.04,663.48],[1,1.02,2194.87],[2,1.01,21.7]],"batl":[[2,1.09,859.15]],"ltp":1.06,"tv":21909.59,"id":9634485}]}]}
{"op":"mcm","clk":"4233875506","pt":1631539604100,"mc":[{"id":"1.187557759","rc":[{"batb":[[0,1.04,963.48],[1,1.03,383],[2,1.02,2744.87]],"batl":[[2,1.09,966.15]],"ltp":1.06,"tv":21909.59,"id":9634485},{"batb":[[0,12,5],[1,11,6],[2,10,19.9]],"batl":[[0,26,2],[1,36,2],[2,55,2]],"ltp":17.5,"tv":1652.45,"id":9712888}]}]}
{"op":"mcm","clk":"4233875678","pt":1631539605815,"mc":[{"id":"1.187557759","rc":[{"batl":[[2,1.09,367.5]],"ltp":1.06,"tv":21909.59,"id":9634485}]}]}
{"op":"mcm","clk":"4233875926","pt":1631539607693,"mc":[{"id":"1.187557759","rc":[{"batb":[[2,1.02,550]],"batl":[[2,1.09,260.5]],"ltp":1.06,"tv":21909.59,"id":9634485},{"batb":[[0,12,2],[1,11,2],[2,10,15.9]],"ltp":17.5,"tv":1652.45,"id":9712888}]}]}
{"op":"mcm","clk":"4233876113","pt":1631539608786,"mc":[{"id":"1.187557759","rc":[{"batb":[[0,1.04,1727.91],[2,1.02,606.36]],"batl":[[0,1.05,521.02],[1,1.06,7013.94],[2,1.07,9.35]],"ltp":1.06,"tv":21909.59,"id":9634485},{"batb":[[0,21,2],[1,19,7.16],[2,18.5,6.94]],"batl":[[0,26,37.72],[1,36,5.78],[2,38,3.68]],"ltp":17.5,"tv":1652.45,"id":9712888}]}]}
{"op":"mcm","clk":"4233876257","pt":1631539609830,"mc":[{"id":"1.187557759","rc":[{"batb":[[1,1.03,392.71]],"batl":[[1,1.06,3541.78]],"ltp":1.06,"tv":21909.59,"id":9634485}]}]}
{"op":"mcm","clk":"4233876299","pt":1631539610195,"mc":[{"id":"1.187557759","rc":[{"batl":[[0,1.05,617.02],[1,1.06,3638.78],[2,1.07,112.35]],"ltp":1.06,"tv":21909.59,"id":9634485},{"batb":[[0,21,4]],"ltp":17.5,"tv":1652.45,"id":9712888}]}]}
{"op":"mcm","clk":"4233876901","pt":1631539615603,"mc":[{"id":"1.187557759","rc":[{"batl":[[1,1.06,4066.03],[2,1.07,464.85]],"ltp":1.06,"tv":21909.59,"id":9634485}]}]}
{"op":"mcm","clk":"4233877018","pt":1631539616694,"mc":[{"id":"1.187557759","rc":[{"batb":[[0,1.04,1984.91]],"ltp":1.06,"tv":21909.59,"id":9634485}]}]}
{"op":"mcm","clk":"4233877430","pt":1631539620529,"mc":[{"id":"1.187557759","rc":[{"batl":[[1,1.06,3760.72]],"ltp":1.06,"tv":21909.59,"id":9634485}]}]}
{"op":"mcm","clk":"4233877719","pt":1631539622828,"mc":[{"id":"1.187557759","rc":[{"batb":[[0,1.04,557],[1,1.03,383],[2,1.02,550]],"batl":[[0,1.05,96],[1,1.06,687.39],[2,1.07,455.5]],"ltp":1.06,"tv":21909.59,"id":9634485},{"batb":[[0,21,2],[1,17.5,4],[2,15,5]],"batl":[[0,26,2],[1,36,2],[2,55,2]],"ltp":17.5,"tv":1652.45,"id":9712888}]}]}
{"op":"mcm","clk":"4233877788","pt":1631539623400,"mc":[{"id":"1.187557759","rc":[{"batb":[[0,1.03,383],[1,1.02,550],[2,1.01,5165.26]],"batl":[[0,1.06,163.14],[1,1.07,455.5],[2,1.08,343.05]],"ltp":1.06,"tv":21909.59,"id":9634485},{"batb":[[0,15,5],[1,12,11.96],[2,11,2]],"batl":[[0,36,2],[1,55,2],[2,110,2]],"ltp":17.5,"tv":1652.45,"id":9712888}]}]}
{"op":"mcm","clk":"4233877991","pt":1631539625322,"mc":[{"id":"1.187557759","rc":[{"batb":[[0,1.03,1052.93]],"batl":[[1,1.07,1032.29]],"ltp":1.06,"tv":21909.59,"id":9634485}]}]}
{"op":"mcm","clk":"4233878156","pt":1631539626830,"mc":[{"id":"1.187557759","rc":[{"batl":[[2,1.08,447.05]],"ltp":1.06,"tv":21909.59,"id":9634485},{"batb":[[1,13.5,3],[2,12,14.96]],"ltp":17.5,"tv":1652.45,"id":9712888}]}]}
{"op":"mcm","clk":"4233879079","pt":1631539636335,"mc":[{"id":"1.187557759","rc":[{"batb":[[0,1.03,383]],"ltp":1.06,"tv":21909.59,"id":9634485}]}]}
{"op":"mcm","clk":"4233879223","pt":1631539637742,"mc":[{"id":"1.187557759","rc":[{"trd":[[1.03,1428.62]],"batb":[[0,1.02,550],[1,1.01,5165.26],[2,1.01,0]],"batl":[[0,1.03,249],[1,1.06,163.14],[2,1.07,1032.29]],"ltp":1.03,"tv":22675.59,"id":9634485},{"batb":[[2,12,11.96]],"ltp":17.5,"tv":1652.45,"id":9712888}],"tv":24328.04}]}
{"op":"mcm","clk":"4233879321","pt":1631539638629,"mc":[{"id":"1.187557759","rc":[{"batb":[[1,1.01,1071.7]],"ltp":1.03,"tv":22675.59,"id":9634485}]}]}
{"op":"mcm","clk":"4233879451","pt":1631539639829,"mc":[{"id":"1.187557759","rc":[{"trd":[[1.03,1926.62],[1.06,1817.76]],"batb":[[0,1.05,2359.02],[1,1.04,23.9],[2,1.03,931.2]],"batl":[[0,1.06,15.92],[1,1.07,1116.64],[2,1.08,433.94]],"ltp":1.06,"tv":23468.03,"id":9634485},{"batb":[[0,15,90.33]],"batl":[[0,21,72.71],[1,25,8],[2,36,2]],"ltp":17.5,"tv":1652.45,"id":9712888}],"tv":25120.48}]}
{"op":"mcm","clk":"4233879543","pt":1631539640550,"mc":[{"id":"1.187557759","rc":[{"batb":[[0,1.05,2609.02],[1,1.04,323.9]],"batl":[[1,1.07,1144.68],[2,1.08,447.96]],"ltp":1.06,"tv":23468.03,"id":9634485},{"batl":[[0,21,74.71],[2,26,2]],"ltp":17.5,"tv":1652.45,"id":9712888}]}]}
{"op":"mcm","clk":"4233879783","pt":1631539642738,"mc":[{"id":"1.187557759","rc":[{"batb":[[0,1.05,2724.81]],"batl":[[1,1.07,1207.56]],"ltp":1.06,"tv":23468.03,"id":9634485}]}]}
{"op":"mcm","clk":"4233880216","pt":1631539647355,"mc":[{"id":"1.187557759","rc":[{"batb":[[0,1.05,3185.81]],"ltp":1.06,"tv":23468.03,"id":9634485}]}]}
{"op":"mcm","clk":"4233880386","pt":1631539649267,"mc":[{"id":"1.187557759","rc":[{"batl":[[1,1.07,1123.21]],"ltp":1.06,"tv":23468.03,"id":9634485}]}]}
{"op":"mcm","clk":"4233880581","pt":1631539651663,"mc":[{"id":"1.187557759","rc":[{"trd":[[1.06,1846.12],[1.07,4055.36]],"batb":[[0,1.07,3318.12],[1,1.05,2850.84],[2,1.04,323.9]],"batl":[[0,1.08,447.96],[1,1.09,283.69],[2,1.1,321.15]],"ltp":1.07,"tv":25742.8,"id":9634485}],"tv":27395.26}]}
{"op":"mcm","clk":"4233880643","pt":1631539652183,"mc":[{"id":"1.187557759","rc":[{"trd":[[1.07,4288.56]],"batb":[[0,1.07,3201.52],[1,1.05,2519.23]],"ltp":1.07,"tv":25976.0,"id":9634485},{"batl":[[0,21,78.79]],"ltp":17.5,"tv":1652.45,"id":9712888}],"tv":27628.46}]}
{"op":"mcm","clk":"4233881012","pt":1631539655502,"mc":[{"id":"1.187557759","rc":[{"trd":[[1.07,7076.36]],"batb":[[0,1.07,1807.62],[1,1.06,409.33],[2,1.05,1814.3]],"batl":[[0,1.08,804.53]],"ltp":1.07,"tv":28763.8,"id":9634485},{"batl":[[2,26,4]],"ltp":17.5,"tv":1652.45,"id":9712888}],"tv":30416.26}]}
{"op":"mcm","clk":"4233881346","pt":1631539658789,"mc":[{"id":"1.187557759","rc":[{"trd":[[1.07,7331.65]],"batb":[[0,1.07,2008.98],[1,1.06,568.28]],"batl":[[0,1.08,960.56]],"ltp":1.07,"tv":29019.09,"id":9634485}],"tv":30671.55}]}
{"op":"mcm","clk":"4233881352","pt":1631539658886,"mc":[{"id":"1.187557759","rc":[{"batb":[[0,1.07,329]],"ltp":1.07,"tv":29019.09,"id":9634485}]}]}
{"op":"mcm","clk":"4233881450","pt":1631539659886,"mc":[{"id":"1.187557759","rc":[{"trd":[[1.07,7338.87]],"batb":[[0,1.07,325.39]],"ltp":1.07,"tv":29026.32,"id":9634485}],"tv":30678.77}]}
{"op":"mcm","clk":"4233881625","pt":1631539661716,"mc":[{"id":"1.187557759","rc":[{"batb":[[1,1.06,639.39]],"batl":[[0,1.08,1086.87]],"ltp":1.07,"tv":29026.32,"id":9634485}]}]}
{"op":"mcm","clk":"4233881675","pt":1631539662401,"mc":[{"id":"1.187557759","rc":[{"batb":[[2,1.05,1732.68]],"ltp":1.07,"tv":29026.32,"id":9634485},{"batl":[[0,21,74.71]],"ltp":17.5,"tv":1652.45,"id":9712888}]}]}
{"op":"mcm","clk":"4233881983","pt":1631539665316,"mc":[{"id":"1.187557759","rc":[{"batl":[[0,1.08,1131.03]],"ltp":1.07,"tv":29026.32,"id":9634485},{"batb":[[1,13.5,6.53]],"batl":[[0,17.5,6.64],[1,21,74.71],[2,25,8]],"ltp":17.5,"tv":1652.45,"id":9712888}]}]}
{"op":"mcm","clk":"4233882134","pt":1631539666718,"mc":[{"id":"1.187557759","rc":[{"batb":[[1,1.05,250],[2,1.04,873.37]],"batl":[[0,1.08,104],[1,1.1,96],[2,1.11,3.53]],"ltp":1.07,"tv":29026.32,"id":9634485},{"batb":[[0,15,3],[1,13.5,3],[2,11,4]],"batl":[[0,21,2],[1,26,4],[2,36,4]],"ltp":17.5,"tv":1652.45,"id":9712888}]}]}
{"op":"mcm","clk":"4233882248","pt":1631539667713,"mc":[{"id":"1.187557759","rc":[{"batb":[[0,1.04,873.37],[1,1.03,844.83],[2,1.02,4065.32]],"batl":[[0,1.07,6.12]],"ltp":1.07,"tv":29026.32,"id":9634485},{"batb":[[0,11,4],[1,9.2,20.25],[2,1.01,115.38]],"batl":[[0,26,4],[1,36,4],[2,55,2]],"ltp":17.5,"tv":1652.45,"id":9712888}]}]}
{"op":"mcm","clk":"4233882341","pt":1631539668709,"mc":[{"id":"1.187557759","rc":[{"batb":[[0,1.05,2971.5],[1,1.04,873.37],[2,1.03,844.83]],"ltp":1.07,"tv":29026.32,"id":9634485},{"batb":[[0,15.5,1.35],[1,11,4],[2,9.2,20.25]],"ltp":17.5,"tv":1652.45,"id":9712888}]}]}
{"op":"mcm","clk":"4233882447","pt":1631539669804,"mc":[{"id":"1.187557759","rc":[{"batb":[[2,1.03,1227.83]],"batl":[[2,1.11,96.53]],"ltp":1.07,"tv":29026.32,"id":9634485},{"batb":[[2,10,4]],"ltp":17.5,"tv":1652.45,"id":9712888}]}]}
{"op":"mcm","clk":"4233882628","pt":1631539671722,"mc":[{"id":"1.187557759","rc":[{"trd":[[1.07,7370.67]],"batb":[[0,1.07,183.97],[1,1.06,439.33],[2,1.05,2971.5]],"batl":[[0,1.08,315.41],[1,1.09,306.56],[2,1.1,96]],"ltp":1.07,"tv":29058.11,"id":9634485},{"trd":[[15.5,1.35]],"batb":[[0,11,4],[1,10,4],[2,9.2,24.25]],"ltp":15.5,"tv":1653.8,"id":9712888}],"tv":30711.92}]}
{"op":"mcm","clk":"4233882926","pt":1631539674596,"mc":[{"id":"1.187557759","rc":[{"trd":[[1.07,7406.03]],"batb":[[0,1.07,166.29],[1,1.06,453.66],[2,1.05,3105.5]],"batl":[[0,1.08,329.5]],"ltp":1.07,"tv":29093.47,"id":9634485}],"tv":30747.28}]}
{"op":"mcm","clk":"4233883344","pt":1631539678811,"mc":[{"id":"1.187557759","rc":[{"batb":[[0,1.05,2971.5],[1,1.04,873.37],[2,1.03,2804.98]],"batl":[[0,1.1,96],[1,1.11,96.53],[2,1.12,97]],"ltp":1.07,"tv":29093.47,"id":9634485}]}]}
{"op":"mcm","clk":"4233883562","pt":1631539681420,"mc":[{"id":"1.187557759","rc":[{"batb":[[1,1.04,1536.85]],"batl":[[1,1.11,587.06],[2,1.12,226.93]],"ltp":1.07,"tv":29093.47,"id":9634485}]}]}
{"op":"mcm","clk":"4233883950","pt":1631539685543,"mc":[{"id":"1.187557759","rc":[{"batl":[[0,1.07,1.7],[1,1.1,96],[2,1.11,587.06]],"ltp":1.07,"tv":29093.47,"id":9634485}]}]}
{"op":"mcm","clk":"4233884660","pt":1631539692936,"mc":[{"id":"1.187557759","rc":[{"batl":[[2,1.11,96.53]],"ltp":1.07,"tv":29093.47,"id":9634485}]}]}
{"op":"mcm","clk":"4233884758","pt":1631539694032,"mc":[{"id":"1.187557759","rc":[{"batl":[[1,1.11,3.53],[2,1.13,14.82]],"ltp":1.07,"tv":29093.47,"id":9634485},{"batb":[[0,9.2,20.25],[1,1.01,115.38],[2,9.2,0]],"ltp":15.5,"tv":1653.8,"id":9712888}]}]}
{"op":"mcm","clk":"4233884923","pt":1631539695651,"mc":[{"id":"1.187557759","rc":[{"batb":[[1,1.04,2323.49],[2,1.03,1227.83]],"batl":[[0,1.06,6759.86],[1,1.07,11.05],[2,1.11,3.53]],"ltp":1.07,"tv":29093.47,"id":9634485},{"batb":[[0,16,9.38],[1,15.5,17.6],[2,15,4.7]],"batl":[[0,26,35.47]],"ltp":15.5,"tv":1653.8,"id":9712888}]}]}
{"op":"mcm","clk":"4233885053","pt":1631539696750,"mc":[{"id":"1.187557759","rc":[{"batb":[[2,1.03,1237.54]],"batl":[[0,1.06,3813.33],[2,1.09,52.74]],"ltp":1.07,"tv":29093.47,"id":9634485},{"batb":[[1,15.5,7.28]],"batl":[[1,32,4.7],[2,36,4]],"ltp":15.5,"tv":1653.8,"id":9712888}]}]}
{"op":"mcm","clk":"4233885155","pt":1631539697444,"mc":[{"id":"1.187557759","rc":[{"batl":[[0,1.06,3921.33],[1,1.07,110.05],[2,1.09,144.74]],"ltp":1.07,"tv":29093.47,"id":9634485},{"batb":[[0,17.5,2],[1,16,1.88],[2,15.5,3.52]],"batl":[[1,36,4.94],[2,55,2]],"ltp":15.5,"tv":1653.8,"id":9712888}]}]}
{"op":"mcm","clk":"4233885467","pt":1631539700650,"mc":[{"id":"1.187557759","rc":[{"batl":[[1,1.07,900.32]],"ltp":1.07,"tv":29093.47,"id":9634485},{"batl":[[0,23,4.45],[1,26,35.47],[2,36,4.94]],"ltp":15.5,"tv":1653.8,"id":9712888}]}]}
{"op":"mcm","clk":"4233885481","pt":1631539700857,"mc":[{"id":"1.187557759","rc":[{"batl":[[1,1.07,110.05]],"ltp":1.07,"tv":29093.47,"id":9634485},{"batl":[[0,26,35.47],[1,36,4.94],[2,55,2]],"ltp":15.5,"tv":1653.8,"id":9712888}]}]}
{"op":"mcm","clk":"4233885631","pt":1631539702370,"mc":[{"id":"1.187557759","rc":[{"batl":[[2,55,4]],"ltp":15.5,"tv":1653.8,"id":9712888}]}]}
{"op":"mcm","clk":"4233885786","pt":1631539703993,"mc":[{"id":"1.187557759","rc":[{"batb":[[0,1.04,2323.49],[1,1.03,1237.54],[2,1.02,1926.2]],"ltp":1.07,"tv":29093.47,"id":9634485}]}]}
{"op":"mcm","clk":"4233885927","pt":1631539705558,"mc":[{"id":"1.187557759","rc":[{"batb":[[0,1.05,304],[1,1.04,2323.49],[2,1.03,1237.54]],"ltp":1.07,"tv":29093.47,"id":9634485}]}]}
{"op":"mcm","clk":"4233886131","pt":1631539707794,"mc":[{"id":"1.187557759","rc":[{"batl":[[0,1.06,3605]],"ltp":1.07,"tv":29093.47,"id":9634485}]}]}
{"op":"mcm","clk":"4233886510","pt":1631539710773,"mc":[{"id":"1.187557759","rc":[{"trd":[[1.05,2743.44]],"batb":[[0,1.04,2323.49],[1,1.03,1237.54],[2,1.02,1926.2]],"ltp":1.05,"tv":29397.47,"id":9634485},{"trd":[[21,15.2],[26,61.44]],"batl":[[0,26,25.96]],"ltp":26.0,"tv":1688.02,"id":9712888}],"tv":31085.5}]}
{"op":"mcm","clk":"4233886699","pt":1631539713007,"mc":[{"id":"1.187557759","rc":[{"batb":[[2,1.02,1869.84]],"batl":[[2,1.09,92]],"ltp":1.05,"tv":29397.47,"id":9634485}]}]}
{"op":"mcm","clk":"4233886871","pt":1631539714680,"mc":[{"id":"1.187557759","rc":[{"trd":[[26,67.34]],"batl":[[0,26,23.01]],"ltp":26.0,"tv":1693.92,"id":9712888}],"tv":31091.4}]}
{"op":"mcm","clk":"4233887025","pt":1631539716403,"mc":[{"id":"1.187557759","rc":[{"batb":[[0,1.05,564],[1,1.04,2323.49],[2,1.03,1237.54]],"ltp":1.05,"tv":29397.47,"id":9634485}]}]}
{"op":"mcm","clk":"4233887482","pt":1631539720689,"mc":[{"id":"1.187557759","rc":[{"batb":[[1,1.04,300],[2,1.03,1227.83]],"batl":[[0,1.06,108],[1,1.07,100.7]],"ltp":1.05,"tv":29397.47,"id":9634485},{"batb":[[1,15,3],[2,14.5,11.63]],"batl":[[0,36,4],[1,55,4],[2,110,2]],"ltp":26.0,"tv":1693.92,"id":9712888}]}]}
{"op":"mcm","clk":"4233887570","pt":1631539721417,"mc":[{"id":"1.187557759","rc":[{"batb":[[0,1.03,1227.83],[1,1.02,1869.84],[2,1.01,7783.8]],"batl":[[0,1.07,1.7],[1,1.09,92],[2,1.11,3.53]],"ltp":1.05,"tv":29397.47,"id":9634485},{"batb":[[0,12,3],[1,11.5,11.63],[2,1.01,115.38]],"ltp":26.0,"tv":1693.92,"id":9712888}]}]}
{"op":"mcm","clk":"4233887770","pt":1631539723601,"mc":[{"id":"1.187557759","rc":[{"batb":[[0,1.03,1897.76]],"batl":[[1,1.08,358.98],[2,1.09,369.35]],"ltp":1.05,"tv":29397.47,"id":9634485}]}]}
{"op":"mcm","clk":"4233887817","pt":1631539724120,"mc":[{"id":"1.187557759","rc":[{"batb":[[2,11,4]],"ltp":26.0,"tv":1693.92,"id":9712888}]}]}
{"op":"mcm","clk":"4233888763","pt":1631539732642,"mc":[{"id":"1.187557759","rc":[{"batl":[[1,1.09,92],[2,1.1,101]],"ltp":1.05,"tv":29397.47,"id":9634485}]}]}
{"op":"mcm","clk":"4233888975","pt":1631539734835,"mc":[{"id":"1.187557759","rc":[{"batb":[[2,1.01,3690.24]],"batl":[[1,1.11,3.53],[2,1.13,14.82]],"ltp":1.05,"tv":29397.47,"id":9634485},{"batb":[[0,11.5,11.63],[1,1.01,115.38],[2,11,0]],"ltp":26.0,"tv":1693.92,"id":9712888}]}]}
{"op":"mcm","clk":"4233889087","pt":1631539735830,"mc":[{"id":"1.187557759","rc":[{"batl":[[0,1.05,5345.13],[1,1.06,9.43],[2,1.07,1.7]],"ltp":1.05,"tv":29397.47,"id":9634485},{"batb":[[0,21,100.45],[1,20,11.5],[2,11.5,11.63]],"batl":[[0,34,6.43],[1,36,4],[2,50,196.19]],"ltp":26.0,"tv":1693.92,"id":9712888}]}]}
{"op":"mcm","clk":"4233889176","pt":1631539736508,"mc":[{"id":"1.187557759","rc":[{"batb":[[1,1.02,1879.64]],"batl":[[0,1.05,2990.7]],"ltp":1.05,"tv":29397.47,"id":9634485},{"batb":[[2,17,6.94]],"ltp":26.0,"tv":1693.92,"id":9712888}]}]}
{"op":"mcm","clk":"4233889278","pt":1631539737445,"mc":[{"id":"1.187557759","rc":[{"batl":[[0,1.05,3091.7],[1,1.06,117.43],[2,1.07,97.7]],"ltp":1.05,"tv":29397.47,"id":9634485},{"batb":[[0,21,102.45],[2,17.5,2]],"ltp":26.0,"tv":1693.92,"id":9712888}]}]}
{"op":"mcm","clk":"4233890244","pt":1631539747349,"mc":[{"id":"1.187557759","rc":[{"batl":[[0,1.05,2767.17]],"ltp":1.05,"tv":29397.47,"id":9634485}]}]}
{"op":"mcm","clk":"4233890941","pt":1631539754535,"mc":[{"id":"1.187557759","rc":[{"batb":[[0,1.03,1160.9],[1,1.02,1869.84]],"batl":[[0,1.06,108],[1,1.07,97.7],[2,1.11,3.53]],"ltp":1.05,"tv":29397.47,"id":9634485},{"batb":[[0,17.5,2],[1,15,3],[2,14.5,11.38]],"batl":[[0,36,2],[1,55,4],[2,110,2]],"ltp":26.0,"tv":1693.92,"id":9712888}]}]}
{"op":"mcm","clk":"4233891253","pt":1631539757567,"mc":[{"id":"1.187557759","rc":[{"batl":[[2,1.08,103]],"ltp":1.05,"tv":29397.47,"id":9634485}]}]}
{"op":"mcm","clk":"4233891349","pt":1631539758562,"mc":[{"id":"1.187557759","rc":[{"batb":[[0,1.04,103.64],[1,1.03,1410.1],[2,1.02,1869.84]],"batl":[[0,1.05,657.16],[1,1.06,108],[2,1.07,97.7]],"ltp":1.05,"tv":29397.47,"id":9634485}]}]}
{"op":"mcm","clk":"4233891623","pt":1631539761411,"mc":[{"id":"1.187557759","rc":[{"batb":[[0,1.04,326.64]],"ltp":1.05,"tv":29397.47,"id":9634485}]}]}
{"op":"mcm","clk":"4233892074","pt":1631539765703,"mc":[{"id":"1.187557759","rc":[{"batb":[[0,1.04,223],[1,1.03,1160.9]],"batl":[[0,1.06,108],[1,1.07,97.7],[2,1.08,103]],"ltp":1.05,"tv":29397.47,"id":9634485}]}]}
{"op":"mcm","clk":"4233892356","pt":1631539768579,"mc":[{"id":"1.187557759","rc":[{"batb":[[2,1.02,2227.16]],"batl":[[0,1.06,758.96]],"ltp":1.05,"tv":29397.47,"id":9634485}]}]}
{"op":"mcm","clk":"4233892453","pt":1631539769607,"mc":[{"id":"1.187557759","rc":[{"batl":[[0,1.06,650.96]],"ltp":1.05,"tv":29397.47,"id":9634485},{"batb":[[0,15,3],[1,14.5,11.38],[2,13.5,3]],"ltp":26.0,"tv":1693.92,"id":9712888}]}]}
{"op":"mcm","clk":"4233892482","pt":1631539769876,"mc":[{"id":"1.187557759","rc":[{"batb":[[0,1.03,1160.9],[1,1.02,2227.16],[2,1.01,3690.24]],"ltp":1.05,"tv":29397.47,"id":9634485}]}]}
{"op":"mcm","clk":"4233893094","pt":1631539776017,"mc":[{"id":"1.187557759","rc":[{"batl":[[0,1.07,97.7],[1,1.08,103],[2,1.09,105]],"ltp":1.05,"tv":29397.47,"id":9634485}]}]}
{"op":"mcm","clk":"4233893229","pt":1631539777313,"mc":[{"id":"1.187557759","rc":[{"batl":[[0,1.07,1.7],[1,1.11,3.53],[2,1.13,17.91]],"ltp":1.05,"tv":29397.47,"id":9634485},{"batb":[[0,14.5,11.38],[1,1.01,115.38],[2,13.5,0]],"ltp":26.0,"tv":1693.92,"id":9712888}]}]}
{"op":"mcm","clk":"4233893350","pt":1631539778717,"mc":[{"id":"1.187557759","rc":[{"batl":[[0,1.04,6106.36],[1,1.05,9.52],[2,1.07,1.7]],"ltp":1.05,"tv":29397.47,"id":9634485},{"batb":[[0,26,77.21],[1,24,6.24],[2,20,10]],"batl":[[1,50,108.07],[2,55,4]],"ltp":26.0,"tv":1693.92,"id":9712888}]}]}
{"op":"mcm","clk":"4233893480","pt":1631539779815,"mc":[{"id":"1.187557759","rc":[{"batb":[[2,1.01,3700.14]],"batl":[[0,1.04,2999.19],[2,1.07,55.43]],"ltp":1.05,"tv":29397.47,"id":9634485},{"batb":[[1,24,3.74],[2,20,6]],"ltp":26.0,"tv":1693.92,"id":9712888}]}]}
{"op":"mcm","clk":"4233893518","pt":1631539780230,"mc":[{"id":"1.187557759","rc":[{"batl":[[0,1.04,3092.19],[1,1.05,104.52],[2,1.06,103]],"ltp":1.05,"tv":29397.47,"id":9634485},{"batb":[[0,26,79.21],[2,21,2]],"ltp":26.0,"tv":1693.92,"id":9712888}]}]}
{"op":"mcm","clk":"4233893867","pt":1631539783720,"mc":[{"id":"1.187557759","rc":[{"batl":[[1,1.05,1003.95]],"ltp":1.05,"tv":29397.47,"id":9634485},{"batl":[[0,34,3.7],[1,36,2],[2,50,108.07]],"ltp":26.0,"tv":1693.92,"id":9712888}]}]}
{"op":"mcm","clk":"4233893890","pt":1631539784038,"mc":[{"id":"1.187557759","rc":[{"batl":[[1,1.05,104.52]],"ltp":1.05,"tv":29397.47,"id":9634485},{"batl":[[0,36,2],[1,50,108.07],[2,55,4]],"ltp":26.0,"tv":1693.92,"id":9712888}]}]}
{"op":"mcm","clk":"4233894566","pt":1631539790726,"mc":[{"id":"1.187557759","rc":[{"batl":[[0,1.04,2760.2]],"ltp":1.05,"tv":29397.47,"id":9634485}]}]}
{"op":"mcm","clk":"4233897336","pt":1631539816511,"mc":[{"id":"1.187557759","rc":[{"trd":[[1.03,2726.62]],"batb":[[0,1.03,316.07]],"ltp":1.03,"tv":30197.47,"id":9634485}],"tv":31891.4}]}
{"op":"mcm","clk":"4233898013","pt":1631539823112,"mc":[{"id":"1.187557759","rc":[{"batl":[[1,1.05,107.61]],"ltp":1.03,"tv":30197.47,"id":9634485}]}]}
{"op":"mcm","clk":"4233898352","pt":1631539826002,"mc":[{"id":"1.187557759","rc":[{"trd":[[1.03,2769.2]],"batb":[[0,1.03,294.78]],"ltp":1.03,"tv":30240.06,"id":9634485}],"tv":31933.98}]}
{"op":"mcm","clk":"4233898684","pt":1631539829239,"mc":[{"id":"1.187557759","rc":[{"batb":[[1,1.02,2241.7]],"ltp":1.03,"tv":30240.06,"id":9634485}]}]}
{"op":"mcm","clk":"4233900626","pt":1631539848677,"mc":[{"id":"1.187557759","rc":[{"trd":[[1.03,2903.76]],"batb":[[0,1.03,227.5]],"ltp":1.03,"tv":30374.62,"id":9634485}],"tv":32068.54}]}
{"op":"mcm","clk":"4233900996","pt":1631539851961,"mc":[{"id":"1.187557759","rc":[{"batb":[[0,1.03,269.47],[1,1.02,2279.24]],"ltp":1.03,"tv":30374.62,"id":9634485}]}]}
{"op":"mcm","clk":"4233901390","pt":1631539855760,"mc":[{"id":"1.187557759","rc":[{"trd":[[1.03,2904.14]],"batb":[[0,1.03,269.28]],"ltp":1.03,"tv":30374.99,"id":9634485},{"trd":[[26,70.74]],"batb":[[0,26,77.51]],"ltp":26.0,"tv":1697.32,"id":9712888}],"tv":32072.32}]}
{"op":"mcm","clk":"4233902576","pt":1631539868395,"mc":[{"id":"1.187557759","rc":[{"batl":[[1,1.05,572.11],[2,1.06,494.75]],"ltp":1.03,"tv":30374.99,"id":9634485},{"batb":[[2,21,4]],"ltp":26.0,"tv":1697.32,"id":9712888}]}]}
{"op":"mcm","clk":"4233903907","pt":1631539881314,"mc":[{"id":"1.187557759","rc":[{"trd":[[1.03,2912.66]],"batb":[[0,1.03,265.02]],"ltp":1.03,"tv":30383.51,"id":9634485}],"tv":32080.84}]}
{"op":"mcm","clk":"4233904155","pt":1631539883826,"mc":[{"id":"1.187557759","rc":[{"batb":[[0,1.02,2279.24],[1,1.01,3690.24],[2,1.01,0]],"batl":[[0,1.04,93],[1,1.05,98.09]],"ltp":1.03,"tv":30383.51,"id":9634485},{"batb":[[0,26,2],[1,21,2],[2,17.5,4]],"batl":[[0,55,4],[1,110,4],[2,160,37.48]],"ltp":26.0,"tv":1697.32,"id":9712888}]}]}
{"op":"mcm","clk":"4233904171","pt":1631539884036,"mc":[{"id":"1.187557759","rc":[{"batb":[[0,1.02,1729.24]],"batl":[[0,1.05,98.09],[1,1.06,494.75],[2,1.07,1.7]],"ltp":1.03,"tv":30383.51,"id":9634485},{"batb":[[0,21,2],[1,17.5,4],[2,17,6.94]],"batl":[[0,55,2]],"ltp":26.0,"tv":1697.32,"id":9712888}]}]}
{"op":"mcm","clk":"4233904426","pt":1631539886427,"mc":[{"id":"1.187557759","rc":[{"batb":[[0,1.02,2001.36]],"batl":[[0,1.05,760.14]],"ltp":1.03,"tv":30383.51,"id":9634485}]}]}
{"op":"mcm","clk":"4233904505","pt":1631539887258,"mc":[{"id":"1.187557759","rc":[{"batb":[[0,1.02,1319.84]],"batl":[[0,1.05,573.39],[1,1.06,103],[2,1.07,109.7]],"ltp":1.03,"tv":30383.51,"id":9634485},{"batb":[[0,21,4]],"ltp":26.0,"tv":1697.32,"id":9712888}]}]}
{"op":"mcm","clk":"4233904666","pt":1631539888826,"mc":[{"id":"1.187557759","rc":[{"batl":[[2,990,0.01]],"ltp":26.0,"tv":1697.32,"id":9712888}]}]}
{"op":"mcm","clk":"4233904762","pt":1631539889658,"mc":[{"id":"1.187557759","rc":[{"batb":[[0,1.02,1329.64]],"batl":[[0,1.05,2554.27]],"ltp":1.03,"tv":30383.51,"id":9634485},{"batb":[[0,21,103.04]],"batl":[[0,32,4.7],[1,34,58.09],[2,42,4.76]],"ltp":26.0,"tv":1697.32,"id":9712888}]}]}
{"op":"mcm","clk":"4233904882","pt":1631539890656,"mc":[{"id":"1.187557759","rc":[{"batb":[[0,1.03,674.9],[1,1.02,1329.64],[2,1.01,3775.63]],"batl":[[0,1.05,3216.32],[1,1.06,112.43]],"ltp":1.03,"tv":30383.51,"id":9634485},{"batb":[[1,20,7.5],[2,17.5,4]],"batl":[[0,32,2.82],[2,42,2.86]],"ltp":26.0,"tv":1697.32,"id":9712888}]}]}
{"op":"mcm","clk":"4233904958","pt":1631539891341,"mc":[{"id":"1.187557759","rc":[{"batb":[[0,1.03,1057.9],[1,1.02,1879.64]],"ltp":1.03,"tv":30383.51,"id":9634485},{"batb":[[1,20,1.5]],"batl":[[2,36,2]],"ltp":26.0,"tv":1697.32,"id":9712888}]}]}
{"op":"mcm","clk":"4233905073","pt":1631539892431,"mc":[{"id":"1.187557759","rc":[{"batb":[[2,1.01,7705.89]],"ltp":1.03,"tv":30383.51,"id":9634485}]}]}
{"op":"mcm","clk":"4233905314","pt":1631539894732,"mc":[{"id":"1.187557759","rc":[{"batb":[[0,21,101.04]],"ltp":26.0,"tv":1697.32,"id":9712888}]}]}
{"op":"mcm","clk":"4233905569","pt":1631539897449,"mc":[{"id":"1.187557759","rc":[{"batb":[[0,1.03,1909.73]],"batl":[[1,1.06,485.18],[2,1.07,510.2]],"ltp":1.03,"tv":30383.51,"id":9634485},{"batl":[[2,36,4]],"ltp":26.0,"tv":1697.32,"id":9712888}]}]}
{"op":"mcm","clk":"4233906264","pt":1631539904783,"mc":[{"id":"1.187557759","rc":[{"batb":[[0,1.03,1234.83],[1,1.02,1869.84]],"batl":[[0,1.05,1060.34],[1,1.06,475.75]],"ltp":1.03,"tv":30383.51,"id":9634485},{"batb":[[0,21,2],[1,17.5,4],[2,17,6.94]],"batl":[[0,36,4],[1,55,4],[2,110,4]],"ltp":26.0,"tv":1697.32,"id":9712888}]}]}
{"op":"mcm","clk":"4233906369","pt":1631539905785,"mc":[{"id":"1.187557759","rc":[{"batb":[[0,1.02,1869.84],[1,1.01,7620.51],[2,1.01,0]],"batl":[[0,1.05,585.04]],"ltp":1.03,"tv":30383.51,"id":9634485},{"batb":[[2,15.5,9.45]],"batl":[[0,55,4],[1,110,4],[2,990,0.01]],"ltp":26.0,"tv":1697.32,"id":9712888}]}]}
{"op":"mcm","clk":"4233906407","pt":1631539906189,"mc":[{"id":"1.187557759","rc":[{"batl":[[0,1.05,438.94]],"ltp":1.03,"tv":30383.51,"id":9634485}]}]}
{"op":"mcm","clk":"4233906561","pt":1631539907760,"mc":[{"id":"1.187557759","rc":[{"batb":[[0,1.02,2551.36]],"batl":[[1,1.06,649.19]],"ltp":1.03,"tv":30383.51,"id":9634485}]}]}
{"op":"mcm","clk":"4233906621","pt":1631539908280,"mc":[{"id":"1.187557759","rc":[{"batb":[[0,1.02,1869.84]],"batl":[[1,1.06,475.75]],"ltp":1.03,"tv":30383.51,"id":9634485}]}]}
{"op":"mcm","clk":"4233906783","pt":1631539909696,"mc":[{"id":"1.187557759","rc":[{"batb":[[0,1.03,674.9],[1,1.02,1869.84],[2,1.01,7620.51]],"batl":[[0,1.04,324.28],[1,1.05,438.94],[2,1.06,475.75]],"ltp":1.03,"tv":30383.51,"id":9634485}]}]}
{"op":"mcm","clk":"4233907097","pt":1631539912558,"mc":[{"id":"1.187557759","rc":[{"batb":[[0,1.03,1421.73]],"ltp":1.03,"tv":30383.51,"id":9634485},{"batl":[[0,36,2],[1,55,4],[2,110,4]],"ltp":26.0,"tv":1697.32,"id":9712888}]}]}
{"op":"mcm","clk":"4233907376","pt":1631539915459,"mc":[{"id":"1.187557759","rc":[{"batb":[[0,1.02,1869.84],[1,1.01,7620.51],[2,1.01,0]],"batl":[[0,1.05,438.94],[1,1.06,475.75],[2,1.07,510.2]],"ltp":1.03,"tv":30383.51,"id":9634485},{"batl":[[0,55,4],[1,110,4],[2,990,0.01]],"ltp":26.0,"tv":1697.32,"id":9712888}]}]}
{"op":"mcm","clk":"4233907708","pt":1631539918683,"mc":[{"id":"1.187557759","rc":[{"batb":[[0,1.03,876.83],[1,1.02,2551.36],[2,1.01,7620.51]],"batl":[[0,1.05,585.04],[1,1.06,649.19]],"ltp":1.03,"tv":30383.51,"id":9634485},{"batl":[[0,36,2],[1,55,4],[2,110,4]],"ltp":26.0,"tv":1697.32,"id":9712888}]}]}
{"op":"mcm","clk":"4233907758","pt":1631539919104,"mc":[{"id":"1.187557759","rc":[{"batb":[[1,1.02,1869.84]],"ltp":1.03,"tv":30383.51,"id":9634485}]}]}
{"op":"mcm","clk":"4233907904","pt":1631539920299,"mc":[{"id":"1.187557759","rc":[{"batb":[[2,1.01,3690.24]],"ltp":1.03,"tv":30383.51,"id":9634485}]}]}
{"op":"mcm","clk":"4233908086","pt":1631539921769,"mc":[{"id":"1.187557759","rc":[{"batb":[[0,1.04,633.98],[1,1.03,876.83],[2,1.02,1879.64]],"batl":[[0,1.05,1570.1]],"ltp":1.03,"tv":30383.51,"id":9634485},{"batb":[[0,21,50.3]],"batl":[[0,26,5.31],[1,27,5.56],[2,32,6.24]],"ltp":26.0,"tv":1697.32,"id":9712888}]}]}
{"op":"mcm","clk":"4233908211","pt":1631539922786,"mc":[{"id":"1.187557759","rc":[{"batl":[[2,1.07,519.55]],"ltp":1.03,"tv":30383.51,"id":9634485},{"batb":[[1,18.5,4.87],[2,18,2.44]],"batl":[[1,27,3.34],[2,32,3.74]],"ltp":26.0,"tv":1697.32,"id":9712888}]}]}
{"op":"mcm","clk":"4233908270","pt":1631539923302,"mc":[{"id":"1.187557759","rc":[{"batb":[[1,1.03,1259.83]],"ltp":1.03,"tv":30383.51,"id":9634485},{"batb":[[1,18.5,1.62],[2,17.5,5.64]],"batl":[[1,27,1.12]],"ltp":26.0,"tv":1697.32,"id":9712888}]}]}
{"op":"mcm","clk":"4233908497","pt":1631539925603,"mc":[{"id":"1.187557759","rc":[{"trd":[[1.05,4439.38]],"batl":[[0,1.05,722.13]],"ltp":1.05,"tv":32079.45,"id":9634485}],"tv":33776.78}]}
{"op":"mcm","clk":"4233908795","pt":1631539928617,"mc":[{"id":"1.187557759","rc":[{"batb":[[0,1.04,670.53]],"batl":[[0,1.05,941.76],[1,1.06,913.98]],"ltp":1.05,"tv":32079.45,"id":9634485},{"batl":[[0,26,7.31]],"ltp":26.0,"tv":1697.32,"id":9712888}]}]}
{"op":"mcm","clk":"4233908871","pt":1631539929314,"mc":[{"id":"1.187557759","rc":[{"batb":[[0,1.04,827.53]],"ltp":1.05,"tv":32079.45,"id":9634485}]}]}
{"op":"mcm","clk":"4233909532","pt":1631539935828,"mc":[{"id":"1.187557759","rc":[{"batb":[[2,1.02,1869.84]],"batl":[[2,1.07,510.2]],"ltp":1.05,"tv":32079.45,"id":9634485},{"batb":[[1,17.5,4],[2,15.5,9.45]],"batl":[[1,34,154.53],[2,36,4]],"ltp":26.0,"tv":1697.32,"id":9712888}]}]}
{"op":"mcm","clk":"4233909592","pt":1631539936311,"mc":[{"id":"1.187557759","rc":[{"batb":[[0,1.04,157]],"batl":[[0,1.06,913.98],[1,1.07,510.2],[2,1.08,312.44]],"ltp":1.05,"tv":32079.45,"id":9634485},{"batb":[[0,21,2],[2,15,5]],"batl":[[0,36,4],[1,55,4],[2,110,4]],"ltp":26.0,"tv":1697.32,"id":9712888}]}]}
{"op":"mcm","clk":"4233909717","pt":1631539937396,"mc":[{"id":"1.187557759","rc":[{"trd":[[1.04,5776.57]],"batb":[[0,1.03,1259.83],[1,1.02,1869.84],[2,1.01,7812.12]],"ltp":1.04,"tv":32080.23,"id":9634485}],"tv":33777.56}]}
{"op":"mcm","clk":"4233909943","pt":1631539939739,"mc":[{"id":"1.187557759","rc":[{"batb":[[0,1.03,1934.73]],"batl":[[0,1.05,98],[1,1.06,1087.08],[2,1.07,510.2]],"ltp":1.04,"tv":32080.23,"id":9634485}]}]}
{"op":"mcm","clk":"4233910738","pt":1631539947909,"mc":[{"id":"1.187557759","rc":[{"batb":[[0,1.03,1259.83]],"ltp":1.04,"tv":32080.23,"id":9634485}]}]}
{"op":"mcm","clk":"4233911054","pt":1631539950850,"mc":[{"id":"1.187557759","rc":[{"trd":[[1.05,4675.38]],"batb":[[0,1.05,23.98],[1,1.04,1770.58],[2,1.03,1341.66]],"batl":[[0,1.06,3225.26],[1,1.07,510.2],[2,1.08,312.44]],"ltp":1.05,"tv":32316.23,"id":9634485},{"trd":[[21,17.2]],"batb":[[0,17.5,4],[1,15,5],[2,1.01,115.38]],"batl":[[0,26,46.77],[1,29,6.9],[2,36,4]],"ltp":21.0,"tv":1699.32,"id":9712888}],"tv":34015.56}]}
{"op":"mcm","clk":"4233911133","pt":1631539951756,"mc":[{"id":"1.187557759","rc":[{"batb":[[0,1.04,30.96],[1,1.03,1283.96],[2,1.02,1884.26]],"batl":[[0,1.06,617.27],[1,1.07,189.81],[2,1.08,70.76]],"ltp":1.05,"tv":32316.23,"id":9634485},{"batb":[[1,15,3],[2,14,12.88]],"batl":[[0,26,2]],"ltp":21.0,"tv":1699.32,"id":9712888}]}]}
{"op":"mcm","clk":"4233911218","pt":1631539952530,"mc":[{"id":"1.187557759","rc":[{"batl":[[0,1.06,504.05],[1,1.07,133.21],[2,1.08,14.16]],"ltp":1.05,"tv":32316.23,"id":9634485},{"batb":[[2,1.01,115.38]],"ltp":21.0,"tv":1699.32,"id":9712888}]}]}
{"op":"mcm","clk":"4233911534","pt":1631539955576,"mc":[{"id":"1.187557759","rc":[{"batl":[[0,1.05,100],[1,1.06,504.05],[2,1.07,133.21]],"ltp":1.05,"tv":32316.23,"id":9634485},{"batb":[[0,21,2],[1,17.5,4],[2,15,3]],"ltp":21.0,"tv":1699.32,"id":9712888}]}]}
{"op":"mcm","clk":"4233911997","pt":1631539960387,"mc":[{"id":"1.187557759","rc":[{"batb":[[0,1.04,2.12],[1,1.03,1259.83],[2,1.02,1869.84]],"batl":[[1,1.06,475.75],[2,1.07,109.7]],"ltp":1.05,"tv":32316.23,"id":9634485},{"batl":[[1,36,4],[2,55,4]],"ltp":21.0,"tv":1699.32,"id":9712888}]}]}
{"op":"mcm","clk":"4233912213","pt":1631539962652,"mc":[{"id":"1.187557759","rc":[{"batb":[[1,1.03,876.83]],"ltp":1.05,"tv":32316.23,"id":9634485},{"batl":[[1,36,2]],"ltp":21.0,"tv":1699.32,"id":9712888}]}]}
{"op":"mcm","clk":"4233912287","pt":1631539963486,"mc":[{"id":"1.187557759","rc":[{"batb":[[1,1.03,1551.73]],"batl":[[0,1.05,762.05]],"ltp":1.05,"tv":32316.23,"id":9634485}]}]}
{"op":"mcm","clk":"4233912958","pt":1631539970278,"mc":[{"id":"1.187557759","rc":[{"batb":[[0,1.02,550],[1,1.01,1071.7],[2,1.02,0]],"batl":[[0,1.05,290.79],[1,1.06,103]],"ltp":1.05,"tv":32316.23,"id":9634485},{"batb":[[1,17.5,2]],"batl":[[0,55,2],[1,110,2],[2,990,0.01]],"ltp":21.0,"tv":1699.32,"id":9712888}]}]}
{"op":"mcm","clk":"4233913208","pt":1631539972868,"mc":[{"id":"1.187557759","rc":[{"batb":[[0,1.02,1231.52]],"batl":[[1,1.06,569.8]],"ltp":1.05,"tv":32316.23,"id":9634485}]}]}
{"op":"mcm","clk":"4233913730","pt":1631539979061,"mc":[{"id":"1.187557759","rc":[{"batb":[[0,1.02,550]],"ltp":1.05,"tv":32316.23,"id":9634485}]}]}
{"op":"mcm","clk":"4233914011","pt":1631539982196,"mc":[{"id":"1.187557759","rc":[{"trd":[[1.05,4677.18]],"batb":[[0,1.04,668.41],[1,1.02,559.8],[2,1.01,1157.09]],"batl":[[0,1.05,915.63],[1,1.06,705.67]],"ltp":1.05,"tv":32318.03,"id":9634485},{"batb":[[0,21,33.29]],"batl":[[0,26,6.25],[1,30,6.34],[2,34,179.98]],"ltp":21.0,"tv":1699.32,"id":9712888}],"tv":34017.36}]}
{"op":"mcm","clk":"4233914135","pt":1631539983494,"mc":[{"id":"1.187557759","rc":[{"batb":[[0,1.04,968.41],[1,1.03,383],[2,1.02,559.8]],"batl":[[2,1.07,119.05]],"ltp":1.05,"tv":32318.03,"id":9634485},{"batb":[[2,17,1.76]],"batl":[[0,26,8.25],[1,30,2.34]],"ltp":21.0,"tv":1699.32,"id":9712888}]}]}
{"op":"mcm","clk":"4233914196","pt":1631539984330,"mc":[{"id":"1.187557759","rc":[{"batb":[[0,1.04,668.41],[1,1.02,9.8],[2,1.01,107.09]],"batl":[[0,1.05,816.53],[1,1.06,602.67],[2,1.07,11.05]],"ltp":1.05,"tv":32318.03,"id":9634485},{"batb":[[0,21,31.29],[1,17,1.76],[2,16,1.76]],"batl":[[0,26,6.25]],"ltp":21.0,"tv":1699.32,"id":9712888}]}]}
{"op":"mcm","clk":"4233914428","pt":1631539986771,"mc":[{"id":"1.187557759","rc":[{"trd":[[1.05,5519.92]],"batl":[[0,1.05,395.16]],"ltp":1.05,"tv":33160.77,"id":9634485}],"tv":34860.1}]}
{"op":"mcm","clk":"4233914492","pt":1631539987393,"mc":[{"id":"1.187557759","rc":[{"batb":[[0,1.04,837.41]],"ltp":1.05,"tv":33160.77,"id":9634485},{"trd":[[21,27.42]],"batb":[[0,21,26.18]],"ltp":21.0,"tv":1709.54,"id":9712888}],"tv":34870.32}]}
{"op":"mcm","clk":"4233914709","pt":1631539989728,"mc":[{"id":"1.187557759","rc":[{"batl":[[1,1.06,791.67]],"ltp":1.05,"tv":33160.77,"id":9634485}]}]}
