{"op":"mcm","clk":"4228423354","pt":1631461538123,"mc":[{"id":"1.187551081","rc":[{"batb":[[0,26,4],[1,25,20.22],[2,4.7,377.56]],"batl":[[0,110,2],[1,990,0.01],[2,50,0]],"ltp":29.0,"tv":1753.48,"id":7445998},{"batb":[[0,1.02,817.54]],"batl":[[0,1.04,1109.52],[1,1.05,477.48],[2,1.06,447]],"ltp":1.04,"tv":22466.95,"id":9629022}]}]}
{"op":"mcm","clk":"4228423879","pt":1631461541217,"mc":[{"id":"1.187551081","rc":[{"batb":[[0,1.01,2408.01],[1,1.01,0]],"batl":[[0,1.04,1857.55],[2,1.06,5.75]],"ltp":1.04,"tv":22466.95,"id":9629022}]}]}
{"op":"mcm","clk":"4228424381","pt":1631461544297,"mc":[{"id":"1.187551081","rc":[{"batb":[[0,26,6],[1,25,22.22]],"ltp":29.0,"tv":1753.48,"id":7445998},{"batb":[[0,1.03,1309.37],[1,1.01,2408.01]],"batl":[[0,1.04,1905.55],[2,1.06,20.8]],"ltp":1.04,"tv":22466.95,"id":9629022}]}]}
{"op":"mcm","clk":"4228424557","pt":1631461545417,"mc":[{"id":"1.187551081","rc":[{"batb":[[0,27,9.26],[1,26,6],[2,25,22.22]],"batl":[[0,44,5.5],[1,110,2],[2,990,0.01]],"ltp":29.0,"tv":1753.48,"id":7445998},{"batb":[[1,1.02,245.1],[2,1.01,2408.01]],"batl":[[0,1.04,2145.93]],"ltp":1.04,"tv":22466.95,"id":9629022}]}]}
{"op":"mcm","clk":"4228424746","pt":1631461546518,"mc":[{"id":"1.187551081","rc":[{"batb":[[0,27,11.26]],"batl":[[1,100,2],[2,110,2]],"ltp":29.0,"tv":1753.48,"id":7445998},{"batb":[[1,1.02,361.1],[2,1.01,2607.01]],"ltp":1.04,"tv":22466.95,"id":9629022}]}]}
{"op":"mcm","clk":"4228424860","pt":1631461547127,"mc":[{"id":"1.187551081","rc":[{"batb":[[0,27,2]],"batl":[[1,50,2],[2,100,2]],"ltp":29.0,"tv":1753.48,"id":7445998}]}]}
{"op":"mcm","clk":"4228425099","pt":1631461548633,"mc":[{"id":"1.187551081","rc":[{"batb":[[0,1.03,1815.83]],"batl":[[0,1.04,2583.33]],"ltp":1.04,"tv":22466.95,"id":9629022}]}]}
{"op":"mcm","clk":"4228425443","pt":1631461550642,"mc":[{"id":"1.187551081","rc":[{"batb":[[0,28,9.26],[1,27,2],[2,26,6]],"batl":[[2,55,2]],"ltp":29.0,"tv":1753.48,"id":7445998},{"batb":[[1,1.02,1688.27]],"batl":[[2,1.06,504.05]],"ltp":1.04,"tv":22466.95,"id":9629022}]}]}
{"op":"mcm","clk":"4228425724","pt":1631461552259,"mc":[{"id":"1.187551081","rc":[{"batb":[[0,1.03,3411.24]],"ltp":1.04,"tv":22466.95,"id":9629022}]}]}
{"op":"mcm","clk":"4228425801","pt":1631461552731,"mc":[{"id":"1.187551081","rc":[{"trd":[[1.03,587.78]],"batb":[[0,1.03,3405.15]],"ltp":1.03,"tv":22479.14,"id":9629022}],"tv":24232.62}]}
{"op":"mcm","clk":"4228426437","pt":1631461556631,"mc":[{"id":"1.187551081","rc":[{"batb":[[0,26,4],[1,25,2],[2,22,16.28]],"batl":[[0,55,2],[1,100,2],[2,110,2]],"ltp":29.0,"tv":1753.48,"id":7445998},{"batb":[[0,1.03,1595.41],[1,1.02,1327.17]],"batl":[[0,1.04,560.76],[2,1.06,489]],"ltp":1.03,"tv":22479.14,"id":9629022}]}]}
{"op":"mcm","clk":"4228426521","pt":1631461557149,"mc":[{"id":"1.187551081","rc":[{"batb":[[0,25,2],[1,22,16.28],[2,21,2]],"ltp":29.0,"tv":1753.48,"id":7445998},{"batl":[[0,1.05,477.48],[1,1.06,489],[2,1.11,11.86]],"ltp":1.03,"tv":22479.14,"id":9629022}]}]}
{"op":"mcm","clk":"4228426893","pt":1631461559245,"mc":[{"id":"1.187551081","rc":[{"batb":[[1,1.02,2649.38]],"batl":[[0,1.05,1761.92]],"ltp":1.03,"tv":22479.14,"id":9629022}]}]}
{"op":"mcm","clk":"4228427127","pt":1631461560545,"mc":[{"id":"1.187551081","rc":[{"batb":[[1,24,2],[2,22,16.28]],"ltp":29.0,"tv":1753.48,"id":7445998},{"batb":[[0,1.02,1327.17],[1,1.01,2607.01],[2,1.01,0]],"batl":[[0,1.05,1802.92],[1,1.06,483.25]],"ltp":1.03,"tv":22479.14,"id":9629022}]}]}
{"op":"mcm","clk":"4228427330","pt":1631461561635,"mc":[{"id":"1.187551081","rc":[{"batl":[[0,32,517.92],[1,55,2],[2,100,2]],"ltp":29.0,"tv":1753.48,"id":7445998}]}]}
{"op":"mcm","clk":"4228427521","pt":1631461562657,"mc":[{"id":"1.187551081","rc":[{"batl":[[0,55,2],[1,100,2],[2,110,2]],"ltp":29.0,"tv":1753.48,"id":7445998},{"batl":[[0,1.03,10],[1,1.05,1802.92],[2,1.06,483.25]],"ltp":1.03,"tv":22479.14,"id":9629022}]}]}
{"op":"mcm","clk":"4228427654","pt":1631461563409,"mc":[{"id":"1.187551081","rc":[{"batb":[[0,22,16.28],[1,21,2],[2,4.7,377.56]],"batl":[[0,36,2],[1,55,2],[2,100,2]],"ltp":29.0,"tv":1753.48,"id":7445998},{"trd":[[1.03,607.78]],"batb":[[0,1.03,9653.67],[1,1.02,1327.17],[2,1.01,2607.01]],"batl":[[0,1.05,1802.92],[1,1.06,483.25],[2,1.07,14.91]],"ltp":1.03,"tv":22499.14,"id":9629022}],"tv":24252.62}]}
{"op":"mcm","clk":"4228427811","pt":1631461564366,"mc":[{"id":"1.187551081","rc":[{"batb":[[2,17.5,33.5]],"ltp":29.0,"tv":1753.48,"id":7445998},{"batb":[[0,1.03,1389.86],[1,1.02,5278.27]],"ltp":1.03,"tv":22499.14,"id":9629022}]}]}
{"op":"mcm","clk":"4228427945","pt":1631461565182,"mc":[{"id":"1.187551081","rc":[{"batl":[[0,36,8.22]],"ltp":29.0,"tv":1753.48,"id":7445998},{"batb":[[0,1.03,1568.44]],"batl":[[0,1.04,90.34],[1,1.05,1802.92],[2,1.06,483.25]],"ltp":1.03,"tv":22499.14,"id":9629022}]}]}
{"op":"mcm","clk":"4228428227","pt":1631461566635,"mc":[{"id":"1.187551081","rc":[{"batb":[[0,23,2],[1,22,18.28],[2,21,2]],"batl":[[0,34,2],[1,36,8.22],[2,50,2]],"ltp":29.0,"tv":1753.48,"id":7445998},{"batb":[[0,1.03,1578.44],[1,1.02,5286.27]],"ltp":1.03,"tv":22499.14,"id":9629022}]}]}
{"op":"mcm","clk":"4228428297","pt":1631461567058,"mc":[{"id":"1.187551081","rc":[{"batl":[[1,36,2]],"ltp":29.0,"tv":1753.48,"id":7445998}]}]}
{"op":"mcm","clk":"4228428572","pt":1631461568666,"mc":[{"id":"1.187551081","rc":[{"batb":[[0,1.03,2167.29],[1,1.02,5292.42]],"batl":[[1,1.05,2348.42]],"ltp":1.03,"tv":22499.14,"id":9629022}]}]}
{"op":"mcm","clk":"4228428873","pt":1631461570170,"mc":[{"id":"1.187551081","rc":[{"batl":[[0,32,8.22],[1,34,2],[2,36,2]],"ltp":29.0,"tv":1753.48,"id":7445998}]}]}
{"op":"mcm","clk":"4228429204","pt":1631461571933,"mc":[{"id":"1.187551081","rc":[{"batb":[[0,24,7.89],[1,23,2],[2,22,18.28]],"ltp":29.0,"tv":1753.48,"id":7445998}]}]}
{"op":"mcm","clk":"4228429794","pt":1631461575234,"mc":[{"id":"1.187551081","rc":[{"trd":[[1.03,627.78]],"batb":[[0,1.03,2097.96]],"ltp":1.03,"tv":22519.14,"id":9629022}],"tv":24272.62}]}
{"op":"mcm","clk":"4228430329","pt":1631461578571,"mc":[{"id":"1.187551081","rc":[{"batb":[[2,22,16.28]],"batl":[[1,36,2],[2,55,2]],"ltp":29.0,"tv":1753.48,"id":7445998},{"batb":[[1,1.02,5284.42],[2,1.01,2408.01]],"batl":[[1,1.05,2973.58],[2,1.06,1122.93]],"ltp":1.03,"tv":22519.14,"id":9629022}]}]}
{"op":"mcm","clk":"4228430516","pt":1631461579564,"mc":[{"id":"1.187551081","rc":[{"trd":[[1.04,2493.32]],"batb":[[0,1.04,973.26],[1,1.03,2097.96],[2,1.02,5284.42]],"batl":[[0,1.05,2973.58],[1,1.06,1122.93],[2,1.07,14.91]],"ltp":1.04,"tv":22699.82,"id":9629022}],"tv":24453.3}]}
{"op":"mcm","clk":"4228430632","pt":1631461580164,"mc":[{"id":"1.187551081","rc":[{"batl":[[1,36,21.87],[2,55,20.43]],"ltp":29.0,"tv":1753.48,"id":7445998},{"batb":[[1,1.03,2792.3],[2,1.02,6278.53]],"ltp":1.04,"tv":22699.82,"id":9629022}]}]}
{"op":"mcm","clk":"4228431173","pt":1631461583369,"mc":[{"id":"1.187551081","rc":[{"batb":[[0,1.03,2792.3],[1,1.02,6278.53],[2,1.01,2408.01]],"ltp":1.04,"tv":22699.82,"id":9629022}]}]}
{"op":"mcm","clk":"4228431235","pt":1631461583751,"mc":[{"id":"1.187551081","rc":[{"batl":[[0,1.04,82.77],[1,1.05,2973.58],[2,1.06,1122.93]],"ltp":1.04,"tv":22699.82,"id":9629022}]}]}
{"op":"mcm","clk":"4228433227","pt":1631461595482,"mc":[{"id":"1.187551081","rc":[{"trd":[[1.04,2502.32]],"batl":[[0,1.04,78.27]],"ltp":1.04,"tv":22708.82,"id":9629022}],"tv":24462.3}]}
{"op":"mcm","clk":"4228433268","pt":1631461595686,"mc":[{"id":"1.187551081","rc":[{"batl":[[0,1.04,22.5]],"ltp":1.04,"tv":22708.82,"id":9629022}]}]}
{"op":"mcm","clk":"4228433519","pt":1631461597154,"mc":[{"id":"1.187551081","rc":[{"trd":[[1.04,2547.32],[1.05,2363.07]],"batl":[[0,1.05,2092.07],[1,1.06,1122.93],[2,1.07,14.91]],"ltp":1.05,"tv":24516.89,"id":9629022}],"tv":26270.37}]}
{"op":"mcm","clk":"4228434009","pt":1631461600212,"mc":[{"id":"1.187551081","rc":[{"batl":[[0,1.05,2496.1]],"ltp":1.05,"tv":24516.89,"id":9629022}]}]}
{"op":"mcm","clk":"4228434133","pt":1631461600961,"mc":[{"id":"1.187551081","rc":[{"batl":[[0,1.04,79.78],[1,1.05,2496.1],[2,1.06,1122.93]],"ltp":1.05,"tv":24516.89,"id":9629022}]}]}
{"op":"mcm","clk":"4228443172","pt":1631461655212,"mc":[{"id":"1.187551081","rc":[{"trd":[[1.04,2647.32]],"batl":[[0,1.04,29.78]],"ltp":1.04,"tv":24616.89,"id":9629022}],"tv":26370.37}]}
{"op":"mcm","clk":"4228444193","pt":1631461661191,"mc":[{"id":"1.187551081","rc":[{"batb":[[0,23,2],[1,22,16.28],[2,21,33.26]],"batl":[[0,32,2]],"ltp":29.0,"tv":1753.48,"id":7445998},{"trd":[[1.04,2683.4]],"batb":[[0,1.03,2613.72]],"batl":[[0,1.05,2496.1],[1,1.06,1122.93],[2,1.11,11.86]],"ltp":1.04,"tv":24652.97,"id":9629022}],"tv":26406.45}]}
{"op":"mcm","clk":"4228445523","pt":1631461670199,"mc":[{"id":"1.187551081","rc":[{"batb":[[0,24,7.11],[1,23,2],[2,22,16.28]],"batl":[[0,30,2.59],[1,32,2],[2,36,21.87]],"ltp":29.0,"tv":1753.48,"id":7445998},{"batb":[[0,1.03,2810.79]],"batl":[[0,1.04,72.09],[1,1.05,2496.1],[2,1.06,1122.93]],"ltp":1.04,"tv":24652.97,"id":9629022}]}]}
{"op":"mcm","clk":"4228446659","pt":1631461677537,"mc":[{"id":"1.187551081","rc":[{"batb":[[0,23,2],[1,22,16.28],[2,21,2]],"batl":[[0,32,2],[1,36,2],[2,55,2]],"ltp":29.0,"tv":1753.48,"id":7445998},{"batb":[[0,1.03,880.19],[1,1.02,5284.42]],"batl":[[0,1.05,41],[1,1.06,483.25],[2,1.11,11.86]],"ltp":1.04,"tv":24652.97,"id":9629022}]}]}
{"op":"mcm","clk":"4228446712","pt":1631461677900,"mc":[{"id":"1.187551081","rc":[{"batb":[[0,17.5,33.5],[1,4.7,377.56],[2,1.01,30]],"batl":[[0,55,2],[1,110,2],[2,520,36.07]],"ltp":29.0,"tv":1753.48,"id":7445998},{"batb":[[0,1.03,859.03],[1,1.02,1333.33]],"batl":[[0,1.06,483.25],[1,1.11,11.86],[2,1.13,11.86]],"ltp":1.04,"tv":24652.97,"id":9629022}]}]}
{"op":"mcm","clk":"4228447098","pt":1631461680538,"mc":[{"id":"1.187551081","rc":[{"batb":[[1,1.02,1788.08]],"batl":[[0,1.06,1316],[1,1.07,435.46],[2,1.11,11.86]],"ltp":1.04,"tv":24652.97,"id":9629022}]}]}
{"op":"mcm","clk":"4228447527","pt":1631461683525,"mc":[{"id":"1.187551081","rc":[{"batl":[[0,1.06,483.25],[1,1.11,11.86],[2,1.13,11.86]],"ltp":1.04,"tv":24652.97,"id":9629022}]}]}
{"op":"mcm","clk":"4228447735","pt":1631461684965,"mc":[{"id":"1.187551081","rc":[{"batl":[[2,990,0.01]],"ltp":29.0,"tv":1753.48,"id":7445998}]}]}
{"op":"mcm","clk":"4228447987","pt":1631461686648,"mc":[{"id":"1.187551081","rc":[{"batl":[[0,1.04,1296.79],[1,1.06,498.3],[2,1.11,11.86]],"ltp":1.04,"tv":24652.97,"id":9629022}]}]}
{"op":"mcm","clk":"4228448151","pt":1631461687629,"mc":[{"id":"1.187551081","rc":[{"batb":[[0,28,22.34],[1,21,20.05],[2,4.7,377.56]],"batl":[[0,46,5.22],[1,55,2],[2,110,2]],"ltp":29.0,"tv":1753.48,"id":7445998},{"batl":[[0,1.04,1537.17]],"ltp":1.04,"tv":24652.97,"id":9629022}]}]}
{"op":"mcm","clk":"4228448229","pt":1631461688138,"mc":[{"id":"1.187551081","rc":[{"batb":[[0,28,13.41],[2,18,2]],"ltp":29.0,"tv":1753.48,"id":7445998},{"batl":[[1,1.05,35],[2,1.06,498.3]],"ltp":1.04,"tv":24652.97,"id":9629022}]}]}
{"op":"mcm","clk":"4228448496","pt":1631461689747,"mc":[{"id":"1.187551081","rc":[{"batb":[[1,27,2],[2,26,2]],"ltp":29.0,"tv":1753.48,"id":7445998}]}]}
{"op":"mcm","clk":"4228448789","pt":1631461691663,"mc":[{"id":"1.187551081","rc":[{"batb":[[0,29,8.93],[1,28,13.41],[2,27,2]],"batl":[[0,44,2]],"ltp":29.0,"tv":1753.48,"id":7445998},{"batb":[[0,1.03,1702.47]],"batl":[[0,1.04,2372.5]],"ltp":1.04,"tv":24652.97,"id":9629022}]}]}
{"op":"mcm","clk":"4228449205","pt":1631461694454,"mc":[{"id":"1.187551081","rc":[{"batb":[[0,21,20.05],[1,18,2],[2,17.5,2]],"batl":[[0,55,2],[1,110,2],[2,990,0.01]],"ltp":29.0,"tv":1753.48,"id":7445998},{"batb":[[0,1.02,1788.08],[1,1.01,2408.01],[2,1.01,0]],"batl":[[0,1.06,483.25],[1,1.11,11.86],[2,1.13,11.86]],"ltp":1.04,"tv":24652.97,"id":9629022}]}]}
{"op":"mcm","clk":"4228449597","pt":1631461697321,"mc":[{"id":"1.187551081","rc":[{"batl":[[0,110,2],[1,990,0.01],[2,990,0]],"ltp":29.0,"tv":1753.48,"id":7445998},{"batb":[[0,1.02,6.16]],"batl":[[0,1.06,518.25]],"ltp":1.04,"tv":24652.97,"id":9629022}]}]}
{"op":"mcm","clk":"4228449934","pt":1631461699661,"mc":[{"id":"1.187551081","rc":[{"batb":[[0,1.03,1309.37],[1,1.02,6.16],[2,1.01,2408.01]],"batl":[[0,1.04,1296.79],[1,1.06,518.25],[2,1.11,11.86]],"ltp":1.04,"tv":24652.97,"id":9629022}]}]}
{"op":"mcm","clk":"4228450030","pt":1631461700251,"mc":[{"id":"1.187551081","rc":[{"batb":[[2,4.7,377.56]],"batl":[[0,55,2],[1,110,2],[2,990,0.01]],"ltp":29.0,"tv":1753.48,"id":7445998},{"batb":[[1,1.02,1296.07]],"ltp":1.04,"tv":24652.97,"id":9629022}]}]}
{"op":"mcm","clk":"4228450131","pt":1631461700862,"mc":[{"id":"1.187551081","rc":[{"batb":[[0,26,9.62],[1,21,20.05],[2,18,2]],"batl":[[0,42,5.29],[1,55,2],[2,110,2]],"ltp":29.0,"tv":1753.48,"id":7445998},{"batb":[[1,1.02,1326.87]],"batl":[[0,1.04,1537.17]],"ltp":1.04,"tv":24652.97,"id":9629022}]}]}
{"op":"mcm","clk":"4228450590","pt":1631461703477,"mc":[{"id":"1.187551081","rc":[{"batb":[[0,21,20.05],[1,18,2],[2,4.7,377.56]],"batl":[[0,55,2],[1,110,2],[2,990,0.01]],"ltp":29.0,"tv":1753.48,"id":7445998},{"batb":[[0,1.02,1296.07],[1,1.01,2408.01],[2,1.01,0]],"batl":[[0,1.06,518.25],[1,1.11,11.86],[2,1.13,11.86]],"ltp":1.04,"tv":24652.97,"id":9629022}]}]}
{"op":"mcm","clk":"4228450665","pt":1631461703863,"mc":[{"id":"1.187551081","rc":[{"batl":[[0,110,2],[1,990,0.01],[2,990,0]],"ltp":29.0,"tv":1753.48,"id":7445998},{"batb":[[0,1.02,6.16]],"ltp":1.04,"tv":24652.97,"id":9629022}]}]}
{"op":"mcm","clk":"4228451056","pt":1631461706357,"mc":[{"id":"1.187551081","rc":[{"batb":[[0,1.02,1328.37]],"batl":[[0,1.05,1284.44],[1,1.06,518.25],[2,1.11,11.86]],"ltp":1.04,"tv":24652.97,"id":9629022}]}]}
{"op":"mcm","clk":"4228451179","pt":1631461707101,"mc":[{"id":"1.187551081","rc":[{"batl":[[0,55,2],[1,110,2],[2,990,0.01]],"ltp":29.0,"tv":1753.48,"id":7445998},{"batb":[[0,1.02,2697.8]],"ltp":1.04,"tv":24652.97,"id":9629022}]}]}
{"op":"mcm","clk":"4228451441","pt":1631461708598,"mc":[{"id":"1.187551081","rc":[{"batb":[[0,1.03,5464.98],[1,1.02,2697.8],[2,1.01,2408.01]],"ltp":1.04,"tv":24652.97,"id":9629022}]}]}
{"op":"mcm","clk":"4228451586","pt":1631461709524,"mc":[{"id":"1.187551081","rc":[{"batb":[[1,1.02,1375.59]],"ltp":1.04,"tv":24652.97,"id":9629022}]}]}
{"op":"mcm","clk":"4228452080","pt":1631461712403,"mc":[{"id":"1.187551081","rc":[{"batl":[[0,36,2.59],[1,55,2],[2,110,2]],"ltp":29.0,"tv":1753.48,"id":7445998},{"batb":[[0,1.04,864.04],[1,1.03,6147.75],[2,1.02,1375.59]],"batl":[[2,1.07,14.91]],"ltp":1.04,"tv":24652.97,"id":9629022}]}]}
{"op":"mcm","clk":"4228452222","pt":1631461713224,"mc":[{"id":"1.187551081","rc":[{"batb":[[0,22,9.59],[1,21,22.05],[2,20,2]],"batl":[[0,34,7.12],[1,36,2.59],[2,55,2]],"ltp":29.0,"tv":1753.48,"id":7445998},{"batb":[[1,1.03,925.49],[2,1.02,4983.61]],"batl":[[0,1.05,1562.54]],"ltp":1.04,"tv":24652.97,"id":9629022}]}]}
{"op":"mcm","clk":"4228452612","pt":1631461715516,"mc":[{"id":"1.187551081","rc":[{"batb":[[0,22,11.59]],"batl":[[0,34,9.12]],"ltp":29.0,"tv":1753.48,"id":7445998}]}]}
{"op":"mcm","clk":"4228452681","pt":1631461715900,"mc":[{"id":"1.187551081","rc":[{"batb":[[0,22,2]],"ltp":29.0,"tv":1753.48,"id":7445998}]}]}
{"op":"mcm","clk":"4228452887","pt":1631461717406,"mc":[{"id":"1.187551081","rc":[{"batb":[[0,1.04,1638.84]],"batl":[[0,1.05,2329.96]],"ltp":1.04,"tv":24652.97,"id":9629022}]}]}
{"op":"mcm","clk":"4228453261","pt":1631461719528,"mc":[{"id":"1.187551081","rc":[{"batb":[[0,23,9.59],[1,22,2],[2,21,22.05]],"batl":[[0,32,15.6],[1,34,28.38],[2,36,24.92]],"ltp":29.0,"tv":1753.48,"id":7445998},{"batb":[[1,1.03,1323.35],[2,1.02,5652.09]],"ltp":1.04,"tv":24652.97,"id":9629022}]}]}
{"op":"mcm","clk":"4228453434","pt":1631461720301,"mc":[{"id":"1.187551081","rc":[{"batl":[[1,34,21.26]],"ltp":29.0,"tv":1753.48,"id":7445998},{"batb":[[1,1.03,2068.43]],"ltp":1.04,"tv":24652.97,"id":9629022}]}]}
{"op":"mcm","clk":"4228453871","pt":1631461722891,"mc":[{"id":"1.187551081","rc":[{"batl":[[0,30,7.12],[1,32,15.6],[2,34,21.26]],"ltp":29.0,"tv":1753.48,"id":7445998}]}]}
{"op":"mcm","clk":"4228454123","pt":1631461724532,"mc":[{"id":"1.187551081","rc":[{"batl":[[0,26,27.33],[1,30,7.12],[2,32,15.6]],"ltp":29.0,"tv":1753.48,"id":7445998},{"batb":[[0,1.04,2322.08],[1,1.03,3030.93]],"ltp":1.04,"tv":24652.97,"id":9629022}]}]}
{"op":"mcm","clk":"4228454260","pt":1631461725350,"mc":[{"id":"1.187551081","rc":[{"batb":[[2,21,48.32]],"ltp":29.0,"tv":1753.48,"id":7445998},{"batl":[[0,1.05,2895.34],[1,1.06,1084.5]],"ltp":1.04,"tv":24652.97,"id":9629022}]}]}
{"op":"mcm","clk":"4228457920","pt":1631461749486,"mc":[{"id":"1.187551081","rc":[{"batb":[[0,1.04,1458.04]],"batl":[[0,1.05,1610.9]],"ltp":1.04,"tv":24652.97,"id":9629022}]}]}
{"op":"mcm","clk":"4228458391","pt":1631461752479,"mc":[{"id":"1.187551081","rc":[{"batb":[[1,1.03,3701.47],[2,1.02,5855.96]],"batl":[[2,1.07,1275.33]],"ltp":1.04,"tv":24652.97,"id":9629022}]}]}
{"op":"mcm","clk":"4228458627","pt":1631461754203,"mc":[{"id":"1.187551081","rc":[{"trd":[[1.04,2689.26]],"batb":[[0,1.04,1455.11]],"ltp":1.04,"tv":24658.83,"id":9629022}],"tv":26412.31}]}
{"op":"mcm","clk":"4228461076","pt":1631461770106,"mc":[{"id":"1.187551081","rc":[{"batb":[[0,16.5,19.51],[1,10.5,27.77],[2,10,34.3]],"batl":[[0,32,15.6],[1,34,19.26],[2,36,22.33]],"ltp":29.0,"tv":1753.48,"id":7445998},{"batb":[[0,1.03,1505.34],[1,1.02,2247.94],[2,1.01,3621.62]],"batl":[[0,1.07,1260.42],[1,1.11,295.3],[2,1.12,327.94]],"ltp":1.04,"tv":24658.83,"id":9629022}]}]}
{"op":"mcm","clk":"4228461392","pt":1631461772003,"mc":[{"id":"1.187551081","rc":[{"batb":[[0,1.03,397.86],[1,1.02,2044.07]],"batl":[[0,1.11,295.3],[1,1.12,327.94],[2,1.13,301.57]],"ltp":1.04,"tv":24658.83,"id":9629022}]}]}
{"op":"mcm","clk":"4228461629","pt":1631461773303,"mc":[{"id":"1.187551081","rc":[{"batb":[[0,16.5,21.51],[1,16,2],[2,10.5,27.77]],"ltp":29.0,"tv":1753.48,"id":7445998},{"batl":[[0,1.07,34],[1,1.11,295.3],[2,1.12,327.94]],"ltp":1.04,"tv":24658.83,"id":9629022}]}]}
{"op":"mcm","clk":"4228462039","pt":1631461775401,"mc":[{"id":"1.187551081","rc":[{"batb":[[0,1.04,1296.79],[1,1.03,397.86],[2,1.02,2044.07]],"batl":[[0,1.05,563.9],[1,1.06,713.74],[2,1.07,34]],"ltp":1.04,"tv":24658.83,"id":9629022}]}]}
{"op":"mcm","clk":"4228462238","pt":1631461776424,"mc":[{"id":"1.187551081","rc":[{"batb":[[0,19,13.16],[1,16.5,21.51],[2,16,2]],"batl":[[0,30,7.19],[1,32,15.6],[2,34,19.26]],"ltp":29.0,"tv":1753.48,"id":7445998},{"batb":[[0,1.04,1376.84]],"batl":[[1,1.06,949.59]],"ltp":1.04,"tv":24658.83,"id":9629022}]}]}
{"op":"mcm","clk":"4228462304","pt":1631461776743,"mc":[{"id":"1.187551081","rc":[{"batl":[[1,1.06,713.74]],"ltp":1.04,"tv":24658.83,"id":9629022}]}]}
{"op":"mcm","clk":"4228462871","pt":1631461779648,"mc":[{"id":"1.187551081","rc":[{"batb":[[0,16.5,21.51],[1,16,2],[2,10.5,27.77]],"batl":[[0,32,15.6],[1,34,19.26],[2,36,22.33]],"ltp":29.0,"tv":1753.48,"id":7445998},{"batb":[[0,1.04,595.82]],"batl":[[0,1.06,560.43],[1,1.07,34],[2,1.11,317.3]],"ltp":1.04,"tv":24658.83,"id":9629022}]}]}
{"op":"mcm","clk":"4228463028","pt":1631461780437,"mc":[{"id":"1.187551081","rc":[{"batb":[[0,1.03,397.86],[1,1.02,2044.07],[2,1.01,3621.62]],"batl":[[0,1.07,34],[1,1.11,317.3],[2,1.12,327.94]],"ltp":1.04,"tv":24658.83,"id":9629022}]}]}
{"op":"mcm","clk":"4228463264","pt":1631461781835,"mc":[{"id":"1.187551081","rc":[{"batb":[[0,1.03,1505.34],[1,1.02,2247.94]],"batl":[[0,1.07,1294.42]],"ltp":1.04,"tv":24658.83,"id":9629022}]}]}
{"op":"mcm","clk":"4228466211","pt":1631461799266,"mc":[{"id":"1.187551081","rc":[{"batb":[[1,4.7,377.56],[2,1.01,30]],"ltp":29.0,"tv":1753.48,"id":7445998},{"batl":[[0,1.07,34],[1,1.11,11.86],[2,1.13,11.86]],"ltp":1.04,"tv":24658.83,"id":9629022}]}]}
{"op":"mcm","clk":"4228466595","pt":1631461801600,"mc":[{"id":"1.187551081","rc":[{"batl":[[0,34,19.26],[1,36,22.33],[2,55,2]],"ltp":29.0,"tv":1753.48,"id":7445998}]}]}
{"op":"mcm","clk":"4228466747","pt":1631461802464,"mc":[{"id":"1.187551081","rc":[{"batb":[[1,1.02,2279.94]],"batl":[[0,1.04,1296.79],[1,1.06,15.05],[2,1.07,34]],"ltp":1.04,"tv":24658.83,"id":9629022}]}]}
{"op":"mcm","clk":"4228466923","pt":1631461803496,"mc":[{"id":"1.187551081","rc":[{"batb":[[0,27,15.89],[1,20,23.28],[2,16.5,2]],"ltp":29.0,"tv":1753.48,"id":7445998},{"batl":[[0,1.04,1466.79]],"ltp":1.04,"tv":24658.83,"id":9629022}]}]}
{"op":"mcm","clk":"4228467092","pt":1631461804445,"mc":[{"id":"1.187551081","rc":[{"batb":[[0,27,17.89],[1,26,2],[2,20,23.28]],"ltp":29.0,"tv":1753.48,"id":7445998},{"batl":[[1,1.06,53.05]],"ltp":1.04,"tv":24658.83,"id":9629022}]}]}
{"op":"mcm","clk":"4228467211","pt":1631461805085,"mc":[{"id":"1.187551081","rc":[{"trd":[[26,4.11],[27,35.78]],"batb":[[0,20,23.28],[1,17,2],[2,16.5,2]],"ltp":26.0,"tv":1793.37,"id":7445998},{"trd":[[1.04,2692.01]],"batl":[[0,1.04,1464.04]],"ltp":1.04,"tv":24661.58,"id":9629022}],"tv":26454.96}]}
{"op":"mcm","clk":"4228467406","pt":1631461806223,"mc":[{"id":"1.187551081","rc":[{"batb":[[0,28,2],[1,20,23.28],[2,17,2]],"ltp":26.0,"tv":1793.37,"id":7445998},{"batb":[[0,1.03,2103.68]],"batl":[[0,1.04,2030.75]],"ltp":1.04,"tv":24661.58,"id":9629022}]}]}
{"op":"mcm","clk":"4228467752","pt":1631461808282,"mc":[{"id":"1.187551081","rc":[{"batb":[[1,21,2],[2,20,26.28]],"ltp":26.0,"tv":1793.37,"id":7445998}]}]}
{"op":"mcm","clk":"4228468084","pt":1631461810415,"mc":[{"id":"1.187551081","rc":[{"batb":[[1,1.02,2900.82]],"ltp":1.04,"tv":24661.58,"id":9629022}]}]}
{"op":"mcm","clk":"4228468410","pt":1631461812525,"mc":[{"id":"1.187551081","rc":[{"batb":[[1,26,27.98],[2,21,65.11]],"ltp":26.0,"tv":1793.37,"id":7445998},{"batl":[[0,1.04,2730.21],[1,1.05,1262.28],[2,1.06,742.26]],"ltp":1.04,"tv":24661.58,"id":9629022}]}]}
{"op":"mcm","clk":"4228468592","pt":1631461813476,"mc":[{"id":"1.187551081","rc":[{"batb":[[0,29,9.26],[1,28,2],[2,26,27.98]],"ltp":26.0,"tv":1793.37,"id":7445998},{"trd":[[1.03,1122.92]],"batb":[[0,1.03,1856.11]],"ltp":1.03,"tv":25156.72,"id":9629022}],"tv":26950.1}]}
{"op":"mcm","clk":"4228470327","pt":1631461824646,"mc":[{"id":"1.187551081","rc":[{"batb":[[0,28,2],[1,21,2],[2,20,26.28]],"batl":[[0,55,2],[1,110,2],[2,990,0.01]],"ltp":26.0,"tv":1793.37,"id":7445998},{"batb":[[0,1.03,598.34],[1,1.02,2232.34],[2,1.01,2408.01]],"batl":[[0,1.04,566.71],[1,1.06,38],[2,1.07,34]],"ltp":1.03,"tv":25156.72,"id":9629022}]}]}
{"op":"mcm","clk":"4228470348","pt":1631461824730,"mc":[{"id":"1.187551081","rc":[{"batb":[[0,20,26.28],[1,4.7,377.56],[2,1.01,30]],"ltp":26.0,"tv":1793.37,"id":7445998},{"batb":[[0,1.02,1579.46],[1,1.01,2408.01],[2,1.01,0]],"batl":[[0,1.06,38],[1,1.11,11.86],[2,1.13,11.86]],"ltp":1.03,"tv":25156.72,"id":9629022}]}]}
{"op":"mcm","clk":"4228470792","pt":1631461827606,"mc":[{"id":"1.187551081","rc":[{"batb":[[0,1.02,2697.8]],"batl":[[0,1.05,1232.35],[1,1.06,567.35],[2,1.11,11.86]],"ltp":1.03,"tv":25156.72,"id":9629022}]}]}
{"op":"mcm","clk":"4228470842","pt":1631461827918,"mc":[{"id":"1.187551081","rc":[{"batb":[[1,19.5,2],[2,4.7,377.56]],"ltp":26.0,"tv":1793.37,"id":7445998},{"batl":[[0,1.05,750.04]],"ltp":1.03,"tv":25156.72,"id":9629022}]}]}
{"op":"mcm","clk":"4228472219","pt":1631461836112,"mc":[{"id":"1.187551081","rc":[{"batl":[[0,1.04,8060.16],[1,1.05,750.04],[2,1.06,567.35]],"ltp":1.03,"tv":25156.72,"id":9629022}]}]}
{"op":"mcm","clk":"4228472877","pt":1631461840245,"mc":[{"id":"1.187551081","rc":[{"batb":[[1,4.7,377.56],[2,1.01,30]],"ltp":26.0,"tv":1793.37,"id":7445998},{"batl":[[1,1.06,38],[2,1.11,11.86]],"ltp":1.03,"tv":25156.72,"id":9629022}]}]}
{"op":"mcm","clk":"4228473337","pt":1631461843441,"mc":[{"id":"1.187551081","rc":[{"batb":[[0,30,6.7],[1,27,15.78],[2,20,26.28]],"batl":[[0,55,4]],"ltp":26.0,"tv":1793.37,"id":7445998},{"batb":[[0,1.02,2819.8],[1,1.01,2624.01]],"batl":[[0,1.03,1309.37],[1,1.06,53.05]],"ltp":1.03,"tv":25156.72,"id":9629022}]}]}
{"op":"mcm","clk":"4228473488","pt":1631461844425,"mc":[{"id":"1.187551081","rc":[{"batb":[[0,36,6.94],[1,30,6.7],[2,27,15.78]],"batl":[[0,50,1.88],[1,55,4],[2,110,2]],"ltp":26.0,"tv":1793.37,"id":7445998},{"batb":[[0,1.02,2930.24]],"batl":[[0,1.03,1552.09]],"ltp":1.03,"tv":25156.72,"id":9629022}]}]}
{"op":"mcm","clk":"4228473780","pt":1631461846335,"mc":[{"id":"1.187551081","rc":[{"batb":[[2,27,17.78]],"ltp":26.0,"tv":1793.37,"id":7445998},{"batl":[[2,1.09,11.86]],"ltp":1.03,"tv":25156.72,"id":9629022}]}]}
{"op":"mcm","clk":"4228473970","pt":1631461847609,"mc":[{"id":"1.187551081","rc":[{"batl":[[2,70,6.98]],"ltp":26.0,"tv":1793.37,"id":7445998},{"batb":[[1,1.01,3175.06]],"batl":[[1,1.04,1727.8],[2,1.06,53.05]],"ltp":1.03,"tv":25156.72,"id":9629022}]}]}
{"op":"mcm","clk":"4228474002","pt":1631461847825,"mc":[{"id":"1.187551081","rc":[{"batl":[[2,110,2]],"ltp":26.0,"tv":1793.37,"id":7445998},{"batl":[[1,1.04,486.95]],"ltp":1.03,"tv":25156.72,"id":9629022}]}]}
{"op":"mcm","clk":"4228474320","pt":1631461850139,"mc":[{"id":"1.187551081","rc":[{"batb":[[0,27,15.78],[1,20,3],[2,4.7,377.56]],"batl":[[0,110,2],[1,990,0.01],[2,110,0]],"ltp":26.0,"tv":1793.37,"id":7445998},{"batb":[[0,1.02,6.16],[1,1.01,2624.01]],"batl":[[0,1.06,38],[1,1.09,11.86],[2,1.11,11.86]],"ltp":1.03,"tv":25156.72,"id":9629022}]}]}
{"op":"mcm","clk":"4228474673","pt":1631461852632,"mc":[{"id":"1.187551081","rc":[{"batb":[[1,1.01,3959.31]],"batl":[[0,1.04,1296.79],[1,1.06,38],[2,1.09,11.86]],"ltp":1.03,"tv":25156.72,"id":9629022}]}]}
{"op":"mcm","clk":"4228474798","pt":1631461853360,"mc":[{"id":"1.187551081","rc":[{"batl":[[0,55,2],[1,110,2],[2,990,0.01]],"ltp":26.0,"tv":1793.37,"id":7445998},{"batb":[[0,1.02,1272.39]],"batl":[[2,1.11,11.86]],"ltp":1.03,"tv":25156.72,"id":9629022}]}]}
{"op":"mcm","clk":"4228474904","pt":1631461854165,"mc":[{"id":"1.187551081","rc":[{"batl":[[0,110,2],[1,990,0.01],[2,990,0]],"ltp":26.0,"tv":1793.37,"id":7445998},{"batb":[[0,1.02,6.16]],"batl":[[0,1.06,38],[1,1.11,11.86],[2,1.13,11.86]],"ltp":1.03,"tv":25156.72,"id":9629022}]}]}
{"op":"mcm","clk":"4228475431","pt":1631461857572,"mc":[{"id":"1.187551081","rc":[{"batb":[[0,1.02,119.16]],"batl":[[0,1.03,1374.21],[1,1.05,15.19],[2,1.06,38]],"ltp":1.03,"tv":25156.72,"id":9629022}]}]}
{"op":"mcm","clk":"4228475541","pt":1631461858346,"mc":[{"id":"1.187551081","rc":[{"batb":[[0,36,2],[1,34,2],[2,30,7.37]],"batl":[[0,100,2],[1,110,2],[2,990,0.01]],"ltp":26.0,"tv":1793.37,"id":7445998},{"batb":[[0,1.02,6.16]],"batl":[[0,1.03,1381.21]],"ltp":1.03,"tv":25156.72,"id":9629022}]}]}
{"op":"mcm","clk":"4228475613","pt":1631461859006,"mc":[{"id":"1.187551081","rc":[{"batb":[[0,46,5.43],[1,36,2],[2,34,2]],"batl":[[0,75,2.92],[1,100,2],[2,110,2]],"ltp":26.0,"tv":1793.37,"id":7445998},{"batl":[[0,1.03,1571.21]],"ltp":1.03,"tv":25156.72,"id":9629022}]}]}
{"op":"mcm","clk":"4228476014","pt":1631461861559,"mc":[{"id":"1.187551081","rc":[{"batb":[[1,38,2],[2,36,2]],"batl":[[1,95,2],[2,100,2]],"ltp":26.0,"tv":1793.37,"id":7445998}]}]}
{"op":"mcm","clk":"4228476166","pt":1631461862477,"mc":[{"id":"1.187551081","rc":[{"batl":[[0,70,2]],"ltp":26.0,"tv":1793.37,"id":7445998},{"batb":[[1,1.01,4559.37]],"batl":[[0,1.03,2129.65]],"ltp":1.03,"tv":25156.72,"id":9629022}]}]}
{"op":"mcm","clk":"4228476413","pt":1631461864295,"mc":[{"id":"1.187551081","rc":[{"batl":[[0,70,12.24],[1,75,13.12],[2,80,11.48]],"ltp":26.0,"tv":1793.37,"id":7445998},{"batb":[[1,1.01,5356.86]],"ltp":1.03,"tv":25156.72,"id":9629022}]}]}
{"op":"mcm","clk":"4228476603","pt":1631461865567,"mc":[{"id":"1.187551081","rc":[{"batl":[[0,65,2.92],[1,70,12.24],[2,75,13.12]],"ltp":26.0,"tv":1793.37,"id":7445998},{"batl":[[0,1.03,2135.49],[1,1.04,5.88],[2,1.05,21.29]],"ltp":1.03,"tv":25156.72,"id":9629022}]}]}
{"op":"mcm","clk":"4228476631","pt":1631461865759,"mc":[{"id":"1.187551081","rc":[{"batl":[[0,65,1.41]],"ltp":26.0,"tv":1793.37,"id":7445998}]}]}
{"op":"mcm","clk":"4228477119","pt":1631461869070,"mc":[{"id":"1.187551081","rc":[{"batl":[[0,1.03,2070.65]],"ltp":1.03,"tv":25156.72,"id":9629022}]}]}
{"op":"mcm","clk":"4228478348","pt":1631461877396,"mc":[{"id":"1.187551081","rc":[{"batb":[[0,34,2],[1,30,7.37],[2,28,2]],"batl":[[0,70,10.24],[1,75,13.12],[2,80,11.48]],"ltp":26.0,"tv":1793.37,"id":7445998},{"batb":[[1,1.01,4540.8]],"batl":[[0,1.03,1315.21],[2,1.05,6.1]],"ltp":1.03,"tv":25156.72,"id":9629022}]}]}
{"op":"mcm","clk":"4228479187","pt":1631461883348,"mc":[{"id":"1.187551081","rc":[{"batb":[[0,30,7.37],[1,28,2],[2,26,2]],"batl":[[0,110,2],[1,990,0.01],[2,80,0]],"ltp":26.0,"tv":1793.37,"id":7445998},{"batb":[[1,1.01,2408.01]],"batl":[[0,1.03,1309.37]],"ltp":1.03,"tv":25156.72,"id":9629022}]}]}
{"op":"mcm","clk":"4228479657","pt":1631461886560,"mc":[{"id":"1.187551081","rc":[{"batb":[[0,34,2],[1,32,2],[2,30,9.37]],"batl":[[0,55,2],[1,110,2],[2,990,0.01]],"ltp":26.0,"tv":1793.37,"id":7445998},{"batb":[[0,1.02,1575.11]],"batl":[[0,1.03,1316.37]],"ltp":1.03,"tv":25156.72,"id":9629022}]}]}
{"op":"mcm","clk":"4228479924","pt":1631461888476,"mc":[{"id":"1.187551081","rc":[{"batb":[[0,36,6.94],[1,34,2],[2,32,2]],"ltp":26.0,"tv":1793.37,"id":7445998},{"batb":[[0,1.02,1710.91],[1,1.01,2619.01]],"batl":[[0,1.03,1559.09]],"ltp":1.03,"tv":25156.72,"id":9629022}]}]}
{"op":"mcm","clk":"4228479983","pt":1631461888754,"mc":[{"id":"1.187551081","rc":[{"batl":[[1,100,2],[2,110,2]],"ltp":26.0,"tv":1793.37,"id":7445998}]}]}
{"op":"mcm","clk":"4228480406","pt":1631461891479,"mc":[{"id":"1.187551081","rc":[{"batl":[[0,50,4.17],[1,55,2],[2,100,2]],"ltp":26.0,"tv":1793.37,"id":7445998},{"batb":[[0,1.02,2293.53]],"batl":[[0,1.03,2101.61]],"ltp":1.03,"tv":25156.72,"id":9629022}]}]}
{"op":"mcm","clk":"4228480480","pt":1631461891956,"mc":[{"id":"1.187551081","rc":[{"batl":[[0,55,2],[1,100,2],[2,110,2]],"ltp":26.0,"tv":1793.37,"id":7445998}]}]}
{"op":"mcm","clk":"4228480649","pt":1631461893180,"mc":[{"id":"1.187551081","rc":[{"batb":[[0,27,14.8],[1,26,2],[2,4.7,377.56]],"batl":[[0,100,2],[1,110,2],[2,990,0.01]],"ltp":26.0,"tv":1793.37,"id":7445998},{"batb":[[0,1.02,6.16]],"batl":[[0,1.04,5.88],[1,1.05,6.1],[2,1.11,11.86]],"ltp":1.03,"tv":25156.72,"id":9629022}]}]}
{"op":"mcm","clk":"4228480957","pt":1631461895267,"mc":[{"id":"1.187551081","rc":[{"batb":[[1,4.7,377.56],[2,1.01,30]],"ltp":26.0,"tv":1793.37,"id":7445998},{"batl":[[0,1.11,11.86],[1,1.13,11.86],[2,1.15,14.82]],"ltp":1.03,"tv":25156.72,"id":9629022}]}]}
{"op":"mcm","clk":"4228481135","pt":1631461896479,"mc":[{"id":"1.187551081","rc":[{"batl":[[0,55,2],[1,100,2],[2,110,2]],"ltp":26.0,"tv":1793.37,"id":7445998},{"batb":[[0,1.02,1118.21]],"ltp":1.03,"tv":25156.72,"id":9629022}]}]}
{"op":"mcm","clk":"4228481179","pt":1631461896785,"mc":[{"id":"1.187551081","rc":[{"batl":[[0,100,2],[1,110,2],[2,990,0.01]],"ltp":26.0,"tv":1793.37,"id":7445998},{"batb":[[0,1.02,6.16]],"ltp":1.03,"tv":25156.72,"id":9629022}]}]}
{"op":"mcm","clk":"4228481444","pt":1631461898484,"mc":[{"id":"1.187551081","rc":[{"batb":[[0,1.02,1328.37]],"batl":[[0,1.03,1309.37],[1,1.11,31.86],[2,1.13,11.86]],"ltp":1.03,"tv":25156.72,"id":9629022}]}]}
{"op":"mcm","clk":"4228481510","pt":1631461898858,"mc":[{"id":"1.187551081","rc":[{"batb":[[0,38,6.58],[1,27,14.8],[2,4.7,377.56]],"batl":[[0,60,3.59],[1,100,2],[2,110,2]],"ltp":26.0,"tv":1793.37,"id":7445998},{"batb":[[0,1.02,1359.17]],"batl":[[0,1.03,1368.67]],"ltp":1.03,"tv":25156.72,"id":9629022}]}]}
{"op":"mcm","clk":"4228481720","pt":1631461900285,"mc":[{"id":"1.187551081","rc":[{"batl":[[0,55,2]],"ltp":26.0,"tv":1793.37,"id":7445998},{"batb":[[0,1.02,2785.38]],"ltp":1.03,"tv":25156.72,"id":9629022}]}]}
{"op":"mcm","clk":"4228482168","pt":1631461903361,"mc":[{"id":"1.187551081","rc":[{"batl":[[0,55,5.59]],"ltp":26.0,"tv":1793.37,"id":7445998},{"batb":[[0,1.02,3372.42]],"batl":[[1,1.04,543.34],[2,1.11,31.86]],"ltp":1.03,"tv":25156.72,"id":9629022}]}]}
{"op":"mcm","clk":"4228482362","pt":1631461904904,"mc":[{"id":"1.187551081","rc":[{"batb":[[0,1.02,2050.21]],"batl":[[0,1.03,59.3]],"ltp":1.03,"tv":25156.72,"id":9629022}]}]}
{"op":"mcm","clk":"4228482589","pt":1631461906505,"mc":[{"id":"1.187551081","rc":[{"trd":[[38,0.29]],"batb":[[0,38,6.29]],"ltp":38.0,"tv":1793.66,"id":7445998},{"trd":[[1.03,1252.22]],"batl":[[0,1.04,543.34],[1,1.11,31.86],[2,1.13,11.86]],"ltp":1.03,"tv":25286.02,"id":9629022}],"tv":27079.69}]}
{"op":"mcm","clk":"4228482687","pt":1631461907208,"mc":[{"id":"1.187551081","rc":[{"batl":[[0,100,2],[1,110,2],[2,990,0.01]],"ltp":38.0,"tv":1793.66,"id":7445998},{"batb":[[0,1.02,36.96]],"batl":[[0,1.11,31.86],[1,1.13,11.86],[2,1.15,14.82]],"ltp":1.03,"tv":25286.02,"id":9629022}]}]}
{"op":"mcm","clk":"4228482846","pt":1631461908273,"mc":[{"id":"1.187551081","rc":[{"batb":[[0,27,14.8],[1,4.7,377.56],[2,1.01,30]],"ltp":38.0,"tv":1793.66,"id":7445998},{"batb":[[0,1.02,6.16],[1,1.01,3954.31]],"batl":[[0,1.04,1296.79],[1,1.11,31.86],[2,1.13,11.86]],"ltp":1.03,"tv":25286.02,"id":9629022}]}]}
{"op":"mcm","clk":"4228483154","pt":1631461910608,"mc":[{"id":"1.187551081","rc":[{"batl":[[1,1.09,11.86],[2,1.11,31.86]],"ltp":1.03,"tv":25286.02,"id":9629022}]}]}
{"op":"mcm","clk":"4228483390","pt":1631461912203,"mc":[{"id":"1.187551081","rc":[{"batb":[[1,1.01,2619.01]],"ltp":1.03,"tv":25286.02,"id":9629022}]}]}
{"op":"mcm","clk":"4228483580","pt":1631461913592,"mc":[{"id":"1.187551081","rc":[{"batl":[[0,55,2],[1,60,2],[2,100,2]],"ltp":38.0,"tv":1793.66,"id":7445998},{"batb":[[0,1.02,1251.94]],"ltp":1.03,"tv":25286.02,"id":9629022}]}]}
{"op":"mcm","clk":"4228483830","pt":1631461915400,"mc":[{"id":"1.187551081","rc":[{"batb":[[0,27,16.8],[1,26,2],[2,4.7,377.56]],"batl":[[0,36,2.59],[1,55,2],[2,60,2]],"ltp":38.0,"tv":1793.66,"id":7445998},{"batb":[[0,1.03,510.42],[1,1.02,2306.96],[2,1.01,2619.01]],"batl":[[0,1.04,1303.79],[1,1.06,15.05]],"ltp":1.03,"tv":25286.02,"id":9629022}]}]}
{"op":"mcm","clk":"4228483951","pt":1631461916294,"mc":[{"id":"1.187551081","rc":[{"batb":[[0,29,8.62],[1,27,16.8],[2,26,2]],"batl":[[1,46,4.7],[2,55,2]],"ltp":38.0,"tv":1793.66,"id":7445998},{"trd":[[1.03,1394.96]],"batb":[[0,1.03,439.05],[1,1.02,2337.76]],"ltp":1.03,"tv":25428.76,"id":9629022}],"tv":27222.43}]}
{"op":"mcm","clk":"4228484017","pt":1631461916784,"mc":[{"id":"1.187551081","rc":[{"batb":[[1,28,2],[2,27,16.8]],"batl":[[2,50,2]],"ltp":38.0,"tv":1793.66,"id":7445998}]}]}
{"op":"mcm","clk":"4228484542","pt":1631461920223,"mc":[{"id":"1.187551081","rc":[{"batb":[[1,1.02,2861.6]],"batl":[[0,1.04,1761.04]],"ltp":1.03,"tv":25428.76,"id":9629022}]}]}
{"op":"mcm","clk":"4228484800","pt":1631461922329,"mc":[{"id":"1.187551081","rc":[{"batl":[[1,38,13.19],[2,40,17.23]],"ltp":38.0,"tv":1793.66,"id":7445998},{"batb":[[1,1.02,3442.43],[2,1.01,3695.3]],"batl":[[2,1.08,320.63]],"ltp":1.03,"tv":25428.76,"id":9629022}]}]}
{"op":"mcm","clk":"4228485342","pt":1631461926295,"mc":[{"id":"1.187551081","rc":[{"batb":[[0,24,12.8],[1,13.5,22.44],[2,13,25.41]],"batl":[[0,38,13.19],[1,40,17.23],[2,42,15.07]],"ltp":38.0,"tv":1793.66,"id":7445998},{"batb":[[0,1.02,2887.79],[1,1.01,3695.3],[2,1.01,0]],"batl":[[0,1.04,1007.57],[1,1.08,320.63],[2,1.09,329.52]],"ltp":1.03,"tv":25428.76,"id":9629022}]}]}
{"op":"mcm","clk":"4228485825","pt":1631461929547,"mc":[{"id":"1.187551081","rc":[{"batb":[[0,24,14.8],[1,23,2],[2,13.5,22.44]],"ltp":38.0,"tv":1793.66,"id":7445998},{"batb":[[0,1.02,3154.98]],"batl":[[1,1.05,286.46],[2,1.08,320.63]],"ltp":1.03,"tv":25428.76,"id":9629022}]}]}
{"op":"mcm","clk":"4228487319","pt":1631461940288,"mc":[{"id":"1.187551081","rc":[{"batb":[[2,4.7,377.56]],"ltp":38.0,"tv":1793.66,"id":7445998},{"batl":[[0,1.04,1804.68],[1,1.11,31.86],[2,1.13,11.86]],"ltp":1.03,"tv":25428.76,"id":9629022}]}]}
{"op":"mcm","clk":"4228487775","pt":1631461943529,"mc":[{"id":"1.187551081","rc":[{"batb":[[1,4.7,377.56],[2,1.01,30]],"batl":[[0,55,2],[1,990,0.01],[2,42,0]],"ltp":38.0,"tv":1793.66,"id":7445998},{"batb":[[0,1.02,3259.98]],"batl":[[0,1.03,1309.37],[1,1.04,14.32],[2,1.06,15.05]],"ltp":1.03,"tv":25428.76,"id":9629022}]}]}
{"op":"mcm","clk":"4228487832","pt":1631461943921,"mc":[{"id":"1.187551081","rc":[{"batb":[[0,34,7.35],[1,30,8],[2,26,18.17]],"ltp":38.0,"tv":1793.66,"id":7445998},{"batb":[[0,1.02,3423.91]],"batl":[[0,1.03,1552.09]],"ltp":1.03,"tv":25428.76,"id":9629022}]}]}
{"op":"mcm","clk":"4228488233","pt":1631461946625,"mc":[{"id":"1.187551081","rc":[{"batb":[[2,27,2]],"batl":[[0,50,4.98],[1,55,2],[2,990,0.01]],"ltp":38.0,"tv":1793.66,"id":7445998}]}]}
{"op":"mcm","clk":"4228488346","pt":1631461947314,"mc":[{"id":"1.187551081","rc":[{"batl":[[0,50,2]],"ltp":38.0,"tv":1793.66,"id":7445998}]}]}
{"op":"mcm","clk":"4228488640","pt":1631461949505,"mc":[{"id":"1.187551081","rc":[{"batl":[[2,110,2]],"ltp":38.0,"tv":1793.66,"id":7445998}]}]}
{"op":"mcm","clk":"4228488769","pt":1631461950412,"mc":[{"id":"1.187551081","rc":[{"batb":[[0,34,33.37]],"batl":[[0,48,2.98],[1,50,2],[2,55,2]],"ltp":38.0,"tv":1793.66,"id":7445998},{"batb":[[0,1.02,3949.79]],"batl":[[0,1.03,2411.26],[1,1.04,1346.33]],"ltp":1.03,"tv":25428.76,"id":9629022}]}]}
{"op":"mcm","clk":"4228489456","pt":1631461955197,"mc":[{"id":"1.187551081","rc":[{"batb":[[1,1.01,3484.3]],"batl":[[1,1.04,1332.01]],"ltp":1.03,"tv":25428.76,"id":9629022}]}]}
{"op":"mcm","clk":"4228489652","pt":1631461956605,"mc":[{"id":"1.187551081","rc":[{"batb":[[0,26,18.17],[1,24,2],[2,4.7,377.56]],"batl":[[0,55,2],[1,110,2],[2,990,0.01]],"ltp":38.0,"tv":1793.66,"id":7445998},{"batb":[[0,1.02,1251.94],[1,1.01,2408.01]],"batl":[[0,1.11,31.86],[1,1.13,11.86],[2,1.15,14.82]],"ltp":1.03,"tv":25428.76,"id":9629022}]}]}
{"op":"mcm","clk":"4228489684","pt":1631461956815,"mc":[{"id":"1.187551081","rc":[{"batl":[[0,110,2],[1,990,0.01],[2,990,0]],"ltp":38.0,"tv":1793.66,"id":7445998},{"batb":[[0,1.02,6.16]],"ltp":1.03,"tv":25428.76,"id":9629022}]}]}
{"op":"mcm","clk":"4228490027","pt":1631461959180,"mc":[{"id":"1.187551081","rc":[{"batb":[[1,1.01,3743.31]],"batl":[[0,1.04,1296.79],[1,1.11,31.86],[2,1.13,11.86]],"ltp":1.03,"tv":25428.76,"id":9629022}]}]}
{"op":"mcm","clk":"4228490250","pt":1631461960410,"mc":[{"id":"1.187551081","rc":[{"batl":[[1,1.05,36],[2,1.11,31.86]],"ltp":1.03,"tv":25428.76,"id":9629022}]}]}
{"op":"mcm","clk":"4228490670","pt":1631461963635,"mc":[{"id":"1.187551081","rc":[{"batl":[[0,55,2],[1,110,2],[2,990,0.01]],"ltp":38.0,"tv":1793.66,"id":7445998},{"batb":[[0,1.02,1333.72]],"ltp":1.03,"tv":25428.76,"id":9629022}]}]}
{"op":"mcm","clk":"4228490775","pt":1631461964427,"mc":[{"id":"1.187551081","rc":[{"batl":[[0,110,2],[1,990,0.01],[2,990,0]],"ltp":38.0,"tv":1793.66,"id":7445998},{"batb":[[0,1.02,6.16]],"batl":[[0,1.03,8169.78],[1,1.04,1296.79],[2,1.05,36]],"ltp":1.03,"tv":25428.76,"id":9629022}]}]}
{"op":"mcm","clk":"4228491166","pt":1631461967415,"mc":[{"id":"1.187551081","rc":[{"batl":[[0,55,2],[1,110,2],[2,990,0.01]],"ltp":38.0,"tv":1793.66,"id":7445998},{"batb":[[0,1.02,1246.67],[1,1.01,2408.01]],"ltp":1.03,"tv":25428.76,"id":9629022}]}]}
{"op":"mcm","clk":"4228491553","pt":1631461970210,"mc":[{"id":"1.187551081","rc":[{"batl":[[0,36,2.07],[1,55,2],[2,110,2]],"ltp":38.0,"tv":1793.66,"id":7445998},{"batb":[[0,1.03,1110.39],[1,1.02,1659.49],[2,1.01,2408.01]],"batl":[[0,1.04,1296.79],[1,1.05,36],[2,1.11,31.86]],"ltp":1.03,"tv":25428.76,"id":9629022}]}]}
{"op":"mcm","clk":"4228491756","pt":1631461971552,"mc":[{"id":"1.187551081","rc":[{"batb":[[0,27,9.26],[2,23,14.74]],"batl":[[1,44,5.5],[2,55,2]],"ltp":38.0,"tv":1793.66,"id":7445998},{"batb":[[1,1.02,1904.59]],"batl":[[2,1.11,11.86]],"ltp":1.03,"tv":25428.76,"id":9629022}]}]}
{"op":"mcm","clk":"4228491805","pt":1631461971829,"mc":[{"id":"1.187551081","rc":[{"batl":[[1,55,2],[2,110,2]],"ltp":38.0,"tv":1793.66,"id":7445998}]}]}
{"op":"mcm","clk":"4228492069","pt":1631461973529,"mc":[{"id":"1.187551081","rc":[{"batb":[[0,27,11.26],[1,26,2],[2,24,2]],"batl":[[1,50,2],[2,55,2]],"ltp":38.0,"tv":1793.66,"id":7445998},{"batl":[[0,1.04,1537.17]],"ltp":1.03,"tv":25428.76,"id":9629022}]}]}
{"op":"mcm","clk":"4228492137","pt":1631461974008,"mc":[{"id":"1.187551081","rc":[{"batb":[[0,27,2],[2,25,2]],"ltp":38.0,"tv":1793.66,"id":7445998}]}]}
{"op":"mcm","clk":"4228492296","pt":1631461975236,"mc":[{"id":"1.187551081","rc":[{"batb":[[0,28,2],[1,27,2],[2,26,2]],"ltp":38.0,"tv":1793.66,"id":7445998},{"batb":[[1,1.02,2634.15]],"batl":[[0,1.04,2252.7]],"ltp":1.03,"tv":25428.76,"id":9629022}]}]}
{"op":"mcm","clk":"4228492505","pt":1631461976636,"mc":[{"id":"1.187551081","rc":[{"batb":[[0,1.03,209.83],[1,1.02,1659.49]],"batl":[[0,1.04,376.4]],"ltp":1.03,"tv":25428.76,"id":9629022}]}]}
{"op":"mcm","clk":"4228492603","pt":1631461977329,"mc":[{"id":"1.187551081","rc":[{"batb":[[0,24,2],[1,23,14.74],[2,4.7,377.56]],"batl":[[0,55,2],[1,110,2],[2,990,0.01]],"ltp":38.0,"tv":1793.66,"id":7445998},{"batb":[[0,1.02,1659.49],[1,1.01,2408.01],[2,1.01,0]],"ltp":1.03,"tv":25428.76,"id":9629022}]}]}
{"op":"mcm","clk":"4228492811","pt":1631461978666,"mc":[{"id":"1.187551081","rc":[{"batb":[[0,1.03,418.69],[1,1.02,1659.49],[2,1.01,2408.01]],"ltp":1.03,"tv":25428.76,"id":9629022}]}]}
{"op":"mcm","clk":"4228492950","pt":1631461979576,"mc":[{"id":"1.187551081","rc":[{"batb":[[1,1.02,2568.88]],"batl":[[1,1.05,947.62]],"ltp":1.03,"tv":25428.76,"id":9629022}]}]}
{"op":"mcm","clk":"4228493022","pt":1631461980163,"mc":[{"id":"1.187551081","rc":[{"batl":[[0,36,2],[1,55,2],[2,110,2]],"ltp":38.0,"tv":1793.66,"id":7445998},{"batb":[[0,1.03,420.85]],"ltp":1.03,"tv":25428.76,"id":9629022}]}]}
{"op":"mcm","clk":"4228493212","pt":1631461981704,"mc":[{"id":"1.187551081","rc":[{"batb":[[1,1.02,2076.67]],"batl":[[1,1.05,36]],"ltp":1.03,"tv":25428.76,"id":9629022}]}]}
{"op":"mcm","clk":"4228493602","pt":1631461984574,"mc":[{"id":"1.187551081","rc":[{"batb":[[0,1.03,930.11]],"batl":[[0,1.04,1316.92]],"ltp":1.03,"tv":25428.76,"id":9629022}]}]}
{"op":"mcm","clk":"4228493634","pt":1631461984787,"mc":[{"id":"1.187551081","rc":[{"batb":[[0,1.03,420.85]],"batl":[[0,1.04,376.4]],"ltp":1.03,"tv":25428.76,"id":9629022}]}]}
{"op":"mcm","clk":"4228493951","pt":1631461986877,"mc":[{"id":"1.187551081","rc":[{"batb":[[1,1.02,2568.88]],"batl":[[1,1.05,947.62]],"ltp":1.03,"tv":25428.76,"id":9629022}]}]}
{"op":"mcm","clk":"4228494878","pt":1631461993294,"mc":[{"id":"1.187551081","rc":[{"batl":[[0,1.04,6119.6]],"ltp":1.03,"tv":25428.76,"id":9629022}]}]}
{"op":"mcm","clk":"4228495235","pt":1631461995889,"mc":[{"id":"1.187551081","rc":[{"batl":[[1,1.05,36]],"ltp":1.03,"tv":25428.76,"id":9629022}]}]}
{"op":"mcm","clk":"4228495800","pt":1631461999656,"mc":[{"id":"1.187551081","rc":[{"batb":[[0,30,8.63],[1,24,14.66],[2,23,14.74]],"batl":[[0,55,2],[1,110,2],[2,990,0.01]],"ltp":38.0,"tv":1793.66,"id":7445998},{"trd":[[1.03,2236.66]],"batb":[[0,1.02,2568.88],[1,1.01,2408.01],[2,1.01,0]],"batl":[[0,1.03,297.31],[1,1.04,585.52],[2,1.05,36]],"ltp":1.03,"tv":26270.46,"id":9629022}],"tv":28064.13}]}
{"op":"mcm","clk":"4228495853","pt":1631462000017,"mc":[{"id":"1.187551081","rc":[{"batb":[[2,4.7,377.56]],"ltp":38.0,"tv":1793.66,"id":7445998}]}]}
{"op":"mcm","clk":"4228495944","pt":1631462000697,"mc":[{"id":"1.187551081","rc":[{"batb":[[0,32,7.81],[1,30,8.63],[2,24,14.66]],"ltp":38.0,"tv":1793.66,"id":7445998},{"batl":[[0,1.03,502.91]],"ltp":1.03,"tv":26270.46,"id":9629022}]}]}
{"op":"mcm","clk":"4228496158","pt":1631462002666,"mc":[{"id":"1.187551081","rc":[{"batb":[[2,27,2]],"batl":[[0,50,2],[1,55,2],[2,110,2]],"ltp":38.0,"tv":1793.66,"id":7445998},{"batb":[[0,1.02,2772.73]],"batl":[[0,1.03,691.19],[1,1.04,815.86]],"ltp":1.03,"tv":26270.46,"id":9629022}]}]}
{"op":"mcm","clk":"4228496281","pt":1631462003634,"mc":[{"id":"1.187551081","rc":[{"batl":[[2,60,8.94]],"ltp":38.0,"tv":1793.66,"id":7445998},{"batl":[[1,1.04,1867.7]],"ltp":1.03,"tv":26270.46,"id":9629022}]}]}
{"op":"mcm","clk":"4228496317","pt":1631462003832,"mc":[{"id":"1.187551081","rc":[{"batl":[[2,110,2]],"ltp":38.0,"tv":1793.66,"id":7445998},{"batb":[[0,1.02,3445.28]],"batl":[[1,1.04,1475.48]],"ltp":1.03,"tv":26270.46,"id":9629022}]}]}
{"op":"mcm","clk":"4228496502","pt":1631462005410,"mc":[{"id":"1.187551081","rc":[{"batl":[[0,48,2],[1,50,2],[2,55,2]],"ltp":38.0,"tv":1793.66,"id":7445998}]}]}
{"op":"mcm","clk":"4228496950","pt":1631462009112,"mc":[{"id":"1.187551081","rc":[{"batl":[[0,46,3.82],[1,48,2],[2,50,2]],"ltp":38.0,"tv":1793.66,"id":7445998}]}]}
{"op":"mcm","clk":"4228497104","pt":1631462010352,"mc":[{"id":"1.187551081","rc":[{"batb":[[0,24,14.66],[1,4.7,377.56],[2,1.01,30]],"batl":[[0,110,2],[1,990,0.01],[2,50,0]],"ltp":38.0,"tv":1793.66,"id":7445998},{"batb":[[0,1.02,6.16]],"batl":[[0,1.04,702.08],[1,1.05,36],[2,1.09,11.86]],"ltp":1.03,"tv":26270.46,"id":9629022}]}]}
{"op":"mcm","clk":"4228497498","pt":1631462013646,"mc":[{"id":"1.187551081","rc":[{"batl":[[0,55,2],[1,110,2],[2,990,0.01]],"ltp":38.0,"tv":1793.66,"id":7445998},{"batb":[[0,1.02,8.36],[1,1.01,3743.31]],"batl":[[1,1.05,625.04]],"ltp":1.03,"tv":26270.46,"id":9629022}]}]}
{"op":"mcm","clk":"4228497523","pt":1631462013867,"mc":[{"id":"1.187551081","rc":[{"batl":[[0,110,2],[1,990,0.01],[2,990,0]],"ltp":38.0,"tv":1793.66,"id":7445998},{"batb":[[0,1.02,6.16]],"ltp":1.03,"tv":26270.46,"id":9629022}]}]}
{"op":"mcm","clk":"4228497735","pt":1631462015765,"mc":[{"id":"1.187551081","rc":[{"batb":[[1,1.01,2408.01]],"batl":[[0,1.05,36],[1,1.09,11.86],[2,1.11,11.86]],"ltp":1.03,"tv":26270.46,"id":9629022}]}]}
{"op":"mcm","clk":"4228498114","pt":1631462018566,"mc":[{"id":"1.187551081","rc":[{"batl":[[0,1.04,2504],[1,1.05,36],[2,1.09,11.86]],"ltp":1.03,"tv":26270.46,"id":9629022}]}]}
{"op":"mcm","clk":"4228498229","pt":1631462019350,"mc":[{"id":"1.187551081","rc":[{"batb":[[1,23,2],[2,4.7,377.56]],"ltp":38.0,"tv":1793.66,"id":7445998},{"batb":[[0,1.02,1328.37]],"batl":[[0,1.03,1151.64]],"ltp":1.03,"tv":26270.46,"id":9629022}]}]}
{"op":"mcm","clk":"4228498378","pt":1631462020567,"mc":[{"id":"1.187551081","rc":[{"batb":[[0,1.02,6.16]],"batl":[[0,1.05,36],[1,1.09,11.86],[2,1.11,11.86]],"ltp":1.03,"tv":26270.46,"id":9629022}]}]}
{"op":"mcm","clk":"4228498773","pt":1631462023548,"mc":[{"id":"1.187551081","rc":[{"batb":[[1,1.01,3743.31]],"batl":[[0,1.04,702.08],[1,1.05,625.04],[2,1.09,11.86]],"ltp":1.03,"tv":26270.46,"id":9629022}]}]}
{"op":"mcm","clk":"4228498881","pt":1631462024140,"mc":[{"id":"1.187551081","rc":[{"batl":[[0,55,2],[1,110,2],[2,990,0.01]],"ltp":38.0,"tv":1793.66,"id":7445998},{"batb":[[0,1.02,8.36]],"ltp":1.03,"tv":26270.46,"id":9629022}]}]}
{"op":"mcm","clk":"4228499302","pt":1631462027412,"mc":[{"id":"1.187551081","rc":[{"batb":[[0,25,2],[1,24,14.66],[2,23,2]],"batl":[[0,50,2],[1,100,2],[2,110,2]],"ltp":38.0,"tv":1793.66,"id":7445998},{"batb":[[0,1.02,6.16]],"batl":[[2,1.11,11.86]],"ltp":1.03,"tv":26270.46,"id":9629022}]}]}
{"op":"mcm","clk":"4228499343","pt":1631462027669,"mc":[{"id":"1.187551081","rc":[{"batl":[[0,100,2],[1,110,2],[2,990,0.01]],"ltp":38.0,"tv":1793.66,"id":7445998}]}]}
{"op":"mcm","clk":"4228499487","pt":1631462028755,"mc":[{"id":"1.187551081","rc":[{"batb":[[1,1.01,2408.01]],"ltp":1.03,"tv":26270.46,"id":9629022}]}]}
{"op":"mcm","clk":"4228499689","pt":1631462030388,"mc":[{"id":"1.187551081","rc":[{"batb":[[1,24,12.66],[2,4.7,377.56]],"batl":[[0,55,2],[1,100,2],[2,110,2]],"ltp":38.0,"tv":1793.66,"id":7445998},{"batb":[[0,1.02,8.36]],"ltp":1.03,"tv":26270.46,"id":9629022}]}]}
{"op":"mcm","clk":"4228499838","pt":1631462031568,"mc":[{"id":"1.187551081","rc":[{"batb":[[0,1.03,8425.71],[1,1.02,8.36],[2,1.01,2408.01]],"ltp":1.03,"tv":26270.46,"id":9629022}]}]}
{"op":"mcm","clk":"4228499954","pt":1631462032466,"mc":[{"id":"1.187551081","rc":[{"batb":[[2,18,31.49]],"batl":[[0,36,2.07],[1,55,2],[2,100,2]],"ltp":38.0,"tv":1793.66,"id":7445998},{"batb":[[0,1.03,1598.31],[1,1.02,4386.85]],"batl":[[2,1.06,15.05]],"ltp":1.03,"tv":26270.46,"id":9629022}]}]}
{"op":"mcm","clk":"4228500043","pt":1631462033217,"mc":[{"id":"1.187551081","rc":[{"batb":[[0,26,7.74],[1,25,2],[2,24,12.66]],"ltp":38.0,"tv":1793.66,"id":7445998},{"batb":[[0,1.03,1629.11]],"batl":[[0,1.04,895.61]],"ltp":1.03,"tv":26270.46,"id":9629022}]}]}
{"op":"mcm","clk":"4228500285","pt":1631462035011,"mc":[{"id":"1.187551081","rc":[{"batb":[[0,1.03,1685.11],[1,1.02,4484.85]],"ltp":1.03,"tv":26270.46,"id":9629022}]}]}
{"op":"mcm","clk":"4228500485","pt":1631462036619,"mc":[{"id":"1.187551081","rc":[{"batl":[[0,34,2.95],[1,36,2.07],[2,44,9.36]],"ltp":38.0,"tv":1793.66,"id":7445998},{"batb":[[0,1.03,2334.29]],"batl":[[0,1.04,1582.88],[1,1.05,1255.62]],"ltp":1.03,"tv":26270.46,"id":9629022}]}]}
{"op":"mcm","clk":"4228500510","pt":1631462036797,"mc":[{"id":"1.187551081","rc":[{"batl":[[2,55,2]],"ltp":38.0,"tv":1793.66,"id":7445998},{"batl":[[0,1.04,895.61]],"ltp":1.03,"tv":26270.46,"id":9629022}]}]}
{"op":"mcm","clk":"4228500876","pt":1631462039818,"mc":[{"id":"1.187551081","rc":[{"batl":[[0,1.04,1548.66]],"ltp":1.03,"tv":26270.46,"id":9629022}]}]}
{"op":"mcm","clk":"4228501360","pt":1631462043620,"mc":[{"id":"1.187551081","rc":[{"batb":[[0,1.03,2254.18]],"ltp":1.03,"tv":26270.46,"id":9629022}]}]}
{"op":"mcm","clk":"4228505628","pt":1631462074539,"mc":[{"id":"1.187551081","rc":[{"trd":[[1.04,2716.01]],"batl":[[0,1.04,1536.66]],"ltp":1.04,"tv":26294.46,"id":9629022}],"tv":28088.13}]}
{"op":"mcm","clk":"4228505761","pt":1631462075635,"mc":[{"id":"1.187551081","rc":[{"trd":[[1.03,2317.45]],"batb":[[0,1.03,2213.79],[1,1.02,4386.85]],"ltp":1.03,"tv":26375.25,"id":9629022}],"tv":28168.91}]}
{"op":"mcm","clk":"4228506032","pt":1631462077961,"mc":[{"id":"1.187551081","rc":[{"batb":[[1,1.02,4501.85]],"ltp":1.03,"tv":26375.25,"id":9629022}]}]}
{"op":"mcm","clk":"4228506197","pt":1631462079132,"mc":[{"id":"1.187551081","rc":[{"batb":[[0,1.03,2254.18]],"batl":[[0,1.04,1564.15]],"ltp":1.03,"tv":26375.25,"id":9629022}]}]}
{"op":"mcm","clk":"4228508369","pt":1631462097066,"mc":[{"id":"1.187551081","rc":[{"trd":[[26,5.55]],"batb":[[0,26,7.02]],"ltp":26.0,"tv":1795.1,"id":7445998},{"batb":[[1,1.02,4386.85]],"ltp":1.03,"tv":26375.25,"id":9629022}],"tv":28170.36}]}
{"op":"mcm","clk":"4228508785","pt":1631462100503,"mc":[{"id":"1.187551081","rc":[{"trd":[[1.04,3116.01]],"batb":[[1,1.02,4493.85]],"batl":[[0,1.04,1364.15]],"ltp":1.04,"tv":26775.25,"id":9629022}],"tv":28570.36}]}
{"op":"mcm","clk":"4228508849","pt":1631462100895,"mc":[{"id":"1.187551081","rc":[{"batl":[[1,36,23.64],[2,55,21.51]],"ltp":26.0,"tv":1795.1,"id":7445998},{"batb":[[0,1.03,3008.3],[1,1.02,5546.04]],"ltp":1.04,"tv":26775.25,"id":9629022}]}]}
{"op":"mcm","clk":"4228509211","pt":1631462103605,"mc":[{"id":"1.187551081","rc":[{"batl":[[1,36,43.85],[2,55,42.51]],"ltp":26.0,"tv":1795.1,"id":7445998},{"batb":[[0,1.03,3714.6],[1,1.02,6678.5]],"ltp":1.04,"tv":26775.25,"id":9629022}]}]}
{"op":"mcm","clk":"4228509240","pt":1631462103776,"mc":[{"id":"1.187551081","rc":[{"batl":[[0,1.04,1453.63],[1,1.05,1349.74]],"ltp":1.04,"tv":26775.25,"id":9629022}]}]}
{"op":"mcm","clk":"4228509734","pt":1631462107176,"mc":[{"id":"1.187551081","rc":[{"batb":[[0,26,26.71]],"ltp":26.0,"tv":1795.1,"id":7445998},{"batl":[[0,1.04,2121.49],[1,1.05,2054.33]],"ltp":1.04,"tv":26775.25,"id":9629022}]}]}
{"op":"mcm","clk":"4228510142","pt":1631462110302,"mc":[{"id":"1.187551081","rc":[{"batb":[[0,27,7.02],[1,26,26.71],[2,25,2]],"ltp":26.0,"tv":1795.1,"id":7445998}]}]}
{"op":"mcm","clk":"4228510618","pt":1631462114298,"mc":[{"id":"1.187551081","rc":[{"batb":[[0,25,2],[1,24,12.66],[2,18,31.49]],"batl":[[1,36,2.07],[2,55,2]],"ltp":26.0,"tv":1795.1,"id":7445998},{"batb":[[0,1.03,2254.18],[1,1.02,4386.85]],"batl":[[0,1.04,1453.63],[1,1.05,1349.74]],"ltp":1.04,"tv":26775.25,"id":9629022}]}]}
{"op":"mcm","clk":"4228511061","pt":1631462117592,"mc":[{"id":"1.187551081","rc":[{"batb":[[0,26,7.64],[1,25,2],[2,24,12.66]],"ltp":26.0,"tv":1795.1,"id":7445998},{"batb":[[1,1.02,4489.85]],"ltp":1.04,"tv":26775.25,"id":9629022}]}]}
{"op":"mcm","clk":"4228511222","pt":1631462118949,"mc":[{"id":"1.187551081","rc":[{"batl":[[2,1.11,11.86]],"ltp":1.04,"tv":26775.25,"id":9629022}]}]}
{"op":"mcm","clk":"4228512468","pt":1631462128426,"mc":[{"id":"1.187551081","rc":[{"batb":[[0,25,2],[1,24,12.66],[2,18,31.49]],"batl":[[0,36,2.07],[1,55,2],[2,100,2]],"ltp":26.0,"tv":1795.1,"id":7445998},{"batb":[[0,1.03,2223.38]],"batl":[[0,1.04,1260.1]],"ltp":1.04,"tv":26775.25,"id":9629022}]}]}
{"op":"mcm","clk":"4228512914","pt":1631462131615,"mc":[{"id":"1.187551081","rc":[{"batb":[[0,26,2],[1,25,2],[2,24,12.66]],"ltp":26.0,"tv":1795.1,"id":7445998}]}]}
{"op":"mcm","clk":"4228512946","pt":1631462131837,"mc":[{"id":"1.187551081","rc":[{"batb":[[1,1.02,4386.85]],"ltp":1.04,"tv":26775.25,"id":9629022}]}]}
{"op":"mcm","clk":"4228513359","pt":1631462135028,"mc":[{"id":"1.187551081","rc":[{"batb":[[1,1.02,4484.85]],"ltp":1.04,"tv":26775.25,"id":9629022}]}]}
{"op":"mcm","clk":"4228513448","pt":1631462135845,"mc":[{"id":"1.187551081","rc":[{"batb":[[0,27,5.6],[1,26,2],[2,25,2]],"batl":[[0,34,3.02],[1,36,2.07],[2,55,2]],"ltp":26.0,"tv":1795.1,"id":7445998},{"batb":[[0,1.03,2332.45]],"batl":[[0,1.04,1451.09]],"ltp":1.04,"tv":26775.25,"id":9629022}]}]}
{"op":"mcm","clk":"4228514799","pt":1631462146566,"mc":[{"id":"1.187551081","rc":[{"batb":[[2,24,12.66]],"ltp":26.0,"tv":1795.1,"id":7445998},{"trd":[[1.04,3216.01]],"batb":[[1,1.02,4386.85]],"batl":[[0,1.04,1401.09]],"ltp":1.04,"tv":26875.25,"id":9629022}],"tv":28670.36}]}
{"op":"mcm","clk":"4228515026","pt":1631462148395,"mc":[{"id":"1.187551081","rc":[{"batb":[[0,18,31.49],[1,4.7,377.56],[2,1.01,30]],"batl":[[0,55,2],[1,100,2],[2,110,2]],"ltp":26.0,"tv":1795.1,"id":7445998},{"batb":[[0,1.02,8.36],[1,1.01,2408.01],[2,1.01,0]],"batl":[[0,1.11,11.86],[1,1.13,11.86],[2,1.15,14.82]],"ltp":1.04,"tv":26875.25,"id":9629022}]}]}
{"op":"mcm","clk":"4228515073","pt":1631462148698,"mc":[{"id":"1.187551081","rc":[{"batl":[[0,100,2],[1,110,2],[2,990,0.01]],"ltp":26.0,"tv":1795.1,"id":7445998},{"batb":[[0,1.02,6.16]],"ltp":1.04,"tv":26875.25,"id":9629022}]}]}
{"op":"mcm","clk":"4228515493","pt":1631462151475,"mc":[{"id":"1.187551081","rc":[{"batb":[[0,1.02,1328.37]],"batl":[[0,1.06,1087.28],[1,1.07,223.92],[2,1.11,11.86]],"ltp":1.04,"tv":26875.25,"id":9629022}]}]}
{"op":"mcm","clk":"4228515611","pt":1631462152274,"mc":[{"id":"1.187551081","rc":[{"batb":[[0,18,33.49],[1,17.5,2],[2,4.7,377.56]],"ltp":26.0,"tv":1795.1,"id":7445998},{"batb":[[0,1.02,6.16]],"batl":[[0,1.06,41],[1,1.11,11.86],[2,1.13,11.86]],"ltp":1.04,"tv":26875.25,"id":9629022}]}]}
{"op":"mcm","clk":"4228515968","pt":1631462154582,"mc":[{"id":"1.187551081","rc":[{"batl":[[0,36,77.15],[1,100,2],[2,110,2]],"ltp":26.0,"tv":1795.1,"id":7445998}]}]}
{"op":"mcm","clk":"4228516106","pt":1631462155595,"mc":[{"id":"1.187551081","rc":[{"batl":[[0,55,2]],"ltp":26.0,"tv":1795.1,"id":7445998},{"batb":[[0,1.03,1309.37],[1,1.02,1383.74],[2,1.01,2408.01]],"batl":[[0,1.05,1284.44],[1,1.06,41],[2,1.11,11.86]],"ltp":1.04,"tv":26875.25,"id":9629022}]}]}
{"op":"mcm","clk":"4228516259","pt":1631462156659,"mc":[{"id":"1.187551081","rc":[{"batb":[[0,22,11.36],[1,18,33.49],[2,17.5,2]],"batl":[[0,36,6.56],[1,55,2],[2,100,2]],"ltp":26.0,"tv":1795.1,"id":7445998},{"batb":[[0,1.03,1340.17]],"batl":[[0,1.05,1489.44]],"ltp":1.04,"tv":26875.25,"id":9629022}]}]}
{"op":"mcm","clk":"4228516396","pt":1631462157593,"mc":[{"id":"1.187551081","rc":[{"batb":[[0,18,33.49],[1,17.5,2],[2,4.7,377.56]],"batl":[[0,100,2],[1,110,2],[2,990,0.01]],"ltp":26.0,"tv":1795.1,"id":7445998},{"batb":[[0,1.02,6.16],[1,1.01,2408.01],[2,1.01,0]],"batl":[[0,1.06,41],[1,1.11,11.86],[2,1.13,11.86]],"ltp":1.04,"tv":26875.25,"id":9629022}]}]}
{"op":"mcm","clk":"4228516734","pt":1631462160111,"mc":[{"id":"1.187551081","rc":[{"batb":[[0,1.02,1328.37]],"batl":[[0,1.06,1087.28],[1,1.07,223.92],[2,1.11,11.86]],"ltp":1.04,"tv":26875.25,"id":9629022}]}]}
{"op":"mcm","clk":"4228516839","pt":1631462160798,"mc":[{"id":"1.187551081","rc":[{"batl":[[0,55,2],[1,100,2],[2,110,2]],"ltp":26.0,"tv":1795.1,"id":7445998},{"batb":[[0,1.02,2610.45]],"ltp":1.04,"tv":26875.25,"id":9629022}]}]}
{"op":"mcm","clk":"4228517409","pt":1631462165177,"mc":[{"id":"1.187551081","rc":[{"batb":[[1,4.7,377.56],[2,1.01,30]],"ltp":26.0,"tv":1795.1,"id":7445998},{"batl":[[0,1.06,41],[1,1.11,11.86],[2,1.13,11.86]],"ltp":1.04,"tv":26875.25,"id":9629022}]}]}
{"op":"mcm","clk":"4228517552","pt":1631462166406,"mc":[{"id":"1.187551081","rc":[{"batl":[[0,1.03,2],[1,1.06,41],[2,1.11,11.86]],"ltp":1.04,"tv":26875.25,"id":9629022}]}]}
{"op":"mcm","clk":"4228517900","pt":1631462168618,"mc":[{"id":"1.187551081","rc":[{"batb":[[0,30,7.83],[1,22,16.35],[2,18,33.49]],"batl":[[0,55,4]],"ltp":26.0,"tv":1795.1,"id":7445998},{"batb":[[0,1.02,2647.45],[1,1.01,2452.01]],"batl":[[0,1.03,658.32],[1,1.04,646.78],[2,1.06,56.05]],"ltp":1.04,"tv":26875.25,"id":9629022}]}]}
{"op":"mcm","clk":"4228518019","pt":1631462169406,"mc":[{"id":"1.187551081","rc":[{"batb":[[0,34,7.35],[1,30,7.83],[2,27,2]],"batl":[[0,50,2],[1,55,4],[2,100,2]],"ltp":26.0,"tv":1795.1,"id":7445998},{"batb":[[0,1.02,2818.55]],"batl":[[0,1.03,863.32]],"ltp":1.04,"tv":26875.25,"id":9629022}]}]}
{"op":"mcm","clk":"4228518420","pt":1631462172401,"mc":[{"id":"1.187551081","rc":[{"batl":[[0,48,3.13],[1,50,2],[2,55,4]],"ltp":26.0,"tv":1795.1,"id":7445998},{"batb":[[0,1.02,3531.77]],"batl":[[0,1.03,1569.62]],"ltp":1.04,"tv":26875.25,"id":9629022}]}]}
{"op":"mcm","clk":"4228520786","pt":1631462190544,"mc":[{"id":"1.187551081","rc":[{"batb":[[0,22,16.35],[1,18.5,2],[2,4.7,377.56]],"batl":[[0,55,2],[1,110,2],[2,990,0.01]],"ltp":26.0,"tv":1795.1,"id":7445998},{"batb":[[0,1.02,1507.14],[1,1.01,2408.01]],"batl":[[0,1.03,2],[1,1.06,41],[2,1.11,11.86]],"ltp":1.04,"tv":26875.25,"id":9629022}]}]}
{"op":"mcm","clk":"4228521164","pt":1631462193504,"mc":[{"id":"1.187551081","rc":[{"batb":[[0,22,18.35],[1,21,2],[2,18.5,2]],"ltp":26.0,"tv":1795.1,"id":7445998}]}]}
{"op":"mcm","clk":"4228521534","pt":1631462196537,"mc":[{"id":"1.187551081","rc":[{"batb":[[0,1.02,2610.45]],"batl":[[1,1.04,1326.79],[2,1.06,41]],"ltp":1.04,"tv":26875.25,"id":9629022}]}]}
{"op":"mcm","clk":"4228521758","pt":1631462198233,"mc":[{"id":"1.187551081","rc":[{"batb":[[0,30,8.33],[1,22,18.35],[2,21,2]],"batl":[[0,48,4.69],[1,55,2],[2,110,2]],"ltp":26.0,"tv":1795.1,"id":7445998},{"batb":[[0,1.02,2855.55]],"batl":[[0,1.03,12]],"ltp":1.04,"tv":26875.25,"id":9629022}]}]}
{"op":"mcm","clk":"4228522103","pt":1631462200608,"mc":[{"id":"1.187551081","rc":[{"batb":[[0,22,18.35],[1,21,2],[2,18.5,2]],"batl":[[0,55,2],[1,110,2],[2,990,0.01]],"ltp":26.0,"tv":1795.1,"id":7445998},{"batb":[[0,1.02,1507.14]],"batl":[[0,1.03,2002],[1,1.04,30]],"ltp":1.04,"tv":26875.25,"id":9629022}]}]}
{"op":"mcm","clk":"4228522435","pt":1631462203241,"mc":[{"id":"1.187551081","rc":[{"batb":[[1,1.01,3522.24]],"batl":[[2,1.05,1284.44]],"ltp":1.04,"tv":26875.25,"id":9629022}]}]}
{"op":"mcm","clk":"4228522512","pt":1631462203945,"mc":[{"id":"1.187551081","rc":[{"batb":[[0,1.02,1288.24],[1,1.01,2408.01]],"ltp":1.04,"tv":26875.25,"id":9629022}]}]}
{"op":"mcm","clk":"4228522690","pt":1631462205638,"mc":[{"id":"1.187551081","rc":[{"batb":[[1,4.7,377.56],[2,1.01,30]],"ltp":26.0,"tv":1795.1,"id":7445998},{"trd":[[1.03,6321.45]],"batl":[[0,1.04,30],[1,1.05,1284.44],[2,1.06,41]],"ltp":1.03,"tv":30879.25,"id":9629022}],"tv":32674.36}]}
{"op":"mcm","clk":"4228522911","pt":1631462207516,"mc":[{"id":"1.187551081","rc":[{"batb":[[1,16,20.35],[2,4.7,377.56]],"batl":[[0,36,2.07],[1,55,2],[2,110,2]],"ltp":26.0,"tv":1795.1,"id":7445998},{"batb":[[0,1.03,1518.2],[1,1.02,5232.13],[2,1.01,2408.01]],"ltp":1.03,"tv":30879.25,"id":9629022}]}]}
{"op":"mcm","clk":"4228523037","pt":1631462208519,"mc":[{"id":"1.187551081","rc":[{"batb":[[0,23,10.78],[1,22,18.35],[2,16,20.35]],"ltp":26.0,"tv":1795.1,"id":7445998},{"batb":[[0,1.03,1704.78]],"batl":[[0,1.04,120.53]],"ltp":1.03,"tv":30879.25,"id":9629022}]}]}
{"op":"mcm","clk":"4228523171","pt":1631462209429,"mc":[{"id":"1.187551081","rc":[{"batb":[[0,23,2],[2,21,2]],"batl":[[0,34,2],[1,36,2.07],[2,50,2]],"ltp":26.0,"tv":1795.1,"id":7445998},{"batb":[[0,1.03,1733.78],[1,1.02,5267.13]],"ltp":1.03,"tv":30879.25,"id":9629022}]}]}
{"op":"mcm","clk":"4228523441","pt":1631462211452,"mc":[{"id":"1.187551081","rc":[{"batb":[[0,24,2],[1,23,2],[2,22,18.35]],"batl":[[0,32,8.49],[1,34,2],[2,36,2.07]],"ltp":26.0,"tv":1795.1,"id":7445998},{"batb":[[0,1.03,2483.04]],"batl":[[1,1.05,2019.43]],"ltp":1.03,"tv":30879.25,"id":9629022}]}]}
{"op":"mcm","clk":"4228523944","pt":1631462215482,"mc":[{"id":"1.187551081","rc":[{"batb":[[0,25,10.78],[1,24,2],[2,23,2]],"ltp":26.0,"tv":1795.1,"id":7445998}]}]}
{"op":"mcm","clk":"4228524568","pt":1631462220299,"mc":[{"id":"1.187551081","rc":[{"batb":[[0,16,20.35],[1,4.7,377.56],[2,1.01,30]],"batl":[[0,55,2],[1,110,2],[2,990,0.01]],"ltp":26.0,"tv":1795.1,"id":7445998},{"batb":[[0,1.02,1288.24],[1,1.01,2408.01],[2,1.01,0]],"batl":[[0,1.04,30],[1,1.11,11.86],[2,1.13,11.86]],"ltp":1.03,"tv":30879.25,"id":9629022}]}]}
{"op":"mcm","clk":"4228524636","pt":1631462220691,"mc":[{"id":"1.187551081","rc":[{"batl":[[0,110,2],[1,990,0.01],[2,990,0]],"ltp":26.0,"tv":1795.1,"id":7445998},{"batb":[[0,1.02,6.16]],"ltp":1.03,"tv":30879.25,"id":9629022}]}]}
{"op":"mcm","clk":"4228524936","pt":1631462222865,"mc":[{"id":"1.187551081","rc":[{"batb":[[0,1.02,1328.37]],"batl":[[1,1.07,1260.42],[2,1.11,11.86]],"ltp":1.03,"tv":30879.25,"id":9629022}]}]}
{"op":"mcm","clk":"4228525067","pt":1631462223862,"mc":[{"id":"1.187551081","rc":[{"batl":[[0,55,2],[1,110,2],[2,990,0.01]],"ltp":26.0,"tv":1795.1,"id":7445998},{"batb":[[0,1.02,2731.97]],"ltp":1.03,"tv":30879.25,"id":9629022}]}]}
{"op":"mcm","clk":"4228525306","pt":1631462225481,"mc":[{"id":"1.187551081","rc":[{"batl":[[0,110,2],[1,990,0.01],[2,990,0]],"ltp":26.0,"tv":1795.1,"id":7445998},{"batb":[[0,1.02,6.16]],"batl":[[0,1.06,50],[1,1.11,11.86],[2,1.13,11.86]],"ltp":1.03,"tv":30879.25,"id":9629022}]}]}
{"op":"mcm","clk":"4228525733","pt":1631462228299,"mc":[{"id":"1.187551081","rc":[{"trd":[[34,0.15]],"ltp":34.0,"tv":1795.25,"id":7445998},{"trd":[[1.03,6326.47]],"batb":[[0,1.04,1064.95],[1,1.03,255.91],[2,1.02,6.16]],"batl":[[0,1.05,1189.27],[1,1.06,50],[2,1.11,11.86]],"ltp":1.03,"tv":30884.27,"id":9629022}],"tv":32679.53}]}
{"op":"mcm","clk":"4228525907","pt":1631462229498,"mc":[{"id":"1.187551081","rc":[{"batb":[[0,20,12.5],[1,16,20.35],[2,4.7,377.56]],"batl":[[0,34,7.35],[1,55,2],[2,110,2]],"ltp":34.0,"tv":1795.25,"id":7445998},{"batb":[[1,1.03,264.88],[2,1.02,1253.42]],"batl":[[0,1.05,1408.07]],"ltp":1.03,"tv":30884.27,"id":9629022}]}]}
{"op":"mcm","clk":"4228526037","pt":1631462230614,"mc":[{"id":"1.187551081","rc":[{"batb":[[0,16,20.35],[1,4.7,377.56],[2,1.01,30]],"batl":[[0,55,2],[1,110,2],[2,520,36.07]],"ltp":34.0,"tv":1795.25,"id":7445998},{"batb":[[0,1.02,1253.42],[1,1.01,2408.01],[2,1.02,0]],"batl":[[0,1.06,50],[1,1.11,11.86],[2,1.13,11.86]],"ltp":1.03,"tv":30884.27,"id":9629022}]}]}
{"op":"mcm","clk":"4228526192","pt":1631462231607,"mc":[{"id":"1.187551081","rc":[{"batl":[[0,110,2],[1,520,36.07],[2,990,0.01]],"ltp":34.0,"tv":1795.25,"id":7445998},{"batb":[[0,1.02,6.16]],"ltp":1.03,"tv":30884.27,"id":9629022}]}]}
{"op":"mcm","clk":"4228526453","pt":1631462233627,"mc":[{"id":"1.187551081","rc":[{"batb":[[0,1.03,546.68],[1,1.02,1328.37],[2,1.01,2408.01]],"batl":[[0,1.05,490.93],[1,1.06,50],[2,1.07,1260.42]],"ltp":1.03,"tv":30884.27,"id":9629022}]}]}
{"op":"mcm","clk":"4228526514","pt":1631462234106,"mc":[{"id":"1.187551081","rc":[{"batl":[[0,55,2],[1,110,2],[2,520,36.07]],"ltp":34.0,"tv":1795.25,"id":7445998},{"batb":[[0,1.02,2582.78],[1,1.01,2408.01],[2,1.01,0]],"batl":[[0,1.06,50],[1,1.07,1260.42],[2,1.11,11.86]],"ltp":1.03,"tv":30884.27,"id":9629022}]}]}
{"op":"mcm","clk":"4228526849","pt":1631462237030,"mc":[{"id":"1.187551081","rc":[{"batl":[[1,1.11,11.86],[2,1.13,11.86]],"ltp":1.03,"tv":30884.27,"id":9629022}]}]}
{"op":"mcm","clk":"4228527046","pt":1631462238484,"mc":[{"id":"1.187551081","rc":[{"batl":[[2,990,0.01]],"ltp":34.0,"tv":1795.25,"id":7445998}]}]}
{"op":"mcm","clk":"4228527102","pt":1631462239025,"mc":[{"id":"1.187551081","rc":[{"batl":[[0,1.05,50],[1,1.06,50],[2,1.11,11.86]],"ltp":1.03,"tv":30884.27,"id":9629022}]}]}
{"op":"mcm","clk":"4228527250","pt":1631462240213,"mc":[{"id":"1.187551081","rc":[{"batl":[[0,1.03,437.37],[1,1.04,863.61],[2,1.05,50]],"ltp":1.03,"tv":30884.27,"id":9629022}]}]}
{"op":"mcm","clk":"4228527452","pt":1631462241598,"mc":[{"id":"1.187551081","rc":[{"batb":[[0,32,7.81],[1,30,8.33],[2,21,19.73]],"batl":[[0,50,5.84],[1,55,2],[2,110,2]],"ltp":34.0,"tv":1795.25,"id":7445998},{"batb":[[0,1.02,2787.76]],"batl":[[1,1.04,1103.99],[2,1.05,100]],"ltp":1.03,"tv":30884.27,"id":9629022}]}]}
{"op":"mcm","clk":"4228527606","pt":1631462242591,"mc":[{"id":"1.187551081","rc":[{"batb":[[2,22,2]],"batl":[[0,50,2]],"ltp":34.0,"tv":1795.25,"id":7445998},{"batl":[[1,1.04,912.61]],"ltp":1.03,"tv":30884.27,"id":9629022}]}]}
{"op":"mcm","clk":"4228527639","pt":1631462242923,"mc":[{"id":"1.187551081","rc":[{"batb":[[2,27,2]],"ltp":34.0,"tv":1795.25,"id":7445998}]}]}
{"op":"mcm","clk":"4228527834","pt":1631462244514,"mc":[{"id":"1.187551081","rc":[{"trd":[[34,1.86]],"ltp":34.0,"tv":1796.96,"id":7445998},{"trd":[[1.03,6382.85]],"batb":[[0,1.02,3339.79]],"batl":[[0,1.03,380.99],[1,1.04,1408.26]],"ltp":1.03,"tv":30940.65,"id":9629022}],"tv":32737.61}]}
{"op":"mcm","clk":"4228527922","pt":1631462245112,"mc":[{"id":"1.187551081","rc":[{"batl":[[0,48,2],[1,50,2],[2,55,2]],"ltp":34.0,"tv":1796.96,"id":7445998},{"batl":[[0,1.03,621.37]],"ltp":1.03,"tv":30940.65,"id":9629022}]}]}
{"op":"mcm","clk":"4228528234","pt":1631462247509,"mc":[{"id":"1.187551081","rc":[{"batl":[[0,1.03,646.6],[1,1.04,1439.12]],"ltp":1.03,"tv":30940.65,"id":9629022}]}]}
{"op":"mcm","clk":"4228528337","pt":1631462248210,"mc":[{"id":"1.187551081","rc":[{"batl":[[0,46,3.84],[1,48,2],[2,50,2]],"ltp":34.0,"tv":1796.96,"id":7445998},{"batb":[[0,1.02,3333.63]],"ltp":1.03,"tv":30940.65,"id":9629022}]}]}
{"op":"mcm","clk":"4228528834","pt":1631462251623,"mc":[{"id":"1.187551081","rc":[{"batb":[[0,30,8.33],[1,22,2],[2,21,21.73]],"batl":[[0,110,2],[1,990,0.01],[2,50,0]],"ltp":34.0,"tv":1796.96,"id":7445998},{"trd":[[1.03,6395.16]],"batb":[[0,1.02,1874.24]],"batl":[[0,1.03,400.06],[1,1.04,1390.12]],"ltp":1.03,"tv":30952.96,"id":9629022}],"tv":32749.93}]}
{"op":"mcm","clk":"4228528938","pt":1631462252335,"mc":[{"id":"1.187551081","rc":[{"batb":[[0,22,2],[1,21,21.73],[2,18,2]],"batl":[[0,990,0.01],[1,990,0]],"ltp":34.0,"tv":1796.96,"id":7445998},{"batl":[[0,1.05,100],[1,1.06,50],[2,1.11,11.86]],"ltp":1.03,"tv":30952.96,"id":9629022}]}]}
{"op":"mcm","clk":"4228529372","pt":1631462255524,"mc":[{"id":"1.187551081","rc":[{"batb":[[1,21,19.73],[2,4.7,377.56]],"ltp":34.0,"tv":1796.96,"id":7445998}]}]}
{"op":"mcm","clk":"4228529497","pt":1631462256547,"mc":[{"id":"1.187551081","rc":[{"batl":[[0,48,64.39],[1,990,0.01]],"ltp":34.0,"tv":1796.96,"id":7445998}]}]}
{"op":"mcm","clk":"4228529605","pt":1631462257345,"mc":[{"id":"1.187551081","rc":[{"batl":[[0,990,0.01],[1,990,0]],"ltp":34.0,"tv":1796.96,"id":7445998},{"trd":[[1.03,6436.16]],"batb":[[0,1.03,345.81],[1,1.02,952.31]],"batl":[[0,1.04,1296.79],[1,1.05,100],[2,1.06,50]],"ltp":1.03,"tv":30993.96,"id":9629022}],"tv":32790.93}]}
{"op":"mcm","clk":"4228529780","pt":1631462258644,"mc":[{"id":"1.187551081","rc":[{"batb":[[0,30,8.33],[1,22,2],[2,21,21.73]],"batl":[[0,110,2],[1,990,0.01]],"ltp":34.0,"tv":1796.96,"id":7445998},{"batb":[[1,1.02,957.31],[2,1.01,2437]],"batl":[[0,1.04,1537.17]],"ltp":1.03,"tv":30993.96,"id":9629022}]}]}
{"op":"mcm","clk":"4228529932","pt":1631462259642,"mc":[{"id":"1.187551081","rc":[{"batl":[[0,48,2.15],[1,110,2],[2,990,0.01]],"ltp":34.0,"tv":1796.96,"id":7445998},{"batl":[[0,1.04,1587.17]],"ltp":1.03,"tv":30993.96,"id":9629022}]}]}
{"op":"mcm","clk":"4228530005","pt":1631462260328,"mc":[{"id":"1.187551081","rc":[{"batb":[[0,22,2],[1,21,21.73],[2,4.7,377.56]],"batl":[[0,990,0.01],[1,110,0],[2,990,0]],"ltp":34.0,"tv":1796.96,"id":7445998},{"batb":[[0,1.01,50],[1,1.02,0],[2,1.01,0]],"batl":[[0,1.04,50]],"ltp":1.03,"tv":30993.96,"id":9629022}]}]}
{"op":"mcm","clk":"4228530283","pt":1631462262457,"mc":[{"id":"1.187551081","rc":[{"batl":[[0,1.03,20],[1,1.04,50],[2,1.05,100]],"ltp":1.03,"tv":30993.96,"id":9629022}]}]}
{"op":"mcm","clk":"4228530410","pt":1631462263538,"mc":[{"id":"1.187551081","rc":[{"batb":[[0,1.01,4125.46]],"batl":[[1,1.05,1384.44],[2,1.06,50]],"ltp":1.03,"tv":30993.96,"id":9629022}]}]}
{"op":"mcm","clk":"4228530550","pt":1631462264654,"mc":[{"id":"1.187551081","rc":[{"batl":[[0,110,2],[1,990,0.01]],"ltp":34.0,"tv":1796.96,"id":7445998},{"batb":[[0,1.01,2790.16]],"ltp":1.03,"tv":30993.96,"id":9629022}]}]}
{"op":"mcm","clk":"4228530647","pt":1631462265350,"mc":[{"id":"1.187551081","rc":[{"trd":[[1.03,6476.16]],"batl":[[0,1.05,1384.44],[1,1.06,50],[2,1.11,11.86]],"ltp":1.03,"tv":31033.96,"id":9629022}],"tv":32830.93}]}
{"op":"mcm","clk":"4228530923","pt":1631462267138,"mc":[{"id":"1.187551081","rc":[{"batl":[[0,36,2.07],[1,110,2],[2,990,0.01]],"ltp":34.0,"tv":1796.96,"id":7445998},{"batb":[[0,1.04,817.92],[1,1.03,692.34],[2,1.01,2790.16]],"batl":[[2,1.07,14.91]],"ltp":1.03,"tv":31033.96,"id":9629022}]}]}
{"op":"mcm","clk":"4228531106","pt":1631462268472,"mc":[{"id":"1.187551081","rc":[{"batb":[[0,23,7.44],[1,22,2],[2,21,21.73]],"ltp":34.0,"tv":1796.96,"id":7445998},{"batb":[[2,1.02,3886.45]],"batl":[[0,1.05,1622.54]],"ltp":1.03,"tv":31033.96,"id":9629022}]}]}
{"op":"mcm","clk":"4228531167","pt":1631462268858,"mc":[{"id":"1.187551081","rc":[{"batl":[[2,520,36.07]],"ltp":34.0,"tv":1796.96,"id":7445998}]}]}
{"op":"mcm","clk":"4228531377","pt":1631462270564,"mc":[{"id":"1.187551081","rc":[{"batb":[[0,23,2],[1,21,19.73],[2,14,28.39]],"batl":[[0,34,2],[1,36,2.07],[2,110,2]],"ltp":34.0,"tv":1796.96,"id":7445998},{"batl":[[1,1.07,14.91],[2,1.11,11.86]],"ltp":1.03,"tv":31033.96,"id":9629022}]}]}
{"op":"mcm","clk":"4228531498","pt":1631462271553,"mc":[{"id":"1.187551081","rc":[{"batl":[[0,30,6.95],[1,34,2],[2,36,2.07]],"ltp":34.0,"tv":1796.96,"id":7445998},{"batb":[[1,1.03,1281.36]],"batl":[[0,1.05,2171.16]],"ltp":1.03,"tv":31033.96,"id":9629022}]}]}
{"op":"mcm","clk":"4228531564","pt":1631462272078,"mc":[{"id":"1.187551081","rc":[{"batl":[[0,34,2],[1,36,2.07],[2,110,2]],"ltp":34.0,"tv":1796.96,"id":7445998}]}]}
{"op":"mcm","clk":"4228531761","pt":1631462273553,"mc":[{"id":"1.187551081","rc":[{"batl":[[2,55,2]],"ltp":34.0,"tv":1796.96,"id":7445998},{"batb":[[2,1.02,5151.75]],"ltp":1.03,"tv":31033.96,"id":9629022}]}]}
{"op":"mcm","clk":"4228531779","pt":1631462273669,"mc":[{"id":"1.187551081","rc":[{"batb":[[0,24,7.44],[1,23,2],[2,21,19.73]],"ltp":34.0,"tv":1796.96,"id":7445998}]}]}
{"op":"mcm","clk":"4228531962","pt":1631462275051,"mc":[{"id":"1.187551081","rc":[{"batl":[[0,26,25.72],[1,32,6.95],[2,34,2]],"ltp":34.0,"tv":1796.96,"id":7445998},{"batb":[[0,1.04,1461.02],[1,1.03,2130.28]],"ltp":1.03,"tv":31033.96,"id":9629022}]}]}
{"op":"mcm","clk":"4228532059","pt":1631462275748,"mc":[{"id":"1.187551081","rc":[{"batl":[[1,1.06,624.31],[2,1.07,757.08]],"ltp":1.03,"tv":31033.96,"id":9629022}]}]}
{"op":"mcm","clk":"4228532180","pt":1631462276742,"mc":[{"id":"1.187551081","rc":[{"batb":[[0,1.04,2035.7]],"ltp":1.03,"tv":31033.96,"id":9629022}]}]}
{"op":"mcm","clk":"4228532456","pt":1631462278653,"mc":[{"id":"1.187551081","rc":[{"batl":[[0,32,6.95],[1,34,2],[2,36,2.07]],"ltp":34.0,"tv":1796.96,"id":7445998},{"batb":[[0,1.04,1412.6],[1,1.03,1281.36]],"batl":[[1,1.07,14.91],[2,1.11,11.86]],"ltp":1.03,"tv":31033.96,"id":9629022}]}]}
{"op":"mcm","clk":"4228532872","pt":1631462282166,"mc":[{"id":"1.187551081","rc":[{"batl":[[0,30,2]],"ltp":34.0,"tv":1796.96,"id":7445998}]}]}
{"op":"mcm","clk":"4228533340","pt":1631462285470,"mc":[{"id":"1.187551081","rc":[{"batb":[[0,14,28.39],[1,4.7,377.56],[2,1.01,30]],"batl":[[0,55,2],[1,110,2],[2,520,36.07]],"ltp":34.0,"tv":1796.96,"id":7445998},{"batb":[[0,1.04,20],[1,1.02,1265.3],[2,1.01,2790.16]],"batl":[[0,1.05,50],[1,1.11,11.86],[2,1.13,11.86]],"ltp":1.03,"tv":31033.96,"id":9629022}]}]}
{"op":"mcm","clk":"4228533540","pt":1631462286863,"mc":[{"id":"1.187551081","rc":[{"batb":[[1,1.01,30],[2,1.01,0]],"batl":[[2,990,0.01]],"ltp":34.0,"tv":1796.96,"id":7445998},{"trd":[[1.05,2463.07]],"batb":[[0,1.05,350],[1,1.04,20],[2,1.02,1265.3]],"batl":[[0,1.11,11.86],[1,1.13,11.86],[2,1.15,14.82]],"ltp":1.05,"tv":31133.96,"id":9629022}],"tv":32930.93}]}
{"op":"mcm","clk":"4228533728","pt":1631462288287,"mc":[{"id":"1.187551081","rc":[{"batb":[[0,14,30.39],[1,13.5,2],[2,1.01,30]],"ltp":34.0,"tv":1796.96,"id":7445998},{"batb":[[2,1.02,2587.51]],"batl":[[0,1.08,1102.19],[1,1.11,11.86],[2,1.13,11.86]],"ltp":1.05,"tv":31133.96,"id":9629022}]}]}
{"op":"mcm","clk":"4228533987","pt":1631462290373,"mc":[{"id":"1.187551081","rc":[{"trd":[[1.05,2587.22]],"batb":[[0,1.05,287.93]],"batl":[[0,1.08,1124.19]],"ltp":1.05,"tv":31258.11,"id":9629022}],"tv":33055.07}]}
{"op":"mcm","clk":"4228534621","pt":1631462294982,"mc":[{"id":"1.187551081","rc":[{"batb":[[2,1.02,1265.3]],"ltp":1.05,"tv":31258.11,"id":9629022}]}]}
{"op":"mcm","clk":"4228534957","pt":1631462297381,"mc":[{"id":"1.187551081","rc":[{"batl":[[1,1.13,11.86],[2,1.15,14.82]],"ltp":1.05,"tv":31258.11,"id":9629022}]}]}
{"op":"mcm","clk":"4228535058","pt":1631462298183,"mc":[{"id":"1.187551081","rc":[{"batb":[[0,1.06,1272.32],[1,1.05,287.93],[2,1.04,20]],"batl":[[1,1.09,14.64],[2,1.13,11.86]],"ltp":1.05,"tv":31258.11,"id":9629022}]}]}
{"op":"mcm","clk":"4228535191","pt":1631462299090,"mc":[{"id":"1.187551081","rc":[{"batb":[[2,9.2,70.93]],"ltp":34.0,"tv":1796.96,"id":7445998},{"batb":[[1,1.05,2284.08]],"ltp":1.05,"tv":31258.11,"id":9629022}]}]}
{"op":"mcm","clk":"4228535400","pt":1631462300524,"mc":[{"id":"1.187551081","rc":[{"batb":[[0,14.5,11.04],[1,14,28.39]],"batl":[[0,20,2],[1,21,10],[2,55,2]],"ltp":34.0,"tv":1796.96,"id":7445998},{"batb":[[0,1.06,1392.05],[1,1.05,2318.08]],"batl":[[0,1.07,36.96],[1,1.08,1124.19],[2,1.09,14.64]],"ltp":1.05,"tv":31258.11,"id":9629022}]}]}
{"op":"mcm","clk":"4228535422","pt":1631462300679,"mc":[{"id":"1.187551081","rc":[{"batb":[[0,14.5,2]],"batl":[[1,55,2],[2,65,41.03]],"ltp":34.0,"tv":1796.96,"id":7445998}]}]}
{"op":"mcm","clk":"4228535737","pt":1631462303020,"mc":[{"id":"1.187551081","rc":[{"batb":[[0,15,2],[1,14.5,2],[2,14,28.39]],"ltp":34.0,"tv":1796.96,"id":7445998},{"batb":[[0,1.06,1934.4]],"batl":[[1,1.08,1616.67]],"ltp":1.05,"tv":31258.11,"id":9629022}]}]}
{"op":"mcm","clk":"4228535951","pt":1631462304499,"mc":[{"id":"1.187551081","rc":[{"batb":[[0,15,11.04]],"batl":[[0,19.5,10],[1,20,2],[2,26,2]],"ltp":34.0,"tv":1796.96,"id":7445998},{"trd":[[1.07,106.7]],"batb":[[2,1.04,685.12]],"batl":[[0,1.07,16.96]],"ltp":1.07,"tv":31298.11,"id":9629022}],"tv":33095.07}]}
{"op":"mcm","clk":"4228536043","pt":1631462305096,"mc":[{"id":"1.187551081","rc":[{"trd":[[1.07,126.7]],"batl":[[0,1.07,6.96]],"ltp":1.07,"tv":31318.11,"id":9629022}],"tv":33115.07}]}
{"op":"mcm","clk":"4228536628","pt":1631462309397,"mc":[{"id":"1.187551081","rc":[{"batb":[[1,1.05,2030.15]],"ltp":1.07,"tv":31318.11,"id":9629022}]}]}
{"op":"mcm","clk":"4228536797","pt":1631462310515,"mc":[{"id":"1.187551081","rc":[{"batb":[[0,14,28.39],[1,9.2,70.93],[2,4.1,377.46]],"batl":[[0,26,2],[1,55,2],[2,65,41.03]],"ltp":34.0,"tv":1796.96,"id":7445998},{"batb":[[0,1.05,1996.15],[1,1.04,685.12],[2,1.03,821.83]],"batl":[[0,1.07,6.16],[1,1.09,14.64],[2,1.13,11.86]],"ltp":1.07,"tv":31318.11,"id":9629022}]}]}
{"op":"mcm","clk":"4228536840","pt":1631462310939,"mc":[{"id":"1.187551081","rc":[{"batb":[[0,9.2,70.93],[1,4.1,377.46],[2,1.01,30]],"batl":[[0,55,2],[1,65,41.03],[2,110,2]],"ltp":34.0,"tv":1796.96,"id":7445998},{"batb":[[0,1.04,20],[1,1.02,4811.02],[2,1.01,2790.16]],"batl":[[1,1.13,11.86],[2,1.15,14.82]],"ltp":1.07,"tv":31318.11,"id":9629022}]}]}
{"op":"mcm","clk":"4228537079","pt":1631462312500,"mc":[{"id":"1.187551081","rc":[{"trd":[[1.07,139.02]],"batb":[[0,1.07,286.77],[1,1.04,20],[2,1.02,4811.02]],"batl":[[0,1.13,11.86],[1,1.15,14.82],[2,1.17,29.65]],"ltp":1.07,"tv":31330.42,"id":9629022}],"tv":33127.39}]}
{"op":"mcm","clk":"4228537184","pt":1631462313227,"mc":[{"id":"1.187551081","rc":[{"batb":[[1,1.04,1244.45]],"batl":[[0,1.12,207.26],[1,1.13,854.75],[2,1.15,14.82]],"ltp":1.07,"tv":31330.42,"id":9629022}]}]}
{"op":"mcm","clk":"4228537343","pt":1631462314243,"mc":[{"id":"1.187551081","rc":[{"batb":[[0,9.2,72.93],[1,9,3],[2,4.1,377.46]],"batl":[[0,26,2],[1,36,2],[2,55,4]],"ltp":34.0,"tv":1796.96,"id":7445998},{"batb":[[1,1.04,645.87],[2,1.03,4386.34]],"batl":[[0,1.13,11.86],[1,1.15,14.82],[2,1.17,29.65]],"ltp":1.07,"tv":31330.42,"id":9629022}]}]}
{"op":"mcm","clk":"4228537568","pt":1631462315626,"mc":[{"id":"1.187551081","rc":[{"trd":[[1.07,427.88]],"batb":[[0,1.07,142.34]],"ltp":1.07,"tv":31619.28,"id":9629022}],"tv":33416.25}]}
{"op":"mcm","clk":"4228537701","pt":1631462316522,"mc":[{"id":"1.187551081","rc":[{"batl":[[0,17.5,116.1],[1,26,2],[2,36,2]],"ltp":34.0,"tv":1796.96,"id":7445998},{"batl":[[0,1.12,18],[1,1.13,30.86],[2,1.15,14.82]],"ltp":1.07,"tv":31619.28,"id":9629022}]}]}
{"op":"mcm","clk":"4228537788","pt":1631462317110,"mc":[{"id":"1.187551081","rc":[{"batl":[[0,26,2],[1,36,2],[2,55,4]],"ltp":34.0,"tv":1796.96,"id":7445998},{"batb":[[0,1.07,1402.76]],"batl":[[0,1.09,1137.93]],"ltp":1.07,"tv":31619.28,"id":9629022}]}]}
{"op":"mcm","clk":"4228537916","pt":1631462318014,"mc":[{"id":"1.187551081","rc":[{"batb":[[0,11.5,21.74],[1,9.2,72.93],[2,9,3]],"batl":[[0,18,10],[1,26,2],[2,36,2]],"ltp":34.0,"tv":1796.96,"id":7445998},{"batb":[[0,1.07,1453.32]],"batl":[[1,1.12,10],[2,1.13,30.86]],"ltp":1.07,"tv":31619.28,"id":9629022}]}]}
{"op":"mcm","clk":"4228538245","pt":1631462320460,"mc":[{"id":"1.187551081","rc":[{"batb":[[0,9.2,72.93],[1,9,3],[2,4.1,377.46]],"batl":[[0,26,2],[1,36,2],[2,55,4]],"ltp":34.0,"tv":1796.96,"id":7445998},{"batb":[[0,1.07,142.34]],"batl":[[0,1.13,30.86],[1,1.15,14.82],[2,1.17,29.65]],"ltp":1.07,"tv":31619.28,"id":9629022}]}]}
{"op":"mcm","clk":"4228538704","pt":1631462323638,"mc":[{"id":"1.187551081","rc":[{"batb":[[0,1.08,491.15],[1,1.07,142.34],[2,1.04,1870.32]],"batl":[[0,1.12,627.05],[1,1.13,873.75],[2,1.14,10]],"ltp":1.07,"tv":31619.28,"id":9629022}]}]}
{"op":"mcm","clk":"4228538738","pt":1631462323838,"mc":[{"id":"1.187551081","rc":[{"batb":[[0,1.07,142.34],[1,1.04,1870.32],[2,1.03,4386.34]],"batl":[[0,1.12,207.26]],"ltp":1.07,"tv":31619.28,"id":9629022}]}]}
{"op":"mcm","clk":"4228539293","pt":1631462328149,"mc":[{"id":"1.187551081","rc":[{"batl":[[0,1.11,5],[1,1.12,207.26],[2,1.13,873.75]],"ltp":1.07,"tv":31619.28,"id":9629022}]}]}
{"op":"mcm","clk":"4228539379","pt":1631462328770,"mc":[{"id":"1.187551081","rc":[{"batl":[[1,1.13,30.86],[2,1.14,10]],"ltp":1.07,"tv":31619.28,"id":9629022}]}]}
{"op":"mcm","clk":"4228539624","pt":1631462330349,"mc":[{"id":"1.187551081","rc":[{"batb":[[1,4.1,377.46],[2,1.01,30]],"batl":[[2,55,2]],"ltp":34.0,"tv":1796.96,"id":7445998}]}]}
{"op":"mcm","clk":"4228539817","pt":1631462331643,"mc":[{"id":"1.187551081","rc":[{"trd":[[1.07,712.56]],"batb":[[0,1.04,1870.32],[1,1.03,4386.34],[2,1.02,1265.3]],"batl":[[0,1.05,1034.7],[1,1.06,247.38],[2,1.11,5]],"ltp":1.07,"tv":31903.96,"id":9629022}],"tv":33700.93}]}
{"op":"mcm","clk":"4228539937","pt":1631462332473,"mc":[{"id":"1.187551081","rc":[{"batb":[[0,20,22.94],[1,13.5,30.65],[2,9.2,72.93]],"ltp":34.0,"tv":1796.96,"id":7445998},{"batb":[[0,1.04,1850.32]],"batl":[[2,1.07,14.91]],"ltp":1.07,"tv":31903.96,"id":9629022}]}]}
{"op":"mcm","clk":"4228540092","pt":1631462333553,"mc":[{"id":"1.187551081","rc":[{"batb":[[1,15.5,7.51],[2,15,2]],"ltp":34.0,"tv":1796.96,"id":7445998},{"batl":[[2,1.07,47.91]],"ltp":1.07,"tv":31903.96,"id":9629022}]}]}
{"op":"mcm","clk":"4228540243","pt":1631462334656,"mc":[{"id":"1.187551081","rc":[{"batb":[[0,20,35.44],[1,18,2],[2,17.5,3]],"ltp":34.0,"tv":1796.96,"id":7445998},{"batl":[[0,1.05,1313.8]],"ltp":1.07,"tv":31903.96,"id":9629022}]}]}
{"op":"mcm","clk":"4228540331","pt":1631462335354,"mc":[{"id":"1.187551081","rc":[{"batb":[[0,22,2],[1,21,2],[2,20,22.94]],"ltp":34.0,"tv":1796.96,"id":7445998}]}]}
{"op":"mcm","clk":"4228540414","pt":1631462335960,"mc":[{"id":"1.187551081","rc":[{"batb":[[0,1.04,2360.36]],"batl":[[0,1.05,1761.57]],"ltp":1.07,"tv":31903.96,"id":9629022}]}]}
{"op":"mcm","clk":"4228540778","pt":1631462338440,"mc":[{"id":"1.187551081","rc":[{"batb":[[0,23,12.5],[1,22,2],[2,21,2]],"ltp":34.0,"tv":1796.96,"id":7445998}]}]}
{"op":"mcm","clk":"4228540864","pt":1631462339067,"mc":[{"id":"1.187551081","rc":[{"batb":[[0,22,2],[1,21,2],[2,20,22.94]],"ltp":34.0,"tv":1796.96,"id":7445998}]}]}
{"op":"mcm","clk":"4228541702","pt":1631462345179,"mc":[{"id":"1.187551081","rc":[{"trd":[[1.05,2599.53]],"batl":[[0,1.05,1755.41],[2,1.07,14.91]],"ltp":1.05,"tv":31916.28,"id":9629022}],"tv":33713.25}]}
{"op":"mcm","clk":"4228541784","pt":1631462345772,"mc":[{"id":"1.187551081","rc":[{"batb":[[0,23,5.85],[1,22,2],[2,21,2]],"ltp":34.0,"tv":1796.96,"id":7445998},{"trd":[[1.05,2600.47]],"batl":[[0,1.05,1754.94]],"ltp":1.05,"tv":31917.22,"id":9629022}],"tv":33714.19}]}
{"op":"mcm","clk":"4228542290","pt":1631462349578,"mc":[{"id":"1.187551081","rc":[{"batl":[[0,26,31.69],[1,36,28.54]],"ltp":34.0,"tv":1796.96,"id":7445998},{"batb":[[0,1.04,3102.52],[1,1.03,5313.83]],"ltp":1.05,"tv":31917.22,"id":9629022}]}]}
{"op":"mcm","clk":"4228542316","pt":1631462349779,"mc":[{"id":"1.187551081","rc":[{"batb":[[2,20,22.94]],"ltp":34.0,"tv":1796.96,"id":7445998}]}]}
{"op":"mcm","clk":"4228542536","pt":1631462351294,"mc":[{"id":"1.187551081","rc":[{"batb":[[0,13.5,30.65],[1,4.1,377.46],[2,1.01,30]],"batl":[[0,520,36.07],[1,990,0.01],[2,55,0]],"ltp":34.0,"tv":1796.96,"id":7445998},{"batb":[[0,1.01,50],[1,1.03,0],[2,1.02,0]],"batl":[[0,1.11,5],[1,1.13,11.86],[2,1.14,10]],"ltp":1.05,"tv":31917.22,"id":9629022}]}]}
{"op":"mcm","clk":"4228542719","pt":1631462352489,"mc":[{"id":"1.187551081","rc":[{"batb":[[0,1.05,20],[1,1.01,50]],"ltp":1.05,"tv":31917.22,"id":9629022}]}]}
{"op":"mcm","clk":"4228542999","pt":1631462354496,"mc":[{"id":"1.187551081","rc":[{"batl":[[0,55,4],[1,110,2],[2,520,36.07]],"ltp":34.0,"tv":1796.96,"id":7445998},{"batb":[[1,1.02,1557.83],[2,1.01,2453.66]],"ltp":1.05,"tv":31917.22,"id":9629022}]}]}
{"op":"mcm","clk":"4228543123","pt":1631462355497,"mc":[{"id":"1.187551081","rc":[{"batl":[[0,55,2],[2,990,0.01]],"ltp":34.0,"tv":1796.96,"id":7445998},{"batb":[[1,1.02,114]],"ltp":1.05,"tv":31917.22,"id":9629022}]}]}
{"op":"mcm","clk":"4228543196","pt":1631462356103,"mc":[{"id":"1.187551081","rc":[{"trd":[[1.05,2610.47]],"batb":[[0,1.05,15]],"ltp":1.05,"tv":31927.22,"id":9629022}],"tv":33724.19}]}
{"op":"mcm","clk":"4228543382","pt":1631462357491,"mc":[{"id":"1.187551081","rc":[{"batb":[[1,1.04,1318.66],[2,1.02,114]],"batl":[[0,1.06,1292.57],[1,1.11,5],[2,1.13,11.86]],"ltp":1.05,"tv":31927.22,"id":9629022}]}]}
{"op":"mcm","clk":"4228543447","pt":1631462358017,"mc":[{"id":"1.187551081","rc":[{"batl":[[0,55,4]],"ltp":34.0,"tv":1796.96,"id":7445998},{"batb":[[1,1.04,1296.79],[2,1.02,1245.85]],"batl":[[0,1.06,1272.32]],"ltp":1.05,"tv":31927.22,"id":9629022}]}]}
{"op":"mcm","clk":"4228543659","pt":1631462359512,"mc":[{"id":"1.187551081","rc":[{"batb":[[0,18.5,13.51],[1,13.5,30.65],[2,4.1,377.46]],"batl":[[0,29,7.95],[1,55,4],[2,110,2]],"ltp":34.0,"tv":1796.96,"id":7445998},{"batl":[[0,1.06,1297.32]],"ltp":1.05,"tv":31927.22,"id":9629022}]}]}
{"op":"mcm","clk":"4228543856","pt":1631462360912,"mc":[{"id":"1.187551081","rc":[{"batb":[[0,13.5,30.65],[1,4.1,377.46],[2,1.01,30]],"batl":[[0,55,4],[1,110,2],[2,160,37.59]],"ltp":34.0,"tv":1796.96,"id":7445998},{"trd":[[1.05,2620.47]],"batb":[[0,1.05,10],[1,1.02,1245.85],[2,1.01,2453.66]],"batl":[[0,1.11,5],[1,1.13,11.86],[2,1.14,10]],"ltp":1.05,"tv":31937.22,"id":9629022}],"tv":33734.19}]}
{"op":"mcm","clk":"4228544075","pt":1631462362543,"mc":[{"id":"1.187551081","rc":[{"batl":[[0,1.07,6.16],[1,1.11,5],[2,1.13,11.86]],"ltp":1.05,"tv":31937.22,"id":9629022}]}]}
{"op":"mcm","clk":"4228544221","pt":1631462363607,"mc":[{"id":"1.187551081","rc":[{"batb":[[1,1.02,2568.06]],"batl":[[1,1.08,813.07],[2,1.09,431.69]],"ltp":1.05,"tv":31937.22,"id":9629022}]}]}
{"op":"mcm","clk":"4228544644","pt":1631462366456,"mc":[{"id":"1.187551081","rc":[{"trd":[[1.07,724.88]],"batb":[[0,1.07,8329.92],[1,1.05,10],[2,1.02,1245.85]],"batl":[[0,1.08,813.07],[1,1.09,431.69],[2,1.11,5]],"ltp":1.07,"tv":31949.54,"id":9629022}],"tv":33746.5}]}
{"op":"mcm","clk":"4228544960","pt":1631462368520,"mc":[{"id":"1.187551081","rc":[{"batl":[[2,990,0.01]],"ltp":34.0,"tv":1796.96,"id":7445998}]}]}
{"op":"mcm","clk":"4228545116","pt":1631462369633,"mc":[{"id":"1.187551081","rc":[{"batl":[[0,15.5,4.71],[1,55,4],[2,110,2]],"ltp":34.0,"tv":1796.96,"id":7445998},{"batb":[[0,1.07,562.83],[1,1.06,977.91],[2,1.05,10]],"batl":[[1,1.09,446.33],[2,1.13,11.86]],"ltp":1.07,"tv":31949.54,"id":9629022}]}]}
{"op":"mcm","clk":"4228545222","pt":1631462370442,"mc":[{"id":"1.187551081","rc":[{"batb":[[0,14,9.66],[1,13.5,30.65],[2,9,29.73]],"batl":[[1,19.5,11.2],[2,55,4]],"ltp":34.0,"tv":1796.96,"id":7445998},{"batb":[[2,1.05,1921.49]],"batl":[[0,1.08,981.17]],"ltp":1.07,"tv":31949.54,"id":9629022}]}]}
{"op":"mcm","clk":"4228545281","pt":1631462370922,"mc":[{"id":"1.187551081","rc":[{"trd":[[1.08,114.96]],"batl":[[0,1.08,971.17]],"ltp":1.08,"tv":31969.54,"id":9629022}],"tv":33766.5}]}
{"op":"mcm","clk":"4228545504","pt":1631462372421,"mc":[{"id":"1.187551081","rc":[{"batb":[[0,14,3],[1,13.5,32.65]],"ltp":34.0,"tv":1796.96,"id":7445998}]}]}
{"op":"mcm","clk":"4228545674","pt":1631462373542,"mc":[{"id":"1.187551081","rc":[{"batb":[[0,14.5,2],[1,14,3],[2,13.5,32.65]],"ltp":34.0,"tv":1796.96,"id":7445998}]}]}
{"op":"mcm","clk":"4228545838","pt":1631462374658,"mc":[{"id":"1.187551081","rc":[{"trd":[[1.07,1805.58]],"batb":[[0,1.07,660.93]],"batl":[[0,1.08,1625.98],[1,1.09,305.6]],"ltp":1.07,"tv":33050.24,"id":9629022}],"tv":34847.2}]}
{"op":"mcm","clk":"4228545956","pt":1631462375434,"mc":[{"id":"1.187551081","rc":[{"batb":[[0,14.5,11.66]],"batl":[[2,26,2]],"ltp":34.0,"tv":1796.96,"id":7445998},{"batb":[[0,1.06,977.91],[1,1.05,1911.49],[2,1.04,657.62]],"ltp":1.07,"tv":33050.24,"id":9629022}]}]}
{"op":"mcm","clk":"4228546275","pt":1631462377575,"mc":[{"id":"1.187551081","rc":[{"batb":[[0,1.06,1882.37]],"batl":[[0,1.08,1778.01]],"ltp":1.07,"tv":33050.24,"id":9629022}]}]}
{"op":"mcm","clk":"4228546374","pt":1631462378172,"mc":[{"id":"1.187551081","rc":[{"batb":[[0,1.06,2038.93],[1,1.05,1961.49]],"ltp":1.07,"tv":33050.24,"id":9629022}]}]}
{"op":"mcm","clk":"4228546609","pt":1631462379765,"mc":[{"id":"1.187551081","rc":[{"batl":[[0,1.07,2.17],[1,1.08,1778.01],[2,1.09,305.6]],"ltp":1.07,"tv":33050.24,"id":9629022}]}]}
{"op":"mcm","clk":"4228547146","pt":1631462383344,"mc":[{"id":"1.187551081","rc":[{"batb":[[0,14.5,2],[1,13.5,30.65],[2,9,29.73]],"ltp":34.0,"tv":1796.96,"id":7445998},{"trd":[[1.06,83.58]],"batb":[[0,1.06,2029.03]],"ltp":1.06,"tv":33070.04,"id":9629022}],"tv":34867.0}]}
{"op":"mcm","clk":"4228547494","pt":1631462385664,"mc":[{"id":"1.187551081","rc":[{"batb":[[0,9,29.73],[1,8,2],[2,6.8,2]],"batl":[[0,26,2],[1,55,4],[2,65,41.03]],"ltp":34.0,"tv":1796.96,"id":7445998},{"batb":[[0,1.04,657.62],[1,1.03,4080.81],[2,1.02,1245.85]],"batl":[[1,1.13,11.86],[2,1.14,190.25]],"ltp":1.06,"tv":33070.04,"id":9629022}]}]}
{"op":"mcm","clk":"4228547564","pt":1631462386287,"mc":[{"id":"1.187551081","rc":[{"batl":[[0,55,4],[1,65,41.03],[2,110,2]],"ltp":34.0,"tv":1796.96,"id":7445998},{"batb":[[0,1.03,4080.81],[1,1.02,1245.85],[2,1.01,2281.66]],"ltp":1.06,"tv":33070.04,"id":9629022}]}]}
{"op":"mcm","clk":"4228548046","pt":1631462389472,"mc":[{"id":"1.187551081","rc":[{"batb":[[0,9,31.73],[1,8.8,3],[2,8,2]],"batl":[[0,36,2],[1,55,4],[2,65,41.03]],"ltp":34.0,"tv":1796.96,"id":7445998},{"batb":[[0,1.03,4082.81]],"ltp":1.06,"tv":33070.04,"id":9629022}]}]}
{"op":"mcm","clk":"4228548218","pt":1631462390498,"mc":[{"id":"1.187551081","rc":[{"trd":[[1.07,1809.91]],"batb":[[0,1.07,1258.25],[1,1.03,4082.81],[2,1.02,1245.85]],"batl":[[0,1.09,1017.18],[1,1.1,218.11],[2,1.13,11.86]],"ltp":1.07,"tv":33074.38,"id":9629022}],"tv":34871.34}]}
{"op":"mcm","clk":"4228548527","pt":1631462392647,"mc":[{"id":"1.187551081","rc":[{"batb":[[0,11.5,21.74],[1,9,31.73],[2,8.8,3]],"batl":[[0,17.5,12.18],[1,26,2],[2,36,2]],"ltp":34.0,"tv":1796.96,"id":7445998},{"batb":[[1,1.04,653.12],[2,1.03,4082.81]],"ltp":1.07,"tv":33074.38,"id":9629022}]}]}
{"op":"mcm","clk":"4228548653","pt":1631462393561,"mc":[{"id":"1.187551081","rc":[{"batb":[[0,9,31.73],[1,8.8,3],[2,8,2]],"batl":[[0,26,2],[1,36,2],[2,55,4]],"ltp":34.0,"tv":1796.96,"id":7445998},{"batb":[[0,1.04,653.12],[1,1.03,4082.81],[2,1.02,1245.85]],"batl":[[0,1.08,53.13],[1,1.13,11.86],[2,1.14,190.25]],"ltp":1.07,"tv":33074.38,"id":9629022}]}]}
{"op":"mcm","clk":"4228548677","pt":1631462393772,"mc":[{"id":"1.187551081","rc":[{"batl":[[0,36,2],[1,55,4],[2,65,41.03]],"ltp":34.0,"tv":1796.96,"id":7445998},{"batb":[[0,1.03,4082.81],[1,1.02,1245.85],[2,1.01,2281.66]],"batl":[[0,1.13,11.86],[1,1.14,190.25],[2,1.15,179.92]],"ltp":1.07,"tv":33074.38,"id":9629022}]}]}
{"op":"mcm","clk":"4228549077","pt":1631462396477,"mc":[{"id":"1.187551081","rc":[{"batb":[[0,1.04,1296.79],[1,1.03,4082.81],[2,1.02,1245.85]],"batl":[[0,1.13,986.22],[1,1.14,407.46]],"ltp":1.07,"tv":33074.38,"id":9629022}]}]}
{"op":"mcm","clk":"4228549165","pt":1631462396965,"mc":[{"id":"1.187551081","rc":[{"batl":[[0,26,2],[1,36,2],[2,55,4]],"ltp":34.0,"tv":1796.96,"id":7445998},{"batb":[[0,1.04,1939.66]],"batl":[[0,1.13,1007.22]],"ltp":1.07,"tv":33074.38,"id":9629022}]}]}
{"op":"mcm","clk":"4228549777","pt":1631462401021,"mc":[{"id":"1.187551081","rc":[{"batb":[[1,8,2],[2,6.8,2]],"batl":[[2,55,2]],"ltp":34.0,"tv":1796.96,"id":7445998},{"batb":[[0,1.04,1945.82],[2,1.02,1131.85]],"ltp":1.07,"tv":33074.38,"id":9629022}]}]}
{"op":"mcm","clk":"4228550374","pt":1631462404263,"mc":[{"id":"1.187551081","rc":[{"batb":[[1,8.8,2],[2,8,2]],"ltp":34.0,"tv":1796.96,"id":7445998}]}]}
{"op":"mcm","clk":"4228551404","pt":1631462410132,"mc":[{"id":"1.187551081","rc":[{"batl":[[1,1.14,397.46]],"ltp":1.07,"tv":33074.38,"id":9629022}]}]}
{"op":"mcm","clk":"4228551678","pt":1631462411600,"mc":[{"id":"1.187551081","rc":[{"batb":[[0,1.11,8169.78],[1,1.04,1945.82],[2,1.03,4082.81]],"batl":[[0,1.13,995.36],[2,1.15,165.1]],"ltp":1.07,"tv":33074.38,"id":9629022}]}]}
{"op":"mcm","clk":"4228551868","pt":1631462412613,"mc":[{"id":"1.187551081","rc":[{"batb":[[1,1.04,649.03]],"batl":[[0,1.12,5],[1,1.13,995.36],[2,1.14,397.46]],"ltp":1.07,"tv":33074.38,"id":9629022}]}]}
{"op":"mcm","clk":"4228551990","pt":1631462413326,"mc":[{"id":"1.187551081","rc":[{"batb":[[2,6.4,2.01]],"ltp":34.0,"tv":1796.96,"id":7445998},{"batl":[[0,1.13,995.36],[1,1.14,217.21],[2,1.15,165.1]],"ltp":1.07,"tv":33074.38,"id":9629022}]}]}
{"op":"mcm","clk":"4228552418","pt":1631462415614,"mc":[{"id":"1.187551081","rc":[{"batl":[[0,10.5,3.39],[1,26,2],[2,36,2]],"ltp":34.0,"tv":1796.96,"id":7445998},{"trd":[[1.11,1790.99]],"batb":[[0,1.11,8299.18],[1,1.1,740.58],[2,1.04,649.03]],"ltp":1.11,"tv":33970.94,"id":9629022}],"tv":35767.91}]}
{"op":"mcm","clk":"4228552616","pt":1631462416631,"mc":[{"id":"1.187551081","rc":[{"batb":[[1,7.4,45.47]],"ltp":34.0,"tv":1796.96,"id":7445998},{"trd":[[1.12,1065.38]],"batb":[[0,1.11,642.52],[2,1.09,1139.59]],"batl":[[0,1.12,2.25],[1,1.13,995.36],[2,1.14,217.21]],"ltp":1.12,"tv":34030.93,"id":9629022}],"tv":35827.9}]}
{"op":"mcm","clk":"4228552751","pt":1631462417535,"mc":[{"id":"1.187551081","rc":[{"batb":[[0,9.2,12.85],[1,9,31.73],[2,7.4,45.47]],"batl":[[1,12.5,10],[2,24,50.55]],"ltp":34.0,"tv":1796.96,"id":7445998},{"batl":[[0,1.12,13.5]],"ltp":1.12,"tv":34030.93,"id":9629022}]}]}
{"op":"mcm","clk":"4228552929","pt":1631462418611,"mc":[{"id":"1.187551081","rc":[{"batb":[[0,9.2,2]],"ltp":34.0,"tv":1796.96,"id":7445998}]}]}
{"op":"mcm","clk":"4228553101","pt":1631462419640,"mc":[{"id":"1.187551081","rc":[{"batb":[[0,9.4,3],[1,9.2,2],[2,9,31.73]],"ltp":34.0,"tv":1796.96,"id":7445998},{"trd":[[1.11,1799.41]],"batb":[[0,1.11,638.31]],"ltp":1.11,"tv":34039.35,"id":9629022}],"tv":35836.32}]}
{"op":"mcm","clk":"4228553271","pt":1631462420609,"mc":[{"id":"1.187551081","rc":[{"batb":[[1,9.2,47.54]],"batl":[[2,14.5,33.69]],"ltp":34.0,"tv":1796.96,"id":7445998},{"trd":[[1.11,2748.65]],"batb":[[0,1.11,681.92]],"batl":[[0,1.12,387.57],[1,1.13,1859.17],[2,1.15,165.1]],"ltp":1.11,"tv":34988.59,"id":9629022}],"tv":36785.56}]}
{"op":"mcm","clk":"4228553393","pt":1631462421422,"mc":[{"id":"1.187551081","rc":[{"batb":[[0,9.4,15.85]],"batl":[[2,24,50.55]],"ltp":34.0,"tv":1796.96,"id":7445998}]}]}
{"op":"mcm","clk":"4228553588","pt":1631462422654,"mc":[{"id":"1.187551081","rc":[{"batb":[[0,9.4,3]],"batl":[[2,13.5,2]],"ltp":34.0,"tv":1796.96,"id":7445998}]}]}
{"op":"mcm","clk":"4228553756","pt":1631462423432,"mc":[{"id":"1.187551081","rc":[{"trd":[[1.11,3217.11]],"batb":[[0,1.11,107.38],[1,1.1,874.41]],"batl":[[0,1.12,636.9],[1,1.13,1817.06]],"ltp":1.11,"tv":35457.05,"id":9629022}],"tv":37254.02}]}
{"op":"mcm","clk":"4228553841","pt":1631462423957,"mc":[{"id":"1.187551081","rc":[{"trd":[[1.11,3232.37]],"batb":[[0,1.11,177.59],[1,1.1,1446.18]],"batl":[[0,1.12,1141.83],[1,1.13,1772.15]],"ltp":1.11,"tv":35472.32,"id":9629022}],"tv":37269.29}]}
{"op":"mcm","clk":"4228554014","pt":1631462424930,"mc":[{"id":"1.187551081","rc":[{"batb":[[0,9.6,12.85],[1,9.4,3],[2,9.2,47.54]],"ltp":34.0,"tv":1796.96,"id":7445998}]}]}
{"op":"mcm","clk":"4228554184","pt":1631462426191,"mc":[{"id":"1.187551081","rc":[{"batb":[[0,1.11,207.61],[1,1.1,1565.92]],"batl":[[0,1.12,1178.6]],"ltp":1.11,"tv":35472.32,"id":9629022}]}]}
{"op":"mcm","clk":"4228554355","pt":1631462427408,"mc":[{"id":"1.187551081","rc":[{"batl":[[0,1.12,1198.6],[1,1.13,1751.15]],"ltp":1.11,"tv":35472.32,"id":9629022}]}]}
{"op":"mcm","clk":"4228555193","pt":1631462432354,"mc":[{"id":"1.187551081","rc":[{"batb":[[2,9.2,45.54]],"ltp":34.0,"tv":1796.96,"id":7445998},{"trd":[[1.12,1105.38]],"batl":[[0,1.12,1178.6]],"ltp":1.12,"tv":35512.32,"id":9629022}],"tv":37309.28}]}
{"op":"mcm","clk":"4228555823","pt":1631462436542,"mc":[{"id":"1.187551081","rc":[{"batl":[[0,1.12,1267.82]],"ltp":1.12,"tv":35512.32,"id":9629022}]}]}
{"op":"mcm","clk":"4228556626","pt":1631462441155,"mc":[{"id":"1.187551081","rc":[{"trd":[[1.12,1106.03]],"batl":[[0,1.12,1267.5]],"ltp":1.12,"tv":35512.97,"id":9629022}],"tv":37309.93}]}
{"op":"mcm","clk":"4228557244","pt":1631462444662,"mc":[{"id":"1.187551081","rc":[{"batb":[[0,9.4,3],[1,7.6,2],[2,7.4,45.47]],"batl":[[0,13.5,2],[1,15.5,2],[2,17,57.15]],"ltp":34.0,"tv":1796.96,"id":7445998},{"batb":[[0,1.1,474.75],[1,1.08,323.31],[2,1.07,1947.25]],"batl":[[0,1.12,429.59],[1,1.13,471.12]],"ltp":1.12,"tv":35512.97,"id":9629022}]}]}
{"op":"mcm","clk":"4228557312","pt":1631462445090,"mc":[{"id":"1.187551081","rc":[{"batb":[[0,7.6,2],[1,7.4,45.47],[2,6.8,2]],"batl":[[0,15.5,2],[1,17,57.15],[2,18,2]],"ltp":34.0,"tv":1796.96,"id":7445998},{"batb":[[0,1.07,1939.55],[1,1.06,487.58],[2,1.05,478.69]],"batl":[[0,1.12,20],[1,1.15,165.1],[2,1.16,147.47]],"ltp":1.12,"tv":35512.97,"id":9629022}]}]}
{"op":"mcm","clk":"4228557488","pt":1631462446104,"mc":[{"id":"1.187551081","rc":[{"batl":[[0,9.6,5],[1,15.5,2],[2,17,57.15]],"ltp":34.0,"tv":1796.96,"id":7445998}]}]}
{"op":"mcm","clk":"4228557731","pt":1631462447569,"mc":[{"id":"1.187551081","rc":[{"trd":[[9.6,59.11]],"batl":[[0,9.6,3]],"ltp":9.6,"tv":1800.96,"id":7445998},{"batb":[[0,1.08,676.4],[1,1.07,2517.25],[2,1.06,487.58]],"batl":[[1,1.15,541.31],[2,1.16,828.29]],"ltp":1.12,"tv":35512.97,"id":9629022}],"tv":37313.93}]}
{"op":"mcm","clk":"4228557859","pt":1631462448370,"mc":[{"id":"1.187551081","rc":[{"batl":[[1,13.5,2],[2,15.5,4]],"ltp":9.6,"tv":1800.96,"id":7445998},{"batb":[[0,1.08,986.21],[1,1.07,2538.25],[2,1.06,503.58]],"ltp":1.12,"tv":35512.97,"id":9629022}]}]}
{"op":"mcm","clk":"4228558409","pt":1631462451661,"mc":[{"id":"1.187551081","rc":[{"batb":[[0,1.08,309.81],[1,1.07,1960.55]],"batl":[[0,1.15,541.31],[1,1.16,828.29],[2,1.17,158.5]],"ltp":1.12,"tv":35512.97,"id":9629022}]}]}
{"op":"mcm","clk":"4228558448","pt":1631462451872,"mc":[{"id":"1.187551081","rc":[{"trd":[[9.6,60.15]],"batl":[[0,9.6,1.96]],"ltp":9.6,"tv":1802.0,"id":7445998},{"trd":[[1.11,3241.39]],"ltp":1.11,"tv":35521.99,"id":9629022}],"tv":37323.99}]}
{"op":"mcm","clk":"4228558848","pt":1631462454375,"mc":[{"id":"1.187551081","rc":[{"batl":[[0,8.8,2.02],[1,9.6,1.96],[2,13.5,2]],"ltp":9.6,"tv":1802.0,"id":7445998},{"batb":[[0,1.13,930.85],[1,1.12,310.12],[2,1.08,309.81]],"batl":[[0,1.14,14],[1,1.15,541.31],[2,1.16,835.17]],"ltp":1.11,"tv":35521.99,"id":9629022}]}]}
{"op":"mcm","clk":"4228559092","pt":1631462455668,"mc":[{"id":"1.187551081","rc":[{"batb":[[0,7.8,9.44],[1,7.6,4],[2,7.4,47.47]],"ltp":9.6,"tv":1802.0,"id":7445998},{"batb":[[1,1.12,1172.12],[2,1.09,1143.86]],"batl":[[0,1.14,34],[1,1.15,642.42]],"ltp":1.11,"tv":35521.99,"id":9629022}]}]}
{"op":"mcm","clk":"4228559180","pt":1631462456255,"mc":[{"id":"1.187551081","rc":[{"batb":[[0,7.8,11.44]],"batl":[[2,13,2]],"ltp":9.6,"tv":1802.0,"id":7445998},{"batb":[[1,1.12,1190.12],[2,1.11,23]],"ltp":1.11,"tv":35521.99,"id":9629022}]}]}
{"op":"mcm","clk":"4228559343","pt":1631462457404,"mc":[{"id":"1.187551081","rc":[{"batb":[[1,7.6,2]],"ltp":9.6,"tv":1802.0,"id":7445998},{"batl":[[0,1.14,14],[1,1.15,477.32]],"ltp":1.11,"tv":35521.99,"id":9629022}]}]}
{"op":"mcm","clk":"4228559538","pt":1631462458470,"mc":[{"id":"1.187551081","rc":[{"batb":[[0,1.13,1275.57]],"batl":[[1,1.15,784.06]],"ltp":1.11,"tv":35521.99,"id":9629022}]}]}
{"op":"mcm","clk":"4228559741","pt":1631462459608,"mc":[{"id":"1.187551081","rc":[{"trd":[[8,26.83]],"batl":[[0,8,2.01],[1,8.8,2.02],[2,9.6,1.96]],"ltp":8.0,"tv":1803.99,"id":7445998},{"trd":[[1.13,290.08],[1.14,204.56]],"batb":[[0,1.13,1279.77]],"batl":[[0,1.15,784.06],[1,1.16,835.17],[2,1.17,158.5]],"ltp":1.14,"tv":35625.2,"id":9629022}],"tv":37429.2}]}
{"op":"mcm","clk":"4228559919","pt":1631462460625,"mc":[{"id":"1.187551081","rc":[{"trd":[[8,28.25]],"batl":[[0,8.8,2.61],[1,9.6,1.96],[2,10.5,2]],"ltp":8.0,"tv":1805.41,"id":7445998},{"trd":[[1.14,214.56]],"batb":[[2,1.11,254.59]],"ltp":1.14,"tv":35635.2,"id":9629022}],"tv":37440.62}]}
{"op":"mcm","clk":"4228560064","pt":1631462461508,"mc":[{"id":"1.187551081","rc":[{"trd":[[8,28.84]],"batb":[[0,8,57.2],[1,7.8,11.44],[2,7.6,68.03]],"batl":[[0,8.8,2.02]],"ltp":8.0,"tv":1806.0,"id":7445998},{"trd":[[1.14,218.7]],"batl":[[0,1.14,407.26],[1,1.15,1220.48],[2,1.16,835.17]],"ltp":1.14,"tv":35639.34,"id":9629022}],"tv":37445.35}]}
{"op":"mcm","clk":"4228560240","pt":1631462462472,"mc":[{"id":"1.187551081","rc":[{"batl":[[1,10.5,2],[2,12.5,2]],"ltp":8.0,"tv":1806.0,"id":7445998}]}]}
{"op":"mcm","clk":"4228560265","pt":1631462462693,"mc":[{"id":"1.187551081","rc":[{"batl":[[0,8.8,48.51],[1,9.4,58.31],[2,10.5,2]],"ltp":8.0,"tv":1806.0,"id":7445998},{"batb":[[0,1.13,1641.88],[1,1.12,1679.49]],"ltp":1.14,"tv":35639.34,"id":9629022}]}]}
{"op":"mcm","clk":"4228560768","pt":1631462465605,"mc":[{"id":"1.187551081","rc":[{"batl":[[0,8.8,58.31]],"ltp":8.0,"tv":1806.0,"id":7445998}]}]}
{"op":"mcm","clk":"4228561051","pt":1631462467305,"mc":[{"id":"1.187551081","rc":[{"batb":[[2,7.6,66.03]],"ltp":8.0,"tv":1806.0,"id":7445998},{"trd":[[1.13,292.78]],"batb":[[0,1.13,1640.53]],"ltp":1.13,"tv":35642.04,"id":9629022}],"tv":37448.05}]}
{"op":"mcm","clk":"4228561803","pt":1631462471630,"mc":[{"id":"1.187551081","rc":[{"trd":[[1.13,1177.84]],"batb":[[0,1.13,1198],[2,1.11,231.59]],"batl":[[2,1.16,697.46]],"ltp":1.13,"tv":36527.1,"id":9629022}],"tv":38333.11}]}
{"op":"mcm","clk":"4228562305","pt":1631462474613,"mc":[{"id":"1.187551081","rc":[{"batb":[[0,1.13,1396.05],[1,1.12,1927.4]],"batl":[[0,1.14,727.02],[1,1.15,1462.24]],"ltp":1.13,"tv":36527.1,"id":9629022}]}]}
{"op":"mcm","clk":"4228562799","pt":1631462477622,"mc":[{"id":"1.187551081","rc":[{"batb":[[0,7.8,2],[1,6.8,2],[2,6.2,70.27]],"batl":[[0,12.5,2],[1,13,2],[2,14,62.24]],"ltp":8.0,"tv":1806.0,"id":7445998},{"batb":[[0,1.12,18],[1,1.09,1412.47],[2,1.01,50]],"batl":[[0,1.14,5.86],[1,1.15,18],[2,1.17,178.5]],"ltp":1.13,"tv":36527.1,"id":9629022}]}]}
{"op":"mcm","clk":"4228563335","pt":1631462480641,"mc":[{"id":"1.187551081","rc":[{"batb":[[0,6.8,2],[1,6.2,70.27],[2,4.1,377.46]],"batl":[[0,9.2,2],[1,12.5,2],[2,13,2]],"ltp":8.0,"tv":1806.0,"id":7445998},{"batb":[[0,1.1,1034.44]],"batl":[[0,1.17,178.5],[1,1.18,153.25],[2,1.19,693.29]],"ltp":1.13,"tv":36527.1,"id":9629022}]}]}
{"op":"mcm","clk":"4228563427","pt":1631462481240,"mc":[{"id":"1.187551081","rc":[{"batb":[[0,6.2,70.27],[1,4.1,377.46],[2,1.01,30]],"batl":[[0,12.5,2],[1,13,2],[2,14,62.24]],"ltp":8.0,"tv":1806.0,"id":7445998},{"batb":[[0,1.1,1278.68]],"batl":[[0,1.17,20],[1,1.19,693.29],[2,1.39,17.79]],"ltp":1.13,"tv":36527.1,"id":9629022}]}]}
{"op":"mcm","clk":"4228563782","pt":1631462483324,"mc":[{"id":"1.187551081","rc":[{"batb":[[0,1.14,50],[1,1.1,1278.68],[2,1.09,1605.83]],"batl":[[1,1.18,498.76],[2,1.19,693.29]],"ltp":1.13,"tv":36527.1,"id":9629022}]}]}
{"op":"mcm","clk":"4228563970","pt":1631462484526,"mc":[{"id":"1.187551081","rc":[{"batb":[[0,6.4,2],[1,6.2,72.27],[2,4.1,377.46]],"batl":[[0,10.5,2],[1,12.5,2],[2,13,2]],"ltp":8.0,"tv":1806.0,"id":7445998},{"batb":[[0,1.11,196.59]],"batl":[[1,1.18,639.01]],"ltp":1.13,"tv":36527.1,"id":9629022}]}]}
{"op":"mcm","clk":"4228564160","pt":1631462485648,"mc":[{"id":"1.187551081","rc":[{"batl":[[0,12.5,2],[1,13,2],[2,14,62.24]],"ltp":8.0,"tv":1806.0,"id":7445998},{"batb":[[0,1.1,1278.68],[1,1.09,1605.83],[2,1.01,50]],"batl":[[1,1.18,140.25],[2,1.19,129.5]],"ltp":1.13,"tv":36527.1,"id":9629022}]}]}
{"op":"mcm","clk":"4228564182","pt":1631462485744,"mc":[{"id":"1.187551081","rc":[{"batl":[[1,1.39,17.79],[2,3.8,27.47]],"ltp":1.13,"tv":36527.1,"id":9629022}]}]}
{"op":"mcm","clk":"4228564463","pt":1631462487523,"mc":[{"id":"1.187551081","rc":[{"batb":[[0,6.8,2],[1,6.4,2],[2,6.2,72.27]],"ltp":8.0,"tv":1806.0,"id":7445998},{"batb":[[0,1.16,7761.74],[1,1.1,1278.68],[2,1.09,1605.83]],"batl":[[0,1.17,167.5]],"ltp":1.13,"tv":36527.1,"id":9629022}]}]}
{"op":"mcm","clk":"4228564675","pt":1631462488659,"mc":[{"id":"1.187551081","rc":[{"batb":[[0,6.4,2],[1,6.2,72.27],[2,4.1,377.46]],"batl":[[2,990,0.01]],"ltp":8.0,"tv":1806.0,"id":7445998},{"batb":[[0,1.1,1278.68],[1,1.09,1605.83],[2,1.04,15.34]],"batl":[[0,1.12,766.06],[1,1.13,459.13],[2,1.14,7]],"ltp":1.13,"tv":36527.1,"id":9629022}]}]}
{"op":"mcm","clk":"4228564839","pt":1631462489535,"mc":[{"id":"1.187551081","rc":[{"batb":[[0,9,29.56],[1,7.2,48.32],[2,6.4,2]],"ltp":8.0,"tv":1806.0,"id":7445998},{"batb":[[1,1.09,1622.83],[2,1.06,1670.41]],"ltp":1.13,"tv":36527.1,"id":9629022}]}]}
{"op":"mcm","clk":"4228565116","pt":1631462491016,"mc":[{"id":"1.187551081","rc":[{"batb":[[1,7.4,2],[2,7.2,50.32]],"batl":[[0,12,10],[1,12.5,2],[2,13,2]],"ltp":8.0,"tv":1806.0,"id":7445998},{"batb":[[0,1.1,1343.44]],"ltp":1.13,"tv":36527.1,"id":9629022}]}]}
{"op":"mcm","clk":"4228565398","pt":1631462492559,"mc":[{"id":"1.187551081","rc":[{"trd":[[9.2,91.52],[9.4,4]],"batl":[[0,12,2]],"ltp":9.2,"tv":1901.52,"id":7445998},{"trd":[[1.12,1824.96]],"batb":[[0,1.1,1309.93],[1,1.09,1429.47]],"batl":[[0,1.12,47.13]],"ltp":1.12,"tv":37246.03,"id":9629022}],"tv":39147.56}]}
{"op":"mcm","clk":"4228565586","pt":1631462493639,"mc":[{"id":"1.187551081","rc":[{"trd":[[1.1,1119.36]],"batb":[[0,1.1,1182.2]],"ltp":1.1,"tv":37501.49,"id":9629022}],"tv":39403.02}]}
{"op":"mcm","clk":"4228565676","pt":1631462494158,"mc":[{"id":"1.187551081","rc":[{"batb":[[0,9.2,14.04],[1,9,29.56],[2,7.4,2]],"ltp":9.2,"tv":1901.52,"id":7445998},{"batb":[[0,1.1,1542.9]],"batl":[[0,1.12,471.06]],"ltp":1.1,"tv":37501.49,"id":9629022}]}]}
{"op":"mcm","clk":"4228565914","pt":1631462495637,"mc":[{"id":"1.187551081","rc":[{"batb":[[0,9.6,2],[1,9,31.56],[2,7.6,2]],"batl":[[0,11.5,10],[1,12,2],[2,12.5,2]],"ltp":9.2,"tv":1901.52,"id":7445998},{"batb":[[0,1.11,357.01],[1,1.1,1542.9],[2,1.09,1429.47]],"batl":[[0,1.12,787.84],[1,1.13,778.12]],"ltp":1.1,"tv":37501.49,"id":9629022}]}]}
{"op":"mcm","clk":"4228565954","pt":1631462495855,"mc":[{"id":"1.187551081","rc":[{"trd":[[1.11,3261.39]],"batb":[[0,1.11,347.01]],"ltp":1.11,"tv":37521.49,"id":9629022}],"tv":39423.02}]}
{"op":"mcm","clk":"4228566091","pt":1631462496670,"mc":[{"id":"1.187551081","rc":[{"batb":[[1,1.1,1895.75]],"batl":[[0,1.12,857.27]],"ltp":1.11,"tv":37521.49,"id":9629022}]}]}
{"op":"mcm","clk":"4228566981","pt":1631462501638,"mc":[{"id":"1.187551081","rc":[{"trd":[[9.6,64.15]],"batb":[[0,9.2,14.04]],"batl":[[0,9.6,1],[1,11.5,10],[2,12,2]],"ltp":9.6,"tv":1905.52,"id":7445998}],"tv":39427.02}]}
{"op":"mcm","clk":"4228567167","pt":1631462502541,"mc":[{"id":"1.187551081","rc":[{"batb":[[0,7.6,2],[1,7.2,50.32],[2,6.8,2]],"batl":[[1,15.5,2],[2,17,57.15]],"ltp":9.6,"tv":1905.52,"id":7445998},{"batb":[[0,1.07,349.07],[1,1.06,2095.69],[2,1.05,529.89]],"batl":[[0,1.15,186.3],[1,1.16,171.72],[2,1.17,170.5]],"ltp":1.11,"tv":37521.49,"id":9629022}]}]}
{"op":"mcm","clk":"4228567214","pt":1631462502861,"mc":[{"id":"1.187551081","rc":[{"batb":[[0,7.2,50.32],[1,6.8,2],[2,4.1,377.46]],"batl":[[1,17,57.15],[2,21,2]],"ltp":9.6,"tv":1905.52,"id":7445998},{"batb":[[0,1.06,2095.69],[1,1.05,529.89],[2,1.04,629.87]],"batl":[[0,1.16,13],[1,1.17,170.5],[2,1.39,17.79]],"ltp":1.11,"tv":37521.49,"id":9629022}]}]}
{"op":"mcm","clk":"4228567513","pt":1631462504544,"mc":[{"id":"1.187551081","rc":[{"batb":[[0,1.12,30],[1,1.06,2095.69],[2,1.05,529.89]],"ltp":1.11,"tv":37521.49,"id":9629022}]}]}
{"op":"mcm","clk":"4228567670","pt":1631462505453,"mc":[{"id":"1.187551081","rc":[{"batb":[[1,1.07,1260.42],[2,1.06,2095.69]],"batl":[[0,1.16,742.62],[1,1.17,599.81]],"ltp":1.11,"tv":37521.49,"id":9629022}]}]}
{"op":"mcm","clk":"4228567878","pt":1631462506643,"mc":[{"id":"1.187551081","rc":[{"batb":[[1,7,2],[2,6.8,2]],"batl":[[0,8.4,1078.38],[1,9.6,1],[2,9.8,4.42]],"ltp":9.6,"tv":1905.52,"id":7445998},{"batb":[[1,1.07,1570.49]],"batl":[[0,1.16,909.59]],"ltp":1.11,"tv":37521.49,"id":9629022}]}]}
{"op":"mcm","clk":"4228567929","pt":1631462506956,"mc":[{"id":"1.187551081","rc":[{"batl":[[0,9.6,1],[1,15.5,2],[2,17,57.15]],"ltp":9.6,"tv":1905.52,"id":7445998}]}]}
{"op":"mcm","clk":"4228568165","pt":1631462508402,"mc":[{"id":"1.187551081","rc":[{"trd":[[1.12,1832.96]],"batb":[[0,1.12,26],[1,1.07,310.07]],"ltp":1.12,"tv":37529.49,"id":9629022}],"tv":39435.02}]}
{"op":"mcm","clk":"4228568389","pt":1631462509655,"mc":[{"id":"1.187551081","rc":[{"batb":[[0,7.6,2],[1,7.2,50.32],[2,7,2]],"ltp":9.6,"tv":1905.52,"id":7445998},{"batl":[[0,1.15,165.9],[1,1.16,909.59],[2,1.17,599.81]],"ltp":1.12,"tv":37529.49,"id":9629022}]}]}
{"op":"mcm","clk":"4228568517","pt":1631462510374,"mc":[{"id":"1.187551081","rc":[{"batb":[[0,7.2,50.32],[1,7,2],[2,6.8,2]],"batl":[[2,21,2]],"ltp":9.6,"tv":1905.52,"id":7445998},{"batl":[[0,1.16,909.59],[1,1.17,599.81],[2,1.39,17.79]],"ltp":1.12,"tv":37529.49,"id":9629022}]}]}
{"op":"mcm","clk":"4228568732","pt":1631462511577,"mc":[{"id":"1.187551081","rc":[{"trd":[[8.2,32.49]],"ltp":8.2,"tv":1938.01,"id":7445998},{"trd":[[1.14,862.23]],"batb":[[0,1.14,349.77],[1,1.13,840.63],[2,1.12,26]],"batl":[[0,1.15,13.87],[1,1.16,909.59],[2,1.17,586.63]],"ltp":1.14,"tv":38173.02,"id":9629022}],"tv":40111.04}]}
{"op":"mcm","clk":"4228568916","pt":1631462512665,"mc":[{"id":"1.187551081","rc":[{"batl":[[0,9.4,5],[1,9.6,1],[2,15.5,2]],"ltp":8.2,"tv":1938.01,"id":7445998},{"batb":[[1,1.13,1753.49]],"ltp":1.14,"tv":38173.02,"id":9629022}]}]}
{"op":"mcm","clk":"4228569083","pt":1631462513664,"mc":[{"id":"1.187551081","rc":[{"trd":[[8.2,36.49]],"batb":[[0,7.4,3],[1,7.2,50.32],[2,7,2]],"batl":[[0,9.2,2],[1,9.4,5],[2,9.6,1]],"ltp":8.2,"tv":1942.01,"id":7445998},{"trd":[[1.14,929.01]],"batb":[[0,1.14,301.99],[1,1.13,1681.11],[2,1.12,44]],"batl":[[2,1.17,560.86]],"ltp":1.14,"tv":38239.8,"id":9629022}],"tv":40181.82}]}
{"op":"mcm","clk":"4228569147","pt":1631462514094,"mc":[{"id":"1.187551081","rc":[{"batl":[[1,9.6,1],[2,12.5,65.54]],"ltp":8.2,"tv":1942.01,"id":7445998}]}]}
{"op":"mcm","clk":"4228569271","pt":1631462514897,"mc":[{"id":"1.187551081","rc":[{"batb":[[1,1.13,1663.11]],"batl":[[1,1.16,742.62]],"ltp":1.14,"tv":38239.8,"id":9629022}]}]}
{"op":"mcm","clk":"4228569584","pt":1631462516653,"mc":[{"id":"1.187551081","rc":[{"batb":[[0,7.2,2],[1,7,2],[2,6,75.87]],"batl":[[0,9.6,1],[1,12.5,65.54],[2,15.5,2]],"ltp":8.2,"tv":1942.01,"id":7445998},{"batb":[[0,1.13,26.64],[1,1.09,1134.9],[2,1.07,310.07]],"batl":[[0,1.16,38.99],[1,1.39,17.79],[2,3.8,27.47]],"ltp":1.14,"tv":38239.8,"id":9629022}]}]}
{"op":"mcm","clk":"4228569735","pt":1631462517563,"mc":[{"id":"1.187551081","rc":[{"batb":[[1,6.4,2],[2,6,77.87]],"batl":[[1,10.5,2],[2,12.5,67.54]],"ltp":8.2,"tv":1942.01,"id":7445998},{"batb":[[0,1.11,216.59],[1,1.1,243.04],[2,1.09,1418.51]],"batl":[[0,1.16,13],[1,1.18,144.75],[2,1.19,145.5]],"ltp":1.14,"tv":38239.8,"id":9629022}]}]}
{"op":"mcm","clk":"4228569788","pt":1631462517889,"mc":[{"id":"1.187551081","rc":[{"batb":[[1,6,77.87],[2,4.1,377.46]],"batl":[[1,12.5,67.54],[2,15.5,2]],"ltp":8.2,"tv":1942.01,"id":7445998},{"batb":[[0,1.09,1418.51],[1,1.07,310.07],[2,1.06,452.58]],"batl":[[1,1.2,126.28],[2,1.39,17.79]],"ltp":1.14,"tv":38239.8,"id":9629022}]}]}
{"op":"mcm","clk":"4228570080","pt":1631462519479,"mc":[{"id":"1.187551081","rc":[{"trd":[[1.15,231.96]],"batb":[[0,1.1,1170.24],[1,1.09,1418.51],[2,1.07,310.07]],"batl":[[1,1.19,309.7],[2,1.2,653.85]],"ltp":1.15,"tv":38291.8,"id":9629022}],"tv":40233.82}]}
{"op":"mcm","clk":"4228570251","pt":1631462520469,"mc":[{"id":"1.187551081","rc":[{"batb":[[1,7,3],[2,6,77.87]],"ltp":8.2,"tv":1942.01,"id":7445998},{"batb":[[0,1.09,1418.51],[1,1.07,310.07],[2,1.06,452.58]],"ltp":1.15,"tv":38291.8,"id":9629022}]}]}
{"op":"mcm","clk":"4228570405","pt":1631462521474,"mc":[{"id":"1.187551081","rc":[{"batb":[[0,1.1,232.54],[1,1.09,1418.51],[2,1.07,310.07]],"batl":[[1,1.19,422.2]],"ltp":1.15,"tv":38291.8,"id":9629022}]}]}
{"op":"mcm","clk":"4228570548","pt":1631462522377,"mc":[{"id":"1.187551081","rc":[{"batl":[[1,12.5,2]],"ltp":8.2,"tv":1942.01,"id":7445998},{"batb":[[0,1.1,262.54]],"ltp":1.15,"tv":38291.8,"id":9629022}]}]}
{"op":"mcm","clk":"4228570752","pt":1631462523559,"mc":[{"id":"1.187551081","rc":[{"trd":[[7,34.36],[7.2,22.26]],"batb":[[0,6,77.87],[1,1.01,30],[2,6,0]],"ltp":7.0,"tv":1947.01,"id":7445998},{"trd":[[1.16,1052.17],[1.17,1113.14]],"batb":[[0,1.17,592.35],[1,1.16,624.19],[2,1.1,262.54]],"batl":[[0,1.18,13.52],[2,1.2,660.5]],"ltp":1.17,"tv":38348.06,"id":9629022}],"tv":40295.08}]}
{"op":"mcm","clk":"4228570873","pt":1631462524314,"mc":[{"id":"1.187551081","rc":[{"batb":[[1,5.3,49.91],[2,1.01,30]],"ltp":7.0,"tv":1947.01,"id":7445998},{"batb":[[0,1.17,1222.81],[2,1.14,773.57]],"ltp":1.17,"tv":38348.06,"id":9629022}]}]}
{"op":"mcm","clk":"4228570966","pt":1631462524894,"mc":[{"id":"1.187551081","rc":[{"batl":[[0,7.8,5],[1,9.6,1],[2,12.5,2]],"ltp":7.0,"tv":1947.01,"id":7445998}]}]}
{"op":"mcm","clk":"4228571230","pt":1631462526607,"mc":[{"id":"1.187551081","rc":[{"batb":[[0,6.4,3],[1,6.2,3],[2,6,79.87]],"batl":[[2,9.8,74.59]],"ltp":7.0,"tv":1947.01,"id":7445998},{"batb":[[1,1.16,654.19],[2,1.15,30]],"batl":[[0,1.18,25.52],[1,1.19,321.7]],"ltp":1.17,"tv":38348.06,"id":9629022}]}]}
{"op":"mcm","clk":"4228571401","pt":1631462527666,"mc":[{"id":"1.187551081","rc":[{"batb":[[0,1.17,1498.7]],"batl":[[0,1.18,13.52],[1,1.19,524.44]],"ltp":1.17,"tv":38348.06,"id":9629022}]}]}
{"op":"mcm","clk":"4228571662","pt":1631462529326,"mc":[{"id":"1.187551081","rc":[{"batb":[[1,1.16,624.19]],"ltp":1.17,"tv":38348.06,"id":9629022}]}]}
{"op":"mcm","clk":"4228571770","pt":1631462529923,"mc":[{"id":"1.187551081","rc":[{"batl":[[0,7.8,2],[1,8.8,2],[2,9.6,1]],"ltp":7.0,"tv":1947.01,"id":7445998},{"batb":[[2,1.15,187.83]],"ltp":1.17,"tv":38348.06,"id":9629022}]}]}
{"op":"mcm","clk":"4228572418","pt":1631462533582,"mc":[{"id":"1.187551081","rc":[{"batb":[[0,5.5,2.12],[1,5.3,49.91],[2,3,383.31]],"ltp":7.0,"tv":1947.01,"id":7445998},{"batb":[[0,1.15,187.83],[1,1.14,988.39],[2,1.13,171.73]],"batl":[[0,1.22,122.25],[1,1.39,17.79],[2,3.8,27.47]],"ltp":1.17,"tv":38348.06,"id":9629022}]}]}
{"op":"mcm","clk":"4228572452","pt":1631462533798,"mc":[{"id":"1.187551081","rc":[{"batl":[[0,8.8,2],[1,9.6,1],[2,9.8,74.59]],"ltp":7.0,"tv":1947.01,"id":7445998},{"batb":[[0,1.14,988.39],[1,1.13,171.73],[2,1.1,30]],"ltp":1.17,"tv":38348.06,"id":9629022}]}]}
{"op":"mcm","clk":"4228572849","pt":1631462536320,"mc":[{"id":"1.187551081","rc":[{"batb":[[0,1.14,1921.05],[1,1.13,424.31]],"batl":[[0,1.22,478.31],[1,1.23,447.16],[2,1.39,17.79]],"ltp":1.17,"tv":38348.06,"id":9629022}]}]}
{"op":"mcm","clk":"4228573057","pt":1631462537602,"mc":[{"id":"1.187551081","rc":[{"batb":[[0,5.7,3],[1,5.6,2],[2,5.5,5.12]],"ltp":7.0,"tv":1947.01,"id":7445998},{"batb":[[0,1.15,5],[1,1.14,1921.05],[2,1.13,424.31]],"batl":[[0,1.22,490.31]],"ltp":1.17,"tv":38348.06,"id":9629022}]}]}
{"op":"mcm","clk":"4228573186","pt":1631462538402,"mc":[{"id":"1.187551081","rc":[{"trd":[[1.14,931.01],[1.15,241.96],[1.16,1062.17]],"batb":[[0,1.14,987.39],[1,1.13,171.73],[2,1.1,30]],"batl":[[0,1.22,134.25],[1,1.39,17.79],[2,3.8,27.47]],"ltp":1.14,"tv":38370.06,"id":9629022}],"tv":40317.08}]}
{"op":"mcm","clk":"4228573366","pt":1631462539391,"mc":[{"id":"1.187551081","rc":[{"batl":[[2,990,0.01]],"ltp":7.0,"tv":1947.01,"id":7445998}]}]}
{"op":"mcm","clk":"4228573569","pt":1631462540609,"mc":[{"id":"1.187551081","rc":[{"batb":[[0,6,2],[1,5.7,3],[2,5.6,2]],"batl":[[0,7.8,2],[1,8.8,2],[2,9.6,1]],"ltp":7.0,"tv":1947.01,"id":7445998},{"batb":[[0,1.15,198.03],[1,1.14,987.39],[2,1.13,171.73]],"batl":[[0,1.2,116.68],[1,1.21,101.5],[2,1.22,134.25]],"ltp":1.14,"tv":38370.06,"id":9629022}]}]}
{"op":"mcm","clk":"4228573715","pt":1631462541485,"mc":[{"id":"1.187551081","rc":[{"batb":[[0,5.7,3],[1,5.6,2],[2,5.5,5.12]],"batl":[[0,8.8,2],[1,9.6,1],[2,990,0.01]],"ltp":7.0,"tv":1947.01,"id":7445998},{"batb":[[0,1.17,178.19],[1,1.16,709.19],[2,1.14,987.39]],"batl":[[0,1.19,633.17],[1,1.2,495.98]],"ltp":1.14,"tv":38370.06,"id":9629022}]}]}
{"op":"mcm","clk":"4228573843","pt":1631462542279,"mc":[{"id":"1.187551081","rc":[{"batb":[[0,1.14,987.39],[1,1.13,171.73],[2,1.1,30]],"batl":[[0,1.22,134.25],[1,1.39,17.79],[2,3.8,27.47]],"ltp":1.14,"tv":38370.06,"id":9629022}]}]}
{"op":"mcm","clk":"4228574033","pt":1631462543528,"mc":[{"id":"1.187551081","rc":[{"batl":[[2,11.5,69.57]],"ltp":7.0,"tv":1947.01,"id":7445998},{"batb":[[0,1.16,5],[1,1.14,987.39],[2,1.13,171.73]],"ltp":1.14,"tv":38370.06,"id":9629022}]}]}
{"op":"mcm","clk":"4228574202","pt":1631462544492,"mc":[{"id":"1.187551081","rc":[{"batb":[[0,1.16,10],[1,1.15,10],[2,1.14,987.39]],"ltp":1.14,"tv":38370.06,"id":9629022}]}]}
{"op":"mcm","clk":"4228574390","pt":1631462545425,"mc":[{"id":"1.187551081","rc":[{"batb":[[2,1.14,1920.05]],"batl":[[0,1.21,14],[1,1.22,490.31],[2,1.23,447.16]],"ltp":1.14,"tv":38370.06,"id":9629022}]}]}
{"op":"mcm","clk":"4228574761","pt":1631462547522,"mc":[{"id":"1.187551081","rc":[{"batb":[[0,6,2.04],[1,5.7,3],[2,5.6,2]],"ltp":7.0,"tv":1947.01,"id":7445998},{"batl":[[0,1.2,122.13],[1,1.21,133.5],[2,1.22,490.31]],"ltp":1.14,"tv":38370.06,"id":9629022}]}]}
{"op":"mcm","clk":"4228574915","pt":1631462548508,"mc":[{"id":"1.187551081","rc":[{"batb":[[0,5.7,3],[1,5.5,2.12],[2,5.3,49.91]],"ltp":7.0,"tv":1947.01,"id":7445998},{"batl":[[0,1.21,14],[1,1.22,134.25],[2,1.39,17.79]],"ltp":1.14,"tv":38370.06,"id":9629022}]}]}
{"op":"mcm","clk":"4228575260","pt":1631462550611,"mc":[{"id":"1.187551081","rc":[{"batl":[[2,990,0.01]],"ltp":7.0,"tv":1947.01,"id":7445998},{"batb":[[0,1.14,1890.05],[1,1.13,424.31],[2,1.03,6.16]],"batl":[[0,1.16,5076.34],[1,1.21,14],[2,1.22,134.25]],"ltp":1.14,"tv":38370.06,"id":9629022}]}]}
{"op":"mcm","clk":"4228575458","pt":1631462551530,"mc":[{"id":"1.187551081","rc":[{"batb":[[1,5.6,3],[2,5.5,2.12]],"ltp":7.0,"tv":1947.01,"id":7445998},{"batl":[[0,1.16,213.46],[1,1.17,639.44],[2,1.21,14]],"ltp":1.14,"tv":38370.06,"id":9629022}]}]}
{"op":"mcm","clk":"4228575648","pt":1631462552618,"mc":[{"id":"1.187551081","rc":[{"batb":[[0,7,54.51],[1,6,15],[2,5.7,3]],"batl":[[0,8.6,10],[1,8.8,2],[2,9.6,1]],"ltp":7.0,"tv":1947.01,"id":7445998},{"batb":[[2,1.09,1154.92]],"batl":[[0,1.16,227.21],[2,1.18,6.76]],"ltp":1.14,"tv":38370.06,"id":9629022}]}]}
{"op":"mcm","clk":"4228575807","pt":1631462553625,"mc":[{"id":"1.187551081","rc":[{"batb":[[1,5.8,2]],"ltp":7.0,"tv":1947.01,"id":7445998}]}]}
{"op":"mcm","clk":"4228576125","pt":1631462555437,"mc":[{"id":"1.187551081","rc":[{"batl":[[0,8.6,2]],"ltp":7.0,"tv":1947.01,"id":7445998}]}]}
{"op":"mcm","clk":"4228576298","pt":1631462556514,"mc":[{"id":"1.187551081","rc":[{"batb":[[0,7,69.51]],"ltp":7.0,"tv":1947.01,"id":7445998},{"batb":[[0,1.14,2167.15]],"batl":[[0,1.16,426.93]],"ltp":1.14,"tv":38370.06,"id":9629022}]}]}
{"op":"mcm","clk":"4228576645","pt":1631462558530,"mc":[{"id":"1.187551081","rc":[{"trd":[[7.2,23.99]],"batb":[[1,6.2,2.02],[2,5.8,2]],"batl":[[0,8.4,10],[1,8.6,2],[2,8.8,2]],"ltp":7.2,"tv":1948.74,"id":7445998},{"trd":[[1.16,1072.89]],"batb":[[2,1.11,236.59]],"batl":[[0,1.16,416.21]],"ltp":1.16,"tv":38380.78,"id":9629022}],"tv":40329.52}]}
{"op":"mcm","clk":"4228577238","pt":1631462561948,"mc":[{"id":"1.187551081","rc":[{"batl":[[0,1.15,5],[1,1.16,416.21],[2,1.17,639.44]],"ltp":1.16,"tv":38380.78,"id":9629022}]}]}
{"op":"mcm","clk":"4228577857","pt":1631462565550,"mc":[{"id":"1.187551081","rc":[{"batb":[[0,1.14,2270.05]],"ltp":1.16,"tv":38380.78,"id":9629022}]}]}
{"op":"mcm","clk":"4228578334","pt":1631462568569,"mc":[{"id":"1.187551081","rc":[{"batb":[[1,5.8,2],[2,5.6,44.63]],"batl":[[2,9.6,1]],"ltp":7.2,"tv":1948.74,"id":7445998},{"batb":[[0,1.14,1152.57],[1,1.09,1154.92],[2,1.07,14.91]],"batl":[[1,1.16,213.47],[2,1.18,6.76]],"ltp":1.16,"tv":38380.78,"id":9629022}]}]}
{"op":"mcm","clk":"4228578428","pt":1631462569069,"mc":[{"id":"1.187551081","rc":[{"batb":[[0,5.6,44.63],[1,3,383.31],[2,1.01,30]],"batl":[[0,9.6,1],[1,12.5,65.54],[2,990,0.01]],"ltp":7.2,"tv":1948.74,"id":7445998},{"batb":[[0,1.09,1154.92],[1,1.03,6.16],[2,1.07,0]],"batl":[[1,1.22,122.25],[2,1.39,17.79]],"ltp":1.16,"tv":38380.78,"id":9629022}]}]}
{"op":"mcm","clk":"4228578816","pt":1631462571474,"mc":[{"id":"1.187551081","rc":[{"batb":[[0,1.1,1067.36],[1,1.09,1154.92],[2,1.03,6.16]],"batl":[[1,1.21,338.8],[2,1.22,593.59]],"ltp":1.16,"tv":38380.78,"id":9629022}]}]}
{"op":"mcm","clk":"4228578948","pt":1631462572340,"mc":[{"id":"1.187551081","rc":[{"batb":[[0,5.6,46.63],[1,5.5,3],[2,3,383.31]],"batl":[[1,11,2],[2,12.5,65.54]],"ltp":7.2,"tv":1948.74,"id":7445998},{"batb":[[0,1.09,1154.92],[1,1.03,6.16],[2,1.03,0]],"batl":[[1,1.22,122.25],[2,1.39,17.79]],"ltp":1.16,"tv":38380.78,"id":9629022}]}]}
{"op":"mcm","clk":"4228579206","pt":1631462573963,"mc":[{"id":"1.187551081","rc":[{"trd":[[1.15,245.96]],"batl":[[0,1.15,3]],"ltp":1.15,"tv":38384.78,"id":9629022}],"tv":40333.52}]}
{"op":"mcm","clk":"4228579361","pt":1631462575194,"mc":[{"id":"1.187551081","rc":[{"batb":[[0,1.14,227.82],[1,1.13,898.64],[2,1.09,1154.92]],"batl":[[1,1.16,840.07],[2,1.17,319.8]],"ltp":1.15,"tv":38384.78,"id":9629022}]}]}
{"op":"mcm","clk":"4228579560","pt":1631462576355,"mc":[{"id":"1.187551081","rc":[{"batb":[[0,6.4,39.06],[1,5.6,46.63],[2,5.5,3]],"batl":[[0,9.4,5],[1,9.6,1],[2,11,2]],"ltp":7.2,"tv":1948.74,"id":7445998}]}]}
{"op":"mcm","clk":"4228580097","pt":1631462579467,"mc":[{"id":"1.187551081","rc":[{"batb":[[0,1.14,760.91]],"batl":[[1,1.16,1081.77]],"ltp":1.15,"tv":38384.78,"id":9629022}]}]}
{"op":"mcm","clk":"4228580139","pt":1631462579766,"mc":[{"id":"1.187551081","rc":[{"batb":[[0,1.14,548.63]],"ltp":1.15,"tv":38384.78,"id":9629022}]}]}
{"op":"mcm","clk":"4228580554","pt":1631462582356,"mc":[{"id":"1.187551081","rc":[{"batb":[[0,5.6,46.63],[1,5.5,3],[2,3,383.31]],"batl":[[0,9.6,1],[1,11,2],[2,12.5,65.54]],"ltp":7.2,"tv":1948.74,"id":7445998},{"batb":[[0,1.09,1154.92],[1,1.03,6.16],[2,1.09,0]],"batl":[[1,1.22,122.25],[2,1.39,17.79]],"ltp":1.15,"tv":38384.78,"id":9629022}]}]}
{"op":"mcm","clk":"4228580675","pt":1631462583205,"mc":[{"id":"1.187551081","rc":[{"batl":[[0,1.15,5]],"ltp":1.15,"tv":38384.78,"id":9629022}]}]}
{"op":"mcm","clk":"4228581056","pt":1631462585382,"mc":[{"id":"1.187551081","rc":[{"batb":[[1,3,383.31],[2,1.01,30]],"ltp":7.2,"tv":1948.74,"id":7445998},{"batb":[[0,1.1,1067.36],[1,1.09,1154.92],[2,1.03,6.16]],"batl":[[1,1.21,338.8],[2,1.22,593.59]],"ltp":1.15,"tv":38384.78,"id":9629022}]}]}
{"op":"mcm","clk":"4228581155","pt":1631462585985,"mc":[{"id":"1.187551081","rc":[{"batl":[[0,1.15,3]],"ltp":1.15,"tv":38384.78,"id":9629022}]}]}
{"op":"mcm","clk":"4228581588","pt":1631462588585,"mc":[{"id":"1.187551081","rc":[{"trd":[[1.15,251.96]],"batb":[[0,1.19,6742.72],[1,1.1,1067.36],[2,1.09,1154.92]],"batl":[[0,1.21,338.8],[1,1.22,593.59],[2,1.39,17.79]],"ltp":1.15,"tv":38390.78,"id":9629022}],"tv":40339.52}]}
{"op":"mcm","clk":"4228581625","pt":1631462588794,"mc":[{"id":"1.187551081","rc":[{"batb":[[0,1.19,6721.38]],"ltp":1.15,"tv":38390.78,"id":9629022}]}]}
{"op":"mcm","clk":"4228582207","pt":1631462592297,"mc":[{"id":"1.187551081","rc":[{"trd":[[1.19,481.26]],"batb":[[0,1.19,6675.84]],"ltp":1.19,"tv":38481.86,"id":9629022}],"tv":40430.6}]}
{"op":"mcm","clk":"4228582302","pt":1631462592885,"mc":[{"id":"1.187551081","rc":[{"trd":[[1.19,485.26]],"batb":[[0,1.19,6673.84]],"ltp":1.19,"tv":38485.86,"id":9629022}],"tv":40434.6}]}
{"op":"mcm","clk":"4228582499","pt":1631462594071,"mc":[{"id":"1.187551081","rc":[{"trd":[[5.7,89.67]],"ltp":5.7,"tv":1965.82,"id":7445998},{"trd":[[1.21,350.01]],"batl":[[0,1.21,258.34]],"ltp":1.21,"tv":38566.32,"id":9629022}],"tv":40532.14}]}
{"op":"mcm","clk":"4228583046","pt":1631462597666,"mc":[{"id":"1.187551081","rc":[{"batb":[[1,1.1,1116.54]],"batl":[[0,1.21,294.35]],"ltp":1.21,"tv":38566.32,"id":9629022}]}]}
{"op":"mcm","clk":"4228584135","pt":1631462603656,"mc":[{"id":"1.187551081","rc":[{"trd":[[1.19,648.14]],"batb":[[0,1.19,6592.4]],"ltp":1.19,"tv":38729.19,"id":9629022}],"tv":40695.02}]}
{"op":"mcm","clk":"4228586655","pt":1631462618864,"mc":[{"id":"1.187551081","rc":[{"trd":[[5.7,90.12]],"ltp":5.7,"tv":1966.27,"id":7445998},{"trd":[[1.21,352.13]],"batl":[[0,1.21,292.23]],"ltp":1.21,"tv":38731.31,"id":9629022}],"tv":40697.59}]}
{"op":"mcm","clk":"4228586968","pt":1631462620864,"mc":[{"id":"1.187551081","rc":[{"batb":[[1,1.1,1140.96]],"ltp":1.21,"tv":38731.31,"id":9629022}]}]}
{"op":"mcm","clk":"4228587796","pt":1631462625981,"mc":[{"id":"1.187551081","rc":[{"trd":[[1.19,4491.34]],"batb":[[0,1.19,4670.8],[1,1.09,1154.92],[2,1.03,6.16]],"ltp":1.19,"tv":42574.51,"id":9629022}],"tv":44540.79}]}
{"op":"mcm","clk":"4228588160","pt":1631462627872,"mc":[{"id":"1.187551081","rc":[{"batl":[[2,990,0.01]],"ltp":5.7,"tv":1966.27,"id":7445998}]}]}
{"op":"mcm","clk":"4228588458","pt":1631462629478,"mc":[{"id":"1.187551081","rc":[{"trd":[[1.19,4518.15]],"batb":[[0,1.19,477.82],[1,1.18,626.46],[2,1.1,14.5]],"batl":[[0,1.21,298.82]],"ltp":1.19,"tv":42601.33,"id":9629022}],"tv":44567.6}]}
{"op":"mcm","clk":"4228588620","pt":1631462630638,"mc":[{"id":"1.187551081","rc":[{"batb":[[1,4.6,70.17],[2,3,383.31]],"batl":[[0,7,5],[1,9.6,1],[2,11,2]],"ltp":5.7,"tv":1966.27,"id":7445998},{"batb":[[0,1.2,52.94],[1,1.19,477.82],[2,1.18,1195.21]],"ltp":1.19,"tv":42601.33,"id":9629022}]}]}
{"op":"mcm","clk":"4228588750","pt":1631462631367,"mc":[{"id":"1.187551081","rc":[{"batl":[[2,9.8,74.6]],"ltp":5.7,"tv":1966.27,"id":7445998}]}]}
{"op":"mcm","clk":"4228589143","pt":1631462633992,"mc":[{"id":"1.187551081","rc":[{"batb":[[1,1.19,753.77]],"batl":[[0,1.21,504.61]],"ltp":1.19,"tv":42601.33,"id":9629022}]}]}
{"op":"mcm","clk":"4228589379","pt":1631462635507,"mc":[{"id":"1.187551081","rc":[{"trd":[[1.19,6025.69],[1.2,662.63]],"batb":[[0,1.18,1195.21],[1,1.15,727.18],[2,1.1,14.5]],"batl":[[0,1.19,1328.4],[1,1.21,504.61],[2,1.22,593.59]],"ltp":1.19,"tv":44214.75,"id":9629022}],"tv":46181.03}]}
{"op":"mcm","clk":"4228589549","pt":1631462636501,"mc":[{"id":"1.187551081","rc":[{"trd":[[5.7,93.54]],"ltp":5.7,"tv":1969.69,"id":7445998},{"trd":[[1.21,368.22]],"batl":[[0,1.21,488.52],[1,1.22,593.59],[2,1.39,17.79]],"ltp":1.21,"tv":44230.84,"id":9629022}],"tv":46200.53}]}
{"op":"mcm","clk":"4228589932","pt":1631462638487,"mc":[{"id":"1.187551081","rc":[{"batb":[[0,1.19,194.89],[1,1.18,1466.1],[2,1.15,727.18]],"batl":[[0,1.2,266.37],[1,1.21,703.88],[2,1.22,593.59]],"ltp":1.21,"tv":44230.84,"id":9629022}]}]}
{"op":"mcm","clk":"4228590069","pt":1631462639200,"mc":[{"id":"1.187551081","rc":[{"batb":[[0,1.19,286.49]],"ltp":1.21,"tv":44230.84,"id":9629022}]}]}
{"op":"mcm","clk":"4228590473","pt":1631462641408,"mc":[{"id":"1.187551081","rc":[{"batb":[[0,1.19,558.83]],"ltp":1.21,"tv":44230.84,"id":9629022}]}]}
{"op":"mcm","clk":"4228590614","pt":1631462642203,"mc":[{"id":"1.187551081","rc":[{"trd":[[6,117.03]],"ltp":6.0,"tv":1971.06,"id":7445998},{"trd":[[1.2,669.52]],"batl":[[0,1.2,259.48]],"ltp":1.2,"tv":44237.73,"id":9629022}],"tv":46208.8}]}
{"op":"mcm","clk":"4228591087","pt":1631462645120,"mc":[{"id":"1.187551081","rc":[{"batb":[[0,6,57.39],[1,5.7,80.13],[2,5.6,46.63]],"ltp":6.0,"tv":1971.06,"id":7445998},{"batl":[[0,1.2,546.44],[1,1.21,1081.37]],"ltp":1.2,"tv":44237.73,"id":9629022}]}]}
{"op":"mcm","clk":"4228591433","pt":1631462647113,"mc":[{"id":"1.187551081","rc":[{"batb":[[2,5.6,44.63]],"batl":[[0,6.4,55.1],[1,6.6,72.99],[2,9.6,1]],"ltp":6.0,"tv":1971.06,"id":7445998},{"batb":[[0,1.19,855.18],[1,1.18,1874.33]],"ltp":1.2,"tv":44237.73,"id":9629022}]}]}
{"op":"mcm","clk":"4228591938","pt":1631462650302,"mc":[{"id":"1.187551081","rc":[{"trd":[[6.4,24.07]],"batl":[[0,6.2,25.13],[1,6.4,54.6],[2,6.6,72.99]],"ltp":6.4,"tv":1972.07,"id":7445998},{"trd":[[1.19,6031.14]],"batb":[[0,1.19,852.46]],"ltp":1.19,"tv":44243.17,"id":9629022}],"tv":46215.25}]}
{"op":"mcm","clk":"4228592271","pt":1631462652408,"mc":[{"id":"1.187551081","rc":[{"batl":[[0,1.2,646.44]],"ltp":1.19,"tv":44243.17,"id":9629022}]}]}
{"op":"mcm","clk":"4228592679","pt":1631462654820,"mc":[{"id":"1.187551081","rc":[{"trd":[[1.19,6040.16]],"batb":[[0,1.19,847.95]],"ltp":1.19,"tv":44252.19,"id":9629022}],"tv":46224.27}]}
{"op":"mcm","clk":"4228592945","pt":1631462656436,"mc":[{"id":"1.187551081","rc":[{"trd":[[1.19,6061.05]],"batb":[[0,1.19,837.5]],"ltp":1.19,"tv":44273.09,"id":9629022}],"tv":46245.16}]}
{"op":"mcm","clk":"4228593194","pt":1631462657897,"mc":[{"id":"1.187551081","rc":[{"batb":[[2,5.6,43.71]],"ltp":6.4,"tv":1972.07,"id":7445998},{"batb":[[2,1.14,737.73]],"ltp":1.19,"tv":44273.09,"id":9629022}]}]}
{"op":"mcm","clk":"4228593455","pt":1631462659542,"mc":[{"id":"1.187551081","rc":[{"batl":[[0,1.2,546.44]],"ltp":1.19,"tv":44273.09,"id":9629022}]}]}
{"op":"mcm","clk":"4228593965","pt":1631462662653,"mc":[{"id":"1.187551081","rc":[{"trd":[[1.19,6261.05]],"batb":[[0,1.19,737.5]],"ltp":1.19,"tv":44473.09,"id":9629022}],"tv":46445.16}]}
{"op":"mcm","clk":"4228594133","pt":1631462663510,"mc":[{"id":"1.187551081","rc":[{"trd":[[1.2,773.15]],"batb":[[0,1.19,665.29]],"batl":[[0,1.2,494.63]],"ltp":1.2,"tv":44576.71,"id":9629022}],"tv":46548.79}]}
{"op":"mcm","clk":"4228594579","pt":1631462666069,"mc":[{"id":"1.187551081","rc":[{"batb":[[1,5.7,165.87],[2,4.6,68]],"ltp":6.4,"tv":1972.07,"id":7445998},{"batb":[[1,1.18,2009.45],[2,1.17,384.61]],"batl":[[1,1.21,1152.6]],"ltp":1.2,"tv":44576.71,"id":9629022}]}]}
{"op":"mcm","clk":"4228596041","pt":1631462676071,"mc":[{"id":"1.187551081","rc":[{"trd":[[1.2,793.15]],"batl":[[0,1.2,484.63]],"ltp":1.2,"tv":44596.71,"id":9629022}],"tv":46568.79}]}
{"op":"mcm","clk":"4228596572","pt":1631462679084,"mc":[{"id":"1.187551081","rc":[{"batb":[[1,1.18,1941.11]],"ltp":1.2,"tv":44596.71,"id":9629022}]}]}
{"op":"mcm","clk":"4228596764","pt":1631462680210,"mc":[{"id":"1.187551081","rc":[{"trd":[[1.2,803.15]],"batl":[[0,1.2,479.63]],"ltp":1.2,"tv":44606.71,"id":9629022}],"tv":46578.79}]}
{"op":"mcm","clk":"4228597073","pt":1631462682315,"mc":[{"id":"1.187551081","rc":[{"batb":[[2,1.17,453.52]],"batl":[[1,1.21,1219.49]],"ltp":1.2,"tv":44606.71,"id":9629022}]}]}
{"op":"mcm","clk":"4228598673","pt":1631462692793,"mc":[{"id":"1.187551081","rc":[{"trd":[[1.2,813.27]],"batl":[[0,1.2,474.57]],"ltp":1.2,"tv":44616.84,"id":9629022}],"tv":46588.91}]}
{"op":"mcm","clk":"4228602235","pt":1631462715250,"mc":[{"id":"1.187551081","rc":[{"trd":[[1.2,817.27]],"batl":[[0,1.2,472.57]],"ltp":1.2,"tv":44620.84,"id":9629022}],"tv":46592.91}]}
{"op":"mcm","clk":"4228602399","pt":1631462716259,"mc":[{"id":"1.187551081","rc":[{"batl":[[1,1.21,1212.9]],"ltp":1.2,"tv":44620.84,"id":9629022}]}]}
{"op":"mcm","clk":"4228602518","pt":1631462717077,"mc":[{"id":"1.187551081","rc":[{"batb":[[0,1.19,660.29]],"ltp":1.2,"tv":44620.84,"id":9629022}]}]}
{"op":"mcm","clk":"4228602875","pt":1631462719254,"mc":[{"id":"1.187551081","rc":[{"batb":[[2,4.8,2.58]],"ltp":6.4,"tv":1972.07,"id":7445998}]}]}
{"op":"mcm","clk":"4228602950","pt":1631462719766,"mc":[{"id":"1.187551081","rc":[{"trd":[[1.2,827.27]],"batl":[[0,1.2,467.57]],"ltp":1.2,"tv":44630.84,"id":9629022}],"tv":46602.91}]}
{"op":"mcm","clk":"4228606135","pt":1631462737377,"mc":[{"id":"1.187551081","rc":[{"trd":[[1.19,6506.81]],"batb":[[0,1.19,537.41]],"ltp":1.19,"tv":44876.6,"id":9629022}],"tv":46848.67}]}
{"op":"mcm","clk":"4228606882","pt":1631462741599,"mc":[{"id":"1.187551081","rc":[{"batb":[[0,1.19,619.85]],"ltp":1.19,"tv":44876.6,"id":9629022}]}]}
{"op":"mcm","clk":"4228607268","pt":1631462743488,"mc":[{"id":"1.187551081","rc":[{"trd":[[1.19,6594.19]],"batb":[[0,1.19,576.16]],"ltp":1.19,"tv":44963.98,"id":9629022}],"tv":46936.05}]}
{"op":"mcm","clk":"4228607456","pt":1631462744510,"mc":[{"id":"1.187551081","rc":[{"batb":[[0,4.6,68],[1,4.4,2.11],[2,3,383.31]],"batl":[[0,8.2,2],[1,9.6,1],[2,9.8,74.6]],"ltp":6.4,"tv":1972.07,"id":7445998},{"batb":[[0,1.14,920.55],[1,1.03,6.16],[2,1.17,0]],"batl":[[0,1.29,80.5],[1,1.39,17.79],[2,3.8,27.47]],"ltp":1.19,"tv":44963.98,"id":9629022}]}]}
{"op":"mcm","clk":"4228608019","pt":1631462747513,"mc":[{"id":"1.187551081","rc":[{"batb":[[0,5.6,2],[1,5.5,3],[2,4.9,3]],"batl":[[0,7.2,2],[1,8.2,2],[2,9.6,1]],"ltp":6.4,"tv":1972.07,"id":7445998},{"batb":[[0,1.18,15],[1,1.17,13],[2,1.16,12]],"batl":[[0,1.25,10],[1,1.29,80.5],[2,1.39,17.79]],"ltp":1.19,"tv":44963.98,"id":9629022}]}]}
{"op":"mcm","clk":"4228608106","pt":1631462747996,"mc":[{"id":"1.187551081","rc":[{"batl":[[0,8.2,4],[1,9.6,1],[2,9.8,74.6]],"ltp":6.4,"tv":1972.07,"id":7445998},{"batb":[[0,1.15,511.58],[1,1.14,1609.6],[2,1.13,21]],"batl":[[1,1.27,9],[2,1.28,10]],"ltp":1.19,"tv":44963.98,"id":9629022}]}]}
{"op":"mcm","clk":"4228608337","pt":1631462749414,"mc":[{"id":"1.187551081","rc":[{"batl":[[2,11,2]],"ltp":6.4,"tv":1972.07,"id":7445998}]}]}
{"op":"mcm","clk":"4228608524","pt":1631462750410,"mc":[{"id":"1.187551081","rc":[{"batb":[[2,5,2]],"batl":[[0,7.8,2],[1,8.2,4],[2,9.6,1]],"ltp":6.4,"tv":1972.07,"id":7445998},{"batb":[[0,1.15,500.58]],"batl":[[0,1.17,547.07],[1,1.18,598.87],[2,1.19,6.71]],"ltp":1.19,"tv":44963.98,"id":9629022}]}]}
{"op":"mcm","clk":"4228608712","pt":1631462751391,"mc":[{"id":"1.187551081","rc":[{"batb":[[0,6.8,57.61],[1,5.6,47.05],[2,5.5,3]],"ltp":6.4,"tv":1972.07,"id":7445998},{"batl":[[2,1.19,8.71]],"ltp":1.19,"tv":44963.98,"id":9629022}]}]}
{"op":"mcm","clk":"4228608913","pt":1631462752588,"mc":[{"id":"1.187551081","rc":[{"batb":[[1,5.7,12],[2,5.6,47.05]],"ltp":6.4,"tv":1972.07,"id":7445998},{"batb":[[0,1.16,57.33],[1,1.15,500.58],[2,1.14,1609.6]],"ltp":1.19,"tv":44963.98,"id":9629022}]}]}
{"op":"mcm","clk":"4228609098","pt":1631462753617,"mc":[{"id":"1.187551081","rc":[{"batb":[[1,6.2,3],[2,6,3]],"ltp":6.4,"tv":1972.07,"id":7445998},{"batl":[[2,1.19,20.71]],"ltp":1.19,"tv":44963.98,"id":9629022}]}]}
{"op":"mcm","clk":"4228609239","pt":1631462754415,"mc":[{"id":"1.187551081","rc":[{"batb":[[1,1.15,764.92]],"batl":[[0,1.17,806.89]],"ltp":1.19,"tv":44963.98,"id":9629022}]}]}
{"op":"mcm","clk":"4228609401","pt":1631462755328,"mc":[{"id":"1.187551081","rc":[{"batl":[[0,7.6,20],[1,7.8,2],[2,8.2,4]],"ltp":6.4,"tv":1972.07,"id":7445998}]}]}
{"op":"mcm","clk":"4228609659","pt":1631462756639,"mc":[{"id":"1.187551081","rc":[{"batb":[[2,6,5]],"ltp":6.4,"tv":1972.07,"id":7445998}]}]}
{"op":"mcm","clk":"4228610212","pt":1631462759632,"mc":[{"id":"1.187551081","rc":[{"batl":[[2,8.2,2]],"ltp":6.4,"tv":1972.07,"id":7445998}]}]}
{"op":"mcm","clk":"4228610765","pt":1631462762357,"mc":[{"id":"1.187551081","rc":[{"batl":[[0,1.17,801.24]],"ltp":1.19,"tv":44963.98,"id":9629022}]}]}
{"op":"mcm","clk":"4228610903","pt":1631462763040,"mc":[{"id":"1.187551081","rc":[{"trd":[[1.16,1092.89]],"batb":[[0,1.16,47.33]],"ltp":1.16,"tv":44983.98,"id":9629022}],"tv":46956.05}]}
{"op":"mcm","clk":"4228611183","pt":1631462764546,"mc":[{"id":"1.187551081","rc":[{"batb":[[0,5.7,2],[1,5.6,45.05],[2,5.5,2]],"batl":[[0,8.2,2],[1,9.4,2],[2,9.6,1]],"ltp":6.4,"tv":1972.07,"id":7445998},{"batb":[[0,1.14,182.82],[1,1.13,178.73],[2,1.12,212.54]],"batl":[[0,1.19,2],[1,1.22,116.25],[2,1.29,80.5]],"ltp":1.16,"tv":44983.98,"id":9629022}]}]}
{"op":"mcm","clk":"4228611232","pt":1631462764746,"mc":[{"id":"1.187551081","rc":[{"batl":[[0,9.4,2],[1,9.6,1],[2,11.5,69.57]],"ltp":6.4,"tv":1972.07,"id":7445998},{"batb":[[0,1.12,212.54],[1,1.11,936.36],[2,1.03,6.16]],"ltp":1.16,"tv":44983.98,"id":9629022}]}]}
{"op":"mcm","clk":"4228611805","pt":1631462767630,"mc":[{"id":"1.187551081","rc":[{"batb":[[2,5.5,48.14]],"ltp":6.4,"tv":1972.07,"id":7445998},{"batb":[[0,1.12,1222.69],[1,1.11,1132.1]],"batl":[[1,1.21,174.41],[2,1.22,602.21]],"ltp":1.16,"tv":44983.98,"id":9629022}]}]}
{"op":"mcm","clk":"4228611930","pt":1631462768260,"mc":[{"id":"1.187551081","rc":[{"batb":[[1,5.6,2]],"batl":[[0,9.4,5]],"ltp":6.4,"tv":1972.07,"id":7445998},{"batb":[[0,1.12,1224.69],[1,1.11,1134.1]],"ltp":1.16,"tv":44983.98,"id":9629022}]}]}
{"op":"mcm","clk":"4228612561","pt":1631462771571,"mc":[{"id":"1.187551081","rc":[{"batl":[[0,8.2,2],[1,8.8,2],[2,9.4,5]],"ltp":6.4,"tv":1972.07,"id":7445998},{"batb":[[0,1.14,203.32],[1,1.13,211.73],[2,1.12,1224.69]],"ltp":1.16,"tv":44983.98,"id":9629022}]}]}
{"op":"mcm","clk":"4228612603","pt":1631462771730,"mc":[{"id":"1.187551081","rc":[{"batl":[[0,9.4,5],[1,9.6,1],[2,11.5,69.57]],"ltp":6.4,"tv":1972.07,"id":7445998},{"batb":[[0,1.12,1224.69],[1,1.11,1134.1],[2,1.03,6.16]],"ltp":1.16,"tv":44983.98,"id":9629022}]}]}
{"op":"mcm","clk":"4228613267","pt":1631462775274,"mc":[{"id":"1.187551081","rc":[{"batl":[[1,1.22,116.25],[2,1.39,17.79]],"ltp":1.16,"tv":44983.98,"id":9629022}]}]}
{"op":"mcm","clk":"4228613525","pt":1631462776526,"mc":[{"id":"1.187551081","rc":[{"batl":[[0,1.14,13.2],[1,1.19,2],[2,1.22,116.25]],"ltp":1.16,"tv":44983.98,"id":9629022}]}]}
{"op":"mcm","clk":"4228613719","pt":1631462777590,"mc":[{"id":"1.187551081","rc":[{"batl":[[2,990,0.01]],"ltp":6.4,"tv":1972.07,"id":7445998},{"batl":[[0,1.19,2],[1,1.22,116.25],[2,1.39,17.79]],"ltp":1.16,"tv":44983.98,"id":9629022}]}]}
{"op":"mcm","clk":"4228613940","pt":1631462778655,"mc":[{"id":"1.187551081","rc":[{"batb":[[2,1.06,15.05]],"batl":[[0,1.14,424.29],[1,1.15,755.01],[2,1.17,6.82]],"ltp":1.16,"tv":44983.98,"id":9629022}]}]}
{"op":"mcm","clk":"4228614125","pt":1631462779533,"mc":[{"id":"1.187551081","rc":[{"batb":[[0,8,39.52],[1,6.6,59.54],[2,5.7,2]],"ltp":6.4,"tv":1972.07,"id":7445998},{"batb":[[1,1.11,1132.1],[2,1.1,1122.68]],"ltp":1.16,"tv":44983.98,"id":9629022}]}]}
{"op":"mcm","clk":"4228614264","pt":1631462780241,"mc":[{"id":"1.187551081","rc":[{"batb":[[1,6.6,69.54],[2,5.8,2]],"batl":[[0,9.2,2],[1,9.4,5],[2,9.6,1]],"ltp":6.4,"tv":1972.07,"id":7445998},{"batb":[[0,1.13,71.29],[1,1.12,1224.69],[2,1.11,1132.1]],"ltp":1.16,"tv":44983.98,"id":9629022}]}]}
{"op":"mcm","clk":"4228614715","pt":1631462782372,"mc":[{"id":"1.187551081","rc":[{"batb":[[1,1.12,1441.03]],"batl":[[0,1.14,645.29]],"ltp":1.16,"tv":44983.98,"id":9629022}]}]}
{"op":"mcm","clk":"4228614928","pt":1631462783451,"mc":[{"id":"1.187551081","rc":[{"batl":[[0,9,15.57],[1,9.2,2],[2,9.4,5]],"ltp":6.4,"tv":1972.07,"id":7445998},{"trd":[[1.13,1215.24]],"batb":[[0,1.13,62.59]],"ltp":1.13,"tv":45021.38,"id":9629022}],"tv":46993.45}]}
{"op":"mcm","clk":"4228615130","pt":1631462784436,"mc":[{"id":"1.187551081","rc":[{"batb":[[1,6.8,2],[2,6.6,69.54]],"ltp":6.4,"tv":1972.07,"id":7445998},{"batb":[[2,1.11,1389.69]],"batl":[[2,1.17,175.32]],"ltp":1.13,"tv":45021.38,"id":9629022}]}]}
{"op":"mcm","clk":"4228615759","pt":1631462788082,"mc":[{"id":"1.187551081","rc":[{"batb":[[0,1.13,72.59]],"ltp":1.13,"tv":45021.38,"id":9629022}]}]}
{"op":"mcm","clk":"4228616034","pt":1631462789559,"mc":[{"id":"1.187551081","rc":[{"batb":[[0,1.13,62.59]],"ltp":1.13,"tv":45021.38,"id":9629022}]}]}
{"op":"mcm","clk":"4228616366","pt":1631462791491,"mc":[{"id":"1.187551081","rc":[{"batb":[[0,6.6,59.54],[1,6.2,2],[2,5.8,2]],"batl":[[0,9.6,1],[1,10.5,2],[2,14,62.24]],"ltp":6.4,"tv":1972.07,"id":7445998},{"batb":[[0,1.13,10],[1,1.11,453.33],[2,1.1,1122.68]],"batl":[[0,1.18,141.75],[1,1.19,133.5],[2,1.22,116.25]],"ltp":1.13,"tv":45021.38,"id":9629022}]}]}
{"op":"mcm","clk":"4228616413","pt":1631462791764,"mc":[{"id":"1.187551081","rc":[{"batb":[[0,1.14,10],[1,1.13,10],[2,1.11,453.33]],"ltp":1.13,"tv":45021.38,"id":9629022}]}]}
{"op":"mcm","clk":"4228616900","pt":1631462794668,"mc":[{"id":"1.187551081","rc":[{"batb":[[0,6.8,5],[1,6.6,61.54],[2,6.4,2]],"batl":[[0,9.4,2],[1,9.6,1],[2,10.5,2]],"ltp":6.4,"tv":1972.07,"id":7445998},{"batb":[[0,1.13,10],[1,1.12,211.79],[2,1.11,642.63]],"batl":[[0,1.17,581.95],[1,1.18,745.17],[2,1.19,133.5]],"ltp":1.13,"tv":45021.38,"id":9629022}]}]}
{"op":"mcm","clk":"4228616986","pt":1631462795079,"mc":[{"id":"1.187551081","rc":[{"batb":[[0,6.8,3]],"batl":[[0,9.6,1],[1,10.5,2],[2,14,62.24]],"ltp":6.4,"tv":1972.07,"id":7445998},{"batb":[[1,1.11,642.63],[2,1.1,1990.46]],"batl":[[0,1.17,9],[1,1.18,141.75]],"ltp":1.13,"tv":45021.38,"id":9629022}]}]}
{"op":"mcm","clk":"4228617278","pt":1631462796596,"mc":[{"id":"1.187551081","rc":[{"batl":[[2,990,0.01]],"ltp":6.4,"tv":1972.07,"id":7445998},{"batb":[[0,1.11,642.63],[1,1.1,1990.46],[2,1.03,6.16]],"batl":[[0,1.15,40.04],[1,1.17,9],[2,1.18,141.75]],"ltp":1.13,"tv":45021.38,"id":9629022}]}]}
{"op":"mcm","clk":"4228617489","pt":1631462797559,"mc":[{"id":"1.187551081","rc":[{"batl":[[0,1.12,267.63],[1,1.13,878.79],[2,1.17,9]],"ltp":1.13,"tv":45021.38,"id":9629022}]}]}
{"op":"mcm","clk":"4228617691","pt":1631462798577,"mc":[{"id":"1.187551081","rc":[{"batb":[[0,9,30.48],[1,8,38.77],[2,7.4,15]],"batl":[[1,10.5,4]],"ltp":6.4,"tv":1972.07,"id":7445998},{"trd":[[1.12,1852.96]],"batb":[[2,1.09,1254.56]],"batl":[[0,1.12,257.63],[1,1.13,892.91],[2,1.15,6.93]],"ltp":1.12,"tv":45041.38,"id":9629022}],"tv":47013.45}]}
{"op":"mcm","clk":"4228617847","pt":1631462799499,"mc":[{"id":"1.187551081","rc":[{"batb":[[0,1.11,735.79],[1,1.1,2000.46]],"ltp":1.12,"tv":45041.38,"id":9629022}]}]}
{"op":"mcm","clk":"4228617967","pt":1631462800090,"mc":[{"id":"1.187551081","rc":[{"batl":[[2,1.14,14]],"ltp":1.12,"tv":45041.38,"id":9629022}]}]}
{"op":"mcm","clk":"4228618166","pt":1631462800974,"mc":[{"id":"1.187551081","rc":[{"batl":[[2,17,57.15]],"ltp":6.4,"tv":1972.07,"id":7445998}]}]}
{"op":"mcm","clk":"4228618480","pt":1631462802498,"mc":[{"id":"1.187551081","rc":[{"batl":[[2,13.5,46.24]],"ltp":6.4,"tv":1972.07,"id":7445998},{"batb":[[0,1.11,941.28]],"batl":[[0,1.12,473.44],[1,1.13,1107.52]],"ltp":1.12,"tv":45041.38,"id":9629022}]}]}
{"op":"mcm","clk":"4228618526","pt":1631462802669,"mc":[{"id":"1.187551081","rc":[{"batl":[[2,17,57.15]],"ltp":6.4,"tv":1972.07,"id":7445998}]}]}
{"op":"mcm","clk":"4228619115","pt":1631462805494,"mc":[{"id":"1.187551081","rc":[{"batb":[[0,9.2,44.7],[1,9,30.48],[2,8.6,60.25]],"batl":[[1,10.5,44.81],[2,11,57]],"ltp":6.4,"tv":1972.07,"id":7445998},{"batb":[[0,1.11,1327.31],[1,1.1,2786.9]],"batl":[[0,1.12,840.68],[1,1.13,1566.14],[2,1.14,178.25]],"ltp":1.12,"tv":45041.38,"id":9629022}]}]}
{"op":"mcm","clk":"4228619197","pt":1631462805879,"mc":[{"id":"1.187551081","rc":[{"trd":[[1.12,1872.96]],"batl":[[0,1.12,830.68]],"ltp":1.12,"tv":45061.38,"id":9629022}],"tv":47033.45}]}
{"op":"mcm","clk":"4228619481","pt":1631462807264,"mc":[{"id":"1.187551081","rc":[{"trd":[[1.12,1873.14]],"batb":[[0,1.11,1307.31]],"batl":[[0,1.12,830.59]],"ltp":1.12,"tv":45061.56,"id":9629022}],"tv":47033.63}]}
{"op":"mcm","clk":"4228619677","pt":1631462808303,"mc":[{"id":"1.187551081","rc":[{"trd":[[9.2,95.52]],"batb":[[0,9.2,42.7]],"ltp":9.2,"tv":1976.07,"id":7445998}],"tv":47037.63}]}
{"op":"mcm","clk":"4228619904","pt":1631462809370,"mc":[{"id":"1.187551081","rc":[{"trd":[[1.12,1874.04]],"batl":[[0,1.12,830.14]],"ltp":1.12,"tv":45062.46,"id":9629022}],"tv":47038.53}]}
{"op":"mcm","clk":"4228620243","pt":1631462810588,"mc":[{"id":"1.187551081","rc":[{"batb":[[0,9,30.48],[1,8,40.77],[2,7.2,2]],"batl":[[1,10.5,4],[2,11,2]],"ltp":9.2,"tv":1976.07,"id":7445998},{"batb":[[0,1.11,473.08],[1,1.1,1811.91]],"batl":[[0,1.12,215.81],[1,1.13,228.73]],"ltp":1.12,"tv":45062.46,"id":9629022}]}]}
{"op":"mcm","clk":"4228620553","pt":1631462811522,"mc":[{"id":"1.187551081","rc":[{"batb":[[0,8,38.77],[1,7.2,2],[2,7,3]],"batl":[[1,11,2],[2,17,57.15]],"ltp":9.2,"tv":1976.07,"id":7445998},{"batb":[[0,1.11,10],[1,1.1,689.23]],"batl":[[0,1.14,14],[1,1.15,166.5],[2,1.16,147.22]],"ltp":1.12,"tv":45062.46,"id":9629022}]}]}
{"op":"mcm","clk":"4228620711","pt":1631462811910,"mc":[{"id":"1.187551081","rc":[{"batl":[[1,1.16,147.22],[2,1.19,2]],"ltp":1.12,"tv":45062.46,"id":9629022}]}]}
{"op":"mcm","clk":"4228621331","pt":1631462813431,"mc":[{"id":"1.187551081","rc":[{"batb":[[2,1.09,2045]],"batl":[[0,1.14,666.98],[1,1.15,525.44],[2,1.16,147.22]],"ltp":1.12,"tv":45062.46,"id":9629022}]}]}
{"op":"mcm","clk":"4228621693","pt":1631462814598,"mc":[{"id":"1.187551081","rc":[{"batb":[[0,8,42.77],[1,7.8,2],[2,7.2,2]],"batl":[[1,11,4]],"ltp":9.2,"tv":1976.07,"id":7445998},{"batl":[[0,1.14,873.23]],"ltp":1.12,"tv":45062.46,"id":9629022}]}]}
{"op":"mcm","clk":"4228621886","pt":1631462815416,"mc":[{"id":"1.187551081","rc":[{"batb":[[2,1.09,1254.56]],"batl":[[0,1.14,539.1],[1,1.15,168.3]],"ltp":1.12,"tv":45062.46,"id":9629022}]}]}
{"op":"mcm","clk":"4228622895","pt":1631462818595,"mc":[{"id":"1.187551081","rc":[{"batb":[[0,9.2,19.22],[1,8,42.77],[2,7.8,2]],"ltp":9.2,"tv":1976.07,"id":7445998},{"batb":[[0,1.11,699.41],[1,1.1,796.58]],"batl":[[0,1.12,19.21],[1,1.13,871.83],[2,1.14,539.1]],"ltp":1.12,"tv":45062.46,"id":9629022}]}]}
{"op":"mcm","clk":"4228623218","pt":1631462819554,"mc":[{"id":"1.187551081","rc":[{"trd":[[9.6,65.15]],"batb":[[0,8,42.77],[1,7.8,2],[2,7.2,2]],"batl":[[0,11,4],[1,17,57.15],[2,990,0.01]],"ltp":9.6,"tv":1977.07,"id":7445998},{"trd":[[1.1,1538.88],[1.11,4629.68]],"batb":[[0,1.1,586.82],[1,1.09,1254.56],[2,1.03,6.16]],"batl":[[0,1.13,871.83],[1,1.14,539.1],[2,1.15,168.3]],"ltp":1.1,"tv":46850.26,"id":9629022}],"tv":48827.33}]}
{"op":"mcm","clk":"4228623516","pt":1631462820326,"mc":[{"id":"1.187551081","rc":[{"batb":[[0,8.2,14.23],[1,8,42.77],[2,7.8,2]],"ltp":9.6,"tv":1977.07,"id":7445998},{"batb":[[0,1.11,50],[1,1.1,586.82],[2,1.09,1254.56]],"batl":[[0,1.13,740.97],[1,1.14,330.72]],"ltp":1.1,"tv":46850.26,"id":9629022}]}]}
{"op":"mcm","clk":"4228624148","pt":1631462821601,"mc":[{"id":"1.187551081","rc":[{"batb":[[0,8,42.77],[1,7.8,2],[2,7.2,2]],"ltp":9.6,"tv":1977.07,"id":7445998},{"batb":[[0,1.1,246.44],[1,1.09,1254.56],[2,1.03,6.16]],"batl":[[0,1.13,294.52],[1,1.14,220.25]],"ltp":1.1,"tv":46850.26,"id":9629022}]}]}
{"op":"mcm","clk":"4228624896","pt":1631462823525,"mc":[{"id":"1.187551081","rc":[{"batl":[[0,10.5,16.35],[1,11,4],[2,17,57.15]],"ltp":9.6,"tv":1977.07,"id":7445998},{"batb":[[1,1.09,1275.56]],"ltp":1.1,"tv":46850.26,"id":9629022}]}]}
{"op":"mcm","clk":"4228625056","pt":1631462823901,"mc":[{"id":"1.187551081","rc":[{"batl":[[0,11,4],[1,17,57.15],[2,990,0.01]],"ltp":9.6,"tv":1977.07,"id":7445998},{"batb":[[1,1.09,2512.86]],"batl":[[1,1.14,1054.37]],"ltp":1.1,"tv":46850.26,"id":9629022}]}]}
{"op":"mcm","clk":"4228626200","pt":1631462828441,"mc":[{"id":"1.187551081","rc":[{"batl":[[0,10.5,2],[1,11,4],[2,17,57.15]],"ltp":9.6,"tv":1977.07,"id":7445998},{"batb":[[0,1.11,252.59],[1,1.1,246.44],[2,1.09,2512.86]],"ltp":1.1,"tv":46850.26,"id":9629022}]}]}
{"op":"mcm","clk":"4228626460","pt":1631462829427,"mc":[{"id":"1.187551081","rc":[{"trd":[[8.6,13.87]],"batb":[[0,8,40.77],[1,7.2,2],[2,3.35,373.95]],"batl":[[0,11,4],[1,17,57.15],[2,990,0.01]],"ltp":8.6,"tv":1978.09,"id":7445998},{"trd":[[1.13,1223.03]],"batb":[[0,1.1,246.44],[1,1.09,2512.86],[2,1.03,6.16]],"batl":[[0,1.14,14],[1,1.15,168.3],[2,1.16,147.22]],"ltp":1.13,"tv":46858.05,"id":9629022}],"tv":48836.14}]}
{"op":"mcm","clk":"4228627288","pt":1631462832115,"mc":[{"id":"1.187551081","rc":[{"batl":[[0,11,2],[1,990,0.01],[2,990,0]],"ltp":8.6,"tv":1978.09,"id":7445998},{"batb":[[0,1.1,236.44],[2,1.04,15.34]],"batl":[[0,1.11,771.93],[1,1.12,439.11],[2,1.13,14.12]],"ltp":1.13,"tv":46858.05,"id":9629022}]}]}
{"op":"mcm","clk":"4228627582","pt":1631462833071,"mc":[{"id":"1.187551081","rc":[{"batb":[[0,9.8,63.14],[1,8.2,38.18],[2,8,2]],"ltp":8.6,"tv":1978.09,"id":7445998},{"batb":[[2,1.06,1769.64]],"ltp":1.13,"tv":46858.05,"id":9629022}]}]}
{"op":"mcm","clk":"4228628000","pt":1631462833928,"mc":[{"id":"1.187551081","rc":[{"batl":[[0,1.11,821.93]],"ltp":1.13,"tv":46858.05,"id":9629022}]}]}
{"op":"mcm","clk":"4228628433","pt":1631462835444,"mc":[{"id":"1.187551081","rc":[{"batb":[[1,8.2,70.67]],"ltp":8.6,"tv":1978.09,"id":7445998},{"batb":[[0,1.1,319.18]],"batl":[[0,1.11,771.93],[2,1.13,98.12]],"ltp":1.13,"tv":46858.05,"id":9629022}]}]}
{"op":"mcm","clk":"4228628641","pt":1631462836128,"mc":[{"id":"1.187551081","rc":[{"batl":[[1,21,53.41],[2,990,0.01]],"ltp":8.6,"tv":1978.09,"id":7445998}]}]}
{"op":"mcm","clk":"4228628963","pt":1631462837134,"mc":[{"id":"1.187551081","rc":[{"trd":[[1.1,1602.68]],"batb":[[0,1.1,602.49]],"batl":[[0,1.11,1084.3]],"ltp":1.1,"tv":46921.85,"id":9629022}],"tv":48899.94}]}
{"op":"mcm","clk":"4228629422","pt":1631462838659,"mc":[{"id":"1.187551081","rc":[{"batb":[[0,10,45.6],[1,9.8,63.14],[2,9.2,53.02]],"batl":[[0,11,56.47],[1,12.5,48.85],[2,15.5,2]],"ltp":8.6,"tv":1978.09,"id":7445998},{"trd":[[1.1,1682.68]],"batb":[[0,1.1,1024.53],[1,1.09,3073.12],[2,1.07,349.07]],"batl":[[0,1.11,1495.1],[1,1.12,874.67],[2,1.13,118.12]],"ltp":1.1,"tv":47001.85,"id":9629022}],"tv":48979.94}]}
{"op":"mcm","clk":"4228630037","pt":1631462841325,"mc":[{"id":"1.187551081","rc":[{"trd":[[1.1,2240.42]],"batb":[[0,1.1,745.66]],"ltp":1.1,"tv":47559.59,"id":9629022}],"tv":49537.68}]}
{"op":"mcm","clk":"4228630255","pt":1631462842322,"mc":[{"id":"1.187551081","rc":[{"batl":[[2,1.13,98.12]],"ltp":1.1,"tv":47559.59,"id":9629022}]}]}
{"op":"mcm","clk":"4228630667","pt":1631462844607,"mc":[{"id":"1.187551081","rc":[{"trd":[[1.1,2260.42]],"batb":[[0,1.1,735.66]],"ltp":1.1,"tv":47579.59,"id":9629022}],"tv":49557.68}]}
{"op":"mcm","clk":"4228630878","pt":1631462845620,"mc":[{"id":"1.187551081","rc":[{"batb":[[0,1.1,810.13]],"ltp":1.1,"tv":47579.59,"id":9629022}]}]}
{"op":"mcm","clk":"4228631071","pt":1631462846539,"mc":[{"id":"1.187551081","rc":[{"trd":[[10,27.8]],"batb":[[0,10,43.7]],"ltp":10.0,"tv":1981.88,"id":7445998}],"tv":49561.48}]}
{"op":"mcm","clk":"4228631237","pt":1631462847529,"mc":[{"id":"1.187551081","rc":[{"trd":[[1.1,2270.4]],"batb":[[0,1.1,805.14]],"ltp":1.1,"tv":47589.57,"id":9629022}],"tv":49571.46}]}
{"op":"mcm","clk":"4228631799","pt":1631462850723,"mc":[{"id":"1.187551081","rc":[{"trd":[[1.1,2281.58]],"batb":[[0,1.1,799.55]],"ltp":1.1,"tv":47600.75,"id":9629022}],"tv":49582.64}]}
{"op":"mcm","clk":"4228632198","pt":1631462853120,"mc":[{"id":"1.187551081","rc":[{"trd":[[1.11,4639.68]],"batl":[[0,1.11,1490.1]],"ltp":1.11,"tv":47610.75,"id":9629022}],"tv":49592.64}]}
{"op":"mcm","clk":"4228632730","pt":1631462856249,"mc":[{"id":"1.187551081","rc":[{"trd":[[10,28.47]],"batb":[[0,10,43.36]],"ltp":10.0,"tv":1982.56,"id":7445998}],"tv":49593.32}]}
{"op":"mcm","clk":"4228633612","pt":1631462861642,"mc":[{"id":"1.187551081","rc":[{"batb":[[0,8.2,40.18],[1,7.6,2],[2,7.2,2]],"batl":[[0,15.5,2],[1,21,2],[2,990,0.01]],"ltp":10.0,"tv":1982.56,"id":7445998},{"batb":[[0,1.07,349.07],[1,1.06,2180.72],[2,1.05,533.49]],"batl":[[0,1.1,5],[1,1.15,168.3],[2,1.16,147.22]],"ltp":1.11,"tv":47610.75,"id":9629022}]}]}
{"op":"mcm","clk":"4228633645","pt":1631462861862,"mc":[{"id":"1.187551081","rc":[{"batl":[[0,21,2],[1,990,0.01],[2,990,0]],"ltp":10.0,"tv":1982.56,"id":7445998},{"batb":[[0,1.06,2180.72],[1,1.05,533.49],[2,1.03,6.16]],"ltp":1.11,"tv":47610.75,"id":9629022}]}]}
{"op":"mcm","clk":"4228633906","pt":1631462863546,"mc":[{"id":"1.187551081","rc":[{"batl":[[0,1.1,105]],"ltp":1.11,"tv":47610.75,"id":9629022}]}]}
{"op":"mcm","clk":"4228634252","pt":1631462865452,"mc":[{"id":"1.187551081","rc":[{"batb":[[1,8,2],[2,7.6,2]],"batl":[[0,18,2],[1,21,2],[2,990,0.01]],"ltp":10.0,"tv":1982.56,"id":7445998},{"batb":[[0,1.06,2186.72],[1,1.05,537.49]],"ltp":1.11,"tv":47610.75,"id":9629022}]}]}
{"op":"mcm","clk":"4228634447","pt":1631462866628,"mc":[{"id":"1.187551081","rc":[{"batb":[[0,1.09,658.02],[1,1.08,584.64],[2,1.06,2186.72]],"batl":[[0,1.1,358.28],[1,1.11,964.01],[2,1.15,168.3]],"ltp":1.11,"tv":47610.75,"id":9629022}]}]}
{"op":"mcm","clk":"4228634592","pt":1631462867516,"mc":[{"id":"1.187551081","rc":[{"batb":[[0,8.6,29.07],[1,8.2,40.18],[2,8,2]],"batl":[[0,13.5,10],[1,18,2],[2,21,2]],"ltp":10.0,"tv":1982.56,"id":7445998},{"batb":[[1,1.08,812.35]],"batl":[[2,1.13,20]],"ltp":1.11,"tv":47610.75,"id":9629022}]}]}
{"op":"mcm","clk":"4228634736","pt":1631462868617,"mc":[{"id":"1.187551081","rc":[{"batl":[[1,15.5,2],[2,18,2]],"ltp":10.0,"tv":1982.56,"id":7445998},{"batb":[[1,1.08,584.64],[2,1.07,326.07]],"ltp":1.11,"tv":47610.75,"id":9629022}]}]}
{"op":"mcm","clk":"4228635187","pt":1631462870965,"mc":[{"id":"1.187551081","rc":[{"batb":[[0,1.09,1258.9]],"batl":[[0,1.1,732.52]],"ltp":1.11,"tv":47610.75,"id":9629022}]}]}
{"op":"mcm","clk":"4228635610","pt":1631462873767,"mc":[{"id":"1.187551081","rc":[{"batb":[[0,1.09,600.88],[1,1.07,326.07],[2,1.06,2186.72]],"batl":[[0,1.1,479.24],[1,1.13,20],[2,1.15,168.3]],"ltp":1.11,"tv":47610.75,"id":9629022}]}]}
{"op":"mcm","clk":"4228636095","pt":1631462876532,"mc":[{"id":"1.187551081","rc":[{"batb":[[1,1.07,1280.33],[2,1.06,2495.77]],"batl":[[2,1.14,1016.8]],"ltp":1.11,"tv":47610.75,"id":9629022}]}]}
{"op":"mcm","clk":"4228636277","pt":1631462877635,"mc":[{"id":"1.187551081","rc":[{"batb":[[0,8.2,40.18],[1,7.6,2],[2,7.2,2]],"batl":[[0,15.5,2],[1,18,2],[2,21,2]],"ltp":10.0,"tv":1982.56,"id":7445998},{"batb":[[0,1.09,373.17]],"ltp":1.11,"tv":47610.75,"id":9629022}]}]}
{"op":"mcm","clk":"4228636310","pt":1631462877857,"mc":[{"id":"1.187551081","rc":[{"batb":[[0,1.07,1280.33],[1,1.06,2495.77],[2,1.05,533.49]],"batl":[[0,1.1,105]],"ltp":1.11,"tv":47610.75,"id":9629022}]}]}
{"op":"mcm","clk":"4228636468","pt":1631462878761,"mc":[{"id":"1.187551081","rc":[{"batl":[[0,1.1,105.19]],"ltp":1.11,"tv":47610.75,"id":9629022}]}]}
{"op":"mcm","clk":"4228637225","pt":1631462883057,"mc":[{"id":"1.187551081","rc":[{"batb":[[2,6.4,2]],"ltp":10.0,"tv":1982.56,"id":7445998},{"batl":[[0,1.1,105],[2,1.15,168.3]],"ltp":1.11,"tv":47610.75,"id":9629022}]}]}
{"op":"mcm","clk":"4228637816","pt":1631462886506,"mc":[{"id":"1.187551081","rc":[{"trd":[[13.5,1.38]],"batb":[[0,12.5,35],[1,12,4.42],[2,9.8,62.22]],"batl":[[0,15.5,4]],"ltp":13.5,"tv":1983.94,"id":7445998},{"trd":[[1.08,132.18]],"batb":[[0,1.07,1311.33]],"batl":[[0,1.08,331.41],[1,1.09,1015.36],[2,1.1,119.5]],"ltp":1.08,"tv":47627.97,"id":9629022}],"tv":49611.92}]}
{"op":"mcm","clk":"4228637984","pt":1631462887400,"mc":[{"id":"1.187551081","rc":[{"batl":[[0,15,8.48],[1,15.5,4],[2,18,2]],"ltp":13.5,"tv":1983.94,"id":7445998},{"batb":[[0,1.07,1448.19]],"batl":[[1,1.09,1122.54]],"ltp":1.08,"tv":47627.97,"id":9629022}]}]}
{"op":"mcm","clk":"4228638166","pt":1631462888595,"mc":[{"id":"1.187551081","rc":[{"batb":[[2,11.5,3]],"batl":[[0,15,10.48]],"ltp":13.5,"tv":1983.94,"id":7445998},{"batl":[[1,1.09,1143.54]],"ltp":1.08,"tv":47627.97,"id":9629022}]}]}
{"op":"mcm","clk":"4228638247","pt":1631462889200,"mc":[{"id":"1.187551081","rc":[{"batl":[[0,15,2]],"ltp":13.5,"tv":1983.94,"id":7445998},{"batl":[[2,1.1,114.5]],"ltp":1.08,"tv":47627.97,"id":9629022}]}]}
{"op":"mcm","clk":"4228638466","pt":1631462890459,"mc":[{"id":"1.187551081","rc":[{"batb":[[0,12.5,58.81]],"ltp":13.5,"tv":1983.94,"id":7445998},{"batb":[[0,1.07,1731.7]],"batl":[[0,1.08,463.57],[1,1.09,1452.92]],"ltp":1.08,"tv":47627.97,"id":9629022}]}]}
{"op":"mcm","clk":"4228638498","pt":1631462890705,"mc":[{"id":"1.187551081","rc":[{"batb":[[0,12.5,41.19]],"ltp":13.5,"tv":1983.94,"id":7445998},{"batl":[[0,1.08,331.41]],"ltp":1.08,"tv":47627.97,"id":9629022}]}]}
{"op":"mcm","clk":"4228638781","pt":1631462892406,"mc":[{"id":"1.187551081","rc":[{"batl":[[0,14.5,8.48],[1,15,2],[2,15.5,4]],"ltp":13.5,"tv":1983.94,"id":7445998},{"trd":[[1.07,1829.91]],"batb":[[0,1.07,1721.7]],"ltp":1.07,"tv":47647.97,"id":9629022}],"tv":49631.92}]}
{"op":"mcm","clk":"4228639100","pt":1631462894601,"mc":[{"id":"1.187551081","rc":[{"batb":[[0,12.5,35],[1,9.8,62.22],[2,9.2,2]],"batl":[[0,26,2],[1,55,2],[2,990,0.01]],"ltp":13.5,"tv":1983.94,"id":7445998},{"batb":[[0,1.06,1769.64],[1,1.04,565.37],[2,1.03,3542.58]],"batl":[[0,1.1,100],[1,1.12,211.46],[2,1.13,228.5]],"ltp":1.07,"tv":47647.97,"id":9629022}]}]}
{"op":"mcm","clk":"4228639174","pt":1631462895012,"mc":[{"id":"1.187551081","rc":[{"batb":[[0,9.8,62.22],[1,9.2,2],[2,8.2,2]],"batl":[[0,55,2],[1,990,0.01],[2,990,0]],"ltp":13.5,"tv":1983.94,"id":7445998},{"batb":[[0,1.03,3542.58],[1,1.02,1287.68],[2,1.03,0]],"ltp":1.07,"tv":47647.97,"id":9629022}]}]}
{"op":"mcm","clk":"4228639802","pt":1631462898518,"mc":[{"id":"1.187551081","rc":[{"batl":[[0,26,4],[1,36,2],[2,55,2]],"ltp":13.5,"tv":1983.94,"id":7445998},{"batb":[[0,1.04,45],[1,1.03,3608.58],[2,1.02,1374.68]],"ltp":1.07,"tv":47647.97,"id":9629022}]}]}
{"op":"mcm","clk":"4228639925","pt":1631462899294,"mc":[{"id":"1.187551081","rc":[{"batl":[[0,26,2]],"ltp":13.5,"tv":1983.94,"id":7445998},{"batb":[[0,1.06,1272.32],[1,1.04,45],[2,1.03,3608.58]],"batl":[[0,1.08,1096.02],[1,1.1,100],[2,1.12,211.46]],"ltp":1.07,"tv":47647.97,"id":9629022}]}]}
{"op":"mcm","clk":"4228640122","pt":1631462900517,"mc":[{"id":"1.187551081","rc":[{"batb":[[0,11,22.73],[1,9.8,62.22],[2,9.2,2]],"batl":[[0,17.5,10],[1,26,2],[2,36,2]],"ltp":13.5,"tv":1983.94,"id":7445998},{"batb":[[0,1.06,1490.83]],"batl":[[1,1.09,172.48],[2,1.1,100]],"ltp":1.07,"tv":47647.97,"id":9629022}]}]}
{"op":"mcm","clk":"4228640445","pt":1631462902312,"mc":[{"id":"1.187551081","rc":[{"batl":[[1,26,4]],"ltp":13.5,"tv":1983.94,"id":7445998},{"batb":[[1,1.04,701.12]],"ltp":1.07,"tv":47647.97,"id":9629022}]}]}
{"op":"mcm","clk":"4228640660","pt":1631462903692,"mc":[{"id":"1.187551081","rc":[{"batb":[[0,1.06,1828.58]],"batl":[[0,1.08,1444.7]],"ltp":1.07,"tv":47647.97,"id":9629022}]}]}
{"op":"mcm","clk":"4228641197","pt":1631462906532,"mc":[{"id":"1.187551081","rc":[{"batb":[[0,9.8,62.22],[1,9.2,2],[2,8.2,2]],"batl":[[0,26,4],[1,36,2],[2,55,2]],"ltp":13.5,"tv":1983.94,"id":7445998},{"batb":[[0,1.04,701.12],[1,1.03,3608.58],[2,1.02,1374.68]],"batl":[[0,1.1,100],[1,1.12,211.46],[2,1.13,228.5]],"ltp":1.07,"tv":47647.97,"id":9629022}]}]}
{"op":"mcm","clk":"4228641229","pt":1631462906715,"mc":[{"id":"1.187551081","rc":[{"batl":[[0,26,2]],"ltp":13.5,"tv":1983.94,"id":7445998},{"batb":[[0,1.04,45]],"ltp":1.07,"tv":47647.97,"id":9629022}]}]}
{"op":"mcm","clk":"4228641812","pt":1631462909618,"mc":[{"id":"1.187551081","rc":[{"batb":[[0,1.05,624.03],[1,1.04,711.75],[2,1.03,3542.58]],"batl":[[1,1.11,904.47],[2,1.12,519.22]],"ltp":1.07,"tv":47647.97,"id":9629022}]}]}
{"op":"mcm","clk":"4228641954","pt":1631462910216,"mc":[{"id":"1.187551081","rc":[{"batl":[[0,26,4],[1,55,2],[2,990,0.01]],"ltp":13.5,"tv":1983.94,"id":7445998},{"batb":[[1,1.04,1257.37]],"ltp":1.07,"tv":47647.97,"id":9629022}]}]}
{"op":"mcm","clk":"4228643674","pt":1631462918953,"mc":[{"id":"1.187551081","rc":[{"batb":[[0,1.04,590.62],[1,1.03,3542.58],[2,1.02,1287.68]],"ltp":1.07,"tv":47647.97,"id":9629022}]}]}
{"op":"mcm","clk":"4228644332","pt":1631462922510,"mc":[{"id":"1.187551081","rc":[{"batb":[[0,9.8,68.87]],"batl":[[0,13,18.47],[1,26,4],[2,55,2]],"ltp":13.5,"tv":1983.94,"id":7445998},{"batb":[[0,1.09,1181.14],[1,1.08,1496.43],[2,1.05,1892.06]],"batl":[[2,1.12,533.47]],"ltp":1.07,"tv":47647.97,"id":9629022}]}]}
{"op":"mcm","clk":"4228644402","pt":1631462922871,"mc":[{"id":"1.187551081","rc":[{"batb":[[1,1.08,1264.95]],"ltp":1.07,"tv":47647.97,"id":9629022}]}]}
{"op":"mcm","clk":"4228644951","pt":1631462925318,"mc":[{"id":"1.187551081","rc":[{"batl":[[0,12,2],[1,25,2],[2,26,4]],"ltp":13.5,"tv":1983.94,"id":7445998}]}]}
{"op":"mcm","clk":"4228645196","pt":1631462926512,"mc":[{"id":"1.187551081","rc":[{"batl":[[1,14.5,45.12],[2,25,2]],"ltp":13.5,"tv":1983.94,"id":7445998},{"trd":[[1.1,2551.54]],"batb":[[0,1.1,18.77],[1,1.09,1460.11],[2,1.08,1264.95]],"batl":[[0,1.11,1208.74],[1,1.12,533.47],[2,1.13,228.5]],"ltp":1.1,"tv":47917.93,"id":9629022}],"tv":49901.88}]}
{"op":"mcm","clk":"4228645422","pt":1631462927613,"mc":[{"id":"1.187551081","rc":[{"batb":[[0,9.8,62.22]],"batl":[[1,25,2],[2,26,4]],"ltp":13.5,"tv":1983.94,"id":7445998},{"batl":[[2,1.13,208.5]],"ltp":1.1,"tv":47917.93,"id":9629022}]}]}
{"op":"mcm","clk":"4228645592","pt":1631462928417,"mc":[{"id":"1.187551081","rc":[{"batl":[[0,11.5,18.47],[1,12,2],[2,18,2]],"ltp":13.5,"tv":1983.94,"id":7445998}]}]}
{"op":"mcm","clk":"4228645826","pt":1631462929423,"mc":[{"id":"1.187551081","rc":[{"batl":[[0,12,2],[1,18,2],[2,25,2]],"ltp":13.5,"tv":1983.94,"id":7445998}]}]}
{"op":"mcm","clk":"4228645980","pt":1631462930046,"mc":[{"id":"1.187551081","rc":[{"batb":[[0,10,6.65],[1,9.8,62.22],[2,9.2,2]],"ltp":13.5,"tv":1983.94,"id":7445998},{"trd":[[1.1,2561.54]],"batb":[[0,1.1,13.77]],"ltp":1.1,"tv":47927.93,"id":9629022}],"tv":49911.88}]}
{"op":"mcm","clk":"4228647251","pt":1631462935645,"mc":[{"id":"1.187551081","rc":[{"batl":[[0,11.5,8.98],[1,12,2],[2,18,2]],"ltp":13.5,"tv":1983.94,"id":7445998}]}]}
{"op":"mcm","clk":"4228648031","pt":1631462939293,"mc":[{"id":"1.187551081","rc":[{"batl":[[1,1.12,519.22]],"ltp":1.1,"tv":47927.93,"id":9629022}]}]}
{"op":"mcm","clk":"4228648779","pt":1631462942466,"mc":[{"id":"1.187551081","rc":[{"batb":[[0,8.2,2],[1,8,41.11],[2,7.6,2]],"batl":[[0,18,2],[1,26,2],[2,36,2]],"ltp":13.5,"tv":1983.94,"id":7445998},{"batb":[[0,1.06,393.08],[1,1.05,2335.59],[2,1.04,590.62]],"batl":[[0,1.14,188.25],[1,1.15,188.3],[2,1.16,136.97]],"ltp":1.1,"tv":47927.93,"id":9629022}]}]}
{"op":"mcm","clk":"4228648852","pt":1631462942807,"mc":[{"id":"1.187551081","rc":[{"batb":[[1,8,39.11]],"batl":[[0,26,2],[1,36,2],[2,55,2]],"ltp":13.5,"tv":1983.94,"id":7445998},{"batb":[[0,1.05,2335.59],[1,1.04,590.62],[2,1.03,781.99]],"batl":[[0,1.15,188.3],[1,1.16,136.97],[2,1.17,140.5]],"ltp":1.1,"tv":47927.93,"id":9629022}]}]}
{"op":"mcm","clk":"4228649430","pt":1631462945595,"mc":[{"id":"1.187551081","rc":[{"batb":[[0,1.06,1272.32],[1,1.05,2335.59],[2,1.04,590.62]],"batl":[[0,1.14,787.49],[1,1.15,580.39],[2,1.16,136.97]],"ltp":1.1,"tv":47927.93,"id":9629022}]}]}
{"op":"mcm","clk":"4228649521","pt":1631462946059,"mc":[{"id":"1.187551081","rc":[{"batb":[[1,8,43.11]],"batl":[[0,18,4],[1,21,2],[2,26,2]],"ltp":13.5,"tv":1983.94,"id":7445998},{"batb":[[0,1.06,1718.4],[1,1.05,2381.59]],"batl":[[0,1.14,977.24],[1,1.15,598.39]],"ltp":1.1,"tv":47927.93,"id":9629022}]}]}
{"op":"mcm","clk":"4228649714","pt":1631462947080,"mc":[{"id":"1.187551081","rc":[{"batb":[[1,8,41.11],[2,7.2,2]],"batl":[[0,18,2]],"ltp":13.5,"tv":1983.94,"id":7445998},{"batb":[[0,1.06,29]],"batl":[[0,1.14,14],[1,1.15,38]],"ltp":1.1,"tv":47927.93,"id":9629022}]}]}
{"op":"mcm","clk":"4228650186","pt":1631462949575,"mc":[{"id":"1.187551081","rc":[{"batl":[[0,1.11,1606.63],[1,1.14,14],[2,1.15,38]],"ltp":1.1,"tv":47927.93,"id":9629022}]}]}
{"op":"mcm","clk":"4228650383","pt":1631462950585,"mc":[{"id":"1.187551081","rc":[{"batb":[[1,8,43.11]],"batl":[[0,18,4]],"ltp":13.5,"tv":1983.94,"id":7445998},{"batb":[[0,1.06,445.08]],"batl":[[0,1.14,200.75],[1,1.15,218.3],[2,1.16,136.97]],"ltp":1.1,"tv":47927.93,"id":9629022}]}]}
{"op":"mcm","clk":"4228650502","pt":1631462951198,"mc":[{"id":"1.187551081","rc":[{"batb":[[1,8,41.11]],"batl":[[0,18,2]],"ltp":13.5,"tv":1983.94,"id":7445998},{"batb":[[0,1.06,29]],"batl":[[0,1.14,14],[1,1.15,38]],"ltp":1.1,"tv":47927.93,"id":9629022}]}]}
{"op":"mcm","clk":"4228650909","pt":1631462953161,"mc":[{"id":"1.187551081","rc":[{"batb":[[0,1.06,1301.32]],"batl":[[0,1.14,801.49],[1,1.15,430.09]],"ltp":1.1,"tv":47927.93,"id":9629022}]}]}
{"op":"mcm","clk":"4228651100","pt":1631462954169,"mc":[{"id":"1.187551081","rc":[{"batb":[[1,8,43.11]],"batl":[[0,18,4]],"ltp":13.5,"tv":1983.94,"id":7445998},{"batb":[[0,1.06,1673.4]],"batl":[[0,1.14,993.43],[1,1.15,597.99]],"ltp":1.1,"tv":47927.93,"id":9629022}]}]}
{"op":"mcm","clk":"4228651317","pt":1631462955350,"mc":[{"id":"1.187551081","rc":[{"batl":[[0,1.14,205.94],[1,1.15,205.9]],"ltp":1.1,"tv":47927.93,"id":9629022}]}]}
{"op":"mcm","clk":"4228651375","pt":1631462955678,"mc":[{"id":"1.187551081","rc":[{"batb":[[1,8,41.11]],"ltp":13.5,"tv":1983.94,"id":7445998},{"batl":[[0,1.14,14.19],[1,1.15,38]],"ltp":1.1,"tv":47927.93,"id":9629022}]}]}
{"op":"mcm","clk":"4228651868","pt":1631462958300,"mc":[{"id":"1.187551081","rc":[{"batb":[[0,13.5,4.4],[1,8.2,2],[2,8,39.11]],"batl":[[1,26,2],[2,36,2]],"ltp":13.5,"tv":1983.94,"id":7445998},{"batb":[[1,1.05,2335.59],[2,1.04,545.62]],"batl":[[0,1.08,1301.26],[1,1.1,14.7],[2,1.12,7.12]],"ltp":1.1,"tv":47927.93,"id":9629022}]}]}
{"op":"mcm","clk":"4228652077","pt":1631462959387,"mc":[{"id":"1.187551081","rc":[{"batb":[[1,13,31.49],[2,10,60.04]],"ltp":13.5,"tv":1983.94,"id":7445998}]}]}
{"op":"mcm","clk":"4228652224","pt":1631462960082,"mc":[{"id":"1.187551081","rc":[{"batl":[[0,17.5,11.78],[1,18,4],[2,26,2]],"ltp":13.5,"tv":1983.94,"id":7445998},{"batb":[[0,1.07,67.48],[1,1.06,1673.4],[2,1.05,2335.59]],"ltp":1.1,"tv":47927.93,"id":9629022}]}]}
{"op":"mcm","clk":"4228652477","pt":1631462961363,"mc":[{"id":"1.187551081","rc":[{"batl":[[0,17.5,2]],"ltp":13.5,"tv":1983.94,"id":7445998}]}]}
{"op":"mcm","clk":"4228652696","pt":1631462962549,"mc":[{"id":"1.187551081","rc":[{"batb":[[1,1.06,1919.98]],"batl":[[0,1.08,1585.51]],"ltp":1.1,"tv":47927.93,"id":9629022}]}]}
{"op":"mcm","clk":"4228652840","pt":1631462963313,"mc":[{"id":"1.187551081","rc":[{"batb":[[0,13.5,14.4]],"batl":[[0,17,2],[1,17.5,2],[2,18,4]],"ltp":13.5,"tv":1983.94,"id":7445998},{"batl":[[0,1.08,1656.46]],"ltp":1.1,"tv":47927.93,"id":9629022}]}]}
{"op":"mcm","clk":"4228653095","pt":1631462964598,"mc":[{"id":"1.187551081","rc":[{"batl":[[0,17,13.78]],"ltp":13.5,"tv":1983.94,"id":7445998}]}]}
{"op":"mcm","clk":"4228653106","pt":1631462964699,"mc":[{"id":"1.187551081","rc":[{"batl":[[0,17,2]],"ltp":13.5,"tv":1983.94,"id":7445998}]}]}
{"op":"mcm","clk":"4228653329","pt":1631462965798,"mc":[{"id":"1.187551081","rc":[{"batb":[[2,10,62.04]],"ltp":13.5,"tv":1983.94,"id":7445998},{"batl":[[2,1.11,211.5]],"ltp":1.1,"tv":47927.93,"id":9629022}]}]}
{"op":"mcm","clk":"4228653600","pt":1631462967086,"mc":[{"id":"1.187551081","rc":[{"trd":[[13.5,4.8]],"batb":[[0,13.5,12.69]],"ltp":13.5,"tv":1987.36,"id":7445998}],"tv":49915.29}]}
{"op":"mcm","clk":"4228653761","pt":1631462967816,"mc":[{"id":"1.187551081","rc":[{"batl":[[0,16.5,11.78],[1,17,2],[2,17.5,2]],"ltp":13.5,"tv":1987.36,"id":7445998}]}]}
{"op":"mcm","clk":"4228654620","pt":1631462972504,"mc":[{"id":"1.187551081","rc":[{"batb":[[0,10,62.04],[1,8.6,2],[2,8.4,2]],"batl":[[0,17,2],[1,36,2],[2,55,2]],"ltp":13.5,"tv":1987.36,"id":7445998},{"trd":[[1.07,1881.16]],"batb":[[0,1.06,29],[1,1.04,3424.72],[2,1.03,4083.19]],"batl":[[0,1.11,211.69],[1,1.12,208.71],[2,1.13,234.5]],"ltp":1.07,"tv":47979.17,"id":9629022}],"tv":49966.54}]}
{"op":"mcm","clk":"4228654779","pt":1631462973297,"mc":[{"id":"1.187551081","rc":[{"batb":[[0,10,60.04]],"batl":[[0,36,2],[1,55,2],[2,990,0.01]],"ltp":13.5,"tv":1987.36,"id":7445998},{"batb":[[0,1.04,3424.72],[1,1.03,4083.19],[2,1.02,1287.68]],"batl":[[0,1.12,208.9],[1,1.13,234.5],[2,1.15,20]],"ltp":1.07,"tv":47979.17,"id":9629022}]}]}
{"op":"mcm","clk":"4228655179","pt":1631462975566,"mc":[{"id":"1.187551081","rc":[{"batb":[[0,13.5,3],[1,13,2],[2,10,60.04]],"batl":[[0,16.5,2],[1,36,2],[2,55,2]],"ltp":13.5,"tv":1987.36,"id":7445998},{"batl":[[0,1.08,24],[1,1.13,234.69]],"ltp":1.07,"tv":47979.17,"id":9629022}]}]}
{"op":"mcm","clk":"4228655339","pt":1631462976488,"mc":[{"id":"1.187551081","rc":[{"batb":[[0,10,60.04],[1,8.6,2],[2,8.4,2]],"batl":[[0,26,2]],"ltp":13.5,"tv":1987.36,"id":7445998},{"batb":[[0,1.04,3483.72],[1,1.03,4156.19]],"batl":[[0,1.12,17.19],[1,1.13,234.5]],"ltp":1.07,"tv":47979.17,"id":9629022}]}]}
{"op":"mcm","clk":"4228655542","pt":1631462977523,"mc":[{"id":"1.187551081","rc":[{"batb":[[0,1.06,1048.94],[1,1.05,225.5],[2,1.04,3483.72]],"batl":[[0,1.07,528.13],[1,1.08,725.51],[2,1.12,17.19]],"ltp":1.07,"tv":47979.17,"id":9629022}]}]}
{"op":"mcm","clk":"4228655712","pt":1631462978321,"mc":[{"id":"1.187551081","rc":[{"batb":[[0,12.5,20],[1,10,60.04],[2,8.6,2]],"batl":[[0,19.5,10],[1,26,2],[2,36,2]],"ltp":13.5,"tv":1987.36,"id":7445998},{"batl":[[2,1.09,229.36]],"ltp":1.07,"tv":47979.17,"id":9629022}]}]}
{"op":"mcm","clk":"4228655981","pt":1631462979603,"mc":[{"id":"1.187551081","rc":[{"trd":[[1.07,1901.16]],"batl":[[0,1.07,518.13]],"ltp":1.07,"tv":47999.17,"id":9629022}],"tv":49986.54}]}
{"op":"mcm","clk":"4228656168","pt":1631462980477,"mc":[{"id":"1.187551081","rc":[{"batb":[[1,10,62.04]],"ltp":13.5,"tv":1987.36,"id":7445998}]}]}
{"op":"mcm","clk":"4228656360","pt":1631462981484,"mc":[{"id":"1.187551081","rc":[{"batb":[[0,1.06,1562.34]],"batl":[[1,1.08,1030.06]],"ltp":1.07,"tv":47999.17,"id":9629022}]}]}
{"op":"mcm","clk":"4228656871","pt":1631462984428,"mc":[{"id":"1.187551081","rc":[{"batb":[[0,1.06,513.4],[1,1.04,3483.72],[2,1.03,4156.19]],"batl":[[0,1.08,304.55],[1,1.09,229.36],[2,1.11,233.69]],"ltp":1.07,"tv":47999.17,"id":9629022}]}]}
{"op":"mcm","clk":"4228656988","pt":1631462984999,"mc":[{"id":"1.187551081","rc":[{"batl":[[0,1.11,233.69],[1,1.12,219.21],[2,1.13,234.5]],"ltp":1.07,"tv":47999.17,"id":9629022}]}]}
{"op":"mcm","clk":"4228657226","pt":1631462986214,"mc":[{"id":"1.187551081","rc":[{"batb":[[0,10,60.04],[1,8.6,2],[2,8.4,2]],"batl":[[0,26,2],[1,36,2],[2,55,2]],"ltp":13.5,"tv":1987.36,"id":7445998},{"batb":[[0,1.04,3483.72],[1,1.03,4156.19],[2,1.02,1287.68]],"batl":[[0,1.11,10.19]],"ltp":1.07,"tv":47999.17,"id":9629022}]}]}
{"op":"mcm","clk":"4228657416","pt":1631462987288,"mc":[{"id":"1.187551081","rc":[{"batb":[[0,1.04,4780.51]],"batl":[[0,1.11,1077.94]],"ltp":1.07,"tv":47999.17,"id":9629022}]}]}
{"op":"mcm","clk":"4228657620","pt":1631462988510,"mc":[{"id":"1.187551081","rc":[{"batb":[[1,1.03,4083.19]],"batl":[[2,1.13,217.5]],"ltp":1.07,"tv":47999.17,"id":9629022}]}]}
{"op":"mcm","clk":"4228657774","pt":1631462989418,"mc":[{"id":"1.187551081","rc":[{"batb":[[0,10,62.04]],"ltp":13.5,"tv":1987.36,"id":7445998},{"batb":[[0,1.04,1355.79]],"batl":[[0,1.11,1286.44]],"ltp":1.07,"tv":47999.17,"id":9629022}]}]}
{"op":"mcm","clk":"4228658098","pt":1631462991048,"mc":[{"id":"1.187551081","rc":[{"batb":[[0,1.07,4.51],[1,1.04,1355.79],[2,1.03,4083.19]],"ltp":1.07,"tv":47999.17,"id":9629022}]}]}
{"op":"mcm","clk":"4228658352","pt":1631462992283,"mc":[{"id":"1.187551081","rc":[{"batb":[[2,1.03,4164.19]],"ltp":1.07,"tv":47999.17,"id":9629022}]}]}
{"op":"mcm","clk":"4228658946","pt":1631462995226,"mc":[{"id":"1.187551081","rc":[{"batb":[[1,1.04,1365.79]],"ltp":1.07,"tv":47999.17,"id":9629022}]}]}
{"op":"mcm","clk":"4228659160","pt":1631462996185,"mc":[{"id":"1.187551081","rc":[{"batb":[[0,1.04,1365.79],[1,1.03,4164.19],[2,1.02,4712.4]],"ltp":1.07,"tv":47999.17,"id":9629022}]}]}
{"op":"mcm","clk":"4228659329","pt":1631462997116,"mc":[{"id":"1.187551081","rc":[{"batb":[[0,10,60.04]],"ltp":13.5,"tv":1987.36,"id":7445998},{"batl":[[0,1.11,10.19]],"ltp":1.07,"tv":47999.17,"id":9629022}]}]}
{"op":"mcm","clk":"4228659801","pt":1631462999603,"mc":[{"id":"1.187551081","rc":[{"batb":[[0,21,2.62],[1,10,60.04],[2,8.6,2]],"ltp":13.5,"tv":1987.36,"id":7445998},{"batl":[[0,1.05,1320.5],[1,1.07,5],[2,1.08,14.77]],"ltp":1.07,"tv":47999.17,"id":9629022}]}]}
{"op":"mcm","clk":"4228659966","pt":1631463000532,"mc":[{"id":"1.187551081","rc":[{"batb":[[1,20,24.54],[2,15,23.95]],"ltp":13.5,"tv":1987.36,"id":7445998}]}]}
{"op":"mcm","clk":"4228660178","pt":1631463001551,"mc":[{"id":"1.187551081","rc":[{"batb":[[2,18,13.89]],"batl":[[0,25,3.76],[1,26,2],[2,36,2]],"ltp":13.5,"tv":1987.36,"id":7445998},{"batb":[[0,1.04,1493.38]],"batl":[[1,1.06,50.95],[2,1.07,5]],"ltp":1.07,"tv":47999.17,"id":9629022}]}]}
{"op":"mcm","clk":"4228660348","pt":1631463002440,"mc":[{"id":"1.187551081","rc":[{"batb":[[2,18,2]],"ltp":13.5,"tv":1987.36,"id":7445998},{"batl":[[1,1.07,5],[2,1.08,14.77]],"ltp":1.07,"tv":47999.17,"id":9629022}]}]}
{"op":"mcm","clk":"4228660742","pt":1631463004626,"mc":[{"id":"1.187551081","rc":[{"batl":[[2,32,20.99]],"ltp":13.5,"tv":1987.36,"id":7445998},{"batb":[[2,1.02,1287.68]],"batl":[[0,1.05,1590.99]],"ltp":1.07,"tv":47999.17,"id":9629022}]}]}
{"op":"mcm","clk":"4228660880","pt":1631463005265,"mc":[{"id":"1.187551081","rc":[{"batb":[[0,21,7.28]],"batl":[[2,36,2]],"ltp":13.5,"tv":1987.36,"id":7445998},{"batb":[[0,1.04,1769.09],[1,1.03,4083.19]],"batl":[[0,1.05,1413.6],[1,1.06,306.84]],"ltp":1.07,"tv":47999.17,"id":9629022}]}]}
{"op":"mcm","clk":"4228661108","pt":1631463006505,"mc":[{"id":"1.187551081","rc":[{"batl":[[2,1.07,354.5]],"ltp":1.07,"tv":47999.17,"id":9629022}]}]}
{"op":"mcm","clk":"4228661307","pt":1631463007537,"mc":[{"id":"1.187551081","rc":[{"batb":[[1,1.03,4436.79]],"batl":[[0,1.05,1776.49]],"ltp":1.07,"tv":47999.17,"id":9629022}]}]}
{"op":"mcm","clk":"4228661499","pt":1631463008616,"mc":[{"id":"1.187551081","rc":[{"trd":[[1.04,3775.01]],"batb":[[0,1.04,1489.59]],"ltp":1.04,"tv":48558.17,"id":9629022}],"tv":50545.54}]}
{"op":"mcm","clk":"4228661665","pt":1631463009525,"mc":[{"id":"1.187551081","rc":[{"batb":[[0,21,2.62]],"ltp":13.5,"tv":1987.36,"id":7445998},{"batb":[[0,1.04,1479.59]],"ltp":1.04,"tv":48558.17,"id":9629022}]}]}
{"op":"mcm","clk":"4228661708","pt":1631463009746,"mc":[{"id":"1.187551081","rc":[{"trd":[[21,3.42]],"batb":[[0,20,25.45],[1,18,2],[2,17.5,3]],"ltp":21.0,"tv":1990.78,"id":7445998}],"tv":50548.95}]}
{"op":"mcm","clk":"4228661995","pt":1631463011374,"mc":[{"id":"1.187551081","rc":[{"trd":[[1.05,2630.47]],"batl":[[0,1.05,1771.49]],"ltp":1.05,"tv":48568.17,"id":9629022}],"tv":50558.95}]}
{"op":"mcm","clk":"4228662195","pt":1631463012650,"mc":[{"id":"1.187551081","rc":[{"batb":[[0,22,4.66],[1,20,25.45],[2,18,2]],"ltp":21.0,"tv":1990.78,"id":7445998},{"batb":[[0,1.04,1593.13],[1,1.03,4441.79]],"batl":[[0,1.05,1889.93]],"ltp":1.05,"tv":48568.17,"id":9629022}]}]}
{"op":"mcm","clk":"4228662260","pt":1631463012972,"mc":[{"id":"1.187551081","rc":[{"batb":[[0,20,25.45],[1,18,2],[2,17.5,3]],"ltp":21.0,"tv":1990.78,"id":7445998},{"batb":[[0,1.04,1644.13],[1,1.03,4504.79]],"ltp":1.05,"tv":48568.17,"id":9629022}]}]}
{"op":"mcm","clk":"4228662772","pt":1631463015581,"mc":[{"id":"1.187551081","rc":[{"batb":[[0,18,2],[1,15,25.95],[2,12,2]],"batl":[[0,26,2],[1,95,39.2],[2,110,2]],"ltp":21.0,"tv":1990.78,"id":7445998},{"batb":[[0,1.04,51],[1,1.03,74.16],[2,1.01,2465.37]],"batl":[[0,1.07,354.5],[1,1.08,348.96],[2,1.09,271.5]],"ltp":1.05,"tv":48568.17,"id":9629022}]}]}
{"op":"mcm","clk":"4228662967","pt":1631463016648,"mc":[{"id":"1.187551081","rc":[{"batb":[[0,15,23.95],[1,12,2],[2,4.2,376.32]],"batl":[[0,95,39.2],[1,110,2],[2,990,0.01]],"ltp":21.0,"tv":1990.78,"id":7445998},{"batb":[[0,1.03,11.16],[1,1.01,2465.37],[2,1.01,0]],"batl":[[0,1.09,271.5],[1,1.1,22.19],[2,1.11,10]],"ltp":1.05,"tv":48568.17,"id":9629022}]}]}
{"op":"mcm","clk":"4228663327","pt":1631463018664,"mc":[{"id":"1.187551081","rc":[{"batb":[[0,1.05,2.89],[1,1.03,11.16],[2,1.02,1322.21]],"batl":[[0,1.07,1277.88],[1,1.09,271.5],[2,1.1,22.19]],"ltp":1.05,"tv":48568.17,"id":9629022}]}]}
{"op":"mcm","clk":"4228663446","pt":1631463019243,"mc":[{"id":"1.187551081","rc":[{"batb":[[0,15,27.95],[1,14.5,3],[2,12,2]],"batl":[[0,95,41.2]],"ltp":21.0,"tv":1990.78,"id":7445998},{"batl":[[0,1.07,1655.38],[1,1.08,314.44],[2,1.09,282.5]],"ltp":1.05,"tv":48568.17,"id":9629022}]}]}
{"op":"mcm","clk":"4228663878","pt":1631463021572,"mc":[{"id":"1.187551081","rc":[{"batb":[[2,1.02,1342.21]],"ltp":1.05,"tv":48568.17,"id":9629022}]}]}
{"op":"mcm","clk":"4228663967","pt":1631463022058,"mc":[{"id":"1.187551081","rc":[{"batb":[[1,1.03,6.16]],"ltp":1.05,"tv":48568.17,"id":9629022}]}]}
{"op":"mcm","clk":"4228664662","pt":1631463025583,"mc":[{"id":"1.187551081","rc":[{"trd":[[1.05,2636.25]],"batb":[[0,1.03,6.16],[1,1.02,1342.21],[2,1.01,2465.37]],"batl":[[0,1.06,20],[1,1.07,410.5],[2,1.08,314.44]],"ltp":1.05,"tv":48573.95,"id":9629022}],"tv":50564.74}]}
{"op":"mcm","clk":"4228664755","pt":1631463026072,"mc":[{"id":"1.187551081","rc":[{"batl":[[0,95,2]],"ltp":21.0,"tv":1990.78,"id":7445998}]}]}
{"op":"mcm","clk":"4228665254","pt":1631463028584,"mc":[{"id":"1.187551081","rc":[{"batb":[[0,34,2],[1,15,27.95],[2,14.5,3]],"batl":[[0,55,2],[1,95,2],[2,110,2]],"ltp":21.0,"tv":1990.78,"id":7445998},{"trd":[[1.03,6488.48]],"batb":[[0,1.02,1342.21],[1,1.01,2465.37],[2,1.01,0]],"batl":[[0,1.03,1432.71],[1,1.06,35.05],[2,1.07,410.5]],"ltp":1.03,"tv":48586.27,"id":9629022}],"tv":50577.05}]}
{"op":"mcm","clk":"4228665449","pt":1631463029551,"mc":[{"id":"1.187551081","rc":[{"batb":[[0,34,9.35],[1,30,8.71],[2,20,23.87]],"batl":[[0,55,6.48]],"ltp":21.0,"tv":1990.78,"id":7445998},{"batl":[[1,1.04,100],[2,1.06,35.05]],"ltp":1.03,"tv":48586.27,"id":9629022}]}]}
{"op":"mcm","clk":"4228665636","pt":1631463030569,"mc":[{"id":"1.187551081","rc":[{"batl":[[1,1.06,35.05],[2,1.07,410.5]],"ltp":1.03,"tv":48586.27,"id":9629022}]}]}
{"op":"mcm","clk":"4228665788","pt":1631463031291,"mc":[{"id":"1.187551081","rc":[{"batl":[[0,50,2],[1,55,2],[2,95,2]],"ltp":21.0,"tv":1990.78,"id":7445998},{"batb":[[0,1.02,1519.51]],"batl":[[2,1.07,377.5]],"ltp":1.03,"tv":48586.27,"id":9629022}]}]}
{"op":"mcm","clk":"4228666029","pt":1631463032375,"mc":[{"id":"1.187551081","rc":[{"batb":[[0,34,34.52],[2,26,37.37]],"ltp":21.0,"tv":1990.78,"id":7445998},{"batl":[[0,1.03,2263.69],[1,1.04,934.32],[2,1.06,35.05]],"ltp":1.03,"tv":48586.27,"id":9629022}]}]}
{"op":"mcm","clk":"4228666292","pt":1631463033613,"mc":[{"id":"1.187551081","rc":[{"batl":[[1,55,19.48]],"ltp":21.0,"tv":1990.78,"id":7445998},{"batb":[[0,1.02,2945.54],[1,1.01,4146.98]],"batl":[[0,1.03,2984.89]],"ltp":1.03,"tv":48586.27,"id":9629022}]}]}
{"op":"mcm","clk":"4228666447","pt":1631463034362,"mc":[{"id":"1.187551081","rc":[{"batl":[[0,48,4.48],[1,50,2],[2,55,19.48]],"ltp":21.0,"tv":1990.78,"id":7445998}]}]}
{"op":"mcm","clk":"4228666673","pt":1631463035601,"mc":[{"id":"1.187551081","rc":[{"batb":[[0,1.02,2935.54]],"ltp":1.03,"tv":48586.27,"id":9629022}]}]}
{"op":"mcm","clk":"4228666851","pt":1631463036475,"mc":[{"id":"1.187551081","rc":[{"trd":[[1.02,949.02]],"batb":[[0,1.02,2881.29]],"ltp":1.02,"tv":48694.77,"id":9629022}],"tv":50685.55}]}
{"op":"mcm","clk":"4228667013","pt":1631463037380,"mc":[{"id":"1.187551081","rc":[{"batl":[[0,1.03,3152.29],[2,1.06,15.05]],"ltp":1.02,"tv":48694.77,"id":9629022}]}]}
{"op":"mcm","clk":"4228667248","pt":1631463038655,"mc":[{"id":"1.187551081","rc":[{"trd":[[48,0.42]],"batl":[[0,50,2],[1,55,19.48],[2,95,2]],"ltp":48.0,"tv":1991.2,"id":7445998},{"trd":[[1.03,6541.72]],"batl":[[0,1.03,3125.67]],"ltp":1.03,"tv":48748.01,"id":9629022}],"tv":50739.21}]}
{"op":"mcm","clk":"4228667439","pt":1631463039783,"mc":[{"id":"1.187551081","rc":[{"batb":[[0,1.02,2935.54]],"ltp":1.03,"tv":48748.01,"id":9629022}]}]}
{"op":"mcm","clk":"4228667719","pt":1631463041391,"mc":[{"id":"1.187551081","rc":[{"batl":[[0,1.03,3158.45]],"ltp":1.03,"tv":48748.01,"id":9629022}]}]}
{"op":"mcm","clk":"4228667844","pt":1631463041984,"mc":[{"id":"1.187551081","rc":[{"batl":[[1,55,17.48],[2,110,17.43]],"ltp":48.0,"tv":1991.2,"id":7445998}]}]}
{"op":"mcm","clk":"4228668153","pt":1631463043602,"mc":[{"id":"1.187551081","rc":[{"trd":[[1.02,1537.71]],"batb":[[0,1.02,2641.19]],"batl":[[0,1.03,2991.05]],"ltp":1.02,"tv":49336.71,"id":9629022}],"tv":51327.91}]}
{"op":"mcm","clk":"4228668452","pt":1631463045063,"mc":[{"id":"1.187551081","rc":[{"batl":[[0,48,4.27],[1,50,2],[2,55,17.48]],"ltp":48.0,"tv":1991.2,"id":7445998}]}]}
{"op":"mcm","clk":"4228668706","pt":1631463046597,"mc":[{"id":"1.187551081","rc":[{"trd":[[1.02,1872.5]],"batb":[[0,1.02,2768.15]],"ltp":1.02,"tv":49671.49,"id":9629022}],"tv":51662.69}]}
{"op":"mcm","clk":"4228669154","pt":1631463049271,"mc":[{"id":"1.187551081","rc":[{"batb":[[0,1.02,2935.54]],"ltp":1.02,"tv":49671.49,"id":9629022}]}]}
{"op":"mcm","clk":"4228669363","pt":1631463050400,"mc":[{"id":"1.187551081","rc":[{"trd":[[1.02,1878.5]],"batb":[[0,1.02,2932.54]],"ltp":1.02,"tv":49677.49,"id":9629022}],"tv":51668.69}]}
{"op":"mcm","clk":"4228670504","pt":1631463056587,"mc":[{"id":"1.187551081","rc":[{"trd":[[1.03,6559.76]],"batl":[[0,1.03,2982.03]],"ltp":1.03,"tv":49695.53,"id":9629022}],"tv":51686.73}]}
{"op":"mcm","clk":"4228673970","pt":1631463074233,"mc":[{"id":"1.187551081","rc":[{"trd":[[1.03,6599.76]],"batl":[[0,1.03,2962.03]],"ltp":1.03,"tv":49735.53,"id":9629022}],"tv":51726.73}]}
{"op":"mcm","clk":"4228674558","pt":1631463077421,"mc":[{"id":"1.187551081","rc":[{"batl":[[0,1.03,2991.05]],"ltp":1.03,"tv":49735.53,"id":9629022}]}]}
{"op":"mcm","clk":"4228677364","pt":1631463091843,"mc":[{"id":"1.187551081","rc":[{"trd":[[48,2.14]],"batl":[[0,48,3.41]],"ltp":48.0,"tv":1992.92,"id":7445998}],"tv":51728.45}]}
{"op":"mcm","clk":"4228680887","pt":1631463109656,"mc":[{"id":"1.187551081","rc":[{"trd":[[1.03,12581.87]],"batb":[[0,1.02,2933.18]],"batl":[[0,1.04,934.32],[1,1.06,15.05],[2,1.07,377.5]],"ltp":1.03,"tv":55717.64,"id":9629022}],"tv":57710.56}]}
{"op":"mcm","clk":"4228681511","pt":1631463113034,"mc":[{"id":"1.187551081","rc":[{"trd":[[1.03,12583.15]],"batb":[[0,1.02,2932.54]],"batl":[[0,1.03,1308.73],[1,1.04,2011.85],[2,1.06,15.05]],"ltp":1.03,"tv":55718.92,"id":9629022}],"tv":57711.84}]}
{"op":"mcm","clk":"4228681660","pt":1631463113936,"mc":[{"id":"1.187551081","rc":[{"batl":[[0,1.03,1542.69]],"ltp":1.03,"tv":55718.92,"id":9629022}]}]}
{"op":"mcm","clk":"4228681878","pt":1631463115130,"mc":[{"id":"1.187551081","rc":[{"batl":[[2,1.07,377.5]],"ltp":1.03,"tv":55718.92,"id":9629022}]}]}
{"op":"mcm","clk":"4228682080","pt":1631463116213,"mc":[{"id":"1.187551081","rc":[{"batl":[[0,1.03,2605.18]],"ltp":1.03,"tv":55718.92,"id":9629022}]}]}
{"op":"mcm","clk":"4228682265","pt":1631463117321,"mc":[{"id":"1.187551081","rc":[{"trd":[[1.03,12585.9]],"batl":[[0,1.03,2603.8]],"ltp":1.03,"tv":55721.67,"id":9629022}],"tv":57714.6}]}
{"op":"mcm","clk":"4228682476","pt":1631463118325,"mc":[{"id":"1.187551081","rc":[{"batl":[[2,1.06,416.25]],"ltp":1.03,"tv":55721.67,"id":9629022}]}]}
{"op":"mcm","clk":"4228683962","pt":1631463126839,"mc":[{"id":"1.187551081","rc":[{"trd":[[1.03,12594.92]],"batl":[[0,1.03,2599.29]],"ltp":1.03,"tv":55730.69,"id":9629022}],"tv":57723.62}]}
{"op":"mcm","clk":"4228684637","pt":1631463130440,"mc":[{"id":"1.187551081","rc":[{"trd":[[1.03,12967.06]],"batl":[[0,1.03,2413.22]],"ltp":1.03,"tv":56102.83,"id":9629022}],"tv":58095.75}]}
{"op":"mcm","clk":"4228685196","pt":1631463133639,"mc":[{"id":"1.187551081","rc":[{"trd":[[1.03,17793.5]],"batb":[[0,1.03,577.09],[1,1.02,2932.54],[2,1.01,4146.98]],"batl":[[0,1.04,2011.85],[1,1.06,416.25],[2,1.07,377.5]],"ltp":1.03,"tv":60929.27,"id":9629022}],"tv":62922.19}]}
{"op":"mcm","clk":"4228685278","pt":1631463134031,"mc":[{"id":"1.187551081","rc":[{"trd":[[1.03,18178.7]],"batb":[[0,1.03,384.49]],"batl":[[0,1.04,934.32]],"ltp":1.03,"tv":61314.47,"id":9629022}],"tv":63307.39}]}
{"op":"mcm","clk":"4228685558","pt":1631463135540,"mc":[{"id":"1.187551081","rc":[{"batb":[[0,20,23.87],[1,17.5,2],[2,15,2]],"batl":[[0,50,2],[1,110,2],[2,990,0.01]],"ltp":48.0,"tv":1992.92,"id":7445998},{"batb":[[1,1.02,10],[2,1.01,2465.37]],"batl":[[0,1.06,416.25],[1,1.08,305.44],[2,1.11,12.05]],"ltp":1.03,"tv":61314.47,"id":9629022}]}]}
{"op":"mcm","clk":"4228686016","pt":1631463137660,"mc":[{"id":"1.187551081","rc":[{"batl":[[0,990,0.01],[1,110,0],[2,990,0]],"ltp":48.0,"tv":1992.92,"id":7445998},{"trd":[[1.03,18947.68]],"batb":[[0,1.02,10],[1,1.02,0],[2,1.01,0]],"ltp":1.03,"tv":62083.45,"id":9629022}],"tv":64076.38}]}
{"op":"mcm","clk":"4228686193","pt":1631463138663,"mc":[{"id":"1.187551081","rc":[{"batb":[[0,21,3],[1,20,25.87]],"ltp":48.0,"tv":1992.92,"id":7445998},{"batb":[[1,1.01,1335.3]],"batl":[[0,1.05,440.18],[1,1.06,669.97],[2,1.08,305.44]],"ltp":1.03,"tv":62083.45,"id":9629022}]}]}
{"op":"mcm","clk":"4228686256","pt":1631463138957,"mc":[{"id":"1.187551081","rc":[{"trd":[[1.02,1898.5]],"batb":[[0,1.01,1335.3],[1,1.01,0]],"batl":[[0,1.02,410],[1,1.05,440.18],[2,1.06,669.97]],"ltp":1.02,"tv":62103.45,"id":9629022}],"tv":64096.38}]}
{"op":"mcm","clk":"4228686494","pt":1631463140397,"mc":[{"id":"1.187551081","rc":[{"batb":[[2,19.5,2]],"ltp":48.0,"tv":1992.92,"id":7445998},{"batl":[[2,1.06,906.9]],"ltp":1.02,"tv":62103.45,"id":9629022}]}]}
{"op":"mcm","clk":"4228686687","pt":1631463141369,"mc":[{"id":"1.187551081","rc":[{"batl":[[0,110,2],[1,990,0.01]],"ltp":48.0,"tv":1992.92,"id":7445998},{"batb":[[0,1.01,3961.01]],"batl":[[2,1.06,1338.65]],"ltp":1.02,"tv":62103.45,"id":9629022}]}]}
{"op":"mcm","clk":"4228686897","pt":1631463142558,"mc":[{"id":"1.187551081","rc":[{"trd":[[1.02,2353.98]],"batl":[[0,1.02,182.26]],"ltp":1.02,"tv":62558.93,"id":9629022}],"tv":64551.86}]}
{"op":"mcm","clk":"4228687140","pt":1631463143778,"mc":[{"id":"1.187551081","rc":[{"batb":[[0,1.01,2625.71]],"ltp":1.02,"tv":62558.93,"id":9629022}]}]}
{"op":"mcm","clk":"4228687589","pt":1631463146084,"mc":[{"id":"1.187551081","rc":[{"trd":[[1.02,2718.5]],"batl":[[0,1.05,440.18],[1,1.06,1338.65],[2,1.08,305.44]],"ltp":1.02,"tv":62923.45,"id":9629022}],"tv":64916.38}]}
{"op":"mcm","clk":"4228687890","pt":1631463147459,"mc":[{"id":"1.187551081","rc":[{"batb":[[0,1.04,1296.79],[1,1.03,3356.22],[2,1.02,427.01]],"batl":[[2,1.08,320.21]],"ltp":1.02,"tv":62923.45,"id":9629022}]}]}
{"op":"mcm","clk":"4228688280","pt":1631463149367,"mc":[{"id":"1.187551081","rc":[{"batb":[[0,21,8.31]],"batl":[[0,29,8.09],[1,50,2],[2,95,39.2]],"ltp":48.0,"tv":1992.92,"id":7445998},{"batb":[[0,1.04,1421.53],[2,1.02,527.01]],"ltp":1.02,"tv":62923.45,"id":9629022}]}]}
{"op":"mcm","clk":"4228688689","pt":1631463151563,"mc":[{"id":"1.187551081","rc":[{"batl":[[1,32,21.25],[2,50,2]],"ltp":48.0,"tv":1992.92,"id":7445998},{"batl":[[0,1.05,705.4]],"ltp":1.02,"tv":62923.45,"id":9629022}]}]}
{"op":"mcm","clk":"4228688833","pt":1631463152280,"mc":[{"id":"1.187551081","rc":[{"batb":[[1,20,23.87],[2,17.5,2]],"batl":[[1,50,2],[2,95,39.2]],"ltp":48.0,"tv":1992.92,"id":7445998},{"batb":[[0,1.04,2281.64]],"batl":[[0,1.05,440.18],[1,1.06,1308.65]],"ltp":1.02,"tv":62923.45,"id":9629022}]}]}
{"op":"mcm","clk":"4228689041","pt":1631463153489,"mc":[{"id":"1.187551081","rc":[{"batl":[[0,26,24.19],[1,29,8.09],[2,36,27.31]],"ltp":48.0,"tv":1992.92,"id":7445998},{"batb":[[0,1.04,2886.3],[1,1.03,4311.04],[2,1.02,1645.9]],"ltp":1.02,"tv":62923.45,"id":9629022}]}]}
{"op":"mcm","clk":"4228689210","pt":1631463154392,"mc":[{"id":"1.187551081","rc":[{"batb":[[0,21,42],[2,17.5,43.8]],"batl":[[1,36,27.31],[2,50,2]],"ltp":48.0,"tv":1992.92,"id":7445998},{"batl":[[0,1.05,1114.02],[1,1.06,1998.72]],"ltp":1.02,"tv":62923.45,"id":9629022}]}]}
{"op":"mcm","clk":"4228689445","pt":1631463155574,"mc":[{"id":"1.187551081","rc":[{"trd":[[21,7.42]],"batb":[[0,21,40]],"ltp":21.0,"tv":1996.92,"id":7445998}],"tv":64920.38}]}
{"op":"mcm","clk":"4228689534","pt":1631463156071,"mc":[{"id":"1.187551081","rc":[{"batb":[[2,1.02,1218.89]],"ltp":1.02,"tv":62923.45,"id":9629022}]}]}
{"op":"mcm","clk":"4228689759","pt":1631463157194,"mc":[{"id":"1.187551081","rc":[{"batl":[[0,25,3.57],[1,26,24.19],[2,36,27.31]],"ltp":21.0,"tv":1996.92,"id":7445998}]}]}
{"op":"mcm","clk":"4228689897","pt":1631463157893,"mc":[{"id":"1.187551081","rc":[{"batl":[[0,1.05,1220.11]],"ltp":1.02,"tv":62923.45,"id":9629022}]}]}
{"op":"mcm","clk":"4228690231","pt":1631463159574,"mc":[{"id":"1.187551081","rc":[{"trd":[[21,12.54]],"batb":[[0,21,37.44]],"ltp":21.0,"tv":2002.04,"id":7445998},{"batb":[[0,1.04,1589.51]],"batl":[[0,1.05,820.93],[1,1.06,1121.82]],"ltp":1.02,"tv":62923.45,"id":9629022}],"tv":64925.5}]}
{"op":"mcm","clk":"4228690445","pt":1631463160484,"mc":[{"id":"1.187551081","rc":[{"batb":[[0,13.5,29.98],[1,11,2],[2,4.2,376.32]],"batl":[[0,95,39.2],[1,110,2],[2,990,0.01]],"ltp":21.0,"tv":2002.04,"id":7445998},{"batb":[[0,1.05,93.03],[1,1.01,2625.71],[2,1.02,0]],"batl":[[0,1.1,258.54],[1,1.11,11.86],[2,1.13,11.86]],"ltp":1.02,"tv":62923.45,"id":9629022}]}]}
{"op":"mcm","clk":"4228690853","pt":1631463162599,"mc":[{"id":"1.187551081","rc":[{"batb":[[1,1.03,198.96],[2,1.02,1121.3]],"batl":[[0,1.08,682.02],[1,1.09,561.54],[2,1.1,258.54]],"ltp":1.02,"tv":62923.45,"id":9629022}]}]}
{"op":"mcm","clk":"4228691050","pt":1631463163626,"mc":[{"id":"1.187551081","rc":[{"batb":[[0,13.5,31.98]],"batl":[[0,55,4],[1,95,39.2],[2,110,2]],"ltp":21.0,"tv":2002.04,"id":7445998},{"batb":[[0,1.02,1228.34],[1,1.01,2625.71],[2,1.02,0]],"batl":[[0,1.08,332.69],[1,1.09,276.5],[2,1.1,281.54]],"ltp":1.02,"tv":62923.45,"id":9629022}]}]}
{"op":"mcm","clk":"4228691244","pt":1631463164601,"mc":[{"id":"1.187551081","rc":[{"batb":[[0,13.5,29.98]],"batl":[[0,55,2],[1,110,2],[2,990,0.01]],"ltp":21.0,"tv":2002.04,"id":7445998},{"batb":[[0,1.01,2625.71],[1,1.01,0]],"batl":[[0,1.1,281.54],[1,1.11,11.86],[2,1.13,11.86]],"ltp":1.02,"tv":62923.45,"id":9629022}]}]}
{"op":"mcm","clk":"4228691302","pt":1631463164922,"mc":[{"id":"1.187551081","rc":[{"batl":[[1,990,0.01],[2,990,0]],"ltp":21.0,"tv":2002.04,"id":7445998}]}]}
{"op":"mcm","clk":"4228691639","pt":1631463166661,"mc":[{"id":"1.187551081","rc":[{"trd":[[1.05,2678.05]],"batb":[[0,1.05,361.72],[1,1.04,910.48]],"batl":[[0,1.06,1239.97],[1,1.1,281.54],[2,1.11,11.86]],"ltp":1.05,"tv":62965.25,"id":9629022}],"tv":64967.3}]}
{"op":"mcm","clk":"4228691821","pt":1631463167532,"mc":[{"id":"1.187551081","rc":[{"batb":[[0,13.5,31.98]],"batl":[[0,55,4]],"ltp":21.0,"tv":2002.04,"id":7445998},{"batb":[[2,1.02,1934.15]],"batl":[[1,1.08,358.69],[2,1.09,271.5]],"ltp":1.05,"tv":62965.25,"id":9629022}]}]}
{"op":"mcm","clk":"4228691965","pt":1631463168344,"mc":[{"id":"1.187551081","rc":[{"batb":[[0,1.02,1934.15],[1,1.01,2850.48],[2,1.02,0]],"batl":[[0,1.08,358.69],[1,1.09,271.5],[2,1.1,281.54]],"ltp":1.05,"tv":62965.25,"id":9629022}]}]}
{"op":"mcm","clk":"4228692043","pt":1631463168728,"mc":[{"id":"1.187551081","rc":[{"batl":[[1,65,41.03],[2,990,0.01]],"ltp":21.0,"tv":2002.04,"id":7445998}]}]}
{"op":"mcm","clk":"4228692547","pt":1631463171434,"mc":[{"id":"1.187551081","rc":[{"batb":[[0,1.05,787.1],[1,1.02,3256.36],[2,1.01,2850.48]],"batl":[[0,1.08,1051.98],[1,1.09,821.86]],"ltp":1.05,"tv":62965.25,"id":9629022}]}]}
{"op":"mcm","clk":"4228692608","pt":1631463171752,"mc":[{"id":"1.187551081","rc":[{"batb":[[0,1.02,3256.36],[1,1.01,2850.48],[2,1.01,0]],"ltp":1.05,"tv":62965.25,"id":9629022}]}]}
{"op":"mcm","clk":"4228693304","pt":1631463175450,"mc":[{"id":"1.187551081","rc":[{"batb":[[0,1.02,1934.15]],"ltp":1.05,"tv":62965.25,"id":9629022}]}]}
{"op":"mcm","clk":"4228693536","pt":1631463176648,"mc":[{"id":"1.187551081","rc":[{"batb":[[0,13.5,2]],"ltp":21.0,"tv":2002.04,"id":7445998},{"batl":[[0,1.08,358.69],[1,1.09,271.5]],"ltp":1.05,"tv":62965.25,"id":9629022}]}]}
{"op":"mcm","clk":"4228693739","pt":1631463177566,"mc":[{"id":"1.187551081","rc":[{"batb":[[0,11,2],[1,4.2,376.32],[2,1.01,30]],"ltp":21.0,"tv":2002.04,"id":7445998},{"batl":[[0,1.09,271.5],[1,1.1,281.54],[2,1.11,11.86]],"ltp":1.05,"tv":62965.25,"id":9629022}]}]}
{"op":"mcm","clk":"4228693934","pt":1631463178511,"mc":[{"id":"1.187551081","rc":[{"batl":[[1,990,0.01],[2,990,0]],"ltp":21.0,"tv":2002.04,"id":7445998},{"batb":[[0,1.07,399.03],[1,1.06,869.52],[2,1.02,1949.79]],"batl":[[1,1.1,273.05],[2,1.12,7.12]],"ltp":1.05,"tv":62965.25,"id":9629022}]}]}
{"op":"mcm","clk":"4228694110","pt":1631463179438,"mc":[{"id":"1.187551081","rc":[{"batb":[[1,10,59.29],[2,4.2,376.32]],"ltp":21.0,"tv":2002.04,"id":7445998},{"trd":[[1.09,927.98]],"batb":[[0,1.09,963.88],[1,1.05,1909.4],[2,1.03,2767.54]],"batl":[[0,1.1,258.54],[1,1.11,436.98],[2,1.12,623.97]],"ltp":1.09,"tv":63508.25,"id":9629022}],"tv":65510.3}]}
{"op":"mcm","clk":"4228694334","pt":1631463180514,"mc":[{"id":"1.187551081","rc":[{"batb":[[1,4.2,376.32],[2,1.01,30]],"batl":[[0,13.5,18.24],[1,55,4],[2,990,0.01]],"ltp":21.0,"tv":2002.04,"id":7445998},{"trd":[[1.09,977.98]],"batb":[[0,1.09,938.88],[1,1.02,1934.15],[2,1.01,2623.48]],"batl":[[2,1.12,548.32]],"ltp":1.09,"tv":63558.25,"id":9629022}],"tv":65560.3}]}
{"op":"mcm","clk":"4228694433","pt":1631463181062,"mc":[{"id":"1.187551081","rc":[{"batl":[[1,16.5,2],[2,50,2]],"ltp":21.0,"tv":2002.04,"id":7445998},{"batb":[[1,1.03,69],[2,1.02,1934.15]],"ltp":1.09,"tv":63558.25,"id":9629022}]}]}
{"op":"mcm","clk":"4228694761","pt":1631463182642,"mc":[{"id":"1.187551081","rc":[{"batl":[[1,24,50.55]],"ltp":21.0,"tv":2002.04,"id":7445998},{"batb":[[0,1.03,69],[1,1.02,1934.15],[2,1.01,2623.48]],"batl":[[1,1.19,14.82],[2,1.21,11.86]],"ltp":1.09,"tv":63558.25,"id":9629022}]}]}
{"op":"mcm","clk":"4228694957","pt":1631463183668,"mc":[{"id":"1.187551081","rc":[{"batl":[[0,24,50.55],[1,55,2],[2,990,0.01]],"ltp":21.0,"tv":2002.04,"id":7445998},{"batb":[[0,1.09,986.18],[1,1.02,1822.15]],"ltp":1.09,"tv":63558.25,"id":9629022}]}]}
{"op":"mcm","clk":"4228695153","pt":1631463184654,"mc":[{"id":"1.187551081","rc":[{"batb":[[1,1.01,30],[2,1.01,0]],"batl":[[0,55,2],[1,990,0.01],[2,990,0]],"ltp":21.0,"tv":2002.04,"id":7445998},{"batb":[[0,1.02,1822.15],[1,1.01,2623.48],[2,1.01,0]],"ltp":1.09,"tv":63558.25,"id":9629022}]}]}
{"op":"mcm","clk":"4228695338","pt":1631463185578,"mc":[{"id":"1.187551081","rc":[{"batb":[[0,11,4],[1,10.5,2],[2,1.01,30]],"ltp":21.0,"tv":2002.04,"id":7445998},{"batl":[[0,1.1,284.54]],"ltp":1.09,"tv":63558.25,"id":9629022}]}]}
{"op":"mcm","clk":"4228695381","pt":1631463185751,"mc":[{"id":"1.187551081","rc":[{"batb":[[0,11,2],[1,1.01,30],[2,1.01,0]],"ltp":21.0,"tv":2002.04,"id":7445998},{"batl":[[0,1.1,258.54]],"ltp":1.09,"tv":63558.25,"id":9629022}]}]}
{"op":"mcm","clk":"4228695741","pt":1631463187647,"mc":[{"id":"1.187551081","rc":[{"batl":[[0,12,2],[1,55,2],[2,990,0.01]],"ltp":21.0,"tv":2002.04,"id":7445998}]}]}
{"op":"mcm","clk":"4228695875","pt":1631463188250,"mc":[{"id":"1.187551081","rc":[{"trd":[[12,103.7]],"batl":[[0,55,2],[1,990,0.01],[2,990,0]],"ltp":12.0,"tv":2004.04,"id":7445998},{"trd":[[1.09,1000]],"batb":[[0,1.06,1272.32],[1,1.02,1822.15],[2,1.01,2623.48]],"batl":[[0,1.08,921.12],[1,1.09,302.81],[2,1.1,258.54]],"ltp":1.09,"tv":63580.27,"id":9629022}],"tv":65584.32}]}
{"op":"mcm","clk":"4228696188","pt":1631463189627,"mc":[{"id":"1.187551081","rc":[{"batb":[[0,12,10],[1,11,2],[2,1.01,30]],"batl":[[0,18.5,10],[1,55,2],[2,990,0.01]],"ltp":12.0,"tv":2004.04,"id":7445998},{"batl":[[1,1.09,307.32]],"ltp":1.09,"tv":63580.27,"id":9629022}]}]}
{"op":"mcm","clk":"4228696564","pt":1631463191665,"mc":[{"id":"1.187551081","rc":[{"batb":[[0,14,2],[1,13.5,2],[2,12,10]],"batl":[[0,17.5,2]],"ltp":12.0,"tv":2004.04,"id":7445998},{"batb":[[1,1.02,1939.15]],"batl":[[0,1.08,1038.45]],"ltp":1.09,"tv":63580.27,"id":9629022}]}]}
{"op":"mcm","clk":"4228696652","pt":1631463192200,"mc":[{"id":"1.187551081","rc":[{"batb":[[2,11,2]],"ltp":12.0,"tv":2004.04,"id":7445998},{"batb":[[0,1.06,1510.42]],"ltp":1.09,"tv":63580.27,"id":9629022}]}]}
{"op":"mcm","clk":"4228697101","pt":1631463194449,"mc":[{"id":"1.187551081","rc":[{"batb":[[0,14.5,2],[1,14,2],[2,13.5,2]],"ltp":12.0,"tv":2004.04,"id":7445998}]}]}
{"op":"mcm","clk":"4228697268","pt":1631463195357,"mc":[{"id":"1.187551081","rc":[{"batb":[[0,1.01,30],[1,14,0],[2,13.5,0]],"batl":[[0,990,0.01],[1,55,0],[2,990,0]],"ltp":12.0,"tv":2004.04,"id":7445998},{"batb":[[0,1.02,544.01],[1,1.02,0],[2,1.01,0]],"batl":[[0,1.09,4.51],[1,1.19,15.02],[2,1.21,11.86]],"ltp":1.09,"tv":63580.27,"id":9629022}]}]}
{"op":"mcm","clk":"4228697426","pt":1631463196145,"mc":[{"id":"1.187551081","rc":[{"batb":[[0,1.08,2.17],[1,1.02,544.01]],"ltp":1.09,"tv":63580.27,"id":9629022}]}]}
{"op":"mcm","clk":"4228697676","pt":1631463197475,"mc":[{"id":"1.187551081","rc":[{"batb":[[0,1.08,85.91]],"batl":[[0,1.19,15.02],[1,1.21,11.86],[2,1.23,29.64]],"ltp":1.09,"tv":63580.27,"id":9629022}]}]}
{"op":"mcm","clk":"4228697870","pt":1631463198556,"mc":[{"id":"1.187551081","rc":[{"batb":[[0,6.2,2],[1,6,3],[2,1.01,30]],"batl":[[0,55,2],[1,990,0.01]],"ltp":12.0,"tv":2004.04,"id":7445998},{"batb":[[2,1.01,4]],"ltp":1.09,"tv":63580.27,"id":9629022}]}]}
{"op":"mcm","clk":"4228698062","pt":1631463199640,"mc":[{"id":"1.187551081","rc":[{"batl":[[0,15,127.2],[1,55,2],[2,990,0.01]],"ltp":12.0,"tv":2004.04,"id":7445998}]}]}
{"op":"mcm","clk":"4228698140","pt":1631463200048,"mc":[{"id":"1.187551081","rc":[{"batl":[[0,55,2],[1,990,0.01],[2,990,0]],"ltp":12.0,"tv":2004.04,"id":7445998},{"batb":[[0,1.08,2.17],[1,1.07,1118.52],[2,1.02,544.01]],"batl":[[0,1.09,1237.3],[1,1.19,17.02],[2,1.21,11.86]],"ltp":1.09,"tv":63580.27,"id":9629022}]}]}
{"op":"mcm","clk":"4228698380","pt":1631463201461,"mc":[{"id":"1.187551081","rc":[{"batl":[[0,17,10],[1,55,2],[2,990,0.01]],"ltp":12.0,"tv":2004.04,"id":7445998}]}]}
{"op":"mcm","clk":"4228698599","pt":1631463202543,"mc":[{"id":"1.187551081","rc":[{"trd":[[1.08,136.52]],"batb":[[0,1.07,1118.52],[1,1.02,544.01],[2,1.01,4]],"ltp":1.08,"tv":63584.61,"id":9629022}],"tv":65588.66}]}
{"op":"mcm","clk":"4228698983","pt":1631463204477,"mc":[{"id":"1.187551081","rc":[{"batb":[[0,1.07,1853.02]],"batl":[[0,1.09,1385]],"ltp":1.08,"tv":63584.61,"id":9629022}]}]}
{"op":"mcm","clk":"4228699090","pt":1631463204968,"mc":[{"id":"1.187551081","rc":[{"batl":[[0,55,2],[1,990,0.01],[2,990,0]],"ltp":12.0,"tv":2004.04,"id":7445998},{"batb":[[0,1.02,544.01],[1,1.01,4],[2,1.01,0]],"batl":[[0,1.19,17.02],[1,1.21,11.86],[2,1.23,29.64]],"ltp":1.08,"tv":63584.61,"id":9629022}]}]}
{"op":"mcm","clk":"4228699346","pt":1631463206260,"mc":[{"id":"1.187551081","rc":[{"batb":[[0,1.08,13.78],[1,1.02,544.01],[2,1.01,4]],"ltp":1.08,"tv":63584.61,"id":9629022}]}]}
{"op":"mcm","clk":"4228699811","pt":1631463208576,"mc":[{"id":"1.187551081","rc":[{"batl":[[0,11.5,2],[1,55,2],[2,990,0.01]],"ltp":12.0,"tv":2004.04,"id":7445998},{"batb":[[1,1.05,615.74],[2,1.04,675.11]],"batl":[[0,1.11,663.55],[1,1.12,546.72],[2,1.19,16.82]],"ltp":1.08,"tv":63584.61,"id":9629022}]}]}
{"op":"mcm","clk":"4228700534","pt":1631463212385,"mc":[{"id":"1.187551081","rc":[{"batb":[[1,1.01,30],[2,1.01,0]],"ltp":12.0,"tv":2004.04,"id":7445998},{"trd":[[1.1,2561.93],[1.11,4868.98]],"batl":[[0,1.11,548.71]],"ltp":1.11,"tv":63814.3,"id":9629022}],"tv":65818.35}]}
{"op":"mcm","clk":"4228700579","pt":1631463212702,"mc":[{"id":"1.187551081","rc":[{"batb":[[2,1.04,607.45]],"ltp":1.11,"tv":63814.3,"id":9629022}]}]}
{"op":"mcm","clk":"4228700833","pt":1631463214207,"mc":[{"id":"1.187551081","rc":[{"batb":[[1,1.02,544.01],[2,1.04,0]],"ltp":1.11,"tv":63814.3,"id":9629022}]}]}
{"op":"mcm","clk":"4228701078","pt":1631463215593,"mc":[{"id":"1.187551081","rc":[{"batb":[[1,1.05,67.02],[2,1.02,544.01]],"batl":[[0,1.11,600],[1,1.12,609.5]],"ltp":1.11,"tv":63814.3,"id":9629022}]}]}
{"op":"mcm","clk":"4228701264","pt":1631463216625,"mc":[{"id":"1.187551081","rc":[{"batl":[[0,55,2],[1,990,0.01],[2,990,0]],"ltp":12.0,"tv":2004.04,"id":7445998},{"batb":[[1,1.02,544.01],[2,1.02,0]],"ltp":1.11,"tv":63814.3,"id":9629022}]}]}
{"op":"mcm","clk":"4228701412","pt":1631463217289,"mc":[{"id":"1.187551081","rc":[{"trd":[[1.09,1038.92]],"batb":[[0,1.09,1217.84],[1,1.08,13.78],[2,1.04,15.34]],"batl":[[2,1.13,14.12]],"ltp":1.09,"tv":63853.22,"id":9629022}],"tv":65857.27}]}
{"op":"mcm","clk":"4228701572","pt":1631463218127,"mc":[{"id":"1.187551081","rc":[{"batb":[[0,11.5,1.71],[1,6.2,2],[2,1.01,30]],"ltp":12.0,"tv":2004.04,"id":7445998}]}]}
{"op":"mcm","clk":"4228701808","pt":1631463219522,"mc":[{"id":"1.187551081","rc":[{"trd":[[11.5,3.42]],"batb":[[0,10.5,2],[1,10,2],[2,6.2,2]],"ltp":11.5,"tv":2007.46,"id":7445998},{"batb":[[0,1.09,1286.74],[1,1.04,15.34],[2,1.02,551.84]],"batl":[[0,1.11,677.17]],"ltp":1.09,"tv":63853.22,"id":9629022}],"tv":65860.68}]}
{"op":"mcm","clk":"4228701866","pt":1631463219800,"mc":[{"id":"1.187551081","rc":[{"trd":[[10.5,75.25]],"batb":[[0,10,2],[1,6.2,2],[2,1.01,30]],"batl":[[0,20,2],[1,55,2],[2,990,0.01]],"ltp":10.5,"tv":2011.46,"id":7445998}],"tv":65864.68}]}
{"op":"mcm","clk":"4228702135","pt":1631463221182,"mc":[{"id":"1.187551081","rc":[{"trd":[[1.11,5011.31]],"batl":[[0,1.11,606]],"ltp":1.11,"tv":63995.56,"id":9629022}],"tv":66007.02}]}
{"op":"mcm","clk":"4228702294","pt":1631463222206,"mc":[{"id":"1.187551081","rc":[{"batb":[[0,1.09,1956.89],[1,1.05,506.1],[2,1.04,15.34]],"ltp":1.11,"tv":63995.56,"id":9629022}]}]}
{"op":"mcm","clk":"4228702541","pt":1631463223499,"mc":[{"id":"1.187551081","rc":[{"batl":[[0,12.5,42.82],[1,13.5,50.7],[2,20,2]],"ltp":10.5,"tv":2011.46,"id":7445998},{"trd":[[1.09,1137.64]],"batb":[[0,1.09,2398.61],[1,1.08,633.7],[2,1.05,506.1]],"ltp":1.09,"tv":64094.28,"id":9629022}],"tv":66105.74}]}
{"op":"mcm","clk":"4228702766","pt":1631463224621,"mc":[{"id":"1.187551081","rc":[{"batb":[[0,10,49.68],[1,9.2,56.87],[2,6.2,2]],"ltp":10.5,"tv":2011.46,"id":7445998},{"batl":[[0,1.11,1078.01],[1,1.12,1078.55]],"ltp":1.09,"tv":64094.28,"id":9629022}]}]}
{"op":"mcm","clk":"4228702787","pt":1631463224692,"mc":[{"id":"1.187551081","rc":[{"batb":[[0,10,59.61]],"ltp":10.5,"tv":2011.46,"id":7445998}]}]}
{"op":"mcm","clk":"4228703048","pt":1631463226303,"mc":[{"id":"1.187551081","rc":[{"trd":[[1.09,1146.66]],"batb":[[0,1.09,2462.92]],"batl":[[0,1.11,1104.85]],"ltp":1.09,"tv":64103.3,"id":9629022}],"tv":66114.76}]}
{"op":"mcm","clk":"4228703185","pt":1631463227127,"mc":[{"id":"1.187551081","rc":[{"batl":[[0,12,10],[1,12.5,42.82],[2,13.5,50.7]],"ltp":10.5,"tv":2011.46,"id":7445998},{"batl":[[1,1.12,1076.66]],"ltp":1.09,"tv":64103.3,"id":9629022}]}]}
{"op":"mcm","clk":"4228703748","pt":1631463230528,"mc":[{"id":"1.187551081","rc":[{"batb":[[2,1.01,30]],"ltp":10.5,"tv":2011.46,"id":7445998},{"batb":[[0,1.1,13.78],[1,1.09,2462.92],[2,1.08,633.7]],"ltp":1.09,"tv":64103.3,"id":9629022}]}]}
{"op":"mcm","clk":"4228703912","pt":1631463231514,"mc":[{"id":"1.187551081","rc":[{"batb":[[0,1.01,30],[1,9.2,0],[2,1.01,0]],"batl":[[0,20,2],[1,990,0.01],[2,13.5,0]],"ltp":10.5,"tv":2011.46,"id":7445998},{"batb":[[1,1.05,506.1],[2,1.02,117]],"batl":[[0,1.19,16.82],[1,1.21,11.86],[2,1.23,29.64]],"ltp":1.09,"tv":64103.3,"id":9629022}]}]}
{"op":"mcm","clk":"4228704476","pt":1631463234620,"mc":[{"id":"1.187551081","rc":[{"batb":[[0,6.2,2],[1,6,2],[2,1.01,30]],"ltp":10.5,"tv":2011.46,"id":7445998},{"batb":[[0,1.11,121.28],[1,1.1,13.78],[2,1.08,760.24]],"batl":[[0,1.13,16],[1,1.19,16.82],[2,1.21,11.86]],"ltp":1.09,"tv":64103.3,"id":9629022}]}]}
{"op":"mcm","clk":"4228704515","pt":1631463234840,"mc":[{"id":"1.187551081","rc":[{"batl":[[1,1.19,2],[2,1.23,29.64]],"ltp":1.09,"tv":64103.3,"id":9629022}]}]}
{"op":"mcm","clk":"4228704752","pt":1631463236565,"mc":[{"id":"1.187551081","rc":[{"trd":[[1.1,2589.48],[1.11,5253.88]],"batb":[[0,1.08,760.24],[1,1.07,493.08],[2,1.05,506.1]],"ltp":1.1,"tv":64373.42,"id":9629022}],"tv":66384.89}]}
{"op":"mcm","clk":"4228705075","pt":1631463237631,"mc":[{"id":"1.187551081","rc":[{"batb":[[0,7.6,3],[1,7.4,2],[2,6.2,2]],"ltp":10.5,"tv":2011.46,"id":7445998},{"batl":[[0,1.09,279.6],[1,1.1,1019.12],[2,1.11,14.37]],"ltp":1.1,"tv":64373.42,"id":9629022}]}]}
{"op":"mcm","clk":"4228705256","pt":1631463238624,"mc":[{"id":"1.187551081","rc":[{"batb":[[0,10,10],[1,7.6,3],[2,7.4,2]],"batl":[[0,16,10],[1,20,2],[2,990,0.01]],"ltp":10.5,"tv":2011.46,"id":7445998}]}]}
{"op":"mcm","clk":"4228705324","pt":1631463239016,"mc":[{"id":"1.187551081","rc":[{"batb":[[0,10,12]],"ltp":10.5,"tv":2011.46,"id":7445998},{"batb":[[0,1.08,824.2]],"ltp":1.1,"tv":64373.42,"id":9629022}]}]}
{"op":"mcm","clk":"4228705451","pt":1631463239755,"mc":[{"id":"1.187551081","rc":[{"batb":[[1,8.8,3],[2,8.6,2]],"ltp":10.5,"tv":2011.46,"id":7445998},{"batb":[[2,1.03,15.49]],"ltp":1.1,"tv":64373.42,"id":9629022}]}]}
{"op":"mcm","clk":"4228705805","pt":1631463241661,"mc":[{"id":"1.187551081","rc":[{"batl":[[0,13.5,42.09],[1,15.5,48.58],[2,20,2]],"ltp":10.5,"tv":2011.46,"id":7445998},{"batb":[[0,1.08,1350.29],[1,1.07,1196.81],[2,1.03,859]],"ltp":1.1,"tv":64373.42,"id":9629022}]}]}
{"op":"mcm","clk":"4228705956","pt":1631463242533,"mc":[{"id":"1.187551081","rc":[{"batb":[[0,12,38.63],[1,11,52.69],[2,10,12]],"ltp":10.5,"tv":2011.46,"id":7445998},{"batb":[[0,1.08,1905.29]],"batl":[[0,1.09,784.91],[1,1.1,1546.07]],"ltp":1.1,"tv":64373.42,"id":9629022}]}]}
