{"op":"mcm","clk":"4224905051","pt":1631438901891,"mc":[{"id":"1.187552248","marketDefinition":{"bspMarket":false,"turnInPlayEnabled":true,"persistenceEnabled":true,"marketBaseRate":5.0,"eventId":"30895222","eventTypeId":"2","numberOfWinners":1,"bettingType":"ODDS","marketType":"MATCH_ODDS","marketTime":"2021-09-12T13:30:00.000Z","suspendTime":"2021-09-12T13:30:00.000Z","bspReconciled":false,"complete":true,"inPlay":false,"crossMatching":false,"runnersVoidable":false,"numberOfActiveRunners":2,"betDelay":0,"status":"OPEN","runners":[{"status":"ACTIVE","sortPriority":1,"id":11376562,"name":"A Santos"},{"status":"ACTIVE","sortPriority":2,"id":11862899,"name":"C Cervino Ruiz"}],"regulators":["MR_INT"],"countryCode":"GB","discountAllowed":false,"timezone":"GMT","openDate":"2021-09-12T13:30:00.000Z","version":4027604622,"name":"Match Odds","eventName":"A Santos v C Cervino Ruiz"},"rc":[{"batb":[[0,1.01,25]],"ltp":0.0,"tv":0.0,"id":11862899},{"batb":[[0,1.01,25]],"ltp":0.0,"tv":0.0,"id":11376562}]}]}
{"op":"mcm","clk":"4224905230","pt":1631438903729,"mc":[{"id":"1.187552248","marketDefinition":{"bspMarket":false,"turnInPlayEnabled":true,"persistenceEnabled":true,"marketBaseRate":5.0,"eventId":"30895222","eventTypeId":"2","numberOfWinners":1,"bettingType":"ODDS","marketType":"MATCH_ODDS","marketTime":"2021-09-12T13:30:00.000Z","suspendTime":"2021-09-12T13:30:00.000Z","bspReconciled":false,"complete":true,"inPlay":false,"crossMatching":false,"runnersVoidable":false,"numberOfActiveRunners":2,"betDelay":0,"status":"OPEN","runners":[{"status":"ACTIVE","sortPriority":1,"id":11376562,"name":"A Santos"},{"status":"ACTIVE","sortPriority":2,"id":11862899,"name":"C Cervino Ruiz"}],"regulators":["MR_INT"],"countryCode":"GB","discountAllowed":true,"timezone":"GMT","openDate":"2021-09-12T13:30:00.000Z","version":4027604622,"name":"Match Odds","eventName":"A Santos v C Cervino Ruiz"}}]}
{"op":"mcm","clk":"4224917380","pt":1631439018399,"mc":[{"id":"1.187552248","rc":[{"batb":[[0,1.01,7]],"ltp":0.0,"tv":0.0,"id":11862899},{"batb":[[0,1.01,7]],"ltp":0.0,"tv":0.0,"id":11376562}]}]}
{"op":"mcm","clk":"4225014810","pt":1631439832642,"mc":[{"id":"1.187552248","rc":[{"batl":[[0,490,48.37]],"ltp":0.0,"tv":0.0,"id":11862899},{"batl":[[0,490,48.37]],"ltp":0.0,"tv":0.0,"id":11376562}]}]}
{"op":"mcm","clk":"4225015876","pt":1631439841888,"mc":[{"id":"1.187552248","rc":[{"batl":[[0,490,6.16]],"ltp":0.0,"tv":0.0,"id":11862899}]}]}
{"op":"mcm","clk":"4225016418","pt":1631439845972,"mc":[{"id":"1.187552248","rc":[{"batl":[[0,490,6.16]],"ltp":0.0,"tv":0.0,"id":11376562}]}]}
{"op":"mcm","clk":"4225155003","pt":1631440928851,"mc":[{"id":"1.187552248","rc":[{"batb":[[0,1.07,483.13],[1,1.01,7]],"ltp":0.0,"tv":0.0,"id":11862899},{"batb":[[0,7,10],[1,1.01,7]],"ltp":0.0,"tv":0.0,"id":11376562}]}]}
{"op":"mcm","clk":"4225159281","pt":1631440957946,"mc":[{"id":"1.187552248","marketDefinition":{"bspMarket":false,"turnInPlayEnabled":true,"persistenceEnabled":true,"marketBaseRate":5.0,"eventId":"30895222","eventTypeId":"2","numberOfWinners":1,"bettingType":"ODDS","marketType":"MATCH_ODDS","marketTime":"2021-09-12T13:30:00.000Z","suspendTime":"2021-09-12T13:30:00.000Z","bspReconciled":false,"complete":true,"inPlay":false,"crossMatching":true,"runnersVoidable":false,"numberOfActiveRunners":2,"betDelay":0,"status":"OPEN","runners":[{"status":"ACTIVE","sortPriority":1,"id":11376562,"name":"A Santos"},{"status":"ACTIVE","sortPriority":2,"id":11862899,"name":"C Cervino Ruiz"}],"regulators":["MR_INT"],"countryCode":"GB","discountAllowed":true,"timezone":"GMT","openDate":"2021-09-12T13:30:00.000Z","version":4027604622,"name":"Match Odds","eventName":"A Santos v C Cervino Ruiz"}}]}
{"op":"mcm","clk":"4225248046","pt":1631441548936,"mc":[{"id":"1.187552248","rc":[{"batl":[[1,990,2.2]],"ltp":0.0,"tv":0.0,"id":11862899},{"batl":[[1,990,2.2]],"ltp":0.0,"tv":0.0,"id":11376562}]}]}
{"op":"mcm","clk":"4225428635","pt":1631442806566,"mc":[{"id":"1.187552248","rc":[{"batb":[[0,1.06,500]],"ltp":0.0,"tv":0.0,"id":11862899},{"batb":[[0,8,10]],"ltp":0.0,"tv":0.0,"id":11376562}]}]}
{"op":"mcm","clk":"4225693354","pt":1631444484960,"mc":[{"id":"1.187552248","rc":[{"batb":[[1,1.01,12]],"ltp":0.0,"tv":0.0,"id":11862899},{"batb":[[1,1.01,12]],"ltp":0.0,"tv":0.0,"id":11376562}]}]}
{"op":"mcm","clk":"4225884404","pt":1631445642652,"mc":[{"id":"1.187552248","rc":[{"batb":[[1,1.02,2198.76],[2,1.01,12]],"ltp":0.0,"tv":0.0,"id":11862899},{"batb":[[1,1.05,879.5],[2,1.01,12]],"ltp":0.0,"tv":0.0,"id":11376562}]}]}
{"op":"mcm","clk":"4225912228","pt":1631445811492,"mc":[{"id":"1.187552248","rc":[{"batb":[[1,1.02,2307.21]],"ltp":0.0,"tv":0.0,"id":11862899},{"batb":[[2,1.02,108.45]],"ltp":0.0,"tv":0.0,"id":11376562}]}]}
{"op":"mcm","clk":"4226059055","pt":1631446714308,"mc":[{"id":"1.187552248","rc":[{"batl":[[0,1.21,80],[1,490,6.16],[2,990,2.2]],"ltp":0.0,"tv":0.0,"id":11862899}]}]}
{"op":"mcm","clk":"4226540221","pt":1631449800655,"mc":[{"id":"1.187552248","rc":[{"batb":[[0,1.06,585.4]],"ltp":0.0,"tv":0.0,"id":11862899},{"batb":[[0,8,11.83]],"ltp":0.0,"tv":0.0,"id":11376562}]}]}
{"op":"mcm","clk":"4226887937","pt":1631452012579,"mc":[{"id":"1.187552248","rc":[{"batl":[[1,1.72,2.66],[2,490,6.16]],"ltp":0.0,"tv":0.0,"id":11862899}]}]}
{"op":"mcm","clk":"4226938318","pt":1631452284389,"mc":[{"id":"1.187552248","rc":[{"batl":[[0,1.12,2],[1,1.21,80],[2,1.72,2.66]],"ltp":0.0,"tv":0.0,"id":11862899}]}]}
{"op":"mcm","clk":"4227027008","pt":1631452774375,"mc":[{"id":"1.187552248","rc":[{"batb":[[0,1.06,500]],"ltp":0.0,"tv":0.0,"id":11862899},{"batb":[[0,8,10]],"ltp":0.0,"tv":0.0,"id":11376562}]}]}
{"op":"mcm","clk":"4227027156","pt":1631452775131,"mc":[{"id":"1.187552248","rc":[{"batb":[[0,1.06,585.4]],"ltp":0.0,"tv":0.0,"id":11862899},{"batb":[[0,8,11.83]],"ltp":0.0,"tv":0.0,"id":11376562}]}]}
{"op":"mcm","clk":"4227037962","pt":1631452843122,"mc":[{"id":"1.187552248","rc":[{"batb":[[0,1.06,500]],"ltp":0.0,"tv":0.0,"id":11862899},{"batb":[[0,8,10]],"ltp":0.0,"tv":0.0,"id":11376562}]}]}
{"op":"mcm","clk":"4227038092","pt":1631452844153,"mc":[{"id":"1.187552248","rc":[{"batb":[[0,1.06,585.4]],"ltp":0.0,"tv":0.0,"id":11862899},{"batb":[[0,8,11.83]],"ltp":0.0,"tv":0.0,"id":11376562}]}]}
{"op":"mcm","clk":"4227124168","pt":1631453380781,"mc":[{"id":"1.187552248","rc":[{"batb":[[1,1.02,108.45],[2,1.01,12]],"ltp":0.0,"tv":0.0,"id":11376562}]}]}
{"op":"mcm","clk":"4227125093","pt":1631453386673,"mc":[{"id":"1.187552248","rc":[{"batl":[[2,1.4,43.98]],"ltp":0.0,"tv":0.0,"id":11862899}]}]}
{"op":"mcm","clk":"4227144927","pt":1631453503269,"mc":[{"id":"1.187552248","marketDefinition":{"bspMarket":false,"turnInPlayEnabled":true,"persistenceEnabled":true,"marketBaseRate":5.0,"eventId":"30895222","eventTypeId":"2","numberOfWinners":1,"bettingType":"ODDS","marketType":"MATCH_ODDS","marketTime":"2021-09-12T13:30:00.000Z","suspendTime":"2021-09-12T13:30:00.000Z","bspReconciled":false,"complete":true,"inPlay":true,"crossMatching":true,"runnersVoidable":false,"numberOfActiveRunners":2,"betDelay":5,"status":"OPEN","runners":[{"status":"ACTIVE","sortPriority":1,"id":11376562,"name":"A Santos"},{"status":"ACTIVE","sortPriority":2,"id":11862899,"name":"C Cervino Ruiz"}],"regulators":["MR_INT"],"countryCode":"GB","discountAllowed":true,"timezone":"GMT","openDate":"2021-09-12T13:30:00.000Z","version":4028393378,"name":"Match Odds","eventName":"A Santos v C Cervino Ruiz"},"rc":[{"batb":[[0,1.01,12],[1,1.02,0],[2,1.01,0]],"batl":[[0,1.21,80],[1,1.21,0],[2,1.4,0]],"ltp":0.0,"tv":0.0,"id":11862899},{"batb":[[0,1.01,12],[1,1.02,0],[2,1.01,0]],"ltp":0.0,"tv":0.0,"id":11376562}]}]}
{"op":"mcm","clk":"4227145740","pt":1631453508625,"mc":[{"id":"1.187552248","rc":[{"batl":[[1,11.5,8.68]],"ltp":0.0,"tv":0.0,"id":11862899}]}]}
{"op":"mcm","clk":"4227228484","pt":1631454037214,"mc":[{"id":"1.187552248","marketDefinition":{"bspMarket":false,"turnInPlayEnabled":true,"persistenceEnabled":true,"marketBaseRate":5.0,"eventId":"30895222","eventTypeId":"2","numberOfWinners":1,"bettingType":"ODDS","marketType":"MATCH_ODDS","marketTime":"2021-09-12T13:40:35.000Z","suspendTime":"2021-09-12T13:40:35.000Z","bspReconciled":false,"complete":true,"inPlay":true,"crossMatching":true,"runnersVoidable":false,"numberOfActiveRunners":2,"betDelay":5,"status":"OPEN","runners":[{"status":"ACTIVE","sortPriority":1,"id":11376562,"name":"A Santos"},{"status":"ACTIVE","sortPriority":2,"id":11862899,"name":"C Cervino Ruiz"}],"regulators":["MR_INT"],"countryCode":"GB","discountAllowed":true,"timezone":"GMT","openDate":"2021-09-12T13:30:00.000Z","version":4028422630,"name":"Match Odds","eventName":"A Santos v C Cervino Ruiz"}}]}
{"op":"mcm","clk":"4227228765","pt":1631454039228,"mc":[{"id":"1.187552248","marketDefinition":{"bspMarket":false,"turnInPlayEnabled":true,"persistenceEnabled":true,"marketBaseRate":5.0,"eventId":"30895222","eventTypeId":"2","numberOfWinners":1,"bettingType":"ODDS","marketType":"MATCH_ODDS","marketTime":"2021-09-12T13:40:35.000Z","suspendTime":"2021-09-12T13:40:35.000Z","bspReconciled":false,"complete":true,"inPlay":true,"crossMatching":true,"runnersVoidable":false,"numberOfActiveRunners":2,"betDelay":5,"status":"OPEN","runners":[{"status":"ACTIVE","sortPriority":1,"id":11376562,"name":"A Santos"},{"status":"ACTIVE","sortPriority":2,"id":11862899,"name":"C Cervino Ruiz"}],"regulators":["MR_INT"],"countryCode":"GB","discountAllowed":true,"timezone":"GMT","openDate":"2021-09-12T13:40:35.000Z","version":4028422630,"name":"Match Odds","eventName":"A Santos v C Cervino Ruiz"}}]}
{"op":"mcm","clk":"4227264621","pt":1631454254970,"mc":[{"id":"1.187552248","rc":[{"batb":[[0,3.9,376.1],[1,1.01,12]],"batl":[[0,34,46.84]],"ltp":0.0,"tv":0.0,"id":11376562}]}]}
{"op":"mcm","clk":"4227274128","pt":1631454310032,"mc":[{"id":"1.187552248","rc":[{"batb":[[0,6,2],[1,3.9,376.1],[2,1.01,12]],"ltp":0.0,"tv":0.0,"id":11376562}]}]}
{"op":"mcm","clk":"4227278029","pt":1631454332871,"mc":[{"id":"1.187552248","rc":[{"batl":[[0,46,43.67]],"ltp":0.0,"tv":0.0,"id":11376562}]}]}
{"op":"mcm","clk":"4227283831","pt":1631454367101,"mc":[{"id":"1.187552248","rc":[{"batl":[[0,60,41.65]],"ltp":0.0,"tv":0.0,"id":11376562}]}]}
{"op":"mcm","clk":"4227293891","pt":1631454434720,"mc":[{"id":"1.187552248","rc":[{"batl":[[0,85,39.77]],"ltp":0.0,"tv":0.0,"id":11376562}]}]}
{"op":"mcm","clk":"4227313389","pt":1631454500180,"mc":[{"id":"1.187552248","rc":[{"batl":[[0,60,41.65]],"ltp":0.0,"tv":0.0,"id":11376562}]}]}
{"op":"mcm","clk":"4227317320","pt":1631454526753,"mc":[{"id":"1.187552248","rc":[{"batl":[[0,85,39.77]],"ltp":0.0,"tv":0.0,"id":11376562}]}]}
{"op":"mcm","clk":"4227322618","pt":1631454561887,"mc":[{"id":"1.187552248","rc":[{"batl":[[0,170,37.59]],"ltp":0.0,"tv":0.0,"id":11376562}]}]}
{"op":"mcm","clk":"4227327938","pt":1631454596122,"mc":[{"id":"1.187552248","rc":[{"batl":[[0,85,39.77]],"ltp":0.0,"tv":0.0,"id":11376562}]}]}
{"op":"mcm","clk":"4227332985","pt":1631454635691,"mc":[{"id":"1.187552248","rc":[{"batl":[[0,170,37.59]],"ltp":0.0,"tv":0.0,"id":11376562}]}]}
{"op":"mcm","clk":"4227337759","pt":1631454675865,"mc":[{"id":"1.187552248","rc":[{"batl":[[0,85,39.77]],"ltp":0.0,"tv":0.0,"id":11376562}]}]}
{"op":"mcm","clk":"4227341732","pt":1631454709259,"mc":[{"id":"1.187552248","rc":[{"batl":[[0,170,37.59]],"ltp":0.0,"tv":0.0,"id":11376562}]}]}
{"op":"mcm","clk":"4227346833","pt":1631454753458,"mc":[{"id":"1.187552248","rc":[{"batb":[[1,1.01,12],[2,1.01,0]],"ltp":0.0,"tv":0.0,"id":11376562}]}]}
{"op":"mcm","clk":"4227347495","pt":1631454759747,"mc":[{"id":"1.187552248","rc":[{"batb":[[1,4.4,379.68],[2,1.01,12]],"ltp":0.0,"tv":0.0,"id":11376562}]}]}
{"op":"mcm","clk":"4227422475","pt":1631455392983,"mc":[{"id":"1.187552248","rc":[{"trd":[[1.01,24]],"batl":[[0,1.01,5.08],[1,1.21,80],[2,11.5,8.68]],"ltp":1.01,"tv":23.99,"id":11862899}],"tv":23.99}]}
{"op":"mcm","clk":"4227468915","pt":1631455660134,"mc":[{"id":"1.187552248","rc":[{"batb":[[0,36,7.08],[1,6,2],[2,4.4,379.68]],"ltp":0.0,"tv":0.0,"id":11376562}]}]}
{"op":"mcm","clk":"4227497874","pt":1631455814054,"mc":[{"id":"1.187552248","rc":[{"batb":[[2,1.01,12]],"ltp":0.0,"tv":0.0,"id":11376562}]}]}
{"op":"mcm","clk":"4227622197","pt":1631456499736,"mc":[{"id":"1.187552248","rc":[{"batb":[[0,6,2],[1,1.01,12],[2,1.01,0]],"ltp":0.0,"tv":0.0,"id":11376562}]}]}
{"op":"mcm","clk":"4227623066","pt":1631456504817,"mc":[{"id":"1.187552248","rc":[{"batb":[[0,42,7.08],[1,6,2],[2,1.01,12]],"ltp":0.0,"tv":0.0,"id":11376562}]}]}
{"op":"mcm","clk":"4227749958","pt":1631457242929,"mc":[{"id":"1.187552248","rc":[{"batb":[[0,6,2],[1,1.01,12],[2,1.01,0]],"ltp":0.0,"tv":0.0,"id":11376562}]}]}
{"op":"mcm","clk":"4227750923","pt":1631457248032,"mc":[{"id":"1.187552248","rc":[{"batb":[[0,190,7.08],[1,6,2],[2,1.01,12]],"ltp":0.0,"tv":0.0,"id":11376562}]}]}
{"op":"mcm","clk":"4227751899","pt":1631457253321,"mc":[{"id":"1.187552248","rc":[{"batb":[[2,4.8,372.81]],"ltp":0.0,"tv":0.0,"id":11376562}]}]}
{"op":"mcm","clk":"4227752190","pt":1631457255240,"mc":[{"id":"1.187552248","rc":[{"batb":[[2,1.01,12]],"ltp":0.0,"tv":0.0,"id":11376562}]}]}
{"op":"mcm","clk":"4227792543","pt":1631457481373,"mc":[{"id":"1.187552248","rc":[{"batb":[[0,6,2],[1,1.01,12],[2,1.01,0]],"ltp":0.0,"tv":0.0,"id":11376562}]}]}
{"op":"mcm","clk":"4227793421","pt":1631457486485,"mc":[{"id":"1.187552248","rc":[{"batb":[[0,55,7.08],[1,6,2],[2,1.01,12]],"ltp":0.0,"tv":0.0,"id":11376562}]}]}
{"op":"mcm","clk":"4227794444","pt":1631457492090,"mc":[{"id":"1.187552248","rc":[{"batb":[[0,6,2],[1,1.01,12],[2,1.01,0]],"ltp":0.0,"tv":0.0,"id":11376562}]}]}
{"op":"mcm","clk":"4227795371","pt":1631457497218,"mc":[{"id":"1.187552248","rc":[{"batb":[[0,90,7.08],[1,6,2],[2,1.01,12]],"ltp":0.0,"tv":0.0,"id":11376562}]}]}
{"op":"mcm","clk":"4227870461","pt":1631457927467,"mc":[{"id":"1.187552248","marketDefinition":{"bspMarket":false,"turnInPlayEnabled":true,"persistenceEnabled":true,"marketBaseRate":5.0,"eventId":"30895222","eventTypeId":"2","numberOfWinners":1,"bettingType":"ODDS","marketType":"MATCH_ODDS","marketTime":"2021-09-12T13:40:35.000Z","suspendTime":"2021-09-12T13:40:35.000Z","bspReconciled":false,"complete":true,"inPlay":true,"crossMatching":true,"runnersVoidable":false,"numberOfActiveRunners":2,"betDelay":5,"status":"SUSPENDED","runners":[{"status":"ACTIVE","sortPriority":1,"id":11376562,"name":"A Santos"},{"status":"ACTIVE","sortPriority":2,"id":11862899,"name":"C Cervino Ruiz"}],"regulators":["MR_INT"],"countryCode":"GB","discountAllowed":true,"timezone":"GMT","openDate":"2021-09-12T13:40:35.000Z","version":4028688544,"name":"Match Odds","eventName":"A Santos v C Cervino Ruiz"}}]}
{"op":"mcm","clk":"4227871597","pt":1631457934482,"mc":[{"id":"1.187552248","marketDefinition":{"bspMarket":false,"turnInPlayEnabled":true,"persistenceEnabled":true,"marketBaseRate":5.0,"eventId":"30895222","eventTypeId":"2","numberOfWinners":1,"bettingType":"ODDS","marketType":"MATCH_ODDS","marketTime":"2021-09-12T13:40:35.000Z","suspendTime":"2021-09-12T13:40:35.000Z","bspReconciled":false,"complete":true,"inPlay":true,"crossMatching":false,"runnersVoidable":false,"numberOfActiveRunners":0,"betDelay":5,"status":"CLOSED","settledTime":"2021-09-12T14:45:32.000Z","runners":[{"status":"LOSER","sortPriority":1,"id":11376562,"name":"A Santos"},{"status":"WINNER","sortPriority":2,"id":11862899,"name":"C Cervino Ruiz"}],"regulators":["MR_INT"],"countryCode":"GB","discountAllowed":true,"timezone":"GMT","openDate":"2021-09-12T13:40:35.000Z","version":4028688692,"name":"Match Odds","eventName":"A Santos v C Cervino Ruiz"},"tv":0.0}]}
