{"op":"mcm","clk":"4225223594","pt":1631441384606,"mc":[{"id":"1.187552454","marketDefinition":{"bspMarket":false,"turnInPlayEnabled":true,"persistenceEnabled":true,"marketBaseRate":5.0,"eventId":"30895321","eventTypeId":"2","numberOfWinners":1,"bettingType":"ODDS","marketType":"MATCH_ODDS","marketTime":"2021-09-12T13:00:00.000Z","suspendTime":"2021-09-12T13:00:00.000Z","bspReconciled":false,"complete":true,"inPlay":false,"crossMatching":true,"runnersVoidable":false,"numberOfActiveRunners":2,"betDelay":0,"status":"OPEN","runners":[{"status":"ACTIVE","sortPriority":1,"id":9028621,"name":"Mayar Sherif"},{"status":"ACTIVE","sortPriority":2,"id":9345630,"name":"Martina Trevisan"}],"regulators":["MR_INT"],"discountAllowed":false,"timezone":"UTC","openDate":"2021-09-12T13:00:00.000Z","version":4027712328,"name":"Match Odds","eventName":"Ma Sherif v Trevisan"}}]}
{"op":"mcm","clk":"4225223911","pt":1631441386611,"mc":[{"id":"1.187552454","marketDefinition":{"bspMarket":false,"turnInPlayEnabled":true,"persistenceEnabled":true,"marketBaseRate":5.0,"eventId":"30895321","eventTypeId":"2","numberOfWinners":1,"bettingType":"ODDS","marketType":"MATCH_ODDS","marketTime":"2021-09-12T13:00:00.000Z","suspendTime":"2021-09-12T13:00:00.000Z","bspReconciled":false,"complete":true,"inPlay":false,"crossMatching":true,"runnersVoidable":false,"numberOfActiveRunners":2,"betDelay":0,"status":"OPEN","runners":[{"status":"ACTIVE","sortPriority":1,"id":9028621,"name":"Mayar Sherif"},{"status":"ACTIVE","sortPriority":2,"id":9345630,"name":"Martina Trevisan"}],"regulators":["MR_INT"],"discountAllowed":false,"timezone":"UTC","openDate":"2021-09-12T13:00:00.000Z","version":4027712328,"name":"Match Odds","eventName":"Ma Sherif v Trevisan"}}]}
{"op":"mcm","clk":"4225224089","pt":1631441387651,"mc":[{"id":"1.187552454","marketDefinition":{"bspMarket":false,"turnInPlayEnabled":true,"persistenceEnabled":true,"marketBaseRate":5.0,"eventId":"30895321","eventTypeId":"2","numberOfWinners":1,"bettingType":"ODDS","marketType":"MATCH_ODDS","marketTime":"2021-09-12T13:00:00.000Z","suspendTime":"2021-09-12T13:00:00.000Z","bspReconciled":false,"complete":true,"inPlay":false,"crossMatching":true,"runnersVoidable":false,"numberOfActiveRunners":2,"betDelay":0,"status":"OPEN","runners":[{"status":"ACTIVE","sortPriority":1,"id":9028621,"name":"Mayar Sherif"},{"status":"ACTIVE","sortPriority":2,"id":9345630,"name":"Martina Trevisan"}],"regulators":["MR_INT"],"discountAllowed":true,"timezone":"UTC","openDate":"2021-09-12T13:00:00.000Z","version":4027712328,"name":"Match Odds","eventName":"Ma Sherif v Trevisan"}}]}
{"op":"mcm","clk":"4225234709","pt":1631441458895,"mc":[{"id":"1.187552454","rc":[{"batb":[[0,1.01,25]],"ltp":0.0,"tv":0.0,"id":9345630},{"batb":[[0,1.01,25]],"ltp":0.0,"tv":0.0,"id":9028621}]}]}
{"op":"mcm","clk":"4225436679","pt":1631442860144,"mc":[{"id":"1.187552454","marketDefinition":{"bspMarket":false,"turnInPlayEnabled":true,"persistenceEnabled":true,"marketBaseRate":5.0,"eventId":"30895321","eventTypeId":"2","numberOfWinners":1,"bettingType":"ODDS","marketType":"MATCH_ODDS","marketTime":"2021-09-12T11:30:00.000Z","suspendTime":"2021-09-12T11:30:00.000Z","bspReconciled":false,"complete":true,"inPlay":false,"crossMatching":true,"runnersVoidable":false,"numberOfActiveRunners":2,"betDelay":0,"status":"OPEN","runners":[{"status":"ACTIVE","sortPriority":1,"id":9028621,"name":"Mayar Sherif"},{"status":"ACTIVE","sortPriority":2,"id":9345630,"name":"Martina Trevisan"}],"regulators":["MR_INT"],"discountAllowed":true,"timezone":"UTC","openDate":"2021-09-12T13:00:00.000Z","version":4027774934,"name":"Match Odds","eventName":"Ma Sherif v Trevisan"}}]}
{"op":"mcm","clk":"4225437174","pt":1631442863145,"mc":[{"id":"1.187552454","marketDefinition":{"bspMarket":false,"turnInPlayEnabled":true,"persistenceEnabled":true,"marketBaseRate":5.0,"eventId":"30895321","eventTypeId":"2","numberOfWinners":1,"bettingType":"ODDS","marketType":"MATCH_ODDS","marketTime":"2021-09-12T11:30:00.000Z","suspendTime":"2021-09-12T11:30:00.000Z","bspReconciled":false,"complete":true,"inPlay":false,"crossMatching":true,"runnersVoidable":false,"numberOfActiveRunners":2,"betDelay":0,"status":"OPEN","runners":[{"status":"ACTIVE","sortPriority":1,"id":9028621,"name":"Mayar Sherif"},{"status":"ACTIVE","sortPriority":2,"id":9345630,"name":"Martina Trevisan"}],"regulators":["MR_INT"],"discountAllowed":true,"timezone":"UTC","openDate":"2021-09-12T11:30:00.000Z","version":4027774934,"name":"Match Odds","eventName":"Ma Sherif v Trevisan"}}]}
{"op":"mcm","clk":"4225460424","pt":1631442989639,"mc":[{"id":"1.187552454","rc":[{"batl":[[0,29,48.37]],"ltp":0.0,"tv":0.0,"id":9345630},{"batl":[[0,29,48.37]],"ltp":0.0,"tv":0.0,"id":9028621}]}]}
{"op":"mcm","clk":"4225475087","pt":1631443080715,"mc":[{"id":"1.187552454","rc":[{"batb":[[0,1.05,879.5],[1,1.01,25]],"ltp":0.0,"tv":0.0,"id":9345630},{"batb":[[0,1.05,879.5],[1,1.01,25]],"ltp":0.0,"tv":0.0,"id":9028621}]}]}
{"op":"mcm","clk":"4225509664","pt":1631443294053,"mc":[{"id":"1.187552454","rc":[{"batb":[[0,1.76,55.1],[1,1.05,879.5],[2,1.01,25]],"ltp":0.0,"tv":0.0,"id":9345630},{"batb":[[0,1.41,73.65],[1,1.05,879.5],[2,1.01,25]],"ltp":0.0,"tv":0.0,"id":9028621}]}]}
{"op":"mcm","clk":"4225510244","pt":1631443297571,"mc":[{"id":"1.187552454","rc":[{"batb":[[0,2,45.09]],"ltp":0.0,"tv":0.0,"id":9345630},{"trd":[[1.8,112.24]],"batb":[[0,1.05,879.74],[1,1.01,25],[2,1.01,0]],"ltp":1.8,"tv":112.24,"id":9028621}],"tv":112.24}]}
{"op":"mcm","clk":"4225510277","pt":1631443297733,"mc":[{"id":"1.187552454","rc":[{"trd":[[1.8,112.72]],"batb":[[0,1.45,74.93],[1,1.05,879.5],[2,1.01,25]],"ltp":1.8,"tv":112.72,"id":9028621}],"tv":112.72}]}
{"op":"mcm","clk":"4225511093","pt":1631443302561,"mc":[{"id":"1.187552454","rc":[{"batb":[[0,1.72,62.62]],"ltp":1.8,"tv":112.72,"id":9028621}]}]}
{"op":"mcm","clk":"4225512405","pt":1631443310209,"mc":[{"id":"1.187552454","rc":[{"batb":[[0,2.02,48.8],[1,2,45.09],[2,1.05,879.5]],"ltp":0.0,"tv":0.0,"id":9345630}]}]}
{"op":"mcm","clk":"4225516963","pt":1631443336198,"mc":[{"id":"1.187552454","rc":[{"batl":[[0,5.6,13.78],[1,29,48.37]],"ltp":0.0,"tv":0.0,"id":9345630}]}]}
{"op":"mcm","clk":"4225517504","pt":1631443339703,"mc":[{"id":"1.187552454","rc":[{"batl":[[0,29,48.37],[1,29,0]],"ltp":0.0,"tv":0.0,"id":9345630}]}]}
{"op":"mcm","clk":"4225521186","pt":1631443362942,"mc":[{"id":"1.187552454","rc":[{"batb":[[0,2.1,40.99],[1,2.02,48.8]],"ltp":0.0,"tv":0.0,"id":9345630},{"batb":[[0,1.73,61.77]],"ltp":1.8,"tv":112.72,"id":9028621}]}]}
{"op":"mcm","clk":"4225525813","pt":1631443392440,"mc":[{"id":"1.187552454","rc":[{"batl":[[0,1.9,22.21],[1,29,48.37]],"ltp":1.8,"tv":112.72,"id":9028621}]}]}
{"op":"mcm","clk":"4225526166","pt":1631443395254,"mc":[{"id":"1.187552454","rc":[{"batb":[[0,2.14,46.04],[1,2.12,22.88],[2,2.1,40.99]],"ltp":0.0,"tv":0.0,"id":9345630},{"batb":[[0,1.74,34.62],[1,1.73,61.77],[2,1.05,879.5]],"ltp":1.8,"tv":112.72,"id":9028621}]}]}
{"op":"mcm","clk":"4225526872","pt":1631443399974,"mc":[{"id":"1.187552454","rc":[{"batl":[[0,3.05,3.75],[1,29,48.37]],"ltp":0.0,"tv":0.0,"id":9345630}]}]}
{"op":"mcm","clk":"4225542131","pt":1631443496924,"mc":[{"id":"1.187552454","rc":[{"batb":[[2,1.01,25]],"ltp":1.8,"tv":112.72,"id":9028621}]}]}
{"op":"mcm","clk":"4225544135","pt":1631443509932,"mc":[{"id":"1.187552454","rc":[{"batb":[[2,1.42,97.62]],"batl":[[1,2.8,43.98],[2,29,48.37]],"ltp":1.8,"tv":112.72,"id":9028621}]}]}
{"op":"mcm","clk":"4225558732","pt":1631443599391,"mc":[{"id":"1.187552454","rc":[{"batl":[[0,1.87,22.21]],"ltp":1.8,"tv":112.72,"id":9028621}]}]}
{"op":"mcm","clk":"4225558805","pt":1631443599762,"mc":[{"id":"1.187552454","rc":[{"batb":[[0,2.16,22.09],[1,2.14,46.04],[2,2.12,22.88]],"ltp":0.0,"tv":0.0,"id":9345630}]}]}
{"op":"mcm","clk":"4225565702","pt":1631443640309,"mc":[{"id":"1.187552454","rc":[{"batb":[[0,2.18,45.19],[1,2.16,22.09]],"ltp":0.0,"tv":0.0,"id":9345630}]}]}
{"op":"mcm","clk":"4225565785","pt":1631443640845,"mc":[{"id":"1.187552454","rc":[{"batb":[[0,2.18,66.9]],"ltp":0.0,"tv":0.0,"id":9345630},{"batb":[[0,1.73,96.87],[1,1.42,97.62],[2,1.01,25]],"ltp":1.8,"tv":112.72,"id":9028621}]}]}
{"op":"mcm","clk":"4225586077","pt":1631443700036,"mc":[{"id":"1.187552454","rc":[{"batl":[[0,3.5,7.8]],"ltp":0.0,"tv":0.0,"id":9345630}]}]}
{"op":"mcm","clk":"4225606623","pt":1631443829734,"mc":[{"id":"1.187552454","rc":[{"batl":[[0,1.83,8.68],[1,1.87,22.21],[2,2.8,43.98]],"ltp":1.8,"tv":112.72,"id":9028621}]}]}
{"op":"mcm","clk":"4225628236","pt":1631443983138,"mc":[{"id":"1.187552454","rc":[{"batb":[[0,2.18,44.38]],"batl":[[0,3.4,3.31]],"ltp":0.0,"tv":0.0,"id":9345630}]}]}
{"op":"mcm","clk":"4225649736","pt":1631444148027,"mc":[{"id":"1.187552454","rc":[{"batl":[[2,2.7,43.98]],"ltp":1.8,"tv":112.72,"id":9028621}]}]}
{"op":"mcm","clk":"4225661059","pt":1631444238773,"mc":[{"id":"1.187552454","rc":[{"batb":[[1,1.68,2.66],[2,1.42,97.62]],"ltp":1.8,"tv":112.72,"id":9028621}]}]}
{"op":"mcm","clk":"4225674630","pt":1631444354503,"mc":[{"id":"1.187552454","rc":[{"batb":[[0,2.22,7.65],[1,2.18,44.38],[2,2.16,22.09]],"ltp":0.0,"tv":0.0,"id":9345630},{"batb":[[0,1.74,8.58],[1,1.73,96.87],[2,1.68,2.66]],"ltp":1.8,"tv":112.72,"id":9028621}]}]}
{"op":"mcm","clk":"4225674734","pt":1631444355289,"mc":[{"id":"1.187552454","rc":[{"batb":[[1,2.18,66.09]],"ltp":0.0,"tv":0.0,"id":9345630},{"batb":[[1,1.73,61.77],[2,1.72,35.59]],"ltp":1.8,"tv":112.72,"id":9028621}]}]}
{"op":"mcm","clk":"4225682696","pt":1631444415395,"mc":[{"id":"1.187552454","rc":[{"batb":[[1,2.18,21.71]],"batl":[[0,29,48.37],[1,29,0]],"ltp":0.0,"tv":0.0,"id":9345630}]}]}
{"op":"mcm","clk":"4225683006","pt":1631444417565,"mc":[{"id":"1.187552454","rc":[{"batl":[[0,2.76,4.07],[1,29,48.37]],"ltp":0.0,"tv":0.0,"id":9345630}]}]}
{"op":"mcm","clk":"4225745100","pt":1631444807986,"mc":[{"id":"1.187552454","rc":[{"batl":[[2,2.6,43.98]],"ltp":1.8,"tv":112.72,"id":9028621}]}]}
{"op":"mcm","clk":"4225837896","pt":1631445354571,"mc":[{"id":"1.187552454","rc":[{"trd":[[2.16,126.84],[2.18,43.42],[2.2,7.22],[2.22,15.3]],"batb":[[0,2.16,12.58],[1,2.12,22.88],[2,2.1,43.65]],"batl":[[0,2.98,9.93]],"ltp":2.16,"tv":192.77,"id":9345630},{"trd":[[1.83,8.68]],"batb":[[0,1.76,10.28],[1,1.74,18.5],[2,1.73,61.77]],"batl":[[0,1.87,22.21],[1,2.6,43.98],[2,29,48.37]],"ltp":1.83,"tv":121.39,"id":9028621}],"tv":314.17}]}
{"op":"mcm","clk":"4225837943","pt":1631445354888,"mc":[{"id":"1.187552454","rc":[{"batb":[[1,2.1,43.65],[2,1.01,30]],"batl":[[0,29,48.37],[1,29,0]],"ltp":2.16,"tv":192.77,"id":9345630},{"batb":[[0,1.75,34.16],[1,1.74,77.01]],"ltp":1.83,"tv":121.39,"id":9028621}]}]}
{"op":"mcm","clk":"4225847028","pt":1631445412503,"mc":[{"id":"1.187552454","rc":[{"batb":[[1,1.74,58.51]],"ltp":1.83,"tv":121.39,"id":9028621}]}]}
{"op":"mcm","clk":"4225847064","pt":1631445412727,"mc":[{"id":"1.187552454","rc":[{"batb":[[0,1.76,12.39],[1,1.75,34.16]],"ltp":1.83,"tv":121.39,"id":9028621}]}]}
{"op":"mcm","clk":"4225847257","pt":1631445413924,"mc":[{"id":"1.187552454","rc":[{"batb":[[0,2.16,34.67]],"ltp":2.16,"tv":192.77,"id":9345630},{"batb":[[1,1.74,34.62]],"ltp":1.83,"tv":121.39,"id":9028621}]}]}
{"op":"mcm","clk":"4225849596","pt":1631445428425,"mc":[{"id":"1.187552454","rc":[{"batl":[[0,14,3.42],[1,29,48.37]],"ltp":2.16,"tv":192.77,"id":9345630}]}]}
{"op":"mcm","clk":"4225852963","pt":1631445449188,"mc":[{"id":"1.187552454","rc":[{"batb":[[0,2.16,79.06]],"ltp":2.16,"tv":192.77,"id":9345630}]}]}
{"op":"mcm","clk":"4225853961","pt":1631445455328,"mc":[{"id":"1.187552454","rc":[{"trd":[[2.16,339.52]],"batb":[[0,2.1,43.65],[1,1.01,30],[2,1.01,0]],"batl":[[0,14,3.43]],"ltp":2.16,"tv":405.45,"id":9345630}],"tv":526.85}]}
{"op":"mcm","clk":"4225854089","pt":1631445456244,"mc":[{"id":"1.187552454","rc":[{"trd":[[2.16,339.55]],"batb":[[0,2.12,8.99],[1,2.1,43.65],[2,1.01,30]],"batl":[[0,14,3.42]],"ltp":2.16,"tv":405.49,"id":9345630},{"batb":[[0,1.77,21.74]],"ltp":1.83,"tv":121.39,"id":9028621}],"tv":526.88}]}
{"op":"mcm","clk":"4225876180","pt":1631445595209,"mc":[{"id":"1.187552454","rc":[{"batb":[[0,2.12,53.4]],"batl":[[0,2.6,2.63],[1,14,3.42],[2,29,48.37]],"ltp":2.16,"tv":405.49,"id":9345630}]}]}
{"op":"mcm","clk":"4225878129","pt":1631445606553,"mc":[{"id":"1.187552454","rc":[{"batb":[[2,1.99,151.52]],"ltp":2.16,"tv":405.49,"id":9345630}]}]}
{"op":"mcm","clk":"4225880251","pt":1631445618251,"mc":[{"id":"1.187552454","rc":[{"batl":[[0,1.89,22.21]],"ltp":1.83,"tv":121.39,"id":9028621}]}]}
{"op":"mcm","clk":"4225880378","pt":1631445619043,"mc":[{"id":"1.187552454","rc":[{"batb":[[1,1.76,33.71],[2,1.74,34.62]],"ltp":1.83,"tv":121.39,"id":9028621}]}]}
{"op":"mcm","clk":"4225887419","pt":1631445661352,"mc":[{"id":"1.187552454","rc":[{"batb":[[0,1.79,9.4],[1,1.77,21.74],[2,1.76,33.71]],"ltp":1.83,"tv":121.39,"id":9028621}]}]}
{"op":"mcm","clk":"4225887548","pt":1631445662051,"mc":[{"id":"1.187552454","rc":[{"batb":[[1,1.77,55.01]],"ltp":1.83,"tv":121.39,"id":9028621}]}]}
{"op":"mcm","clk":"4225895906","pt":1631445712512,"mc":[{"id":"1.187552454","rc":[{"batb":[[1,1.77,33.27]],"ltp":1.83,"tv":121.39,"id":9028621}]}]}
{"op":"mcm","clk":"4225895995","pt":1631445713104,"mc":[{"id":"1.187552454","rc":[{"batb":[[0,1.8,14.63],[1,1.79,9.4],[2,1.78,32.85]],"ltp":1.83,"tv":121.39,"id":9028621}]}]}
{"op":"mcm","clk":"4225902429","pt":1631445753383,"mc":[{"id":"1.187552454","rc":[{"batl":[[1,29,48.37],[2,29,0]],"ltp":2.16,"tv":405.49,"id":9345630}]}]}
{"op":"mcm","clk":"4225923986","pt":1631445882387,"mc":[{"id":"1.187552454","rc":[{"batb":[[0,2.12,8.99]],"ltp":2.16,"tv":405.49,"id":9345630}]}]}
{"op":"mcm","clk":"4225925216","pt":1631445889934,"mc":[{"id":"1.187552454","rc":[{"batb":[[0,2.12,53.4]],"ltp":2.16,"tv":405.49,"id":9345630}]}]}
{"op":"mcm","clk":"4225926024","pt":1631445895076,"mc":[{"id":"1.187552454","rc":[{"batl":[[0,29,48.37],[1,29,0]],"ltp":2.16,"tv":405.49,"id":9345630}]}]}
{"op":"mcm","clk":"4225926369","pt":1631445897466,"mc":[{"id":"1.187552454","rc":[{"batl":[[0,1.87,5],[1,1.89,22.21],[2,2.6,43.98]],"ltp":1.83,"tv":121.39,"id":9028621}]}]}
{"op":"mcm","clk":"4225929614","pt":1631445917315,"mc":[{"id":"1.187552454","rc":[{"trd":[[1.8,122.32]],"batb":[[0,1.8,9.83],[2,1.76,33.71]],"ltp":1.8,"tv":130.99,"id":9028621}],"tv":536.48}]}
{"op":"mcm","clk":"4225968419","pt":1631446153961,"mc":[{"id":"1.187552454","rc":[{"batb":[[2,1.99,252.53]],"ltp":2.16,"tv":405.49,"id":9345630}]}]}
{"op":"mcm","clk":"4225969565","pt":1631446158799,"mc":[{"id":"1.187552454","marketDefinition":{"bspMarket":false,"turnInPlayEnabled":true,"persistenceEnabled":true,"marketBaseRate":5.0,"eventId":"30895321","eventTypeId":"2","numberOfWinners":1,"bettingType":"ODDS","marketType":"MATCH_ODDS","marketTime":"2021-09-12T11:35:00.000Z","suspendTime":"2021-09-12T11:35:00.000Z","bspReconciled":false,"complete":true,"inPlay":false,"crossMatching":true,"runnersVoidable":false,"numberOfActiveRunners":2,"betDelay":0,"status":"OPEN","runners":[{"status":"ACTIVE","sortPriority":1,"id":9028621,"name":"Mayar Sherif"},{"status":"ACTIVE","sortPriority":2,"id":9345630,"name":"Martina Trevisan"}],"regulators":["MR_INT"],"discountAllowed":true,"timezone":"UTC","openDate":"2021-09-12T11:30:00.000Z","version":4027913328,"name":"Match Odds","eventName":"Ma Sherif v Trevisan"}}]}
{"op":"mcm","clk":"4225970288","pt":1631446161833,"mc":[{"id":"1.187552454","marketDefinition":{"bspMarket":false,"turnInPlayEnabled":true,"persistenceEnabled":true,"marketBaseRate":5.0,"eventId":"30895321","eventTypeId":"2","numberOfWinners":1,"bettingType":"ODDS","marketType":"MATCH_ODDS","marketTime":"2021-09-12T11:35:00.000Z","suspendTime":"2021-09-12T11:35:00.000Z","bspReconciled":false,"complete":true,"inPlay":false,"crossMatching":true,"runnersVoidable":false,"numberOfActiveRunners":2,"betDelay":0,"status":"OPEN","runners":[{"status":"ACTIVE","sortPriority":1,"id":9028621,"name":"Mayar Sherif"},{"status":"ACTIVE","sortPriority":2,"id":9345630,"name":"Martina Trevisan"}],"regulators":["MR_INT"],"discountAllowed":true,"timezone":"UTC","openDate":"2021-09-12T11:35:00.000Z","version":4027913328,"name":"Match Odds","eventName":"Ma Sherif v Trevisan"}}]}
{"op":"mcm","clk":"4225976377","pt":1631446197403,"mc":[{"id":"1.187552454","rc":[{"batl":[[0,2.26,2],[1,29,48.37]],"ltp":2.16,"tv":405.49,"id":9345630},{"batb":[[2,1.78,32.85]],"batl":[[0,1.87,7]],"ltp":1.8,"tv":130.99,"id":9028621}]}]}
{"op":"mcm","clk":"4225981348","pt":1631446226467,"mc":[{"id":"1.187552454","rc":[{"batb":[[0,2.12,44.41]],"ltp":2.16,"tv":405.49,"id":9345630},{"trd":[[1.8,141.98]],"batb":[[0,1.79,9.4],[1,1.73,96.87],[2,1.72,35.59]],"batl":[[0,1.8,10.17],[1,1.87,7],[2,1.89,22.21]],"ltp":1.8,"tv":150.65,"id":9028621}],"tv":556.14}]}
{"op":"mcm","clk":"4225981375","pt":1631446226681,"mc":[{"id":"1.187552454","rc":[{"batb":[[0,2.16,12.55],[1,2.12,44.41],[2,2.1,43.65]],"ltp":2.16,"tv":405.49,"id":9345630},{"batb":[[0,1.79,15.39]],"ltp":1.8,"tv":150.65,"id":9028621}]}]}
{"op":"mcm","clk":"4225985408","pt":1631446253416,"mc":[{"id":"1.187552454","rc":[{"batb":[[1,2.1,43.65],[2,1.99,252.53]],"ltp":2.16,"tv":405.49,"id":9345630},{"trd":[[1.79,20.34]],"batb":[[0,1.79,5.22]],"batl":[[0,1.87,7],[1,1.89,22.21],[2,2.6,43.98]],"ltp":1.79,"tv":170.99,"id":9028621}],"tv":576.48}]}
{"op":"mcm","clk":"4225995536","pt":1631446312548,"mc":[{"id":"1.187552454","rc":[{"batb":[[0,1.74,21.8]],"ltp":1.79,"tv":170.99,"id":9028621}]}]}
{"op":"mcm","clk":"4225995704","pt":1631446313515,"mc":[{"id":"1.187552454","rc":[{"batb":[[0,1.75,34.16],[1,1.74,219.34],[2,1.73,100.87]],"ltp":1.79,"tv":170.99,"id":9028621}]}]}
{"op":"mcm","clk":"4225998707","pt":1631446330458,"mc":[{"id":"1.187552454","rc":[{"batb":[[1,1.74,26.8],[2,1.73,96.87]],"ltp":1.79,"tv":170.99,"id":9028621}]}]}
{"op":"mcm","clk":"4225998877","pt":1631446331464,"mc":[{"id":"1.187552454","rc":[{"batb":[[0,1.76,224.03],[1,1.75,34.16],[2,1.74,26.8]],"ltp":1.79,"tv":170.99,"id":9028621}]}]}
{"op":"mcm","clk":"4226001037","pt":1631446343533,"mc":[{"id":"1.187552454","rc":[{"batb":[[0,1.75,34.16],[1,1.74,26.8],[2,1.73,96.87]],"ltp":1.79,"tv":170.99,"id":9028621}]}]}
{"op":"mcm","clk":"4226002011","pt":1631446349470,"mc":[{"id":"1.187552454","rc":[{"batb":[[0,2.18,2],[1,2.16,163.22],[2,2.1,43.65]],"ltp":2.16,"tv":405.49,"id":9345630},{"batb":[[0,1.74,61.43],[1,1.73,96.87],[2,1.72,35.59]],"batl":[[0,1.86,3],[1,1.87,7],[2,1.89,22.21]],"ltp":1.79,"tv":170.99,"id":9028621}]}]}
{"op":"mcm","clk":"4226002291","pt":1631446351066,"mc":[{"id":"1.187552454","rc":[{"batb":[[0,2.2,2],[1,2.18,2],[2,2.16,150.67]],"ltp":2.16,"tv":405.49,"id":9345630},{"batb":[[0,1.74,34.62]],"batl":[[0,1.84,3],[1,1.86,3],[2,1.87,7]],"ltp":1.79,"tv":170.99,"id":9028621}]}]}
{"op":"mcm","clk":"4226003981","pt":1631446361499,"mc":[{"id":"1.187552454","rc":[{"batb":[[2,2.16,2]],"ltp":2.16,"tv":405.49,"id":9345630}]}]}
{"op":"mcm","clk":"4226004170","pt":1631446362574,"mc":[{"id":"1.187552454","rc":[{"batb":[[0,2.22,150.47],[1,2.2,2],[2,2.18,2]],"ltp":2.16,"tv":405.49,"id":9345630},{"batb":[[0,1.73,61.77],[1,1.72,35.59],[2,1.69,144.93]],"batl":[[0,1.83,3],[1,1.84,3],[2,1.86,3]],"ltp":1.79,"tv":170.99,"id":9028621}]}]}
{"op":"mcm","clk":"4226004276","pt":1631446363263,"mc":[{"id":"1.187552454","rc":[{"trd":[[2.26,4]],"batb":[[0,2.24,2],[1,2.22,150.47],[2,2.2,2]],"batl":[[0,3.05,11.13]],"ltp":2.26,"tv":409.49,"id":9345630},{"batl":[[0,1.81,3],[1,1.83,3],[2,1.84,3]],"ltp":1.79,"tv":170.99,"id":9028621}],"tv":580.48}]}
{"op":"mcm","clk":"4226019585","pt":1631446457756,"mc":[{"id":"1.187552454","marketDefinition":{"bspMarket":false,"turnInPlayEnabled":true,"persistenceEnabled":true,"marketBaseRate":5.0,"eventId":"30895321","eventTypeId":"2","numberOfWinners":1,"bettingType":"ODDS","marketType":"MATCH_ODDS","marketTime":"2021-09-12T11:40:00.000Z","suspendTime":"2021-09-12T11:40:00.000Z","bspReconciled":false,"complete":true,"inPlay":false,"crossMatching":true,"runnersVoidable":false,"numberOfActiveRunners":2,"betDelay":0,"status":"OPEN","runners":[{"status":"ACTIVE","sortPriority":1,"id":9028621,"name":"Mayar Sherif"},{"status":"ACTIVE","sortPriority":2,"id":9345630,"name":"Martina Trevisan"}],"regulators":["MR_INT"],"discountAllowed":true,"timezone":"UTC","openDate":"2021-09-12T11:35:00.000Z","version":4027933296,"name":"Match Odds","eventName":"Ma Sherif v Trevisan"}}]}
{"op":"mcm","clk":"4226020060","pt":1631446460443,"mc":[{"id":"1.187552454","marketDefinition":{"bspMarket":false,"turnInPlayEnabled":true,"persistenceEnabled":true,"marketBaseRate":5.0,"eventId":"30895321","eventTypeId":"2","numberOfWinners":1,"bettingType":"ODDS","marketType":"MATCH_ODDS","marketTime":"2021-09-12T11:40:00.000Z","suspendTime":"2021-09-12T11:40:00.000Z","bspReconciled":false,"complete":true,"inPlay":false,"crossMatching":true,"runnersVoidable":false,"numberOfActiveRunners":2,"betDelay":0,"status":"OPEN","runners":[{"status":"ACTIVE","sortPriority":1,"id":9028621,"name":"Mayar Sherif"},{"status":"ACTIVE","sortPriority":2,"id":9345630,"name":"Martina Trevisan"}],"regulators":["MR_INT"],"discountAllowed":true,"timezone":"UTC","openDate":"2021-09-12T11:40:00.000Z","version":4027933296,"name":"Match Odds","eventName":"Ma Sherif v Trevisan"},"rc":[{"batb":[[1,2.1,43.65],[2,1.99,252.53]],"batl":[[0,29,48.37],[1,29,0]],"ltp":2.26,"tv":409.49,"id":9345630},{"batl":[[1,1.87,7],[2,1.89,22.21]],"ltp":1.79,"tv":170.99,"id":9028621}]}]}
{"op":"mcm","clk":"4226020088","pt":1631446460659,"mc":[{"id":"1.187552454","rc":[{"batb":[[0,1.73,96.87]],"ltp":1.79,"tv":170.99,"id":9028621}]}]}
{"op":"mcm","clk":"4226021085","pt":1631446466985,"mc":[{"id":"1.187552454","rc":[{"batl":[[0,3.3,5.12],[1,29,48.37]],"ltp":2.26,"tv":409.49,"id":9345630}]}]}
{"op":"mcm","clk":"4226043447","pt":1631446611418,"mc":[{"id":"1.187552454","marketDefinition":{"bspMarket":false,"turnInPlayEnabled":true,"persistenceEnabled":true,"marketBaseRate":5.0,"eventId":"30895321","eventTypeId":"2","numberOfWinners":1,"bettingType":"ODDS","marketType":"MATCH_ODDS","marketTime":"2021-09-12T11:40:00.000Z","suspendTime":"2021-09-12T11:40:00.000Z","bspReconciled":false,"complete":true,"inPlay":true,"crossMatching":true,"runnersVoidable":false,"numberOfActiveRunners":2,"betDelay":3,"status":"OPEN","runners":[{"status":"ACTIVE","sortPriority":1,"id":9028621,"name":"Mayar Sherif"},{"status":"ACTIVE","sortPriority":2,"id":9345630,"name":"Martina Trevisan"}],"regulators":["MR_INT"],"discountAllowed":true,"timezone":"UTC","openDate":"2021-09-12T11:40:00.000Z","version":4027945483,"name":"Match Odds","eventName":"Ma Sherif v Trevisan"},"rc":[{"batb":[[0,1.01,30],[1,2.1,0],[2,1.99,0]],"ltp":2.26,"tv":409.49,"id":9345630},{"batb":[[0,1.01,30],[1,1.72,0],[2,1.69,0]],"batl":[[0,1.87,5],[1,1.87,0],[2,1.89,0]],"ltp":1.79,"tv":170.99,"id":9028621}]}]}
{"op":"mcm","clk":"4226046574","pt":1631446631389,"mc":[{"id":"1.187552454","rc":[{"batb":[[0,2.14,4],[1,2.12,4],[2,1.01,502.85]],"batl":[[0,2.18,3]],"ltp":2.26,"tv":409.49,"id":9345630},{"batb":[[0,1.84,5],[1,1.83,5],[2,1.01,506.85]],"batl":[[0,1.87,10]],"ltp":1.79,"tv":170.99,"id":9028621}]}]}
{"op":"mcm","clk":"4226047023","pt":1631446634530,"mc":[{"id":"1.187552454","rc":[{"batb":[[2,1.03,494.32]],"ltp":1.79,"tv":170.99,"id":9028621}]}]}
{"op":"mcm","clk":"4226047065","pt":1631446634843,"mc":[{"id":"1.187552454","rc":[{"batb":[[2,1.03,494.32]],"batl":[[0,2.2,4]],"ltp":2.26,"tv":409.49,"id":9345630}]}]}
{"op":"mcm","clk":"4226047560","pt":1631446637967,"mc":[{"id":"1.187552454","rc":[{"batb":[[0,1.05,474.54],[1,1.03,494.32],[2,1.01,502.85]],"ltp":2.26,"tv":409.49,"id":9345630},{"batb":[[0,1.05,474.54],[1,1.03,494.32],[2,1.01,506.85]],"batl":[[0,1.87,5]],"ltp":1.79,"tv":170.99,"id":9028621}]}]}
{"op":"mcm","clk":"4226048045","pt":1631446641236,"mc":[{"id":"1.187552454","rc":[{"batb":[[0,1.05,479.54],[1,1.04,4],[2,1.03,494.32]],"batl":[[0,21,2]],"ltp":2.26,"tv":409.49,"id":9345630},{"batb":[[0,1.11,269.63],[1,1.1,296.59],[2,1.09,353.11]],"ltp":1.79,"tv":170.99,"id":9028621}]}]}
{"op":"mcm","clk":"4226048564","pt":1631446644543,"mc":[{"id":"1.187552454","rc":[{"batb":[[0,1.05,474.54],[1,1.03,494.32],[2,1.01,502.85]],"batl":[[0,10.5,2],[1,11,3],[2,21,2]],"ltp":2.26,"tv":409.49,"id":9345630}]}]}
{"op":"mcm","clk":"4226049529","pt":1631446650553,"mc":[{"id":"1.187552454","rc":[{"trd":[[2.14,4.37]],"ltp":2.14,"tv":413.86,"id":9345630},{"trd":[[1.87,5]],"ltp":1.87,"tv":175.99,"id":9028621}],"tv":589.85}]}
{"op":"mcm","clk":"4226049999","pt":1631446653468,"mc":[{"id":"1.187552454","rc":[{"batb":[[0,1.96,4],[1,1.95,4],[2,1.09,353.11]],"batl":[[0,2.04,4],[1,10.5,2],[2,11,3]],"ltp":2.14,"tv":413.86,"id":9345630},{"batb":[[0,1.96,4],[1,1.95,4],[2,1.2,385.57]],"batl":[[0,2.04,4]],"ltp":1.87,"tv":175.99,"id":9028621}]}]}
{"op":"mcm","clk":"4226050037","pt":1631446653757,"mc":[{"id":"1.187552454","rc":[{"batl":[[1,21,2]],"ltp":1.87,"tv":175.99,"id":9028621}]}]}
{"op":"mcm","clk":"4226050550","pt":1631446657246,"mc":[{"id":"1.187552454","rc":[{"batl":[[1,10.5,0],[2,11,0]],"ltp":2.14,"tv":413.86,"id":9345630},{"batb":[[2,1.4,148.3]],"ltp":1.87,"tv":175.99,"id":9028621}]}]}
{"op":"mcm","clk":"4226053202","pt":1631446675394,"mc":[{"id":"1.187552454","rc":[{"trd":[[2.04,4]],"batb":[[1,1.09,353.11],[2,1.05,474.54]],"ltp":2.04,"tv":417.86,"id":9345630},{"trd":[[1.95,8],[1.96,12.16]],"batb":[[0,1.4,148.3],[1,1.3,197.73],[2,1.2,385.57]],"batl":[[1,21,0]],"ltp":1.95,"tv":196.15,"id":9028621}],"tv":614.01}]}
{"op":"mcm","clk":"4226053383","pt":1631446676504,"mc":[{"id":"1.187552454","rc":[{"batl":[[0,2,100]],"ltp":2.04,"tv":417.86,"id":9345630}]}]}
{"op":"mcm","clk":"4226053695","pt":1631446678495,"mc":[{"id":"1.187552454","rc":[{"trd":[[2,20]],"batb":[[1,1.11,269.63],[2,1.1,296.59]],"batl":[[0,2,88],[1,2.16,3]],"ltp":2.0,"tv":437.86,"id":9345630},{"trd":[[2,4]],"batb":[[0,1.86,4],[1,1.85,4],[2,1.4,155.3]],"ltp":2.0,"tv":200.15,"id":9028621}],"tv":638.01}]}
{"op":"mcm","clk":"4226053719","pt":1631446678700,"mc":[{"id":"1.187552454","rc":[{"batb":[[1,1.95,4],[2,1.11,269.63]],"batl":[[2,3.5,3]],"ltp":2.0,"tv":437.86,"id":9345630}]}]}
{"op":"mcm","clk":"4226054202","pt":1631446681792,"mc":[{"id":"1.187552454","rc":[{"batb":[[2,1.2,444.88]],"ltp":2.0,"tv":437.86,"id":9345630}]}]}
{"op":"mcm","clk":"4226054721","pt":1631446685316,"mc":[{"id":"1.187552454","rc":[{"batb":[[2,1.4,148.3]],"ltp":2.0,"tv":437.86,"id":9345630}]}]}
{"op":"mcm","clk":"4226056489","pt":1631446697440,"mc":[{"id":"1.187552454","rc":[{"batb":[[0,1.4,148.3],[1,1.3,197.73],[2,1.2,444.88]],"ltp":2.0,"tv":437.86,"id":9345630},{"batb":[[0,1.4,155.3],[1,1.3,197.73],[2,1.2,385.57]],"ltp":2.0,"tv":200.15,"id":9028621}]}]}
{"op":"mcm","clk":"4226056959","pt":1631446700569,"mc":[{"id":"1.187552454","rc":[{"batb":[[0,1.4,155.3],[1,1.39,6],[2,1.3,197.73]],"ltp":2.0,"tv":437.86,"id":9345630},{"batb":[[1,1.39,7],[2,1.3,197.73]],"ltp":2.0,"tv":200.15,"id":9028621}]}]}
{"op":"mcm","clk":"4226056979","pt":1631446700725,"mc":[{"id":"1.187552454","rc":[{"batl":[[0,3.5,3]],"ltp":2.0,"tv":437.86,"id":9345630},{"batl":[[0,3.5,3]],"ltp":2.0,"tv":200.15,"id":9028621}]}]}
{"op":"mcm","clk":"4226058819","pt":1631446712922,"mc":[{"id":"1.187552454","rc":[{"batb":[[1,1.3,197.73],[2,1.2,444.88]],"ltp":2.0,"tv":437.86,"id":9345630},{"batb":[[1,1.3,197.73],[2,1.2,385.57]],"batl":[[0,2,15.49],[1,3.5,3]],"ltp":2.0,"tv":200.15,"id":9028621}]}]}
{"op":"mcm","clk":"4226059314","pt":1631446716134,"mc":[{"id":"1.187552454","rc":[{"batb":[[1,1.39,8],[2,1.3,197.73]],"ltp":2.0,"tv":437.86,"id":9345630},{"batb":[[0,1.76,4],[1,1.75,4],[2,1.4,155.3]],"batl":[[0,2,19.49]],"ltp":2.0,"tv":200.15,"id":9028621}]}]}
{"op":"mcm","clk":"4226059774","pt":1631446719344,"mc":[{"id":"1.187552454","rc":[{"batb":[[0,2.2,3],[1,2.18,3],[2,2,3]],"batl":[[0,2.32,4],[1,3.5,3]],"ltp":2.0,"tv":437.86,"id":9345630},{"batl":[[0,2,4]],"ltp":2.0,"tv":200.15,"id":9028621}]}]}
{"op":"mcm","clk":"4226059824","pt":1631446719622,"mc":[{"id":"1.187552454","rc":[{"batb":[[0,2,3],[1,1.99,3],[2,1.5,106.77]],"ltp":2.0,"tv":437.86,"id":9345630}]}]}
{"op":"mcm","clk":"4226060290","pt":1631446722548,"mc":[{"id":"1.187552454","rc":[{"batl":[[0,1.84,5],[1,1.97,15.49],[2,2,4]],"ltp":2.0,"tv":200.15,"id":9028621}]}]}
{"op":"mcm","clk":"4226060654","pt":1631446725138,"mc":[{"id":"1.187552454","rc":[{"batb":[[0,2.02,4],[1,2,3],[2,1.99,3]],"ltp":2.0,"tv":437.86,"id":9345630},{"batl":[[1,1.97,19.49]],"ltp":2.0,"tv":200.15,"id":9028621}]}]}
{"op":"mcm","clk":"4226060760","pt":1631446725832,"mc":[{"id":"1.187552454","rc":[{"batb":[[0,2.16,4],[1,2.02,4],[2,2,3]],"ltp":2.0,"tv":437.86,"id":9345630}]}]}
{"op":"mcm","clk":"4226061450","pt":1631446729918,"mc":[{"id":"1.187552454","rc":[{"batb":[[0,1.6,98.86],[1,1.5,106.77],[2,1.4,155.3]],"batl":[[0,3.5,3],[1,3.5,0]],"ltp":2.0,"tv":437.86,"id":9345630},{"batb":[[0,1.4,155.3],[1,1.3,197.73],[2,1.2,385.57]],"ltp":2.0,"tv":200.15,"id":9028621}]}]}
{"op":"mcm","clk":"4226061936","pt":1631446733257,"mc":[{"id":"1.187552454","rc":[{"batb":[[0,1.6,104.86],[1,1.59,6],[2,1.5,106.77]],"ltp":2.0,"tv":437.86,"id":9345630},{"batb":[[1,1.39,5],[2,1.3,197.73]],"batl":[[0,2.68,4]],"ltp":2.0,"tv":200.15,"id":9028621}]}]}
{"op":"mcm","clk":"4226068005","pt":1631446772475,"mc":[{"id":"1.187552454","rc":[{"batl":[[0,2.5,31.82],[1,3.5,3]],"ltp":2.0,"tv":437.86,"id":9345630},{"batl":[[0,1.72,65.49],[1,2.68,4]],"ltp":2.0,"tv":200.15,"id":9028621}]}]}
{"op":"mcm","clk":"4226068063","pt":1631446772734,"mc":[{"id":"1.187552454","rc":[{"batb":[[1,1.5,106.77],[2,1.4,148.3]],"batl":[[0,3.5,3],[1,3.5,0]],"ltp":2.0,"tv":437.86,"id":9345630},{"batb":[[0,1.4,7],[1,1.3,197.73],[2,1.2,385.57]],"batl":[[0,2.68,4],[1,2.68,0]],"ltp":2.0,"tv":200.15,"id":9028621}]}]}
{"op":"mcm","clk":"4226068570","pt":1631446775986,"mc":[{"id":"1.187552454","rc":[{"batb":[[1,1.59,5],[2,1.5,106.77]],"batl":[[0,2.5,4],[1,3.5,3]],"ltp":2.0,"tv":437.86,"id":9345630},{"batb":[[0,1.66,5],[1,1.65,5],[2,1.4,7]],"ltp":2.0,"tv":200.15,"id":9028621}]}]}
{"op":"mcm","clk":"4226069550","pt":1631446782295,"mc":[{"id":"1.187552454","rc":[{"batb":[[0,1.65,4],[1,1.64,4],[2,1.6,104.86]],"ltp":2.0,"tv":437.86,"id":9345630},{"batl":[[0,2.52,3],[1,2.68,4]],"ltp":2.0,"tv":200.15,"id":9028621}]}]}
{"op":"mcm","clk":"4226070139","pt":1631446786401,"mc":[{"id":"1.187552454","rc":[{"batb":[[0,1.82,3.43],[1,1.65,4],[2,1.64,4]],"ltp":2.0,"tv":437.86,"id":9345630}]}]}
{"op":"mcm","clk":"4226070608","pt":1631446789490,"mc":[{"id":"1.187552454","rc":[{"batb":[[0,1.65,4],[1,1.64,4],[2,1.6,104.86]],"ltp":2.0,"tv":437.86,"id":9345630}]}]}
{"op":"mcm","clk":"4226070639","pt":1631446789704,"mc":[{"id":"1.187552454","rc":[{"batb":[[0,1.82,4],[1,1.81,4],[2,1.65,4]],"batl":[[1,3.5,0]],"ltp":2.0,"tv":437.86,"id":9345630},{"batb":[[1,1.3,197.73],[2,1.2,385.57]],"batl":[[0,2.22,4],[1,2.52,3],[2,2.68,4]],"ltp":2.0,"tv":200.15,"id":9028621}]}]}
{"op":"mcm","clk":"4226071110","pt":1631446792899,"mc":[{"id":"1.187552454","rc":[{"batb":[[1,1.65,5],[2,1.3,197.73]],"ltp":2.0,"tv":200.15,"id":9028621}]}]}
{"op":"mcm","clk":"4226073013","pt":1631446805505,"mc":[{"id":"1.187552454","rc":[{"trd":[[2.5,4]],"batl":[[0,2.7,31.72]],"ltp":2.5,"tv":441.86,"id":9345630},{"trd":[[1.65,10],[1.66,16.02]],"batb":[[0,1.3,197.73],[1,1.2,385.57],[2,1.11,269.63]],"batl":[[0,1.64,60.09],[1,2.22,4],[2,2.52,3]],"ltp":1.65,"tv":226.17,"id":9028621}],"tv":668.03}]}
{"op":"mcm","clk":"4226073052","pt":1631446805729,"mc":[{"id":"1.187552454","rc":[{"batb":[[1,1.6,98.86],[2,1.5,106.77]],"ltp":2.5,"tv":441.86,"id":9345630},{"batl":[[0,2.22,4],[1,2.22,0],[2,2.52,0]],"ltp":1.65,"tv":226.17,"id":9028621}]}]}
{"op":"mcm","clk":"4226073373","pt":1631446807626,"mc":[{"id":"1.187552454","rc":[{"batb":[[0,1.83,3.41],[1,1.82,4],[2,1.6,98.86]],"ltp":2.5,"tv":441.86,"id":9345630}]}]}
{"op":"mcm","clk":"4226073591","pt":1631446808908,"mc":[{"id":"1.187552454","rc":[{"batb":[[2,1.81,5]],"batl":[[0,2.52,3],[1,2.7,3],[2,4.4,2]],"ltp":2.5,"tv":441.86,"id":9345630},{"batb":[[0,1.58,6],[1,1.57,6],[2,1.3,205.73]],"ltp":1.65,"tv":226.17,"id":9028621}]}]}
{"op":"mcm","clk":"4226073892","pt":1631446810812,"mc":[{"id":"1.187552454","rc":[{"batb":[[0,1.83,7.41]],"ltp":2.5,"tv":441.86,"id":9345630}]}]}
{"op":"mcm","clk":"4226074061","pt":1631446811938,"mc":[{"id":"1.187552454","rc":[{"batb":[[0,1.65,5],[1,1.64,4],[2,1.58,6]],"ltp":1.65,"tv":226.17,"id":9028621}]}]}
{"op":"mcm","clk":"4226075120","pt":1631446818490,"mc":[{"id":"1.187552454","rc":[{"batb":[[0,1.83,4]],"ltp":2.5,"tv":441.86,"id":9345630}]}]}
{"op":"mcm","clk":"4226075573","pt":1631446821462,"mc":[{"id":"1.187552454","rc":[{"batl":[[0,2.4,50],[1,2.52,3],[2,2.7,3]],"ltp":2.5,"tv":441.86,"id":9345630}]}]}
{"op":"mcm","clk":"4226075627","pt":1631446821783,"mc":[{"id":"1.187552454","rc":[{"batb":[[1,1.6,98.86],[2,1.5,106.77]],"batl":[[2,2.7,0]],"ltp":2.5,"tv":441.86,"id":9345630},{"batb":[[2,1.3,197.73]],"ltp":1.65,"tv":226.17,"id":9028621}]}]}
{"op":"mcm","clk":"4226075989","pt":1631446824179,"mc":[{"id":"1.187552454","rc":[{"batb":[[1,1.3,197.73],[2,1.2,385.57]],"batl":[[0,2.08,27.55],[1,2.22,4]],"ltp":1.65,"tv":226.17,"id":9028621}]}]}
{"op":"mcm","clk":"4226076103","pt":1631446824982,"mc":[{"id":"1.187552454","rc":[{"batb":[[1,1.82,5],[2,1.6,98.86]],"batl":[[0,2.4,53]],"ltp":2.5,"tv":441.86,"id":9345630},{"batb":[[0,1.71,4],[1,1.7,5],[2,1.65,5]],"ltp":1.65,"tv":226.17,"id":9028621}]}]}
{"op":"mcm","clk":"4226076462","pt":1631446827288,"mc":[{"id":"1.187552454","rc":[{"batb":[[0,1.92,4],[1,1.91,5],[2,1.83,4]],"ltp":2.5,"tv":441.86,"id":9345630},{"batl":[[0,2.08,32.55]],"ltp":1.65,"tv":226.17,"id":9028621}]}]}
{"op":"mcm","clk":"4226076596","pt":1631446828053,"mc":[{"id":"1.187552454","rc":[{"batb":[[2,1.66,50]],"ltp":1.65,"tv":226.17,"id":9028621}]}]}
{"op":"mcm","clk":"4226077126","pt":1631446831294,"mc":[{"id":"1.187552454","rc":[{"batb":[[0,1.93,13.96],[1,1.92,4],[2,1.91,5]],"ltp":2.5,"tv":441.86,"id":9345630}]}]}
{"op":"mcm","clk":"4226077639","pt":1631446834454,"mc":[{"id":"1.187552454","rc":[{"batb":[[0,1.93,18.96]],"ltp":2.5,"tv":441.86,"id":9345630}]}]}
{"op":"mcm","clk":"4226077812","pt":1631446835630,"mc":[{"id":"1.187552454","rc":[{"batb":[[2,1.65,5]],"ltp":1.65,"tv":226.17,"id":9028621}]}]}
{"op":"mcm","clk":"4226078340","pt":1631446839291,"mc":[{"id":"1.187552454","rc":[{"batb":[[1,1.6,98.86],[2,1.5,106.77]],"batl":[[1,2.52,0]],"ltp":2.5,"tv":441.86,"id":9345630},{"batb":[[0,1.72,50],[1,1.71,4],[2,1.3,197.73]],"batl":[[1,2.22,0]],"ltp":1.65,"tv":226.17,"id":9028621}]}]}
{"op":"mcm","clk":"4226078799","pt":1631446842489,"mc":[{"id":"1.187552454","rc":[{"batb":[[1,1.92,4],[2,1.6,98.86]],"ltp":2.5,"tv":441.86,"id":9345630}]}]}
{"op":"mcm","clk":"4226079276","pt":1631446845631,"mc":[{"id":"1.187552454","rc":[{"trd":[[1.72,10.12]],"batb":[[0,1.72,44.94]],"ltp":1.72,"tv":236.29,"id":9028621}],"tv":678.15}]}
{"op":"mcm","clk":"4226079611","pt":1631446847915,"mc":[{"id":"1.187552454","rc":[{"trd":[[1.93,17.42]],"batb":[[0,1.93,5]],"ltp":1.93,"tv":459.28,"id":9345630}],"tv":695.57}]}
{"op":"mcm","clk":"4226080561","pt":1631446854531,"mc":[{"id":"1.187552454","rc":[{"batb":[[1,1.6,98.86],[2,1.5,106.77]],"ltp":1.93,"tv":459.28,"id":9345630},{"batb":[[1,1.3,197.73],[2,1.2,385.57]],"batl":[[0,1.9,8.54],[1,2.08,32.55]],"ltp":1.72,"tv":236.29,"id":9028621}]}]}
{"op":"mcm","clk":"4226081047","pt":1631446857739,"mc":[{"id":"1.187552454","rc":[{"batb":[[0,2.1,4],[1,2.08,4],[2,1.93,5]],"ltp":1.93,"tv":459.28,"id":9345630},{"batl":[[0,1.9,12.54]],"ltp":1.72,"tv":236.29,"id":9028621}]}]}
{"op":"mcm","clk":"4226081322","pt":1631446859423,"mc":[{"id":"1.187552454","rc":[{"batl":[[0,1.84,4],[1,1.9,12.54],[2,2.08,32.55]],"ltp":1.72,"tv":236.29,"id":9028621}]}]}
{"op":"mcm","clk":"4226081368","pt":1631446859729,"mc":[{"id":"1.187552454","rc":[{"batl":[[0,1.9,12.54],[1,2.08,32.55],[2,2.08,0]],"ltp":1.72,"tv":236.29,"id":9028621}]}]}
{"op":"mcm","clk":"4226081785","pt":1631446862570,"mc":[{"id":"1.187552454","rc":[{"batl":[[0,1.84,4],[1,1.9,12.54],[2,2.08,32.55]],"ltp":1.72,"tv":236.29,"id":9028621}]}]}
{"op":"mcm","clk":"4226082613","pt":1631446867891,"mc":[{"id":"1.187552454","rc":[{"batl":[[1,1.9,4]],"ltp":1.72,"tv":236.29,"id":9028621}]}]}
{"op":"mcm","clk":"4226083142","pt":1631446871199,"mc":[{"id":"1.187552454","rc":[{"batb":[[1,1.6,98.86],[2,1.5,106.77]],"ltp":1.93,"tv":459.28,"id":9345630},{"batl":[[0,1.81,8.54],[1,1.84,4],[2,2.08,27.55]],"ltp":1.72,"tv":236.29,"id":9028621}]}]}
{"op":"mcm","clk":"4226084946","pt":1631446882319,"mc":[{"id":"1.187552454","rc":[{"trd":[[2.4,8]],"ltp":2.4,"tv":467.28,"id":9345630},{"trd":[[1.72,45.28]],"batb":[[0,1.72,21.78]],"ltp":1.72,"tv":271.45,"id":9028621}],"tv":738.73}]}
{"op":"mcm","clk":"4226085121","pt":1631446883404,"mc":[{"id":"1.187552454","rc":[{"batb":[[2,1.25,237.27]],"ltp":1.72,"tv":271.45,"id":9028621}]}]}
{"op":"mcm","clk":"4226085308","pt":1631446884517,"mc":[{"id":"1.187552454","rc":[{"trd":[[1.72,88.84]],"batb":[[0,1.3,197.73],[1,1.25,237.27],[2,1.2,385.57]],"batl":[[0,1.72,110.6],[1,1.81,8.54],[2,1.84,4]],"ltp":1.72,"tv":315.01,"id":9028621}],"tv":782.29}]}
{"op":"mcm","clk":"4226085452","pt":1631446885537,"mc":[{"id":"1.187552454","rc":[{"batb":[[0,2.22,4],[1,2.2,4],[2,2.1,4]],"ltp":2.4,"tv":467.28,"id":9345630},{"batl":[[0,1.72,361.18],[1,1.81,12.54]],"ltp":1.72,"tv":315.01,"id":9028621}]}]}
{"op":"mcm","clk":"4226085598","pt":1631446886553,"mc":[{"id":"1.187552454","rc":[{"batl":[[0,1.72,577.61]],"ltp":1.72,"tv":315.01,"id":9028621}]}]}
{"op":"mcm","clk":"4226085762","pt":1631446887520,"mc":[{"id":"1.187552454","rc":[{"batb":[[0,2.38,4],[1,2.36,3],[2,2.22,4]],"batl":[[0,4.4,3]],"ltp":2.4,"tv":467.28,"id":9345630},{"batb":[[0,1.3,201.73],[1,1.29,4],[2,1.25,237.27]],"batl":[[0,1.72,190.21]],"ltp":1.72,"tv":315.01,"id":9028621}]}]}
{"op":"mcm","clk":"4226085894","pt":1631446888441,"mc":[{"id":"1.187552454","rc":[{"batb":[[0,1.31,188.59],[1,1.3,201.73],[2,1.29,4]],"batl":[[0,1.72,190.48]],"ltp":1.72,"tv":315.01,"id":9028621}]}]}
{"op":"mcm","clk":"4226086058","pt":1631446889560,"mc":[{"id":"1.187552454","rc":[{"batl":[[0,2.92,4],[1,4.4,3]],"ltp":2.4,"tv":467.28,"id":9345630},{"batl":[[0,1.72,125.38]],"ltp":1.72,"tv":315.01,"id":9028621}]}]}
{"op":"mcm","clk":"4226086203","pt":1631446890509,"mc":[{"id":"1.187552454","rc":[{"batl":[[0,3.1,2.41]],"ltp":2.4,"tv":467.28,"id":9345630},{"batb":[[0,1.3,201.73],[1,1.29,4],[2,1.25,237.27]],"batl":[[0,1.72,81.82]],"ltp":1.72,"tv":315.01,"id":9028621}]}]}
{"op":"mcm","clk":"4226086284","pt":1631446891050,"mc":[{"id":"1.187552454","rc":[{"batl":[[0,4.3,2]],"ltp":2.4,"tv":467.28,"id":9345630},{"batb":[[0,1.31,9],[1,1.3,201.73],[2,1.29,4]],"batl":[[0,1.72,46.77]],"ltp":1.72,"tv":315.01,"id":9028621}]}]}
{"op":"mcm","clk":"4226086403","pt":1631446891755,"mc":[{"id":"1.187552454","rc":[{"batl":[[0,1.72,6]],"ltp":1.72,"tv":315.01,"id":9028621}]}]}
{"op":"mcm","clk":"4226086664","pt":1631446893488,"mc":[{"id":"1.187552454","rc":[{"batb":[[0,1.32,182.05],[1,1.31,9],[2,1.3,201.73]],"ltp":1.72,"tv":315.01,"id":9028621}]}]}
{"op":"mcm","clk":"4226086826","pt":1631446894471,"mc":[{"id":"1.187552454","rc":[{"batl":[[0,3.1,3],[1,4.3,2],[2,4.4,3]],"ltp":2.4,"tv":467.28,"id":9345630},{"batb":[[0,1.47,6],[1,1.46,6],[2,1.31,9]],"ltp":1.72,"tv":315.01,"id":9028621}]}]}
{"op":"mcm","clk":"4226086878","pt":1631446894738,"mc":[{"id":"1.187552454","rc":[{"batl":[[1,1.81,4]],"ltp":1.72,"tv":315.01,"id":9028621}]}]}
{"op":"mcm","clk":"4226087111","pt":1631446896358,"mc":[{"id":"1.187552454","rc":[{"batb":[[0,1.5,5],[1,1.47,6],[2,1.46,6]],"ltp":1.72,"tv":315.01,"id":9028621}]}]}
{"op":"mcm","clk":"4226087183","pt":1631446896663,"mc":[{"id":"1.187552454","rc":[{"batl":[[1,4.2,3],[2,4.3,2]],"ltp":2.4,"tv":467.28,"id":9345630}]}]}
{"op":"mcm","clk":"4226087690","pt":1631446899517,"mc":[{"id":"1.187552454","rc":[{"batb":[[1,1.49,5],[2,1.47,6]],"ltp":1.72,"tv":315.01,"id":9028621}]}]}
{"op":"mcm","clk":"4226087733","pt":1631446899744,"mc":[{"id":"1.187552454","rc":[{"batb":[[1,1.6,98.86],[2,1.5,106.77]],"batl":[[0,3,3],[1,3.1,3],[2,4.2,3]],"ltp":2.4,"tv":467.28,"id":9345630},{"batl":[[1,2.08,27.55],[2,1.84,0]],"ltp":1.72,"tv":315.01,"id":9028621}]}]}
{"op":"mcm","clk":"4226088262","pt":1631446903274,"mc":[{"id":"1.187552454","rc":[{"batb":[[0,1.6,98.86],[1,1.5,106.77],[2,1.4,148.3]],"ltp":2.4,"tv":467.28,"id":9345630},{"batl":[[0,2.08,27.55],[1,2.08,0]],"ltp":1.72,"tv":315.01,"id":9028621}]}]}
{"op":"mcm","clk":"4226088804","pt":1631446906576,"mc":[{"id":"1.187552454","rc":[{"batb":[[0,2.18,3],[1,2.16,4],[2,1.92,5]],"batl":[[0,2.54,35],[1,3,3],[2,3.1,3]],"ltp":2.4,"tv":467.28,"id":9345630},{"batb":[[2,1.32,5]],"batl":[[0,2.08,31.55]],"ltp":1.72,"tv":315.01,"id":9028621}]}]}
{"op":"mcm","clk":"4226089288","pt":1631446909988,"mc":[{"id":"1.187552454","rc":[{"batl":[[0,3,3],[1,3,0],[2,3.1,0]],"ltp":2.4,"tv":467.28,"id":9345630},{"batb":[[2,1.3,197.73]],"batl":[[0,1.85,4],[1,2.08,31.55]],"ltp":1.72,"tv":315.01,"id":9028621}]}]}
{"op":"mcm","clk":"4226090027","pt":1631446914485,"mc":[{"id":"1.187552454","rc":[{"batb":[[1,1.3,197.73],[2,1.25,237.27]],"ltp":1.72,"tv":315.01,"id":9028621}]}]}
{"op":"mcm","clk":"4226090179","pt":1631446915501,"mc":[{"id":"1.187552454","rc":[{"batb":[[0,2.84,4],[1,2.18,3],[2,2.16,4]],"ltp":2.4,"tv":467.28,"id":9345630},{"batl":[[0,1.56,6],[1,1.85,4],[2,2.08,31.55]],"ltp":1.72,"tv":315.01,"id":9028621}]}]}
{"op":"mcm","clk":"4226090212","pt":1631446915668,"mc":[{"id":"1.187552454","rc":[{"batb":[[1,1.25,237.27],[2,1.2,385.57]],"ltp":1.72,"tv":315.01,"id":9028621}]}]}
{"op":"mcm","clk":"4226090586","pt":1631446918305,"mc":[{"id":"1.187552454","rc":[{"batb":[[2,1.6,98.86]],"ltp":2.4,"tv":467.28,"id":9345630},{"batb":[[1,1.49,6],[2,1.25,237.27]],"ltp":1.72,"tv":315.01,"id":9028621}]}]}
{"op":"mcm","clk":"4226090631","pt":1631446918601,"mc":[{"id":"1.187552454","rc":[{"trd":[[3,0.03]],"batl":[[0,3,2.97]],"ltp":3.0,"tv":467.31,"id":9345630},{"trd":[[1.5,10.06]],"batb":[[0,1.49,6],[1,1.25,237.27],[2,1.2,385.57]],"ltp":1.5,"tv":325.07,"id":9028621}],"tv":792.38}]}
{"op":"mcm","clk":"4226090841","pt":1631446919910,"mc":[{"id":"1.187552454","rc":[{"trd":[[3,3]],"ltp":3.0,"tv":470.28,"id":9345630},{"trd":[[1.5,16]],"ltp":1.5,"tv":331.01,"id":9028621}],"tv":801.29}]}
{"op":"mcm","clk":"4226091089","pt":1631446921493,"mc":[{"id":"1.187552454","rc":[{"batl":[[2,2.08,27.55]],"ltp":1.5,"tv":331.01,"id":9028621}]}]}
{"op":"mcm","clk":"4226091141","pt":1631446921804,"mc":[{"id":"1.187552454","rc":[{"batb":[[0,1.5,6],[1,1.49,6],[2,1.48,6]],"ltp":1.5,"tv":331.01,"id":9028621}]}]}
{"op":"mcm","clk":"4226091409","pt":1631446923215,"mc":[{"id":"1.187552454","rc":[{"batl":[[0,3.05,3]],"ltp":3.0,"tv":470.28,"id":9345630},{"batl":[[0,1.54,8.54],[1,1.56,6],[2,1.85,4]],"ltp":1.5,"tv":331.01,"id":9028621}]}]}
{"op":"mcm","clk":"4226091651","pt":1631446924405,"mc":[{"id":"1.187552454","rc":[{"trd":[[2.18,48.3],[2.78,3.37],[2.84,12.63]],"batb":[[0,1.6,99.42],[1,1.5,106.77],[2,1.4,148.3]],"ltp":2.18,"tv":491.16,"id":9345630},{"trd":[[1.54,8.54],[1.56,6]],"batl":[[0,1.85,4],[1,2.08,27.55],[2,810,0.07]],"ltp":1.56,"tv":345.55,"id":9028621}],"tv":836.71}]}
{"op":"mcm","clk":"4226091766","pt":1631446925115,"mc":[{"id":"1.187552454","rc":[{"batb":[[0,1.6,98.86]],"batl":[[0,3,3],[1,3.05,3]],"ltp":2.18,"tv":491.16,"id":9345630}]}]}
{"op":"mcm","clk":"4226092195","pt":1631446927585,"mc":[{"id":"1.187552454","rc":[{"batb":[[0,2.16,3],[1,2.14,3],[2,1.6,98.86]],"ltp":2.18,"tv":491.16,"id":9345630}]}]}
{"op":"mcm","clk":"4226092577","pt":1631446929725,"mc":[{"id":"1.187552454","rc":[{"batl":[[0,2.84,10.14],[1,3,3],[2,3.05,3]],"ltp":2.18,"tv":491.16,"id":9345630}]}]}
{"op":"mcm","clk":"4226092859","pt":1631446931424,"mc":[{"id":"1.187552454","rc":[{"batl":[[2,820,0.14]],"ltp":1.56,"tv":345.55,"id":9028621}]}]}
{"op":"mcm","clk":"4226092945","pt":1631446931915,"mc":[{"id":"1.187552454","rc":[{"trd":[[2.84,22.77]],"ltp":2.84,"tv":501.3,"id":9345630},{"trd":[[1.54,27.24]],"batb":[[0,1.25,237.27],[1,1.2,385.57],[2,1.11,269.63]],"batl":[[0,1.48,198.2],[1,1.85,4],[2,2.08,27.55]],"ltp":1.54,"tv":364.25,"id":9028621}],"tv":865.56}]}
{"op":"mcm","clk":"4226093158","pt":1631446933138,"mc":[{"id":"1.187552454","rc":[{"trd":[[3.05,3]],"ltp":3.05,"tv":504.3,"id":9345630},{"trd":[[1.48,24.18]],"batl":[[0,1.48,183.02]],"ltp":1.48,"tv":388.44,"id":9028621}],"tv":892.74}]}
{"op":"mcm","clk":"4226093537","pt":1631446935236,"mc":[{"id":"1.187552454","rc":[{"batl":[[0,5,3]],"ltp":3.05,"tv":504.3,"id":9345630},{"batb":[[0,1.25,247.27],[1,1.24,9],[2,1.2,385.57]],"ltp":1.48,"tv":388.44,"id":9028621}]}]}
{"op":"mcm","clk":"4226094059","pt":1631446938337,"mc":[{"id":"1.187552454","rc":[{"trd":[[3.05,13.06]],"ltp":3.05,"tv":514.36,"id":9345630},{"trd":[[1.48,44.91]],"batl":[[0,1.48,162.29]],"ltp":1.48,"tv":409.17,"id":9028621}],"tv":923.53}]}
{"op":"mcm","clk":"4226094270","pt":1631446939410,"mc":[{"id":"1.187552454","rc":[{"trd":[[3.05,21.06]],"ltp":3.05,"tv":522.36,"id":9345630},{"trd":[[1.48,89.39]],"batl":[[0,1.48,131.81]],"ltp":1.48,"tv":453.65,"id":9028621}],"tv":976.01}]}
{"op":"mcm","clk":"4226094320","pt":1631446939724,"mc":[{"id":"1.187552454","rc":[{"batb":[[1,1.6,98.86],[2,1.5,106.77]],"ltp":3.05,"tv":522.36,"id":9345630}]}]}
{"op":"mcm","clk":"4226094603","pt":1631446941523,"mc":[{"id":"1.187552454","rc":[{"batb":[[0,1.36,466.94],[1,1.28,187.83],[2,1.25,247.27]],"batl":[[2,2,400.21]],"ltp":1.48,"tv":453.65,"id":9028621}]}]}
{"op":"mcm","clk":"4226094777","pt":1631446942654,"mc":[{"id":"1.187552454","rc":[{"trd":[[1.36,5.26]],"batb":[[0,1.36,464.31]],"batl":[[0,1.85,4],[1,2,400.21],[2,2.08,27.55]],"ltp":1.36,"tv":458.91,"id":9028621}],"tv":981.27}]}
{"op":"mcm","clk":"4226095064","pt":1631446944429,"mc":[{"id":"1.187552454","rc":[{"batl":[[0,3.8,2],[1,5,3]],"ltp":3.05,"tv":522.36,"id":9345630},{"batb":[[0,1.36,471.31],[1,1.35,9],[2,1.28,187.83]],"ltp":1.36,"tv":458.91,"id":9028621}]}]}
{"op":"mcm","clk":"4226095282","pt":1631446945818,"mc":[{"id":"1.187552454","rc":[{"batb":[[1,2.14,4],[2,1.6,98.86]],"ltp":3.05,"tv":522.36,"id":9345630}]}]}
{"op":"mcm","clk":"4226095535","pt":1631446947434,"mc":[{"id":"1.187552454","rc":[{"batb":[[2,1.8,11.86]],"batl":[[0,2.96,3],[1,3.8,2],[2,5,3]],"ltp":3.05,"tv":522.36,"id":9345630},{"batb":[[0,1.51,6],[1,1.5,7],[2,1.36,471.31]],"ltp":1.36,"tv":458.91,"id":9028621}]}]}
{"op":"mcm","clk":"4226096111","pt":1631446950963,"mc":[{"id":"1.187552454","rc":[{"trd":[[1.85,0.28]],"batl":[[0,1.85,3.86]],"ltp":1.85,"tv":459.19,"id":9028621}],"tv":981.55}]}
{"op":"mcm","clk":"4226096333","pt":1631446952452,"mc":[{"id":"1.187552454","rc":[{"batb":[[0,2.2,13.91],[1,2.16,3],[2,2.14,4]],"ltp":3.05,"tv":522.36,"id":9345630}]}]}
{"op":"mcm","clk":"4226096571","pt":1631446953917,"mc":[{"id":"1.187552454","rc":[{"batb":[[0,2.16,3],[1,2.14,4],[2,1.8,11.86]],"ltp":3.05,"tv":522.36,"id":9345630}]}]}
{"op":"mcm","clk":"4226096867","pt":1631446955726,"mc":[{"id":"1.187552454","rc":[{"batb":[[0,2.2,4],[1,2.18,3],[2,2.16,3]],"ltp":3.05,"tv":522.36,"id":9345630},{"batl":[[0,1.84,5],[1,1.85,3.86],[2,2,400.21]],"ltp":1.85,"tv":459.19,"id":9028621}]}]}
{"op":"mcm","clk":"4226097109","pt":1631446957435,"mc":[{"id":"1.187552454","rc":[{"batb":[[2,1.8,11.86]],"batl":[[1,3.8,0],[2,5,0]],"ltp":3.05,"tv":522.36,"id":9345630},{"batb":[[2,1.36,464.31]],"ltp":1.85,"tv":459.19,"id":9028621}]}]}
{"op":"mcm","clk":"4226097510","pt":1631446960064,"mc":[{"id":"1.187552454","rc":[{"trd":[[1.84,0.02]],"batb":[[0,1.36,464.31],[1,1.25,237.27],[2,1.2,385.57]],"batl":[[0,1.84,4.99]],"ltp":1.84,"tv":459.21,"id":9028621}],"tv":981.57}]}
{"op":"mcm","clk":"4226097730","pt":1631446961354,"mc":[{"id":"1.187552454","rc":[{"batl":[[0,1.77,5.98],[1,1.84,4.99],[2,1.85,3.86]],"ltp":1.84,"tv":459.21,"id":9028621}]}]}
{"op":"mcm","clk":"4226098035","pt":1631446963336,"mc":[{"id":"1.187552454","rc":[{"batl":[[0,3.8,3]],"ltp":3.05,"tv":522.36,"id":9345630},{"batb":[[0,1.36,470.31],[1,1.35,8],[2,1.25,237.27]],"ltp":1.84,"tv":459.21,"id":9028621}]}]}
{"op":"mcm","clk":"4226098230","pt":1631446964560,"mc":[{"id":"1.187552454","rc":[{"batb":[[0,2.28,4],[1,2.26,3],[2,2.2,4]],"ltp":3.05,"tv":522.36,"id":9345630},{"batl":[[0,1.77,9.98]],"ltp":1.84,"tv":459.21,"id":9028621}]}]}
{"op":"mcm","clk":"4226098697","pt":1631446967569,"mc":[{"id":"1.187552454","rc":[{"batb":[[2,1.8,11.86]],"ltp":3.05,"tv":522.36,"id":9345630},{"batb":[[0,1.36,6]],"batl":[[1,2,400.21],[2,2.08,27.55]],"ltp":1.84,"tv":459.21,"id":9028621}]}]}
{"op":"mcm","clk":"4226099011","pt":1631446969473,"mc":[{"id":"1.187552454","rc":[{"batl":[[0,2.66,8],[1,3.8,3]],"ltp":3.05,"tv":522.36,"id":9345630},{"batb":[[0,1.59,12],[1,1.36,6],[2,1.35,8]],"ltp":1.84,"tv":459.21,"id":9028621}]}]}
{"op":"mcm","clk":"4226099042","pt":1631446969691,"mc":[{"id":"1.187552454","rc":[{"batl":[[0,2.66,4]],"ltp":3.05,"tv":522.36,"id":9345630},{"batb":[[0,1.59,6]],"ltp":1.84,"tv":459.21,"id":9028621}]}]}
{"op":"mcm","clk":"4226099337","pt":1631446971595,"mc":[{"id":"1.187552454","rc":[{"batb":[[1,1.42,445.57],[2,1.36,6]],"ltp":1.84,"tv":459.21,"id":9028621}]}]}
{"op":"mcm","clk":"4226099852","pt":1631446974785,"mc":[{"id":"1.187552454","rc":[{"batl":[[0,2.66,7]],"ltp":3.05,"tv":522.36,"id":9345630},{"batb":[[0,1.6,6],[1,1.59,11],[2,1.42,445.57]],"ltp":1.84,"tv":459.21,"id":9028621}]}]}
{"op":"mcm","clk":"4226101005","pt":1631446981826,"mc":[{"id":"1.187552454","rc":[{"batb":[[1,1.8,11.86],[2,1.7,16.95]],"ltp":3.05,"tv":522.36,"id":9345630},{"batb":[[0,1.62,5],[1,1.6,6],[2,1.59,11]],"ltp":1.84,"tv":459.21,"id":9028621}]}]}
{"op":"mcm","clk":"4226101480","pt":1631446985022,"mc":[{"id":"1.187552454","rc":[{"trd":[[2.66,7],[2.72,3]],"batb":[[1,2.26,3],[2,1.8,11.86]],"batl":[[0,3.8,3],[1,3.8,0]],"ltp":2.72,"tv":532.36,"id":9345630},{"trd":[[1.58,27.17],[1.59,22],[1.6,23.64],[1.62,10]],"batb":[[0,1.42,445.57],[1,1.25,237.27],[2,1.2,385.57]],"batl":[[0,1.58,94.79],[1,1.77,9.98],[2,2,400.21]],"ltp":1.58,"tv":542.02,"id":9028621}],"tv":1074.39}]}
{"op":"mcm","clk":"4226101923","pt":1631446988024,"mc":[{"id":"1.187552454","rc":[{"batl":[[0,3.4,3],[1,3.8,3]],"ltp":2.72,"tv":532.36,"id":9345630},{"batb":[[0,1.42,451.57],[1,1.41,7],[2,1.25,237.27]],"batl":[[0,1.77,9.98],[1,2,400.21],[2,2.08,27.55]],"ltp":1.58,"tv":542.02,"id":9028621}]}]}
{"op":"mcm","clk":"4226102027","pt":1631446988709,"mc":[{"id":"1.187552454","rc":[{"batl":[[0,1.77,4]],"ltp":1.58,"tv":542.02,"id":9028621}]}]}
{"op":"mcm","clk":"4226102598","pt":1631446992839,"mc":[{"id":"1.187552454","rc":[{"batl":[[0,2.72,50],[1,3.4,3],[2,3.8,3]],"ltp":2.72,"tv":532.36,"id":9345630}]}]}
{"op":"mcm","clk":"4226103402","pt":1631446998352,"mc":[{"id":"1.187552454","rc":[{"batl":[[0,3.4,3],[1,3.8,3],[2,3.8,0]],"ltp":2.72,"tv":532.36,"id":9345630}]}]}
{"op":"mcm","clk":"4226103445","pt":1631446998618,"mc":[{"id":"1.187552454","rc":[{"batb":[[1,1.8,11.86],[2,1.7,16.95]],"ltp":2.72,"tv":532.36,"id":9345630}]}]}
{"op":"mcm","clk":"4226103872","pt":1631447002054,"mc":[{"id":"1.187552454","rc":[{"batb":[[1,2.26,3],[2,1.8,11.86]],"batl":[[1,3.8,0]],"ltp":2.72,"tv":532.36,"id":9345630},{"batb":[[1,1.25,237.27],[2,1.2,385.57]],"ltp":1.58,"tv":542.02,"id":9028621}]}]}
{"op":"mcm","clk":"4226104185","pt":1631447004244,"mc":[{"id":"1.187552454","rc":[{"batl":[[0,1.76,1.71],[1,1.77,4],[2,2,400.21]],"ltp":1.58,"tv":542.02,"id":9028621}]}]}
{"op":"mcm","clk":"4226104316","pt":1631447005257,"mc":[{"id":"1.187552454","rc":[{"batb":[[1,1.41,4],[2,1.25,237.27]],"ltp":1.58,"tv":542.02,"id":9028621}]}]}
{"op":"mcm","clk":"4226104840","pt":1631447008975,"mc":[{"id":"1.187552454","rc":[{"batb":[[0,1.42,6]],"batl":[[2,2.08,27.55]],"ltp":1.58,"tv":542.02,"id":9028621}]}]}
{"op":"mcm","clk":"4226105360","pt":1631447012461,"mc":[{"id":"1.187552454","rc":[{"batb":[[2,1.7,16.95]],"batl":[[0,2.48,4],[1,3.4,3]],"ltp":2.72,"tv":532.36,"id":9345630},{"batb":[[0,1.67,6],[1,1.42,6],[2,1.41,4]],"ltp":1.58,"tv":542.02,"id":9028621}]}]}
{"op":"mcm","clk":"4226105747","pt":1631447015287,"mc":[{"id":"1.187552454","rc":[{"batb":[[1,1.7,16.95],[2,1.6,98.86]],"ltp":2.72,"tv":532.36,"id":9345630}]}]}
{"op":"mcm","clk":"4226105930","pt":1631447016569,"mc":[{"id":"1.187552454","rc":[{"batl":[[0,2.48,7]],"ltp":2.72,"tv":532.36,"id":9345630},{"batb":[[0,1.67,9],[1,1.66,4],[2,1.42,6]],"ltp":1.58,"tv":542.02,"id":9028621}]}]}
{"op":"mcm","clk":"4226106199","pt":1631447018472,"mc":[{"id":"1.187552454","rc":[{"batb":[[1,2.26,4],[2,1.7,16.95]],"ltp":2.72,"tv":532.36,"id":9345630}]}]}
{"op":"mcm","clk":"4226106232","pt":1631447018682,"mc":[{"id":"1.187552454","rc":[{"batb":[[2,1.25,237.27]],"ltp":1.58,"tv":542.02,"id":9028621}]}]}
{"op":"mcm","clk":"4226106762","pt":1631447021777,"mc":[{"id":"1.187552454","rc":[{"batl":[[0,1.77,4],[1,2.08,27.55],[2,810,0.07]],"ltp":1.58,"tv":542.02,"id":9028621}]}]}
{"op":"mcm","clk":"4226107305","pt":1631447025673,"mc":[{"id":"1.187552454","rc":[{"trd":[[2.48,14]],"batb":[[0,2.48,3.14],[1,2.28,4],[2,2.26,4]],"batl":[[0,3.4,3],[1,3.4,0]],"ltp":2.48,"tv":546.36,"id":9345630}],"tv":1088.39}]}
{"op":"mcm","clk":"4226107813","pt":1631447029164,"mc":[{"id":"1.187552454","rc":[{"batl":[[0,2.5,3],[1,3.4,3]],"ltp":2.48,"tv":546.36,"id":9345630},{"batb":[[1,1.25,237.27],[2,1.2,385.57]],"ltp":1.58,"tv":542.02,"id":9028621}]}]}
{"op":"mcm","clk":"4226108224","pt":1631447032390,"mc":[{"id":"1.187552454","rc":[{"trd":[[2.48,20.29]],"batb":[[0,2.28,4],[1,1.7,16.95],[2,1.6,98.86]],"batl":[[0,2.48,82.26],[1,2.5,3],[2,3.4,3]],"ltp":2.48,"tv":552.65,"id":9345630},{"batb":[[1,1.66,5],[2,1.25,237.27]],"ltp":1.58,"tv":542.02,"id":9028621}],"tv":1094.68}]}
{"op":"mcm","clk":"4226108353","pt":1631447033296,"mc":[{"id":"1.187552454","rc":[{"trd":[[2.28,11.11]],"batb":[[0,1.7,16.95],[1,1.6,98.86],[2,1.5,106.77]],"batl":[[0,2.26,27.89],[1,2.48,82.26],[2,2.5,3]],"ltp":2.28,"tv":563.76,"id":9345630},{"trd":[[1.77,4]],"batl":[[0,2.08,27.55],[1,810,0.07],[2,810,0]],"ltp":1.77,"tv":546.02,"id":9028621}],"tv":1109.79}]}
{"op":"mcm","clk":"4226108560","pt":1631447035067,"mc":[{"id":"1.187552454","rc":[{"trd":[[2.26,10]],"batl":[[0,2.26,24.89],[1,2.48,85.26]],"ltp":2.26,"tv":569.76,"id":9345630},{"batb":[[2,1.3,197.73]],"ltp":1.77,"tv":546.02,"id":9028621}],"tv":1115.79}]}
{"op":"mcm","clk":"4226108717","pt":1631447036501,"mc":[{"id":"1.187552454","rc":[{"trd":[[2.26,13.17]],"batb":[[0,1.92,3],[1,1.91,5],[2,1.7,16.95]],"batl":[[0,2.26,21.72]],"ltp":2.26,"tv":572.93,"id":9345630},{"trd":[[1.79,24.34]],"batl":[[0,2.08,31.55]],"ltp":1.79,"tv":550.02,"id":9028621}],"tv":1122.96}]}
{"op":"mcm","clk":"4226108795","pt":1631447037084,"mc":[{"id":"1.187552454","rc":[{"batl":[[0,2.48,3],[1,2.5,3],[2,3.4,3]],"ltp":2.26,"tv":572.93,"id":9345630}]}]}
{"op":"mcm","clk":"4226109233","pt":1631447040391,"mc":[{"id":"1.187552454","rc":[{"batb":[[0,1.3,197.73],[1,1.25,237.27],[2,1.2,385.57]],"ltp":1.79,"tv":550.02,"id":9028621}]}]}
{"op":"mcm","clk":"4226109718","pt":1631447043526,"mc":[{"id":"1.187552454","rc":[{"batb":[[0,1.41,6],[1,1.4,7],[2,1.3,197.73]],"ltp":1.79,"tv":550.02,"id":9028621}]}]}
{"op":"mcm","clk":"4226109732","pt":1631447043622,"mc":[{"id":"1.187552454","rc":[{"batl":[[0,4.4,2]],"ltp":2.26,"tv":572.93,"id":9345630},{"batb":[[2,1.3,206.73]],"ltp":1.79,"tv":550.02,"id":9028621}]}]}
{"op":"mcm","clk":"4226110246","pt":1631447046754,"mc":[{"id":"1.187552454","rc":[{"batl":[[0,3.45,3],[1,4.4,2]],"ltp":2.26,"tv":572.93,"id":9345630}]}]}
{"op":"mcm","clk":"4226110424","pt":1631447047930,"mc":[{"id":"1.187552454","rc":[{"batl":[[0,2.42,4],[1,3.45,3],[2,4.4,2]],"ltp":2.26,"tv":572.93,"id":9345630},{"batb":[[0,1.71,6],[1,1.41,6],[2,1.4,7]],"ltp":1.79,"tv":550.02,"id":9028621}]}]}
{"op":"mcm","clk":"4226111073","pt":1631447052559,"mc":[{"id":"1.187552454","rc":[{"batb":[[1,1.6,98.86],[2,1.5,106.77]],"ltp":2.26,"tv":572.93,"id":9345630}]}]}
{"op":"mcm","clk":"4226111292","pt":1631447054272,"mc":[{"id":"1.187552454","rc":[{"trd":[[2.42,4]],"batl":[[0,3.45,3],[1,4.4,2],[2,4.4,0]],"ltp":2.42,"tv":576.93,"id":9345630},{"trd":[[1.7,5.69],[1.71,12]],"batb":[[0,1.41,6],[1,1.4,7],[2,1.3,206.73]],"batl":[[0,1.67,88.31],[1,2.08,31.55],[2,810,0.07]],"ltp":1.7,"tv":567.71,"id":9028621}],"tv":1144.65}]}
{"op":"mcm","clk":"4226111483","pt":1631447055447,"mc":[{"id":"1.187552454","rc":[{"trd":[[1.67,38]],"batl":[[0,1.67,69.31],[1,1.81,4],[2,2.08,31.55]],"ltp":1.67,"tv":605.71,"id":9028621}],"tv":1182.65}]}
{"op":"mcm","clk":"4226111532","pt":1631447055765,"mc":[{"id":"1.187552454","rc":[{"trd":[[2.48,23.29]],"batb":[[1,1.91,5],[2,1.6,98.86]],"ltp":2.48,"tv":579.93,"id":9345630},{"trd":[[1.67,42.46]],"batb":[[1,1.3,197.73],[2,1.25,237.27]],"batl":[[0,1.67,64.85]],"ltp":1.67,"tv":610.17,"id":9028621}],"tv":1190.11}]}
{"op":"mcm","clk":"4226111774","pt":1631447057431,"mc":[{"id":"1.187552454","rc":[{"trd":[[2.48,24.54]],"ltp":2.48,"tv":581.18,"id":9345630},{"trd":[[1.67,48.18]],"batb":[[0,1.43,176.56],[1,1.41,6],[2,1.3,197.73]],"batl":[[0,1.67,61.06]],"ltp":1.67,"tv":615.89,"id":9028621}],"tv":1197.08}]}
{"op":"mcm","clk":"4226111833","pt":1631447057750,"mc":[{"id":"1.187552454","rc":[{"trd":[[1.67,82.34]],"batl":[[0,1.67,43.98]],"ltp":1.67,"tv":650.05,"id":9028621}],"tv":1231.24}]}
{"op":"mcm","clk":"4226112002","pt":1631447059046,"mc":[{"id":"1.187552454","rc":[{"batl":[[1,4.4,0]],"ltp":2.48,"tv":581.18,"id":9345630},{"batb":[[2,1.4,8]],"ltp":1.67,"tv":650.05,"id":9028621}]}]}
{"op":"mcm","clk":"4226112262","pt":1631447060573,"mc":[{"id":"1.187552454","rc":[{"batl":[[0,2.48,85.4],[1,3.45,3]],"ltp":2.48,"tv":581.18,"id":9345630},{"trd":[[1.67,170.29]],"batb":[[0,1.67,285.77],[1,1.43,7],[2,1.42,7]],"batl":[[0,1.81,4],[1,2.08,31.55],[2,810,0.07]],"ltp":1.67,"tv":738.0,"id":9028621}],"tv":1319.19}]}
{"op":"mcm","clk":"4226112408","pt":1631447061554,"mc":[{"id":"1.187552454","rc":[{"batl":[[1,3.35,3],[2,3.45,3]],"ltp":2.48,"tv":581.18,"id":9345630},{"batb":[[0,1.67,945.33]],"ltp":1.67,"tv":738.0,"id":9028621}]}]}
{"op":"mcm","clk":"4226112599","pt":1631447062567,"mc":[{"id":"1.187552454","rc":[{"batb":[[0,1.67,730.35]],"ltp":1.67,"tv":738.0,"id":9028621}]}]}
{"op":"mcm","clk":"4226112724","pt":1631447063576,"mc":[{"id":"1.187552454","rc":[{"batb":[[0,2.22,4],[1,2.2,4],[2,1.92,3]],"batl":[[0,2.48,89.4],[1,2.5,3],[2,3.35,3]],"ltp":2.48,"tv":581.18,"id":9345630},{"batb":[[0,1.67,353.4],[1,1.66,4],[2,1.43,7]],"ltp":1.67,"tv":738.0,"id":9028621}]}]}
{"op":"mcm","clk":"4226112834","pt":1631447064379,"mc":[{"id":"1.187552454","rc":[{"batb":[[0,1.67,146.89]],"ltp":1.67,"tv":738.0,"id":9028621}]}]}
{"op":"mcm","clk":"4226113005","pt":1631447065453,"mc":[{"id":"1.187552454","rc":[{"batb":[[0,1.67,5]],"ltp":1.67,"tv":738.0,"id":9028621}]}]}
{"op":"mcm","clk":"4226113565","pt":1631447069192,"mc":[{"id":"1.187552454","rc":[{"trd":[[2.2,15.22],[2.22,26.56]],"batb":[[0,1.92,3],[1,1.6,98.86],[2,1.5,106.77]],"batl":[[0,2.2,18.74],[1,2.48,89.4],[2,2.5,3]],"ltp":2.2,"tv":600.44,"id":9345630},{"trd":[[1.81,4]],"batl":[[0,2.08,27.55],[1,810,0.07],[2,810,0]],"ltp":1.81,"tv":742.0,"id":9028621}],"tv":1342.45}]}
{"op":"mcm","clk":"4226114042","pt":1631447072392,"mc":[{"id":"1.187552454","rc":[{"trd":[[2.2,19.38]],"batb":[[1,1.91,4],[2,1.6,98.86]],"batl":[[0,2.2,14.58]],"ltp":2.2,"tv":604.6,"id":9345630},{"trd":[[1.83,13.68]],"batb":[[2,1.3,197.73]],"batl":[[0,2.08,30.55]],"ltp":1.83,"tv":747.0,"id":9028621}],"tv":1351.61}]}
{"op":"mcm","clk":"4226114624","pt":1631447076398,"mc":[{"id":"1.187552454","rc":[{"trd":[[2.2,20.8]],"batl":[[0,2.2,13.16],[2,2.5,0]],"ltp":2.2,"tv":606.02,"id":9345630},{"trd":[[1.83,15.38]],"batb":[[1,1.3,197.73],[2,1.25,237.27]],"ltp":1.83,"tv":748.71,"id":9028621}],"tv":1354.74}]}
{"op":"mcm","clk":"4226115165","pt":1631447080504,"mc":[{"id":"1.187552454","rc":[{"trd":[[2.2,31.46]],"batl":[[0,2.2,2.5],[1,2.48,85.4]],"ltp":2.2,"tv":616.68,"id":9345630},{"trd":[[1.83,28.19]],"batb":[[0,1.3,197.73],[1,1.25,237.27],[2,1.2,385.57]],"ltp":1.83,"tv":761.52,"id":9028621}],"tv":1378.21}]}
{"op":"mcm","clk":"4226115774","pt":1631447085129,"mc":[{"id":"1.187552454","rc":[{"batb":[[1,1.6,98.86],[2,1.5,106.77]],"batl":[[0,2.48,85.4],[1,2.48,0]],"ltp":2.2,"tv":616.68,"id":9345630}]}]}
{"op":"mcm","clk":"4226116209","pt":1631447088422,"mc":[{"id":"1.187552454","rc":[{"batb":[[0,2.12,10],[1,1.92,3],[2,1.6,98.86]],"ltp":2.2,"tv":616.68,"id":9345630},{"batl":[[0,1.88,10],[1,2.08,30.55],[2,810,0.07]],"ltp":1.83,"tv":761.52,"id":9028621}]}]}
{"op":"mcm","clk":"4226116233","pt":1631447088637,"mc":[{"id":"1.187552454","rc":[{"batb":[[0,2.12,5]],"ltp":2.2,"tv":616.68,"id":9345630},{"batl":[[0,1.88,5]],"ltp":1.83,"tv":761.52,"id":9028621}]}]}
{"op":"mcm","clk":"4226116359","pt":1631447089600,"mc":[{"id":"1.187552454","rc":[{"batb":[[2,1.7,16.95]],"ltp":2.2,"tv":616.68,"id":9345630}]}]}
{"op":"mcm","clk":"4226116743","pt":1631447092534,"mc":[{"id":"1.187552454","rc":[{"batb":[[0,2.12,8],[1,2.1,4],[2,1.92,3]],"batl":[[0,2.46,32.32],[1,2.48,85.4]],"ltp":2.2,"tv":616.68,"id":9345630},{"batl":[[0,1.73,46.07],[1,1.88,10],[2,1.91,2.56]],"ltp":1.83,"tv":761.52,"id":9028621}]}]}
{"op":"mcm","clk":"4226116773","pt":1631447092738,"mc":[{"id":"1.187552454","rc":[{"batl":[[0,2.48,85.4],[1,2.48,0]],"ltp":2.2,"tv":616.68,"id":9345630},{"batl":[[0,1.88,10],[1,1.91,2.56],[2,2.08,30.55]],"ltp":1.83,"tv":761.52,"id":9028621}]}]}
{"op":"mcm","clk":"4226117123","pt":1631447095138,"mc":[{"id":"1.187552454","rc":[{"batb":[[0,1.31,189.17],[1,1.3,197.73],[2,1.25,237.27]],"ltp":1.83,"tv":761.52,"id":9028621}]}]}
{"op":"mcm","clk":"4226117220","pt":1631447095728,"mc":[{"id":"1.187552454","rc":[{"batb":[[0,2.36,3],[1,2.34,4],[2,2.12,8]],"ltp":2.2,"tv":616.68,"id":9345630},{"batl":[[0,1.73,5],[1,1.88,10],[2,1.91,2.56]],"ltp":1.83,"tv":761.52,"id":9028621}]}]}
{"op":"mcm","clk":"4226118311","pt":1631447102441,"mc":[{"id":"1.187552454","rc":[{"batl":[[2,2.08,30.55]],"ltp":1.83,"tv":761.52,"id":9028621}]}]}
{"op":"mcm","clk":"4226118838","pt":1631447105517,"mc":[{"id":"1.187552454","rc":[{"trd":[[2.48,109.95]],"batb":[[2,2.12,5]],"ltp":2.48,"tv":702.09,"id":9345630},{"trd":[[1.67,297.12]],"batl":[[0,1.65,17.77],[1,1.73,5],[2,1.85,2.56]],"ltp":1.67,"tv":888.35,"id":9028621}],"tv":1590.45}]}
{"op":"mcm","clk":"4226119095","pt":1631447106957,"mc":[{"id":"1.187552454","rc":[{"batb":[[0,2.12,5],[1,1.7,16.95],[2,1.6,98.86]],"ltp":2.48,"tv":702.09,"id":9345630},{"batb":[[0,1.3,197.73],[1,1.25,237.27],[2,1.2,385.57]],"batl":[[1,1.85,2.56],[2,1.88,5]],"ltp":1.67,"tv":888.35,"id":9028621}]}]}
{"op":"mcm","clk":"4226119257","pt":1631447108143,"mc":[{"id":"1.187552454","rc":[{"batl":[[0,4.3,2]],"ltp":2.48,"tv":702.09,"id":9345630},{"batb":[[0,1.31,8],[1,1.3,205.73],[2,1.25,237.27]],"ltp":1.67,"tv":888.35,"id":9028621}]}]}
{"op":"mcm","clk":"4226119560","pt":1631447110061,"mc":[{"id":"1.187552454","rc":[{"batl":[[1,4.4,2]],"ltp":2.48,"tv":702.09,"id":9345630},{"batb":[[2,1.29,9]],"ltp":1.67,"tv":888.35,"id":9028621}]}]}
{"op":"mcm","clk":"4226120106","pt":1631447113422,"mc":[{"id":"1.187552454","rc":[{"batb":[[0,1.7,16.95],[1,1.6,98.86],[2,1.5,106.77]],"ltp":2.48,"tv":702.09,"id":9345630},{"batl":[[2,2.08,27.55]],"ltp":1.67,"tv":888.35,"id":9028621}]}]}
{"op":"mcm","clk":"4226120548","pt":1631447116546,"mc":[{"id":"1.187552454","rc":[{"batb":[[0,1.71,5.9],[1,1.7,16.95],[2,1.6,98.86]],"ltp":2.48,"tv":702.09,"id":9345630}]}]}
{"op":"mcm","clk":"4226120582","pt":1631447116843,"mc":[{"id":"1.187552454","rc":[{"batb":[[0,2.18,5]],"ltp":2.48,"tv":702.09,"id":9345630},{"batl":[[1,1.83,5],[2,1.85,2.56]],"ltp":1.67,"tv":888.35,"id":9028621}]}]}
{"op":"mcm","clk":"4226120775","pt":1631447118085,"mc":[{"id":"1.187552454","rc":[{"batl":[[0,1.83,5],[1,1.85,2.56],[2,2.08,27.55]],"ltp":1.67,"tv":888.35,"id":9028621}]}]}
{"op":"mcm","clk":"4226121110","pt":1631447120267,"mc":[{"id":"1.187552454","rc":[{"batb":[[0,2.52,3],[1,2.5,4],[2,2.18,5]],"ltp":2.48,"tv":702.09,"id":9345630},{"batb":[[1,1.3,197.73]],"batl":[[0,1.65,5],[1,1.83,5],[2,1.85,2.56]],"ltp":1.67,"tv":888.35,"id":9028621}]}]}
{"op":"mcm","clk":"4226121309","pt":1631447121551,"mc":[{"id":"1.187552454","rc":[{"batb":[[2,2.2,4]],"batl":[[1,4.4,0]],"ltp":2.48,"tv":702.09,"id":9345630},{"batb":[[0,1.33,186.28],[1,1.31,8],[2,1.3,197.73]],"batl":[[1,1.83,9]],"ltp":1.67,"tv":888.35,"id":9028621}]}]}
{"op":"mcm","clk":"4226121576","pt":1631447123482,"mc":[{"id":"1.187552454","rc":[{"batl":[[0,2.62,3],[1,4,82.84],[2,4.3,2]],"ltp":2.48,"tv":702.09,"id":9345630},{"batb":[[0,1.61,6],[1,1.6,6],[2,1.31,8]],"ltp":1.67,"tv":888.35,"id":9028621}]}]}
{"op":"mcm","clk":"4226121757","pt":1631447124554,"mc":[{"id":"1.187552454","rc":[{"batl":[[2,4.1,3]],"ltp":2.48,"tv":702.09,"id":9345630},{"batb":[[2,1.33,6]],"ltp":1.67,"tv":888.35,"id":9028621}]}]}
{"op":"mcm","clk":"4226122040","pt":1631447126367,"mc":[{"id":"1.187552454","rc":[{"batl":[[1,4,85.84]],"ltp":2.48,"tv":702.09,"id":9345630}]}]}
{"op":"mcm","clk":"4226122356","pt":1631447128572,"mc":[{"id":"1.187552454","rc":[{"batb":[[0,2.2,4],[1,2.18,4],[2,1.8,11.86]],"batl":[[0,4,85.84],[1,4.1,3],[2,4.3,2]],"ltp":2.48,"tv":702.09,"id":9345630},{"batb":[[0,1.33,6],[1,1.32,6],[2,1.31,8]],"batl":[[0,1.83,4],[1,1.85,2.56],[2,2.08,27.55]],"ltp":1.67,"tv":888.35,"id":9028621}]}]}
{"op":"mcm","clk":"4226123479","pt":1631447135461,"mc":[{"id":"1.187552454","rc":[{"batb":[[1,1.8,11.86],[2,1.7,16.95]],"ltp":2.48,"tv":702.09,"id":9345630},{"batb":[[2,1.3,197.73]],"batl":[[0,1.61,86.04],[1,1.83,4],[2,1.85,2.56]],"ltp":1.67,"tv":888.35,"id":9028621}]}]}
{"op":"mcm","clk":"4226123865","pt":1631447138286,"mc":[{"id":"1.187552454","rc":[{"batb":[[0,2.2,9]],"batl":[[1,4.1,0],[2,4.3,0]],"ltp":2.48,"tv":702.09,"id":9345630},{"batb":[[1,1.25,237.27],[2,1.2,385.57]],"batl":[[2,1.84,5]],"ltp":1.67,"tv":888.35,"id":9028621}]}]}
{"op":"mcm","clk":"4226124317","pt":1631447141220,"mc":[{"id":"1.187552454","rc":[{"batb":[[1,1.32,7],[2,1.25,237.27]],"ltp":1.67,"tv":888.35,"id":9028621}]}]}
{"op":"mcm","clk":"4226124836","pt":1631447144392,"mc":[{"id":"1.187552454","rc":[{"batb":[[0,2.62,3],[1,2.6,4],[2,2.2,9]],"ltp":2.48,"tv":702.09,"id":9345630},{"batl":[[0,1.61,6]],"ltp":1.67,"tv":888.35,"id":9028621}]}]}
{"op":"mcm","clk":"4226125122","pt":1631447146319,"mc":[{"id":"1.187552454","rc":[{"batl":[[0,2.74,4],[1,4,85.84]],"ltp":2.48,"tv":702.09,"id":9345630},{"batb":[[0,1.57,6],[1,1.56,7],[2,1.33,6]],"ltp":1.67,"tv":888.35,"id":9028621}]}]}
{"op":"mcm","clk":"4226126815","pt":1631447157318,"mc":[{"id":"1.187552454","rc":[{"batb":[[0,2.2,4],[1,2.18,4],[2,1.8,11.86]],"batl":[[0,4,82.84],[1,4,0]],"ltp":2.48,"tv":702.09,"id":9345630},{"batb":[[0,1.56,7],[1,1.25,237.27],[2,1.2,385.57]],"batl":[[0,1.85,2.56],[1,2.08,27.55],[2,810,0.07]],"ltp":1.67,"tv":888.35,"id":9028621}]}]}
{"op":"mcm","clk":"4226126944","pt":1631447158223,"mc":[{"id":"1.187552454","rc":[{"batb":[[1,1.8,11.86],[2,1.7,16.95]],"ltp":2.48,"tv":702.09,"id":9345630},{"batl":[[0,1.57,86.04],[1,1.85,2.56],[2,2.08,27.55]],"ltp":1.67,"tv":888.35,"id":9028621}]}]}
{"op":"mcm","clk":"4226127268","pt":1631447160533,"mc":[{"id":"1.187552454","rc":[{"batl":[[0,2.8,3],[1,4,82.84]],"ltp":2.48,"tv":702.09,"id":9345630},{"batb":[[1,1.55,6],[2,1.25,237.27]],"batl":[[1,1.84,4],[2,1.85,2.56]],"ltp":1.67,"tv":888.35,"id":9028621}]}]}
{"op":"mcm","clk":"4226127733","pt":1631447163469,"mc":[{"id":"1.187552454","rc":[{"trd":[[2.8,3]],"batl":[[0,4,82.84],[1,4,0]],"ltp":2.8,"tv":705.09,"id":9345630},{"trd":[[1.55,17.42],[1.56,20]],"batb":[[0,1.25,237.27],[1,1.2,385.57],[2,1.17,314.03]],"batl":[[0,1.84,4],[1,1.85,2.56],[2,2.08,27.55]],"ltp":1.55,"tv":919.77,"id":9028621}],"tv":1624.87}]}
{"op":"mcm","clk":"4226128237","pt":1631447166533,"mc":[{"id":"1.187552454","rc":[{"batb":[[0,2.2,9]],"batl":[[0,2.82,4],[1,4,82.84]],"ltp":2.8,"tv":705.09,"id":9345630},{"batb":[[0,1.36,464.27],[1,1.33,8],[2,1.32,8]],"batl":[[0,1.82,5],[1,1.84,4],[2,1.85,2.56]],"ltp":1.55,"tv":919.77,"id":9028621}]}]}
{"op":"mcm","clk":"4226128281","pt":1631447166845,"mc":[{"id":"1.187552454","rc":[{"batl":[[1,4,85.84]],"ltp":2.8,"tv":705.09,"id":9345630}]}]}
{"op":"mcm","clk":"4226128590","pt":1631447169031,"mc":[{"id":"1.187552454","rc":[{"batb":[[1,2.18,4],[2,1.8,11.86]],"ltp":2.8,"tv":705.09,"id":9345630},{"batl":[[0,1.82,9]],"ltp":1.55,"tv":919.77,"id":9028621}]}]}
{"op":"mcm","clk":"4226128715","pt":1631447169782,"mc":[{"id":"1.187552454","rc":[{"batb":[[0,1.54,5],[1,1.53,5],[2,1.36,464.27]],"ltp":1.55,"tv":919.77,"id":9028621}]}]}
{"op":"mcm","clk":"4226129239","pt":1631447172949,"mc":[{"id":"1.187552454","rc":[{"batb":[[0,2.68,3],[1,2.66,4],[2,2.2,9]],"ltp":2.8,"tv":705.09,"id":9345630},{"batl":[[0,1.59,5],[1,1.82,9],[2,1.84,4]],"ltp":1.55,"tv":919.77,"id":9028621}]}]}
{"op":"mcm","clk":"4226131240","pt":1631447186285,"mc":[{"id":"1.187552454","rc":[{"batb":[[1,2.2,5],[2,1.8,11.86]],"batl":[[1,4,82.84]],"ltp":2.8,"tv":705.09,"id":9345630},{"batb":[[1,1.36,464.27],[2,1.25,237.27]],"batl":[[1,1.81,27.55],[2,1.82,5]],"ltp":1.55,"tv":919.77,"id":9028621}]}]}
{"op":"mcm","clk":"4226131706","pt":1631447189469,"mc":[{"id":"1.187552454","rc":[{"batb":[[1,2.66,3],[2,2.2,5]],"ltp":2.8,"tv":705.09,"id":9345630},{"batb":[[1,1.53,5],[2,1.36,464.27]],"ltp":1.55,"tv":919.77,"id":9028621}]}]}
{"op":"mcm","clk":"4226132891","pt":1631447197681,"mc":[{"id":"1.187552454","rc":[{"trd":[[1.59,32]],"batb":[[0,1.59,87.35],[1,1.54,5],[2,1.53,5]],"batl":[[0,1.81,27.55],[1,1.82,5],[2,1.85,2.56]],"ltp":1.59,"tv":929.77,"id":9028621}],"tv":1634.86}]}
{"op":"mcm","clk":"4226133407","pt":1631447200890,"mc":[{"id":"1.187552454","rc":[{"batl":[[0,1.6,6],[1,1.81,27.55],[2,1.82,5]],"ltp":1.59,"tv":929.77,"id":9028621}]}]}
{"op":"mcm","clk":"4226135561","pt":1631447215533,"mc":[{"id":"1.187552454","rc":[{"batb":[[1,2.2,5],[2,1.8,11.86]],"ltp":2.8,"tv":705.09,"id":9345630},{"trd":[[1.59,40.54]],"batb":[[0,1.59,83.08],[2,1.36,464.27]],"ltp":1.59,"tv":938.31,"id":9028621}],"tv":1643.4}]}
{"op":"mcm","clk":"4226135656","pt":1631447216118,"mc":[{"id":"1.187552454","rc":[{"trd":[[2.68,6]],"batb":[[0,2.2,5],[1,1.8,11.86],[2,1.7,16.95]],"batl":[[0,2.68,47],[1,2.82,4],[2,4,82.84]],"ltp":2.68,"tv":711.09,"id":9345630}],"tv":1649.4}]}
{"op":"mcm","clk":"4226135760","pt":1631447216718,"mc":[{"id":"1.187552454","rc":[{"batl":[[0,2.68,57.76]],"ltp":2.68,"tv":711.09,"id":9345630}]}]}
{"op":"mcm","clk":"4226135957","pt":1631447218131,"mc":[{"id":"1.187552454","rc":[{"batb":[[0,2.66,3],[1,2.2,5],[2,1.8,11.86]],"ltp":2.68,"tv":711.09,"id":9345630}]}]}
{"op":"mcm","clk":"4226136191","pt":1631447219422,"mc":[{"id":"1.187552454","rc":[{"trd":[[2.64,3],[2.66,10]],"batb":[[0,2.2,5],[1,1.8,11.86],[2,1.7,16.95]],"ltp":2.64,"tv":717.09,"id":9345630},{"trd":[[1.6,35.64],[1.61,9.88]],"batb":[[0,1.61,34.12],[1,1.59,83.08],[2,1.54,5]],"batl":[[0,1.81,27.55],[1,1.82,5],[2,2,402.01]],"ltp":1.61,"tv":960.19,"id":9028621}],"tv":1677.28}]}
{"op":"mcm","clk":"4226136680","pt":1631447222549,"mc":[{"id":"1.187552454","rc":[{"batb":[[0,2.32,4],[1,2.3,3],[2,2.22,3]],"ltp":2.64,"tv":717.09,"id":9345630},{"batl":[[0,1.76,5],[1,1.81,32.55],[2,1.82,5]],"ltp":1.61,"tv":960.19,"id":9028621}]}]}
{"op":"mcm","clk":"4226136767","pt":1631447223122,"mc":[{"id":"1.187552454","rc":[{"batb":[[2,2.24,6.5]],"batl":[[2,4,0]],"ltp":2.64,"tv":717.09,"id":9345630}]}]}
{"op":"mcm","clk":"4226137567","pt":1631447228553,"mc":[{"id":"1.187552454","rc":[{"batb":[[2,2.22,3]],"ltp":2.64,"tv":717.09,"id":9345630}]}]}
{"op":"mcm","clk":"4226139449","pt":1631447241573,"mc":[{"id":"1.187552454","rc":[{"batb":[[1,2.2,5],[2,1.8,11.86]],"ltp":2.64,"tv":717.09,"id":9345630},{"batl":[[1,1.81,27.55]],"ltp":1.61,"tv":960.19,"id":9028621}]}]}
{"op":"mcm","clk":"4226139997","pt":1631447245156,"mc":[{"id":"1.187552454","rc":[{"batb":[[0,2.34,4.37],[1,2.32,4],[2,2.3,3]],"ltp":2.64,"tv":717.09,"id":9345630},{"trd":[[1.61,78.12]],"batb":[[0,1.59,83.08],[1,1.54,5],[2,1.36,464.27]],"batl":[[0,1.61,51.92],[1,1.76,5],[2,1.81,27.55]],"ltp":1.61,"tv":1028.43,"id":9028621}],"tv":1745.52}]}
{"op":"mcm","clk":"4226140516","pt":1631447248571,"mc":[{"id":"1.187552454","rc":[{"batb":[[0,2.62,3],[1,2.6,3],[2,2.34,4]],"ltp":2.64,"tv":717.09,"id":9345630},{"trd":[[1.61,181.96]],"batl":[[0,1.61,4],[1,1.75,6],[2,1.76,5]],"ltp":1.61,"tv":1132.27,"id":9028621}],"tv":1849.36}]}
{"op":"mcm","clk":"4226141688","pt":1631447256487,"mc":[{"id":"1.187552454","rc":[{"batb":[[0,2.34,4],[1,1.8,11.86],[2,1.7,16.95]],"batl":[[1,2.82,0]],"ltp":2.64,"tv":717.09,"id":9345630},{"batb":[[1,1.36,464.27],[2,1.25,237.27]],"batl":[[0,1.75,6],[1,1.76,5],[2,1.81,27.55]],"ltp":1.61,"tv":1132.27,"id":9028621}]}]}
{"op":"mcm","clk":"4226142183","pt":1631447259904,"mc":[{"id":"1.187552454","rc":[{"batb":[[1,2.32,4],[2,1.8,11.86]],"ltp":2.64,"tv":717.09,"id":9345630},{"batl":[[1,1.81,27.55],[2,2,402.01]],"ltp":1.61,"tv":1132.27,"id":9028621}]}]}
{"op":"mcm","clk":"4226143408","pt":1631447268040,"mc":[{"id":"1.187552454","rc":[{"batl":[[0,2.68,47]],"ltp":2.64,"tv":717.09,"id":9345630}]}]}
{"op":"mcm","clk":"4226143833","pt":1631447271188,"mc":[{"id":"1.187552454","rc":[{"trd":[[2.32,10.76],[2.34,8]],"batb":[[0,1.8,11.86],[1,1.7,16.95],[2,1.6,98.86]],"ltp":2.32,"tv":735.85,"id":9345630},{"trd":[[1.75,3.66]],"batl":[[0,1.75,2.34]],"ltp":1.75,"tv":1135.93,"id":9028621}],"tv":1871.78}]}
{"op":"mcm","clk":"4226144322","pt":1631447274344,"mc":[{"id":"1.187552454","rc":[{"batb":[[0,2.3,3],[1,2.28,4],[2,1.8,11.86]],"ltp":2.32,"tv":735.85,"id":9345630}]}]}
{"op":"mcm","clk":"4226145007","pt":1631447278952,"mc":[{"id":"1.187552454","rc":[{"trd":[[2.68,53]],"ltp":2.68,"tv":782.85,"id":9345630},{"trd":[[1.59,285.92]],"batb":[[0,1.36,464.27],[1,1.25,237.27],[2,1.2,385.57]],"ltp":1.59,"tv":1381.31,"id":9028621}],"tv":2164.16}]}
{"op":"mcm","clk":"4226145231","pt":1631447280473,"mc":[{"id":"1.187552454","rc":[{"batb":[[0,2.44,4],[1,2.3,3],[2,2.28,4]],"ltp":2.68,"tv":782.85,"id":9345630},{"batl":[[0,1.72,6],[1,1.75,2.34],[2,1.81,27.55]],"ltp":1.59,"tv":1381.31,"id":9028621}]}]}
{"op":"mcm","clk":"4226145586","pt":1631447282467,"mc":[{"id":"1.187552454","rc":[{"batl":[[0,3.8,3]],"ltp":2.68,"tv":782.85,"id":9345630},{"batb":[[0,1.36,471.27],[1,1.35,8],[2,1.25,237.27]],"ltp":1.59,"tv":1381.31,"id":9028621}]}]}
{"op":"mcm","clk":"4226145989","pt":1631447285199,"mc":[{"id":"1.187552454","rc":[{"batb":[[0,2.44,7],[1,2.42,3],[2,2.3,3]],"ltp":2.68,"tv":782.85,"id":9345630},{"batl":[[0,1.7,4],[1,1.72,6],[2,1.75,2.34]],"ltp":1.59,"tv":1381.31,"id":9028621}]}]}
{"op":"mcm","clk":"4226146484","pt":1631447288468,"mc":[{"id":"1.187552454","rc":[{"batb":[[0,2.92,3],[1,2.9,2],[2,2.44,7]],"batl":[[0,3.1,3],[1,3.8,3]],"ltp":2.68,"tv":782.85,"id":9345630},{"batb":[[0,1.47,6],[1,1.46,6],[2,1.36,471.27]],"batl":[[0,1.52,5],[1,1.7,4],[2,1.72,6]],"ltp":1.59,"tv":1381.31,"id":9028621}]}]}
{"op":"mcm","clk":"4226148811","pt":1631447302704,"mc":[{"id":"1.187552454","rc":[{"batb":[[0,2.44,3],[1,1.8,11.86],[2,1.7,16.95]],"ltp":2.68,"tv":782.85,"id":9345630},{"batb":[[0,1.36,471.27],[1,1.25,237.27],[2,1.2,385.57]],"batl":[[0,1.81,27.55],[1,2,402.01],[2,1.72,0]],"ltp":1.59,"tv":1381.31,"id":9028621}]}]}
{"op":"mcm","clk":"4226149332","pt":1631447305990,"mc":[{"id":"1.187552454","rc":[{"batb":[[1,2.42,3],[2,1.8,11.86]],"batl":[[0,3.8,3]],"ltp":2.68,"tv":782.85,"id":9345630},{"batb":[[1,1.35,8],[2,1.25,237.27]],"batl":[[0,1.7,6],[1,1.81,27.55],[2,2,402.01]],"ltp":1.59,"tv":1381.31,"id":9028621}]}]}
{"op":"mcm","clk":"4226150271","pt":1631447312319,"mc":[{"id":"1.187552454","rc":[{"trd":[[2.42,12],[2.44,6]],"batb":[[0,1.8,11.86],[1,1.7,16.95],[2,1.6,98.86]],"ltp":2.42,"tv":796.85,"id":9345630},{"trd":[[1.7,8.54]],"batb":[[0,1.68,12],[1,1.36,471.27],[2,1.35,8]],"batl":[[0,1.7,3.15]],"ltp":1.7,"tv":1384.16,"id":9028621}],"tv":2181.01}]}
{"op":"mcm","clk":"4226150359","pt":1631447312859,"mc":[{"id":"1.187552454","rc":[{"batb":[[0,1.7,16.95],[1,1.6,98.86],[2,1.5,106.77]],"ltp":2.42,"tv":796.85,"id":9345630},{"batb":[[0,1.68,6]],"ltp":1.7,"tv":1384.16,"id":9028621}]}]}
{"op":"mcm","clk":"4226150854","pt":1631447315542,"mc":[{"id":"1.187552454","rc":[{"batb":[[0,2.4,3],[1,2.22,3],[2,2.2,4]],"ltp":2.42,"tv":796.85,"id":9345630},{"trd":[[1.68,12]],"batb":[[0,1.36,471.27],[1,1.35,8],[2,1.2,385.57]],"batl":[[0,1.42,131.37],[1,1.7,3.15],[2,1.81,27.55]],"ltp":1.68,"tv":1396.16,"id":9028621}],"tv":2193.01}]}
{"op":"mcm","clk":"4226150975","pt":1631447316234,"mc":[{"id":"1.187552454","rc":[{"trd":[[3.35,28.22]],"ltp":3.35,"tv":825.07,"id":9345630},{"trd":[[1.42,66.58]],"batl":[[0,1.42,64.8]],"ltp":1.42,"tv":1462.74,"id":9028621}],"tv":2287.81}]}
{"op":"mcm","clk":"4226151299","pt":1631447318469,"mc":[{"id":"1.187552454","rc":[{"trd":[[1.42,196.17]],"batl":[[0,1.7,3.15],[1,1.81,27.55],[2,2,402.01]],"ltp":1.42,"tv":1592.33,"id":9028621}],"tv":2417.4}]}
{"op":"mcm","clk":"4226151449","pt":1631447319439,"mc":[{"id":"1.187552454","rc":[{"batb":[[1,1.2,385.57],[2,1.17,314.03]],"ltp":1.42,"tv":1592.33,"id":9028621}]}]}
{"op":"mcm","clk":"4226151977","pt":1631447322541,"mc":[{"id":"1.187552454","rc":[{"batb":[[0,2.42,3],[1,2.4,3],[2,2.22,3]],"ltp":3.35,"tv":825.07,"id":9345630}]}]}
{"op":"mcm","clk":"4226152108","pt":1631447323441,"mc":[{"id":"1.187552454","rc":[{"batl":[[0,3.4,2],[1,3.8,3]],"ltp":3.35,"tv":825.07,"id":9345630},{"batb":[[0,1.42,3],[1,1.41,3],[2,1.36,471.27]],"ltp":1.42,"tv":1592.33,"id":9028621}]}]}
{"op":"mcm","clk":"4226155156","pt":1631447340403,"mc":[{"id":"1.187552454","rc":[{"batb":[[1,1.8,11.86],[2,1.7,16.95]],"batl":[[1,3.8,0]],"ltp":3.35,"tv":825.07,"id":9345630},{"batb":[[1,1.2,385.57],[2,1.17,314.03]],"batl":[[2,2,0]],"ltp":1.42,"tv":1592.33,"id":9028621}]}]}
{"op":"mcm","clk":"4226155480","pt":1631447342261,"mc":[{"id":"1.187552454","rc":[{"batb":[[0,2.5,4],[1,2.42,3],[2,1.8,11.86]],"ltp":3.35,"tv":825.07,"id":9345630},{"batl":[[0,1.68,6],[1,1.7,3.15],[2,1.81,27.55]],"ltp":1.42,"tv":1592.33,"id":9028621}]}]}
{"op":"mcm","clk":"4226155697","pt":1631447343598,"mc":[{"id":"1.187552454","rc":[{"batb":[[1,1.41,3],[2,1.2,385.57]],"ltp":1.42,"tv":1592.33,"id":9028621}]}]}
{"op":"mcm","clk":"4226155799","pt":1631447344248,"mc":[{"id":"1.187552454","rc":[{"batb":[[2,1.29,491.02]],"ltp":1.42,"tv":1592.33,"id":9028621}]}]}
{"op":"mcm","clk":"4226156203","pt":1631447347095,"mc":[{"id":"1.187552454","rc":[{"batb":[[0,2.5,8],[1,2.48,4],[2,2.42,3]],"ltp":3.35,"tv":825.07,"id":9345630},{"batl":[[0,1.67,2],[1,1.68,6],[2,1.7,3.15]],"ltp":1.42,"tv":1592.33,"id":9028621}]}]}
{"op":"mcm","clk":"4226156605","pt":1631447349864,"mc":[{"id":"1.187552454","rc":[{"batb":[[0,2.96,3],[1,2.94,3],[2,2.5,8]],"batl":[[0,3.15,3],[1,3.4,2]],"ltp":3.35,"tv":825.07,"id":9345630},{"batb":[[0,1.46,7],[1,1.45,6],[2,1.42,3]],"batl":[[0,1.51,3],[1,1.67,2],[2,1.68,6]],"ltp":1.42,"tv":1592.33,"id":9028621}]}]}
{"op":"mcm","clk":"4226158379","pt":1631447361401,"mc":[{"id":"1.187552454","rc":[{"batb":[[0,2.5,4],[1,1.8,11.86],[2,1.7,16.95]],"ltp":3.35,"tv":825.07,"id":9345630},{"batb":[[0,1.29,491.02],[1,1.2,385.57],[2,1.17,314.03]],"batl":[[0,1.81,27.55],[1,1.85,464.26],[2,1.68,0]],"ltp":1.42,"tv":1592.33,"id":9028621}]}]}
{"op":"mcm","clk":"4226158637","pt":1631447363027,"mc":[{"id":"1.187552454","rc":[{"trd":[[2.5,8]],"batb":[[0,1.8,11.86],[1,1.7,16.95],[2,1.6,98.86]],"ltp":2.5,"tv":829.07,"id":9345630},{"trd":[[1.67,303.11],[1.81,59.11],[1.85,145.76]],"batl":[[0,1.85,391.52],[1,1.85,0]],"ltp":1.85,"tv":1798.91,"id":9028621}],"tv":2627.98}]}
{"op":"mcm","clk":"4226158898","pt":1631447364887,"mc":[{"id":"1.187552454","rc":[{"batb":[[0,2.48,3],[1,1.8,11.86],[2,1.7,16.95]],"batl":[[0,4.5,2]],"ltp":2.5,"tv":829.07,"id":9345630},{"batb":[[0,1.29,499.02],[1,1.28,9],[2,1.2,385.57]],"ltp":1.85,"tv":1798.91,"id":9028621}]}]}
{"op":"mcm","clk":"4226159078","pt":1631447366236,"mc":[{"id":"1.187552454","rc":[{"batb":[[1,2.46,3],[2,2.44,3]],"ltp":2.5,"tv":829.07,"id":9345630},{"batl":[[0,1.85,395.52]],"ltp":1.85,"tv":1798.91,"id":9028621}]}]}
{"op":"mcm","clk":"4226159327","pt":1631447367832,"mc":[{"id":"1.187552454","rc":[{"batl":[[0,1.68,6],[1,1.85,395.52]],"ltp":1.85,"tv":1798.91,"id":9028621}]}]}
{"op":"mcm","clk":"4226159608","pt":1631447369539,"mc":[{"id":"1.187552454","rc":[{"batl":[[0,1.44,1522.78],[1,1.68,6],[2,1.85,395.52]],"ltp":1.85,"tv":1798.91,"id":9028621}]}]}
{"op":"mcm","clk":"4226159628","pt":1631447369634,"mc":[{"id":"1.187552454","rc":[{"batl":[[0,1.68,6],[1,1.85,395.52],[2,1.85,0]],"ltp":1.85,"tv":1798.91,"id":9028621}]}]}
{"op":"mcm","clk":"4226159846","pt":1631447370948,"mc":[{"id":"1.187552454","rc":[{"batb":[[0,2.84,4],[1,2.48,3],[2,2.46,3]],"ltp":2.5,"tv":829.07,"id":9345630},{"batl":[[0,1.56,6],[1,1.68,6],[2,1.85,395.52]],"ltp":1.85,"tv":1798.91,"id":9028621}]}]}
{"op":"mcm","clk":"4226160505","pt":1631447375519,"mc":[{"id":"1.187552454","rc":[{"batl":[[1,1.59,2.91],[2,1.68,6]],"ltp":1.85,"tv":1798.91,"id":9028621}]}]}
{"op":"mcm","clk":"4226160922","pt":1631447378549,"mc":[{"id":"1.187552454","rc":[{"batb":[[0,2.84,7],[1,2.82,4],[2,1.8,11.86]],"ltp":2.5,"tv":829.07,"id":9345630},{"batb":[[1,1.2,385.57],[2,1.17,314.03]],"batl":[[0,1.55,6],[1,1.56,6],[2,1.59,2.91]],"ltp":1.85,"tv":1798.91,"id":9028621}]}]}
{"op":"mcm","clk":"4226160949","pt":1631447378747,"mc":[{"id":"1.187552454","rc":[{"batb":[[0,3.3,3],[1,3.25,3],[2,2.84,7]],"batl":[[0,3.55,3],[1,4.5,2]],"ltp":2.5,"tv":829.07,"id":9345630},{"batb":[[0,1.39,8],[1,1.38,7],[2,1.29,499.02]],"batl":[[0,1.43,7],[1,1.55,6],[2,1.56,6]],"ltp":1.85,"tv":1798.91,"id":9028621}]}]}
{"op":"mcm","clk":"4226162845","pt":1631447393268,"mc":[{"id":"1.187552454","rc":[{"batb":[[0,2.84,3],[1,2,11.86],[2,1.8,11.86]],"ltp":2.5,"tv":829.07,"id":9345630},{"batb":[[0,1.29,499.02],[1,1.2,385.57],[2,1.17,314.03]],"batl":[[0,1.59,2.91],[1,1.85,391.52],[2,1.56,0]],"ltp":1.85,"tv":1798.91,"id":9028621}]}]}
{"op":"mcm","clk":"4226163261","pt":1631447396464,"mc":[{"id":"1.187552454","rc":[{"batb":[[1,2.82,3],[2,2,11.86]],"ltp":2.5,"tv":829.07,"id":9345630},{"batb":[[1,1.28,6],[2,1.2,385.57]],"ltp":1.85,"tv":1798.91,"id":9028621}]}]}
{"op":"mcm","clk":"4226163300","pt":1631447396765,"mc":[{"id":"1.187552454","rc":[{"batl":[[0,4.5,2]],"ltp":2.5,"tv":829.07,"id":9345630},{"batl":[[0,1.55,6],[1,1.59,2.91],[2,1.85,391.52]],"ltp":1.85,"tv":1798.91,"id":9028621}]}]}
{"op":"mcm","clk":"4226164672","pt":1631447407496,"mc":[{"id":"1.187552454","rc":[{"trd":[[2.82,3],[2.84,25.77]],"batb":[[0,1.7,16.95],[1,1.6,98.86],[2,1.5,106.77]],"ltp":2.82,"tv":835.07,"id":9345630},{"trd":[[1.55,40.37],[1.59,291.75]],"batb":[[0,1.7,124.73],[1,1.29,499.02],[2,1.28,6]],"batl":[[0,1.85,391.52],[1,1.59,0],[2,1.85,0]],"ltp":1.59,"tv":1827.69,"id":9028621}],"tv":2662.76}]}
{"op":"mcm","clk":"4226165122","pt":1631447410598,"mc":[{"id":"1.187552454","rc":[{"batb":[[0,2.8,3],[1,2.78,4],[2,2.16,3]],"ltp":2.82,"tv":835.07,"id":9345630},{"trd":[[1.7,258]],"batb":[[0,1.29,499.02],[1,1.2,385.57],[2,1.17,314.03]],"batl":[[0,1.85,395.52]],"ltp":1.7,"tv":2077.15,"id":9028621}],"tv":2912.23}]}
{"op":"mcm","clk":"4226165432","pt":1631447412582,"mc":[{"id":"1.187552454","rc":[{"batl":[[0,1.7,19.83],[1,1.85,395.52]],"ltp":1.7,"tv":2077.15,"id":9028621}]}]}
{"op":"mcm","clk":"4226165568","pt":1631447413530,"mc":[{"id":"1.187552454","rc":[{"batl":[[0,1.7,29.75]],"ltp":1.7,"tv":2077.15,"id":9028621}]}]}
{"op":"mcm","clk":"4226165702","pt":1631447414545,"mc":[{"id":"1.187552454","rc":[{"batb":[[1,1.28,6],[2,1.2,385.57]],"batl":[[0,1.56,5],[1,1.7,4.27],[2,1.85,395.52]],"ltp":1.7,"tv":2077.15,"id":9028621}]}]}
{"op":"mcm","clk":"4226165768","pt":1631447415030,"mc":[{"id":"1.187552454","rc":[{"trd":[[2.78,12.37],[2.8,9]],"batb":[[0,2.16,3],[1,2.14,3],[2,1.8,11.86]],"ltp":2.78,"tv":850.07,"id":9345630},{"trd":[[1.56,28.22]],"batb":[[0,1.56,2.78],[1,1.29,499.02],[2,1.28,6]],"batl":[[0,1.7,4.27],[1,1.85,395.52],[2,1.85,0]],"ltp":1.56,"tv":2085.37,"id":9028621}],"tv":2935.45}]}
{"op":"mcm","clk":"4226166273","pt":1631447418539,"mc":[{"id":"1.187552454","rc":[{"batb":[[0,2.8,4.89],[1,2.42,4],[2,2.4,4]],"batl":[[0,3.25,16.98],[1,4.5,2]],"ltp":2.78,"tv":850.07,"id":9345630},{"trd":[[1.56,33.78]],"batb":[[0,1.29,499.02],[1,1.28,6],[2,1.25,237.31]],"batl":[[0,1.48,92.26],[1,1.56,5.93],[2,1.57,5]],"ltp":1.56,"tv":2090.94,"id":9028621}],"tv":2941.01}]}
{"op":"mcm","clk":"4226166422","pt":1631447419535,"mc":[{"id":"1.187552454","rc":[{"batl":[[0,4.5,2],[1,4.5,0]],"ltp":2.78,"tv":850.07,"id":9345630},{"batl":[[0,1.56,11.36],[1,1.57,5],[2,1.7,10.27]],"ltp":1.56,"tv":2090.94,"id":9028621}]}]}
{"op":"mcm","clk":"4226166548","pt":1631447420451,"mc":[{"id":"1.187552454","rc":[{"batb":[[0,2.42,4],[1,2.4,4],[2,2.16,3]],"ltp":2.78,"tv":850.07,"id":9345630},{"batl":[[0,1.56,37.87]],"ltp":1.56,"tv":2090.94,"id":9028621}]}]}
{"op":"mcm","clk":"4226166724","pt":1631447421537,"mc":[{"id":"1.187552454","rc":[{"batb":[[0,2.74,3],[1,2.72,3],[2,2.42,4]],"ltp":2.78,"tv":850.07,"id":9345630},{"batl":[[0,1.56,13.57],[2,1.7,6]],"ltp":1.56,"tv":2090.94,"id":9028621}]}]}
{"op":"mcm","clk":"4226166838","pt":1631447422547,"mc":[{"id":"1.187552454","rc":[{"batl":[[0,1.57,5],[1,1.7,6],[2,1.85,395.52]],"ltp":1.56,"tv":2090.94,"id":9028621}]}]}
{"op":"mcm","clk":"4226167110","pt":1631447424562,"mc":[{"id":"1.187552454","rc":[{"batb":[[0,2.78,3],[1,2.74,3],[2,2.72,3]],"ltp":2.78,"tv":850.07,"id":9345630}]}]}
{"op":"mcm","clk":"4226167196","pt":1631447425258,"mc":[{"id":"1.187552454","rc":[{"batb":[[0,2.74,3],[1,2.72,3],[2,2.42,4]],"batl":[[0,3.3,3],[1,4.5,2]],"ltp":2.78,"tv":850.07,"id":9345630},{"batb":[[1,1.25,237.31],[2,1.2,385.57]],"batl":[[0,1.49,7],[1,1.57,5],[2,1.7,6]],"ltp":1.56,"tv":2090.94,"id":9028621}]}]}
{"op":"mcm","clk":"4226167625","pt":1631447428455,"mc":[{"id":"1.187552454","rc":[{"batb":[[0,2.98,3],[1,2.74,3],[2,2.72,3]],"ltp":2.78,"tv":850.07,"id":9345630},{"batb":[[0,1.42,6],[1,1.29,499.02],[2,1.25,237.31]],"ltp":1.56,"tv":2090.94,"id":9028621}]}]}
{"op":"mcm","clk":"4226170615","pt":1631447451475,"mc":[{"id":"1.187552454","rc":[{"trd":[[3,4.82]],"ltp":3.0,"tv":851.88,"id":9345630},{"trd":[[1.49,3.66]],"batl":[[0,1.49,3.34]],"ltp":1.49,"tv":2094.6,"id":9028621}],"tv":2946.49}]}
{"op":"mcm","clk":"4226170643","pt":1631447451676,"mc":[{"id":"1.187552454","rc":[{"batb":[[0,2.74,3],[1,1.8,11.86],[2,1.7,16.95]],"ltp":3.0,"tv":851.88,"id":9345630},{"batb":[[0,1.29,499.02],[1,1.25,237.31],[2,1.2,385.57]],"batl":[[0,1.85,391.52],[1,810,0.07],[2,1.7,0]],"ltp":1.49,"tv":2094.6,"id":9028621}]}]}
{"op":"mcm","clk":"4226171164","pt":1631447455578,"mc":[{"id":"1.187552454","rc":[{"batb":[[1,2.72,2],[2,1.8,11.86]],"batl":[[0,4.5,3]],"ltp":3.0,"tv":851.88,"id":9345630},{"batb":[[1,1.28,4],[2,1.25,237.31]],"batl":[[0,1.57,6.89],[1,1.58,6],[2,1.85,391.52]],"ltp":1.49,"tv":2094.6,"id":9028621}]}]}
{"op":"mcm","clk":"4226171588","pt":1631447458759,"mc":[{"id":"1.187552454","rc":[{"batl":[[0,1.57,12.89]],"ltp":1.49,"tv":2094.6,"id":9028621}]}]}
{"op":"mcm","clk":"4226175066","pt":1631447484343,"mc":[{"id":"1.187552454","rc":[{"batb":[[0,1.29,8]],"ltp":1.49,"tv":2094.6,"id":9028621}]}]}
{"op":"mcm","clk":"4226175155","pt":1631447485043,"mc":[{"id":"1.187552454","rc":[{"batb":[[1,1.8,11.86],[2,1.7,16.95]],"ltp":3.0,"tv":851.88,"id":9345630},{"batb":[[1,1.25,237.31],[2,1.2,385.57]],"batl":[[0,1.57,6],[1,1.85,391.52],[2,810,0.07]],"ltp":1.49,"tv":2094.6,"id":9028621}]}]}
{"op":"mcm","clk":"4226175310","pt":1631447486363,"mc":[{"id":"1.187552454","rc":[{"trd":[[2.74,9.44]],"batb":[[0,1.8,11.86],[1,1.7,16.95],[2,1.6,98.86]],"batl":[[0,2.46,1.56],[1,4.5,3]],"ltp":2.74,"tv":861.32,"id":9345630},{"trd":[[1.57,6]],"batb":[[0,1.68,12],[1,1.29,8],[2,1.25,237.31]],"batl":[[0,1.85,391.52],[1,810,0.07],[2,810,0]],"ltp":1.57,"tv":2100.6,"id":9028621}],"tv":2961.93}]}
{"op":"mcm","clk":"4226175349","pt":1631447486668,"mc":[{"id":"1.187552454","rc":[{"batl":[[0,4.5,3],[1,4.5,0]],"ltp":2.74,"tv":861.32,"id":9345630},{"batb":[[0,1.68,6]],"ltp":1.57,"tv":2100.6,"id":9028621}]}]}
{"op":"mcm","clk":"4226175569","pt":1631447488533,"mc":[{"id":"1.187552454","rc":[{"trd":[[2.48,113.95]],"ltp":2.48,"tv":865.32,"id":9345630},{"trd":[[1.68,17.9]],"batb":[[0,1.36,545.59]],"ltp":1.68,"tv":2106.5,"id":9028621}],"tv":2971.83}]}
{"op":"mcm","clk":"4226175708","pt":1631447489553,"mc":[{"id":"1.187552454","rc":[{"trd":[[2.48,114.02]],"batb":[[0,2.16,3],[1,2.14,3],[2,1.8,11.86]],"ltp":2.48,"tv":865.39,"id":9345630},{"trd":[[1.68,18]],"batb":[[0,1.36,545.49]],"batl":[[0,1.85,395.52]],"ltp":1.68,"tv":2106.6,"id":9028621}],"tv":2972.0}]}
{"op":"mcm","clk":"4226175855","pt":1631447490560,"mc":[{"id":"1.187552454","rc":[{"batl":[[0,1.68,5.89],[1,1.85,395.52],[2,810,0.07]],"ltp":1.68,"tv":2106.6,"id":9028621}]}]}
{"op":"mcm","clk":"4226175971","pt":1631447491474,"mc":[{"id":"1.187552454","rc":[{"batl":[[0,3.8,2],[1,4.5,3]],"ltp":2.48,"tv":865.39,"id":9345630},{"batb":[[0,1.36,554.49],[1,1.35,8],[2,1.29,8]],"batl":[[0,1.85,395.52],[1,810,0.07],[2,810,0]],"ltp":1.68,"tv":2106.6,"id":9028621}]}]}
{"op":"mcm","clk":"4226176291","pt":1631447494058,"mc":[{"id":"1.187552454","rc":[{"batb":[[0,2.7,3],[1,2.46,3],[2,2.44,3]],"ltp":2.48,"tv":865.39,"id":9345630},{"batl":[[0,1.58,5],[1,1.68,5],[2,1.85,395.52]],"ltp":1.68,"tv":2106.6,"id":9028621}]}]}
{"op":"mcm","clk":"4226176455","pt":1631447495480,"mc":[{"id":"1.187552454","rc":[{"batl":[[1,1.68,6.71],[2,1.83,6.89]],"ltp":1.68,"tv":2106.6,"id":9028621}]}]}
{"op":"mcm","clk":"4226176902","pt":1631447499389,"mc":[{"id":"1.187552454","rc":[{"batl":[[2,1.85,395.52]],"ltp":1.68,"tv":2106.6,"id":9028621}]}]}
{"op":"mcm","clk":"4226177317","pt":1631447502581,"mc":[{"id":"1.187552454","rc":[{"batb":[[0,2.72,3],[1,2.7,3],[2,2.46,3]],"ltp":2.48,"tv":865.39,"id":9345630}]}]}
{"op":"mcm","clk":"4226177359","pt":1631447502853,"mc":[{"id":"1.187552454","rc":[{"batb":[[2,1.25,237.31]],"ltp":1.68,"tv":2106.6,"id":9028621}]}]}
{"op":"mcm","clk":"4226177577","pt":1631447504550,"mc":[{"id":"1.187552454","rc":[{"batl":[[1,4.5,0]],"ltp":2.48,"tv":865.39,"id":9345630},{"batb":[[1,1.25,237.31],[2,1.2,385.57]],"batl":[[1,1.66,6.89],[2,1.67,6.89]],"ltp":1.68,"tv":2106.6,"id":9028621}]}]}
{"op":"mcm","clk":"4226177939","pt":1631447507590,"mc":[{"id":"1.187552454","rc":[{"trd":[[2.72,7]],"batb":[[0,2.7,3],[1,1.8,11.86],[2,1.7,16.95]],"ltp":2.72,"tv":869.39,"id":9345630},{"batb":[[1,1.35,6],[2,1.25,237.31]],"ltp":1.68,"tv":2106.6,"id":9028621}],"tv":2976.0}]}
{"op":"mcm","clk":"4226177950","pt":1631447507681,"mc":[{"id":"1.187552454","rc":[{"batb":[[0,1.8,11.86],[1,1.7,16.95],[2,1.6,98.86]],"ltp":2.72,"tv":869.39,"id":9345630}]}]}
{"op":"mcm","clk":"4226178333","pt":1631447510569,"mc":[{"id":"1.187552454","rc":[{"batb":[[0,2.68,3],[1,1.8,11.86],[2,1.7,16.95]],"ltp":2.72,"tv":869.39,"id":9345630},{"batb":[[2,1.2,385.57]],"batl":[[0,1.39,122.91],[1,1.58,5],[2,1.66,6.89]],"ltp":1.68,"tv":2106.6,"id":9028621}]}]}
{"op":"mcm","clk":"4226178405","pt":1631447511049,"mc":[{"id":"1.187552454","rc":[{"batb":[[0,2.7,4],[1,2.68,3],[2,1.8,11.86]],"ltp":2.72,"tv":869.39,"id":9345630}]}]}
{"op":"mcm","clk":"4226178713","pt":1631447513494,"mc":[{"id":"1.187552454","rc":[{"batb":[[2,2,11.86]],"ltp":2.72,"tv":869.39,"id":9345630},{"trd":[[1.39,19.46]],"batl":[[0,1.39,113.18]],"ltp":1.39,"tv":2126.06,"id":9028621}],"tv":2995.46}]}
{"op":"mcm","clk":"4226178817","pt":1631447514283,"mc":[{"id":"1.187552454","rc":[{"trd":[[1.39,67.29]],"batl":[[0,1.39,89.26]],"ltp":1.39,"tv":2173.89,"id":9028621}],"tv":3043.29}]}
{"op":"mcm","clk":"4226178911","pt":1631447515208,"mc":[{"id":"1.187552454","rc":[{"batb":[[0,2,11.86],[1,1.8,11.86],[2,1.7,16.95]],"ltp":2.72,"tv":869.39,"id":9345630},{"trd":[[1.39,162.95]],"batb":[[0,1.36,545.49],[1,1.2,385.57],[2,1.17,314.03]],"batl":[[0,1.66,6.89],[1,1.67,6.89],[2,1.68,1.71]],"ltp":1.39,"tv":2269.55,"id":9028621}],"tv":3138.95}]}
{"op":"mcm","clk":"4226179197","pt":1631447517508,"mc":[{"id":"1.187552454","rc":[{"batb":[[0,1.39,11.96],[1,1.36,545.49],[2,1.2,385.57]],"batl":[[0,1.68,1.71],[1,1.85,391.52],[2,44,7.23]],"ltp":1.39,"tv":2269.55,"id":9028621}]}]}
{"op":"mcm","clk":"4226179311","pt":1631447518595,"mc":[{"id":"1.187552454","rc":[{"batb":[[0,2.5,4],[1,2.48,4],[2,2,11.86]],"ltp":2.72,"tv":869.39,"id":9345630},{"batb":[[0,1.39,7.69]],"batl":[[0,1.66,5],[1,1.68,1.71],[2,1.85,391.52]],"ltp":1.39,"tv":2269.55,"id":9028621}]}]}
{"op":"mcm","clk":"4226179410","pt":1631447519378,"mc":[{"id":"1.187552454","rc":[{"batb":[[0,1.39,17.53]],"ltp":1.39,"tv":2269.55,"id":9028621}]}]}
{"op":"mcm","clk":"4226179561","pt":1631447520479,"mc":[{"id":"1.187552454","rc":[{"batb":[[2,2.16,4]],"ltp":2.72,"tv":869.39,"id":9345630},{"batb":[[0,1.39,3.07]],"batl":[[2,1.85,396.52]],"ltp":1.39,"tv":2269.55,"id":9028621}]}]}
{"op":"mcm","clk":"4226179601","pt":1631447520804,"mc":[{"id":"1.187552454","rc":[{"batb":[[0,1.36,545.49],[1,1.2,385.57],[2,1.17,314.03]],"ltp":1.39,"tv":2269.55,"id":9028621}]}]}
{"op":"mcm","clk":"4226179839","pt":1631447522411,"mc":[{"id":"1.187552454","rc":[{"batb":[[0,1.4,17.22],[1,1.39,17.66],[2,1.36,545.49]],"ltp":1.39,"tv":2269.55,"id":9028621}]}]}
{"op":"mcm","clk":"4226180636","pt":1631447528568,"mc":[{"id":"1.187552454","rc":[{"batb":[[2,1.2,385.57]],"batl":[[0,1.51,20.68],[1,1.66,5],[2,1.68,1.71]],"ltp":1.39,"tv":2269.55,"id":9028621}]}]}
{"op":"mcm","clk":"4226180662","pt":1631447528777,"mc":[{"id":"1.187552454","rc":[{"batb":[[0,1.2,385.57],[1,1.17,314.03],[2,1.11,269.63]],"batl":[[0,1.66,5],[1,1.68,1.71],[2,1.85,396.52]],"ltp":1.39,"tv":2269.55,"id":9028621}]}]}
{"op":"mcm","clk":"4226180883","pt":1631447530407,"mc":[{"id":"1.187552454","rc":[{"batb":[[0,2.62,8],[1,2.5,4],[2,2.48,4]],"ltp":2.72,"tv":869.39,"id":9345630},{"batl":[[0,1.62,12],[1,1.66,5],[2,1.68,1.71]],"ltp":1.39,"tv":2269.55,"id":9028621}]}]}
{"op":"mcm","clk":"4226181003","pt":1631447531488,"mc":[{"id":"1.187552454","rc":[{"batb":[[0,2.62,4],[2,2.16,4]],"batl":[[0,3.5,3]],"ltp":2.72,"tv":869.39,"id":9345630},{"batb":[[0,1.4,6],[1,1.39,5],[2,1.2,385.57]],"batl":[[0,1.62,6]],"ltp":1.39,"tv":2269.55,"id":9028621}]}]}
{"op":"mcm","clk":"4226181105","pt":1631447532281,"mc":[{"id":"1.187552454","rc":[{"batb":[[2,2,11.86]],"batl":[[1,6,2]],"ltp":2.72,"tv":869.39,"id":9345630},{"batb":[[2,1.29,577.8]],"ltp":1.39,"tv":2269.55,"id":9028621}]}]}
{"op":"mcm","clk":"4226181349","pt":1631447534301,"mc":[{"id":"1.187552454","rc":[{"batb":[[0,2.62,8],[1,2.6,4],[2,2.5,4]],"ltp":2.72,"tv":869.39,"id":9345630},{"batl":[[0,1.62,12]],"ltp":1.39,"tv":2269.55,"id":9028621}]}]}
{"op":"mcm","clk":"4226181788","pt":1631447537614,"mc":[{"id":"1.187552454","rc":[{"batb":[[0,1.4,23.22]],"ltp":1.39,"tv":2269.55,"id":9028621}]}]}
{"op":"mcm","clk":"4226181978","pt":1631447539294,"mc":[{"id":"1.187552454","rc":[{"batb":[[0,1.41,16.8],[1,1.4,23.22],[2,1.39,5]],"ltp":1.39,"tv":2269.55,"id":9028621}]}]}
{"op":"mcm","clk":"4226182134","pt":1631447540709,"mc":[{"id":"1.187552454","rc":[{"batl":[[0,3.35,2],[1,3.5,3],[2,6,2]],"ltp":2.72,"tv":869.39,"id":9345630},{"batl":[[0,1.49,5],[1,1.62,12],[2,1.66,5]],"ltp":1.39,"tv":2269.55,"id":9028621}]}]}
{"op":"mcm","clk":"4226182322","pt":1631447542543,"mc":[{"id":"1.187552454","rc":[{"batb":[[0,1.41,22.8]],"ltp":1.39,"tv":2269.55,"id":9028621}]}]}
{"op":"mcm","clk":"4226182454","pt":1631447543520,"mc":[{"id":"1.187552454","rc":[{"batl":[[1,3.45,3],[2,3.5,3]],"ltp":2.72,"tv":869.39,"id":9345630},{"batb":[[0,1.41,6],[1,1.4,6]],"ltp":1.39,"tv":2269.55,"id":9028621}]}]}
{"op":"mcm","clk":"4226182512","pt":1631447543899,"mc":[{"id":"1.187552454","rc":[{"batb":[[0,2.98,2],[1,2.62,8],[2,2.6,4]],"batl":[[2,3.5,0]],"ltp":2.72,"tv":869.39,"id":9345630},{"batb":[[1,1.29,577.8],[2,1.2,385.57]],"ltp":1.39,"tv":2269.55,"id":9028621}]}]}
{"op":"mcm","clk":"4226183082","pt":1631447548426,"mc":[{"id":"1.187552454","rc":[{"batb":[[1,2.62,4],[2,2,11.86]],"ltp":2.72,"tv":869.39,"id":9345630},{"batb":[[1,1.3,22.96],[2,1.29,577.8]],"batl":[[1,1.62,6],[2,1.68,1.71]],"ltp":1.39,"tv":2269.55,"id":9028621}]}]}
{"op":"mcm","clk":"4226183476","pt":1631447551634,"mc":[{"id":"1.187552454","rc":[{"batb":[[0,3,2],[1,2.98,2],[2,2.62,4]],"ltp":2.72,"tv":869.39,"id":9345630},{"batb":[[0,1.42,5],[1,1.41,6],[2,1.3,22.96]],"ltp":1.39,"tv":2269.55,"id":9028621}]}]}
{"op":"mcm","clk":"4226183791","pt":1631447554208,"mc":[{"id":"1.187552454","rc":[{"batb":[[0,2,11.86],[1,1.8,11.86],[2,1.7,16.95]],"ltp":2.72,"tv":869.39,"id":9345630},{"batb":[[0,1.3,22.96],[1,1.29,577.8],[2,1.2,385.57]],"batl":[[0,1.68,1.71],[1,1.85,391.52],[2,44,7.23]],"ltp":1.39,"tv":2269.55,"id":9028621}]}]}
{"op":"mcm","clk":"4226184177","pt":1631447557422,"mc":[{"id":"1.187552454","rc":[{"batb":[[0,2.6,2],[1,2.58,2],[2,2.16,4]],"batl":[[0,4.4,3]],"ltp":2.72,"tv":869.39,"id":9345630},{"batb":[[0,1.3,31.96],[1,1.29,586.8]],"batl":[[1,1.85,395.52]],"ltp":1.39,"tv":2269.55,"id":9028621}]}]}
{"op":"mcm","clk":"4226184548","pt":1631447560642,"mc":[{"id":"1.187552454","rc":[{"batl":[[0,1.63,5],[1,1.68,1.71],[2,1.85,395.52]],"ltp":1.39,"tv":2269.55,"id":9028621}]}]}
{"op":"mcm","clk":"4226184870","pt":1631447563042,"mc":[{"id":"1.187552454","rc":[{"batb":[[0,1.3,9],[1,1.29,9]],"batl":[[2,1.85,4]],"ltp":1.39,"tv":2269.55,"id":9028621}]}]}
{"op":"mcm","clk":"4226185105","pt":1631447564937,"mc":[{"id":"1.187552454","rc":[{"batb":[[0,3.2,3],[1,2.6,2],[2,2.58,2]],"ltp":2.72,"tv":869.39,"id":9345630},{"batl":[[0,1.45,7],[1,1.63,5],[2,1.68,1.71]],"ltp":1.39,"tv":2269.55,"id":9028621}]}]}
{"op":"mcm","clk":"4226185289","pt":1631447566529,"mc":[{"id":"1.187552454","rc":[{"batb":[[2,1.23,605.12]],"ltp":1.39,"tv":2269.55,"id":9028621}]}]}
{"op":"mcm","clk":"4226185673","pt":1631447569440,"mc":[{"id":"1.187552454","rc":[{"batb":[[2,2,11.86]],"ltp":2.72,"tv":869.39,"id":9345630},{"batb":[[1,1.23,605.12],[2,1.2,385.57]],"ltp":1.39,"tv":2269.55,"id":9028621}]}]}
{"op":"mcm","clk":"4226185726","pt":1631447569873,"mc":[{"id":"1.187552454","rc":[{"batb":[[0,3.2,6],[1,3.15,3],[2,2.6,2]],"ltp":2.72,"tv":869.39,"id":9345630},{"batl":[[0,1.45,15]],"ltp":1.39,"tv":2269.55,"id":9028621}]}]}
{"op":"mcm","clk":"4226185905","pt":1631447570964,"mc":[{"id":"1.187552454","rc":[{"batb":[[0,1.3,31.96]],"ltp":1.39,"tv":2269.55,"id":9028621}]}]}
{"op":"mcm","clk":"4226186142","pt":1631447572565,"mc":[{"id":"1.187552454","rc":[{"batb":[[0,3.55,3],[1,3.5,2],[2,3.2,6]],"ltp":2.72,"tv":869.39,"id":9345630},{"batl":[[0,1.39,6],[1,1.45,15]],"ltp":1.39,"tv":2269.55,"id":9028621}]}]}
{"op":"mcm","clk":"4226186157","pt":1631447572671,"mc":[{"id":"1.187552454","rc":[{"batb":[[1,1.29,6],[2,1.23,605.12]],"ltp":1.39,"tv":2269.55,"id":9028621}]}]}
{"op":"mcm","clk":"4226186394","pt":1631447574462,"mc":[{"id":"1.187552454","rc":[{"batb":[[0,1.3,9]],"ltp":1.39,"tv":2269.55,"id":9028621}]}]}
{"op":"mcm","clk":"4226186710","pt":1631447576373,"mc":[{"id":"1.187552454","rc":[{"batb":[[1,1.29,29.75]],"ltp":1.39,"tv":2269.55,"id":9028621}]}]}
{"op":"mcm","clk":"4226187914","pt":1631447584328,"mc":[{"id":"1.187552454","rc":[{"batb":[[1,3.2,3],[2,2,11.86]],"batl":[[0,3.75,20],[1,4.4,3]],"ltp":2.72,"tv":869.39,"id":9345630},{"batb":[[1,1.29,23.75]],"batl":[[1,1.45,7]],"ltp":1.39,"tv":2269.55,"id":9028621}]}]}
{"op":"mcm","clk":"4226188366","pt":1631447586450,"mc":[{"id":"1.187552454","rc":[{"batb":[[2,1.28,24.6]],"batl":[[0,1.39,6.85]],"ltp":1.39,"tv":2269.55,"id":9028621}]}]}
{"op":"mcm","clk":"4226188523","pt":1631447587556,"mc":[{"id":"1.187552454","rc":[{"batb":[[1,3.5,3],[2,3.2,3]],"ltp":2.72,"tv":869.39,"id":9345630},{"batb":[[2,1.23,605.12]],"ltp":1.39,"tv":2269.55,"id":9028621}]}]}
{"op":"mcm","clk":"4226188789","pt":1631447589409,"mc":[{"id":"1.187552454","rc":[{"batl":[[1,3.8,15],[2,4.4,3]],"ltp":2.72,"tv":869.39,"id":9345630},{"batb":[[1,1.23,605.12],[2,1.2,385.57]],"ltp":1.39,"tv":2269.55,"id":9028621}]}]}
{"op":"mcm","clk":"4226189107","pt":1631447591727,"mc":[{"id":"1.187552454","rc":[{"batl":[[0,3.8,15],[1,4.4,3],[2,4.4,0]],"ltp":2.72,"tv":869.39,"id":9345630}]}]}
{"op":"mcm","clk":"4226189488","pt":1631447594238,"mc":[{"id":"1.187552454","rc":[{"batb":[[0,2,11.86],[1,1.8,11.86],[2,1.7,16.95]],"ltp":2.72,"tv":869.39,"id":9345630},{"batb":[[0,1.23,605.12],[1,1.2,385.57],[2,1.17,314.03]],"batl":[[0,1.68,2.56],[1,1.72,483.76],[2,44,7.23]],"ltp":1.39,"tv":2269.55,"id":9028621}]}]}
{"op":"mcm","clk":"4226189577","pt":1631447594839,"mc":[{"id":"1.187552454","rc":[{"batl":[[0,3.95,20]],"ltp":2.72,"tv":869.39,"id":9345630},{"batl":[[0,1.68,1.71]],"ltp":1.39,"tv":2269.55,"id":9028621}]}]}
{"op":"mcm","clk":"4226189995","pt":1631447597441,"mc":[{"id":"1.187552454","rc":[{"batb":[[0,2.38,4],[1,2.36,3],[2,2,11.86]],"batl":[[0,3.65,15],[1,3.95,20],[2,5.4,2]],"ltp":2.72,"tv":869.39,"id":9345630},{"batb":[[0,1.23,607.12],[1,1.22,2],[2,1.2,385.57]],"batl":[[0,1.68,6.71]],"ltp":1.39,"tv":2269.55,"id":9028621}]}]}
{"op":"mcm","clk":"4226190062","pt":1631447597931,"mc":[{"id":"1.187552454","rc":[{"batl":[[0,1.68,7.56],[1,1.72,488.76]],"ltp":1.39,"tv":2269.55,"id":9028621}]}]}
{"op":"mcm","clk":"4226190420","pt":1631447600228,"mc":[{"id":"1.187552454","rc":[{"batb":[[0,2.46,4],[1,2.44,4],[2,2.38,4]],"ltp":2.72,"tv":869.39,"id":9345630}]}]}
{"op":"mcm","clk":"4226191198","pt":1631447605534,"mc":[{"id":"1.187552454","rc":[{"trd":[[3.65,17.26]],"batl":[[0,3.65,3.74]],"ltp":3.65,"tv":886.65,"id":9345630},{"trd":[[1.37,14]],"ltp":1.37,"tv":2283.55,"id":9028621}],"tv":3170.21}]}
{"op":"mcm","clk":"4226191629","pt":1631447608440,"mc":[{"id":"1.187552454","rc":[{"trd":[[3.65,17.58]],"batb":[[2,2,11.86]],"batl":[[0,3.65,3.42]],"ltp":3.65,"tv":886.97,"id":9345630},{"trd":[[1.37,14.85]],"ltp":1.37,"tv":2284.41,"id":9028621}],"tv":3171.39}]}
{"op":"mcm","clk":"4226191765","pt":1631447609433,"mc":[{"id":"1.187552454","rc":[{"trd":[[3.65,21]],"batl":[[0,3.95,20],[1,4.2,22.17]],"ltp":3.65,"tv":890.39,"id":9345630},{"trd":[[1.37,23.96]],"batl":[[0,1.35,130.36],[1,1.68,7.56],[2,1.72,488.76]],"ltp":1.37,"tv":2293.52,"id":9028621}],"tv":3183.92}]}
{"op":"mcm","clk":"4226191801","pt":1631447609651,"mc":[{"id":"1.187552454","rc":[{"batl":[[1,5.4,2],[2,5.4,0]],"ltp":3.65,"tv":890.39,"id":9345630},{"batb":[[1,1.17,314.03],[2,1.11,269.63]],"batl":[[0,1.68,7.56],[1,1.72,483.76],[2,44,7.23]],"ltp":1.37,"tv":2293.52,"id":9028621}]}]}
{"op":"mcm","clk":"4226192331","pt":1631447613428,"mc":[{"id":"1.187552454","rc":[{"batb":[[0,3.85,3],[1,3.8,3],[2,2.2,42.66]],"ltp":3.65,"tv":890.39,"id":9345630},{"batl":[[0,1.35,6],[1,1.6,14.63],[2,1.68,6.71]],"ltp":1.37,"tv":2293.52,"id":9028621}]}]}
{"op":"mcm","clk":"4226192557","pt":1631447615060,"mc":[{"id":"1.187552454","rc":[{"trd":[[3.95,20]],"batl":[[0,5.4,2],[1,5.4,0]],"ltp":3.95,"tv":910.39,"id":9345630},{"trd":[[1.33,59.4]],"batl":[[0,1.33,10.6],[1,1.35,6],[2,1.6,14.63]],"ltp":1.33,"tv":2352.92,"id":9028621}],"tv":3263.32}]}
{"op":"mcm","clk":"4226193040","pt":1631447618293,"mc":[{"id":"1.187552454","rc":[{"batb":[[0,4,2],[1,3.95,2],[2,3.85,3]],"ltp":3.95,"tv":910.39,"id":9345630},{"batb":[[1,1.22,12],[2,1.17,314.03]],"batl":[[0,1.33,10]],"ltp":1.33,"tv":2352.92,"id":9028621}]}]}
{"op":"mcm","clk":"4226193256","pt":1631447619379,"mc":[{"id":"1.187552454","rc":[{"batl":[[2,1.68,7.56]],"ltp":1.33,"tv":2352.92,"id":9028621}]}]}
{"op":"mcm","clk":"4226193488","pt":1631447621072,"mc":[{"id":"1.187552454","rc":[{"batb":[[0,2.2,42.66],[1,2,11.86],[2,1.8,11.86]],"ltp":3.95,"tv":910.39,"id":9345630},{"batb":[[0,1.24,28.7],[1,1.23,607.12],[2,1.22,12]],"batl":[[0,1.68,7.56],[1,1.72,483.76],[2,1.94,8.68]],"ltp":1.33,"tv":2352.92,"id":9028621}]}]}
{"op":"mcm","clk":"4226193928","pt":1631447624388,"mc":[{"id":"1.187552454","rc":[{"batb":[[0,2.66,3],[1,2.64,3],[2,2.46,3]],"batl":[[0,5.2,3],[1,5.4,2]],"ltp":3.95,"tv":910.39,"id":9345630},{"batb":[[0,1.24,67.4]],"ltp":1.33,"tv":2352.92,"id":9028621}]}]}
{"op":"mcm","clk":"4226194339","pt":1631447627472,"mc":[{"id":"1.187552454","rc":[{"batl":[[0,1.61,5.85],[1,1.68,6.71],[2,1.72,483.76]],"ltp":1.33,"tv":2352.92,"id":9028621}]}]}
{"op":"mcm","clk":"4226195020","pt":1631447632597,"mc":[{"id":"1.187552454","rc":[{"batb":[[1,1.23,2]],"ltp":1.33,"tv":2352.92,"id":9028621}]}]}
{"op":"mcm","clk":"4226195063","pt":1631447632881,"mc":[{"id":"1.187552454","rc":[{"batb":[[1,1.17,314.03],[2,1.11,269.63]],"ltp":1.33,"tv":2352.92,"id":9028621}]}]}
{"op":"mcm","clk":"4226195251","pt":1631447634408,"mc":[{"id":"1.187552454","rc":[{"batl":[[0,4.3,2],[1,5.2,3],[2,5.4,2]],"ltp":3.95,"tv":910.39,"id":9345630},{"batb":[[0,1.29,8],[1,1.24,67.4],[2,1.17,314.03]],"ltp":1.33,"tv":2352.92,"id":9028621}]}]}
{"op":"mcm","clk":"4226195524","pt":1631447636580,"mc":[{"id":"1.187552454","rc":[{"batb":[[1,1.24,679.28]],"ltp":1.33,"tv":2352.92,"id":9028621}]}]}
{"op":"mcm","clk":"4226195630","pt":1631447637585,"mc":[{"id":"1.187552454","rc":[{"batb":[[1,2.2,42.66],[2,2,11.86]],"batl":[[2,5.4,0]],"ltp":3.95,"tv":910.39,"id":9345630},{"batb":[[1,1.24,10]],"ltp":1.33,"tv":2352.92,"id":9028621}]}]}
{"op":"mcm","clk":"4226195739","pt":1631447638482,"mc":[{"id":"1.187552454","rc":[{"batl":[[0,3.8,16.35],[1,4.3,2],[2,5.2,3]],"ltp":3.95,"tv":910.39,"id":9345630},{"batb":[[0,1.33,20.88],[1,1.29,8],[2,1.24,10]],"batl":[[0,1.39,113.41],[1,1.61,5],[2,1.68,6.71]],"ltp":1.33,"tv":2352.92,"id":9028621}]}]}
{"op":"mcm","clk":"4226195765","pt":1631447638696,"mc":[{"id":"1.187552454","rc":[{"batl":[[0,4.3,2],[1,5.2,3],[2,5.2,0]],"ltp":3.95,"tv":910.39,"id":9345630},{"batl":[[0,1.61,5.85],[1,1.68,6.71],[2,1.72,483.76]],"ltp":1.33,"tv":2352.92,"id":9028621}]}]}
{"op":"mcm","clk":"4226196025","pt":1631447640594,"mc":[{"id":"1.187552454","rc":[{"batb":[[1,2.64,2],[2,2.2,42.66]],"batl":[[0,4.3,4]],"ltp":3.95,"tv":910.39,"id":9345630},{"batb":[[0,1.35,19.68],[1,1.33,20.88],[2,1.3,8]],"batl":[[0,1.55,3.84],[1,1.61,5]],"ltp":1.33,"tv":2352.92,"id":9028621}]}]}
{"op":"mcm","clk":"4226196194","pt":1631447641823,"mc":[{"id":"1.187552454","rc":[{"batb":[[0,3.55,3],[1,3.5,3],[2,2.66,3]],"ltp":3.95,"tv":910.39,"id":9345630},{"batl":[[0,1.39,7.85],[1,1.55,2.99],[2,1.61,5]],"ltp":1.33,"tv":2352.92,"id":9028621}]}]}
{"op":"mcm","clk":"4226196335","pt":1631447642931,"mc":[{"id":"1.187552454","rc":[{"batb":[[0,1.33,20.88],[1,1.3,8],[2,1.29,16]],"batl":[[1,1.55,8.99]],"ltp":1.33,"tv":2352.92,"id":9028621}]}]}
{"op":"mcm","clk":"4226196620","pt":1631447645112,"mc":[{"id":"1.187552454","rc":[{"batb":[[0,1.3,8],[1,1.29,16],[2,1.24,10]],"ltp":1.33,"tv":2352.92,"id":9028621}]}]}
{"op":"mcm","clk":"4226196884","pt":1631447646917,"mc":[{"id":"1.187552454","rc":[{"batb":[[0,1.31,22.22],[1,1.3,8],[2,1.29,16]],"ltp":1.33,"tv":2352.92,"id":9028621}]}]}
{"op":"mcm","clk":"4226197319","pt":1631447650139,"mc":[{"id":"1.187552454","rc":[{"batb":[[0,1.31,30.22]],"ltp":1.33,"tv":2352.92,"id":9028621}]}]}
{"op":"mcm","clk":"4226197839","pt":1631447654552,"mc":[{"id":"1.187552454","rc":[{"batb":[[0,2.66,3],[1,2.2,42.66],[2,2,11.86]],"batl":[[0,4.3,2],[1,5.2,0]],"ltp":3.95,"tv":910.39,"id":9345630},{"batb":[[0,1.31,22.22],[2,1.17,314.03]],"batl":[[0,1.55,3.84],[1,1.72,483.76],[2,1.94,8.68]],"ltp":1.33,"tv":2352.92,"id":9028621}]}]}
{"op":"mcm","clk":"4226198200","pt":1631447657242,"mc":[{"id":"1.187552454","rc":[{"trd":[[3.6,0.33]],"batl":[[0,3.55,3.29],[1,4.3,2]],"ltp":3.6,"tv":910.72,"id":9345630},{"trd":[[1.38,0.85]],"batl":[[0,1.55,2.99]],"ltp":1.38,"tv":2353.77,"id":9028621}],"tv":3264.5}]}
{"op":"mcm","clk":"4226198283","pt":1631447657830,"mc":[{"id":"1.187552454","rc":[{"batb":[[0,2.8,3],[1,2.78,3],[2,2.66,3]],"ltp":3.6,"tv":910.72,"id":9345630},{"batl":[[0,1.55,9.99]],"ltp":1.38,"tv":2353.77,"id":9028621}]}]}
{"op":"mcm","clk":"4226198579","pt":1631447660314,"mc":[{"id":"1.187552454","rc":[{"trd":[[3.55,3.29]],"batl":[[0,4.3,2],[1,4.3,0]],"ltp":3.55,"tv":914.01,"id":9345630},{"trd":[[1.39,171.35]],"batb":[[0,1.3,8],[1,1.17,314.03],[2,1.11,269.63]],"ltp":1.39,"tv":2362.17,"id":9028621}],"tv":3276.18}]}
{"op":"mcm","clk":"4226198747","pt":1631447661554,"mc":[{"id":"1.187552454","rc":[{"batb":[[0,3.95,6],[1,2.8,3],[2,2.78,3]],"ltp":3.55,"tv":914.01,"id":9345630},{"batl":[[0,1.36,14],[1,1.55,9.99],[2,1.72,483.76]],"ltp":1.39,"tv":2362.17,"id":9028621}]}]}
{"op":"mcm","clk":"4226198794","pt":1631447661931,"mc":[{"id":"1.187552454","rc":[{"batb":[[0,3.95,3]],"ltp":3.55,"tv":914.01,"id":9345630},{"batl":[[0,1.36,7]],"ltp":1.39,"tv":2362.17,"id":9028621}]}]}
{"op":"mcm","clk":"4226199000","pt":1631447663467,"mc":[{"id":"1.187552454","rc":[{"batb":[[1,1.29,9],[2,1.21,211.95]],"ltp":1.39,"tv":2362.17,"id":9028621}]}]}
{"op":"mcm","clk":"4226199046","pt":1631447663742,"mc":[{"id":"1.187552454","rc":[{"batb":[[2,1.24,28.7]],"ltp":1.39,"tv":2362.17,"id":9028621}]}]}
{"op":"mcm","clk":"4226199263","pt":1631447665119,"mc":[{"id":"1.187552454","rc":[{"batb":[[0,3.95,5],[1,3.9,2],[2,2.8,3]],"ltp":3.55,"tv":914.01,"id":9345630},{"batl":[[0,1.34,9],[1,1.36,7],[2,1.55,9.99]],"ltp":1.39,"tv":2362.17,"id":9028621}]}]}
{"op":"mcm","clk":"4226199738","pt":1631447669251,"mc":[{"id":"1.187552454","rc":[{"trd":[[3.95,21.18]],"batb":[[0,3.95,4.41],[2,2.2,42.66]],"ltp":3.95,"tv":915.19,"id":9345630},{"batb":[[0,1.31,7],[1,1.3,8],[2,1.29,9]],"ltp":1.39,"tv":2362.17,"id":9028621}],"tv":3277.36}]}
{"op":"mcm","clk":"4226200916","pt":1631447678579,"mc":[{"id":"1.187552454","rc":[{"trd":[[4.3,2]],"batb":[[0,2.2,42.66],[1,2,11.86],[2,1.8,11.86]],"ltp":4.3,"tv":917.19,"id":9345630},{"trd":[[1.21,18.72],[1.24,57.4],[1.29,18],[1.3,22.62],[1.31,14]],"batb":[[0,1.21,202.59],[1,1.17,314.03],[2,1.11,269.63]],"batl":[[0,1.55,2.99],[1,1.72,483.76],[2,1.94,8.68]],"ltp":1.21,"tv":2492.91,"id":9028621}],"tv":3410.1}]}
{"op":"mcm","clk":"4226201381","pt":1631447681551,"mc":[{"id":"1.187552454","rc":[{"batl":[[0,5.8,2]],"ltp":4.3,"tv":917.19,"id":9345630},{"batb":[[0,1.21,213.59],[1,1.2,11],[2,1.17,314.03]],"ltp":1.21,"tv":2492.91,"id":9028621}]}]}
{"op":"mcm","clk":"4226201411","pt":1631447681766,"mc":[{"id":"1.187552454","rc":[{"batb":[[0,2.38,4],[1,2.36,4],[2,2.2,42.66]],"ltp":4.3,"tv":917.19,"id":9345630},{"batl":[[0,1.55,7.99]],"ltp":1.21,"tv":2492.91,"id":9028621}]}]}
{"op":"mcm","clk":"4226201816","pt":1631447685088,"mc":[{"id":"1.187552454","rc":[{"batb":[[0,2.8,2],[1,2.78,3],[2,2.38,4]],"ltp":4.3,"tv":917.19,"id":9345630},{"batl":[[0,1.43,24.89],[1,1.55,7.99],[2,1.72,483.76]],"ltp":1.21,"tv":2492.91,"id":9028621}]}]}
{"op":"mcm","clk":"4226202377","pt":1631447689668,"mc":[{"id":"1.187552454","rc":[{"batb":[[0,1.21,11]],"ltp":1.21,"tv":2492.91,"id":9028621}]}]}
{"op":"mcm","clk":"4226202605","pt":1631447691466,"mc":[{"id":"1.187552454","rc":[{"batb":[[0,3.3,3],[1,3.25,3],[2,2.8,2]],"batl":[[0,4.1,2],[1,5.8,2]],"ltp":4.3,"tv":917.19,"id":9345630},{"batb":[[0,1.32,8],[1,1.21,11],[2,1.2,11]],"batl":[[0,1.43,7]],"ltp":1.21,"tv":2492.91,"id":9028621}]}]}
{"op":"mcm","clk":"4226202951","pt":1631447694000,"mc":[{"id":"1.187552454","rc":[{"batb":[[1,1.24,190.32],[2,1.21,11]],"ltp":1.21,"tv":2492.91,"id":9028621}]}]}
{"op":"mcm","clk":"4226203265","pt":1631447696484,"mc":[{"id":"1.187552454","rc":[{"trd":[[4.1,2]],"batl":[[0,5.8,2],[1,5.8,0]],"ltp":4.1,"tv":919.19,"id":9345630},{"trd":[[1.21,40.72],[1.24,438.05],[1.32,22.21]],"batb":[[0,1.17,314.03],[1,1.11,269.63],[2,1.1,296.59]],"batl":[[0,1.21,657.29],[1,1.43,7],[2,1.55,7.99]],"ltp":1.21,"tv":2917.77,"id":9028621}],"tv":3836.96}]}
{"op":"mcm","clk":"4226203403","pt":1631447697593,"mc":[{"id":"1.187552454","rc":[{"trd":[[5.7,3]],"batb":[[2,2.2,42.66]],"ltp":5.7,"tv":922.19,"id":9345630},{"trd":[[1.21,86.85]],"batb":[[0,1.06,494.32],[1,1.05,474.54],[2,1.03,494.32]],"batl":[[0,1.21,627.15],[2,1.52,23.41]],"ltp":1.21,"tv":2963.9,"id":9028621}],"tv":3886.09}]}
{"op":"mcm","clk":"4226203563","pt":1631447698916,"mc":[{"id":"1.187552454","rc":[{"batb":[[0,3.5,3],[1,3.45,3],[2,3.3,3]],"ltp":5.7,"tv":922.19,"id":9345630},{"batl":[[1,1.4,8],[2,1.43,7]],"ltp":1.21,"tv":2963.9,"id":9028621}]}]}
{"op":"mcm","clk":"4226203713","pt":1631447699930,"mc":[{"id":"1.187552454","rc":[{"trd":[[5.7,5]],"ltp":5.7,"tv":924.19,"id":9345630},{"trd":[[1.21,1331.74]],"batb":[[0,1.2,10],[1,1.19,11],[2,1.06,494.32]],"batl":[[0,1.4,8],[1,1.43,7],[2,1.52,23.41]],"ltp":1.21,"tv":4208.78,"id":9028621}],"tv":5132.98}]}
{"op":"mcm","clk":"4226203816","pt":1631447700730,"mc":[{"id":"1.187552454","rc":[{"trd":[[1.2,4]],"batb":[[0,1.2,8]],"ltp":1.2,"tv":4212.78,"id":9028621}],"tv":5136.98}]}
{"op":"mcm","clk":"4226204126","pt":1631447702498,"mc":[{"id":"1.187552454","rc":[{"batb":[[0,1.21,32.8],[1,1.2,8],[2,1.19,11]],"ltp":1.2,"tv":4212.78,"id":9028621}]}]}
{"op":"mcm","clk":"4226204268","pt":1631447703398,"mc":[{"id":"1.187552454","rc":[{"batb":[[2,2.2,42.66]],"ltp":5.7,"tv":924.19,"id":9345630},{"batb":[[0,1.21,79.61]],"batl":[[1,1.52,23.41],[2,1.55,2.99]],"ltp":1.2,"tv":4212.78,"id":9028621}]}]}
{"op":"mcm","clk":"4226205877","pt":1631447715064,"mc":[{"id":"1.187552454","rc":[{"batb":[[0,2.2,42.66],[1,2,11.86],[2,1.8,11.86]],"ltp":5.7,"tv":924.19,"id":9345630},{"batb":[[0,1.21,65.61],[1,1.06,494.32],[2,1.05,474.54]],"batl":[[0,1.52,23.41],[1,1.55,2.99],[2,1.72,483.76]],"ltp":1.2,"tv":4212.78,"id":9028621}]}]}
{"op":"mcm","clk":"4226206321","pt":1631447718232,"mc":[{"id":"1.187552454","rc":[{"batb":[[1,1.1,296.65],[2,1.06,494.32]],"ltp":1.2,"tv":4212.78,"id":9028621}]}]}
{"op":"mcm","clk":"4226206688","pt":1631447721044,"mc":[{"id":"1.187552454","rc":[{"batb":[[0,1.3,3.45],[1,1.21,65.61],[2,1.1,296.65]],"ltp":1.2,"tv":4212.78,"id":9028621}]}]}
{"op":"mcm","clk":"4226207439","pt":1631447725879,"mc":[{"id":"1.187552454","rc":[{"batb":[[0,1.4,3.67],[1,1.3,3.45],[2,1.21,65.61]],"ltp":1.2,"tv":4212.78,"id":9028621}]}]}
{"op":"mcm","clk":"4226207927","pt":1631447729436,"mc":[{"id":"1.187552454","rc":[{"trd":[[1.3,29.51],[1.4,7.34]],"batb":[[0,1.21,65.61],[1,1.06,494.32],[2,1.05,474.54]],"batl":[[0,1.22,101.33],[1,1.52,23.41],[2,1.55,2.99]],"ltp":1.3,"tv":4227.02,"id":9028621}],"tv":5151.22}]}
{"op":"mcm","clk":"4226208468","pt":1631447732520,"mc":[{"id":"1.187552454","rc":[{"batb":[[0,3,5.94],[1,2.6,3.71],[2,2.2,42.66]],"ltp":5.7,"tv":924.19,"id":9345630}]}]}
{"op":"mcm","clk":"4226208907","pt":1631447735516,"mc":[{"id":"1.187552454","rc":[{"trd":[[5.5,14.86]],"ltp":5.5,"tv":939.05,"id":9345630},{"trd":[[1.22,94.01]],"batb":[[0,1.06,494.32],[1,1.05,474.54],[2,1.03,494.32]],"batl":[[0,1.22,20.83],[1,1.55,2.99],[2,1.72,483.76]],"ltp":1.22,"tv":4321.03,"id":9028621}],"tv":5260.09}]}
{"op":"mcm","clk":"4226209064","pt":1631447736539,"mc":[{"id":"1.187552454","rc":[{"trd":[[5.5,19.48]],"batl":[[0,5.5,109.09]],"ltp":5.5,"tv":943.67,"id":9345630},{"trd":[[1.22,114.84]],"batb":[[0,1.22,27.56],[1,1.06,494.32],[2,1.05,474.54]],"batl":[[0,1.55,2.99],[1,1.72,483.76],[2,1.94,8.68]],"ltp":1.22,"tv":4341.86,"id":9028621}],"tv":5285.54}]}
{"op":"mcm","clk":"4226209212","pt":1631447737507,"mc":[{"id":"1.187552454","rc":[{"batl":[[0,5.5,104.87]],"ltp":5.5,"tv":943.67,"id":9345630},{"batb":[[0,1.22,51.24]],"ltp":1.22,"tv":4341.86,"id":9028621}]}]}
{"op":"mcm","clk":"4226209391","pt":1631447738522,"mc":[{"id":"1.187552454","rc":[{"batl":[[0,5.5,16.74]],"ltp":5.5,"tv":943.67,"id":9345630},{"batb":[[0,1.06,494.32],[1,1.05,474.54],[2,1.03,494.32]],"ltp":1.22,"tv":4341.86,"id":9028621}]}]}
{"op":"mcm","clk":"4226209512","pt":1631447739423,"mc":[{"id":"1.187552454","rc":[{"batl":[[0,5.5,74.5]],"ltp":5.5,"tv":943.67,"id":9345630},{"batb":[[0,1.22,61.59],[1,1.06,494.32],[2,1.05,474.54]],"ltp":1.22,"tv":4341.86,"id":9028621}]}]}
{"op":"mcm","clk":"4226209641","pt":1631447740426,"mc":[{"id":"1.187552454","rc":[{"batl":[[0,5.5,23.8]],"ltp":5.5,"tv":943.67,"id":9345630}]}]}
{"op":"mcm","clk":"4226209714","pt":1631447740972,"mc":[{"id":"1.187552454","rc":[{"batb":[[0,1.22,31.31]],"ltp":1.22,"tv":4341.86,"id":9028621}]}]}
{"op":"mcm","clk":"4226210382","pt":1631447746338,"mc":[{"id":"1.187552454","rc":[{"trd":[[3,9.63]],"batb":[[0,3,3.53]],"batl":[[0,3.7,3643.56]],"ltp":3.0,"tv":948.48,"id":9345630}],"tv":5290.35}]}
{"op":"mcm","clk":"4226210417","pt":1631447746657,"mc":[{"id":"1.187552454","rc":[{"batb":[[0,2.2,42.66],[1,2,11.86],[2,1.8,11.86]],"ltp":3.0,"tv":948.48,"id":9345630}]}]}
{"op":"mcm","clk":"4226210914","pt":1631447750426,"mc":[{"id":"1.187552454","rc":[{"batl":[[0,3.6,3]],"ltp":3.0,"tv":948.48,"id":9345630},{"batb":[[0,1.39,7]],"ltp":1.22,"tv":4341.86,"id":9028621}]}]}
{"op":"mcm","clk":"4226211768","pt":1631447757435,"mc":[{"id":"1.187552454","rc":[{"batb":[[0,2,11.86],[1,1.8,11.86],[2,1.7,16.95]],"ltp":3.0,"tv":948.48,"id":9345630}]}]}
{"op":"mcm","clk":"4226212410","pt":1631447762371,"mc":[{"id":"1.187552454","rc":[{"batb":[[0,2.24,1086.62],[1,2,11.86],[2,1.8,11.86]],"ltp":3.0,"tv":948.48,"id":9345630},{"batb":[[0,1.5,252.36],[1,1.49,289.53],[2,1.39,7]],"batl":[[0,1.54,340.08],[1,1.55,248.21],[2,1.72,483.76]],"ltp":1.22,"tv":4341.86,"id":9028621}]}]}
{"op":"mcm","clk":"4226212782","pt":1631447765464,"mc":[{"id":"1.187552454","rc":[{"batb":[[0,2.78,4],[1,2.76,4],[2,2.4,3]],"batl":[[0,3.55,3],[1,3.6,3]],"ltp":3.0,"tv":948.48,"id":9345630},{"batb":[[2,1.48,7]],"ltp":1.22,"tv":4341.86,"id":9028621}]}]}
{"op":"mcm","clk":"4226214221","pt":1631447776592,"mc":[{"id":"1.187552454","rc":[{"batl":[[0,3.5,6.62],[1,3.55,3],[2,3.6,3]],"ltp":3.0,"tv":948.48,"id":9345630},{"trd":[[1.5,416]],"batb":[[0,1.49,289.53],[1,1.48,7],[2,1.47,7]],"ltp":1.5,"tv":4741.86,"id":9028621}],"tv":5690.35}]}
{"op":"mcm","clk":"4226214354","pt":1631447777481,"mc":[{"id":"1.187552454","rc":[{"batb":[[1,2,11.86],[2,1.8,11.86]],"batl":[[0,3.55,3],[1,3.6,3],[2,3.6,0]],"ltp":3.0,"tv":948.48,"id":9345630},{"batb":[[0,1.48,7],[1,1.39,7],[2,1.06,494.32]],"batl":[[0,1.55,2.99],[1,1.72,483.76],[2,1.94,8.68]],"ltp":1.5,"tv":4741.86,"id":9028621}]}]}
{"op":"mcm","clk":"4226214411","pt":1631447777899,"mc":[{"id":"1.187552454","rc":[{"batb":[[0,2,11.86],[1,1.8,11.86],[2,1.7,16.95]],"ltp":3.0,"tv":948.48,"id":9345630},{"batb":[[0,1.06,494.32],[1,1.05,474.54],[2,1.03,494.32]],"ltp":1.5,"tv":4741.86,"id":9028621}]}]}
{"op":"mcm","clk":"4226214879","pt":1631447781086,"mc":[{"id":"1.187552454","rc":[{"batb":[[0,2.38,3],[1,2.36,3],[2,2,11.86]],"batl":[[0,18,2]],"ltp":3.0,"tv":948.48,"id":9345630},{"batb":[[0,1.06,497.32],[1,1.05,477.54]],"ltp":1.5,"tv":4741.86,"id":9028621}]}]}
{"op":"mcm","clk":"4226214978","pt":1631447781895,"mc":[{"id":"1.187552454","rc":[{"batb":[[0,1.41,397],[1,1.4,380.61],[2,1.06,497.32]],"batl":[[1,1.69,349.98],[2,1.71,348.3]],"ltp":1.5,"tv":4741.86,"id":9028621}]}]}
{"op":"mcm","clk":"4226215452","pt":1631447785236,"mc":[{"id":"1.187552454","rc":[{"batb":[[0,2.44,4],[1,2.42,3],[2,2.38,3]],"ltp":3.0,"tv":948.48,"id":9345630},{"batb":[[2,1.1,296.65]],"ltp":1.5,"tv":4741.86,"id":9028621}]}]}
{"op":"mcm","clk":"4226215910","pt":1631447788513,"mc":[{"id":"1.187552454","rc":[{"batb":[[2,1.17,314.09]],"ltp":1.5,"tv":4741.86,"id":9028621}]}]}
{"op":"mcm","clk":"4226216635","pt":1631447793213,"mc":[{"id":"1.187552454","rc":[{"batb":[[2,2,11.86]],"ltp":3.0,"tv":948.48,"id":9345630},{"trd":[[1.41,10.7]],"batb":[[0,1.41,391.65]],"ltp":1.41,"tv":4752.56,"id":9028621}],"tv":5701.05}]}
{"op":"mcm","clk":"4226218483","pt":1631447806582,"mc":[{"id":"1.187552454","rc":[{"batb":[[1,2,11.86],[2,1.8,11.86]],"ltp":3.0,"tv":948.48,"id":9345630},{"batl":[[0,1.45,4413.1],[1,1.55,2.99],[2,1.72,483.76]],"ltp":1.41,"tv":4752.56,"id":9028621}]}]}
{"op":"mcm","clk":"4226218594","pt":1631447807214,"mc":[{"id":"1.187552454","rc":[{"batl":[[0,1.55,2.99],[1,1.72,483.76],[2,1.94,8.68]],"ltp":1.41,"tv":4752.56,"id":9028621}]}]}
{"op":"mcm","clk":"4226218923","pt":1631447809547,"mc":[{"id":"1.187552454","rc":[{"batl":[[0,1.45,475.25],[1,1.46,310.13],[2,1.55,2.99]],"ltp":1.41,"tv":4752.56,"id":9028621}]}]}
{"op":"mcm","clk":"4226219052","pt":1631447810455,"mc":[{"id":"1.187552454","rc":[{"trd":[[3.45,6]],"batb":[[0,2.54,1084.66],[1,2.44,4],[2,2,11.86]],"ltp":3.45,"tv":954.48,"id":9345630},{"trd":[[1.41,53.38],[1.45,9.96]],"batb":[[0,1.41,362.97]],"batl":[[0,1.45,470.27]],"ltp":1.45,"tv":4805.2,"id":9028621}],"tv":5759.69}]}
{"op":"mcm","clk":"4226219277","pt":1631447812157,"mc":[{"id":"1.187552454","rc":[{"batb":[[0,3.15,3],[1,3.1,3],[2,2.54,1084.66]],"ltp":3.45,"tv":954.48,"id":9345630}]}]}
{"op":"mcm","clk":"4226219628","pt":1631447814563,"mc":[{"id":"1.187552454","rc":[{"trd":[[1.41,287.58]],"batb":[[0,1.41,245.87]],"ltp":1.41,"tv":5039.4,"id":9028621}],"tv":5993.89}]}
{"op":"mcm","clk":"4226219740","pt":1631447815356,"mc":[{"id":"1.187552454","rc":[{"batb":[[2,2.96,2.38]],"batl":[[0,4.2,2],[1,18,2]],"ltp":3.45,"tv":954.48,"id":9345630},{"batb":[[2,1.32,42.39]],"batl":[[0,1.45,470.96],[2,1.51,22.5]],"ltp":1.41,"tv":5039.4,"id":9028621}]}]}
{"op":"mcm","clk":"4226219868","pt":1631447816368,"mc":[{"id":"1.187552454","rc":[{"batb":[[2,2.54,1084.66]],"batl":[[1,6.4,3.76],[2,18,2]],"ltp":3.45,"tv":954.48,"id":9345630},{"batb":[[2,1.17,314.09]],"batl":[[0,1.45,470.27]],"ltp":1.41,"tv":5039.4,"id":9028621}]}]}
{"op":"mcm","clk":"4226219923","pt":1631447816788,"mc":[{"id":"1.187552454","rc":[{"batl":[[0,1.45,470.96]],"ltp":1.41,"tv":5039.4,"id":9028621}]}]}
{"op":"mcm","clk":"4226220061","pt":1631447817845,"mc":[{"id":"1.187552454","rc":[{"trd":[[1.41,288.96]],"batb":[[0,1.41,334.47]],"batl":[[0,1.45,533.26]],"ltp":1.41,"tv":5040.78,"id":9028621}],"tv":5995.27}]}
{"op":"mcm","clk":"4226220279","pt":1631447819549,"mc":[{"id":"1.187552454","rc":[{"batb":[[2,2.46,3]],"batl":[[0,4.1,2],[1,4.2,2],[2,6.4,3.76]],"ltp":3.45,"tv":954.48,"id":9345630},{"trd":[[1.41,338.06]],"batb":[[0,1.41,309.92],[2,1.33,38.53]],"batl":[[0,1.45,532.57]],"ltp":1.41,"tv":5089.88,"id":9028621}],"tv":6044.37}]}
{"op":"mcm","clk":"4226220329","pt":1631447819961,"mc":[{"id":"1.187552454","rc":[{"batb":[[2,1.17,314.09]],"batl":[[0,1.45,321.98],[1,1.51,22.5],[2,1.55,25.49]],"ltp":1.41,"tv":5089.88,"id":9028621}]}]}
{"op":"mcm","clk":"4226220711","pt":1631447822578,"mc":[{"id":"1.187552454","rc":[{"batb":[[2,2.96,2.38]],"batl":[[2,18,2]],"ltp":3.45,"tv":954.48,"id":9345630},{"batb":[[2,1.32,40.89]],"ltp":1.41,"tv":5089.88,"id":9028621}]}]}
{"op":"mcm","clk":"4226220740","pt":1631447822746,"mc":[{"id":"1.187552454","rc":[{"batb":[[2,2.46,3]],"ltp":3.45,"tv":954.48,"id":9345630},{"batb":[[2,1.17,314.09]],"batl":[[0,1.44,222.69],[1,1.45,321.98],[2,1.51,22.5]],"ltp":1.41,"tv":5089.88,"id":9028621}]}]}
{"op":"mcm","clk":"4226220968","pt":1631447824554,"mc":[{"id":"1.187552454","rc":[{"batb":[[0,1.41,310.61]],"ltp":1.41,"tv":5089.88,"id":9028621}]}]}
{"op":"mcm","clk":"4226221116","pt":1631447825575,"mc":[{"id":"1.187552454","rc":[{"batb":[[1,2,11.86],[2,1.8,11.86]],"batl":[[0,4,11.9],[1,4.1,2],[2,4.2,2]],"ltp":3.45,"tv":954.48,"id":9345630}]}]}
{"op":"mcm","clk":"4226221244","pt":1631447826430,"mc":[{"id":"1.187552454","rc":[{"batb":[[2,1.33,38.53]],"batl":[[0,1.44,225.25]],"ltp":1.41,"tv":5089.88,"id":9028621}]}]}
{"op":"mcm","clk":"4226221291","pt":1631447826691,"mc":[{"id":"1.187552454","rc":[{"batb":[[2,1.17,314.09]],"ltp":1.41,"tv":5089.88,"id":9028621}]}]}
{"op":"mcm","clk":"4226221574","pt":1631447828792,"mc":[{"id":"1.187552454","rc":[{"batb":[[1,3.1,3],[2,2,11.86]],"ltp":3.45,"tv":954.48,"id":9345630}]}]}
{"op":"mcm","clk":"4226221996","pt":1631447832015,"mc":[{"id":"1.187552454","rc":[{"trd":[[1.44,30]],"batl":[[0,1.44,210.25]],"ltp":1.44,"tv":5119.88,"id":9028621}],"tv":6074.37}]}
{"op":"mcm","clk":"4226222248","pt":1631447833529,"mc":[{"id":"1.187552454","rc":[{"batb":[[2,1.33,36.53]],"batl":[[0,1.44,2.56]],"ltp":1.44,"tv":5119.88,"id":9028621}]}]}
{"op":"mcm","clk":"4226222296","pt":1631447833821,"mc":[{"id":"1.187552454","rc":[{"batb":[[2,1.17,314.09]],"ltp":1.44,"tv":5119.88,"id":9028621}]}]}
{"op":"mcm","clk":"4226222598","pt":1631447835907,"mc":[{"id":"1.187552454","rc":[{"batb":[[2,1.18,38.27]],"batl":[[1,1.45,536.92],[2,1.46,310.16]],"ltp":1.44,"tv":5119.88,"id":9028621}]}]}
{"op":"mcm","clk":"4226223123","pt":1631447839513,"mc":[{"id":"1.187552454","rc":[{"batb":[[0,2,11.86],[1,1.8,11.86],[2,1.7,16.95]],"batl":[[0,4.1,2],[1,18,2],[2,4.2,0]],"ltp":3.45,"tv":954.48,"id":9345630},{"batb":[[0,1.18,38.96],[1,1.17,314.09],[2,1.1,296.65]],"batl":[[1,1.55,22.5],[2,1.72,483.76]],"ltp":1.44,"tv":5119.88,"id":9028621}]}]}
{"op":"mcm","clk":"4226223241","pt":1631447840316,"mc":[{"id":"1.187552454","rc":[{"batb":[[0,2.96,2.38],[1,2.8,2.13],[2,2,11.86]],"ltp":3.45,"tv":954.48,"id":9345630}]}]}
{"op":"mcm","clk":"4226223297","pt":1631447840727,"mc":[{"id":"1.187552454","rc":[{"batb":[[0,2.8,2.13],[1,2,11.86],[2,1.8,11.86]],"ltp":3.45,"tv":954.48,"id":9345630},{"batb":[[0,1.33,41.22],[1,1.18,38.27],[2,1.17,314.09]],"ltp":1.44,"tv":5119.88,"id":9028621}]}]}
{"op":"mcm","clk":"4226223474","pt":1631447842127,"mc":[{"id":"1.187552454","rc":[{"batb":[[0,1.35,556.68],[1,1.34,471.83],[2,1.33,40.53]],"batl":[[1,1.54,279.07],[2,1.55,269]],"ltp":1.44,"tv":5119.88,"id":9028621}]}]}
{"op":"mcm","clk":"4226224088","pt":1631447846448,"mc":[{"id":"1.187552454","rc":[{"batl":[[1,1.51,22.5],[2,1.54,279.07]],"ltp":1.44,"tv":5119.88,"id":9028621}]}]}
{"op":"mcm","clk":"4226224237","pt":1631447847537,"mc":[{"id":"1.187552454","rc":[{"batb":[[0,2.96,2.38],[1,2.8,2.13],[2,2,11.86]],"ltp":3.45,"tv":954.48,"id":9345630},{"batl":[[1,1.54,279.07],[2,1.55,269]],"ltp":1.44,"tv":5119.88,"id":9028621}]}]}
{"op":"mcm","clk":"4226224309","pt":1631447847953,"mc":[{"id":"1.187552454","rc":[{"batb":[[0,2.8,2.13],[1,2,11.86],[2,1.8,11.86]],"ltp":3.45,"tv":954.48,"id":9345630}]}]}
{"op":"mcm","clk":"4226225026","pt":1631447853587,"mc":[{"id":"1.187552454","rc":[{"batl":[[1,1.51,23.01],[2,1.54,279.07]],"ltp":1.44,"tv":5119.88,"id":9028621}]}]}
{"op":"mcm","clk":"4226225057","pt":1631447853787,"mc":[{"id":"1.187552454","rc":[{"batl":[[1,1.54,279.07],[2,1.55,269]],"ltp":1.44,"tv":5119.88,"id":9028621}]}]}
{"op":"mcm","clk":"4226225992","pt":1631447860458,"mc":[{"id":"1.187552454","rc":[{"batl":[[1,1.51,25.5],[2,1.54,279.07]],"ltp":1.44,"tv":5119.88,"id":9028621}]}]}
{"op":"mcm","clk":"4226226043","pt":1631447860879,"mc":[{"id":"1.187552454","rc":[{"trd":[[1.35,0.82],[1.41,339.43]],"batb":[[0,1.35,555.58]],"batl":[[1,1.54,279.07],[2,1.55,269]],"ltp":1.35,"tv":5122.08,"id":9028621}],"tv":6076.57}]}
{"op":"mcm","clk":"4226226581","pt":1631447865300,"mc":[{"id":"1.187552454","rc":[{"batb":[[0,2.96,2.38],[1,2.8,2.13],[2,2,11.86]],"ltp":3.45,"tv":954.48,"id":9345630}]}]}
{"op":"mcm","clk":"4226226678","pt":1631447866118,"mc":[{"id":"1.187552454","rc":[{"batb":[[0,2.8,2.13],[1,2,11.86],[2,1.8,11.86]],"ltp":3.45,"tv":954.48,"id":9345630},{"batb":[[0,1.33,40.53],[1,1.18,38.27],[2,1.17,314.09]],"ltp":1.35,"tv":5122.08,"id":9028621}]}]}
{"op":"mcm","clk":"4226226841","pt":1631447867373,"mc":[{"id":"1.187552454","rc":[{"trd":[[3.25,1.14]],"ltp":3.25,"tv":955.62,"id":9345630},{"trd":[[1.44,32.56]],"batl":[[0,1.51,23.01]],"ltp":1.44,"tv":5124.64,"id":9028621}],"tv":6080.27}]}
{"op":"mcm","clk":"4226226884","pt":1631447867701,"mc":[{"id":"1.187552454","rc":[{"batl":[[0,1.54,279.07],[1,1.55,269],[2,1.94,8.68]],"ltp":1.44,"tv":5124.64,"id":9028621}]}]}
{"op":"mcm","clk":"4226227119","pt":1631447869400,"mc":[{"id":"1.187552454","rc":[{"batb":[[0,2.84,4],[1,2.82,3],[2,2.8,2.13]],"batl":[[0,3.55,3],[1,4.1,2],[2,18,2]],"ltp":3.25,"tv":955.62,"id":9345630},{"batb":[[0,1.5,320.43],[1,1.49,291.02],[2,1.4,7]],"ltp":1.44,"tv":5124.64,"id":9028621}]}]}
{"op":"mcm","clk":"4226227212","pt":1631447870195,"mc":[{"id":"1.187552454","rc":[{"batb":[[0,2.8,2.13],[1,2,11.86],[2,1.8,11.86]],"batl":[[1,4,3],[2,4.1,2]],"ltp":3.25,"tv":955.62,"id":9345630}]}]}
{"op":"mcm","clk":"4226227770","pt":1631447874303,"mc":[{"id":"1.187552454","rc":[{"trd":[[1.5,579.86]],"batb":[[0,1.5,238.5]],"ltp":1.5,"tv":5288.5,"id":9028621}],"tv":6244.13}]}
{"op":"mcm","clk":"4226227916","pt":1631447875418,"mc":[{"id":"1.187552454","rc":[{"batb":[[1,2.44,2.92],[2,2.28,3.41]],"batl":[[0,3.45,2.04],[1,3.55,3],[2,3.8,2]],"ltp":3.25,"tv":955.62,"id":9345630},{"batb":[[2,1.41,32.89]],"batl":[[2,1.69,19.5]],"ltp":1.5,"tv":5288.5,"id":9028621}]}]}
{"op":"mcm","clk":"4226228183","pt":1631447877492,"mc":[{"id":"1.187552454","rc":[{"batb":[[0,1.5,284.99]],"batl":[[0,1.54,313.77]],"ltp":1.5,"tv":5288.5,"id":9028621}]}]}
{"op":"mcm","clk":"4226229859","pt":1631447890216,"mc":[{"id":"1.187552454","rc":[{"trd":[[2.84,53.58]],"ltp":2.84,"tv":983.43,"id":9345630},{"trd":[[1.54,78.53]],"batl":[[0,1.54,262.48]],"ltp":1.54,"tv":5339.79,"id":9028621}],"tv":6323.23}]}
{"op":"mcm","clk":"4226230294","pt":1631447893502,"mc":[{"id":"1.187552454","rc":[{"batb":[[0,2.8,5.13],[1,2.78,3],[2,2.44,2.92]],"ltp":2.84,"tv":983.43,"id":9345630}]}]}
{"op":"mcm","clk":"4226230705","pt":1631447896320,"mc":[{"id":"1.187552454","rc":[{"batb":[[0,2.28,3.41],[1,2,11.86],[2,1.8,11.86]],"batl":[[0,3.8,2],[1,4,3],[2,3.8,0]],"ltp":2.84,"tv":983.43,"id":9345630},{"batb":[[0,1.36,34.43],[1,1.34,8],[2,1.25,237.31]],"batl":[[0,1.77,17.5],[1,1.94,8.68],[2,2,783.31]],"ltp":1.54,"tv":5339.79,"id":9028621}]}]}
{"op":"mcm","clk":"4226230875","pt":1631447897646,"mc":[{"id":"1.187552454","rc":[{"batb":[[0,1.54,50],[1,1.36,34.43],[2,1.34,8]],"ltp":1.54,"tv":5339.79,"id":9028621}]}]}
{"op":"mcm","clk":"4226231144","pt":1631447899508,"mc":[{"id":"1.187552454","rc":[{"batb":[[0,2.44,3],[1,2.42,4],[2,2.28,6.41]],"ltp":2.84,"tv":983.43,"id":9345630},{"batb":[[1,1.41,558.72],[2,1.4,382.98]],"batl":[[0,1.69,249.46],[1,1.7,5],[2,1.71,349.41]],"ltp":1.54,"tv":5339.79,"id":9028621}]}]}
{"op":"mcm","clk":"4226231172","pt":1631447899723,"mc":[{"id":"1.187552454","rc":[{"batb":[[0,2.44,6.42]],"batl":[[0,3.45,2.1],[1,3.8,2],[2,4,3]],"ltp":2.84,"tv":983.43,"id":9345630},{"batb":[[1,1.41,589.61]],"batl":[[0,1.69,270.96]],"ltp":1.54,"tv":5339.79,"id":9028621}]}]}
{"op":"mcm","clk":"4226231729","pt":1631447904355,"mc":[{"id":"1.187552454","rc":[{"batb":[[0,2.44,3]],"batl":[[2,4,0]],"ltp":2.84,"tv":983.43,"id":9345630},{"batl":[[0,1.69,5],[2,1.77,4]],"ltp":1.54,"tv":5339.79,"id":9028621}]}]}
{"op":"mcm","clk":"4226231921","pt":1631447906055,"mc":[{"id":"1.187552454","rc":[{"trd":[[1.54,178.53]],"batb":[[0,1.41,589.61],[1,1.4,382.98],[2,1.36,34.43]],"ltp":1.54,"tv":5439.79,"id":9028621}],"tv":6423.23}]}
{"op":"mcm","clk":"4226232073","pt":1631447907538,"mc":[{"id":"1.187552454","rc":[{"trd":[[3.45,14.1]],"batb":[[0,2.52,1093.34],[1,2.44,3],[2,2.42,4]],"batl":[[0,3.8,2],[1,3.8,0]],"ltp":3.45,"tv":991.53,"id":9345630},{"trd":[[1.41,376.97]],"batb":[[0,1.41,566.07]],"batl":[[0,1.45,324.29],[1,1.46,312.06],[2,1.69,5]],"ltp":1.41,"tv":5477.33,"id":9028621}],"tv":6468.87}]}
{"op":"mcm","clk":"4226232169","pt":1631447908328,"mc":[{"id":"1.187552454","rc":[{"batl":[[2,1.49,144.6]],"ltp":1.41,"tv":5477.33,"id":9028621}]}]}
{"op":"mcm","clk":"4226232307","pt":1631447909341,"mc":[{"id":"1.187552454","rc":[{"batb":[[0,3.15,3],[1,3.1,3],[2,2.86,3]],"ltp":3.45,"tv":991.53,"id":9345630},{"batl":[[2,1.68,4]],"ltp":1.41,"tv":5477.33,"id":9028621}]}]}
{"op":"mcm","clk":"4226232575","pt":1631447911574,"mc":[{"id":"1.187552454","rc":[{"trd":[[1.41,482.17]],"batb":[[0,1.41,513.47]],"ltp":1.41,"tv":5582.53,"id":9028621}],"tv":6574.07}]}
{"op":"mcm","clk":"4226232840","pt":1631447913774,"mc":[{"id":"1.187552454","rc":[{"batb":[[2,2.88,2.46]],"batl":[[1,4.2,2]],"ltp":3.45,"tv":991.53,"id":9345630},{"batl":[[2,1.53,22.5]],"ltp":1.41,"tv":5582.53,"id":9028621}]}]}
{"op":"mcm","clk":"4226232963","pt":1631447914832,"mc":[{"id":"1.187552454","rc":[{"batb":[[0,1.41,557.57]],"ltp":1.41,"tv":5582.53,"id":9028621}]}]}
{"op":"mcm","clk":"4226233953","pt":1631447923365,"mc":[{"id":"1.187552454","rc":[{"batb":[[1,2.88,2.46],[2,2.72,2.59]],"ltp":3.45,"tv":991.53,"id":9345630},{"batl":[[0,1.43,1.71],[1,1.45,324.29],[2,1.46,312.06]],"ltp":1.41,"tv":5582.53,"id":9028621}]}]}
{"op":"mcm","clk":"4226234285","pt":1631447926589,"mc":[{"id":"1.187552454","rc":[{"batb":[[1,3.1,2],[2,2.88,2.46]],"ltp":3.45,"tv":991.53,"id":9345630}]}]}
{"op":"mcm","clk":"4226234335","pt":1631447926977,"mc":[{"id":"1.187552454","rc":[{"batb":[[2,2.92,2.19]],"batl":[[1,4.1,2],[2,4.2,2]],"ltp":3.45,"tv":991.53,"id":9345630}]}]}
{"op":"mcm","clk":"4226234893","pt":1631447932298,"mc":[{"id":"1.187552454","rc":[{"batb":[[0,2.74,2.52],[1,2,11.86],[2,1.8,11.86]],"batl":[[0,4.1,2],[1,4.1,0],[2,4.2,0]],"ltp":3.45,"tv":991.53,"id":9345630},{"batb":[[0,1.2,385.63],[1,1.17,314.09],[2,1.1,296.65]],"batl":[[1,1.68,4],[2,1.85,884.12]],"ltp":1.41,"tv":5582.53,"id":9028621}]}]}
{"op":"mcm","clk":"4226235294","pt":1631447935477,"mc":[{"id":"1.187552454","rc":[{"batb":[[0,2.74,5.52],[1,2.72,3],[2,2,11.86]],"ltp":3.45,"tv":991.53,"id":9345630},{"batb":[[0,1.36,295.17],[1,1.35,451.95],[2,1.2,385.63]],"batl":[[1,1.55,360.74],[2,1.56,240.39]],"ltp":1.41,"tv":5582.53,"id":9028621}]}]}
{"op":"mcm","clk":"4226235358","pt":1631447936007,"mc":[{"id":"1.187552454","rc":[{"batl":[[0,3.8,2],[1,4.1,2]],"ltp":3.45,"tv":991.53,"id":9345630},{"batb":[[0,1.36,331.1],[2,1.33,38.53]],"ltp":1.41,"tv":5582.53,"id":9028621}]}]}
{"op":"mcm","clk":"4226235474","pt":1631447937193,"mc":[{"id":"1.187552454","rc":[{"batl":[[0,4.1,2],[1,4.1,0]],"ltp":3.45,"tv":991.53,"id":9345630},{"batb":[[0,1.33,38.53],[1,1.2,385.63],[2,1.17,314.09]],"batl":[[1,1.57,21.5],[2,1.68,4]],"ltp":1.41,"tv":5582.53,"id":9028621}]}]}
{"op":"mcm","clk":"4226235599","pt":1631447938410,"mc":[{"id":"1.187552454","rc":[{"batb":[[0,3.25,20.89],[1,2.74,5.52],[2,2.72,3]],"batl":[[0,3.45,18.7],[1,4.1,2]],"ltp":3.45,"tv":991.53,"id":9345630},{"batl":[[1,1.44,22.33],[2,1.57,21.5]],"ltp":1.41,"tv":5582.53,"id":9028621}]}]}
{"op":"mcm","clk":"4226235728","pt":1631447939571,"mc":[{"id":"1.187552454","rc":[{"batb":[[0,2.8,3],[1,2.78,4],[2,2.74,5.52]],"batl":[[0,4.1,2],[1,4.1,0]],"ltp":3.45,"tv":991.53,"id":9345630},{"batl":[[1,1.57,21.5],[2,1.68,4]],"ltp":1.41,"tv":5582.53,"id":9028621}]}]}
{"op":"mcm","clk":"4226235993","pt":1631447941719,"mc":[{"id":"1.187552454","rc":[{"trd":[[1.43,3.42]],"batb":[[0,1.43,415.3],[1,1.42,358.31],[2,1.33,38.53]],"batl":[[0,1.47,387.79],[1,1.48,294.91],[2,1.57,21.5]],"ltp":1.43,"tv":5585.95,"id":9028621}],"tv":6577.49}]}
{"op":"mcm","clk":"4226236159","pt":1631447942792,"mc":[{"id":"1.187552454","rc":[{"batb":[[0,2.92,2.44],[1,2.8,3],[2,2.78,4]],"ltp":3.45,"tv":991.53,"id":9345630},{"batl":[[2,1.52,25.01]],"ltp":1.43,"tv":5585.95,"id":9028621}]}]}
{"op":"mcm","clk":"4226236338","pt":1631447944014,"mc":[{"id":"1.187552454","rc":[{"batl":[[0,3.8,2.02],[1,4.1,2]],"ltp":3.45,"tv":991.53,"id":9345630},{"batb":[[2,1.36,37.18]],"ltp":1.43,"tv":5585.95,"id":9028621}]}]}
{"op":"mcm","clk":"4226236620","pt":1631447946180,"mc":[{"id":"1.187552454","rc":[{"batb":[[0,2.8,3],[1,2.78,4],[2,2.74,5.52]],"batl":[[0,4.1,2],[1,4.1,0]],"ltp":3.45,"tv":991.53,"id":9345630},{"batb":[[0,1.33,38.53],[1,1.2,385.63],[2,1.17,314.09]],"batl":[[0,1.57,21.5],[1,1.68,4],[2,1.85,884.12]],"ltp":1.43,"tv":5585.95,"id":9028621}]}]}
{"op":"mcm","clk":"4226236989","pt":1631447949497,"mc":[{"id":"1.187552454","rc":[{"batb":[[0,2.92,2.44],[1,2.8,3],[2,2.78,4]],"batl":[[0,3.8,2],[1,4.1,2]],"ltp":3.45,"tv":991.53,"id":9345630},{"batb":[[0,1.36,330.84],[1,1.35,451.95],[2,1.33,38.53]],"batl":[[0,1.52,24.76],[1,1.55,361.41],[2,1.56,245.39]],"ltp":1.43,"tv":5585.95,"id":9028621}]}]}
{"op":"mcm","clk":"4226237029","pt":1631447949822,"mc":[{"id":"1.187552454","rc":[{"batb":[[0,2.8,3],[1,2.78,4],[2,2.74,2.52]],"ltp":3.45,"tv":991.53,"id":9345630},{"batl":[[0,1.55,361.41],[1,1.56,245.39],[2,1.57,21.5]],"ltp":1.43,"tv":5585.95,"id":9028621}]}]}
{"op":"mcm","clk":"4226237452","pt":1631447953565,"mc":[{"id":"1.187552454","rc":[{"batb":[[1,2.74,2.52],[2,2,11.86]],"ltp":3.45,"tv":991.53,"id":9345630}]}]}
{"op":"mcm","clk":"4226237568","pt":1631447954526,"mc":[{"id":"1.187552454","rc":[{"batl":[[0,4.1,2],[1,4.1,0]],"ltp":3.45,"tv":991.53,"id":9345630},{"batb":[[0,1.33,38.53],[1,1.2,385.63],[2,1.17,314.09]],"ltp":1.43,"tv":5585.95,"id":9028621}]}]}
{"op":"mcm","clk":"4226238001","pt":1631447957508,"mc":[{"id":"1.187552454","rc":[{"batb":[[0,2.74,2.52],[1,2,11.86],[2,1.8,11.86]],"batl":[[0,3.55,6],[1,4.1,2]],"ltp":3.45,"tv":991.53,"id":9345630},{"batb":[[0,1.51,210.52],[1,1.5,320.18],[2,1.39,14]],"batl":[[0,1.55,368.41],[1,1.56,240.39]],"ltp":1.43,"tv":5585.95,"id":9028621}]}]}
{"op":"mcm","clk":"4226238030","pt":1631447957719,"mc":[{"id":"1.187552454","rc":[{"batl":[[0,3.55,3]],"ltp":3.45,"tv":991.53,"id":9345630},{"batb":[[2,1.39,7]],"batl":[[0,1.55,361.41]],"ltp":1.43,"tv":5585.95,"id":9028621}]}]}
{"op":"mcm","clk":"4226238236","pt":1631447959415,"mc":[{"id":"1.187552454","rc":[{"batb":[[0,2.82,15],[1,2.74,2.52],[2,2,11.86]],"batl":[[0,3.45,10],[1,3.55,3],[2,4.1,2]],"ltp":3.45,"tv":991.53,"id":9345630},{"batb":[[2,1.41,159.07]],"batl":[[0,1.55,400.57]],"ltp":1.43,"tv":5585.95,"id":9028621}]}]}
{"op":"mcm","clk":"4226238347","pt":1631447960415,"mc":[{"id":"1.187552454","rc":[{"batb":[[0,2.74,2.52],[1,2,11.86],[2,1.8,11.86]],"batl":[[2,4,2]],"ltp":3.45,"tv":991.53,"id":9345630}]}]}
{"op":"mcm","clk":"4226238587","pt":1631447962271,"mc":[{"id":"1.187552454","rc":[{"batl":[[0,3.55,3],[1,4,2],[2,4.1,2]],"ltp":3.45,"tv":991.53,"id":9345630},{"trd":[[1.51,74.56]],"batb":[[0,1.51,173.24]],"ltp":1.51,"tv":5660.51,"id":9028621}],"tv":6652.05}]}
{"op":"mcm","clk":"4226238770","pt":1631447963588,"mc":[{"id":"1.187552454","rc":[{"batb":[[0,2.76,15],[1,2.74,2.52],[2,2,11.86]],"ltp":3.45,"tv":991.53,"id":9345630},{"batb":[[0,1.5,320.18],[1,1.41,159.07],[2,1.39,7]],"ltp":1.51,"tv":5660.51,"id":9028621}]}]}
{"op":"mcm","clk":"4226239011","pt":1631447965431,"mc":[{"id":"1.187552454","rc":[{"batb":[[2,2.42,3.13]],"batl":[[0,3.4,50],[1,3.45,2.04],[2,3.55,3]],"ltp":3.45,"tv":991.53,"id":9345630},{"batb":[[1,1.41,190.96]],"ltp":1.51,"tv":5660.51,"id":9028621}]}]}
{"op":"mcm","clk":"4226239090","pt":1631447965999,"mc":[{"id":"1.187552454","rc":[{"batl":[[0,3.45,2.04],[1,3.55,3],[2,3.9,2]],"ltp":3.45,"tv":991.53,"id":9345630},{"batb":[[0,1.5,515.64],[1,1.49,292.42],[2,1.41,190.96]],"ltp":1.51,"tv":5660.51,"id":9028621}]}]}
{"op":"mcm","clk":"4226239230","pt":1631447967108,"mc":[{"id":"1.187552454","rc":[{"batl":[[0,3.45,10.83]],"ltp":3.45,"tv":991.53,"id":9345630}]}]}
{"op":"mcm","clk":"4226239502","pt":1631447969436,"mc":[{"id":"1.187552454","rc":[{"batb":[[0,1.5,478.28]],"ltp":1.51,"tv":5660.51,"id":9028621}]}]}
{"op":"mcm","clk":"4226239591","pt":1631447970377,"mc":[{"id":"1.187552454","rc":[{"trd":[[2.8,13.27]],"ltp":2.8,"tv":995.81,"id":9345630},{"trd":[[1.55,48.08]],"batl":[[0,1.55,392.86]],"ltp":1.55,"tv":5668.22,"id":9028621}],"tv":6664.03}]}
{"op":"mcm","clk":"4226239842","pt":1631447972441,"mc":[{"id":"1.187552454","rc":[{"batb":[[0,2.76,18],[1,2.74,5.52]],"ltp":2.8,"tv":995.81,"id":9345630}]}]}
{"op":"mcm","clk":"4226239901","pt":1631447972929,"mc":[{"id":"1.187552454","rc":[{"batb":[[0,2.76,3]],"ltp":2.8,"tv":995.81,"id":9345630}]}]}
{"op":"mcm","clk":"4226240322","pt":1631447976458,"mc":[{"id":"1.187552454","rc":[{"batb":[[0,2.42,3.13],[1,2.28,3.16],[2,2,11.86]],"batl":[[0,3.45,2.04]],"ltp":2.8,"tv":995.81,"id":9345630},{"batb":[[0,1.41,31.89],[1,1.39,7],[2,1.35,39.87]],"batl":[[0,1.68,4],[1,1.7,17.85],[2,1.78,16.25]],"ltp":1.55,"tv":5668.22,"id":9028621}]}]}
{"op":"mcm","clk":"4226240354","pt":1631447976726,"mc":[{"id":"1.187552454","rc":[{"batb":[[0,2.28,3.16],[1,2,11.86],[2,1.8,11.86]],"batl":[[0,3.9,2],[1,4,2],[2,3.9,0]],"ltp":2.8,"tv":995.81,"id":9345630},{"batb":[[0,1.35,39.87],[1,1.34,9],[2,1.25,237.31]],"batl":[[1,1.78,16.25],[2,1.85,884.12]],"ltp":1.55,"tv":5668.22,"id":9028621}]}]}
{"op":"mcm","clk":"4226240680","pt":1631447979458,"mc":[{"id":"1.187552454","rc":[{"batb":[[0,1.42,369.44],[1,1.41,369.47],[2,1.35,39.87]],"batl":[[1,1.7,298.42],[2,1.72,342.64]],"ltp":1.55,"tv":5668.22,"id":9028621}]}]}
{"op":"mcm","clk":"4226240754","pt":1631447979936,"mc":[{"id":"1.187552454","rc":[{"batb":[[0,2.46,3],[1,2.44,3],[2,2.42,3.44]],"batl":[[0,3.45,2],[1,3.6,3],[2,3.9,5]],"ltp":2.8,"tv":995.81,"id":9345630},{"batb":[[1,1.41,401.36],[2,1.4,4]],"batl":[[1,1.7,315.87]],"ltp":1.55,"tv":5668.22,"id":9028621}]}]}
{"op":"mcm","clk":"4226242788","pt":1631447996350,"mc":[{"id":"1.187552454","rc":[{"batb":[[0,1.41,31.89],[1,1.4,4],[2,1.39,3]],"ltp":1.55,"tv":5668.22,"id":9028621}]}]}
{"op":"mcm","clk":"4226242906","pt":1631447997354,"mc":[{"id":"1.187552454","rc":[{"batb":[[1,2.42,3.44],[2,2.28,3.16]],"batl":[[0,3.6,3],[1,3.9,2],[2,3.9,0]],"ltp":2.8,"tv":995.81,"id":9345630},{"batb":[[0,1.4,4],[1,1.35,39.87],[2,1.25,237.31]],"ltp":1.55,"tv":5668.22,"id":9028621}]}]}
{"op":"mcm","clk":"4226243167","pt":1631447999548,"mc":[{"id":"1.187552454","rc":[{"batb":[[0,2.42,3.44],[1,2.28,3.16],[2,1.7,16.95]],"batl":[[0,2.72,8],[1,3.6,3],[2,3.9,2]],"ltp":2.8,"tv":995.81,"id":9345630},{"batb":[[0,1.65,207.24],[1,1.64,201.41],[2,1.56,12]],"batl":[[0,1.7,315.87],[1,1.72,342.64],[2,1.78,16.25]],"ltp":1.55,"tv":5668.22,"id":9028621}]}]}
{"op":"mcm","clk":"4226243322","pt":1631448000535,"mc":[{"id":"1.187552454","rc":[{"batl":[[0,2.72,4],[1,2.88,15],[2,3.6,3]],"ltp":2.8,"tv":995.81,"id":9345630},{"batb":[[2,1.56,6]],"ltp":1.55,"tv":5668.22,"id":9028621}]}]}
{"op":"mcm","clk":"4226243443","pt":1631448001345,"mc":[{"id":"1.187552454","rc":[{"batl":[[1,3.6,3],[2,3.9,2]],"ltp":2.8,"tv":995.81,"id":9345630}]}]}
{"op":"mcm","clk":"4226243659","pt":1631448002589,"mc":[{"id":"1.187552454","rc":[{"batb":[[0,2.38,3],[1,2.36,2],[2,2.28,3.16]],"batl":[[1,3.55,3],[2,3.6,3]],"ltp":2.8,"tv":995.81,"id":9345630},{"batl":[[0,1.7,298.42]],"ltp":1.55,"tv":5668.22,"id":9028621}]}]}
{"op":"mcm","clk":"4226243794","pt":1631448003464,"mc":[{"id":"1.187552454","rc":[{"trd":[[1.65,63.36]],"batb":[[0,1.65,180.56]],"batl":[[0,1.7,327.56]],"ltp":1.65,"tv":5721.58,"id":9028621}],"tv":6717.39}]}
{"op":"mcm","clk":"4226243992","pt":1631448004552,"mc":[{"id":"1.187552454","rc":[{"batl":[[0,2.7,20],[1,2.72,4],[2,3.55,3]],"ltp":2.8,"tv":995.81,"id":9345630},{"batb":[[0,1.66,10.44],[1,1.65,180.56],[2,1.64,201.41]],"ltp":1.65,"tv":5721.58,"id":9028621}]}]}
{"op":"mcm","clk":"4226244240","pt":1631448006137,"mc":[{"id":"1.187552454","rc":[{"batb":[[0,2.4,17.2],[1,2.38,3],[2,2.36,2]],"ltp":2.8,"tv":995.81,"id":9345630}]}]}
{"op":"mcm","clk":"4226244672","pt":1631448008755,"mc":[{"id":"1.187552454","rc":[{"batb":[[0,1.66,230.31]],"ltp":1.65,"tv":5721.58,"id":9028621}]}]}
{"op":"mcm","clk":"4226246164","pt":1631448018558,"mc":[{"id":"1.187552454","rc":[{"batl":[[0,2.7,31.62]],"ltp":2.8,"tv":995.81,"id":9345630},{"trd":[[1.66,31.49]],"batb":[[0,1.66,222.58]],"ltp":1.66,"tv":5737.05,"id":9028621}],"tv":6732.86}]}
{"op":"mcm","clk":"4226246203","pt":1631448018767,"mc":[{"id":"1.187552454","rc":[{"batb":[[2,2.28,3.16]],"batl":[[0,2.7,11.62]],"ltp":2.8,"tv":995.81,"id":9345630}]}]}
{"op":"mcm","clk":"4226246651","pt":1631448022001,"mc":[{"id":"1.187552454","rc":[{"batb":[[2,2.36,4]],"batl":[[0,2.68,41.58],[1,2.7,11.62],[2,2.72,4]],"ltp":2.8,"tv":995.81,"id":9345630}]}]}
{"op":"mcm","clk":"4226247130","pt":1631448025471,"mc":[{"id":"1.187552454","rc":[{"trd":[[2.42,113.08]],"ltp":2.42,"tv":1096.89,"id":9345630},{"trd":[[1.7,401.89]],"batl":[[0,1.7,183.67]],"ltp":1.7,"tv":5880.94,"id":9028621}],"tv":6977.83}]}
{"op":"mcm","clk":"4226247573","pt":1631448028521,"mc":[{"id":"1.187552454","rc":[{"batb":[[1,1.65,258.44]],"batl":[[0,1.7,277.91]],"ltp":1.7,"tv":5880.94,"id":9028621}]}]}
{"op":"mcm","clk":"4226249987","pt":1631448044586,"mc":[{"id":"1.187552454","rc":[{"batb":[[2,2.28,3.16]],"batl":[[1,2.72,4],[2,3.55,3]],"ltp":2.42,"tv":1096.89,"id":9345630},{"batb":[[0,1.66,219.88]],"ltp":1.7,"tv":5880.94,"id":9028621}]}]}
{"op":"mcm","clk":"4226250008","pt":1631448044792,"mc":[{"id":"1.187552454","rc":[{"batl":[[0,2.72,4],[1,3.55,3],[2,3.9,2]],"ltp":2.42,"tv":1096.89,"id":9345630}]}]}
{"op":"mcm","clk":"4226250315","pt":1631448047597,"mc":[{"id":"1.187552454","rc":[{"batb":[[2,2.36,3]],"ltp":2.42,"tv":1096.89,"id":9345630},{"batl":[[0,1.69,7.6],[1,1.7,277.91],[2,1.72,342.64]],"ltp":1.7,"tv":5880.94,"id":9028621}]}]}
{"op":"mcm","clk":"4226250412","pt":1631448048404,"mc":[{"id":"1.187552454","rc":[{"batl":[[0,2.7,11.62],[1,2.72,4],[2,3.55,3]],"ltp":2.42,"tv":1096.89,"id":9345630}]}]}
{"op":"mcm","clk":"4226250855","pt":1631448051591,"mc":[{"id":"1.187552454","rc":[{"batl":[[0,2.68,41.58],[1,2.7,11.62],[2,2.72,4]],"ltp":2.42,"tv":1096.89,"id":9345630}]}]}
{"op":"mcm","clk":"4226251734","pt":1631448058547,"mc":[{"id":"1.187552454","rc":[{"batl":[[1,2.72,4],[2,3.55,3]],"ltp":2.42,"tv":1096.89,"id":9345630}]}]}
{"op":"mcm","clk":"4226251766","pt":1631448058818,"mc":[{"id":"1.187552454","rc":[{"batl":[[0,2.72,4],[1,3.55,3],[2,3.9,2]],"ltp":2.42,"tv":1096.89,"id":9345630}]}]}
{"op":"mcm","clk":"4226252265","pt":1631448062106,"mc":[{"id":"1.187552454","rc":[{"batb":[[2,2.28,3.16]],"batl":[[0,2.7,20],[1,2.72,4],[2,3.55,3]],"ltp":2.42,"tv":1096.89,"id":9345630}]}]}
{"op":"mcm","clk":"4226252682","pt":1631448065329,"mc":[{"id":"1.187552454","rc":[{"trd":[[2.42,207.82],[2.44,11.26]],"batb":[[2,2.36,4]],"ltp":2.42,"tv":1196.89,"id":9345630},{"trd":[[1.69,7.6],[1.7,536.76]],"batl":[[0,1.7,143.04],[1,1.72,342.64],[2,1.78,16.25]],"ltp":1.7,"tv":6023.41,"id":9028621}],"tv":7220.3}]}
{"op":"mcm","clk":"4226253138","pt":1631448068569,"mc":[{"id":"1.187552454","rc":[{"trd":[[1.66,37.49]],"batb":[[0,1.66,216.88],[1,1.65,316.95]],"batl":[[0,1.7,221.17]],"ltp":1.66,"tv":6029.41,"id":9028621}],"tv":7226.3}]}
{"op":"mcm","clk":"4226255776","pt":1631448089311,"mc":[{"id":"1.187552454","rc":[{"batb":[[2,2.34,3.72]],"batl":[[2,2.9,2.45]],"ltp":2.42,"tv":1196.89,"id":9345630},{"batl":[[2,1.74,17.25]],"ltp":1.66,"tv":6029.41,"id":9028621}]}]}
{"op":"mcm","clk":"4226256256","pt":1631448092504,"mc":[{"id":"1.187552454","rc":[{"batb":[[2,2.36,4]],"batl":[[0,2.7,11.62]],"ltp":2.42,"tv":1196.89,"id":9345630}]}]}
{"op":"mcm","clk":"4226256635","pt":1631448095588,"mc":[{"id":"1.187552454","rc":[{"batl":[[0,2.68,41.58],[1,2.7,11.62],[2,2.72,4]],"ltp":2.42,"tv":1196.89,"id":9345630}]}]}
{"op":"mcm","clk":"4226256786","pt":1631448096824,"mc":[{"id":"1.187552454","rc":[{"batb":[[0,2.38,3],[1,2.36,4],[2,2.34,3.72]],"batl":[[0,2.7,11.62],[1,2.72,4],[2,2.9,2.45]],"ltp":2.42,"tv":1196.89,"id":9345630},{"batl":[[0,1.7,192.03]],"ltp":1.66,"tv":6029.41,"id":9028621}]}]}
{"op":"mcm","clk":"4226257048","pt":1631448098475,"mc":[{"id":"1.187552454","rc":[{"batb":[[0,2.34,3.72],[1,2.28,3.16],[2,1.7,16.95]],"batl":[[0,2.72,4],[1,2.9,2.45],[2,3.2,2.03]],"ltp":2.42,"tv":1196.89,"id":9345630},{"batb":[[1,1.56,6],[2,1.55,4.97]],"batl":[[0,1.74,17.25],[1,1.77,17.5],[2,1.94,8.68]],"ltp":1.66,"tv":6029.41,"id":9028621}]}]}
{"op":"mcm","clk":"4226257120","pt":1631448099013,"mc":[{"id":"1.187552454","rc":[{"batb":[[0,2.28,3.16],[1,1.7,16.95],[2,1.6,98.88]],"batl":[[0,2.9,2.45],[1,3.2,2.03],[2,3.55,3]],"ltp":2.42,"tv":1196.89,"id":9345630},{"batb":[[0,1.55,4.97],[1,1.53,21.33],[2,1.46,29.88]],"batl":[[0,1.77,17.5],[1,1.94,8.68],[2,8.8,7.23]],"ltp":1.66,"tv":6029.41,"id":9028621}]}]}
{"op":"mcm","clk":"4226257441","pt":1631448101410,"mc":[{"id":"1.187552454","rc":[{"batb":[[0,1.56,332.5],[1,1.55,253.54],[2,1.53,21.33]],"batl":[[1,1.79,270.02],[2,1.81,289.59]],"ltp":1.66,"tv":6029.41,"id":9028621}]}]}
{"op":"mcm","clk":"4226258910","pt":1631448111533,"mc":[{"id":"1.187552454","rc":[{"batb":[[0,1.55,4.97],[1,1.53,21.33],[2,1.46,29.88]],"ltp":1.66,"tv":6029.41,"id":9028621}]}]}
{"op":"mcm","clk":"4226259059","pt":1631448112544,"mc":[{"id":"1.187552454","rc":[{"batb":[[0,1.73,7.69],[1,1.68,731.06],[2,1.55,4.97]],"ltp":1.66,"tv":6029.41,"id":9028621}]}]}
{"op":"mcm","clk":"4226259330","pt":1631448114527,"mc":[{"id":"1.187552454","rc":[{"batb":[[0,1.73,278.19],[1,1.71,345.53],[2,1.68,731.06]],"ltp":1.66,"tv":6029.41,"id":9028621}]}]}
{"op":"mcm","clk":"4226259449","pt":1631448115439,"mc":[{"id":"1.187552454","rc":[{"batb":[[1,1.6,98.88],[2,1.5,106.77]],"batl":[[0,2.32,4],[1,2.9,2.45],[2,3.2,2.03]],"ltp":2.42,"tv":1196.89,"id":9345630},{"trd":[[1.77,28]],"batb":[[2,1.55,4.97]],"batl":[[0,1.77,5.5]],"ltp":1.77,"tv":6053.41,"id":9028621}],"tv":7250.3}]}
{"op":"mcm","clk":"4226259576","pt":1631448116256,"mc":[{"id":"1.187552454","rc":[{"batl":[[1,2.68,12.25],[2,2.9,2.45]],"ltp":2.42,"tv":1196.89,"id":9345630}]}]}
{"op":"mcm","clk":"4226259722","pt":1631448117320,"mc":[{"id":"1.187552454","rc":[{"batb":[[2,1.69,9.98]],"ltp":1.77,"tv":6053.41,"id":9028621}]}]}
{"op":"mcm","clk":"4226260026","pt":1631448119454,"mc":[{"id":"1.187552454","rc":[{"trd":[[2.32,14.76]],"batl":[[0,2.9,2.45],[1,3.2,2.03],[2,3.55,3]],"ltp":2.32,"tv":1200.89,"id":9345630},{"trd":[[1.73,3.98],[1.75,8.96]],"batb":[[0,1.73,276.2]],"ltp":1.73,"tv":6062.69,"id":9028621}],"tv":7263.58}]}
{"op":"mcm","clk":"4226260449","pt":1631448122452,"mc":[{"id":"1.187552454","rc":[{"batb":[[1,2.2,3.77],[2,2.16,3.53]],"batl":[[0,2.6,157.01],[1,2.76,2.27],[2,2.9,2.45]],"ltp":2.32,"tv":1200.89,"id":9345630}]}]}
{"op":"mcm","clk":"4226260547","pt":1631448123263,"mc":[{"id":"1.187552454","rc":[{"batb":[[0,1.74,219.88],[1,1.73,276.2],[2,1.71,345.53]],"ltp":1.73,"tv":6062.69,"id":9028621}]}]}
{"op":"mcm","clk":"4226260740","pt":1631448124854,"mc":[{"id":"1.187552454","rc":[{"batb":[[0,1.74,229.18]],"ltp":1.73,"tv":6062.69,"id":9028621}]}]}
{"op":"mcm","clk":"4226260985","pt":1631448126458,"mc":[{"id":"1.187552454","rc":[{"batl":[[0,2.58,65.02],[1,2.6,157.01],[2,2.76,2.27]],"ltp":2.32,"tv":1200.89,"id":9345630}]}]}
{"op":"mcm","clk":"4226261337","pt":1631448128481,"mc":[{"id":"1.187552454","rc":[{"trd":[[1.77,39]],"batb":[[0,1.77,30.56],[1,1.74,229.18],[2,1.73,276.2]],"batl":[[0,1.79,270.02],[1,1.81,289.59],[2,1.82,15.75]],"ltp":1.77,"tv":6073.69,"id":9028621}],"tv":7274.58}]}
{"op":"mcm","clk":"4226261985","pt":1631448132460,"mc":[{"id":"1.187552454","rc":[{"batl":[[0,2.6,2.36],[1,2.76,2.27],[2,2.9,2.45]],"ltp":2.32,"tv":1200.89,"id":9345630},{"batl":[[0,1.79,298.89]],"ltp":1.77,"tv":6073.69,"id":9028621}]}]}
{"op":"mcm","clk":"4226262086","pt":1631448133043,"mc":[{"id":"1.187552454","rc":[{"batb":[[2,2.18,3.86]],"batl":[[2,2.8,2.32]],"ltp":2.32,"tv":1200.89,"id":9345630}]}]}
{"op":"mcm","clk":"4226262442","pt":1631448135357,"mc":[{"id":"1.187552454","rc":[{"batb":[[0,2.14,3.46],[1,1.6,98.88],[2,1.5,106.77]],"ltp":2.32,"tv":1200.89,"id":9345630},{"batb":[[2,1.73,5.7]],"batl":[[0,1.87,17.5],[1,1.94,8.68],[2,2.26,617.9]],"ltp":1.77,"tv":6073.69,"id":9028621}]}]}
{"op":"mcm","clk":"4226262638","pt":1631448136286,"mc":[{"id":"1.187552454","rc":[{"batb":[[1,1.74,219.88]],"ltp":1.77,"tv":6073.69,"id":9028621}]}]}
{"op":"mcm","clk":"4226262752","pt":1631448137070,"mc":[{"id":"1.187552454","rc":[{"batl":[[0,2.76,2.27],[1,2.8,2.32],[2,2.9,2.45]],"ltp":2.32,"tv":1200.89,"id":9345630},{"batb":[[1,1.73,5.7],[2,1.57,19.57]],"ltp":1.77,"tv":6073.69,"id":9028621}]}]}
{"op":"mcm","clk":"4226262980","pt":1631448138571,"mc":[{"id":"1.187552454","rc":[{"batb":[[0,2.18,3.86],[1,2.16,4],[2,2.14,7.46]],"ltp":2.32,"tv":1200.89,"id":9345630},{"batb":[[2,1.64,268.69]],"batl":[[0,1.84,16.53],[1,1.87,244.18],[2,1.89,252.88]],"ltp":1.77,"tv":6073.69,"id":9028621}]}]}
{"op":"mcm","clk":"4226263091","pt":1631448139495,"mc":[{"id":"1.187552454","rc":[{"batb":[[0,2.16,4],[1,2.14,7.46],[2,2.12,3]],"ltp":2.32,"tv":1200.89,"id":9345630},{"batb":[[2,1.57,19.57]],"batl":[[0,1.87,244.18],[1,1.89,252.88],[2,1.94,8.68]],"ltp":1.77,"tv":6073.69,"id":9028621}]}]}
{"op":"mcm","clk":"4226263201","pt":1631448140283,"mc":[{"id":"1.187552454","rc":[{"batl":[[0,2.6,2.66],[1,2.76,2.27],[2,2.8,2.32]],"ltp":2.32,"tv":1200.89,"id":9345630},{"batb":[[0,1.8,731.06],[1,1.77,30.56],[2,1.73,5.7]],"ltp":1.77,"tv":6073.69,"id":9028621}]}]}
{"op":"mcm","clk":"4226263384","pt":1631448141521,"mc":[{"id":"1.187552454","rc":[{"batb":[[0,2.14,3.46],[1,1.6,98.88],[2,1.5,106.77]],"ltp":2.32,"tv":1200.89,"id":9345630},{"batl":[[0,1.87,239.18]],"ltp":1.77,"tv":6073.69,"id":9028621}]}]}
{"op":"mcm","clk":"4226263589","pt":1631448142589,"mc":[{"id":"1.187552454","rc":[{"batl":[[0,2.24,8],[1,2.36,2.02],[2,2.6,2.66]],"ltp":2.32,"tv":1200.89,"id":9345630},{"batb":[[0,1.81,208.89],[1,1.8,743.06],[2,1.79,296.16]],"ltp":1.77,"tv":6073.69,"id":9028621}]}]}
{"op":"mcm","clk":"4226263720","pt":1631448143302,"mc":[{"id":"1.187552454","rc":[{"batl":[[0,2.24,4]],"ltp":2.32,"tv":1200.89,"id":9345630},{"batb":[[1,1.8,737.06]],"ltp":1.77,"tv":6073.69,"id":9028621}]}]}
{"op":"mcm","clk":"4226263912","pt":1631448144483,"mc":[{"id":"1.187552454","rc":[{"batl":[[2,2.52,13.3]],"ltp":2.32,"tv":1200.89,"id":9345630}]}]}
{"op":"mcm","clk":"4226264044","pt":1631448145387,"mc":[{"id":"1.187552454","rc":[{"batb":[[0,1.81,217.39]],"ltp":1.77,"tv":6073.69,"id":9028621}]}]}
{"op":"mcm","clk":"4226264565","pt":1631448148721,"mc":[{"id":"1.187552454","rc":[{"batb":[[1,2.12,4.04],[2,2.1,4]],"batl":[[2,2.38,3.04]],"ltp":2.32,"tv":1200.89,"id":9345630},{"batb":[[1,1.8,6]],"batl":[[1,1.88,14.29],[2,1.89,252.88]],"ltp":1.77,"tv":6073.69,"id":9028621}]}]}
{"op":"mcm","clk":"4226264717","pt":1631448149701,"mc":[{"id":"1.187552454","rc":[{"batb":[[0,1.83,219.88],[1,1.81,217.39],[2,1.8,6]],"ltp":1.77,"tv":6073.69,"id":9028621}]}]}
{"op":"mcm","clk":"4226265476","pt":1631448153720,"mc":[{"id":"1.187552454","rc":[{"batl":[[2,1.89,267.38]],"ltp":1.77,"tv":6073.69,"id":9028621}]}]}
{"op":"mcm","clk":"4226266654","pt":1631448161565,"mc":[{"id":"1.187552454","rc":[{"batb":[[0,2.12,4.04],[1,2.1,4],[2,2.08,4.06]],"batl":[[0,2.38,3.04],[1,2.48,2.99],[2,2.5,2.45]],"ltp":2.32,"tv":1200.89,"id":9345630},{"batb":[[1,1.81,208.89],[2,1.79,296.16]],"batl":[[0,1.87,221.68],[1,1.89,267.38],[2,1.91,14.5]],"ltp":1.77,"tv":6073.69,"id":9028621}]}]}
{"op":"mcm","clk":"4226266771","pt":1631448162273,"mc":[{"id":"1.187552454","rc":[{"batb":[[0,2.08,4.06],[1,1.6,98.88],[2,1.5,106.77]],"ltp":2.32,"tv":1200.89,"id":9345630},{"batb":[[1,1.77,30.56],[2,1.73,21.83]],"batl":[[0,1.91,14.5],[1,1.94,8.68],[2,2.26,617.9]],"ltp":1.77,"tv":6073.69,"id":9028621}]}]}
{"op":"mcm","clk":"4226266918","pt":1631448163187,"mc":[{"id":"1.187552454","rc":[{"batl":[[0,2.5,2.45],[1,2.76,2.27],[2,2.8,2.32]],"ltp":2.32,"tv":1200.89,"id":9345630},{"batb":[[0,1.77,30.56],[1,1.73,5.7],[2,1.67,18.47]],"ltp":1.77,"tv":6073.69,"id":9028621}]}]}
{"op":"mcm","clk":"4226267067","pt":1631448164089,"mc":[{"id":"1.187552454","rc":[{"batb":[[2,1.69,9.98]],"ltp":1.77,"tv":6073.69,"id":9028621}]}]}
{"op":"mcm","clk":"4226267336","pt":1631448165492,"mc":[{"id":"1.187552454","rc":[{"batb":[[0,2.12,3.79],[1,2.08,9.06],[2,2.06,4]],"ltp":2.32,"tv":1200.89,"id":9345630},{"batl":[[0,1.89,14.5],[1,1.91,19.5],[2,1.94,8.68]],"ltp":1.77,"tv":6073.69,"id":9028621}]}]}
{"op":"mcm","clk":"4226267487","pt":1631448166458,"mc":[{"id":"1.187552454","rc":[{"batb":[[0,2.08,9.06],[1,2.06,4],[2,1.6,98.88]],"batl":[[0,2.38,3.04],[1,2.5,2.45],[2,2.76,2.27]],"ltp":2.32,"tv":1200.89,"id":9345630},{"batb":[[0,1.78,8.83],[1,1.77,30.56],[2,1.73,22.83]],"batl":[[0,1.91,19.5],[1,1.94,8.68],[2,2.26,617.9]],"ltp":1.77,"tv":6073.69,"id":9028621}]}]}
{"op":"mcm","clk":"4226267659","pt":1631448167588,"mc":[{"id":"1.187552454","rc":[{"batl":[[0,2.5,2.45],[1,2.76,2.27],[2,2.8,2.32]],"ltp":2.32,"tv":1200.89,"id":9345630},{"batb":[[2,1.73,5.7]],"batl":[[0,1.89,4],[1,1.91,19.5],[2,1.94,8.68]],"ltp":1.77,"tv":6073.69,"id":9028621}]}]}
{"op":"mcm","clk":"4226267788","pt":1631448168396,"mc":[{"id":"1.187552454","rc":[{"batl":[[0,1.91,19.5],[1,1.94,8.68],[2,2.26,617.9]],"ltp":1.77,"tv":6073.69,"id":9028621}]}]}
{"op":"mcm","clk":"4226268107","pt":1631448170298,"mc":[{"id":"1.187552454","rc":[{"batb":[[0,2.1,45.3],[1,2.08,9.06],[2,2.06,4]],"ltp":2.32,"tv":1200.89,"id":9345630},{"batb":[[0,1.79,266.63],[1,1.78,8.83],[2,1.77,338.08]],"batl":[[0,1.85,190.64],[1,1.87,261.45],[2,1.9,45.27]],"ltp":1.77,"tv":6073.69,"id":9028621}]}]}
{"op":"mcm","clk":"4226268467","pt":1631448172499,"mc":[{"id":"1.187552454","rc":[{"batb":[[0,2.12,4.04],[1,2.1,45.3],[2,2.08,9.06]],"ltp":2.32,"tv":1200.89,"id":9345630},{"batl":[[2,1.89,15.5]],"ltp":1.77,"tv":6073.69,"id":9028621}]}]}
{"op":"mcm","clk":"4226268652","pt":1631448173595,"mc":[{"id":"1.187552454","rc":[{"batb":[[1,2.08,9.06],[2,2.06,4]],"batl":[[0,2.36,15.2],[1,2.38,3.25],[2,2.5,2.45]],"ltp":2.32,"tv":1200.89,"id":9345630}]}]}
{"op":"mcm","clk":"4226268717","pt":1631448174006,"mc":[{"id":"1.187552454","rc":[{"batb":[[0,2.08,9.06],[1,2.06,4],[2,1.6,98.88]],"batl":[[0,2.5,2.45],[1,2.76,2.27],[2,2.8,2.32]],"ltp":2.32,"tv":1200.89,"id":9345630},{"batb":[[0,1.78,8.83],[1,1.77,30.56],[2,1.73,5.7]],"batl":[[0,1.91,19.5],[1,1.94,8.68],[2,2.26,617.9]],"ltp":1.77,"tv":6073.69,"id":9028621}]}]}
{"op":"mcm","clk":"4226269287","pt":1631448177592,"mc":[{"id":"1.187552454","rc":[{"batb":[[1,1.6,98.88],[2,1.5,106.77]],"batl":[[0,2.38,3.25],[1,2.5,2.45],[2,2.76,2.27]],"ltp":2.32,"tv":1200.89,"id":9345630},{"batb":[[0,1.8,8.61],[1,1.78,8.83],[2,1.77,30.56]],"batl":[[1,1.94,239],[2,1.96,226.32]],"ltp":1.77,"tv":6073.69,"id":9028621}]}]}
{"op":"mcm","clk":"4226269809","pt":1631448180590,"mc":[{"id":"1.187552454","rc":[{"batb":[[0,1.77,30.56],[1,1.73,265.53],[2,1.71,345.44]],"ltp":1.77,"tv":6073.69,"id":9028621}]}]}
{"op":"mcm","clk":"4226269926","pt":1631448181080,"mc":[{"id":"1.187552454","rc":[{"batb":[[1,2.06,4],[2,1.6,98.88]],"ltp":2.32,"tv":1200.89,"id":9345630}]}]}
{"op":"mcm","clk":"4226270920","pt":1631448186614,"mc":[{"id":"1.187552454","rc":[{"trd":[[1.91,0.02]],"batl":[[0,1.91,19.49]],"ltp":1.91,"tv":6073.71,"id":9028621}],"tv":7274.6}]}
{"op":"mcm","clk":"4226271742","pt":1631448191386,"mc":[{"id":"1.187552454","rc":[{"batb":[[0,2.12,4.04],[1,2.08,9.06],[2,2.06,4]],"ltp":2.32,"tv":1200.89,"id":9345630},{"batl":[[0,1.89,15.5],[1,1.91,19.49],[2,1.94,239]],"ltp":1.91,"tv":6073.71,"id":9028621}]}]}
{"op":"mcm","clk":"4226271823","pt":1631448191714,"mc":[{"id":"1.187552454","rc":[{"batb":[[0,2.08,9.06],[1,2.06,4],[2,1.6,98.88]],"ltp":2.32,"tv":1200.89,"id":9345630},{"batl":[[0,1.91,19.49],[1,1.94,239],[2,1.96,226.32]],"ltp":1.91,"tv":6073.71,"id":9028621}]}]}
{"op":"mcm","clk":"4226272132","pt":1631448193432,"mc":[{"id":"1.187552454","rc":[{"batb":[[1,1.74,9.31],[2,1.73,265.53]],"ltp":1.91,"tv":6073.71,"id":9028621}]}]}
{"op":"mcm","clk":"4226272289","pt":1631448194338,"mc":[{"id":"1.187552454","rc":[{"batb":[[1,1.6,98.88],[2,1.5,106.77]],"ltp":2.32,"tv":1200.89,"id":9345630},{"batl":[[1,1.94,8.68],[2,2.26,617.9]],"ltp":1.91,"tv":6073.71,"id":9028621}]}]}
{"op":"mcm","clk":"4226272473","pt":1631448195512,"mc":[{"id":"1.187552454","rc":[{"batl":[[0,1.82,731.06],[1,1.91,19.49],[2,1.94,8.68]],"ltp":1.91,"tv":6073.71,"id":9028621}]}]}
{"op":"mcm","clk":"4226272545","pt":1631448196000,"mc":[{"id":"1.187552454","rc":[{"batb":[[2,1.73,259.83]],"ltp":1.91,"tv":6073.71,"id":9028621}]}]}
{"op":"mcm","clk":"4226272794","pt":1631448197594,"mc":[{"id":"1.187552454","rc":[{"batb":[[1,2.06,3],[2,1.6,98.88]],"ltp":2.32,"tv":1200.89,"id":9345630},{"batb":[[1,1.73,259.83],[2,1.71,345.44]],"batl":[[0,1.79,296.63],[1,1.81,289.52],[2,1.82,731.06]],"ltp":1.91,"tv":6073.71,"id":9028621}]}]}
{"op":"mcm","clk":"4226272882","pt":1631448198087,"mc":[{"id":"1.187552454","rc":[{"batb":[[0,2.16,5],[1,2.1,1223.72],[2,2.08,9.06]],"ltp":2.32,"tv":1200.89,"id":9345630}]}]}
{"op":"mcm","clk":"4226273031","pt":1631448199201,"mc":[{"id":"1.187552454","rc":[{"batb":[[0,2.2,3],[1,2.18,4],[2,2.16,5]],"ltp":2.32,"tv":1200.89,"id":9345630},{"batl":[[1,1.81,319.05],[2,1.84,5]],"ltp":1.91,"tv":6073.71,"id":9028621}]}]}
{"op":"mcm","clk":"4226273954","pt":1631448204421,"mc":[{"id":"1.187552454","rc":[{"batb":[[2,2.16,8.78]],"batl":[[2,2.62,2.96]],"ltp":2.32,"tv":1200.89,"id":9345630}]}]}
{"op":"mcm","clk":"4226274266","pt":1631448205516,"mc":[{"id":"1.187552454","rc":[{"batb":[[0,2.22,45.3],[1,2.2,3],[2,2.18,4]],"batl":[[0,2.38,19.5]],"ltp":2.32,"tv":1200.89,"id":9345630}]}]}
{"op":"mcm","clk":"4226274513","pt":1631448206030,"mc":[{"id":"1.187552454","rc":[{"batb":[[0,2.2,3],[1,2.18,4],[2,2.16,8.78]],"ltp":2.32,"tv":1200.89,"id":9345630}]}]}
{"op":"mcm","clk":"4226274693","pt":1631448206828,"mc":[{"id":"1.187552454","rc":[{"trd":[[1.79,124.34]],"batl":[[0,1.79,246.63]],"ltp":1.79,"tv":6173.71,"id":9028621}],"tv":7374.6}]}
{"op":"mcm","clk":"4226274844","pt":1631448207737,"mc":[{"id":"1.187552454","rc":[{"batb":[[1,1.75,219.88],[2,1.73,259.83]],"ltp":1.79,"tv":6173.71,"id":9028621}]}]}
{"op":"mcm","clk":"4226275261","pt":1631448210520,"mc":[{"id":"1.187552454","rc":[{"batl":[[0,1.79,275.59]],"ltp":1.79,"tv":6173.71,"id":9028621}]}]}
{"op":"mcm","clk":"4226275615","pt":1631448212530,"mc":[{"id":"1.187552454","rc":[{"batb":[[0,2.22,21.89],[1,2.2,3],[2,2.18,4]],"ltp":2.32,"tv":1200.89,"id":9345630}]}]}
{"op":"mcm","clk":"4226275735","pt":1631448213151,"mc":[{"id":"1.187552454","rc":[{"batb":[[2,2.16,8.78]],"ltp":2.32,"tv":1200.89,"id":9345630},{"trd":[[1.77,49]],"batb":[[0,1.77,25.56]],"ltp":1.77,"tv":6183.71,"id":9028621}],"tv":7384.6}]}
{"op":"mcm","clk":"4226276214","pt":1631448215930,"mc":[{"id":"1.187552454","rc":[{"batb":[[2,2.18,3]],"ltp":2.32,"tv":1200.89,"id":9345630}]}]}
{"op":"mcm","clk":"4226277603","pt":1631448222550,"mc":[{"id":"1.187552454","rc":[{"batb":[[0,2.16,5],[1,2.12,3.79],[2,1.6,98.88]],"batl":[[0,2.5,2.45],[1,2.62,2.96],[2,2.76,2.27]],"ltp":2.32,"tv":1200.89,"id":9345630},{"batb":[[2,1.67,18.47]],"batl":[[0,1.84,5],[1,1.85,14.3],[2,1.89,15.5]],"ltp":1.77,"tv":6183.71,"id":9028621}]}]}
{"op":"mcm","clk":"4226277689","pt":1631448223160,"mc":[{"id":"1.187552454","rc":[{"batb":[[0,2.12,3.79],[1,1.6,98.88],[2,1.5,106.77]],"ltp":2.32,"tv":1200.89,"id":9345630},{"batl":[[0,1.89,15.5],[1,1.91,5],[2,1.94,8.68]],"ltp":1.77,"tv":6183.71,"id":9028621}]}]}
{"op":"mcm","clk":"4226278026","pt":1631448225454,"mc":[{"id":"1.187552454","rc":[{"batl":[[0,2.62,2.96],[1,2.76,2.27],[2,2.8,2.32]],"ltp":2.32,"tv":1200.89,"id":9345630},{"batb":[[1,1.63,232.26],[2,1.62,232.79]],"batl":[[0,1.88,195.2],[1,1.89,15.5],[2,1.9,248.81]],"ltp":1.77,"tv":6183.71,"id":9028621}]}]}
{"op":"mcm","clk":"4226278187","pt":1631448226474,"mc":[{"id":"1.187552454","rc":[{"batb":[[0,2.12,7.79],[1,2.1,3],[2,1.6,98.88]],"ltp":2.32,"tv":1200.89,"id":9345630},{"batl":[[0,1.85,16.5],[1,1.88,195.2],[2,1.89,19.5]],"ltp":1.77,"tv":6183.71,"id":9028621}]}]}
{"op":"mcm","clk":"4226278237","pt":1631448226762,"mc":[{"id":"1.187552454","rc":[{"batl":[[0,1.88,195.2],[1,1.89,19.5],[2,1.9,248.81]],"ltp":1.77,"tv":6183.71,"id":9028621}]}]}
{"op":"mcm","clk":"4226278540","pt":1631448228640,"mc":[{"id":"1.187552454","rc":[{"batl":[[0,1.88,200.2]],"ltp":1.77,"tv":6183.71,"id":9028621}]}]}
{"op":"mcm","clk":"4226279041","pt":1631448231341,"mc":[{"id":"1.187552454","rc":[{"batb":[[2,1.5,106.77]],"ltp":2.32,"tv":1200.89,"id":9345630},{"batb":[[0,1.87,7.69],[1,1.82,731.06],[2,1.77,25.56]],"ltp":1.77,"tv":6183.71,"id":9028621}]}]}
{"op":"mcm","clk":"4226279151","pt":1631448231985,"mc":[{"id":"1.187552454","rc":[{"batb":[[0,2.12,3.79],[1,1.5,106.77],[2,1.4,148.32]],"batl":[[0,2.5,2.73],[1,2.62,2.96],[2,2.76,2.27]],"ltp":2.32,"tv":1200.89,"id":9345630},{"batl":[[0,1.88,195.2],[1,1.89,15.5]],"ltp":1.77,"tv":6183.71,"id":9028621}]}]}
{"op":"mcm","clk":"4226279439","pt":1631448233384,"mc":[{"id":"1.187552454","rc":[{"trd":[[2.16,343.58]],"batl":[[0,2.24,2.19],[1,2.5,2.73],[2,2.62,2.96]],"ltp":2.16,"tv":1204.92,"id":9345630},{"trd":[[1.87,9.65]],"batb":[[0,1.87,3.03],[2,1.81,6.87]],"ltp":1.87,"tv":6188.36,"id":9028621}],"tv":7393.28}]}
{"op":"mcm","clk":"4226279658","pt":1631448234570,"mc":[{"id":"1.187552454","rc":[{"batl":[[0,2.28,4]],"ltp":2.16,"tv":1204.92,"id":9345630},{"batb":[[0,1.82,955.23],[1,1.8,296.8],[2,1.77,25.56]],"ltp":1.87,"tv":6188.36,"id":9028621}]}]}
{"op":"mcm","clk":"4226280010","pt":1631448236568,"mc":[{"id":"1.187552454","rc":[{"batb":[[0,1.82,224.17]],"ltp":1.87,"tv":6188.36,"id":9028621}]}]}
{"op":"mcm","clk":"4226280114","pt":1631448237210,"mc":[{"id":"1.187552454","rc":[{"batb":[[0,1.82,254.04]],"ltp":1.87,"tv":6188.36,"id":9028621}]}]}
{"op":"mcm","clk":"4226280447","pt":1631448239052,"mc":[{"id":"1.187552454","rc":[{"batl":[[0,2.26,20],[1,2.28,4],[2,2.5,2.73]],"ltp":2.16,"tv":1204.92,"id":9345630}]}]}
{"op":"mcm","clk":"4226280563","pt":1631448239796,"mc":[{"id":"1.187552454","rc":[{"batb":[[1,2.08,4.06],[2,1.5,106.77]],"batl":[[1,2.28,7.84],[2,2.32,3.36]],"ltp":2.16,"tv":1204.92,"id":9345630},{"batb":[[2,1.79,18.31]],"ltp":1.87,"tv":6188.36,"id":9028621}]}]}
{"op":"mcm","clk":"4226280892","pt":1631448241903,"mc":[{"id":"1.187552454","rc":[{"batb":[[0,1.83,219.88],[1,1.82,254.04],[2,1.8,296.8]],"ltp":1.87,"tv":6188.36,"id":9028621}]}]}
{"op":"mcm","clk":"4226282289","pt":1631448250192,"mc":[{"id":"1.187552454","rc":[{"batb":[[0,2.12,22.74]],"ltp":2.16,"tv":1204.92,"id":9345630}]}]}
{"op":"mcm","clk":"4226283102","pt":1631448255417,"mc":[{"id":"1.187552454","rc":[{"batb":[[0,2.12,3.79]],"batl":[[0,2.28,3.84],[1,2.32,3.36],[2,2.5,2.73]],"ltp":2.16,"tv":1204.92,"id":9345630},{"batb":[[1,1.79,18.31],[2,1.77,25.56]],"batl":[[0,1.89,15.5],[1,1.92,13.06],[2,1.94,8.68]],"ltp":1.87,"tv":6188.36,"id":9028621}]}]}
{"op":"mcm","clk":"4226283158","pt":1631448255749,"mc":[{"id":"1.187552454","rc":[{"batb":[[0,2.08,4.06],[1,1.5,106.77],[2,1.4,148.32]],"ltp":2.16,"tv":1204.92,"id":9345630},{"batl":[[0,1.92,13.06],[1,1.94,8.68],[2,2.26,617.9]],"ltp":1.87,"tv":6188.36,"id":9028621}]}]}
{"op":"mcm","clk":"4226283612","pt":1631448258422,"mc":[{"id":"1.187552454","rc":[{"batl":[[2,1.95,219.1]],"ltp":1.87,"tv":6188.36,"id":9028621}]}]}
{"op":"mcm","clk":"4226283744","pt":1631448259233,"mc":[{"id":"1.187552454","rc":[{"batl":[[0,2.32,3.36],[1,2.5,2.73],[2,2.62,2.96]],"ltp":2.16,"tv":1204.92,"id":9345630},{"batb":[[0,1.77,25.56],[1,1.76,17.48],[2,1.74,285.94]],"batl":[[0,1.92,17.06]],"ltp":1.87,"tv":6188.36,"id":9028621}]}]}
{"op":"mcm","clk":"4226284303","pt":1631448262540,"mc":[{"id":"1.187552454","rc":[{"batb":[[0,2.12,3.54],[1,2.08,4.06],[2,1.5,106.77]],"batl":[[0,2.28,3.59],[1,2.3,4],[2,2.32,3.36]],"ltp":2.16,"tv":1204.92,"id":9345630},{"batb":[[0,1.79,14.31],[1,1.78,5],[2,1.77,29.56]],"batl":[[0,1.89,14.68],[1,1.92,17.06],[2,1.94,8.68]],"ltp":1.87,"tv":6188.36,"id":9028621}]}]}
{"op":"mcm","clk":"4226284343","pt":1631448262810,"mc":[{"id":"1.187552454","rc":[{"batb":[[0,2.08,4.06],[1,1.5,106.77],[2,1.4,148.32]],"batl":[[0,2.3,4],[1,2.32,3.36],[2,2.5,2.73]],"ltp":2.16,"tv":1204.92,"id":9345630},{"batb":[[0,1.78,5],[1,1.77,29.56],[2,1.76,22.48]],"batl":[[0,1.92,17.06],[1,1.94,8.68],[2,1.95,219.1]],"ltp":1.87,"tv":6188.36,"id":9028621}]}]}
{"op":"mcm","clk":"4226284616","pt":1631448264337,"mc":[{"id":"1.187552454","rc":[{"batb":[[0,1.78,13.83]],"batl":[[2,2.26,617.9]],"ltp":1.87,"tv":6188.36,"id":9028621}]}]}
{"op":"mcm","clk":"4226284797","pt":1631448265448,"mc":[{"id":"1.187552454","rc":[{"batl":[[0,1.84,1137.59],[1,1.92,17.06],[2,1.94,8.68]],"ltp":1.87,"tv":6188.36,"id":9028621}]}]}
{"op":"mcm","clk":"4226284965","pt":1631448266356,"mc":[{"id":"1.187552454","rc":[{"batb":[[0,2.12,3.79],[1,2.08,4.06],[2,1.5,106.77]],"batl":[[0,2.32,3.36],[1,2.5,2.73],[2,2.62,2.96]],"ltp":2.16,"tv":1204.92,"id":9345630},{"batb":[[0,1.77,25.56],[1,1.76,17.48],[2,1.74,285.94]],"batl":[[1,1.89,12.5],[2,1.92,17.06]],"ltp":1.87,"tv":6188.36,"id":9028621}]}]}
{"op":"mcm","clk":"4226285155","pt":1631448267539,"mc":[{"id":"1.187552454","rc":[{"batl":[[0,1.8,240.2],[1,1.82,284.6],[2,1.84,1137.59]],"ltp":1.87,"tv":6188.36,"id":9028621}]}]}
{"op":"mcm","clk":"4226285296","pt":1631448268352,"mc":[{"id":"1.187552454","rc":[{"batb":[[0,2.18,5],[1,2.12,3.79],[2,2.1,20.3]],"ltp":2.16,"tv":1204.92,"id":9345630}]}]}
{"op":"mcm","clk":"4226285478","pt":1631448269329,"mc":[{"id":"1.187552454","rc":[{"batb":[[0,2.2,4],[1,2.18,9],[2,2.14,1206.09]],"ltp":2.16,"tv":1204.92,"id":9345630},{"batl":[[2,1.83,4]],"ltp":1.87,"tv":6188.36,"id":9028621}]}]}
{"op":"mcm","clk":"4226285608","pt":1631448270136,"mc":[{"id":"1.187552454","rc":[{"batb":[[2,2.12,3.79]],"ltp":2.16,"tv":1204.92,"id":9345630}]}]}
{"op":"mcm","clk":"4226286457","pt":1631448275362,"mc":[{"id":"1.187552454","rc":[{"batb":[[0,2.22,25],[1,2.2,4],[2,2.18,9]],"batl":[[1,2.48,2.74],[2,2.5,2.73]],"ltp":2.16,"tv":1204.92,"id":9345630}]}]}
{"op":"mcm","clk":"4226288190","pt":1631448285582,"mc":[{"id":"1.187552454","rc":[{"trd":[[2.24,142.7]],"batb":[[0,2.18,5],[1,2.1,3],[2,2.06,3.74]],"batl":[[0,2.48,2.74],[1,2.6,2.61],[2,3.55,3]],"ltp":2.24,"tv":1347.62,"id":9345630},{"trd":[[1.8,319.56]],"batb":[[1,1.68,16.61],[2,1.63,18.23]],"batl":[[0,1.85,5],[1,1.93,14.64],[2,1.94,8.68]],"ltp":1.8,"tv":6365.94,"id":9028621}],"tv":7713.57}]}
{"op":"mcm","clk":"4226288239","pt":1631448285853,"mc":[{"id":"1.187552454","rc":[{"batb":[[0,2.1,3],[1,2.06,3.74],[2,1.6,98.88]],"ltp":2.24,"tv":1347.62,"id":9345630},{"batl":[[0,1.93,14.64],[1,1.94,8.68],[2,2.26,617.9]],"ltp":1.8,"tv":6365.94,"id":9028621}]}]}
{"op":"mcm","clk":"4226288797","pt":1631448289169,"mc":[{"id":"1.187552454","rc":[{"batb":[[0,2.12,4.04],[1,2.1,3],[2,2.08,4]],"ltp":2.24,"tv":1347.62,"id":9345630},{"batl":[[0,1.88,13.04],[1,1.9,4],[2,1.91,4]],"ltp":1.8,"tv":6365.94,"id":9028621}]}]}
{"op":"mcm","clk":"4226288979","pt":1631448290234,"mc":[{"id":"1.187552454","rc":[{"batb":[[0,2.1,3],[1,2.08,4],[2,2.06,3.74]],"ltp":2.24,"tv":1347.62,"id":9345630},{"batl":[[0,1.9,4],[1,1.91,4],[2,1.92,223.83]],"ltp":1.8,"tv":6365.94,"id":9028621}]}]}
{"op":"mcm","clk":"4226289880","pt":1631448295242,"mc":[{"id":"1.187552454","rc":[{"batb":[[2,1.64,10.76]],"ltp":1.8,"tv":6365.94,"id":9028621}]}]}
{"op":"mcm","clk":"4226290102","pt":1631448296550,"mc":[{"id":"1.187552454","rc":[{"batb":[[0,2.12,3.79],[1,2.1,3],[2,2.08,4]],"ltp":2.24,"tv":1347.62,"id":9345630},{"trd":[[1.77,69.94]],"batb":[[0,1.77,15.09]],"batl":[[0,1.88,12.79],[1,1.9,4],[2,1.91,4]],"ltp":1.77,"tv":6386.88,"id":9028621}],"tv":7734.5}]}
{"op":"mcm","clk":"4226290166","pt":1631448296878,"mc":[{"id":"1.187552454","rc":[{"batb":[[0,2.1,3],[1,2.08,4],[2,2.06,3.74]],"ltp":2.24,"tv":1347.62,"id":9345630},{"batl":[[0,1.9,4],[1,1.91,4],[2,1.92,223.83]],"ltp":1.77,"tv":6386.88,"id":9028621}]}]}
{"op":"mcm","clk":"4226291381","pt":1631448303896,"mc":[{"id":"1.187552454","rc":[{"batb":[[1,2.06,3.74],[2,1.6,98.88]],"ltp":2.24,"tv":1347.62,"id":9345630},{"batl":[[1,1.92,223.83],[2,1.93,14.64]],"ltp":1.77,"tv":6386.88,"id":9028621}]}]}
{"op":"mcm","clk":"4226292154","pt":1631448307390,"mc":[{"id":"1.187552454","rc":[{"batb":[[1,2.08,3],[2,2.06,3.74]],"ltp":2.24,"tv":1347.62,"id":9345630},{"batl":[[1,1.93,14.64],[2,1.94,8.68]],"ltp":1.77,"tv":6386.88,"id":9028621}]}]}
{"op":"mcm","clk":"4226292357","pt":1631448308414,"mc":[{"id":"1.187552454","rc":[{"batl":[[0,2.6,2.61],[1,3.55,3],[2,3.55,0]],"ltp":2.24,"tv":1347.62,"id":9345630},{"trd":[[1.77,100.12]],"batb":[[0,1.64,10.76],[1,1.63,18.23],[2,1.62,398.9]],"batl":[[0,1.7,715.97],[1,1.73,406.52],[2,1.9,4]],"ltp":1.77,"tv":6417.06,"id":9028621}],"tv":7764.68}]}
{"op":"mcm","clk":"4226292489","pt":1631448309100,"mc":[{"id":"1.187552454","rc":[{"batb":[[0,1.63,18.23],[1,1.62,398.9],[2,1.61,215.37]],"ltp":1.77,"tv":6417.06,"id":9028621}]}]}
{"op":"mcm","clk":"4226292742","pt":1631448310399,"mc":[{"id":"1.187552454","rc":[{"batb":[[0,2.12,1217.57],[1,2.1,3],[2,2.08,3]],"ltp":2.24,"tv":1347.62,"id":9345630},{"batl":[[0,1.68,348.37],[1,1.7,1071.04]],"ltp":1.77,"tv":6417.06,"id":9028621}]}]}
{"op":"mcm","clk":"4226292945","pt":1631448311485,"mc":[{"id":"1.187552454","rc":[{"batb":[[0,2.28,4],[1,2.26,15],[2,2.12,1217.57]],"ltp":2.24,"tv":1347.62,"id":9345630},{"batl":[[1,1.69,50.89],[2,1.7,1071.04]],"ltp":1.77,"tv":6417.06,"id":9028621}]}]}
{"op":"mcm","clk":"4226293140","pt":1631448312506,"mc":[{"id":"1.187552454","rc":[{"batb":[[1,2.12,1217.57],[2,2.1,3]],"batl":[[0,2.6,6.61]],"ltp":2.24,"tv":1347.62,"id":9345630},{"batl":[[1,1.7,1071.04],[2,1.77,6]],"ltp":1.77,"tv":6417.06,"id":9028621}]}]}
{"op":"mcm","clk":"4226293311","pt":1631448313513,"mc":[{"id":"1.187552454","rc":[{"batb":[[0,2.44,3],[1,2.42,4],[2,2.28,4]],"batl":[[0,2.6,2.61]],"ltp":2.24,"tv":1347.62,"id":9345630},{"batl":[[1,1.69,6],[2,1.7,1071.04]],"ltp":1.77,"tv":6417.06,"id":9028621}]}]}
{"op":"mcm","clk":"4226293615","pt":1631448315221,"mc":[{"id":"1.187552454","rc":[{"trd":[[1.63,7.7]],"batb":[[0,1.63,14.38]],"batl":[[0,1.67,50.89],[1,1.68,348.37],[2,1.69,6]],"ltp":1.63,"tv":6424.76,"id":9028621}],"tv":7772.38}]}
{"op":"mcm","clk":"4226293912","pt":1631448316812,"mc":[{"id":"1.187552454","rc":[{"batl":[[1,2.94,2.25],[2,3.3,2.15]],"ltp":2.24,"tv":1347.62,"id":9345630}]}]}
{"op":"mcm","clk":"4226294243","pt":1631448318536,"mc":[{"id":"1.187552454","rc":[{"batb":[[0,2.46,20],[1,2.44,3],[2,2.42,4]],"batl":[[2,3,2.33]],"ltp":2.24,"tv":1347.62,"id":9345630}]}]}
{"op":"mcm","clk":"4226294540","pt":1631448320036,"mc":[{"id":"1.187552454","rc":[{"batb":[[0,1.64,219.88],[1,1.63,14.38],[2,1.62,398.9]],"ltp":1.63,"tv":6424.76,"id":9028621}]}]}
{"op":"mcm","clk":"4226295192","pt":1631448323597,"mc":[{"id":"1.187552454","rc":[{"batl":[[2,2.98,2.25]],"ltp":2.24,"tv":1347.62,"id":9345630}]}]}
{"op":"mcm","clk":"4226296788","pt":1631448332955,"mc":[{"id":"1.187552454","rc":[{"trd":[[2.48,119.29]],"batb":[[2,2.28,21.57]],"ltp":2.48,"tv":1352.89,"id":9345630},{"trd":[[1.67,310.95]],"batl":[[0,1.67,43.05]],"ltp":1.67,"tv":6432.6,"id":9028621}],"tv":7785.5}]}
{"op":"mcm","clk":"4226297417","pt":1631448336542,"mc":[{"id":"1.187552454","rc":[{"batb":[[0,2.28,21.57],[1,2.26,18.96],[2,2.18,18.72]],"batl":[[0,2.98,2.25],[1,3,2.33],[2,3.3,2.15]],"ltp":2.48,"tv":1352.89,"id":9345630},{"batb":[[1,1.51,25.99],[2,1.5,28.1]],"batl":[[0,1.77,6],[1,1.78,22.5],[2,1.79,22.19]],"ltp":1.67,"tv":6432.6,"id":9028621}]}]}
{"op":"mcm","clk":"4226297575","pt":1631448337349,"mc":[{"id":"1.187552454","rc":[{"batb":[[0,2.28,4],[1,2.18,3.86],[2,1.7,16.95]],"ltp":2.48,"tv":1352.89,"id":9345630},{"trd":[[1.64,3.42]],"batb":[[0,1.64,218.17]],"batl":[[1,1.84,15.78],[2,1.94,8.68]],"ltp":1.64,"tv":6436.02,"id":9028621}],"tv":7788.92}]}
{"op":"mcm","clk":"4226297953","pt":1631448339436,"mc":[{"id":"1.187552454","rc":[{"batl":[[0,3.3,2.15],[1,3.55,3],[2,3.3,0]],"ltp":2.48,"tv":1352.89,"id":9345630},{"batb":[[0,1.5,339.99],[1,1.49,290.19],[2,1.44,28.67]],"batl":[[1,1.8,257.92],[2,1.82,284.32]],"ltp":1.64,"tv":6436.02,"id":9028621}]}]}
{"op":"mcm","clk":"4226298135","pt":1631448340415,"mc":[{"id":"1.187552454","rc":[{"batb":[[0,2.28,7.66],[1,2.18,19.22]],"ltp":2.48,"tv":1352.89,"id":9345630},{"batl":[[1,1.78,16.25],[2,1.8,257.92]],"ltp":1.64,"tv":6436.02,"id":9028621}]}]}
{"op":"mcm","clk":"4226298332","pt":1631448341564,"mc":[{"id":"1.187552454","rc":[{"batb":[[0,2.28,4]],"ltp":2.48,"tv":1352.89,"id":9345630},{"batb":[[0,1.44,28.67],[1,1.4,4],[2,1.3,197.76]],"batl":[[1,1.84,21.81],[2,1.94,8.68]],"ltp":1.64,"tv":6436.02,"id":9028621}]}]}
{"op":"mcm","clk":"4226298521","pt":1631448342521,"mc":[{"id":"1.187552454","rc":[{"batb":[[1,2.18,3.86]],"batl":[[0,3.3,5.15]],"ltp":2.48,"tv":1352.89,"id":9345630},{"batb":[[0,1.44,34.67],[1,1.43,6],[2,1.4,4]],"batl":[[1,1.84,15.78]],"ltp":1.64,"tv":6436.02,"id":9028621}]}]}
{"op":"mcm","clk":"4226298669","pt":1631448343543,"mc":[{"id":"1.187552454","rc":[{"batb":[[0,2.5,20.6],[1,2.28,18.66],[2,2.18,3.86]],"batl":[[0,2.6,19.06],[1,3,3],[2,3.3,5.15]],"ltp":2.48,"tv":1352.89,"id":9345630},{"batb":[[0,1.49,6],[1,1.44,34.67],[2,1.43,6]],"batl":[[0,1.67,19.5],[1,1.77,6],[2,1.78,6.25]],"ltp":1.64,"tv":6436.02,"id":9028621}]}]}
{"op":"mcm","clk":"4226298844","pt":1631448344530,"mc":[{"id":"1.187552454","rc":[{"batb":[[0,2.28,4],[1,2.18,3.86],[2,1.7,16.95]],"batl":[[0,3,3],[1,3.3,5.15],[2,3.55,3]],"ltp":2.48,"tv":1352.89,"id":9345630},{"batb":[[0,1.6,263.51],[1,1.59,225.11],[2,1.49,6]],"batl":[[0,1.65,332.05],[1,1.66,191.56],[2,1.77,6]],"ltp":1.64,"tv":6436.02,"id":9028621}]}]}
{"op":"mcm","clk":"4226298945","pt":1631448345114,"mc":[{"id":"1.187552454","rc":[{"batb":[[0,2.32,20],[1,2.28,4],[2,2.18,20.22]],"ltp":2.48,"tv":1352.89,"id":9345630}]}]}
{"op":"mcm","clk":"4226299062","pt":1631448345871,"mc":[{"id":"1.187552454","rc":[{"batl":[[0,2.98,2.75],[1,3,3],[2,3.3,5.15]],"ltp":2.48,"tv":1352.89,"id":9345630},{"batb":[[2,1.51,25.99]],"ltp":1.64,"tv":6436.02,"id":9028621}]}]}
{"op":"mcm","clk":"4226299356","pt":1631448347543,"mc":[{"id":"1.187552454","rc":[{"batb":[[1,2.28,21.32]],"ltp":2.48,"tv":1352.89,"id":9345630}]}]}
{"op":"mcm","clk":"4226299504","pt":1631448348327,"mc":[{"id":"1.187552454","rc":[{"batl":[[0,2.98,17.75]],"ltp":2.48,"tv":1352.89,"id":9345630},{"batl":[[0,1.64,34.64],[1,1.65,332.05],[2,1.66,191.56]],"ltp":1.64,"tv":6436.02,"id":9028621}]}]}
{"op":"mcm","clk":"4226299648","pt":1631448349030,"mc":[{"id":"1.187552454","rc":[{"batb":[[1,2.28,17.32]],"batl":[[0,2.98,2.75]],"ltp":2.48,"tv":1352.89,"id":9345630}]}]}
{"op":"mcm","clk":"4226300040","pt":1631448351252,"mc":[{"id":"1.187552454","rc":[{"batb":[[0,2.18,3.86],[1,1.8,11.86],[2,1.7,16.95]],"batl":[[0,3,3],[1,3.3,5.15],[2,3.55,3]],"ltp":2.48,"tv":1352.89,"id":9345630},{"batb":[[0,1.49,6],[1,1.48,6],[2,1.44,34.67]],"batl":[[0,1.84,15.78],[1,1.94,8.68],[2,2.12,662.18]],"ltp":1.64,"tv":6436.02,"id":9028621}]}]}
{"op":"mcm","clk":"4226300631","pt":1631448354566,"mc":[{"id":"1.187552454","rc":[{"batb":[[0,2.28,18.32],[1,2.18,20.22],[2,1.8,11.86]],"batl":[[0,2.98,2.75],[1,3,3],[2,3.3,2.15]],"ltp":2.48,"tv":1352.89,"id":9345630},{"batb":[[0,1.51,23.99],[1,1.5,339.99],[2,1.49,296.19]],"batl":[[0,1.78,23.5],[1,1.8,257.92],[2,1.82,284.32]],"ltp":1.64,"tv":6436.02,"id":9028621}]}]}
{"op":"mcm","clk":"4226300712","pt":1631448355055,"mc":[{"id":"1.187552454","rc":[{"batb":[[0,2.18,20.22],[1,1.8,11.86],[2,1.7,16.95]],"batl":[[0,2.96,3]],"ltp":2.48,"tv":1352.89,"id":9345630},{"batb":[[0,1.5,339.99],[1,1.49,296.19],[2,1.48,6]],"batl":[[0,1.6,10]],"ltp":1.64,"tv":6436.02,"id":9028621}]}]}
{"op":"mcm","clk":"4226301155","pt":1631448357485,"mc":[{"id":"1.187552454","rc":[{"batb":[[0,1.5,344.99],[1,1.49,290.19],[2,1.44,28.67]],"batl":[[0,1.54,3416.1],[1,1.6,10],[2,1.63,55.51]],"ltp":1.64,"tv":6436.02,"id":9028621}]}]}
{"op":"mcm","clk":"4226301312","pt":1631448358348,"mc":[{"id":"1.187552454","rc":[{"batb":[[0,2.28,17.32],[1,2.18,20.22],[2,1.8,11.86]],"batl":[[1,2.98,3],[2,3,3]],"ltp":2.48,"tv":1352.89,"id":9345630},{"batb":[[0,1.51,6],[1,1.5,344.99],[2,1.49,290.19]],"ltp":1.64,"tv":6436.02,"id":9028621}]}]}
{"op":"mcm","clk":"4226301683","pt":1631448360370,"mc":[{"id":"1.187552454","rc":[{"batl":[[1,1.63,55.51],[2,1.78,23.5]],"ltp":1.64,"tv":6436.02,"id":9028621}]}]}
{"op":"mcm","clk":"4226301779","pt":1631448360757,"mc":[{"id":"1.187552454","rc":[{"trd":[[1.54,736.32]],"batl":[[0,1.54,3137.21]],"ltp":1.54,"tv":6993.8,"id":9028621}],"tv":8346.7}]}
{"op":"mcm","clk":"4226302494","pt":1631448364574,"mc":[{"id":"1.187552454","rc":[{"batb":[[0,1.52,219.88],[1,1.51,6],[2,1.5,344.99]],"batl":[[1,1.58,731.06],[2,1.63,55.51]],"ltp":1.54,"tv":6993.8,"id":9028621}]}]}
{"op":"mcm","clk":"4226302624","pt":1631448365428,"mc":[{"id":"1.187552454","rc":[{"batl":[[1,2.98,5.75]],"ltp":2.48,"tv":1352.89,"id":9345630},{"batb":[[1,1.51,32.99]],"batl":[[2,1.59,431.29]],"ltp":1.54,"tv":6993.8,"id":9028621}]}]}
{"op":"mcm","clk":"4226302999","pt":1631448367330,"mc":[{"id":"1.187552454","rc":[{"batl":[[0,2.94,3],[2,3.3,2.15]],"ltp":2.48,"tv":1352.89,"id":9345630},{"batb":[[0,1.52,226.88]],"ltp":1.54,"tv":6993.8,"id":9028621}]}]}
{"op":"mcm","clk":"4226303184","pt":1631448368377,"mc":[{"id":"1.187552454","rc":[{"batl":[[1,1.59,431.29],[2,1.63,55.51]],"ltp":1.54,"tv":6993.8,"id":9028621}]}]}
{"op":"mcm","clk":"4226303231","pt":1631448368697,"mc":[{"id":"1.187552454","rc":[{"batl":[[1,1.78,23.5],[2,1.8,257.92]],"ltp":1.54,"tv":6993.8,"id":9028621}]}]}
{"op":"mcm","clk":"4226303871","pt":1631448372102,"mc":[{"id":"1.187552454","rc":[{"trd":[[1.52,17.08]],"batb":[[0,1.52,218.34],[1,1.51,26.99],[2,1.5,339.99]],"ltp":1.52,"tv":7010.88,"id":9028621}],"tv":8363.78}]}
{"op":"mcm","clk":"4226304049","pt":1631448373009,"mc":[{"id":"1.187552454","rc":[{"batb":[[2,1.44,28.67]],"batl":[[2,1.84,6.78]],"ltp":1.52,"tv":7010.88,"id":9028621}]}]}
{"op":"mcm","clk":"4226304315","pt":1631448374506,"mc":[{"id":"1.187552454","rc":[{"batl":[[0,2.98,2.75],[1,3.3,2.15],[2,3.3,0]],"ltp":2.48,"tv":1352.89,"id":9345630},{"batb":[[0,1.52,211.34]],"ltp":1.52,"tv":7010.88,"id":9028621}]}]}
{"op":"mcm","clk":"4226304510","pt":1631448375584,"mc":[{"id":"1.187552454","rc":[{"batb":[[0,2.8,9.38],[1,2.28,17.32],[2,2.18,20.22]],"ltp":2.48,"tv":1352.89,"id":9345630},{"batl":[[1,1.55,5.7],[2,1.78,23.5]],"ltp":1.52,"tv":7010.88,"id":9028621}]}]}
{"op":"mcm","clk":"4226304666","pt":1631448376484,"mc":[{"id":"1.187552454","rc":[{"batb":[[1,2.64,4],[2,2.18,3.86]],"ltp":2.48,"tv":1352.89,"id":9345630},{"batb":[[2,1.5,339.99]],"batl":[[0,1.54,257.04],[1,1.55,251.45],[2,1.61,6]],"ltp":1.52,"tv":7010.88,"id":9028621}]}]}
{"op":"mcm","clk":"4226304793","pt":1631448377181,"mc":[{"id":"1.187552454","rc":[{"trd":[[1.52,30.86]],"batb":[[0,1.52,204.45]],"ltp":1.52,"tv":7024.65,"id":9028621}],"tv":8377.55}]}
{"op":"mcm","clk":"4226305015","pt":1631448378532,"mc":[{"id":"1.187552454","rc":[{"batl":[[0,1.54,299.54]],"ltp":1.52,"tv":7024.65,"id":9028621}]}]}
{"op":"mcm","clk":"4226305179","pt":1631448379499,"mc":[{"id":"1.187552454","rc":[{"batl":[[0,3.3,2.15],[1,3.3,0]],"ltp":2.48,"tv":1352.89,"id":9345630},{"batb":[[0,1.5,339.99],[1,1.49,290.19],[2,1.44,28.67]],"batl":[[0,1.54,257.04]],"ltp":1.52,"tv":7024.65,"id":9028621}]}]}
{"op":"mcm","clk":"4226305325","pt":1631448380414,"mc":[{"id":"1.187552454","rc":[{"batl":[[1,3.35,59.37]],"ltp":2.48,"tv":1352.89,"id":9345630},{"trd":[[1.5,645.84]],"batb":[[0,1.5,307]],"ltp":1.5,"tv":7090.63,"id":9028621}],"tv":8443.53}]}
{"op":"mcm","clk":"4226305537","pt":1631448381595,"mc":[{"id":"1.187552454","rc":[{"batb":[[0,2.84,3],[1,2.82,3],[2,2.8,9.38]],"batl":[[1,3.35,0]],"ltp":2.48,"tv":1352.89,"id":9345630},{"batl":[[2,1.57,84.55]],"ltp":1.5,"tv":7090.63,"id":9028621}]}]}
{"op":"mcm","clk":"4226305671","pt":1631448382437,"mc":[{"id":"1.187552454","rc":[{"batb":[[0,2.82,3],[1,2.8,9.38],[2,2.64,4]],"batl":[[0,3.25,10.75],[1,3.3,2.15]],"ltp":2.48,"tv":1352.89,"id":9345630},{"batb":[[0,1.5,511.45]],"ltp":1.5,"tv":7090.63,"id":9028621}]}]}
{"op":"mcm","clk":"4226305749","pt":1631448382800,"mc":[{"id":"1.187552454","rc":[{"batl":[[2,3.8,2]],"ltp":2.48,"tv":1352.89,"id":9345630},{"batl":[[0,1.53,42.5],[1,1.54,257.04],[2,1.55,251.45]],"ltp":1.5,"tv":7090.63,"id":9028621}]}]}
{"op":"mcm","clk":"4226306231","pt":1631448385499,"mc":[{"id":"1.187552454","rc":[{"batb":[[0,2.84,15],[1,2.82,3],[2,2.8,9.38]],"batl":[[0,3.3,2.15],[1,3.8,2],[2,4.6,2]],"ltp":2.48,"tv":1352.89,"id":9345630},{"batl":[[0,1.52,83.34],[1,1.53,42.5],[2,1.54,257.04]],"ltp":1.5,"tv":7090.63,"id":9028621}]}]}
{"op":"mcm","clk":"4226306385","pt":1631448386413,"mc":[{"id":"1.187552454","rc":[{"batl":[[2,4.5,2]],"ltp":2.48,"tv":1352.89,"id":9345630}]}]}
{"op":"mcm","clk":"4226306570","pt":1631448387393,"mc":[{"id":"1.187552454","rc":[{"batb":[[0,2.82,3],[1,2.8,9.38],[2,2.48,15.52]],"batl":[[0,4.5,2],[1,4.6,2],[2,4.5,0]],"ltp":2.48,"tv":1352.89,"id":9345630},{"batb":[[0,1.5,204.45],[1,1.29,39.81],[2,1.28,51.16]],"batl":[[1,1.55,5.7],[2,1.57,84.55]],"ltp":1.5,"tv":7090.63,"id":9028621}]}]}
{"op":"mcm","clk":"4226306744","pt":1631448388525,"mc":[{"id":"1.187552454","rc":[{"batl":[[0,3.9,2],[1,4.5,2],[2,4.6,2]],"ltp":2.48,"tv":1352.89,"id":9345630},{"trd":[[1.5,665.84]],"batb":[[0,1.5,194.45],[1,1.35,37.67],[2,1.29,39.81]],"ltp":1.5,"tv":7110.64,"id":9028621}],"tv":8463.53}]}
{"op":"mcm","clk":"4226306828","pt":1631448389007,"mc":[{"id":"1.187552454","rc":[{"batb":[[0,2.8,9.38],[1,2.48,15.52],[2,2.34,16.44]],"ltp":2.48,"tv":1352.89,"id":9345630}]}]}
{"op":"mcm","clk":"4226307069","pt":1631448390425,"mc":[{"id":"1.187552454","rc":[{"batl":[[0,3.8,2],[1,3.9,2],[2,4.5,2]],"ltp":2.48,"tv":1352.89,"id":9345630},{"batb":[[1,1.37,565.86],[2,1.36,471.98]],"ltp":1.5,"tv":7110.64,"id":9028621}]}]}
{"op":"mcm","clk":"4226307462","pt":1631448392638,"mc":[{"id":"1.187552454","rc":[{"batl":[[0,1.55,5.7],[1,1.57,84.55],[2,1.67,288.12]],"ltp":1.5,"tv":7110.64,"id":9028621}]}]}
{"op":"mcm","clk":"4226307685","pt":1631448393840,"mc":[{"id":"1.187552454","rc":[{"batb":[[0,1.37,565.86],[1,1.36,471.98],[2,1.35,37.67]],"ltp":1.5,"tv":7110.64,"id":9028621}]}]}
{"op":"mcm","clk":"4226307979","pt":1631448395714,"mc":[{"id":"1.187552454","rc":[{"batl":[[0,1.5,83.34],[1,1.55,5.7],[2,1.57,84.55]],"ltp":1.5,"tv":7110.64,"id":9028621}]}]}
{"op":"mcm","clk":"4226308299","pt":1631448397444,"mc":[{"id":"1.187552454","rc":[{"batl":[[0,3.75,3],[1,3.8,2],[2,3.9,2]],"ltp":2.48,"tv":1352.89,"id":9345630},{"batb":[[0,1.37,570.86],[1,1.36,477.98]],"batl":[[0,1.5,152.23]],"ltp":1.5,"tv":7110.64,"id":9028621}]}]}
{"op":"mcm","clk":"4226308614","pt":1631448399114,"mc":[{"id":"1.187552454","rc":[{"batl":[[0,1.5,156.13]],"ltp":1.5,"tv":7110.64,"id":9028621}]}]}
{"op":"mcm","clk":"4226308852","pt":1631448400562,"mc":[{"id":"1.187552454","rc":[{"batl":[[0,1.5,72.79]],"ltp":1.5,"tv":7110.64,"id":9028621}]}]}
{"op":"mcm","clk":"4226308992","pt":1631448401472,"mc":[{"id":"1.187552454","rc":[{"batl":[[0,1.5,3.9]],"ltp":1.5,"tv":7110.64,"id":9028621}]}]}
{"op":"mcm","clk":"4226309289","pt":1631448402977,"mc":[{"id":"1.187552454","rc":[{"batb":[[0,2.48,15.52],[1,2.34,16.44],[2,2.32,18.53]],"ltp":2.48,"tv":1352.89,"id":9345630},{"batl":[[1,1.57,84.55],[2,1.67,288.12]],"ltp":1.5,"tv":7110.64,"id":9028621}]}]}
{"op":"mcm","clk":"4226309644","pt":1631448405186,"mc":[{"id":"1.187552454","rc":[{"batl":[[0,1.57,84.55],[1,1.67,288.12],[2,1.69,362.9]],"ltp":1.5,"tv":7110.64,"id":9028621}]}]}
{"op":"mcm","clk":"4226309893","pt":1631448406575,"mc":[{"id":"1.187552454","rc":[{"batb":[[0,2.48,12.51]],"ltp":2.48,"tv":1352.89,"id":9345630},{"batl":[[0,1.44,731.06],[1,1.57,84.55],[2,1.67,7.5]],"ltp":1.5,"tv":7110.64,"id":9028621}]}]}
{"op":"mcm","clk":"4226310038","pt":1631448407486,"mc":[{"id":"1.187552454","rc":[{"batl":[[0,1.41,3950.12],[1,1.44,731.06],[2,1.45,431.29]],"ltp":1.5,"tv":7110.64,"id":9028621}]}]}
{"op":"mcm","clk":"4226310065","pt":1631448407659,"mc":[{"id":"1.187552454","rc":[{"batl":[[0,1.44,731.06],[1,1.45,431.29],[2,1.57,84.55]],"ltp":1.5,"tv":7110.64,"id":9028621}]}]}
{"op":"mcm","clk":"4226310352","pt":1631448409456,"mc":[{"id":"1.187552454","rc":[{"batb":[[0,3.4,3],[1,2.48,12.51],[2,2.34,16.44]],"batl":[[0,3.8,2],[1,3.9,2],[2,4.5,2]],"ltp":2.48,"tv":1352.89,"id":9345630},{"batb":[[0,1.37,565.86],[1,1.36,471.98]],"batl":[[0,1.41,477.42],[1,1.42,354.59],[2,1.44,731.06]],"ltp":1.5,"tv":7110.64,"id":9028621}]}]}
{"op":"mcm","clk":"4226310441","pt":1631448409992,"mc":[{"id":"1.187552454","rc":[{"batb":[[1,2.54,1177.63],[2,2.48,12.51]],"ltp":2.48,"tv":1352.89,"id":9345630}]}]}
{"op":"mcm","clk":"4226310850","pt":1631448412354,"mc":[{"id":"1.187552454","rc":[{"batb":[[1,3.3,3],[2,3.25,3]],"ltp":2.48,"tv":1352.89,"id":9345630},{"trd":[[1.37,190.65]],"batb":[[0,1.37,482.52]],"batl":[[2,1.67,7.5]],"ltp":1.37,"tv":7277.32,"id":9028621}],"tv":8630.22}]}
{"op":"mcm","clk":"4226311165","pt":1631448414276,"mc":[{"id":"1.187552454","rc":[{"batb":[[0,3.45,62.55],[1,3.4,3],[2,3.3,3]],"ltp":2.48,"tv":1352.89,"id":9345630},{"trd":[[1.37,291.15]],"batb":[[0,1.37,432.27]],"batl":[[0,1.4,101.69],[1,1.41,477.42],[2,1.42,354.59]],"ltp":1.37,"tv":7377.82,"id":9028621}],"tv":8730.72}]}
{"op":"mcm","clk":"4226311406","pt":1631448415570,"mc":[{"id":"1.187552454","rc":[{"batb":[[0,3.45,15]],"ltp":2.48,"tv":1352.89,"id":9345630},{"batb":[[0,1.37,479.36]],"batl":[[0,1.4,41.34]],"ltp":1.37,"tv":7377.82,"id":9028621}]}]}
{"op":"mcm","clk":"4226311524","pt":1631448416162,"mc":[{"id":"1.187552454","rc":[{"batl":[[2,4.1,2]],"ltp":2.48,"tv":1352.89,"id":9345630}]}]}
{"op":"mcm","clk":"4226311714","pt":1631448417354,"mc":[{"id":"1.187552454","rc":[{"trd":[[1.37,295.15]],"batb":[[0,1.37,477.36]],"batl":[[1,1.41,532.09]],"ltp":1.37,"tv":7381.82,"id":9028621}],"tv":8734.72}]}
{"op":"mcm","clk":"4226312187","pt":1631448419986,"mc":[{"id":"1.187552454","rc":[{"trd":[[1.37,570.69]],"batb":[[0,1.37,339.59]],"ltp":1.37,"tv":7657.36,"id":9028621}],"tv":9010.26}]}
{"op":"mcm","clk":"4226312443","pt":1631448421482,"mc":[{"id":"1.187552454","rc":[{"batl":[[1,1.41,362.4],[2,1.42,7]],"ltp":1.37,"tv":7657.36,"id":9028621}]}]}
{"op":"mcm","clk":"4226312665","pt":1631448422500,"mc":[{"id":"1.187552454","rc":[{"batl":[[0,1.39,29.02],[1,1.4,41.34],[2,1.41,362.4]],"ltp":1.37,"tv":7657.36,"id":9028621}]}]}
{"op":"mcm","clk":"4226312975","pt":1631448424303,"mc":[{"id":"1.187552454","rc":[{"batb":[[0,1.37,445.35]],"ltp":1.37,"tv":7657.36,"id":9028621}]}]}
{"op":"mcm","clk":"4226313294","pt":1631448426010,"mc":[{"id":"1.187552454","rc":[{"batl":[[0,3.8,12],[2,3.95,2]],"ltp":2.48,"tv":1352.89,"id":9345630}]}]}
{"op":"mcm","clk":"4226313441","pt":1631448426828,"mc":[{"id":"1.187552454","rc":[{"batl":[[2,1.41,559.15]],"ltp":1.37,"tv":7657.36,"id":9028621}]}]}
{"op":"mcm","clk":"4226314410","pt":1631448432516,"mc":[{"id":"1.187552454","rc":[{"trd":[[3.55,13.29]],"ltp":3.55,"tv":1362.89,"id":9345630},{"trd":[[1.39,196.89]],"batl":[[0,1.39,3.48]],"ltp":1.39,"tv":7682.9,"id":9028621}],"tv":9045.8}]}
{"op":"mcm","clk":"4226315097","pt":1631448436089,"mc":[{"id":"1.187552454","rc":[{"batb":[[0,1.38,427.02],[1,1.37,445.35],[2,1.36,471.98]],"ltp":1.39,"tv":7682.9,"id":9028621}]}]}
{"op":"mcm","clk":"4226316506","pt":1631448444712,"mc":[{"id":"1.187552454","rc":[{"trd":[[3.65,23]],"ltp":3.65,"tv":1364.89,"id":9345630},{"trd":[[1.38,6.14]],"batb":[[0,1.38,421.74]],"ltp":1.38,"tv":7688.19,"id":9028621}],"tv":9053.08}]}
{"op":"mcm","clk":"4226316988","pt":1631448447448,"mc":[{"id":"1.187552454","rc":[{"batb":[[0,3.3,3],[1,2.96,2.38],[2,2.48,12.51]],"batl":[[0,3.9,2],[1,3.95,2],[2,4.1,2]],"ltp":3.65,"tv":1364.89,"id":9345630},{"batb":[[1,1.35,37.67],[2,1.34,37.22]],"batl":[[1,1.64,33.04],[2,1.67,7.5]],"ltp":1.38,"tv":7688.19,"id":9028621}]}]}
{"op":"mcm","clk":"4226317357","pt":1631448449554,"mc":[{"id":"1.187552454","rc":[{"batl":[[1,1.47,361.19],[2,1.48,293.93]],"ltp":1.38,"tv":7688.19,"id":9028621}]}]}
{"op":"mcm","clk":"4226317517","pt":1631448450527,"mc":[{"id":"1.187552454","rc":[{"batb":[[0,3.1,2.04]],"ltp":3.65,"tv":1364.89,"id":9345630},{"batl":[[1,1.47,389.69]],"ltp":1.38,"tv":7688.19,"id":9028621}]}]}
{"op":"mcm","clk":"4226317953","pt":1631448453031,"mc":[{"id":"1.187552454","rc":[{"batb":[[0,3.1,5.04],[1,3.05,2],[2,2.96,2.38]],"ltp":3.65,"tv":1364.89,"id":9345630}]}]}
{"op":"mcm","clk":"4226318154","pt":1631448454167,"mc":[{"id":"1.187552454","rc":[{"batb":[[0,3.1,3]],"ltp":3.65,"tv":1364.89,"id":9345630},{"batl":[[1,1.51,22.5],[2,1.52,6.89]],"ltp":1.38,"tv":7688.19,"id":9028621}]}]}
{"op":"mcm","clk":"4226318302","pt":1631448454967,"mc":[{"id":"1.187552454","rc":[{"batl":[[0,4.1,2],[1,4.2,2],[2,4.5,2]],"ltp":3.65,"tv":1364.89,"id":9345630},{"batb":[[0,1.33,582.26],[1,1.32,547.95],[2,1.29,39.81]],"ltp":1.38,"tv":7688.19,"id":9028621}]}]}
{"op":"mcm","clk":"4226318576","pt":1631448456434,"mc":[{"id":"1.187552454","rc":[{"batl":[[0,1.36,431.29],[1,1.38,731.06],[2,1.39,3.48]],"ltp":1.38,"tv":7688.19,"id":9028621}]}]}
{"op":"mcm","clk":"4226318776","pt":1631448457568,"mc":[{"id":"1.187552454","rc":[{"batb":[[0,3.9,3],[1,3.1,3],[2,3.05,2]],"ltp":3.65,"tv":1364.89,"id":9345630},{"batl":[[0,1.36,733.81],[1,1.37,411.88],[2,1.38,731.06]],"ltp":1.38,"tv":7688.19,"id":9028621}]}]}
{"op":"mcm","clk":"4226318962","pt":1631448458533,"mc":[{"id":"1.187552454","rc":[{"trd":[[3.9,4.62]],"batb":[[0,3.35,15]],"ltp":3.9,"tv":1369.51,"id":9345630},{"trd":[[1.35,4.82]],"batl":[[2,1.38,748.46]],"ltp":1.35,"tv":7692.19,"id":9028621}],"tv":9061.7}]}
{"op":"mcm","clk":"4226319048","pt":1631448459057,"mc":[{"id":"1.187552454","rc":[{"batl":[[1,1.37,418.77],[2,1.38,731.06]],"ltp":1.35,"tv":7692.19,"id":9028621}]}]}
{"op":"mcm","clk":"4226319307","pt":1631448460567,"mc":[{"id":"1.187552454","rc":[{"batl":[[1,1.37,411.88],[2,1.38,30]],"ltp":1.35,"tv":7692.19,"id":9028621}]}]}
{"op":"mcm","clk":"4226319490","pt":1631448461540,"mc":[{"id":"1.187552454","rc":[{"trd":[[1.33,137.9]],"batb":[[0,1.33,543.01]],"ltp":1.33,"tv":7770.69,"id":9028621}],"tv":9140.2}]}
{"op":"mcm","clk":"4226319612","pt":1631448462140,"mc":[{"id":"1.187552454","rc":[{"batl":[[0,1.36,780.31]],"ltp":1.33,"tv":7770.69,"id":9028621}]}]}
{"op":"mcm","clk":"4226319841","pt":1631448463465,"mc":[{"id":"1.187552454","rc":[{"batb":[[0,3.55,2],[1,3.35,17],[2,3.1,3]],"batl":[[2,4.4,2]],"ltp":3.9,"tv":1369.51,"id":9345630},{"batb":[[2,1.3,43.08]],"ltp":1.33,"tv":7770.69,"id":9028621}]}]}
{"op":"mcm","clk":"4226320013","pt":1631448464422,"mc":[{"id":"1.187552454","rc":[{"batb":[[1,3.35,2]],"batl":[[2,4.3,2]],"ltp":3.9,"tv":1369.51,"id":9345630},{"batb":[[2,1.31,45.79]],"batl":[[0,1.35,6.89],[1,1.36,780.31],[2,1.37,411.88]],"ltp":1.33,"tv":7770.69,"id":9028621}]}]}
{"op":"mcm","clk":"4226320158","pt":1631448465364,"mc":[{"id":"1.187552454","rc":[{"batl":[[1,1.36,349.02]],"ltp":1.33,"tv":7770.69,"id":9028621}]}]}
{"op":"mcm","clk":"4226320413","pt":1631448466931,"mc":[{"id":"1.187552454","rc":[{"batb":[[0,3.6,15],[1,3.55,2],[2,3.35,2]],"ltp":3.9,"tv":1369.51,"id":9345630}]}]}
{"op":"mcm","clk":"4226320701","pt":1631448468451,"mc":[{"id":"1.187552454","rc":[{"batb":[[0,1.34,213.51],[1,1.33,543.01],[2,1.32,547.95]],"ltp":1.33,"tv":7770.69,"id":9028621}]}]}
{"op":"mcm","clk":"4226321040","pt":1631448470374,"mc":[{"id":"1.187552454","rc":[{"trd":[[1.34,22.05]],"batb":[[0,1.34,202.49]],"ltp":1.34,"tv":7792.73,"id":9028621}],"tv":9162.25}]}
{"op":"mcm","clk":"4226321539","pt":1631448473170,"mc":[{"id":"1.187552454","rc":[{"batl":[[0,1.36,349.02],[1,1.37,411.88],[2,1.38,30]],"ltp":1.34,"tv":7792.73,"id":9028621}]}]}
{"op":"mcm","clk":"4226322033","pt":1631448476148,"mc":[{"id":"1.187552454","rc":[{"batb":[[0,3.55,2],[1,3.35,2],[2,3.1,3]],"batl":[[0,4.2,2],[1,4.3,2],[2,4.4,2]],"ltp":3.9,"tv":1369.51,"id":9345630},{"batl":[[0,1.36,295.52],[2,1.39,33.5]],"ltp":1.34,"tv":7792.73,"id":9028621}]}]}
{"op":"mcm","clk":"4226322192","pt":1631448477162,"mc":[{"id":"1.187552454","rc":[{"batb":[[0,3.35,2],[1,3.1,3],[2,2.96,2.38]],"ltp":3.9,"tv":1369.51,"id":9345630},{"batb":[[1,1.32,39.89],[2,1.31,45.79]],"batl":[[0,1.42,30.25],[1,1.51,22.5],[2,1.64,33.04]],"ltp":1.34,"tv":7792.73,"id":9028621}]}]}
{"op":"mcm","clk":"4226322291","pt":1631448477647,"mc":[{"id":"1.187552454","rc":[{"batb":[[0,3.4,2.01],[1,3.35,2],[2,3.1,3]],"ltp":3.9,"tv":1369.51,"id":9345630},{"batl":[[0,1.41,32.5],[1,1.42,30.25],[2,1.51,22.5]],"ltp":1.34,"tv":7792.73,"id":9028621}]}]}
{"op":"mcm","clk":"4226322570","pt":1631448479165,"mc":[{"id":"1.187552454","rc":[{"trd":[[1.34,82.05]],"batb":[[0,1.34,172.48]],"ltp":1.34,"tv":7852.74,"id":9028621}],"tv":9222.25}]}
{"op":"mcm","clk":"4226322785","pt":1631448480375,"mc":[{"id":"1.187552454","rc":[{"batb":[[0,3.55,2],[1,3.4,2.01],[2,3.35,5]],"ltp":3.9,"tv":1369.51,"id":9345630},{"batl":[[0,1.39,33.5],[1,1.4,8],[2,1.41,32.5]],"ltp":1.34,"tv":7852.74,"id":9028621}]}]}
{"op":"mcm","clk":"4226322875","pt":1631448480862,"mc":[{"id":"1.187552454","rc":[{"batb":[[0,3.4,5.01],[1,3.35,5],[2,3.3,3]],"ltp":3.9,"tv":1369.51,"id":9345630},{"batl":[[0,1.4,8],[1,1.41,39.5],[2,1.42,570.82]],"ltp":1.34,"tv":7852.74,"id":9028621}]}]}
{"op":"mcm","clk":"4226323039","pt":1631448481890,"mc":[{"id":"1.187552454","rc":[{"batl":[[0,1.4,14.89]],"ltp":1.34,"tv":7852.74,"id":9028621}]}]}
{"op":"mcm","clk":"4226323506","pt":1631448484478,"mc":[{"id":"1.187552454","rc":[{"batb":[[0,3.4,2.01]],"ltp":3.9,"tv":1369.51,"id":9345630},{"batl":[[0,1.4,6.89],[1,1.41,32.5],[2,1.42,563.82]],"ltp":1.34,"tv":7852.74,"id":9028621}]}]}
{"op":"mcm","clk":"4226323676","pt":1631448485587,"mc":[{"id":"1.187552454","rc":[{"batb":[[0,1.38,7355.24],[1,1.37,431.29],[2,1.34,172.48]],"batl":[[0,1.41,32.5],[1,1.42,563.82],[2,1.43,337.57]],"ltp":1.34,"tv":7852.74,"id":9028621}]}]}
{"op":"mcm","clk":"4226323695","pt":1631448485705,"mc":[{"id":"1.187552454","rc":[{"batb":[[0,1.38,731.06]],"ltp":1.34,"tv":7852.74,"id":9028621}]}]}
{"op":"mcm","clk":"4226324002","pt":1631448487378,"mc":[{"id":"1.187552454","rc":[{"batl":[[0,3.9,6],[1,4.2,2],[2,4.3,2]],"ltp":3.9,"tv":1369.51,"id":9345630},{"batb":[[0,1.38,1191.5],[1,1.37,852.64],[2,1.35,9]],"ltp":1.34,"tv":7852.74,"id":9028621}]}]}
{"op":"mcm","clk":"4226324150","pt":1631448488329,"mc":[{"id":"1.187552454","rc":[{"batb":[[0,3.45,10.05],[1,3.4,2.01],[2,3.35,5]],"ltp":3.9,"tv":1369.51,"id":9345630},{"batb":[[0,1.38,460.44],[1,1.37,421.35]],"batl":[[0,1.41,72.08]],"ltp":1.34,"tv":7852.74,"id":9028621}]}]}
{"op":"mcm","clk":"4226324348","pt":1631448489524,"mc":[{"id":"1.187552454","rc":[{"batb":[[0,1.4,213.51],[1,1.38,460.44],[2,1.37,421.35]],"ltp":1.34,"tv":7852.74,"id":9028621}]}]}
{"op":"mcm","clk":"4226324672","pt":1631448491504,"mc":[{"id":"1.187552454","rc":[{"batl":[[0,3.85,25.56],[1,3.9,6],[2,4.2,2]],"ltp":3.9,"tv":1369.51,"id":9345630},{"trd":[[1.4,11.44]],"batb":[[0,1.4,211.46]],"ltp":1.4,"tv":7856.83,"id":9028621}],"tv":9226.35}]}
{"op":"mcm","clk":"4226325051","pt":1631448493828,"mc":[{"id":"1.187552454","rc":[{"batl":[[2,3.95,2]],"ltp":3.9,"tv":1369.51,"id":9345630}]}]}
{"op":"mcm","clk":"4226326871","pt":1631448504859,"mc":[{"id":"1.187552454","rc":[{"batl":[[0,3.9,6],[1,3.95,2],[2,4.2,2]],"ltp":3.9,"tv":1369.51,"id":9345630}]}]}
{"op":"mcm","clk":"4226327151","pt":1631448506458,"mc":[{"id":"1.187552454","rc":[{"batb":[[0,1.39,213.51]],"ltp":1.4,"tv":7856.83,"id":9028621}]}]}
{"op":"mcm","clk":"4226327283","pt":1631448507158,"mc":[{"id":"1.187552454","rc":[{"batb":[[0,3.4,2.01],[1,3.35,2],[2,3.3,3]],"ltp":3.9,"tv":1369.51,"id":9345630},{"batl":[[0,1.4,5],[1,1.41,32.5],[2,1.42,563.82]],"ltp":1.4,"tv":7856.83,"id":9028621}]}]}
{"op":"mcm","clk":"4226327500","pt":1631448508429,"mc":[{"id":"1.187552454","rc":[{"batb":[[0,3.3,3],[1,3.05,2.09],[2,2.96,2.38]],"ltp":3.9,"tv":1369.51,"id":9345630},{"batl":[[1,1.42,533.57],[2,1.43,337.57]],"ltp":1.4,"tv":7856.83,"id":9028621}]}]}
{"op":"mcm","clk":"4226327602","pt":1631448509066,"mc":[{"id":"1.187552454","rc":[{"batb":[[0,3.05,2.09],[1,2.96,2.38],[2,2.92,2.44]],"batl":[[0,3.95,2],[1,4.2,2],[2,4.3,2]],"ltp":3.9,"tv":1369.51,"id":9345630},{"batb":[[1,1.34,36.72],[2,1.32,39.89]],"batl":[[1,1.48,27.99],[2,1.51,22.5]],"ltp":1.4,"tv":7856.83,"id":9028621}]}]}
{"op":"mcm","clk":"4226327810","pt":1631448510349,"mc":[{"id":"1.187552454","rc":[{"batb":[[0,3.4,10.05]],"ltp":3.9,"tv":1369.51,"id":9345630},{"batl":[[1,1.51,22.5],[2,1.52,28.51]],"ltp":1.4,"tv":7856.83,"id":9028621}]}]}
{"op":"mcm","clk":"4226327872","pt":1631448510696,"mc":[{"id":"1.187552454","rc":[{"batb":[[0,2.96,2.38],[1,2.92,2.44],[2,2.48,12.51]],"ltp":3.9,"tv":1369.51,"id":9345630}]}]}
{"op":"mcm","clk":"4226328101","pt":1631448511969,"mc":[{"id":"1.187552454","rc":[{"batb":[[2,1.33,656.59]],"batl":[[0,1.49,269.95],[1,1.5,279.18],[2,1.51,22.5]],"ltp":1.4,"tv":7856.83,"id":9028621}]}]}
{"op":"mcm","clk":"4226328345","pt":1631448513475,"mc":[{"id":"1.187552454","rc":[{"batb":[[0,3.05,2.29],[1,2.96,2.38],[2,2.92,2.44]],"ltp":3.9,"tv":1369.51,"id":9345630},{"batl":[[0,1.48,27.24],[1,1.49,269.95],[2,1.5,279.18]],"ltp":1.4,"tv":7856.83,"id":9028621}]}]}
{"op":"mcm","clk":"4226328413","pt":1631448513858,"mc":[{"id":"1.187552454","rc":[{"batb":[[0,2.96,2.38],[1,2.92,2.44],[2,2.48,12.51]],"ltp":3.9,"tv":1369.51,"id":9345630},{"batl":[[0,1.49,269.95],[1,1.5,279.18],[2,1.51,22.5]],"ltp":1.4,"tv":7856.83,"id":9028621}]}]}
{"op":"mcm","clk":"4226328649","pt":1631448515153,"mc":[{"id":"1.187552454","rc":[{"batb":[[0,3,3],[1,2.98,3],[2,2.96,2.38]],"ltp":3.9,"tv":1369.51,"id":9345630},{"trd":[[1.39,206.89]],"batb":[[0,1.39,208.51]],"batl":[[0,1.49,275.95]],"ltp":1.39,"tv":7866.83,"id":9028621}],"tv":9236.35}]}
{"op":"mcm","clk":"4226329025","pt":1631448517360,"mc":[{"id":"1.187552454","rc":[{"batb":[[0,3.05,3],[1,3,3],[2,2.98,3]],"ltp":3.9,"tv":1369.51,"id":9345630},{"batb":[[0,1.45,7779.37],[1,1.42,731.06],[2,1.39,208.51]],"batl":[[0,1.48,6],[1,1.49,275.95],[2,1.5,279.18]],"ltp":1.39,"tv":7866.83,"id":9028621}]}]}
{"op":"mcm","clk":"4226329609","pt":1631448520565,"mc":[{"id":"1.187552454","rc":[{"batb":[[0,3.05,5.09]],"ltp":3.9,"tv":1369.51,"id":9345630},{"trd":[[1.45,189.19]],"batb":[[0,1.45,7689.76],[1,1.39,208.51],[2,1.34,36.72]],"batl":[[0,1.48,29.49]],"ltp":1.45,"tv":8046.06,"id":9028621}],"tv":9415.58}]}
{"op":"mcm","clk":"4226329717","pt":1631448521157,"mc":[{"id":"1.187552454","rc":[{"batb":[[0,3.05,3]],"ltp":3.9,"tv":1369.51,"id":9345630},{"trd":[[1.45,746.97]],"batb":[[0,1.45,7410.87]],"batl":[[0,1.48,6]],"ltp":1.45,"tv":8603.84,"id":9028621}],"tv":9973.36}]}
{"op":"mcm","clk":"4226330095","pt":1631448523491,"mc":[{"id":"1.187552454","rc":[{"batb":[[0,1.45,7348.08]],"ltp":1.45,"tv":8603.84,"id":9028621}]}]}
{"op":"mcm","clk":"4226330421","pt":1631448525577,"mc":[{"id":"1.187552454","rc":[{"trd":[[1.45,2826.63]],"batb":[[0,1.45,6308.25]],"ltp":1.45,"tv":10683.5,"id":9028621}],"tv":12053.02}]}
{"op":"mcm","clk":"4226330773","pt":1631448527484,"mc":[{"id":"1.187552454","rc":[{"batb":[[0,3.05,5.09]],"ltp":3.9,"tv":1369.51,"id":9345630},{"batl":[[0,1.48,30.74]],"ltp":1.45,"tv":10683.5,"id":9028621}]}]}
{"op":"mcm","clk":"4226330827","pt":1631448527820,"mc":[{"id":"1.187552454","rc":[{"batb":[[0,3.05,3],[1,2.96,2.38],[2,2.92,2.44]],"ltp":3.9,"tv":1369.51,"id":9345630},{"batl":[[0,1.48,6]],"ltp":1.45,"tv":10683.5,"id":9028621}]}]}
