{"info": {"id": "1.187552449", "eventId": "30895261", "eventName": "Match Odds", "marketType": "MATCH_ODDS", "openDate": 1631448049395, "name": "W Falkowska v M Sequeira", "numberOfActiveRunner": 2, "countryCode": "", "sport": "TENNIS", "venue": "", "volume": {"total": 12753.2, "preMatch": 423.67, "inPlay": 12329.53}, "winner": {"id": 13310360, "name": "W Falkowska", "status": "WINNER", "position": 1}, "delay": 5}, "runners": [{"id": 13310360, "name": "W Falkowska", "status": "WINNER", "position": 1, "inPlayOdds": 1.01, "inPlayTime": 1631448049395, "avgPrematch": 1.01, "closedOdds": 1.02, "maxPrematch": 1.01, "minPrematch": 1.01, "maxInPlay": 1.03, "minInPlay": 1.01, "inPlayIndex": 6, "lengthOdds": 123, "lengthOddsPrematch": 6, "lengthOddsInPlay": 117, "tradedVolume": 12663.28, "preMatchVolume": 411.71, "inPlayVolume": 12251.57}, {"id": 40084547, "name": "M Sequeira", "status": "LOSER", "position": 2, "inPlayOdds": 100.0, "inPlayTime": 1631448657885, "avgPrematch": 0, "closedOdds": 70.0, "maxPrematch": -100, "minPrematch": 1001, "maxInPlay": 100.0, "minInPlay": 50.0, "inPlayIndex": 0, "lengthOdds": 37, "lengthOddsPrematch": 0, "lengthOddsInPlay": 37, "tradedVolume": 89.92, "preMatchVolume": 11.96, "inPlayVolume": 77.96}], "marketUpdates": [{"timestamp": 1631440798116000000, "openDate": "2021-09-12T12:00:00.000Z", "status": "OPEN", "betDelay": 0, "inPlay": false, "complete": true}, {"timestamp": 1631448049395000000, "openDate": "2021-09-12T12:00:00.000Z", "status": "OPEN", "betDelay": 5, "inPlay": true, "complete": true}, {"timestamp": 1631448900833000000, "openDate": "2021-09-12T12:14:57.000Z", "status": "OPEN", "betDelay": 5, "inPlay": true, "complete": true}, {"timestamp": 1631455844831000000, "openDate": "2021-09-12T12:14:57.000Z", "status": "SUSPENDED", "betDelay": 5, "inPlay": true, "complete": true}, {"timestamp": 1631455849838000000, "openDate": "2021-09-12T12:14:57.000Z", "status": "CLOSED", "betDelay": 5, "inPlay": true, "complete": true}], "odds": [{"runnerId": 13310360, "odds": [{"timestamp": 1631444783161, "ltp": 1.01, "tv": 23.99, "trd": [[1.01, 24]], "batb": NaN, "batl": [[0, 1.01, 2188.56], [1, 1.02, 4644.29], [2, 5, 44.41]]}, {"timestamp": 1631444797944, "ltp": 1.01, "tv": 23.99, "trd": NaN, "batb": NaN, "batl": [[2, 1.1, 43.98]]}, {"timestamp": 1631445530030, "ltp": 1.01, "tv": 194.8, "trd": [[1.01, 194.81]], "batb": NaN, "batl": [[0, 1.01, 2103.15]]}, {"timestamp": 1631445819378, "ltp": 1.01, "tv": 411.71, "trd": [[1.01, 411.72]], "batb": NaN, "batl": [[0, 1.01, 1994.7]]}, {"timestamp": 1631446881414, "ltp": 1.01, "tv": 411.71, "trd": NaN, "batb": NaN, "batl": [[1, 1.02, 3416.18]]}, {"timestamp": 1631447650947, "ltp": 1.01, "tv": 411.71, "trd": NaN, "batb": NaN, "batl": [[0, 1.01, 1994.69]]}, {"timestamp": 1631448049395, "ltp": 1.01, "tv": 411.71, "trd": NaN, "batb": NaN, "batl": [[0, 1.02, 3416.18], [1, 1.02, 0], [2, 1.1, 0]]}, {"timestamp": 1631448495116, "ltp": 1.01, "tv": 411.71, "trd": NaN, "batb": NaN, "batl": [[0, 1.01, 1400.82], [1, 1.02, 3416.18]]}, {"timestamp": 1631448642287, "ltp": 1.01, "tv": 845.52, "trd": [[1.01, 845.53]], "batb": NaN, "batl": [[0, 1.01, 1183.91]]}, {"timestamp": 1631448657885, "ltp": 1.01, "tv": 2029.43, "trd": [[1.01, 2029.44]], "batb": NaN, "batl": [[0, 1.02, 3416.18], [1, 1.02, 0]]}, {"timestamp": 1631448663083, "ltp": 1.01, "tv": 2029.43, "trd": NaN, "batb": NaN, "batl": [[1, 11.5, 8.68]]}, {"timestamp": 1631448730710, "ltp": 1.01, "tv": 2029.43, "trd": NaN, "batb": [[0, 1.01, 817.65]], "batl": NaN}, {"timestamp": 1631448761949, "ltp": 1.02, "tv": 3480.9, "trd": [[1.02, 1451.47]], "batb": NaN, "batl": [[0, 1.02, 1964.7]]}, {"timestamp": 1631448816116, "ltp": 1.01, "tv": 4382.77, "trd": [[1.01, 2931.31]], "batb": [[0, 1.01, 366.72]], "batl": NaN}, {"timestamp": 1631448885600, "ltp": 1.02, "tv": 4431.78, "trd": [[1.02, 1500.48]], "batb": NaN, "batl": [[0, 1.02, 1940.2]]}, {"timestamp": 1631449068243, "ltp": 1.02, "tv": 4431.78, "trd": NaN, "batb": NaN, "batl": [[1, 11, 42.7], [2, 11.5, 8.68]]}, {"timestamp": 1631449117723, "ltp": 1.02, "tv": 5167.74, "trd": [[1.02, 2236.44]], "batb": NaN, "batl": [[0, 1.02, 1572.22]]}, {"timestamp": 1631449155216, "ltp": 1.02, "tv": 5167.74, "trd": NaN, "batb": NaN, "batl": [[1, 1.3, 1269.21], [2, 11, 42.7]]}, {"timestamp": 1631449325631, "ltp": 1.01, "tv": 5601.55, "trd": [[1.01, 3365.11]], "batb": [[0, 1.01, 149.81]], "batl": NaN}, {"timestamp": 1631449408904, "ltp": 1.01, "tv": 5601.55, "trd": NaN, "batb": [[0, 1.01, 4126.99]], "batl": NaN}, {"timestamp": 1631449425497, "ltp": 1.01, "tv": 5601.55, "trd": NaN, "batb": [[0, 1.01, 149.81]], "batl": NaN}, {"timestamp": 1631449558436, "ltp": 1.01, "tv": 5601.55, "trd": NaN, "batb": NaN, "batl": [[1, 11, 42.7], [2, 11.5, 8.68]]}, {"timestamp": 1631449634819, "ltp": 1.01, "tv": 5601.55, "trd": NaN, "batb": [[0, 1.01, 4314.59]], "batl": NaN}, {"timestamp": 1631449635130, "ltp": 1.01, "tv": 5601.55, "trd": NaN, "batb": NaN, "batl": [[1, 1.32, 1173.52], [2, 11, 42.7]]}, {"timestamp": 1631449650676, "ltp": 1.01, "tv": 5601.55, "trd": NaN, "batb": [[0, 1.01, 149.81]], "batl": NaN}, {"timestamp": 1631449656139, "ltp": 1.01, "tv": 5601.55, "trd": NaN, "batb": [[0, 1.01, 4126.99]], "batl": NaN}, {"timestamp": 1631449680431, "ltp": 1.01, "tv": 5601.55, "trd": NaN, "batb": [[0, 1.01, 149.81]], "batl": NaN}, {"timestamp": 1631449686650, "ltp": 1.01, "tv": 5601.55, "trd": NaN, "batb": [[0, 1.01, 4314.59]], "batl": NaN}, {"timestamp": 1631449703760, "ltp": 1.01, "tv": 5601.55, "trd": NaN, "batb": [[0, 1.01, 149.81]], "batl": NaN}, {"timestamp": 1631449710001, "ltp": 1.01, "tv": 5601.55, "trd": NaN, "batb": [[0, 1.01, 4126.99]], "batl": NaN}, {"timestamp": 1631449776363, "ltp": 1.01, "tv": 5601.55, "trd": NaN, "batb": [[0, 1.01, 149.81]], "batl": NaN}, {"timestamp": 1631449782553, "ltp": 1.02, "tv": 9162.51, "trd": [[1.02, 5797.4]], "batb": NaN, "batl": [[0, 1.32, 1173.52], [1, 11, 42.7], [2, 11.5, 8.68]]}, {"timestamp": 1631449805520, "ltp": 1.02, "tv": 9162.51, "trd": NaN, "batb": [[0, 1.01, 1700.77]], "batl": NaN}, {"timestamp": 1631449823412, "ltp": 1.02, "tv": 9162.51, "trd": NaN, "batb": NaN, "batl": [[0, 1.09, 142.31], [1, 1.32, 1173.52], [2, 11, 42.7]]}, {"timestamp": 1631449850124, "ltp": 1.02, "tv": 9162.51, "trd": NaN, "batb": [[0, 1.01, 149.81]], "batl": NaN}, {"timestamp": 1631449992823, "ltp": 1.02, "tv": 9162.51, "trd": NaN, "batb": NaN, "batl": [[0, 1.02, 1029.24], [1, 1.09, 142.31], [2, 1.32, 1173.52]]}, {"timestamp": 1631450052007, "ltp": 1.02, "tv": 9162.51, "trd": NaN, "batb": NaN, "batl": [[2, 11, 42.7]]}, {"timestamp": 1631450057883, "ltp": 1.02, "tv": 9162.51, "trd": NaN, "batb": NaN, "batl": [[2, 1.27, 2975.92]]}, {"timestamp": 1631450134953, "ltp": 1.01, "tv": 9426.75, "trd": [[1.01, 3629.35]], "batb": [[0, 1.01, 17.69]], "batl": NaN}, {"timestamp": 1631450223284, "ltp": 1.02, "tv": 11426.75, "trd": [[1.02, 7797.4]], "batb": NaN, "batl": [[0, 1.02, 29.24]]}, {"timestamp": 1631450237701, "ltp": 1.02, "tv": 11426.75, "trd": NaN, "batb": [[0, 1.01, 1244.18]], "batl": NaN}, {"timestamp": 1631450421298, "ltp": 1.01, "tv": 11460.91, "trd": [[1.01, 3663.52]], "batb": [[0, 1.01, 1227.09]], "batl": NaN}, {"timestamp": 1631450534267, "ltp": 1.01, "tv": 11460.91, "trd": NaN, "batb": NaN, "batl": [[2, 11, 42.7]]}, {"timestamp": 1631450573733, "ltp": 1.01, "tv": 11460.91, "trd": NaN, "batb": [[0, 1.01, 0.61]], "batl": NaN}, {"timestamp": 1631450626957, "ltp": 1.01, "tv": 11460.91, "trd": NaN, "batb": NaN, "batl": [[1, 1.06, 75.13], [2, 1.09, 142.31]]}, {"timestamp": 1631450723815, "ltp": 1.01, "tv": 11460.91, "trd": NaN, "batb": [[0, 1.01, 1104.56]], "batl": NaN}, {"timestamp": 1631450840348, "ltp": 1.01, "tv": 11460.91, "trd": NaN, "batb": NaN, "batl": [[1, 1.09, 142.31], [2, 1.28, 2941.83]]}, {"timestamp": 1631450845415, "ltp": 1.01, "tv": 11460.91, "trd": NaN, "batb": NaN, "batl": [[1, 1.05, 75.13], [2, 1.09, 142.31]]}, {"timestamp": 1631450909698, "ltp": 1.01, "tv": 11460.91, "trd": NaN, "batb": NaN, "batl": [[0, 1.05, 75.13], [1, 1.09, 142.31], [2, 1.28, 2941.83]]}, {"timestamp": 1631450968700, "ltp": 1.02, "tv": 11946.64, "trd": [[1.02, 8283.13]], "batb": NaN, "batl": NaN}, {"timestamp": 1631450987131, "ltp": 1.02, "tv": 11946.64, "trd": NaN, "batb": NaN, "batl": [[0, 1.09, 142.31], [1, 1.28, 2941.83], [2, 11, 42.7]]}, {"timestamp": 1631450992406, "ltp": 1.02, "tv": 11946.64, "trd": NaN, "batb": NaN, "batl": [[0, 1.04, 75.13], [1, 1.09, 142.31], [2, 1.28, 2941.83]]}, {"timestamp": 1631451015367, "ltp": 1.02, "tv": 11946.64, "trd": NaN, "batb": [[0, 1.01, 1825]], "batl": NaN}, {"timestamp": 1631451038319, "ltp": 1.02, "tv": 11946.64, "trd": NaN, "batb": [[0, 1.01, 1104.56]], "batl": NaN}, {"timestamp": 1631451044456, "ltp": 1.02, "tv": 11946.64, "trd": NaN, "batb": [[0, 1.01, 2655.51]], "batl": NaN}, {"timestamp": 1631451061648, "ltp": 1.02, "tv": 11946.64, "trd": NaN, "batb": [[0, 1.01, 1104.56]], "batl": NaN}, {"timestamp": 1631451094309, "ltp": 1.02, "tv": 11946.64, "trd": NaN, "batb": [[0, 1.01, 1825]], "batl": NaN}, {"timestamp": 1631451130855, "ltp": 1.02, "tv": 11946.64, "trd": NaN, "batb": [[0, 1.01, 1104.56]], "batl": [[2, 11, 42.7]]}, {"timestamp": 1631451144770, "ltp": 1.02, "tv": 11946.64, "trd": NaN, "batb": NaN, "batl": [[2, 1.3, 2786.44]]}, {"timestamp": 1631451151957, "ltp": 1.02, "tv": 11946.64, "trd": NaN, "batb": NaN, "batl": [[0, 1.04, 247.83]]}, {"timestamp": 1631451160405, "ltp": 1.02, "tv": 11946.64, "trd": NaN, "batb": NaN, "batl": [[2, 11, 42.7]]}, {"timestamp": 1631451172406, "ltp": 1.02, "tv": 11946.64, "trd": NaN, "batb": NaN, "batl": [[2, 1.3, 2814.45]]}, {"timestamp": 1631451454900, "ltp": 1.02, "tv": 11946.64, "trd": NaN, "batb": NaN, "batl": [[2, 11, 42.7]]}, {"timestamp": 1631451483161, "ltp": 1.02, "tv": 11946.64, "trd": NaN, "batb": NaN, "batl": [[2, 1.28, 2892.45]]}, {"timestamp": 1631451502796, "ltp": 1.02, "tv": 11946.64, "trd": NaN, "batb": NaN, "batl": [[2, 11, 42.7]]}, {"timestamp": 1631451516745, "ltp": 1.02, "tv": 11946.64, "trd": NaN, "batb": NaN, "batl": [[2, 1.3, 2786.44]]}, {"timestamp": 1631451523544, "ltp": 1.02, "tv": 11946.64, "trd": NaN, "batb": NaN, "batl": [[0, 1.09, 142.31], [1, 1.3, 2786.44], [2, 11, 42.7]]}, {"timestamp": 1631451528638, "ltp": 1.02, "tv": 11946.64, "trd": NaN, "batb": NaN, "batl": [[0, 1.03, 247.83], [1, 1.09, 142.31], [2, 1.3, 2786.44]]}, {"timestamp": 1631451544051, "ltp": 1.02, "tv": 11946.64, "trd": NaN, "batb": [[0, 1.01, 2655.51]], "batl": NaN}, {"timestamp": 1631451553668, "ltp": 1.02, "tv": 11946.64, "trd": NaN, "batb": [[0, 1.01, 1104.56]], "batl": NaN}, {"timestamp": 1631451606629, "ltp": 1.03, "tv": 12112.48, "trd": [[1.03, 165.84]], "batb": NaN, "batl": [[0, 1.03, 164.92]]}, {"timestamp": 1631451612942, "ltp": 1.03, "tv": 12442.31, "trd": [[1.03, 495.67]], "batb": [[0, 1.03, 83.47], [1, 1.01, 1104.56]], "batl": [[0, 1.09, 142.31], [1, 1.3, 2786.44], [2, 11, 42.7]]}, {"timestamp": 1631451618437, "ltp": 1.03, "tv": 12609.26, "trd": [[1.03, 662.61]], "batb": [[0, 1.01, 1104.56], [1, 1.01, 0]], "batl": [[0, 1.03, 22.88], [1, 1.09, 142.31], [2, 1.3, 2786.44]]}, {"timestamp": 1631451623561, "ltp": 1.03, "tv": 12655.01, "trd": [[1.03, 708.37]], "batb": NaN, "batl": [[0, 1.09, 142.31], [1, 1.3, 2786.44], [2, 11, 42.7]]}, {"timestamp": 1631451678789, "ltp": 1.03, "tv": 12655.01, "trd": NaN, "batb": NaN, "batl": [[0, 1.08, 73.6], [1, 1.09, 142.31], [2, 1.3, 2786.44]]}, {"timestamp": 1631451686744, "ltp": 1.03, "tv": 12655.01, "trd": NaN, "batb": [[0, 1.01, 1825]], "batl": NaN}, {"timestamp": 1631451729739, "ltp": 1.03, "tv": 12655.01, "trd": NaN, "batb": [[0, 1.01, 1104.56]], "batl": NaN}, {"timestamp": 1631452030249, "ltp": 1.03, "tv": 12655.01, "trd": NaN, "batb": [[0, 1.01, 1825]], "batl": NaN}, {"timestamp": 1631452048058, "ltp": 1.03, "tv": 12655.01, "trd": NaN, "batb": [[0, 1.01, 1104.56]], "batl": NaN}, {"timestamp": 1631452077888, "ltp": 1.03, "tv": 12655.01, "trd": NaN, "batb": NaN, "batl": [[2, 11, 42.7]]}, {"timestamp": 1631452080691, "ltp": 1.03, "tv": 12655.01, "trd": NaN, "batb": NaN, "batl": [[0, 1.03, 70.98], [1, 1.08, 73.6], [2, 1.09, 142.31]]}, {"timestamp": 1631452093797, "ltp": 1.03, "tv": 12655.01, "trd": NaN, "batb": [[0, 1.01, 1825]], "batl": NaN}, {"timestamp": 1631452116346, "ltp": 1.03, "tv": 12655.01, "trd": NaN, "batb": NaN, "batl": [[0, 1.08, 73.6], [1, 1.09, 142.31], [2, 11, 42.7]]}, {"timestamp": 1631452119955, "ltp": 1.03, "tv": 12655.01, "trd": NaN, "batb": [[0, 1.01, 1104.56]], "batl": NaN}, {"timestamp": 1631452121436, "ltp": 1.03, "tv": 12655.01, "trd": NaN, "batb": NaN, "batl": [[0, 1.04, 70.98], [1, 1.08, 73.6], [2, 1.09, 142.31]]}, {"timestamp": 1631452131767, "ltp": 1.03, "tv": 12655.01, "trd": NaN, "batb": NaN, "batl": [[0, 1.04, 243.69]]}, {"timestamp": 1631452250671, "ltp": 1.03, "tv": 12655.01, "trd": NaN, "batb": NaN, "batl": [[1, 1.09, 142.31], [2, 1.28, 2941.83]]}, {"timestamp": 1631452251989, "ltp": 1.03, "tv": 12655.01, "trd": NaN, "batb": NaN, "batl": [[0, 1.09, 142.31], [1, 1.28, 2941.83], [2, 11, 42.7]]}, {"timestamp": 1631452257075, "ltp": 1.03, "tv": 12655.01, "trd": NaN, "batb": NaN, "batl": [[0, 1.02, 243.69], [1, 1.09, 142.31], [2, 1.28, 2941.83]]}, {"timestamp": 1631452262624, "ltp": 1.03, "tv": 12655.01, "trd": NaN, "batb": NaN, "batl": [[0, 1.09, 142.31], [1, 1.28, 2941.83], [2, 11, 42.7]]}, {"timestamp": 1631452267722, "ltp": 1.03, "tv": 12655.01, "trd": NaN, "batb": NaN, "batl": [[0, 1.03, 243.69], [1, 1.09, 142.31], [2, 1.28, 2941.83]]}, {"timestamp": 1631452304716, "ltp": 1.03, "tv": 12655.01, "trd": NaN, "batb": NaN, "batl": [[2, 11, 42.7]]}, {"timestamp": 1631452562855, "ltp": 1.03, "tv": 12655.01, "trd": NaN, "batb": NaN, "batl": [[2, 1.27, 2975.92]]}, {"timestamp": 1631452615642, "ltp": 1.03, "tv": 12655.01, "trd": NaN, "batb": NaN, "batl": [[0, 1.09, 142.31], [1, 1.27, 2975.92], [2, 11, 42.7]]}, {"timestamp": 1631452620716, "ltp": 1.03, "tv": 12655.01, "trd": NaN, "batb": NaN, "batl": [[0, 1.02, 243.69], [1, 1.09, 142.31], [2, 1.27, 2975.92]]}, {"timestamp": 1631452766825, "ltp": 1.03, "tv": 12655.01, "trd": NaN, "batb": [[0, 1.01, 1108.69]], "batl": NaN}, {"timestamp": 1631452795415, "ltp": 1.03, "tv": 12655.01, "trd": NaN, "batb": [[0, 1.01, 1104.56]], "batl": NaN}, {"timestamp": 1631452808361, "ltp": 1.02, "tv": 12663.28, "trd": [[1.02, 8291.4]], "batb": NaN, "batl": [[0, 1.02, 239.55]]}, {"timestamp": 1631452838705, "ltp": 1.02, "tv": 12663.28, "trd": NaN, "batb": [[0, 1.01, 0.61]], "batl": NaN}, {"timestamp": 1631452852004, "ltp": 1.02, "tv": 12663.28, "trd": NaN, "batb": NaN, "batl": [[1, 1.04, 3.86], [2, 1.09, 142.31]]}, {"timestamp": 1631452859213, "ltp": 1.02, "tv": 12663.28, "trd": NaN, "batb": NaN, "batl": [[2, 1.08, 291.23]]}, {"timestamp": 1631452904582, "ltp": 1.02, "tv": 12663.28, "trd": NaN, "batb": NaN, "batl": [[1, 1.08, 291.23], [2, 1.09, 142.31]]}, {"timestamp": 1631452931646, "ltp": 1.02, "tv": 12663.28, "trd": NaN, "batb": NaN, "batl": [[1, 1.04, 3.86], [2, 1.08, 291.23]]}, {"timestamp": 1631453333020, "ltp": 1.02, "tv": 12663.28, "trd": NaN, "batb": NaN, "batl": [[1, 1.08, 291.23], [2, 1.09, 142.31]]}, {"timestamp": 1631454469705, "ltp": 1.02, "tv": 12663.28, "trd": NaN, "batb": NaN, "batl": [[0, 1.01, 837.38], [1, 1.02, 239.55], [2, 1.08, 291.23]]}, {"timestamp": 1631454506458, "ltp": 1.02, "tv": 12663.28, "trd": NaN, "batb": NaN, "batl": [[0, 1.02, 239.55], [1, 1.08, 291.23], [2, 1.09, 142.31]]}, {"timestamp": 1631455252999, "ltp": 1.02, "tv": 12663.28, "trd": NaN, "batb": [[0, 1.01, 720.45]], "batl": NaN}, {"timestamp": 1631455299444, "ltp": 1.02, "tv": 12663.28, "trd": NaN, "batb": NaN, "batl": [[1, 1.09, 142.31], [2, 1.32, 2690.33]]}, {"timestamp": 1631455459515, "ltp": 1.02, "tv": 12663.28, "trd": NaN, "batb": NaN, "batl": [[2, 11, 42.7]]}, {"timestamp": 1631455485152, "ltp": 1.02, "tv": 12663.28, "trd": NaN, "batb": NaN, "batl": [[2, 1.3, 2786.44]]}, {"timestamp": 1631455502985, "ltp": 1.02, "tv": 12663.28, "trd": NaN, "batb": NaN, "batl": [[2, 11, 42.7]]}, {"timestamp": 1631455519276, "ltp": 1.02, "tv": 12663.28, "trd": NaN, "batb": NaN, "batl": [[2, 1.28, 2892.45]]}, {"timestamp": 1631455535315, "ltp": 1.02, "tv": 12663.28, "trd": NaN, "batb": NaN, "batl": [[0, 1.09, 142.31], [1, 1.28, 2892.45], [2, 11, 42.7]]}, {"timestamp": 1631455540393, "ltp": 1.02, "tv": 12663.28, "trd": NaN, "batb": NaN, "batl": [[0, 1.03, 239.55], [1, 1.09, 142.31], [2, 1.28, 2892.45]]}, {"timestamp": 1631455613207, "ltp": 1.02, "tv": 12663.28, "trd": NaN, "batb": NaN, "batl": [[2, 11, 42.7]]}, {"timestamp": 1631455629353, "ltp": 1.02, "tv": 12663.28, "trd": NaN, "batb": NaN, "batl": [[2, 1.27, 2975.92]]}, {"timestamp": 1631455637483, "ltp": 1.02, "tv": 12663.28, "trd": NaN, "batb": NaN, "batl": [[2, 11, 42.7]]}, {"timestamp": 1631455663601, "ltp": 1.02, "tv": 12663.28, "trd": NaN, "batb": NaN, "batl": [[2, 1.27, 2999.57]]}, {"timestamp": 1631455674796, "ltp": 1.02, "tv": 12663.28, "trd": NaN, "batb": NaN, "batl": [[2, 11, 42.7]]}, {"timestamp": 1631455750234, "ltp": 1.02, "tv": 12663.28, "trd": NaN, "batb": NaN, "batl": [[2, 1.27, 2975.92]]}, {"timestamp": 1631455761677, "ltp": 1.02, "tv": 12663.28, "trd": NaN, "batb": NaN, "batl": [[2, 11, 42.7]]}, {"timestamp": 1631455816647, "ltp": 1.02, "tv": 12663.28, "trd": NaN, "batb": NaN, "batl": [[0, 11, 42.7], [1, 11.5, 8.68], [2, 11, 0]]}, {"timestamp": 1631455821954, "ltp": 1.02, "tv": 12663.28, "trd": NaN, "batb": NaN, "batl": [[0, 10.5, 2.89], [1, 11, 42.7], [2, 11.5, 8.68]]}]}, {"runnerId": 40084547, "odds": [{"timestamp": 1631448657885, "ltp": 100.0, "tv": 11.96, "trd": [[100, 11.96]], "batb": NaN, "batl": [[0, 100, 29.61]]}, {"timestamp": 1631448761949, "ltp": 50.0, "tv": 41.57, "trd": [[50, 29.61]], "batb": NaN, "batl": NaN}, {"timestamp": 1631448806987, "ltp": 50.0, "tv": 41.57, "trd": NaN, "batb": [[0, 70, 7.08], [1, 1.01, 12]], "batl": NaN}, {"timestamp": 1631448906062, "ltp": 70.0, "tv": 55.73, "trd": [[70, 14.16]], "batb": [[0, 1.01, 12], [1, 1.01, 0]], "batl": [[0, 70, 10.07]]}, {"timestamp": 1631448921475, "ltp": 70.0, "tv": 75.76, "trd": [[70, 34.2]], "batb": NaN, "batl": [[0, 70, 0.05]]}, {"timestamp": 1631448932310, "ltp": 70.0, "tv": 75.76, "trd": NaN, "batb": [[0, 55, 10.54], [1, 1.01, 12]], "batl": NaN}, {"timestamp": 1631449142723, "ltp": 70.0, "tv": 75.76, "trd": NaN, "batb": [[0, 55, 7.08]], "batl": NaN}, {"timestamp": 1631449155216, "ltp": 70.0, "tv": 75.76, "trd": NaN, "batb": NaN, "batl": [[0, 340, 36.48]]}, {"timestamp": 1631449261627, "ltp": 70.0, "tv": 75.76, "trd": NaN, "batb": [[0, 1.01, 12], [1, 1.01, 0]], "batl": NaN}, {"timestamp": 1631449266776, "ltp": 70.0, "tv": 75.76, "trd": NaN, "batb": [[0, 60, 7.08], [1, 1.01, 12]], "batl": NaN}, {"timestamp": 1631449385774, "ltp": 70.0, "tv": 75.76, "trd": NaN, "batb": NaN, "batl": [[0, 170, 37.59]]}, {"timestamp": 1631449431204, "ltp": 70.0, "tv": 75.76, "trd": NaN, "batb": NaN, "batl": [[0, 170, 37.59]]}, {"timestamp": 1631449494439, "ltp": 70.0, "tv": 75.76, "trd": NaN, "batb": NaN, "batl": [[0, 340, 36.48]]}, {"timestamp": 1631449524668, "ltp": 70.0, "tv": 75.76, "trd": NaN, "batb": NaN, "batl": [[0, 170, 37.59]]}, {"timestamp": 1631449782553, "ltp": 60.0, "tv": 82.84, "trd": [[60, 7.08]], "batb": [[0, 1.01, 12], [1, 1.01, 0]], "batl": NaN}, {"timestamp": 1631449806121, "ltp": 60.0, "tv": 82.84, "trd": NaN, "batb": [[0, 36, 12.26], [1, 1.01, 12]], "batl": NaN}, {"timestamp": 1631449813234, "ltp": 60.0, "tv": 82.84, "trd": NaN, "batb": [[0, 36, 7.08]], "batl": NaN}, {"timestamp": 1631449856323, "ltp": 60.0, "tv": 82.84, "trd": NaN, "batb": NaN, "batl": [[0, 170, 25.31]]}, {"timestamp": 1631450089513, "ltp": 60.0, "tv": 82.84, "trd": NaN, "batb": [[0, 1.01, 12], [1, 1.01, 0]], "batl": NaN}, {"timestamp": 1631450094630, "ltp": 60.0, "tv": 82.84, "trd": NaN, "batb": [[0, 55, 7.08], [1, 1.01, 12]], "batl": NaN}, {"timestamp": 1631450600981, "ltp": 60.0, "tv": 82.84, "trd": NaN, "batb": [[0, 1.01, 12], [1, 1.01, 0]], "batl": NaN}, {"timestamp": 1631450606108, "ltp": 60.0, "tv": 82.84, "trd": NaN, "batb": [[0, 70, 7.08], [1, 1.01, 12]], "batl": NaN}, {"timestamp": 1631450925048, "ltp": 60.0, "tv": 82.84, "trd": NaN, "batb": NaN, "batl": [[0, 340, 30.35]]}, {"timestamp": 1631450959466, "ltp": 60.0, "tv": 82.84, "trd": NaN, "batb": NaN, "batl": [[0, 170, 25.31]]}, {"timestamp": 1631450968700, "ltp": 70.0, "tv": 89.92, "trd": [[70, 41.28]], "batb": [[0, 1.01, 12], [1, 1.01, 0]], "batl": NaN}, {"timestamp": 1631451144770, "ltp": 70.0, "tv": 89.92, "trd": NaN, "batb": NaN, "batl": [[0, 170, 25.31]]}, {"timestamp": 1631451172406, "ltp": 70.0, "tv": 89.92, "trd": NaN, "batb": NaN, "batl": [[0, 340, 30.35]]}, {"timestamp": 1631451516745, "ltp": 70.0, "tv": 89.92, "trd": NaN, "batb": NaN, "batl": [[0, 170, 25.31]]}, {"timestamp": 1631451735383, "ltp": 70.0, "tv": 89.92, "trd": NaN, "batb": NaN, "batl": [[0, 170, 25.31]]}, {"timestamp": 1631451907156, "ltp": 70.0, "tv": 89.92, "trd": NaN, "batb": NaN, "batl": [[0, 340, 30.35]]}, {"timestamp": 1631452010829, "ltp": 70.0, "tv": 89.92, "trd": NaN, "batb": NaN, "batl": [[0, 170, 25.31]]}, {"timestamp": 1631452054499, "ltp": 70.0, "tv": 89.92, "trd": NaN, "batb": NaN, "batl": [[0, 340, 30.35]]}, {"timestamp": 1631452166504, "ltp": 70.0, "tv": 89.92, "trd": NaN, "batb": NaN, "batl": [[0, 170, 25.31]]}, {"timestamp": 1631455081645, "ltp": 70.0, "tv": 89.92, "trd": NaN, "batb": NaN, "batl": [[0, 170, 25.31]]}, {"timestamp": 1631455303466, "ltp": 70.0, "tv": 89.92, "trd": NaN, "batb": NaN, "batl": [[0, 170, 25.31]]}, {"timestamp": 1631455485152, "ltp": 70.0, "tv": 89.92, "trd": NaN, "batb": NaN, "batl": [[0, 170, 25.31]]}, {"timestamp": 1631455830576, "ltp": 70.0, "tv": 89.92, "trd": NaN, "batb": [[0, 690, 2.07], [1, 1.01, 12]], "batl": NaN}]}]}