{"info": {"id": "1.187566733", "eventId": "30896763", "eventName": "Match Odds", "marketType": "MATCH_ODDS", "openDate": 1631552478297, "name": "Galarneau v Sarkissian", "numberOfActiveRunner": 2, "countryCode": "", "sport": "TENNIS", "venue": "", "volume": {"total": 368436.08, "preMatch": 7473.44, "inPlay": 360962.64}, "winner": {"id": 8734382, "name": "Alexander Sarkissian", "status": "WINNER", "position": 2}, "delay": 3}, "runners": [{"id": 9323645, "name": "Alexis Galarneau", "status": "LOSER", "position": 1, "inPlayOdds": 1.43, "inPlayTime": 1631552478297, "avgPrematch": 1.45, "closedOdds": 9.2, "maxPrematch": 1.5, "minPrematch": 1.41, "maxInPlay": 9.2, "minInPlay": 1.01, "inPlayIndex": 151, "lengthOdds": 4678, "lengthOddsPrematch": 151, "lengthOddsInPlay": 4527, "tradedVolume": 271677.84, "preMatchVolume": 7413.63, "inPlayVolume": 264264.21}, {"id": 8734382, "name": "Alexander Sarkissian", "status": "WINNER", "position": 2, "inPlayOdds": 3.3, "inPlayTime": 1631552478297, "avgPrematch": 3.02, "closedOdds": 1.13, "maxPrematch": 3.3, "minPrematch": 3.0, "maxInPlay": 21.0, "minInPlay": 1.1, "inPlayIndex": 150, "lengthOdds": 3509, "lengthOddsPrematch": 150, "lengthOddsInPlay": 3359, "tradedVolume": 96758.24, "preMatchVolume": 59.81, "inPlayVolume": 96698.43}], "marketUpdates": [{"timestamp": 1631484721383000000, "openDate": "2021-09-13T17:00:00.000Z", "status": "OPEN", "betDelay": 0, "inPlay": false, "complete": true}, {"timestamp": 1631545031107000000, "openDate": "2021-09-13T16:55:00.000Z", "status": "OPEN", "betDelay": 0, "inPlay": false, "complete": true}, {"timestamp": 1631551608105000000, "openDate": "2021-09-13T16:50:00.000Z", "status": "OPEN", "betDelay": 0, "inPlay": false, "complete": true}, {"timestamp": 1631551908772000000, "openDate": "2021-09-13T17:05:00.000Z", "status": "OPEN", "betDelay": 0, "inPlay": false, "complete": true}, {"timestamp": 1631552249614000000, "openDate": "2021-09-13T16:53:00.000Z", "status": "OPEN", "betDelay": 0, "inPlay": false, "complete": true}, {"timestamp": 1631552477962000000, "openDate": "2021-09-13T16:53:00.000Z", "status": "SUSPENDED", "betDelay": 0, "inPlay": false, "complete": true}, {"timestamp": 1631552478297000000, "openDate": "2021-09-13T16:53:00.000Z", "status": "OPEN", "betDelay": 3, "inPlay": true, "complete": true}, {"timestamp": 1631561885577000000, "openDate": "2021-09-13T16:53:00.000Z", "status": "SUSPENDED", "betDelay": 3, "inPlay": true, "complete": true}, {"timestamp": 1631561947855000000, "openDate": "2021-09-13T16:53:00.000Z", "status": "CLOSED", "betDelay": 3, "inPlay": true, "complete": true}], "odds": [{"runnerId": 9323645, "odds": [{"timestamp": 1631504865087, "ltp": 1.48, "tv": 48.66, "trd": [[1.48, 48.66]], "batb": [[0, 1.48, 7.88], [1, 1.12, 15.36], [2, 1.11, 43.76]], "batl": [[0, 1.59, 30.02], [1, 1.6, 65.23], [2, 990, 2.2]]}, {"timestamp": 1631504865292, "ltp": 1.48, "tv": 64.41, "trd": [[1.48, 64.42]], "batb": [[0, 1.12, 15.36], [1, 1.11, 43.76], [2, 1.1, 767.79]], "batl": NaN}, {"timestamp": 1631511638188, "ltp": 1.48, "tv": 64.38, "trd": [[1.48, 64.39]], "batb": [[0, 1.12, 15.36], [1, 1.11, 43.77], [2, 1.1, 767.85]], "batl": NaN}, {"timestamp": 1631517465632, "ltp": 1.48, "tv": 64.45, "trd": [[1.48, 64.45]], "batb": [[0, 1.12, 15.36], [1, 1.11, 43.78], [2, 1.1, 767.98]], "batl": [[0, 1.59, 30.03], [1, 1.6, 65.23]]}, {"timestamp": 1631521468797, "ltp": 1.48, "tv": 64.45, "trd": NaN, "batb": NaN, "batl": [[0, 1.58, 221.13], [1, 1.59, 30.03], [2, 1.6, 65.23]]}, {"timestamp": 1631525523027, "ltp": 1.48, "tv": 64.47, "trd": [[1.48, 64.48]], "batb": [[0, 1.12, 15.36], [1, 1.11, 43.78], [2, 1.1, 768.11]], "batl": [[0, 1.58, 221], [1, 1.59, 30.03], [2, 1.6, 65.23]]}, {"timestamp": 1631525658872, "ltp": 1.5, "tv": 73.1, "trd": [[1.5, 8.63]], "batb": NaN, "batl": [[0, 1.54, 21.4], [1, 1.58, 221]]}, {"timestamp": 1631525681204, "ltp": 1.5, "tv": 94.5, "trd": [[1.5, 30.03]], "batb": NaN, "batl": [[0, 1.58, 221], [1, 1.6, 65.23], [2, 1.66, 25]]}, {"timestamp": 1631525690515, "ltp": 1.5, "tv": 94.5, "trd": NaN, "batb": NaN, "batl": [[0, 1.58, 221.69], [1, 1.6, 64.54]]}, {"timestamp": 1631526695684, "ltp": 1.5, "tv": 94.5, "trd": NaN, "batb": [[1, 1.11, 37.55]], "batl": NaN}, {"timestamp": 1631531420858, "ltp": 1.5, "tv": 94.33, "trd": [[1.48, 64.36], [1.5, 29.97]], "batb": [[0, 1.5, 62.65], [1, 1.12, 15.33], [2, 1.11, 37.48]], "batl": [[0, 1.58, 221.48], [1, 1.6, 64.43]]}, {"timestamp": 1631531513997, "ltp": 1.5, "tv": 94.33, "trd": NaN, "batb": [[1, 1.11, 37.48], [2, 1.1, 766.61]], "batl": NaN}, {"timestamp": 1631531758837, "ltp": 1.5, "tv": 228.27, "trd": [[1.5, 163.91]], "batb": [[0, 1.11, 37.48], [1, 1.1, 766.61], [2, 1.04, 271.21]], "batl": [[0, 1.5, 1074.19], [1, 1.58, 221.48], [2, 1.6, 64.43]]}, {"timestamp": 1631531762065, "ltp": 1.5, "tv": 228.27, "trd": NaN, "batb": [[0, 1.42, 74.58], [1, 1.11, 37.48], [2, 1.1, 766.61]], "batl": NaN}, {"timestamp": 1631531772144, "ltp": 1.5, "tv": 228.27, "trd": NaN, "batb": NaN, "batl": [[0, 1.49, 1074.19]]}, {"timestamp": 1631532088112, "ltp": 1.5, "tv": 228.27, "trd": NaN, "batb": [[1, 1.17, 104.86], [2, 1.11, 37.48]], "batl": NaN}, {"timestamp": 1631532374607, "ltp": 1.49, "tv": 267.39, "trd": [[1.49, 39.12]], "batb": NaN, "batl": [[0, 1.49, 1054.63]]}, {"timestamp": 1631532440583, "ltp": 1.49, "tv": 267.39, "trd": NaN, "batb": [[0, 1.46, 21.29], [1, 1.42, 74.58], [2, 1.17, 104.86]], "batl": NaN}, {"timestamp": 1631532454502, "ltp": 1.49, "tv": 267.39, "trd": NaN, "batb": [[0, 1.42, 74.58], [1, 1.17, 104.86], [2, 1.11, 37.48]], "batl": NaN}, {"timestamp": 1631532544847, "ltp": 1.49, "tv": 298.89, "trd": [[1.49, 70.62]], "batb": NaN, "batl": [[0, 1.49, 1038.88]]}, {"timestamp": 1631532960674, "ltp": 1.49, "tv": 318.83, "trd": [[1.49, 90.56]], "batb": NaN, "batl": [[0, 1.49, 1028.9]]}, {"timestamp": 1631533181752, "ltp": 1.49, "tv": 318.83, "trd": NaN, "batb": [[0, 1.44, 71.19]], "batl": NaN}, {"timestamp": 1631533267977, "ltp": 1.49, "tv": 318.83, "trd": NaN, "batb": [[0, 1.45, 3.01], [1, 1.44, 71.19], [2, 1.17, 104.86]], "batl": NaN}, {"timestamp": 1631533655071, "ltp": 1.49, "tv": 318.83, "trd": NaN, "batb": NaN, "batl": [[0, 1.48, 1028.9]]}, {"timestamp": 1631534049912, "ltp": 1.48, "tv": 339.81, "trd": [[1.48, 85.34]], "batb": NaN, "batl": [[0, 1.48, 1018.41]]}, {"timestamp": 1631534136082, "ltp": 1.48, "tv": 380.91, "trd": [[1.48, 126.44]], "batb": NaN, "batl": [[0, 1.48, 997.86]]}, {"timestamp": 1631534308878, "ltp": 1.48, "tv": 427.53, "trd": [[1.48, 173.06]], "batb": NaN, "batl": [[0, 1.48, 974.55]]}, {"timestamp": 1631535937272, "ltp": 1.48, "tv": 550.82, "trd": [[1.48, 296.35]], "batb": NaN, "batl": [[0, 1.48, 912.9]]}, {"timestamp": 1631536049949, "ltp": 1.48, "tv": 653.57, "trd": [[1.48, 399.1]], "batb": NaN, "batl": [[0, 1.48, 861.53]]}, {"timestamp": 1631536161962, "ltp": 1.48, "tv": 694.67, "trd": [[1.48, 440.2]], "batb": NaN, "batl": [[0, 1.48, 840.97]]}, {"timestamp": 1631538224985, "ltp": 1.48, "tv": 694.67, "trd": [[1.48, 440.21], [1.49, 90.58], [1.5, 163.89]], "batb": [[2, 1.17, 104.78]], "batl": [[0, 1.48, 840.84], [1, 1.58, 221.33], [2, 1.6, 64.4]]}, {"timestamp": 1631540457424, "ltp": 1.48, "tv": 694.67, "trd": NaN, "batb": NaN, "batl": [[0, 1.46, 3.44], [1, 1.48, 840.84], [2, 1.58, 221.33]]}, {"timestamp": 1631540553281, "ltp": 1.48, "tv": 714.07, "trd": [[1.46, 6.87], [1.48, 452.74]], "batb": NaN, "batl": [[0, 1.48, 834.57], [1, 1.58, 221.33], [2, 1.6, 64.4]]}, {"timestamp": 1631541375711, "ltp": 1.45, "tv": 720.09, "trd": [[1.45, 6.02]], "batb": [[0, 1.44, 71.19], [1, 1.17, 104.78], [2, 1.15, 15.97]], "batl": NaN}, {"timestamp": 1631541393654, "ltp": 1.45, "tv": 720.09, "trd": NaN, "batb": NaN, "batl": [[0, 1.47, 3.06], [1, 1.48, 834.57], [2, 1.58, 221.33]]}, {"timestamp": 1631541730957, "ltp": 1.47, "tv": 740.77, "trd": [[1.47, 20.68]], "batb": NaN, "batl": [[0, 1.48, 834.57], [1, 1.58, 221.33], [2, 1.6, 64.4]]}, {"timestamp": 1631541746186, "ltp": 1.47, "tv": 740.77, "trd": NaN, "batb": [[0, 1.45, 6.01], [1, 1.44, 71.19], [2, 1.17, 104.78]], "batl": NaN}, {"timestamp": 1631541814153, "ltp": 1.48, "tv": 781.85, "trd": [[1.48, 493.81]], "batb": NaN, "batl": [[0, 1.48, 814.05]]}, {"timestamp": 1631542762942, "ltp": 1.48, "tv": 781.85, "trd": NaN, "batb": NaN, "batl": [[0, 1.47, 45], [1, 1.48, 814.05], [2, 1.58, 221.33]]}, {"timestamp": 1631542962100, "ltp": 1.47, "tv": 1097.05, "trd": [[1.47, 335.89]], "batb": NaN, "batl": [[0, 1.48, 814.05], [1, 1.58, 221.33], [2, 1.6, 64.4]]}, {"timestamp": 1631543101357, "ltp": 1.47, "tv": 1097.05, "trd": NaN, "batb": NaN, "batl": [[1, 1.53, 2.09], [2, 1.58, 221.33]]}, {"timestamp": 1631543423691, "ltp": 1.47, "tv": 1097.05, "trd": NaN, "batb": NaN, "batl": [[0, 1.47, 1485.75], [1, 1.48, 814.05], [2, 1.53, 2.09]]}, {"timestamp": 1631544172763, "ltp": 1.47, "tv": 1097.05, "trd": NaN, "batb": [[2, 1.22, 194.02]], "batl": NaN}, {"timestamp": 1631544339870, "ltp": 1.47, "tv": 1097.05, "trd": NaN, "batb": NaN, "batl": [[0, 1.46, 814.05], [1, 1.47, 1485.75]]}, {"timestamp": 1631544361508, "ltp": 1.46, "tv": 1200.43, "trd": [[1.46, 110.25]], "batb": NaN, "batl": [[0, 1.46, 762.39]]}, {"timestamp": 1631544526557, "ltp": 1.46, "tv": 1311.85, "trd": [[1.46, 221.67]], "batb": NaN, "batl": [[0, 1.46, 706.71]]}, {"timestamp": 1631544569915, "ltp": 1.46, "tv": 1318.54, "trd": [[1.46, 228.35]], "batb": NaN, "batl": [[0, 1.46, 703.37]]}, {"timestamp": 1631544570599, "ltp": 1.46, "tv": 1318.54, "trd": NaN, "batb": [[2, 1.35, 14.07]], "batl": [[0, 1.46, 720.39]]}, {"timestamp": 1631545050736, "ltp": 1.46, "tv": 1318.54, "trd": NaN, "batb": NaN, "batl": [[1, 1.53, 2.09], [2, 1.58, 221.33]]}, {"timestamp": 1631545072135, "ltp": 1.46, "tv": 1318.54, "trd": NaN, "batb": NaN, "batl": [[0, 1.46, 711.43]]}, {"timestamp": 1631545137721, "ltp": 1.46, "tv": 1318.54, "trd": NaN, "batb": [[1, 1.44, 94.92]], "batl": NaN}, {"timestamp": 1631545163852, "ltp": 1.45, "tv": 1330.56, "trd": [[1.45, 18.05]], "batb": [[0, 1.44, 94.92], [1, 1.35, 14.07], [2, 1.23, 85.68]], "batl": [[0, 1.45, 736.86], [1, 1.46, 711.43], [2, 1.53, 2.09]]}, {"timestamp": 1631545179373, "ltp": 1.45, "tv": 1330.56, "trd": NaN, "batb": NaN, "batl": [[1, 1.46, 703.37]]}, {"timestamp": 1631545235829, "ltp": 1.45, "tv": 1442.9, "trd": [[1.45, 129.52], [1.46, 228.49], [1.47, 336.16], [1.48, 494.09], [1.49, 90.63], [1.5, 164]], "batb": [[2, 1.23, 85.6]], "batl": [[0, 1.45, 680.28], [1, 1.46, 704.24]]}, {"timestamp": 1631545292112, "ltp": 1.45, "tv": 1442.9, "trd": NaN, "batb": [[1, 1.43, 8.53], [2, 1.35, 14.08]], "batl": NaN}, {"timestamp": 1631545325394, "ltp": 1.45, "tv": 1901.78, "trd": [[1.45, 588.41]], "batb": NaN, "batl": [[0, 1.45, 450.84]]}, {"timestamp": 1631545381089, "ltp": 1.45, "tv": 1901.78, "trd": NaN, "batb": [[2, 1.23, 85.6]], "batl": NaN}, {"timestamp": 1631545411804, "ltp": 1.45, "tv": 1901.78, "trd": NaN, "batb": [[2, 1.22, 193.8]], "batl": NaN}, {"timestamp": 1631545426827, "ltp": 1.45, "tv": 2803.46, "trd": [[1.45, 1490.08]], "batb": [[0, 1.45, 423.14], [1, 1.44, 94.92], [2, 1.43, 8.53]], "batl": [[0, 1.46, 704.24], [1, 1.53, 2.09], [2, 1.58, 221.08]]}, {"timestamp": 1631545451153, "ltp": 1.45, "tv": 2803.46, "trd": NaN, "batb": [[1, 1.44, 99.18]], "batl": NaN}, {"timestamp": 1631545495011, "ltp": 1.46, "tv": 2927.78, "trd": [[1.46, 352.81]], "batb": NaN, "batl": [[0, 1.46, 642.08]]}, {"timestamp": 1631546191965, "ltp": 1.45, "tv": 3774.06, "trd": [[1.45, 2336.36]], "batb": [[0, 1.44, 99.18], [1, 1.43, 8.53], [2, 1.22, 193.8]], "batl": [[0, 1.45, 723.57], [1, 1.46, 642.08], [2, 1.53, 2.09]]}, {"timestamp": 1631546195672, "ltp": 1.45, "tv": 3774.06, "trd": NaN, "batb": [[2, 1.35, 28.03]], "batl": NaN}, {"timestamp": 1631546288991, "ltp": 1.45, "tv": 3774.06, "trd": NaN, "batb": [[2, 1.23, 370.72]], "batl": NaN}, {"timestamp": 1631546458898, "ltp": 1.45, "tv": 3793.64, "trd": [[1.45, 2355.94]], "batb": NaN, "batl": [[0, 1.45, 713.78]]}, {"timestamp": 1631546647973, "ltp": 1.45, "tv": 3793.64, "trd": NaN, "batb": [[2, 1.25, 174.59]], "batl": NaN}, {"timestamp": 1631547923851, "ltp": 1.45, "tv": 4183.14, "trd": [[1.45, 2745.45]], "batb": NaN, "batl": [[0, 1.45, 519.03]]}, {"timestamp": 1631548145301, "ltp": 1.45, "tv": 4363.21, "trd": [[1.45, 2925.51]], "batb": NaN, "batl": [[0, 1.45, 428.99]]}, {"timestamp": 1631548226338, "ltp": 1.44, "tv": 4561.21, "trd": [[1.44, 198]], "batb": [[0, 1.43, 8.71], [1, 1.25, 174.59], [2, 1.23, 370.72]], "batl": NaN}, {"timestamp": 1631548229124, "ltp": 1.44, "tv": 4561.21, "trd": NaN, "batb": [[1, 1.36, 116.02], [2, 1.25, 174.59]], "batl": NaN}, {"timestamp": 1631548274360, "ltp": 1.44, "tv": 4561.21, "trd": NaN, "batb": NaN, "batl": [[0, 1.45, 458.98]]}, {"timestamp": 1631548285570, "ltp": 1.44, "tv": 4561.21, "trd": NaN, "batb": [[1, 1.37, 23.32], [2, 1.36, 116.02]], "batl": NaN}, {"timestamp": 1631548305420, "ltp": 1.44, "tv": 4561.21, "trd": NaN, "batb": [[0, 1.37, 23.5], [1, 1.36, 116.02], [2, 1.25, 174.59]], "batl": NaN}, {"timestamp": 1631548318238, "ltp": 1.44, "tv": 4561.21, "trd": NaN, "batb": [[0, 1.38, 4.44], [1, 1.37, 23.32], [2, 1.36, 116.02]], "batl": NaN}, {"timestamp": 1631548418453, "ltp": 1.44, "tv": 4561.21, "trd": NaN, "batb": [[0, 1.39, 39.42], [1, 1.38, 4.26], [2, 1.37, 23.32]], "batl": NaN}, {"timestamp": 1631548472120, "ltp": 1.44, "tv": 4561.21, "trd": NaN, "batb": [[2, 1.36, 116.02]], "batl": NaN}, {"timestamp": 1631548472219, "ltp": 1.44, "tv": 4561.21, "trd": NaN, "batb": [[0, 1.4, 23.5], [1, 1.39, 39.24], [2, 1.38, 4.26]], "batl": NaN}, {"timestamp": 1631548486146, "ltp": 1.44, "tv": 4561.21, "trd": NaN, "batb": [[1, 1.38, 4.26], [2, 1.36, 116.02]], "batl": NaN}, {"timestamp": 1631548488140, "ltp": 1.44, "tv": 4561.21, "trd": NaN, "batb": [[0, 1.41, 38.86], [1, 1.4, 23.32], [2, 1.38, 4.26]], "batl": NaN}, {"timestamp": 1631548500981, "ltp": 1.44, "tv": 4561.21, "trd": NaN, "batb": [[2, 1.38, 37.92]], "batl": NaN}, {"timestamp": 1631548541004, "ltp": 1.44, "tv": 4561.21, "trd": NaN, "batb": [[0, 1.42, 23.5], [1, 1.41, 38.68]], "batl": NaN}, {"timestamp": 1631548603102, "ltp": 1.45, "tv": 4765.29, "trd": [[1.45, 3129.59]], "batb": NaN, "batl": [[0, 1.45, 356.94]]}, {"timestamp": 1631548604012, "ltp": 1.45, "tv": 4765.29, "trd": NaN, "batb": [[0, 1.42, 61.89], [1, 1.38, 37.92], [2, 1.36, 116.02]], "batl": [[0, 1.45, 361.97]]}, {"timestamp": 1631548808708, "ltp": 1.45, "tv": 4765.29, "trd": NaN, "batb": [[1, 1.4, 48.01], [2, 1.38, 37.92]], "batl": NaN}, {"timestamp": 1631548835559, "ltp": 1.45, "tv": 4817.72, "trd": [[1.45, 3182.02]], "batb": NaN, "batl": [[0, 1.45, 335.76]]}, {"timestamp": 1631548980680, "ltp": 1.45, "tv": 4817.72, "trd": NaN, "batb": NaN, "batl": [[2, 1.53, 2.61]]}, {"timestamp": 1631549342961, "ltp": 1.45, "tv": 4817.72, "trd": NaN, "batb": [[1, 1.4, 50.11]], "batl": [[2, 1.47, 2]]}, {"timestamp": 1631549480641, "ltp": 1.45, "tv": 4998.47, "trd": [[1.45, 3362.78]], "batb": NaN, "batl": [[0, 1.45, 245.37]]}, {"timestamp": 1631549827661, "ltp": 1.45, "tv": 5088.76, "trd": [[1.45, 3453.06]], "batb": NaN, "batl": [[0, 1.45, 200.22]]}, {"timestamp": 1631549837459, "ltp": 1.44, "tv": 5089.12, "trd": [[1.44, 198.36]], "batb": [[0, 1.42, 61.71]], "batl": [[0, 1.44, 5.03], [1, 1.45, 200.22], [2, 1.46, 642.08]]}, {"timestamp": 1631549843692, "ltp": 1.44, "tv": 5089.12, "trd": NaN, "batb": NaN, "batl": [[1, 1.45, 170.24]]}, {"timestamp": 1631549935150, "ltp": 1.44, "tv": 5089.12, "trd": NaN, "batb": [[0, 1.43, 7.68], [1, 1.42, 61.71], [2, 1.4, 50.11]], "batl": NaN}, {"timestamp": 1631549953193, "ltp": 1.44, "tv": 5099.18, "trd": [[1.44, 208.42]], "batb": [[0, 1.44, 2.65]], "batl": [[0, 1.45, 165.21], [1, 1.46, 644.69], [2, 1.47, 2]]}, {"timestamp": 1631549953293, "ltp": 1.44, "tv": 5099.18, "trd": NaN, "batb": NaN, "batl": [[1, 1.46, 642.08], [2, 1.47, 4.61]]}, {"timestamp": 1631549961980, "ltp": 1.44, "tv": 5099.18, "trd": NaN, "batb": [[0, 1.43, 2.65]], "batl": NaN}, {"timestamp": 1631550120190, "ltp": 1.44, "tv": 5099.18, "trd": NaN, "batb": [[1, 1.42, 23.32]], "batl": NaN}, {"timestamp": 1631550127084, "ltp": 1.44, "tv": 5099.18, "trd": NaN, "batb": [[1, 1.41, 23.32]], "batl": NaN}, {"timestamp": 1631550153653, "ltp": 1.44, "tv": 5099.18, "trd": NaN, "batb": NaN, "batl": [[0, 1.44, 25.72], [1, 1.45, 167.39], [2, 1.46, 642.08]]}, {"timestamp": 1631550217835, "ltp": 1.44, "tv": 5102.59, "trd": [[1.44, 211.83]], "batb": NaN, "batl": [[0, 1.44, 24.02]]}, {"timestamp": 1631550230953, "ltp": 1.44, "tv": 5102.59, "trd": NaN, "batb": [[1, 1.41, 1.74]], "batl": NaN}, {"timestamp": 1631550265327, "ltp": 1.44, "tv": 5102.59, "trd": NaN, "batb": NaN, "batl": [[0, 1.44, 22.18]]}, {"timestamp": 1631550331145, "ltp": 1.44, "tv": 5146.94, "trd": [[1.44, 256.18]], "batb": [[0, 1.44, 23.34], [1, 1.43, 2.65], [2, 1.41, 1.74]], "batl": [[0, 1.45, 165.21], [1, 1.46, 642.08], [2, 1.47, 4.61]]}, {"timestamp": 1631550349543, "ltp": 1.44, "tv": 5146.94, "trd": NaN, "batb": [[0, 1.44, 45.52], [2, 1.4, 50.11]], "batl": NaN}, {"timestamp": 1631550351166, "ltp": 1.44, "tv": 5146.94, "trd": NaN, "batb": [[2, 1.4, 82.09]], "batl": NaN}, {"timestamp": 1631550354258, "ltp": 1.44, "tv": 5146.94, "trd": NaN, "batb": [[1, 1.43, 6.92]], "batl": NaN}, {"timestamp": 1631550430188, "ltp": 1.44, "tv": 5146.94, "trd": NaN, "batb": [[0, 1.44, 22.18]], "batl": NaN}, {"timestamp": 1631550430707, "ltp": 1.44, "tv": 5146.94, "trd": NaN, "batb": [[0, 1.43, 9.2], [1, 1.41, 22.18], [2, 1.4, 50.11]], "batl": NaN}, {"timestamp": 1631550435696, "ltp": 1.45, "tv": 5193.12, "trd": [[1.45, 3499.25]], "batb": NaN, "batl": [[0, 1.45, 142.12]]}, {"timestamp": 1631550447729, "ltp": 1.45, "tv": 5193.12, "trd": NaN, "batb": [[1, 1.42, 22.18]], "batl": NaN}, {"timestamp": 1631550457849, "ltp": 1.45, "tv": 5193.12, "trd": NaN, "batb": [[0, 1.43, 7.7], [1, 1.42, 24.11]], "batl": NaN}, {"timestamp": 1631550459158, "ltp": 1.45, "tv": 5193.12, "trd": NaN, "batb": NaN, "batl": [[0, 1.45, 158.16]]}, {"timestamp": 1631550484695, "ltp": 1.45, "tv": 5193.12, "trd": NaN, "batb": [[0, 1.44, 1.31], [1, 1.43, 6.92], [2, 1.42, 24.11]], "batl": NaN}, {"timestamp": 1631550587066, "ltp": 1.45, "tv": 5193.12, "trd": NaN, "batb": [[2, 1.42, 1.93]], "batl": [[0, 1.45, 142.12]]}, {"timestamp": 1631550639344, "ltp": 1.45, "tv": 5193.12, "trd": NaN, "batb": [[2, 1.42, 24.42]], "batl": [[0, 1.45, 158.16]]}, {"timestamp": 1631550681820, "ltp": 1.45, "tv": 5193.12, "trd": NaN, "batb": [[1, 1.43, 5.05]], "batl": NaN}, {"timestamp": 1631550793048, "ltp": 1.45, "tv": 5193.12, "trd": NaN, "batb": [[0, 1.44, 3.01]], "batl": [[1, 1.46, 643.88]]}, {"timestamp": 1631550827967, "ltp": 1.43, "tv": 5197.12, "trd": [[1.43, 1.38], [1.44, 258.8]], "batb": [[0, 1.43, 6.06], [1, 1.42, 22.49], [2, 1.4, 50.11]], "batl": NaN}, {"timestamp": 1631550840004, "ltp": 1.43, "tv": 5197.12, "trd": NaN, "batb": [[1, 1.41, 22.49]], "batl": NaN}, {"timestamp": 1631550846420, "ltp": 1.43, "tv": 5209.25, "trd": [[1.43, 13.51]], "batb": [[0, 1.41, 22.49], [1, 1.4, 50.11], [2, 1.39, 7.11]], "batl": [[0, 1.43, 1.61], [1, 1.45, 158.16], [2, 1.46, 643.88]]}, {"timestamp": 1631550847780, "ltp": 1.43, "tv": 5209.25, "trd": NaN, "batb": [[0, 1.41, 24.46], [1, 1.4, 52.08]], "batl": [[0, 1.43, 6.61]]}, {"timestamp": 1631550849707, "ltp": 1.43, "tv": 5209.25, "trd": NaN, "batb": [[2, 1.39, 9.09]], "batl": [[0, 1.43, 5]]}, {"timestamp": 1631550852113, "ltp": 1.45, "tv": 5221.34, "trd": [[1.43, 23.5], [1.45, 3501.35]], "batb": NaN, "batl": [[0, 1.45, 157.11], [1, 1.46, 643.88], [2, 1.47, 4.61]]}, {"timestamp": 1631550854108, "ltp": 1.45, "tv": 5221.34, "trd": NaN, "batb": NaN, "batl": [[0, 1.45, 141.07]]}, {"timestamp": 1631550854416, "ltp": 1.45, "tv": 5221.34, "trd": NaN, "batb": NaN, "batl": [[0, 1.44, 16.04], [1, 1.45, 143.04], [2, 1.46, 643.88]]}, {"timestamp": 1631551033020, "ltp": 1.45, "tv": 5221.34, "trd": NaN, "batb": [[0, 1.42, 4.26], [1, 1.41, 24.46], [2, 1.4, 52.08]], "batl": NaN}, {"timestamp": 1631551144030, "ltp": 1.45, "tv": 5221.34, "trd": NaN, "batb": NaN, "batl": [[0, 1.45, 143.04], [1, 1.46, 643.88], [2, 1.47, 4.61]]}, {"timestamp": 1631551321642, "ltp": 1.45, "tv": 5221.34, "trd": NaN, "batb": [[0, 1.43, 11.47], [1, 1.42, 6.1], [2, 1.41, 24.46]], "batl": NaN}, {"timestamp": 1631551331960, "ltp": 1.45, "tv": 5221.34, "trd": NaN, "batb": [[0, 1.43, 33.96], [2, 1.41, 1.97]], "batl": NaN}, {"timestamp": 1631551557732, "ltp": 1.45, "tv": 5292.97, "trd": [[1.45, 3572.97]], "batb": NaN, "batl": [[0, 1.45, 107.23]]}, {"timestamp": 1631551740165, "ltp": 1.45, "tv": 5292.97, "trd": NaN, "batb": [[0, 1.43, 36.63]], "batl": NaN}, {"timestamp": 1631551741061, "ltp": 1.43, "tv": 5366.21, "trd": [[1.43, 96.75]], "batb": [[0, 1.42, 4.26], [1, 1.4, 50.11], [2, 1.39, 7.11]], "batl": [[0, 1.43, 536.74], [1, 1.45, 105.26], [2, 1.46, 642.08]]}, {"timestamp": 1631551743890, "ltp": 1.43, "tv": 5366.21, "trd": NaN, "batb": [[1, 1.41, 1.59], [2, 1.4, 50.11]], "batl": NaN}, {"timestamp": 1631551796153, "ltp": 1.43, "tv": 5366.21, "trd": NaN, "batb": NaN, "batl": [[0, 1.43, 538.74]]}, {"timestamp": 1631551806368, "ltp": 1.42, "tv": 5366.42, "trd": [[1.42, 0.2]], "batb": [[0, 1.42, 4.16]], "batl": NaN}, {"timestamp": 1631551824478, "ltp": 1.42, "tv": 5371.41, "trd": [[1.42, 5.2]], "batb": [[0, 1.42, 1.66]], "batl": NaN}, {"timestamp": 1631551905920, "ltp": 1.42, "tv": 5371.41, "trd": NaN, "batb": [[2, 1.4, 54.63]], "batl": NaN}, {"timestamp": 1631552082040, "ltp": 1.43, "tv": 5374.82, "trd": [[1.43, 100.16]], "batb": NaN, "batl": [[0, 1.43, 537.03]]}, {"timestamp": 1631552106107, "ltp": 1.43, "tv": 5374.82, "trd": NaN, "batb": [[0, 1.42, 214.83]], "batl": NaN}, {"timestamp": 1631552107205, "ltp": 1.43, "tv": 5374.82, "trd": NaN, "batb": [[1, 1.41, 7.36]], "batl": NaN}, {"timestamp": 1631552108880, "ltp": 1.43, "tv": 5374.82, "trd": NaN, "batb": [[2, 1.4, 159.04]], "batl": NaN}, {"timestamp": 1631552113212, "ltp": 1.43, "tv": 5374.82, "trd": NaN, "batb": [[1, 1.41, 5.77]], "batl": NaN}, {"timestamp": 1631552116181, "ltp": 1.43, "tv": 5801.16, "trd": [[1.43, 526.5]], "batb": [[0, 1.42, 1.66]], "batl": [[0, 1.43, 323.86]]}, {"timestamp": 1631552119199, "ltp": 1.43, "tv": 5801.16, "trd": NaN, "batb": [[1, 1.41, 8.33]], "batl": NaN}, {"timestamp": 1631552206635, "ltp": 1.43, "tv": 5801.16, "trd": NaN, "batb": [[1, 1.41, 2.56], [2, 1.4, 154.52]], "batl": NaN}, {"timestamp": 1631552210013, "ltp": 1.41, "tv": 5807.16, "trd": [[1.41, 2.68], [1.42, 8.52]], "batb": [[0, 1.41, 1.22], [1, 1.4, 154.52], [2, 1.39, 7.11]], "batl": NaN}, {"timestamp": 1631552238468, "ltp": 1.43, "tv": 6429.61, "trd": [[1.43, 1148.95]], "batb": NaN, "batl": [[0, 1.43, 12.63]]}, {"timestamp": 1631552258714, "ltp": 1.43, "tv": 6429.61, "trd": NaN, "batb": NaN, "batl": [[0, 1.43, 585.99]]}, {"timestamp": 1631552304136, "ltp": 1.43, "tv": 6484.97, "trd": [[1.43, 1204.31]], "batb": NaN, "batl": [[0, 1.43, 530.63]]}, {"timestamp": 1631552338469, "ltp": 1.43, "tv": 6519.08, "trd": [[1.43, 1238.41]], "batb": NaN, "batl": [[0, 1.43, 513.57]]}, {"timestamp": 1631552365721, "ltp": 1.43, "tv": 7408.04, "trd": [[1.43, 2127.38]], "batb": NaN, "batl": [[0, 1.43, 69.08]]}, {"timestamp": 1631552473442, "ltp": 1.43, "tv": 7413.63, "trd": [[1.41, 2.68], [1.42, 8.52], [1.43, 2129.11], [1.44, 258.84], [1.45, 3576.1], [1.46, 353], [1.47, 336.36], [1.48, 494.29], [1.49, 90.67], [1.5, 164.08]], "batb": [[0, 1.41, 1.22], [1, 1.4, 50.17]], "batl": [[0, 1.43, 69.14], [1, 1.45, 105.34], [2, 1.46, 642.59]]}, {"timestamp": 1631552478297, "ltp": 1.43, "tv": 7413.63, "trd": NaN, "batb": [[1, 1.4, 2.1], [2, 1.01, 98.87]], "batl": [[0, 1.47, 2], [1, 1.48, 8.53], [2, 1.5, 10.79]]}, {"timestamp": 1631552491168, "ltp": 1.01, "tv": 7463.63, "trd": [[1.01, 43.36], [1.4, 4.2], [1.41, 5.12]], "batb": [[0, 1.01, 77.2], [1, 1.4, 0], [2, 1.01, 0]], "batl": NaN}, {"timestamp": 1631552492435, "ltp": 1.45, "tv": 7599.92, "trd": [[1.45, 3687.52], [1.46, 377.88]], "batb": [[0, 1.45, 250.54], [1, 1.01, 77.2]], "batl": [[1, 1.48, 20.23], [2, 1.5, 256.45]]}, {"timestamp": 1631552493553, "ltp": 1.45, "tv": 7665.19, "trd": [[1.45, 3752.79]], "batb": [[0, 1.45, 185.27], [1, 1.33, 99.02], [2, 1.31, 106.49]], "batl": NaN}, {"timestamp": 1631552497594, "ltp": 1.45, "tv": 7909.35, "trd": [[1.45, 3996.95]], "batb": [[0, 1.45, 63.19]], "batl": NaN}, {"timestamp": 1631552500566, "ltp": 1.45, "tv": 7909.35, "trd": NaN, "batb": [[0, 1.45, 83.73]], "batl": [[0, 1.47, 22.26]]}, {"timestamp": 1631552502673, "ltp": 1.45, "tv": 7909.35, "trd": NaN, "batb": [[0, 1.31, 106.49], [1, 1.01, 77.2], [2, 1.31, 0]], "batl": [[0, 1.47, 2], [1, 1.48, 8.53], [2, 1.5, 10.79]]}, {"timestamp": 1631552505879, "ltp": 1.45, "tv": 7909.35, "trd": NaN, "batb": [[0, 1.01, 77.2], [1, 1.01, 0]], "batl": NaN}, {"timestamp": 1631552513318, "ltp": 1.45, "tv": 7909.35, "trd": NaN, "batb": [[0, 1.01, 5]], "batl": NaN}, {"timestamp": 1631552525937, "ltp": 1.01, "tv": 7919.35, "trd": [[1.01, 53.36]], "batb": NaN, "batl": [[0, 1.01, 15.6], [1, 1.47, 2], [2, 1.48, 8.53]]}, {"timestamp": 1631552526311, "ltp": 1.01, "tv": 7950.55, "trd": [[1.01, 84.56]], "batb": [[0, 1.05, 752.45]], "batl": [[0, 1.47, 2], [1, 1.48, 8.53], [2, 1.5, 10.79]]}, {"timestamp": 1631552532526, "ltp": 1.01, "tv": 7950.55, "trd": NaN, "batb": [[0, 1.42, 12.35], [1, 1.4, 285.71], [2, 1.05, 752.45]], "batl": [[0, 1.44, 14.95], [1, 1.47, 2], [2, 1.48, 8.53]]}, {"timestamp": 1631552533619, "ltp": 1.01, "tv": 7950.55, "trd": NaN, "batb": [[2, 1.33, 103.98]], "batl": NaN}, {"timestamp": 1631552537547, "ltp": 1.4, "tv": 8100.47, "trd": [[1.4, 129.42], [1.42, 33.22]], "batb": [[0, 1.4, 223.1], [1, 1.33, 103.98], [2, 1.31, 111.28]], "batl": NaN}, {"timestamp": 1631552540536, "ltp": 1.4, "tv": 8100.47, "trd": NaN, "batb": [[0, 1.4, 244.4]], "batl": [[0, 1.44, 35.66]]}, {"timestamp": 1631552541744, "ltp": 1.4, "tv": 8100.47, "trd": NaN, "batb": NaN, "batl": [[0, 1.42, 1.71], [1, 1.44, 35.66], [2, 1.47, 2]]}, {"timestamp": 1631552543126, "ltp": 1.4, "tv": 8100.47, "trd": NaN, "batb": NaN, "batl": [[2, 1.47, 50.5]]}, {"timestamp": 1631552544853, "ltp": 1.4, "tv": 8100.47, "trd": NaN, "batb": NaN, "batl": [[1, 1.43, 25], [2, 1.44, 35.66]]}, {"timestamp": 1631552546158, "ltp": 1.4, "tv": 8100.47, "trd": NaN, "batb": [[1, 1.39, 60.91], [2, 1.33, 103.98]], "batl": NaN}, {"timestamp": 1631552546633, "ltp": 1.4, "tv": 8100.47, "trd": NaN, "batb": [[1, 1.33, 103.98], [2, 1.31, 111.28]], "batl": NaN}, {"timestamp": 1631552547568, "ltp": 1.4, "tv": 8100.47, "trd": NaN, "batb": NaN, "batl": [[2, 1.44, 20.71]]}, {"timestamp": 1631552548663, "ltp": 1.4, "tv": 8100.47, "trd": NaN, "batb": [[0, 1.31, 111.28], [1, 1.05, 752.45], [2, 1.31, 0]], "batl": [[1, 1.47, 2], [2, 1.48, 8.53]]}, {"timestamp": 1631552550074, "ltp": 1.4, "tv": 8100.47, "trd": NaN, "batb": [[0, 1.39, 62.91], [1, 1.31, 111.28], [2, 1.05, 752.45]], "batl": NaN}, {"timestamp": 1631552555045, "ltp": 1.4, "tv": 8100.47, "trd": NaN, "batb": NaN, "batl": [[0, 1.42, 21.46]]}, {"timestamp": 1631552555673, "ltp": 1.4, "tv": 8100.47, "trd": NaN, "batb": NaN, "batl": [[0, 1.42, 1.71]]}, {"timestamp": 1631552563063, "ltp": 1.42, "tv": 8103.89, "trd": [[1.42, 36.64]], "batb": [[0, 1.43, 110.41], [1, 1.42, 116.84], [2, 1.39, 62.91]], "batl": [[0, 1.47, 2], [1, 1.48, 8.53], [2, 1.49, 52.5]]}, {"timestamp": 1631552565061, "ltp": 1.42, "tv": 8103.89, "trd": NaN, "batb": NaN, "batl": [[2, 1.5, 10.79]]}, {"timestamp": 1631552568057, "ltp": 1.39, "tv": 8573.21, "trd": [[1.39, 14.82], [1.42, 270.32], [1.43, 2349.93]], "batb": [[0, 1.39, 67.21], [1, 1.38, 483.64], [2, 1.31, 111.28]], "batl": [[0, 1.41, 18.45], [1, 1.43, 471.4], [2, 1.47, 101.69]]}, {"timestamp": 1631552571201, "ltp": 1.41, "tv": 8670.89, "trd": [[1.41, 102.8]], "batb": [[0, 1.42, 23.58], [1, 1.41, 121.68], [2, 1.39, 67.21]], "batl": [[0, 1.43, 471.4], [1, 1.46, 172.73]]}, {"timestamp": 1631552572200, "ltp": 1.41, "tv": 8670.89, "trd": NaN, "batb": [[0, 1.41, 121.68], [1, 1.39, 97.63], [2, 1.38, 483.64]], "batl": [[0, 1.42, 29.77], [1, 1.43, 471.4], [2, 1.46, 103.4]]}, {"timestamp": 1631552572988, "ltp": 1.41, "tv": 8863.43, "trd": [[1.41, 295.34]], "batb": [[0, 1.41, 25.41]], "batl": NaN}, {"timestamp": 1631552573506, "ltp": 1.41, "tv": 8914.25, "trd": [[1.41, 346.16]], "batb": [[0, 1.39, 97.63], [1, 1.38, 483.64], [2, 1.31, 111.28]], "batl": [[0, 1.41, 106.59], [1, 1.42, 29.77], [2, 1.43, 471.4]]}, {"timestamp": 1631552574786, "ltp": 1.41, "tv": 9033.87, "trd": [[1.41, 465.78]], "batb": [[0, 1.4, 164.01], [1, 1.39, 97.63], [2, 1.38, 546.6]], "batl": [[0, 1.41, 46.78], [2, 1.43, 507.77]]}, {"timestamp": 1631552576194, "ltp": 1.41, "tv": 9120.01, "trd": [[1.41, 551.92]], "batb": [[0, 1.4, 227.17]], "batl": [[0, 1.41, 3.71]]}, {"timestamp": 1631552577197, "ltp": 1.41, "tv": 9142.75, "trd": [[1.41, 574.66]], "batb": NaN, "batl": [[0, 1.41, 35.34]]}, {"timestamp": 1631552578196, "ltp": 1.41, "tv": 9196.27, "trd": [[1.41, 628.18]], "batb": NaN, "batl": [[0, 1.42, 29.77], [1, 1.43, 507.77], [2, 1.44, 155.61]]}, {"timestamp": 1631552579195, "ltp": 1.41, "tv": 9293.99, "trd": [[1.41, 725.9]], "batb": NaN, "batl": [[0, 1.41, 36.36], [1, 1.42, 29.77], [2, 1.43, 507.77]]}, {"timestamp": 1631552580187, "ltp": 1.41, "tv": 9293.99, "trd": NaN, "batb": [[0, 1.39, 55.5], [1, 1.3, 116.82], [2, 1.05, 752.45]], "batl": [[1, 1.44, 52.33], [2, 1.47, 2]]}, {"timestamp": 1631552580609, "ltp": 1.41, "tv": 9293.99, "trd": NaN, "batb": NaN, "batl": [[0, 1.44, 52.33], [1, 1.47, 2], [2, 1.48, 8.53]]}, {"timestamp": 1631552583902, "ltp": 1.41, "tv": 9293.99, "trd": NaN, "batb": [[0, 1.39, 134.3], [1, 1.38, 136.06], [2, 1.3, 116.82]], "batl": [[1, 1.47, 107.24], [2, 1.48, 107.46]]}, {"timestamp": 1631552584213, "ltp": 1.41, "tv": 9293.99, "trd": NaN, "batb": NaN, "batl": [[1, 1.47, 2], [2, 1.48, 8.53]]}, {"timestamp": 1631552587009, "ltp": 1.39, "tv": 9309.03, "trd": [[1.39, 29.86]], "batb": [[0, 1.39, 126.78]], "batl": [[0, 1.41, 22.51], [1, 1.42, 790.05], [2, 1.43, 114.12]]}, {"timestamp": 1631552588112, "ltp": 1.39, "tv": 9309.03, "trd": NaN, "batb": [[2, 1.31, 114.38]], "batl": NaN}, {"timestamp": 1631552591030, "ltp": 1.39, "tv": 9309.03, "trd": NaN, "batb": [[0, 1.39, 181.38]], "batl": [[0, 1.41, 76.33]]}, {"timestamp": 1631552591926, "ltp": 1.39, "tv": 9369.85, "trd": [[1.39, 90.68]], "batb": [[0, 1.39, 150.97]], "batl": NaN}, {"timestamp": 1631552594304, "ltp": 1.39, "tv": 9369.85, "trd": NaN, "batb": NaN, "batl": [[0, 1.4, 209], [1, 1.41, 76.33], [2, 1.42, 790.05]]}, {"timestamp": 1631552597506, "ltp": 1.39, "tv": 9369.85, "trd": NaN, "batb": [[1, 1.38, 194.12]], "batl": [[0, 1.4, 266.23]]}, {"timestamp": 1631552605128, "ltp": 1.38, "tv": 9769.85, "trd": [[1.38, 98.06], [1.39, 392.62]], "batb": [[0, 1.38, 145.09], [1, 1.31, 114.38], [2, 1.26, 136.29]], "batl": NaN}, {"timestamp": 1631552606637, "ltp": 1.38, "tv": 9769.85, "trd": NaN, "batb": NaN, "batl": [[0, 1.39, 14.45], [1, 1.4, 266.23], [2, 1.41, 76.33]]}, {"timestamp": 1631552608535, "ltp": 1.38, "tv": 9769.85, "trd": NaN, "batb": [[0, 1.38, 203.39], [1, 1.37, 142.34], [2, 1.31, 114.38]], "batl": [[2, 1.41, 152.86]]}, {"timestamp": 1631552612732, "ltp": 1.38, "tv": 9769.85, "trd": NaN, "batb": NaN, "batl": [[0, 1.4, 266.23], [1, 1.41, 152.86], [2, 1.42, 790.05]]}, {"timestamp": 1631552615834, "ltp": 1.38, "tv": 9798.76, "trd": [[1.38, 126.96]], "batb": [[0, 1.38, 188.94]], "batl": NaN}, {"timestamp": 1631552624546, "ltp": 1.38, "tv": 9798.76, "trd": NaN, "batb": [[0, 1.31, 114.38], [1, 1.26, 136.29], [2, 1.05, 752.45]], "batl": [[1, 1.41, 76.33], [2, 1.42, 663.37]]}, {"timestamp": 1631552627960, "ltp": 1.38, "tv": 9798.76, "trd": NaN, "batb": [[0, 1.33, 103.59], [1, 1.32, 186.89], [2, 1.31, 114.38]], "batl": [[0, 1.39, 60.72], [1, 1.4, 266.23], [2, 1.41, 76.33]]}, {"timestamp": 1631552631163, "ltp": 1.38, "tv": 9798.76, "trd": NaN, "batb": [[0, 1.34, 16], [1, 1.33, 608.01], [2, 1.32, 186.89]], "batl": NaN}, {"timestamp": 1631552639183, "ltp": 1.39, "tv": 9800.33, "trd": [[1.39, 394.2]], "batb": [[1, 1.33, 103.59]], "batl": [[0, 1.39, 59.93]]}, {"timestamp": 1631552641664, "ltp": 1.39, "tv": 9800.33, "trd": NaN, "batb": [[0, 1.33, 103.59], [1, 1.32, 171.01], [2, 1.26, 136.29]], "batl": [[0, 1.4, 209], [1, 1.44, 52.33], [2, 1.46, 150.66]]}, {"timestamp": 1631552642662, "ltp": 1.39, "tv": 9800.33, "trd": NaN, "batb": NaN, "batl": [[0, 1.46, 150.66], [1, 1.47, 104], [2, 1.48, 8.53]]}, {"timestamp": 1631552644769, "ltp": 1.39, "tv": 9800.33, "trd": NaN, "batb": [[0, 1.32, 92.14], [1, 1.26, 136.29], [2, 1.05, 752.45]], "batl": [[0, 1.46, 55.75], [1, 1.47, 2]]}, {"timestamp": 1631552647191, "ltp": 1.39, "tv": 9800.33, "trd": NaN, "batb": NaN, "batl": [[0, 1.43, 395.21], [1, 1.46, 55.75], [2, 1.47, 2]]}, {"timestamp": 1631552648185, "ltp": 1.39, "tv": 9800.33, "trd": NaN, "batb": [[0, 1.37, 126.45], [1, 1.36, 147.35], [2, 1.34, 73.22]], "batl": [[0, 1.4, 106.33], [1, 1.41, 122.39], [2, 1.46, 55.75]]}, {"timestamp": 1631552649290, "ltp": 1.39, "tv": 9800.33, "trd": NaN, "batb": NaN, "batl": [[2, 1.44, 63.58]]}, {"timestamp": 1631552652814, "ltp": 1.39, "tv": 9800.33, "trd": NaN, "batb": [[0, 1.32, 92.14], [1, 1.26, 136.29], [2, 1.05, 752.45]], "batl": [[0, 1.46, 55.75], [1, 1.47, 2], [2, 1.48, 8.53]]}, {"timestamp": 1631552656121, "ltp": 1.39, "tv": 9800.33, "trd": NaN, "batb": [[0, 1.34, 70.22], [1, 1.33, 103.59], [2, 1.32, 263.15]], "batl": [[0, 1.44, 54.58], [1, 1.46, 206.41], [2, 1.47, 104]]}, {"timestamp": 1631552656381, "ltp": 1.39, "tv": 9800.33, "trd": NaN, "batb": [[0, 1.33, 103.59], [1, 1.32, 263.15], [2, 1.26, 136.29]], "batl": [[0, 1.46, 206.41], [1, 1.47, 104], [2, 1.48, 8.53]]}, {"timestamp": 1631552659012, "ltp": 1.39, "tv": 9800.33, "trd": NaN, "batb": NaN, "batl": [[0, 1.47, 2], [1, 1.48, 8.53], [2, 1.5, 10.79]]}, {"timestamp": 1631552661915, "ltp": 1.33, "tv": 9815.83, "trd": [[1.33, 15.5]], "batb": [[0, 1.33, 112.65], [2, 1.31, 566.34]], "batl": [[0, 1.35, 19.89], [1, 1.36, 728.1], [2, 1.37, 172.25]]}, {"timestamp": 1631552667006, "ltp": 1.33, "tv": 9925.01, "trd": [[1.33, 124.68]], "batb": [[0, 1.33, 16.81]], "batl": NaN}, {"timestamp": 1631552669903, "ltp": 1.33, "tv": 9925.01, "trd": NaN, "batb": [[1, 1.32, 375.89], [2, 1.31, 746.94]], "batl": [[0, 1.35, 193.89], [1, 1.36, 833.33]]}, {"timestamp": 1631552674197, "ltp": 1.33, "tv": 9925.01, "trd": NaN, "batb": [[0, 1.32, 375.89], [1, 1.31, 180.6], [2, 1.28, 104.41]], "batl": [[0, 1.35, 174], [1, 1.36, 287.14]]}, {"timestamp": 1631552675141, "ltp": 1.32, "tv": 10325.01, "trd": [[1.32, 400]], "batb": [[0, 1.32, 12.7], [1, 1.26, 100.98], [2, 1.22, 168.34]], "batl": [[0, 1.42, 57.25], [1, 1.47, 2], [2, 1.48, 8.53]]}, {"timestamp": 1631552679348, "ltp": 1.32, "tv": 10325.01, "trd": NaN, "batb": [[1, 1.27, 91.43], [2, 1.26, 325.26]], "batl": [[0, 1.39, 106.71], [1, 1.4, 127.94], [2, 1.42, 57.25]]}, {"timestamp": 1631552682023, "ltp": 1.32, "tv": 10325.01, "trd": NaN, "batb": NaN, "batl": [[1, 1.4, 192.08]]}, {"timestamp": 1631552682601, "ltp": 1.32, "tv": 10325.01, "trd": NaN, "batb": [[1, 1.26, 100.98], [2, 1.22, 168.34]], "batl": NaN}, {"timestamp": 1631552686197, "ltp": 1.32, "tv": 10325.01, "trd": NaN, "batb": [[0, 1.36, 144.3], [1, 1.35, 154.84], [2, 1.32, 12.7]], "batl": [[0, 1.39, 122.28], [1, 1.4, 425.77]]}, {"timestamp": 1631552686618, "ltp": 1.37, "tv": 10332.59, "trd": [[1.37, 7.58]], "batb": NaN, "batl": NaN}, {"timestamp": 1631552690842, "ltp": 1.36, "tv": 10430.69, "trd": [[1.36, 89.92], [1.37, 15.76]], "batb": [[0, 1.36, 99.34]], "batl": NaN}, {"timestamp": 1631552691632, "ltp": 1.36, "tv": 10430.69, "trd": NaN, "batb": [[0, 1.36, 136.37]], "batl": [[0, 1.39, 197.65]]}, {"timestamp": 1631552692733, "ltp": 1.36, "tv": 10430.69, "trd": NaN, "batb": [[2, 1.32, 90.59]], "batl": NaN}, {"timestamp": 1631552694202, "ltp": 1.36, "tv": 10517.73, "trd": [[1.36, 176.96]], "batb": [[0, 1.36, 112.97]], "batl": [[0, 1.38, 249], [1, 1.39, 221.94], [2, 1.4, 425.77]]}, {"timestamp": 1631552695160, "ltp": 1.35, "tv": 11532.75, "trd": [[1.35, 789.08], [1.36, 402.9]], "batb": [[0, 1.32, 90.59], [1, 1.3, 204.57], [2, 1.26, 100.98]], "batl": [[0, 1.35, 1856.51], [1, 1.36, 87.03], [2, 1.38, 249]]}, {"timestamp": 1631552696946, "ltp": 1.35, "tv": 11604.31, "trd": [[1.35, 860.64]], "batb": NaN, "batl": [[0, 1.35, 1820.73], [2, 1.38, 323.85]]}, {"timestamp": 1631552698147, "ltp": 1.35, "tv": 11889.57, "trd": [[1.35, 1145.9]], "batb": [[0, 1.34, 162.64], [1, 1.32, 90.59], [2, 1.31, 75.79]], "batl": [[0, 1.35, 1678.1], [2, 1.37, 75.49]]}, {"timestamp": 1631552700043, "ltp": 1.35, "tv": 11901.43, "trd": [[1.35, 1157.76]], "batb": [[0, 1.32, 12.7], [1, 1.27, 97.87], [2, 1.25, 146.61]], "batl": [[0, 1.35, 1743.45], [1, 1.42, 57.25], [2, 1.44, 57.33]]}, {"timestamp": 1631552701161, "ltp": 1.35, "tv": 11901.43, "trd": NaN, "batb": NaN, "batl": [[0, 1.35, 1666.24], [1, 1.36, 90.09], [2, 1.42, 57.25]]}, {"timestamp": 1631552701748, "ltp": 1.35, "tv": 11901.43, "trd": NaN, "batb": NaN, "batl": [[1, 1.42, 57.25], [2, 1.44, 57.33]]}, {"timestamp": 1631552702909, "ltp": 1.35, "tv": 11901.43, "trd": NaN, "batb": [[1, 1.29, 236.29], [2, 1.28, 209.96]], "batl": [[1, 1.42, 193.55], [2, 1.43, 118.43]]}, {"timestamp": 1631552703228, "ltp": 1.35, "tv": 11901.43, "trd": NaN, "batb": [[1, 1.29, 148.48]], "batl": NaN}, {"timestamp": 1631552710136, "ltp": 1.35, "tv": 11901.43, "trd": NaN, "batb": [[1, 1.29, 224.29]], "batl": [[0, 1.42, 136.3], [1, 1.43, 118.43], [2, 1.44, 57.33]]}, {"timestamp": 1631552710239, "ltp": 1.35, "tv": 11901.43, "trd": NaN, "batb": [[1, 1.29, 148.48]], "batl": NaN}, {"timestamp": 1631552713036, "ltp": 1.35, "tv": 11901.43, "trd": NaN, "batb": [[1, 1.27, 97.87], [2, 1.25, 146.61]], "batl": NaN}, {"timestamp": 1631552716152, "ltp": 1.35, "tv": 11901.43, "trd": NaN, "batb": [[0, 1.39, 82.98], [1, 1.38, 2403.54], [2, 1.32, 12.7]], "batl": [[1, 1.43, 631.29], [2, 1.44, 151.77]]}, {"timestamp": 1631552717150, "ltp": 1.39, "tv": 11916.13, "trd": [[1.39, 408.9]], "batb": [[0, 1.39, 75.63], [1, 1.38, 324.6], [2, 1.33, 104.56]], "batl": NaN}, {"timestamp": 1631552719956, "ltp": 1.39, "tv": 11916.13, "trd": NaN, "batb": NaN, "batl": [[0, 1.42, 223.8]]}, {"timestamp": 1631552723186, "ltp": 1.39, "tv": 11916.13, "trd": NaN, "batb": [[2, 1.36, 66.68]], "batl": [[0, 1.41, 247], [1, 1.42, 223.8], [2, 1.43, 689.79]]}, {"timestamp": 1631552726077, "ltp": 1.39, "tv": 12086.73, "trd": [[1.39, 579.49]], "batb": [[0, 1.38, 324.6], [1, 1.36, 66.68], [2, 1.34, 70.22]], "batl": [[0, 1.39, 276.46], [1, 1.41, 247], [2, 1.42, 223.8]]}, {"timestamp": 1631552726390, "ltp": 1.38, "tv": 12486.73, "trd": [[1.38, 526.96]], "batb": [[0, 1.38, 124.6]], "batl": [[1, 1.41, 333.01]]}, {"timestamp": 1631552728979, "ltp": 1.38, "tv": 12486.73, "trd": NaN, "batb": [[0, 1.38, 162.03], [1, 1.37, 147.51], [2, 1.36, 66.68]], "batl": [[0, 1.4, 90.01], [2, 1.42, 268.61]]}, {"timestamp": 1631552729707, "ltp": 1.38, "tv": 12486.73, "trd": NaN, "batb": NaN, "batl": [[2, 1.42, 277.44]]}, {"timestamp": 1631552733017, "ltp": 1.38, "tv": 12486.73, "trd": NaN, "batb": [[0, 1.35, 67.67], [1, 1.34, 70.22], [2, 1.33, 73.53]], "batl": [[0, 1.41, 247], [1, 1.43, 58.5], [2, 1.44, 57.33]]}, {"timestamp": 1631552733814, "ltp": 1.38, "tv": 12486.73, "trd": NaN, "batb": [[0, 1.33, 73.53], [1, 1.32, 12.7], [2, 1.29, 123.03]], "batl": [[0, 1.45, 55.1], [1, 1.47, 2], [2, 1.48, 8.53]]}, {"timestamp": 1631552735870, "ltp": 1.38, "tv": 12486.73, "trd": NaN, "batb": [[0, 1.33, 234.96], [1, 1.32, 190.8]], "batl": [[1, 1.46, 157.42], [2, 1.47, 107.45]]}, {"timestamp": 1631552737071, "ltp": 1.38, "tv": 12486.73, "trd": NaN, "batb": NaN, "batl": [[0, 1.43, 64.5], [1, 1.45, 55.1], [2, 1.46, 157.42]]}, {"timestamp": 1631552738090, "ltp": 1.38, "tv": 12486.73, "trd": NaN, "batb": [[0, 1.33, 73.53], [1, 1.32, 12.7]], "batl": [[0, 1.45, 55.1], [1, 1.46, 157.42], [2, 1.47, 107.45]]}, {"timestamp": 1631552741205, "ltp": 1.38, "tv": 12486.73, "trd": NaN, "batb": [[0, 1.42, 2297.98], [1, 1.41, 128.5], [2, 1.38, 1500.67]], "batl": [[0, 1.44, 16.41], [1, 1.45, 55.1], [2, 1.46, 157.42]]}, {"timestamp": 1631552742197, "ltp": 1.42, "tv": 12501.11, "trd": [[1.42, 284.7]], "batb": [[0, 1.42, 321.5]], "batl": NaN}, {"timestamp": 1631552745087, "ltp": 1.42, "tv": 12501.11, "trd": NaN, "batb": NaN, "batl": [[0, 1.44, 98.51]]}, {"timestamp": 1631552747888, "ltp": 1.42, "tv": 12501.11, "trd": NaN, "batb": [[2, 1.39, 61.91]], "batl": [[2, 1.46, 217.67]]}, {"timestamp": 1631552748411, "ltp": 1.42, "tv": 12501.11, "trd": NaN, "batb": NaN, "batl": [[0, 1.44, 223.51]]}, {"timestamp": 1631552749981, "ltp": 1.42, "tv": 12901.11, "trd": [[1.42, 684.7]], "batb": [[0, 1.42, 121.5]], "batl": NaN}, {"timestamp": 1631552753088, "ltp": 1.42, "tv": 12901.11, "trd": NaN, "batb": [[0, 1.37, 69.77], [1, 1.33, 104.56], [2, 1.32, 12.7]], "batl": [[0, 1.44, 125], [2, 1.46, 60.25]]}, {"timestamp": 1631552753615, "ltp": 1.42, "tv": 12901.11, "trd": NaN, "batb": NaN, "batl": [[0, 1.46, 60.25], [1, 1.47, 2], [2, 1.48, 8.53]]}, {"timestamp": 1631552754722, "ltp": 1.42, "tv": 12901.11, "trd": NaN, "batb": NaN, "batl": [[0, 1.42, 371.43], [1, 1.46, 60.25], [2, 1.47, 2]]}, {"timestamp": 1631552755734, "ltp": 1.42, "tv": 12901.11, "trd": NaN, "batb": [[0, 1.38, 151.61], [1, 1.37, 217.22], [2, 1.33, 104.56]], "batl": NaN}, {"timestamp": 1631552756899, "ltp": 1.42, "tv": 12901.11, "trd": NaN, "batb": NaN, "batl": [[1, 1.45, 60.5], [2, 1.46, 60.25]]}, {"timestamp": 1631552758990, "ltp": 1.42, "tv": 12901.11, "trd": NaN, "batb": NaN, "batl": [[0, 1.46, 60.25], [1, 1.47, 2], [2, 1.48, 8.53]]}, {"timestamp": 1631552760199, "ltp": 1.42, "tv": 12901.11, "trd": NaN, "batb": [[0, 1.37, 69.77], [1, 1.33, 104.56], [2, 1.32, 12.7]], "batl": NaN}, {"timestamp": 1631552763105, "ltp": 1.42, "tv": 12901.11, "trd": NaN, "batb": [[0, 1.44, 104.16], [1, 1.43, 195.44], [2, 1.42, 52.08]], "batl": NaN}, {"timestamp": 1631552764110, "ltp": 1.45, "tv": 12915.29, "trd": [[1.45, 4011.13]], "batb": [[0, 1.45, 95.2], [1, 1.44, 137.48], [2, 1.43, 150.98]], "batl": NaN}, {"timestamp": 1631552768014, "ltp": 1.45, "tv": 12922.61, "trd": [[1.45, 4018.45]], "batb": [[0, 1.45, 91.54]], "batl": [[1, 1.47, 79.21]]}, {"timestamp": 1631552770827, "ltp": 1.45, "tv": 12922.61, "trd": NaN, "batb": NaN, "batl": [[0, 1.46, 245.25]]}, {"timestamp": 1631552774035, "ltp": 1.45, "tv": 12922.61, "trd": NaN, "batb": NaN, "batl": [[0, 1.46, 315.32]]}, {"timestamp": 1631552774665, "ltp": 1.44, "tv": 13322.61, "trd": [[1.44, 475.76], [1.45, 4201.53]], "batb": [[0, 1.44, 29.02], [1, 1.43, 150.98], [2, 1.42, 10.42]], "batl": NaN}, {"timestamp": 1631552778134, "ltp": 1.44, "tv": 13322.61, "trd": NaN, "batb": [[0, 1.44, 114.36], [1, 1.43, 272.1]], "batl": [[2, 1.48, 172.79]]}, {"timestamp": 1631552798084, "ltp": 1.44, "tv": 13322.61, "trd": NaN, "batb": [[0, 1.4, 54.71], [1, 1.38, 62.96], [2, 1.37, 69.77]], "batl": [[0, 1.46, 185], [1, 1.47, 2], [2, 1.48, 8.53]]}, {"timestamp": 1631552798673, "ltp": 1.44, "tv": 13322.61, "trd": NaN, "batb": [[0, 1.38, 62.96], [1, 1.36, 95.08], [2, 1.32, 12.7]], "batl": [[0, 1.47, 2], [1, 1.48, 8.53], [2, 1.5, 10.79]]}, {"timestamp": 1631552803490, "ltp": 1.44, "tv": 13322.61, "trd": NaN, "batb": [[0, 1.45, 164.46], [1, 1.44, 117.74], [2, 1.38, 62.96]], "batl": [[2, 1.49, 105.59]]}, {"timestamp": 1631552804966, "ltp": 1.44, "tv": 13322.61, "trd": NaN, "batb": [[2, 1.4, 62.26]], "batl": NaN}, {"timestamp": 1631552808174, "ltp": 1.44, "tv": 13322.61, "trd": NaN, "batb": [[0, 1.4, 62.26], [1, 1.38, 62.96], [2, 1.36, 95.08]], "batl": [[0, 1.47, 69.37], [2, 1.5, 10.79]]}, {"timestamp": 1631552808383, "ltp": 1.44, "tv": 13322.61, "trd": NaN, "batb": [[0, 1.38, 62.96], [1, 1.36, 95.08], [2, 1.32, 12.7]], "batl": [[0, 1.47, 2]]}, {"timestamp": 1631552811099, "ltp": 1.44, "tv": 13322.61, "trd": NaN, "batb": [[0, 1.4, 135.12], [1, 1.39, 138.21], [2, 1.38, 62.96]], "batl": NaN}, {"timestamp": 1631552812993, "ltp": 1.44, "tv": 13322.61, "trd": NaN, "batb": NaN, "batl": [[0, 1.45, 5], [1, 1.47, 2], [2, 1.48, 8.53]]}, {"timestamp": 1631552815089, "ltp": 1.44, "tv": 13322.61, "trd": NaN, "batb": [[0, 1.4, 205.48]], "batl": NaN}, {"timestamp": 1631552815299, "ltp": 1.44, "tv": 13322.61, "trd": NaN, "batb": [[0, 1.4, 135.12]], "batl": NaN}, {"timestamp": 1631552821944, "ltp": 1.44, "tv": 13322.61, "trd": NaN, "batb": [[0, 1.4, 189.48]], "batl": NaN}, {"timestamp": 1631552822693, "ltp": 1.4, "tv": 13337.11, "trd": [[1.4, 143.92]], "batb": [[0, 1.4, 388.84]], "batl": [[0, 1.42, 14.87], [1, 1.43, 133.27], [2, 1.44, 127.09]]}, {"timestamp": 1631552823947, "ltp": 1.4, "tv": 13337.11, "trd": NaN, "batb": [[2, 1.38, 84.7]], "batl": NaN}, {"timestamp": 1631552826803, "ltp": 1.4, "tv": 13749.81, "trd": [[1.4, 556.62]], "batb": [[0, 1.4, 182.49]], "batl": [[0, 1.42, 82.84]]}, {"timestamp": 1631552829815, "ltp": 1.4, "tv": 13749.81, "trd": NaN, "batb": [[1, 1.39, 199.19], [2, 1.38, 229]], "batl": [[1, 1.43, 206.2]]}, {"timestamp": 1631552830650, "ltp": 1.4, "tv": 14132.3, "trd": [[1.4, 939.11]], "batb": [[0, 1.39, 199.19], [1, 1.38, 229], [2, 1.37, 77.65]], "batl": [[0, 1.42, 198.84]]}, {"timestamp": 1631552834133, "ltp": 1.4, "tv": 14132.3, "trd": NaN, "batb": NaN, "batl": [[0, 1.41, 64.68], [1, 1.42, 82.84], [2, 1.43, 206.2]]}, {"timestamp": 1631552835138, "ltp": 1.4, "tv": 14132.3, "trd": NaN, "batb": [[1, 1.38, 207.26], [2, 1.37, 66.77]], "batl": [[1, 1.42, 67.97], [2, 1.43, 152.72]]}, {"timestamp": 1631552835819, "ltp": 1.4, "tv": 14132.3, "trd": NaN, "batb": [[0, 1.37, 66.77], [1, 1.34, 102.72], [2, 1.32, 12.7]], "batl": [[0, 1.45, 5], [1, 1.47, 55.5], [2, 1.48, 8.53]]}, {"timestamp": 1631552838134, "ltp": 1.4, "tv": 14132.3, "trd": NaN, "batb": [[0, 1.42, 40], [1, 1.37, 66.77], [2, 1.34, 102.72]], "batl": [[1, 1.46, 61.75], [2, 1.47, 55.5]]}, {"timestamp": 1631552839038, "ltp": 1.4, "tv": 14132.3, "trd": NaN, "batb": [[1, 1.38, 67.96], [2, 1.37, 66.77]], "batl": [[0, 1.45, 64.1]]}, {"timestamp": 1631552839740, "ltp": 1.4, "tv": 14132.3, "trd": NaN, "batb": [[1, 1.37, 66.77], [2, 1.36, 222.63]], "batl": [[0, 1.46, 61.75], [1, 1.47, 55.5], [2, 1.48, 8.53]]}, {"timestamp": 1631552842137, "ltp": 1.42, "tv": 14142.3, "trd": [[1.42, 694.7]], "batb": [[0, 1.42, 35]], "batl": NaN}, {"timestamp": 1631552842932, "ltp": 1.42, "tv": 14142.3, "trd": NaN, "batb": [[1, 1.38, 69.96], [2, 1.37, 66.77]], "batl": [[0, 1.45, 174.65], [1, 1.46, 61.75], [2, 1.47, 55.5]]}, {"timestamp": 1631552843244, "ltp": 1.42, "tv": 14142.3, "trd": NaN, "batb": [[1, 1.37, 66.77], [2, 1.36, 222.63]], "batl": [[0, 1.45, 120.15]]}, {"timestamp": 1631552845623, "ltp": 1.42, "tv": 14142.3, "trd": NaN, "batb": NaN, "batl": [[0, 1.44, 57.7], [1, 1.45, 120.15], [2, 1.46, 61.75]]}, {"timestamp": 1631552848068, "ltp": 1.42, "tv": 14142.3, "trd": NaN, "batb": NaN, "batl": [[0, 1.45, 57], [1, 1.46, 61.75], [2, 1.47, 55.5]]}, {"timestamp": 1631552848447, "ltp": 1.42, "tv": 14142.3, "trd": NaN, "batb": NaN, "batl": [[0, 1.46, 61.75], [1, 1.47, 55.5], [2, 1.48, 8.53]]}, {"timestamp": 1631552850174, "ltp": 1.42, "tv": 14142.3, "trd": NaN, "batb": [[1, 1.38, 61.46], [2, 1.37, 66.77]], "batl": [[0, 1.45, 52.9], [1, 1.46, 61.75], [2, 1.47, 55.5]]}, {"timestamp": 1631552850345, "ltp": 1.42, "tv": 14142.3, "trd": NaN, "batb": [[1, 1.37, 66.77], [2, 1.34, 102.72]], "batl": [[0, 1.46, 61.75], [1, 1.47, 55.5], [2, 1.48, 8.53]]}, {"timestamp": 1631552853663, "ltp": 1.42, "tv": 14182.8, "trd": [[1.42, 735.2]], "batb": [[0, 1.42, 14.75], [1, 1.41, 75.91], [2, 1.4, 133.76]], "batl": [[0, 1.44, 127.49], [1, 1.45, 169.05], [2, 1.46, 61.75]]}, {"timestamp": 1631552857037, "ltp": 1.42, "tv": 14182.8, "trd": NaN, "batb": [[1, 1.38, 61.46], [2, 1.37, 66.77]], "batl": [[0, 1.45, 55.7], [1, 1.46, 61.75], [2, 1.47, 55.5]]}, {"timestamp": 1631552857250, "ltp": 1.42, "tv": 14182.8, "trd": NaN, "batb": NaN, "batl": [[0, 1.46, 61.75], [1, 1.47, 55.5], [2, 1.48, 8.53]]}, {"timestamp": 1631552864147, "ltp": 1.42, "tv": 14182.8, "trd": NaN, "batb": NaN, "batl": [[0, 1.45, 61.9], [1, 1.46, 61.75], [2, 1.47, 55.5]]}, {"timestamp": 1631552864364, "ltp": 1.42, "tv": 14182.8, "trd": NaN, "batb": NaN, "batl": [[0, 1.46, 61.75], [1, 1.47, 55.5], [2, 1.48, 8.53]]}, {"timestamp": 1631552866052, "ltp": 1.38, "tv": 14227.0, "trd": [[1.38, 541.66], [1.42, 764.7]], "batb": [[0, 1.37, 66.77], [1, 1.36, 222.63], [2, 1.35, 161.1]], "batl": [[0, 1.39, 46.43], [1, 1.4, 180.35], [2, 1.41, 270.36]]}, {"timestamp": 1631552870983, "ltp": 1.38, "tv": 14227.0, "trd": NaN, "batb": NaN, "batl": [[0, 1.39, 101]]}, {"timestamp": 1631552872675, "ltp": 1.38, "tv": 14227.0, "trd": NaN, "batb": [[1, 1.36, 291.31]], "batl": NaN}, {"timestamp": 1631552873466, "ltp": 1.38, "tv": 14227.0, "trd": NaN, "batb": NaN, "batl": [[0, 1.39, 238]]}, {"timestamp": 1631552875192, "ltp": 1.36, "tv": 14607.2, "trd": [[1.36, 629.76], [1.37, 169.1]], "batb": [[0, 1.36, 177.88], [1, 1.35, 161.1], [2, 1.34, 102.72]], "batl": NaN}, {"timestamp": 1631552875883, "ltp": 1.36, "tv": 14607.2, "trd": NaN, "batb": NaN, "batl": [[0, 1.39, 101], [1, 1.4, 133.27], [2, 1.41, 142.55]]}, {"timestamp": 1631552879103, "ltp": 1.36, "tv": 14607.2, "trd": NaN, "batb": [[0, 1.37, 68.77], [1, 1.36, 228.62], [2, 1.35, 226.37]], "batl": [[0, 1.38, 416.55], [1, 1.39, 209.63], [2, 1.4, 133.27]]}, {"timestamp": 1631552882003, "ltp": 1.36, "tv": 14607.2, "trd": NaN, "batb": [[0, 1.35, 65.27], [1, 1.32, 123.31], [2, 1.05, 752.45]], "batl": [[0, 1.38, 361], [1, 1.42, 58.75], [2, 1.44, 53.08]]}, {"timestamp": 1631552882692, "ltp": 1.36, "tv": 14607.2, "trd": NaN, "batb": NaN, "batl": [[0, 1.44, 53.08], [1, 1.47, 2], [2, 1.48, 8.53]]}, {"timestamp": 1631552885117, "ltp": 1.36, "tv": 14732.06, "trd": [[1.36, 754.62]], "batb": [[1, 1.34, 159.28], [2, 1.33, 173.95]], "batl": [[0, 1.36, 137.57], [1, 1.44, 234.11], [2, 1.45, 113.43]]}, {"timestamp": 1631552885913, "ltp": 1.36, "tv": 14732.06, "trd": NaN, "batb": NaN, "batl": [[1, 1.42, 58.75], [2, 1.44, 234.11]]}, {"timestamp": 1631552888177, "ltp": 1.36, "tv": 14732.06, "trd": NaN, "batb": [[1, 1.32, 123.31], [2, 1.05, 752.45]], "batl": NaN}, {"timestamp": 1631552891184, "ltp": 1.36, "tv": 15007.2, "trd": [[1.36, 1029.76]], "batb": [[0, 1.4, 2120.43], [1, 1.39, 237.4], [2, 1.38, 95.68]], "batl": [[0, 1.42, 13.99], [1, 1.44, 234.11], [2, 1.45, 113.43]]}, {"timestamp": 1631552892186, "ltp": 1.4, "tv": 15021.58, "trd": [[1.4, 953.49]], "batb": [[0, 1.4, 314.75]], "batl": NaN}, {"timestamp": 1631552896131, "ltp": 1.4, "tv": 15021.58, "trd": NaN, "batb": NaN, "batl": [[0, 1.42, 201.99]]}, {"timestamp": 1631552898712, "ltp": 1.4, "tv": 15021.58, "trd": NaN, "batb": [[2, 1.38, 170.64]], "batl": [[0, 1.42, 259.23]]}, {"timestamp": 1631552902124, "ltp": 1.4, "tv": 15021.58, "trd": NaN, "batb": [[0, 1.38, 74.96], [1, 1.37, 65.77], [2, 1.35, 165.55]], "batl": [[0, 1.42, 188], [1, 1.46, 85.25], [2, 1.47, 2]]}, {"timestamp": 1631552902700, "ltp": 1.4, "tv": 15021.58, "trd": NaN, "batb": [[0, 1.37, 65.77], [1, 1.35, 100.28], [2, 1.32, 12.7]], "batl": [[0, 1.47, 2], [1, 1.48, 95.77], [2, 1.5, 10.79]]}, {"timestamp": 1631552904018, "ltp": 1.4, "tv": 15021.58, "trd": NaN, "batb": NaN, "batl": [[1, 1.48, 87.24]]}, {"timestamp": 1631552905126, "ltp": 1.4, "tv": 15021.58, "trd": NaN, "batb": [[0, 1.37, 164.59], [1, 1.36, 154.61], [2, 1.35, 100.28]], "batl": NaN}, {"timestamp": 1631552905918, "ltp": 1.4, "tv": 15021.58, "trd": NaN, "batb": NaN, "batl": [[0, 1.46, 84.75], [1, 1.47, 2], [2, 1.48, 87.24]]}, {"timestamp": 1631552906234, "ltp": 1.4, "tv": 15021.58, "trd": NaN, "batb": NaN, "batl": [[0, 1.47, 2], [1, 1.48, 87.24], [2, 1.5, 10.79]]}, {"timestamp": 1631552913038, "ltp": 1.4, "tv": 15021.58, "trd": NaN, "batb": NaN, "batl": [[0, 1.46, 79.25], [1, 1.47, 2], [2, 1.48, 87.24]]}, {"timestamp": 1631552913352, "ltp": 1.4, "tv": 15021.58, "trd": NaN, "batb": NaN, "batl": [[0, 1.47, 2], [1, 1.48, 87.24], [2, 1.5, 10.79]]}, {"timestamp": 1631552920054, "ltp": 1.4, "tv": 15021.58, "trd": NaN, "batb": NaN, "batl": [[0, 1.46, 83.25], [1, 1.47, 2], [2, 1.48, 87.24]]}, {"timestamp": 1631552920266, "ltp": 1.4, "tv": 15021.58, "trd": NaN, "batb": NaN, "batl": [[0, 1.47, 2], [1, 1.48, 87.24], [2, 1.5, 10.79]]}, {"timestamp": 1631552923167, "ltp": 1.4, "tv": 15021.58, "trd": NaN, "batb": [[0, 1.38, 68.96], [1, 1.37, 164.59], [2, 1.36, 154.61]], "batl": NaN}, {"timestamp": 1631552923751, "ltp": 1.4, "tv": 15021.58, "trd": NaN, "batb": [[0, 1.37, 164.59], [1, 1.36, 154.61], [2, 1.35, 100.28]], "batl": NaN}, {"timestamp": 1631552924752, "ltp": 1.37, "tv": 15036.28, "trd": [[1.37, 183.8]], "batb": [[0, 1.37, 157.24]], "batl": [[0, 1.39, 121.51], [1, 1.4, 153.16], [2, 1.41, 128.6]]}, {"timestamp": 1631552925963, "ltp": 1.37, "tv": 15036.28, "trd": NaN, "batb": [[2, 1.35, 122.5]], "batl": NaN}, {"timestamp": 1631552929175, "ltp": 1.37, "tv": 15408.35, "trd": [[1.37, 555.87]], "batb": [[0, 1.36, 154.61], [1, 1.35, 122.5], [2, 1.34, 11.12]], "batl": [[0, 1.39, 183.74]]}, {"timestamp": 1631552930481, "ltp": 1.37, "tv": 15408.35, "trd": NaN, "batb": NaN, "batl": [[0, 1.39, 293.74]]}, {"timestamp": 1631552931763, "ltp": 1.37, "tv": 15408.35, "trd": NaN, "batb": [[0, 1.36, 270.91], [1, 1.35, 284.56]], "batl": [[1, 1.4, 206.46], [2, 1.41, 220.1]]}, {"timestamp": 1631552933994, "ltp": 1.37, "tv": 15408.35, "trd": NaN, "batb": NaN, "batl": [[0, 1.38, 63.61], [1, 1.39, 183.74], [2, 1.4, 206.46]]}, {"timestamp": 1631552935483, "ltp": 1.37, "tv": 15608.35, "trd": [[1.37, 755.87]], "batb": NaN, "batl": NaN}, {"timestamp": 1631552937100, "ltp": 1.37, "tv": 15608.35, "trd": NaN, "batb": NaN, "batl": [[0, 1.38, 344.61]]}, {"timestamp": 1631552937578, "ltp": 1.37, "tv": 15608.35, "trd": NaN, "batb": [[1, 1.35, 353.23]], "batl": NaN}, {"timestamp": 1631552947105, "ltp": 1.38, "tv": 15608.4, "trd": [[1.38, 541.71]], "batb": NaN, "batl": [[0, 1.38, 344.56]]}, {"timestamp": 1631552949206, "ltp": 1.38, "tv": 15608.4, "trd": NaN, "batb": [[1, 1.35, 342.12], [2, 1.34, 5.56]], "batl": [[1, 1.39, 165.73]]}, {"timestamp": 1631552949687, "ltp": 1.38, "tv": 15608.4, "trd": NaN, "batb": [[0, 1.35, 68.67], [1, 1.33, 105.99], [2, 1.32, 12.7]], "batl": [[0, 1.43, 117.5], [1, 1.47, 2], [2, 1.5, 10.79]]}, {"timestamp": 1631552953206, "ltp": 1.38, "tv": 15608.4, "trd": NaN, "batb": [[1, 1.34, 208.79], [2, 1.33, 281.24]], "batl": [[1, 1.44, 166.54], [2, 1.45, 113.92]]}, {"timestamp": 1631552959983, "ltp": 1.38, "tv": 15608.4, "trd": NaN, "batb": [[0, 1.36, 79.68], [1, 1.35, 68.67], [2, 1.34, 208.79]], "batl": [[0, 1.41, 117.5], [1, 1.47, 2], [2, 1.5, 10.79]]}, {"timestamp": 1631552960294, "ltp": 1.38, "tv": 15608.4, "trd": NaN, "batb": [[0, 1.35, 68.67], [1, 1.34, 208.79], [2, 1.33, 281.24]], "batl": [[0, 1.47, 2], [1, 1.5, 10.79], [2, 1.51, 0.52]]}, {"timestamp": 1631552962180, "ltp": 1.35, "tv": 15623.22, "trd": [[1.35, 1172.58]], "batb": [[0, 1.35, 61.26]], "batl": [[0, 1.37, 17.37], [1, 1.38, 1773.3], [2, 1.47, 2]]}, {"timestamp": 1631552963173, "ltp": 1.35, "tv": 15623.22, "trd": NaN, "batb": NaN, "batl": [[0, 1.37, 111.15], [1, 1.38, 419.24]]}, {"timestamp": 1631552967126, "ltp": 1.35, "tv": 15623.22, "trd": NaN, "batb": NaN, "batl": [[1, 1.38, 453.38]]}, {"timestamp": 1631552967282, "ltp": 1.35, "tv": 15623.22, "trd": NaN, "batb": NaN, "batl": [[1, 1.38, 419.24]]}, {"timestamp": 1631552970321, "ltp": 1.35, "tv": 15623.22, "trd": NaN, "batb": NaN, "batl": [[0, 1.37, 337.21]]}, {"timestamp": 1631552972633, "ltp": 1.35, "tv": 15884.48, "trd": [[1.35, 1433.84]], "batb": [[0, 1.34, 208.79], [1, 1.33, 281.24], [2, 1.32, 115.72]], "batl": NaN}, {"timestamp": 1631552974214, "ltp": 1.35, "tv": 15884.48, "trd": NaN, "batb": NaN, "batl": [[1, 1.38, 276.21]]}, {"timestamp": 1631552975789, "ltp": 1.35, "tv": 15884.48, "trd": NaN, "batb": NaN, "batl": [[0, 1.36, 95.77], [1, 1.37, 337.21], [2, 1.38, 276.21]]}, {"timestamp": 1631552982795, "ltp": 1.35, "tv": 15884.48, "trd": NaN, "batb": NaN, "batl": [[1, 1.37, 319.84]]}, {"timestamp": 1631552985834, "ltp": 1.35, "tv": 16084.48, "trd": [[1.35, 1633.84]], "batb": [[0, 1.34, 229.96]], "batl": [[0, 1.36, 112.55], [1, 1.37, 187.84]]}, {"timestamp": 1631552988929, "ltp": 1.35, "tv": 16084.48, "trd": NaN, "batb": NaN, "batl": [[0, 1.36, 408.55]]}, {"timestamp": 1631552997946, "ltp": 1.34, "tv": 16359.74, "trd": [[1.34, 150.52], [1.35, 1758.58]], "batb": [[0, 1.34, 154.7]], "batl": NaN}, {"timestamp": 1631552998834, "ltp": 1.36, "tv": 16368.76, "trd": [[1.36, 1038.78]], "batb": NaN, "batl": [[0, 1.36, 404.04]]}, {"timestamp": 1631553001358, "ltp": 1.36, "tv": 16368.76, "trd": NaN, "batb": [[0, 1.34, 188.25]], "batl": [[1, 1.37, 228.39]]}, {"timestamp": 1631553003957, "ltp": 1.36, "tv": 16368.76, "trd": NaN, "batb": [[0, 1.34, 410.25]], "batl": NaN}, {"timestamp": 1631553004635, "ltp": 1.36, "tv": 16368.76, "trd": NaN, "batb": [[0, 1.35, 830.25], [1, 1.34, 410.25], [2, 1.33, 281.24]], "batl": NaN}, {"timestamp": 1631553008444, "ltp": 1.35, "tv": 16863.84, "trd": [[1.35, 2253.66]], "batb": [[0, 1.35, 582.71]], "batl": NaN}, {"timestamp": 1631553011648, "ltp": 1.35, "tv": 16863.84, "trd": NaN, "batb": [[0, 1.35, 613.35]], "batl": NaN}, {"timestamp": 1631553013849, "ltp": 1.35, "tv": 17863.84, "trd": [[1.35, 3253.66]], "batb": [[0, 1.35, 113.35]], "batl": NaN}, {"timestamp": 1631553020340, "ltp": 1.36, "tv": 17868.55, "trd": [[1.36, 1043.49]], "batb": NaN, "batl": [[0, 1.36, 399.33]]}, {"timestamp": 1631553024786, "ltp": 1.34, "tv": 18868.55, "trd": [[1.34, 923.82], [1.35, 3480.36]], "batb": [[0, 1.34, 23.6], [1, 1.33, 281.24], [2, 1.32, 115.72]], "batl": NaN}, {"timestamp": 1631553028181, "ltp": 1.34, "tv": 18868.55, "trd": NaN, "batb": [[1, 1.33, 356.6], [2, 1.32, 300.18]], "batl": [[1, 1.37, 318.4]]}, {"timestamp": 1631553030868, "ltp": 1.34, "tv": 18868.55, "trd": NaN, "batb": NaN, "batl": [[0, 1.36, 594.81]]}, {"timestamp": 1631553034987, "ltp": 1.34, "tv": 18868.55, "trd": NaN, "batb": NaN, "batl": [[0, 1.36, 578.03]]}, {"timestamp": 1631553036682, "ltp": 1.34, "tv": 18868.55, "trd": NaN, "batb": [[0, 1.34, 245.6]], "batl": NaN}, {"timestamp": 1631553037892, "ltp": 1.34, "tv": 18868.55, "trd": NaN, "batb": NaN, "batl": [[0, 1.35, 19.35], [1, 1.36, 578.03], [2, 1.37, 318.4]]}, {"timestamp": 1631553073734, "ltp": 1.34, "tv": 18868.55, "trd": NaN, "batb": [[1, 1.32, 12.7], [2, 1.31, 222]], "batl": [[0, 1.36, 491.48], [1, 1.4, 140.74], [2, 1.42, 149.75]]}, {"timestamp": 1631553074525, "ltp": 1.34, "tv": 18868.55, "trd": NaN, "batb": NaN, "batl": [[0, 1.36, 195.48]]}, {"timestamp": 1631553076654, "ltp": 1.34, "tv": 18868.55, "trd": NaN, "batb": NaN, "batl": [[1, 1.4, 225.41], [2, 1.41, 130.8]]}, {"timestamp": 1631553077956, "ltp": 1.34, "tv": 18868.55, "trd": NaN, "batb": [[0, 1.32, 12.7], [1, 1.28, 128.82], [2, 1.05, 752.45]], "batl": [[1, 1.4, 140.74], [2, 1.42, 149.75]]}, {"timestamp": 1631553080121, "ltp": 1.34, "tv": 18868.55, "trd": NaN, "batb": [[0, 1.32, 264.77], [1, 1.31, 192.26], [2, 1.28, 128.82]], "batl": [[0, 1.35, 91.35], [1, 1.36, 350.72], [2, 1.4, 140.74]]}, {"timestamp": 1631553083035, "ltp": 1.34, "tv": 18868.55, "trd": NaN, "batb": [[0, 1.32, 12.7], [1, 1.28, 128.82], [2, 1.05, 752.45]], "batl": [[0, 1.36, 195.48], [1, 1.4, 140.74], [2, 1.42, 149.75]]}, {"timestamp": 1631553085941, "ltp": 1.34, "tv": 18868.55, "trd": NaN, "batb": [[1, 1.29, 81.03], [2, 1.28, 345.29]], "batl": [[1, 1.4, 225.41], [2, 1.41, 130.8]]}, {"timestamp": 1631553090137, "ltp": 1.34, "tv": 18868.55, "trd": NaN, "batb": [[1, 1.28, 128.82], [2, 1.05, 752.45]], "batl": NaN}, {"timestamp": 1631553091168, "ltp": 1.34, "tv": 18868.55, "trd": NaN, "batb": NaN, "batl": [[0, 1.4, 84.67], [1, 1.41, 130.8], [2, 1.47, 2]]}, {"timestamp": 1631553093168, "ltp": 1.34, "tv": 18868.55, "trd": NaN, "batb": [[0, 1.37, 176.47], [1, 1.36, 157.22], [2, 1.32, 12.7]], "batl": [[2, 1.42, 463.46]]}, {"timestamp": 1631553094172, "ltp": 1.34, "tv": 18868.55, "trd": NaN, "batb": [[1, 1.36, 252.64]], "batl": [[0, 1.38, 7.25], [1, 1.4, 84.67], [2, 1.41, 130.8]]}, {"timestamp": 1631553095550, "ltp": 1.34, "tv": 18868.55, "trd": NaN, "batb": NaN, "batl": [[1, 1.4, 274.57]]}, {"timestamp": 1631553098173, "ltp": 1.37, "tv": 19302.35, "trd": [[1.37, 1189.67]], "batb": [[0, 1.36, 252.64], [1, 1.32, 12.7], [2, 1.31, 111.86]], "batl": [[1, 1.39, 143.8], [2, 1.4, 274.57]]}, {"timestamp": 1631553100072, "ltp": 1.37, "tv": 19302.35, "trd": NaN, "batb": [[1, 1.34, 76.22], [2, 1.32, 86.59]], "batl": [[0, 1.38, 333.25]]}, {"timestamp": 1631553100961, "ltp": 1.37, "tv": 19302.35, "trd": NaN, "batb": [[0, 1.37, 78.95], [1, 1.36, 252.64], [2, 1.34, 76.22]], "batl": [[0, 1.38, 466.05], [2, 1.4, 369.66]]}, {"timestamp": 1631553105158, "ltp": 1.37, "tv": 19581.3, "trd": [[1.37, 1468.62]], "batb": [[0, 1.36, 252.64], [1, 1.34, 76.22], [2, 1.32, 86.59]], "batl": NaN}, {"timestamp": 1631553105505, "ltp": 1.37, "tv": 19581.3, "trd": NaN, "batb": NaN, "batl": [[2, 1.4, 326.28]]}, {"timestamp": 1631553106676, "ltp": 1.37, "tv": 19581.3, "trd": NaN, "batb": [[0, 1.36, 255.07]], "batl": NaN}, {"timestamp": 1631553107795, "ltp": 1.37, "tv": 19581.3, "trd": NaN, "batb": [[0, 1.36, 2.43], [1, 1.32, 86.59], [2, 1.31, 111.86]], "batl": [[0, 1.38, 326], [1, 1.4, 189.9], [2, 1.41, 161.5]]}, {"timestamp": 1631553108789, "ltp": 1.37, "tv": 19581.3, "trd": NaN, "batb": NaN, "batl": [[0, 1.4, 189.9], [1, 1.41, 161.5], [2, 1.43, 149.5]]}, {"timestamp": 1631553111099, "ltp": 1.37, "tv": 19581.3, "trd": NaN, "batb": [[1, 1.34, 67.72], [2, 1.32, 178.43]], "batl": [[2, 1.43, 289.58]]}, {"timestamp": 1631553112105, "ltp": 1.37, "tv": 19581.3, "trd": NaN, "batb": [[1, 1.32, 86.59], [2, 1.31, 111.86]], "batl": [[2, 1.43, 149.5]]}, {"timestamp": 1631553115089, "ltp": 1.37, "tv": 19581.3, "trd": NaN, "batb": [[1, 1.35, 203.71], [2, 1.34, 171.31]], "batl": [[0, 1.38, 110.41], [1, 1.39, 141.02], [2, 1.4, 189.9]]}, {"timestamp": 1631553115402, "ltp": 1.37, "tv": 19581.3, "trd": NaN, "batb": NaN, "batl": [[0, 1.38, 91.16]]}, {"timestamp": 1631553117570, "ltp": 1.37, "tv": 19581.3, "trd": NaN, "batb": [[1, 1.32, 86.59], [2, 1.31, 111.86]], "batl": [[0, 1.4, 189.9], [1, 1.41, 161.5], [2, 1.43, 149.5]]}, {"timestamp": 1631553120210, "ltp": 1.37, "tv": 19581.3, "trd": NaN, "batb": [[0, 1.36, 224.43]], "batl": NaN}, {"timestamp": 1631553120415, "ltp": 1.37, "tv": 19581.3, "trd": NaN, "batb": [[1, 1.32, 178.43], [2, 1.31, 303.81]], "batl": [[2, 1.43, 289.58]]}, {"timestamp": 1631553121902, "ltp": 1.37, "tv": 19581.3, "trd": NaN, "batb": [[1, 1.34, 72.22], [2, 1.32, 178.43]], "batl": NaN}, {"timestamp": 1631553122693, "ltp": 1.37, "tv": 19581.3, "trd": NaN, "batb": [[2, 1.32, 86.59]], "batl": NaN}, {"timestamp": 1631553123938, "ltp": 1.37, "tv": 19581.3, "trd": NaN, "batb": NaN, "batl": [[0, 1.43, 289.58], [1, 1.44, 119.61], [2, 1.47, 2]]}, {"timestamp": 1631553125703, "ltp": 1.37, "tv": 19581.3, "trd": NaN, "batb": [[0, 1.4, 299.17], [1, 1.39, 163.24], [2, 1.38, 10.8]], "batl": [[2, 1.45, 449.4]]}, {"timestamp": 1631553127016, "ltp": 1.37, "tv": 19581.3, "trd": NaN, "batb": [[1, 1.39, 248.92]], "batl": [[0, 1.41, 7.09], [1, 1.43, 289.58], [2, 1.44, 140.45]]}, {"timestamp": 1631553127919, "ltp": 1.37, "tv": 19581.3, "trd": NaN, "batb": [[2, 1.38, 232.8]], "batl": NaN}, {"timestamp": 1631553129788, "ltp": 1.37, "tv": 19581.3, "trd": NaN, "batb": NaN, "batl": [[1, 1.42, 124.21], [2, 1.43, 289.58]]}, {"timestamp": 1631553130992, "ltp": 1.37, "tv": 19581.3, "trd": NaN, "batb": NaN, "batl": [[0, 1.41, 327.09], [1, 1.42, 346.21]]}, {"timestamp": 1631553133000, "ltp": 1.4, "tv": 19981.3, "trd": [[1.4, 1353.49]], "batb": [[0, 1.4, 99.17], [2, 1.38, 304.76]], "batl": [[1, 1.42, 502.46]]}, {"timestamp": 1631553133649, "ltp": 1.4, "tv": 19981.3, "trd": NaN, "batb": NaN, "batl": [[0, 1.41, 444.82]]}, {"timestamp": 1631553137843, "ltp": 1.4, "tv": 19981.3, "trd": NaN, "batb": [[0, 1.38, 293.96], [1, 1.37, 76.77], [2, 1.36, 224.43]], "batl": [[0, 1.41, 320], [1, 1.42, 378.25], [2, 1.43, 149.5]]}, {"timestamp": 1631553138538, "ltp": 1.4, "tv": 19981.3, "trd": NaN, "batb": NaN, "batl": [[0, 1.42, 378.25], [1, 1.43, 149.5], [2, 1.44, 222]]}, {"timestamp": 1631553140435, "ltp": 1.4, "tv": 19981.3, "trd": NaN, "batb": [[2, 1.36, 313.58]], "batl": NaN}, {"timestamp": 1631553152125, "ltp": 1.4, "tv": 19981.3, "trd": NaN, "batb": [[0, 1.37, 76.77], [1, 1.36, 91.58], [2, 1.35, 261.82]], "batl": NaN}, {"timestamp": 1631553154149, "ltp": 1.37, "tv": 19995.9, "trd": [[1.37, 1483.22]], "batb": [[0, 1.37, 69.47]], "batl": [[0, 1.38, 26.03], [1, 1.39, 171.5], [2, 1.4, 237.27]]}, {"timestamp": 1631553155148, "ltp": 1.37, "tv": 19995.9, "trd": NaN, "batb": NaN, "batl": [[1, 1.39, 356.44], [2, 1.4, 372.81]]}, {"timestamp": 1631553159149, "ltp": 1.37, "tv": 19995.9, "trd": NaN, "batb": NaN, "batl": [[0, 1.38, 145.34]]}, {"timestamp": 1631553160150, "ltp": 1.37, "tv": 19995.9, "trd": NaN, "batb": NaN, "batl": [[0, 1.38, 337.99]]}, {"timestamp": 1631553162468, "ltp": 1.37, "tv": 19995.9, "trd": NaN, "batb": NaN, "batl": [[0, 1.38, 509.99]]}, {"timestamp": 1631553168758, "ltp": 1.37, "tv": 19995.9, "trd": NaN, "batb": [[0, 1.36, 2.43], [1, 1.32, 12.7], [2, 1.3, 118.83]], "batl": [[0, 1.38, 364.65], [1, 1.41, 163.5], [2, 1.42, 156.25]]}, {"timestamp": 1631553169547, "ltp": 1.37, "tv": 19995.9, "trd": NaN, "batb": NaN, "batl": [[0, 1.38, 192.65]]}, {"timestamp": 1631553171749, "ltp": 1.37, "tv": 19995.9, "trd": NaN, "batb": [[2, 1.3, 393.34]], "batl": NaN}, {"timestamp": 1631553172569, "ltp": 1.37, "tv": 19995.9, "trd": NaN, "batb": [[2, 1.3, 118.83]], "batl": NaN}, {"timestamp": 1631553175656, "ltp": 1.37, "tv": 19995.9, "trd": NaN, "batb": [[1, 1.35, 78.21], [2, 1.34, 170.02]], "batl": [[0, 1.38, 402.59], [1, 1.39, 139.97], [2, 1.41, 163.5]]}, {"timestamp": 1631553178771, "ltp": 1.35, "tv": 20053.59, "trd": [[1.35, 3535.62], [1.36, 1045.92]], "batb": [[0, 1.35, 22.95], [1, 1.34, 170.02], [2, 1.32, 12.7]], "batl": NaN}, {"timestamp": 1631553179672, "ltp": 1.35, "tv": 20053.59, "trd": NaN, "batb": [[0, 1.32, 12.7], [1, 1.3, 118.83], [2, 1.06, 284.46]], "batl": [[0, 1.38, 192.65], [1, 1.41, 163.5], [2, 1.42, 156.25]]}, {"timestamp": 1631553182166, "ltp": 1.35, "tv": 20053.59, "trd": NaN, "batb": [[2, 1.1, 299.23]], "batl": [[0, 1.37, 108.51], [1, 1.38, 192.65], [2, 1.41, 163.5]]}, {"timestamp": 1631553182478, "ltp": 1.35, "tv": 20053.59, "trd": NaN, "batb": NaN, "batl": [[0, 1.38, 192.65], [1, 1.41, 163.5], [2, 1.42, 156.25]]}, {"timestamp": 1631553183654, "ltp": 1.35, "tv": 20053.59, "trd": NaN, "batb": [[1, 1.3, 361.3], [2, 1.29, 211.83]], "batl": [[2, 1.42, 239.17]]}, {"timestamp": 1631553186986, "ltp": 1.35, "tv": 20053.59, "trd": NaN, "batb": [[1, 1.3, 118.83], [2, 1.1, 299.23]], "batl": [[0, 1.41, 163.5], [1, 1.42, 239.17], [2, 1.43, 273.52]]}, {"timestamp": 1631553187255, "ltp": 1.35, "tv": 20053.59, "trd": NaN, "batb": NaN, "batl": [[0, 1.42, 82.92], [1, 1.43, 273.52], [2, 1.47, 2]]}, {"timestamp": 1631553189168, "ltp": 1.35, "tv": 20053.59, "trd": NaN, "batb": [[0, 1.39, 156.15], [1, 1.38, 246.13], [2, 1.37, 95.64]], "batl": [[0, 1.41, 16.99], [1, 1.42, 82.92], [2, 1.43, 273.52]]}, {"timestamp": 1631553189963, "ltp": 1.35, "tv": 20053.59, "trd": NaN, "batb": [[0, 1.39, 242.5]], "batl": [[0, 1.4, 7.14], [1, 1.41, 16.99], [2, 1.42, 82.92]]}, {"timestamp": 1631553194194, "ltp": 1.4, "tv": 20060.73, "trd": [[1.4, 1360.63]], "batb": NaN, "batl": [[0, 1.41, 16.99], [1, 1.42, 82.92], [2, 1.43, 459.43]]}, {"timestamp": 1631553195085, "ltp": 1.4, "tv": 20060.73, "trd": NaN, "batb": NaN, "batl": [[0, 1.4, 302], [1, 1.41, 122.42], [2, 1.42, 82.92]]}, {"timestamp": 1631553195669, "ltp": 1.4, "tv": 20060.73, "trd": NaN, "batb": [[2, 1.37, 165.41]], "batl": [[1, 1.41, 284.92], [2, 1.42, 244.67]]}, {"timestamp": 1631553198207, "ltp": 1.4, "tv": 20060.73, "trd": NaN, "batb": [[1, 1.38, 313.59]], "batl": [[0, 1.4, 404.51]]}, {"timestamp": 1631553201009, "ltp": 1.39, "tv": 20460.73, "trd": [[1.39, 979.49]], "batb": [[0, 1.39, 42.5]], "batl": NaN}, {"timestamp": 1631553204211, "ltp": 1.4, "tv": 20464.73, "trd": [[1.4, 1364.63]], "batb": [[1, 1.38, 384.1], [2, 1.37, 319.59]], "batl": [[0, 1.4, 402.51], [2, 1.42, 328.8]]}, {"timestamp": 1631553210093, "ltp": 1.4, "tv": 20464.73, "trd": NaN, "batb": [[0, 1.36, 66.93], [1, 1.35, 99.53], [2, 1.32, 12.7]], "batl": [[0, 1.4, 300], [1, 1.41, 162.5], [2, 1.42, 161.75]]}, {"timestamp": 1631553210783, "ltp": 1.4, "tv": 20464.73, "trd": NaN, "batb": NaN, "batl": [[0, 1.38, 500], [1, 1.42, 161.75], [2, 1.43, 335.41]]}, {"timestamp": 1631553213098, "ltp": 1.4, "tv": 20464.73, "trd": NaN, "batb": [[1, 1.35, 214.31], [2, 1.34, 272.64]], "batl": NaN}, {"timestamp": 1631553214203, "ltp": 1.4, "tv": 20464.73, "trd": NaN, "batb": [[1, 1.35, 114.78]], "batl": [[0, 1.41, 168.5]]}, {"timestamp": 1631553214412, "ltp": 1.4, "tv": 20464.73, "trd": NaN, "batb": NaN, "batl": [[0, 1.42, 161.75], [1, 1.43, 335.41], [2, 1.44, 77.38]]}, {"timestamp": 1631553217112, "ltp": 1.4, "tv": 20464.73, "trd": NaN, "batb": NaN, "batl": [[0, 1.38, 101.35], [1, 1.41, 98.94], [2, 1.42, 161.75]]}, {"timestamp": 1631553218009, "ltp": 1.4, "tv": 20464.73, "trd": NaN, "batb": NaN, "batl": [[0, 1.4, 98.79]]}, {"timestamp": 1631553220593, "ltp": 1.4, "tv": 20464.73, "trd": NaN, "batb": NaN, "batl": [[0, 1.41, 98.94], [1, 1.42, 161.75], [2, 1.43, 335.41]]}, {"timestamp": 1631553221714, "ltp": 1.4, "tv": 20464.73, "trd": NaN, "batb": NaN, "batl": [[0, 1.42, 161.75], [1, 1.43, 335.41], [2, 1.44, 77.38]]}, {"timestamp": 1631553229915, "ltp": 1.4, "tv": 20464.73, "trd": NaN, "batb": [[1, 1.34, 101.04], [2, 1.32, 12.7]], "batl": NaN}, {"timestamp": 1631553231025, "ltp": 1.4, "tv": 20464.73, "trd": NaN, "batb": [[0, 1.37, 59.77], [1, 1.36, 66.93], [2, 1.34, 101.04]], "batl": [[1, 1.43, 149.5]]}, {"timestamp": 1631553231717, "ltp": 1.4, "tv": 20464.73, "trd": NaN, "batb": [[0, 1.36, 66.93], [1, 1.34, 101.04], [2, 1.32, 12.7]], "batl": [[0, 1.41, 166.5], [1, 1.42, 161.75]]}, {"timestamp": 1631553232924, "ltp": 1.4, "tv": 20464.73, "trd": NaN, "batb": [[0, 1.41, 802.14], [1, 1.4, 159.6], [2, 1.39, 10.72]], "batl": [[0, 1.42, 161.75], [1, 1.44, 77.38], [2, 1.45, 117.19]]}, {"timestamp": 1631553234026, "ltp": 1.4, "tv": 20464.73, "trd": NaN, "batb": [[0, 1.41, 884.05]], "batl": [[1, 1.43, 6.99], [2, 1.44, 77.38]]}, {"timestamp": 1631553235518, "ltp": 1.4, "tv": 20464.73, "trd": NaN, "batb": [[2, 1.39, 232.72]], "batl": NaN}, {"timestamp": 1631553236438, "ltp": 1.41, "tv": 21002.93, "trd": [[1.41, 1264.1]], "batb": [[0, 1.41, 614.95]], "batl": NaN}, {"timestamp": 1631553238133, "ltp": 1.42, "tv": 21146.67, "trd": [[1.42, 908.44]], "batb": NaN, "batl": [[0, 1.42, 205.23], [1, 1.43, 93.4]]}, {"timestamp": 1631553241929, "ltp": 1.42, "tv": 21146.67, "trd": NaN, "batb": NaN, "batl": [[0, 1.42, 451.23]]}, {"timestamp": 1631553248637, "ltp": 1.42, "tv": 21146.67, "trd": NaN, "batb": [[2, 1.39, 10.72]], "batl": NaN}, {"timestamp": 1631553249844, "ltp": 1.42, "tv": 21146.67, "trd": NaN, "batb": NaN, "batl": [[0, 1.42, 558.88]]}, {"timestamp": 1631553252447, "ltp": 1.41, "tv": 21570.15, "trd": [[1.41, 1687.58]], "batb": [[0, 1.41, 403.21]], "batl": NaN}, {"timestamp": 1631553258261, "ltp": 1.41, "tv": 21574.49, "trd": [[1.41, 1691.92]], "batb": [[0, 1.41, 401.04]], "batl": NaN}, {"timestamp": 1631553264269, "ltp": 1.42, "tv": 21664.64, "trd": [[1.42, 998.59]], "batb": NaN, "batl": [[0, 1.42, 468.73]]}, {"timestamp": 1631553267765, "ltp": 1.42, "tv": 21664.64, "trd": NaN, "batb": [[0, 1.37, 91.47], [1, 1.32, 12.7], [2, 1.15, 359.07]], "batl": [[0, 1.42, 361.08], [1, 1.47, 2], [2, 1.49, 129.5]]}, {"timestamp": 1631553268557, "ltp": 1.42, "tv": 21664.64, "trd": NaN, "batb": NaN, "batl": [[0, 1.42, 115.08]]}, {"timestamp": 1631553271197, "ltp": 1.42, "tv": 21664.64, "trd": NaN, "batb": [[0, 1.37, 269.98], [1, 1.36, 229.54], [2, 1.32, 12.7]], "batl": NaN}, {"timestamp": 1631553271975, "ltp": 1.42, "tv": 21664.64, "trd": NaN, "batb": [[0, 1.37, 91.47], [1, 1.36, 69.93]], "batl": NaN}, {"timestamp": 1631553273555, "ltp": 1.42, "tv": 21664.64, "trd": NaN, "batb": NaN, "batl": [[0, 1.47, 2], [1, 1.5, 10.79], [2, 1.52, 136.53]]}, {"timestamp": 1631553275068, "ltp": 1.42, "tv": 21664.64, "trd": NaN, "batb": [[0, 1.42, 195.64], [1, 1.41, 133.98], [2, 1.37, 91.47]], "batl": [[0, 1.46, 127.46], [1, 1.47, 112.15], [2, 1.5, 10.79]]}, {"timestamp": 1631553277197, "ltp": 1.42, "tv": 21664.64, "trd": NaN, "batb": NaN, "batl": [[0, 1.44, 113.48], [1, 1.46, 127.46], [2, 1.47, 112.15]]}, {"timestamp": 1631553278178, "ltp": 1.42, "tv": 21664.64, "trd": NaN, "batb": [[2, 1.38, 66.96]], "batl": NaN}, {"timestamp": 1631553278873, "ltp": 1.42, "tv": 21664.64, "trd": NaN, "batb": [[0, 1.37, 91.47], [1, 1.36, 69.93], [2, 1.32, 12.7]], "batl": [[1, 1.47, 2], [2, 1.49, 59.5]]}, {"timestamp": 1631553280157, "ltp": 1.42, "tv": 21664.64, "trd": NaN, "batb": NaN, "batl": [[1, 1.45, 190], [2, 1.47, 2]]}, {"timestamp": 1631553280855, "ltp": 1.42, "tv": 21664.64, "trd": NaN, "batb": [[0, 1.38, 2.64], [1, 1.37, 91.47], [2, 1.36, 69.93]], "batl": [[1, 1.47, 2], [2, 1.49, 59.5]]}, {"timestamp": 1631553282087, "ltp": 1.42, "tv": 21664.64, "trd": NaN, "batb": [[0, 1.38, 64.1], [1, 1.37, 269.98], [2, 1.36, 229.54]], "batl": NaN}, {"timestamp": 1631553282362, "ltp": 1.42, "tv": 21664.64, "trd": NaN, "batb": [[0, 1.38, 2.64]], "batl": NaN}, {"timestamp": 1631553289104, "ltp": 1.42, "tv": 21664.64, "trd": NaN, "batb": [[0, 1.38, 73.1]], "batl": NaN}, {"timestamp": 1631553289387, "ltp": 1.42, "tv": 21664.64, "trd": NaN, "batb": [[0, 1.38, 2.64]], "batl": NaN}, {"timestamp": 1631553291196, "ltp": 1.42, "tv": 21664.64, "trd": NaN, "batb": [[0, 1.38, 16.23]], "batl": [[0, 1.39, 7.19], [1, 1.4, 177.6], [2, 1.41, 132.86]]}, {"timestamp": 1631553294205, "ltp": 1.42, "tv": 21664.64, "trd": NaN, "batb": NaN, "batl": [[0, 1.39, 124.76]]}, {"timestamp": 1631553294789, "ltp": 1.39, "tv": 21665.28, "trd": [[1.39, 980.13]], "batb": NaN, "batl": [[0, 1.39, 124.12], [1, 1.4, 308.64]]}, {"timestamp": 1631553295586, "ltp": 1.39, "tv": 21779.06, "trd": [[1.39, 1093.91]], "batb": NaN, "batl": [[0, 1.39, 10.34]]}, {"timestamp": 1631553296488, "ltp": 1.39, "tv": 21779.06, "trd": NaN, "batb": NaN, "batl": [[0, 1.39, 333.34]]}, {"timestamp": 1631553297606, "ltp": 1.39, "tv": 21779.06, "trd": NaN, "batb": NaN, "batl": [[0, 1.39, 455.98]]}, {"timestamp": 1631553305137, "ltp": 1.39, "tv": 21779.06, "trd": NaN, "batb": [[0, 1.38, 2.64], [1, 1.36, 69.93], [2, 1.35, 60.67]], "batl": [[1, 1.4, 131.04], [2, 1.43, 64.5]]}, {"timestamp": 1631553305843, "ltp": 1.39, "tv": 21779.06, "trd": NaN, "batb": [[1, 1.35, 60.67], [2, 1.34, 100.28]], "batl": [[0, 1.39, 10.34], [1, 1.45, 64.3], [2, 1.47, 2]]}, {"timestamp": 1631553308129, "ltp": 1.39, "tv": 21779.06, "trd": NaN, "batb": [[2, 1.34, 314.11]], "batl": [[2, 1.47, 169.63]]}, {"timestamp": 1631553309030, "ltp": 1.39, "tv": 21779.06, "trd": NaN, "batb": [[2, 1.34, 100.28]], "batl": [[1, 1.43, 70.5], [2, 1.45, 64.3]]}, {"timestamp": 1631553309308, "ltp": 1.39, "tv": 21779.06, "trd": NaN, "batb": NaN, "batl": [[1, 1.45, 64.3], [2, 1.47, 2]]}, {"timestamp": 1631553310834, "ltp": 1.39, "tv": 21779.06, "trd": NaN, "batb": [[0, 1.38, 194.65], [1, 1.37, 153.97], [2, 1.35, 60.67]], "batl": [[1, 1.42, 191.46], [2, 1.43, 123.89]]}, {"timestamp": 1631553312147, "ltp": 1.39, "tv": 21779.06, "trd": NaN, "batb": [[2, 1.36, 69.68]], "batl": NaN}, {"timestamp": 1631553312520, "ltp": 1.39, "tv": 21779.06, "trd": NaN, "batb": NaN, "batl": [[2, 1.43, 190.39]]}, {"timestamp": 1631553313852, "ltp": 1.39, "tv": 21779.06, "trd": NaN, "batb": [[0, 1.38, 2.64], [1, 1.35, 60.67], [2, 1.34, 100.28]], "batl": [[1, 1.45, 64.3], [2, 1.47, 2]]}, {"timestamp": 1631553314713, "ltp": 1.39, "tv": 21799.74, "trd": [[1.39, 1114.59]], "batb": [[0, 1.39, 23.66], [1, 1.38, 2.64], [2, 1.35, 60.67]], "batl": [[0, 1.45, 64.3], [1, 1.47, 2], [2, 1.5, 10.79]]}, {"timestamp": 1631553317036, "ltp": 1.39, "tv": 21799.74, "trd": NaN, "batb": [[2, 1.36, 72.68]], "batl": [[0, 1.43, 67.5], [1, 1.45, 64.3], [2, 1.47, 169.63]]}, {"timestamp": 1631553317837, "ltp": 1.39, "tv": 21803.78, "trd": [[1.39, 1118.63]], "batb": [[0, 1.39, 21.64], [2, 1.35, 60.67]], "batl": [[0, 1.45, 64.3], [1, 1.47, 169.63], [2, 1.48, 106.8]]}, {"timestamp": 1631553323041, "ltp": 1.39, "tv": 21803.78, "trd": NaN, "batb": [[0, 1.43, 339.74], [1, 1.42, 129.28], [2, 1.41, 700.39]], "batl": NaN}, {"timestamp": 1631553323923, "ltp": 1.39, "tv": 21803.78, "trd": NaN, "batb": [[0, 1.43, 415.1]], "batl": [[0, 1.45, 71.2]]}, {"timestamp": 1631553330718, "ltp": 1.39, "tv": 21803.78, "trd": NaN, "batb": NaN, "batl": [[0, 1.45, 378.27]]}, {"timestamp": 1631553334472, "ltp": 1.39, "tv": 21803.78, "trd": NaN, "batb": [[0, 1.43, 214.49]], "batl": NaN}, {"timestamp": 1631553336571, "ltp": 1.43, "tv": 21812.8, "trd": [[1.43, 2358.95]], "batb": [[0, 1.43, 209.98]], "batl": NaN}, {"timestamp": 1631553343201, "ltp": 1.43, "tv": 21812.8, "trd": NaN, "batb": [[2, 1.39, 108.33]], "batl": [[0, 1.45, 307.07]]}, {"timestamp": 1631553343680, "ltp": 1.43, "tv": 21812.8, "trd": NaN, "batb": [[0, 1.39, 108.33], [1, 1.38, 79.06], [2, 1.36, 70.86]], "batl": [[0, 1.47, 2], [1, 1.5, 10.79], [2, 1.57, 58.02]]}, {"timestamp": 1631553344539, "ltp": 1.43, "tv": 21812.8, "trd": NaN, "batb": [[0, 1.45, 1.8], [1, 1.39, 108.33], [2, 1.38, 79.06]], "batl": NaN}, {"timestamp": 1631553346962, "ltp": 1.43, "tv": 21812.8, "trd": NaN, "batb": [[2, 1.38, 264.81]], "batl": [[2, 1.54, 58.77]]}, {"timestamp": 1631553347375, "ltp": 1.43, "tv": 21812.8, "trd": NaN, "batb": NaN, "batl": [[2, 1.57, 176.11]]}, {"timestamp": 1631553351047, "ltp": 1.43, "tv": 21812.8, "trd": NaN, "batb": [[0, 1.39, 108.33], [1, 1.38, 264.81], [2, 1.37, 153.93]], "batl": NaN}, {"timestamp": 1631553354164, "ltp": 1.43, "tv": 21812.8, "trd": NaN, "batb": NaN, "batl": [[2, 1.54, 61.77]]}, {"timestamp": 1631553354484, "ltp": 1.43, "tv": 21812.8, "trd": NaN, "batb": NaN, "batl": [[2, 1.57, 176.11]]}, {"timestamp": 1631553358408, "ltp": 1.43, "tv": 21812.8, "trd": NaN, "batb": [[1, 1.38, 79.06], [2, 1.36, 70.86]], "batl": NaN}, {"timestamp": 1631553361160, "ltp": 1.51, "tv": 21826.11, "trd": [[1.47, 338.36], [1.5, 174.87], [1.51, 0.52]], "batb": [[0, 1.51, 2.48], [1, 1.5, 254.38], [2, 1.39, 108.33]], "batl": [[0, 1.56, 22.99], [1, 1.57, 175.59], [2, 1.58, 561.91]]}, {"timestamp": 1631553362181, "ltp": 1.53, "tv": 21829.43, "trd": [[1.53, 3.32]], "batb": [[0, 1.53, 141.4], [1, 1.52, 95.77], [2, 1.51, 2.48]], "batl": [[0, 1.54, 6.49], [1, 1.56, 22.99], [2, 1.57, 175.59]]}, {"timestamp": 1631553366204, "ltp": 1.53, "tv": 21829.43, "trd": NaN, "batb": NaN, "batl": [[1, 1.55, 94.91], [2, 1.56, 22.99]]}, {"timestamp": 1631553367091, "ltp": 1.53, "tv": 21902.41, "trd": [[1.53, 63.02], [1.54, 13.28]], "batb": [[0, 1.53, 111.55]], "batl": [[0, 1.55, 94.91], [1, 1.56, 22.99], [2, 1.57, 175.59]]}, {"timestamp": 1631553368196, "ltp": 1.53, "tv": 21902.41, "trd": NaN, "batb": [[0, 1.53, 58.74]], "batl": [[0, 1.54, 185], [1, 1.55, 94.91], [2, 1.56, 22.99]]}, {"timestamp": 1631553370681, "ltp": 1.54, "tv": 21915.37, "trd": [[1.54, 26.24]], "batb": [[1, 1.52, 163.22], [2, 1.51, 101.23]], "batl": [[0, 1.54, 262.63]]}, {"timestamp": 1631553372804, "ltp": 1.52, "tv": 22315.37, "trd": [[1.52, 282.52], [1.53, 180.51]], "batb": [[0, 1.52, 21.96], [1, 1.51, 101.23], [2, 1.5, 254.38]], "batl": NaN}, {"timestamp": 1631553375197, "ltp": 1.52, "tv": 22315.37, "trd": NaN, "batb": [[2, 1.46, 70.16]], "batl": [[0, 1.54, 178.52], [1, 1.57, 84.47], [2, 1.71, 49.5]]}, {"timestamp": 1631553376101, "ltp": 1.54, "tv": 22319.37, "trd": [[1.54, 30.24]], "batb": [[0, 1.51, 2.48], [1, 1.46, 70.16], [2, 1.38, 24.28]], "batl": [[0, 1.54, 174.52], [1, 1.71, 49.5], [2, 1.72, 50.66]]}, {"timestamp": 1631553376702, "ltp": 1.54, "tv": 22319.37, "trd": NaN, "batb": NaN, "batl": [[0, 1.77, 52.5], [1, 44, 7.23], [2, 1.72, 0]]}, {"timestamp": 1631553378188, "ltp": 1.54, "tv": 22319.37, "trd": NaN, "batb": [[2, 1.4, 3.11]], "batl": NaN}, {"timestamp": 1631553379144, "ltp": 1.54, "tv": 22319.37, "trd": NaN, "batb": [[1, 1.44, 71.83], [2, 1.43, 3.22]], "batl": NaN}, {"timestamp": 1631553379995, "ltp": 1.54, "tv": 22319.37, "trd": NaN, "batb": [[2, 1.38, 24.28]], "batl": [[0, 1.71, 49.5], [1, 1.77, 52.5], [2, 44, 7.23]]}, {"timestamp": 1631553380789, "ltp": 1.54, "tv": 22319.37, "trd": NaN, "batb": NaN, "batl": [[0, 1.53, 573.82]]}, {"timestamp": 1631553382119, "ltp": 1.53, "tv": 22355.61, "trd": [[1.53, 216.74]], "batb": NaN, "batl": [[0, 1.53, 537.58], [1, 1.58, 19.25], [2, 1.77, 52.5]]}, {"timestamp": 1631553382927, "ltp": 1.53, "tv": 22855.29, "trd": [[1.53, 716.42]], "batb": NaN, "batl": [[0, 1.53, 287.74], [1, 1.59, 122.58], [2, 1.6, 78.52]]}, {"timestamp": 1631553383937, "ltp": 1.53, "tv": 22855.29, "trd": NaN, "batb": NaN, "batl": [[1, 1.71, 50.5], [2, 1.77, 52.5]]}, {"timestamp": 1631553386017, "ltp": 1.53, "tv": 22855.29, "trd": NaN, "batb": [[2, 1.43, 3.22]], "batl": NaN}, {"timestamp": 1631553386919, "ltp": 1.53, "tv": 23007.19, "trd": [[1.53, 868.32]], "batb": [[0, 1.53, 37.11], [1, 1.52, 96.51], [2, 1.51, 2.48]], "batl": [[0, 1.57, 93.01], [1, 1.58, 82.84]]}, {"timestamp": 1631553388943, "ltp": 1.53, "tv": 23007.19, "trd": NaN, "batb": [[0, 1.44, 71.83], [1, 1.38, 24.28], [2, 1.32, 12.7]], "batl": [[0, 1.77, 52.5], [1, 44, 7.23], [2, 810, 0.07]]}, {"timestamp": 1631553390113, "ltp": 1.53, "tv": 23007.19, "trd": NaN, "batb": NaN, "batl": [[0, 1.56, 66.95], [1, 1.71, 54.5], [2, 1.77, 52.5]]}, {"timestamp": 1631553390931, "ltp": 1.53, "tv": 23007.19, "trd": NaN, "batb": NaN, "batl": [[0, 1.77, 52.5], [1, 44, 7.23], [2, 810, 0.07]]}, {"timestamp": 1631553391832, "ltp": 1.53, "tv": 23007.19, "trd": NaN, "batb": [[1, 1.43, 90.4], [2, 1.42, 130.4]], "batl": [[0, 1.7, 113], [1, 1.71, 61.72], [2, 1.77, 52.5]]}, {"timestamp": 1631553393211, "ltp": 1.53, "tv": 23007.19, "trd": NaN, "batb": [[1, 1.43, 93.62]], "batl": NaN}, {"timestamp": 1631553393843, "ltp": 1.53, "tv": 23007.19, "trd": NaN, "batb": [[1, 1.43, 90.4]], "batl": [[1, 1.71, 114.22]]}, {"timestamp": 1631553400035, "ltp": 1.53, "tv": 23007.19, "trd": NaN, "batb": [[1, 1.43, 93.62]], "batl": NaN}, {"timestamp": 1631553400344, "ltp": 1.53, "tv": 23007.19, "trd": NaN, "batb": [[1, 1.43, 90.4]], "batl": NaN}, {"timestamp": 1631553407042, "ltp": 1.53, "tv": 23007.19, "trd": NaN, "batb": [[1, 1.43, 93.62]], "batl": NaN}, {"timestamp": 1631553407532, "ltp": 1.53, "tv": 23007.19, "trd": NaN, "batb": [[1, 1.43, 90.4]], "batl": NaN}, {"timestamp": 1631553409742, "ltp": 1.53, "tv": 23007.19, "trd": NaN, "batb": [[1, 1.38, 24.28], [2, 1.32, 12.7]], "batl": NaN}, {"timestamp": 1631553410758, "ltp": 1.53, "tv": 23007.19, "trd": NaN, "batb": [[1, 1.43, 3.22], [2, 1.38, 24.28]], "batl": [[0, 1.7, 119.01]]}, {"timestamp": 1631553412147, "ltp": 1.53, "tv": 23007.19, "trd": NaN, "batb": [[1, 1.38, 24.28], [2, 1.32, 12.7]], "batl": NaN}, {"timestamp": 1631553413146, "ltp": 1.68, "tv": 23019.09, "trd": [[1.68, 11.9]], "batb": [[0, 1.68, 3.91], [1, 1.67, 40.78], [2, 1.65, 77.52]], "batl": [[2, 1.73, 86.72]]}, {"timestamp": 1631553413572, "ltp": 1.68, "tv": 23019.09, "trd": NaN, "batb": NaN, "batl": [[2, 1.73, 17.34]]}, {"timestamp": 1631553417165, "ltp": 1.68, "tv": 23019.09, "trd": NaN, "batb": NaN, "batl": [[2, 1.72, 58.57]]}, {"timestamp": 1631553417644, "ltp": 1.68, "tv": 23026.87, "trd": [[1.68, 19.68]], "batb": [[0, 1.67, 40.8], [1, 1.65, 77.52], [2, 1.64, 71.3]], "batl": NaN}, {"timestamp": 1631553419969, "ltp": 1.68, "tv": 23026.87, "trd": NaN, "batb": NaN, "batl": [[0, 1.7, 230.01], [1, 1.71, 173.13]]}, {"timestamp": 1631553421869, "ltp": 1.7, "tv": 23061.69, "trd": [[1.7, 34.82]], "batb": NaN, "batl": [[0, 1.7, 195.19]]}, {"timestamp": 1631553422867, "ltp": 1.7, "tv": 23212.29, "trd": [[1.7, 185.42]], "batb": [[1, 1.65, 69.66], [2, 1.57, 50.77]], "batl": [[0, 1.7, 117.01]]}, {"timestamp": 1631553423354, "ltp": 1.7, "tv": 23212.29, "trd": NaN, "batb": [[0, 1.67, 40.78]], "batl": NaN}, {"timestamp": 1631553425051, "ltp": 1.7, "tv": 23212.29, "trd": NaN, "batb": NaN, "batl": [[0, 1.7, 172.16]]}, {"timestamp": 1631553426061, "ltp": 1.7, "tv": 23212.29, "trd": NaN, "batb": [[1, 1.66, 70.46], [2, 1.65, 69.66]], "batl": [[0, 1.68, 1.71], [1, 1.7, 172.16], [2, 1.71, 224.92]]}, {"timestamp": 1631553426377, "ltp": 1.7, "tv": 23212.29, "trd": NaN, "batb": NaN, "batl": [[1, 1.7, 187.13]]}, {"timestamp": 1631553427861, "ltp": 1.7, "tv": 23212.29, "trd": NaN, "batb": NaN, "batl": [[1, 1.7, 172.16]]}, {"timestamp": 1631553430785, "ltp": 1.7, "tv": 23212.29, "trd": NaN, "batb": NaN, "batl": [[0, 1.7, 187.13], [1, 1.71, 224.92], [2, 1.72, 119]]}, {"timestamp": 1631553436081, "ltp": 1.7, "tv": 23212.29, "trd": NaN, "batb": [[0, 1.57, 50.77], [1, 1.38, 21.64], [2, 1.32, 12.7]], "batl": [[0, 1.7, 117.01], [1, 1.93, 47.5], [2, 2, 24.18]]}, {"timestamp": 1631553436459, "ltp": 1.7, "tv": 23212.29, "trd": NaN, "batb": NaN, "batl": [[0, 1.7, 6.01]]}, {"timestamp": 1631553439200, "ltp": 1.7, "tv": 23212.29, "trd": NaN, "batb": [[1, 1.56, 109.99], [2, 1.55, 89.04]], "batl": [[2, 44, 7.23]]}, {"timestamp": 1631553442119, "ltp": 1.7, "tv": 23314.29, "trd": [[1.7, 287.42]], "batb": NaN, "batl": [[0, 1.59, 6.29], [1, 1.6, 13.23], [2, 1.61, 71.5]]}, {"timestamp": 1631553443186, "ltp": 1.7, "tv": 23314.29, "trd": NaN, "batb": NaN, "batl": [[1, 1.6, 86.25], [2, 1.61, 148.58]]}, {"timestamp": 1631553445198, "ltp": 1.59, "tv": 23326.87, "trd": [[1.59, 12.58]], "batb": NaN, "batl": [[0, 1.6, 86.25], [1, 1.61, 148.58], [2, 1.64, 430.99]]}, {"timestamp": 1631553446988, "ltp": 1.59, "tv": 23326.87, "trd": NaN, "batb": NaN, "batl": [[0, 1.59, 49.68], [1, 1.6, 86.25], [2, 1.61, 148.58]]}, {"timestamp": 1631553448099, "ltp": 1.59, "tv": 23326.87, "trd": NaN, "batb": NaN, "batl": [[1, 1.6, 134.64]]}, {"timestamp": 1631553450485, "ltp": 1.59, "tv": 23326.87, "trd": NaN, "batb": NaN, "batl": [[0, 1.59, 165.68]]}, {"timestamp": 1631553453195, "ltp": 1.59, "tv": 23326.87, "trd": NaN, "batb": NaN, "batl": [[0, 1.59, 116], [1, 1.6, 73.02], [2, 1.61, 77.08]]}, {"timestamp": 1631553453821, "ltp": 1.59, "tv": 23326.87, "trd": NaN, "batb": [[0, 1.45, 68.56], [1, 1.38, 21.64], [2, 1.32, 12.7]], "batl": [[0, 2.1, 6.55], [1, 810, 0.07], [2, 1.61, 0]]}, {"timestamp": 1631553456026, "ltp": 1.59, "tv": 23326.87, "trd": NaN, "batb": [[0, 1.59, 53.33], [1, 1.45, 68.56], [2, 1.38, 21.64]], "batl": NaN}, {"timestamp": 1631553457133, "ltp": 1.59, "tv": 23326.87, "trd": NaN, "batb": NaN, "batl": [[0, 1.98, 36.75], [1, 2.1, 6.55], [2, 810, 0.07]]}, {"timestamp": 1631553457400, "ltp": 1.59, "tv": 23326.87, "trd": NaN, "batb": NaN, "batl": [[0, 2.1, 6.55], [1, 810, 0.07], [2, 810, 0]]}, {"timestamp": 1631553459201, "ltp": 1.59, "tv": 23326.87, "trd": NaN, "batb": NaN, "batl": [[0, 1.65, 20.9], [1, 2.1, 6.55], [2, 810, 0.07]]}, {"timestamp": 1631553459516, "ltp": 1.59, "tv": 23326.87, "trd": NaN, "batb": [[0, 1.61, 67.1], [1, 1.6, 78.39], [2, 1.59, 53.33]], "batl": [[0, 1.65, 81.96], [1, 1.66, 68.72], [2, 2.1, 6.55]]}, {"timestamp": 1631553462827, "ltp": 1.59, "tv": 23326.87, "trd": NaN, "batb": [[0, 1.59, 53.33], [1, 1.45, 68.56], [2, 1.38, 21.64]], "batl": [[0, 2.1, 6.55], [1, 810, 0.07], [2, 2.1, 0]]}, {"timestamp": 1631553464191, "ltp": 1.59, "tv": 23331.21, "trd": [[1.59, 16.92]], "batb": [[0, 1.45, 68.56], [1, 1.38, 21.64], [2, 1.32, 12.7]], "batl": [[0, 1.98, 40.75], [1, 2.1, 6.55], [2, 810, 0.07]]}, {"timestamp": 1631553464936, "ltp": 1.59, "tv": 23331.21, "trd": NaN, "batb": NaN, "batl": [[0, 2.1, 6.55], [1, 810, 0.07], [2, 810, 0]]}, {"timestamp": 1631553465807, "ltp": 1.59, "tv": 23331.21, "trd": NaN, "batb": [[1, 1.44, 170.52], [2, 1.43, 126.44]], "batl": [[0, 1.89, 83.01], [1, 1.91, 85.21], [2, 2.1, 6.55]]}, {"timestamp": 1631553468132, "ltp": 1.59, "tv": 23331.21, "trd": NaN, "batb": NaN, "batl": [[2, 1.98, 41.25]]}, {"timestamp": 1631553468417, "ltp": 1.59, "tv": 23331.21, "trd": NaN, "batb": NaN, "batl": [[2, 2.1, 6.55]]}, {"timestamp": 1631553475133, "ltp": 1.59, "tv": 23331.21, "trd": NaN, "batb": NaN, "batl": [[2, 1.98, 37.25]]}, {"timestamp": 1631553475443, "ltp": 1.59, "tv": 23331.21, "trd": NaN, "batb": [[1, 1.38, 21.64], [2, 1.32, 12.7]], "batl": [[2, 810, 0.07]]}, {"timestamp": 1631553478031, "ltp": 1.59, "tv": 23331.21, "trd": NaN, "batb": [[0, 1.81, 82.88], [1, 1.8, 155.34], [2, 1.79, 41.44]], "batl": [[0, 1.89, 97.2], [2, 1.98, 526.23]]}, {"timestamp": 1631553479133, "ltp": 1.85, "tv": 23342.03, "trd": [[1.85, 10.82]], "batb": [[0, 1.88, 22.7], [1, 1.83, 65.74], [2, 1.81, 148.95]], "batl": [[1, 1.9, 78.96], [2, 1.91, 124.69]]}, {"timestamp": 1631553479724, "ltp": 1.85, "tv": 23342.03, "trd": NaN, "batb": [[2, 1.81, 115.8]], "batl": [[1, 1.9, 15.8], [2, 1.91, 93.11]]}, {"timestamp": 1631553483053, "ltp": 1.88, "tv": 23387.44, "trd": [[1.88, 45.41]], "batb": [[0, 1.83, 65.74], [1, 1.81, 115.8], [2, 1.8, 75.51]], "batl": [[0, 1.88, 61.35], [1, 1.89, 135.65], [2, 1.9, 15.8]]}, {"timestamp": 1631553487655, "ltp": 1.88, "tv": 23387.44, "trd": NaN, "batb": [[0, 1.85, 28.53], [1, 1.83, 65.74], [2, 1.81, 115.8]], "batl": NaN}, {"timestamp": 1631553491462, "ltp": 1.88, "tv": 23387.44, "trd": NaN, "batb": NaN, "batl": [[0, 1.88, 171.35], [1, 1.89, 122.89]]}, {"timestamp": 1631553492961, "ltp": 1.88, "tv": 23387.44, "trd": NaN, "batb": NaN, "batl": [[0, 1.88, 173.06]]}, {"timestamp": 1631553494240, "ltp": 1.88, "tv": 23387.44, "trd": NaN, "batb": [[1, 1.83, 79.13]], "batl": NaN}, {"timestamp": 1631553496857, "ltp": 1.89, "tv": 23683.39, "trd": [[1.88, 218.47], [1.89, 122.89]], "batb": NaN, "batl": [[0, 1.9, 15.8], [1, 1.91, 93.11], [2, 1.92, 7.9]]}, {"timestamp": 1631553497480, "ltp": 1.89, "tv": 23683.39, "trd": NaN, "batb": [[1, 1.81, 16.58], [2, 1.8, 75.51]], "batl": [[1, 1.91, 7.9]]}, {"timestamp": 1631553500065, "ltp": 1.89, "tv": 23729.72, "trd": [[1.89, 123.25], [1.9, 45.97]], "batb": [[0, 1.86, 32.65], [1, 1.85, 28.53], [2, 1.81, 16.58]], "batl": [[0, 1.91, 7.9], [1, 1.92, 7.9], [2, 1.98, 526.23]]}, {"timestamp": 1631553500639, "ltp": 1.89, "tv": 23729.72, "trd": NaN, "batb": [[2, 1.84, 70.87]], "batl": [[0, 1.9, 74.38], [1, 1.91, 7.9], [2, 1.92, 91.88]]}, {"timestamp": 1631553503867, "ltp": 1.9, "tv": 23743.54, "trd": [[1.9, 59.79]], "batb": NaN, "batl": [[0, 1.9, 60.56]]}, {"timestamp": 1631553506079, "ltp": 1.89, "tv": 23743.58, "trd": [[1.89, 123.29]], "batb": NaN, "batl": NaN}, {"timestamp": 1631553507073, "ltp": 1.89, "tv": 23743.58, "trd": NaN, "batb": [[2, 1.84, 79.28]], "batl": NaN}, {"timestamp": 1631553509977, "ltp": 1.89, "tv": 23743.58, "trd": NaN, "batb": NaN, "batl": [[2, 1.92, 106.89]]}, {"timestamp": 1631553513062, "ltp": 1.89, "tv": 24225.48, "trd": [[1.89, 584.83], [1.9, 80.15]], "batb": NaN, "batl": [[0, 1.89, 112.28], [1, 1.9, 284.2], [2, 1.91, 7.9]]}, {"timestamp": 1631553515755, "ltp": 1.89, "tv": 24225.48, "trd": NaN, "batb": [[2, 1.84, 90.97]], "batl": [[1, 1.9, 299.03]]}, {"timestamp": 1631553519543, "ltp": 1.89, "tv": 24233.58, "trd": [[1.89, 592.94]], "batb": NaN, "batl": [[0, 1.89, 104.17]]}, {"timestamp": 1631553521278, "ltp": 1.89, "tv": 24233.58, "trd": NaN, "batb": NaN, "batl": [[1, 1.9, 244]]}, {"timestamp": 1631553524176, "ltp": 1.89, "tv": 24233.58, "trd": NaN, "batb": NaN, "batl": [[2, 1.91, 103.17]]}, {"timestamp": 1631553538405, "ltp": 1.86, "tv": 24241.02, "trd": [[1.86, 7.44]], "batb": [[0, 1.86, 28.93]], "batl": NaN}, {"timestamp": 1631553541687, "ltp": 1.9, "tv": 24641.02, "trd": [[1.89, 801.27], [1.9, 271.81]], "batb": [[1, 1.85, 60.09]], "batl": [[0, 1.9, 148.17], [1, 1.91, 103.17], [2, 1.92, 22.91]]}, {"timestamp": 1631553544811, "ltp": 1.9, "tv": 24641.02, "trd": NaN, "batb": NaN, "batl": [[0, 1.89, 10.12], [1, 1.9, 148.17], [2, 1.91, 103.17]]}, {"timestamp": 1631553551921, "ltp": 1.86, "tv": 24651.02, "trd": [[1.86, 17.44]], "batb": [[0, 1.86, 23.93]], "batl": NaN}, {"timestamp": 1631553559134, "ltp": 1.89, "tv": 24659.02, "trd": [[1.89, 809.27]], "batb": NaN, "batl": [[0, 1.89, 6.12]]}, {"timestamp": 1631553567557, "ltp": 1.89, "tv": 24659.02, "trd": NaN, "batb": NaN, "batl": [[0, 1.88, 7], [1, 1.89, 6.12], [2, 1.9, 148.17]]}, {"timestamp": 1631553572826, "ltp": 1.86, "tv": 24695.15, "trd": [[1.86, 53.57]], "batb": [[0, 1.86, 5.86]], "batl": NaN}, {"timestamp": 1631553576138, "ltp": 1.86, "tv": 24695.15, "trd": NaN, "batb": NaN, "batl": [[0, 1.88, 18.81]]}, {"timestamp": 1631553582052, "ltp": 1.88, "tv": 24703.16, "trd": [[1.88, 226.47]], "batb": NaN, "batl": [[0, 1.88, 14.81]]}, {"timestamp": 1631553591658, "ltp": 1.88, "tv": 24732.77, "trd": [[1.88, 256.08]], "batb": [[0, 1.88, 13.06], [1, 1.86, 5.86], [2, 1.85, 60.09]], "batl": [[0, 1.89, 6.12], [1, 1.9, 148.17], [2, 1.91, 103.17]]}, {"timestamp": 1631553594755, "ltp": 1.88, "tv": 24732.77, "trd": NaN, "batb": [[1, 1.87, 26.64], [2, 1.86, 5.86]], "batl": NaN}, {"timestamp": 1631553596891, "ltp": 1.88, "tv": 24732.77, "trd": NaN, "batb": [[0, 1.88, 40.93]], "batl": NaN}, {"timestamp": 1631553600094, "ltp": 1.88, "tv": 24732.77, "trd": NaN, "batb": [[0, 1.88, 70.25]], "batl": [[1, 1.9, 154.5]]}, {"timestamp": 1631553602190, "ltp": 1.89, "tv": 24745.01, "trd": [[1.89, 821.51]], "batb": [[0, 1.89, 21.75], [1, 1.88, 70.25], [2, 1.87, 26.64]], "batl": [[0, 1.9, 154.5], [1, 1.91, 103.17], [2, 1.92, 27.63]]}, {"timestamp": 1631553607601, "ltp": 1.89, "tv": 24745.01, "trd": NaN, "batb": [[0, 1.89, 49.62]], "batl": NaN}, {"timestamp": 1631553608808, "ltp": 1.89, "tv": 24745.01, "trd": NaN, "batb": [[1, 1.88, 40.93], [2, 1.72, 40.59]], "batl": [[0, 1.9, 148.17], [1, 1.98, 50.25], [2, 2, 27.27]]}, {"timestamp": 1631553609806, "ltp": 1.89, "tv": 24745.01, "trd": NaN, "batb": NaN, "batl": [[0, 2, 27.27], [1, 810, 0.07], [2, 2, 0]]}, {"timestamp": 1631553616081, "ltp": 1.88, "tv": 24867.37, "trd": [[1.88, 279.2], [1.89, 920.75]], "batb": [[0, 1.88, 29.38], [1, 1.72, 40.59], [2, 1.71, 36.76]], "batl": NaN}, {"timestamp": 1631553620690, "ltp": 1.88, "tv": 24926.11, "trd": [[1.88, 337.95]], "batb": [[0, 1.71, 36.76], [1, 1.66, 38.78], [2, 1.57, 1.95]], "batl": NaN}, {"timestamp": 1631553622208, "ltp": 1.88, "tv": 24926.11, "trd": NaN, "batb": [[0, 1.71, 135.43], [1, 1.7, 62.54], [2, 1.66, 38.78]], "batl": [[1, 2.02, 62.72], [2, 2.04, 69.4]]}, {"timestamp": 1631553622415, "ltp": 1.88, "tv": 24926.11, "trd": NaN, "batb": NaN, "batl": [[1, 2.04, 69.4], [2, 810, 0.07]]}, {"timestamp": 1631553624620, "ltp": 2.0, "tv": 24930.36, "trd": [[2, 4.25]], "batb": [[0, 1.71, 153.61]], "batl": [[0, 2, 23.02], [1, 2.04, 116.63], [2, 2.06, 67.53]]}, {"timestamp": 1631553632005, "ltp": 2.0, "tv": 24930.36, "trd": NaN, "batb": [[0, 1.71, 36.76], [1, 1.66, 38.78], [2, 1.57, 1.95]], "batl": NaN}, {"timestamp": 1631553633135, "ltp": 2.0, "tv": 24953.38, "trd": [[2, 27.27]], "batb": NaN, "batl": [[0, 2.04, 116.63], [1, 2.06, 67.53], [2, 810, 0.07]]}, {"timestamp": 1631553635142, "ltp": 2.0, "tv": 24957.65, "trd": [[2, 31.54]], "batb": [[0, 1.96, 56.06], [1, 1.95, 15.38], [2, 1.94, 86.67]], "batl": [[0, 2.04, 409.46]]}, {"timestamp": 1631553636133, "ltp": 2.0, "tv": 24962.8, "trd": [[2, 36.69]], "batb": [[2, 1.94, 135.93]], "batl": [[1, 2.06, 82.09], [2, 2.08, 7.28]]}, {"timestamp": 1631553639934, "ltp": 2.0, "tv": 24962.8, "trd": NaN, "batb": [[0, 1.97, 32.23], [1, 1.96, 56.06], [2, 1.95, 15.38]], "batl": NaN}, {"timestamp": 1631553641716, "ltp": 2.0, "tv": 24962.8, "trd": NaN, "batb": NaN, "batl": [[2, 2.08, 15.47]]}, {"timestamp": 1631553647956, "ltp": 2.0, "tv": 24962.8, "trd": NaN, "batb": NaN, "batl": [[0, 2.02, 8.49], [1, 2.04, 409.46], [2, 2.06, 82.09]]}, {"timestamp": 1631553648366, "ltp": 1.98, "tv": 24963.19, "trd": [[1.98, 0.39]], "batb": NaN, "batl": NaN}, {"timestamp": 1631553653154, "ltp": 1.98, "tv": 24963.19, "trd": NaN, "batb": [[1, 1.94, 49.26], [2, 1.85, 33.77]], "batl": [[0, 2.08, 8.19], [1, 2.1, 7.95], [2, 810, 0.07]]}, {"timestamp": 1631553653750, "ltp": 1.98, "tv": 24963.19, "trd": NaN, "batb": [[0, 1.81, 57], [1, 1.57, 1.95], [2, 1.4, 149.61]], "batl": [[0, 2.1, 7.95], [1, 810, 0.07], [2, 810, 0]]}, {"timestamp": 1631553656159, "ltp": 1.98, "tv": 24963.19, "trd": NaN, "batb": [[0, 1.82, 74.61], [1, 1.81, 57], [2, 1.8, 101.43]], "batl": [[1, 2.14, 96.91], [2, 2.16, 58.48]]}, {"timestamp": 1631553657062, "ltp": 1.98, "tv": 24963.19, "trd": NaN, "batb": [[0, 1.85, 28.77], [1, 1.82, 74.61], [2, 1.81, 57]], "batl": [[0, 2.08, 8.19], [1, 2.1, 7.95], [2, 2.14, 96.91]]}, {"timestamp": 1631553657379, "ltp": 1.98, "tv": 24963.19, "trd": NaN, "batb": [[0, 1.81, 57], [1, 1.57, 1.95], [2, 1.4, 149.61]], "batl": [[0, 2.1, 7.95], [1, 810, 0.07], [2, 2.14, 0]]}, {"timestamp": 1631553660179, "ltp": 1.98, "tv": 24963.19, "trd": NaN, "batb": [[0, 2.04, 100.49], [1, 1.81, 57], [2, 1.57, 1.95]], "batl": [[1, 2.12, 9.22], [2, 2.16, 433.13]]}, {"timestamp": 1631553661164, "ltp": 2.06, "tv": 24968.09, "trd": [[2.06, 4.9]], "batb": [[0, 2.04, 98.53], [1, 2.02, 43.05], [2, 1.91, 51.69]], "batl": NaN}, {"timestamp": 1631553667353, "ltp": 2.06, "tv": 24968.09, "trd": NaN, "batb": [[2, 1.97, 25.17]], "batl": [[2, 2.14, 7.25]]}, {"timestamp": 1631553671288, "ltp": 2.06, "tv": 24968.09, "trd": NaN, "batb": NaN, "batl": [[1, 2.14, 7.25], [2, 2.16, 439.85]]}, {"timestamp": 1631553674464, "ltp": 2.06, "tv": 24968.09, "trd": NaN, "batb": NaN, "batl": [[1, 2.12, 13.97], [2, 2.14, 7.25]]}, {"timestamp": 1631553676054, "ltp": 2.06, "tv": 24968.09, "trd": NaN, "batb": [[0, 1.93, 27.93], [1, 1.91, 51.69], [2, 1.4, 149.61]], "batl": [[0, 810, 0.07], [1, 2.12, 0], [2, 2.14, 0]]}, {"timestamp": 1631553679178, "ltp": 2.06, "tv": 24968.09, "trd": NaN, "batb": [[0, 1.97, 27.17], [1, 1.93, 27.93], [2, 1.91, 51.69]], "batl": [[0, 2.12, 8.21], [1, 2.14, 7.75], [2, 810, 0.07]]}, {"timestamp": 1631553679389, "ltp": 2.06, "tv": 24968.09, "trd": NaN, "batb": [[0, 1.93, 27.93], [1, 1.91, 51.69], [2, 1.4, 149.61]], "batl": [[0, 2.14, 7.75], [1, 810, 0.07], [2, 810, 0]]}, {"timestamp": 1631553682182, "ltp": 2.06, "tv": 24968.09, "trd": NaN, "batb": NaN, "batl": [[0, 2.08, 20.44], [1, 2.14, 7.75], [2, 810, 0.07]]}, {"timestamp": 1631553683084, "ltp": 2.06, "tv": 24968.09, "trd": NaN, "batb": NaN, "batl": [[0, 2.14, 7.75], [1, 810, 0.07], [2, 810, 0]]}, {"timestamp": 1631553684664, "ltp": 2.06, "tv": 24968.09, "trd": NaN, "batb": NaN, "batl": [[1, 810, 0]]}, {"timestamp": 1631553690190, "ltp": 2.06, "tv": 24968.09, "trd": NaN, "batb": [[0, 1.97, 27.17], [1, 1.93, 27.93], [2, 1.91, 51.69]], "batl": [[0, 2.12, 8.46], [1, 2.14, 7.75]]}, {"timestamp": 1631553690668, "ltp": 2.06, "tv": 24968.09, "trd": NaN, "batb": [[0, 1.93, 27.93], [1, 1.91, 51.69], [2, 1.4, 149.61]], "batl": [[0, 2.14, 7.75], [1, 2.14, 0]]}, {"timestamp": 1631553694091, "ltp": 2.06, "tv": 24968.09, "trd": NaN, "batb": [[0, 1.97, 25.17], [1, 1.93, 27.93], [2, 1.91, 51.69]], "batl": NaN}, {"timestamp": 1631553694298, "ltp": 2.06, "tv": 24968.09, "trd": NaN, "batb": [[0, 1.93, 27.93], [1, 1.91, 51.69], [2, 1.4, 149.61]], "batl": NaN}, {"timestamp": 1631553697193, "ltp": 2.06, "tv": 24968.09, "trd": NaN, "batb": NaN, "batl": [[1, 2.2, 13.73], [2, 2.24, 418.2]]}, {"timestamp": 1631553698082, "ltp": 2.12, "tv": 24972.85, "trd": [[2.12, 4.76]], "batb": [[0, 2.08, 38.94], [1, 2, 44.48], [2, 1.93, 27.93]], "batl": NaN}, {"timestamp": 1631553703605, "ltp": 2.12, "tv": 24972.85, "trd": NaN, "batb": [[1, 2.04, 8.62], [2, 2.02, 8.24]], "batl": [[1, 2.16, 6.72], [2, 2.18, 7.75]]}, {"timestamp": 1631553711139, "ltp": 2.16, "tv": 24990.12, "trd": [[2.14, 7.75], [2.16, 9.52]], "batb": NaN, "batl": [[0, 2.2, 13.73], [1, 2.24, 418.2], [2, 2.18, 0]]}, {"timestamp": 1631553711305, "ltp": 2.16, "tv": 24990.12, "trd": NaN, "batb": [[1, 2, 44.48], [2, 1.93, 27.93]], "batl": NaN}, {"timestamp": 1631553717913, "ltp": 2.16, "tv": 24990.12, "trd": NaN, "batb": [[0, 2.14, 31], [2, 1.5, 107.72]], "batl": NaN}, {"timestamp": 1631553724730, "ltp": 2.2, "tv": 24990.99, "trd": [[2.2, 0.87]], "batb": NaN, "batl": NaN}, {"timestamp": 1631553729060, "ltp": 2.2, "tv": 24990.99, "trd": NaN, "batb": [[0, 2.16, 94.91], [1, 2.14, 31], [2, 2, 44.48]], "batl": [[0, 2.24, 9], [1, 2.28, 328.79]]}, {"timestamp": 1631553730158, "ltp": 2.2, "tv": 24995.62, "trd": [[2.2, 5.5]], "batb": [[0, 2.16, 54.31], [2, 2.08, 39.53]], "batl": NaN}, {"timestamp": 1631553743154, "ltp": 2.24, "tv": 25004.62, "trd": [[2.24, 9]], "batb": [[0, 2.16, 54.92]], "batl": [[0, 2.28, 328.79], [1, 2.28, 0]]}, {"timestamp": 1631553744056, "ltp": 2.24, "tv": 25022.89, "trd": [[2.24, 27.26]], "batb": [[0, 2.16, 54.31]], "batl": NaN}, {"timestamp": 1631553746053, "ltp": 2.24, "tv": 25026.73, "trd": [[2.24, 31.11]], "batb": NaN, "batl": NaN}, {"timestamp": 1631553747744, "ltp": 2.24, "tv": 25068.28, "trd": [[2.24, 72.66]], "batb": NaN, "batl": NaN}, {"timestamp": 1631553751847, "ltp": 2.24, "tv": 25068.28, "trd": NaN, "batb": [[0, 2.18, 42.69], [1, 2.16, 54.31], [2, 2.14, 31]], "batl": [[0, 2.2, 8.53], [1, 2.28, 328.79]]}, {"timestamp": 1631553752370, "ltp": 2.2, "tv": 25068.61, "trd": [[2.2, 5.83]], "batb": [[0, 2.16, 54.31], [1, 2.14, 31], [2, 2.08, 39.53]], "batl": [[0, 2.2, 8.21]]}, {"timestamp": 1631553754189, "ltp": 2.2, "tv": 25076.81, "trd": [[2.2, 14.04]], "batb": NaN, "batl": [[0, 2.28, 328.79], [1, 2.28, 0]]}, {"timestamp": 1631553757082, "ltp": 2.2, "tv": 25076.81, "trd": NaN, "batb": NaN, "batl": [[0, 2.28, 340.8]]}, {"timestamp": 1631553762781, "ltp": 2.2, "tv": 25078.61, "trd": [[2.2, 15.84]], "batb": NaN, "batl": NaN}, {"timestamp": 1631553770612, "ltp": 2.2, "tv": 25078.61, "trd": NaN, "batb": [[0, 2.14, 31], [1, 2.08, 39.53], [2, 1.5, 107.72]], "batl": NaN}, {"timestamp": 1631553773596, "ltp": 2.2, "tv": 25078.61, "trd": NaN, "batb": [[2, 2.04, 7.87]], "batl": NaN}, {"timestamp": 1631553777808, "ltp": 2.2, "tv": 25078.61, "trd": NaN, "batb": NaN, "batl": [[0, 2.2, 2.62]]}, {"timestamp": 1631553792193, "ltp": 2.2, "tv": 25078.61, "trd": NaN, "batb": [[0, 2.32, 14.53], [1, 2.2, 8.92], [2, 2.14, 31]], "batl": [[0, 2.4, 6.95], [1, 2.42, 287.42]]}, {"timestamp": 1631553793141, "ltp": 2.34, "tv": 25085.63, "trd": [[2.34, 7.01]], "batb": [[1, 2.26, 30.63], [2, 2.2, 8.92]], "batl": NaN}, {"timestamp": 1631553797037, "ltp": 2.36, "tv": 25101.92, "trd": [[2.36, 16.29]], "batb": NaN, "batl": NaN}, {"timestamp": 1631553808927, "ltp": 2.36, "tv": 25101.92, "trd": NaN, "batb": [[0, 2.18, 34.16], [1, 2.14, 31], [2, 1.5, 107.72]], "batl": NaN}, {"timestamp": 1631553812155, "ltp": 2.36, "tv": 25101.92, "trd": NaN, "batb": [[0, 2.18, 41.52], [2, 2.12, 8.04]], "batl": NaN}, {"timestamp": 1631553812366, "ltp": 2.36, "tv": 25101.92, "trd": NaN, "batb": [[0, 2.18, 34.16]], "batl": NaN}, {"timestamp": 1631553816169, "ltp": 2.22, "tv": 25106.47, "trd": [[2.22, 4.55]], "batb": NaN, "batl": [[0, 2.3, 219.86]]}, {"timestamp": 1631553817174, "ltp": 2.22, "tv": 25106.47, "trd": NaN, "batb": [[2, 2.12, 45.38]], "batl": NaN}, {"timestamp": 1631553821187, "ltp": 2.22, "tv": 25106.47, "trd": NaN, "batb": NaN, "batl": [[0, 2.26, 18.36]]}, {"timestamp": 1631553823155, "ltp": 2.22, "tv": 25106.47, "trd": NaN, "batb": [[0, 2.18, 40.52], [1, 2.16, 8.28], [2, 2.14, 31]], "batl": NaN}, {"timestamp": 1631553824841, "ltp": 2.22, "tv": 25106.47, "trd": NaN, "batb": [[0, 2.16, 8.28], [1, 2.14, 31], [2, 2.12, 37.34]], "batl": NaN}, {"timestamp": 1631553828157, "ltp": 2.22, "tv": 25106.47, "trd": NaN, "batb": [[0, 2.18, 6.97], [1, 2.16, 8.28], [2, 2.14, 31]], "batl": NaN}, {"timestamp": 1631553828472, "ltp": 2.22, "tv": 25106.47, "trd": NaN, "batb": [[0, 2.16, 8.28], [1, 2.14, 31], [2, 2.12, 37.34]], "batl": NaN}, {"timestamp": 1631553832987, "ltp": 2.22, "tv": 25106.47, "trd": NaN, "batb": NaN, "batl": [[0, 2.24, 1.39]]}, {"timestamp": 1631553835202, "ltp": 2.22, "tv": 25106.47, "trd": NaN, "batb": [[0, 2.18, 7.36], [1, 2.16, 8.28], [2, 2.14, 31]], "batl": NaN}, {"timestamp": 1631553835502, "ltp": 2.22, "tv": 25106.47, "trd": NaN, "batb": [[0, 2.16, 8.28], [1, 2.14, 31], [2, 2.12, 37.34]], "batl": NaN}, {"timestamp": 1631553842174, "ltp": 2.24, "tv": 25107.85, "trd": [[2.24, 74.04]], "batb": [[0, 2.18, 6.86], [1, 2.16, 8.28], [2, 2.14, 31]], "batl": NaN}, {"timestamp": 1631553842395, "ltp": 2.24, "tv": 25107.85, "trd": NaN, "batb": [[0, 2.16, 8.28], [1, 2.14, 31], [2, 2.12, 37.34]], "batl": NaN}, {"timestamp": 1631553846694, "ltp": 2.4, "tv": 25114.03, "trd": [[2.4, 6.18]], "batb": [[0, 2.4, 2.36], [1, 2.34, 9.22], [2, 2.16, 8.28]], "batl": [[0, 2.46, 6.26], [1, 2.5, 347.47]]}, {"timestamp": 1631553847907, "ltp": 2.4, "tv": 25114.03, "trd": NaN, "batb": [[1, 2.34, 37.5], [2, 2.22, 32.31]], "batl": NaN}, {"timestamp": 1631553851598, "ltp": 2.4, "tv": 25118.75, "trd": [[2.4, 10.9]], "batb": [[0, 2.34, 37.5], [1, 2.22, 32.31], [2, 2.16, 8.28]], "batl": NaN}, {"timestamp": 1631553853491, "ltp": 2.4, "tv": 25118.75, "trd": NaN, "batb": [[1, 2.28, 7.16], [2, 2.22, 39.15]], "batl": NaN}, {"timestamp": 1631553855315, "ltp": 2.4, "tv": 25118.75, "trd": NaN, "batb": [[2, 2.24, 6.77]], "batl": NaN}, {"timestamp": 1631553856633, "ltp": 2.4, "tv": 25118.75, "trd": NaN, "batb": NaN, "batl": [[0, 2.5, 347.47], [1, 2.5, 0]]}, {"timestamp": 1631553859512, "ltp": 2.4, "tv": 25118.75, "trd": NaN, "batb": [[0, 2.36, 10.44], [1, 2.34, 37.5], [2, 2.28, 7.16]], "batl": NaN}, {"timestamp": 1631553861625, "ltp": 2.4, "tv": 25118.75, "trd": NaN, "batb": [[0, 2.34, 37.5], [1, 2.28, 7.16], [2, 2.24, 6.77]], "batl": NaN}, {"timestamp": 1631553864717, "ltp": 2.4, "tv": 25118.75, "trd": NaN, "batb": [[0, 2.36, 10.44], [1, 2.34, 37.5], [2, 2.28, 7.16]], "batl": NaN}, {"timestamp": 1631553871162, "ltp": 2.4, "tv": 25118.75, "trd": NaN, "batb": [[0, 2.34, 37.5], [1, 2.28, 7.16], [2, 2.24, 6.77]], "batl": NaN}, {"timestamp": 1631553871633, "ltp": 2.4, "tv": 25118.75, "trd": NaN, "batb": [[0, 2.28, 7.16], [1, 2.24, 6.77], [2, 2.22, 39.15]], "batl": NaN}, {"timestamp": 1631553883131, "ltp": 2.4, "tv": 25118.75, "trd": NaN, "batb": [[0, 2.22, 39.15], [1, 2.14, 31], [2, 1.5, 107.72]], "batl": NaN}, {"timestamp": 1631553884131, "ltp": 2.24, "tv": 25131.46, "trd": [[2.24, 78.5], [2.74, 8.25]], "batb": NaN, "batl": [[0, 2.44, 84.01]]}, {"timestamp": 1631553885167, "ltp": 2.24, "tv": 25131.46, "trd": NaN, "batb": [[2, 2.12, 36.84]], "batl": [[0, 2.44, 16.81]]}, {"timestamp": 1631553891437, "ltp": 2.24, "tv": 25131.46, "trd": NaN, "batb": [[1, 2.2, 6.87], [2, 2.16, 7.53]], "batl": NaN}, {"timestamp": 1631553892855, "ltp": 2.24, "tv": 25131.46, "trd": NaN, "batb": [[2, 2.18, 6.36]], "batl": NaN}, {"timestamp": 1631553894566, "ltp": 2.3, "tv": 25136.46, "trd": [[2.3, 5]], "batb": NaN, "batl": [[0, 2.42, 198.4], [1, 2.44, 16.81]]}, {"timestamp": 1631553896135, "ltp": 2.3, "tv": 25136.46, "trd": NaN, "batb": [[0, 2.22, 32.31]], "batl": NaN}, {"timestamp": 1631553896571, "ltp": 2.3, "tv": 25136.46, "trd": NaN, "batb": [[0, 2.2, 6.87], [1, 2.18, 6.36], [2, 2.16, 7.53]], "batl": NaN}, {"timestamp": 1631553899958, "ltp": 2.26, "tv": 25215.73, "trd": [[2.26, 79.26]], "batb": NaN, "batl": [[0, 2.26, 6.96]]}, {"timestamp": 1631553900266, "ltp": 2.26, "tv": 25215.73, "trd": NaN, "batb": [[0, 2.16, 7.53], [1, 2.14, 31], [2, 2.12, 36.84]], "batl": NaN}, {"timestamp": 1631553902063, "ltp": 2.26, "tv": 25222.68, "trd": [[2.26, 86.22]], "batb": NaN, "batl": NaN}, {"timestamp": 1631553903763, "ltp": 2.26, "tv": 25222.68, "trd": NaN, "batb": [[0, 2.2, 7.72], [1, 2.16, 7.53], [2, 2.14, 31]], "batl": NaN}, {"timestamp": 1631553905084, "ltp": 2.26, "tv": 25222.68, "trd": NaN, "batb": [[0, 2.16, 7.53], [1, 2.14, 31], [2, 2.12, 36.84]], "batl": NaN}, {"timestamp": 1631553912997, "ltp": 2.26, "tv": 25222.68, "trd": NaN, "batb": NaN, "batl": [[0, 810, 0.07]]}, {"timestamp": 1631553922342, "ltp": 2.26, "tv": 25222.68, "trd": NaN, "batb": [[0, 2.2, 7.57], [1, 2.16, 7.53], [2, 2.14, 31]], "batl": NaN}, {"timestamp": 1631553929696, "ltp": 2.26, "tv": 25222.68, "trd": NaN, "batb": [[0, 2.16, 7.53], [1, 2.14, 31], [2, 2.12, 36.84]], "batl": NaN}, {"timestamp": 1631553932110, "ltp": 2.16, "tv": 25232.02, "trd": [[2.16, 18.86]], "batb": [[0, 2.16, 2.86]], "batl": [[0, 2.24, 253.06], [1, 2.26, 95.64], [2, 2.28, 6.7]]}, {"timestamp": 1631553938797, "ltp": 2.16, "tv": 25232.02, "trd": NaN, "batb": [[1, 2.14, 37.82], [2, 2.12, 44.38]], "batl": NaN}, {"timestamp": 1631553962039, "ltp": 2.16, "tv": 25232.02, "trd": NaN, "batb": [[0, 2.14, 31], [1, 2.06, 40.11], [2, 1.5, 107.72]], "batl": [[0, 2.4, 6.34], [1, 810, 0.07], [2, 2.28, 0]]}, {"timestamp": 1631553965056, "ltp": 2.16, "tv": 25232.02, "trd": NaN, "batb": [[0, 2.14, 37.82], [1, 2.12, 7.79], [2, 2.06, 40.11]], "batl": NaN}, {"timestamp": 1631553965543, "ltp": 2.16, "tv": 25232.02, "trd": NaN, "batb": [[0, 2.14, 31]], "batl": NaN}, {"timestamp": 1631553968840, "ltp": 2.16, "tv": 25232.02, "trd": NaN, "batb": NaN, "batl": [[0, 2.34, 6.25], [1, 2.4, 6.34], [2, 810, 0.07]]}, {"timestamp": 1631553970954, "ltp": 2.16, "tv": 25239.27, "trd": [[2.16, 26.1]], "batb": NaN, "batl": NaN}, {"timestamp": 1631553972055, "ltp": 2.16, "tv": 25239.27, "trd": NaN, "batb": [[0, 2.14, 38.32]], "batl": [[0, 2.4, 6.34], [1, 810, 0.07], [2, 810, 0]]}, {"timestamp": 1631553972368, "ltp": 2.16, "tv": 25239.27, "trd": NaN, "batb": [[0, 2.14, 31]], "batl": NaN}, {"timestamp": 1631553979083, "ltp": 2.16, "tv": 25239.27, "trd": NaN, "batb": [[0, 2.14, 38.32]], "batl": NaN}, {"timestamp": 1631553979360, "ltp": 2.16, "tv": 25239.27, "trd": NaN, "batb": [[0, 2.14, 31]], "batl": NaN}, {"timestamp": 1631553980774, "ltp": 2.16, "tv": 25239.27, "trd": NaN, "batb": [[0, 2.28, 39.48], [1, 2.26, 19.74], [2, 2.24, 28.26]], "batl": NaN}, {"timestamp": 1631553981764, "ltp": 2.28, "tv": 25248.11, "trd": [[2.28, 8.84]], "batb": [[0, 2.28, 8.74], [1, 2.26, 37.71], [2, 2.24, 15.1]], "batl": [[1, 2.42, 12.4], [2, 2.44, 6.2]]}, {"timestamp": 1631554000102, "ltp": 2.28, "tv": 25248.11, "trd": NaN, "batb": [[0, 2.18, 6.36], [1, 2.16, 35.41], [2, 2.14, 31]], "batl": [[0, 2.62, 4.75], [1, 810, 0.07], [2, 2.44, 0]]}, {"timestamp": 1631554006137, "ltp": 2.28, "tv": 25248.11, "trd": NaN, "batb": NaN, "batl": [[0, 2.36, 20.82], [1, 2.62, 4.75], [2, 810, 0.07]]}, {"timestamp": 1631554007026, "ltp": 2.28, "tv": 25248.11, "trd": NaN, "batb": NaN, "batl": [[0, 2.62, 4.75], [1, 810, 0.07], [2, 810, 0]]}, {"timestamp": 1631554008346, "ltp": 2.28, "tv": 25248.11, "trd": NaN, "batb": NaN, "batl": [[0, 2.28, 6.09], [1, 2.62, 4.75], [2, 810, 0.07]]}, {"timestamp": 1631554010026, "ltp": 2.28, "tv": 25248.11, "trd": NaN, "batb": [[0, 2.2, 6.92], [1, 2.18, 6.36], [2, 2.16, 35.41]], "batl": NaN}, {"timestamp": 1631554010609, "ltp": 2.28, "tv": 25248.11, "trd": NaN, "batb": [[0, 2.18, 6.36], [1, 2.16, 35.41], [2, 2.14, 31]], "batl": NaN}, {"timestamp": 1631554013915, "ltp": 2.28, "tv": 25248.11, "trd": NaN, "batb": NaN, "batl": [[1, 2.52, 5.51], [2, 2.62, 4.75]]}, {"timestamp": 1631554015121, "ltp": 2.18, "tv": 25248.26, "trd": [[2.18, 0.16]], "batb": [[0, 2.18, 6.28]], "batl": [[1, 2.62, 4.75], [2, 810, 0.07]]}, {"timestamp": 1631554017021, "ltp": 2.18, "tv": 25248.26, "trd": NaN, "batb": [[0, 2.2, 6.92], [1, 2.18, 6.28], [2, 2.16, 35.41]], "batl": NaN}, {"timestamp": 1631554018123, "ltp": 2.28, "tv": 25254.36, "trd": [[2.28, 14.93]], "batb": [[0, 2.18, 6.28], [1, 2.16, 35.41], [2, 2.14, 31]], "batl": [[0, 2.62, 4.75], [1, 810, 0.07], [2, 810, 0]]}, {"timestamp": 1631554019156, "ltp": 2.28, "tv": 25254.36, "trd": NaN, "batb": [[0, 2.5, 80.4], [1, 2.46, 12.2], [2, 2.44, 14.02]], "batl": [[0, 2.56, 9.99], [1, 2.62, 4.75], [2, 810, 0.07]]}, {"timestamp": 1631554019624, "ltp": 2.5, "tv": 25262.56, "trd": [[2.5, 8.2]], "batb": [[0, 2.5, 76.3], [1, 2.46, 36.7]], "batl": NaN}, {"timestamp": 1631554023542, "ltp": 2.5, "tv": 25285.46, "trd": [[2.5, 31.1]], "batb": [[0, 2.5, 64.85]], "batl": NaN}, {"timestamp": 1631554024922, "ltp": 2.5, "tv": 25285.46, "trd": NaN, "batb": NaN, "batl": [[2, 3, 3.53]]}, {"timestamp": 1631554045048, "ltp": 2.5, "tv": 25285.46, "trd": NaN, "batb": [[0, 2.28, 30.21], [1, 2.22, 7.34], [2, 2.14, 31]], "batl": [[0, 3, 3.53], [1, 3.25, 3.98], [2, 810, 0.07]]}, {"timestamp": 1631554045468, "ltp": 2.5, "tv": 25285.46, "trd": NaN, "batb": NaN, "batl": [[0, 3.25, 3.98], [1, 810, 0.07], [2, 810, 0]]}, {"timestamp": 1631554050198, "ltp": 2.5, "tv": 25285.46, "trd": NaN, "batb": NaN, "batl": [[1, 1000, 2.24]]}, {"timestamp": 1631554050678, "ltp": 2.5, "tv": 25285.46, "trd": NaN, "batb": NaN, "batl": [[1, 810, 0.07]]}, {"timestamp": 1631554052059, "ltp": 2.5, "tv": 25285.46, "trd": NaN, "batb": NaN, "batl": [[0, 3, 4.84], [1, 3.25, 3.98], [2, 810, 0.07]]}, {"timestamp": 1631554053171, "ltp": 2.5, "tv": 25285.46, "trd": NaN, "batb": NaN, "batl": [[0, 3.25, 3.98], [1, 810, 0.07], [2, 810, 0]]}, {"timestamp": 1631554053801, "ltp": 2.5, "tv": 25285.46, "trd": NaN, "batb": NaN, "batl": [[1, 820, 0.14]]}, {"timestamp": 1631554055762, "ltp": 3.25, "tv": 25296.94, "trd": [[3.25, 11.48]], "batb": NaN, "batl": [[0, 820, 0.14], [1, 820, 0]]}, {"timestamp": 1631554058176, "ltp": 3.25, "tv": 25296.94, "trd": NaN, "batb": [[0, 2.28, 37.62]], "batl": NaN}, {"timestamp": 1631554059016, "ltp": 3.25, "tv": 25296.94, "trd": NaN, "batb": [[0, 2.28, 30.21]], "batl": [[0, 3, 4.21], [1, 3.25, 3.42], [2, 820, 0.14]]}, {"timestamp": 1631554059282, "ltp": 3.25, "tv": 25296.94, "trd": NaN, "batb": NaN, "batl": [[0, 3.25, 3.42], [1, 820, 0.14], [2, 820, 0]]}, {"timestamp": 1631554061186, "ltp": 3.25, "tv": 25296.94, "trd": NaN, "batb": [[0, 2.9, 41.38], [1, 2.84, 31.69], [2, 2.82, 15.85]], "batl": [[0, 2.92, 7.88], [1, 3, 116.19], [2, 3.25, 3.42]]}, {"timestamp": 1631554062130, "ltp": 2.9, "tv": 25304.08, "trd": [[2.9, 7.14]], "batb": [[0, 2.9, 37.81], [1, 2.84, 10.56], [2, 2.82, 47.24]], "batl": NaN}, {"timestamp": 1631554069208, "ltp": 2.92, "tv": 25311.96, "trd": [[2.92, 7.88]], "batb": NaN, "batl": [[0, 3, 116.19], [1, 3.25, 3.42], [2, 810, 0.07]]}, {"timestamp": 1631554070205, "ltp": 2.92, "tv": 25311.96, "trd": NaN, "batb": [[0, 2.92, 7.87], [1, 2.9, 37.81], [2, 2.84, 10.56]], "batl": NaN}, {"timestamp": 1631554072210, "ltp": 2.92, "tv": 25311.96, "trd": NaN, "batb": [[0, 2.92, 47.27]], "batl": NaN}, {"timestamp": 1631554074206, "ltp": 2.92, "tv": 25311.96, "trd": NaN, "batb": [[0, 2.98, 16.25], [1, 2.92, 47.27], [2, 2.9, 37.81]], "batl": NaN}, {"timestamp": 1631554075107, "ltp": 2.92, "tv": 25311.96, "trd": NaN, "batb": [[0, 2.98, 42.11]], "batl": NaN}, {"timestamp": 1631554076100, "ltp": 2.92, "tv": 25311.96, "trd": NaN, "batb": [[0, 2.98, 56.24], [1, 2.94, 11.92], [2, 2.92, 47.27]], "batl": NaN}, {"timestamp": 1631554076999, "ltp": 2.96, "tv": 25441.49, "trd": [[2.96, 42.91], [2.98, 86.62]], "batb": [[0, 2.9, 37.81], [1, 2.84, 10.56], [2, 2.82, 47.24]], "batl": NaN}, {"timestamp": 1631554080053, "ltp": 3.0, "tv": 25520.82, "trd": [[3, 79.34]], "batb": NaN, "batl": [[0, 3, 61.9]]}, {"timestamp": 1631554081113, "ltp": 3.0, "tv": 25595.53, "trd": [[3, 154.04]], "batb": [[0, 3, 12.8], [1, 2.9, 37.81], [2, 2.84, 10.56]], "batl": [[0, 3.25, 3.42], [1, 810, 0.07], [2, 810, 0]]}, {"timestamp": 1631554082112, "ltp": 3.0, "tv": 25607.4, "trd": [[3, 165.92]], "batb": [[0, 3, 6.86]], "batl": NaN}, {"timestamp": 1631554082532, "ltp": 3.0, "tv": 25607.4, "trd": NaN, "batb": [[0, 2.9, 37.81], [1, 2.84, 10.56], [2, 2.82, 47.24]], "batl": NaN}, {"timestamp": 1631554084118, "ltp": 3.0, "tv": 25607.4, "trd": NaN, "batb": NaN, "batl": [[0, 3.2, 274.74], [1, 3.25, 3.42], [2, 810, 0.07]]}, {"timestamp": 1631554084746, "ltp": 3.0, "tv": 25613.34, "trd": [[3, 171.86]], "batb": [[1, 2.88, 6.19], [2, 2.84, 10.56]], "batl": [[0, 3.25, 3.42], [1, 810, 0.07], [2, 810, 0]]}, {"timestamp": 1631554086806, "ltp": 3.05, "tv": 25627.08, "trd": [[3.05, 13.74]], "batb": NaN, "batl": NaN}, {"timestamp": 1631554090617, "ltp": 3.05, "tv": 25627.08, "trd": NaN, "batb": NaN, "batl": [[0, 3.25, 46.37]]}, {"timestamp": 1631554091909, "ltp": 3.05, "tv": 25647.9, "trd": [[3.05, 34.55]], "batb": [[1, 2.84, 10.56], [2, 2.82, 47.24]], "batl": NaN}, {"timestamp": 1631554095049, "ltp": 3.05, "tv": 25647.9, "trd": NaN, "batb": NaN, "batl": [[0, 3.25, 3.42]]}, {"timestamp": 1631554097936, "ltp": 3.05, "tv": 25647.9, "trd": NaN, "batb": [[0, 2.96, 6.11], [1, 2.9, 37.81], [2, 2.84, 10.56]], "batl": [[0, 3.05, 6.76], [1, 3.25, 3.42], [2, 810, 0.07]]}, {"timestamp": 1631554151506, "ltp": 3.05, "tv": 25647.9, "trd": NaN, "batb": NaN, "batl": [[1, 3.1, 3.35], [2, 3.15, 3.9]]}, {"timestamp": 1631554176176, "ltp": 3.05, "tv": 25647.9, "trd": NaN, "batb": [[0, 2.82, 41.96], [1, 2.66, 25.17], [2, 2.56, 5.33]], "batl": [[0, 3.1, 3.35], [1, 3.15, 3.9], [2, 810, 0.07]]}, {"timestamp": 1631554176872, "ltp": 3.05, "tv": 25647.9, "trd": NaN, "batb": [[0, 2.66, 19.89], [1, 2.56, 5.33], [2, 2.14, 31]], "batl": [[0, 3.15, 3.9], [1, 810, 0.07], [2, 810, 0]]}, {"timestamp": 1631554180185, "ltp": 3.05, "tv": 25647.9, "trd": NaN, "batb": NaN, "batl": [[0, 3.1, 4.45], [1, 3.15, 3.9], [2, 810, 0.07]]}, {"timestamp": 1631554180444, "ltp": 3.05, "tv": 25647.9, "trd": NaN, "batb": NaN, "batl": [[0, 3.15, 3.9], [1, 810, 0.07], [2, 810, 0]]}, {"timestamp": 1631554183773, "ltp": 3.05, "tv": 25647.9, "trd": NaN, "batb": [[0, 2.66, 24.67]], "batl": [[0, 3.1, 3.75], [1, 3.15, 3.9], [2, 810, 0.07]]}, {"timestamp": 1631554185458, "ltp": 3.05, "tv": 25647.9, "trd": NaN, "batb": [[0, 2.66, 19.89]], "batl": [[0, 3.15, 3.9], [1, 810, 0.07], [2, 810, 0]]}, {"timestamp": 1631554192165, "ltp": 2.72, "tv": 25676.49, "trd": [[2.72, 3.76], [3, 196.69]], "batb": NaN, "batl": [[0, 2.88, 238.63], [1, 2.92, 13.7], [2, 3.15, 3.9]]}, {"timestamp": 1631554192692, "ltp": 2.72, "tv": 25676.49, "trd": NaN, "batb": [[2, 2.48, 23.83]], "batl": NaN}, {"timestamp": 1631554196211, "ltp": 2.78, "tv": 25681.23, "trd": [[2.78, 4.74]], "batb": NaN, "batl": NaN}, {"timestamp": 1631554198116, "ltp": 2.78, "tv": 25681.23, "trd": NaN, "batb": [[0, 2.66, 25.67], [1, 2.6, 4.49], [2, 2.56, 5.33]], "batl": [[2, 2.94, 4.25]]}, {"timestamp": 1631554201917, "ltp": 2.86, "tv": 25687.23, "trd": [[2.86, 6]], "batb": NaN, "batl": NaN}, {"timestamp": 1631554203206, "ltp": 2.86, "tv": 25687.23, "trd": NaN, "batb": NaN, "batl": [[0, 2.94, 4.25], [1, 3.15, 3.9], [2, 810, 0.07]]}, {"timestamp": 1631554203999, "ltp": 2.86, "tv": 25687.23, "trd": NaN, "batb": [[0, 2.48, 23.83], [1, 2.14, 31], [2, 1.8, 11.97]], "batl": [[0, 3.15, 3.9], [1, 810, 0.07], [2, 810, 0]]}, {"timestamp": 1631554204798, "ltp": 2.86, "tv": 25687.23, "trd": NaN, "batb": NaN, "batl": [[0, 810, 0.07], [1, 810, 0]]}, {"timestamp": 1631554206815, "ltp": 2.86, "tv": 25687.23, "trd": NaN, "batb": [[0, 2.6, 5.29], [1, 2.48, 23.83], [2, 2.14, 31]], "batl": [[0, 2.94, 5.25], [1, 810, 0.07]]}, {"timestamp": 1631554210028, "ltp": 2.86, "tv": 25687.23, "trd": NaN, "batb": [[0, 2.66, 4.81], [1, 2.6, 5.29], [2, 2.48, 23.83]], "batl": NaN}, {"timestamp": 1631554210409, "ltp": 2.86, "tv": 25687.23, "trd": NaN, "batb": [[0, 2.6, 5.29], [1, 2.48, 23.83], [2, 2.14, 31]], "batl": NaN}, {"timestamp": 1631554213944, "ltp": 2.86, "tv": 25687.23, "trd": NaN, "batb": NaN, "batl": [[1, 810, 0]]}, {"timestamp": 1631554216050, "ltp": 2.86, "tv": 25687.23, "trd": NaN, "batb": [[0, 2.88, 5.13], [1, 2.86, 52.44], [2, 2.84, 26.22]], "batl": [[1, 2.96, 7.1], [2, 3, 121.91]]}, {"timestamp": 1631554217055, "ltp": 2.88, "tv": 25694.47, "trd": [[2.88, 7.24]], "batb": [[0, 2.88, 1.51], [1, 2.86, 10.48], [2, 2.84, 5.24]], "batl": NaN}, {"timestamp": 1631554222935, "ltp": 2.88, "tv": 25694.47, "trd": NaN, "batb": NaN, "batl": [[2, 2.98, 4.75]]}, {"timestamp": 1631554226942, "ltp": 2.88, "tv": 25694.47, "trd": NaN, "batb": [[0, 2.86, 10.48], [1, 2.84, 5.24], [2, 2.82, 5.24]], "batl": [[1, 2.98, 4.75], [2, 3, 126.64]]}, {"timestamp": 1631554228051, "ltp": 2.88, "tv": 25694.47, "trd": NaN, "batb": [[0, 2.74, 4.79], [1, 2.68, 5.36], [2, 2.6, 5.29]], "batl": [[0, 3, 4.73], [1, 2.98, 0], [2, 3, 0]]}, {"timestamp": 1631554230042, "ltp": 2.88, "tv": 25694.47, "trd": NaN, "batb": [[0, 2.68, 5.36], [1, 2.58, 21.4], [2, 2.14, 31]], "batl": NaN}, {"timestamp": 1631554234973, "ltp": 2.88, "tv": 25694.47, "trd": NaN, "batb": NaN, "batl": [[0, 2.98, 4.75], [1, 3, 4.73]]}, {"timestamp": 1631554236077, "ltp": 2.88, "tv": 25694.47, "trd": NaN, "batb": [[0, 2.74, 5.29], [1, 2.68, 5.36], [2, 2.58, 21.4]], "batl": [[0, 3, 4.73], [1, 3, 0]]}, {"timestamp": 1631554236453, "ltp": 2.88, "tv": 25694.47, "trd": NaN, "batb": [[0, 2.68, 5.36], [1, 2.58, 21.4], [2, 2.14, 31]], "batl": NaN}, {"timestamp": 1631554237554, "ltp": 2.88, "tv": 25694.47, "trd": NaN, "batb": NaN, "batl": [[0, 2.86, 2.17], [1, 3, 4.73]]}, {"timestamp": 1631554239979, "ltp": 2.88, "tv": 25694.47, "trd": NaN, "batb": NaN, "batl": [[0, 3, 4.73], [1, 3, 0]]}, {"timestamp": 1631554242177, "ltp": 2.88, "tv": 25694.47, "trd": NaN, "batb": NaN, "batl": [[0, 2.98, 4.75], [1, 3, 4.73]]}, {"timestamp": 1631554243154, "ltp": 2.88, "tv": 25694.47, "trd": NaN, "batb": [[0, 2.74, 5.29], [1, 2.68, 5.36], [2, 2.58, 21.4]], "batl": [[0, 3, 4.73], [1, 3, 0]]}, {"timestamp": 1631554243677, "ltp": 2.74, "tv": 25711.23, "trd": [[2.74, 25.01]], "batb": [[0, 2.68, 5.36], [1, 2.6, 233.41]], "batl": [[0, 2.78, 10.8], [1, 2.8, 5.4], [2, 2.82, 5.4]]}, {"timestamp": 1631554244895, "ltp": 2.78, "tv": 25720.23, "trd": [[2.78, 13.74]], "batb": [[1, 2.6, 244.95], [2, 2.58, 27.16]], "batl": [[0, 2.78, 6.3]]}, {"timestamp": 1631554250893, "ltp": 2.78, "tv": 25720.23, "trd": NaN, "batb": [[2, 2.58, 33.22]], "batl": NaN}, {"timestamp": 1631554255570, "ltp": 2.78, "tv": 25720.23, "trd": NaN, "batb": NaN, "batl": [[0, 2.74, 2.17], [1, 2.78, 6.3], [2, 2.8, 5.4]]}, {"timestamp": 1631554256573, "ltp": 2.78, "tv": 25720.23, "trd": NaN, "batb": NaN, "batl": [[1, 2.78, 16.88]]}, {"timestamp": 1631554257683, "ltp": 2.68, "tv": 25723.83, "trd": [[2.68, 3.6]], "batb": [[0, 2.68, 3.56]], "batl": [[0, 2.78, 16.88], [1, 2.8, 5.4], [2, 2.82, 5.4]]}, {"timestamp": 1631554260089, "ltp": 2.68, "tv": 25723.83, "trd": NaN, "batb": [[0, 2.52, 5.49], [1, 2.4, 26.18], [2, 2.14, 31]], "batl": [[0, 3, 4.73], [1, 2.8, 0], [2, 2.82, 0]]}, {"timestamp": 1631554266209, "ltp": 2.68, "tv": 25723.83, "trd": NaN, "batb": [[0, 2.68, 74.62], [1, 2.52, 5.49], [2, 2.4, 26.18]], "batl": [[0, 2.88, 6.31], [1, 2.92, 186.4], [2, 3, 4.73]]}, {"timestamp": 1631554266633, "ltp": 2.68, "tv": 25723.83, "trd": NaN, "batb": [[0, 2.78, 10.66], [1, 2.68, 44.77], [2, 2.52, 5.49]], "batl": NaN}, {"timestamp": 1631554267638, "ltp": 2.78, "tv": 25731.19, "trd": [[2.78, 21.1]], "batb": [[0, 2.78, 6.98], [1, 2.72, 18.71], [2, 2.68, 44.77]], "batl": NaN}, {"timestamp": 1631554273630, "ltp": 2.78, "tv": 25731.19, "trd": NaN, "batb": [[2, 2.68, 49.88]], "batl": NaN}, {"timestamp": 1631554281143, "ltp": 2.78, "tv": 25731.19, "trd": NaN, "batb": [[0, 2.72, 18.71], [1, 2.68, 5.11], [2, 2.62, 5.54]], "batl": NaN}, {"timestamp": 1631554281625, "ltp": 2.78, "tv": 25731.19, "trd": NaN, "batb": [[0, 2.62, 5.54], [1, 2.5, 23.5], [2, 2.14, 31]], "batl": NaN}, {"timestamp": 1631554284944, "ltp": 2.78, "tv": 25731.19, "trd": NaN, "batb": NaN, "batl": [[0, 3.1, 3.85]]}, {"timestamp": 1631554288123, "ltp": 2.78, "tv": 25731.19, "trd": NaN, "batb": [[0, 2.68, 5.36], [1, 2.62, 5.54], [2, 2.5, 23.5]], "batl": [[0, 3, 4.71], [1, 3.1, 3.85]]}, {"timestamp": 1631554288852, "ltp": 2.8, "tv": 25733.7, "trd": [[2.8, 2.51]], "batb": [[0, 2.84, 236.09]], "batl": [[0, 3.05, 11.48]]}, {"timestamp": 1631554289866, "ltp": 2.92, "tv": 25737.2, "trd": [[2.92, 11.38]], "batb": [[0, 2.84, 277.46], [1, 2.64, 19.97], [2, 2.62, 5.54]], "batl": NaN}, {"timestamp": 1631554295454, "ltp": 2.92, "tv": 25737.2, "trd": NaN, "batb": [[0, 2.84, 282.18], [1, 2.78, 4.66], [2, 2.64, 19.97]], "batl": [[2, 3.15, 4.1]]}, {"timestamp": 1631554299743, "ltp": 2.92, "tv": 25737.2, "trd": NaN, "batb": NaN, "batl": [[0, 3.1, 3.85], [1, 3.15, 4.1], [2, 3.15, 0]]}, {"timestamp": 1631554302654, "ltp": 2.92, "tv": 25737.2, "trd": NaN, "batb": [[0, 2.88, 9.97], [1, 2.84, 282.18], [2, 2.78, 4.66]], "batl": [[0, 3, 3.98], [1, 3.1, 3.85], [2, 3.15, 4.1]]}, {"timestamp": 1631554304981, "ltp": 2.92, "tv": 25737.2, "trd": NaN, "batb": [[0, 2.84, 46.09], [1, 2.78, 4.66], [2, 2.64, 19.97]], "batl": [[0, 3.1, 3.85], [1, 3.15, 4.1], [2, 3.15, 0]]}, {"timestamp": 1631554306166, "ltp": 2.92, "tv": 25737.2, "trd": NaN, "batb": [[0, 2.78, 4.66], [1, 2.64, 19.97], [2, 2.14, 31]], "batl": NaN}, {"timestamp": 1631554308060, "ltp": 2.92, "tv": 25737.2, "trd": NaN, "batb": NaN, "batl": [[0, 3.05, 4.7], [1, 3.1, 3.85], [2, 3.15, 4.1]]}, {"timestamp": 1631554308959, "ltp": 2.92, "tv": 25737.2, "trd": NaN, "batb": [[0, 2.84, 4.22], [1, 2.78, 4.66], [2, 2.64, 19.97]], "batl": [[0, 3.1, 3.85], [1, 3.15, 4.1], [2, 3.15, 0]]}, {"timestamp": 1631554309278, "ltp": 2.92, "tv": 25737.2, "trd": NaN, "batb": [[0, 2.78, 4.66], [1, 2.64, 19.97], [2, 2.14, 31]], "batl": NaN}, {"timestamp": 1631554316188, "ltp": 2.92, "tv": 25737.2, "trd": NaN, "batb": [[0, 2.84, 4.72], [1, 2.78, 4.66], [2, 2.64, 19.97]], "batl": NaN}, {"timestamp": 1631554316494, "ltp": 2.92, "tv": 25737.2, "trd": NaN, "batb": [[0, 2.78, 4.66], [1, 2.64, 19.97], [2, 2.14, 31]], "batl": NaN}, {"timestamp": 1631554318086, "ltp": 2.78, "tv": 25744.6, "trd": [[2.78, 28.5]], "batb": [[0, 2.64, 20.93], [1, 2.14, 31], [2, 1.8, 11.97]], "batl": [[0, 2.84, 53.22], [1, 2.88, 31.25], [2, 2.9, 15.62]]}, {"timestamp": 1631554319092, "ltp": 2.78, "tv": 25744.6, "trd": NaN, "batb": [[1, 2.46, 24.59], [2, 2.14, 31]], "batl": [[1, 2.88, 10.42], [2, 2.9, 5.2]]}, {"timestamp": 1631554323087, "ltp": 2.84, "tv": 25747.6, "trd": [[2.84, 3]], "batb": NaN, "batl": [[0, 2.84, 50.22]]}, {"timestamp": 1631554325980, "ltp": 2.84, "tv": 25747.6, "trd": NaN, "batb": [[0, 2.66, 5.74], [1, 2.64, 19.97], [2, 2.6, 5.09]], "batl": NaN}, {"timestamp": 1631554326299, "ltp": 2.84, "tv": 25747.6, "trd": NaN, "batb": [[0, 2.66, 92.69]], "batl": NaN}, {"timestamp": 1631554344108, "ltp": 2.84, "tv": 25747.6, "trd": NaN, "batb": [[0, 2.66, 4.78], [1, 2.6, 5.09], [2, 2.46, 24.59]], "batl": [[0, 2.98, 3.75], [1, 3.05, 4.3], [2, 3.1, 3.85]]}, {"timestamp": 1631554344528, "ltp": 2.84, "tv": 25747.6, "trd": NaN, "batb": [[0, 2.6, 5.09], [1, 2.46, 24.59], [2, 2.14, 31]], "batl": [[0, 3.05, 4.3], [1, 3.05, 0], [2, 3.1, 0]]}, {"timestamp": 1631554351108, "ltp": 2.84, "tv": 25747.6, "trd": NaN, "batb": [[0, 2.66, 5.78], [1, 2.6, 5.09], [2, 2.46, 24.59]], "batl": [[0, 2.98, 4.75], [1, 3.05, 4.3]]}, {"timestamp": 1631554352011, "ltp": 2.84, "tv": 25747.6, "trd": NaN, "batb": [[0, 2.6, 5.09], [1, 2.46, 24.59], [2, 2.14, 31]], "batl": [[0, 3.05, 4.3], [1, 3.05, 0]]}, {"timestamp": 1631554355147, "ltp": 2.92, "tv": 25749.77, "trd": [[2.92, 13.55]], "batb": [[0, 2.88, 9.21], [1, 2.86, 52.44], [2, 2.84, 26.22]], "batl": [[0, 2.96, 9.33], [1, 3.05, 312.16]]}, {"timestamp": 1631554356108, "ltp": 2.92, "tv": 25753.32, "trd": [[2.92, 17.1]], "batb": [[1, 2.86, 31.46], [2, 2.84, 15.73]], "batl": [[2, 3.1, 9.68]]}, {"timestamp": 1631554362718, "ltp": 2.92, "tv": 25753.32, "trd": NaN, "batb": NaN, "batl": [[1, 3, 4.14], [2, 3.05, 312.16]]}, {"timestamp": 1631554368138, "ltp": 2.92, "tv": 25753.32, "trd": NaN, "batb": [[0, 2.8, 4.83], [1, 2.74, 5.02], [2, 2.6, 26.15]], "batl": [[0, 3, 4.14], [1, 3.05, 4.3], [2, 3.05, 0]]}, {"timestamp": 1631554368826, "ltp": 2.92, "tv": 25753.32, "trd": NaN, "batb": [[0, 2.74, 5.02], [1, 2.6, 21.06], [2, 2.14, 31]], "batl": [[0, 3.05, 4.3], [1, 3.05, 0]]}, {"timestamp": 1631554372064, "ltp": 2.92, "tv": 25753.32, "trd": NaN, "batb": NaN, "batl": [[0, 3, 4.55], [1, 3.05, 4.3]]}, {"timestamp": 1631554372339, "ltp": 2.92, "tv": 25753.32, "trd": NaN, "batb": NaN, "batl": [[0, 3.05, 4.3], [1, 3.05, 0]]}, {"timestamp": 1631554375141, "ltp": 2.92, "tv": 25753.32, "trd": NaN, "batb": [[0, 2.8, 4.83], [1, 2.74, 5.02], [2, 2.6, 21.06]], "batl": [[0, 2.92, 2], [1, 3.05, 4.3]]}, {"timestamp": 1631554376037, "ltp": 2.92, "tv": 25753.32, "trd": NaN, "batb": [[0, 2.74, 5.02], [1, 2.6, 21.06], [2, 2.14, 31]], "batl": [[2, 3.1, 175.37]]}, {"timestamp": 1631554376827, "ltp": 2.92, "tv": 25753.32, "trd": NaN, "batb": NaN, "batl": [[2, 3.1, 0]]}, {"timestamp": 1631554379163, "ltp": 2.92, "tv": 25753.32, "trd": NaN, "batb": NaN, "batl": [[1, 3, 4.19], [2, 3.05, 4.3]]}, {"timestamp": 1631554379435, "ltp": 2.92, "tv": 25753.32, "trd": NaN, "batb": NaN, "batl": [[1, 3.05, 4.3], [2, 3.05, 0]]}, {"timestamp": 1631554382056, "ltp": 2.92, "tv": 25753.32, "trd": NaN, "batb": [[0, 2.8, 4.38], [1, 2.74, 5.02], [2, 2.6, 21.06]], "batl": NaN}, {"timestamp": 1631554382276, "ltp": 2.92, "tv": 25753.32, "trd": NaN, "batb": [[0, 2.74, 5.02], [1, 2.6, 21.06], [2, 2.14, 31]], "batl": NaN}, {"timestamp": 1631554383646, "ltp": 3.0, "tv": 25759.06, "trd": [[2.92, 19.1], [3, 200.43]], "batb": NaN, "batl": [[0, 3.05, 4.3], [1, 3.05, 0]]}, {"timestamp": 1631554387185, "ltp": 3.0, "tv": 25766.48, "trd": [[3, 207.85]], "batb": NaN, "batl": NaN}, {"timestamp": 1631554389142, "ltp": 3.0, "tv": 25766.48, "trd": NaN, "batb": [[0, 2.8, 4.38], [1, 2.74, 5.02], [2, 2.6, 21.06]], "batl": NaN}, {"timestamp": 1631554389460, "ltp": 3.0, "tv": 25766.48, "trd": NaN, "batb": [[0, 2.74, 5.02], [1, 2.6, 21.06], [2, 2.14, 31]], "batl": NaN}, {"timestamp": 1631554396164, "ltp": 3.0, "tv": 25766.48, "trd": NaN, "batb": [[0, 2.8, 5.13], [1, 2.74, 5.02], [2, 2.6, 21.06]], "batl": NaN}, {"timestamp": 1631554396493, "ltp": 3.0, "tv": 25766.48, "trd": NaN, "batb": [[0, 2.74, 5.02], [1, 2.6, 21.06], [2, 2.14, 31]], "batl": NaN}, {"timestamp": 1631554401171, "ltp": 2.74, "tv": 25773.94, "trd": [[2.74, 32.47]], "batb": [[0, 2.74, 1.29]], "batl": [[0, 2.78, 8.78], [1, 2.82, 42.55], [2, 2.84, 258.22]]}, {"timestamp": 1631554402166, "ltp": 2.74, "tv": 25773.94, "trd": NaN, "batb": [[1, 2.64, 11.36], [2, 2.62, 5.68]], "batl": [[2, 2.84, 237.09]]}, {"timestamp": 1631554416699, "ltp": 2.78, "tv": 25782.72, "trd": [[2.78, 37.28]], "batb": NaN, "batl": [[0, 2.82, 42.55], [1, 2.84, 237.09], [2, 2.86, 5.28]]}, {"timestamp": 1631554421395, "ltp": 2.78, "tv": 25782.72, "trd": NaN, "batb": [[2, 2.62, 11.22]], "batl": NaN}, {"timestamp": 1631554429795, "ltp": 2.78, "tv": 25782.72, "trd": NaN, "batb": NaN, "batl": [[1, 2.84, 247.2]]}, {"timestamp": 1631554432115, "ltp": 2.78, "tv": 25782.72, "trd": NaN, "batb": [[0, 2.6, 5.44], [1, 2.58, 5.56], [2, 2.56, 5.58]], "batl": [[0, 2.98, 4.25], [1, 3.05, 4.3], [2, 2.86, 0]]}, {"timestamp": 1631554433117, "ltp": 2.78, "tv": 25782.72, "trd": NaN, "batb": [[0, 2.58, 5.56], [1, 2.56, 5.58], [2, 2.4, 26.43]], "batl": [[0, 3.05, 4.32], [1, 3.05, 0]]}, {"timestamp": 1631554437011, "ltp": 2.78, "tv": 25782.72, "trd": NaN, "batb": NaN, "batl": [[0, 3.05, 4.3]]}, {"timestamp": 1631554438112, "ltp": 2.78, "tv": 25782.72, "trd": NaN, "batb": NaN, "batl": [[0, 2.92, 182.51], [1, 3.05, 4.3]]}, {"timestamp": 1631554438907, "ltp": 2.78, "tv": 25782.72, "trd": NaN, "batb": [[0, 2.62, 6.04], [1, 2.58, 5.56], [2, 2.56, 5.58]], "batl": [[0, 3.05, 4.3], [1, 3.05, 0]]}, {"timestamp": 1631554439970, "ltp": 2.78, "tv": 25782.72, "trd": NaN, "batb": [[0, 2.58, 5.56], [1, 2.56, 5.58], [2, 2.4, 26.43]], "batl": NaN}, {"timestamp": 1631554446032, "ltp": 2.78, "tv": 25782.72, "trd": NaN, "batb": [[0, 2.62, 5.54], [1, 2.58, 5.56], [2, 2.56, 5.58]], "batl": NaN}, {"timestamp": 1631554446415, "ltp": 2.78, "tv": 25782.72, "trd": NaN, "batb": [[0, 2.58, 5.56], [1, 2.56, 5.58], [2, 2.4, 26.43]], "batl": NaN}, {"timestamp": 1631554448001, "ltp": 2.78, "tv": 25782.72, "trd": NaN, "batb": NaN, "batl": [[0, 2.98, 4.75], [1, 3.05, 4.3]]}, {"timestamp": 1631554448320, "ltp": 2.78, "tv": 25782.72, "trd": NaN, "batb": NaN, "batl": [[0, 3.05, 4.3], [1, 3.05, 0]]}, {"timestamp": 1631554453129, "ltp": 2.78, "tv": 25782.72, "trd": NaN, "batb": [[0, 2.62, 6.04], [1, 2.58, 5.56], [2, 2.56, 5.58]], "batl": NaN}, {"timestamp": 1631554454027, "ltp": 2.58, "tv": 25790.72, "trd": [[2.58, 8]], "batb": [[0, 2.58, 1.56], [1, 2.56, 5.58], [2, 2.4, 26.43]], "batl": [[0, 2.66, 14.01], [1, 2.84, 916.6], [2, 3.05, 4.3]]}, {"timestamp": 1631554461044, "ltp": 2.58, "tv": 25790.72, "trd": NaN, "batb": NaN, "batl": [[2, 2.86, 4.25]]}, {"timestamp": 1631554469116, "ltp": 2.58, "tv": 25790.72, "trd": NaN, "batb": [[0, 2.4, 26.43], [1, 2.38, 5.96], [2, 2.32, 6.64]], "batl": [[0, 2.86, 4.25], [1, 2.98, 4.25], [2, 3.05, 4.3]]}, {"timestamp": 1631554469326, "ltp": 2.58, "tv": 25790.72, "trd": NaN, "batb": [[0, 2.32, 6.64], [1, 2.18, 34.07], [2, 2.14, 31]], "batl": [[0, 2.98, 4.25], [1, 2.98, 0], [2, 3.05, 0]]}, {"timestamp": 1631554472952, "ltp": 2.58, "tv": 25790.72, "trd": NaN, "batb": NaN, "batl": [[0, 2.86, 4.25], [1, 2.98, 4.25]]}, {"timestamp": 1631554473955, "ltp": 2.58, "tv": 25790.72, "trd": NaN, "batb": NaN, "batl": [[0, 2.58, 20], [1, 2.86, 4.25], [2, 2.98, 4.25]]}, {"timestamp": 1631554476159, "ltp": 2.8, "tv": 25826.88, "trd": [[2.58, 28], [2.78, 51.64], [2.8, 4.31]], "batb": NaN, "batl": [[0, 2.84, 368.49]]}, {"timestamp": 1631554476952, "ltp": 2.72, "tv": 25830.67, "trd": [[2.72, 7.55]], "batb": [[0, 2.56, 22.07], [1, 2.36, 27.53], [2, 2.32, 6.64]], "batl": [[2, 2.88, 10.42]]}, {"timestamp": 1631554482456, "ltp": 2.72, "tv": 25830.67, "trd": NaN, "batb": [[0, 2.6, 5.44], [1, 2.56, 27.65], [2, 2.36, 27.53]], "batl": NaN}, {"timestamp": 1631554489062, "ltp": 2.72, "tv": 25830.67, "trd": NaN, "batb": [[0, 2.56, 5.58], [1, 2.36, 27.53], [2, 2.14, 31]], "batl": [[0, 2.9, 4.65], [1, 2.98, 4.25], [2, 2.88, 0]]}, {"timestamp": 1631554489963, "ltp": 2.8, "tv": 25840.97, "trd": [[2.8, 14.61]], "batb": NaN, "batl": [[0, 2.98, 4.25], [1, 2.98, 0]]}, {"timestamp": 1631554493185, "ltp": 2.8, "tv": 25840.97, "trd": NaN, "batb": NaN, "batl": [[0, 2.9, 4.45], [1, 2.98, 4.25]]}, {"timestamp": 1631554493455, "ltp": 2.8, "tv": 25840.97, "trd": NaN, "batb": NaN, "batl": [[0, 2.98, 4.25], [1, 2.98, 0]]}, {"timestamp": 1631554496677, "ltp": 2.8, "tv": 25840.97, "trd": NaN, "batb": NaN, "batl": [[0, 2.9, 4.25], [1, 2.98, 4.25]]}, {"timestamp": 1631554498846, "ltp": 2.8, "tv": 25840.97, "trd": NaN, "batb": [[0, 2.6, 5.44], [1, 2.56, 5.58], [2, 2.36, 27.53]], "batl": NaN}, {"timestamp": 1631554499857, "ltp": 2.8, "tv": 25840.97, "trd": NaN, "batb": [[0, 2.56, 5.58], [1, 2.36, 27.53], [2, 2.14, 31]], "batl": NaN}, {"timestamp": 1631554502159, "ltp": 2.8, "tv": 25840.97, "trd": NaN, "batb": NaN, "batl": [[0, 2.98, 4.25], [1, 2.98, 0]]}, {"timestamp": 1631554508976, "ltp": 2.8, "tv": 25840.97, "trd": NaN, "batb": NaN, "batl": [[0, 2.9, 4.25], [1, 2.98, 4.25]]}, {"timestamp": 1631554509689, "ltp": 2.8, "tv": 25840.97, "trd": NaN, "batb": NaN, "batl": [[0, 2.98, 4.25], [1, 2.98, 0]]}, {"timestamp": 1631554510583, "ltp": 2.56, "tv": 25841.34, "trd": [[2.56, 0.38]], "batb": [[0, 2.56, 5.39]], "batl": NaN}, {"timestamp": 1631554514859, "ltp": 2.56, "tv": 25849.4, "trd": [[2.56, 8.44]], "batb": [[0, 2.56, 1.36], [1, 2.42, 255.41], [2, 2.36, 27.53]], "batl": [[0, 2.6, 46.15], [1, 2.66, 14.08], [2, 2.84, 1062.34]]}, {"timestamp": 1631554515974, "ltp": 2.56, "tv": 25849.4, "trd": NaN, "batb": [[1, 2.46, 12.2], [2, 2.44, 6.1]], "batl": NaN}, {"timestamp": 1631554522300, "ltp": 2.56, "tv": 25849.4, "trd": NaN, "batb": NaN, "batl": [[2, 2.8, 4.32]]}, {"timestamp": 1631554526900, "ltp": 2.6, "tv": 25870.4, "trd": [[2.6, 21]], "batb": NaN, "batl": [[0, 2.6, 35.65]]}, {"timestamp": 1631554535000, "ltp": 2.6, "tv": 25870.4, "trd": NaN, "batb": [[0, 2.32, 6.64], [1, 2.14, 67], [2, 1.8, 11.97]], "batl": [[0, 2.9, 5.05], [1, 2.98, 4.25], [2, 2.8, 0]]}, {"timestamp": 1631554535426, "ltp": 2.6, "tv": 25870.4, "trd": NaN, "batb": NaN, "batl": [[1, 2.98, 0]]}, {"timestamp": 1631554538602, "ltp": 2.6, "tv": 25870.4, "trd": NaN, "batb": NaN, "batl": [[0, 2.8, 4.37], [1, 2.9, 5.05]]}, {"timestamp": 1631554544746, "ltp": 2.6, "tv": 25870.4, "trd": NaN, "batb": NaN, "batl": [[0, 2.9, 5.05], [1, 2.9, 0]]}, {"timestamp": 1631554547201, "ltp": 2.32, "tv": 25879.1, "trd": [[2.32, 8.7]], "batb": [[0, 2.32, 17.01]], "batl": [[0, 2.4, 319.73], [1, 2.9, 5.05]]}, {"timestamp": 1631554548146, "ltp": 2.32, "tv": 25879.1, "trd": NaN, "batb": [[2, 2.08, 39.19]], "batl": NaN}, {"timestamp": 1631554549513, "ltp": 2.32, "tv": 25913.12, "trd": [[2.32, 42.72]], "batb": [[0, 2.14, 67], [1, 2.08, 39.19], [2, 1.5, 107.72]], "batl": [[0, 2.32, 2.99], [1, 2.4, 319.73], [2, 2.9, 5.05]]}, {"timestamp": 1631554552814, "ltp": 2.32, "tv": 25913.12, "trd": NaN, "batb": NaN, "batl": [[0, 2.4, 319.73], [1, 2.9, 5.05], [2, 2.9, 0]]}, {"timestamp": 1631554554835, "ltp": 2.32, "tv": 25913.12, "trd": NaN, "batb": [[0, 2.26, 6.98], [1, 2.24, 7.77], [2, 2.14, 67]], "batl": [[1, 2.58, 5.94], [2, 2.68, 4.64]]}, {"timestamp": 1631554556145, "ltp": 2.32, "tv": 25913.12, "trd": NaN, "batb": [[2, 2.18, 291.65]], "batl": NaN}, {"timestamp": 1631554556941, "ltp": 2.32, "tv": 25913.12, "trd": NaN, "batb": [[0, 2.28, 6.41], [1, 2.26, 6.98], [2, 2.24, 7.77]], "batl": NaN}, {"timestamp": 1631554559839, "ltp": 2.32, "tv": 25913.12, "trd": NaN, "batb": NaN, "batl": [[0, 2.4, 312.56]]}, {"timestamp": 1631554562167, "ltp": 2.28, "tv": 25913.18, "trd": [[2.28, 14.99]], "batb": [[0, 2.28, 6.38]], "batl": NaN}, {"timestamp": 1631554575771, "ltp": 2.32, "tv": 25921.18, "trd": [[2.32, 50.72]], "batb": NaN, "batl": NaN}, {"timestamp": 1631554583150, "ltp": 2.32, "tv": 25921.18, "trd": NaN, "batb": [[0, 2.22, 31], [1, 2.14, 36], [2, 2.08, 39.19]], "batl": [[0, 2.58, 5.94], [1, 2.68, 4.64], [2, 2.9, 5.05]]}, {"timestamp": 1631554583473, "ltp": 2.32, "tv": 25921.18, "trd": NaN, "batb": [[1, 2.08, 39.19], [2, 1.5, 107.72]], "batl": [[0, 2.68, 4.64], [1, 2.68, 0], [2, 2.9, 0]]}, {"timestamp": 1631554586976, "ltp": 2.32, "tv": 25921.18, "trd": NaN, "batb": [[0, 2.28, 6.16], [1, 2.22, 31], [2, 2.08, 39.19]], "batl": NaN}, {"timestamp": 1631554589180, "ltp": 2.32, "tv": 25921.18, "trd": NaN, "batb": NaN, "batl": [[0, 2.36, 40.57], [1, 2.68, 4.64]]}, {"timestamp": 1631554590180, "ltp": 2.32, "tv": 25921.18, "trd": NaN, "batb": NaN, "batl": [[0, 2.68, 4.64], [1, 2.68, 0]]}, {"timestamp": 1631554593851, "ltp": 2.32, "tv": 25921.18, "trd": NaN, "batb": NaN, "batl": [[0, 2.58, 5.94], [1, 2.68, 4.64]]}, {"timestamp": 1631554605296, "ltp": 2.28, "tv": 25954.06, "trd": [[2.28, 47.87]], "batb": [[0, 2.22, 31], [1, 2.08, 39.19], [2, 1.5, 107.72]], "batl": NaN}, {"timestamp": 1631554608468, "ltp": 2.28, "tv": 25954.06, "trd": NaN, "batb": [[0, 2.28, 6.66], [1, 2.22, 31], [2, 2.08, 39.19]], "batl": NaN}, {"timestamp": 1631554612710, "ltp": 2.28, "tv": 25954.06, "trd": NaN, "batb": [[0, 2.42, 6.27], [1, 2.36, 85.16], [2, 2.28, 6.66]], "batl": NaN}, {"timestamp": 1631554613895, "ltp": 2.42, "tv": 25962.32, "trd": [[2.42, 8.26]], "batb": [[0, 2.42, 2.14], [2, 2.28, 36.7]], "batl": [[0, 2.58, 17.56], [1, 2.6, 5.82], [2, 2.62, 5.82]]}, {"timestamp": 1631554620017, "ltp": 2.42, "tv": 25962.32, "trd": NaN, "batb": [[1, 2.38, 5.96], [2, 2.36, 91.59]], "batl": [[2, 2.62, 10.28]]}, {"timestamp": 1631554623692, "ltp": 2.42, "tv": 25962.32, "trd": NaN, "batb": [[0, 2.38, 5.96], [1, 2.36, 91.59], [2, 2.28, 36.7]], "batl": NaN}, {"timestamp": 1631554626618, "ltp": 2.42, "tv": 25962.32, "trd": NaN, "batb": [[0, 2.4, 7.25], [1, 2.38, 5.96], [2, 2.36, 91.59]], "batl": [[0, 2.46, 7.66], [1, 2.58, 17.56], [2, 2.6, 5.82]]}, {"timestamp": 1631554638095, "ltp": 2.42, "tv": 25962.32, "trd": NaN, "batb": [[0, 2.34, 6.22], [1, 2.22, 31], [2, 2.18, 34.16]], "batl": [[0, 2.44, 4.8], [1, 2.7, 5.05], [2, 2.6, 0]]}, {"timestamp": 1631554641001, "ltp": 2.44, "tv": 25965.89, "trd": [[2.44, 3.57]], "batb": NaN, "batl": [[0, 2.44, 1.23]]}, {"timestamp": 1631554644906, "ltp": 2.44, "tv": 25967.12, "trd": [[2.44, 4.8]], "batb": [[0, 2.36, 6.43], [1, 2.34, 6.22], [2, 2.22, 31]], "batl": [[0, 2.7, 5.05], [1, 2.7, 0]]}, {"timestamp": 1631554646332, "ltp": 2.44, "tv": 25967.12, "trd": NaN, "batb": [[0, 2.34, 6.22], [1, 2.22, 31], [2, 2.18, 34.16]], "batl": NaN}, {"timestamp": 1631554648123, "ltp": 2.44, "tv": 25967.12, "trd": NaN, "batb": NaN, "batl": [[0, 2.62, 5.96], [1, 2.7, 5.05]]}, {"timestamp": 1631554648913, "ltp": 2.44, "tv": 25967.12, "trd": NaN, "batb": NaN, "batl": [[0, 2.7, 5.05], [1, 2.7, 0]]}, {"timestamp": 1631554659054, "ltp": 2.34, "tv": 25976.62, "trd": [[2.34, 15.55], [2.44, 5.76]], "batb": [[0, 2.34, 1.95]], "batl": [[0, 2.4, 12.5], [1, 2.42, 6.24], [2, 2.44, 6.24]]}, {"timestamp": 1631554660058, "ltp": 2.34, "tv": 25998.57, "trd": [[2.34, 37.5]], "batb": [[0, 2.26, 13.28], [1, 2.24, 6.64], [2, 2.22, 37.64]], "batl": NaN}, {"timestamp": 1631554668029, "ltp": 2.4, "tv": 26105.59, "trd": [[2.4, 117.91]], "batb": [[0, 2.4, 284.39], [1, 2.26, 13.28], [2, 2.24, 6.64]], "batl": [[0, 2.42, 6.24], [1, 2.44, 6.24], [2, 2.46, 469.3]]}, {"timestamp": 1631554674946, "ltp": 2.4, "tv": 26105.59, "trd": NaN, "batb": [[1, 2.36, 7.75], [2, 2.26, 13.28]], "batl": [[0, 2.42, 14.23]]}, {"timestamp": 1631554677168, "ltp": 2.4, "tv": 26105.59, "trd": NaN, "batb": [[1, 2.22, 31], [2, 2.1, 38.18]], "batl": [[0, 2.54, 5.25], [1, 2.6, 5.51], [2, 2.62, 5.25]]}, {"timestamp": 1631554677849, "ltp": 2.4, "tv": 26105.59, "trd": NaN, "batb": NaN, "batl": [[0, 2.6, 5.51], [1, 2.6, 0], [2, 2.62, 0]]}, {"timestamp": 1631554681068, "ltp": 2.4, "tv": 26105.59, "trd": NaN, "batb": NaN, "batl": [[0, 2.54, 5.75], [1, 2.6, 5.51]]}, {"timestamp": 1631554681339, "ltp": 2.4, "tv": 26105.59, "trd": NaN, "batb": NaN, "batl": [[0, 2.6, 5.51], [1, 2.6, 0]]}, {"timestamp": 1631554684660, "ltp": 2.4, "tv": 26105.59, "trd": NaN, "batb": NaN, "batl": [[0, 2.54, 5.38], [1, 2.6, 5.51]]}, {"timestamp": 1631554687986, "ltp": 2.4, "tv": 26105.59, "trd": NaN, "batb": NaN, "batl": [[0, 2.6, 5.51], [1, 2.6, 0]]}, {"timestamp": 1631554691180, "ltp": 2.4, "tv": 26105.59, "trd": NaN, "batb": NaN, "batl": [[0, 2.54, 5.75], [1, 2.6, 5.51]]}, {"timestamp": 1631554692192, "ltp": 2.4, "tv": 26105.59, "trd": NaN, "batb": NaN, "batl": [[0, 2.6, 5.51], [1, 2.6, 0]]}, {"timestamp": 1631554695207, "ltp": 2.4, "tv": 26105.59, "trd": NaN, "batb": [[0, 2.5, 68.77], [1, 2.48, 30], [2, 2.46, 30]], "batl": [[0, 2.6, 364.72]]}, {"timestamp": 1631554696175, "ltp": 2.5, "tv": 26113.65, "trd": [[2.5, 39.16]], "batb": [[0, 2.5, 16.74], [1, 2.48, 6], [2, 2.46, 6]], "batl": [[1, 2.68, 11.2], [2, 2.7, 16.79]]}, {"timestamp": 1631554696480, "ltp": 2.5, "tv": 26113.65, "trd": NaN, "batb": NaN, "batl": [[2, 2.7, 5.6]]}, {"timestamp": 1631554722109, "ltp": 2.5, "tv": 26113.65, "trd": NaN, "batb": [[0, 2.4, 284.39], [1, 2.38, 5.46], [2, 2.32, 5.64]], "batl": [[0, 2.82, 4.75], [1, 2.68, 0], [2, 2.7, 0]]}, {"timestamp": 1631554728118, "ltp": 2.5, "tv": 26123.65, "trd": [[2.5, 49.16]], "batb": NaN, "batl": NaN}, {"timestamp": 1631554728801, "ltp": 2.5, "tv": 26123.65, "trd": NaN, "batb": NaN, "batl": [[0, 2.74, 5.25], [1, 2.82, 4.75]]}, {"timestamp": 1631554730112, "ltp": 2.5, "tv": 26123.65, "trd": NaN, "batb": NaN, "batl": [[0, 2.82, 4.75], [1, 2.82, 0]]}, {"timestamp": 1631554735425, "ltp": 2.5, "tv": 26123.65, "trd": NaN, "batb": [[1, 2.32, 5.64], [2, 2.22, 64.06]], "batl": NaN}, {"timestamp": 1631554737027, "ltp": 2.5, "tv": 26123.65, "trd": NaN, "batb": NaN, "batl": [[0, 2.74, 4.98], [1, 2.82, 4.75]]}, {"timestamp": 1631554737225, "ltp": 2.5, "tv": 26123.65, "trd": NaN, "batb": NaN, "batl": [[0, 2.82, 4.75], [1, 2.82, 0]]}, {"timestamp": 1631554738617, "ltp": 2.5, "tv": 26123.65, "trd": NaN, "batb": [[1, 2.38, 5.96], [2, 2.32, 5.64]], "batl": NaN}, {"timestamp": 1631554744032, "ltp": 2.5, "tv": 26123.65, "trd": NaN, "batb": NaN, "batl": [[0, 2.74, 5.25], [1, 2.82, 4.75]]}, {"timestamp": 1631554744240, "ltp": 2.5, "tv": 26123.65, "trd": NaN, "batb": NaN, "batl": [[0, 2.82, 4.75], [1, 2.82, 0]]}, {"timestamp": 1631554750959, "ltp": 2.5, "tv": 26123.65, "trd": NaN, "batb": NaN, "batl": [[0, 2.74, 4.98], [1, 2.82, 4.75]]}, {"timestamp": 1631554751262, "ltp": 2.5, "tv": 26123.65, "trd": NaN, "batb": NaN, "batl": [[0, 2.82, 4.75], [1, 2.82, 0]]}, {"timestamp": 1631554753571, "ltp": 2.5, "tv": 26123.65, "trd": NaN, "batb": [[1, 2.32, 5.64], [2, 2.22, 64.06]], "batl": NaN}, {"timestamp": 1631554756159, "ltp": 2.82, "tv": 26134.7, "trd": [[2.82, 11.05]], "batb": [[0, 2.76, 72.46], [1, 2.4, 284.39], [2, 2.32, 5.64]], "batl": [[0, 2.78, 6.56]]}, {"timestamp": 1631554757154, "ltp": 2.76, "tv": 26142.22, "trd": [[2.76, 7.52]], "batb": [[0, 2.76, 39.72], [1, 2.52, 22.66], [2, 2.4, 284.39]], "batl": NaN}, {"timestamp": 1631554761162, "ltp": 2.76, "tv": 26146.8, "trd": [[2.76, 12.1]], "batb": [[0, 2.76, 37.43]], "batl": NaN}, {"timestamp": 1631554763866, "ltp": 2.76, "tv": 26146.8, "trd": NaN, "batb": [[2, 2.5, 5.8]], "batl": [[1, 3, 3.95], [2, 3.1, 4.05]]}, {"timestamp": 1631554770280, "ltp": 2.78, "tv": 26150.8, "trd": [[2.78, 55.64]], "batb": NaN, "batl": [[0, 2.78, 4.56]]}, {"timestamp": 1631554780101, "ltp": 2.76, "tv": 26188.23, "trd": [[2.76, 49.53]], "batb": [[0, 2.52, 22.66], [1, 2.5, 5.8], [2, 2.44, 6.17]], "batl": NaN}, {"timestamp": 1631554781066, "ltp": 2.76, "tv": 26188.23, "trd": NaN, "batb": [[0, 2.44, 6.17], [1, 2.4, 284.39], [2, 2.38, 26.6]], "batl": [[0, 3, 3.95], [1, 3.1, 4.05], [2, 3.1, 0]]}, {"timestamp": 1631554782171, "ltp": 2.76, "tv": 26188.23, "trd": NaN, "batb": NaN, "batl": [[0, 3.1, 4.05], [1, 3.1, 0]]}, {"timestamp": 1631554784201, "ltp": 2.76, "tv": 26188.23, "trd": NaN, "batb": [[0, 2.5, 5.86], [1, 2.44, 6.17], [2, 2.4, 284.39]], "batl": NaN}, {"timestamp": 1631554785172, "ltp": 2.76, "tv": 26188.23, "trd": NaN, "batb": [[0, 2.44, 6.17], [1, 2.4, 284.39], [2, 2.38, 26.6]], "batl": NaN}, {"timestamp": 1631554787990, "ltp": 2.56, "tv": 26192.17, "trd": [[2.56, 12.38]], "batb": [[0, 2.5, 5.75], [1, 2.44, 6.17], [2, 2.4, 284.39]], "batl": [[0, 2.66, 7.37], [1, 2.68, 11.2], [2, 2.7, 10.65]]}, {"timestamp": 1631554789111, "ltp": 2.56, "tv": 26192.17, "trd": NaN, "batb": [[0, 2.5, 17.75], [1, 2.48, 6], [2, 2.46, 6]], "batl": NaN}, {"timestamp": 1631554799210, "ltp": 2.56, "tv": 26192.17, "trd": NaN, "batb": [[0, 2.4, 284.39], [1, 2.38, 26.6], [2, 2.36, 6.68]], "batl": [[0, 3, 4.08], [1, 3.1, 4.05], [2, 3.15, 3.7]]}, {"timestamp": 1631554800017, "ltp": 2.56, "tv": 26192.17, "trd": NaN, "batb": [[1, 2.36, 6.68], [2, 2.22, 63.64]], "batl": [[0, 3.2, 3.53], [1, 3.1, 0], [2, 3.15, 0]]}, {"timestamp": 1631554803206, "ltp": 2.56, "tv": 26192.17, "trd": NaN, "batb": NaN, "batl": [[0, 3, 4.53], [1, 3.2, 3.53]]}, {"timestamp": 1631554803901, "ltp": 2.56, "tv": 26192.17, "trd": NaN, "batb": NaN, "batl": [[0, 3.2, 3.53], [1, 3.2, 0]]}, {"timestamp": 1631554807104, "ltp": 2.4, "tv": 26200.51, "trd": [[2.4, 126.26]], "batb": [[0, 2.4, 280.22], [2, 2.32, 246.36]], "batl": [[0, 2.5, 319.87], [1, 2.52, 5.51], [2, 3, 3.91]]}, {"timestamp": 1631554813612, "ltp": 2.4, "tv": 26200.51, "trd": NaN, "batb": [[2, 2.32, 252.25]], "batl": [[2, 2.68, 5.14]]}, {"timestamp": 1631554821713, "ltp": 2.4, "tv": 26200.51, "trd": NaN, "batb": [[0, 2.36, 6.68], [1, 2.32, 252.25], [2, 2.3, 59.12]], "batl": NaN}, {"timestamp": 1631554824150, "ltp": 2.4, "tv": 26200.51, "trd": NaN, "batb": [[1, 2.32, 5.89], [2, 2.22, 31]], "batl": [[0, 2.68, 5.14], [1, 2.76, 4.77], [2, 3, 3.91]]}, {"timestamp": 1631554824835, "ltp": 2.4, "tv": 26200.51, "trd": NaN, "batb": [[0, 2.48, 280.22]], "batl": [[0, 2.76, 4.77], [1, 2.76, 0], [2, 3, 0]]}, {"timestamp": 1631554826162, "ltp": 2.4, "tv": 26200.51, "trd": NaN, "batb": [[0, 2.32, 5.89], [1, 2.22, 31], [2, 2.12, 37.18]], "batl": NaN}, {"timestamp": 1631554831183, "ltp": 2.4, "tv": 26200.51, "trd": NaN, "batb": [[0, 2.36, 5.93], [1, 2.32, 5.89], [2, 2.22, 31]], "batl": [[0, 2.68, 5.39], [1, 2.76, 4.77]]}, {"timestamp": 1631554831351, "ltp": 2.4, "tv": 26200.51, "trd": NaN, "batb": [[0, 2.32, 5.89], [1, 2.22, 31], [2, 2.12, 37.18]], "batl": [[0, 2.76, 4.77], [1, 2.76, 0]]}, {"timestamp": 1631554837070, "ltp": 2.32, "tv": 26220.98, "trd": [[2.32, 71.19]], "batb": [[0, 2.22, 31], [1, 2.12, 37.18], [2, 1.5, 107.72]], "batl": NaN}, {"timestamp": 1631554837861, "ltp": 2.32, "tv": 26220.98, "trd": NaN, "batb": [[2, 2.06, 40.7]], "batl": NaN}, {"timestamp": 1631554843154, "ltp": 2.32, "tv": 26220.98, "trd": NaN, "batb": [[0, 2.3, 6.78], [1, 2.22, 31], [2, 2.12, 37.18]], "batl": [[0, 2.5, 5.75], [1, 2.54, 5.38], [2, 2.76, 4.77]]}, {"timestamp": 1631554843680, "ltp": 2.32, "tv": 26220.98, "trd": NaN, "batb": [[1, 2.24, 7.27], [2, 2.22, 37.84]], "batl": [[2, 2.58, 5.25]]}, {"timestamp": 1631554845163, "ltp": 2.32, "tv": 26220.98, "trd": NaN, "batb": [[1, 2.26, 6.98], [2, 2.24, 7.27]], "batl": NaN}, {"timestamp": 1631554847174, "ltp": 2.38, "tv": 26428.62, "trd": [[2.34, 140.68], [2.36, 37.46], [2.38, 83.28]], "batb": [[0, 2.38, 72.27], [1, 2.3, 6.78], [2, 2.28, 6.66]], "batl": NaN}, {"timestamp": 1631554847493, "ltp": 2.38, "tv": 26437.43, "trd": [[2.38, 92.09]], "batb": [[0, 2.38, 65.88]], "batl": NaN}, {"timestamp": 1631554850079, "ltp": 2.38, "tv": 26503.31, "trd": [[2.38, 157.98]], "batb": [[0, 2.3, 6.78], [1, 2.28, 6.66], [2, 2.26, 6.98]], "batl": NaN}, {"timestamp": 1631554856164, "ltp": 2.38, "tv": 26503.31, "trd": NaN, "batb": [[0, 2.22, 31], [1, 2.06, 40.7], [2, 1.5, 107.72]], "batl": [[0, 2.58, 5.25], [1, 2.54, 0], [2, 2.58, 0]]}, {"timestamp": 1631554859073, "ltp": 2.38, "tv": 26503.31, "trd": NaN, "batb": [[0, 2.28, 6.66], [1, 2.22, 31], [2, 2.06, 40.7]], "batl": NaN}, {"timestamp": 1631554865080, "ltp": 2.3, "tv": 26523.31, "trd": [[2.3, 25]], "batb": NaN, "batl": NaN}, {"timestamp": 1631554866978, "ltp": 2.3, "tv": 26523.31, "trd": NaN, "batb": NaN, "batl": [[0, 2.5, 5.45], [1, 2.58, 5.25]]}, {"timestamp": 1631554868079, "ltp": 2.3, "tv": 26523.31, "trd": NaN, "batb": NaN, "batl": [[0, 2.58, 5.25], [1, 2.58, 0]]}, {"timestamp": 1631554874012, "ltp": 2.3, "tv": 26523.31, "trd": NaN, "batb": NaN, "batl": [[0, 2.5, 5.01], [1, 2.58, 5.25]]}, {"timestamp": 1631554874278, "ltp": 2.3, "tv": 26523.31, "trd": NaN, "batb": NaN, "batl": [[0, 2.58, 5.25], [1, 2.58, 0]]}, {"timestamp": 1631554881013, "ltp": 2.3, "tv": 26523.31, "trd": NaN, "batb": NaN, "batl": [[0, 2.5, 5.31], [1, 2.58, 5.25]]}, {"timestamp": 1631554881543, "ltp": 2.3, "tv": 26523.31, "trd": NaN, "batb": NaN, "batl": [[0, 2.58, 5.25], [1, 2.58, 0]]}, {"timestamp": 1631554884113, "ltp": 2.3, "tv": 26523.31, "trd": NaN, "batb": NaN, "batl": [[0, 2.48, 3.4], [1, 2.58, 5.25]]}, {"timestamp": 1631554884747, "ltp": 2.28, "tv": 26534.43, "trd": [[2.28, 58.99]], "batb": [[0, 2.22, 31], [1, 2.06, 40.7], [2, 1.5, 107.72]], "batl": [[0, 2.34, 85.91], [1, 2.38, 11.25], [2, 2.58, 5.25]]}, {"timestamp": 1631554885810, "ltp": 2.28, "tv": 26534.43, "trd": NaN, "batb": [[1, 2.2, 13.64], [2, 2.18, 6.82]], "batl": NaN}, {"timestamp": 1631554905852, "ltp": 2.28, "tv": 26534.43, "trd": NaN, "batb": [[0, 2.2, 13.64], [1, 2.18, 6.82], [2, 2.16, 6.82]], "batl": NaN}, {"timestamp": 1631554907155, "ltp": 2.24, "tv": 26536.43, "trd": [[2.24, 80.5]], "batb": NaN, "batl": NaN}, {"timestamp": 1631554908857, "ltp": 2.24, "tv": 26536.43, "trd": NaN, "batb": [[0, 2.26, 31], [1, 2.2, 13.64], [2, 2.18, 6.82]], "batl": NaN}, {"timestamp": 1631554947193, "ltp": 2.26, "tv": 26570.56, "trd": [[2.26, 120.35]], "batb": [[0, 2.26, 13.94]], "batl": NaN}, {"timestamp": 1631554955809, "ltp": 2.26, "tv": 26587.62, "trd": [[2.26, 137.41]], "batb": [[0, 2.26, 5.41]], "batl": NaN}, {"timestamp": 1631554973945, "ltp": 2.26, "tv": 26593.03, "trd": [[2.26, 142.82]], "batb": [[0, 2.2, 13.64], [1, 2.18, 6.82], [2, 2.16, 6.82]], "batl": NaN}, {"timestamp": 1631554974523, "ltp": 2.26, "tv": 26593.03, "trd": NaN, "batb": NaN, "batl": [[2, 2.54, 6.25]]}, {"timestamp": 1631554984167, "ltp": 2.26, "tv": 26593.03, "trd": NaN, "batb": NaN, "batl": [[0, 2.28, 9.08], [1, 2.34, 85.91], [2, 2.38, 11.25]]}, {"timestamp": 1631554993057, "ltp": 2.26, "tv": 26593.03, "trd": NaN, "batb": [[0, 2.06, 40.7], [1, 1.85, 28.45], [2, 1.5, 107.72]], "batl": [[0, 2.54, 6.25], [1, 2.68, 4.39], [2, 2.38, 0]]}, {"timestamp": 1631554993761, "ltp": 2.26, "tv": 26593.03, "trd": NaN, "batb": [[0, 1.85, 28.45], [1, 1.5, 107.72], [2, 1.4, 149.61]], "batl": [[0, 2.68, 4.39], [1, 2.68, 0]]}, {"timestamp": 1631554996950, "ltp": 2.26, "tv": 26593.03, "trd": NaN, "batb": NaN, "batl": [[0, 2.2, 8.53], [1, 2.54, 5.25], [2, 2.68, 4.39]]}, {"timestamp": 1631554997268, "ltp": 2.26, "tv": 26593.03, "trd": NaN, "batb": NaN, "batl": [[1, 2.68, 4.39], [2, 2.68, 0]]}, {"timestamp": 1631554998690, "ltp": 2.26, "tv": 26593.03, "trd": NaN, "batb": NaN, "batl": [[0, 2.68, 4.39], [1, 2.68, 0]]}, {"timestamp": 1631555004099, "ltp": 2.26, "tv": 26593.03, "trd": NaN, "batb": NaN, "batl": [[0, 2.54, 5.75], [1, 2.68, 4.39]]}, {"timestamp": 1631555004469, "ltp": 2.26, "tv": 26593.03, "trd": NaN, "batb": NaN, "batl": [[0, 2.68, 4.39], [1, 2.68, 0]]}, {"timestamp": 1631555007076, "ltp": 2.26, "tv": 26593.03, "trd": NaN, "batb": [[0, 2.4, 10.66], [1, 2.36, 63.56], [2, 2.34, 31.78]], "batl": NaN}, {"timestamp": 1631555008081, "ltp": 2.26, "tv": 26593.03, "trd": NaN, "batb": [[1, 2.36, 12.72], [2, 2.34, 6.36]], "batl": [[0, 2.42, 4.13], [1, 2.68, 4.39]]}, {"timestamp": 1631555014017, "ltp": 2.4, "tv": 26610.09, "trd": [[2.4, 143.32]], "batb": [[0, 2.4, 2.13]], "batl": [[1, 2.64, 5.18], [2, 2.68, 4.39]]}, {"timestamp": 1631555022108, "ltp": 2.4, "tv": 26610.09, "trd": NaN, "batb": [[0, 2.24, 31.81], [1, 2.02, 43.3], [2, 1.85, 28.45]], "batl": [[0, 2.64, 5.18], [1, 2.68, 4.39], [2, 2.74, 4.48]]}, {"timestamp": 1631555022689, "ltp": 2.4, "tv": 26610.09, "trd": NaN, "batb": [[0, 2.02, 43.3], [1, 1.5, 107.72], [2, 1.4, 149.61]], "batl": [[0, 2.74, 4.48], [1, 2.68, 0], [2, 2.74, 0]]}, {"timestamp": 1631555026208, "ltp": 2.4, "tv": 26610.09, "trd": NaN, "batb": NaN, "batl": [[0, 2.64, 5.93], [1, 2.74, 4.48]]}, {"timestamp": 1631555026519, "ltp": 2.4, "tv": 26610.09, "trd": NaN, "batb": NaN, "batl": [[0, 2.74, 4.48], [1, 2.74, 0]]}, {"timestamp": 1631555028905, "ltp": 2.4, "tv": 26610.09, "trd": NaN, "batb": [[0, 2.56, 5.9], [1, 2.52, 138.88], [2, 2.5, 29.76]], "batl": [[0, 2.66, 14.47], [1, 2.72, 301.43], [2, 2.74, 4.48]]}, {"timestamp": 1631555030014, "ltp": 2.6, "tv": 26613.94, "trd": [[2.6, 24.85]], "batb": [[1, 2.52, 91.26], [2, 2.5, 5.96]], "batl": NaN}, {"timestamp": 1631555032123, "ltp": 2.6, "tv": 26622.48, "trd": [[2.6, 33.38]], "batb": NaN, "batl": NaN}, {"timestamp": 1631555043119, "ltp": 2.6, "tv": 26622.48, "trd": NaN, "batb": [[0, 2.42, 6.44], [1, 2.36, 6.18], [2, 2.22, 32.9]], "batl": [[0, 2.82, 5.25], [1, 2.72, 0], [2, 2.74, 0]]}, {"timestamp": 1631555043435, "ltp": 2.6, "tv": 26622.48, "trd": NaN, "batb": [[0, 2.36, 6.18], [1, 2.22, 32.9], [2, 1.8, 12]], "batl": NaN}, {"timestamp": 1631555050138, "ltp": 2.6, "tv": 26622.48, "trd": NaN, "batb": [[0, 2.42, 6.94], [1, 2.36, 6.18], [2, 2.22, 32.9]], "batl": NaN}, {"timestamp": 1631555050938, "ltp": 2.66, "tv": 26625.05, "trd": [[2.66, 2.57]], "batb": [[0, 2.36, 6.18], [1, 2.22, 32.9], [2, 1.8, 12]], "batl": [[0, 2.64, 16.36], [1, 2.82, 5.25]]}, {"timestamp": 1631555051251, "ltp": 2.66, "tv": 26625.05, "trd": NaN, "batb": NaN, "batl": [[0, 2.82, 5.25], [1, 2.82, 0]]}, {"timestamp": 1631555053740, "ltp": 2.66, "tv": 26625.05, "trd": NaN, "batb": [[0, 2.42, 6.13], [1, 2.36, 6.18], [2, 2.22, 32.9]], "batl": NaN}, {"timestamp": 1631555056141, "ltp": 2.66, "tv": 26625.05, "trd": NaN, "batb": [[0, 2.36, 6.18], [1, 2.22, 32.9], [2, 1.8, 12]], "batl": NaN}, {"timestamp": 1631555062933, "ltp": 2.66, "tv": 26625.05, "trd": NaN, "batb": [[0, 2.42, 5.44], [1, 2.36, 6.18], [2, 2.22, 32.9]], "batl": NaN}, {"timestamp": 1631555064034, "ltp": 2.66, "tv": 26625.05, "trd": NaN, "batb": [[0, 2.36, 6.18], [1, 2.22, 32.9], [2, 1.8, 12]], "batl": [[0, 2.76, 5.02], [1, 2.82, 5.25]]}, {"timestamp": 1631555064242, "ltp": 2.66, "tv": 26625.05, "trd": NaN, "batb": NaN, "batl": [[0, 2.82, 5.25], [1, 2.82, 0]]}, {"timestamp": 1631555071048, "ltp": 2.66, "tv": 26625.05, "trd": NaN, "batb": NaN, "batl": [[0, 2.76, 4.77], [1, 2.82, 5.25]]}, {"timestamp": 1631555071398, "ltp": 2.66, "tv": 26625.05, "trd": NaN, "batb": NaN, "batl": [[0, 2.82, 5.25], [1, 2.82, 0]]}, {"timestamp": 1631555074173, "ltp": 2.78, "tv": 26633.83, "trd": [[2.78, 64.42]], "batb": [[0, 2.7, 77.79], [1, 2.68, 16.67], [2, 2.66, 16.67]], "batl": [[1, 2.84, 190.71]]}, {"timestamp": 1631555074548, "ltp": 2.78, "tv": 26637.48, "trd": [[2.78, 68.07]], "batb": NaN, "batl": [[2, 2.92, 10.28]]}, {"timestamp": 1631555079859, "ltp": 2.78, "tv": 26637.48, "trd": NaN, "batb": NaN, "batl": [[2, 2.86, 4.75]]}, {"timestamp": 1631555083178, "ltp": 2.78, "tv": 26638.32, "trd": [[2.78, 68.91]], "batb": NaN, "batl": NaN}, {"timestamp": 1631555086546, "ltp": 2.78, "tv": 26638.32, "trd": NaN, "batb": NaN, "batl": [[1, 2.84, 200.85]]}, {"timestamp": 1631555097197, "ltp": 2.78, "tv": 26638.32, "trd": NaN, "batb": [[0, 2.7, 42.6], [1, 2.68, 2.78], [2, 2.66, 2.78]], "batl": [[1, 2.86, 4.75], [2, 2.9, 4.35]]}, {"timestamp": 1631555098097, "ltp": 2.78, "tv": 26638.32, "trd": NaN, "batb": [[0, 2.56, 5.58], [1, 2.4, 25.85], [2, 1.8, 12]], "batl": [[0, 2.9, 4.35], [1, 2.86, 0], [2, 2.9, 0]]}, {"timestamp": 1631555104616, "ltp": 2.78, "tv": 26638.32, "trd": NaN, "batb": [[0, 2.6, 5.49], [1, 2.56, 5.58], [2, 2.4, 25.85]], "batl": NaN}, {"timestamp": 1631555107907, "ltp": 2.78, "tv": 26638.32, "trd": NaN, "batb": [[0, 2.56, 5.58], [1, 2.4, 25.85], [2, 1.8, 12]], "batl": [[0, 2.86, 4.75], [1, 2.9, 4.35]]}, {"timestamp": 1631555108709, "ltp": 2.78, "tv": 26638.32, "trd": NaN, "batb": NaN, "batl": [[0, 2.9, 4.35], [1, 2.9, 0]]}, {"timestamp": 1631555110023, "ltp": 2.8, "tv": 26640.05, "trd": [[2.8, 16.34]], "batb": NaN, "batl": [[0, 2.8, 1.88], [1, 2.9, 4.35]]}, {"timestamp": 1631555115105, "ltp": 2.8, "tv": 26640.05, "trd": NaN, "batb": NaN, "batl": [[1, 2.86, 5.25], [2, 2.9, 4.35]]}, {"timestamp": 1631555115621, "ltp": 2.8, "tv": 26640.05, "trd": NaN, "batb": NaN, "batl": [[1, 2.9, 4.35], [2, 2.9, 0]]}, {"timestamp": 1631555116728, "ltp": 2.8, "tv": 26641.45, "trd": [[2.8, 17.75]], "batb": NaN, "batl": [[0, 2.9, 4.83], [1, 2.9, 0]]}, {"timestamp": 1631555125211, "ltp": 2.8, "tv": 26641.45, "trd": NaN, "batb": [[0, 2.6, 7.01], [1, 2.56, 5.58], [2, 2.5, 271.01]], "batl": [[0, 2.62, 3.82], [1, 2.72, 11.04], [2, 2.74, 5.52]]}, {"timestamp": 1631555125921, "ltp": 2.8, "tv": 26641.45, "trd": NaN, "batb": [[2, 2.54, 11.82]], "batl": NaN}, {"timestamp": 1631555154186, "ltp": 2.8, "tv": 26641.45, "trd": NaN, "batb": [[0, 2.46, 6.51], [1, 2.42, 6.13], [2, 2.4, 25.85]], "batl": [[0, 2.82, 5.73], [1, 2.9, 4.35], [2, 2.74, 0]]}, {"timestamp": 1631555154981, "ltp": 2.8, "tv": 26641.45, "trd": NaN, "batb": [[0, 2.42, 6.13], [1, 2.22, 32.64], [2, 1.8, 12]], "batl": [[1, 2.9, 0]]}, {"timestamp": 1631555158198, "ltp": 2.8, "tv": 26641.45, "trd": NaN, "batb": [[0, 2.46, 5.88], [1, 2.42, 6.13], [2, 2.22, 32.64]], "batl": NaN}, {"timestamp": 1631555159163, "ltp": 2.8, "tv": 26641.45, "trd": NaN, "batb": [[0, 2.42, 6.13], [1, 2.22, 32.64], [2, 1.8, 12]], "batl": NaN}, {"timestamp": 1631555161067, "ltp": 2.8, "tv": 26641.45, "trd": NaN, "batb": NaN, "batl": [[0, 2.76, 4.27], [1, 2.82, 5.73]]}, {"timestamp": 1631555162075, "ltp": 2.8, "tv": 26641.45, "trd": NaN, "batb": NaN, "batl": [[0, 2.62, 21.75]]}, {"timestamp": 1631555162556, "ltp": 2.8, "tv": 26641.45, "trd": NaN, "batb": NaN, "batl": [[0, 2.82, 5.73], [1, 2.82, 0]]}, {"timestamp": 1631555168060, "ltp": 2.8, "tv": 26641.45, "trd": NaN, "batb": NaN, "batl": [[0, 2.76, 4.52], [1, 2.82, 5.73]]}, {"timestamp": 1631555169046, "ltp": 2.8, "tv": 26641.45, "trd": NaN, "batb": [[0, 2.46, 5.88], [1, 2.42, 6.13], [2, 2.22, 32.64]], "batl": [[0, 2.82, 5.73], [1, 2.82, 0]]}, {"timestamp": 1631555170175, "ltp": 2.8, "tv": 26641.45, "trd": NaN, "batb": [[0, 2.42, 6.13], [1, 2.22, 32.64], [2, 1.8, 12]], "batl": NaN}, {"timestamp": 1631555175179, "ltp": 2.8, "tv": 26641.45, "trd": NaN, "batb": NaN, "batl": [[0, 2.76, 4.27], [1, 2.82, 5.73]]}, {"timestamp": 1631555176076, "ltp": 2.8, "tv": 26641.45, "trd": NaN, "batb": [[0, 2.46, 5.51], [1, 2.42, 6.13], [2, 2.22, 32.64]], "batl": [[0, 2.82, 5.73], [1, 2.82, 0]]}, {"timestamp": 1631555176496, "ltp": 2.8, "tv": 26641.45, "trd": NaN, "batb": [[0, 2.42, 6.13], [1, 2.22, 32.64], [2, 1.8, 12]], "batl": NaN}, {"timestamp": 1631555179157, "ltp": 2.8, "tv": 26641.45, "trd": NaN, "batb": NaN, "batl": [[0, 2.76, 5.27], [1, 2.82, 5.73]]}, {"timestamp": 1631555179964, "ltp": 2.42, "tv": 26645.49, "trd": [[2.42, 12.3]], "batb": [[0, 2.42, 2.09]], "batl": [[0, 2.82, 5.73], [1, 2.82, 0]]}, {"timestamp": 1631555181700, "ltp": 2.42, "tv": 26645.49, "trd": NaN, "batb": [[1, 2.4, 9.04], [2, 2.32, 256.89]], "batl": [[0, 2.44, 4.1], [1, 2.46, 87.73], [2, 2.48, 12.1]]}, {"timestamp": 1631555182763, "ltp": 2.42, "tv": 26645.49, "trd": NaN, "batb": [[2, 2.32, 269.83]], "batl": NaN}, {"timestamp": 1631555191204, "ltp": 2.44, "tv": 26649.59, "trd": [[2.44, 9.86]], "batb": NaN, "batl": [[0, 2.46, 87.73], [1, 2.48, 12.1], [2, 2.5, 279.66]]}, {"timestamp": 1631555212129, "ltp": 2.44, "tv": 26649.59, "trd": NaN, "batb": [[0, 2.22, 32.64], [1, 1.95, 48.42], [2, 1.4, 149.61]], "batl": [[0, 2.82, 5.73], [1, 2.9, 4.55], [2, 880, 0.01]]}, {"timestamp": 1631555212510, "ltp": 2.44, "tv": 26649.59, "trd": NaN, "batb": [[0, 1.95, 48.42], [1, 1.4, 149.61], [2, 1.32, 12.7]], "batl": NaN}, {"timestamp": 1631555215640, "ltp": 2.44, "tv": 26649.59, "trd": NaN, "batb": NaN, "batl": [[0, 2.76, 4.77], [1, 2.82, 5.73], [2, 2.9, 4.55]]}, {"timestamp": 1631555226137, "ltp": 2.28, "tv": 26651.63, "trd": [[2.28, 61.03]], "batb": NaN, "batl": [[0, 2.14, 4.67], [1, 2.16, 29.69], [2, 2.2, 443.85]]}, {"timestamp": 1631555226554, "ltp": 2.28, "tv": 26651.63, "trd": NaN, "batb": [[0, 2.08, 72.12], [1, 2.06, 36.06], [2, 2.04, 36.06]], "batl": NaN}, {"timestamp": 1631555227964, "ltp": 2.28, "tv": 26651.63, "trd": NaN, "batb": [[0, 2.08, 14.42], [1, 2.06, 7.22], [2, 2.04, 7.22]], "batl": [[2, 2.2, 389.31]]}, {"timestamp": 1631555232840, "ltp": 2.08, "tv": 26683.12, "trd": [[2.08, 31.49]], "batb": [[0, 2.06, 7.22], [1, 2.04, 7.22], [2, 1.95, 48.42]], "batl": NaN}, {"timestamp": 1631555240174, "ltp": 2.1, "tv": 26683.57, "trd": [[2.1, 0.45]], "batb": NaN, "batl": NaN}, {"timestamp": 1631555240967, "ltp": 2.1, "tv": 26683.57, "trd": NaN, "batb": NaN, "batl": [[0, 2.1, 10], [1, 2.14, 4.67], [2, 2.16, 29.69]]}, {"timestamp": 1631555241475, "ltp": 2.1, "tv": 26683.93, "trd": [[2.1, 0.81]], "batb": NaN, "batl": [[0, 2.1, 9.64]]}, {"timestamp": 1631555243055, "ltp": 2.1, "tv": 26693.57, "trd": [[2.1, 10.45]], "batb": NaN, "batl": [[0, 2.14, 4.67], [1, 2.16, 18.98], [2, 2.2, 389.31]]}, {"timestamp": 1631555246168, "ltp": 2.12, "tv": 26693.93, "trd": [[2.12, 5.12]], "batb": NaN, "batl": [[1, 2.16, 32.24]]}, {"timestamp": 1631555248168, "ltp": 2.12, "tv": 26693.93, "trd": NaN, "batb": [[0, 1.67, 40.03], [1, 1.4, 149.61], [2, 1.32, 12.7]], "batl": [[0, 2.52, 5.51], [1, 2.7, 5.15], [2, 2.74, 5.25]]}, {"timestamp": 1631555251158, "ltp": 2.12, "tv": 26694.29, "trd": [[2.12, 5.48]], "batb": NaN, "batl": NaN}, {"timestamp": 1631555261892, "ltp": 2.12, "tv": 26694.29, "trd": NaN, "batb": [[1, 1.32, 12.7], [2, 1.03, 498.71]], "batl": NaN}, {"timestamp": 1631555264101, "ltp": 2.0, "tv": 26714.29, "trd": [[2, 56.69]], "batb": [[0, 1.74, 93.47], [1, 1.72, 727.65], [2, 1.67, 40.03]], "batl": [[0, 1.8, 104.02], [1, 1.82, 101.18], [2, 1.83, 17.46]]}, {"timestamp": 1631555265107, "ltp": 2.0, "tv": 26714.29, "trd": NaN, "batb": [[0, 1.77, 16.96], [1, 1.76, 8.48], [2, 1.75, 8.48]], "batl": NaN}, {"timestamp": 1631555268900, "ltp": 1.8, "tv": 26800.85, "trd": [[1.8, 86.56]], "batb": [[0, 1.77, 25.46]], "batl": [[0, 1.8, 17.46]]}, {"timestamp": 1631555269281, "ltp": 1.8, "tv": 26800.85, "trd": NaN, "batb": NaN, "batl": [[0, 1.83, 17.46], [1, 1.84, 71.28], [2, 1.87, 80.75]]}, {"timestamp": 1631555272418, "ltp": 1.8, "tv": 26800.85, "trd": NaN, "batb": [[0, 1.78, 9.08], [1, 1.77, 25.46], [2, 1.76, 8.48]], "batl": [[0, 1.81, 107.06], [1, 1.83, 116.8], [2, 1.84, 71.28]]}, {"timestamp": 1631555273882, "ltp": 1.81, "tv": 26817.92, "trd": [[1.81, 17.06]], "batb": NaN, "batl": [[0, 1.81, 98.53]]}, {"timestamp": 1631555274895, "ltp": 1.76, "tv": 26953.21, "trd": [[1.76, 16.96], [1.77, 50.93], [1.78, 29.36], [1.8, 107.54], [1.81, 34.13]], "batb": [[0, 1.75, 93.07], [1, 1.73, 117.67], [2, 1.72, 607.51]], "batl": [[0, 1.76, 157.77], [1, 1.81, 90], [2, 1.83, 116.8]]}, {"timestamp": 1631555277105, "ltp": 1.76, "tv": 26963.42, "trd": [[1.76, 27.18]], "batb": NaN, "batl": [[0, 1.76, 147.55], [2, 1.83, 104.8]]}, {"timestamp": 1631555277789, "ltp": 1.76, "tv": 27040.45, "trd": [[1.76, 104.21]], "batb": [[0, 1.75, 116.43]], "batl": [[0, 1.76, 109.04], [1, 1.81, 97.64]]}, {"timestamp": 1631555278996, "ltp": 1.76, "tv": 27045.45, "trd": [[1.76, 109.21]], "batb": NaN, "batl": [[0, 1.76, 270.54]]}, {"timestamp": 1631555280098, "ltp": 1.76, "tv": 27073.33, "trd": [[1.76, 137.08]], "batb": NaN, "batl": [[0, 1.76, 256.6], [1, 1.8, 11.7], [2, 1.81, 97.64]]}, {"timestamp": 1631555280830, "ltp": 1.76, "tv": 27073.33, "trd": NaN, "batb": [[1, 1.74, 18.35], [2, 1.73, 117.67]], "batl": [[1, 1.77, 18.47], [2, 1.8, 11.7]]}, {"timestamp": 1631555281719, "ltp": 1.76, "tv": 27073.33, "trd": NaN, "batb": NaN, "batl": [[2, 1.78, 22.09]]}, {"timestamp": 1631555282821, "ltp": 1.76, "tv": 27073.87, "trd": [[1.76, 137.62]], "batb": NaN, "batl": [[0, 1.76, 256.33]]}, {"timestamp": 1631555284089, "ltp": 1.75, "tv": 27197.99, "trd": [[1.75, 11.84], [1.76, 249.9]], "batb": [[0, 1.75, 110.51]], "batl": [[0, 1.76, 200.19]]}, {"timestamp": 1631555285030, "ltp": 1.75, "tv": 27197.99, "trd": NaN, "batb": NaN, "batl": [[2, 1.81, 97.64]]}, {"timestamp": 1631555286210, "ltp": 1.75, "tv": 27197.99, "trd": NaN, "batb": [[0, 1.75, 107.95]], "batl": [[0, 1.76, 164]]}, {"timestamp": 1631555286822, "ltp": 1.75, "tv": 27197.99, "trd": NaN, "batb": [[0, 1.6, 256.02], [1, 1.4, 78.8], [2, 1.32, 12.7]], "batl": [[1, 2.2, 7.83], [2, 2.32, 5.61]]}, {"timestamp": 1631555288025, "ltp": 1.75, "tv": 27197.99, "trd": NaN, "batb": NaN, "batl": [[0, 2.32, 5.61], [1, 2.34, 6.25], [2, 2.52, 5.51]]}, {"timestamp": 1631555288501, "ltp": 1.75, "tv": 27197.99, "trd": NaN, "batb": NaN, "batl": [[0, 1.89, 256.02], [1, 2.32, 5.61], [2, 2.34, 6.25]]}, {"timestamp": 1631555289538, "ltp": 1.75, "tv": 27197.99, "trd": NaN, "batb": [[1, 1.47, 145.29], [2, 1.46, 114.53]], "batl": [[1, 2.12, 53.14], [2, 2.14, 61.19]]}, {"timestamp": 1631555299852, "ltp": 1.89, "tv": 27208.08, "trd": [[1.89, 930.85]], "batb": NaN, "batl": [[0, 1.89, 245.92]]}, {"timestamp": 1631555302222, "ltp": 1.89, "tv": 27238.85, "trd": [[1.89, 961.62]], "batb": NaN, "batl": [[0, 1.89, 215.16]]}, {"timestamp": 1631555306138, "ltp": 1.89, "tv": 27238.85, "trd": NaN, "batb": NaN, "batl": [[0, 2.12, 53.14], [1, 2.14, 61.19], [2, 2.32, 5.61]]}, {"timestamp": 1631555309039, "ltp": 1.89, "tv": 27238.85, "trd": NaN, "batb": [[0, 1.47, 145.29], [1, 1.46, 114.53], [2, 1.4, 78.8]], "batl": NaN}, {"timestamp": 1631555317849, "ltp": 1.89, "tv": 27238.85, "trd": NaN, "batb": [[0, 1.48, 2.88], [1, 1.47, 145.29], [2, 1.46, 114.53]], "batl": NaN}, {"timestamp": 1631555319160, "ltp": 1.89, "tv": 27238.85, "trd": NaN, "batb": [[1, 1.4, 78.8], [2, 1.32, 12.7]], "batl": [[0, 2.32, 5.61], [1, 2.34, 6.25], [2, 2.52, 5.51]]}, {"timestamp": 1631555321054, "ltp": 2.1, "tv": 27248.94, "trd": [[2.1, 20.54]], "batb": [[0, 2, 7.58], [1, 1.48, 2.88], [2, 1.4, 78.8]], "batl": [[0, 2.2, 471.17], [1, 2.32, 5.61], [2, 2.34, 6.25]]}, {"timestamp": 1631555322164, "ltp": 2.1, "tv": 27248.94, "trd": NaN, "batb": [[1, 1.93, 49.76], [2, 1.66, 41.12]], "batl": [[0, 2.12, 4.72], [1, 2.2, 471.17], [2, 2.32, 5.61]]}, {"timestamp": 1631555329077, "ltp": 2.1, "tv": 27253.94, "trd": [[2.1, 25.54]], "batb": NaN, "batl": NaN}, {"timestamp": 1631555330175, "ltp": 2.1, "tv": 27271.0, "trd": [[2.1, 42.61]], "batb": NaN, "batl": NaN}, {"timestamp": 1631555331171, "ltp": 2.1, "tv": 27271.0, "trd": NaN, "batb": [[0, 2.02, 116.85], [1, 2, 7.58], [2, 1.93, 49.76]], "batl": NaN}, {"timestamp": 1631555332167, "ltp": 2.1, "tv": 27271.0, "trd": NaN, "batb": [[1, 1.93, 49.76], [2, 1.66, 41.12]], "batl": NaN}, {"timestamp": 1631555335190, "ltp": 2.1, "tv": 27298.69, "trd": [[2.1, 70.3]], "batb": NaN, "batl": NaN}, {"timestamp": 1631555336146, "ltp": 2.08, "tv": 27334.54, "trd": [[2.08, 63.55], [2.1, 74.08]], "batb": NaN, "batl": NaN}, {"timestamp": 1631555337084, "ltp": 2.08, "tv": 27334.54, "trd": NaN, "batb": [[0, 1.93, 49.76], [1, 1.66, 41.12], [2, 1.32, 12.7]], "batl": [[0, 2.1, 57.89], [1, 2.12, 4.72], [2, 2.2, 471.17]]}, {"timestamp": 1631555339180, "ltp": 2.1, "tv": 27340.86, "trd": [[2.1, 80.4]], "batb": NaN, "batl": [[0, 2.1, 51.57]]}, {"timestamp": 1631555340071, "ltp": 2.08, "tv": 27350.21, "trd": [[2.08, 72.9]], "batb": [[0, 1.94, 72.65], [1, 1.93, 49.76], [2, 1.66, 41.12]], "batl": [[0, 2.08, 57.72], [1, 2.1, 118.69], [2, 2.12, 4.72]]}, {"timestamp": 1631555341189, "ltp": 2.08, "tv": 27367.14, "trd": [[2.08, 89.83]], "batb": NaN, "batl": [[0, 2.08, 40.79]]}, {"timestamp": 1631555343172, "ltp": 2.06, "tv": 27383.39, "trd": [[2.06, 21.15]], "batb": [[0, 1.95, 65.32], [1, 1.94, 72.65], [2, 1.93, 49.76]], "batl": [[0, 2.06, 45.21], [1, 2.08, 40.79], [2, 2.1, 118.69]]}, {"timestamp": 1631555343963, "ltp": 2.06, "tv": 27383.39, "trd": NaN, "batb": [[0, 1.95, 1600.04]], "batl": [[1, 2.1, 67.12], [2, 2.12, 4.72]]}, {"timestamp": 1631555347004, "ltp": 2.04, "tv": 27422.32, "trd": [[2.04, 38.93]], "batb": [[0, 1.96, 58.83], [1, 1.95, 1600.04], [2, 1.94, 72.65]], "batl": [[0, 2.06, 2.42]]}, {"timestamp": 1631555348211, "ltp": 2.06, "tv": 27427.16, "trd": [[2.06, 25.99]], "batb": [[0, 2.06, 5.65], [1, 1.96, 58.83], [2, 1.95, 65.32]], "batl": [[0, 2.12, 19.75], [1, 2.2, 471.17], [2, 2.32, 5.61]]}, {"timestamp": 1631555350206, "ltp": 2.04, "tv": 27449.88, "trd": [[2.04, 50.35], [2.06, 37.29]], "batb": [[0, 1.93, 49.76], [1, 1.8, 20], [2, 1.66, 41.12]], "batl": NaN}, {"timestamp": 1631555350895, "ltp": 2.04, "tv": 27449.88, "trd": NaN, "batb": [[0, 1.8, 20], [1, 1.66, 41.12], [2, 1.32, 12.7]], "batl": [[0, 2.4, 6.19], [1, 2.52, 5.51], [2, 2.54, 5.75]]}, {"timestamp": 1631555353204, "ltp": 2.04, "tv": 27449.88, "trd": NaN, "batb": [[0, 1.96, 1473.31], [1, 1.94, 54.29], [2, 1.8, 20]], "batl": NaN}, {"timestamp": 1631555353816, "ltp": 2.04, "tv": 27449.88, "trd": NaN, "batb": [[0, 1.8, 20], [1, 1.66, 41.12], [2, 1.32, 12.7]], "batl": NaN}, {"timestamp": 1631555358023, "ltp": 2.04, "tv": 27449.88, "trd": NaN, "batb": NaN, "batl": [[0, 2.38, 6.75], [1, 2.4, 6.19], [2, 2.52, 5.51]]}, {"timestamp": 1631555359119, "ltp": 2.04, "tv": 27449.88, "trd": NaN, "batb": NaN, "batl": [[0, 2.4, 6.19], [1, 2.52, 5.51], [2, 2.54, 5.75]]}, {"timestamp": 1631555368041, "ltp": 2.04, "tv": 27449.88, "trd": NaN, "batb": NaN, "batl": [[0, 2.06, 3.61], [1, 2.4, 6.19], [2, 2.52, 5.51]]}, {"timestamp": 1631555373745, "ltp": 2.04, "tv": 27449.88, "trd": NaN, "batb": NaN, "batl": [[1, 2.38, 6.25], [2, 2.4, 6.19]]}, {"timestamp": 1631555374949, "ltp": 2.04, "tv": 27449.88, "trd": NaN, "batb": NaN, "batl": [[0, 2.4, 6.19], [1, 2.52, 5.51], [2, 2.54, 5.75]]}, {"timestamp": 1631555378052, "ltp": 1.94, "tv": 27453.49, "trd": [[1.94, 3.43], [2.04, 50.53]], "batb": NaN, "batl": NaN}, {"timestamp": 1631555392167, "ltp": 1.8, "tv": 27493.49, "trd": [[1.8, 147.54]], "batb": [[0, 1.74, 94], [1, 1.72, 120.13], [2, 1.66, 41.12]], "batl": [[0, 1.76, 94.21], [1, 1.78, 9.76], [2, 1.79, 68.08]]}, {"timestamp": 1631555393056, "ltp": 1.8, "tv": 27493.49, "trd": NaN, "batb": [[1, 1.73, 17.34], [2, 1.72, 128.81]], "batl": NaN}, {"timestamp": 1631555396365, "ltp": 1.76, "tv": 27539.96, "trd": [[1.76, 296.37]], "batb": NaN, "batl": [[0, 1.76, 47.74]]}, {"timestamp": 1631555397569, "ltp": 1.76, "tv": 27539.96, "trd": NaN, "batb": NaN, "batl": [[0, 1.76, 138.74]]}, {"timestamp": 1631555399090, "ltp": 1.74, "tv": 27568.42, "trd": [[1.74, 8.62], [1.76, 316.21]], "batb": [[0, 1.74, 89.69]], "batl": [[0, 1.76, 118.9]]}, {"timestamp": 1631555399884, "ltp": 1.74, "tv": 27621.86, "trd": [[1.74, 52.06], [1.76, 326.21]], "batb": [[0, 1.74, 67.97], [2, 1.72, 173.9]], "batl": [[0, 1.76, 113.9]]}, {"timestamp": 1631555401067, "ltp": 1.76, "tv": 27655.99, "trd": [[1.76, 360.33]], "batb": NaN, "batl": [[0, 1.76, 96.84]]}, {"timestamp": 1631555401688, "ltp": 1.76, "tv": 27661.65, "trd": [[1.76, 366]], "batb": NaN, "batl": [[0, 1.76, 94.01]]}, {"timestamp": 1631555405174, "ltp": 1.76, "tv": 27661.65, "trd": NaN, "batb": [[1, 1.73, 60.36]], "batl": NaN}, {"timestamp": 1631555406075, "ltp": 1.76, "tv": 27665.61, "trd": [[1.76, 369.96]], "batb": NaN, "batl": [[0, 1.76, 92.03]]}, {"timestamp": 1631555407075, "ltp": 1.76, "tv": 27777.88, "trd": [[1.76, 482.22]], "batb": NaN, "batl": [[0, 1.76, 35.9]]}, {"timestamp": 1631555408654, "ltp": 1.76, "tv": 27813.78, "trd": [[1.76, 518.12]], "batb": NaN, "batl": [[0, 1.78, 9.76], [1, 1.79, 68.08], [2, 1.8, 72.62]]}, {"timestamp": 1631555409388, "ltp": 1.76, "tv": 27820.79, "trd": [[1.76, 525.14]], "batb": NaN, "batl": [[0, 1.79, 68.08], [1, 1.8, 72.62], [2, 1.81, 119.64]]}, {"timestamp": 1631555412187, "ltp": 1.76, "tv": 27820.79, "trd": NaN, "batb": [[0, 1.74, 105.48], [2, 1.72, 188.18]], "batl": NaN}, {"timestamp": 1631555412392, "ltp": 1.76, "tv": 27820.79, "trd": NaN, "batb": [[2, 1.72, 173.9]], "batl": NaN}, {"timestamp": 1631555413985, "ltp": 1.76, "tv": 27820.79, "trd": NaN, "batb": [[0, 1.74, 105.52]], "batl": NaN}, {"timestamp": 1631555415083, "ltp": 1.76, "tv": 27820.79, "trd": NaN, "batb": NaN, "batl": [[0, 1.79, 135.08]]}, {"timestamp": 1631555415297, "ltp": 1.76, "tv": 27820.79, "trd": NaN, "batb": [[2, 1.72, 188.18]], "batl": NaN}, {"timestamp": 1631555417090, "ltp": 1.76, "tv": 27982.56, "trd": [[1.76, 686.91]], "batb": [[0, 1.74, 105.48]], "batl": [[0, 1.76, 77.21], [1, 1.79, 135.08], [2, 1.8, 72.62]]}, {"timestamp": 1631555417392, "ltp": 1.76, "tv": 27982.56, "trd": NaN, "batb": NaN, "batl": [[1, 1.79, 68.08]]}, {"timestamp": 1631555420494, "ltp": 1.76, "tv": 27982.56, "trd": NaN, "batb": NaN, "batl": [[0, 1.76, 246.21]]}, {"timestamp": 1631555422699, "ltp": 1.76, "tv": 27982.56, "trd": NaN, "batb": [[2, 1.72, 173.9]], "batl": [[0, 1.76, 169]]}, {"timestamp": 1631555425803, "ltp": 1.76, "tv": 28003.16, "trd": [[1.76, 707.51]], "batb": NaN, "batl": [[0, 1.75, 77.21], [1, 1.76, 158.7], [2, 1.79, 68.08]]}, {"timestamp": 1631555426380, "ltp": 1.75, "tv": 28003.18, "trd": [[1.75, 11.86]], "batb": NaN, "batl": [[0, 1.75, 77.21]]}, {"timestamp": 1631555427290, "ltp": 1.76, "tv": 28343.18, "trd": [[1.75, 166.28], [1.76, 893.09]], "batb": NaN, "batl": [[0, 1.76, 65.91], [1, 1.79, 68.08], [2, 1.8, 72.62]]}, {"timestamp": 1631555428704, "ltp": 1.76, "tv": 28363.78, "trd": [[1.76, 913.69]], "batb": [[0, 1.74, 37.51], [2, 1.72, 53.77]], "batl": [[0, 1.76, 55.61], [1, 1.8, 87.92], [2, 1.81, 16.58]]}, {"timestamp": 1631555432177, "ltp": 1.74, "tv": 28363.9, "trd": [[1.74, 52.18]], "batb": [[0, 1.66, 41.12], [1, 1.6, 256.02], [2, 1.46, 174.76]], "batl": [[0, 1.76, 158.7], [1, 1.89, 256.02], [2, 2.1, 62.49]]}, {"timestamp": 1631555432592, "ltp": 1.74, "tv": 28363.9, "trd": NaN, "batb": [[0, 1.6, 256.02], [1, 1.46, 174.76], [2, 1.45, 118.24]], "batl": [[0, 1.89, 256.02], [1, 2.1, 62.49], [2, 2.12, 62.94]]}, {"timestamp": 1631555439188, "ltp": 1.89, "tv": 28377.36, "trd": [[1.89, 975.07]], "batb": NaN, "batl": [[0, 1.89, 242.56], [1, 880, 0.48], [2, 2.12, 0]]}, {"timestamp": 1631555440119, "ltp": 1.89, "tv": 28377.36, "trd": NaN, "batb": [[0, 1.46, 174.76], [1, 1.45, 118.24], [2, 1.4, 79.98]], "batl": NaN}, {"timestamp": 1631555441902, "ltp": 1.89, "tv": 28377.36, "trd": NaN, "batb": [[2, 1.43, 870.12]], "batl": [[0, 1.5, 99.77], [1, 1.51, 158.47], [2, 1.52, 36.39]]}, {"timestamp": 1631555443010, "ltp": 1.89, "tv": 28377.36, "trd": NaN, "batb": [[1, 1.45, 138.92], [2, 1.44, 10.34]], "batl": [[1, 1.51, 118.73], [2, 1.52, 16.52]]}, {"timestamp": 1631555444007, "ltp": 1.5, "tv": 28381.36, "trd": [[1.5, 178.87]], "batb": NaN, "batl": [[0, 1.5, 95.77]]}, {"timestamp": 1631555446208, "ltp": 1.5, "tv": 28381.36, "trd": NaN, "batb": [[0, 1.47, 44.5], [1, 1.46, 174.76], [2, 1.45, 138.92]], "batl": NaN}, {"timestamp": 1631555447931, "ltp": 1.5, "tv": 28381.36, "trd": NaN, "batb": [[0, 1.47, 59.23]], "batl": [[0, 1.49, 100], [1, 1.5, 95.77], [2, 1.51, 118.73]]}, {"timestamp": 1631555449130, "ltp": 1.5, "tv": 28381.36, "trd": NaN, "batb": [[0, 1.47, 73.97]], "batl": NaN}, {"timestamp": 1631555450130, "ltp": 1.5, "tv": 28381.36, "trd": NaN, "batb": [[0, 1.48, 17.2], [1, 1.47, 73.97], [2, 1.46, 174.76]], "batl": NaN}, {"timestamp": 1631555450711, "ltp": 1.49, "tv": 28396.0, "trd": [[1.49, 105.31]], "batb": [[2, 1.46, 222.45]], "batl": [[0, 1.49, 85.36]]}, {"timestamp": 1631555452026, "ltp": 1.5, "tv": 28536.91, "trd": [[1.49, 190.67], [1.5, 234.42]], "batb": [[2, 1.46, 161.82]], "batl": [[0, 1.51, 118.73], [1, 1.52, 16.52], [2, 1.53, 9.94]]}, {"timestamp": 1631555455042, "ltp": 1.5, "tv": 28536.91, "trd": NaN, "batb": [[0, 1.48, 60.63], [1, 1.47, 167.86]], "batl": [[0, 1.51, 185.11], [1, 1.52, 112.3]]}, {"timestamp": 1631555455920, "ltp": 1.5, "tv": 28536.91, "trd": NaN, "batb": NaN, "batl": [[0, 1.51, 118.73], [1, 1.52, 16.52]]}, {"timestamp": 1631555456909, "ltp": 1.48, "tv": 28564.61, "trd": [[1.48, 521.97], [1.49, 190.69]], "batb": [[0, 1.48, 61.2]], "batl": [[0, 1.5, 70.98], [1, 1.51, 118.73], [2, 1.52, 16.52]]}, {"timestamp": 1631555458009, "ltp": 1.48, "tv": 28564.61, "trd": NaN, "batb": [[1, 1.47, 182.59]], "batl": NaN}, {"timestamp": 1631555458524, "ltp": 1.48, "tv": 28564.61, "trd": NaN, "batb": NaN, "batl": [[1, 1.51, 239.73]]}, {"timestamp": 1631555459828, "ltp": 1.5, "tv": 28572.16, "trd": [[1.49, 194.23], [1.5, 238.42]], "batb": NaN, "batl": [[0, 1.5, 66.98]]}, {"timestamp": 1631555460516, "ltp": 1.48, "tv": 28674.4, "trd": [[1.48, 624.21]], "batb": [[0, 1.48, 10.08]], "batl": [[0, 1.51, 239.73], [1, 1.52, 16.52], [2, 1.53, 9.94]]}, {"timestamp": 1631555461512, "ltp": 1.48, "tv": 28674.4, "trd": NaN, "batb": NaN, "batl": [[0, 1.51, 118.73]]}, {"timestamp": 1631555463712, "ltp": 1.48, "tv": 28674.4, "trd": NaN, "batb": [[0, 1.48, 50.51]], "batl": [[0, 1.51, 187.01], [1, 1.52, 112.3]]}, {"timestamp": 1631555465133, "ltp": 1.48, "tv": 28674.4, "trd": NaN, "batb": NaN, "batl": [[0, 1.5, 186], [1, 1.51, 187.01], [2, 1.52, 112.3]]}, {"timestamp": 1631555466137, "ltp": 1.48, "tv": 28775.42, "trd": [[1.48, 725.23]], "batb": [[0, 1.47, 182.59], [1, 1.46, 161.82], [2, 1.45, 20.68]], "batl": [[0, 1.48, 1.91], [1, 1.5, 271.34], [2, 1.51, 187.01]]}, {"timestamp": 1631555466713, "ltp": 1.48, "tv": 28775.42, "trd": NaN, "batb": NaN, "batl": [[0, 1.48, 1.86]]}, {"timestamp": 1631555469040, "ltp": 1.48, "tv": 28779.14, "trd": [[1.48, 728.95]], "batb": [[0, 1.48, 43.23], [1, 1.47, 138.39], [2, 1.46, 161.82]], "batl": [[0, 1.49, 33.19], [1, 1.5, 304.38]]}, {"timestamp": 1631555470033, "ltp": 1.48, "tv": 28829.14, "trd": [[1.48, 778.95]], "batb": [[0, 1.48, 18.23]], "batl": NaN}, {"timestamp": 1631555470961, "ltp": 1.49, "tv": 28837.48, "trd": [[1.49, 202.57]], "batb": NaN, "batl": [[0, 1.49, 29.02]]}, {"timestamp": 1631555473162, "ltp": 1.49, "tv": 28837.48, "trd": NaN, "batb": [[1, 1.47, 150.09]], "batl": [[1, 1.5, 233.28]]}, {"timestamp": 1631555473635, "ltp": 1.49, "tv": 28838.38, "trd": [[1.49, 203.47]], "batb": NaN, "batl": [[0, 1.49, 28.57]]}, {"timestamp": 1631555474666, "ltp": 1.49, "tv": 28840.3, "trd": [[1.49, 205.39]], "batb": NaN, "batl": [[0, 1.49, 27.61]]}, {"timestamp": 1631555476159, "ltp": 1.49, "tv": 28895.14, "trd": [[1.48, 822.18], [1.49, 217]], "batb": [[0, 1.47, 150.09], [1, 1.46, 161.82], [2, 1.45, 20.68]], "batl": [[0, 1.49, 16]]}, {"timestamp": 1631555477160, "ltp": 1.47, "tv": 29024.6, "trd": [[1.47, 426.6], [1.48, 863.4]], "batb": [[0, 1.46, 48.07], [1, 1.43, 256.02], [2, 1.34, 95.67]], "batl": [[1, 1.5, 219.04], [2, 1.56, 256.02]]}, {"timestamp": 1631555477550, "ltp": 1.47, "tv": 29024.6, "trd": NaN, "batb": [[0, 1.43, 256.02], [1, 1.34, 95.67], [2, 1.32, 12.7]], "batl": [[0, 1.56, 256.02], [1, 1.61, 59.5], [2, 1.63, 64.5]]}, {"timestamp": 1631555479946, "ltp": 1.48, "tv": 29039.02, "trd": [[1.48, 877.83]], "batb": [[1, 1.4, 197.47], [2, 1.39, 143.3]], "batl": [[2, 1.63, 181.26]]}, {"timestamp": 1631555481579, "ltp": 1.48, "tv": 29059.02, "trd": [[1.48, 897.83]], "batb": [[0, 1.48, 41], [1, 1.43, 256.02], [2, 1.4, 197.47]], "batl": NaN}, {"timestamp": 1631555482583, "ltp": 1.48, "tv": 29119.02, "trd": [[1.48, 957.83]], "batb": [[0, 1.48, 11]], "batl": NaN}, {"timestamp": 1631555489957, "ltp": 1.48, "tv": 29170.02, "trd": [[1.48, 1008.83]], "batb": [[0, 1.43, 256.02], [1, 1.4, 197.47], [2, 1.39, 143.3]], "batl": NaN}, {"timestamp": 1631555492055, "ltp": 1.48, "tv": 29170.02, "trd": NaN, "batb": [[0, 1.4, 197.47], [1, 1.39, 143.3], [2, 1.34, 95.67]], "batl": [[2, 1.63, 64.5]]}, {"timestamp": 1631555494989, "ltp": 1.48, "tv": 29176.42, "trd": [[1.48, 1015.23]], "batb": [[0, 1.42, 19.26], [1, 1.4, 524.35], [2, 1.39, 143.3]], "batl": [[0, 1.44, 153.69], [1, 1.45, 260.79], [2, 1.46, 31.03]]}, {"timestamp": 1631555495777, "ltp": 1.48, "tv": 29176.42, "trd": NaN, "batb": NaN, "batl": [[1, 1.45, 219.41], [2, 1.46, 10.34]]}, {"timestamp": 1631555497191, "ltp": 1.44, "tv": 29184.96, "trd": [[1.44, 484.29]], "batb": NaN, "batl": [[0, 1.44, 149.42]]}, {"timestamp": 1631555498901, "ltp": 1.44, "tv": 29184.96, "trd": NaN, "batb": [[0, 1.42, 46.13], [1, 1.41, 16.89], [2, 1.4, 524.35]], "batl": [[0, 1.44, 312.37]]}, {"timestamp": 1631555500099, "ltp": 1.44, "tv": 29184.96, "trd": NaN, "batb": [[1, 1.41, 272.91]], "batl": NaN}, {"timestamp": 1631555504975, "ltp": 1.44, "tv": 29185.86, "trd": [[1.44, 485.19]], "batb": NaN, "batl": [[0, 1.44, 311.92]]}, {"timestamp": 1631555508581, "ltp": 1.44, "tv": 29187.66, "trd": [[1.44, 486.99]], "batb": NaN, "batl": [[0, 1.44, 311.02]]}, {"timestamp": 1631555510196, "ltp": 1.44, "tv": 29187.66, "trd": NaN, "batb": [[0, 1.41, 272.91], [1, 1.39, 70.91], [2, 1.37, 62.77]], "batl": [[0, 1.44, 110], [1, 1.48, 256.02], [2, 1.5, 72.51]]}, {"timestamp": 1631555510811, "ltp": 1.44, "tv": 29187.66, "trd": NaN, "batb": [[0, 1.41, 256.02]], "batl": [[0, 1.48, 256.02], [1, 1.5, 72.51], [2, 1.53, 69.5]]}, {"timestamp": 1631555512011, "ltp": 1.44, "tv": 29187.66, "trd": NaN, "batb": NaN, "batl": [[0, 1.42, 172.44], [1, 1.48, 256.02], [2, 1.5, 72.51]]}, {"timestamp": 1631555519116, "ltp": 1.44, "tv": 29187.66, "trd": NaN, "batb": NaN, "batl": [[0, 1.48, 256.02], [1, 1.5, 72.51], [2, 1.53, 69.5]]}, {"timestamp": 1631555520013, "ltp": 1.44, "tv": 29187.66, "trd": NaN, "batb": [[0, 1.42, 141.85], [1, 1.41, 389.63], [2, 1.39, 70.91]], "batl": [[0, 1.46, 178.04], [1, 1.47, 109.68], [2, 1.48, 256.02]]}, {"timestamp": 1631555521206, "ltp": 1.44, "tv": 29187.66, "trd": NaN, "batb": [[0, 1.41, 256.02], [1, 1.39, 70.91], [2, 1.37, 62.77]], "batl": [[0, 1.48, 256.02], [1, 1.5, 72.51], [2, 1.53, 69.5]]}, {"timestamp": 1631555521991, "ltp": 1.42, "tv": 29532.55, "trd": [[1.42, 1343.48]], "batb": [[0, 1.42, 83.57], [1, 1.41, 256.02], [2, 1.39, 70.91]], "batl": NaN}, {"timestamp": 1631555524124, "ltp": 1.42, "tv": 29532.55, "trd": NaN, "batb": NaN, "batl": [[2, 1.53, 191.67]]}, {"timestamp": 1631555526725, "ltp": 1.42, "tv": 29532.55, "trd": NaN, "batb": [[0, 1.41, 256.02], [1, 1.39, 70.91], [2, 1.37, 62.77]], "batl": NaN}, {"timestamp": 1631555528330, "ltp": 1.42, "tv": 29532.55, "trd": NaN, "batb": NaN, "batl": [[0, 1.43, 171.24], [1, 1.48, 256.02], [2, 1.5, 72.51]]}, {"timestamp": 1631555534716, "ltp": 1.41, "tv": 29589.74, "trd": [[1.41, 1749.11]], "batb": [[0, 1.41, 227.42]], "batl": NaN}, {"timestamp": 1631555542031, "ltp": 1.41, "tv": 29589.74, "trd": NaN, "batb": [[0, 1.37, 62.77], [1, 1.36, 117], [2, 1.35, 164.26]], "batl": NaN}, {"timestamp": 1631555544116, "ltp": 1.41, "tv": 29589.74, "trd": NaN, "batb": NaN, "batl": [[0, 1.39, 159.27], [1, 1.4, 227.24], [2, 1.43, 178.23]]}, {"timestamp": 1631555544950, "ltp": 1.39, "tv": 29589.86, "trd": [[1.39, 1118.75]], "batb": [[1, 1.36, 227.28], [2, 1.35, 219.4]], "batl": [[0, 1.39, 159.21], [2, 1.43, 6.99]]}, {"timestamp": 1631555545531, "ltp": 1.39, "tv": 29589.86, "trd": NaN, "batb": [[1, 1.36, 139.06], [2, 1.35, 175.28]], "batl": NaN}, {"timestamp": 1631555547626, "ltp": 1.39, "tv": 29624.14, "trd": [[1.39, 1153.03]], "batb": NaN, "batl": [[0, 1.39, 142.07]]}, {"timestamp": 1631555549133, "ltp": 1.39, "tv": 29665.23, "trd": [[1.39, 1194.12]], "batb": [[0, 1.37, 106.53]], "batl": [[0, 1.39, 167.13]]}, {"timestamp": 1631555550129, "ltp": 1.38, "tv": 29678.54, "trd": [[1.38, 555.02]], "batb": NaN, "batl": [[0, 1.38, 193.36], [1, 1.39, 167.13], [2, 1.4, 227.24]]}, {"timestamp": 1631555551115, "ltp": 1.38, "tv": 29678.54, "trd": NaN, "batb": [[1, 1.36, 217.74], [2, 1.35, 240.75]], "batl": [[1, 1.39, 317.13]]}, {"timestamp": 1631555552361, "ltp": 1.38, "tv": 29678.54, "trd": NaN, "batb": [[1, 1.36, 241.03]], "batl": [[1, 1.39, 343.21]]}, {"timestamp": 1631555554149, "ltp": 1.38, "tv": 29678.54, "trd": NaN, "batb": NaN, "batl": [[0, 1.38, 257.38]]}, {"timestamp": 1631555555862, "ltp": 1.38, "tv": 29678.54, "trd": NaN, "batb": [[1, 1.36, 538.4]], "batl": NaN}, {"timestamp": 1631555559167, "ltp": 1.37, "tv": 29891.6, "trd": [[1.37, 1696.28]], "batb": [[0, 1.36, 538.4], [1, 1.35, 240.75], [2, 1.34, 88.74]], "batl": [[0, 1.37, 97.57], [1, 1.38, 257.38], [2, 1.39, 193.21]]}, {"timestamp": 1631555561062, "ltp": 1.37, "tv": 29891.6, "trd": NaN, "batb": NaN, "batl": [[0, 1.37, 197.57]]}, {"timestamp": 1631555562058, "ltp": 1.36, "tv": 30884.19, "trd": [[1.36, 1861.71], [1.37, 1873.08]], "batb": [[0, 1.36, 130.5]], "batl": [[0, 1.37, 109.17]]}, {"timestamp": 1631555563160, "ltp": 1.36, "tv": 30884.19, "trd": NaN, "batb": NaN, "batl": [[0, 1.37, 100]]}, {"timestamp": 1631555563271, "ltp": 1.37, "tv": 30909.58, "trd": [[1.37, 1898.47]], "batb": NaN, "batl": [[0, 1.37, 74.61]]}, {"timestamp": 1631555565573, "ltp": 1.37, "tv": 30909.58, "trd": NaN, "batb": [[1, 1.35, 308.5], [2, 1.34, 261.23]], "batl": [[0, 1.37, 154.87], [2, 1.39, 274.15]]}, {"timestamp": 1631555569161, "ltp": 1.37, "tv": 31140.21, "trd": [[1.37, 2129.11]], "batb": [[1, 1.34, 77.72], [2, 1.33, 75.53]], "batl": [[0, 1.37, 345.77], [1, 1.38, 193.36], [2, 1.43, 74.5]]}, {"timestamp": 1631555570061, "ltp": 1.37, "tv": 31150.45, "trd": [[1.37, 2139.35]], "batb": NaN, "batl": [[0, 1.37, 133.77]]}, {"timestamp": 1631555571878, "ltp": 1.36, "tv": 31208.27, "trd": [[1.36, 1919.52]], "batb": [[0, 1.36, 101.6]], "batl": NaN}, {"timestamp": 1631555574177, "ltp": 1.36, "tv": 31208.27, "trd": NaN, "batb": [[0, 1.33, 75.53], [1, 1.32, 261.47], [2, 1.31, 194.54]], "batl": NaN}, {"timestamp": 1631555576181, "ltp": 1.36, "tv": 31208.27, "trd": NaN, "batb": NaN, "batl": [[0, 1.36, 137.33], [1, 1.37, 188.91], [2, 1.38, 2715.82]]}, {"timestamp": 1631555577171, "ltp": 1.36, "tv": 31208.27, "trd": NaN, "batb": NaN, "batl": [[0, 1.35, 100.56], [1, 1.36, 179.04], [2, 1.37, 11.02]]}, {"timestamp": 1631555580003, "ltp": 1.36, "tv": 31208.27, "trd": NaN, "batb": NaN, "batl": [[1, 1.36, 206.09]]}, {"timestamp": 1631555581200, "ltp": 1.35, "tv": 31235.58, "trd": [[1.34, 927.43], [1.35, 3559.32]], "batb": [[0, 1.33, 98.82]], "batl": [[0, 1.35, 161.74]]}, {"timestamp": 1631555582196, "ltp": 1.34, "tv": 31406.8, "trd": [[1.34, 1098.65]], "batb": [[0, 1.33, 354.84], [1, 1.32, 197.04], [2, 1.29, 23.88]], "batl": NaN}, {"timestamp": 1631555583766, "ltp": 1.34, "tv": 31406.8, "trd": NaN, "batb": [[1, 1.32, 276.68]], "batl": NaN}, {"timestamp": 1631555585189, "ltp": 1.34, "tv": 31406.8, "trd": NaN, "batb": [[0, 1.33, 331.55], [1, 1.32, 92.34]], "batl": [[0, 1.35, 155], [1, 1.4, 138.94], [2, 1.43, 74.5]]}, {"timestamp": 1631555586804, "ltp": 1.34, "tv": 31406.8, "trd": NaN, "batb": NaN, "batl": [[0, 1.4, 138.94], [1, 1.72, 16], [2, 44, 7.7]]}, {"timestamp": 1631555588178, "ltp": 1.34, "tv": 31406.8, "trd": NaN, "batb": [[2, 1.31, 134.06]], "batl": [[0, 1.35, 256.02], [1, 1.39, 184.42], [2, 1.4, 274.86]]}, {"timestamp": 1631555588486, "ltp": 1.34, "tv": 31406.8, "trd": NaN, "batb": [[2, 1.29, 23.88]], "batl": [[1, 1.38, 134.25], [2, 1.4, 138.94]]}, {"timestamp": 1631555591205, "ltp": 1.34, "tv": 31406.8, "trd": NaN, "batb": NaN, "batl": [[0, 1.35, 20.7]]}, {"timestamp": 1631555591594, "ltp": 1.34, "tv": 31406.8, "trd": NaN, "batb": [[0, 1.33, 519.31], [1, 1.32, 278.08]], "batl": [[0, 1.36, 139.67], [1, 1.37, 150.9]]}, {"timestamp": 1631555592894, "ltp": 1.34, "tv": 31406.8, "trd": NaN, "batb": [[0, 1.34, 256.02], [1, 1.33, 331.55], [2, 1.32, 92.34]], "batl": [[0, 1.4, 138.94], [1, 1.72, 16], [2, 44, 7.7]]}, {"timestamp": 1631555593890, "ltp": 1.34, "tv": 31406.8, "trd": NaN, "batb": [[0, 1.35, 172.44], [1, 1.34, 256.02], [2, 1.33, 331.55]], "batl": NaN}, {"timestamp": 1631555594989, "ltp": 1.34, "tv": 31406.8, "trd": NaN, "batb": NaN, "batl": [[0, 1.38, 137.25], [1, 1.4, 138.94], [2, 1.72, 16]]}, {"timestamp": 1631555596107, "ltp": 1.35, "tv": 31751.68, "trd": [[1.35, 3904.2]], "batb": [[0, 1.35, 20.36]], "batl": [[0, 1.39, 265.04], [1, 1.4, 274.86]]}, {"timestamp": 1631555596892, "ltp": 1.35, "tv": 31751.68, "trd": NaN, "batb": [[0, 1.34, 256.02], [1, 1.33, 331.55], [2, 1.32, 92.34]], "batl": [[0, 1.36, 256.02], [1, 1.39, 184.42], [2, 1.4, 274.86]]}, {"timestamp": 1631555598889, "ltp": 1.35, "tv": 31751.68, "trd": NaN, "batb": NaN, "batl": [[0, 1.39, 184.42], [1, 1.4, 274.86], [2, 1.72, 16]]}, {"timestamp": 1631555601189, "ltp": 1.35, "tv": 31751.68, "trd": NaN, "batb": [[0, 1.36, 91.41], [1, 1.35, 2381.13], [2, 1.34, 354.55]], "batl": [[0, 1.38, 12.6], [1, 1.39, 184.42], [2, 1.4, 274.86]]}, {"timestamp": 1631555602131, "ltp": 1.35, "tv": 31751.68, "trd": NaN, "batb": [[1, 1.35, 436.09], [2, 1.34, 98.53]], "batl": NaN}, {"timestamp": 1631555602397, "ltp": 1.36, "tv": 31760.8, "trd": [[1.36, 1928.64]], "batb": [[0, 1.36, 86.85]], "batl": NaN}, {"timestamp": 1631555604124, "ltp": 1.36, "tv": 31769.14, "trd": [[1.36, 1936.99]], "batb": [[0, 1.36, 82.68]], "batl": NaN}, {"timestamp": 1631555604604, "ltp": 1.36, "tv": 31769.14, "trd": NaN, "batb": [[0, 1.37, 18.72], [1, 1.36, 82.68], [2, 1.35, 436.09]], "batl": [[0, 1.38, 62.6]]}, {"timestamp": 1631555606119, "ltp": 1.38, "tv": 32115.15, "trd": [[1.36, 2231], [1.37, 2176.79], [1.38, 569.58]], "batb": [[0, 1.35, 436.09], [1, 1.34, 98.53], [2, 1.33, 173.31]], "batl": [[0, 1.38, 81.2], [1, 1.39, 141.9], [2, 1.4, 138.94]]}, {"timestamp": 1631555607010, "ltp": 1.38, "tv": 32115.15, "trd": NaN, "batb": [[0, 1.36, 256.02], [1, 1.35, 436.09], [2, 1.34, 98.53]], "batl": [[0, 1.38, 337.22]]}, {"timestamp": 1631555607631, "ltp": 1.38, "tv": 32115.27, "trd": [[1.38, 569.7]], "batb": NaN, "batl": [[0, 1.38, 337.16]]}, {"timestamp": 1631555608940, "ltp": 1.38, "tv": 32115.27, "trd": NaN, "batb": [[1, 1.35, 549.42], [2, 1.34, 343.77]], "batl": [[0, 1.38, 429.72]]}, {"timestamp": 1631555611525, "ltp": 1.38, "tv": 32115.27, "trd": NaN, "batb": NaN, "batl": [[0, 1.38, 549.72]]}, {"timestamp": 1631555612933, "ltp": 1.38, "tv": 32115.27, "trd": NaN, "batb": [[1, 1.35, 378.39]], "batl": NaN}, {"timestamp": 1631555613824, "ltp": 1.38, "tv": 32115.27, "trd": NaN, "batb": NaN, "batl": [[0, 1.38, 429.72]]}, {"timestamp": 1631555616115, "ltp": 1.38, "tv": 32115.27, "trd": NaN, "batb": [[0, 1.37, 256.02], [1, 1.36, 276.9], [2, 1.35, 378.39]], "batl": NaN}, {"timestamp": 1631555616840, "ltp": 1.37, "tv": 32627.3, "trd": [[1.37, 2688.82]], "batb": [[0, 1.36, 276.9], [1, 1.35, 378.39], [2, 1.34, 343.77]], "batl": [[0, 1.37, 246.7], [1, 1.38, 429.72], [2, 1.39, 141.9]]}, {"timestamp": 1631555619031, "ltp": 1.37, "tv": 32644.67, "trd": [[1.37, 2706.19]], "batb": NaN, "batl": [[0, 1.37, 229.33], [2, 1.39, 159.01]]}, {"timestamp": 1631555620029, "ltp": 1.37, "tv": 32644.67, "trd": NaN, "batb": NaN, "batl": [[0, 1.37, 330.71]]}, {"timestamp": 1631555620843, "ltp": 1.37, "tv": 32684.67, "trd": [[1.37, 2746.19]], "batb": NaN, "batl": [[0, 1.37, 310.71]]}, {"timestamp": 1631555622644, "ltp": 1.37, "tv": 32704.67, "trd": [[1.37, 2766.19]], "batb": NaN, "batl": [[0, 1.37, 555.38]]}, {"timestamp": 1631555623950, "ltp": 1.37, "tv": 32704.67, "trd": NaN, "batb": [[0, 1.36, 256.02], [1, 1.34, 72.72], [2, 1.33, 75.53]], "batl": [[0, 1.37, 454], [1, 1.38, 256.02], [2, 1.4, 138.94]]}, {"timestamp": 1631555624952, "ltp": 1.37, "tv": 32704.67, "trd": NaN, "batb": [[2, 1.33, 175.53]], "batl": [[0, 1.38, 256.02], [1, 1.4, 138.94], [2, 1.41, 122.5]]}, {"timestamp": 1631555626731, "ltp": 1.37, "tv": 32704.67, "trd": NaN, "batb": [[2, 1.33, 125.53]], "batl": NaN}, {"timestamp": 1631555628028, "ltp": 1.37, "tv": 32704.67, "trd": NaN, "batb": [[0, 1.33, 125.53], [1, 1.32, 92.34], [2, 1.28, 119.67]], "batl": NaN}, {"timestamp": 1631555628444, "ltp": 1.37, "tv": 32704.67, "trd": NaN, "batb": [[1, 1.32, 12.7]], "batl": NaN}, {"timestamp": 1631555631057, "ltp": 1.37, "tv": 32704.67, "trd": NaN, "batb": [[0, 1.36, 202.65], [1, 1.35, 166.09], [2, 1.33, 125.53]], "batl": [[0, 1.38, 275.27], [1, 1.39, 80.68], [2, 1.4, 276.32]]}, {"timestamp": 1631555632152, "ltp": 1.36, "tv": 32726.35, "trd": [[1.36, 2252.68]], "batb": [[0, 1.34, 66.72], [1, 1.33, 125.53], [2, 1.32, 12.7]], "batl": [[0, 1.38, 256.02], [1, 1.4, 138.94], [2, 1.41, 122.5]]}, {"timestamp": 1631555632629, "ltp": 1.36, "tv": 32726.35, "trd": NaN, "batb": [[0, 1.35, 256.02]], "batl": NaN}, {"timestamp": 1631555633560, "ltp": 1.36, "tv": 32726.35, "trd": NaN, "batb": [[0, 1.36, 20], [1, 1.35, 256.02], [2, 1.33, 125.53]], "batl": NaN}, {"timestamp": 1631555635132, "ltp": 1.36, "tv": 32726.35, "trd": NaN, "batb": NaN, "batl": [[0, 1.42, 133.75], [1, 1.72, 16], [2, 44, 7.7]]}, {"timestamp": 1631555636169, "ltp": 1.36, "tv": 32726.35, "trd": NaN, "batb": [[2, 1.34, 92.09]], "batl": [[1, 1.44, 146.44], [2, 1.45, 117.1]]}, {"timestamp": 1631555637168, "ltp": 1.36, "tv": 32726.35, "trd": NaN, "batb": [[0, 1.38, 10], [1, 1.36, 20], [2, 1.35, 256.02]], "batl": NaN}, {"timestamp": 1631555638155, "ltp": 1.36, "tv": 32726.35, "trd": NaN, "batb": [[0, 1.4, 784.88], [1, 1.39, 241.95], [2, 1.38, 104.96]], "batl": NaN}, {"timestamp": 1631555642140, "ltp": 1.4, "tv": 34007.99, "trd": [[1.4, 2644.85], [1.41, 1750.53]], "batb": [[0, 1.4, 183.85]], "batl": [[0, 1.42, 240.87]]}, {"timestamp": 1631555642448, "ltp": 1.42, "tv": 34027.99, "trd": [[1.42, 1363.48]], "batb": [[1, 1.39, 497.97]], "batl": [[0, 1.42, 230.87]]}, {"timestamp": 1631555644170, "ltp": 1.42, "tv": 34027.99, "trd": NaN, "batb": NaN, "batl": [[1, 1.43, 256.02], [2, 1.44, 146.44]]}, {"timestamp": 1631555645165, "ltp": 1.42, "tv": 34027.99, "trd": NaN, "batb": [[0, 1.4, 212.44]], "batl": [[2, 1.44, 180.66]]}, {"timestamp": 1631555645581, "ltp": 1.42, "tv": 34027.99, "trd": NaN, "batb": [[0, 1.41, 10], [1, 1.4, 212.44], [2, 1.39, 497.97]], "batl": [[0, 1.42, 426.87]]}, {"timestamp": 1631555647150, "ltp": 1.41, "tv": 34032.99, "trd": [[1.41, 1755.53]], "batb": [[0, 1.41, 7.5]], "batl": NaN}, {"timestamp": 1631555648974, "ltp": 1.41, "tv": 34049.11, "trd": [[1.41, 1770.53], [1.42, 1364.59]], "batb": [[0, 1.4, 212.44], [1, 1.39, 497.97], [2, 1.38, 94.96]], "batl": [[0, 1.41, 103.1], [1, 1.42, 426.31], [2, 1.43, 256.02]]}, {"timestamp": 1631555649561, "ltp": 1.41, "tv": 34055.9, "trd": [[1.41, 1777.33]], "batb": NaN, "batl": [[0, 1.41, 99.7]]}, {"timestamp": 1631555656295, "ltp": 1.41, "tv": 34072.97, "trd": [[1.41, 1794.39]], "batb": NaN, "batl": [[0, 1.41, 91.17]]}, {"timestamp": 1631555659794, "ltp": 1.4, "tv": 34396.83, "trd": [[1.4, 2968.71]], "batb": [[0, 1.4, 50.51]], "batl": NaN}, {"timestamp": 1631555661209, "ltp": 1.4, "tv": 34396.83, "trd": NaN, "batb": [[1, 1.39, 400.13], [2, 1.35, 122.48]], "batl": NaN}, {"timestamp": 1631555661787, "ltp": 1.4, "tv": 34396.83, "trd": NaN, "batb": [[0, 1.39, 256.02], [1, 1.35, 30], [2, 1.34, 30]], "batl": [[0, 1.42, 196], [1, 1.43, 256.02], [2, 1.49, 118.5]]}, {"timestamp": 1631555662992, "ltp": 1.4, "tv": 34396.83, "trd": NaN, "batb": NaN, "batl": [[0, 1.43, 256.02], [1, 1.49, 118.5], [2, 1.5, 115.29]]}, {"timestamp": 1631555664573, "ltp": 1.4, "tv": 34396.83, "trd": NaN, "batb": [[1, 1.34, 30], [2, 1.33, 288.56]], "batl": NaN}, {"timestamp": 1631555667078, "ltp": 1.39, "tv": 34447.42, "trd": [[1.39, 1244.71]], "batb": [[0, 1.39, 230.72]], "batl": NaN}, {"timestamp": 1631555673927, "ltp": 1.39, "tv": 34447.42, "trd": NaN, "batb": NaN, "batl": [[0, 1.52, 114.26], [1, 1.55, 115.52], [2, 1.56, 87.74]]}, {"timestamp": 1631555674820, "ltp": 1.39, "tv": 34447.42, "trd": NaN, "batb": [[2, 1.33, 50]], "batl": [[1, 44, 7.7], [2, 1.56, 0]]}, {"timestamp": 1631555677118, "ltp": 1.39, "tv": 34447.42, "trd": NaN, "batb": NaN, "batl": [[0, 1.49, 115.5], [1, 1.52, 114.26], [2, 44, 7.7]]}, {"timestamp": 1631555678011, "ltp": 1.39, "tv": 34447.42, "trd": NaN, "batb": [[0, 1.42, 96.82], [1, 1.41, 134.91], [2, 1.39, 230.72]], "batl": [[0, 1.43, 19.57], [1, 1.45, 112.46], [2, 1.46, 114.81]]}, {"timestamp": 1631555678321, "ltp": 1.39, "tv": 34447.42, "trd": NaN, "batb": [[0, 1.39, 230.72], [1, 1.34, 30], [2, 1.33, 50]], "batl": [[0, 1.52, 114.26], [1, 44, 7.7], [2, 1.46, 0]]}, {"timestamp": 1631555680824, "ltp": 1.39, "tv": 34447.42, "trd": NaN, "batb": NaN, "batl": [[0, 1.41, 24.94], [1, 1.52, 114.26], [2, 44, 7.7]]}, {"timestamp": 1631555681922, "ltp": 1.39, "tv": 34447.42, "trd": NaN, "batb": NaN, "batl": [[2, 1.55, 115.52]]}, {"timestamp": 1631555682934, "ltp": 1.51, "tv": 34492.35, "trd": [[1.41, 1819.33], [1.51, 20.52]], "batb": [[0, 1.51, 110.94], [1, 1.5, 103.01], [2, 1.48, 20.28]], "batl": [[0, 1.52, 133.54], [1, 1.55, 115.52], [2, 1.56, 87.74]]}, {"timestamp": 1631555688209, "ltp": 1.52, "tv": 34677.14, "trd": [[1.51, 187.84], [1.52, 299.99]], "batb": [[0, 1.5, 129.39], [1, 1.48, 20.28], [2, 1.47, 10.14]], "batl": [[0, 1.52, 121.07], [1, 1.53, 90.71], [2, 1.55, 90.33]]}, {"timestamp": 1631555690042, "ltp": 1.52, "tv": 34787.43, "trd": [[1.51, 271.5], [1.52, 326.63]], "batb": NaN, "batl": [[0, 1.52, 107.75]]}, {"timestamp": 1631555691152, "ltp": 1.52, "tv": 34787.43, "trd": NaN, "batb": [[0, 1.51, 26.21], [1, 1.5, 194.61], [2, 1.49, 106.39]], "batl": [[0, 1.52, 365.06], [2, 1.54, 70.59]]}, {"timestamp": 1631555691629, "ltp": 1.52, "tv": 34805.1, "trd": [[1.52, 344.29]], "batb": [[0, 1.5, 194.61], [1, 1.49, 106.39], [2, 1.48, 20.28]], "batl": [[0, 1.52, 356.23]]}, {"timestamp": 1631555695136, "ltp": 1.52, "tv": 34805.1, "trd": NaN, "batb": [[2, 1.48, 276.3]], "batl": NaN}, {"timestamp": 1631555698628, "ltp": 1.52, "tv": 34805.1, "trd": NaN, "batb": NaN, "batl": [[2, 1.54, 83.73]]}, {"timestamp": 1631555706785, "ltp": 1.52, "tv": 34805.1, "trd": NaN, "batb": [[0, 1.48, 256.02], [1, 1.36, 89.79], [2, 1.34, 30]], "batl": [[0, 1.52, 166], [1, 1.54, 13.14], [2, 1.63, 256.02]]}, {"timestamp": 1631555707564, "ltp": 1.52, "tv": 34805.1, "trd": NaN, "batb": NaN, "batl": [[0, 1.54, 13.14], [1, 1.63, 256.02], [2, 1.74, 93.75]]}, {"timestamp": 1631555711542, "ltp": 1.52, "tv": 34805.1, "trd": NaN, "batb": NaN, "batl": [[0, 1.63, 256.02], [1, 1.74, 93.75], [2, 1.81, 79.5]]}, {"timestamp": 1631555712947, "ltp": 1.52, "tv": 34805.1, "trd": NaN, "batb": [[0, 1.54, 113.32], [1, 1.53, 95.15], [2, 1.48, 256.02]], "batl": [[0, 1.56, 18.92], [1, 1.58, 89.25], [2, 1.59, 81.83]]}, {"timestamp": 1631555714052, "ltp": 1.52, "tv": 34805.1, "trd": NaN, "batb": [[0, 1.48, 256.02], [1, 1.36, 89.79], [2, 1.34, 30]], "batl": [[0, 1.63, 256.02], [1, 1.74, 93.75], [2, 1.81, 79.5]]}, {"timestamp": 1631555715854, "ltp": 1.52, "tv": 34805.1, "trd": NaN, "batb": NaN, "batl": [[0, 1.59, 12.73], [1, 1.63, 256.02], [2, 1.74, 93.75]]}, {"timestamp": 1631555717069, "ltp": 1.52, "tv": 34805.1, "trd": NaN, "batb": [[1, 1.4, 161.64], [2, 1.39, 145.08]], "batl": NaN}, {"timestamp": 1631555718890, "ltp": 1.52, "tv": 34805.1, "trd": NaN, "batb": NaN, "batl": [[1, 1.6, 4], [2, 1.63, 256.02]]}, {"timestamp": 1631555723652, "ltp": 1.52, "tv": 34805.1, "trd": NaN, "batb": [[0, 1.4, 161.64], [1, 1.39, 145.08], [2, 1.37, 20]], "batl": NaN}, {"timestamp": 1631555726167, "ltp": 1.52, "tv": 34805.1, "trd": NaN, "batb": [[0, 1.4, 174.28], [2, 1.38, 197.1]], "batl": [[0, 1.42, 3.52], [1, 1.43, 200.49], [2, 1.44, 1502.22]]}, {"timestamp": 1631555727062, "ltp": 1.52, "tv": 34805.1, "trd": NaN, "batb": [[2, 1.38, 98.56]], "batl": [[0, 1.43, 201.19], [1, 1.44, 233.95], [2, 1.45, 93.78]]}, {"timestamp": 1631555728804, "ltp": 1.43, "tv": 34807.24, "trd": [[1.42, 1365.99], [1.43, 2359.69]], "batb": NaN, "batl": [[0, 1.43, 200.12]]}, {"timestamp": 1631555730158, "ltp": 1.43, "tv": 34807.24, "trd": NaN, "batb": NaN, "batl": [[0, 1.42, 85.88], [1, 1.43, 200.12], [2, 1.44, 233.95]]}, {"timestamp": 1631555731155, "ltp": 1.42, "tv": 34811.77, "trd": [[1.42, 1370.52]], "batb": [[0, 1.41, 16.89], [1, 1.4, 174.28], [2, 1.39, 145.08]], "batl": [[0, 1.42, 81.35]]}, {"timestamp": 1631555732092, "ltp": 1.42, "tv": 34811.77, "trd": NaN, "batb": [[0, 1.41, 50.67]], "batl": [[1, 1.43, 285.12]]}, {"timestamp": 1631555733982, "ltp": 1.42, "tv": 34811.77, "trd": NaN, "batb": NaN, "batl": [[1, 1.43, 368.04]]}, {"timestamp": 1631555736665, "ltp": 1.41, "tv": 34831.77, "trd": [[1.41, 1839.33]], "batb": [[0, 1.41, 40.67]], "batl": NaN}, {"timestamp": 1631555737972, "ltp": 1.41, "tv": 34831