{"info": {"id": "1.187594316", "eventId": "30897697", "eventName": "Match Odds", "marketType": "MATCH_ODDS", "openDate": 1631530885730, "name": "S Ma v S Sekulic", "numberOfActiveRunner": 2, "countryCode": "", "sport": "TENNIS", "venue": "", "volume": {"total": 1303.25, "preMatch": 85.38, "inPlay": 1217.87}, "winner": {"id": 9626933, "name": "S Sekulic", "status": "WINNER", "position": 2}, "delay": 5}, "runners": [{"id": 11486880, "name": "S Ma", "status": "LOSER", "position": 1, "inPlayOdds": 1.66, "inPlayTime": 1631531584315, "avgPrematch": 0, "closedOdds": 50.0, "maxPrematch": -100, "minPrematch": 1001, "maxInPlay": 50.0, "minInPlay": 1.66, "inPlayIndex": 0, "lengthOdds": 110, "lengthOddsPrematch": 0, "lengthOddsInPlay": 110, "tradedVolume": 234.93, "preMatchVolume": 51.31, "inPlayVolume": 183.62}, {"id": 9626933, "name": "S Sekulic", "status": "WINNER", "position": 2, "inPlayOdds": 2.5, "inPlayTime": 1631531584315, "avgPrematch": 0, "closedOdds": 1.01, "maxPrematch": -100, "minPrematch": 1001, "maxInPlay": 2.5, "minInPlay": 1.01, "inPlayIndex": 0, "lengthOdds": 26, "lengthOddsPrematch": 0, "lengthOddsInPlay": 26, "tradedVolume": 1068.32, "preMatchVolume": 34.07, "inPlayVolume": 1034.25}], "marketUpdates": [{"timestamp": 1631518387236000000, "openDate": "2021-09-13T09:00:00.000Z", "status": "OPEN", "betDelay": 0, "inPlay": false, "complete": true}, {"timestamp": 1631522764139000000, "openDate": "2021-09-13T11:00:00.000Z", "status": "OPEN", "betDelay": 0, "inPlay": false, "complete": true}, {"timestamp": 1631526089043000000, "openDate": "2021-09-13T11:10:00.000Z", "status": "OPEN", "betDelay": 0, "inPlay": false, "complete": true}, {"timestamp": 1631529806862000000, "openDate": "2021-09-13T11:00:00.000Z", "status": "OPEN", "betDelay": 0, "inPlay": false, "complete": true}, {"timestamp": 1631530885730000000, "openDate": "2021-09-13T11:00:00.000Z", "status": "OPEN", "betDelay": 5, "inPlay": true, "complete": true}, {"timestamp": 1631531423785000000, "openDate": "2021-09-13T11:10:19.000Z", "status": "OPEN", "betDelay": 5, "inPlay": true, "complete": true}, {"timestamp": 1631534523530000000, "openDate": "2021-09-13T11:10:19.000Z", "status": "SUSPENDED", "betDelay": 5, "inPlay": true, "complete": true}, {"timestamp": 1631534697429000000, "openDate": "2021-09-13T11:10:19.000Z", "status": "CLOSED", "betDelay": 5, "inPlay": true, "complete": true}], "odds": [{"runnerId": 11486880, "odds": [{"timestamp": 1631531584315, "ltp": 1.66, "tv": 51.31, "trd": [[1.66, 51.31]], "batb": NaN, "batl": [[0, 1.66, 48.69]]}, {"timestamp": 1631531586029, "ltp": 1.66, "tv": 61.63, "trd": [[1.66, 61.63]], "batb": NaN, "batl": [[0, 1.66, 43.53]]}, {"timestamp": 1631531591335, "ltp": 1.66, "tv": 100.6, "trd": [[1.66, 100.6]], "batb": NaN, "batl": [[0, 1.66, 24.05]]}, {"timestamp": 1631531596544, "ltp": 1.66, "tv": 100.6, "trd": NaN, "batb": [[0, 1.01, 7], [1, 1.01, 0]], "batl": NaN}, {"timestamp": 1631531602460, "ltp": 1.66, "tv": 100.6, "trd": NaN, "batb": [[0, 1.55, 426.3], [1, 1.01, 7]], "batl": NaN}, {"timestamp": 1631531604338, "ltp": 1.66, "tv": 148.7, "trd": [[1.66, 148.7]], "batb": [[0, 1.66, 47.89], [1, 1.55, 426.3], [2, 1.01, 7]], "batl": [[0, 2.3, 314.02], [1, 2.3, 0]]}, {"timestamp": 1631531605542, "ltp": 1.66, "tv": 148.7, "trd": NaN, "batb": [[0, 1.66, 381.24]], "batl": NaN}, {"timestamp": 1631531606567, "ltp": 1.66, "tv": 148.7, "trd": NaN, "batb": [[0, 1.66, 372.8]], "batl": NaN}, {"timestamp": 1631531607459, "ltp": 1.66, "tv": 148.7, "trd": NaN, "batb": [[0, 1.66, 95.89]], "batl": NaN}, {"timestamp": 1631531608441, "ltp": 1.66, "tv": 148.7, "trd": NaN, "batb": [[0, 1.66, 103.62]], "batl": NaN}, {"timestamp": 1631531609371, "ltp": 1.66, "tv": 148.7, "trd": NaN, "batb": [[0, 1.66, 145.86]], "batl": NaN}, {"timestamp": 1631531610463, "ltp": 1.66, "tv": 148.7, "trd": NaN, "batb": [[0, 1.66, 62.27]], "batl": NaN}, {"timestamp": 1631531611349, "ltp": 1.66, "tv": 148.7, "trd": NaN, "batb": [[0, 1.66, 23.94]], "batl": NaN}, {"timestamp": 1631531612168, "ltp": 1.66, "tv": 148.7, "trd": NaN, "batb": [[0, 1.66, 10.34]], "batl": NaN}, {"timestamp": 1631531614149, "ltp": 1.66, "tv": 148.7, "trd": NaN, "batb": [[0, 1.55, 426.3], [1, 1.01, 7], [2, 1.01, 0]], "batl": NaN}, {"timestamp": 1631531660338, "ltp": 1.66, "tv": 148.7, "trd": NaN, "batb": [[0, 1.01, 7], [1, 1.01, 0]], "batl": NaN}, {"timestamp": 1631531666235, "ltp": 1.66, "tv": 148.7, "trd": NaN, "batb": [[0, 1.62, 421.17], [1, 1.01, 7]], "batl": [[0, 2.6, 261.12]]}, {"timestamp": 1631531694776, "ltp": 1.66, "tv": 148.7, "trd": NaN, "batb": [[0, 1.01, 7], [1, 1.01, 0]], "batl": NaN}, {"timestamp": 1631531700481, "ltp": 1.66, "tv": 148.7, "trd": NaN, "batb": [[0, 1.67, 415.42], [1, 1.01, 7]], "batl": NaN}, {"timestamp": 1631531743550, "ltp": 1.66, "tv": 148.7, "trd": NaN, "batb": [[0, 1.01, 7], [1, 1.01, 0]], "batl": NaN}, {"timestamp": 1631531749162, "ltp": 1.66, "tv": 148.7, "trd": NaN, "batb": [[0, 1.74, 409.86], [1, 1.01, 7]], "batl": [[0, 2.92, 224.31]]}, {"timestamp": 1631531874497, "ltp": 1.66, "tv": 148.7, "trd": NaN, "batb": [[0, 1.01, 7], [1, 1.01, 0]], "batl": NaN}, {"timestamp": 1631531880605, "ltp": 1.66, "tv": 148.7, "trd": NaN, "batb": [[0, 1.82, 406.77], [1, 1.01, 7]], "batl": NaN}, {"timestamp": 1631531927955, "ltp": 1.66, "tv": 148.7, "trd": NaN, "batb": NaN, "batl": [[0, 3.3, 194.57]]}, {"timestamp": 1631531940381, "ltp": 1.66, "tv": 148.7, "trd": NaN, "batb": NaN, "batl": [[0, 3, 216.4]]}, {"timestamp": 1631532048206, "ltp": 1.66, "tv": 148.7, "trd": NaN, "batb": [[0, 1.01, 7], [1, 1.01, 0]], "batl": NaN}, {"timestamp": 1631532054422, "ltp": 1.66, "tv": 148.7, "trd": NaN, "batb": [[0, 2.04, 399.53], [1, 1.01, 7]], "batl": [[0, 3.9, 160.43]]}, {"timestamp": 1631532163752, "ltp": 1.66, "tv": 148.7, "trd": NaN, "batb": NaN, "batl": [[0, 3.45, 182.89]]}, {"timestamp": 1631532209122, "ltp": 1.66, "tv": 148.7, "trd": NaN, "batb": [[0, 1.01, 7], [1, 1.01, 0]], "batl": NaN}, {"timestamp": 1631532214498, "ltp": 1.66, "tv": 148.7, "trd": NaN, "batb": [[0, 1.82, 406.77], [1, 1.01, 7]], "batl": [[0, 3.15, 203.19]]}, {"timestamp": 1631532246032, "ltp": 1.66, "tv": 148.7, "trd": NaN, "batb": NaN, "batl": [[0, 3, 216.4]]}, {"timestamp": 1631532266643, "ltp": 1.66, "tv": 148.7, "trd": NaN, "batb": [[0, 1.85, 29.05], [1, 1.82, 406.77], [2, 1.01, 7]], "batl": NaN}, {"timestamp": 1631532367641, "ltp": 1.66, "tv": 148.7, "trd": NaN, "batb": [[0, 1.87, 32.25], [1, 1.85, 29.05], [2, 1.82, 406.77]], "batl": NaN}, {"timestamp": 1631532452241, "ltp": 1.66, "tv": 148.7, "trd": NaN, "batb": NaN, "batl": [[0, 2.82, 234.47]]}, {"timestamp": 1631532482816, "ltp": 1.66, "tv": 148.7, "trd": NaN, "batb": [[0, 1.85, 29.05], [1, 1.82, 406.77], [2, 1.01, 7]], "batl": NaN}, {"timestamp": 1631532484008, "ltp": 1.66, "tv": 148.7, "trd": NaN, "batb": [[1, 1.01, 7], [2, 1.01, 0]], "batl": NaN}, {"timestamp": 1631532489822, "ltp": 1.66, "tv": 148.7, "trd": NaN, "batb": [[1, 1.62, 421.17], [2, 1.01, 7]], "batl": [[0, 2.6, 261.12]]}, {"timestamp": 1631532490706, "ltp": 1.66, "tv": 148.7, "trd": NaN, "batb": [[0, 1.62, 421.17], [1, 1.01, 7], [2, 1.01, 0]], "batl": NaN}, {"timestamp": 1631532495792, "ltp": 1.66, "tv": 148.7, "trd": NaN, "batb": [[0, 1.76, 29.05], [1, 1.62, 421.17], [2, 1.01, 7]], "batl": NaN}, {"timestamp": 1631532529678, "ltp": 1.66, "tv": 148.7, "trd": NaN, "batb": [[0, 1.62, 421.17], [1, 1.01, 7], [2, 1.01, 0]], "batl": NaN}, {"timestamp": 1631532534792, "ltp": 1.66, "tv": 148.7, "trd": NaN, "batb": [[0, 1.63, 29.05], [1, 1.62, 421.17], [2, 1.01, 7]], "batl": NaN}, {"timestamp": 1631532571310, "ltp": 1.66, "tv": 148.7, "trd": NaN, "batb": [[1, 1.01, 7], [2, 1.01, 0]], "batl": NaN}, {"timestamp": 1631532576832, "ltp": 1.66, "tv": 148.7, "trd": NaN, "batb": [[0, 1.7, 414.97], [1, 1.63, 29.05], [2, 1.01, 7]], "batl": NaN}, {"timestamp": 1631532577829, "ltp": 1.66, "tv": 148.7, "trd": NaN, "batb": [[1, 1.01, 7], [2, 1.01, 0]], "batl": NaN}, {"timestamp": 1631532601808, "ltp": 1.66, "tv": 148.7, "trd": NaN, "batb": [[0, 1.01, 7], [1, 1.01, 0]], "batl": NaN}, {"timestamp": 1631532608340, "ltp": 1.66, "tv": 148.7, "trd": NaN, "batb": [[0, 1.77, 407.82], [1, 1.01, 7]], "batl": [[0, 3, 216.4]]}, {"timestamp": 1631532628266, "ltp": 1.66, "tv": 148.7, "trd": NaN, "batb": [[0, 1.01, 7], [1, 1.01, 0]], "batl": NaN}, {"timestamp": 1631532630670, "ltp": 1.66, "tv": 148.7, "trd": NaN, "batb": [[0, 1.81, 29.05], [1, 1.01, 7]], "batl": NaN}, {"timestamp": 1631532634589, "ltp": 1.66, "tv": 148.7, "trd": NaN, "batb": [[0, 1.86, 404.12], [1, 1.81, 29.05], [2, 1.01, 7]], "batl": NaN}, {"timestamp": 1631532640686, "ltp": 1.66, "tv": 148.7, "trd": NaN, "batb": [[1, 1.01, 7], [2, 1.01, 0]], "batl": NaN}, {"timestamp": 1631532645882, "ltp": 1.66, "tv": 148.7, "trd": NaN, "batb": [[0, 1.87, 29.05], [1, 1.86, 404.12], [2, 1.01, 7]], "batl": NaN}, {"timestamp": 1631532760940, "ltp": 1.66, "tv": 148.7, "trd": NaN, "batb": [[1, 1.01, 7], [2, 1.01, 0]], "batl": NaN}, {"timestamp": 1631532767562, "ltp": 1.66, "tv": 148.7, "trd": NaN, "batb": [[1, 1.86, 404.12], [2, 1.01, 7]], "batl": [[0, 3.3, 194.57]]}, {"timestamp": 1631532857909, "ltp": 1.66, "tv": 148.7, "trd": NaN, "batb": [[1, 1.01, 7], [2, 1.01, 0]], "batl": NaN}, {"timestamp": 1631532864232, "ltp": 1.66, "tv": 148.7, "trd": NaN, "batb": [[0, 2.04, 399.53], [1, 1.87, 29.05], [2, 1.01, 7]], "batl": [[0, 3.9, 160.43]]}, {"timestamp": 1631532893761, "ltp": 1.66, "tv": 148.7, "trd": NaN, "batb": [[0, 1.87, 29.05], [1, 1.01, 7], [2, 1.01, 0]], "batl": NaN}, {"timestamp": 1631532900195, "ltp": 1.66, "tv": 148.7, "trd": NaN, "batb": [[0, 2.22, 389.82], [1, 1.87, 29.05], [2, 1.01, 7]], "batl": [[0, 4.6, 137.93]]}, {"timestamp": 1631532901884, "ltp": 1.66, "tv": 148.7, "trd": NaN, "batb": [[0, 1.87, 29.05], [1, 1.01, 7], [2, 1.01, 0]], "batl": NaN}, {"timestamp": 1631533096678, "ltp": 1.66, "tv": 148.7, "trd": NaN, "batb": [[0, 1.01, 7], [1, 1.01, 0]], "batl": NaN}, {"timestamp": 1631533388220, "ltp": 1.66, "tv": 148.7, "trd": NaN, "batb": [[0, 2.12, 394.01], [1, 1.01, 7]], "batl": [[0, 4.2, 150.07]]}, {"timestamp": 1631533409958, "ltp": 1.66, "tv": 148.7, "trd": NaN, "batb": NaN, "batl": [[0, 3.9, 160.43]]}, {"timestamp": 1631533516691, "ltp": 1.66, "tv": 148.7, "trd": NaN, "batb": NaN, "batl": [[0, 3.65, 172.76]]}, {"timestamp": 1631533576955, "ltp": 1.66, "tv": 148.7, "trd": NaN, "batb": NaN, "batl": [[0, 4.2, 150.07]]}, {"timestamp": 1631533600344, "ltp": 1.66, "tv": 148.7, "trd": NaN, "batb": [[0, 1.01, 7], [1, 1.01, 0]], "batl": NaN}, {"timestamp": 1631533606523, "ltp": 1.66, "tv": 148.7, "trd": NaN, "batb": [[0, 2.3, 390.4], [1, 1.01, 7]], "batl": [[0, 4.9, 128.02]]}, {"timestamp": 1631533634000, "ltp": 1.66, "tv": 148.7, "trd": NaN, "batb": NaN, "batl": [[0, 4.6, 137.93]]}, {"timestamp": 1631533651096, "ltp": 1.66, "tv": 148.7, "trd": NaN, "batb": NaN, "batl": [[0, 4.2, 150.07]]}, {"timestamp": 1631533666039, "ltp": 1.66, "tv": 148.7, "trd": NaN, "batb": [[0, 1.01, 7], [1, 1.01, 0]], "batl": NaN}, {"timestamp": 1631533671955, "ltp": 1.66, "tv": 148.7, "trd": NaN, "batb": [[0, 1.97, 400.31], [1, 1.01, 7]], "batl": [[0, 3.65, 172.76]]}, {"timestamp": 1631533693067, "ltp": 1.66, "tv": 148.7, "trd": NaN, "batb": NaN, "batl": [[0, 3.3, 194.57]]}, {"timestamp": 1631533721328, "ltp": 1.66, "tv": 148.7, "trd": NaN, "batb": [[0, 1.01, 7], [1, 1.01, 0]], "batl": NaN}, {"timestamp": 1631533727430, "ltp": 1.66, "tv": 148.7, "trd": NaN, "batb": [[0, 1.77, 407.82], [1, 1.01, 7]], "batl": [[0, 3, 216.4]]}, {"timestamp": 1631533801589, "ltp": 1.66, "tv": 148.7, "trd": NaN, "batb": [[0, 1.01, 7], [1, 1.01, 0]], "batl": NaN}, {"timestamp": 1631533807378, "ltp": 1.66, "tv": 148.7, "trd": NaN, "batb": [[0, 1.92, 400.36], [1, 1.01, 7]], "batl": [[0, 3.45, 182.89]]}, {"timestamp": 1631533824111, "ltp": 1.66, "tv": 148.7, "trd": NaN, "batb": [[0, 1.01, 7], [1, 1.01, 0]], "batl": NaN}, {"timestamp": 1631533829726, "ltp": 1.66, "tv": 148.7, "trd": NaN, "batb": [[0, 2.04, 399.53], [1, 1.01, 7]], "batl": [[0, 3.9, 160.43]]}, {"timestamp": 1631533886955, "ltp": 1.66, "tv": 148.7, "trd": NaN, "batb": NaN, "batl": [[0, 3.45, 182.89]]}, {"timestamp": 1631533899994, "ltp": 1.66, "tv": 148.7, "trd": NaN, "batb": [[0, 1.01, 7], [1, 1.01, 0]], "batl": NaN}, {"timestamp": 1631533906174, "ltp": 1.66, "tv": 148.7, "trd": NaN, "batb": [[0, 1.77, 407.82], [1, 1.01, 7]], "batl": [[0, 3, 216.4]]}, {"timestamp": 1631533925813, "ltp": 1.66, "tv": 148.7, "trd": NaN, "batb": [[0, 1.01, 7], [1, 1.01, 0]], "batl": NaN}, {"timestamp": 1631533932038, "ltp": 1.66, "tv": 148.7, "trd": NaN, "batb": [[0, 1.58, 422.21], [1, 1.01, 7]], "batl": [[0, 2.5, 278.33]]}, {"timestamp": 1631533953590, "ltp": 1.66, "tv": 148.7, "trd": NaN, "batb": [[0, 1.01, 7], [1, 1.01, 0]], "batl": NaN}, {"timestamp": 1631533959391, "ltp": 1.66, "tv": 148.7, "trd": NaN, "batb": [[0, 1.74, 409.86], [1, 1.01, 7]], "batl": [[0, 2.92, 224.31]]}, {"timestamp": 1631533979223, "ltp": 1.66, "tv": 148.7, "trd": NaN, "batb": [[0, 1.01, 7], [1, 1.01, 0]], "batl": NaN}, {"timestamp": 1631533985007, "ltp": 1.66, "tv": 148.7, "trd": NaN, "batb": [[0, 1.97, 400.31], [1, 1.01, 7]], "batl": [[0, 3.65, 172.76]]}, {"timestamp": 1631534011062, "ltp": 1.66, "tv": 148.7, "trd": NaN, "batb": [[0, 1.01, 7], [1, 1.01, 0]], "batl": NaN}, {"timestamp": 1631534017462, "ltp": 1.66, "tv": 148.7, "trd": NaN, "batb": [[0, 1.74, 409.86], [1, 1.01, 7]], "batl": [[0, 2.92, 224.31]]}, {"timestamp": 1631534021067, "ltp": 1.66, "tv": 148.7, "trd": NaN, "batb": NaN, "batl": [[1, 4, 4.26]]}, {"timestamp": 1631534023274, "ltp": 1.66, "tv": 148.7, "trd": NaN, "batb": NaN, "batl": [[1, 4, 0]]}, {"timestamp": 1631534038699, "ltp": 1.66, "tv": 148.7, "trd": NaN, "batb": [[0, 1.01, 7], [1, 1.01, 0]], "batl": NaN}, {"timestamp": 1631534044724, "ltp": 1.66, "tv": 148.7, "trd": NaN, "batb": [[0, 1.97, 400.31], [1, 1.01, 7]], "batl": [[0, 3.65, 172.76]]}, {"timestamp": 1631534066332, "ltp": 1.66, "tv": 148.7, "trd": NaN, "batb": NaN, "batl": [[0, 3.45, 182.89]]}, {"timestamp": 1631534075623, "ltp": 1.66, "tv": 148.7, "trd": NaN, "batb": [[0, 1.01, 7], [1, 1.01, 0]], "batl": NaN}, {"timestamp": 1631534081558, "ltp": 1.66, "tv": 148.7, "trd": NaN, "batb": [[0, 2.22, 389.82], [1, 1.01, 7]], "batl": [[0, 4.6, 137.93]]}, {"timestamp": 1631534103693, "ltp": 1.66, "tv": 148.7, "trd": NaN, "batb": NaN, "batl": [[0, 4.2, 4.26], [1, 4.6, 137.93]]}, {"timestamp": 1631534199444, "ltp": 1.66, "tv": 148.7, "trd": NaN, "batb": [[0, 1.01, 7], [1, 1.01, 0]], "batl": [[1, 4.6, 0]]}, {"timestamp": 1631534205648, "ltp": 1.66, "tv": 148.7, "trd": NaN, "batb": [[0, 2.38, 387.57], [1, 1.01, 7]], "batl": [[1, 5.3, 120.43]]}, {"timestamp": 1631534222050, "ltp": 1.66, "tv": 148.7, "trd": NaN, "batb": [[0, 1.01, 7], [1, 1.01, 0]], "batl": [[1, 5.3, 0]]}, {"timestamp": 1631534228169, "ltp": 1.66, "tv": 148.7, "trd": NaN, "batb": [[0, 2.52, 386.72], [1, 1.01, 7]], "batl": [[0, 6, 107.64]]}, {"timestamp": 1631534313109, "ltp": 1.66, "tv": 148.7, "trd": NaN, "batb": [[0, 1.01, 7], [1, 1.01, 0]], "batl": NaN}, {"timestamp": 1631534318723, "ltp": 1.66, "tv": 148.7, "trd": NaN, "batb": [[0, 2.72, 383.47], [1, 1.01, 7]], "batl": [[0, 7.2, 93.45]]}, {"timestamp": 1631534375766, "ltp": 1.66, "tv": 148.7, "trd": NaN, "batb": NaN, "batl": [[0, 8.2, 86.64]]}, {"timestamp": 1631534389213, "ltp": 1.66, "tv": 148.7, "trd": NaN, "batb": [[0, 1.01, 7], [1, 1.01, 0]], "batl": NaN}, {"timestamp": 1631534395049, "ltp": 1.66, "tv": 148.7, "trd": NaN, "batb": [[0, 2.98, 379.45], [1, 1.01, 7]], "batl": [[0, 9.4, 79.11]]}, {"timestamp": 1631534409402, "ltp": 9.4, "tv": 227.81, "trd": [[9.4, 79.11]], "batb": NaN, "batl": NaN}, {"timestamp": 1631534420501, "ltp": 26.0, "tv": 229.86, "trd": [[26, 2.04]], "batb": NaN, "batl": NaN}, {"timestamp": 1631534421604, "ltp": 26.0, "tv": 231.65, "trd": [[26, 3.83]], "batb": NaN, "batl": NaN}, {"timestamp": 1631534428002, "ltp": 26.0, "tv": 231.65, "trd": NaN, "batb": [[0, 1.01, 7], [1, 1.01, 0]], "batl": NaN}, {"timestamp": 1631534439403, "ltp": 26.0, "tv": 231.65, "trd": NaN, "batb": NaN, "batl": [[0, 1000, 3.28]]}, {"timestamp": 1631534444949, "ltp": 50.0, "tv": 234.93, "trd": [[50, 3.28]], "batb": NaN, "batl": NaN}]}, {"runnerId": 9626933, "odds": [{"timestamp": 1631531584315, "ltp": 2.5, "tv": 34.07, "trd": [[2.5, 34.07]], "batb": NaN, "batl": NaN}, {"timestamp": 1631532476680, "ltp": 2.5, "tv": 34.07, "trd": NaN, "batb": [[0, 1.56, 29.05], [1, 1.01, 7]], "batl": NaN}, {"timestamp": 1631532513743, "ltp": 2.5, "tv": 34.07, "trd": NaN, "batb": [[0, 1.01, 7], [1, 1.01, 0]], "batl": NaN}, {"timestamp": 1631532518965, "ltp": 2.5, "tv": 34.07, "trd": NaN, "batb": [[0, 1.63, 29.05], [1, 1.01, 7]], "batl": NaN}, {"timestamp": 1631532573706, "ltp": 2.5, "tv": 34.07, "trd": NaN, "batb": [[0, 1.01, 7], [1, 1.01, 0]], "batl": NaN}, {"timestamp": 1631532922733, "ltp": 2.5, "tv": 34.07, "trd": NaN, "batb": NaN, "batl": [[0, 1.88, 29.05]]}, {"timestamp": 1631533157828, "ltp": 2.5, "tv": 34.07, "trd": NaN, "batb": NaN, "batl": [[0, 1.86, 44.16], [1, 1.88, 29.05]]}, {"timestamp": 1631533418776, "ltp": 2.5, "tv": 34.07, "trd": NaN, "batb": NaN, "batl": [[0, 1.88, 29.05], [1, 1.88, 0]]}, {"timestamp": 1631533590725, "ltp": 2.5, "tv": 34.07, "trd": NaN, "batb": NaN, "batl": [[0, 1.88, 29.05]]}, {"timestamp": 1631533634000, "ltp": 2.5, "tv": 34.07, "trd": NaN, "batb": NaN, "batl": [[0, 1.73, 29.05]]}, {"timestamp": 1631533653920, "ltp": 2.5, "tv": 34.07, "trd": NaN, "batb": NaN, "batl": [[0, 1.76, 29.05]]}, {"timestamp": 1631533715718, "ltp": 2.5, "tv": 34.07, "trd": NaN, "batb": [[0, 1.45, 23.24], [1, 1.01, 7]], "batl": NaN}, {"timestamp": 1631533730647, "ltp": 2.5, "tv": 34.07, "trd": NaN, "batb": [[0, 1.01, 7], [1, 1.01, 0]], "batl": NaN}, {"timestamp": 1631533890660, "ltp": 2.5, "tv": 34.07, "trd": NaN, "batb": NaN, "batl": [[0, 1.95, 29.05]]}, {"timestamp": 1631534409402, "ltp": 1.11, "tv": 704.04, "trd": [[1.11, 669.97]], "batb": NaN, "batl": [[0, 1.1, 2311.29]]}, {"timestamp": 1631534418296, "ltp": 1.11, "tv": 704.04, "trd": NaN, "batb": NaN, "batl": [[0, 1.04, 3407.16], [1, 1.1, 2311.29]]}, {"timestamp": 1631534420501, "ltp": 1.04, "tv": 755.15, "trd": [[1.04, 51.11]], "batb": NaN, "batl": [[0, 1.04, 3356.05]]}, {"timestamp": 1631534421604, "ltp": 1.04, "tv": 799.87, "trd": [[1.04, 95.83]], "batb": NaN, "batl": [[0, 1.04, 3311.33]]}, {"timestamp": 1631534423964, "ltp": 1.04, "tv": 893.56, "trd": [[1.04, 189.52]], "batb": NaN, "batl": [[0, 1.04, 3264.48]]}, {"timestamp": 1631534441721, "ltp": 1.04, "tv": 893.56, "trd": NaN, "batb": NaN, "batl": [[0, 1.02, 1703.58], [1, 1.04, 3264.48], [2, 1.1, 2311.29]]}, {"timestamp": 1631534444949, "ltp": 1.02, "tv": 1054.32, "trd": [[1.02, 160.76]], "batb": NaN, "batl": [[0, 1.02, 1542.82]]}, {"timestamp": 1631534470496, "ltp": 1.01, "tv": 1068.32, "trd": [[1.01, 14]], "batb": NaN, "batl": [[0, 1.01, 844.79], [1, 1.02, 1542.82], [2, 1.04, 3264.48]]}, {"timestamp": 1631534475619, "ltp": 1.01, "tv": 1068.32, "trd": NaN, "batb": NaN, "batl": [[0, 1.02, 1542.82], [1, 1.04, 3264.48], [2, 1.1, 2311.29]]}, {"timestamp": 1631534485981, "ltp": 1.01, "tv": 1068.32, "trd": NaN, "batb": NaN, "batl": [[2, 1.1, 0]]}, {"timestamp": 1631534491141, "ltp": 1.01, "tv": 1068.32, "trd": NaN, "batb": NaN, "batl": [[0, 1.01, 2311.29], [1, 1.02, 1542.82], [2, 1.04, 3264.48]]}, {"timestamp": 1631534530006, "ltp": 1.01, "tv": 1068.32, "trd": NaN, "batb": NaN, "batl": [[0, 1.02, 1542.82], [1, 1.04, 3264.48], [2, 1.04, 0]]}]}]}