{"info": {"id": "1.187552294", "eventId": "30895223", "eventName": "Match Odds", "marketType": "MATCH_ODDS", "openDate": 1631448081966, "name": "S Pinto v H Kuwata", "numberOfActiveRunner": 2, "countryCode": "", "sport": "TENNIS", "venue": "", "volume": {"total": 327.55, "preMatch": 10.0, "inPlay": 317.55}, "winner": {"id": 9628686, "name": "H Kuwata", "status": "WINNER", "position": 2}, "delay": 5}, "runners": [{"id": 25156643, "name": "S Pinto", "status": "LOSER", "position": 1, "inPlayOdds": 26.0, "inPlayTime": 1631448173037, "avgPrematch": 0, "closedOdds": 17.5, "maxPrematch": -100, "minPrematch": 1001, "maxInPlay": 26.0, "minInPlay": 17.5, "inPlayIndex": 0, "lengthOdds": 51, "lengthOddsPrematch": 0, "lengthOddsInPlay": 51, "tradedVolume": 12.91, "preMatchVolume": 4.22, "inPlayVolume": 8.69}, {"id": 9628686, "name": "H Kuwata", "status": "WINNER", "position": 2, "inPlayOdds": 1.04, "inPlayTime": 1631448081966, "avgPrematch": 1.04, "closedOdds": 1.01, "maxPrematch": 1.04, "minPrematch": 1.04, "maxInPlay": 1.06, "minInPlay": 1.01, "inPlayIndex": 3, "lengthOdds": 19, "lengthOddsPrematch": 3, "lengthOddsInPlay": 16, "tradedVolume": 314.64, "preMatchVolume": 5.78, "inPlayVolume": 308.86}], "marketUpdates": [{"timestamp": 1631438901992000000, "openDate": "2021-09-12T12:00:00.000Z", "status": "OPEN", "betDelay": 0, "inPlay": false, "complete": true}, {"timestamp": 1631448081966000000, "openDate": "2021-09-12T12:00:00.000Z", "status": "OPEN", "betDelay": 5, "inPlay": true, "complete": true}, {"timestamp": 1631449046750000000, "openDate": "2021-09-12T12:17:22.000Z", "status": "OPEN", "betDelay": 5, "inPlay": true, "complete": true}, {"timestamp": 1631453248814000000, "openDate": "2021-09-12T12:17:22.000Z", "status": "SUSPENDED", "betDelay": 5, "inPlay": true, "complete": true}, {"timestamp": 1631453260855000000, "openDate": "2021-09-12T12:17:22.000Z", "status": "CLOSED", "betDelay": 5, "inPlay": true, "complete": true}], "odds": [{"runnerId": 25156643, "odds": [{"timestamp": 1631448173037, "ltp": 26.0, "tv": 4.22, "trd": [[26, 4.22]], "batb": NaN, "batl": [[0, 26, 95.78]]}, {"timestamp": 1631448586072, "ltp": 26.0, "tv": 8.44, "trd": [[26, 8.44]], "batb": NaN, "batl": [[0, 26, 141.57]]}, {"timestamp": 1631449118626, "ltp": 17.5, "tv": 12.73, "trd": [[17.5, 4.3]], "batb": NaN, "batl": [[0, 17.5, 32.55]]}, {"timestamp": 1631449124223, "ltp": 17.5, "tv": 12.91, "trd": [[17.5, 4.47]], "batb": NaN, "batl": [[0, 17.5, 32.38]]}, {"timestamp": 1631449381867, "ltp": 17.5, "tv": 12.91, "trd": NaN, "batb": [[0, 3.7, 376.92], [1, 1.01, 12]], "batl": [[0, 23, 52.09]]}, {"timestamp": 1631449426399, "ltp": 17.5, "tv": 12.91, "trd": NaN, "batb": NaN, "batl": [[0, 21, 54.36]]}, {"timestamp": 1631449455762, "ltp": 17.5, "tv": 12.91, "trd": NaN, "batb": NaN, "batl": [[0, 18, 57.14]]}, {"timestamp": 1631449488274, "ltp": 17.5, "tv": 12.91, "trd": NaN, "batb": NaN, "batl": [[0, 23, 52.09]]}, {"timestamp": 1631449558577, "ltp": 17.5, "tv": 12.91, "trd": NaN, "batb": [[0, 1.01, 12], [1, 1.01, 0]], "batl": NaN}, {"timestamp": 1631449576909, "ltp": 17.5, "tv": 12.91, "trd": NaN, "batb": [[0, 3.9, 376.1], [1, 1.01, 12]], "batl": [[0, 34, 46.84]]}, {"timestamp": 1631449599583, "ltp": 17.5, "tv": 12.91, "trd": NaN, "batb": NaN, "batl": [[0, 60, 41.65]]}, {"timestamp": 1631449656423, "ltp": 17.5, "tv": 12.91, "trd": NaN, "batb": NaN, "batl": [[0, 46, 43.67]]}, {"timestamp": 1631449717125, "ltp": 17.5, "tv": 12.91, "trd": NaN, "batb": NaN, "batl": [[0, 34, 46.84]]}, {"timestamp": 1631449751882, "ltp": 17.5, "tv": 12.91, "trd": NaN, "batb": NaN, "batl": [[0, 46, 43.67]]}, {"timestamp": 1631449767899, "ltp": 17.5, "tv": 12.91, "trd": NaN, "batb": NaN, "batl": [[0, 60, 41.65]]}, {"timestamp": 1631449809585, "ltp": 17.5, "tv": 12.91, "trd": NaN, "batb": NaN, "batl": [[0, 34, 46.84]]}, {"timestamp": 1631449849135, "ltp": 17.5, "tv": 12.91, "trd": NaN, "batb": NaN, "batl": [[0, 46, 43.67]]}, {"timestamp": 1631449880072, "ltp": 17.5, "tv": 12.91, "trd": NaN, "batb": NaN, "batl": [[0, 34, 46.84]]}, {"timestamp": 1631449900116, "ltp": 17.5, "tv": 12.91, "trd": NaN, "batb": NaN, "batl": [[0, 46, 43.67]]}, {"timestamp": 1631449924561, "ltp": 17.5, "tv": 12.91, "trd": NaN, "batb": NaN, "batl": [[0, 34, 46.84]]}, {"timestamp": 1631449960099, "ltp": 17.5, "tv": 12.91, "trd": NaN, "batb": NaN, "batl": [[0, 26, 50.19]]}, {"timestamp": 1631450069180, "ltp": 17.5, "tv": 12.91, "trd": NaN, "batb": NaN, "batl": [[0, 21, 54.36]]}, {"timestamp": 1631450087397, "ltp": 17.5, "tv": 12.91, "trd": NaN, "batb": NaN, "batl": [[0, 26, 50.19]]}, {"timestamp": 1631450105702, "ltp": 17.5, "tv": 12.91, "trd": NaN, "batb": NaN, "batl": [[0, 23, 52.09]]}, {"timestamp": 1631450133270, "ltp": 17.5, "tv": 12.91, "trd": NaN, "batb": NaN, "batl": [[0, 34, 46.84]]}, {"timestamp": 1631450201186, "ltp": 17.5, "tv": 12.91, "trd": NaN, "batb": NaN, "batl": [[0, 46, 43.67]]}, {"timestamp": 1631450251158, "ltp": 17.5, "tv": 12.91, "trd": NaN, "batb": NaN, "batl": [[0, 60, 41.65]]}, {"timestamp": 1631450270159, "ltp": 17.5, "tv": 12.91, "trd": NaN, "batb": NaN, "batl": [[0, 34, 46.84]]}, {"timestamp": 1631450288409, "ltp": 17.5, "tv": 12.91, "trd": NaN, "batb": NaN, "batl": [[0, 46, 43.67]]}, {"timestamp": 1631450337377, "ltp": 17.5, "tv": 12.91, "trd": NaN, "batb": NaN, "batl": [[0, 34, 46.84]]}, {"timestamp": 1631450375945, "ltp": 17.5, "tv": 12.91, "trd": NaN, "batb": NaN, "batl": [[0, 46, 43.67]]}, {"timestamp": 1631450403498, "ltp": 17.5, "tv": 12.91, "trd": NaN, "batb": NaN, "batl": [[0, 34, 46.84]]}, {"timestamp": 1631450434867, "ltp": 17.5, "tv": 12.91, "trd": NaN, "batb": NaN, "batl": [[0, 46, 43.67]]}, {"timestamp": 1631450470402, "ltp": 17.5, "tv": 12.91, "trd": NaN, "batb": NaN, "batl": [[0, 34, 46.84]]}, {"timestamp": 1631450499016, "ltp": 17.5, "tv": 12.91, "trd": NaN, "batb": NaN, "batl": [[0, 26, 50.19]]}, {"timestamp": 1631450534227, "ltp": 17.5, "tv": 12.91, "trd": NaN, "batb": [[0, 1.01, 12], [1, 1.01, 0]], "batl": NaN}, {"timestamp": 1631450701636, "ltp": 17.5, "tv": 12.91, "trd": NaN, "batb": [[0, 3.7, 376.92], [1, 1.01, 12]], "batl": [[0, 23, 52.09]]}, {"timestamp": 1631450721968, "ltp": 17.5, "tv": 12.91, "trd": NaN, "batb": NaN, "batl": [[0, 21, 54.36]]}, {"timestamp": 1631450762627, "ltp": 17.5, "tv": 12.91, "trd": NaN, "batb": NaN, "batl": [[0, 34, 46.84]]}, {"timestamp": 1631450811326, "ltp": 17.5, "tv": 12.91, "trd": NaN, "batb": NaN, "batl": [[0, 26, 50.19]]}, {"timestamp": 1631450822448, "ltp": 17.5, "tv": 12.91, "trd": NaN, "batb": NaN, "batl": [[0, 46, 43.67]]}, {"timestamp": 1631450860003, "ltp": 17.5, "tv": 12.91, "trd": NaN, "batb": NaN, "batl": [[0, 34, 46.84]]}, {"timestamp": 1631450900751, "ltp": 17.5, "tv": 12.91, "trd": NaN, "batb": NaN, "batl": [[0, 46, 43.67]]}, {"timestamp": 1631450941282, "ltp": 17.5, "tv": 12.91, "trd": NaN, "batb": NaN, "batl": [[0, 60, 41.65]]}, {"timestamp": 1631450961499, "ltp": 17.5, "tv": 12.91, "trd": NaN, "batb": NaN, "batl": [[0, 46, 43.67]]}, {"timestamp": 1631450995564, "ltp": 17.5, "tv": 12.91, "trd": NaN, "batb": [[0, 1.01, 12], [1, 1.01, 0]], "batl": NaN}, {"timestamp": 1631451001289, "ltp": 17.5, "tv": 12.91, "trd": NaN, "batb": [[0, 4.2, 377.06], [1, 1.01, 12]], "batl": [[0, 85, 39.77]]}, {"timestamp": 1631451040557, "ltp": 17.5, "tv": 12.91, "trd": NaN, "batb": NaN, "batl": [[0, 340, 36.48]]}, {"timestamp": 1631452077914, "ltp": 17.5, "tv": 12.91, "trd": NaN, "batb": [[0, 1.01, 12], [1, 1.01, 0]], "batl": NaN}, {"timestamp": 1631452516441, "ltp": 17.5, "tv": 12.91, "trd": NaN, "batb": [[0, 4.8, 372.81], [1, 1.01, 12]], "batl": NaN}, {"timestamp": 1631452841046, "ltp": 17.5, "tv": 12.91, "trd": NaN, "batb": [[0, 1.01, 12], [1, 1.01, 0]], "batl": NaN}]}, {"runnerId": 9628686, "odds": [{"timestamp": 1631445819528, "ltp": 1.04, "tv": 5.78, "trd": [[1.04, 5.78]], "batb": [[0, 1.02, 608.45]], "batl": [[0, 1.04, 102.63]]}, {"timestamp": 1631446910192, "ltp": 1.04, "tv": 5.78, "trd": NaN, "batb": NaN, "batl": [[0, 1.04, 105.52]]}, {"timestamp": 1631447993887, "ltp": 1.04, "tv": 5.78, "trd": NaN, "batb": NaN, "batl": [[0, 1.04, 107.52]]}, {"timestamp": 1631448081966, "ltp": 1.04, "tv": 5.78, "trd": NaN, "batb": [[0, 1.01, 12], [1, 1.01, 0]], "batl": [[0, 1.04, 105.52], [2, 1.2, 0]]}, {"timestamp": 1631448087271, "ltp": 1.04, "tv": 5.78, "trd": NaN, "batb": NaN, "batl": [[2, 11.5, 8.68]]}, {"timestamp": 1631448173037, "ltp": 1.04, "tv": 111.3, "trd": [[1.04, 111.31]], "batb": NaN, "batl": [[0, 1.08, 82.38], [1, 11.5, 8.68], [2, 11.5, 0]]}, {"timestamp": 1631448515796, "ltp": 1.04, "tv": 111.3, "trd": NaN, "batb": NaN, "batl": [[0, 1.04, 105.52], [1, 1.08, 82.38], [2, 11.5, 8.68]]}, {"timestamp": 1631448586072, "ltp": 1.04, "tv": 216.83, "trd": [[1.04, 216.83]], "batb": NaN, "batl": [[0, 1.08, 82.38], [1, 11.5, 8.68], [2, 11.5, 0]]}, {"timestamp": 1631448638715, "ltp": 1.04, "tv": 216.83, "trd": NaN, "batb": NaN, "batl": [[0, 1.06, 70.98], [1, 1.08, 82.38], [2, 11.5, 8.68]]}, {"timestamp": 1631449118626, "ltp": 1.06, "tv": 287.81, "trd": [[1.06, 70.98]], "batb": NaN, "batl": [[0, 1.08, 82.38], [1, 11.5, 8.68], [2, 11.5, 0]]}, {"timestamp": 1631449118900, "ltp": 1.06, "tv": 287.81, "trd": NaN, "batb": NaN, "batl": [[1, 11.5, 0]]}, {"timestamp": 1631449124223, "ltp": 1.06, "tv": 290.64, "trd": [[1.06, 73.82]], "batb": NaN, "batl": [[1, 11.5, 8.68]]}, {"timestamp": 1631449494699, "ltp": 1.06, "tv": 290.64, "trd": NaN, "batb": NaN, "batl": [[0, 11.5, 8.68], [1, 11.5, 0]]}, {"timestamp": 1631449504497, "ltp": 1.06, "tv": 290.64, "trd": NaN, "batb": NaN, "batl": [[0, 1.11, 41.62], [1, 11.5, 8.68]]}, {"timestamp": 1631449746469, "ltp": 1.06, "tv": 290.64, "trd": NaN, "batb": NaN, "batl": [[0, 11.5, 8.68], [1, 11.5, 0]]}, {"timestamp": 1631449751560, "ltp": 1.06, "tv": 290.64, "trd": NaN, "batb": NaN, "batl": [[0, 1.08, 41.62], [1, 11.5, 8.68]]}, {"timestamp": 1631450652886, "ltp": 1.06, "tv": 290.64, "trd": NaN, "batb": NaN, "batl": [[0, 11.5, 8.68], [1, 11.5, 0]]}, {"timestamp": 1631450658024, "ltp": 1.06, "tv": 290.64, "trd": NaN, "batb": NaN, "batl": [[0, 1.09, 41.62], [1, 11.5, 8.68]]}, {"timestamp": 1631451509018, "ltp": 1.01, "tv": 314.64, "trd": [[1.01, 24]], "batb": NaN, "batl": [[0, 1.01, 5.08], [1, 1.09, 41.62], [2, 11.5, 8.68]]}]}]}