{"info": {"id": "1.187557995", "eventId": "30896141", "eventName": "Match Odds", "marketType": "MATCH_ODDS", "openDate": 1631532407849, "name": "Kuzmova v Stefanini", "numberOfActiveRunner": 2, "countryCode": "", "sport": "TENNIS", "venue": "", "volume": {"total": 392437.82, "preMatch": 3445.78, "inPlay": 388992.04}, "winner": {"id": 9342449, "name": "Viktoria Kuzmova", "status": "WINNER", "position": 1}, "delay": 3}, "runners": [{"id": 9342449, "name": "Viktoria Kuzmova", "status": "WINNER", "position": 1, "inPlayOdds": 1.93, "inPlayTime": 1631532407849, "avgPrematch": 1.97, "closedOdds": 1.01, "maxPrematch": 2.02, "minPrematch": 1.92, "maxInPlay": 3.65, "minInPlay": 1.01, "inPlayIndex": 118, "lengthOdds": 6183, "lengthOddsPrematch": 118, "lengthOddsInPlay": 6065, "tradedVolume": 344016.93, "preMatchVolume": 2253.18, "inPlayVolume": 341763.75}, {"id": 9633869, "name": "Lucrezia Stefanini", "status": "LOSER", "position": 2, "inPlayOdds": 2.08, "inPlayTime": 1631532407849, "avgPrematch": 2.02, "closedOdds": 990.0, "maxPrematch": 2.08, "minPrematch": 1.99, "maxInPlay": 990.0, "minInPlay": 1.37, "inPlayIndex": 93, "lengthOdds": 3977, "lengthOddsPrematch": 93, "lengthOddsInPlay": 3884, "tradedVolume": 48420.89, "preMatchVolume": 1192.6, "inPlayVolume": 47228.29}], "marketUpdates": [{"timestamp": 1631463867693000000, "openDate": "2021-09-13T10:30:00.000Z", "status": "OPEN", "betDelay": 0, "inPlay": false, "complete": true}, {"timestamp": 1631529560620000000, "openDate": "2021-09-13T10:50:00.000Z", "status": "OPEN", "betDelay": 0, "inPlay": false, "complete": true}, {"timestamp": 1631530459490000000, "openDate": "2021-09-13T11:00:00.000Z", "status": "OPEN", "betDelay": 0, "inPlay": false, "complete": true}, {"timestamp": 1631530762170000000, "openDate": "2021-09-13T11:20:00.000Z", "status": "OPEN", "betDelay": 0, "inPlay": false, "complete": true}, {"timestamp": 1631531959564000000, "openDate": "2021-09-13T11:25:00.000Z", "status": "OPEN", "betDelay": 0, "inPlay": false, "complete": true}, {"timestamp": 1631532407849000000, "openDate": "2021-09-13T11:25:00.000Z", "status": "OPEN", "betDelay": 3, "inPlay": true, "complete": true}, {"timestamp": 1631532561189000000, "openDate": "2021-09-13T11:30:00.000Z", "status": "OPEN", "betDelay": 3, "inPlay": true, "complete": true}, {"timestamp": 1631542701097000000, "openDate": "2021-09-13T11:30:00.000Z", "status": "SUSPENDED", "betDelay": 3, "inPlay": true, "complete": true}, {"timestamp": 1631542781305000000, "openDate": "2021-09-13T11:30:00.000Z", "status": "CLOSED", "betDelay": 3, "inPlay": true, "complete": true}], "odds": [{"runnerId": 9342449, "odds": [{"timestamp": 1631517188674, "ltp": 2.02, "tv": 91.91, "trd": [[2.02, 91.92]], "batb": [[0, 2, 37.55], [1, 1.9, 37.57], [2, 1.5, 88.09]], "batl": NaN}, {"timestamp": 1631517189187, "ltp": 2.02, "tv": 91.91, "trd": NaN, "batb": [[1, 1.94, 67.05], [2, 1.9, 37.57]], "batl": [[0, 2.02, 3], [1, 2.04, 8.1], [2, 2.1, 7.99]]}, {"timestamp": 1631517193659, "ltp": 2.02, "tv": 91.91, "trd": NaN, "batb": NaN, "batl": [[0, 2.04, 8.1], [1, 2.1, 7.99], [2, 2.4, 5.17]]}, {"timestamp": 1631517242620, "ltp": 2.02, "tv": 91.91, "trd": NaN, "batb": [[1, 1.94, 49.68]], "batl": NaN}, {"timestamp": 1631517243030, "ltp": 2.02, "tv": 91.91, "trd": NaN, "batb": [[1, 1.92, 65.49]], "batl": NaN}, {"timestamp": 1631517282988, "ltp": 2.02, "tv": 91.91, "trd": NaN, "batb": [[2, 1.83, 40.74]], "batl": NaN}, {"timestamp": 1631517835851, "ltp": 2.0, "tv": 111.91, "trd": [[2, 20]], "batb": [[0, 2, 27.55]], "batl": NaN}, {"timestamp": 1631519243645, "ltp": 2.0, "tv": 111.91, "trd": NaN, "batb": [[2, 1.84, 4]], "batl": NaN}, {"timestamp": 1631519530309, "ltp": 2.0, "tv": 112.12, "trd": [[2, 20.2]], "batb": [[0, 2, 27.44]], "batl": NaN}, {"timestamp": 1631519620685, "ltp": 2.0, "tv": 112.12, "trd": NaN, "batb": NaN, "batl": [[2, 29, 48.45]]}, {"timestamp": 1631519621407, "ltp": 2.0, "tv": 112.12, "trd": NaN, "batb": NaN, "batl": [[2, 2.4, 5.17]]}, {"timestamp": 1631519803542, "ltp": 2.0, "tv": 112.12, "trd": NaN, "batb": [[2, 1.83, 40.74]], "batl": [[0, 2.02, 4], [1, 2.04, 8.1], [2, 2.1, 7.99]]}, {"timestamp": 1631519805026, "ltp": 2.0, "tv": 112.12, "trd": NaN, "batb": [[2, 1.5, 88.09]], "batl": NaN}, {"timestamp": 1631520109182, "ltp": 2.0, "tv": 112.12, "trd": NaN, "batb": [[2, 1.83, 40.74]], "batl": NaN}, {"timestamp": 1631520387963, "ltp": 2.0, "tv": 112.12, "trd": NaN, "batb": [[2, 1.83, 37.74]], "batl": NaN}, {"timestamp": 1631520492958, "ltp": 2.0, "tv": 112.12, "trd": NaN, "batb": [[0, 2, 44.39]], "batl": NaN}, {"timestamp": 1631520505842, "ltp": 2.0, "tv": 112.12, "trd": NaN, "batb": NaN, "batl": [[0, 2.02, 54]]}, {"timestamp": 1631520574027, "ltp": 2.0, "tv": 162.33, "trd": [[2, 70.42]], "batb": [[0, 2, 19.28]], "batl": NaN}, {"timestamp": 1631520575731, "ltp": 2.0, "tv": 162.33, "trd": NaN, "batb": [[2, 1.5, 88.09]], "batl": NaN}, {"timestamp": 1631520662973, "ltp": 2.0, "tv": 162.33, "trd": NaN, "batb": [[1, 1.97, 27.15]], "batl": NaN}, {"timestamp": 1631520715148, "ltp": 2.0, "tv": 179.4, "trd": [[2, 87.49]], "batb": [[0, 2, 10.74]], "batl": NaN}, {"timestamp": 1631521211238, "ltp": 2.0, "tv": 179.4, "trd": NaN, "batb": [[2, 1.5, 127.11]], "batl": NaN}, {"timestamp": 1631521538827, "ltp": 2.0, "tv": 238.48, "trd": [[2, 146.57]], "batb": [[0, 1.97, 27.15], [1, 1.5, 127.11], [2, 1.41, 43.26]], "batl": [[0, 2, 1.66], [1, 2.02, 4], [2, 2.04, 8.1]]}, {"timestamp": 1631521544062, "ltp": 2.0, "tv": 238.48, "trd": NaN, "batb": [[1, 1.83, 37.74], [2, 1.5, 127.11]], "batl": NaN}, {"timestamp": 1631521750621, "ltp": 2.0, "tv": 238.48, "trd": NaN, "batb": [[0, 1.98, 38.4], [1, 1.97, 27.15], [2, 1.83, 37.74]], "batl": NaN}, {"timestamp": 1631521802800, "ltp": 2.0, "tv": 238.48, "trd": NaN, "batb": [[2, 1.83, 50.32]], "batl": NaN}, {"timestamp": 1631522255099, "ltp": 2.0, "tv": 238.48, "trd": NaN, "batb": NaN, "batl": [[0, 2, 9.76], [2, 2.1, 7.99]]}, {"timestamp": 1631522698270, "ltp": 1.98, "tv": 284.49, "trd": [[1.98, 46.01]], "batb": [[0, 1.98, 15.39]], "batl": NaN}, {"timestamp": 1631522721709, "ltp": 2.0, "tv": 294.25, "trd": [[2, 156.33]], "batb": NaN, "batl": [[0, 2.02, 4], [1, 2.1, 7.99], [2, 2.4, 5.17]]}, {"timestamp": 1631522745957, "ltp": 2.0, "tv": 294.25, "trd": NaN, "batb": [[0, 1.98, 40.99]], "batl": NaN}, {"timestamp": 1631523221471, "ltp": 2.0, "tv": 294.25, "trd": NaN, "batb": NaN, "batl": [[2, 2.36, 5.32]]}, {"timestamp": 1631523394718, "ltp": 1.98, "tv": 304.25, "trd": [[1.98, 56.01]], "batb": [[0, 1.98, 35.99]], "batl": NaN}, {"timestamp": 1631523395285, "ltp": 1.98, "tv": 304.25, "trd": NaN, "batb": [[2, 1.8, 4]], "batl": NaN}, {"timestamp": 1631523592069, "ltp": 1.98, "tv": 304.25, "trd": NaN, "batb": NaN, "batl": [[0, 2.1, 7.99], [1, 2.36, 5.32], [2, 29, 48.45]]}, {"timestamp": 1631523593093, "ltp": 1.98, "tv": 304.25, "trd": NaN, "batb": [[2, 1.8, 56.2]], "batl": NaN}, {"timestamp": 1631523720480, "ltp": 1.98, "tv": 304.28, "trd": [[1.98, 56.01], [2, 156.35], [2.02, 91.93]], "batb": [[0, 1.98, 36], [1, 1.97, 27.16], [2, 1.9, 46.4]], "batl": [[0, 2.1, 7.99], [1, 2.36, 5.32], [2, 29, 48.42]]}, {"timestamp": 1631523852228, "ltp": 1.98, "tv": 304.28, "trd": NaN, "batb": [[2, 1.83, 50.32]], "batl": NaN}, {"timestamp": 1631523920826, "ltp": 1.98, "tv": 304.28, "trd": NaN, "batb": NaN, "batl": [[0, 2.1, 8.84]]}, {"timestamp": 1631524259664, "ltp": 1.98, "tv": 304.28, "trd": NaN, "batb": NaN, "batl": [[0, 2, 17.61], [1, 2.1, 8.84], [2, 2.36, 5.32]]}, {"timestamp": 1631524271882, "ltp": 1.98, "tv": 304.28, "trd": NaN, "batb": NaN, "batl": [[0, 1.99, 17.61]]}, {"timestamp": 1631524404281, "ltp": 1.98, "tv": 304.28, "trd": NaN, "batb": NaN, "batl": [[0, 1.99, 27.61]]}, {"timestamp": 1631524414402, "ltp": 1.98, "tv": 304.28, "trd": NaN, "batb": [[0, 1.98, 78.67]], "batl": NaN}, {"timestamp": 1631524453151, "ltp": 1.98, "tv": 304.28, "trd": NaN, "batb": NaN, "batl": [[2, 29, 48.42]]}, {"timestamp": 1631524637559, "ltp": 1.98, "tv": 304.28, "trd": NaN, "batb": NaN, "batl": [[1, 2.04, 4.3], [2, 2.1, 7.99]]}, {"timestamp": 1631525400458, "ltp": 1.98, "tv": 304.28, "trd": NaN, "batb": [[2, 1.92, 27.83]], "batl": NaN}, {"timestamp": 1631525522505, "ltp": 1.98, "tv": 304.28, "trd": NaN, "batb": [[1, 1.97, 10.24]], "batl": NaN}, {"timestamp": 1631525988517, "ltp": 1.98, "tv": 339.49, "trd": [[1.98, 91.22]], "batb": [[0, 1.98, 61.07]], "batl": [[0, 1.99, 10]]}, {"timestamp": 1631526179797, "ltp": 1.98, "tv": 342.83, "trd": [[1.98, 94.57]], "batb": [[0, 1.98, 59.39]], "batl": NaN}, {"timestamp": 1631526243225, "ltp": 1.98, "tv": 343.23, "trd": [[1.98, 94.96]], "batb": [[0, 1.98, 59.2]], "batl": NaN}, {"timestamp": 1631527231469, "ltp": 1.98, "tv": 356.71, "trd": [[1.98, 108.45]], "batb": [[0, 1.98, 52.45]], "batl": NaN}, {"timestamp": 1631527262484, "ltp": 1.98, "tv": 356.71, "trd": NaN, "batb": [[1, 1.97, 104.98]], "batl": NaN}, {"timestamp": 1631527941578, "ltp": 1.98, "tv": 356.92, "trd": [[1.98, 108.65]], "batb": [[0, 1.98, 52.35]], "batl": NaN}, {"timestamp": 1631528134733, "ltp": 1.98, "tv": 356.92, "trd": NaN, "batb": [[1, 1.97, 108.95]], "batl": NaN}, {"timestamp": 1631528243627, "ltp": 2.02, "tv": 1349.03, "trd": [[1.96, 575.81], [1.97, 217.91], [1.98, 287.02], [1.99, 20], [2.02, 91.94]], "batb": [[0, 1.92, 27.83], [1, 1.8, 4], [2, 1.5, 88.04]], "batl": [[0, 2.04, 4.29], [1, 2.1, 7.99], [2, 29, 48.42]]}, {"timestamp": 1631528244146, "ltp": 2.02, "tv": 1349.03, "trd": NaN, "batb": [[0, 1.93, 44.42], [1, 1.92, 27.83], [2, 1.8, 4]], "batl": NaN}, {"timestamp": 1631528245748, "ltp": 2.02, "tv": 1349.03, "trd": NaN, "batb": [[2, 1.83, 50.32]], "batl": NaN}, {"timestamp": 1631528279473, "ltp": 2.02, "tv": 1349.03, "trd": NaN, "batb": NaN, "batl": [[0, 1.98, 426.73], [1, 2.04, 4.29], [2, 2.1, 7.99]]}, {"timestamp": 1631528279986, "ltp": 2.02, "tv": 1349.03, "trd": NaN, "batb": [[1, 1.91, 28.14]], "batl": NaN}, {"timestamp": 1631528282163, "ltp": 2.02, "tv": 1349.03, "trd": NaN, "batb": [[0, 1.94, 162.93], [1, 1.93, 44.42], [2, 1.91, 28.14]], "batl": NaN}, {"timestamp": 1631528360650, "ltp": 2.02, "tv": 1349.03, "trd": NaN, "batb": [[1, 1.91, 28.31], [2, 1.83, 50.32]], "batl": NaN}, {"timestamp": 1631528360962, "ltp": 2.02, "tv": 1349.03, "trd": NaN, "batb": [[0, 1.95, 24.82], [1, 1.94, 162.93], [2, 1.91, 28.31]], "batl": NaN}, {"timestamp": 1631528397102, "ltp": 2.02, "tv": 1349.03, "trd": NaN, "batb": NaN, "batl": [[1, 2.04, 15.77]]}, {"timestamp": 1631528716753, "ltp": 1.96, "tv": 1354.03, "trd": [[1.96, 580.81]], "batb": NaN, "batl": NaN}, {"timestamp": 1631528732647, "ltp": 1.95, "tv": 1467.76, "trd": [[1.95, 49.64], [1.96, 644.9]], "batb": [[0, 1.94, 162.16], [1, 1.91, 28.14], [2, 1.9, 46.4]], "batl": [[0, 1.95, 118.63], [1, 1.98, 426.73], [2, 2.04, 15.77]]}, {"timestamp": 1631528733369, "ltp": 1.95, "tv": 1467.76, "trd": NaN, "batb": [[1, 1.93, 25.56]], "batl": NaN}, {"timestamp": 1631528940154, "ltp": 1.95, "tv": 1467.76, "trd": NaN, "batb": NaN, "batl": [[0, 1.95, 120.33]]}, {"timestamp": 1631528953489, "ltp": 1.95, "tv": 1708.42, "trd": [[1.95, 290.3]], "batb": [[0, 1.95, 41.83], [2, 1.9, 74.85]], "batl": [[0, 1.98, 426.73], [1, 2.04, 15.77], [2, 2.1, 7.99]]}, {"timestamp": 1631528959564, "ltp": 1.95, "tv": 1708.42, "trd": NaN, "batb": [[0, 1.94, 41.83], [2, 1.9, 46.4]], "batl": NaN}, {"timestamp": 1631528996729, "ltp": 1.95, "tv": 1708.42, "trd": NaN, "batb": NaN, "batl": [[0, 1.98, 428.73]]}, {"timestamp": 1631529008527, "ltp": 1.95, "tv": 1708.42, "trd": NaN, "batb": [[0, 1.95, 3.11], [1, 1.94, 41.83], [2, 1.93, 25.56]], "batl": NaN}, {"timestamp": 1631529450188, "ltp": 1.95, "tv": 1708.42, "trd": NaN, "batb": [[1, 1.93, 25.56], [2, 1.9, 46.4]], "batl": NaN}, {"timestamp": 1631529477113, "ltp": 1.95, "tv": 1708.42, "trd": NaN, "batb": NaN, "batl": [[1, 2, 170.69], [2, 2.04, 15.77]]}, {"timestamp": 1631529558209, "ltp": 1.95, "tv": 1708.42, "trd": NaN, "batb": NaN, "batl": [[0, 1.98, 430.79]]}, {"timestamp": 1631529799986, "ltp": 1.95, "tv": 1708.42, "trd": NaN, "batb": NaN, "batl": [[1, 2, 172.69]]}, {"timestamp": 1631529833723, "ltp": 1.95, "tv": 1708.42, "trd": NaN, "batb": NaN, "batl": [[2, 2.04, 12.32]]}, {"timestamp": 1631529839620, "ltp": 1.95, "tv": 1708.42, "trd": NaN, "batb": NaN, "batl": [[0, 1.96, 3.44], [1, 1.98, 430.79], [2, 2, 172.69]]}, {"timestamp": 1631529844725, "ltp": 1.95, "tv": 1708.42, "trd": NaN, "batb": [[1, 1.93, 95.35]], "batl": NaN}, {"timestamp": 1631530140217, "ltp": 1.95, "tv": 1708.42, "trd": NaN, "batb": NaN, "batl": [[1, 1.98, 428.73]]}, {"timestamp": 1631530291327, "ltp": 1.95, "tv": 1708.42, "trd": NaN, "batb": NaN, "batl": [[0, 1.98, 428.73], [1, 2, 172.69], [2, 2.04, 12.32]]}, {"timestamp": 1631530295683, "ltp": 1.94, "tv": 1715.3, "trd": [[1.94, 0.66], [1.95, 296.52]], "batb": [[0, 1.93, 95.35], [1, 1.9, 46.4], [2, 1.89, 28.77]], "batl": NaN}, {"timestamp": 1631530298011, "ltp": 1.95, "tv": 1791.75, "trd": [[1.95, 372.98]], "batb": NaN, "batl": NaN}, {"timestamp": 1631530320642, "ltp": 1.95, "tv": 1791.75, "trd": NaN, "batb": NaN, "batl": [[0, 1.97, 3.16], [1, 1.98, 428.73], [2, 2, 172.69]]}, {"timestamp": 1631530456619, "ltp": 1.95, "tv": 1791.75, "trd": NaN, "batb": NaN, "batl": [[0, 1.97, 5.63]]}, {"timestamp": 1631530456826, "ltp": 1.95, "tv": 1791.75, "trd": NaN, "batb": NaN, "batl": [[1, 1.98, 431.19]]}, {"timestamp": 1631530551506, "ltp": 1.93, "tv": 1874.55, "trd": [[1.93, 82.79]], "batb": [[0, 1.93, 53.96], [1, 1.91, 26.74], [2, 1.9, 46.4]], "batl": NaN}, {"timestamp": 1631530740298, "ltp": 1.93, "tv": 1874.55, "trd": NaN, "batb": NaN, "batl": [[0, 1.97, 3.16], [1, 1.98, 428.73]]}, {"timestamp": 1631530742077, "ltp": 1.93, "tv": 2134.27, "trd": [[1.93, 342.52]], "batb": [[0, 1.91, 26.74], [1, 1.9, 46.4], [2, 1.89, 28.77]], "batl": [[0, 1.93, 45.95], [1, 1.97, 3.16], [2, 1.98, 428.73]]}, {"timestamp": 1631530742908, "ltp": 1.93, "tv": 2134.27, "trd": NaN, "batb": [[2, 1.88, 2.66]], "batl": NaN}, {"timestamp": 1631531214443, "ltp": 1.93, "tv": 2130.58, "trd": [[1.93, 341.97], [1.95, 372.26], [1.96, 643.63], [1.97, 217.48], [1.98, 286.55], [1.99, 19.98], [2, 156.22], [2.02, 91.84]], "batb": [[0, 1.91, 28.58], [2, 1.88, 2.66]], "batl": [[0, 1.97, 5.01], [1, 1.98, 429.74], [2, 2, 172.36]]}, {"timestamp": 1631531215122, "ltp": 1.93, "tv": 2130.58, "trd": NaN, "batb": [[2, 1.89, 28.71]], "batl": NaN}, {"timestamp": 1631531223382, "ltp": 1.92, "tv": 2176.83, "trd": [[1.92, 46.25]], "batb": NaN, "batl": NaN}, {"timestamp": 1631531430677, "ltp": 1.92, "tv": 2176.83, "trd": NaN, "batb": [[1, 1.9, 48.41]], "batl": [[0, 1.94, 3.41], [1, 1.97, 5.01], [2, 1.98, 429.74]]}, {"timestamp": 1631531431399, "ltp": 1.92, "tv": 2176.83, "trd": NaN, "batb": [[2, 1.88, 2.66]], "batl": NaN}, {"timestamp": 1631531434107, "ltp": 1.92, "tv": 2176.83, "trd": NaN, "batb": [[1, 1.9, 46.4]], "batl": [[0, 1.93, 3.41]]}, {"timestamp": 1631531437489, "ltp": 1.92, "tv": 2180.24, "trd": [[1.92, 49.65]], "batb": NaN, "batl": [[0, 1.97, 5.01], [1, 1.98, 429.74], [2, 2, 172.36]]}, {"timestamp": 1631531438318, "ltp": 1.92, "tv": 2180.24, "trd": NaN, "batb": [[2, 1.89, 28.71]], "batl": NaN}, {"timestamp": 1631531484052, "ltp": 1.92, "tv": 2180.24, "trd": NaN, "batb": [[1, 1.9, 48.46]], "batl": [[0, 1.96, 12], [1, 1.97, 5.01], [2, 1.98, 429.74]]}, {"timestamp": 1631531499076, "ltp": 1.96, "tv": 2180.66, "trd": [[1.96, 644.05]], "batb": [[2, 1.89, 30.78]], "batl": [[0, 1.96, 11.79]]}, {"timestamp": 1631531513586, "ltp": 1.94, "tv": 2197.63, "trd": [[1.94, 17.63]], "batb": NaN, "batl": [[0, 1.95, 5318.86], [1, 1.96, 14.9], [2, 1.97, 5.01]]}, {"timestamp": 1631531514311, "ltp": 1.94, "tv": 2197.63, "trd": NaN, "batb": [[2, 1.89, 2.07]], "batl": NaN}, {"timestamp": 1631531578416, "ltp": 1.95, "tv": 2209.3, "trd": [[1.95, 383.93]], "batb": NaN, "batl": [[0, 1.95, 5307.19]]}, {"timestamp": 1631531668710, "ltp": 1.95, "tv": 2209.3, "trd": NaN, "batb": [[2, 1.89, 74.87]], "batl": NaN}, {"timestamp": 1631531714567, "ltp": 1.95, "tv": 2217.76, "trd": [[1.95, 392.39]], "batb": NaN, "batl": [[0, 1.95, 5302.96]]}, {"timestamp": 1631531846651, "ltp": 1.95, "tv": 2217.76, "trd": NaN, "batb": [[0, 1.93, 113.3], [1, 1.91, 28.58], [2, 1.9, 48.46]], "batl": NaN}, {"timestamp": 1631531847949, "ltp": 1.95, "tv": 2224.53, "trd": [[1.95, 399.16]], "batb": NaN, "batl": [[0, 1.95, 5299.57]]}, {"timestamp": 1631531849459, "ltp": 1.95, "tv": 2229.6, "trd": [[1.95, 404.23]], "batb": NaN, "batl": [[0, 1.95, 5297.03]]}, {"timestamp": 1631531940163, "ltp": 1.95, "tv": 2229.6, "trd": NaN, "batb": [[1, 1.91, 26.69], [2, 1.9, 46.4]], "batl": [[0, 1.95, 5293.93], [1, 1.96, 11.79], [2, 1.97, 3.16]]}, {"timestamp": 1631531957002, "ltp": 1.95, "tv": 2229.6, "trd": NaN, "batb": NaN, "batl": [[0, 1.95, 5299.6], [1, 1.96, 17.46]]}, {"timestamp": 1631531964501, "ltp": 1.95, "tv": 2229.6, "trd": NaN, "batb": [[1, 1.92, 44.29], [2, 1.91, 26.69]], "batl": NaN}, {"timestamp": 1631531991908, "ltp": 1.95, "tv": 2229.6, "trd": NaN, "batb": [[1, 1.91, 26.69], [2, 1.9, 46.4]], "batl": NaN}, {"timestamp": 1631532092861, "ltp": 1.95, "tv": 2229.6, "trd": NaN, "batb": [[2, 1.89, 72.8]], "batl": NaN}, {"timestamp": 1631532104865, "ltp": 1.95, "tv": 2229.6, "trd": NaN, "batb": [[1, 1.9, 37.82]], "batl": NaN}, {"timestamp": 1631532157394, "ltp": 1.93, "tv": 2253.18, "trd": [[1.93, 365.55]], "batb": [[0, 1.93, 101.51]], "batl": [[1, 1.96, 5.67], [2, 1.97, 8.68]]}, {"timestamp": 1631532240229, "ltp": 1.93, "tv": 2253.18, "trd": NaN, "batb": NaN, "batl": [[0, 1.95, 5293.93], [1, 1.97, 3.16], [2, 1.98, 427.89]]}, {"timestamp": 1631532300400, "ltp": 1.93, "tv": 2253.18, "trd": NaN, "batb": [[1, 1.89, 72.8], [2, 1.88, 31.7]], "batl": NaN}, {"timestamp": 1631532355243, "ltp": 1.93, "tv": 2253.18, "trd": NaN, "batb": [[2, 1.88, 105.84]], "batl": NaN}, {"timestamp": 1631532364937, "ltp": 1.93, "tv": 2253.18, "trd": NaN, "batb": [[0, 1.94, 101.51]], "batl": NaN}, {"timestamp": 1631532407629, "ltp": 1.93, "tv": 2253.18, "trd": NaN, "batb": [[1, 1.88, 31.7], [2, 1.86, 29.71]], "batl": NaN}, {"timestamp": 1631532407849, "ltp": 1.93, "tv": 2253.18, "trd": NaN, "batb": [[1, 1.8, 3.41], [2, 1.29, 3.45]], "batl": [[1, 1.98, 425.89], [2, 2, 2]]}, {"timestamp": 1631532417631, "ltp": 1.94, "tv": 2456.2, "trd": [[1.94, 220.65]], "batb": [[0, 1.92, 107.39]], "batl": [[0, 1.94, 16.58], [1, 1.95, 5399.66], [2, 1.98, 425.89]]}, {"timestamp": 1631532417942, "ltp": 1.94, "tv": 2456.2, "trd": NaN, "batb": [[0, 1.8, 3.41], [1, 1.29, 3.45], [2, 1.2, 2]], "batl": [[0, 1.95, 5293.93], [1, 1.98, 425.89], [2, 2, 2]]}, {"timestamp": 1631532424457, "ltp": 1.95, "tv": 2485.95, "trd": [[1.95, 433.98]], "batb": NaN, "batl": [[0, 1.95, 5279.06]]}, {"timestamp": 1631532441466, "ltp": 1.95, "tv": 5635.41, "trd": [[1.95, 3583.44]], "batb": NaN, "batl": [[0, 1.95, 2129.6]]}, {"timestamp": 1631532443396, "ltp": 1.95, "tv": 5894.99, "trd": [[1.95, 3843.02]], "batb": [[0, 1.85, 76.99], [1, 1.8, 3.41], [2, 1.29, 3.45]], "batl": [[0, 1.95, 1999.81]]}, {"timestamp": 1631532444648, "ltp": 1.95, "tv": 9248.84, "trd": [[1.95, 7196.87]], "batb": NaN, "batl": [[0, 1.95, 184.47]]}, {"timestamp": 1631532445381, "ltp": 1.95, "tv": 9281.8, "trd": [[1.95, 7229.83]], "batb": [[0, 1.94, 4], [1, 1.85, 76.99], [2, 1.8, 3.41]], "batl": [[0, 1.95, 165.9]]}, {"timestamp": 1631532446596, "ltp": 1.94, "tv": 9289.8, "trd": [[1.94, 228.65]], "batb": [[0, 1.86, 110.85]], "batl": [[0, 1.94, 42.1], [1, 1.95, 165.9], [2, 1.98, 425.89]]}, {"timestamp": 1631532447482, "ltp": 1.95, "tv": 9342.73, "trd": [[1.94, 270.75], [1.95, 7240.66]], "batb": NaN, "batl": [[0, 1.95, 155.07], [1, 1.98, 425.89], [2, 2, 2]]}, {"timestamp": 1631532448576, "ltp": 1.98, "tv": 9604.03, "trd": [[1.95, 7395.73], [1.98, 392.78]], "batb": NaN, "batl": [[0, 1.98, 319.67], [1, 2, 2], [2, 2.1, 7.97]]}, {"timestamp": 1631532449567, "ltp": 1.98, "tv": 9604.03, "trd": NaN, "batb": [[0, 1.95, 167.52], [1, 1.86, 110.85], [2, 1.85, 76.99]], "batl": NaN}, {"timestamp": 1631532449777, "ltp": 1.98, "tv": 9604.03, "trd": NaN, "batb": [[0, 1.95, 283.54], [1, 1.93, 4], [2, 1.86, 110.85]], "batl": NaN}, {"timestamp": 1631532451666, "ltp": 1.98, "tv": 9866.1, "trd": [[1.98, 654.85]], "batb": [[0, 1.97, 4], [1, 1.95, 227.58], [2, 1.93, 4]], "batl": [[0, 1.98, 61.59]]}, {"timestamp": 1631532452291, "ltp": 1.98, "tv": 9866.1, "trd": NaN, "batb": [[0, 1.93, 98.66], [1, 1.86, 110.85], [2, 1.85, 76.99]], "batl": NaN}, {"timestamp": 1631532452863, "ltp": 1.98, "tv": 9866.1, "trd": NaN, "batb": [[0, 1.94, 97.99], [1, 1.93, 98.66], [2, 1.86, 110.85]], "batl": NaN}, {"timestamp": 1631532454592, "ltp": 1.98, "tv": 9927.69, "trd": [[1.98, 716.44]], "batb": [[0, 1.96, 94.29], [1, 1.95, 95.87]], "batl": [[0, 2, 2], [1, 2.1, 7.97], [2, 2.16, 2]]}, {"timestamp": 1631532455479, "ltp": 1.98, "tv": 9927.69, "trd": NaN, "batb": [[0, 1.87, 4], [1, 1.86, 115.85], [2, 1.85, 76.99]], "batl": NaN}, {"timestamp": 1631532457572, "ltp": 1.98, "tv": 9927.69, "trd": NaN, "batb": [[0, 1.86, 5], [1, 1.85, 76.99], [2, 1.8, 3.41]], "batl": NaN}, {"timestamp": 1631532460621, "ltp": 1.98, "tv": 9927.69, "trd": NaN, "batb": [[1, 1.85, 78.99], [2, 1.84, 79.25]], "batl": [[1, 2.02, 5], [2, 2.1, 7.97]]}, {"timestamp": 1631532462495, "ltp": 1.98, "tv": 9927.69, "trd": NaN, "batb": [[0, 1.84, 79.25], [1, 1.8, 3.41], [2, 1.29, 3.45]], "batl": NaN}, {"timestamp": 1631532464693, "ltp": 1.98, "tv": 9927.69, "trd": NaN, "batb": [[0, 1.86, 190.18], [1, 1.84, 256.76], [2, 1.82, 577.95]], "batl": [[0, 1.93, 134.37], [1, 1.95, 150.71], [2, 1.96, 975.78]]}, {"timestamp": 1631532466677, "ltp": 1.93, "tv": 10062.06, "trd": [[1.93, 499.92]], "batb": NaN, "batl": [[0, 1.95, 150.71], [1, 1.96, 975.78], [2, 1.97, 947.06]]}, {"timestamp": 1631532467510, "ltp": 1.93, "tv": 10062.06, "trd": NaN, "batb": [[0, 1.84, 84.25], [1, 1.82, 577.95], [2, 1.81, 560.96]], "batl": [[0, 1.96, 975.78], [1, 1.97, 947.06], [2, 1.98, 947.06]]}, {"timestamp": 1631532468605, "ltp": 1.93, "tv": 10062.06, "trd": NaN, "batb": [[0, 1.87, 84.54], [1, 1.84, 84.25], [2, 1.82, 577.95]], "batl": NaN}, {"timestamp": 1631532470478, "ltp": 1.93, "tv": 10062.06, "trd": NaN, "batb": [[0, 1.87, 264.73], [1, 1.85, 265.22], [2, 1.84, 84.25]], "batl": [[0, 1.94, 135.96], [1, 1.96, 1124.13], [2, 1.97, 947.06]]}, {"timestamp": 1631532473181, "ltp": 1.93, "tv": 10062.06, "trd": NaN, "batb": [[0, 1.88, 110.81], [1, 1.87, 264.73], [2, 1.85, 265.22]], "batl": NaN}, {"timestamp": 1631532474702, "ltp": 1.93, "tv": 10062.06, "trd": NaN, "batb": [[0, 1.83, 1642], [1, 1.8, 3.41], [2, 1.72, 97.82]], "batl": [[0, 2, 2], [1, 2.02, 5], [2, 2.1, 7.97]]}, {"timestamp": 1631532475225, "ltp": 1.93, "tv": 10062.06, "trd": NaN, "batb": [[0, 1.8, 3.41], [1, 1.72, 97.82], [2, 1.29, 3.45]], "batl": NaN}, {"timestamp": 1631532477715, "ltp": 1.93, "tv": 10062.06, "trd": NaN, "batb": [[1, 1.76, 163.8], [2, 1.74, 309.07]], "batl": [[2, 2.06, 120.49]]}, {"timestamp": 1631532485202, "ltp": 1.93, "tv": 10062.06, "trd": NaN, "batb": NaN, "batl": [[2, 2.1, 7.97]]}, {"timestamp": 1631532488414, "ltp": 1.93, "tv": 10062.06, "trd": NaN, "batb": NaN, "batl": [[0, 1.81, 14.69], [1, 1.82, 162.04], [2, 1.84, 1219.99]]}, {"timestamp": 1631532492161, "ltp": 1.8, "tv": 10066.71, "trd": [[1.8, 4.65]], "batb": [[0, 1.8, 1.08], [1, 1.78, 109.65], [2, 1.76, 163.8]], "batl": NaN}, {"timestamp": 1631532496208, "ltp": 1.8, "tv": 10066.71, "trd": NaN, "batb": [[1, 1.79, 97.59], [2, 1.78, 109.65]], "batl": NaN}, {"timestamp": 1631532498700, "ltp": 1.81, "tv": 10096.09, "trd": [[1.81, 29.37]], "batb": [[0, 1.81, 9.03], [1, 1.8, 1.08], [2, 1.79, 97.59]], "batl": [[0, 1.82, 162.04], [1, 1.84, 1219.99], [2, 1.85, 1008.82]]}, {"timestamp": 1631532499013, "ltp": 1.81, "tv": 10096.09, "trd": NaN, "batb": [[0, 1.8, 1.08], [1, 1.79, 97.59], [2, 1.78, 109.65]], "batl": NaN}, {"timestamp": 1631532501251, "ltp": 1.81, "tv": 10096.09, "trd": NaN, "batb": NaN, "batl": [[0, 1.81, 108], [1, 1.82, 162.04], [2, 1.84, 1219.99]]}, {"timestamp": 1631532501937, "ltp": 1.8, "tv": 10113.13, "trd": [[1.8, 21.69]], "batb": [[0, 1.8, 70.28], [1, 1.76, 163.8], [2, 1.74, 309.07]], "batl": NaN}, {"timestamp": 1631532505648, "ltp": 1.8, "tv": 10113.13, "trd": NaN, "batb": [[0, 1.77, 76.32]], "batl": [[0, 1.82, 162.04], [1, 1.84, 180.59], [2, 2, 2]]}, {"timestamp": 1631532506016, "ltp": 1.8, "tv": 10113.13, "trd": NaN, "batb": [[0, 1.62, 121.25], [1, 1.29, 3.45], [2, 1.2, 2]], "batl": [[0, 2, 2], [1, 2.02, 5], [2, 2.1, 7.97]]}, {"timestamp": 1631532508452, "ltp": 1.8, "tv": 10113.13, "trd": NaN, "batb": [[2, 1.2, 388.24]], "batl": NaN}, {"timestamp": 1631532509442, "ltp": 1.8, "tv": 10113.13, "trd": NaN, "batb": [[0, 1.63, 5], [1, 1.62, 127.25], [2, 1.29, 3.45]], "batl": [[0, 1.94, 4], [1, 2, 2], [2, 2.02, 5]]}, {"timestamp": 1631532510332, "ltp": 1.8, "tv": 10113.13, "trd": NaN, "batb": [[0, 1.81, 14.87], [1, 1.63, 5], [2, 1.62, 127.25]], "batl": NaN}, {"timestamp": 1631532511518, "ltp": 1.8, "tv": 10113.13, "trd": NaN, "batb": NaN, "batl": [[1, 1.95, 4], [2, 2, 2]]}, {"timestamp": 1631532512658, "ltp": 1.81, "tv": 10142.87, "trd": [[1.81, 59.12]], "batb": [[0, 1.74, 145.76], [1, 1.72, 222.36], [2, 1.66, 5]], "batl": [[0, 1.8, 183.42], [1, 1.82, 186.95], [2, 1.93, 5]]}, {"timestamp": 1631532513640, "ltp": 1.81, "tv": 10142.87, "trd": NaN, "batb": [[0, 1.66, 5], [1, 1.65, 5], [2, 1.63, 5]], "batl": [[0, 1.93, 5], [1, 1.94, 4], [2, 1.95, 4]]}, {"timestamp": 1631532517367, "ltp": 1.81, "tv": 10142.87, "trd": NaN, "batb": [[0, 1.66, 139.21], [1, 1.65, 134.47]], "batl": [[0, 1.93, 117.35], [2, 1.95, 154.68]]}, {"timestamp": 1631532517935, "ltp": 1.81, "tv": 10142.87, "trd": NaN, "batb": [[0, 1.66, 5], [1, 1.65, 5]], "batl": NaN}, {"timestamp": 1631532520670, "ltp": 1.81, "tv": 10142.87, "trd": NaN, "batb": [[0, 1.86, 1606.95], [1, 1.84, 2078.8], [2, 1.83, 2017.66]], "batl": [[0, 1.93, 112.35], [1, 1.95, 150.68], [2, 1.96, 1951.54]]}, {"timestamp": 1631532521548, "ltp": 1.81, "tv": 10142.87, "trd": NaN, "batb": [[0, 1.87, 126.11], [1, 1.86, 15.28], [2, 1.85, 252.76]], "batl": [[2, 1.96, 536.68]]}, {"timestamp": 1631532524653, "ltp": 1.81, "tv": 10142.87, "trd": NaN, "batb": [[0, 1.88, 80.76], [1, 1.87, 126.11], [2, 1.86, 15.28]], "batl": NaN}, {"timestamp": 1631532525639, "ltp": 1.87, "tv": 10356.69, "trd": [[1.87, 52.3], [1.88, 161.52]], "batb": [[0, 1.87, 99.96], [1, 1.86, 15.28], [2, 1.85, 252.76]], "batl": NaN}, {"timestamp": 1631532528592, "ltp": 1.87, "tv": 10356.69, "trd": NaN, "batb": [[0, 1.88, 75.1], [1, 1.87, 99.96], [2, 1.86, 15.28]], "batl": [[0, 1.92, 46.73], [1, 1.93, 112.35], [2, 1.95, 150.68]]}, {"timestamp": 1631532528749, "ltp": 1.87, "tv": 10356.69, "trd": NaN, "batb": NaN, "batl": [[1, 1.93, 126.35]]}, {"timestamp": 1631532531590, "ltp": 1.88, "tv": 10386.44, "trd": [[1.88, 191.26]], "batb": [[0, 1.88, 60.23]], "batl": NaN}, {"timestamp": 1631532532469, "ltp": 1.88, "tv": 10386.44, "trd": NaN, "batb": [[2, 1.85, 252.76]], "batl": NaN}, {"timestamp": 1631532534168, "ltp": 1.87, "tv": 10527.62, "trd": [[1.87, 73.02], [1.88, 311.72]], "batb": [[0, 1.87, 89.6], [1, 1.85, 252.76], [2, 1.84, 1039.4]], "batl": NaN}, {"timestamp": 1631532534791, "ltp": 1.87, "tv": 10527.62, "trd": NaN, "batb": [[0, 1.85, 78.41], [1, 1.84, 1039.4], [2, 1.83, 1008.82]], "batl": NaN}, {"timestamp": 1631532537693, "ltp": 1.87, "tv": 10527.62, "trd": NaN, "batb": [[0, 1.86, 192.7], [1, 1.85, 78.41], [2, 1.84, 177.5]], "batl": [[0, 1.93, 126.35], [1, 1.95, 150.68], [2, 1.97, 29.5]]}, {"timestamp": 1631532538260, "ltp": 1.87, "tv": 10527.62, "trd": NaN, "batb": [[0, 1.7, 102.51], [1, 1.66, 5], [2, 1.3, 198.07]], "batl": [[0, 2, 7], [1, 2.06, 8.25], [2, 2.1, 7.97]]}, {"timestamp": 1631532540698, "ltp": 1.87, "tv": 10527.62, "trd": NaN, "batb": [[0, 1.73, 143.61], [1, 1.71, 226.91], [2, 1.7, 102.51]], "batl": [[2, 2.08, 116.66]]}, {"timestamp": 1631532541477, "ltp": 1.87, "tv": 10527.62, "trd": NaN, "batb": [[2, 1.7, 107.51]], "batl": [[0, 2, 33.22]]}, {"timestamp": 1631532541788, "ltp": 1.87, "tv": 10527.62, "trd": NaN, "batb": NaN, "batl": [[0, 2, 7]]}, {"timestamp": 1631532543862, "ltp": 1.87, "tv": 10527.62, "trd": NaN, "batb": NaN, "batl": [[0, 1.85, 70.59], [1, 2, 7], [2, 2.06, 8.25]]}, {"timestamp": 1631532546607, "ltp": 1.87, "tv": 10527.62, "trd": NaN, "batb": NaN, "batl": [[0, 2, 7], [1, 2.06, 8.25], [2, 2.08, 116.66]]}, {"timestamp": 1631532547593, "ltp": 1.87, "tv": 10527.62, "trd": NaN, "batb": [[0, 1.7, 107.51], [1, 1.69, 5], [2, 1.66, 5]], "batl": [[2, 2.1, 12.93]]}, {"timestamp": 1631532548572, "ltp": 1.87, "tv": 10527.62, "trd": NaN, "batb": [[0, 1.85, 17.68], [1, 1.7, 107.51], [2, 1.69, 5]], "batl": [[0, 2, 32.61]]}, {"timestamp": 1631532549714, "ltp": 2.0, "tv": 10545.62, "trd": [[2, 174.22]], "batb": [[0, 2, 2330.72], [1, 1.85, 8.85], [2, 1.7, 107.51]], "batl": [[0, 2.06, 8.25], [1, 2.1, 12.93], [2, 2.16, 2]]}, {"timestamp": 1631532550594, "ltp": 2.0, "tv": 10545.62, "trd": NaN, "batb": [[0, 1.99, 961.06], [1, 1.98, 932.8], [2, 1.97, 932.8]], "batl": NaN}, {"timestamp": 1631532551681, "ltp": 2.0, "tv": 10545.62, "trd": NaN, "batb": [[2, 1.97, 1062]], "batl": [[2, 2.14, 9.35]]}, {"timestamp": 1631532553480, "ltp": 2.0, "tv": 10545.62, "trd": NaN, "batb": [[0, 2, 4], [1, 1.99, 965.06], [2, 1.98, 932.8]], "batl": NaN}, {"timestamp": 1631532554620, "ltp": 2.0, "tv": 10545.62, "trd": NaN, "batb": [[0, 2, 69.92]], "batl": [[0, 2.06, 72.25]]}, {"timestamp": 1631532556124, "ltp": 2.0, "tv": 10545.62, "trd": NaN, "batb": NaN, "batl": [[0, 2.04, 74.38], [1, 2.06, 72.25], [2, 2.1, 12.93]]}, {"timestamp": 1631532558714, "ltp": 2.0, "tv": 10545.62, "trd": NaN, "batb": NaN, "batl": [[2, 2.1, 20.38]]}, {"timestamp": 1631532560426, "ltp": 2.0, "tv": 10545.62, "trd": NaN, "batb": [[0, 1.84, 26.22], [1, 1.83, 81], [2, 1.77, 33.37]], "batl": [[0, 2.1, 20.38], [1, 2.16, 9.72], [2, 2.1, 0]]}, {"timestamp": 1631532561189, "ltp": 2.0, "tv": 10545.62, "trd": NaN, "batb": [[0, 1.83, 81], [1, 1.77, 33.37], [2, 1.3, 198.07]], "batl": NaN}, {"timestamp": 1631532563638, "ltp": 2.0, "tv": 10545.62, "trd": NaN, "batb": NaN, "batl": [[0, 2, 13.02], [1, 2.1, 20.38], [2, 2.16, 9.72]]}, {"timestamp": 1631532563998, "ltp": 2.0, "tv": 10545.62, "trd": NaN, "batb": [[0, 1.84, 33.97], [1, 1.83, 85], [2, 1.82, 5]], "batl": NaN}, {"timestamp": 1631532565295, "ltp": 2.0, "tv": 10545.62, "trd": NaN, "batb": [[0, 1.83, 85], [1, 1.82, 5], [2, 1.77, 33.37]], "batl": NaN}, {"timestamp": 1631532567424, "ltp": 2.0, "tv": 10558.63, "trd": [[2, 187.24]], "batb": NaN, "batl": [[0, 2.1, 12.93], [1, 2.16, 9.72], [2, 2.16, 0]]}, {"timestamp": 1631532568716, "ltp": 2.1, "tv": 10571.56, "trd": [[2.1, 12.93]], "batb": [[0, 2.06, 110.21], [1, 1.98, 126.78], [2, 1.83, 85]], "batl": [[0, 2.16, 9.72], [1, 2.26, 8.85]]}, {"timestamp": 1631532569129, "ltp": 2.1, "tv": 10571.56, "trd": NaN, "batb": [[2, 1.83, 4]], "batl": NaN}, {"timestamp": 1631532570628, "ltp": 2.1, "tv": 10571.56, "trd": NaN, "batb": [[0, 2.1, 4], [1, 2.08, 4], [2, 2.06, 110.21]], "batl": NaN}, {"timestamp": 1631532572713, "ltp": 2.1, "tv": 10571.56, "trd": NaN, "batb": NaN, "batl": [[1, 2.22, 53.33], [2, 2.26, 8.85]]}, {"timestamp": 1631532572930, "ltp": 2.1, "tv": 10571.56, "trd": NaN, "batb": NaN, "batl": [[1, 2.26, 8.85], [2, 2.26, 0]]}, {"timestamp": 1631532575426, "ltp": 2.1, "tv": 10571.56, "trd": NaN, "batb": NaN, "batl": [[2, 1000, 1]]}, {"timestamp": 1631532576620, "ltp": 2.1, "tv": 10571.56, "trd": NaN, "batb": [[1, 2.08, 111.03]], "batl": [[2, 1000, 0]]}, {"timestamp": 1631532577509, "ltp": 2.1, "tv": 10571.56, "trd": NaN, "batb": NaN, "batl": [[0, 2.16, 7.72]]}, {"timestamp": 1631532579211, "ltp": 2.1, "tv": 10571.56, "trd": NaN, "batb": NaN, "batl": [[1, 2.26, 9.85]]}, {"timestamp": 1631532580611, "ltp": 2.12, "tv": 10573.56, "trd": [[2.12, 2]], "batb": NaN, "batl": NaN}, {"timestamp": 1631532581646, "ltp": 2.16, "tv": 10587.76, "trd": [[2.16, 14.2]], "batb": NaN, "batl": [[0, 2.26, 10.47], [1, 2.26, 0]]}, {"timestamp": 1631532596639, "ltp": 2.16, "tv": 10587.76, "trd": NaN, "batb": [[1, 2.08, 107.03]], "batl": NaN}, {"timestamp": 1631532628301, "ltp": 2.16, "tv": 10587.76, "trd": NaN, "batb": NaN, "batl": [[1, 2.3, 5.95], [2, 2.38, 6.75]]}, {"timestamp": 1631532629669, "ltp": 2.16, "tv": 10587.76, "trd": NaN, "batb": NaN, "batl": [[0, 2.26, 1.62]]}, {"timestamp": 1631532630087, "ltp": 2.16, "tv": 10587.76, "trd": NaN, "batb": [[0, 2, 151.02], [1, 1.95, 26.31], [2, 1.82, 4.2]], "batl": [[0, 2.26, 1], [1, 2.38, 6.75], [2, 2.38, 0]]}, {"timestamp": 1631532634590, "ltp": 2.16, "tv": 10587.76, "trd": NaN, "batb": NaN, "batl": [[1, 2.3, 4], [2, 2.38, 6.75]]}, {"timestamp": 1631532636406, "ltp": 2.16, "tv": 10587.76, "trd": NaN, "batb": NaN, "batl": [[2, 2.32, 4]]}, {"timestamp": 1631532637615, "ltp": 2.16, "tv": 10587.76, "trd": NaN, "batb": NaN, "batl": [[1, 2.3, 9.95]]}, {"timestamp": 1631532638089, "ltp": 2.16, "tv": 10587.76, "trd": NaN, "batb": NaN, "batl": [[1, 2.3, 5.95], [2, 2.38, 6.75]]}, {"timestamp": 1631532640795, "ltp": 2.16, "tv": 10587.76, "trd": NaN, "batb": [[0, 2.04, 4], [1, 2.02, 766.33], [2, 2, 151.02]], "batl": NaN}, {"timestamp": 1631532644008, "ltp": 2.16, "tv": 10587.76, "trd": NaN, "batb": [[0, 2.06, 4], [1, 2.04, 4], [2, 2.02, 766.33]], "batl": NaN}, {"timestamp": 1631532647501, "ltp": 2.16, "tv": 10587.76, "trd": NaN, "batb": [[0, 2, 151.02], [1, 1.95, 26.31], [2, 1.82, 4.2]], "batl": [[1, 2.38, 6.75], [2, 2.38, 0]]}, {"timestamp": 1631532650407, "ltp": 2.16, "tv": 10587.76, "trd": NaN, "batb": NaN, "batl": [[1, 2.34, 3], [2, 2.38, 6.75]]}, {"timestamp": 1631532653623, "ltp": 2.16, "tv": 10587.76, "trd": NaN, "batb": NaN, "batl": [[1, 2.3, 10.35], [2, 2.32, 4]]}, {"timestamp": 1631532653989, "ltp": 2.16, "tv": 10587.76, "trd": NaN, "batb": [[0, 2, 123.09]], "batl": [[1, 2.3, 4]]}, {"timestamp": 1631532657314, "ltp": 2.16, "tv": 10587.76, "trd": NaN, "batb": [[0, 2, 147.43]], "batl": NaN}, {"timestamp": 1631532660579, "ltp": 2.16, "tv": 10587.76, "trd": NaN, "batb": [[0, 2, 123.09]], "batl": [[1, 2.28, 4], [2, 2.3, 10.15]]}, {"timestamp": 1631532660848, "ltp": 2.16, "tv": 10587.76, "trd": NaN, "batb": NaN, "batl": [[2, 2.3, 4]]}, {"timestamp": 1631532663680, "ltp": 2.16, "tv": 10587.76, "trd": NaN, "batb": [[0, 2, 147.17]], "batl": [[0, 2.28, 4], [1, 2.3, 4], [2, 2.32, 4]]}, {"timestamp": 1631532667569, "ltp": 2.16, "tv": 10587.76, "trd": NaN, "batb": NaN, "batl": [[1, 2.3, 6.15], [2, 2.38, 6.75]]}, {"timestamp": 1631532667879, "ltp": 2.16, "tv": 10587.76, "trd": NaN, "batb": NaN, "batl": [[1, 2.38, 6.75], [2, 2.38, 0]]}, {"timestamp": 1631532672598, "ltp": 2.02, "tv": 10600.54, "trd": [[2.02, 104.61]], "batb": NaN, "batl": NaN}, {"timestamp": 1631532674681, "ltp": 2.02, "tv": 10600.54, "trd": NaN, "batb": NaN, "batl": [[1, 2.3, 6.15], [2, 2.38, 6.75]]}, {"timestamp": 1631532674994, "ltp": 2.02, "tv": 10600.54, "trd": NaN, "batb": NaN, "batl": [[1, 2.38, 6.75], [2, 2.38, 0]]}, {"timestamp": 1631532681691, "ltp": 2.02, "tv": 10600.54, "trd": NaN, "batb": NaN, "batl": [[1, 2.3, 6.35], [2, 2.38, 6.75]]}, {"timestamp": 1631532682678, "ltp": 2.02, "tv": 10600.54, "trd": NaN, "batb": [[1, 1.98, 593.43], [2, 1.97, 296.72]], "batl": [[1, 2.38, 6.75], [2, 2.38, 0]]}, {"timestamp": 1631532683195, "ltp": 2.02, "tv": 10600.54, "trd": NaN, "batb": [[1, 1.98, 148.36], [2, 1.97, 74.18]], "batl": NaN}, {"timestamp": 1631532684290, "ltp": 2.02, "tv": 10600.54, "trd": NaN, "batb": [[0, 2.02, 4], [1, 2, 152.17], [2, 1.98, 148.36]], "batl": [[0, 2.26, 3], [1, 2.28, 4], [2, 2.38, 6.75]]}, {"timestamp": 1631532688991, "ltp": 2.02, "tv": 10600.54, "trd": NaN, "batb": NaN, "batl": [[0, 2.16, 7.97], [1, 2.22, 6.75], [2, 2.26, 3]]}, {"timestamp": 1631532694423, "ltp": 2.02, "tv": 10600.54, "trd": NaN, "batb": NaN, "batl": [[1, 2.2, 7.28], [2, 2.22, 6.75]]}, {"timestamp": 1631532698196, "ltp": 2.02, "tv": 10600.54, "trd": NaN, "batb": [[1, 2, 147.17]], "batl": NaN}, {"timestamp": 1631532700427, "ltp": 2.02, "tv": 10600.54, "trd": NaN, "batb": [[0, 1.92, 69.45], [1, 1.91, 32.39], [2, 1.82, 4.2]], "batl": [[0, 2.26, 3], [1, 2.82, 234.47], [2, 2.22, 0]]}, {"timestamp": 1631532703649, "ltp": 2.02, "tv": 10600.54, "trd": NaN, "batb": [[0, 1.97, 25.17], [1, 1.92, 72.45], [2, 1.91, 35.39]], "batl": [[0, 2.16, 7.97], [1, 2.2, 4], [2, 2.22, 10.25]]}, {"timestamp": 1631532704109, "ltp": 2.02, "tv": 10600.54, "trd": NaN, "batb": [[0, 1.92, 72.45], [1, 1.91, 35.39], [2, 1.82, 4.2]], "batl": [[0, 2.2, 4], [1, 2.22, 10.25], [2, 2.26, 3]]}, {"timestamp": 1631532707115, "ltp": 2.02, "tv": 10600.54, "trd": NaN, "batb": [[0, 1.97, 27.17], [1, 1.92, 72.45], [2, 1.91, 35.39]], "batl": [[0, 2.16, 6.47], [1, 2.2, 4], [2, 2.22, 10.25]]}, {"timestamp": 1631532712444, "ltp": 2.02, "tv": 10600.54, "trd": NaN, "batb": [[0, 1.92, 72.45], [1, 1.91, 35.39], [2, 1.82, 4.2]], "batl": [[0, 2.2, 4], [1, 2.22, 10.25], [2, 2.26, 3]]}, {"timestamp": 1631532715652, "ltp": 2.02, "tv": 10600.54, "trd": NaN, "batb": [[0, 1.97, 26.17], [1, 1.92, 72.45], [2, 1.91, 32.39]], "batl": [[0, 2.16, 6.47], [1, 2.2, 4], [2, 2.22, 6.25]]}, {"timestamp": 1631532716036, "ltp": 2.02, "tv": 10600.54, "trd": NaN, "batb": [[0, 1.92, 72.45], [1, 1.91, 32.39], [2, 1.82, 4.2]], "batl": [[0, 2.2, 4], [1, 2.82, 234.47], [2, 2.22, 0]]}, {"timestamp": 1631532718663, "ltp": 2.02, "tv": 10600.54, "trd": NaN, "batb": [[1, 1.91, 35.39]], "batl": NaN}, {"timestamp": 1631532722654, "ltp": 2.02, "tv": 10600.54, "trd": NaN, "batb": [[0, 1.93, 753.28], [1, 1.92, 72.45], [2, 1.91, 35.39]], "batl": NaN}, {"timestamp": 1631532723642, "ltp": 2.02, "tv": 10600.54, "trd": NaN, "batb": [[0, 1.92, 72.45], [1, 1.91, 35.39], [2, 1.82, 4.2]], "batl": NaN}, {"timestamp": 1631532732365, "ltp": 2.02, "tv": 10600.54, "trd": NaN, "batb": [[1, 1.91, 32.39]], "batl": NaN}, {"timestamp": 1631532735672, "ltp": 2.02, "tv": 10600.54, "trd": NaN, "batb": [[0, 1.92, 236.17], [1, 1.91, 37.39], [2, 1.9, 159.98]], "batl": [[0, 1.99, 114.91], [1, 2.02, 204.08], [2, 2.08, 9.62]]}, {"timestamp": 1631532742668, "ltp": 2.02, "tv": 10600.54, "trd": NaN, "batb": NaN, "batl": [[0, 1.98, 3.24], [1, 1.99, 114.91], [2, 2.02, 204.08]]}, {"timestamp": 1631532743706, "ltp": 2.02, "tv": 10600.54, "trd": NaN, "batb": [[1, 1.91, 77.79]], "batl": [[2, 2, 38.58]]}, {"timestamp": 1631532746705, "ltp": 2.02, "tv": 10600.54, "trd": NaN, "batb": [[0, 1.92, 277.45]], "batl": [[0, 1.98, 43.27]]}, {"timestamp": 1631532747466, "ltp": 2.02, "tv": 10600.54, "trd": NaN, "batb": [[1, 1.91, 72.79]], "batl": NaN}, {"timestamp": 1631532751707, "ltp": 2.02, "tv": 10600.54, "trd": NaN, "batb": [[0, 1.92, 72.45], [1, 1.91, 32.39], [2, 1.86, 76.9]], "batl": [[0, 1.97, 8.52], [1, 1.98, 3.24], [2, 2.18, 4]]}, {"timestamp": 1631532752179, "ltp": 2.02, "tv": 10600.54, "trd": NaN, "batb": [[0, 1.92, 3], [1, 1.86, 76.9], [2, 1.82, 4.2]], "batl": [[0, 1.96, 8.52], [1, 1.97, 8.52], [2, 1.98, 3.24]]}, {"timestamp": 1631532754463, "ltp": 2.02, "tv": 10600.54, "trd": NaN, "batb": [[1, 1.91, 4], [2, 1.86, 76.9]], "batl": NaN}, {"timestamp": 1631532757370, "ltp": 2.02, "tv": 10600.54, "trd": NaN, "batb": NaN, "batl": [[0, 1.98, 3.24], [1, 2.18, 4], [2, 2.82, 234.47]]}, {"timestamp": 1631532757783, "ltp": 2.02, "tv": 10600.54, "trd": NaN, "batb": NaN, "batl": [[2, 2.82, 0]]}, {"timestamp": 1631532759704, "ltp": 1.92, "tv": 10606.54, "trd": [[1.92, 55.65]], "batb": [[0, 1.86, 76.9], [1, 1.85, 154.02], [2, 1.83, 180.54]], "batl": [[0, 1.92, 190.83], [1, 1.93, 990.94], [2, 1.94, 1114.78]]}, {"timestamp": 1631532763176, "ltp": 1.92, "tv": 10606.54, "trd": NaN, "batb": [[0, 1.86, 118.23]], "batl": [[0, 1.91, 40.24], [1, 1.92, 190.83], [2, 1.93, 990.94]]}, {"timestamp": 1631532771402, "ltp": 1.92, "tv": 10606.54, "trd": NaN, "batb": [[0, 1.82, 82.43], [1, 1.8, 4.96], [2, 1.58, 422.21]], "batl": [[0, 1.98, 3.24], [1, 2.18, 4], [2, 2.5, 278.33]]}, {"timestamp": 1631532772233, "ltp": 1.92, "tv": 10606.54, "trd": NaN, "batb": [[0, 1.92, 26.03], [1, 1.82, 82.43], [2, 1.8, 4.96]], "batl": NaN}, {"timestamp": 1631532774628, "ltp": 1.92, "tv": 10606.54, "trd": NaN, "batb": [[1, 1.86, 4], [2, 1.85, 4]], "batl": [[0, 1.98, 151.25], [1, 2, 139.48], [2, 2.18, 4]]}, {"timestamp": 1631532783526, "ltp": 1.92, "tv": 10606.54, "trd": NaN, "batb": NaN, "batl": [[0, 1.97, 2.32], [1, 1.98, 151.25], [2, 2, 139.48]]}, {"timestamp": 1631532784408, "ltp": 1.92, "tv": 10606.54, "trd": NaN, "batb": [[1, 1.91, 136.56], [2, 1.89, 162.68]], "batl": NaN}, {"timestamp": 1631532785133, "ltp": 1.92, "tv": 10606.54, "trd": NaN, "batb": [[0, 1.93, 68.87], [1, 1.92, 26.03], [2, 1.91, 136.56]], "batl": NaN}, {"timestamp": 1631532790032, "ltp": 1.92, "tv": 10606.54, "trd": NaN, "batb": [[0, 1.93, 134.78]], "batl": [[0, 1.97, 66.89]]}, {"timestamp": 1631532794644, "ltp": 1.92, "tv": 10606.54, "trd": NaN, "batb": NaN, "batl": [[0, 1.97, 64.57]]}, {"timestamp": 1631532796163, "ltp": 1.92, "tv": 10606.54, "trd": NaN, "batb": [[0, 1.92, 26.03], [1, 1.87, 186.47], [2, 1.86, 122.66]], "batl": [[0, 1.98, 3.24], [1, 2.04, 8.38], [2, 2.06, 113.49]]}, {"timestamp": 1631532798027, "ltp": 1.92, "tv": 10606.54, "trd": NaN, "batb": [[1, 1.9, 28.36], [2, 1.87, 186.47]], "batl": NaN}, {"timestamp": 1631532803674, "ltp": 1.92, "tv": 10606.54, "trd": NaN, "batb": [[0, 1.93, 115.52], [1, 1.92, 26.03], [2, 1.91, 157.34]], "batl": [[1, 2, 154.68], [2, 2.02, 135.38]]}, {"timestamp": 1631532808437, "ltp": 1.92, "tv": 10606.54, "trd": NaN, "batb": [[0, 1.92, 26.03], [1, 1.9, 28.36], [2, 1.87, 186.47]], "batl": [[1, 2.06, 113.49], [2, 2.08, 108.55]]}, {"timestamp": 1631532811651, "ltp": 1.92, "tv": 10606.54, "trd": NaN, "batb": NaN, "batl": [[1, 2.04, 8.38], [2, 2.06, 113.49]]}, {"timestamp": 1631532811859, "ltp": 1.92, "tv": 10606.54, "trd": NaN, "batb": NaN, "batl": [[1, 2.06, 113.49], [2, 2.08, 262.3]]}, {"timestamp": 1631532818566, "ltp": 1.92, "tv": 10606.54, "trd": NaN, "batb": NaN, "batl": [[1, 2.04, 8.88], [2, 2.06, 113.49]]}, {"timestamp": 1631532819289, "ltp": 1.92, "tv": 10606.54, "trd": NaN, "batb": [[2, 1.87, 75.98]], "batl": [[1, 2.06, 113.49], [2, 2.08, 108.55]]}, {"timestamp": 1631532820278, "ltp": 1.98, "tv": 10623.54, "trd": [[1.93, 510.44], [1.98, 722.92]], "batb": NaN, "batl": [[0, 2.06, 113.49], [1, 2.08, 108.55], [2, 2.1, 123.09]]}, {"timestamp": 1631532822660, "ltp": 1.98, "tv": 10623.54, "trd": NaN, "batb": [[0, 1.99, 982.57], [1, 1.98, 932.8], [2, 1.97, 932.8]], "batl": [[0, 2.08, 108.55], [1, 2.1, 123.09], [2, 2.18, 4]]}, {"timestamp": 1631532823591, "ltp": 1.98, "tv": 10623.54, "trd": NaN, "batb": [[0, 2.02, 119.08], [1, 1.99, 982.57], [2, 1.98, 932.8]], "batl": [[2, 2.14, 9.35]]}, {"timestamp": 1631532826457, "ltp": 1.98, "tv": 10623.54, "trd": NaN, "batb": [[0, 2.02, 174.84], [1, 2, 5], [2, 1.99, 986.57]], "batl": [[0, 2.06, 54.67], [1, 2.08, 108.55], [2, 2.1, 123.09]]}, {"timestamp": 1631532827186, "ltp": 1.98, "tv": 10623.54, "trd": NaN, "batb": [[0, 2.02, 119.08]], "batl": [[0, 2.08, 108.55], [1, 2.1, 123.09], [2, 2.14, 9.35]]}, {"timestamp": 1631532829562, "ltp": 1.98, "tv": 10623.54, "trd": NaN, "batb": NaN, "batl": [[0, 2.08, 109.55]]}, {"timestamp": 1631532835574, "ltp": 1.98, "tv": 10623.54, "trd": NaN, "batb": [[0, 1.93, 25.36], [1, 1.92, 95.99], [2, 1.9, 28.36]], "batl": [[0, 2.08, 1], [1, 2.24, 6.73], [2, 2.72, 244.88]]}, {"timestamp": 1631532836410, "ltp": 1.98, "tv": 10623.54, "trd": NaN, "batb": NaN, "batl": [[0, 2.02, 70.59], [1, 2.08, 1], [2, 2.24, 6.73]]}, {"timestamp": 1631532838693, "ltp": 1.98, "tv": 10623.54, "trd": NaN, "batb": NaN, "batl": [[2, 2.18, 7.75]]}, {"timestamp": 1631532839102, "ltp": 1.98, "tv": 10623.54, "trd": NaN, "batb": [[0, 1.93, 27.36], [1, 1.92, 97.99]], "batl": NaN}, {"timestamp": 1631532843693, "ltp": 1.98, "tv": 10623.54, "trd": NaN, "batb": [[2, 1.86, 4]], "batl": [[0, 2.08, 1], [1, 2.24, 6.73], [2, 2.72, 244.88]]}, {"timestamp": 1631532850622, "ltp": 1.98, "tv": 10623.54, "trd": NaN, "batb": [[1, 1.92, 95.99], [2, 1.8, 4.96]], "batl": NaN}, {"timestamp": 1631532854145, "ltp": 1.98, "tv": 10623.54, "trd": NaN, "batb": [[1, 1.92, 98.99]], "batl": NaN}, {"timestamp": 1631532857534, "ltp": 1.98, "tv": 10623.54, "trd": NaN, "batb": [[0, 1.93, 25.36], [1, 1.92, 95.99], [2, 1.87, 182.37]], "batl": [[0, 1.94, 133.53], [1, 1.96, 1124.05], [2, 1.97, 947.06]]}, {"timestamp": 1631532870470, "ltp": 1.94, "tv": 10683.03, "trd": [[1.94, 330.25]], "batb": [[2, 1.84, 571.67]], "batl": [[0, 1.94, 103.78]]}, {"timestamp": 1631532872567, "ltp": 1.94, "tv": 10683.03, "trd": NaN, "batb": NaN, "batl": [[0, 1.94, 247.78]]}, {"timestamp": 1631532873561, "ltp": 1.94, "tv": 10692.95, "trd": [[1.94, 340.17]], "batb": [[1, 1.92, 151.95], [2, 1.88, 114.19]], "batl": [[0, 1.94, 256.13], [1, 1.95, 55.09], [2, 1.96, 1124.05]]}, {"timestamp": 1631532877536, "ltp": 1.93, "tv": 10714.64, "trd": [[1.93, 532.12]], "batb": [[0, 1.93, 14.52]], "batl": NaN}, {"timestamp": 1631532878270, "ltp": 1.92, "tv": 10760.71, "trd": [[1.92, 72.69], [1.93, 561.16]], "batb": [[0, 1.92, 143.43], [1, 1.88, 114.19], [2, 1.86, 171.24]], "batl": [[0, 1.93, 6.66], [1, 1.94, 256.13], [2, 1.95, 55.09]]}, {"timestamp": 1631532878955, "ltp": 1.92, "tv": 10760.71, "trd": NaN, "batb": NaN, "batl": [[1, 1.94, 320.98]]}, {"timestamp": 1631532881246, "ltp": 1.92, "tv": 10760.71, "trd": NaN, "batb": [[1, 1.91, 73.29], [2, 1.88, 114.19]], "batl": NaN}, {"timestamp": 1631532889678, "ltp": 1.92, "tv": 10760.71, "trd": NaN, "batb": NaN, "batl": [[0, 1.94, 320.98], [1, 1.95, 55.09], [2, 1.96, 1124.05]]}, {"timestamp": 1631532891361, "ltp": 1.92, "tv": 10760.71, "trd": NaN, "batb": [[0, 1.92, 17.51], [1, 1.79, 221.72], [2, 1.78, 122.81]], "batl": [[0, 1.94, 144], [1, 2.02, 8.25], [2, 2.04, 82.23]]}, {"timestamp": 1631532892399, "ltp": 1.92, "tv": 10760.71, "trd": NaN, "batb": NaN, "batl": [[0, 2.04, 82.23], [1, 2.06, 110.06], [2, 2.08, 159.72]]}, {"timestamp": 1631532894654, "ltp": 1.92, "tv": 10760.71, "trd": NaN, "batb": [[1, 1.81, 31.29], [2, 1.79, 221.72]], "batl": [[1, 2.06, 266.45], [2, 2.08, 283.89]]}, {"timestamp": 1631532895578, "ltp": 1.92, "tv": 10760.71, "trd": NaN, "batb": [[1, 1.79, 221.72], [2, 1.78, 122.81]], "batl": [[0, 2.02, 8.75], [1, 2.04, 86.23], [2, 2.06, 266.45]]}, {"timestamp": 1631532896269, "ltp": 1.92, "tv": 10760.71, "trd": NaN, "batb": NaN, "batl": [[0, 2.04, 86.23], [1, 2.06, 110.06], [2, 2.08, 159.72]]}, {"timestamp": 1631532899337, "ltp": 1.92, "tv": 10796.81, "trd": [[1.92, 108.79]], "batb": [[0, 1.85, 180.56], [1, 1.83, 180.55], [2, 1.79, 221.72]], "batl": [[0, 1.92, 132.77], [1, 1.94, 152.98], [2, 2.04, 86.23]]}, {"timestamp": 1631532900557, "ltp": 1.92, "tv": 10796.81, "trd": NaN, "batb": NaN, "batl": [[2, 2.02, 52.08]]}, {"timestamp": 1631532902554, "ltp": 1.92, "tv": 10796.81, "trd": NaN, "batb": [[0, 1.86, 35.19], [1, 1.85, 180.56], [2, 1.83, 180.55]], "batl": [[2, 2.02, 59.83]]}, {"timestamp": 1631532903967, "ltp": 1.92, "tv": 10796.81, "trd": NaN, "batb": [[0, 1.86, 97.14]], "batl": [[0, 1.91, 94.6], [1, 1.92, 132.77], [2, 1.94, 152.98]]}, {"timestamp": 1631532905639, "ltp": 1.92, "tv": 10796.81, "trd": NaN, "batb": [[0, 1.87, 92.58], [1, 1.86, 97.14], [2, 1.85, 180.56]], "batl": NaN}, {"timestamp": 1631532906582, "ltp": 1.92, "tv": 10796.81, "trd": NaN, "batb": [[0, 1.79, 221.72], [1, 1.78, 122.81], [2, 1.77, 170.11]], "batl": [[0, 2.02, 52.08], [1, 2.04, 86.23], [2, 2.06, 110.06]]}, {"timestamp": 1631532907261, "ltp": 1.92, "tv": 10796.81, "trd": NaN, "batb": NaN, "batl": [[0, 2.04, 86.23], [1, 2.06, 110.06], [2, 2.08, 159.72]]}, {"timestamp": 1631532909666, "ltp": 1.92, "tv": 10796.81, "trd": NaN, "batb": [[0, 1.81, 4], [1, 1.8, 5], [2, 1.79, 221.72]], "batl": [[1, 2.06, 256.88], [2, 2.08, 283.88]]}, {"timestamp": 1631532910452, "ltp": 1.92, "tv": 10796.81, "trd": NaN, "batb": [[2, 1.79, 225.72]], "batl": NaN}, {"timestamp": 1631532915689, "ltp": 1.92, "tv": 10796.81, "trd": NaN, "batb": NaN, "batl": [[0, 2.04, 4], [1, 2.06, 155.57], [2, 2.08, 132.35]]}, {"timestamp": 1631532915850, "ltp": 1.92, "tv": 10796.81, "trd": NaN, "batb": NaN, "batl": [[1, 2.08, 1], [2, 2.5, 278.33]]}, {"timestamp": 1631532917170, "ltp": 1.92, "tv": 10796.81, "trd": NaN, "batb": [[0, 1.79, 221.72], [1, 1.78, 122.81], [2, 1.77, 313.13]], "batl": [[2, 2.5, 0]]}, {"timestamp": 1631532918573, "ltp": 1.92, "tv": 10796.81, "trd": NaN, "batb": NaN, "batl": [[0, 1.83, 1770.21], [1, 1.84, 2078.8], [2, 1.85, 2017.66]]}, {"timestamp": 1631532919566, "ltp": 1.92, "tv": 10796.81, "trd": NaN, "batb": [[0, 1.79, 86.36]], "batl": [[0, 1.83, 189.42], [1, 1.84, 1039.4], [2, 1.85, 1186.23]]}, {"timestamp": 1631532923577, "ltp": 1.92, "tv": 10796.81, "trd": NaN, "batb": [[0, 1.79, 174.95]], "batl": [[0, 1.83, 276.08]]}, {"timestamp": 1631532930582, "ltp": 1.92, "tv": 10796.81, "trd": NaN, "batb": NaN, "batl": [[0, 1.83, 259.38]]}, {"timestamp": 1631532933670, "ltp": 1.92, "tv": 10796.81, "trd": NaN, "batb": [[0, 1.8, 96.8], [1, 1.79, 174.95], [2, 1.78, 122.81]], "batl": [[0, 1.82, 95.73], [1, 1.83, 259.38], [2, 1.84, 1039.4]]}, {"timestamp": 1631532936693, "ltp": 1.92, "tv": 10796.81, "trd": NaN, "batb": [[0, 1.79, 86.36], [1, 1.78, 122.81], [2, 1.77, 313.13]], "batl": [[0, 1.83, 172.72], [1, 1.85, 177.41], [2, 1.92, 119.8]]}, {"timestamp": 1631532937210, "ltp": 1.92, "tv": 10796.81, "trd": NaN, "batb": [[0, 1.68, 118.71], [1, 1.67, 255.18], [2, 1.66, 174.27]], "batl": [[0, 1.92, 92.99], [1, 1.93, 106.01], [2, 1.94, 150.42]]}, {"timestamp": 1631532940620, "ltp": 1.92, "tv": 10796.81, "trd": NaN, "batb": [[0, 1.69, 5], [1, 1.68, 123.71], [2, 1.67, 260.18]], "batl": [[0, 1.79, 5.41], [1, 1.92, 92.99], [2, 1.93, 106.01]]}, {"timestamp": 1631532943431, "ltp": 1.79, "tv": 10804.3, "trd": [[1.79, 7.48]], "batb": NaN, "batl": [[0, 1.79, 1.67]]}, {"timestamp": 1631532944320, "ltp": 1.79, "tv": 10804.3, "trd": NaN, "batb": [[0, 1.7, 25], [1, 1.69, 5], [2, 1.68, 123.71]], "batl": NaN}, {"timestamp": 1631532945030, "ltp": 1.79, "tv": 10804.3, "trd": NaN, "batb": [[0, 1.75, 131.57], [1, 1.73, 217.84], [2, 1.69, 5]], "batl": [[1, 1.81, 202.06], [2, 1.83, 183.63]]}, {"timestamp": 1631532947639, "ltp": 1.79, "tv": 10804.3, "trd": NaN, "batb": [[0, 1.69, 37.21], [1, 1.68, 123.71], [2, 1.67, 260.18]], "batl": [[1, 1.92, 92.99], [2, 1.93, 106.01]]}, {"timestamp": 1631532948470, "ltp": 1.79, "tv": 10804.3, "trd": NaN, "batb": [[0, 1.69, 5]], "batl": NaN}, {"timestamp": 1631532950604, "ltp": 1.79, "tv": 10830.7, "trd": [[1.79, 33.89]], "batb": [[2, 1.67, 398.19]], "batl": [[0, 1.97, 25.83], [1, 2, 4], [2, 2.08, 1]]}, {"timestamp": 1631532952220, "ltp": 1.79, "tv": 10830.7, "trd": NaN, "batb": [[1, 1.68, 118.71], [2, 1.67, 393.19]], "batl": NaN}, {"timestamp": 1631532953431, "ltp": 1.79, "tv": 10830.7, "trd": NaN, "batb": [[0, 1.68, 118.71], [1, 1.67, 393.19], [2, 1.66, 300.96]], "batl": [[0, 1.72, 173.43], [1, 1.74, 216.74], [2, 1.75, 1092.86]]}, {"timestamp": 1631532956337, "ltp": 1.79, "tv": 10830.7, "trd": NaN, "batb": [[0, 1.68, 148.12]], "batl": NaN}, {"timestamp": 1631532957668, "ltp": 1.79, "tv": 10830.7, "trd": NaN, "batb": [[0, 1.68, 238.11]], "batl": [[0, 1.72, 261.33]]}, {"timestamp": 1631532963542, "ltp": 1.79, "tv": 10830.7, "trd": NaN, "batb": [[1, 1.67, 255.18], [2, 1.66, 174.27]], "batl": [[0, 1.75, 1092.86], [1, 1.76, 1060.72], [2, 1.77, 1060.72]]}, {"timestamp": 1631532964542, "ltp": 1.79, "tv": 10830.7, "trd": NaN, "batb": [[0, 1.68, 208.7]], "batl": NaN}, {"timestamp": 1631532966714, "ltp": 1.79, "tv": 10830.7, "trd": NaN, "batb": [[0, 1.69, 141.3], [1, 1.68, 208.7], [2, 1.67, 255.18]], "batl": [[0, 1.74, 137.24], [1, 1.75, 1092.86], [2, 1.76, 1060.72]]}, {"timestamp": 1631532968064, "ltp": 1.79, "tv": 10830.7, "trd": NaN, "batb": [[2, 1.67, 393.19]], "batl": [[0, 1.72, 173.43], [1, 1.74, 353.98], [2, 1.75, 1092.86]]}, {"timestamp": 1631532969627, "ltp": 1.79, "tv": 10830.7, "trd": NaN, "batb": [[0, 1.61, 36.09], [1, 1.59, 148.84], [2, 1.58, 140.89]], "batl": [[0, 1.8, 109.53], [1, 1.81, 185.6], [2, 1.82, 165.13]]}, {"timestamp": 1631532972653, "ltp": 1.71, "tv": 10837.77, "trd": [[1.71, 7.07]], "batb": [[1, 1.59, 288.57], [2, 1.58, 292.89]], "batl": [[1, 1.81, 387.36]]}, {"timestamp": 1631532973065, "ltp": 1.71, "tv": 10837.77, "trd": NaN, "batb": [[0, 1.59, 288.57], [1, 1.58, 292.89], [2, 1.57, 345.12]], "batl": NaN}, {"timestamp": 1631532975666, "ltp": 1.71, "tv": 10837.77, "trd": NaN, "batb": [[0, 1.61, 5], [1, 1.6, 5], [2, 1.59, 288.57]], "batl": NaN}, {"timestamp": 1631532976552, "ltp": 1.71, "tv": 10837.77, "trd": NaN, "batb": [[0, 1.62, 5], [1, 1.59, 294.57], [2, 1.58, 297.89]], "batl": NaN}, {"timestamp": 1631532983557, "ltp": 1.71, "tv": 10837.77, "trd": NaN, "batb": NaN, "batl": [[0, 1.81, 30.71], [1, 1.85, 27.5], [2, 1.86, 30.75]]}, {"timestamp": 1631532983765, "ltp": 1.71, "tv": 10837.77, "trd": NaN, "batb": NaN, "batl": [[0, 1.85, 27.5], [1, 1.86, 30.75], [2, 2.08, 1]]}, {"timestamp": 1631532986681, "ltp": 1.71, "tv": 10837.77, "trd": NaN, "batb": [[0, 1.59, 288.57], [1, 1.58, 297.89], [2, 1.57, 345.12]], "batl": [[0, 1.63, 135.15], [1, 1.64, 132.31], [2, 1.73, 11.56]]}, {"timestamp": 1631532989457, "ltp": 1.71, "tv": 10837.77, "trd": NaN, "batb": [[0, 1.59, 326.98]], "batl": NaN}, {"timestamp": 1631532991554, "ltp": 1.71, "tv": 10837.77, "trd": NaN, "batb": [[0, 1.59, 474.95]], "batl": [[0, 1.63, 279.49]]}, {"timestamp": 1631532992179, "ltp": 1.71, "tv": 10837.77, "trd": NaN, "batb": [[0, 1.6, 144.22], [1, 1.59, 474.95], [2, 1.58, 297.89]], "batl": NaN}, {"timestamp": 1631532993483, "ltp": 1.71, "tv": 10837.77, "trd": NaN, "batb": NaN, "batl": [[2, 1.68, 180.04]]}, {"timestamp": 1631532994059, "ltp": 1.71, "tv": 10837.77, "trd": NaN, "batb": NaN, "batl": [[0, 1.63, 481.49]]}, {"timestamp": 1631532995361, "ltp": 1.6, "tv": 10887.77, "trd": [[1.6, 50]], "batb": [[0, 1.6, 119.22]], "batl": NaN}, {"timestamp": 1631532996448, "ltp": 1.59, "tv": 11439.96, "trd": [[1.59, 301.24], [1.6, 300.95]], "batb": [[0, 1.59, 324.33], [1, 1.58, 297.89], [2, 1.57, 345.12]], "batl": [[0, 1.63, 279.49]]}, {"timestamp": 1631532998482, "ltp": 1.59, "tv": 11439.96, "trd": NaN, "batb": NaN, "batl": [[0, 1.6, 33.19], [1, 1.62, 140.94], [2, 1.63, 279.49]]}, {"timestamp": 1631532998853, "ltp": 1.59, "tv": 11439.96, "trd": NaN, "batb": NaN, "batl": [[0, 1.6, 30.21], [2, 1.63, 429.4]]}, {"timestamp": 1631533001670, "ltp": 1.59, "tv": 11439.96, "trd": NaN, "batb": NaN, "batl": [[1, 1.61, 131.57], [2, 1.62, 140.94]]}, {"timestamp": 1631533004685, "ltp": 1.59, "tv": 11439.96, "trd": NaN, "batb": NaN, "batl": [[0, 1.6, 313.21], [2, 1.62, 320.67]]}, {"timestamp": 1631533006203, "ltp": 1.59, "tv": 11439.96, "trd": NaN, "batb": NaN, "batl": [[0, 1.6, 283]]}, {"timestamp": 1631533007403, "ltp": 1.59, "tv": 11439.96, "trd": NaN, "batb": [[0, 1.54, 167.59], [1, 1.53, 133.25], [2, 1.52, 213.98]], "batl": [[1, 1.68, 180.04], [2, 1.69, 161.31]]}, {"timestamp": 1631533008395, "ltp": 1.59, "tv": 11439.96, "trd": NaN, "batb": NaN, "batl": [[0, 1.68, 138.9], [1, 1.69, 161.31], [2, 1.7, 164.72]]}, {"timestamp": 1631533011887, "ltp": 1.59, "tv": 11439.96, "trd": NaN, "batb": [[0, 1.6, 2.32], [1, 1.54, 167.59], [2, 1.53, 133.25]], "batl": NaN}, {"timestamp": 1631533013503, "ltp": 1.59, "tv": 11439.96, "trd": NaN, "batb": [[1, 1.58, 137.02], [2, 1.57, 155.71]], "batl": [[0, 1.62, 148.92], [1, 1.63, 135.2], [2, 1.68, 138.9]]}, {"timestamp": 1631533014593, "ltp": 1.59, "tv": 11439.96, "trd": NaN, "batb": NaN, "batl": [[2, 1.67, 51.14]]}, {"timestamp": 1631533016686, "ltp": 1.59, "tv": 11439.96, "trd": NaN, "batb": [[1, 1.54, 167.59], [2, 1.53, 133.25]], "batl": [[0, 1.68, 138.9], [1, 1.69, 161.31], [2, 1.7, 164.72]]}, {"timestamp": 1631533019717, "ltp": 1.59, "tv": 11439.96, "trd": NaN, "batb": [[1, 1.54, 306.59], [2, 1.53, 305.42]], "batl": [[0, 1.67, 105.26], [1, 1.69, 224.81], [2, 1.71, 269.15]]}, {"timestamp": 1631533020400, "ltp": 1.59, "tv": 11439.96, "trd": NaN, "batb": [[0, 1.54, 306.59], [1, 1.53, 305.42], [2, 1.52, 164.74]], "batl": [[0, 1.59, 21.1], [1, 1.72, 37.66], [2, 1.84, 4]]}, {"timestamp": 1631533022630, "ltp": 1.59, "tv": 11439.96, "trd": NaN, "batb": NaN, "batl": [[0, 1.58, 2867.41], [1, 1.59, 21.1], [2, 1.6, 2390.62]]}, {"timestamp": 1631533023630, "ltp": 1.59, "tv": 11439.96, "trd": NaN, "batb": NaN, "batl": [[0, 1.58, 223.44], [1, 1.59, 168.93], [2, 1.6, 1195.32]]}, {"timestamp": 1631533024512, "ltp": 1.59, "tv": 11439.96, "trd": NaN, "batb": [[0, 1.54, 163.41]], "batl": NaN}, {"timestamp": 1631533026136, "ltp": 1.59, "tv": 11439.96, "trd": NaN, "batb": NaN, "batl": [[1, 1.59, 147.83]]}, {"timestamp": 1631533027714, "ltp": 1.59, "tv": 11439.96, "trd": NaN, "batb": [[1, 1.53, 433.77], [2, 1.52, 342.34]], "batl": [[0, 1.57, 111.96], [1, 1.58, 223.44], [2, 1.59, 147.83]]}, {"timestamp": 1631533028499, "ltp": 1.59, "tv": 11439.96, "trd": NaN, "batb": NaN, "batl": [[0, 1.57, 172.96]]}, {"timestamp": 1631533032414, "ltp": 1.57, "tv": 11505.21, "trd": [[1.57, 65.24]], "batb": NaN, "batl": [[0, 1.57, 140.34]]}, {"timestamp": 1631533033556, "ltp": 1.57, "tv": 11535.21, "trd": [[1.57, 95.24]], "batb": NaN, "batl": [[0, 1.57, 125.34]]}, {"timestamp": 1631533034652, "ltp": 1.57, "tv": 11535.21, "trd": NaN, "batb": NaN, "batl": [[1, 1.58, 196.39]]}, {"timestamp": 1631533035643, "ltp": 1.57, "tv": 11535.21, "trd": NaN, "batb": [[0, 1.54, 198.89]], "batl": NaN}, {"timestamp": 1631533037152, "ltp": 1.57, "tv": 11535.21, "trd": NaN, "batb": [[0, 1.55, 50.45], [1, 1.54, 198.89], [2, 1.53, 433.77]], "batl": NaN}, {"timestamp": 1631533044665, "ltp": 1.57, "tv": 11555.21, "trd": [[1.57, 115.24]], "batb": NaN, "batl": [[0, 1.57, 115.34]]}, {"timestamp": 1631533055963, "ltp": 1.55, "tv": 11555.37, "trd": [[1.55, 0.16]], "batb": [[0, 1.55, 50.37]], "batl": NaN}, {"timestamp": 1631533058771, "ltp": 1.57, "tv": 11575.37, "trd": [[1.57, 135.24]], "batb": NaN, "batl": [[0, 1.57, 105.34]]}, {"timestamp": 1631533070581, "ltp": 1.55, "tv": 11676.1, "trd": [[1.55, 100.9]], "batb": [[0, 1.54, 163.41], [1, 1.53, 433.77], [2, 1.52, 342.34]], "batl": [[0, 1.55, 34.81], [1, 1.57, 105.34], [2, 1.58, 196.39]]}, {"timestamp": 1631533073392, "ltp": 1.55, "tv": 11676.1, "trd": NaN, "batb": NaN, "batl": [[1, 1.56, 67.71], [2, 1.57, 105.34]]}, {"timestamp": 1631533078209, "ltp": 1.55, "tv": 11676.1, "trd": NaN, "batb": NaN, "batl": [[2, 1.57, 44.34]]}, {"timestamp": 1631533081708, "ltp": 1.54, "tv": 11677.3, "trd": [[1.54, 1.2]], "batb": [[0, 1.54, 162.81]], "batl": [[0, 1.55, 487.81]]}, {"timestamp": 1631533084510, "ltp": 1.55, "tv": 11680.7, "trd": [[1.55, 104.3]], "batb": [[0, 1.54, 37.44]], "batl": [[0, 1.55, 564.72]]}, {"timestamp": 1631533089089, "ltp": 1.55, "tv": 11680.7, "trd": NaN, "batb": NaN, "batl": [[0, 1.55, 761.48]]}, {"timestamp": 1631533090331, "ltp": 1.55, "tv": 11680.7, "trd": NaN, "batb": NaN, "batl": [[0, 1.55, 922.47]]}, {"timestamp": 1631533093511, "ltp": 1.55, "tv": 11680.7, "trd": NaN, "batb": [[1, 1.53, 459.56]], "batl": NaN}, {"timestamp": 1631533107926, "ltp": 1.55, "tv": 11683.31, "trd": [[1.55, 106.91]], "batb": NaN, "batl": [[0, 1.55, 921.17]]}, {"timestamp": 1631533119255, "ltp": 1.55, "tv": 11683.31, "trd": NaN, "batb": [[0, 1.53, 459.56], [1, 1.52, 342.34], [2, 1.51, 206.07]], "batl": NaN}, {"timestamp": 1631533127282, "ltp": 1.55, "tv": 11723.58, "trd": [[1.55, 147.18]], "batb": NaN, "batl": [[0, 1.55, 901.03]]}, {"timestamp": 1631533132785, "ltp": 1.55, "tv": 11723.58, "trd": NaN, "batb": [[0, 1.53, 502.23]], "batl": NaN}, {"timestamp": 1631533142568, "ltp": 1.55, "tv": 11723.58, "trd": NaN, "batb": [[0, 1.53, 459.56]], "batl": NaN}, {"timestamp": 1631533143715, "ltp": 1.55, "tv": 11723.58, "trd": NaN, "batb": [[0, 1.51, 160.08], [1, 1.5, 44.62], [2, 1.49, 138.48]], "batl": [[0, 1.55, 464.67], [1, 1.66, 144.21], [2, 1.67, 153.17]]}, {"timestamp": 1631533144208, "ltp": 1.55, "tv": 11723.58, "trd": NaN, "batb": [[0, 1.49, 138.48], [1, 1.48, 241.8], [2, 1.47, 173.92]], "batl": [[0, 1.55, 11.67]]}, {"timestamp": 1631533146592, "ltp": 1.55, "tv": 11723.58, "trd": NaN, "batb": [[1, 1.48, 383.99], [2, 1.47, 376.67]], "batl": [[1, 1.66, 277.17], [2, 1.67, 277.32]]}, {"timestamp": 1631533147682, "ltp": 1.55, "tv": 11723.58, "trd": NaN, "batb": [[0, 1.5, 5], [1, 1.49, 145.48], [2, 1.48, 246.8]], "batl": [[0, 1.55, 11.75], [1, 1.66, 144.21], [2, 1.67, 153.17]]}, {"timestamp": 1631533151590, "ltp": 1.55, "tv": 11747.08, "trd": [[1.53, 0.16], [1.55, 170.52]], "batb": [[0, 1.55, 199.81], [1, 1.54, 168.2], [2, 1.5, 53.7]], "batl": [[0, 1.6, 258.15], [1, 1.61, 141.01], [2, 1.66, 144.21]]}, {"timestamp": 1631533153415, "ltp": 1.55, "tv": 11941.08, "trd": [[1.55, 364.52]], "batb": [[0, 1.55, 102.81]], "batl": NaN}, {"timestamp": 1631533154413, "ltp": 1.55, "tv": 11941.08, "trd": NaN, "batb": [[0, 1.56, 187.63], [1, 1.5, 5], [2, 1.49, 145.48]], "batl": [[0, 1.59, 217.28], [1, 1.66, 144.21], [2, 1.67, 153.17]]}, {"timestamp": 1631533155021, "ltp": 1.55, "tv": 11941.08, "trd": NaN, "batb": [[0, 1.5, 5], [1, 1.49, 145.48], [2, 1.48, 246.8]], "batl": [[0, 1.66, 144.21], [1, 1.67, 153.17], [2, 1.68, 170.78]]}, {"timestamp": 1631533156583, "ltp": 1.55, "tv": 11941.08, "trd": NaN, "batb": NaN, "batl": [[0, 1.66, 283.22], [1, 1.67, 277.33]]}, {"timestamp": 1631533158194, "ltp": 1.55, "tv": 11941.08, "trd": NaN, "batb": [[1, 1.49, 138.48]], "batl": [[0, 1.66, 333.2]]}, {"timestamp": 1631533159614, "ltp": 1.55, "tv": 11941.08, "trd": NaN, "batb": [[1, 1.48, 55.76], [2, 1.47, 282.35]], "batl": NaN}, {"timestamp": 1631533159924, "ltp": 1.55, "tv": 11941.08, "trd": NaN, "batb": [[1, 1.48, 50.76], [2, 1.46, 184.85]], "batl": NaN}, {"timestamp": 1631533161399, "ltp": 1.55, "tv": 11941.08, "trd": NaN, "batb": [[1, 1.49, 6], [2, 1.48, 50.76]], "batl": NaN}, {"timestamp": 1631533162703, "ltp": 1.55, "tv": 11941.08, "trd": NaN, "batb": [[0, 1.61, 194.78], [1, 1.6, 145.42], [2, 1.59, 10.11]], "batl": NaN}, {"timestamp": 1631533163634, "ltp": 1.55, "tv": 11941.08, "trd": NaN, "batb": [[1, 1.6, 274.96]], "batl": NaN}, {"timestamp": 1631533167527, "ltp": 1.55, "tv": 11941.08, "trd": NaN, "batb": [[0, 1.62, 162.54], [1, 1.61, 194.78], [2, 1.6, 274.96]], "batl": [[0, 1.65, 196.55], [1, 1.66, 333.2], [2, 1.67, 277.33]]}, {"timestamp": 1631533170025, "ltp": 1.55, "tv": 11941.08, "trd": NaN, "batb": NaN, "batl": [[0, 1.65, 317.55]]}, {"timestamp": 1631533172337, "ltp": 1.55, "tv": 11941.08, "trd": NaN, "batb": [[0, 1.62, 194.02]], "batl": NaN}, {"timestamp": 1631533173639, "ltp": 1.55, "tv": 11941.08, "trd": NaN, "batb": [[0, 1.62, 162.54], [1, 1.57, 47.57], [2, 1.56, 111.14]], "batl": [[1, 1.75, 32.46], [2, 1.76, 131.14]]}, {"timestamp": 1631533174528, "ltp": 1.55, "tv": 11941.08, "trd": NaN, "batb": [[0, 1.56, 111.14], [1, 1.55, 183.8], [2, 1.54, 178.49]], "batl": [[0, 1.76, 131.14], [1, 1.77, 159.1], [2, 1.78, 151.13]]}, {"timestamp": 1631533176713, "ltp": 1.55, "tv": 11941.08, "trd": NaN, "batb": [[2, 1.54, 367.07]], "batl": [[0, 1.76, 299.5], [2, 1.78, 352.48]]}, {"timestamp": 1631533177708, "ltp": 1.55, "tv": 11941.08, "trd": NaN, "batb": [[0, 1.56, 118.14], [1, 1.55, 189.8]], "batl": [[0, 1.75, 37.1], [1, 1.76, 304.5], [2, 1.77, 159.1]]}, {"timestamp": 1631533178065, "ltp": 1.55, "tv": 11941.08, "trd": NaN, "batb": [[2, 1.54, 178.49]], "batl": [[0, 1.75, 5], [1, 1.76, 136.14]]}, {"timestamp": 1631533180822, "ltp": 1.55, "tv": 11941.08, "trd": NaN, "batb": [[0, 1.61, 194.78], [1, 1.6, 145.42], [2, 1.56, 118.14]], "batl": [[0, 1.66, 188.99], [1, 1.67, 124.19], [2, 1.75, 5]]}, {"timestamp": 1631533184052, "ltp": 1.55, "tv": 11941.08, "trd": NaN, "batb": [[0, 1.62, 89.73], [1, 1.61, 194.78], [2, 1.6, 145.42]], "batl": [[0, 1.65, 145.09], [1, 1.66, 188.99], [2, 1.67, 124.19]]}, {"timestamp": 1631533188531, "ltp": 1.55, "tv": 11941.08, "trd": NaN, "batb": [[0, 1.56, 118.14], [1, 1.55, 183.8], [2, 1.54, 178.49]], "batl": [[0, 1.75, 5], [1, 1.76, 136.14], [2, 1.77, 159.1]]}, {"timestamp": 1631533190138, "ltp": 1.55, "tv": 11941.08, "trd": NaN, "batb": NaN, "batl": [[1, 1.76, 131.14]]}, {"timestamp": 1631533191647, "ltp": 1.55, "tv": 11941.08, "trd": NaN, "batb": [[1, 1.55, 188.8], [2, 1.54, 367.07]], "batl": [[0, 1.62, 84.71], [1, 1.75, 5], [2, 1.76, 299.5]]}, {"timestamp": 1631533194377, "ltp": 1.55, "tv": 11941.08, "trd": NaN, "batb": NaN, "batl": [[0, 1.75, 5], [1, 1.76, 299.5], [2, 1.77, 159.1]]}, {"timestamp": 1631533197660, "ltp": 1.55, "tv": 11941.08, "trd": NaN, "batb": NaN, "batl": [[1, 1.8, 29.17], [2, 2.04, 388.3]]}, {"timestamp": 1631533199433, "ltp": 1.55, "tv": 11941.08, "trd": NaN, "batb": [[0, 1.56, 111.14], [1, 1.55, 183.8]], "batl": [[2, 2.08, 1]]}, {"timestamp": 1631533200643, "ltp": 1.55, "tv": 11941.08, "trd": NaN, "batb": [[0, 1.54, 367.07], [1, 1.53, 221.09], [2, 1.52, 154.39]], "batl": [[0, 1.58, 150.25], [1, 1.59, 148.33], [2, 1.69, 11.83]]}, {"timestamp": 1631533202368, "ltp": 1.55, "tv": 11941.08, "trd": NaN, "batb": [[0, 1.54, 372.07], [1, 1.53, 225.09]], "batl": NaN}, {"timestamp": 1631533203484, "ltp": 1.55, "tv": 11941.08, "trd": NaN, "batb": [[0, 1.55, 31.36], [1, 1.54, 372.07], [2, 1.53, 225.09]], "batl": [[2, 1.68, 5]]}, {"timestamp": 1631533203959, "ltp": 1.57, "tv": 11943.25, "trd": [[1.57, 137.41]], "batb": NaN, "batl": NaN}, {"timestamp": 1631533205462, "ltp": 1.57, "tv": 11953.83, "trd": [[1.57, 147.99]], "batb": [[0, 1.55, 103.21]], "batl": [[0, 1.57, 126.3], [1, 1.58, 150.25], [2, 1.59, 148.33]]}, {"timestamp": 1631533206361, "ltp": 1.57, "tv": 11953.83, "trd": NaN, "batb": NaN, "batl": [[1, 1.58, 435.69]]}, {"timestamp": 1631533211980, "ltp": 1.57, "tv": 11958.15, "trd": [[1.57, 152.31]], "batb": NaN, "batl": [[0, 1.57, 124.14]]}, {"timestamp": 1631533215266, "ltp": 1.55, "tv": 12099.33, "trd": [[1.55, 505.7]], "batb": [[0, 1.55, 32.62], [2, 1.53, 221.09]], "batl": NaN}, {"timestamp": 1631533218696, "ltp": 1.55, "tv": 12099.33, "trd": NaN, "batb": [[1, 1.54, 193.58], [2, 1.53, 226.09]], "batl": NaN}, {"timestamp": 1631533219174, "ltp": 1.55, "tv": 12099.33, "trd": NaN, "batb": [[0, 1.49, 162.54], [1, 1.48, 146.29], [2, 1.47, 221.26]], "batl": [[0, 1.68, 106.1], [1, 1.69, 154.56], [2, 1.7, 147.96]]}, {"timestamp": 1631533222389, "ltp": 1.55, "tv": 12099.33, "trd": NaN, "batb": [[0, 1.49, 168.54], [1, 1.48, 152.29], [2, 1.47, 470.75]], "batl": [[0, 1.68, 278.7], [2, 1.7, 382.98]]}, {"timestamp": 1631533226295, "ltp": 1.55, "tv": 12099.33, "trd": NaN, "batb": NaN, "batl": [[0, 1.68, 5], [1, 1.8, 29.17], [2, 2.08, 1]]}, {"timestamp": 1631533227497, "ltp": 1.55, "tv": 12099.33, "trd": NaN, "batb": [[0, 1.48, 146.29], [1, 1.47, 470.75], [2, 1.46, 392.15]], "batl": NaN}, {"timestamp": 1631533229482, "ltp": 1.55, "tv": 12099.33, "trd": NaN, "batb": [[0, 1.47, 470.75], [1, 1.46, 392.15], [2, 1.29, 3.45]], "batl": [[0, 1.5, 2.17], [1, 1.51, 202.87], [2, 1.52, 1434.06]]}, {"timestamp": 1631533230513, "ltp": 1.51, "tv": 12112.71, "trd": [[1.5, 2.17], [1.51, 11.21]], "batb": [[2, 1.41, 213.22]], "batl": [[0, 1.51, 191.66], [1, 1.52, 1434.06], [2, 1.53, 1221.22]]}, {"timestamp": 1631533233402, "ltp": 1.51, "tv": 12112.71, "trd": NaN, "batb": [[0, 1.47, 506.23]], "batl": [[0, 1.51, 325.2]]}, {"timestamp": 1631533236603, "ltp": 1.51, "tv": 12112.71, "trd": NaN, "batb": [[0, 1.48, 35.82], [1, 1.47, 506.23], [2, 1.46, 392.15]], "batl": [[0, 1.5, 133.76], [1, 1.51, 325.2], [2, 1.52, 1434.06]]}, {"timestamp": 1631533238315, "ltp": 1.51, "tv": 12112.71, "trd": NaN, "batb": [[1, 1.47, 548.6]], "batl": NaN}, {"timestamp": 1631533240200, "ltp": 1.51, "tv": 12112.71, "trd": NaN, "batb": [[0, 1.43, 171.77], [1, 1.42, 214], [2, 1.41, 401.42]], "batl": [[0, 1.58, 114.58], [1, 1.59, 170.32], [2, 1.6, 149.68]]}, {"timestamp": 1631533241441, "ltp": 1.51, "tv": 12112.71, "trd": NaN, "batb": [[0, 1.43, 234.2]], "batl": [[2, 1.6, 190.64]]}, {"timestamp": 1631533242692, "ltp": 1.51, "tv": 12112.71, "trd": NaN, "batb": [[0, 1.5, 2], [1, 1.43, 234.2], [2, 1.42, 214]], "batl": NaN}, {"timestamp": 1631533243514, "ltp": 1.5, "tv": 12116.71, "trd": [[1.5, 6.17]], "batb": [[0, 1.44, 7], [1, 1.43, 242.2], [2, 1.42, 221]], "batl": [[1, 1.59, 334.22], [2, 1.6, 335.5]]}, {"timestamp": 1631533244715, "ltp": 1.5, "tv": 12116.71, "trd": NaN, "batb": [[0, 1.45, 7], [1, 1.44, 7], [2, 1.43, 242.2]], "batl": [[0, 1.56, 45.67], [1, 1.58, 114.58], [2, 1.59, 170.32]]}, {"timestamp": 1631533245018, "ltp": 1.5, "tv": 12116.71, "trd": NaN, "batb": NaN, "batl": [[0, 1.58, 114.58], [1, 1.59, 170.32], [2, 1.6, 190.64]]}, {"timestamp": 1631533247625, "ltp": 1.5, "tv": 12116.71, "trd": NaN, "batb": [[0, 1.49, 142.41], [1, 1.48, 197.41], [2, 1.46, 35]], "batl": [[0, 1.53, 269.24], [1, 1.54, 166.72], [2, 1.57, 61.86]]}, {"timestamp": 1631533248621, "ltp": 1.53, "tv": 12121.05, "trd": [[1.53, 4.5]], "batb": [[2, 1.45, 7]], "batl": [[0, 1.53, 267.07], [2, 1.56, 43.42]]}, {"timestamp": 1631533250644, "ltp": 1.53, "tv": 12121.05, "trd": NaN, "batb": [[0, 1.45, 7], [1, 1.44, 7], [2, 1.43, 242.2]], "batl": [[0, 1.58, 114.58], [1, 1.59, 170.32], [2, 1.6, 190.64]]}, {"timestamp": 1631533253230, "ltp": 1.53, "tv": 12121.05, "trd": NaN, "batb": NaN, "batl": [[1, 1.59, 333.07], [2, 1.6, 335.5]]}, {"timestamp": 1631533257539, "ltp": 1.53, "tv": 12121.05, "trd": NaN, "batb": [[1, 1.44, 55.67], [2, 1.43, 234.2]], "batl": [[0, 1.56, 43.67], [1, 1.58, 114.58], [2, 1.59, 333.07]]}, {"timestamp": 1631533257746, "ltp": 1.53, "tv": 12121.05, "trd": NaN, "batb": [[1, 1.43, 234.2], [2, 1.42, 214]], "batl": [[0, 1.58, 114.58], [1, 1.59, 333.07], [2, 1.6, 335.5]]}, {"timestamp": 1631533259043, "ltp": 1.53, "tv": 12121.05, "trd": NaN, "batb": [[0, 1.56, 2.17], [1, 1.45, 7], [2, 1.43, 234.2]], "batl": NaN}, {"timestamp": 1631533261444, "ltp": 1.56, "tv": 12125.39, "trd": [[1.56, 4.34]], "batb": [[0, 1.45, 7], [1, 1.44, 6], [2, 1.43, 62.43]], "batl": NaN}, {"timestamp": 1631533264567, "ltp": 1.56, "tv": 12125.39, "trd": NaN, "batb": [[0, 1.55, 161.59], [1, 1.54, 179.83], [2, 1.45, 7]], "batl": [[0, 1.58, 4]]}, {"timestamp": 1631533265348, "ltp": 1.56, "tv": 12125.39, "trd": NaN, "batb": [[1, 1.54, 328.53], [2, 1.46, 184.1]], "batl": [[0, 1.59, 333.07], [1, 1.6, 335.5], [2, 1.67, 6]]}, {"timestamp": 1631533267352, "ltp": 1.56, "tv": 12125.39, "trd": NaN, "batb": [[2, 1.53, 5]], "batl": NaN}, {"timestamp": 1631533269680, "ltp": 1.56, "tv": 12125.39, "trd": NaN, "batb": [[0, 1.55, 250.66]], "batl": [[0, 1.59, 470.99]]}, {"timestamp": 1631533273158, "ltp": 1.55, "tv": 12129.8, "trd": [[1.55, 510.12]], "batb": [[0, 1.55, 248.45]], "batl": NaN}, {"timestamp": 1631533275388, "ltp": 1.59, "tv": 12155.83, "trd": [[1.59, 327.27]], "batb": NaN, "batl": [[0, 1.59, 457.97]]}, {"timestamp": 1631533278613, "ltp": 1.59, "tv": 12155.83, "trd": NaN, "batb": [[0, 1.56, 44.6], [1, 1.55, 248.45], [2, 1.54, 328.53]], "batl": NaN}, {"timestamp": 1631533281532, "ltp": 1.59, "tv": 12155.83, "trd": NaN, "batb": [[0, 1.46, 184.1], [1, 1.43, 62.43], [2, 1.41, 63.89]], "batl": [[0, 1.78, 30.75], [1, 1.8, 29.17], [2, 2.08, 1]]}, {"timestamp": 1631533284701, "ltp": 1.59, "tv": 12155.83, "trd": NaN, "batb": [[0, 1.48, 59.76], [1, 1.47, 5], [2, 1.46, 477.72]], "batl": [[0, 1.71, 36.81], [1, 1.72, 216.01], [2, 1.74, 216.97]]}, {"timestamp": 1631533285324, "ltp": 1.59, "tv": 12155.83, "trd": NaN, "batb": [[0, 1.48, 5], [2, 1.46, 191.1]], "batl": [[0, 1.71, 5], [1, 1.72, 5], [2, 1.75, 5]]}, {"timestamp": 1631533288547, "ltp": 1.53, "tv": 12158.0, "trd": [[1.53, 6.67]], "batb": [[0, 1.57, 187.87], [1, 1.56, 160.07], [2, 1.48, 52.51]], "batl": [[0, 1.62, 250.69], [1, 1.63, 135.1], [2, 1.71, 5]]}, {"timestamp": 1631533290627, "ltp": 1.53, "tv": 12158.0, "trd": NaN, "batb": [[2, 1.49, 25]], "batl": [[2, 1.7, 25]]}, {"timestamp": 1631533290944, "ltp": 1.53, "tv": 12158.0, "trd": NaN, "batb": [[2, 1.48, 52.51]], "batl": NaN}, {"timestamp": 1631533292352, "ltp": 1.53, "tv": 12158.0, "trd": NaN, "batb": [[0, 1.48, 5], [1, 1.47, 5], [2, 1.46, 191.1]], "batl": [[0, 1.71, 5], [1, 1.72, 5], [2, 1.75, 5]]}, {"timestamp": 1631533295628, "ltp": 1.53, "tv": 12158.0, "trd": NaN, "batb": [[0, 1.48, 55.76], [2, 1.46, 477.72]], "batl": [[0, 1.71, 35.5], [1, 1.72, 216.01], [2, 1.74, 216.97]]}, {"timestamp": 1631533295938, "ltp": 1.53, "tv": 12158.0, "trd": NaN, "batb": [[0, 1.48, 5]], "batl": [[0, 1.71, 5]]}, {"timestamp": 1631533299438, "ltp": 1.53, "tv": 12158.0, "trd": NaN, "batb": [[1, 1.46, 470.72], [2, 1.45, 216.29]], "batl": [[1, 1.72, 211.01]]}, {"timestamp": 1631533302635, "ltp": 1.53, "tv": 12158.0, "trd": NaN, "batb": [[1, 1.47, 5], [2, 1.46, 470.72]], "batl": [[0, 1.49, 2.17], [1, 1.71, 5], [2, 1.72, 211.01]]}, {"timestamp": 1631533304251, "ltp": 1.53, "tv": 12158.0, "trd": NaN, "batb": NaN, "batl": [[0, 1.71, 5], [1, 1.72, 211.01], [2, 1.74, 216.97]]}, {"timestamp": 1631533305136, "ltp": 1.53, "tv": 12158.0, "trd": NaN, "batb": NaN, "batl": [[1, 1.78, 30.75], [2, 1.8, 29.17]]}, {"timestamp": 1631533306234, "ltp": 1.53, "tv": 12158.0, "trd": NaN, "batb": [[0, 1.48, 56.01]], "batl": [[0, 1.71, 40.5]]}, {"timestamp": 1631533307270, "ltp": 1.53, "tv": 12158.0, "trd": NaN, "batb": [[0, 1.48, 5]], "batl": [[0, 1.71, 5]]}, {"timestamp": 1631533308058, "ltp": 1.53, "tv": 12158.0, "trd": NaN, "batb": [[0, 1.46, 470.72], [1, 1.45, 216.29], [2, 1.43, 62.43]], "batl": [[0, 1.5, 187.79], [1, 1.51, 1447.1], [2, 1.52, 1229.32]]}, {"timestamp": 1631533309362, "ltp": 1.5, "tv": 12171.42, "trd": [[1.5, 19.59]], "batb": NaN, "batl": [[0, 1.5, 174.37]]}, {"timestamp": 1631533311140, "ltp": 1.5, "tv": 12171.42, "trd": NaN, "batb": [[0, 1.46, 518.01]], "batl": NaN}, {"timestamp": 1631533312546, "ltp": 1.5, "tv": 12171.42, "trd": NaN, "batb": [[0, 1.46, 550.24]], "batl": [[0, 1.5, 306.35]]}, {"timestamp": 1631533316454, "ltp": 1.5, "tv": 12173.62, "trd": [[1.5, 21.79]], "batb": NaN, "batl": [[0, 1.5, 304.15]]}, {"timestamp": 1631533319048, "ltp": 1.5, "tv": 12173.62, "trd": NaN, "batb": [[0, 1.47, 61.14], [1, 1.46, 550.24], [2, 1.45, 216.29]], "batl": NaN}, {"timestamp": 1631533322661, "ltp": 1.5, "tv": 12173.62, "trd": NaN, "batb": NaN, "batl": [[0, 1.49, 153.56], [1, 1.5, 362.15], [2, 1.51, 1447.1]]}, {"timestamp": 1631533326668, "ltp": 1.5, "tv": 12173.62, "trd": NaN, "batb": [[1, 1.46, 502.95]], "batl": [[2, 1.51, 180.54]]}, {"timestamp": 1631533327555, "ltp": 1.5, "tv": 12173.62, "trd": NaN, "batb": [[0, 1.41, 167.01], [1, 1.4, 503.97], [2, 1.39, 253.93]], "batl": [[0, 1.58, 131.96], [1, 1.59, 171.06], [2, 1.6, 251.19]]}, {"timestamp": 1631533328284, "ltp": 1.5, "tv": 12173.62, "trd": NaN, "batb": NaN, "batl": [[0, 1.47, 57.85], [1, 1.58, 131.96], [2, 1.59, 171.06]]}, {"timestamp": 1631533330687, "ltp": 1.5, "tv": 12173.62, "trd": NaN, "batb": [[0, 1.43, 7], [1, 1.42, 7], [2, 1.41, 175.01]], "batl": NaN}, {"timestamp": 1631533331002, "ltp": 1.5, "tv": 12173.62, "trd": NaN, "batb": NaN, "batl": [[0, 1.47, 1.38]]}, {"timestamp": 1631533331786, "ltp": 1.5, "tv": 12173.62, "trd": NaN, "batb": [[1, 1.42, 507]], "batl": NaN}, {"timestamp": 1631533337674, "ltp": 1.47, "tv": 12176.38, "trd": [[1.47, 2.76]], "batb": [[0, 1.43, 7.79]], "batl": [[0, 1.55, 41.9]]}, {"timestamp": 1631533338563, "ltp": 1.54, "tv": 12177.96, "trd": [[1.54, 2.77]], "batb": [[0, 1.48, 230.22], [1, 1.47, 203.6], [2, 1.43, 7]], "batl": [[0, 1.5, 20.52], [1, 1.52, 202.76], [2, 1.53, 171.29]]}, {"timestamp": 1631533338979, "ltp": 1.54, "tv": 12177.96, "trd": NaN, "batb": NaN, "batl": [[0, 1.52, 202.76], [1, 1.53, 171.29], [2, 1.58, 131.96]]}, {"timestamp": 1631533340592, "ltp": 1.54, "tv": 12177.96, "trd": NaN, "batb": NaN, "batl": [[2, 1.57, 70.62]]}, {"timestamp": 1631533341582, "ltp": 1.54, "tv": 12177.96, "trd": NaN, "batb": [[2, 1.43, 62.43]], "batl": [[2, 1.55, 45.3]]}, {"timestamp": 1631533343611, "ltp": 1.54, "tv": 12177.96, "trd": NaN, "batb": [[0, 1.49, 77.76], [1, 1.48, 272.05], [2, 1.47, 203.6]], "batl": [[0, 1.51, 163.92], [1, 1.52, 202.76], [2, 1.53, 171.29]]}, {"timestamp": 1631533344706, "ltp": 1.54, "tv": 12177.96, "trd": NaN, "batb": [[0, 1.43, 7], [1, 1.42, 500], [2, 1.41, 167.01]], "batl": [[0, 1.58, 131.96], [1, 1.59, 171.06], [2, 1.6, 251.19]]}, {"timestamp": 1631533346583, "ltp": 1.54, "tv": 12177.96, "trd": NaN, "batb": NaN, "batl": [[0, 1.51, 74], [1, 1.58, 131.96], [2, 1.59, 171.06]]}, {"timestamp": 1631533347412, "ltp": 1.54, "tv": 12177.96, "trd": NaN, "batb": [[1, 1.42, 506]], "batl": [[0, 1.58, 131.96], [1, 1.59, 171.06], [2, 1.6, 460.06]]}, {"timestamp": 1631533349593, "ltp": 1.54, "tv": 12177.96, "trd": NaN, "batb": [[2, 1.4, 305.22]], "batl": NaN}, {"timestamp": 1631533350381, "ltp": 1.54, "tv": 12177.96, "trd": NaN, "batb": [[0, 1.54, 2.17], [1, 1.43, 7], [2, 1.42, 506]], "batl": NaN}, {"timestamp": 1631533351484, "ltp": 1.54, "tv": 12177.96, "trd": NaN, "batb": [[1, 1.43, 67.43], [2, 1.42, 6]], "batl": [[0, 1.55, 45.7], [1, 1.58, 131.96], [2, 1.59, 171.06]]}, {"timestamp": 1631533352690, "ltp": 1.54, "tv": 12177.96, "trd": NaN, "batb": [[0, 1.55, 290.61], [1, 1.54, 170.8], [2, 1.53, 12.33]], "batl": [[0, 1.59, 171.06], [1, 1.6, 473.08], [2, 1.61, 141.38]]}, {"timestamp": 1631533353526, "ltp": 1.54, "tv": 12177.96, "trd": NaN, "batb": [[0, 1.55, 435.29], [1, 1.54, 168.63]], "batl": NaN}, {"timestamp": 1631533354679, "ltp": 1.54, "tv": 12177.96, "trd": NaN, "batb": [[0, 1.55, 440.29], [1, 1.54, 174.63]], "batl": NaN}, {"timestamp": 1631533357706, "ltp": 1.54, "tv": 12177.96, "trd": NaN, "batb": [[0, 1.56, 35.56], [1, 1.55, 501.5], [2, 1.54, 174.63]], "batl": [[0, 1.59, 317.23]]}, {"timestamp": 1631533359386, "ltp": 1.56, "tv": 12182.12, "trd": [[1.56, 8.5]], "batb": [[0, 1.56, 10.4]], "batl": NaN}, {"timestamp": 1631533360908, "ltp": 1.56, "tv": 12182.12, "trd": NaN, "batb": [[0, 1.57, 20.89], [1, 1.56, 68.01], [2, 1.55, 501.5]], "batl": NaN}, {"timestamp": 1631533363327, "ltp": 1.56, "tv": 12182.12, "trd": NaN, "batb": NaN, "batl": [[1, 1.6, 460.06]]}, {"timestamp": 1631533364318, "ltp": 1.56, "tv": 12182.12, "trd": NaN, "batb": [[2, 1.55, 475.42]], "batl": NaN}, {"timestamp": 1631533365207, "ltp": 1.59, "tv": 12186.77, "trd": [[1.59, 331.92]], "batb": NaN, "batl": [[0, 1.59, 314.91]]}, {"timestamp": 1631533367615, "ltp": 1.59, "tv": 12186.77, "trd": NaN, "batb": NaN, "batl": [[0, 1.59, 182.35], [1, 1.6, 253.93]]}, {"timestamp": 1631533368402, "ltp": 1.59, "tv": 12186.77, "trd": NaN, "batb": [[0, 1.47, 179.66], [1, 1.44, 6], [2, 1.43, 53.43]], "batl": [[0, 1.71, 5], [1, 1.79, 29.5], [2, 2.08, 1]]}, {"timestamp": 1631533371641, "ltp": 1.59, "tv": 12186.77, "trd": NaN, "batb": [[0, 1.48, 49.01], [1, 1.47, 366.31], [2, 1.46, 215.24]], "batl": [[1, 1.72, 157.01], [2, 1.74, 217.26]]}, {"timestamp": 1631533372015, "ltp": 1.59, "tv": 12186.77, "trd": NaN, "batb": [[0, 1.47, 366.31], [1, 1.46, 215.24], [2, 1.44, 6]], "batl": [[1, 1.72, 123.1]]}, {"timestamp": 1631533374517, "ltp": 1.59, "tv": 12186.77, "trd": NaN, "batb": NaN, "batl": [[1, 1.79, 29.5], [2, 2.08, 1]]}, {"timestamp": 1631533375612, "ltp": 1.59, "tv": 12186.77, "trd": NaN, "batb": [[0, 1.48, 500], [1, 1.47, 366.31], [2, 1.46, 215.24]], "batl": NaN}, {"timestamp": 1631533376231, "ltp": 1.48, "tv": 12191.11, "trd": [[1.48, 4.34]], "batb": [[0, 1.48, 497.83]], "batl": NaN}, {"timestamp": 1631533377640, "ltp": 1.48, "tv": 12191.11, "trd": NaN, "batb": [[1, 1.47, 361.31]], "batl": [[0, 1.51, 2411.06], [1, 1.52, 1433.58], [2, 1.53, 1221.22]]}, {"timestamp": 1631533378525, "ltp": 1.51, "tv": 12204.36, "trd": [[1.51, 24.46]], "batb": NaN, "batl": [[0, 1.51, 270.55]]}, {"timestamp": 1631533383646, "ltp": 1.51, "tv": 12204.36, "trd": NaN, "batb": NaN, "batl": [[0, 1.51, 397.45]]}, {"timestamp": 1631533385566, "ltp": 1.51, "tv": 12206.5, "trd": [[1.51, 26.6]], "batb": NaN, "batl": [[0, 1.51, 449.31]]}, {"timestamp": 1631533386344, "ltp": 1.48, "tv": 12306.5, "trd": [[1.48, 104.34]], "batb": [[0, 1.48, 447.83]], "batl": NaN}, {"timestamp": 1631533387649, "ltp": 1.48, "tv": 13202.16, "trd": [[1.48, 1000]], "batb": [[0, 1.47, 361.31], [1, 1.46, 215.24], [2, 1.43, 53.43]], "batl": [[0, 1.48, 46.29], [1, 1.51, 449.31], [2, 1.52, 1433.58]]}, {"timestamp": 1631533388636, "ltp": 1.48, "tv": 13294.74, "trd": [[1.48, 1092.58]], "batb": [[0, 1.48, 12.04], [1, 1.47, 361.31], [2, 1.46, 215.24]], "batl": [[0, 1.51, 395.31], [1, 1.52, 1433.58], [2, 1.53, 1221.22]]}, {"timestamp": 1631533389256, "ltp": 1.48, "tv": 13294.74, "trd": NaN, "batb": NaN, "batl": [[0, 1.51, 393.68]]}, {"timestamp": 1631533391450, "ltp": 1.48, "tv": 13318.82, "trd": [[1.48, 1116.66]], "batb": [[0, 1.47, 458.88], [1, 1.46, 215.24], [2, 1.43, 53.43]], "batl": [[0, 1.48, 245.96], [1, 1.49, 151.8], [2, 1.51, 393.68]]}, {"timestamp": 1631533391761, "ltp": 1.48, "tv": 13318.82, "trd": NaN, "batb": NaN, "batl": [[2, 1.5, 150.28]]}, {"timestamp": 1631533395671, "ltp": 1.48, "tv": 13318.82, "trd": NaN, "batb": [[0, 1.42, 66.94], [1, 1.41, 211.96], [2, 1.4, 62.46]], "batl": [[1, 1.54, 46.25], [2, 1.55, 39.1]]}, {"timestamp": 1631533396474, "ltp": 1.48, "tv": 13318.82, "trd": NaN, "batb": [[0, 1.41, 211.96], [1, 1.4, 62.46], [2, 1.39, 68.91]], "batl": [[0, 1.57, 45.5], [1, 1.71, 5], [2, 1.79, 29.5]]}, {"timestamp": 1631533398454, "ltp": 1.48, "tv": 13318.82, "trd": NaN, "batb": [[1, 1.4, 328.82], [2, 1.39, 330]], "batl": [[1, 1.61, 263.7], [2, 1.62, 138.04]]}, {"timestamp": 1631533399652, "ltp": 1.48, "tv": 13318.82, "trd": NaN, "batb": [[0, 1.42, 8], [1, 1.41, 218.96], [2, 1.4, 334.82]], "batl": [[0, 1.57, 51.5]]}, {"timestamp": 1631533402264, "ltp": 1.48, "tv": 13318.82, "trd": NaN, "batb": NaN, "batl": [[0, 1.47, 13.02], [1, 1.57, 51.5], [2, 1.61, 263.7]]}, {"timestamp": 1631533403671, "ltp": 1.48, "tv": 13318.82, "trd": NaN, "batb": NaN, "batl": [[1, 1.57, 6], [2, 1.71, 5]]}, {"timestamp": 1631533405552, "ltp": 1.48, "tv": 13318.82, "trd": NaN, "batb": [[0, 1.41, 211.96], [1, 1.4, 334.82], [2, 1.39, 330]], "batl": NaN}, {"timestamp": 1631533406465, "ltp": 1.48, "tv": 13318.82, "trd": NaN, "batb": NaN, "batl": [[0, 1.44, 340.26], [1, 1.45, 1530.75], [2, 1.46, 1280.16]]}, {"timestamp": 1631533407496, "ltp": 1.44, "tv": 13332.7, "trd": [[1.44, 13.88]], "batb": NaN, "batl": [[0, 1.44, 326.38], [2, 1.46, 1334.1]]}, {"timestamp": 1631533409071, "ltp": 1.44, "tv": 13332.7, "trd": NaN, "batb": NaN, "batl": [[1, 1.45, 1701.11]]}, {"timestamp": 1631533411706, "ltp": 1.44, "tv": 13332.7, "trd": NaN, "batb": NaN, "batl": [[0, 1.44, 483.44]]}, {"timestamp": 1631533413683, "ltp": 1.44, "tv": 13332.7, "trd": NaN, "batb": [[0, 1.42, 23.1], [1, 1.41, 211.96], [2, 1.4, 334.82]], "batl": [[0, 1.43, 517.48], [1, 1.44, 483.44], [2, 1.45, 1587.65]]}, {"timestamp": 1631533416082, "ltp": 1.44, "tv": 13332.7, "trd": NaN, "batb": NaN, "batl": [[1, 1.44, 533.44]]}, {"timestamp": 1631533417479, "ltp": 1.44, "tv": 13332.7, "trd": NaN, "batb": NaN, "batl": [[0, 1.43, 683.91]]}, {"timestamp": 1631533418572, "ltp": 1.42, "tv": 13376.65, "trd": [[1.42, 43.95]], "batb": [[0, 1.42, 1.12]], "batl": [[0, 1.43, 166.43]]}, {"timestamp": 1631533419088, "ltp": 1.42, "tv": 13376.65, "trd": NaN, "batb": NaN, "batl": [[1, 1.44, 483.44]]}, {"timestamp": 1631533420490, "ltp": 1.42, "tv": 13378.89, "trd": [[1.42, 46.2]], "batb": [[0, 1.41, 211.96], [1, 1.4, 334.82], [2, 1.39, 330]], "batl": [[0, 1.43, 166.73]]}, {"timestamp": 1631533422686, "ltp": 1.42, "tv": 13378.89, "trd": NaN, "batb": NaN, "batl": [[0, 1.42, 521.43], [1, 1.43, 347.43], [2, 1.44, 483.44]]}, {"timestamp": 1631533423617, "ltp": 1.42, "tv": 13382.89, "trd": [[1.42, 50.19]], "batb": NaN, "batl": [[0, 1.42, 519.43]]}, {"timestamp": 1631533426323, "ltp": 1.42, "tv": 13382.89, "trd": NaN, "batb": NaN, "batl": [[0, 1.42, 153.35], [2, 1.44, 539.77]]}, {"timestamp": 1631533429191, "ltp": 1.42, "tv": 13382.89, "trd": NaN, "batb": NaN, "batl": [[0, 1.43, 347.43], [1, 1.44, 539.77], [2, 1.45, 1587.65]]}, {"timestamp": 1631533430126, "ltp": 1.41, "tv": 13806.82, "trd": [[1.41, 423.93]], "batb": [[0, 1.4, 334.82], [1, 1.39, 330], [2, 1.38, 828.69]], "batl": [[0, 1.41, 311.45], [1, 1.43, 347.43], [2, 1.44, 539.77]]}, {"timestamp": 1631533433311, "ltp": 1.41, "tv": 13806.82, "trd": NaN, "batb": [[0, 1.4, 378.49]], "batl": [[1, 1.42, 145.65], [2, 1.43, 347.43]]}, {"timestamp": 1631533440608, "ltp": 1.41, "tv": 13807.42, "trd": [[1.41, 424.53]], "batb": NaN, "batl": [[0, 1.41, 311.15]]}, {"timestamp": 1631533442443, "ltp": 1.41, "tv": 13807.42, "trd": NaN, "batb": [[0, 1.36, 323.22], [1, 1.34, 542.57], [2, 1.33, 73.53]], "batl": [[1, 1.43, 181], [2, 1.44, 56.33]]}, {"timestamp": 1631533443640, "ltp": 1.41, "tv": 13807.42, "trd": NaN, "batb": NaN, "batl": [[0, 1.44, 56.33], [1, 1.45, 56.9], [2, 1.46, 56.25]]}, {"timestamp": 1631533443849, "ltp": 1.41, "tv": 13807.42, "trd": NaN, "batb": NaN, "batl": [[0, 1.46, 56.25], [1, 1.57, 6], [2, 1.95, 415.52]]}, {"timestamp": 1631533445624, "ltp": 1.41, "tv": 13807.42, "trd": NaN, "batb": [[0, 1.36, 80.93], [1, 1.35, 705.21], [2, 1.34, 856.54]], "batl": [[1, 1.48, 170.36], [2, 1.49, 323.87]]}, {"timestamp": 1631533446347, "ltp": 1.41, "tv": 13807.42, "trd": NaN, "batb": [[0, 1.36, 8]], "batl": NaN}, {"timestamp": 1631533447238, "ltp": 1.41, "tv": 13807.42, "trd": NaN, "batb": NaN, "batl": [[0, 1.46, 62.25]]}, {"timestamp": 1631533449525, "ltp": 1.41, "tv": 13807.42, "trd": NaN, "batb": [[0, 1.36, 73.93]], "batl": NaN}, {"timestamp": 1631533450461, "ltp": 1.41, "tv": 13807.42, "trd": NaN, "batb": [[0, 1.36, 8]], "batl": [[0, 1.44, 61.08], [1, 1.46, 62.25], [2, 1.48, 170.36]]}, {"timestamp": 1631533450727, "ltp": 1.41, "tv": 13807.42, "trd": NaN, "batb": NaN, "batl": [[0, 1.46, 62.25], [1, 1.48, 170.36], [2, 1.49, 323.87]]}, {"timestamp": 1631533456349, "ltp": 1.41, "tv": 13807.42, "trd": NaN, "batb": NaN, "batl": [[0, 1.46, 6], [2, 1.57, 6]]}, {"timestamp": 1631533457454, "ltp": 1.41, "tv": 13807.42, "trd": NaN, "batb": [[1, 1.35, 697.21]], "batl": [[0, 1.44, 64.33], [1, 1.46, 6], [2, 1.48, 170.36]]}, {"timestamp": 1631533458243, "ltp": 1.41, "tv": 13807.42, "trd": NaN, "batb": [[0, 1.35, 697.21], [1, 1.34, 384.69], [2, 1.33, 243.89]], "batl": [[0, 1.46, 6], [1, 1.48, 170.36], [2, 2.08, 1]]}, {"timestamp": 1631533459646, "ltp": 1.41, "tv": 13807.42, "trd": NaN, "batb": [[2, 1.33, 1034.77]], "batl": [[0, 1.39, 1705.78], [1, 1.4, 1582.27], [2, 1.41, 1335.42]]}, {"timestamp": 1631533460587, "ltp": 1.41, "tv": 13807.42, "trd": NaN, "batb": [[0, 1.36, 37.32], [1, 1.35, 704.21], [2, 1.34, 384.69]], "batl": [[2, 1.41, 1350.42]]}, {"timestamp": 1631533463671, "ltp": 1.41, "tv": 13807.42, "trd": NaN, "batb": NaN, "batl": [[0, 1.38, 149.09], [1, 1.39, 1705.78], [2, 1.4, 1582.27]]}, {"timestamp": 1631533465491, "ltp": 1.41, "tv": 13807.42, "trd": NaN, "batb": NaN, "batl": [[1, 1.39, 1766.78]]}, {"timestamp": 1631533466066, "ltp": 1.41, "tv": 13807.42, "trd": NaN, "batb": NaN, "batl": [[0, 1.38, 467]]}, {"timestamp": 1631533467105, "ltp": 1.41, "tv": 13807.42, "trd": NaN, "batb": NaN, "batl": [[2, 1.4, 1636.86]]}, {"timestamp": 1631533468508, "ltp": 1.41, "tv": 13807.42, "trd": NaN, "batb": [[0, 1.36, 101.18]], "batl": [[1, 1.39, 1705.78]]}, {"timestamp": 1631533471480, "ltp": 1.41, "tv": 13807.42, "trd": NaN, "batb": NaN, "batl": [[0, 1.37, 365], [1, 1.38, 467], [2, 1.39, 1705.78]]}, {"timestamp": 1631533472377, "ltp": 1.41, "tv": 13807.42, "trd": NaN, "batb": [[0, 1.33, 26.11], [1, 1.32, 278.05], [2, 1.31, 181.64]], "batl": [[1, 1.38, 317.91], [2, 1.4, 54.59]]}, {"timestamp": 1631533473524, "ltp": 1.41, "tv": 13807.42, "trd": NaN, "batb": [[0, 1.32, 278.05], [1, 1.31, 181.64], [2, 1.3, 594.33]], "batl": [[0, 1.38, 317.91], [1, 1.4, 54.59], [2, 1.41, 56.5]]}, {"timestamp": 1631533475573, "ltp": 1.41, "tv": 13807.42, "trd": NaN, "batb": [[0, 1.33, 9], [1, 1.32, 285.05], [2, 1.31, 583.76]], "batl": NaN}, {"timestamp": 1631533476968, "ltp": 1.41, "tv": 13807.42, "trd": NaN, "batb": [[2, 1.31, 591.76]], "batl": NaN}, {"timestamp": 1631533478679, "ltp": 1.41, "tv": 13807.42, "trd": NaN, "batb": [[1, 1.32, 78.64], [2, 1.31, 8]], "batl": NaN}, {"timestamp": 1631533479709, "ltp": 1.4, "tv": 14562.62, "trd": [[1.38, 635.82], [1.4, 119.38]], "batb": [[1, 1.32, 7]], "batl": [[0, 1.42, 60.75], [1, 1.43, 385.4], [2, 1.44, 393.18]]}, {"timestamp": 1631533481689, "ltp": 1.42, "tv": 14568.47, "trd": [[1.42, 56.04]], "batb": [[0, 1.4, 237.37], [1, 1.39, 274.65], [2, 1.38, 2078.81]], "batl": [[0, 1.42, 54.9]]}, {"timestamp": 1631533482685, "ltp": 1.42, "tv": 14568.47, "trd": NaN, "batb": [[1, 1.39, 497.49], [2, 1.38, 1543.92]], "batl": NaN}, {"timestamp": 1631533484704, "ltp": 1.42, "tv": 14568.47, "trd": NaN, "batb": [[1, 1.39, 503.49], [2, 1.38, 1439.36]], "batl": NaN}, {"timestamp": 1631533484912, "ltp": 1.42, "tv": 14568.47, "trd": NaN, "batb": [[2, 1.38, 1392.88]], "batl": [[1, 1.43, 324.9]]}, {"timestamp": 1631533486691, "ltp": 1.42, "tv": 14590.41, "trd": [[1.42, 77.98]], "batb": [[0, 1.4, 281.87]], "batl": [[0, 1.42, 223.88]]}, {"timestamp": 1631533487429, "ltp": 1.42, "tv": 14590.41, "trd": NaN, "batb": [[0, 1.4, 326.87], [2, 1.38, 1417.21]], "batl": [[0, 1.42, 350.88]]}, {"timestamp": 1631533488627, "ltp": 1.42, "tv": 14590.41, "trd": NaN, "batb": NaN, "batl": [[2, 1.44, 448.76]]}, {"timestamp": 1631533493643, "ltp": 1.42, "tv": 14590.41, "trd": NaN, "batb": [[0, 1.38, 24.33], [1, 1.36, 183.85], [2, 1.35, 188.11]], "batl": [[0, 1.42, 127], [1, 1.44, 55.58], [2, 1.46, 56.25]]}, {"timestamp": 1631533494471, "ltp": 1.42, "tv": 14590.41, "trd": NaN, "batb": [[0, 1.36, 183.85], [1, 1.35, 188.11], [2, 1.34, 626.14]], "batl": [[0, 1.4, 705.88]]}, {"timestamp": 1631533496443, "ltp": 1.42, "tv": 14590.41, "trd": NaN, "batb": [[1, 1.35, 416.32], [2, 1.34, 937.4]], "batl": NaN}, {"timestamp": 1631533499548, "ltp": 1.42, "tv": 14590.41, "trd": NaN, "batb": [[0, 1.37, 500], [1, 1.36, 183.85], [2, 1.35, 416.32]], "batl": [[0, 1.46, 56.25], [1, 1.48, 173.74], [2, 1.49, 403.01]]}, {"timestamp": 1631533501065, "ltp": 1.42, "tv": 14590.41, "trd": NaN, "batb": [[2, 1.35, 188.11]], "batl": [[2, 1.49, 172.78]]}, {"timestamp": 1631533502488, "ltp": 1.42, "tv": 14590.41, "trd": NaN, "batb": NaN, "batl": [[0, 1.44, 7], [1, 1.46, 56.25], [2, 1.48, 173.74]]}, {"timestamp": 1631533503069, "ltp": 1.42, "tv": 14590.41, "trd": NaN, "batb": NaN, "batl": [[1, 1.45, 7], [2, 1.46, 62.25]]}, {"timestamp": 1631533504484, "ltp": 1.42, "tv": 14590.41, "trd": NaN, "batb": [[0, 1.39, 227.41], [1, 1.38, 269.63], [2, 1.37, 500]], "batl": [[0, 1.42, 178.32], [1, 1.43, 226.16], [2, 1.44, 7]]}, {"timestamp": 1631533506268, "ltp": 1.42, "tv": 14590.41, "trd": NaN, "batb": NaN, "batl": [[2, 1.44, 110.48]]}, {"timestamp": 1631533506893, "ltp": 1.42, "tv": 14611.49, "trd": [[1.42, 99.07]], "batb": NaN, "batl": [[0, 1.42, 167.78]]}, {"timestamp": 1631533508671, "ltp": 1.42, "tv": 14611.49, "trd": NaN, "batb": [[0, 1.37, 500], [1, 1.36, 183.85], [2, 1.35, 188.11]], "batl": [[0, 1.42, 57], [1, 1.44, 67.33], [2, 1.45, 7]]}, {"timestamp": 1631533509561, "ltp": 1.37, "tv": 15351.24, "trd": [[1.37, 739.74]], "batb": [[0, 1.37, 130.13]], "batl": [[0, 1.44, 7], [1, 1.45, 7], [2, 1.46, 62.25]]}, {"timestamp": 1631533511695, "ltp": 1.37, "tv": 15351.24, "trd": NaN, "batb": [[2, 1.35, 422.47]], "batl": NaN}, {"timestamp": 1631533516069, "ltp": 1.37, "tv": 15351.24, "trd": NaN, "batb": NaN, "batl": [[1, 1.46, 56.25], [2, 1.48, 173.74]]}, {"timestamp": 1631533520201, "ltp": 1.37, "tv": 15351.24, "trd": NaN, "batb": NaN, "batl": [[2, 1.82, 475.58]]}, {"timestamp": 1631533523709, "ltp": 1.37, "tv": 15351.24, "trd": NaN, "batb": NaN, "batl": [[0, 1.38, 265.66], [1, 1.39, 1631.57], [2, 1.4, 1335.42]]}, {"timestamp": 1631533524605, "ltp": 1.37, "tv": 15351.24, "trd": NaN, "batb": [[2, 1.35, 428.47]], "batl": [[2, 1.4, 1350.42]]}, {"timestamp": 1631533526280, "ltp": 1.37, "tv": 15351.24, "trd": NaN, "batb": [[0, 1.35, 428.47], [1, 1.34, 937.41], [2, 1.33, 790.88]], "batl": NaN}, {"timestamp": 1631533527492, "ltp": 1.37, "tv": 15351.24, "trd": NaN, "batb": NaN, "batl": [[0, 1.38, 428.15]]}, {"timestamp": 1631533529513, "ltp": 1.37, "tv": 15351.24, "trd": NaN, "batb": [[0, 1.35, 470.37]], "batl": [[0, 1.38, 521.15]]}, {"timestamp": 1631533530089, "ltp": 1.37, "tv": 15351.24, "trd": NaN, "batb": NaN, "batl": [[2, 1.4, 1411.36]]}, {"timestamp": 1631533532402, "ltp": 1.37, "tv": 15351.24, "trd": NaN, "batb": NaN, "batl": [[0, 1.37, 181.3], [1, 1.38, 428.15], [2, 1.39, 1631.57]]}, {"timestamp": 1631533535388, "ltp": 1.37, "tv": 15351.24, "trd": NaN, "batb": NaN, "batl": [[0, 1.37, 482.3]]}, {"timestamp": 1631533537687, "ltp": 1.37, "tv": 15351.24, "trd": NaN, "batb": [[0, 1.36, 20.45], [1, 1.35, 470.37], [2, 1.34, 937.41]], "batl": NaN}, {"timestamp": 1631533538519, "ltp": 1.37, "tv": 15351.24, "trd": NaN, "batb": [[1, 1.35, 509.63], [2, 1.34, 930.41]], "batl": NaN}, {"timestamp": 1631533539616, "ltp": 1.35, "tv": 16685.6, "trd": [[1.35, 1293.46], [1.36, 40.9]], "batb": [[0, 1.34, 930.41], [1, 1.33, 790.88], [2, 1.32, 794.13]], "batl": [[0, 1.35, 254.54], [1, 1.37, 482.3], [2, 1.38, 428.15]]}, {"timestamp": 1631533541127, "ltp": 1.35, "tv": 16685.6, "trd": NaN, "batb": [[0, 1.34, 939.41]], "batl": NaN}, {"timestamp": 1631533542692, "ltp": 1.35, "tv": 16723.0, "trd": [[1.35, 1330.86]], "batb": NaN, "batl": [[0, 1.35, 235.84], [1, 1.36, 190.12], [2, 1.37, 482.3]]}, {"timestamp": 1631533543627, "ltp": 1.35, "tv": 16723.0, "trd": NaN, "batb": [[0, 1.34, 1099.94], [1, 1.33, 1118.44]], "batl": NaN}, {"timestamp": 1631533544620, "ltp": 1.35, "tv": 16723.0, "trd": NaN, "batb": [[0, 1.34, 9], [1, 1.32, 26.51], [2, 1.29, 3.45]], "batl": [[1, 1.37, 301], [2, 1.38, 70.25]]}, {"timestamp": 1631533545620, "ltp": 1.35, "tv": 16723.0, "trd": NaN, "batb": [[0, 1.29, 3.45], [1, 1.28, 327.69], [2, 1.26, 99.98]], "batl": [[0, 1.4, 60.94], [1, 1.43, 7], [2, 1.46, 56.25]]}, {"timestamp": 1631533547299, "ltp": 1.35, "tv": 16723.0, "trd": NaN, "batb": [[0, 1.3, 204.28], [1, 1.29, 385.66], [2, 1.28, 327.69]], "batl": [[1, 1.43, 304.75], [2, 1.44, 219.55]]}, {"timestamp": 1631533548617, "ltp": 1.35, "tv": 16723.0, "trd": NaN, "batb": [[0, 1.29, 13.45], [1, 1.28, 336.69], [2, 1.26, 99.98]], "batl": [[1, 1.43, 7], [2, 1.82, 475.58]]}, {"timestamp": 1631533549244, "ltp": 1.35, "tv": 16723.0, "trd": NaN, "batb": NaN, "batl": [[0, 1.4, 64.94]]}, {"timestamp": 1631533551605, "ltp": 1.35, "tv": 16723.0, "trd": NaN, "batb": [[0, 1.33, 437.07], [1, 1.32, 340.97], [2, 1.29, 13.45]], "batl": [[0, 1.37, 412.12], [1, 1.38, 264.14], [2, 1.4, 64.94]]}, {"timestamp": 1631533552441, "ltp": 1.35, "tv": 16723.0, "trd": NaN, "batb": [[2, 1.29, 101.26]], "batl": [[1, 1.38, 326.39]]}, {"timestamp": 1631533553224, "ltp": 1.35, "tv": 16723.0, "trd": NaN, "batb": NaN, "batl": [[2, 1.39, 67.58]]}, {"timestamp": 1631533555634, "ltp": 1.35, "tv": 16723.0, "trd": NaN, "batb": [[0, 1.29, 13.45], [1, 1.28, 336.69], [2, 1.26, 99.98]], "batl": [[0, 1.36, 204.7], [1, 1.4, 64.94], [2, 1.43, 7]]}, {"timestamp": 1631533556516, "ltp": 1.35, "tv": 16723.0, "trd": NaN, "batb": NaN, "batl": [[0, 1.4, 64.94], [1, 1.43, 7], [2, 1.82, 475.58]]}, {"timestamp": 1631533558655, "ltp": 1.35, "tv": 16723.0, "trd": NaN, "batb": [[0, 1.3, 204.28], [1, 1.29, 488.47], [2, 1.28, 336.69]], "batl": [[0, 1.38, 72.25], [1, 1.4, 64.94], [2, 1.43, 304.75]]}, {"timestamp": 1631533558858, "ltp": 1.35, "tv": 16723.0, "trd": NaN, "batb": NaN, "batl": [[0, 1.4, 64.94], [1, 1.43, 304.75], [2, 1.44, 219.55]]}, {"timestamp": 1631533562426, "ltp": 1.35, "tv": 16723.0, "trd": NaN, "batb": [[2, 1.28, 327.69]], "batl": [[1, 1.43, 297.75]]}, {"timestamp": 1631533565667, "ltp": 1.35, "tv": 16723.0, "trd": NaN, "batb": NaN, "batl": [[0, 1.38, 66.25], [1, 1.4, 64.94], [2, 1.43, 297.75]]}, {"timestamp": 1631533566639, "ltp": 1.3, "tv": 16723.12, "trd": [[1.3, 0.12]], "batb": [[0, 1.29, 13.45], [1, 1.28, 327.69], [2, 1.26, 99.98]], "batl": [[0, 1.4, 64.94], [1, 1.82, 475.58], [2, 2.08, 1]]}, {"timestamp": 1631533568586, "ltp": 1.3, "tv": 16723.12, "trd": NaN, "batb": NaN, "batl": [[1, 2.08, 1], [2, 44, 7.23]]}, {"timestamp": 1631533569676, "ltp": 1.3, "tv": 16723.12, "trd": NaN, "batb": [[0, 1.3, 204.25], [1, 1.29, 395.66], [2, 1.28, 1149.47]], "batl": [[0, 1.33, 454.52], [1, 1.34, 303.52], [2, 1.38, 60.25]]}, {"timestamp": 1631533570637, "ltp": 1.3, "tv": 16723.12, "trd": NaN, "batb": [[2, 1.28, 1158.47]], "batl": NaN}, {"timestamp": 1631533571445, "ltp": 1.3, "tv": 16723.12, "trd": NaN, "batb": [[1, 1.29, 453.93], [2, 1.28, 1186.81]], "batl": [[2, 1.36, 15]]}, {"timestamp": 1631533572338, "ltp": 1.3, "tv": 16723.12, "trd": NaN, "batb": [[0, 1.3, 213.25]], "batl": NaN}, {"timestamp": 1631533574537, "ltp": 1.32, "tv": 16743.68, "trd": [[1.32, 20.56]], "batb": NaN, "batl": [[0, 1.32, 388.75], [1, 1.33, 454.52], [2, 1.34, 303.52]]}, {"timestamp": 1631533575688, "ltp": 1.3, "tv": 17170.18, "trd": [[1.3, 426.62]], "batb": [[0, 1.29, 453.93], [1, 1.28, 1186.81], [2, 1.27, 797.6]], "batl": [[0, 1.3, 176.54], [1, 1.32, 388.75], [2, 1.33, 484.84]]}, {"timestamp": 1631533576582, "ltp": 1.3, "tv": 17170.18, "trd": NaN, "batb": [[2, 1.27, 1027.34]], "batl": NaN}, {"timestamp": 1631533578644, "ltp": 1.3, "tv": 17206.22, "trd": [[1.3, 462.66]], "batb": [[0, 1.29, 546.11], [1, 1.28, 1592.97]], "batl": [[0, 1.3, 158.52], [1, 1.31, 183.75], [2, 1.32, 635.52]]}, {"timestamp": 1631533579268, "ltp": 1.3, "tv": 17206.22, "trd": NaN, "batb": NaN, "batl": [[2, 1.32, 719.63]]}, {"timestamp": 1631533582268, "ltp": 1.3, "tv": 17206.22, "trd": NaN, "batb": [[1, 1.28, 1583.97]], "batl": [[0, 1.3, 171.54]]}, {"timestamp": 1631533592247, "ltp": 1.3, "tv": 17222.22, "trd": [[1.3, 478.66]], "batb": NaN, "batl": [[0, 1.3, 163.54]]}, {"timestamp": 1631533595647, "ltp": 1.3, "tv": 17222.22, "trd": NaN, "batb": [[0, 1.29, 487.84], [1, 1.28, 762.19], [2, 1.27, 229.74]], "batl": NaN}, {"timestamp": 1631533596646, "ltp": 1.29, "tv": 17226.08, "trd": [[1.29, 3.86]], "batb": [[0, 1.29, 11.52], [1, 1.28, 28.34]], "batl": [[1, 1.32, 84.11], [2, 1.34, 74.25]]}, {"timestamp": 1631533597630, "ltp": 1.29, "tv": 17226.08, "trd": NaN, "batb": [[0, 1.29, 1.52], [1, 1.27, 229.74], [2, 1.26, 201.51]], "batl": NaN}, {"timestamp": 1631533599145, "ltp": 1.29, "tv": 17226.08, "trd": NaN, "batb": [[2, 1.26, 548.48]], "batl": NaN}, {"timestamp": 1631533603163, "ltp": 1.29, "tv": 17226.08, "trd": NaN, "batb": [[1, 1.25, 512.06], [2, 1.24, 483.57]], "batl": NaN}, {"timestamp": 1631533604525, "ltp": 1.29, "tv": 17226.08, "trd": NaN, "batb": NaN, "batl": [[0, 1.3, 13.02], [1, 1.34, 74.25], [2, 1.36, 377.58]]}, {"timestamp": 1631533605624, "ltp": 1.3, "tv": 17252.12, "trd": [[1.3, 504.7]], "batb": NaN, "batl": [[0, 1.34, 74.25], [1, 1.36, 377.58], [2, 1.37, 415.63]]}, {"timestamp": 1631533606522, "ltp": 1.34, "tv": 17260.85, "trd": [[1.34, 8.73]], "batb": [[0, 1.33, 257.22], [1, 1.32, 1788.91], [2, 1.31, 1406.26]], "batl": [[0, 1.34, 65.52]]}, {"timestamp": 1631533607465, "ltp": 1.34, "tv": 17260.85, "trd": NaN, "batb": [[0, 1.33, 535.79], [1, 1.32, 1881.87]], "batl": NaN}, {"timestamp": 1631533609661, "ltp": 1.34, "tv": 17260.85, "trd": NaN, "batb": [[0, 1.33, 544.79], [1, 1.32, 1843.39]], "batl": [[1, 1.36, 309.76]]}, {"timestamp": 1631533610522, "ltp": 1.34, "tv": 17260.85, "trd": NaN, "batb": [[0, 1.33, 590.13], [1, 1.32, 1796.91], [2, 1.31, 1433.2]], "batl": [[1, 1.35, 199.86], [2, 1.36, 309.76]]}, {"timestamp": 1631533611363, "ltp": 1.33, "tv": 17569.92, "trd": [[1.33, 294.26], [1.34, 23.54]], "batb": [[0, 1.33, 443]], "batl": [[0, 1.34, 50.71]]}, {"timestamp": 1631533613149, "ltp": 1.33, "tv": 17569.92, "trd": NaN, "batb": NaN, "batl": [[0, 1.34, 218.71]]}, {"timestamp": 1631533615646, "ltp": 1.33, "tv": 17569.92, "trd": NaN, "batb": [[0, 1.33, 508.82]], "batl": [[2, 1.36, 389.21]]}, {"timestamp": 1631533616954, "ltp": 1.33, "tv": 17569.92, "trd": NaN, "batb": NaN, "batl": [[0, 1.34, 425.71]]}, {"timestamp": 1631533624366, "ltp": 1.33, "tv": 17569.92, "trd": NaN, "batb": [[0, 1.31, 26.94], [1, 1.29, 1.52], [2, 1.27, 197.02]], "batl": [[0, 1.34, 168], [1, 1.39, 68.5], [2, 1.4, 60.94]]}, {"timestamp": 1631533625455, "ltp": 1.33, "tv": 17569.92, "trd": NaN, "batb": [[0, 1.29, 1.52], [1, 1.27, 197.02], [2, 1.26, 644.78]], "batl": [[0, 1.42, 220.12], [1, 1.43, 150.02], [2, 1.44, 189.25]]}, {"timestamp": 1631533627587, "ltp": 1.33, "tv": 17569.92, "trd": NaN, "batb": [[1, 1.27, 466.99], [2, 1.26, 1087.05]], "batl": [[0, 1.42, 445.77], [1, 1.43, 378.75]]}, {"timestamp": 1631533628687, "ltp": 1.33, "tv": 17569.92, "trd": NaN, "batb": NaN, "batl": [[0, 1.39, 67.5], [1, 1.42, 451.77], [2, 1.43, 378.75]]}, {"timestamp": 1631533629465, "ltp": 1.33, "tv": 17569.92, "trd": NaN, "batb": [[1, 1.28, 500], [2, 1.27, 466.99]], "batl": NaN}, {"timestamp": 1631533633270, "ltp": 1.33, "tv": 17569.92, "trd": NaN, "batb": [[2, 1.26, 371.79]], "batl": [[0, 1.39, 7]]}, {"timestamp": 1631533634162, "ltp": 1.33, "tv": 17569.92, "trd": NaN, "batb": [[1, 1.26, 371.79], [2, 1.24, 91.02]], "batl": NaN}, {"timestamp": 1631533635670, "ltp": 1.39, "tv": 17583.92, "trd": [[1.39, 14]], "batb": [[0, 1.34, 84.22], [1, 1.29, 1.52], [2, 1.26, 371.79]], "batl": [[0, 1.42, 451.77], [1, 1.43, 378.75], [2, 1.44, 2845.49]]}, {"timestamp": 1631533636657, "ltp": 1.39, "tv": 17583.92, "trd": NaN, "batb": [[0, 1.39, 187.36], [1, 1.38, 272.6], [2, 1.34, 84.22]], "batl": [[0, 1.42, 445.77], [2, 1.44, 1517.37]]}, {"timestamp": 1631533637390, "ltp": 1.39, "tv": 17583.92, "trd": NaN, "batb": [[0, 1.39, 410.2], [2, 1.36, 25]], "batl": NaN}, {"timestamp": 1631533638695, "ltp": 1.39, "tv": 17583.92, "trd": NaN, "batb": [[2, 1.34, 84.22]], "batl": NaN}, {"timestamp": 1631533639072, "ltp": 1.39, "tv": 17583.92, "trd": NaN, "batb": [[2, 1.37, 7]], "batl": NaN}, {"timestamp": 1631533640675, "ltp": 1.41, "tv": 17595.9, "trd": [[1.41, 436.51]], "batb": [[0, 1.39, 456.16]], "batl": [[0, 1.41, 172.21], [1, 1.42, 445.77], [2, 1.43, 378.75]]}, {"timestamp": 1631533641611, "ltp": 1.41, "tv": 17595.9, "trd": NaN, "batb": [[2, 1.37, 31.65]], "batl": NaN}, {"timestamp": 1631533647295, "ltp": 1.41, "tv": 17595.9, "trd": NaN, "batb": NaN, "batl": [[0, 1.41, 277.21]]}, {"timestamp": 1631533651199, "ltp": 1.41, "tv": 17595.9, "trd": NaN, "batb": [[0, 1.37, 24.65], [1, 1.34, 208.76], [2, 1.33, 201.71]], "batl": [[0, 1.41, 105], [1, 1.44, 56.08], [2, 1.45, 56.7]]}, {"timestamp": 1631533652711, "ltp": 1.41, "tv": 17595.9, "trd": NaN, "batb": [[0, 1.34, 208.76], [1, 1.33, 201.71], [2, 1.32, 476.47]], "batl": [[0, 1.46, 64.25], [1, 1.49, 157.7], [2, 1.5, 183.12]]}, {"timestamp": 1631533654298, "ltp": 1.41, "tv": 17595.9, "trd": NaN, "batb": [[1, 1.33, 387.29], [2, 1.32, 816.66]], "batl": [[1, 1.49, 427.14], [2, 1.5, 370.04]]}, {"timestamp": 1631533655683, "ltp": 1.41, "tv": 17595.9, "trd": NaN, "batb": [[0, 1.32, 280.25], [1, 1.31, 478.9], [2, 1.3, 94.88]], "batl": NaN}, {"timestamp": 1631533658590, "ltp": 1.46, "tv": 17602.22, "trd": [[1.46, 6.32]], "batb": [[0, 1.45, 228.88], [1, 1.44, 224.81], [2, 1.39, 85.91]], "batl": [[0, 1.46, 57.93]]}, {"timestamp": 1631533659625, "ltp": 1.46, "tv": 17602.22, "trd": NaN, "batb": [[1, 1.44, 414.51], [2, 1.39, 311.43]], "batl": NaN}, {"timestamp": 1631533661709, "ltp": 1.44, "tv": 18195.6, "trd": [[1.44, 142.88], [1.45, 464.38]], "batb": [[0, 1.44, 356.01], [1, 1.43, 7]], "batl": [[1, 1.49, 351.05], [2, 1.5, 183.12]]}, {"timestamp": 1631533662598, "ltp": 1.44, "tv": 18195.6, "trd": NaN, "batb": [[2, 1.42, 23.14]], "batl": NaN}, {"timestamp": 1631533663629, "ltp": 1.44, "tv": 18195.6, "trd": NaN, "batb": [[2, 1.39, 311.43]], "batl": [[1, 1.47, 158.07], [2, 1.49, 351.05]]}, {"timestamp": 1631533664615, "ltp": 1.44, "tv": 18195.6, "trd": NaN, "batb": [[0, 1.45, 50.95], [1, 1.44, 488.07], [2, 1.43, 423.66]], "batl": [[0, 1.46, 382.81], [2, 1.48, 235.08]]}, {"timestamp": 1631533666036, "ltp": 1.44, "tv": 18195.6, "trd": NaN, "batb": [[2, 1.43, 446.53]], "batl": NaN}, {"timestamp": 1631533671133, "ltp": 1.44, "tv": 18195.6, "trd": NaN, "batb": [[2, 1.43, 666.69]], "batl": NaN}, {"timestamp": 1631533674309, "ltp": 1.44, "tv": 18195.6, "trd": NaN, "batb": [[1, 1.44, 482.07], [2, 1.43, 659.69]], "batl": NaN}, {"timestamp": 1631533675713, "ltp": 1.44, "tv": 18195.6, "trd": NaN, "batb": [[0, 1.45, 6], [1, 1.43, 22.87], [2, 1.4, 155.15]], "batl": [[0, 1.46, 169], [1, 1.54, 124.39], [2, 1.55, 138.99]]}, {"timestamp": 1631533676422, "ltp": 1.44, "tv": 18195.6, "trd": NaN, "batb": [[0, 1.4, 155.15], [1, 1.39, 398.85], [2, 1.38, 207.67]], "batl": [[0, 1.54, 124.39], [1, 1.55, 138.99], [2, 1.56, 159.04]]}, {"timestamp": 1631533678537, "ltp": 1.44, "tv": 18195.6, "trd": NaN, "batb": [[2, 1.38, 492.6]], "batl": [[1, 1.55, 425.42], [2, 1.56, 320.25]]}, {"timestamp": 1631533679631, "ltp": 1.44, "tv": 18195.6, "trd": NaN, "batb": NaN, "batl": [[0, 1.53, 7], [1, 1.54, 129.39], [2, 1.55, 425.42]]}, {"timestamp": 1631533680418, "ltp": 1.44, "tv": 18195.6, "trd": NaN, "batb": [[0, 1.41, 500], [1, 1.4, 155.15], [2, 1.39, 398.85]], "batl": NaN}, {"timestamp": 1631533681449, "ltp": 1.44, "tv": 18195.6, "trd": NaN, "batb": NaN, "batl": [[2, 1.55, 138.99]]}, {"timestamp": 1631533684625, "ltp": 1.44, "tv": 18195.6, "trd": NaN, "batb": [[0, 1.43, 232.6], [1, 1.42, 240.54], [2, 1.41, 500]], "batl": [[0, 1.47, 313.97], [1, 1.48, 198.24], [2, 1.53, 7]]}, {"timestamp": 1631533686433, "ltp": 1.44, "tv": 18195.6, "trd": NaN, "batb": NaN, "batl": [[2, 1.52, 35]]}, {"timestamp": 1631533687936, "ltp": 1.44, "tv": 18195.6, "trd": NaN, "batb": [[0, 1.41, 500], [1, 1.4, 155.15], [2, 1.39, 398.85]], "batl": [[0, 1.53, 7], [1, 1.54, 129.39], [2, 1.55, 138.99]]}, {"timestamp": 1631533689545, "ltp": 1.44, "tv": 18195.6, "trd": NaN, "batb": [[0, 1.44, 71.08], [1, 1.41, 500], [2, 1.4, 155.15]], "batl": NaN}, {"timestamp": 1631533689818, "ltp": 1.44, "tv": 18195.6, "trd": NaN, "batb": [[0, 1.41, 500], [1, 1.4, 155.15], [2, 1.39, 398.85]], "batl": NaN}, {"timestamp": 1631533690857, "ltp": 1.44, "tv": 18195.6, "trd": NaN, "batb": NaN, "batl": [[2, 1.55, 425.42]]}, {"timestamp": 1631533693437, "ltp": 1.44, "tv": 18195.6, "trd": NaN, "batb": [[1, 1.39, 225.52], [2, 1.36, 95.68]], "batl": [[1, 1.54, 124.39]]}, {"timestamp": 1631533696664, "ltp": 1.44, "tv": 18195.6, "trd": NaN, "batb": [[0, 1.5, 291.88], [1, 1.49, 1479.14], [2, 1.48, 1245.82]], "batl": [[0, 1.54, 124.39], [1, 1.55, 425.42], [2, 1.56, 320.25]]}, {"timestamp": 1631533697659, "ltp": 1.44, "tv": 18195.6, "trd": NaN, "batb": [[0, 1.5, 455.64]], "batl": NaN}, {"timestamp": 1631533698656, "ltp": 1.44, "tv": 18195.6, "trd": NaN, "batb": [[0, 1.51, 7], [1, 1.5, 461.64], [2, 1.49, 1479.14]], "batl": NaN}, {"timestamp": 1631533699237, "ltp": 1.44, "tv": 18195.6, "trd": NaN, "batb": [[2, 1.49, 1486.14]], "batl": NaN}, {"timestamp": 1631533700654, "ltp": 1.44, "tv": 18195.6, "trd": NaN, "batb": NaN, "batl": [[0, 1.53, 116.37], [1, 1.54, 124.39], [2, 1.55, 425.42]]}, {"timestamp": 1631533701538, "ltp": 1.44, "tv": 18195.6, "trd": NaN, "batb": [[0, 1.51, 42]], "batl": NaN}, {"timestamp": 1631533704449, "ltp": 1.44, "tv": 18195.6, "trd": NaN, "batb": [[2, 1.49, 1507.56]], "batl": [[1, 1.54, 238.13]]}, {"timestamp": 1631533705538, "ltp": 1.44, "tv": 18195.6, "trd": NaN, "batb": [[1, 1.5, 459.47]], "batl": NaN}, {"timestamp": 1631533706159, "ltp": 1.44, "tv": 18195.6, "trd": NaN, "batb": NaN, "batl": [[0, 1.53, 221.37]]}, {"timestamp": 1631533711269, "ltp": 1.44, "tv": 18195.6, "trd": NaN, "batb": [[1, 1.5, 453.47], [2, 1.49, 1500.56]], "batl": NaN}, {"timestamp": 1631533711962, "ltp": 1.53, "tv": 18237.38, "trd": [[1.53, 48.45]], "batb": NaN, "batl": [[0, 1.53, 200.48]]}, {"timestamp": 1631533713047, "ltp": 1.53, "tv": 18237.38, "trd": NaN, "batb": [[1, 1.5, 659.6]], "batl": NaN}, {"timestamp": 1631533715052, "ltp": 1.53, "tv": 18237.38, "trd": NaN, "batb": [[2, 1.49, 1706.69]], "batl": NaN}, {"timestamp": 1631533719501, "ltp": 1.5, "tv": 18907.98, "trd": [[1.5, 573.11], [1.51, 145.88]], "batb": [[0, 1.5, 383.94], [1, 1.49, 1706.69], [2, 1.48, 1440.67]], "batl": [[2, 1.55, 304.87]]}, {"timestamp": 1631533722481, "ltp": 1.5, "tv": 18907.98, "trd": NaN, "batb": [[0, 1.51, 5], [1, 1.5, 514.26], [2, 1.49, 1706.69]], "batl": [[1, 1.54, 507.38]]}, {"timestamp": 1631533723154, "ltp": 1.5, "tv": 18907.98, "trd": NaN, "batb": [[1, 1.5, 556.95]], "batl": NaN}, {"timestamp": 1631533726183, "ltp": 1.49, "tv": 21477.37, "trd": [[1.49, 1191.34], [1.5, 1935.28], [1.51, 161.76]], "batb": [[0, 1.49, 1111.02], [1, 1.48, 1440.67], [2, 1.47, 1455.98]], "batl": [[0, 1.53, 95.48], [1, 1.54, 409.05], [2, 1.55, 138.99]]}, {"timestamp": 1631533729565, "ltp": 1.49, "tv": 21477.37, "trd": NaN, "batb": [[0, 1.49, 1344.7], [1, 1.48, 1642.92]], "batl": [[0, 1.52, 126.86], [1, 1.53, 269.99], [2, 1.54, 533.24]]}, {"timestamp": 1631533729974, "ltp": 1.49, "tv": 21477.37, "trd": NaN, "batb": [[0, 1.49, 1389.69]], "batl": NaN}, {"timestamp": 1631533732694, "ltp": 1.49, "tv": 23589.01, "trd": [[1.49, 3296.98], [1.5, 1941.28]], "batb": [[0, 1.5, 33.16], [1, 1.49, 336.87], [2, 1.48, 1642.92]], "batl": NaN}, {"timestamp": 1631533734196, "ltp": 1.49, "tv": 23589.01, "trd": NaN, "batb": NaN, "batl": [[0, 1.52, 491.86]]}, {"timestamp": 1631533735585, "ltp": 1.49, "tv": 23589.01, "trd": NaN, "batb": [[1, 1.49, 424.37], [2, 1.48, 1729.52]], "batl": [[1, 1.53, 375.04], [2, 1.54, 657.43]]}, {"timestamp": 1631533736700, "ltp": 1.49, "tv": 23589.01, "trd": NaN, "batb": [[0, 1.51, 7], [1, 1.5, 39.16], [2, 1.49, 424.37]], "batl": NaN}, {"timestamp": 1631533737378, "ltp": 1.49, "tv": 23589.01, "trd": NaN, "batb": [[2, 1.49, 474]], "batl": NaN}, {"timestamp": 1631533739616, "ltp": 1.49, "tv": 24147.75, "trd": [[1.49, 3757.44], [1.5, 2025.56], [1.51, 175.76]], "batb": [[0, 1.49, 156.27], [1, 1.48, 1729.52], [2, 1.47, 1455.98]], "batl": [[1, 1.53, 271.72], [2, 1.54, 486.51]]}, {"timestamp": 1631533739891, "ltp": 1.49, "tv": 24147.75, "trd": NaN, "batb": NaN, "batl": [[0, 1.51, 178.89], [1, 1.52, 491.86], [2, 1.53, 271.72]]}, {"timestamp": 1631533742705, "ltp": 1.49, "tv": 24147.75, "trd": NaN, "batb": [[0, 1.49, 94.62], [1, 1.48, 2014.51], [2, 1.47, 1665.29]], "batl": [[1, 1.52, 629.93]]}, {"timestamp": 1631533745688, "ltp": 1.49, "tv": 24147.75, "trd": NaN, "batb": [[0, 1.49, 99.62]], "batl": NaN}, {"timestamp": 1631533746307, "ltp": 1.49, "tv": 24352.99, "trd": [[1.49, 3956.68], [1.5, 2031.56]], "batb": [[0, 1.48, 2014.51], [1, 1.47, 1665.29], [2, 1.46, 172.74]], "batl": [[0, 1.49, 106.14], [1, 1.51, 178.89], [2, 1.52, 629.93]]}, {"timestamp": 1631533749603, "ltp": 1.49, "tv": 24565.28, "trd": [[1.49, 4168.96]], "batb": [[0, 1.49, 92.33], [1, 1.48, 2020.51], [2, 1.47, 1665.29]], "batl": [[0, 1.51, 178.89], [1, 1.52, 629.93], [2, 1.53, 271.72]]}, {"timestamp": 1631533750222, "ltp": 1.49, "tv": 24565.28, "trd": NaN, "batb": [[0, 1.49, 128.91]], "batl": NaN}, {"timestamp": 1631533752319, "ltp": 1.49, "tv": 24565.28, "trd": NaN, "batb": [[0, 1.5, 5], [1, 1.49, 128.91], [2, 1.48, 2020.51]], "batl": NaN}, {"timestamp": 1631533753525, "ltp": 1.48, "tv": 28518.21, "trd": [[1.48, 4801.78], [1.49, 4426.78], [1.5, 2041.56]], "batb": [[0, 1.48, 177.95], [1, 1.47, 1665.29], [2, 1.46, 172.74]], "batl": NaN}, {"timestamp": 1631533756530, "ltp": 1.48, "tv": 28518.21, "trd": NaN, "batb": [[1, 1.47, 1752.8]], "batl": NaN}, {"timestamp": 1631533757528, "ltp": 1.48, "tv": 28518.21, "trd": NaN, "batb": [[0, 1.49, 32.92], [1, 1.48, 319.01], [2, 1.47, 1752.8]], "batl": [[1, 1.52, 799.19]]}, {"timestamp": 1631533757726, "ltp": 1.48, "tv": 28518.21, "trd": NaN, "batb": [[0, 1.48, 319.01], [1, 1.47, 1752.8], [2, 1.46, 172.74]], "batl": NaN}, {"timestamp": 1631533759929, "ltp": 1.48, "tv": 28518.21, "trd": NaN, "batb": [[0, 1.49, 5], [1, 1.48, 319.01], [2, 1.47, 1752.8]], "batl": NaN}, {"timestamp": 1631533760933, "ltp": 1.48, "tv": 28518.21, "trd": NaN, "batb": [[1, 1.48, 362.41]], "batl": NaN}, {"timestamp": 1631533764429, "ltp": 1.48, "tv": 28935.73, "trd": [[1.48, 5203.3], [1.49, 4436.78], [1.5, 2047.56]], "batb": [[0, 1.48, 161.65], [1, 1.47, 1752.8], [2, 1.46, 172.74]], "batl": NaN}, {"timestamp": 1631533765112, "ltp": 1.48, "tv": 28935.73, "trd": NaN, "batb": [[0, 1.48, 43.4]], "batl": [[1, 1.52, 673.72], [2, 1.53, 95.48]]}, {"timestamp": 1631533767621, "ltp": 1.48, "tv": 28935.73, "trd": NaN, "batb": [[0, 1.48, 50.4]], "batl": NaN}, {"timestamp": 1631533768037, "ltp": 1.48, "tv": 28935.73, "trd": NaN, "batb": [[1, 1.47, 1883.85], [2, 1.46, 389.5]], "batl": [[0, 1.51, 319.47], [1, 1.52, 842.37]]}, {"timestamp": 1631533771041, "ltp": 1.48, "tv": 29127.31, "trd": [[1.48, 5394.88]], "batb": [[0, 1.47, 1883.85], [1, 1.46, 389.5], [2, 1.42, 289.69]], "batl": NaN}, {"timestamp": 1631533772139, "ltp": 1.48, "tv": 29127.31, "trd": NaN, "batb": [[0, 1.47, 1260.94]], "batl": NaN}, {"timestamp": 1631533774238, "ltp": 1.5, "tv": 29135.31, "trd": [[1.5, 2055.56]], "batb": [[0, 1.49, 5], [1, 1.47, 1265.94], [2, 1.46, 389.5]], "batl": [[0, 1.5, 218.76], [1, 1.51, 319.47], [2, 1.52, 842.37]]}, {"timestamp": 1631533775016, "ltp": 1.5, "tv": 29135.31, "trd": NaN, "batb": [[1, 1.48, 36.83], [2, 1.47, 1265.94]], "batl": NaN}, {"timestamp": 1631533777212, "ltp": 1.5, "tv": 29149.31, "trd": [[1.5, 2069.56]], "batb": [[1, 1.48, 88.74]], "batl": [[0, 1.5, 211.76]]}, {"timestamp": 1631533778517, "ltp": 1.47, "tv": 32167.35, "trd": [[1.47, 2321.94], [1.48, 6083.74], [1.49, 4446.78]], "batb": [[0, 1.47, 106.35], [1, 1.46, 389.5], [2, 1.42, 289.69]], "batl": NaN}, {"timestamp": 1631533781546, "ltp": 1.47, "tv": 32167.35, "trd": NaN, "batb": [[0, 1.47, 213.28], [2, 1.45, 89.44]], "batl": [[1, 1.51, 447.71]]}, {"timestamp": 1631533782436, "ltp": 1.47, "tv": 32167.35, "trd": NaN, "batb": [[0, 1.48, 33.15], [1, 1.47, 213.28], [2, 1.46, 389.5]], "batl": NaN}, {"timestamp": 1631533785141, "ltp": 1.47, "tv": 32167.35, "trd": NaN, "batb": [[0, 1.47, 213.28], [1, 1.46, 389.5], [2, 1.45, 89.44]], "batl": NaN}, {"timestamp": 1631533786652, "ltp": 1.47, "tv": 32167.35, "trd": NaN, "batb": NaN, "batl": [[0, 1.49, 1411.77], [1, 1.5, 211.76], [2, 1.51, 447.71]]}, {"timestamp": 1631533788337, "ltp": 1.49, "tv": 32187.39, "trd": [[1.49, 4466.82]], "batb": [[0, 1.47, 258.7]], "batl": [[0, 1.49, 1398.73]]}, {"timestamp": 1631533789367, "ltp": 1.49, "tv": 32187.39, "trd": NaN, "batb": [[0, 1.48, 7], [1, 1.47, 258.7], [2, 1.46, 389.5]], "batl": [[0, 1.49, 1596.52]]}, {"timestamp": 1631533792663, "ltp": 1.48, "tv": 32201.39, "trd": [[1.48, 6097.74]], "batb": [[0, 1.47, 213.28], [1, 1.46, 389.5], [2, 1.45, 89.44]], "batl": [[0, 1.48, 213.26], [1, 1.49, 1596.52], [2, 1.5, 211.76]]}, {"timestamp": 1631533793760, "ltp": 1.48, "tv": 32222.77, "trd": [[1.48, 6119.12]], "batb": NaN, "batl": [[0, 1.48, 202.57]]}, {"timestamp": 1631533798677, "ltp": 1.48, "tv": 32627.91, "trd": [[1.48, 6524.26]], "batb": [[0, 1.48, 2636.72], [1, 1.47, 213.28], [2, 1.46, 216.76]], "batl": [[0, 1.49, 1596.52], [1, 1.5, 211.76], [2, 1.51, 447.71]]}, {"timestamp": 1631533801385, "ltp": 1.48, "tv": 32627.91, "trd": NaN, "batb": NaN, "batl": [[0, 1.5, 211.76], [1, 1.51, 447.71], [2, 1.52, 673.72]]}, {"timestamp": 1631533802650, "ltp": 1.5, "tv": 32633.91, "trd": [[1.5, 2075.56]], "batb": [[0, 1.49, 5], [1, 1.48, 2636.72], [2, 1.47, 456.01]], "batl": [[0, 1.5, 205.76]]}, {"timestamp": 1631533804548, "ltp": 1.5, "tv": 32643.91, "trd": [[1.5, 2085.56]], "batb": [[1, 1.48, 2928.2]], "batl": [[0, 1.5, 200.76]]}, {"timestamp": 1631533806074, "ltp": 1.5, "tv": 32643.91, "trd": NaN, "batb": [[0, 1.49, 283.98]], "batl": [[0, 1.51, 447.71], [1, 1.52, 673.72], [2, 1.53, 15]]}, {"timestamp": 1631533815602, "ltp": 1.5, "tv": 32643.91, "trd": NaN, "batb": [[1, 1.48, 291.48], [2, 1.47, 451.01]], "batl": NaN}, {"timestamp": 1631533816359, "ltp": 1.5, "tv": 32643.91, "trd": NaN, "batb": [[1, 1.48, 285.48]], "batl": NaN}, {"timestamp": 1631533817459, "ltp": 1.5, "tv": 32643.91, "trd": NaN, "batb": [[0, 1.45, 89.44], [1, 1.42, 200.25], [2, 1.41, 89.89]], "batl": [[0, 1.52, 365], [1, 1.53, 15], [2, 1.95, 418.98]]}, {"timestamp": 1631533818601, "ltp": 1.5, "tv": 32643.91, "trd": NaN, "batb": [[0, 1.42, 200.25], [1, 1.41, 89.89], [2, 1.38, 449.59]], "batl": [[0, 1.95, 418.98], [1, 2.08, 1], [2, 8.8, 7.23]]}, {"timestamp": 1631533820695, "ltp": 1.5, "tv": 32643.91, "trd": NaN, "batb": [[1, 1.41, 392.13], [2, 1.4, 262.58]], "batl": [[0, 1.59, 193.35], [1, 1.6, 149.43], [2, 1.95, 418.98]]}, {"timestamp": 1631533821700, "ltp": 1.5, "tv": 32643.91, "trd": NaN, "batb": [[1, 1.41, 89.89], [2, 1.38, 449.59]], "batl": [[0, 1.59, 5], [1, 1.95, 418.98], [2, 2.08, 1]]}, {"timestamp": 1631533821864, "ltp": 1.5, "tv": 32643.91, "trd": NaN, "batb": [[0, 1.5, 59.63], [1, 1.42, 200.25], [2, 1.41, 89.89]], "batl": NaN}, {"timestamp": 1631533824578, "ltp": 1.5, "tv": 32643.91, "trd": NaN, "batb": [[1, 1.48, 303.92], [2, 1.47, 210.97]], "batl": [[0, 1.52, 198.5], [1, 1.53, 177.72], [2, 1.59, 5]]}, {"timestamp": 1631533825465, "ltp": 1.5, "tv": 32643.91, "trd": NaN, "batb": NaN, "batl": [[0, 1.52, 158.74], [2, 1.58, 25]]}, {"timestamp": 1631533828170, "ltp": 1.5, "tv": 32643.91, "trd": NaN, "batb": [[1, 1.42, 200.25], [2, 1.41, 89.89]], "batl": [[0, 1.59, 5], [1, 1.95, 418.98], [2, 2.08, 1]]}, {"timestamp": 1631533829604, "ltp": 1.5, "tv": 32643.91, "trd": NaN, "batb": [[0, 1.5, 242.18]], "batl": [[0, 1.52, 189.76], [1, 1.59, 5], [2, 1.95, 418.98]]}, {"timestamp": 1631533829829, "ltp": 1.5, "tv": 32643.91, "trd": NaN, "batb": [[0, 1.5, 59.63]], "batl": [[0, 1.59, 5], [1, 1.95, 418.98], [2, 2.08, 1]]}, {"timestamp": 1631533831413, "ltp": 1.5, "tv": 32643.91, "trd": NaN, "batb": [[2, 1.41, 392.13]], "batl": [[0, 1.59, 198.35], [1, 1.6, 149.43], [2, 1.95, 418.98]]}, {"timestamp": 1631533834912, "ltp": 1.5, "tv": 32643.91, "trd": NaN, "batb": NaN, "batl": [[0, 1.59, 5], [1, 1.95, 418.98], [2, 2.08, 1]]}, {"timestamp": 1631533836378, "ltp": 1.5, "tv": 32643.91, "trd": NaN, "batb": [[0, 1.42, 700.25], [1, 1.41, 392.13], [2, 1.4, 262.58]], "batl": NaN}, {"timestamp": 1631533837587, "ltp": 1.5, "tv": 32643.91, "trd": NaN, "batb": NaN, "batl": [[0, 1.47, 2602.04], [1, 1.48, 2525.5], [2, 1.49, 2525.5]]}, {"timestamp": 1631533838570, "ltp": 1.45, "tv": 32658.39, "trd": [[1.45, 478.86]], "batb": NaN, "batl": [[0, 1.45, 302.14], [1, 1.46, 214.48], [2, 1.47, 1301.02]]}, {"timestamp": 1631533840710, "ltp": 1.45, "tv": 32658.39, "trd": NaN, "batb": [[0, 1.43, 6], [1, 1.42, 707.25], [2, 1.41, 392.13]], "batl": NaN}, {"timestamp": 1631533842591, "ltp": 1.44, "tv": 32670.15, "trd": [[1.44, 154.63]], "batb": [[0, 1.43, 275.81]], "batl": [[0, 1.44, 66.09], [1, 1.45, 501.06], [2, 1.46, 214.48]]}, {"timestamp": 1631533844212, "ltp": 1.44, "tv": 32801.32, "trd": [[1.44, 285.81]], "batb": NaN, "batl": [[0, 1.45, 650.56], [1, 1.46, 214.48], [2, 1.47, 1301.02]]}, {"timestamp": 1631533845613, "ltp": 1.44, "tv": 32801.32, "trd": NaN, "batb": [[2, 1.41, 2885.17]], "batl": NaN}, {"timestamp": 1631533846297, "ltp": 1.44, "tv": 32801.32, "trd": NaN, "batb": [[2, 1.41, 392.13]], "batl": [[1, 1.46, 229.48]]}, {"timestamp": 1631533849419, "ltp": 1.44, "tv": 32801.32, "trd": NaN, "batb": NaN, "batl": [[0, 1.45, 726.89]]}, {"timestamp": 1631533850514, "ltp": 1.44, "tv": 32801.32, "trd": NaN, "batb": [[0, 1.43, 78.33], [1, 1.42, 500], [2, 1.39, 356.69]], "batl": [[0, 1.45, 225.83], [1, 1.46, 15], [2, 1.53, 125.46]]}, {"timestamp": 1631533851529, "ltp": 1.44, "tv": 32801.32, "trd": NaN, "batb": [[0, 1.39, 260.62], [1, 1.38, 228.19], [2, 1.37, 442.05]], "batl": [[0, 1.53, 125.46], [1, 1.54, 157.71], [2, 1.55, 155.43]]}, {"timestamp": 1631533853306, "ltp": 1.44, "tv": 32801.32, "trd": NaN, "batb": NaN, "batl": [[0, 1.52, 281.75], [1, 1.53, 302.58], [2, 1.54, 157.71]]}, {"timestamp": 1631533854622, "ltp": 1.44, "tv": 32801.32, "trd": NaN, "batb": NaN, "batl": [[0, 1.53, 131.46], [1, 1.54, 157.71], [2, 1.55, 155.43]]}, {"timestamp": 1631533855029, "ltp": 1.44, "tv": 32801.32, "trd": NaN, "batb": NaN, "batl": [[0, 1.43, 3.41], [1, 1.53, 131.46], [2, 1.54, 157.71]]}, {"timestamp": 1631533856601, "ltp": 1.44, "tv": 32801.32, "trd": NaN, "batb": [[0, 1.4, 500], [1, 1.39, 260.62], [2, 1.38, 228.19]], "batl": [[1, 1.52, 5], [2, 1.53, 131.46]]}, {"timestamp": 1631533857596, "ltp": 1.44, "tv": 32801.32, "trd": NaN, "batb": [[0, 1.42, 364.86], [1, 1.41, 254.45], [2, 1.4, 500]], "batl": [[1, 1.46, 252.87], [2, 1.47, 208.87]]}, {"timestamp": 1631533857910, "ltp": 1.44, "tv": 32801.32, "trd": NaN, "batb": NaN, "batl": [[1, 1.46, 231.62]]}, {"timestamp": 1631533860412, "ltp": 1.44, "tv": 32801.32, "trd": NaN, "batb": NaN, "batl": [[0, 1.46, 231.62], [1, 1.47, 208.87], [2, 1.52, 5]]}, {"timestamp": 1631533861311, "ltp": 1.44, "tv": 32801.32, "trd": NaN, "batb": [[0, 1.4, 500], [1, 1.39, 260.62], [2, 1.38, 228.19]], "batl": [[0, 1.52, 5], [1, 1.53, 131.46], [2, 1.54, 157.71]]}, {"timestamp": 1631533863514, "ltp": 1.42, "tv": 32808.14, "trd": [[1.42, 105.88]], "batb": [[0, 1.43, 145.16], [1, 1.4, 500], [2, 1.39, 260.62]], "batl": [[0, 1.45, 168.45], [1, 1.52, 5], [2, 1.53, 131.46]]}, {"timestamp": 1631533864510, "ltp": 1.42, "tv": 32808.14, "trd": NaN, "batb": [[0, 1.43, 111.56]], "batl": [[0, 1.52, 286.75], [1, 1.53, 308.58], [2, 1.54, 157.71]]}, {"timestamp": 1631533865707, "ltp": 1.42, "tv": 32808.14, "trd": NaN, "batb": NaN, "batl": [[0, 1.52, 5], [1, 1.53, 6], [2, 1.59, 5]]}, {"timestamp": 1631533867113, "ltp": 1.42, "tv": 32808.14, "trd": NaN, "batb": [[0, 1.4, 500], [1, 1.39, 260.62], [2, 1.38, 228.19]], "batl": [[1, 2.08, 1], [2, 8.8, 7.23]]}, {"timestamp": 1631533868638, "ltp": 1.4, "tv": 33808.14, "trd": [[1.4, 1119.38]], "batb": [[0, 1.38, 228.19], [1, 1.37, 442.05], [2, 1.36, 522.84]], "batl": [[1, 1.54, 12.99], [2, 2.08, 1]]}, {"timestamp": 1631533869559, "ltp": 1.4, "tv": 33808.14, "trd": NaN, "batb": [[0, 1.37, 442.05], [1, 1.36, 522.84], [2, 1.35, 314.57]], "batl": [[0, 1.4, 351.71], [1, 1.41, 249.51], [2, 1.52, 5]]}, {"timestamp": 1631533870642, "ltp": 1.4, "tv": 33808.14, "trd": NaN, "batb": NaN, "batl": [[2, 1.49, 25]]}, {"timestamp": 1631533871943, "ltp": 1.4, "tv": 33808.14, "trd": NaN, "batb": [[0, 1.38, 7], [1, 1.37, 485.29], [2, 1.36, 522.84]], "batl": NaN}, {"timestamp": 1631533873620, "ltp": 1.4, "tv": 33808.14, "trd": NaN, "batb": [[0, 1.38, 297.81]], "batl": [[0, 1.39, 75.19], [1, 1.4, 526.18], [2, 1.41, 264.51]]}, {"timestamp": 1631533874516, "ltp": 1.4, "tv": 33808.14, "trd": NaN, "batb": NaN, "batl": [[2, 1.41, 249.51]]}, {"timestamp": 1631533875557, "ltp": 1.4, "tv": 33808.14, "trd": NaN, "batb": [[1, 1.37, 3334.61]], "batl": NaN}, {"timestamp": 1631533877425, "ltp": 1.4, "tv": 33808.14, "trd": NaN, "batb": [[0, 1.38, 518.42]], "batl": [[0, 1.39, 309.19], [1, 1.4, 541.18]]}, {"timestamp": 1631533878929, "ltp": 1.39, "tv": 33814.09, "trd": [[1.39, 19.95]], "batb": [[2, 1.36, 750.27]], "batl": [[0, 1.39, 306.21]]}, {"timestamp": 1631533880547, "ltp": 1.39, "tv": 33829.89, "trd": [[1.39, 35.75]], "batb": [[0, 1.38, 503.96], [1, 1.37, 3478.26]], "batl": [[0, 1.39, 396.22], [1, 1.4, 610.63]]}, {"timestamp": 1631533881659, "ltp": 1.39, "tv": 33829.89, "trd": NaN, "batb": [[0, 1.38, 378.06], [1, 1.37, 715.71]], "batl": [[1, 1.4, 541.18]]}, {"timestamp": 1631533882527, "ltp": 1.39, "tv": 33829.89, "trd": NaN, "batb": [[0, 1.37, 8], [1, 1.36, 95.68], [2, 1.34, 530.43]], "batl": [[0, 1.39, 226.1], [1, 1.4, 15], [2, 1.45, 159.19]]}, {"timestamp": 1631533883460, "ltp": 1.39, "tv": 33829.89, "trd": NaN, "batb": [[1, 1.34, 530.43], [2, 1.33, 213.12]], "batl": [[0, 1.45, 159.19], [1, 1.46, 145.52], [2, 1.47, 219.11]]}, {"timestamp": 1631533885548, "ltp": 1.37, "tv": 33845.89, "trd": [[1.37, 755.74]], "batb": [[0, 1.36, 9], [2, 1.33, 535.95]], "batl": [[0, 1.37, 7050.83], [1, 1.45, 474.25], [2, 1.46, 359.95]]}, {"timestamp": 1631533886644, "ltp": 1.37, "tv": 33845.89, "trd": NaN, "batb": NaN, "batl": [[1, 1.45, 481.25]]}, {"timestamp": 1631533888671, "ltp": 1.37, "tv": 33845.89, "trd": NaN, "batb": [[1, 1.35, 9], [2, 1.34, 538.43]], "batl": [[0, 1.45, 481.25], [1, 1.46, 359.95], [2, 1.47, 219.11]]}, {"timestamp": 1631533900380, "ltp": 1.37, "tv": 33845.89, "trd": NaN, "batb": [[1, 1.34, 530.43], [2, 1.33, 535.95]], "batl": NaN}, {"timestamp": 1631533901478, "ltp": 1.37, "tv": 33845.89, "trd": NaN, "batb": NaN, "batl": [[0, 1.45, 7], [1, 1.82, 479.32], [2, 2.08, 1]]}, {"timestamp": 1631533903569, "ltp": 1.37, "tv": 33845.89, "trd": NaN, "batb": [[1, 1.35, 7], [2, 1.34, 530.43]], "batl": NaN}, {"timestamp": 1631533904596, "ltp": 1.36, "tv": 33869.4, "trd": [[1.36, 64.41]], "batb": [[0, 1.35, 7], [1, 1.34, 530.43], [2, 1.33, 535.95]], "batl": [[0, 1.36, 264.27], [1, 1.37, 1682.03], [2, 1.38, 1354.92]]}, {"timestamp": 1631533905707, "ltp": 1.36, "tv": 33885.39, "trd": [[1.36, 80.4]], "batb": NaN, "batl": [[0, 1.36, 248.28]]}, {"timestamp": 1631533907577, "ltp": 1.36, "tv": 33885.39, "trd": NaN, "batb": NaN, "batl": [[0, 1.36, 263.28]]}, {"timestamp": 1631533908571, "ltp": 1.36, "tv": 33885.39, "trd": NaN, "batb": [[0, 1.35, 84.42], [1, 1.34, 3617.28]], "batl": [[0, 1.36, 327.56]]}, {"timestamp": 1631533909394, "ltp": 1.36, "tv": 33885.39, "trd": NaN, "batb": [[1, 1.34, 3789.04]], "batl": [[0, 1.36, 519.09]]}, {"timestamp": 1631533910389, "ltp": 1.34, "tv": 34921.59, "trd": [[1.34, 882.35], [1.35, 1508.26]], "batb": [[0, 1.34, 3359.63], [1, 1.33, 535.95], [2, 1.32, 880.94]], "batl": NaN}, {"timestamp": 1631533911377, "ltp": 1.34, "tv": 34921.59, "trd": NaN, "batb": [[1, 1.33, 627.48]], "batl": [[0, 1.36, 739.09]]}, {"timestamp": 1631533913577, "ltp": 1.34, "tv": 34921.59, "trd": NaN, "batb": [[0, 1.34, 3368.63]], "batl": NaN}, {"timestamp": 1631533916493, "ltp": 1.34, "tv": 34921.59, "trd": NaN, "batb": [[0, 1.34, 574.42]], "batl": NaN}, {"timestamp": 1631533917486, "ltp": 1.34, "tv": 36070.44, "trd": [[1.34, 2031.19]], "batb": [[0, 1.33, 623.9], [1, 1.32, 880.94], [2, 1.29, 1.52]], "batl": [[0, 1.34, 2954.98], [1, 1.36, 674.81], [2, 1.37, 1682.03]]}, {"timestamp": 1631533918687, "ltp": 1.34, "tv": 36086.44, "trd": [[1.34, 2047.19]], "batb": NaN, "batl": [[0, 1.34, 2946.98]]}, {"timestamp": 1631533919676, "ltp": 1.34, "tv": 36092.26, "trd": [[1.34, 2053.01]], "batb": [[0, 1.32, 289.53], [1, 1.29, 1.52], [2, 1.28, 487.18]], "batl": [[0, 1.34, 2941.16], [1, 1.36, 235], [2, 1.45, 7]]}, {"timestamp": 1631533920694, "ltp": 1.34, "tv": 39294.7, "trd": [[1.34, 5255.45]], "batb": NaN, "batl": [[0, 1.34, 1339.94], [1, 1.38, 65.75], [2, 1.4, 61.54]]}, {"timestamp": 1631533921608, "ltp": 1.34, "tv": 39294.7, "trd": NaN, "batb": [[0, 1.32, 371.67], [1, 1.31, 72.79], [2, 1.29, 1.52]], "batl": NaN}, {"timestamp": 1631533922603, "ltp": 1.34, "tv": 39463.14, "trd": [[1.34, 5423.89]], "batb": [[0, 1.33, 77.53], [1, 1.32, 82.14], [2, 1.31, 712.29]], "batl": [[0, 1.38, 65.75], [1, 1.39, 250.77], [2, 1.4, 320.04]]}, {"timestamp": 1631533923501, "ltp": 1.34, "tv": 39463.14, "trd": NaN, "batb": [[1, 1.32, 9], [2, 1.31, 720.29]], "batl": [[0, 1.39, 250.77], [1, 1.4, 320.04], [2, 1.41, 60.5]]}, {"timestamp": 1631533924024, "ltp": 1.34, "tv": 39463.14, "trd": NaN, "batb": [[0, 1.34, 3.62], [1, 1.33, 77.53], [2, 1.32, 9]], "batl": NaN}, {"timestamp": 1631533926594, "ltp": 1.34, "tv": 39463.14, "trd": NaN, "batb": NaN, "batl": [[0, 1.39, 6], [1, 1.4, 61.54]]}, {"timestamp": 1631533927598, "ltp": 1.34, "tv": 39463.14, "trd": NaN, "batb": [[0, 1.33, 77.53], [1, 1.32, 509], [2, 1.31, 380.7]], "batl": NaN}, {"timestamp": 1631533929522, "ltp": 1.34, "tv": 39463.14, "trd": NaN, "batb": [[0, 1.34, 185.5], [1, 1.33, 414.04], [2, 1.32, 509]], "batl": [[0, 1.37, 376.57], [1, 1.38, 275.1], [2, 1.39, 6]]}, {"timestamp": 1631533930525, "ltp": 1.34, "tv": 39463.14, "trd": NaN, "batb": [[1, 1.33, 460.69]], "batl": [[1, 1.38, 340.35]]}, {"timestamp": 1631533932305, "ltp": 1.34, "tv": 39463.14, "trd": NaN, "batb": [[0, 1.33, 77.53], [1, 1.32, 509], [2, 1.31, 380.7]], "batl": [[0, 1.39, 6], [1, 1.4, 61.54], [2, 1.41, 60.5]]}, {"timestamp": 1631533933712, "ltp": 1.34, "tv": 39463.14, "trd": NaN, "batb": NaN, "batl": [[0, 1.37, 35.48], [1, 1.39, 6], [2, 1.4, 61.54]]}, {"timestamp": 1631533933920, "ltp": 1.34, "tv": 39463.14, "trd": NaN, "batb": NaN, "batl": [[0, 1.39, 6], [1, 1.4, 61.54], [2, 1.41, 60.5]]}, {"timestamp": 1631533935535, "ltp": 1.34, "tv": 39463.14, "trd": NaN, "batb": [[2, 1.31, 712.29]], "batl": [[0, 1.38, 63.25], [1, 1.39, 256.77], [2, 1.4, 320.04]]}, {"timestamp": 1631533936638, "ltp": 1.34, "tv": 39463.14, "trd": NaN, "batb": NaN, "batl": [[0, 1.39, 256.77], [1, 1.4, 320.04], [2, 1.41, 60.5]]}, {"timestamp": 1631533938624, "ltp": 1.34, "tv": 39463.14, "trd": NaN, "batb": [[2, 1.31, 372.7]], "batl": NaN}, {"timestamp": 1631533940446, "ltp": 1.34, "tv": 39463.14, "trd": NaN, "batb": NaN, "batl": [[0, 1.39, 250.77]]}, {"timestamp": 1631533941333, "ltp": 1.39, "tv": 39478.62, "trd": [[1.39, 51.23]], "batb": [[0, 1.36, 259.12], [1, 1.35, 1729.23], [2, 1.34, 1384.22]], "batl": [[0, 1.39, 235.29]]}, {"timestamp": 1631533942638, "ltp": 1.39, "tv": 39478.62, "trd": NaN, "batb": [[0, 1.36, 503.22], [2, 1.34, 1453.62]], "batl": [[0, 1.39, 250.29]]}, {"timestamp": 1631533943675, "ltp": 1.39, "tv": 39478.62, "trd": NaN, "batb": [[0, 1.37, 7], [1, 1.36, 512.22], [2, 1.35, 1729.23]], "batl": NaN}, {"timestamp": 1631533944472, "ltp": 1.39, "tv": 39478.62, "trd": NaN, "batb": [[0, 1.37, 11.13], [2, 1.35, 1737.23]], "batl": NaN}, {"timestamp": 1631533945446, "ltp": 1.39, "tv": 39478.62, "trd": NaN, "batb": [[0, 1.37, 329.75]], "batl": [[0, 1.38, 498.28], [1, 1.39, 250.29], [2, 1.4, 320.04]]}, {"timestamp": 1631533946587, "ltp": 1.39, "tv": 39478.62, "trd": NaN, "batb": [[1, 1.36, 3351.51]], "batl": [[1, 1.39, 599.19]]}, {"timestamp": 1631533947276, "ltp": 1.39, "tv": 39478.62, "trd": NaN, "batb": NaN, "batl": [[1, 1.39, 775.19]]}, {"timestamp": 1631533948681, "ltp": 1.39, "tv": 39478.62, "trd": NaN, "batb": [[2, 1.35, 1803.3]], "batl": NaN}, {"timestamp": 1631533950657, "ltp": 1.39, "tv": 39478.62, "trd": NaN, "batb": [[2, 1.35, 386.64]], "batl": NaN}, {"timestamp": 1631533951285, "ltp": 1.39, "tv": 39478.62, "trd": NaN, "batb": [[0, 1.37, 72.57], [1, 1.36, 2839.29], [2, 1.35, 74.07]], "batl": [[0, 1.38, 133.65], [1, 1.39, 15], [2, 1.4, 61.54]]}, {"timestamp": 1631533952599, "ltp": 1.39, "tv": 39478.62, "trd": NaN, "batb": NaN, "batl": [[1, 1.4, 61.54], [2, 1.41, 60.5]]}, {"timestamp": 1631533953697, "ltp": 1.36, "tv": 45302.35, "trd": [[1.36, 5758.99], [1.37, 900.89]], "batb": [[0, 1.35, 8], [1, 1.34, 174.41], [2, 1.33, 738.63]], "batl": [[0, 1.36, 617.55], [1, 1.38, 133.65], [2, 1.4, 61.54]]}, {"timestamp": 1631533954574, "ltp": 1.36, "tv": 45310.61, "trd": [[1.36, 5767.25]], "batb": [[1, 1.34, 8], [2, 1.33, 523.99]], "batl": [[0, 1.36, 613.42], [1, 1.4, 61.54], [2, 1.41, 60.5]]}, {"timestamp": 1631533956609, "ltp": 1.36, "tv": 45310.61, "trd": NaN, "batb": [[1, 1.33, 516.99], [2, 1.32, 349.74]], "batl": NaN}, {"timestamp": 1631533958396, "ltp": 1.36, "tv": 45310.61, "trd": NaN, "batb": NaN, "batl": [[0, 1.82, 479.32], [1, 2.08, 1], [2, 8.8, 7.23]]}, {"timestamp": 1631533959075, "ltp": 1.36, "tv": 45310.61, "trd": NaN, "batb": [[1, 1.34, 500], [2, 1.33, 516.99]], "batl": NaN}, {"timestamp": 1631533960600, "ltp": 1.36, "tv": 45310.61, "trd": NaN, "batb": [[0, 1.34, 500], [1, 1.33, 516.99], [2, 1.32, 349.74]], "batl": [[0, 1.37, 2791.98], [1, 1.38, 2709.86], [2, 1.39, 2709.86]]}, {"timestamp": 1631533961601, "ltp": 1.36, "tv": 45349.86, "trd": [[1.36, 5806.5]], "batb": NaN, "batl": [[0, 1.36, 397.84], [1, 1.37, 1680.1], [2, 1.38, 1354.92]]}, {"timestamp": 1631533962606, "ltp": 1.36, "tv": 45349.86, "trd": NaN, "batb": NaN, "batl": [[0, 1.36, 412.84]]}, {"timestamp": 1631533963494, "ltp": 1.36, "tv": 45349.86, "trd": NaN, "batb": NaN, "batl": [[0, 1.36, 397.84]]}, {"timestamp": 1631533964691, "ltp": 1.36, "tv": 45349.86, "trd": NaN, "batb": [[0, 1.34, 636.29]], "batl": [[0, 1.36, 686.06]]}, {"timestamp": 1631533965691, "ltp": 1.36, "tv": 45349.86, "trd": NaN, "batb": [[0, 1.34, 693.14]], "batl": [[0, 1.35, 328.13], [1, 1.36, 766.55], [2, 1.37, 1680.1]]}, {"timestamp": 1631533966325, "ltp": 1.36, "tv": 45349.86, "trd": NaN, "batb": NaN, "batl": [[0, 1.35, 153.59]]}, {"timestamp": 1631533968676, "ltp": 1.36, "tv": 45349.86, "trd": NaN, "batb": [[1, 1.33, 524.99]], "batl": [[2, 1.37, 1739.6]]}, {"timestamp": 1631533969712, "ltp": 1.36, "tv": 45349.86, "trd": NaN, "batb": [[0, 1.34, 767.3]], "batl": [[0, 1.35, 444.59], [1, 1.36, 845.45]]}, {"timestamp": 1631533970021, "ltp": 1.36, "tv": 45349.86, "trd": NaN, "batb": NaN, "batl": [[1, 1.36, 766.55]]}, {"timestamp": 1631533972418, "ltp": 1.35, "tv": 45357.1, "trd": [[1.35, 1515.49]], "batb": NaN, "batl": [[0, 1.35, 712.08]]}, {"timestamp": 1631533973408, "ltp": 1.34, "tv": 46891.68, "trd": [[1.34, 6958.48]], "batb": [[0, 1.33, 524.99], [1, 1.32, 349.74], [2, 1.31, 72.79]], "batl": [[0, 1.34, 2071.72], [1, 1.35, 712.08], [2, 1.36, 686.06]]}, {"timestamp": 1631533975118, "ltp": 1.34, "tv": 46891.68, "trd": NaN, "batb": NaN, "batl": [[0, 1.34, 2636.43], [1, 1.35, 562.11]]}, {"timestamp": 1631533976634, "ltp": 1.34, "tv": 46909.69, "trd": [[1.34, 6976.48]], "batb": [[0, 1.33, 633.36]], "batl": [[0, 1.34, 2899.27]]}, {"timestamp": 1631533977094, "ltp": 1.34, "tv": 46909.69, "trd": NaN, "batb": [[1, 1.32, 2479.21]], "batl": NaN}, {"timestamp": 1631533978704, "ltp": 1.34, "tv": 46909.69, "trd": NaN, "batb": NaN, "batl": [[0, 1.34, 3003.85]]}, {"timestamp": 1631533982431, "ltp": 1.33, "tv": 47615.57, "trd": [[1.33, 1000.14]], "batb": [[0, 1.33, 172.05], [1, 1.32, 2550.13]], "batl": NaN}, {"timestamp": 1631533985635, "ltp": 1.33, "tv": 47615.57, "trd": NaN, "batb": NaN, "batl": [[0, 1.34, 2439.14]]}, {"timestamp": 1631533986527, "ltp": 1.33, "tv": 47615.57, "trd": NaN, "batb": [[1, 1.32, 420.66]], "batl": [[0, 1.34, 376.43]]}, {"timestamp": 1631533989706, "ltp": 1.33, "tv": 47615.57, "trd": NaN, "batb": [[0, 1.33, 296.4]], "batl": [[0, 1.34, 271.84]]}, {"timestamp": 1631533990641, "ltp": 1.33, "tv": 47615.57, "trd": NaN, "batb": [[0, 1.29, 405.26], [1, 1.28, 575.59], [2, 1.2, 2]], "batl": [[0, 1.35, 291], [1, 1.37, 59.5], [2, 1.38, 63.75]]}, {"timestamp": 1631533991525, "ltp": 1.33, "tv": 47615.57, "trd": NaN, "batb": NaN, "batl": [[0, 1.39, 62.5], [1, 1.42, 6], [2, 1.82, 479.32]]}, {"timestamp": 1631533993707, "ltp": 1.33, "tv": 47615.57, "trd": NaN, "batb": [[0, 1.3, 10], [1, 1.29, 455.81], [2, 1.28, 1326.84]], "batl": [[1, 1.4, 382.84], [2, 1.41, 248.87]]}, {"timestamp": 1631533994126, "ltp": 1.33, "tv": 47615.57, "trd": NaN, "batb": [[0, 1.29, 9.52], [1, 1.28, 919.15], [2, 1.2, 2]], "batl": [[1, 1.42, 6], [2, 1.82, 479.32]]}, {"timestamp": 1631533995117, "ltp": 1.33, "tv": 47615.57, "trd": NaN, "batb": NaN, "batl": [[0, 1.33, 50], [1, 1.39, 70.5], [2, 1.42, 6]]}, {"timestamp": 1631533996626, "ltp": 1.33, "tv": 47615.57, "trd": NaN, "batb": NaN, "batl": [[1, 1.34, 41.75], [2, 1.39, 70.5]]}, {"timestamp": 1631533997516, "ltp": 1.33, "tv": 47615.57, "trd": NaN, "batb": NaN, "batl": [[1, 1.39, 70.5], [2, 1.42, 6]]}, {"timestamp": 1631533998347, "ltp": 1.33, "tv": 47615.57, "trd": NaN, "batb": [[0, 1.32, 255.85], [1, 1.31, 365.33], [2, 1.3, 47.6]], "batl": [[1, 1.35, 373.27], [2, 1.36, 294.79]]}, {"timestamp": 1631534000232, "ltp": 1.33, "tv": 47615.57, "trd": NaN, "batb": [[0, 1.29, 9.52], [1, 1.28, 919.15], [2, 1.2, 2]], "batl": [[1, 1.39, 70.5], [2, 1.42, 6]]}, {"timestamp": 1631534001538, "ltp": 1.33, "tv": 47615.57, "trd": NaN, "batb": NaN, "batl": [[0, 1.39, 70.5], [1, 1.42, 6], [2, 1.82, 479.32]]}, {"timestamp": 1631534003472, "ltp": 1.33, "tv": 47615.57, "trd": NaN, "batb": NaN, "batl": [[0, 1.37, 68.5], [1, 1.39, 70.5], [2, 1.42, 6]]}, {"timestamp": 1631534004669, "ltp": 1.3, "tv": 47715.57, "trd": [[1.3, 604.7]], "batb": NaN, "batl": [[0, 1.39, 70.5], [1, 1.42, 6], [2, 1.82, 479.32]]}, {"timestamp": 1631534005665, "ltp": 1.3, "tv": 47715.57, "trd": NaN, "batb": [[0, 1.33, 179.29], [1, 1.32, 349.75], [2, 1.29, 9.52]], "batl": [[0, 1.36, 412.38], [1, 1.37, 284.12], [2, 1.39, 70.5]]}, {"timestamp": 1631534006656, "ltp": 1.3, "tv": 47715.57, "trd": NaN, "batb": [[2, 1.3, 1674.82]], "batl": [[0, 1.34, 23.86], [1, 1.36, 724.81], [2, 1.37, 284.12]]}, {"timestamp": 1631534007440, "ltp": 1.3, "tv": 47715.57, "trd": NaN, "batb": [[2, 1.3, 1722.42]], "batl": [[1, 1.36, 781.92]]}, {"timestamp": 1631534008646, "ltp": 1.3, "tv": 47715.57, "trd": NaN, "batb": NaN, "batl": [[0, 1.35, 293.36]]}, {"timestamp": 1631534008956, "ltp": 1.3, "tv": 47715.57, "trd": NaN, "batb": NaN, "batl": [[1, 1.36, 724.81]]}, {"timestamp": 1631534010642, "ltp": 1.3, "tv": 47715.57, "trd": NaN, "batb": [[0, 1.33, 183.19], [2, 1.3, 1674.82]], "batl": NaN}, {"timestamp": 1631534011376, "ltp": 1.3, "tv": 47715.57, "trd": NaN, "batb": [[0, 1.33, 3.9], [1, 1.29, 9.52], [2, 1.28, 911.15]], "batl": [[0, 1.39, 70.5], [1, 1.82, 479.32], [2, 2.08, 1]]}, {"timestamp": 1631534014161, "ltp": 1.3, "tv": 47715.57, "trd": NaN, "batb": [[1, 1.29, 264.59], [2, 1.28, 1326.84]], "batl": [[1, 1.4, 382.84], [2, 1.41, 248.87]]}, {"timestamp": 1631534017984, "ltp": 1.3, "tv": 47715.57, "trd": NaN, "batb": [[1, 1.29, 9.52], [2, 1.28, 911.15]], "batl": [[0, 1.39, 8]]}, {"timestamp": 1631534019295, "ltp": 1.33, "tv": 47723.37, "trd": [[1.33, 1007.95]], "batb": [[0, 1.29, 9.52], [1, 1.28, 911.15], [2, 1.2, 2]], "batl": [[0, 1.33, 23.36], [1, 1.36, 23.51], [2, 1.39, 8]]}, {"timestamp": 1631534020493, "ltp": 1.36, "tv": 47817.11, "trd": [[1.33, 1054.66], [1.36, 5853.52]], "batb": [[0, 1.36, 2812.5], [1, 1.35, 2729.78], [2, 1.34, 2729.78]], "batl": [[0, 1.4, 382.84], [1, 1.41, 248.87], [2, 1.82, 479.32]]}, {"timestamp": 1631534021695, "ltp": 1.36, "tv": 47817.11, "trd": NaN, "batb": [[0, 1.36, 1798.36], [1, 1.35, 1931.05], [2, 1.34, 3242.68]], "batl": [[2, 1.53, 13.07]]}, {"timestamp": 1631534022699, "ltp": 1.36, "tv": 47817.11, "trd": NaN, "batb": [[2, 1.34, 1364.88]], "batl": NaN}, {"timestamp": 1631534023581, "ltp": 1.36, "tv": 47817.11, "trd": NaN, "batb": [[0, 1.37, 6], [1, 1.36, 1806.36], [2, 1.35, 1931.05]], "batl": [[0, 1.39, 36.24], [1, 1.4, 382.84], [2, 1.41, 248.87]]}, {"timestamp": 1631534025673, "ltp": 1.36, "tv": 47817.11, "trd": NaN, "batb": [[0, 1.37, 72.45], [2, 1.35, 4851.47]], "batl": [[0, 1.38, 273.91], [1, 1.39, 366.17], [2, 1.4, 382.84]]}, {"timestamp": 1631534026687, "ltp": 1.36, "tv": 48801.05, "trd": [[1.36, 6692.56], [1.37, 1045.78]], "batb": [[0, 1.36, 1386.84], [1, 1.35, 4851.47], [2, 1.34, 1364.88]], "batl": [[2, 1.4, 397.84]]}, {"timestamp": 1631534027198, "ltp": 1.36, "tv": 48801.05, "trd": NaN, "batb": NaN, "batl": [[1, 1.39, 567.17]]}, {"timestamp": 1631534027985, "ltp": 1.36, "tv": 48801.05, "trd": NaN, "batb": NaN, "batl": [[0, 1.38, 525.04]]}, {"timestamp": 1631534029713, "ltp": 1.36, "tv": 48801.05, "trd": NaN, "batb": [[0, 1.37, 60.58], [1, 1.36, 1386.84], [2, 1.35, 4851.47]], "batl": [[0, 1.38, 593.53]]}, {"timestamp": 1631534030699, "ltp": 1.36, "tv": 51712.26, "trd": [[1.36, 9474.51], [1.37, 1175.04]], "batb": [[0, 1.35, 4851.47], [1, 1.34, 1364.88], [2, 1.33, 104.44]], "batl": [[0, 1.36, 2065.62], [1, 1.38, 593.53], [2, 1.39, 488.01]]}, {"timestamp": 1631534031593, "ltp": 1.36, "tv": 51712.26, "trd": NaN, "batb": NaN, "batl": [[1, 1.38, 251.13]]}, {"timestamp": 1631534033681, "ltp": 1.36, "tv": 52808.48, "trd": [[1.36, 10570.73]], "batb": [[0, 1.35, 4908.07]], "batl": [[0, 1.36, 1517.51], [1, 1.37, 281.19], [2, 1.38, 251.13]]}, {"timestamp": 1631534034677, "ltp": 1.36, "tv": 52808.48, "trd": NaN, "batb": [[0, 1.35, 575.17], [1, 1.33, 104.44], [2, 1.31, 293.22]], "batl": [[0, 1.37, 281.19], [1, 1.38, 251.13], [2, 1.39, 722.75]]}, {"timestamp": 1631534035408, "ltp": 1.36, "tv": 52808.48, "trd": NaN, "batb": [[0, 1.35, 9.53], [2, 1.31, 292.97]], "batl": [[0, 1.4, 15], [1, 1.82, 479.32], [2, 2.08, 1]]}, {"timestamp": 1631534036712, "ltp": 1.36, "tv": 52808.48, "trd": NaN, "batb": [[0, 1.31, 293.5], [1, 1.29, 1.52], [2, 1.28, 575.59]], "batl": [[0, 1.82, 479.32], [1, 2.08, 1], [2, 8.8, 7.23]]}, {"timestamp": 1631534037605, "ltp": 1.38, "tv": 52809.54, "trd": [[1.38, 636.88]], "batb": [[0, 1.36, 9], [1, 1.31, 292.97], [2, 1.29, 1.52]], "batl": NaN}, {"timestamp": 1631534038699, "ltp": 1.38, "tv": 52809.54, "trd": NaN, "batb": [[0, 1.31, 292.97], [1, 1.29, 1.52], [2, 1.28, 575.59]], "batl": NaN}, {"timestamp": 1631534039479, "ltp": 1.38, "tv": 52809.54, "trd": NaN, "batb": NaN, "batl": [[0, 1.43, 6], [1, 1.82, 479.32], [2, 2.08, 1]]}, {"timestamp": 1631534040686, "ltp": 1.38, "tv": 52809.54, "trd": NaN, "batb": [[0, 1.31, 301.97], [1, 1.3, 9], [2, 1.29, 1.52]], "batl": [[0, 1.4, 4], [1, 1.43, 6], [2, 1.82, 479.32]]}, {"timestamp": 1631534041577, "ltp": 1.38, "tv": 52809.54, "trd": NaN, "batb": [[0, 1.34, 470.9], [1, 1.33, 343.43], [2, 1.31, 301.97]], "batl": [[0, 1.37, 402.94], [1, 1.38, 396.86], [2, 1.39, 268.7]]}, {"timestamp": 1631534042417, "ltp": 1.38, "tv": 52809.54, "trd": NaN, "batb": [[2, 1.32, 71.13]], "batl": NaN}, {"timestamp": 1631534045622, "ltp": 1.38, "tv": 52809.54, "trd": NaN, "batb": [[0, 1.34, 678.9]], "batl": [[0, 1.37, 444.17]]}, {"timestamp": 1631534046512, "ltp": 1.38, "tv": 52809.54, "trd": NaN, "batb": [[2, 1.31, 301.97]], "batl": NaN}, {"timestamp": 1631534047294, "ltp": 1.38, "tv": 52809.54, "trd": NaN, "batb": [[0, 1.31, 301.97], [1, 1.3, 9], [2, 1.29, 1.52]], "batl": [[0, 1.37, 11.57], [1, 1.4, 6], [2, 1.42, 6]]}, {"timestamp": 1631534049695, "ltp": 1.38, "tv": 52809.54, "trd": NaN, "batb": [[0, 1.31, 793.62], [1, 1.3, 397.8]], "batl": [[2, 1.42, 186.87]]}, {"timestamp": 1631534050739, "ltp": 1.38, "tv": 52809.54, "trd": NaN, "batb": NaN, "batl": [[2, 1.42, 6]]}, {"timestamp": 1631534052635, "ltp": 1.38, "tv": 52809.54, "trd": NaN, "batb": [[1, 1.3, 388.8]], "batl": NaN}, {"timestamp": 1631534053628, "ltp": 1.38, "tv": 52809.54, "trd": NaN, "batb": [[2, 1.29, 2966.64]], "batl": [[0, 1.34, 199.55], [1, 1.35, 311.58], [2, 1.37, 11.57]]}, {"timestamp": 1631534054514, "ltp": 1.38, "tv": 52809.54, "trd": NaN, "batb": [[2, 1.29, 1484.08]], "batl": NaN}, {"timestamp": 1631534055416, "ltp": 1.38, "tv": 52809.54, "trd": NaN, "batb": [[0, 1.32, 500], [1, 1.31, 793.62], [2, 1.3, 388.8]], "batl": [[2, 1.36, 15]]}, {"timestamp": 1631534056142, "ltp": 1.38, "tv": 52809.54, "trd": NaN, "batb": [[2, 1.3, 398.8]], "batl": NaN}, {"timestamp": 1631534057706, "ltp": 1.38, "tv": 52809.54, "trd": NaN, "batb": NaN, "batl": [[2, 1.4, 6]]}, {"timestamp": 1631534058644, "ltp": 1.38, "tv": 52809.54, "trd": NaN, "batb": [[0, 1.32, 697.58], [1, 1.31, 869.95]], "batl": [[0, 1.33, 492.79], [1, 1.34, 618.41], [2, 1.35, 373.37]]}, {"timestamp": 1631534059330, "ltp": 1.38, "tv": 52809.54, "trd": NaN, "batb": [[0, 1.32, 705.58]], "batl": [[1, 1.34, 806.41]]}, {"timestamp": 1631534061528, "ltp": 1.38, "tv": 52809.54, "trd": NaN, "batb": [[1, 1.31, 3163.92]], "batl": [[2, 1.35, 388.37]]}, {"timestamp": 1631534062534, "ltp": 1.38, "tv": 52809.54, "trd": NaN, "batb": [[0, 1.32, 785.07]], "batl": [[1, 1.34, 863.59]]}, {"timestamp": 1631534063522, "ltp": 1.33, "tv": 52809.88, "trd": [[1.33, 1055.01]], "batb": [[0, 1.32, 705.58], [1, 1.31, 3087.58]], "batl": [[0, 1.33, 492.44], [2, 1.35, 326.58]]}, {"timestamp": 1631534065552, "ltp": 1.33, "tv": 52909.88, "trd": [[1.33, 1155.01]], "batb": NaN, "batl": [[0, 1.33, 442.44]]}, {"timestamp": 1631534066540, "ltp": 1.33, "tv": 52909.88, "trd": NaN, "batb": [[0, 1.32, 583.6], [1, 1.31, 2207.17], [2, 1.3, 10]], "batl": [[1, 1.34, 245.18], [2, 1.35, 15]]}, {"timestamp": 1631534067530, "ltp": 1.33, "tv": 52909.88, "trd": NaN, "batb": [[0, 1.32, 575.6], [1, 1.29, 1.52], [2, 1.28, 575.59]], "batl": [[1, 1.34, 57.18], [2, 1.37, 72.5]]}, {"timestamp": 1631534067946, "ltp": 1.33, "tv": 52909.88, "trd": NaN, "batb": [[0, 1.32, 75.6]], "batl": NaN}, {"timestamp": 1631534069559, "ltp": 1.33, "tv": 52909.88, "trd": NaN, "batb": [[0, 1.29, 1.52], [1, 1.28, 575.59], [2, 1.27, 348.78]], "batl": [[0, 1.4, 66.69], [1, 1.82, 479.32], [2, 2.08, 1]]}, {"timestamp": 1631534072352, "ltp": 1.33, "tv": 52909.88, "trd": NaN, "batb": [[0, 1.31, 174.9], [1, 1.3, 384.22], [2, 1.29, 1.52]], "batl": [[0, 1.32, 104.59], [1, 1.33, 173.73], [2, 1.34, 323.75]]}, {"timestamp": 1631534073444, "ltp": 1.33, "tv": 52909.88, "trd": NaN, "batb": [[2, 1.29, 9.12]], "batl": NaN}, {"timestamp": 1631534073815, "ltp": 1.33, "tv": 52909.88, "trd": NaN, "batb": [[2, 1.29, 509.12]], "batl": NaN}, {"timestamp": 1631534075523, "ltp": 1.32, "tv": 52969.38, "trd": [[1.32, 80.06]], "batb": [[2, 1.29, 501.52]], "batl": [[0, 1.32, 145.84]]}, {"timestamp": 1631534076658, "ltp": 1.32, "tv": 52969.38, "trd": NaN, "batb": [[0, 1.29, 501.52], [1, 1.28, 586.59], [2, 1.27, 356.78]], "batl": [[0, 1.32, 74.84], [1, 1.37, 68.5], [2, 1.38, 7]]}, {"timestamp": 1631534076923, "ltp": 1.32, "tv": 52969.38, "trd": NaN, "batb": NaN, "batl": [[1, 1.38, 7], [2, 1.39, 7]]}, {"timestamp": 1631534079633, "ltp": 1.32, "tv": 52969.38, "trd": NaN, "batb": [[0, 1.29, 510.52]], "batl": NaN}, {"timestamp": 1631534082070, "ltp": 1.32, "tv": 52969.38, "trd": NaN, "batb": [[0, 1.29, 501.52], [1, 1.28, 775.59], [2, 1.27, 348.78]], "batl": [[1, 1.4, 60.69], [2, 1.82, 479.32]]}, {"timestamp": 1631534083630, "ltp": 1.32, "tv": 52969.38, "trd": NaN, "batb": NaN, "batl": [[1, 1.37, 70.5], [2, 1.4, 60.69]]}, {"timestamp": 1631534084461, "ltp": 1.32, "tv": 52969.38, "trd": NaN, "batb": [[1, 1.28, 575.59]], "batl": [[1, 1.4, 60.69], [2, 1.82, 479.32]]}, {"timestamp": 1631534086648, "ltp": 1.32, "tv": 52969.38, "trd": NaN, "batb": NaN, "batl": [[1, 1.39, 358.47], [2, 1.4, 320.96]]}, {"timestamp": 1631534087636, "ltp": 1.32, "tv": 53119.06, "trd": [[1.32, 229.73]], "batb": [[0, 1.35, 1923.04], [1, 1.29, 501.52], [2, 1.28, 575.59]], "batl": [[0, 1.37, 77.5]]}, {"timestamp": 1631534088677, "ltp": 1.37, "tv": 53127.27, "trd": [[1.37, 1183.25]], "batb": [[0, 1.36, 154.42], [1, 1.35, 1731.24], [2, 1.34, 1375]], "batl": [[0, 1.39, 358.47], [1, 1.4, 320.96], [2, 1.82, 479.32]]}, {"timestamp": 1631534089668, "ltp": 1.37, "tv": 53127.27, "trd": NaN, "batb": [[1, 1.35, 1985.04]], "batl": [[2, 1.53, 13.07]]}, {"timestamp": 1631534091639, "ltp": 1.37, "tv": 53127.27, "trd": NaN, "batb": [[0, 1.36, 162.42], [1, 1.35, 1993.04]], "batl": [[0, 1.39, 408.07], [1, 1.4, 335.96]]}, {"timestamp": 1631534092579, "ltp": 1.37, "tv": 53127.27, "trd": NaN, "batb": [[0, 1.37, 71.73], [1, 1.36, 162.42], [2, 1.35, 4913.46]], "batl": [[0, 1.38, 351.5], [1, 1.39, 800.48], [2, 1.4, 335.96]]}, {"timestamp": 1631534094251, "ltp": 1.37, "tv": 53127.27, "trd": NaN, "batb": NaN, "batl": [[1, 1.39, 724.48]]}, {"timestamp": 1631534095346, "ltp": 1.37, "tv": 53127.27, "trd": NaN, "batb": NaN, "batl": [[0, 1.38, 654.25]]}, {"timestamp": 1631534097486, "ltp": 1.37, "tv": 53127.27, "trd": NaN, "batb": NaN, "batl": [[0, 1.38, 982.17]]}, {"timestamp": 1631534103367, "ltp": 1.37, "tv": 53127.27, "trd": NaN, "batb": [[0, 1.36, 162.42], [1, 1.35, 4905.46], [2, 1.34, 1375]], "batl": [[0, 1.38, 563.75]]}, {"timestamp": 1631534106976, "ltp": 1.37, "tv": 53127.27, "trd": NaN, "batb": NaN, "batl": [[1, 1.39, 788.98]]}, {"timestamp": 1631534110378, "ltp": 1.37, "tv": 53127.27, "trd": NaN, "batb": [[1, 1.35, 1985.04]], "batl": NaN}, {"timestamp": 1631534111575, "ltp": 1.37, "tv": 53127.27, "trd": NaN, "batb": [[0, 1.33, 104.44], [1, 1.31, 374.28], [2, 1.3, 89.68]], "batl": [[0, 1.38, 261], [1, 1.39, 64.5], [2, 1.4, 75.69]]}, {"timestamp": 1631534112511, "ltp": 1.37, "tv": 53127.27, "trd": NaN, "batb": [[0, 1.31, 374.28], [1, 1.3, 89.68], [2, 1.29, 1.52]], "batl": [[0, 1.4, 60.69], [1, 1.42, 56.75], [2, 1.82, 479.32]]}, {"timestamp": 1631534114077, "ltp": 1.37, "tv": 53127.27, "trd": NaN, "batb": [[0, 1.31, 787.05], [1, 1.3, 477.34]], "batl": [[2, 1.43, 233.24]]}, {"timestamp": 1631534115699, "ltp": 1.37, "tv": 53127.27, "trd": NaN, "batb": NaN, "batl": [[0, 1.4, 68.69]]}, {"timestamp": 1631534116387, "ltp": 1.37, "tv": 53127.27, "trd": NaN, "batb": [[2, 1.29, 501.52]], "batl": [[1, 1.43, 233.24], [2, 1.44, 230.32]]}, {"timestamp": 1631534118692, "ltp": 1.37, "tv": 53127.27, "trd": NaN, "batb": NaN, "batl": [[1, 1.82, 479.32], [2, 2.08, 1]]}, {"timestamp": 1631534119675, "ltp": 1.37, "tv": 53127.27, "trd": NaN, "batb": NaN, "batl": [[0, 1.39, 73.5], [1, 1.4, 68.69], [2, 1.82, 479.32]]}, {"timestamp": 1631534119777, "ltp": 1.37, "tv": 53127.27, "trd": NaN, "batb": NaN, "batl": [[0, 1.4, 68.69], [1, 1.82, 479.32], [2, 2.08, 1]]}, {"timestamp": 1631534121717, "ltp": 1.37, "tv": 53127.27, "trd": NaN, "batb": [[2, 1.29, 1316.93]], "batl": [[0, 1.34, 273.36], [1, 1.35, 353.78], [2, 1.4, 246.49]]}, {"timestamp": 1631534122605, "ltp": 1.37, "tv": 53127.27, "trd": NaN, "batb": NaN, "batl": [[2, 1.4, 68.69]]}, {"timestamp": 1631534123389, "ltp": 1.37, "tv": 53127.27, "trd": NaN, "batb": [[2, 1.29, 1428.34]], "batl": [[2, 1.36, 15]]}, {"timestamp": 1631534124495, "ltp": 1.37, "tv": 53127.27, "trd": NaN, "batb": [[0, 1.32, 7], [1, 1.31, 796.05], [2, 1.3, 477.34]], "batl": NaN}, {"timestamp": 1631534125698, "ltp": 1.37, "tv": 53127.27, "trd": NaN, "batb": [[0, 1.32, 285.7]], "batl": [[0, 1.33, 632.55], [1, 1.34, 273.36], [2, 1.35, 353.78]]}, {"timestamp": 1631534126684, "ltp": 1.33, "tv": 53133.58, "trd": [[1.33, 1161.32]], "batb": [[1, 1.31, 1077.88]], "batl": [[0, 1.33, 615.61], [1, 1.34, 675.06]]}, {"timestamp": 1631534127510, "ltp": 1.33, "tv": 53133.58, "trd": NaN, "batb": [[2, 1.3, 2748.78]], "batl": [[1, 1.34, 984.54]]}, {"timestamp": 1631534129394, "ltp": 1.33, "tv": 53133.58, "trd": NaN, "batb": NaN, "batl": [[1, 1.34, 924.54], [2, 1.35, 368.78]]}, {"timestamp": 1631534130718, "ltp": 1.32, "tv": 53147.58, "trd": [[1.32, 243.74]], "batb": [[0, 1.31, 1077.88], [1, 1.3, 2748.78], [2, 1.29, 928.34]], "batl": [[0, 1.32, 75.42], [1, 1.33, 521.47], [2, 1.34, 667.98]]}, {"timestamp": 1631534132410, "ltp": 1.32, "tv": 53147.58, "trd": NaN, "batb": NaN, "batl": [[1, 1.33, 746.47]]}, {"timestamp": 1631534133624, "ltp": 1.32, "tv": 53147.58, "trd": NaN, "batb": [[0, 1.31, 1003.09], [1, 1.3, 2659.1], [2, 1.29, 112.93]], "batl": [[2, 1.34, 522.84]]}, {"timestamp": 1631534134203, "ltp": 1.32, "tv": 53147.58, "trd": NaN, "batb": [[0, 1.31, 281.82], [1, 1.29, 112.93], [2, 1.28, 487.18]], "batl": [[1, 1.33, 264.26], [2, 1.35, 15]]}, {"timestamp": 1631534135508, "ltp": 1.32, "tv": 53147.58, "trd": NaN, "batb": [[1, 1.29, 1.52]], "batl": [[1, 1.33, 28.11], [2, 1.39, 6]]}, {"timestamp": 1631534136986, "ltp": 1.32, "tv": 53147.58, "trd": NaN, "batb": [[0, 1.29, 1.52], [1, 1.28, 487.18], [2, 1.27, 292.87]], "batl": [[0, 1.39, 6], [1, 1.4, 461.23], [2, 1.41, 251.56]]}, {"timestamp": 1631534138714, "ltp": 1.32, "tv": 53147.58, "trd": NaN, "batb": NaN, "batl": [[0, 1.37, 67.5], [1, 1.39, 6], [2, 1.4, 461.23]]}, {"timestamp": 1631534138978, "ltp": 1.32, "tv": 53147.58, "trd": NaN, "batb": NaN, "batl": [[0, 1.39, 6], [1, 1.4, 461.23], [2, 1.41, 251.56]]}, {"timestamp": 1631534145672, "ltp": 1.32, "tv": 53147.58, "trd": NaN, "batb": NaN, "batl": [[0, 1.37, 64.5], [1, 1.39, 6], [2, 1.4, 461.23]]}, {"timestamp": 1631534145994, "ltp": 1.32, "tv": 53147.58, "trd": NaN, "batb": NaN, "batl": [[0, 1.39, 6], [1, 1.4, 461.23], [2, 1.41, 251.56]]}, {"timestamp": 1631534150293, "ltp": 1.32, "tv": 53147.58, "trd": NaN, "batb": NaN, "batl": [[1, 1.82, 479.32], [2, 2.08, 1]]}, {"timestamp": 1631534151609, "ltp": 1.32, "tv": 53147.58, "trd": NaN, "batb": [[1, 1.27, 292.87], [2, 1.26, 555.36]], "batl": [[1, 2.08, 1], [2, 8.8, 7.23]]}, {"timestamp": 1631534152601, "ltp": 1.29, "tv": 53150.62, "trd": [[1.29, 6.9]], "batb": [[0, 1.27, 292.87], [1, 1.26, 555.36], [2, 1.25, 973.75]], "batl": NaN}, {"timestamp": 1631534153708, "ltp": 1.29, "tv": 53150.62, "trd": NaN, "batb": NaN, "batl": [[0, 1.29, 510.28], [1, 1.3, 1846.14], [2, 1.31, 1427.88]]}, {"timestamp": 1631534154599, "ltp": 1.29, "tv": 53150.62, "trd": NaN, "batb": NaN, "batl": [[1, 1.3, 1861.14]]}, {"timestamp": 1631534157717, "ltp": 1.29, "tv": 53150.62, "trd": NaN, "batb": NaN, "batl": [[0, 1.28, 365.18], [1, 1.29, 1083.66], [2, 1.3, 2145.13]]}, {"timestamp": 1631534158611, "ltp": 1.28, "tv": 53169.29, "trd": [[1.28, 18.67]], "batb": [[1, 1.26, 833.81]], "batl": [[0, 1.28, 346.51], [1, 1.29, 1145.48]]}, {"timestamp": 1631534159601, "ltp": 1.28, "tv": 53169.29, "trd": NaN, "batb": [[2, 1.25, 3699.48]], "batl": [[1, 1.29, 1269.48]]}, {"timestamp": 1631534160704, "ltp": 1.28, "tv": 53220.89, "trd": [[1.28, 70.27]], "batb": [[0, 1.27, 595.05]], "batl": [[0, 1.28, 586.82]]}, {"timestamp": 1631534161382, "ltp": 1.28, "tv": 53220.89, "trd": NaN, "batb": NaN, "batl": [[1, 1.29, 1284.48]]}, {"timestamp": 1631534162433, "ltp": 1.28, "tv": 53220.89, "trd": NaN, "batb": [[1, 1.26, 555.36]], "batl": [[2, 1.3, 1846.14]]}, {"timestamp": 1631534163357, "ltp": 1.28, "tv": 53220.89, "trd": NaN, "batb": [[1, 1.26, 753.83]], "batl": NaN}, {"timestamp": 1631534164194, "ltp": 1.28, "tv": 53220.89, "trd": NaN, "batb": [[0, 1.27, 351.76], [2, 1.25, 4096.41]], "batl": NaN}, {"timestamp": 1631534168590, "ltp": 1.28, "tv": 53220.89, "trd": NaN, "batb": [[0, 1.27, 292.87]], "batl": [[0, 1.28, 266.11], [1, 1.29, 986.02]]}, {"timestamp": 1631534176314, "ltp": 1.28, "tv": 53220.89, "trd": NaN, "batb": [[2, 1.25, 1370.69]], "batl": [[0, 1.29, 986.02], [1, 1.3, 1846.14], [2, 1.31, 1427.88]]}, {"timestamp": 1631534178624, "ltp": 1.28, "tv": 53220.89, "trd": NaN, "batb": [[0, 1.27, 200], [1, 1.26, 198.47], [2, 1.25, 772.58]], "batl": [[0, 1.29, 139], [1, 1.32, 87.86], [2, 1.34, 74.75]]}, {"timestamp": 1631534179514, "ltp": 1.27, "tv": 53229.16, "trd": [[1.27, 8.26]], "batb": [[0, 1.27, 195.87], [2, 1.25, 396.93]], "batl": [[0, 1.34, 74.75], [1, 1.35, 76.7], [2, 1.36, 7]]}, {"timestamp": 1631534181651, "ltp": 1.27, "tv": 53229.16, "trd": NaN, "batb": [[1, 1.22, 524.8], [2, 1.21, 110.69]], "batl": NaN}, {"timestamp": 1631534183225, "ltp": 1.27, "tv": 53229.16, "trd": NaN, "batb": NaN, "batl": [[0, 1.34, 83.75]]}, {"timestamp": 1631534184645, "ltp": 1.27, "tv": 53229.16, "trd": NaN, "batb": [[1, 1.25, 451.24], [2, 1.24, 514.26]], "batl": [[0, 1.28, 1424.78], [1, 1.29, 390.32], [2, 1.34, 83.75]]}, {"timestamp": 1631534185428, "ltp": 1.27, "tv": 53229.16, "trd": NaN, "batb": NaN, "batl": [[0, 1.28, 1403.94]]}, {"timestamp": 1631534186415, "ltp": 1.27, "tv": 53229.16, "trd": NaN, "batb": NaN, "batl": [[2, 1.32, 76.86]]}, {"timestamp": 1631534188454, "ltp": 1.27, "tv": 53229.16, "trd": NaN, "batb": NaN, "batl": [[0, 1.28, 604.88]]}, {"timestamp": 1631534189655, "ltp": 1.27, "tv": 53229.16, "trd": NaN, "batb": [[1, 1.23, 236.8], [2, 1.22, 524.8]], "batl": [[0, 1.28, 88.94], [1, 1.33, 198.47], [2, 1.34, 83.75]]}, {"timestamp": 1631534191672, "ltp": 1.27, "tv": 53229.16, "trd": NaN, "batb": NaN, "batl": [[0, 1.28, 331.94]]}, {"timestamp": 1631534192245, "ltp": 1.27, "tv": 53229.16, "trd": NaN, "batb": NaN, "batl": [[0, 1.28, 88.94], [2, 1.34, 354.26]]}, {"timestamp": 1631534197345, "ltp": 1.27, "tv": 53229.16, "trd": NaN, "batb": [[2, 1.21, 650.17]], "batl": NaN}, {"timestamp": 1631534198660, "ltp": 1.27, "tv": 53229.16, "trd": NaN, "batb": [[1, 1.21, 650.17], [2, 1.2, 1107.99]], "batl": [[1, 1.34, 354.26], [2, 1.35, 387.4]]}, {"timestamp": 1631534200448, "ltp": 1.27, "tv": 53229.16, "trd": NaN, "batb": [[1, 1.21, 110.69], [2, 1.2, 502]], "batl": [[0, 1.34, 354.26], [1, 1.35, 387.4], [2, 1.49, 2.99]]}, {"timestamp": 1631534201878, "ltp": 1.27, "tv": 53229.16, "trd": NaN, "batb": NaN, "batl": [[0, 1.34, 345.26]]}, {"timestamp": 1631534203557, "ltp": 1.27, "tv": 53229.16, "trd": NaN, "batb": [[0, 1.31, 484.51], [1, 1.3, 1858.83], [2, 1.29, 1427.88]], "batl": NaN}, {"timestamp": 1631534204656, "ltp": 1.27, "tv": 53229.16, "trd": NaN, "batb": [[1, 1.3, 2161.59]], "batl": [[1, 1.35, 402.4], [2, 1.48, 13.51]]}, {"timestamp": 1631534205553, "ltp": 1.27, "tv": 53229.16, "trd": NaN, "batb": NaN, "batl": [[0, 1.34, 390.15]]}, {"timestamp": 1631534206462, "ltp": 1.27, "tv": 53229.16, "trd": NaN, "batb": [[0, 1.32, 9], [1, 1.31, 494.51], [2, 1.3, 4433.03]], "batl": NaN}, {"timestamp": 1631534207552, "ltp": 1.27, "tv": 53229.16, "trd": NaN, "batb": [[0, 1.32, 73.67]], "batl": [[0, 1.33, 389.22], [1, 1.34, 798.66], [2, 1.35, 402.4]]}, {"timestamp": 1631534208555, "ltp": 1.27, "tv": 53229.16, "trd": NaN, "batb": [[1, 1.31, 571.98]], "batl": NaN}, {"timestamp": 1631534210482, "ltp": 1.27, "tv": 53229.16, "trd": NaN, "batb": NaN, "batl": [[0, 1.33, 619.38]]}, {"timestamp": 1631534212375, "ltp": 1.27, "tv": 53229.16, "trd": NaN, "batb": [[1, 1.31, 494.51]], "batl": [[1, 1.34, 718.29]]}, {"timestamp": 1631534213887, "ltp": 1.27, "tv": 53229.16, "trd": NaN, "batb": [[2, 1.3, 2161.59]], "batl": NaN}, {"timestamp": 1631534215155, "ltp": 1.33, "tv": 53234.93, "trd": [[1.33, 1167.1]], "batb": [[1, 1.31, 425.79]], "batl": [[0, 1.33, 616.5]]}, {"timestamp": 1631534218594, "ltp": 1.33, "tv": 53234.93, "trd": NaN, "batb": [[0, 1.32, 9], [1, 1.31, 415.79]], "batl": [[0, 1.33, 230.16]]}, {"timestamp": 1631534221569, "ltp": 1.33, "tv": 53234.93, "trd": NaN, "batb": NaN, "batl": [[1, 1.34, 627.29]]}, {"timestamp": 1631534223572, "ltp": 1.33, "tv": 53234.93, "trd": NaN, "batb": [[0, 1.29, 111.41], [1, 1.27, 195.87], [2, 1.26, 334.65]], "batl": [[0, 1.35, 15], [1, 1.38, 65.75], [2, 1.49, 2.99]]}, {"timestamp": 1631534224567, "ltp": 1.33, "tv": 53234.93, "trd": NaN, "batb": [[0, 1.27, 195.87], [1, 1.26, 334.65], [2, 1.25, 377.57]], "batl": [[0, 1.38, 65.75], [1, 1.49, 2.99], [2, 1.62, 618.19]]}, {"timestamp": 1631534226699, "ltp": 1.33, "tv": 53234.93, "trd": NaN, "batb": [[1, 1.26, 785.42], [2, 1.25, 866.38]], "batl": [[1, 1.4, 398], [2, 1.41, 251.59]]}, {"timestamp": 1631534227697, "ltp": 1.33, "tv": 53234.93, "trd": NaN, "batb": [[0, 1.27, 705.87], [1, 1.26, 793.42]], "batl": NaN}, {"timestamp": 1631534229113, "ltp": 1.33, "tv": 53234.93, "trd": NaN, "batb": [[1, 1.26, 342.65], [2, 1.25, 377.57]], "batl": [[0, 1.38, 274.44]]}, {"timestamp": 1631534230678, "ltp": 1.36, "tv": 53388.07, "trd": [[1.36, 10723.87]], "batb": [[0, 1.36, 5861.59], [1, 1.27, 705.87], [2, 1.26, 96.48]], "batl": [[0, 1.38, 65.75]]}, {"timestamp": 1631534231685, "ltp": 1.38, "tv": 53396.31, "trd": [[1.38, 645.12]], "batb": [[0, 1.36, 2812.5], [1, 1.35, 2729.78], [2, 1.34, 2729.78]], "batl": [[0, 1.38, 57.51]]}, {"timestamp": 1631534232677, "ltp": 1.38, "tv": 53396.31, "trd": NaN, "batb": [[0, 1.36, 1794.8], [1, 1.35, 1681.94], [2, 1.34, 1364.88]], "batl": NaN}, {"timestamp": 1631534233672, "ltp": 1.38, "tv": 53396.31, "trd": NaN, "batb": [[0, 1.36, 1871.23], [1, 1.35, 1936.66]], "batl": [[2, 1.41, 266.59]]}, {"timestamp": 1631534234715, "ltp": 1.38, "tv": 53396.31, "trd": NaN, "batb": [[0, 1.36, 1794.8]], "batl": NaN}, {"timestamp": 1631534235321, "ltp": 1.38, "tv": 53396.31, "trd": NaN, "batb": [[0, 1.37, 8], [1, 1.36, 1803.8], [2, 1.35, 1936.66]], "batl": NaN}, {"timestamp": 1631534236676, "ltp": 1.37, "tv": 53412.31, "trd": [[1.37, 1199.25]], "batb": [[0, 1.36, 1883.78], [1, 1.35, 2011.53], [2, 1.34, 1364.88]], "batl": [[0, 1.37, 288.83], [1, 1.38, 289.47], [2, 1.39, 56.86]]}, {"timestamp": 1631534237581, "ltp": 1.37, "tv": 53412.31, "trd": NaN, "batb": [[0, 1.36, 4723.08]], "batl": NaN}, {"timestamp": 1631534238577, "ltp": 1.37, "tv": 53420.41, "trd": [[1.37, 1207.35]], "batb": NaN, "batl": [[0, 1.37, 280.73]]}, {"timestamp": 1631534239447, "ltp": 1.37, "tv": 53420.41, "trd": NaN, "batb": [[2, 1.34, 1467.77]], "batl": NaN}, {"timestamp": 1631534240670, "ltp": 1.37, "tv": 53420.41, "trd": NaN, "batb": [[0, 1.36, 4803.09]], "batl": [[0, 1.37, 582.73], [1, 1.38, 365.16], [2, 1.39, 116.36]]}, {"timestamp": 1631534240985, "ltp": 1.37, "tv": 53420.41, "trd": NaN, "batb": [[0, 1.36, 4723.08], [1, 1.35, 1936.66]], "batl": [[1, 1.38, 289.47], [2, 1.39, 59.5]]}, {"timestamp": 1631534243699, "ltp": 1.37, "tv": 53420.41, "trd": NaN, "batb": [[0, 1.36, 2928.28], [1, 1.35, 254.72], [2, 1.34, 102.89]], "batl": [[1, 1.38, 231.96]]}, {"timestamp": 1631534244697, "ltp": 1.37, "tv": 53420.41, "trd": NaN, "batb": [[0, 1.36, 79.98], [1, 1.31, 305.22], [2, 1.3, 305.35]], "batl": [[0, 1.37, 280.73], [1, 1.38, 61.36]]}, {"timestamp": 1631534246590, "ltp": 1.37, "tv": 53420.41, "trd": NaN, "batb": [[0, 1.31, 697.15], [1, 1.3, 692.81], [2, 1.29, 10]], "batl": NaN}, {"timestamp": 1631534247599, "ltp": 1.37, "tv": 53420.41, "trd": NaN, "batb": [[0, 1.31, 305.22], [1, 1.3, 305.35]], "batl": [[0, 1.36, 29.75], [1, 1.41, 304.82], [2, 1.42, 57.25]]}, {"timestamp": 1631534249634, "ltp": 1.37, "tv": 53420.41, "trd": NaN, "batb": NaN, "batl": [[1, 1.41, 59.5]]}, {"timestamp": 1631534250516, "ltp": 1.37, "tv": 53420.41, "trd": NaN, "batb": [[0, 1.35, 368.8], [1, 1.34, 329.24], [2, 1.31, 312.22]], "batl": [[1, 1.38, 183.78], [2, 1.39, 343.34]]}, {"timestamp": 1631534251619, "ltp": 1.37, "tv": 53420.41, "trd": NaN, "batb": [[2, 1.32, 86.62]], "batl": NaN}, {"timestamp": 1631534254497, "ltp": 1.37, "tv": 53420.41, "trd": NaN, "batb": [[0, 1.31, 312.22], [1, 1.3, 313.35], [2, 1.29, 10]], "batl": [[1, 1.39, 72.5], [2, 1.41, 59.5]]}, {"timestamp": 1631534254816, "ltp": 1.37, "tv": 53420.41, "trd": NaN, "batb": NaN, "batl": [[1, 1.41, 59.5], [2, 1.43, 227.43]]}, {"timestamp": 1631534257634, "ltp": 1.37, "tv": 53420.41, "trd": NaN, "batb": [[0, 1.31, 697.15], [1, 1.3, 700.81]], "batl": NaN}, {"timestamp": 1631534259040, "ltp": 1.37, "tv": 53420.41, "trd": NaN, "batb": [[0, 1.31, 469.72]], "batl": [[2, 1.49, 2.99]]}, {"timestamp": 1631534260714, "ltp": 1.37, "tv": 53420.41, "trd": NaN, "batb": [[2, 1.29, 825.41]], "batl": [[0, 1.34, 293.13], [1, 1.35, 310.6], [2, 1.36, 29.75]]}, {"timestamp": 1631534261708, "ltp": 1.37, "tv": 53420.41, "trd": NaN, "batb": [[2, 1.29, 926.82]], "batl": [[2, 1.36, 44.75]]}, {"timestamp": 1631534262330, "ltp": 1.37, "tv": 53420.41, "trd": NaN, "batb": NaN, "batl": [[1, 1.35, 310.52]]}, {"timestamp": 1631534263107, "ltp": 1.37, "tv": 53420.41, "trd": NaN, "batb": [[0, 1.32, 8], [1, 1.31, 469.72], [2, 1.3, 700.81]], "batl": NaN}, {"timestamp": 1631534264620, "ltp": 1.37, "tv": 53420.41, "trd": NaN, "batb": [[0, 1.32, 70.74], [1, 1.31, 477.72]], "batl": [[0, 1.33, 363.74], [1, 1.34, 293.13], [2, 1.35, 310.52]]}, {"timestamp": 1631534265517, "ltp": 1.37, "tv": 53420.41, "trd": NaN, "batb": [[1, 1.31, 633.04]], "batl": [[1, 1.34, 779.43]]}, {"timestamp": 1631534266607, "ltp": 1.37, "tv": 53420.41, "trd": NaN, "batb": [[2, 1.3, 2972.25]], "batl": [[1, 1.34, 779.35]]}, {"timestamp": 1631534268431, "ltp": 1.37, "tv": 53420.41, "trd": NaN, "batb": NaN, "batl": [[0, 1.33, 923.36], [2, 1.35, 325.52]]}, {"timestamp": 1631534269422, "ltp": 1.37, "tv": 53420.41, "trd": NaN, "batb": NaN, "batl": [[0, 1.33, 923.44]]}, {"timestamp": 1631534270940, "ltp": 1.37, "tv": 53420.41, "trd": NaN, "batb": NaN, "batl": [[1, 1.34, 710.5]]}, {"timestamp": 1631534272562, "ltp": 1.37, "tv": 53420.41, "trd": NaN, "batb": [[0, 1.32, 126.66]], "batl": [[0, 1.33, 994.67]]}, {"timestamp": 1631534272769, "ltp": 1.37, "tv": 53420.41, "trd": NaN, "batb": [[0, 1.32, 70.74], [1, 1.31, 559.04]], "batl": [[0, 1.33, 923.44]]}, {"timestamp": 1631534274745, "ltp": 1.37, "tv": 53420.41, "trd": NaN, "batb": [[0, 1.32, 8]], "batl": [[0, 1.33, 559.7]]}, {"timestamp": 1631534280033, "ltp": 1.37, "tv": 53420.41, "trd": NaN, "batb": [[1, 1.31, 551.04], [2, 1.3, 692.81]], "batl": NaN}, {"timestamp": 1631534283266, "ltp": 1.37, "tv": 53420.41, "trd": NaN, "batb": [[1, 1.31, 558.04]], "batl": NaN}, {"timestamp": 1631534284581, "ltp": 1.37, "tv": 53420.41, "trd": NaN, "batb": [[0, 1.29, 111.41], [1, 1.28, 434.41], [2, 1.27, 195.87]], "batl": [[0, 1.33, 238.08], [1, 1.35, 15], [2, 1.36, 69.07]]}, {"timestamp": 1631534285540, "ltp": 1.37, "tv": 53420.41, "trd": NaN, "batb": [[0, 1.28, 434.41], [1, 1.27, 195.87], [2, 1.26, 88.48]], "batl": [[0, 1.37, 179.81], [1, 1.38, 64.75], [2, 1.39, 59.5]]}, {"timestamp": 1631534287335, "ltp": 1.37, "tv": 53420.41, "trd": NaN, "batb": [[2, 1.26, 516.15]], "batl": [[2, 1.39, 217.47]]}, {"timestamp": 1631534288550, "ltp": 1.37, "tv": 53420.41, "trd": NaN, "batb": [[0, 1.29, 10], [1, 1.28, 445.41], [2, 1.27, 203.87]], "batl": [[2, 1.39, 59.5]]}, {"timestamp": 1631534291455, "ltp": 1.37, "tv": 53420.41, "trd": NaN, "batb": [[0, 1.3, 383.26], [1, 1.29, 414.46], [2, 1.28, 445.41]], "batl": [[0, 1.32, 427.66], [1, 1.33, 339.76], [2, 1.34, 321.71]]}, {"timestamp": 1631534292659, "ltp": 1.37, "tv": 53420.41, "trd": NaN, "batb": [[1, 1.29, 461.06]], "batl": [[1, 1.33, 339.68]]}, {"timestamp": 1631534294491, "ltp": 1.37, "tv": 53420.41, "trd": NaN, "batb": [[0, 1.29, 10], [1, 1.28, 445.41], [2, 1.27, 203.87]], "batl": [[1, 1.36, 75.07], [2, 1.37, 179.73]]}, {"timestamp": 1631534295551, "ltp": 1.37, "tv": 53420.41, "trd": NaN, "batb": NaN, "batl": [[0, 1.32, 300.55]]}, {"timestamp": 1631534301571, "ltp": 1.37, "tv": 53420.41, "trd": NaN, "batb": NaN, "batl": [[0, 1.36, 75.15], [1, 1.37, 179.73], [2, 1.38, 64.75]]}, {"timestamp": 1631534302570, "ltp": 1.37, "tv": 53420.41, "trd": NaN, "batb": [[1, 1.28, 434.41], [2, 1.27, 195.87]], "batl": [[0, 1.38, 64.83], [1, 1.39, 217.47], [2, 1.4, 262.19]]}, {"timestamp": 1631534303675, "ltp": 1.32, "tv": 53420.57, "trd": [[1.32, 243.9]], "batb": [[0, 1.36, 18.24], [1, 1.29, 10], [2, 1.28, 434.41]], "batl": [[0, 1.38, 64.75]]}, {"timestamp": 1631534304676, "ltp": 1.32, "tv": 53420.57, "trd": NaN, "batb": [[0, 1.36, 412.3], [1, 1.35, 1733.61], [2, 1.34, 1389.22]], "batl": NaN}, {"timestamp": 1631534305698, "ltp": 1.32, "tv": 53420.57, "trd": NaN, "batb": [[1, 1.35, 1991.85]], "batl": NaN}, {"timestamp": 1631534307002, "ltp": 1.36, "tv": 53457.05, "trd": [[1.36, 10760.35]], "batb": [[0, 1.37, 8], [1, 1.36, 402.06], [2, 1.35, 1991.85]], "batl": NaN}, {"timestamp": 1631534308613, "ltp": 1.37, "tv": 53473.05, "trd": [[1.37, 1223.35]], "batb": [[0, 1.36, 473.85], [1, 1.35, 1991.85], [2, 1.34, 1389.22]], "batl": [[0, 1.37, 272.73], [1, 1.38, 134.82], [2, 1.39, 236.77]]}, {"timestamp": 1631534309706, "ltp": 1.37, "tv": 53473.05, "trd": NaN, "batb": [[1, 1.35, 2062.09]], "batl": [[1, 1.38, 328.75]]}, {"timestamp": 1631534310179, "ltp": 1.37, "tv": 53481.15, "trd": [[1.37, 1231.45]], "batb": [[1, 1.35, 4982.5]], "batl": [[0, 1.37, 264.63], [1, 1.38, 604.75]]}, {"timestamp": 1631534312318, "ltp": 1.37, "tv": 53481.15, "trd": NaN, "batb": [[2, 1.34, 1492.11]], "batl": [[2, 1.39, 302.27]]}, {"timestamp": 1631534314901, "ltp": 1.37, "tv": 53481.15, "trd": NaN, "batb": NaN, "batl": [[2, 1.39, 223.47]]}, {"timestamp": 1631534316580, "ltp": 1.37, "tv": 53481.15, "trd": NaN, "batb": [[0, 1.36, 446.29], [1, 1.35, 4912.27]], "batl": NaN}, {"timestamp": 1631534317631, "ltp": 1.37, "tv": 53481.15, "trd": NaN, "batb": [[0, 1.36, 71.79], [1, 1.35, 2920.42], [2, 1.34, 102.89]], "batl": [[1, 1.38, 346.07], [2, 1.39, 65.5]]}, {"timestamp": 1631534318609, "ltp": 1.37, "tv": 53481.15, "trd": NaN, "batb": [[0, 1.32, 512.75], [1, 1.31, 214.34], [2, 1.3, 576.02]], "batl": [[0, 1.39, 65.5], [1, 1.4, 62.94], [2, 1.41, 59.5]]}, {"timestamp": 1631534319029, "ltp": 1.37, "tv": 53481.15, "trd": NaN, "batb": NaN, "batl": [[0, 1.41, 59.5], [1, 1.45, 156.76], [2, 1.46, 176.23]]}, {"timestamp": 1631534320615, "ltp": 1.37, "tv": 53481.15, "trd": NaN, "batb": [[1, 1.31, 592.66], [2, 1.3, 963.28]], "batl": [[1, 1.45, 479.06], [2, 1.46, 392.7]]}, {"timestamp": 1631534321124, "ltp": 1.37, "tv": 53481.15, "trd": NaN, "batb": [[2, 1.3, 962.36]], "batl": NaN}, {"timestamp": 1631534322707, "ltp": 1.37, "tv": 53481.15, "trd": NaN, "batb": [[0, 1.33, 7], [1, 1.32, 521.75], [2, 1.31, 602.66]], "batl": [[1, 1.49, 2.99], [2, 1.62, 618.19]]}, {"timestamp": 1631534323698, "ltp": 1.37, "tv": 53481.15, "trd": NaN, "batb": [[0, 1.37, 6.51], [1, 1.32, 275.1], [2, 1.31, 592.66]], "batl": [[1, 1.42, 210.39], [2, 1.49, 2.99]]}, {"timestamp": 1631534324530, "ltp": 1.37, "tv": 53481.15, "trd": NaN, "batb": [[1, 1.33, 500], [2, 1.32, 196.46]], "batl": NaN}, {"timestamp": 1631534325632, "ltp": 1.37, "tv": 53494.16, "trd": [[1.37, 1244.47]], "batb": [[0, 1.33, 500], [1, 1.32, 196.46], [2, 1.31, 592.66]], "batl": [[0, 1.34, 305.86], [1, 1.35, 310.37], [2, 1.41, 59.5]]}, {"timestamp": 1631534328626, "ltp": 1.37, "tv": 53494.16, "trd": NaN, "batb": NaN, "batl": [[2, 1.4, 6]]}, {"timestamp": 1631534330618, "ltp": 1.37, "tv": 53494.16, "trd": NaN, "batb": [[0, 1.33, 557.39], [1, 1.32, 263.19]], "batl": [[0, 1.34, 636.27], [1, 1.35, 615.89], [2, 1.36, 15]]}, {"timestamp": 1631534331617, "ltp": 1.37, "tv": 53494.16, "trd": NaN, "batb": NaN, "batl": [[0, 1.34, 682.6], [2, 1.38, 218.91]]}, {"timestamp": 1631534332606, "ltp": 1.34, "tv": 53509.84, "trd": [[1.34, 6992.16]], "batb": NaN, "batl": [[0, 1.34, 913.76], [2, 1.37, 61.5]]}, {"timestamp": 1631534334637, "ltp": 1.34, "tv": 53509.84, "trd": NaN, "batb": NaN, "batl": [[1, 1.35, 630.89]]}, {"timestamp": 1631534335331, "ltp": 1.34, "tv": 53509.84, "trd": NaN, "batb": [[1, 1.32, 196.46]], "batl": [[0, 1.34, 1159.76], [1, 1.35, 572.4]]}, {"timestamp": 1631534337154, "ltp": 1.34, "tv": 53509.84, "trd": NaN, "batb": [[1, 1.32, 205.46], [2, 1.31, 601.66]], "batl": NaN}, {"timestamp": 1631534338517, "ltp": 1.34, "tv": 53509.84, "trd": NaN, "batb": NaN, "batl": [[0, 1.34, 1240.23]]}, {"timestamp": 1631534340463, "ltp": 1.34, "tv": 53509.84, "trd": NaN, "batb": [[0, 1.33, 500]], "batl": [[0, 1.34, 850.02]]}, {"timestamp": 1631534344728, "ltp": 1.34, "tv": 53509.84, "trd": NaN, "batb": NaN, "batl": [[0, 1.34, 1056.78]]}, {"timestamp": 1631534346767, "ltp": 1.34, "tv": 53509.84, "trd": NaN, "batb": NaN, "batl": [[1, 1.35, 788.75]]}, {"timestamp": 1631534347868, "ltp": 1.33, "tv": 53551.18, "trd": [[1.33, 1208.44]], "batb": [[0, 1.33, 479.33]], "batl": NaN}, {"timestamp": 1631534349240, "ltp": 1.33, "tv": 53551.18, "trd": NaN, "batb": [[2, 1.31, 592.66]], "batl": [[2, 1.36, 237.65]]}, {"timestamp": 1631534352427, "ltp": 1.33, "tv": 53551.18, "trd": NaN, "batb": [[2, 1.31, 600.66]], "batl": NaN}, {"timestamp": 1631534354305, "ltp": 1.33, "tv": 53551.18, "trd": NaN, "batb": NaN, "batl": [[2, 1.36, 454.22]]}, {"timestamp": 1631534362535, "ltp": 1.33, "tv": 53551.18, "trd": NaN, "batb": [[1, 1.32, 9], [2, 1.31, 8]], "batl": [[0, 1.34, 485], [1, 1.35, 262.03], [2, 1.37, 61.5]]}, {"timestamp": 1631534363436, "ltp": 1.33, "tv": 53551.18, "trd": NaN, "batb": [[0, 1.3, 202.73], [1, 1.29, 405.45], [2, 1.28, 177.89]], "batl": [[0, 1.38, 218.91], [1, 1.39, 60.5], [2, 1.4, 139.87]]}, {"timestamp": 1631534365526, "ltp": 1.33, "tv": 53551.18, "trd": NaN, "batb": NaN, "batl": [[1, 1.39, 224.74], [2, 1.4, 401.97]]}, {"timestamp": 1631534365945, "ltp": 1.33, "tv": 53551.18, "trd": NaN, "batb": [[0, 1.29, 405.45], [1, 1.28, 177.89], [2, 1.27, 416.44]], "batl": NaN}, {"timestamp": 1631534367526, "ltp": 1.33, "tv": 53551.18, "trd": NaN, "batb": NaN, "batl": [[1, 1.39, 60.5], [2, 1.4, 139.87]]}, {"timestamp": 1631534369634, "ltp": 1.33, "tv": 53551.18, "trd": NaN, "batb": [[0, 1.3, 423.35], [1, 1.29, 820.7], [2, 1.28, 187.89]], "batl": [[0, 1.33, 348.16], [1, 1.34, 321.55], [2, 1.36, 4]]}, {"timestamp": 1631534370539, "ltp": 1.33, "tv": 53551.18, "trd": NaN, "batb": [[0, 1.3, 373.99]], "batl": [[0, 1.33, 757.04], [2, 1.37, 75.5]]}, {"timestamp": 1631534372544, "ltp": 1.33, "tv": 53551.18, "trd": NaN, "batb": [[0, 1.29, 416.45], [1, 1.28, 187.89], [2, 1.27, 416.44]], "batl": [[0, 1.33, 408.88], [1, 1.37, 75.5], [2, 1.38, 218.91]]}, {"timestamp": 1631534373750, "ltp": 1.33, "tv": 53551.18, "trd": NaN, "batb": NaN, "batl": [[0, 1.33, 21.69]]}, {"timestamp": 1631534379549, "ltp": 1.33, "tv": 53551.18, "trd": NaN, "batb": [[1, 1.28, 10], [2, 1.27, 195.87]], "batl": [[0, 1.37, 75.5], [1, 1.38, 218.91], [2, 1.39, 224.74]]}, {"timestamp": 1631534379759, "ltp": 1.33, "tv": 53551.18, "trd": NaN, "batb": NaN, "batl": [[0, 1.38, 218.91], [1, 1.39, 224.74], [2, 1.4, 401.97]]}, {"timestamp": 1631534381288, "ltp": 1.33, "tv": 53551.18, "trd": NaN, "batb": [[1, 1.27, 195.87], [2, 1.26, 88.48]], "batl": [[0, 1.39, 224.74], [1, 1.4, 401.97], [2, 1.41, 215.35]]}, {"timestamp": 1631534382674, "ltp": 1.33, "tv": 53551.18, "trd": NaN, "batb": [[0, 1.36, 414.11], [1, 1.35, 1733.49], [2, 1.34, 1388.72]], "batl": NaN}, {"timestamp": 1631534383464, "ltp": 1.33, "tv": 53551.18, "trd": NaN, "batb": [[1, 1.35, 1992.65]], "batl": [[1, 1.4, 416.97]]}, {"timestamp": 1631534385249, "ltp": 1.33, "tv": 53551.18, "trd": NaN, "batb": [[0, 1.37, 8], [1, 1.36, 423.11], [2, 1.35, 1992.65]], "batl": NaN}, {"timestamp": 1631534386670, "ltp": 1.33, "tv": 53551.18, "trd": NaN, "batb": [[0, 1.37, 75.57]], "batl": [[0, 1.38, 508.4], [1, 1.39, 224.74], [2, 1.4, 416.97]]}, {"timestamp": 1631534387681, "ltp": 1.37, "tv": 53591.63, "trd": [[1.37, 1284.91]], "batb": [[0, 1.37, 55.35], [1, 1.36, 3328.29]], "batl": [[1, 1.39, 302.17]]}, {"timestamp": 1631534388577, "ltp": 1.37, "tv": 53591.63, "trd": NaN, "batb": NaN, "batl": [[1, 1.39, 559.45]]}, {"timestamp": 1631534389370, "ltp": 1.37, "tv": 53591.63, "trd": NaN, "batb": NaN, "batl": [[2, 1.4, 485.51]]}, {"timestamp": 1631534394577, "ltp": 1.37, "tv": 53599.73, "trd": [[1.37, 1293.01]], "batb": [[0, 1.36, 3273.93], [1, 1.35, 1992.65], [2, 1.34, 1491.61]], "batl": [[0, 1.37, 213.42], [1, 1.38, 245.68], [2, 1.39, 482.02]]}, {"timestamp": 1631534396484, "ltp": 1.37, "tv": 53599.73, "trd": NaN, "batb": [[0, 1.36, 3208.04]], "batl": [[0, 1.38, 183.12], [1, 1.39, 482.02], [2, 1.4, 485.51]]}, {"timestamp": 1631534397588, "ltp": 1.37, "tv": 53600.03, "trd": [[1.37, 1293.31]], "batb": NaN, "batl": [[0, 1.37, 29.6], [1, 1.38, 183.12], [2, 1.39, 482.02]]}, {"timestamp": 1631534399708, "ltp": 1.37, "tv": 53659.23, "trd": [[1.37, 1352.51]], "batb": [[0, 1.37, 61.28], [1, 1.36, 3208.04], [2, 1.35, 1992.65]], "batl": [[0, 1.38, 183.12], [1, 1.39, 482.02], [2, 1.4, 485.51]]}, {"timestamp": 1631534400611, "ltp": 1.37, "tv": 53659.23, "trd": NaN, "batb": [[0, 1.36, 2839.29], [1, 1.34, 102.89], [2, 1.33, 145.59]], "batl": [[0, 1.39, 83], [1, 1.4, 15], [2, 1.41, 59.5]]}, {"timestamp": 1631534401421, "ltp": 1.37, "tv": 53659.23, "trd": NaN, "batb": [[0, 1.33, 145.59], [1, 1.32, 699.32], [2, 1.31, 241.64]], "batl": [[0, 1.41, 59.5], [1, 1.45, 126.15], [2, 1.46, 203.83]]}, {"timestamp": 1631534404694, "ltp": 1.37, "tv": 53659.23, "trd": NaN, "batb": [[0, 1.34, 9], [1, 1.33, 154.59], [2, 1.32, 707.32]], "batl": NaN}, {"timestamp": 1631534405696, "ltp": 1.37, "tv": 53659.23, "trd": NaN, "batb": [[0, 1.35, 349.75], [1, 1.34, 337.98], [2, 1.33, 154.59]], "batl": [[0, 1.38, 201.65], [1, 1.39, 270.63], [2, 1.41, 59.5]]}, {"timestamp": 1631534406117, "ltp": 1.37, "tv": 53659.23, "trd": NaN, "batb": [[1, 1.34, 544.96], [2, 1.33, 654.59]], "batl": NaN}, {"timestamp": 1631534407484, "ltp": 1.37, "tv": 53659.23, "trd": NaN, "batb": [[1, 1.34, 596.61]], "batl": [[1, 1.39, 341.13], [2, 1.4, 63.81]]}, {"timestamp": 1631534408699, "ltp": 1.37, "tv": 53659.23, "trd": NaN, "batb": NaN, "batl": [[0, 1.37, 2077.05], [1, 1.38, 201.65], [2, 1.39, 341.13]]}, {"timestamp": 1631534410612, "ltp": 1.37, "tv": 53659.23, "trd": NaN, "batb": [[0, 1.36, 73.41], [1, 1.35, 349.75], [2, 1.34, 596.61]], "batl": [[0, 1.37, 2436.95], [1, 1.38, 284.65]]}, {"timestamp": 1631534410822, "ltp": 1.37, "tv": 53659.23, "trd": NaN, "batb": [[0, 1.35, 349.75], [1, 1.34, 596.61], [2, 1.33, 654.59]], "batl": NaN}, {"timestamp": 1631534412627, "ltp": 1.37, "tv": 53659.23, "trd": NaN, "batb": [[0, 1.35, 428.39], [1, 1.34, 544.96]], "batl": NaN}, {"timestamp": 1631534413210, "ltp": 1.37, "tv": 53659.23, "trd": NaN, "batb": [[0, 1.34, 215.98], [1, 1.33, 654.59], [2, 1.32, 707.32]], "batl": [[0, 1.37, 2077.05], [1, 1.39, 70.5], [2, 1.41, 59.5]]}, {"timestamp": 1631534416217, "ltp": 1.37, "tv": 53659.23, "trd": NaN, "batb": [[1, 1.33, 645.59], [2, 1.32, 699.32]], "batl": NaN}, {"timestamp": 1631534419227, "ltp": 1.37, "tv": 53659.23, "trd": NaN, "batb": [[1, 1.33, 652.59]], "batl": NaN}, {"timestamp": 1631534423431, "ltp": 1.34, "tv": 54091.16, "trd": [[1.34, 7424.1]], "batb": [[0, 1.33, 507], [1, 1.32, 520.11], [2, 1.3, 309.12]], "batl": NaN}, {"timestamp": 1631534425117, "ltp": 1.34, "tv": 54091.16, "trd": NaN, "batb": [[1, 1.32, 83.14]], "batl": NaN}, {"timestamp": 1631534426518, "ltp": 1.41, "tv": 58507.53, "trd": [[1.37, 5507.15], [1.39, 192.23], [1.4, 1127.98], [1.41, 548.64]], "batb": [[0, 1.37, 13.77], [1, 1.33, 7], [2, 1.29, 88.81]], "batl": [[0, 1.49, 2.99], [1, 1.82, 2.89], [2, 2.08, 1]]}, {"timestamp": 1631534427418, "ltp": 1.41, "tv": 58507.53, "trd": NaN, "batb": [[0, 1.41, 9.39], [1, 1.37, 2785.33], [2, 1.36, 6]], "batl": [[1, 1.59, 12.58], [2, 1.82, 2.89]]}, {"timestamp": 1631534428643, "ltp": 1.41, "tv": 58507.53, "trd": NaN, "batb": [[0, 1.41, 132.2], [1, 1.37, 2776.33], [2, 1.29, 88.81]], "batl": [[2, 1.82, 482.28]]}, {"timestamp": 1631534429640, "ltp": 1.41, "tv": 58507.53, "trd": NaN, "batb": [[0, 1.41, 2625.24], [1, 1.38, 1309.61], [2, 1.37, 3012.27]], "batl": [[0, 1.46, 41.1], [1, 1.49, 2.99], [2, 1.59, 12.58]]}, {"timestamp": 1631534430540, "ltp": 1.41, "tv": 58507.53, "trd": NaN, "batb": [[0, 1.41, 2615.85], [1, 1.37, 13.77], [2, 1.29, 88.81]], "batl": [[0, 1.42, 195.32]]}, {"timestamp": 1631534430852, "ltp": 1.41, "tv": 58507.53, "trd": NaN, "batb": [[0, 1.37, 13.77], [1, 1.29, 88.81], [2, 1.27, 195.87]], "batl": [[0, 1.49, 2.99], [1, 1.59, 12.58], [2, 1.82, 2.89]]}, {"timestamp": 1631534434554, "ltp": 1.36, "tv": 58540.6, "trd": [[1.36, 10765.87], [1.37, 5534.7]], "batb": [[0, 1.29, 88.81], [1, 1.27, 195.87], [2, 1.2, 2]], "batl": [[0, 1.34, 187.69], [1, 1.49, 2.99], [2, 1.59, 12.58]]}, {"timestamp": 1631534439357, "ltp": 1.36, "tv": 58540.6, "trd": NaN, "batb": NaN, "batl": [[1, 1.41, 1022.15], [2, 1.49, 2.99]]}, {"timestamp": 1631534441153, "ltp": 1.34, "tv": 58605.74, "trd": [[1.34, 7489.24]], "batb": [[0, 1.31, 350.99], [1, 1.3, 387.2], [2, 1.29, 88.81]], "batl": [[0, 1.34, 487.46], [1, 1.35, 310.33]]}, {"timestamp": 1631534442677, "ltp": 1.34, "tv": 58605.74, "trd": NaN, "batb": [[1, 1.3, 1582.44]], "batl": NaN}, {"timestamp": 1631534444673, "ltp": 1.34, "tv": 58605.74, "trd": NaN, "batb": [[0, 1.32, 64.89], [1, 1.31, 360.99], [2, 1.3, 1582.44]], "batl": [[0, 1.33, 348.44], [1, 1.34, 487.46], [2, 1.35, 310.33]]}, {"timestamp": 1631534445168, "ltp": 1.34, "tv": 58605.74, "trd": NaN, "batb": [[1, 1.31, 432.42]], "batl": [[1, 1.34, 559.55]]}, {"timestamp": 1631534448174, "ltp": 1.33, "tv": 58614.03, "trd": [[1.33, 1216.73]], "batb": [[1, 1.31, 81.43], [2, 1.27, 195.87]], "batl": [[0, 1.33, 342.92], [1, 1.34, 227.21], [2, 1.49, 2.99]]}, {"timestamp": 1631534451469, "ltp": 1.33, "tv": 58614.03, "trd": NaN, "batb": NaN, "batl": [[1, 1.34, 72.09], [2, 1.39, 193.79]]}, {"timestamp": 1631534452574, "ltp": 1.33, "tv": 58614.03, "trd": NaN, "batb": [[0, 1.32, 141.64]], "batl": [[1, 1.34, 129.38], [2, 1.49, 2.99]]}, {"timestamp": 1631534453467, "ltp": 1.33, "tv": 58673.54, "trd": [[1.33, 1276.24]], "batb": [[1, 1.31, 10]], "batl": [[0, 1.33, 313.16], [1, 1.34, 72.09]]}, {"timestamp": 1631534454663, "ltp": 1.33, "tv": 58673.54, "trd": NaN, "batb": [[0, 1.32, 9]], "batl": [[0, 1.49, 2.99], [1, 1.59, 12.58], [2, 1.82, 2.89]]}, {"timestamp": 1631534455556, "ltp": 1.33, "tv": 58673.54, "trd": NaN, "batb": [[1, 1.31, 360.99], [2, 1.3, 387.2]], "batl": [[0, 1.34, 332.34], [1, 1.35, 310.33], [2, 1.49, 2.99]]}, {"timestamp": 1631534455764, "ltp": 1.33, "tv": 58673.54, "trd": NaN, "batb": [[1, 1.31, 464.04]], "batl": [[0, 1.33, 389.76], [1, 1.34, 332.34], [2, 1.35, 310.33]]}, {"timestamp": 1631534458663, "ltp": 1.33, "tv": 58673.54, "trd": NaN, "batb": [[1, 1.28, 235.95], [2, 1.27, 195.87]], "batl": [[0, 1.49, 8.99], [1, 1.59, 12.58], [2, 1.82, 2.89]]}, {"timestamp": 1631534459870, "ltp": 1.32, "tv": 58700.86, "trd": [[1.32, 271.22]], "batb": [[0, 1.28, 235.95], [1, 1.27, 195.87], [2, 1.2, 2]], "batl": [[0, 1.32, 138.75], [1, 1.49, 8.99], [2, 1.59, 12.58]]}, {"timestamp": 1631534461672, "ltp": 1.32, "tv": 58700.86, "trd": NaN, "batb": [[0, 1.31, 8], [1, 1.28, 235.95], [2, 1.27, 195.87]], "batl": [[1, 1.39, 193.79], [2, 1.4, 262.09]]}, {"timestamp": 1631534463085, "ltp": 1.32, "tv": 58767.07, "trd": [[1.32, 337.43]], "batb": [[1, 1.29, 9], [2, 1.28, 243.95]], "batl": [[0, 1.32, 105.64]]}, {"timestamp": 1631534464606, "ltp": 1.32, "tv": 58767.07, "trd": NaN, "batb": [[1, 1.3, 7], [2, 1.29, 9]], "batl": [[0, 1.39, 193.79], [1, 1.4, 262.09], [2, 1.49, 8.99]]}, {"timestamp": 1631534465675, "ltp": 1.32, "tv": 58767.07, "trd": NaN, "batb": [[0, 1.36, 329.38], [1, 1.35, 316.81], [2, 1.32, 103.89]], "batl": NaN}, {"timestamp": 1631534466701, "ltp": 1.32, "tv": 58767.07, "trd": NaN, "batb": [[2, 1.31, 8]], "batl": NaN}, {"timestamp": 1631534467705, "ltp": 1.32, "tv": 58767.07, "trd": NaN, "batb": [[2, 1.33, 104.44]], "batl": [[1, 1.4, 277.09]]}, {"timestamp": 1631534468704, "ltp": 1.36, "tv": 58972.13, "trd": [[1.36, 10970.92]], "batb": [[0, 1.37, 7], [1, 1.36, 235.86], [2, 1.35, 316.81]], "batl": NaN}, {"timestamp": 1631534470612, "ltp": 1.36, "tv": 58972.13, "trd": NaN, "batb": [[0, 1.37, 66.22], [1, 1.36, 344.86]], "batl": [[0, 1.38, 294.25], [1, 1.39, 574.61], [2, 1.4, 277.09]]}, {"timestamp": 1631534471706, "ltp": 1.38, "tv": 58986.13, "trd": [[1.38, 659.12]], "batb": [[1, 1.36, 390.73]], "batl": [[0, 1.38, 287.25], [1, 1.39, 629.88]]}, {"timestamp": 1631534472098, "ltp": 1.38, "tv": 58986.13, "trd": NaN, "batb": NaN, "batl": [[1, 1.39, 602]]}, {"timestamp": 1631534473295, "ltp": 1.38, "tv": 58986.13, "trd": NaN, "batb": [[1, 1.36, 3230.03]], "batl": [[0, 1.38, 571.47]]}, {"timestamp": 1631534475299, "ltp": 1.38, "tv": 58986.13, "trd": NaN, "batb": [[1, 1.36, 3258.68]], "batl": NaN}, {"timestamp": 1631534476610, "ltp": 1.38, "tv": 58986.13, "trd": NaN, "batb": [[0, 1.37, 59.22], [1, 1.36, 3209.68]], "batl": NaN}, {"timestamp": 1631534477505, "ltp": 1.38, "tv": 58986.13, "trd": NaN, "batb": [[0, 1.37, 116.09], [1, 1.36, 2908.3], [2, 1.33, 302.05]], "batl": [[0, 1.38, 346.98], [1, 1.39, 71.42], [2, 1.4, 15]]}, {"timestamp": 1631534478540, "ltp": 1.38, "tv": 58986.13, "trd": NaN, "batb": [[0, 1.37, 59.22], [1, 1.33, 197.61], [2, 1.3, 7]], "batl": [[0, 1.38, 287.25], [1, 1.49, 8.99], [2, 1.82, 2.89]]}, {"timestamp": 1631534479701, "ltp": 1.38, "tv": 58986.13, "trd": NaN, "batb": [[0, 1.33, 197.61], [1, 1.31, 305.07], [2, 1.3, 394.1]], "batl": [[0, 1.44, 154.68], [1, 1.45, 224.45], [2, 1.49, 8.99]]}, {"timestamp": 1631534480219, "ltp": 1.38, "tv": 58986.13, "trd": NaN, "batb": [[1, 1.3, 7], [2, 1.27, 195.87]], "batl": [[0, 1.49, 8.99], [1, 1.82, 2.89], [2, 2.08, 1]]}, {"timestamp": 1631534482628, "ltp": 1.38, "tv": 58986.13, "trd": NaN, "batb": [[0, 1.35, 290.22], [1, 1.34, 328.98], [2, 1.33, 197.61]], "batl": [[0, 1.37, 363.75], [1, 1.38, 259.73], [2, 1.39, 270.66]]}, {"timestamp": 1631534483008, "ltp": 1.38, "tv": 58986.13, "trd": NaN, "batb": NaN, "batl": [[0, 1.38, 259.73], [1, 1.39, 270.66], [2, 1.44, 6]]}, {"timestamp": 1631534484353, "ltp": 1.38, "tv": 58986.13, "trd": NaN, "batb": [[1, 1.34, 386.57]], "batl": NaN}, {"timestamp": 1631534485306, "ltp": 1.38, "tv": 58986.13, "trd": NaN, "batb": [[1, 1.34, 328.98], [2, 1.32, 245.32]], "batl": NaN}, {"timestamp": 1631534487503, "ltp": 1.38, "tv": 58986.13, "trd": NaN, "batb": NaN, "batl": [[0, 1.38, 509.72]]}, {"timestamp": 1631534487819, "ltp": 1.38, "tv": 58986.13, "trd": NaN, "batb": [[0, 1.35, 347.81]], "batl": NaN}, {"timestamp": 1631534489646, "ltp": 1.38, "tv": 58986.13, "trd": NaN, "batb": [[0, 1.35, 57.59], [1, 1.32, 245.32], [2, 1.3, 7]], "batl": [[0, 1.38, 249.99], [1, 1.44, 6], [2, 1.47, 44.95]]}, {"timestamp": 1631534490023, "ltp": 1.38, "tv": 58986.13, "trd": NaN, "batb": [[0, 1.32, 245.32], [1, 1.3, 7], [2, 1.27, 195.87]], "batl": [[0, 1.44, 6], [1, 1.49, 8.99], [2, 1.82, 2.89]]}, {"timestamp": 1631534492646, "ltp": 1.38, "tv": 58986.13, "trd": NaN, "batb": [[1, 1.31, 305.07], [2, 1.3, 394.1]], "batl": [[0, 1.44, 160.68], [1, 1.45, 224.45], [2, 1.49, 8.99]]}, {"timestamp": 1631534493455, "ltp": 1.38, "tv": 58986.13, "trd": NaN, "batb": [[0, 1.32, 251.32], [1, 1.31, 311.07]], "batl": NaN}, {"timestamp": 1631534495242, "ltp": 1.38, "tv": 58986.13, "trd": NaN, "batb": [[0, 1.32, 251.55]], "batl": [[2, 1.49, 2.99]]}, {"timestamp": 1631534496139, "ltp": 1.38, "tv": 58986.13, "trd": NaN, "batb": [[0, 1.32, 245.55], [1, 1.31, 305.07]], "batl": [[0, 1.43, 8], [1, 1.44, 6]]}, {"timestamp": 1631534497439, "ltp": 1.38, "tv": 58986.13, "trd": NaN, "batb": [[0, 1.33, 500.23]], "batl": [[0, 1.43, 255.02]]}, {"timestamp": 1631534498618, "ltp": 1.38, "tv": 58986.59, "trd": [[1.38, 659.58]], "batb": [[0, 1.31, 305.07], [1, 1.3, 394.1], [2, 1.29, 2965.12]], "batl": [[0, 1.34, 2392.1], [1, 1.43, 255.02], [2, 1.44, 6]]}, {"timestamp": 1631534499650, "ltp": 1.38, "tv": 58986.59, "trd": NaN, "batb": [[2, 1.29, 815.41]], "batl": [[0, 1.34, 399.34], [1, 1.35, 310.26], [2, 1.43, 8]]}, {"timestamp": 1631534500647, "ltp": 1.38, "tv": 58986.59, "trd": NaN, "batb": NaN, "batl": [[0, 1.34, 431.91], [1, 1.35, 325.26], [2, 1.41, 40]]}, {"timestamp": 1631534502638, "ltp": 1.38, "tv": 58986.59, "trd": NaN, "batb": [[0, 1.31, 2503.24]], "batl": NaN}, {"timestamp": 1631534503636, "ltp": 1.38, "tv": 58986.59, "trd": NaN, "batb": [[0, 1.32, 58.64], [1, 1.31, 2571.18], [2, 1.3, 394.1]], "batl": [[0, 1.33, 298.73], [1, 1.34, 698.97], [2, 1.35, 325.26]]}, {"timestamp": 1631534504456, "ltp": 1.38, "tv": 58986.59, "trd": NaN, "batb": NaN, "batl": [[2, 1.35, 310.26]]}, {"timestamp": 1631534507660, "ltp": 1.38, "tv": 58986.59, "trd": NaN, "batb": NaN, "batl": [[1, 1.34, 713.97]]}, {"timestamp": 1631534507868, "ltp": 1.38, "tv": 58986.59, "trd": NaN, "batb": NaN, "batl": [[1, 1.34, 681.4]]}, {"timestamp": 1631534510665, "ltp": 1.38, "tv": 58986.59, "trd": NaN, "batb": NaN, "batl": [[0, 1.33, 536.22], [1, 1.34, 658.88]]}, {"timestamp": 1631534511657, "ltp": 1.32, "tv": 59052.73, "trd": [[1.32, 403.56]], "batb": [[0, 1.32, 106.1], [1, 1.31, 2503.24]], "batl": [[1, 1.34, 602.36]]}, {"timestamp": 1631534513290, "ltp": 1.32, "tv": 59052.73, "trd": NaN, "batb": [[0, 1.31, 2503.24], [1, 1.3, 394.1], [2, 1.29, 815.41]], "batl": [[0, 1.33, 237.49]]}, {"timestamp": 1631534516086, "ltp": 1.32, "tv": 59052.73, "trd": NaN, "batb": [[0, 1.32, 8], [1, 1.31, 2512.24], [2, 1.3, 394.1]], "batl": NaN}, {"timestamp": 1631534518494, "ltp": 1.32, "tv": 59052.73, "trd": NaN, "batb": [[0, 1.31, 2503.24], [1, 1.3, 387.1], [2, 1.29, 815.41]], "batl": [[0, 1.34, 602.36], [1, 1.35, 310.26], [2, 1.39, 189.1]]}, {"timestamp": 1631534520504, "ltp": 1.32, "tv": 59052.73, "trd": NaN, "batb": [[0, 1.31, 305.07], [2, 1.28, 113.38]], "batl": NaN}, {"timestamp": 1631534520927, "ltp": 1.32, "tv": 59052.73, "trd": NaN, "batb": [[0, 1.28, 113.38], [1, 1.27, 421.59], [2, 1.22, 524.56]], "batl": [[0, 1.34, 15], [1, 1.39, 189.1], [2, 1.49, 2.99]]}, {"timestamp": 1631534522503, "ltp": 1.32, "tv": 59052.73, "trd": NaN, "batb": [[0, 1.27, 421.59], [1, 1.22, 524.56], [2, 1.2, 2]], "batl": [[0, 1.39, 189.1], [1, 1.49, 2.99], [2, 1.71, 553.48]]}, {"timestamp": 1631534523812, "ltp": 1.32, "tv": 59052.73, "trd": NaN, "batb": [[1, 1.26, 330.01], [2, 1.25, 487.9]], "batl": [[0, 1.39, 420.1], [1, 1.4, 262.04], [2, 1.49, 2.99]]}, {"timestamp": 1631534525700, "ltp": 1.32, "tv": 59052.73, "trd": NaN, "batb": [[0, 1.27, 522.46]], "batl": [[0, 1.36, 64.07], [1, 1.38, 75.25], [2, 1.39, 420.1]]}, {"timestamp": 1631534526223, "ltp": 1.32, "tv": 59052.73, "trd": NaN, "batb": NaN, "batl": [[0, 1.38, 75.25], [1, 1.39, 420.1], [2, 1.4, 262.04]]}, {"timestamp": 1631534528112, "ltp": 1.32, "tv": 59052.73, "trd": NaN, "batb": [[0, 1.28, 500], [1, 1.27, 522.46], [2, 1.26, 330.01]], "batl": NaN}, {"timestamp": 1631534529529, "ltp": 1.32, "tv": 59052.73, "trd": NaN, "batb": NaN, "batl": [[0, 1.36, 65.57], [1, 1.38, 75.25], [2, 1.39, 420.1]]}, {"timestamp": 1631534530420, "ltp": 1.32, "tv": 59052.73, "trd": NaN, "batb": [[2, 1.24, 114.77]], "batl": [[0, 1.38, 75.25], [1, 1.39, 420.1], [2, 1.4, 262.04]]}, {"timestamp": 1631534532501, "ltp": 1.32, "tv": 59052.73, "trd": NaN, "batb": [[0, 1.27, 522.46], [1, 1.24, 114.77], [2, 1.2, 2]], "batl": [[1, 1.39, 231]]}, {"timestamp": 1631534533710, "ltp": 1.36, "tv": 59206.37, "trd": [[1.36, 11124.56]], "batb": [[0, 1.36, 331.91], [1, 1.35, 1733.39], [2, 1.34, 1457.72]], "batl": NaN}, {"timestamp": 1631534534713, "ltp": 1.36, "tv": 59206.37, "trd": NaN, "batb": NaN, "batl": [[2, 1.4, 277.04]]}, {"timestamp": 1631534536510, "ltp": 1.36, "tv": 59206.37, "trd": NaN, "batb": [[0, 1.37, 6], [1, 1.36, 374.17], [2, 1.35, 1742.39]], "batl": NaN}, {"timestamp": 1631534537511, "ltp": 1.37, "tv": 59218.37, "trd": [[1.37, 5546.7]], "batb": [[0, 1.36, 453.28], [1, 1.35, 1742.39], [2, 1.34, 1457.72]], "batl": [[0, 1.37, 253.31], [1, 1.38, 396.55], [2, 1.39, 231]]}, {"timestamp": 1631534538615, "ltp": 1.37, "tv": 59218.37, "trd": NaN, "batb": [[0, 1.36, 453.98], [1, 1.35, 1811.15]], "batl": [[2, 1.39, 290.28]]}, {"timestamp": 1631534539663, "ltp": 1.37, "tv": 59237.77, "trd": [[1.37, 5566.1]], "batb": [[0, 1.36, 417.02]], "batl": [[0, 1.37, 240.91]]}, {"timestamp": 1631534540513, "ltp": 1.37, "tv": 59719.55, "trd": [[1.37, 6047.88]], "batb": [[0, 1.37, 12.44], [1, 1.36, 417.02], [2, 1.35, 1811.15]], "batl": [[0, 1.38, 396.55], [1, 1.39, 290.28], [2, 1.4, 333.48]]}, {"timestamp": 1631534541308, "ltp": 1.37, "tv": 59719.55, "trd": NaN, "batb": [[0, 1.36, 417.02], [1, 1.35, 1811.15], [2, 1.34, 1457.72]], "batl": [[1, 1.39, 353.78]]}, {"timestamp": 1631534545628, "ltp": 1.37, "tv": 59719.55, "trd": NaN, "batb": [[0, 1.36, 376.12], [1, 1.35, 1742.39]], "batl": [[1, 1.39, 294.5]]}, {"timestamp": 1631534547466, "ltp": 1.38, "tv": 59726.17, "trd": [[1.38, 666.2]], "batb": [[0, 1.36, 297.01]], "batl": [[0, 1.38, 323.71]]}, {"timestamp": 1631534548523, "ltp": 1.38, "tv": 59726.17, "trd": NaN, "batb": [[0, 1.36, 6], [1, 1.33, 104.44], [2, 1.32, 562.3]], "batl": [[0, 1.4, 15], [1, 1.49, 2.99], [2, 1.71, 553.48]]}, {"timestamp": 1631534549632, "ltp": 1.38, "tv": 59726.17, "trd": NaN, "batb": [[0, 1.32, 562.3], [1, 1.31, 294.47], [2, 1.29, 116.81]], "batl": [[0, 1.49, 2.99], [1, 1.71, 553.48], [2, 1.82, 2.89]]}, {"timestamp": 1631534550633, "ltp": 1.38, "tv": 59726.17, "trd": NaN, "batb": [[0, 1.37, 8], [1, 1.32, 562.3], [2, 1.31, 294.47]], "batl": NaN}, {"timestamp": 1631534551474, "ltp": 1.38, "tv": 59726.17, "trd": NaN, "batb": [[0, 1.32, 562.3], [1, 1.31, 587.36], [2, 1.3, 386.92]], "batl": [[0, 1.44, 161.85], [1, 1.45, 224.4], [2, 1.49, 2.99]]}, {"timestamp": 1631534552632, "ltp": 1.38, "tv": 59726.17, "trd": NaN, "batb": NaN, "batl": [[0, 1.43, 8], [1, 1.44, 161.85], [2, 1.45, 224.4]]}, {"timestamp": 1631534552840, "ltp": 1.38, "tv": 59726.17, "trd": NaN, "batb": [[0, 1.32, 568.3], [1, 1.31, 594.36]], "batl": NaN}, {"timestamp": 1631534554879, "ltp": 1.38, "tv": 59726.17, "trd": NaN, "batb": [[0, 1.33, 500], [1, 1.32, 568.3], [2, 1.31, 594.36]], "batl": [[0, 1.43, 235.43]]}, {"timestamp": 1631534556553, "ltp": 1.38, "tv": 59726.17, "trd": NaN, "batb": [[2, 1.31, 301.47]], "batl": [[0, 1.43, 227.43]]}, {"timestamp": 1631534557656, "ltp": 1.38, "tv": 59726.17, "trd": NaN, "batb": [[1, 1.32, 133.89]], "batl": [[0, 1.44, 161.85], [1, 1.45, 224.4], [2, 1.49, 2.99]]}, {"timestamp": 1631534559650, "ltp": 1.38, "tv": 59726.17, "trd": NaN, "batb": [[0, 1.41, 239.92], [1, 1.4, 264.79], [2, 1.39, 1375.9]], "batl": [[2, 1.47, 715.56]]}, {"timestamp": 1631534560650, "ltp": 1.38, "tv": 59726.17, "trd": NaN, "batb": [[1, 1.4, 482.61]], "batl": [[2, 1.46, 15]]}, {"timestamp": 1631534561589, "ltp": 1.38, "tv": 59726.17, "trd": NaN, "batb": [[0, 1.42, 6], [1, 1.41, 239.92], [2, 1.4, 3037.98]], "batl": NaN}, {"timestamp": 1631534562591, "ltp": 1.38, "tv": 59726.17, "trd": NaN, "batb": [[1, 1.41, 245.92], [2, 1.4, 3045.98]], "batl": NaN}, {"timestamp": 1631534563584, "ltp": 1.38, "tv": 59726.17, "trd": NaN, "batb": [[0, 1.42, 84], [1, 1.41, 2738.96]], "batl": [[0, 1.43, 64.7], [1, 1.44, 161.85], [2, 1.45, 224.4]]}, {"timestamp": 1631534564479, "ltp": 1.38, "tv": 59726.17, "trd": NaN, "batb": [[0, 1.42, 6]], "batl": [[0, 1.44, 405.98], [1, 1.45, 224.4], [2, 1.46, 15]]}, {"timestamp": 1631534569375, "ltp": 1.38, "tv": 59726.17, "trd": NaN, "batb": [[2, 1.4, 3042.71]], "batl": NaN}, {"timestamp": 1631534571490, "ltp": 1.38, "tv": 59726.17, "trd": NaN, "batb": [[0, 1.42, 81.3]], "batl": [[0, 1.43, 71.14], [1, 1.44, 405.98], [2, 1.45, 224.4]]}, {"timestamp": 1631534573473, "ltp": 1.38, "tv": 59726.17, "trd": NaN, "batb": [[0, 1.42, 6]], "batl": [[0, 1.44, 405.98], [1, 1.45, 224.4], [2, 1.46, 15]]}, {"timestamp": 1631534574408, "ltp": 1.44, "tv": 59731.44, "trd": [[1.44, 291.09]], "batb": [[1, 1.41, 2732.96], [2, 1.4, 3034.71]], "batl": [[0, 1.44, 577.1]]}, {"timestamp": 1631534576602, "ltp": 1.44, "tv": 59731.44, "trd": NaN, "batb": [[0, 1.43, 8], [1, 1.42, 6], [2, 1.41, 2732.96]], "batl": NaN}, {"timestamp": 1631534577603, "ltp": 1.44, "tv": 59731.44, "trd": NaN, "batb": [[0, 1.43, 33.75], [2, 1.41, 2944.42]], "batl": [[1, 1.45, 422.01]]}, {"timestamp": 1631534580573, "ltp": 1.44, "tv": 59731.44, "trd": NaN, "batb": NaN, "batl": [[2, 1.46, 188.76]]}, {"timestamp": 1631534581324, "ltp": 1.44, "tv": 59731.44, "trd": NaN, "batb": [[0, 1.43, 8]], "batl": NaN}, {"timestamp": 1631534586113, "ltp": 1.44, "tv": 59781.78, "trd": [[1.44, 341.43]], "batb": NaN, "batl": [[0, 1.44, 551.93]]}, {"timestamp": 1631534589687, "ltp": 1.44, "tv": 59781.78, "trd": NaN, "batb": [[2, 1.41, 3159.07]], "batl": NaN}, {"timestamp": 1631534589896, "ltp": 1.44, "tv": 59781.78, "trd": NaN, "batb": [[1, 1.41, 3159.07], [2, 1.4, 3266.25]], "batl": NaN}, {"timestamp": 1631534592690, "ltp": 1.43, "tv": 59797.78, "trd": [[1.43, 16]], "batb": [[0, 1.41, 3159.07], [1, 1.4, 3042.65], [2, 1.39, 1471.97]], "batl": [[0, 1.43, 164.85], [1, 1.44, 551.93], [2, 1.45, 422.01]]}, {"timestamp": 1631534596007, "ltp": 1.43, "tv": 59811.78, "trd": [[1.43, 30]], "batb": [[0, 1.42, 7], [1, 1.41, 3323.87], [2, 1.4, 3042.65]], "batl": [[0, 1.43, 375.63]]}, {"timestamp": 1631534600538, "ltp": 1.43, "tv": 59811.78, "trd": NaN, "batb": NaN, "batl": [[0, 1.43, 217.78]]}, {"timestamp": 1631534603637, "ltp": 1.41, "tv": 60114.95, "trd": [[1.41, 825.25], [1.42, 132.45]], "batb": [[0, 1.41, 3182.29], [1, 1.4, 3042.65], [2, 1.39, 1471.97]], "batl": NaN}, {"timestamp": 1631534604115, "ltp": 1.41, "tv": 60114.95, "trd": NaN, "batb": [[0, 1.41, 3056.53]], "batl": NaN}, {"timestamp": 1631534607141, "ltp": 1.41, "tv": 60114.95, "trd": NaN, "batb": [[0, 1.41, 3134.17]], "batl": [[1, 1.44, 639]]}, {"timestamp": 1631534610336, "ltp": 1.43, "tv": 60126.95, "trd": [[1.43, 42]], "batb": [[0, 1.42, 91.35], [1, 1.41, 3134.17], [2, 1.4, 3042.65]], "batl": [[0, 1.43, 211.78]]}, {"timestamp": 1631534616043, "ltp": 1.43, "tv": 60126.95, "trd": NaN, "batb": [[0, 1.42, 296.28], [1, 1.41, 2925.97]], "batl": NaN}, {"timestamp": 1631534617621, "ltp": 1.43, "tv": 60138.67, "trd": [[1.43, 53.72]], "batb": NaN, "batl": [[0, 1.44, 639], [1, 1.45, 422.01], [2, 1.46, 188.76]]}, {"timestamp": 1631534627450, "ltp": 1.43, "tv": 60138.67, "trd": NaN, "batb": [[0, 1.43, 6], [1, 1.42, 296.28], [2, 1.41, 2925.97]], "batl": NaN}, {"timestamp": 1631534640516, "ltp": 1.43, "tv": 60138.67, "trd": NaN, "batb": [[1, 1.42, 289.28]], "batl": NaN}, {"timestamp": 1631534643674, "ltp": 1.43, "tv": 60150.67, "trd": [[1.43, 65.72]], "batb": [[0, 1.42, 289.28], [1, 1.41, 2925.97], [2, 1.4, 487.29]], "batl": [[0, 1.43, 176.65], [1, 1.44, 639], [2, 1.45, 422.01]]}, {"timestamp": 1631534644176, "ltp": 1.43, "tv": 60150.67, "trd": NaN, "batb": [[0, 1.42, 204.93]], "batl": NaN}, {"timestamp": 1631534646710, "ltp": 1.43, "tv": 60150.67, "trd": NaN, "batb": [[0, 1.42, 261.97]], "batl": [[1, 1.44, 700.04], [2, 1.45, 484.87]]}, {"timestamp": 1631534647232, "ltp": 1.43, "tv": 60166.67, "trd": [[1.43, 81.72]], "batb": [[0, 1.42, 267.97], [1, 1.41, 2983.57]], "batl": [[0, 1.44, 700.04], [1, 1.45, 422.01], [2, 1.46, 188.76]]}, {"timestamp": 1631534652337, "ltp": 1.43, "tv": 60166.67, "trd": NaN, "batb": [[0, 1.42, 210.93], [1, 1.41, 2925.97]], "batl": [[0, 1.44, 639]]}, {"timestamp": 1631534656915, "ltp": 1.43, "tv": 60166.67, "trd": NaN, "batb": [[1, 1.41, 2886.93]], "batl": NaN}, {"timestamp": 1631534663233, "ltp": 1.43, "tv": 60166.67, "trd": NaN, "batb": [[0, 1.43, 8], [1, 1.42, 210.93], [2, 1.41, 2886.93]], "batl": NaN}, {"timestamp": 1631534664225, "ltp": 1.44, "tv": 60172.43, "trd": [[1.44, 347.18]], "batb": NaN, "batl": [[0, 1.44, 636.12]]}, {"timestamp": 1631534675431, "ltp": 1.44, "tv": 60172.43, "trd": NaN, "batb": NaN, "batl": [[0, 1.44, 605.07]]}, {"timestamp": 1631534675742, "ltp": 1.44, "tv": 60172.43, "trd": NaN, "batb": [[1, 1.42, 204.93]], "batl": NaN}, {"timestamp": 1631534678470, "ltp": 1.44, "tv": 60172.43, "trd": NaN, "batb": [[2, 1.41, 2921.73]], "batl": NaN}, {"timestamp": 1631534678940, "ltp": 1.44, "tv": 60172.43, "trd": NaN, "batb": [[2, 1.41, 428.69]], "batl": NaN}, {"timestamp": 1631534692655, "ltp": 1.43, "tv": 60179.22, "trd": [[1.43, 88.52]], "batb": [[0, 1.43, 4.6]], "batl": NaN}, {"timestamp": 1631534694488, "ltp": 1.43, "tv": 60179.22, "trd": NaN, "batb": [[1, 1.39, 96.07], [2, 1.38, 207.84]], "batl": [[0, 1.46, 15], [1, 1.49, 2.99], [2, 1.82, 2.89]]}, {"timestamp": 1631534695486, "ltp": 1.43, "tv": 60179.22, "trd": NaN, "batb": [[1, 1.38, 207.84], [2, 1.36, 247.95]], "batl": [[0, 1.49, 2.99], [1, 1.82, 2.89], [2, 1.89, 444.94]]}, {"timestamp": 1631534696095, "ltp": 1.43, "tv": 60179.22, "trd": NaN, "batb": [[0, 1.38, 207.84], [1, 1.36, 247.95], [2, 1.35, 136.47]], "batl": NaN}, {"timestamp": 1631534700390, "ltp": 1.43, "tv": 60179.22, "trd": NaN, "batb": [[0, 1.42, 342.94], [1, 1.41, 257.06], [2, 1.38, 207.84]], "batl": [[0, 1.46, 262.43], [1, 1.47, 211.12], [2, 1.49, 2.99]]}, {"timestamp": 1631534702273, "ltp": 1.43, "tv": 60179.22, "trd": NaN, "batb": NaN, "batl": [[2, 1.48, 14.95]]}, {"timestamp": 1631534703009, "ltp": 1.43, "tv": 60179.22, "trd": NaN, "batb": [[0, 1.38, 207.84], [1, 1.36, 247.95], [2, 1.35, 136.47]], "batl": [[0, 1.49, 2.99], [1, 1.52, 236.8], [2, 1.82, 2.89]]}, {"timestamp": 1631534705874, "ltp": 1.43, "tv": 60179.22, "trd": NaN, "batb": [[2, 1.35, 463.5]], "batl": [[2, 1.53, 238.02]]}, {"timestamp": 1631534709514, "ltp": 1.43, "tv": 60179.22, "trd": NaN, "batb": NaN, "batl": [[2, 1.82, 2.89]]}, {"timestamp": 1631534710617, "ltp": 1.43, "tv": 60179.22, "trd": NaN, "batb": [[0, 1.36, 247.95], [1, 1.35, 463.5], [2, 1.34, 329.82]], "batl": [[1, 1.82, 2.89], [2, 1.89, 444.94]]}, {"timestamp": 1631534710890, "ltp": 1.43, "tv": 60179.22, "trd": NaN, "batb": NaN, "batl": [[2, 2.08, 1]]}, {"timestamp": 1631534712624, "ltp": 1.43, "tv": 60179.22, "trd": NaN, "batb": NaN, "batl": [[0, 1.38, 230.2], [1, 1.39, 1647.24], [2, 1.4, 1335.42]]}, {"timestamp": 1631534713403, "ltp": 1.38, "tv": 60194.79, "trd": [[1.38, 681.77]], "batb": NaN, "batl": [[0, 1.38, 214.63], [2, 1.4, 1350.42]]}, {"timestamp": 1631534715406, "ltp": 1.38, "tv": 60194.79, "trd": NaN, "batb": [[0, 1.37, 3], [1, 1.36, 251.95], [2, 1.35, 463.5]], "batl": NaN}, {"timestamp": 1631534716507, "ltp": 1.38, "tv": 60194.79, "trd": NaN, "batb": NaN, "batl": [[0, 1.38, 338.21]]}, {"timestamp": 1631534717397, "ltp": 1.38, "tv": 60194.79, "trd": NaN, "batb": NaN, "batl": [[2, 1.4, 1335.42]]}, {"timestamp": 1631534718630, "ltp": 1.38, "tv": 60194.79, "trd": NaN, "batb": [[1, 1.36, 3091.24]], "batl": NaN}, {"timestamp": 1631534720621, "ltp": 1.38, "tv": 60194.79, "trd": NaN, "batb": NaN, "batl": [[1, 1.39, 1662.24]]}, {"timestamp": 1631534723234, "ltp": 1.38, "tv": 60194.79, "trd": NaN, "batb": NaN, "batl": [[0, 1.38, 516.21]]}, {"timestamp": 1631534725501, "ltp": 1.38, "tv": 60194.79, "trd": NaN, "batb": [[0, 1.36, 2839.29], [1, 1.33, 660.38], [2, 1.31, 415.33]], "batl": [[0, 1.38, 178], [1, 1.39, 15], [2, 1.44, 246.17]]}, {"timestamp": 1631534726441, "ltp": 1.38, "tv": 60194.79, "trd": NaN, "batb": [[0, 1.33, 555.94], [1, 1.31, 415.33], [2, 1.3, 126.28]], "batl": [[0, 1.44, 246.17], [1, 1.49, 2.99], [2, 1.77, 511.35]]}, {"timestamp": 1631534728612, "ltp": 1.38, "tv": 60194.79, "trd": NaN, "batb": [[2, 1.3, 644.33]], "batl": [[1, 1.45, 187.86], [2, 1.46, 217.8]]}, {"timestamp": 1631534730853, "ltp": 1.38, "tv": 60194.79, "trd": NaN, "batb": [[2, 1.3, 126.28]], "batl": [[1, 1.49, 2.99], [2, 1.77, 511.35]]}, {"timestamp": 1631534734259, "ltp": 1.38, "tv": 60194.79, "trd": NaN, "batb": [[0, 1.36, 405.38], [1, 1.35, 318.21], [2, 1.33, 555.94]], "batl": [[0, 1.4, 385.81], [1, 1.41, 252.54], [2, 1.44, 246.17]]}, {"timestamp": 1631534735553, "ltp": 1.38, "tv": 60194.79, "trd": NaN, "batb": NaN, "batl": [[2, 1.43, 69.62]]}, {"timestamp": 1631534735953, "ltp": 1.4, "tv": 60199.05, "trd": [[1.4, 1132.24]], "batb": NaN, "batl": [[0, 1.4, 381.55]]}, {"timestamp": 1631534738647, "ltp": 1.4, "tv": 60199.05, "trd": NaN, "batb": [[0, 1.37, 94.89], [1, 1.36, 405.38], [2, 1.35, 318.21]], "batl": [[0, 1.39, 181.81], [1, 1.4, 381.55], [2, 1.41, 252.54]]}, {"timestamp": 1631534739259, "ltp": 1.44, "tv": 60199.4, "trd": [[1.44, 347.53]], "batb": [[0, 1.33, 555.94], [1, 1.31, 415.33], [2, 1.3, 126.28]], "batl": [[0, 1.44, 245.82], [1, 1.49, 2.99], [2, 1.77, 511.35]]}, {"timestamp": 1631534742028, "ltp": 1.44, "tv": 60199.4, "trd": NaN, "batb": [[2, 1.3, 646.9]], "batl": [[1, 1.45, 185.6], [2, 1.46, 217.8]]}, {"timestamp": 1631534743958, "ltp": 1.44, "tv": 60199.4, "trd": NaN, "batb": [[2, 1.3, 126.28]], "batl": NaN}, {"timestamp": 1631534746647, "lt