{"info": {"id": "1.187594273", "eventId": "30897691", "eventName": "Match Odds", "marketType": "MATCH_ODDS", "openDate": 1631525507521, "name": "S Djoubri v E Shalimova", "numberOfActiveRunner": 2, "countryCode": "", "sport": "TENNIS", "venue": "", "volume": {"total": 558.26, "preMatch": 50.28, "inPlay": 507.98}, "winner": {"id": 12531094, "name": "S Djoubri", "status": "WINNER", "position": 1}, "delay": 5}, "runners": [{"id": 12531094, "name": "S Djoubri", "status": "WINNER", "position": 1, "inPlayOdds": 1.71, "inPlayTime": 1631526841811, "avgPrematch": 0, "closedOdds": 1.01, "maxPrematch": -100, "minPrematch": 1001, "maxInPlay": 1.71, "minInPlay": 1.01, "inPlayIndex": 0, "lengthOdds": 151, "lengthOddsPrematch": 0, "lengthOddsInPlay": 151, "tradedVolume": 490.13, "preMatchVolume": 49.91, "inPlayVolume": 440.22}, {"id": 13689566, "name": "E Shalimova", "status": "LOSER", "position": 2, "inPlayOdds": 1.05, "inPlayTime": 1631525507521, "avgPrematch": 1.05, "closedOdds": 2.4, "maxPrematch": 1.05, "minPrematch": 1.05, "maxInPlay": 2.4, "minInPlay": 1.05, "inPlayIndex": 7, "lengthOdds": 13, "lengthOddsPrematch": 7, "lengthOddsInPlay": 6, "tradedVolume": 68.13, "preMatchVolume": 0.37, "inPlayVolume": 67.76}], "marketUpdates": [{"timestamp": 1631518387108000000, "openDate": "2021-09-13T09:00:00.000Z", "status": "OPEN", "betDelay": 0, "inPlay": false, "complete": true}, {"timestamp": 1631522764146000000, "openDate": "2021-09-13T09:30:00.000Z", "status": "OPEN", "betDelay": 0, "inPlay": false, "complete": true}, {"timestamp": 1631525507521000000, "openDate": "2021-09-13T09:30:00.000Z", "status": "OPEN", "betDelay": 5, "inPlay": true, "complete": true}, {"timestamp": 1631526208624000000, "openDate": "2021-09-13T09:45:00.000Z", "status": "OPEN", "betDelay": 5, "inPlay": true, "complete": true}, {"timestamp": 1631526717255000000, "openDate": "2021-09-13T09:51:53.000Z", "status": "OPEN", "betDelay": 5, "inPlay": true, "complete": true}, {"timestamp": 1631531822858000000, "openDate": "2021-09-13T09:51:53.000Z", "status": "SUSPENDED", "betDelay": 5, "inPlay": true, "complete": true}, {"timestamp": 1631531828887000000, "openDate": "2021-09-13T09:51:53.000Z", "status": "CLOSED", "betDelay": 5, "inPlay": true, "complete": true}], "odds": [{"runnerId": 12531094, "odds": [{"timestamp": 1631526841811, "ltp": 1.71, "tv": 49.91, "trd": [[1.71, 49.91]], "batb": NaN, "batl": [[0, 1.71, 50.09]]}, {"timestamp": 1631526849803, "ltp": 1.71, "tv": 59.51, "trd": [[1.71, 59.51]], "batb": NaN, "batl": [[0, 1.71, 45.29]]}, {"timestamp": 1631526855599, "ltp": 1.71, "tv": 86.25, "trd": [[1.71, 86.25]], "batb": NaN, "batl": [[0, 1.71, 18.55]]}, {"timestamp": 1631526856004, "ltp": 1.71, "tv": 104.8, "trd": [[1.71, 104.8]], "batb": NaN, "batl": NaN}, {"timestamp": 1631526946475, "ltp": 1.71, "tv": 104.8, "trd": NaN, "batb": [[0, 1.62, 421.99], [1, 1.01, 7]], "batl": [[0, 2.6, 261.64]]}, {"timestamp": 1631526988732, "ltp": 1.71, "tv": 104.8, "trd": NaN, "batb": [[0, 1.01, 7], [1, 1.01, 0]], "batl": NaN}, {"timestamp": 1631526994268, "ltp": 1.71, "tv": 104.8, "trd": NaN, "batb": [[0, 1.67, 416.23], [1, 1.01, 7]], "batl": NaN}, {"timestamp": 1631527030523, "ltp": 1.71, "tv": 104.8, "trd": NaN, "batb": [[0, 1.01, 7], [1, 1.01, 0]], "batl": NaN}, {"timestamp": 1631527035695, "ltp": 1.71, "tv": 104.8, "trd": NaN, "batb": [[0, 1.74, 410.67], [1, 1.01, 7]], "batl": [[0, 2.92, 224.75]]}, {"timestamp": 1631527434740, "ltp": 1.71, "tv": 104.8, "trd": NaN, "batb": [[0, 1.01, 7], [1, 1.01, 0]], "batl": NaN}, {"timestamp": 1631528071851, "ltp": 1.71, "tv": 104.8, "trd": NaN, "batb": [[0, 1.77, 408.62], [1, 1.01, 7]], "batl": [[0, 3, 216.82]]}, {"timestamp": 1631528178767, "ltp": 1.71, "tv": 104.8, "trd": NaN, "batb": [[0, 1.01, 7], [1, 1.01, 0]], "batl": NaN}, {"timestamp": 1631528184465, "ltp": 1.71, "tv": 104.8, "trd": NaN, "batb": [[0, 1.86, 404.92], [1, 1.01, 7]], "batl": NaN}, {"timestamp": 1631528296830, "ltp": 1.71, "tv": 104.8, "trd": NaN, "batb": NaN, "batl": [[0, 3, 236.82]]}, {"timestamp": 1631528351225, "ltp": 1.71, "tv": 104.8, "trd": NaN, "batb": NaN, "batl": [[0, 3, 216.82]]}, {"timestamp": 1631528439055, "ltp": 1.71, "tv": 104.8, "trd": NaN, "batb": [[0, 1.01, 7], [1, 1.01, 0]], "batl": NaN}, {"timestamp": 1631528444852, "ltp": 1.71, "tv": 104.8, "trd": NaN, "batb": [[0, 1.7, 415.78], [1, 1.01, 7]], "batl": [[0, 2.82, 234.93]]}, {"timestamp": 1631528563912, "ltp": 1.71, "tv": 104.8, "trd": NaN, "batb": NaN, "batl": [[0, 2.6, 261.64]]}, {"timestamp": 1631528604855, "ltp": 1.71, "tv": 104.8, "trd": NaN, "batb": [[0, 1.01, 7], [1, 1.01, 0]], "batl": NaN}, {"timestamp": 1631528610461, "ltp": 1.71, "tv": 104.8, "trd": NaN, "batb": [[0, 1.58, 423.04], [1, 1.01, 7]], "batl": [[0, 2.5, 278.88]]}, {"timestamp": 1631528641614, "ltp": 1.71, "tv": 104.8, "trd": NaN, "batb": [[0, 1.01, 7], [1, 1.01, 0]], "batl": NaN}, {"timestamp": 1631528647018, "ltp": 1.71, "tv": 104.8, "trd": NaN, "batb": [[0, 1.62, 421.99], [1, 1.01, 7]], "batl": NaN}, {"timestamp": 1631528712140, "ltp": 1.71, "tv": 104.8, "trd": NaN, "batb": [[0, 1.01, 7], [1, 1.01, 0]], "batl": NaN}, {"timestamp": 1631528718147, "ltp": 1.71, "tv": 104.8, "trd": NaN, "batb": [[0, 1.46, 442.58], [1, 1.01, 7]], "batl": [[0, 2.22, 334.21]]}, {"timestamp": 1631528776097, "ltp": 1.71, "tv": 104.8, "trd": NaN, "batb": NaN, "batl": [[0, 2.1, 369.04]]}, {"timestamp": 1631528793963, "ltp": 1.71, "tv": 104.8, "trd": NaN, "batb": [[0, 1.01, 7], [1, 1.01, 0]], "batl": NaN}, {"timestamp": 1631528800448, "ltp": 1.71, "tv": 104.8, "trd": NaN, "batb": [[0, 1.34, 472.77], [1, 1.01, 7]], "batl": [[0, 1.95, 416.34]]}, {"timestamp": 1631528994436, "ltp": 1.71, "tv": 104.8, "trd": NaN, "batb": [[0, 1.01, 7], [1, 1.01, 0]], "batl": NaN}, {"timestamp": 1631529000547, "ltp": 1.71, "tv": 104.8, "trd": NaN, "batb": [[0, 1.28, 493.56], [1, 1.01, 7]], "batl": [[0, 1.82, 476.51]]}, {"timestamp": 1631529013864, "ltp": 1.71, "tv": 104.8, "trd": NaN, "batb": [[0, 1.01, 7], [1, 1.01, 0]], "batl": NaN}, {"timestamp": 1631529019785, "ltp": 1.71, "tv": 104.8, "trd": NaN, "batb": [[0, 1.23, 524.63], [1, 1.01, 7]], "batl": [[0, 1.73, 535.9]]}, {"timestamp": 1631529059792, "ltp": 1.71, "tv": 104.8, "trd": NaN, "batb": [[0, 1.01, 7], [1, 1.01, 0]], "batl": NaN}, {"timestamp": 1631529065300, "ltp": 1.71, "tv": 104.8, "trd": NaN, "batb": [[0, 1.2, 539.24], [1, 1.01, 7]], "batl": [[0, 1.66, 588.96]]}, {"timestamp": 1631529109694, "ltp": 1.71, "tv": 104.8, "trd": NaN, "batb": [[0, 1.01, 7], [1, 1.01, 0]], "batl": NaN}, {"timestamp": 1631529114961, "ltp": 1.71, "tv": 104.8, "trd": NaN, "batb": [[0, 1.23, 524.63], [1, 1.01, 7]], "batl": NaN}, {"timestamp": 1631529151622, "ltp": 1.71, "tv": 104.8, "trd": NaN, "batb": [[0, 1.01, 7], [1, 1.01, 0]], "batl": NaN}, {"timestamp": 1631529157744, "ltp": 1.71, "tv": 104.8, "trd": NaN, "batb": [[0, 1.18, 558.4], [1, 1.01, 7]], "batl": NaN}, {"timestamp": 1631529183177, "ltp": 1.71, "tv": 104.8, "trd": NaN, "batb": NaN, "batl": [[0, 1.58, 660.85]]}, {"timestamp": 1631529357922, "ltp": 1.71, "tv": 104.8, "trd": NaN, "batb": [[0, 1.01, 7], [1, 1.01, 0]], "batl": NaN}, {"timestamp": 1631529364033, "ltp": 1.71, "tv": 104.8, "trd": NaN, "batb": [[0, 1.2, 539.24], [1, 1.01, 7]], "batl": NaN}, {"timestamp": 1631529383448, "ltp": 1.71, "tv": 104.8, "trd": NaN, "batb": [[0, 1.01, 7], [1, 1.01, 0]], "batl": NaN}, {"timestamp": 1631529389467, "ltp": 1.71, "tv": 104.8, "trd": NaN, "batb": [[0, 1.22, 531.25], [1, 1.01, 7]], "batl": NaN}, {"timestamp": 1631529445757, "ltp": 1.71, "tv": 104.8, "trd": NaN, "batb": [[0, 1.01, 7], [1, 1.01, 0]], "batl": NaN}, {"timestamp": 1631529451556, "ltp": 1.71, "tv": 104.8, "trd": NaN, "batb": [[0, 1.16, 585.23], [1, 1.01, 7]], "batl": NaN}, {"timestamp": 1631529483733, "ltp": 1.71, "tv": 104.8, "trd": NaN, "batb": [[0, 1.01, 7], [1, 1.01, 0]], "batl": NaN}, {"timestamp": 1631529489703, "ltp": 1.71, "tv": 104.8, "trd": NaN, "batb": [[0, 1.14, 620.09], [1, 1.01, 7]], "batl": NaN}, {"timestamp": 1631529533076, "ltp": 1.71, "tv": 104.8, "trd": NaN, "batb": [[0, 1.01, 7], [1, 1.01, 0]], "batl": NaN}, {"timestamp": 1631529538679, "ltp": 1.71, "tv": 104.8, "trd": NaN, "batb": [[0, 1.1, 734.62], [1, 1.01, 7]], "batl": [[0, 1.48, 797.33]]}, {"timestamp": 1631529668938, "ltp": 1.71, "tv": 104.8, "trd": NaN, "batb": [[0, 1.01, 7], [1, 1.01, 0]], "batl": NaN}, {"timestamp": 1631529954089, "ltp": 1.71, "tv": 104.8, "trd": NaN, "batb": [[0, 1.08, 813.6], [1, 1.01, 7]], "batl": [[0, 1.44, 871.28]]}, {"timestamp": 1631529978519, "ltp": 1.71, "tv": 104.8, "trd": NaN, "batb": [[0, 1.01, 7], [1, 1.01, 0]], "batl": NaN}, {"timestamp": 1631529984510, "ltp": 1.71, "tv": 104.8, "trd": NaN, "batb": [[0, 1.06, 1009.59], [1, 1.01, 7]], "batl": NaN}, {"timestamp": 1631530010154, "ltp": 1.71, "tv": 104.8, "trd": NaN, "batb": [[0, 1.01, 7], [1, 1.01, 0]], "batl": NaN}, {"timestamp": 1631530016048, "ltp": 1.71, "tv": 104.8, "trd": NaN, "batb": [[0, 1.08, 813.6], [1, 1.01, 7]], "batl": NaN}, {"timestamp": 1631530030467, "ltp": 1.71, "tv": 104.8, "trd": NaN, "batb": [[0, 1.01, 7], [1, 1.01, 0]], "batl": NaN}, {"timestamp": 1631530036395, "ltp": 1.71, "tv": 104.8, "trd": NaN, "batb": [[0, 1.1, 734.62], [1, 1.01, 7]], "batl": NaN}, {"timestamp": 1631530060013, "ltp": 1.71, "tv": 104.8, "trd": NaN, "batb": [[0, 1.01, 7], [1, 1.01, 0]], "batl": NaN}, {"timestamp": 1631530065846, "ltp": 1.71, "tv": 104.8, "trd": NaN, "batb": [[0, 1.08, 813.6], [1, 1.01, 7]], "batl": NaN}, {"timestamp": 1631530075606, "ltp": 1.71, "tv": 104.8, "trd": NaN, "batb": [[1, 1.01, 9]], "batl": NaN}, {"timestamp": 1631530079225, "ltp": 1.71, "tv": 104.8, "trd": NaN, "batb": [[0, 1.01, 9], [1, 1.01, 0]], "batl": NaN}, {"timestamp": 1631530084721, "ltp": 1.71, "tv": 104.8, "trd": NaN, "batb": [[0, 1.06, 1009.59], [1, 1.01, 9]], "batl": NaN}, {"timestamp": 1631530091558, "ltp": 1.71, "tv": 104.8, "trd": NaN, "batb": [[0, 1.01, 9], [1, 1.01, 0]], "batl": NaN}, {"timestamp": 1631530097079, "ltp": 1.71, "tv": 104.8, "trd": NaN, "batb": [[0, 1.1, 734.62], [1, 1.01, 9]], "batl": NaN}, {"timestamp": 1631530139385, "ltp": 1.71, "tv": 104.8, "trd": NaN, "batb": [[0, 1.01, 9], [1, 1.01, 0]], "batl": NaN}, {"timestamp": 1631530145613, "ltp": 1.71, "tv": 104.8, "trd": NaN, "batb": [[0, 1.08, 813.6], [1, 1.01, 9]], "batl": NaN}, {"timestamp": 1631530163817, "ltp": 1.71, "tv": 104.8, "trd": NaN, "batb": [[0, 1.01, 9], [1, 1.01, 0]], "batl": NaN}, {"timestamp": 1631530170159, "ltp": 1.71, "tv": 104.8, "trd": NaN, "batb": [[0, 1.06, 1009.59], [1, 1.01, 9]], "batl": NaN}, {"timestamp": 1631530187284, "ltp": 1.71, "tv": 104.8, "trd": NaN, "batb": [[0, 1.01, 9], [1, 1.01, 0]], "batl": NaN}, {"timestamp": 1631530193381, "ltp": 1.71, "tv": 104.8, "trd": NaN, "batb": [[0, 1.05, 1086.47], [1, 1.01, 9]], "batl": NaN}, {"timestamp": 1631530256475, "ltp": 1.71, "tv": 104.8, "trd": NaN, "batb": [[0, 1.01, 9], [1, 1.01, 0]], "batl": NaN}, {"timestamp": 1631530262074, "ltp": 1.71, "tv": 104.8, "trd": NaN, "batb": [[0, 1.04, 1254.04], [1, 1.01, 9]], "batl": [[0, 1.36, 1042.16]]}, {"timestamp": 1631530292107, "ltp": 1.71, "tv": 104.8, "trd": NaN, "batb": NaN, "batl": [[0, 1.05, 183.8], [1, 1.36, 1042.16]]}, {"timestamp": 1631530300290, "ltp": 1.71, "tv": 104.8, "trd": NaN, "batb": [[0, 1.01, 9], [1, 1.01, 0]], "batl": NaN}, {"timestamp": 1631530302511, "ltp": 1.71, "tv": 104.8, "trd": NaN, "batb": NaN, "batl": [[0, 1.36, 1042.16], [1, 1.36, 0]]}, {"timestamp": 1631530306412, "ltp": 1.71, "tv": 104.8, "trd": NaN, "batb": [[0, 1.05, 1086.47], [1, 1.01, 9]], "batl": NaN}, {"timestamp": 1631530307608, "ltp": 1.05, "tv": 472.5, "trd": [[1.05, 367.7]], "batb": [[0, 1.05, 902.58]], "batl": NaN}, {"timestamp": 1631530335968, "ltp": 1.05, "tv": 472.5, "trd": NaN, "batb": [[0, 1.01, 9], [1, 1.01, 0]], "batl": NaN}, {"timestamp": 1631530342146, "ltp": 1.05, "tv": 472.5, "trd": NaN, "batb": [[0, 1.06, 800.22], [1, 1.01, 9]], "batl": NaN}, {"timestamp": 1631530373599, "ltp": 1.05, "tv": 472.5, "trd": NaN, "batb": [[0, 1.01, 9], [1, 1.01, 0]], "batl": NaN}, {"timestamp": 1631530379512, "ltp": 1.05, "tv": 472.5, "trd": NaN, "batb": [[0, 1.09, 583.79], [1, 1.01, 9]], "batl": NaN}, {"timestamp": 1631530444808, "ltp": 1.05, "tv": 472.5, "trd": NaN, "batb": [[0, 1.01, 9], [1, 1.01, 0]], "batl": NaN}, {"timestamp": 1631530450404, "ltp": 1.05, "tv": 472.5, "trd": NaN, "batb": [[0, 1.06, 769.33], [1, 1.01, 9]], "batl": NaN}, {"timestamp": 1631530475351, "ltp": 1.05, "tv": 472.5, "trd": NaN, "batb": [[0, 1.01, 9], [1, 1.01, 0]], "batl": NaN}, {"timestamp": 1631530480733, "ltp": 1.05, "tv": 472.5, "trd": NaN, "batb": [[0, 1.08, 630.79], [1, 1.01, 9]], "batl": NaN}, {"timestamp": 1631530503763, "ltp": 1.05, "tv": 472.5, "trd": NaN, "batb": [[0, 1.01, 9], [1, 1.01, 0]], "batl": NaN}, {"timestamp": 1631530510287, "ltp": 1.05, "tv": 472.5, "trd": NaN, "batb": [[0, 1.06, 769.33], [1, 1.01, 9]], "batl": NaN}, {"timestamp": 1631530554727, "ltp": 1.05, "tv": 472.5, "trd": NaN, "batb": [[0, 1.01, 9], [1, 1.01, 0]], "batl": NaN}, {"timestamp": 1631530560752, "ltp": 1.05, "tv": 472.5, "trd": NaN, "batb": [[0, 1.04, 1064.04], [1, 1.01, 9]], "batl": NaN}, {"timestamp": 1631530593258, "ltp": 1.05, "tv": 472.5, "trd": NaN, "batb": [[0, 1.01, 9], [1, 1.01, 0]], "batl": NaN}, {"timestamp": 1631530599098, "ltp": 1.05, "tv": 472.5, "trd": NaN, "batb": [[0, 1.06, 769.33], [1, 1.01, 9]], "batl": NaN}, {"timestamp": 1631530632041, "ltp": 1.05, "tv": 472.5, "trd": NaN, "batb": [[0, 1.01, 9], [1, 1.01, 0]], "batl": NaN}, {"timestamp": 1631530637339, "ltp": 1.05, "tv": 472.5, "trd": NaN, "batb": [[0, 1.04, 1088.26], [1, 1.01, 9]], "batl": NaN}, {"timestamp": 1631530678695, "ltp": 1.05, "tv": 472.5, "trd": NaN, "batb": [[0, 1.01, 9], [1, 1.01, 0]], "batl": NaN}, {"timestamp": 1631530684221, "ltp": 1.05, "tv": 472.5, "trd": NaN, "batb": [[0, 1.06, 769.33], [1, 1.01, 9]], "batl": NaN}, {"timestamp": 1631530712227, "ltp": 1.05, "tv": 472.5, "trd": NaN, "batb": [[0, 1.01, 9], [1, 1.01, 0]], "batl": NaN}, {"timestamp": 1631530718622, "ltp": 1.05, "tv": 472.5, "trd": NaN, "batb": [[0, 1.04, 1088.26], [1, 1.01, 9]], "batl": NaN}, {"timestamp": 1631530739773, "ltp": 1.05, "tv": 472.5, "trd": NaN, "batb": [[0, 1.01, 9], [1, 1.01, 0]], "batl": NaN}, {"timestamp": 1631530745855, "ltp": 1.05, "tv": 472.5, "trd": NaN, "batb": [[0, 1.06, 769.33], [1, 1.01, 9]], "batl": NaN}, {"timestamp": 1631530772210, "ltp": 1.05, "tv": 472.5, "trd": NaN, "batb": [[0, 1.01, 9], [1, 1.01, 0]], "batl": NaN}, {"timestamp": 1631530778299, "ltp": 1.05, "tv": 472.5, "trd": NaN, "batb": [[0, 1.08, 630.79], [1, 1.01, 9]], "batl": NaN}, {"timestamp": 1631530807669, "ltp": 1.05, "tv": 472.13, "trd": [[1.05, 367.33], [1.71, 104.8]], "batb": [[0, 1.01, 9], [1, 1.01, 0]], "batl": [[0, 1.36, 1040.12]]}, {"timestamp": 1631530813654, "ltp": 1.05, "tv": 472.13, "trd": NaN, "batb": [[0, 1.06, 767.82], [1, 1.01, 9]], "batl": NaN}, {"timestamp": 1631530851410, "ltp": 1.05, "tv": 472.13, "trd": NaN, "batb": [[0, 1.01, 9], [1, 1.01, 0]], "batl": NaN}, {"timestamp": 1631530856793, "ltp": 1.05, "tv": 472.13, "trd": NaN, "batb": [[0, 1.04, 1086.12], [1, 1.01, 9]], "batl": NaN}, {"timestamp": 1631530876925, "ltp": 1.05, "tv": 472.13, "trd": NaN, "batb": [[0, 1.01, 9], [1, 1.01, 0]], "batl": NaN}, {"timestamp": 1631530883354, "ltp": 1.05, "tv": 472.13, "trd": NaN, "batb": [[0, 1.03, 1359.51], [1, 1.01, 9]], "batl": NaN}, {"timestamp": 1631530900675, "ltp": 1.05, "tv": 472.13, "trd": NaN, "batb": NaN, "batl": [[0, 1.31, 29.05], [1, 1.36, 1040.12]]}, {"timestamp": 1631530938827, "ltp": 1.05, "tv": 472.13, "trd": NaN, "batb": [[0, 1.01, 9], [1, 1.01, 0]], "batl": NaN}, {"timestamp": 1631530944919, "ltp": 1.05, "tv": 472.13, "trd": NaN, "batb": [[0, 1.02, 1961.01], [1, 1.01, 9]], "batl": NaN}, {"timestamp": 1631530961676, "ltp": 1.05, "tv": 472.13, "trd": NaN, "batb": NaN, "batl": [[0, 1.29, 29.05], [1, 1.31, 29.05], [2, 1.36, 1040.12]]}, {"timestamp": 1631530969360, "ltp": 1.05, "tv": 472.13, "trd": NaN, "batb": [[0, 1.01, 9], [1, 1.01, 0]], "batl": NaN}, {"timestamp": 1631530975080, "ltp": 1.05, "tv": 472.13, "trd": NaN, "batb": [[0, 1.01, 3742.54]], "batl": NaN}, {"timestamp": 1631530977675, "ltp": 1.05, "tv": 472.13, "trd": NaN, "batb": NaN, "batl": [[0, 1.31, 29.05], [1, 1.36, 1040.12], [2, 1.36, 0]]}, {"timestamp": 1631530982783, "ltp": 1.05, "tv": 472.13, "trd": NaN, "batb": NaN, "batl": [[0, 1.28, 32.54], [1, 1.31, 29.05], [2, 1.36, 1040.12]]}, {"timestamp": 1631531000910, "ltp": 1.05, "tv": 472.13, "trd": NaN, "batb": [[0, 1.01, 9]], "batl": NaN}, {"timestamp": 1631531007012, "ltp": 1.05, "tv": 472.13, "trd": NaN, "batb": [[0, 1.02, 1961.01], [1, 1.01, 9]], "batl": NaN}, {"timestamp": 1631531012818, "ltp": 1.05, "tv": 472.13, "trd": NaN, "batb": NaN, "batl": [[1, 1.36, 1040.12], [2, 1.36, 0]]}, {"timestamp": 1631531017933, "ltp": 1.05, "tv": 472.13, "trd": NaN, "batb": NaN, "batl": [[0, 1.27, 44.16], [1, 1.28, 32.54], [2, 1.36, 1040.12]]}, {"timestamp": 1631531035498, "ltp": 1.05, "tv": 472.13, "trd": NaN, "batb": [[0, 1.01, 9], [1, 1.01, 0]], "batl": NaN}, {"timestamp": 1631531041100, "ltp": 1.05, "tv": 472.13, "trd": NaN, "batb": [[0, 1.01, 3742.54]], "batl": NaN}, {"timestamp": 1631531059730, "ltp": 1.05, "tv": 472.13, "trd": NaN, "batb": NaN, "batl": [[1, 1.36, 1040.12], [2, 1.36, 0]]}, {"timestamp": 1631531063728, "ltp": 1.05, "tv": 472.13, "trd": NaN, "batb": [[0, 1.01, 9]], "batl": NaN}, {"timestamp": 1631531064818, "ltp": 1.05, "tv": 472.13, "trd": NaN, "batb": NaN, "batl": [[0, 1.26, 29.05], [1, 1.27, 44.16], [2, 1.36, 1040.12]]}, {"timestamp": 1631531069327, "ltp": 1.05, "tv": 472.13, "trd": NaN, "batb": [[0, 1.01, 3832.75]], "batl": NaN}, {"timestamp": 1631531100398, "ltp": 1.05, "tv": 472.13, "trd": NaN, "batb": [[0, 1.01, 9]], "batl": [[2, 1.36, 0]]}, {"timestamp": 1631531102787, "ltp": 1.05, "tv": 472.13, "trd": NaN, "batb": NaN, "batl": [[1, 1.27, 0]]}, {"timestamp": 1631531105984, "ltp": 1.05, "tv": 472.13, "trd": NaN, "batb": NaN, "batl": [[1, 1.3, 1390.38]]}, {"timestamp": 1631531107968, "ltp": 1.05, "tv": 472.13, "trd": NaN, "batb": NaN, "batl": [[0, 1.25, 44.16], [1, 1.26, 29.05], [2, 1.3, 1390.38]]}, {"timestamp": 1631531230764, "ltp": 1.05, "tv": 472.13, "trd": NaN, "batb": NaN, "batl": [[1, 1.3, 1390.38], [2, 1.3, 0]]}, {"timestamp": 1631531235861, "ltp": 1.05, "tv": 472.13, "trd": NaN, "batb": NaN, "batl": [[0, 1.25, 73.21]]}, {"timestamp": 1631531236753, "ltp": 1.05, "tv": 472.13, "trd": NaN, "batb": NaN, "batl": [[0, 1.25, 29.05]]}, {"timestamp": 1631531241979, "ltp": 1.05, "tv": 472.13, "trd": NaN, "batb": NaN, "batl": [[0, 1.24, 44.16], [1, 1.25, 29.05], [2, 1.3, 1390.38]]}, {"timestamp": 1631531269701, "ltp": 1.05, "tv": 472.13, "trd": NaN, "batb": NaN, "batl": [[1, 1.3, 1390.38], [2, 1.3, 0]]}, {"timestamp": 1631531274784, "ltp": 1.05, "tv": 472.13, "trd": NaN, "batb": NaN, "batl": [[0, 1.2, 29.05], [1, 1.24, 44.16], [2, 1.3, 1390.38]]}, {"timestamp": 1631531275712, "ltp": 1.05, "tv": 472.13, "trd": NaN, "batb": NaN, "batl": [[1, 1.3, 1390.38], [2, 1.3, 0]]}, {"timestamp": 1631531280790, "ltp": 1.05, "tv": 472.13, "trd": NaN, "batb": NaN, "batl": [[0, 1.19, 44.16], [1, 1.2, 29.05], [2, 1.3, 1390.38]]}, {"timestamp": 1631531321650, "ltp": 1.01, "tv": 490.13, "trd": [[1.01, 18]], "batb": NaN, "batl": [[0, 1.01, 86], [1, 1.19, 44.16], [2, 1.2, 29.05]]}, {"timestamp": 1631531391861, "ltp": 1.01, "tv": 490.13, "trd": NaN, "batb": NaN, "batl": [[0, 1.19, 44.16], [1, 1.2, 29.05], [2, 1.3, 1390.38]]}, {"timestamp": 1631531444546, "ltp": 1.01, "tv": 490.13, "trd": NaN, "batb": NaN, "batl": [[2, 1.3, 0]]}, {"timestamp": 1631531512855, "ltp": 1.01, "tv": 490.13, "trd": NaN, "batb": NaN, "batl": [[0, 1.18, 766.61], [1, 1.19, 44.16], [2, 1.2, 29.05]]}, {"timestamp": 1631531515353, "ltp": 1.01, "tv": 490.13, "trd": NaN, "batb": NaN, "batl": [[0, 1.17, 56.22], [1, 1.18, 766.61], [2, 1.19, 44.16]]}, {"timestamp": 1631531582857, "ltp": 1.01, "tv": 490.13, "trd": NaN, "batb": NaN, "batl": [[2, 1.2, 29.05]]}, {"timestamp": 1631531588063, "ltp": 1.01, "tv": 490.13, "trd": NaN, "batb": NaN, "batl": [[0, 1.09, 44.16], [1, 1.17, 56.22], [2, 1.18, 766.61]]}, {"timestamp": 1631531600041, "ltp": 1.01, "tv": 490.13, "trd": NaN, "batb": NaN, "batl": [[0, 1.09, 73.21]]}, {"timestamp": 1631531613720, "ltp": 1.01, "tv": 490.13, "trd": NaN, "batb": NaN, "batl": [[0, 1.08, 396.93], [1, 1.09, 73.21], [2, 1.17, 56.22]]}, {"timestamp": 1631531675182, "ltp": 1.01, "tv": 490.13, "trd": NaN, "batb": NaN, "batl": [[0, 1.01, 17.04], [1, 1.08, 396.93], [2, 1.09, 73.21]]}, {"timestamp": 1631531690874, "ltp": 1.01, "tv": 490.13, "trd": NaN, "batb": NaN, "batl": [[2, 1.09, 29.05]]}, {"timestamp": 1631531696117, "ltp": 1.01, "tv": 490.13, "trd": NaN, "batb": NaN, "batl": [[1, 1.07, 44.16], [2, 1.08, 396.93]]}, {"timestamp": 1631531738543, "ltp": 1.01, "tv": 490.13, "trd": NaN, "batb": NaN, "batl": [[2, 1.09, 29.05]]}, {"timestamp": 1631531743651, "ltp": 1.01, "tv": 490.13, "trd": NaN, "batb": NaN, "batl": [[1, 1.06, 396.93], [2, 1.07, 44.16]]}, {"timestamp": 1631531796329, "ltp": 1.01, "tv": 490.13, "trd": NaN, "batb": NaN, "batl": [[0, 1.01, 4275.98]]}]}, {"runnerId": 13689566, "odds": [{"timestamp": 1631521060629, "ltp": 1.05, "tv": 0.18, "trd": [[1.05, 0.19]], "batb": [[0, 1.05, 880.79]], "batl": NaN}, {"timestamp": 1631521330485, "ltp": 1.05, "tv": 0.37, "trd": [[1.05, 0.37]], "batb": [[0, 1.05, 880.69]], "batl": NaN}, {"timestamp": 1631523661423, "ltp": 1.05, "tv": 0.37, "trd": NaN, "batb": [[0, 1.05, 880.17]], "batl": NaN}, {"timestamp": 1631523785964, "ltp": 1.05, "tv": 0.37, "trd": NaN, "batb": [[0, 2.38, 30.26], [1, 1.05, 880.17], [2, 1.01, 7]], "batl": NaN}, {"timestamp": 1631523787156, "ltp": 1.05, "tv": 0.37, "trd": NaN, "batb": [[0, 2.4, 9.14], [1, 2.38, 30.26], [2, 1.05, 880.17]], "batl": NaN}, {"timestamp": 1631524024869, "ltp": 1.05, "tv": 0.37, "trd": NaN, "batb": [[2, 1.01, 7]], "batl": NaN}, {"timestamp": 1631524759816, "ltp": 1.05, "tv": 0.37, "trd": NaN, "batb": [[2, 2.36, 2.66]], "batl": NaN}, {"timestamp": 1631525507521, "ltp": 1.05, "tv": 0.37, "trd": NaN, "batb": [[0, 1.01, 7], [1, 2.38, 0], [2, 2.36, 0]], "batl": NaN}, {"timestamp": 1631526841811, "ltp": 2.4, "tv": 35.93, "trd": [[2.4, 35.56]], "batb": NaN, "batl": NaN}, {"timestamp": 1631526855599, "ltp": 2.4, "tv": 54.98, "trd": [[2.4, 54.61]], "batb": NaN, "batl": NaN}, {"timestamp": 1631526856004, "ltp": 2.4, "tv": 68.2, "trd": [[2.4, 67.83]], "batb": NaN, "batl": NaN}, {"timestamp": 1631530807669, "ltp": 2.4, "tv": 68.13, "trd": [[2.4, 67.76]], "batb": NaN, "batl": NaN}, {"timestamp": 1631531105984, "ltp": 2.4, "tv": 68.13, "trd": NaN, "batb": NaN, "batl": [[0, 170, 36.3]]}]}]}