{"info": {"id": "1.187560677", "eventId": "30896281", "eventName": "Match Odds", "marketType": "MATCH_ODDS", "openDate": 1631545052619, "name": "Al Kovacevic v Str Kirchheimer", "numberOfActiveRunner": 2, "countryCode": "", "sport": "TENNIS", "venue": "", "volume": {"total": 39031.24, "preMatch": 11340.35, "inPlay": 27690.89}, "winner": {"id": 11439844, "name": "Aleksandar Kovacevic", "status": "WINNER", "position": 1}, "delay": 3}, "runners": [{"id": 11439844, "name": "Aleksandar Kovacevic", "status": "WINNER", "position": 1, "inPlayOdds": 1.35, "inPlayTime": 1631545052619, "avgPrematch": 1.37, "closedOdds": 1.01, "maxPrematch": 1.42, "minPrematch": 1.32, "maxInPlay": 1.52, "minInPlay": 1.01, "inPlayIndex": 200, "lengthOdds": 1918, "lengthOddsPrematch": 200, "lengthOddsInPlay": 1718, "tradedVolume": 37154.07, "preMatchVolume": 10676.74, "inPlayVolume": 26477.33}, {"id": 7588306, "name": "Strong Kirchheimer", "status": "LOSER", "position": 2, "inPlayOdds": 3.85, "inPlayTime": 1631545052619, "avgPrematch": 3.7, "closedOdds": 21.0, "maxPrematch": 4.0, "minPrematch": 3.45, "maxInPlay": 50.0, "minInPlay": 2.4, "inPlayIndex": 109, "lengthOdds": 1354, "lengthOddsPrematch": 109, "lengthOddsInPlay": 1245, "tradedVolume": 1877.17, "preMatchVolume": 663.61, "inPlayVolume": 1213.56}], "marketUpdates": [{"timestamp": 1631469492057000000, "openDate": "2021-09-13T15:00:00.000Z", "status": "OPEN", "betDelay": 0, "inPlay": false, "complete": true}, {"timestamp": 1631545022032000000, "openDate": "2021-09-13T14:56:00.000Z", "status": "OPEN", "betDelay": 0, "inPlay": false, "complete": true}, {"timestamp": 1631545052619000000, "openDate": "2021-09-13T14:56:00.000Z", "status": "OPEN", "betDelay": 3, "inPlay": true, "complete": true}, {"timestamp": 1631551511593000000, "openDate": "2021-09-13T14:56:00.000Z", "status": "SUSPENDED", "betDelay": 3, "inPlay": true, "complete": true}, {"timestamp": 1631551562863000000, "openDate": "2021-09-13T14:56:00.000Z", "status": "CLOSED", "betDelay": 3, "inPlay": true, "complete": true}], "odds": [{"runnerId": 11439844, "odds": [{"timestamp": 1631531145675, "ltp": 1.4, "tv": 34.98, "trd": [[1.4, 34.98]], "batb": [[0, 1.4, 60.82], [1, 1.16, 149.42], [2, 1.15, 766.61]], "batl": [[1, 3.2, 42.59], [2, 46, 29.02]]}, {"timestamp": 1631531146204, "ltp": 1.4, "tv": 34.98, "trd": NaN, "batb": [[0, 1.4, 78.31]], "batl": NaN}, {"timestamp": 1631531645626, "ltp": 1.4, "tv": 254.1, "trd": [[1.4, 254.1]], "batb": [[0, 1.17, 34.19]], "batl": [[0, 1.4, 1004.66], [1, 1.57, 25.53], [2, 3.2, 42.59]]}, {"timestamp": 1631531645928, "ltp": 1.4, "tv": 254.1, "trd": NaN, "batb": [[0, 1.16, 149.42], [1, 1.15, 766.61], [2, 1.12, 90.4]], "batl": NaN}, {"timestamp": 1631531649612, "ltp": 1.4, "tv": 254.1, "trd": NaN, "batb": [[0, 1.32, 97.89], [1, 1.16, 149.42], [2, 1.15, 766.61]], "batl": NaN}, {"timestamp": 1631531718625, "ltp": 1.4, "tv": 254.1, "trd": NaN, "batb": NaN, "batl": [[0, 1.57, 25.53], [1, 3.2, 42.59], [2, 46, 29.02]]}, {"timestamp": 1631531718728, "ltp": 1.4, "tv": 254.1, "trd": NaN, "batb": NaN, "batl": [[0, 1.39, 1004.66], [1, 1.57, 25.53], [2, 3.2, 42.59]]}, {"timestamp": 1631531792668, "ltp": 1.39, "tv": 259.2, "trd": [[1.39, 5.11]], "batb": NaN, "batl": [[0, 1.39, 999.56]]}, {"timestamp": 1631531824924, "ltp": 1.39, "tv": 301.79, "trd": [[1.39, 47.7]], "batb": NaN, "batl": [[0, 1.39, 978.26]]}, {"timestamp": 1631531826431, "ltp": 1.39, "tv": 319.56, "trd": [[1.39, 65.46]], "batb": NaN, "batl": [[0, 1.39, 969.38]]}, {"timestamp": 1631531877394, "ltp": 1.39, "tv": 362.15, "trd": [[1.39, 108.05]], "batb": NaN, "batl": [[0, 1.39, 948.09]]}, {"timestamp": 1631531936647, "ltp": 1.39, "tv": 383.74, "trd": [[1.39, 129.65]], "batb": NaN, "batl": [[0, 1.39, 937.29]]}, {"timestamp": 1631532109015, "ltp": 1.39, "tv": 594.54, "trd": [[1.39, 340.45]], "batb": NaN, "batl": [[0, 1.39, 831.89]]}, {"timestamp": 1631532176669, "ltp": 1.39, "tv": 594.54, "trd": NaN, "batb": [[0, 1.36, 85.18], [1, 1.32, 97.89], [2, 1.16, 149.42]], "batl": NaN}, {"timestamp": 1631532212503, "ltp": 1.39, "tv": 764.9, "trd": [[1.39, 510.8]], "batb": NaN, "batl": [[0, 1.39, 746.71]]}, {"timestamp": 1631532224216, "ltp": 1.39, "tv": 764.9, "trd": NaN, "batb": [[0, 1.38, 42.59], [1, 1.36, 85.18], [2, 1.32, 97.89]], "batl": NaN}, {"timestamp": 1631532244675, "ltp": 1.38, "tv": 1063.08, "trd": [[1.38, 42.64], [1.39, 766.34]], "batb": [[0, 1.36, 85.18], [1, 1.32, 97.89], [2, 1.16, 149.42]], "batl": [[0, 1.39, 618.94]]}, {"timestamp": 1631532245616, "ltp": 1.38, "tv": 1063.08, "trd": NaN, "batb": NaN, "batl": [[0, 1.38, 3.5], [1, 1.39, 618.94], [2, 1.57, 25.53]]}, {"timestamp": 1631532252846, "ltp": 1.36, "tv": 1070.08, "trd": [[1.36, 7]], "batb": [[0, 1.36, 81.68]], "batl": [[0, 1.39, 618.94], [1, 1.57, 25.53], [2, 3.2, 42.59]]}, {"timestamp": 1631532257293, "ltp": 1.36, "tv": 1070.08, "trd": NaN, "batb": [[0, 1.38, 42.59], [1, 1.36, 81.68], [2, 1.32, 97.89]], "batl": NaN}, {"timestamp": 1631532304231, "ltp": 1.36, "tv": 1070.08, "trd": NaN, "batb": [[0, 1.38, 85.18]], "batl": NaN}, {"timestamp": 1631532318542, "ltp": 1.39, "tv": 1223.4, "trd": [[1.39, 919.66]], "batb": NaN, "batl": [[0, 1.39, 542.28]]}, {"timestamp": 1631532335905, "ltp": 1.39, "tv": 1223.4, "trd": NaN, "batb": [[0, 1.32, 97.89], [1, 1.16, 149.42], [2, 1.15, 766.61]], "batl": NaN}, {"timestamp": 1631532347498, "ltp": 1.39, "tv": 1223.4, "trd": NaN, "batb": [[0, 1.37, 85.18], [1, 1.32, 97.89], [2, 1.16, 149.42]], "batl": NaN}, {"timestamp": 1631532378482, "ltp": 1.39, "tv": 1223.4, "trd": NaN, "batb": [[0, 1.38, 5.02], [1, 1.37, 85.18], [2, 1.32, 97.89]], "batl": NaN}, {"timestamp": 1631532466568, "ltp": 1.39, "tv": 1234.2, "trd": [[1.39, 930.46]], "batb": NaN, "batl": [[0, 1.39, 536.88]]}, {"timestamp": 1631532534482, "ltp": 1.39, "tv": 1449.7, "trd": [[1.39, 1145.96]], "batb": NaN, "batl": [[0, 1.39, 429.13]]}, {"timestamp": 1631532550395, "ltp": 1.39, "tv": 1449.7, "trd": NaN, "batb": [[2, 1.3, 104.41]], "batl": NaN}, {"timestamp": 1631532553122, "ltp": 1.39, "tv": 1457.36, "trd": [[1.39, 1153.62]], "batb": NaN, "batl": [[0, 1.39, 425.3]]}, {"timestamp": 1631532560643, "ltp": 1.39, "tv": 1457.36, "trd": NaN, "batb": [[0, 1.38, 90.2], [1, 1.3, 104.41], [2, 1.16, 149.42]], "batl": NaN}, {"timestamp": 1631532569543, "ltp": 1.39, "tv": 1457.36, "trd": NaN, "batb": [[0, 1.38, 5.02]], "batl": NaN}, {"timestamp": 1631532584818, "ltp": 1.39, "tv": 1542.54, "trd": [[1.39, 1238.8]], "batb": NaN, "batl": [[0, 1.39, 382.71]]}, {"timestamp": 1631532600644, "ltp": 1.39, "tv": 1552.57, "trd": [[1.39, 1248.84]], "batb": NaN, "batl": [[0, 1.39, 377.69]]}, {"timestamp": 1631532615457, "ltp": 1.39, "tv": 1552.57, "trd": NaN, "batb": [[1, 1.36, 42.59], [2, 1.3, 104.41]], "batl": NaN}, {"timestamp": 1631532652482, "ltp": 1.39, "tv": 1552.57, "trd": NaN, "batb": [[2, 1.16, 149.42]], "batl": NaN}, {"timestamp": 1631532692148, "ltp": 1.39, "tv": 1556.99, "trd": [[1.39, 1253.26]], "batb": NaN, "batl": [[0, 1.39, 375.48]]}, {"timestamp": 1631532805184, "ltp": 1.39, "tv": 1559.17, "trd": [[1.39, 1255.43]], "batb": NaN, "batl": [[0, 1.39, 373.31]]}, {"timestamp": 1631532952534, "ltp": 1.38, "tv": 1569.2, "trd": [[1.38, 52.67]], "batb": [[0, 1.36, 42.59], [1, 1.16, 149.42], [2, 1.15, 766.61]], "batl": [[0, 1.38, 5.77], [1, 1.39, 373.31], [2, 1.57, 25.53]]}, {"timestamp": 1631532958944, "ltp": 1.38, "tv": 1605.41, "trd": [[1.38, 88.88]], "batb": NaN, "batl": [[0, 1.39, 373.31], [1, 1.57, 25.53], [2, 3.2, 42.59]]}, {"timestamp": 1631533017634, "ltp": 1.38, "tv": 1605.41, "trd": NaN, "batb": [[0, 1.17, 23.63]], "batl": NaN}, {"timestamp": 1631533018319, "ltp": 1.38, "tv": 1605.41, "trd": NaN, "batb": [[0, 1.29, 11.53]], "batl": NaN}, {"timestamp": 1631533050135, "ltp": 1.38, "tv": 1605.41, "trd": NaN, "batb": [[0, 1.35, 37.57], [1, 1.29, 11.53], [2, 1.16, 149.42]], "batl": NaN}, {"timestamp": 1631533078680, "ltp": 1.39, "tv": 1642.32, "trd": [[1.39, 1292.34]], "batb": NaN, "batl": [[0, 1.39, 354.85]]}, {"timestamp": 1631533094666, "ltp": 1.39, "tv": 1642.32, "trd": NaN, "batb": [[0, 1.36, 3.01], [1, 1.35, 37.57], [2, 1.29, 11.53]], "batl": NaN}, {"timestamp": 1631533096678, "ltp": 1.39, "tv": 1642.32, "trd": NaN, "batb": NaN, "batl": [[1, 1.56, 13.44], [2, 1.57, 25]]}, {"timestamp": 1631533634578, "ltp": 1.39, "tv": 1642.32, "trd": NaN, "batb": NaN, "batl": [[0, 1.39, 1500.33]]}, {"timestamp": 1631533782642, "ltp": 1.39, "tv": 1642.32, "trd": NaN, "batb": [[0, 1.36, 40.58], [1, 1.29, 11.53], [2, 1.16, 149.42]], "batl": NaN}, {"timestamp": 1631534005664, "ltp": 1.39, "tv": 2112.23, "trd": [[1.39, 1762.25]], "batb": NaN, "batl": [[0, 1.39, 1030.42]]}, {"timestamp": 1631534039488, "ltp": 1.39, "tv": 2112.23, "trd": NaN, "batb": [[0, 1.37, 20.95], [1, 1.36, 40.58]], "batl": NaN}, {"timestamp": 1631534219558, "ltp": 1.39, "tv": 2135.85, "trd": [[1.39, 1785.87]], "batb": NaN, "batl": [[0, 1.39, 1006.8]]}, {"timestamp": 1631534307675, "ltp": 1.39, "tv": 2229.83, "trd": [[1.39, 1879.85]], "batb": NaN, "batl": [[0, 1.39, 912.82]]}, {"timestamp": 1631534407751, "ltp": 1.39, "tv": 2239.67, "trd": [[1.39, 1889.69]], "batb": NaN, "batl": [[0, 1.39, 907.9]]}, {"timestamp": 1631534677575, "ltp": 1.37, "tv": 2248.67, "trd": [[1.37, 9]], "batb": [[0, 1.37, 16.45]], "batl": NaN}, {"timestamp": 1631534929135, "ltp": 1.39, "tv": 2302.19, "trd": [[1.39, 1943.21]], "batb": NaN, "batl": [[0, 1.39, 881.13]]}, {"timestamp": 1631535098316, "ltp": 1.39, "tv": 2529.92, "trd": [[1.39, 2170.95]], "batb": NaN, "batl": [[0, 1.39, 767.23]]}, {"timestamp": 1631535124460, "ltp": 1.39, "tv": 2643.78, "trd": [[1.39, 2284.81]], "batb": NaN, "batl": [[0, 1.39, 710.28]]}, {"timestamp": 1631535164780, "ltp": 1.37, "tv": 2661.28, "trd": [[1.37, 26.49]], "batb": [[0, 1.37, 7.7]], "batl": NaN}, {"timestamp": 1631535165867, "ltp": 1.37, "tv": 2661.28, "trd": NaN, "batb": NaN, "batl": [[0, 1.38, 10.3], [1, 1.39, 710.28], [2, 1.56, 13.44]]}, {"timestamp": 1631535202075, "ltp": 1.39, "tv": 2775.14, "trd": [[1.38, 109.47], [1.39, 2378.08]], "batb": NaN, "batl": [[0, 1.39, 663.63], [1, 1.56, 13.44], [2, 1.57, 25]]}, {"timestamp": 1631535203276, "ltp": 1.39, "tv": 2775.14, "trd": NaN, "batb": [[0, 1.37, 18.47]], "batl": NaN}, {"timestamp": 1631535208800, "ltp": 1.39, "tv": 2775.14, "trd": NaN, "batb": [[0, 1.37, 41.75]], "batl": NaN}, {"timestamp": 1631535228312, "ltp": 1.39, "tv": 3055.84, "trd": [[1.39, 2658.78]], "batb": NaN, "batl": [[0, 1.39, 523.23]]}, {"timestamp": 1631535235260, "ltp": 1.39, "tv": 3055.84, "trd": NaN, "batb": [[0, 1.37, 18.47]], "batl": NaN}, {"timestamp": 1631535309398, "ltp": 1.39, "tv": 3168.13, "trd": [[1.39, 2771.07]], "batb": NaN, "batl": [[0, 1.39, 467.06]]}, {"timestamp": 1631535464690, "ltp": 1.39, "tv": 3356.17, "trd": [[1.39, 2959.11]], "batb": NaN, "batl": [[0, 1.39, 279.02]]}, {"timestamp": 1631535621256, "ltp": 1.39, "tv": 3356.17, "trd": NaN, "batb": [[0, 1.38, 37.57], [1, 1.37, 18.47], [2, 1.36, 3.01]], "batl": NaN}, {"timestamp": 1631535934480, "ltp": 1.39, "tv": 3404.17, "trd": [[1.39, 3007.12]], "batb": NaN, "batl": [[0, 1.39, 255.02]]}, {"timestamp": 1631536510985, "ltp": 1.39, "tv": 3479.32, "trd": [[1.39, 3082.26]], "batb": [[0, 1.37, 18.47], [1, 1.36, 3.01], [2, 1.16, 149.42]], "batl": [[0, 1.39, 217.44]]}, {"timestamp": 1631536578343, "ltp": 1.39, "tv": 3542.17, "trd": [[1.39, 3145.11]], "batb": NaN, "batl": [[0, 1.39, 186.01]]}, {"timestamp": 1631536636585, "ltp": 1.39, "tv": 3874.19, "trd": [[1.39, 3477.13]], "batb": NaN, "batl": [[0, 1.39, 19.94]]}, {"timestamp": 1631536642778, "ltp": 1.39, "tv": 3874.19, "trd": NaN, "batb": NaN, "batl": [[1, 1.49, 21.55], [2, 1.56, 13.44]]}, {"timestamp": 1631536697681, "ltp": 1.39, "tv": 3874.19, "trd": NaN, "batb": NaN, "batl": [[2, 1.57, 25.53]]}, {"timestamp": 1631536698159, "ltp": 1.39, "tv": 3874.19, "trd": NaN, "batb": NaN, "batl": [[2, 1.57, 38.21]]}, {"timestamp": 1631536759646, "ltp": 1.39, "tv": 3874.19, "trd": NaN, "batb": [[2, 1.16, 411.79]], "batl": NaN}, {"timestamp": 1631536780632, "ltp": 1.39, "tv": 3874.19, "trd": NaN, "batb": NaN, "batl": [[1, 1.4, 3.44], [2, 1.49, 21.55]]}, {"timestamp": 1631536807460, "ltp": 1.39, "tv": 3883.76, "trd": [[1.39, 3486.7]], "batb": NaN, "batl": [[0, 1.39, 15.15]]}, {"timestamp": 1631536811297, "ltp": 1.39, "tv": 3883.76, "trd": NaN, "batb": NaN, "batl": [[2, 1.5, 21.55]]}, {"timestamp": 1631536841191, "ltp": 1.39, "tv": 3883.76, "trd": NaN, "batb": [[0, 1.38, 30.78], [1, 1.37, 18.47], [2, 1.36, 3.01]], "batl": NaN}, {"timestamp": 1631536849218, "ltp": 1.39, "tv": 3883.76, "trd": NaN, "batb": [[0, 1.37, 18.47], [1, 1.36, 3.01], [2, 1.16, 411.79]], "batl": NaN}, {"timestamp": 1631536859038, "ltp": 1.4, "tv": 3920.94, "trd": [[1.39, 3517.01], [1.4, 260.98]], "batb": [[0, 1.4, 12.67], [1, 1.37, 18.47], [2, 1.36, 3.01]], "batl": [[0, 1.5, 21.55], [1, 1.57, 38.21], [2, 1.8, 43.73]]}, {"timestamp": 1631536860603, "ltp": 1.4, "tv": 3920.94, "trd": NaN, "batb": [[0, 1.37, 10.77], [1, 1.36, 3.01], [2, 1.16, 411.79]], "batl": NaN}, {"timestamp": 1631536862537, "ltp": 1.4, "tv": 3920.94, "trd": NaN, "batb": [[0, 1.4, 78.31], [1, 1.37, 10.77], [2, 1.36, 3.01]], "batl": NaN}, {"timestamp": 1631536863219, "ltp": 1.4, "tv": 3920.94, "trd": NaN, "batb": [[1, 1.39, 7.88]], "batl": NaN}, {"timestamp": 1631536878651, "ltp": 1.4, "tv": 3920.94, "trd": NaN, "batb": NaN, "batl": [[0, 1.57, 38.21], [1, 1.8, 43.73], [2, 1.89, 2.66]]}, {"timestamp": 1631536878755, "ltp": 1.4, "tv": 3920.94, "trd": NaN, "batb": NaN, "batl": [[0, 1.53, 22.08], [1, 1.57, 37.69], [2, 1.8, 43.73]]}, {"timestamp": 1631536895236, "ltp": 1.4, "tv": 3920.94, "trd": NaN, "batb": [[0, 1.41, 22.62], [1, 1.4, 78.31], [2, 1.39, 7.88]], "batl": NaN}, {"timestamp": 1631536896594, "ltp": 1.4, "tv": 3920.94, "trd": NaN, "batb": [[2, 1.36, 3.01]], "batl": NaN}, {"timestamp": 1631536896800, "ltp": 1.4, "tv": 3920.94, "trd": NaN, "batb": [[0, 1.41, 30.38]], "batl": NaN}, {"timestamp": 1631537285600, "ltp": 1.4, "tv": 3920.94, "trd": NaN, "batb": [[1, 1.4, 80.87]], "batl": NaN}, {"timestamp": 1631537302473, "ltp": 1.4, "tv": 4164.21, "trd": [[1.4, 443.48], [1.41, 60.77]], "batb": [[0, 1.36, 3.01], [1, 1.16, 411.79], [2, 1.15, 766.61]], "batl": NaN}, {"timestamp": 1631537304556, "ltp": 1.4, "tv": 4164.21, "trd": NaN, "batb": [[1, 1.32, 97.89], [2, 1.16, 411.79]], "batl": NaN}, {"timestamp": 1631537323988, "ltp": 1.4, "tv": 4168.22, "trd": [[1.4, 447.48]], "batb": NaN, "batl": [[0, 1.4, 3.11], [1, 1.53, 22.08], [2, 1.57, 37.69]]}, {"timestamp": 1631537391446, "ltp": 1.4, "tv": 4173.33, "trd": [[1.4, 452.59]], "batb": NaN, "batl": [[0, 1.52, 1.08], [1, 1.53, 21.55]]}, {"timestamp": 1631537493757, "ltp": 1.4, "tv": 4173.33, "trd": NaN, "batb": [[2, 1.18, 108.94]], "batl": NaN}, {"timestamp": 1631537567555, "ltp": 1.4, "tv": 4173.33, "trd": NaN, "batb": [[0, 1.38, 86.03], [1, 1.36, 3.01], [2, 1.32, 97.89]], "batl": NaN}, {"timestamp": 1631537674779, "ltp": 1.4, "tv": 4173.33, "trd": NaN, "batb": [[0, 1.36, 3.01], [1, 1.32, 97.89], [2, 1.18, 108.94]], "batl": NaN}, {"timestamp": 1631537809537, "ltp": 1.4, "tv": 4173.33, "trd": NaN, "batb": NaN, "batl": [[0, 1.53, 22.08], [1, 1.57, 37.69], [2, 1.8, 43.73]]}, {"timestamp": 1631537821116, "ltp": 1.4, "tv": 4173.33, "trd": NaN, "batb": [[0, 1.4, 137.14], [1, 1.36, 3.01], [2, 1.32, 97.89]], "batl": NaN}, {"timestamp": 1631537821899, "ltp": 1.4, "tv": 4173.33, "trd": NaN, "batb": [[0, 1.41, 9.64], [1, 1.4, 137.14], [2, 1.36, 3.01]], "batl": NaN}, {"timestamp": 1631537911671, "ltp": 1.4, "tv": 4173.33, "trd": NaN, "batb": NaN, "batl": [[2, 1.89, 2.66]]}, {"timestamp": 1631538002709, "ltp": 1.4, "tv": 4173.33, "trd": NaN, "batb": [[0, 1.4, 137.14], [1, 1.36, 3.01], [2, 1.32, 130.52]], "batl": NaN}, {"timestamp": 1631538018850, "ltp": 1.4, "tv": 4173.69, "trd": [[1.36, 7], [1.37, 26.48], [1.38, 109.46], [1.39, 3517.42], [1.4, 452.54], [1.41, 60.79]], "batb": [[0, 1.4, 137.11]], "batl": [[0, 1.53, 22.11], [1, 1.57, 37.68], [2, 1.89, 2.66]]}, {"timestamp": 1631538144265, "ltp": 1.4, "tv": 4173.69, "trd": NaN, "batb": [[0, 1.42, 94.53], [1, 1.4, 137.11], [2, 1.36, 3.01]], "batl": NaN}, {"timestamp": 1631538237304, "ltp": 1.42, "tv": 4362.76, "trd": [[1.42, 189.06]], "batb": [[0, 1.4, 137.11], [1, 1.36, 3.01], [2, 1.32, 130.52]], "batl": [[0, 1.42, 1050.76], [1, 1.53, 22.11], [2, 1.57, 37.68]]}, {"timestamp": 1631538313365, "ltp": 1.42, "tv": 4362.76, "trd": NaN, "batb": NaN, "batl": [[0, 1.41, 21.58], [1, 1.42, 1050.76], [2, 1.57, 38.2]]}, {"timestamp": 1631539458616, "ltp": 1.42, "tv": 4362.76, "trd": NaN, "batb": NaN, "batl": [[0, 1.42, 1050.76], [1, 1.57, 38.2], [2, 1.89, 2.66]]}, {"timestamp": 1631539486485, "ltp": 1.42, "tv": 4362.76, "trd": NaN, "batb": NaN, "batl": [[0, 1.41, 22.65], [1, 1.42, 1050.76], [2, 1.57, 38.2]]}, {"timestamp": 1631540052708, "ltp": 1.4, "tv": 4636.99, "trd": [[1.4, 726.77]], "batb": [[0, 1.36, 3.01], [1, 1.32, 130.52], [2, 1.2, 218.49]], "batl": [[0, 1.4, 913.65], [1, 1.41, 22.65]]}, {"timestamp": 1631540099139, "ltp": 1.4, "tv": 4636.99, "trd": NaN, "batb": NaN, "batl": [[0, 1.39, 22.65], [1, 1.4, 913.65]]}, {"timestamp": 1631540149160, "ltp": 1.4, "tv": 4636.99, "trd": NaN, "batb": [[0, 1.37, 150.74], [1, 1.36, 3.01], [2, 1.32, 130.52]], "batl": NaN}, {"timestamp": 1631540298714, "ltp": 1.4, "tv": 4636.99, "trd": NaN, "batb": NaN, "batl": [[2, 1.57, 25.53]]}, {"timestamp": 1631540299607, "ltp": 1.4, "tv": 4636.99, "trd": NaN, "batb": NaN, "batl": [[2, 1.57, 38.2]]}, {"timestamp": 1631541194343, "ltp": 1.4, "tv": 4636.99, "trd": NaN, "batb": NaN, "batl": [[0, 1.4, 913.65], [1, 1.57, 38.2], [2, 1.8, 43.7]]}, {"timestamp": 1631541226455, "ltp": 1.4, "tv": 4636.99, "trd": NaN, "batb": NaN, "batl": [[0, 1.39, 22.97], [1, 1.4, 913.65], [2, 1.57, 38.2]]}, {"timestamp": 1631541356539, "ltp": 1.37, "tv": 4640.39, "trd": [[1.37, 29.89]], "batb": [[0, 1.37, 149.04]], "batl": NaN}, {"timestamp": 1631541601158, "ltp": 1.37, "tv": 4640.39, "trd": NaN, "batb": [[2, 1.34, 37.57]], "batl": NaN}, {"timestamp": 1631541946183, "ltp": 1.37, "tv": 4645.71, "trd": [[1.37, 35.21]], "batb": [[0, 1.37, 146.38]], "batl": [[0, 1.39, 25.97]]}, {"timestamp": 1631542421034, "ltp": 1.37, "tv": 4645.71, "trd": NaN, "batb": NaN, "batl": [[2, 1.43, 2.03]]}, {"timestamp": 1631543326545, "ltp": 1.36, "tv": 5136.84, "trd": [[1.36, 114.37], [1.37, 418.96]], "batb": [[0, 1.34, 37.57], [1, 1.32, 130.52], [2, 1.21, 121.67]], "batl": [[0, 1.35, 4981.37], [1, 1.39, 25.97], [2, 1.4, 913.65]]}, {"timestamp": 1631543327170, "ltp": 1.34, "tv": 5174.37, "trd": [[1.34, 37.53]], "batb": [[0, 1.32, 130.52], [1, 1.29, 44.05]], "batl": NaN}, {"timestamp": 1631543347352, "ltp": 1.34, "tv": 5174.37, "trd": NaN, "batb": NaN, "batl": [[0, 1.34, 32.61], [1, 1.35, 4981.37], [2, 1.39, 3]]}, {"timestamp": 1631543415079, "ltp": 1.34, "tv": 5181.56, "trd": [[1.34, 44.71]], "batb": NaN, "batl": [[0, 1.34, 29.02]]}, {"timestamp": 1631543505985, "ltp": 1.32, "tv": 5193.49, "trd": [[1.32, 11.93]], "batb": [[0, 1.32, 124.55]], "batl": NaN}, {"timestamp": 1631543507291, "ltp": 1.34, "tv": 5222.51, "trd": [[1.34, 73.74]], "batb": NaN, "batl": [[0, 1.35, 4991.07], [1, 1.39, 3], [2, 1.4, 913.65]]}, {"timestamp": 1631543509535, "ltp": 1.34, "tv": 5222.51, "trd": NaN, "batb": [[0, 1.32, 130.52]], "batl": NaN}, {"timestamp": 1631543509744, "ltp": 1.34, "tv": 5222.51, "trd": NaN, "batb": NaN, "batl": [[0, 1.35, 4981.37]]}, {"timestamp": 1631543525550, "ltp": 1.34, "tv": 5222.51, "trd": NaN, "batb": [[1, 1.31, 8.71], [2, 1.29, 44.05]], "batl": NaN}, {"timestamp": 1631543526649, "ltp": 1.35, "tv": 5572.67, "trd": [[1.35, 350.16]], "batb": NaN, "batl": [[0, 1.35, 4806.33]]}, {"timestamp": 1631543563726, "ltp": 1.32, "tv": 5582.67, "trd": [[1.32, 21.93]], "batb": [[0, 1.32, 125.52]], "batl": NaN}, {"timestamp": 1631543565240, "ltp": 1.32, "tv": 5582.67, "trd": NaN, "batb": [[0, 1.32, 130.52]], "batl": NaN}, {"timestamp": 1631543615688, "ltp": 1.35, "tv": 5590.57, "trd": [[1.35, 358.06]], "batb": NaN, "batl": [[0, 1.35, 4802.38]]}, {"timestamp": 1631543618395, "ltp": 1.34, "tv": 5599.89, "trd": [[1.34, 83.06]], "batb": NaN, "batl": NaN}, {"timestamp": 1631543637503, "ltp": 1.35, "tv": 5662.66, "trd": [[1.35, 420.83]], "batb": NaN, "batl": [[0, 1.35, 4746.14]]}, {"timestamp": 1631543639737, "ltp": 1.35, "tv": 5692.01, "trd": [[1.35, 450.18]], "batb": NaN, "batl": [[0, 1.35, 4716.78]]}, {"timestamp": 1631543646920, "ltp": 1.35, "tv": 5692.01, "trd": NaN, "batb": [[0, 1.32, 280.41]], "batl": NaN}, {"timestamp": 1631543650011, "ltp": 1.35, "tv": 5714.81, "trd": [[1.35, 472.98]], "batb": NaN, "batl": [[0, 1.35, 4705.39]]}, {"timestamp": 1631543661673, "ltp": 1.35, "tv": 5786.7, "trd": [[1.35, 544.87]], "batb": NaN, "batl": [[0, 1.35, 4669.45]]}, {"timestamp": 1631543676586, "ltp": 1.35, "tv": 5806.28, "trd": [[1.35, 564.45]], "batb": NaN, "batl": [[0, 1.35, 4659.66]]}, {"timestamp": 1631543687080, "ltp": 1.35, "tv": 5911.53, "trd": [[1.35, 669.7]], "batb": NaN, "batl": [[0, 1.35, 4607.04]]}, {"timestamp": 1631543726938, "ltp": 1.35, "tv": 5911.53, "trd": NaN, "batb": NaN, "batl": [[0, 1.34, 3.41], [1, 1.35, 4607.04], [2, 1.39, 3]]}, {"timestamp": 1631543810659, "ltp": 1.35, "tv": 5931.36, "trd": [[1.34, 89.87], [1.35, 682.71]], "batb": NaN, "batl": [[0, 1.35, 4600.53], [1, 1.39, 3], [2, 1.4, 913.65]]}, {"timestamp": 1631543899692, "ltp": 1.35, "tv": 5931.36, "trd": NaN, "batb": [[2, 1.21, 121.67]], "batl": NaN}, {"timestamp": 1631543905703, "ltp": 1.35, "tv": 5931.36, "trd": NaN, "batb": [[2, 1.29, 44.05]], "batl": NaN}, {"timestamp": 1631543906284, "ltp": 1.34, "tv": 5931.43, "trd": [[1.34, 89.95]], "batb": NaN, "batl": [[0, 1.34, 42.51], [1, 1.35, 4600.53], [2, 1.39, 3]]}, {"timestamp": 1631543907715, "ltp": 1.34, "tv": 5993.91, "trd": [[1.34, 152.42]], "batb": NaN, "batl": [[0, 1.34, 11.29]]}, {"timestamp": 1631543916478, "ltp": 1.34, "tv": 5993.91, "trd": NaN, "batb": NaN, "batl": [[0, 1.35, 4610.67], [1, 1.39, 3], [2, 1.4, 913.65]]}, {"timestamp": 1631543920527, "ltp": 1.35, "tv": 6055.34, "trd": [[1.35, 744.15]], "batb": NaN, "batl": [[0, 1.35, 4569.8]]}, {"timestamp": 1631543929696, "ltp": 1.35, "tv": 6254.62, "trd": [[1.35, 943.43]], "batb": NaN, "batl": [[0, 1.35, 4470.17]]}, {"timestamp": 1631543931211, "ltp": 1.35, "tv": 6256.02, "trd": [[1.35, 944.82]], "batb": NaN, "batl": [[0, 1.35, 4469.48]]}, {"timestamp": 1631543961660, "ltp": 1.35, "tv": 6693.04, "trd": [[1.35, 1381.85]], "batb": NaN, "batl": [[0, 1.35, 4251.01]]}, {"timestamp": 1631543971788, "ltp": 1.35, "tv": 6693.04, "trd": NaN, "batb": [[2, 1.21, 121.67]], "batl": NaN}, {"timestamp": 1631543997688, "ltp": 1.35, "tv": 6795.53, "trd": [[1.35, 1484.34]], "batb": [[2, 1.3, 42.58]], "batl": [[0, 1.35, 4199.77]]}, {"timestamp": 1631543997897, "ltp": 1.35, "tv": 6795.53, "trd": NaN, "batb": [[0, 1.33, 24.01], [1, 1.32, 290.75], [2, 1.31, 8.71]], "batl": NaN}, {"timestamp": 1631544047701, "ltp": 1.35, "tv": 6822.79, "trd": [[1.35, 1511.6]], "batb": NaN, "batl": [[0, 1.35, 4172.51]]}, {"timestamp": 1631544049884, "ltp": 1.35, "tv": 6842.45, "trd": [[1.35, 1531.25]], "batb": NaN, "batl": [[0, 1.35, 4162.68]]}, {"timestamp": 1631544051673, "ltp": 1.35, "tv": 6904.95, "trd": [[1.35, 1593.76]], "batb": NaN, "batl": [[0, 1.35, 4131.43]]}, {"timestamp": 1631544063722, "ltp": 1.35, "tv": 7404.83, "trd": [[1.35, 2093.64]], "batb": NaN, "batl": [[0, 1.35, 3881.54]]}, {"timestamp": 1631544129850, "ltp": 1.35, "tv": 7430.83, "trd": [[1.35, 2119.64]], "batb": NaN, "batl": [[0, 1.35, 3868.54]]}, {"timestamp": 1631544174233, "ltp": 1.35, "tv": 7474.86, "trd": [[1.35, 2163.66]], "batb": NaN, "batl": [[0, 1.35, 3824.52]]}, {"timestamp": 1631544193011, "ltp": 1.35, "tv": 7580.52, "trd": [[1.35, 2269.32]], "batb": NaN, "batl": [[0, 1.35, 3771.66]]}, {"timestamp": 1631544205221, "ltp": 1.35, "tv": 7635.17, "trd": [[1.35, 2323.97]], "batb": NaN, "batl": [[0, 1.35, 3717.01]]}, {"timestamp": 1631544210326, "ltp": 1.35, "tv": 7635.17, "trd": NaN, "batb": [[0, 1.32, 280.41], [1, 1.31, 8.71], [2, 1.29, 44.05]], "batl": NaN}, {"timestamp": 1631544214555, "ltp": 1.35, "tv": 7635.17, "trd": NaN, "batb": [[0, 1.33, 152.79], [1, 1.32, 280.41], [2, 1.31, 8.71]], "batl": NaN}, {"timestamp": 1631544229286, "ltp": 1.35, "tv": 7635.17, "trd": NaN, "batb": [[0, 1.33, 9.24], [2, 1.31, 17.97]], "batl": NaN}, {"timestamp": 1631544235071, "ltp": 1.35, "tv": 8003.27, "trd": [[1.35, 2692.08]], "batb": NaN, "batl": [[0, 1.35, 3532.86]]}, {"timestamp": 1631544239300, "ltp": 1.35, "tv": 8011.79, "trd": [[1.35, 2700.6]], "batb": NaN, "batl": [[0, 1.35, 3528.6]]}, {"timestamp": 1631544266652, "ltp": 1.35, "tv": 8017.1, "trd": [[1.35, 2705.9]], "batb": NaN, "batl": [[0, 1.35, 3525.94]]}, {"timestamp": 1631544306822, "ltp": 1.35, "tv": 8036.59, "trd": [[1.35, 2725.4]], "batb": NaN, "batl": [[0, 1.35, 3516.2]]}, {"timestamp": 1631544337062, "ltp": 1.33, "tv": 8041.07, "trd": [[1.33, 4.48]], "batb": [[0, 1.33, 7]], "batl": NaN}, {"timestamp": 1631544412360, "ltp": 1.33, "tv": 8041.07, "trd": NaN, "batb": [[0, 1.32, 280.41], [1, 1.31, 17.97], [2, 1.29, 44.05]], "batl": [[0, 1.34, 913.65], [1, 1.35, 3516.2], [2, 1.39, 3]]}, {"timestamp": 1631544447604, "ltp": 1.34, "tv": 8225.03, "trd": [[1.34, 336.38]], "batb": [[1, 1.31, 8.71]], "batl": [[0, 1.34, 821.67]]}, {"timestamp": 1631544468620, "ltp": 1.34, "tv": 8225.03, "trd": NaN, "batb": [[0, 1.32, 291.86]], "batl": NaN}, {"timestamp": 1631544517971, "ltp": 1.32, "tv": 8230.15, "trd": [[1.32, 27.05]], "batb": [[0, 1.32, 289.3]], "batl": NaN}, {"timestamp": 1631544519166, "ltp": 1.32, "tv": 8230.15, "trd": NaN, "batb": [[0, 1.32, 291.86]], "batl": NaN}, {"timestamp": 1631544534829, "ltp": 1.34, "tv": 8261.89, "trd": [[1.34, 368.12]], "batb": NaN, "batl": [[0, 1.34, 805.8]]}, {"timestamp": 1631544556243, "ltp": 1.34, "tv": 8261.89, "trd": NaN, "batb": [[0, 1.33, 212.91], [1, 1.32, 300.85], [2, 1.31, 8.71]], "batl": NaN}, {"timestamp": 1631544565075, "ltp": 1.34, "tv": 8687.72, "trd": [[1.34, 793.95]], "batb": NaN, "batl": [[0, 1.34, 592.89]]}, {"timestamp": 1631544568882, "ltp": 1.34, "tv": 8718.71, "trd": [[1.34, 824.94]], "batb": NaN, "batl": [[0, 1.34, 561.89]]}, {"timestamp": 1631544576686, "ltp": 1.34, "tv": 9144.54, "trd": [[1.34, 1250.77]], "batb": [[0, 1.32, 291.86], [1, 1.31, 17.06], [2, 1.29, 44.05]], "batl": [[0, 1.34, 348.98]]}, {"timestamp": 1631544577256, "ltp": 1.34, "tv": 9144.54, "trd": NaN, "batb": [[1, 1.31, 8.71]], "batl": NaN}, {"timestamp": 1631544578393, "ltp": 1.34, "tv": 9144.54, "trd": NaN, "batb": [[2, 1.2, 121.67]], "batl": NaN}, {"timestamp": 1631544579291, "ltp": 1.34, "tv": 9144.54, "trd": NaN, "batb": [[2, 1.29, 44.05]], "batl": NaN}, {"timestamp": 1631544603687, "ltp": 1.34, "tv": 9634.24, "trd": [[1.34, 1740.47]], "batb": [[1, 1.31, 22.08]], "batl": [[0, 1.34, 104.28]]}, {"timestamp": 1631544635528, "ltp": 1.34, "tv": 9842.97, "trd": [[1.34, 1949.2]], "batb": [[0, 1.34, 108.46], [1, 1.32, 291.86], [2, 1.31, 22.08]], "batl": [[0, 1.35, 3516.2], [1, 1.39, 3], [2, 1.42, 11.45]]}, {"timestamp": 1631544668874, "ltp": 1.35, "tv": 9872.85, "trd": [[1.35, 2755.28]], "batb": NaN, "batl": [[0, 1.35, 3486.32]]}, {"timestamp": 1631544722569, "ltp": 1.35, "tv": 9876.79, "trd": [[1.35, 2759.22]], "batb": NaN, "batl": [[0, 1.35, 3482.38]]}, {"timestamp": 1631544754014, "ltp": 1.35, "tv": 9883.22, "trd": [[1.35, 2765.65]], "batb": NaN, "batl": [[0, 1.35, 3479.16]]}, {"timestamp": 1631544762300, "ltp": 1.35, "tv": 9883.22, "trd": NaN, "batb": [[1, 1.32, 161.34]], "batl": NaN}, {"timestamp": 1631544787757, "ltp": 1.35, "tv": 9889.54, "trd": [[1.35, 2771.97]], "batb": NaN, "batl": [[0, 1.35, 3476]]}, {"timestamp": 1631544836999, "ltp": 1.35, "tv": 9946.05, "trd": [[1.35, 2828.48]], "batb": NaN, "batl": [[0, 1.35, 3447.74]]}, {"timestamp": 1631544890470, "ltp": 1.35, "tv": 10037.16, "trd": [[1.35, 2919.59]], "batb": NaN, "batl": [[0, 1.35, 3402.17]]}, {"timestamp": 1631544920698, "ltp": 1.35, "tv": 10219.35, "trd": [[1.35, 3101.78]], "batb": NaN, "batl": [[0, 1.35, 3311.02]]}, {"timestamp": 1631544960544, "ltp": 1.35, "tv": 10346.34, "trd": [[1.35, 3228.77]], "batb": NaN, "batl": [[0, 1.35, 3247.54]]}, {"timestamp": 1631544966150, "ltp": 1.35, "tv": 10457.89, "trd": [[1.35, 3340.32]], "batb": NaN, "batl": [[0, 1.35, 3191.77]]}, {"timestamp": 1631544988722, "ltp": 1.35, "tv": 10640.24, "trd": [[1.35, 3522.66]], "batb": NaN, "batl": [[0, 1.35, 3100.54]]}, {"timestamp": 1631544991595, "ltp": 1.35, "tv": 10659.98, "trd": [[1.35, 3542.41]], "batb": NaN, "batl": [[0, 1.35, 3090.67]]}, {"timestamp": 1631545008011, "ltp": 1.34, "tv": 10660.18, "trd": [[1.34, 1949.4]], "batb": [[0, 1.34, 108.35]], "batl": NaN}, {"timestamp": 1631545009232, "ltp": 1.34, "tv": 10660.18, "trd": NaN, "batb": [[0, 1.34, 115.77]], "batl": [[1, 1.42, 11.45], [2, 1.43, 2.03]]}, {"timestamp": 1631545025459, "ltp": 1.35, "tv": 10676.74, "trd": [[1.35, 3558.97]], "batb": NaN, "batl": [[0, 1.35, 3074.11]]}, {"timestamp": 1631545034781, "ltp": 1.35, "tv": 10676.74, "trd": NaN, "batb": NaN, "batl": [[0, 1.35, 3076.11]]}, {"timestamp": 1631545052619, "ltp": 1.35, "tv": 10676.74, "trd": NaN, "batb": [[0, 1.34, 7.42], [1, 1.12, 60.22], [2, 1.06, 766.48]], "batl": [[0, 1.35, 3074.11], [1, 1.52, 0.53], [2, 1.43, 0]]}, {"timestamp": 1631545055884, "ltp": 1.35, "tv": 10696.44, "trd": [[1.35, 3578.67]], "batb": [[0, 1.12, 60.22], [1, 1.06, 766.48], [2, 1.01, 578.33]], "batl": [[0, 1.35, 3064.26]]}, {"timestamp": 1631545058012, "ltp": 1.35, "tv": 10815.85, "trd": [[1.35, 3698.08]], "batb": NaN, "batl": [[0, 1.35, 3004.56]]}, {"timestamp": 1631545058899, "ltp": 1.35, "tv": 10815.85, "trd": NaN, "batb": [[0, 1.12, 69.09]], "batl": NaN}, {"timestamp": 1631545060109, "ltp": 1.35, "tv": 10815.85, "trd": NaN, "batb": [[0, 1.13, 196.53], [1, 1.12, 60.22], [2, 1.06, 766.48]], "batl": NaN}, {"timestamp": 1631545060727, "ltp": 1.35, "tv": 10815.85, "trd": NaN, "batb": [[2, 1.07, 364.99]], "batl": NaN}, {"timestamp": 1631545063021, "ltp": 1.35, "tv": 10815.85, "trd": NaN, "batb": [[0, 1.13, 205.33]], "batl": NaN}, {"timestamp": 1631545063909, "ltp": 1.35, "tv": 10972.38, "trd": [[1.35, 3854.6]], "batb": NaN, "batl": [[0, 1.35, 2926.31]]}, {"timestamp": 1631545067242, "ltp": 1.35, "tv": 10972.38, "trd": NaN, "batb": [[0, 1.13, 196.53]], "batl": NaN}, {"timestamp": 1631545070321, "ltp": 1.35, "tv": 10972.38, "trd": NaN, "batb": [[0, 1.18, 8.42], [1, 1.15, 170.33], [2, 1.13, 196.53]], "batl": NaN}, {"timestamp": 1631545078328, "ltp": 1.15, "tv": 11022.36, "trd": [[1.15, 33.14], [1.18, 16.84]], "batb": [[0, 1.15, 153.76], [1, 1.13, 196.53], [2, 1.12, 60.22]], "batl": NaN}, {"timestamp": 1631545080316, "ltp": 1.15, "tv": 11022.36, "trd": NaN, "batb": [[0, 1.19, 134.47], [1, 1.15, 153.76], [2, 1.13, 196.53]], "batl": NaN}, {"timestamp": 1631545081417, "ltp": 1.15, "tv": 11022.36, "trd": NaN, "batb": [[0, 1.15, 153.76], [1, 1.13, 196.53], [2, 1.12, 60.22]], "batl": NaN}, {"timestamp": 1631545086467, "ltp": 1.15, "tv": 11022.36, "trd": NaN, "batb": NaN, "batl": [[0, 1.33, 14.32], [1, 1.35, 2926.31], [2, 1.52, 0.53]]}, {"timestamp": 1631545089557, "ltp": 1.35, "tv": 11192.76, "trd": [[1.33, 33.13], [1.35, 3996.36]], "batb": NaN, "batl": [[0, 1.35, 2855.39], [1, 1.52, 0.53], [2, 1.52, 0]]}, {"timestamp": 1631545090666, "ltp": 1.35, "tv": 11192.76, "trd": NaN, "batb": [[0, 1.16, 609.73], [1, 1.15, 153.76], [2, 1.13, 196.53]], "batl": NaN}, {"timestamp": 1631545096628, "ltp": 1.35, "tv": 11192.76, "trd": NaN, "batb": [[1, 1.13, 196.53], [2, 1.12, 60.22]], "batl": NaN}, {"timestamp": 1631545097659, "ltp": 1.35, "tv": 11192.76, "trd": NaN, "batb": [[0, 1.17, 300.58], [1, 1.16, 609.73], [2, 1.13, 196.53]], "batl": NaN}, {"timestamp": 1631545104478, "ltp": 1.35, "tv": 11192.76, "trd": NaN, "batb": [[1, 1.12, 60.22], [2, 1.07, 364.99]], "batl": NaN}, {"timestamp": 1631545104994, "ltp": 1.35, "tv": 11192.76, "trd": NaN, "batb": [[0, 1.17, 450.87]], "batl": NaN}, {"timestamp": 1631545107587, "ltp": 1.35, "tv": 11192.76, "trd": NaN, "batb": [[0, 1.17, 1055.3]], "batl": NaN}, {"timestamp": 1631545110573, "ltp": 1.35, "tv": 11192.76, "trd": NaN, "batb": [[0, 1.19, 134.47], [1, 1.17, 1055.3], [2, 1.12, 60.22]], "batl": NaN}, {"timestamp": 1631545114682, "ltp": 1.35, "tv": 11192.76, "trd": NaN, "batb": [[0, 1.18, 141.94], [1, 1.17, 604.43]], "batl": NaN}, {"timestamp": 1631545115714, "ltp": 1.35, "tv": 11192.76, "trd": NaN, "batb": [[0, 1.18, 283.89]], "batl": NaN}, {"timestamp": 1631545116622, "ltp": 1.35, "tv": 11192.76, "trd": NaN, "batb": [[0, 1.18, 286.89]], "batl": NaN}, {"timestamp": 1631545129715, "ltp": 1.35, "tv": 11955.85, "trd": [[1.35, 4759.44]], "batb": NaN, "batl": [[0, 1.35, 2473.9]]}, {"timestamp": 1631545129926, "ltp": 1.35, "tv": 11955.85, "trd": NaN, "batb": [[1, 1.12, 60.22], [2, 1.07, 364.99]], "batl": NaN}, {"timestamp": 1631545134238, "ltp": 1.35, "tv": 12003.36, "trd": [[1.35, 4806.96]], "batb": NaN, "batl": [[0, 1.35, 2450.12]]}, {"timestamp": 1631545135222, "ltp": 1.35, "tv": 12049.77, "trd": [[1.35, 4853.36]], "batb": NaN, "batl": [[0, 1.35, 2426.91]]}, {"timestamp": 1631545138603, "ltp": 1.35, "tv": 12049.77, "trd": NaN, "batb": NaN, "batl": [[1, 1.5, 2.13], [2, 1.52, 0.53]]}, {"timestamp": 1631545140530, "ltp": 1.35, "tv": 12049.77, "trd": NaN, "batb": [[0, 1.2, 127.75], [1, 1.18, 286.89], [2, 1.12, 60.22]], "batl": NaN}, {"timestamp": 1631545141314, "ltp": 1.35, "tv": 12049.77, "trd": NaN, "batb": [[1, 1.18, 3]], "batl": NaN}, {"timestamp": 1631545145412, "ltp": 1.35, "tv": 12073.53, "trd": [[1.35, 4877.12]], "batb": [[2, 1.15, 340.66]], "batl": [[0, 1.35, 2415.02]]}, {"timestamp": 1631545157660, "ltp": 1.35, "tv": 12121.04, "trd": [[1.35, 4924.64]], "batb": NaN, "batl": [[0, 1.35, 2391.25]]}, {"timestamp": 1631545158027, "ltp": 1.35, "tv": 12174.11, "trd": [[1.35, 4977.7]], "batb": NaN, "batl": [[0, 1.35, 2364.7]]}, {"timestamp": 1631545159332, "ltp": 1.35, "tv": 12303.15, "trd": [[1.35, 5106.74]], "batb": NaN, "batl": [[0, 1.35, 2300.15]]}, {"timestamp": 1631545160656, "ltp": 1.35, "tv": 12923.16, "trd": [[1.35, 5726.76]], "batb": NaN, "batl": [[0, 1.35, 1990.01]]}, {"timestamp": 1631545161564, "ltp": 1.35, "tv": 13016.16, "trd": [[1.35, 5819.75]], "batb": NaN, "batl": [[0, 1.35, 1943.48]]}, {"timestamp": 1631545162448, "ltp": 1.35, "tv": 13316.0, "trd": [[1.35, 6119.6]], "batb": NaN, "batl": [[0, 1.35, 1793.52]]}, {"timestamp": 1631545163274, "ltp": 1.35, "tv": 13560.88, "trd": [[1.35, 6364.47]], "batb": NaN, "batl": [[0, 1.35, 1671.04]]}, {"timestamp": 1631545163958, "ltp": 1.35, "tv": 13672.38, "trd": [[1.35, 6475.97]], "batb": NaN, "batl": [[0, 1.35, 1615.26]]}, {"timestamp": 1631545165463, "ltp": 1.35, "tv": 14155.26, "trd": [[1.35, 6958.85]], "batb": NaN, "batl": [[0, 1.35, 1373.74]]}, {"timestamp": 1631545166359, "ltp": 1.35, "tv": 14376.74, "trd": [[1.35, 7180.33]], "batb": NaN, "batl": [[0, 1.35, 1262.96]]}, {"timestamp": 1631545167559, "ltp": 1.35, "tv": 14545.59, "trd": [[1.35, 7349.19]], "batb": NaN, "batl": [[0, 1.35, 1178.53]]}, {"timestamp": 1631545167864, "ltp": 1.35, "tv": 14607.87, "trd": [[1.35, 7411.46]], "batb": NaN, "batl": [[0, 1.35, 1147.39]]}, {"timestamp": 1631545170076, "ltp": 1.35, "tv": 14670.14, "trd": [[1.35, 7473.74]], "batb": NaN, "batl": [[0, 1.35, 1116.26]]}, {"timestamp": 1631545171559, "ltp": 1.35, "tv": 14794.69, "trd": [[1.35, 7598.29]], "batb": NaN, "batl": [[0, 1.35, 1053.99]]}, {"timestamp": 1631545172668, "ltp": 1.35, "tv": 14818.45, "trd": [[1.35, 7622.05]], "batb": [[0, 1.25, 97.55], [1, 1.2, 127.75], [2, 1.18, 3]], "batl": [[0, 1.35, 1042.1]]}, {"timestamp": 1631545175672, "ltp": 1.35, "tv": 14846.76, "trd": [[1.35, 7650.35]], "batb": NaN, "batl": [[0, 1.35, 1013.79]]}, {"timestamp": 1631545178177, "ltp": 1.35, "tv": 14846.76, "trd": NaN, "batb": [[0, 1.26, 98.26], [1, 1.25, 97.55], [2, 1.2, 127.75]], "batl": NaN}, {"timestamp": 1631545179683, "ltp": 1.35, "tv": 15026.9, "trd": [[1.35, 7830.5]], "batb": [[2, 1.18, 3]], "batl": [[0, 1.35, 923.68]]}, {"timestamp": 1631545180052, "ltp": 1.35, "tv": 15172.01, "trd": [[1.35, 7975.6]], "batb": NaN, "batl": [[0, 1.35, 851.09]]}, {"timestamp": 1631545181293, "ltp": 1.35, "tv": 15577.6, "trd": [[1.35, 8381.2]], "batb": NaN, "batl": [[0, 1.35, 648.18]]}, {"timestamp": 1631545182490, "ltp": 1.35, "tv": 15865.37, "trd": [[1.35, 8668.96]], "batb": NaN, "batl": [[0, 1.35, 504.23]]}, {"timestamp": 1631545183180, "ltp": 1.35, "tv": 15954.96, "trd": [[1.35, 8758.55]], "batb": NaN, "batl": [[0, 1.35, 459.41]]}, {"timestamp": 1631545184380, "ltp": 1.35, "tv": 16017.23, "trd": [[1.35, 8820.82]], "batb": NaN, "batl": [[0, 1.35, 428.28]]}, {"timestamp": 1631545184907, "ltp": 1.35, "tv": 16079.51, "trd": [[1.35, 8883.1]], "batb": NaN, "batl": [[0, 1.35, 397.14]]}, {"timestamp": 1631545186497, "ltp": 1.35, "tv": 16150.11, "trd": [[1.35, 8953.7]], "batb": NaN, "batl": [[0, 1.35, 361.82]]}, {"timestamp": 1631545187364, "ltp": 1.35, "tv": 16212.43, "trd": [[1.35, 9016.02]], "batb": NaN, "batl": [[0, 1.35, 330.65], [1, 1.52, 0.53], [2, 1.52, 0]]}, {"timestamp": 1631545189392, "ltp": 1.35, "tv": 16212.43, "trd": NaN, "batb": [[1, 1.18, 3], [2, 1.15, 340.66]], "batl": NaN}, {"timestamp": 1631545191892, "ltp": 1.35, "tv": 16212.43, "trd": NaN, "batb": [[0, 1.27, 97.55], [1, 1.26, 98.26], [2, 1.18, 3]], "batl": NaN}, {"timestamp": 1631545196705, "ltp": 1.35, "tv": 16212.43, "trd": NaN, "batb": [[1, 1.18, 3], [2, 1.15, 340.66]], "batl": NaN}, {"timestamp": 1631545197016, "ltp": 1.35, "tv": 16305.92, "trd": [[1.35, 9109.51]], "batb": NaN, "batl": [[0, 1.35, 283.88]]}, {"timestamp": 1631545198321, "ltp": 1.35, "tv": 16443.72, "trd": [[1.35, 9247.31]], "batb": [[0, 1.28, 91.25], [1, 1.27, 97.55], [2, 1.18, 3]], "batl": [[0, 1.35, 214.94]]}, {"timestamp": 1631545198950, "ltp": 1.35, "tv": 16536.72, "trd": [[1.35, 9340.31]], "batb": NaN, "batl": [[0, 1.35, 168.42]]}, {"timestamp": 1631545200566, "ltp": 1.35, "tv": 16629.72, "trd": [[1.35, 9433.31]], "batb": NaN, "batl": [[0, 1.35, 121.89]]}, {"timestamp": 1631545205464, "ltp": 1.35, "tv": 16815.41, "trd": [[1.15, 33.16], [1.32, 27.06], [1.33, 33.16], [1.34, 1951.08], [1.35, 9612.93], [1.36, 114.38], [1.37, 419.16], [1.38, 109.52], [1.39, 3520.59], [1.4, 727.39], [1.41, 60.84], [1.42, 189.29]], "batb": [[0, 1.28, 91.35], [1, 1.27, 97.44]], "batl": [[0, 1.35, 32.97]]}, {"timestamp": 1631545208632, "ltp": 1.35, "tv": 16881.36, "trd": [[1.35, 9678.88]], "batb": [[0, 1.35, 1.33], [1, 1.28, 91.35]], "batl": [[0, 1.52, 0.53], [1, 1.52, 0]]}, {"timestamp": 1631545209267, "ltp": 1.35, "tv": 16881.36, "trd": NaN, "batb": [[0, 1.35, 71.03]], "batl": NaN}, {"timestamp": 1631545210540, "ltp": 1.35, "tv": 16881.36, "trd": NaN, "batb": [[0, 1.35, 41.8]], "batl": NaN}, {"timestamp": 1631545210958, "ltp": 1.35, "tv": 16881.36, "trd": NaN, "batb": [[0, 1.35, 40.46], [1, 1.29, 97.44], [2, 1.28, 91.35]], "batl": NaN}, {"timestamp": 1631545213733, "ltp": 1.35, "tv": 16881.36, "trd": NaN, "batb": [[0, 1.29, 97.44], [1, 1.28, 91.35], [2, 1.18, 3]], "batl": NaN}, {"timestamp": 1631545215458, "ltp": 1.35, "tv": 16881.36, "trd": NaN, "batb": [[1, 1.18, 3], [2, 1.15, 341.06]], "batl": NaN}, {"timestamp": 1631545219768, "ltp": 1.35, "tv": 16881.36, "trd": NaN, "batb": [[0, 1.18, 3], [1, 1.15, 341.06], [2, 1.12, 60.16]], "batl": NaN}, {"timestamp": 1631545221955, "ltp": 1.35, "tv": 16881.36, "trd": NaN, "batb": [[0, 1.2, 127.9], [1, 1.18, 3], [2, 1.15, 341.06]], "batl": NaN}, {"timestamp": 1631545246967, "ltp": 1.35, "tv": 16881.36, "trd": NaN, "batb": [[0, 1.3, 283.94], [1, 1.2, 127.9], [2, 1.18, 3]], "batl": NaN}, {"timestamp": 1631545373623, "ltp": 1.35, "tv": 16881.36, "trd": NaN, "batb": [[2, 1.15, 341.06]], "batl": NaN}, {"timestamp": 1631545376691, "ltp": 1.35, "tv": 16881.36, "trd": NaN, "batb": [[0, 1.35, 3], [1, 1.3, 283.94], [2, 1.2, 127.9]], "batl": NaN}, {"timestamp": 1631545411442, "ltp": 1.35, "tv": 16881.36, "trd": NaN, "batb": NaN, "batl": [[0, 1000, 0.6]]}, {"timestamp": 1631545411756, "ltp": 1.35, "tv": 16881.36, "trd": NaN, "batb": NaN, "batl": [[0, 1.52, 0.53]]}, {"timestamp": 1631545415672, "ltp": 1.35, "tv": 16881.36, "trd": NaN, "batb": NaN, "batl": [[0, 810, 0.6]]}, {"timestamp": 1631545432805, "ltp": 1.35, "tv": 16881.36, "trd": NaN, "batb": NaN, "batl": [[0, 820, 0.67]]}, {"timestamp": 1631545435682, "ltp": 1.35, "tv": 16881.36, "trd": NaN, "batb": NaN, "batl": [[0, 1.94, 524.36], [1, 820, 0.14]]}, {"timestamp": 1631545435888, "ltp": 1.35, "tv": 16881.36, "trd": NaN, "batb": NaN, "batl": [[0, 820, 0.67], [1, 820, 0]]}, {"timestamp": 1631545439017, "ltp": 1.35, "tv": 16881.36, "trd": NaN, "batb": NaN, "batl": [[0, 2.26, 450.85], [1, 820, 0.14]]}, {"timestamp": 1631545449399, "ltp": 1.35, "tv": 16881.36, "trd": NaN, "batb": NaN, "batl": [[0, 1.94, 3.61]]}, {"timestamp": 1631545452523, "ltp": 1.35, "tv": 16881.36, "trd": NaN, "batb": NaN, "batl": [[0, 1.86, 546.64], [1, 1.94, 3.08], [2, 820, 0.14]]}, {"timestamp": 1631545459639, "ltp": 1.35, "tv": 16881.36, "trd": NaN, "batb": [[2, 1.15, 341.06]], "batl": NaN}, {"timestamp": 1631545461620, "ltp": 1.35, "tv": 16881.36, "trd": NaN, "batb": NaN, "batl": [[0, 1.84, 870.24], [1, 1.86, 546.11], [2, 1.94, 3.08]]}, {"timestamp": 1631545471358, "ltp": 1.35, "tv": 16881.36, "trd": NaN, "batb": [[2, 1.17, 726.47]], "batl": [[1, 1.94, 3.08], [2, 820, 0.14]]}, {"timestamp": 1631545474538, "ltp": 1.35, "tv": 16881.36, "trd": NaN, "batb": NaN, "batl": [[0, 1.83, 555.5], [1, 1.84, 869.71], [2, 1.94, 3.08]]}, {"timestamp": 1631545495390, "ltp": 1.35, "tv": 16881.36, "trd": NaN, "batb": NaN, "batl": [[1, 1.94, 3.08], [2, 820, 0.14]]}, {"timestamp": 1631545496067, "ltp": 1.35, "tv": 16881.36, "trd": NaN, "batb": NaN, "batl": [[0, 1.94, 3.61], [1, 820, 0.14], [2, 820, 0]]}, {"timestamp": 1631545498494, "ltp": 1.35, "tv": 16881.36, "trd": NaN, "batb": NaN, "batl": [[0, 1.82, 870.24], [1, 1.94, 3.08], [2, 820, 0.14]]}, {"timestamp": 1631545504002, "ltp": 1.35, "tv": 16881.36, "trd": NaN, "batb": [[1, 1.17, 726.47], [2, 1.15, 341.06]], "batl": NaN}, {"timestamp": 1631545521308, "ltp": 1.35, "tv": 16887.36, "trd": [[1.35, 9684.88]], "batb": [[0, 1.17, 726.47], [1, 1.15, 341.06], [2, 1.07, 365.42]], "batl": [[0, 1.35, 2], [1, 1.82, 870.24], [2, 1.94, 3.08]]}, {"timestamp": 1631545532344, "ltp": 1.35, "tv": 16887.36, "trd": NaN, "batb": [[0, 1.18, 142.11], [1, 1.17, 726.47]], "batl": NaN}, {"timestamp": 1631545541224, "ltp": 1.35, "tv": 16887.36, "trd": NaN, "batb": [[0, 1.19, 179.91], [1, 1.18, 142.11], [2, 1.17, 726.47]], "batl": NaN}, {"timestamp": 1631545550261, "ltp": 1.35, "tv": 16887.36, "trd": NaN, "batb": [[0, 1.2, 127.9], [1, 1.19, 179.91]], "batl": NaN}, {"timestamp": 1631545559967, "ltp": 1.35, "tv": 16887.36, "trd": NaN, "batb": [[1, 1.17, 726.47], [2, 1.07, 365.42]], "batl": NaN}, {"timestamp": 1631545562636, "ltp": 1.35, "tv": 16887.36, "trd": NaN, "batb": [[0, 1.21, 29], [1, 1.2, 127.9], [2, 1.17, 726.47]], "batl": NaN}, {"timestamp": 1631545563054, "ltp": 1.35, "tv": 16887.36, "trd": NaN, "batb": [[0, 1.21, 208.91]], "batl": NaN}, {"timestamp": 1631545569260, "ltp": 1.35, "tv": 16887.36, "trd": NaN, "batb": [[0, 1.22, 116.27], [1, 1.21, 208.91]], "batl": NaN}, {"timestamp": 1631545569776, "ltp": 1.35, "tv": 16887.36, "trd": NaN, "batb": [[1, 1.21, 179.91]], "batl": NaN}, {"timestamp": 1631545572844, "ltp": 1.35, "tv": 16887.36, "trd": NaN, "batb": [[0, 1.22, 145.27]], "batl": NaN}, {"timestamp": 1631545577866, "ltp": 1.35, "tv": 16887.36, "trd": NaN, "batb": [[0, 1.22, 116.27]], "batl": NaN}, {"timestamp": 1631545581081, "ltp": 1.35, "tv": 16887.36, "trd": NaN, "batb": [[0, 1.25, 29], [1, 1.22, 116.27], [2, 1.21, 179.91]], "batl": NaN}, {"timestamp": 1631545589364, "ltp": 1.35, "tv": 16887.36, "trd": NaN, "batb": [[0, 1.26, 32.79], [1, 1.25, 29], [2, 1.22, 116.27]], "batl": NaN}, {"timestamp": 1631545590606, "ltp": 1.35, "tv": 16887.36, "trd": NaN, "batb": [[0, 1.26, 182.86]], "batl": NaN}, {"timestamp": 1631545594876, "ltp": 1.35, "tv": 16887.36, "trd": NaN, "batb": [[0, 1.27, 150.07], [1, 1.26, 182.86], [2, 1.25, 29]], "batl": NaN}, {"timestamp": 1631545599821, "ltp": 1.35, "tv": 16887.36, "trd": NaN, "batb": [[1, 1.26, 150.07]], "batl": NaN}, {"timestamp": 1631545609103, "ltp": 1.35, "tv": 16887.36, "trd": NaN, "batb": [[0, 1.3, 283.94], [1, 1.27, 150.07], [2, 1.26, 150.07]], "batl": NaN}, {"timestamp": 1631545615553, "ltp": 1.35, "tv": 16887.36, "trd": NaN, "batb": [[0, 1.31, 150.07], [1, 1.3, 283.94], [2, 1.25, 29]], "batl": NaN}, {"timestamp": 1631545622714, "ltp": 1.35, "tv": 16887.36, "trd": NaN, "batb": [[2, 1.22, 116.27]], "batl": NaN}, {"timestamp": 1631545625524, "ltp": 1.35, "tv": 16887.36, "trd": NaN, "batb": [[1, 1.22, 116.27], [2, 1.15, 726.47]], "batl": NaN}, {"timestamp": 1631545625939, "ltp": 1.35, "tv": 16887.36, "trd": NaN, "batb": [[0, 1.32, 29], [1, 1.31, 150.07], [2, 1.22, 116.27]], "batl": NaN}, {"timestamp": 1631545628638, "ltp": 1.35, "tv": 16887.36, "trd": NaN, "batb": [[0, 1.32, 312.93]], "batl": NaN}, {"timestamp": 1631545632164, "ltp": 1.35, "tv": 16887.36, "trd": NaN, "batb": [[2, 1.15, 726.47]], "batl": NaN}, {"timestamp": 1631545640673, "ltp": 1.35, "tv": 16891.36, "trd": [[1.35, 9688.88]], "batb": [[0, 1.35, 54.27], [1, 1.32, 312.93], [2, 1.31, 150.07]], "batl": [[0, 1.82, 870.24], [1, 1.94, 3.08], [2, 820, 0.14]]}, {"timestamp": 1631545641661, "ltp": 1.35, "tv": 16891.36, "trd": NaN, "batb": [[1, 1.33, 56.28], [2, 1.32, 312.93]], "batl": NaN}, {"timestamp": 1631545641969, "ltp": 1.52, "tv": 16891.89, "trd": [[1.52, 0.53]], "batb": NaN, "batl": [[0, 1.82, 869.71]]}, {"timestamp": 1631545648641, "ltp": 1.52, "tv": 16891.89, "trd": NaN, "batb": NaN, "batl": [[0, 1.52, 56.28], [1, 1.82, 869.71], [2, 1.94, 3.08]]}, {"timestamp": 1631545657788, "ltp": 1.52, "tv": 16891.89, "trd": NaN, "batb": [[2, 1.32, 283.94]], "batl": NaN}, {"timestamp": 1631545692391, "ltp": 1.52, "tv": 16891.89, "trd": NaN, "batb": [[0, 1.4, 34.62], [1, 1.35, 54.27], [2, 1.33, 56.28]], "batl": NaN}, {"timestamp": 1631545854018, "ltp": 1.4, "tv": 16960.1, "trd": [[1.4, 795.61]], "batb": [[0, 1.35, 54.78], [1, 1.33, 56.28], [2, 1.31, 150.07]], "batl": NaN}, {"timestamp": 1631545859489, "ltp": 1.4, "tv": 16960.1, "trd": NaN, "batb": [[0, 1.15, 1084.9], [1, 1.12, 767.39], [2, 1.11, 271.16]], "batl": [[0, 1.82, 869.71], [1, 1.94, 3.08], [2, 1.94, 0]]}, {"timestamp": 1631545877033, "ltp": 1.4, "tv": 16960.1, "trd": NaN, "batb": [[0, 1.16, 107.09], [1, 1.15, 1084.39], [2, 1.12, 767.39]], "batl": NaN}, {"timestamp": 1631545880724, "ltp": 1.4, "tv": 16960.1, "trd": NaN, "batb": [[0, 1.17, 87.51], [1, 1.16, 106.58], [2, 1.15, 1084.39]], "batl": NaN}, {"timestamp": 1631545893842, "ltp": 1.4, "tv": 16960.1, "trd": NaN, "batb": [[1, 1.15, 1084.39], [2, 1.12, 767.39]], "batl": NaN}, {"timestamp": 1631545896920, "ltp": 1.4, "tv": 16960.1, "trd": NaN, "batb": [[0, 1.18, 107.09], [1, 1.17, 87], [2, 1.15, 1084.39]], "batl": NaN}, {"timestamp": 1631545904758, "ltp": 1.4, "tv": 16960.1, "trd": NaN, "batb": [[1, 1.15, 1084.39], [2, 1.12, 767.39]], "batl": NaN}, {"timestamp": 1631545907930, "ltp": 1.4, "tv": 16960.1, "trd": NaN, "batb": [[0, 1.2, 87.51], [1, 1.18, 106.58], [2, 1.15, 1084.39]], "batl": NaN}, {"timestamp": 1631545909547, "ltp": 1.4, "tv": 16960.1, "trd": NaN, "batb": [[0, 1.44, 11.74], [1, 1.2, 87.51], [2, 1.18, 106.58]], "batl": [[0, 1.46, 13.78], [1, 1.82, 869.71], [2, 1.94, 3.08]]}, {"timestamp": 1631545911055, "ltp": 1.4, "tv": 16960.1, "trd": NaN, "batb": [[2, 1.15, 1084.39]], "batl": NaN}, {"timestamp": 1631545913237, "ltp": 1.46, "tv": 16987.38, "trd": [[1.46, 27.28]], "batb": NaN, "batl": [[0, 1.82, 869.85], [1, 1.94, 3.08], [2, 1.94, 0]]}, {"timestamp": 1631545914172, "ltp": 1.46, "tv": 16987.38, "trd": NaN, "batb": [[1, 1.21, 107.09], [2, 1.2, 87]], "batl": NaN}, {"timestamp": 1631545919550, "ltp": 1.46, "tv": 16987.38, "trd": NaN, "batb": NaN, "batl": [[0, 1.81, 394.11], [1, 1.82, 869.71], [2, 1.94, 3.08]]}, {"timestamp": 1631545919753, "ltp": 1.46, "tv": 16987.38, "trd": NaN, "batb": NaN, "batl": [[0, 1.82, 869.85], [1, 1.94, 3.08], [2, 1.94, 0]]}, {"timestamp": 1631545923484, "ltp": 1.46, "tv": 16987.38, "trd": NaN, "batb": [[0, 1.21, 107.09], [1, 1.2, 87], [2, 1.15, 1084.39]], "batl": [[0, 1.82, 869.71]]}, {"timestamp": 1631545925579, "ltp": 1.46, "tv": 16987.38, "trd": NaN, "batb": NaN, "batl": [[0, 1.44, 1.88], [1, 1.82, 869.71], [2, 1.94, 3.08]]}, {"timestamp": 1631545926358, "ltp": 1.44, "tv": 16991.14, "trd": [[1.44, 3.76]], "batb": [[0, 1.45, 10.56], [1, 1.21, 107.09], [2, 1.2, 87]], "batl": [[0, 1.47, 12.18]]}, {"timestamp": 1631545927449, "ltp": 1.44, "tv": 16991.14, "trd": NaN, "batb": [[0, 1.21, 107.09], [1, 1.2, 87], [2, 1.15, 1084.39]], "batl": [[0, 1.48, 56.28]]}, {"timestamp": 1631545930681, "ltp": 1.48, "tv": 17015.01, "trd": [[1.48, 23.87]], "batb": NaN, "batl": [[0, 1.48, 44.34]]}, {"timestamp": 1631545949487, "ltp": 1.48, "tv": 17015.01, "trd": NaN, "batb": NaN, "batl": [[1, 1.55, 56.28], [2, 1.82, 869.71]]}, {"timestamp": 1631545950522, "ltp": 1.48, "tv": 17015.01, "trd": NaN, "batb": NaN, "batl": [[2, 1.67, 56.28]]}, {"timestamp": 1631545951214, "ltp": 1.48, "tv": 17015.01, "trd": NaN, "batb": NaN, "batl": [[2, 1.67, 112.55]]}, {"timestamp": 1631545952626, "ltp": 1.48, "tv": 17015.01, "trd": NaN, "batb": NaN, "batl": [[2, 1.67, 168.83]]}, {"timestamp": 1631545956330, "ltp": 1.48, "tv": 17015.01, "trd": NaN, "batb": [[0, 1.22, 709.92], [1, 1.21, 106.58], [2, 1.2, 87]], "batl": NaN}, {"timestamp": 1631545960536, "ltp": 1.48, "tv": 17015.01, "trd": NaN, "batb": [[0, 1.4, 12.67], [1, 1.38, 560.99], [2, 1.22, 709.41]], "batl": NaN}, {"timestamp": 1631545961217, "ltp": 1.38, "tv": 17165.06, "trd": [[1.38, 222.08], [1.4, 833.1]], "batb": [[0, 1.38, 504.71], [1, 1.22, 709.41], [2, 1.21, 106.58]], "batl": [[0, 1.39, 31.45], [1, 1.41, 56.28], [2, 1.48, 44.34]]}, {"timestamp": 1631545964645, "ltp": 1.39, "tv": 17226.45, "trd": [[1.39, 3581.98]], "batb": NaN, "batl": [[0, 1.41, 57.03], [1, 1.48, 44.34], [2, 1.55, 56.28]]}, {"timestamp": 1631545964813, "ltp": 1.39, "tv": 17226.45, "trd": NaN, "batb": [[1, 1.23, 87], [2, 1.22, 709.41]], "batl": NaN}, {"timestamp": 1631545967635, "ltp": 1.39, "tv": 17226.45, "trd": NaN, "batb": NaN, "batl": [[1, 1.48, 96.33], [2, 1.51, 51.5]]}, {"timestamp": 1631545974551, "ltp": 1.39, "tv": 17227.21, "trd": [[1.39, 3582.74]], "batb": NaN, "batl": [[0, 1.41, 70.94]]}, {"timestamp": 1631545977161, "ltp": 1.41, "tv": 17288.6, "trd": [[1.41, 122.23]], "batb": NaN, "batl": [[0, 1.41, 40.24]]}, {"timestamp": 1631545982645, "ltp": 1.41, "tv": 17288.6, "trd": NaN, "batb": [[0, 1.23, 87], [1, 1.22, 709.41], [2, 1.15, 1084.39]], "batl": [[0, 1.41, 25.58]]}, {"timestamp": 1631545983216, "ltp": 1.41, "tv": 17288.6, "trd": NaN, "batb": [[1, 1.15, 1084.39], [2, 1.12, 767.39]], "batl": NaN}, {"timestamp": 1631545985649, "ltp": 1.41, "tv": 17288.6, "trd": NaN, "batb": [[0, 1.37, 65.77], [1, 1.23, 87], [2, 1.15, 1084.39]], "batl": NaN}, {"timestamp": 1631545986339, "ltp": 1.41, "tv": 17288.6, "trd": NaN, "batb": [[1, 1.24, 709.41], [2, 1.23, 87]], "batl": NaN}, {"timestamp": 1631546003076, "ltp": 1.35, "tv": 17517.93, "trd": [[1.35, 9745.15], [1.36, 155.89], [1.37, 550.7]], "batb": [[0, 1.24, 709.41], [1, 1.23, 87], [2, 1.15, 1084.39]], "batl": [[0, 1.36, 21.97], [1, 1.38, 16.53], [2, 1.4, 223.36]]}, {"timestamp": 1631546009546, "ltp": 1.35, "tv": 17517.93, "trd": NaN, "batb": [[0, 1.35, 76.27], [1, 1.34, 85.22], [2, 1.24, 709.41]], "batl": NaN}, {"timestamp": 1631546010128, "ltp": 1.35, "tv": 17517.93, "trd": NaN, "batb": [[2, 1.3, 320.69]], "batl": NaN}, {"timestamp": 1631546013222, "ltp": 1.35, "tv": 17517.93, "trd": NaN, "batb": NaN, "batl": [[1, 1.4, 223.36], [2, 1.41, 25.58]]}, {"timestamp": 1631546016528, "ltp": 1.35, "tv": 17517.93, "trd": NaN, "batb": NaN, "batl": [[1, 1.41, 25.58], [2, 1.42, 53.75]]}, {"timestamp": 1631546016843, "ltp": 1.35, "tv": 17517.93, "trd": NaN, "batb": [[0, 1.34, 85.22], [1, 1.3, 320.69], [2, 1.26, 112.55]], "batl": [[2, 1.44, 57.08]]}, {"timestamp": 1631546023551, "ltp": 1.35, "tv": 17517.93, "trd": NaN, "batb": [[0, 1.35, 71.07], [1, 1.34, 85.22], [2, 1.3, 320.69]], "batl": [[2, 1.42, 61.75]]}, {"timestamp": 1631546023759, "ltp": 1.35, "tv": 17517.93, "trd": NaN, "batb": [[0, 1.34, 85.22], [1, 1.3, 320.69], [2, 1.26, 112.55]], "batl": [[2, 1.44, 57.08]]}, {"timestamp": 1631546030632, "ltp": 1.35, "tv": 17517.93, "trd": NaN, "batb": [[0, 1.35, 82.27], [1, 1.34, 85.22], [2, 1.3, 320.69]], "batl": [[2, 1.42, 54.25]]}, {"timestamp": 1631546031448, "ltp": 1.35, "tv": 17517.93, "trd": NaN, "batb": [[0, 1.34, 85.22], [1, 1.3, 320.69], [2, 1.26, 112.55]], "batl": [[0, 1.44, 57.08], [1, 1.48, 44.34], [2, 1.55, 56.28]]}, {"timestamp": 1631546034238, "ltp": 1.35, "tv": 17517.93, "trd": NaN, "batb": [[0, 1.39, 12.08], [1, 1.38, 189.29], [2, 1.37, 189.29]], "batl": [[0, 1.41, 18.23], [1, 1.44, 479.84], [2, 1.48, 44.34]]}, {"timestamp": 1631546040508, "ltp": 1.35, "tv": 17517.93, "trd": NaN, "batb": NaN, "batl": [[2, 1.46, 55.75]]}, {"timestamp": 1631546046510, "ltp": 1.35, "tv": 17517.93, "trd": NaN, "batb": [[0, 1.38, 189.29], [1, 1.37, 189.29], [2, 1.36, 258.72]], "batl": [[0, 1.44, 57.08], [1, 1.46, 55.75], [2, 1.48, 44.34]]}, {"timestamp": 1631546046782, "ltp": 1.35, "tv": 17517.93, "trd": NaN, "batb": NaN, "batl": [[0, 1.46, 55.75], [1, 1.48, 44.34], [2, 1.55, 56.28]]}, {"timestamp": 1631546053709, "ltp": 1.35, "tv": 17517.93, "trd": NaN, "batb": NaN, "batl": [[0, 1.42, 20.25], [1, 1.44, 55.58], [2, 1.46, 55.75]]}, {"timestamp": 1631546053921, "ltp": 1.35, "tv": 17517.93, "trd": NaN, "batb": NaN, "batl": [[0, 1.46, 55.75], [1, 1.48, 44.34], [2, 1.55, 56.28]]}, {"timestamp": 1631546064629, "ltp": 1.35, "tv": 17517.93, "trd": NaN, "batb": NaN, "batl": [[0, 1.44, 60.33], [1, 1.46, 55.75], [2, 1.48, 44.34]]}, {"timestamp": 1631546064845, "ltp": 1.35, "tv": 17517.93, "trd": NaN, "batb": NaN, "batl": [[0, 1.46, 55.75], [1, 1.48, 44.34], [2, 1.55, 56.28]]}, {"timestamp": 1631546070448, "ltp": 1.35, "tv": 17517.93, "trd": NaN, "batb": NaN, "batl": [[0, 1.48, 44.34], [1, 1.55, 56.28], [2, 1.67, 168.83]]}, {"timestamp": 1631546071541, "ltp": 1.35, "tv": 17517.93, "trd": NaN, "batb": [[0, 1.36, 69.43], [1, 1.3, 320.69], [2, 1.26, 112.55]], "batl": [[0, 1.44, 54.83], [1, 1.48, 44.34], [2, 1.55, 56.28]]}, {"timestamp": 1631546071749, "ltp": 1.35, "tv": 17517.93, "trd": NaN, "batb": NaN, "batl": [[0, 1.48, 44.34], [1, 1.55, 56.28], [2, 1.67, 168.83]]}, {"timestamp": 1631546073420, "ltp": 1.35, "tv": 17517.93, "trd": NaN, "batb": [[1, 1.26, 112.55], [2, 1.23, 87]], "batl": [[0, 1.37, 56.28], [1, 1.38, 79.64], [2, 1.39, 38.5]]}, {"timestamp": 1631546075149, "ltp": 1.35, "tv": 17517.93, "trd": NaN, "batb": NaN, "batl": [[0, 1.38, 79.64], [1, 1.39, 38.5], [2, 1.4, 28.58]]}, {"timestamp": 1631546117019, "ltp": 1.38, "tv": 17521.77, "trd": [[1.38, 225.92]], "batb": NaN, "batl": [[0, 1.38, 77.72]]}, {"timestamp": 1631546127109, "ltp": 1.38, "tv": 17521.77, "trd": NaN, "batb": NaN, "batl": [[0, 1.38, 56.28]]}, {"timestamp": 1631546130133, "ltp": 1.38, "tv": 17521.77, "trd": NaN, "batb": [[0, 1.36, 81.39]], "batl": [[0, 1.38, 77.72]]}, {"timestamp": 1631546133635, "ltp": 1.38, "tv": 17521.77, "trd": NaN, "batb": [[1, 1.32, 86.64], [2, 1.3, 81.98]], "batl": [[2, 1.4, 89.27]]}, {"timestamp": 1631546136124, "ltp": 1.38, "tv": 17521.77, "trd": NaN, "batb": [[0, 1.3, 81.98], [1, 1.26, 112.55], [2, 1.23, 87]], "batl": [[0, 1.38, 56.28], [1, 1.41, 171.05], [2, 1.48, 44.34]]}, {"timestamp": 1631546141250, "ltp": 1.38, "tv": 17521.77, "trd": NaN, "batb": NaN, "batl": [[0, 1.41, 171.05], [1, 1.48, 44.34], [2, 1.55, 56.28]]}, {"timestamp": 1631546142655, "ltp": 1.38, "tv": 17521.77, "trd": NaN, "batb": NaN, "batl": [[0, 1.4, 64.24], [1, 1.41, 58.5], [2, 1.48, 44.34]]}, {"timestamp": 1631546143650, "ltp": 1.38, "tv": 17521.77, "trd": NaN, "batb": NaN, "batl": [[0, 1.41, 58.5], [1, 1.48, 44.34], [2, 1.55, 56.28]]}, {"timestamp": 1631546145555, "ltp": 1.38, "tv": 17521.77, "trd": NaN, "batb": [[2, 1.25, 512.59]], "batl": NaN}, {"timestamp": 1631546146260, "ltp": 1.38, "tv": 17521.77, "trd": NaN, "batb": [[0, 1.38, 302.1], [1, 1.3, 81.98], [2, 1.26, 112.55]], "batl": NaN}, {"timestamp": 1631546149670, "ltp": 1.42, "tv": 17667.27, "trd": [[1.41, 239.23], [1.42, 217.79]], "batb": [[0, 1.42, 206.59], [1, 1.38, 302.1], [2, 1.3, 81.98]], "batl": [[0, 1.48, 44.34], [1, 1.55, 56.28], [2, 1.67, 168.83]]}, {"timestamp": 1631546150260, "ltp": 1.42, "tv": 17781.76, "trd": [[1.42, 332.29]], "batb": [[0, 1.38, 302.1], [1, 1.36, 75.43], [2, 1.34, 71.72]], "batl": [[0, 1.43, 57.5], [1, 1.48, 44.34], [2, 1.55, 56.28]]}, {"timestamp": 1631546153452, "ltp": 1.42, "tv": 17781.76, "trd": NaN, "batb": NaN, "batl": [[1, 1.46, 61.25], [2, 1.47, 53.5]]}, {"timestamp": 1631546154248, "ltp": 1.42, "tv": 17781.76, "trd": NaN, "batb": NaN, "batl": [[1, 1.44, 49.33], [2, 1.46, 61.25]]}, {"timestamp": 1631546155153, "ltp": 1.42, "tv": 17781.76, "trd": NaN, "batb": NaN, "batl": [[0, 1.43, 113.78]]}, {"timestamp": 1631546159614, "ltp": 1.42, "tv": 17781.76, "trd": NaN, "batb": NaN, "batl": [[0, 1.43, 56.28], [1, 1.48, 44.34], [2, 1.52, 112.55]]}, {"timestamp": 1631546163122, "ltp": 1.42, "tv": 17781.76, "trd": NaN, "batb": NaN, "batl": [[1, 1.44, 63.08], [2, 1.48, 44.34]]}, {"timestamp": 1631546169404, "ltp": 1.42, "tv": 17781.76, "trd": NaN, "batb": [[0, 1.34, 71.72], [1, 1.26, 112.55], [2, 1.15, 357.92]], "batl": [[1, 1.48, 44.34], [2, 1.52, 112.55]]}, {"timestamp": 1631546171225, "ltp": 1.42, "tv": 17781.76, "trd": NaN, "batb": [[0, 1.34, 621.65]], "batl": [[0, 1.38, 24.7], [1, 1.43, 1577.33], [2, 1.48, 44.34]]}, {"timestamp": 1631546175896, "ltp": 1.42, "tv": 17781.76, "trd": NaN, "batb": NaN, "batl": [[1, 1.4, 56.28], [2, 1.43, 1577.33]]}, {"timestamp": 1631546179196, "ltp": 1.42, "tv": 17781.76, "trd": NaN, "batb": [[1, 1.31, 82.79], [2, 1.29, 91.81]], "batl": [[0, 1.38, 97.7], [1, 1.4, 123.47], [2, 1.42, 57.25]]}, {"timestamp": 1631546191333, "ltp": 1.42, "tv": 17781.76, "trd": NaN, "batb": [[0, 1.29, 91.81], [1, 1.26, 112.55], [2, 1.15, 357.92]], "batl": [[0, 1.4, 56.28], [1, 1.43, 56.28], [2, 1.48, 44.34]]}, {"timestamp": 1631546194532, "ltp": 1.42, "tv": 17781.76, "trd": NaN, "batb": [[0, 1.31, 81.79], [1, 1.29, 91.81], [2, 1.26, 112.55]], "batl": [[1, 1.42, 64.75], [2, 1.43, 56.28]]}, {"timestamp": 1631546194752, "ltp": 1.42, "tv": 17781.76, "trd": NaN, "batb": [[0, 1.29, 91.81], [1, 1.26, 112.55], [2, 1.15, 357.92]], "batl": NaN}, {"timestamp": 1631546201443, "ltp": 1.42, "tv": 17781.76, "trd": NaN, "batb": [[0, 1.31, 81.79], [1, 1.29, 91.81], [2, 1.26, 112.55]], "batl": NaN}, {"timestamp": 1631546201759, "ltp": 1.42, "tv": 17781.76, "trd": NaN, "batb": [[0, 1.29, 91.81], [1, 1.26, 112.55], [2, 1.15, 357.92]], "batl": NaN}, {"timestamp": 1631546207065, "ltp": 1.4, "tv": 17781.81, "trd": [[1.4, 833.15]], "batb": NaN, "batl": [[0, 1.4, 56.22]]}, {"timestamp": 1631546208530, "ltp": 1.4, "tv": 17781.81, "trd": NaN, "batb": [[0, 1.31, 82.79], [1, 1.29, 91.81], [2, 1.26, 112.55]], "batl": NaN}, {"timestamp": 1631546208748, "ltp": 1.4, "tv": 17781.81, "trd": NaN, "batb": [[0, 1.29, 91.81], [1, 1.26, 112.55], [2, 1.15, 357.92]], "batl": NaN}, {"timestamp": 1631546213481, "ltp": 1.4, "tv": 17781.81, "trd": NaN, "batb": NaN, "batl": [[0, 1.42, 64.75], [1, 1.43, 56.28], [2, 1.48, 44.34]]}, {"timestamp": 1631546215486, "ltp": 1.4, "tv": 17781.81, "trd": NaN, "batb": NaN, "batl": [[1, 1.48, 44.34], [2, 1.52, 112.55]]}, {"timestamp": 1631546216324, "ltp": 1.4, "tv": 17781.81, "trd": NaN, "batb": [[0, 1.39, 112.55], [1, 1.38, 661.82], [2, 1.37, 112.55]], "batl": NaN}, {"timestamp": 1631546224035, "ltp": 1.4, "tv": 17781.81, "trd": NaN, "batb": NaN, "batl": [[1, 1.43, 57.5], [2, 1.44, 63.08]]}, {"timestamp": 1631546227245, "ltp": 1.4, "tv": 17781.81, "trd": NaN, "batb": NaN, "batl": [[0, 1.42, 117.75]]}, {"timestamp": 1631546234428, "ltp": 1.4, "tv": 17781.81, "trd": NaN, "batb": [[1, 1.38, 140.51]], "batl": NaN}, {"timestamp": 1631546235328, "ltp": 1.4, "tv": 17781.81, "trd": NaN, "batb": [[1, 1.38, 112.55]], "batl": [[0, 1.48, 44.34], [1, 1.52, 112.55], [2, 1.55, 56.28]]}, {"timestamp": 1631546238224, "ltp": 1.4, "tv": 17781.81, "trd": NaN, "batb": NaN, "batl": [[0, 1.44, 52.33], [1, 1.48, 44.34], [2, 1.52, 112.55]]}, {"timestamp": 1631546241620, "ltp": 1.43, "tv": 17803.15, "trd": [[1.43, 21.34]], "batb": [[0, 1.41, 169.12], [1, 1.4, 493.69], [2, 1.39, 112.55]], "batl": [[0, 1.43, 42.83], [1, 1.44, 52.33], [2, 1.46, 14.93]]}, {"timestamp": 1631546241724, "ltp": 1.43, "tv": 17803.15, "trd": NaN, "batb": [[0, 1.42, 112.55], [1, 1.41, 168.19], [2, 1.4, 493.69]], "batl": [[0, 1.44, 52.33], [1, 1.48, 44.34], [2, 1.52, 112.55]]}, {"timestamp": 1631546244643, "ltp": 1.44, "tv": 17824.35, "trd": [[1.44, 24.96]], "batb": NaN, "batl": [[0, 1.44, 41.73], [1, 1.46, 14.93], [2, 1.48, 44.34]]}, {"timestamp": 1631546249345, "ltp": 1.44, "tv": 17824.35, "trd": NaN, "batb": [[2, 1.4, 553.65]], "batl": [[1, 1.45, 53.5], [2, 1.46, 14.93]]}, {"timestamp": 1631546251761, "ltp": 1.44, "tv": 17824.35, "trd": NaN, "batb": NaN, "batl": [[2, 1.48, 44.34]]}, {"timestamp": 1631546254645, "ltp": 1.44, "tv": 17824.35, "trd": NaN, "batb": [[0, 1.42, 129.61]], "batl": [[0, 1.44, 52.33]]}, {"timestamp": 1631546254853, "ltp": 1.44, "tv": 17824.35, "trd": NaN, "batb": [[0, 1.42, 112.55]], "batl": [[0, 1.44, 41.73]]}, {"timestamp": 1631546257738, "ltp": 1.44, "tv": 17824.35, "trd": NaN, "batb": [[0, 1.42, 129.61]], "batl": [[0, 1.44, 52.33]]}, {"timestamp": 1631546260165, "ltp": 1.44, "tv": 17824.35, "trd": NaN, "batb": [[0, 1.42, 112.55], [1, 1.41, 112.55], [2, 1.4, 59.96]], "batl": [[0, 1.48, 44.34], [1, 1.52, 112.55], [2, 1.55, 56.28]]}, {"timestamp": 1631546263665, "ltp": 1.44, "tv": 17824.35, "trd": NaN, "batb": NaN, "batl": [[0, 1.45, 54.1], [1, 1.48, 44.34], [2, 1.52, 112.55]]}, {"timestamp": 1631546269654, "ltp": 1.45, "tv": 17848.17, "trd": [[1.45, 23.82]], "batb": [[0, 1.43, 139.86], [1, 1.42, 112.55], [2, 1.41, 112.55]], "batl": [[0, 1.45, 42.19], [1, 1.47, 13.29], [2, 1.48, 44.34]]}, {"timestamp": 1631546270068, "ltp": 1.45, "tv": 17848.17, "trd": NaN, "batb": [[0, 1.43, 140.53], [1, 1.42, 149.99]], "batl": NaN}, {"timestamp": 1631546274682, "ltp": 1.45, "tv": 17932.55, "trd": [[1.45, 108.2]], "batb": [[0, 1.45, 104.51], [1, 1.43, 140.53], [2, 1.42, 149.99]], "batl": [[0, 1.47, 13.29], [1, 1.48, 44.34], [2, 1.5, 192.98]]}, {"timestamp": 1631546280182, "ltp": 1.45, "tv": 17932.55, "trd": NaN, "batb": NaN, "batl": [[0, 1.48, 44.34], [1, 1.5, 192.98], [2, 1.51, 50.5]]}, {"timestamp": 1631546282652, "ltp": 1.45, "tv": 17932.55, "trd": NaN, "batb": [[1, 1.44, 13.36], [2, 1.43, 140.53]], "batl": [[0, 1.46, 12.79], [1, 1.48, 44.34], [2, 1.5, 192.98]]}, {"timestamp": 1631546283279, "ltp": 1.45, "tv": 17936.21, "trd": [[1.45, 111.85]], "batb": [[0, 1.45, 102.69]], "batl": NaN}, {"timestamp": 1631546294374, "ltp": 1.45, "tv": 18106.74, "trd": [[1.45, 282.38]], "batb": [[0, 1.45, 17.42]], "batl": NaN}, {"timestamp": 1631546301512, "ltp": 1.45, "tv": 18106.74, "trd": NaN, "batb": [[1, 1.43, 112.55], [2, 1.42, 112.55]], "batl": [[0, 1.48, 44.34], [1, 1.52, 112.55], [2, 1.53, 46.5]]}, {"timestamp": 1631546301829, "ltp": 1.45, "tv": 18106.74, "trd": NaN, "batb": NaN, "batl": [[2, 1.54, 44.25]]}, {"timestamp": 1631546306734, "ltp": 1.45, "tv": 18106.74, "trd": NaN, "batb": [[0, 1.41, 112.55], [1, 1.4, 59.96], [2, 1.39, 168.46]], "batl": NaN}, {"timestamp": 1631546309233, "ltp": 1.45, "tv": 18106.74, "trd": NaN, "batb": [[1, 1.4, 417.2]], "batl": [[0, 1.43, 56.28], [1, 1.44, 56.28], [2, 1.45, 56.28]]}, {"timestamp": 1631546316905, "ltp": 1.45, "tv": 18106.74, "trd": NaN, "batb": NaN, "batl": [[0, 1.43, 185.28], [2, 1.45, 108.98]]}, {"timestamp": 1631546321822, "ltp": 1.45, "tv": 18106.74, "trd": NaN, "batb": [[1, 1.4, 59.96]], "batl": NaN}, {"timestamp": 1631546324421, "ltp": 1.45, "tv": 18106.74, "trd": NaN, "batb": NaN, "batl": [[0, 1.43, 56.28]]}, {"timestamp": 1631546324737, "ltp": 1.45, "tv": 18106.74, "trd": NaN, "batb": NaN, "batl": [[2, 1.45, 56.28]]}, {"timestamp": 1631546330659, "ltp": 1.45, "tv": 18106.74, "trd": NaN, "batb": [[0, 1.4, 59.96], [1, 1.39, 55.91], [2, 1.38, 112.55]], "batl": NaN}, {"timestamp": 1631546331537, "ltp": 1.45, "tv": 18106.74, "trd": NaN, "batb": [[0, 1.39, 55.91], [1, 1.38, 112.55], [2, 1.37, 112.55]], "batl": [[2, 1.45, 113.58]]}, {"timestamp": 1631546331752, "ltp": 1.45, "tv": 18106.74, "trd": NaN, "batb": NaN, "batl": [[2, 1.45, 56.28]]}, {"timestamp": 1631546333150, "ltp": 1.45, "tv": 18106.74, "trd": NaN, "batb": [[1, 1.38, 586.97]], "batl": [[0, 1.4, 56.28], [1, 1.41, 56.28], [2, 1.43, 499.47]]}, {"timestamp": 1631546334451, "ltp": 1.45, "tv": 18106.74, "trd": NaN, "batb": NaN, "batl": [[0, 1.41, 56.28], [1, 1.43, 499.47], [2, 1.44, 56.28]]}, {"timestamp": 1631546338027, "ltp": 1.45, "tv": 18106.74, "trd": NaN, "batb": NaN, "batl": [[1, 1.43, 503.24]]}, {"timestamp": 1631546340263, "ltp": 1.45, "tv": 18106.74, "trd": NaN, "batb": [[1, 1.38, 648.43], [2, 1.37, 181.32]], "batl": [[1, 1.43, 563.74]]}, {"timestamp": 1631546341259, "ltp": 1.45, "tv": 18106.74, "trd": NaN, "batb": NaN, "batl": [[0, 1.4, 243], [1, 1.41, 56.28], [2, 1.43, 563.74]]}, {"timestamp": 1631546346566, "ltp": 1.45, "tv": 18106.74, "trd": NaN, "batb": [[0, 1.38, 112.55], [1, 1.37, 181.32], [2, 1.36, 60.93]], "batl": [[2, 1.43, 120.55]]}, {"timestamp": 1631546347558, "ltp": 1.45, "tv": 18106.74, "trd": NaN, "batb": NaN, "batl": [[0, 1.41, 56.28], [1, 1.43, 60.05], [2, 1.44, 56.28]]}, {"timestamp": 1631546349344, "ltp": 1.45, "tv": 18106.74, "trd": NaN, "batb": NaN, "batl": [[1, 1.43, 56.28]]}, {"timestamp": 1631546351057, "ltp": 1.45, "tv": 18106.74, "trd": NaN, "batb": [[0, 1.37, 181.32], [1, 1.36, 60.93], [2, 1.34, 71.22]], "batl": NaN}, {"timestamp": 1631546352054, "ltp": 1.45, "tv": 18106.74, "trd": NaN, "batb": [[1, 1.36, 563.26]], "batl": [[0, 1.38, 24.61], [1, 1.4, 28.58], [2, 1.41, 589.11]]}, {"timestamp": 1631546358572, "ltp": 1.45, "tv": 18106.74, "trd": NaN, "batb": NaN, "batl": [[2, 1.41, 645.61]]}, {"timestamp": 1631546361770, "ltp": 1.45, "tv": 18106.74, "trd": NaN, "batb": NaN, "batl": [[0, 1.38, 236.61]]}, {"timestamp": 1631546369496, "ltp": 1.45, "tv": 18106.74, "trd": NaN, "batb": [[0, 1.37, 112.55], [1, 1.36, 60.93]], "batl": [[0, 1.38, 212], [1, 1.41, 112.78], [2, 1.43, 116.78]]}, {"timestamp": 1631546370592, "ltp": 1.45, "tv": 18106.74, "trd": NaN, "batb": [[2, 1.26, 112.55]], "batl": [[0, 1.41, 56.28], [1, 1.43, 116.78], [2, 1.44, 56.28]]}, {"timestamp": 1631546372688, "ltp": 1.45, "tv": 18106.74, "trd": NaN, "batb": [[0, 1.37, 174.32]], "batl": NaN}, {"timestamp": 1631546372894, "ltp": 1.45, "tv": 18106.74, "trd": NaN, "batb": [[0, 1.37, 112.55]], "batl": NaN}, {"timestamp": 1631546374302, "ltp": 1.45, "tv": 18106.74, "trd": NaN, "batb": NaN, "batl": [[1, 1.43, 56.28]]}, {"timestamp": 1631546375605, "ltp": 1.45, "tv": 18106.74, "trd": NaN, "batb": [[0, 1.36, 60.93], [1, 1.26, 112.55], [2, 1.15, 357.92]], "batl": NaN}, {"timestamp": 1631546377393, "ltp": 1.36, "tv": 18134.1, "trd": [[1.36, 183.25]], "batb": [[0, 1.36, 47.25]], "batl": [[0, 1.39, 387.81], [1, 1.4, 28.58], [2, 1.41, 56.28]]}, {"timestamp": 1631546379113, "ltp": 1.36, "tv": 18134.1, "trd": NaN, "batb": [[2, 1.2, 538.74]], "batl": NaN}, {"timestamp": 1631546380685, "ltp": 1.36, "tv": 18134.1, "trd": NaN, "batb": [[1, 1.2, 538.74], [2, 1.15, 357.92]], "batl": [[2, 1.66, 588.41]]}, {"timestamp": 1631546382192, "ltp": 1.36, "tv": 18134.1, "trd": NaN, "batb": [[0, 1.37, 18.43], [1, 1.36, 47.25], [2, 1.2, 538.74]], "batl": NaN}, {"timestamp": 1631546382885, "ltp": 1.39, "tv": 18209.1, "trd": [[1.39, 3657.74]], "batb": NaN, "batl": [[0, 1.39, 350.31]]}, {"timestamp": 1631546383978, "ltp": 1.39, "tv": 18209.1, "trd": NaN, "batb": NaN, "batl": [[0, 1.38, 195], [1, 1.39, 350.31], [2, 1.4, 28.58]]}, {"timestamp": 1631546390074, "ltp": 1.37, "tv": 18242.74, "trd": [[1.37, 584.34]], "batb": [[0, 1.37, 1.61]], "batl": NaN}, {"timestamp": 1631546392689, "ltp": 1.37, "tv": 18242.74, "trd": NaN, "batb": [[0, 1.36, 47.25], [1, 1.2, 538.74], [2, 1.15, 357.92]], "batl": NaN}, {"timestamp": 1631546400412, "ltp": 1.38, "tv": 18245.94, "trd": [[1.38, 229.12]], "batb": NaN, "batl": [[0, 1.38, 193.4]]}, {"timestamp": 1631546403202, "ltp": 1.38, "tv": 18245.94, "trd": NaN, "batb": [[0, 1.36, 64.2]], "batl": [[0, 1.38, 209.46]]}, {"timestamp": 1631546468126, "ltp": 1.38, "tv": 18245.94, "trd": NaN, "batb": [[1, 1.32, 79.14], [2, 1.3, 94.48]], "batl": NaN}, {"timestamp": 1631546470632, "ltp": 1.38, "tv": 18245.94, "trd": NaN, "batb": [[0, 1.3, 94.48], [1, 1.2, 538.74], [2, 1.15, 357.92]], "batl": [[0, 1.38, 193.4], [1, 1.42, 61.25], [2, 1.44, 57.83]]}, {"timestamp": 1631546471523, "ltp": 1.38, "tv": 18245.94, "trd": NaN, "batb": NaN, "batl": [[0, 1.44, 57.83], [1, 1.66, 588.41], [2, 1.94, 3.08]]}, {"timestamp": 1631546473706, "ltp": 1.38, "tv": 18245.94, "trd": NaN, "batb": [[0, 1.38, 1.92], [1, 1.3, 94.48], [2, 1.2, 538.74]], "batl": NaN}, {"timestamp": 1631546474703, "ltp": 1.38, "tv": 18245.94, "trd": NaN, "batb": NaN, "batl": [[0, 1.42, 67.25], [1, 1.44, 57.83], [2, 1.66, 588.41]]}, {"timestamp": 1631546474905, "ltp": 1.38, "tv": 18245.94, "trd": NaN, "batb": NaN, "batl": [[0, 1.44, 57.83], [1, 1.66, 588.41], [2, 1.94, 3.08]]}, {"timestamp": 1631546477420, "ltp": 1.38, "tv": 18245.94, "trd": NaN, "batb": [[1, 1.32, 74.89], [2, 1.3, 94.48]], "batl": NaN}, {"timestamp": 1631546478430, "ltp": 1.38, "tv": 18245.94, "trd": NaN, "batb": [[1, 1.3, 94.48], [2, 1.2, 538.74]], "batl": NaN}, {"timestamp": 1631546479818, "ltp": 1.38, "tv": 18245.94, "trd": NaN, "batb": [[0, 1.3, 94.48], [1, 1.2, 538.74], [2, 1.15, 357.92]], "batl": [[0, 1.66, 588.41], [1, 1.94, 3.08], [2, 44, 7.22]]}, {"timestamp": 1631546481640, "ltp": 1.38, "tv": 18245.94, "trd": NaN, "batb": [[1, 1.15, 357.92], [2, 1.11, 271.16]], "batl": [[0, 1.42, 56.25], [1, 1.66, 588.41], [2, 1.94, 3.08]]}, {"timestamp": 1631546482644, "ltp": 1.38, "tv": 18245.94, "trd": NaN, "batb": [[0, 1.38, 61.46], [1, 1.3, 94.48], [2, 1.15, 357.92]], "batl": [[0, 1.66, 588.41], [1, 1.94, 3.08], [2, 44, 7.22]]}, {"timestamp": 1631546485416, "ltp": 1.38, "tv": 18245.94, "trd": NaN, "batb": [[2, 1.23, 524.14]], "batl": NaN}, {"timestamp": 1631546488608, "ltp": 1.38, "tv": 18245.94, "trd": NaN, "batb": NaN, "batl": [[0, 1.42, 163], [1, 1.66, 588.41], [2, 1.94, 3.08]]}, {"timestamp": 1631546489338, "ltp": 1.38, "tv": 18245.94, "trd": NaN, "batb": [[1, 1.37, 64.77], [2, 1.35, 67.27]], "batl": [[1, 1.43, 54.5], [2, 1.44, 63.33]]}, {"timestamp": 1631546494455, "ltp": 1.4, "tv": 18247.94, "trd": [[1.4, 835.15]], "batb": NaN, "batl": NaN}, {"timestamp": 1631546495669, "ltp": 1.4, "tv": 18247.94, "trd": NaN, "batb": [[0, 1.23, 524.14], [1, 1.15, 357.92], [2, 1.11, 271.16]], "batl": NaN}, {"timestamp": 1631546496459, "ltp": 1.4, "tv": 18247.94, "trd": NaN, "batb": NaN, "batl": [[0, 1.44, 63.33], [1, 1.66, 588.41], [2, 1.94, 3.08]]}, {"timestamp": 1631546499640, "ltp": 1.44, "tv": 18311.27, "trd": [[1.44, 88.29]], "batb": [[0, 1.35, 75.67], [1, 1.23, 524.14], [2, 1.15, 357.92]], "batl": [[0, 1.43, 61.5]]}, {"timestamp": 1631546499955, "ltp": 1.44, "tv": 18311.27, "trd": NaN, "batb": NaN, "batl": [[0, 1.66, 588.41], [1, 1.94, 3.08], [2, 44, 7.22]]}, {"timestamp": 1631546505839, "ltp": 1.44, "tv": 18311.27, "trd": NaN, "batb": [[0, 1.37, 93.77], [1, 1.35, 75.67], [2, 1.23, 524.14]], "batl": NaN}, {"timestamp": 1631546513854, "ltp": 1.44, "tv": 18311.27, "trd": NaN, "batb": NaN, "batl": [[0, 1.43, 62.5], [1, 1.66, 588.41], [2, 1.94, 3.08]]}, {"timestamp": 1631546515851, "ltp": 1.44, "tv": 18311.27, "trd": NaN, "batb": NaN, "batl": [[0, 1.66, 588.41], [1, 1.94, 3.08], [2, 44, 7.22]]}, {"timestamp": 1631546519486, "ltp": 1.44, "tv": 18311.27, "trd": NaN, "batb": [[2, 1.15, 357.92]], "batl": NaN}, {"timestamp": 1631546520589, "ltp": 1.44, "tv": 18311.27, "trd": NaN, "batb": [[0, 1.43, 14.31], [1, 1.42, 28.16], [2, 1.41, 96.89]], "batl": [[0, 1.45, 12.15], [1, 1.47, 395.36], [2, 1.66, 588.41]]}, {"timestamp": 1631546531682, "ltp": 1.44, "tv": 18311.27, "trd": NaN, "batb": NaN, "batl": [[0, 1.45, 64.25], [1, 1.46, 59.25], [2, 1.47, 395.36]]}, {"timestamp": 1631546534403, "ltp": 1.44, "tv": 18311.27, "trd": NaN, "batb": NaN, "batl": [[0, 1.45, 228.25]]}, {"timestamp": 1631546542102, "ltp": 1.44, "tv": 18311.27, "trd": NaN, "batb": [[0, 1.39, 93.91], [1, 1.37, 93.77], [2, 1.35, 75.67]], "batl": [[0, 1.45, 164], [2, 1.66, 588.41]]}, {"timestamp": 1631546543308, "ltp": 1.44, "tv": 18311.27, "trd": NaN, "batb": NaN, "batl": [[0, 1.46, 59.25], [1, 1.66, 588.41], [2, 1.94, 3.08]]}, {"timestamp": 1631546546418, "ltp": 1.44, "tv": 18311.27, "trd": NaN, "batb": NaN, "batl": [[1, 1.94, 3.08], [2, 44, 7.22]]}, {"timestamp": 1631546547521, "ltp": 1.46, "tv": 18333.19, "trd": [[1.46, 49.2]], "batb": NaN, "batl": [[0, 1.46, 48.29], [1, 1.48, 13.24], [2, 1.5, 201.7]]}, {"timestamp": 1631546547834, "ltp": 1.46, "tv": 18333.19, "trd": NaN, "batb": [[0, 1.42, 94.44], [1, 1.39, 93.91], [2, 1.37, 93.77]], "batl": NaN}, {"timestamp": 1631546554615, "ltp": 1.46, "tv": 18333.19, "trd": NaN, "batb": [[1, 1.41, 98.89], [2, 1.39, 93.91]], "batl": [[1, 1.47, 59.5], [2, 1.48, 13.24]]}, {"timestamp": 1631546557698, "ltp": 1.46, "tv": 18333.19, "trd": NaN, "batb": NaN, "batl": [[2, 1.5, 201.7]]}, {"timestamp": 1631546557801, "ltp": 1.46, "tv": 18333.19, "trd": NaN, "batb": NaN, "batl": [[0, 1.46, 173.29]]}, {"timestamp": 1631546560623, "ltp": 1.46, "tv": 18333.19, "trd": NaN, "batb": [[0, 1.45, 12.83], [1, 1.42, 94.44], [2, 1.41, 98.89]], "batl": [[1, 1.47, 71.78]]}, {"timestamp": 1631546561509, "ltp": 1.46, "tv": 18333.19, "trd": NaN, "batb": [[0, 1.41, 98.89], [1, 1.39, 93.91], [2, 1.37, 93.77]], "batl": [[0, 1.46, 125], [1, 1.47, 59.5], [2, 1.82, 476.07]]}, {"timestamp": 1631546562244, "ltp": 1.46, "tv": 18333.19, "trd": NaN, "batb": NaN, "batl": [[0, 1.47, 59.5], [1, 1.82, 476.07], [2, 1.94, 3.08]]}, {"timestamp": 1631546563524, "ltp": 1.46, "tv": 18333.19, "trd": NaN, "batb": [[1, 1.28, 493.1], [2, 1.15, 357.92]], "batl": NaN}, {"timestamp": 1631546564433, "ltp": 1.46, "tv": 18333.19, "trd": NaN, "batb": [[1, 1.4, 93.41], [2, 1.28, 493.1]], "batl": NaN}, {"timestamp": 1631546568457, "ltp": 1.47, "tv": 18408.64, "trd": [[1.46, 100.45], [1.47, 24.2]], "batb": [[0, 1.42, 106.94], [1, 1.41, 98.89], [2, 1.4, 93.41]], "batl": [[0, 1.47, 47.4], [1, 1.5, 11.39], [2, 1.52, 380.31]]}, {"timestamp": 1631546574343, "ltp": 1.47, "tv": 18408.64, "trd": NaN, "batb": NaN, "batl": [[0, 1.47, 218.4]]}, {"timestamp": 1631546578308, "ltp": 1.46, "tv": 18410.82, "trd": [[1.46, 102.63]], "batb": NaN, "batl": [[1, 1.52, 380.31], [2, 1.82, 476.07]]}, {"timestamp": 1631546581255, "ltp": 1.46, "tv": 18410.82, "trd": NaN, "batb": [[0, 1.46, 12.55], [1, 1.42, 106.94], [2, 1.41, 98.89]], "batl": [[1, 1.48, 12.03], [2, 1.52, 380.31]]}, {"timestamp": 1631546583967, "ltp": 1.47, "tv": 18428.06, "trd": [[1.47, 41.44]], "batb": NaN, "batl": [[0, 1.47, 209.78]]}, {"timestamp": 1631546587696, "ltp": 1.47, "tv": 18601.6, "trd": [[1.47, 214.98]], "batb": NaN, "batl": [[0, 1.47, 36.24]]}, {"timestamp": 1631546587971, "ltp": 1.46, "tv": 18604.48, "trd": [[1.46, 105.51]], "batb": [[0, 1.46, 11.11]], "batl": NaN}, {"timestamp": 1631546598181, "ltp": 1.46, "tv": 18604.48, "trd": NaN, "batb": [[0, 1.42, 106.94], [1, 1.41, 98.89], [2, 1.4, 93.41]], "batl": [[1, 1.52, 380.31], [2, 1.82, 476.07]]}, {"timestamp": 1631546601478, "ltp": 1.46, "tv": 18604.48, "trd": NaN, "batb": [[0, 1.46, 11.11], [1, 1.42, 106.94], [2, 1.41, 98.89]], "batl": [[0, 1.47, 171], [1, 1.48, 13.45], [2, 1.52, 380.31]]}, {"timestamp": 1631546603584, "ltp": 1.46, "tv": 18604.48, "trd": NaN, "batb": [[0, 1.39, 145.91], [1, 1.28, 493.1], [2, 1.15, 357.92]], "batl": [[0, 1.82, 476.07], [1, 1.94, 3.08], [2, 44, 7.22]]}, {"timestamp": 1631546610502, "ltp": 1.46, "tv": 18604.48, "trd": NaN, "batb": [[0, 1.42, 504.91], [1, 1.39, 145.91], [2, 1.28, 493.1]], "batl": [[0, 1.44, 13.9], [1, 1.82, 476.07], [2, 1.94, 3.08]]}, {"timestamp": 1631546616996, "ltp": 1.46, "tv": 18604.48, "trd": NaN, "batb": [[1, 1.41, 156.89], [2, 1.4, 164.31]], "batl": NaN}, {"timestamp": 1631546620199, "ltp": 1.46, "tv": 18604.48, "trd": NaN, "batb": NaN, "batl": [[0, 1.44, 181.9]]}, {"timestamp": 1631546628407, "ltp": 1.46, "tv": 18604.48, "trd": NaN, "batb": [[0, 1.28, 493.1], [1, 1.15, 357.92], [2, 1.11, 271.16]], "batl": [[0, 1.82, 476.07], [1, 1.94, 3.08], [2, 44, 7.22]]}, {"timestamp": 1631546631508, "ltp": 1.46, "tv": 18604.48, "trd": NaN, "batb": [[0, 1.4, 178.06], [1, 1.28, 493.1], [2, 1.15, 357.92]], "batl": NaN}, {"timestamp": 1631546632832, "ltp": 1.46, "tv": 18604.48, "trd": NaN, "batb": [[1, 1.15, 357.92], [2, 1.11, 271.16]], "batl": [[0, 1.94, 3.08], [1, 44, 7.22], [2, 44, 0]]}, {"timestamp": 1631546634549, "ltp": 1.46, "tv": 18604.48, "trd": NaN, "batb": NaN, "batl": [[0, 1.41, 14.57], [1, 1.46, 27.4], [2, 1.94, 3.08]]}, {"timestamp": 1631546636360, "ltp": 1.46, "tv": 18604.48, "trd": NaN, "batb": [[1, 1.23, 524.14], [2, 1.15, 357.92]], "batl": [[2, 1.73, 535.39]]}, {"timestamp": 1631546641631, "ltp": 1.46, "tv": 18604.48, "trd": NaN, "batb": [[1, 1.39, 174.91], [2, 1.38, 161.46]], "batl": [[0, 1.41, 264.57]]}, {"timestamp": 1631546645446, "ltp": 1.46, "tv": 18604.48, "trd": NaN, "batb": [[0, 1.38, 161.46], [1, 1.23, 524.14], [2, 1.15, 357.92]], "batl": [[0, 1.41, 250], [1, 1.73, 535.39], [2, 1.94, 3.08]]}, {"timestamp": 1631546646266, "ltp": 1.46, "tv": 18604.48, "trd": NaN, "batb": NaN, "batl": [[0, 1.73, 535.39], [1, 1.94, 3.08], [2, 44, 7.22]]}, {"timestamp": 1631546648658, "ltp": 1.46, "tv": 18604.48, "trd": NaN, "batb": [[0, 1.39, 177.91], [1, 1.38, 161.46], [2, 1.23, 524.14]], "batl": NaN}, {"timestamp": 1631546648867, "ltp": 1.46, "tv": 18604.48, "trd": NaN, "batb": [[0, 1.38, 161.46], [1, 1.23, 524.14], [2, 1.15, 357.92]], "batl": NaN}, {"timestamp": 1631546652463, "ltp": 1.39, "tv": 18637.7, "trd": [[1.39, 3690.96]], "batb": NaN, "batl": [[0, 1.42, 429.55], [1, 1.46, 27.4], [2, 1.73, 535.39]]}, {"timestamp": 1631546663156, "ltp": 1.39, "tv": 18637.7, "trd": NaN, "batb": NaN, "batl": [[0, 1.41, 108], [1, 1.42, 429.55], [2, 1.46, 27.4]]}, {"timestamp": 1631546664565, "ltp": 1.39, "tv": 18637.7, "trd": NaN, "batb": NaN, "batl": [[1, 1.73, 535.39], [2, 1.94, 3.08]]}, {"timestamp": 1631546665469, "ltp": 1.39, "tv": 18637.7, "trd": NaN, "batb": [[0, 1.23, 524.14], [1, 1.15, 357.92], [2, 1.11, 271.16]], "batl": [[0, 1.73, 535.39], [1, 1.94, 3.08], [2, 44, 7.22]]}, {"timestamp": 1631546668395, "ltp": 1.39, "tv": 18637.7, "trd": NaN, "batb": [[0, 1.38, 147.46], [1, 1.23, 524.14], [2, 1.15, 357.92]], "batl": NaN}, {"timestamp": 1631546685591, "ltp": 1.39, "tv": 18637.7, "trd": NaN, "batb": [[0, 1.39, 155.91], [1, 1.38, 147.46], [2, 1.23, 524.14]], "batl": NaN}, {"timestamp": 1631546685901, "ltp": 1.39, "tv": 18637.7, "trd": NaN, "batb": [[0, 1.38, 147.46], [1, 1.23, 524.14], [2, 1.15, 357.92]], "batl": NaN}, {"timestamp": 1631546691995, "ltp": 1.39, "tv": 18637.7, "trd": NaN, "batb": [[1, 1.15, 357.92], [2, 1.11, 271.16]], "batl": NaN}, {"timestamp": 1631546692820, "ltp": 1.39, "tv": 18637.7, "trd": NaN, "batb": [[0, 1.39, 175.91], [1, 1.38, 147.46], [2, 1.15, 357.92]], "batl": NaN}, {"timestamp": 1631546694440, "ltp": 1.39, "tv": 18637.7, "trd": NaN, "batb": [[0, 1.41, 45.05], [1, 1.39, 175.91], [2, 1.38, 1332.89]], "batl": [[0, 1.43, 11.61], [1, 1.73, 535.39], [2, 1.94, 3.08]]}, {"timestamp": 1631546699235, "ltp": 1.41, "tv": 18644.48, "trd": [[1.41, 246.01]], "batb": [[0, 1.41, 40.54]], "batl": NaN}, {"timestamp": 1631546701343, "ltp": 1.41, "tv": 18644.48, "trd": NaN, "batb": [[1, 1.4, 158.96], [2, 1.39, 322.22]], "batl": [[1, 1.49, 144.61], [2, 1.5, 116.08]]}, {"timestamp": 1631546702443, "ltp": 1.41, "tv": 18644.48, "trd": NaN, "batb": NaN, "batl": [[0, 1.43, 182.61]]}, {"timestamp": 1631546714954, "ltp": 1.41, "tv": 18655.3, "trd": [[1.41, 256.83]], "batb": [[0, 1.41, 35.13]], "batl": NaN}, {"timestamp": 1631546717665, "ltp": 1.41, "tv": 18655.3, "trd": NaN, "batb": [[0, 1.4, 158.96], [1, 1.39, 322.22], [2, 1.38, 311.29]], "batl": [[0, 1.43, 171]]}, {"timestamp": 1631546717939, "ltp": 1.41, "tv": 18655.3, "trd": NaN, "batb": [[0, 1.39, 322.22], [1, 1.38, 311.29], [2, 1.37, 182.44]], "batl": NaN}, {"timestamp": 1631546720253, "ltp": 1.41, "tv": 18655.3, "trd": NaN, "batb": NaN, "batl": [[0, 1.49, 144.61], [1, 1.5, 116.08], [2, 1.51, 162.33]]}, {"timestamp": 1631546723571, "ltp": 1.41, "tv": 18655.3, "trd": NaN, "batb": [[1, 1.38, 163.83]], "batl": [[0, 1.73, 535.39], [1, 1.94, 3.08], [2, 44, 7.22]]}, {"timestamp": 1631546724564, "ltp": 1.41, "tv": 18655.3, "trd": NaN, "batb": [[0, 1.4, 157.96], [1, 1.39, 322.22], [2, 1.38, 163.83]], "batl": NaN}, {"timestamp": 1631546725349, "ltp": 1.41, "tv": 18655.3, "trd": NaN, "batb": [[0, 1.39, 322.22], [1, 1.38, 163.83], [2, 1.37, 182.44]], "batl": NaN}, {"timestamp": 1631546726483, "ltp": 1.41, "tv": 18655.3, "trd": NaN, "batb": NaN, "batl": [[0, 1.41, 13.25], [1, 1.43, 382.28], [2, 1.73, 535.39]]}, {"timestamp": 1631546733489, "ltp": 1.41, "tv": 18655.3, "trd": NaN, "batb": NaN, "batl": [[2, 1.48, 138.92]]}, {"timestamp": 1631546743185, "ltp": 1.41, "tv": 18655.3, "trd": NaN, "batb": NaN, "batl": [[0, 1.41, 211.25]]}, {"timestamp": 1631546749490, "ltp": 1.41, "tv": 18655.48, "trd": [[1.41, 257.01]], "batb": NaN, "batl": [[0, 1.41, 211.16]]}, {"timestamp": 1631546759728, "ltp": 1.41, "tv": 18655.48, "trd": NaN, "batb": NaN, "batl": [[0, 1.41, 198]]}, {"timestamp": 1631546762609, "ltp": 1.41, "tv": 18655.48, "trd": NaN, "batb": NaN, "batl": [[0, 1.41, 211.16]]}, {"timestamp": 1631546763121, "ltp": 1.41, "tv": 18727.82, "trd": [[1.41, 329.35]], "batb": NaN, "batl": [[0, 1.41, 138.82]]}, {"timestamp": 1631546792378, "ltp": 1.41, "tv": 18727.82, "trd": NaN, "batb": NaN, "batl": [[0, 1.41, 148.82]]}, {"timestamp": 1631546824610, "ltp": 1.41, "tv": 18727.82, "trd": NaN, "batb": [[0, 1.35, 140.08], [1, 1.34, 307.92], [2, 1.33, 217.12]], "batl": [[0, 1.41, 135.66], [1, 1.48, 138.92], [2, 1.49, 120.46]]}, {"timestamp": 1631546825294, "ltp": 1.41, "tv": 18727.82, "trd": NaN, "batb": NaN, "batl": [[0, 1.41, 10]]}, {"timestamp": 1631546841434, "ltp": 1.41, "tv": 18727.82, "trd": NaN, "batb": NaN, "batl": [[0, 1.48, 138.92], [1, 1.49, 120.46], [2, 1.5, 181.25]]}, {"timestamp": 1631546849229, "ltp": 1.41, "tv": 18727.82, "trd": NaN, "batb": NaN, "batl": [[0, 1.94, 3.08], [1, 44, 7.22], [2, 1.5, 0]]}, {"timestamp": 1631546852348, "ltp": 1.35, "tv": 18767.74, "trd": [[1.35, 9785.08]], "batb": [[0, 1.35, 120.11], [2, 1.33, 234.07]], "batl": NaN}, {"timestamp": 1631546857265, "ltp": 1.35, "tv": 18772.57, "trd": [[1.35, 9789.91]], "batb": [[0, 1.35, 117.7]], "batl": NaN}, {"timestamp": 1631546859077, "ltp": 1.35, "tv": 18772.57, "trd": NaN, "batb": NaN, "batl": [[0, 1.4, 304.4], [1, 1.94, 3.08], [2, 44, 7.22]]}, {"timestamp": 1631546860438, "ltp": 1.35, "tv": 18772.57, "trd": NaN, "batb": NaN, "batl": [[0, 1.39, 403.95], [1, 1.4, 304.4], [2, 1.94, 3.08]]}, {"timestamp": 1631546862561, "ltp": 1.35, "tv": 18772.57, "trd": NaN, "batb": [[2, 1.33, 217.12]], "batl": [[0, 1.39, 335.95]]}, {"timestamp": 1631546865682, "ltp": 1.35, "tv": 18772.57, "trd": NaN, "batb": [[1, 1.34, 325.98]], "batl": [[0, 1.36, 17.06], [1, 1.38, 101], [2, 1.39, 335.95]]}, {"timestamp": 1631546867465, "ltp": 1.35, "tv": 18772.57, "trd": NaN, "batb": NaN, "batl": [[2, 1.94, 3.08]]}, {"timestamp": 1631546867880, "ltp": 1.35, "tv": 18772.57, "trd": NaN, "batb": NaN, "batl": [[1, 1.94, 3.08], [2, 44, 7.22]]}, {"timestamp": 1631546869695, "ltp": 1.35, "tv": 18772.57, "trd": NaN, "batb": [[0, 1.25, 162.49], [1, 1.15, 357.92], [2, 1.11, 271.16]], "batl": [[0, 1.94, 3.08], [1, 44, 7.22], [2, 44, 0]]}, {"timestamp": 1631546875588, "ltp": 1.35, "tv": 18772.57, "trd": NaN, "batb": NaN, "batl": [[0, 1.36, 22.07], [1, 1.94, 3.08], [2, 44, 7.22]]}, {"timestamp": 1631546876575, "ltp": 1.35, "tv": 18772.57, "trd": NaN, "batb": [[0, 1.28, 173.91], [1, 1.25, 162.49], [2, 1.15, 357.92]], "batl": [[0, 1.94, 3.08], [1, 44, 7.22], [2, 44, 0]]}, {"timestamp": 1631546876892, "ltp": 1.35, "tv": 18772.57, "trd": NaN, "batb": [[0, 1.25, 162.49], [1, 1.15, 357.92], [2, 1.11, 271.16]], "batl": NaN}, {"timestamp": 1631546883682, "ltp": 1.35, "tv": 18772.57, "trd": NaN, "batb": [[0, 1.28, 166.41], [1, 1.25, 162.49], [2, 1.15, 357.92]], "batl": NaN}, {"timestamp": 1631546883888, "ltp": 1.35, "tv": 18772.57, "trd": NaN, "batb": [[0, 1.25, 162.49], [1, 1.15, 357.92], [2, 1.11, 271.16]], "batl": NaN}, {"timestamp": 1631546890610, "ltp": 1.35, "tv": 18772.57, "trd": NaN, "batb": [[0, 1.28, 176.41], [1, 1.25, 162.49], [2, 1.15, 357.92]], "batl": NaN}, {"timestamp": 1631546890912, "ltp": 1.35, "tv": 18772.57, "trd": NaN, "batb": [[0, 1.25, 162.49], [1, 1.15, 357.92], [2, 1.11, 271.16]], "batl": NaN}, {"timestamp": 1631546897428, "ltp": 1.35, "tv": 18772.57, "trd": NaN, "batb": [[0, 1.38, 167.96], [1, 1.25, 162.49], [2, 1.15, 357.92]], "batl": [[0, 1.41, 19.03], [1, 1.94, 3.08], [2, 44, 7.22]]}, {"timestamp": 1631546904825, "ltp": 1.35, "tv": 18772.57, "trd": NaN, "batb": [[1, 1.32, 172.39], [2, 1.29, 148.81]], "batl": [[0, 1.39, 200], [1, 1.41, 19.03], [2, 1.94, 3.08]]}, {"timestamp": 1631546905860, "ltp": 1.35, "tv": 18772.57, "trd": NaN, "batb": [[2, 1.31, 167.79]], "batl": NaN}, {"timestamp": 1631546910333, "ltp": 1.38, "tv": 18792.57, "trd": [[1.38, 249.12]], "batb": [[0, 1.38, 157.96]], "batl": NaN}, {"timestamp": 1631546911835, "ltp": 1.38, "tv": 18792.57, "trd": NaN, "batb": NaN, "batl": [[1, 1.94, 3.08], [2, 44, 7.22]]}, {"timestamp": 1631546921346, "ltp": 1.38, "tv": 18792.57, "trd": NaN, "batb": [[0, 1.28, 151.66], [1, 1.15, 357.92], [2, 1.1, 298.27]], "batl": [[0, 1.94, 3.08], [1, 44, 7.22], [2, 44, 0]]}, {"timestamp": 1631546934685, "ltp": 1.38, "tv": 18792.57, "trd": NaN, "batb": [[0, 1.31, 154.79], [1, 1.28, 151.66], [2, 1.15, 357.92]], "batl": NaN}, {"timestamp": 1631546935368, "ltp": 1.38, "tv": 18792.57, "trd": NaN, "batb": [[0, 1.42, 16.56], [1, 1.41, 188.25], [2, 1.28, 151.66]], "batl": [[0, 1.44, 10.86], [1, 1.47, 494.57], [2, 1.94, 3.08]]}, {"timestamp": 1631546937165, "ltp": 1.38, "tv": 18792.57, "trd": NaN, "batb": NaN, "batl": [[2, 1.77, 508.04]]}, {"timestamp": 1631546942805, "ltp": 1.38, "tv": 18792.57, "trd": NaN, "batb": [[2, 1.38, 148.96]], "batl": NaN}, {"timestamp": 1631546946406, "ltp": 1.38, "tv": 18792.57, "trd": NaN, "batb": [[0, 1.41, 159.89], [1, 1.38, 148.96], [2, 1.36, 157.93]], "batl": [[0, 1.44, 120], [1, 1.77, 508.04], [2, 1.94, 3.08]]}, {"timestamp": 1631546947386, "ltp": 1.38, "tv": 18792.57, "trd": NaN, "batb": [[0, 1.25, 512.59], [1, 1.15, 357.92], [2, 1.1, 298.27]], "batl": [[0, 1.77, 508.04], [1, 1.94, 3.08], [2, 44, 7.22]]}, {"timestamp": 1631546950188, "ltp": 1.38, "tv": 18792.57, "trd": NaN, "batb": [[0, 1.36, 153.93], [1, 1.25, 512.59], [2, 1.15, 357.92]], "batl": NaN}, {"timestamp": 1631546952623, "ltp": 1.38, "tv": 18792.57, "trd": NaN, "batb": NaN, "batl": [[0, 1.43, 18.64], [1, 1.77, 508.04], [2, 1.94, 3.08]]}, {"timestamp": 1631546953711, "ltp": 1.38, "tv": 18792.57, "trd": NaN, "batb": [[0, 1.38, 147.46], [1, 1.36, 153.93], [2, 1.25, 512.59]], "batl": [[0, 1.77, 508.04], [1, 1.94, 3.08], [2, 44, 7.22]]}, {"timestamp": 1631546954023, "ltp": 1.38, "tv": 18792.57, "trd": NaN, "batb": [[0, 1.36, 153.93], [1, 1.25, 512.59], [2, 1.15, 357.92]], "batl": NaN}, {"timestamp": 1631546959951, "ltp": 1.38, "tv": 18792.57, "trd": NaN, "batb": [[1, 1.15, 357.92], [2, 1.1, 298.27]], "batl": [[0, 1.94, 3.08], [1, 44, 7.22], [2, 44, 0]]}, {"timestamp": 1631546962603, "ltp": 1.38, "tv": 18792.57, "trd": NaN, "batb": [[0, 1.38, 155.96], [1, 1.36, 153.93], [2, 1.15, 357.92]], "batl": NaN}, {"timestamp": 1631546962910, "ltp": 1.38, "tv": 18792.57, "trd": NaN, "batb": [[0, 1.36, 153.93], [1, 1.15, 357.92], [2, 1.1, 298.27]], "batl": NaN}, {"timestamp": 1631546965503, "ltp": 1.38, "tv": 18792.57, "trd": NaN, "batb": [[0, 1.36, 168.39]], "batl": [[0, 1.38, 18.65], [1, 1.4, 28.58], [2, 1.41, 722.57]]}, {"timestamp": 1631546972346, "ltp": 1.38, "tv": 18792.57, "trd": NaN, "batb": [[1, 1.27, 156.87], [2, 1.24, 146.77]], "batl": NaN}, {"timestamp": 1631546975422, "ltp": 1.38, "tv": 18792.57, "trd": NaN, "batb": NaN, "batl": [[0, 1.38, 146.65]]}, {"timestamp": 1631546988649, "ltp": 1.38, "tv": 18792.57, "trd": NaN, "batb": [[0, 1.27, 156.87], [1, 1.24, 146.77], [2, 1.15, 357.92]], "batl": [[0, 1.38, 128], [1, 1.94, 3.08], [2, 44, 7.22]]}, {"timestamp": 1631546989275, "ltp": 1.38, "tv": 18792.57, "trd": NaN, "batb": [[0, 1.24, 146.77], [1, 1.15, 357.92], [2, 1.1, 298.27]], "batl": [[0, 1.94, 3.08], [1, 44, 7.22], [2, 44, 0]]}, {"timestamp": 1631546995448, "ltp": 1.38, "tv": 18792.57, "trd": NaN, "batb": [[0, 1.41, 153.89], [1, 1.4, 306.36], [2, 1.38, 28.98]], "batl": NaN}, {"timestamp": 1631547006181, "ltp": 1.38, "tv": 18792.57, "trd": NaN, "batb": NaN, "batl": [[0, 1.44, 66], [1, 1.94, 3.08], [2, 44, 7.22]]}, {"timestamp": 1631547014106, "ltp": 1.38, "tv": 18792.57, "trd": NaN, "batb": NaN, "batl": [[0, 1.94, 3.08], [1, 44, 7.22], [2, 44, 0]]}, {"timestamp": 1631547017274, "ltp": 1.38, "tv": 18792.57, "trd": NaN, "batb": NaN, "batl": [[0, 1.43, 257], [1, 1.94, 3.08], [2, 44, 7.22]]}, {"timestamp": 1631547021692, "ltp": 1.38, "tv": 18792.57, "trd": NaN, "batb": [[0, 1.35, 139.07], [1, 1.15, 357.92], [2, 1.1, 298.27]], "batl": NaN}, {"timestamp": 1631547022320, "ltp": 1.38, "tv": 18792.57, "trd": NaN, "batb": NaN, "batl": [[0, 1.94, 3.08], [1, 44, 7.22], [2, 44, 0]]}, {"timestamp": 1631547028517, "ltp": 1.38, "tv": 18792.57, "trd": NaN, "batb": [[0, 1.37, 134.77], [1, 1.35, 139.07], [2, 1.15, 357.92]], "batl": NaN}, {"timestamp": 1631547028990, "ltp": 1.37, "tv": 19098.5, "trd": [[1.37, 844.12], [1.43, 67.49]], "batb": [[0, 1.35, 139.07], [1, 1.15, 357.92], [2, 1.1, 298.27]], "batl": NaN}, {"timestamp": 1631547037302, "ltp": 1.37, "tv": 19098.5, "trd": NaN, "batb": [[1, 1.28, 92.66], [2, 1.25, 95.61]], "batl": [[0, 1.42, 6.75], [1, 1.44, 6.33], [2, 1.94, 3.08]]}, {"timestamp": 1631547038093, "ltp": 1.35, "tv": 19269.04, "trd": [[1.35, 9960.44]], "batb": [[0, 1.35, 53.8]], "batl": NaN}, {"timestamp": 1631547041950, "ltp": 1.35, "tv": 19269.04, "trd": NaN, "batb": [[0, 1.36, 16.82], [1, 1.35, 53.8], [2, 1.28, 92.66]], "batl": [[0, 1.38, 15.93], [1, 1.42, 6.75], [2, 1.44, 6.33]]}, {"timestamp": 1631547044386, "ltp": 1.35, "tv": 19269.04, "trd": NaN, "batb": [[0, 1.25, 95.61], [1, 1.15, 357.92], [2, 1.1, 298.27]], "batl": [[0, 1.94, 3.08], [1, 44, 7.22], [2, 1.44, 0]]}, {"timestamp": 1631547046360, "ltp": 1.35, "tv": 19269.04, "trd": NaN, "batb": [[1, 1.23, 112.63], [2, 1.15, 357.92]], "batl": [[0, 1.44, 60.58], [1, 1.94, 3.08], [2, 44, 7.22]]}, {"timestamp": 1631547047554, "ltp": 1.35, "tv": 19269.04, "trd": NaN, "batb": NaN, "batl": [[0, 1.42, 6.25], [1, 1.44, 66.41], [2, 1.94, 3.08]]}, {"timestamp": 1631547047761, "ltp": 1.35, "tv": 19269.04, "trd": NaN, "batb": NaN, "batl": [[0, 1.44, 60.58], [1, 1.94, 3.08], [2, 44, 7.22]]}, {"timestamp": 1631547049582, "ltp": 1.35, "tv": 19269.04, "trd": NaN, "batb": NaN, "batl": [[0, 1.42, 58.25], [1, 1.44, 60.58], [2, 1.94, 3.08]]}, {"timestamp": 1631547050098, "ltp": 1.35, "tv": 19269.04, "trd": NaN, "batb": NaN, "batl": [[0, 1.44, 60.58], [1, 1.94, 3.08], [2, 44, 7.22]]}, {"timestamp": 1631547054504, "ltp": 1.35, "tv": 19269.04, "trd": NaN, "batb": [[0, 1.28, 88.91], [1, 1.25, 95.61], [2, 1.23, 112.63]], "batl": [[0, 1.42, 6.75], [1, 1.44, 66.41], [2, 1.94, 3.08]]}, {"timestamp": 1631547054815, "ltp": 1.35, "tv": 19269.04, "trd": NaN, "batb": [[0, 1.25, 95.61], [1, 1.23, 112.63], [2, 1.15, 357.92]], "batl": [[0, 1.44, 60.58], [1, 1.94, 3.08], [2, 44, 7.22]]}, {"timestamp": 1631547061469, "ltp": 1.35, "tv": 19269.04, "trd": NaN, "batb": [[0, 1.28, 79.41], [1, 1.25, 95.61], [2, 1.23, 112.63]], "batl": [[0, 1.42, 6.25], [1, 1.44, 66.91], [2, 1.94, 3.08]]}, {"timestamp": 1631547061787, "ltp": 1.35, "tv": 19269.04, "trd": NaN, "batb": [[0, 1.25, 95.61], [1, 1.23, 112.63], [2, 1.15, 357.92]], "batl": [[0, 1.44, 60.58], [1, 1.94, 3.08], [2, 44, 7.22]]}, {"timestamp": 1631547065387, "ltp": 1.35, "tv": 19269.04, "trd": NaN, "batb": NaN, "batl": [[0, 1.94, 3.08], [1, 44, 7.22], [2, 44, 0]]}, {"timestamp": 1631547067517, "ltp": 1.35, "tv": 19269.04, "trd": NaN, "batb": [[0, 1.28, 15.54], [1, 1.25, 647.95], [2, 1.23, 112.63]], "batl": [[0, 1.31, 36.17], [1, 1.94, 3.08], [2, 44, 7.22]]}, {"timestamp": 1631547072626, "ltp": 1.3, "tv": 19270.66, "trd": [[1.3, 1.62]], "batb": NaN, "batl": NaN}, {"timestamp": 1631547074091, "ltp": 1.3, "tv": 19270.66, "trd": NaN, "batb": NaN, "batl": [[1, 1.38, 5.75], [2, 1.41, 6.11]]}, {"timestamp": 1631547079247, "ltp": 1.25, "tv": 19498.74, "trd": [[1.25, 197], [1.28, 31.08]], "batb": [[0, 1.25, 549.45], [1, 1.23, 112.63], [2, 1.15, 357.92]], "batl": NaN}, {"timestamp": 1631547086521, "ltp": 1.25, "tv": 19498.74, "trd": NaN, "batb": NaN, "batl": [[0, 1.29, 18.85], [1, 1.31, 36.17], [2, 1.38, 5.75]]}, {"timestamp": 1631547087812, "ltp": 1.29, "tv": 19499.43, "trd": [[1.29, 0.7]], "batb": NaN, "batl": [[0, 1.29, 18.5], [2, 1.38, 66]]}, {"timestamp": 1631547089427, "ltp": 1.29, "tv": 19499.43, "trd": NaN, "batb": NaN, "batl": [[0, 1.31, 36.17], [1, 1.38, 66], [2, 1.41, 66.61]]}, {"timestamp": 1631547091037, "ltp": 1.31, "tv": 19499.47, "trd": [[1.31, 0.04]], "batb": NaN, "batl": [[0, 1.31, 36.15]]}, {"timestamp": 1631547092446, "ltp": 1.31, "tv": 19499.47, "trd": NaN, "batb": NaN, "batl": [[0, 1.29, 18.5], [1, 1.31, 36.15], [2, 1.38, 66]]}, {"timestamp": 1631547093425, "ltp": 1.31, "tv": 19499.47, "trd": NaN, "batb": [[0, 1.15, 357.92], [1, 1.13, 197.73], [2, 1.1, 298.27]], "batl": [[0, 1.31, 5.63], [1, 1.94, 3.08], [2, 44, 7.22]]}, {"timestamp": 1631547094563, "ltp": 1.31, "tv": 19499.47, "trd": NaN, "batb": NaN, "batl": [[0, 1.94, 3.08], [1, 44, 7.22], [2, 44, 0]]}, {"timestamp": 1631547096638, "ltp": 1.31, "tv": 19499.47, "trd": NaN, "batb": [[1, 1.14, 168.32], [2, 1.13, 197.73]], "batl": [[0, 1.38, 77.5], [1, 1.41, 72.61], [2, 1.94, 3.08]]}, {"timestamp": 1631547097257, "ltp": 1.31, "tv": 19499.47, "trd": NaN, "batb": NaN, "batl": [[0, 1.27, 5], [1, 1.41, 66.5]]}, {"timestamp": 1631547099637, "ltp": 1.27, "tv": 19504.47, "trd": [[1.27, 5]], "batb": NaN, "batl": [[0, 1.3, 473.48]]}, {"timestamp": 1631547100571, "ltp": 1.27, "tv": 19504.47, "trd": NaN, "batb": NaN, "batl": [[0, 1.41, 66.5], [1, 1.94, 3.08], [2, 8.8, 7.22]]}, {"timestamp": 1631547103630, "ltp": 1.27, "tv": 19504.47, "trd": NaN, "batb": NaN, "batl": [[0, 1.38, 82.5], [1, 1.41, 72.22], [2, 1.94, 3.08]]}, {"timestamp": 1631547104044, "ltp": 1.27, "tv": 19504.47, "trd": NaN, "batb": NaN, "batl": [[0, 1.41, 66.5], [1, 1.94, 3.08], [2, 8.8, 7.22]]}, {"timestamp": 1631547114254, "ltp": 1.27, "tv": 19504.47, "trd": NaN, "batb": NaN, "batl": [[0, 1.38, 6.25], [1, 1.41, 72.61], [2, 1.94, 3.08]]}, {"timestamp": 1631547114818, "ltp": 1.27, "tv": 19504.47, "trd": NaN, "batb": NaN, "batl": [[0, 1.41, 66.5], [1, 1.94, 3.08], [2, 8.8, 7.22]]}, {"timestamp": 1631547120136, "ltp": 1.37, "tv": 19506.47, "trd": [[1.37, 846.12]], "batb": NaN, "batl": [[0, 1.39, 691.98], [1, 1.41, 66.5], [2, 1.94, 3.08]]}, {"timestamp": 1631547121546, "ltp": 1.37, "tv": 19506.47, "trd": NaN, "batb": [[0, 1.2, 538.74], [1, 1.15, 357.92], [2, 1.14, 168.32]], "batl": [[2, 1.66, 588.41]]}, {"timestamp": 1631547123628, "ltp": 1.35, "tv": 19510.95, "trd": [[1.35, 9964.92]], "batb": NaN, "batl": [[0, 1.35, 132.84], [1, 1.39, 691.98], [2, 1.41, 66.5]]}, {"timestamp": 1631547123837, "ltp": 1.35, "tv": 19510.95, "trd": NaN, "batb": NaN, "batl": [[0, 1.39, 691.98], [1, 1.41, 66.5], [2, 1.66, 588.41]]}, {"timestamp": 1631547126840, "ltp": 1.35, "tv": 19510.95, "trd": NaN, "batb": [[0, 1.26, 96.98], [1, 1.23, 103.63], [2, 1.2, 538.74]], "batl": [[1, 1.41, 73], [2, 1.43, 62]]}, {"timestamp": 1631547132877, "ltp": 1.35, "tv": 19510.95, "trd": NaN, "batb": NaN, "batl": [[0, 1.37, 18.2], [1, 1.39, 691.98], [2, 1.41, 73]]}, {"timestamp": 1631547147068, "ltp": 1.35, "tv": 19510.95, "trd": NaN, "batb": NaN, "batl": [[0, 1.37, 207.2]]}, {"timestamp": 1631547153477, "ltp": 1.35, "tv": 19510.95, "trd": NaN, "batb": [[0, 1.2, 538.74], [1, 1.15, 357.92], [2, 1.14, 168.32]], "batl": [[0, 1.43, 55.5], [1, 1.66, 588.41], [2, 1.94, 3.08]]}, {"timestamp": 1631547156699, "ltp": 1.35, "tv": 19510.95, "trd": NaN, "batb": [[0, 1.23, 103.63], [1, 1.2, 538.74], [2, 1.15, 357.92]], "batl": [[0, 1.41, 66.22], [1, 1.43, 61.21], [2, 1.66, 588.41]]}, {"timestamp": 1631547157122, "ltp": 1.35, "tv": 19510.95, "trd": NaN, "batb": NaN, "batl": [[0, 1.43, 55.5], [1, 1.66, 588.41], [2, 1.94, 3.08]]}, {"timestamp": 1631547163713, "ltp": 1.35, "tv": 19510.95, "trd": NaN, "batb": [[0, 1.26, 102.98], [1, 1.23, 103.63], [2, 1.2, 538.74]], "batl": [[0, 1.41, 6.11], [1, 1.43, 61.35], [2, 1.66, 588.41]]}, {"timestamp": 1631547164081, "ltp": 1.35, "tv": 19510.95, "trd": NaN, "batb": [[0, 1.23, 103.63], [1, 1.2, 538.74], [2, 1.15, 357.92]], "batl": [[0, 1.43, 55.5], [1, 1.66, 588.41], [2, 1.94, 3.08]]}, {"timestamp": 1631547166580, "ltp": 1.35, "tv": 19510.95, "trd": NaN, "batb": [[1, 1.15, 357.92], [2, 1.14, 168.32]], "batl": [[1, 1.94, 3.08], [2, 8.8, 7.22]]}, {"timestamp": 1631547167612, "ltp": 1.35, "tv": 19510.95, "trd": NaN, "batb": [[0, 1.25, 372.85], [1, 1.23, 103.63], [2, 1.15, 357.92]], "batl": [[0, 1.29, 2983.8]]}, {"timestamp": 1631547167878, "ltp": 1.35, "tv": 19510.95, "trd": NaN, "batb": NaN, "batl": [[0, 1.29, 40.07]]}, {"timestamp": 1631547170100, "ltp": 1.35, "tv": 19510.95, "trd": NaN, "batb": NaN, "batl": [[1, 1.56, 685.62], [2, 1.94, 3.08]]}, {"timestamp": 1631547177831, "ltp": 1.35, "tv": 19510.95, "trd": NaN, "batb": NaN, "batl": [[1, 1.37, 74.46], [2, 1.4, 69.23]]}, {"timestamp": 1631547181032, "ltp": 1.35, "tv": 19510.95, "trd": NaN, "batb": NaN, "batl": [[0, 1.29, 152.07]]}, {"timestamp": 1631547184141, "ltp": 1.35, "tv": 19510.95, "trd": NaN, "batb": NaN, "batl": [[0, 1.29, 40.07]]}, {"timestamp": 1631547187217, "ltp": 1.35, "tv": 19510.95, "trd": NaN, "batb": NaN, "batl": [[0, 1.28, 351], [1, 1.29, 40.07], [2, 1.37, 74.46]]}, {"timestamp": 1631547191624, "ltp": 1.35, "tv": 19510.95, "trd": NaN, "batb": [[0, 1.23, 103.63], [1, 1.15, 357.92], [2, 1.14, 805.56]], "batl": [[1, 1.29, 9.07]]}, {"timestamp": 1631547191837, "ltp": 1.35, "tv": 19510.95, "trd": NaN, "batb": [[0, 1.15, 357.92], [1, 1.14, 637.24], [2, 1.13, 197.73]], "batl": [[0, 1.29, 5.88], [1, 1.37, 74.46], [2, 1.4, 69.23]]}, {"timestamp": 1631547195561, "ltp": 1.35, "tv": 19510.95, "trd": NaN, "batb": [[1, 1.13, 197.73], [2, 1.1, 298.27]], "batl": [[0, 1.4, 62.54], [1, 1.56, 685.62], [2, 1.94, 3.08]]}, {"timestamp": 1631547196617, "ltp": 1.35, "tv": 19510.95, "trd": NaN, "batb": NaN, "batl": [[0, 1.27, 20.5], [1, 1.4, 62.54], [2, 1.56, 685.62]]}, {"timestamp": 1631547197141, "ltp": 1.35, "tv": 19510.95, "trd": NaN, "batb": [[0, 1.1, 298.27], [1, 1.09, 280.61], [2, 1.08, 1063.95]], "batl": [[0, 1.4, 62.54], [1, 1.56, 685.62], [2, 1.94, 3.08]]}, {"timestamp": 1631547198560, "ltp": 1.35, "tv": 19510.95, "trd": NaN, "batb": [[0, 1.13, 639.32], [1, 1.1, 298.27], [2, 1.09, 280.61]], "batl": NaN}, {"timestamp": 1631547200352, "ltp": 1.35, "tv": 19510.95, "trd": NaN, "batb": [[0, 1.13, 831.05]], "batl": NaN}, {"timestamp": 1631547202553, "ltp": 1.35, "tv": 19510.95, "trd": NaN, "batb": NaN, "batl": [[0, 1.37, 81.19], [1, 1.4, 68.58], [2, 1.56, 685.62]]}, {"timestamp": 1631547202877, "ltp": 1.35, "tv": 19510.95, "trd": NaN, "batb": NaN, "batl": [[0, 1.4, 62.54], [1, 1.56, 685.62], [2, 1.94, 3.08]]}, {"timestamp": 1631547209693, "ltp": 1.35, "tv": 19510.95, "trd": NaN, "batb": NaN, "batl": [[0, 1.37, 75.46], [1, 1.4, 68.63], [2, 1.56, 685.62]]}, {"timestamp": 1631547209977, "ltp": 1.35, "tv": 19510.95, "trd": NaN, "batb": NaN, "batl": [[0, 1.4, 62.54], [1, 1.56, 685.62], [2, 1.94, 3.08]]}, {"timestamp": 1631547216653, "ltp": 1.35, "tv": 19510.95, "trd": NaN, "batb": NaN, "batl": [[0, 1.37, 73.46], [1, 1.4, 68.28], [2, 1.56, 685.62]]}, {"timestamp": 1631547217290, "ltp": 1.35, "tv": 19510.95, "trd": NaN, "batb": NaN, "batl": [[0, 1.56, 685.62], [1, 1.94, 3.08], [2, 8.8, 7.22]]}, {"timestamp": 1631547218701, "ltp": 1.35, "tv": 19510.95, "trd": NaN, "batb": [[0, 1.1, 298.27], [1, 1.09, 280.61], [2, 1.08, 1063.95]], "batl": [[0, 1.94, 3.08], [1, 8.8, 7.22], [2, 44, 7.22]]}, {"timestamp": 1631547220479, "ltp": 1.35, "tv": 19510.95, "trd": NaN, "batb": [[0, 1.09, 280.61], [1, 1.08, 1063.95], [2, 1.03, 497.12]], "batl": [[0, 1.19, 29.7], [1, 1.21, 1295.01], [2, 1.24, 32.26]]}, {"timestamp": 1631547221683, "ltp": 1.35, "tv": 19510.95, "trd": NaN, "batb": [[1, 1.08, 1900.87]], "batl": NaN}, {"timestamp": 1631547223404, "ltp": 1.35, "tv": 19510.95, "trd": NaN, "batb": [[1, 1.08, 1133.47]], "batl": NaN}, {"timestamp": 1631547225309, "ltp": 1.35, "tv": 19510.95, "trd": NaN, "batb": NaN, "batl": [[0, 1.19, 523.7]]}, {"timestamp": 1631547227558, "ltp": 1.35, "tv": 19510.95, "trd": NaN, "batb": [[0, 1.16, 189.98], [1, 1.15, 217.39], [2, 1.14, 241.92]], "batl": [[0, 1.19, 29.7]]}, {"timestamp": 1631547228554, "ltp": 1.35, "tv": 19510.95, "trd": NaN, "batb": [[1, 1.15, 378.42]], "batl": [[1, 1.21, 1433.25], [2, 1.22, 104]]}, {"timestamp": 1631547228868, "ltp": 1.35, "tv": 19510.95, "trd": NaN, "batb": [[1, 1.15, 217.39]], "batl": NaN}, {"timestamp": 1631547230768, "ltp": 1.35, "tv": 19510.95, "trd": NaN, "batb": NaN, "batl": [[0, 1.18, 1230], [1, 1.19, 29.7], [2, 1.21, 1433.25]]}, {"timestamp": 1631547234548, "ltp": 1.18, "tv": 19562.65, "trd": [[1.18, 68.54]], "batb": NaN, "batl": [[0, 1.18, 1204.15]]}, {"timestamp": 1631547235548, "ltp": 1.18, "tv": 19562.65, "trd": NaN, "batb": [[1, 1.15, 403.42]], "batl": NaN}, {"timestamp": 1631547236280, "ltp": 1.17, "tv": 19564.65, "trd": [[1.17, 2]], "batb": [[1, 1.15, 217.39]], "batl": NaN}, {"timestamp": 1631547239165, "ltp": 1.17, "tv": 19564.65, "trd": NaN, "batb": [[1, 1.15, 377.62]], "batl": NaN}, {"timestamp": 1631547243047, "ltp": 1.18, "tv": 19662.54, "trd": [[1.18, 166.43]], "batb": [[1, 1.15, 217.39]], "batl": [[0, 1.18, 1106.26]]}, {"timestamp": 1631547246573, "ltp": 1.18, "tv": 19662.54, "trd": NaN, "batb": NaN, "batl": [[1, 1.21, 1433.25], [2, 1.22, 104]]}, {"timestamp": 1631547249367, "ltp": 1.18, "tv": 19662.54, "trd": NaN, "batb": NaN, "batl": [[1, 1.19, 31.64], [2, 1.21, 1433.25]]}, {"timestamp": 1631547251892, "ltp": 1.18, "tv": 19662.54, "trd": NaN, "batb": NaN, "batl": [[1, 1.21, 138.24], [2, 1.22, 104]]}, {"timestamp": 1631547253568, "ltp": 1.18, "tv": 19662.54, "trd": NaN, "batb": [[1, 1.15, 392.22]], "batl": [[0, 1.22, 6.26], [1, 1.23, 115], [2, 1.25, 190.02]]}, {"timestamp": 1631547253776, "ltp": 1.18, "tv": 19662.54, "trd": NaN, "batb": NaN, "batl": [[0, 1.23, 108.51], [1, 1.25, 190.02], [2, 1.26, 186.94]]}, {"timestamp": 1631547260675, "ltp": 1.18, "tv": 19662.54, "trd": NaN, "batb": [[0, 1.15, 174.83], [1, 1.08, 1133.47], [2, 1.03, 497.12]], "batl": [[0, 1.22, 6.76], [1, 1.23, 115], [2, 1.39, 17.9]]}, {"timestamp": 1631547262289, "ltp": 1.18, "tv": 19662.54, "trd": NaN, "batb": NaN, "batl": [[0, 1.23, 108.51], [1, 1.39, 17.9], [2, 1.45, 852.3]]}, {"timestamp": 1631547263495, "ltp": 1.18, "tv": 19662.54, "trd": NaN, "batb": [[1, 1.13, 180.73], [2, 1.12, 194.54]], "batl": NaN}, {"timestamp": 1631547264174, "ltp": 1.18, "tv": 19662.54, "trd": NaN, "batb": [[1, 1.08, 1133.47], [2, 1.03, 497.12]], "batl": NaN}, {"timestamp": 1631547268622, "ltp": 1.18, "tv": 19662.54, "trd": NaN, "batb": NaN, "batl": [[0, 1.22, 6.76], [1, 1.23, 115], [2, 1.39, 17.9]]}, {"timestamp": 1631547268782, "ltp": 1.18, "tv": 19662.54, "trd": NaN, "batb": NaN, "batl": [[0, 1.23, 108.51], [1, 1.39, 17.9], [2, 1.45, 852.3]]}, {"timestamp": 1631547270615, "ltp": 1.18, "tv": 19662.54, "trd": NaN, "batb": [[1, 1.13, 194.73], [2, 1.12, 235.04]], "batl": NaN}, {"timestamp": 1631547271624, "ltp": 1.18, "tv": 19662.54, "trd": NaN, "batb": [[1, 1.08, 1133.47], [2, 1.03, 497.12]], "batl": [[0, 1.21, 134.51], [1, 1.22, 122.25], [2, 1.23, 108.5]]}, {"timestamp": 1631547272313, "ltp": 1.18, "tv": 19662.54, "trd": NaN, "batb": NaN, "batl": [[0, 1.23, 108.51], [1, 1.39, 17.9], [2, 1.45, 852.3]]}, {"timestamp": 1631547274691, "ltp": 1.17, "tv": 19662.55, "trd": [[1.17, 2.01]], "batb": NaN, "batl": [[0, 1.23, 108.5]]}, {"timestamp": 1631547275110, "ltp": 1.17, "tv": 19662.55, "trd": NaN, "batb": [[1, 1.08, 296.56]], "batl": [[0, 1.23, 144.24], [1, 1.24, 923.05]]}, {"timestamp": 1631547278624, "ltp": 1.17, "tv": 19662.55, "trd": NaN, "batb": [[1, 1.11, 694.47], [2, 1.08, 296.56]], "batl": NaN}, {"timestamp": 1631547281935, "ltp": 1.17, "tv": 19662.55, "trd": NaN, "batb": [[0, 1.17, 164.97], [1, 1.15, 174.83], [2, 1.11, 694.47]], "batl": [[2, 1.28, 85.18]]}, {"timestamp": 1631547284142, "ltp": 1.17, "tv": 19662.55, "trd": NaN, "batb": [[2, 1.08, 296.56]], "batl": NaN}, {"timestamp": 1631547285133, "ltp": 1.17, "tv": 19662.55, "trd": NaN, "batb": NaN, "batl": [[0, 1.22, 269], [1, 1.23, 144.24], [2, 1.24, 923.05]]}, {"timestamp": 1631547293448, "ltp": 1.17, "tv": 19662.55, "trd": NaN, "batb": NaN, "batl": [[0, 1.22, 551.23]]}, {"timestamp": 1631547295235, "ltp": 1.17, "tv": 19662.55, "trd": NaN, "batb": [[0, 1.2, 270.29], [1, 1.17, 164.97], [2, 1.15, 174.83]], "batl": NaN}, {"timestamp": 1631547297671, "ltp": 1.17, "tv": 19662.55, "trd": NaN, "batb": [[0, 1.15, 174.83], [1, 1.05, 477.27], [2, 1.03, 497.12]], "batl": [[0, 1.22, 269], [1, 1.28, 85.18], [2, 1.3, 95.5]]}, {"timestamp": 1631547298566, "ltp": 1.17, "tv": 19662.55, "trd": NaN, "batb": NaN, "batl": [[0, 1.3, 88.85], [1, 1.56, 73.64], [2, 1.94, 3.08]]}, {"timestamp": 1631547300582, "ltp": 1.17, "tv": 19662.55, "trd": NaN, "batb": [[0, 1.16, 148.53], [1, 1.15, 174.83], [2, 1.05, 477.27]], "batl": NaN}, {"timestamp": 1631547301685, "ltp": 1.17, "tv": 19662.55, "trd": NaN, "batb": [[0, 1.15, 174.83], [1, 1.05, 477.27], [2, 1.03, 497.12]], "batl": [[0, 1.28, 5.84], [1, 1.3, 95.4], [2, 1.56, 73.64]]}, {"timestamp": 1631547302242, "ltp": 1.17, "tv": 19662.55, "trd": NaN, "batb": NaN, "batl": [[0, 1.3, 88.85], [1, 1.56, 73.64], [2, 1.94, 3.08]]}, {"timestamp": 1631547304551, "ltp": 1.17, "tv": 19662.55, "trd": NaN, "batb": [[0, 1.17, 145.97], [1, 1.15, 174.83], [2, 1.05, 477.27]], "batl": NaN}, {"timestamp": 1631547305453, "ltp": 1.17, "tv": 19662.55, "trd": NaN, "batb": [[0, 1.15, 174.83], [1, 1.05, 477.27], [2, 1.03, 497.12]], "batl": [[0, 1.28, 95.34], [1, 1.3, 88.85], [2, 1.56, 73.64]]}, {"timestamp": 1631547305767, "ltp": 1.17, "tv": 19662.55, "trd": NaN, "batb": NaN, "batl": [[0, 1.3, 88.85], [1, 1.56, 73.64], [2, 1.94, 3.08]]}, {"timestamp": 1631547308681, "ltp": 1.17, "tv": 19662.55, "trd": NaN, "batb": NaN, "batl": [[0, 1.28, 6.84], [1, 1.3, 94.9], [2, 1.56, 73.64]]}, {"timestamp": 1631547309260, "ltp": 1.17, "tv": 19662.55, "trd": NaN, "batb": NaN, "batl": [[0, 1.3, 88.85], [1, 1.56, 73.64], [2, 1.94, 3.08]]}, {"timestamp": 1631547311470, "ltp": 1.17, "tv": 19662.55, "trd": NaN, "batb": [[0, 1.17, 138.97], [1, 1.15, 174.83], [2, 1.05, 477.27]], "batl": NaN}, {"timestamp": 1631547312467, "ltp": 1.17, "tv": 19662.55, "trd": NaN, "batb": [[0, 1.15, 174.83], [1, 1.05, 477.27], [2, 1.03, 497.12]], "batl": [[0, 1.28, 83.34], [1, 1.3, 88.85], [2, 1.56, 73.64]]}, {"timestamp": 1631547312782, "ltp": 1.17, "tv": 19662.55, "trd": NaN, "batb": NaN, "batl": [[0, 1.3, 88.85], [1, 1.56, 73.64], [2, 1.94, 3.08]]}, {"timestamp": 1631547314459, "ltp": 1.17, "tv": 19662.55, "trd": NaN, "batb": [[1, 1.03, 497.12], [2, 1.01, 577.96]], "batl": [[0, 1.2, 23.15], [1, 1.21, 918.22], [2, 1.3, 88.85]]}, {"timestamp": 1631547317061, "ltp": 1.17, "tv": 19662.55, "trd": NaN, "batb": [[1, 1.09, 790.61], [2, 1.03, 497.12]], "batl": NaN}, {"timestamp": 1631547318265, "ltp": 1.17, "tv": 19662.55, "trd": NaN, "batb": NaN, "batl": [[0, 1.2, 97.15]]}, {"timestamp": 1631547321561, "ltp": 1.17, "tv": 19662.55, "trd": NaN, "batb": [[0, 1.16, 379.33], [1, 1.15, 460], [2, 1.14, 467.66]], "batl": [[0, 1.2, 23.15], [2, 1.25, 106.84]]}, {"timestamp": 1631547324788, "ltp": 1.17, "tv": 19662.55, "trd": NaN, "batb": NaN, "batl": [[0, 1.19, 247], [1, 1.2, 23.15], [2, 1.21, 918.22]]}, {"timestamp": 1631547333577, "ltp": 1.17, "tv": 19662.55, "trd": NaN, "batb": NaN, "batl": [[1, 1.2, 5.63], [2, 1.24, 116.21]]}, {"timestamp": 1631547334577, "ltp": 1.17, "tv": 19662.55, "trd": NaN, "batb": NaN, "batl": [[0, 1.2, 5.63], [1, 1.25, 6.42], [2, 1.26, 252.95]]}, {"timestamp": 1631547334788, "ltp": 1.17, "tv": 19662.55, "trd": NaN, "batb": NaN, "batl": [[1, 1.26, 252.95], [2, 1.27, 286.04]]}, {"timestamp": 1631547338676, "ltp": 1.17, "tv": 19662.55, "trd": NaN, "batb": NaN, "batl": [[1, 1.26, 89.75], [2, 1.27, 103.5]]}, {"timestamp": 1631547339575, "ltp": 1.17, "tv": 19662.55, "trd": NaN, "batb": NaN, "batl": [[2, 1.56, 73.64]]}, {"timestamp": 1631547341606, "ltp": 1.17, "tv": 19662.55, "trd": NaN, "batb": NaN, "batl": [[0, 1.18, 51.45], [1, 1.24, 106.21], [2, 1.25, 98.94]]}, {"timestamp": 1631547341804, "ltp": 1.17, "tv": 19662.55, "trd": NaN, "batb": NaN, "batl": [[1, 1.24, 6.23], [2, 1.26, 89.75]]}, {"timestamp": 1631547348401, "ltp": 1.17, "tv": 19662.55, "trd": NaN, "batb": [[1, 1.15, 651.03], [2, 1.14, 689.28]], "batl": [[0, 1.18, 128.45], [1, 1.23, 200.45], [2, 1.24, 237.52]]}, {"timestamp": 1631547350415, "ltp": 1.17, "tv": 19662.55, "trd": NaN, "batb": NaN, "batl": [[1, 1.2, 129.36], [2, 1.21, 132.81]]}, {"timestamp": 1631547351699, "ltp": 1.17, "tv": 19662.55, "trd": NaN, "batb": [[0, 1.15, 191.03], [1, 1.14, 420.94], [2, 1.13, 373.98]], "batl": [[0, 1.18, 5.75], [1, 1.21, 132.81], [2, 1.23, 200.45]]}, {"timestamp": 1631547352007, "ltp": 1.17, "tv": 19662.55, "trd": NaN, "batb": NaN, "batl": [[1, 1.21, 126.5]]}, {"timestamp": 1631547355707, "ltp": 1.17, "tv": 19662.55, "trd": NaN, "batb": [[0, 1.15, 367.86]], "batl": NaN}, {"timestamp": 1631547357524, "ltp": 1.17, "tv": 19662.55, "trd": NaN, "batb": NaN, "batl": [[1, 1.19, 19.5], [2, 1.21, 126.5]]}, {"timestamp": 1631547358715, "ltp": 1.17, "tv": 19662.55, "trd": NaN, "batb": NaN, "batl": [[1, 1.21, 133], [2, 1.23, 200.45]]}, {"timestamp": 1631547359609, "ltp": 1.15, "tv": 20128.51, "trd": [[1.15, 499.12]], "batb": [[0, 1.15, 134.88]], "batl": [[1, 1.21, 126.5]]}, {"timestamp": 1631547365523, "ltp": 1.15, "tv": 20128.51, "trd": NaN, "batb": NaN, "batl": [[1, 1.2, 132.16], [2, 1.21, 126.5]]}, {"timestamp": 1631547366146, "ltp": 1.15, "tv": 20128.51, "trd": NaN, "batb": NaN, "batl": [[1, 1.21, 126.5], [2, 1.24, 6.23]]}, {"timestamp": 1631547368626, "ltp": 1.15, "tv": 20128.51, "trd": NaN, "batb": [[1, 1.14, 1184.04]], "batl": [[0, 1.16, 30.09], [1, 1.17, 1147.4], [2, 1.18, 103.46]]}, {"timestamp": 1631547371849, "ltp": 1.16, "tv": 20135.73, "trd": [[1.16, 7.22]], "batb": NaN, "batl": [[0, 1.16, 26.48]]}, {"timestamp": 1631547374938, "ltp": 1.16, "tv": 20135.73, "trd": NaN, "batb": [[1, 1.14, 1410.31], [2, 1.13, 595.02]], "batl": [[2, 1.18, 244.46]]}, {"timestamp": 1631547376726, "ltp": 1.16, "tv": 20135.73, "trd": NaN, "batb": NaN, "batl": [[0, 1.16, 205.48]]}, {"timestamp": 1631547379749, "ltp": 1.16, "tv": 20135.73, "trd": NaN, "batb": NaN, "batl": [[2, 1.18, 174.9]]}, {"timestamp": 1631547382054, "ltp": 1.16, "tv": 20135.73, "trd": NaN, "batb": NaN, "batl": [[0, 1.16, 179]]}, {"timestamp": 1631547383461, "ltp": 1.16, "tv": 20135.73, "trd": NaN, "batb": [[0, 1.14, 425.59], [1, 1.13, 221.04], [2, 1.12, 359.12]], "batl": [[1, 1.17, 5.62], [2, 1.18, 141]]}, {"timestamp": 1631547384659, "ltp": 1.16, "tv": 20135.73, "trd": NaN, "batb": NaN, "batl": [[0, 1.17, 5.62], [1, 1.18, 134.25], [2, 1.2, 226.89]]}, {"timestamp": 1631547387487, "ltp": 1.16, "tv": 20135.73, "trd": NaN, "batb": [[0, 1.15, 178.43], [1, 1.14, 425.59], [2, 1.13, 221.04]], "batl": [[0, 1.17, 130.12]]}, {"timestamp": 1631547388578, "ltp": 1.16, "tv": 20135.73, "trd": NaN, "batb": [[0, 1.14, 425.59], [1, 1.13, 221.04], [2, 1.12, 359.12]], "batl": [[0, 1.17, 5.62]]}, {"timestamp": 1631547394675, "ltp": 1.16, "tv": 20135.73, "trd": NaN, "batb": [[0, 1.14, 199.32], [1, 1.06, 969.79], [2, 1.03, 497.12]], "batl": [[0, 1.16, 265], [1, 1.17, 149.12], [2, 1.18, 134.25]]}, {"timestamp": 1631547395613, "ltp": 1.16, "tv": 20135.73, "trd": NaN, "batb": NaN, "batl": [[0, 1.18, 140.5], [1, 1.39, 17.9], [2, 1.56, 73.64]]}, {"timestamp": 1631547395875, "ltp": 1.16, "tv": 20135.73, "trd": NaN, "batb": NaN, "batl": [[0, 1.18, 134.25]]}, {"timestamp": 1631547401710, "ltp": 1.16, "tv": 20135.73, "trd": NaN, "batb": [[0, 1.15, 184.03], [1, 1.14, 199.32], [2, 1.06, 969.79]], "batl": [[0, 1.17, 6.03], [1, 1.18, 134.25], [2, 1.39, 17.9]]}, {"timestamp": 1631547402711, "ltp": 1.16, "tv": 20135.73, "trd": NaN, "batb": [[0, 1.14, 199.32], [1, 1.03, 497.12], [2, 1.01, 577.96]], "batl": [[0, 1.17, 145.5], [1, 1.18, 141]]}, {"timestamp": 1631547403596, "ltp": 1.16, "tv": 20135.73, "trd": NaN, "batb": [[0, 1.15, 173.92], [1, 1.14, 199.32], [2, 1.03, 497.12]], "batl": [[0, 1.18, 160.84], [1, 1.39, 17.9], [2, 1.56, 73.64]]}, {"timestamp": 1631547404015, "ltp": 1.16, "tv": 20135.73, "trd": NaN, "batb": [[0, 1.15, 34.78]], "batl": NaN}, {"timestamp": 1631547405790, "ltp": 1.16, "tv": 20135.73, "trd": NaN, "batb": [[2, 1.08, 836.91]], "batl": NaN}, {"timestamp": 1631547410809, "ltp": 1.16, "tv": 20135.73, "trd": NaN, "batb": [[0, 1.15, 194.41], [1, 1.14, 411.12], [2, 1.13, 294.45]], "batl": [[1, 1.2, 120.86], [2, 1.21, 125.43]]}, {"timestamp": 1631547414012, "ltp": 1.16, "tv": 20135.73, "trd": NaN, "batb": NaN, "batl": [[0, 1.18, 240.84]]}, {"timestamp": 1631547422625, "ltp": 1.16, "tv": 20135.73, "trd": NaN, "batb": [[0, 1.14, 411.12], [1, 1.13, 294.45], [2, 1.12, 323.07]], "batl": [[0, 1.2, 6.58], [1, 1.21, 5.93], [2, 1.22, 6.75]]}, {"timestamp": 1631547422936, "ltp": 1.16, "tv": 20135.73, "trd": NaN, "batb": NaN, "batl": [[0, 1.24, 187.08], [1, 1.25, 194.07], [2, 1.26, 187.59]]}, {"timestamp": 1631547425712, "ltp": 1.16, "tv": 20135.73, "trd": NaN, "batb": NaN, "batl": [[0, 1.17, 258], [1, 1.24, 187.08], [2, 1.25, 194.07]]}, {"timestamp": 1631547426649, "ltp": 1.16, "tv": 20135.73, "trd": NaN, "batb": NaN, "batl": [[0, 1.22, 126.25]]}, {"timestamp": 1631547429530, "ltp": 1.16, "tv": 20135.73, "trd": NaN, "batb": [[0, 1.15, 146.23], [1, 1.14, 411.12], [2, 1.13, 294.45]], "batl": [[0, 1.2, 136.71], [1, 1.21, 115.5], [2, 1.22, 126.25]]}, {"timestamp": 1631547430150, "ltp": 1.16, "tv": 20135.73, "trd": NaN, "batb": [[0, 1.14, 411.12], [1, 1.13, 294.45], [2, 1.12, 323.07]], "batl": [[0, 1.22, 126.25], [1, 1.24, 187.08], [2, 1.25, 194.07]]}, {"timestamp": 1631547440653, "ltp": 1.16, "tv": 20135.73, "trd": NaN, "batb": [[0, 1.15, 155.23], [1, 1.14, 411.12], [2, 1.13, 294.45]], "batl": [[0, 1.2, 122.98], [1, 1.21, 105.5], [2, 1.22, 126.25]]}, {"timestamp": 1631547441236, "ltp": 1.16, "tv": 20135.73, "trd": NaN, "batb": [[0, 1.14, 411.12], [1, 1.13, 294.45], [2, 1.12, 323.07]], "batl": [[0, 1.22, 126.25], [1, 1.24, 187.08], [2, 1.25, 194.07]]}, {"timestamp": 1631547442274, "ltp": 1.16, "tv": 20135.73, "trd": NaN, "batb": NaN, "batl": [[0, 1.39, 17.9], [1, 1.56, 73.64], [2, 1.94, 3.08]]}, {"timestamp": 1631547444696, "ltp": 1.16, "tv": 20135.73, "trd": NaN, "batb": NaN, "batl": [[0, 1.21, 6.31], [1, 1.22, 6.75], [2, 1.39, 17.9]]}, {"timestamp": 1631547445478, "ltp": 1.16, "tv": 20135.73, "trd": NaN, "batb": [[0, 1.15, 24.32], [1, 1.14, 1254.43], [2, 1.13, 294.45]], "batl": [[0, 1.16, 22.16], [1, 1.17, 1049.96], [2, 1.18, 54.87]]}, {"timestamp": 1631547452059, "ltp": 1.16, "tv": 20135.73, "trd": NaN, "batb": [[1, 1.14, 1485.37], [2, 1.13, 576.88]], "batl": NaN}, {"timestamp": 1631547456997, "ltp": 1.16, "tv": 20135.73, "trd": NaN, "batb": NaN, "batl": [[2, 1.21, 198.13]]}, {"timestamp": 1631547466681, "ltp": 1.16, "tv": 20135.73, "trd": NaN, "batb": NaN, "batl": [[0, 1.16, 227.16]]}, {"timestamp": 1631547468775, "ltp": 1.16, "tv": 20242.31, "trd": [[1.16, 113.8]], "batb": NaN, "batl": [[0, 1.16, 173.87]]}, {"timestamp": 1631547479023, "ltp": 1.16, "tv": 20242.31, "trd": NaN, "batb": [[0, 1.14, 1485.37], [1, 1.13, 576.88], [2, 1.12, 597.14]], "batl": NaN}, {"timestamp": 1631547481945, "ltp": 1.16, "tv": 20242.31, "trd": NaN, "batb": NaN, "batl": [[1, 1.17, 1091.13]]}, {"timestamp": 1631547489916, "ltp": 1.15, "tv": 20255.65, "trd": [[1.15, 512.46]], "batb": NaN, "batl": NaN}, {"timestamp": 1631547500153, "ltp": 1.15, "tv": 20255.65, "trd": NaN, "batb": NaN, "batl": [[1, 1.17, 1049.96]]}, {"timestamp": 1631547536700, "ltp": 1.15, "tv": 20255.65, "trd": NaN, "batb": [[0, 1.15, 158.43], [1, 1.14, 1485.37], [2, 1.13, 576.88]], "batl": [[2, 1.18, 154]]}, {"timestamp": 1631547555515, "ltp": 1.15, "tv": 20255.65, "trd": NaN, "batb": [[1, 1.14, 642.06]], "batl": [[1, 1.17, 29.12]]}, {"timestamp": 1631547556646, "ltp": 1.15, "tv": 20255.65, "trd": NaN, "batb": [[0, 1.14, 430.25], [1, 1.13, 282.43], [2, 1.12, 274.07]], "batl": [[0, 1.18, 147.75], [1, 1.21, 198.13], [2, 1.22, 210]]}, {"timestamp": 1631547562491, "ltp": 1.15, "tv": 20255.65, "trd": NaN, "batb": [[0, 1.15, 165.63], [1, 1.14, 430.25], [2, 1.13, 282.43]], "batl": [[0, 1.17, 152.53], [1, 1.18, 147.75], [2, 1.21, 198.13]]}, {"timestamp": 1631547563486, "ltp": 1.15, "tv": 20255.65, "trd": NaN, "batb": [[0, 1.14, 430.25], [1, 1.13, 282.43], [2, 1.12, 274.07]], "batl": [[0, 1.18, 154.5], [1, 1.21, 198.13], [2, 1.22, 210]]}, {"timestamp": 1631547564272, "ltp": 1.15, "tv": 20255.65, "trd": NaN, "batb": NaN, "batl": [[0, 1.17, 90], [1, 1.18, 147.75], [2, 1.21, 198.13]]}, {"timestamp": 1631547566669, "ltp": 1.15, "tv": 20255.65, "trd": NaN, "batb": NaN, "batl": [[0, 1.18, 147.75], [1, 1.21, 198.13], [2, 1.22, 210]]}, {"timestamp": 1631547574886, "ltp": 1.15, "tv": 20255.65, "trd": NaN, "batb": NaN, "batl": [[0, 1.39, 17.9], [1, 1.56, 73.64], [2, 1.94, 3.08]]}, {"timestamp": 1631547576677, "ltp": 1.15, "tv": 20255.65, "trd": NaN, "batb": NaN, "batl": [[0, 1.17, 6.5], [1, 1.39, 17.9], [2, 1.56, 73.64]]}, {"timestamp": 1631547577668, "ltp": 1.15, "tv": 20255.65, "trd": NaN, "batb": NaN, "batl": [[0, 1.15, 32.81], [1, 1.16, 29.44], [2, 1.39, 17.9]]}, {"timestamp": 1631547583710, "ltp": 1.15, "tv": 20255.65, "trd": NaN, "batb": NaN, "batl": [[0, 1.15, 359.38], [1, 1.16, 386.7]]}, {"timestamp": 1631547584282, "ltp": 1.15, "tv": 20255.65, "trd": NaN, "batb": [[1, 1.13, 463.16]], "batl": [[2, 1.17, 174.53]]}, {"timestamp": 1631547584909, "ltp": 1.15, "tv": 20255.65, "trd": NaN, "batb": [[1, 1.13, 709.54], [2, 1.12, 609.58]], "batl": NaN}, {"timestamp": 1631547588306, "ltp": 1.15, "tv": 20255.65, "trd": NaN, "batb": NaN, "batl": [[0, 1.15, 479.38]]}, {"timestamp": 1631547591486, "ltp": 1.15, "tv": 20255.65, "trd": NaN, "batb": [[0, 1.13, 427.11], [1, 1.12, 335.51], [2, 1.11, 370.21]], "batl": [[0, 1.15, 120], [1, 1.16, 5.72]]}, {"timestamp": 1631547592630, "ltp": 1.15, "tv": 20255.65, "trd": NaN, "batb": NaN, "batl": [[0, 1.16, 5.72], [1, 1.17, 168.5], [2, 1.2, 223.68]]}, {"timestamp": 1631547594619, "ltp": 1.15, "tv": 20255.65, "trd": NaN, "batb": [[0, 1.13, 180.73], [1, 1.01, 577.96], [2, 1.11, 0]], "batl": [[0, 1.16, 169.44]]}, {"timestamp": 1631547595090, "ltp": 1.15, "tv": 20255.65, "trd": NaN, "batb": NaN, "batl": [[0, 1.16, 5.72], [1, 1.2, 223.68], [2, 1.21, 205.94]]}, {"timestamp": 1631547597634, "ltp": 1.15, "tv": 20255.65, "trd": NaN, "batb": NaN, "batl": [[0, 1.16, 647.91]]}, {"timestamp": 1631547604612, "ltp": 1.15, "tv": 20255.65, "trd": NaN, "batb": [[0, 1.14, 171.32], [1, 1.13, 400.23], [2, 1.12, 226.71]], "batl": [[1, 1.17, 156.53], [2, 1.2, 439.35]]}, {"timestamp": 1631547607331, "ltp": 1.15, "tv": 20255.65, "trd": NaN, "batb": NaN, "batl": [[0, 1.15, 266], [1, 1.16, 804.13], [2, 1.17, 156.53]]}, {"timestamp": 1631547612639, "ltp": 1.15, "tv": 20255.65, "trd": NaN, "batb": NaN, "batl": [[1, 1.16, 161.94]]}, {"timestamp": 1631547613625, "ltp": 1.15, "tv": 20255.65, "trd": NaN, "batb": [[0, 1.13, 400.23], [1, 1.12, 226.71], [2, 1.11, 275.38]], "batl": [[0, 1.17, 156.53], [1, 1.2, 215.67], [2, 1.21, 205.6]]}, {"timestamp": 1631547613836, "ltp": 1.15, "tv": 20255.65, "trd": NaN, "batb": NaN, "batl": [[0, 1.17, 150.5]]}, {"timestamp": 1631547618693, "ltp": 1.15, "tv": 20255.65, "trd": NaN, "batb": NaN, "batl": [[0, 1.39, 17.9], [1, 1.56, 73.64], [2, 1.94, 3.08]]}, {"timestamp": 1631547619679, "ltp": 1.15, "tv": 20255.65, "trd": NaN, "batb": [[0, 1.14, 157.32], [1, 1.13, 400.23], [2, 1.12, 226.71]], "batl": [[0, 1.16, 6.22], [1, 1.39, 17.9], [2, 1.56, 73.64]]}, {"timestamp": 1631547620617, "ltp": 1.15, "tv": 20255.65, "trd": NaN, "batb": [[0, 1.13, 400.23], [1, 1.12, 226.71], [2, 1.11, 275.38]], "batl": [[0, 1.39, 17.9], [1, 1.56, 73.64], [2, 1.94, 3.08]]}, {"timestamp": 1631547621292, "ltp": 1.15, "tv": 20255.65, "trd": NaN, "batb": NaN, "batl": [[0, 1.15, 1085.78], [1, 1.39, 17.9], [2, 1.56, 73.64]]}, {"timestamp": 1631547624232, "ltp": 1.15, "tv": 20255.65, "trd": NaN, "batb": NaN, "batl": [[1, 1.38, 987.41], [2, 1.39, 17.9]]}, {"timestamp": 1631547627932, "ltp": 1.15, "tv": 20255.65, "trd": NaN, "batb": [[1, 1.12, 443.25]], "batl": [[1, 1.16, 153.19], [2, 1.17, 165]]}, {"timestamp": 1631547631214, "ltp": 1.15, "tv": 20255.65, "trd": NaN, "batb": NaN, "batl": [[0, 1.15, 1158.78]]}, {"timestamp": 1631547635707, "ltp": 1.15, "tv": 20255.65, "trd": NaN, "batb": [[0, 1.12, 216.54], [1, 1.05, 1085.43], [2, 1.01, 577.96]], "batl": [[0, 1.15, 78.7], [1, 1.17, 158.5], [2, 1.38, 987.41]]}, {"timestamp": 1631547636333, "ltp": 1.15, "tv": 20255.65, "trd": NaN, "batb": NaN, "batl": [[0, 1.15, 5.7]]}, {"timestamp": 1631547638624, "ltp": 1.15, "tv": 20255.65, "trd": NaN, "batb": NaN, "batl": [[1, 1.16, 150.44], [2, 1.17, 158.5]]}, {"timestamp": 1631547639300, "ltp": 1.15, "tv": 20255.65, "trd": NaN, "batb": NaN, "batl": [[1, 1.17, 158.5], [2, 1.38, 987.41]]}, {"timestamp": 1631547642537, "ltp": 1.15, "tv": 20255.65, "trd": NaN, "batb": [[0, 1.13, 190.73], [1, 1.12, 216.54], [2, 1.05, 1085.43]], "batl": [[1, 1.17, 165]]}, {"timestamp": 1631547642857, "ltp": 1.15, "tv": 20255.65, "trd": NaN, "batb": [[0, 1.12, 216.54], [1, 1.05, 1085.43], [2, 1.01, 577.96]], "batl": [[1, 1.17, 158.5]]}, {"timestamp": 1631547644307, "ltp": 1.15, "tv": 20255.65, "trd": NaN, "batb": NaN, "batl": [[0, 1.15, 76.7]]}, {"timestamp": 1631547647325, "ltp": 1.15, "tv": 20255.65, "trd": NaN, "batb": NaN, "batl": [[0, 1.15, 5.7]]}, {"timestamp": 1631547648526, "ltp": 1.15, "tv": 20255.65, "trd": NaN, "batb": NaN, "batl": [[0, 1.17, 158.5], [1, 1.38, 987.41], [2, 1.39, 17.9]]}, {"timestamp": 1631547649513, "ltp": 1.15, "tv": 20255.65, "trd": NaN, "batb": [[0, 1.13, 203.73], [1, 1.12, 216.54], [2, 1.05, 1085.43]], "batl": [[0, 1.17, 165]]}, {"timestamp": 1631547650553, "ltp": 1.15, "tv": 20255.65, "trd": NaN, "batb": [[0, 1.12, 216.54], [1, 1.05, 1085.43], [2, 1.01, 577.96]], "batl": [[0, 1.14, 150], [1, 1.17, 158.5], [2, 1.38, 987.41]]}, {"timestamp": 1631547650821, "ltp": 1.15, "tv": 20255.65, "trd": NaN, "batb": NaN, "batl": [[0, 1.17, 158.5], [1, 1.38, 987.41], [2, 1.39, 17.9]]}, {"timestamp": 1631547652652, "ltp": 1.15, "tv": 20255.65, "trd": NaN, "batb": NaN, "batl": [[0, 1.16, 166.44], [1, 1.17, 158.5], [2, 1.38, 987.41]]}, {"timestamp": 1631547653362, "ltp": 1.15, "tv": 20255.65, "trd": NaN, "batb": [[0, 1.13, 210.73], [1, 1.12, 216.54], [2, 1.05, 1085.43]], "batl": [[0, 1.17, 158.5], [1, 1.38, 987.41], [2, 1.39, 17.9]]}, {"timestamp": 1631547653742, "ltp": 1.15, "tv": 20255.65, "trd": NaN, "batb": [[0, 1.12, 216.54], [1, 1.05, 1085.43], [2, 1.01, 577.96]], "batl": NaN}, {"timestamp": 1631547656666, "ltp": 1.15, "tv": 20255.65, "trd": NaN, "batb": NaN, "batl": [[0, 1.17, 165]]}, {"timestamp": 1631547657426, "ltp": 1.15, "tv": 20255.65, "trd": NaN, "batb": NaN, "batl": [[0, 1.38, 987.41], [1, 1.39, 17.9], [2, 1.56, 73.64]]}, {"timestamp": 1631547658359, "ltp": 1.15, "tv": 20255.65, "trd": NaN, "batb": [[1, 1.01, 577.96], [2, 1.01, 0]], "batl": NaN}, {"timestamp": 1631547659705, "ltp": 1.15, "tv": 20255.65, "trd": NaN, "batb": [[1, 1.11, 783.29], [2, 1.01, 577.96]], "batl": [[0, 1.13, 39.07], [1, 1.38, 987.41], [2, 1.39, 17.9]]}, {"timestamp": 1631547660087, "ltp": 1.15, "tv": 20255.65, "trd": NaN, "batb": NaN, "batl": [[1, 1.14, 31], [2, 1.38, 987.41]]}, {"timestamp": 1631547662534, "ltp": 1.15, "tv": 20255.65, "trd": NaN, "batb": [[2, 1.04, 1281.74]], "batl": NaN}, {"timestamp": 1631547667130, "ltp": 1.15, "tv": 20255.65, "trd": NaN, "batb": [[1, 1.11, 1350.81], [2, 1.1, 294.53]], "batl": [[2, 1.15, 186]]}, {"timestamp": 1631547670532, "ltp": 1.15, "tv": 20255.65, "trd": NaN, "batb": NaN, "batl": [[0, 1.13, 239.07]]}, {"timestamp": 1631547671048, "ltp": 1.12, "tv": 20259.65, "trd": [[1.12, 4]], "batb": [[0, 1.12, 214.54]], "batl": NaN}, {"timestamp": 1631547685156, "ltp": 1.12, "tv": 20259.65, "trd": NaN, "batb": [[0, 1.11, 303.93], [1, 1.1, 294.53], [2, 1.09, 388.63]], "batl": [[0, 1.13, 200], [1, 1.14, 5.75]]}, {"timestamp": 1631547687563, "ltp": 1.12, "tv": 20259.65, "trd": NaN, "batb": NaN, "batl": [[0, 1.15, 186], [1, 1.16, 156.44], [2, 1.18, 215.96]]}, {"timestamp": 1631547688175, "ltp": 1.12, "tv": 20259.65, "trd": NaN, "batb": NaN, "batl": [[0, 1.16, 149.72], [1, 1.18, 215.96], [2, 1.19, 212.42]]}, {"timestamp": 1631547689485, "ltp": 1.12, "tv": 20259.65, "trd": NaN, "batb": [[0, 1.04, 1281.74], [1, 1.01, 577.96], [2, 1.09, 0]], "batl": [[0, 1.18, 215.96], [1, 1.19, 212.42], [2, 1.2, 228.1]]}, {"timestamp": 1631547691672, "ltp": 1.12, "tv": 20259.65, "trd": NaN, "batb": [[0, 1.01, 577.96], [1, 1.01, 0]], "batl": NaN}, {"timestamp": 1631547692650, "ltp": 1.12, "tv": 20259.65, "trd": NaN, "batb": NaN, "batl": [[0, 1.14, 744.38], [1, 1.18, 215.96], [2, 1.19, 212.42]]}, {"timestamp": 1631547694948, "ltp": 1.12, "tv": 20259.65, "trd": NaN, "batb": [[0, 1.05, 1085.43], [1, 1.01, 577.96]], "batl": NaN}, {"timestamp": 1631547698682, "ltp": 1.12, "tv": 20259.65, "trd": NaN, "batb": NaN, "batl": [[1, 1.15, 170.3], [2, 1.16, 160.22]]}, {"timestamp": 1631547701354, "ltp": 1.12, "tv": 20259.65, "trd": NaN, "batb": [[0, 1.06, 76.21], [1, 1.05, 1085.43], [2, 1.01, 577.96]], "batl": NaN}, {"timestamp": 1631547701872, "ltp": 1.12, "tv": 20259.65, "trd": NaN, "batb": NaN, "batl": [[0, 1.14, 837.38]]}, {"timestamp": 1631547703273, "ltp": 1.12, "tv": 20259.65, "trd": NaN, "batb": [[0, 1.05, 1085.43], [1, 1.01, 577.96], [2, 1.01, 0]], "batl": [[0, 1.14, 93], [1, 1.16, 160.22], [2, 1.38, 987.41]]}, {"timestamp": 1631547704469, "ltp": 1.12, "tv": 20259.65, "trd": NaN, "batb": NaN, "batl": [[0, 1.16, 160.22], [1, 1.38, 987.41], [2, 1.39, 17.9]]}, {"timestamp": 1631547707484, "ltp": 1.12, "tv": 20259.65, "trd": NaN, "batb": NaN, "batl": [[0, 1.13, 6.72], [1, 1.16, 160.22], [2, 1.38, 987.41]]}, {"timestamp": 1631547708597, "ltp": 1.12, "tv": 20259.65, "trd": NaN, "batb": NaN, "batl": [[1, 1.15, 688.19], [2, 1.16, 160.22]]}, {"timestamp": 1631547709088, "ltp": 1.12, "tv": 20259.65, "trd": NaN, "batb": NaN, "batl": [[1, 1.16, 160.22], [2, 1.38, 987.41]]}, {"timestamp": 1631547710707, "ltp": 1.12, "tv": 20259.65, "trd": NaN, "batb": NaN, "batl": [[1, 1.15, 162.3], [2, 1.16, 160.22]]}, {"timestamp": 1631547711005, "ltp": 1.12, "tv": 20259.65, "trd": NaN, "batb": NaN, "batl": [[1, 1.16, 160.22], [2, 1.38, 987.41]]}, {"timestamp": 1631547713613, "ltp": 1.12, "tv": 20259.65, "trd": NaN, "batb": NaN, "batl": [[2, 1.17, 161.5]]}, {"timestamp": 1631547714601, "ltp": 1.12, "tv": 20259.65, "trd": NaN, "batb": NaN, "batl": [[2, 1.38, 987.41]]}, {"timestamp": 1631547721618, "ltp": 1.12, "tv": 20259.65, "trd": NaN, "batb": [[0, 1.01, 577.96], [1, 1.01, 0]], "batl": [[1, 1.15, 166.5], [2, 1.16, 160.22]]}, {"timestamp": 1631547721722, "ltp": 1.12, "tv": 20259.65, "trd": NaN, "batb": NaN, "batl": [[1, 1.16, 160.22], [2, 1.38, 987.41]]}, {"timestamp": 1631547723398, "ltp": 1.13, "tv": 20266.37, "trd": [[1.13, 6.72]], "batb": [[0, 1.14, 28.7], [1, 1.13, 845.06], [2, 1.01, 577.96]], "batl": [[0, 1.15, 21.13], [1, 1.16, 1408.21]]}, {"timestamp": 1631547725310, "ltp": 1.14, "tv": 20269.79, "trd": [[1.14, 3.42]], "batb": [[0, 1.14, 26.99], [2, 1.06, 969.79]], "batl": NaN}, {"timestamp": 1631547728189, "ltp": 1.14, "tv": 20269.79, "trd": NaN, "batb": [[0, 1.14, 355.26], [1, 1.13, 1213.41]], "batl": NaN}, {"timestamp": 1631547730422, "ltp": 1.14, "tv": 20269.79, "trd": NaN, "batb": [[1, 1.13, 1478.09], [2, 1.12, 316.57]], "batl": [[0, 1.15, 401.42], [1, 1.16, 1911.28], [2, 1.17, 142.5]]}, {"timestamp": 1631547731407, "ltp": 1.14, "tv": 20269.79, "trd": NaN, "batb": NaN, "batl": [[0, 1.15, 609.42]]}, {"timestamp": 1631547735315, "ltp": 1.14, "tv": 20269.79, "trd": NaN, "batb": [[0, 1.14, 328.27]], "batl": [[0, 1.15, 588.29]]}, {"timestamp": 1631547738220, "ltp": 1.14, "tv": 20269.79, "trd": NaN, "batb": [[0, 1.14, 355.26]], "batl": [[0, 1.15, 611.11]]}, {"timestamp": 1631547740606, "ltp": 1.15, "tv": 20271.49, "trd": [[1.15, 514.17]], "batb": NaN, "batl": [[0, 1.15, 610.25]]}, {"timestamp": 1631547742519, "ltp": 1.15, "tv": 20271.49, "trd": NaN, "batb": [[0, 1.13, 264.68], [1, 1.12, 316.57], [2, 1.11, 292.61]], "batl": [[0, 1.15, 208], [1, 1.16, 160.22]]}, {"timestamp": 1631547743610, "ltp": 1.15, "tv": 20271.49, "trd": NaN, "batb": NaN, "batl": [[0, 1.14, 36.73], [1, 1.17, 142.5], [2, 1.2, 227.74]]}, {"timestamp": 1631547747748, "ltp": 1.15, "tv": 20271.49, "trd": NaN, "batb": NaN, "batl": [[0, 1.17, 142.5], [1, 1.2, 227.74], [2, 1.21, 217.63]]}, {"timestamp": 1631547750760, "ltp": 1.15, "tv": 20271.49, "trd": NaN, "batb": [[0, 1.06, 969.79], [1, 1.01, 577.96], [2, 1.11, 0]], "batl": NaN}, {"timestamp": 1631547753615, "ltp": 1.15, "tv": 20271.49, "trd": NaN, "batb": [[0, 1.14, 847.86], [1, 1.06, 969.79], [2, 1.01, 577.96]], "batl": [[0, 1.16, 17.04], [1, 1.17, 1248.69], [2, 1.2, 227.74]]}, {"timestamp": 1631547754645, "ltp": 1.16, "tv": 20282.07, "trd": [[1.16, 124.38]], "batb": NaN, "batl": [[0, 1.16, 6.46]]}, {"timestamp": 1631547760050, "ltp": 1.16, "tv": 20282.07, "trd": NaN, "batb": NaN, "batl": [[0, 1.16, 176.9], [1, 1.17, 1254.72]]}, {"timestamp": 1631547764864, "ltp": 1.16, "tv": 20282.07, "trd": NaN, "batb": NaN, "batl": [[0, 1.16, 170.44]]}, {"timestamp": 1631547767649, "ltp": 1.16, "tv": 20282.07, "trd": NaN, "batb": NaN, "batl": [[1, 1.17, 1302.21]]}, {"timestamp": 1631547768274, "ltp": 1.16, "tv": 20282.07, "trd": NaN, "batb": NaN, "batl": [[0, 1.16, 250.22]]}, {"timestamp": 1631547771439, "ltp": 1.16, "tv": 20282.07, "trd": NaN, "batb": NaN, "batl": [[0, 1.16, 256.69]]}, {"timestamp": 1631547772056, "ltp": 1.16, "tv": 20282.07, "trd": NaN, "batb": NaN, "batl": [[0, 1.16, 571.32], [1, 1.17, 1691.02]]}, {"timestamp": 1631547773357, "ltp": 1.16, "tv": 20282.07, "trd": NaN, "batb": [[0, 1.06, 969.79], [1, 1.01, 577.96], [2, 1.01, 0]], "batl": [[0, 1.16, 256.69], [1, 1.17, 148.53], [2, 1.38, 987.41]]}, {"timestamp": 1631547774344, "ltp": 1.16, "tv": 20282.07, "trd": NaN, "batb": NaN, "batl": [[0, 1.17, 142.5], [1, 1.38, 987.41], [2, 1.39, 17.9]]}, {"timestamp": 1631547777570, "ltp": 1.16, "tv": 20282.07, "trd": NaN, "batb": [[0, 1.01, 577.96], [1, 1.01, 0]], "batl": NaN}, {"timestamp": 1631547779662, "ltp": 1.16, "tv": 20282.07, "trd": NaN, "batb": [[0, 1.15, 706.74], [1, 1.01, 577.96]], "batl": [[1, 1.18, 1099.05], [2, 1.38, 987.41]]}, {"timestamp": 1631547780655, "ltp": 1.16, "tv": 20282.07, "trd": NaN, "batb": [[1, 1.02, 626.67], [2, 1.01, 577.96]], "batl": NaN}, {"timestamp": 1631547780866, "ltp": 1.16, "tv": 20282.07, "trd": NaN, "batb": [[1, 1.07, 907.25]], "batl": NaN}, {"timestamp": 1631547784383, "ltp": 1.16, "tv": 20282.07, "trd": NaN, "batb": NaN, "batl": [[0, 1.17, 256.5], [2, 1.37, 250.68]]}, {"timestamp": 1631547786395, "ltp": 1.16, "tv": 20282.07, "trd": NaN, "batb": NaN, "batl": [[0, 1.17, 547.26], [1, 1.18, 1461.43], [2, 1.2, 126.53]]}, {"timestamp": 1631547786752, "ltp": 1.16, "tv": 20282.07, "trd": NaN, "batb": [[1, 1.14, 268.29], [2, 1.13, 259.27]], "batl": NaN}, {"timestamp": 1631547808097, "ltp": 1.16, "tv": 20282.11, "trd": [[1.16, 124.42]], "batb": NaN, "batl": NaN}, {"timestamp": 1631547810195, "ltp": 1.16, "tv": 20282.11, "trd": NaN, "batb": [[0, 1.14, 268.29], [1, 1.13, 259.27], [2, 1.12, 364.85]], "batl": [[0, 1.17, 114], [1, 1.2, 126.53], [2, 1.21, 111.5]]}, {"timestamp": 1631547811512, "ltp": 1.16, "tv": 20282.11, "trd": NaN, "batb": NaN, "batl": [[0, 1.22, 117.75], [1, 1.24, 184.77], [2, 1.25, 196.28]]}, {"timestamp": 1631547814698, "ltp": 1.16, "tv": 20282.11, "trd": NaN, "batb": NaN, "batl": [[0, 1.2, 122.43], [1, 1.21, 119.5], [2, 1.22, 117.75]]}, {"timestamp": 1631547815627, "ltp": 1.16, "tv": 20282.11, "trd": NaN, "batb": NaN, "batl": [[0, 1.17, 38.5], [1, 1.22, 117.75], [2, 1.24, 184.77]]}, {"timestamp": 1631547815934, "ltp": 1.16, "tv": 20282.11, "trd": NaN, "batb": NaN, "batl": [[0, 1.22, 117.75], [1, 1.24, 184.77], [2, 1.25, 196.28]]}, {"timestamp": 1631547818546, "ltp": 1.16, "tv": 20282.11, "trd": NaN, "batb": NaN, "batl": [[0, 1.2, 109.58], [1, 1.21, 116.5], [2, 1.22, 117.75]]}, {"timestamp": 1631547818800, "ltp": 1.16, "tv": 20282.11, "trd": NaN, "batb": NaN, "batl": [[0, 1.22, 117.75], [1, 1.24, 184.77], [2, 1.25, 196.28]]}, {"timestamp": 1631547829550, "ltp": 1.16, "tv": 20282.11, "trd": NaN, "batb": [[0, 1.07, 907.25], [1, 1.01, 577.96], [2, 1.12, 0]], "batl": NaN}, {"timestamp": 1631547831321, "ltp": 1.16, "tv": 20282.11, "trd": NaN, "batb": [[0, 1.01, 577.96], [1, 1.01, 0]], "batl": NaN}, {"timestamp": 1631547832633, "ltp": 1.16, "tv": 20282.11, "trd": NaN, "batb": NaN, "batl": [[0, 1.22, 1027.68]]}, {"timestamp": 1631547835337, "ltp": 1.16, "tv": 20282.11, "trd": NaN, "batb": [[0, 1.03, 497.16], [1, 1.01, 577.96]], "batl": NaN}, {"timestamp": 1631547838516, "ltp": 1.16, "tv": 20282.11, "trd": NaN, "batb": [[0, 1.05, 477.27], [1, 1.03, 497.16], [2, 1.01, 577.96]], "batl": NaN}, {"timestamp": 1631547839347, "ltp": 1.16, "tv": 20282.11, "trd": NaN, "batb": [[0, 1.17, 215.71], [1, 1.16, 226.94], [2, 1.15, 276.01]], "batl": NaN}, {"timestamp": 1631547841557, "ltp": 1.16, "tv": 20282.11, "trd": NaN, "batb": NaN, "batl": [[0, 1.22, 1385.06], [1, 1.23, 324.86], [2, 1.24, 184.77]]}, {"timestamp": 1631547842131, "ltp": 1.16, "tv": 20282.11, "trd": NaN, "batb": NaN, "batl": [[0, 1.21, 277.97], [1, 1.22, 1711.63], [2, 1.23, 324.86]]}, {"timestamp": 1631547848670, "ltp": 1.16, "tv": 20282.11, "trd": NaN, "batb": NaN, "batl": [[0, 1.22, 76], [1, 1.27, 91.5], [2, 1.28, 88.59]]}, {"timestamp": 1631547849349, "ltp": 1.16, "tv": 20282.11, "trd": NaN, "batb": NaN, "batl": [[0, 1.29, 75.5], [1, 1.31, 230.16], [2, 1.32, 173.44]]}, {"timestamp": 1631547866709, "ltp": 1.16, "tv": 20282.11, "trd": NaN, "batb": NaN, "batl": [[0, 1.27, 92.5], [1, 1.29, 75.5], [2, 1.31, 230.16]]}, {"timestamp": 1631547866978, "ltp": 1.16, "tv": 20282.11, "trd": NaN, "batb": NaN, "batl": [[0, 1.29, 75.5], [1, 1.31, 230.16], [2, 1.32, 173.44]]}, {"timestamp": 1631547868171, "ltp": 1.16, "tv": 20282.11, "trd": NaN, "batb": [[0, 1.05, 477.27], [1, 1.03, 497.16], [2, 1.01, 577.96]], "batl": NaN}, {"timestamp": 1631547871505, "ltp": 1.16, "tv": 20282.11, "trd": NaN, "batb": [[0, 1.25, 16.78], [1, 1.23, 784.85], [2, 1.05, 477.27]], "batl": [[0, 1.27, 16.86], [1, 1.28, 807.7], [2, 1.29, 75.5]]}, {"timestamp": 1631547872779, "ltp": 1.16, "tv": 20282.11, "trd": NaN, "batb": [[2, 1.13, 639.32]], "batl": NaN}, {"timestamp": 1631547878194, "ltp": 1.16, "tv": 20282.11, "trd": NaN, "batb": [[2, 1.21, 181.23]], "batl": NaN}, {"timestamp": 1631547881405, "ltp": 1.16, "tv": 20282.11, "trd": NaN, "batb": NaN, "batl": [[0, 1.27, 400.86]]}, {"timestamp": 1631547885711, "ltp": 1.16, "tv": 20282.11, "trd": NaN, "batb": [[0, 1.21, 181.23], [1, 1.2, 191.35], [2, 1.19, 300.24]], "batl": [[0, 1.39, 128.24], [1, 1.4, 221.85], [2, 1.41, 153.03]]}, {"timestamp": 1631547886714, "ltp": 1.16, "tv": 20282.11, "trd": NaN, "batb": [[0, 1.25, 283.08], [1, 1.24, 326.14], [2, 1.21, 181.23]], "batl": NaN}, {"timestamp": 1631547886926, "ltp": 1.16, "tv": 20282.11, "trd": NaN, "batb": [[0, 1.21, 181.23], [1, 1.2, 191.35], [2, 1.19, 300.24]], "batl": NaN}, {"timestamp": 1631547889724, "ltp": 1.16, "tv": 20282.11, "trd": NaN, "batb": NaN, "batl": [[0, 1.4, 68.34], [1, 1.53, 724.69], [2, 1.56, 73.64]]}, {"timestamp": 1631547892616, "ltp": 1.16, "tv": 20282.11, "trd": NaN, "batb": [[0, 1.22, 18.06], [1, 1.21, 181.23], [2, 1.2, 547.84]], "batl": [[0, 1.23, 2314.86], [1, 1.24, 870.91], [2, 1.4, 68.34]]}, {"timestamp": 1631547892824, "ltp": 1.16, "tv": 20282.11, "trd": NaN, "batb": NaN, "batl": [[0, 1.23, 32.52]]}, {"timestamp": 1631547898590, "ltp": 1.16, "tv": 20282.11, "trd": NaN, "batb": NaN, "batl": [[0, 1.23, 505.37], [1, 1.24, 1212.83]]}, {"timestamp": 1631547899325, "ltp": 1.16, "tv": 20282.11, "trd": NaN, "batb": NaN, "batl": [[2, 1.33, 80.5]]}, {"timestamp": 1631547906743, "ltp": 1.23, "tv": 20387.84, "trd": [[1.23, 105.73]], "batb": NaN, "batl": [[0, 1.23, 452.51]]}, {"timestamp": 1631547911622, "ltp": 1.23, "tv": 20387.84, "trd": NaN, "batb": [[0, 1.21, 181.23], [1, 1.2, 191.35], [2, 1.19, 300.24]], "batl": [[1, 1.24, 341.92]]}, {"timestamp": 1631547912143, "ltp": 1.23, "tv": 20387.84, "trd": NaN, "batb": [[0, 1.18, 220.88], [1, 1.17, 280.64], [2, 1.16, 233.33]], "batl": [[0, 1.35, 131.63], [1, 1.36, 164.84], [2, 1.37, 296.13]]}, {"timestamp": 1631547918350, "ltp": 1.23, "tv": 20387.84, "trd": NaN, "batb": NaN, "batl": [[0, 1.35, 209.13]]}, {"timestamp": 1631547935076, "ltp": 1.23, "tv": 20387.84, "trd": NaN, "batb": [[0, 1.11, 694.47], [1, 1.05, 477.27], [2, 1.03, 497.16]], "batl": NaN}, {"timestamp": 1631547936702, "ltp": 1.23, "tv": 20387.84, "trd": NaN, "batb": NaN, "batl": [[0, 1.33, 77.5], [1, 1.35, 209.13], [2, 1.36, 164.84]]}, {"timestamp": 1631547936910, "ltp": 1.23, "tv": 20387.84, "trd": NaN, "batb": [[0, 1.05, 477.27], [1, 1.03, 497.16], [2, 1.01, 577.96]], "batl": [[0, 1.35, 209.13], [1, 1.36, 164.84], [2, 1.37, 296.13]]}, {"timestamp": 1631547938384, "ltp": 1.23, "tv": 20387.84, "trd": NaN, "batb": [[0, 1.22, 3553], [1, 1.05, 477.27], [2, 1.03, 497.16]], "batl": [[0, 1.32, 667.01], [1, 1.35, 209.13], [2, 1.36, 164.84]]}, {"timestamp": 1631547940612, "ltp": 1.23, "tv": 20387.84, "trd": NaN, "batb": [[1, 1.16, 584.68], [2, 1.05, 477.27]], "batl": NaN}, {"timestamp": 1631547941400, "ltp": 1.23, "tv": 20387.84, "trd": NaN, "batb": [[2, 1.1, 298.3]], "batl": NaN}, {"timestamp": 1631547942682, "ltp": 1.23, "tv": 20387.84, "trd": NaN, "batb": NaN, "batl": [[0, 1.3, 131.3], [1, 1.32, 667.01], [2, 1.35, 209.13]]}, {"timestamp": 1631547943309, "ltp": 1.23, "tv": 20387.84, "trd": NaN, "batb": NaN, "batl": [[0, 1.31, 1770]]}, {"timestamp": 1631547945098, "ltp": 1.23, "tv": 20387.84, "trd": NaN, "batb": [[0, 1.24, 146.33], [1, 1.23, 201.19], [2, 1.22, 3748.67]], "batl": NaN}, {"timestamp": 1631547947726, "ltp": 1.23, "tv": 20387.84, "trd": NaN, "batb": NaN, "batl": [[0, 1.31, 2038.59], [1, 1.32, 1016.6]]}, {"timestamp": 1631547952941, "ltp": 1.23, "tv": 20387.84, "trd": NaN, "batb": NaN, "batl": [[1, 1.32, 995.65]]}, {"timestamp": 1631547954230, "ltp": 1.23, "tv": 20387.84, "trd": NaN, "batb": [[2, 1.22, 195.67]], "batl": [[0, 1.46, 170.92], [1, 1.47, 139.47], [2, 1.48, 184.35]]}, {"timestamp": 1631547956703, "ltp": 1.23, "tv": 20387.84, "trd": NaN, "batb": NaN, "batl": [[0, 1.46, 117.17]]}, {"timestamp": 1631547959709, "ltp": 1.23, "tv": 20387.84, "trd": NaN, "batb": NaN, "batl": [[0, 1.33, 21.5], [1, 1.46, 117.17], [2, 1.47, 139.47]]}, {"timestamp": 1631547960340, "ltp": 1.23, "tv": 20387.84, "trd": NaN, "batb": NaN, "batl": [[0, 1.46, 174.42], [1, 1.47, 139.47], [2, 1.48, 184.35]]}, {"timestamp": 1631547974544, "ltp": 1.23, "tv": 20387.84, "trd": NaN, "batb": [[0, 1.24, 255.6], [2, 1.22, 307.51]], "batl": NaN}, {"timestamp": 1631547974852, "ltp": 1.23, "tv": 20387.84, "trd": NaN, "batb": [[0, 1.24, 146.33]], "batl": NaN}, {"timestamp": 1631547977342, "ltp": 1.23, "tv": 20387.84, "trd": NaN, "batb": NaN, "batl": [[0, 1.53, 724.69], [1, 1.56, 73.64], [2, 1.94, 3.08]]}, {"timestamp": 1631547980454, "ltp": 1.25, "tv": 20403.64, "trd": [[1.25, 212.8]], "batb": NaN, "batl": [[0, 1.25, 10.18], [1, 1.32, 2720.93], [2, 1.53, 724.69]]}, {"timestamp": 1631547987571, "ltp": 1.25, "tv": 20403.64, "trd": NaN, "batb": NaN, "batl": [[2, 1.5, 44.39]]}, {"timestamp": 1631547990348, "ltp": 1.25, "tv": 20403.64, "trd": NaN, "batb": NaN, "batl": [[0, 1.25, 175.18]]}, {"timestamp": 1631547990749, "ltp": 1.25, "tv": 20403.64, "trd": NaN, "batb": [[0, 1.23, 201.19], [1, 1.22, 307.51], [2, 1.18, 128.36]], "batl": NaN}, {"timestamp": 1631547993382, "ltp": 1.25, "tv": 20403.64, "trd": NaN, "batb": NaN, "batl": [[1, 1.26, 25.52], [2, 1.32, 2720.93]]}, {"timestamp": 1631548001591, "ltp": 1.25, "tv": 20425.72, "trd": [[1.25, 234.88]], "batb": NaN, "batl": [[0, 1.25, 164.14]]}, {"timestamp": 1631548006596, "ltp": 1.25, "tv": 20425.72, "trd": NaN, "batb": [[0, 1.16, 147.53], [1, 1.05, 477.27], [2, 1.03, 497.16]], "batl": [[0, 1.56, 73.64], [1, 1.58, 46.75], [2, 1.94, 3.08]]}, {"timestamp": 1631548009481, "ltp": 1.25, "tv": 20425.72, "trd": NaN, "batb": [[0, 1.18, 131.36], [1, 1.16, 147.53], [2, 1.05, 477.27]], "batl": NaN}, {"timestamp": 1631548010211, "ltp": 1.25, "tv": 20425.72, "trd": NaN, "batb": [[0, 1.16, 147.53], [1, 1.05, 477.27], [2, 1.03, 497.16]], "batl": NaN}, {"timestamp": 1631548016503, "ltp": 1.25, "tv": 20425.72, "trd": NaN, "batb": [[0, 1.18, 154.36], [1, 1.16, 147.53], [2, 1.05, 477.27]], "batl": NaN}, {"timestamp": 1631548017181, "ltp": 1.25, "tv": 20425.72, "trd": NaN, "batb": [[0, 1.16, 147.53], [1, 1.05, 477.27], [2, 1.03, 497.16]], "batl": NaN}, {"timestamp": 1631548020311, "ltp": 1.25, "tv": 20425.72, "trd": NaN, "batb": NaN, "batl": [[1, 1.94, 3.08], [2, 3.8, 27.43]]}, {"timestamp": 1631548022511, "ltp": 1.25, "tv": 20425.72, "trd": NaN, "batb": [[1, 1.03, 497.16], [2, 1.01, 577.96]], "batl": [[0, 1.2, 29.27], [1, 1.56, 73.64], [2, 1.94, 3.08]]}, {"timestamp": 1631548026225, "ltp": 1.25, "tv": 20425.72, "trd": NaN, "batb": [[1, 1.09, 790.61], [2, 1.03, 497.16]], "batl": [[1, 1.47, 815.13], [2, 1.56, 73.64]]}, {"timestamp": 1631548029411, "ltp": 1.25, "tv": 20425.72, "trd": NaN, "batb": [[1, 1.15, 395.24], [2, 1.14, 278.87]], "batl": [[1, 1.28, 90.59], [2, 1.3, 255.8]]}, {"timestamp": 1631548029947, "ltp": 1.25, "tv": 20425.72, "trd": NaN, "batb": NaN, "batl": [[0, 1.2, 310.65], [1, 1.21, 349.59], [2, 1.28, 90.59]]}, {"timestamp": 1631548031131, "ltp": 1.25, "tv": 20425.72, "trd": NaN, "batb": [[0, 1.16, 450.22], [1, 1.15, 782.34]], "batl": NaN}, {"timestamp": 1631548032442, "ltp": 1.25, "tv": 20425.72, "trd": NaN, "batb": NaN, "batl": [[0, 1.2, 415.65]]}, {"timestamp": 1631548036632, "ltp": 1.2, "tv": 20428.5, "trd": [[1.2, 2.78]], "batb": NaN, "batl": [[0, 1.2, 309.26]]}, {"timestamp": 1631548039744, "ltp": 1.2, "tv": 20428.5, "trd": NaN, "batb": NaN, "batl": [[0, 1.19, 369], [1, 1.2, 309.26], [2, 1.21, 349.59]]}, {"timestamp": 1631548046560, "ltp": 1.2, "tv": 20428.5, "trd": NaN, "batb": NaN, "batl": [[1, 1.2, 293.61]]}, {"timestamp": 1631548050667, "ltp": 1.2, "tv": 20428.5, "trd": NaN, "batb": [[0, 1.15, 395.24], [1, 1.14, 278.87], [2, 1.13, 368.38]], "batl": [[0, 1.3, 170.95], [1, 1.31, 266.88], [2, 1.32, 159.98]]}, {"timestamp": 1631548055257, "ltp": 1.2, "tv": 20428.5, "trd": NaN, "batb": NaN, "batl": [[0, 1.31, 91.5], [1, 1.47, 815.13], [2, 1.56, 73.64]]}, {"timestamp": 1631548056677, "ltp": 1.2, "tv": 20428.5, "trd": NaN, "batb": [[0, 1.16, 177.03], [1, 1.15, 395.24], [2, 1.14, 278.87]], "batl": NaN}, {"timestamp": 1631548057690, "ltp": 1.2, "tv": 20428.5, "trd": NaN, "batb": [[0, 1.15, 395.24], [1, 1.14, 278.87], [2, 1.13, 368.38]], "batl": [[0, 1.28, 89.59], [1, 1.31, 91.5], [2, 1.47, 815.13]]}, {"timestamp": 1631548058474, "ltp": 1.2, "tv": 20428.5, "trd": NaN, "batb": [[1, 1.14, 1286.88]], "batl": [[0, 1.17, 49.57], [1, 1.18, 33.9], [2, 1.2, 1382.34]]}, {"timestamp": 1631548064568, "ltp": 1.2, "tv": 20428.5, "trd": NaN, "batb": [[1, 1.14, 1467.7], [2, 1.13, 561.11]], "batl": [[2, 1.19, 126.5]]}, {"timestamp": 1631548065370, "ltp": 1.2, "tv": 20428.5, "trd": NaN, "batb": [[1, 1.14, 1678.34], [2, 1.13, 813.28]], "batl": NaN}, {"timestamp": 1631548071372, "ltp": 1.2, "tv": 20428.5, "trd": NaN, "batb": NaN, "batl": [[0, 1.17, 155.57]]}, {"timestamp": 1631548073469, "ltp": 1.2, "tv": 20428.5, "trd": NaN, "batb": [[0, 1.14, 391.46], [1, 1.13, 444.9], [2, 1.12, 274.96]], "batl": [[0, 1.17, 106], [1, 1.19, 126.5], [2, 1.2, 134.13]]}, {"timestamp": 1631548074579, "ltp": 1.2, "tv": 20428.5, "trd": NaN, "batb": NaN, "batl": [[0, 1.2, 134.13], [1, 1.24, 202.17], [2, 1.25, 171.6]]}, {"timestamp": 1631548077499, "ltp": 1.2, "tv": 20428.5, "trd": NaN, "batb": [[0, 1.14, 210.64]], "batl": [[1, 1.39, 17.9], [2, 1.47, 815.13]]}, {"timestamp": 1631548079070, "ltp": 1.2, "tv": 20428.5, "trd": NaN, "batb": NaN, "batl": [[2, 1.56, 73.64]]}, {"timestamp": 1631548080497, "ltp": 1.2, "tv": 20428.5, "trd": NaN, "batb": [[0, 1.13, 444.9], [1, 1.12, 274.96], [2, 1.01, 577.96]], "batl": [[0, 1.15, 826.89], [1, 1.2, 134.13], [2, 1.39, 17.9]]}, {"timestamp": 1631548083604, "ltp": 1.15, "tv": 20468.5, "trd": [[1.15, 554.17]], "batb": [[2, 1.06, 935.82]], "batl": [[0, 1.15, 806.89]]}, {"timestamp": 1631548094689, "ltp": 1.15, "tv": 20468.5, "trd": NaN, "batb": NaN, "batl": [[1, 1.16, 775.91], [2, 1.2, 134.13]]}, {"timestamp": 1631548095604, "ltp": 1.15, "tv": 20468.5, "trd": NaN, "batb": NaN, "batl": [[0, 1.14, 54.23], [1, 1.15, 905.89], [2, 1.16, 775.91]]}, {"timestamp": 1631548097016, "ltp": 1.14, "tv": 20475.56, "trd": [[1.14, 10.48]], "batb": NaN, "batl": [[0, 1.14, 50.7]]}, {"timestamp": 1631548105429, "ltp": 1.14, "tv": 20495.17, "trd": [[1.14, 30.09]], "batb": NaN, "batl": [[0, 1.14, 40.89]]}, {"timestamp": 1631548118869, "ltp": 1.13, "tv": 20515.17, "trd": [[1.13, 26.72]], "batb": [[0, 1.13, 434.9]], "batl": NaN}, {"timestamp": 1631548128470, "ltp": 1.14, "tv": 20556.06, "trd": [[1.14, 70.98]], "batb": [[0, 1.13, 182.73], [1, 1.06, 935.82], [2, 1.01, 105.79]], "batl": [[0, 1.15, 905.89], [1, 1.16, 775.91], [2, 1.2, 134.13]]}, {"timestamp": 1631548131443, "ltp": 1.14, "tv": 20556.06, "trd": NaN, "batb": NaN, "batl": [[1, 1.2, 134.13], [2, 1.39, 17.9]]}, {"timestamp": 1631548212263, "ltp": 1.14, "tv": 20556.06, "trd": NaN, "batb": [[2, 1.01, 120.59]], "batl": NaN}, {"timestamp": 1631548213366, "ltp": 1.14, "tv": 20556.06, "trd": NaN, "batb": [[0, 1.06, 935.82], [1, 1.01, 120.59], [2, 1.01, 0]], "batl": [[0, 1.15, 99], [1, 1.39, 17.9], [2, 1.4, 1040.75]]}, {"timestamp": 1631548214369, "ltp": 1.14, "tv": 20556.06, "trd": NaN, "batb": [[1, 1.02, 5.95], [2, 1.01, 120.59]], "batl": [[0, 1.39, 17.9], [1, 1.4, 1040.75], [2, 1.94, 3.08]]}, {"timestamp": 1631548215362, "ltp": 1.14, "tv": 20556.06, "trd": NaN, "batb": [[1, 1.04, 2.97], [2, 1.03, 3.73]], "batl": NaN}, {"timestamp": 1631548217637, "ltp": 1.14, "tv": 20556.06, "trd": NaN, "batb": [[1, 1.05, 2.23], [2, 1.04, 2.97]], "batl": NaN}, {"timestamp": 1631548219475, "ltp": 1.14, "tv": 20556.06, "trd": NaN, "batb": [[0, 1.06, 2.22]], "batl": NaN}, {"timestamp": 1631548220467, "ltp": 1.14, "tv": 20556.06, "trd": NaN, "batb": [[0, 1.14, 35.08], [1, 1.07, 2.22], [2, 1.06, 2.22]], "batl": [[0, 1.17, 882.7], [1, 1.39, 17.9], [2, 1.4, 1040.75]]}, {"timestamp": 1631548222041, "ltp": 1.14, "tv": 20556.06, "trd": NaN, "batb": [[1, 1.08, 2.21], [2, 1.07, 2.22]], "batl": NaN}, {"timestamp": 1631548223661, "ltp": 1.14, "tv": 20556.06, "trd": NaN, "batb": [[2, 1.07, 909.46]], "batl": NaN}, {"timestamp": 1631548226703, "ltp": 1.14, "tv": 20556.06, "trd": NaN, "batb": NaN, "batl": [[0, 1.17, 944.7]]}, {"timestamp": 1631548227382, "ltp": 1.14, "tv": 20556.06, "trd": NaN, "batb": [[0, 1.14, 212.9], [1, 1.13, 184.73], [2, 1.08, 2.21]], "batl": [[0, 1.17, 1097.2], [1, 1.18, 148.25], [2, 1.39, 17.9]]}, {"timestamp": 1631548228480, "ltp": 1.14, "tv": 20556.06, "trd": NaN, "batb": NaN, "batl": [[0, 1.17, 1035.2]]}, {"timestamp": 1631548229588, "ltp": 1.14, "tv": 20556.06, "trd": NaN, "batb": [[0, 1.14, 213.13]], "batl": NaN}, {"timestamp": 1631548230169, "ltp": 1.14, "tv": 20556.06, "trd": NaN, "batb": [[2, 1.08, 2.4]], "batl": NaN}, {"timestamp": 1631548231592, "ltp": 1.14, "tv": 20556.06, "trd": NaN, "batb": [[0, 1.14, 178.05], [2, 1.08, 2.65]], "batl": [[0, 1.16, 225]]}, {"timestamp": 1631548232695, "ltp": 1.14, "tv": 20556.06, "trd": NaN, "batb": [[2, 1.08, 3.08]], "batl": [[0, 1.18, 148.25], [1, 1.39, 17.9], [2, 1.4, 1040.75]]}, {"timestamp": 1631548233484, "ltp": 1.14, "tv": 20556.06, "trd": NaN, "batb": [[1, 1.13, 184.98]], "batl": NaN}, {"timestamp": 1631548234375, "ltp": 1.14, "tv": 20556.06, "trd": NaN, "batb": NaN, "batl": [[0, 1.17, 137.5], [1, 1.18, 148.25], [2, 1.39, 17.9]]}, {"timestamp": 1631548236586, "ltp": 1.14, "tv": 20556.06, "trd": NaN, "batb": NaN, "batl": [[0, 1.18, 148.25], [1, 1.39, 17.9], [2, 1.4, 1040.75]]}, {"timestamp": 1631548240621, "ltp": 1.14, "tv": 20556.06, "trd": NaN, "batb": NaN, "batl": [[0, 1.17, 144.5], [1, 1.18, 148.25], [2, 1.39, 17.9]]}, {"timestamp": 1631548241248, "ltp": 1.14, "tv": 20556.06, "trd": NaN, "batb": NaN, "batl": [[0, 1.18, 148.25], [1, 1.39, 17.9], [2, 1.4, 1040.75]]}, {"timestamp": 1631548244554, "ltp": 1.17, "tv": 20656.39, "trd": [[1.17, 102.34]], "batb": NaN, "batl": NaN}, {"timestamp": 1631548246699, "ltp": 1.18, "tv": 20658.39, "trd": [[1.18, 168.43]], "batb": NaN, "batl": [[0, 1.39, 17.9], [1, 1.4, 1040.75], [2, 1.94, 3.08]]}, {"timestamp": 1631548248065, "ltp": 1.18, "tv": 20658.39, "trd": NaN, "batb": [[0, 1.13, 185.21], [1, 1.08, 3.08], [2, 1.07, 2.22]], "batl": NaN}, {"timestamp": 1631548249176, "ltp": 1.14, "tv": 20658.85, "trd": [[1.14, 71.44]], "batb": [[0, 1.13, 206.98], [1, 1.12, 865.83], [2, 1.08, 2.87]], "batl": [[0, 1.14, 31.43], [1, 1.15, 1280.67], [2, 1.16, 34.48]]}, {"timestamp": 1631548252098, "ltp": 1.14, "tv": 20721.71, "trd": [[1.14, 134.3]], "batb": NaN, "batl": [[0, 1.15, 1280.67], [1, 1.16, 34.48], [2, 1.39, 17.9]]}, {"timestamp": 1631548255184, "ltp": 1.14, "tv": 20721.71, "trd": NaN, "batb": NaN, "batl": [[0, 1.14, 180], [1, 1.15, 1280.67], [2, 1.16, 34.48]]}, {"timestamp": 1631548256174, "ltp": 1.14, "tv": 20721.71, "trd": NaN, "batb": [[2, 1.11, 237.81]], "batl": [[2, 1.16, 205.67]]}, {"timestamp": 1631548259375, "ltp": 1.14, "tv": 20721.71, "trd": NaN, "batb": [[0, 1.13, 184.98]], "batl": NaN}, {"timestamp": 1631548265199, "ltp": 1.14, "tv": 20721.71, "trd": NaN, "batb": NaN, "batl": [[1, 1.15, 1327.42]]}, {"timestamp": 1631548266304, "ltp": 1.14, "tv": 20721.71, "trd": NaN, "batb": NaN, "batl": [[1, 1.15, 1327.64]]}, {"timestamp": 1631548273421, "ltp": 1.14, "tv": 20721.71, "trd": NaN, "batb": [[0, 1.09, 1.12], [1, 1.08, 2.21], [2, 1.07, 2.22]], "batl": [[1, 1.16, 171.41], [2, 1.17, 6.03]]}, {"timestamp": 1631548274514, "ltp": 1.14, "tv": 20848.37, "trd": [[1.14, 260.96]], "batb": NaN, "batl": [[0, 1.17, 6.25], [1, 1.39, 17.9], [2, 1.4, 1040.75]]}, {"timestamp": 1631548274725, "ltp": 1.14, "tv": 20848.37, "trd": NaN, "batb": NaN, "batl": [[0, 1.39, 18.11], [1, 1.4, 1040.75], [2, 1.94, 3.08]]}, {"timestamp": 1631548276307, "ltp": 1.14, "tv": 20848.37, "trd": NaN, "batb": NaN, "batl": [[0, 1.17, 167.72], [1, 1.39, 17.9], [2, 1.4, 1040.75]]}, {"timestamp": 1631548276935, "ltp": 1.14, "tv": 20848.37, "trd": NaN, "batb": [[1, 1.08, 299.52]], "batl": NaN}, {"timestamp": 1631548284524, "ltp": 1.14, "tv": 20848.37, "trd": NaN, "batb": NaN, "batl": [[0, 1.16, 6.94], [1, 1.17, 167.5], [2, 1.39, 17.9]]}, {"timestamp": 1631548285624, "ltp": 1.14, "tv": 20848.37, "trd": NaN, "batb": NaN, "batl": [[0, 1.16, 148.19], [1, 1.17, 173.59]]}, {"timestamp": 1631548285946, "ltp": 1.14, "tv": 20848.37, "trd": NaN, "batb": NaN, "batl": [[0, 1.17, 167.72], [1, 1.39, 17.9], [2, 1.4, 1040.75]]}, {"timestamp": 1631548287356, "ltp": 1.14, "tv": 20848.37, "trd": NaN, "batb": [[0, 1.1, 252.66], [1, 1.09, 267.8], [2, 1.08, 299.52]], "batl": NaN}, {"timestamp": 1631548288346, "ltp": 1.14, "tv": 20848.37, "trd": NaN, "batb": [[0, 1.09, 1.12], [1, 1.08, 299.52], [2, 1.07, 2.22]], "batl": NaN}, {"timestamp": 1631548289659, "ltp": 1.14, "tv": 20848.37, "trd": NaN, "batb": NaN, "batl": [[0, 1.39, 18.11], [1, 1.4, 1040.75], [2, 1.94, 3.08]]}, {"timestamp": 1631548291542, "ltp": 1.14, "tv": 20848.37, "trd": NaN, "batb": [[0, 1.1, 254.76], [1, 1.09, 307.8], [2, 1.08, 299.52]], "batl": [[0, 1.16, 6.19], [1, 1.39, 17.9], [2, 1.4, 1040.75]]}, {"timestamp": 1631548292055, "ltp": 1.12, "tv": 20849.29, "trd": [[1.12, 4.42], [1.13, 27.21]], "batb": [[0, 1.1, 293.41]], "batl": [[0, 1.12, 1391.35], [1, 1.39, 18.11]]}, {"timestamp": 1631548298660, "ltp": 1.11, "tv": 20849.73, "trd": [[1.11, 0.44]], "batb": [[0, 1.1, 293.19]], "batl": [[0, 1.11, 273.78], [1, 1.12, 1391.35], [2, 1.14, 169.75]]}, {"timestamp": 1631548298770, "ltp": 1.11, "tv": 20849.73, "trd": NaN, "batb": NaN, "batl": [[2, 1.14, 176.5]]}, {"timestamp": 1631548301215, "ltp": 1.11, "tv": 20856.69, "trd": [[1.11, 7.4]], "batb": NaN, "batl": [[0, 1.11, 270.3]]}, {"timestamp": 1631548304637, "ltp": 1.09, "tv": 23586.84, "trd": [[1.09, 2084.68], [1.1, 645.47]], "batb": [[0, 1.08, 299.52], [1, 1.07, 421.29], [2, 1.06, 393.8]], "batl": [[0, 1.09, 343.55], [1, 1.11, 270.3], [2, 1.12, 1391.35]]}, {"timestamp": 1631548307648, "ltp": 1.09, "tv": 23631.92, "trd": [[1.09, 2129.76]], "batb": NaN, "batl": [[0, 1.09, 321.02]]}, {"timestamp": 1631548309408, "ltp": 1.09, "tv": 23631.92, "trd": NaN, "batb": NaN, "batl": [[0, 1.11, 270.3], [1, 1.12, 1391.35], [2, 1.14, 176.93]]}, {"timestamp": 1631548312521, "ltp": 1.09, "tv": 23631.92, "trd": NaN, "batb": [[0, 1.08, 838.4], [1, 1.07, 1134.96]], "batl": [[0, 1.1, 321.02], [1, 1.11, 270.3], [2, 1.12, 1391.35]]}, {"timestamp": 1631548313250, "ltp": 1.09, "tv": 23631.92, "trd": NaN, "batb": NaN, "batl": [[1, 1.11, 700.89], [2, 1.12, 1866.28]]}, {"timestamp": 1631548314342, "ltp": 1.09, "tv": 23631.92, "trd": NaN, "batb": NaN, "batl": [[0, 1.1, 778.04], [1, 1.11, 1205.67], [2, 1.12, 1811.62]]}, {"timestamp": 1631548317255, "ltp": 1.09, "tv": 23631.92, "trd": NaN, "batb": NaN, "batl": [[1, 1.11, 1277.46]]}, {"timestamp": 1631548319551, "ltp": 1.09, "tv": 23631.92, "trd": NaN, "batb": NaN, "batl": [[1, 1.11, 1205.67], [2, 1.12, 480.64]]}, {"timestamp": 1631548320644, "ltp": 1.09, "tv": 23631.92, "trd": NaN, "batb": [[0, 1.08, 2.21], [1, 1.07, 2.22], [2, 1.06, 2.22]], "batl": [[0, 1.1, 321.02], [1, 1.11, 270.3], [2, 1.14, 176.93]]}, {"timestamp": 1631548322250, "ltp": 1.09, "tv": 23631.92, "trd": NaN, "batb": NaN, "batl": [[1, 1.14, 176.93], [2, 1.15, 168.82]]}, {"timestamp": 1631548323347, "ltp": 1.09, "tv": 23631.92, "trd": NaN, "batb": NaN, "batl": [[1, 1.14, 177.16]]}, {"timestamp": 1631548324188, "ltp": 1.09, "tv": 23631.92, "trd": NaN, "batb": NaN, "batl": [[0, 1.1, 321.2]]}, {"timestamp": 1631548325739, "ltp": 1.1, "tv": 23635.92, "trd": [[1.1, 649.47]], "batb": NaN, "batl": [[0, 1.1, 319.19]]}, {"timestamp": 1631548327149, "ltp": 1.1, "tv": 23635.92, "trd": NaN, "batb": NaN, "batl": [[1, 1.14, 7.41], [2, 1.15, 6.12]]}, {"timestamp": 1631548329540, "ltp": 1.08, "tv": 23640.34, "trd": [[1.08, 4.42]], "batb": [[0, 1.07, 2.22], [1, 1.06, 2.22], [2, 1.05, 2295.12]], "batl": [[0, 1.08, 359.83], [1, 1.1, 319.19], [2, 1.11, 4923.37]]}, {"timestamp": 1631548332663, "ltp": 1.08, "tv": 23640.34, "trd": NaN, "batb": NaN, "batl": [[0, 1.08, 459.83]]}, {"timestamp": 1631548334277, "ltp": 1.08, "tv": 23640.34, "trd": NaN, "batb": NaN, "batl": [[0, 1.08, 582.83]]}, {"timestamp": 1631548335583, "ltp": 1.08, "tv": 23640.34, "trd": NaN, "batb": NaN, "batl": [[1, 1.09, 2.21], [2, 1.1, 319.19]]}, {"timestamp": 1631548339652, "ltp": 1.08, "tv": 23640.34, "trd": NaN, "batb": NaN, "batl": [[0, 1.08, 538.44]]}, {"timestamp": 1631548342583, "ltp": 1.08, "tv": 23640.34, "trd": NaN, "batb": NaN, "batl": [[0, 1.08, 578.31]]}, {"timestamp": 1631548347184, "ltp": 1.08, "tv": 23640.34, "trd": NaN, "batb": NaN, "batl": [[0, 1.08, 538.44]]}, {"timestamp": 1631548350159, "ltp": 1.07, "tv": 23644.48, "trd": [[1.07, 4.14]], "batb": [[0, 1.06, 2.37], [1, 1.05, 2295.12], [2, 1.04, 2.97]], "batl": [[0, 1.08, 578.31]]}, {"timestamp": 1631548351574, "ltp": 1.07, "tv": 23644.48, "trd": NaN, "batb": [[1, 1.05, 2.23]], "batl": [[0, 1.08, 538.44]]}, {"timestamp": 1631548352404, "ltp": 1.07, "tv": 23644.48, "trd": NaN, "batb": NaN, "batl": [[0, 1.08, 100]]}, {"timestamp": 1631548358473, "ltp": 1.08, "tv": 23793.31, "trd": [[1.08, 153.25]], "batb": [[0, 1.07, 187.06], [1, 1.06, 2.22], [2, 1.05, 2.23]], "batl": [[0, 1.09, 2.98], [1, 1.1, 1327.05], [2, 1.11, 222.73]]}, {"timestamp": 1631548359409, "ltp": 1.08, "tv": 23793.31, "trd": NaN, "batb": [[0, 1.07, 37.52]], "batl": NaN}, {"timestamp": 1631548368588, "ltp": 1.08, "tv": 23793.31, "trd": NaN, "batb": NaN, "batl": [[1, 1.1, 1288.13]]}, {"timestamp": 1631548371596, "ltp": 1.08, "tv": 23793.31, "trd": NaN, "batb": NaN, "batl": [[0, 1.09, 100.42]]}, {"timestamp": 1631548378293, "ltp": 1.07, "tv": 23813.32, "trd": [[1.07, 24.15]], "batb": [[0, 1.07, 27.52]], "batl": NaN}, {"timestamp": 1631548379601, "ltp": 1.07, "tv": 23813.32, "trd": NaN, "batb": [[0, 1.06, 2.22], [1, 1.05, 2.23], [2, 1.04, 2.97]], "batl": [[0, 1.09, 2.98], [1, 1.1, 319.19], [2, 1.14, 193.16]]}, {"timestamp": 1631548381541, "ltp": 1.08, "tv": 23813.5, "trd": [[1.08, 153.43]], "batb": NaN, "batl": [[0, 1.09, 2.89]]}, {"timestamp": 1631548385139, "ltp": 1.08, "tv": 23813.5, "trd": NaN, "batb": NaN, "batl": [[0, 1.08, 2.9], [1, 1.09, 2.21], [2, 1.1, 319.19]]}, {"timestamp": 1631548387543, "ltp": 1.11, "tv": 24138.03, "trd": [[1.08, 156.33], [1.09, 2131.97], [1.1, 968.67], [1.11, 7.63]], "batb": [[0, 1.1, 635], [1, 1.06, 2.22], [2, 1.05, 2.23]], "batl": [[0, 1.13, 1424.01], [1, 1.14, 192.74], [2, 1.15, 189.42]]}, {"timestamp": 1631548389258, "ltp": 1.11, "tv": 24138.03, "trd": NaN, "batb": [[2, 1.05, 1087.66]], "batl": NaN}, {"timestamp": 1631548398673, "ltp": 1.11, "tv": 24138.03, "trd": NaN, "batb": [[1, 1.07, 2.51], [2, 1.06, 2.22]], "batl": NaN}, {"timestamp": 1631548399966, "ltp": 1.11, "tv": 24138.03, "trd": NaN, "batb": [[0, 1.1, 680.85], [1, 1.08, 2.45], [2, 1.07, 2.51]], "batl": [[0, 1.12, 61.07], [1, 1.13, 1424.01], [2, 1.14, 192.74]]}, {"timestamp": 1631548407623, "ltp": 1.11, "tv": 24138.03, "trd": NaN, "batb": [[0, 1.08, 2.45], [1, 1.07, 2.51], [2, 1.06, 4.4]], "batl": [[0, 1.14, 192.93], [1, 1.15, 189.42], [2, 1.16, 166.94]]}, {"timestamp": 1631548408665, "ltp": 1.11, "tv": 24138.03, "trd": NaN, "batb": [[0, 1.08, 2.9], [2, 1.06, 2.22]], "batl": [[0, 1.15, 183.95], [1, 1.16, 6.72], [2, 1.23, 29.83]]}, {"timestamp": 1631548414606, "ltp": 1.11, "tv": 24138.03, "trd": NaN, "batb": NaN, "batl": [[0, 1.14, 209.18], [1, 1.15, 183.52], [2, 1.16, 6.72]]}, {"timestamp": 1631548415489, "ltp": 1.11, "tv": 24138.03, "trd": NaN, "batb": NaN, "batl": [[0, 1.15, 183.95], [1, 1.16, 6.72], [2, 1.23, 29.83]]}, {"timestamp": 1631548417571, "ltp": 1.11, "tv": 24138.03, "trd": NaN, "batb": NaN, "batl": [[1, 1.16, 195.44]]}, {"timestamp": 1631548418506, "ltp": 1.11, "tv": 24138.03, "trd": NaN, "batb": NaN, "batl": [[1, 1.16, 6.72]]}, {"timestamp": 1631548421696, "ltp": 1.11, "tv": 24138.03, "trd": NaN, "batb": NaN, "batl": [[0, 1.14, 211.68], [1, 1.15, 183.52], [2, 1.16, 6.72]]}, {"timestamp": 1631548422011, "ltp": 1.11, "tv": 24138.03, "trd": NaN, "batb": NaN, "batl": [[0, 1.15, 183.95], [1, 1.16, 6.72], [2, 1.23, 29.83]]}, {"timestamp": 1631548427689, "ltp": 1.11, "tv": 24138.03, "trd": NaN, "batb": NaN, "batl": [[0, 1.23, 30.48], [1, 1.25, 14.92], [2, 1.38, 987.41]]}, {"timestamp": 1631548430395, "ltp": 1.09, "tv": 24138.92, "trd": [[1.09, 2132.35], [1.1, 969.17]], "batb": [[0, 1.08, 2.45]], "batl": [[0, 1.09, 445.28], [1, 1.12, 4534.09], [2, 1.23, 30.48]]}, {"timestamp": 1631548432694, "ltp": 1.09, "tv": 24138.92, "trd": NaN, "batb": [[1, 1.07, 140.36]], "batl": NaN}, {"timestamp": 1631548436227, "ltp": 1.08, "tv": 24143.83, "trd": [[1.08, 161.24]], "batb": [[0, 1.07, 140.36], [1, 1.06, 2.22], [2, 1.05, 2.23]], "batl": [[0, 1.08, 1.44], [1, 1.09, 445.28], [2, 1.12, 4534.09]]}, {"timestamp": 1631548437111, "ltp": 1.08, "tv": 24143.83, "trd": NaN, "batb": NaN, "batl": [[2, 1.12, 4746.3]]}, {"timestamp": 1631548447650, "ltp": 1.08, "tv": 24143.83, "trd": NaN, "batb": NaN, "batl": [[2, 1.12, 4746.55]]}, {"timestamp": 1631548448542, "ltp": 1.08, "tv": 24143.83, "trd": NaN, "batb": NaN, "batl": [[1, 1.09, 447.66], [2, 1.12, 4746.75]]}, {"timestamp": 1631548449061, "ltp": 1.08, "tv": 24143.83, "trd": NaN, "batb": NaN, "batl": [[1, 1.09, 2.38], [2, 1.12, 212.66]]}, {"timestamp": 1631548461432, "ltp": 1.1, "tv": 24147.85, "trd": [[1.08, 162.68], [1.09, 2134.73], [1.1, 969.37]], "batb": [[0, 1.1, 36.38], [1, 1.07, 140.36], [2, 1.06, 2.22]], "batl": [[0, 1.12, 77.42], [1, 1.13, 1914.14], [2, 1.14, 184.49]]}, {"timestamp": 1631548465042, "ltp": 1.1, "tv": 24147.85, "trd": NaN, "batb": NaN, "batl": [[1, 1.13, 1731.64]]}, {"timestamp": 1631548468157, "ltp": 1.1, "tv": 24147.85, "trd": NaN, "batb": [[1, 1.08, 2.64], [2, 1.07, 140.36]], "batl": NaN}, {"timestamp": 1631548469563, "ltp": 1.11, "tv": 24148.35, "trd": [[1.11, 8.14]], "batb": [[0, 1.11, 9.93], [1, 1.1, 36.38], [2, 1.08, 2.64]], "batl": [[0, 1.12, 77.17]]}, {"timestamp": 1631548472687, "ltp": 1.11, "tv": 24168.21, "trd": [[1.11, 28]], "batb": [[0, 1.1, 36.38], [1, 1.08, 2.64], [2, 1.07, 140.36]], "batl": NaN}, {"timestamp": 1631548475668, "ltp": 1.11, "tv": 24168.21, "trd": NaN, "batb": [[1, 1.08, 2.85]], "batl": NaN}, {"timestamp": 1631548479498, "ltp": 1.11, "tv": 24168.21, "trd": NaN, "batb": [[0, 1.08, 2.85], [1, 1.07, 140.36], [2, 1.06, 2.22]], "batl": [[0, 1.16, 158.87], [1, 1.23, 29.83], [2, 1.25, 14.92]]}, {"timestamp": 1631548482700, "ltp": 1.11, "tv": 24168.21, "trd": NaN, "batb": [[0, 1.08, 3.13]], "batl": NaN}, {"timestamp": 1631548486568, "ltp": 1.11, "tv": 24168.21, "trd": NaN, "batb": [[0, 1.12, 999.28], [1, 1.08, 3.13], [2, 1.07, 140.36]], "batl": [[0, 1.14, 57.42], [1, 1.15, 1319.34], [2, 1.16, 158.22]]}, {"timestamp": 1631548494083, "ltp": 1.11, "tv": 24168.21, "trd": NaN, "batb": [[1, 1.1, 228.11], [2, 1.09, 257.82]], "batl": [[0, 1.14, 257.17]]}, {"timestamp": 1631548497416, "ltp": 1.11, "tv": 24168.21, "trd": NaN, "batb": NaN, "batl": [[1, 1.15, 1511.84]]}, {"timestamp": 1631548502396, "ltp": 1.11, "tv": 24168.21, "trd": NaN, "batb": [[0, 1.09, 258.09], [1, 1.08, 2.64], [2, 1.07, 140.36]], "batl": [[0, 1.15, 193.15], [1, 1.23, 29.83], [2, 1.25, 14.92]]}, {"timestamp": 1631548505694, "ltp": 1.11, "tv": 24168.21, "trd": NaN, "batb": [[0, 1.1, 266.71], [1, 1.09, 257.82], [2, 1.08, 2.64]], "batl": [[0, 1.14, 202.68], [1, 1.15, 192.72], [2, 1.23, 29.83]]}, {"timestamp": 1631548505902, "ltp": 1.11, "tv": 24168.21, "trd": NaN, "batb": [[0, 1.09, 258.09], [1, 1.08, 2.64], [2, 1.07, 140.36]], "batl": [[0, 1.15, 193.15], [1, 1.23, 29.83], [2, 1.25, 14.92]]}, {"timestamp": 1631548512634, "ltp": 1.11, "tv": 24168.21, "trd": NaN, "batb": [[0, 1.1, 246.41], [1, 1.09, 257.82], [2, 1.08, 2.64]], "batl": [[0, 1.14, 198.18], [1, 1.15, 192.72], [2, 1.23, 29.83]]}, {"timestamp": 1631548512843, "ltp": 1.11, "tv": 24168.21, "trd": NaN, "batb": [[0, 1.09, 258.09], [1, 1.08, 2.64], [2, 1.07, 140.36]], "batl": [[0, 1.15, 193.15], [1, 1.23, 29.83], [2, 1.25, 14.92]]}, {"timestamp": 1631548514534, "ltp": 1.11, "tv": 24168.21, "trd": NaN, "batb": NaN, "batl": [[0, 1.23, 30.48], [1, 1.25, 14.92], [2, 1.38, 987.41]]}, {"timestamp": 1631548516342, "ltp": 1.11, "tv": 24168.21, "trd": NaN, "batb": [[0, 1.1, 212.11], [1, 1.09, 257.82], [2, 1.08, 2.64]], "batl": NaN}, {"timestamp": 1631548517622, "ltp": 1.11, "tv": 24168.21, "trd": NaN, "batb": [[0, 1.1, 362.11]], "batl": [[0, 1.11, 157.23], [1, 1.12, 2460.75], [2, 1.13, 96.19]]}, {"timestamp": 1631548518242, "ltp": 1.11, "tv": 24168.21, "trd": NaN, "batb": NaN, "batl": [[1, 1.12, 1398.95]]}, {"timestamp": 1631548522662, "ltp": 1.11, "tv": 24168.21, "trd": NaN, "batb": [[0, 1.1, 842.16], [1, 1.09, 901.58]], "batl": NaN}, {"timestamp": 1631548523657, "ltp": 1.11, "tv": 24168.21, "trd": NaN, "batb": NaN, "batl": [[0, 1.11, 567.36], [1, 1.12, 1932.72]]}, {"timestamp": 1631548523869, "ltp": 1.11, "tv": 24168.21, "trd": NaN, "batb": NaN, "batl": [[2, 1.13, 308.69]]}, {"timestamp": 1631548529253, "ltp": 1.11, "tv": 24168.21, "trd": NaN, "batb": NaN, "batl": [[1, 1.12, 1831.6]]}, {"timestamp": 1631548538651, "ltp": 1.11, "tv": 24168.21, "trd": NaN, "batb": [[0, 1.08, 3.13], [1, 1.07, 333.36], [2, 1.06, 219.22]], "batl": [[0, 1.13, 96.19], [1, 1.14, 186.99], [2, 1.23, 30.05]]}, {"timestamp": 1631548541367, "ltp": 1.11, "tv": 24168.21, "trd": NaN, "batb": NaN, "batl": [[1, 1.14, 293.99], [2, 1.15, 108.22]]}, {"timestamp": 1631548543538, "ltp": 1.11, "tv": 24168.21, "trd": NaN, "batb": NaN, "batl": [[0, 1.12, 773.74], [1, 1.13, 96.19], [2, 1.14, 293.99]]}, {"timestamp": 1631548544063, "ltp": 1.11, "tv": 24168.21, "trd": NaN, "batb": NaN, "batl": [[0, 1.13, 96.19], [1, 1.14, 293.99], [2, 1.15, 108.22]]}, {"timestamp": 1631548545462, "ltp": 1.11, "tv": 24168.21, "trd": NaN, "batb": NaN, "batl": [[0, 1.13, 297.69]]}, {"timestamp": 1631548545990, "ltp": 1.11, "tv": 24168.21, "trd": NaN, "batb": NaN, "batl": [[0, 1.13, 96.19]]}, {"timestamp": 1631548546781, "ltp": 1.11, "tv": 24168.21, "trd": NaN, "batb": NaN, "batl": [[2, 1.15, 302.32]]}, {"timestamp": 1631548552668, "ltp": 1.13, "tv": 24264.41, "trd": [[1.13, 123.41]], "batb": NaN, "batl": [[0, 1.13, 205.5]]}, {"timestamp": 1631548553087, "ltp": 1.13, "tv": 24264.41, "trd": NaN, "batb": NaN, "batl": [[0, 1.14, 293.99], [1, 1.15, 302.32], [2, 1.23, 29.83]]}, {"timestamp": 1631548553770, "ltp": 1.13, "tv": 24264.41, "trd": NaN, "batb": NaN, "batl": [[2, 1.2, 55.46]]}, {"timestamp": 1631548561510, "ltp": 1.13, "tv": 24264.41, "trd": NaN, "batb": [[0, 1.12, 133], [1, 1.1, 150.27], [2, 1.09, 161.21]], "batl": [[0, 1.13, 101], [1, 1.14, 293.99], [2, 1.15, 302.32]]}, {"timestamp": 1631548567714, "ltp": 1.13, "tv": 24264.41, "trd": NaN, "batb": [[0, 1.12, 133.21], [1, 1.11, 13.13], [2, 1.1, 397.95]], "batl": NaN}, {"timestamp": 1631548568180, "ltp": 1.13, "tv": 24264.41, "trd": NaN, "batb": [[2, 1.1, 638.1]], "batl": NaN}, {"timestamp": 1631548576605, "ltp": 1.12, "tv": 24282.45, "trd": [[1.12, 22.46]], "batb": [[0, 1.12, 124.19]], "batl": NaN}, {"timestamp": 1631548582419, "ltp": 1.12, "tv": 24282.45, "trd": NaN, "batb": [[0, 1.11, 13.33], [1, 1.1, 638.1], [2, 1.09, 721.78]], "batl": [[0, 1.14, 107.24], [1, 1.15, 302.32], [2, 1.19, 161.7]]}, {"timestamp": 1631548585615, "ltp": 1.12, "tv": 24282.45, "trd": NaN, "batb": [[1, 1.1, 397.95], [2, 1.09, 417.82]], "batl": [[2, 1.16, 100]]}, {"timestamp": 1631548586032, "ltp": 1.12, "tv": 24282.45, "trd": NaN, "batb": NaN, "batl": [[0, 1.15, 302.55], [1, 1.16, 100], [2, 1.19, 161.7]]}, {"timestamp": 1631548588644, "ltp": 1.14, "tv": 24282.93, "trd": [[1.14, 261.44]], "batb": [[0, 1.14, 21.43], [1, 1.11, 13.33], [2, 1.1, 397.95]], "batl": [[0, 1.15, 335.35], [1, 1.16, 965.41]]}, {"timestamp": 1631548588851, "ltp": 1.14, "tv": 24282.93, "trd": NaN, "batb": [[1, 1.13, 127], [2, 1.12, 133.21]], "batl": [[2, 1.18, 105]]}, {"timestamp": 1631548590342, "ltp": 1.14, "tv": 24282.93, "trd": NaN, "batb": [[2, 1.12, 145.24]], "batl": NaN}, {"timestamp": 1631548591540, "ltp": 1.14, "tv": 24325.79, "trd": [[1.14, 304.3]], "batb": [[0, 1.13, 138.1], [1, 1.12, 145.24], [2, 1.11, 154.13]], "batl": NaN}, {"timestamp": 1631548599062, "ltp": 1.14, "tv": 24325.79, "trd": NaN, "batb": NaN, "batl": [[0, 1.15, 302.32]]}, {"timestamp": 1631548601665, "ltp": 1.14, "tv": 24325.79, "trd": NaN, "batb": [[1, 1.12, 133.21]], "batl": [[0, 1.15, 356.82]]}, {"timestamp": 1631548602551, "ltp": 1.14, "tv": 24325.79, "trd": NaN, "batb": [[0, 1.13, 138.36]], "batl": [[0, 1.15, 302.32]]}, {"timestamp": 1631548604787, "ltp": 1.14, "tv": 24325.79, "trd": NaN, "batb": NaN, "batl": [[0, 1.15, 356.82]]}, {"timestamp": 1631548605984, "ltp": 1.14, "tv": 24325.79, "trd": NaN, "batb": [[0, 1.13, 127.25]], "batl": NaN}, {"timestamp": 1631548648943, "ltp": 1.14, "tv": 24325.79, "trd": NaN, "batb": [[1, 1.12, 343.25], [2, 1.11, 399.72]], "batl": [[2, 1.17, 176.5]]}, {"timestamp": 1631548651716, "ltp": 1.13, "tv": 24340.23, "trd": [[1.13, 137.85]], "batb": [[0, 1.13, 120.03]], "batl": NaN}, {"timestamp": 1631548653655, "ltp": 1.13, "tv": 24340.23, "trd": NaN, "batb": NaN, "batl": [[0, 1.15, 302.32], [1, 1.16, 100]]}, {"timestamp": 1631548654130, "ltp": 1.13, "tv": 24340.23, "trd": NaN, "batb": [[0, 1.12, 133.46], [1, 1.11, 399.72], [2, 1.1, 164.71]], "batl": [[0, 1.18, 275.47], [1, 1.2, 55.46], [2, 1.38, 987.41]]}, {"timestamp": 1631548656635, "ltp": 1.13, "tv": 24340.23, "trd": NaN, "batb": NaN, "batl": [[1, 1.19, 94], [2, 1.2, 161.46]]}, {"timestamp": 1631548657633, "ltp": 1.13, "tv": 24340.23, "trd": NaN, "batb": NaN, "batl": [[0, 1.18, 170.47], [1, 1.2, 55.46], [2, 1.38, 987.41]]}, {"timestamp": 1631548659657, "ltp": 1.13, "tv": 24340.73, "trd": [[1.13, 138.35]], "batb": [[0, 1.12, 133.21]], "batl": [[0, 1.13, 21.23], [1, 1.14, 625], [2, 1.15, 1584.25]]}, {"timestamp": 1631548660645, "ltp": 1.13, "tv": 24340.73, "trd": NaN, "batb": NaN, "batl": [[0, 1.13, 269.73], [1, 1.14, 104], [2, 1.15, 1554.11]]}, {"timestamp": 1631548666267, "ltp": 1.13, "tv": 24340.73, "trd": NaN, "batb": [[0, 1.12, 318]], "batl": [[2, 1.15, 1750.21]]}, {"timestamp": 1631548667569, "ltp": 1.13, "tv": 24340.73, "trd": NaN, "batb": [[0, 1.11, 696.91], [1, 1.1, 502.7], [2, 1.09, 564.93]], "batl": [[0, 1.15, 196.32], [1, 1.16, 296.22], [2, 1.18, 170.25]]}, {"timestamp": 1631548667727, "ltp": 1.13, "tv": 24340.73, "trd": NaN, "batb": NaN, "batl": [[0, 1.16, 296.44], [1, 1.18, 170.25], [2, 1.19, 175.41]]}, {"timestamp": 1631548670547, "ltp": 1.13, "tv": 24340.73, "trd": NaN, "batb": NaN, "batl": [[1, 1.17, 107], [2, 1.18, 280.25]]}, {"timestamp": 1631548673578, "ltp": 1.13, "tv": 24340.73, "trd": NaN, "batb": NaN, "batl": [[0, 1.16, 296.69]]}, {"timestamp": 1631548674550, "ltp": 1.13, "tv": 24340.73, "trd": NaN, "batb": NaN, "batl": [[0, 1.15, 185.77], [1, 1.16, 296.22], [2, 1.17, 107]]}, {"timestamp": 1631548674863, "ltp": 1.13, "tv": 24340.73, "trd": NaN, "batb": NaN, "batl": [[0, 1.16, 296.69], [1, 1.17, 107], [2, 1.18, 280.25]]}, {"timestamp": 1631548676059, "ltp": 1.13, "tv": 24340.73, "trd": NaN, "batb": [[0, 1.11, 399.92], [1, 1.1, 164.71], [2, 1.09, 161.21]], "batl": NaN}, {"timestamp": 1631548679354, "ltp": 1.14, "tv": 24340.98, "trd": [[1.14, 304.55]], "batb": [[0, 1.13, 127], [1, 1.12, 3936.03], [2, 1.11, 399.72]], "batl": [[0, 1.16, 296.44], [1, 1.17, 1035.34]]}, {"timestamp": 1631548695596, "ltp": 1.14, "tv": 24340.98, "trd": NaN, "batb": [[0, 1.12, 133.48], [1, 1.11, 154.13], [2, 1.1, 164.71]], "batl": [[0, 1.18, 280.47], [1, 1.19, 185.5], [2, 1.2, 224.34]]}, {"timestamp": 1631548695905, "ltp": 1.14, "tv": 24340.98, "trd": NaN, "batb": NaN, "batl": [[0, 1.18, 110.22]]}, {"timestamp": 1631548698570, "ltp": 1.14, "tv": 24340.98, "trd": NaN, "batb": NaN, "batl": [[1, 1.19, 286.5], [2, 1.2, 326.34]]}, {"timestamp": 1631548702595, "ltp": 1.14, "tv": 24340.98, "trd": NaN, "batb": NaN, "batl": [[0, 1.18, 277.47]]}, {"timestamp": 1631548703068, "ltp": 1.14, "tv": 24340.98, "trd": NaN, "batb": NaN, "batl": [[0, 1.18, 110.22], [1, 1.19, 101]]}, {"timestamp": 1631548706572, "ltp": 1.14, "tv": 24340.98, "trd": NaN, "batb": NaN, "batl": [[1, 1.19, 261.5]]}, {"timestamp": 1631548710379, "ltp": 1.14, "tv": 24340.98, "trd": NaN, "batb": NaN, "batl": [[1, 1.19, 101]]}, {"timestamp": 1631548713679, "ltp": 1.14, "tv": 24340.98, "trd": NaN, "batb": NaN, "batl": [[1, 1.19, 283.5], [2, 1.2, 224.34]]}, {"timestamp": 1631548713784, "ltp": 1.14, "tv": 24340.98, "trd": NaN, "batb": NaN, "batl": [[1, 1.19, 101]]}, {"timestamp": 1631548716680, "ltp": 1.15, "tv": 24341.2, "trd": [[1.15, 554.39]], "batb": [[0, 1.16, 113], [1, 1.14, 4813.91], [2, 1.13, 127.27]], "batl": [[0, 1.18, 110], [1, 1.19, 133.86]]}, {"timestamp": 1631548720697, "ltp": 1.17, "tv": 24344.81, "trd": [[1.17, 105.95]], "batb": NaN, "batl": NaN}, {"timestamp": 1631548730402, "ltp": 1.17, "tv": 24344.81, "trd": NaN, "batb": [[1, 1.14, 4814.14]], "batl": NaN}, {"timestamp": 1631548732432, "ltp": 1.17, "tv": 24344.81, "trd": NaN, "batb": [[0, 1.14, 121.23], [1, 1.13, 127.27], [2, 1.12, 133.21]], "batl": [[0, 1.2, 55.46], [1, 1.24, 161.23], [2, 1.26, 160.25]]}, {"timestamp": 1631548732742, "ltp": 1.17, "tv": 24344.81, "trd": NaN, "batb": NaN, "batl": [[1, 1.26, 160.25], [2, 1.39, 17.9]]}, {"timestamp": 1631548739561, "ltp": 1.17, "tv": 24344.81, "trd": NaN, "batb": NaN, "batl": [[0, 1.17, 72.2], [1, 1.2, 55.46], [2, 1.24, 164.23]]}, {"timestamp": 1631548739721, "ltp": 1.17, "tv": 24344.81, "trd": NaN, "batb": NaN, "batl": [[2, 1.26, 160.25]]}, {"timestamp": 1631548743851, "ltp": 1.17, "tv": 24356.57, "trd": [[1.17, 117.71]], "batb": NaN, "batl": [[0, 1.17, 66.32]]}, {"timestamp": 1631548746590, "ltp": 1.17, "tv": 24356.57, "trd": NaN, "batb": NaN, "batl": [[2, 1.24, 150.73]]}, {"timestamp": 1631548747535, "ltp": 1.17, "tv": 24356.57, "trd": NaN, "batb": [[1, 1.12, 133.48], [2, 1.11, 154.13]], "batl": [[2, 1.26, 160.25]]}, {"timestamp": 1631548750564, "ltp": 1.17, "tv": 24356.57, "trd": NaN, "batb": NaN, "batl": [[0, 1.16, 271.14], [1, 1.17, 170.32], [2, 1.18, 1069.37]]}, {"timestamp": 1631548771403, "ltp": 1.17, "tv": 24356.57, "trd": NaN, "batb": [[0, 1.12, 133.71], [1, 1.11, 154.13], [2, 1.1, 164.71]], "batl": [[0, 1.17, 66.32], [1, 1.2, 55.46], [2, 1.23, 152.5]]}, {"timestamp": 1631548774567, "ltp": 1.17, "tv": 24356.57, "trd": NaN, "batb": [[0, 1.16, 17.05], [1, 1.12, 133.71], [2, 1.11, 154.13]], "batl": [[2, 1.21, 156.5]]}, {"timestamp": 1631548774881, "ltp": 1.17, "tv": 24356.57, "trd": NaN, "batb": NaN, "batl": [[2, 1.23, 152.5]]}, {"timestamp": 1631548777707, "ltp": 1.17, "tv": 24356.57, "trd": NaN, "batb": [[1, 1.12, 145.74]], "batl": [[0, 1.2, 55.46], [1, 1.23, 152.5], [2, 1.31, 2]]}, {"timestamp": 1631548780698, "ltp": 1.14, "tv": 24393.93, "trd": [[1.14, 305.01], [1.16, 161.32]], "batb": [[0, 1.12, 145.5], [1, 1.11, 154.13], [2, 1.1, 164.71]], "batl": [[0, 1.14, 391.84], [1, 1.15, 154.47], [2, 1.17, 107]]}, {"timestamp": 1631548783166, "ltp": 1.14, "tv": 24410.67, "trd": [[1.14, 321.75]], "batb": NaN, "batl": [[0, 1.14, 383.47]]}, {"timestamp": 1631548784105, "ltp": 1.14, "tv": 24410.67, "trd": NaN, "batb": NaN, "batl": [[1, 1.15, 108]]}, {"timestamp": 1631548786714, "ltp": 1.14, "tv": 24410.67, "trd": NaN, "batb": [[0, 1.12, 364.79], [1, 1.11, 417.72]], "batl": [[2, 1.16, 198.22]]}, {"timestamp": 1631548790482, "ltp": 1.14, "tv": 24410.67, "trd": NaN, "batb": NaN, "batl": [[0, 1.14, 348.75]]}, {"timestamp": 1631548793620, "ltp": 1.14, "tv": 24410.67, "trd": NaN, "batb": [[0, 1.12, 12.5]], "batl": [[0, 1.16, 198.22], [1, 1.17, 282.5], [2, 1.2, 55.46]]}, {"timestamp": 1631548794311, "ltp": 1.14, "tv": 24410.67, "trd": NaN, "batb": NaN, "batl": [[0, 1.17, 282.5], [1, 1.2, 55.46], [2, 1.23, 152.5]]}, {"timestamp": 1631548796624, "ltp": 1.11, "tv": 24442.82, "trd": [[1.11, 31.99], [1.12, 46.94], [1.13, 138.88], [1.14, 324.91]], "batb": [[0, 1.12, 215.79], [1, 1.11, 415.72]], "batl": [[1, 1.18, 104], [2, 1.19, 107]]}, {"timestamp": 1631548797680, "ltp": 1.11, "tv": 24442.82, "trd": NaN, "batb": [[0, 1.11, 415.72], [1, 1.1, 164.71], [2, 1.09, 161.21]], "batl": NaN}, {"timestamp": 1631548799694, "ltp": 1.11, "tv": 24442.82, "trd": NaN, "batb": NaN, "batl": [[0, 1.17, 282.73]]}, {"timestamp": 1631548803592, "ltp": 1.11, "tv": 24442.82, "trd": NaN, "batb": [[0, 1.12, 202.54], [1, 1.11, 415.72], [2, 1.1, 164.71]], "batl": NaN}, {"timestamp": 1631548804227, "ltp": 1.11, "tv": 24442.82, "trd": NaN, "batb": [[0, 1.11, 415.72], [1, 1.1, 164.71], [2, 1.09, 161.21]], "batl": NaN}, {"timestamp": 1631548806338, "ltp": 1.11, "tv": 24442.82, "trd": NaN, "batb": [[0, 1.12, 12.03], [1, 1.11, 415.72], [2, 1.1, 164.71]], "batl": NaN}, {"timestamp": 1631548808540, "ltp": 1.11, "tv": 24442.82, "trd": NaN, "batb": [[0, 1.11, 415.72], [1, 1.1, 164.71], [2, 1.09, 161.21]], "batl": [[1, 1.23, 152.5], [2, 1.31, 2]]}, {"timestamp": 1631548810705, "ltp": 1.15, "tv": 24443.05, "trd": [[1.15, 554.62]], "batb": [[0, 1.12, 203.04], [1, 1.11, 415.72], [2, 1.1, 164.71]], "batl": [[0, 1.17, 319.81]]}, {"timestamp": 1631548811013, "ltp": 1.15, "tv": 24443.05, "trd": NaN, "batb": [[0, 1.14, 121], [1, 1.12, 336.04], [2, 1.11, 415.72]], "batl": [[0, 1.16, 95], [1, 1.17, 319.81], [2, 1.23, 152.5]]}, {"timestamp": 1631548813545, "ltp": 1.15, "tv": 24443.53, "trd": [[1.15, 555.09]], "batb": [[1, 1.13, 22.21], [2, 1.12, 336.04]], "batl": NaN}, {"timestamp": 1631548817153, "ltp": 1.15, "tv": 24443.53, "trd": NaN, "batb": NaN, "batl": [[0, 1.16, 104.02], [2, 1.21, 183.5]]}, {"timestamp": 1631548819560, "ltp": 1.15, "tv": 24468.73, "trd": [[1.15, 580.3]], "batb": NaN, "batl": NaN}, {"timestamp": 1631548820135, "ltp": 1.15, "tv": 24472.21, "trd": [[1.15, 583.78]], "batb": NaN, "batl": NaN}, {"timestamp": 1631548822644, "ltp": 1.15, "tv": 24472.21, "trd": NaN, "batb": [[1, 1.12, 336.04], [2, 1.11, 415.72]], "batl": NaN}, {"timestamp": 1631548826669, "ltp": 1.16, "tv": 24476.55, "trd": [[1.16, 165.66]], "batb": [[0, 1.14, 121.25], [1, 1.12, 348.07]], "batl": [[0, 1.16, 101.85]]}, {"timestamp": 1631548826730, "ltp": 1.16, "tv": 24476.55, "trd": NaN, "batb": [[0, 1.15, 323.16], [1, 1.14, 526.26], [2, 1.12, 348.07]], "batl": NaN}, {"timestamp": 1631548830457, "ltp": 1.16, "tv": 24476.55, "trd": NaN, "batb": NaN, "batl": [[1, 1.17, 1172.17]]}, {"timestamp": 1631548830878, "ltp": 1.15, "tv": 24765.35, "trd": [[1.15, 872.58]], "batb": [[0, 1.15, 178.75]], "batl": NaN}, {"timestamp": 1631548832583, "ltp": 1.15, "tv": 24765.35, "trd": NaN, "batb": NaN, "batl": [[2, 1.2, 55.46]]}, {"timestamp": 1631548833576, "ltp": 1.15, "tv": 24765.35, "trd": NaN, "batb": [[2, 1.12, 348.57]], "batl": [[1, 1.17, 1134.86]]}, {"timestamp": 1631548834053, "ltp": 1.15, "tv": 24765.35, "trd": NaN, "batb": [[0, 1.12, 145.78], [1, 1.11, 152.13], [2, 1.1, 164.71]], "batl": [[0, 1.16, 9.02], [1, 1.2, 55.46], [2, 1.21, 183.5]]}, {"timestamp": 1631548841321, "ltp": 1.15, "tv": 24765.35, "trd": NaN, "batb": [[0, 1.12, 133.75]], "batl": NaN}, {"timestamp": 1631548842381, "ltp": 1.14, "tv": 24765.85, "trd": [[1.14, 325.4]], "batb": [[0, 1.13, 924.63], [1, 1.12, 133.22], [2, 1.11, 152.13]], "batl": [[0, 1.14, 352.5], [1, 1.15, 141.78], [2, 1.16, 1184.57]]}, {"timestamp": 1631548848292, "ltp": 1.14, "tv": 24765.85, "trd": NaN, "batb": [[1, 1.12, 343.76], [2, 1.11, 371.72]], "batl": [[2, 1.16, 1388.29]]}, {"timestamp": 1631548849299, "ltp": 1.14, "tv": 24765.85, "trd": NaN, "batb": [[0, 1.13, 1315.15], [1, 1.12, 1092.95], [2, 1.11, 643.16]], "batl": NaN}, {"timestamp": 1631548851199, "ltp": 1.14, "tv": 24765.85, "trd": NaN, "batb": NaN, "batl": [[0, 1.14, 362.81]]}, {"timestamp": 1631548853501, "ltp": 1.14, "tv": 24765.85, "trd": NaN, "batb": NaN, "batl": [[0, 1.14, 749.06], [1, 1.15, 545.09]]}, {"timestamp": 1631548856604, "ltp": 1.14, "tv": 24765.85, "trd": NaN, "batb": NaN, "batl": [[2, 1.16, 1379.27]]}, {"timestamp": 1631548858295, "ltp": 1.14, "tv": 24765.85, "trd": NaN, "batb": NaN, "batl": [[1, 1.15, 545.33]]}, {"timestamp": 1631548861707, "ltp": 1.14, "tv": 24765.85, "trd": NaN, "batb": [[0, 1.12, 627.68], [1, 1.11, 643.16], [2, 1.1, 461.52]], "batl": [[0, 1.14, 108.31], [1, 1.15, 107.25], [2, 1.16, 203.72]]}, {"timestamp": 1631548862182, "ltp": 1.14, "tv": 24765.85, "trd": NaN, "batb": [[0, 1.12, 494.68]], "batl": [[0, 1.14, 10.31], [1, 1.17, 288.75], [2, 1.2, 55.46]]}, {"timestamp": 1631548864800, "ltp": 1.14, "tv": 24765.85, "trd": NaN, "batb": NaN, "batl": [[2, 1.18, 101]]}, {"timestamp": 1631548866426, "ltp": 1.14, "tv": 24772.16, "trd": [[1.14, 331.71]], "batb": [[0, 1.11, 372.23], [1, 1.1, 164.71], [2, 1.09, 161.21]], "batl": [[0, 1.14, 4], [2, 1.2, 55.46]]}, {"timestamp": 1631548867728, "ltp": 1.14, "tv": 24772.16, "trd": NaN, "batb": NaN, "batl": [[0, 1.17, 288.75], [1, 1.2, 55.46], [2, 1.21, 377.87]]}, {"timestamp": 1631548869093, "ltp": 1.16, "tv": 24798.53, "trd": [[1.15, 872.82], [1.16, 191.79]], "batb": [[0, 1.14, 121], [1, 1.12, 133.51], [2, 1.11, 371.72]], "batl": [[0, 1.16, 76.87], [1, 1.17, 288.5], [2, 1.19, 907.62]]}, {"timestamp": 1631548871390, "ltp": 1.16, "tv": 24798.53, "trd": NaN, "batb": [[1, 1.13, 11.39], [2, 1.12, 133.22]], "batl": NaN}, {"timestamp": 1631548871915, "ltp": 1.16, "tv": 24798.53, "trd": NaN, "batb": [[0, 1.14, 131.31]], "batl": NaN}, {"timestamp": 1631548876036, "ltp": 1.16, "tv": 24798.53, "trd": NaN, "batb": [[1, 1.13, 231.1], [2, 1.12, 412.34]], "batl": NaN}, {"timestamp": 1631548877238, "ltp": 1.16, "tv": 24798.53, "trd": NaN, "batb": [[0, 1.14, 121]], "batl": NaN}, {"timestamp": 1631548882244, "ltp": 1.16, "tv": 24798.53, "trd": NaN, "batb": NaN, "batl": [[1, 1.17, 330.14]]}, {"timestamp": 1631548883642, "ltp": 1.16, "tv": 24798.53, "trd": NaN, "batb": [[0, 1.13, 231.1], [1, 1.12, 412.34], [2, 1.11, 486.41]], "batl": [[0, 1.2, 55.46], [1, 1.23, 6], [2, 1.25, 322.9]]}, {"timestamp": 1631548886626, "ltp": 1.16, "tv": 24798.53, "trd": NaN, "batb": NaN, "batl": [[1, 1.22, 164.25], [2, 1.23, 6]]}, {"timestamp": 1631548887251, "ltp": 1.16, "tv": 24798.53, "trd": NaN, "batb": [[0, 1.13, 231.36]], "batl": [[1, 1.23, 6], [2, 1.25, 322.9]]}, {"timestamp": 1631548900466, "ltp": 1.16, "tv": 24798.53, "trd": NaN, "batb": NaN, "batl": [[1, 1.22, 154.25], [2, 1.23, 6]]}, {"timestamp": 1631548900734, "ltp": 1.16, "tv": 24798.53, "trd": NaN, "batb": NaN, "batl": [[1, 1.23, 6], [2, 1.25, 322.9]]}, {"timestamp": 1631548905379, "ltp": 1.13, "tv": 24802.53, "trd": [[1.13, 142.36], [1.14, 332.23]], "batb": [[0, 1.13, 229.36]], "batl": NaN}, {"timestamp": 1631548907445, "ltp": 1.13, "tv": 24802.53, "trd": NaN, "batb": NaN, "batl": [[1, 1.22, 164.25], [2, 1.23, 6]]}, {"timestamp": 1631548908651, "ltp": 1.13, "tv": 24802.53, "trd": NaN, "batb": NaN, "batl": [[1, 1.23, 6], [2, 1.25, 322.9]]}, {"timestamp": 1631548917301, "ltp": 1.13, "tv": 24802.53, "trd": NaN, "batb": [[0, 1.13, 9.65], [1, 1.12, 133.22], [2, 1.11, 152.13]], "batl": NaN}, {"timestamp": 1631548918659, "ltp": 1.13, "tv": 24802.53, "trd": NaN, "batb": NaN, "batl": [[1, 1.22, 169.75], [2, 1.23, 6]]}, {"timestamp": 1631548919453, "ltp": 1.13, "tv": 24802.53, "trd": NaN, "batb": NaN, "batl": [[1, 1.23, 6], [2, 1.25, 322.9]]}, {"timestamp": 1631548920601, "ltp": 1.2, "tv": 24860.56, "trd": [[1.2, 60.81]], "batb": [[0, 1.14, 121], [1, 1.13, 136.65], [2, 1.12, 133.22]], "batl": [[0, 1.2, 16.77], [1, 1.22, 35.27], [2, 1.23, 6]]}, {"timestamp": 1631548922594, "ltp": 1.19, "tv": 24861.1, "trd": [[1.19, 0.54]], "batb": NaN, "batl": NaN}, {"timestamp": 1631548927389, "ltp": 1.19, "tv": 24861.1, "trd": NaN, "batb": [[0, 1.15, 8.83], [1, 1.14, 129.89], [2, 1.13, 146.38]], "batl": NaN}, {"timestamp": 1631548930511, "ltp": 1.19, "tv": 24861.1, "trd": NaN, "batb": NaN, "batl": [[1, 1.23, 6], [2, 1.25, 800.42]]}, {"timestamp": 1631548932081, "ltp": 1.19, "tv": 24861.1, "trd": NaN, "batb": NaN, "batl": [[0, 1.23, 6], [1, 1.25, 800.42], [2, 1.26, 182.67]]}, {"timestamp": 1631548933487, "ltp": 1.19, "tv": 24863.21, "trd": [[1.19, 2.65]], "batb": NaN, "batl": [[0, 1.21, 38.38], [1, 1.23, 6], [2, 1.25, 800.42]]}, {"timestamp": 1631548935602, "ltp": 1.19, "tv": 24879.98, "trd": [[1.19, 19.42]], "batb": [[1, 1.14, 130.16]], "batl": NaN}, {"timestamp": 1631548942410, "ltp": 1.19, "tv": 24879.98, "trd": NaN, "batb": [[2, 1.13, 146.67]], "batl": NaN}, {"timestamp": 1631548949634, "ltp": 1.19, "tv": 24879.98, "trd": NaN, "batb": [[0, 1.14, 121.27], [1, 1.13, 146.67], [2, 1.12, 133.22]], "batl": [[0, 1.23, 6], [1, 1.31, 2], [2, 1.39, 17.9]]}, {"timestamp": 1631548950430, "ltp": 1.19, "tv": 24879.98, "trd": NaN, "batb": NaN, "batl": [[0, 1.19, 9.02], [1, 1.23, 6], [2, 1.31, 2]]}, {"timestamp": 1631548956507, "ltp": 1.19, "tv": 24879.98, "trd": NaN, "batb": [[0, 1.15, 8.03], [1, 1.14, 121.27], [2, 1.13, 146.67]], "batl": NaN}, {"timestamp": 1631548957539, "ltp": 1.19, "tv": 24889.0, "trd": [[1.19, 28.44]], "batb": [[0, 1.14, 121.27], [1, 1.13, 146.67], [2, 1.12, 133.22]], "batl": [[0, 1.23, 6], [1, 1.31, 2], [2, 1.39, 17.9]]}, {"timestamp": 1631548957745, "ltp": 1.19, "tv": 24889.0, "trd": NaN, "batb": [[0, 1.15, 117], [1, 1.14, 121.27], [2, 1.13, 146.67]], "batl": NaN}, {"timestamp": 1631548959325, "ltp": 1.19, "tv": 24889.0, "trd": NaN, "batb": NaN, "batl": [[0, 1.23, 25.5]]}, {"timestamp": 1631548960353, "ltp": 1.19, "tv": 24889.0, "trd": NaN, "batb": NaN, "batl": [[0, 1.23, 6]]}, {"timestamp": 1631548963653, "ltp": 1.19, "tv": 24889.0, "trd": NaN, "batb": [[0, 1.15, 125.23]], "batl": [[2, 1.35, 119.3]]}, {"timestamp": 1631548963817, "ltp": 1.19, "tv": 24889.0, "trd": NaN, "batb": [[0, 1.15, 117]], "batl": [[2, 1.39, 17.9]]}, {"timestamp": 1631548970635, "ltp": 1.19, "tv": 24889.0, "trd": NaN, "batb": NaN, "batl": [[2, 1.35, 131.9]]}, {"timestamp": 1631548971051, "ltp": 1.19, "tv": 24889.0, "trd": NaN, "batb": NaN, "batl": [[2, 1.39, 17.9]]}, {"timestamp": 1631548976346, "ltp": 1.23, "tv": 24895.0, "trd": [[1.23, 111.73]], "batb": [[0, 1.29, 31], [1, 1.28, 97.19], [2, 1.2, 100]], "batl": [[0, 1.3, 24.86], [2, 1.4, 123.46]]}, {"timestamp": 1631548977337, "ltp": 1.3, "tv": 24900.64, "trd": [[1.3, 7.26]], "batb": NaN, "batl": [[0, 1.3, 19.22]]}, {"timestamp": 1631548979568, "ltp": 1.29, "tv": 24962.64, "trd": [[1.29, 62.7]], "batb": [[0, 1.28, 97.19], [1, 1.2, 100], [2, 1.19, 103]], "batl": NaN}, {"timestamp": 1631548987660, "ltp": 1.29, "tv": 24962.64, "trd": NaN, "batb": [[0, 1.28, 71]], "batl": [[0, 1.31, 2], [1, 1.4, 123.46], [2, 1.94, 3.08]]}, {"timestamp": 1631548990475, "ltp": 1.29, "tv": 24962.64, "trd": NaN, "batb": NaN, "batl": [[0, 1.3, 19.22], [1, 1.31, 2], [2, 1.4, 123.46]]}, {"timestamp": 1631548998277, "ltp": 1.3, "tv": 24967.5, "trd": [[1.3, 12.13]], "batb": NaN, "batl": [[0, 1.3, 16.79]]}, {"timestamp": 1631548999678, "ltp": 1.28, "tv": 24969.34, "trd": [[1.28, 32.92]], "batb": [[0, 1.28, 70.08]], "batl": NaN}, {"timestamp": 1631549000405, "ltp": 1.28, "tv": 24969.34, "trd": NaN, "batb": NaN, "batl": [[0, 1.3, 255.53], [1, 1.31, 298.73], [2, 1.33, 195.5]]}, {"timestamp": 1631549001598, "ltp": 1.28, "tv": 24969.34, "trd": NaN, "batb": [[1, 1.21, 277.11], [2, 1.2, 408.66]], "batl": [[2, 1.4, 123.46]]}, {"timestamp": 1631549007478, "ltp": 1.28, "tv": 24969.34, "trd": NaN, "batb": NaN, "batl": [[2, 1.33, 183.5]]}, {"timestamp": 1631549008595, "ltp": 1.28, "tv": 24969.34, "trd": NaN, "batb": NaN, "batl": [[0, 1.3, 238.74], [2, 1.4, 123.46]]}, {"timestamp": 1631549011510, "ltp": 1.28, "tv": 24969.34, "trd": NaN, "batb": [[1, 1.27, 606.05], [2, 1.21, 277.11]], "batl": [[0, 1.3, 16.79]]}, {"timestamp": 1631549012185, "ltp": 1.28, "tv": 24969.34, "trd": NaN, "batb": NaN, "batl": [[1, 1.31, 296.73]]}, {"timestamp": 1631549015424, "ltp": 1.28, "tv": 24969.34, "trd": NaN, "batb": NaN, "batl": [[2, 1.33, 194.5]]}, {"timestamp": 1631549016006, "ltp": 1.28, "tv": 24969.34, "trd": NaN, "batb": [[1, 1.2, 100], [2, 1.19, 103]], "batl": [[1, 1.4, 123.46], [2, 1.94, 3.08]]}, {"timestamp": 1631549019332, "ltp": 1.3, "tv": 24970.1, "trd": [[1.3, 12.89]], "batb": NaN, "batl": [[0, 1.3, 16.41]]}, {"timestamp": 1631549021613, "ltp": 1.3, "tv": 24970.1, "trd": NaN, "batb": NaN, "batl": [[0, 1.4, 123.46], [1, 1.94, 3.08], [2, 3.8, 27.43]]}, {"timestamp": 1631549022607, "ltp": 1.3, "tv": 24970.1, "trd": NaN, "batb": [[0, 1.2, 100], [1, 1.19, 103], [2, 1.18, 106]], "batl": [[0, 1.33, 173.5], [1, 1.4, 123.46], [2, 1.94, 3.08]]}, {"timestamp": 1631549028448, "ltp": 1.3, "tv": 24970.1, "trd": NaN, "batb": [[0, 1.2, 100.26]], "batl": NaN}, {"timestamp": 1631549029543, "ltp": 1.3, "tv": 24970.1, "trd": NaN, "batb": [[0, 1.2, 100.52]], "batl": NaN}, {"timestamp": 1631549030117, "ltp": 1.33, "tv": 25307.42, "trd": [[1.33, 370.48]], "batb": [[0, 1.31, 65], [1, 1.3, 4.3], [2, 1.2, 100]], "batl": [[0, 1.4, 123.46], [1, 1.94, 3.08], [2, 3.8, 27.43]]}, {"timestamp": 1631549033313, "ltp": 1.33, "tv": 25320.86, "trd": [[1.33, 383.92]], "batb": NaN, "batl": NaN}, {"timestamp": 1631549036559, "ltp": 1.33, "tv": 25320.86, "trd": NaN, "batb": [[2, 1.28, 96.82]], "batl": [[0, 1.34, 98.25], [1, 1.4, 123.46], [2, 1.94, 3.08]]}, {"timestamp": 1631549040520, "ltp": 1.33, "tv": 25320.86, "trd": NaN, "batb": [[2, 1.29, 81.24]], "batl": [[1, 1.36, 93.32], [2, 1.37, 97.5]]}, {"timestamp": 1631549042663, "ltp": 1.33, "tv": 25320.86, "trd": NaN, "batb": [[0, 1.3, 4.3], [1, 1.27, 4.87], [2, 1.2, 100]], "batl": [[0, 1.4, 123.46], [1, 1.94, 3.08], [2, 3.8, 27.43]]}, {"timestamp": 1631549043127, "ltp": 1.35, "tv": 25321.12, "trd": [[1.35, 9965.18]], "batb": [[1, 1.2, 100], [2, 1.19, 103]], "batl": NaN}, {"timestamp": 1631549044530, "ltp": 1.35, "tv": 25321.12, "trd": NaN, "batb": [[0, 1.3, 3.78]], "batl": NaN}, {"timestamp": 1631549046560, "ltp": 1.35, "tv": 25321.12, "trd": NaN, "batb": [[1, 1.27, 92.87], [2, 1.2, 100]], "batl": [[0, 1.37, 86.5], [1, 1.4, 123.46], [2, 1.94, 3.08]]}, {"timestamp": 1631549047661, "ltp": 1.35, "tv": 25321.12, "trd": NaN, "batb": [[2, 1.2, 100.52]], "batl": NaN}, {"timestamp": 1631549049546, "ltp": 1.35, "tv": 25321.12, "trd": NaN, "batb": [[1, 1.27, 97.48]], "batl": NaN}, {"timestamp": 1631549049856, "ltp": 1.35, "tv": 25321.12, "trd": NaN, "batb": [[1, 1.27, 92.87]], "batl": [[2, 1.94, 3.33]]}, {"timestamp": 1631549056688, "ltp": 1.35, "tv": 25321.12, "trd": NaN, "batb": [[1, 1.27, 97.74]], "batl": NaN}, {"timestamp": 1631549057180, "ltp": 1.35, "tv": 25321.12, "trd": NaN, "batb": [[0, 1.27, 92.87], [1, 1.2, 100.52], [2, 1.19, 103]], "batl": [[0, 1.4, 123.46], [1, 1.94, 3.33], [2, 3.8, 27.43]]}, {"timestamp": 1631549059686, "ltp": 1.35, "tv": 25321.12, "trd": NaN, "batb": [[0, 1.29, 697.99], [1, 1.27, 92.87], [2, 1.2, 100.52]], "batl": [[0, 1.31, 909.64], [1, 1.32, 108.11], [2, 1.34, 679.37]]}, {"timestamp": 1631549059952, "ltp": 1.31, "tv": 25324.6, "trd": [[1.31, 3.52]], "batb": [[1, 1.27, 166.87]], "batl": [[0, 1.32, 108.11], [1, 1.34, 679.37], [2, 1.4, 123.46]]}, {"timestamp": 1631549066666, "ltp": 1.31, "tv": 25336.74, "trd": [[1.31, 15.65]], "batb": [[2, 1.24, 118.77]], "batl": [[1, 1.33, 90.5], [2, 1.34, 776.62]]}, {"timestamp": 1631549072964, "ltp": 1.31, "tv": 25336.74, "trd": NaN, "batb": NaN, "batl": [[0, 1.31, 17.84], [1, 1.32, 108.11], [2, 1.33, 90.5]]}, {"timestamp": 1631549076961, "ltp": 1.31, "tv": 25336.74, "trd": NaN, "batb": NaN, "batl": [[0, 1.32, 108.11], [1, 1.33, 90.5], [2, 1.34, 776.62]]}, {"timestamp": 1631549079886, "ltp": 1.31, "tv": 25336.74, "trd": NaN, "batb": NaN, "batl": [[0, 1.31, 17.84], [1, 1.32, 108.11], [2, 1.33, 90.5]]}, {"timestamp": 1631549085668, "ltp": 1.31, "tv": 25343.15, "trd": [[1.31, 22.06]], "batb": NaN, "batl": [[0, 1.31, 11.43]]}, {"timestamp": 1631549087189, "ltp": 1.31, "tv": 25343.15, "trd": NaN, "batb": [[0, 1.22, 113.36], [1, 1.2, 100], [2, 1.19, 103]], "batl": [[0, 1.34, 97.25], [1, 1.4, 123.46], [2, 1.44, 94.65]]}, {"timestamp": 1631549090616, "ltp": 1.31, "tv": 25343.15, "trd": NaN, "batb": [[0, 1.24, 100.77], [1, 1.22, 113.36], [2, 1.2, 100]], "batl": NaN}, {"timestamp": 1631549090780, "ltp": 1.31, "tv": 25343.15, "trd": NaN, "batb": [[0, 1.22, 113.36], [1, 1.2, 100], [2, 1.19, 103]], "batl": NaN}, {"timestamp": 1631549093703, "ltp": 1.31, "tv": 25343.15, "trd": NaN, "batb": [[0, 1.3, 153.84], [1, 1.22, 113.36], [2, 1.2, 100]], "batl": NaN}, {"timestamp": 1631549094234, "ltp": 1.33, "tv": 25538.15, "trd": [[1.33, 578.92]], "batb": [[0, 1.33, 415.57], [1, 1.31, 65], [2, 1.3, 30.76]], "batl": [[1, 1.35, 15], [2, 1.38, 628.63]]}, {"timestamp": 1631549095893, "ltp": 1.33, "tv": 25538.15, "trd": NaN, "batb": NaN, "batl": [[1, 1.38, 628.63], [2, 1.4, 123.46]]}, {"timestamp": 1631549098813, "ltp": 1.34, "tv": 25562.02, "trd": [[1.34, 1974.96]], "batb": [[0, 1.33, 429.13]], "batl": [[0, 1.34, 85.31]]}, {"timestamp": 1631549100605, "ltp": 1.34, "tv": 25562.02, "trd": NaN, "batb": NaN, "batl": [[1, 1.36, 67.07], [2, 1.37, 69.5]]}, {"timestamp": 1631549104035, "ltp": 1.34, "tv": 25562.02, "trd": NaN, "batb": [[0, 1.33, 415.57]], "batl": NaN}, {"timestamp": 1631549107631, "ltp": 1.33, "tv": 25885.32, "trd": [[1.33, 902.22]], "batb": [[0, 1.33, 267.48]], "batl": NaN}, {"timestamp": 1631549117640, "ltp": 1.33, "tv": 25885.32, "trd": NaN, "batb": [[2, 1.3, 15.38]], "batl": NaN}, {"timestamp": 1631549118158, "ltp": 1.33, "tv": 25885.32, "trd": NaN, "batb": [[0, 1.27, 97.87], [1, 1.2, 100.52], [2, 1.19, 103]], "batl": [[0, 1.4, 123.46], [1, 1.44, 94.65], [2, 1.94, 3.33]]}, {"timestamp": 1631549121562, "ltp": 1.33, "tv": 25885.32, "trd": NaN, "batb": [[0, 1.34, 10], [1, 1.27, 97.87], [2, 1.2, 100.52]], "batl": [[0, 1.37, 60.5], [1, 1.4, 123.46], [2, 1.44, 94.65]]}, {"timestamp": 1631549124685, "ltp": 1.34, "tv": 25895.32, "trd": [[1.34, 1984.96]], "batb": [[0, 1.27, 97.87], [1, 1.2, 100.52], [2, 1.19, 103]], "batl": [[0, 1.36, 72.57], [1, 1.37, 60.5], [2, 1.4, 123.46]]}, {"timestamp": 1631549125061, "ltp": 1.34, "tv": 25895.32, "trd": NaN, "batb": NaN, "batl": [[0, 1.37, 60.5], [1, 1.4, 123.46], [2, 1.44, 94.65]]}, {"timestamp": 1631549131654, "ltp": 1.34, "tv": 25895.32, "trd": NaN, "batb": [[0, 1.29, 79.81], [1, 1.27, 97.87], [2, 1.2, 100.52]], "batl": [[0, 1.36, 70.57], [1, 1.37, 60.5], [2, 1.4, 123.46]]}, {"timestamp": 1631549131971, "ltp": 1.34, "tv": 25895.32, "trd": NaN, "batb": [[0, 1.27, 97.87], [1, 1.2, 100.52], [2, 1.19, 103]], "batl": [[0, 1.37, 60.5], [1, 1.4, 123.46], [2, 1.44, 94.65]]}, {"timestamp": 1631549142567, "ltp": 1.34, "tv": 25895.32, "trd": NaN, "batb": [[0, 1.29, 72.81], [1, 1.27, 97.87], [2, 1.2, 100.52]], "batl": [[0, 1.36, 62.82], [1, 1.37, 60.5], [2, 1.4, 123.46]]}, {"timestamp": 1631549143173, "ltp": 1.34, "tv": 25895.32, "trd": NaN, "batb": [[0, 1.28, 98.33]], "batl": [[0, 1.3, 22.31], [1, 1.31, 45.5], [2, 1.32, 30.3]]}, {"timestamp": 1631549148784, "ltp": 1.28, "tv": 25911.16, "trd": [[1.28, 48.76]], "batb": [[0, 1.28, 90.41]], "batl": NaN}, {"timestamp": 1631549150262, "ltp": 1.28, "tv": 25911.16, "trd": NaN, "batb": [[2, 1.22, 116.86]], "batl": NaN}, {"timestamp": 1631549158990, "ltp": 1.28, "tv": 25911.16, "trd": NaN, "batb": [[0, 1.28, 71]], "batl": [[0, 1.31, 45.5], [1, 1.32, 30.3], [2, 1.34, 65.75]]}, {"timestamp": 1631549161926, "ltp": 1.28, "tv": 25911.16, "trd": NaN, "batb": [[0, 1.28, 90.41]], "batl": NaN}, {"timestamp": 1631549169704, "ltp": 1.28, "tv": 25911.16, "trd": NaN, "batb": NaN, "batl": [[1, 1.32, 15.15]]}, {"timestamp": 1631549170124, "ltp": 1.28, "tv": 25911.16, "trd": NaN, "batb": [[0, 1.2, 100.52], [1, 1.19, 250.71], [2, 1.18, 106]], "batl": [[0, 1.36, 73.32], [1, 1.4, 123.46], [2, 1.44, 94.65]]}, {"timestamp": 1631549173613, "ltp": 1.28, "tv": 25911.16, "trd": NaN, "batb": [[0, 1.22, 98.86], [1, 1.2, 100], [2, 1.19, 250.71]], "batl": NaN}, {"timestamp": 1631549174711, "ltp": 1.28, "tv": 25911.16, "trd": NaN, "batb": [[0, 1.2, 100.52], [1, 1.19, 250.71], [2, 1.18, 106]], "batl": [[0, 1.32, 464.25], [1, 1.36, 73.32], [2, 1.4, 123.46]]}, {"timestamp": 1631549175703, "ltp": 1.28, "tv": 25911.16, "trd": NaN, "batb": NaN, "batl": [[0, 1.29, 21.5]]}, {"timestamp": 1631549176013, "ltp": 1.28, "tv": 25911.16, "trd": NaN, "batb": NaN, "batl": [[0, 1.36, 73.32], [1, 1.4, 123.46], [2, 1.44, 94.65]]}, {"timestamp": 1631549179314, "ltp": 1.28, "tv": 25911.16, "trd": NaN, "batb": [[0, 1.21, 7.39], [1, 1.2, 100], [2, 1.19, 250.71]], "batl": NaN}, {"timestamp": 1631549184401, "ltp": 1.28, "tv": 25911.16, "trd": NaN, "batb": [[0, 1.22, 131.36], [1, 1.21, 6.87], [2, 1.2, 100]], "batl": NaN}, {"timestamp": 1631549185440, "ltp": 1.28, "tv": 25911.16, "trd": NaN, "batb": [[0, 1.22, 7.08]], "batl": NaN}, {"timestamp": 1631549187332, "ltp": 1.28, "tv": 25911.16, "trd": NaN, "batb": NaN, "batl": [[0, 1.34, 86.25], [1, 1.36, 73.32], [2, 1.4, 123.46]]}, {"timestamp": 1631549188222, "ltp": 1.28, "tv": 25911.16, "trd": NaN, "batb": NaN, "batl": [[0, 1.36, 73.32], [1, 1.4, 123.46], [2, 1.44, 94.65]]}, {"timestamp": 1631549195642, "ltp": 1.28, "tv": 25911.16, "trd": NaN, "batb": [[2, 1.19, 147.71]], "batl": NaN}, {"timestamp": 1631549195955, "ltp": 1.28, "tv": 25911.16, "trd": NaN, "batb": NaN, "batl": [[0, 1.4, 123.46], [1, 1.44, 94.65], [2, 1.94, 3.33]]}, {"timestamp": 1631549197048, "ltp": 1.28, "tv": 25911.16, "trd": NaN, "batb": [[1, 1.19, 147.71], [2, 1.14, 121.27]], "batl": NaN}, {"timestamp": 1631549198663, "ltp": 1.28, "tv": 25911.16, "trd": NaN, "batb": [[0, 1.21, 95.52]], "batl": [[0, 1.24, 91.07], [1, 1.3, 2625.95], [2, 1.4, 123.46]]}, {"timestamp": 1631549205237, "ltp": 1.28, "tv": 25911.16, "trd": NaN, "batb": NaN, "batl": [[2, 1.33, 83.5]]}, {"timestamp": 1631549206451, "ltp": 1.22, "tv": 25922.66, "trd": [[1.22, 11.5]], "batb": [[0, 1.21, 95]], "batl": NaN}, {"timestamp": 1631549208470, "ltp": 1.22, "tv": 25922.66, "trd": NaN, "batb": NaN, "batl": [[1, 1.3, 2696.2]]}, {"timestamp": 1631549216646, "ltp": 1.22, "tv": 25922.66, "trd": NaN, "batb": NaN, "batl": [[0, 1.24, 52.48]]}, {"timestamp": 1631549219562, "ltp": 1.22, "tv": 25922.66, "trd": NaN, "batb": [[0, 1.22, 16.82], [1, 1.21, 95], [2, 1.19, 147.71]], "batl": [[0, 1.23, 17.45], [1, 1.24, 52.48], [2, 1.3, 2696.2]]}, {"timestamp": 1631549224085, "ltp": 1.22, "tv": 25922.66, "trd": NaN, "batb": [[0, 1.14, 121.27], [1, 1.13, 331.67], [2, 1.12, 133.22]], "batl": [[0, 1.33, 83.5], [1, 1.4, 123.96], [2, 1.44, 94.65]]}, {"timestamp": 1631549244692, "ltp": 1.22, "tv": 25922.66, "trd": NaN, "batb": NaN, "batl": [[0, 1.3, 87.85], [1, 1.33, 83.5], [2, 1.4, 123.96]]}, {"timestamp": 1631549244902, "ltp": 1.22, "tv": 25922.66, "trd": NaN, "batb": NaN, "batl": [[0, 1.33, 83.5], [1, 1.4, 123.96], [2, 1.44, 94.65]]}, {"timestamp": 1631549249598, "ltp": 1.22, "tv": 25922.66, "trd": NaN, "batb": [[0, 1.13, 331.95], [1, 1.12, 133.22], [2, 1.11, 152.13]], "batl": [[0, 1.4, 123.96], [1, 1.44, 94.65], [2, 1.94, 3.33]]}, {"timestamp": 1631549249901, "ltp": 1.22, "tv": 25922.66, "trd": NaN, "batb": [[0, 1.13, 137.22]], "batl": NaN}, {"timestamp": 1631549252529, "ltp": 1.22, "tv": 25922.66, "trd": NaN, "batb": [[0, 1.15, 117], [1, 1.13, 137.22], [2, 1.12, 133.22]], "batl": [[0, 1.16, 64.22], [1, 1.17, 91], [2, 1.18, 99]]}, {"timestamp": 1631549252737, "ltp": 1.22, "tv": 25922.66, "trd": NaN, "batb": [[1, 1.13, 127.57]], "batl": NaN}, {"timestamp": 1631549262513, "ltp": 1.15, "tv": 25928.16, "trd": [[1.15, 878.32]], "batb": [[0, 1.15, 114.25]], "batl": NaN}, {"timestamp": 1631549266622, "ltp": 1.16, "tv": 25935.38, "trd": [[1.16, 199.01]], "batb": NaN, "batl": [[0, 1.16, 60.61]]}, {"timestamp": 1631549275721, "ltp": 1.16, "tv": 25942.34, "trd": [[1.16, 205.97]], "batb": NaN, "batl": [[0, 1.16, 57.13]]}, {"timestamp": 1631549297784, "ltp": 1.16, "tv": 25942.34, "trd": NaN, "batb": NaN, "batl": [[1, 1.17, 141.61]]}, {"timestamp": 1631549302668, "ltp": 1.16, "tv": 25942.34, "trd": NaN, "batb": NaN, "batl": [[1, 1.17, 91], [2, 1.19, 91]]}, {"timestamp": 1631549305579, "ltp": 1.16, "tv": 25942.42, "trd": [[1.16, 206.05]], "batb": NaN, "batl": [[0, 1.16, 166.09], [1, 1.17, 141.61]]}, {"timestamp": 1631549342849, "ltp": 1.16, "tv": 25942.42, "trd": NaN, "batb": [[1, 1.13, 315.3]], "batl": NaN}, {"timestamp": 1631549346036, "ltp": 1.16, "tv": 25942.42, "trd": NaN, "batb": [[1, 1.14, 121.27], [2, 1.13, 315.03]], "batl": NaN}, {"timestamp": 1631549366678, "ltp": 1.16, "tv": 25942.42, "trd": NaN, "batb": [[0, 1.14, 121.27], [1, 1.13, 315.03], [2, 1.12, 133.22]], "batl": [[0, 1.19, 91], [1, 1.2, 107.43], [2, 1.22, 105.25]]}, {"timestamp": 1631549367406, "ltp": 1.16, "tv": 25942.42, "trd": NaN, "batb": NaN, "batl": [[1, 1.22, 105.25], [2, 1.34, 168.22]]}, {"timestamp": 1631549369569, "ltp": 1.16, "tv": 25942.42, "trd": NaN, "batb": NaN, "batl": [[1, 1.2, 96], [2, 1.22, 105.25]]}, {"timestamp": 1631549377766, "ltp": 1.16, "tv": 25942.42, "trd": NaN, "batb": NaN, "batl": [[0, 1.2, 96], [1, 1.22, 105.25], [2, 1.34, 168.22]]}, {"timestamp": 1631549382880, "ltp": 1.16, "tv": 25942.42, "trd": NaN, "batb": NaN, "batl": [[0, 1.22, 105.25], [1, 1.34, 168.22], [2, 1.39, 18.43]]}, {"timestamp": 1631549385594, "ltp": 1.16, "tv": 25942.42, "trd": NaN, "batb": NaN, "batl": [[0, 1.15, 39.33], [1, 1.16, 781.17], [2, 1.22, 105.25]]}, {"timestamp": 1631549385853, "ltp": 1.16, "tv": 25942.42, "trd": NaN, "batb": NaN, "batl": [[0, 1.15, 132.33], [1, 1.16, 872.17], [2, 1.18, 99]]}, {"timestamp": 1631549392559, "ltp": 1.16, "tv": 25942.42, "trd": NaN, "batb": [[2, 1.12, 347.01]], "batl": [[2, 1.17, 140.5]]}, {"timestamp": 1631549394615, "ltp": 1.16, "tv": 25942.42, "trd": NaN, "batb": [[0, 1.13, 127.57], [1, 1.12, 347.01], [2, 1.11, 141]], "batl": [[0, 1.18, 246.75], [1, 1.34, 168.22], [2, 1.39, 18.43]]}, {"timestamp"