{"info": {"id": "1.187594321", "eventId": "30897905", "eventName": "Match Odds", "marketType": "MATCH_ODDS", "openDate": 1631545259120, "name": "I Rosca v C Cervino Ruiz", "numberOfActiveRunner": 2, "countryCode": "", "sport": "TENNIS", "venue": "", "volume": {"total": 1084.71, "preMatch": 2.59, "inPlay": 1082.12}, "winner": {"id": 8679184, "name": "I Rosca", "status": "WINNER", "position": 1}, "delay": 5}, "runners": [{"id": 8679184, "name": "I Rosca", "status": "WINNER", "position": 1, "inPlayOdds": 1.57, "inPlayTime": 1631545259120, "avgPrematch": 1.57, "closedOdds": 1.66, "maxPrematch": 1.57, "minPrematch": 1.57, "maxInPlay": 2.12, "minInPlay": 1.27, "inPlayIndex": 18, "lengthOdds": 447, "lengthOddsPrematch": 18, "lengthOddsInPlay": 429, "tradedVolume": 761.09, "preMatchVolume": 1.67, "inPlayVolume": 759.42}, {"id": 11862899, "name": "C Cervino Ruiz", "status": "LOSER", "position": 2, "inPlayOdds": 2.54, "inPlayTime": 1631551222271, "avgPrematch": 0, "closedOdds": 2.84, "maxPrematch": -100, "minPrematch": 1001, "maxInPlay": 4.1, "minInPlay": 1.88, "inPlayIndex": 0, "lengthOdds": 411, "lengthOddsPrematch": 0, "lengthOddsInPlay": 411, "tradedVolume": 323.62, "preMatchVolume": 0.92, "inPlayVolume": 322.7}], "marketUpdates": [{"timestamp": 1631518387105000000, "openDate": "2021-09-13T12:00:00.000Z", "status": "OPEN", "betDelay": 0, "inPlay": false, "complete": true}, {"timestamp": 1631522764139000000, "openDate": "2021-09-13T14:00:00.000Z", "status": "OPEN", "betDelay": 0, "inPlay": false, "complete": true}, {"timestamp": 1631526089043000000, "openDate": "2021-09-13T14:10:00.000Z", "status": "OPEN", "betDelay": 0, "inPlay": false, "complete": true}, {"timestamp": 1631529806864000000, "openDate": "2021-09-13T14:00:00.000Z", "status": "OPEN", "betDelay": 0, "inPlay": false, "complete": true}, {"timestamp": 1631531511221000000, "openDate": "2021-09-13T14:10:00.000Z", "status": "OPEN", "betDelay": 0, "inPlay": false, "complete": true}, {"timestamp": 1631534548664000000, "openDate": "2021-09-13T14:00:00.000Z", "status": "OPEN", "betDelay": 0, "inPlay": false, "complete": true}, {"timestamp": 1631536941264000000, "openDate": "2021-09-13T14:10:00.000Z", "status": "OPEN", "betDelay": 0, "inPlay": false, "complete": true}, {"timestamp": 1631542015055000000, "openDate": "2021-09-13T14:20:00.000Z", "status": "OPEN", "betDelay": 0, "inPlay": false, "complete": true}, {"timestamp": 1631542560288000000, "openDate": "2021-09-13T14:30:00.000Z", "status": "OPEN", "betDelay": 0, "inPlay": false, "complete": true}, {"timestamp": 1631543231967000000, "openDate": "2021-09-13T14:40:00.000Z", "status": "OPEN", "betDelay": 0, "inPlay": false, "complete": true}, {"timestamp": 1631543803057000000, "openDate": "2021-09-13T14:50:00.000Z", "status": "OPEN", "betDelay": 0, "inPlay": false, "complete": true}, {"timestamp": 1631544423142000000, "openDate": "2021-09-13T15:00:00.000Z", "status": "OPEN", "betDelay": 0, "inPlay": false, "complete": true}, {"timestamp": 1631544993986000000, "openDate": "2021-09-13T15:10:00.000Z", "status": "OPEN", "betDelay": 0, "inPlay": false, "complete": true}, {"timestamp": 1631545101460000000, "openDate": "2021-09-13T15:00:00.000Z", "status": "OPEN", "betDelay": 0, "inPlay": false, "complete": true}, {"timestamp": 1631545259120000000, "openDate": "2021-09-13T15:00:00.000Z", "status": "OPEN", "betDelay": 5, "inPlay": true, "complete": true}, {"timestamp": 1631549237922000000, "openDate": "2021-09-13T16:20:00.000Z", "status": "OPEN", "betDelay": 5, "inPlay": true, "complete": true}, {"timestamp": 1631549788954000000, "openDate": "2021-09-13T16:30:00.000Z", "status": "OPEN", "betDelay": 5, "inPlay": true, "complete": true}, {"timestamp": 1631551062029000000, "openDate": "2021-09-13T16:37:37.000Z", "status": "OPEN", "betDelay": 5, "inPlay": true, "complete": true}, {"timestamp": 1631558861366000000, "openDate": "2021-09-13T16:37:37.000Z", "status": "SUSPENDED", "betDelay": 5, "inPlay": true, "complete": true}, {"timestamp": 1631558866397000000, "openDate": "2021-09-13T16:37:37.000Z", "status": "CLOSED", "betDelay": 5, "inPlay": true, "complete": true}], "odds": [{"runnerId": 8679184, "odds": [{"timestamp": 1631524671423, "ltp": 1.57, "tv": 1.67, "trd": [[1.57, 1.68]], "batb": [[0, 1.57, 54.11]], "batl": [[2, 1000, 0]]}, {"timestamp": 1631524676332, "ltp": 1.57, "tv": 1.67, "trd": NaN, "batb": [[0, 1.57, 54.95]], "batl": NaN}, {"timestamp": 1631531865779, "ltp": 1.57, "tv": 1.67, "trd": NaN, "batb": [[1, 1.22, 195.25], [2, 1.2, 13.29]], "batl": [[0, 2.3, 2.66]]}, {"timestamp": 1631534656327, "ltp": 1.57, "tv": 1.67, "trd": NaN, "batb": [[0, 1.57, 73.27]], "batl": NaN}, {"timestamp": 1631534957058, "ltp": 1.57, "tv": 1.67, "trd": NaN, "batb": NaN, "batl": [[0, 2.3, 26.72]]}, {"timestamp": 1631535038159, "ltp": 1.57, "tv": 1.67, "trd": NaN, "batb": [[0, 1.57, 74.12]], "batl": NaN}, {"timestamp": 1631535357884, "ltp": 1.57, "tv": 1.67, "trd": NaN, "batb": [[0, 1.57, 73.27]], "batl": NaN}, {"timestamp": 1631535375379, "ltp": 1.57, "tv": 1.67, "trd": NaN, "batb": [[0, 1.6, 94.55], [1, 1.57, 73.27], [2, 1.22, 195.25]], "batl": NaN}, {"timestamp": 1631535375921, "ltp": 1.57, "tv": 1.67, "trd": NaN, "batb": NaN, "batl": [[0, 2.26, 3.5], [1, 2.3, 2.66], [2, 990, 2.2]]}, {"timestamp": 1631536034720, "ltp": 1.57, "tv": 1.67, "trd": NaN, "batb": [[2, 1.2, 13.29]], "batl": NaN}, {"timestamp": 1631536048921, "ltp": 1.57, "tv": 1.67, "trd": NaN, "batb": [[2, 1.37, 122.44]], "batl": [[2, 2.6, 43.73]]}, {"timestamp": 1631536866591, "ltp": 1.57, "tv": 1.67, "trd": NaN, "batb": NaN, "batl": [[0, 2.3, 2.66], [1, 2.6, 43.73], [2, 990, 2.2]]}, {"timestamp": 1631536926685, "ltp": 1.57, "tv": 1.67, "trd": NaN, "batb": NaN, "batl": [[0, 1.8, 75], [1, 2.3, 2.66], [2, 2.6, 43.73]]}, {"timestamp": 1631537081508, "ltp": 1.57, "tv": 1.67, "trd": NaN, "batb": NaN, "batl": [[0, 1.8, 100]]}, {"timestamp": 1631538922266, "ltp": 1.57, "tv": 1.67, "trd": NaN, "batb": [[0, 1.6, 94.53], [2, 1.37, 122.36]], "batl": [[1, 2.3, 2.66], [2, 2.6, 43.7]]}, {"timestamp": 1631540183799, "ltp": 1.57, "tv": 1.67, "trd": NaN, "batb": [[0, 1.6, 174.59]], "batl": NaN}, {"timestamp": 1631543352183, "ltp": 1.57, "tv": 1.67, "trd": NaN, "batb": [[0, 1.65, 1.41], [1, 1.6, 174.59], [2, 1.57, 73.27]], "batl": NaN}, {"timestamp": 1631543613365, "ltp": 1.57, "tv": 1.67, "trd": NaN, "batb": [[1, 1.6, 94.53]], "batl": NaN}, {"timestamp": 1631545259120, "ltp": 1.57, "tv": 1.67, "trd": [[1.57, 1.68]], "batb": [[0, 1.65, 1.41], [1, 1.01, 7], [2, 1.57, 0]], "batl": [[1, 2.3, 0], [2, 2.6, 0]]}, {"timestamp": 1631545264388, "ltp": 1.57, "tv": 1.67, "trd": NaN, "batb": [[1, 1.55, 54.54], [2, 1.01, 7]], "batl": NaN}, {"timestamp": 1631549092077, "ltp": 1.57, "tv": 1.67, "trd": NaN, "batb": [[2, 1.01, 12]], "batl": NaN}, {"timestamp": 1631551058176, "ltp": 1.57, "tv": 1.67, "trd": NaN, "batb": [[1, 1.01, 12], [2, 1.01, 0]], "batl": NaN}, {"timestamp": 1631551063072, "ltp": 1.57, "tv": 1.67, "trd": NaN, "batb": [[1, 1.58, 51.72], [2, 1.01, 12]], "batl": NaN}, {"timestamp": 1631551068282, "ltp": 1.57, "tv": 1.67, "trd": NaN, "batb": [[1, 1.01, 12], [2, 1.01, 0]], "batl": NaN}, {"timestamp": 1631551073162, "ltp": 1.57, "tv": 1.67, "trd": NaN, "batb": [[1, 1.6, 49.99], [2, 1.01, 12]], "batl": NaN}, {"timestamp": 1631551085729, "ltp": 1.57, "tv": 1.67, "trd": NaN, "batb": [[1, 1.01, 12], [2, 1.01, 0]], "batl": NaN}, {"timestamp": 1631551090607, "ltp": 1.57, "tv": 1.67, "trd": NaN, "batb": [[0, 1.71, 42.25], [1, 1.65, 1.41], [2, 1.01, 12]], "batl": NaN}, {"timestamp": 1631551119147, "ltp": 1.57, "tv": 1.67, "trd": NaN, "batb": [[0, 1.65, 1.41], [1, 1.01, 12], [2, 1.01, 0]], "batl": NaN}, {"timestamp": 1631551142261, "ltp": 1.57, "tv": 1.67, "trd": NaN, "batb": [[0, 1.71, 42.25], [1, 1.65, 1.41], [2, 1.01, 12]], "batl": NaN}, {"timestamp": 1631551161106, "ltp": 1.57, "tv": 1.67, "trd": NaN, "batb": [[0, 1.65, 1.41], [1, 1.01, 12], [2, 1.01, 0]], "batl": NaN}, {"timestamp": 1631551165978, "ltp": 1.57, "tv": 1.67, "trd": NaN, "batb": [[1, 1.63, 47.61], [2, 1.01, 12]], "batl": NaN}, {"timestamp": 1631551192710, "ltp": 1.57, "tv": 1.67, "trd": NaN, "batb": [[1, 1.01, 12], [2, 1.01, 0]], "batl": NaN}, {"timestamp": 1631551197614, "ltp": 1.57, "tv": 1.67, "trd": NaN, "batb": [[1, 1.51, 58.82], [2, 1.01, 12]], "batl": NaN}, {"timestamp": 1631551217028, "ltp": 1.57, "tv": 1.67, "trd": NaN, "batb": [[1, 1.01, 12], [2, 1.01, 0]], "batl": NaN}, {"timestamp": 1631551222271, "ltp": 1.65, "tv": 3.09, "trd": [[1.65, 1.41]], "batb": [[0, 1.45, 66.66]], "batl": NaN}, {"timestamp": 1631551275541, "ltp": 1.65, "tv": 3.09, "trd": NaN, "batb": [[0, 1.01, 12], [1, 1.01, 0]], "batl": NaN}, {"timestamp": 1631551280563, "ltp": 1.65, "tv": 3.09, "trd": NaN, "batb": [[0, 1.51, 58.82], [1, 1.01, 12]], "batl": NaN}, {"timestamp": 1631551301058, "ltp": 1.65, "tv": 3.09, "trd": NaN, "batb": [[0, 1.01, 12], [1, 1.01, 0]], "batl": NaN}, {"timestamp": 1631551306084, "ltp": 1.65, "tv": 3.09, "trd": NaN, "batb": [[0, 1.45, 66.66], [1, 1.01, 12]], "batl": NaN}, {"timestamp": 1631551323699, "ltp": 1.65, "tv": 3.09, "trd": NaN, "batb": [[0, 1.01, 12], [1, 1.01, 0]], "batl": NaN}, {"timestamp": 1631551328589, "ltp": 1.65, "tv": 3.09, "trd": NaN, "batb": [[0, 1.51, 58.82], [1, 1.01, 12]], "batl": NaN}, {"timestamp": 1631551349332, "ltp": 1.65, "tv": 3.09, "trd": NaN, "batb": [[0, 1.01, 12], [1, 1.01, 0]], "batl": NaN}, {"timestamp": 1631551354356, "ltp": 1.65, "tv": 3.09, "trd": NaN, "batb": [[0, 1.58, 51.72], [1, 1.01, 12]], "batl": NaN}, {"timestamp": 1631551438912, "ltp": 1.65, "tv": 3.09, "trd": NaN, "batb": [[0, 1.01, 12], [1, 1.01, 0]], "batl": NaN}, {"timestamp": 1631551443960, "ltp": 1.65, "tv": 3.09, "trd": NaN, "batb": [[0, 1.63, 47.61], [1, 1.01, 12]], "batl": NaN}, {"timestamp": 1631551469983, "ltp": 1.65, "tv": 3.09, "trd": NaN, "batb": [[0, 1.01, 12], [1, 1.01, 0]], "batl": NaN}, {"timestamp": 1631551474888, "ltp": 1.65, "tv": 3.09, "trd": NaN, "batb": [[0, 1.78, 38.46], [1, 1.01, 12]], "batl": NaN}, {"timestamp": 1631551514441, "ltp": 1.65, "tv": 3.09, "trd": NaN, "batb": [[0, 1.01, 12], [1, 1.01, 0]], "batl": NaN}, {"timestamp": 1631551521365, "ltp": 1.8, "tv": 145.23, "trd": [[1.8, 142.14]], "batb": NaN, "batl": [[0, 1.8, 28.91]]}, {"timestamp": 1631551523563, "ltp": 1.8, "tv": 203.03, "trd": [[1.8, 199.95]], "batb": [[0, 1.8, 218.37], [1, 1.01, 12]], "batl": NaN}, {"timestamp": 1631551524570, "ltp": 1.8, "tv": 203.03, "trd": NaN, "batb": [[0, 1.8, 524.44]], "batl": NaN}, {"timestamp": 1631551525570, "ltp": 1.8, "tv": 203.03, "trd": NaN, "batb": [[0, 1.8, 314.12]], "batl": NaN}, {"timestamp": 1631551526563, "ltp": 1.8, "tv": 203.03, "trd": NaN, "batb": [[0, 1.8, 178.32]], "batl": NaN}, {"timestamp": 1631551527568, "ltp": 1.8, "tv": 203.03, "trd": NaN, "batb": [[0, 1.8, 76.47]], "batl": NaN}, {"timestamp": 1631551528564, "ltp": 1.8, "tv": 203.03, "trd": NaN, "batb": [[0, 1.88, 34.09], [1, 1.8, 76.94], [2, 1.01, 12]], "batl": NaN}, {"timestamp": 1631551529574, "ltp": 1.8, "tv": 203.03, "trd": NaN, "batb": [[1, 1.8, 57.44]], "batl": NaN}, {"timestamp": 1631551529882, "ltp": 1.8, "tv": 203.03, "trd": NaN, "batb": [[1, 1.8, 23.44]], "batl": NaN}, {"timestamp": 1631551530816, "ltp": 1.8, "tv": 203.03, "trd": NaN, "batb": [[1, 1.01, 12], [2, 1.01, 0]], "batl": NaN}, {"timestamp": 1631551548690, "ltp": 1.8, "tv": 203.03, "trd": NaN, "batb": [[0, 1.01, 12], [1, 1.01, 0]], "batl": NaN}, {"timestamp": 1631551553761, "ltp": 1.8, "tv": 203.03, "trd": NaN, "batb": [[0, 1.85, 35.29], [1, 1.01, 12]], "batl": NaN}, {"timestamp": 1631551589367, "ltp": 1.8, "tv": 203.03, "trd": NaN, "batb": [[0, 1.01, 12], [1, 1.01, 0]], "batl": NaN}, {"timestamp": 1631551594419, "ltp": 1.8, "tv": 203.03, "trd": NaN, "batb": [[0, 1.88, 34.09], [1, 1.01, 12]], "batl": NaN}, {"timestamp": 1631551615308, "ltp": 1.8, "tv": 203.03, "trd": NaN, "batb": [[0, 1.01, 12], [1, 1.01, 0]], "batl": NaN}, {"timestamp": 1631551620209, "ltp": 1.8, "tv": 203.03, "trd": NaN, "batb": [[0, 1.85, 35.29], [1, 1.01, 12]], "batl": NaN}, {"timestamp": 1631551652142, "ltp": 1.8, "tv": 203.03, "trd": NaN, "batb": [[0, 1.01, 12], [1, 1.01, 0]], "batl": NaN}, {"timestamp": 1631551657157, "ltp": 1.8, "tv": 203.03, "trd": NaN, "batb": [[0, 2.06, 28.3], [1, 1.01, 12]], "batl": NaN}, {"timestamp": 1631551758499, "ltp": 2.06, "tv": 206.45, "trd": [[2.06, 3.42]], "batb": [[0, 2.06, 26.59]], "batl": NaN}, {"timestamp": 1631551758809, "ltp": 2.06, "tv": 206.45, "trd": NaN, "batb": [[0, 1.01, 12], [1, 1.01, 0]], "batl": NaN}, {"timestamp": 1631551768908, "ltp": 2.06, "tv": 206.45, "trd": NaN, "batb": [[0, 1.88, 34.09], [1, 1.01, 12]], "batl": NaN}, {"timestamp": 1631551818770, "ltp": 2.06, "tv": 206.45, "trd": NaN, "batb": [[0, 1.01, 12], [1, 1.01, 0]], "batl": NaN}, {"timestamp": 1631551823638, "ltp": 2.06, "tv": 206.45, "trd": NaN, "batb": [[0, 2.06, 28.3], [1, 1.01, 12]], "batl": NaN}, {"timestamp": 1631551857943, "ltp": 2.06, "tv": 206.45, "trd": NaN, "batb": [[0, 1.01, 12], [1, 1.01, 0]], "batl": NaN}, {"timestamp": 1631551862935, "ltp": 2.06, "tv": 206.45, "trd": NaN, "batb": [[0, 1.88, 34.09], [1, 1.01, 12]], "batl": NaN}, {"timestamp": 1631551886446, "ltp": 2.06, "tv": 206.45, "trd": NaN, "batb": [[0, 1.01, 12], [1, 1.01, 0]], "batl": NaN}, {"timestamp": 1631551891467, "ltp": 2.06, "tv": 206.45, "trd": NaN, "batb": [[0, 2.06, 28.3], [1, 1.01, 12]], "batl": NaN}, {"timestamp": 1631551909682, "ltp": 2.06, "tv": 206.45, "trd": NaN, "batb": [[0, 1.01, 12], [1, 1.01, 0]], "batl": NaN}, {"timestamp": 1631551914591, "ltp": 2.06, "tv": 206.45, "trd": NaN, "batb": [[0, 1.98, 30.61], [1, 1.01, 12]], "batl": NaN}, {"timestamp": 1631551923523, "ltp": 2.06, "tv": 206.45, "trd": NaN, "batb": [[0, 1.01, 12], [1, 1.01, 0]], "batl": NaN}, {"timestamp": 1631551928533, "ltp": 2.06, "tv": 206.45, "trd": NaN, "batb": [[0, 2.2, 24.99], [1, 1.01, 12]], "batl": NaN}, {"timestamp": 1631551961834, "ltp": 2.06, "tv": 206.45, "trd": NaN, "batb": [[0, 1.01, 12], [1, 1.01, 0]], "batl": NaN}, {"timestamp": 1631551966840, "ltp": 2.06, "tv": 206.45, "trd": NaN, "batb": [[0, 2, 30], [1, 1.01, 12]], "batl": NaN}, {"timestamp": 1631551998979, "ltp": 2.06, "tv": 206.45, "trd": NaN, "batb": [[0, 1.01, 12], [1, 1.01, 0]], "batl": NaN}, {"timestamp": 1631552004021, "ltp": 2.06, "tv": 206.45, "trd": NaN, "batb": [[0, 2.2, 24.99], [1, 1.01, 12]], "batl": NaN}, {"timestamp": 1631552029120, "ltp": 2.06, "tv": 206.45, "trd": NaN, "batb": [[0, 1.01, 12], [1, 1.01, 0]], "batl": NaN}, {"timestamp": 1631552034129, "ltp": 2.06, "tv": 206.45, "trd": NaN, "batb": [[0, 2, 30], [1, 1.01, 12]], "batl": NaN}, {"timestamp": 1631552076094, "ltp": 2.06, "tv": 206.45, "trd": NaN, "batb": [[0, 1.01, 12], [1, 1.01, 0]], "batl": NaN}, {"timestamp": 1631552081103, "ltp": 2.06, "tv": 206.45, "trd": NaN, "batb": [[0, 1.85, 35.29], [1, 1.01, 12]], "batl": NaN}, {"timestamp": 1631552100829, "ltp": 2.06, "tv": 206.45, "trd": NaN, "batb": [[0, 1.01, 12], [1, 1.01, 0]], "batl": NaN}, {"timestamp": 1631552105743, "ltp": 2.06, "tv": 206.45, "trd": NaN, "batb": [[0, 1.65, 46.15], [1, 1.01, 12]], "batl": NaN}, {"timestamp": 1631552149080, "ltp": 2.06, "tv": 206.45, "trd": NaN, "batb": [[0, 1.01, 12], [1, 1.01, 0]], "batl": NaN}, {"timestamp": 1631552153956, "ltp": 2.06, "tv": 206.45, "trd": NaN, "batb": [[0, 1.78, 38.46], [1, 1.01, 12]], "batl": NaN}, {"timestamp": 1631552198548, "ltp": 2.06, "tv": 206.45, "trd": NaN, "batb": [[0, 1.01, 12], [1, 1.01, 0]], "batl": NaN}, {"timestamp": 1631552203411, "ltp": 2.06, "tv": 206.45, "trd": NaN, "batb": [[0, 1.88, 34.09], [1, 1.01, 12]], "batl": NaN}, {"timestamp": 1631552238897, "ltp": 2.06, "tv": 206.45, "trd": NaN, "batb": [[0, 1.01, 12], [1, 1.01, 0]], "batl": NaN}, {"timestamp": 1631552243673, "ltp": 2.06, "tv": 206.45, "trd": NaN, "batb": [[0, 1.85, 35.29], [1, 1.01, 12]], "batl": NaN}, {"timestamp": 1631552247583, "ltp": 2.12, "tv": 237.42, "trd": [[2.12, 30.97]], "batb": NaN, "batl": [[0, 2.12, 369.96]]}, {"timestamp": 1631552248613, "ltp": 2.12, "tv": 237.42, "trd": NaN, "batb": NaN, "batl": [[0, 2.12, 681.89]]}, {"timestamp": 1631552249598, "ltp": 2.12, "tv": 237.42, "trd": NaN, "batb": NaN, "batl": [[0, 2.12, 313.02]]}, {"timestamp": 1631552250599, "ltp": 2.12, "tv": 237.42, "trd": NaN, "batb": NaN, "batl": [[0, 2.12, 159.76]]}, {"timestamp": 1631552251590, "ltp": 2.12, "tv": 237.42, "trd": NaN, "batb": NaN, "batl": [[0, 2.12, 308.58]]}, {"timestamp": 1631552252415, "ltp": 2.12, "tv": 237.42, "trd": NaN, "batb": NaN, "batl": [[0, 2.12, 141.5]]}, {"timestamp": 1631552252997, "ltp": 2.12, "tv": 237.42, "trd": NaN, "batb": NaN, "batl": [[0, 2.12, 28.3]]}, {"timestamp": 1631552285251, "ltp": 2.12, "tv": 237.42, "trd": NaN, "batb": [[0, 1.01, 12], [1, 1.01, 0]], "batl": NaN}, {"timestamp": 1631552290237, "ltp": 2.12, "tv": 237.42, "trd": NaN, "batb": [[0, 1.65, 46.15], [1, 1.01, 12]], "batl": NaN}, {"timestamp": 1631552315286, "ltp": 2.12, "tv": 237.42, "trd": NaN, "batb": [[0, 1.01, 12], [1, 1.01, 0]], "batl": NaN}, {"timestamp": 1631552320280, "ltp": 2.12, "tv": 237.42, "trd": NaN, "batb": [[0, 1.71, 42.25], [1, 1.01, 12]], "batl": NaN}, {"timestamp": 1631552330618, "ltp": 2.12, "tv": 237.42, "trd": NaN, "batb": [[0, 1.01, 12], [1, 1.01, 0]], "batl": NaN}, {"timestamp": 1631552335591, "ltp": 2.12, "tv": 237.42, "trd": NaN, "batb": [[0, 1.55, 54.54], [1, 1.01, 12]], "batl": NaN}, {"timestamp": 1631552361448, "ltp": 2.12, "tv": 237.42, "trd": NaN, "batb": [[0, 1.01, 12], [1, 1.01, 0]], "batl": NaN}, {"timestamp": 1631552366487, "ltp": 2.12, "tv": 237.42, "trd": NaN, "batb": [[0, 1.48, 62.5], [1, 1.01, 12]], "batl": NaN}, {"timestamp": 1631552476177, "ltp": 2.12, "tv": 237.53, "trd": [[1.65, 1.41], [1.8, 200.03], [2.06, 3.42], [2.12, 31]], "batb": [[0, 1.01, 12], [1, 1.01, 0]], "batl": NaN}, {"timestamp": 1631552481075, "ltp": 2.12, "tv": 237.53, "trd": NaN, "batb": [[0, 1.55, 54.54], [1, 1.01, 12]], "batl": NaN}, {"timestamp": 1631552503519, "ltp": 2.12, "tv": 237.53, "trd": NaN, "batb": [[0, 1.01, 12], [1, 1.01, 0]], "batl": NaN}, {"timestamp": 1631552508326, "ltp": 2.12, "tv": 237.53, "trd": NaN, "batb": [[0, 1.63, 47.61], [1, 1.01, 12]], "batl": NaN}, {"timestamp": 1631552529667, "ltp": 2.12, "tv": 237.53, "trd": NaN, "batb": [[0, 1.01, 12], [1, 1.01, 0]], "batl": NaN}, {"timestamp": 1631552534562, "ltp": 2.12, "tv": 237.53, "trd": NaN, "batb": [[0, 1.55, 54.54], [1, 1.01, 12]], "batl": NaN}, {"timestamp": 1631552561265, "ltp": 2.12, "tv": 237.53, "trd": NaN, "batb": [[0, 1.01, 12], [1, 1.01, 0]], "batl": NaN}, {"timestamp": 1631552566159, "ltp": 2.12, "tv": 237.53, "trd": NaN, "batb": [[0, 1.63, 47.61], [1, 1.01, 12]], "batl": NaN}, {"timestamp": 1631552606426, "ltp": 2.12, "tv": 237.53, "trd": NaN, "batb": [[0, 1.01, 12], [1, 1.01, 0]], "batl": NaN}, {"timestamp": 1631552611320, "ltp": 2.12, "tv": 237.53, "trd": NaN, "batb": [[0, 1.55, 54.54], [1, 1.01, 12]], "batl": NaN}, {"timestamp": 1631552642096, "ltp": 2.12, "tv": 237.53, "trd": NaN, "batb": [[0, 1.01, 12], [1, 1.01, 0]], "batl": NaN}, {"timestamp": 1631552647092, "ltp": 2.12, "tv": 237.53, "trd": NaN, "batb": [[0, 1.65, 46.15], [1, 1.01, 12]], "batl": NaN}, {"timestamp": 1631552679149, "ltp": 2.12, "tv": 237.53, "trd": NaN, "batb": [[0, 1.01, 12], [1, 1.01, 0]], "batl": NaN}, {"timestamp": 1631552684019, "ltp": 2.12, "tv": 237.53, "trd": NaN, "batb": [[0, 1.85, 35.29], [1, 1.01, 12]], "batl": NaN}, {"timestamp": 1631552702637, "ltp": 2.12, "tv": 237.53, "trd": NaN, "batb": [[0, 1.01, 12], [1, 1.01, 0]], "batl": NaN}, {"timestamp": 1631552707556, "ltp": 2.12, "tv": 237.53, "trd": NaN, "batb": [[0, 1.71, 42.25], [1, 1.01, 12]], "batl": NaN}, {"timestamp": 1631552742193, "ltp": 2.12, "tv": 237.53, "trd": NaN, "batb": [[0, 1.01, 12], [1, 1.01, 0]], "batl": NaN}, {"timestamp": 1631552747083, "ltp": 2.12, "tv": 237.53, "trd": NaN, "batb": [[0, 1.85, 35.29], [1, 1.01, 12]], "batl": NaN}, {"timestamp": 1631552764787, "ltp": 2.12, "tv": 237.53, "trd": NaN, "batb": [[0, 1.01, 12], [1, 1.01, 0]], "batl": NaN}, {"timestamp": 1631552769810, "ltp": 2.12, "tv": 237.53, "trd": NaN, "batb": [[0, 1.71, 42.25], [1, 1.01, 12]], "batl": NaN}, {"timestamp": 1631552788164, "ltp": 2.12, "tv": 237.53, "trd": NaN, "batb": [[0, 1.01, 12], [1, 1.01, 0]], "batl": NaN}, {"timestamp": 1631552793132, "ltp": 2.12, "tv": 237.53, "trd": NaN, "batb": [[0, 1.73, 41.09], [1, 1.01, 12]], "batl": NaN}, {"timestamp": 1631552803858, "ltp": 2.12, "tv": 237.53, "trd": NaN, "batb": [[0, 1.01, 12], [1, 1.01, 0]], "batl": NaN}, {"timestamp": 1631552808741, "ltp": 2.12, "tv": 237.53, "trd": NaN, "batb": [[0, 1.88, 34.09], [1, 1.01, 12]], "batl": NaN}, {"timestamp": 1631552842721, "ltp": 2.12, "tv": 237.53, "trd": NaN, "batb": [[0, 1.01, 12], [1, 1.01, 0]], "batl": NaN}, {"timestamp": 1631552847592, "ltp": 2.12, "tv": 237.53, "trd": NaN, "batb": [[0, 1.71, 42.25], [1, 1.01, 12]], "batl": NaN}, {"timestamp": 1631552870243, "ltp": 2.12, "tv": 237.53, "trd": NaN, "batb": [[0, 1.01, 12], [1, 1.01, 0]], "batl": NaN}, {"timestamp": 1631552875137, "ltp": 2.12, "tv": 237.53, "trd": NaN, "batb": [[0, 1.55, 54.54], [1, 1.01, 12]], "batl": NaN}, {"timestamp": 1631552921380, "ltp": 2.12, "tv": 237.53, "trd": NaN, "batb": [[0, 1.01, 12], [1, 1.01, 0]], "batl": NaN}, {"timestamp": 1631552926380, "ltp": 2.12, "tv": 237.53, "trd": NaN, "batb": [[0, 1.58, 51.72], [1, 1.01, 12]], "batl": NaN}, {"timestamp": 1631552932894, "ltp": 2.12, "tv": 237.53, "trd": NaN, "batb": [[0, 1.01, 12], [1, 1.01, 0]], "batl": NaN}, {"timestamp": 1631552937794, "ltp": 2.12, "tv": 237.53, "trd": NaN, "batb": [[0, 1.73, 41.09], [1, 1.01, 12]], "batl": NaN}, {"timestamp": 1631552965746, "ltp": 2.12, "tv": 237.53, "trd": NaN, "batb": [[0, 1.01, 12], [1, 1.01, 0]], "batl": NaN}, {"timestamp": 1631552970641, "ltp": 2.12, "tv": 237.53, "trd": NaN, "batb": [[0, 1.88, 34.09], [1, 1.01, 12]], "batl": NaN}, {"timestamp": 1631552981156, "ltp": 2.12, "tv": 237.53, "trd": NaN, "batb": [[0, 1.01, 12], [1, 1.01, 0]], "batl": NaN}, {"timestamp": 1631552986159, "ltp": 2.12, "tv": 237.53, "trd": NaN, "batb": [[0, 1.98, 30.61], [1, 1.01, 12]], "batl": NaN}, {"timestamp": 1631553011872, "ltp": 2.12, "tv": 237.53, "trd": NaN, "batb": [[0, 1.01, 12], [1, 1.01, 0]], "batl": NaN}, {"timestamp": 1631553016903, "ltp": 2.12, "tv": 237.53, "trd": NaN, "batb": [[0, 1.73, 41.09], [1, 1.01, 12]], "batl": NaN}, {"timestamp": 1631553036321, "ltp": 2.12, "tv": 237.53, "trd": NaN, "batb": [[0, 1.01, 12], [1, 1.01, 0]], "batl": NaN}, {"timestamp": 1631553041232, "ltp": 2.12, "tv": 237.53, "trd": NaN, "batb": [[0, 1.78, 38.46], [1, 1.01, 12]], "batl": NaN}, {"timestamp": 1631553053222, "ltp": 2.12, "tv": 237.53, "trd": NaN, "batb": [[0, 1.01, 12], [1, 1.01, 0]], "batl": NaN}, {"timestamp": 1631553058252, "ltp": 2.12, "tv": 237.53, "trd": NaN, "batb": [[0, 1.88, 34.09], [1, 1.01, 12]], "batl": NaN}, {"timestamp": 1631553086284, "ltp": 2.12, "tv": 237.53, "trd": NaN, "batb": [[0, 1.01, 12], [1, 1.01, 0]], "batl": NaN}, {"timestamp": 1631553091270, "ltp": 2.12, "tv": 237.53, "trd": NaN, "batb": [[0, 1.73, 41.09], [1, 1.01, 12]], "batl": NaN}, {"timestamp": 1631553106689, "ltp": 2.12, "tv": 237.53, "trd": NaN, "batb": [[0, 1.01, 12], [1, 1.01, 0]], "batl": NaN}, {"timestamp": 1631553111476, "ltp": 2.12, "tv": 237.53, "trd": NaN, "batb": [[0, 1.58, 51.72], [1, 1.01, 12]], "batl": NaN}, {"timestamp": 1631553125229, "ltp": 2.12, "tv": 237.53, "trd": NaN, "batb": [[0, 1.01, 12], [1, 1.01, 0]], "batl": NaN}, {"timestamp": 1631553130124, "ltp": 2.12, "tv": 237.53, "trd": NaN, "batb": [[0, 1.6, 49.99], [1, 1.01, 12]], "batl": NaN}, {"timestamp": 1631553140714, "ltp": 2.12, "tv": 237.53, "trd": NaN, "batb": [[0, 1.01, 12], [1, 1.01, 0]], "batl": NaN}, {"timestamp": 1631553145702, "ltp": 2.12, "tv": 237.53, "trd": NaN, "batb": [[0, 1.48, 62.5], [1, 1.01, 12]], "batl": NaN}, {"timestamp": 1631553270302, "ltp": 2.12, "tv": 237.53, "trd": NaN, "batb": [[0, 1.01, 12], [1, 1.01, 0]], "batl": NaN}, {"timestamp": 1631553275207, "ltp": 2.12, "tv": 237.53, "trd": NaN, "batb": [[0, 1.38, 78.94], [1, 1.01, 12]], "batl": NaN}, {"timestamp": 1631553317716, "ltp": 2.12, "tv": 237.53, "trd": NaN, "batb": [[0, 1.01, 12], [1, 1.01, 0]], "batl": NaN}, {"timestamp": 1631553322605, "ltp": 2.12, "tv": 237.53, "trd": NaN, "batb": [[0, 1.48, 62.5], [1, 1.01, 12]], "batl": NaN}, {"timestamp": 1631553349553, "ltp": 2.12, "tv": 237.53, "trd": NaN, "batb": [[0, 1.01, 12], [1, 1.01, 0]], "batl": NaN}, {"timestamp": 1631553354427, "ltp": 2.12, "tv": 237.53, "trd": NaN, "batb": [[0, 1.38, 78.94], [1, 1.01, 12]], "batl": NaN}, {"timestamp": 1631553374283, "ltp": 2.12, "tv": 237.53, "trd": NaN, "batb": [[0, 1.01, 12], [1, 1.01, 0]], "batl": NaN}, {"timestamp": 1631553379182, "ltp": 2.12, "tv": 237.53, "trd": NaN, "batb": [[0, 1.48, 62.5], [1, 1.01, 12]], "batl": NaN}, {"timestamp": 1631553393636, "ltp": 2.12, "tv": 237.53, "trd": NaN, "batb": [[0, 1.01, 12], [1, 1.01, 0]], "batl": NaN}, {"timestamp": 1631553398414, "ltp": 2.12, "tv": 237.53, "trd": NaN, "batb": [[0, 1.45, 66.66], [1, 1.01, 12]], "batl": NaN}, {"timestamp": 1631553407315, "ltp": 2.12, "tv": 237.53, "trd": NaN, "batb": [[0, 1.01, 12], [1, 1.01, 0]], "batl": NaN}, {"timestamp": 1631553412348, "ltp": 2.12, "tv": 237.53, "trd": NaN, "batb": [[0, 1.58, 51.72], [1, 1.01, 12]], "batl": NaN}, {"timestamp": 1631553442862, "ltp": 2.12, "tv": 237.53, "trd": NaN, "batb": [[0, 1.01, 12], [1, 1.01, 0]], "batl": NaN}, {"timestamp": 1631553447839, "ltp": 2.12, "tv": 237.53, "trd": NaN, "batb": [[0, 1.71, 42.25], [1, 1.01, 12]], "batl": NaN}, {"timestamp": 1631553472540, "ltp": 2.12, "tv": 237.53, "trd": NaN, "batb": [[0, 1.01, 12], [1, 1.01, 0]], "batl": NaN}, {"timestamp": 1631553477452, "ltp": 2.12, "tv": 237.53, "trd": NaN, "batb": [[0, 1.73, 41.09], [1, 1.01, 12]], "batl": NaN}, {"timestamp": 1631553490368, "ltp": 2.12, "tv": 237.53, "trd": NaN, "batb": [[0, 1.01, 12], [1, 1.01, 0]], "batl": NaN}, {"timestamp": 1631553495280, "ltp": 2.12, "tv": 237.53, "trd": NaN, "batb": [[0, 1.88, 34.09], [1, 1.01, 12]], "batl": NaN}, {"timestamp": 1631553517810, "ltp": 2.12, "tv": 237.53, "trd": NaN, "batb": [[0, 1.01, 12], [1, 1.01, 0]], "batl": NaN}, {"timestamp": 1631553522706, "ltp": 2.12, "tv": 237.53, "trd": NaN, "batb": [[0, 1.71, 42.25], [1, 1.01, 12]], "batl": NaN}, {"timestamp": 1631553536846, "ltp": 2.12, "tv": 237.53, "trd": NaN, "batb": [[0, 1.01, 12], [1, 1.01, 0]], "batl": NaN}, {"timestamp": 1631553541854, "ltp": 2.12, "tv": 237.53, "trd": NaN, "batb": [[0, 1.78, 38.46], [1, 1.01, 12]], "batl": NaN}, {"timestamp": 1631553548454, "ltp": 2.12, "tv": 237.53, "trd": NaN, "batb": [[0, 1.01, 12], [1, 1.01, 0]], "batl": NaN}, {"timestamp": 1631553553360, "ltp": 2.12, "tv": 237.53, "trd": NaN, "batb": [[0, 1.58, 51.72], [1, 1.01, 12]], "batl": NaN}, {"timestamp": 1631553569251, "ltp": 2.12, "tv": 237.53, "trd": NaN, "batb": [[0, 1.01, 12], [1, 1.01, 0]], "batl": NaN}, {"timestamp": 1631553574188, "ltp": 2.12, "tv": 237.53, "trd": NaN, "batb": [[0, 1.6, 49.99], [1, 1.01, 12]], "batl": NaN}, {"timestamp": 1631553594020, "ltp": 2.12, "tv": 237.53, "trd": NaN, "batb": [[0, 1.01, 12], [1, 1.01, 0]], "batl": NaN}, {"timestamp": 1631553598914, "ltp": 2.12, "tv": 237.53, "trd": NaN, "batb": [[0, 1.48, 62.5], [1, 1.01, 12]], "batl": NaN}, {"timestamp": 1631553627749, "ltp": 2.12, "tv": 237.53, "trd": NaN, "batb": [[0, 1.01, 12], [1, 1.01, 0]], "batl": NaN}, {"timestamp": 1631553632665, "ltp": 2.12, "tv": 237.53, "trd": NaN, "batb": [[0, 1.55, 54.54], [1, 1.01, 12]], "batl": NaN}, {"timestamp": 1631553654843, "ltp": 2.12, "tv": 237.53, "trd": NaN, "batb": [[0, 1.01, 12], [1, 1.01, 0]], "batl": NaN}, {"timestamp": 1631553659738, "ltp": 2.12, "tv": 237.53, "trd": NaN, "batb": [[0, 1.45, 66.66], [1, 1.01, 12]], "batl": NaN}, {"timestamp": 1631553777816, "ltp": 2.12, "tv": 237.53, "trd": NaN, "batb": [[0, 1.01, 12], [1, 1.01, 0]], "batl": NaN}, {"timestamp": 1631553782701, "ltp": 2.12, "tv": 237.53, "trd": NaN, "batb": [[0, 1.34, 88.23], [1, 1.01, 12]], "batl": NaN}, {"timestamp": 1631553812740, "ltp": 2.12, "tv": 237.53, "trd": NaN, "batb": [[0, 1.01, 12], [1, 1.01, 0]], "batl": NaN}, {"timestamp": 1631553817652, "ltp": 2.12, "tv": 237.53, "trd": NaN, "batb": [[0, 1.28, 107.14], [1, 1.01, 12]], "batl": NaN}, {"timestamp": 1631553849328, "ltp": 2.12, "tv": 237.53, "trd": NaN, "batb": [[0, 1.01, 12], [1, 1.01, 0]], "batl": NaN}, {"timestamp": 1631553854219, "ltp": 2.12, "tv": 237.53, "trd": NaN, "batb": [[0, 1.34, 88.23], [1, 1.01, 12]], "batl": NaN}, {"timestamp": 1631553898057, "ltp": 2.12, "tv": 237.53, "trd": NaN, "batb": [[0, 1.01, 12], [1, 1.01, 0]], "batl": NaN}, {"timestamp": 1631553902980, "ltp": 2.12, "tv": 237.53, "trd": NaN, "batb": [[0, 1.42, 71.42], [1, 1.01, 12]], "batl": NaN}, {"timestamp": 1631553955491, "ltp": 2.12, "tv": 237.53, "trd": NaN, "batb": [[0, 1.01, 12], [1, 1.01, 0]], "batl": NaN}, {"timestamp": 1631553960404, "ltp": 2.12, "tv": 237.53, "trd": NaN, "batb": [[0, 1.58, 51.72], [1, 1.01, 12]], "batl": NaN}, {"timestamp": 1631553990951, "ltp": 2.12, "tv": 237.53, "trd": NaN, "batb": [[0, 1.01, 12], [1, 1.01, 0]], "batl": NaN}, {"timestamp": 1631553995858, "ltp": 2.12, "tv": 237.53, "trd": NaN, "batb": [[0, 1.42, 71.42], [1, 1.01, 12]], "batl": NaN}, {"timestamp": 1631554016060, "ltp": 2.12, "tv": 237.53, "trd": NaN, "batb": [[0, 1.01, 12], [1, 1.01, 0]], "batl": NaN}, {"timestamp": 1631554021057, "ltp": 2.12, "tv": 237.53, "trd": NaN, "batb": [[0, 1.38, 78.94], [1, 1.01, 12]], "batl": NaN}, {"timestamp": 1631554031691, "ltp": 2.12, "tv": 237.53, "trd": NaN, "batb": [[0, 1.01, 12], [1, 1.01, 0]], "batl": NaN}, {"timestamp": 1631554036576, "ltp": 2.12, "tv": 237.53, "trd": NaN, "batb": [[0, 1.58, 51.72], [1, 1.01, 12]], "batl": NaN}, {"timestamp": 1631554097722, "ltp": 2.12, "tv": 237.53, "trd": NaN, "batb": [[0, 1.01, 12], [1, 1.01, 0]], "batl": NaN}, {"timestamp": 1631554102758, "ltp": 2.12, "tv": 237.53, "trd": NaN, "batb": [[0, 1.42, 71.42], [1, 1.01, 12]], "batl": NaN}, {"timestamp": 1631554124990, "ltp": 2.12, "tv": 237.53, "trd": NaN, "batb": [[0, 1.01, 12], [1, 1.01, 0]], "batl": NaN}, {"timestamp": 1631554129975, "ltp": 2.12, "tv": 237.53, "trd": NaN, "batb": [[0, 1.31, 96.77], [1, 1.01, 12]], "batl": NaN}, {"timestamp": 1631554148429, "ltp": 2.12, "tv": 237.53, "trd": NaN, "batb": [[0, 1.01, 12], [1, 1.01, 0]], "batl": NaN}, {"timestamp": 1631554153351, "ltp": 2.12, "tv": 237.53, "trd": NaN, "batb": [[0, 1.28, 107.14], [1, 1.01, 12]], "batl": NaN}, {"timestamp": 1631554182086, "ltp": 2.12, "tv": 237.53, "trd": NaN, "batb": [[0, 1.01, 12], [1, 1.01, 0]], "batl": NaN}, {"timestamp": 1631554186989, "ltp": 2.12, "tv": 237.53, "trd": NaN, "batb": [[0, 1.42, 71.42], [1, 1.01, 12]], "batl": NaN}, {"timestamp": 1631554204207, "ltp": 2.12, "tv": 237.53, "trd": NaN, "batb": NaN, "batl": [[0, 1.57, 38.26]]}, {"timestamp": 1631554240402, "ltp": 2.12, "tv": 237.53, "trd": NaN, "batb": [[0, 1.01, 12], [1, 1.01, 0]], "batl": NaN}, {"timestamp": 1631554245366, "ltp": 2.12, "tv": 237.53, "trd": NaN, "batb": [[0, 1.31, 96.77], [1, 1.01, 12]], "batl": NaN}, {"timestamp": 1631554258099, "ltp": 2.12, "tv": 237.53, "trd": NaN, "batb": NaN, "batl": [[0, 1.42, 38.26]]}, {"timestamp": 1631554272421, "ltp": 2.12, "tv": 237.53, "trd": NaN, "batb": [[0, 1.01, 12], [1, 1.01, 0]], "batl": NaN}, {"timestamp": 1631554277017, "ltp": 2.12, "tv": 237.53, "trd": NaN, "batb": [[0, 1.18, 166.66], [1, 1.01, 12]], "batl": NaN}, {"timestamp": 1631554284730, "ltp": 1.33, "tv": 268.36, "trd": [[1.33, 30.83]], "batb": [[0, 1.33, 7.43], [1, 1.18, 166.66], [2, 1.01, 12]], "batl": NaN}, {"timestamp": 1631554287532, "ltp": 1.33, "tv": 268.36, "trd": NaN, "batb": [[0, 1.18, 166.66], [1, 1.01, 12], [2, 1.01, 0]], "batl": NaN}, {"timestamp": 1631554307371, "ltp": 1.33, "tv": 268.36, "trd": NaN, "batb": [[0, 1.2, 136], [1, 1.18, 166.66], [2, 1.01, 12]], "batl": NaN}, {"timestamp": 1631554310377, "ltp": 1.33, "tv": 268.36, "trd": NaN, "batb": NaN, "batl": [[0, 1.33, 68]]}, {"timestamp": 1631554405441, "ltp": 1.33, "tv": 268.36, "trd": NaN, "batb": [[1, 1.01, 12], [2, 1.01, 0]], "batl": NaN}, {"timestamp": 1631554410333, "ltp": 1.33, "tv": 268.36, "trd": NaN, "batb": [[1, 1.15, 200], [2, 1.01, 12]], "batl": NaN}, {"timestamp": 1631554455142, "ltp": 1.33, "tv": 268.36, "trd": NaN, "batb": [[0, 1.15, 200], [1, 1.01, 12], [2, 1.01, 0]], "batl": NaN}, {"timestamp": 1631554456322, "ltp": 1.33, "tv": 268.36, "trd": NaN, "batb": [[0, 1.01, 12], [1, 1.01, 0]], "batl": NaN}, {"timestamp": 1631554461370, "ltp": 1.33, "tv": 268.36, "trd": NaN, "batb": [[0, 1.12, 249.99], [1, 1.01, 12]], "batl": NaN}, {"timestamp": 1631554484486, "ltp": 1.33, "tv": 268.36, "trd": NaN, "batb": [[0, 1.01, 12], [1, 1.01, 0]], "batl": NaN}, {"timestamp": 1631554489384, "ltp": 1.33, "tv": 268.36, "trd": NaN, "batb": [[0, 1.11, 272.72], [1, 1.01, 12]], "batl": NaN}, {"timestamp": 1631554513500, "ltp": 1.33, "tv": 268.36, "trd": NaN, "batb": [[0, 1.01, 12], [1, 1.01, 0]], "batl": NaN}, {"timestamp": 1631554518517, "ltp": 1.33, "tv": 268.36, "trd": NaN, "batb": [[0, 1.08, 374.99], [1, 1.01, 12]], "batl": NaN}, {"timestamp": 1631554528438, "ltp": 1.33, "tv": 268.36, "trd": NaN, "batb": [[0, 1.11, 68], [1, 1.08, 374.99], [2, 1.01, 12]], "batl": NaN}, {"timestamp": 1631554529233, "ltp": 1.33, "tv": 268.36, "trd": NaN, "batb": [[0, 1.11, 136], [1, 1.1, 68], [2, 1.08, 374.99]], "batl": NaN}, {"timestamp": 1631554561280, "ltp": 1.33, "tv": 268.36, "trd": NaN, "batb": [[0, 1.08, 374.99], [1, 1.01, 12], [2, 1.08, 0]], "batl": NaN}, {"timestamp": 1631554573611, "ltp": 1.33, "tv": 268.36, "trd": NaN, "batb": [[0, 1.01, 12], [1, 1.01, 0]], "batl": NaN}, {"timestamp": 1631554578613, "ltp": 1.33, "tv": 268.36, "trd": NaN, "batb": [[0, 1.11, 272.72], [1, 1.01, 12]], "batl": NaN}, {"timestamp": 1631554610909, "ltp": 1.33, "tv": 268.36, "trd": NaN, "batb": [[0, 1.01, 12], [1, 1.01, 0]], "batl": NaN}, {"timestamp": 1631554615849, "ltp": 1.33, "tv": 268.36, "trd": NaN, "batb": [[0, 1.15, 200], [1, 1.01, 12]], "batl": NaN}, {"timestamp": 1631554642376, "ltp": 1.33, "tv": 268.36, "trd": NaN, "batb": [[0, 1.01, 12], [1, 1.01, 0]], "batl": NaN}, {"timestamp": 1631554647275, "ltp": 1.33, "tv": 268.36, "trd": NaN, "batb": [[0, 1.18, 166.66], [1, 1.01, 12]], "batl": NaN}, {"timestamp": 1631554665973, "ltp": 1.33, "tv": 268.36, "trd": NaN, "batb": [[0, 1.01, 12], [1, 1.01, 0]], "batl": NaN}, {"timestamp": 1631554670898, "ltp": 1.33, "tv": 268.36, "trd": NaN, "batb": [[0, 1.15, 200], [1, 1.01, 12]], "batl": NaN}, {"timestamp": 1631554695531, "ltp": 1.33, "tv": 268.36, "trd": NaN, "batb": [[0, 1.01, 12], [1, 1.01, 0]], "batl": NaN}, {"timestamp": 1631554700453, "ltp": 1.33, "tv": 268.36, "trd": NaN, "batb": [[0, 1.11, 272.72], [1, 1.01, 12]], "batl": NaN}, {"timestamp": 1631554729901, "ltp": 1.33, "tv": 268.36, "trd": NaN, "batb": [[0, 1.01, 12], [1, 1.01, 0]], "batl": NaN}, {"timestamp": 1631554734892, "ltp": 1.33, "tv": 268.36, "trd": NaN, "batb": [[0, 1.15, 200], [1, 1.01, 12]], "batl": NaN}, {"timestamp": 1631554765398, "ltp": 1.33, "tv": 268.36, "trd": NaN, "batb": [[0, 1.01, 12], [1, 1.01, 0]], "batl": NaN}, {"timestamp": 1631554770347, "ltp": 1.33, "tv": 268.36, "trd": NaN, "batb": [[0, 1.12, 249.99], [1, 1.01, 12]], "batl": NaN}, {"timestamp": 1631554786116, "ltp": 1.33, "tv": 268.36, "trd": NaN, "batb": [[0, 1.01, 12], [1, 1.01, 0]], "batl": NaN}, {"timestamp": 1631554791040, "ltp": 1.33, "tv": 268.36, "trd": NaN, "batb": [[0, 1.11, 272.72], [1, 1.01, 12]], "batl": NaN}, {"timestamp": 1631554818596, "ltp": 1.33, "tv": 268.36, "trd": NaN, "batb": [[0, 1.01, 12], [1, 1.01, 0]], "batl": NaN}, {"timestamp": 1631554823569, "ltp": 1.33, "tv": 268.36, "trd": NaN, "batb": [[0, 1.08, 374.99], [1, 1.01, 12]], "batl": NaN}, {"timestamp": 1631554838896, "ltp": 1.33, "tv": 268.36, "trd": NaN, "batb": [[0, 1.01, 12], [1, 1.01, 0]], "batl": NaN}, {"timestamp": 1631554843785, "ltp": 1.33, "tv": 268.36, "trd": NaN, "batb": [[0, 1.11, 272.72], [1, 1.01, 12]], "batl": NaN}, {"timestamp": 1631554880647, "ltp": 1.33, "tv": 268.36, "trd": NaN, "batb": [[0, 1.01, 12], [1, 1.01, 0]], "batl": NaN}, {"timestamp": 1631554885546, "ltp": 1.33, "tv": 268.36, "trd": NaN, "batb": [[0, 1.12, 249.99], [1, 1.01, 12]], "batl": NaN}, {"timestamp": 1631554914719, "ltp": 1.33, "tv": 268.36, "trd": NaN, "batb": [[0, 1.01, 12], [1, 1.01, 0]], "batl": NaN}, {"timestamp": 1631554919622, "ltp": 1.33, "tv": 268.36, "trd": NaN, "batb": [[0, 1.18, 166.66], [1, 1.01, 12]], "batl": NaN}, {"timestamp": 1631554951796, "ltp": 1.33, "tv": 268.36, "trd": NaN, "batb": [[0, 1.01, 12], [1, 1.01, 0]], "batl": NaN}, {"timestamp": 1631554956702, "ltp": 1.33, "tv": 268.36, "trd": NaN, "batb": [[0, 1.23, 130.43], [1, 1.01, 12]], "batl": NaN}, {"timestamp": 1631555011901, "ltp": 1.33, "tv": 268.36, "trd": NaN, "batb": [[0, 1.01, 12], [1, 1.01, 0]], "batl": NaN}, {"timestamp": 1631555016923, "ltp": 1.33, "tv": 268.36, "trd": NaN, "batb": [[0, 1.34, 88.23], [1, 1.01, 12]], "batl": NaN}, {"timestamp": 1631555123821, "ltp": 1.33, "tv": 268.36, "trd": NaN, "batb": [[0, 1.01, 12], [1, 1.01, 0]], "batl": NaN}, {"timestamp": 1631555128826, "ltp": 1.33, "tv": 268.36, "trd": NaN, "batb": [[0, 1.27, 111.11], [1, 1.01, 12]], "batl": NaN}, {"timestamp": 1631555143588, "ltp": 1.33, "tv": 268.36, "trd": NaN, "batb": [[0, 1.01, 12], [1, 1.01, 0]], "batl": NaN}, {"timestamp": 1631555148608, "ltp": 1.33, "tv": 268.36, "trd": NaN, "batb": [[0, 1.34, 88.23], [1, 1.01, 12]], "batl": NaN}, {"timestamp": 1631555164819, "ltp": 1.33, "tv": 268.36, "trd": NaN, "batb": [[0, 1.01, 12], [1, 1.01, 0]], "batl": NaN}, {"timestamp": 1631555169711, "ltp": 1.33, "tv": 268.36, "trd": NaN, "batb": [[0, 1.31, 96.77], [1, 1.01, 12]], "batl": NaN}, {"timestamp": 1631555183720, "ltp": 1.33, "tv": 268.36, "trd": NaN, "batb": [[0, 1.01, 12], [1, 1.01, 0]], "batl": NaN}, {"timestamp": 1631555188739, "ltp": 1.33, "tv": 268.36, "trd": NaN, "batb": [[0, 1.38, 78.94], [1, 1.01, 12]], "batl": NaN}, {"timestamp": 1631555214564, "ltp": 1.33, "tv": 268.36, "trd": NaN, "batb": [[0, 1.01, 12], [1, 1.01, 0]], "batl": NaN}, {"timestamp": 1631555219489, "ltp": 1.33, "tv": 268.36, "trd": NaN, "batb": [[0, 1.45, 66.66], [1, 1.01, 12]], "batl": NaN}, {"timestamp": 1631555244625, "ltp": 1.33, "tv": 268.36, "trd": NaN, "batb": [[0, 1.01, 12], [1, 1.01, 0]], "batl": NaN}, {"timestamp": 1631555249444, "ltp": 1.33, "tv": 268.36, "trd": NaN, "batb": [[0, 1.38, 78.94], [1, 1.01, 12]], "batl": NaN}, {"timestamp": 1631555283294, "ltp": 1.33, "tv": 268.36, "trd": NaN, "batb": [[0, 1.01, 12], [1, 1.01, 0]], "batl": NaN}, {"timestamp": 1631555288078, "ltp": 1.33, "tv": 268.36, "trd": NaN, "batb": [[0, 1.31, 96.77], [1, 1.01, 12]], "batl": NaN}, {"timestamp": 1631555327508, "ltp": 1.33, "tv": 268.36, "trd": NaN, "batb": [[0, 1.01, 12], [1, 1.01, 0]], "batl": NaN}, {"timestamp": 1631555332533, "ltp": 1.33, "tv": 268.36, "trd": NaN, "batb": [[0, 1.38, 78.94], [1, 1.01, 12]], "batl": NaN}, {"timestamp": 1631555386258, "ltp": 1.33, "tv": 268.36, "trd": NaN, "batb": [[0, 1.01, 12], [1, 1.01, 0]], "batl": NaN}, {"timestamp": 1631555391226, "ltp": 1.33, "tv": 268.36, "trd": NaN, "batb": [[0, 1.31, 96.77], [1, 1.01, 12]], "batl": NaN}, {"timestamp": 1631555406754, "ltp": 1.33, "tv": 268.36, "trd": NaN, "batb": NaN, "batl": [[0, 100, 0.93]]}, {"timestamp": 1631555430698, "ltp": 1.33, "tv": 268.36, "trd": NaN, "batb": [[0, 1.01, 12], [1, 1.01, 0]], "batl": NaN}, {"timestamp": 1631555435567, "ltp": 1.33, "tv": 268.36, "trd": NaN, "batb": [[0, 1.38, 78.94], [1, 1.01, 12]], "batl": NaN}, {"timestamp": 1631555467923, "ltp": 1.33, "tv": 268.36, "trd": NaN, "batb": [[0, 1.01, 12], [1, 1.01, 0]], "batl": NaN}, {"timestamp": 1631555472843, "ltp": 1.33, "tv": 268.36, "trd": NaN, "batb": [[0, 1.45, 66.66], [1, 1.01, 12]], "batl": NaN}, {"timestamp": 1631555505756, "ltp": 1.33, "tv": 268.36, "trd": NaN, "batb": [[0, 1.01, 12], [1, 1.01, 0]], "batl": NaN}, {"timestamp": 1631555510658, "ltp": 1.33, "tv": 268.36, "trd": NaN, "batb": [[0, 1.51, 58.82], [1, 1.01, 12]], "batl": NaN}, {"timestamp": 1631555538119, "ltp": 1.33, "tv": 268.36, "trd": NaN, "batb": [[0, 1.01, 12], [1, 1.01, 0]], "batl": NaN}, {"timestamp": 1631555543124, "ltp": 1.33, "tv": 268.36, "trd": NaN, "batb": [[0, 1.45, 66.66], [1, 1.01, 12]], "batl": NaN}, {"timestamp": 1631555563069, "ltp": 1.33, "tv": 268.36, "trd": NaN, "batb": [[0, 1.01, 12], [1, 1.01, 0]], "batl": NaN}, {"timestamp": 1631555567985, "ltp": 1.33, "tv": 268.36, "trd": NaN, "batb": [[0, 1.38, 78.94], [1, 1.01, 12]], "batl": NaN}, {"timestamp": 1631555603755, "ltp": 1.33, "tv": 268.36, "trd": NaN, "batb": [[0, 1.01, 12], [1, 1.01, 0]], "batl": NaN}, {"timestamp": 1631555608629, "ltp": 1.33, "tv": 268.36, "trd": NaN, "batb": [[0, 1.42, 71.42], [1, 1.01, 12]], "batl": NaN}, {"timestamp": 1631555616787, "ltp": 1.33, "tv": 268.36, "trd": NaN, "batb": [[0, 1.01, 12], [1, 1.01, 0]], "batl": NaN}, {"timestamp": 1631555621656, "ltp": 1.33, "tv": 268.36, "trd": NaN, "batb": [[0, 1.38, 78.94], [1, 1.01, 12]], "batl": NaN}, {"timestamp": 1631555643389, "ltp": 1.38, "tv": 271.78, "trd": [[1.38, 3.42]], "batb": [[0, 1.01, 12], [1, 1.01, 0]], "batl": NaN}, {"timestamp": 1631555648298, "ltp": 1.38, "tv": 271.78, "trd": NaN, "batb": [[0, 1.38, 78.94], [1, 1.01, 12]], "batl": NaN}, {"timestamp": 1631555656869, "ltp": 1.38, "tv": 271.78, "trd": NaN, "batb": [[0, 1.01, 12], [1, 1.01, 0]], "batl": NaN}, {"timestamp": 1631555661785, "ltp": 1.38, "tv": 271.78, "trd": NaN, "batb": [[0, 1.34, 88.23], [1, 1.01, 12]], "batl": NaN}, {"timestamp": 1631555798884, "ltp": 1.38, "tv": 271.78, "trd": NaN, "batb": [[0, 1.01, 12], [1, 1.01, 0]], "batl": NaN}, {"timestamp": 1631555803890, "ltp": 1.38, "tv": 271.78, "trd": NaN, "batb": [[0, 1.38, 78.94], [1, 1.01, 12]], "batl": NaN}, {"timestamp": 1631555829329, "ltp": 1.38, "tv": 271.78, "trd": NaN, "batb": [[0, 1.01, 12], [1, 1.01, 0]], "batl": NaN}, {"timestamp": 1631555834235, "ltp": 1.38, "tv": 271.78, "trd": NaN, "batb": [[0, 1.34, 88.23], [1, 1.01, 12]], "batl": NaN}, {"timestamp": 1631555870148, "ltp": 1.38, "tv": 271.78, "trd": NaN, "batb": [[0, 1.01, 12], [1, 1.01, 0]], "batl": NaN}, {"timestamp": 1631555875074, "ltp": 1.38, "tv": 271.78, "trd": NaN, "batb": [[0, 1.27, 111.11], [1, 1.01, 12]], "batl": NaN}, {"timestamp": 1631555949893, "ltp": 1.38, "tv": 271.78, "trd": NaN, "batb": [[0, 1.01, 12], [1, 1.01, 0]], "batl": NaN}, {"timestamp": 1631555954797, "ltp": 1.38, "tv": 271.78, "trd": NaN, "batb": [[0, 1.34, 88.23], [1, 1.01, 12]], "batl": NaN}, {"timestamp": 1631556008368, "ltp": 1.38, "tv": 271.78, "trd": NaN, "batb": [[0, 1.01, 12], [1, 1.01, 0]], "batl": NaN}, {"timestamp": 1631556013305, "ltp": 1.38, "tv": 271.78, "trd": NaN, "batb": [[0, 1.23, 130.43], [1, 1.01, 12]], "batl": NaN}, {"timestamp": 1631556035506, "ltp": 1.38, "tv": 271.78, "trd": NaN, "batb": [[0, 1.01, 12], [1, 1.01, 0]], "batl": NaN}, {"timestamp": 1631556040404, "ltp": 1.38, "tv": 271.78, "trd": NaN, "batb": [[0, 1.34, 88.23], [1, 1.01, 12]], "batl": NaN}, {"timestamp": 1631556062451, "ltp": 1.38, "tv": 271.78, "trd": NaN, "batb": [[0, 1.01, 12], [1, 1.01, 0]], "batl": NaN}, {"timestamp": 1631556067433, "ltp": 1.38, "tv": 271.78, "trd": NaN, "batb": [[0, 1.23, 130.43], [1, 1.01, 12]], "batl": NaN}, {"timestamp": 1631556085021, "ltp": 1.38, "tv": 271.78, "trd": NaN, "batb": [[0, 1.01, 12], [1, 1.01, 0]], "batl": NaN}, {"timestamp": 1631556089976, "ltp": 1.38, "tv": 271.78, "trd": NaN, "batb": [[0, 1.34, 88.23], [1, 1.01, 12]], "batl": NaN}, {"timestamp": 1631556110306, "ltp": 1.38, "tv": 271.78, "trd": NaN, "batb": [[0, 1.01, 12], [1, 1.01, 0]], "batl": NaN}, {"timestamp": 1631556115206, "ltp": 1.38, "tv": 271.78, "trd": NaN, "batb": [[0, 1.38, 78.94], [1, 1.01, 12]], "batl": NaN}, {"timestamp": 1631556132755, "ltp": 1.38, "tv": 271.78, "trd": NaN, "batb": [[0, 1.01, 12], [1, 1.01, 0]], "batl": NaN}, {"timestamp": 1631556137782, "ltp": 1.38, "tv": 271.78, "trd": NaN, "batb": [[0, 1.48, 62.5], [1, 1.01, 12]], "batl": NaN}, {"timestamp": 1631556159628, "ltp": 1.48, "tv": 276.6, "trd": [[1.48, 4.82]], "batb": [[0, 1.48, 60.09]], "batl": NaN}, {"timestamp": 1631556160035, "ltp": 1.48, "tv": 276.6, "trd": NaN, "batb": [[0, 1.01, 12], [1, 1.01, 0]], "batl": NaN}, {"timestamp": 1631556164906, "ltp": 1.48, "tv": 276.6, "trd": NaN, "batb": [[0, 1.48, 62.5], [1, 1.01, 12]], "batl": NaN}, {"timestamp": 1631556170739, "ltp": 1.48, "tv": 276.6, "trd": NaN, "batb": [[0, 1.01, 12], [1, 1.01, 0]], "batl": NaN}, {"timestamp": 1631556175518, "ltp": 1.48, "tv": 276.6, "trd": NaN, "batb": [[0, 1.55, 54.54], [1, 1.01, 12]], "batl": NaN}, {"timestamp": 1631556199458, "ltp": 1.48, "tv": 276.6, "trd": NaN, "batb": [[0, 1.01, 12], [1, 1.01, 0]], "batl": NaN}, {"timestamp": 1631556204371, "ltp": 1.48, "tv": 276.6, "trd": NaN, "batb": [[0, 1.48, 62.5], [1, 1.01, 12]], "batl": NaN}, {"timestamp": 1631556221247, "ltp": 1.48, "tv": 276.6, "trd": NaN, "batb": [[0, 1.01, 12], [1, 1.01, 0]], "batl": NaN}, {"timestamp": 1631556226128, "ltp": 1.48, "tv": 276.6, "trd": NaN, "batb": [[0, 1.45, 66.66], [1, 1.01, 12]], "batl": NaN}, {"timestamp": 1631556239832, "ltp": 1.48, "tv": 276.6, "trd": NaN, "batb": [[0, 1.01, 12], [1, 1.01, 0]], "batl": NaN}, {"timestamp": 1631556244752, "ltp": 1.48, "tv": 276.6, "trd": NaN, "batb": [[0, 1.38, 78.94], [1, 1.01, 12]], "batl": NaN}, {"timestamp": 1631556450742, "ltp": 1.38, "tv": 434.45, "trd": [[1.38, 161.27]], "batb": [[0, 1.01, 12], [1, 1.01, 0]], "batl": [[0, 1.38, 263.08], [1, 100, 0.93]]}, {"timestamp": 1631556456084, "ltp": 1.38, "tv": 434.45, "trd": NaN, "batb": [[0, 1.31, 96.77], [1, 1.01, 12]], "batl": NaN}, {"timestamp": 1631556488508, "ltp": 1.38, "tv": 434.45, "trd": NaN, "batb": [[0, 1.01, 12], [1, 1.01, 0]], "batl": NaN}, {"timestamp": 1631556491722, "ltp": 1.38, "tv": 434.45, "trd": NaN, "batb": NaN, "batl": [[0, 100, 0.93], [1, 100, 0]]}, {"timestamp": 1631556496417, "ltp": 1.38, "tv": 434.45, "trd": NaN, "batb": [[0, 1.38, 65.35], [1, 1.01, 12]], "batl": NaN}, {"timestamp": 1631556497436, "ltp": 1.38, "tv": 434.45, "trd": NaN, "batb": [[0, 1.45, 66.66], [1, 1.38, 238.74], [2, 1.01, 12]], "batl": NaN}, {"timestamp": 1631556498524, "ltp": 1.38, "tv": 434.45, "trd": NaN, "batb": [[1, 1.38, 119.54]], "batl": NaN}, {"timestamp": 1631556498914, "ltp": 1.38, "tv": 434.45, "trd": NaN, "batb": [[1, 1.38, 48.34]], "batl": NaN}, {"timestamp": 1631556502724, "ltp": 1.38, "tv": 434.45, "trd": NaN, "batb": [[1, 1.01, 12], [2, 1.01, 0]], "batl": NaN}, {"timestamp": 1631556523452, "ltp": 1.38, "tv": 434.45, "trd": NaN, "batb": [[0, 1.01, 12], [1, 1.01, 0]], "batl": NaN}, {"timestamp": 1631556528374, "ltp": 1.38, "tv": 434.45, "trd": NaN, "batb": [[0, 1.48, 62.5], [1, 1.01, 12]], "batl": NaN}, {"timestamp": 1631556564506, "ltp": 1.38, "tv": 434.45, "trd": NaN, "batb": [[0, 1.01, 12], [1, 1.01, 0]], "batl": NaN}, {"timestamp": 1631556569391, "ltp": 1.38, "tv": 434.45, "trd": NaN, "batb": [[0, 1.45, 66.66], [1, 1.01, 12]], "batl": NaN}, {"timestamp": 1631556599224, "ltp": 1.38, "tv": 434.45, "trd": NaN, "batb": [[0, 1.01, 12], [1, 1.01, 0]], "batl": NaN}, {"timestamp": 1631556604169, "ltp": 1.38, "tv": 434.45, "trd": NaN, "batb": [[0, 1.34, 88.23], [1, 1.01, 12]], "batl": NaN}, {"timestamp": 1631556612658, "ltp": 1.34, "tv": 610.88, "trd": [[1.34, 176.43]], "batb": [[0, 1.01, 12], [1, 1.01, 0]], "batl": [[0, 1.34, 58.89], [1, 100, 0.93]]}, {"timestamp": 1631556617866, "ltp": 1.34, "tv": 610.88, "trd": NaN, "batb": [[0, 1.27, 111.11], [1, 1.01, 12]], "batl": NaN}, {"timestamp": 1631556638827, "ltp": 1.34, "tv": 610.88, "trd": NaN, "batb": NaN, "batl": [[0, 100, 0.93], [1, 100, 0]]}, {"timestamp": 1631556644316, "ltp": 1.27, "tv": 728.7, "trd": [[1.27, 117.82]], "batb": [[0, 1.01, 12], [1, 1.01, 0]], "batl": NaN}, {"timestamp": 1631556649259, "ltp": 1.27, "tv": 728.7, "trd": NaN, "batb": [[0, 1.27, 111.11], [1, 1.01, 12]], "batl": NaN}, {"timestamp": 1631556660757, "ltp": 1.27, "tv": 728.7, "trd": NaN, "batb": [[0, 1.01, 12], [1, 1.01, 0]], "batl": NaN}, {"timestamp": 1631556665683, "ltp": 1.27, "tv": 728.7, "trd": NaN, "batb": [[0, 1.18, 166.66], [1, 1.01, 12]], "batl": NaN}, {"timestamp": 1631556692815, "ltp": 1.27, "tv": 728.7, "trd": NaN, "batb": [[0, 1.01, 12], [1, 1.01, 0]], "batl": NaN}, {"timestamp": 1631556697703, "ltp": 1.27, "tv": 728.7, "trd": NaN, "batb": [[0, 1.12, 249.99], [1, 1.01, 12]], "batl": NaN}, {"timestamp": 1631556721048, "ltp": 1.27, "tv": 728.7, "trd": NaN, "batb": [[0, 1.01, 12], [1, 1.01, 0]], "batl": NaN}, {"timestamp": 1631556725916, "ltp": 1.27, "tv": 728.7, "trd": NaN, "batb": [[0, 1.08, 374.99], [1, 1.01, 12]], "batl": NaN}, {"timestamp": 1631556745457, "ltp": 1.27, "tv": 728.7, "trd": NaN, "batb": [[0, 1.01, 12], [1, 1.01, 0]], "batl": NaN}, {"timestamp": 1631556750390, "ltp": 1.27, "tv": 728.7, "trd": NaN, "batb": [[0, 1.12, 249.99], [1, 1.01, 12]], "batl": NaN}, {"timestamp": 1631556781291, "ltp": 1.27, "tv": 728.7, "trd": NaN, "batb": [[0, 1.01, 12], [1, 1.01, 0]], "batl": NaN}, {"timestamp": 1631556786229, "ltp": 1.27, "tv": 728.7, "trd": NaN, "batb": [[0, 1.08, 374.99], [1, 1.01, 12]], "batl": NaN}, {"timestamp": 1631556803397, "ltp": 1.27, "tv": 728.7, "trd": NaN, "batb": [[0, 1.01, 12], [1, 1.01, 0]], "batl": NaN}, {"timestamp": 1631556808367, "ltp": 1.27, "tv": 728.7, "trd": NaN, "batb": [[0, 1.05, 599.99], [1, 1.01, 12]], "batl": NaN}, {"timestamp": 1631556920772, "ltp": 1.27, "tv": 728.7, "trd": NaN, "batb": [[0, 1.01, 12], [1, 1.01, 0]], "batl": NaN}, {"timestamp": 1631556925706, "ltp": 1.27, "tv": 728.7, "trd": NaN, "batb": [[0, 1.08, 374.99], [1, 1.01, 12]], "batl": NaN}, {"timestamp": 1631556942839, "ltp": 1.27, "tv": 728.7, "trd": NaN, "batb": [[0, 1.01, 12], [1, 1.01, 0]], "batl": NaN}, {"timestamp": 1631556947823, "ltp": 1.27, "tv": 728.7, "trd": NaN, "batb": [[0, 1.15, 200], [1, 1.01, 12]], "batl": NaN}, {"timestamp": 1631556977439, "ltp": 1.27, "tv": 728.7, "trd": NaN, "batb": [[0, 1.01, 12], [1, 1.01, 0]], "batl": NaN}, {"timestamp": 1631556982333, "ltp": 1.27, "tv": 728.7, "trd": NaN, "batb": [[0, 1.08, 374.99], [1, 1.01, 12]], "batl": NaN}, {"timestamp": 1631557001277, "ltp": 1.27, "tv": 728.7, "trd": NaN, "batb": [[0, 1.01, 12], [1, 1.01, 0]], "batl": NaN}, {"timestamp": 1631557006305, "ltp": 1.27, "tv": 728.7, "trd": NaN, "batb": [[0, 1.15, 200], [1, 1.01, 12]], "batl": NaN}, {"timestamp": 1631557032517, "ltp": 1.27, "tv": 728.7, "trd": NaN, "batb": [[0, 1.01, 12], [1, 1.01, 0]], "batl": NaN}, {"timestamp": 1631557037436, "ltp": 1.27, "tv": 728.7, "trd": NaN, "batb": [[0, 1.18, 166.66], [1, 1.01, 12]], "batl": NaN}, {"timestamp": 1631557078475, "ltp": 1.27, "tv": 728.7, "trd": NaN, "batb": [[0, 1.01, 12], [1, 1.01, 0]], "batl": NaN}, {"timestamp": 1631557083476, "ltp": 1.27, "tv": 728.7, "trd": NaN, "batb": [[0, 1.12, 249.99], [1, 1.01, 12]], "batl": NaN}, {"timestamp": 1631557126207, "ltp": 1.27, "tv": 728.7, "trd": NaN, "batb": [[0, 1.01, 12], [1, 1.01, 0]], "batl": NaN}, {"timestamp": 1631557132228, "ltp": 1.27, "tv": 728.7, "trd": NaN, "batb": [[0, 1.18, 166.66], [1, 1.01, 12]], "batl": NaN}, {"timestamp": 1631557149934, "ltp": 1.27, "tv": 728.7, "trd": NaN, "batb": [[0, 1.01, 12], [1, 1.01, 0]], "batl": NaN}, {"timestamp": 1631557154826, "ltp": 1.27, "tv": 728.7, "trd": NaN, "batb": [[0, 1.12, 249.99], [1, 1.01, 12]], "batl": NaN}, {"timestamp": 1631557166847, "ltp": 1.27, "tv": 728.7, "trd": NaN, "batb": [[0, 1.01, 12], [1, 1.01, 0]], "batl": NaN}, {"timestamp": 1631557171745, "ltp": 1.27, "tv": 728.7, "trd": NaN, "batb": [[0, 1.15, 200], [1, 1.01, 12]], "batl": NaN}, {"timestamp": 1631557189197, "ltp": 1.27, "tv": 728.7, "trd": NaN, "batb": [[0, 1.01, 12], [1, 1.01, 0]], "batl": NaN}, {"timestamp": 1631557194101, "ltp": 1.27, "tv": 728.7, "trd": NaN, "batb": [[0, 1.08, 374.99], [1, 1.01, 12]], "batl": NaN}, {"timestamp": 1631557332176, "ltp": 1.27, "tv": 728.7, "trd": NaN, "batb": [[0, 1.01, 12], [1, 1.01, 0]], "batl": NaN}, {"timestamp": 1631557337012, "ltp": 1.27, "tv": 728.7, "trd": NaN, "batb": [[0, 1.11, 272.72], [1, 1.01, 12]], "batl": NaN}, {"timestamp": 1631557354336, "ltp": 1.27, "tv": 728.7, "trd": NaN, "batb": [[0, 1.01, 12], [1, 1.01, 0]], "batl": NaN}, {"timestamp": 1631557359281, "ltp": 1.27, "tv": 728.7, "trd": NaN, "batb": [[0, 1.15, 200], [1, 1.01, 12]], "batl": NaN}, {"timestamp": 1631557376869, "ltp": 1.27, "tv": 728.7, "trd": NaN, "batb": [[0, 1.01, 12], [1, 1.01, 0]], "batl": NaN}, {"timestamp": 1631557381792, "ltp": 1.27, "tv": 728.7, "trd": NaN, "batb": [[0, 1.18, 166.66], [1, 1.01, 12]], "batl": NaN}, {"timestamp": 1631557400427, "ltp": 1.27, "tv": 728.7, "trd": NaN, "batb": [[0, 1.01, 12], [1, 1.01, 0]], "batl": NaN}, {"timestamp": 1631557405395, "ltp": 1.27, "tv": 728.7, "trd": NaN, "batb": [[0, 1.15, 200], [1, 1.01, 12]], "batl": NaN}, {"timestamp": 1631557429664, "ltp": 1.27, "tv": 728.7, "trd": NaN, "batb": [[0, 1.01, 12], [1, 1.01, 0]], "batl": NaN}, {"timestamp": 1631557434663, "ltp": 1.27, "tv": 728.7, "trd": NaN, "batb": [[0, 1.12, 249.99], [1, 1.01, 12]], "batl": NaN}, {"timestamp": 1631557459169, "ltp": 1.27, "tv": 728.7, "trd": NaN, "batb": [[0, 1.01, 12], [1, 1.01, 0]], "batl": NaN}, {"timestamp": 1631557464001, "ltp": 1.27, "tv": 728.7, "trd": NaN, "batb": [[0, 1.11, 272.72], [1, 1.01, 12]], "batl": NaN}, {"timestamp": 1631557478794, "ltp": 1.27, "tv": 728.7, "trd": NaN, "batb": [[0, 1.01, 12], [1, 1.01, 0]], "batl": NaN}, {"timestamp": 1631557483809, "ltp": 1.27, "tv": 728.7, "trd": NaN, "batb": [[0, 1.06, 499.99], [1, 1.01, 12]], "batl": NaN}, {"timestamp": 1631557507760, "ltp": 1.27, "tv": 728.7, "trd": NaN, "batb": [[0, 1.01, 12], [1, 1.01, 0]], "batl": NaN}, {"timestamp": 1631557512777, "ltp": 1.27, "tv": 728.7, "trd": NaN, "batb": [[0, 1.12, 249.99], [1, 1.01, 12]], "batl": NaN}, {"timestamp": 1631557542665, "ltp": 1.27, "tv": 728.7, "trd": NaN, "batb": [[0, 1.01, 12], [1, 1.01, 0]], "batl": NaN}, {"timestamp": 1631557547717, "ltp": 1.27, "tv": 728.7, "trd": NaN, "batb": [[0, 1.18, 166.66], [1, 1.01, 12]], "batl": NaN}, {"timestamp": 1631557591989, "ltp": 1.27, "tv": 728.7, "trd": NaN, "batb": [[0, 1.01, 12], [1, 1.01, 0]], "batl": NaN}, {"timestamp": 1631557596898, "ltp": 1.27, "tv": 728.7, "trd": NaN, "batb": [[0, 1.12, 249.99], [1, 1.01, 12]], "batl": NaN}, {"timestamp": 1631557624508, "ltp": 1.27, "tv": 728.7, "trd": NaN, "batb": [[0, 1.01, 12], [1, 1.01, 0]], "batl": NaN}, {"timestamp": 1631557629391, "ltp": 1.27, "tv": 728.7, "trd": NaN, "batb": [[0, 1.18, 166.66], [1, 1.01, 12]], "batl": NaN}, {"timestamp": 1631557670805, "ltp": 1.27, "tv": 728.7, "trd": NaN, "batb": [[0, 1.01, 12], [1, 1.01, 0]], "batl": NaN}, {"timestamp": 1631557675721, "ltp": 1.27, "tv": 728.7, "trd": NaN, "batb": [[0, 1.27, 111.11], [1, 1.01, 12]], "batl": NaN}, {"timestamp": 1631557710745, "ltp": 1.27, "tv": 728.7, "trd": NaN, "batb": [[0, 1.01, 12], [1, 1.01, 0]], "batl": NaN}, {"timestamp": 1631557715669, "ltp": 1.27, "tv": 728.7, "trd": NaN, "batb": [[0, 1.42, 71.42], [1, 1.01, 12]], "batl": NaN}, {"timestamp": 1631557742195, "ltp": 1.27, "tv": 728.7, "trd": NaN, "batb": [[0, 1.01, 12], [1, 1.01, 0]], "batl": NaN}, {"timestamp": 1631557747102, "ltp": 1.27, "tv": 728.7, "trd": NaN, "batb": [[0, 1.55, 54.54], [1, 1.01, 12]], "batl": NaN}, {"timestamp": 1631557776959, "ltp": 1.27, "tv": 728.7, "trd": NaN, "batb": [[0, 1.01, 12], [1, 1.01, 0]], "batl": NaN}, {"timestamp": 1631557781848, "ltp": 1.27, "tv": 728.7, "trd": NaN, "batb": [[0, 1.71, 42.25], [1, 1.01, 12]], "batl": NaN}, {"timestamp": 1631557873459, "ltp": 1.27, "tv": 728.7, "trd": NaN, "batb": [[0, 1.01, 12], [1, 1.01, 0]], "batl": NaN}, {"timestamp": 1631557878300, "ltp": 1.27, "tv": 728.7, "trd": NaN, "batb": [[0, 1.78, 38.46], [1, 1.01, 12]], "batl": NaN}, {"timestamp": 1631557898300, "ltp": 1.27, "tv": 728.7, "trd": NaN, "batb": [[0, 1.01, 12], [1, 1.01, 0]], "batl": NaN}, {"timestamp": 1631557903202, "ltp": 1.27, "tv": 728.7, "trd": NaN, "batb": [[0, 1.73, 41.09], [1, 1.01, 12]], "batl": NaN}, {"timestamp": 1631557923051, "ltp": 1.27, "tv": 728.7, "trd": NaN, "batb": [[0, 1.01, 12], [1, 1.01, 0]], "batl": NaN}, {"timestamp": 1631557927936, "ltp": 1.27, "tv": 728.7, "trd": NaN, "batb": [[0, 1.65, 46.15], [1, 1.01, 12]], "batl": NaN}, {"timestamp": 1631557954388, "ltp": 1.27, "tv": 728.7, "trd": NaN, "batb": [[0, 1.01, 12], [1, 1.01, 0]], "batl": NaN}, {"timestamp": 1631557959302, "ltp": 1.27, "tv": 728.7, "trd": NaN, "batb": [[0, 1.78, 38.46], [1, 1.01, 12]], "batl": NaN}, {"timestamp": 1631558105684, "ltp": 1.27, "tv": 728.7, "trd": NaN, "batb": [[0, 1.01, 12], [1, 1.01, 0]], "batl": NaN}, {"timestamp": 1631558110575, "ltp": 1.27, "tv": 728.7, "trd": NaN, "batb": [[0, 1.88, 34.09], [1, 1.01, 12]], "batl": NaN}, {"timestamp": 1631558110891, "ltp": 1.27, "tv": 728.7, "trd": NaN, "batb": [[0, 1.01, 12], [1, 1.01, 0]], "batl": NaN}, {"timestamp": 1631558120980, "ltp": 1.27, "tv": 728.7, "trd": NaN, "batb": [[0, 1.6, 49.99], [1, 1.01, 12]], "batl": NaN}, {"timestamp": 1631558267091, "ltp": 1.27, "tv": 728.7, "trd": NaN, "batb": [[0, 1.01, 12], [1, 1.01, 0]], "batl": NaN}, {"timestamp": 1631558272084, "ltp": 1.27, "tv": 728.7, "trd": NaN, "batb": [[0, 1.45, 66.66], [1, 1.01, 12]], "batl": NaN}, {"timestamp": 1631558322705, "ltp": 1.27, "tv": 728.7, "trd": NaN, "batb": [[0, 1.01, 12], [1, 1.01, 0]], "batl": NaN}, {"timestamp": 1631558327698, "ltp": 1.27, "tv": 728.7, "trd": NaN, "batb": [[0, 1.38, 78.94], [1, 1.01, 12]], "batl": NaN}, {"timestamp": 1631558359831, "ltp": 1.27, "tv": 728.7, "trd": NaN, "batb": [[0, 1.01, 12], [1, 1.01, 0]], "batl": NaN}, {"timestamp": 1631558364720, "ltp": 1.27, "tv": 728.7, "trd": NaN, "batb": [[0, 1.42, 71.42], [1, 1.01, 12]], "batl": NaN}, {"timestamp": 1631558375137, "ltp": 1.61, "tv": 758.56, "trd": [[1.61, 29.86]], "batb": NaN, "batl": NaN}, {"timestamp": 1631558380247, "ltp": 1.61, "tv": 758.56, "trd": NaN, "batb": [[0, 1.61, 32.34], [1, 1.42, 71.42], [2, 1.01, 12]], "batl": NaN}, {"timestamp": 1631558381247, "ltp": 1.61, "tv": 758.56, "trd": NaN, "batb": [[0, 1.61, 2.54]], "batl": NaN}, {"timestamp": 1631558387369, "ltp": 1.61, "tv": 758.56, "trd": NaN, "batb": [[0, 1.42, 71.42], [1, 1.01, 12], [2, 1.01, 0]], "batl": NaN}, {"timestamp": 1631558387748, "ltp": 1.61, "tv": 758.56, "trd": NaN, "batb": [[0, 1.66, 29.87], [1, 1.42, 71.42], [2, 1.01, 12]], "batl": NaN}, {"timestamp": 1631558389059, "ltp": 1.61, "tv": 758.56, "trd": NaN, "batb": [[0, 1.42, 71.42], [1, 1.01, 12], [2, 1.01, 0]], "batl": NaN}, {"timestamp": 1631558391859, "ltp": 1.61, "tv": 758.56, "trd": NaN, "batb": [[0, 1.66, 2.54], [1, 1.42, 71.42], [2, 1.01, 12]], "batl": NaN}, {"timestamp": 1631558393171, "ltp": 1.61, "tv": 758.56, "trd": NaN, "batb": [[1, 1.01, 12], [2, 1.01, 0]], "batl": NaN}, {"timestamp": 1631558398209, "ltp": 1.61, "tv": 758.56, "trd": NaN, "batb": [[1, 1.34, 88.23], [2, 1.01, 12]], "batl": NaN}, {"timestamp": 1631558409102, "ltp": 1.66, "tv": 761.09, "trd": [[1.66, 2.54]], "batb": [[0, 1.34, 88.23], [1, 1.01, 12], [2, 1.01, 0]], "batl": NaN}, {"timestamp": 1631558418798, "ltp": 1.66, "tv": 761.09, "trd": NaN, "batb": [[0, 1.01, 12], [1, 1.01, 0]], "batl": NaN}, {"timestamp": 1631558424607, "ltp": 1.66, "tv": 761.09, "trd": NaN, "batb": [[0, 1.38, 78.94], [1, 1.01, 12]], "batl": NaN}, {"timestamp": 1631558439497, "ltp": 1.66, "tv": 761.09, "trd": NaN, "batb": [[0, 1.01, 12], [1, 1.01, 0]], "batl": NaN}]}, {"runnerId": 11862899, "odds": [{"timestamp": 1631551222271, "ltp": 2.54, "tv": 0.92, "trd": [[2.54, 0.92]], "batb": NaN, "batl": NaN}, {"timestamp": 1631551227139, "ltp": 2.54, "tv": 0.92, "trd": NaN, "batb": [[0, 2.58, 18.98], [1, 1.01, 12]], "batl": NaN}, {"timestamp": 1631551275541, "ltp": 2.54, "tv": 0.92, "trd": NaN, "batb": [[0, 1.01, 12], [1, 1.01, 0]], "batl": NaN}, {"timestamp": 1631551280563, "ltp": 2.54, "tv": 0.92, "trd": NaN, "batb": [[0, 2.42, 21.12], [1, 1.01, 12]], "batl": NaN}, {"timestamp": 1631551301058, "ltp": 2.54, "tv": 0.92, "trd": NaN, "batb": [[0, 1.01, 12], [1, 1.01, 0]], "batl": NaN}, {"timestamp": 1631551306084, "ltp": 2.54, "tv": 0.92, "trd": NaN, "batb": [[0, 2.58, 18.98], [1, 1.01, 12]], "batl": NaN}, {"timestamp": 1631551323699, "ltp": 2.54, "tv": 0.92, "trd": NaN, "batb": [[0, 1.01, 12], [1, 1.01, 0]], "batl": NaN}, {"timestamp": 1631551328589, "ltp": 2.54, "tv": 0.92, "trd": NaN, "batb": [[0, 2.42, 21.12], [1, 1.01, 12]], "batl": NaN}, {"timestamp": 1631551349332, "ltp": 2.54, "tv": 0.92, "trd": NaN, "batb": [[0, 1.01, 12], [1, 1.01, 0]], "batl": NaN}, {"timestamp": 1631551354356, "ltp": 2.54, "tv": 0.92, "trd": NaN, "batb": [[0, 2.26, 23.8], [1, 1.01, 12]], "batl": NaN}, {"timestamp": 1631551438912, "ltp": 2.54, "tv": 0.92, "trd": NaN, "batb": [[0, 1.01, 12], [1, 1.01, 0]], "batl": NaN}, {"timestamp": 1631551443960, "ltp": 2.54, "tv": 0.92, "trd": NaN, "batb": [[0, 2.16, 25.86], [1, 1.01, 12]], "batl": NaN}, {"timestamp": 1631551469983, "ltp": 2.54, "tv": 0.92, "trd": NaN, "batb": [[0, 1.01, 12], [1, 1.01, 0]], "batl": NaN}, {"timestamp": 1631551474888, "ltp": 2.54, "tv": 0.92, "trd": NaN, "batb": [[0, 1.98, 30.61], [1, 1.01, 12]], "batl": NaN}, {"timestamp": 1631551514441, "ltp": 2.54, "tv": 0.92, "trd": NaN, "batb": [[0, 1.01, 12], [1, 1.01, 0]], "batl": NaN}, {"timestamp": 1631551519363, "ltp": 2.54, "tv": 0.92, "trd": NaN, "batb": [[0, 1.85, 35.29], [1, 1.01, 12]], "batl": NaN}, {"timestamp": 1631551548690, "ltp": 2.54, "tv": 0.92, "trd": NaN, "batb": [[0, 1.01, 12], [1, 1.01, 0]], "batl": NaN}, {"timestamp": 1631551553761, "ltp": 2.54, "tv": 0.92, "trd": NaN, "batb": [[0, 1.88, 34.09], [1, 1.01, 12]], "batl": NaN}, {"timestamp": 1631551589367, "ltp": 2.54, "tv": 0.92, "trd": NaN, "batb": [[0, 1.01, 12], [1, 1.01, 0]], "batl": NaN}, {"timestamp": 1631551594419, "ltp": 2.54, "tv": 0.92, "trd": NaN, "batb": [[0, 1.85, 35.29], [1, 1.01, 12]], "batl": NaN}, {"timestamp": 1631551615308, "ltp": 2.54, "tv": 0.92, "trd": NaN, "batb": [[0, 1.01, 12], [1, 1.01, 0]], "batl": NaN}, {"timestamp": 1631551620209, "ltp": 2.54, "tv": 0.92, "trd": NaN, "batb": [[0, 1.88, 34.09], [1, 1.01, 12]], "batl": NaN}, {"timestamp": 1631551652142, "ltp": 2.54, "tv": 0.92, "trd": NaN, "batb": [[0, 1.01, 12], [1, 1.01, 0]], "batl": NaN}, {"timestamp": 1631551657157, "ltp": 2.54, "tv": 0.92, "trd": NaN, "batb": [[0, 1.71, 42.25], [1, 1.01, 12]], "batl": NaN}, {"timestamp": 1631551760633, "ltp": 2.54, "tv": 0.92, "trd": NaN, "batb": [[0, 1.01, 12], [1, 1.01, 0]], "batl": NaN}, {"timestamp": 1631551765616, "ltp": 2.54, "tv": 0.92, "trd": NaN, "batb": [[0, 1.85, 35.29], [1, 1.01, 12]], "batl": NaN}, {"timestamp": 1631551818770, "ltp": 2.54, "tv": 0.92, "trd": NaN, "batb": [[0, 1.01, 12], [1, 1.01, 0]], "batl": NaN}, {"timestamp": 1631551823638, "ltp": 2.54, "tv": 0.92, "trd": NaN, "batb": [[0, 1.71, 42.25], [1, 1.01, 12]], "batl": NaN}, {"timestamp": 1631551857943, "ltp": 2.54, "tv": 0.92, "trd": NaN, "batb": [[0, 1.01, 12], [1, 1.01, 0]], "batl": NaN}, {"timestamp": 1631551862935, "ltp": 2.54, "tv": 0.92, "trd": NaN, "batb": [[0, 1.85, 35.29], [1, 1.01, 12]], "batl": NaN}, {"timestamp": 1631551886446, "ltp": 2.54, "tv": 0.92, "trd": NaN, "batb": [[0, 1.01, 12], [1, 1.01, 0]], "batl": NaN}, {"timestamp": 1631551891467, "ltp": 2.54, "tv": 0.92, "trd": NaN, "batb": [[0, 1.71, 42.25], [1, 1.01, 12]], "batl": NaN}, {"timestamp": 1631551909682, "ltp": 2.54, "tv": 0.92, "trd": NaN, "batb": [[0, 1.01, 12], [1, 1.01, 0]], "batl": NaN}, {"timestamp": 1631551914591, "ltp": 2.54, "tv": 0.92, "trd": NaN, "batb": [[0, 1.78, 38.46], [1, 1.01, 12]], "batl": NaN}, {"timestamp": 1631551923523, "ltp": 2.54, "tv": 0.92, "trd": NaN, "batb": [[0, 1.01, 12], [1, 1.01, 0]], "batl": NaN}, {"timestamp": 1631551928533, "ltp": 2.54, "tv": 0.92, "trd": NaN, "batb": [[0, 1.6, 49.99], [1, 1.01, 12]], "batl": NaN}, {"timestamp": 1631551961834, "ltp": 2.54, "tv": 0.92, "trd": NaN, "batb": [[0, 1.01, 12], [1, 1.01, 0]], "batl": NaN}, {"timestamp": 1631551966840, "ltp": 2.54, "tv": 0.92, "trd": NaN, "batb": [[0, 1.73, 41.09], [1, 1.01, 12]], "batl": NaN}, {"timestamp": 1631551998979, "ltp": 2.54, "tv": 0.92, "trd": NaN, "batb": [[0, 1.01, 12], [1, 1.01, 0]], "batl": NaN}, {"timestamp": 1631552004021, "ltp": 2.54, "tv": 0.92, "trd": NaN, "batb": [[0, 1.6, 49.99], [1, 1.01, 12]], "batl": NaN}, {"timestamp": 1631552029120, "ltp": 2.54, "tv": 0.92, "trd": NaN, "batb": [[0, 1.01, 12], [1, 1.01, 0]], "batl": NaN}, {"timestamp": 1631552034129, "ltp": 2.54, "tv": 0.92, "trd": NaN, "batb": [[0, 1.73, 41.09], [1, 1.01, 12]], "batl": NaN}, {"timestamp": 1631552060356, "ltp": 2.54, "tv": 0.92, "trd": NaN, "batb": [[0, 1.01, 12], [1, 1.01, 0]], "batl": NaN}, {"timestamp": 1631552065360, "ltp": 2.54, "tv": 0.92, "trd": NaN, "batb": [[0, 1.78, 38.46], [1, 1.01, 12]], "batl": NaN}, {"timestamp": 1631552076094, "ltp": 2.54, "tv": 0.92, "trd": NaN, "batb": [[0, 1.01, 12], [1, 1.01, 0]], "batl": NaN}, {"timestamp": 1631552081103, "ltp": 2.54, "tv": 0.92, "trd": NaN, "batb": [[0, 1.88, 34.09], [1, 1.01, 12]], "batl": NaN}, {"timestamp": 1631552100829, "ltp": 2.54, "tv": 0.92, "trd": NaN, "batb": [[0, 1.01, 12], [1, 1.01, 0]], "batl": NaN}, {"timestamp": 1631552105743, "ltp": 2.54, "tv": 0.92, "trd": NaN, "batb": [[0, 2.1, 27.27], [1, 1.01, 12]], "batl": NaN}, {"timestamp": 1631552149080, "ltp": 2.54, "tv": 0.92, "trd": NaN, "batb": [[0, 1.01, 12], [1, 1.01, 0]], "batl": NaN}, {"timestamp": 1631552153956, "ltp": 2.54, "tv": 0.92, "trd": NaN, "batb": [[0, 1.98, 30.61], [1, 1.01, 12]], "batl": NaN}, {"timestamp": 1631552198548, "ltp": 2.54, "tv": 0.92, "trd": NaN, "batb": [[0, 1.01, 12], [1, 1.01, 0]], "batl": NaN}, {"timestamp": 1631552203411, "ltp": 2.54, "tv": 0.92, "trd": NaN, "batb": [[0, 1.85, 35.29], [1, 1.01, 12]], "batl": NaN}, {"timestamp": 1631552233978, "ltp": 2.54, "tv": 0.92, "trd": NaN, "batb": NaN, "batl": [[0, 1.88, 60]]}, {"timestamp": 1631552238897, "ltp": 2.54, "tv": 0.92, "trd": NaN, "batb": [[0, 1.01, 12], [1, 1.01, 0]], "batl": NaN}, {"timestamp": 1631552245080, "ltp": 1.88, "tv": 51.04, "trd": [[1.88, 50.12]], "batb": NaN, "batl": [[0, 1.88, 34.94]]}, {"timestamp": 1631552247583, "ltp": 1.88, "tv": 85.98, "trd": [[1.88, 85.06]], "batb": NaN, "batl": NaN}, {"timestamp": 1631552252415, "ltp": 1.88, "tv": 85.98, "trd": NaN, "batb": [[0, 1.88, 34.09], [1, 1.01, 12]], "batl": NaN}, {"timestamp": 1631552269522, "ltp": 1.88, "tv": 94.36, "trd": [[1.88, 93.44]], "batb": [[0, 1.88, 29.9]], "batl": NaN}, {"timestamp": 1631552269935, "ltp": 1.88, "tv": 94.36, "trd": NaN, "batb": [[0, 1.01, 12], [1, 1.01, 0]], "batl": NaN}, {"timestamp": 1631552274818, "ltp": 1.88, "tv": 94.36, "trd": NaN, "batb": [[0, 1.88, 34.09], [1, 1.01, 12]], "batl": NaN}, {"timestamp": 1631552285251, "ltp": 1.88, "tv": 94.36, "trd": NaN, "batb": [[0, 1.01, 12], [1, 1.01, 0]], "batl": NaN}, {"timestamp": 1631552290237, "ltp": 1.88, "tv": 94.36, "trd": NaN, "batb": [[0, 2.1, 27.27], [1, 1.01, 12]], "batl": NaN}, {"timestamp": 1631552315286, "ltp": 1.88, "tv": 94.36, "trd": NaN, "batb": [[0, 1.01, 12], [1, 1.01, 0]], "batl": NaN}, {"timestamp": 1631552320280, "ltp": 1.88, "tv": 94.36, "trd": NaN, "batb": [[0, 2.06, 28.3], [1, 1.01, 12]], "batl": NaN}, {"timestamp": 1631552330618, "ltp": 1.88, "tv": 94.36, "trd": NaN, "batb": [[0, 1.01, 12], [1, 1.01, 0]], "batl": NaN}, {"timestamp": 1631552335591, "ltp": 1.88, "tv": 94.36, "trd": NaN, "batb": [[0, 2.34, 22.38], [1, 1.01, 12]], "batl": NaN}, {"timestamp": 1631552361448, "ltp": 1.88, "tv": 94.36, "trd": NaN, "batb": [[0, 1.01, 12], [1, 1.01, 0]], "batl": NaN}, {"timestamp": 1631552366487, "ltp": 1.88, "tv": 94.36, "trd": NaN, "batb": [[0, 2.5, 20], [1, 1.01, 12]], "batl": NaN}, {"timestamp": 1631552476177, "ltp": 1.88, "tv": 94.36, "trd": NaN, "batb": [[0, 1.01, 12], [1, 1.01, 0]], "batl": NaN}, {"timestamp": 1631552481075, "ltp": 1.88, "tv": 94.36, "trd": NaN, "batb": [[0, 2.34, 22.38], [1, 1.01, 12]], "batl": NaN}, {"timestamp": 1631552503519, "ltp": 1.88, "tv": 94.36, "trd": NaN, "batb": [[0, 1.01, 12], [1, 1.01, 0]], "batl": NaN}, {"timestamp": 1631552508326, "ltp": 1.88, "tv": 94.36, "trd": NaN, "batb": [[0, 2.16, 25.86], [1, 1.01, 12]], "batl": NaN}, {"timestamp": 1631552529667, "ltp": 1.88, "tv": 94.36, "trd": NaN, "batb": [[0, 1.01, 12], [1, 1.01, 0]], "batl": NaN}, {"timestamp": 1631552534562, "ltp": 1.88, "tv": 94.36, "trd": NaN, "batb": [[0, 2.34, 22.38], [1, 1.01, 12]], "batl": NaN}, {"timestamp": 1631552561265, "ltp": 1.88, "tv": 94.36, "trd": NaN, "batb": [[0, 1.01, 12], [1, 1.01, 0]], "batl": NaN}, {"timestamp": 1631552566159, "ltp": 1.88, "tv": 94.36, "trd": NaN, "batb": [[0, 2.16, 25.86], [1, 1.01, 12]], "batl": NaN}, {"timestamp": 1631552606426, "ltp": 1.88, "tv": 94.36, "trd": NaN, "batb": [[0, 1.01, 12], [1, 1.01, 0]], "batl": NaN}, {"timestamp": 1631552611320, "ltp": 1.88, "tv": 94.36, "trd": NaN, "batb": [[0, 2.34, 22.38], [1, 1.01, 12]], "batl": NaN}, {"timestamp": 1631552642096, "ltp": 1.88, "tv": 94.36, "trd": NaN, "batb": [[0, 1.01, 12], [1, 1.01, 0]], "batl": NaN}, {"timestamp": 1631552647092, "ltp": 1.88, "tv": 94.36, "trd": NaN, "batb": [[0, 2.1, 27.27], [1, 1.01, 12]], "batl": NaN}, {"timestamp": 1631552679149, "ltp": 1.88, "tv": 94.36, "trd": NaN, "batb": [[0, 1.01, 12], [1, 1.01, 0]], "batl": NaN}, {"timestamp": 1631552684019, "ltp": 1.88, "tv": 94.36, "trd": NaN, "batb": [[0, 1.88, 34.09], [1, 1.01, 12]], "batl": NaN}, {"timestamp": 1631552702637, "ltp": 1.88, "tv": 94.36, "trd": NaN, "batb": [[0, 1.01, 12], [1, 1.01, 0]], "batl": NaN}, {"timestamp": 1631552707556, "ltp": 1.88, "tv": 94.36, "trd": NaN, "batb": [[0, 2.06, 28.3], [1, 1.01, 12]], "batl": NaN}, {"timestamp": 1631552742193, "ltp": 1.88, "tv": 94.36, "trd": NaN, "batb": [[0, 1.01, 12], [1, 1.01, 0]], "batl": NaN}, {"timestamp": 1631552747083, "ltp": 1.88, "tv": 94.36, "trd": NaN, "batb": [[0, 1.88, 34.09], [1, 1.01, 12]], "batl": NaN}, {"timestamp": 1631552764787, "ltp": 1.88, "tv": 94.36, "trd": NaN, "batb": [[0, 1.01, 12], [1, 1.01, 0]], "batl": NaN}, {"timestamp": 1631552769810, "ltp": 1.88, "tv": 94.36, "trd": NaN, "batb": [[0, 2.06, 28.3], [1, 1.01, 12]], "batl": NaN}, {"timestamp": 1631552803858, "ltp": 1.88, "tv": 94.36, "trd": NaN, "batb": [[0, 1.01, 12], [1, 1.01, 0]], "batl": NaN}, {"timestamp": 1631552808741, "ltp": 1.88, "tv": 94.36, "trd": NaN, "batb": [[0, 1.85, 35.29], [1, 1.01, 12]], "batl": NaN}, {"timestamp": 1631552842721, "ltp": 1.88, "tv": 94.36, "trd": NaN, "batb": [[0, 1.01, 12], [1, 1.01, 0]], "batl": NaN}, {"timestamp": 1631552847592, "ltp": 1.88, "tv": 94.36, "trd": NaN, "batb": [[0, 2.06, 28.3], [1, 1.01, 12]], "batl": NaN}, {"timestamp": 1631552868612, "ltp": 2.06, "tv": 103.03, "trd": [[2.06, 8.68]], "batb": [[0, 2.06, 23.96]], "batl": NaN}, {"timestamp": 1631552869041, "ltp": 2.06, "tv": 103.03, "trd": NaN, "batb": [[0, 1.01, 12], [1, 1.01, 0]], "batl": NaN}, {"timestamp": 1631552879160, "ltp": 2.06, "tv": 103.03, "trd": NaN, "batb": [[0, 2.34, 22.38], [1, 1.01, 12]], "batl": NaN}, {"timestamp": 1631552915373, "ltp": 2.06, "tv": 103.03, "trd": NaN, "batb": NaN, "batl": [[0, 2.6, 0.05]]}, {"timestamp": 1631552921380, "ltp": 2.06, "tv": 103.03, "trd": NaN, "batb": [[0, 1.01, 12], [1, 1.01, 0]], "batl": NaN}, {"timestamp": 1631552926380, "ltp": 2.06, "tv": 103.03, "trd": NaN, "batb": [[0, 2.26, 23.8], [1, 1.01, 12]], "batl": NaN}, {"timestamp": 1631552932894, "ltp": 2.06, "tv": 103.03, "trd": NaN, "batb": [[0, 1.01, 12], [1, 1.01, 0]], "batl": NaN}, {"timestamp": 1631552937794, "ltp": 2.06, "tv": 103.03, "trd": NaN, "batb": [[0, 2, 30], [1, 1.01, 12]], "batl": NaN}, {"timestamp": 1631552948419, "ltp": 2.0, "tv": 103.13, "trd": [[2, 0.1]], "batb": [[0, 1.01, 12], [1, 1.01, 0]], "batl": NaN}, {"timestamp": 1631552953303, "ltp": 2.0, "tv": 103.13, "trd": NaN, "batb": [[0, 2, 30], [1, 1.01, 12]], "batl": NaN}, {"timestamp": 1631552965746, "ltp": 2.0, "tv": 103.13, "trd": NaN, "batb": [[0, 1.01, 12], [1, 1.01, 0]], "batl": NaN}, {"timestamp": 1631552970641, "ltp": 2.0, "tv": 103.13, "trd": NaN, "batb": [[0, 1.85, 35.29], [1, 1.01, 12]], "batl": NaN}, {"timestamp": 1631552981156, "ltp": 2.0, "tv": 103.13, "trd": NaN, "batb": [[0, 1.01, 12], [1, 1.01, 0]], "batl": NaN}, {"timestamp": 1631552986159, "ltp": 2.0, "tv": 103.13, "trd": NaN, "batb": [[0, 1.78, 38.46], [1, 1.01, 12]], "batl": NaN}, {"timestamp": 1631553011872, "ltp": 2.0, "tv": 103.13, "trd": NaN, "batb": [[0, 1.01, 12], [1, 1.01, 0]], "batl": NaN}, {"timestamp": 1631553016903, "ltp": 2.0, "tv": 103.13, "trd": NaN, "batb": [[0, 2, 30], [1, 1.01, 12]], "batl": NaN}, {"timestamp": 1631553053222, "ltp": 2.0, "tv": 103.13, "trd": NaN, "batb": [[0, 1.01, 12], [1, 1.01, 0]], "batl": NaN}, {"timestamp": 1631553058252, "ltp": 2.0, "tv": 103.13, "trd": NaN, "batb": [[0, 1.85, 35.29], [1, 1.01, 12]], "batl": NaN}, {"timestamp": 1631553073683, "ltp": 2.0, "tv": 103.13, "trd": NaN, "batb": [[0, 1.01, 12], [1, 1.01, 0]], "batl": NaN}, {"timestamp": 1631553078542, "ltp": 2.0, "tv": 103.13, "trd": NaN, "batb": [[0, 1.78, 38.46], [1, 1.01, 12]], "batl": NaN}, {"timestamp": 1631553086284, "ltp": 2.0, "tv": 103.13, "trd": NaN, "batb": [[0, 1.01, 12], [1, 1.01, 0]], "batl": NaN}, {"timestamp": 1631553091270, "ltp": 2.0, "tv": 103.13, "trd": NaN, "batb": [[0, 2, 30], [1, 1.01, 12]], "batl": NaN}, {"timestamp": 1631553106689, "ltp": 2.0, "tv": 103.13, "trd": NaN, "batb": [[0, 1.01, 12], [1, 1.01, 0]], "batl": NaN}, {"timestamp": 1631553111476, "ltp": 2.0, "tv": 103.13, "trd": NaN, "batb": [[0, 2.26, 23.8], [1, 1.01, 12]], "batl": NaN}, {"timestamp": 1631553125229, "ltp": 2.0, "tv": 103.13, "trd": NaN, "batb": [[0, 1.01, 12], [1, 1.01, 0]], "batl": NaN}, {"timestamp": 1631553130124, "ltp": 2.0, "tv": 103.13, "trd": NaN, "batb": [[0, 2.2, 24.99], [1, 1.01, 12]], "batl": NaN}, {"timestamp": 1631553140714, "ltp": 2.0, "tv": 103.13, "trd": NaN, "batb": [[0, 1.01, 12], [1, 1.01, 0]], "batl": NaN}, {"timestamp": 1631553145702, "ltp": 2.0, "tv": 103.13, "trd": NaN, "batb": [[0, 2.5, 20], [1, 1.01, 12]], "batl": NaN}, {"timestamp": 1631553270302, "ltp": 2.0, "tv": 103.13, "trd": NaN, "batb": [[0, 1.01, 12], [1, 1.01, 0]], "batl": NaN}, {"timestamp": 1631553275207, "ltp": 2.0, "tv": 103.13, "trd": NaN, "batb": [[0, 2.84, 16.3], [1, 1.01, 12]], "batl": NaN}, {"timestamp": 1631553317716, "ltp": 2.0, "tv": 103.13, "trd": NaN, "batb": [[0, 1.01, 12], [1, 1.01, 0]], "batl": NaN}, {"timestamp": 1631553322605, "ltp": 2.0, "tv": 103.13, "trd": NaN, "batb": [[0, 2.5, 20], [1, 1.01, 12]], "batl": NaN}, {"timestamp": 1631553349553, "ltp": 2.0, "tv": 103.13, "trd": NaN, "batb": [[0, 1.01, 12], [1, 1.01, 0]], "batl": NaN}, {"timestamp": 1631553354427, "ltp": 2.0, "tv": 103.13, "trd": NaN, "batb": [[0, 2.84, 16.3], [1, 1.01, 12]], "batl": NaN}, {"timestamp": 1631553374283, "ltp": 2.0, "tv": 103.13, "trd": NaN, "batb": [[0, 1.01, 12], [1, 1.01, 0]], "batl": NaN}, {"timestamp": 1631553379182, "ltp": 2.0, "tv": 103.13, "trd": NaN, "batb": [[0, 2.5, 20], [1, 1.01, 12]], "batl": NaN}, {"timestamp": 1631553393636, "ltp": 2.0, "tv": 103.13, "trd": NaN, "batb": [[0, 1.01, 12], [1, 1.01, 0]], "batl": NaN}, {"timestamp": 1631553398414, "ltp": 2.0, "tv": 103.13, "trd": NaN, "batb": [[0, 2.58, 18.98], [1, 1.01, 12]], "batl": NaN}, {"timestamp": 1631553407315, "ltp": 2.0, "tv": 103.13, "trd": NaN, "batb": [[0, 1.01, 12], [1, 1.01, 0]], "batl": NaN}, {"timestamp": 1631553412348, "ltp": 2.0, "tv": 103.13, "trd": NaN, "batb": [[0, 2.26, 23.8], [1, 1.01, 12]], "batl": NaN}, {"timestamp": 1631553442862, "ltp": 2.0, "tv": 103.13, "trd": NaN, "batb": [[0, 1.01, 12], [1, 1.01, 0]], "batl": NaN}, {"timestamp": 1631553447839, "ltp": 2.0, "tv": 103.13, "trd": NaN, "batb": [[0, 2.06, 28.3], [1, 1.01, 12]], "batl": NaN}, {"timestamp": 1631553472540, "ltp": 2.0, "tv": 103.13, "trd": NaN, "batb": [[0, 1.01, 12], [1, 1.01, 0]], "batl": NaN}, {"timestamp": 1631553477452, "ltp": 2.0, "tv": 103.13, "trd": NaN, "batb": [[0, 2, 30], [1, 1.01, 12]], "batl": NaN}, {"timestamp": 1631553490368, "ltp": 2.0, "tv": 103.13, "trd": NaN, "batb": [[0, 1.01, 12], [1, 1.01, 0]], "batl": NaN}, {"timestamp": 1631553495280, "ltp": 2.0, "tv": 103.13, "trd": NaN, "batb": [[0, 1.85, 35.29], [1, 1.01, 12]], "batl": NaN}, {"timestamp": 1631553517810, "ltp": 2.0, "tv": 103.13, "trd": NaN, "batb": [[0, 1.01, 12], [1, 1.01, 0]], "batl": NaN}, {"timestamp": 1631553522706, "ltp": 2.0, "tv": 103.13, "trd": NaN, "batb": [[0, 2.06, 28.3], [1, 1.01, 12]], "batl": NaN}, {"timestamp": 1631553536846, "ltp": 2.0, "tv": 103.13, "trd": NaN, "batb": [[0, 1.01, 12], [1, 1.01, 0]], "batl": NaN}, {"timestamp": 1631553541854, "ltp": 2.0, "tv": 103.13, "trd": NaN, "batb": [[0, 1.98, 30.61], [1, 1.01, 12]], "batl": NaN}, {"timestamp": 1631553548454, "ltp": 2.0, "tv": 103.13, "trd": NaN, "batb": [[0, 1.01, 12], [1, 1.01, 0]], "batl": NaN}, {"timestamp": 1631553553360, "ltp": 2.0, "tv": 103.13, "trd": NaN, "batb": [[0, 2.26, 23.8], [1, 1.01, 12]], "batl": NaN}, {"timestamp": 1631553569251, "ltp": 2.0, "tv": 103.13, "trd": NaN, "batb": [[0, 1.01, 12], [1, 1.01, 0]], "batl": NaN}, {"timestamp": 1631553574188, "ltp": 2.0, "tv": 103.13, "trd": NaN, "batb": [[0, 2.2, 24.99], [1, 1.01, 12]], "batl": NaN}, {"timestamp": 1631553594020, "ltp": 2.0, "tv": 103.13, "trd": NaN, "batb": [[0, 1.01, 12], [1, 1.01, 0]], "batl": NaN}, {"timestamp": 1631553598914, "ltp": 2.0, "tv": 103.13, "trd": NaN, "batb": [[0, 2.5, 20], [1, 1.01, 12]], "batl": NaN}, {"timestamp": 1631553627749, "ltp": 2.0, "tv": 103.13, "trd": NaN, "batb": [[0, 1.01, 12], [1, 1.01, 0]], "batl": NaN}, {"timestamp": 1631553632665, "ltp": 2.0, "tv": 103.13, "trd": NaN, "batb": [[0, 2.34, 22.38], [1, 1.01, 12]], "batl": NaN}, {"timestamp": 1631553654843, "ltp": 2.0, "tv": 103.13, "trd": NaN, "batb": [[0, 1.01, 12], [1, 1.01, 0]], "batl": NaN}, {"timestamp": 1631553659738, "ltp": 2.0, "tv": 103.13, "trd": NaN, "batb": [[0, 2.58, 18.98], [1, 1.01, 12]], "batl": NaN}, {"timestamp": 1631553777816, "ltp": 2.0, "tv": 103.13, "trd": NaN, "batb": [[0, 1.01, 12], [1, 1.01, 0]], "batl": NaN}, {"timestamp": 1631553782701, "ltp": 2.0, "tv": 103.13, "trd": NaN, "batb": [[0, 3, 15], [1, 1.01, 12]], "batl": NaN}, {"timestamp": 1631553812740, "ltp": 2.0, "tv": 103.13, "trd": NaN, "batb": [[0, 1.01, 12], [1, 1.01, 0]], "batl": NaN}, {"timestamp": 1631553817652, "ltp": 2.0, "tv": 103.13, "trd": NaN, "batb": [[0, 3.3, 13.04], [1, 1.01, 12]], "batl": NaN}, {"timestamp": 1631553849328, "ltp": 2.0, "tv": 103.13, "trd": NaN, "batb": [[0, 1.01, 12], [1, 1.01, 0]], "batl": NaN}, {"timestamp": 1631553854219, "ltp": 2.0, "tv": 103.13, "trd": NaN, "batb": [[0, 3, 15], [1, 1.01, 12]], "batl": NaN}, {"timestamp": 1631553898057, "ltp": 2.0, "tv": 103.13, "trd": NaN, "batb": [[0, 1.01, 12], [1, 1.01, 0]], "batl": NaN}, {"timestamp": 1631553902980, "ltp": 2.0, "tv": 103.13, "trd": NaN, "batb": [[0, 2.66, 18.07], [1, 1.01, 12]], "batl": NaN}, {"timestamp": 1631553955491, "ltp": 2.0, "tv": 103.13, "trd": NaN, "batb": [[0, 1.01, 12], [1, 1.01, 0]], "batl": NaN}, {"timestamp": 1631553960404, "ltp": 2.0, "tv": 103.13, "trd": NaN, "batb": [[0, 2.26, 23.8], [1, 1.01, 12]], "batl": NaN}, {"timestamp": 1631553990951, "ltp": 2.0, "tv": 103.13, "trd": NaN, "batb": [[0, 1.01, 12], [1, 1.01, 0]], "batl": NaN}, {"timestamp": 1631553995858, "ltp": 2.0, "tv": 103.13, "trd": NaN, "batb": [[0, 2.66, 18.07], [1, 1.01, 12]], "batl": NaN}, {"timestamp": 1631554016060, "ltp": 2.0, "tv": 103.13, "trd": NaN, "batb": [[0, 1.01, 12], [1, 1.01, 0]], "batl": NaN}, {"timestamp": 1631554021057, "ltp": 2.0, "tv": 103.13, "trd": NaN, "batb": [[0, 2.84, 16.3], [1, 1.01, 12]], "batl": NaN}, {"timestamp": 1631554031691, "ltp": 2.0, "tv": 103.13, "trd": NaN, "batb": [[0, 1.01, 12], [1, 1.01, 0]], "batl": NaN}, {"timestamp": 1631554036576, "ltp": 2.0, "tv": 103.13, "trd": NaN, "batb": [[0, 2.26, 23.8], [1, 1.01, 12]], "batl": NaN}, {"timestamp": 1631554097722, "ltp": 2.0, "tv": 103.13, "trd": NaN, "batb": [[0, 1.01, 12], [1, 1.01, 0]], "batl": NaN}, {"timestamp": 1631554102758, "ltp": 2.0, "tv": 103.13, "trd": NaN, "batb": [[0, 2.66, 18.07], [1, 1.01, 12]], "batl": NaN}, {"timestamp": 1631554124990, "ltp": 2.0, "tv": 103.13, "trd": NaN, "batb": [[0, 1.01, 12], [1, 1.01, 0]], "batl": NaN}, {"timestamp": 1631554129975, "ltp": 2.0, "tv": 103.13, "trd": NaN, "batb": [[0, 3.15, 13.95], [1, 1.01, 12]], "batl": NaN}, {"timestamp": 1631554148429, "ltp": 2.0, "tv": 103.13, "trd": NaN, "batb": [[0, 1.01, 12], [1, 1.01, 0]], "batl": NaN}, {"timestamp": 1631554153351, "ltp": 2.0, "tv": 103.13, "trd": NaN, "batb": [[0, 3.3, 13.04], [1, 1.01, 12]], "batl": NaN}, {"timestamp": 1631554182086, "ltp": 2.0, "tv": 103.13, "trd": NaN, "batb": [[0, 1.01, 12], [1, 1.01, 0]], "batl": NaN}, {"timestamp": 1631554186989, "ltp": 2.0, "tv": 103.13, "trd": NaN, "batb": [[0, 2.66, 18.07], [1, 1.01, 12]], "batl": NaN}, {"timestamp": 1631554240402, "ltp": 2.0, "tv": 103.13, "trd": NaN, "batb": [[0, 1.01, 12], [1, 1.01, 0]], "batl": NaN}, {"timestamp": 1631554245366, "ltp": 2.0, "tv": 103.13, "trd": NaN, "batb": [[0, 3.15, 13.95], [1, 1.01, 12]], "batl": NaN}, {"timestamp": 1631554272421, "ltp": 2.0, "tv": 103.13, "trd": NaN, "batb": [[0, 1.01, 12], [1, 1.01, 0]], "batl": NaN}, {"timestamp": 1631554277017, "ltp": 2.0, "tv": 103.13, "trd": NaN, "batb": [[0, 4.1, 10], [1, 1.01, 12]], "batl": NaN}, {"timestamp": 1631554284730, "ltp": 4.1, "tv": 113.13, "trd": [[4.1, 10]], "batb": [[0, 1.01, 12], [1, 1.01, 0]], "batl": NaN}, {"timestamp": 1631554290550, "ltp": 4.1, "tv": 113.13, "trd": NaN, "batb": [[0, 4.1, 2], [1, 3.7, 11.11], [2, 1.01, 12]], "batl": NaN}, {"timestamp": 1631554290722, "ltp": 4.1, "tv": 113.13, "trd": NaN, "batb": [[0, 3.7, 11.11], [1, 1.01, 12], [2, 1.01, 0]], "batl": NaN}, {"timestamp": 1631554405441, "ltp": 4.1, "tv": 113.13, "trd": NaN, "batb": [[0, 1.01, 12], [1, 1.01, 0]], "batl": NaN}, {"timestamp": 1631554410333, "ltp": 4.1, "tv": 113.13, "trd": NaN, "batb": [[0, 4.8, 10], [1, 1.01, 12]], "batl": NaN}, {"timestamp": 1631554456322, "ltp": 4.1, "tv": 113.13, "trd": NaN, "batb": [[0, 1.01, 12], [1, 1.01, 0]], "batl": NaN}, {"timestamp": 1631554461370, "ltp": 4.1, "tv": 113.13, "trd": NaN, "batb": [[0, 5.3, 10], [1, 1.01, 12]], "batl": NaN}, {"timestamp": 1631554484486, "ltp": 4.1, "tv": 113.13, "trd": NaN, "batb": [[0, 1.01, 12], [1, 1.01, 0]], "batl": NaN}, {"timestamp": 1631554489384, "ltp": 4.1, "tv": 113.13, "trd": NaN, "batb": [[0, 5.8, 10], [1, 1.01, 12]], "batl": NaN}, {"timestamp": 1631554513500, "ltp": 4.1, "tv": 113.13, "trd": NaN, "batb": [[0, 1.01, 12], [1, 1.01, 0]], "batl": NaN}, {"timestamp": 1631554518517, "ltp": 4.1, "tv": 113.13, "trd": NaN, "batb": [[0, 6, 10], [1, 1.01, 12]], "batl": NaN}, {"timestamp": 1631554573611, "ltp": 4.1, "tv": 113.13, "trd": NaN, "batb": [[0, 1.01, 12], [1, 1.01, 0]], "batl": NaN}, {"timestamp": 1631554578613, "ltp": 4.1, "tv": 113.13, "trd": NaN, "batb": [[0, 5.8, 10], [1, 1.01, 12]], "batl": NaN}, {"timestamp": 1631554610909, "ltp": 4.1, "tv": 113.13, "trd": NaN, "batb": [[0, 1.01, 12], [1, 1.01, 0]], "batl": NaN}, {"timestamp": 1631554615849, "ltp": 4.1, "tv": 113.13, "trd": NaN, "batb": [[0, 4.8, 10], [1, 1.01, 12]], "batl": NaN}, {"timestamp": 1631554642376, "ltp": 4.1, "tv": 113.13, "trd": NaN, "batb": [[0, 1.01, 12], [1, 1.01, 0]], "batl": NaN}, {"timestamp": 1631554647275, "ltp": 4.1, "tv": 113.13, "trd": NaN, "batb": [[0, 4.3, 10], [1, 1.01, 12]], "batl": NaN}, {"timestamp": 1631554665973, "ltp": 4.1, "tv": 113.13, "trd": NaN, "batb": [[0, 1.01, 12], [1, 1.01, 0]], "batl": NaN}, {"timestamp": 1631554670898, "ltp": 4.1, "tv": 113.13, "trd": NaN, "batb": [[0, 4.8, 10], [1, 1.01, 12]], "batl": NaN}, {"timestamp": 1631554695531, "ltp": 4.1, "tv": 113.13, "trd": NaN, "batb": [[0, 1.01, 12], [1, 1.01, 0]], "batl": NaN}, {"timestamp": 1631554700453, "ltp": 4.1, "tv": 113.13, "trd": NaN, "batb": [[0, 5.8, 10], [1, 1.01, 12]], "batl": NaN}, {"timestamp": 1631554729901, "ltp": 4.1, "tv": 113.13, "trd": NaN, "batb": [[0, 1.01, 12], [1, 1.01, 0]], "batl": NaN}, {"timestamp": 1631554734892, "ltp": 4.1, "tv": 113.13, "trd": NaN, "batb": [[0, 4.8, 10], [1, 1.01, 12]], "batl": NaN}, {"timestamp": 1631554765398, "ltp": 4.1, "tv": 113.13, "trd": NaN, "batb": [[0, 1.01, 12], [1, 1.01, 0]], "batl": NaN}, {"timestamp": 1631554770347, "ltp": 4.1, "tv": 113.13, "trd": NaN, "batb": [[0, 5.3, 10], [1, 1.01, 12]], "batl": NaN}, {"timestamp": 1631554786116, "ltp": 4.1, "tv": 113.13, "trd": NaN, "batb": [[0, 1.01, 12], [1, 1.01, 0]], "batl": NaN}, {"timestamp": 1631554791040, "ltp": 4.1, "tv": 113.13, "trd": NaN, "batb": [[0, 5.8, 10], [1, 1.01, 12]], "batl": NaN}, {"timestamp": 1631554818596, "ltp": 4.1, "tv": 113.13, "trd": NaN, "batb": [[0, 1.01, 12], [1, 1.01, 0]], "batl": NaN}, {"timestamp": 1631554823569, "ltp": 4.1, "tv": 113.13, "trd": NaN, "batb": [[0, 6, 10], [1, 1.01, 12]], "batl": NaN}, {"timestamp": 1631554838896, "ltp": 4.1, "tv": 113.13, "trd": NaN, "batb": [[0, 1.01, 12], [1, 1.01, 0]], "batl": NaN}, {"timestamp": 1631554843785, "ltp": 4.1, "tv": 113.13, "trd": NaN, "batb": [[0, 5.8, 10], [1, 1.01, 12]], "batl": NaN}, {"timestamp": 1631554880647, "ltp": 4.1, "tv": 113.13, "trd": NaN, "batb": [[0, 1.01, 12], [1, 1.01, 0]], "batl": NaN}, {"timestamp": 1631554885546, "ltp": 4.1, "tv": 113.13, "trd": NaN, "batb": [[0, 5.3, 10], [1, 1.01, 12]], "batl": NaN}, {"timestamp": 1631554914719, "ltp": 4.1, "tv": 113.13, "trd": NaN, "batb": [[0, 1.01, 12], [1, 1.01, 0]], "batl": NaN}, {"timestamp": 1631554919622, "ltp": 4.1, "tv": 113.13, "trd": NaN, "batb": [[0, 4.3, 10], [1, 1.01, 12]], "batl": NaN}, {"timestamp": 1631554936463, "ltp": 4.1, "tv": 113.13, "trd": NaN, "batb": [[0, 1.01, 12], [1, 1.01, 0]], "batl": NaN}, {"timestamp": 1631554941381, "ltp": 4.1, "tv": 113.13, "trd": NaN, "batb": [[0, 4.1, 10], [1, 1.01, 12]], "batl": NaN}, {"timestamp": 1631554951796, "ltp": 4.1, "tv": 113.13, "trd": NaN, "batb": [[0, 1.01, 12], [1, 1.01, 0]], "batl": NaN}, {"timestamp": 1631554956702, "ltp": 4.1, "tv": 113.13, "trd": NaN, "batb": [[0, 3.7, 11.11], [1, 1.01, 12]], "batl": NaN}, {"timestamp": 1631555011901, "ltp": 4.1, "tv": 113.13, "trd": NaN, "batb": [[0, 1.01, 12], [1, 1.01, 0]], "batl": NaN}, {"timestamp": 1631555016923, "ltp": 4.1, "tv": 113.13, "trd": NaN, "batb": [[0, 3, 15], [1, 1.01, 12]], "batl": NaN}, {"timestamp": 1631555123821, "ltp": 4.1, "tv": 113.13, "trd": NaN, "batb": [[0, 1.01, 12], [1, 1.01, 0]], "batl": NaN}, {"timestamp": 1631555128826, "ltp": 4.1, "tv": 113.13, "trd": NaN, "batb": [[0, 3.4, 12.5], [1, 1.01, 12]], "batl": NaN}, {"timestamp": 1631555143588, "ltp": 4.1, "tv": 113.13, "trd": NaN, "batb": [[0, 1.01, 12], [1, 1.01, 0]], "batl": NaN}, {"timestamp": 1631555148608, "ltp": 4.1, "tv": 113.13, "trd": NaN, "batb": [[0, 3, 15], [1, 1.01, 12]], "batl": NaN}, {"timestamp": 1631555164819, "ltp": 4.1, "tv": 113.13, "trd": NaN, "batb": [[0, 1.01, 12], [1, 1.01, 0]], "batl": NaN}, {"timestamp": 1631555169711, "ltp": 4.1, "tv": 113.13, "trd": NaN, "batb": [[0, 3.15, 13.95], [1, 1.01, 12]], "batl": NaN}, {"timestamp": 1631555183720, "ltp": 4.1, "tv": 113.13, "trd": NaN, "batb": [[0, 1.01, 12], [1, 1.01, 0]], "batl": NaN}, {"timestamp": 1631555188739, "ltp": 4.1, "tv": 113.13, "trd": NaN, "batb": [[0, 2.84, 16.3], [1, 1.01, 12]], "batl": NaN}, {"timestamp": 1631555214564, "ltp": 4.1, "tv": 113.13, "trd": NaN, "batb": [[0, 1.01, 12], [1, 1.01, 0]], "batl": NaN}, {"timestamp": 1631555219489, "ltp": 4.1, "tv": 113.13, "trd": NaN, "batb": [[0, 2.58, 18.98], [1, 1.01, 12]], "batl": NaN}, {"timestamp": 1631555244625, "ltp": 4.1, "tv": 113.13, "trd": NaN, "batb": [[0, 1.01, 12], [1, 1.01, 0]], "batl": NaN}, {"timestamp": 1631555249444, "ltp": 4.1, "tv": 113.13, "trd": NaN, "batb": [[0, 2.84, 16.3], [1, 1.01, 12]], "batl": NaN}, {"timestamp": 1631555283294, "ltp": 4.1, "tv": 113.13, "trd": NaN, "batb": [[0, 1.01, 12], [1, 1.01, 0]], "batl": NaN}, {"timestamp": 1631555288078, "ltp": 4.1, "tv": 113.13, "trd": NaN, "batb": [[0, 3.15, 13.95], [1, 1.01, 12]], "batl": NaN}, {"timestamp": 1631555327508, "ltp": 4.1, "tv": 113.13, "trd": NaN, "batb": [[0, 1.01, 12], [1, 1.01, 0]], "batl": NaN}, {"timestamp": 1631555332533, "ltp": 4.1, "tv": 113.13, "trd": NaN, "batb": [[0, 2.84, 16.3], [1, 1.01, 12]], "batl": NaN}, {"timestamp": 1631555386258, "ltp": 4.1, "tv": 113.13, "trd": NaN, "batb": [[0, 1.01, 12], [1, 1.01, 0]], "batl": NaN}, {"timestamp": 1631555391226, "ltp": 4.1, "tv": 113.13, "trd": NaN, "batb": [[0, 3.15, 13.95], [1, 1.01, 12]], "batl": NaN}, {"timestamp": 1631555430698, "ltp": 4.1, "tv": 113.13, "trd": NaN, "batb": [[0, 1.01, 12], [1, 1.01, 0]], "batl": NaN}, {"timestamp": 1631555435567, "ltp": 4.1, "tv": 113.13, "trd": NaN, "batb": [[0, 2.84, 16.3], [1, 1.01, 12]], "batl": NaN}, {"timestamp": 1631555467923, "ltp": 4.1, "tv": 113.13, "trd": NaN, "batb": [[0, 1.01, 12], [1, 1.01, 0]], "batl": NaN}, {"timestamp": 1631555472843, "ltp": 4.1, "tv": 113.13, "trd": NaN, "batb": [[0, 2.58, 18.98], [1, 1.01, 12]], "batl": NaN}, {"timestamp": 1631555504766, "ltp": 4.1, "tv": 113.13, "trd": NaN, "batb": NaN, "batl": [[0, 100, 0.19]]}, {"timestamp": 1631555505756, "ltp": 4.1, "tv": 113.13, "trd": NaN, "batb": [[0, 1.01, 12], [1, 1.01, 0]], "batl": NaN}, {"timestamp": 1631555510658, "ltp": 4.1, "tv": 113.13, "trd": NaN, "batb": [[0, 2.42, 21.12], [1, 1.01, 12]], "batl": NaN}, {"timestamp": 1631555538119, "ltp": 4.1, "tv": 113.13, "trd": NaN, "batb": [[0, 1.01, 12], [1, 1.01, 0]], "batl": NaN}, {"timestamp": 1631555543124, "ltp": 4.1, "tv": 113.13, "trd": NaN, "batb": [[0, 2.58, 18.98], [1, 1.01, 12]], "batl": NaN}, {"timestamp": 1631555548553, "ltp": 2.58, "tv": 115.91, "trd": [[2.58, 2.78]], "batb": [[0, 1.01, 12], [1, 1.01, 0]], "batl": NaN}, {"timestamp": 1631555553460, "ltp": 2.58, "tv": 115.91, "trd": NaN, "batb": [[0, 2.58, 18.98], [1, 1.01, 12]], "batl": NaN}, {"timestamp": 1631555563069, "ltp": 2.58, "tv": 115.91, "trd": NaN, "batb": [[0, 1.01, 12], [1, 1.01, 0]], "batl": NaN}, {"timestamp": 1631555567985, "ltp": 2.58, "tv": 115.91, "trd": NaN, "batb": [[0, 2.84, 16.3], [1, 1.01, 12]], "batl": NaN}, {"timestamp": 1631555603755, "ltp": 2.58, "tv": 115.91, "trd": NaN, "batb": [[0, 1.01, 12], [1, 1.01, 0]], "batl": NaN}, {"timestamp": 1631555608629, "ltp": 2.58, "tv": 115.91, "trd": NaN, "batb": [[0, 2.66, 18.07], [1, 1.01, 12]], "batl": NaN}, {"timestamp": 1631555616787, "ltp": 2.58, "tv": 115.91, "trd": NaN, "batb": [[0, 1.01, 12], [1, 1.01, 0]], "batl": NaN}, {"timestamp": 1631555621656, "ltp": 2.58, "tv": 115.91, "trd": NaN, "batb": [[0, 2.84, 16.3], [1, 1.01, 12]], "batl": NaN}, {"timestamp": 1631555656869, "ltp": 2.58, "tv": 115.91, "trd": NaN, "batb": [[0, 1.01, 12], [1, 1.01, 0]], "batl": NaN}, {"timestamp": 1631555661785, "ltp": 2.58, "tv": 115.91, "trd": NaN, "batb": [[0, 3, 15], [1, 1.01, 12]], "batl": NaN}, {"timestamp": 1631555798884, "ltp": 2.58, "tv": 115.91, "trd": NaN, "batb": [[0, 1.01, 12], [1, 1.01, 0]], "batl": NaN}, {"timestamp": 1631555803890, "ltp": 2.58, "tv": 115.91, "trd": NaN, "batb": [[0, 2.84, 16.3], [1, 1.01, 12]], "batl": NaN}, {"timestamp": 1631555829329, "ltp": 2.58, "tv": 115.91, "trd": NaN, "batb": [[0, 1.01, 12], [1, 1.01, 0]], "batl": NaN}, {"timestamp": 1631555834235, "ltp": 2.58, "tv": 115.91, "trd": NaN, "batb": [[0, 3, 15], [1, 1.01, 12]], "batl": NaN}, {"timestamp": 1631555870148, "ltp": 2.58, "tv": 115.91, "trd": NaN, "batb": [[0, 1.01, 12], [1, 1.01, 0]], "batl": NaN}, {"timestamp": 1631555875074, "ltp": 2.58, "tv": 115.91, "trd": NaN, "batb": [[0, 3.4, 12.5], [1, 1.01, 12]], "batl": NaN}, {"timestamp": 1631555949893, "ltp": 2.58, "tv": 115.91, "trd": NaN, "batb": [[0, 1.01, 12], [1, 1.01, 0]], "batl": NaN}, {"timestamp": 1631555954797, "ltp": 2.58, "tv": 115.91, "trd": NaN, "batb": [[0, 3, 15], [1, 1.01, 12]], "batl": NaN}, {"timestamp": 1631556008368, "ltp": 2.58, "tv": 115.91, "trd": NaN, "batb": [[0, 1.01, 12], [1, 1.01, 0]], "batl": NaN}, {"timestamp": 1631556013305, "ltp": 2.58, "tv": 115.91, "trd": NaN, "batb": [[0, 3.7, 11.11], [1, 1.01, 12]], "batl": NaN}, {"timestamp": 1631556035506, "ltp": 2.58, "tv": 115.91, "trd": NaN, "batb": [[0, 1.01, 12], [1, 1.01, 0]], "batl": NaN}, {"timestamp": 1631556040404, "ltp": 2.58, "tv": 115.91, "trd": NaN, "batb": [[0, 3, 15], [1, 1.01, 12]], "batl": NaN}, {"timestamp": 1631556062451, "ltp": 2.58, "tv": 115.91, "trd": NaN, "batb": [[0, 1.01, 12], [1, 1.01, 0]], "batl": NaN}, {"timestamp": 1631556067433, "ltp": 2.58, "tv": 115.91, "trd": NaN, "batb": [[0, 3.7, 11.11], [1, 1.01, 12]], "batl": NaN}, {"timestamp": 1631556085021, "ltp": 2.58, "tv": 115.91, "trd": NaN, "batb": [[0, 1.01, 12], [1, 1.01, 0]], "batl": NaN}, {"timestamp": 1631556089976, "ltp": 2.58, "tv": 115.91, "trd": NaN, "batb": [[0, 3, 15], [1, 1.01, 12]], "batl": NaN}, {"timestamp": 1631556110306, "ltp": 2.58, "tv": 115.91, "trd": NaN, "batb": [[0, 1.01, 12], [1, 1.01, 0]], "batl": NaN}, {"timestamp": 1631556115206, "ltp": 2.58, "tv": 115.91, "trd": NaN, "batb": [[0, 2.84, 16.3], [1, 1.01, 12]], "batl": NaN}, {"timestamp": 1631556132755, "ltp": 2.58, "tv": 115.91, "trd": NaN, "batb": [[0, 1.01, 12], [1, 1.01, 0]], "batl": NaN}, {"timestamp": 1631556137782, "ltp": 2.58, "tv": 115.91, "trd": NaN, "batb": [[0, 2.5, 20], [1, 1.01, 12]], "batl": NaN}, {"timestamp": 1631556170739, "ltp": 2.58, "tv": 115.91, "trd": NaN, "batb": [[0, 1.01, 12], [1, 1.01, 0]], "batl": NaN}, {"timestamp": 1631556175518, "ltp": 2.58, "tv": 115.91, "trd": NaN, "batb": [[0, 2.34, 22.38], [1, 1.01, 12]], "batl": NaN}, {"timestamp": 1631556199458, "ltp": 2.58, "tv": 115.91, "trd": NaN, "batb": [[0, 1.01, 12], [1, 1.01, 0]], "batl": NaN}, {"timestamp": 1631556204371, "ltp": 2.58, "tv": 115.91, "trd": NaN, "batb": [[0, 2.5, 20], [1, 1.01, 12]], "batl": NaN}, {"timestamp": 1631556221247, "ltp": 2.58, "tv": 115.91, "trd": NaN, "batb": [[0, 1.01, 12], [1, 1.01, 0]], "batl": NaN}, {"timestamp": 1631556226128, "ltp": 2.58, "tv": 115.91, "trd": NaN, "batb": [[0, 2.58, 18.98], [1, 1.01, 12]], "batl": NaN}, {"timestamp": 1631556239832, "ltp": 2.58, "tv": 115.91, "trd": NaN, "batb": [[0, 1.01, 12], [1, 1.01, 0]], "batl": NaN}, {"timestamp": 1631556244752, "ltp": 2.58, "tv": 115.91, "trd": NaN, "batb": [[0, 2.84, 16.3], [1, 1.01, 12]], "batl": NaN}, {"timestamp": 1631556309042, "ltp": 2.58, "tv": 115.91, "trd": NaN, "batb": NaN, "batl": [[0, 3.3, 27.04], [1, 100, 0.19]]}, {"timestamp": 1631556326773, "ltp": 2.58, "tv": 115.91, "trd": NaN, "batb": NaN, "batl": [[0, 100, 0.19], [1, 100, 0]]}, {"timestamp": 1631556488508, "ltp": 2.58, "tv": 115.91, "trd": NaN, "batb": [[0, 1.01, 12], [1, 1.01, 0]], "batl": NaN}, {"timestamp": 1631556493438, "ltp": 2.58, "tv": 115.91, "trd": NaN, "batb": [[0, 2.58, 18.98], [1, 1.01, 12]], "batl": NaN}, {"timestamp": 1631556523452, "ltp": 2.58, "tv": 115.91, "trd": NaN, "batb": [[0, 1.01, 12], [1, 1.01, 0]], "batl": NaN}, {"timestamp": 1631556528374, "ltp": 2.58, "tv": 115.91, "trd": NaN, "batb": [[0, 2.42, 21.12], [1, 1.01, 12]], "batl": NaN}, {"timestamp": 1631556545887, "ltp": 2.58, "tv": 115.91, "trd": NaN, "batb": [[0, 1.01, 12], [1, 1.01, 0]], "batl": NaN}, {"timestamp": 1631556550858, "ltp": 2.58, "tv": 115.91, "trd": NaN, "batb": [[0, 2.5, 20], [1, 1.01, 12]], "batl": NaN}, {"timestamp": 1631556564506, "ltp": 2.58, "tv": 115.91, "trd": NaN, "batb": [[0, 1.01, 12], [1, 1.01, 0]], "batl": NaN}, {"timestamp": 1631556569391, "ltp": 2.58, "tv": 115.91, "trd": NaN, "batb": [[0, 2.58, 18.98], [1, 1.01, 12]], "batl": NaN}, {"timestamp": 1631556599224, "ltp": 2.58, "tv": 115.91, "trd": NaN, "batb": [[0, 1.01, 12], [1, 1.01, 0]], "batl": NaN}, {"timestamp": 1631556604169, "ltp": 2.58, "tv": 115.91, "trd": NaN, "batb": [[0, 3, 15], [1, 1.01, 12]], "batl": NaN}, {"timestamp": 1631556632691, "ltp": 2.58, "tv": 115.91, "trd": NaN, "batb": [[0, 1.01, 12], [1, 1.01, 0]], "batl": NaN}, {"timestamp": 1631556637709, "ltp": 2.58, "tv": 115.91, "trd": NaN, "batb": [[0, 3.4, 12.5], [1, 1.01, 12]], "batl": NaN}, {"timestamp": 1631556660757, "ltp": 2.58, "tv": 115.91, "trd": NaN, "batb": [[0, 1.01, 12], [1, 1.01, 0]], "batl": NaN}, {"timestamp": 1631556665683, "ltp": 2.58, "tv": 115.91, "trd": NaN, "batb": [[0, 4.3, 10], [1, 1.01, 12]], "batl": NaN}, {"timestamp": 1631556692815, "ltp": 2.58, "tv": 115.91, "trd": NaN, "batb": [[0, 1.01, 12], [1, 1.01, 0]], "batl": NaN}, {"timestamp": 1631556697703, "ltp": 2.58, "tv": 115.91, "trd": NaN, "batb": [[0, 5.3, 10], [1, 1.01, 12]], "batl": NaN}, {"timestamp": 1631556721048, "ltp": 2.58, "tv": 115.91, "trd": NaN, "batb": [[0, 1.01, 12], [1, 1.01, 0]], "batl": NaN}, {"timestamp": 1631556725916, "ltp": 2.58, "tv": 115.91, "trd": NaN, "batb": [[0, 6, 10], [1, 1.01, 12]], "batl": NaN}, {"timestamp": 1631556745457, "ltp": 2.58, "tv": 115.91, "trd": NaN, "batb": [[0, 1.01, 12], [1, 1.01, 0]], "batl": NaN}, {"timestamp": 1631556750390, "ltp": 2.58, "tv": 115.91, "trd": NaN, "batb": [[0, 5.3, 10], [1, 1.01, 12]], "batl": NaN}, {"timestamp": 1631556781291, "ltp": 2.58, "tv": 115.91, "trd": NaN, "batb": [[0, 1.01, 12], [1, 1.01, 0]], "batl": NaN}, {"timestamp": 1631556786229, "ltp": 2.58, "tv": 115.91, "trd": NaN, "batb": [[0, 6, 10], [1, 1.01, 12]], "batl": NaN}, {"timestamp": 1631556803397, "ltp": 2.58, "tv": 115.91, "trd": NaN, "batb": [[0, 1.01, 12], [1, 1.01, 0]], "batl": NaN}, {"timestamp": 1631556808367, "ltp": 2.58, "tv": 115.91, "trd": NaN, "batb": [[0, 7.6, 10], [1, 1.01, 12]], "batl": NaN}, {"timestamp": 1631556920772, "ltp": 2.58, "tv": 115.91, "trd": NaN, "batb": [[0, 1.01, 12], [1, 1.01, 0]], "batl": NaN}, {"timestamp": 1631556925706, "ltp": 2.58, "tv": 115.91, "trd": NaN, "batb": [[0, 6, 10], [1, 1.01, 12]], "batl": NaN}, {"timestamp": 1631556942839, "ltp": 2.58, "tv": 115.91, "trd": NaN, "batb": [[0, 1.01, 12], [1, 1.01, 0]], "batl": NaN}, {"timestamp": 1631556947823, "ltp": 2.58, "tv": 115.91, "trd": NaN, "batb": [[0, 4.8, 10], [1, 1.01, 12]], "batl": NaN}, {"timestamp": 1631556977439, "ltp": 2.58, "tv": 115.91, "trd": NaN, "batb": [[0, 1.01, 12], [1, 1.01, 0]], "batl": NaN}, {"timestamp": 1631556982333, "ltp": 2.58, "tv": 115.91, "trd": NaN, "batb": [[0, 6, 10], [1, 1.01, 12]], "batl": NaN}, {"timestamp": 1631557001277, "ltp": 2.58, "tv": 115.91, "trd": NaN, "batb": [[0, 1.01, 12], [1, 1.01, 0]], "batl": NaN}, {"timestamp": 1631557006305, "ltp": 2.58, "tv": 115.91, "trd": NaN, "batb": [[0, 4.8, 10], [1, 1.01, 12]], "batl": NaN}, {"timestamp": 1631557032517, "ltp": 2.58, "tv": 115.91, "trd": NaN, "batb": [[0, 1.01, 12], [1, 1.01, 0]], "batl": NaN}, {"timestamp": 1631557037436, "ltp": 2.58, "tv": 115.91, "trd": NaN, "batb": [[0, 4.1, 10], [1, 1.01, 12]], "batl": NaN}, {"timestamp": 1631557078475, "ltp": 2.58, "tv": 115.91, "trd": NaN, "batb": [[0, 1.01, 12], [1, 1.01, 0]], "batl": NaN}, {"timestamp": 1631557083476, "ltp": 2.58, "tv": 115.91, "trd": NaN, "batb": [[0, 5.3, 10], [1, 1.01, 12]], "batl": NaN}, {"timestamp": 1631557126207, "ltp": 2.58, "tv": 115.91, "trd": NaN, "batb": [[0, 1.01, 12], [1, 1.01, 0]], "batl": NaN}, {"timestamp": 1631557132228, "ltp": 2.58, "tv": 115.91, "trd": NaN, "batb": [[0, 4.1, 10], [1, 1.01, 12]], "batl": NaN}, {"timestamp": 1631557149934, "ltp": 2.58, "tv": 115.91, "trd": NaN, "batb": [[0, 1.01, 12], [1, 1.01, 0]], "batl": NaN}, {"timestamp": 1631557154826, "ltp": 2.58, "tv": 115.91, "trd": NaN, "batb": [[0, 5.3, 10], [1, 1.01, 12]], "batl": NaN}, {"timestamp": 1631557189197, "ltp": 2.58, "tv": 115.91, "trd": NaN, "batb": [[0, 1.01, 12], [1, 1.01, 0]], "batl": NaN}, {"timestamp": 1631557194101, "ltp": 2.58, "tv": 115.91, "trd": NaN, "batb": [[0, 6, 10], [1, 1.01, 12]], "batl": NaN}, {"timestamp": 1631557332176, "ltp": 2.58, "tv": 115.91, "trd": NaN, "batb": [[0, 1.01, 12], [1, 1.01, 0]], "batl": NaN}, {"timestamp": 1631557337012, "ltp": 2.58, "tv": 115.91, "trd": NaN, "batb": [[0, 5.8, 10], [1, 1.01, 12]], "batl": NaN}, {"timestamp": 1631557354336, "ltp": 2.58, "tv": 115.91, "trd": NaN, "batb": [[0, 1.01, 12], [1, 1.01, 0]], "batl": NaN}, {"timestamp": 1631557359281, "ltp": 2.58, "tv": 115.91, "trd": NaN, "batb": [[0, 4.8, 10], [1, 1.01, 12]], "batl": NaN}, {"timestamp": 1631557376869, "ltp": 2.58, "tv": 115.91, "trd": NaN, "batb": [[0, 1.01, 12], [1, 1.01, 0]], "batl": NaN}, {"timestamp": 1631557381792, "ltp": 2.58, "tv": 115.91, "trd": NaN, "batb": [[0, 4.3, 10], [1, 1.01, 12]], "batl": NaN}, {"timestamp": 1631557400427, "ltp": 2.58, "tv": 115.91, "trd": NaN, "batb": [[0, 1.01, 12], [1, 1.01, 0]], "batl": NaN}, {"timestamp": 1631557405395, "ltp": 2.58, "tv": 115.91, "trd": NaN, "batb": [[0, 4.8, 10], [1, 1.01, 12]], "batl": NaN}, {"timestamp": 1631557429664, "ltp": 2.58, "tv": 115.91, "trd": NaN, "batb": [[0, 1.01, 12], [1, 1.01, 0]], "batl": NaN}, {"timestamp": 1631557434663, "ltp": 2.58, "tv": 115.91, "trd": NaN, "batb": [[0, 5.3, 10], [1, 1.01, 12]], "batl": NaN}, {"timestamp": 1631557459169, "ltp": 2.58, "tv": 115.91, "trd": NaN, "batb": [[0, 1.01, 12], [1, 1.01, 0]], "batl": NaN}, {"timestamp": 1631557464001, "ltp": 2.58, "tv": 115.91, "trd": NaN, "batb": [[0, 5.8, 10], [1, 1.01, 12]], "batl": NaN}, {"timestamp": 1631557478794, "ltp": 2.58, "tv": 115.91, "trd": NaN, "batb": [[0, 1.01, 12], [1, 1.01, 0]], "batl": NaN}, {"timestamp": 1631557483809, "ltp": 2.58, "tv": 115.91, "trd": NaN, "batb": [[0, 7, 10], [1, 1.01, 12]], "batl": NaN}, {"timestamp": 1631557507760, "ltp": 2.58, "tv": 115.91, "trd": NaN, "batb": [[0, 1.01, 12], [1, 1.01, 0]], "batl": NaN}, {"timestamp": 1631557512777, "ltp": 2.58, "tv": 115.91, "trd": NaN, "batb": [[0, 5.3, 10], [1, 1.01, 12]], "batl": NaN}, {"timestamp": 1631557542665, "ltp": 2.58, "tv": 115.91, "trd": NaN, "batb": [[0, 1.01, 12], [1, 1.01, 0]], "batl": NaN}, {"timestamp": 1631557547717, "ltp": 2.58, "tv": 115.91, "trd": NaN, "batb": [[0, 4.1, 10], [1, 1.01, 12]], "batl": NaN}, {"timestamp": 1631557591989, "ltp": 2.58, "tv": 115.91, "trd": NaN, "batb": [[0, 1.01, 12], [1, 1.01, 0]], "batl": NaN}, {"timestamp": 1631557596898, "ltp": 2.58, "tv": 115.91, "trd": NaN, "batb": [[0, 5.3, 10], [1, 1.01, 12]], "batl": NaN}, {"timestamp": 1631557624508, "ltp": 2.58, "tv": 115.91, "trd": NaN, "batb": [[0, 1.01, 12], [1, 1.01, 0]], "batl": NaN}, {"timestamp": 1631557629391, "ltp": 2.58, "tv": 115.91, "trd": NaN, "batb": [[0, 4.1, 10], [1, 1.01, 12]], "batl": NaN}, {"timestamp": 1631557648576, "ltp": 2.58, "tv": 115.91, "trd": NaN, "batb": [[0, 1.01, 12], [1, 1.01, 0]], "batl": NaN}, {"timestamp": 1631557653478, "ltp": 2.58, "tv": 115.91, "trd": NaN, "batb": [[0, 4.3, 10], [1, 1.01, 12]], "batl": NaN}, {"timestamp": 1631557670805, "ltp": 2.58, "tv": 115.91, "trd": NaN, "batb": [[0, 1.01, 12], [1, 1.01, 0]], "batl": NaN}, {"timestamp": 1631557675721, "ltp": 2.58, "tv": 115.91, "trd": NaN, "batb": [[0, 3.4, 12.5], [1, 1.01, 12]], "batl": NaN}, {"timestamp": 1631557710745, "ltp": 2.58, "tv": 115.91, "trd": NaN, "batb": [[0, 1.01, 12], [1, 1.01, 0]], "batl": NaN}, {"timestamp": 1631557715669, "ltp": 2.58, "tv": 115.91, "trd": NaN, "batb": [[0, 2.66, 18.07], [1, 1.01, 12]], "batl": NaN}, {"timestamp": 1631557742195, "ltp": 2.58, "tv": 115.91, "trd": NaN, "batb": [[0, 1.01, 12], [1, 1.01, 0]], "batl": NaN}, {"timestamp": 1631557747102, "ltp": 2.58, "tv": 115.91, "trd": NaN, "batb": [[0, 2.34, 22.38], [1, 1.01, 12]], "batl": NaN}, {"timestamp": 1631557776959, "ltp": 2.58, "tv": 115.91, "trd": NaN, "batb": [[0, 1.01, 12], [1, 1.01, 0]], "batl": NaN}, {"timestamp": 1631557781848, "ltp": 2.58, "tv": 115.91, "trd": NaN, "batb": [[0, 2.06, 28.3], [1, 1.01, 12]], "batl": NaN}, {"timestamp": 1631557855042, "ltp": 2.58, "tv": 115.91, "trd": NaN, "batb": [[0, 1.01, 12], [1, 1.01, 0]], "batl": NaN}, {"timestamp": 1631557859961, "ltp": 2.58, "tv": 115.91, "trd": NaN, "batb": [[0, 2.1, 27.27], [1, 1.01, 12]], "batl": NaN}, {"timestamp": 1631557873459, "ltp": 2.58, "tv": 115.91, "trd": NaN, "batb": [[0, 1.01, 12], [1, 1.01, 0]], "batl": NaN}, {"timestamp": 1631557878300, "ltp": 2.58, "tv": 115.91, "trd": NaN, "batb": [[0, 1.98, 30.61], [1, 1.01, 12]], "batl": NaN}, {"timestamp": 1631557898300, "ltp": 2.58, "tv": 115.91, "trd": NaN, "batb": [[0, 1.01, 12], [1, 1.01, 0]], "batl": NaN}, {"timestamp": 1631557903202, "ltp": 2.58, "tv": 115.91, "trd": NaN, "batb": [[0, 2, 30], [1, 1.01, 12]], "batl": NaN}, {"timestamp": 1631557923051, "ltp": 2.58, "tv": 115.91, "trd": NaN, "batb": [[0, 1.01, 12], [1, 1.01, 0]], "batl": NaN}, {"timestamp": 1631557927936, "ltp": 2.58, "tv": 115.91, "trd": NaN, "batb": [[0, 2.1, 27.27], [1, 1.01, 12]], "batl": NaN}, {"timestamp": 1631557954388, "ltp": 2.58, "tv": 115.91, "trd": NaN, "batb": [[0, 1.01, 12], [1, 1.01, 0]], "batl": NaN}, {"timestamp": 1631557959302, "ltp": 2.58, "tv": 115.91, "trd": NaN, "batb": [[0, 1.98, 30.61], [1, 1.01, 12]], "batl": NaN}, {"timestamp": 1631558105684, "ltp": 2.58, "tv": 115.91, "trd": NaN, "batb": [[0, 1.01, 12], [1, 1.01, 0]], "batl": NaN}, {"timestamp": 1631558110575, "ltp": 2.58, "tv": 115.91, "trd": NaN, "batb": [[0, 1.85, 35.29], [1, 1.01, 12]], "batl": NaN}, {"timestamp": 1631558110891, "ltp": 2.58, "tv": 115.91, "trd": NaN, "batb": [[0, 1.01, 12], [1, 1.01, 0]], "batl": NaN}, {"timestamp": 1631558120980, "ltp": 2.58, "tv": 115.91, "trd": NaN, "batb": [[0, 2.2, 24.99], [1, 1.01, 12]], "batl": NaN}, {"timestamp": 1631558267091, "ltp": 2.58, "tv": 115.91, "trd": NaN, "batb": [[0, 1.01, 12], [1, 1.01, 0]], "batl": NaN}, {"timestamp": 1631558272084, "ltp": 2.58, "tv": 115.91, "trd": NaN, "batb": [[0, 2.58, 18.98], [1, 1.01, 12]], "batl": NaN}, {"timestamp": 1631558281503, "ltp": 2.58, "tv": 153.87, "trd": [[2.58, 40.74]], "batb": [[0, 1.01, 12], [1, 1.01, 0]], "batl": [[0, 2.58, 43.88], [1, 100, 0.19]]}, {"timestamp": 1631558281781, "ltp": 2.58, "tv": 153.87, "trd": NaN, "batb": NaN, "batl": [[0, 100, 0.19], [1, 100, 0]]}, {"timestamp": 1631558285890, "ltp": 2.58, "tv": 153.87, "trd": NaN, "batb": NaN, "batl": [[0, 2.58, 16.9], [1, 100, 0.19]]}, {"timestamp": 1631558287303, "ltp": 2.58, "tv": 187.65, "trd": [[2.58, 74.52]], "batb": [[0, 2.44, 20.83], [1, 1.01, 12]], "batl": [[0, 2.58, 15.7]]}, {"timestamp": 1631558288580, "ltp": 2.58, "tv": 187.65, "trd": NaN, "batb": NaN, "batl": [[0, 100, 0.19], [1, 100, 0]]}, {"timestamp": 1631558322705, "ltp": 2.58, "tv": 187.65, "trd": NaN, "batb": [[0, 1.01, 12], [1, 1.01, 0]], "batl": NaN}, {"timestamp": 1631558327698, "ltp": 2.58, "tv": 187.65, "trd": NaN, "batb": [[0, 2.84, 16.3], [1, 1.01, 12]], "batl": NaN}, {"timestamp": 1631558330065, "ltp": 2.84, "tv": 220.25, "trd": [[2.84, 32.6]], "batb": [[0, 1.01, 12], [1, 1.01, 0]], "batl": NaN}, {"timestamp": 1631558335311, "ltp": 2.84, "tv": 220.25, "trd": NaN, "batb": [[0, 2.7, 17.64], [1, 1.01, 12]], "batl": NaN}, {"timestamp": 1631558345910, "ltp": 2.7, "tv": 232.53, "trd": [[2.7, 12.28]], "batb": [[0, 1.01, 12], [1, 1.01, 0]], "batl": NaN}, {"timestamp": 1631558350923, "ltp": 2.7, "tv": 232.53, "trd": NaN, "batb": [[0, 2.7, 17.64], [1, 1.01, 12]], "batl": NaN}, {"timestamp": 1631558359831, "ltp": 2.7, "tv": 232.53, "trd": NaN, "batb": [[0, 1.01, 12], [1, 1.01, 0]], "batl": NaN}, {"timestamp": 1631558364720, "ltp": 2.7, "tv": 232.53, "trd": NaN, "batb": [[0, 2.66, 18.07], [1, 1.01, 12]], "batl": NaN}, {"timestamp": 1631558375137, "ltp": 2.66, "tv": 250.6, "trd": [[2.66, 18.07]], "batb": [[0, 1.01, 12], [1, 1.01, 0]], "batl": NaN}, {"timestamp": 1631558380247, "ltp": 2.66, "tv": 250.6, "trd": NaN, "batb": [[0, 2.52, 19.73], [1, 1.01, 12]], "batl": NaN}, {"timestamp": 1631558387369, "ltp": 2.52, "tv": 290.03, "trd": [[2.52, 39.42]], "batb": [[0, 1.01, 12], [1, 1.01, 0]], "batl": [[0, 2.52, 14.8], [1, 100, 0.19]]}, {"timestamp": 1631558389059, "ltp": 2.52, "tv": 290.03, "trd": NaN, "batb": NaN, "batl": [[0, 100, 0.19], [1, 100, 0]]}, {"timestamp": 1631558390164, "ltp": 2.52, "tv": 290.03, "trd": NaN, "batb": NaN, "batl": [[0, 2.52, 12.8], [1, 100, 0.19]]}, {"timestamp": 1631558403610, "ltp": 2.52, "tv": 290.03, "trd": NaN, "batb": NaN, "batl": [[0, 100, 0.19], [1, 100, 0]]}, {"timestamp": 1631558409102, "ltp": 2.52, "tv": 291.7, "trd": [[2.52, 41.09]], "batb": NaN, "batl": NaN}, {"timestamp": 1631558414088, "ltp": 2.52, "tv": 291.7, "trd": NaN, "batb": [[0, 3, 15], [1, 1.01, 12]], "batl": NaN}, {"timestamp": 1631558418798, "ltp": 2.52, "tv": 291.7, "trd": NaN, "batb": [[0, 1.01, 12], [1, 1.01, 0]], "batl": NaN}, {"timestamp": 1631558423115, "ltp": 2.52, "tv": 291.7, "trd": NaN, "batb": NaN, "batl": [[0, 3, 14.42], [1, 100, 0.19]]}, {"timestamp": 1631558424607, "ltp": 2.52, "tv": 291.7, "trd": NaN, "batb": [[0, 2.84, 16.3], [1, 1.01, 12]], "batl": [[0, 3, 28.59]]}, {"timestamp": 1631558425205, "ltp": 2.52, "tv": 291.7, "trd": NaN, "batb": NaN, "batl": [[0, 3, 13.65]]}, {"timestamp": 1631558427344, "ltp": 2.52, "tv": 291.7, "trd": NaN, "batb": NaN, "batl": [[0, 100, 0.19], [1, 100, 0]]}, {"timestamp": 1631558431494, "ltp": 2.84, "tv": 323.62, "trd": [[2.84, 64.52]], "batb": [[0, 1.01, 12], [1, 1.01, 0]], "batl": NaN}, {"timestamp": 1631558431763, "ltp": 2.84, "tv": 323.62, "trd": NaN, "batb": NaN, "batl": [[0, 2.84, 16.3], [1, 100, 0.19]]}, {"timestamp": 1631558433006, "ltp": 2.84, "tv": 323.62, "trd": NaN, "batb": NaN, "batl": [[0, 100, 0.19], [1, 100, 0]]}, {"timestamp": 1631558436403, "ltp": 2.84, "tv": 323.62, "trd": NaN, "batb": [[0, 2.7, 17.64], [1, 1.01, 12]], "batl": NaN}, {"timestamp": 1631558439497, "ltp": 2.84, "tv": 323.62, "trd": NaN, "batb": [[0, 1.01, 12], [1, 1.01, 0]], "batl": NaN}, {"timestamp": 1631558444278, "ltp": 2.84, "tv": 323.62, "trd": NaN, "batb": NaN, "batl": [[0, 2.7, 14.51], [1, 100, 0.19]]}, {"timestamp": 1631558459333, "ltp": 2.84, "tv": 323.62, "trd": NaN, "batb": NaN, "batl": [[0, 100, 0.19], [1, 100, 0]]}]}]}