{"info": {"id": "1.187594322", "eventId": "30897917", "eventName": "Match Odds", "marketType": "MATCH_ODDS", "openDate": 1631538171871, "name": "E Bogdan v A Moratelli", "numberOfActiveRunner": 2, "countryCode": "", "sport": "TENNIS", "venue": "", "volume": {"total": 692.65, "preMatch": 90.75, "inPlay": 601.9}, "winner": {"id": 7429606, "name": "E Bogdan", "status": "WINNER", "position": 1}, "delay": 5}, "runners": [{"id": 7429606, "name": "E Bogdan", "status": "WINNER", "position": 1, "inPlayOdds": 2.76, "inPlayTime": 1631538171871, "avgPrematch": 2.76, "closedOdds": 1.01, "maxPrematch": 2.76, "minPrematch": 2.76, "maxInPlay": 2.84, "minInPlay": 1.01, "inPlayIndex": 6, "lengthOdds": 518, "lengthOddsPrematch": 6, "lengthOddsInPlay": 512, "tradedVolume": 404.03, "preMatchVolume": 1.43, "inPlayVolume": 402.6}, {"id": 9628072, "name": "A Moratelli", "status": "LOSER", "position": 2, "inPlayOdds": 1.57, "inPlayTime": 1631538171871, "avgPrematch": 1.63, "closedOdds": 8.6, "maxPrematch": 1.66, "minPrematch": 1.57, "maxInPlay": 8.6, "minInPlay": 1.52, "inPlayIndex": 33, "lengthOdds": 295, "lengthOddsPrematch": 33, "lengthOddsInPlay": 262, "tradedVolume": 288.62, "preMatchVolume": 89.32, "inPlayVolume": 199.3}], "marketUpdates": [{"timestamp": 1631518387105000000, "openDate": "2021-09-13T10:30:00.000Z", "status": "OPEN", "betDelay": 0, "inPlay": false, "complete": true}, {"timestamp": 1631522764138000000, "openDate": "2021-09-13T12:30:00.000Z", "status": "OPEN", "betDelay": 0, "inPlay": false, "complete": true}, {"timestamp": 1631526208624000000, "openDate": "2021-09-13T12:45:00.000Z", "status": "OPEN", "betDelay": 0, "inPlay": false, "complete": true}, {"timestamp": 1631527854192000000, "openDate": "2021-09-13T13:05:00.000Z", "status": "OPEN", "betDelay": 0, "inPlay": false, "complete": true}, {"timestamp": 1631530622442000000, "openDate": "2021-09-13T12:30:00.000Z", "status": "OPEN", "betDelay": 0, "inPlay": false, "complete": true}, {"timestamp": 1631531634100000000, "openDate": "2021-09-13T12:40:00.000Z", "status": "OPEN", "betDelay": 0, "inPlay": false, "complete": true}, {"timestamp": 1631536574414000000, "openDate": "2021-09-13T12:50:00.000Z", "status": "OPEN", "betDelay": 0, "inPlay": false, "complete": true}, {"timestamp": 1631537247903000000, "openDate": "2021-09-13T13:00:00.000Z", "status": "OPEN", "betDelay": 0, "inPlay": false, "complete": true}, {"timestamp": 1631537889485000000, "openDate": "2021-09-13T13:10:00.000Z", "status": "OPEN", "betDelay": 0, "inPlay": false, "complete": true}, {"timestamp": 1631537977970000000, "openDate": "2021-09-13T13:05:00.000Z", "status": "OPEN", "betDelay": 0, "inPlay": false, "complete": true}, {"timestamp": 1631538171871000000, "openDate": "2021-09-13T13:05:00.000Z", "status": "OPEN", "betDelay": 5, "inPlay": true, "complete": true}, {"timestamp": 1631538341817000000, "openDate": "2021-09-13T13:00:00.000Z", "status": "OPEN", "betDelay": 5, "inPlay": true, "complete": true}, {"timestamp": 1631538463476000000, "openDate": "2021-09-13T13:07:38.000Z", "status": "OPEN", "betDelay": 5, "inPlay": true, "complete": true}, {"timestamp": 1631542545955000000, "openDate": "2021-09-13T13:07:38.000Z", "status": "SUSPENDED", "betDelay": 5, "inPlay": true, "complete": true}, {"timestamp": 1631542555009000000, "openDate": "2021-09-13T13:07:38.000Z", "status": "CLOSED", "betDelay": 5, "inPlay": true, "complete": true}], "odds": [{"runnerId": 7429606, "odds": [{"timestamp": 1631536601687, "ltp": 2.76, "tv": 1.43, "trd": [[2.76, 1.43]], "batb": NaN, "batl": NaN}, {"timestamp": 1631536866591, "ltp": 2.76, "tv": 1.43, "trd": NaN, "batb": NaN, "batl": [[0, 990, 2.2], [1, 990, 0]]}, {"timestamp": 1631537250123, "ltp": 2.76, "tv": 1.43, "trd": NaN, "batb": NaN, "batl": [[0, 4.4, 2.44], [1, 990, 2.2]]}, {"timestamp": 1631537889485, "ltp": 2.76, "tv": 1.43, "trd": NaN, "batb": NaN, "batl": [[0, 990, 2.2], [1, 990, 0]]}, {"timestamp": 1631537890167, "ltp": 2.76, "tv": 1.43, "trd": NaN, "batb": NaN, "batl": [[0, 3.9, 2.75], [1, 990, 2.2]]}, {"timestamp": 1631537977970, "ltp": 2.76, "tv": 1.43, "trd": NaN, "batb": NaN, "batl": [[0, 3.85, 2.78]]}, {"timestamp": 1631538171871, "ltp": 2.76, "tv": 1.43, "trd": NaN, "batb": [[0, 1.01, 7], [1, 2.46, 0], [2, 2.44, 0]], "batl": NaN}, {"timestamp": 1631538177079, "ltp": 2.76, "tv": 1.43, "trd": NaN, "batb": [[0, 2.2, 24.99], [1, 1.01, 7]], "batl": NaN}, {"timestamp": 1631538459455, "ltp": 2.76, "tv": 1.43, "trd": NaN, "batb": [[0, 1.01, 7], [1, 1.01, 0]], "batl": NaN}, {"timestamp": 1631538464084, "ltp": 2.76, "tv": 1.43, "trd": NaN, "batb": [[0, 2.26, 23.8], [1, 1.01, 7]], "batl": NaN}, {"timestamp": 1631538482381, "ltp": 2.76, "tv": 1.43, "trd": NaN, "batb": [[0, 1.01, 7], [1, 1.01, 0]], "batl": NaN}, {"timestamp": 1631538487306, "ltp": 2.76, "tv": 1.43, "trd": NaN, "batb": [[0, 2.1, 27.27], [1, 1.01, 7]], "batl": NaN}, {"timestamp": 1631538497504, "ltp": 2.52, "tv": 8.31, "trd": [[2.52, 6.88]], "batb": NaN, "batl": [[0, 2.52, 6.87]]}, {"timestamp": 1631538518723, "ltp": 2.52, "tv": 8.31, "trd": NaN, "batb": [[0, 1.01, 7], [1, 1.01, 0]], "batl": NaN}, {"timestamp": 1631538523633, "ltp": 2.52, "tv": 8.31, "trd": NaN, "batb": [[0, 2, 30], [1, 1.01, 7]], "batl": NaN}, {"timestamp": 1631538548264, "ltp": 2.52, "tv": 8.31, "trd": NaN, "batb": [[0, 1.01, 7], [1, 1.01, 0]], "batl": NaN}, {"timestamp": 1631538553285, "ltp": 2.52, "tv": 8.31, "trd": NaN, "batb": [[0, 1.88, 34.09], [1, 1.01, 7]], "batl": NaN}, {"timestamp": 1631538583596, "ltp": 2.52, "tv": 8.31, "trd": NaN, "batb": [[0, 1.01, 7], [1, 1.01, 0]], "batl": NaN}, {"timestamp": 1631538588506, "ltp": 2.52, "tv": 8.31, "trd": NaN, "batb": [[0, 2, 30], [1, 1.01, 7]], "batl": NaN}, {"timestamp": 1631538606565, "ltp": 2.52, "tv": 8.31, "trd": NaN, "batb": [[0, 1.01, 7], [1, 1.01, 0]], "batl": NaN}, {"timestamp": 1631538611428, "ltp": 2.52, "tv": 8.31, "trd": NaN, "batb": [[0, 2.1, 27.27], [1, 1.01, 7]], "batl": NaN}, {"timestamp": 1631538640642, "ltp": 2.52, "tv": 8.31, "trd": NaN, "batb": [[0, 1.01, 7], [1, 1.01, 0]], "batl": NaN}, {"timestamp": 1631538645466, "ltp": 2.52, "tv": 8.31, "trd": NaN, "batb": [[0, 1.98, 30.61], [1, 1.01, 7]], "batl": NaN}, {"timestamp": 1631538722890, "ltp": 2.52, "tv": 8.31, "trd": NaN, "batb": [[0, 1.01, 7], [1, 1.01, 0]], "batl": NaN}, {"timestamp": 1631538727779, "ltp": 2.52, "tv": 8.31, "trd": NaN, "batb": [[0, 1.85, 35.29], [1, 1.01, 7]], "batl": NaN}, {"timestamp": 1631538728781, "ltp": 2.52, "tv": 8.31, "trd": NaN, "batb": [[1, 1.62, 421.1], [2, 1.01, 7]], "batl": [[0, 2.6, 261.08]]}, {"timestamp": 1631538749206, "ltp": 2.52, "tv": 8.31, "trd": NaN, "batb": [[0, 1.62, 421.1], [1, 1.01, 7], [2, 1.01, 0]], "batl": NaN}, {"timestamp": 1631538749997, "ltp": 2.52, "tv": 8.31, "trd": NaN, "batb": [[0, 1.01, 7], [1, 1.01, 0]], "batl": NaN}, {"timestamp": 1631538754069, "ltp": 2.52, "tv": 8.31, "trd": NaN, "batb": [[0, 1.98, 30.61], [1, 1.01, 7]], "batl": NaN}, {"timestamp": 1631538756096, "ltp": 2.52, "tv": 8.31, "trd": NaN, "batb": [[1, 1.67, 415.35], [2, 1.01, 7]], "batl": NaN}, {"timestamp": 1631538779611, "ltp": 2.52, "tv": 8.31, "trd": NaN, "batb": [[1, 1.01, 7], [2, 1.01, 0]], "batl": NaN}, {"timestamp": 1631538780918, "ltp": 2.52, "tv": 8.31, "trd": NaN, "batb": [[0, 1.01, 7], [1, 1.01, 0]], "batl": NaN}, {"timestamp": 1631538785817, "ltp": 2.52, "tv": 8.31, "trd": NaN, "batb": [[0, 2.1, 27.27], [1, 1.01, 7]], "batl": NaN}, {"timestamp": 1631538803162, "ltp": 2.52, "tv": 8.31, "trd": NaN, "batb": [[0, 1.01, 7], [1, 1.01, 0]], "batl": NaN}, {"timestamp": 1631538808048, "ltp": 2.52, "tv": 8.31, "trd": NaN, "batb": [[0, 2.2, 24.99], [1, 1.01, 7]], "batl": NaN}, {"timestamp": 1631538856975, "ltp": 2.52, "tv": 8.31, "trd": NaN, "batb": [[0, 1.01, 7], [1, 1.01, 0]], "batl": NaN}, {"timestamp": 1631538861910, "ltp": 2.52, "tv": 8.31, "trd": NaN, "batb": [[0, 2.34, 22.38], [1, 1.01, 7]], "batl": NaN}, {"timestamp": 1631538896646, "ltp": 2.52, "tv": 8.31, "trd": NaN, "batb": [[0, 1.01, 7], [1, 1.01, 0]], "batl": NaN}, {"timestamp": 1631538901440, "ltp": 2.52, "tv": 8.31, "trd": NaN, "batb": [[0, 2.5, 20], [1, 1.01, 7]], "batl": NaN}, {"timestamp": 1631538920025, "ltp": 2.52, "tv": 8.31, "trd": NaN, "batb": [[0, 1.01, 7], [1, 1.01, 0]], "batl": NaN}, {"timestamp": 1631538925037, "ltp": 2.52, "tv": 8.31, "trd": NaN, "batb": [[0, 2.58, 18.98], [1, 1.01, 7]], "batl": NaN}, {"timestamp": 1631538930083, "ltp": 2.52, "tv": 8.31, "trd": NaN, "batb": [[0, 1.01, 7], [1, 1.01, 0]], "batl": NaN}, {"timestamp": 1631538934986, "ltp": 2.52, "tv": 8.31, "trd": NaN, "batb": [[0, 2.34, 22.38], [1, 1.01, 7]], "batl": NaN}, {"timestamp": 1631538936957, "ltp": 2.52, "tv": 8.31, "trd": NaN, "batb": [[1, 1.86, 404.05], [2, 1.01, 7]], "batl": [[0, 3.3, 194.53]]}, {"timestamp": 1631538955662, "ltp": 2.52, "tv": 8.31, "trd": NaN, "batb": [[0, 1.86, 404.05], [1, 1.01, 7], [2, 1.01, 0]], "batl": NaN}, {"timestamp": 1631538960688, "ltp": 2.52, "tv": 8.31, "trd": NaN, "batb": [[0, 2.16, 25.86], [1, 1.86, 404.05], [2, 1.01, 7]], "batl": NaN}, {"timestamp": 1631538976825, "ltp": 2.52, "tv": 8.31, "trd": NaN, "batb": [[0, 1.86, 404.05], [1, 1.01, 7], [2, 1.01, 0]], "batl": NaN}, {"timestamp": 1631538981683, "ltp": 2.52, "tv": 8.31, "trd": NaN, "batb": [[0, 2.06, 28.3], [1, 1.86, 404.05], [2, 1.01, 7]], "batl": NaN}, {"timestamp": 1631538984829, "ltp": 2.52, "tv": 8.31, "trd": NaN, "batb": NaN, "batl": [[0, 2.92, 224.27]]}, {"timestamp": 1631539014673, "ltp": 2.52, "tv": 8.31, "trd": NaN, "batb": [[0, 1.86, 404.05], [1, 1.01, 7], [2, 1.01, 0]], "batl": NaN}, {"timestamp": 1631539019645, "ltp": 2.52, "tv": 8.31, "trd": NaN, "batb": [[0, 2.16, 25.86], [1, 1.86, 404.05], [2, 1.01, 7]], "batl": NaN}, {"timestamp": 1631539047374, "ltp": 2.52, "tv": 8.31, "trd": NaN, "batb": [[0, 1.86, 404.05], [1, 1.01, 7], [2, 1.01, 0]], "batl": NaN}, {"timestamp": 1631539047789, "ltp": 2.52, "tv": 8.31, "trd": NaN, "batb": [[0, 1.01, 7], [1, 1.01, 0]], "batl": NaN}, {"timestamp": 1631539052302, "ltp": 2.52, "tv": 8.31, "trd": NaN, "batb": [[0, 2, 30], [1, 1.01, 7]], "batl": NaN}, {"timestamp": 1631539053715, "ltp": 2.52, "tv": 8.31, "trd": NaN, "batb": [[1, 1.7, 414.9], [2, 1.01, 7]], "batl": NaN}, {"timestamp": 1631539163354, "ltp": 2.52, "tv": 8.31, "trd": NaN, "batb": [[0, 1.7, 414.9], [1, 1.01, 7], [2, 1.01, 0]], "batl": NaN}, {"timestamp": 1631539164570, "ltp": 2.52, "tv": 8.31, "trd": NaN, "batb": [[0, 1.01, 7], [1, 1.01, 0]], "batl": NaN}, {"timestamp": 1631539168382, "ltp": 2.52, "tv": 8.31, "trd": NaN, "batb": [[0, 2.1, 27.27], [1, 1.01, 7]], "batl": NaN}, {"timestamp": 1631539170116, "ltp": 2.52, "tv": 8.31, "trd": NaN, "batb": [[1, 1.77, 407.75], [2, 1.01, 7]], "batl": NaN}, {"timestamp": 1631539195035, "ltp": 2.52, "tv": 8.31, "trd": NaN, "batb": [[0, 1.01, 7], [1, 1.77, 0], [2, 1.01, 0]], "batl": NaN}, {"timestamp": 1631539199513, "ltp": 2.52, "tv": 8.31, "trd": NaN, "batb": [[0, 2.26, 23.8], [1, 1.01, 7]], "batl": NaN}, {"timestamp": 1631539201314, "ltp": 2.52, "tv": 8.31, "trd": NaN, "batb": [[1, 1.86, 404.05], [2, 1.01, 7]], "batl": [[0, 3.3, 194.53]]}, {"timestamp": 1631539217034, "ltp": 2.52, "tv": 8.31, "trd": NaN, "batb": [[0, 1.86, 404.05], [1, 1.01, 7], [2, 1.01, 0]], "batl": NaN}, {"timestamp": 1631539222086, "ltp": 2.52, "tv": 8.31, "trd": NaN, "batb": [[0, 2.42, 21.12], [1, 1.86, 404.05], [2, 1.01, 7]], "batl": NaN}, {"timestamp": 1631539238907, "ltp": 2.52, "tv": 8.31, "trd": NaN, "batb": [[0, 1.01, 7], [1, 1.86, 0], [2, 1.01, 0]], "batl": NaN}, {"timestamp": 1631539243807, "ltp": 2.52, "tv": 8.31, "trd": NaN, "batb": [[0, 2.5, 20], [1, 1.01, 7]], "batl": NaN}, {"timestamp": 1631539244793, "ltp": 2.52, "tv": 8.31, "trd": NaN, "batb": [[1, 1.97, 400.24], [2, 1.01, 7]], "batl": [[0, 3.65, 172.73]]}, {"timestamp": 1631539279020, "ltp": 2.52, "tv": 8.31, "trd": NaN, "batb": [[0, 1.97, 400.24], [1, 1.01, 7], [2, 1.01, 0]], "batl": NaN}, {"timestamp": 1631539284066, "ltp": 2.52, "tv": 8.31, "trd": NaN, "batb": [[0, 2.66, 18.07], [1, 1.97, 400.24], [2, 1.01, 7]], "batl": NaN}, {"timestamp": 1631539308898, "ltp": 2.52, "tv": 8.31, "trd": NaN, "batb": [[0, 1.01, 7], [1, 1.97, 0], [2, 1.01, 0]], "batl": NaN}, {"timestamp": 1631539313592, "ltp": 2.74, "tv": 10.04, "trd": [[2.74, 1.73]], "batb": [[0, 2.84, 14.57], [1, 1.01, 7]], "batl": NaN}, {"timestamp": 1631539313860, "ltp": 2.74, "tv": 10.04, "trd": NaN, "batb": [[0, 1.01, 7], [1, 1.01, 0]], "batl": NaN}, {"timestamp": 1631539314774, "ltp": 2.74, "tv": 10.04, "trd": NaN, "batb": [[0, 2.12, 393.94], [1, 1.01, 7]], "batl": [[0, 4.2, 150.04]]}, {"timestamp": 1631539318788, "ltp": 2.74, "tv": 10.04, "trd": NaN, "batb": [[0, 2.84, 16.3], [1, 2.12, 393.94], [2, 1.01, 7]], "batl": NaN}, {"timestamp": 1631539324200, "ltp": 2.84, "tv": 11.68, "trd": [[2.84, 1.64]], "batb": [[0, 2.12, 393.94], [1, 1.01, 7], [2, 1.01, 0]], "batl": NaN}, {"timestamp": 1631539329182, "ltp": 2.84, "tv": 11.68, "trd": NaN, "batb": [[0, 2.84, 16.3], [1, 2.12, 393.94], [2, 1.01, 7]], "batl": NaN}, {"timestamp": 1631539331601, "ltp": 2.84, "tv": 13.32, "trd": [[2.84, 3.28]], "batb": [[0, 2.12, 393.94], [1, 1.01, 7], [2, 1.01, 0]], "batl": NaN}, {"timestamp": 1631539336610, "ltp": 2.84, "tv": 13.32, "trd": NaN, "batb": [[0, 2.84, 16.3], [1, 2.12, 393.94], [2, 1.01, 7]], "batl": NaN}, {"timestamp": 1631539343033, "ltp": 2.84, "tv": 14.96, "trd": [[2.84, 4.92]], "batb": [[0, 2.12, 393.94], [1, 1.01, 7], [2, 1.01, 0]], "batl": NaN}, {"timestamp": 1631539353313, "ltp": 2.58, "tv": 16.87, "trd": [[2.58, 1.91]], "batb": NaN, "batl": NaN}, {"timestamp": 1631539363423, "ltp": 2.58, "tv": 16.87, "trd": NaN, "batb": [[0, 2.84, 16.3], [1, 2.12, 393.94], [2, 1.01, 7]], "batl": NaN}, {"timestamp": 1631539384094, "ltp": 2.58, "tv": 16.87, "trd": NaN, "batb": [[0, 2.12, 393.94], [1, 1.01, 7], [2, 1.01, 0]], "batl": NaN}, {"timestamp": 1631539389086, "ltp": 2.58, "tv": 16.87, "trd": NaN, "batb": [[0, 2.5, 20], [1, 2.12, 393.94], [2, 1.01, 7]], "batl": NaN}, {"timestamp": 1631539390661, "ltp": 2.58, "tv": 16.87, "trd": NaN, "batb": NaN, "batl": [[0, 3.65, 172.73]]}, {"timestamp": 1631539424400, "ltp": 2.58, "tv": 16.87, "trd": NaN, "batb": [[0, 2.12, 393.94], [1, 1.01, 7], [2, 1.01, 0]], "batl": NaN}, {"timestamp": 1631539425602, "ltp": 2.58, "tv": 16.87, "trd": NaN, "batb": [[0, 1.01, 7], [1, 1.01, 0]], "batl": NaN}, {"timestamp": 1631539429321, "ltp": 2.58, "tv": 16.87, "trd": NaN, "batb": [[0, 2.26, 23.8], [1, 1.01, 7]], "batl": NaN}, {"timestamp": 1631539431139, "ltp": 2.58, "tv": 16.87, "trd": NaN, "batb": [[1, 1.86, 404.05], [2, 1.01, 7]], "batl": [[0, 3.3, 194.53]]}, {"timestamp": 1631539453154, "ltp": 2.58, "tv": 16.87, "trd": NaN, "batb": [[0, 1.86, 404.05], [1, 1.01, 7], [2, 1.01, 0]], "batl": NaN}, {"timestamp": 1631539457883, "ltp": 2.58, "tv": 16.87, "trd": NaN, "batb": [[0, 2.06, 28.3], [1, 1.86, 404.05], [2, 1.01, 7]], "batl": NaN}, {"timestamp": 1631539459350, "ltp": 2.58, "tv": 16.87, "trd": NaN, "batb": NaN, "batl": [[0, 3, 216.36]]}, {"timestamp": 1631539576979, "ltp": 2.58, "tv": 16.87, "trd": NaN, "batb": [[0, 1.86, 404.05], [1, 1.01, 7], [2, 1.01, 0]], "batl": NaN}, {"timestamp": 1631539578286, "ltp": 2.58, "tv": 16.87, "trd": NaN, "batb": [[0, 1.01, 7], [1, 1.01, 0]], "batl": NaN}, {"timestamp": 1631539582002, "ltp": 2.58, "tv": 16.87, "trd": NaN, "batb": [[0, 1.88, 34.09], [1, 1.01, 7]], "batl": NaN}, {"timestamp": 1631539583980, "ltp": 2.58, "tv": 16.87, "trd": NaN, "batb": [[1, 1.67, 415.35], [2, 1.01, 7]], "batl": [[0, 2.72, 244.84]]}, {"timestamp": 1631539603104, "ltp": 2.58, "tv": 16.87, "trd": NaN, "batb": NaN, "batl": [[0, 1.94, 3], [1, 2.72, 244.84]]}, {"timestamp": 1631539606439, "ltp": 2.58, "tv": 16.87, "trd": NaN, "batb": [[0, 1.67, 415.35], [1, 1.01, 7], [2, 1.01, 0]], "batl": NaN}, {"timestamp": 1631539607755, "ltp": 2.58, "tv": 16.87, "trd": NaN, "batb": NaN, "batl": [[1, 2.72, 0]]}, {"timestamp": 1631539611449, "ltp": 2.58, "tv": 16.87, "trd": NaN, "batb": [[0, 1.78, 38.46], [1, 1.67, 415.35], [2, 1.01, 7]], "batl": NaN}, {"timestamp": 1631539613117, "ltp": 2.58, "tv": 16.87, "trd": NaN, "batb": NaN, "batl": [[1, 2.5, 278.28]]}, {"timestamp": 1631539630059, "ltp": 2.58, "tv": 16.87, "trd": NaN, "batb": [[0, 1.67, 415.35], [1, 1.01, 7], [2, 1.01, 0]], "batl": NaN}, {"timestamp": 1631539635447, "ltp": 2.58, "tv": 16.87, "trd": NaN, "batb": [[0, 1.88, 34.09], [1, 1.82, 8], [2, 1.67, 415.35]], "batl": NaN}, {"timestamp": 1631539672506, "ltp": 2.58, "tv": 16.87, "trd": NaN, "batb": [[1, 1.67, 415.35], [2, 1.01, 7]], "batl": NaN}, {"timestamp": 1631539685695, "ltp": 2.58, "tv": 16.87, "trd": NaN, "batb": [[0, 1.67, 415.35], [1, 1.01, 7], [2, 1.01, 0]], "batl": NaN}, {"timestamp": 1631539690696, "ltp": 2.58, "tv": 16.87, "trd": NaN, "batb": [[0, 1.71, 42.25], [1, 1.67, 415.35], [2, 1.01, 7]], "batl": NaN}, {"timestamp": 1631539693710, "ltp": 2.58, "tv": 16.87, "trd": NaN, "batb": [[0, 1.72, 10], [1, 1.71, 42.25], [2, 1.67, 415.35]], "batl": NaN}, {"timestamp": 1631539711084, "ltp": 2.58, "tv": 16.87, "trd": NaN, "batb": [[1, 1.67, 415.35], [2, 1.01, 7]], "batl": NaN}, {"timestamp": 1631539712386, "ltp": 2.58, "tv": 16.87, "trd": NaN, "batb": [[1, 1.01, 7], [2, 1.01, 0]], "batl": NaN}, {"timestamp": 1631539716040, "ltp": 2.58, "tv": 16.87, "trd": NaN, "batb": [[1, 1.65, 46.15], [2, 1.01, 7]], "batl": NaN}, {"timestamp": 1631539718603, "ltp": 2.58, "tv": 16.87, "trd": NaN, "batb": [[2, 1.55, 426.23]], "batl": NaN}, {"timestamp": 1631539719231, "ltp": 2.58, "tv": 16.87, "trd": NaN, "batb": [[0, 1.65, 46.15], [1, 1.55, 426.23], [2, 1.01, 7]], "batl": NaN}, {"timestamp": 1631539757092, "ltp": 2.58, "tv": 16.87, "trd": NaN, "batb": [[0, 1.55, 426.23], [1, 1.01, 7], [2, 1.01, 0]], "batl": [[1, 2.5, 0]]}, {"timestamp": 1631539761778, "ltp": 2.58, "tv": 16.87, "trd": NaN, "batb": [[0, 1.58, 51.72], [1, 1.55, 426.23], [2, 1.01, 7]], "batl": NaN}, {"timestamp": 1631539762879, "ltp": 2.58, "tv": 16.87, "trd": NaN, "batb": NaN, "batl": [[1, 2.3, 313.97]]}, {"timestamp": 1631539778990, "ltp": 2.58, "tv": 16.87, "trd": NaN, "batb": [[0, 1.6, 12], [1, 1.58, 51.72], [2, 1.55, 426.23]], "batl": NaN}, {"timestamp": 1631539788179, "ltp": 2.58, "tv": 16.87, "trd": NaN, "batb": [[0, 1.78, 3], [1, 1.6, 12], [2, 1.58, 51.72]], "batl": NaN}, {"timestamp": 1631539792297, "ltp": 2.58, "tv": 16.87, "trd": NaN, "batb": [[2, 1.55, 426.23]], "batl": NaN}, {"timestamp": 1631539793604, "ltp": 2.58, "tv": 16.87, "trd": NaN, "batb": [[2, 1.01, 7]], "batl": [[1, 2.3, 0]]}, {"timestamp": 1631539797311, "ltp": 1.78, "tv": 19.87, "trd": [[1.78, 3]], "batb": [[0, 1.6, 12], [1, 1.51, 58.82]], "batl": NaN}, {"timestamp": 1631539799196, "ltp": 1.78, "tv": 19.87, "trd": NaN, "batb": [[2, 1.44, 442.12]], "batl": [[1, 2.16, 347.49]]}, {"timestamp": 1631539801607, "ltp": 1.78, "tv": 19.87, "trd": NaN, "batb": NaN, "batl": [[0, 1.78, 2], [1, 1.94, 3], [2, 2.16, 347.49]]}, {"timestamp": 1631539802538, "ltp": 1.78, "tv": 19.87, "trd": NaN, "batb": [[0, 1.51, 58.82], [1, 1.44, 442.12], [2, 1.01, 7]], "batl": [[0, 1.94, 3], [1, 2.16, 347.49], [2, 2.16, 0]]}, {"timestamp": 1631539822644, "ltp": 1.78, "tv": 19.87, "trd": NaN, "batb": NaN, "batl": [[0, 1.7, 4], [1, 1.94, 3], [2, 2.16, 347.49]]}, {"timestamp": 1631539830480, "ltp": 1.78, "tv": 19.87, "trd": NaN, "batb": [[0, 1.44, 442.12], [1, 1.01, 7], [2, 1.01, 0]], "batl": NaN}, {"timestamp": 1631539832211, "ltp": 1.78, "tv": 19.87, "trd": NaN, "batb": [[0, 1.01, 7], [1, 1.01, 0]], "batl": [[2, 2.16, 0]]}, {"timestamp": 1631539835510, "ltp": 1.78, "tv": 19.87, "trd": NaN, "batb": [[0, 1.45, 66.66], [1, 1.01, 7]], "batl": NaN}, {"timestamp": 1631539837801, "ltp": 1.78, "tv": 19.87, "trd": NaN, "batb": [[1, 1.38, 454.56], [2, 1.01, 7]], "batl": [[2, 2.04, 388.23]]}, {"timestamp": 1631539847731, "ltp": 1.78, "tv": 19.87, "trd": NaN, "batb": [[0, 1.38, 454.56], [1, 1.01, 7], [2, 1.01, 0]], "batl": NaN}, {"timestamp": 1631539850125, "ltp": 1.78, "tv": 19.87, "trd": NaN, "batb": NaN, "batl": [[0, 1.54, 3], [1, 1.7, 4], [2, 1.94, 3]]}, {"timestamp": 1631539851330, "ltp": 1.78, "tv": 19.87, "trd": NaN, "batb": NaN, "batl": [[0, 1.45, 72.27], [1, 1.54, 3], [2, 1.7, 4]]}, {"timestamp": 1631539852635, "ltp": 1.78, "tv": 19.87, "trd": NaN, "batb": [[0, 1.42, 71.42], [1, 1.38, 454.56], [2, 1.01, 7]], "batl": NaN}, {"timestamp": 1631539853620, "ltp": 1.78, "tv": 19.87, "trd": NaN, "batb": NaN, "batl": [[0, 1.54, 3], [1, 1.7, 4], [2, 1.94, 3]]}, {"timestamp": 1631539863638, "ltp": 1.42, "tv": 162.7, "trd": [[1.42, 142.84]], "batb": [[0, 1.38, 454.56], [1, 1.01, 7], [2, 1.01, 0]], "batl": [[0, 1.54, 3.85]]}, {"timestamp": 1631539866558, "ltp": 1.42, "tv": 162.7, "trd": NaN, "batb": NaN, "batl": [[0, 1.54, 3]]}, {"timestamp": 1631539868370, "ltp": 1.42, "tv": 162.7, "trd": NaN, "batb": NaN, "batl": [[0, 1.49, 3], [1, 1.54, 3], [2, 1.7, 4]]}, {"timestamp": 1631539873921, "ltp": 1.42, "tv": 162.7, "trd": NaN, "batb": [[0, 1.38, 533.5]], "batl": NaN}, {"timestamp": 1631539886848, "ltp": 1.42, "tv": 162.7, "trd": NaN, "batb": NaN, "batl": [[0, 1.44, 3], [1, 1.49, 3], [2, 1.54, 3]]}, {"timestamp": 1631539890384, "ltp": 1.42, "tv": 162.7, "trd": NaN, "batb": NaN, "batl": [[1, 1.54, 3], [2, 1.7, 4]]}, {"timestamp": 1631539891761, "ltp": 1.42, "tv": 162.7, "trd": NaN, "batb": NaN, "batl": [[0, 1.54, 3], [1, 1.7, 4], [2, 1.94, 3]]}, {"timestamp": 1631539917484, "ltp": 1.42, "tv": 162.7, "trd": NaN, "batb": [[0, 1.42, 12], [1, 1.38, 533.5], [2, 1.01, 7]], "batl": NaN}, {"timestamp": 1631539932888, "ltp": 1.42, "tv": 162.7, "trd": NaN, "batb": NaN, "batl": [[0, 1.46, 3], [1, 1.54, 3], [2, 1.7, 4]]}, {"timestamp": 1631539984022, "ltp": 1.42, "tv": 162.7, "trd": NaN, "batb": [[1, 1.38, 454.56]], "batl": NaN}, {"timestamp": 1631539986414, "ltp": 1.42, "tv": 162.7, "trd": NaN, "batb": [[1, 1.01, 7], [2, 1.01, 0]], "batl": NaN}, {"timestamp": 1631539989006, "ltp": 1.42, "tv": 162.7, "trd": NaN, "batb": [[1, 1.34, 88.23], [2, 1.01, 7]], "batl": NaN}, {"timestamp": 1631539992532, "ltp": 1.42, "tv": 162.7, "trd": NaN, "batb": [[2, 1.28, 492.51]], "batl": NaN}, {"timestamp": 1631539995607, "ltp": 1.42, "tv": 162.7, "trd": NaN, "batb": [[0, 1.34, 88.23], [1, 1.28, 492.51], [2, 1.01, 7]], "batl": NaN}, {"timestamp": 1631540034453, "ltp": 1.42, "tv": 162.7, "trd": NaN, "batb": [[0, 1.37, 12], [1, 1.34, 88.23], [2, 1.28, 492.51]], "batl": NaN}, {"timestamp": 1631540055073, "ltp": 1.42, "tv": 162.7, "trd": NaN, "batb": [[0, 1.44, 3], [1, 1.37, 12], [2, 1.34, 88.23]], "batl": NaN}, {"timestamp": 1631540083415, "ltp": 1.42, "tv": 162.7, "trd": NaN, "batb": [[0, 1.37, 12], [1, 1.34, 88.23], [2, 1.23, 523.51]], "batl": NaN}, {"timestamp": 1631540113060, "ltp": 1.42, "tv": 162.7, "trd": NaN, "batb": [[0, 1.34, 88.23], [1, 1.23, 523.51], [2, 1.01, 7]], "batl": NaN}, {"timestamp": 1631540114678, "ltp": 1.42, "tv": 162.7, "trd": NaN, "batb": [[0, 1.23, 523.51], [1, 1.01, 7], [2, 1.01, 0]], "batl": NaN}, {"timestamp": 1631540116163, "ltp": 1.42, "tv": 162.7, "trd": NaN, "batb": [[0, 1.01, 7], [1, 1.01, 0]], "batl": NaN}, {"timestamp": 1631540119671, "ltp": 1.42, "tv": 162.7, "trd": NaN, "batb": [[0, 1.28, 107.14], [1, 1.01, 7]], "batl": NaN}, {"timestamp": 1631540121360, "ltp": 1.42, "tv": 162.7, "trd": NaN, "batb": [[1, 1.2, 538.09], [2, 1.01, 7]], "batl": [[2, 1.66, 587.71]]}, {"timestamp": 1631540140470, "ltp": 1.42, "tv": 162.7, "trd": NaN, "batb": NaN, "batl": [[0, 1.33, 3], [1, 1.46, 3], [2, 1.54, 3]]}, {"timestamp": 1631540222028, "ltp": 1.42, "tv": 162.7, "trd": NaN, "batb": NaN, "batl": [[2, 1.66, 587.71]]}, {"timestamp": 1631540233947, "ltp": 1.42, "tv": 162.7, "trd": NaN, "batb": [[0, 1.2, 538.09], [1, 1.01, 7], [2, 1.01, 0]], "batl": NaN}, {"timestamp": 1631540235878, "ltp": 1.42, "tv": 162.7, "trd": NaN, "batb": [[0, 1.01, 7], [1, 1.01, 0]], "batl": NaN}, {"timestamp": 1631540241732, "ltp": 1.42, "tv": 162.7, "trd": NaN, "batb": [[0, 1.23, 523.51], [1, 1.01, 7]], "batl": NaN}, {"timestamp": 1631540260509, "ltp": 1.42, "tv": 162.7, "trd": NaN, "batb": [[0, 1.31, 96.77], [1, 1.23, 523.51], [2, 1.01, 7]], "batl": NaN}, {"timestamp": 1631540276087, "ltp": 1.42, "tv": 162.7, "trd": NaN, "batb": [[0, 1.23, 523.51], [1, 1.01, 7], [2, 1.01, 0]], "batl": NaN}, {"timestamp": 1631540277499, "ltp": 1.42, "tv": 162.7, "trd": NaN, "batb": [[0, 1.01, 7], [1, 1.01, 0]], "batl": NaN}, {"timestamp": 1631540281099, "ltp": 1.42, "tv": 162.7, "trd": NaN, "batb": [[0, 1.23, 130.43], [1, 1.01, 7]], "batl": NaN}, {"timestamp": 1631540283318, "ltp": 1.42, "tv": 162.7, "trd": NaN, "batb": [[1, 1.18, 557.21], [2, 1.01, 7]], "batl": NaN}, {"timestamp": 1631540291316, "ltp": 1.42, "tv": 162.7, "trd": NaN, "batb": [[0, 1.18, 557.21], [1, 1.01, 7], [2, 1.01, 0]], "batl": NaN}, {"timestamp": 1631540296316, "ltp": 1.42, "tv": 162.7, "trd": NaN, "batb": [[0, 1.27, 111.11], [1, 1.18, 557.21], [2, 1.01, 7]], "batl": NaN}, {"timestamp": 1631540302618, "ltp": 1.42, "tv": 162.7, "trd": NaN, "batb": [[0, 1.28, 8], [1, 1.27, 111.11], [2, 1.18, 557.21]], "batl": NaN}, {"timestamp": 1631540310967, "ltp": 1.42, "tv": 162.7, "trd": NaN, "batb": [[1, 1.18, 557.21], [2, 1.01, 7]], "batl": [[2, 1.66, 0]]}, {"timestamp": 1631540315554, "ltp": 1.42, "tv": 162.7, "trd": NaN, "batb": [[1, 1.2, 150], [2, 1.18, 557.21]], "batl": NaN}, {"timestamp": 1631540316395, "ltp": 1.42, "tv": 162.7, "trd": NaN, "batb": NaN, "batl": [[2, 1.58, 659.44]]}, {"timestamp": 1631540324808, "ltp": 1.2, "tv": 204.12, "trd": [[1.2, 25.42], [1.28, 16]], "batb": [[0, 1.18, 557.21], [1, 1.01, 7], [2, 1.18, 0]], "batl": NaN}, {"timestamp": 1631540329842, "ltp": 1.2, "tv": 204.12, "trd": NaN, "batb": [[0, 1.2, 150], [1, 1.18, 557.21], [2, 1.01, 7]], "batl": NaN}, {"timestamp": 1631540360958, "ltp": 1.2, "tv": 204.12, "trd": NaN, "batb": [[0, 1.18, 557.21], [1, 1.01, 7], [2, 1.01, 0]], "batl": NaN}, {"timestamp": 1631540365981, "ltp": 1.2, "tv": 204.12, "trd": NaN, "batb": [[0, 1.23, 130.43], [1, 1.18, 557.21], [2, 1.01, 7]], "batl": NaN}, {"timestamp": 1631540389012, "ltp": 1.2, "tv": 204.12, "trd": NaN, "batb": [[0, 1.26, 8], [1, 1.23, 130.43], [2, 1.18, 557.21]], "batl": NaN}, {"timestamp": 1631540394836, "ltp": 1.2, "tv": 204.12, "trd": NaN, "batb": [[1, 1.18, 557.21], [2, 1.01, 7]], "batl": NaN}, {"timestamp": 1631540398728, "ltp": 1.2, "tv": 204.12, "trd": NaN, "batb": NaN, "batl": [[0, 1.46, 3], [1, 1.58, 659.44], [2, 1.58, 0]]}, {"timestamp": 1631540399829, "ltp": 1.2, "tv": 204.12, "trd": NaN, "batb": [[1, 1.18, 723.87]], "batl": NaN}, {"timestamp": 1631540411638, "ltp": 1.2, "tv": 204.12, "trd": NaN, "batb": [[0, 1.18, 723.87], [1, 1.01, 7], [2, 1.01, 0]], "batl": NaN}, {"timestamp": 1631540430449, "ltp": 1.2, "tv": 204.12, "trd": NaN, "batb": [[0, 1.22, 10], [1, 1.18, 723.87], [2, 1.01, 7]], "batl": NaN}, {"timestamp": 1631540472523, "ltp": 1.2, "tv": 204.12, "trd": NaN, "batb": [[1, 1.18, 557.21]], "batl": NaN}, {"timestamp": 1631540473517, "ltp": 1.2, "tv": 204.12, "trd": NaN, "batb": [[1, 1.01, 7], [2, 1.01, 0]], "batl": [[1, 1.58, 0]]}, {"timestamp": 1631540479627, "ltp": 1.2, "tv": 204.12, "trd": NaN, "batb": [[1, 1.12, 659.2], [2, 1.01, 7]], "batl": [[1, 1.51, 751.18]]}, {"timestamp": 1631540480517, "ltp": 1.2, "tv": 204.12, "trd": NaN, "batb": [[1, 1.01, 7], [2, 1.01, 0]], "batl": NaN}, {"timestamp": 1631540482505, "ltp": 1.2, "tv": 204.12, "trd": NaN, "batb": [[1, 1.18, 166.66], [2, 1.01, 7]], "batl": NaN}, {"timestamp": 1631540482818, "ltp": 1.2, "tv": 204.12, "trd": NaN, "batb": [[1, 1.01, 7], [2, 1.01, 0]], "batl": NaN}, {"timestamp": 1631540486734, "ltp": 1.2, "tv": 204.12, "trd": NaN, "batb": [[1, 1.18, 557.21], [2, 1.01, 7]], "batl": NaN}, {"timestamp": 1631540487728, "ltp": 1.2, "tv": 204.12, "trd": NaN, "batb": [[0, 1.23, 130.43], [1, 1.22, 10], [2, 1.18, 557.21]], "batl": NaN}, {"timestamp": 1631540499113, "ltp": 1.2, "tv": 204.12, "trd": NaN, "batb": [[0, 1.22, 10], [1, 1.18, 557.21], [2, 1.01, 7]], "batl": NaN}, {"timestamp": 1631540500846, "ltp": 1.2, "tv": 204.12, "trd": NaN, "batb": [[1, 1.01, 7], [2, 1.01, 0]], "batl": [[1, 1.51, 0]]}, {"timestamp": 1631540504050, "ltp": 1.2, "tv": 204.12, "trd": NaN, "batb": [[0, 1.28, 107.14], [1, 1.22, 10], [2, 1.01, 7]], "batl": NaN}, {"timestamp": 1631540506959, "ltp": 1.2, "tv": 204.12, "trd": NaN, "batb": [[2, 1.2, 538.09]], "batl": [[1, 1.66, 587.71]]}, {"timestamp": 1631540514415, "ltp": 1.2, "tv": 204.12, "trd": NaN, "batb": [[0, 1.22, 10], [1, 1.2, 538.09], [2, 1.01, 7]], "batl": NaN}, {"timestamp": 1631540519408, "ltp": 1.2, "tv": 204.12, "trd": NaN, "batb": [[0, 1.23, 130.43], [1, 1.22, 10], [2, 1.2, 538.09]], "batl": NaN}, {"timestamp": 1631540534345, "ltp": 1.2, "tv": 204.12, "trd": NaN, "batb": [[2, 1.01, 7]], "batl": [[1, 1.66, 0]]}, {"timestamp": 1631540545220, "ltp": 1.2, "tv": 204.12, "trd": NaN, "batb": [[0, 1.22, 10], [1, 1.01, 7], [2, 1.01, 0]], "batl": NaN}, {"timestamp": 1631540550150, "ltp": 1.2, "tv": 204.12, "trd": NaN, "batb": [[0, 1.28, 107.14], [1, 1.22, 10], [2, 1.01, 7]], "batl": NaN}, {"timestamp": 1631540561178, "ltp": 1.2, "tv": 204.12, "trd": NaN, "batb": [[0, 1.22, 10], [1, 1.01, 7], [2, 1.01, 0]], "batl": NaN}, {"timestamp": 1631540566157, "ltp": 1.2, "tv": 204.12, "trd": NaN, "batb": [[0, 1.27, 111.11], [1, 1.22, 10], [2, 1.01, 7]], "batl": NaN}, {"timestamp": 1631540582075, "ltp": 1.2, "tv": 204.12, "trd": NaN, "batb": [[0, 1.22, 10], [1, 1.01, 7], [2, 1.01, 0]], "batl": NaN}, {"timestamp": 1631540587077, "ltp": 1.2, "tv": 204.12, "trd": NaN, "batb": [[0, 1.31, 96.77], [1, 1.22, 10], [2, 1.01, 7]], "batl": NaN}, {"timestamp": 1631540610399, "ltp": 1.2, "tv": 204.12, "trd": NaN, "batb": [[0, 1.35, 5], [1, 1.31, 96.77], [2, 1.22, 10]], "batl": NaN}, {"timestamp": 1631540627620, "ltp": 1.2, "tv": 204.12, "trd": NaN, "batb": [[0, 1.44, 3], [1, 1.35, 5], [2, 1.31, 96.77]], "batl": NaN}, {"timestamp": 1631540631611, "ltp": 1.2, "tv": 204.12, "trd": NaN, "batb": [[2, 1.22, 10]], "batl": NaN}, {"timestamp": 1631540636540, "ltp": 1.2, "tv": 204.12, "trd": NaN, "batb": [[1, 1.38, 78.94], [2, 1.35, 5]], "batl": NaN}, {"timestamp": 1631540649567, "ltp": 1.2, "tv": 204.12, "trd": NaN, "batb": [[0, 1.51, 3], [1, 1.44, 3], [2, 1.38, 78.94]], "batl": NaN}, {"timestamp": 1631540662451, "ltp": 1.51, "tv": 210.12, "trd": [[1.51, 6]], "batb": [[0, 1.44, 3], [1, 1.35, 5], [2, 1.22, 10]], "batl": [[0, 1.51, 5.94]]}, {"timestamp": 1631540663566, "ltp": 1.51, "tv": 214.12, "trd": [[1.51, 10]], "batb": NaN, "batl": [[0, 1.51, 14.9]]}, {"timestamp": 1631540664575, "ltp": 1.51, "tv": 214.12, "trd": NaN, "batb": NaN, "batl": [[0, 1.51, 11.92]]}, {"timestamp": 1631540665459, "ltp": 1.51, "tv": 226.08, "trd": [[1.51, 21.96]], "batb": [[0, 1.55, 4.02], [1, 1.44, 3], [2, 1.35, 5]], "batl": NaN}, {"timestamp": 1631540665875, "ltp": 1.55, "tv": 234.12, "trd": [[1.55, 8.04]], "batb": [[0, 1.44, 3], [1, 1.35, 5], [2, 1.22, 10]], "batl": [[0, 1.5, 65.56], [1, 1.51, 1.94]]}, {"timestamp": 1631540667177, "ltp": 1.55, "tv": 234.12, "trd": NaN, "batb": [[2, 1.31, 96.77]], "batl": [[1, 1.51, 0]]}, {"timestamp": 1631540669469, "ltp": 1.44, "tv": 240.08, "trd": [[1.44, 5.96]], "batb": [[0, 1.35, 5.02], [1, 1.31, 96.77], [2, 1.22, 10]], "batl": NaN}, {"timestamp": 1631540670557, "ltp": 1.44, "tv": 240.12, "trd": [[1.44, 6]], "batb": [[0, 1.35, 5]], "batl": [[0, 1.44, 11.94], [1, 1.5, 65.56]]}, {"timestamp": 1631540671595, "ltp": 1.44, "tv": 240.12, "trd": NaN, "batb": NaN, "batl": [[2, 1.55, 18]]}, {"timestamp": 1631540672598, "ltp": 1.44, "tv": 240.12, "trd": NaN, "batb": NaN, "batl": [[0, 1.44, 29.96], [1, 1.55, 16], [2, 1.55, 0]]}, {"timestamp": 1631540673469, "ltp": 1.44, "tv": 240.12, "trd": NaN, "batb": NaN, "batl": [[0, 1.44, 9], [1, 1.55, 0]]}, {"timestamp": 1631540679359, "ltp": 1.44, "tv": 240.12, "trd": NaN, "batb": NaN, "batl": [[0, 1.44, 65.56]]}, {"timestamp": 1631540686984, "ltp": 1.44, "tv": 240.12, "trd": NaN, "batb": [[1, 1.22, 10], [2, 1.01, 7]], "batl": NaN}, {"timestamp": 1631540692001, "ltp": 1.44, "tv": 240.12, "trd": NaN, "batb": [[1, 1.27, 111.11], [2, 1.22, 10]], "batl": NaN}, {"timestamp": 1631540694290, "ltp": 1.44, "tv": 240.12, "trd": NaN, "batb": NaN, "batl": [[1, 1.66, 587.71]]}, {"timestamp": 1631540705111, "ltp": 1.44, "tv": 240.12, "trd": NaN, "batb": [[1, 1.22, 10], [2, 1.2, 538.09]], "batl": NaN}, {"timestamp": 1631540710049, "ltp": 1.44, "tv": 240.12, "trd": NaN, "batb": [[1, 1.28, 107.14], [2, 1.22, 10]], "batl": NaN}, {"timestamp": 1631540715607, "ltp": 1.44, "tv": 240.12, "trd": NaN, "batb": [[1, 1.22, 10], [2, 1.01, 7]], "batl": [[1, 1.66, 0]]}, {"timestamp": 1631540719985, "ltp": 1.35, "tv": 245.12, "trd": [[1.35, 5]], "batb": [[0, 1.22, 10], [1, 1.2, 150]], "batl": NaN}, {"timestamp": 1631540721478, "ltp": 1.35, "tv": 245.12, "trd": NaN, "batb": [[2, 1.16, 583.98]], "batl": [[1, 1.58, 659.44]]}, {"timestamp": 1631540723501, "ltp": 1.35, "tv": 245.12, "trd": NaN, "batb": NaN, "batl": [[0, 1.35, 14.82], [1, 1.44, 65.56], [2, 1.58, 659.44]]}, {"timestamp": 1631540724592, "ltp": 1.35, "tv": 245.12, "trd": NaN, "batb": NaN, "batl": [[0, 1.35, 9.88]]}, {"timestamp": 1631540725580, "ltp": 1.35, "tv": 245.12, "trd": NaN, "batb": NaN, "batl": [[0, 1.44, 65.56], [1, 1.58, 659.44], [2, 1.58, 0]]}, {"timestamp": 1631540741030, "ltp": 1.35, "tv": 245.12, "trd": NaN, "batb": [[2, 1.01, 7]], "batl": NaN}, {"timestamp": 1631540746926, "ltp": 1.35, "tv": 245.12, "trd": NaN, "batb": [[2, 1.18, 557.21]], "batl": NaN}, {"timestamp": 1631540747812, "ltp": 1.35, "tv": 245.12, "trd": NaN, "batb": [[1, 1.18, 557.21], [2, 1.01, 7]], "batl": NaN}, {"timestamp": 1631540749112, "ltp": 1.35, "tv": 245.12, "trd": NaN, "batb": [[1, 1.01, 7], [2, 1.01, 0]], "batl": NaN}, {"timestamp": 1631540752737, "ltp": 1.35, "tv": 245.12, "trd": NaN, "batb": [[0, 1.27, 111.11], [1, 1.22, 10], [2, 1.01, 7]], "batl": NaN}, {"timestamp": 1631540754660, "ltp": 1.35, "tv": 245.12, "trd": NaN, "batb": [[2, 1.2, 538.09]], "batl": NaN}, {"timestamp": 1631540773777, "ltp": 1.35, "tv": 245.12, "trd": NaN, "batb": NaN, "batl": [[0, 1.35, 3], [1, 1.44, 65.56], [2, 1.58, 659.44]]}, {"timestamp": 1631540775485, "ltp": 1.35, "tv": 245.12, "trd": NaN, "batb": [[0, 1.22, 10], [1, 1.01, 7], [2, 1.2, 0]], "batl": NaN}, {"timestamp": 1631540779586, "ltp": 1.35, "tv": 245.12, "trd": NaN, "batb": NaN, "batl": [[1, 1.58, 659.44], [2, 1.58, 0]]}, {"timestamp": 1631540779793, "ltp": 1.35, "tv": 245.12, "trd": NaN, "batb": [[0, 1.34, 88.23], [1, 1.22, 10], [2, 1.01, 7]], "batl": NaN}, {"timestamp": 1631540781145, "ltp": 1.35, "tv": 245.12, "trd": NaN, "batb": [[1, 1.23, 523.51], [2, 1.22, 10]], "batl": NaN}, {"timestamp": 1631540785688, "ltp": 1.35, "tv": 245.12, "trd": NaN, "batb": NaN, "batl": [[0, 1.58, 659.44], [1, 1.58, 0]]}, {"timestamp": 1631540789685, "ltp": 1.35, "tv": 245.12, "trd": NaN, "batb": NaN, "batl": [[0, 1.49, 65.56], [1, 1.58, 659.44]]}, {"timestamp": 1631540798875, "ltp": 1.35, "tv": 245.12, "trd": NaN, "batb": [[0, 1.23, 523.51], [1, 1.22, 10], [2, 1.01, 7]], "batl": NaN}, {"timestamp": 1631540799712, "ltp": 1.35, "tv": 245.12, "trd": NaN, "batb": [[0, 1.22, 10], [1, 1.01, 7], [2, 1.01, 0]], "batl": NaN}, {"timestamp": 1631540803774, "ltp": 1.35, "tv": 245.12, "trd": NaN, "batb": [[0, 1.27, 111.11], [1, 1.22, 10], [2, 1.01, 7]], "batl": NaN}, {"timestamp": 1631540805385, "ltp": 1.35, "tv": 245.12, "trd": NaN, "batb": [[2, 1.2, 538.09]], "batl": NaN}, {"timestamp": 1631540814798, "ltp": 1.35, "tv": 245.12, "trd": NaN, "batb": [[0, 1.22, 10], [1, 1.2, 538.09], [2, 1.01, 7]], "batl": NaN}, {"timestamp": 1631540819840, "ltp": 1.35, "tv": 245.12, "trd": NaN, "batb": [[0, 1.28, 107.14], [1, 1.22, 10], [2, 1.2, 538.09]], "batl": NaN}, {"timestamp": 1631540830341, "ltp": 1.35, "tv": 245.12, "trd": NaN, "batb": [[0, 1.22, 10], [1, 1.2, 538.09], [2, 1.01, 7]], "batl": NaN}, {"timestamp": 1631540832148, "ltp": 1.35, "tv": 245.12, "trd": NaN, "batb": [[1, 1.01, 7], [2, 1.01, 0]], "batl": NaN}, {"timestamp": 1631540835250, "ltp": 1.35, "tv": 245.12, "trd": NaN, "batb": [[0, 1.34, 88.23], [1, 1.22, 10], [2, 1.01, 7]], "batl": NaN}, {"timestamp": 1631540837758, "ltp": 1.35, "tv": 245.12, "trd": NaN, "batb": [[1, 1.23, 523.51], [2, 1.22, 10]], "batl": NaN}, {"timestamp": 1631540872772, "ltp": 1.35, "tv": 245.12, "trd": NaN, "batb": [[0, 1.22, 10], [1, 1.01, 7], [2, 1.22, 0]], "batl": [[1, 1.58, 0]]}, {"timestamp": 1631540877686, "ltp": 1.35, "tv": 245.12, "trd": NaN, "batb": [[0, 1.42, 71.42], [1, 1.22, 10], [2, 1.01, 7]], "batl": NaN}, {"timestamp": 1631540879091, "ltp": 1.35, "tv": 245.12, "trd": NaN, "batb": [[1, 1.31, 484.01], [2, 1.22, 10]], "batl": [[1, 1.89, 441.21]]}, {"timestamp": 1631540881179, "ltp": 1.35, "tv": 245.12, "trd": NaN, "batb": NaN, "batl": [[0, 1.89, 441.21], [1, 1.89, 0]]}, {"timestamp": 1631540892322, "ltp": 1.35, "tv": 245.12, "trd": NaN, "batb": NaN, "batl": [[0, 1.6, 65.56], [1, 1.89, 441.21]]}, {"timestamp": 1631540911559, "ltp": 1.35, "tv": 245.12, "trd": NaN, "batb": [[0, 1.31, 484.01], [1, 1.22, 10], [2, 1.01, 7]], "batl": NaN}, {"timestamp": 1631540912400, "ltp": 1.35, "tv": 245.12, "trd": NaN, "batb": [[0, 1.22, 10], [1, 1.01, 7], [2, 1.01, 0]], "batl": [[0, 1.89, 441.21], [1, 1.89, 0]]}, {"timestamp": 1631540916460, "ltp": 1.35, "tv": 245.12, "trd": NaN, "batb": [[0, 1.58, 51.72], [1, 1.22, 10], [2, 1.01, 7]], "batl": NaN}, {"timestamp": 1631540918588, "ltp": 1.35, "tv": 245.12, "trd": NaN, "batb": [[1, 1.38, 454.56], [2, 1.22, 10]], "batl": NaN}, {"timestamp": 1631540928195, "ltp": 1.35, "tv": 245.12, "trd": NaN, "batb": NaN, "batl": [[0, 1.75, 65.56], [1, 1.89, 441.21]]}, {"timestamp": 1631540943523, "ltp": 1.35, "tv": 245.12, "trd": NaN, "batb": NaN, "batl": [[0, 1.7, 9], [1, 1.75, 65.56], [2, 1.89, 441.21]]}, {"timestamp": 1631540961175, "ltp": 1.58, "tv": 248.52, "trd": [[1.58, 3.4]], "batb": [[0, 1.38, 454.56], [1, 1.22, 10], [2, 1.01, 7]], "batl": NaN}, {"timestamp": 1631540966056, "ltp": 1.58, "tv": 248.52, "trd": NaN, "batb": [[0, 1.58, 51.72], [1, 1.38, 454.56], [2, 1.22, 10]], "batl": NaN}, {"timestamp": 1631540970151, "ltp": 1.58, "tv": 248.52, "trd": NaN, "batb": [[1, 1.5, 131.12], [2, 1.38, 454.56]], "batl": NaN}, {"timestamp": 1631540974367, "ltp": 1.58, "tv": 248.52, "trd": NaN, "batb": [[2, 1.22, 10]], "batl": [[2, 1.89, 0]]}, {"timestamp": 1631541011891, "ltp": 1.58, "tv": 248.52, "trd": NaN, "batb": [[0, 1.5, 131.12], [1, 1.22, 10], [2, 1.01, 7]], "batl": NaN}, {"timestamp": 1631541013606, "ltp": 1.58, "tv": 248.52, "trd": NaN, "batb": [[0, 1.22, 10], [1, 1.01, 7], [2, 1.01, 0]], "batl": NaN}, {"timestamp": 1631541016923, "ltp": 1.58, "tv": 248.52, "trd": NaN, "batb": [[0, 1.48, 62.5], [1, 1.22, 10], [2, 1.01, 7]], "batl": NaN}, {"timestamp": 1631541018635, "ltp": 1.58, "tv": 248.52, "trd": NaN, "batb": NaN, "batl": [[1, 1.75, 0]]}, {"timestamp": 1631541024521, "ltp": 1.58, "tv": 248.52, "trd": NaN, "batb": NaN, "batl": [[0, 1.66, 65.56]]}, {"timestamp": 1631541040635, "ltp": 1.58, "tv": 248.52, "trd": NaN, "batb": NaN, "batl": [[0, 1.63, 8], [1, 1.66, 65.56]]}, {"timestamp": 1631541055665, "ltp": 1.58, "tv": 248.52, "trd": NaN, "batb": [[0, 1.22, 10], [1, 1.01, 7], [2, 1.01, 0]], "batl": NaN}, {"timestamp": 1631541060588, "ltp": 1.58, "tv": 248.52, "trd": NaN, "batb": [[0, 1.38, 78.94], [1, 1.22, 10], [2, 1.01, 7]], "batl": NaN}, {"timestamp": 1631541062688, "ltp": 1.58, "tv": 248.52, "trd": NaN, "batb": NaN, "batl": [[1, 1.66, 0]]}, {"timestamp": 1631541101637, "ltp": 1.58, "tv": 248.52, "trd": NaN, "batb": [[0, 1.22, 10], [1, 1.01, 7], [2, 1.01, 0]], "batl": NaN}, {"timestamp": 1631541106635, "ltp": 1.58, "tv": 248.52, "trd": NaN, "batb": [[0, 1.45, 66.66], [1, 1.22, 10], [2, 1.01, 7]], "batl": NaN}, {"timestamp": 1631541144253, "ltp": 1.58, "tv": 248.52, "trd": NaN, "batb": [[0, 1.22, 10], [1, 1.01, 7], [2, 1.01, 0]], "batl": NaN}, {"timestamp": 1631541149263, "ltp": 1.58, "tv": 248.52, "trd": NaN, "batb": [[0, 1.38, 78.94], [1, 1.22, 10], [2, 1.01, 7]], "batl": NaN}, {"timestamp": 1631541150151, "ltp": 1.58, "tv": 248.52, "trd": NaN, "batb": NaN, "batl": [[0, 1.45, 65.56], [1, 1.63, 8]]}, {"timestamp": 1631541152484, "ltp": 1.58, "tv": 248.52, "trd": NaN, "batb": NaN, "batl": [[0, 1.63, 8], [1, 1.63, 0]]}, {"timestamp": 1631541154474, "ltp": 1.58, "tv": 248.52, "trd": NaN, "batb": [[1, 1.33, 131.12], [2, 1.22, 10]], "batl": NaN}, {"timestamp": 1631541155281, "ltp": 1.58, "tv": 248.52, "trd": NaN, "batb": [[1, 1.33, 196.68]], "batl": NaN}, {"timestamp": 1631541158283, "ltp": 1.58, "tv": 248.52, "trd": NaN, "batb": NaN, "batl": [[0, 1.5, 65.56], [1, 1.63, 8]]}, {"timestamp": 1631541174727, "ltp": 1.58, "tv": 248.52, "trd": NaN, "batb": [[0, 1.33, 196.68], [1, 1.22, 10], [2, 1.01, 7]], "batl": NaN}, {"timestamp": 1631541176433, "ltp": 1.58, "tv": 248.52, "trd": NaN, "batb": [[0, 1.22, 10], [1, 1.01, 7], [2, 1.01, 0]], "batl": NaN}, {"timestamp": 1631541179698, "ltp": 1.58, "tv": 248.52, "trd": NaN, "batb": [[0, 1.31, 96.77], [1, 1.22, 10], [2, 1.01, 7]], "batl": NaN}, {"timestamp": 1631541181889, "ltp": 1.58, "tv": 248.52, "trd": NaN, "batb": NaN, "batl": [[0, 1.63, 8], [1, 1.63, 0]]}, {"timestamp": 1631541185296, "ltp": 1.58, "tv": 248.52, "trd": NaN, "batb": [[1, 1.28, 196.68], [2, 1.22, 10]], "batl": NaN}, {"timestamp": 1631541187633, "ltp": 1.58, "tv": 248.52, "trd": NaN, "batb": NaN, "batl": [[0, 1.45, 65.56], [1, 1.63, 8]]}, {"timestamp": 1631541199432, "ltp": 1.58, "tv": 248.52, "trd": NaN, "batb": NaN, "batl": [[0, 1.36, 3], [1, 1.45, 65.56], [2, 1.63, 8]]}, {"timestamp": 1631541207047, "ltp": 1.58, "tv": 248.52, "trd": NaN, "batb": [[0, 1.28, 196.68], [1, 1.22, 10], [2, 1.01, 7]], "batl": NaN}, {"timestamp": 1631541208957, "ltp": 1.58, "tv": 248.52, "trd": NaN, "batb": [[0, 1.22, 10], [1, 1.01, 7], [2, 1.01, 0]], "batl": NaN}, {"timestamp": 1631541212047, "ltp": 1.58, "tv": 248.52, "trd": NaN, "batb": [[0, 1.23, 130.43], [1, 1.22, 10], [2, 1.01, 7]], "batl": NaN}, {"timestamp": 1631541214558, "ltp": 1.58, "tv": 248.52, "trd": NaN, "batb": NaN, "batl": [[1, 1.63, 8], [2, 1.63, 0]]}, {"timestamp": 1631541218444, "ltp": 1.58, "tv": 248.52, "trd": NaN, "batb": [[1, 1.22, 272.24]], "batl": NaN}, {"timestamp": 1631541219845, "ltp": 1.58, "tv": 248.52, "trd": NaN, "batb": NaN, "batl": [[0, 1.35, 65.56], [1, 1.36, 3], [2, 1.63, 8]]}, {"timestamp": 1631541224839, "ltp": 1.58, "tv": 248.52, "trd": NaN, "batb": NaN, "batl": [[1, 1.63, 8], [2, 1.63, 0]]}, {"timestamp": 1631541231553, "ltp": 1.58, "tv": 248.52, "trd": NaN, "batb": [[0, 1.22, 272.24], [1, 1.01, 7], [2, 1.01, 0]], "batl": NaN}, {"timestamp": 1631541232951, "ltp": 1.58, "tv": 248.52, "trd": NaN, "batb": [[0, 1.22, 10]], "batl": NaN}, {"timestamp": 1631541236588, "ltp": 1.58, "tv": 248.52, "trd": NaN, "batb": [[1, 1.2, 150], [2, 1.01, 7]], "batl": NaN}, {"timestamp": 1631541238572, "ltp": 1.58, "tv": 248.52, "trd": NaN, "batb": NaN, "batl": [[0, 1.63, 8], [1, 1.63, 0]]}, {"timestamp": 1631541241622, "ltp": 1.58, "tv": 248.52, "trd": NaN, "batb": [[1, 1.2, 346.68]], "batl": NaN}, {"timestamp": 1631541241992, "ltp": 1.58, "tv": 248.52, "trd": NaN, "batb": [[1, 1.2, 477.8]], "batl": NaN}, {"timestamp": 1631541244597, "ltp": 1.58, "tv": 248.52, "trd": NaN, "batb": NaN, "batl": [[0, 1.33, 65.56], [1, 1.63, 8]]}, {"timestamp": 1631541256190, "ltp": 1.58, "tv": 248.52, "trd": NaN, "batb": [[1, 1.2, 327.8]], "batl": NaN}, {"timestamp": 1631541257384, "ltp": 1.58, "tv": 248.52, "trd": NaN, "batb": NaN, "batl": [[0, 1.63, 8], [1, 1.63, 0]]}, {"timestamp": 1631541261193, "ltp": 1.58, "tv": 248.52, "trd": NaN, "batb": [[0, 1.23, 130.43], [1, 1.22, 10]], "batl": NaN}, {"timestamp": 1631541265028, "ltp": 1.58, "tv": 248.52, "trd": NaN, "batb": NaN, "batl": [[0, 1.4, 65.56], [1, 1.63, 8]]}, {"timestamp": 1631541267622, "ltp": 1.58, "tv": 248.52, "trd": NaN, "batb": [[1, 1.22, 272.24]], "batl": NaN}, {"timestamp": 1631541269132, "ltp": 1.58, "tv": 248.52, "trd": NaN, "batb": [[1, 1.22, 10]], "batl": [[0, 1.63, 8], [1, 1.63, 0]]}, {"timestamp": 1631541283270, "ltp": 1.58, "tv": 248.52, "trd": NaN, "batb": [[0, 1.22, 10], [1, 1.01, 7], [2, 1.01, 0]], "batl": NaN}, {"timestamp": 1631541288166, "ltp": 1.58, "tv": 248.52, "trd": NaN, "batb": [[1, 1.18, 166.66], [2, 1.01, 7]], "batl": NaN}, {"timestamp": 1631541314486, "ltp": 1.58, "tv": 248.52, "trd": NaN, "batb": [[0, 1.18, 166.66], [1, 1.01, 7], [2, 1.01, 0]], "batl": NaN}, {"timestamp": 1631541318877, "ltp": 1.58, "tv": 248.52, "trd": NaN, "batb": [[1, 1.14, 618.77], [2, 1.01, 7]], "batl": [[0, 1.55, 700.17], [1, 1.63, 8]]}, {"timestamp": 1631541333821, "ltp": 1.58, "tv": 248.52, "trd": NaN, "batb": [[0, 1.22, 4], [1, 1.18, 166.66], [2, 1.14, 618.77]], "batl": NaN}, {"timestamp": 1631541348170, "ltp": 1.58, "tv": 248.52, "trd": NaN, "batb": [[0, 1.28, 3], [1, 1.22, 4], [2, 1.18, 166.66]], "batl": NaN}, {"timestamp": 1631541374878, "ltp": 1.58, "tv": 248.52, "trd": NaN, "batb": NaN, "batl": [[0, 1.3, 65.56], [1, 1.55, 700.17], [2, 1.63, 8]]}, {"timestamp": 1631541386508, "ltp": 1.28, "tv": 251.28, "trd": [[1.28, 18.76]], "batb": [[0, 1.28, 1.62]], "batl": NaN}, {"timestamp": 1631541396249, "ltp": 1.28, "tv": 251.28, "trd": NaN, "batb": [[0, 1.22, 4], [1, 1.18, 166.66], [2, 1.14, 618.77]], "batl": NaN}, {"timestamp": 1631541410677, "ltp": 1.28, "tv": 251.28, "trd": NaN, "batb": NaN, "batl": [[0, 1.24, 3], [1, 1.3, 65.56], [2, 1.55, 700.17]]}, {"timestamp": 1631541425190, "ltp": 1.28, "tv": 251.28, "trd": NaN, "batb": [[1, 1.14, 618.77], [2, 1.01, 7]], "batl": NaN}, {"timestamp": 1631541430184, "ltp": 1.28, "tv": 251.28, "trd": NaN, "batb": [[1, 1.15, 200], [2, 1.14, 618.77]], "batl": NaN}, {"timestamp": 1631541432983, "ltp": 1.28, "tv": 251.28, "trd": NaN, "batb": [[1, 1.14, 618.77], [2, 1.01, 7]], "batl": NaN}, {"timestamp": 1631541434373, "ltp": 1.22, "tv": 259.28, "trd": [[1.22, 8]], "batb": [[0, 1.01, 7], [1, 1.14, 0], [2, 1.01, 0]], "batl": [[0, 1.22, 2.51], [1, 1.24, 3], [2, 1.3, 65.56]]}, {"timestamp": 1631541438098, "ltp": 1.22, "tv": 259.28, "trd": NaN, "batb": [[0, 1.11, 272.72], [1, 1.01, 7]], "batl": [[2, 1.63, 8]]}, {"timestamp": 1631541440276, "ltp": 1.22, "tv": 259.28, "trd": NaN, "batb": [[1, 1.1, 733.06], [2, 1.01, 7]], "batl": [[2, 1.48, 795.63]]}, {"timestamp": 1631541445193, "ltp": 1.22, "tv": 259.28, "trd": NaN, "batb": [[0, 1.12, 131.12], [1, 1.11, 272.72], [2, 1.1, 733.06]], "batl": NaN}, {"timestamp": 1631541446486, "ltp": 1.22, "tv": 259.28, "trd": NaN, "batb": [[0, 1.12, 262.24]], "batl": NaN}, {"timestamp": 1631541449437, "ltp": 1.22, "tv": 259.28, "trd": NaN, "batb": [[0, 1.18, 3], [1, 1.12, 262.24], [2, 1.11, 272.72]], "batl": NaN}, {"timestamp": 1631541468431, "ltp": 1.22, "tv": 259.28, "trd": NaN, "batb": [[2, 1.1, 733.06]], "batl": NaN}, {"timestamp": 1631541469870, "ltp": 1.22, "tv": 259.28, "trd": NaN, "batb": [[2, 1.01, 7]], "batl": NaN}, {"timestamp": 1631541473444, "ltp": 1.22, "tv": 259.28, "trd": NaN, "batb": [[0, 1.18, 169.66]], "batl": NaN}, {"timestamp": 1631541475567, "ltp": 1.22, "tv": 259.28, "trd": NaN, "batb": [[1, 1.14, 618.77], [2, 1.12, 262.24]], "batl": NaN}, {"timestamp": 1631541475873, "ltp": 1.22, "tv": 259.28, "trd": NaN, "batb": [[2, 1.01, 7]], "batl": NaN}, {"timestamp": 1631541479458, "ltp": 1.22, "tv": 259.28, "trd": NaN, "batb": [[1, 1.16, 131.12], [2, 1.14, 618.77]], "batl": NaN}, {"timestamp": 1631541480083, "ltp": 1.22, "tv": 259.28, "trd": NaN, "batb": [[1, 1.16, 196.68]], "batl": [[1, 1.48, 795.63], [2, 1.63, 8]]}, {"timestamp": 1631541488386, "ltp": 1.22, "tv": 264.3, "trd": [[1.22, 13.01]], "batb": [[0, 1.22, 1.49], [1, 1.18, 169.66], [2, 1.16, 196.68]], "batl": [[0, 1.48, 795.63], [1, 1.63, 8], [2, 1.63, 0]]}, {"timestamp": 1631541493312, "ltp": 1.22, "tv": 264.3, "trd": NaN, "batb": [[0, 1.22, 3.49]], "batl": NaN}, {"timestamp": 1631541502621, "ltp": 1.22, "tv": 264.3, "trd": NaN, "batb": [[1, 1.18, 3]], "batl": NaN}, {"timestamp": 1631541507513, "ltp": 1.22, "tv": 267.79, "trd": [[1.22, 16.5]], "batb": [[0, 1.18, 3], [1, 1.16, 196.68], [2, 1.08, 374.99]], "batl": NaN}, {"timestamp": 1631541508391, "ltp": 1.22, "tv": 267.79, "trd": NaN, "batb": [[1, 1.08, 374.99], [2, 1.01, 7]], "batl": NaN}, {"timestamp": 1631541509790, "ltp": 1.22, "tv": 267.79, "trd": NaN, "batb": [[1, 1.1, 733.06], [2, 1.08, 374.99]], "batl": NaN}, {"timestamp": 1631541517411, "ltp": 1.22, "tv": 267.79, "trd": NaN, "batb": [[1, 1.12, 196.68], [2, 1.1, 733.06]], "batl": NaN}, {"timestamp": 1631541520724, "ltp": 1.22, "tv": 267.79, "trd": NaN, "batb": [[1, 1.12, 262.24]], "batl": NaN}, {"timestamp": 1631541532644, "ltp": 1.22, "tv": 267.79, "trd": NaN, "batb": [[2, 1.08, 374.99]], "batl": NaN}, {"timestamp": 1631541538453, "ltp": 1.22, "tv": 267.79, "trd": NaN, "batb": [[2, 1.09, 763.32]], "batl": NaN}, {"timestamp": 1631541549988, "ltp": 1.22, "tv": 267.79, "trd": NaN, "batb": [[2, 1.01, 7]], "batl": NaN}, {"timestamp": 1631541552173, "ltp": 1.22, "tv": 267.79, "trd": NaN, "batb": [[1, 1.15, 200], [2, 1.12, 262.24]], "batl": NaN}, {"timestamp": 1631541555692, "ltp": 1.22, "tv": 267.79, "trd": NaN, "batb": [[2, 1.14, 618.77]], "batl": NaN}, {"timestamp": 1631541563497, "ltp": 1.22, "tv": 267.79, "trd": NaN, "batb": [[0, 1.26, 3], [1, 1.18, 3], [2, 1.15, 200]], "batl": NaN}, {"timestamp": 1631541567442, "ltp": 1.22, "tv": 267.79, "trd": NaN, "batb": [[2, 1.16, 131.12]], "batl": NaN}, {"timestamp": 1631541598762, "ltp": 1.22, "tv": 267.79, "trd": NaN, "batb": [[1, 1.2, 150], [2, 1.18, 3]], "batl": NaN}, {"timestamp": 1631541601491, "ltp": 1.22, "tv": 267.79, "trd": NaN, "batb": [[0, 1.27, 65.56], [1, 1.26, 3], [2, 1.2, 150]], "batl": NaN}, {"timestamp": 1631541602012, "ltp": 1.22, "tv": 267.79, "trd": NaN, "batb": [[0, 1.26, 3], [1, 1.2, 150], [2, 1.18, 560.21]], "batl": NaN}, {"timestamp": 1631541617130, "ltp": 1.22, "tv": 267.79, "trd": NaN, "batb": [[1, 1.18, 3], [2, 1.01, 7]], "batl": [[0, 1.63, 8], [1, 1.63, 0]]}, {"timestamp": 1631541621826, "ltp": 1.22, "tv": 267.79, "trd": NaN, "batb": [[0, 1.28, 107.14], [1, 1.26, 3], [2, 1.18, 3]], "batl": NaN}, {"timestamp": 1631541623173, "ltp": 1.22, "tv": 267.79, "trd": NaN, "batb": [[2, 1.2, 538.09]], "batl": [[1, 1.66, 587.71]]}, {"timestamp": 1631541631668, "ltp": 1.22, "tv": 267.79, "trd": NaN, "batb": [[0, 1.4, 3], [1, 1.28, 107.14], [2, 1.26, 3]], "batl": NaN}, {"timestamp": 1631541634785, "ltp": 1.4, "tv": 273.79, "trd": [[1.4, 6]], "batb": [[0, 1.28, 107.14], [1, 1.26, 3], [2, 1.2, 538.09]], "batl": [[0, 1.4, 62.56], [1, 1.63, 8], [2, 1.66, 587.71]]}, {"timestamp": 1631541638293, "ltp": 1.4, "tv": 273.79, "trd": NaN, "batb": NaN, "batl": [[0, 1.4, 64.56]]}, {"timestamp": 1631541638978, "ltp": 1.4, "tv": 273.79, "trd": NaN, "batb": NaN, "batl": [[0, 1.4, 62.56]]}, {"timestamp": 1631541651601, "ltp": 1.4, "tv": 273.79, "trd": NaN, "batb": [[0, 1.26, 3], [1, 1.2, 538.09], [2, 1.18, 3]], "batl": NaN}, {"timestamp": 1631541655418, "ltp": 1.4, "tv": 273.79, "trd": NaN, "batb": [[0, 1.37, 3], [1, 1.26, 3], [2, 1.2, 538.09]], "batl": NaN}, {"timestamp": 1631541656613, "ltp": 1.37, "tv": 276.79, "trd": [[1.37, 3]], "batb": [[0, 1.26, 3], [1, 1.2, 688.09], [2, 1.18, 3]], "batl": NaN}, {"timestamp": 1631541663443, "ltp": 1.26, "tv": 279.55, "trd": [[1.26, 2.76]], "batb": [[0, 1.26, 1.62]], "batl": NaN}, {"timestamp": 1631541690767, "ltp": 1.26, "tv": 279.55, "trd": NaN, "batb": [[1, 1.2, 538.09]], "batl": NaN}, {"timestamp": 1631541692282, "ltp": 1.26, "tv": 279.55, "trd": NaN, "batb": [[1, 1.18, 3], [2, 1.01, 7]], "batl": [[2, 1.66, 0]]}, {"timestamp": 1631541695772, "ltp": 1.26, "tv": 279.55, "trd": NaN, "batb": [[1, 1.18, 169.66]], "batl": NaN}, {"timestamp": 1631541697550, "ltp": 1.26, "tv": 279.55, "trd": NaN, "batb": NaN, "batl": [[0, 1.63, 8], [1, 1.63, 0]]}, {"timestamp": 1631541698387, "ltp": 1.26, "tv": 279.55, "trd": NaN, "batb": [[2, 1.16, 583.98]], "batl": [[0, 1.58, 659.44], [1, 1.63, 8]]}, {"timestamp": 1631541700578, "ltp": 1.26, "tv": 279.55, "trd": NaN, "batb": [[0, 1.18, 169.66], [1, 1.16, 583.98], [2, 1.01, 7]], "batl": NaN}, {"timestamp": 1631541713413, "ltp": 1.26, "tv": 279.55, "trd": NaN, "batb": [[0, 1.2, 150], [1, 1.18, 169.66], [2, 1.16, 583.98]], "batl": NaN}, {"timestamp": 1631541714304, "ltp": 1.26, "tv": 279.55, "trd": NaN, "batb": [[0, 1.2, 300]], "batl": NaN}, {"timestamp": 1631541718375, "ltp": 1.26, "tv": 279.55, "trd": NaN, "batb": NaN, "batl": [[0, 1.22, 3], [1, 1.58, 659.44], [2, 1.63, 8]]}, {"timestamp": 1631541721095, "ltp": 1.26, "tv": 279.55, "trd": NaN, "batb": [[1, 1.18, 3]], "batl": NaN}, {"timestamp": 1631541721884, "ltp": 1.26, "tv": 279.55, "trd": NaN, "batb": [[2, 1.01, 7]], "batl": NaN}, {"timestamp": 1631541726118, "ltp": 1.26, "tv": 279.55, "trd": NaN, "batb": [[2, 1.15, 200]], "batl": NaN}, {"timestamp": 1631541727522, "ltp": 1.26, "tv": 279.55, "trd": NaN, "batb": [[0, 1.18, 3], [1, 1.15, 200], [2, 1.01, 7]], "batl": NaN}, {"timestamp": 1631541727830, "ltp": 1.26, "tv": 279.55, "trd": NaN, "batb": [[2, 1.14, 618.77]], "batl": NaN}, {"timestamp": 1631541733598, "ltp": 1.26, "tv": 279.55, "trd": NaN, "batb": [[1, 1.16, 100], [2, 1.15, 200]], "batl": NaN}, {"timestamp": 1631541733906, "ltp": 1.26, "tv": 279.55, "trd": NaN, "batb": [[1, 1.16, 200]], "batl": NaN}, {"timestamp": 1631541746450, "ltp": 1.26, "tv": 279.55, "trd": NaN, "batb": [[2, 1.14, 618.77]], "batl": NaN}, {"timestamp": 1631541750546, "ltp": 1.26, "tv": 279.55, "trd": NaN, "batb": NaN, "batl": [[0, 1.58, 659.44], [1, 1.63, 8], [2, 1.63, 0]]}, {"timestamp": 1631541751328, "ltp": 1.26, "tv": 279.55, "trd": NaN, "batb": [[0, 1.18, 169.66]], "batl": NaN}, {"timestamp": 1631541778891, "ltp": 1.26, "tv": 279.55, "trd": NaN, "batb": [[0, 1.18, 3]], "batl": NaN}, {"timestamp": 1631541780877, "ltp": 1.26, "tv": 279.55, "trd": NaN, "batb": [[2, 1.01, 7]], "batl": NaN}, {"timestamp": 1631541783890, "ltp": 1.26, "tv": 279.55, "trd": NaN, "batb": [[0, 1.2, 150], [1, 1.18, 3], [2, 1.16, 200]], "batl": NaN}, {"timestamp": 1631541786417, "ltp": 1.26, "tv": 279.55, "trd": NaN, "batb": [[2, 1.16, 783.98]], "batl": NaN}, {"timestamp": 1631541806254, "ltp": 1.26, "tv": 279.55, "trd": NaN, "batb": [[2, 1.16, 200]], "batl": NaN}, {"timestamp": 1631541811693, "ltp": 1.26, "tv": 279.55, "trd": NaN, "batb": [[1, 1.18, 560.21]], "batl": NaN}, {"timestamp": 1631541820983, "ltp": 1.2, "tv": 282.31, "trd": [[1.2, 28.18]], "batb": [[0, 1.18, 560.21], [1, 1.16, 200], [2, 1.01, 7]], "batl": NaN}, {"timestamp": 1631541825573, "ltp": 1.2, "tv": 282.31, "trd": NaN, "batb": [[0, 1.18, 3]], "batl": NaN}, {"timestamp": 1631541829113, "ltp": 1.2, "tv": 282.31, "trd": NaN, "batb": [[1, 1.01, 7], [2, 1.01, 0]], "batl": NaN}, {"timestamp": 1631541831222, "ltp": 1.2, "tv": 282.31, "trd": NaN, "batb": [[0, 1.31, 96.77], [1, 1.22, 530.12], [2, 1.18, 3]], "batl": NaN}, {"timestamp": 1631541836512, "ltp": 1.2, "tv": 282.31, "trd": NaN, "batb": [[1, 1.28, 50], [2, 1.22, 530.12]], "batl": NaN}, {"timestamp": 1631541836983, "ltp": 1.2, "tv": 282.31, "trd": NaN, "batb": [[0, 1.4, 3], [1, 1.31, 96.77], [2, 1.28, 200]], "batl": NaN}, {"timestamp": 1631541838494, "ltp": 1.2, "tv": 282.31, "trd": NaN, "batb": NaN, "batl": [[0, 1.46, 62.56], [1, 1.58, 659.44], [2, 1.63, 8]]}, {"timestamp": 1631541843816, "ltp": 1.2, "tv": 282.31, "trd": NaN, "batb": [[1, 1.28, 200], [2, 1.22, 530.12]], "batl": NaN}, {"timestamp": 1631541845806, "ltp": 1.2, "tv": 282.31, "trd": NaN, "batb": [[2, 1.18, 3]], "batl": NaN}, {"timestamp": 1631541847119, "ltp": 1.2, "tv": 282.31, "trd": NaN, "batb": [[1, 1.18, 3], [2, 1.01, 7]], "batl": NaN}, {"timestamp": 1631541849129, "ltp": 1.4, "tv": 285.31, "trd": [[1.4, 9]], "batb": [[0, 1.2, 150]], "batl": NaN}, {"timestamp": 1631541851524, "ltp": 1.4, "tv": 285.31, "trd": NaN, "batb": [[1, 1.18, 560.21]], "batl": [[0, 1.4, 2], [1, 1.46, 62.56], [2, 1.58, 659.44]]}, {"timestamp": 1631541852411, "ltp": 1.4, "tv": 285.31, "trd": NaN, "batb": NaN, "batl": [[0, 1.4, 8.94]]}, {"timestamp": 1631541853615, "ltp": 1.4, "tv": 285.31, "trd": NaN, "batb": NaN, "batl": [[0, 1.4, 47.69]]}, {"timestamp": 1631541854629, "ltp": 1.4, "tv": 285.31, "trd": NaN, "batb": NaN, "batl": [[0, 1.4, 14.9]]}, {"timestamp": 1631541855365, "ltp": 1.4, "tv": 285.31, "trd": NaN, "batb": NaN, "batl": [[0, 1.4, 2.98], [1, 1.58, 659.44], [2, 1.63, 8]]}, {"timestamp": 1631541855745, "ltp": 1.4, "tv": 285.31, "trd": NaN, "batb": NaN, "batl": [[0, 1.58, 659.44], [1, 1.63, 8], [2, 1.63, 0]]}, {"timestamp": 1631541857628, "ltp": 1.4, "tv": 285.31, "trd": NaN, "batb": [[0, 1.22, 100], [1, 1.2, 150], [2, 1.18, 560.21]], "batl": NaN}, {"timestamp": 1631541858349, "ltp": 1.4, "tv": 285.31, "trd": NaN, "batb": [[0, 1.22, 300]], "batl": NaN}, {"timestamp": 1631541861163, "ltp": 1.4, "tv": 285.31, "trd": NaN, "batb": NaN, "batl": [[0, 1.37, 62.56], [1, 1.58, 659.44], [2, 1.63, 8]]}, {"timestamp": 1631541865269, "ltp": 1.4, "tv": 285.31, "trd": NaN, "batb": [[1, 1.18, 3], [2, 1.01, 7]], "batl": NaN}, {"timestamp": 1631541866788, "ltp": 1.4, "tv": 285.31, "trd": NaN, "batb": [[0, 1.18, 3], [1, 1.01, 7], [2, 1.01, 0]], "batl": NaN}, {"timestamp": 1631541869761, "ltp": 1.4, "tv": 285.31, "trd": NaN, "batb": [[1, 1.15, 200], [2, 1.01, 7]], "batl": NaN}, {"timestamp": 1631541871283, "ltp": 1.4, "tv": 285.31, "trd": NaN, "batb": [[2, 1.14, 618.77]], "batl": NaN}, {"timestamp": 1631541875078, "ltp": 1.4, "tv": 285.31, "trd": NaN, "batb": NaN, "batl": [[0, 1.58, 659.44], [1, 1.63, 8], [2, 1.63, 0]]}, {"timestamp": 1631541878583, "ltp": 1.4, "tv": 285.31, "trd": NaN, "batb": [[1, 1.16, 150], [2, 1.15, 200]], "batl": NaN}, {"timestamp": 1631541879093, "ltp": 1.4, "tv": 285.31, "trd": NaN, "batb": [[1, 1.16, 300]], "batl": NaN}, {"timestamp": 1631541881393, "ltp": 1.4, "tv": 285.31, "trd": NaN, "batb": NaN, "batl": [[0, 1.3, 62.56], [1, 1.58, 659.44], [2, 1.63, 8]]}, {"timestamp": 1631541988320, "ltp": 1.4, "tv": 285.31, "trd": NaN, "batb": [[1, 1.15, 200], [2, 1.14, 618.77]], "batl": [[0, 1.58, 659.44], [1, 1.63, 8], [2, 1.63, 0]]}, {"timestamp": 1631542020455, "ltp": 1.15, "tv": 298.21, "trd": [[1.15, 9.9], [1.18, 3]], "batb": [[0, 1.14, 618.77], [1, 1.01, 7], [2, 1.14, 0]], "batl": NaN}, {"timestamp": 1631542025475, "ltp": 1.15, "tv": 298.21, "trd": NaN, "batb": [[0, 1.15, 200], [1, 1.14, 618.77], [2, 1.01, 7]], "batl": NaN}, {"timestamp": 1631542030464, "ltp": 1.15, "tv": 298.21, "trd": NaN, "batb": [[0, 1.14, 618.77], [1, 1.01, 7], [2, 1.01, 0]], "batl": NaN}, {"timestamp": 1631542031546, "ltp": 1.15, "tv": 298.21, "trd": NaN, "batb": [[0, 1.16, 100], [1, 1.14, 618.77], [2, 1.01, 7]], "batl": NaN}, {"timestamp": 1631542032067, "ltp": 1.15, "tv": 298.21, "trd": NaN, "batb": [[0, 1.16, 200]], "batl": NaN}, {"timestamp": 1631542032743, "ltp": 1.15, "tv": 298.21, "trd": NaN, "batb": [[1, 1.01, 7], [2, 1.01, 0]], "batl": [[0, 1.63, 8], [1, 1.63, 0]]}, {"timestamp": 1631542034089, "ltp": 1.15, "tv": 298.21, "trd": NaN, "batb": [[0, 1.01, 7], [1, 1.01, 0]], "batl": NaN}, {"timestamp": 1631542035443, "ltp": 1.15, "tv": 298.21, "trd": NaN, "batb": [[0, 1.08, 374.99], [1, 1.01, 7]], "batl": NaN}, {"timestamp": 1631542038473, "ltp": 1.15, "tv": 298.21, "trd": NaN, "batb": [[0, 1.1, 733.06], [1, 1.08, 374.99], [2, 1.01, 7]], "batl": [[0, 1.48, 795.63], [1, 1.63, 8]]}, {"timestamp": 1631542041077, "ltp": 1.15, "tv": 298.21, "trd": NaN, "batb": [[0, 1.12, 150], [1, 1.1, 733.06], [2, 1.08, 374.99]], "batl": NaN}, {"timestamp": 1631542060130, "ltp": 1.15, "tv": 298.21, "trd": NaN, "batb": [[1, 1.08, 374.99], [2, 1.01, 7]], "batl": NaN}, {"timestamp": 1631542065706, "ltp": 1.15, "tv": 298.21, "trd": NaN, "batb": [[1, 1.09, 763.32], [2, 1.08, 374.99]], "batl": NaN}, {"timestamp": 1631542067115, "ltp": 1.15, "tv": 298.21, "trd": NaN, "batb": [[2, 1.01, 7]], "batl": NaN}, {"timestamp": 1631542069307, "ltp": 1.15, "tv": 298.21, "trd": NaN, "batb": [[1, 1.01, 7], [2, 1.01, 0]], "batl": [[0, 1.63, 8], [1, 1.63, 0]]}, {"timestamp": 1631542070819, "ltp": 1.15, "tv": 298.21, "trd": NaN, "batb": [[0, 1.01, 7], [1, 1.01, 0]], "batl": NaN}, {"timestamp": 1631542072122, "ltp": 1.15, "tv": 298.21, "trd": NaN, "batb": [[0, 1.05, 599.99], [1, 1.01, 7]], "batl": NaN}, {"timestamp": 1631542074835, "ltp": 1.15, "tv": 298.21, "trd": NaN, "batb": [[0, 1.06, 1007.44], [1, 1.05, 599.99], [2, 1.01, 7]], "batl": [[0, 1.41, 914.95], [1, 1.63, 8]]}, {"timestamp": 1631542077917, "ltp": 1.15, "tv": 298.21, "trd": NaN, "batb": [[0, 1.08, 50], [1, 1.06, 1007.44], [2, 1.05, 599.99]], "batl": NaN}, {"timestamp": 1631542079225, "ltp": 1.15, "tv": 298.21, "trd": NaN, "batb": [[0, 1.08, 250]], "batl": NaN}, {"timestamp": 1631542097880, "ltp": 1.15, "tv": 298.21, "trd": NaN, "batb": [[2, 1.01, 7]], "batl": NaN}, {"timestamp": 1631542099655, "ltp": 1.15, "tv": 298.21, "trd": NaN, "batb": [[1, 1.01, 7], [2, 1.01, 0]], "batl": NaN}, {"timestamp": 1631542102844, "ltp": 1.15, "tv": 298.21, "trd": NaN, "batb": [[1, 1.04, 749.99], [2, 1.01, 7]], "batl": NaN}, {"timestamp": 1631542105353, "ltp": 1.15, "tv": 298.21, "trd": NaN, "batb": [[1, 1.06, 949.57], [2, 1.04, 749.99]], "batl": NaN}, {"timestamp": 1631542117635, "ltp": 1.15, "tv": 298.21, "trd": NaN, "batb": [[0, 1.06, 949.57], [1, 1.01, 7], [2, 1.04, 0]], "batl": NaN}, {"timestamp": 1631542117843, "ltp": 1.15, "tv": 298.21, "trd": NaN, "batb": [[0, 1.01, 7], [1, 1.01, 0]], "batl": NaN}, {"timestamp": 1631542121737, "ltp": 1.15, "tv": 298.21, "trd": NaN, "batb": [[0, 1.02, 1499.99], [1, 1.01, 7]], "batl": NaN}, {"timestamp": 1631542123781, "ltp": 1.15, "tv": 298.21, "trd": NaN, "batb": [[0, 1.04, 1251.37], [1, 1.02, 1499.99], [2, 1.01, 7]], "batl": NaN}, {"timestamp": 1631542126361, "ltp": 1.15, "tv": 298.21, "trd": NaN, "batb": [[0, 1.05, 50], [1, 1.04, 1251.37], [2, 1.02, 1499.99]], "batl": NaN}, {"timestamp": 1631542126985, "ltp": 1.15, "tv": 298.21, "trd": NaN, "batb": [[0, 1.05, 100]], "batl": NaN}, {"timestamp": 1631542128557, "ltp": 1.15, "tv": 298.21, "trd": NaN, "batb": NaN, "batl": [[0, 1.08, 8.52], [1, 1.41, 914.95], [2, 1.63, 8]]}, {"timestamp": 1631542129282, "ltp": 1.15, "tv": 298.21, "trd": NaN, "batb": [[1, 1.04, 1401.37]], "batl": NaN}, {"timestamp": 1631542146886, "ltp": 1.15, "tv": 298.21, "trd": NaN, "batb": NaN, "batl": [[0, 1.41, 914.95], [1, 1.63, 8], [2, 1.63, 0]]}, {"timestamp": 1631542148560, "ltp": 1.05, "tv": 308.21, "trd": [[1.05, 10]], "batb": [[0, 1.05, 95]], "batl": NaN}, {"timestamp": 1631542149762, "ltp": 1.05, "tv": 308.21, "trd": NaN, "batb": [[2, 1.01, 7]], "batl": NaN}, {"timestamp": 1631542151381, "ltp": 1.05, "tv": 308.21, "trd": NaN, "batb": [[1, 1.04, 150]], "batl": NaN}, {"timestamp": 1631542154680, "ltp": 1.05, "tv": 308.21, "trd": NaN, "batb": [[1, 1.04, 899.99]], "batl": NaN}, {"timestamp": 1631542157088, "ltp": 1.05, "tv": 308.21, "trd": NaN, "batb": [[0, 1.05, 1179.16]], "batl": NaN}, {"timestamp": 1631542164405, "ltp": 1.05, "tv": 333.78, "trd": [[1.05, 35.56]], "batb": [[0, 1.05, 1166.37]], "batl": NaN}, {"timestamp": 1631542167676, "ltp": 1.05, "tv": 333.78, "trd": NaN, "batb": [[1, 1.04, 150]], "batl": NaN}, {"timestamp": 1631542168714, "ltp": 1.05, "tv": 333.78, "trd": NaN, "batb": [[0, 1.05, 82.21]], "batl": NaN}, {"timestamp": 1631542172623, "ltp": 1.05, "tv": 333.78, "trd": NaN, "batb": [[0, 1.06, 499.99], [1, 1.05, 82.21], [2, 1.04, 150]], "batl": NaN}, {"timestamp": 1631542174188, "ltp": 1.05, "tv": 333.78, "trd": NaN, "batb": [[0, 1.08, 811.87], [1, 1.06, 499.99], [2, 1.05, 82.21]], "batl": NaN}, {"timestamp": 1631542184395, "ltp": 1.05, "tv": 333.78, "trd": NaN, "batb": [[2, 1.04, 150]], "batl": NaN}, {"timestamp": 1631542184920, "ltp": 1.05, "tv": 333.78, "trd": NaN, "batb": [[0, 1.06, 499.99], [1, 1.01, 7], [2, 1.04, 0]], "batl": [[0, 1.63, 8], [1, 1.63, 0]]}, {"timestamp": 1631542201254, "ltp": 1.05, "tv": 333.78, "trd": NaN, "batb": [[0, 1.01, 7], [1, 1.01, 0]], "batl": NaN}, {"timestamp": 1631542206276, "ltp": 1.05, "tv": 333.78, "trd": NaN, "batb": [[0, 1.12, 249.99], [1, 1.01, 7]], "batl": NaN}, {"timestamp": 1631542207638, "ltp": 1.05, "tv": 333.78, "trd": NaN, "batb": [[0, 1.12, 909.19]], "batl": [[0, 1.51, 751.18], [1, 1.63, 8]]}, {"timestamp": 1631542228591, "ltp": 1.05, "tv": 333.78, "trd": NaN, "batb": [[0, 1.01, 7], [1, 1.01, 0]], "batl": [[0, 1.63, 8], [1, 1.63, 0]]}, {"timestamp": 1631542232681, "ltp": 1.05, "tv": 333.78, "trd": NaN, "batb": [[0, 1.06, 499.99], [1, 1.01, 7]], "batl": NaN}, {"timestamp": 1631542234886, "ltp": 1.05, "tv": 333.78, "trd": NaN, "batb": [[0, 1.08, 811.87], [1, 1.06, 499.99], [2, 1.01, 7]], "batl": [[0, 1.44, 869.43], [1, 1.63, 8]]}, {"timestamp": 1631542241390, "ltp": 1.05, "tv": 333.78, "trd": NaN, "batb": [[0, 1.1, 100], [1, 1.08, 811.87], [2, 1.06, 499.99]], "batl": NaN}, {"timestamp": 1631542248901, "ltp": 1.05, "tv": 333.78, "trd": NaN, "batb": [[1, 1.06, 499.99], [2, 1.01, 7]], "batl": [[0, 1.63, 8], [1, 1.63, 0]]}, {"timestamp": 1631542249897, "ltp": 1.05, "tv": 333.78, "trd": NaN, "batb": [[1, 1.01, 7], [2, 1.01, 0]], "batl": NaN}, {"timestamp": 1631542254803, "ltp": 1.05, "tv": 333.78, "trd": NaN, "batb": [[0, 1.12, 249.99], [1, 1.1, 100], [2, 1.01, 7]], "batl": NaN}, {"timestamp": 1631542257219, "ltp": 1.05, "tv": 333.78, "trd": NaN, "batb": [[0, 1.12, 909.19], [1, 1.01, 7], [2, 1.01, 0]], "batl": [[0, 1.51, 751.18], [1, 1.63, 8]]}, {"timestamp": 1631542259208, "ltp": 1.05, "tv": 333.78, "trd": NaN, "batb": [[0, 1.14, 100], [1, 1.12, 909.19], [2, 1.01, 7]], "batl": NaN}, {"timestamp": 1631542281543, "ltp": 1.05, "tv": 333.78, "trd": NaN, "batb": [[1, 1.01, 7], [2, 1.01, 0]], "batl": [[0, 1.63, 8], [1, 1.63, 0]]}, {"timestamp": 1631542283463, "ltp": 1.05, "tv": 333.78, "trd": NaN, "batb": [[0, 1.01, 7], [1, 1.01, 0]], "batl": NaN}, {"timestamp": 1631542285762, "ltp": 1.05, "tv": 333.78, "trd": NaN, "batb": [[0, 1.06, 499.99], [1, 1.01, 7]], "batl": NaN}, {"timestamp": 1631542287436, "ltp": 1.05, "tv": 333.78, "trd": NaN, "batb": [[0, 1.06, 1507.43]], "batl": [[0, 1.41, 914.95], [1, 1.63, 8]]}, {"timestamp": 1631542296470, "ltp": 1.05, "tv": 333.78, "trd": NaN, "batb": [[0, 1.08, 150], [1, 1.06, 499.99], [2, 1.01, 7]], "batl": [[0, 1.63, 8], [1, 1.63, 0]]}, {"timestamp": 1631542297257, "ltp": 1.05, "tv": 333.78, "trd": NaN, "batb": [[0, 1.08, 200]], "batl": NaN}, {"timestamp": 1631542297875, "ltp": 1.05, "tv": 333.78, "trd": NaN, "batb": [[0, 1.08, 250]], "batl": NaN}, {"timestamp": 1631542305396, "ltp": 1.05, "tv": 333.78, "trd": NaN, "batb": [[1, 1.01, 7], [2, 1.01, 0]], "batl": NaN}, {"timestamp": 1631542306800, "ltp": 1.05, "tv": 333.78, "trd": NaN, "batb": [[0, 1.01, 7], [1, 1.01, 0]], "batl": NaN}, {"timestamp": 1631542310598, "ltp": 1.05, "tv": 333.78, "trd": NaN, "batb": [[0, 1.03, 1556.77], [1, 1.01, 7]], "batl": [[0, 1.35, 1087.64], [1, 1.63, 8]]}, {"timestamp": 1631542313503, "ltp": 1.05, "tv": 333.78, "trd": NaN, "batb": [[0, 1.04, 150], [1, 1.03, 1556.77], [2, 1.01, 7]], "batl": NaN}, {"timestamp": 1631542314603, "ltp": 1.05, "tv": 333.78, "trd": NaN, "batb": [[1, 1.03, 1656.77]], "batl": NaN}, {"timestamp": 1631542315589, "ltp": 1.05, "tv": 333.78, "trd": NaN, "batb": [[1, 1.03, 1706.77], [2, 1.02, 50]], "batl": NaN}, {"timestamp": 1631542316491, "ltp": 1.05, "tv": 333.78, "trd": NaN, "batb": [[2, 1.02, 150]], "batl": NaN}, {"timestamp": 1631542323897, "ltp": 1.05, "tv": 333.78, "trd": NaN, "batb": NaN, "batl": [[1, 1.48, 26], [2, 1.63, 8]]}, {"timestamp": 1631542333694, "ltp": 1.05, "tv": 333.78, "trd": NaN, "batb": [[0, 1.04, 200]], "batl": NaN}, {"timestamp": 1631542346502, "ltp": 1.05, "tv": 333.78, "trd": NaN, "batb": [[1, 1.03, 150]], "batl": NaN}, {"timestamp": 1631542346713, "ltp": 1.05, "tv": 333.78, "trd": NaN, "batb": [[0, 1.03, 150], [1, 1.02, 150], [2, 1.01, 157]], "batl": NaN}, {"timestamp": 1631542348121, "ltp": 1.05, "tv": 333.78, "trd": NaN, "batb": [[0, 1.02, 150], [1, 1.01, 157], [2, 1.01, 0]], "batl": NaN}, {"timestamp": 1631542352292, "ltp": 1.05, "tv": 333.78, "trd": NaN, "batb": [[1, 1.01, 4123]], "batl": NaN}, {"timestamp": 1631542360809, "ltp": 1.02, "tv": 369.95, "trd": [[1.02, 36.17]], "batb": [[0, 1.02, 131.91]], "batl": NaN}, {"timestamp": 1631542363585, "ltp": 1.02, "tv": 369.95, "trd": NaN, "batb": [[1, 1.01, 157]], "batl": [[0, 1.48, 26], [1, 1.63, 8], [2, 1.63, 0]]}, {"timestamp": 1631542372413, "ltp": 1.02, "tv": 369.95, "trd": NaN, "batb": [[0, 1.01, 157], [1, 1.01, 0]], "batl": NaN}, {"timestamp": 1631542376506, "ltp": 1.02, "tv": 369.95, "trd": NaN, "batb": NaN, "batl": [[0, 1.28, 1326.95], [1, 1.48, 26], [2, 1.63, 8]]}, {"timestamp": 1631542379518, "ltp": 1.02, "tv": 369.95, "trd": NaN, "batb": [[0, 1.01, 357]], "batl": NaN}, {"timestamp": 1631542384837, "ltp": 1.02, "tv": 369.95, "trd": NaN, "batb": NaN, "batl": [[0, 1.02, 1000], [1, 1.28, 1326.95], [2, 1.48, 26]]}, {"timestamp": 1631542391042, "ltp": 1.02, "tv": 369.95, "trd": NaN, "batb": NaN, "batl": [[1, 1.48, 26], [2, 1.63, 8]]}, {"timestamp": 1631542393968, "ltp": 1.02, "tv": 369.95, "trd": NaN, "batb": [[0, 1.01, 7]], "batl": NaN}, {"timestamp": 1631542399577, "ltp": 1.02, "tv": 369.95, "trd": NaN, "batb": NaN, "batl": [[0, 1.48, 26], [1, 1.63, 8], [2, 1.63, 0]]}, {"timestamp": 1631542402666, "ltp": 1.02, "tv": 369.95, "trd": NaN, "batb": NaN, "batl": [[0, 1.27, 1412.67], [1, 1.48, 26], [2, 1.63, 8]]}, {"timestamp": 1631542406384, "ltp": 1.01, "tv": 383.94, "trd": [[1.01, 13.99]], "batb": NaN, "batl": [[0, 1.01, 10.04], [1, 1.27, 1412.67], [2, 1.48, 26]]}, {"timestamp": 1631542408374, "ltp": 1.01, "tv": 383.94, "trd": NaN, "batb": NaN, "batl": [[0, 1.01, 1010.04]]}, {"timestamp": 1631542415287, "ltp": 1.01, "tv": 383.94, "trd": NaN, "batb": NaN, "batl": [[1, 1.48, 26], [2, 1.63, 8]]}, {"timestamp": 1631542431121, "ltp": 1.01, "tv": 383.94, "trd": NaN, "batb": NaN, "batl": [[1, 1.28, 1366.24], [2, 1.48, 26]]}, {"timestamp": 1631542444744, "ltp": 1.01, "tv": 383.94, "trd": NaN, "batb": NaN, "batl": [[0, 1.01, 10.04]]}, {"timestamp": 1631542451943, "ltp": 1.01, "tv": 383.94, "trd": NaN, "batb": NaN, "batl": [[1, 1.48, 26], [2, 1.63, 8]]}, {"timestamp": 1631542465481, "ltp": 1.01, "tv": 383.94, "trd": NaN, "batb": NaN, "batl": [[1, 1.28, 1352.39], [2, 1.48, 26]]}, {"timestamp": 1631542467061, "ltp": 1.01, "tv": 383.94, "trd": NaN, "batb": NaN, "batl": [[1, 1.48, 26], [2, 1.63, 8]]}, {"timestamp": 1631542477794, "ltp": 1.01, "tv": 383.94, "trd": NaN, "batb": NaN, "batl": [[1, 1.3, 1265.64], [2, 1.48, 26]]}, {"timestamp": 1631542480202, "ltp": 1.01, "tv": 404.03, "trd": [[1.01, 34.08]], "batb": [[0, 1.01, 1989.95]], "batl": [[0, 1.3, 1265.64], [1, 1.48, 26], [2, 1.63, 8]]}, {"timestamp": 1631542490483, "ltp": 1.01, "tv": 404.03, "trd": NaN, "batb": NaN, "batl": [[0, 1.48, 26], [1, 1.63, 8], [2, 1.63, 0]]}]}, {"runnerId": 9628072, "odds": [{"timestamp": 1631525394886, "ltp": 1.66, "tv": 6.0, "trd": [[1.66, 6]], "batb": NaN, "batl": NaN}, {"timestamp": 1631525418590, "ltp": 1.66, "tv": 6.0, "trd": NaN, "batb": [[0, 1.64, 3], [1, 1.57, 54.95], [2, 1.18, 246.5]], "batl": NaN}, {"timestamp": 1631525653745, "ltp": 1.66, "tv": 6.0, "trd": NaN, "batb": [[2, 1.16, 15.98]], "batl": NaN}, {"timestamp": 1631525663618, "ltp": 1.66, "tv": 6.0, "trd": NaN, "batb": [[2, 1.28, 158.46]], "batl": NaN}, {"timestamp": 1631525681360, "ltp": 1.66, "tv": 6.0, "trd": NaN, "batb": [[0, 1.57, 54.95], [1, 1.28, 158.46], [2, 1.16, 15.98]], "batl": NaN}, {"timestamp": 1631525703378, "ltp": 1.66, "tv": 6.0, "trd": NaN, "batb": NaN, "batl": [[0, 1.6, 3], [1, 1.67, 10.53], [2, 2.16, 2.66]]}, {"timestamp": 1631525934141, "ltp": 1.66, "tv": 6.0, "trd": NaN, "batb": NaN, "batl": [[0, 1.67, 10.53], [1, 2.16, 2.66], [2, 2.4, 44.02]]}, {"timestamp": 1631525942745, "ltp": 1.66, "tv": 6.0, "trd": NaN, "batb": [[0, 1.61, 12], [1, 1.57, 54.95], [2, 1.28, 158.46]], "batl": NaN}, {"timestamp": 1631525964603, "ltp": 1.66, "tv": 6.0, "trd": NaN, "batb": [[0, 1.63, 4], [1, 1.61, 12], [2, 1.57, 54.95]], "batl": NaN}, {"timestamp": 1631525969416, "ltp": 1.66, "tv": 6.0, "trd": NaN, "batb": [[1, 1.57, 54.95], [2, 1.28, 158.46]], "batl": NaN}, {"timestamp": 1631525977514, "ltp": 1.66, "tv": 12.0, "trd": [[1.66, 12]], "batb": NaN, "batl": NaN}, {"timestamp": 1631525979533, "ltp": 1.66, "tv": 12.0, "trd": NaN, "batb": [[0, 1.66, 3], [1, 1.63, 4], [2, 1.57, 54.95]], "batl": NaN}, {"timestamp": 1631526394807, "ltp": 1.66, "tv": 12.0, "trd": NaN, "batb": [[0, 1.63, 4], [1, 1.57, 54.95], [2, 1.28, 158.46]], "batl": NaN}, {"timestamp": 1631526403625, "ltp": 1.66, "tv": 12.0, "trd": NaN, "batb": NaN, "batl": [[0, 1.65, 5], [1, 1.67, 10.53], [2, 2.16, 2.66]]}, {"timestamp": 1631526416858, "ltp": 1.66, "tv": 12.0, "trd": NaN, "batb": [[0, 1.57, 54.95], [1, 1.28, 158.46], [2, 1.16, 15.98]], "batl": NaN}, {"timestamp": 1631526422359, "ltp": 1.66, "tv": 12.0, "trd": NaN, "batb": NaN, "batl": [[0, 1.59, 3], [1, 1.65, 5], [2, 1.67, 10.53]]}, {"timestamp": 1631526676456, "ltp": 1.66, "tv": 12.0, "trd": NaN, "batb": [[0, 1.6, 1], [1, 1.57, 54.95], [2, 1.28, 158.46]], "batl": [[0, 1.65, 5], [1, 1.67, 10.53], [2, 2.16, 2.66]]}, {"timestamp": 1631526794149, "ltp": 1.66, "tv": 12.0, "trd": NaN, "batb": [[0, 1.63, 3], [1, 1.6, 1], [2, 1.57, 54.95]], "batl": NaN}, {"timestamp": 1631527013025, "ltp": 1.66, "tv": 12.0, "trd": NaN, "batb": [[1, 1.57, 54.95], [2, 1.28, 158.46]], "batl": NaN}, {"timestamp": 1631527466186, "ltp": 1.66, "tv": 12.0, "trd": NaN, "batb": [[0, 1.57, 54.95], [1, 1.28, 158.46], [2, 1.16, 15.98]], "batl": NaN}, {"timestamp": 1631527473804, "ltp": 1.66, "tv": 12.0, "trd": NaN, "batb": NaN, "batl": [[0, 1.6, 3], [1, 1.65, 5], [2, 1.67, 10.53]]}, {"timestamp": 1631529150482, "ltp": 1.66, "tv": 12.0, "trd": NaN, "batb": NaN, "batl": [[0, 1.59, 3], [1, 1.6, 3], [2, 1.65, 5]]}, {"timestamp": 1631529390450, "ltp": 1.66, "tv": 12.0, "trd": NaN, "batb": NaN, "batl": [[0, 1.6, 3], [1, 1.65, 5], [2, 1.67, 10.53]]}, {"timestamp": 1631529848819, "ltp": 1.57, "tv": 86.88, "trd": [[1.57, 74.89]], "batb": [[0, 1.57, 17.51]], "batl": NaN}, {"timestamp": 1631529854001, "ltp": 1.57, "tv": 86.88, "trd": NaN, "batb": [[0, 1.57, 54.95]], "batl": NaN}, {"timestamp": 1631529861618, "ltp": 1.57, "tv": 86.88, "trd": NaN, "batb": NaN, "batl": [[1, 1.65, 15.53], [2, 2.16, 2.66]]}, {"timestamp": 1631530627308, "ltp": 1.57, "tv": 86.88, "trd": NaN, "batb": [[0, 1.57, 73.27]], "batl": NaN}, {"timestamp": 1631531634100, "ltp": 1.57, "tv": 86.82, "trd": [[1.57, 74.82]], "batb": [[1, 1.28, 158.31], [2, 1.16, 15.95]], "batl": [[1, 1.65, 15.51], [2, 2.16, 2.66]]}, {"timestamp": 1631533201264, "ltp": 1.57, "tv": 86.82, "trd": NaN, "batb": [[1, 1.52, 24.57], [2, 1.28, 158.31]], "batl": NaN}, {"timestamp": 1631535063563, "ltp": 1.57, "tv": 86.82, "trd": NaN, "batb": [[1, 1.55, 3.31], [2, 1.52, 24.57]], "batl": NaN}, {"timestamp": 1631535092614, "ltp": 1.57, "tv": 86.82, "trd": NaN, "batb": [[2, 1.52, 27.23]], "batl": NaN}, {"timestamp": 1631536601687, "ltp": 1.57, "tv": 89.34, "trd": [[1.57, 77.34]], "batb": [[0, 1.57, 70.75]], "batl": NaN}, {"timestamp": 1631536603257, "ltp": 1.57, "tv": 89.34, "trd": NaN, "batb": [[0, 1.57, 73.27]], "batl": NaN}, {"timestamp": 1631538171871, "ltp": 1.57, "tv": 89.32, "trd": [[1.57, 77.33]], "batb": [[0, 1.01, 7], [1, 1.55, 0], [2, 1.52, 0]], "batl": [[0, 1.65, 10.5], [1, 1.65, 0], [2, 2.16, 0]]}, {"timestamp": 1631538177079, "ltp": 1.57, "tv": 89.32, "trd": NaN, "batb": [[0, 1.55, 54.54], [1, 1.01, 7]], "batl": NaN}, {"timestamp": 1631538459455, "ltp": 1.57, "tv": 89.32, "trd": NaN, "batb": [[0, 1.01, 7], [1, 1.01, 0]], "batl": NaN}, {"timestamp": 1631538464084, "ltp": 1.57, "tv": 89.32, "trd": NaN, "batb": [[0, 1.58, 51.72], [1, 1.01, 7]], "batl": NaN}, {"timestamp": 1631538482381, "ltp": 1.57, "tv": 89.32, "trd": NaN, "batb": [[0, 1.01, 7], [1, 1.01, 0]], "batl": NaN}, {"timestamp": 1631538497504, "ltp": 1.65, "tv": 99.82, "trd": [[1.65, 10.5]], "batb": NaN, "batl": NaN}, {"timestamp": 1631538502410, "ltp": 1.65, "tv": 99.82, "trd": NaN, "batb": [[0, 1.65, 46.15], [1, 1.01, 7]], "batl": NaN}, {"timestamp": 1631538518723, "ltp": 1.65, "tv": 99.82, "trd": NaN, "batb": [[0, 1.01, 7], [1, 1.01, 0]], "batl": NaN}, {"timestamp": 1631538523633, "ltp": 1.65, "tv": 99.82, "trd": NaN, "batb": [[0, 1.73, 41.09], [1, 1.01, 7]], "batl": NaN}, {"timestamp": 1631538548264, "ltp": 1.65, "tv": 99.82, "trd": NaN, "batb": [[0, 1.01, 7], [1, 1.01, 0]], "batl": NaN}, {"timestamp": 1631538553285, "ltp": 1.65, "tv": 99.82, "trd": NaN, "batb": [[0, 1.85, 35.29], [1, 1.01, 7]], "batl": NaN}, {"timestamp": 1631538583596, "ltp": 1.65, "tv": 99.82, "trd": NaN, "batb": [[0, 1.01, 7], [1, 1.01, 0]], "batl": NaN}, {"timestamp": 1631538588506, "ltp": 1.65, "tv": 99.82, "trd": NaN, "batb": [[0, 1.73, 41.09], [1, 1.01, 7]], "batl": NaN}, {"timestamp": 1631538606565, "ltp": 1.65, "tv": 99.82, "trd": NaN, "batb": [[0, 1.01, 7], [1, 1.01, 0]], "batl": NaN}, {"timestamp": 1631538611428, "ltp": 1.65, "tv": 99.82, "trd": NaN, "batb": [[0, 1.65, 46.15], [1, 1.01, 7]], "batl": NaN}, {"timestamp": 1631538640642, "ltp": 1.65, "tv": 99.82, "trd": NaN, "batb": [[0, 1.01, 7], [1, 1.01, 0]], "batl": NaN}, {"timestamp": 1631538645466, "ltp": 1.65, "tv": 99.82, "trd": NaN, "batb": [[0, 1.78, 38.46], [1, 1.01, 7]], "batl": NaN}, {"timestamp": 1631538722890, "ltp": 1.65, "tv": 99.82, "trd": NaN, "batb": [[0, 1.01, 7], [1, 1.01, 0]], "batl": NaN}, {"timestamp": 1631538727779, "ltp": 1.65, "tv": 99.82, "trd": NaN, "batb": [[0, 1.88, 34.09], [1, 1.01, 7]], "batl": NaN}, {"timestamp": 1631538749206, "ltp": 1.65, "tv": 99.82, "trd": NaN, "batb": [[0, 1.01, 7], [1, 1.01, 0]], "batl": NaN}, {"timestamp": 1631538754069, "ltp": 1.65, "tv": 99.82, "trd": NaN, "batb": [[0, 1.78, 38.46], [1, 1.01, 7]], "batl": NaN}, {"timestamp": 1631538780918, "ltp": 1.65, "tv": 99.82, "trd": NaN, "batb": [[0, 1.01, 7], [1, 1.01, 0]], "batl": NaN}, {"timestamp": 1631538785817, "ltp": 1.65, "tv": 99.82, "trd": NaN, "batb": [[0, 1.65, 46.15], [1, 1.01, 7]], "batl": NaN}, {"timestamp": 1631538803162, "ltp": 1.65, "tv": 99.82, "trd": NaN, "batb": [[0, 1.01, 7], [1, 1.01, 0]], "batl": NaN}, {"timestamp": 1631538808048, "ltp": 1.65, "tv": 99.82, "trd": NaN, "batb": [[0, 1.6, 49.99], [1, 1.01, 7]], "batl": NaN}, {"timestamp": 1631538856975, "ltp": 1.65, "tv": 99.82, "trd": NaN, "batb": [[0, 1.01, 7], [1, 1.01, 0]], "batl": NaN}, {"timestamp": 1631538861910, "ltp": 1.65, "tv": 99.82, "trd": NaN, "batb": [[0, 1.55, 54.54], [1, 1.01, 7]], "batl": NaN}, {"timestamp": 1631538896646, "ltp": 1.65, "tv": 99.82, "trd": NaN, "batb": [[0, 1.01, 7], [1, 1.01, 0]], "batl": NaN}, {"timestamp": 1631538901440, "ltp": 1.65, "tv": 99.82, "trd": NaN, "batb": [[0, 1.48, 62.5], [1, 1.01, 7]], "batl": NaN}, {"timestamp": 1631538920025, "ltp": 1.65, "tv": 99.82, "trd": NaN, "batb": [[0, 1.01, 7], [1, 1.01, 0]], "batl": NaN}, {"timestamp": 1631538925037, "ltp": 1.65, "tv": 99.82, "trd": NaN, "batb": [[0, 1.45, 66.66], [1, 1.01, 7]], "batl": NaN}, {"timestamp": 1631538930083, "ltp": 1.65, "tv": 99.82, "trd": NaN, "batb": [[0, 1.01, 7], [1, 1.01, 0]], "batl": NaN}, {"timestamp": 1631538934986, "ltp": 1.65, "tv": 99.82, "trd": NaN, "batb": [[0, 1.55, 54.54], [1, 1.01, 7]], "batl": NaN}, {"timestamp": 1631538955662, "ltp": 1.65, "tv": 99.82, "trd": NaN, "batb": [[0, 1.01, 7], [1, 1.01, 0]], "batl": NaN}, {"timestamp": 1631538960688, "ltp": 1.65, "tv": 99.82, "trd": NaN, "batb": [[0, 1.63, 47.61], [1, 1.01, 7]], "batl": NaN}, {"timestamp": 1631538976825, "ltp": 1.65, "tv": 99.82, "trd": NaN, "batb": [[0, 1.01, 7], [1, 1.01, 0]], "batl": NaN}, {"timestamp": 1631538981683, "ltp": 1.65, "tv": 99.82, "trd": NaN, "batb": [[0, 1.71, 42.25], [1, 1.01, 7]], "batl": NaN}, {"timestamp": 1631539014673, "ltp": 1.65, "tv": 99.82, "trd": NaN, "batb": [[0, 1.01, 7], [1, 1.01, 0]], "batl": NaN}, {"timestamp": 1631539019645, "ltp": 1.65, "tv": 99.82, "trd": NaN, "batb": [[0, 1.63, 47.61], [1, 1.01, 7]], "batl": NaN}, {"timestamp": 1631539047374, "ltp": 1.65, "tv": 99.82, "trd": NaN, "batb": [[0, 1.01, 7], [1, 1.01, 0]], "batl": NaN}, {"timestamp": 1631539052302, "ltp": 1.65, "tv": 99.82, "trd": NaN, "batb": [[0, 1.73, 41.09], [1, 1.01, 7]], "batl": NaN}, {"timestamp": 1631539066398, "ltp": 1.73, "tv": 182.01, "trd": [[1.73, 82.18]], "batb": [[0, 1.01, 7], [1, 1.01, 0]], "batl": [[0, 1.73, 31.9]]}, {"timestamp": 1631539071632, "ltp": 1.73, "tv": 182.01, "trd": NaN, "batb": [[0, 1.66, 45.45], [1, 1.01, 7]], "batl": NaN}, {"timestamp": 1631539087641, "ltp": 1.73, "tv": 245.79, "trd": [[1.73, 145.97]], "batb": NaN, "batl": [[0, 1.73, 0.01]]}, {"timestamp": 1631539163354, "ltp": 1.73, "tv": 245.79, "trd": NaN, "batb": [[0, 1.01, 7], [1, 1.01, 0]], "batl": NaN}, {"timestamp": 1631539168382, "ltp": 1.73, "tv": 245.79, "trd": NaN, "batb": [[0, 1.65, 46.15], [1, 1.01, 7]], "batl": NaN}, {"timestamp": 1631539195035, "ltp": 1.73, "tv": 245.79, "trd": NaN, "batb": [[0, 1.01, 7], [1, 1.01, 0]], "batl": NaN}, {"timestamp": 1631539199513, "ltp": 1.73, "tv": 245.79, "trd": NaN, "batb": [[0, 1.58, 51.72], [1, 1.01, 7]], "batl": NaN}, {"timestamp": 1631539217034, "ltp": 1.73, "tv": 245.79, "trd": NaN, "batb": [[0, 1.01, 7], [1, 1.01, 0]], "batl": NaN}, {"timestamp": 1631539222086, "ltp": 1.73, "tv": 245.79, "trd": NaN, "batb": [[0, 1.51, 58.82], [1, 1.01, 7]], "batl": NaN}, {"timestamp": 1631539238907, "ltp": 1.73, "tv": 245.79, "trd": NaN, "batb": [[0, 1.01, 7], [1, 1.01, 0]], "batl": NaN}, {"timestamp": 1631539243807, "ltp": 1.73, "tv": 245.79, "trd": NaN, "batb": [[0, 1.48, 62.5], [1, 1.01, 7]], "batl": NaN}, {"timestamp": 1631539279020, "ltp": 1.73, "tv": 245.79, "trd": NaN, "batb": [[0, 1.01, 7], [1, 1.01, 0]], "batl": NaN}, {"timestamp": 1631539284066, "ltp": 1.73, "tv": 245.79, "trd": NaN, "batb": [[0, 1.42, 71.42], [1, 1.01, 7]], "batl": NaN}, {"timestamp": 1631539304848, "ltp": 1.73, "tv": 245.79, "trd": NaN, "batb": [[0, 1.58, 3], [1, 1.42, 71.42], [2, 1.01, 7]], "batl": NaN}, {"timestamp": 1631539308898, "ltp": 1.73, "tv": 245.79, "trd": NaN, "batb": [[1, 1.01, 7], [2, 1.01, 0]], "batl": NaN}, {"timestamp": 1631539313592, "ltp": 1.58, "tv": 248.79, "trd": [[1.58, 3]], "batb": [[0, 1.38, 78.94]], "batl": NaN}, {"timestamp": 1631539324200, "ltp": 1.55, "tv": 251.79, "trd": [[1.55, 3]], "batb": NaN, "batl": NaN}, {"timestamp": 1631539331601, "ltp": 1.55, "tv": 254.79, "trd": [[1.55, 6]], "batb": NaN, "batl": NaN}, {"timestamp": 1631539343033, "ltp": 1.55, "tv": 257.79, "trd": [[1.55, 9]], "batb": NaN, "batl": NaN}, {"timestamp": 1631539345903, "ltp": 1.55, "tv": 257.79, "trd": NaN, "batb": [[0, 1.01, 7], [1, 1.01, 0]], "batl": NaN}, {"timestamp": 1631539349808, "ltp": 1.55, "tv": 257.79, "trd": NaN, "batb": [[0, 1.64, 3], [1, 1.01, 7]], "batl": NaN}, {"timestamp": 1631539350843, "ltp": 1.55, "tv": 257.79, "trd": NaN, "batb": [[1, 1.34, 88.23], [2, 1.01, 7]], "batl": NaN}, {"timestamp": 1631539353313, "ltp": 1.64, "tv": 260.79, "trd": [[1.64, 3]], "batb": [[0, 1.34, 88.23], [1, 1.01, 7], [2, 1.01, 0]], "batl": NaN}, {"timestamp": 1631539358513, "ltp": 1.64, "tv": 260.79, "trd": NaN, "batb": [[0, 1.01, 7], [1, 1.01, 0]], "batl": NaN}, {"timestamp": 1631539363423, "ltp": 1.64, "tv": 260.79, "trd": NaN, "batb": [[0, 1.38, 78.94], [1, 1.01, 7]], "batl": NaN}, {"timestamp": 1631539384094, "ltp": 1.64, "tv": 260.79, "trd": NaN, "batb": [[0, 1.01, 7], [1, 1.01, 0]], "batl": NaN}, {"timestamp": 1631539389086, "ltp": 1.64, "tv": 260.79, "trd": NaN, "batb": [[0, 1.48, 62.5], [1, 1.01, 7]], "batl": NaN}, {"timestamp": 1631539412392, "ltp": 1.64, "tv": 260.79, "trd": NaN, "batb": NaN, "batl": [[0, 1.52, 3]]}, {"timestamp": 1631539424400, "ltp": 1.64, "tv": 260.79, "trd": NaN, "batb": [[0, 1.01, 7], [1, 1.01, 0]], "batl": NaN}, {"timestamp": 1631539440219, "ltp": 1.52, "tv": 266.79, "trd": [[1.52, 6]], "batb": [[0, 1.52, 26.49], [1, 1.01, 7]], "batl": NaN}, {"timestamp": 1631539440643, "ltp": 1.52, "tv": 266.79, "trd": NaN, "batb": [[0, 1.01, 7], [1, 1.01, 0]], "batl": NaN}, {"timestamp": 1631539445420, "ltp": 1.52, "tv": 266.79, "trd": NaN, "batb": [[0, 1.58, 51.72], [1, 1.01, 7]], "batl": NaN}, {"timestamp": 1631539453154, "ltp": 1.52, "tv": 266.79, "trd": NaN, "batb": [[0, 1.01, 7], [1, 1.01, 0]], "batl": NaN}, {"timestamp": 1631539457883, "ltp": 1.52, "tv": 266.79, "trd": NaN, "batb": [[0, 1.71, 42.25], [1, 1.01, 7]], "batl": NaN}, {"timestamp": 1631539472594, "ltp": 1.71, "tv": 270.79, "trd": [[1.71, 4]], "batb": [[0, 1.01, 7], [1, 1.01, 0]], "batl": [[0, 1.71, 2]]}, {"timestamp": 1631539477598, "ltp": 1.71, "tv": 278.79, "trd": [[1.71, 12]], "batb": NaN, "batl": NaN}, {"timestamp": 1631539482502, "ltp": 1.71, "tv": 278.79, "trd": NaN, "batb": [[0, 1.71, 42.25], [1, 1.01, 7]], "batl": NaN}, {"timestamp": 1631539483870, "ltp": 1.71, "tv": 278.79, "trd": NaN, "batb": NaN, "batl": [[0, 1.85, 6]]}, {"timestamp": 1631539539067, "ltp": 1.71, "tv": 278.79, "trd": NaN, "batb": NaN, "batl": [[0, 1.74, 3], [1, 1.85, 6]]}, {"timestamp": 1631539553917, "ltp": 1.71, "tv": 278.79, "trd": NaN, "batb": NaN, "batl": [[0, 1.85, 6], [1, 1.85, 0]]}, {"timestamp": 1631539569270, "ltp": 1.71, "tv": 278.79, "trd": NaN, "batb": [[0, 1.77, 3], [1, 1.71, 42.25], [2, 1.01, 7]], "batl": NaN}, {"timestamp": 1631539576979, "ltp": 1.71, "tv": 278.79, "trd": NaN, "batb": [[1, 1.01, 7], [2, 1.01, 0]], "batl": NaN}, {"timestamp": 1631539579421, "ltp": 1.71, "tv": 278.79, "trd": NaN, "batb": [[0, 1.87, 3], [1, 1.77, 3], [2, 1.01, 7]], "batl": NaN}, {"timestamp": 1631539582002, "ltp": 1.71, "tv": 278.79, "trd": NaN, "batb": [[1, 1.85, 35.29], [2, 1.77, 3]], "batl": NaN}, {"timestamp": 1631539606439, "ltp": 1.71, "tv": 278.79, "trd": NaN, "batb": [[1, 1.77, 3], [2, 1.01, 7]], "batl": NaN}, {"timestamp": 1631539611449, "ltp": 1.71, "tv": 278.79, "trd": NaN, "batb": [[0, 1.98, 30.61], [1, 1.87, 3], [2, 1.77, 3]], "batl": NaN}, {"timestamp": 1631539630059, "ltp": 1.71, "tv": 278.79, "trd": NaN, "batb": [[0, 1.87, 3], [1, 1.77, 3], [2, 1.01, 7]], "batl": NaN}, {"timestamp": 1631539635447, "ltp": 1.71, "tv": 278.79, "trd": NaN, "batb": [[0, 1.88, 34.09], [1, 1.87, 3], [2, 1.77, 3]], "batl": NaN}, {"timestamp": 1631539685695, "ltp": 1.71, "tv": 278.79, "trd": NaN, "batb": [[0, 1.87, 3], [1, 1.77, 3], [2, 1.01, 7]], "batl": NaN}, {"timestamp": 1631539690696, "ltp": 1.71, "tv": 278.79, "trd": NaN, "batb": [[0, 2.06, 28.3], [1, 1.87, 3], [2, 1.77, 3]], "batl": NaN}, {"timestamp": 1631539711084, "ltp": 1.71, "tv": 278.79, "trd": NaN, "batb": [[0, 1.87, 3], [1, 1.77, 3], [2, 1.01, 7]], "batl": NaN}, {"timestamp": 1631539716040, "ltp": 1.71, "tv": 278.79, "trd": NaN, "batb": [[0, 2.1, 27.27], [1, 1.87, 3], [2, 1.77, 3]], "batl": NaN}, {"timestamp": 1631539757092, "ltp": 1.71, "tv": 278.79, "trd": NaN, "batb": [[0, 1.87, 3], [1, 1.77, 3], [2, 1.01, 7]], "batl": NaN}, {"timestamp": 1631539761778, "ltp": 1.71, "tv": 278.79, "trd": NaN, "batb": [[0, 2.26, 23.8], [1, 1.87, 3], [2, 1.77, 3]], "batl": NaN}, {"timestamp": 1631539792297, "ltp": 1.71, "tv": 278.79, "trd": NaN, "batb": [[0, 1.87, 3], [1, 1.77, 3], [2, 1.01, 7]], "batl": NaN}, {"timestamp": 1631539797311, "ltp": 2.3, "tv": 281.11, "trd": [[2.3, 2.32]], "batb": [[0, 2.42, 18.8], [1, 1.87, 3], [2, 1.77, 3]], "batl": NaN}, {"timestamp": 1631539797726, "ltp": 2.3, "tv": 281.11, "trd": NaN, "batb": [[0, 1.87, 3], [1, 1.77, 3], [2, 1.01, 7]], "batl": NaN}, {"timestamp": 1631539802538, "ltp": 2.3, "tv": 281.11, "trd": NaN, "batb": [[0, 2.42, 21.12], [1, 1.87, 3], [2, 1.77, 3]], "batl": NaN}, {"timestamp": 1631539830480, "ltp": 2.3, "tv": 281.11, "trd": NaN, "batb": [[0, 1.87, 3], [1, 1.77, 3], [2, 1.01, 7]], "batl": NaN}, {"timestamp": 1631539835510, "ltp": 2.3, "tv": 281.11, "trd": NaN, "batb": [[0, 2.58, 18.98], [1, 1.87, 3], [2, 1.77, 3]], "batl": NaN}, {"timestamp": 1631539847731, "ltp": 2.3, "tv": 281.11, "trd": NaN, "batb": [[0, 1.87, 3], [1, 1.77, 3], [2, 1.01, 7]], "batl": NaN}, {"timestamp": 1631539852635, "ltp": 2.3, "tv": 281.11, "trd": NaN, "batb": [[0, 2.66, 18.07], [1, 1.87, 3], [2, 1.77, 3]], "batl": NaN}, {"timestamp": 1631539864842, "ltp": 2.3, "tv": 281.11, "trd": NaN, "batb": [[0, 1.87, 3], [1, 1.77, 3], [2, 1.01, 7]], "batl": NaN}, {"timestamp": 1631539869851, "ltp": 2.3, "tv": 281.11, "trd": NaN, "batb": [[0, 2.84, 16.3], [1, 1.87, 3], [2, 1.77, 3]], "batl": NaN}, {"timestamp": 1631539984022, "ltp": 2.3, "tv": 281.11, "trd": NaN, "batb": [[0, 1.87, 3], [1, 1.77, 3], [2, 1.01, 7]], "batl": NaN}, {"timestamp": 1631539989006, "ltp": 2.3, "tv": 281.11, "trd": NaN, "batb": [[0, 3, 15], [1, 1.87, 3], [2, 1.77, 3]], "batl": NaN}, {"timestamp": 1631540114678, "ltp": 2.3, "tv": 281.11, "trd": NaN, "batb": [[0, 1.87, 3], [1, 1.77, 3], [2, 1.01, 7]], "batl": NaN}, {"timestamp": 1631540119671, "ltp": 2.3, "tv": 281.11, "trd": NaN, "batb": [[0, 3.3, 13.04], [1, 1.87, 3], [2, 1.77, 3]], "batl": NaN}, {"timestamp": 1631540233947, "ltp": 2.3, "tv": 281.11, "trd": NaN, "batb": [[0, 1.87, 3], [1, 1.77, 3], [2, 1.01, 7]], "batl": NaN}, {"timestamp": 1631540238838, "ltp": 2.3, "tv": 281.11, "trd": NaN, "batb": [[0, 3, 15], [1, 1.87, 3], [2, 1.77, 3]], "batl": NaN}, {"timestamp": 1631540255581, "ltp": 2.3, "tv": 281.11, "trd": NaN, "batb": [[0, 1.87, 3], [1, 1.77, 3], [2, 1.01, 7]], "batl": NaN}, {"timestamp": 1631540260509, "ltp": 2.3, "tv": 281.11, "trd": NaN, "batb": [[0, 3.15, 13.95], [1, 1.87, 3], [2, 1.77, 3]], "batl": NaN}, {"timestamp": 1631540276087, "ltp": 2.3, "tv": 281.11, "trd": NaN, "batb": [[0, 1.87, 3], [1, 1.77, 3], [2, 1.01, 7]], "batl": NaN}, {"timestamp": 1631540281099, "ltp": 2.3, "tv": 281.11, "trd": NaN, "batb": [[0, 3.7, 11.11], [1, 1.87, 3], [2, 1.77, 3]], "batl": NaN}, {"timestamp": 1631540291316, "ltp": 2.3, "tv": 281.11, "trd": NaN, "batb": [[0, 1.87, 3], [1, 1.77, 3], [2, 1.01, 7]], "batl": NaN}, {"timestamp": 1631540296316, "ltp": 2.3, "tv": 281.11, "trd": NaN, "batb": [[0, 3.4, 12.5], [1, 1.87, 3], [2, 1.77, 3]], "batl": NaN}, {"timestamp": 1631540310967, "ltp": 2.3, "tv": 281.11, "trd": NaN, "batb": [[0, 1.87, 3], [1, 1.77, 3], [2, 1.01, 7]], "batl": NaN}, {"timestamp": 1631540315554, "ltp": 2.3, "tv": 281.11, "trd": NaN, "batb": [[0, 4, 10], [1, 1.87, 3], [2, 1.77, 3]], "batl": NaN}, {"timestamp": 1631540336635, "ltp": 4.0, "tv": 281.43, "trd": [[4, 0.32]], "batb": [[0, 4, 9.84]], "batl": NaN}, {"timestamp": 1631540336846, "ltp": 4.0, "tv": 281.43, "trd": NaN, "batb": [[0, 1.87, 3], [1, 1.77, 3], [2, 1.01, 7]], "batl": NaN}, {"timestamp": 1631540341831, "ltp": 4.0, "tv": 281.43, "trd": NaN, "batb": [[0, 4, 10], [1, 1.87, 3], [2, 1.77, 3]], "batl": NaN}, {"timestamp": 1631540360958, "ltp": 4.0, "tv": 281.43, "trd": NaN, "batb": [[0, 1.87, 3], [1, 1.77, 3], [2, 1.01, 7]], "batl": NaN}, {"timestamp": 1631540365981, "ltp": 4.0, "tv": 281.43, "trd": NaN, "batb": [[0, 3.7, 11.11], [1, 1.87, 3], [2, 1.77, 3]], "batl": NaN}, {"timestamp": 1631540394836, "ltp": 4.0, "tv": 281.43, "trd": NaN, "batb": [[0, 1.87, 3], [1, 1.77, 3], [2, 1.01, 7]], "batl": NaN}, {"timestamp": 1631540399829, "ltp": 4.0, "tv": 281.43, "trd": NaN, "batb": [[0, 4.1, 10], [1, 1.87, 3], [2, 1.77, 3]], "batl": NaN}, {"timestamp": 1631540472523, "ltp": 4.0, "tv": 281.43, "trd": NaN, "batb": [[0, 1.87, 3], [1, 1.77, 3], [2, 1.01, 7]], "batl": NaN}, {"timestamp": 1631540482505, "ltp": 4.0, "tv": 281.43, "trd": NaN, "batb": [[0, 4.1, 10], [1, 1.87, 3], [2, 1.77, 3]], "batl": NaN}, {"timestamp": 1631540482818, "ltp": 4.0, "tv": 281.43, "trd": NaN, "batb": [[0, 1.87, 3], [1, 1.77, 3], [2, 1.01, 7]], "batl": NaN}, {"timestamp": 1631540487728, "ltp": 4.0, "tv": 281.43, "trd": NaN, "batb": [[0, 3.7, 11.11], [1, 1.87, 3], [2, 1.77, 3]], "batl": NaN}, {"timestamp": 1631540499113, "ltp": 4.0, "tv": 281.43, "trd": NaN, "batb": [[0, 1.87, 3], [1, 1.77, 3], [2, 1.01, 7]], "batl": NaN}, {"timestamp": 1631540504050, "ltp": 4.0, "tv": 281.43, "trd": NaN, "batb": [[0, 3.3, 13.04], [1, 1.87, 3], [2, 1.77, 3]], "batl": NaN}, {"timestamp": 1631540514415, "ltp": 4.0, "tv": 281.43, "trd": NaN, "batb": [[0, 1.87, 3], [1, 1.77, 3], [2, 1.01, 7]], "batl": NaN}, {"timestamp": 1631540519408, "ltp": 4.0, "tv": 281.43, "trd": NaN, "batb": [[0, 3.7, 11.11], [1, 1.87, 3], [2, 1.77, 3]], "batl": NaN}, {"timestamp": 1631540545220, "ltp": 4.0, "tv": 281.43, "trd": NaN, "batb": [[0, 1.87, 3], [1, 1.77, 3], [2, 1.01, 7]], "batl": NaN}, {"timestamp": 1631540550150, "ltp": 4.0, "tv": 281.43, "trd": NaN, "batb": [[0, 3.3, 13.04], [1, 1.87, 3], [2, 1.77, 3]], "batl": NaN}, {"timestamp": 1631540561178, "ltp": 4.0, "tv": 281.43, "trd": NaN, "batb": [[0, 1.87, 3], [1, 1.77, 3], [2, 1.01, 7]], "batl": NaN}, {"timestamp": 1631540566157, "ltp": 4.0, "tv": 281.43, "trd": NaN, "batb": [[0, 3.4, 12.5], [1, 1.87, 3], [2, 1.77, 3]], "batl": NaN}, {"timestamp": 1631540582075, "ltp": 4.0, "tv": 281.43, "trd": NaN, "batb": [[0, 1.87, 3], [1, 1.77, 3], [2, 1.01, 7]], "batl": NaN}, {"timestamp": 1631540587077, "ltp": 4.0, "tv": 281.43, "trd": NaN, "batb": [[0, 3.15, 13.95], [1, 1.87, 3], [2, 1.77, 3]], "batl": NaN}, {"timestamp": 1631540609102, "ltp": 4.0, "tv": 281.43, "trd": NaN, "batb": [[1, 1.77, 3], [2, 1.01, 7]], "batl": NaN}, {"timestamp": 1631540610399, "ltp": 4.0, "tv": 281.43, "trd": NaN, "batb": [[1, 1.01, 7], [2, 1.01, 0]], "batl": NaN}, {"timestamp": 1631540631611, "ltp": 4.0, "tv": 281.43, "trd": NaN, "batb": [[0, 1.01, 7], [1, 1.01, 0]], "batl": NaN}, {"timestamp": 1631540636540, "ltp": 4.0, "tv": 281.43, "trd": NaN, "batb": [[0, 2.84, 16.3], [1, 1.01, 7]], "batl": NaN}, {"timestamp": 1631540662451, "ltp": 4.0, "tv": 281.43, "trd": NaN, "batb": [[0, 1.01, 7], [1, 1.01, 0]], "batl": NaN}, {"timestamp": 1631540667177, "ltp": 4.0, "tv": 281.43, "trd": NaN, "batb": [[0, 3.15, 13.95], [1, 1.01, 7]], "batl": NaN}, {"timestamp": 1631540686984, "ltp": 4.0, "tv": 281.43, "trd": NaN, "batb": [[0, 1.01, 7], [1, 1.01, 0]], "batl": NaN}, {"timestamp": 1631540692001, "ltp": 4.0, "tv": 281.43, "trd": NaN, "batb": [[0, 3.4, 12.5], [1, 1.01, 7]], "batl": NaN}, {"timestamp": 1631540705111, "ltp": 4.0, "tv": 281.43, "trd": NaN, "batb": [[0, 1.01, 7], [1, 1.01, 0]], "batl": NaN}, {"timestamp": 1631540710049, "ltp": 4.0, "tv": 281.43, "trd": NaN, "batb": [[0, 3.3, 13.04], [1, 1.01, 7]], "batl": NaN}, {"timestamp": 1631540715607, "ltp": 4.0, "tv": 281.43, "trd": NaN, "batb": [[0, 1.01, 7], [1, 1.01, 0]], "batl": NaN}, {"timestamp": 1631540719985, "ltp": 3.9, "tv": 283.16, "trd": [[3.9, 1.73]], "batb": NaN, "batl": NaN}, {"timestamp": 1631540725580, "ltp": 3.9, "tv": 283.16, "trd": NaN, "batb": [[0, 3.95, 10.16], [1, 1.01, 7]], "batl": NaN}, {"timestamp": 1631540739314, "ltp": 3.9, "tv": 283.16, "trd": NaN, "batb": [[0, 1.01, 7], [1, 1.01, 0]], "batl": NaN}, {"timestamp": 1631540744224, "ltp": 3.9, "tv": 283.16, "trd": NaN, "batb": [[0, 3.7, 11.11], [1, 1.01, 7]], "batl": NaN}, {"timestamp": 1631540747812, "ltp": 3.9, "tv": 283.16, "trd": NaN, "batb": [[0, 1.01, 7], [1, 1.01, 0]], "batl": NaN}, {"timestamp": 1631540752737, "ltp": 3.9, "tv": 283.16, "trd": NaN, "batb": [[0, 3.4, 12.5], [1, 1.01, 7]], "batl": NaN}, {"timestamp": 1631540775485, "ltp": 3.9, "tv": 283.16, "trd": NaN, "batb": [[0, 1.01, 7], [1, 1.01, 0]], "batl": NaN}, {"timestamp": 1631540779793, "ltp": 3.9, "tv": 283.16, "trd": NaN, "batb": [[0, 3, 15], [1, 1.01, 7]], "batl": NaN}, {"timestamp": 1631540798875, "ltp": 3.9, "tv": 283.16, "trd": NaN, "batb": [[0, 1.01, 7], [1, 1.01, 0]], "batl": NaN}, {"timestamp": 1631540803774, "ltp": 3.9, "tv": 283.16, "trd": NaN, "batb": [[0, 3.4, 12.5], [1, 1.01, 7]], "batl": NaN}, {"timestamp": 1631540814798, "ltp": 3.9, "tv": 283.16, "trd": NaN, "batb": [[0, 1.01, 7], [1, 1.01, 0]], "batl": NaN}, {"timestamp": 1631540819840, "ltp": 3.9, "tv": 283.16, "trd": NaN, "batb": [[0, 3.3, 13.04], [1, 1.01, 7]], "batl": NaN}, {"timestamp": 1631540830341, "ltp": 3.9, "tv": 283.16, "trd": NaN, "batb": [[0, 1.01, 7], [1, 1.01, 0]], "batl": NaN}, {"timestamp": 1631540835250, "ltp": 3.9, "tv": 283.16, "trd": NaN, "batb": [[0, 3, 15], [1, 1.01, 7]], "batl": NaN}, {"timestamp": 1631540872772, "ltp": 3.9, "tv": 283.16, "trd": NaN, "batb": [[0, 1.01, 7], [1, 1.01, 0]], "batl": NaN}, {"timestamp": 1631540877686, "ltp": 3.9, "tv": 283.16, "trd": NaN, "batb": [[0, 2.66, 18.07], [1, 1.01, 7]], "batl": NaN}, {"timestamp": 1631540911559, "ltp": 3.9, "tv": 283.16, "trd": NaN, "batb": [[0, 1.01, 7], [1, 1.01, 0]], "batl": NaN}, {"timestamp": 1631540916460, "ltp": 3.9, "tv": 283.16, "trd": NaN, "batb": [[0, 2.26, 23.8], [1, 1.01, 7]], "batl": NaN}, {"timestamp": 1631541011891, "ltp": 3.9, "tv": 283.16, "trd": NaN, "batb": [[0, 1.01, 7], [1, 1.01, 0]], "batl": NaN}, {"timestamp": 1631541016923, "ltp": 3.9, "tv": 283.16, "trd": NaN, "batb": [[0, 2.5, 20], [1, 1.01, 7]], "batl": NaN}, {"timestamp": 1631541055665, "ltp": 3.9, "tv": 283.16, "trd": NaN, "batb": [[0, 1.01, 7], [1, 1.01, 0]], "batl": NaN}, {"timestamp": 1631541060588, "ltp": 3.9, "tv": 283.16, "trd": NaN, "batb": [[0, 2.84, 16.3], [1, 1.01, 7]], "batl": NaN}, {"timestamp": 1631541101637, "ltp": 3.9, "tv": 283.16, "trd": NaN, "batb": [[0, 1.01, 7], [1, 1.01, 0]], "batl": NaN}, {"timestamp": 1631541106635, "ltp": 3.9, "tv": 283.16, "trd": NaN, "batb": [[0, 2.58, 18.98], [1, 1.01, 7]], "batl": NaN}, {"timestamp": 1631541144253, "ltp": 3.9, "tv": 283.16, "trd": NaN, "batb": [[0, 1.01, 7], [1, 1.01, 0]], "batl": NaN}, {"timestamp": 1631541149263, "ltp": 3.9, "tv": 283.16, "trd": NaN, "batb": [[0, 2.84, 16.3], [1, 1.01, 7]], "batl": NaN}, {"timestamp": 1631541174727, "ltp": 3.9, "tv": 283.16, "trd": NaN, "batb": [[0, 1.01, 7], [1, 1.01, 0]], "batl": NaN}, {"timestamp": 1631541179698, "ltp": 3.9, "tv": 283.16, "trd": NaN, "batb": [[0, 3.15, 13.95], [1, 1.01, 7]], "batl": NaN}, {"timestamp": 1631541207047, "ltp": 3.9, "tv": 283.16, "trd": NaN, "batb": [[0, 1.01, 7], [1, 1.01, 0]], "batl": NaN}, {"timestamp": 1631541212047, "ltp": 3.9, "tv": 283.16, "trd": NaN, "batb": [[0, 3.7, 11.11], [1, 1.01, 7]], "batl": NaN}, {"timestamp": 1631541231553, "ltp": 3.9, "tv": 283.16, "trd": NaN, "batb": [[0, 1.01, 7], [1, 1.01, 0]], "batl": NaN}, {"timestamp": 1631541236588, "ltp": 3.9, "tv": 283.16, "trd": NaN, "batb": [[0, 4, 10], [1, 1.01, 7]], "batl": NaN}, {"timestamp": 1631541256190, "ltp": 3.9, "tv": 283.16, "trd": NaN, "batb": [[0, 1.01, 7], [1, 1.01, 0]], "batl": NaN}, {"timestamp": 1631541261193, "ltp": 3.9, "tv": 283.16, "trd": NaN, "batb": [[0, 3.7, 11.11], [1, 1.01, 7]], "batl": NaN}, {"timestamp": 1631541283270, "ltp": 3.9, "tv": 283.16, "trd": NaN, "batb": [[0, 1.01, 7], [1, 1.01, 0]], "batl": NaN}, {"timestamp": 1631541288166, "ltp": 3.9, "tv": 283.16, "trd": NaN, "batb": [[0, 4.1, 10], [1, 1.01, 7]], "batl": NaN}, {"timestamp": 1631541313607, "ltp": 3.9, "tv": 283.16, "trd": NaN, "batb": [[0, 3.05, 13.24]], "batl": NaN}, {"timestamp": 1631541318512, "ltp": 3.9, "tv": 283.16, "trd": NaN, "batb": [[0, 4.3, 10], [1, 3.05, 13.24], [2, 1.01, 7]], "batl": NaN}, {"timestamp": 1631541425190, "ltp": 3.9, "tv": 283.16, "trd": NaN, "batb": [[0, 3.05, 13.24], [1, 1.01, 7], [2, 1.01, 0]], "batl": NaN}, {"timestamp": 1631541430184, "ltp": 3.9, "tv": 283.16, "trd": NaN, "batb": [[0, 4.8, 10], [1, 3.05, 13.24], [2, 1.01, 7]], "batl": NaN}, {"timestamp": 1631541432983, "ltp": 3.9, "tv": 283.16, "trd": NaN, "batb": [[0, 3.05, 13.24], [1, 1.01, 7], [2, 1.01, 0]], "batl": NaN}, {"timestamp": 1631541438098, "ltp": 3.9, "tv": 283.16, "trd": NaN, "batb": [[0, 5.8, 10], [1, 3.05, 13.24], [2, 1.01, 7]], "batl": NaN}, {"timestamp": 1631541468431, "ltp": 3.9, "tv": 283.16, "trd": NaN, "batb": [[0, 3.05, 13.24], [1, 1.01, 7], [2, 1.01, 0]], "batl": NaN}, {"timestamp": 1631541473444, "ltp": 3.9, "tv": 283.16, "trd": NaN, "batb": [[0, 4.3, 10], [1, 3.05, 13.24], [2, 1.01, 7]], "batl": NaN}, {"timestamp": 1631541502621, "ltp": 3.9, "tv": 283.16, "trd": NaN, "batb": [[0, 3.05, 13.24], [1, 1.01, 7], [2, 1.01, 0]], "batl": NaN}, {"timestamp": 1631541507513, "ltp": 5.6, "tv": 283.92, "trd": [[5.6, 0.76]], "batb": [[0, 5.8, 9.24], [1, 3.05, 13.24], [2, 1.01, 7]], "batl": NaN}, {"timestamp": 1631541508391, "ltp": 5.6, "tv": 283.92, "trd": NaN, "batb": [[0, 3.05, 13.24], [1, 1.01, 7], [2, 1.01, 0]], "batl": NaN}, {"timestamp": 1631541512808, "ltp": 5.6, "tv": 283.92, "trd": NaN, "batb": [[0, 5.8, 10], [1, 3.05, 13.24], [2, 1.01, 7]], "batl": NaN}, {"timestamp": 1631541532073, "ltp": 5.6, "tv": 283.92, "trd": NaN, "batb": [[0, 3.05, 13.24], [1, 1.01, 7], [2, 1.01, 0]], "batl": NaN}, {"timestamp": 1631541537057, "ltp": 5.6, "tv": 283.92, "trd": NaN, "batb": [[0, 6, 10], [1, 3.05, 13.24], [2, 1.01, 7]], "batl": NaN}, {"timestamp": 1631541547293, "ltp": 5.6, "tv": 283.92, "trd": NaN, "batb": [[0, 3.05, 13.24], [1, 1.01, 7], [2, 1.01, 0]], "batl": NaN}, {"timestamp": 1631541552173, "ltp": 5.6, "tv": 283.92, "trd": NaN, "batb": [[0, 4.8, 10], [1, 3.05, 13.24], [2, 1.01, 7]], "batl": NaN}, {"timestamp": 1631541593888, "ltp": 5.6, "tv": 283.92, "trd": NaN, "batb": [[0, 3.05, 13.24], [1, 1.01, 7], [2, 1.01, 0]], "batl": NaN}, {"timestamp": 1631541598762, "ltp": 5.6, "tv": 283.92, "trd": NaN, "batb": [[0, 3.95, 10.16], [1, 3.05, 13.24], [2, 1.01, 7]], "batl": NaN}, {"timestamp": 1631541606129, "ltp": 5.6, "tv": 283.92, "trd": NaN, "batb": [[0, 3.05, 13.24], [1, 1.01, 7], [2, 1.01, 0]], "batl": NaN}, {"timestamp": 1631541611034, "ltp": 5.6, "tv": 283.92, "trd": NaN, "batb": [[0, 4, 10], [1, 3.05, 13.24], [2, 1.01, 7]], "batl": NaN}, {"timestamp": 1631541617130, "ltp": 5.6, "tv": 283.92, "trd": NaN, "batb": [[0, 3.05, 13.24], [1, 1.01, 7], [2, 1.01, 0]], "batl": NaN}, {"timestamp": 1631541621826, "ltp": 5.6, "tv": 283.92, "trd": NaN, "batb": [[0, 3.3, 13.04], [1, 3.05, 13.24], [2, 1.01, 7]], "batl": NaN}, {"timestamp": 1631541651601, "ltp": 5.6, "tv": 283.92, "trd": NaN, "batb": [[0, 3.05, 13.24], [1, 1.01, 7], [2, 1.01, 0]], "batl": NaN}, {"timestamp": 1631541656613, "ltp": 3.75, "tv": 285.02, "trd": [[3.75, 1.1]], "batb": [[0, 3.95, 9.06], [1, 3.05, 13.24], [2, 1.01, 7]], "batl": NaN}, {"timestamp": 1631541656821, "ltp": 3.75, "tv": 285.02, "trd": NaN, "batb": [[0, 3.05, 13.24], [1, 1.01, 7], [2, 1.01, 0]], "batl": NaN}, {"timestamp": 1631541661723, "ltp": 3.75, "tv": 285.02, "trd": NaN, "batb": [[0, 3.95, 10.16], [1, 3.05, 13.24], [2, 1.01, 7]], "batl": NaN}, {"timestamp": 1631541670050, "ltp": 3.75, "tv": 285.02, "trd": NaN, "batb": [[0, 3.05, 13.24], [1, 1.01, 7], [2, 1.01, 0]], "batl": NaN}, {"timestamp": 1631541675049, "ltp": 3.75, "tv": 285.02, "trd": NaN, "batb": [[0, 3.7, 11.11], [1, 3.05, 13.24], [2, 1.01, 7]], "batl": NaN}, {"timestamp": 1631541690767, "ltp": 3.75, "tv": 285.02, "trd": NaN, "batb": [[0, 3.05, 13.24], [1, 1.01, 7], [2, 1.01, 0]], "batl": NaN}, {"timestamp": 1631541695772, "ltp": 3.75, "tv": 285.02, "trd": NaN, "batb": [[0, 4.3, 10], [1, 3.05, 13.24], [2, 1.01, 7]], "batl": NaN}, {"timestamp": 1631541721095, "ltp": 3.75, "tv": 285.02, "trd": NaN, "batb": [[0, 3.05, 13.24], [1, 1.01, 7], [2, 1.01, 0]], "batl": NaN}, {"timestamp": 1631541726118, "ltp": 3.75, "tv": 285.02, "trd": NaN, "batb": [[0, 4.8, 10], [1, 3.05, 13.24], [2, 1.01, 7]], "batl": NaN}, {"timestamp": 1631541746450, "ltp": 3.75, "tv": 285.02, "trd": NaN, "batb": [[0, 3.05, 13.24], [1, 1.01, 7], [2, 1.01, 0]], "batl": NaN}, {"timestamp": 1631541751328, "ltp": 3.75, "tv": 285.02, "trd": NaN, "batb": [[0, 4.3, 10], [1, 3.05, 13.24], [2, 1.01, 7]], "batl": NaN}, {"timestamp": 1631541778891, "ltp": 3.75, "tv": 285.02, "trd": NaN, "batb": [[0, 3.05, 13.24], [1, 1.01, 7], [2, 1.01, 0]], "batl": NaN}, {"timestamp": 1631541783890, "ltp": 3.75, "tv": 285.02, "trd": NaN, "batb": [[0, 3.95, 10.16], [1, 3.05, 13.24], [2, 1.01, 7]], "batl": NaN}, {"timestamp": 1631541823483, "ltp": 3.75, "tv": 285.02, "trd": NaN, "batb": [[0, 3.05, 13.24], [1, 1.01, 7], [2, 1.01, 0]], "batl": NaN}, {"timestamp": 1631541828486, "ltp": 3.75, "tv": 285.02, "trd": NaN, "batb": [[0, 3.15, 13.95], [1, 3.05, 13.24], [2, 1.01, 7]], "batl": NaN}, {"timestamp": 1631541831222, "ltp": 3.75, "tv": 285.02, "trd": NaN, "batb": [[1, 1.01, 7], [2, 1.01, 0]], "batl": NaN}, {"timestamp": 1631541843816, "ltp": 3.75, "tv": 285.02, "trd": NaN, "batb": [[0, 1.01, 7], [1, 1.01, 0]], "batl": NaN}, {"timestamp": 1631541849129, "ltp": 3.5, "tv": 286.22, "trd": [[3.5, 1.2]], "batb": NaN, "batl": NaN}, {"timestamp": 1631541854629, "ltp": 3.5, "tv": 286.22, "trd": NaN, "batb": [[0, 3.95, 10.16], [1, 1.01, 7]], "batl": NaN}, {"timestamp": 1631541865269, "ltp": 3.5, "tv": 286.22, "trd": NaN, "batb": [[0, 1.01, 7], [1, 1.01, 0]], "batl": NaN}, {"timestamp": 1631541869761, "ltp": 3.5, "tv": 286.22, "trd": NaN, "batb": [[0, 4.8, 10], [1, 1.01, 7]], "batl": NaN}, {"timestamp": 1631542020455, "ltp": 7.8, "tv": 288.22, "trd": [[6.6, 0.54], [7.8, 1.46]], "batb": NaN, "batl": NaN}, {"timestamp": 1631542030464, "ltp": 7.8, "tv": 288.22, "trd": NaN, "batb": [[0, 1.01, 7], [1, 1.01, 0]], "batl": NaN}, {"timestamp": 1631542035443, "ltp": 7.8, "tv": 288.22, "trd": NaN, "batb": [[0, 6, 10], [1, 1.01, 7]], "batl": NaN}, {"timestamp": 1631542067115, "ltp": 7.8, "tv": 288.22, "trd": NaN, "batb": [[0, 1.01, 7], [1, 1.01, 0]], "batl": NaN}, {"timestamp": 1631542072122, "ltp": 7.8, "tv": 288.22, "trd": NaN, "batb": [[0, 7.6, 10], [1, 1.01, 7]], "batl": NaN}, {"timestamp": 1631542097880, "ltp": 7.8, "tv": 288.22, "trd": NaN, "batb": [[0, 1.01, 7], [1, 1.01, 0]], "batl": NaN}, {"timestamp": 1631542102844, "ltp": 7.8, "tv": 288.22, "trd": NaN, "batb": [[0, 8, 10], [1, 1.01, 7]], "batl": NaN}, {"timestamp": 1631542117635, "ltp": 7.8, "tv": 288.22, "trd": NaN, "batb": [[0, 1.01, 7], [1, 1.01, 0]], "batl": NaN}, {"timestamp": 1631542121737, "ltp": 7.8, "tv": 288.22, "trd": NaN, "batb": [[0, 10, 10], [1, 1.01, 7]], "batl": NaN}, {"timestamp": 1631542149762, "ltp": 7.8, "tv": 288.22, "trd": NaN, "batb": [[0, 1.01, 7], [1, 1.01, 0]], "batl": NaN}, {"timestamp": 1631542154680, "ltp": 7.8, "tv": 288.22, "trd": NaN, "batb": [[0, 8.6, 10], [1, 1.01, 7]], "batl": NaN}, {"timestamp": 1631542166482, "ltp": 8.6, "tv": 288.62, "trd": [[8.6, 0.4]], "batb": [[0, 1.01, 7], [1, 1.01, 0]], "batl": NaN}, {"timestamp": 1631542171425, "ltp": 8.6, "tv": 288.62, "trd": NaN, "batb": [[0, 8.6, 10], [1, 1.01, 7]], "batl": NaN}, {"timestamp": 1631542172623, "ltp": 8.6, "tv": 288.62, "trd": NaN, "batb": [[0, 1.01, 7], [1, 1.01, 0]], "batl": NaN}, {"timestamp": 1631542176589, "ltp": 8.6, "tv": 288.62, "trd": NaN, "batb": [[0, 7, 10], [1, 1.01, 7]], "batl": NaN}, {"timestamp": 1631542201254, "ltp": 8.6, "tv": 288.62, "trd": NaN, "batb": [[0, 1.01, 7], [1, 1.01, 0]], "batl": NaN}, {"timestamp": 1631542206276, "ltp": 8.6, "tv": 288.62, "trd": NaN, "batb": [[0, 5.3, 10], [1, 1.01, 7]], "batl": NaN}, {"timestamp": 1631542228591, "ltp": 8.6, "tv": 288.62, "trd": NaN, "batb": [[0, 1.01, 7], [1, 1.01, 0]], "batl": NaN}, {"timestamp": 1631542232681, "ltp": 8.6, "tv": 288.62, "trd": NaN, "batb": [[0, 7, 10], [1, 1.01, 7]], "batl": NaN}, {"timestamp": 1631542249897, "ltp": 8.6, "tv": 288.62, "trd": NaN, "batb": [[0, 1.01, 7], [1, 1.01, 0]], "batl": NaN}, {"timestamp": 1631542254803, "ltp": 8.6, "tv": 288.62, "trd": NaN, "batb": [[0, 5.3, 10], [1, 1.01, 7]], "batl": NaN}, {"timestamp": 1631542281543, "ltp": 8.6, "tv": 288.62, "trd": NaN, "batb": [[0, 1.01, 7], [1, 1.01, 0]], "batl": NaN}, {"timestamp": 1631542285762, "ltp": 8.6, "tv": 288.62, "trd": NaN, "batb": [[0, 7, 10], [1, 1.01, 7]], "batl": NaN}, {"timestamp": 1631542305396, "ltp": 8.6, "tv": 288.62, "trd": NaN, "batb": [[0, 1.01, 7], [1, 1.01, 0]], "batl": NaN}, {"timestamp": 1631542310598, "ltp": 8.6, "tv": 288.62, "trd": NaN, "batb": [[0, 14, 10], [1, 1.01, 7]], "batl": NaN}, {"timestamp": 1631542345005, "ltp": 8.6, "tv": 288.62, "trd": NaN, "batb": [[0, 1.01, 7], [1, 1.01, 0]], "batl": NaN}, {"timestamp": 1631542349996, "ltp": 8.6, "tv": 288.62, "trd": NaN, "batb": [[0, 19.5, 10], [1, 1.01, 7]], "batl": NaN}, {"timestamp": 1631542369128, "ltp": 8.6, "tv": 288.62, "trd": NaN, "batb": [[0, 1.01, 7], [1, 1.01, 0]], "batl": NaN}, {"timestamp": 1631542477794, "ltp": 8.6, "tv": 288.62, "trd": NaN, "batb": NaN, "batl": [[0, 340, 36.37]]}, {"timestamp": 1631542489107, "ltp": 8.6, "tv": 288.62, "trd": NaN, "batb": [[0, 19.5, 10], [1, 1.01, 7]], "batl": NaN}, {"timestamp": 1631542507646, "ltp": 8.6, "tv": 288.62, "trd": NaN, "batb": [[0, 1.01, 7], [1, 1.01, 0]], "batl": NaN}]}]}