{"info": {"id": "1.187552299", "eventId": "30895245", "eventName": "Match Odds", "marketType": "MATCH_ODDS", "openDate": 1631460681255, "name": "D Semenistaja v G Maristany Zuleta De Reales", "numberOfActiveRunner": 2, "countryCode": "", "sport": "TENNIS", "venue": "", "volume": {"total": 932.49, "preMatch": 42.92, "inPlay": 889.57}, "winner": {"id": 16100628, "name": "G Maristany Zuleta de Reales", "status": "WINNER", "position": 2}, "delay": 5}, "runners": [{"id": 23806970, "name": "D Semenistaja", "status": "LOSER", "position": 1, "inPlayOdds": 1.83, "inPlayTime": 1631460681255, "avgPrematch": 1.83, "closedOdds": 2.28, "maxPrematch": 1.83, "minPrematch": 1.83, "maxInPlay": 11.5, "minInPlay": 1.71, "inPlayIndex": 4, "lengthOdds": 162, "lengthOddsPrematch": 4, "lengthOddsInPlay": 158, "tradedVolume": 211.07, "preMatchVolume": 32.92, "inPlayVolume": 178.15}, {"id": 16100628, "name": "G Maristany Zuleta de Reales", "status": "WINNER", "position": 2, "inPlayOdds": 1.09, "inPlayTime": 1631473381069, "avgPrematch": 0, "closedOdds": 2.3, "maxPrematch": -100, "minPrematch": 1001, "maxInPlay": 2.4, "minInPlay": 1.01, "inPlayIndex": 0, "lengthOdds": 262, "lengthOddsPrematch": 0, "lengthOddsInPlay": 262, "tradedVolume": 721.42, "preMatchVolume": 10.0, "inPlayVolume": 711.42}], "marketUpdates": [{"timestamp": 1631439438070000000, "openDate": "2021-09-12T15:30:00.000Z", "status": "OPEN", "betDelay": 0, "inPlay": false, "complete": true}, {"timestamp": 1631460681255000000, "openDate": "2021-09-12T15:30:00.000Z", "status": "OPEN", "betDelay": 5, "inPlay": true, "complete": true}, {"timestamp": 1631469003612000000, "openDate": "2021-09-12T17:49:59.000Z", "status": "OPEN", "betDelay": 5, "inPlay": true, "complete": true}, {"timestamp": 1631475970216000000, "openDate": "2021-09-12T17:49:59.000Z", "status": "SUSPENDED", "betDelay": 5, "inPlay": true, "complete": true}, {"timestamp": 1631475977251000000, "openDate": "2021-09-12T17:49:59.000Z", "status": "CLOSED", "betDelay": 5, "inPlay": true, "complete": true}], "odds": [{"runnerId": 23806970, "odds": [{"timestamp": 1631456889697, "ltp": 1.83, "tv": 32.92, "trd": [[1.83, 32.92]], "batb": [[0, 1.83, 37.86]], "batl": NaN}, {"timestamp": 1631456890906, "ltp": 1.83, "tv": 32.92, "trd": NaN, "batb": [[0, 1.83, 54.32]], "batl": NaN}, {"timestamp": 1631457001320, "ltp": 1.83, "tv": 32.92, "trd": NaN, "batb": [[0, 1.84, 15.25], [1, 1.83, 54.32], [2, 1.05, 879.5]], "batl": NaN}, {"timestamp": 1631457762821, "ltp": 1.83, "tv": 32.92, "trd": NaN, "batb": [[2, 1.02, 108.45]], "batl": NaN}, {"timestamp": 1631460681255, "ltp": 1.83, "tv": 32.92, "trd": NaN, "batb": [[0, 1.01, 12], [1, 1.83, 0], [2, 1.02, 0]], "batl": NaN}, {"timestamp": 1631461659316, "ltp": 1.83, "tv": 32.92, "trd": NaN, "batb": NaN, "batl": [[0, 1.04, 2.17]]}, {"timestamp": 1631461664489, "ltp": 1.83, "tv": 32.92, "trd": NaN, "batb": NaN, "batl": [[1, 11.5, 8.68]]}, {"timestamp": 1631461669423, "ltp": 1.83, "tv": 32.92, "trd": NaN, "batb": NaN, "batl": [[0, 11.5, 8.68], [1, 11.5, 0]]}, {"timestamp": 1631469897516, "ltp": 1.83, "tv": 32.92, "trd": NaN, "batb": [[0, 1.02, 12], [1, 1.01, 12]], "batl": NaN}, {"timestamp": 1631470690023, "ltp": 1.83, "tv": 32.92, "trd": NaN, "batb": [[0, 1.48, 18.08], [1, 1.02, 12], [2, 1.01, 12]], "batl": NaN}, {"timestamp": 1631470716764, "ltp": 1.83, "tv": 32.92, "trd": NaN, "batb": [[0, 1.88, 13.01], [1, 1.48, 18.08], [2, 1.02, 12]], "batl": NaN}, {"timestamp": 1631470828117, "ltp": 1.83, "tv": 32.92, "trd": NaN, "batb": [[2, 1.01, 12]], "batl": NaN}, {"timestamp": 1631471158639, "ltp": 1.83, "tv": 32.92, "trd": NaN, "batb": [[0, 1.88, 7.95]], "batl": NaN}, {"timestamp": 1631472211666, "ltp": 1.83, "tv": 32.92, "trd": NaN, "batb": [[0, 1.48, 18.08], [1, 1.01, 12], [2, 1.01, 0]], "batl": NaN}, {"timestamp": 1631472213781, "ltp": 1.83, "tv": 32.92, "trd": NaN, "batb": [[0, 1.48, 10.85]], "batl": NaN}, {"timestamp": 1631473381069, "ltp": 11.5, "tv": 33.86, "trd": [[11.5, 0.95]], "batb": NaN, "batl": [[0, 11.5, 7.73]]}, {"timestamp": 1631473447893, "ltp": 11.5, "tv": 33.86, "trd": NaN, "batb": [[0, 1.5, 7.26], [1, 1.48, 10.85], [2, 1.01, 12]], "batl": NaN}, {"timestamp": 1631473458118, "ltp": 11.5, "tv": 33.86, "trd": NaN, "batb": [[0, 1.55, 7.23], [1, 1.5, 7.26], [2, 1.48, 10.85]], "batl": NaN}, {"timestamp": 1631473478015, "ltp": 11.5, "tv": 33.86, "trd": NaN, "batb": [[0, 2, 232.09], [1, 1.55, 7.23], [2, 1.5, 7.26]], "batl": NaN}, {"timestamp": 1631473480434, "ltp": 11.5, "tv": 33.86, "trd": NaN, "batb": [[0, 2, 232.81]], "batl": NaN}, {"timestamp": 1631473491576, "ltp": 11.5, "tv": 33.86, "trd": NaN, "batb": [[0, 2.2, 23.86], [1, 2, 232.09], [2, 1.55, 7.23]], "batl": NaN}, {"timestamp": 1631473502871, "ltp": 11.5, "tv": 33.86, "trd": NaN, "batb": [[1, 1.55, 7.23], [2, 1.5, 7.26]], "batl": NaN}, {"timestamp": 1631473513000, "ltp": 11.5, "tv": 33.86, "trd": NaN, "batb": [[0, 3.2, 13.01], [1, 2.2, 23.86], [2, 1.55, 7.23]], "batl": NaN}, {"timestamp": 1631473529803, "ltp": 11.5, "tv": 33.86, "trd": NaN, "batb": [[1, 2.2, 23.14]], "batl": NaN}, {"timestamp": 1631473534921, "ltp": 11.5, "tv": 33.86, "trd": NaN, "batb": [[0, 3.2, 13.74]], "batl": NaN}, {"timestamp": 1631473669621, "ltp": 11.5, "tv": 33.86, "trd": NaN, "batb": [[0, 4, 1.45], [1, 3.2, 13.01], [2, 2.2, 23.14]], "batl": NaN}, {"timestamp": 1631473674750, "ltp": 11.5, "tv": 33.86, "trd": NaN, "batb": [[0, 4.5, 1.45], [1, 3.2, 13.74]], "batl": NaN}, {"timestamp": 1631473697479, "ltp": 11.5, "tv": 33.86, "trd": NaN, "batb": [[0, 4, 1.45], [1, 3.2, 13.01]], "batl": NaN}, {"timestamp": 1631473777684, "ltp": 11.5, "tv": 33.86, "trd": NaN, "batb": [[1, 3.2, 8.68]], "batl": NaN}, {"timestamp": 1631473924629, "ltp": 11.5, "tv": 33.86, "trd": NaN, "batb": [[0, 3.2, 8.68], [1, 2.2, 23.14], [2, 1.55, 7.23]], "batl": NaN}, {"timestamp": 1631473925222, "ltp": 11.5, "tv": 33.86, "trd": NaN, "batb": [[0, 2.2, 23.14], [1, 1.55, 7.23], [2, 1.5, 7.26]], "batl": NaN}, {"timestamp": 1631473947977, "ltp": 11.5, "tv": 33.86, "trd": NaN, "batb": [[0, 3.1, 2.17], [1, 2.2, 23.14], [2, 1.55, 7.23]], "batl": NaN}, {"timestamp": 1631473973923, "ltp": 11.5, "tv": 33.86, "trd": NaN, "batb": [[0, 2.2, 23.14], [1, 1.55, 7.23], [2, 1.5, 7.26]], "batl": NaN}, {"timestamp": 1631473979839, "ltp": 11.5, "tv": 33.86, "trd": NaN, "batb": [[0, 2.2, 13.01]], "batl": NaN}, {"timestamp": 1631473985329, "ltp": 3.5, "tv": 36.65, "trd": [[3.5, 1.45], [4.3, 1.34]], "batb": NaN, "batl": [[0, 3.4, 47.21]]}, {"timestamp": 1631473994842, "ltp": 3.4, "tv": 131.06, "trd": [[3.4, 94.4]], "batb": [[0, 3.4, 29.36], [1, 2.2, 13.01], [2, 1.55, 7.23]], "batl": NaN}, {"timestamp": 1631473995841, "ltp": 3.4, "tv": 131.06, "trd": NaN, "batb": [[0, 3.4, 215.81]], "batl": NaN}, {"timestamp": 1631473996837, "ltp": 3.4, "tv": 131.06, "trd": NaN, "batb": [[0, 3.4, 173.28]], "batl": NaN}, {"timestamp": 1631473997779, "ltp": 3.4, "tv": 131.06, "trd": NaN, "batb": [[0, 3.4, 37.04]], "batl": NaN}, {"timestamp": 1631473998846, "ltp": 3.4, "tv": 131.06, "trd": NaN, "batb": [[0, 3.4, 90.65]], "batl": NaN}, {"timestamp": 1631473999844, "ltp": 3.4, "tv": 131.06, "trd": NaN, "batb": [[0, 3.4, 137.39]], "batl": NaN}, {"timestamp": 1631474000750, "ltp": 3.4, "tv": 131.06, "trd": NaN, "batb": [[0, 3.4, 33.94]], "batl": NaN}, {"timestamp": 1631474001643, "ltp": 3.4, "tv": 131.06, "trd": NaN, "batb": [[0, 2.2, 13.01], [1, 1.55, 7.23], [2, 1.5, 7.26]], "batl": NaN}, {"timestamp": 1631474002847, "ltp": 3.4, "tv": 131.06, "trd": NaN, "batb": [[0, 3.4, 4.95], [1, 2.2, 13.01], [2, 1.55, 7.23]], "batl": NaN}, {"timestamp": 1631474003151, "ltp": 3.4, "tv": 131.06, "trd": NaN, "batb": [[0, 2.2, 13.01], [1, 1.55, 7.23], [2, 1.5, 7.26]], "batl": NaN}, {"timestamp": 1631474031654, "ltp": 3.4, "tv": 131.06, "trd": NaN, "batb": [[0, 4, 20], [1, 2.2, 13.01], [2, 1.55, 7.23]], "batl": NaN}, {"timestamp": 1631474034236, "ltp": 3.4, "tv": 131.06, "trd": NaN, "batb": [[0, 2.2, 13.01], [1, 1.55, 7.23], [2, 1.5, 7.26]], "batl": NaN}, {"timestamp": 1631474039381, "ltp": 3.4, "tv": 131.06, "trd": NaN, "batb": [[0, 4.2, 20], [1, 2.2, 13.01], [2, 1.55, 7.23]], "batl": NaN}, {"timestamp": 1631474164402, "ltp": 4.2, "tv": 147.8, "trd": [[4.2, 16.74]], "batb": [[0, 4.2, 11.63]], "batl": NaN}, {"timestamp": 1631474251776, "ltp": 4.2, "tv": 147.8, "trd": NaN, "batb": NaN, "batl": [[0, 1000, 1.97]]}, {"timestamp": 1631474257191, "ltp": 7.2, "tv": 149.77, "trd": [[7.2, 1.97]], "batb": NaN, "batl": NaN}, {"timestamp": 1631474280519, "ltp": 4.2, "tv": 161.4, "trd": [[4.2, 28.37]], "batb": [[0, 2.2, 13.01], [1, 1.55, 7.23], [2, 1.5, 7.26]], "batl": NaN}, {"timestamp": 1631474294191, "ltp": 4.2, "tv": 161.4, "trd": NaN, "batb": [[0, 1.55, 7.23], [1, 1.5, 7.26], [2, 1.48, 10.85]], "batl": NaN}, {"timestamp": 1631474297548, "ltp": 4.2, "tv": 161.4, "trd": NaN, "batb": [[0, 2.46, 8.68], [1, 1.55, 7.23], [2, 1.5, 7.26]], "batl": NaN}, {"timestamp": 1631474405012, "ltp": 3.0, "tv": 163.57, "trd": [[3, 0.72], [3.5, 2.9]], "batb": NaN, "batl": NaN}, {"timestamp": 1631474427534, "ltp": 3.0, "tv": 163.57, "trd": NaN, "batb": [[1, 1.74, 18.08], [2, 1.55, 7.23]], "batl": NaN}, {"timestamp": 1631474460797, "ltp": 3.0, "tv": 163.57, "trd": NaN, "batb": [[1, 1.74, 10.85]], "batl": NaN}, {"timestamp": 1631474569797, "ltp": 3.0, "tv": 163.57, "trd": NaN, "batb": [[0, 1.74, 10.85], [1, 1.55, 7.23], [2, 1.5, 7.26]], "batl": NaN}, {"timestamp": 1631474781822, "ltp": 3.0, "tv": 163.57, "trd": NaN, "batb": [[2, 1.48, 10.85]], "batl": NaN}, {"timestamp": 1631474851887, "ltp": 3.0, "tv": 163.57, "trd": NaN, "batb": NaN, "batl": [[0, 3.9, 7.04]]}, {"timestamp": 1631474852567, "ltp": 2.6, "tv": 172.59, "trd": [[2.6, 9.02]], "batb": NaN, "batl": NaN}, {"timestamp": 1631474855561, "ltp": 2.6, "tv": 172.59, "trd": NaN, "batb": [[0, 1.55, 7.23], [1, 1.48, 10.85], [2, 1.01, 12]], "batl": NaN}, {"timestamp": 1631474907560, "ltp": 2.6, "tv": 172.59, "trd": NaN, "batb": [[0, 1.64, 10.85], [1, 1.55, 7.23], [2, 1.48, 10.85]], "batl": NaN}, {"timestamp": 1631474981862, "ltp": 2.6, "tv": 172.59, "trd": NaN, "batb": [[0, 1.64, 5.78]], "batl": NaN}, {"timestamp": 1631474983659, "ltp": 2.6, "tv": 172.59, "trd": NaN, "batb": [[1, 1.48, 10.85], [2, 1.01, 12]], "batl": NaN}, {"timestamp": 1631474992968, "ltp": 2.6, "tv": 172.59, "trd": NaN, "batb": NaN, "batl": [[0, 2.6, 6.16]]}, {"timestamp": 1631474997752, "ltp": 2.6, "tv": 172.59, "trd": NaN, "batb": [[1, 1.63, 2], [2, 1.48, 10.85]], "batl": NaN}, {"timestamp": 1631475027697, "ltp": 2.6, "tv": 172.59, "trd": NaN, "batb": [[0, 1.9, 1.23], [1, 1.64, 5.78], [2, 1.63, 2]], "batl": NaN}, {"timestamp": 1631475036607, "ltp": 2.6, "tv": 172.59, "trd": NaN, "batb": [[2, 1.63, 3]], "batl": NaN}, {"timestamp": 1631475041269, "ltp": 2.6, "tv": 172.59, "trd": NaN, "batb": [[2, 1.63, 1]], "batl": NaN}, {"timestamp": 1631475056372, "ltp": 2.6, "tv": 172.59, "trd": NaN, "batb": [[2, 1.48, 10.85]], "batl": NaN}, {"timestamp": 1631475058305, "ltp": 2.6, "tv": 172.59, "trd": NaN, "batb": [[0, 1.64, 5.78], [1, 1.48, 10.85], [2, 1.01, 12]], "batl": NaN}, {"timestamp": 1631475061525, "ltp": 2.6, "tv": 172.59, "trd": NaN, "batb": [[0, 1.72, 1], [1, 1.64, 5.78], [2, 1.48, 10.85]], "batl": NaN}, {"timestamp": 1631475063431, "ltp": 2.6, "tv": 172.59, "trd": NaN, "batb": [[0, 2, 1.23], [1, 1.72, 1], [2, 1.64, 5.78]], "batl": NaN}, {"timestamp": 1631475065497, "ltp": 2.6, "tv": 172.59, "trd": NaN, "batb": [[0, 1.72, 1], [1, 1.64, 5.78], [2, 1.48, 10.85]], "batl": NaN}, {"timestamp": 1631475070648, "ltp": 2.6, "tv": 172.59, "trd": NaN, "batb": [[0, 2.06, 1.23], [1, 1.72, 1], [2, 1.64, 5.78]], "batl": NaN}, {"timestamp": 1631475075210, "ltp": 2.6, "tv": 172.59, "trd": NaN, "batb": [[2, 1.48, 10.85]], "batl": NaN}, {"timestamp": 1631475092774, "ltp": 2.6, "tv": 172.59, "trd": NaN, "batb": [[0, 1.72, 1], [1, 1.48, 10.85], [2, 1.01, 12]], "batl": NaN}, {"timestamp": 1631475097877, "ltp": 2.6, "tv": 172.59, "trd": NaN, "batb": [[0, 2.12, 1.23], [1, 1.72, 1], [2, 1.48, 10.85]], "batl": NaN}, {"timestamp": 1631475124699, "ltp": 2.12, "tv": 175.05, "trd": [[2.12, 2.46]], "batb": [[0, 1.72, 1], [1, 1.48, 10.85], [2, 1.01, 12]], "batl": [[0, 2.12, 7.57]]}, {"timestamp": 1631475126184, "ltp": 1.71, "tv": 184.39, "trd": [[1.71, 7.34], [1.72, 2]], "batb": [[0, 1.48, 10.85], [1, 1.01, 12], [2, 1.01, 0]], "batl": NaN}, {"timestamp": 1631475130672, "ltp": 1.71, "tv": 184.39, "trd": NaN, "batb": [[0, 1.01, 12], [1, 1.01, 0]], "batl": NaN}, {"timestamp": 1631475148822, "ltp": 2.0, "tv": 208.25, "trd": [[2, 23.86]], "batb": NaN, "batl": [[0, 2, 8.25]]}, {"timestamp": 1631475180294, "ltp": 2.0, "tv": 208.25, "trd": NaN, "batb": [[0, 1.02, 11], [1, 1.01, 12]], "batl": NaN}, {"timestamp": 1631475252105, "ltp": 2.0, "tv": 208.25, "trd": NaN, "batb": NaN, "batl": [[0, 2.44, 108.45]]}, {"timestamp": 1631475256519, "ltp": 2.0, "tv": 208.25, "trd": NaN, "batb": [[0, 1.1, 232.09], [1, 1.02, 11], [2, 1.01, 12]], "batl": NaN}, {"timestamp": 1631475268511, "ltp": 2.0, "tv": 208.25, "trd": NaN, "batb": [[0, 1.22, 18.08], [1, 1.12, 20], [2, 1.1, 232.09]], "batl": NaN}, {"timestamp": 1631475277852, "ltp": 2.0, "tv": 208.25, "trd": NaN, "batb": NaN, "batl": [[0, 2.42, 6.16]]}, {"timestamp": 1631475278646, "ltp": 2.0, "tv": 208.25, "trd": NaN, "batb": [[0, 1.3, 72.3], [1, 1.22, 18.08], [2, 1.12, 20]], "batl": NaN}, {"timestamp": 1631475282538, "ltp": 2.0, "tv": 208.25, "trd": NaN, "batb": NaN, "batl": [[0, 2.28, 108.45]]}, {"timestamp": 1631475286744, "ltp": 2.28, "tv": 211.07, "trd": [[2.28, 2.82]], "batb": NaN, "batl": [[0, 2.28, 105.63]]}, {"timestamp": 1631475288971, "ltp": 2.28, "tv": 211.07, "trd": NaN, "batb": [[1, 1.12, 20], [2, 1.1, 232.09]], "batl": NaN}, {"timestamp": 1631475290764, "ltp": 2.28, "tv": 211.07, "trd": NaN, "batb": [[0, 1.36, 10.12], [1, 1.3, 72.3], [2, 1.12, 20]], "batl": NaN}, {"timestamp": 1631475301479, "ltp": 2.28, "tv": 211.07, "trd": NaN, "batb": [[0, 1.3, 72.3], [1, 1.12, 20], [2, 1.1, 232.09]], "batl": NaN}, {"timestamp": 1631475302854, "ltp": 2.28, "tv": 211.07, "trd": NaN, "batb": NaN, "batl": [[0, 2, 6.16], [1, 2.28, 105.63]]}, {"timestamp": 1631475305803, "ltp": 2.28, "tv": 211.07, "trd": NaN, "batb": NaN, "batl": [[0, 2.28, 105.63], [1, 2.28, 0]]}, {"timestamp": 1631475307182, "ltp": 2.28, "tv": 211.07, "trd": NaN, "batb": [[0, 1.12, 20], [1, 1.1, 232.09], [2, 1.02, 11]], "batl": NaN}, {"timestamp": 1631475337240, "ltp": 2.28, "tv": 211.07, "trd": NaN, "batb": [[1, 1.02, 11], [2, 1.01, 12]], "batl": NaN}, {"timestamp": 1631475346718, "ltp": 2.28, "tv": 211.07, "trd": NaN, "batb": [[0, 1.15, 72.3], [1, 1.12, 20], [2, 1.02, 11]], "batl": NaN}, {"timestamp": 1631475367642, "ltp": 2.28, "tv": 211.07, "trd": NaN, "batb": NaN, "batl": [[0, 2, 8.8]]}, {"timestamp": 1631475430897, "ltp": 2.28, "tv": 211.07, "trd": NaN, "batb": [[0, 1.12, 20], [1, 1.02, 11], [2, 1.01, 12]], "batl": NaN}, {"timestamp": 1631475442428, "ltp": 2.28, "tv": 211.07, "trd": NaN, "batb": [[0, 1.15, 72.3], [1, 1.12, 20], [2, 1.02, 11]], "batl": NaN}, {"timestamp": 1631475463604, "ltp": 2.28, "tv": 211.07, "trd": NaN, "batb": [[0, 1.16, 81.13], [1, 1.15, 72.3], [2, 1.12, 20]], "batl": NaN}, {"timestamp": 1631475467552, "ltp": 2.28, "tv": 211.07, "trd": NaN, "batb": [[1, 1.12, 20], [2, 1.02, 11]], "batl": NaN}, {"timestamp": 1631475472682, "ltp": 2.28, "tv": 211.07, "trd": NaN, "batb": [[0, 1.18, 72.3], [1, 1.16, 81.13], [2, 1.12, 20]], "batl": NaN}, {"timestamp": 1631475479202, "ltp": 2.28, "tv": 211.07, "trd": NaN, "batb": [[1, 1.12, 20], [2, 1.02, 11]], "batl": NaN}, {"timestamp": 1631475484279, "ltp": 2.28, "tv": 211.07, "trd": NaN, "batb": [[0, 1.19, 81.13], [1, 1.18, 72.3], [2, 1.12, 20]], "batl": NaN}, {"timestamp": 1631475490830, "ltp": 2.28, "tv": 211.07, "trd": NaN, "batb": [[1, 1.12, 20], [2, 1.02, 11]], "batl": NaN}, {"timestamp": 1631475495939, "ltp": 2.28, "tv": 211.07, "trd": NaN, "batb": [[0, 1.21, 72.3], [1, 1.19, 81.13], [2, 1.12, 20]], "batl": NaN}, {"timestamp": 1631475499435, "ltp": 2.28, "tv": 211.07, "trd": NaN, "batb": [[1, 1.12, 20], [2, 1.02, 11]], "batl": NaN}, {"timestamp": 1631475504528, "ltp": 2.28, "tv": 211.07, "trd": NaN, "batb": [[0, 1.23, 81.13], [1, 1.21, 72.3], [2, 1.12, 20]], "batl": NaN}, {"timestamp": 1631475510544, "ltp": 2.28, "tv": 211.07, "trd": NaN, "batb": [[0, 1.21, 72.3], [1, 1.12, 20], [2, 1.02, 11]], "batl": NaN}, {"timestamp": 1631475517573, "ltp": 2.28, "tv": 211.07, "trd": NaN, "batb": [[0, 1.12, 20], [1, 1.02, 11], [2, 1.01, 12]], "batl": NaN}, {"timestamp": 1631475530484, "ltp": 2.28, "tv": 211.07, "trd": NaN, "batb": [[0, 1.13, 72.3], [1, 1.12, 20], [2, 1.02, 11]], "batl": NaN}, {"timestamp": 1631475540376, "ltp": 2.28, "tv": 211.07, "trd": NaN, "batb": [[0, 1.14, 81.13], [1, 1.13, 72.3], [2, 1.12, 20]], "batl": NaN}, {"timestamp": 1631475548522, "ltp": 2.28, "tv": 211.07, "trd": NaN, "batb": [[1, 1.12, 20], [2, 1.02, 11]], "batl": NaN}, {"timestamp": 1631475554898, "ltp": 2.28, "tv": 211.07, "trd": NaN, "batb": [[0, 1.12, 20], [1, 1.02, 11], [2, 1.01, 12]], "batl": NaN}, {"timestamp": 1631475616670, "ltp": 2.28, "tv": 211.07, "trd": NaN, "batb": [[0, 1.15, 72.3], [1, 1.12, 20], [2, 1.02, 11]], "batl": NaN}, {"timestamp": 1631475635885, "ltp": 2.28, "tv": 211.07, "trd": NaN, "batb": [[0, 1.16, 284.4], [1, 1.15, 72.3], [2, 1.12, 20]], "batl": NaN}, {"timestamp": 1631475647429, "ltp": 2.28, "tv": 211.07, "trd": NaN, "batb": [[0, 1.2, 72.3], [1, 1.16, 284.4], [2, 1.15, 72.3]], "batl": NaN}, {"timestamp": 1631475659573, "ltp": 2.28, "tv": 211.07, "trd": NaN, "batb": [[0, 1.22, 284.4], [1, 1.2, 72.3], [2, 1.16, 284.4]], "batl": NaN}, {"timestamp": 1631475668640, "ltp": 2.28, "tv": 211.07, "trd": NaN, "batb": [[0, 1.25, 72.3], [1, 1.22, 284.4], [2, 1.2, 72.3]], "batl": NaN}, {"timestamp": 1631475680469, "ltp": 2.28, "tv": 211.07, "trd": NaN, "batb": [[0, 1.26, 284.4], [1, 1.25, 72.3], [2, 1.22, 284.4]], "batl": NaN}, {"timestamp": 1631475689771, "ltp": 2.28, "tv": 211.07, "trd": NaN, "batb": [[0, 1.3, 72.3], [1, 1.26, 284.4], [2, 1.25, 72.3]], "batl": NaN}, {"timestamp": 1631475701590, "ltp": 2.28, "tv": 211.07, "trd": NaN, "batb": [[0, 1.31, 284.4], [1, 1.3, 72.3], [2, 1.26, 284.4]], "batl": NaN}, {"timestamp": 1631475721028, "ltp": 2.28, "tv": 211.07, "trd": NaN, "batb": [[1, 1.26, 284.4], [2, 1.22, 284.4]], "batl": NaN}, {"timestamp": 1631475730641, "ltp": 2.28, "tv": 211.07, "trd": NaN, "batb": [[0, 1.16, 284.4], [1, 1.12, 20], [2, 1.02, 11]], "batl": NaN}, {"timestamp": 1631475734448, "ltp": 2.28, "tv": 211.07, "trd": NaN, "batb": [[0, 1.12, 20], [1, 1.02, 11], [2, 1.01, 12]], "batl": NaN}, {"timestamp": 1631475745545, "ltp": 2.28, "tv": 211.07, "trd": NaN, "batb": [[0, 1.15, 72.3], [1, 1.12, 20], [2, 1.02, 11]], "batl": NaN}, {"timestamp": 1631475761257, "ltp": 2.28, "tv": 211.07, "trd": NaN, "batb": [[0, 1.16, 81.13], [1, 1.15, 72.3], [2, 1.12, 20]], "batl": NaN}, {"timestamp": 1631475764357, "ltp": 2.28, "tv": 211.07, "trd": NaN, "batb": [[0, 1.16, 84.13]], "batl": NaN}, {"timestamp": 1631475777521, "ltp": 2.28, "tv": 211.07, "trd": NaN, "batb": [[1, 1.12, 20], [2, 1.02, 11]], "batl": NaN}, {"timestamp": 1631475781498, "ltp": 2.28, "tv": 211.07, "trd": NaN, "batb": [[0, 1.12, 20], [1, 1.02, 11], [2, 1.01, 12]], "batl": NaN}, {"timestamp": 1631475786592, "ltp": 2.28, "tv": 211.07, "trd": NaN, "batb": [[0, 1.17, 3], [1, 1.12, 20], [2, 1.02, 11]], "batl": NaN}, {"timestamp": 1631475789517, "ltp": 2.28, "tv": 211.07, "trd": NaN, "batb": [[0, 1.2, 72.3], [1, 1.17, 3], [2, 1.12, 20]], "batl": NaN}, {"timestamp": 1631475798127, "ltp": 2.28, "tv": 211.07, "trd": NaN, "batb": [[2, 1.15, 2]], "batl": NaN}, {"timestamp": 1631475802836, "ltp": 2.28, "tv": 211.07, "trd": NaN, "batb": [[0, 1.25, 72.3], [1, 1.2, 72.3], [2, 1.17, 3]], "batl": NaN}, {"timestamp": 1631475803211, "ltp": 2.28, "tv": 211.07, "trd": NaN, "batb": [[0, 1.25, 153.44]], "batl": NaN}, {"timestamp": 1631475813041, "ltp": 2.28, "tv": 211.07, "trd": NaN, "batb": [[2, 1.15, 2]], "batl": NaN}, {"timestamp": 1631475814721, "ltp": 2.28, "tv": 211.07, "trd": NaN, "batb": [[0, 1.35, 81.13], [1, 1.3, 72.3], [2, 1.25, 153.44]], "batl": NaN}, {"timestamp": 1631475822649, "ltp": 2.28, "tv": 211.07, "trd": NaN, "batb": [[1, 1.25, 81.13], [2, 1.15, 2]], "batl": NaN}, {"timestamp": 1631475836957, "ltp": 2.28, "tv": 211.07, "trd": NaN, "batb": [[0, 1.15, 2], [1, 1.12, 20], [2, 1.01, 12]], "batl": NaN}, {"timestamp": 1631475845795, "ltp": 2.28, "tv": 211.07, "trd": NaN, "batb": [[0, 1.3, 81.13], [1, 1.15, 2], [2, 1.12, 20]], "batl": NaN}, {"timestamp": 1631475846064, "ltp": 2.28, "tv": 211.07, "trd": NaN, "batb": [[0, 1.4, 72.3], [1, 1.3, 81.13], [2, 1.15, 2]], "batl": NaN}, {"timestamp": 1631475855662, "ltp": 2.28, "tv": 211.07, "trd": NaN, "batb": [[0, 1.6, 81.13], [1, 1.4, 72.3], [2, 1.3, 81.13]], "batl": NaN}, {"timestamp": 1631475856962, "ltp": 2.28, "tv": 211.07, "trd": NaN, "batb": [[1, 1.52, 72.3], [2, 1.4, 72.3]], "batl": NaN}, {"timestamp": 1631475860073, "ltp": 2.28, "tv": 211.07, "trd": NaN, "batb": [[1, 1.3, 81.13], [2, 1.15, 2]], "batl": NaN}, {"timestamp": 1631475866672, "ltp": 2.28, "tv": 211.07, "trd": NaN, "batb": [[0, 1.15, 2], [1, 1.12, 20], [2, 1.01, 12]], "batl": NaN}, {"timestamp": 1631475875071, "ltp": 2.28, "tv": 211.07, "trd": NaN, "batb": [[0, 1.2, 72.3], [1, 1.15, 2], [2, 1.12, 20]], "batl": NaN}, {"timestamp": 1631475885420, "ltp": 2.28, "tv": 211.07, "trd": NaN, "batb": [[0, 1.22, 81.13], [1, 1.2, 72.3], [2, 1.15, 2]], "batl": NaN}, {"timestamp": 1631475892312, "ltp": 2.28, "tv": 211.07, "trd": NaN, "batb": [[1, 1.15, 2], [2, 1.12, 20]], "batl": NaN}, {"timestamp": 1631475895214, "ltp": 2.28, "tv": 211.07, "trd": NaN, "batb": [[0, 1.15, 2], [1, 1.12, 20], [2, 1.01, 12]], "batl": NaN}, {"timestamp": 1631475903722, "ltp": 2.28, "tv": 211.07, "trd": NaN, "batb": [[0, 1.5, 81.13], [1, 1.3, 72.3], [2, 1.15, 2]], "batl": NaN}, {"timestamp": 1631475907648, "ltp": 2.28, "tv": 211.07, "trd": NaN, "batb": [[1, 1.4, 72.3], [2, 1.3, 72.3]], "batl": NaN}, {"timestamp": 1631475911224, "ltp": 2.28, "tv": 211.07, "trd": NaN, "batb": [[0, 1.55, 72.3], [1, 1.5, 81.13], [2, 1.4, 72.3]], "batl": NaN}, {"timestamp": 1631475912331, "ltp": 2.28, "tv": 211.07, "trd": NaN, "batb": [[0, 1.6, 81.13], [1, 1.55, 72.3], [2, 1.5, 81.13]], "batl": NaN}, {"timestamp": 1631475919864, "ltp": 2.28, "tv": 211.07, "trd": NaN, "batb": [[0, 1.65, 72.3], [1, 1.6, 81.13], [2, 1.55, 72.3]], "batl": NaN}, {"timestamp": 1631475922339, "ltp": 2.28, "tv": 211.07, "trd": NaN, "batb": [[0, 1.75, 72.3], [1, 1.65, 72.3], [2, 1.6, 81.13]], "batl": NaN}, {"timestamp": 1631475928468, "ltp": 2.28, "tv": 211.07, "trd": NaN, "batb": [[1, 1.7, 81.13], [2, 1.65, 72.3]], "batl": NaN}, {"timestamp": 1631475936473, "ltp": 2.28, "tv": 211.07, "trd": NaN, "batb": [[0, 1.85, 81.13], [2, 1.6, 81.13]], "batl": NaN}, {"timestamp": 1631475949809, "ltp": 2.28, "tv": 211.07, "trd": NaN, "batb": [[0, 2, 72.3], [1, 1.85, 81.13], [2, 1.7, 81.13]], "batl": NaN}, {"timestamp": 1631475952512, "ltp": 2.28, "tv": 211.07, "trd": NaN, "batb": [[0, 2.2, 72.3], [1, 2, 72.3], [2, 1.85, 81.13]], "batl": NaN}]}, {"runnerId": 16100628, "odds": [{"timestamp": 1631473381069, "ltp": 1.09, "tv": 10.0, "trd": [[1.09, 10]], "batb": NaN, "batl": NaN}, {"timestamp": 1631473438749, "ltp": 1.09, "tv": 10.0, "trd": NaN, "batb": [[0, 1.01, 1207.86]], "batl": NaN}, {"timestamp": 1631473502871, "ltp": 1.09, "tv": 10.0, "trd": NaN, "batb": NaN, "batl": [[0, 1.5, 72.3]]}, {"timestamp": 1631473503556, "ltp": 1.09, "tv": 10.0, "trd": NaN, "batb": [[0, 1.02, 100], [1, 1.01, 1207.86]], "batl": NaN}, {"timestamp": 1631473508883, "ltp": 1.09, "tv": 10.0, "trd": NaN, "batb": [[1, 1.01, 12]], "batl": NaN}, {"timestamp": 1631473523894, "ltp": 1.09, "tv": 10.0, "trd": NaN, "batb": NaN, "batl": [[0, 1.4, 3.62], [1, 1.5, 72.3]]}, {"timestamp": 1631473550754, "ltp": 1.09, "tv": 10.0, "trd": NaN, "batb": NaN, "batl": [[0, 1.3, 1.45], [1, 1.4, 3.62], [2, 1.5, 72.3]]}, {"timestamp": 1631473579087, "ltp": 1.09, "tv": 10.0, "trd": NaN, "batb": [[0, 1.03, 9], [1, 1.02, 100], [2, 1.01, 12]], "batl": NaN}, {"timestamp": 1631473593384, "ltp": 1.03, "tv": 28.0, "trd": [[1.03, 18]], "batb": [[0, 1.02, 100], [1, 1.01, 12], [2, 1.01, 0]], "batl": [[0, 1.03, 4.78], [1, 1.3, 1.45], [2, 1.4, 3.62]]}, {"timestamp": 1631473598905, "ltp": 1.03, "tv": 28.0, "trd": NaN, "batb": NaN, "batl": [[0, 1.3, 1.45], [1, 1.4, 3.62], [2, 1.5, 72.3]]}, {"timestamp": 1631473608114, "ltp": 1.03, "tv": 28.0, "trd": NaN, "batb": [[0, 1.03, 72.3], [1, 1.02, 100], [2, 1.01, 12]], "batl": NaN}, {"timestamp": 1631473617536, "ltp": 1.03, "tv": 55.55, "trd": [[1.03, 45.56]], "batb": [[0, 1.03, 58.52]], "batl": NaN}, {"timestamp": 1631473625045, "ltp": 1.03, "tv": 55.55, "trd": NaN, "batb": [[0, 1.02, 100], [1, 1.01, 12], [2, 1.01, 0]], "batl": NaN}, {"timestamp": 1631473642655, "ltp": 1.03, "tv": 55.55, "trd": NaN, "batb": NaN, "batl": [[0, 1.2, 4], [1, 1.3, 1.45], [2, 1.4, 3.62]]}, {"timestamp": 1631473647794, "ltp": 1.02, "tv": 255.55, "trd": [[1.02, 200]], "batb": [[0, 1.01, 12], [1, 1.01, 0]], "batl": [[0, 1.02, 113.51], [1, 1.2, 4], [2, 1.3, 1.45]]}, {"timestamp": 1631473658222, "ltp": 1.02, "tv": 400.16, "trd": [[1.02, 344.6]], "batb": NaN, "batl": [[0, 1.02, 41.21]]}, {"timestamp": 1631473689063, "ltp": 1.02, "tv": 482.57, "trd": [[1.02, 427.02]], "batb": [[0, 1.02, 31.1], [1, 1.01, 12]], "batl": [[0, 1.2, 4], [1, 1.3, 1.45], [2, 1.4, 3.62]]}, {"timestamp": 1631473692071, "ltp": 1.02, "tv": 482.57, "trd": NaN, "batb": [[0, 1.01, 12], [1, 1.01, 0]], "batl": NaN}, {"timestamp": 1631473703184, "ltp": 1.02, "tv": 482.57, "trd": NaN, "batb": [[0, 1.01, 84.3]], "batl": NaN}, {"timestamp": 1631473722624, "ltp": 1.02, "tv": 482.57, "trd": NaN, "batb": [[0, 1.01, 316.39]], "batl": NaN}, {"timestamp": 1631473738121, "ltp": 1.02, "tv": 482.57, "trd": NaN, "batb": NaN, "batl": [[0, 1.19, 72.3], [1, 1.2, 4], [2, 1.3, 1.45]]}, {"timestamp": 1631473748365, "ltp": 1.02, "tv": 482.57, "trd": NaN, "batb": NaN, "batl": [[1, 1.3, 1.45], [2, 1.4, 3.62]]}, {"timestamp": 1631473753437, "ltp": 1.02, "tv": 482.57, "trd": NaN, "batb": NaN, "batl": [[0, 1.17, 4], [1, 1.19, 72.3], [2, 1.3, 1.45]]}, {"timestamp": 1631473766186, "ltp": 1.02, "tv": 482.57, "trd": NaN, "batb": NaN, "batl": [[0, 1.12, 3.62], [1, 1.17, 4], [2, 1.19, 72.3]]}, {"timestamp": 1631473783012, "ltp": 1.02, "tv": 482.57, "trd": NaN, "batb": NaN, "batl": [[1, 1.19, 72.3], [2, 1.3, 1.45]]}, {"timestamp": 1631473787407, "ltp": 1.02, "tv": 482.57, "trd": NaN, "batb": NaN, "batl": [[0, 1.19, 72.3], [1, 1.3, 1.45], [2, 1.4, 3.62]]}, {"timestamp": 1631473788091, "ltp": 1.02, "tv": 482.57, "trd": NaN, "batb": NaN, "batl": [[0, 1.1, 4], [1, 1.19, 72.3], [2, 1.3, 1.45]]}, {"timestamp": 1631473804723, "ltp": 1.01, "tv": 486.57, "trd": [[1.01, 4]], "batb": [[0, 1.01, 314.39]], "batl": NaN}, {"timestamp": 1631473913634, "ltp": 1.01, "tv": 486.57, "trd": NaN, "batb": NaN, "batl": [[1, 1.3, 1.45], [2, 1.4, 3.62]]}, {"timestamp": 1631473915239, "ltp": 1.01, "tv": 520.57, "trd": [[1.01, 38]], "batb": [[0, 1.01, 297.39]], "batl": NaN}, {"timestamp": 1631473928623, "ltp": 1.01, "tv": 520.57, "trd": NaN, "batb": NaN, "batl": [[0, 1.3, 1.45], [1, 1.4, 3.62], [2, 1.5, 72.3]]}, {"timestamp": 1631473934172, "ltp": 1.01, "tv": 520.57, "trd": NaN, "batb": [[0, 1.02, 17.35], [1, 1.01, 297.39]], "batl": NaN}, {"timestamp": 1631473958314, "ltp": 1.01, "tv": 520.57, "trd": NaN, "batb": NaN, "batl": [[0, 1.3, 4.45]]}, {"timestamp": 1631473973923, "ltp": 1.01, "tv": 520.57, "trd": NaN, "batb": [[0, 1.03, 232.09], [1, 1.02, 17.35], [2, 1.01, 297.39]], "batl": NaN}, {"timestamp": 1631473975780, "ltp": 1.01, "tv": 520.57, "trd": NaN, "batb": [[0, 1.03, 242.93]], "batl": NaN}, {"timestamp": 1631473985329, "ltp": 1.4, "tv": 528.63, "trd": [[1.3, 4.45], [1.4, 3.62]], "batb": NaN, "batl": [[0, 1.5, 72.3], [1, 1.4, 0], [2, 1.5, 0]]}, {"timestamp": 1631473989433, "ltp": 1.4, "tv": 528.63, "trd": NaN, "batb": [[0, 1.04, 10.85], [1, 1.03, 242.93], [2, 1.02, 17.35]], "batl": NaN}, {"timestamp": 1631473996837, "ltp": 1.4, "tv": 528.63, "trd": NaN, "batb": NaN, "batl": [[0, 1.41, 132.87], [1, 1.5, 72.3]]}, {"timestamp": 1631473997779, "ltp": 1.4, "tv": 528.63, "trd": NaN, "batb": NaN, "batl": [[0, 1.41, 72.3]]}, {"timestamp": 1631474000750, "ltp": 1.4, "tv": 528.63, "trd": NaN, "batb": NaN, "batl": [[0, 1.41, 144.6]]}, {"timestamp": 1631474004054, "ltp": 1.4, "tv": 528.63, "trd": NaN, "batb": [[0, 1.03, 242.93], [1, 1.02, 17.35], [2, 1.01, 297.39]], "batl": NaN}, {"timestamp": 1631474005787, "ltp": 1.4, "tv": 528.63, "trd": NaN, "batb": NaN, "batl": [[0, 1.35, 72.3], [1, 1.41, 144.6], [2, 1.5, 72.3]]}, {"timestamp": 1631474006575, "ltp": 1.4, "tv": 528.63, "trd": NaN, "batb": NaN, "batl": [[1, 1.39, 7.95], [2, 1.41, 144.6]]}, {"timestamp": 1631474010297, "ltp": 1.4, "tv": 528.63, "trd": NaN, "batb": NaN, "batl": [[1, 1.41, 144.6], [2, 1.5, 72.3]]}, {"timestamp": 1631474015368, "ltp": 1.4, "tv": 528.63, "trd": NaN, "batb": NaN, "batl": [[0, 1.34, 7.95], [1, 1.35, 72.3], [2, 1.41, 144.6]]}, {"timestamp": 1631474017576, "ltp": 1.4, "tv": 528.63, "trd": NaN, "batb": NaN, "batl": [[2, 1.41, 72.3]]}, {"timestamp": 1631474018418, "ltp": 1.4, "tv": 528.63, "trd": NaN, "batb": NaN, "batl": [[0, 1.34, 6.51]]}, {"timestamp": 1631474020624, "ltp": 1.4, "tv": 528.63, "trd": NaN, "batb": NaN, "batl": [[1, 1.41, 72.3], [2, 1.5, 72.3]]}, {"timestamp": 1631474025728, "ltp": 1.4, "tv": 528.63, "trd": NaN, "batb": NaN, "batl": [[0, 1.32, 72.3], [1, 1.34, 6.51]]}, {"timestamp": 1631474027823, "ltp": 1.4, "tv": 528.63, "trd": NaN, "batb": NaN, "batl": [[1, 1.5, 72.3], [2, 1.5, 0]]}, {"timestamp": 1631474033549, "ltp": 1.4, "tv": 528.63, "trd": NaN, "batb": [[0, 1.03, 10.85]], "batl": NaN}, {"timestamp": 1631474043281, "ltp": 1.4, "tv": 528.63, "trd": NaN, "batb": [[0, 1.02, 17.35], [1, 1.01, 297.39], [2, 1.01, 0]], "batl": NaN}, {"timestamp": 1631474046394, "ltp": 1.4, "tv": 528.63, "trd": NaN, "batb": NaN, "batl": [[0, 1.3, 10.85], [1, 1.32, 72.3], [2, 1.5, 72.3]]}, {"timestamp": 1631474055101, "ltp": 1.4, "tv": 528.63, "trd": NaN, "batb": NaN, "batl": [[0, 1.25, 72.3], [1, 1.3, 10.85], [2, 1.32, 72.3]]}, {"timestamp": 1631474062645, "ltp": 1.4, "tv": 528.63, "trd": NaN, "batb": NaN, "batl": [[0, 1.3, 10.85], [1, 1.32, 72.3], [2, 1.5, 72.3]]}, {"timestamp": 1631474066446, "ltp": 1.4, "tv": 528.63, "trd": NaN, "batb": NaN, "batl": [[0, 1.23, 5.78], [1, 1.3, 10.85], [2, 1.32, 72.3]]}, {"timestamp": 1631474067731, "ltp": 1.4, "tv": 528.63, "trd": NaN, "batb": NaN, "batl": [[0, 1.3, 10.85], [1, 1.32, 72.3], [2, 1.5, 72.3]]}, {"timestamp": 1631474068366, "ltp": 1.4, "tv": 528.63, "trd": NaN, "batb": NaN, "batl": [[0, 1.32, 72.3], [1, 1.5, 72.3], [2, 1.5, 0]]}, {"timestamp": 1631474072654, "ltp": 1.4, "tv": 528.63, "trd": NaN, "batb": [[0, 1.03, 232.09], [1, 1.02, 17.35], [2, 1.01, 297.39]], "batl": NaN}, {"timestamp": 1631474074972, "ltp": 1.4, "tv": 528.63, "trd": NaN, "batb": NaN, "batl": [[1, 1.5, 0]]}, {"timestamp": 1631474077457, "ltp": 1.4, "tv": 528.63, "trd": NaN, "batb": [[0, 1.04, 10.85], [1, 1.03, 232.09], [2, 1.02, 17.35]], "batl": NaN}, {"timestamp": 1631474098861, "ltp": 1.4, "tv": 528.63, "trd": NaN, "batb": NaN, "batl": [[0, 1.7, 72.3]]}, {"timestamp": 1631474107949, "ltp": 1.4, "tv": 528.63, "trd": NaN, "batb": [[0, 1.05, 232.09], [1, 1.04, 10.85], [2, 1.03, 232.09]], "batl": NaN}, {"timestamp": 1631474112026, "ltp": 1.4, "tv": 528.63, "trd": NaN, "batb": [[0, 1.08, 10.85], [1, 1.05, 232.09], [2, 1.04, 10.85]], "batl": NaN}, {"timestamp": 1631474168662, "ltp": 1.4, "tv": 528.63, "trd": NaN, "batb": NaN, "batl": [[0, 1.3, 3.62], [1, 1.7, 72.3]]}, {"timestamp": 1631474207924, "ltp": 1.4, "tv": 528.63, "trd": NaN, "batb": [[1, 1.04, 10.85], [2, 1.03, 232.09]], "batl": NaN}, {"timestamp": 1631474217819, "ltp": 1.4, "tv": 528.63, "trd": NaN, "batb": NaN, "batl": [[0, 1.3, 75.92]]}, {"timestamp": 1631474224365, "ltp": 1.4, "tv": 528.63, "trd": NaN, "batb": NaN, "batl": [[0, 1.16, 12.29], [1, 1.3, 75.92], [2, 1.7, 72.3]]}, {"timestamp": 1631474228053, "ltp": 1.4, "tv": 528.63, "trd": NaN, "batb": [[2, 1.02, 17.35]], "batl": NaN}, {"timestamp": 1631474251776, "ltp": 1.4, "tv": 528.63, "trd": NaN, "batb": NaN, "batl": [[1, 1.3, 3.62]]}, {"timestamp": 1631474257191, "ltp": 1.16, "tv": 540.88, "trd": [[1.16, 12.25]], "batb": NaN, "batl": [[0, 1.3, 3.66], [1, 1.7, 72.3], [2, 1.7, 0]]}, {"timestamp": 1631474279730, "ltp": 1.16, "tv": 540.88, "trd": NaN, "batb": [[0, 1.1, 72.3], [1, 1.08, 10.85], [2, 1.04, 10.85]], "batl": NaN}, {"timestamp": 1631474280519, "ltp": 1.32, "tv": 585.19, "trd": [[1.16, 12.33], [1.3, 11.67], [1.32, 37]], "batb": NaN, "batl": [[0, 1.7, 72.3], [1, 1.7, 0]]}, {"timestamp": 1631474294191, "ltp": 1.32, "tv": 585.19, "trd": NaN, "batb": [[0, 1.12, 15.91], [1, 1.1, 72.3], [2, 1.08, 10.85]], "batl": NaN}, {"timestamp": 1631474299922, "ltp": 1.32, "tv": 585.19, "trd": NaN, "batb": NaN, "batl": [[0, 1.4, 3.62], [1, 1.7, 72.3]]}, {"timestamp": 1631474310875, "ltp": 1.32, "tv": 585.19, "trd": NaN, "batb": NaN, "batl": [[0, 1.32, 23.86], [1, 1.4, 3.62], [2, 1.7, 72.3]]}, {"timestamp": 1631474315870, "ltp": 1.32, "tv": 585.19, "trd": NaN, "batb": [[1, 1.08, 10.85], [2, 1.04, 10.85]], "batl": NaN}, {"timestamp": 1631474328071, "ltp": 1.32, "tv": 585.19, "trd": NaN, "batb": [[0, 1.08, 10.85], [1, 1.04, 10.85], [2, 1.02, 17.35]], "batl": NaN}, {"timestamp": 1631474332801, "ltp": 1.32, "tv": 585.19, "trd": NaN, "batb": NaN, "batl": [[0, 1.4, 3.62], [1, 1.7, 72.3], [2, 1.7, 0]]}, {"timestamp": 1631474342988, "ltp": 1.32, "tv": 585.19, "trd": NaN, "batb": [[0, 1.09, 72.3], [1, 1.08, 10.85], [2, 1.04, 10.85]], "batl": NaN}, {"timestamp": 1631474351441, "ltp": 1.32, "tv": 585.19, "trd": NaN, "batb": [[0, 1.12, 11.57], [1, 1.09, 72.3], [2, 1.08, 10.85]], "batl": NaN}, {"timestamp": 1631474370049, "ltp": 1.32, "tv": 585.19, "trd": NaN, "batb": NaN, "batl": [[1, 1.7, 0]]}, {"timestamp": 1631474370939, "ltp": 1.32, "tv": 585.19, "trd": NaN, "batb": NaN, "batl": [[1, 1.5, 23.86]]}, {"timestamp": 1631474375171, "ltp": 1.32, "tv": 585.19, "trd": NaN, "batb": NaN, "batl": [[2, 2.4, 72.3]]}, {"timestamp": 1631474392268, "ltp": 1.32, "tv": 585.19, "trd": NaN, "batb": [[0, 1.09, 72.3], [1, 1.08, 10.85], [2, 1.04, 10.85]], "batl": NaN}, {"timestamp": 1631474396631, "ltp": 1.32, "tv": 585.19, "trd": NaN, "batb": [[1, 1.04, 10.85], [2, 1.02, 17.35]], "batl": NaN}, {"timestamp": 1631474405012, "ltp": 1.5, "tv": 590.25, "trd": [[1.4, 7.23], [1.5, 1.45]], "batb": NaN, "batl": [[0, 1.5, 22.41], [1, 2.4, 72.3], [2, 2.4, 0]]}, {"timestamp": 1631474414144, "ltp": 1.5, "tv": 590.25, "trd": NaN, "batb": [[0, 1.04, 10.85], [1, 1.02, 17.35], [2, 1.01, 297.39]], "batl": NaN}, {"timestamp": 1631474419828, "ltp": 1.5, "tv": 590.25, "trd": NaN, "batb": NaN, "batl": [[2, 1000, 2.17]]}, {"timestamp": 1631474420831, "ltp": 1.5, "tv": 590.25, "trd": NaN, "batb": NaN, "batl": [[2, 1000, 0]]}, {"timestamp": 1631474425955, "ltp": 1.5, "tv": 590.25, "trd": NaN, "batb": NaN, "batl": [[0, 1.4, 72.3], [1, 1.46, 1.45], [2, 1.5, 22.41]]}, {"timestamp": 1631474437477, "ltp": 1.5, "tv": 590.25, "trd": NaN, "batb": NaN, "batl": [[0, 1.38, 5.06], [1, 1.4, 72.3], [2, 1.46, 1.45]]}, {"timestamp": 1631474457889, "ltp": 1.5, "tv": 590.25, "trd": NaN, "batb": [[0, 1.05, 72.3], [1, 1.04, 10.85], [2, 1.02, 17.35]], "batl": [[0, 1.4, 72.3], [1, 1.46, 1.45], [2, 1.5, 22.41]]}, {"timestamp": 1631474457997, "ltp": 1.5, "tv": 590.25, "trd": NaN, "batb": NaN, "batl": [[1, 1.5, 22.41], [2, 2.4, 72.3]]}, {"timestamp": 1631474470015, "ltp": 1.5, "tv": 590.25, "trd": NaN, "batb": NaN, "batl": [[0, 1.5, 22.41], [1, 2.4, 72.3], [2, 2.4, 0]]}, {"timestamp": 1631474489486, "ltp": 1.5, "tv": 590.25, "trd": NaN, "batb": [[0, 1.1, 72.3], [1, 1.05, 72.3], [2, 1.04, 10.85]], "batl": NaN}, {"timestamp": 1631474514010, "ltp": 1.5, "tv": 590.25, "trd": NaN, "batb": [[0, 1.05, 72.3], [1, 1.04, 10.85], [2, 1.02, 17.35]], "batl": NaN}, {"timestamp": 1631474525031, "ltp": 1.5, "tv": 590.25, "trd": NaN, "batb": NaN, "batl": [[0, 1.5, 94.71]]}, {"timestamp": 1631474564486, "ltp": 1.5, "tv": 590.25, "trd": NaN, "batb": [[0, 1.08, 17.35], [1, 1.05, 72.3], [2, 1.04, 10.85]], "batl": NaN}, {"timestamp": 1631474567174, "ltp": 1.5, "tv": 590.25, "trd": NaN, "batb": NaN, "batl": [[0, 1.5, 22.41]]}, {"timestamp": 1631474577927, "ltp": 1.5, "tv": 590.25, "trd": NaN, "batb": NaN, "batl": [[1, 1.67, 72.3], [2, 2.4, 72.3]]}, {"timestamp": 1631474583321, "ltp": 1.5, "tv": 590.25, "trd": NaN, "batb": [[0, 1.1, 72.3], [1, 1.08, 17.35], [2, 1.05, 72.3]], "batl": NaN}, {"timestamp": 1631474584160, "ltp": 1.5, "tv": 590.25, "trd": NaN, "batb": [[0, 1.15, 11.57], [1, 1.1, 72.3], [2, 1.08, 17.35]], "batl": NaN}, {"timestamp": 1631474586157, "ltp": 1.5, "tv": 590.25, "trd": NaN, "batb": NaN, "batl": [[1, 2.4, 72.3], [2, 2.4, 0]]}, {"timestamp": 1631474591257, "ltp": 1.5, "tv": 590.25, "trd": NaN, "batb": NaN, "batl": [[1, 1.95, 72.3], [2, 2.4, 72.3]]}, {"timestamp": 1631474690515, "ltp": 1.5, "tv": 590.25, "trd": NaN, "batb": NaN, "batl": [[0, 1.95, 72.3], [1, 2.4, 72.3], [2, 2.4, 0]]}, {"timestamp": 1631474695594, "ltp": 1.5, "tv": 590.25, "trd": NaN, "batb": NaN, "batl": [[0, 1.62, 22.41], [1, 1.95, 72.3], [2, 2.4, 72.3]]}, {"timestamp": 1631474696114, "ltp": 1.5, "tv": 590.25, "trd": NaN, "batb": NaN, "batl": [[2, 2.4, 0]]}, {"timestamp": 1631474718666, "ltp": 1.5, "tv": 590.25, "trd": NaN, "batb": [[0, 1.16, 72.3], [1, 1.15, 11.57], [2, 1.1, 72.3]], "batl": NaN}, {"timestamp": 1631474748986, "ltp": 1.5, "tv": 590.25, "trd": NaN, "batb": [[0, 1.18, 17.35], [1, 1.16, 72.3], [2, 1.15, 11.57]], "batl": NaN}, {"timestamp": 1631474753999, "ltp": 1.5, "tv": 590.25, "trd": NaN, "batb": [[0, 1.18, 14.46]], "batl": NaN}, {"timestamp": 1631474755324, "ltp": 1.5, "tv": 590.25, "trd": NaN, "batb": [[2, 1.1, 72.3]], "batl": NaN}, {"timestamp": 1631474765017, "ltp": 1.18, "tv": 608.07, "trd": [[1.18, 17.82]], "batb": [[0, 1.18, 5.55]], "batl": NaN}, {"timestamp": 1631474772507, "ltp": 1.18, "tv": 608.07, "trd": NaN, "batb": [[1, 1.1, 72.3], [2, 1.08, 17.35]], "batl": NaN}, {"timestamp": 1631474787797, "ltp": 1.18, "tv": 608.07, "trd": NaN, "batb": [[0, 1.1, 72.3], [1, 1.08, 17.35], [2, 1.05, 72.3]], "batl": NaN}, {"timestamp": 1631474789022, "ltp": 1.18, "tv": 608.07, "trd": NaN, "batb": NaN, "batl": [[0, 1.34, 5.78], [1, 1.62, 22.41], [2, 1.95, 72.3]]}, {"timestamp": 1631474793128, "ltp": 1.18, "tv": 608.07, "trd": NaN, "batb": [[0, 1.14, 5.55], [1, 1.1, 72.3], [2, 1.08, 17.35]], "batl": NaN}, {"timestamp": 1631474808708, "ltp": 1.18, "tv": 608.07, "trd": NaN, "batb": [[0, 1.15, 72.3], [1, 1.14, 5.55], [2, 1.1, 72.3]], "batl": NaN}, {"timestamp": 1631474849890, "ltp": 1.34, "tv": 619.64, "trd": [[1.34, 11.57]], "batb": [[0, 1.34, 66.52], [1, 1.15, 72.3], [2, 1.14, 5.55]], "batl": [[0, 1.62, 22.41], [1, 1.95, 72.3], [2, 1.95, 0]]}, {"timestamp": 1631474852567, "ltp": 1.62, "tv": 634.12, "trd": [[1.62, 14.48]], "batb": [[1, 1.18, 5.78], [2, 1.15, 72.3]], "batl": [[0, 1.62, 7.93]]}, {"timestamp": 1631474853989, "ltp": 1.62, "tv": 634.12, "trd": NaN, "batb": [[0, 1.18, 5.78], [1, 1.15, 72.3], [2, 1.1, 72.3]], "batl": NaN}, {"timestamp": 1631474857093, "ltp": 1.62, "tv": 634.12, "trd": NaN, "batb": [[2, 1.12, 5.55]], "batl": NaN}, {"timestamp": 1631474867478, "ltp": 1.62, "tv": 634.12, "trd": NaN, "batb": NaN, "batl": [[2, 1000, 2.17]]}, {"timestamp": 1631474868515, "ltp": 1.62, "tv": 634.12, "trd": NaN, "batb": NaN, "batl": [[2, 1000, 0]]}, {"timestamp": 1631474871401, "ltp": 1.62, "tv": 634.12, "trd": NaN, "batb": NaN, "batl": [[0, 1.62, 31.79], [1, 1.95, 0]]}, {"timestamp": 1631474873594, "ltp": 1.62, "tv": 634.12, "trd": NaN, "batb": NaN, "batl": [[0, 1.62, 32.51]]}, {"timestamp": 1631474890010, "ltp": 1.62, "tv": 634.12, "trd": NaN, "batb": NaN, "batl": [[1, 2.6, 72.3]]}, {"timestamp": 1631474918676, "ltp": 1.62, "tv": 634.12, "trd": NaN, "batb": NaN, "batl": [[0, 1.62, 31.79]]}, {"timestamp": 1631474923765, "ltp": 1.62, "tv": 634.12, "trd": NaN, "batb": NaN, "batl": [[0, 1.62, 32.51]]}, {"timestamp": 1631474938178, "ltp": 1.62, "tv": 634.12, "trd": NaN, "batb": NaN, "batl": [[0, 1.62, 28.9]]}, {"timestamp": 1631474943187, "ltp": 1.62, "tv": 634.12, "trd": NaN, "batb": NaN, "batl": [[0, 1.62, 26.01]]}, {"timestamp": 1631474949413, "ltp": 1.62, "tv": 634.12, "trd": NaN, "batb": NaN, "batl": [[0, 1.47, 222], [1, 1.62, 22.39], [2, 2.6, 72.3]]}, {"timestamp": 1631474956854, "ltp": 1.62, "tv": 634.12, "trd": NaN, "batb": NaN, "batl": [[0, 1.62, 22.39], [1, 2.6, 72.3], [2, 2.6, 0]]}, {"timestamp": 1631474965037, "ltp": 1.62, "tv": 634.12, "trd": NaN, "batb": [[0, 1.2, 72.3], [1, 1.18, 5.78], [2, 1.15, 72.3]], "batl": NaN}, {"timestamp": 1631474970042, "ltp": 1.62, "tv": 634.12, "trd": NaN, "batb": [[0, 1.21, 222], [1, 1.2, 72.3], [2, 1.18, 5.78]], "batl": NaN}, {"timestamp": 1631474974046, "ltp": 1.62, "tv": 634.12, "trd": NaN, "batb": [[1, 1.2, 144.6]], "batl": [[0, 1.62, 21.67]]}, {"timestamp": 1631474979132, "ltp": 1.62, "tv": 634.12, "trd": NaN, "batb": NaN, "batl": [[0, 1.62, 22.39]]}, {"timestamp": 1631474980029, "ltp": 1.62, "tv": 634.12, "trd": NaN, "batb": [[0, 1.25, 72.3], [1, 1.21, 222], [2, 1.2, 144.6]], "batl": NaN}, {"timestamp": 1631474986347, "ltp": 1.62, "tv": 634.12, "trd": NaN, "batb": NaN, "batl": [[0, 2.6, 73.02], [1, 2.6, 0]]}, {"timestamp": 1631474991338, "ltp": 1.62, "tv": 634.12, "trd": NaN, "batb": NaN, "batl": [[0, 2.6, 72.3]]}, {"timestamp": 1631474998165, "ltp": 1.62, "tv": 634.12, "trd": NaN, "batb": [[0, 1.29, 222], [1, 1.25, 72.3], [2, 1.21, 222]], "batl": NaN}, {"timestamp": 1631475001964, "ltp": 1.62, "tv": 634.12, "trd": NaN, "batb": NaN, "batl": [[0, 2.4, 31.81], [1, 2.6, 72.3]]}, {"timestamp": 1631475003395, "ltp": 1.62, "tv": 634.12, "trd": NaN, "batb": [[0, 1.32, 13.01], [1, 1.29, 222], [2, 1.25, 72.3]], "batl": NaN}, {"timestamp": 1631475010004, "ltp": 1.62, "tv": 634.12, "trd": NaN, "batb": [[1, 1.3, 72.3], [2, 1.29, 222]], "batl": NaN}, {"timestamp": 1631475012990, "ltp": 1.62, "tv": 634.12, "trd": NaN, "batb": [[0, 1.35, 72.3], [1, 1.32, 13.01], [2, 1.3, 72.3]], "batl": NaN}, {"timestamp": 1631475024006, "ltp": 1.62, "tv": 634.12, "trd": NaN, "batb": [[0, 1.4, 72.3], [1, 1.35, 72.3], [2, 1.32, 13.01]], "batl": NaN}, {"timestamp": 1631475036607, "ltp": 1.62, "tv": 634.12, "trd": NaN, "batb": [[0, 1.42, 10.12], [1, 1.4, 72.3], [2, 1.35, 72.3]], "batl": NaN}, {"timestamp": 1631475039018, "ltp": 1.62, "tv": 634.12, "trd": NaN, "batb": NaN, "batl": [[0, 2.06, 23.86], [1, 2.4, 31.81], [2, 2.6, 72.3]]}, {"timestamp": 1631475052686, "ltp": 1.62, "tv": 634.12, "trd": NaN, "batb": NaN, "batl": [[0, 2.4, 31.81], [1, 2.6, 72.3], [2, 2.6, 0]]}, {"timestamp": 1631475057783, "ltp": 1.62, "tv": 634.12, "trd": NaN, "batb": NaN, "batl": [[0, 1.98, 23.86], [1, 2.4, 31.81], [2, 2.6, 72.3]]}, {"timestamp": 1631475066552, "ltp": 1.62, "tv": 634.12, "trd": NaN, "batb": NaN, "batl": [[2, 2.6, 0]]}, {"timestamp": 1631475075210, "ltp": 1.62, "tv": 634.12, "trd": NaN, "batb": NaN, "batl": [[0, 2.4, 31.81], [1, 2.4, 0]]}, {"timestamp": 1631475084057, "ltp": 1.62, "tv": 634.12, "trd": NaN, "batb": [[0, 1.42, 6.51]], "batl": NaN}, {"timestamp": 1631475089250, "ltp": 1.62, "tv": 634.12, "trd": NaN, "batb": NaN, "batl": [[0, 1.9, 7.23], [1, 2.4, 31.81]]}, {"timestamp": 1631475109382, "ltp": 1.62, "tv": 634.12, "trd": NaN, "batb": NaN, "batl": [[0, 2.4, 31.81], [1, 2.4, 0]]}, {"timestamp": 1631475111481, "ltp": 1.62, "tv": 634.12, "trd": NaN, "batb": NaN, "batl": [[0, 1.9, 59.66], [1, 2.4, 31.81]]}, {"timestamp": 1631475117182, "ltp": 1.62, "tv": 634.12, "trd": NaN, "batb": NaN, "batl": [[0, 2.4, 31.81], [1, 2.4, 0]]}, {"timestamp": 1631475122292, "ltp": 1.62, "tv": 634.12, "trd": NaN, "batb": NaN, "batl": [[0, 1.82, 59.66], [1, 2.4, 31.81]]}, {"timestamp": 1631475124699, "ltp": 1.62, "tv": 634.12, "trd": NaN, "batb": NaN, "batl": [[0, 2.4, 31.81], [1, 2.4, 0]]}, {"timestamp": 1631475126184, "ltp": 2.4, "tv": 639.35, "trd": [[2.4, 5.23]], "batb": NaN, "batl": [[0, 2.4, 26.59]]}, {"timestamp": 1631475128596, "ltp": 2.4, "tv": 639.35, "trd": NaN, "batb": [[0, 1.82, 46.93], [1, 1.42, 6.51], [2, 1.4, 72.3]], "batl": NaN}, {"timestamp": 1631475129118, "ltp": 2.4, "tv": 639.35, "trd": NaN, "batb": [[0, 1.42, 6.51], [1, 1.4, 72.3], [2, 1.35, 72.3]], "batl": NaN}, {"timestamp": 1631475131317, "ltp": 2.4, "tv": 639.35, "trd": NaN, "batb": [[0, 1.4, 72.3], [1, 1.35, 72.3], [2, 1.3, 72.3]], "batl": NaN}, {"timestamp": 1631475139164, "ltp": 2.4, "tv": 639.35, "trd": NaN, "batb": NaN, "batl": [[0, 2, 23.86], [1, 2.4, 26.59]]}, {"timestamp": 1631475148822, "ltp": 2.0, "tv": 663.2, "trd": [[2, 23.86]], "batb": NaN, "batl": [[0, 2.4, 26.59], [1, 2.4, 0]]}, {"timestamp": 1631475156848, "ltp": 2.0, "tv": 663.2, "trd": NaN, "batb": [[0, 1.42, 222], [1, 1.4, 72.3], [2, 1.35, 72.3]], "batl": NaN}, {"timestamp": 1631475176742, "ltp": 1.42, "tv": 668.72, "trd": [[1.42, 5.52]], "batb": [[0, 1.42, 219.24]], "batl": NaN}, {"timestamp": 1631475192021, "ltp": 1.42, "tv": 668.72, "trd": NaN, "batb": [[0, 1.4, 72.3], [1, 1.35, 72.3], [2, 1.3, 72.3]], "batl": NaN}, {"timestamp": 1631475202812, "ltp": 1.42, "tv": 668.72, "trd": NaN, "batb": NaN, "batl": [[0, 1.53, 2.56], [1, 2.4, 26.59]]}, {"timestamp": 1631475205355, "ltp": 1.42, "tv": 668.72, "trd": NaN, "batb": NaN, "batl": [[1, 2.4, 0]]}, {"timestamp": 1631475210434, "ltp": 1.42, "tv": 668.72, "trd": NaN, "batb": NaN, "batl": [[1, 2, 26.59]]}, {"timestamp": 1631475213660, "ltp": 1.53, "tv": 673.84, "trd": [[1.53, 5.12]], "batb": [[0, 1.53, 1.06], [1, 1.4, 72.3], [2, 1.35, 72.3]], "batl": [[0, 2, 26.59], [1, 2, 0]]}, {"timestamp": 1631475218261, "ltp": 1.53, "tv": 673.84, "trd": NaN, "batb": [[1, 1.2, 144.6], [2, 1.15, 72.3]], "batl": NaN}, {"timestamp": 1631475223296, "ltp": 1.53, "tv": 673.84, "trd": NaN, "batb": [[0, 1.2, 144.6], [1, 1.15, 72.3], [2, 1.1, 72.3]], "batl": NaN}, {"timestamp": 1631475229286, "ltp": 1.53, "tv": 673.84, "trd": NaN, "batb": [[0, 1.15, 72.3], [1, 1.1, 72.3], [2, 1.05, 72.3]], "batl": NaN}, {"timestamp": 1631475230386, "ltp": 1.53, "tv": 673.84, "trd": NaN, "batb": NaN, "batl": [[0, 1.66, 170], [1, 2, 26.59]]}, {"timestamp": 1631475232705, "ltp": 1.53, "tv": 673.84, "trd": NaN, "batb": [[0, 1.1, 72.3], [1, 1.05, 72.3], [2, 1.01, 297.39]], "batl": NaN}, {"timestamp": 1631475236172, "ltp": 1.53, "tv": 673.84, "trd": NaN, "batb": [[0, 1.05, 72.3], [1, 1.01, 297.39], [2, 1.01, 0]], "batl": NaN}, {"timestamp": 1631475242200, "ltp": 1.53, "tv": 673.84, "trd": NaN, "batb": NaN, "batl": [[0, 2, 26.59], [1, 2, 0]]}, {"timestamp": 1631475268511, "ltp": 1.53, "tv": 673.84, "trd": NaN, "batb": NaN, "batl": [[0, 1.7, 23.86]]}, {"timestamp": 1631475275641, "ltp": 1.53, "tv": 673.84, "trd": NaN, "batb": [[0, 1.7, 14.59], [1, 1.05, 72.3], [2, 1.01, 297.39]], "batl": NaN}, {"timestamp": 1631475276849, "ltp": 1.53, "tv": 673.84, "trd": NaN, "batb": [[0, 1.7, 9.77]], "batl": NaN}, {"timestamp": 1631475277852, "ltp": 1.53, "tv": 673.84, "trd": NaN, "batb": [[0, 1.05, 72.3], [1, 1.01, 297.39], [2, 1.01, 0]], "batl": NaN}, {"timestamp": 1631475283273, "ltp": 1.53, "tv": 673.84, "trd": NaN, "batb": NaN, "batl": [[0, 2, 15.91]]}, {"timestamp": 1631475284059, "ltp": 1.53, "tv": 673.84, "trd": NaN, "batb": [[0, 1.15, 15.18], [1, 1.05, 72.3], [2, 1.01, 297.39]], "batl": NaN}, {"timestamp": 1631475286744, "ltp": 1.78, "tv": 677.45, "trd": [[1.78, 3.62]], "batb": NaN, "batl": NaN}, {"timestamp": 1631475300844, "ltp": 1.78, "tv": 677.45, "trd": NaN, "batb": [[0, 2, 15.9], [1, 1.15, 15.18], [2, 1.05, 72.3]], "batl": NaN}, {"timestamp": 1631475301479, "ltp": 1.78, "tv": 677.45, "trd": NaN, "batb": [[0, 1.15, 15.18], [1, 1.05, 72.3], [2, 1.01, 297.39]], "batl": NaN}, {"timestamp": 1631475303486, "ltp": 1.78, "tv": 677.45, "trd": NaN, "batb": [[0, 1.05, 72.3], [1, 1.01, 297.39], [2, 1.01, 0]], "batl": NaN}, {"timestamp": 1631475308453, "ltp": 1.78, "tv": 677.45, "trd": NaN, "batb": NaN, "batl": [[0, 2.3, 21.99]]}, {"timestamp": 1631475332717, "ltp": 2.3, "tv": 721.42, "trd": [[2.3, 43.97]], "batb": NaN, "batl": NaN}, {"timestamp": 1631475344404, "ltp": 2.3, "tv": 721.42, "trd": NaN, "batb": [[1, 1.01, 0]], "batl": NaN}, {"timestamp": 1631475362362, "ltp": 2.3, "tv": 721.42, "trd": NaN, "batb": [[0, 1.05, 304.39]], "batl": NaN}, {"timestamp": 1631475383846, "ltp": 2.3, "tv": 721.42, "trd": NaN, "batb": [[0, 1.06, 435.56], [1, 1.05, 304.39]], "batl": NaN}, {"timestamp": 1631475396366, "ltp": 2.3, "tv": 721.42, "trd": NaN, "batb": [[0, 1.1, 472.85], [1, 1.06, 435.56], [2, 1.05, 304.39]], "batl": NaN}, {"timestamp": 1631475410598, "ltp": 2.3, "tv": 721.42, "trd": NaN, "batb": [[0, 1.11, 472.29], [1, 1.1, 472.85], [2, 1.06, 435.56]], "batl": NaN}, {"timestamp": 1631475414491, "ltp": 2.3, "tv": 721.42, "trd": NaN, "batb": [[1, 1.06, 435.56], [2, 1.05, 304.39]], "batl": NaN}, {"timestamp": 1631475419597, "ltp": 2.3, "tv": 721.42, "trd": NaN, "batb": [[0, 1.13, 472.85], [1, 1.11, 472.29], [2, 1.06, 435.56]], "batl": NaN}, {"timestamp": 1631475427838, "ltp": 2.3, "tv": 721.42, "trd": NaN, "batb": [[0, 1.2, 472.29], [1, 1.13, 472.85], [2, 1.11, 472.29]], "batl": NaN}, {"timestamp": 1631475430897, "ltp": 2.3, "tv": 721.42, "trd": NaN, "batb": [[0, 1.3, 472.29], [1, 1.2, 544.59], [2, 1.13, 472.85]], "batl": NaN}, {"timestamp": 1631475445029, "ltp": 2.3, "tv": 721.42, "trd": NaN, "batb": [[0, 1.2, 544.59], [1, 1.13, 472.85], [2, 1.11, 472.29]], "batl": NaN}, {"timestamp": 1631475446511, "ltp": 2.3, "tv": 721.42, "trd": NaN, "batb": [[0, 1.31, 72.3], [1, 1.2, 544.59], [2, 1.13, 472.85]], "batl": NaN}, {"timestamp": 1631475449550, "ltp": 2.3, "tv": 721.42, "trd": NaN, "batb": [[1, 1.2, 472.29], [2, 1.11, 472.29]], "batl": NaN}, {"timestamp": 1631475455856, "ltp": 2.3, "tv": 721.42, "trd": NaN, "batb": [[0, 1.32, 81.13], [1, 1.31, 72.3], [2, 1.2, 472.29]], "batl": NaN}, {"timestamp": 1631475459461, "ltp": 2.3, "tv": 721.42, "trd": NaN, "batb": [[1, 1.2, 472.29], [2, 1.11, 472.29]], "batl": NaN}, {"timestamp": 1631475473091, "ltp": 2.3, "tv": 721.42, "trd": NaN, "batb": [[0, 1.11, 472.29], [1, 1.06, 435.56], [2, 1.05, 304.39]], "batl": NaN}, {"timestamp": 1631475479202, "ltp": 2.3, "tv": 721.42, "trd": NaN, "batb": [[0, 1.06, 435.56], [1, 1.05, 304.39], [2, 1.05, 0]], "batl": NaN}, {"timestamp": 1631475497528, "ltp": 2.3, "tv": 721.42, "trd": NaN, "batb": [[1, 1.05, 72.3]], "batl": NaN}, {"timestamp": 1631475502626, "ltp": 2.3, "tv": 721.42, "trd": NaN, "batb": [[0, 1.07, 232.09], [1, 1.06, 435.56], [2, 1.05, 72.3]], "batl": NaN}, {"timestamp": 1631475512062, "ltp": 2.3, "tv": 721.42, "trd": NaN, "batb": [[0, 1.2, 473.99], [1, 1.07, 232.09], [2, 1.06, 435.56]], "batl": NaN}, {"timestamp": 1631475515571, "ltp": 2.3, "tv": 721.42, "trd": NaN, "batb": [[0, 1.2, 546.3]], "batl": NaN}, {"timestamp": 1631475533597, "ltp": 2.3, "tv": 721.42, "trd": NaN, "batb": [[0, 1.22, 72.3], [1, 1.2, 546.3], [2, 1.07, 232.09]], "batl": NaN}, {"timestamp": 1631475548522, "ltp": 2.3, "tv": 721.42, "trd": NaN, "batb": [[0, 1.24, 81.13], [1, 1.2, 473.99], [2, 1.06, 435.56]], "batl": NaN}, {"timestamp": 1631475554898, "ltp": 2.3, "tv": 721.42, "trd": NaN, "batb": [[1, 1.06, 435.56], [2, 1.06, 0]], "batl": NaN}, {"timestamp": 1631475557521, "ltp": 2.3, "tv": 721.42, "trd": NaN, "batb": [[0, 1.3, 72.3], [1, 1.24, 81.13], [2, 1.06, 435.56]], "batl": NaN}, {"timestamp": 1631475559982, "ltp": 2.3, "tv": 721.42, "trd": NaN, "batb": [[0, 1.35, 473.99], [1, 1.3, 72.3], [2, 1.24, 81.13]], "batl": NaN}, {"timestamp": 1631475565919, "ltp": 2.3, "tv": 721.42, "trd": NaN, "batb": [[0, 1.4, 72.3], [1, 1.35, 473.99], [2, 1.3, 72.3]], "batl": NaN}, {"timestamp": 1631475570507, "ltp": 2.3, "tv": 721.42, "trd": NaN, "batb": [[0, 1.5, 81.13], [1, 1.4, 72.3], [2, 1.35, 473.99]], "batl": NaN}, {"timestamp": 1631475574410, "ltp": 2.3, "tv": 721.42, "trd": NaN, "batb": [[0, 1.55, 72.3], [1, 1.5, 81.13], [2, 1.4, 72.3]], "batl": NaN}, {"timestamp": 1631475580149, "ltp": 2.3, "tv": 721.42, "trd": NaN, "batb": [[0, 1.6, 81.13], [1, 1.55, 72.3], [2, 1.5, 81.13]], "batl": NaN}, {"timestamp": 1631475582883, "ltp": 2.3, "tv": 721.42, "trd": NaN, "batb": [[0, 1.62, 72.3], [1, 1.6, 81.13], [2, 1.55, 72.3]], "batl": NaN}, {"timestamp": 1631475584468, "ltp": 2.3, "tv": 721.42, "trd": NaN, "batb": [[0, 1.6, 81.13], [1, 1.5, 81.13], [2, 1.35, 473.99]], "batl": NaN}, {"timestamp": 1631475591825, "ltp": 2.3, "tv": 721.42, "trd": NaN, "batb": [[0, 1.64, 81.13], [1, 1.6, 81.13], [2, 1.5, 81.13]], "batl": NaN}, {"timestamp": 1631475606923, "ltp": 2.3, "tv": 721.42, "trd": NaN, "batb": [[0, 1.35, 473.99], [1, 1.06, 435.56], [2, 1.5, 0]], "batl": NaN}, {"timestamp": 1631475619715, "ltp": 2.3, "tv": 721.42, "trd": NaN, "batb": [[0, 1.1, 72.3]], "batl": NaN}, {"timestamp": 1631475635885, "ltp": 2.3, "tv": 721.42, "trd": NaN, "batb": [[0, 1.11, 284.4], [1, 1.1, 72.3]], "batl": NaN}, {"timestamp": 1631475649532, "ltp": 2.3, "tv": 721.42, "trd": NaN, "batb": [[0, 1.15, 72.3], [1, 1.11, 284.4], [2, 1.1, 72.3]], "batl": NaN}, {"timestamp": 1631475659573, "ltp": 2.3, "tv": 721.42, "trd": NaN, "batb": [[0, 1.17, 284.4], [1, 1.15, 72.3], [2, 1.11, 284.4]], "batl": NaN}, {"timestamp": 1631475670748, "ltp": 2.3, "tv": 721.42, "trd": NaN, "batb": [[0, 1.2, 72.3], [1, 1.17, 284.4], [2, 1.15, 72.3]], "batl": NaN}, {"timestamp": 1631475680469, "ltp": 2.3, "tv": 721.42, "trd": NaN, "batb": [[0, 1.21, 284.4], [1, 1.2, 72.3], [2, 1.17, 284.4]], "batl": NaN}, {"timestamp": 1631475691405, "ltp": 2.3, "tv": 721.42, "trd": NaN, "batb": [[0, 1.25, 72.3], [1, 1.21, 284.4], [2, 1.2, 72.3]], "batl": NaN}, {"timestamp": 1631475701590, "ltp": 2.3, "tv": 721.42, "trd": NaN, "batb": [[0, 1.26, 284.4], [1, 1.25, 72.3], [2, 1.21, 284.4]], "batl": NaN}, {"timestamp": 1631475721028, "ltp": 2.3, "tv": 721.42, "trd": NaN, "batb": [[1, 1.21, 284.4], [2, 1.17, 284.4]], "batl": NaN}, {"timestamp": 1631475733660, "ltp": 2.3, "tv": 721.42, "trd": NaN, "batb": [[0, 1.3, 72.3], [1, 1.26, 284.4], [2, 1.21, 284.4]], "batl": NaN}, {"timestamp": 1631475735656, "ltp": 2.3, "tv": 721.42, "trd": NaN, "batb": [[0, 1.35, 72.3], [1, 1.3, 72.3], [2, 1.26, 284.4]], "batl": NaN}, {"timestamp": 1631475737351, "ltp": 2.3, "tv": 721.42, "trd": NaN, "batb": [[2, 1.21, 284.4]], "batl": NaN}, {"timestamp": 1631475738135, "ltp": 2.3, "tv": 721.42, "trd": NaN, "batb": [[0, 1.4, 72.3], [1, 1.35, 72.3], [2, 1.3, 72.3]], "batl": NaN}, {"timestamp": 1631475740291, "ltp": 2.3, "tv": 721.42, "trd": NaN, "batb": [[0, 1.45, 72.3], [1, 1.4, 72.3], [2, 1.35, 72.3]], "batl": NaN}, {"timestamp": 1631475749692, "ltp": 2.3, "tv": 721.42, "trd": NaN, "batb": [[0, 1.5, 81.13], [1, 1.45, 72.3], [2, 1.4, 72.3]], "batl": NaN}, {"timestamp": 1631475751600, "ltp": 2.3, "tv": 721.42, "trd": NaN, "batb": [[0, 1.55, 81.13], [1, 1.5, 81.13], [2, 1.45, 72.3]], "batl": NaN}, {"timestamp": 1631475753374, "ltp": 2.3, "tv": 721.42, "trd": NaN, "batb": [[0, 1.6, 81.13], [1, 1.55, 81.13], [2, 1.5, 81.13]], "batl": NaN}, {"timestamp": 1631475791552, "ltp": 2.3, "tv": 721.42, "trd": NaN, "batb": [[0, 1.15, 72.3]], "batl": NaN}, {"timestamp": 1631475803211, "ltp": 2.3, "tv": 721.42, "trd": NaN, "batb": [[0, 1.2, 81.13], [1, 1.15, 72.3]], "batl": NaN}, {"timestamp": 1631475804826, "ltp": 2.3, "tv": 721.42, "trd": NaN, "batb": [[0, 1.2, 153.44]], "batl": NaN}, {"timestamp": 1631475817074, "ltp": 2.3, "tv": 721.42, "trd": NaN, "batb": [[0, 1.22, 72.3], [1, 1.2, 153.44], [2, 1.15, 72.3]], "batl": NaN}, {"timestamp": 1631475822649, "ltp": 2.3, "tv": 721.42, "trd": NaN, "batb": [[0, 1.2, 81.13], [1, 1.2, 0], [2, 1.15, 0]], "batl": NaN}, {"timestamp": 1631475825944, "ltp": 2.3, "tv": 721.42, "trd": NaN, "batb": [[0, 1.24, 81.13], [1, 1.2, 81.13]], "batl": NaN}, {"timestamp": 1631475845795, "ltp": 2.3, "tv": 721.42, "trd": NaN, "batb": [[0, 1.15, 2]], "batl": NaN}, {"timestamp": 1631475850798, "ltp": 2.3, "tv": 721.42, "trd": NaN, "batb": [[1, 1.05, 232.09]], "batl": NaN}, {"timestamp": 1631475860073, "ltp": 2.3, "tv": 721.42, "trd": NaN, "batb": [[1, 1.05, 0]], "batl": NaN}, {"timestamp": 1631475862891, "ltp": 2.3, "tv": 721.42, "trd": NaN, "batb": [[1, 1.1, 256.21]], "batl": NaN}, {"timestamp": 1631475868111, "ltp": 2.3, "tv": 721.42, "trd": NaN, "batb": [[0, 1.2, 72.3], [1, 1.15, 2], [2, 1.1, 256.21]], "batl": NaN}, {"timestamp": 1631475878001, "ltp": 2.3, "tv": 721.42, "trd": NaN, "batb": [[0, 1.22, 81.13], [1, 1.2, 72.3], [2, 1.15, 2]], "batl": NaN}, {"timestamp": 1631475892312, "ltp": 2.3, "tv": 721.42, "trd": NaN, "batb": [[1, 1.15, 2], [2, 1.1, 256.21]], "batl": NaN}, {"timestamp": 1631475895214, "ltp": 2.3, "tv": 721.42, "trd": NaN, "batb": [[0, 1.15, 2], [1, 1.15, 0], [2, 1.1, 0]], "batl": NaN}, {"timestamp": 1631475946976, "ltp": 2.3, "tv": 721.42, "trd": NaN, "batb": NaN, "batl": [[0, 1.01, 7686.4]]}, {"timestamp": 1631475948701, "ltp": 2.3, "tv": 721.42, "trd": NaN, "batb": NaN, "batl": [[0, 1.01, 7703.48], [1, 1.15, 21.99]]}, {"timestamp": 1631475953720, "ltp": 2.3, "tv": 721.42, "trd": NaN, "batb": NaN, "batl": [[1, 1.15, 0]]}, {"timestamp": 1631475954818, "ltp": 2.3, "tv": 721.42, "trd": NaN, "batb": NaN, "batl": [[1, 1.2, 768.64]]}, {"timestamp": 1631475956820, "ltp": 2.3, "tv": 721.42, "trd": NaN, "batb": NaN, "batl": [[1, 1.02, 768.64], [2, 1.2, 768.64]]}, {"timestamp": 1631475959908, "ltp": 2.3, "tv": 721.42, "trd": NaN, "batb": NaN, "batl": [[0, 1.01, 7710.71]]}, {"timestamp": 1631475964923, "ltp": 2.3, "tv": 721.42, "trd": NaN, "batb": NaN, "batl": [[2, 1.05, 768.64]]}]}]}