{"info": {"id": "1.187595433", "eventId": "30897878", "eventName": "Match Odds", "marketType": "MATCH_ODDS", "openDate": 1631525491703, "name": "A Gamiz v K Bartone", "numberOfActiveRunner": 2, "countryCode": "", "sport": "TENNIS", "venue": "", "volume": {"total": 80.24, "preMatch": 5.52, "inPlay": 74.72}, "winner": {"id": 9626775, "name": "A Gamiz", "status": "WINNER", "position": 1}, "delay": 5}, "runners": [{"id": 9626775, "name": "A Gamiz", "status": "WINNER", "position": 1, "inPlayOdds": 2.24, "inPlayTime": 1631525491703, "avgPrematch": 2.24, "closedOdds": 1.01, "maxPrematch": 2.24, "minPrematch": 2.24, "maxInPlay": 2.24, "minInPlay": 1.01, "inPlayIndex": 2, "lengthOdds": 314, "lengthOddsPrematch": 2, "lengthOddsInPlay": 312, "tradedVolume": 73.64, "preMatchVolume": 5.32, "inPlayVolume": 68.32}, {"id": 22955132, "name": "K Bartone", "status": "LOSER", "position": 2, "inPlayOdds": 8.0, "inPlayTime": 1631531701889, "avgPrematch": 0, "closedOdds": 8.0, "maxPrematch": -100, "minPrematch": 1001, "maxInPlay": 8.0, "minInPlay": 8.0, "inPlayIndex": 0, "lengthOdds": 8, "lengthOddsPrematch": 0, "lengthOddsInPlay": 8, "tradedVolume": 6.6, "preMatchVolume": 0.2, "inPlayVolume": 6.4}], "marketUpdates": [{"timestamp": 1631518765917000000, "openDate": "2021-09-13T09:30:00.000Z", "status": "OPEN", "betDelay": 0, "inPlay": false, "complete": true}, {"timestamp": 1631525491703000000, "openDate": "2021-09-13T09:30:00.000Z", "status": "OPEN", "betDelay": 5, "inPlay": true, "complete": true}, {"timestamp": 1631525941326000000, "openDate": "2021-09-13T09:38:57.000Z", "status": "OPEN", "betDelay": 5, "inPlay": true, "complete": true}, {"timestamp": 1631532319667000000, "openDate": "2021-09-13T09:38:57.000Z", "status": "SUSPENDED", "betDelay": 5, "inPlay": true, "complete": true}, {"timestamp": 1631532321682000000, "openDate": "2021-09-13T09:38:57.000Z", "status": "CLOSED", "betDelay": 5, "inPlay": true, "complete": true}], "odds": [{"runnerId": 9626775, "odds": [{"timestamp": 1631525135701, "ltp": 2.24, "tv": 5.32, "trd": [[2.24, 5.32]], "batb": [[0, 2.24, 33.68]], "batl": NaN}, {"timestamp": 1631525139520, "ltp": 2.24, "tv": 5.32, "trd": NaN, "batb": [[0, 2.24, 36.34]], "batl": NaN}, {"timestamp": 1631525491703, "ltp": 2.24, "tv": 5.32, "trd": NaN, "batb": [[0, 1.01, 7], [1, 1.05, 0], [2, 1.01, 0]], "batl": NaN}, {"timestamp": 1631526349062, "ltp": 2.24, "tv": 5.32, "trd": NaN, "batb": [[0, 1.7, 415.78], [1, 1.01, 7]], "batl": [[0, 2.82, 234.93], [1, 2.88, 106.55]]}, {"timestamp": 1631526391910, "ltp": 2.24, "tv": 5.32, "trd": NaN, "batb": [[0, 1.01, 7], [1, 1.01, 0]], "batl": [[0, 2.88, 106.55], [1, 2.88, 0]]}, {"timestamp": 1631526397711, "ltp": 2.24, "tv": 5.32, "trd": NaN, "batb": [[0, 1.82, 407.57], [1, 1.01, 7]], "batl": [[1, 3.15, 203.58]]}, {"timestamp": 1631526459090, "ltp": 2.24, "tv": 5.32, "trd": NaN, "batb": NaN, "batl": [[1, 3.15, 0]]}, {"timestamp": 1631526464511, "ltp": 2.24, "tv": 5.32, "trd": NaN, "batb": NaN, "batl": [[1, 2.92, 224.75]]}, {"timestamp": 1631526740594, "ltp": 2.24, "tv": 5.32, "trd": NaN, "batb": [[0, 1.01, 7], [1, 1.01, 0]], "batl": [[1, 2.92, 0]]}, {"timestamp": 1631526746112, "ltp": 2.24, "tv": 5.32, "trd": NaN, "batb": [[0, 1.62, 421.99], [1, 1.01, 7]], "batl": [[0, 2.6, 261.64], [1, 2.88, 106.55]]}, {"timestamp": 1631526845327, "ltp": 2.24, "tv": 5.32, "trd": NaN, "batb": [[0, 1.01, 7], [1, 1.01, 0]], "batl": NaN}, {"timestamp": 1631526851451, "ltp": 2.24, "tv": 5.32, "trd": NaN, "batb": [[0, 1.7, 415.78], [1, 1.01, 7]], "batl": NaN}, {"timestamp": 1631526956256, "ltp": 2.24, "tv": 5.32, "trd": NaN, "batb": [[0, 1.01, 7], [1, 1.01, 0]], "batl": [[0, 2.88, 106.55], [1, 2.88, 0]]}, {"timestamp": 1631526961951, "ltp": 2.24, "tv": 5.32, "trd": NaN, "batb": [[0, 1.77, 408.62], [1, 1.01, 7]], "batl": [[1, 3, 216.82]]}, {"timestamp": 1631526985794, "ltp": 2.24, "tv": 5.32, "trd": NaN, "batb": [[0, 1.01, 7], [1, 1.01, 0]], "batl": NaN}, {"timestamp": 1631526991210, "ltp": 2.24, "tv": 5.32, "trd": NaN, "batb": [[0, 1.86, 404.92], [1, 1.01, 7]], "batl": NaN}, {"timestamp": 1631527160647, "ltp": 2.24, "tv": 5.32, "trd": NaN, "batb": [[0, 1.01, 7], [1, 1.01, 0]], "batl": [[1, 3, 0]]}, {"timestamp": 1631527166757, "ltp": 2.24, "tv": 5.32, "trd": NaN, "batb": [[0, 1.97, 401.09], [1, 1.01, 7]], "batl": [[1, 3.65, 173.1]]}, {"timestamp": 1631527200216, "ltp": 2.24, "tv": 5.32, "trd": NaN, "batb": NaN, "batl": [[1, 3.65, 0]]}, {"timestamp": 1631527206022, "ltp": 2.24, "tv": 5.32, "trd": NaN, "batb": NaN, "batl": [[1, 3.3, 194.95]]}, {"timestamp": 1631527250835, "ltp": 2.24, "tv": 5.32, "trd": NaN, "batb": [[0, 1.01, 7], [1, 1.01, 0]], "batl": [[1, 3.3, 0]]}, {"timestamp": 1631527256656, "ltp": 2.24, "tv": 5.32, "trd": NaN, "batb": [[0, 1.74, 410.67], [1, 1.01, 7]], "batl": [[1, 2.92, 224.75]]}, {"timestamp": 1631527279409, "ltp": 2.24, "tv": 5.32, "trd": NaN, "batb": NaN, "batl": [[1, 2.92, 0]]}, {"timestamp": 1631527284995, "ltp": 2.24, "tv": 5.32, "trd": NaN, "batb": NaN, "batl": [[0, 2.72, 245.36], [1, 2.88, 106.55]]}, {"timestamp": 1631527435675, "ltp": 2.24, "tv": 5.32, "trd": NaN, "batb": [[0, 1.01, 7], [1, 1.01, 0]], "batl": [[0, 2.88, 106.55], [1, 2.88, 0]]}, {"timestamp": 1631527442021, "ltp": 2.24, "tv": 5.32, "trd": NaN, "batb": [[0, 1.62, 421.99], [1, 1.01, 7]], "batl": [[0, 2.6, 261.64], [1, 2.88, 106.55]]}, {"timestamp": 1631527444821, "ltp": 2.24, "tv": 5.32, "trd": NaN, "batb": NaN, "batl": [[0, 2.88, 106.55], [1, 2.88, 0]]}, {"timestamp": 1631527451105, "ltp": 2.24, "tv": 5.32, "trd": NaN, "batb": NaN, "batl": [[0, 2.5, 278.88], [1, 2.88, 106.55]]}, {"timestamp": 1631527512920, "ltp": 2.24, "tv": 5.32, "trd": NaN, "batb": [[0, 1.01, 7], [1, 1.01, 0]], "batl": [[0, 2.88, 106.55], [1, 2.88, 0]]}, {"timestamp": 1631527518910, "ltp": 2.24, "tv": 5.32, "trd": NaN, "batb": [[0, 1.74, 410.67], [1, 1.01, 7]], "batl": [[1, 2.92, 224.75]]}, {"timestamp": 1631527546484, "ltp": 2.24, "tv": 5.32, "trd": NaN, "batb": [[0, 1.01, 7], [1, 1.01, 0]], "batl": [[1, 2.92, 0]]}, {"timestamp": 1631527552372, "ltp": 2.24, "tv": 5.32, "trd": NaN, "batb": [[0, 1.62, 421.99], [1, 1.01, 7]], "batl": [[0, 2.6, 261.64], [1, 2.88, 106.55]]}, {"timestamp": 1631527569799, "ltp": 2.24, "tv": 5.32, "trd": NaN, "batb": [[0, 1.01, 7], [1, 1.01, 0]], "batl": NaN}, {"timestamp": 1631527575737, "ltp": 2.24, "tv": 5.32, "trd": NaN, "batb": [[0, 1.67, 416.23], [1, 1.01, 7]], "batl": NaN}, {"timestamp": 1631527587035, "ltp": 2.24, "tv": 5.32, "trd": NaN, "batb": [[0, 1.01, 7], [1, 1.01, 0]], "batl": [[0, 2.88, 106.55], [1, 2.88, 0]]}, {"timestamp": 1631527592817, "ltp": 2.24, "tv": 5.32, "trd": NaN, "batb": [[0, 1.74, 410.67], [1, 1.01, 7]], "batl": [[1, 2.92, 224.75]]}, {"timestamp": 1631527616472, "ltp": 2.24, "tv": 5.32, "trd": NaN, "batb": [[0, 1.01, 7], [1, 1.01, 0]], "batl": [[1, 2.92, 0]]}, {"timestamp": 1631527622166, "ltp": 2.24, "tv": 5.32, "trd": NaN, "batb": [[0, 1.62, 421.99], [1, 1.01, 7]], "batl": [[0, 2.6, 261.64], [1, 2.88, 106.55]]}, {"timestamp": 1631527657008, "ltp": 2.24, "tv": 5.32, "trd": NaN, "batb": [[0, 1.01, 7], [1, 1.01, 0]], "batl": [[0, 2.88, 106.55], [1, 2.88, 0]]}, {"timestamp": 1631527662603, "ltp": 2.24, "tv": 5.32, "trd": NaN, "batb": [[0, 1.74, 410.67], [1, 1.01, 7]], "batl": [[1, 2.92, 224.75]]}, {"timestamp": 1631527698659, "ltp": 2.24, "tv": 5.32, "trd": NaN, "batb": [[0, 1.01, 7], [1, 1.01, 0]], "batl": NaN}, {"timestamp": 1631527704154, "ltp": 2.24, "tv": 5.32, "trd": NaN, "batb": [[0, 1.82, 407.57], [1, 1.01, 7]], "batl": NaN}, {"timestamp": 1631527875370, "ltp": 2.24, "tv": 5.32, "trd": NaN, "batb": [[0, 1.01, 7], [1, 1.01, 0]], "batl": [[1, 2.92, 0]]}, {"timestamp": 1631527881727, "ltp": 2.24, "tv": 5.32, "trd": NaN, "batb": [[0, 1.97, 401.09], [1, 1.01, 7]], "batl": [[1, 3.65, 173.1]]}, {"timestamp": 1631527920353, "ltp": 2.24, "tv": 5.32, "trd": NaN, "batb": NaN, "batl": [[1, 3.65, 0]]}, {"timestamp": 1631527926259, "ltp": 2.24, "tv": 5.32, "trd": NaN, "batb": NaN, "batl": [[1, 3.15, 203.58]]}, {"timestamp": 1631527933703, "ltp": 2.24, "tv": 5.32, "trd": NaN, "batb": [[0, 1.01, 7], [1, 1.01, 0]], "batl": [[1, 3.15, 0]]}, {"timestamp": 1631528073846, "ltp": 2.24, "tv": 5.32, "trd": NaN, "batb": [[0, 1.62, 421.99], [1, 1.01, 7]], "batl": [[0, 2.6, 261.64], [1, 2.88, 106.55]]}, {"timestamp": 1631528181881, "ltp": 2.24, "tv": 5.32, "trd": NaN, "batb": [[0, 1.01, 7], [1, 1.01, 0]], "batl": [[0, 2.88, 106.55], [1, 2.88, 0]]}, {"timestamp": 1631528499854, "ltp": 2.24, "tv": 5.32, "trd": NaN, "batb": [[0, 1.52, 432.21], [1, 1.01, 7]], "batl": [[0, 2.36, 303.89], [1, 2.88, 106.55]]}, {"timestamp": 1631528515276, "ltp": 2.24, "tv": 5.32, "trd": NaN, "batb": NaN, "batl": [[0, 2.1, 256.04], [1, 2.36, 303.89], [2, 2.88, 106.55]]}, {"timestamp": 1631528524894, "ltp": 2.24, "tv": 5.32, "trd": NaN, "batb": [[0, 1.01, 7], [1, 1.01, 0]], "batl": [[1, 2.88, 106.55], [2, 2.88, 0]]}, {"timestamp": 1631528547507, "ltp": 2.24, "tv": 5.32, "trd": NaN, "batb": [[0, 1.38, 455.53], [1, 1.01, 7]], "batl": [[0, 2.04, 389.06], [1, 2.1, 256.04], [2, 2.88, 106.55]]}, {"timestamp": 1631528562307, "ltp": 2.24, "tv": 5.32, "trd": NaN, "batb": NaN, "batl": [[1, 2.88, 106.55], [2, 2.88, 0]]}, {"timestamp": 1631528566409, "ltp": 2.24, "tv": 5.32, "trd": NaN, "batb": NaN, "batl": [[0, 1.8, 256.04], [1, 2.04, 389.06], [2, 2.88, 106.55]]}, {"timestamp": 1631528569515, "ltp": 2.24, "tv": 5.32, "trd": NaN, "batb": [[0, 1.47, 256.04], [1, 1.38, 455.53], [2, 1.01, 7]], "batl": NaN}, {"timestamp": 1631528579249, "ltp": 2.24, "tv": 5.32, "trd": NaN, "batb": [[0, 1.38, 455.53], [1, 1.01, 7], [2, 1.01, 0]], "batl": NaN}, {"timestamp": 1631528580256, "ltp": 2.24, "tv": 5.32, "trd": NaN, "batb": [[0, 1.01, 7], [1, 1.01, 0]], "batl": [[1, 2.88, 106.55], [2, 2.88, 0]]}, {"timestamp": 1631528585353, "ltp": 2.24, "tv": 5.32, "trd": NaN, "batb": [[0, 1.4, 256.04], [1, 1.01, 7]], "batl": NaN}, {"timestamp": 1631528586138, "ltp": 2.24, "tv": 5.32, "trd": NaN, "batb": [[1, 1.31, 485.05], [2, 1.01, 7]], "batl": [[1, 1.89, 442.15], [2, 2.88, 106.55]]}, {"timestamp": 1631528596143, "ltp": 2.24, "tv": 5.32, "trd": NaN, "batb": NaN, "batl": [[0, 1.6, 256.04], [1, 1.8, 256.04], [2, 1.89, 442.15]]}, {"timestamp": 1631528607863, "ltp": 2.24, "tv": 5.32, "trd": NaN, "batb": [[1, 1.01, 7], [2, 1.01, 0]], "batl": NaN}, {"timestamp": 1631528609160, "ltp": 2.24, "tv": 5.32, "trd": NaN, "batb": NaN, "batl": [[0, 1.8, 256.04], [1, 1.89, 442.15], [2, 2.88, 106.55]]}, {"timestamp": 1631528613471, "ltp": 2.24, "tv": 5.32, "trd": NaN, "batb": [[1, 1.38, 455.53], [2, 1.01, 7]], "batl": [[0, 1.89, 442.15], [1, 2.88, 106.55], [2, 2.88, 0]]}, {"timestamp": 1631528614874, "ltp": 2.24, "tv": 5.32, "trd": NaN, "batb": NaN, "batl": [[0, 1.7, 256.04], [1, 1.89, 442.15], [2, 2.88, 106.55]]}, {"timestamp": 1631528619081, "ltp": 2.24, "tv": 5.32, "trd": NaN, "batb": [[1, 1.01, 7], [2, 1.01, 0]], "batl": [[1, 2.88, 106.55], [2, 2.88, 0]]}, {"timestamp": 1631528624898, "ltp": 2.24, "tv": 5.32, "trd": NaN, "batb": [[0, 1.44, 443.07], [1, 1.4, 256.04], [2, 1.01, 7]], "batl": [[1, 2.16, 348.23], [2, 2.88, 106.55]]}, {"timestamp": 1631528631188, "ltp": 2.24, "tv": 5.32, "trd": NaN, "batb": NaN, "batl": [[0, 2.16, 348.23], [1, 2.88, 106.55], [2, 2.88, 0]]}, {"timestamp": 1631528635390, "ltp": 2.24, "tv": 5.32, "trd": NaN, "batb": [[0, 1.56, 256.04], [1, 1.44, 443.07], [2, 1.4, 256.04]], "batl": NaN}, {"timestamp": 1631528637206, "ltp": 2.24, "tv": 5.32, "trd": NaN, "batb": NaN, "batl": [[0, 1.8, 256.04], [1, 2.16, 348.23], [2, 2.88, 106.55]]}, {"timestamp": 1631528651730, "ltp": 2.24, "tv": 5.32, "trd": NaN, "batb": [[1, 1.4, 256.04], [2, 1.01, 7]], "batl": NaN}, {"timestamp": 1631528656552, "ltp": 2.24, "tv": 5.32, "trd": NaN, "batb": NaN, "batl": [[0, 2.16, 348.23], [1, 2.88, 106.55], [2, 2.88, 0]]}, {"timestamp": 1631528657230, "ltp": 2.24, "tv": 5.32, "trd": NaN, "batb": [[1, 1.5, 433.64], [2, 1.4, 256.04]], "batl": NaN}, {"timestamp": 1631528660640, "ltp": 2.24, "tv": 5.32, "trd": NaN, "batb": [[0, 1.66, 256.04], [1, 1.56, 256.04], [2, 1.5, 433.64]], "batl": NaN}, {"timestamp": 1631528663179, "ltp": 2.24, "tv": 5.32, "trd": NaN, "batb": NaN, "batl": [[0, 1.9, 256.04], [1, 2.16, 348.23], [2, 2.88, 106.55]]}, {"timestamp": 1631528684604, "ltp": 2.24, "tv": 5.32, "trd": NaN, "batb": [[2, 1.4, 256.04]], "batl": [[1, 2.88, 106.55], [2, 2.88, 0]]}, {"timestamp": 1631528687608, "ltp": 2.24, "tv": 5.32, "trd": NaN, "batb": NaN, "batl": [[0, 2.88, 106.55], [1, 2.88, 0]]}, {"timestamp": 1631528690811, "ltp": 2.24, "tv": 5.32, "trd": NaN, "batb": [[2, 1.55, 427.14]], "batl": [[0, 2.42, 291.05], [1, 2.88, 106.55]]}, {"timestamp": 1631528693803, "ltp": 2.24, "tv": 5.32, "trd": NaN, "batb": [[0, 1.75, 256.04], [1, 1.66, 256.04], [2, 1.56, 256.04]], "batl": NaN}, {"timestamp": 1631528695919, "ltp": 2.24, "tv": 5.32, "trd": NaN, "batb": NaN, "batl": [[0, 2.1, 256.04], [1, 2.42, 291.05], [2, 2.88, 106.55]]}, {"timestamp": 1631528723439, "ltp": 2.24, "tv": 5.32, "trd": NaN, "batb": [[1, 1.56, 256.04], [2, 1.55, 427.14]], "batl": NaN}, {"timestamp": 1631528795948, "ltp": 2.24, "tv": 5.32, "trd": NaN, "batb": [[2, 1.4, 256.04]], "batl": NaN}, {"timestamp": 1631528801546, "ltp": 2.24, "tv": 5.32, "trd": NaN, "batb": [[1, 1.62, 421.99], [2, 1.56, 256.04]], "batl": [[0, 2.42, 291.05], [1, 2.88, 106.55], [2, 2.88, 0]]}, {"timestamp": 1631528837032, "ltp": 2.24, "tv": 5.32, "trd": NaN, "batb": [[1, 1.56, 256.04], [2, 1.4, 256.04]], "batl": [[0, 2.88, 106.55], [1, 2.88, 0]]}, {"timestamp": 1631528839533, "ltp": 2.24, "tv": 5.32, "trd": NaN, "batb": [[0, 1.56, 256.04], [1, 1.4, 256.04], [2, 1.01, 7]], "batl": NaN}, {"timestamp": 1631528843341, "ltp": 2.24, "tv": 5.32, "trd": NaN, "batb": [[0, 1.74, 410.67], [1, 1.56, 256.04], [2, 1.4, 256.04]], "batl": [[1, 2.92, 224.75]]}, {"timestamp": 1631528876880, "ltp": 2.24, "tv": 5.32, "trd": NaN, "batb": [[0, 1.56, 256.04], [1, 1.4, 256.04], [2, 1.01, 7]], "batl": NaN}, {"timestamp": 1631528882652, "ltp": 2.24, "tv": 5.32, "trd": NaN, "batb": [[0, 1.82, 407.57], [1, 1.56, 256.04], [2, 1.4, 256.04]], "batl": NaN}, {"timestamp": 1631528953441, "ltp": 2.24, "tv": 5.32, "trd": NaN, "batb": NaN, "batl": [[1, 2.92, 0]]}, {"timestamp": 1631528958943, "ltp": 2.24, "tv": 5.32, "trd": NaN, "batb": NaN, "batl": [[1, 3.3, 194.95]]}, {"timestamp": 1631528998400, "ltp": 2.24, "tv": 5.32, "trd": NaN, "batb": NaN, "batl": [[1, 3.3, 0]]}, {"timestamp": 1631529004613, "ltp": 2.24, "tv": 5.32, "trd": NaN, "batb": NaN, "batl": [[1, 2.92, 224.75]]}, {"timestamp": 1631529016856, "ltp": 2.24, "tv": 5.32, "trd": NaN, "batb": NaN, "batl": [[1, 2.92, 0]]}, {"timestamp": 1631529022842, "ltp": 2.24, "tv": 5.32, "trd": NaN, "batb": NaN, "batl": [[1, 3.3, 194.95]]}, {"timestamp": 1631529043571, "ltp": 2.24, "tv": 5.32, "trd": NaN, "batb": NaN, "batl": [[1, 3.3, 0]]}, {"timestamp": 1631529049486, "ltp": 2.24, "tv": 5.32, "trd": NaN, "batb": NaN, "batl": [[0, 2.82, 234.93], [1, 2.88, 106.55]]}, {"timestamp": 1631529080247, "ltp": 2.24, "tv": 5.32, "trd": NaN, "batb": [[0, 1.56, 256.04], [1, 1.4, 256.04], [2, 1.01, 7]], "batl": [[0, 2.88, 106.55], [1, 2.88, 0]]}, {"timestamp": 1631529085824, "ltp": 2.24, "tv": 5.32, "trd": NaN, "batb": [[0, 1.62, 421.99], [1, 1.56, 256.04], [2, 1.4, 256.04]], "batl": [[0, 2.6, 261.64], [1, 2.88, 106.55]]}, {"timestamp": 1631529098457, "ltp": 2.24, "tv": 5.32, "trd": NaN, "batb": NaN, "batl": [[0, 2.88, 106.55], [1, 2.88, 0]]}, {"timestamp": 1631529103971, "ltp": 2.24, "tv": 5.32, "trd": NaN, "batb": NaN, "batl": [[0, 2.5, 278.88], [1, 2.88, 106.55]]}, {"timestamp": 1631529154065, "ltp": 2.24, "tv": 5.32, "trd": NaN, "batb": [[1, 1.01, 7], [2, 1.4, 0]], "batl": NaN}, {"timestamp": 1631529179589, "ltp": 2.24, "tv": 5.32, "trd": NaN, "batb": NaN, "batl": [[0, 1.81, 10.53], [1, 2.5, 278.88], [2, 2.88, 106.55]]}, {"timestamp": 1631529226215, "ltp": 2.24, "tv": 5.32, "trd": NaN, "batb": [[0, 1.01, 7], [1, 1.01, 0]], "batl": [[1, 2.88, 106.55], [2, 2.88, 0]]}, {"timestamp": 1631529231960, "ltp": 2.24, "tv": 5.32, "trd": NaN, "batb": [[0, 1.46, 442.58], [1, 1.01, 7]], "batl": [[1, 2.22, 334.21], [2, 2.88, 106.55]]}, {"timestamp": 1631529270106, "ltp": 2.24, "tv": 5.32, "trd": NaN, "batb": [[0, 1.01, 7], [1, 1.01, 0]], "batl": [[1, 2.88, 106.55], [2, 2.88, 0]]}, {"timestamp": 1631529275505, "ltp": 2.24, "tv": 5.32, "trd": NaN, "batb": [[0, 1.38, 455.53], [1, 1.01, 7]], "batl": [[1, 2.04, 389.06], [2, 2.88, 106.55]]}, {"timestamp": 1631529316074, "ltp": 2.24, "tv": 5.32, "trd": NaN, "batb": [[0, 1.01, 7], [1, 1.01, 0]], "batl": [[1, 2.88, 106.55], [2, 2.88, 0]]}, {"timestamp": 1631529322272, "ltp": 2.24, "tv": 5.32, "trd": NaN, "batb": [[0, 1.31, 485.05], [1, 1.01, 7]], "batl": [[1, 1.89, 442.15], [2, 2.88, 106.55]]}, {"timestamp": 1631529346713, "ltp": 2.24, "tv": 5.32, "trd": NaN, "batb": [[0, 1.01, 7], [1, 1.01, 0]], "batl": NaN}, {"timestamp": 1631529352712, "ltp": 2.24, "tv": 5.32, "trd": NaN, "batb": [[0, 1.34, 472.77], [1, 1.01, 7]], "batl": NaN}, {"timestamp": 1631529376430, "ltp": 2.24, "tv": 5.32, "trd": NaN, "batb": [[0, 1.01, 7], [1, 1.01, 0]], "batl": [[1, 2.88, 106.55], [2, 2.88, 0]]}, {"timestamp": 1631529382460, "ltp": 2.24, "tv": 5.32, "trd": NaN, "batb": [[0, 1.25, 513.07], [1, 1.01, 7]], "batl": [[0, 1.77, 508.52], [1, 1.81, 10.53], [2, 2.88, 106.55]]}, {"timestamp": 1631529622960, "ltp": 2.24, "tv": 5.32, "trd": NaN, "batb": [[0, 1.01, 7], [1, 1.01, 0]], "batl": NaN}, {"timestamp": 1631529629070, "ltp": 2.24, "tv": 5.32, "trd": NaN, "batb": [[0, 1.31, 485.05], [1, 1.01, 7]], "batl": NaN}, {"timestamp": 1631529651496, "ltp": 2.24, "tv": 5.32, "trd": NaN, "batb": [[0, 1.01, 7], [1, 1.01, 0]], "batl": [[0, 1.81, 10.53], [1, 2.88, 106.55], [2, 2.88, 0]]}, {"timestamp": 1631529657628, "ltp": 2.24, "tv": 5.32, "trd": NaN, "batb": [[0, 1.34, 472.77], [1, 1.01, 7]], "batl": [[1, 1.95, 416.34], [2, 2.88, 106.55]]}, {"timestamp": 1631529668945, "ltp": 2.24, "tv": 5.32, "trd": NaN, "batb": [[0, 1.01, 7], [1, 1.01, 0]], "batl": [[1, 2.88, 106.55], [2, 2.88, 0]]}, {"timestamp": 1631529670035, "ltp": 2.24, "tv": 5.32, "trd": NaN, "batb": NaN, "batl": [[1, 2.88, 0]]}, {"timestamp": 1631529678918, "ltp": 2.24, "tv": 5.32, "trd": NaN, "batb": [[0, 1.31, 485.05], [1, 1.01, 7]], "batl": [[0, 1.89, 442.15]]}, {"timestamp": 1631529682240, "ltp": 2.24, "tv": 5.32, "trd": NaN, "batb": NaN, "batl": [[0, 1.56, 10.53], [1, 1.89, 442.15]]}, {"timestamp": 1631529686862, "ltp": 2.24, "tv": 5.32, "trd": NaN, "batb": NaN, "batl": [[0, 1.56, 5.35]]}, {"timestamp": 1631529689162, "ltp": 2.24, "tv": 5.32, "trd": NaN, "batb": [[0, 1.01, 7], [1, 1.01, 0]], "batl": [[1, 1.89, 0]]}, {"timestamp": 1631529835025, "ltp": 2.24, "tv": 5.32, "trd": NaN, "batb": [[0, 1.18, 558.4], [1, 1.01, 7]], "batl": [[1, 1.62, 624.1]]}, {"timestamp": 1631529896280, "ltp": 2.24, "tv": 5.32, "trd": NaN, "batb": [[0, 1.01, 7], [1, 1.01, 0]], "batl": [[1, 1.62, 0]]}, {"timestamp": 1631529901707, "ltp": 2.24, "tv": 5.32, "trd": NaN, "batb": [[0, 1.14, 620.09], [1, 1.01, 7]], "batl": [[0, 1.55, 701.66], [1, 1.56, 5.35]]}, {"timestamp": 1631529913524, "ltp": 2.24, "tv": 5.32, "trd": NaN, "batb": [[0, 1.01, 7], [1, 1.01, 0]], "batl": NaN}, {"timestamp": 1631529919032, "ltp": 2.24, "tv": 5.32, "trd": NaN, "batb": [[0, 1.12, 660.6], [1, 1.01, 7]], "batl": NaN}, {"timestamp": 1631529938865, "ltp": 2.24, "tv": 5.32, "trd": NaN, "batb": [[0, 1.01, 7], [1, 1.01, 0]], "batl": NaN}, {"timestamp": 1631529945267, "ltp": 2.24, "tv": 5.32, "trd": NaN, "batb": [[0, 1.14, 620.09], [1, 1.01, 7]], "batl": NaN}, {"timestamp": 1631529970400, "ltp": 2.24, "tv": 5.32, "trd": NaN, "batb": [[0, 1.01, 7], [1, 1.01, 0]], "batl": NaN}, {"timestamp": 1631529976643, "ltp": 2.24, "tv": 5.32, "trd": NaN, "batb": [[0, 1.18, 558.4], [1, 1.01, 7]], "batl": NaN}, {"timestamp": 1631530014170, "ltp": 2.24, "tv": 5.32, "trd": NaN, "batb": [[0, 1.01, 7], [1, 1.01, 0]], "batl": NaN}, {"timestamp": 1631530020205, "ltp": 2.24, "tv": 5.32, "trd": NaN, "batb": [[0, 1.2, 539.24], [1, 1.01, 7]], "batl": NaN}, {"timestamp": 1631530038545, "ltp": 2.24, "tv": 5.32, "trd": NaN, "batb": [[0, 1.01, 7], [1, 1.01, 0]], "batl": [[0, 1.56, 5.35], [1, 1.56, 0]]}, {"timestamp": 1631530044513, "ltp": 2.24, "tv": 5.32, "trd": NaN, "batb": [[0, 1.22, 531.25], [1, 1.01, 7]], "batl": [[1, 1.71, 550.62]]}, {"timestamp": 1631530061925, "ltp": 2.24, "tv": 5.32, "trd": NaN, "batb": [[0, 1.01, 7], [1, 1.01, 0]], "batl": [[1, 1.71, 0]]}, {"timestamp": 1631530067778, "ltp": 2.24, "tv": 5.32, "trd": NaN, "batb": [[0, 1.16, 585.23], [1, 1.01, 7]], "batl": [[1, 1.58, 660.85]]}, {"timestamp": 1631530093556, "ltp": 2.24, "tv": 5.32, "trd": NaN, "batb": [[0, 1.01, 7], [1, 1.01, 0]], "batl": NaN}, {"timestamp": 1631530099206, "ltp": 2.24, "tv": 5.32, "trd": NaN, "batb": [[0, 1.2, 539.24], [1, 1.01, 7]], "batl": NaN}, {"timestamp": 1631530121127, "ltp": 2.24, "tv": 5.32, "trd": NaN, "batb": [[0, 1.01, 7], [1, 1.01, 0]], "batl": NaN}, {"timestamp": 1631530122831, "ltp": 2.24, "tv": 5.32, "trd": NaN, "batb": NaN, "batl": [[0, 1.2, 55], [1, 1.56, 5.35], [2, 1.58, 660.85]]}, {"timestamp": 1631530125118, "ltp": 2.24, "tv": 5.32, "trd": NaN, "batb": NaN, "batl": [[0, 1.56, 5.35], [1, 1.58, 660.85], [2, 1.58, 0]]}, {"timestamp": 1631530127434, "ltp": 2.24, "tv": 5.32, "trd": NaN, "batb": [[0, 1.23, 524.63], [1, 1.01, 7]], "batl": NaN}, {"timestamp": 1631530164862, "ltp": 2.24, "tv": 5.32, "trd": NaN, "batb": [[0, 1.01, 7], [1, 1.01, 0]], "batl": [[1, 1.58, 0]]}, {"timestamp": 1631530171095, "ltp": 2.24, "tv": 5.32, "trd": NaN, "batb": [[0, 1.28, 493.56], [1, 1.01, 7]], "batl": [[1, 1.82, 476.51]]}, {"timestamp": 1631530204511, "ltp": 2.24, "tv": 5.32, "trd": NaN, "batb": [[0, 1.01, 7], [1, 1.01, 0]], "batl": [[1, 1.82, 0]]}, {"timestamp": 1631530210631, "ltp": 2.24, "tv": 5.32, "trd": NaN, "batb": [[0, 1.23, 524.63], [1, 1.01, 7]], "batl": [[1, 1.73, 535.9]]}, {"timestamp": 1631530230975, "ltp": 2.24, "tv": 5.32, "trd": NaN, "batb": [[0, 1.01, 7], [1, 1.01, 0]], "batl": [[1, 1.73, 0]]}, {"timestamp": 1631530236893, "ltp": 2.24, "tv": 5.32, "trd": NaN, "batb": [[0, 1.2, 539.24], [1, 1.01, 7]], "batl": [[1, 1.66, 588.96]]}, {"timestamp": 1631530262598, "ltp": 2.24, "tv": 5.32, "trd": NaN, "batb": [[0, 1.01, 7], [1, 1.01, 0]], "batl": NaN}, {"timestamp": 1631530268226, "ltp": 2.24, "tv": 5.32, "trd": NaN, "batb": [[0, 1.25, 513.07], [1, 1.01, 7]], "batl": NaN}, {"timestamp": 1631530329811, "ltp": 2.24, "tv": 5.32, "trd": NaN, "batb": [[0, 1.01, 7], [1, 1.01, 0]], "batl": [[1, 1.66, 0]]}, {"timestamp": 1631530335986, "ltp": 2.24, "tv": 5.32, "trd": NaN, "batb": [[0, 1.31, 485.05], [1, 1.01, 7]], "batl": [[1, 1.89, 442.15]]}, {"timestamp": 1631530351202, "ltp": 2.24, "tv": 5.32, "trd": NaN, "batb": [[0, 1.01, 7], [1, 1.01, 0]], "batl": [[1, 1.89, 0]]}, {"timestamp": 1631530357332, "ltp": 2.24, "tv": 5.32, "trd": NaN, "batb": [[0, 1.25, 513.07], [1, 1.01, 7]], "batl": [[1, 1.77, 508.52]]}, {"timestamp": 1631530384860, "ltp": 2.24, "tv": 5.32, "trd": NaN, "batb": [[0, 1.01, 7], [1, 1.01, 0]], "batl": NaN}, {"timestamp": 1631530390777, "ltp": 2.24, "tv": 5.32, "trd": NaN, "batb": [[0, 1.31, 485.05], [1, 1.01, 7]], "batl": NaN}, {"timestamp": 1631530424394, "ltp": 2.24, "tv": 5.32, "trd": NaN, "batb": [[0, 1.01, 7], [1, 1.01, 0]], "batl": [[1, 1.77, 0]]}, {"timestamp": 1631530430120, "ltp": 2.24, "tv": 5.32, "trd": NaN, "batb": [[0, 1.38, 455.53], [1, 1.01, 7]], "batl": [[1, 2.04, 389.06]]}, {"timestamp": 1631530560699, "ltp": 2.24, "tv": 5.32, "trd": NaN, "batb": [[0, 1.01, 7], [1, 1.01, 0]], "batl": [[1, 2.04, 0]]}, {"timestamp": 1631530566878, "ltp": 2.24, "tv": 5.32, "trd": NaN, "batb": [[0, 1.28, 493.56], [1, 1.01, 7]], "batl": [[1, 1.82, 476.51]]}, {"timestamp": 1631530584110, "ltp": 2.24, "tv": 5.32, "trd": NaN, "batb": [[0, 1.01, 7], [1, 1.01, 0]], "batl": NaN}, {"timestamp": 1631530590057, "ltp": 2.24, "tv": 5.32, "trd": NaN, "batb": [[0, 1.31, 485.05], [1, 1.01, 7]], "batl": NaN}, {"timestamp": 1631530607566, "ltp": 2.24, "tv": 5.32, "trd": NaN, "batb": [[0, 1.01, 7], [1, 1.01, 0]], "batl": [[1, 1.82, 0]]}, {"timestamp": 1631530613480, "ltp": 2.24, "tv": 5.32, "trd": NaN, "batb": [[0, 1.38, 455.53], [1, 1.01, 7]], "batl": [[1, 2.04, 389.06]]}, {"timestamp": 1631530630012, "ltp": 2.24, "tv": 5.32, "trd": NaN, "batb": [[0, 1.01, 7], [1, 1.01, 0]], "batl": [[1, 2.04, 0]]}, {"timestamp": 1631530635624, "ltp": 2.24, "tv": 5.32, "trd": NaN, "batb": [[0, 1.31, 485.05], [1, 1.01, 7]], "batl": [[1, 1.89, 442.15]]}, {"timestamp": 1631530658419, "ltp": 2.24, "tv": 5.32, "trd": NaN, "batb": [[0, 1.01, 7], [1, 1.01, 0]], "batl": [[1, 1.89, 0]]}, {"timestamp": 1631530664048, "ltp": 2.24, "tv": 5.32, "trd": NaN, "batb": [[0, 1.23, 524.63], [1, 1.01, 7]], "batl": [[1, 1.73, 535.9]]}, {"timestamp": 1631530707209, "ltp": 2.24, "tv": 5.32, "trd": NaN, "batb": [[0, 1.01, 7], [1, 1.01, 0]], "batl": NaN}, {"timestamp": 1631530713519, "ltp": 2.24, "tv": 5.32, "trd": NaN, "batb": [[0, 1.28, 493.56], [1, 1.01, 7]], "batl": NaN}, {"timestamp": 1631530750826, "ltp": 2.24, "tv": 5.32, "trd": NaN, "batb": [[0, 1.01, 7], [1, 1.01, 0]], "batl": [[1, 1.73, 0]]}, {"timestamp": 1631530757053, "ltp": 2.24, "tv": 5.32, "trd": NaN, "batb": [[0, 1.34, 472.77], [1, 1.01, 7]], "batl": [[1, 1.95, 416.34]]}, {"timestamp": 1631530773153, "ltp": 2.24, "tv": 5.32, "trd": NaN, "batb": [[0, 1.01, 7], [1, 1.01, 0]], "batl": [[1, 1.95, 0]]}, {"timestamp": 1631530779184, "ltp": 2.24, "tv": 5.32, "trd": NaN, "batb": [[0, 1.28, 493.56], [1, 1.01, 7]], "batl": [[1, 1.82, 476.51]]}, {"timestamp": 1631530817949, "ltp": 2.24, "tv": 5.31, "trd": [[2.24, 5.32]], "batb": [[0, 1.01, 7], [1, 1.01, 0]], "batl": [[0, 1.56, 5.34], [1, 1.82, 0]]}, {"timestamp": 1631530823744, "ltp": 2.24, "tv": 5.31, "trd": NaN, "batb": [[0, 1.23, 523.6], [1, 1.01, 7]], "batl": [[1, 1.73, 534.85]]}, {"timestamp": 1631530846372, "ltp": 2.24, "tv": 5.31, "trd": NaN, "batb": [[0, 1.01, 7], [1, 1.01, 0]], "batl": NaN}, {"timestamp": 1631530852083, "ltp": 2.24, "tv": 5.31, "trd": NaN, "batb": [[0, 1.31, 484.1], [1, 1.01, 7]], "batl": NaN}, {"timestamp": 1631530881021, "ltp": 2.24, "tv": 5.31, "trd": NaN, "batb": [[0, 1.01, 7], [1, 1.01, 0]], "batl": NaN}, {"timestamp": 1631530887325, "ltp": 2.24, "tv": 5.31, "trd": NaN, "batb": [[0, 1.23, 523.6], [1, 1.01, 7]], "batl": NaN}, {"timestamp": 1631530936756, "ltp": 2.24, "tv": 5.31, "trd": NaN, "batb": [[0, 1.01, 7], [1, 1.01, 0]], "batl": NaN}, {"timestamp": 1631530942892, "ltp": 2.24, "tv": 5.31, "trd": NaN, "batb": [[0, 1.31, 484.1], [1, 1.01, 7]], "batl": NaN}, {"timestamp": 1631530971338, "ltp": 2.24, "tv": 5.31, "trd": NaN, "batb": [[0, 1.01, 7], [1, 1.01, 0]], "batl": NaN}, {"timestamp": 1631530977370, "ltp": 2.24, "tv": 5.31, "trd": NaN, "batb": [[0, 1.25, 512.06], [1, 1.01, 7]], "batl": NaN}, {"timestamp": 1631531017101, "ltp": 2.24, "tv": 5.31, "trd": NaN, "batb": [[0, 1.01, 7], [1, 1.01, 0]], "batl": [[1, 1.73, 0]]}, {"timestamp": 1631531023002, "ltp": 2.24, "tv": 5.31, "trd": NaN, "batb": [[0, 1.2, 538.19], [1, 1.01, 7]], "batl": [[1, 1.66, 587.81]]}, {"timestamp": 1631531040790, "ltp": 2.24, "tv": 5.31, "trd": NaN, "batb": NaN, "batl": [[0, 1.5, 255.54], [1, 1.56, 5.34], [2, 1.66, 587.81]]}, {"timestamp": 1631531054731, "ltp": 2.24, "tv": 5.31, "trd": NaN, "batb": [[0, 1.01, 7], [1, 1.01, 0]], "batl": [[2, 1.66, 0]]}, {"timestamp": 1631531060428, "ltp": 2.24, "tv": 5.31, "trd": NaN, "batb": [[0, 1.16, 584.08], [1, 1.01, 7]], "batl": [[2, 1.58, 659.56]]}, {"timestamp": 1631531064823, "ltp": 2.24, "tv": 5.31, "trd": NaN, "batb": [[0, 1.17, 255.54], [1, 1.16, 584.08], [2, 1.01, 7]], "batl": NaN}, {"timestamp": 1631531152278, "ltp": 2.24, "tv": 5.31, "trd": NaN, "batb": [[1, 1.01, 7], [2, 1.01, 0]], "batl": [[2, 1.58, 0]]}, {"timestamp": 1631531156563, "ltp": 2.24, "tv": 5.31, "trd": NaN, "batb": [[0, 1.01, 7], [1, 1.01, 0]], "batl": NaN}, {"timestamp": 1631531158587, "ltp": 2.24, "tv": 5.31, "trd": NaN, "batb": [[0, 1.12, 659.31], [1, 1.01, 7]], "batl": [[1, 1.51, 751.3], [2, 1.56, 5.34]]}, {"timestamp": 1631531162407, "ltp": 2.24, "tv": 5.31, "trd": NaN, "batb": [[1, 1.1, 255.54], [2, 1.01, 7]], "batl": NaN}, {"timestamp": 1631531163704, "ltp": 2.24, "tv": 5.31, "trd": NaN, "batb": NaN, "batl": [[0, 1.3, 255.54], [1, 1.5, 255.54], [2, 1.51, 751.3]]}, {"timestamp": 1631531181716, "ltp": 2.24, "tv": 5.31, "trd": NaN, "batb": [[0, 1.1, 255.54], [1, 1.01, 7], [2, 1.01, 0]], "batl": NaN}, {"timestamp": 1631531187794, "ltp": 2.24, "tv": 5.31, "trd": NaN, "batb": [[0, 1.16, 584.08], [1, 1.1, 255.54], [2, 1.01, 7]], "batl": NaN}, {"timestamp": 1631531210156, "ltp": 2.24, "tv": 5.31, "trd": NaN, "batb": [[0, 1.1, 255.54], [1, 1.01, 7], [2, 1.01, 0]], "batl": NaN}, {"timestamp": 1631531214755, "ltp": 2.24, "tv": 5.31, "trd": NaN, "batb": NaN, "batl": [[1, 1.51, 751.3], [2, 1.56, 5.34]]}, {"timestamp": 1631531216064, "ltp": 2.24, "tv": 5.31, "trd": NaN, "batb": [[0, 1.12, 659.31], [1, 1.1, 255.54], [2, 1.01, 7]], "batl": NaN}, {"timestamp": 1631531240573, "ltp": 2.24, "tv": 5.31, "trd": NaN, "batb": [[0, 1.1, 255.54], [1, 1.01, 7], [2, 1.01, 0]], "batl": NaN}, {"timestamp": 1631531246572, "ltp": 2.24, "tv": 5.31, "trd": NaN, "batb": [[0, 1.16, 584.08], [1, 1.1, 255.54], [2, 1.01, 7]], "batl": NaN}, {"timestamp": 1631531254302, "ltp": 2.24, "tv": 5.31, "trd": NaN, "batb": NaN, "batl": [[0, 1.51, 751.3], [1, 1.56, 5.34], [2, 1.56, 0]]}, {"timestamp": 1631531258915, "ltp": 2.24, "tv": 5.31, "trd": NaN, "batb": [[1, 1.01, 7], [2, 1.01, 0]], "batl": NaN}, {"timestamp": 1631531260008, "ltp": 2.24, "tv": 5.31, "trd": NaN, "batb": NaN, "batl": [[0, 1.4, 255.54], [1, 1.51, 751.3], [2, 1.56, 5.34]]}, {"timestamp": 1631531261930, "ltp": 2.24, "tv": 5.31, "trd": NaN, "batb": [[0, 1.2, 255.54], [1, 1.16, 584.08], [2, 1.01, 7]], "batl": NaN}, {"timestamp": 1631531278262, "ltp": 2.24, "tv": 5.31, "trd": NaN, "batb": [[1, 1.01, 7], [2, 1.01, 0]], "batl": [[1, 1.56, 5.34], [2, 1.56, 0]]}, {"timestamp": 1631531283930, "ltp": 2.24, "tv": 5.31, "trd": NaN, "batb": [[0, 1.2, 793.72]], "batl": [[2, 1.66, 587.81]]}, {"timestamp": 1631531313607, "ltp": 2.24, "tv": 5.31, "trd": NaN, "batb": [[0, 1.2, 255.54]], "batl": NaN}, {"timestamp": 1631531319311, "ltp": 2.24, "tv": 5.31, "trd": NaN, "batb": [[0, 1.23, 523.6], [1, 1.2, 255.54], [2, 1.01, 7]], "batl": NaN}, {"timestamp": 1631531331016, "ltp": 2.24, "tv": 5.31, "trd": NaN, "batb": NaN, "batl": [[0, 1.56, 5.34], [1, 1.66, 587.81], [2, 1.66, 0]]}, {"timestamp": 1631531374479, "ltp": 2.24, "tv": 5.31, "trd": NaN, "batb": [[0, 1.2, 255.54], [1, 1.01, 7], [2, 1.01, 0]], "batl": [[1, 1.66, 0]]}, {"timestamp": 1631531379892, "ltp": 2.24, "tv": 5.31, "trd": NaN, "batb": [[0, 1.28, 492.6], [1, 1.2, 255.54], [2, 1.01, 7]], "batl": [[1, 1.82, 475.58]]}, {"timestamp": 1631531384887, "ltp": 2.24, "tv": 5.31, "trd": NaN, "batb": [[0, 1.3, 255.54], [1, 1.28, 492.6], [2, 1.2, 255.54]], "batl": NaN}, {"timestamp": 1631531394819, "ltp": 2.24, "tv": 5.31, "trd": NaN, "batb": [[1, 1.2, 255.54], [2, 1.01, 7]], "batl": NaN}, {"timestamp": 1631531401121, "ltp": 2.24, "tv": 5.31, "trd": NaN, "batb": [[0, 1.34, 471.85], [1, 1.3, 255.54]], "batl": NaN}, {"timestamp": 1631531413631, "ltp": 2.24, "tv": 5.31, "trd": NaN, "batb": NaN, "batl": [[0, 1.82, 475.58], [1, 1.82, 0]]}, {"timestamp": 1631531425148, "ltp": 2.24, "tv": 5.31, "trd": NaN, "batb": [[0, 1.3, 255.54], [1, 1.01, 7], [2, 1.01, 0]], "batl": NaN}, {"timestamp": 1631531431350, "ltp": 2.24, "tv": 5.31, "trd": NaN, "batb": [[0, 1.4, 457.22], [1, 1.3, 255.54], [2, 1.01, 7]], "batl": [[0, 2.1, 368.32]]}, {"timestamp": 1631531432545, "ltp": 2.24, "tv": 5.31, "trd": NaN, "batb": [[0, 1.4, 712.76], [1, 1.01, 7], [2, 1.01, 0]], "batl": NaN}, {"timestamp": 1631531433638, "ltp": 2.24, "tv": 5.31, "trd": NaN, "batb": [[0, 1.5, 255.54], [1, 1.4, 712.76], [2, 1.01, 7]], "batl": NaN}, {"timestamp": 1631531435462, "ltp": 2.24, "tv": 5.31, "trd": NaN, "batb": NaN, "batl": [[0, 1.8, 255.54], [1, 2.1, 368.32]]}, {"timestamp": 1631531442575, "ltp": 2.24, "tv": 5.31, "trd": NaN, "batb": [[1, 1.4, 715.4]], "batl": NaN}, {"timestamp": 1631531444492, "ltp": 2.24, "tv": 5.31, "trd": NaN, "batb": [[1, 1.4, 258.18]], "batl": [[1, 2.1, 0]]}, {"timestamp": 1631531457413, "ltp": 2.24, "tv": 5.31, "trd": NaN, "batb": [[1, 1.4, 2.64]], "batl": NaN}, {"timestamp": 1631531501148, "ltp": 2.24, "tv": 5.31, "trd": NaN, "batb": [[0, 1.4, 2.64], [1, 1.01, 7], [2, 1.01, 0]], "batl": NaN}, {"timestamp": 1631531507767, "ltp": 2.24, "tv": 5.31, "trd": NaN, "batb": [[0, 1.4, 258.18]], "batl": NaN}, {"timestamp": 1631531510263, "ltp": 2.24, "tv": 5.31, "trd": NaN, "batb": NaN, "batl": [[0, 1.6, 255.54], [1, 1.8, 255.54]]}, {"timestamp": 1631531520465, "ltp": 2.24, "tv": 5.31, "trd": NaN, "batb": NaN, "batl": [[0, 1.8, 255.54], [1, 1.8, 0]]}, {"timestamp": 1631531521405, "ltp": 2.24, "tv": 5.31, "trd": NaN, "batb": [[0, 1.4, 2.64]], "batl": NaN}, {"timestamp": 1631531529596, "ltp": 2.24, "tv": 5.31, "trd": NaN, "batb": NaN, "batl": [[0, 1.5, 255.54], [1, 1.8, 255.54]]}, {"timestamp": 1631531530796, "ltp": 2.24, "tv": 5.31, "trd": NaN, "batb": NaN, "batl": [[0, 1.5, 261.62]]}, {"timestamp": 1631531533876, "ltp": 2.24, "tv": 5.31, "trd": NaN, "batb": [[1, 1.3, 255.54], [2, 1.01, 7]], "batl": NaN}, {"timestamp": 1631531566318, "ltp": 2.24, "tv": 5.31, "trd": NaN, "batb": [[1, 1.01, 7], [2, 1.01, 0]], "batl": NaN}, {"timestamp": 1631531570545, "ltp": 1.4, "tv": 9.31, "trd": [[1.4, 4]], "batb": [[0, 1.01, 7.64], [1, 1.01, 0]], "batl": NaN}, {"timestamp": 1631531570812, "ltp": 1.4, "tv": 10.59, "trd": [[1.4, 5.28]], "batb": [[0, 1.01, 7]], "batl": NaN}, {"timestamp": 1631531579242, "ltp": 1.4, "tv": 10.59, "trd": NaN, "batb": [[0, 1.2, 255.54], [1, 1.01, 7]], "batl": NaN}, {"timestamp": 1631531585350, "ltp": 1.4, "tv": 10.59, "trd": NaN, "batb": [[1, 1.18, 557.31], [2, 1.01, 7]], "batl": [[1, 1.62, 622.88], [2, 1.8, 255.54]]}, {"timestamp": 1631531590482, "ltp": 1.4, "tv": 10.59, "trd": NaN, "batb": [[1, 1.01, 7], [2, 1.01, 0]], "batl": [[1, 1.8, 255.54], [2, 1.8, 0]]}, {"timestamp": 1631531594252, "ltp": 1.4, "tv": 10.59, "trd": NaN, "batb": [[0, 1.01, 7], [1, 1.01, 0]], "batl": NaN}, {"timestamp": 1631531596341, "ltp": 1.4, "tv": 10.59, "trd": NaN, "batb": [[0, 1.14, 618.88], [1, 1.01, 7]], "batl": [[1, 1.55, 700.29], [2, 1.8, 255.54]]}, {"timestamp": 1631531598466, "ltp": 1.4, "tv": 10.59, "trd": NaN, "batb": NaN, "batl": [[0, 1.3, 255.54], [1, 1.5, 261.62], [2, 1.55, 700.29]]}, {"timestamp": 1631531601434, "ltp": 1.4, "tv": 10.59, "trd": NaN, "batb": [[0, 1.14, 874.41]], "batl": [[1, 1.5, 270.74]]}, {"timestamp": 1631531676536, "ltp": 1.4, "tv": 10.59, "trd": NaN, "batb": NaN, "batl": [[1, 1.5, 264.66]]}, {"timestamp": 1631531680250, "ltp": 1.4, "tv": 10.59, "trd": NaN, "batb": NaN, "batl": [[1, 1.5, 9.12]]}, {"timestamp": 1631531682062, "ltp": 1.4, "tv": 10.59, "trd": NaN, "batb": [[0, 1.14, 255.54]], "batl": [[2, 1.8, 255.54]]}, {"timestamp": 1631531688334, "ltp": 1.14, "tv": 13.35, "trd": [[1.14, 2.76]], "batb": [[0, 1.14, 254.16]], "batl": NaN}, {"timestamp": 1631531688659, "ltp": 1.14, "tv": 13.35, "trd": NaN, "batb": [[1, 1.1, 733.19], [2, 1.01, 7]], "batl": [[1, 1.48, 795.77], [2, 1.5, 9.12]]}, {"timestamp": 1631531692534, "ltp": 1.14, "tv": 13.35, "trd": NaN, "batb": [[0, 1.1, 733.19], [1, 1.01, 7], [2, 1.01, 0]], "batl": NaN}, {"timestamp": 1631531699958, "ltp": 1.14, "tv": 13.35, "trd": NaN, "batb": [[0, 1.12, 255.54], [1, 1.1, 733.19], [2, 1.01, 7]], "batl": NaN}, {"timestamp": 1631531701889, "ltp": 1.14, "tv": 14.73, "trd": [[1.14, 4.14]], "batb": NaN, "batl": NaN}, {"timestamp": 1631531703967, "ltp": 1.14, "tv": 14.73, "trd": NaN, "batb": [[1, 1.01, 7], [2, 1.01, 0]], "batl": [[1, 1.5, 9.12], [2, 1.8, 255.54]]}, {"timestamp": 1631531709662, "ltp": 1.14, "tv": 14.73, "trd": NaN, "batb": [[1, 1.06, 1007.61], [2, 1.01, 7]], "batl": [[1, 1.41, 915.1], [2, 1.5, 9.12]]}, {"timestamp": 1631531715606, "ltp": 1.14, "tv": 14.73, "trd": NaN, "batb": [[0, 1.06, 1007.61], [1, 1.01, 7], [2, 1.01, 0]], "batl": NaN}, {"timestamp": 1631531719095, "ltp": 1.14, "tv": 14.73, "trd": NaN, "batb": NaN, "batl": [[0, 1.41, 915.1], [1, 1.5, 9.12], [2, 1.8, 255.54]]}, {"timestamp": 1631531721278, "ltp": 1.14, "tv": 14.73, "trd": NaN, "batb": [[0, 1.08, 255.54], [1, 1.06, 1007.61], [2, 1.01, 7]], "batl": NaN}, {"timestamp": 1631531722685, "ltp": 1.14, "tv": 14.73, "trd": NaN, "batb": NaN, "batl": [[0, 1.2, 255.54], [1, 1.41, 915.1], [2, 1.5, 9.12]]}, {"timestamp": 1631531727369, "ltp": 1.14, "tv": 14.73, "trd": NaN, "batb": [[1, 1.01, 7], [2, 1.01, 0]], "batl": NaN}, {"timestamp": 1631531733008, "ltp": 1.14, "tv": 14.73, "trd": NaN, "batb": [[0, 1.09, 763.45], [1, 1.08, 255.54], [2, 1.01, 7]], "batl": NaN}, {"timestamp": 1631531736723, "ltp": 1.14, "tv": 14.73, "trd": NaN, "batb": [[0, 1.11, 255.54], [1, 1.09, 763.45], [2, 1.08, 255.54]], "batl": NaN}, {"timestamp": 1631531747027, "ltp": 1.14, "tv": 14.73, "trd": NaN, "batb": NaN, "batl": [[2, 1.8, 255.54]]}, {"timestamp": 1631531756812, "ltp": 1.14, "tv": 14.73, "trd": NaN, "batb": [[1, 1.08, 255.54], [2, 1.01, 7]], "batl": NaN}, {"timestamp": 1631531763211, "ltp": 1.14, "tv": 14.73, "trd": NaN, "batb": [[1, 1.1, 733.19], [2, 1.08, 255.54]], "batl": NaN}, {"timestamp": 1631531767311, "ltp": 1.14, "tv": 14.73, "trd": NaN, "batb": NaN, "batl": [[0, 1.41, 915.1], [1, 1.8, 255.54], [2, 1.8, 0]]}, {"timestamp": 1631531767930, "ltp": 1.14, "tv": 14.73, "trd": NaN, "batb": [[1, 1.08, 255.54], [2, 1.01, 7]], "batl": NaN}, {"timestamp": 1631531773339, "ltp": 1.14, "tv": 14.73, "trd": NaN, "batb": [[0, 1.14, 618.88], [1, 1.11, 255.54], [2, 1.08, 255.54]], "batl": NaN}, {"timestamp": 1631531799755, "ltp": 1.14, "tv": 14.73, "trd": NaN, "batb": [[2, 1.01, 7]], "batl": NaN}, {"timestamp": 1631531801944, "ltp": 1.14, "tv": 14.73, "trd": NaN, "batb": [[1, 1.01, 7], [2, 1.01, 0]], "batl": NaN}, {"timestamp": 1631531804485, "ltp": 1.14, "tv": 14.73, "trd": NaN, "batb": [[0, 1.01, 7], [1, 1.01, 0]], "batl": NaN}, {"timestamp": 1631531810781, "ltp": 1.14, "tv": 14.73, "trd": NaN, "batb": [[0, 1.08, 812.01], [1, 1.01, 7]], "batl": NaN}, {"timestamp": 1631531826793, "ltp": 1.14, "tv": 14.73, "trd": NaN, "batb": [[0, 1.01, 7], [1, 1.01, 0]], "batl": [[0, 1.8, 255.54], [1, 1.8, 0]]}, {"timestamp": 1631531838001, "ltp": 1.14, "tv": 14.73, "trd": NaN, "batb": [[0, 1.14, 618.88], [1, 1.01, 7]], "batl": [[0, 1.55, 700.29], [1, 1.8, 255.54]]}, {"timestamp": 1631531857724, "ltp": 1.14, "tv": 14.73, "trd": NaN, "batb": NaN, "batl": [[0, 1.54, 29.05], [1, 1.55, 700.29], [2, 1.8, 255.54]]}, {"timestamp": 1631531875430, "ltp": 1.14, "tv": 14.73, "trd": NaN, "batb": [[0, 1.01, 7], [1, 1.01, 0]], "batl": NaN}, {"timestamp": 1631531881542, "ltp": 1.14, "tv": 14.73, "trd": NaN, "batb": [[0, 1.2, 538.19], [1, 1.01, 7]], "batl": NaN}, {"timestamp": 1631531894752, "ltp": 1.14, "tv": 14.73, "trd": NaN, "batb": NaN, "batl": [[0, 1.55, 700.29], [1, 1.8, 255.54], [2, 1.8, 0]]}, {"timestamp": 1631531899889, "ltp": 1.14, "tv": 14.73, "trd": NaN, "batb": NaN, "batl": [[1, 1.79, 29.05], [2, 1.8, 255.54]]}, {"timestamp": 1631531901766, "ltp": 1.14, "tv": 14.73, "trd": NaN, "batb": [[0, 1.01, 7], [1, 1.01, 0]], "batl": NaN}, {"timestamp": 1631531907894, "ltp": 1.14, "tv": 14.73, "trd": NaN, "batb": [[0, 1.14, 618.88], [1, 1.01, 7]], "batl": NaN}, {"timestamp": 1631531933514, "ltp": 1.14, "tv": 14.73, "trd": NaN, "batb": [[0, 1.01, 7], [1, 1.01, 0]], "batl": [[0, 1.79, 29.05], [1, 1.8, 255.54], [2, 1.8, 0]]}, {"timestamp": 1631531939437, "ltp": 1.14, "tv": 14.73, "trd": NaN, "batb": [[0, 1.08, 812.01], [1, 1.01, 7]], "batl": [[0, 1.44, 869.57], [1, 1.79, 29.05], [2, 1.8, 255.54]]}, {"timestamp": 1631531955844, "ltp": 1.14, "tv": 14.73, "trd": NaN, "batb": [[0, 1.01, 7], [1, 1.01, 0]], "batl": [[0, 1.79, 29.05], [1, 1.8, 255.54], [2, 1.8, 0]]}, {"timestamp": 1631531964555, "ltp": 1.14, "tv": 59.64, "trd": [[1.14, 49.04]], "batb": [[0, 1.04, 1251.58], [1, 1.01, 7]], "batl": [[0, 1.36, 1040.12], [1, 1.79, 29.05], [2, 1.8, 255.54]]}, {"timestamp": 1631531965544, "ltp": 1.14, "tv": 59.64, "trd": NaN, "batb": NaN, "batl": [[0, 1.14, 123.09], [1, 1.36, 1040.12], [2, 1.79, 29.05]]}, {"timestamp": 1631531965960, "ltp": 1.14, "tv": 59.64, "trd": NaN, "batb": NaN, "batl": [[0, 1.36, 1040.12], [1, 1.79, 29.05], [2, 1.8, 255.54]]}, {"timestamp": 1631531983754, "ltp": 1.14, "tv": 59.64, "trd": NaN, "batb": NaN, "batl": [[1, 1.8, 255.54], [2, 1.8, 0]]}, {"timestamp": 1631531988897, "ltp": 1.14, "tv": 59.64, "trd": NaN, "batb": NaN, "batl": [[0, 1.35, 29.05], [1, 1.36, 1040.12], [2, 1.8, 255.54]]}, {"timestamp": 1631532027928, "ltp": 1.14, "tv": 59.64, "trd": NaN, "batb": [[0, 1.01, 7], [1, 1.01, 0]], "batl": NaN}, {"timestamp": 1631532033346, "ltp": 1.14, "tv": 59.64, "trd": NaN, "batb": [[0, 1.06, 949.73], [1, 1.01, 7]], "batl": NaN}, {"timestamp": 1631532040431, "ltp": 1.14, "tv": 59.64, "trd": NaN, "batb": NaN, "batl": [[0, 1.14, 255.54], [1, 1.15, 255.54], [2, 1.35, 29.05]]}, {"timestamp": 1631532048251, "ltp": 1.14, "tv": 59.64, "trd": NaN, "batb": [[0, 1.01, 7], [1, 1.01, 0]], "batl": NaN}, {"timestamp": 1631532054683, "ltp": 1.14, "tv": 59.64, "trd": NaN, "batb": [[0, 1.04, 1251.58], [1, 1.01, 7]], "batl": NaN}, {"timestamp": 1631532062470, "ltp": 1.14, "tv": 59.64, "trd": NaN, "batb": [[0, 1.01, 7], [1, 1.01, 0]], "batl": NaN}, {"timestamp": 1631532070864, "ltp": 1.14, "tv": 59.64, "trd": NaN, "batb": [[0, 1.03, 1557.04], [1, 1.01, 7]], "batl": [[2, 1.35, 1116.88]]}, {"timestamp": 1631532072581, "ltp": 1.14, "tv": 59.64, "trd": NaN, "batb": [[0, 1.01, 7], [1, 1.01, 0]], "batl": [[2, 1.35, 29.05]]}, {"timestamp": 1631532081997, "ltp": 1.14, "tv": 59.64, "trd": NaN, "batb": [[0, 1.06, 949.73], [1, 1.01, 7]], "batl": NaN}, {"timestamp": 1631532097041, "ltp": 1.14, "tv": 59.64, "trd": NaN, "batb": [[0, 1.01, 7], [1, 1.01, 0]], "batl": NaN}, {"timestamp": 1631532103258, "ltp": 1.14, "tv": 59.64, "trd": NaN, "batb": [[0, 1.09, 763.45], [1, 1.01, 7]], "batl": NaN}, {"timestamp": 1631532115397, "ltp": 1.14, "tv": 59.64, "trd": NaN, "batb": [[0, 1.01, 7], [1, 1.01, 0]], "batl": NaN}, {"timestamp": 1631532121491, "ltp": 1.14, "tv": 59.64, "trd": NaN, "batb": [[0, 1.1, 733.19], [1, 1.01, 7]], "batl": NaN}, {"timestamp": 1631532213132, "ltp": 1.14, "tv": 59.64, "trd": NaN, "batb": [[0, 1.01, 7], [1, 1.01, 0]], "batl": NaN}, {"timestamp": 1631532218602, "ltp": 1.14, "tv": 59.64, "trd": NaN, "batb": [[0, 1.06, 1007.61], [1, 1.01, 7]], "batl": NaN}, {"timestamp": 1631532231460, "ltp": 1.14, "tv": 59.64, "trd": NaN, "batb": [[0, 1.01, 7], [1, 1.01, 0]], "batl": NaN}, {"timestamp": 1631532240973, "ltp": 1.14, "tv": 59.64, "trd": NaN, "batb": [[0, 1.03, 1557.04], [1, 1.01, 7]], "batl": [[2, 1.35, 1116.88]]}, {"timestamp": 1631532254665, "ltp": 1.14, "tv": 59.64, "trd": NaN, "batb": [[0, 1.01, 7], [1, 1.01, 0]], "batl": [[2, 1.35, 29.05]]}, {"timestamp": 1631532265077, "ltp": 1.14, "tv": 59.64, "trd": NaN, "batb": NaN, "batl": [[2, 1.28, 1327.17]]}, {"timestamp": 1631532270477, "ltp": 1.01, "tv": 73.64, "trd": [[1.01, 14]], "batb": NaN, "batl": [[0, 1.01, 10.03], [1, 1.14, 255.54], [2, 1.15, 255.54]]}, {"timestamp": 1631532288909, "ltp": 1.01, "tv": 73.64, "trd": NaN, "batb": NaN, "batl": [[1, 1.09, 29.05], [2, 1.14, 255.54]]}, {"timestamp": 1631532294606, "ltp": 1.01, "tv": 73.64, "trd": NaN, "batb": NaN, "batl": [[0, 1.01, 5546.66]]}, {"timestamp": 1631532298329, "ltp": 1.01, "tv": 73.64, "trd": NaN, "batb": NaN, "batl": [[0, 1.01, 10278.35]]}, {"timestamp": 1631532313754, "ltp": 1.01, "tv": 73.64, "trd": NaN, "batb": NaN, "batl": [[0, 1.01, 5546.66]]}, {"timestamp": 1631532316986, "ltp": 1.01, "tv": 73.64, "trd": NaN, "batb": NaN, "batl": [[2, 1.8, 255.54]]}, {"timestamp": 1631532318855, "ltp": 1.01, "tv": 73.64, "trd": NaN, "batb": NaN, "batl": [[2, 1.2, 4731.69]]}]}, {"runnerId": 22955132, "odds": [{"timestamp": 1631531701889, "ltp": 8.0, "tv": 0.2, "trd": [[8, 0.2]], "batb": NaN, "batl": [[0, 8, 6.4]]}, {"timestamp": 1631531741714, "ltp": 8.0, "tv": 0.2, "trd": NaN, "batb": NaN, "batl": [[0, 7, 6.4]]}, {"timestamp": 1631531775935, "ltp": 8.0, "tv": 0.2, "trd": NaN, "batb": NaN, "batl": [[0, 6, 6.4]]}, {"timestamp": 1631531812496, "ltp": 8.0, "tv": 0.2, "trd": NaN, "batb": NaN, "batl": [[0, 8, 6.4]]}, {"timestamp": 1631531843902, "ltp": 8.0, "tv": 0.2, "trd": NaN, "batb": NaN, "batl": [[0, 6, 6.4]]}, {"timestamp": 1631531914603, "ltp": 8.0, "tv": 0.2, "trd": NaN, "batb": NaN, "batl": [[0, 7, 6.4]]}, {"timestamp": 1631531944538, "ltp": 8.0, "tv": 0.2, "trd": NaN, "batb": NaN, "batl": [[0, 8, 6.4]]}, {"timestamp": 1631531964555, "ltp": 8.0, "tv": 6.6, "trd": [[8, 6.6]], "batb": NaN, "batl": NaN}]}]}