{"info": {"id": "1.187607461", "eventId": "30898293", "eventName": "Match Odds", "marketType": "MATCH_ODDS", "openDate": 1631546502276, "name": "E Avanesyan v G Maristany Zuleta De Reales", "numberOfActiveRunner": 2, "countryCode": "", "sport": "TENNIS", "venue": "", "volume": {"total": 738.12, "preMatch": 35.22, "inPlay": 702.9}, "winner": {"id": 16100628, "name": "G Maristany Zuleta de Reales", "status": "WINNER", "position": 2}, "delay": 5}, "runners": [{"id": 14036296, "name": "E Avanesyan", "status": "LOSER", "position": 1, "inPlayOdds": 1.54, "inPlayTime": 1631548894825, "avgPrematch": 0, "closedOdds": 2.06, "maxPrematch": -100, "minPrematch": 1001, "maxInPlay": 2.5, "minInPlay": 1.54, "inPlayIndex": 0, "lengthOdds": 226, "lengthOddsPrematch": 0, "lengthOddsInPlay": 226, "tradedVolume": 103.13, "preMatchVolume": 3.46, "inPlayVolume": 99.67}, {"id": 16100628, "name": "G Maristany Zuleta de Reales", "status": "WINNER", "position": 2, "inPlayOdds": 1.73, "inPlayTime": 1631547671530, "avgPrematch": 0, "closedOdds": 1.48, "maxPrematch": -100, "minPrematch": 1001, "maxInPlay": 2.84, "minInPlay": 1.18, "inPlayIndex": 0, "lengthOdds": 363, "lengthOddsPrematch": 0, "lengthOddsInPlay": 363, "tradedVolume": 634.99, "preMatchVolume": 31.76, "inPlayVolume": 603.23}], "marketUpdates": [{"timestamp": 1631523892115000000, "openDate": "2021-09-13T15:00:00.000Z", "status": "OPEN", "betDelay": 0, "inPlay": false, "complete": true}, {"timestamp": 1631539617753000000, "openDate": "2021-09-13T15:10:00.000Z", "status": "OPEN", "betDelay": 0, "inPlay": false, "complete": true}, {"timestamp": 1631540232538000000, "openDate": "2021-09-13T15:20:00.000Z", "status": "OPEN", "betDelay": 0, "inPlay": false, "complete": true}, {"timestamp": 1631540292894000000, "openDate": "2021-09-13T15:15:00.000Z", "status": "OPEN", "betDelay": 0, "inPlay": false, "complete": true}, {"timestamp": 1631541649850000000, "openDate": "2021-09-13T15:25:00.000Z", "status": "OPEN", "betDelay": 0, "inPlay": false, "complete": true}, {"timestamp": 1631546447856000000, "openDate": "2021-09-13T15:20:00.000Z", "status": "OPEN", "betDelay": 0, "inPlay": false, "complete": true}, {"timestamp": 1631546502276000000, "openDate": "2021-09-13T15:20:00.000Z", "status": "OPEN", "betDelay": 5, "inPlay": true, "complete": true}, {"timestamp": 1631547050958000000, "openDate": "2021-09-13T15:30:48.000Z", "status": "OPEN", "betDelay": 5, "inPlay": true, "complete": true}, {"timestamp": 1631552946869000000, "openDate": "2021-09-13T15:30:48.000Z", "status": "SUSPENDED", "betDelay": 5, "inPlay": true, "complete": true}, {"timestamp": 1631552953912000000, "openDate": "2021-09-13T15:30:48.000Z", "status": "CLOSED", "betDelay": 5, "inPlay": true, "complete": true}], "odds": [{"runnerId": 14036296, "odds": [{"timestamp": 1631548894825, "ltp": 1.54, "tv": 3.46, "trd": [[1.54, 3.47]], "batb": NaN, "batl": NaN}, {"timestamp": 1631548897919, "ltp": 1.54, "tv": 3.46, "trd": NaN, "batb": [[0, 1.01, 7], [1, 1.01, 0]], "batl": NaN}, {"timestamp": 1631548902838, "ltp": 1.54, "tv": 3.46, "trd": NaN, "batb": [[0, 1.58, 51.72], [1, 1.01, 7]], "batl": NaN}, {"timestamp": 1631548927854, "ltp": 1.54, "tv": 3.46, "trd": NaN, "batb": [[0, 1.01, 7], [1, 1.01, 0]], "batl": NaN}, {"timestamp": 1631548932854, "ltp": 1.54, "tv": 3.46, "trd": NaN, "batb": [[0, 1.78, 38.46], [1, 1.01, 7]], "batl": NaN}, {"timestamp": 1631548959606, "ltp": 1.54, "tv": 3.46, "trd": NaN, "batb": [[0, 1.01, 7], [1, 1.01, 0]], "batl": NaN}, {"timestamp": 1631548964592, "ltp": 1.54, "tv": 3.46, "trd": NaN, "batb": [[0, 2.06, 28.3], [1, 1.01, 7]], "batl": NaN}, {"timestamp": 1631548993858, "ltp": 1.54, "tv": 3.46, "trd": NaN, "batb": NaN, "batl": [[0, 2.24, 160.61]]}, {"timestamp": 1631549067642, "ltp": 1.54, "tv": 3.46, "trd": NaN, "batb": [[0, 1.01, 7], [1, 1.01, 0]], "batl": NaN}, {"timestamp": 1631549072543, "ltp": 1.54, "tv": 3.46, "trd": NaN, "batb": [[0, 2.16, 25.86], [1, 1.01, 7]], "batl": NaN}, {"timestamp": 1631549080879, "ltp": 1.54, "tv": 3.46, "trd": NaN, "batb": NaN, "batl": [[0, 2.42, 160.61]]}, {"timestamp": 1631549088588, "ltp": 1.54, "tv": 3.46, "trd": NaN, "batb": [[0, 1.01, 12], [1, 1.01, 0]], "batl": NaN}, {"timestamp": 1631549095268, "ltp": 1.54, "tv": 3.46, "trd": NaN, "batb": [[0, 2.42, 21.12], [1, 1.01, 12]], "batl": NaN}, {"timestamp": 1631549121726, "ltp": 1.54, "tv": 3.46, "trd": NaN, "batb": [[0, 1.01, 12], [1, 1.01, 0]], "batl": NaN}, {"timestamp": 1631549126736, "ltp": 1.54, "tv": 3.46, "trd": NaN, "batb": [[0, 2.2, 24.99], [1, 1.01, 12]], "batl": NaN}, {"timestamp": 1631549179520, "ltp": 1.54, "tv": 3.46, "trd": NaN, "batb": [[0, 1.01, 12], [1, 1.01, 0]], "batl": NaN}, {"timestamp": 1631549184510, "ltp": 1.54, "tv": 3.46, "trd": NaN, "batb": [[0, 2.16, 25.86], [1, 1.01, 12]], "batl": NaN}, {"timestamp": 1631549206074, "ltp": 1.54, "tv": 3.46, "trd": NaN, "batb": [[0, 1.01, 12], [1, 1.01, 0]], "batl": NaN}, {"timestamp": 1631549211082, "ltp": 1.54, "tv": 3.46, "trd": NaN, "batb": [[0, 2.5, 20], [1, 1.01, 12]], "batl": NaN}, {"timestamp": 1631549238891, "ltp": 1.54, "tv": 3.46, "trd": NaN, "batb": [[0, 1.01, 12], [1, 1.01, 0]], "batl": NaN}, {"timestamp": 1631549243804, "ltp": 1.54, "tv": 3.46, "trd": NaN, "batb": [[0, 2.58, 18.98], [1, 1.01, 12]], "batl": NaN}, {"timestamp": 1631549289363, "ltp": 1.54, "tv": 3.46, "trd": NaN, "batb": [[0, 1.01, 12], [1, 1.01, 0]], "batl": NaN}, {"timestamp": 1631549294371, "ltp": 1.54, "tv": 3.46, "trd": NaN, "batb": [[0, 2.66, 18.07], [1, 1.01, 12]], "batl": NaN}, {"timestamp": 1631549307409, "ltp": 1.54, "tv": 3.46, "trd": NaN, "batb": [[0, 1.01, 12], [1, 1.01, 0]], "batl": NaN}, {"timestamp": 1631549312407, "ltp": 1.54, "tv": 3.46, "trd": NaN, "batb": [[0, 2.84, 16.3], [1, 1.01, 12]], "batl": NaN}, {"timestamp": 1631549318407, "ltp": 1.54, "tv": 3.46, "trd": NaN, "batb": [[0, 1.01, 12], [1, 1.01, 0]], "batl": NaN}, {"timestamp": 1631549323346, "ltp": 1.54, "tv": 3.46, "trd": NaN, "batb": [[0, 2.58, 18.98], [1, 1.01, 12]], "batl": NaN}, {"timestamp": 1631549349019, "ltp": 1.54, "tv": 3.46, "trd": NaN, "batb": [[0, 1.01, 12], [1, 1.01, 0]], "batl": NaN}, {"timestamp": 1631549354040, "ltp": 1.54, "tv": 3.46, "trd": NaN, "batb": [[0, 2.84, 16.3], [1, 1.01, 12]], "batl": NaN}, {"timestamp": 1631549377868, "ltp": 1.54, "tv": 3.46, "trd": NaN, "batb": [[0, 1.01, 12], [1, 1.01, 0]], "batl": NaN}, {"timestamp": 1631549382872, "ltp": 1.54, "tv": 3.46, "trd": NaN, "batb": [[0, 2.58, 18.98], [1, 1.01, 12]], "batl": NaN}, {"timestamp": 1631549413581, "ltp": 1.54, "tv": 3.46, "trd": NaN, "batb": [[0, 1.01, 12], [1, 1.01, 0]], "batl": NaN}, {"timestamp": 1631549418587, "ltp": 1.54, "tv": 3.46, "trd": NaN, "batb": [[0, 2.5, 20], [1, 1.01, 12]], "batl": NaN}, {"timestamp": 1631549428210, "ltp": 2.5, "tv": 23.46, "trd": [[2.5, 20]], "batb": [[0, 1.01, 12], [1, 1.01, 0]], "batl": NaN}, {"timestamp": 1631549433324, "ltp": 2.5, "tv": 23.46, "trd": NaN, "batb": [[0, 2.36, 22.05], [1, 1.01, 12]], "batl": NaN}, {"timestamp": 1631549445637, "ltp": 2.5, "tv": 23.46, "trd": NaN, "batb": [[0, 1.01, 12], [1, 1.01, 0]], "batl": NaN}, {"timestamp": 1631549450545, "ltp": 2.5, "tv": 23.46, "trd": NaN, "batb": [[0, 2.58, 18.98], [1, 1.01, 12]], "batl": NaN}, {"timestamp": 1631549484606, "ltp": 2.5, "tv": 23.46, "trd": NaN, "batb": [[0, 1.01, 12], [1, 1.01, 0]], "batl": NaN}, {"timestamp": 1631549489575, "ltp": 2.5, "tv": 23.46, "trd": NaN, "batb": [[0, 2.66, 18.07], [1, 1.01, 12]], "batl": NaN}, {"timestamp": 1631549492717, "ltp": 2.5, "tv": 23.46, "trd": NaN, "batb": [[0, 1.01, 12], [1, 1.01, 0]], "batl": NaN}, {"timestamp": 1631549497635, "ltp": 2.5, "tv": 23.46, "trd": NaN, "batb": [[0, 2.5, 20], [1, 1.01, 12]], "batl": NaN}, {"timestamp": 1631549506660, "ltp": 2.5, "tv": 43.46, "trd": [[2.5, 40]], "batb": [[0, 1.01, 12], [1, 1.01, 0]], "batl": NaN}, {"timestamp": 1631549511877, "ltp": 2.5, "tv": 43.46, "trd": NaN, "batb": [[0, 2.36, 22.05], [1, 1.01, 12]], "batl": NaN}, {"timestamp": 1631549518718, "ltp": 2.5, "tv": 43.46, "trd": NaN, "batb": [[0, 1.01, 12], [1, 1.01, 0]], "batl": NaN}, {"timestamp": 1631549523631, "ltp": 2.5, "tv": 43.46, "trd": NaN, "batb": [[0, 2.58, 18.98], [1, 1.01, 12]], "batl": NaN}, {"timestamp": 1631549536413, "ltp": 2.5, "tv": 43.46, "trd": NaN, "batb": [[0, 1.01, 12], [1, 1.01, 0]], "batl": NaN}, {"timestamp": 1631549541459, "ltp": 2.5, "tv": 43.46, "trd": NaN, "batb": [[0, 2.84, 16.3], [1, 1.01, 12]], "batl": NaN}, {"timestamp": 1631549552923, "ltp": 2.5, "tv": 43.46, "trd": NaN, "batb": [[0, 1.01, 12], [1, 1.01, 0]], "batl": NaN}, {"timestamp": 1631549558037, "ltp": 2.5, "tv": 43.46, "trd": NaN, "batb": [[0, 2.58, 18.98], [1, 1.01, 12]], "batl": NaN}, {"timestamp": 1631549575130, "ltp": 2.5, "tv": 43.46, "trd": NaN, "batb": [[0, 1.01, 12], [1, 1.01, 0]], "batl": NaN}, {"timestamp": 1631549580045, "ltp": 2.5, "tv": 43.46, "trd": NaN, "batb": [[0, 2.5, 20], [1, 1.01, 12]], "batl": NaN}, {"timestamp": 1631549590488, "ltp": 2.5, "tv": 63.46, "trd": [[2.5, 60]], "batb": [[0, 1.01, 12], [1, 1.01, 0]], "batl": NaN}, {"timestamp": 1631549595446, "ltp": 2.5, "tv": 63.46, "trd": NaN, "batb": [[0, 2.36, 22.05], [1, 1.01, 12]], "batl": NaN}, {"timestamp": 1631549639918, "ltp": 2.5, "tv": 63.46, "trd": NaN, "batb": [[0, 1.01, 12], [1, 1.01, 0]], "batl": NaN}, {"timestamp": 1631549644873, "ltp": 2.5, "tv": 63.46, "trd": NaN, "batb": [[0, 2.58, 18.98], [1, 1.01, 12]], "batl": NaN}, {"timestamp": 1631549666987, "ltp": 2.5, "tv": 63.46, "trd": NaN, "batb": [[0, 1.01, 12], [1, 1.01, 0]], "batl": NaN}, {"timestamp": 1631549671811, "ltp": 2.5, "tv": 63.46, "trd": NaN, "batb": [[0, 2.84, 16.3], [1, 1.01, 12]], "batl": NaN}, {"timestamp": 1631549708638, "ltp": 2.5, "tv": 63.46, "trd": NaN, "batb": [[0, 1.01, 12], [1, 1.01, 0]], "batl": NaN}, {"timestamp": 1631549713543, "ltp": 2.5, "tv": 63.46, "trd": NaN, "batb": [[0, 2.66, 18.07], [1, 1.01, 12]], "batl": NaN}, {"timestamp": 1631549721260, "ltp": 2.5, "tv": 63.46, "trd": NaN, "batb": [[0, 1.01, 12], [1, 1.01, 0]], "batl": NaN}, {"timestamp": 1631549726307, "ltp": 2.5, "tv": 63.46, "trd": NaN, "batb": [[0, 2.84, 16.3], [1, 1.01, 12]], "batl": NaN}, {"timestamp": 1631549744803, "ltp": 2.5, "tv": 63.46, "trd": NaN, "batb": [[0, 1.01, 12], [1, 1.01, 0]], "batl": NaN}, {"timestamp": 1631549749708, "ltp": 2.5, "tv": 63.46, "trd": NaN, "batb": [[0, 3.15, 13.95], [1, 1.01, 12]], "batl": NaN}, {"timestamp": 1631550165998, "ltp": 2.5, "tv": 63.46, "trd": NaN, "batb": [[0, 1.01, 12], [1, 1.01, 0]], "batl": NaN}, {"timestamp": 1631550171006, "ltp": 2.5, "tv": 63.46, "trd": NaN, "batb": [[0, 3.4, 12.5], [1, 1.01, 12]], "batl": NaN}, {"timestamp": 1631550195191, "ltp": 2.5, "tv": 63.46, "trd": NaN, "batb": [[0, 1.01, 12], [1, 1.01, 0]], "batl": NaN}, {"timestamp": 1631550200204, "ltp": 2.5, "tv": 63.46, "trd": NaN, "batb": [[0, 3, 15], [1, 1.01, 12]], "batl": NaN}, {"timestamp": 1631550230333, "ltp": 2.5, "tv": 63.46, "trd": NaN, "batb": [[0, 1.01, 12], [1, 1.01, 0]], "batl": NaN}, {"timestamp": 1631550235268, "ltp": 2.5, "tv": 63.46, "trd": NaN, "batb": [[0, 3.4, 12.5], [1, 1.01, 12]], "batl": NaN}, {"timestamp": 1631550256875, "ltp": 2.5, "tv": 63.46, "trd": NaN, "batb": [[0, 1.01, 12], [1, 1.01, 0]], "batl": NaN}, {"timestamp": 1631550261786, "ltp": 2.5, "tv": 63.46, "trd": NaN, "batb": [[0, 3, 15], [1, 1.01, 12]], "batl": NaN}, {"timestamp": 1631550282030, "ltp": 2.5, "tv": 63.46, "trd": NaN, "batb": [[0, 1.01, 12], [1, 1.01, 0]], "batl": NaN}, {"timestamp": 1631550286941, "ltp": 2.5, "tv": 63.46, "trd": NaN, "batb": [[0, 3.4, 12.5], [1, 1.01, 12]], "batl": NaN}, {"timestamp": 1631550326917, "ltp": 2.5, "tv": 63.46, "trd": NaN, "batb": [[0, 1.01, 12], [1, 1.01, 0]], "batl": NaN}, {"timestamp": 1631550331822, "ltp": 2.5, "tv": 63.46, "trd": NaN, "batb": [[0, 4.1, 10], [1, 1.01, 12]], "batl": NaN}, {"timestamp": 1631550383205, "ltp": 2.5, "tv": 63.46, "trd": NaN, "batb": [[0, 1.01, 12], [1, 1.01, 0]], "batl": NaN}, {"timestamp": 1631550388121, "ltp": 2.5, "tv": 63.46, "trd": NaN, "batb": [[0, 3.7, 11.11], [1, 1.01, 12]], "batl": NaN}, {"timestamp": 1631550426145, "ltp": 2.5, "tv": 63.46, "trd": NaN, "batb": [[0, 1.01, 12], [1, 1.01, 0]], "batl": NaN}, {"timestamp": 1631550431177, "ltp": 2.5, "tv": 63.46, "trd": NaN, "batb": [[0, 3.3, 13.04], [1, 1.01, 12]], "batl": NaN}, {"timestamp": 1631550447989, "ltp": 2.5, "tv": 63.46, "trd": NaN, "batb": [[0, 1.01, 12], [1, 1.01, 0]], "batl": NaN}, {"timestamp": 1631550452983, "ltp": 2.5, "tv": 63.46, "trd": NaN, "batb": [[0, 3, 15], [1, 1.01, 12]], "batl": NaN}, {"timestamp": 1631550505851, "ltp": 2.5, "tv": 63.46, "trd": NaN, "batb": [[0, 1.01, 12], [1, 1.01, 0]], "batl": NaN}, {"timestamp": 1631550510744, "ltp": 2.5, "tv": 63.46, "trd": NaN, "batb": [[0, 3.3, 13.04], [1, 1.01, 12]], "batl": NaN}, {"timestamp": 1631550534572, "ltp": 2.5, "tv": 63.46, "trd": NaN, "batb": [[0, 1.01, 12], [1, 1.01, 0]], "batl": NaN}, {"timestamp": 1631550539569, "ltp": 2.5, "tv": 63.46, "trd": NaN, "batb": [[0, 2.84, 16.3], [1, 1.01, 12]], "batl": NaN}, {"timestamp": 1631550570235, "ltp": 2.5, "tv": 63.46, "trd": NaN, "batb": [[0, 1.01, 12], [1, 1.01, 0]], "batl": NaN}, {"timestamp": 1631550575144, "ltp": 2.5, "tv": 63.46, "trd": NaN, "batb": [[0, 2.58, 18.98], [1, 1.01, 12]], "batl": NaN}, {"timestamp": 1631550641527, "ltp": 2.5, "tv": 63.46, "trd": NaN, "batb": [[0, 1.01, 12], [1, 1.01, 0]], "batl": NaN}, {"timestamp": 1631550646461, "ltp": 2.5, "tv": 63.46, "trd": NaN, "batb": [[0, 2.42, 21.12], [1, 1.01, 12]], "batl": NaN}, {"timestamp": 1631550704934, "ltp": 2.5, "tv": 63.46, "trd": NaN, "batb": [[0, 1.01, 12], [1, 1.01, 0]], "batl": NaN}, {"timestamp": 1631550709868, "ltp": 2.5, "tv": 63.46, "trd": NaN, "batb": [[0, 2.2, 24.99], [1, 1.01, 12]], "batl": NaN}, {"timestamp": 1631550805456, "ltp": 2.5, "tv": 63.46, "trd": NaN, "batb": [[0, 1.01, 12], [1, 1.01, 0]], "batl": NaN}, {"timestamp": 1631550810413, "ltp": 2.5, "tv": 63.46, "trd": NaN, "batb": [[0, 2.42, 21.12], [1, 1.01, 12]], "batl": NaN}, {"timestamp": 1631550828444, "ltp": 2.5, "tv": 63.46, "trd": NaN, "batb": [[0, 1.01, 12], [1, 1.01, 0]], "batl": NaN}, {"timestamp": 1631550833339, "ltp": 2.5, "tv": 63.46, "trd": NaN, "batb": [[0, 2.5, 20], [1, 1.01, 12]], "batl": NaN}, {"timestamp": 1631550850336, "ltp": 2.5, "tv": 63.46, "trd": NaN, "batb": [[0, 1.01, 12], [1, 1.01, 0]], "batl": NaN}, {"timestamp": 1631550855277, "ltp": 2.5, "tv": 63.46, "trd": NaN, "batb": [[0, 2.2, 24.99], [1, 1.01, 12]], "batl": NaN}, {"timestamp": 1631550872190, "ltp": 2.5, "tv": 63.46, "trd": NaN, "batb": [[0, 1.01, 12], [1, 1.01, 0]], "batl": NaN}, {"timestamp": 1631550877203, "ltp": 2.5, "tv": 63.46, "trd": NaN, "batb": [[0, 2.06, 28.3], [1, 1.01, 12]], "batl": NaN}, {"timestamp": 1631550894821, "ltp": 2.5, "tv": 63.46, "trd": NaN, "batb": [[0, 1.01, 12], [1, 1.01, 0]], "batl": NaN}, {"timestamp": 1631550899824, "ltp": 2.5, "tv": 63.46, "trd": NaN, "batb": [[0, 1.98, 30.61], [1, 1.01, 12]], "batl": NaN}, {"timestamp": 1631550910601, "ltp": 2.5, "tv": 63.46, "trd": NaN, "batb": [[0, 1.01, 12], [1, 1.01, 0]], "batl": NaN}, {"timestamp": 1631550915544, "ltp": 2.5, "tv": 63.46, "trd": NaN, "batb": [[0, 2, 30], [1, 1.01, 12]], "batl": NaN}, {"timestamp": 1631550929249, "ltp": 2.5, "tv": 63.46, "trd": NaN, "batb": [[0, 1.01, 12], [1, 1.01, 0]], "batl": NaN}, {"timestamp": 1631550934242, "ltp": 2.5, "tv": 63.46, "trd": NaN, "batb": [[0, 2.06, 28.3], [1, 1.01, 12]], "batl": NaN}, {"timestamp": 1631550957368, "ltp": 2.5, "tv": 63.46, "trd": NaN, "batb": [[0, 1.01, 12], [1, 1.01, 0]], "batl": NaN}, {"timestamp": 1631550962391, "ltp": 2.5, "tv": 63.46, "trd": NaN, "batb": [[0, 1.98, 30.61], [1, 1.01, 12]], "batl": NaN}, {"timestamp": 1631550998730, "ltp": 2.5, "tv": 63.46, "trd": NaN, "batb": [[0, 1.01, 12], [1, 1.01, 0]], "batl": NaN}, {"timestamp": 1631551003719, "ltp": 2.5, "tv": 63.46, "trd": NaN, "batb": [[0, 1.85, 35.29], [1, 1.01, 12]], "batl": NaN}, {"timestamp": 1631551029878, "ltp": 2.5, "tv": 63.46, "trd": NaN, "batb": [[0, 1.01, 12], [1, 1.01, 0]], "batl": NaN}, {"timestamp": 1631551034756, "ltp": 2.5, "tv": 63.46, "trd": NaN, "batb": [[0, 1.73, 41.09], [1, 1.01, 12]], "batl": NaN}, {"timestamp": 1631551056890, "ltp": 2.5, "tv": 63.46, "trd": NaN, "batb": [[0, 1.01, 12], [1, 1.01, 0]], "batl": NaN}, {"timestamp": 1631551061783, "ltp": 2.5, "tv": 63.46, "trd": NaN, "batb": [[0, 1.85, 35.29], [1, 1.01, 12]], "batl": NaN}, {"timestamp": 1631551095189, "ltp": 2.5, "tv": 63.46, "trd": NaN, "batb": [[0, 1.01, 12], [1, 1.01, 0]], "batl": NaN}, {"timestamp": 1631551100112, "ltp": 2.5, "tv": 63.46, "trd": NaN, "batb": [[0, 1.78, 38.46], [1, 1.01, 12]], "batl": NaN}, {"timestamp": 1631551109412, "ltp": 2.5, "tv": 63.46, "trd": NaN, "batb": [[0, 1.01, 12], [1, 1.01, 0]], "batl": NaN}, {"timestamp": 1631551114335, "ltp": 2.5, "tv": 63.46, "trd": NaN, "batb": [[0, 1.88, 34.09], [1, 1.01, 12]], "batl": NaN}, {"timestamp": 1631551139964, "ltp": 2.5, "tv": 63.46, "trd": NaN, "batb": [[0, 1.01, 12], [1, 1.01, 0]], "batl": NaN}, {"timestamp": 1631551144970, "ltp": 2.5, "tv": 63.46, "trd": NaN, "batb": [[0, 1.78, 38.46], [1, 1.01, 12]], "batl": NaN}, {"timestamp": 1631551186717, "ltp": 2.5, "tv": 63.46, "trd": NaN, "batb": [[0, 1.01, 12], [1, 1.01, 0]], "batl": NaN}, {"timestamp": 1631551191719, "ltp": 2.5, "tv": 63.46, "trd": NaN, "batb": [[0, 1.88, 34.09], [1, 1.01, 12]], "batl": NaN}, {"timestamp": 1631551231649, "ltp": 2.5, "tv": 63.46, "trd": NaN, "batb": [[0, 1.01, 12], [1, 1.01, 0]], "batl": NaN}, {"timestamp": 1631551236661, "ltp": 2.5, "tv": 63.46, "trd": NaN, "batb": [[0, 2.06, 28.3], [1, 1.01, 12]], "batl": NaN}, {"timestamp": 1631551288126, "ltp": 2.5, "tv": 63.46, "trd": NaN, "batb": [[0, 1.01, 12], [1, 1.01, 0]], "batl": NaN}, {"timestamp": 1631551293150, "ltp": 2.5, "tv": 63.46, "trd": NaN, "batb": [[0, 2.2, 24.99], [1, 1.01, 12]], "batl": NaN}, {"timestamp": 1631551388712, "ltp": 2.5, "tv": 63.46, "trd": NaN, "batb": [[0, 1.01, 12], [1, 1.01, 0]], "batl": NaN}, {"timestamp": 1631551393741, "ltp": 2.5, "tv": 63.46, "trd": NaN, "batb": [[0, 2.42, 21.12], [1, 1.01, 12]], "batl": NaN}, {"timestamp": 1631551406442, "ltp": 2.5, "tv": 63.46, "trd": NaN, "batb": [[0, 1.01, 12], [1, 1.01, 0]], "batl": NaN}, {"timestamp": 1631551411333, "ltp": 2.5, "tv": 63.46, "trd": NaN, "batb": [[0, 2.2, 24.99], [1, 1.01, 12]], "batl": NaN}, {"timestamp": 1631551426457, "ltp": 2.5, "tv": 63.46, "trd": NaN, "batb": [[0, 1.01, 12], [1, 1.01, 0]], "batl": NaN}, {"timestamp": 1631551431477, "ltp": 2.5, "tv": 63.46, "trd": NaN, "batb": [[0, 2.5, 20], [1, 1.01, 12]], "batl": NaN}, {"timestamp": 1631551473093, "ltp": 2.5, "tv": 63.46, "trd": NaN, "batb": [[0, 1.01, 12], [1, 1.01, 0]], "batl": NaN}, {"timestamp": 1631551477988, "ltp": 2.5, "tv": 63.46, "trd": NaN, "batb": [[0, 2.26, 23.8], [1, 1.01, 12]], "batl": NaN}, {"timestamp": 1631551491626, "ltp": 2.5, "tv": 63.46, "trd": NaN, "batb": [[0, 1.01, 12], [1, 1.01, 0]], "batl": NaN}, {"timestamp": 1631551496531, "ltp": 2.5, "tv": 63.46, "trd": NaN, "batb": [[0, 2.06, 28.3], [1, 1.01, 12]], "batl": NaN}, {"timestamp": 1631551509645, "ltp": 2.5, "tv": 63.46, "trd": NaN, "batb": [[0, 1.01, 12], [1, 1.01, 0]], "batl": NaN}, {"timestamp": 1631551514647, "ltp": 2.5, "tv": 63.46, "trd": NaN, "batb": [[0, 1.88, 34.09], [1, 1.01, 12]], "batl": NaN}, {"timestamp": 1631551536868, "ltp": 2.5, "tv": 63.46, "trd": NaN, "batb": [[0, 1.01, 12], [1, 1.01, 0]], "batl": NaN}, {"timestamp": 1631551541934, "ltp": 2.5, "tv": 63.46, "trd": NaN, "batb": [[0, 2, 30], [1, 1.01, 12]], "batl": NaN}, {"timestamp": 1631551562430, "ltp": 2.5, "tv": 63.46, "trd": NaN, "batb": [[0, 1.01, 12], [1, 1.01, 0]], "batl": NaN}, {"timestamp": 1631551567360, "ltp": 2.5, "tv": 63.46, "trd": NaN, "batb": [[0, 2.06, 28.3], [1, 1.01, 12]], "batl": NaN}, {"timestamp": 1631551590890, "ltp": 2.06, "tv": 103.11, "trd": [[2.06, 39.65]], "batb": [[0, 1.01, 12], [1, 1.01, 0]], "batl": NaN}, {"timestamp": 1631551595801, "ltp": 2.06, "tv": 103.11, "trd": NaN, "batb": [[0, 1.96, 31.25], [1, 1.01, 12]], "batl": NaN}, {"timestamp": 1631551606010, "ltp": 2.06, "tv": 103.11, "trd": NaN, "batb": [[0, 1.01, 12], [1, 1.01, 0]], "batl": NaN}, {"timestamp": 1631551610917, "ltp": 2.06, "tv": 103.11, "trd": NaN, "batb": [[0, 1.98, 30.61], [1, 1.01, 12]], "batl": NaN}, {"timestamp": 1631551646944, "ltp": 2.06, "tv": 103.11, "trd": NaN, "batb": [[0, 1.01, 12], [1, 1.01, 0]], "batl": NaN}, {"timestamp": 1631551651972, "ltp": 2.06, "tv": 103.11, "trd": NaN, "batb": [[0, 2.06, 28.3], [1, 1.01, 12]], "batl": NaN}, {"timestamp": 1631551689111, "ltp": 2.06, "tv": 103.11, "trd": NaN, "batb": [[0, 1.01, 12], [1, 1.01, 0]], "batl": NaN}, {"timestamp": 1631551694121, "ltp": 2.06, "tv": 103.11, "trd": NaN, "batb": [[0, 2, 30], [1, 1.01, 12]], "batl": NaN}, {"timestamp": 1631551720987, "ltp": 2.06, "tv": 103.11, "trd": NaN, "batb": [[0, 1.01, 12], [1, 1.01, 0]], "batl": NaN}, {"timestamp": 1631551725895, "ltp": 2.06, "tv": 103.11, "trd": NaN, "batb": [[0, 2.1, 27.27], [1, 1.01, 12]], "batl": NaN}, {"timestamp": 1631551810226, "ltp": 2.06, "tv": 103.11, "trd": NaN, "batb": [[0, 1.01, 12], [1, 1.01, 0]], "batl": NaN}, {"timestamp": 1631551815110, "ltp": 2.06, "tv": 103.11, "trd": NaN, "batb": [[0, 1.98, 30.61], [1, 1.01, 12]], "batl": NaN}, {"timestamp": 1631551842183, "ltp": 2.06, "tv": 103.11, "trd": NaN, "batb": [[0, 1.01, 12], [1, 1.01, 0]], "batl": NaN}, {"timestamp": 1631551847120, "ltp": 2.06, "tv": 103.11, "trd": NaN, "batb": [[0, 1.88, 34.09], [1, 1.01, 12]], "batl": NaN}, {"timestamp": 1631551863662, "ltp": 2.06, "tv": 103.11, "trd": NaN, "batb": [[0, 1.01, 12], [1, 1.01, 0]], "batl": NaN}, {"timestamp": 1631551868559, "ltp": 2.06, "tv": 103.11, "trd": NaN, "batb": [[0, 1.78, 38.46], [1, 1.01, 12]], "batl": NaN}, {"timestamp": 1631551904302, "ltp": 2.06, "tv": 103.11, "trd": NaN, "batb": [[0, 1.01, 12], [1, 1.01, 0]], "batl": NaN}, {"timestamp": 1631551909312, "ltp": 2.06, "tv": 103.11, "trd": NaN, "batb": [[0, 1.73, 41.09], [1, 1.01, 12]], "batl": NaN}, {"timestamp": 1631551938041, "ltp": 2.06, "tv": 103.11, "trd": NaN, "batb": [[0, 1.01, 12], [1, 1.01, 0]], "batl": NaN}, {"timestamp": 1631551943020, "ltp": 2.06, "tv": 103.11, "trd": NaN, "batb": [[0, 1.85, 35.29], [1, 1.01, 12]], "batl": NaN}, {"timestamp": 1631551960062, "ltp": 2.06, "tv": 103.11, "trd": NaN, "batb": [[0, 1.01, 12], [1, 1.01, 0]], "batl": NaN}, {"timestamp": 1631551965072, "ltp": 2.06, "tv": 103.11, "trd": NaN, "batb": [[0, 1.88, 34.09], [1, 1.01, 12]], "batl": NaN}, {"timestamp": 1631552033458, "ltp": 2.06, "tv": 103.11, "trd": NaN, "batb": [[0, 1.01, 12], [1, 1.01, 0]], "batl": NaN}, {"timestamp": 1631552038475, "ltp": 2.06, "tv": 103.11, "trd": NaN, "batb": [[0, 1.98, 30.61], [1, 1.01, 12]], "batl": NaN}, {"timestamp": 1631552125456, "ltp": 2.06, "tv": 103.11, "trd": NaN, "batb": [[0, 1.01, 12], [1, 1.01, 0]], "batl": NaN}, {"timestamp": 1631552130370, "ltp": 2.06, "tv": 103.11, "trd": NaN, "batb": [[0, 1.85, 35.29], [1, 1.01, 12]], "batl": NaN}, {"timestamp": 1631552146784, "ltp": 2.06, "tv": 103.11, "trd": NaN, "batb": [[0, 1.01, 12], [1, 1.01, 0]], "batl": NaN}, {"timestamp": 1631552151679, "ltp": 2.06, "tv": 103.11, "trd": NaN, "batb": [[0, 1.71, 42.25], [1, 1.01, 12]], "batl": NaN}, {"timestamp": 1631552160000, "ltp": 2.06, "tv": 103.11, "trd": NaN, "batb": [[0, 1.01, 12], [1, 1.01, 0]], "batl": NaN}, {"timestamp": 1631552165002, "ltp": 2.06, "tv": 103.11, "trd": NaN, "batb": [[0, 1.73, 41.09], [1, 1.01, 12]], "batl": NaN}, {"timestamp": 1631552170902, "ltp": 2.06, "tv": 103.11, "trd": NaN, "batb": [[0, 1.01, 12], [1, 1.01, 0]], "batl": NaN}, {"timestamp": 1631552175895, "ltp": 2.06, "tv": 103.11, "trd": NaN, "batb": [[0, 1.71, 42.25], [1, 1.01, 12]], "batl": NaN}, {"timestamp": 1631552199697, "ltp": 2.06, "tv": 103.11, "trd": NaN, "batb": [[0, 1.01, 12], [1, 1.01, 0]], "batl": NaN}, {"timestamp": 1631552204704, "ltp": 2.06, "tv": 103.11, "trd": NaN, "batb": [[0, 1.73, 41.09], [1, 1.01, 12]], "batl": NaN}, {"timestamp": 1631552227722, "ltp": 2.06, "tv": 103.11, "trd": NaN, "batb": [[0, 1.01, 12], [1, 1.01, 0]], "batl": NaN}, {"timestamp": 1631552232606, "ltp": 2.06, "tv": 103.11, "trd": NaN, "batb": [[0, 1.65, 46.15], [1, 1.01, 12]], "batl": NaN}, {"timestamp": 1631552323569, "ltp": 2.06, "tv": 103.11, "trd": NaN, "batb": [[0, 1.01, 12], [1, 1.01, 0]], "batl": NaN}, {"timestamp": 1631552328461, "ltp": 2.06, "tv": 103.11, "trd": NaN, "batb": [[0, 1.58, 51.72], [1, 1.01, 12]], "batl": NaN}, {"timestamp": 1631552343585, "ltp": 2.06, "tv": 103.11, "trd": NaN, "batb": [[0, 1.01, 12], [1, 1.01, 0]], "batl": NaN}, {"timestamp": 1631552348468, "ltp": 2.06, "tv": 103.11, "trd": NaN, "batb": [[0, 1.63, 47.61], [1, 1.01, 12]], "batl": NaN}, {"timestamp": 1631552352966, "ltp": 2.06, "tv": 103.11, "trd": NaN, "batb": [[0, 1.01, 12], [1, 1.01, 0]], "batl": NaN}, {"timestamp": 1631552357984, "ltp": 2.06, "tv": 103.11, "trd": NaN, "batb": [[0, 1.65, 46.15], [1, 1.01, 12]], "batl": NaN}, {"timestamp": 1631552361711, "ltp": 2.06, "tv": 103.11, "trd": NaN, "batb": [[0, 1.01, 12], [1, 1.01, 0]], "batl": NaN}, {"timestamp": 1631552366696, "ltp": 2.06, "tv": 103.11, "trd": NaN, "batb": [[0, 2.06, 28.3], [1, 1.01, 12]], "batl": NaN}, {"timestamp": 1631552384246, "ltp": 2.06, "tv": 103.11, "trd": NaN, "batb": [[0, 1.01, 12], [1, 1.01, 0]], "batl": NaN}, {"timestamp": 1631552389115, "ltp": 2.06, "tv": 103.11, "trd": NaN, "batb": [[0, 2.1, 27.27], [1, 1.01, 12]], "batl": NaN}, {"timestamp": 1631552398931, "ltp": 2.06, "tv": 103.11, "trd": NaN, "batb": [[0, 1.01, 12], [1, 1.01, 0]], "batl": NaN}, {"timestamp": 1631552403901, "ltp": 2.06, "tv": 103.13, "trd": [[1.54, 3.46], [2.06, 39.67]], "batb": [[0, 1.73, 41.09], [1, 1.01, 12]], "batl": NaN}, {"timestamp": 1631552420401, "ltp": 2.06, "tv": 103.13, "trd": NaN, "batb": [[0, 1.01, 12], [1, 1.01, 0]], "batl": NaN}, {"timestamp": 1631552425404, "ltp": 2.06, "tv": 103.13, "trd": NaN, "batb": [[0, 1.48, 62.5], [1, 1.01, 12]], "batl": NaN}, {"timestamp": 1631552456566, "ltp": 2.06, "tv": 103.13, "trd": NaN, "batb": [[0, 1.01, 12], [1, 1.01, 0]], "batl": NaN}, {"timestamp": 1631552461564, "ltp": 2.06, "tv": 103.13, "trd": NaN, "batb": [[0, 1.78, 38.46], [1, 1.67, 29.95], [2, 1.01, 12]], "batl": NaN}, {"timestamp": 1631552461988, "ltp": 2.06, "tv": 103.13, "trd": NaN, "batb": [[1, 1.01, 12], [2, 1.01, 0]], "batl": NaN}, {"timestamp": 1631552464568, "ltp": 2.06, "tv": 103.13, "trd": NaN, "batb": NaN, "batl": [[0, 1.9, 2.6]]}, {"timestamp": 1631552484816, "ltp": 2.06, "tv": 103.13, "trd": NaN, "batb": [[0, 1.01, 12], [1, 1.01, 0]], "batl": NaN}, {"timestamp": 1631552492221, "ltp": 2.06, "tv": 103.13, "trd": NaN, "batb": [[0, 2.1, 27.27], [1, 1.01, 12]], "batl": NaN}, {"timestamp": 1631552508430, "ltp": 2.06, "tv": 103.13, "trd": NaN, "batb": [[0, 1.01, 12], [1, 1.01, 0]], "batl": NaN}, {"timestamp": 1631552513432, "ltp": 2.06, "tv": 103.13, "trd": NaN, "batb": [[0, 2.84, 16.3], [1, 1.01, 12]], "batl": NaN}, {"timestamp": 1631552561581, "ltp": 2.06, "tv": 103.13, "trd": NaN, "batb": [[0, 1.01, 12], [1, 1.01, 0]], "batl": NaN}, {"timestamp": 1631552566581, "ltp": 2.06, "tv": 103.13, "trd": NaN, "batb": [[0, 3.15, 13.95], [1, 1.01, 12]], "batl": NaN}, {"timestamp": 1631552578880, "ltp": 2.06, "tv": 103.13, "trd": NaN, "batb": [[0, 1.01, 12], [1, 1.01, 0]], "batl": NaN}, {"timestamp": 1631552583797, "ltp": 2.06, "tv": 103.13, "trd": NaN, "batb": [[0, 4.3, 10], [1, 1.01, 12]], "batl": NaN}, {"timestamp": 1631552631151, "ltp": 2.06, "tv": 103.13, "trd": NaN, "batb": [[0, 1.01, 12], [1, 1.01, 0]], "batl": NaN}, {"timestamp": 1631552636090, "ltp": 2.06, "tv": 103.13, "trd": NaN, "batb": [[0, 3.15, 13.95], [1, 1.01, 12]], "batl": NaN}, {"timestamp": 1631552658329, "ltp": 2.06, "tv": 103.13, "trd": NaN, "batb": [[0, 1.01, 12], [1, 1.01, 0]], "batl": NaN}, {"timestamp": 1631552663341, "ltp": 2.06, "tv": 103.13, "trd": NaN, "batb": [[0, 2.2, 24.99], [1, 1.01, 12]], "batl": NaN}, {"timestamp": 1631552684494, "ltp": 2.06, "tv": 103.13, "trd": NaN, "batb": [[0, 1.01, 12], [1, 1.01, 0]], "batl": NaN}, {"timestamp": 1631552689520, "ltp": 2.06, "tv": 103.13, "trd": NaN, "batb": [[0, 3.3, 13.04], [1, 1.01, 12]], "batl": NaN}, {"timestamp": 1631552699524, "ltp": 2.06, "tv": 103.13, "trd": NaN, "batb": [[0, 1.01, 12], [1, 1.01, 0]], "batl": NaN}, {"timestamp": 1631552704356, "ltp": 2.06, "tv": 103.13, "trd": NaN, "batb": [[0, 3.4, 12.5], [1, 1.01, 12]], "batl": NaN}, {"timestamp": 1631552717879, "ltp": 2.06, "tv": 103.13, "trd": NaN, "batb": [[0, 1.01, 12], [1, 1.01, 0]], "batl": NaN}, {"timestamp": 1631552722882, "ltp": 2.06, "tv": 103.13, "trd": NaN, "batb": [[0, 2.5, 20], [1, 1.01, 12]], "batl": NaN}, {"timestamp": 1631552728556, "ltp": 2.06, "tv": 103.13, "trd": NaN, "batb": [[0, 3.1, 2], [1, 2.5, 20], [2, 1.01, 12]], "batl": NaN}, {"timestamp": 1631552729088, "ltp": 2.06, "tv": 103.13, "trd": NaN, "batb": [[0, 2.5, 20], [1, 1.01, 12], [2, 1.01, 0]], "batl": NaN}, {"timestamp": 1631552751090, "ltp": 2.06, "tv": 103.13, "trd": NaN, "batb": [[0, 1.01, 12], [1, 1.01, 0]], "batl": NaN}, {"timestamp": 1631552755994, "ltp": 2.06, "tv": 103.13, "trd": NaN, "batb": [[0, 3.7, 11.11], [1, 1.01, 12]], "batl": NaN}, {"timestamp": 1631552800236, "ltp": 2.06, "tv": 103.13, "trd": NaN, "batb": [[0, 1.01, 12], [1, 1.01, 0]], "batl": NaN}, {"timestamp": 1631552805281, "ltp": 2.06, "tv": 103.13, "trd": NaN, "batb": [[0, 6, 10], [1, 1.01, 12]], "batl": NaN}, {"timestamp": 1631552817073, "ltp": 2.06, "tv": 103.13, "trd": NaN, "batb": [[0, 1.01, 12], [1, 1.01, 0]], "batl": NaN}, {"timestamp": 1631552821997, "ltp": 2.06, "tv": 103.13, "trd": NaN, "batb": [[0, 4.3, 10], [1, 1.01, 12]], "batl": NaN}, {"timestamp": 1631552834124, "ltp": 2.06, "tv": 103.13, "trd": NaN, "batb": [[0, 1.01, 12], [1, 1.01, 0]], "batl": NaN}, {"timestamp": 1631552839097, "ltp": 2.06, "tv": 103.13, "trd": NaN, "batb": [[0, 4.8, 10], [1, 1.01, 12]], "batl": NaN}, {"timestamp": 1631552858568, "ltp": 2.06, "tv": 103.13, "trd": NaN, "batb": [[0, 1.01, 12], [1, 1.01, 0]], "batl": NaN}, {"timestamp": 1631552863564, "ltp": 2.06, "tv": 103.13, "trd": NaN, "batb": [[0, 12, 10], [1, 1.01, 12]], "batl": NaN}, {"timestamp": 1631552891078, "ltp": 2.06, "tv": 103.13, "trd": NaN, "batb": [[0, 1.01, 12], [1, 1.01, 0]], "batl": NaN}]}, {"runnerId": 16100628, "odds": [{"timestamp": 1631547671530, "ltp": 1.73, "tv": 31.76, "trd": [[1.73, 31.76]], "batb": [[0, 1.01, 7], [1, 1.01, 0]], "batl": NaN}, {"timestamp": 1631547676531, "ltp": 1.73, "tv": 31.76, "trd": NaN, "batb": [[0, 1.73, 41.09], [1, 1.01, 7]], "batl": NaN}, {"timestamp": 1631547687249, "ltp": 1.73, "tv": 31.76, "trd": NaN, "batb": [[0, 1.01, 7], [1, 1.01, 0]], "batl": NaN}, {"timestamp": 1631547692129, "ltp": 1.73, "tv": 31.76, "trd": NaN, "batb": [[0, 1.85, 35.29], [1, 1.01, 7]], "batl": NaN}, {"timestamp": 1631547712896, "ltp": 1.85, "tv": 46.2, "trd": [[1.85, 14.44]], "batb": [[0, 1.01, 7], [1, 1.01, 0]], "batl": NaN}, {"timestamp": 1631547717776, "ltp": 1.85, "tv": 46.2, "trd": NaN, "batb": [[0, 1.85, 35.29], [1, 1.01, 7]], "batl": NaN}, {"timestamp": 1631547717984, "ltp": 1.85, "tv": 46.2, "trd": NaN, "batb": [[0, 1.01, 7], [1, 1.01, 0]], "batl": NaN}, {"timestamp": 1631547722983, "ltp": 1.85, "tv": 46.2, "trd": NaN, "batb": [[0, 1.98, 30.61], [1, 1.01, 7]], "batl": NaN}, {"timestamp": 1631547772673, "ltp": 1.85, "tv": 46.2, "trd": NaN, "batb": NaN, "batl": [[0, 2.24, 24.21], [1, 2.84, 106.47]]}, {"timestamp": 1631547820217, "ltp": 1.85, "tv": 46.2, "trd": NaN, "batb": [[0, 1.01, 7], [1, 1.01, 0]], "batl": NaN}, {"timestamp": 1631547825003, "ltp": 1.85, "tv": 46.2, "trd": NaN, "batb": [[0, 2.06, 28.3], [1, 1.01, 7]], "batl": NaN}, {"timestamp": 1631547828247, "ltp": 1.85, "tv": 46.2, "trd": NaN, "batb": NaN, "batl": [[0, 2.84, 106.47], [1, 2.84, 0]]}, {"timestamp": 1631547844535, "ltp": 1.85, "tv": 46.2, "trd": NaN, "batb": [[0, 1.01, 7], [1, 1.01, 0]], "batl": NaN}, {"timestamp": 1631547849455, "ltp": 1.85, "tv": 46.2, "trd": NaN, "batb": [[0, 2.1, 27.27], [1, 1.01, 7]], "batl": NaN}, {"timestamp": 1631547858469, "ltp": 1.85, "tv": 46.2, "trd": NaN, "batb": [[0, 1.01, 7], [1, 1.01, 0]], "batl": NaN}, {"timestamp": 1631547863352, "ltp": 1.85, "tv": 46.2, "trd": NaN, "batb": [[0, 1.88, 34.09], [1, 1.01, 7]], "batl": NaN}, {"timestamp": 1631547884502, "ltp": 1.85, "tv": 46.2, "trd": NaN, "batb": [[0, 1.01, 7], [1, 1.01, 0]], "batl": NaN}, {"timestamp": 1631547889426, "ltp": 1.85, "tv": 46.2, "trd": NaN, "batb": [[0, 1.85, 35.29], [1, 1.01, 7]], "batl": NaN}, {"timestamp": 1631547920299, "ltp": 1.85, "tv": 46.2, "trd": NaN, "batb": NaN, "batl": [[0, 2.1, 24.21], [1, 2.84, 106.47]]}, {"timestamp": 1631547925490, "ltp": 1.85, "tv": 46.2, "trd": NaN, "batb": [[0, 1.01, 7], [1, 1.01, 0]], "batl": NaN}, {"timestamp": 1631547929154, "ltp": 1.85, "tv": 46.2, "trd": NaN, "batb": [[0, 1.9, 24.21], [1, 1.01, 7]], "batl": NaN}, {"timestamp": 1631547930477, "ltp": 1.85, "tv": 46.2, "trd": NaN, "batb": [[0, 1.71, 42.25]], "batl": NaN}, {"timestamp": 1631547940500, "ltp": 1.85, "tv": 46.2, "trd": NaN, "batb": [[0, 1.8, 24.21], [1, 1.71, 42.25], [2, 1.01, 7]], "batl": NaN}, {"timestamp": 1631547942784, "ltp": 1.85, "tv": 46.2, "trd": NaN, "batb": NaN, "batl": [[0, 2.84, 106.47], [1, 2.84, 0]]}, {"timestamp": 1631547963205, "ltp": 1.85, "tv": 46.2, "trd": NaN, "batb": [[0, 1.71, 42.25], [1, 1.01, 7], [2, 1.01, 0]], "batl": NaN}, {"timestamp": 1631547971539, "ltp": 1.85, "tv": 46.2, "trd": NaN, "batb": [[0, 1.01, 7], [1, 1.01, 0]], "batl": NaN}, {"timestamp": 1631547976450, "ltp": 1.85, "tv": 46.2, "trd": NaN, "batb": [[0, 1.85, 35.29], [1, 1.01, 7]], "batl": NaN}, {"timestamp": 1631548003386, "ltp": 1.85, "tv": 46.2, "trd": NaN, "batb": [[0, 1.01, 7], [1, 1.01, 0]], "batl": NaN}, {"timestamp": 1631548008278, "ltp": 1.85, "tv": 46.2, "trd": NaN, "batb": [[0, 1.65, 46.15], [1, 1.01, 7]], "batl": NaN}, {"timestamp": 1631548014793, "ltp": 1.85, "tv": 46.2, "trd": NaN, "batb": NaN, "batl": [[0, 2, 24.21], [1, 2.84, 106.47]]}, {"timestamp": 1631548036228, "ltp": 1.85, "tv": 46.2, "trd": NaN, "batb": [[0, 1.01, 7], [1, 1.01, 0]], "batl": NaN}, {"timestamp": 1631548041155, "ltp": 1.85, "tv": 46.2, "trd": NaN, "batb": [[0, 1.78, 38.46], [1, 1.01, 7]], "batl": NaN}, {"timestamp": 1631548048156, "ltp": 1.85, "tv": 46.2, "trd": NaN, "batb": NaN, "batl": [[0, 2.84, 106.47], [1, 2.84, 0]]}, {"timestamp": 1631548050458, "ltp": 1.85, "tv": 46.2, "trd": NaN, "batb": [[0, 1.01, 7], [1, 1.01, 0]], "batl": NaN}, {"timestamp": 1631548055359, "ltp": 1.85, "tv": 46.2, "trd": NaN, "batb": [[0, 1.85, 35.29], [1, 1.01, 7]], "batl": NaN}, {"timestamp": 1631548081100, "ltp": 1.85, "tv": 46.2, "trd": NaN, "batb": [[0, 1.01, 7], [1, 1.01, 0]], "batl": NaN}, {"timestamp": 1631548086110, "ltp": 1.85, "tv": 46.2, "trd": NaN, "batb": [[0, 1.73, 41.09], [1, 1.01, 7]], "batl": NaN}, {"timestamp": 1631548123642, "ltp": 1.85, "tv": 46.2, "trd": NaN, "batb": [[0, 1.01, 7], [1, 1.01, 0]], "batl": NaN}, {"timestamp": 1631548128523, "ltp": 1.85, "tv": 46.2, "trd": NaN, "batb": [[0, 1.65, 46.15], [1, 1.01, 7]], "batl": NaN}, {"timestamp": 1631548151561, "ltp": 1.65, "tv": 63.25, "trd": [[1.65, 17.06]], "batb": [[0, 1.01, 7], [1, 1.01, 0]], "batl": NaN}, {"timestamp": 1631548161656, "ltp": 1.65, "tv": 63.25, "trd": NaN, "batb": [[0, 1.78, 38.46], [1, 1.01, 7]], "batl": NaN}, {"timestamp": 1631548182032, "ltp": 1.65, "tv": 63.25, "trd": NaN, "batb": [[0, 1.01, 7], [1, 1.01, 0]], "batl": NaN}, {"timestamp": 1631548187039, "ltp": 1.65, "tv": 63.25, "trd": NaN, "batb": [[0, 1.63, 47.61], [1, 1.01, 7]], "batl": NaN}, {"timestamp": 1631548208473, "ltp": 1.65, "tv": 63.25, "trd": NaN, "batb": [[0, 1.01, 7], [1, 1.01, 0]], "batl": NaN}, {"timestamp": 1631548213474, "ltp": 1.65, "tv": 63.25, "trd": NaN, "batb": [[0, 1.51, 58.82], [1, 1.01, 7]], "batl": NaN}, {"timestamp": 1631548228130, "ltp": 1.65, "tv": 63.25, "trd": NaN, "batb": [[0, 1.01, 7], [1, 1.01, 0]], "batl": NaN}, {"timestamp": 1631548233011, "ltp": 1.65, "tv": 63.25, "trd": NaN, "batb": [[0, 1.63, 47.61], [1, 1.01, 7]], "batl": NaN}, {"timestamp": 1631548243556, "ltp": 1.65, "tv": 63.25, "trd": NaN, "batb": [[0, 1.01, 7], [1, 1.01, 0]], "batl": NaN}, {"timestamp": 1631548248495, "ltp": 1.65, "tv": 63.25, "trd": NaN, "batb": [[0, 1.6, 49.99], [1, 1.01, 7]], "batl": NaN}, {"timestamp": 1631548255496, "ltp": 1.65, "tv": 63.25, "trd": NaN, "batb": [[0, 1.01, 7], [1, 1.01, 0]], "batl": NaN}, {"timestamp": 1631548260376, "ltp": 1.65, "tv": 63.25, "trd": NaN, "batb": [[0, 1.51, 58.82], [1, 1.01, 7]], "batl": NaN}, {"timestamp": 1631548264421, "ltp": 1.65, "tv": 63.25, "trd": NaN, "batb": [[0, 1.61, 160.61], [1, 1.51, 58.82], [2, 1.01, 7]], "batl": NaN}, {"timestamp": 1631548275315, "ltp": 1.65, "tv": 63.25, "trd": NaN, "batb": [[1, 1.01, 7], [2, 1.01, 0]], "batl": NaN}, {"timestamp": 1631548280322, "ltp": 1.65, "tv": 63.25, "trd": NaN, "batb": [[0, 1.63, 47.61], [1, 1.61, 160.61], [2, 1.01, 7]], "batl": NaN}, {"timestamp": 1631548285725, "ltp": 1.65, "tv": 63.25, "trd": NaN, "batb": [[1, 1.01, 7], [2, 1.01, 0]], "batl": NaN}, {"timestamp": 1631548291640, "ltp": 1.65, "tv": 63.25, "trd": NaN, "batb": [[0, 1.7, 160.61], [1, 1.63, 47.61], [2, 1.01, 7]], "batl": NaN}, {"timestamp": 1631548298662, "ltp": 1.65, "tv": 63.25, "trd": NaN, "batb": [[1, 1.01, 7], [2, 1.01, 0]], "batl": NaN}, {"timestamp": 1631548303549, "ltp": 1.65, "tv": 63.25, "trd": NaN, "batb": [[0, 1.71, 42.25], [1, 1.7, 160.61], [2, 1.01, 7]], "batl": NaN}, {"timestamp": 1631548306768, "ltp": 1.65, "tv": 63.25, "trd": NaN, "batb": [[1, 1.01, 7], [2, 1.01, 0]], "batl": NaN}, {"timestamp": 1631548316264, "ltp": 1.65, "tv": 63.25, "trd": NaN, "batb": [[0, 1.01, 7], [1, 1.01, 0]], "batl": NaN}, {"timestamp": 1631548321163, "ltp": 1.65, "tv": 63.25, "trd": NaN, "batb": [[0, 1.6, 49.99], [1, 1.01, 7]], "batl": NaN}, {"timestamp": 1631548333910, "ltp": 1.65, "tv": 63.25, "trd": NaN, "batb": [[0, 1.01, 7], [1, 1.01, 0]], "batl": NaN}, {"timestamp": 1631548338810, "ltp": 1.65, "tv": 63.25, "trd": NaN, "batb": [[0, 1.58, 51.72], [1, 1.01, 7]], "batl": NaN}, {"timestamp": 1631548346401, "ltp": 1.65, "tv": 63.25, "trd": NaN, "batb": [[0, 1.01, 7], [1, 1.01, 0]], "batl": NaN}, {"timestamp": 1631548351728, "ltp": 1.65, "tv": 63.25, "trd": NaN, "batb": [[0, 1.51, 58.82], [1, 1.01, 7]], "batl": NaN}, {"timestamp": 1631548365722, "ltp": 1.65, "tv": 63.25, "trd": NaN, "batb": [[0, 1.01, 7], [1, 1.01, 0]], "batl": NaN}, {"timestamp": 1631548370721, "ltp": 1.65, "tv": 63.25, "trd": NaN, "batb": [[0, 1.48, 62.5], [1, 1.01, 7]], "batl": NaN}, {"timestamp": 1631548381544, "ltp": 1.65, "tv": 63.25, "trd": NaN, "batb": [[0, 1.01, 7], [1, 1.01, 0]], "batl": NaN}, {"timestamp": 1631548383850, "ltp": 1.65, "tv": 63.25, "trd": NaN, "batb": NaN, "batl": [[0, 1.48, 50], [1, 2.84, 106.47]]}, {"timestamp": 1631548395149, "ltp": 1.65, "tv": 63.25, "trd": NaN, "batb": NaN, "batl": [[0, 2.84, 106.47], [1, 2.84, 0]]}, {"timestamp": 1631548398778, "ltp": 1.65, "tv": 63.25, "trd": NaN, "batb": [[0, 1.48, 11.35], [1, 1.01, 7]], "batl": NaN}, {"timestamp": 1631548399191, "ltp": 1.65, "tv": 63.25, "trd": NaN, "batb": [[0, 1.01, 7], [1, 1.01, 0]], "batl": NaN}, {"timestamp": 1631548400857, "ltp": 1.65, "tv": 63.25, "trd": NaN, "batb": [[0, 1.6, 49.99], [1, 1.48, 11.35], [2, 1.01, 7]], "batl": NaN}, {"timestamp": 1631548401268, "ltp": 1.65, "tv": 63.25, "trd": NaN, "batb": [[1, 1.01, 7], [2, 1.01, 0]], "batl": NaN}, {"timestamp": 1631548402883, "ltp": 1.65, "tv": 63.25, "trd": NaN, "batb": [[0, 1.01, 7], [1, 1.01, 0]], "batl": NaN}, {"timestamp": 1631548407884, "ltp": 1.65, "tv": 63.25, "trd": NaN, "batb": [[0, 1.71, 42.25], [1, 1.01, 7]], "batl": NaN}, {"timestamp": 1631548443637, "ltp": 1.65, "tv": 63.25, "trd": NaN, "batb": [[0, 1.01, 7], [1, 1.01, 0]], "batl": NaN}, {"timestamp": 1631548448644, "ltp": 1.65, "tv": 63.25, "trd": NaN, "batb": [[0, 1.78, 38.46], [1, 1.01, 7]], "batl": NaN}, {"timestamp": 1631548543383, "ltp": 1.65, "tv": 63.25, "trd": NaN, "batb": [[0, 1.01, 7], [1, 1.01, 0]], "batl": NaN}, {"timestamp": 1631548548349, "ltp": 1.65, "tv": 63.25, "trd": NaN, "batb": [[0, 1.85, 35.29], [1, 1.01, 7]], "batl": NaN}, {"timestamp": 1631548556493, "ltp": 1.65, "tv": 63.25, "trd": NaN, "batb": [[0, 1.01, 7], [1, 1.01, 0]], "batl": NaN}, {"timestamp": 1631548561407, "ltp": 1.65, "tv": 63.25, "trd": NaN, "batb": [[0, 1.88, 34.09], [1, 1.01, 7]], "batl": NaN}, {"timestamp": 1631548584152, "ltp": 1.65, "tv": 63.25, "trd": NaN, "batb": [[0, 1.01, 7], [1, 1.01, 0]], "batl": NaN}, {"timestamp": 1631548589005, "ltp": 1.65, "tv": 63.25, "trd": NaN, "batb": [[0, 2.1, 27.27], [1, 1.01, 7]], "batl": NaN}, {"timestamp": 1631548619706, "ltp": 1.65, "tv": 63.25, "trd": NaN, "batb": [[0, 1.01, 7], [1, 1.01, 0]], "batl": NaN}, {"timestamp": 1631548624713, "ltp": 1.65, "tv": 63.25, "trd": NaN, "batb": [[0, 1.98, 30.61], [1, 1.01, 7]], "batl": NaN}, {"timestamp": 1631548653236, "ltp": 1.65, "tv": 63.25, "trd": NaN, "batb": [[0, 1.01, 7], [1, 1.01, 0]], "batl": NaN}, {"timestamp": 1631548658556, "ltp": 1.65, "tv": 63.25, "trd": NaN, "batb": [[0, 2.16, 25.86], [1, 1.01, 7]], "batl": NaN}, {"timestamp": 1631548688049, "ltp": 1.65, "tv": 63.25, "trd": NaN, "batb": [[0, 1.01, 7], [1, 1.01, 0]], "batl": NaN}, {"timestamp": 1631548692977, "ltp": 1.65, "tv": 63.25, "trd": NaN, "batb": [[0, 2, 30], [1, 1.01, 7]], "batl": NaN}, {"timestamp": 1631548710484, "ltp": 1.65, "tv": 63.25, "trd": NaN, "batb": [[0, 1.01, 7], [1, 1.01, 0]], "batl": NaN}, {"timestamp": 1631548715378, "ltp": 1.65, "tv": 63.25, "trd": NaN, "batb": [[0, 2.06, 28.3], [1, 1.01, 7]], "batl": NaN}, {"timestamp": 1631548730141, "ltp": 1.65, "tv": 63.25, "trd": NaN, "batb": [[0, 1.01, 7], [1, 1.01, 0]], "batl": NaN}, {"timestamp": 1631548735030, "ltp": 1.65, "tv": 63.25, "trd": NaN, "batb": [[0, 2.26, 23.8], [1, 1.01, 7]], "batl": NaN}, {"timestamp": 1631548792730, "ltp": 1.65, "tv": 63.25, "trd": NaN, "batb": [[0, 1.01, 7], [1, 1.01, 0]], "batl": NaN}, {"timestamp": 1631548797731, "ltp": 1.65, "tv": 63.25, "trd": NaN, "batb": [[0, 2.1, 27.27], [1, 1.01, 7]], "batl": NaN}, {"timestamp": 1631548816360, "ltp": 1.65, "tv": 63.25, "trd": NaN, "batb": [[0, 1.01, 7], [1, 1.01, 0]], "batl": NaN}, {"timestamp": 1631548821381, "ltp": 1.65, "tv": 63.25, "trd": NaN, "batb": [[0, 2.06, 28.3], [1, 1.01, 7]], "batl": NaN}, {"timestamp": 1631548831658, "ltp": 1.65, "tv": 63.25, "trd": NaN, "batb": [[0, 1.01, 7], [1, 1.01, 0]], "batl": NaN}, {"timestamp": 1631548836572, "ltp": 1.65, "tv": 63.25, "trd": NaN, "batb": [[0, 2.26, 23.8], [1, 1.01, 7]], "batl": NaN}, {"timestamp": 1631548871386, "ltp": 1.65, "tv": 63.25, "trd": NaN, "batb": [[0, 1.01, 7], [1, 1.01, 0]], "batl": NaN}, {"timestamp": 1631548876293, "ltp": 1.65, "tv": 63.25, "trd": NaN, "batb": [[0, 2.5, 20], [1, 1.01, 7]], "batl": NaN}, {"timestamp": 1631548894825, "ltp": 2.84, "tv": 65.13, "trd": [[2.84, 1.88]], "batb": NaN, "batl": [[0, 2.84, 104.59]]}, {"timestamp": 1631548897919, "ltp": 2.84, "tv": 65.13, "trd": NaN, "batb": [[0, 1.01, 7], [1, 1.01, 0]], "batl": NaN}, {"timestamp": 1631548902838, "ltp": 2.84, "tv": 65.13, "trd": NaN, "batb": [[0, 2.26, 23.8], [1, 1.01, 7]], "batl": NaN}, {"timestamp": 1631548927854, "ltp": 2.84, "tv": 65.13, "trd": NaN, "batb": [[0, 1.01, 7], [1, 1.01, 0]], "batl": NaN}, {"timestamp": 1631548932854, "ltp": 2.84, "tv": 65.13, "trd": NaN, "batb": [[0, 1.98, 30.61], [1, 1.01, 7]], "batl": NaN}, {"timestamp": 1631548959606, "ltp": 2.84, "tv": 65.13, "trd": NaN, "batb": [[0, 1.01, 7], [1, 1.01, 0]], "batl": NaN}, {"timestamp": 1631548964592, "ltp": 2.84, "tv": 65.13, "trd": NaN, "batb": [[0, 1.71, 42.25], [1, 1.01, 7]], "batl": NaN}, {"timestamp": 1631549067642, "ltp": 2.84, "tv": 65.13, "trd": NaN, "batb": [[0, 1.01, 7], [1, 1.01, 0]], "batl": NaN}, {"timestamp": 1631549072543, "ltp": 2.84, "tv": 65.13, "trd": NaN, "batb": [[0, 1.63, 47.61], [1, 1.01, 7]], "batl": NaN}, {"timestamp": 1631549088588, "ltp": 2.84, "tv": 65.13, "trd": NaN, "batb": [[0, 1.01, 12], [1, 1.01, 0]], "batl": NaN}, {"timestamp": 1631549093593, "ltp": 2.84, "tv": 65.13, "trd": NaN, "batb": [[0, 1.51, 58.82], [1, 1.01, 12]], "batl": NaN}, {"timestamp": 1631549099702, "ltp": 2.84, "tv": 65.13, "trd": NaN, "batb": [[0, 1.61, 160.61], [1, 1.51, 58.82], [2, 1.01, 12]], "batl": NaN}, {"timestamp": 1631549103197, "ltp": 2.84, "tv": 65.13, "trd": NaN, "batb": NaN, "batl": [[0, 1.83, 160.61], [1, 2.84, 104.59]]}, {"timestamp": 1631549121726, "ltp": 2.84, "tv": 65.13, "trd": NaN, "batb": [[1, 1.01, 12], [2, 1.01, 0]], "batl": NaN}, {"timestamp": 1631549123244, "ltp": 2.84, "tv": 65.13, "trd": NaN, "batb": NaN, "batl": [[0, 2.84, 104.59], [1, 2.84, 0]]}, {"timestamp": 1631549126736, "ltp": 2.84, "tv": 65.13, "trd": NaN, "batb": [[1, 1.6, 49.99], [2, 1.01, 12]], "batl": NaN}, {"timestamp": 1631549127149, "ltp": 2.84, "tv": 65.13, "trd": NaN, "batb": [[0, 1.6, 49.99], [1, 1.01, 12], [2, 1.01, 0]], "batl": NaN}, {"timestamp": 1631549132836, "ltp": 2.84, "tv": 65.13, "trd": NaN, "batb": [[0, 1.7, 160.61], [1, 1.6, 49.99], [2, 1.01, 12]], "batl": NaN}, {"timestamp": 1631549179520, "ltp": 2.84, "tv": 65.13, "trd": NaN, "batb": [[1, 1.01, 12], [2, 1.01, 0]], "batl": NaN}, {"timestamp": 1631549184510, "ltp": 2.84, "tv": 65.13, "trd": NaN, "batb": [[1, 1.63, 47.61], [2, 1.01, 12]], "batl": NaN}, {"timestamp": 1631549206074, "ltp": 2.84, "tv": 65.13, "trd": NaN, "batb": [[1, 1.01, 12], [2, 1.01, 0]], "batl": NaN}, {"timestamp": 1631549207332, "ltp": 2.84, "tv": 65.13, "trd": NaN, "batb": [[0, 1.01, 12], [1, 1.01, 0]], "batl": NaN}, {"timestamp": 1631549211082, "ltp": 2.84, "tv": 65.13, "trd": NaN, "batb": [[0, 1.48, 62.5], [1, 1.01, 12]], "batl": NaN}, {"timestamp": 1631549215549, "ltp": 2.84, "tv": 65.13, "trd": NaN, "batb": [[0, 1.57, 160.61], [1, 1.48, 62.5], [2, 1.01, 12]], "batl": NaN}, {"timestamp": 1631549217947, "ltp": 2.84, "tv": 65.13, "trd": NaN, "batb": NaN, "batl": [[0, 1.8, 160.61], [1, 2.84, 104.59]]}, {"timestamp": 1631549238891, "ltp": 2.84, "tv": 65.13, "trd": NaN, "batb": [[1, 1.01, 12], [2, 1.01, 0]], "batl": NaN}, {"timestamp": 1631549240503, "ltp": 2.84, "tv": 65.13, "trd": NaN, "batb": [[0, 1.01, 12], [1, 1.01, 0]], "batl": NaN}, {"timestamp": 1631549243804, "ltp": 2.84, "tv": 65.13, "trd": NaN, "batb": [[0, 1.45, 66.66], [1, 1.01, 12]], "batl": [[0, 2.84, 104.59], [1, 2.84, 0]]}, {"timestamp": 1631549248028, "ltp": 2.84, "tv": 65.13, "trd": NaN, "batb": [[0, 1.5, 160.61], [1, 1.45, 66.66], [2, 1.01, 12]], "batl": NaN}, {"timestamp": 1631549249334, "ltp": 2.84, "tv": 65.13, "trd": NaN, "batb": NaN, "batl": [[0, 1.7, 160.61], [1, 2.84, 104.59]]}, {"timestamp": 1631549289363, "ltp": 2.84, "tv": 65.13, "trd": NaN, "batb": [[1, 1.01, 12], [2, 1.01, 0]], "batl": NaN}, {"timestamp": 1631549294371, "ltp": 2.84, "tv": 65.13, "trd": NaN, "batb": [[1, 1.42, 71.42], [2, 1.01, 12]], "batl": NaN}, {"timestamp": 1631549299705, "ltp": 2.84, "tv": 65.13, "trd": NaN, "batb": [[0, 1.42, 71.42], [1, 1.01, 12], [2, 1.01, 0]], "batl": NaN}, {"timestamp": 1631549306202, "ltp": 2.84, "tv": 65.13, "trd": NaN, "batb": [[0, 1.44, 321.22], [1, 1.42, 71.42], [2, 1.01, 12]], "batl": NaN}, {"timestamp": 1631549307409, "ltp": 2.84, "tv": 65.13, "trd": NaN, "batb": [[1, 1.01, 12], [2, 1.01, 0]], "batl": NaN}, {"timestamp": 1631549312407, "ltp": 2.84, "tv": 65.13, "trd": NaN, "batb": [[1, 1.38, 78.94], [2, 1.01, 12]], "batl": NaN}, {"timestamp": 1631549318407, "ltp": 2.84, "tv": 65.13, "trd": NaN, "batb": [[1, 1.01, 12], [2, 1.01, 0]], "batl": NaN}, {"timestamp": 1631549323346, "ltp": 2.84, "tv": 65.13, "trd": NaN, "batb": [[0, 1.45, 66.66], [1, 1.44, 321.22], [2, 1.01, 12]], "batl": NaN}, {"timestamp": 1631549326327, "ltp": 2.84, "tv": 65.13, "trd": NaN, "batb": [[1, 1.01, 12], [2, 1.01, 0]], "batl": NaN}, {"timestamp": 1631549332465, "ltp": 2.84, "tv": 65.13, "trd": NaN, "batb": [[0, 1.5, 321.22], [1, 1.45, 66.66], [2, 1.01, 12]], "batl": NaN}, {"timestamp": 1631549349019, "ltp": 2.84, "tv": 65.13, "trd": NaN, "batb": [[1, 1.01, 12], [2, 1.01, 0]], "batl": NaN}, {"timestamp": 1631549350637, "ltp": 2.84, "tv": 65.13, "trd": NaN, "batb": [[0, 1.01, 12], [1, 1.01, 0]], "batl": NaN}, {"timestamp": 1631549354040, "ltp": 2.84, "tv": 65.13, "trd": NaN, "batb": [[0, 1.38, 78.94], [1, 1.01, 12]], "batl": NaN}, {"timestamp": 1631549358121, "ltp": 2.84, "tv": 65.13, "trd": NaN, "batb": [[0, 1.44, 321.22], [1, 1.38, 78.94], [2, 1.01, 12]], "batl": NaN}, {"timestamp": 1631549377868, "ltp": 2.84, "tv": 65.13, "trd": NaN, "batb": [[1, 1.01, 12], [2, 1.01, 0]], "batl": NaN}, {"timestamp": 1631549381874, "ltp": 2.84, "tv": 65.13, "trd": NaN, "batb": NaN, "batl": [[0, 2.84, 104.59], [1, 2.84, 0]]}, {"timestamp": 1631549382872, "ltp": 2.84, "tv": 65.13, "trd": NaN, "batb": [[0, 1.45, 66.66], [1, 1.44, 321.22], [2, 1.01, 12]], "batl": NaN}, {"timestamp": 1631549383656, "ltp": 2.84, "tv": 65.13, "trd": NaN, "batb": [[1, 1.01, 12], [2, 1.01, 0]], "batl": NaN}, {"timestamp": 1631549388769, "ltp": 2.84, "tv": 65.13, "trd": NaN, "batb": [[0, 1.5, 160.61], [1, 1.45, 66.66], [2, 1.01, 12]], "batl": NaN}, {"timestamp": 1631549390677, "ltp": 2.84, "tv": 65.13, "trd": NaN, "batb": [[0, 1.45, 66.66], [1, 1.01, 12], [2, 1.01, 0]], "batl": NaN}, {"timestamp": 1631549392085, "ltp": 2.84, "tv": 65.13, "trd": NaN, "batb": NaN, "batl": [[0, 1.7, 160.61], [1, 2.84, 104.59]]}, {"timestamp": 1631549406771, "ltp": 2.84, "tv": 65.13, "trd": NaN, "batb": [[0, 1.5, 321.22], [1, 1.45, 66.66], [2, 1.01, 12]], "batl": NaN}, {"timestamp": 1631549407489, "ltp": 2.84, "tv": 65.13, "trd": NaN, "batb": [[0, 1.45, 66.66], [1, 1.01, 12], [2, 1.01, 0]], "batl": NaN}, {"timestamp": 1631549413581, "ltp": 2.84, "tv": 65.13, "trd": NaN, "batb": [[0, 1.01, 12], [1, 1.01, 0]], "batl": NaN}, {"timestamp": 1631549418587, "ltp": 2.84, "tv": 65.13, "trd": NaN, "batb": [[0, 1.48, 62.5], [1, 1.01, 12]], "batl": NaN}, {"timestamp": 1631549421391, "ltp": 2.84, "tv": 65.13, "trd": NaN, "batb": NaN, "batl": [[0, 2.84, 104.59], [1, 2.84, 0]]}, {"timestamp": 1631549428210, "ltp": 1.67, "tv": 95.07, "trd": [[1.67, 29.94]], "batb": [[0, 1.67, 130.67], [1, 1.48, 62.5], [2, 1.01, 12]], "batl": NaN}, {"timestamp": 1631549435935, "ltp": 1.67, "tv": 95.07, "trd": NaN, "batb": [[0, 1.48, 62.5], [1, 1.01, 12], [2, 1.01, 0]], "batl": NaN}, {"timestamp": 1631549445637, "ltp": 1.67, "tv": 95.07, "trd": NaN, "batb": [[0, 1.01, 12], [1, 1.01, 0]], "batl": NaN}, {"timestamp": 1631549450545, "ltp": 1.67, "tv": 95.07, "trd": NaN, "batb": [[0, 1.45, 66.66], [1, 1.01, 12]], "batl": NaN}, {"timestamp": 1631549484606, "ltp": 1.67, "tv": 95.07, "trd": NaN, "batb": [[0, 1.01, 12], [1, 1.01, 0]], "batl": NaN}, {"timestamp": 1631549489575, "ltp": 1.67, "tv": 95.07, "trd": NaN, "batb": [[0, 1.42, 71.42], [1, 1.01, 12]], "batl": NaN}, {"timestamp": 1631549492717, "ltp": 1.67, "tv": 95.07, "trd": NaN, "batb": [[0, 1.01, 12], [1, 1.01, 0]], "batl": NaN}, {"timestamp": 1631549497635, "ltp": 1.67, "tv": 95.07, "trd": NaN, "batb": [[0, 1.48, 62.5], [1, 1.01, 12]], "batl": NaN}, {"timestamp": 1631549500567, "ltp": 1.67, "tv": 95.07, "trd": NaN, "batb": [[0, 1.65, 160.61], [1, 1.48, 62.5], [2, 1.01, 12]], "batl": NaN}, {"timestamp": 1631549501093, "ltp": 1.67, "tv": 95.07, "trd": NaN, "batb": [[0, 1.48, 62.5], [1, 1.01, 12], [2, 1.01, 0]], "batl": NaN}, {"timestamp": 1631549506660, "ltp": 1.67, "tv": 125.01, "trd": [[1.67, 59.88]], "batb": [[0, 1.67, 130.67], [1, 1.48, 62.5], [2, 1.01, 12]], "batl": NaN}, {"timestamp": 1631549508903, "ltp": 1.67, "tv": 125.01, "trd": NaN, "batb": [[0, 1.48, 62.5], [1, 1.01, 12], [2, 1.01, 0]], "batl": NaN}, {"timestamp": 1631549518718, "ltp": 1.67, "tv": 125.01, "trd": NaN, "batb": [[0, 1.67, 160.61]], "batl": NaN}, {"timestamp": 1631549519607, "ltp": 1.67, "tv": 125.01, "trd": NaN, "batb": [[0, 1.01, 12], [1, 1.01, 0]], "batl": NaN}, {"timestamp": 1631549523631, "ltp": 1.67, "tv": 125.01, "trd": NaN, "batb": [[0, 1.45, 66.66], [1, 1.01, 12]], "batl": NaN}, {"timestamp": 1631549524001, "ltp": 1.67, "tv": 125.01, "trd": NaN, "batb": NaN, "batl": [[0, 1.48, 1.71], [1, 2.84, 104.59]]}, {"timestamp": 1631549530803, "ltp": 1.67, "tv": 125.01, "trd": NaN, "batb": NaN, "batl": [[0, 2.84, 104.59], [1, 2.84, 0]]}, {"timestamp": 1631549536413, "ltp": 1.67, "tv": 125.01, "trd": NaN, "batb": [[0, 1.01, 12], [1, 1.01, 0]], "batl": NaN}, {"timestamp": 1631549538906, "ltp": 1.67, "tv": 125.01, "trd": NaN, "batb": NaN, "batl": [[0, 1.45, 1.71], [1, 2.84, 104.59]]}, {"timestamp": 1631549541459, "ltp": 1.67, "tv": 125.01, "trd": NaN, "batb": [[0, 1.38, 78.94], [1, 1.01, 12]], "batl": NaN}, {"timestamp": 1631549550766, "ltp": 1.67, "tv": 125.01, "trd": NaN, "batb": [[0, 1.4, 160.61], [1, 1.38, 78.94], [2, 1.01, 12]], "batl": NaN}, {"timestamp": 1631549552923, "ltp": 1.67, "tv": 125.01, "trd": NaN, "batb": [[1, 1.01, 12], [2, 1.01, 0]], "batl": NaN}, {"timestamp": 1631549558037, "ltp": 1.67, "tv": 125.01, "trd": NaN, "batb": [[0, 1.01, 12], [1, 1.01, 0]], "batl": NaN}, {"timestamp": 1631549590488, "ltp": 1.67, "tv": 158.37, "trd": [[1.45, 3.42], [1.67, 89.82]], "batb": [[0, 1.67, 68.35], [1, 1.01, 12]], "batl": [[0, 2.84, 104.59], [1, 2.84, 0]]}, {"timestamp": 1631549591689, "ltp": 1.67, "tv": 158.37, "trd": NaN, "batb": [[0, 1.01, 12], [1, 1.01, 0]], "batl": NaN}, {"timestamp": 1631549595446, "ltp": 1.67, "tv": 158.37, "trd": NaN, "batb": [[0, 1.48, 62.5], [1, 1.01, 12]], "batl": NaN}, {"timestamp": 1631549639918, "ltp": 1.67, "tv": 158.37, "trd": NaN, "batb": [[0, 1.01, 12], [1, 1.01, 0]], "batl": NaN}, {"timestamp": 1631549644873, "ltp": 1.67, "tv": 158.37, "trd": NaN, "batb": [[0, 1.45, 66.66], [1, 1.01, 12]], "batl": NaN}, {"timestamp": 1631549666987, "ltp": 1.67, "tv": 158.37, "trd": NaN, "batb": [[0, 1.01, 12], [1, 1.01, 0]], "batl": NaN}, {"timestamp": 1631549671811, "ltp": 1.67, "tv": 158.37, "trd": NaN, "batb": [[0, 1.38, 78.94], [1, 1.01, 12]], "batl": NaN}, {"timestamp": 1631549708638, "ltp": 1.67, "tv": 158.37, "trd": NaN, "batb": [[0, 1.01, 12], [1, 1.01, 0]], "batl": NaN}, {"timestamp": 1631549713543, "ltp": 1.67, "tv": 158.37, "trd": NaN, "batb": [[0, 1.42, 71.42], [1, 1.01, 12]], "batl": NaN}, {"timestamp": 1631549721260, "ltp": 1.67, "tv": 158.37, "trd": NaN, "batb": [[0, 1.01, 12], [1, 1.01, 0]], "batl": NaN}, {"timestamp": 1631549726307, "ltp": 1.67, "tv": 158.37, "trd": NaN, "batb": [[0, 1.38, 78.94], [1, 1.01, 12]], "batl": NaN}, {"timestamp": 1631549744803, "ltp": 1.67, "tv": 158.37, "trd": NaN, "batb": [[0, 1.01, 12], [1, 1.01, 0]], "batl": NaN}, {"timestamp": 1631549749708, "ltp": 1.67, "tv": 158.37, "trd": NaN, "batb": [[0, 1.31, 96.77], [1, 1.01, 12]], "batl": NaN}, {"timestamp": 1631549767331, "ltp": 1.67, "tv": 158.37, "trd": NaN, "batb": [[0, 1.32, 100], [1, 1.31, 96.77], [2, 1.01, 12]], "batl": NaN}, {"timestamp": 1631549769636, "ltp": 1.67, "tv": 158.37, "trd": NaN, "batb": NaN, "batl": [[0, 1.46, 50], [1, 2.84, 104.59]]}, {"timestamp": 1631549771365, "ltp": 1.67, "tv": 158.37, "trd": NaN, "batb": NaN, "batl": [[0, 1.46, 150]]}, {"timestamp": 1631549772154, "ltp": 1.67, "tv": 158.37, "trd": NaN, "batb": NaN, "batl": [[0, 1.46, 200]]}, {"timestamp": 1631549840551, "ltp": 1.67, "tv": 158.37, "trd": NaN, "batb": [[0, 1.31, 96.77], [1, 1.01, 12], [2, 1.01, 0]], "batl": [[0, 2.84, 104.59], [1, 2.84, 0]]}, {"timestamp": 1631550165998, "ltp": 1.67, "tv": 158.37, "trd": NaN, "batb": [[0, 1.01, 12], [1, 1.01, 0]], "batl": NaN}, {"timestamp": 1631550171006, "ltp": 1.67, "tv": 158.37, "trd": NaN, "batb": [[0, 1.27, 111.11], [1, 1.01, 12]], "batl": NaN}, {"timestamp": 1631550195191, "ltp": 1.67, "tv": 158.37, "trd": NaN, "batb": [[0, 1.01, 12], [1, 1.01, 0]], "batl": NaN}, {"timestamp": 1631550200204, "ltp": 1.67, "tv": 158.37, "trd": NaN, "batb": [[0, 1.34, 88.23], [1, 1.01, 12]], "batl": NaN}, {"timestamp": 1631550218414, "ltp": 1.34, "tv": 166.33, "trd": [[1.34, 7.96]], "batb": [[0, 1.01, 12], [1, 1.01, 0]], "batl": NaN}, {"timestamp": 1631550223452, "ltp": 1.34, "tv": 166.33, "trd": NaN, "batb": [[0, 1.34, 88.23], [1, 1.01, 12]], "batl": NaN}, {"timestamp": 1631550230333, "ltp": 1.34, "tv": 166.33, "trd": NaN, "batb": [[0, 1.01, 12], [1, 1.01, 0]], "batl": NaN}, {"timestamp": 1631550235268, "ltp": 1.34, "tv": 166.33, "trd": NaN, "batb": [[0, 1.27, 111.11], [1, 1.01, 12]], "batl": NaN}, {"timestamp": 1631550256875, "ltp": 1.34, "tv": 166.33, "trd": NaN, "batb": [[0, 1.01, 12], [1, 1.01, 0]], "batl": NaN}, {"timestamp": 1631550261786, "ltp": 1.34, "tv": 166.33, "trd": NaN, "batb": [[0, 1.34, 88.23], [1, 1.01, 12]], "batl": NaN}, {"timestamp": 1631550282030, "ltp": 1.34, "tv": 166.33, "trd": NaN, "batb": [[0, 1.01, 12], [1, 1.01, 0]], "batl": NaN}, {"timestamp": 1631550286941, "ltp": 1.34, "tv": 166.33, "trd": NaN, "batb": [[0, 1.27, 111.11], [1, 1.01, 12]], "batl": NaN}, {"timestamp": 1631550326917, "ltp": 1.34, "tv": 166.33, "trd": NaN, "batb": [[0, 1.01, 12], [1, 1.01, 0]], "batl": NaN}, {"timestamp": 1631550331822, "ltp": 1.34, "tv": 166.33, "trd": NaN, "batb": [[0, 1.18, 166.66], [1, 1.01, 12]], "batl": NaN}, {"timestamp": 1631550383205, "ltp": 1.34, "tv": 166.33, "trd": NaN, "batb": [[0, 1.01, 12], [1, 1.01, 0]], "batl": NaN}, {"timestamp": 1631550388121, "ltp": 1.34, "tv": 166.33, "trd": NaN, "batb": [[0, 1.23, 130.43], [1, 1.01, 12]], "batl": NaN}, {"timestamp": 1631550426145, "ltp": 1.34, "tv": 166.33, "trd": NaN, "batb": [[0, 1.01, 12], [1, 1.01, 0]], "batl": NaN}, {"timestamp": 1631550431177, "ltp": 1.34, "tv": 166.33, "trd": NaN, "batb": [[0, 1.28, 107.14], [1, 1.01, 12]], "batl": NaN}, {"timestamp": 1631550447989, "ltp": 1.34, "tv": 166.33, "trd": NaN, "batb": [[0, 1.01, 12], [1, 1.01, 0]], "batl": NaN}, {"timestamp": 1631550452983, "ltp": 1.34, "tv": 166.33, "trd": NaN, "batb": [[0, 1.34, 88.23], [1, 1.01, 12]], "batl": NaN}, {"timestamp": 1631550505851, "ltp": 1.34, "tv": 166.33, "trd": NaN, "batb": [[0, 1.01, 12], [1, 1.01, 0]], "batl": NaN}, {"timestamp": 1631550510744, "ltp": 1.34, "tv": 166.33, "trd": NaN, "batb": [[0, 1.28, 107.14], [1, 1.01, 12]], "batl": NaN}, {"timestamp": 1631550534572, "ltp": 1.34, "tv": 166.33, "trd": NaN, "batb": [[0, 1.01, 12], [1, 1.01, 0]], "batl": NaN}, {"timestamp": 1631550539569, "ltp": 1.34, "tv": 166.33, "trd": NaN, "batb": [[0, 1.38, 78.94], [1, 1.01, 12]], "batl": NaN}, {"timestamp": 1631550570235, "ltp": 1.34, "tv": 166.33, "trd": NaN, "batb": [[0, 1.01, 12], [1, 1.01, 0]], "batl": NaN}, {"timestamp": 1631550575144, "ltp": 1.34, "tv": 166.33, "trd": NaN, "batb": [[0, 1.45, 66.66], [1, 1.01, 12]], "batl": NaN}, {"timestamp": 1631550641527, "ltp": 1.34, "tv": 166.33, "trd": NaN, "batb": [[0, 1.01, 12], [1, 1.01, 0]], "batl": NaN}, {"timestamp": 1631550646461, "ltp": 1.34, "tv": 166.33, "trd": NaN, "batb": [[0, 1.51, 58.82], [1, 1.01, 12]], "batl": NaN}, {"timestamp": 1631550704934, "ltp": 1.34, "tv": 166.33, "trd": NaN, "batb": [[0, 1.01, 12], [1, 1.01, 0]], "batl": NaN}, {"timestamp": 1631550709868, "ltp": 1.34, "tv": 166.33, "trd": NaN, "batb": [[0, 1.6, 49.99], [1, 1.01, 12]], "batl": NaN}, {"timestamp": 1631550805456, "ltp": 1.34, "tv": 166.33, "trd": NaN, "batb": [[0, 1.01, 12], [1, 1.01, 0]], "batl": NaN}, {"timestamp": 1631550810413, "ltp": 1.34, "tv": 166.33, "trd": NaN, "batb": [[0, 1.51, 58.82], [1, 1.01, 12]], "batl": NaN}, {"timestamp": 1631550828444, "ltp": 1.34, "tv": 166.33, "trd": NaN, "batb": [[0, 1.01, 12], [1, 1.01, 0]], "batl": NaN}, {"timestamp": 1631550833339, "ltp": 1.34, "tv": 166.33, "trd": NaN, "batb": [[0, 1.48, 62.5], [1, 1.01, 12]], "batl": NaN}, {"timestamp": 1631550850336, "ltp": 1.34, "tv": 166.33, "trd": NaN, "batb": [[0, 1.01, 12], [1, 1.01, 0]], "batl": NaN}, {"timestamp": 1631550855277, "ltp": 1.34, "tv": 166.33, "trd": NaN, "batb": [[0, 1.6, 49.99], [1, 1.01, 12]], "batl": NaN}, {"timestamp": 1631550872190, "ltp": 1.34, "tv": 166.33, "trd": NaN, "batb": [[0, 1.01, 12], [1, 1.01, 0]], "batl": NaN}, {"timestamp": 1631550877203, "ltp": 1.34, "tv": 166.33, "trd": NaN, "batb": [[0, 1.71, 42.25], [1, 1.01, 12]], "batl": NaN}, {"timestamp": 1631550894821, "ltp": 1.34, "tv": 166.33, "trd": NaN, "batb": [[0, 1.01, 12], [1, 1.01, 0]], "batl": NaN}, {"timestamp": 1631550899824, "ltp": 1.34, "tv": 166.33, "trd": NaN, "batb": [[0, 1.78, 38.46], [1, 1.01, 12]], "batl": NaN}, {"timestamp": 1631550910601, "ltp": 1.34, "tv": 166.33, "trd": NaN, "batb": [[0, 1.01, 12], [1, 1.01, 0]], "batl": NaN}, {"timestamp": 1631550915544, "ltp": 1.34, "tv": 166.33, "trd": NaN, "batb": [[0, 1.73, 41.09], [1, 1.01, 12]], "batl": NaN}, {"timestamp": 1631550929249, "ltp": 1.34, "tv": 166.33, "trd": NaN, "batb": [[0, 1.01, 12], [1, 1.01, 0]], "batl": NaN}, {"timestamp": 1631550934242, "ltp": 1.34, "tv": 166.33, "trd": NaN, "batb": [[0, 1.71, 42.25], [1, 1.01, 12]], "batl": NaN}, {"timestamp": 1631550957368, "ltp": 1.34, "tv": 166.33, "trd": NaN, "batb": [[0, 1.01, 12], [1, 1.01, 0]], "batl": NaN}, {"timestamp": 1631550962391, "ltp": 1.34, "tv": 166.33, "trd": NaN, "batb": [[0, 1.78, 38.46], [1, 1.01, 12]], "batl": NaN}, {"timestamp": 1631550998730, "ltp": 1.34, "tv": 166.33, "trd": NaN, "batb": [[0, 1.01, 12], [1, 1.01, 0]], "batl": NaN}, {"timestamp": 1631551003719, "ltp": 1.34, "tv": 166.33, "trd": NaN, "batb": [[0, 1.88, 34.09], [1, 1.01, 12]], "batl": NaN}, {"timestamp": 1631551029878, "ltp": 1.34, "tv": 166.33, "trd": NaN, "batb": [[0, 1.01, 12], [1, 1.01, 0]], "batl": NaN}, {"timestamp": 1631551034756, "ltp": 1.34, "tv": 166.33, "trd": NaN, "batb": [[0, 2, 30], [1, 1.01, 12]], "batl": NaN}, {"timestamp": 1631551056890, "ltp": 1.34, "tv": 166.33, "trd": NaN, "batb": [[0, 1.01, 12], [1, 1.01, 0]], "batl": NaN}, {"timestamp": 1631551061783, "ltp": 1.34, "tv": 166.33, "trd": NaN, "batb": [[0, 1.88, 34.09], [1, 1.01, 12]], "batl": NaN}, {"timestamp": 1631551095189, "ltp": 1.34, "tv": 166.33, "trd": NaN, "batb": [[0, 1.01, 12], [1, 1.01, 0]], "batl": NaN}, {"timestamp": 1631551100112, "ltp": 1.34, "tv": 166.33, "trd": NaN, "batb": [[0, 1.98, 30.61], [1, 1.01, 12]], "batl": NaN}, {"timestamp": 1631551109412, "ltp": 1.34, "tv": 166.33, "trd": NaN, "batb": [[0, 1.01, 12], [1, 1.01, 0]], "batl": NaN}, {"timestamp": 1631551114335, "ltp": 1.34, "tv": 166.33, "trd": NaN, "batb": [[0, 1.85, 35.29], [1, 1.01, 12]], "batl": NaN}, {"timestamp": 1631551139964, "ltp": 1.34, "tv": 166.33, "trd": NaN, "batb": [[0, 1.01, 12], [1, 1.01, 0]], "batl": NaN}, {"timestamp": 1631551144970, "ltp": 1.34, "tv": 166.33, "trd": NaN, "batb": [[0, 1.98, 30.61], [1, 1.01, 12]], "batl": NaN}, {"timestamp": 1631551186717, "ltp": 1.34, "tv": 166.33, "trd": NaN, "batb": [[0, 1.01, 12], [1, 1.01, 0]], "batl": NaN}, {"timestamp": 1631551191719, "ltp": 1.34, "tv": 166.33, "trd": NaN, "batb": [[0, 1.85, 35.29], [1, 1.01, 12]], "batl": NaN}, {"timestamp": 1631551231649, "ltp": 1.34, "tv": 166.33, "trd": NaN, "batb": [[0, 1.01, 12], [1, 1.01, 0]], "batl": NaN}, {"timestamp": 1631551236661, "ltp": 1.34, "tv": 166.33, "trd": NaN, "batb": [[0, 1.71, 42.25], [1, 1.01, 12]], "batl": NaN}, {"timestamp": 1631551288126, "ltp": 1.34, "tv": 166.33, "trd": NaN, "batb": [[0, 1.01, 12], [1, 1.01, 0]], "batl": NaN}, {"timestamp": 1631551293150, "ltp": 1.34, "tv": 166.33, "trd": NaN, "batb": [[0, 1.6, 49.99], [1, 1.01, 12]], "batl": NaN}, {"timestamp": 1631551388712, "ltp": 1.34, "tv": 166.33, "trd": NaN, "batb": [[0, 1.01, 12], [1, 1.01, 0]], "batl": NaN}, {"timestamp": 1631551393741, "ltp": 1.34, "tv": 166.33, "trd": NaN, "batb": [[0, 1.51, 58.82], [1, 1.01, 12]], "batl": NaN}, {"timestamp": 1631551406442, "ltp": 1.34, "tv": 166.33, "trd": NaN, "batb": [[0, 1.01, 12], [1, 1.01, 0]], "batl": NaN}, {"timestamp": 1631551411333, "ltp": 1.34, "tv": 166.33, "trd": NaN, "batb": [[0, 1.6, 49.99], [1, 1.01, 12]], "batl": NaN}, {"timestamp": 1631551426457, "ltp": 1.34, "tv": 166.33, "trd": NaN, "batb": [[0, 1.01, 12], [1, 1.01, 0]], "batl": NaN}, {"timestamp": 1631551431477, "ltp": 1.34, "tv": 166.33, "trd": NaN, "batb": [[0, 1.48, 62.5], [1, 1.01, 12]], "batl": NaN}, {"timestamp": 1631551473093, "ltp": 1.34, "tv": 166.33, "trd": NaN, "batb": [[0, 1.01, 12], [1, 1.01, 0]], "batl": NaN}, {"timestamp": 1631551477988, "ltp": 1.34, "tv": 166.33, "trd": NaN, "batb": [[0, 1.58, 51.72], [1, 1.01, 12]], "batl": NaN}, {"timestamp": 1631551491626, "ltp": 1.34, "tv": 166.33, "trd": NaN, "batb": [[0, 1.01, 12], [1, 1.01, 0]], "batl": NaN}, {"timestamp": 1631551496531, "ltp": 1.34, "tv": 166.33, "trd": NaN, "batb": [[0, 1.71, 42.25], [1, 1.01, 12]], "batl": NaN}, {"timestamp": 1631551509645, "ltp": 1.34, "tv": 166.33, "trd": NaN, "batb": [[0, 1.01, 12], [1, 1.01, 0]], "batl": NaN}, {"timestamp": 1631551514647, "ltp": 1.34, "tv": 166.33, "trd": NaN, "batb": [[0, 1.85, 35.29], [1, 1.01, 12]], "batl": NaN}, {"timestamp": 1631551536868, "ltp": 1.34, "tv": 166.33, "trd": NaN, "batb": [[0, 1.01, 12], [1, 1.01, 0]], "batl": NaN}, {"timestamp": 1631551541934, "ltp": 1.34, "tv": 166.33, "trd": NaN, "batb": [[0, 1.73, 41.09], [1, 1.01, 12]], "batl": NaN}, {"timestamp": 1631551562430, "ltp": 1.34, "tv": 166.33, "trd": NaN, "batb": [[0, 1.01, 12], [1, 1.01, 0]], "batl": NaN}, {"timestamp": 1631551567360, "ltp": 1.34, "tv": 166.33, "trd": NaN, "batb": [[0, 1.71, 42.25], [1, 1.01, 12]], "batl": NaN}, {"timestamp": 1631551606010, "ltp": 1.34, "tv": 166.33, "trd": NaN, "batb": [[0, 1.01, 12], [1, 1.01, 0]], "batl": NaN}, {"timestamp": 1631551610917, "ltp": 1.34, "tv": 166.33, "trd": NaN, "batb": [[0, 1.78, 38.46], [1, 1.01, 12]], "batl": NaN}, {"timestamp": 1631551646944, "ltp": 1.34, "tv": 166.33, "trd": NaN, "batb": [[0, 1.01, 12], [1, 1.01, 0]], "batl": NaN}, {"timestamp": 1631551651972, "ltp": 1.34, "tv": 166.33, "trd": NaN, "batb": [[0, 1.71, 42.25], [1, 1.01, 12]], "batl": NaN}, {"timestamp": 1631551689111, "ltp": 1.34, "tv": 166.33, "trd": NaN, "batb": [[0, 1.01, 12], [1, 1.01, 0]], "batl": NaN}, {"timestamp": 1631551694121, "ltp": 1.34, "tv": 166.33, "trd": NaN, "batb": [[0, 1.73, 41.09], [1, 1.01, 12]], "batl": NaN}, {"timestamp": 1631551720987, "ltp": 1.34, "tv": 166.33, "trd": NaN, "batb": [[0, 1.01, 12], [1, 1.01, 0]], "batl": NaN}, {"timestamp": 1631551725895, "ltp": 1.34, "tv": 166.33, "trd": NaN, "batb": [[0, 1.65, 46.15], [1, 1.01, 12]], "batl": NaN}, {"timestamp": 1631551810226, "ltp": 1.34, "tv": 166.33, "trd": NaN, "batb": [[0, 1.01, 12], [1, 1.01, 0]], "batl": NaN}, {"timestamp": 1631551815110, "ltp": 1.34, "tv": 166.33, "trd": NaN, "batb": [[0, 1.78, 38.46], [1, 1.01, 12]], "batl": NaN}, {"timestamp": 1631551842183, "ltp": 1.34, "tv": 166.33, "trd": NaN, "batb": [[0, 1.01, 12], [1, 1.01, 0]], "batl": NaN}, {"timestamp": 1631551847120, "ltp": 1.34, "tv": 166.33, "trd": NaN, "batb": [[0, 1.88, 34.09], [1, 1.01, 12]], "batl": NaN}, {"timestamp": 1631551863662, "ltp": 1.34, "tv": 166.33, "trd": NaN, "batb": [[0, 1.01, 12], [1, 1.01, 0]], "batl": NaN}, {"timestamp": 1631551868559, "ltp": 1.34, "tv": 166.33, "trd": NaN, "batb": [[0, 1.98, 30.61], [1, 1.01, 12]], "batl": NaN}, {"timestamp": 1631551904302, "ltp": 1.34, "tv": 166.33, "trd": NaN, "batb": [[0, 1.01, 12], [1, 1.01, 0]], "batl": NaN}, {"timestamp": 1631551909312, "ltp": 1.34, "tv": 166.33, "trd": NaN, "batb": [[0, 2, 30], [1, 1.01, 12]], "batl": NaN}, {"timestamp": 1631551938041, "ltp": 1.34, "tv": 166.33, "trd": NaN, "batb": [[0, 1.01, 12], [1, 1.01, 0]], "batl": NaN}, {"timestamp": 1631551943020, "ltp": 1.34, "tv": 166.33, "trd": NaN, "batb": [[0, 1.88, 34.09], [1, 1.01, 12]], "batl": NaN}, {"timestamp": 1631551986371, "ltp": 1.34, "tv": 166.33, "trd": NaN, "batb": [[0, 1.01, 12], [1, 1.01, 0]], "batl": NaN}, {"timestamp": 1631551991382, "ltp": 1.34, "tv": 166.33, "trd": NaN, "batb": [[0, 1.85, 35.29], [1, 1.01, 12]], "batl": NaN}, {"timestamp": 1631552033458, "ltp": 1.34, "tv": 166.33, "trd": NaN, "batb": [[0, 1.01, 12], [1, 1.01, 0]], "batl": NaN}, {"timestamp": 1631552038475, "ltp": 1.34, "tv": 166.33, "trd": NaN, "batb": [[0, 1.78, 38.46], [1, 1.01, 12]], "batl": NaN}, {"timestamp": 1631552125456, "ltp": 1.34, "tv": 166.33, "trd": NaN, "batb": [[0, 1.01, 12], [1, 1.01, 0]], "batl": NaN}, {"timestamp": 1631552130370, "ltp": 1.34, "tv": 166.33, "trd": NaN, "batb": [[0, 1.88, 34.09], [1, 1.01, 12]], "batl": NaN}, {"timestamp": 1631552146784, "ltp": 1.34, "tv": 166.33, "trd": NaN, "batb": [[0, 1.01, 12], [1, 1.01, 0]], "batl": NaN}, {"timestamp": 1631552151679, "ltp": 1.34, "tv": 166.33, "trd": NaN, "batb": [[0, 2.06, 28.3], [1, 1.01, 12]], "batl": NaN}, {"timestamp": 1631552160000, "ltp": 1.34, "tv": 166.33, "trd": NaN, "batb": [[0, 1.01, 12], [1, 1.01, 0]], "batl": NaN}, {"timestamp": 1631552165002, "ltp": 1.34, "tv": 166.33, "trd": NaN, "batb": [[0, 2, 30], [1, 1.01, 12]], "batl": NaN}, {"timestamp": 1631552170902, "ltp": 1.34, "tv": 166.33, "trd": NaN, "batb": [[0, 1.01, 12], [1, 1.01, 0]], "batl": NaN}, {"timestamp": 1631552175895, "ltp": 1.34, "tv": 166.33, "trd": NaN, "batb": [[0, 2.06, 28.3], [1, 1.01, 12]], "batl": NaN}, {"timestamp": 1631552199697, "ltp": 1.34, "tv": 166.33, "trd": NaN, "batb": [[0, 1.01, 12], [1, 1.01, 0]], "batl": NaN}, {"timestamp": 1631552204704, "ltp": 1.34, "tv": 166.33, "trd": NaN, "batb": [[0, 2, 30], [1, 1.01, 12]], "batl": NaN}, {"timestamp": 1631552227722, "ltp": 1.34, "tv": 166.33, "trd": NaN, "batb": [[0, 1.01, 12], [1, 1.01, 0]], "batl": NaN}, {"timestamp": 1631552232606, "ltp": 1.34, "tv": 166.33, "trd": NaN, "batb": [[0, 2.1, 27.27], [1, 1.01, 12]], "batl": NaN}, {"timestamp": 1631552300760, "ltp": 2.1, "tv": 220.86, "trd": [[2.1, 54.53]], "batb": [[0, 1.01, 12], [1, 1.01, 0]], "batl": [[0, 2.1, 58.01], [1, 2.84, 104.59]]}, {"timestamp": 1631552303510, "ltp": 2.1, "tv": 220.86, "trd": NaN, "batb": NaN, "batl": [[0, 2.84, 104.59], [1, 2.84, 0]]}, {"timestamp": 1631552305922, "ltp": 2.1, "tv": 220.86, "trd": NaN, "batb": [[0, 1.98, 30.61], [1, 1.01, 12]], "batl": NaN}, {"timestamp": 1631552323569, "ltp": 2.1, "tv": 220.86, "trd": NaN, "batb": [[0, 1.01, 12], [1, 1.01, 0]], "batl": NaN}, {"timestamp": 1631552328461, "ltp": 2.1, "tv": 220.86, "trd": NaN, "batb": [[0, 2.26, 23.8], [1, 1.01, 12]], "batl": NaN}, {"timestamp": 1631552343585, "ltp": 2.1, "tv": 220.86, "trd": NaN, "batb": [[0, 1.01, 12], [1, 1.01, 0]], "batl": NaN}, {"timestamp": 1631552348468, "ltp": 2.1, "tv": 220.86, "trd": NaN, "batb": [[0, 2.16, 25.86], [1, 1.01, 12]], "batl": NaN}, {"timestamp": 1631552352966, "ltp": 2.1, "tv": 220.86, "trd": NaN, "batb": [[0, 1.01, 12], [1, 1.01, 0]], "batl": NaN}, {"timestamp": 1631552357984, "ltp": 2.1, "tv": 220.86, "trd": NaN, "batb": [[0, 2.1, 27.27], [1, 1.01, 12]], "batl": NaN}, {"timestamp": 1631552361711, "ltp": 2.1, "tv": 220.86, "trd": NaN, "batb": [[0, 1.01, 12], [1, 1.01, 0]], "batl": NaN}, {"timestamp": 1631552366696, "ltp": 2.1, "tv": 220.86, "trd": NaN, "batb": [[0, 1.71, 42.25], [1, 1.01, 12]], "batl": NaN}, {"timestamp": 1631552384246, "ltp": 2.1, "tv": 220.86, "trd": NaN, "batb": [[0, 1.01, 12], [1, 1.01, 0]], "batl": NaN}, {"timestamp": 1631552389115, "ltp": 2.1, "tv": 220.86, "trd": NaN, "batb": [[0, 1.65, 46.15], [1, 1.01, 12]], "batl": NaN}, {"timestamp": 1631552398931, "ltp": 2.1, "tv": 220.86, "trd": NaN, "batb": [[0, 1.01, 12], [1, 1.01, 0]], "batl": NaN}, {"timestamp": 1631552403901, "ltp": 2.1, "tv": 220.91, "trd": [[1.34, 7.96], [1.45, 3.42], [1.65, 17.06], [1.73, 31.78], [1.85, 14.45], [2.1, 54.55]], "batb": [[0, 2, 30], [1, 1.01, 12]], "batl": [[0, 2.84, 104.58]]}, {"timestamp": 1631552420401, "ltp": 2.1, "tv": 220.91, "trd": NaN, "batb": [[0, 1.01, 12], [1, 1.01, 0]], "batl": NaN}, {"timestamp": 1631552425404, "ltp": 2.1, "tv": 220.91, "trd": NaN, "batb": [[0, 2.5, 20], [1, 1.01, 12]], "batl": NaN}, {"timestamp": 1631552456566, "ltp": 2.1, "tv": 220.91, "trd": NaN, "batb": [[0, 1.01, 12], [1, 1.01, 0]], "batl": NaN}, {"timestamp": 1631552461564, "ltp": 2.1, "tv": 220.91, "trd": NaN, "batb": [[0, 1.98, 30.61], [1, 1.01, 12]], "batl": NaN}, {"timestamp": 1631552484816, "ltp": 2.1, "tv": 220.91, "trd": NaN, "batb": [[0, 1.01, 12], [1, 1.01, 0]], "batl": NaN}, {"timestamp": 1631552489700, "ltp": 2.1, "tv": 220.91, "trd": NaN, "batb": [[0, 1.65, 46.15], [1, 1.01, 12]], "batl": NaN}, {"timestamp": 1631552508430, "ltp": 2.1, "tv": 220.91, "trd": NaN, "batb": [[0, 1.01, 12], [1, 1.01, 0]], "batl": NaN}, {"timestamp": 1631552513432, "ltp": 2.1, "tv": 220.91, "trd": NaN, "batb": [[0, 1.38, 78.94], [1, 1.01, 12]], "batl": NaN}, {"timestamp": 1631552561581, "ltp": 2.1, "tv": 220.91, "trd": NaN, "batb": [[0, 1.01, 12], [1, 1.01, 0]], "batl": NaN}, {"timestamp": 1631552566581, "ltp": 2.1, "tv": 220.91, "trd": NaN, "batb": [[0, 1.31, 96.77], [1, 1.01, 12]], "batl": NaN}, {"timestamp": 1631552578880, "ltp": 2.1, "tv": 220.91, "trd": NaN, "batb": [[0, 1.01, 12], [1, 1.01, 0]], "batl": NaN}, {"timestamp": 1631552583797, "ltp": 2.1, "tv": 220.91, "trd": NaN, "batb": [[0, 1.18, 166.66], [1, 1.01, 12]], "batl": NaN}, {"timestamp": 1631552605590, "ltp": 1.18, "tv": 509.99, "trd": [[1.18, 289.08]], "batb": [[0, 1.01, 12], [1, 1.01, 0]], "batl": NaN}, {"timestamp": 1631552610472, "ltp": 1.18, "tv": 509.99, "trd": NaN, "batb": [[0, 1.11, 272.72], [1, 1.01, 12]], "batl": NaN}, {"timestamp": 1631552631151, "ltp": 1.18, "tv": 509.99, "trd": NaN, "batb": [[0, 1.01, 12], [1, 1.01, 0]], "batl": NaN}, {"timestamp": 1631552636090, "ltp": 1.18, "tv": 509.99, "trd": NaN, "batb": [[0, 1.31, 96.77], [1, 1.01, 12]], "batl": NaN}, {"timestamp": 1631552658329, "ltp": 1.18, "tv": 509.99, "trd": NaN, "batb": [[0, 1.01, 12], [1, 1.01, 0]], "batl": NaN}, {"timestamp": 1631552663341, "ltp": 1.18, "tv": 509.99, "trd": NaN, "batb": [[0, 1.6, 49.99], [1, 1.01, 12]], "batl": NaN}, {"timestamp": 1631552684494, "ltp": 1.18, "tv": 509.99, "trd": NaN, "batb": [[0, 1.01, 12], [1, 1.01, 0]], "batl": NaN}, {"timestamp": 1631552689520, "ltp": 1.18, "tv": 509.99, "trd": NaN, "batb": [[0, 1.28, 107.14], [1, 1.01, 12]], "batl": NaN}, {"timestamp": 1631552699524, "ltp": 1.18, "tv": 509.99, "trd": NaN, "batb": [[0, 1.01, 12], [1, 1.01, 0]], "batl": NaN}, {"timestamp": 1631552704356, "ltp": 1.18, "tv": 509.99, "trd": NaN, "batb": [[0, 1.27, 111.11], [1, 1.01, 12]], "batl": NaN}, {"timestamp": 1631552717879, "ltp": 1.18, "tv": 509.99, "trd": NaN, "batb": [[0, 1.01, 12], [1, 1.01, 0]], "batl": NaN}, {"timestamp": 1631552722882, "ltp": 1.18, "tv": 509.99, "trd": NaN, "batb": [[0, 1.48, 62.5], [1, 1.01, 12]], "batl": NaN}, {"timestamp": 1631552728556, "ltp": 1.48, "tv": 634.99, "trd": [[1.48, 125]], "batb": [[0, 1.01, 12], [1, 1.01, 0]], "batl": NaN}, {"timestamp": 1631552733498, "ltp": 1.48, "tv": 634.99, "trd": NaN, "batb": [[0, 1.41, 73.17], [1, 1.01, 12]], "batl": NaN}, {"timestamp": 1631552751090, "ltp": 1.48, "tv": 634.99, "trd": NaN, "batb": [[0, 1.01, 12], [1, 1.01, 0]], "batl": NaN}, {"timestamp": 1631552755994, "ltp": 1.48, "tv": 634.99, "trd": NaN, "batb": [[0, 1.23, 130.43], [1, 1.01, 12]], "batl": NaN}, {"timestamp": 1631552800236, "ltp": 1.48, "tv": 634.99, "trd": NaN, "batb": [[0, 1.01, 12], [1, 1.01, 0]], "batl": NaN}, {"timestamp": 1631552805281, "ltp": 1.48, "tv": 634.99, "trd": NaN, "batb": [[0, 1.08, 374.99], [1, 1.01, 12]], "batl": NaN}, {"timestamp": 1631552817073, "ltp": 1.48, "tv": 634.99, "trd": NaN, "batb": [[0, 1.01, 12], [1, 1.01, 0]], "batl": NaN}, {"timestamp": 1631552821997, "ltp": 1.48, "tv": 634.99, "trd": NaN, "batb": [[0, 1.18, 166.66], [1, 1.01, 12]], "batl": NaN}, {"timestamp": 1631552834124, "ltp": 1.48, "tv": 634.99, "trd": NaN, "batb": [[0, 1.01, 12], [1, 1.01, 0]], "batl": NaN}, {"timestamp": 1631552839097, "ltp": 1.48, "tv": 634.99, "trd": NaN, "batb": [[0, 1.15, 200], [1, 1.01, 12]], "batl": NaN}, {"timestamp": 1631552858568, "ltp": 1.48, "tv": 634.99, "trd": NaN, "batb": [[0, 1.01, 12], [1, 1.01, 0]], "batl": NaN}]}]}