{"info": {"id": "1.187552454", "eventId": "30895321", "eventName": "Match Odds", "marketType": "MATCH_ODDS", "openDate": 1631446611418, "name": "Ma Sherif v Trevisan", "numberOfActiveRunner": 2, "countryCode": "", "sport": "TENNIS", "venue": "", "volume": {"total": 124424.14, "preMatch": 580.48, "inPlay": 123843.66}, "winner": {"id": 9028621, "name": "Mayar Sherif", "status": "WINNER", "position": 1}, "delay": 3}, "runners": [{"id": 9028621, "name": "Mayar Sherif", "status": "WINNER", "position": 1, "inPlayOdds": 1.79, "inPlayTime": 1631446611418, "avgPrematch": 1.81, "closedOdds": 1.01, "maxPrematch": 1.83, "minPrematch": 1.79, "maxInPlay": 2.0, "minInPlay": 1.01, "inPlayIndex": 45, "lengthOdds": 2758, "lengthOddsPrematch": 45, "lengthOddsInPlay": 2713, "tradedVolume": 117174.41, "preMatchVolume": 170.99, "inPlayVolume": 117003.42}, {"id": 9345630, "name": "Martina Trevisan", "status": "LOSER", "position": 2, "inPlayOdds": 2.26, "inPlayTime": 1631446611418, "avgPrematch": 2.17, "closedOdds": 55.0, "maxPrematch": 2.26, "minPrematch": 2.16, "maxInPlay": 110.0, "minInPlay": 1.93, "inPlayIndex": 25, "lengthOdds": 2185, "lengthOddsPrematch": 25, "lengthOddsInPlay": 2160, "tradedVolume": 7249.73, "preMatchVolume": 409.49, "inPlayVolume": 6840.24}], "marketUpdates": [{"timestamp": 1631441384606000000, "openDate": "2021-09-12T13:00:00.000Z", "status": "OPEN", "betDelay": 0, "inPlay": false, "complete": true}, {"timestamp": 1631442863145000000, "openDate": "2021-09-12T11:30:00.000Z", "status": "OPEN", "betDelay": 0, "inPlay": false, "complete": true}, {"timestamp": 1631446161833000000, "openDate": "2021-09-12T11:35:00.000Z", "status": "OPEN", "betDelay": 0, "inPlay": false, "complete": true}, {"timestamp": 1631446460443000000, "openDate": "2021-09-12T11:40:00.000Z", "status": "OPEN", "betDelay": 0, "inPlay": false, "complete": true}, {"timestamp": 1631446611418000000, "openDate": "2021-09-12T11:40:00.000Z", "status": "OPEN", "betDelay": 3, "inPlay": true, "complete": true}, {"timestamp": 1631452427528000000, "openDate": "2021-09-12T11:40:00.000Z", "status": "SUSPENDED", "betDelay": 3, "inPlay": true, "complete": true}, {"timestamp": 1631452478975000000, "openDate": "2021-09-12T11:40:00.000Z", "status": "CLOSED", "betDelay": 3, "inPlay": true, "complete": true}], "odds": [{"runnerId": 9028621, "odds": [{"timestamp": 1631443297571, "ltp": 1.8, "tv": 112.24, "trd": [[1.8, 112.24]], "batb": [[0, 1.05, 879.74], [1, 1.01, 25], [2, 1.01, 0]], "batl": NaN}, {"timestamp": 1631443297733, "ltp": 1.8, "tv": 112.72, "trd": [[1.8, 112.72]], "batb": [[0, 1.45, 74.93], [1, 1.05, 879.5], [2, 1.01, 25]], "batl": NaN}, {"timestamp": 1631443302561, "ltp": 1.8, "tv": 112.72, "trd": NaN, "batb": [[0, 1.72, 62.62]], "batl": NaN}, {"timestamp": 1631443362942, "ltp": 1.8, "tv": 112.72, "trd": NaN, "batb": [[0, 1.73, 61.77]], "batl": NaN}, {"timestamp": 1631443392440, "ltp": 1.8, "tv": 112.72, "trd": NaN, "batb": NaN, "batl": [[0, 1.9, 22.21], [1, 29, 48.37]]}, {"timestamp": 1631443395254, "ltp": 1.8, "tv": 112.72, "trd": NaN, "batb": [[0, 1.74, 34.62], [1, 1.73, 61.77], [2, 1.05, 879.5]], "batl": NaN}, {"timestamp": 1631443496924, "ltp": 1.8, "tv": 112.72, "trd": NaN, "batb": [[2, 1.01, 25]], "batl": NaN}, {"timestamp": 1631443509932, "ltp": 1.8, "tv": 112.72, "trd": NaN, "batb": [[2, 1.42, 97.62]], "batl": [[1, 2.8, 43.98], [2, 29, 48.37]]}, {"timestamp": 1631443599391, "ltp": 1.8, "tv": 112.72, "trd": NaN, "batb": NaN, "batl": [[0, 1.87, 22.21]]}, {"timestamp": 1631443640845, "ltp": 1.8, "tv": 112.72, "trd": NaN, "batb": [[0, 1.73, 96.87], [1, 1.42, 97.62], [2, 1.01, 25]], "batl": NaN}, {"timestamp": 1631443829734, "ltp": 1.8, "tv": 112.72, "trd": NaN, "batb": NaN, "batl": [[0, 1.83, 8.68], [1, 1.87, 22.21], [2, 2.8, 43.98]]}, {"timestamp": 1631444148027, "ltp": 1.8, "tv": 112.72, "trd": NaN, "batb": NaN, "batl": [[2, 2.7, 43.98]]}, {"timestamp": 1631444238773, "ltp": 1.8, "tv": 112.72, "trd": NaN, "batb": [[1, 1.68, 2.66], [2, 1.42, 97.62]], "batl": NaN}, {"timestamp": 1631444354503, "ltp": 1.8, "tv": 112.72, "trd": NaN, "batb": [[0, 1.74, 8.58], [1, 1.73, 96.87], [2, 1.68, 2.66]], "batl": NaN}, {"timestamp": 1631444355289, "ltp": 1.8, "tv": 112.72, "trd": NaN, "batb": [[1, 1.73, 61.77], [2, 1.72, 35.59]], "batl": NaN}, {"timestamp": 1631444807986, "ltp": 1.8, "tv": 112.72, "trd": NaN, "batb": NaN, "batl": [[2, 2.6, 43.98]]}, {"timestamp": 1631445354571, "ltp": 1.83, "tv": 121.39, "trd": [[1.83, 8.68]], "batb": [[0, 1.76, 10.28], [1, 1.74, 18.5], [2, 1.73, 61.77]], "batl": [[0, 1.87, 22.21], [1, 2.6, 43.98], [2, 29, 48.37]]}, {"timestamp": 1631445354888, "ltp": 1.83, "tv": 121.39, "trd": NaN, "batb": [[0, 1.75, 34.16], [1, 1.74, 77.01]], "batl": NaN}, {"timestamp": 1631445412503, "ltp": 1.83, "tv": 121.39, "trd": NaN, "batb": [[1, 1.74, 58.51]], "batl": NaN}, {"timestamp": 1631445412727, "ltp": 1.83, "tv": 121.39, "trd": NaN, "batb": [[0, 1.76, 12.39], [1, 1.75, 34.16]], "batl": NaN}, {"timestamp": 1631445413924, "ltp": 1.83, "tv": 121.39, "trd": NaN, "batb": [[1, 1.74, 34.62]], "batl": NaN}, {"timestamp": 1631445456244, "ltp": 1.83, "tv": 121.39, "trd": NaN, "batb": [[0, 1.77, 21.74]], "batl": NaN}, {"timestamp": 1631445618251, "ltp": 1.83, "tv": 121.39, "trd": NaN, "batb": NaN, "batl": [[0, 1.89, 22.21]]}, {"timestamp": 1631445619043, "ltp": 1.83, "tv": 121.39, "trd": NaN, "batb": [[1, 1.76, 33.71], [2, 1.74, 34.62]], "batl": NaN}, {"timestamp": 1631445661352, "ltp": 1.83, "tv": 121.39, "trd": NaN, "batb": [[0, 1.79, 9.4], [1, 1.77, 21.74], [2, 1.76, 33.71]], "batl": NaN}, {"timestamp": 1631445662051, "ltp": 1.83, "tv": 121.39, "trd": NaN, "batb": [[1, 1.77, 55.01]], "batl": NaN}, {"timestamp": 1631445712512, "ltp": 1.83, "tv": 121.39, "trd": NaN, "batb": [[1, 1.77, 33.27]], "batl": NaN}, {"timestamp": 1631445713104, "ltp": 1.83, "tv": 121.39, "trd": NaN, "batb": [[0, 1.8, 14.63], [1, 1.79, 9.4], [2, 1.78, 32.85]], "batl": NaN}, {"timestamp": 1631445897466, "ltp": 1.83, "tv": 121.39, "trd": NaN, "batb": NaN, "batl": [[0, 1.87, 5], [1, 1.89, 22.21], [2, 2.6, 43.98]]}, {"timestamp": 1631445917315, "ltp": 1.8, "tv": 130.99, "trd": [[1.8, 122.32]], "batb": [[0, 1.8, 9.83], [2, 1.76, 33.71]], "batl": NaN}, {"timestamp": 1631446197403, "ltp": 1.8, "tv": 130.99, "trd": NaN, "batb": [[2, 1.78, 32.85]], "batl": [[0, 1.87, 7]]}, {"timestamp": 1631446226467, "ltp": 1.8, "tv": 150.65, "trd": [[1.8, 141.98]], "batb": [[0, 1.79, 9.4], [1, 1.73, 96.87], [2, 1.72, 35.59]], "batl": [[0, 1.8, 10.17], [1, 1.87, 7], [2, 1.89, 22.21]]}, {"timestamp": 1631446226681, "ltp": 1.8, "tv": 150.65, "trd": NaN, "batb": [[0, 1.79, 15.39]], "batl": NaN}, {"timestamp": 1631446253416, "ltp": 1.79, "tv": 170.99, "trd": [[1.79, 20.34]], "batb": [[0, 1.79, 5.22]], "batl": [[0, 1.87, 7], [1, 1.89, 22.21], [2, 2.6, 43.98]]}, {"timestamp": 1631446312548, "ltp": 1.79, "tv": 170.99, "trd": NaN, "batb": [[0, 1.74, 21.8]], "batl": NaN}, {"timestamp": 1631446313515, "ltp": 1.79, "tv": 170.99, "trd": NaN, "batb": [[0, 1.75, 34.16], [1, 1.74, 219.34], [2, 1.73, 100.87]], "batl": NaN}, {"timestamp": 1631446330458, "ltp": 1.79, "tv": 170.99, "trd": NaN, "batb": [[1, 1.74, 26.8], [2, 1.73, 96.87]], "batl": NaN}, {"timestamp": 1631446331464, "ltp": 1.79, "tv": 170.99, "trd": NaN, "batb": [[0, 1.76, 224.03], [1, 1.75, 34.16], [2, 1.74, 26.8]], "batl": NaN}, {"timestamp": 1631446343533, "ltp": 1.79, "tv": 170.99, "trd": NaN, "batb": [[0, 1.75, 34.16], [1, 1.74, 26.8], [2, 1.73, 96.87]], "batl": NaN}, {"timestamp": 1631446349470, "ltp": 1.79, "tv": 170.99, "trd": NaN, "batb": [[0, 1.74, 61.43], [1, 1.73, 96.87], [2, 1.72, 35.59]], "batl": [[0, 1.86, 3], [1, 1.87, 7], [2, 1.89, 22.21]]}, {"timestamp": 1631446351066, "ltp": 1.79, "tv": 170.99, "trd": NaN, "batb": [[0, 1.74, 34.62]], "batl": [[0, 1.84, 3], [1, 1.86, 3], [2, 1.87, 7]]}, {"timestamp": 1631446362574, "ltp": 1.79, "tv": 170.99, "trd": NaN, "batb": [[0, 1.73, 61.77], [1, 1.72, 35.59], [2, 1.69, 144.93]], "batl": [[0, 1.83, 3], [1, 1.84, 3], [2, 1.86, 3]]}, {"timestamp": 1631446363263, "ltp": 1.79, "tv": 170.99, "trd": NaN, "batb": NaN, "batl": [[0, 1.81, 3], [1, 1.83, 3], [2, 1.84, 3]]}, {"timestamp": 1631446460443, "ltp": 1.79, "tv": 170.99, "trd": NaN, "batb": NaN, "batl": [[1, 1.87, 7], [2, 1.89, 22.21]]}, {"timestamp": 1631446460659, "ltp": 1.79, "tv": 170.99, "trd": NaN, "batb": [[0, 1.73, 96.87]], "batl": NaN}, {"timestamp": 1631446611418, "ltp": 1.79, "tv": 170.99, "trd": NaN, "batb": [[0, 1.01, 30], [1, 1.72, 0], [2, 1.69, 0]], "batl": [[0, 1.87, 5], [1, 1.87, 0], [2, 1.89, 0]]}, {"timestamp": 1631446631389, "ltp": 1.79, "tv": 170.99, "trd": NaN, "batb": [[0, 1.84, 5], [1, 1.83, 5], [2, 1.01, 506.85]], "batl": [[0, 1.87, 10]]}, {"timestamp": 1631446634530, "ltp": 1.79, "tv": 170.99, "trd": NaN, "batb": [[2, 1.03, 494.32]], "batl": NaN}, {"timestamp": 1631446637967, "ltp": 1.79, "tv": 170.99, "trd": NaN, "batb": [[0, 1.05, 474.54], [1, 1.03, 494.32], [2, 1.01, 506.85]], "batl": [[0, 1.87, 5]]}, {"timestamp": 1631446641236, "ltp": 1.79, "tv": 170.99, "trd": NaN, "batb": [[0, 1.11, 269.63], [1, 1.1, 296.59], [2, 1.09, 353.11]], "batl": NaN}, {"timestamp": 1631446650553, "ltp": 1.87, "tv": 175.99, "trd": [[1.87, 5]], "batb": NaN, "batl": NaN}, {"timestamp": 1631446653468, "ltp": 1.87, "tv": 175.99, "trd": NaN, "batb": [[0, 1.96, 4], [1, 1.95, 4], [2, 1.2, 385.57]], "batl": [[0, 2.04, 4]]}, {"timestamp": 1631446653757, "ltp": 1.87, "tv": 175.99, "trd": NaN, "batb": NaN, "batl": [[1, 21, 2]]}, {"timestamp": 1631446657246, "ltp": 1.87, "tv": 175.99, "trd": NaN, "batb": [[2, 1.4, 148.3]], "batl": NaN}, {"timestamp": 1631446675394, "ltp": 1.95, "tv": 196.15, "trd": [[1.95, 8], [1.96, 12.16]], "batb": [[0, 1.4, 148.3], [1, 1.3, 197.73], [2, 1.2, 385.57]], "batl": [[1, 21, 0]]}, {"timestamp": 1631446678495, "ltp": 2.0, "tv": 200.15, "trd": [[2, 4]], "batb": [[0, 1.86, 4], [1, 1.85, 4], [2, 1.4, 155.3]], "batl": NaN}, {"timestamp": 1631446697440, "ltp": 2.0, "tv": 200.15, "trd": NaN, "batb": [[0, 1.4, 155.3], [1, 1.3, 197.73], [2, 1.2, 385.57]], "batl": NaN}, {"timestamp": 1631446700569, "ltp": 2.0, "tv": 200.15, "trd": NaN, "batb": [[1, 1.39, 7], [2, 1.3, 197.73]], "batl": NaN}, {"timestamp": 1631446700725, "ltp": 2.0, "tv": 200.15, "trd": NaN, "batb": NaN, "batl": [[0, 3.5, 3]]}, {"timestamp": 1631446712922, "ltp": 2.0, "tv": 200.15, "trd": NaN, "batb": [[1, 1.3, 197.73], [2, 1.2, 385.57]], "batl": [[0, 2, 15.49], [1, 3.5, 3]]}, {"timestamp": 1631446716134, "ltp": 2.0, "tv": 200.15, "trd": NaN, "batb": [[0, 1.76, 4], [1, 1.75, 4], [2, 1.4, 155.3]], "batl": [[0, 2, 19.49]]}, {"timestamp": 1631446719344, "ltp": 2.0, "tv": 200.15, "trd": NaN, "batb": NaN, "batl": [[0, 2, 4]]}, {"timestamp": 1631446722548, "ltp": 2.0, "tv": 200.15, "trd": NaN, "batb": NaN, "batl": [[0, 1.84, 5], [1, 1.97, 15.49], [2, 2, 4]]}, {"timestamp": 1631446725138, "ltp": 2.0, "tv": 200.15, "trd": NaN, "batb": NaN, "batl": [[1, 1.97, 19.49]]}, {"timestamp": 1631446729918, "ltp": 2.0, "tv": 200.15, "trd": NaN, "batb": [[0, 1.4, 155.3], [1, 1.3, 197.73], [2, 1.2, 385.57]], "batl": NaN}, {"timestamp": 1631446733257, "ltp": 2.0, "tv": 200.15, "trd": NaN, "batb": [[1, 1.39, 5], [2, 1.3, 197.73]], "batl": [[0, 2.68, 4]]}, {"timestamp": 1631446772475, "ltp": 2.0, "tv": 200.15, "trd": NaN, "batb": NaN, "batl": [[0, 1.72, 65.49], [1, 2.68, 4]]}, {"timestamp": 1631446772734, "ltp": 2.0, "tv": 200.15, "trd": NaN, "batb": [[0, 1.4, 7], [1, 1.3, 197.73], [2, 1.2, 385.57]], "batl": [[0, 2.68, 4], [1, 2.68, 0]]}, {"timestamp": 1631446775986, "ltp": 2.0, "tv": 200.15, "trd": NaN, "batb": [[0, 1.66, 5], [1, 1.65, 5], [2, 1.4, 7]], "batl": NaN}, {"timestamp": 1631446782295, "ltp": 2.0, "tv": 200.15, "trd": NaN, "batb": NaN, "batl": [[0, 2.52, 3], [1, 2.68, 4]]}, {"timestamp": 1631446789704, "ltp": 2.0, "tv": 200.15, "trd": NaN, "batb": [[1, 1.3, 197.73], [2, 1.2, 385.57]], "batl": [[0, 2.22, 4], [1, 2.52, 3], [2, 2.68, 4]]}, {"timestamp": 1631446792899, "ltp": 2.0, "tv": 200.15, "trd": NaN, "batb": [[1, 1.65, 5], [2, 1.3, 197.73]], "batl": NaN}, {"timestamp": 1631446805505, "ltp": 1.65, "tv": 226.17, "trd": [[1.65, 10], [1.66, 16.02]], "batb": [[0, 1.3, 197.73], [1, 1.2, 385.57], [2, 1.11, 269.63]], "batl": [[0, 1.64, 60.09], [1, 2.22, 4], [2, 2.52, 3]]}, {"timestamp": 1631446805729, "ltp": 1.65, "tv": 226.17, "trd": NaN, "batb": NaN, "batl": [[0, 2.22, 4], [1, 2.22, 0], [2, 2.52, 0]]}, {"timestamp": 1631446808908, "ltp": 1.65, "tv": 226.17, "trd": NaN, "batb": [[0, 1.58, 6], [1, 1.57, 6], [2, 1.3, 205.73]], "batl": NaN}, {"timestamp": 1631446811938, "ltp": 1.65, "tv": 226.17, "trd": NaN, "batb": [[0, 1.65, 5], [1, 1.64, 4], [2, 1.58, 6]], "batl": NaN}, {"timestamp": 1631446821783, "ltp": 1.65, "tv": 226.17, "trd": NaN, "batb": [[2, 1.3, 197.73]], "batl": NaN}, {"timestamp": 1631446824179, "ltp": 1.65, "tv": 226.17, "trd": NaN, "batb": [[1, 1.3, 197.73], [2, 1.2, 385.57]], "batl": [[0, 2.08, 27.55], [1, 2.22, 4]]}, {"timestamp": 1631446824982, "ltp": 1.65, "tv": 226.17, "trd": NaN, "batb": [[0, 1.71, 4], [1, 1.7, 5], [2, 1.65, 5]], "batl": NaN}, {"timestamp": 1631446827288, "ltp": 1.65, "tv": 226.17, "trd": NaN, "batb": NaN, "batl": [[0, 2.08, 32.55]]}, {"timestamp": 1631446828053, "ltp": 1.65, "tv": 226.17, "trd": NaN, "batb": [[2, 1.66, 50]], "batl": NaN}, {"timestamp": 1631446835630, "ltp": 1.65, "tv": 226.17, "trd": NaN, "batb": [[2, 1.65, 5]], "batl": NaN}, {"timestamp": 1631446839291, "ltp": 1.65, "tv": 226.17, "trd": NaN, "batb": [[0, 1.72, 50], [1, 1.71, 4], [2, 1.3, 197.73]], "batl": [[1, 2.22, 0]]}, {"timestamp": 1631446845631, "ltp": 1.72, "tv": 236.29, "trd": [[1.72, 10.12]], "batb": [[0, 1.72, 44.94]], "batl": NaN}, {"timestamp": 1631446854531, "ltp": 1.72, "tv": 236.29, "trd": NaN, "batb": [[1, 1.3, 197.73], [2, 1.2, 385.57]], "batl": [[0, 1.9, 8.54], [1, 2.08, 32.55]]}, {"timestamp": 1631446857739, "ltp": 1.72, "tv": 236.29, "trd": NaN, "batb": NaN, "batl": [[0, 1.9, 12.54]]}, {"timestamp": 1631446859423, "ltp": 1.72, "tv": 236.29, "trd": NaN, "batb": NaN, "batl": [[0, 1.84, 4], [1, 1.9, 12.54], [2, 2.08, 32.55]]}, {"timestamp": 1631446859729, "ltp": 1.72, "tv": 236.29, "trd": NaN, "batb": NaN, "batl": [[0, 1.9, 12.54], [1, 2.08, 32.55], [2, 2.08, 0]]}, {"timestamp": 1631446862570, "ltp": 1.72, "tv": 236.29, "trd": NaN, "batb": NaN, "batl": [[0, 1.84, 4], [1, 1.9, 12.54], [2, 2.08, 32.55]]}, {"timestamp": 1631446867891, "ltp": 1.72, "tv": 236.29, "trd": NaN, "batb": NaN, "batl": [[1, 1.9, 4]]}, {"timestamp": 1631446871199, "ltp": 1.72, "tv": 236.29, "trd": NaN, "batb": NaN, "batl": [[0, 1.81, 8.54], [1, 1.84, 4], [2, 2.08, 27.55]]}, {"timestamp": 1631446882319, "ltp": 1.72, "tv": 271.45, "trd": [[1.72, 45.28]], "batb": [[0, 1.72, 21.78]], "batl": NaN}, {"timestamp": 1631446883404, "ltp": 1.72, "tv": 271.45, "trd": NaN, "batb": [[2, 1.25, 237.27]], "batl": NaN}, {"timestamp": 1631446884517, "ltp": 1.72, "tv": 315.01, "trd": [[1.72, 88.84]], "batb": [[0, 1.3, 197.73], [1, 1.25, 237.27], [2, 1.2, 385.57]], "batl": [[0, 1.72, 110.6], [1, 1.81, 8.54], [2, 1.84, 4]]}, {"timestamp": 1631446885537, "ltp": 1.72, "tv": 315.01, "trd": NaN, "batb": NaN, "batl": [[0, 1.72, 361.18], [1, 1.81, 12.54]]}, {"timestamp": 1631446886553, "ltp": 1.72, "tv": 315.01, "trd": NaN, "batb": NaN, "batl": [[0, 1.72, 577.61]]}, {"timestamp": 1631446887520, "ltp": 1.72, "tv": 315.01, "trd": NaN, "batb": [[0, 1.3, 201.73], [1, 1.29, 4], [2, 1.25, 237.27]], "batl": [[0, 1.72, 190.21]]}, {"timestamp": 1631446888441, "ltp": 1.72, "tv": 315.01, "trd": NaN, "batb": [[0, 1.31, 188.59], [1, 1.3, 201.73], [2, 1.29, 4]], "batl": [[0, 1.72, 190.48]]}, {"timestamp": 1631446889560, "ltp": 1.72, "tv": 315.01, "trd": NaN, "batb": NaN, "batl": [[0, 1.72, 125.38]]}, {"timestamp": 1631446890509, "ltp": 1.72, "tv": 315.01, "trd": NaN, "batb": [[0, 1.3, 201.73], [1, 1.29, 4], [2, 1.25, 237.27]], "batl": [[0, 1.72, 81.82]]}, {"timestamp": 1631446891050, "ltp": 1.72, "tv": 315.01, "trd": NaN, "batb": [[0, 1.31, 9], [1, 1.3, 201.73], [2, 1.29, 4]], "batl": [[0, 1.72, 46.77]]}, {"timestamp": 1631446891755, "ltp": 1.72, "tv": 315.01, "trd": NaN, "batb": NaN, "batl": [[0, 1.72, 6]]}, {"timestamp": 1631446893488, "ltp": 1.72, "tv": 315.01, "trd": NaN, "batb": [[0, 1.32, 182.05], [1, 1.31, 9], [2, 1.3, 201.73]], "batl": NaN}, {"timestamp": 1631446894471, "ltp": 1.72, "tv": 315.01, "trd": NaN, "batb": [[0, 1.47, 6], [1, 1.46, 6], [2, 1.31, 9]], "batl": NaN}, {"timestamp": 1631446894738, "ltp": 1.72, "tv": 315.01, "trd": NaN, "batb": NaN, "batl": [[1, 1.81, 4]]}, {"timestamp": 1631446896358, "ltp": 1.72, "tv": 315.01, "trd": NaN, "batb": [[0, 1.5, 5], [1, 1.47, 6], [2, 1.46, 6]], "batl": NaN}, {"timestamp": 1631446899517, "ltp": 1.72, "tv": 315.01, "trd": NaN, "batb": [[1, 1.49, 5], [2, 1.47, 6]], "batl": NaN}, {"timestamp": 1631446899744, "ltp": 1.72, "tv": 315.01, "trd": NaN, "batb": NaN, "batl": [[1, 2.08, 27.55], [2, 1.84, 0]]}, {"timestamp": 1631446903274, "ltp": 1.72, "tv": 315.01, "trd": NaN, "batb": NaN, "batl": [[0, 2.08, 27.55], [1, 2.08, 0]]}, {"timestamp": 1631446906576, "ltp": 1.72, "tv": 315.01, "trd": NaN, "batb": [[2, 1.32, 5]], "batl": [[0, 2.08, 31.55]]}, {"timestamp": 1631446909988, "ltp": 1.72, "tv": 315.01, "trd": NaN, "batb": [[2, 1.3, 197.73]], "batl": [[0, 1.85, 4], [1, 2.08, 31.55]]}, {"timestamp": 1631446914485, "ltp": 1.72, "tv": 315.01, "trd": NaN, "batb": [[1, 1.3, 197.73], [2, 1.25, 237.27]], "batl": NaN}, {"timestamp": 1631446915501, "ltp": 1.72, "tv": 315.01, "trd": NaN, "batb": NaN, "batl": [[0, 1.56, 6], [1, 1.85, 4], [2, 2.08, 31.55]]}, {"timestamp": 1631446915668, "ltp": 1.72, "tv": 315.01, "trd": NaN, "batb": [[1, 1.25, 237.27], [2, 1.2, 385.57]], "batl": NaN}, {"timestamp": 1631446918305, "ltp": 1.72, "tv": 315.01, "trd": NaN, "batb": [[1, 1.49, 6], [2, 1.25, 237.27]], "batl": NaN}, {"timestamp": 1631446918601, "ltp": 1.5, "tv": 325.07, "trd": [[1.5, 10.06]], "batb": [[0, 1.49, 6], [1, 1.25, 237.27], [2, 1.2, 385.57]], "batl": NaN}, {"timestamp": 1631446919910, "ltp": 1.5, "tv": 331.01, "trd": [[1.5, 16]], "batb": NaN, "batl": NaN}, {"timestamp": 1631446921493, "ltp": 1.5, "tv": 331.01, "trd": NaN, "batb": NaN, "batl": [[2, 2.08, 27.55]]}, {"timestamp": 1631446921804, "ltp": 1.5, "tv": 331.01, "trd": NaN, "batb": [[0, 1.5, 6], [1, 1.49, 6], [2, 1.48, 6]], "batl": NaN}, {"timestamp": 1631446923215, "ltp": 1.5, "tv": 331.01, "trd": NaN, "batb": NaN, "batl": [[0, 1.54, 8.54], [1, 1.56, 6], [2, 1.85, 4]]}, {"timestamp": 1631446924405, "ltp": 1.56, "tv": 345.55, "trd": [[1.54, 8.54], [1.56, 6]], "batb": NaN, "batl": [[0, 1.85, 4], [1, 2.08, 27.55], [2, 810, 0.07]]}, {"timestamp": 1631446931424, "ltp": 1.56, "tv": 345.55, "trd": NaN, "batb": NaN, "batl": [[2, 820, 0.14]]}, {"timestamp": 1631446931915, "ltp": 1.54, "tv": 364.25, "trd": [[1.54, 27.24]], "batb": [[0, 1.25, 237.27], [1, 1.2, 385.57], [2, 1.11, 269.63]], "batl": [[0, 1.48, 198.2], [1, 1.85, 4], [2, 2.08, 27.55]]}, {"timestamp": 1631446933138, "ltp": 1.48, "tv": 388.44, "trd": [[1.48, 24.18]], "batb": NaN, "batl": [[0, 1.48, 183.02]]}, {"timestamp": 1631446935236, "ltp": 1.48, "tv": 388.44, "trd": NaN, "batb": [[0, 1.25, 247.27], [1, 1.24, 9], [2, 1.2, 385.57]], "batl": NaN}, {"timestamp": 1631446938337, "ltp": 1.48, "tv": 409.17, "trd": [[1.48, 44.91]], "batb": NaN, "batl": [[0, 1.48, 162.29]]}, {"timestamp": 1631446939410, "ltp": 1.48, "tv": 453.65, "trd": [[1.48, 89.39]], "batb": NaN, "batl": [[0, 1.48, 131.81]]}, {"timestamp": 1631446941523, "ltp": 1.48, "tv": 453.65, "trd": NaN, "batb": [[0, 1.36, 466.94], [1, 1.28, 187.83], [2, 1.25, 247.27]], "batl": [[2, 2, 400.21]]}, {"timestamp": 1631446942654, "ltp": 1.36, "tv": 458.91, "trd": [[1.36, 5.26]], "batb": [[0, 1.36, 464.31]], "batl": [[0, 1.85, 4], [1, 2, 400.21], [2, 2.08, 27.55]]}, {"timestamp": 1631446944429, "ltp": 1.36, "tv": 458.91, "trd": NaN, "batb": [[0, 1.36, 471.31], [1, 1.35, 9], [2, 1.28, 187.83]], "batl": NaN}, {"timestamp": 1631446947434, "ltp": 1.36, "tv": 458.91, "trd": NaN, "batb": [[0, 1.51, 6], [1, 1.5, 7], [2, 1.36, 471.31]], "batl": NaN}, {"timestamp": 1631446950963, "ltp": 1.85, "tv": 459.19, "trd": [[1.85, 0.28]], "batb": NaN, "batl": [[0, 1.85, 3.86]]}, {"timestamp": 1631446955726, "ltp": 1.85, "tv": 459.19, "trd": NaN, "batb": NaN, "batl": [[0, 1.84, 5], [1, 1.85, 3.86], [2, 2, 400.21]]}, {"timestamp": 1631446957435, "ltp": 1.85, "tv": 459.19, "trd": NaN, "batb": [[2, 1.36, 464.31]], "batl": NaN}, {"timestamp": 1631446960064, "ltp": 1.84, "tv": 459.21, "trd": [[1.84, 0.02]], "batb": [[0, 1.36, 464.31], [1, 1.25, 237.27], [2, 1.2, 385.57]], "batl": [[0, 1.84, 4.99]]}, {"timestamp": 1631446961354, "ltp": 1.84, "tv": 459.21, "trd": NaN, "batb": NaN, "batl": [[0, 1.77, 5.98], [1, 1.84, 4.99], [2, 1.85, 3.86]]}, {"timestamp": 1631446963336, "ltp": 1.84, "tv": 459.21, "trd": NaN, "batb": [[0, 1.36, 470.31], [1, 1.35, 8], [2, 1.25, 237.27]], "batl": NaN}, {"timestamp": 1631446964560, "ltp": 1.84, "tv": 459.21, "trd": NaN, "batb": NaN, "batl": [[0, 1.77, 9.98]]}, {"timestamp": 1631446967569, "ltp": 1.84, "tv": 459.21, "trd": NaN, "batb": [[0, 1.36, 6]], "batl": [[1, 2, 400.21], [2, 2.08, 27.55]]}, {"timestamp": 1631446969473, "ltp": 1.84, "tv": 459.21, "trd": NaN, "batb": [[0, 1.59, 12], [1, 1.36, 6], [2, 1.35, 8]], "batl": NaN}, {"timestamp": 1631446969691, "ltp": 1.84, "tv": 459.21, "trd": NaN, "batb": [[0, 1.59, 6]], "batl": NaN}, {"timestamp": 1631446971595, "ltp": 1.84, "tv": 459.21, "trd": NaN, "batb": [[1, 1.42, 445.57], [2, 1.36, 6]], "batl": NaN}, {"timestamp": 1631446974785, "ltp": 1.84, "tv": 459.21, "trd": NaN, "batb": [[0, 1.6, 6], [1, 1.59, 11], [2, 1.42, 445.57]], "batl": NaN}, {"timestamp": 1631446981826, "ltp": 1.84, "tv": 459.21, "trd": NaN, "batb": [[0, 1.62, 5], [1, 1.6, 6], [2, 1.59, 11]], "batl": NaN}, {"timestamp": 1631446985022, "ltp": 1.58, "tv": 542.02, "trd": [[1.58, 27.17], [1.59, 22], [1.6, 23.64], [1.62, 10]], "batb": [[0, 1.42, 445.57], [1, 1.25, 237.27], [2, 1.2, 385.57]], "batl": [[0, 1.58, 94.79], [1, 1.77, 9.98], [2, 2, 400.21]]}, {"timestamp": 1631446988024, "ltp": 1.58, "tv": 542.02, "trd": NaN, "batb": [[0, 1.42, 451.57], [1, 1.41, 7], [2, 1.25, 237.27]], "batl": [[0, 1.77, 9.98], [1, 2, 400.21], [2, 2.08, 27.55]]}, {"timestamp": 1631446988709, "ltp": 1.58, "tv": 542.02, "trd": NaN, "batb": NaN, "batl": [[0, 1.77, 4]]}, {"timestamp": 1631447002054, "ltp": 1.58, "tv": 542.02, "trd": NaN, "batb": [[1, 1.25, 237.27], [2, 1.2, 385.57]], "batl": NaN}, {"timestamp": 1631447004244, "ltp": 1.58, "tv": 542.02, "trd": NaN, "batb": NaN, "batl": [[0, 1.76, 1.71], [1, 1.77, 4], [2, 2, 400.21]]}, {"timestamp": 1631447005257, "ltp": 1.58, "tv": 542.02, "trd": NaN, "batb": [[1, 1.41, 4], [2, 1.25, 237.27]], "batl": NaN}, {"timestamp": 1631447008975, "ltp": 1.58, "tv": 542.02, "trd": NaN, "batb": [[0, 1.42, 6]], "batl": [[2, 2.08, 27.55]]}, {"timestamp": 1631447012461, "ltp": 1.58, "tv": 542.02, "trd": NaN, "batb": [[0, 1.67, 6], [1, 1.42, 6], [2, 1.41, 4]], "batl": NaN}, {"timestamp": 1631447016569, "ltp": 1.58, "tv": 542.02, "trd": NaN, "batb": [[0, 1.67, 9], [1, 1.66, 4], [2, 1.42, 6]], "batl": NaN}, {"timestamp": 1631447018682, "ltp": 1.58, "tv": 542.02, "trd": NaN, "batb": [[2, 1.25, 237.27]], "batl": NaN}, {"timestamp": 1631447021777, "ltp": 1.58, "tv": 542.02, "trd": NaN, "batb": NaN, "batl": [[0, 1.77, 4], [1, 2.08, 27.55], [2, 810, 0.07]]}, {"timestamp": 1631447029164, "ltp": 1.58, "tv": 542.02, "trd": NaN, "batb": [[1, 1.25, 237.27], [2, 1.2, 385.57]], "batl": NaN}, {"timestamp": 1631447032390, "ltp": 1.58, "tv": 542.02, "trd": NaN, "batb": [[1, 1.66, 5], [2, 1.25, 237.27]], "batl": NaN}, {"timestamp": 1631447033296, "ltp": 1.77, "tv": 546.02, "trd": [[1.77, 4]], "batb": NaN, "batl": [[0, 2.08, 27.55], [1, 810, 0.07], [2, 810, 0]]}, {"timestamp": 1631447035067, "ltp": 1.77, "tv": 546.02, "trd": NaN, "batb": [[2, 1.3, 197.73]], "batl": NaN}, {"timestamp": 1631447036501, "ltp": 1.79, "tv": 550.02, "trd": [[1.79, 24.34]], "batb": NaN, "batl": [[0, 2.08, 31.55]]}, {"timestamp": 1631447040391, "ltp": 1.79, "tv": 550.02, "trd": NaN, "batb": [[0, 1.3, 197.73], [1, 1.25, 237.27], [2, 1.2, 385.57]], "batl": NaN}, {"timestamp": 1631447043526, "ltp": 1.79, "tv": 550.02, "trd": NaN, "batb": [[0, 1.41, 6], [1, 1.4, 7], [2, 1.3, 197.73]], "batl": NaN}, {"timestamp": 1631447043622, "ltp": 1.79, "tv": 550.02, "trd": NaN, "batb": [[2, 1.3, 206.73]], "batl": NaN}, {"timestamp": 1631447047930, "ltp": 1.79, "tv": 550.02, "trd": NaN, "batb": [[0, 1.71, 6], [1, 1.41, 6], [2, 1.4, 7]], "batl": NaN}, {"timestamp": 1631447054272, "ltp": 1.7, "tv": 567.71, "trd": [[1.7, 5.69], [1.71, 12]], "batb": [[0, 1.41, 6], [1, 1.4, 7], [2, 1.3, 206.73]], "batl": [[0, 1.67, 88.31], [1, 2.08, 31.55], [2, 810, 0.07]]}, {"timestamp": 1631447055447, "ltp": 1.67, "tv": 605.71, "trd": [[1.67, 38]], "batb": NaN, "batl": [[0, 1.67, 69.31], [1, 1.81, 4], [2, 2.08, 31.55]]}, {"timestamp": 1631447055765, "ltp": 1.67, "tv": 610.17, "trd": [[1.67, 42.46]], "batb": [[1, 1.3, 197.73], [2, 1.25, 237.27]], "batl": [[0, 1.67, 64.85]]}, {"timestamp": 1631447057431, "ltp": 1.67, "tv": 615.89, "trd": [[1.67, 48.18]], "batb": [[0, 1.43, 176.56], [1, 1.41, 6], [2, 1.3, 197.73]], "batl": [[0, 1.67, 61.06]]}, {"timestamp": 1631447057750, "ltp": 1.67, "tv": 650.05, "trd": [[1.67, 82.34]], "batb": NaN, "batl": [[0, 1.67, 43.98]]}, {"timestamp": 1631447059046, "ltp": 1.67, "tv": 650.05, "trd": NaN, "batb": [[2, 1.4, 8]], "batl": NaN}, {"timestamp": 1631447060573, "ltp": 1.67, "tv": 738.0, "trd": [[1.67, 170.29]], "batb": [[0, 1.67, 285.77], [1, 1.43, 7], [2, 1.42, 7]], "batl": [[0, 1.81, 4], [1, 2.08, 31.55], [2, 810, 0.07]]}, {"timestamp": 1631447061554, "ltp": 1.67, "tv": 738.0, "trd": NaN, "batb": [[0, 1.67, 945.33]], "batl": NaN}, {"timestamp": 1631447062567, "ltp": 1.67, "tv": 738.0, "trd": NaN, "batb": [[0, 1.67, 730.35]], "batl": NaN}, {"timestamp": 1631447063576, "ltp": 1.67, "tv": 738.0, "trd": NaN, "batb": [[0, 1.67, 353.4], [1, 1.66, 4], [2, 1.43, 7]], "batl": NaN}, {"timestamp": 1631447064379, "ltp": 1.67, "tv": 738.0, "trd": NaN, "batb": [[0, 1.67, 146.89]], "batl": NaN}, {"timestamp": 1631447065453, "ltp": 1.67, "tv": 738.0, "trd": NaN, "batb": [[0, 1.67, 5]], "batl": NaN}, {"timestamp": 1631447069192, "ltp": 1.81, "tv": 742.0, "trd": [[1.81, 4]], "batb": NaN, "batl": [[0, 2.08, 27.55], [1, 810, 0.07], [2, 810, 0]]}, {"timestamp": 1631447072392, "ltp": 1.83, "tv": 747.0, "trd": [[1.83, 13.68]], "batb": [[2, 1.3, 197.73]], "batl": [[0, 2.08, 30.55]]}, {"timestamp": 1631447076398, "ltp": 1.83, "tv": 748.71, "trd": [[1.83, 15.38]], "batb": [[1, 1.3, 197.73], [2, 1.25, 237.27]], "batl": NaN}, {"timestamp": 1631447080504, "ltp": 1.83, "tv": 761.52, "trd": [[1.83, 28.19]], "batb": [[0, 1.3, 197.73], [1, 1.25, 237.27], [2, 1.2, 385.57]], "batl": NaN}, {"timestamp": 1631447088422, "ltp": 1.83, "tv": 761.52, "trd": NaN, "batb": NaN, "batl": [[0, 1.88, 10], [1, 2.08, 30.55], [2, 810, 0.07]]}, {"timestamp": 1631447088637, "ltp": 1.83, "tv": 761.52, "trd": NaN, "batb": NaN, "batl": [[0, 1.88, 5]]}, {"timestamp": 1631447092534, "ltp": 1.83, "tv": 761.52, "trd": NaN, "batb": NaN, "batl": [[0, 1.73, 46.07], [1, 1.88, 10], [2, 1.91, 2.56]]}, {"timestamp": 1631447092738, "ltp": 1.83, "tv": 761.52, "trd": NaN, "batb": NaN, "batl": [[0, 1.88, 10], [1, 1.91, 2.56], [2, 2.08, 30.55]]}, {"timestamp": 1631447095138, "ltp": 1.83, "tv": 761.52, "trd": NaN, "batb": [[0, 1.31, 189.17], [1, 1.3, 197.73], [2, 1.25, 237.27]], "batl": NaN}, {"timestamp": 1631447095728, "ltp": 1.83, "tv": 761.52, "trd": NaN, "batb": NaN, "batl": [[0, 1.73, 5], [1, 1.88, 10], [2, 1.91, 2.56]]}, {"timestamp": 1631447102441, "ltp": 1.83, "tv": 761.52, "trd": NaN, "batb": NaN, "batl": [[2, 2.08, 30.55]]}, {"timestamp": 1631447105517, "ltp": 1.67, "tv": 888.35, "trd": [[1.67, 297.12]], "batb": NaN, "batl": [[0, 1.65, 17.77], [1, 1.73, 5], [2, 1.85, 2.56]]}, {"timestamp": 1631447106957, "ltp": 1.67, "tv": 888.35, "trd": NaN, "batb": [[0, 1.3, 197.73], [1, 1.25, 237.27], [2, 1.2, 385.57]], "batl": [[1, 1.85, 2.56], [2, 1.88, 5]]}, {"timestamp": 1631447108143, "ltp": 1.67, "tv": 888.35, "trd": NaN, "batb": [[0, 1.31, 8], [1, 1.3, 205.73], [2, 1.25, 237.27]], "batl": NaN}, {"timestamp": 1631447110061, "ltp": 1.67, "tv": 888.35, "trd": NaN, "batb": [[2, 1.29, 9]], "batl": NaN}, {"timestamp": 1631447113422, "ltp": 1.67, "tv": 888.35, "trd": NaN, "batb": NaN, "batl": [[2, 2.08, 27.55]]}, {"timestamp": 1631447116843, "ltp": 1.67, "tv": 888.35, "trd": NaN, "batb": NaN, "batl": [[1, 1.83, 5], [2, 1.85, 2.56]]}, {"timestamp": 1631447118085, "ltp": 1.67, "tv": 888.35, "trd": NaN, "batb": NaN, "batl": [[0, 1.83, 5], [1, 1.85, 2.56], [2, 2.08, 27.55]]}, {"timestamp": 1631447120267, "ltp": 1.67, "tv": 888.35, "trd": NaN, "batb": [[1, 1.3, 197.73]], "batl": [[0, 1.65, 5], [1, 1.83, 5], [2, 1.85, 2.56]]}, {"timestamp": 1631447121551, "ltp": 1.67, "tv": 888.35, "trd": NaN, "batb": [[0, 1.33, 186.28], [1, 1.31, 8], [2, 1.3, 197.73]], "batl": [[1, 1.83, 9]]}, {"timestamp": 1631447123482, "ltp": 1.67, "tv": 888.35, "trd": NaN, "batb": [[0, 1.61, 6], [1, 1.6, 6], [2, 1.31, 8]], "batl": NaN}, {"timestamp": 1631447124554, "ltp": 1.67, "tv": 888.35, "trd": NaN, "batb": [[2, 1.33, 6]], "batl": NaN}, {"timestamp": 1631447128572, "ltp": 1.67, "tv": 888.35, "trd": NaN, "batb": [[0, 1.33, 6], [1, 1.32, 6], [2, 1.31, 8]], "batl": [[0, 1.83, 4], [1, 1.85, 2.56], [2, 2.08, 27.55]]}, {"timestamp": 1631447135461, "ltp": 1.67, "tv": 888.35, "trd": NaN, "batb": [[2, 1.3, 197.73]], "batl": [[0, 1.61, 86.04], [1, 1.83, 4], [2, 1.85, 2.56]]}, {"timestamp": 1631447138286, "ltp": 1.67, "tv": 888.35, "trd": NaN, "batb": [[1, 1.25, 237.27], [2, 1.2, 385.57]], "batl": [[2, 1.84, 5]]}, {"timestamp": 1631447141220, "ltp": 1.67, "tv": 888.35, "trd": NaN, "batb": [[1, 1.32, 7], [2, 1.25, 237.27]], "batl": NaN}, {"timestamp": 1631447144392, "ltp": 1.67, "tv": 888.35, "trd": NaN, "batb": NaN, "batl": [[0, 1.61, 6]]}, {"timestamp": 1631447146319, "ltp": 1.67, "tv": 888.35, "trd": NaN, "batb": [[0, 1.57, 6], [1, 1.56, 7], [2, 1.33, 6]], "batl": NaN}, {"timestamp": 1631447157318, "ltp": 1.67, "tv": 888.35, "trd": NaN, "batb": [[0, 1.56, 7], [1, 1.25, 237.27], [2, 1.2, 385.57]], "batl": [[0, 1.85, 2.56], [1, 2.08, 27.55], [2, 810, 0.07]]}, {"timestamp": 1631447158223, "ltp": 1.67, "tv": 888.35, "trd": NaN, "batb": NaN, "batl": [[0, 1.57, 86.04], [1, 1.85, 2.56], [2, 2.08, 27.55]]}, {"timestamp": 1631447160533, "ltp": 1.67, "tv": 888.35, "trd": NaN, "batb": [[1, 1.55, 6], [2, 1.25, 237.27]], "batl": [[1, 1.84, 4], [2, 1.85, 2.56]]}, {"timestamp": 1631447163469, "ltp": 1.55, "tv": 919.77, "trd": [[1.55, 17.42], [1.56, 20]], "batb": [[0, 1.25, 237.27], [1, 1.2, 385.57], [2, 1.17, 314.03]], "batl": [[0, 1.84, 4], [1, 1.85, 2.56], [2, 2.08, 27.55]]}, {"timestamp": 1631447166533, "ltp": 1.55, "tv": 919.77, "trd": NaN, "batb": [[0, 1.36, 464.27], [1, 1.33, 8], [2, 1.32, 8]], "batl": [[0, 1.82, 5], [1, 1.84, 4], [2, 1.85, 2.56]]}, {"timestamp": 1631447169031, "ltp": 1.55, "tv": 919.77, "trd": NaN, "batb": NaN, "batl": [[0, 1.82, 9]]}, {"timestamp": 1631447169782, "ltp": 1.55, "tv": 919.77, "trd": NaN, "batb": [[0, 1.54, 5], [1, 1.53, 5], [2, 1.36, 464.27]], "batl": NaN}, {"timestamp": 1631447172949, "ltp": 1.55, "tv": 919.77, "trd": NaN, "batb": NaN, "batl": [[0, 1.59, 5], [1, 1.82, 9], [2, 1.84, 4]]}, {"timestamp": 1631447186285, "ltp": 1.55, "tv": 919.77, "trd": NaN, "batb": [[1, 1.36, 464.27], [2, 1.25, 237.27]], "batl": [[1, 1.81, 27.55], [2, 1.82, 5]]}, {"timestamp": 1631447189469, "ltp": 1.55, "tv": 919.77, "trd": NaN, "batb": [[1, 1.53, 5], [2, 1.36, 464.27]], "batl": NaN}, {"timestamp": 1631447197681, "ltp": 1.59, "tv": 929.77, "trd": [[1.59, 32]], "batb": [[0, 1.59, 87.35], [1, 1.54, 5], [2, 1.53, 5]], "batl": [[0, 1.81, 27.55], [1, 1.82, 5], [2, 1.85, 2.56]]}, {"timestamp": 1631447200890, "ltp": 1.59, "tv": 929.77, "trd": NaN, "batb": NaN, "batl": [[0, 1.6, 6], [1, 1.81, 27.55], [2, 1.82, 5]]}, {"timestamp": 1631447215533, "ltp": 1.59, "tv": 938.31, "trd": [[1.59, 40.54]], "batb": [[0, 1.59, 83.08], [2, 1.36, 464.27]], "batl": NaN}, {"timestamp": 1631447219422, "ltp": 1.61, "tv": 960.19, "trd": [[1.6, 35.64], [1.61, 9.88]], "batb": [[0, 1.61, 34.12], [1, 1.59, 83.08], [2, 1.54, 5]], "batl": [[0, 1.81, 27.55], [1, 1.82, 5], [2, 2, 402.01]]}, {"timestamp": 1631447222549, "ltp": 1.61, "tv": 960.19, "trd": NaN, "batb": NaN, "batl": [[0, 1.76, 5], [1, 1.81, 32.55], [2, 1.82, 5]]}, {"timestamp": 1631447241573, "ltp": 1.61, "tv": 960.19, "trd": NaN, "batb": NaN, "batl": [[1, 1.81, 27.55]]}, {"timestamp": 1631447245156, "ltp": 1.61, "tv": 1028.43, "trd": [[1.61, 78.12]], "batb": [[0, 1.59, 83.08], [1, 1.54, 5], [2, 1.36, 464.27]], "batl": [[0, 1.61, 51.92], [1, 1.76, 5], [2, 1.81, 27.55]]}, {"timestamp": 1631447248571, "ltp": 1.61, "tv": 1132.27, "trd": [[1.61, 181.96]], "batb": NaN, "batl": [[0, 1.61, 4], [1, 1.75, 6], [2, 1.76, 5]]}, {"timestamp": 1631447256487, "ltp": 1.61, "tv": 1132.27, "trd": NaN, "batb": [[1, 1.36, 464.27], [2, 1.25, 237.27]], "batl": [[0, 1.75, 6], [1, 1.76, 5], [2, 1.81, 27.55]]}, {"timestamp": 1631447259904, "ltp": 1.61, "tv": 1132.27, "trd": NaN, "batb": NaN, "batl": [[1, 1.81, 27.55], [2, 2, 402.01]]}, {"timestamp": 1631447271188, "ltp": 1.75, "tv": 1135.93, "trd": [[1.75, 3.66]], "batb": NaN, "batl": [[0, 1.75, 2.34]]}, {"timestamp": 1631447278952, "ltp": 1.59, "tv": 1381.31, "trd": [[1.59, 285.92]], "batb": [[0, 1.36, 464.27], [1, 1.25, 237.27], [2, 1.2, 385.57]], "batl": NaN}, {"timestamp": 1631447280473, "ltp": 1.59, "tv": 1381.31, "trd": NaN, "batb": NaN, "batl": [[0, 1.72, 6], [1, 1.75, 2.34], [2, 1.81, 27.55]]}, {"timestamp": 1631447282467, "ltp": 1.59, "tv": 1381.31, "trd": NaN, "batb": [[0, 1.36, 471.27], [1, 1.35, 8], [2, 1.25, 237.27]], "batl": NaN}, {"timestamp": 1631447285199, "ltp": 1.59, "tv": 1381.31, "trd": NaN, "batb": NaN, "batl": [[0, 1.7, 4], [1, 1.72, 6], [2, 1.75, 2.34]]}, {"timestamp": 1631447288468, "ltp": 1.59, "tv": 1381.31, "trd": NaN, "batb": [[0, 1.47, 6], [1, 1.46, 6], [2, 1.36, 471.27]], "batl": [[0, 1.52, 5], [1, 1.7, 4], [2, 1.72, 6]]}, {"timestamp": 1631447302704, "ltp": 1.59, "tv": 1381.31, "trd": NaN, "batb": [[0, 1.36, 471.27], [1, 1.25, 237.27], [2, 1.2, 385.57]], "batl": [[0, 1.81, 27.55], [1, 2, 402.01], [2, 1.72, 0]]}, {"timestamp": 1631447305990, "ltp": 1.59, "tv": 1381.31, "trd": NaN, "batb": [[1, 1.35, 8], [2, 1.25, 237.27]], "batl": [[0, 1.7, 6], [1, 1.81, 27.55], [2, 2, 402.01]]}, {"timestamp": 1631447312319, "ltp": 1.7, "tv": 1384.16, "trd": [[1.7, 8.54]], "batb": [[0, 1.68, 12], [1, 1.36, 471.27], [2, 1.35, 8]], "batl": [[0, 1.7, 3.15]]}, {"timestamp": 1631447312859, "ltp": 1.7, "tv": 1384.16, "trd": NaN, "batb": [[0, 1.68, 6]], "batl": NaN}, {"timestamp": 1631447315542, "ltp": 1.68, "tv": 1396.16, "trd": [[1.68, 12]], "batb": [[0, 1.36, 471.27], [1, 1.35, 8], [2, 1.2, 385.57]], "batl": [[0, 1.42, 131.37], [1, 1.7, 3.15], [2, 1.81, 27.55]]}, {"timestamp": 1631447316234, "ltp": 1.42, "tv": 1462.74, "trd": [[1.42, 66.58]], "batb": NaN, "batl": [[0, 1.42, 64.8]]}, {"timestamp": 1631447318469, "ltp": 1.42, "tv": 1592.33, "trd": [[1.42, 196.17]], "batb": NaN, "batl": [[0, 1.7, 3.15], [1, 1.81, 27.55], [2, 2, 402.01]]}, {"timestamp": 1631447319439, "ltp": 1.42, "tv": 1592.33, "trd": NaN, "batb": [[1, 1.2, 385.57], [2, 1.17, 314.03]], "batl": NaN}, {"timestamp": 1631447323441, "ltp": 1.42, "tv": 1592.33, "trd": NaN, "batb": [[0, 1.42, 3], [1, 1.41, 3], [2, 1.36, 471.27]], "batl": NaN}, {"timestamp": 1631447340403, "ltp": 1.42, "tv": 1592.33, "trd": NaN, "batb": [[1, 1.2, 385.57], [2, 1.17, 314.03]], "batl": [[2, 2, 0]]}, {"timestamp": 1631447342261, "ltp": 1.42, "tv": 1592.33, "trd": NaN, "batb": NaN, "batl": [[0, 1.68, 6], [1, 1.7, 3.15], [2, 1.81, 27.55]]}, {"timestamp": 1631447343598, "ltp": 1.42, "tv": 1592.33, "trd": NaN, "batb": [[1, 1.41, 3], [2, 1.2, 385.57]], "batl": NaN}, {"timestamp": 1631447344248, "ltp": 1.42, "tv": 1592.33, "trd": NaN, "batb": [[2, 1.29, 491.02]], "batl": NaN}, {"timestamp": 1631447347095, "ltp": 1.42, "tv": 1592.33, "trd": NaN, "batb": NaN, "batl": [[0, 1.67, 2], [1, 1.68, 6], [2, 1.7, 3.15]]}, {"timestamp": 1631447349864, "ltp": 1.42, "tv": 1592.33, "trd": NaN, "batb": [[0, 1.46, 7], [1, 1.45, 6], [2, 1.42, 3]], "batl": [[0, 1.51, 3], [1, 1.67, 2], [2, 1.68, 6]]}, {"timestamp": 1631447361401, "ltp": 1.42, "tv": 1592.33, "trd": NaN, "batb": [[0, 1.29, 491.02], [1, 1.2, 385.57], [2, 1.17, 314.03]], "batl": [[0, 1.81, 27.55], [1, 1.85, 464.26], [2, 1.68, 0]]}, {"timestamp": 1631447363027, "ltp": 1.85, "tv": 1798.91, "trd": [[1.67, 303.11], [1.81, 59.11], [1.85, 145.76]], "batb": NaN, "batl": [[0, 1.85, 391.52], [1, 1.85, 0]]}, {"timestamp": 1631447364887, "ltp": 1.85, "tv": 1798.91, "trd": NaN, "batb": [[0, 1.29, 499.02], [1, 1.28, 9], [2, 1.2, 385.57]], "batl": NaN}, {"timestamp": 1631447366236, "ltp": 1.85, "tv": 1798.91, "trd": NaN, "batb": NaN, "batl": [[0, 1.85, 395.52]]}, {"timestamp": 1631447367832, "ltp": 1.85, "tv": 1798.91, "trd": NaN, "batb": NaN, "batl": [[0, 1.68, 6], [1, 1.85, 395.52]]}, {"timestamp": 1631447369539, "ltp": 1.85, "tv": 1798.91, "trd": NaN, "batb": NaN, "batl": [[0, 1.44, 1522.78], [1, 1.68, 6], [2, 1.85, 395.52]]}, {"timestamp": 1631447369634, "ltp": 1.85, "tv": 1798.91, "trd": NaN, "batb": NaN, "batl": [[0, 1.68, 6], [1, 1.85, 395.52], [2, 1.85, 0]]}, {"timestamp": 1631447370948, "ltp": 1.85, "tv": 1798.91, "trd": NaN, "batb": NaN, "batl": [[0, 1.56, 6], [1, 1.68, 6], [2, 1.85, 395.52]]}, {"timestamp": 1631447375519, "ltp": 1.85, "tv": 1798.91, "trd": NaN, "batb": NaN, "batl": [[1, 1.59, 2.91], [2, 1.68, 6]]}, {"timestamp": 1631447378549, "ltp": 1.85, "tv": 1798.91, "trd": NaN, "batb": [[1, 1.2, 385.57], [2, 1.17, 314.03]], "batl": [[0, 1.55, 6], [1, 1.56, 6], [2, 1.59, 2.91]]}, {"timestamp": 1631447378747, "ltp": 1.85, "tv": 1798.91, "trd": NaN, "batb": [[0, 1.39, 8], [1, 1.38, 7], [2, 1.29, 499.02]], "batl": [[0, 1.43, 7], [1, 1.55, 6], [2, 1.56, 6]]}, {"timestamp": 1631447393268, "ltp": 1.85, "tv": 1798.91, "trd": NaN, "batb": [[0, 1.29, 499.02], [1, 1.2, 385.57], [2, 1.17, 314.03]], "batl": [[0, 1.59, 2.91], [1, 1.85, 391.52], [2, 1.56, 0]]}, {"timestamp": 1631447396464, "ltp": 1.85, "tv": 1798.91, "trd": NaN, "batb": [[1, 1.28, 6], [2, 1.2, 385.57]], "batl": NaN}, {"timestamp": 1631447396765, "ltp": 1.85, "tv": 1798.91, "trd": NaN, "batb": NaN, "batl": [[0, 1.55, 6], [1, 1.59, 2.91], [2, 1.85, 391.52]]}, {"timestamp": 1631447407496, "ltp": 1.59, "tv": 1827.69, "trd": [[1.55, 40.37], [1.59, 291.75]], "batb": [[0, 1.7, 124.73], [1, 1.29, 499.02], [2, 1.28, 6]], "batl": [[0, 1.85, 391.52], [1, 1.59, 0], [2, 1.85, 0]]}, {"timestamp": 1631447410598, "ltp": 1.7, "tv": 2077.15, "trd": [[1.7, 258]], "batb": [[0, 1.29, 499.02], [1, 1.2, 385.57], [2, 1.17, 314.03]], "batl": [[0, 1.85, 395.52]]}, {"timestamp": 1631447412582, "ltp": 1.7, "tv": 2077.15, "trd": NaN, "batb": NaN, "batl": [[0, 1.7, 19.83], [1, 1.85, 395.52]]}, {"timestamp": 1631447413530, "ltp": 1.7, "tv": 2077.15, "trd": NaN, "batb": NaN, "batl": [[0, 1.7, 29.75]]}, {"timestamp": 1631447414545, "ltp": 1.7, "tv": 2077.15, "trd": NaN, "batb": [[1, 1.28, 6], [2, 1.2, 385.57]], "batl": [[0, 1.56, 5], [1, 1.7, 4.27], [2, 1.85, 395.52]]}, {"timestamp": 1631447415030, "ltp": 1.56, "tv": 2085.37, "trd": [[1.56, 28.22]], "batb": [[0, 1.56, 2.78], [1, 1.29, 499.02], [2, 1.28, 6]], "batl": [[0, 1.7, 4.27], [1, 1.85, 395.52], [2, 1.85, 0]]}, {"timestamp": 1631447418539, "ltp": 1.56, "tv": 2090.94, "trd": [[1.56, 33.78]], "batb": [[0, 1.29, 499.02], [1, 1.28, 6], [2, 1.25, 237.31]], "batl": [[0, 1.48, 92.26], [1, 1.56, 5.93], [2, 1.57, 5]]}, {"timestamp": 1631447419535, "ltp": 1.56, "tv": 2090.94, "trd": NaN, "batb": NaN, "batl": [[0, 1.56, 11.36], [1, 1.57, 5], [2, 1.7, 10.27]]}, {"timestamp": 1631447420451, "ltp": 1.56, "tv": 2090.94, "trd": NaN, "batb": NaN, "batl": [[0, 1.56, 37.87]]}, {"timestamp": 1631447421537, "ltp": 1.56, "tv": 2090.94, "trd": NaN, "batb": NaN, "batl": [[0, 1.56, 13.57], [2, 1.7, 6]]}, {"timestamp": 1631447422547, "ltp": 1.56, "tv": 2090.94, "trd": NaN, "batb": NaN, "batl": [[0, 1.57, 5], [1, 1.7, 6], [2, 1.85, 395.52]]}, {"timestamp": 1631447425258, "ltp": 1.56, "tv": 2090.94, "trd": NaN, "batb": [[1, 1.25, 237.31], [2, 1.2, 385.57]], "batl": [[0, 1.49, 7], [1, 1.57, 5], [2, 1.7, 6]]}, {"timestamp": 1631447428455, "ltp": 1.56, "tv": 2090.94, "trd": NaN, "batb": [[0, 1.42, 6], [1, 1.29, 499.02], [2, 1.25, 237.31]], "batl": NaN}, {"timestamp": 1631447451475, "ltp": 1.49, "tv": 2094.6, "trd": [[1.49, 3.66]], "batb": NaN, "batl": [[0, 1.49, 3.34]]}, {"timestamp": 1631447451676, "ltp": 1.49, "tv": 2094.6, "trd": NaN, "batb": [[0, 1.29, 499.02], [1, 1.25, 237.31], [2, 1.2, 385.57]], "batl": [[0, 1.85, 391.52], [1, 810, 0.07], [2, 1.7, 0]]}, {"timestamp": 1631447455578, "ltp": 1.49, "tv": 2094.6, "trd": NaN, "batb": [[1, 1.28, 4], [2, 1.25, 237.31]], "batl": [[0, 1.57, 6.89], [1, 1.58, 6], [2, 1.85, 391.52]]}, {"timestamp": 1631447458759, "ltp": 1.49, "tv": 2094.6, "trd": NaN, "batb": NaN, "batl": [[0, 1.57, 12.89]]}, {"timestamp": 1631447484343, "ltp": 1.49, "tv": 2094.6, "trd": NaN, "batb": [[0, 1.29, 8]], "batl": NaN}, {"timestamp": 1631447485043, "ltp": 1.49, "tv": 2094.6, "trd": NaN, "batb": [[1, 1.25, 237.31], [2, 1.2, 385.57]], "batl": [[0, 1.57, 6], [1, 1.85, 391.52], [2, 810, 0.07]]}, {"timestamp": 1631447486363, "ltp": 1.57, "tv": 2100.6, "trd": [[1.57, 6]], "batb": [[0, 1.68, 12], [1, 1.29, 8], [2, 1.25, 237.31]], "batl": [[0, 1.85, 391.52], [1, 810, 0.07], [2, 810, 0]]}, {"timestamp": 1631447486668, "ltp": 1.57, "tv": 2100.6, "trd": NaN, "batb": [[0, 1.68, 6]], "batl": NaN}, {"timestamp": 1631447488533, "ltp": 1.68, "tv": 2106.5, "trd": [[1.68, 17.9]], "batb": [[0, 1.36, 545.59]], "batl": NaN}, {"timestamp": 1631447489553, "ltp": 1.68, "tv": 2106.6, "trd": [[1.68, 18]], "batb": [[0, 1.36, 545.49]], "batl": [[0, 1.85, 395.52]]}, {"timestamp": 1631447490560, "ltp": 1.68, "tv": 2106.6, "trd": NaN, "batb": NaN, "batl": [[0, 1.68, 5.89], [1, 1.85, 395.52], [2, 810, 0.07]]}, {"timestamp": 1631447491474, "ltp": 1.68, "tv": 2106.6, "trd": NaN, "batb": [[0, 1.36, 554.49], [1, 1.35, 8], [2, 1.29, 8]], "batl": [[0, 1.85, 395.52], [1, 810, 0.07], [2, 810, 0]]}, {"timestamp": 1631447494058, "ltp": 1.68, "tv": 2106.6, "trd": NaN, "batb": NaN, "batl": [[0, 1.58, 5], [1, 1.68, 5], [2, 1.85, 395.52]]}, {"timestamp": 1631447495480, "ltp": 1.68, "tv": 2106.6, "trd": NaN, "batb": NaN, "batl": [[1, 1.68, 6.71], [2, 1.83, 6.89]]}, {"timestamp": 1631447499389, "ltp": 1.68, "tv": 2106.6, "trd": NaN, "batb": NaN, "batl": [[2, 1.85, 395.52]]}, {"timestamp": 1631447502853, "ltp": 1.68, "tv": 2106.6, "trd": NaN, "batb": [[2, 1.25, 237.31]], "batl": NaN}, {"timestamp": 1631447504550, "ltp": 1.68, "tv": 2106.6, "trd": NaN, "batb": [[1, 1.25, 237.31], [2, 1.2, 385.57]], "batl": [[1, 1.66, 6.89], [2, 1.67, 6.89]]}, {"timestamp": 1631447507590, "ltp": 1.68, "tv": 2106.6, "trd": NaN, "batb": [[1, 1.35, 6], [2, 1.25, 237.31]], "batl": NaN}, {"timestamp": 1631447510569, "ltp": 1.68, "tv": 2106.6, "trd": NaN, "batb": [[2, 1.2, 385.57]], "batl": [[0, 1.39, 122.91], [1, 1.58, 5], [2, 1.66, 6.89]]}, {"timestamp": 1631447513494, "ltp": 1.39, "tv": 2126.06, "trd": [[1.39, 19.46]], "batb": NaN, "batl": [[0, 1.39, 113.18]]}, {"timestamp": 1631447514283, "ltp": 1.39, "tv": 2173.89, "trd": [[1.39, 67.29]], "batb": NaN, "batl": [[0, 1.39, 89.26]]}, {"timestamp": 1631447515208, "ltp": 1.39, "tv": 2269.55, "trd": [[1.39, 162.95]], "batb": [[0, 1.36, 545.49], [1, 1.2, 385.57], [2, 1.17, 314.03]], "batl": [[0, 1.66, 6.89], [1, 1.67, 6.89], [2, 1.68, 1.71]]}, {"timestamp": 1631447517508, "ltp": 1.39, "tv": 2269.55, "trd": NaN, "batb": [[0, 1.39, 11.96], [1, 1.36, 545.49], [2, 1.2, 385.57]], "batl": [[0, 1.68, 1.71], [1, 1.85, 391.52], [2, 44, 7.23]]}, {"timestamp": 1631447518595, "ltp": 1.39, "tv": 2269.55, "trd": NaN, "batb": [[0, 1.39, 7.69]], "batl": [[0, 1.66, 5], [1, 1.68, 1.71], [2, 1.85, 391.52]]}, {"timestamp": 1631447519378, "ltp": 1.39, "tv": 2269.55, "trd": NaN, "batb": [[0, 1.39, 17.53]], "batl": NaN}, {"timestamp": 1631447520479, "ltp": 1.39, "tv": 2269.55, "trd": NaN, "batb": [[0, 1.39, 3.07]], "batl": [[2, 1.85, 396.52]]}, {"timestamp": 1631447520804, "ltp": 1.39, "tv": 2269.55, "trd": NaN, "batb": [[0, 1.36, 545.49], [1, 1.2, 385.57], [2, 1.17, 314.03]], "batl": NaN}, {"timestamp": 1631447522411, "ltp": 1.39, "tv": 2269.55, "trd": NaN, "batb": [[0, 1.4, 17.22], [1, 1.39, 17.66], [2, 1.36, 545.49]], "batl": NaN}, {"timestamp": 1631447528568, "ltp": 1.39, "tv": 2269.55, "trd": NaN, "batb": [[2, 1.2, 385.57]], "batl": [[0, 1.51, 20.68], [1, 1.66, 5], [2, 1.68, 1.71]]}, {"timestamp": 1631447528777, "ltp": 1.39, "tv": 2269.55, "trd": NaN, "batb": [[0, 1.2, 385.57], [1, 1.17, 314.03], [2, 1.11, 269.63]], "batl": [[0, 1.66, 5], [1, 1.68, 1.71], [2, 1.85, 396.52]]}, {"timestamp": 1631447530407, "ltp": 1.39, "tv": 2269.55, "trd": NaN, "batb": NaN, "batl": [[0, 1.62, 12], [1, 1.66, 5], [2, 1.68, 1.71]]}, {"timestamp": 1631447531488, "ltp": 1.39, "tv": 2269.55, "trd": NaN, "batb": [[0, 1.4, 6], [1, 1.39, 5], [2, 1.2, 385.57]], "batl": [[0, 1.62, 6]]}, {"timestamp": 1631447532281, "ltp": 1.39, "tv": 2269.55, "trd": NaN, "batb": [[2, 1.29, 577.8]], "batl": NaN}, {"timestamp": 1631447534301, "ltp": 1.39, "tv": 2269.55, "trd": NaN, "batb": NaN, "batl": [[0, 1.62, 12]]}, {"timestamp": 1631447537614, "ltp": 1.39, "tv": 2269.55, "trd": NaN, "batb": [[0, 1.4, 23.22]], "batl": NaN}, {"timestamp": 1631447539294, "ltp": 1.39, "tv": 2269.55, "trd": NaN, "batb": [[0, 1.41, 16.8], [1, 1.4, 23.22], [2, 1.39, 5]], "batl": NaN}, {"timestamp": 1631447540709, "ltp": 1.39, "tv": 2269.55, "trd": NaN, "batb": NaN, "batl": [[0, 1.49, 5], [1, 1.62, 12], [2, 1.66, 5]]}, {"timestamp": 1631447542543, "ltp": 1.39, "tv": 2269.55, "trd": NaN, "batb": [[0, 1.41, 22.8]], "batl": NaN}, {"timestamp": 1631447543520, "ltp": 1.39, "tv": 2269.55, "trd": NaN, "batb": [[0, 1.41, 6], [1, 1.4, 6]], "batl": NaN}, {"timestamp": 1631447543899, "ltp": 1.39, "tv": 2269.55, "trd": NaN, "batb": [[1, 1.29, 577.8], [2, 1.2, 385.57]], "batl": NaN}, {"timestamp": 1631447548426, "ltp": 1.39, "tv": 2269.55, "trd": NaN, "batb": [[1, 1.3, 22.96], [2, 1.29, 577.8]], "batl": [[1, 1.62, 6], [2, 1.68, 1.71]]}, {"timestamp": 1631447551634, "ltp": 1.39, "tv": 2269.55, "trd": NaN, "batb": [[0, 1.42, 5], [1, 1.41, 6], [2, 1.3, 22.96]], "batl": NaN}, {"timestamp": 1631447554208, "ltp": 1.39, "tv": 2269.55, "trd": NaN, "batb": [[0, 1.3, 22.96], [1, 1.29, 577.8], [2, 1.2, 385.57]], "batl": [[0, 1.68, 1.71], [1, 1.85, 391.52], [2, 44, 7.23]]}, {"timestamp": 1631447557422, "ltp": 1.39, "tv": 2269.55, "trd": NaN, "batb": [[0, 1.3, 31.96], [1, 1.29, 586.8]], "batl": [[1, 1.85, 395.52]]}, {"timestamp": 1631447560642, "ltp": 1.39, "tv": 2269.55, "trd": NaN, "batb": NaN, "batl": [[0, 1.63, 5], [1, 1.68, 1.71], [2, 1.85, 395.52]]}, {"timestamp": 1631447563042, "ltp": 1.39, "tv": 2269.55, "trd": NaN, "batb": [[0, 1.3, 9], [1, 1.29, 9]], "batl": [[2, 1.85, 4]]}, {"timestamp": 1631447564937, "ltp": 1.39, "tv": 2269.55, "trd": NaN, "batb": NaN, "batl": [[0, 1.45, 7], [1, 1.63, 5], [2, 1.68, 1.71]]}, {"timestamp": 1631447566529, "ltp": 1.39, "tv": 2269.55, "trd": NaN, "batb": [[2, 1.23, 605.12]], "batl": NaN}, {"timestamp": 1631447569440, "ltp": 1.39, "tv": 2269.55, "trd": NaN, "batb": [[1, 1.23, 605.12], [2, 1.2, 385.57]], "batl": NaN}, {"timestamp": 1631447569873, "ltp": 1.39, "tv": 2269.55, "trd": NaN, "batb": NaN, "batl": [[0, 1.45, 15]]}, {"timestamp": 1631447570964, "ltp": 1.39, "tv": 2269.55, "trd": NaN, "batb": [[0, 1.3, 31.96]], "batl": NaN}, {"timestamp": 1631447572565, "ltp": 1.39, "tv": 2269.55, "trd": NaN, "batb": NaN, "batl": [[0, 1.39, 6], [1, 1.45, 15]]}, {"timestamp": 1631447572671, "ltp": 1.39, "tv": 2269.55, "trd": NaN, "batb": [[1, 1.29, 6], [2, 1.23, 605.12]], "batl": NaN}, {"timestamp": 1631447574462, "ltp": 1.39, "tv": 2269.55, "trd": NaN, "batb": [[0, 1.3, 9]], "batl": NaN}, {"timestamp": 1631447576373, "ltp": 1.39, "tv": 2269.55, "trd": NaN, "batb": [[1, 1.29, 29.75]], "batl": NaN}, {"timestamp": 1631447584328, "ltp": 1.39, "tv": 2269.55, "trd": NaN, "batb": [[1, 1.29, 23.75]], "batl": [[1, 1.45, 7]]}, {"timestamp": 1631447586450, "ltp": 1.39, "tv": 2269.55, "trd": NaN, "batb": [[2, 1.28, 24.6]], "batl": [[0, 1.39, 6.85]]}, {"timestamp": 1631447587556, "ltp": 1.39, "tv": 2269.55, "trd": NaN, "batb": [[2, 1.23, 605.12]], "batl": NaN}, {"timestamp": 1631447589409, "ltp": 1.39, "tv": 2269.55, "trd": NaN, "batb": [[1, 1.23, 605.12], [2, 1.2, 385.57]], "batl": NaN}, {"timestamp": 1631447594238, "ltp": 1.39, "tv": 2269.55, "trd": NaN, "batb": [[0, 1.23, 605.12], [1, 1.2, 385.57], [2, 1.17, 314.03]], "batl": [[0, 1.68, 2.56], [1, 1.72, 483.76], [2, 44, 7.23]]}, {"timestamp": 1631447594839, "ltp": 1.39, "tv": 2269.55, "trd": NaN, "batb": NaN, "batl": [[0, 1.68, 1.71]]}, {"timestamp": 1631447597441, "ltp": 1.39, "tv": 2269.55, "trd": NaN, "batb": [[0, 1.23, 607.12], [1, 1.22, 2], [2, 1.2, 385.57]], "batl": [[0, 1.68, 6.71]]}, {"timestamp": 1631447597931, "ltp": 1.39, "tv": 2269.55, "trd": NaN, "batb": NaN, "batl": [[0, 1.68, 7.56], [1, 1.72, 488.76]]}, {"timestamp": 1631447605534, "ltp": 1.37, "tv": 2283.55, "trd": [[1.37, 14]], "batb": NaN, "batl": NaN}, {"timestamp": 1631447608440, "ltp": 1.37, "tv": 2284.41, "trd": [[1.37, 14.85]], "batb": NaN, "batl": NaN}, {"timestamp": 1631447609433, "ltp": 1.37, "tv": 2293.52, "trd": [[1.37, 23.96]], "batb": NaN, "batl": [[0, 1.35, 130.36], [1, 1.68, 7.56], [2, 1.72, 488.76]]}, {"timestamp": 1631447609651, "ltp": 1.37, "tv": 2293.52, "trd": NaN, "batb": [[1, 1.17, 314.03], [2, 1.11, 269.63]], "batl": [[0, 1.68, 7.56], [1, 1.72, 483.76], [2, 44, 7.23]]}, {"timestamp": 1631447613428, "ltp": 1.37, "tv": 2293.52, "trd": NaN, "batb": NaN, "batl": [[0, 1.35, 6], [1, 1.6, 14.63], [2, 1.68, 6.71]]}, {"timestamp": 1631447615060, "ltp": 1.33, "tv": 2352.92, "trd": [[1.33, 59.4]], "batb": NaN, "batl": [[0, 1.33, 10.6], [1, 1.35, 6], [2, 1.6, 14.63]]}, {"timestamp": 1631447618293, "ltp": 1.33, "tv": 2352.92, "trd": NaN, "batb": [[1, 1.22, 12], [2, 1.17, 314.03]], "batl": [[0, 1.33, 10]]}, {"timestamp": 1631447619379, "ltp": 1.33, "tv": 2352.92, "trd": NaN, "batb": NaN, "batl": [[2, 1.68, 7.56]]}, {"timestamp": 1631447621072, "ltp": 1.33, "tv": 2352.92, "trd": NaN, "batb": [[0, 1.24, 28.7], [1, 1.23, 607.12], [2, 1.22, 12]], "batl": [[0, 1.68, 7.56], [1, 1.72, 483.76], [2, 1.94, 8.68]]}, {"timestamp": 1631447624388, "ltp": 1.33, "tv": 2352.92, "trd": NaN, "batb": [[0, 1.24, 67.4]], "batl": NaN}, {"timestamp": 1631447627472, "ltp": 1.33, "tv": 2352.92, "trd": NaN, "batb": NaN, "batl": [[0, 1.61, 5.85], [1, 1.68, 6.71], [2, 1.72, 483.76]]}, {"timestamp": 1631447632597, "ltp": 1.33, "tv": 2352.92, "trd": NaN, "batb": [[1, 1.23, 2]], "batl": NaN}, {"timestamp": 1631447632881, "ltp": 1.33, "tv": 2352.92, "trd": NaN, "batb": [[1, 1.17, 314.03], [2, 1.11, 269.63]], "batl": NaN}, {"timestamp": 1631447634408, "ltp": 1.33, "tv": 2352.92, "trd": NaN, "batb": [[0, 1.29, 8], [1, 1.24, 67.4], [2, 1.17, 314.03]], "batl": NaN}, {"timestamp": 1631447636580, "ltp": 1.33, "tv": 2352.92, "trd": NaN, "batb": [[1, 1.24, 679.28]], "batl": NaN}, {"timestamp": 1631447637585, "ltp": 1.33, "tv": 2352.92, "trd": NaN, "batb": [[1, 1.24, 10]], "batl": NaN}, {"timestamp": 1631447638482, "ltp": 1.33, "tv": 2352.92, "trd": NaN, "batb": [[0, 1.33, 20.88], [1, 1.29, 8], [2, 1.24, 10]], "batl": [[0, 1.39, 113.41], [1, 1.61, 5], [2, 1.68, 6.71]]}, {"timestamp": 1631447638696, "ltp": 1.33, "tv": 2352.92, "trd": NaN, "batb": NaN, "batl": [[0, 1.61, 5.85], [1, 1.68, 6.71], [2, 1.72, 483.76]]}, {"timestamp": 1631447640594, "ltp": 1.33, "tv": 2352.92, "trd": NaN, "batb": [[0, 1.35, 19.68], [1, 1.33, 20.88], [2, 1.3, 8]], "batl": [[0, 1.55, 3.84], [1, 1.61, 5]]}, {"timestamp": 1631447641823, "ltp": 1.33, "tv": 2352.92, "trd": NaN, "batb": NaN, "batl": [[0, 1.39, 7.85], [1, 1.55, 2.99], [2, 1.61, 5]]}, {"timestamp": 1631447642931, "ltp": 1.33, "tv": 2352.92, "trd": NaN, "batb": [[0, 1.33, 20.88], [1, 1.3, 8], [2, 1.29, 16]], "batl": [[1, 1.55, 8.99]]}, {"timestamp": 1631447645112, "ltp": 1.33, "tv": 2352.92, "trd": NaN, "batb": [[0, 1.3, 8], [1, 1.29, 16], [2, 1.24, 10]], "batl": NaN}, {"timestamp": 1631447646917, "ltp": 1.33, "tv": 2352.92, "trd": NaN, "batb": [[0, 1.31, 22.22], [1, 1.3, 8], [2, 1.29, 16]], "batl": NaN}, {"timestamp": 1631447650139, "ltp": 1.33, "tv": 2352.92, "trd": NaN, "batb": [[0, 1.31, 30.22]], "batl": NaN}, {"timestamp": 1631447654552, "ltp": 1.33, "tv": 2352.92, "trd": NaN, "batb": [[0, 1.31, 22.22], [2, 1.17, 314.03]], "batl": [[0, 1.55, 3.84], [1, 1.72, 483.76], [2, 1.94, 8.68]]}, {"timestamp": 1631447657242, "ltp": 1.38, "tv": 2353.77, "trd": [[1.38, 0.85]], "batb": NaN, "batl": [[0, 1.55, 2.99]]}, {"timestamp": 1631447657830, "ltp": 1.38, "tv": 2353.77, "trd": NaN, "batb": NaN, "batl": [[0, 1.55, 9.99]]}, {"timestamp": 1631447660314, "ltp": 1.39, "tv": 2362.17, "trd": [[1.39, 171.35]], "batb": [[0, 1.3, 8], [1, 1.17, 314.03], [2, 1.11, 269.63]], "batl": NaN}, {"timestamp": 1631447661554, "ltp": 1.39, "tv": 2362.17, "trd": NaN, "batb": NaN, "batl": [[0, 1.36, 14], [1, 1.55, 9.99], [2, 1.72, 483.76]]}, {"timestamp": 1631447661931, "ltp": 1.39, "tv": 2362.17, "trd": NaN, "batb": NaN, "batl": [[0, 1.36, 7]]}, {"timestamp": 1631447663467, "ltp": 1.39, "tv": 2362.17, "trd": NaN, "batb": [[1, 1.29, 9], [2, 1.21, 211.95]], "batl": NaN}, {"timestamp": 1631447663742, "ltp": 1.39, "tv": 2362.17, "trd": NaN, "batb": [[2, 1.24, 28.7]], "batl": NaN}, {"timestamp": 1631447665119, "ltp": 1.39, "tv": 2362.17, "trd": NaN, "batb": NaN, "batl": [[0, 1.34, 9], [1, 1.36, 7], [2, 1.55, 9.99]]}, {"timestamp": 1631447669251, "ltp": 1.39, "tv": 2362.17, "trd": NaN, "batb": [[0, 1.31, 7], [1, 1.3, 8], [2, 1.29, 9]], "batl": NaN}, {"timestamp": 1631447678579, "ltp": 1.21, "tv": 2492.91, "trd": [[1.21, 18.72], [1.24, 57.4], [1.29, 18], [1.3, 22.62], [1.31, 14]], "batb": [[0, 1.21, 202.59], [1, 1.17, 314.03], [2, 1.11, 269.63]], "batl": [[0, 1.55, 2.99], [1, 1.72, 483.76], [2, 1.94, 8.68]]}, {"timestamp": 1631447681551, "ltp": 1.21, "tv": 2492.91, "trd": NaN, "batb": [[0, 1.21, 213.59], [1, 1.2, 11], [2, 1.17, 314.03]], "batl": NaN}, {"timestamp": 1631447681766, "ltp": 1.21, "tv": 2492.91, "trd": NaN, "batb": NaN, "batl": [[0, 1.55, 7.99]]}, {"timestamp": 1631447685088, "ltp": 1.21, "tv": 2492.91, "trd": NaN, "batb": NaN, "batl": [[0, 1.43, 24.89], [1, 1.55, 7.99], [2, 1.72, 483.76]]}, {"timestamp": 1631447689668, "ltp": 1.21, "tv": 2492.91, "trd": NaN, "batb": [[0, 1.21, 11]], "batl": NaN}, {"timestamp": 1631447691466, "ltp": 1.21, "tv": 2492.91, "trd": NaN, "batb": [[0, 1.32, 8], [1, 1.21, 11], [2, 1.2, 11]], "batl": [[0, 1.43, 7]]}, {"timestamp": 1631447694000, "ltp": 1.21, "tv": 2492.91, "trd": NaN, "batb": [[1, 1.24, 190.32], [2, 1.21, 11]], "batl": NaN}, {"timestamp": 1631447696484, "ltp": 1.21, "tv": 2917.77, "trd": [[1.21, 40.72], [1.24, 438.05], [1.32, 22.21]], "batb": [[0, 1.17, 314.03], [1, 1.11, 269.63], [2, 1.1, 296.59]], "batl": [[0, 1.21, 657.29], [1, 1.43, 7], [2, 1.55, 7.99]]}, {"timestamp": 1631447697593, "ltp": 1.21, "tv": 2963.9, "trd": [[1.21, 86.85]], "batb": [[0, 1.06, 494.32], [1, 1.05, 474.54], [2, 1.03, 494.32]], "batl": [[0, 1.21, 627.15], [2, 1.52, 23.41]]}, {"timestamp": 1631447698916, "ltp": 1.21, "tv": 2963.9, "trd": NaN, "batb": NaN, "batl": [[1, 1.4, 8], [2, 1.43, 7]]}, {"timestamp": 1631447699930, "ltp": 1.21, "tv": 4208.78, "trd": [[1.21, 1331.74]], "batb": [[0, 1.2, 10], [1, 1.19, 11], [2, 1.06, 494.32]], "batl": [[0, 1.4, 8], [1, 1.43, 7], [2, 1.52, 23.41]]}, {"timestamp": 1631447700730, "ltp": 1.2, "tv": 4212.78, "trd": [[1.2, 4]], "batb": [[0, 1.2, 8]], "batl": NaN}, {"timestamp": 1631447702498, "ltp": 1.2, "tv": 4212.78, "trd": NaN, "batb": [[0, 1.21, 32.8], [1, 1.2, 8], [2, 1.19, 11]], "batl": NaN}, {"timestamp": 1631447703398, "ltp": 1.2, "tv": 4212.78, "trd": NaN, "batb": [[0, 1.21, 79.61]], "batl": [[1, 1.52, 23.41], [2, 1.55, 2.99]]}, {"timestamp": 1631447715064, "ltp": 1.2, "tv": 4212.78, "trd": NaN, "batb": [[0, 1.21, 65.61], [1, 1.06, 494.32], [2, 1.05, 474.54]], "batl": [[0, 1.52, 23.41], [1, 1.55, 2.99], [2, 1.72, 483.76]]}, {"timestamp": 1631447718232, "ltp": 1.2, "tv": 4212.78, "trd": NaN, "batb": [[1, 1.1, 296.65], [2, 1.06, 494.32]], "batl": NaN}, {"timestamp": 1631447721044, "ltp": 1.2, "tv": 4212.78, "trd": NaN, "batb": [[0, 1.3, 3.45], [1, 1.21, 65.61], [2, 1.1, 296.65]], "batl": NaN}, {"timestamp": 1631447725879, "ltp": 1.2, "tv": 4212.78, "trd": NaN, "batb": [[0, 1.4, 3.67], [1, 1.3, 3.45], [2, 1.21, 65.61]], "batl": NaN}, {"timestamp": 1631447729436, "ltp": 1.3, "tv": 4227.02, "trd": [[1.3, 29.51], [1.4, 7.34]], "batb": [[0, 1.21, 65.61], [1, 1.06, 494.32], [2, 1.05, 474.54]], "batl": [[0, 1.22, 101.33], [1, 1.52, 23.41], [2, 1.55, 2.99]]}, {"timestamp": 1631447735516, "ltp": 1.22, "tv": 4321.03, "trd": [[1.22, 94.01]], "batb": [[0, 1.06, 494.32], [1, 1.05, 474.54], [2, 1.03, 494.32]], "batl": [[0, 1.22, 20.83], [1, 1.55, 2.99], [2, 1.72, 483.76]]}, {"timestamp": 1631447736539, "ltp": 1.22, "tv": 4341.86, "trd": [[1.22, 114.84]], "batb": [[0, 1.22, 27.56], [1, 1.06, 494.32], [2, 1.05, 474.54]], "batl": [[0, 1.55, 2.99], [1, 1.72, 483.76], [2, 1.94, 8.68]]}, {"timestamp": 1631447737507, "ltp": 1.22, "tv": 4341.86, "trd": NaN, "batb": [[0, 1.22, 51.24]], "batl": NaN}, {"timestamp": 1631447738522, "ltp": 1.22, "tv": 4341.86, "trd": NaN, "batb": [[0, 1.06, 494.32], [1, 1.05, 474.54], [2, 1.03, 494.32]], "batl": NaN}, {"timestamp": 1631447739423, "ltp": 1.22, "tv": 4341.86, "trd": NaN, "batb": [[0, 1.22, 61.59], [1, 1.06, 494.32], [2, 1.05, 474.54]], "batl": NaN}, {"timestamp": 1631447740972, "ltp": 1.22, "tv": 4341.86, "trd": NaN, "batb": [[0, 1.22, 31.31]], "batl": NaN}, {"timestamp": 1631447750426, "ltp": 1.22, "tv": 4341.86, "trd": NaN, "batb": [[0, 1.39, 7]], "batl": NaN}, {"timestamp": 1631447762371, "ltp": 1.22, "tv": 4341.86, "trd": NaN, "batb": [[0, 1.5, 252.36], [1, 1.49, 289.53], [2, 1.39, 7]], "batl": [[0, 1.54, 340.08], [1, 1.55, 248.21], [2, 1.72, 483.76]]}, {"timestamp": 1631447765464, "ltp": 1.22, "tv": 4341.86, "trd": NaN, "batb": [[2, 1.48, 7]], "batl": NaN}, {"timestamp": 1631447776592, "ltp": 1.5, "tv": 4741.86, "trd": [[1.5, 416]], "batb": [[0, 1.49, 289.53], [1, 1.48, 7], [2, 1.47, 7]], "batl": NaN}, {"timestamp": 1631447777481, "ltp": 1.5, "tv": 4741.86, "trd": NaN, "batb": [[0, 1.48, 7], [1, 1.39, 7], [2, 1.06, 494.32]], "batl": [[0, 1.55, 2.99], [1, 1.72, 483.76], [2, 1.94, 8.68]]}, {"timestamp": 1631447777899, "ltp": 1.5, "tv": 4741.86, "trd": NaN, "batb": [[0, 1.06, 494.32], [1, 1.05, 474.54], [2, 1.03, 494.32]], "batl": NaN}, {"timestamp": 1631447781086, "ltp": 1.5, "tv": 4741.86, "trd": NaN, "batb": [[0, 1.06, 497.32], [1, 1.05, 477.54]], "batl": NaN}, {"timestamp": 1631447781895, "ltp": 1.5, "tv": 4741.86, "trd": NaN, "batb": [[0, 1.41, 397], [1, 1.4, 380.61], [2, 1.06, 497.32]], "batl": [[1, 1.69, 349.98], [2, 1.71, 348.3]]}, {"timestamp": 1631447785236, "ltp": 1.5, "tv": 4741.86, "trd": NaN, "batb": [[2, 1.1, 296.65]], "batl": NaN}, {"timestamp": 1631447788513, "ltp": 1.5, "tv": 4741.86, "trd": NaN, "batb": [[2, 1.17, 314.09]], "batl": NaN}, {"timestamp": 1631447793213, "ltp": 1.41, "tv": 4752.56, "trd": [[1.41, 10.7]], "batb": [[0, 1.41, 391.65]], "batl": NaN}, {"timestamp": 1631447806582, "ltp": 1.41, "tv": 4752.56, "trd": NaN, "batb": NaN, "batl": [[0, 1.45, 4413.1], [1, 1.55, 2.99], [2, 1.72, 483.76]]}, {"timestamp": 1631447807214, "ltp": 1.41, "tv": 4752.56, "trd": NaN, "batb": NaN, "batl": [[0, 1.55, 2.99], [1, 1.72, 483.76], [2, 1.94, 8.68]]}, {"timestamp": 1631447809547, "ltp": 1.41, "tv": 4752.56, "trd": NaN, "batb": NaN, "batl": [[0, 1.45, 475.25], [1, 1.46, 310.13], [2, 1.55, 2.99]]}, {"timestamp": 1631447810455, "ltp": 1.45, "tv": 4805.2, "trd": [[1.41, 53.38], [1.45, 9.96]], "batb": [[0, 1.41, 362.97]], "batl": [[0, 1.45, 470.27]]}, {"timestamp": 1631447814563, "ltp": 1.41, "tv": 5039.4, "trd": [[1.41, 287.58]], "batb": [[0, 1.41, 245.87]], "batl": NaN}, {"timestamp": 1631447815356, "ltp": 1.41, "tv": 5039.4, "trd": NaN, "batb": [[2, 1.32, 42.39]], "batl": [[0, 1.45, 470.96], [2, 1.51, 22.5]]}, {"timestamp": 1631447816368, "ltp": 1.41, "tv": 5039.4, "trd": NaN, "batb": [[2, 1.17, 314.09]], "batl": [[0, 1.45, 470.27]]}, {"timestamp": 1631447816788, "ltp": 1.41, "tv": 5039.4, "trd": NaN, "batb": NaN, "batl": [[0, 1.45, 470.96]]}, {"timestamp": 1631447817845, "ltp": 1.41, "tv": 5040.78, "trd": [[1.41, 288.96]], "batb": [[0, 1.41, 334.47]], "batl": [[0, 1.45, 533.26]]}, {"timestamp": 1631447819549, "ltp": 1.41, "tv": 5089.88, "trd": [[1.41, 338.06]], "batb": [[0, 1.41, 309.92], [2, 1.33, 38.53]], "batl": [[0, 1.45, 532.57]]}, {"timestamp": 1631447819961, "ltp": 1.41, "tv": 5089.88, "trd": NaN, "batb": [[2, 1.17, 314.09]], "batl": [[0, 1.45, 321.98], [1, 1.51, 22.5], [2, 1.55, 25.49]]}, {"timestamp": 1631447822578, "ltp": 1.41, "tv": 5089.88, "trd": NaN, "batb": [[2, 1.32, 40.89]], "batl": NaN}, {"timestamp": 1631447822746, "ltp": 1.41, "tv": 5089.88, "trd": NaN, "batb": [[2, 1.17, 314.09]], "batl": [[0, 1.44, 222.69], [1, 1.45, 321.98], [2, 1.51, 22.5]]}, {"timestamp": 1631447824554, "ltp": 1.41, "tv": 5089.88, "trd": NaN, "batb": [[0, 1.41, 310.61]], "batl": NaN}, {"timestamp": 1631447826430, "ltp": 1.41, "tv": 5089.88, "trd": NaN, "batb": [[2, 1.33, 38.53]], "batl": [[0, 1.44, 225.25]]}, {"timestamp": 1631447826691, "ltp": 1.41, "tv": 5089.88, "trd": NaN, "batb": [[2, 1.17, 314.09]], "batl": NaN}, {"timestamp": 1631447832015, "ltp": 1.44, "tv": 5119.88, "trd": [[1.44, 30]], "batb": NaN, "batl": [[0, 1.44, 210.25]]}, {"timestamp": 1631447833529, "ltp": 1.44, "tv": 5119.88, "trd": NaN, "batb": [[2, 1.33, 36.53]], "batl": [[0, 1.44, 2.56]]}, {"timestamp": 1631447833821, "ltp": 1.44, "tv": 5119.88, "trd": NaN, "batb": [[2, 1.17, 314.09]], "batl": NaN}, {"timestamp": 1631447835907, "ltp": 1.44, "tv": 5119.88, "trd": NaN, "batb": [[2, 1.18, 38.27]], "batl": [[1, 1.45, 536.92], [2, 1.46, 310.16]]}, {"timestamp": 1631447839513, "ltp": 1.44, "tv": 5119.88, "trd": NaN, "batb": [[0, 1.18, 38.96], [1, 1.17, 314.09], [2, 1.1, 296.65]], "batl": [[1, 1.55, 22.5], [2, 1.72, 483.76]]}, {"timestamp": 1631447840727, "ltp": 1.44, "tv": 5119.88, "trd": NaN, "batb": [[0, 1.33, 41.22], [1, 1.18, 38.27], [2, 1.17, 314.09]], "batl": NaN}, {"timestamp": 1631447842127, "ltp": 1.44, "tv": 5119.88, "trd": NaN, "batb": [[0, 1.35, 556.68], [1, 1.34, 471.83], [2, 1.33, 40.53]], "batl": [[1, 1.54, 279.07], [2, 1.55, 269]]}, {"timestamp": 1631447846448, "ltp": 1.44, "tv": 5119.88, "trd": NaN, "batb": NaN, "batl": [[1, 1.51, 22.5], [2, 1.54, 279.07]]}, {"timestamp": 1631447847537, "ltp": 1.44, "tv": 5119.88, "trd": NaN, "batb": NaN, "batl": [[1, 1.54, 279.07], [2, 1.55, 269]]}, {"timestamp": 1631447853587, "ltp": 1.44, "tv": 5119.88, "trd": NaN, "batb": NaN, "batl": [[1, 1.51, 23.01], [2, 1.54, 279.07]]}, {"timestamp": 1631447853787, "ltp": 1.44, "tv": 5119.88, "trd": NaN, "batb": NaN, "batl": [[1, 1.54, 279.07], [2, 1.55, 269]]}, {"timestamp": 1631447860458, "ltp": 1.44, "tv": 5119.88, "trd": NaN, "batb": NaN, "batl": [[1, 1.51, 25.5], [2, 1.54, 279.07]]}, {"timestamp": 1631447860879, "ltp": 1.35, "tv": 5122.08, "trd": [[1.35, 0.82], [1.41, 339.43]], "batb": [[0, 1.35, 555.58]], "batl": [[1, 1.54, 279.07], [2, 1.55, 269]]}, {"timestamp": 1631447866118, "ltp": 1.35, "tv": 5122.08, "trd": NaN, "batb": [[0, 1.33, 40.53], [1, 1.18, 38.27], [2, 1.17, 314.09]], "batl": NaN}, {"timestamp": 1631447867373, "ltp": 1.44, "tv": 5124.64, "trd": [[1.44, 32.56]], "batb": NaN, "batl": [[0, 1.51, 23.01]]}, {"timestamp": 1631447867701, "ltp": 1.44, "tv": 5124.64, "trd": NaN, "batb": NaN, "batl": [[0, 1.54, 279.07], [1, 1.55, 269], [2, 1.94, 8.68]]}, {"timestamp": 1631447869400, "ltp": 1.44, "tv": 5124.64, "trd": NaN, "batb": [[0, 1.5, 320.43], [1, 1.49, 291.02], [2, 1.4, 7]], "batl": NaN}, {"timestamp": 1631447874303, "ltp": 1.5, "tv": 5288.5, "trd": [[1.5, 579.86]], "batb": [[0, 1.5, 238.5]], "batl": NaN}, {"timestamp": 1631447875418, "ltp": 1.5, "tv": 5288.5, "trd": NaN, "batb": [[2, 1.41, 32.89]], "batl": [[2, 1.69, 19.5]]}, {"timestamp": 1631447877492, "ltp": 1.5, "tv": 5288.5, "trd": NaN, "batb": [[0, 1.5, 284.99]], "batl": [[0, 1.54, 313.77]]}, {"timestamp": 1631447890216, "ltp": 1.54, "tv": 5339.79, "trd": [[1.54, 78.53]], "batb": NaN, "batl": [[0, 1.54, 262.48]]}, {"timestamp": 1631447896320, "ltp": 1.54, "tv": 5339.79, "trd": NaN, "batb": [[0, 1.36, 34.43], [1, 1.34, 8], [2, 1.25, 237.31]], "batl": [[0, 1.77, 17.5], [1, 1.94, 8.68], [2, 2, 783.31]]}, {"timestamp": 1631447897646, "ltp": 1.54, "tv": 5339.79, "trd": NaN, "batb": [[0, 1.54, 50], [1, 1.36, 34.43], [2, 1.34, 8]], "batl": NaN}, {"timestamp": 1631447899508, "ltp": 1.54, "tv": 5339.79, "trd": NaN, "batb": [[1, 1.41, 558.72], [2, 1.4, 382.98]], "batl": [[0, 1.69, 249.46], [1, 1.7, 5], [2, 1.71, 349.41]]}, {"timestamp": 1631447899723, "ltp": 1.54, "tv": 5339.79, "trd": NaN, "batb": [[1, 1.41, 589.61]], "batl": [[0, 1.69, 270.96]]}, {"timestamp": 1631447904355, "ltp": 1.54, "tv": 5339.79, "trd": NaN, "batb": NaN, "batl": [[0, 1.69, 5], [2, 1.77, 4]]}, {"timestamp": 1631447906055, "ltp": 1.54, "tv": 5439.79, "trd": [[1.54, 178.53]], "batb": [[0, 1.41, 589.61], [1, 1.4, 382.98], [2, 1.36, 34.43]], "batl": NaN}, {"timestamp": 1631447907538, "ltp": 1.41, "tv": 5477.33, "trd": [[1.41, 376.97]], "batb": [[0, 1.41, 566.07]], "batl": [[0, 1.45, 324.29], [1, 1.46, 312.06], [2, 1.69, 5]]}, {"timestamp": 1631447908328, "ltp": 1.41, "tv": 5477.33, "trd": NaN, "batb": NaN, "batl": [[2, 1.49, 144.6]]}, {"timestamp": 1631447909341, "ltp": 1.41, "tv": 5477.33, "trd": NaN, "batb": NaN, "batl": [[2, 1.68, 4]]}, {"timestamp": 1631447911574, "ltp": 1.41, "tv": 5582.53, "trd": [[1.41, 482.17]], "batb": [[0, 1.41, 513.47]], "batl": NaN}, {"timestamp": 1631447913774, "ltp": 1.41, "tv": 5582.53, "trd": NaN, "batb": NaN, "batl": [[2, 1.53, 22.5]]}, {"timestamp": 1631447914832, "ltp": 1.41, "tv": 5582.53, "trd": NaN, "batb": [[0, 1.41, 557.57]], "batl": NaN}, {"timestamp": 1631447923365, "ltp": 1.41, "tv": 5582.53, "trd": NaN, "batb": NaN, "batl": [[0, 1.43, 1.71], [1, 1.45, 324.29], [2, 1.46, 312.06]]}, {"timestamp": 1631447932298, "ltp": 1.41, "tv": 5582.53, "trd": NaN, "batb": [[0, 1.2, 385.63], [1, 1.17, 314.09], [2, 1.1, 296.65]], "batl": [[1, 1.68, 4], [2, 1.85, 884.12]]}, {"timestamp": 1631447935477, "ltp": 1.41, "tv": 5582.53, "trd": NaN, "batb": [[0, 1.36, 295.17], [1, 1.35, 451.95], [2, 1.2, 385.63]], "batl": [[1, 1.55, 360.74], [2, 1.56, 240.39]]}, {"timestamp": 1631447936007, "ltp": 1.41, "tv": 5582.53, "trd": NaN, "batb": [[0, 1.36, 331.1], [2, 1.33, 38.53]], "batl": NaN}, {"timestamp": 1631447937193, "ltp": 1.41, "tv": 5582.53, "trd": NaN, "batb": [[0, 1.33, 38.53], [1, 1.2, 385.63], [2, 1.17, 314.09]], "batl": [[1, 1.57, 21.5], [2, 1.68, 4]]}, {"timestamp": 1631447938410, "ltp": 1.41, "tv": 5582.53, "trd": NaN, "batb": NaN, "batl": [[1, 1.44, 22.33], [2, 1.57, 21.5]]}, {"timestamp": 1631447939571, "ltp": 1.41, "tv": 5582.53, "trd": NaN, "batb": NaN, "batl": [[1, 1.57, 21.5], [2, 1.68, 4]]}, {"timestamp": 1631447941719, "ltp": 1.43, "tv": 5585.95, "trd": [[1.43, 3.42]], "batb": [[0, 1.43, 415.3], [1, 1.42, 358.31], [2, 1.33, 38.53]], "batl": [[0, 1.47, 387.79], [1, 1.48, 294.91], [2, 1.57, 21.5]]}, {"timestamp": 1631447942792, "ltp": 1.43, "tv": 5585.95, "trd": NaN, "batb": NaN, "batl": [[2, 1.52, 25.01]]}, {"timestamp": 1631447944014, "ltp": 1.43, "tv": 5585.95, "trd": NaN, "batb": [[2, 1.36, 37.18]], "batl": NaN}, {"timestamp": 1631447946180, "ltp": 1.43, "tv": 5585.95, "trd": NaN, "batb": [[0, 1.33, 38.53], [1, 1.2, 385.63], [2, 1.17, 314.09]], "batl": [[0, 1.57, 21.5], [1, 1.68, 4], [2, 1.85, 884.12]]}, {"timestamp": 1631447949497, "ltp": 1.43, "tv": 5585.95, "trd": NaN, "batb": [[0, 1.36, 330.84], [1, 1.35, 451.95], [2, 1.33, 38.53]], "batl": [[0, 1.52, 24.76], [1, 1.55, 361.41], [2, 1.56, 245.39]]}, {"timestamp": 1631447949822, "ltp": 1.43, "tv": 5585.95, "trd": NaN, "batb": NaN, "batl": [[0, 1.55, 361.41], [1, 1.56, 245.39], [2, 1.57, 21.5]]}, {"timestamp": 1631447954526, "ltp": 1.43, "tv": 5585.95, "trd": NaN, "batb": [[0, 1.33, 38.53], [1, 1.2, 385.63], [2, 1.17, 314.09]], "batl": NaN}, {"timestamp": 1631447957508, "ltp": 1.43, "tv": 5585.95, "trd": NaN, "batb": [[0, 1.51, 210.52], [1, 1.5, 320.18], [2, 1.39, 14]], "batl": [[0, 1.55, 368.41], [1, 1.56, 240.39]]}, {"timestamp": 1631447957719, "ltp": 1.43, "tv": 5585.95, "trd": NaN, "batb": [[2, 1.39, 7]], "batl": [[0, 1.55, 361.41]]}, {"timestamp": 1631447959415, "ltp": 1.43, "tv": 5585.95, "trd": NaN, "batb": [[2, 1.41, 159.07]], "batl": [[0, 1.55, 400.57]]}, {"timestamp": 1631447962271, "ltp": 1.51, "tv": 5660.51, "trd": [[1.51, 74.56]], "batb": [[0, 1.51, 173.24]], "batl": NaN}, {"timestamp": 1631447963588, "ltp": 1.51, "tv": 5660.51, "trd": NaN, "batb": [[0, 1.5, 320.18], [1, 1.41, 159.07], [2, 1.39, 7]], "batl": NaN}, {"timestamp": 1631447965431, "ltp": 1.51, "tv": 5660.51, "trd": NaN, "batb": [[1, 1.41, 190.96]], "batl": NaN}, {"timestamp": 1631447965999, "ltp": 1.51, "tv": 5660.51, "trd": NaN, "batb": [[0, 1.5, 515.64], [1, 1.49, 292.42], [2, 1.41, 190.96]], "batl": NaN}, {"timestamp": 1631447969436, "ltp": 1.51, "tv": 5660.51, "trd": NaN, "batb": [[0, 1.5, 478.28]], "batl": NaN}, {"timestamp": 1631447970377, "ltp": 1.55, "tv": 5668.22, "trd": [[1.55, 48.08]], "batb": NaN, "batl": [[0, 1.55, 392.86]]}, {"timestamp": 1631447976458, "ltp": 1.55, "tv": 5668.22, "trd": NaN, "batb": [[0, 1.41, 31.89], [1, 1.39, 7], [2, 1.35, 39.87]], "batl": [[0, 1.68, 4], [1, 1.7, 17.85], [2, 1.78, 16.25]]}, {"timestamp": 1631447976726, "ltp": 1.55, "tv": 5668.22, "trd": NaN, "batb": [[0, 1.35, 39.87], [1, 1.34, 9], [2, 1.25, 237.31]], "batl": [[1, 1.78, 16.25], [2, 1.85, 884.12]]}, {"timestamp": 1631447979458, "ltp": 1.55, "tv": 5668.22, "trd": NaN, "batb": [[0, 1.42, 369.44], [1, 1.41, 369.47], [2, 1.35, 39.87]], "batl": [[1, 1.7, 298.42], [2, 1.72, 342.64]]}, {"timestamp": 1631447979936, "ltp": 1.55, "tv": 5668.22, "trd": NaN, "batb": [[1, 1.41, 401.36], [2, 1.4, 4]], "batl": [[1, 1.7, 315.87]]}, {"timestamp": 1631447996350, "ltp": 1.55, "tv": 5668.22, "trd": NaN, "batb": [[0, 1.41, 31.89], [1, 1.4, 4], [2, 1.39, 3]], "batl": NaN}, {"timestamp": 1631447997354, "ltp": 1.55, "tv": 5668.22, "trd": NaN, "batb": [[0, 1.4, 4], [1, 1.35, 39.87], [2, 1.25, 237.31]], "batl": NaN}, {"timestamp": 1631447999548, "ltp": 1.55, "tv": 5668.22, "trd": NaN, "batb": [[0, 1.65, 207.24], [1, 1.64, 201.41], [2, 1.56, 12]], "batl": [[0, 1.7, 315.87], [1, 1.72, 342.64], [2, 1.78, 16.25]]}, {"timestamp": 1631448000535, "ltp": 1.55, "tv": 5668.22, "trd": NaN, "batb": [[2, 1.56, 6]], "batl": NaN}, {"timestamp": 1631448002589, "ltp": 1.55, "tv": 5668.22, "trd": NaN, "batb": NaN, "batl": [[0, 1.7, 298.42]]}, {"timestamp": 1631448003464, "ltp": 1.65, "tv": 5721.58, "trd": [[1.65, 63.36]], "batb": [[0, 1.65, 180.56]], "batl": [[0, 1.7, 327.56]]}, {"timestamp": 1631448004552, "ltp": 1.65, "tv": 5721.58, "trd": NaN, "batb": [[0, 1.66, 10.44], [1, 1.65, 180.56], [2, 1.64, 201.41]], "batl": NaN}, {"timestamp": 1631448008755, "ltp": 1.65, "tv": 5721.58, "trd": NaN, "batb": [[0, 1.66, 230.31]], "batl": NaN}, {"timestamp": 1631448018558, "ltp": 1.66, "tv": 5737.05, "trd": [[1.66, 31.49]], "batb": [[0, 1.66, 222.58]], "batl": NaN}, {"timestamp": 1631448025471, "ltp": 1.7, "tv": 5880.94, "trd": [[1.7, 401.89]], "batb": NaN, "batl": [[0, 1.7, 183.67]]}, {"timestamp": 1631448028521, "ltp": 1.7, "tv": 5880.94, "trd": NaN, "batb": [[1, 1.65, 258.44]], "batl": [[0, 1.7, 277.91]]}, {"timestamp": 1631448044586, "ltp": 1.7, "tv": 5880.94, "trd": NaN, "batb": [[0, 1.66, 219.88]], "batl": NaN}, {"timestamp": 1631448047597, "ltp": 1.7, "tv": 5880.94, "trd": NaN, "batb": NaN, "batl": [[0, 1.69, 7.6], [1, 1.7, 277.91], [2, 1.72, 342.64]]}, {"timestamp": 1631448065329, "ltp": 1.7, "tv": 6023.41, "trd": [[1.69, 7.6], [1.7, 536.76]], "batb": NaN, "batl": [[0, 1.7, 143.04], [1, 1.72, 342.64], [2, 1.78, 16.25]]}, {"timestamp": 1631448068569, "ltp": 1.66, "tv": 6029.41, "trd": [[1.66, 37.49]], "batb": [[0, 1.66, 216.88], [1, 1.65, 316.95]], "batl": [[0, 1.7, 221.17]]}, {"timestamp": 1631448089311, "ltp": 1.66, "tv": 6029.41, "trd": NaN, "batb": NaN, "batl": [[2, 1.74, 17.25]]}, {"timestamp": 1631448096824, "ltp": 1.66, "tv": 6029.41, "trd": NaN, "batb": NaN, "batl": [[0, 1.7, 192.03]]}, {"timestamp": 1631448098475, "ltp": 1.66, "tv": 6029.41, "trd": NaN, "batb": [[1, 1.56, 6], [2, 1.55, 4.97]], "batl": [[0, 1.74, 17.25], [1, 1.77, 17.5], [2, 1.94, 8.68]]}, {"timestamp": 1631448099013, "ltp": 1.66, "tv": 6029.41, "trd": NaN, "batb": [[0, 1.55, 4.97], [1, 1.53, 21.33], [2, 1.46, 29.88]], "batl": [[0, 1.77, 17.5], [1, 1.94, 8.68], [2, 8.8, 7.23]]}, {"timestamp": 1631448101410, "ltp": 1.66, "tv": 6029.41, "trd": NaN, "batb": [[0, 1.56, 332.5], [1, 1.55, 253.54], [2, 1.53, 21.33]], "batl": [[1, 1.79, 270.02], [2, 1.81, 289.59]]}, {"timestamp": 1631448111533, "ltp": 1.66, "tv": 6029.41, "trd": NaN, "batb": [[0, 1.55, 4.97], [1, 1.53, 21.33], [2, 1.46, 29.88]], "batl": NaN}, {"timestamp": 1631448112544, "ltp": 1.66, "tv": 6029.41, "trd": NaN, "batb": [[0, 1.73, 7.69], [1, 1.68, 731.06], [2, 1.55, 4.97]], "batl": NaN}, {"timestamp": 1631448114527, "ltp": 1.66, "tv": 6029.41, "trd": NaN, "batb": [[0, 1.73, 278.19], [1, 1.71, 345.53], [2, 1.68, 731.06]], "batl": NaN}, {"timestamp": 1631448115439, "ltp": 1.77, "tv": 6053.41, "trd": [[1.77, 28]], "batb": [[2, 1.55, 4.97]], "batl": [[0, 1.77, 5.5]]}, {"timestamp": 1631448117320, "ltp": 1.77, "tv": 6053.41, "trd": NaN, "batb": [[2, 1.69, 9.98]], "batl": NaN}, {"timestamp": 1631448119454, "ltp": 1.73, "tv": 6062.69, "trd": [[1.73, 3.98], [1.75, 8.96]], "batb": [[0, 1.73, 276.2]], "batl": NaN}, {"timestamp": 1631448123263, "ltp": 1.73, "tv": 6062.69, "trd": NaN, "batb": [[0, 1.74, 219.88], [1, 1.73, 276.2], [2, 1.71, 345.53]], "batl": NaN}, {"timestamp": 1631448124854, "ltp": 1.73, "tv": 6062.69, "trd": NaN, "batb": [[0, 1.74, 229.18]], "batl": NaN}, {"timestamp": 1631448128481, "ltp": 1.77, "tv": 6073.69, "trd": [[1.77, 39]], "batb": [[0, 1.77, 30.56], [1, 1.74, 229.18], [2, 1.73, 276.2]], "batl": [[0, 1.79, 270.02], [1, 1.81, 289.59], [2, 1.82, 15.75]]}, {"timestamp": 1631448132460, "ltp": 1.77, "tv": 6073.69, "trd": NaN, "batb": NaN, "batl": [[0, 1.79, 298.89]]}, {"timestamp": 1631448135357, "ltp": 1.77, "tv": 6073.69, "trd": NaN, "batb": [[2, 1.73, 5.7]], "batl": [[0, 1.87, 17.5], [1, 1.94, 8.68], [2, 2.26, 617.9]]}, {"timestamp": 1631448136286, "ltp": 1.77, "tv": 6073.69, "trd": NaN, "batb": [[1, 1.74, 219.88]], "batl": NaN}, {"timestamp": 1631448137070, "ltp": 1.77, "tv": 6073.69, "trd": NaN, "batb": [[1, 1.73, 5.7], [2, 1.57, 19.57]], "batl": NaN}, {"timestamp": 1631448138571, "ltp": 1.77, "tv": 6073.69, "trd": NaN, "batb": [[2, 1.64, 268.69]], "batl": [[0, 1.84, 16.53], [1, 1.87, 244.18], [2, 1.89, 252.88]]}, {"timestamp": 1631448139495, "ltp": 1.77, "tv": 6073.69, "trd": NaN, "batb": [[2, 1.57, 19.57]], "batl": [[0, 1.87, 244.18], [1, 1.89, 252.88], [2, 1.94, 8.68]]}, {"timestamp": 1631448140283, "ltp": 1.77, "tv": 6073.69, "trd": NaN, "batb": [[0, 1.8, 731.06], [1, 1.77, 30.56], [2, 1.73, 5.7]], "batl": NaN}, {"timestamp": 1631448141521, "ltp": 1.77, "tv": 6073.69, "trd": NaN, "batb": NaN, "batl": [[0, 1.87, 239.18]]}, {"timestamp": 1631448142589, "ltp": 1.77, "tv": 6073.69, "trd": NaN, "batb": [[0, 1.81, 208.89], [1, 1.8, 743.06], [2, 1.79, 296.16]], "batl": NaN}, {"timestamp": 1631448143302, "ltp": 1.77, "tv": 6073.69, "trd": NaN, "batb": [[1, 1.8, 737.06]], "batl": NaN}, {"timestamp": 1631448145387, "ltp": 1.77, "tv": 6073.69, "trd": NaN, "batb": [[0, 1.81, 217.39]], "batl": NaN}, {"timestamp": 1631448148721, "ltp": 1.77, "tv": 6073.69, "trd": NaN, "batb": [[1, 1.8, 6]], "batl": [[1, 1.88, 14.29], [2, 1.89, 252.88]]}, {"timestamp": 1631448149701, "ltp": 1.77, "tv": 6073.69, "trd": NaN, "batb": [[0, 1.83, 219.88], [1, 1.81, 217.39], [2, 1.8, 6]], "batl": NaN}, {"timestamp": 1631448153720, "ltp": 1.77, "tv": 6073.69, "trd": NaN, "batb": NaN, "batl": [[2, 1.89, 267.38]]}, {"timestamp": 1631448161565, "ltp": 1.77, "tv": 6073.69, "trd": NaN, "batb": [[1, 1.81, 208.89], [2, 1.79, 296.16]], "batl": [[0, 1.87, 221.68], [1, 1.89, 267.38], [2, 1.91, 14.5]]}, {"timestamp": 1631448162273, "ltp": 1.77, "tv": 6073.69, "trd": NaN, "batb": [[1, 1.77, 30.56], [2, 1.73, 21.83]], "batl": [[0, 1.91, 14.5], [1, 1.94, 8.68], [2, 2.26, 617.9]]}, {"timestamp": 1631448163187, "ltp": 1.77, "tv": 6073.69, "trd": NaN, "batb": [[0, 1.77, 30.56], [1, 1.73, 5.7], [2, 1.67, 18.47]], "batl": NaN}, {"timestamp": 1631448164089, "ltp": 1.77, "tv": 6073.69, "trd": NaN, "batb": [[2, 1.69, 9.98]], "batl": NaN}, {"timestamp": 1631448165492, "ltp": 1.77, "tv": 6073.69, "trd": NaN, "batb": NaN, "batl": [[0, 1.89, 14.5], [1, 1.91, 19.5], [2, 1.94, 8.68]]}, {"timestamp": 1631448166458, "ltp": 1.77, "tv": 6073.69, "trd": NaN, "batb": [[0, 1.78, 8.83], [1, 1.77, 30.56], [2, 1.73, 22.83]], "batl": [[0, 1.91, 19.5], [1, 1.94, 8.68], [2, 2.26, 617.9]]}, {"timestamp": 1631448167588, "ltp": 1.77, "tv": 6073.69, "trd": NaN, "batb": [[2, 1.73, 5.7]], "batl": [[0, 1.89, 4], [1, 1.91, 19.5], [2, 1.94, 8.68]]}, {"timestamp": 1631448168396, "ltp": 1.77, "tv": 6073.69, "trd": NaN, "batb": NaN, "batl": [[0, 1.91, 19.5], [1, 1.94, 8.68], [2, 2.26, 617.9]]}, {"timestamp": 1631448170298, "ltp": 1.77, "tv": 6073.69, "trd": NaN, "batb": [[0, 1.79, 266.63], [1, 1.78, 8.83], [2, 1.77, 338.08]], "batl": [[0, 1.85, 190.64], [1, 1.87, 261.45], [2, 1.9, 45.27]]}, {"timestamp": 1631448172499, "ltp": 1.77, "tv": 6073.69, "trd": NaN, "batb": NaN, "batl": [[2, 1.89, 15.5]]}, {"timestamp": 1631448174006, "ltp": 1.77, "tv": 6073.69, "trd": NaN, "batb": [[0, 1.78, 8.83], [1, 1.77, 30.56], [2, 1.73, 5.7]], "batl": [[0, 1.91, 19.5], [1, 1.94, 8.68], [2, 2.26, 617.9]]}, {"timestamp": 1631448177592, "ltp": 1.77, "tv": 6073.69, "trd": NaN, "batb": [[0, 1.8, 8.61], [1, 1.78, 8.83], [2, 1.77, 30.56]], "batl": [[1, 1.94, 239], [2, 1.96, 226.32]]}, {"timestamp": 1631448180590, "ltp": 1.77, "tv": 6073.69, "trd": NaN, "batb": [[0, 1.77, 30.56], [1, 1.73, 265.53], [2, 1.71, 345.44]], "batl": NaN}, {"timestamp": 1631448186614, "ltp": 1.91, "tv": 6073.71, "trd": [[1.91, 0.02]], "batb": NaN, "batl": [[0, 1.91, 19.49]]}, {"timestamp": 1631448191386, "ltp": 1.91, "tv": 6073.71, "trd": NaN, "batb": NaN, "batl": [[0, 1.89, 15.5], [1, 1.91, 19.49], [2, 1.94, 239]]}, {"timestamp": 1631448191714, "ltp": 1.91, "tv": 6073.71, "trd": NaN, "batb": NaN, "batl": [[0, 1.91, 19.49], [1, 1.94, 239], [2, 1.96, 226.32]]}, {"timestamp": 1631448193432, "ltp": 1.91, "tv": 6073.71, "trd": NaN, "batb": [[1, 1.74, 9.31], [2, 1.73, 265.53]], "batl": NaN}, {"timestamp": 1631448194338, "ltp": 1.91, "tv": 6073.71, "trd": NaN, "batb": NaN, "batl": [[1, 1.94, 8.68], [2, 2.26, 617.9]]}, {"timestamp": 1631448195512, "ltp": 1.91, "tv": 6073.71, "trd": NaN, "batb": NaN, "batl": [[0, 1.82, 731.06], [1, 1.91, 19.49], [2, 1.94, 8.68]]}, {"timestamp": 1631448196000, "ltp": 1.91, "tv": 6073.71, "trd": NaN, "batb": [[2, 1.73, 259.83]], "batl": NaN}, {"timestamp": 1631448197594, "ltp": 1.91, "tv": 6073.71, "trd": NaN, "batb": [[1, 1.73, 259.83], [2, 1.71, 345.44]], "batl": [[0, 1.79, 296.63], [1, 1.81, 289.52], [2, 1.82, 731.06]]}, {"timestamp": 1631448199201, "ltp": 1.91, "tv": 6073.71, "trd": NaN, "batb": NaN, "batl": [[1, 1.81, 319.05], [2, 1.84, 5]]}, {"timestamp": 1631448206828, "ltp": 1.79, "tv": 6173.71, "trd": [[1.79, 124.34]], "batb": NaN, "batl": [[0, 1.79, 246.63]]}, {"timestamp": 1631448207737, "ltp": 1.79, "tv": 6173.71, "trd": NaN, "batb": [[1, 1.75, 219.88], [2, 1.73, 259.83]], "batl": NaN}, {"timestamp": 1631448210520, "ltp": 1.79, "tv": 6173.71, "trd": NaN, "batb": NaN, "batl": [[0, 1.79, 275.59]]}, {"timestamp": 1631448213151, "ltp": 1.77, "tv": 6183.71, "trd": [[1.77, 49]], "batb": [[0, 1.77, 25.56]], "batl": NaN}, {"timestamp": 1631448222550, "ltp": 1.77, "tv": 6183.71, "trd": NaN, "batb": [[2, 1.67, 18.47]], "batl": [[0, 1.84, 5], [1, 1.85, 14.3], [2, 1.89, 15.5]]}, {"timestamp": 1631448223160, "ltp": 1.77, "tv": 6183.71, "trd": NaN, "batb": NaN, "batl": [[0, 1.89, 15.5], [1, 1.91, 5], [2, 1.94, 8.68]]}, {"timestamp": 1631448225454, "ltp": 1.77, "tv": 6183.71, "trd": NaN, "batb": [[1, 1.63, 232.26], [2, 1.62, 232.79]], "batl": [[0, 1.88, 195.2], [1, 1.89, 15.5], [2, 1.9, 248.81]]}, {"timestamp": 1631448226474, "ltp": 1.77, "tv": 6183.71, "trd": NaN, "batb": NaN, "batl": [[0, 1.85, 16.5], [1, 1.88, 195.2], [2, 1.89, 19.5]]}, {"timestamp": 1631448226762, "ltp": 1.77, "tv": 6183.71, "trd": NaN, "batb": NaN, "batl": [[0, 1.88, 195.2], [1, 1.89, 19.5], [2, 1.9, 248.81]]}, {"timestamp": 1631448228640, "ltp": 1.77, "tv": 6183.71, "trd": NaN, "batb": NaN, "batl": [[0, 1.88, 200.2]]}, {"timestamp": 1631448231341, "ltp": 1.77, "tv": 6183.71, "trd": NaN, "batb": [[0, 1.87, 7.69], [1, 1.82, 731.06], [2, 1.77, 25.56]], "batl": NaN}, {"timestamp": 1631448231985, "ltp": 1.77, "tv": 6183.71, "trd": NaN, "batb": NaN, "batl": [[0, 1.88, 195.2], [1, 1.89, 15.5]]}, {"timestamp": 1631448233384, "ltp": 1.87, "tv": 6188.36, "trd": [[1.87, 9.65]], "batb": [[0, 1.87, 3.03], [2, 1.81, 6.87]], "batl": NaN}, {"timestamp": 1631448234570, "ltp": 1.87, "tv": 6188.36, "trd": NaN, "batb": [[0, 1.82, 955.23], [1, 1.8, 296.8], [2, 1.77, 25.56]], "batl": NaN}, {"timestamp": 1631448236568, "ltp": 1.87, "tv": 6188.36, "trd": NaN, "batb": [[0, 1.82, 224.17]], "batl": NaN}, {"timestamp": 1631448237210, "ltp": 1.87, "tv": 6188.36, "trd": NaN, "batb": [[0, 1.82, 254.04]], "batl": NaN}, {"timestamp": 1631448239796, "ltp": 1.87, "tv": 6188.36, "trd": NaN, "batb": [[2, 1.79, 18.31]], "batl": NaN}, {"timestamp": 1631448241903, "ltp": 1.87, "tv": 6188.36, "trd": NaN, "batb": [[0, 1.83, 219.88], [1, 1.82, 254.04], [2, 1.8, 296.8]], "batl": NaN}, {"timestamp": 1631448255417, "ltp": 1.87, "tv": 6188.36, "trd": NaN, "batb": [[1, 1.79, 18.31], [2, 1.77, 25.56]], "batl": [[0, 1.89, 15.5], [1, 1.92, 13.06], [2, 1.94, 8.68]]}, {"timestamp": 1631448255749, "ltp": 1.87, "tv": 6188.36, "trd": NaN, "batb": NaN, "batl": [[0, 1.92, 13.06], [1, 1.94, 8.68], [2, 2.26, 617.9]]}, {"timestamp": 1631448258422, "ltp": 1.87, "tv": 6188.36, "trd": NaN, "batb": NaN, "batl": [[2, 1.95, 219.1]]}, {"timestamp": 1631448259233, "ltp": 1.87, "tv": 6188.36, "trd": NaN, "batb": [[0, 1.77, 25.56], [1, 1.76, 17.48], [2, 1.74, 285.94]], "batl": [[0, 1.92, 17.06]]}, {"timestamp": 1631448262540, "ltp": 1.87, "tv": 6188.36, "trd": NaN, "batb": [[0, 1.79, 14.31], [1, 1.78, 5], [2, 1.77, 29.56]], "batl": [[0, 1.89, 14.68], [1, 1.92, 17.06], [2, 1.94, 8.68]]}, {"timestamp": 1631448262810, "ltp": 1.87, "tv": 6188.36, "trd": NaN, "batb": [[0, 1.78, 5], [1, 1.77, 29.56], [2, 1.76, 22.48]], "batl": [[0, 1.92, 17.06], [1, 1.94, 8.68], [2, 1.95, 219.1]]}, {"timestamp": 1631448264337, "ltp": 1.87, "tv": 6188.36, "trd": NaN, "batb": [[0, 1.78, 13.83]], "batl": [[2, 2.26, 617.9]]}, {"timestamp": 1631448265448, "ltp": 1.87, "tv": 6188.36, "trd": NaN, "batb": NaN, "batl": [[0, 1.84, 1137.59], [1, 1.92, 17.06], [2, 1.94, 8.68]]}, {"timestamp": 1631448266356, "ltp": 1.87, "tv": 6188.36, "trd": NaN, "batb": [[0, 1.77, 25.56], [1, 1.76, 17.48], [2, 1.74, 285.94]], "batl": [[1, 1.89, 12.5], [2, 1.92, 17.06]]}, {"timestamp": 1631448267539, "ltp": 1.87, "tv": 6188.36, "trd": NaN, "batb": NaN, "batl": [[0, 1.8, 240.2], [1, 1.82, 284.6], [2, 1.84, 1137.59]]}, {"timestamp": 1631448269329, "ltp": 1.87, "tv": 6188.36, "trd": NaN, "batb": NaN, "batl": [[2, 1.83, 4]]}, {"timestamp": 1631448285582, "ltp": 1.8, "tv": 6365.94, "trd": [[1.8, 319.56]], "batb": [[1, 1.68, 16.61], [2, 1.63, 18.23]], "batl": [[0, 1.85, 5], [1, 1.93, 14.64], [2, 1.94, 8.68]]}, {"timestamp": 1631448285853, "ltp": 1.8, "tv": 6365.94, "trd": NaN, "batb": NaN, "batl": [[0, 1.93, 14.64], [1, 1.94, 8.68], [2, 2.26, 617.9]]}, {"timestamp": 1631448289169, "ltp": 1.8, "tv": 6365.94, "trd": NaN, "batb": NaN, "batl": [[0, 1.88, 13.04], [1, 1.9, 4], [2, 1.91, 4]]}, {"timestamp": 1631448290234, "ltp": 1.8, "tv": 6365.94, "trd": NaN, "batb": NaN, "batl": [[0, 1.9, 4], [1, 1.91, 4], [2, 1.92, 223.83]]}, {"timestamp": 1631448295242, "ltp": 1.8, "tv": 6365.94, "trd": NaN, "batb": [[2, 1.64, 10.76]], "batl": NaN}, {"timestamp": 1631448296550, "ltp": 1.77, "tv": 6386.88, "trd": [[1.77, 69.94]], "batb": [[0, 1.77, 15.09]], "batl": [[0, 1.88, 12.79], [1, 1.9, 4], [2, 1.91, 4]]}, {"timestamp": 1631448296878, "ltp": 1.77, "tv": 6386.88, "trd": NaN, "batb": NaN, "batl": [[0, 1.9, 4], [1, 1.91, 4], [2, 1.92, 223.83]]}, {"timestamp": 1631448303896, "ltp": 1.77, "tv": 6386.88, "trd": NaN, "batb": NaN, "batl": [[1, 1.92, 223.83], [2, 1.93, 14.64]]}, {"timestamp": 1631448307390, "ltp": 1.77, "tv": 6386.88, "trd": NaN, "batb": NaN, "batl": [[1, 1.93, 14.64], [2, 1.94, 8.68]]}, {"timestamp": 1631448308414, "ltp": 1.77, "tv": 6417.06, "trd": [[1.77, 100.12]], "batb": [[0, 1.64, 10.76], [1, 1.63, 18.23], [2, 1.62, 398.9]], "batl": [[0, 1.7, 715.97], [1, 1.73, 406.52], [2, 1.9, 4]]}, {"timestamp": 1631448309100, "ltp": 1.77, "tv": 6417.06, "trd": NaN, "batb": [[0, 1.63, 18.23], [1, 1.62, 398.9], [2, 1.61, 215.37]], "batl": NaN}, {"timestamp": 1631448310399, "ltp": 1.77, "tv": 6417.06, "trd": NaN, "batb": NaN, "batl": [[0, 1.68, 348.37], [1, 1.7, 1071.04]]}, {"timestamp": 1631448311485, "ltp": 1.77, "tv": 6417.06, "trd": NaN, "batb": NaN, "batl": [[1, 1.69, 50.89], [2, 1.7, 1071.04]]}, {"timestamp": 1631448312506, "ltp": 1.77, "tv": 6417.06, "trd": NaN, "batb": NaN, "batl": [[1, 1.7, 1071.04], [2, 1.77, 6]]}, {"timestamp": 1631448313513, "ltp": 1.77, "tv": 6417.06, "trd": NaN, "batb": NaN, "batl": [[1, 1.69, 6], [2, 1.7, 1071.04]]}, {"timestamp": 1631448315221, "ltp": 1.63, "tv": 6424.76, "trd": [[1.63, 7.7]], "batb": [[0, 1.63, 14.38]], "batl": [[0, 1.67, 50.89], [1, 1.68, 348.37], [2, 1.69, 6]]}, {"timestamp": 1631448320036, "ltp": 1.63, "tv": 6424.76, "trd": NaN, "batb": [[0, 1.64, 219.88], [1, 1.63, 14.38], [2, 1.62, 398.9]], "batl": NaN}, {"timestamp": 1631448332955, "ltp": 1.67, "tv": 6432.6, "trd": [[1.67, 310.95]], "batb": NaN, "batl": [[0, 1.67, 43.05]]}, {"timestamp": 1631448336542, "ltp": 1.67, "tv": 6432.6, "trd": NaN, "batb": [[1, 1.51, 25.99], [2, 1.5, 28.1]], "batl": [[0, 1.77, 6], [1, 1.78, 22.5], [2, 1.79, 22.19]]}, {"timestamp": 1631448337349, "ltp": 1.64, "tv": 6436.02, "trd": [[1.64, 3.42]], "batb": [[0, 1.64, 218.17]], "batl": [[1, 1.84, 15.78], [2, 1.94, 8.68]]}, {"timestamp": 1631448339436, "ltp": 1.64, "tv": 6436.02, "trd": NaN, "batb": [[0, 1.5, 339.99], [1, 1.49, 290.19], [2, 1.44, 28.67]], "batl": [[1, 1.8, 257.92], [2, 1.82, 284.32]]}, {"timestamp": 1631448340415, "ltp": 1.64, "tv": 6436.02, "trd": NaN, "batb": NaN, "batl": [[1, 1.78, 16.25], [2, 1.8, 257.92]]}, {"timestamp": 1631448341564, "ltp": 1.64, "tv": 6436.02, "trd": NaN, "batb": [[0, 1.44, 28.67], [1, 1.4, 4], [2, 1.3, 197.76]], "batl": [[1, 1.84, 21.81], [2, 1.94, 8.68]]}, {"timestamp": 1631448342521, "ltp": 1.64, "tv": 6436.02, "trd": NaN, "batb": [[0, 1.44, 34.67], [1, 1.43, 6], [2, 1.4, 4]], "batl": [[1, 1.84, 15.78]]}, {"timestamp": 1631448343543, "ltp": 1.64, "tv": 6436.02, "trd": NaN, "batb": [[0, 1.49, 6], [1, 1.44, 34.67], [2, 1.43, 6]], "batl": [[0, 1.67, 19.5], [1, 1.77, 6], [2, 1.78, 6.25]]}, {"timestamp": 1631448344530, "ltp": 1.64, "tv": 6436.02, "trd": NaN, "batb": [[0, 1.6, 263.51], [1, 1.59, 225.11], [2, 1.49, 6]], "batl": [[0, 1.65, 332.05], [1, 1.66, 191.56], [2, 1.77, 6]]}, {"timestamp": 1631448345871, "ltp": 1.64, "tv": 6436.02, "trd": NaN, "batb": [[2, 1.51, 25.99]], "batl": NaN}, {"timestamp": 1631448348327, "ltp": 1.64, "tv": 6436.02, "trd": NaN, "batb": NaN, "batl": [[0, 1.64, 34.64], [1, 1.65, 332.05], [2, 1.66, 191.56]]}, {"timestamp": 1631448351252, "ltp": 1.64, "tv": 6436.02, "trd": NaN, "batb": [[0, 1.49, 6], [1, 1.48, 6], [2, 1.44, 34.67]], "batl": [[0, 1.84, 15.78], [1, 1.94, 8.68], [2, 2.12, 662.18]]}, {"timestamp": 1631448354566, "ltp": 1.64, "tv": 6436.02, "trd": NaN, "batb": [[0, 1.51, 23.99], [1, 1.5, 339.99], [2, 1.49, 296.19]], "batl": [[0, 1.78, 23.5], [1, 1.8, 257.92], [2, 1.82, 284.32]]}, {"timestamp": 1631448355055, "ltp": 1.64, "tv": 6436.02, "trd": NaN, "batb": [[0, 1.5, 339.99], [1, 1.49, 296.19], [2, 1.48, 6]], "batl": [[0, 1.6, 10]]}, {"timestamp": 1631448357485, "ltp": 1.64, "tv": 6436.02, "trd": NaN, "batb": [[0, 1.5, 344.99], [1, 1.49, 290.19], [2, 1.44, 28.67]], "batl": [[0, 1.54, 3416.1], [1, 1.6, 10], [2, 1.63, 55.51]]}, {"timestamp": 1631448358348, "ltp": 1.64, "tv": 6436.02, "trd": NaN, "batb": [[0, 1.51, 6], [1, 1.5, 344.99], [2, 1.49, 290.19]], "batl": NaN}, {"timestamp": 1631448360370, "ltp": 1.64, "tv": 6436.02, "trd": NaN, "batb": NaN, "batl": [[1, 1.63, 55.51], [2, 1.78, 23.5]]}, {"timestamp": 1631448360757, "ltp": 1.54, "tv": 6993.8, "trd": [[1.54, 736.32]], "batb": NaN, "batl": [[0, 1.54, 3137.21]]}, {"timestamp": 1631448364574, "ltp": 1.54, "tv": 6993.8, "trd": NaN, "batb": [[0, 1.52, 219.88], [1, 1.51, 6], [2, 1.5, 344.99]], "batl": [[1, 1.58, 731.06], [2, 1.63, 55.51]]}, {"timestamp": 1631448365428, "ltp": 1.54, "tv": 6993.8, "trd": NaN, "batb": [[1, 1.51, 32.99]], "batl": [[2, 1.59, 431.29]]}, {"timestamp": 1631448367330, "ltp": 1.54, "tv": 6993.8, "trd": NaN, "batb": [[0, 1.52, 226.88]], "batl": NaN}, {"timestamp": 1631448368377, "ltp": 1.54, "tv": 6993.8, "trd": NaN, "batb": NaN, "batl": [[1, 1.59, 431.29], [2, 1.63, 55.51]]}, {"timestamp": 1631448368697, "ltp": 1.54, "tv": 6993.8, "trd": NaN, "batb": NaN, "batl": [[1, 1.78, 23.5], [2, 1.8, 257.92]]}, {"timestamp": 1631448372102, "ltp": 1.52, "tv": 7010.88, "trd": [[1.52, 17.08]], "batb": [[0, 1.52, 218.34], [1, 1.51, 26.99], [2, 1.5, 339.99]], "batl": NaN}, {"timestamp": 1631448373009, "ltp": 1.52, "tv": 7010.88, "trd": NaN, "batb": [[2, 1.44, 28.67]], "batl": [[2, 1.84, 6.78]]}, {"timestamp": 1631448374506, "ltp": 1.52, "tv": 7010.88, "trd": NaN, "batb": [[0, 1.52, 211.34]], "batl": NaN}, {"timestamp": 1631448375584, "ltp": 1.52, "tv": 7010.88, "trd": NaN, "batb": NaN, "batl": [[1, 1.55, 5.7], [2, 1.78, 23.5]]}, {"timestamp": 1631448376484, "ltp": 1.52, "tv": 7010.88, "trd": NaN, "batb": [[2, 1.5, 339.99]], "batl": [[0, 1.54, 257.04], [1, 1.55, 251.45], [2, 1.61, 6]]}, {"timestamp": 1631448377181, "ltp": 1.52, "tv": 7024.65, "trd": [[1.52, 30.86]], "batb": [[0, 1.52, 204.45]], "batl": NaN}, {"timestamp": 1631448378532, "ltp": 1.52, "tv": 7024.65, "trd": NaN, "batb": NaN, "batl": [[0, 1.54, 299.54]]}, {"timestamp": 1631448379499, "ltp": 1.52, "tv": 7024.65, "trd": NaN, "batb": [[0, 1.5, 339.99], [1, 1.49, 290.19], [2, 1.44, 28.67]], "batl": [[0, 1.54, 257.04]]}, {"timestamp": 1631448380414, "ltp": 1.5, "tv": 7090.63, "trd": [[1.5, 645.84]], "batb": [[0, 1.5, 307]], "batl": NaN}, {"timestamp": 1631448381595, "ltp": 1.5, "tv": 7090.63, "trd": NaN, "batb": NaN, "batl": [[2, 1.57, 84.55]]}, {"timestamp": 1631448382437, "ltp": 1.5, "tv": 7090.63, "trd": NaN, "batb": [[0, 1.5, 511.45]], "batl": NaN}, {"timestamp": 1631448382800, "ltp": 1.5, "tv": 7090.63, "trd": NaN, "batb": NaN, "batl": [[0, 1.53, 42.5], [1, 1.54, 257.04], [2, 1.55, 251.45]]}, {"timestamp": 1631448385499, "ltp": 1.5, "tv": 7090.63, "trd": NaN, "batb": NaN, "batl": [[0, 1.52, 83.34], [1, 1.53, 42.5], [2, 1.54, 257.04]]}, {"timestamp": 1631448387393, "ltp": 1.5, "tv": 7090.63, "trd": NaN, "batb": [[0, 1.5, 204.45], [1, 1.29, 39.81], [2, 1.28, 51.16]], "batl": [[1, 1.55, 5.7], [2, 1.57, 84.55]]}, {"timestamp": 1631448388525, "ltp": 1.5, "tv": 7110.64, "trd": [[1.5, 665.84]], "batb": [[0, 1.5, 194.45], [1, 1.35, 37.67], [2, 1.29, 39.81]], "batl": NaN}, {"timestamp": 1631448390425, "ltp": 1.5, "tv": 7110.64, "trd": NaN, "batb": [[1, 1.37, 565.86], [2, 1.36, 471.98]], "batl": NaN}, {"timestamp": 1631448392638, "ltp": 1.5, "tv": 7110.64, "trd": NaN, "batb": NaN, "batl": [[0, 1.55, 5.7], [1, 1.57, 84.55], [2, 1.67, 288.12]]}, {"timestamp": 1631448393840, "ltp": 1.5, "tv": 7110.64, "trd": NaN, "batb": [[0, 1.37, 565.86], [1, 1.36, 471.98], [2, 1.35, 37.67]], "batl": NaN}, {"timestamp": 1631448395714, "ltp": 1.5, "tv": 7110.64, "trd": NaN, "batb": NaN, "batl": [[0, 1.5, 83.34], [1, 1.55, 5.7], [2, 1.57, 84.55]]}, {"timestamp": 1631448397444, "ltp": 1.5, "tv": 7110.64, "trd": NaN, "batb": [[0, 1.37, 570.86], [1, 1.36, 477.98]], "batl": [[0, 1.5, 152.23]]}, {"timestamp": 1631448399114, "ltp": 1.5, "tv": 7110.64, "trd": NaN, "batb": NaN, "batl": [[0, 1.5, 156.13]]}, {"timestamp": 1631448400562, "ltp": 1.5, "tv": 7110.64, "trd": NaN, "batb": NaN, "batl": [[0, 1.5, 72.79]]}, {"timestamp": 1631448401472, "ltp": 1.5, "tv": 7110.64, "trd": NaN, "batb": NaN, "batl": [[0, 1.5, 3.9]]}, {"timestamp": 1631448402977, "ltp": 1.5, "tv": 7110.64, "trd": NaN, "batb": NaN, "batl": [[1, 1.57, 84.55], [2, 1.67, 288.12]]}, {"timestamp": 1631448405186, "ltp": 1.5, "tv": 7110.64, "trd": NaN, "batb": NaN, "batl": [[0, 1.57, 84.55], [1, 1.67, 288.12], [2, 1.69, 362.9]]}, {"timestamp": 1631448406575, "ltp": 1.5, "tv": 7110.64, "trd": NaN, "batb": NaN, "batl": [[0, 1.44, 731.06], [1, 1.57, 84.55], [2, 1.67, 7.5]]}, {"timestamp": 1631448407486, "ltp": 1.5, "tv": 7110.64, "trd": NaN, "batb": NaN, "batl": [[0, 1.41, 3950.12], [1, 1.44, 731.06], [2, 1.45, 431.29]]}, {"timestamp": 1631448407659, "ltp": 1.5, "tv": 7110.64, "trd": NaN, "batb": NaN, "batl": [[0, 1.44, 731.06], [1, 1.45, 431.29], [2, 1.57, 84.55]]}, {"timestamp": 1631448409456, "ltp": 1.5, "tv": 7110.64, "trd": NaN, "batb": [[0, 1.37, 565.86], [1, 1.36, 471.98]], "batl": [[0, 1.41, 477.42], [1, 1.42, 354.59], [2, 1.44, 731.06]]}, {"timestamp": 1631448412354, "ltp": 1.37, "tv": 7277.32, "trd": [[1.37, 190.65]], "batb": [[0, 1.37, 482.52]], "batl": [[2, 1.67, 7.5]]}, {"timestamp": 1631448414276, "ltp": 1.37, "tv": 7377.82, "trd": [[1.37, 291.15]], "batb": [[0, 1.37, 432.27]], "batl": [[0, 1.4, 101.69], [1, 1.41, 477.42], [2, 1.42, 354.59]]}, {"timestamp": 1631448415570, "ltp": 1.37, "tv": 7377.82, "trd": NaN, "batb": [[0, 1.37, 479.36]], "batl": [[0, 1.4, 41.34]]}, {"timestamp": 1631448417354, "ltp": 1.37, "tv": 7381.82, "trd": [[1.37, 295.15]], "batb": [[0, 1.37, 477.36]], "batl": [[1, 1.41, 532.09]]}, {"timestamp": 1631448419986, "ltp": 1.37, "tv": 7657.36, "trd": [[1.37, 570.69]], "batb": [[0, 1.37, 339.59]], "batl": NaN}, {"timestamp": 1631448421482, "ltp": 1.37, "tv": 7657.36, "trd": NaN, "batb": NaN, "batl": [[1, 1.41, 362.4], [2, 1.42, 7]]}, {"timestamp": 1631448422500, "ltp": 1.37, "tv": 7657.36, "trd": NaN, "batb": NaN, "batl": [[0, 1.39, 29.02], [1, 1.4, 41.34], [2, 1.41, 362.4]]}, {"timestamp": 1631448424303, "ltp": 1.37, "tv": 7657.36, "trd": NaN, "batb": [[0, 1.37, 445.35]], "batl": NaN}, {"timestamp": 1631448426828, "ltp": 1.37, "tv": 7657.36, "trd": NaN, "batb": NaN, "batl": [[2, 1.41, 559.15]]}, {"timestamp": 1631448432516, "ltp": 1.39, "tv": 7682.9, "trd": [[1.39, 196.89]], "batb": NaN, "batl": [[0, 1.39, 3.48]]}, {"timestamp": 1631448436089, "ltp": 1.39, "tv": 7682.9, "trd": NaN, "batb": [[0, 1.38, 427.02], [1, 1.37, 445.35], [2, 1.36, 471.98]], "batl": NaN}, {"timestamp": 1631448444712, "ltp": 1.38, "tv": 7688.19, "trd": [[1.38, 6.14]], "batb": [[0, 1.38, 421.74]], "batl": NaN}, {"timestamp": 1631448447448, "ltp": 1.38, "tv": 7688.19, "trd": NaN, "batb": [[1, 1.35, 37.67], [2, 1.34, 37.22]], "batl": [[1, 1.64, 33.04], [2, 1.67, 7.5]]}, {"timestamp": 1631448449554, "ltp": 1.38, "tv": 7688.19, "trd": NaN, "batb": NaN, "batl": [[1, 1.47, 361.19], [2, 1.48, 293.93]]}, {"timestamp": 1631448450527, "ltp": 1.38, "tv": 7688.19, "trd": NaN, "batb": NaN, "batl": [[1, 1.47, 389.69]]}, {"timestamp": 1631448454167, "ltp": 1.38, "tv": 7688.19, "trd": NaN, "batb": NaN, "batl": [[1, 1.51, 22.5], [2, 1.52, 6.89]]}, {"timestamp": 1631448454967, "ltp": 1.38, "tv": 7688.19, "trd": NaN, "batb": [[0, 1.33, 582.26], [1, 1.32, 547.95], [2, 1.29, 39.81]], "batl": NaN}, {"timestamp": 1631448456434, "ltp": 1.38, "tv": 7688.19, "trd": NaN, "batb": NaN, "batl": [[0, 1.36, 431.29], [1, 1.38, 731.06], [2, 1.39, 3.48]]}, {"timestamp": 1631448457568, "ltp": 1.38, "tv": 7688.19, "trd": NaN, "batb": NaN, "batl": [[0, 1.36, 733.81], [1, 1.37, 411.88], [2, 1.38, 731.06]]}, {"timestamp": 1631448458533, "ltp": 1.35, "tv": 7692.19, "trd": [[1.35, 4.82]], "batb": NaN, "batl": [[2, 1.38, 748.46]]}, {"timestamp": 1631448459057, "ltp": 1.35, "tv": 7692.19, "trd": NaN, "batb": NaN, "batl": [[1, 1.37, 418.77], [2, 1.38, 731.06]]}, {"timestamp": 1631448460567, "ltp": 1.35, "tv": 7692.19, "trd": NaN, "batb": NaN, "batl": [[1, 1.37, 411.88], [2, 1.38, 30]]}, {"timestamp": 1631448461540, "ltp": 1.33, "tv": 7770.69, "trd": [[1.33, 137.9]], "batb": [[0, 1.33, 543.01]], "batl": NaN}, {"timestamp": 1631448462140, "ltp": 1.33, "tv": 7770.69, "trd": NaN, "batb": NaN, "batl": [[0, 1.36, 780.31]]}, {"timestamp": 1631448463465, "ltp": 1.33, "tv": 7770.69, "trd": NaN, "batb": [[2, 1.3, 43.08]], "batl": NaN}, {"timestamp": 1631448464422, "ltp": 1.33, "tv": 7770.69, "trd": NaN, "batb": [[2, 1.31, 45.79]], "batl": [[0, 1.35, 6.89], [1, 1.36, 780.31], [2, 1.37, 411.88]]}, {"timestamp": 1631448465364, "ltp": 1.33, "tv": 7770.69, "trd": NaN, "batb": NaN, "batl": [[1, 1.36, 349.02]]}, {"timestamp": 1631448468451, "ltp": 1.33, "tv": 7770.69, "trd": NaN, "batb": [[0, 1.34, 213.51], [1, 1.33, 543.01], [2, 1.32, 547.95]], "batl": NaN}, {"timestamp": 1631448470374, "ltp": 1.34, "tv": 7792.73, "trd": [[1.34, 22.05]], "batb": [[0, 1.34, 202.49]], "batl": NaN}, {"timestamp": 1631448473170, "ltp": 1.34, "tv": 7792.73, "trd": NaN, "batb": NaN, "batl": [[0, 1.36, 349.02], [1, 1.37, 411.88], [2, 1.38, 30]]}, {"timestamp": 1631448476148, "ltp": 1.34, "tv": 7792.73, "trd": NaN, "batb": NaN, "batl": [[0, 1.36, 295.52], [2, 1.39, 33.5]]}, {"timestamp": 1631448477162, "ltp": 1.34, "tv": 7792.73, "trd": NaN, "batb": [[1, 1.32, 39.89], [2, 1.31, 45.79]], "batl": [[0, 1.42, 30.25], [1, 1.51, 22.5], [2, 1.64, 33.04]]}, {"timestamp": 1631448477647, "ltp": 1.34, "tv": 7792.73, "trd": NaN, "batb": NaN, "batl": [[0, 1.41, 32.5], [1, 1.42, 30.25], [2, 1.51, 22.5]]}, {"timestamp": 1631448479165, "ltp": 1.34, "tv": 7852.74, "trd": [[1.34, 82.05]], "batb": [[0, 1.34, 172.48]], "batl": NaN}, {"timestamp": 1631448480375, "ltp": 1.34, "tv": 7852.74, "trd": NaN, "batb": NaN, "batl": [[0, 1.39, 33.5], [1, 1.4, 8], [2, 1.41, 32.5]]}, {"timestamp": 1631448480862, "ltp": 1.34, "tv": 7852.74, "trd": NaN, "batb": NaN, "batl": [[0, 1.4, 8], [1, 1.41, 39.5], [2, 1.42, 570.82]]}, {"timestamp": 1631448481890, "ltp": 1.34, "tv": 7852.74, "trd": NaN, "batb": NaN, "batl": [[0, 1.4, 14.89]]}, {"timestamp": 1631448484478, "ltp": 1.34, "tv": 7852.74, "trd": NaN, "batb": NaN, "batl": [[0, 1.4, 6.89], [1, 1.41, 32.5], [2, 1.42, 563.82]]}, {"timestamp": 1631448485587, "ltp": 1.34, "tv": 7852.74, "trd": NaN, "batb": [[0, 1.38, 7355.24], [1, 1.37, 431.29], [2, 1.34, 172.48]], "batl": [[0, 1.41, 32.5], [1, 1.42, 563.82], [2, 1.43, 337.57]]}, {"timestamp": 1631448485705, "ltp": 1.34, "tv": 7852.74, "trd": NaN, "batb": [[0, 1.38, 731.06]], "batl": NaN}, {"timestamp": 1631448487378, "ltp": 1.34, "tv": 7852.74, "trd": NaN, "batb": [[0, 1.38, 1191.5], [1, 1.37, 852.64], [2, 1.35, 9]], "batl": NaN}, {"timestamp": 1631448488329, "ltp": 1.34, "tv": 7852.74, "trd": NaN, "batb": [[0, 1.38, 460.44], [1, 1.37, 421.35]], "batl": [[0, 1.41, 72.08]]}, {"timestamp": 1631448489524, "ltp": 1.34, "tv": 7852.74, "trd": NaN, "batb": [[0, 1.4, 213.51], [1, 1.38, 460.44], [2, 1.37, 421.35]], "batl": NaN}, {"timestamp": 1631448491504, "ltp": 1.4, "tv": 7856.83, "trd": [[1.4, 11.44]], "batb": [[0, 1.4, 211.46]], "batl": NaN}, {"timestamp": 1631448506458, "ltp": 1.4, "tv": 7856.83, "trd": NaN, "batb": [[0, 1.39, 213.51]], "batl": NaN}, {"timestamp": 1631448507158, "ltp": 1.4, "tv": 7856.83, "trd": NaN, "batb": NaN, "batl": [[0, 1.4, 5], [1, 1.41, 32.5], [2, 1.42, 563.82]]}, {"timestamp": 1631448508429, "ltp": 1.4, "tv": 7856.83, "trd": NaN, "batb": NaN, "batl": [[1, 1.42, 533.57], [2, 1.43, 337.57]]}, {"timestamp": 1631448509066, "ltp": 1.4, "tv": 7856.83, "trd": NaN, "batb": [[1, 1.34, 36.72], [2, 1.32, 39.89]], "batl": [[1, 1.48, 27.99], [2, 1.51, 22.5]]}, {"timestamp": 1631448510349, "ltp": 1.4, "tv": 7856.83, "trd": NaN, "batb": NaN, "batl": [[1, 1.51, 22.5], [2, 1.52, 28.51]]}, {"timestamp": 1631448511969, "ltp": 1.4, "tv": 7856.83, "trd": NaN, "batb": [[2, 1.33, 656.59]], "batl": [[0, 1.49, 269.95], [1, 1.5, 279.18], [2, 1.51, 22.5]]}, {"timestamp": 1631448513475, "ltp": 1.4, "tv": 7856.83, "trd": NaN, "batb": NaN, "batl": [[0, 1.48, 27.24], [1, 1.49, 269.95], [2, 1.5, 279.18]]}, {"timestamp": 1631448513858, "ltp": 1.4, "tv": 7856.83, "trd": NaN, "batb": NaN, "batl": [[0, 1.49, 269.95], [1, 1.5, 279.18], [2, 1.51, 22.5]]}, {"timestamp": 1631448515153, "ltp": 1.39, "tv": 7866.83, "trd": [[1.39, 206.89]], "batb": [[0, 1.39, 208.51]], "batl": [[0, 1.49, 275.95]]}, {"timestamp": 1631448517360, "ltp": 1.39, "tv": 7866.83, "trd": NaN, "batb": [[0, 1.45, 7779.37], [1, 1.42, 731.06], [2, 1.39, 208.51]], "batl": [[0, 1.48, 6], [1, 1.49, 275.95], [2, 1.5, 279.18]]}, {"timestamp": 1631448520565, "ltp": 1.45, "tv": 8046.06, "trd": [[1.45, 189.19]], "batb": [[0, 1.45, 7689.76], [1, 1.39, 208.51], [2, 1.34, 36.72]], "batl": [[0, 1.48, 29.49]]}, {"timestamp": 1631448521157, "ltp": 1.45, "tv": 8603.84, "trd": [[1.45, 746.97]], "batb": [[0, 1.45, 7410.87]], "batl": [[0, 1.48, 6]]}, {"timestamp": 1631448523491, "ltp": 1.45, "tv": 8603.84, "trd": NaN, "batb": [[0, 1.45, 7348.08]], "batl": NaN}, {"timestamp": 1631448525577, "ltp": 1.45, "tv": 10683.5, "trd": [[1.45, 2826.63]], "batb": [[0, 1.45, 6308.25]], "batl": NaN}, {"timestamp": 1631448527484, "ltp": 1.45, "tv": 10683.5, "trd": NaN, "batb": NaN, "batl": [[0, 1.48, 30.74]]}, {"timestamp": 1631448527820, "ltp": 1.45, "tv": 10683.5, "trd": NaN, "batb": NaN, "batl": [[0, 1.48, 6]]}, {"timestamp": 1631448529060, "ltp": 1.45, "tv": 12741.34, "trd": [[1.45, 4884.47]], "batb": [[0, 1.45, 5279.33]], "batl": [[1, 1.49, 269.95]]}, {"timestamp": 1631448532190, "ltp": 1.45, "tv": 12741.34, "trd": NaN, "batb": NaN, "batl": [[0, 1.46, 3.42], [1, 1.48, 6], [2, 1.49, 269.95]]}, {"timestamp": 1631448533155, "ltp": 1.48, "tv": 12755.49, "trd": [[1.46, 6.83], [1.48, 96.71]], "batb": NaN, "batl": [[0, 1.48, 2.34], [1, 1.49, 269.95], [2, 1.5, 279.18]]}, {"timestamp": 1631448534885, "ltp": 1.48, "tv": 12755.49, "trd": NaN, "batb": NaN, "batl": [[0, 1.47, 416.77], [1, 1.48, 2.34], [2, 1.49, 269.95]]}, {"timestamp": 1631448537187, "ltp": 1.48, "tv": 12755.49, "trd": NaN, "batb": [[1, 1.34, 36.72], [2, 1.33, 656.59]], "batl": NaN}, {"timestamp": 1631448538090, "ltp": 1.48, "tv": 12755.49, "trd": NaN, "batb": [[2, 1.32, 39.89]], "batl": [[0, 1.47, 421.77], [1, 1.48, 26.83]]}, {"timestamp": 1631448539376, "ltp": 1.47, "tv": 13396.12, "trd": [[1.47, 640.63]], "batb": NaN, "batl": [[0, 1.47, 101.46]]}, {"timestamp": 1631448541598, "ltp": 1.45, "tv": 14336.94, "trd": [[1.45, 5825.29]], "batb": [[0, 1.44, 336.19]], "batl": [[0, 1.45, 4568.45], [1, 1.47, 101.46], [2, 1.48, 26.83]]}, {"timestamp": 1631448542423, "ltp": 1.45, "tv": 14336.94, "trd": NaN, "batb": [[1, 1.4, 7], [2, 1.34, 36.72]], "batl": NaN}, {"timestamp": 1631448545587, "ltp": 1.45, "tv": 14871.31, "trd": [[1.45, 6359.66]], "batb": NaN, "batl": [[0, 1.45, 4307.26]]}, {"timestamp": 1631448546511, "ltp": 1.45, "tv": 14871.31, "trd": NaN, "batb": [[1, 1.34, 36.72], [2, 1.33, 16.16]], "batl": NaN}, {"timestamp": 1631448547578, "ltp": 1.45, "tv": 14871.31, "trd": NaN, "batb": [[0, 1.33, 16.16], [1, 1.17, 314.09], [2, 1.1, 296.65]], "batl": [[0, 1.45, 4301.26], [1, 1.47, 96.46], [2, 1.64, 33.04]]}, {"timestamp": 1631448547908, "ltp": 1.45, "tv": 14871.31, "trd": NaN, "batb": [[0, 1.35, 32.07], [1, 1.33, 16.16], [2, 1.17, 314.09]], "batl": [[2, 1.54, 21.75]]}, {"timestamp": 1631448550420, "ltp": 1.45, "tv": 14871.31, "trd": NaN, "batb": NaN, "batl": [[0, 1.47, 96.46], [1, 1.54, 21.75], [2, 1.59, 23.5]]}, {"timestamp": 1631448551399, "ltp": 1.45, "tv": 14871.31, "trd": NaN, "batb": [[0, 1.37, 7], [1, 1.36, 7], [2, 1.35, 40.07]], "batl": [[1, 1.59, 23.5], [2, 1.64, 33.04]]}, {"timestamp": 1631448552415, "ltp": 1.45, "tv": 14871.31, "trd": NaN, "batb": [[0, 1.45, 8.54], [1, 1.37, 7], [2, 1.36, 7]], "batl": NaN}, {"timestamp": 1631448553009, "ltp": 1.45, "tv": 14871.31, "trd": NaN, "batb": [[1, 1.38, 505.98], [2, 1.37, 432.37]], "batl": [[1, 1.58, 263.57], [2, 1.59, 248.71]]}, {"timestamp": 1631448554620, "ltp": 1.45, "tv": 14871.31, "trd": NaN, "batb": [[1, 1.38, 539.44]], "batl": NaN}, {"timestamp": 1631448555718, "ltp": 1.45, "tv": 14871.31, "trd": NaN, "batb": [[1, 1.38, 557.57]], "batl": NaN}, {"timestamp": 1631448558141, "ltp": 1.45, "tv": 14871.31, "trd": NaN, "batb": NaN, "batl": [[0, 1.58, 263.57], [1, 1.59, 248.71], [2, 1.64, 33.04]]}, {"timestamp": 1631448560434, "ltp": 1.45, "tv": 14871.31, "trd": NaN, "batb": [[1, 1.38, 539.44]], "batl": NaN}, {"timestamp": 1631448561405, "ltp": 1.45, "tv": 14871.31, "trd": NaN, "batb": NaN, "batl": [[0, 1.52, 96.46], [1, 1.58, 269.57], [2, 1.59, 248.71]]}, {"timestamp": 1631448562324, "ltp": 1.45, "tv": 14871.31, "trd": NaN, "batb": [[0, 1.38, 539.44], [1, 1.37, 432.37], [2, 1.35, 40.07]], "batl": [[0, 1.58, 269.57], [1, 1.59, 248.71], [2, 1.64, 33.04]]}, {"timestamp": 1631448563527, "ltp": 1.45, "tv": 14871.31, "trd": NaN, "batb": NaN, "batl": [[0, 1.42, 731.06], [1, 1.43, 508.16], [2, 1.58, 269.57]]}, {"timestamp": 1631448563643, "ltp": 1.45, "tv": 14871.31, "trd": NaN, "batb": [[2, 1.35, 32.07]], "batl": NaN}, {"timestamp": 1631448565212, "ltp": 1.43, "tv": 16110.53, "trd": [[1.42, 927.23], [1.43, 511.57]], "batb": [[0, 1.47, 8.54], [1, 1.38, 539.44], [2, 1.37, 432.37]], "batl": [[0, 1.58, 269.57], [1, 1.59, 248.71], [2, 1.64, 33.04]]}, {"timestamp": 1631448566320, "ltp": 1.47, "tv": 16127.61, "trd": [[1.47, 657.71]], "batb": [[0, 1.38, 539.44], [1, 1.37, 432.37], [2, 1.35, 32.07]], "batl": NaN}, {"timestamp": 1631448569039, "ltp": 1.47, "tv": 16127.61, "trd": NaN, "batb": NaN, "batl": [[2, 1.64, 30.15]]}, {"timestamp": 1631448570158, "ltp": 1.47, "tv": 16127.61, "trd": NaN, "batb": [[0, 1.37, 7], [1, 1.35, 32.07], [2, 1.33, 16.16]], "batl": [[0, 1.58, 6], [1, 1.59, 23.5], [2, 1.64, 11.51]]}, {"timestamp": 1631448573549, "ltp": 1.47, "tv": 16127.61, "trd": NaN, "batb": [[0, 1.38, 30.96]], "batl": [[0, 1.59, 23.5], [1, 1.64, 11.51], [2, 1.67, 7.5]]}, {"timestamp": 1631448574514, "ltp": 1.47, "tv": 16127.61, "trd": NaN, "batb": [[0, 1.35, 32.07], [1, 1.33, 16.16], [2, 1.2, 385.63]], "batl": [[0, 1.57, 6.89], [1, 1.59, 23.5], [2, 1.64, 5.86]]}, {"timestamp": 1631448575536, "ltp": 1.47, "tv": 16127.61, "trd": NaN, "batb": [[0, 1.4, 473.99], [1, 1.35, 32.07], [2, 1.33, 16.16]], "batl": [[0, 1.54, 24.25], [1, 1.57, 6.89], [2, 1.59, 23.5]]}, {"timestamp": 1631448575631, "ltp": 1.47, "tv": 16127.61, "trd": NaN, "batb": NaN, "batl": [[0, 1.57, 6.89], [1, 1.59, 23.5], [2, 1.64, 5.86]]}, {"timestamp": 1631448576863, "ltp": 1.47, "tv": 16127.61, "trd": NaN, "batb": [[1, 1.38, 32.96], [2, 1.35, 32.07]], "batl": NaN}, {"timestamp": 1631448579522, "ltp": 1.47, "tv": 16127.61, "trd": NaN, "batb": [[1, 1.38, 538.94], [2, 1.37, 425.37]], "batl": [[1, 1.58, 263.57], [2, 1.59, 248.71]]}, {"timestamp": 1631448581450, "ltp": 1.47, "tv": 16127.61, "trd": NaN, "batb": NaN, "batl": [[0, 1.52, 6.89], [1, 1.53, 6.89], [2, 1.57, 6.89]]}, {"timestamp": 1631448582552, "ltp": 1.47, "tv": 16127.61, "trd": NaN, "batb": NaN, "batl": [[0, 1.51, 6.89], [1, 1.52, 6.89], [2, 1.53, 6.89]]}, {"timestamp": 1631448587435, "ltp": 1.4, "tv": 16150.09, "trd": [[1.4, 33.92]], "batb": [[0, 1.4, 460.26]], "batl": [[0, 1.42, 503.68], [1, 1.43, 340.88], [2, 1.51, 6.89]]}, {"timestamp": 1631448588458, "ltp": 1.4, "tv": 16165.08, "trd": [[1.4, 48.91]], "batb": [[0, 1.4, 445.26]], "batl": [[0, 1.41, 7], [1, 1.42, 503.68], [2, 1.43, 340.88]]}, {"timestamp": 1631448589249, "ltp": 1.4, "tv": 16167.64, "trd": [[1.4, 51.47]], "batb": [[0, 1.4, 443.98]], "batl": NaN}, {"timestamp": 1631448591559, "ltp": 1.41, "tv": 16168.44, "trd": [[1.41, 482.97]], "batb": NaN, "batl": [[0, 1.41, 6.6]]}, {"timestamp": 1631448592571, "ltp": 1.4, "tv": 16213.9, "trd": [[1.4, 96.93]], "batb": [[0, 1.4, 421.26]], "batl": NaN}, {"timestamp": 1631448596369, "ltp": 1.4, "tv": 16213.9, "trd": NaN, "batb": [[0, 1.4, 341.62]], "batl": NaN}, {"timestamp": 1631448597562, "ltp": 1.4, "tv": 16213.9, "trd": NaN, "batb": [[0, 1.4, 1005.21], [1, 1.38, 505.98]], "batl": NaN}, {"timestamp": 1631448598174, "ltp": 1.4, "tv": 16213.9, "trd": NaN, "batb": [[1, 1.32, 40.14], [2, 1.28, 41.16]], "batl": [[0, 1.5, 6], [1, 1.56, 20.67], [2, 1.59, 23.5]]}, {"timestamp": 1631448599556, "ltp": 1.4, "tv": 16213.9, "trd": NaN, "batb": [[0, 1.42, 20.5], [1, 1.4, 1005.21], [2, 1.32, 40.14]], "batl": NaN}, {"timestamp": 1631448601469, "ltp": 1.4, "tv": 16213.9, "trd": NaN, "batb": [[1, 1.41, 1.04], [2, 1.32, 651.07]], "batl": [[1, 1.51, 24.5], [2, 1.52, 452.66]]}, {"timestamp": 1631448601963, "ltp": 1.4, "tv": 16213.9, "trd": NaN, "batb": NaN, "batl": [[1, 1.56, 20.67], [2, 1.67, 7.5]]}, {"timestamp": 1631448603282, "ltp": 1.41, "tv": 16256.97, "trd": [[1.41, 485.05], [1.42, 968.23]], "batb": [[0, 1.32, 651.07], [1, 1.31, 534.51], [2, 1.28, 41.16]], "batl": [[0, 1.36, 709.52], [1, 1.5, 6], [2, 1.56, 20.67]]}, {"timestamp": 1631448604517, "ltp": 1.41, "tv": 16256.97, "trd": NaN, "batb": NaN, "batl": [[0, 1.35, 4492.3], [1, 1.36, 711.52], [2, 1.37, 14]]}, {"timestamp": 1631448605482, "ltp": 1.41, "tv": 16256.97, "trd": NaN, "batb": NaN, "batl": [[0, 1.35, 336.3], [1, 1.36, 432.49], [2, 1.37, 7]]}, {"timestamp": 1631448607582, "ltp": 1.41, "tv": 16256.97, "trd": NaN, "batb": [[0, 1.32, 695.11]], "batl": [[1, 1.36, 476.4]]}, {"timestamp": 1631448609386, "ltp": 1.32, "tv": 16286.33, "trd": [[1.32, 51.57]], "batb": [[0, 1.32, 680.43]], "batl": NaN}, {"timestamp": 1631448613497, "ltp": 1.35, "tv": 16958.93, "trd": [[1.35, 677.42]], "batb": [[0, 1.35, 32.65], [1, 1.32, 680.43], [2, 1.31, 534.51]], "batl": [[0, 1.36, 476.4], [1, 1.37, 7], [2, 1.39, 36.5]]}, {"timestamp": 1631448616493, "ltp": 1.36, "tv": 18342.45, "trd": [[1.35, 742.72], [1.36, 1323.49]], "batb": [[0, 1.32, 806.93], [1, 1.31, 534.51], [2, 1.28, 41.16]], "batl": [[0, 1.37, 417.31], [1, 1.39, 36.5], [2, 1.41, 29.5]]}, {"timestamp": 1631448617535, "ltp": 1.36, "tv": 18342.45, "trd": NaN, "batb": [[0, 1.32, 575.82], [1, 1.28, 41.16], [2, 1.25, 50.09]], "batl": NaN}, {"timestamp": 1631448620251, "ltp": 1.36, "tv": 18342.45, "trd": NaN, "batb": [[0, 1.35, 6.18], [1, 1.33, 487.65], [2, 1.32, 575.64]], "batl": [[0, 1.36, 347.17], [1, 1.37, 417.31], [2, 1.39, 36.5]]}, {"timestamp": 1631448621546, "ltp": 1.36, "tv": 18342.45, "trd": NaN, "batb": NaN, "batl": [[0, 1.36, 384.75]]}, {"timestamp": 1631448622441, "ltp": 1.36, "tv": 18342.45, "trd": NaN, "batb": [[1, 1.25, 50.09], [2, 1.24, 59.27]], "batl": [[0, 1.37, 7], [1, 1.43, 30.5], [2, 1.44, 27.58]]}, {"timestamp": 1631448623139, "ltp": 1.36, "tv": 18342.45, "trd": NaN, "batb": NaN, "batl": [[0, 1.43, 30.5], [1, 1.44, 27.58], [2, 1.5, 6]]}, {"timestamp": 1631448625423, "ltp": 1.36, "tv": 18342.45, "trd": NaN, "batb": [[0, 1.33, 18.12], [1, 1.29, 313.94], [2, 1.28, 594.37]], "batl": [[0, 1.43, 298.83], [1, 1.44, 357.05]]}, {"timestamp": 1631448625631, "ltp": 1.36, "tv": 18342.45, "trd": NaN, "batb": [[2, 1.28, 640.28]], "batl": NaN}, {"timestamp": 1631448628537, "ltp": 1.36, "tv": 18342.45, "trd": NaN, "batb": [[0, 1.37, 6], [1, 1.33, 18.12], [2, 1.29, 313.94]], "batl": [[0, 1.4, 30.69], [1, 1.42, 382.3], [2, 1.43, 298.83]]}, {"timestamp": 1631448628868, "ltp": 1.36, "tv": 18342.45, "trd": NaN, "batb": NaN, "batl": [[0, 1.42, 382.3], [1, 1.43, 298.83], [2, 1.44, 357.05]]}, {"timestamp": 1631448631242, "ltp": 1.36, "tv": 18342.45, "trd": NaN, "batb": [[1, 1.33, 17.93]], "batl": NaN}, {"timestamp": 1631448632473, "ltp": 1.36, "tv": 18342.45, "trd": NaN, "batb": NaN, "batl": [[0, 1.4, 28.19], [1, 1.42, 382.3], [2, 1.43, 298.83]]}, {"timestamp": 1631448632742, "ltp": 1.36, "tv": 18342.45, "trd": NaN, "batb": NaN, "batl": [[0, 1.42, 382.3], [1, 1.43, 298.83], [2, 1.44, 357.05]]}, {"timestamp": 1631448637425, "ltp": 1.36, "tv": 18342.45, "trd": NaN, "batb": [[0, 1.33, 17.93], [1, 1.25, 59.09], [2, 1.24, 70.27]], "batl": NaN}, {"timestamp": 1631448638549, "ltp": 1.36, "tv": 18342.45, "trd": NaN, "batb": [[0, 1.38, 731.06], [1, 1.37, 508.16], [2, 1.33, 17.93]], "batl": NaN}, {"timestamp": 1631448639572, "ltp": 1.36, "tv": 18342.45, "trd": NaN, "batb": NaN, "batl": [[0, 1.4, 34.99], [1, 1.42, 382.3], [2, 1.43, 298.83]]}, {"timestamp": 1631448640553, "ltp": 1.4, "tv": 18354.45, "trd": [[1.4, 108.93]], "batb": [[0, 1.4, 302.8], [1, 1.39, 391.2], [2, 1.38, 731.06]], "batl": [[0, 1.42, 390.3], [1, 1.43, 298.83], [2, 1.44, 357.05]]}, {"timestamp": 1631448641467, "ltp": 1.4, "tv": 18354.45, "trd": NaN, "batb": [[1, 1.39, 435.66], [2, 1.37, 508.16]], "batl": [[0, 1.42, 382.3]]}, {"timestamp": 1631448642342, "ltp": 1.4, "tv": 18354.45, "trd": NaN, "batb": [[0, 1.41, 16.8], [1, 1.4, 302.8], [2, 1.39, 435.66]], "batl": NaN}, {"timestamp": 1631448643255, "ltp": 1.4, "tv": 18354.45, "trd": NaN, "batb": [[0, 1.4, 302.8], [1, 1.39, 435.66], [2, 1.34, 13]], "batl": NaN}, {"timestamp": 1631448645251, "ltp": 1.4, "tv": 18358.93, "trd": [[1.4, 113.41]], "batb": [[0, 1.4, 300.56]], "batl": NaN}, {"timestamp": 1631448650270, "ltp": 1.4, "tv": 18358.93, "trd": NaN, "batb": [[0, 1.41, 17.93], [1, 1.4, 300.56], [2, 1.39, 435.66]], "batl": NaN}, {"timestamp": 1631448652367, "ltp": 1.41, "tv": 18370.94, "trd": [[1.41, 497.05]], "batb": [[0, 1.41, 11.93]], "batl": NaN}, {"timestamp": 1631448653408, "ltp": 1.42, "tv": 18376.25, "trd": [[1.42, 973.54]], "batb": NaN, "batl": [[0, 1.42, 376.99]]}, {"timestamp": 1631448664475, "ltp": 1.42, "tv": 18376.25, "trd": NaN, "batb": [[2, 1.39, 391.2]], "batl": [[0, 1.43, 298.83], [1, 1.44, 357.05], [2, 1.5, 6]]}, {"timestamp": 1631448665068, "ltp": 1.42, "tv": 18376.25, "trd": NaN, "batb": [[1, 1.28, 24.6], [2, 1.27, 62.46]], "batl": [[0, 1.5, 6], [1, 1.57, 23.5], [2, 1.8, 826.8]]}, {"timestamp": 1631448666105, "ltp": 1.41, "tv": 18400.11, "trd": [[1.41, 520.92]], "batb": [[0, 1.28, 24.6], [1, 1.27, 62.46], [2, 1.17, 314.09]], "batl": NaN}, {"timestamp": 1631448668282, "ltp": 1.41, "tv": 18400.11, "trd": NaN, "batb": [[0, 1.33, 718.51], [1, 1.32, 550.78], [2, 1.28, 24.6]], "batl": [[1, 1.52, 30.02], [2, 1.54, 432.93]]}, {"timestamp": 1631448668993, "ltp": 1.41, "tv": 18400.11, "trd": NaN, "batb": [[2, 1.28, 32.6]], "batl": [[1, 1.54, 432.93], [2, 1.55, 244.43]]}, {"timestamp": 1631448670384, "ltp": 1.41, "tv": 18400.11, "trd": NaN, "batb": [[0, 1.28, 32.6], [1, 1.27, 73.46], [2, 1.17, 314.09]], "batl": [[1, 1.57, 23.5], [2, 1.8, 826.8]]}, {"timestamp": 1631448670707, "ltp": 1.41, "tv": 18400.11, "trd": NaN, "batb": [[0, 1.29, 23.75], [1, 1.28, 32.6], [2, 1.27, 73.46]], "batl": NaN}, {"timestamp": 1631448673580, "ltp": 1.41, "tv": 18400.11, "trd": NaN, "batb": [[0, 1.42, 229.37], [1, 1.41, 365.9], [2, 1.34, 194.25]], "batl": [[0, 1.45, 282.8], [1, 1.46, 310.82], [2, 1.49, 30]]}, {"timestamp": 1631448675929, "ltp": 1.41, "tv": 18400.11, "trd": NaN, "batb": NaN, "batl": [[0, 1.44, 360.07], [1, 1.45, 282.8], [2, 1.46, 310.82]]}, {"timestamp": 1631448677123, "ltp": 1.41, "tv": 18400.11, "trd": NaN, "batb": [[2, 1.34, 173.99]], "batl": NaN}, {"timestamp": 1631448679094, "ltp": 1.42, "tv": 18827.13, "trd": [[1.42, 1400.56]], "batb": [[0, 1.42, 15.86]], "batl": [[0, 1.45, 282.8], [1, 1.46, 310.82], [2, 1.49, 30]]}, {"timestamp": 1631448680333, "ltp": 1.42, "tv": 18827.13, "trd": NaN, "batb": [[0, 1.32, 53.64], [1, 1.31, 8], [2, 1.3, 8]], "batl": [[0, 1.5, 6], [1, 1.52, 30.02], [2, 1.57, 30]]}, {"timestamp": 1631448680702, "ltp": 1.42, "tv": 18827.13, "trd": NaN, "batb": [[0, 1.32, 8]], "batl": [[1, 1.57, 23.5], [2, 1.8, 826.8]]}, {"timestamp": 1631448683221, "ltp": 1.42, "tv": 18827.13, "trd": NaN, "batb": [[0, 1.33, 622.31], [1, 1.32, 517.5], [2, 1.31, 8]], "batl": [[1, 1.53, 265.58], [2, 1.54, 252.07]]}, {"timestamp": 1631448684136, "ltp": 1.42, "tv": 18827.13, "trd": NaN, "batb": [[1, 1.32, 555.39]], "batl": NaN}, {"timestamp": 1631448685212, "ltp": 1.42, "tv": 18827.13, "trd": NaN, "batb": [[0, 1.33, 643.19], [2, 1.27, 62.46]], "batl": NaN}, {"timestamp": 1631448687304, "ltp": 1.42, "tv": 18827.13, "trd": NaN, "batb": NaN, "batl": [[0, 1.48, 145.49], [1, 1.5, 6], [2, 1.52, 31.27]]}, {"timestamp": 1631448691111, "ltp": 1.42, "tv": 18827.13, "trd": NaN, "batb": [[0, 1.33, 622.31], [2, 1.27, 45.87]], "batl": [[0, 1.37, 508.16], [1, 1.38, 731.06], [2, 1.48, 145.49]]}, {"timestamp": 1631448692413, "ltp": 1.42, "tv": 18827.13, "trd": NaN, "batb": NaN, "batl": [[0, 1.37, 518.54]]}, {"timestamp": 1631448693540, "ltp": 1.42, "tv": 18827.13, "trd": NaN, "batb": NaN, "batl": [[0, 1.36, 7], [1, 1.37, 1154.53], [2, 1.38, 1125.3]]}, {"timestamp": 1631448694129, "ltp": 1.42, "tv": 18827.13, "trd": NaN, "batb": [[0, 1.33, 662.76]], "batl": [[1, 1.37, 1199.29]]}, {"timestamp": 1631448695839, "ltp": 1.42, "tv": 18827.13, "trd": NaN, "batb": NaN, "batl": [[1, 1.37, 691.13], [2, 1.38, 394.24]]}, {"timestamp": 1631448699065, "ltp": 1.42, "tv": 18827.13, "trd": NaN, "batb": [[2, 1.28, 45.66]], "batl": [[0, 1.35, 159.5], [1, 1.36, 7], [2, 1.37, 691.13]]}, {"timestamp": 1631448700560, "ltp": 1.33, "tv": 18837.13, "trd": [[1.33, 147.9]], "batb": [[0, 1.33, 657.76]], "batl": NaN}, {"timestamp": 1631448708378, "ltp": 1.35, "tv": 18839.31, "trd": [[1.35, 744.89]], "batb": NaN, "batl": [[0, 1.35, 158.42]]}, {"timestamp": 1631448713469, "ltp": 1.33, "tv": 18859.31, "trd": [[1.33, 167.9]], "batb": [[0, 1.33, 647.76]], "batl": NaN}, {"timestamp": 1631448714483, "ltp": 1.35, "tv": 18878.95, "trd": [[1.35, 764.53]], "batb": NaN, "batl": [[0, 1.35, 138.77]]}, {"timestamp": 1631448717485, "ltp": 1.35, "tv": 18979.31, "trd": [[1.35, 864.9]], "batb": NaN, "batl": [[0, 1.35, 88.59]]}, {"timestamp": 1631448718488, "ltp": 1.35, "tv": 18979.31, "trd": NaN, "batb": [[0, 1.33, 607.31], [1, 1.32, 547.39]], "batl": [[2, 1.37, 646.37]]}, {"timestamp": 1631448719595, "ltp": 1.35, "tv": 18979.31, "trd": NaN, "batb": [[0, 1.25, 47.13], [1, 1.23, 33.79], [2, 1.2, 68.89]], "batl": [[1, 1.43, 31.5], [2, 1.5, 6]]}, {"timestamp": 1631448720371, "ltp": 1.35, "tv": 19079.32, "trd": [[1.35, 964.9]], "batb": [[1, 1.2, 68.89], [2, 1.17, 314.09]], "batl": [[0, 1.35, 38.59]]}, {"timestamp": 1631448721562, "ltp": 1.35, "tv": 19079.6, "trd": [[1.35, 965.18]], "batb": [[0, 1.29, 426.26], [1, 1.28, 598.3], [2, 1.25, 47.13]], "batl": [[0, 1.35, 38.3], [2, 1.44, 484.98]]}, {"timestamp": 1631448722375, "ltp": 1.35, "tv": 19079.6, "trd": NaN, "batb": [[1, 1.28, 644.96], [2, 1.27, 8]], "batl": [[1, 1.4, 35.48], [2, 1.43, 37.14]]}, {"timestamp": 1631448722691, "ltp": 1.35, "tv": 19079.6, "trd": NaN, "batb": NaN, "batl": [[1, 1.43, 31.5], [2, 1.44, 484.98]]}, {"timestamp": 1631448726308, "ltp": 1.35, "tv": 19082.69, "trd": [[1.35, 968.28]], "batb": NaN, "batl": [[0, 1.35, 36.76]]}, {"timestamp": 1631448729513, "ltp": 1.35, "tv": 19082.69, "trd": NaN, "batb": NaN, "batl": [[1, 1.4, 39.98], [2, 1.43, 38]]}, {"timestamp": 1631448730114, "ltp": 1.35, "tv": 19082.69, "trd": NaN, "batb": NaN, "batl": [[1, 1.43, 31.5], [2, 1.44, 484.98]]}, {"timestamp": 1631448731400, "ltp": 1.35, "tv": 19082.69, "trd": NaN, "batb": NaN, "batl": [[0, 1.33, 508.16], [1, 1.34, 731.06], [2, 1.35, 36.76]]}, {"timestamp": 1631448733595, "ltp": 1.35, "tv": 19082.69, "trd": NaN, "batb": NaN, "batl": [[0, 1.31, 4.92], [1, 1.33, 508.16], [2, 1.34, 731.06]]}, {"timestamp": 1631448734504, "ltp": 1.35, "tv": 19082.69, "trd": NaN, "batb": NaN, "batl": [[1, 1.32, 612.28], [2, 1.33, 978.99]]}, {"timestamp": 1631448735531, "ltp": 1.35, "tv": 19082.69, "trd": NaN, "batb": [[2, 1.25, 47.13]], "batl": [[2, 1.33, 986.99]]}, {"timestamp": 1631448736128, "ltp": 1.29, "tv": 19086.69, "trd": [[1.29, 22]], "batb": [[0, 1.29, 424.26]], "batl": NaN}, {"timestamp": 1631448736832, "ltp": 1.29, "tv": 19086.69, "trd": NaN, "batb": NaN, "batl": [[2, 1.33, 478.83]]}, {"timestamp": 1631448738383, "ltp": 1.29, "tv": 19146.61, "trd": [[1.29, 81.92]], "batb": [[0, 1.29, 394.3], [2, 1.27, 5]], "batl": NaN}, {"timestamp": 1631448738923, "ltp": 1.31, "tv": 19156.19, "trd": [[1.31, 23.58]], "batb": NaN, "batl": [[0, 1.32, 612.41], [1, 1.33, 478.83], [2, 1.4, 37.43]]}, {"timestamp": 1631448741244, "ltp": 1.29, "tv": 19744.89, "trd": [[1.29, 670.62]], "batb": [[0, 1.29, 99.95]], "batl": NaN}, {"timestamp": 1631448742206, "ltp": 1.31, "tv": 19745.15, "trd": [[1.31, 23.84]], "batb": [[0, 1.29, 100.32]], "batl": [[0, 1.32, 547.28], [1, 1.33, 8]]}, {"timestamp": 1631448744812, "ltp": 1.31, "tv": 19745.89, "trd": [[1.31, 24.58]], "batb": [[0, 1.29, 288.97]], "batl": [[0, 1.31, 250.64], [1, 1.32, 547.28], [2, 1.33, 8]]}, {"timestamp": 1631448746528, "ltp": 1.31, "tv": 19745.89, "trd": NaN, "batb": NaN, "batl": [[0, 1.3, 49.63], [1, 1.31, 250.64], [2, 1.32, 547.28]]}, {"timestamp": 1631448751344, "ltp": 1.31, "tv": 19745.89, "trd": NaN, "batb": [[2, 1.25, 47.13]], "batl": NaN}, {"timestamp": 1631448751838, "ltp": 1.3, "tv": 19760.06, "trd": [[1.29, 677.56], [1.3, 36.74]], "batb": [[0, 1.29, 285.5]], "batl": [[0, 1.3, 46.02]]}, {"timestamp": 1631448754361, "ltp": 1.3, "tv": 19760.06, "trd": NaN, "batb": [[2, 1.27, 10]], "batl": NaN}, {"timestamp": 1631448764333, "ltp": 1.31, "tv": 19821.68, "trd": [[1.3, 82.75], [1.31, 40.19]], "batb": NaN, "batl": [[0, 1.32, 547.28], [1, 1.33, 8], [2, 1.4, 37.43]]}, {"timestamp": 1631448767356, "ltp": 1.31, "tv": 19821.68, "trd": NaN, "batb": [[2, 1.25, 47.13]], "batl": [[0, 1.32, 784.94], [1, 1.33, 478.91]]}, {"timestamp": 1631448767736, "ltp": 1.31, "tv": 19821.68, "trd": NaN, "batb": [[0, 1.3, 2.3], [1, 1.29, 285.5], [2, 1.28, 644.96]], "batl": NaN}, {"timestamp": 1631448772662, "ltp": 1.32, "tv": 19838.76, "trd": [[1.32, 68.65]], "batb": NaN, "batl": [[0, 1.32, 776.4]]}, {"timestamp": 1631448774165, "ltp": 1.32, "tv": 19838.76, "trd": NaN, "batb": [[0, 1.29, 285.5], [1, 1.28, 644.96], [2, 1.25, 47.13]], "batl": NaN}, {"timestamp": 1631448780570, "ltp": 1.32, "tv": 19838.76, "trd": NaN, "batb": NaN, "batl": [[0, 1.3, 20], [1, 1.32, 776.4], [2, 1.33, 478.91]]}, {"timestamp": 1631448785452, "ltp": 1.32, "tv": 19838.76, "trd": NaN, "batb": NaN, "batl": [[0, 1.3, 123]]}, {"timestamp": 1631448786459, "ltp": 1.3, "tv": 19918.22, "trd": [[1.3, 162.21]], "batb": NaN, "batl": [[0, 1.3, 83.27]]}, {"timestamp": 1631448787469, "ltp": 1.3, "tv": 19987.19, "trd": [[1.3, 231.18]], "batb": NaN, "batl": [[0, 1.3, 48.79]]}, {"timestamp": 1631448788867, "ltp": 1.3, "tv": 19991.79, "trd": [[1.3, 235.78]], "batb": NaN, "batl": [[0, 1.3, 46.49]]}, {"timestamp": 1631448791168, "ltp": 1.3, "tv": 20008.33, "trd": [[1.3, 252.32]], "batb": NaN, "batl": [[0, 1.32, 776.4], [1, 1.33, 478.91], [2, 1.4, 37.43]]}, {"timestamp": 1631448793566, "ltp": 1.29, "tv": 20048.33, "trd": [[1.29, 717.56]], "batb": [[0, 1.29, 265.5]], "batl": [[0, 1.32, 547.3], [1, 1.33, 8]]}, {"timestamp": 1631448796590, "ltp": 1.29, "tv": 20048.33, "trd": NaN, "batb": NaN, "batl": [[0, 1.31, 247.37], [1, 1.32, 547.3], [2, 1.33, 8]]}, {"timestamp": 1631448802393, "ltp": 1.31, "tv": 20048.53, "trd": [[1.31, 40.39]], "batb": [[0, 1.3, 1.55], [1, 1.29, 265.5], [2, 1.28, 644.96]], "batl": [[0, 1.31, 247.27]]}, {"timestamp": 1631448806306, "ltp": 1.31, "tv": 20192.61, "trd": [[1.31, 184.47]], "batb": NaN, "batl": [[0, 1.32, 547.3], [1, 1.33, 8], [2, 1.4, 37.43]]}, {"timestamp": 1631448809273, "ltp": 1.31, "tv": 20192.61, "trd": NaN, "batb": [[1, 1.29, 355]], "batl": [[0, 1.32, 731.99], [1, 1.33, 478.9]]}, {"timestamp": 1631448815595, "ltp": 1.32, "tv": 20203.8, "trd": [[1.32, 79.84]], "batb": [[0, 1.3, 57.55]], "batl": [[0, 1.32, 720.8]]}, {"timestamp": 1631448818423, "ltp": 1.29, "tv": 21028.89, "trd": [[1.29, 1427.56], [1.3, 367.41]], "batb": [[0, 1.28, 644.96], [1, 1.25, 47.13], [2, 1.2, 34.44]], "batl": [[0, 1.29, 99.88], [1, 1.32, 547.35], [2, 1.33, 8]]}, {"timestamp": 1631448821304, "ltp": 1.29, "tv": 21028.89, "trd": NaN, "batb": [[0, 1.28, 913.07], [1, 1.27, 637.67], [2, 1.25, 47.13]], "batl": [[1, 1.31, 328.51], [2, 1.32, 547.35]]}, {"timestamp": 1631448824016, "ltp": 1.29, "tv": 21028.89, "trd": NaN, "batb": [[2, 1.26, 46.98]], "batl": NaN}, {"timestamp": 1631448839532, "ltp": 1.29, "tv": 21033.65, "trd": [[1.29, 1432.32]], "batb": [[0, 1.26, 46.98], [1, 1.24, 52.02], [2, 1.2, 34.44]], "batl": [[0, 1.29, 95.11], [1, 1.33, 8], [2, 1.4, 37.43]]}, {"timestamp": 1631448840027, "ltp": 1.29, "tv": 21033.65, "trd": NaN, "batb": [[0, 1.24, 52.02], [1, 1.2, 34.44], [2, 1.17, 314.09]], "batl": [[1, 1.5, 6], [2, 1.94, 8.68]]}, {"timestamp": 1631448840975, "ltp": 1.29, "tv": 21223.88, "trd": [[1.29, 1622.55]], "batb": [[0, 1.29, 3.89], [1, 1.24, 52.02], [2, 1.2, 34.44]], "batl": [[0, 1.5, 6], [1, 1.94, 8.68], [2, 8.8, 7.23]]}, {"timestamp": 1631448842472, "ltp": 1.29, "tv": 21223.88, "trd": NaN, "batb": [[1, 1.26, 599.56], [2, 1.25, 695.98]], "batl": [[0, 1.34, 678.57], [1, 1.35, 439.88], [2, 1.5, 6]]}, {"timestamp": 1631448842952, "ltp": 1.29, "tv": 21223.88, "trd": NaN, "batb": [[1, 1.26, 656.54], [2, 1.25, 707.98]], "batl": NaN}, {"timestamp": 1631448844188, "ltp": 1.29, "tv": 21231.66, "trd": [[1.29, 1630.33]], "batb": [[0, 1.26, 656.54], [1, 1.25, 707.98], [2, 1.24, 61.02]], "batl": [[0, 1.34, 682.57], [2, 1.4, 4]]}, {"timestamp": 1631448845581, "ltp": 1.29, "tv": 21231.66, "trd": NaN, "batb": NaN, "batl": [[0, 1.31, 34.5], [1, 1.32, 4], [2, 1.34, 682.57]]}, {"timestamp": 1631448845795, "ltp": 1.29, "tv": 21231.66, "trd": NaN, "batb": NaN, "batl": [[0, 1.32, 4], [1, 1.34, 682.57], [2, 1.35, 439.88]]}, {"timestamp": 1631448850393, "ltp": 1.29, "tv": 21231.66, "trd": NaN, "batb": [[0, 1.26, 56.98], [1, 1.25, 12]], "batl": NaN}, {"timestamp": 1631448850717, "ltp": 1.29, "tv": 21231.66, "trd": NaN, "batb": [[0, 1.26, 10]], "batl": NaN}, {"timestamp": 1631448852582, "ltp": 1.29, "tv": 21231.66, "trd": NaN, "batb": NaN, "batl": [[0, 1.31, 37.5], [1, 1.34, 678.57]]}, {"timestamp": 1631448853588, "ltp": 1.31, "tv": 21306.66, "trd": [[1.31, 259.47]], "batb": [[0, 1.31, 212.22], [1, 1.3, 550.07], [2, 1.29, 2]], "batl": [[0, 1.34, 678.57], [1, 1.35, 439.88], [2, 1.4, 4]]}, {"timestamp": 1631448854437, "ltp": 1.31, "tv": 21306.66, "trd": NaN, "batb": [[0, 1.3, 550.07], [1, 1.29, 2], [2, 1.26, 18]], "batl": NaN}, {"timestamp": 1631448855469, "ltp": 1.31, "tv": 21306.66, "trd": NaN, "batb": [[2, 1.27, 33.51]], "batl": NaN}, {"timestamp": 1631448856502, "ltp": 1.31, "tv": 21306.66, "trd": NaN, "batb": [[0, 1.3, 557.07], [1, 1.29, 11]], "batl": [[0, 1.34, 716.49]]}, {"timestamp": 1631448857505, "ltp": 1.32, "tv": 21313.02, "trd": [[1.32, 86.21]], "batb": [[0, 1.32, 15.16], [1, 1.3, 792.94], [2, 1.29, 594.49]], "batl": NaN}, {"timestamp": 1631448858360, "ltp": 1.3, "tv": 21355.25, "trd": [[1.3, 379.31], [1.32, 116.53]], "batb": [[0, 1.3, 844.04], [1, 1.29, 594.49], [2, 1.27, 33.51]], "batl": NaN}, {"timestamp": 1631448859176, "ltp": 1.3, "tv": 21375.25, "trd": [[1.3, 399.31]], "batb": [[0, 1.31, 22.22], [1, 1.3, 834.04], [2, 1.29, 594.49]], "batl": NaN}, {"timestamp": 1631448860302, "ltp": 1.3, "tv": 21375.25, "trd": NaN, "batb": NaN, "batl": [[0, 1.32, 42.11], [1, 1.33, 38.5], [2, 1.34, 500.89]]}, {"timestamp": 1631448861484, "ltp": 1.3, "tv": 21375.25, "trd": NaN, "batb": NaN, "batl": [[2, 1.34, 538.64]]}, {"timestamp": 1631448862503, "ltp": 1.3, "tv": 21375.25, "trd": NaN, "batb": NaN, "batl": [[1, 1.33, 277.78]]}, {"timestamp": 1631448865483, "ltp": 1.3, "tv": 21375.25, "trd": NaN, "batb": [[0, 1.3, 834.04], [1, 1.29, 594.49], [2, 1.28, 44.41]], "batl": NaN}, {"timestamp": 1631448870506, "ltp": 1.3, "tv": 21375.25, "trd": NaN, "batb": [[2, 1.28, 69.01]], "batl": NaN}, {"timestamp": 1631448870716, "ltp": 1.3, "tv": 21375.25, "trd": NaN, "batb": [[1, 1.29, 585.49]], "batl": NaN}, {"timestamp": 1631448873320, "ltp": 1.3, "tv": 21375.25, "trd": NaN, "batb": [[0, 1.28, 69.01], [1, 1.26, 55.48], [2, 1.25, 52.09]], "batl": [[0, 1.33, 38.5], [1, 1.34, 37.75], [2, 1.35, 38.5]]}, {"timestamp": 1631448873627, "ltp": 1.3, "tv": 21375.25, "trd": NaN, "batb": [[0, 1.28, 24.6], [2, 1.17, 314.09]], "batl": [[1, 1.36, 20.89], [2, 1.4, 4]]}, {"timestamp": 1631448876552, "ltp": 1.3, "tv": 21375.25, "trd": NaN, "batb": NaN, "batl": [[0, 1.32, 38.61], [1, 1.33, 45.5], [2, 1.36, 20.89]]}, {"timestamp": 1631448877233, "ltp": 1.3, "tv": 21375.25, "trd": NaN, "batb": NaN, "batl": [[0, 1.33, 45.5], [1, 1.36, 20.89], [2, 1.4, 4]]}, {"timestamp": 1631448879213, "ltp": 1.3, "tv": 21375.25, "trd": NaN, "batb": [[0, 1.3, 515.22], [1, 1.29, 578.83], [2, 1.28, 24.6]], "batl": [[0, 1.33, 530.84], [1, 1.34, 459.31], [2, 1.36, 20.89]]}, {"timestamp": 1631448880508, "ltp": 1.32, "tv": 21376.04, "trd": [[1.32, 117.33]], "batb": [[0, 1.3, 514.82], [1, 1.29, 649.73], [2, 1.28, 69.76]], "batl": NaN}, {"timestamp": 1631448880852, "ltp": 1.32, "tv": 21376.04, "trd": NaN, "batb": [[1, 1.29, 578.83]], "batl": NaN}, {"timestamp": 1631448884445, "ltp": 1.32, "tv": 21376.04, "trd": NaN, "batb": [[0, 1.28, 69.76], [1, 1.26, 55.48], [2, 1.17, 314.09]], "batl": [[0, 1.33, 45.5], [1, 1.36, 20.89], [2, 1.4, 4]]}, {"timestamp": 1631448884746, "ltp": 1.32, "tv": 21376.04, "trd": NaN, "batb": [[0, 1.28, 24.6]], "batl": NaN}, {"timestamp": 1631448887459, "ltp": 1.32, "tv": 21376.04, "trd": NaN, "batb": [[0, 1.28, 607.34], [1, 1.27, 634.07], [2, 1.26, 55.48]], "batl": [[1, 1.36, 629.81], [2, 1.37, 411.47]]}, {"timestamp": 1631448888460, "ltp": 1.32, "tv": 21376.04, "trd": NaN, "batb": [[0, 1.28, 648.5]], "batl": [[0, 1.33, 7], [1, 1.36, 20.89], [2, 1.94, 8.68]]}, {"timestamp": 1631448890563, "ltp": 1.32, "tv": 21376.04, "trd": NaN, "batb": [[1, 1.27, 642.07], [2, 1.26, 66.48]], "batl": [[1, 1.94, 8.68], [2, 8.8, 7.23]]}, {"timestamp": 1631448891049, "ltp": 1.32, "tv": 21376.04, "trd": NaN, "batb": [[1, 1.27, 667.58]], "batl": NaN}, {"timestamp": 1631448892562, "ltp": 1.32, "tv": 21376.04, "trd": NaN, "batb": [[0, 1.28, 698.16]], "batl": [[0, 1.31, 517.57], [1, 1.32, 529.69], [2, 1.33, 7]]}, {"timestamp": 1631448893315, "ltp": 1.32, "tv": 21376.04, "trd": NaN, "batb": NaN, "batl": [[1, 1.32, 551.22]]}, {"timestamp": 1631448896493, "ltp": 1.28, "tv": 21433.9, "trd": [[1.28, 57.86]], "batb": [[0, 1.28, 669.23]], "batl": NaN}, {"timestamp": 1631448898075, "ltp": 1.28, "tv": 21433.9, "trd": NaN, "batb": NaN, "batl": [[0, 1.31, 553.07]]}, {"timestamp": 1631448899964, "ltp": 1.28, "tv": 21433.9, "trd": NaN, "batb": [[1, 1.27, 642.07]], "batl": [[1, 1.32, 529.69]]}, {"timestamp": 1631448901591, "ltp": 1.28, "tv": 21433.9, "trd": NaN, "batb": [[0, 1.28, 669.54]], "batl": NaN}, {"timestamp": 1631448902966, "ltp": 1.28, "tv": 21433.9, "trd": NaN, "batb": [[2, 1.26, 55.48]], "batl": NaN}, {"timestamp": 1631448905270, "ltp": 1.28, "tv": 21433.9, "trd": NaN, "batb": NaN, "batl": [[1, 1.32, 551.22]]}, {"timestamp": 1631448906546, "ltp": 1.28, "tv": 21433.9, "trd": NaN, "batb": [[0, 1.28, 619.88], [2, 1.26, 81.97]], "batl": [[1, 1.32, 516.22]]}, {"timestamp": 1631448907377, "ltp": 1.28, "tv": 21433.9, "trd": NaN, "batb": [[0, 1.26, 26.8], [1, 1.22, 53.84], [2, 1.17, 314.09]], "batl": [[0, 1.32, 21.53], [1, 1.33, 7], [2, 1.94, 8.68]]}, {"timestamp": 1631448910388, "ltp": 1.28, "tv": 21433.9, "trd": NaN, "batb": [[1, 1.25, 946.1], [2, 1.24, 738.99]], "batl": [[0, 1.31, 39.5], [1, 1.32, 70.64], [2, 1.33, 293.43]]}, {"timestamp": 1631448910667, "ltp": 1.28, "tv": 21433.9, "trd": NaN, "batb": NaN, "batl": [[0, 1.32, 70.64], [1, 1.33, 293.43], [2, 1.34, 462.45]]}, {"timestamp": 1631448915798, "ltp": 1.28, "tv": 21433.9, "trd": NaN, "batb": NaN, "batl": [[1, 1.33, 7], [2, 1.94, 8.68]]}, {"timestamp": 1631448917479, "ltp": 1.28, "tv": 21433.9, "trd": NaN, "batb": [[0, 1.29, 1482.87], [1, 1.28, 1438.96], [2, 1.27, 1438.96]], "batl": [[0, 1.32, 49.11]]}, {"timestamp": 1631448918506, "ltp": 1.29, "tv": 21448.88, "trd": [[1.29, 1644.69], [1.3, 399.93]], "batb": [[0, 1.29, 66.95], [1, 1.28, 71.95], [2, 1.27, 71.95]], "batl": NaN}, {"timestamp": 1631448919410, "ltp": 1.28, "tv": 21726.68, "trd": [[1.28, 201.76], [1.29, 1778.59]], "batb": [[0, 1.27, 71.95], [1, 1.25, 746.89], [2, 1.22, 53.84]], "batl": [[0, 1.28, 336.52], [1, 1.29, 559.32], [2, 1.31, 8]]}, {"timestamp": 1631448920596, "ltp": 1.28, "tv": 21726.68, "trd": NaN, "batb": [[1, 1.25, 754.89], [2, 1.24, 8]], "batl": NaN}, {"timestamp": 1631448921583, "ltp": 1.28, "tv": 21726.68, "trd": NaN, "batb": NaN, "batl": [[2, 1.31, 119.55]]}, {"timestamp": 1631448922214, "ltp": 1.28, "tv": 21726.68, "trd": NaN, "batb": NaN, "batl": [[2, 1.31, 141.24]]}, {"timestamp": 1631448923480, "ltp": 1.27, "tv": 21833.64, "trd": [[1.27, 106.96]], "batb": [[0, 1.27, 18.47], [1, 1.26, 257.18], [2, 1.25, 754.89]], "batl": [[0, 1.28, 416.76]]}, {"timestamp": 1631448924306, "ltp": 1.27, "tv": 21870.58, "trd": [[1.27, 143.9]], "batb": [[0, 1.26, 257.18], [1, 1.25, 754.89], [2, 1.24, 8]], "batl": [[0, 1.27, 3.91], [1, 1.28, 416.76], [2, 1.29, 559.32]]}, {"timestamp": 1631448925812, "ltp": 1.27, "tv": 21870.58, "trd": NaN, "batb": NaN, "batl": [[2, 1.29, 601.82]]}, {"timestamp": 1631448927609, "ltp": 1.27, "tv": 21870.58, "trd": NaN, "batb": NaN, "batl": [[1, 1.28, 462.1]]}, {"timestamp": 1631448933510, "ltp": 1.27, "tv": 21870.58, "trd": NaN, "batb": [[2, 1.23, 50.63]], "batl": NaN}, {"timestamp": 1631448934137, "ltp": 1.27, "tv": 21870.58, "trd": NaN, "batb": [[0, 1.21, 60.69], [1, 1.19, 66.2], [2, 1.1, 296.65]], "batl": [[1, 1.29, 42.5], [2, 1.32, 9]]}, {"timestamp": 1631448935009, "ltp": 1.27, "tv": 21870.58, "trd": NaN, "batb": [[1, 1.1, 296.65], [2, 1.05, 474.54]], "batl": NaN}, {"timestamp": 1631448937449, "ltp": 1.27, "tv": 21870.58, "trd": NaN, "batb": [[0, 1.23, 67.63], [1, 1.22, 3], [2, 1.21, 64.69]], "batl": [[1, 1.28, 46.09], [2, 1.29, 42.5]]}, {"timestamp": 1631448937721, "ltp": 1.27, "tv": 21870.58, "trd": NaN, "batb": [[0, 1.23, 4]], "batl": [[1, 1.29, 42.5], [2, 1.32, 9]]}, {"timestamp": 1631448939226, "ltp": 1.27, "tv": 21870.58, "trd": NaN, "batb": [[2, 1.21, 97.49]], "batl": NaN}, {"timestamp": 1631448941210, "ltp": 1.27, "tv": 21870.58, "trd": NaN, "batb": [[0, 1.25, 572.23], [1, 1.24, 729.97], [2, 1.23, 4]], "batl": [[1, 1.28, 759.39], [2, 1.29, 595.01]]}, {"timestamp": 1631448944439, "ltp": 1.27, "tv": 21870.58, "trd": NaN, "batb": [[0, 1.23, 57.63], [1, 1.22, 3], [2, 1.21, 97.49]], "batl": [[1, 1.28, 41.09], [2, 1.29, 42.5]]}, {"timestamp": 1631448944807, "ltp": 1.27, "tv": 21870.58, "trd": NaN, "batb": [[0, 1.23, 4]], "batl": [[1, 1.29, 42.5], [2, 1.32, 9]]}, {"timestamp": 1631448947032, "ltp": 1.27, "tv": 21870.58, "trd": NaN, "batb": [[0, 1.23, 485.63], [1, 1.22, 810.94]], "batl": [[2, 1.31, 607.68]]}, {"timestamp": 1631448948438, "ltp": 1.27, "tv": 21870.58, "trd": NaN, "batb": [[0, 1.23, 550.26], [1, 1.22, 807.94]], "batl": NaN}, {"timestamp": 1631448949535, "ltp": 1.27, "tv": 21870.58, "trd": NaN, "batb": [[0, 1.23, 4], [1, 1.21, 93.49], [2, 1.1, 296.65]], "batl": NaN}, {"timestamp": 1631448950547, "ltp": 1.27, "tv": 21874.49, "trd": [[1.27, 147.81]], "batb": [[1, 1.21, 60.69]], "batl": [[0, 1.29, 42.5], [1, 1.31, 607.68], [2, 1.32, 501.33]]}, {"timestamp": 1631448951442, "ltp": 1.27, "tv": 21874.49, "trd": NaN, "batb": [[0, 1.26, 24.98], [1, 1.23, 4], [2, 1.21, 60.69]], "batl": NaN}, {"timestamp": 1631448952535, "ltp": 1.27, "tv": 21874.49, "trd": NaN, "batb": [[0, 1.28, 506.99], [1, 1.27, 631.05], [2, 1.26, 24.98]], "batl": [[2, 1.32, 492.33]]}, {"timestamp": 1631448953455, "ltp": 1.28, "tv": 21926.09, "trd": [[1.28, 253.36]], "batb": [[0, 1.28, 481.19]], "batl": NaN}, {"timestamp": 1631448956342, "ltp": 1.28, "tv": 21966.49, "trd": [[1.28, 293.76]], "batb": [[0, 1.28, 460.99]], "batl": NaN}, {"timestamp": 1631448957829, "ltp": 1.28, "tv": 21966.49, "trd": NaN, "batb": [[0, 1.28, 504.37]], "batl": [[1, 1.31, 647.18]]}, {"timestamp": 1631448959641, "ltp": 1.28, "tv": 22028.05, "trd": [[1.28, 355.32]], "batb": [[0, 1.28, 473.59]], "batl": NaN}, {"timestamp": 1631448963183, "ltp": 1.28, "tv": 22028.05, "trd": NaN, "batb": [[0, 1.28, 518.07]], "batl": NaN}, {"timestamp": 1631448968492, "ltp": 1.28, "tv": 22028.05, "trd": NaN, "batb": [[2, 1.26, 32.98]], "batl": NaN}, {"timestamp": 1631448972377, "ltp": 1.28, "tv": 22028.05, "trd": NaN, "batb": [[0, 1.26, 8], [1, 1.24, 28.7], [2, 1.23, 4]], "batl": [[0, 1.28, 605.94], [1, 1.33, 37.5], [2, 1.94, 8.68]]}, {"timestamp": 1631448972714, "ltp": 1.28, "tv": 22028.05, "trd": NaN, "batb": [[0, 1.24, 28.7], [1, 1.23, 4], [2, 1.21, 60.69]], "batl": NaN}, {"timestamp": 1631448975403, "ltp": 1.28, "tv": 22028.05, "trd": NaN, "batb": [[0, 1.24, 74.47]], "batl": [[1, 1.31, 38.5], [2, 1.33, 37.5]]}, {"timestamp": 1631448976537, "ltp": 1.28, "tv": 22028.05, "trd": NaN, "batb": [[0, 1.24, 9]], "batl": NaN}, {"timestamp": 1631448979290, "ltp": 1.28, "tv": 22028.05, "trd": NaN, "batb": [[0, 1.27, 707.12], [1, 1.26, 665.83], [2, 1.24, 9]], "batl": [[1, 1.3, 490.3], [2, 1.31, 553.1]]}, {"timestamp": 1631448982517, "ltp": 1.28, "tv": 22028.05, "trd": NaN, "batb": [[2, 1.24, 67.02]], "batl": NaN}, {"timestamp": 1631448983527, "ltp": 1.28, "tv": 22028.05, "trd": NaN, "batb": NaN, "batl": [[0, 1.3, 490.3], [1, 1.31, 553.1], [2, 1.33, 37.5]]}, {"timestamp": 1631448984412, "ltp": 1.28, "tv": 22028.05, "trd": NaN, "batb": [[0, 1.27, 52.63], [1, 1.24, 9], [2, 1.23, 4]], "batl": [[0, 1.33, 37.5], [1, 1.94, 8.68], [2, 8.8, 7.23]]}, {"timestamp": 1631448984722, "ltp": 1.28, "tv": 22028.05, "trd": NaN, "batb": [[0, 1.24, 9], [1, 1.23, 4], [2, 1.22, 31.31]], "batl": NaN}, {"timestamp": 1631448986428, "ltp": 1.28, "tv": 22028.05, "trd": NaN, "batb": NaN, "batl": [[0, 1.27, 605.94], [1, 1.33, 37.5], [2, 1.94, 8.68]]}, {"timestamp": 1631448987517, "ltp": 1.28, "tv": 22028.05, "trd": NaN, "batb": [[0, 1.25, 393.67], [1, 1.24, 735.45]], "batl": [[1, 1.31, 8], [2, 1.32, 7]]}, {"timestamp": 1631448987615, "ltp": 1.28, "tv": 22028.05, "trd": NaN, "batb": [[1, 1.24, 796.22]], "batl": [[1, 1.31, 51.5]]}, {"timestamp": 1631448990408, "ltp": 1.28, "tv": 22028.05, "trd": NaN, "batb": [[0, 1.24, 9], [1, 1.22, 31.31], [2, 1.21, 60.69]], "batl": NaN}, {"timestamp": 1631448992517, "ltp": 1.27, "tv": 23239.93, "trd": [[1.27, 1359.69]], "batb": [[0, 1.3, 1493.55], [1, 1.29, 944.94], [2, 1.28, 1427.88]], "batl": [[0, 1.31, 43.5], [1, 1.32, 60.55], [2, 1.33, 37.5]]}, {"timestamp": 1631448993534, "ltp": 1.27, "tv": 23239.93, "trd": NaN, "batb": [[0, 1.31, 322.34], [1, 1.3, 1360.47], [2, 1.29, 785.33]], "batl": [[0, 1.32, 60.55], [1, 1.33, 37.5], [2, 1.34, 610.91]]}, {"timestamp": 1631448995318, "ltp": 1.27, "tv": 23239.93, "trd": NaN, "batb": [[0, 1.31, 344.56], [2, 1.29, 809.08]], "batl": NaN}, {"timestamp": 1631448996232, "ltp": 1.27, "tv": 23239.93, "trd": NaN, "batb": [[0, 1.31, 322.34], [2, 1.29, 785.33]], "batl": NaN}, {"timestamp": 1631449000056, "ltp": 1.27, "tv": 23239.93, "trd": NaN, "batb": NaN, "batl": [[2, 1.34, 652.16]]}, {"timestamp": 1631449004305, "ltp": 1.32, "tv": 23361.03, "trd": [[1.32, 238.42]], "batb": [[0, 1.32, 6.45], [1, 1.31, 322.34], [2, 1.3, 1360.47]], "batl": [[0, 1.33, 37.5], [1, 1.34, 652.16], [2, 1.35, 440.88]]}, {"timestamp": 1631449007260, "ltp": 1.32, "tv": 23361.03, "trd": NaN, "batb": NaN, "batl": [[1, 1.34, 609.37]]}, {"timestamp": 1631449008271, "ltp": 1.32, "tv": 23361.39, "trd": [[1.32, 238.78]], "batb": [[0, 1.32, 6.27]], "batl": [[2, 1.35, 472.98]]}, {"timestamp": 1631449010360, "ltp": 1.32, "tv": 23361.39, "trd": NaN, "batb": [[1, 1.31, 366.18]], "batl": NaN}, {"timestamp": 1631449011897, "ltp": 1.32, "tv": 23361.39, "trd": NaN, "batb": [[0, 1.31, 366.18], [1, 1.3, 1360.47], [2, 1.29, 785.33]], "batl": NaN}, {"timestamp": 1631449014564, "ltp": 1.32, "tv": 23361.39, "trd": NaN, "batb": NaN, "batl": [[1, 1.34, 571.28]]}, {"timestamp": 1631449015004, "ltp": 1.31, "tv": 23839.77, "trd": [[1.31, 737.85]], "batb": [[0, 1.31, 126.99]], "batl": NaN}, {"timestamp": 1631449016386, "ltp": 1.31, "tv": 23839.77, "trd": NaN, "batb": [[1, 1.3, 551.34], [2, 1.27, 59.87]], "batl": [[0, 1.34, 571.28], [1, 1.35, 472.98], [2, 1.72, 877.31]]}, {"timestamp": 1631449017500, "ltp": 1.31, "tv": 23839.77, "trd": NaN, "batb": [[0, 1.26, 26.49], [1, 1.24, 51.77], [2, 1.23, 46.5]], "batl": [[0, 1.35, 32.1], [1, 1.72, 877.31], [2, 1.94, 8.68]]}, {"timestamp": 1631449020072, "ltp": 1.31, "tv": 23839.77, "trd": NaN, "batb": [[0, 1.33, 3.9], [1, 1.28, 383.88], [2, 1.27, 629.7]], "batl": [[0, 1.34, 8], [1, 1.35, 32.1], [2, 1.36, 324]]}, {"timestamp": 1631449021106, "ltp": 1.31, "tv": 23839.77, "trd": NaN, "batb": [[2, 1.27, 676.57]], "batl": [[1, 1.35, 40.1]]}, {"timestamp": 1631449023514, "ltp": 1.31, "tv": 23839.77, "trd": NaN, "batb": [[1, 1.27, 46.87], [2, 1.25, 27.55]], "batl": NaN}, {"timestamp": 1631449024592, "ltp": 1.31, "tv": 23839.77, "trd": NaN, "batb": [[1, 1.32, 72.44], [2, 1.31, 70.31]], "batl": [[0, 1.35, 32.1], [1, 1.36, 324], [2, 1.37, 415.1]]}, {"timestamp": 1631449025289, "ltp": 1.31, "tv": 23839.77, "trd": NaN, "batb": [[0, 1.32, 72.44], [1, 1.31, 70.31], [2, 1.3, 70.31]], "batl": NaN}, {"timestamp": 1631449026576, "ltp": 1.31, "tv": 23839.77, "trd": NaN, "batb": [[0, 1.33, 527.35], [1, 1.32, 1308.8], [2, 1.31, 773.44]], "batl": NaN}, {"timestamp": 1631449027597, "ltp": 1.31, "tv": 23839.77, "trd": NaN, "batb": [[0, 1.33, 546.85]], "batl": NaN}, {"timestamp": 1631449029378, "ltp": 1.31, "tv": 23839.77, "trd": NaN, "batb": [[0, 1.33, 567.73]], "batl": NaN}, {"timestamp": 1631449037199, "ltp": 1.35, "tv": 23848.21, "trd": [[1.35, 976.72]], "batb": NaN, "batl": [[0, 1.35, 23.66]]}, {"timestamp": 1631449040409, "ltp": 1.35, "tv": 23856.01, "trd": [[1.35, 984.52]], "batb": NaN, "batl": [[0, 1.35, 19.76]]}, {"timestamp": 1631449044712, "ltp": 1.33, "tv": 24031.91, "trd": [[1.33, 343.8]], "batb": [[0, 1.33, 479.78]], "batl": NaN}, {"timestamp": 1631449047555, "ltp": 1.33, "tv": 24031.91, "trd": NaN, "batb": [[0, 1.33, 458.9]], "batl": NaN}, {"timestamp": 1631449048454, "ltp": 1.35, "tv": 24046.52, "trd": [[1.35, 999.13]], "batb": [[0, 1.33, 509.84]], "batl": [[0, 1.35, 5.15]]}, {"timestamp": 1631449051140, "ltp": 1.35, "tv": 24046.52, "trd": NaN, "batb": NaN, "batl": [[1, 1.36, 364.26]]}, {"timestamp": 1631449054547, "ltp": 1.35, "tv": 24046.52, "trd": NaN, "batb": [[0, 1.26, 26.49], [1, 1.25, 51.49], [2, 1.24, 37.49]], "batl": [[0, 1.41, 30.5], [1, 1.45, 26.7], [2, 1.72, 877.31]]}, {"timestamp": 1631449054661, "ltp": 1.35, "tv": 24046.52, "trd": NaN, "batb": NaN, "batl": [[0, 1.45, 26.7], [1, 1.72, 877.31], [2, 1.94, 8.68]]}, {"timestamp": 1631449057528, "ltp": 1.35, "tv": 24046.52, "trd": NaN, "batb": [[0, 1.29, 550.73], [1, 1.28, 606.18], [2, 1.26, 26.49]], "batl": [[0, 1.41, 8], [1, 1.43, 523.79], [2, 1.44, 331.14]]}, {"timestamp": 1631449058233, "ltp": 1.35, "tv": 24046.52, "trd": NaN, "batb": [[1, 1.28, 650.09], [2, 1.27, 9]], "batl": [[1, 1.42, 8], [2, 1.43, 523.79]]}, {"timestamp": 1631449059349, "ltp": 1.35, "tv": 24046.52, "trd": NaN, "batb": NaN, "batl": [[0, 1.33, 68.89], [1, 1.41, 8], [2, 1.42, 8]]}, {"timestamp": 1631449060158, "ltp": 1.35, "tv": 24046.52, "trd": NaN, "batb": NaN, "batl": [[1, 1.4, 7], [2, 1.41, 8]]}, {"timestamp": 1631449061430, "ltp": 1.35, "tv": 24046.52, "trd": NaN, "batb": NaN, "batl": [[2, 1.41, 40.5]]}, {"timestamp": 1631449061657, "ltp": 1.35, "tv": 24046.52, "trd": NaN, "batb": NaN, "batl": [[2, 1.41, 8]]}, {"timestamp": 1631449063072, "ltp": 1.35, "tv": 24046.52, "trd": NaN, "batb": NaN, "batl": [[0, 1.4, 7], [1, 1.41, 8], [2, 1.42, 8]]}, {"timestamp": 1631449064449, "ltp": 1.35, "tv": 24046.52, "trd": NaN, "batb": NaN, "batl": [[0, 1.32, 5403.18], [1, 1.33, 1437.97], [2, 1.34, 1395.68]]}, {"timestamp": 1631449065039, "ltp": 1.35, "tv": 24046.52, "trd": NaN, "batb": NaN, "batl": [[0, 1.33, 71.9], [1, 1.34, 69.78], [2, 1.35, 69.78]]}, {"timestamp": 1631449066474, "ltp": 1.35, "tv": 24046.52, "trd": NaN, "batb": NaN, "batl": [[0, 1.33, 1509.87], [1, 1.34, 1465.46], [2, 1.35, 1465.46]]}, {"timestamp": 1631449067441, "ltp": 1.35, "tv": 24046.52, "trd": NaN, "batb": NaN, "batl": [[0, 1.32, 511.44], [1, 1.33, 1267.98], [2, 1.34, 774.62]]}, {"timestamp": 1631449069570, "ltp": 1.35, "tv": 24046.52, "trd": NaN, "batb": [[0, 1.29, 599.89]], "batl": [[1, 1.33, 1317.97]]}, {"timestamp": 1631449083160, "ltp": 1.29, "tv": 24050.52, "trd": [[1.29, 1782.59]], "batb": [[0, 1.29, 597.89]], "batl": NaN}, {"timestamp": 1631449084488, "ltp": 1.29, "tv": 24050.52, "trd": NaN, "batb": [[0, 1.27, 9], [1, 1.25, 51.49], [2, 1.22, 65.34]], "batl": [[0, 1.29, 137.77], [1, 1.35, 37.1], [2, 1.38, 29.75]]}, {"timestamp": 1631449084876, "ltp": 1.29, "tv": 24050.52, "trd": NaN, "batb": [[0, 1.22, 65.34], [1, 1.1, 296.65], [2, 1.05, 474.54]], "batl": [[1, 1.38, 29.75], [2, 1.4, 7]]}, {"timestamp": 1631449085689, "ltp": 1.29, "tv": 24050.52, "trd": NaN, "batb": [[0, 1.23, 29.95], [1, 1.22, 65.34], [2, 1.1, 296.65]], "batl": NaN}, {"timestamp": 1631449087591, "ltp": 1.29, "tv": 24050.52, "trd": NaN, "batb": [[0, 1.26, 505.62], [1, 1.25, 695.39], [2, 1.23, 29.95]], "batl": [[0, 1.34, 8], [1, 1.35, 7], [2, 1.37, 346.13]]}, {"timestamp": 1631449088180, "ltp": 1.29, "tv": 24050.52, "trd": NaN, "batb": [[1, 1.25, 750.72]], "batl": NaN}, {"timestamp": 1631449089399, "ltp": 1.29, "tv": 24050.52, "trd": NaN, "batb": [[0, 1.23, 41.95], [1, 1.22, 78.34], [2, 1.21, 10]], "batl": [[0, 1.34, 8.99], [2, 1.38, 29.75]]}, {"timestamp": 1631449089981, "ltp": 1.29, "tv": 24050.52, "trd": NaN, "batb": NaN, "batl": [[0, 1.29, 12.02], [1, 1.34, 8], [2, 1.35, 7]]}, {"timestamp": 1631449091481, "ltp": 1.29, "tv": 24062.54, "trd": [[1.29, 1794.6]], "batb": NaN, "batl": [[0, 1.34, 8], [1, 1.35, 42.1], [2, 1.38, 29.75]]}, {"timestamp": 1631449092592, "ltp": 1.29, "tv": 24062.54, "trd": NaN, "batb": [[0, 1.3, 522.98], [1, 1.29, 579.62], [2, 1.25, 54.17]], "batl": [[0, 1.33, 479.46], [1, 1.34, 507.95], [2, 1.35, 7]]}, {"timestamp": 1631449093484, "ltp": 1.29, "tv": 24062.54, "trd": NaN, "batb": [[2, 1.26, 26.49]], "batl": NaN}, {"timestamp": 1631449094911, "ltp": 1.29, "tv": 24062.54, "trd": NaN, "batb": NaN, "batl": [[2, 1.35, 41.3]]}, {"timestamp": 1631449095991, "ltp": 1.29, "tv": 24062.54, "trd": NaN, "batb": [[0, 1.3, 567.93]], "batl": NaN}, {"timestamp": 1631449099326, "ltp": 1.29, "tv": 24062.54, "trd": NaN, "batb": [[0, 1.26, 26.49], [1, 1.25, 27.55], [2, 1.23, 41.95]], "batl": [[0, 1.34, 8], [1, 1.38, 29.75], [2, 1.94, 8.68]]}, {"timestamp": 1631449101519, "ltp": 1.29, "tv": 24062.54, "trd": NaN, "batb": [[0, 1.23, 12], [1, 1.22, 65.34], [2, 1.1, 296.65]], "batl": NaN}, {"timestamp": 1631449102538, "ltp": 1.29, "tv": 24062.54, "trd": NaN, "batb": [[0, 1.26, 505.62], [1, 1.25, 740.4], [2, 1.23, 12]], "batl": [[1, 1.37, 346.13], [2, 1.38, 431.15]]}, {"timestamp": 1631449105543, "ltp": 1.29, "tv": 24062.54, "trd": NaN, "batb": [[2, 1.23, 41.95]], "batl": [[1, 1.35, 31.3], [2, 1.37, 346.13]]}, {"timestamp": 1631449106246, "ltp": 1.29, "tv": 24062.54, "trd": NaN, "batb": NaN, "batl": [[0, 1.27, 593.14], [1, 1.34, 8]]}, {"timestamp": 1631449107321, "ltp": 1.26, "tv": 24162.54, "trd": [[1.26, 100]], "batb": [[0, 1.26, 455.62]], "batl": NaN}, {"timestamp": 1631449108547, "ltp": 1.27, "tv": 24283.63, "trd": [[1.27, 1480.78]], "batb": NaN, "batl": [[0, 1.27, 610.59]]}, {"timestamp": 1631449109520, "ltp": 1.27, "tv": 24283.63, "trd": NaN, "batb": NaN, "batl": [[2, 1.35, 39.1]]}, {"timestamp": 1631449112939, "ltp": 1.27, "tv": 24283.63, "trd": NaN, "batb": NaN, "batl": [[0, 1.27, 532.59]]}, {"timestamp": 1631449114436, "ltp": 1.27, "tv": 25308.49, "trd": [[1.27, 2505.64]], "batb": NaN, "batl": [[0, 1.27, 20.16]]}, {"timestamp": 1631449114820, "ltp": 1.27, "tv": 25308.49, "trd": NaN, "batb": NaN, "batl": [[2, 1.37, 346.13]]}, {"timestamp": 1631449116137, "ltp": 1.34, "tv": 25364.81, "trd": [[1.27, 2545.96], [1.34, 98.05]], "batb": [[0, 1.34, 7538.2], [1, 1.33, 71.9], [2, 1.32, 69.78]], "batl": [[0, 1.37, 346.13], [1, 1.38, 431.15], [2, 1.94, 8.68]]}, {"timestamp": 1631449118838, "ltp": 1.34, "tv": 25364.81, "trd": NaN, "batb": NaN, "batl": [[0, 1.35, 8], [1, 1.37, 346.13], [2, 1.38, 431.15]]}, {"timestamp": 1631449121520, "ltp": 1.34, "tv": 25364.81, "trd": NaN, "batb": NaN, "batl": [[0, 1.35, 40.9], [1, 1.36, 9], [2, 1.37, 346.13]]}, {"timestamp": 1631449122031, "ltp": 1.34, "tv": 25364.81, "trd": NaN, "batb": NaN, "batl": [[0, 1.35, 8]]}, {"timestamp": 1631449128480, "ltp": 1.34, "tv": 25364.81, "trd": NaN, "batb": NaN, "batl": [[0, 1.35, 42.1]]}, {"timestamp": 1631449129217, "ltp": 1.34, "tv": 25436.31, "trd": [[1.34, 169.55]], "batb": [[0, 1.34, 7502.45]], "batl": [[0, 1.35, 8]]}, {"timestamp": 1631449132613, "ltp": 1.34, "tv": 25477.95, "trd": [[1.34, 211.19]], "batb": [[0, 1.34, 7481.63]], "batl": NaN}, {"timestamp": 1631449135321, "ltp": 1.34, "tv": 25477.95, "trd": NaN, "batb": NaN, "batl": [[0, 1.35, 44.9]]}, {"timestamp": 1631449135600, "ltp": 1.34, "tv": 25477.95, "trd": NaN, "batb": NaN, "batl": [[0, 1.35, 8], [1, 1.37, 346.13], [2, 1.38, 431.15]]}, {"timestamp": 1631449140531, "ltp": 1.34, "tv": 27527.66, "trd": [[1.34, 2260.9]], "batb": [[0, 1.34, 6456.78]], "batl": NaN}, {"timestamp": 1631449142300, "ltp": 1.34, "tv": 27527.66, "trd": NaN, "batb": [[1, 1.26, 455.62], [2, 1.25, 740.4]], "batl": [[0, 1.35, 41.5]]}, {"timestamp": 1631449143102, "ltp": 1.34, "tv": 27531.63, "trd": [[1.34, 2264.87]], "batb": [[0, 1.34, 6454.79]], "batl": [[0, 1.35, 8]]}, {"timestamp": 1631449144218, "ltp": 1.34, "tv": 27565.53, "trd": [[1.34, 2298.77]], "batb": [[0, 1.34, 6437.84]], "batl": NaN}, {"timestamp": 1631449145295, "ltp": 1.34, "tv": 27595.45, "trd": [[1.34, 2328.69]], "batb": [[0, 1.34, 6422.88]], "batl": NaN}, {"timestamp": 1631449149602, "ltp": 1.34, "tv": 27595.45, "trd": NaN, "batb": NaN, "batl": [[1, 1.38, 29.75], [2, 1.94, 8.96]]}, {"timestamp": 1631449152536, "ltp": 1.34, "tv": 39759.07, "trd": [[1.34, 14492.31]], "batb": [[0, 1.34, 341.07]], "batl": NaN}, {"timestamp": 1631449153505, "ltp": 1.34, "tv": 39759.07, "trd": NaN, "batb": [[0, 1.26, 455.62], [1, 1.25, 45.01], [2, 1.23, 12]], "batl": [[0, 1.3, 8], [1, 1.35, 8], [2, 1.38, 29.75]]}, {"timestamp": 1631449154521, "ltp": 1.34, "tv": 39759.07, "trd": NaN, "batb": NaN, "batl": [[1, 1.34, 355.13], [2, 1.35, 8]]}, {"timestamp": 1631449155421, "ltp": 1.34, "tv": 39759.07, "trd": NaN, "batb": NaN, "batl": [[1, 1.34, 1363.51]]}, {"timestamp": 1631449156537, "ltp": 1.34, "tv": 39759.07, "trd": NaN, "batb": [[0, 1.26, 496.47]], "batl": [[1, 1.34, 1370.51]]}, {"timestamp": 1631449157329, "ltp": 1.27, "tv": 39779.03, "trd": [[1.27, 2565.92]], "batb": [[0, 1.23, 12], [1, 1.22, 65.34], [2, 1.1, 296.65]], "batl": [[0, 1.34, 151.66], [1, 1.35, 8], [2, 1.38, 29.75]]}, {"timestamp": 1631449158504, "ltp": 1.27, "tv": 39779.03, "trd": NaN, "batb": NaN, "batl": [[0, 1.34, 144.77]]}, {"timestamp": 1631449159302, "ltp": 1.27, "tv": 39779.03, "trd": NaN, "batb": NaN, "batl": [[0, 1.33, 34.5], [1, 1.34, 209.77], [2, 1.35, 8]]}, {"timestamp": 1631449160108, "ltp": 1.27, "tv": 39779.03, "trd": NaN, "batb": [[0, 1.25, 256.62], [1, 1.24, 712.22], [2, 1.23, 12]], "batl": [[0, 1.33, 358.98], [1, 1.34, 664.2]]}, {"timestamp": 1631449161505, "ltp": 1.27, "tv": 39779.03, "trd": NaN, "batb": [[1, 1.24, 719.66]], "batl": [[0, 1.33, 34.5], [1, 1.34, 144.77]]}, {"timestamp": 1631449162515, "ltp": 1.27, "tv": 39779.03, "trd": NaN, "batb": [[1, 1.24, 771.68]], "batl": [[0, 1.27, 1464.86], [1, 1.31, 37.5], [2, 1.33, 34.5]]}, {"timestamp": 1631449163535, "ltp": 1.27, "tv": 39779.03, "trd": NaN, "batb": [[1, 1.24, 764.24]], "batl": [[0, 1.27, 4980.4], [1, 1.33, 34.5], [2, 1.34, 7]]}, {"timestamp": 1631449164446, "ltp": 1.27, "tv": 39779.03, "trd": NaN, "batb": NaN, "batl": [[0, 1.27, 567.37], [1, 1.28, 574.29], [2, 1.29, 8]]}, {"timestamp": 1631449165565, "ltp": 1.27, "tv": 39779.03, "trd": NaN, "batb": NaN, "batl": [[1, 1.28, 589.29]]}, {"timestamp": 1631449166325, "ltp": 1.27, "tv": 39779.03, "trd": NaN, "batb": [[0, 1.24, 764.24], [1, 1.23, 12], [2, 1.22, 76.34]], "batl": [[0, 1.27, 615.03]]}, {"timestamp": 1631449168449, "ltp": 1.24, "tv": 39853.39, "trd": [[1.24, 512.41]], "batb": [[0, 1.24, 727.06]], "batl": NaN}, {"timestamp": 1631449169464, "ltp": 1.24, "tv": 39853.39, "trd": NaN, "batb": [[0, 1.24, 1010.3], [1, 1.23, 756.28]], "batl": [[0, 1.25, 80], [1, 1.27, 615.03], [2, 1.28, 589.29]]}, {"timestamp": 1631449170156, "ltp": 1.24, "tv": 39853.39, "trd": NaN, "batb": [[1, 1.23, 809.91]], "batl": [[1, 1.26, 6.89], [2, 1.27, 663.53]]}, {"timestamp": 1631449171441, "ltp": 1.24, "tv": 39853.39, "trd": NaN, "batb": NaN, "batl": [[0, 1.25, 580]]}, {"timestamp": 1631449172558, "ltp": 1.24, "tv": 39853.39, "trd": NaN, "batb": [[2, 1.22, 65.34]], "batl": NaN}, {"timestamp": 1631449173438, "ltp": 1.24, "tv": 39853.39, "trd": NaN, "batb": NaN, "batl": [[0, 1.25, 500]]}, {"timestamp": 1631449175352, "ltp": 1.24, "tv": 39853.39, "trd": NaN, "batb": NaN, "batl": [[0, 1.26, 6.89], [1, 1.27, 624.58], [2, 1.28, 633.38]]}, {"timestamp": 1631449178461, "ltp": 1.24, "tv": 40853.78, "trd": [[1.24, 1512.41], [1.26, 100.39]], "batb": [[0, 1.24, 510.3]], "batl": [[0, 1.26, 6.69]]}, {"timestamp": 1631449179258, "ltp": 1.24, "tv": 40853.78, "trd": NaN, "batb": NaN, "batl": [[0, 1.25, 137.77], [1, 1.26, 6.69], [2, 1.27, 624.58]]}, {"timestamp": 1631449181541, "ltp": 1.24, "tv": 41029.78, "trd": [[1.24, 1688.41]], "batb": [[0, 1.23, 489.28], [1, 1.22, 65.34], [2, 1.21, 63.69]], "batl": [[2, 1.27, 48.5]]}, {"timestamp": 1631449184584, "ltp": 1.24, "tv": 41029.78, "trd": NaN, "batb": [[0, 1.24, 52.27], [1, 1.23, 489.28], [2, 1.22, 866.66]], "batl": [[0, 1.26, 6.69], [1, 1.27, 48.5], [2, 1.29, 596.84]]}, {"timestamp": 1631449184955, "ltp": 1.24, "tv": 41029.78, "trd": NaN, "batb": [[0, 1.23, 489.28], [1, 1.22, 866.66], [2, 1.21, 63.69]], "batl": NaN}, {"timestamp": 1631449186371, "ltp": 1.24, "tv": 41029.78, "trd": NaN, "batb": [[2, 1.05, 474.54]], "batl": [[2, 1.32, 7]]}, {"timestamp": 1631449187276, "ltp": 1.26, "tv": 41032.57, "trd": [[1.26, 103.17]], "batb": NaN, "batl": [[0, 1.24, 137.77], [1, 1.26, 16.3], [2, 1.27, 48.5]]}, {"timestamp": 1631449188140, "ltp": 1.24, "tv": 41131.61, "trd": [[1.24, 1787.45]], "batb": NaN, "batl": [[0, 1.24, 88.25]]}, {"timestamp": 1631449189368, "ltp": 1.24, "tv": 41151.61, "trd": [[1.24, 1807.45]], "batb": [[2, 1.18, 13.52]], "batl": [[0, 1.24, 78.25], [1, 1.25, 447.06], [2, 1.26, 639.83]]}, {"timestamp": 1631449190477, "ltp": 1.24, "tv": 41151.61, "trd": NaN, "batb": NaN, "batl": [[1, 1.25, 462.06], [2, 1.26, 673.28]]}, {"timestamp": 1631449191597, "ltp": 1.24, "tv": 41151.61, "trd": NaN, "batb": [[0, 1.23, 434.9]], "batl": [[1, 1.25, 447.06]]}, {"timestamp": 1631449194285, "ltp": 1.24, "tv": 41151.61, "trd": NaN, "batb": NaN, "batl": [[2, 1.26, 688.28]]}, {"timestamp": 1631449196186, "ltp": 1.24, "tv": 41151.61, "trd": NaN, "batb": NaN, "batl": [[0, 1.25, 447.06], [1, 1.26, 682.98], [2, 1.27, 48.5]]}, {"timestamp": 1631449197474, "ltp": 1.23, "tv": 41158.44, "trd": [[1.23, 6.84]], "batb": [[0, 1.23, 431.48]], "batl": NaN}, {"timestamp": 1631449198492, "ltp": 1.25, "tv": 41398.44, "trd": [[1.25, 240]], "batb": NaN, "batl": [[0, 1.25, 207.06]]}, {"timestamp": 1631449199465, "ltp": 1.25, "tv": 41398.44, "trd": NaN, "batb": [[0, 1.24, 12.96], [1, 1.23, 431.48], [2, 1.22, 866.66]], "batl": NaN}, {"timestamp": 1631449200588, "ltp": 1.25, "tv": 41398.44, "trd": NaN, "batb": [[0, 1.24, 59.93]], "batl": NaN}, {"timestamp": 1631449202580, "ltp": 1.25, "tv": 41398.44, "trd": NaN, "batb": [[1, 1.23, 536.15]], "batl": [[0, 1.25, 364.68]]}, {"timestamp": 1631449204586, "ltp": 1.25, "tv": 41398.44, "trd": NaN, "batb": [[0, 1.24, 60.19]], "batl": NaN}, {"timestamp": 1631449212567, "ltp": 1.25, "tv": 41398.44, "trd": NaN, "batb": [[0, 1.24, 56.29]], "batl": NaN}, {"timestamp": 1631449215006, "ltp": 1.25, "tv": 41763.12, "trd": [[1.25, 604.68]], "batb": NaN, "batl": [[0, 1.26, 682.98], [1, 1.27, 48.5], [2, 1.28, 12.47]]}, {"timestamp": 1631449217395, "ltp": 1.25, "tv": 41763.12, "trd": NaN, "batb": [[0, 1.24, 56.54]], "batl": NaN}, {"timestamp": 1631449217899, "ltp": 1.25, "tv": 41763.12, "trd": NaN, "batb": [[1, 1.23, 692.18]], "batl": [[0, 1.26, 892.67], [1, 1.27, 640.8]]}, {"timestamp": 1631449219125, "ltp": 1.25, "tv": 41763.12, "trd": NaN, "batb": [[0, 1.25, 13.01], [1, 1.24, 56.29], [2, 1.23, 692.18]], "batl": NaN}, {"timestamp": 1631449219790, "ltp": 1.25, "tv": 41763.12, "trd": NaN, "batb": [[0, 1.25, 16.91]], "batl": NaN}, {"timestamp": 1631449223807, "ltp": 1.26, "tv": 41763.5, "trd": [[1.26, 103.55]], "batb": NaN, "batl": [[0, 1.26, 892.48]]}, {"timestamp": 1631449229416, "ltp": 1.26, "tv": 41763.5, "trd": NaN, "batb": [[1, 1.24, 56.03]], "batl": NaN}, {"timestamp": 1631449232421, "ltp": 1.25, "tv": 41765.68, "trd": [[1.25, 606.86]], "batb": [[0, 1.25, 15.83]], "batl": NaN}, {"timestamp": 1631449236219, "ltp": 1.26, "tv": 41766.03, "trd": [[1.26, 103.91]], "batb": NaN, "batl": [[0, 1.26, 892.3]]}, {"timestamp": 1631449236806, "ltp": 1.26, "tv": 41766.03, "trd": NaN, "batb": [[0, 1.25, 62.8], [1, 1.24, 9.06]], "batl": NaN}, {"timestamp": 1631449248749, "ltp": 1.26, "tv": 41766.03, "trd": NaN, "batb": [[0, 1.25, 50.87]], "batl": NaN}, {"timestamp": 1631449252758, "ltp": 1.26, "tv": 41766.03, "trd": NaN, "batb": [[0, 1.25, 46.97]], "batl": NaN}, {"timestamp": 1631449258048, "ltp": 1.26, "tv": 41766.03, "trd": NaN, "batb": [[0, 1.25, 52.82]], "batl": NaN}, {"timestamp": 1631449261944, "ltp": 1.26, "tv": 41782.03, "trd": [[1.26, 119.91]], "batb": NaN, "batl": [[0, 1.26, 884.3]]}, {"timestamp": 1631449270080, "ltp": 1.26, "tv": 41784.65, "trd": [[1.26, 122.53]], "batb": NaN, "batl": [[0, 1.26, 882.99]]}, {"timestamp": 1631449273684, "ltp": 1.26, "tv": 41808.51, "trd": [[1.26, 146.39]], "batb": NaN, "batl": [[0, 1.26, 871.06]]}, {"timestamp": 1631449281227, "ltp": 1.26, "tv": 41812.41, "trd": [[1.26, 150.28]], "batb": NaN, "batl": [[0, 1.26, 869.11]]}, {"timestamp": 1631449291845, "ltp": 1.26, "tv": 41814.17, "trd": [[1.26, 152.04]], "batb": NaN, "batl": [[0, 1.26, 868.23]]}, {"timestamp": 1631449293438, "ltp": 1.26, "tv": 41814.17, "trd": NaN, "batb": [[0, 1.25, 46.97]], "batl": NaN}, {"timestamp": 1631449301546, "ltp": 1.26, "tv": 41958.77, "trd": [[1.26, 296.64]], "batb": NaN, "batl": [[0, 1.26, 795.93]]}, {"timestamp": 1631449302329, "ltp": 1.26, "tv": 41975.85, "trd": [[1.26, 313.73]], "batb": NaN, "batl": [[0, 1.26, 787.39]]}, {"timestamp": 1631449302754, "ltp": 1.26, "tv": 41977.51, "trd": [[1.26, 315.39]], "batb": NaN, "batl": [[0, 1.26, 786.56]]}, {"timestamp": 1631449304937, "ltp": 1.26, "tv": 41977.51, "trd": NaN, "batb": [[2, 1.23, 733.92]], "batl": [[0, 1.26, 842.6]]}, {"timestamp": 1631449309986, "ltp": 1.26, "tv": 41981.41, "trd": [[1.26, 319.29]], "batb": NaN, "batl": [[0, 1.26, 840.65]]}, {"timestamp": 1631449314904, "ltp": 1.26, "tv": 41981.41, "trd": NaN, "batb": [[1, 1.24, 14.91]], "batl": NaN}, {"timestamp": 1631449316011, "ltp": 1.24, "tv": 42105.17, "trd": [[1.24, 1837.27], [1.25, 700.8]], "batb": [[0, 1.23, 733.92], [1, 1.22, 866.66], [2, 1.18, 13.52]], "batl": [[0, 1.24, 10.42], [1, 1.26, 840.65], [2, 1.27, 640.8]]}, {"timestamp": 1631449319823, "ltp": 1.24, "tv": 42105.17, "trd": NaN, "batb": NaN, "batl": [[0, 1.26, 840.65], [1, 1.27, 640.8], [2, 1.28, 12.47]]}, {"timestamp": 1631449331321, "ltp": 1.23, "tv": 42108.59, "trd": [[1.23, 10.25]], "batb": [[0, 1.23, 771.93]], "batl": NaN}, {"timestamp": 1631449332949, "ltp": 1.23, "tv": 42108.59, "trd": NaN, "batb": NaN, "batl": [[1, 1.27, 646.65]]}, {"timestamp": 1631449336250, "ltp": 1.23, "tv": 42108.59, "trd": NaN, "batb": [[2, 1.01, 30]], "batl": [[2, 1.29, 8]]}, {"timestamp": 1631449337747, "ltp": 1.23, "tv": 42108.59, "trd": NaN, "batb": NaN, "batl": [[0, 1.25, 2.56], [1, 1.26, 840.65], [2, 1.27, 646.65]]}, {"timestamp": 1631449347457, "ltp": 1.25, "tv": 42113.71, "trd": [[1.25, 705.93]], "batb": [[0, 1.25, 1.34], [1, 1.23, 771.93], [2, 1.22, 866.66]], "batl": [[0, 1.26, 840.65], [1, 1.27, 646.65], [2, 1.29, 8]]}, {"timestamp": 1631449351565, "ltp": 1.24, "tv": 42253.38, "trd": [[1.24, 1974.25], [1.25, 708.6]], "batb": [[0, 1.23, 771.93], [1, 1.22, 866.66], [2, 1.01, 30]], "batl": [[0, 1.24, 9.51], [1, 1.26, 840.65], [2, 1.27, 646.65]]}, {"timestamp": 1631449363404, "ltp": 1.24, "tv": 42263.98, "trd": [[1.24, 1984.85]], "batb": NaN, "batl": [[0, 1.24, 4.21]]}, {"timestamp": 1631449374355, "ltp": 1.24, "tv": 42268.19, "trd": [[1.24, 1989.06]], "batb": NaN, "batl": [[0, 1.26, 840.65], [1, 1.27, 646.65], [2, 1.29, 8]]}, {"timestamp": 1631449375646, "ltp": 1.25, "tv": 42274.35, "trd": [[1.25, 714.76]], "batb": NaN, "batl": NaN}, {"timestamp": 1631449377556, "ltp": 1.25, "tv": 42274.35, "trd": NaN, "batb": [[0, 1.24, 3.18], [1, 1.23, 771.93], [2, 1.22, 866.66]], "batl": NaN}, {"timestamp": 1631449383959, "ltp": 1.25, "tv": 42274.35, "trd": NaN, "batb": [[0, 1.23, 771.93], [1, 1.22, 866.66], [2, 1.21, 32.73]], "batl": NaN}, {"timestamp": 1631449386763, "ltp": 1.26, "tv": 42274.74, "trd": [[1.26, 319.69]], "batb": NaN, "batl": [[0, 1.26, 840.45]]}, {"timestamp": 1631449391771, "ltp": 1.26, "tv": 42280.05, "trd": [[1.26, 324.99]], "batb": NaN, "batl": [[0, 1.26, 837.8]]}, {"timestamp": 1631449392754, "ltp": 1.23, "tv": 42281.29, "trd": [[1.23, 11.5]], "batb": [[0, 1.23, 771.31]], "batl": NaN}, {"timestamp": 1631449410412, "ltp": 1.23, "tv": 42281.71, "trd": [[1.23, 11.92]], "batb": [[0, 1.23, 771.1]], "batl": NaN}, {"timestamp": 1631449422883, "ltp": 1.23, "tv": 42281.71, "trd": NaN, "batb": [[0, 1.24, 23], [1, 1.23, 771.1], [2, 1.22, 866.66]], "batl": NaN}, {"timestamp": 1631449448253, "ltp": 1.24, "tv": 42289.23, "trd": [[1.24, 1996.58]], "batb": [[0, 1.24, 19.24]], "batl": NaN}, {"timestamp": 1631449451966, "ltp": 1.26, "tv": 42289.63, "trd": [[1.26, 325.38]], "batb": NaN, "batl": [[0, 1.26, 837.6]]}, {"timestamp": 1631449452855, "ltp": 1.26, "tv": 42298.13, "trd": [[1.26, 333.89]], "batb": NaN, "batl": [[0, 1.26, 833.35]]}, {"timestamp": 1631449477727, "ltp": 1.26, "tv": 42300.09, "trd": [[1.26, 335.84]], "batb": NaN, "batl": [[0, 1.26, 832.37]]}, {"timestamp": 1631449514476, "ltp": 1.25, "tv": 42347.76, "trd": [[1.25, 762.44]], "batb": NaN, "batl": NaN}, {"timestamp": 1631449525988, "ltp": 1.25, "tv": 42368.58, "trd": [[1.25, 783.26]], "batb": NaN, "batl": NaN}, {"timestamp": 1631449527498, "ltp": 1.25, "tv": 42368.58, "trd": NaN, "batb": [[1, 1.21, 32.73], [2, 1.01, 30]], "batl": [[0, 1.26, 15], [1, 1.27, 5.85], [2, 1.32, 7]]}, {"timestamp": 1631449528464, "ltp": 1.25, "tv": 42368.58, "trd": NaN, "batb": [[1, 1.01, 30], [2, 1.01, 0]], "batl": [[0, 1.27, 5.85], [1, 1.32, 7], [2, 1.34, 13.01]]}, {"timestamp": 1631449530388, "ltp": 1.25, "tv": 42368.58, "trd": NaN, "batb": [[1, 1.19, 1190.88], [2, 1.18, 579.63]], "batl": [[1, 1.29, 551.5], [2, 1.3, 526.34]]}, {"timestamp": 1631449530740, "ltp": 1.25, "tv": 42368.58, "trd": NaN, "batb": [[1, 1.01, 30], [2, 1.18, 0]], "batl": [[1, 1.32, 7], [2, 1.34, 13.01]]}, {"timestamp": 1631449534491, "ltp": 1.25, "tv": 42592.27, "trd": [[1.25, 1006.95]], "batb": [[1, 1.22, 920.99], [2, 1.21, 710.51]], "batl": [[0, 1.25, 457.72], [1, 1.26, 622.37], [2, 1.27, 5.85]]}, {"timestamp": 1631449536401, "ltp": 1.25, "tv": 42693.49, "trd": [[1.25, 1108.17]], "batb": NaN, "batl": [[0, 1.25, 407.11]]}, {"timestamp": 1631449537389, "ltp": 1.25, "tv": 42693.49, "trd": NaN, "batb": [[1, 1.22, 1017.54]], "batl": [[0, 1.25, 536.69]]}, {"timestamp": 1631449538485, "ltp": 1.25, "tv": 42693.49, "trd": NaN, "batb": NaN, "batl": [[0, 1.25, 587.57]]}, {"timestamp": 1631449538706, "ltp": 1.25, "tv": 42693.49, "trd": NaN, "batb": [[1, 1.01, 30], [2, 1.21, 0]], "batl": [[0, 1.27, 5.85], [1, 1.32, 7], [2, 1.34, 13.01]]}, {"timestamp": 1631449540806, "ltp": 1.25, "tv": 42693.49, "trd": NaN, "batb": [[1, 1.2, 2], [2, 1.01, 30]], "batl": NaN}, {"timestamp": 1631449541612, "ltp": 1.25, "tv": 42693.49, "trd": NaN, "batb": [[1, 1.2, 372.53], [2, 1.19, 938.64]], "batl": [[1, 1.29, 439.51], [2, 1.3, 526.26]]}, {"timestamp": 1631449543219, "ltp": 1.24, "tv": 42731.97, "trd": [[1.24, 2035.06]], "batb": [[0, 1.2, 372.53], [1, 1.19, 938.64], [2, 1.01, 30]], "batl": [[0, 1.24, 81.76], [1, 1.27, 5.85], [2, 1.29, 439.51]]}, {"timestamp": 1631449544201, "ltp": 1.24, "tv": 42804.27, "trd": [[1.24, 2107.36]], "batb": NaN, "batl": [[0, 1.24, 45.61]]}, {"timestamp": 1631449545316, "ltp": 1.24, "tv": 42804.27, "trd": NaN, "batb": [[0, 1.2, 370.53]], "batl": NaN}, {"timestamp": 1631449552814, "ltp": 1.27, "tv": 42907.19, "trd": [[1.24, 2198.58], [1.27, 2577.62]], "batb": [[0, 1.27, 20.84], [1, 1.2, 370.53], [2, 1.19, 938.64]], "batl": [[0, 1.29, 439.51], [1, 1.3, 526.26], [2, 1.32, 7]]}, {"timestamp": 1631449555417, "ltp": 1.29, "tv": 42952.69, "trd": [[1.29, 1840.1]], "batb": NaN, "batl": [[0, 1.29, 394.01]]}, {"timestamp": 1631449556315, "ltp": 1.29, "tv": 42952.69, "trd": NaN, "batb": [[0, 1.2, 370.53], [1, 1.19, 938.64], [2, 1.01, 30]], "batl": [[0, 1.29, 404.01]]}, {"timestamp": 1631449558583, "ltp": 1.29, "tv": 42952.69, "trd": NaN, "batb": NaN, "batl": [[0, 1.29, 10], [1, 1.32, 7], [2, 1.34, 13.01]]}, {"timestamp": 1631449561203, "ltp": 1.29, "tv": 42952.69, "trd": NaN, "batb": [[2, 1.15, 13.87]], "batl": [[0, 1.22, 650.17], [1, 1.23, 716.64], [2, 1.24, 12.86]]}, {"timestamp": 1631449562413, "ltp": 1.29, "tv": 42952.69, "trd": NaN, "batb": [[2, 1.18, 35.35]], "batl": [[2, 1.24, 27.86]]}, {"timestamp": 1631449565417, "ltp": 1.29, "tv": 42952.69, "trd": NaN, "batb": NaN, "batl": [[0, 1.22, 703.65]]}, {"timestamp": 1631449566097, "ltp": 1.2, "tv": 43108.97, "trd": [[1.2, 160.28]], "batb": [[0, 1.2, 292.39], [2, 1.15, 13.87]], "batl": [[2, 1.24, 12.86]]}, {"timestamp": 1631449567433, "ltp": 1.2, "tv": 43108.97, "trd": NaN, "batb": [[2, 1.16, 83.03]], "batl": [[2, 1.24, 60.84]]}, {"timestamp": 1631449569344, "ltp": 1.2, "tv": 43108.97, "trd": NaN, "batb": [[0, 1.2, 362.73]], "batl": [[1, 1.23, 731.64]]}, {"timestamp": 1631449575328, "ltp": 1.2, "tv": 43418.91, "trd": [[1.2, 470.22]], "batb": [[0, 1.2, 207.76]], "batl": NaN}, {"timestamp": 1631449579457, "ltp": 1.21, "tv": 43538.09, "trd": [[1.21, 1450.92]], "batb": [[0, 1.2, 297.52]], "batl": [[0, 1.21, 63.41], [1, 1.22, 795.82], [2, 1.23, 731.64]]}, {"timestamp": 1631449579616, "ltp": 1.2, "tv": 43580.13, "trd": [[1.2, 470.62], [1.21, 1492.56]], "batb": [[0, 1.2, 297.32]], "batl": [[0, 1.21, 42.59]]}, {"timestamp": 1631449582739, "ltp": 1.21, "tv": 43580.57, "trd": [[1.21, 1493]], "batb": NaN, "batl": [[0, 1.21, 42.37], [2, 1.23, 790.14]]}, {"timestamp": 1631449585541, "ltp": 1.21, "tv": 43580.57, "trd": NaN, "batb": [[0, 1.16, 83.03], [1, 1.13, 635.71], [2, 1.01, 30]], "batl": [[0, 1.23, 15], [1, 1.24, 47.98], [2, 1.25, 56.18]]}, {"timestamp": 1631449586496, "ltp": 1.21, "tv": 43580.57, "trd": NaN, "batb": [[0, 1.13, 635.71], [1, 1.01, 30], [2, 1.01, 0]], "batl": [[0, 1.25, 56.18], [1, 1.26, 49.75], [2, 1.28, 10]]}, {"timestamp": 1631449588262, "ltp": 1.21, "tv": 43580.57, "trd": NaN, "batb": [[0, 1.16, 748.34], [1, 1.15, 1072.2], [2, 1.13, 635.71]], "batl": [[0, 1.25, 439.34], [1, 1.26, 678.25]]}, {"timestamp": 1631449589372, "ltp": 1.21, "tv": 43580.57, "trd": NaN, "batb": [[0, 1.16, 825.62], [1, 1.15, 1155.23]], "batl": NaN}, {"timestamp": 1631449589789, "ltp": 1.21, "tv": 43580.57, "trd": NaN, "batb": [[2, 1.13, 654.71]], "batl": [[0, 1.25, 448.34]]}, {"timestamp": 1631449591571, "ltp": 1.21, "tv": 43580.57, "trd": NaN, "batb": [[0, 1.16, 842.62], [1, 1.15, 1170.23]], "batl": NaN}, {"timestamp": 1631449592574, "ltp": 1.21, "tv": 43580.57, "trd": NaN, "batb": NaN, "batl": [[0, 1.24, 62.98], [1, 1.25, 448.34], [2, 1.26, 678.25]]}, {"timestamp": 1631449592766, "ltp": 1.21, "tv": 43580.57, "trd": NaN, "batb": NaN, "batl": [[0, 1.24, 12]]}, {"timestamp": 1631449597778, "ltp": 1.21, "tv": 43580.57, "trd": NaN, "batb": NaN, "batl": [[1, 1.25, 65.18], [2, 1.26, 49.75]]}, {"timestamp": 1631449599594, "ltp": 1.21, "tv": 43580.57, "trd": NaN, "batb": [[0, 1.16, 825.62], [2, 1.13, 119.73]], "batl": [[0, 1.23, 58.5], [1, 1.24, 62.48], [2, 1.25, 65.18]]}, {"timestamp": 1631449601284, "ltp": 1.21, "tv": 43580.57, "trd": NaN, "batb": [[2, 1.13, 100.73]], "batl": [[0, 1.18, 746], [1, 1.19, 894.49], [2, 1.21, 13.18]]}, {"timestamp": 1631449602496, "ltp": 1.21, "tv": 43580.57, "trd": NaN, "batb": [[1, 1.15, 1208.95]], "batl": [[2, 1.2, 15]]}, {"timestamp": 1631449603350, "ltp": 1.21, "tv": 43580.57, "trd": NaN, "batb": [[0, 1.16, 870.73]], "batl": NaN}, {"timestamp": 1631449605545, "ltp": 1.21, "tv": 43580.57, "trd": NaN, "batb": NaN, "batl": [[0, 1.17, 90.02], [1, 1.18, 746], [2, 1.19, 894.49]]}, {"timestamp": 1631449606316, "ltp": 1.21, "tv": 43580.57, "trd": NaN, "batb": NaN, "batl": [[0, 1.18, 803], [1, 1.19, 894.49], [2, 1.21, 13.18]]}, {"timestamp": 1631449607477, "ltp": 1.16, "tv": 43780.57, "trd": [[1.16, 200]], "batb": [[0, 1.16, 770.73]], "batl": [[2, 1.21, 70.68]]}, {"timestamp": 1631449608594, "ltp": 1.16, "tv": 43789.07, "trd": [[1.16, 208.5]], "batb": [[0, 1.16, 766.48]], "batl": NaN}, {"timestamp": 1631449609383, "ltp": 1.16, "tv": 43789.07, "trd": NaN, "batb": NaN, "batl": [[1, 1.19, 987.99], [2, 1.2, 71.13]]}, {"timestamp": 1631449610902, "ltp": 1.16, "tv": 43789.07, "trd": NaN, "batb": [[0, 1.16, 824.41]], "batl": NaN}, {"timestamp": 1631449612491, "ltp": 1.16, "tv": 43789.07, "trd": NaN, "batb": [[0, 1.15, 38.72], [1, 1.1, 126.64], [2, 1.09, 810.12]], "batl": [[0, 1.19, 15], [1, 1.21, 57.5], [2, 1.24, 12]]}, {"timestamp": 1631449613611, "ltp": 1.16, "tv": 43789.07, "trd": NaN, "batb": [[0, 1.1, 126.64], [1, 1.09, 810.12], [2, 1.01, 30]], "batl": [[0, 1.21, 57.5], [1, 1.24, 12], [2, 1.34, 13.01]]}, {"timestamp": 1631449615580, "ltp": 1.16, "tv": 43789.07, "trd": NaN, "batb": [[0, 1.13, 746.49], [1, 1.12, 1122.84], [2, 1.1, 126.64]], "batl": [[0, 1.16, 10], [1, 1.21, 801.91], [2, 1.22, 756.26]]}, {"timestamp": 1631449616177, "ltp": 1.16, "tv": 43789.07, "trd": NaN, "batb": [[1, 1.12, 1225.63], [2, 1.11, 117.59]], "batl": NaN}, {"timestamp": 1631449618471, "ltp": 1.16, "tv": 43789.07, "trd": NaN, "batb": NaN, "batl": [[0, 1.16, 26.62]]}, {"timestamp": 1631449619384, "ltp": 1.16, "tv": 43789.07, "trd": NaN, "batb": NaN, "batl": [[1, 1.19, 75.5], [2, 1.2, 64.68]]}, {"timestamp": 1631449619979, "ltp": 1.16, "tv": 43789.07, "trd": NaN, "batb": NaN, "batl": [[0, 1.16, 16.62], [1, 1.21, 801.91], [2, 1.22, 756.26]]}, {"timestamp": 1631449621407, "ltp": 1.17, "tv": 43826.97, "trd": [[1.16, 241.75], [1.17, 4.65]], "batb": [[0, 1.19, 37.38], [1, 1.18, 1620.76], [2, 1.17, 1551.82]], "batl": [[0, 1.21, 801.91], [1, 1.22, 756.26], [2, 1.24, 12]]}, {"timestamp": 1631449621692, "ltp": 1.17, "tv": 43826.97, "trd": NaN, "batb": [[0, 1.18, 81.04], [1, 1.17, 78.65], [2, 1.16, 78.65]], "batl": NaN}, {"timestamp": 1631449623580, "ltp": 1.18, "tv": 43854.33, "trd": [[1.18, 27.36]], "batb": [[0, 1.18, 1707.48], [1, 1.17, 1651.74], [2, 1.16, 1651.74]], "batl": NaN}, {"timestamp": 1631449624598, "ltp": 1.18, "tv": 43854.33, "trd": NaN, "batb": [[0, 1.2, 8], [1, 1.19, 393.13], [2, 1.18, 1901.84]], "batl": [[0, 1.21, 811.91], [2, 1.24, 24.86]]}, {"timestamp": 1631449625415, "ltp": 1.18, "tv": 43854.33, "trd": NaN, "batb": NaN, "batl": [[0, 1.21, 801.91], [1, 1.22, 771.26]]}, {"timestamp": 1631449625684, "ltp": 1.18, "tv": 43854.33, "trd": NaN, "batb": [[2, 1.18, 1976.81]], "batl": [[0, 1.21, 856.37]]}, {"timestamp": 1631449628518, "ltp": 1.19, "tv": 43906.8, "trd": [[1.19, 26.64], [1.2, 496.45]], "batb": [[0, 1.19, 379.81], [1, 1.18, 1976.81], [2, 1.17, 901.58]], "batl": NaN}, {"timestamp": 1631449630495, "ltp": 1.19, "tv": 43981.18, "trd": [[1.19, 101.02]], "batb": [[0, 1.19, 342.62]], "batl": NaN}, {"timestamp": 1631449630713, "ltp": 1.19, "tv": 43981.18, "trd": NaN, "batb": NaN, "batl": [[2, 1.24, 83.59]]}, {"timestamp": 1631449633121, "ltp": 1.19, "tv": 43981.18, "trd": NaN, "batb": NaN, "batl": [[0, 1.2, 9.75], [1, 1.21, 856.37], [2, 1.22, 816.26]]}, {"timestamp": 1631449637836, "ltp": 1.19, "tv": 43981.18, "trd": NaN, "batb": NaN, "batl": [[0, 1.21, 856.37], [1, 1.22, 816.26], [2, 1.23, 54.5]]}, {"timestamp": 1631449641444, "ltp": 1.19, "tv": 43981.18, "trd": NaN, "batb": [[0, 1.17, 36.38], [1, 1.13, 106.73], [2, 1.11, 694.99]], "batl": [[0, 1.22, 60], [1, 1.24, 70.73], [2, 1.25, 54.58]]}, {"timestamp": 1631449642476, "ltp": 1.19, "tv": 43981.18, "trd": NaN, "batb": [[0, 1.11, 694.99], [1, 1.1, 140.64], [2, 1.09, 136.61]], "batl": [[0, 1.24, 12], [1, 1.26, 50.75], [2, 1.34, 13.01]]}, {"timestamp": 1631449644382, "ltp": 1.19, "tv": 43981.18, "trd": NaN, "batb": [[0, 1.14, 1559.97], [1, 1.13, 285.61], [2, 1.11, 694.99]], "batl": [[1, 1.25, 679.75], [2, 1.26, 673.8]]}, {"timestamp": 1631449645445, "ltp": 1.19, "tv": 43981.18, "trd": NaN, "batb": [[1, 1.13, 384.34]], "batl": [[0, 1.24, 65.48], [1, 1.25, 731.69]]}, {"timestamp": 1631449645665, "ltp": 1.19, "tv": 43981.18, "trd": NaN, "batb": [[2, 1.12, 11]], "batl": [[0, 1.24, 12]]}, {"timestamp": 1631449647470, "ltp": 1.19, "tv": 43981.18, "trd": NaN, "batb": NaN, "batl": [[1, 1.26, 50.75], [2, 1.34, 13.01]]}, {"timestamp": 1631449648583, "ltp": 1.19, "tv": 43981.18, "trd": NaN, "batb": NaN, "batl": [[0, 1.23, 71.59], [1, 1.24, 12], [2, 1.26, 50.75]]}, {"timestamp": 1631449649060, "ltp": 1.19, "tv": 43981.18, "trd": NaN, "batb": NaN, "batl": [[0, 1.23, 92.41]]}, {"timestamp": 1631449650576, "ltp": 1.23, "tv": 45607.24, "trd": [[1.21, 2829.81], [1.22, 188.69], [1.23, 227.33]], "batb": [[0, 1.14, 1006.19], [1, 1.13, 98.73]], "batl": [[0, 1.24, 12], [1, 1.25, 16]]}, {"timestamp": 1631449651586, "ltp": 1.24, "tv": 46059.71, "trd": [[1.19, 220.66], [1.2, 496.63], [1.23, 229.83], [1.24, 2528.72]], "batb": [[0, 1.24, 618.18], [1, 1.14, 1046.27], [2, 1.13, 98.73]], "batl": [[0, 1.25, 8], [1, 1.26, 50.75], [2, 1.34, 13.01]]}, {"timestamp": 1631449652274, "ltp": 1.24, "tv": 46539.27, "trd": [[1.24, 3008.28]], "batb": [[0, 1.24, 346.96], [1, 1.14, 1046.6]], "batl": NaN}, {"timestamp": 1631449653379, "ltp": 1.21, "tv": 47191.9, "trd": [[1.21, 2830.47], [1.24, 3660.26]], "batb": [[0, 1.15, 829.62], [1, 1.14, 1046.27]], "batl": [[0, 1.17, 473.17], [1, 1.18, 930.36], [2, 1.25, 8]]}, {"timestamp": 1631449654598, "ltp": 1.21, "tv": 47191.9, "trd": NaN, "batb": [[1, 1.14, 911.37]], "batl": [[1, 1.18, 945.36]]}, {"timestamp": 1631449655504, "ltp": 1.21, "tv": 47191.9, "trd": NaN, "batb": [[1, 1.14, 871.29]], "batl": [[2, 1.24, 8]]}, {"timestamp": 1631449656580, "ltp": 1.21, "tv": 47191.9, "trd": NaN, "batb": [[0, 1.15, 1013.28]], "batl": [[0, 1.17, 636.9]]}, {"timestamp": 1631449657376, "ltp": 1.17, "tv": 47192.56, "trd": [[1.17, 5.31]], "batb": NaN, "batl": [[0, 1.17, 636.57]]}, {"timestamp": 1631449658389, "ltp": 1.17, "tv": 47192.56, "trd": NaN, "batb": NaN, "batl": [[2, 1.19, 60]]}, {"timestamp": 1631449658682, "ltp": 1.17, "tv": 47192.56, "trd": NaN, "batb": [[0, 1.15, 1052]], "batl": NaN}, {"timestamp": 1631449660110, "ltp": 1.17, "tv": 48456.54, "trd": [[1.17, 1269.29]], "batb": [[1, 1.14, 598.15]], "batl": [[0, 1.17, 4.58]]}, {"timestamp": 1631449662488, "ltp": 1.15, "tv": 48461.67, "trd": [[1.15, 5.12]], "batb": [[0, 1.15, 1049.44]], "batl": NaN}, {"timestamp": 1631449663493, "ltp": 1.15, "tv": 48461.67, "trd": NaN, "batb": [[0, 1.15, 1320.21]], "batl": [[0, 1.17, 370.85]]}, {"timestamp": 1631449664400, "ltp": 1.17, "tv": 48462.52, "trd": [[1.17, 1270.15]], "batb": NaN, "batl": [[0, 1.17, 370.42]]}, {"timestamp": 1631449666579, "ltp": 1.17, "tv": 48462.52, "trd": NaN, "batb": [[0, 1.15, 38.72], [1, 1.08, 719.06], [2, 1.01, 30]], "batl": [[0, 1.19, 60], [1, 1.34, 13.01], [2, 1.47, 896.39]]}, {"timestamp": 1631449667588, "ltp": 1.17, "tv": 48462.52, "trd": NaN, "batb": [[0, 1.08, 719.06], [1, 1.01, 30], [2, 1.01, 0]], "batl": [[0, 1.34, 13.01], [1, 1.39, 17.8]]}, {"timestamp": 1631449669519, "ltp": 1.17, "tv": 48462.52, "trd": NaN, "batb": [[0, 1.12, 981.95], [1, 1.11, 902.11], [2, 1.08, 719.06]], "batl": [[0, 1.21, 999.55], [1, 1.22, 719.31], [2, 1.34, 13.01]]}, {"timestamp": 1631449671520, "ltp": 1.17, "tv": 48462.52, "trd": NaN, "batb": NaN, "batl": [[2, 1.34, 17.01]]}, {"timestamp": 1631449673224, "ltp": 1.17, "tv": 48462.52, "trd": NaN, "batb": [[0, 1.08, 719.06], [1, 1.01, 30], [2, 1.08, 0]], "batl": [[0, 1.2, 9.75], [1, 1.21, 999.55], [2, 1.22, 719.31]]}, {"timestamp": 1631449674511, "ltp": 1.17, "tv": 48462.52, "trd": NaN, "batb": [[0, 1.01, 30.12], [1, 1.01, 0]], "batl": NaN}, {"timestamp": 1631449675509, "ltp": 1.17, "tv": 48462.52, "trd": NaN, "batb": [[0, 1.18, 81.04], [1, 1.17, 78.77], [2, 1.16, 78.65]], "batl": NaN}, {"timestamp": 1631449676512, "ltp": 1.17, "tv": 48462.52, "trd": NaN, "batb": [[0, 1.18, 1896.89], [1, 1.17, 1647.08], [2, 1.16, 865.2]], "batl": NaN}, {"timestamp": 1631449677424, "ltp": 1.2, "tv": 48472.27, "trd": [[1.2, 506.38]], "batb": [[0, 1.18, 1904.89], [1, 1.17, 1683.46]], "batl": [[0, 1.21, 999.55], [1, 1.22, 779.31], [2, 1.24, 12.86]]}, {"timestamp": 1631449681447, "ltp": 1.18, "tv": 48562.51, "trd": [[1.18, 117.6]], "batb": [[0, 1.18, 2009.77]], "batl": [[0, 1.21, 1072.65]]}, {"timestamp": 1631449682427, "ltp": 1.18, "tv": 48562.51, "trd": NaN, "batb": [[0, 1.18, 914.9], [1, 1.17, 901.58]], "batl": [[0, 1.21, 73.1], [1, 1.22, 60]]}, {"timestamp": 1631449683128, "ltp": 1.18, "tv": 48562.51, "trd": NaN, "batb": NaN, "batl": [[2, 1.23, 53.5]]}, {"timestamp": 1631449688233, "ltp": 1.21, "tv": 48566.51, "trd": [[1.21, 2834.47]], "batb": NaN, "batl": [[0, 1.21, 71.1]]}, {"timestamp": 1631449689456, "ltp": 1.21, "tv": 48566.51, "trd": NaN, "batb": [[0, 1.18, 1920.37], [1, 1.17, 1683.34]], "batl": [[0, 1.21, 1070.65], [1, 1.22, 779.31]]}, {"timestamp": 1631449695464, "ltp": 1.21, "tv": 48566.51, "trd": NaN, "batb": [[0, 1.17, 36.38], [1, 1.13, 7.04], [2, 1.11, 586.4]], "batl": [[0, 1.22, 60], [1, 1.26, 46.25], [2, 1.34, 17.01]]}, {"timestamp": 1631449696471, "ltp": 1.21, "tv": 48566.51, "trd": NaN, "batb": [[0, 1.13, 7.04], [1, 1.11, 586.4], [2, 1.1, 104.74]], "batl": [[0, 1.26, 46.25], [1, 1.34, 17.01], [2, 1.39, 17.8]]}, {"timestamp": 1631449697550, "ltp": 1.21, "tv": 48566.51, "trd": NaN, "batb": NaN, "batl": [[0, 1.18, 8], [1, 1.26, 46.25], [2, 1.34, 17.01]]}, {"timestamp": 1631449698456, "ltp": 1.18, "tv": 48566.71, "trd": [[1.18, 117.8]], "batb": [[1, 1.12, 1679.56], [2, 1.11, 586.4]], "batl": [[0, 1.18, 7.9], [1, 1.26, 459.59], [2, 1.27, 579.51]]}, {"timestamp": 1631449699776, "ltp": 1.18, "tv": 48566.71, "trd": NaN, "batb": NaN, "batl": [[1, 1.26, 465.59]]}, {"timestamp": 1631449705566, "ltp": 1.18, "tv": 48566.71, "trd": NaN, "batb": NaN, "batl": [[1, 1.23, 51.5], [2, 1.24, 59.98]]}, {"timestamp": 1631449705892, "ltp": 1.18, "tv": 48566.71, "trd": NaN, "batb": NaN, "batl": [[1, 1.26, 465.59], [2, 1.27, 579.51]]}, {"timestamp": 1631449707585, "ltp": 1.18, "tv": 48566.71, "trd": NaN, "batb": [[0, 1.14, 11.7], [1, 1.13, 7.04], [2, 1.12, 1679.56]], "batl": NaN}, {"timestamp": 1631449708188, "ltp": 1.14, "tv": 48590.11, "trd": [[1.14, 23.4]], "batb": [[0, 1.13, 7.04], [1, 1.12, 1679.56], [2, 1.11, 586.4]], "batl": [[0, 1.14, 9.99]]}, {"timestamp": 1631449710308, "ltp": 1.14, "tv": 48590.11, "trd": NaN, "batb": NaN, "batl": [[0, 1.26, 465.59], [1, 1.27, 579.51], [2, 1.34, 17.01]]}, {"timestamp": 1631449711327, "ltp": 1.14, "tv": 48590.11, "trd": NaN, "batb": [[0, 1.18, 1.95], [1, 1.13, 7.04], [2, 1.12, 1679.56]], "batl": [[2, 1.34, 13.01]]}, {"timestamp": 1631449713461, "ltp": 1.13, "tv": 48594.11, "trd": [[1.13, 0.1], [1.18, 121.7]], "batb": [[0, 1.13, 6.99], [1, 1.11, 586.4], [2, 1.1, 104.74]], "batl": [[0, 1.25, 7], [1, 1.26, 465.59], [2, 1.27, 579.51]]}, {"timestamp": 1631449714355, "ltp": 1.15, "tv": 48636.81, "trd": [[1.15, 47.82]], "batb": NaN, "batl": [[0, 1.26, 459.59], [1, 1.27, 579.51], [2, 1.34, 13.01]]}, {"timestamp": 1631449715577, "ltp": 1.15, "tv": 48636.81, "trd": NaN, "batb": [[0, 1.2, 19.02], [1, 1.13, 6.99]], "batl": NaN}, {"timestamp": 1631449716396, "ltp": 1.15, "tv": 48636.81, "trd": NaN, "batb": [[0, 1.24, 307.47], [1, 1.23, 733.59], [2, 1.2, 19.02]], "batl": [[2, 1.29, 12.37]]}, {"timestamp": 1631449717512, "ltp": 1.15, "tv": 48636.81, "trd": NaN, "batb": [[2, 1.22, 9]], "batl": [[0, 1.26, 519.59]]}, {"timestamp": 1631449722586, "ltp": 1.15, "tv": 48636.81, "trd": NaN, "batb": NaN, "batl": [[2, 1.29, 59.87]]}, {"timestamp": 1631449723000, "ltp": 1.24, "tv": 48662.21, "trd": [[1.24, 3685.66]], "batb": [[0, 1.24, 294.77]], "batl": NaN}, {"timestamp": 1631449724168, "ltp": 1.24, "tv": 48663.21, "trd": [[1.24, 3686.65]], "batb": [[0, 1.24, 315.96]], "batl": NaN}, {"timestamp": 1631449725510, "ltp": 1.26, "tv": 48682.71, "trd": [[1.26, 355.34]], "batb": NaN, "batl": [[0, 1.26, 509.84]]}, {"timestamp": 1631449726085, "ltp": 1.26, "tv": 48682.71, "trd": NaN, "batb": [[0, 1.24, 294.27]], "batl": NaN}, {"timestamp": 1631449727613, "ltp": 1.24, "tv": 48683.11, "trd": [[1.24, 3687.05]], "batb": [[0, 1.24, 294.07]], "batl": NaN}, {"timestamp": 1631449731923, "ltp": 1.26, "tv": 48684.63, "trd": [[1.26, 356.86]], "batb": NaN, "batl": [[0, 1.26, 509.08]]}, {"timestamp": 1631449734321, "ltp": 1.24, "tv": 48742.05, "trd": [[1.24, 3744.47]], "batb": [[0, 1.24, 265.36]], "batl": NaN}, {"timestamp": 1631449735204, "ltp": 1.24, "tv": 48756.39, "trd": [[1.24, 3756.47], [1.26, 359.2]], "batb": [[0, 1.24, 259.36]], "batl": [[0, 1.26, 507.91]]}, {"timestamp": 1631449739406, "ltp": 1.24, "tv": 48756.39, "trd": NaN, "batb": [[0, 1.21, 32.73], [1, 1.15, 588.42], [2, 1.13, 6.99]], "batl": [[0, 1.26, 60], [1, 1.31, 44.5], [2, 1.34, 13.01]]}, {"timestamp": 1631449740413, "ltp": 1.24, "tv": 48756.39, "trd": NaN, "batb": [[0, 1.15, 588.42], [1, 1.13, 6.99], [2, 1.12, 28.7]], "batl": [[0, 1.31, 44.5], [1, 1.34, 13.01], [2, 1.47, 896.39]]}, {"timestamp": 1631449742320, "ltp": 1.24, "tv": 48756.39, "trd": NaN, "batb": [[0, 1.18, 916.76], [1, 1.17, 871.63], [2, 1.15, 588.42]], "batl": [[0, 1.29, 43.5], [1, 1.31, 371.56], [2, 1.32, 474]]}, {"timestamp": 1631449742713, "ltp": 1.24, "tv": 48756.39, "trd": NaN, "batb": NaN, "batl": [[0, 1.31, 371.56], [1, 1.32, 474], [2, 1.34, 13.01]]}, {"timestamp": 1631449744230, "ltp": 1.24, "tv": 48756.39, "trd": NaN, "batb": [[2, 1.15, 604.42]], "batl": [[0, 1.27, 10], [1, 1.31, 380.56], [2, 1.32, 474]]}, {"timestamp": 1631449745526, "ltp": 1.24, "tv": 48756.39, "trd": NaN, "batb": NaN, "batl": [[1, 1.29, 8], [2, 1.31, 380.56]]}, {"timestamp": 1631449746248, "ltp": 1.24, "tv": 48756.39, "trd": NaN, "batb": NaN, "batl": [[2, 1.3, 8]]}, {"timestamp": 1631449749414, "ltp": 1.24, "tv": 48756.39, "trd": NaN, "batb": [[0, 1.18, 916.36]], "batl": [[1, 1.29, 51.5]]}, {"timestamp": 1631449749735, "ltp": 1.24, "tv": 48756.39, "trd": NaN, "batb": NaN, "batl": [[0, 1.19, 111], [1, 1.27, 10], [2, 1.29, 8]]}, {"timestamp": 1631449751411, "ltp": 1.19, "tv": 48877.48, "trd": [[1.19, 341.76]], "batb": NaN, "batl": [[0, 1.19, 50.45]]}, {"timestamp": 1631449757214, "ltp": 1.19, "tv": 48877.48, "trd": NaN, "batb": NaN, "batl": [[1, 1.29, 8], [2, 1.31, 371.56]]}, {"timestamp": 1631449761358, "ltp": 1.19, "tv": 48879.07, "trd": [[1.19, 343.34]], "batb": NaN, "batl": [[0, 1.19, 49.66]]}, {"timestamp": 1631449763235, "ltp": 1.19, "tv": 48879.27, "trd": [[1.19, 343.54]], "batb": NaN, "batl": [[0, 1.19, 49.56]]}, {"timestamp": 1631449763965, "ltp": 1.18, "tv": 48890.84, "trd": [[1.18, 125.7], [1.19, 351.12]], "batb": [[0, 1.18, 914.36]], "batl": [[0, 1.19, 45.77], [2, 1.31, 44.5]]}, {"timestamp": 1631449765555, "ltp": 1.28, "tv": 48993.4, "trd": [[1.19, 442.66], [1.28, 366.34]], "batb": NaN, "batl": [[0, 1.29, 8], [1, 1.31, 44.5], [2, 1.34, 13.01]]}, {"timestamp": 1631449766240, "ltp": 1.28, "tv": 48993.4, "trd": NaN, "batb": [[0, 1.19, 49.65], [1, 1.18, 914.36], [2, 1.17, 871.63]], "batl": NaN}, {"timestamp": 1631449767574, "ltp": 1.27, "tv": 49001.41, "trd": [[1.27, 2585.63]], "batb": [[0, 1.18, 914.64], [1, 1.17, 871.63], [2, 1.15, 95.4]], "batl": [[0, 1.2, 299.09], [1, 1.21, 782.85], [2, 1.23, 12.97]]}, {"timestamp": 1631449768468, "ltp": 1.27, "tv": 49001.41, "trd": NaN, "batb": [[0, 1.19, 5.32], [1, 1.18, 914.36], [2, 1.17, 908.01]], "batl": [[2, 1.22, 60]]}, {"timestamp": 1631449769486, "ltp": 1.27, "tv": 49001.41, "trd": NaN, "batb": [[1, 1.18, 971.35], [2, 1.17, 871.63]], "batl": NaN}, {"timestamp": 1631449772368, "ltp": 1.18, "tv": 49083.74, "trd": [[1.18, 196.64], [1.19, 454.04]], "batb": [[0, 1.18, 935.88], [1, 1.17, 871.63], [2, 1.15, 95.4]], "batl": NaN}, {"timestamp": 1631449773270, "ltp": 1.18, "tv": 49141.16, "trd": [[1.18, 254.06]], "batb": [[0, 1.18, 907.17], [1, 1.17, 908.01]], "batl": NaN}, {"timestamp": 1631449773640, "ltp": 1.18, "tv": 49141.16, "trd": NaN, "batb": [[2, 1.15, 95.23]], "batl": NaN}, {"timestamp": 1631449782382, "ltp": 1.2, "tv": 49151.15, "trd": [[1.2, 516.36]], "batb": NaN, "batl": [[0, 1.2, 294.1]]}, {"timestamp": 1631449788162, "ltp": 1.2, "tv": 49155.04, "trd": [[1.2, 520.26]], "batb": NaN, "batl": [[0, 1.2, 292.15]]}, {"timestamp": 1631449789383, "ltp": 1.2, "tv": 49155.38, "trd": [[1.2, 520.59]], "batb": NaN, "batl": [[0, 1.2, 291.98]]}, {"timestamp": 1631449790455, "ltp": 1.2, "tv": 49156.27, "trd": [[1.2, 521.48]], "batb": NaN, "batl": [[0, 1.2, 291.53]]}, {"timestamp": 1631449792385, "ltp": 1.2, "tv": 49156.27, "trd": NaN, "batb": [[0, 1.17, 36.38], [1, 1.13, 6.99], [2, 1.11, 594.32]], "batl": [[0, 1.22, 60], [1, 1.25, 46.38], [2, 1.26, 43.25]]}, {"timestamp": 1631449793489, "ltp": 1.2, "tv": 49156.27, "trd": NaN, "batb": [[0, 1.13, 6.99], [1, 1.11, 594.32], [2, 1.1, 104.74]], "batl": [[0, 1.18, 4.25], [1, 1.27, 10], [2, 1.28, 45.09]]}, {"timestamp": 1631449793878, "ltp": 1.2, "tv": 49156.27, "trd": NaN, "batb": NaN, "batl": [[1, 1.26, 9.75], [2, 1.27, 10]]}, {"timestamp": 1631449798493, "ltp": 1.2, "tv": 49156.27, "trd": NaN, "batb": [[0, 1.17, 741.4], [1, 1.16, 1063.51], [2, 1.13, 6.99]], "batl": [[1, 1.19, 566.22], [2, 1.2, 819.67]]}, {"timestamp": 1631449801119, "ltp": 1.2, "tv": 49156.27, "trd": NaN, "batb": [[2, 1.13, 25.51]], "batl": [[0, 1.18, 224.13]]}, {"timestamp": 1631449802503, "ltp": 1.17, "tv": 49474.58, "trd": [[1.17, 1342.45], [1.18, 500.07]], "batb": [[0, 1.17, 705.25]], "batl": [[0, 1.18, 101.13]]}, {"timestamp": 1631449803415, "ltp": 1.18, "tv": 49475.61, "trd": [[1.18, 501.1]], "batb": [[0, 1.13, 25.51], [1, 1.11, 594.32], [2, 1.1, 104.74]], "batl": [[0, 1.18, 100.09], [1, 1.2, 39.73], [2, 1.25, 51.74]]}, {"timestamp": 1631449804015, "ltp": 1.18, "tv": 49475.61, "trd": NaN, "batb": NaN, "batl": [[1, 1.2, 60.55]]}, {"timestamp": 1631449805796, "ltp": 1.18, "tv": 49475.61, "trd": NaN, "batb": [[1, 1.12, 1567.32], [2, 1.11, 905.77]], "batl": [[1, 1.2, 20.82]]}, {"timestamp": 1631449810023, "ltp": 1.18, "tv": 49475.61, "trd": NaN, "batb": NaN, "batl": [[0, 1.26, 568.43], [1, 1.27, 588.26], [2, 1.28, 45.09]]}, {"timestamp": 1631449811310, "ltp": 1.13, "tv": 49507.43, "trd": [[1.13, 31.91]], "batb": [[0, 1.13, 9.6]], "batl": NaN}, {"timestamp": 1631449813299, "ltp": 1.13, "tv": 49507.43, "trd": NaN, "batb": NaN, "batl": [[0, 1.25, 62.34], [1, 1.26, 576.43], [2, 1.27, 588.26]]}, {"timestamp": 1631449814519, "ltp": 1.13, "tv": 49507.43, "trd": NaN, "batb": NaN, "batl": [[0, 1.25, 11]]}, {"timestamp": 1631449815595, "ltp": 1.13, "tv": 49507.43, "trd": NaN, "batb": [[0, 1.13, 10.38]], "batl": NaN}, {"timestamp": 1631449815808, "ltp": 1.13, "tv": 49507.43, "trd": NaN, "batb": [[0, 1.12, 1568.09], [1, 1.11, 905.77], [2, 1.1, 104.74]], "batl": NaN}, {"timestamp": 1631449816923, "ltp": 1.13, "tv": 49507.43, "trd": NaN, "batb": NaN, "batl": [[0, 1.25, 56.18]]}, {"timestamp": 1631449817845, "ltp": 1.13, "tv": 49507.43, "trd": NaN, "batb": NaN, "batl": [[0, 1.25, 11]]}, {"timestamp": 1631449818669, "ltp": 1.18, "tv": 49508.97, "trd": [[1.18, 502.64]], "batb": [[0, 1.11, 594.32], [1, 1.1, 104.74], [2, 1.08, 167.31]], "batl": [[0, 1.13, 99.23], [1, 1.25, 11], [2, 1.26, 576.43]]}, {"timestamp": 1631449820521, "ltp": 1.13, "tv": 49573.97, "trd": [[1.13, 96.91]], "batb": [[0, 1.11, 7.92]], "batl": [[0, 1.13, 34.23], [1, 1.26, 568.43], [2, 1.27, 588.26]]}, {"timestamp": 1631449821508, "ltp": 1.16, "tv": 49879.46, "trd": [[1.13, 165.37], [1.15, 130.97], [1.16, 395.63]], "batb": [[0, 1.23, 1554.88], [1, 1.22, 1256.68], [2, 1.21, 1538.84]], "batl": [[0, 1.25, 46.74]]}, {"timestamp": 1631449822341, "ltp": 1.16, "tv": 49879.46, "trd": NaN, "batb": [[0, 1.23, 1692.16], [1, 1.22, 1538.42], [2, 1.21, 762.57]], "batl": [[0, 1.26, 568.43], [1, 1.27, 588.26], [2, 1.28, 57.56]]}, {"timestamp": 1631449824047, "ltp": 1.16, "tv": 49879.46, "trd": NaN, "batb": NaN, "batl": [[0, 1.26, 558.68]]}, {"timestamp": 1631449825124, "ltp": 1.16, "tv": 49879.46, "trd": NaN, "batb": [[0, 1.23, 1752.05]], "batl": [[0, 1.26, 613.96]]}, {"timestamp": 1631449827240, "ltp": 1.16, "tv": 49879.46, "trd": NaN, "batb": [[2, 1.21, 795.3]], "batl": NaN}, {"timestamp": 1631449828718, "ltp": 1.16, "tv": 49879.46, "trd": NaN, "batb": [[0, 1.24, 97.62], [1, 1.23, 1752.05], [2, 1.22, 1538.42]], "batl": NaN}, {"timestamp": 1631449832657, "ltp": 1.24, "tv": 49879.95, "trd": [[1.24, 3756.96]], "batb": [[0, 1.24, 97.38]], "batl": NaN}, {"timestamp": 1631449835839, "ltp": 1.24, "tv": 49939.19, "trd": [[1.24, 3816.2]], "batb": [[0, 1.24, 38.14]], "batl": NaN}, {"timestamp": 1631449838547, "ltp": 1.26, "tv": 49947.69, "trd": [[1.26, 367.71]], "batb": NaN, "batl": [[0, 1.25, 39.73], [1, 1.26, 609.71], [2, 1.27, 588.26]]}, {"timestamp": 1631449839131, "ltp": 1.25, "tv": 50068.79, "trd": [[1.25, 1229.26]], "batb": [[0, 1.25, 62.45], [1, 1.24, 38.14], [2, 1.23, 1752.05]], "batl": [[0, 1.26, 609.71], [1, 1.27, 588.26], [2, 1.28, 57.56]]}, {"timestamp": 1631449840246, "ltp": 1.25, "tv": 50069.79, "trd": [[1.25, 1230.26]], "batb": [[0, 1.25, 61.95]], "batl": NaN}, {"timestamp": 1631449844147, "ltp": 1.25, "tv": 50071.37, "trd": [[1.25, 1231.85]], "batb": [[0, 1.25, 61.16]], "batl": NaN}, {"timestamp": 1631449846097, "ltp": 1.25, "tv": 50071.37, "trd": NaN, "batb": [[0, 1.24, 38.14], [1, 1.23, 1752.05], [2, 1.22, 1538.42]], "batl": NaN}, {"timestamp": 1631449849903, "ltp": 1.25, "tv": 50071.37, "trd": NaN, "batb": NaN, "batl": [[0, 1.26, 568.68]]}, {"timestamp": 1631449851425, "ltp": 1.25, "tv": 50071.37, "trd": NaN, "batb": [[1, 1.21, 40.73], [2, 1.18, 13.52]], "batl": [[0, 1.26, 60], [1, 1.27, 10], [2, 1.28, 12.47]]}, {"timestamp": 1631449852596, "ltp": 1.25, "tv": 50071.37, "trd": NaN, "batb": [[1, 1.16, 80.78], [2, 1.15, 509.02]], "batl": [[0, 1.27, 10], [1, 1.31, 42.5], [2, 1.34, 13.01]]}, {"timestamp": 1631449854407, "ltp": 1.25, "tv": 50071.37, "trd": NaN, "batb": [[1, 1.18, 813.21], [2, 1.17, 975.66]], "batl": [[1, 1.31, 454], [2, 1.32, 473.22]]}, {"timestamp": 1631449855682, "ltp": 1.25, "tv": 50071.37, "trd": NaN, "batb": [[0, 1.18, 813.21], [1, 1.17, 975.66], [2, 1.16, 80.78]], "batl": NaN}, {"timestamp": 1631449858528, "ltp": 1.25, "tv": 50071.37, "trd": NaN, "batb": NaN, "batl": [[1, 1.29, 47.5], [2, 1.31, 454]]}, {"timestamp": 1631449858914, "ltp": 1.25, "tv": 50071.37, "trd": NaN, "batb": NaN, "batl": [[1, 1.31, 454], [2, 1.32, 473.22]]}, {"timestamp": 1631449861498, "ltp": 1.28, "tv": 50125.1, "trd": [[1.27, 2621.23], [1.28, 384.47]], "batb": [[0, 1.28, 21.91], [1, 1.26, 1.99], [2, 1.18, 813.21]], "batl": [[0, 1.31, 454], [1, 1.32, 473.22], [2, 1.34, 13.01]]}, {"timestamp": 1631449863252, "ltp": 1.28, "tv": 50125.1, "trd": NaN, "batb": [[0, 1.26, 1.99], [1, 1.18, 813.21], [2, 1.17, 975.66]], "batl": NaN}, {"timestamp": 1631449865316, "ltp": 1.28, "tv": 50125.1, "trd": NaN, "batb": NaN, "batl": [[0, 1.29, 8], [1, 1.3, 9], [2, 1.31, 463]]}, {"timestamp": 1631449869200, "ltp": 1.28, "tv": 50125.1, "trd": NaN, "batb": NaN, "batl": [[0, 1.29, 51.5]]}, {"timestamp": 1631449870343, "ltp": 1.28, "tv": 50125.1, "trd": NaN, "batb": NaN, "batl": [[0, 1.29, 8]]}, {"timestamp": 1631449873348, "ltp": 1.28, "tv": 50125.1, "trd": NaN, "batb": [[1, 1.15, 509.02], [2, 1.12, 112.45]], "batl": NaN}, {"timestamp": 1631449874255, "ltp": 1.28, "tv": 50125.1, "trd": NaN, "batb": NaN, "batl": [[0, 1.31, 454], [1, 1.32, 473.22], [2, 1.34, 13.01]]}, {"timestamp": 1631449875554, "ltp": 1.28, "tv": 50125.1, "trd": NaN, "batb": [[0, 1.28, 11269.86], [1, 1.26, 1.99], [2, 1.25, 27.81]], "batl": [[2, 1.33, 1685.03]]}, {"timestamp": 1631449876350, "ltp": 1.28, "tv": 50125.1, "trd": NaN, "batb": [[0, 1.28, 731.97], [1, 1.27, 607.16], [2, 1.26, 1.99]], "batl": [[1, 1.32, 485.31], [2, 1.33, 842.51]]}, {"timestamp": 1631449877435, "ltp": 1.28, "tv": 50125.1, "trd": NaN, "batb": [[1, 1.27, 625.11]], "batl": [[0, 1.31, 514]]}, {"timestamp": 1631449877752, "ltp": 1.28, "tv": 50125.1, "trd": NaN, "batb": [[1, 1.27, 615.16]], "batl": NaN}, {"timestamp": 1631449881089, "ltp": 1.28, "tv": 50125.1, "trd": NaN, "batb": [[0, 1.28, 781.33]], "batl": NaN}, {"timestamp": 1631449881953, "ltp": 1.28, "tv": 50125.1, "trd": NaN, "batb": NaN, "batl": [[2, 1.33, 879.01]]}, {"timestamp": 1631449882759, "ltp": 1.28, "tv": 50125.1, "trd": NaN, "batb": NaN, "batl": [[0, 1.3, 2198.76], [1, 1.31, 514], [2, 1.32, 485.31]]}, {"timestamp": 1631449884359, "ltp": 1.28, "tv": 50342.82, "trd": [[1.28, 602.19]], "batb": [[0, 1.28, 672.47], [2, 1.26, 31.4]], "batl": NaN}, {"timestamp": 1631449886072, "ltp": 1.28, "tv": 50344.78, "trd": [[1.28, 604.14]], "batb": [[0, 1.28, 671.49]], "batl": NaN}, {"timestamp": 1631449890362, "ltp": 1.28, "tv": 50367.03, "trd": [[1.28, 626.39]], "batb": [[0, 1.28, 649.24], [2, 1.26, 29.41]], "batl": NaN}, {"timestamp": 1631449891065, "ltp": 1.3, "tv": 50367.82, "trd": [[1.3, 400.72]], "batb": NaN, "batl": [[0, 1.3, 2198.36]]}, {"timestamp": 1631449891664, "ltp": 1.3, "tv": 50367.82, "trd": NaN, "batb": [[0, 1.29, 43.98], [1, 1.28, 649.24], [2, 1.27, 615.16]], "batl": NaN}, {"timestamp": 1631449896785, "ltp": 1.3, "tv": 50367.82, "trd": NaN, "batb": NaN, "batl": [[0, 1.31, 514], [1, 1.32, 485.31], [2, 1.33, 879.01]]}, {"timestamp": 1631449898596, "ltp": 1.3, "tv": 50367.82, "trd": NaN, "batb": [[0, 1.29, 44.17], [1, 1.27, 8], [2, 1.26, 29.41]], "batl": [[0, 1.31, 60], [1, 1.32, 12.09], [2, 1.34, 18.97]]}, {"timestamp": 1631449899460, "ltp": 1.3, "tv": 50367.82, "trd": NaN, "batb": [[1, 1.22, 50.34], [2, 1.2, 1.71]], "batl": [[0, 1.34, 13.01], [1, 1.35, 34.5], [2, 1.47, 896.39]]}, {"timestamp": 1631449900471, "ltp": 1.3, "tv": 50367.82, "trd": NaN, "batb": NaN, "batl": [[0, 1.34, 49.76], [2, 1.36, 36.57]]}, {"timestamp": 1631449901484, "ltp": 1.3, "tv": 50367.82, "trd": NaN, "batb": [[0, 1.3, 2.19], [1, 1.29, 43.98], [2, 1.23, 808.58]], "batl": [[0, 1.33, 40.5], [1, 1.34, 13.01], [2, 1.35, 34.5]]}, {"timestamp": 1631449901865, "ltp": 1.3, "tv": 50367.82, "trd": NaN, "batb": NaN, "batl": [[0, 1.34, 13.01], [1, 1.35, 34.5], [2, 1.36, 618.52]]}, {"timestamp": 1631449902777, "ltp": 1.3, "tv": 50367.82, "trd": NaN, "batb": NaN, "batl": [[0, 1.34, 21.01]]}, {"timestamp": 1631449903987, "ltp": 1.3, "tv": 50367.82, "trd": NaN, "batb": [[1, 1.22, 50.34], [2, 1.2, 1.71]], "batl": NaN}, {"timestamp": 1631449906597, "ltp": 1.34, "tv": 50386.86, "trd": [[1.34, 14511.35]], "batb": [[0, 1.32, 1521.3], [1, 1.31, 1476.56], [2, 1.3, 1478.75]], "batl": [[0, 1.35, 34.5], [1, 1.36, 618.52], [2, 1.37, 393.6]]}, {"timestamp": 1631449907485, "ltp": 1.32, "tv": 50391.86, "trd": [[1.32, 243.78]], "batb": [[0, 1.32, 1473.08], [1, 1.31, 1286.86], [2, 1.3, 775.63]], "batl": [[1, 1.36, 630.25]]}, {"timestamp": 1631449908459, "ltp": 1.35, "tv": 50431.27, "trd": [[1.35, 1038.54]], "batb": [[2, 1.3, 803.01]], "batl": [[0, 1.35, 9.09], [2, 1.37, 453.6]]}, {"timestamp": 1631449911482, "ltp": 1.35, "tv": 50431.27, "trd": NaN, "batb": [[0, 1.32, 1524.73], [2, 1.3, 775.63]], "batl": NaN}, {"timestamp": 1631449911973, "ltp": 1.32, "tv": 50489.11, "trd": [[1.32, 301.63]], "batb": [[0, 1.32, 1495.81]], "batl": NaN}, {"timestamp": 1631449913471, "ltp": 1.32, "tv": 50489.11, "trd": NaN, "batb": [[0, 1.32, 1496.64], [2, 1.3, 773.64]], "batl": NaN}, {"timestamp": 1631449914200, "ltp": 1.32, "tv": 50489.11, "trd": NaN, "batb": [[1, 1.31, 1313.8]], "batl": NaN}, {"timestamp": 1631449915708, "ltp": 1.32, "tv": 50489.11, "trd": NaN, "batb": [[0, 1.34, 250.83], [1, 1.32, 1495.81], [2, 1.31, 1313.8]], "batl": NaN}, {"timestamp": 1631449917311, "ltp": 1.32, "tv": 50489.11, "trd": NaN, "batb": [[0, 1.34, 250]], "batl": NaN}, {"timestamp": 1631449919406, "ltp": 1.32, "tv": 50489.11, "trd": NaN, "batb": [[1, 1.33, 48.81], [2, 1.32, 1495.81]], "batl": NaN}, {"timestamp": 1631449920207, "ltp": 1.35, "tv": 50514.97, "trd": [[1.35, 1064.39]], "batb": NaN, "batl": [[0, 1.35, 2181.99]]}, {"timestamp": 1631449921543, "ltp": 1.35, "tv": 50518.94, "trd": [[1.35, 1068.37]], "batb": NaN, "batl": [[0, 1.35, 2180.01]]}, {"timestamp": 1631449921931, "ltp": 1.35, "tv": 50519.23, "trd": [[1.35, 1068.65]], "batb": NaN, "batl": [[0, 1.35, 2179.72]]}, {"timestamp": 1631449924851, "ltp": 1.35, "tv": 50530.63, "trd": [[1.35, 1080.05]], "batb": NaN, "batl": [[0, 1.35, 2174.02]]}, {"timestamp": 1631449925648, "ltp": 1.34, "tv": 50546.53, "trd": [[1.34, 14527.26]], "batb": [[0, 1.34, 242.05]], "batl": NaN}, {"timestamp": 1631449928058, "ltp": 1.35, "tv": 50568.02, "trd": [[1.34, 14548.36], [1.35, 1080.44]], "batb": [[0, 1.34, 231.5]], "batl": [[0, 1.35, 2173.83]]}, {"timestamp": 1631449930434, "ltp": 1.34, "tv": 51354.3, "trd": [[1.34, 14590.73], [1.35, 1824.35]], "batb": [[0, 1.34, 197.88]], "batl": [[0, 1.35, 1429.92]]}, {"timestamp": 1631449931572, "ltp": 1.34, "tv": 51364.23, "trd": [[1.34, 14598.99], [1.35, 1826.02]], "batb": [[0, 1.34, 193.75]], "batl": [[0, 1.35, 1429.09]]}, {"timestamp": 1631449931848, "ltp": 1.35, "tv": 51462.29, "trd": [[1.35, 1924.08]], "batb": NaN, "batl": [[0, 1.35, 1331.02]]}, {"timestamp": 1631449933864, "ltp": 1.34, "tv": 51849.79, "trd": [[1.34, 14986.49]], "batb": [[0, 1.33, 48.81], [1, 1.32, 1495.81], [2, 1.31, 1313.8]], "batl": [[0, 1.34, 48.25], [1, 1.35, 1331.02], [2, 1.36, 630.25]]}, {"timestamp": 1631449937945, "ltp": 1.34, "tv": 51853.13, "trd": [[1.34, 14989.83]], "batb": NaN, "batl": [[0, 1.34, 46.58]]}, {"timestamp": 1631449938757, "ltp": 1.34, "tv": 51853.13, "trd": NaN, "batb": NaN, "batl": [[0, 1.35, 1331.02], [1, 1.36, 630.25], [2, 1.37, 453.6]]}, {"timestamp": 1631449940721, "ltp": 1.35, "tv": 51858.43, "trd": [[1.35, 1929.38]], "batb": NaN, "batl": [[0, 1.35, 1328.37]]}, {"timestamp": 1631449943896, "ltp": 1.35, "tv": 51858.43, "trd": NaN, "batb": [[1, 1.32, 817.1], [2, 1.31, 800.38]], "batl": [[1, 1.36, 36.57], [2, 1.37, 60]]}, {"timestamp": 1631449947380, "ltp": 1.35, "tv": 51858.43, "trd": NaN, "batb": NaN, "batl": [[0, 1.34, 219.88], [1, 1.35, 1328.37], [2, 1.36, 36.57]]}, {"timestamp": 1631449955587, "ltp": 1.34, "tv": 51871.27, "trd": [[1.34, 15002.67]], "batb": NaN, "batl": [[0, 1.34, 213.46]]}, {"timestamp": 1631449959182, "ltp": 1.34, "tv": 51890.92, "trd": [[1.34, 15022.31]], "batb": NaN, "batl": [[0, 1.34, 203.63]]}, {"timestamp": 1631449962293, "ltp": 1.33, "tv": 51898.33, "trd": [[1.33, 351.21]], "batb": [[0, 1.33, 45.11]], "batl": NaN}, {"timestamp": 1631449965716, "ltp": 1.34, "tv": 51903.9, "trd": [[1.34, 15027.89]], "batb": NaN, "batl": [[0, 1.34, 200.85]]}, {"timestamp": 1631449969401, "ltp": 1.33, "tv": 51994.12, "trd": [[1.33, 441.42]], "batb": [[0, 1.32, 817.1], [1, 1.31, 800.38], [2, 1.3, 773.64]], "batl": [[0, 1.33, 36.73], [1, 1.34, 200.85]]}, {"timestamp": 1631449977096, "ltp": 1.33, "tv": 51994.42, "trd": [[1.33, 441.72]], "batb": NaN, "batl": [[0, 1.33, 36.43]]}, {"timestamp": 1631449980516, "ltp": 1.33, "tv": 51994.42, "trd": NaN, "batb": [[0, 1.31, 26.94], [1, 1.29, 539.04], [2, 1.28, 579.24]], "batl": [[0, 1.32, 5.12], [1, 1.33, 36.43], [2, 1.37, 60]]}, {"timestamp": 1631449981509, "ltp": 1.33, "tv": 51994.42, "trd": NaN, "batb": [[0, 1.29, 539.04], [1, 1.28, 579.24], [2, 1.27, 48.87]], "batl": [[1, 1.38, 33.25], [2, 1.41, 301.1]]}, {"timestamp": 1631449981724, "ltp": 1.33, "tv": 51994.42, "trd": NaN, "batb": NaN, "batl": [[1, 1.41, 301.1], [2, 1.42, 339.11]]}, {"timestamp": 1631449983558, "ltp": 1.32, "tv": 51994.93, "trd": [[1.32, 302.14]], "batb": NaN, "batl": [[0, 1.32, 4.87]]}, {"timestamp": 1631449984384, "ltp": 1.32, "tv": 51994.93, "trd": NaN, "batb": [[0, 1.29, 582.85]], "batl": [[0, 1.32, 41.3]]}, {"timestamp": 1631449988441, "ltp": 1.32, "tv": 51994.93, "trd": NaN, "batb": NaN, "batl": [[1, 1.38, 30.25], [2, 1.41, 301.1]]}, {"timestamp": 1631449988717, "ltp": 1.32, "tv": 51994.93, "trd": NaN, "batb": NaN, "batl": [[1, 1.41, 301.1], [2, 1.42, 339.11]]}, {"timestamp": 1631449995428, "ltp": 1.32, "tv": 51994.93, "trd": NaN, "batb": NaN, "batl