{"info": {"id": "1.187595437", "eventId": "30898003", "eventName": "Match Odds", "marketType": "MATCH_ODDS", "openDate": 1631540744079, "name": "T Lukas v Y Cavalle-reimers", "numberOfActiveRunner": 2, "countryCode": "", "sport": "TENNIS", "venue": "", "volume": {"total": 2617.14, "preMatch": 18.17, "inPlay": 2598.97}, "winner": {"id": 9168659, "name": "T Lukas", "status": "WINNER", "position": 1}, "delay": 5}, "runners": [{"id": 9168659, "name": "T Lukas", "status": "WINNER", "position": 1, "inPlayOdds": 1.87, "inPlayTime": 1631542191128, "avgPrematch": 0, "closedOdds": 1.01, "maxPrematch": -100, "minPrematch": 1001, "maxInPlay": 1.87, "minInPlay": 1.01, "inPlayIndex": 0, "lengthOdds": 323, "lengthOddsPrematch": 0, "lengthOddsInPlay": 323, "tradedVolume": 2346.74, "preMatchVolume": 2.0, "inPlayVolume": 2344.74}, {"id": 9628279, "name": "Y Cavalle-Reimers", "status": "LOSER", "position": 2, "inPlayOdds": 1.45, "inPlayTime": 1631540744079, "avgPrematch": 1.45, "closedOdds": 7.0, "maxPrematch": 1.45, "minPrematch": 1.45, "maxInPlay": 100.0, "minInPlay": 1.42, "inPlayIndex": 4, "lengthOdds": 239, "lengthOddsPrematch": 4, "lengthOddsInPlay": 235, "tradedVolume": 270.4, "preMatchVolume": 16.17, "inPlayVolume": 254.23}], "marketUpdates": [{"timestamp": 1631518765810000000, "openDate": "2021-09-13T13:30:00.000Z", "status": "OPEN", "betDelay": 0, "inPlay": false, "complete": true}, {"timestamp": 1631539617753000000, "openDate": "2021-09-13T13:40:00.000Z", "status": "OPEN", "betDelay": 0, "inPlay": false, "complete": true}, {"timestamp": 1631540232209000000, "openDate": "2021-09-13T13:50:00.000Z", "status": "OPEN", "betDelay": 0, "inPlay": false, "complete": true}, {"timestamp": 1631540292538000000, "openDate": "2021-09-13T13:45:00.000Z", "status": "OPEN", "betDelay": 0, "inPlay": false, "complete": true}, {"timestamp": 1631540744079000000, "openDate": "2021-09-13T13:45:00.000Z", "status": "OPEN", "betDelay": 5, "inPlay": true, "complete": true}, {"timestamp": 1631541568405000000, "openDate": "2021-09-13T13:59:24.000Z", "status": "OPEN", "betDelay": 5, "inPlay": true, "complete": true}, {"timestamp": 1631546140134000000, "openDate": "2021-09-13T13:59:24.000Z", "status": "SUSPENDED", "betDelay": 5, "inPlay": true, "complete": true}, {"timestamp": 1631546147196000000, "openDate": "2021-09-13T13:59:24.000Z", "status": "CLOSED", "betDelay": 5, "inPlay": true, "complete": true}], "odds": [{"runnerId": 9168659, "odds": [{"timestamp": 1631542191128, "ltp": 1.87, "tv": 2.0, "trd": [[1.87, 2]], "batb": [[0, 1.58, 422.14], [1, 1.55, 54.54]], "batl": NaN}, {"timestamp": 1631542192361, "ltp": 1.87, "tv": 2.0, "trd": NaN, "batb": NaN, "batl": [[0, 2.3, 313.97]]}, {"timestamp": 1631542194557, "ltp": 1.87, "tv": 2.0, "trd": NaN, "batb": NaN, "batl": [[0, 1.87, 386.42], [1, 2.3, 313.97]]}, {"timestamp": 1631542195272, "ltp": 1.87, "tv": 2.0, "trd": NaN, "batb": NaN, "batl": [[0, 2.3, 313.97], [1, 2.3, 0]]}, {"timestamp": 1631542230700, "ltp": 1.87, "tv": 2.0, "trd": NaN, "batb": [[0, 1.61, 28.45], [1, 1.58, 422.14], [2, 1.55, 54.54]], "batl": NaN}, {"timestamp": 1631542235626, "ltp": 1.87, "tv": 2.0, "trd": NaN, "batb": [[1, 1.01, 7], [2, 1.55, 0]], "batl": NaN}, {"timestamp": 1631542240544, "ltp": 1.87, "tv": 2.0, "trd": NaN, "batb": [[1, 1.51, 58.82], [2, 1.01, 7]], "batl": NaN}, {"timestamp": 1631542241713, "ltp": 1.87, "tv": 2.0, "trd": NaN, "batb": [[2, 1.46, 441.64]], "batl": NaN}, {"timestamp": 1631542344435, "ltp": 1.87, "tv": 2.0, "trd": NaN, "batb": [[1, 1.46, 441.64], [2, 1.01, 7]], "batl": NaN}, {"timestamp": 1631542349326, "ltp": 1.87, "tv": 2.0, "trd": NaN, "batb": [[1, 1.48, 62.5], [2, 1.46, 441.64]], "batl": NaN}, {"timestamp": 1631542351357, "ltp": 1.87, "tv": 2.0, "trd": NaN, "batb": NaN, "batl": [[0, 2.16, 347.49]]}, {"timestamp": 1631542368251, "ltp": 1.87, "tv": 2.0, "trd": NaN, "batb": [[1, 1.46, 441.64], [2, 1.01, 7]], "batl": NaN}, {"timestamp": 1631542373137, "ltp": 1.87, "tv": 2.0, "trd": NaN, "batb": [[1, 1.51, 58.82], [2, 1.46, 441.64]], "batl": NaN}, {"timestamp": 1631542373767, "ltp": 1.87, "tv": 2.0, "trd": NaN, "batb": [[0, 1.51, 58.82], [1, 1.46, 441.64], [2, 1.01, 7]], "batl": NaN}, {"timestamp": 1631542387473, "ltp": 1.87, "tv": 2.0, "trd": NaN, "batb": [[0, 1.46, 441.64], [1, 1.01, 7], [2, 1.01, 0]], "batl": NaN}, {"timestamp": 1631542392398, "ltp": 1.87, "tv": 2.0, "trd": NaN, "batb": [[1, 1.45, 66.66], [2, 1.01, 7]], "batl": NaN}, {"timestamp": 1631542428547, "ltp": 1.87, "tv": 2.0, "trd": NaN, "batb": [[0, 1.45, 66.66], [1, 1.01, 7], [2, 1.01, 0]], "batl": NaN}, {"timestamp": 1631542429128, "ltp": 1.87, "tv": 2.0, "trd": NaN, "batb": [[0, 1.01, 7], [1, 1.01, 0]], "batl": NaN}, {"timestamp": 1631542434246, "ltp": 1.87, "tv": 2.0, "trd": NaN, "batb": [[0, 1.42, 71.42], [1, 1.34, 471.77], [2, 1.01, 7]], "batl": [[0, 1.95, 415.45]]}, {"timestamp": 1631542454693, "ltp": 1.87, "tv": 2.0, "trd": NaN, "batb": [[0, 1.49, 31.16], [1, 1.42, 71.42], [2, 1.34, 471.77]], "batl": NaN}, {"timestamp": 1631542471348, "ltp": 1.87, "tv": 2.0, "trd": NaN, "batb": [[1, 1.34, 471.77], [2, 1.01, 7]], "batl": NaN}, {"timestamp": 1631542472138, "ltp": 1.87, "tv": 2.0, "trd": NaN, "batb": [[1, 1.01, 7], [2, 1.01, 0]], "batl": NaN}, {"timestamp": 1631542476373, "ltp": 1.87, "tv": 2.0, "trd": NaN, "batb": [[1, 1.45, 66.66], [2, 1.01, 7]], "batl": NaN}, {"timestamp": 1631542477736, "ltp": 1.87, "tv": 2.0, "trd": NaN, "batb": [[2, 1.38, 454.56]], "batl": NaN}, {"timestamp": 1631542506481, "ltp": 1.87, "tv": 2.0, "trd": NaN, "batb": [[1, 1.38, 454.56], [2, 1.01, 7]], "batl": NaN}, {"timestamp": 1631542507682, "ltp": 1.87, "tv": 2.0, "trd": NaN, "batb": [[1, 1.01, 7], [2, 1.01, 0]], "batl": NaN}, {"timestamp": 1631542511389, "ltp": 1.87, "tv": 2.0, "trd": NaN, "batb": [[0, 1.51, 58.82], [1, 1.49, 31.16], [2, 1.01, 7]], "batl": NaN}, {"timestamp": 1631542514015, "ltp": 1.87, "tv": 2.0, "trd": NaN, "batb": [[2, 1.44, 442.12]], "batl": [[0, 2.16, 347.49]]}, {"timestamp": 1631542547337, "ltp": 1.87, "tv": 2.0, "trd": NaN, "batb": [[0, 1.49, 31.16], [1, 1.01, 7], [2, 1.44, 0]], "batl": NaN}, {"timestamp": 1631542552131, "ltp": 1.87, "tv": 2.0, "trd": NaN, "batb": [[1, 1.45, 66.66], [2, 1.01, 7]], "batl": NaN}, {"timestamp": 1631542553284, "ltp": 1.87, "tv": 2.0, "trd": NaN, "batb": [[2, 1.38, 454.56]], "batl": [[0, 2.04, 388.23]]}, {"timestamp": 1631542571793, "ltp": 1.87, "tv": 2.0, "trd": NaN, "batb": [[2, 1.01, 7]], "batl": NaN}, {"timestamp": 1631542583277, "ltp": 1.87, "tv": 2.0, "trd": NaN, "batb": [[1, 1.01, 7], [2, 1.01, 0]], "batl": NaN}, {"timestamp": 1631542585091, "ltp": 1.87, "tv": 2.0, "trd": NaN, "batb": [[1, 1.34, 471.77], [2, 1.01, 7]], "batl": [[0, 1.95, 415.45]]}, {"timestamp": 1631542586025, "ltp": 1.87, "tv": 2.0, "trd": NaN, "batb": [[1, 1.01, 7], [2, 1.01, 0]], "batl": NaN}, {"timestamp": 1631542588206, "ltp": 1.87, "tv": 2.0, "trd": NaN, "batb": [[1, 1.38, 78.94], [2, 1.01, 7]], "batl": NaN}, {"timestamp": 1631542594583, "ltp": 1.49, "tv": 56.54, "trd": [[1.49, 54.54]], "batb": [[0, 1.38, 78.94], [1, 1.01, 7], [2, 1.01, 0]], "batl": [[0, 1.49, 126.93]]}, {"timestamp": 1631542619433, "ltp": 1.49, "tv": 56.54, "trd": NaN, "batb": [[1, 1.25, 511.97], [2, 1.01, 7]], "batl": [[0, 1.77, 507.43]]}, {"timestamp": 1631542640323, "ltp": 1.49, "tv": 56.54, "trd": NaN, "batb": [[0, 1.25, 511.97], [1, 1.01, 7], [2, 1.01, 0]], "batl": NaN}, {"timestamp": 1631542640789, "ltp": 1.49, "tv": 56.54, "trd": NaN, "batb": [[0, 1.01, 7], [1, 1.01, 0]], "batl": NaN}, {"timestamp": 1631542645218, "ltp": 1.49, "tv": 56.54, "trd": NaN, "batb": [[0, 1.34, 88.23], [1, 1.01, 7]], "batl": NaN}, {"timestamp": 1631542646793, "ltp": 1.49, "tv": 56.54, "trd": NaN, "batb": [[1, 1.22, 530.12], [2, 1.01, 7]], "batl": NaN}, {"timestamp": 1631542656725, "ltp": 1.49, "tv": 56.54, "trd": NaN, "batb": NaN, "batl": [[0, 1.66, 587.71]]}, {"timestamp": 1631542673759, "ltp": 1.49, "tv": 56.54, "trd": NaN, "batb": [[0, 1.22, 530.12], [1, 1.01, 7], [2, 1.01, 0]], "batl": NaN}, {"timestamp": 1631542678745, "ltp": 1.49, "tv": 56.54, "trd": NaN, "batb": [[0, 1.38, 78.94], [1, 1.22, 530.12], [2, 1.01, 7]], "batl": NaN}, {"timestamp": 1631542692371, "ltp": 1.38, "tv": 80.28, "trd": [[1.38, 23.74]], "batb": [[0, 1.22, 530.12], [1, 1.01, 7], [2, 1.01, 0]], "batl": NaN}, {"timestamp": 1631542697361, "ltp": 1.38, "tv": 80.28, "trd": NaN, "batb": [[0, 1.38, 78.94], [1, 1.22, 530.12], [2, 1.01, 7]], "batl": NaN}, {"timestamp": 1631542726021, "ltp": 1.38, "tv": 80.28, "trd": NaN, "batb": [[1, 1.01, 7], [2, 1.01, 0]], "batl": NaN}, {"timestamp": 1631542731741, "ltp": 1.38, "tv": 80.28, "trd": NaN, "batb": [[1, 1.25, 511.97], [2, 1.01, 7]], "batl": NaN}, {"timestamp": 1631542735225, "ltp": 1.38, "tv": 80.28, "trd": NaN, "batb": [[1, 1.01, 7], [2, 1.01, 0]], "batl": NaN}, {"timestamp": 1631542740945, "ltp": 1.38, "tv": 80.28, "trd": NaN, "batb": [[1, 1.22, 530.12], [2, 1.01, 7]], "batl": NaN}, {"timestamp": 1631542757585, "ltp": 1.38, "tv": 80.28, "trd": NaN, "batb": [[1, 1.01, 7], [2, 1.01, 0]], "batl": NaN}, {"timestamp": 1631542763105, "ltp": 1.38, "tv": 80.28, "trd": NaN, "batb": [[1, 1.25, 511.97], [2, 1.01, 7]], "batl": NaN}, {"timestamp": 1631542789030, "ltp": 1.38, "tv": 80.28, "trd": NaN, "batb": [[1, 1.01, 7], [2, 1.01, 0]], "batl": NaN}, {"timestamp": 1631542794467, "ltp": 1.38, "tv": 80.28, "trd": NaN, "batb": [[1, 1.22, 530.12], [2, 1.01, 7]], "batl": NaN}, {"timestamp": 1631542799252, "ltp": 1.38, "tv": 80.28, "trd": NaN, "batb": [[1, 1.01, 7], [2, 1.01, 0]], "batl": NaN}, {"timestamp": 1631542807979, "ltp": 1.38, "tv": 80.28, "trd": NaN, "batb": [[0, 1.01, 7], [1, 1.01, 0]], "batl": NaN}, {"timestamp": 1631542812857, "ltp": 1.38, "tv": 80.28, "trd": NaN, "batb": [[0, 1.34, 88.23], [1, 1.01, 7]], "batl": NaN}, {"timestamp": 1631542857732, "ltp": 1.38, "tv": 80.28, "trd": NaN, "batb": NaN, "batl": [[0, 1.4, 5]]}, {"timestamp": 1631542863267, "ltp": 1.34, "tv": 87.06, "trd": [[1.34, 6.78]], "batb": [[0, 1.01, 7], [1, 1.01, 0]], "batl": NaN}, {"timestamp": 1631542868264, "ltp": 1.34, "tv": 87.06, "trd": NaN, "batb": [[0, 1.34, 88.23], [1, 1.01, 7]], "batl": NaN}, {"timestamp": 1631542919135, "ltp": 1.34, "tv": 87.06, "trd": NaN, "batb": [[0, 1.01, 7], [1, 1.01, 0]], "batl": NaN}, {"timestamp": 1631542924068, "ltp": 1.34, "tv": 87.06, "trd": NaN, "batb": [[0, 1.31, 96.77], [1, 1.01, 7]], "batl": NaN}, {"timestamp": 1631542946493, "ltp": 1.34, "tv": 87.06, "trd": NaN, "batb": [[0, 1.01, 7], [1, 1.01, 0]], "batl": NaN}, {"timestamp": 1631542951387, "ltp": 1.34, "tv": 87.06, "trd": NaN, "batb": [[0, 1.34, 88.23], [1, 1.01, 7]], "batl": NaN}, {"timestamp": 1631542978417, "ltp": 1.34, "tv": 87.06, "trd": NaN, "batb": [[1, 1.16, 583.98], [2, 1.01, 7]], "batl": [[1, 1.58, 659.44]]}, {"timestamp": 1631542980628, "ltp": 1.34, "tv": 112.62, "trd": [[1.34, 32.34]], "batb": [[0, 1.34, 62.67]], "batl": NaN}, {"timestamp": 1631542981630, "ltp": 1.34, "tv": 163.74, "trd": [[1.34, 83.46]], "batb": [[0, 1.16, 583.98], [1, 1.01, 7], [2, 1.01, 0]], "batl": [[0, 1.34, 68.13], [1, 1.4, 5], [2, 1.58, 659.44]]}, {"timestamp": 1631542982469, "ltp": 1.34, "tv": 163.74, "trd": NaN, "batb": NaN, "batl": [[0, 1.34, 42.58]]}, {"timestamp": 1631542983568, "ltp": 1.34, "tv": 163.74, "trd": NaN, "batb": NaN, "batl": [[0, 1.34, 34.07]]}, {"timestamp": 1631542984463, "ltp": 1.34, "tv": 163.74, "trd": NaN, "batb": NaN, "batl": [[0, 1.4, 5], [1, 1.58, 659.44], [2, 1.58, 0]]}, {"timestamp": 1631542985565, "ltp": 1.34, "tv": 163.74, "trd": NaN, "batb": NaN, "batl": [[0, 1.34, 60], [1, 1.4, 5], [2, 1.58, 659.44]]}, {"timestamp": 1631542986559, "ltp": 1.34, "tv": 340.2, "trd": [[1.34, 259.92]], "batb": NaN, "batl": [[0, 1.34, 1.77]]}, {"timestamp": 1631542987077, "ltp": 1.34, "tv": 340.2, "trd": NaN, "batb": NaN, "batl": [[0, 1.34, 30]]}, {"timestamp": 1631542988171, "ltp": 1.34, "tv": 340.2, "trd": NaN, "batb": NaN, "batl": [[0, 1.4, 5], [1, 1.58, 659.44], [2, 1.58, 0]]}, {"timestamp": 1631543041317, "ltp": 1.34, "tv": 340.2, "trd": NaN, "batb": [[0, 1.21, 62.3], [1, 1.16, 583.98], [2, 1.01, 7]], "batl": NaN}, {"timestamp": 1631543042256, "ltp": 1.34, "tv": 340.2, "trd": NaN, "batb": [[1, 1.2, 124.6], [2, 1.16, 583.98]], "batl": NaN}, {"timestamp": 1631543044350, "ltp": 1.34, "tv": 340.2, "trd": NaN, "batb": [[0, 1.2, 124.6], [1, 1.16, 583.98], [2, 1.01, 7]], "batl": [[0, 1.36, 62.3], [1, 1.4, 5], [2, 1.58, 659.44]]}, {"timestamp": 1631543086999, "ltp": 1.34, "tv": 340.2, "trd": NaN, "batb": [[1, 1.01, 7], [2, 1.01, 0]], "batl": NaN}, {"timestamp": 1631543092321, "ltp": 1.34, "tv": 340.2, "trd": NaN, "batb": NaN, "batl": [[0, 1.4, 5], [1, 1.58, 659.44], [2, 1.58, 0]]}, {"timestamp": 1631543092842, "ltp": 1.34, "tv": 340.2, "trd": NaN, "batb": [[1, 1.18, 557.21], [2, 1.01, 7]], "batl": NaN}, {"timestamp": 1631543097910, "ltp": 1.34, "tv": 340.2, "trd": NaN, "batb": NaN, "batl": [[0, 1.39, 62.3], [1, 1.4, 5], [2, 1.58, 659.44]]}, {"timestamp": 1631543100135, "ltp": 1.34, "tv": 340.2, "trd": NaN, "batb": [[0, 1.2, 186.9]], "batl": NaN}, {"timestamp": 1631543131809, "ltp": 1.34, "tv": 340.2, "trd": NaN, "batb": [[1, 1.01, 7], [2, 1.01, 0]], "batl": NaN}, {"timestamp": 1631543137074, "ltp": 1.34, "tv": 340.2, "trd": NaN, "batb": [[0, 1.2, 724.99]], "batl": NaN}, {"timestamp": 1631543145881, "ltp": 1.34, "tv": 340.2, "trd": NaN, "batb": NaN, "batl": [[0, 1.4, 5], [1, 1.58, 659.44], [2, 1.58, 0]]}, {"timestamp": 1631543152327, "ltp": 1.34, "tv": 340.2, "trd": NaN, "batb": NaN, "batl": [[1, 1.5, 62.3], [2, 1.58, 659.44]]}, {"timestamp": 1631543185672, "ltp": 1.34, "tv": 340.2, "trd": NaN, "batb": [[0, 1.31, 96.77], [1, 1.2, 724.99], [2, 1.01, 7]], "batl": NaN}, {"timestamp": 1631543196993, "ltp": 1.34, "tv": 340.2, "trd": NaN, "batb": NaN, "batl": [[1, 1.58, 659.44], [2, 1.58, 0]]}, {"timestamp": 1631543204189, "ltp": 1.34, "tv": 340.2, "trd": NaN, "batb": NaN, "batl": [[0, 1.4, 67.3]]}, {"timestamp": 1631543211726, "ltp": 1.34, "tv": 340.2, "trd": NaN, "batb": [[1, 1.2, 186.9]], "batl": NaN}, {"timestamp": 1631543217048, "ltp": 1.34, "tv": 340.2, "trd": NaN, "batb": [[1, 1.01, 7], [2, 1.01, 0]], "batl": NaN}, {"timestamp": 1631543218035, "ltp": 1.34, "tv": 340.2, "trd": NaN, "batb": [[1, 1.14, 618.77], [2, 1.01, 7]], "batl": NaN}, {"timestamp": 1631543223265, "ltp": 1.34, "tv": 340.2, "trd": NaN, "batb": [[1, 1.16, 186.9]], "batl": NaN}, {"timestamp": 1631543223740, "ltp": 1.34, "tv": 340.2, "trd": NaN, "batb": [[1, 1.16, 249.2]], "batl": NaN}, {"timestamp": 1631543229168, "ltp": 1.34, "tv": 340.2, "trd": NaN, "batb": [[1, 1.16, 833.18]], "batl": NaN}, {"timestamp": 1631543229883, "ltp": 1.34, "tv": 340.2, "trd": NaN, "batb": [[1, 1.16, 249.2]], "batl": NaN}, {"timestamp": 1631543235068, "ltp": 1.34, "tv": 340.2, "trd": NaN, "batb": [[0, 1.16, 249.2], [1, 1.01, 7], [2, 1.01, 0]], "batl": NaN}, {"timestamp": 1631543239972, "ltp": 1.34, "tv": 340.2, "trd": NaN, "batb": [[0, 1.28, 107.14], [1, 1.16, 249.2], [2, 1.01, 7]], "batl": NaN}, {"timestamp": 1631543243986, "ltp": 1.34, "tv": 340.2, "trd": NaN, "batb": [[0, 1.16, 249.2], [1, 1.01, 7], [2, 1.01, 0]], "batl": NaN}, {"timestamp": 1631543248904, "ltp": 1.34, "tv": 340.2, "trd": NaN, "batb": [[0, 1.27, 111.11], [1, 1.16, 249.2], [2, 1.01, 7]], "batl": NaN}, {"timestamp": 1631543270433, "ltp": 1.4, "tv": 365.78, "trd": [[1.4, 25.58]], "batb": NaN, "batl": [[0, 1.4, 41.72]]}, {"timestamp": 1631543270644, "ltp": 1.4, "tv": 365.78, "trd": NaN, "batb": NaN, "batl": [[1, 1.58, 0]]}, {"timestamp": 1631543311464, "ltp": 1.27, "tv": 368.54, "trd": [[1.27, 2.76]], "batb": [[0, 1.16, 249.2], [1, 1.01, 7], [2, 1.01, 0]], "batl": NaN}, {"timestamp": 1631543316498, "ltp": 1.27, "tv": 368.54, "trd": NaN, "batb": [[0, 1.27, 111.11], [1, 1.16, 249.2], [2, 1.01, 7]], "batl": NaN}, {"timestamp": 1631543333412, "ltp": 1.27, "tv": 368.54, "trd": NaN, "batb": [[0, 1.16, 249.2], [1, 1.01, 7], [2, 1.01, 0]], "batl": NaN}, {"timestamp": 1631543338435, "ltp": 1.27, "tv": 368.54, "trd": NaN, "batb": [[0, 1.2, 150], [1, 1.16, 249.2], [2, 1.01, 7]], "batl": NaN}, {"timestamp": 1631543367869, "ltp": 1.27, "tv": 368.54, "trd": NaN, "batb": [[0, 1.16, 249.2], [1, 1.01, 7], [2, 1.01, 0]], "batl": NaN}, {"timestamp": 1631543371257, "ltp": 1.27, "tv": 368.54, "trd": NaN, "batb": NaN, "batl": [[0, 1.2, 7.95], [1, 1.4, 41.72]]}, {"timestamp": 1631543373059, "ltp": 1.2, "tv": 384.44, "trd": [[1.2, 15.9]], "batb": NaN, "batl": [[0, 1.4, 41.72], [1, 1.4, 0]]}, {"timestamp": 1631543377874, "ltp": 1.2, "tv": 384.44, "trd": NaN, "batb": [[0, 1.27, 111.11], [1, 1.16, 249.2], [2, 1.01, 7]], "batl": NaN}, {"timestamp": 1631543398602, "ltp": 1.2, "tv": 384.44, "trd": NaN, "batb": [[0, 1.16, 249.2], [1, 1.01, 7], [2, 1.01, 0]], "batl": NaN}, {"timestamp": 1631543401731, "ltp": 1.2, "tv": 384.44, "trd": NaN, "batb": [[0, 1.01, 7], [1, 1.01, 0]], "batl": NaN}, {"timestamp": 1631543403507, "ltp": 1.2, "tv": 384.44, "trd": NaN, "batb": [[0, 1.2, 150], [1, 1.01, 7]], "batl": NaN}, {"timestamp": 1631543408524, "ltp": 1.2, "tv": 384.44, "trd": NaN, "batb": [[0, 1.22, 50], [1, 1.21, 50], [2, 1.2, 150]], "batl": NaN}, {"timestamp": 1631543409519, "ltp": 1.2, "tv": 384.44, "trd": NaN, "batb": [[0, 1.22, 250]], "batl": NaN}, {"timestamp": 1631543410143, "ltp": 1.2, "tv": 384.44, "trd": NaN, "batb": [[0, 1.21, 50], [1, 1.2, 150], [2, 1.01, 7]], "batl": NaN}, {"timestamp": 1631543410818, "ltp": 1.2, "tv": 384.44, "trd": NaN, "batb": [[0, 1.2, 150], [1, 1.01, 7], [2, 1.01, 0]], "batl": NaN}, {"timestamp": 1631543418341, "ltp": 1.2, "tv": 384.44, "trd": NaN, "batb": [[1, 1.16, 200], [2, 1.01, 7]], "batl": NaN}, {"timestamp": 1631543418652, "ltp": 1.2, "tv": 384.44, "trd": NaN, "batb": [[1, 1.16, 250]], "batl": NaN}, {"timestamp": 1631543429305, "ltp": 1.2, "tv": 384.44, "trd": NaN, "batb": [[0, 1.16, 250], [1, 1.01, 7], [2, 1.01, 0]], "batl": NaN}, {"timestamp": 1631543434211, "ltp": 1.2, "tv": 384.44, "trd": NaN, "batb": [[0, 1.18, 166.66], [1, 1.16, 250], [2, 1.01, 7]], "batl": NaN}, {"timestamp": 1631543446423, "ltp": 1.2, "tv": 384.44, "trd": NaN, "batb": [[1, 1.01, 7], [2, 1.01, 0]], "batl": NaN}, {"timestamp": 1631543453624, "ltp": 1.2, "tv": 384.44, "trd": NaN, "batb": [[1, 1.14, 100], [2, 1.01, 7]], "batl": NaN}, {"timestamp": 1631543453727, "ltp": 1.2, "tv": 384.44, "trd": NaN, "batb": [[1, 1.14, 150]], "batl": NaN}, {"timestamp": 1631543454720, "ltp": 1.2, "tv": 384.44, "trd": NaN, "batb": [[1, 1.14, 200]], "batl": NaN}, {"timestamp": 1631543461770, "ltp": 1.2, "tv": 384.44, "trd": NaN, "batb": [[0, 1.14, 200], [1, 1.01, 7], [2, 1.01, 0]], "batl": NaN}, {"timestamp": 1631543467168, "ltp": 1.2, "tv": 384.44, "trd": NaN, "batb": [[0, 1.2, 150]], "batl": NaN}, {"timestamp": 1631543467675, "ltp": 1.2, "tv": 384.44, "trd": NaN, "batb": [[1, 1.14, 618.77], [2, 1.01, 7]], "batl": [[1, 1.55, 700.17]]}, {"timestamp": 1631543471253, "ltp": 1.2, "tv": 384.44, "trd": NaN, "batb": [[1, 1.16, 200], [2, 1.14, 618.77]], "batl": NaN}, {"timestamp": 1631543492898, "ltp": 1.2, "tv": 384.44, "trd": NaN, "batb": [[0, 1.16, 200], [1, 1.01, 7], [2, 1.14, 0]], "batl": [[1, 1.55, 0]]}, {"timestamp": 1631543496721, "ltp": 1.2, "tv": 384.44, "trd": NaN, "batb": [[0, 1.01, 7], [1, 1.01, 0]], "batl": NaN}, {"timestamp": 1631543497824, "ltp": 1.2, "tv": 384.44, "trd": NaN, "batb": [[0, 1.18, 166.66], [1, 1.01, 7]], "batl": NaN}, {"timestamp": 1631543498876, "ltp": 1.2, "tv": 384.44, "trd": NaN, "batb": [[1, 1.1, 733.06], [2, 1.01, 7]], "batl": [[1, 1.48, 795.63]]}, {"timestamp": 1631543504209, "ltp": 1.2, "tv": 384.44, "trd": NaN, "batb": [[1, 1.12, 200], [2, 1.1, 733.06]], "batl": [[0, 1.48, 795.63], [1, 1.48, 0]]}, {"timestamp": 1631543511840, "ltp": 1.2, "tv": 384.44, "trd": NaN, "batb": NaN, "batl": [[0, 1.3, 41.72], [1, 1.48, 795.63]]}, {"timestamp": 1631543572126, "ltp": 1.2, "tv": 384.44, "trd": NaN, "batb": [[0, 1.12, 200], [1, 1.1, 733.06], [2, 1.01, 7]], "batl": NaN}, {"timestamp": 1631543573630, "ltp": 1.2, "tv": 384.44, "trd": NaN, "batb": [[1, 1.01, 7], [2, 1.01, 0]], "batl": NaN}, {"timestamp": 1631543577116, "ltp": 1.2, "tv": 384.44, "trd": NaN, "batb": [[0, 1.12, 249.99]], "batl": NaN}, {"timestamp": 1631543579252, "ltp": 1.2, "tv": 384.44, "trd": NaN, "batb": [[1, 1.08, 811.87], [2, 1.01, 7]], "batl": NaN}, {"timestamp": 1631543583631, "ltp": 1.2, "tv": 384.44, "trd": NaN, "batb": [[1, 1.1, 150], [2, 1.08, 811.87]], "batl": NaN}, {"timestamp": 1631543583742, "ltp": 1.2, "tv": 384.44, "trd": NaN, "batb": [[1, 1.1, 200]], "batl": NaN}, {"timestamp": 1631543595174, "ltp": 1.2, "tv": 384.44, "trd": NaN, "batb": [[0, 1.1, 200], [1, 1.08, 811.87], [2, 1.01, 7]], "batl": NaN}, {"timestamp": 1631543596861, "ltp": 1.2, "tv": 384.44, "trd": NaN, "batb": [[1, 1.01, 7], [2, 1.01, 0]], "batl": [[1, 1.48, 0]]}, {"timestamp": 1631543600138, "ltp": 1.2, "tv": 384.44, "trd": NaN, "batb": [[1, 1.08, 374.99], [2, 1.01, 7]], "batl": NaN}, {"timestamp": 1631543600768, "ltp": 1.2, "tv": 384.44, "trd": NaN, "batb": [[0, 1.08, 374.99], [1, 1.01, 7], [2, 1.01, 0]], "batl": NaN}, {"timestamp": 1631543602666, "ltp": 1.2, "tv": 384.44, "trd": NaN, "batb": [[1, 1.06, 949.57], [2, 1.01, 7]], "batl": [[0, 1.4, 953.33]]}, {"timestamp": 1631543603985, "ltp": 1.2, "tv": 384.44, "trd": NaN, "batb": [[1, 1.01, 7], [2, 1.01, 0]], "batl": NaN}, {"timestamp": 1631543608476, "ltp": 1.2, "tv": 384.44, "trd": NaN, "batb": [[1, 1.07, 100], [2, 1.01, 7]], "batl": NaN}, {"timestamp": 1631543609580, "ltp": 1.2, "tv": 384.44, "trd": NaN, "batb": [[1, 1.07, 250], [2, 1.05, 1084.16]], "batl": NaN}, {"timestamp": 1631543609685, "ltp": 1.2, "tv": 384.44, "trd": NaN, "batb": [[1, 1.07, 300]], "batl": NaN}, {"timestamp": 1631543611163, "ltp": 1.2, "tv": 384.44, "trd": NaN, "batb": NaN, "batl": [[0, 1.25, 41.72], [1, 1.4, 953.33]]}, {"timestamp": 1631543613949, "ltp": 1.2, "tv": 384.44, "trd": NaN, "batb": [[2, 1.01, 7]], "batl": NaN}, {"timestamp": 1631543619693, "ltp": 1.2, "tv": 384.44, "trd": NaN, "batb": [[2, 1.06, 949.57]], "batl": NaN}, {"timestamp": 1631543633303, "ltp": 1.2, "tv": 384.44, "trd": NaN, "batb": [[0, 1.07, 300], [1, 1.01, 7], [2, 1.06, 0]], "batl": NaN}, {"timestamp": 1631543634769, "ltp": 1.2, "tv": 384.44, "trd": NaN, "batb": [[0, 1.01, 7], [1, 1.01, 0]], "batl": NaN}, {"timestamp": 1631543638177, "ltp": 1.2, "tv": 384.44, "trd": NaN, "batb": [[0, 1.05, 599.99], [1, 1.01, 7]], "batl": NaN}, {"timestamp": 1631543638911, "ltp": 1.2, "tv": 384.44, "trd": NaN, "batb": [[1, 1.04, 1251.37], [2, 1.01, 7]], "batl": NaN}, {"timestamp": 1631543640575, "ltp": 1.2, "tv": 384.44, "trd": NaN, "batb": [[0, 1.05, 649.99]], "batl": NaN}, {"timestamp": 1631543641470, "ltp": 1.2, "tv": 384.44, "trd": NaN, "batb": [[0, 1.05, 799.99]], "batl": NaN}, {"timestamp": 1631543641681, "ltp": 1.2, "tv": 384.44, "trd": NaN, "batb": [[0, 1.05, 849.99]], "batl": NaN}, {"timestamp": 1631543694203, "ltp": 1.2, "tv": 384.44, "trd": NaN, "batb": [[0, 1.05, 250]], "batl": NaN}, {"timestamp": 1631543695802, "ltp": 1.2, "tv": 384.44, "trd": NaN, "batb": [[1, 1.01, 7], [2, 1.01, 0]], "batl": NaN}, {"timestamp": 1631543699084, "ltp": 1.2, "tv": 384.44, "trd": NaN, "batb": [[0, 1.08, 374.99], [1, 1.05, 250], [2, 1.01, 7]], "batl": NaN}, {"timestamp": 1631543700610, "ltp": 1.08, "tv": 444.44, "trd": [[1.08, 60]], "batb": [[0, 1.08, 344.99]], "batl": NaN}, {"timestamp": 1631543701403, "ltp": 1.08, "tv": 444.44, "trd": NaN, "batb": [[0, 1.05, 250], [1, 1.04, 1298.58]], "batl": NaN}, {"timestamp": 1631543703992, "ltp": 1.08, "tv": 444.44, "trd": NaN, "batb": [[1, 1.01, 7], [2, 1.01, 0]], "batl": NaN}, {"timestamp": 1631543705789, "ltp": 1.08, "tv": 444.44, "trd": NaN, "batb": [[0, 1.08, 374.99], [1, 1.05, 250], [2, 1.01, 7]], "batl": NaN}, {"timestamp": 1631543710199, "ltp": 1.08, "tv": 444.44, "trd": NaN, "batb": [[1, 1.06, 949.57], [2, 1.05, 250]], "batl": NaN}, {"timestamp": 1631543711503, "ltp": 1.08, "tv": 444.44, "trd": NaN, "batb": [[1, 1.07, 200], [2, 1.06, 949.57]], "batl": NaN}, {"timestamp": 1631543711915, "ltp": 1.08, "tv": 444.44, "trd": NaN, "batb": [[1, 1.07, 300]], "batl": NaN}, {"timestamp": 1631543722545, "ltp": 1.08, "tv": 444.44, "trd": NaN, "batb": [[0, 1.07, 300], [1, 1.06, 949.57], [2, 1.05, 250]], "batl": NaN}, {"timestamp": 1631543723130, "ltp": 1.08, "tv": 444.44, "trd": NaN, "batb": [[1, 1.05, 250], [2, 1.01, 7]], "batl": NaN}, {"timestamp": 1631543725213, "ltp": 1.08, "tv": 444.44, "trd": NaN, "batb": [[0, 1.01, 7], [1, 1.05, 0], [2, 1.01, 0]], "batl": [[0, 1.4, 953.33], [1, 1.4, 0]]}, {"timestamp": 1631543727408, "ltp": 1.08, "tv": 444.44, "trd": NaN, "batb": [[0, 1.05, 599.99], [1, 1.01, 7]], "batl": NaN}, {"timestamp": 1631543729442, "ltp": 1.08, "tv": 444.44, "trd": NaN, "batb": [[1, 1.03, 1556.77], [2, 1.01, 7]], "batl": NaN}, {"timestamp": 1631543732431, "ltp": 1.08, "tv": 444.44, "trd": NaN, "batb": [[1, 1.04, 50], [2, 1.03, 1556.77]], "batl": NaN}, {"timestamp": 1631543733008, "ltp": 1.08, "tv": 444.44, "trd": NaN, "batb": [[1, 1.04, 200]], "batl": NaN}, {"timestamp": 1631543734529, "ltp": 1.08, "tv": 444.44, "trd": NaN, "batb": [[2, 1.03, 1656.77]], "batl": NaN}, {"timestamp": 1631543735423, "ltp": 1.08, "tv": 444.44, "trd": NaN, "batb": [[2, 1.03, 1706.77]], "batl": NaN}, {"timestamp": 1631543737357, "ltp": 1.08, "tv": 444.44, "trd": NaN, "batb": NaN, "batl": [[0, 1.15, 41.72], [1, 1.4, 953.33]]}, {"timestamp": 1631543746833, "ltp": 1.08, "tv": 444.44, "trd": NaN, "batb": [[0, 1.09, 11.11], [1, 1.05, 599.99], [2, 1.04, 200]], "batl": NaN}, {"timestamp": 1631543757569, "ltp": 1.08, "tv": 444.44, "trd": NaN, "batb": [[1, 1.04, 200], [2, 1.03, 1706.77]], "batl": NaN}, {"timestamp": 1631543762471, "ltp": 1.08, "tv": 444.44, "trd": NaN, "batb": [[1, 1.04, 949.99]], "batl": NaN}, {"timestamp": 1631543764158, "ltp": 1.08, "tv": 444.44, "trd": NaN, "batb": [[0, 1.04, 949.99], [1, 1.03, 1706.77], [2, 1.02, 100]], "batl": NaN}, {"timestamp": 1631543767475, "ltp": 1.08, "tv": 444.44, "trd": NaN, "batb": [[1, 1.03, 150]], "batl": [[1, 1.4, 0]]}, {"timestamp": 1631543770585, "ltp": 1.08, "tv": 444.44, "trd": NaN, "batb": [[0, 1.04, 749.99]], "batl": NaN}, {"timestamp": 1631543774160, "ltp": 1.08, "tv": 444.44, "trd": NaN, "batb": [[2, 1.02, 2277.23]], "batl": [[0, 1.33, 1136.66]]}, {"timestamp": 1631543777783, "ltp": 1.08, "tv": 444.44, "trd": NaN, "batb": NaN, "batl": [[0, 1.13, 41.72], [1, 1.33, 1136.66]]}, {"timestamp": 1631543792304, "ltp": 1.08, "tv": 444.44, "trd": NaN, "batb": [[0, 1.03, 150], [1, 1.02, 2277.23], [2, 1.01, 307]], "batl": NaN}, {"timestamp": 1631543793724, "ltp": 1.08, "tv": 444.44, "trd": NaN, "batb": [[1, 1.02, 100]], "batl": NaN}, {"timestamp": 1631543797299, "ltp": 1.08, "tv": 444.44, "trd": NaN, "batb": [[0, 1.05, 599.99], [1, 1.03, 150], [2, 1.02, 100]], "batl": NaN}, {"timestamp": 1631543799830, "ltp": 1.08, "tv": 444.44, "trd": NaN, "batb": [[1, 1.03, 1706.77]], "batl": NaN}, {"timestamp": 1631543813853, "ltp": 1.08, "tv": 444.44, "trd": NaN, "batb": [[0, 1.03, 1706.77], [1, 1.02, 100], [2, 1.01, 307]], "batl": NaN}, {"timestamp": 1631543814843, "ltp": 1.08, "tv": 444.44, "trd": NaN, "batb": [[0, 1.03, 150]], "batl": NaN}, {"timestamp": 1631543818730, "ltp": 1.08, "tv": 444.44, "trd": NaN, "batb": [[0, 1.04, 749.99], [1, 1.03, 150], [2, 1.02, 100]], "batl": NaN}, {"timestamp": 1631543820251, "ltp": 1.08, "tv": 444.44, "trd": NaN, "batb": [[2, 1.02, 2277.23]], "batl": NaN}, {"timestamp": 1631543842157, "ltp": 1.08, "tv": 444.44, "trd": NaN, "batb": [[2, 1.02, 100]], "batl": NaN}, {"timestamp": 1631543848472, "ltp": 1.08, "tv": 444.44, "trd": NaN, "batb": [[1, 1.03, 1706.77]], "batl": NaN}, {"timestamp": 1631543864321, "ltp": 1.08, "tv": 444.44, "trd": NaN, "batb": [[1, 1.03, 150]], "batl": NaN}, {"timestamp": 1631543867204, "ltp": 1.08, "tv": 444.44, "trd": NaN, "batb": [[0, 1.03, 150], [1, 1.02, 100], [2, 1.01, 307]], "batl": NaN}, {"timestamp": 1631543872223, "ltp": 1.08, "tv": 444.44, "trd": NaN, "batb": [[0, 1.05, 599.99], [1, 1.03, 150], [2, 1.02, 100]], "batl": NaN}, {"timestamp": 1631543889085, "ltp": 1.08, "tv": 444.44, "trd": NaN, "batb": [[0, 1.03, 150], [1, 1.02, 100], [2, 1.01, 307]], "batl": NaN}, {"timestamp": 1631543894055, "ltp": 1.08, "tv": 444.44, "trd": NaN, "batb": [[0, 1.06, 499.99], [1, 1.03, 150], [2, 1.02, 100]], "batl": NaN}, {"timestamp": 1631543895852, "ltp": 1.08, "tv": 444.44, "trd": NaN, "batb": [[1, 1.04, 1251.37], [2, 1.03, 150]], "batl": NaN}, {"timestamp": 1631543899001, "ltp": 1.08, "tv": 444.44, "trd": NaN, "batb": NaN, "batl": [[0, 1.33, 1136.66], [1, 1.33, 0]]}, {"timestamp": 1631543904174, "ltp": 1.08, "tv": 444.44, "trd": NaN, "batb": [[0, 1.04, 1251.37], [1, 1.03, 150], [2, 1.02, 100]], "batl": NaN}, {"timestamp": 1631543905489, "ltp": 1.08, "tv": 444.44, "trd": NaN, "batb": [[0, 1.03, 150], [1, 1.02, 100], [2, 1.01, 307]], "batl": [[0, 1.16, 41.72], [1, 1.33, 1136.66]]}, {"timestamp": 1631543909179, "ltp": 1.08, "tv": 444.44, "trd": NaN, "batb": [[0, 1.03, 1149.99]], "batl": NaN}, {"timestamp": 1631543910919, "ltp": 1.08, "tv": 444.44, "trd": NaN, "batb": [[1, 1.02, 2277.23]], "batl": NaN}, {"timestamp": 1631543927712, "ltp": 1.08, "tv": 444.44, "trd": NaN, "batb": [[0, 1.03, 150]], "batl": NaN}, {"timestamp": 1631543928913, "ltp": 1.08, "tv": 444.44, "trd": NaN, "batb": [[1, 1.02, 100]], "batl": NaN}, {"timestamp": 1631543934932, "ltp": 1.03, "tv": 450.44, "trd": [[1.03, 6]], "batb": [[0, 1.03, 147], [2, 1.01, 4273]], "batl": NaN}, {"timestamp": 1631543937129, "ltp": 1.03, "tv": 450.44, "trd": NaN, "batb": [[0, 1.02, 100], [1, 1.01, 4273], [2, 1.01, 0]], "batl": NaN}, {"timestamp": 1631543943543, "ltp": 1.03, "tv": 450.44, "trd": NaN, "batb": [[0, 1.02, 250]], "batl": NaN}, {"timestamp": 1631543996442, "ltp": 1.03, "tv": 450.44, "trd": NaN, "batb": NaN, "batl": [[0, 1.33, 1136.66], [1, 1.33, 0]]}, {"timestamp": 1631544032472, "ltp": 1.03, "tv": 450.44, "trd": NaN, "batb": [[0, 1.02, 550]], "batl": NaN}, {"timestamp": 1631544032681, "ltp": 1.03, "tv": 450.44, "trd": NaN, "batb": [[0, 1.02, 600]], "batl": NaN}, {"timestamp": 1631544037960, "ltp": 1.03, "tv": 450.44, "trd": NaN, "batb": [[1, 1.01, 307]], "batl": NaN}, {"timestamp": 1631544053397, "ltp": 1.03, "tv": 450.44, "trd": NaN, "batb": [[0, 1.02, 2099.99]], "batl": NaN}, {"timestamp": 1631544055011, "ltp": 1.03, "tv": 450.44, "trd": NaN, "batb": [[1, 1.01, 4460.07]], "batl": NaN}, {"timestamp": 1631544091665, "ltp": 1.03, "tv": 450.44, "trd": NaN, "batb": [[0, 1.02, 600]], "batl": NaN}, {"timestamp": 1631544092657, "ltp": 1.03, "tv": 450.44, "trd": NaN, "batb": [[1, 1.01, 307]], "batl": NaN}, {"timestamp": 1631544096682, "ltp": 1.03, "tv": 450.44, "trd": NaN, "batb": [[0, 1.04, 749.99], [1, 1.02, 600], [2, 1.01, 307]], "batl": NaN}, {"timestamp": 1631544098880, "ltp": 1.03, "tv": 450.44, "trd": NaN, "batb": [[1, 1.02, 2777.23]], "batl": NaN}, {"timestamp": 1631544116908, "ltp": 1.03, "tv": 450.44, "trd": NaN, "batb": [[0, 1.02, 2777.23], [1, 1.01, 307], [2, 1.01, 0]], "batl": NaN}, {"timestamp": 1631544118167, "ltp": 1.03, "tv": 450.44, "trd": NaN, "batb": [[0, 1.02, 600]], "batl": NaN}, {"timestamp": 1631544121881, "ltp": 1.03, "tv": 450.44, "trd": NaN, "batb": [[0, 1.03, 999.99], [1, 1.02, 600], [2, 1.01, 307]], "batl": NaN}, {"timestamp": 1631544124009, "ltp": 1.03, "tv": 450.44, "trd": NaN, "batb": [[2, 1.01, 4460.07]], "batl": NaN}, {"timestamp": 1631544154424, "ltp": 1.03, "tv": 450.44, "trd": NaN, "batb": [[0, 1.02, 600], [1, 1.01, 4460.07], [2, 1.01, 0]], "batl": NaN}, {"timestamp": 1631544155523, "ltp": 1.03, "tv": 450.44, "trd": NaN, "batb": [[1, 1.01, 307]], "batl": NaN}, {"timestamp": 1631544159305, "ltp": 1.03, "tv": 450.44, "trd": NaN, "batb": [[0, 1.04, 749.99], [1, 1.02, 600], [2, 1.01, 307]], "batl": NaN}, {"timestamp": 1631544161133, "ltp": 1.03, "tv": 450.44, "trd": NaN, "batb": [[1, 1.02, 2777.23]], "batl": NaN}, {"timestamp": 1631544189772, "ltp": 1.03, "tv": 450.44, "trd": NaN, "batb": [[0, 1.02, 2777.23], [1, 1.01, 307], [2, 1.01, 0]], "batl": NaN}, {"timestamp": 1631544194684, "ltp": 1.03, "tv": 450.44, "trd": NaN, "batb": [[0, 1.03, 999.99], [1, 1.02, 2777.23], [2, 1.01, 307]], "batl": NaN}, {"timestamp": 1631544253270, "ltp": 1.03, "tv": 450.44, "trd": NaN, "batb": [[0, 1.02, 2777.23], [1, 1.01, 307], [2, 1.01, 0]], "batl": NaN}, {"timestamp": 1631544253948, "ltp": 1.03, "tv": 450.44, "trd": NaN, "batb": [[0, 1.02, 600]], "batl": NaN}, {"timestamp": 1631544264357, "ltp": 1.03, "tv": 450.44, "trd": NaN, "batb": [[0, 1.02, 2777.23]], "batl": NaN}, {"timestamp": 1631544264985, "ltp": 1.03, "tv": 450.44, "trd": NaN, "batb": [[0, 1.02, 600]], "batl": NaN}, {"timestamp": 1631544270476, "ltp": 1.03, "tv": 450.44, "trd": NaN, "batb": [[0, 1.03, 999.99], [1, 1.02, 600], [2, 1.01, 307]], "batl": NaN}, {"timestamp": 1631544270790, "ltp": 1.03, "tv": 450.44, "trd": NaN, "batb": [[0, 1.02, 600], [1, 1.01, 307], [2, 1.01, 0]], "batl": NaN}, {"timestamp": 1631544276460, "ltp": 1.03, "tv": 450.44, "trd": NaN, "batb": [[1, 1.01, 4273]], "batl": [[0, 1.31, 1203.19]]}, {"timestamp": 1631544280300, "ltp": 1.03, "tv": 450.44, "trd": NaN, "batb": [[1, 1.01, 307]], "batl": NaN}, {"timestamp": 1631544300394, "ltp": 1.03, "tv": 450.44, "trd": NaN, "batb": NaN, "batl": [[0, 1.33, 1136.66]]}, {"timestamp": 1631544306716, "ltp": 1.03, "tv": 450.44, "trd": NaN, "batb": [[0, 1.02, 2777.23]], "batl": NaN}, {"timestamp": 1631544308494, "ltp": 1.03, "tv": 450.44, "trd": NaN, "batb": [[0, 1.02, 600]], "batl": NaN}, {"timestamp": 1631544314805, "ltp": 1.03, "tv": 450.44, "trd": NaN, "batb": [[1, 1.01, 4460.07]], "batl": NaN}, {"timestamp": 1631544325747, "ltp": 1.03, "tv": 450.44, "trd": NaN, "batb": [[1, 1.01, 307]], "batl": NaN}, {"timestamp": 1631544331823, "ltp": 1.03, "tv": 450.44, "trd": NaN, "batb": [[1, 1.01, 4273]], "batl": NaN}, {"timestamp": 1631544335861, "ltp": 1.03, "tv": 450.44, "trd": NaN, "batb": [[1, 1.01, 307]], "batl": NaN}, {"timestamp": 1631544379707, "ltp": 1.02, "tv": 464.44, "trd": [[1.02, 14]], "batb": [[0, 1.02, 593]], "batl": NaN}, {"timestamp": 1631544415146, "ltp": 1.02, "tv": 664.44, "trd": [[1.02, 214]], "batb": [[0, 1.02, 493]], "batl": NaN}, {"timestamp": 1631544422878, "ltp": 1.02, "tv": 664.44, "trd": NaN, "batb": [[0, 1.01, 307], [1, 1.01, 0]], "batl": NaN}, {"timestamp": 1631544429454, "ltp": 1.02, "tv": 664.44, "trd": NaN, "batb": [[0, 1.01, 407]], "batl": NaN}, {"timestamp": 1631544430361, "ltp": 1.02, "tv": 664.44, "trd": NaN, "batb": [[0, 1.01, 457]], "batl": NaN}, {"timestamp": 1631544431040, "ltp": 1.02, "tv": 664.44, "trd": NaN, "batb": [[0, 1.01, 557]], "batl": NaN}, {"timestamp": 1631544535197, "ltp": 1.02, "tv": 664.44, "trd": NaN, "batb": NaN, "batl": [[0, 1.29, 1287.28]]}, {"timestamp": 1631544647516, "ltp": 1.02, "tv": 664.44, "trd": NaN, "batb": [[0, 1.01, 7]], "batl": NaN}, {"timestamp": 1631544648455, "ltp": 1.02, "tv": 664.44, "trd": NaN, "batb": NaN, "batl": [[0, 1.28, 1366.24]]}, {"timestamp": 1631544666485, "ltp": 1.02, "tv": 664.44, "trd": NaN, "batb": NaN, "batl": [[0, 1.28, 1326.95]]}, {"timestamp": 1631544684471, "ltp": 1.02, "tv": 664.44, "trd": NaN, "batb": NaN, "batl": [[0, 1.3, 1265.64]]}, {"timestamp": 1631544719140, "ltp": 1.02, "tv": 664.44, "trd": NaN, "batb": [[0, 1.01, 3973]], "batl": [[0, 1.31, 1203.19]]}, {"timestamp": 1631544732433, "ltp": 1.02, "tv": 664.44, "trd": NaN, "batb": [[0, 1.02, 600], [1, 1.01, 3973]], "batl": NaN}, {"timestamp": 1631544732847, "ltp": 1.02, "tv": 664.44, "trd": NaN, "batb": [[0, 1.02, 1000]], "batl": NaN}, {"timestamp": 1631544739555, "ltp": 1.02, "tv": 664.44, "trd": NaN, "batb": NaN, "batl": [[0, 1.09, 140], [1, 1.31, 1203.19]]}, {"timestamp": 1631544742565, "ltp": 1.02, "tv": 664.44, "trd": NaN, "batb": NaN, "batl": [[0, 1.31, 1203.19], [1, 1.31, 0]]}, {"timestamp": 1631544743957, "ltp": 1.02, "tv": 664.44, "trd": NaN, "batb": [[1, 1.01, 7]], "batl": NaN}, {"timestamp": 1631544748632, "ltp": 1.02, "tv": 664.44, "trd": NaN, "batb": [[0, 1.01, 7], [1, 1.01, 0]], "batl": NaN}, {"timestamp": 1631544778704, "ltp": 1.02, "tv": 664.44, "trd": NaN, "batb": [[0, 1.01, 3973]], "batl": NaN}, {"timestamp": 1631544808765, "ltp": 1.02, "tv": 664.44, "trd": NaN, "batb": [[0, 1.01, 7]], "batl": NaN}, {"timestamp": 1631544885833, "ltp": 1.02, "tv": 664.44, "trd": NaN, "batb": NaN, "batl": [[0, 1.27, 1393.59]]}, {"timestamp": 1631544894729, "ltp": 1.01, "tv": 678.44, "trd": [[1.01, 14]], "batb": NaN, "batl": [[0, 1.01, 22.46], [1, 1.27, 1393.59]]}, {"timestamp": 1631544914974, "ltp": 1.01, "tv": 678.44, "trd": NaN, "batb": NaN, "batl": [[0, 1.01, 859.05]]}, {"timestamp": 1631544926463, "ltp": 1.01, "tv": 678.44, "trd": NaN, "batb": NaN, "batl": [[0, 1.01, 836.6]]}, {"timestamp": 1631544931407, "ltp": 1.01, "tv": 678.44, "trd": NaN, "batb": NaN, "batl": [[1, 1.27, 0]]}, {"timestamp": 1631544947090, "ltp": 1.01, "tv": 678.44, "trd": NaN, "batb": NaN, "batl": [[1, 1.27, 1412.67]]}, {"timestamp": 1631544956598, "ltp": 1.01, "tv": 678.44, "trd": NaN, "batb": NaN, "batl": [[1, 1.27, 0]]}, {"timestamp": 1631545191685, "ltp": 1.01, "tv": 678.44, "trd": NaN, "batb": NaN, "batl": [[1, 1.27, 1393.59]]}, {"timestamp": 1631545207317, "ltp": 1.01, "tv": 678.43, "trd": [[1.01, 14.02], [1.2, 15.89], [1.27, 2.77], [1.38, 23.76], [1.49, 54.51]], "batb": NaN, "batl": [[0, 1.01, 838.8], [1, 1.27, 0]]}, {"timestamp": 1631545226226, "ltp": 1.01, "tv": 678.43, "trd": NaN, "batb": NaN, "batl": [[1, 1.27, 1414.36]]}, {"timestamp": 1631545239482, "ltp": 1.01, "tv": 678.43, "trd": NaN, "batb": NaN, "batl": [[1, 1.27, 0]]}, {"timestamp": 1631545253171, "ltp": 1.01, "tv": 678.43, "trd": NaN, "batb": NaN, "batl": [[1, 1.27, 1395.25]]}, {"timestamp": 1631545269799, "ltp": 1.01, "tv": 678.43, "trd": NaN, "batb": NaN, "batl": [[1, 1.27, 0]]}, {"timestamp": 1631545281582, "ltp": 1.01, "tv": 678.43, "trd": NaN, "batb": NaN, "batl": [[1, 1.28, 1367.87]]}, {"timestamp": 1631545299260, "ltp": 1.01, "tv": 678.43, "trd": NaN, "batb": NaN, "batl": [[1, 1.28, 0]]}, {"timestamp": 1631545305854, "ltp": 1.01, "tv": 678.43, "trd": NaN, "batb": NaN, "batl": [[1, 1.28, 1354.01]]}, {"timestamp": 1631545310218, "ltp": 1.01, "tv": 678.43, "trd": NaN, "batb": NaN, "batl": [[1, 1.28, 0]]}, {"timestamp": 1631545318863, "ltp": 1.01, "tv": 678.43, "trd": NaN, "batb": NaN, "batl": [[1, 1.28, 1328.53]]}, {"timestamp": 1631545334269, "ltp": 1.01, "tv": 687.73, "trd": [[1.01, 23.31]], "batb": NaN, "batl": [[0, 1.01, 829.51]]}, {"timestamp": 1631545576060, "ltp": 1.01, "tv": 687.73, "trd": NaN, "batb": NaN, "batl": [[1, 1.28, 0]]}, {"timestamp": 1631545586044, "ltp": 1.01, "tv": 687.73, "trd": NaN, "batb": NaN, "batl": [[1, 1.27, 1395.25]]}, {"timestamp": 1631545606310, "ltp": 1.01, "tv": 687.73, "trd": NaN, "batb": NaN, "batl": [[1, 1.27, 0]]}, {"timestamp": 1631545623229, "ltp": 1.01, "tv": 687.73, "trd": NaN, "batb": NaN, "batl": [[1, 1.28, 1354.01]]}, {"timestamp": 1631545635666, "ltp": 1.01, "tv": 687.73, "trd": NaN, "batb": NaN, "batl": [[1, 1.28, 0]]}, {"timestamp": 1631545661583, "ltp": 1.01, "tv": 687.73, "trd": NaN, "batb": NaN, "batl": [[1, 1.29, 1288.82]]}, {"timestamp": 1631545710651, "ltp": 1.01, "tv": 697.01, "trd": [[1.01, 32.59]], "batb": NaN, "batl": [[0, 1.01, 824.87]]}, {"timestamp": 1631545724074, "ltp": 1.01, "tv": 2346.74, "trd": [[1.01, 1682.32]], "batb": NaN, "batl": [[0, 1.29, 1288.82], [1, 1.29, 0]]}, {"timestamp": 1631545739026, "ltp": 1.01, "tv": 2346.74, "trd": NaN, "batb": [[0, 1.03, 999.99]], "batl": NaN}, {"timestamp": 1631545740114, "ltp": 1.01, "tv": 2346.74, "trd": NaN, "batb": [[1, 1.02, 1252.25]], "batl": [[0, 1.33, 1756.38]]}, {"timestamp": 1631545751708, "ltp": 1.01, "tv": 2346.74, "trd": NaN, "batb": [[1, 1.02, 0]], "batl": NaN}, {"timestamp": 1631545756929, "ltp": 1.01, "tv": 2346.74, "trd": NaN, "batb": [[0, 1.03, 1711.13]], "batl": NaN}, {"timestamp": 1631545773637, "ltp": 1.01, "tv": 2346.74, "trd": NaN, "batb": [[0, 1.03, 711.14]], "batl": NaN}, {"timestamp": 1631545780240, "ltp": 1.01, "tv": 2346.74, "trd": NaN, "batb": [[0, 1.01, 2978.25]], "batl": NaN}, {"timestamp": 1631545814294, "ltp": 1.01, "tv": 2346.74, "trd": NaN, "batb": [[0, 1.03, 999.99]], "batl": NaN}, {"timestamp": 1631545815593, "ltp": 1.01, "tv": 2346.74, "trd": NaN, "batb": [[0, 1.03, 1711.13]], "batl": [[0, 1.35, 1700.38]]}, {"timestamp": 1631545829213, "ltp": 1.01, "tv": 2346.74, "trd": NaN, "batb": [[0, 1.03, 711.14]], "batl": NaN}, {"timestamp": 1631545834205, "ltp": 1.01, "tv": 2346.74, "trd": NaN, "batb": [[0, 1.04, 749.99], [1, 1.03, 711.14]], "batl": NaN}, {"timestamp": 1631545843743, "ltp": 1.01, "tv": 2346.74, "trd": NaN, "batb": [[0, 1.03, 711.14], [1, 1.03, 0]], "batl": NaN}, {"timestamp": 1631545848625, "ltp": 1.01, "tv": 2346.74, "trd": NaN, "batb": [[0, 1.06, 499.99]], "batl": NaN}, {"timestamp": 1631545850910, "ltp": 1.01, "tv": 2346.74, "trd": NaN, "batb": [[1, 1.05, 260.11]], "batl": NaN}, {"timestamp": 1631545873342, "ltp": 1.01, "tv": 2346.74, "trd": NaN, "batb": [[0, 1.08, 374.99]], "batl": NaN}, {"timestamp": 1631545874271, "ltp": 1.01, "tv": 2346.74, "trd": NaN, "batb": [[1, 1.06, 109.71]], "batl": NaN}, {"timestamp": 1631545939128, "ltp": 1.01, "tv": 2346.74, "trd": NaN, "batb": [[1, 1.06, 0]], "batl": NaN}, {"timestamp": 1631545944834, "ltp": 1.01, "tv": 2346.74, "trd": NaN, "batb": [[0, 1.08, 402.68]], "batl": NaN}, {"timestamp": 1631545992962, "ltp": 1.01, "tv": 2346.74, "trd": NaN, "batb": [[0, 1.08, 27.69]], "batl": NaN}, {"timestamp": 1631545997866, "ltp": 1.01, "tv": 2346.74, "trd": NaN, "batb": [[0, 1.05, 599.99]], "batl": NaN}, {"timestamp": 1631545999590, "ltp": 1.01, "tv": 2346.74, "trd": NaN, "batb": [[0, 1.05, 860.1]], "batl": NaN}, {"timestamp": 1631546021515, "ltp": 1.01, "tv": 2346.74, "trd": NaN, "batb": [[0, 1.05, 599.99]], "batl": NaN}, {"timestamp": 1631546034052, "ltp": 1.01, "tv": 2346.74, "trd": NaN, "batb": [[0, 1.02, 1252.25]], "batl": [[0, 1.33, 1756.38]]}, {"timestamp": 1631546060407, "ltp": 1.01, "tv": 2346.74, "trd": NaN, "batb": [[0, 1.04, 749.99]], "batl": NaN}, {"timestamp": 1631546062406, "ltp": 1.01, "tv": 2346.74, "trd": NaN, "batb": [[0, 1.04, 1188.27]], "batl": [[0, 1.36, 1645.42]]}, {"timestamp": 1631546068471, "ltp": 1.01, "tv": 2346.74, "trd": NaN, "batb": [[0, 1.04, 749.99]], "batl": NaN}, {"timestamp": 1631546087012, "ltp": 1.01, "tv": 2346.74, "trd": NaN, "batb": NaN, "batl": [[0, 1.3, 1877.33]]}]}, {"runnerId": 9628279, "odds": [{"timestamp": 1631539569425, "ltp": 1.45, "tv": 0.2, "trd": [[1.45, 0.2]], "batb": [[0, 1.45, 28.28], [2, 1.07, 611.78]], "batl": [[1, 1.94, 2.66], [2, 2.2, 43.7]]}, {"timestamp": 1631540362214, "ltp": 1.45, "tv": 16.17, "trd": [[1.45, 16.18]], "batb": [[0, 1.45, 20.29]], "batl": NaN}, {"timestamp": 1631540667752, "ltp": 1.45, "tv": 16.17, "trd": NaN, "batb": [[2, 1.06, 42.58]], "batl": NaN}, {"timestamp": 1631540672848, "ltp": 1.45, "tv": 16.17, "trd": NaN, "batb": [[2, 1.22, 194.02]], "batl": NaN}, {"timestamp": 1631540744079, "ltp": 1.45, "tv": 16.17, "trd": NaN, "batb": [[0, 1.01, 7], [1, 1.44, 0], [2, 1.22, 0]], "batl": [[1, 1.94, 0], [2, 2.2, 0]]}, {"timestamp": 1631540749269, "ltp": 1.45, "tv": 16.17, "trd": NaN, "batb": [[0, 1.42, 71.42], [1, 1.01, 7]], "batl": NaN}, {"timestamp": 1631540965493, "ltp": 1.42, "tv": 19.57, "trd": [[1.42, 3.4]], "batb": [[0, 1.01, 7], [1, 1.01, 0]], "batl": NaN}, {"timestamp": 1631540970408, "ltp": 1.42, "tv": 19.57, "trd": NaN, "batb": [[0, 1.42, 71.42], [1, 1.01, 7]], "batl": NaN}, {"timestamp": 1631541621501, "ltp": 1.42, "tv": 19.57, "trd": NaN, "batb": [[0, 1.01, 7], [1, 1.01, 0]], "batl": NaN}, {"timestamp": 1631541626400, "ltp": 1.42, "tv": 19.57, "trd": NaN, "batb": [[0, 1.48, 62.5], [1, 1.01, 7]], "batl": NaN}, {"timestamp": 1631541658634, "ltp": 1.42, "tv": 19.57, "trd": NaN, "batb": [[0, 1.01, 7], [1, 1.01, 0]], "batl": NaN}, {"timestamp": 1631541663660, "ltp": 1.42, "tv": 19.57, "trd": NaN, "batb": [[0, 1.55, 54.54], [1, 1.01, 7]], "batl": NaN}, {"timestamp": 1631541686911, "ltp": 1.42, "tv": 19.57, "trd": NaN, "batb": [[0, 1.01, 7], [1, 1.01, 0]], "batl": NaN}, {"timestamp": 1631541691813, "ltp": 1.42, "tv": 19.57, "trd": NaN, "batb": [[0, 1.48, 62.5], [1, 1.01, 7]], "batl": NaN}, {"timestamp": 1631541728558, "ltp": 1.42, "tv": 19.57, "trd": NaN, "batb": [[0, 1.01, 7], [1, 1.01, 0]], "batl": NaN}, {"timestamp": 1631541733594, "ltp": 1.42, "tv": 19.57, "trd": NaN, "batb": [[0, 1.55, 54.54], [1, 1.01, 7]], "batl": NaN}, {"timestamp": 1631541750024, "ltp": 1.42, "tv": 19.57, "trd": NaN, "batb": [[0, 1.01, 7], [1, 1.01, 0]], "batl": NaN}, {"timestamp": 1631541754911, "ltp": 1.42, "tv": 19.57, "trd": NaN, "batb": [[0, 1.51, 58.82], [1, 1.01, 7]], "batl": NaN}, {"timestamp": 1631541762255, "ltp": 1.42, "tv": 19.57, "trd": NaN, "batb": [[0, 1.01, 7], [1, 1.01, 0]], "batl": NaN}, {"timestamp": 1631541843974, "ltp": 1.42, "tv": 19.57, "trd": NaN, "batb": [[0, 1.55, 54.54], [1, 1.01, 7]], "batl": NaN}, {"timestamp": 1631541866527, "ltp": 1.42, "tv": 19.57, "trd": NaN, "batb": [[0, 1.01, 7], [1, 1.01, 0]], "batl": NaN}, {"timestamp": 1631541908706, "ltp": 1.61, "tv": 125.43, "trd": [[1.61, 105.86]], "batb": NaN, "batl": [[0, 1.61, 47.04]]}, {"timestamp": 1631541911474, "ltp": 1.61, "tv": 157.85, "trd": [[1.61, 138.27]], "batb": NaN, "batl": [[0, 1.61, 30.82]]}, {"timestamp": 1631541912617, "ltp": 1.61, "tv": 219.45, "trd": [[1.61, 199.88]], "batb": [[0, 1.61, 120.14], [1, 1.01, 7]], "batl": NaN}, {"timestamp": 1631541913611, "ltp": 1.61, "tv": 219.45, "trd": NaN, "batb": [[0, 1.61, 143.24]], "batl": NaN}, {"timestamp": 1631541914625, "ltp": 1.61, "tv": 219.45, "trd": NaN, "batb": [[0, 1.61, 33.5]], "batl": NaN}, {"timestamp": 1631541915000, "ltp": 1.61, "tv": 219.45, "trd": NaN, "batb": [[0, 1.61, 5.58]], "batl": NaN}, {"timestamp": 1631541916298, "ltp": 1.61, "tv": 219.45, "trd": NaN, "batb": [[0, 1.61, 52.49]], "batl": NaN}, {"timestamp": 1631541916927, "ltp": 1.61, "tv": 219.45, "trd": NaN, "batb": [[0, 1.73, 41.09], [1, 1.61, 98.56], [2, 1.01, 7]], "batl": NaN}, {"timestamp": 1631541917915, "ltp": 1.61, "tv": 219.45, "trd": NaN, "batb": [[1, 1.61, 5.58]], "batl": NaN}, {"timestamp": 1631541919642, "ltp": 1.61, "tv": 219.45, "trd": NaN, "batb": [[1, 1.01, 7], [2, 1.01, 0]], "batl": NaN}, {"timestamp": 1631541925633, "ltp": 1.61, "tv": 219.45, "trd": NaN, "batb": [[0, 1.01, 7], [1, 1.01, 0]], "batl": NaN}, {"timestamp": 1631541930562, "ltp": 1.61, "tv": 219.45, "trd": NaN, "batb": [[0, 1.78, 38.46], [1, 1.01, 7]], "batl": NaN}, {"timestamp": 1631541945870, "ltp": 1.61, "tv": 219.45, "trd": NaN, "batb": [[0, 1.01, 7], [1, 1.01, 0]], "batl": NaN}, {"timestamp": 1631541950773, "ltp": 1.61, "tv": 219.45, "trd": NaN, "batb": [[0, 1.65, 46.15], [1, 1.01, 7]], "batl": NaN}, {"timestamp": 1631541976631, "ltp": 1.61, "tv": 219.45, "trd": NaN, "batb": [[0, 1.01, 7], [1, 1.01, 0]], "batl": NaN}, {"timestamp": 1631541981525, "ltp": 1.61, "tv": 219.45, "trd": NaN, "batb": [[0, 1.78, 38.46], [1, 1.01, 7]], "batl": NaN}, {"timestamp": 1631542018992, "ltp": 1.61, "tv": 219.45, "trd": NaN, "batb": [[0, 1.01, 7], [1, 1.01, 0]], "batl": NaN}, {"timestamp": 1631542023992, "ltp": 1.61, "tv": 219.45, "trd": NaN, "batb": [[0, 1.85, 35.29], [1, 1.01, 7]], "batl": NaN}, {"timestamp": 1631542031290, "ltp": 1.61, "tv": 219.45, "trd": NaN, "batb": [[0, 1.01, 7], [1, 1.01, 0]], "batl": NaN}, {"timestamp": 1631542036333, "ltp": 1.61, "tv": 219.45, "trd": NaN, "batb": [[0, 1.65, 46.15], [1, 1.01, 7]], "batl": NaN}, {"timestamp": 1631542059767, "ltp": 1.61, "tv": 219.45, "trd": NaN, "batb": [[0, 1.01, 7], [1, 1.01, 0]], "batl": NaN}, {"timestamp": 1631542064556, "ltp": 1.61, "tv": 219.45, "trd": NaN, "batb": [[0, 1.85, 35.29], [1, 1.01, 7]], "batl": NaN}, {"timestamp": 1631542079077, "ltp": 1.61, "tv": 219.45, "trd": NaN, "batb": [[0, 1.01, 7], [1, 1.01, 0]], "batl": NaN}, {"timestamp": 1631542084013, "ltp": 1.61, "tv": 219.45, "trd": NaN, "batb": [[0, 2, 30], [1, 1.01, 7]], "batl": NaN}, {"timestamp": 1631542099404, "ltp": 1.61, "tv": 219.45, "trd": NaN, "batb": [[0, 1.01, 7], [1, 1.01, 0]], "batl": NaN}, {"timestamp": 1631542104319, "ltp": 1.61, "tv": 219.45, "trd": NaN, "batb": [[0, 1.88, 34.09], [1, 1.01, 7]], "batl": NaN}, {"timestamp": 1631542120178, "ltp": 1.61, "tv": 219.45, "trd": NaN, "batb": [[0, 1.01, 7], [1, 1.01, 0]], "batl": NaN}, {"timestamp": 1631542125049, "ltp": 1.61, "tv": 219.45, "trd": NaN, "batb": [[0, 2.06, 28.3], [1, 1.01, 7]], "batl": NaN}, {"timestamp": 1631542143495, "ltp": 1.61, "tv": 219.45, "trd": NaN, "batb": [[0, 1.01, 7], [1, 1.01, 0]], "batl": NaN}, {"timestamp": 1631542148510, "ltp": 1.61, "tv": 219.45, "trd": NaN, "batb": [[0, 2.16, 25.86], [1, 1.01, 7]], "batl": NaN}, {"timestamp": 1631542185874, "ltp": 1.61, "tv": 219.45, "trd": NaN, "batb": [[0, 1.01, 7], [1, 1.01, 0]], "batl": NaN}, {"timestamp": 1631542191128, "ltp": 2.16, "tv": 221.18, "trd": [[2.16, 1.73]], "batb": NaN, "batl": NaN}, {"timestamp": 1631542196053, "ltp": 2.16, "tv": 221.18, "trd": NaN, "batb": [[0, 2.34, 22.38], [1, 1.01, 7]], "batl": NaN}, {"timestamp": 1631542235626, "ltp": 2.16, "tv": 221.18, "trd": NaN, "batb": [[0, 1.01, 7], [1, 1.01, 0]], "batl": NaN}, {"timestamp": 1631542240544, "ltp": 2.16, "tv": 221.18, "trd": NaN, "batb": [[0, 2.42, 21.12], [1, 1.01, 7]], "batl": NaN}, {"timestamp": 1631542333380, "ltp": 2.42, "tv": 228.1, "trd": [[2.42, 6.92]], "batb": [[0, 2.42, 17.66]], "batl": NaN}, {"timestamp": 1631542333792, "ltp": 2.42, "tv": 228.1, "trd": NaN, "batb": [[0, 1.01, 7], [1, 1.01, 0]], "batl": NaN}, {"timestamp": 1631542338685, "ltp": 2.42, "tv": 228.1, "trd": NaN, "batb": [[0, 2.42, 21.12], [1, 1.01, 7]], "batl": NaN}, {"timestamp": 1631542344435, "ltp": 2.42, "tv": 228.1, "trd": NaN, "batb": [[0, 1.01, 7], [1, 1.01, 0]], "batl": NaN}, {"timestamp": 1631542349326, "ltp": 2.42, "tv": 228.1, "trd": NaN, "batb": [[0, 2.5, 20], [1, 1.01, 7]], "batl": NaN}, {"timestamp": 1631542368251, "ltp": 2.42, "tv": 228.1, "trd": NaN, "batb": [[0, 1.01, 7], [1, 1.01, 0]], "batl": NaN}, {"timestamp": 1631542373137, "ltp": 2.42, "tv": 228.1, "trd": NaN, "batb": [[0, 2.42, 21.12], [1, 1.01, 7]], "batl": NaN}, {"timestamp": 1631542387473, "ltp": 2.42, "tv": 228.1, "trd": NaN, "batb": [[0, 1.01, 7], [1, 1.01, 0]], "batl": NaN}, {"timestamp": 1631542392398, "ltp": 2.42, "tv": 228.1, "trd": NaN, "batb": [[0, 2.58, 18.98], [1, 1.01, 7]], "batl": NaN}, {"timestamp": 1631542429128, "ltp": 2.42, "tv": 228.1, "trd": NaN, "batb": [[0, 1.01, 7], [1, 1.01, 0]], "batl": NaN}, {"timestamp": 1631542434246, "ltp": 2.42, "tv": 228.1, "trd": NaN, "batb": [[0, 2.66, 18.07], [1, 1.01, 7]], "batl": NaN}, {"timestamp": 1631542471348, "ltp": 2.42, "tv": 228.1, "trd": NaN, "batb": [[0, 1.01, 7], [1, 1.01, 0]], "batl": NaN}, {"timestamp": 1631542476373, "ltp": 2.42, "tv": 228.1, "trd": NaN, "batb": [[0, 2.58, 18.98], [1, 1.01, 7]], "batl": NaN}, {"timestamp": 1631542506481, "ltp": 2.42, "tv": 228.1, "trd": NaN, "batb": [[0, 1.01, 7], [1, 1.01, 0]], "batl": NaN}, {"timestamp": 1631542511389, "ltp": 2.42, "tv": 228.1, "trd": NaN, "batb": [[0, 2.42, 21.12], [1, 1.01, 7]], "batl": NaN}, {"timestamp": 1631542529406, "ltp": 2.42, "tv": 228.1, "trd": NaN, "batb": [[0, 1.01, 7], [1, 1.01, 0]], "batl": NaN}, {"timestamp": 1631542534307, "ltp": 2.42, "tv": 228.1, "trd": NaN, "batb": [[0, 2.5, 20], [1, 1.01, 7]], "batl": NaN}, {"timestamp": 1631542547337, "ltp": 2.42, "tv": 228.1, "trd": NaN, "batb": [[0, 1.01, 7], [1, 1.01, 0]], "batl": NaN}, {"timestamp": 1631542552131, "ltp": 2.42, "tv": 228.1, "trd": NaN, "batb": [[0, 2.58, 18.98], [1, 1.01, 7]], "batl": NaN}, {"timestamp": 1631542583277, "ltp": 2.42, "tv": 228.1, "trd": NaN, "batb": [[0, 1.01, 7], [1, 1.01, 0]], "batl": NaN}, {"timestamp": 1631542588206, "ltp": 2.42, "tv": 228.1, "trd": NaN, "batb": [[0, 2.84, 16.3], [1, 1.01, 7]], "batl": NaN}, {"timestamp": 1631542594583, "ltp": 3.05, "tv": 231.9, "trd": [[3.05, 3.8]], "batb": NaN, "batl": NaN}, {"timestamp": 1631542640323, "ltp": 3.05, "tv": 231.9, "trd": NaN, "batb": [[0, 1.01, 7], [1, 1.01, 0]], "batl": NaN}, {"timestamp": 1631542645218, "ltp": 3.05, "tv": 231.9, "trd": NaN, "batb": [[0, 3, 15], [1, 1.01, 7]], "batl": NaN}, {"timestamp": 1631542673759, "ltp": 3.05, "tv": 231.9, "trd": NaN, "batb": [[0, 1.01, 7], [1, 1.01, 0]], "batl": NaN}, {"timestamp": 1631542678745, "ltp": 3.05, "tv": 231.9, "trd": NaN, "batb": [[0, 2.84, 16.3], [1, 1.01, 7]], "batl": NaN}, {"timestamp": 1631542807979, "ltp": 3.05, "tv": 231.9, "trd": NaN, "batb": [[0, 1.01, 7], [1, 1.01, 0]], "batl": NaN}, {"timestamp": 1631542812857, "ltp": 3.05, "tv": 231.9, "trd": NaN, "batb": [[0, 3, 15], [1, 1.01, 7]], "batl": NaN}, {"timestamp": 1631542919135, "ltp": 3.05, "tv": 231.9, "trd": NaN, "batb": [[0, 1.01, 7], [1, 1.01, 0]], "batl": NaN}, {"timestamp": 1631542924068, "ltp": 3.05, "tv": 231.9, "trd": NaN, "batb": [[0, 3.15, 13.95], [1, 1.01, 7]], "batl": NaN}, {"timestamp": 1631542946493, "ltp": 3.05, "tv": 231.9, "trd": NaN, "batb": [[0, 1.01, 7], [1, 1.01, 0]], "batl": NaN}, {"timestamp": 1631542951387, "ltp": 3.05, "tv": 231.9, "trd": NaN, "batb": [[0, 3, 15], [1, 1.01, 7]], "batl": NaN}, {"timestamp": 1631542980628, "ltp": 3.95, "tv": 240.56, "trd": [[3.95, 8.66]], "batb": NaN, "batl": NaN}, {"timestamp": 1631542981630, "ltp": 3.95, "tv": 257.89, "trd": [[3.95, 25.98]], "batb": [[0, 3.95, 73.61], [1, 3, 15], [2, 1.01, 7]], "batl": NaN}, {"timestamp": 1631542982469, "ltp": 3.95, "tv": 257.89, "trd": NaN, "batb": [[0, 3.95, 98.21]], "batl": NaN}, {"timestamp": 1631542983568, "ltp": 3.95, "tv": 257.89, "trd": NaN, "batb": [[0, 3.95, 40.48]], "batl": NaN}, {"timestamp": 1631542984463, "ltp": 3.95, "tv": 257.89, "trd": NaN, "batb": [[0, 3.95, 69.68]], "batl": NaN}, {"timestamp": 1631542986559, "ltp": 3.95, "tv": 257.89, "trd": NaN, "batb": [[0, 3.95, 30.51]], "batl": NaN}, {"timestamp": 1631542987077, "ltp": 3.95, "tv": 257.89, "trd": NaN, "batb": [[0, 3.95, 20.34]], "batl": NaN}, {"timestamp": 1631542988171, "ltp": 3.95, "tv": 257.89, "trd": NaN, "batb": [[0, 3, 15], [1, 1.01, 7], [2, 1.01, 0]], "batl": NaN}, {"timestamp": 1631543180781, "ltp": 3.95, "tv": 257.89, "trd": NaN, "batb": [[0, 1.01, 7], [1, 1.01, 0]], "batl": NaN}, {"timestamp": 1631543185672, "ltp": 3.95, "tv": 257.89, "trd": NaN, "batb": [[0, 3.15, 13.95], [1, 1.01, 7]], "batl": NaN}, {"timestamp": 1631543235068, "ltp": 3.95, "tv": 257.89, "trd": NaN, "batb": [[0, 1.01, 7], [1, 1.01, 0]], "batl": NaN}, {"timestamp": 1631543239972, "ltp": 3.95, "tv": 257.89, "trd": NaN, "batb": [[0, 3.3, 13.04], [1, 1.01, 7]], "batl": NaN}, {"timestamp": 1631543243986, "ltp": 3.95, "tv": 257.89, "trd": NaN, "batb": [[0, 1.01, 7], [1, 1.01, 0]], "batl": NaN}, {"timestamp": 1631543248904, "ltp": 3.95, "tv": 257.89, "trd": NaN, "batb": [[0, 3.4, 12.5], [1, 1.01, 7]], "batl": NaN}, {"timestamp": 1631543270433, "ltp": 3.5, "tv": 268.11, "trd": [[3.5, 10.22]], "batb": NaN, "batl": NaN}, {"timestamp": 1631543333412, "ltp": 3.5, "tv": 268.11, "trd": NaN, "batb": [[0, 1.01, 7], [1, 1.01, 0]], "batl": NaN}, {"timestamp": 1631543338435, "ltp": 3.5, "tv": 268.11, "trd": NaN, "batb": [[0, 3.95, 10.16], [1, 1.01, 7]], "batl": NaN}, {"timestamp": 1631543367869, "ltp": 3.5, "tv": 268.11, "trd": NaN, "batb": [[0, 1.01, 7], [1, 1.01, 0]], "batl": NaN}, {"timestamp": 1631543373059, "ltp": 3.5, "tv": 268.11, "trd": NaN, "batb": [[0, 3.4, 12.5], [1, 1.01, 7]], "batl": NaN}, {"timestamp": 1631543398602, "ltp": 3.5, "tv": 268.11, "trd": NaN, "batb": [[0, 1.01, 7], [1, 1.01, 0]], "batl": NaN}, {"timestamp": 1631543403507, "ltp": 3.5, "tv": 268.11, "trd": NaN, "batb": [[0, 3.95, 10.16], [1, 1.01, 7]], "batl": NaN}, {"timestamp": 1631543429305, "ltp": 3.5, "tv": 268.11, "trd": NaN, "batb": [[0, 1.01, 7], [1, 1.01, 0]], "batl": NaN}, {"timestamp": 1631543434211, "ltp": 3.5, "tv": 268.11, "trd": NaN, "batb": [[0, 4.3, 10], [1, 1.01, 7]], "batl": NaN}, {"timestamp": 1631543461770, "ltp": 3.5, "tv": 268.11, "trd": NaN, "batb": [[0, 1.01, 7], [1, 1.01, 0]], "batl": NaN}, {"timestamp": 1631543467168, "ltp": 3.5, "tv": 268.11, "trd": NaN, "batb": [[0, 3.95, 10.16], [1, 1.01, 7]], "batl": NaN}, {"timestamp": 1631543492898, "ltp": 3.5, "tv": 268.11, "trd": NaN, "batb": [[0, 1.01, 7], [1, 1.01, 0]], "batl": NaN}, {"timestamp": 1631543497824, "ltp": 3.5, "tv": 268.11, "trd": NaN, "batb": [[0, 4.3, 10], [1, 1.01, 7]], "batl": NaN}, {"timestamp": 1631543572126, "ltp": 3.5, "tv": 268.11, "trd": NaN, "batb": [[0, 1.01, 7], [1, 1.01, 0]], "batl": NaN}, {"timestamp": 1631543577116, "ltp": 3.5, "tv": 268.11, "trd": NaN, "batb": [[0, 5.3, 10], [1, 1.01, 7]], "batl": NaN}, {"timestamp": 1631543595174, "ltp": 3.5, "tv": 268.11, "trd": NaN, "batb": [[0, 1.01, 7], [1, 1.01, 0]], "batl": NaN}, {"timestamp": 1631543600138, "ltp": 3.5, "tv": 268.11, "trd": NaN, "batb": [[0, 6, 10], [1, 1.01, 7]], "batl": NaN}, {"timestamp": 1631543633303, "ltp": 3.5, "tv": 268.11, "trd": NaN, "batb": [[0, 1.01, 7], [1, 1.01, 0]], "batl": NaN}, {"timestamp": 1631543638177, "ltp": 3.5, "tv": 268.11, "trd": NaN, "batb": [[0, 7.6, 10], [1, 1.01, 7]], "batl": NaN}, {"timestamp": 1631543694203, "ltp": 3.5, "tv": 268.11, "trd": NaN, "batb": [[0, 1.01, 7], [1, 1.01, 0]], "batl": NaN}, {"timestamp": 1631543699084, "ltp": 3.5, "tv": 268.11, "trd": NaN, "batb": [[0, 6, 10], [1, 1.01, 7]], "batl": NaN}, {"timestamp": 1631543722545, "ltp": 3.5, "tv": 268.11, "trd": NaN, "batb": [[0, 1.01, 7], [1, 1.01, 0]], "batl": NaN}, {"timestamp": 1631543727408, "ltp": 3.5, "tv": 268.11, "trd": NaN, "batb": [[0, 7.6, 10], [1, 1.01, 7]], "batl": NaN}, {"timestamp": 1631543757569, "ltp": 3.5, "tv": 268.11, "trd": NaN, "batb": [[0, 1.01, 7], [1, 1.01, 0]], "batl": NaN}, {"timestamp": 1631543762471, "ltp": 3.5, "tv": 268.11, "trd": NaN, "batb": [[0, 8.6, 10], [1, 1.01, 7]], "batl": NaN}, {"timestamp": 1631543792304, "ltp": 3.5, "tv": 268.11, "trd": NaN, "batb": [[0, 1.01, 7], [1, 1.01, 0]], "batl": NaN}, {"timestamp": 1631543797299, "ltp": 3.5, "tv": 268.11, "trd": NaN, "batb": [[0, 7.6, 10], [1, 1.01, 7]], "batl": NaN}, {"timestamp": 1631543813853, "ltp": 3.5, "tv": 268.11, "trd": NaN, "batb": [[0, 1.01, 7], [1, 1.01, 0]], "batl": NaN}, {"timestamp": 1631543818730, "ltp": 3.5, "tv": 268.11, "trd": NaN, "batb": [[0, 8.6, 10], [1, 1.01, 7]], "batl": NaN}, {"timestamp": 1631543867204, "ltp": 3.5, "tv": 268.11, "trd": NaN, "batb": [[0, 1.01, 7], [1, 1.01, 0]], "batl": NaN}, {"timestamp": 1631543872223, "ltp": 3.5, "tv": 268.11, "trd": NaN, "batb": [[0, 7.6, 10], [1, 1.01, 7]], "batl": NaN}, {"timestamp": 1631543889085, "ltp": 3.5, "tv": 268.11, "trd": NaN, "batb": [[0, 1.01, 7], [1, 1.01, 0]], "batl": NaN}, {"timestamp": 1631543894055, "ltp": 3.5, "tv": 268.11, "trd": NaN, "batb": [[0, 7, 10], [1, 1.01, 7]], "batl": NaN}, {"timestamp": 1631543904174, "ltp": 3.5, "tv": 268.11, "trd": NaN, "batb": [[0, 1.01, 7], [1, 1.01, 0]], "batl": NaN}, {"timestamp": 1631543909179, "ltp": 3.5, "tv": 268.11, "trd": NaN, "batb": [[0, 8.6, 10], [1, 1.01, 7]], "batl": NaN}, {"timestamp": 1631543927712, "ltp": 3.5, "tv": 268.11, "trd": NaN, "batb": [[0, 1.01, 7], [1, 1.01, 0]], "batl": NaN}, {"timestamp": 1631543932633, "ltp": 3.5, "tv": 268.11, "trd": NaN, "batb": [[0, 11, 10], [1, 1.01, 7]], "batl": NaN}, {"timestamp": 1631544044305, "ltp": 3.5, "tv": 268.11, "trd": NaN, "batb": NaN, "batl": [[0, 170, 37.48]]}, {"timestamp": 1631544048480, "ltp": 3.5, "tv": 268.11, "trd": NaN, "batb": [[0, 1.01, 7], [1, 1.01, 0]], "batl": NaN}, {"timestamp": 1631544053397, "ltp": 3.5, "tv": 268.11, "trd": NaN, "batb": [[0, 10, 10], [1, 1.01, 7]], "batl": NaN}, {"timestamp": 1631544091665, "ltp": 3.5, "tv": 268.11, "trd": NaN, "batb": [[0, 1.01, 7], [1, 1.01, 0]], "batl": NaN}, {"timestamp": 1631544096682, "ltp": 3.5, "tv": 268.11, "trd": NaN, "batb": [[0, 8.6, 10], [1, 1.01, 7]], "batl": NaN}, {"timestamp": 1631544116908, "ltp": 3.5, "tv": 268.11, "trd": NaN, "batb": [[0, 1.01, 7], [1, 1.01, 0]], "batl": NaN}, {"timestamp": 1631544121881, "ltp": 3.5, "tv": 268.11, "trd": NaN, "batb": [[0, 9.6, 10], [1, 1.01, 7]], "batl": NaN}, {"timestamp": 1631544154424, "ltp": 3.5, "tv": 268.11, "trd": NaN, "batb": [[0, 1.01, 7], [1, 1.01, 0]], "batl": NaN}, {"timestamp": 1631544159305, "ltp": 3.5, "tv": 268.11, "trd": NaN, "batb": [[0, 8, 10], [1, 1.01, 7]], "batl": NaN}, {"timestamp": 1631544189772, "ltp": 3.5, "tv": 268.11, "trd": NaN, "batb": [[0, 1.01, 7], [1, 1.01, 0]], "batl": NaN}, {"timestamp": 1631544194684, "ltp": 3.5, "tv": 268.11, "trd": NaN, "batb": [[0, 9.6, 10], [1, 1.01, 7]], "batl": NaN}, {"timestamp": 1631544253270, "ltp": 3.5, "tv": 268.11, "trd": NaN, "batb": [[0, 1.01, 7], [1, 1.01, 0]], "batl": NaN}, {"timestamp": 1631544268348, "ltp": 3.5, "tv": 268.11, "trd": NaN, "batb": [[0, 12, 10], [1, 1.01, 7]], "batl": NaN}, {"timestamp": 1631544268654, "ltp": 3.5, "tv": 268.11, "trd": NaN, "batb": [[0, 1.01, 7], [1, 1.01, 0]], "batl": NaN}, {"timestamp": 1631544273555, "ltp": 3.5, "tv": 268.11, "trd": NaN, "batb": [[0, 9.6, 10], [1, 1.01, 7]], "batl": NaN}, {"timestamp": 1631544273862, "ltp": 3.5, "tv": 268.11, "trd": NaN, "batb": [[0, 1.01, 7], [1, 1.01, 0]], "batl": NaN}, {"timestamp": 1631544278791, "ltp": 3.5, "tv": 268.11, "trd": NaN, "batb": [[0, 12, 10], [1, 1.01, 7]], "batl": NaN}, {"timestamp": 1631544280300, "ltp": 3.5, "tv": 268.11, "trd": NaN, "batb": [[0, 1.01, 7], [1, 1.01, 0]], "batl": NaN}, {"timestamp": 1631544284582, "ltp": 3.5, "tv": 268.11, "trd": NaN, "batb": [[0, 16, 10], [1, 1.01, 7]], "batl": NaN}, {"timestamp": 1631544286586, "ltp": 3.5, "tv": 268.11, "trd": NaN, "batb": NaN, "batl": [[0, 340, 36.37]]}, {"timestamp": 1631544291393, "ltp": 3.5, "tv": 268.11, "trd": NaN, "batb": [[0, 1.01, 7], [1, 1.01, 0]], "batl": NaN}, {"timestamp": 1631544306509, "ltp": 3.5, "tv": 268.11, "trd": NaN, "batb": [[0, 9.6, 10], [1, 1.01, 7]], "batl": NaN}, {"timestamp": 1631544308494, "ltp": 3.5, "tv": 268.11, "trd": NaN, "batb": [[0, 1.01, 7], [1, 1.01, 0]], "batl": NaN}, {"timestamp": 1631544312924, "ltp": 3.5, "tv": 268.11, "trd": NaN, "batb": [[0, 12, 10], [1, 1.01, 7]], "batl": NaN}, {"timestamp": 1631544324920, "ltp": 3.5, "tv": 268.11, "trd": NaN, "batb": [[0, 1.01, 7], [1, 1.01, 0]], "batl": NaN}, {"timestamp": 1631544329948, "ltp": 3.5, "tv": 268.11, "trd": NaN, "batb": [[0, 14, 10], [1, 1.01, 7]], "batl": NaN}, {"timestamp": 1631544370299, "ltp": 3.5, "tv": 268.11, "trd": NaN, "batb": [[0, 1.01, 7], [1, 1.01, 0]], "batl": NaN}, {"timestamp": 1631544375268, "ltp": 3.5, "tv": 268.11, "trd": NaN, "batb": [[0, 12, 10], [1, 1.01, 7]], "batl": NaN}, {"timestamp": 1631544407139, "ltp": 3.5, "tv": 268.11, "trd": NaN, "batb": [[0, 1.01, 7], [1, 1.01, 0]], "batl": NaN}, {"timestamp": 1631544412148, "ltp": 3.5, "tv": 268.11, "trd": NaN, "batb": [[0, 14, 10], [1, 1.01, 7]], "batl": NaN}, {"timestamp": 1631544507256, "ltp": 3.5, "tv": 268.11, "trd": NaN, "batb": [[0, 1.01, 7], [1, 1.01, 0]], "batl": NaN}, {"timestamp": 1631544512157, "ltp": 3.5, "tv": 268.11, "trd": NaN, "batb": [[0, 16, 10], [1, 1.01, 7]], "batl": NaN}, {"timestamp": 1631544528484, "ltp": 3.5, "tv": 268.11, "trd": NaN, "batb": [[0, 1.01, 7], [1, 1.01, 0]], "batl": NaN}, {"timestamp": 1631544533324, "ltp": 3.5, "tv": 268.11, "trd": NaN, "batb": [[0, 19.5, 10], [1, 1.01, 7]], "batl": NaN}, {"timestamp": 1631544571437, "ltp": 3.5, "tv": 268.11, "trd": NaN, "batb": [[0, 1.01, 7], [1, 1.01, 0]], "batl": NaN}, {"timestamp": 1631544576363, "ltp": 3.5, "tv": 268.11, "trd": NaN, "batb": [[0, 16, 10], [1, 1.01, 7]], "batl": NaN}, {"timestamp": 1631544577669, "ltp": 3.5, "tv": 268.11, "trd": NaN, "batb": NaN, "batl": [[0, 340, 36.37]]}, {"timestamp": 1631544609014, "ltp": 3.5, "tv": 268.11, "trd": NaN, "batb": [[0, 1.01, 7], [1, 1.01, 0]], "batl": NaN}, {"timestamp": 1631544613927, "ltp": 3.5, "tv": 268.11, "trd": NaN, "batb": [[0, 19.5, 10], [1, 1.01, 7]], "batl": NaN}, {"timestamp": 1631544642615, "ltp": 3.5, "tv": 268.11, "trd": NaN, "batb": [[0, 1.01, 7], [1, 1.01, 0]], "batl": NaN}, {"timestamp": 1631544647516, "ltp": 3.5, "tv": 268.11, "trd": NaN, "batb": [[0, 24, 10], [1, 1.01, 7]], "batl": NaN}, {"timestamp": 1631544659276, "ltp": 3.5, "tv": 268.11, "trd": NaN, "batb": [[0, 1.01, 7], [1, 1.01, 0]], "batl": NaN}, {"timestamp": 1631544664157, "ltp": 3.5, "tv": 268.11, "trd": NaN, "batb": [[0, 19.5, 10], [1, 1.01, 7]], "batl": NaN}, {"timestamp": 1631544678299, "ltp": 3.5, "tv": 268.11, "trd": NaN, "batb": [[0, 1.01, 7], [1, 1.01, 0]], "batl": NaN}, {"timestamp": 1631544683073, "ltp": 3.5, "tv": 268.11, "trd": NaN, "batb": [[0, 16, 10], [1, 1.01, 7]], "batl": NaN}, {"timestamp": 1631544685194, "ltp": 3.5, "tv": 268.11, "trd": NaN, "batb": NaN, "batl": [[0, 340, 36.37]]}, {"timestamp": 1631544713000, "ltp": 3.5, "tv": 268.11, "trd": NaN, "batb": [[0, 1.01, 7], [1, 1.01, 0]], "batl": NaN}, {"timestamp": 1631544718048, "ltp": 3.5, "tv": 268.11, "trd": NaN, "batb": [[0, 12, 10], [1, 1.01, 7]], "batl": NaN}, {"timestamp": 1631544743129, "ltp": 3.5, "tv": 268.11, "trd": NaN, "batb": [[0, 1.01, 7], [1, 1.01, 0]], "batl": NaN}, {"timestamp": 1631544748632, "ltp": 3.5, "tv": 268.11, "trd": NaN, "batb": [[0, 16, 10], [1, 1.01, 7]], "batl": NaN}, {"timestamp": 1631544749353, "ltp": 3.5, "tv": 268.11, "trd": NaN, "batb": NaN, "batl": [[0, 170, 37.48]]}, {"timestamp": 1631544770986, "ltp": 3.5, "tv": 268.11, "trd": NaN, "batb": [[0, 1.01, 7], [1, 1.01, 0]], "batl": NaN}, {"timestamp": 1631544775907, "ltp": 3.5, "tv": 268.11, "trd": NaN, "batb": [[0, 12, 10], [1, 1.01, 7]], "batl": NaN}, {"timestamp": 1631544808038, "ltp": 3.5, "tv": 268.11, "trd": NaN, "batb": [[0, 1.01, 7], [1, 1.01, 0]], "batl": NaN}, {"timestamp": 1631544813031, "ltp": 3.5, "tv": 268.11, "trd": NaN, "batb": [[0, 16, 10], [1, 1.01, 7]], "batl": NaN}, {"timestamp": 1631544814853, "ltp": 3.5, "tv": 268.11, "trd": NaN, "batb": NaN, "batl": [[0, 170, 37.48]]}, {"timestamp": 1631544835993, "ltp": 3.5, "tv": 268.11, "trd": NaN, "batb": [[0, 1.01, 7], [1, 1.01, 0]], "batl": NaN}, {"timestamp": 1631544840574, "ltp": 3.5, "tv": 268.11, "trd": NaN, "batb": [[0, 19.5, 10], [1, 1.01, 7]], "batl": NaN}, {"timestamp": 1631544866993, "ltp": 3.5, "tv": 268.11, "trd": NaN, "batb": [[0, 1.01, 7], [1, 1.01, 0]], "batl": NaN}, {"timestamp": 1631544871926, "ltp": 3.5, "tv": 268.11, "trd": NaN, "batb": [[0, 24, 10], [1, 1.01, 7]], "batl": NaN}, {"timestamp": 1631544879840, "ltp": 3.5, "tv": 268.11, "trd": NaN, "batb": [[0, 1.01, 7], [1, 1.01, 0]], "batl": NaN}, {"timestamp": 1631545207317, "ltp": 3.5, "tv": 268.29, "trd": [[1.42, 3.41], [1.45, 16.19], [1.61, 200], [2.42, 6.93], [3.5, 10.23], [3.95, 26.01]], "batb": NaN, "batl": NaN}, {"timestamp": 1631545318863, "ltp": 3.5, "tv": 268.29, "trd": NaN, "batb": [[0, 19.5, 10], [1, 1.01, 7]], "batl": NaN}, {"timestamp": 1631545334269, "ltp": 100.0, "tv": 268.38, "trd": [[100, 0.09]], "batb": NaN, "batl": NaN}, {"timestamp": 1631545439439, "ltp": 100.0, "tv": 268.38, "trd": NaN, "batb": [[0, 1.01, 7], [1, 1.01, 0]], "batl": NaN}, {"timestamp": 1631545444425, "ltp": 100.0, "tv": 268.38, "trd": NaN, "batb": [[0, 16, 10], [1, 1.01, 7]], "batl": NaN}, {"timestamp": 1631545473168, "ltp": 100.0, "tv": 268.38, "trd": NaN, "batb": NaN, "batl": [[0, 340, 36.42]]}, {"timestamp": 1631545557044, "ltp": 100.0, "tv": 268.38, "trd": NaN, "batb": [[0, 1.01, 7], [1, 1.01, 0]], "batl": NaN}, {"timestamp": 1631545561899, "ltp": 100.0, "tv": 268.38, "trd": NaN, "batb": [[0, 19.5, 10], [1, 1.01, 7]], "batl": NaN}, {"timestamp": 1631545579674, "ltp": 100.0, "tv": 268.38, "trd": NaN, "batb": [[0, 1.01, 7], [1, 1.01, 0]], "batl": NaN}, {"timestamp": 1631545674290, "ltp": 100.0, "tv": 268.38, "trd": NaN, "batb": [[0, 16, 10], [1, 1.01, 7]], "batl": NaN}, {"timestamp": 1631545691344, "ltp": 100.0, "tv": 268.38, "trd": NaN, "batb": [[0, 1.01, 7], [1, 1.01, 0]], "batl": NaN}, {"timestamp": 1631545696352, "ltp": 100.0, "tv": 268.38, "trd": NaN, "batb": [[0, 14, 10], [1, 1.01, 7]], "batl": NaN}, {"timestamp": 1631545697718, "ltp": 100.0, "tv": 268.38, "trd": NaN, "batb": NaN, "batl": [[0, 340, 36.42]]}, {"timestamp": 1631545727589, "ltp": 100.0, "tv": 268.38, "trd": NaN, "batb": NaN, "batl": [[0, 1000, 3.41]]}, {"timestamp": 1631545734120, "ltp": 100.0, "tv": 268.38, "trd": NaN, "batb": [[0, 1.01, 7], [1, 1.01, 0]], "batl": NaN}, {"timestamp": 1631545739026, "ltp": 100.0, "tv": 268.38, "trd": NaN, "batb": [[0, 9.6, 10], [1, 1.01, 7]], "batl": NaN}, {"timestamp": 1631545749215, "ltp": 100.0, "tv": 268.38, "trd": NaN, "batb": [[0, 1.01, 7], [1, 1.01, 0]], "batl": NaN}, {"timestamp": 1631545754230, "ltp": 100.0, "tv": 268.38, "trd": NaN, "batb": [[0, 8.6, 10], [1, 1.01, 7]], "batl": NaN}, {"timestamp": 1631545773637, "ltp": 100.0, "tv": 268.38, "trd": NaN, "batb": [[0, 1.01, 7], [1, 1.01, 0]], "batl": NaN}, {"timestamp": 1631545778665, "ltp": 100.0, "tv": 268.38, "trd": NaN, "batb": [[0, 12, 10], [1, 1.01, 7]], "batl": NaN}, {"timestamp": 1631545809397, "ltp": 100.0, "tv": 268.38, "trd": NaN, "batb": [[0, 1.01, 7], [1, 1.01, 0]], "batl": NaN}, {"timestamp": 1631545814294, "ltp": 100.0, "tv": 268.38, "trd": NaN, "batb": [[0, 8.6, 10], [1, 1.01, 7]], "batl": NaN}, {"timestamp": 1631545843743, "ltp": 100.0, "tv": 268.38, "trd": NaN, "batb": [[0, 1.01, 7], [1, 1.01, 0]], "batl": NaN}, {"timestamp": 1631545848625, "ltp": 100.0, "tv": 268.38, "trd": NaN, "batb": [[0, 7, 10], [1, 1.01, 7]], "batl": NaN}, {"timestamp": 1631545861533, "ltp": 7.0, "tv": 270.4, "trd": [[7, 2.02]], "batb": [[0, 7, 8.99]], "batl": NaN}, {"timestamp": 1631545861843, "ltp": 7.0, "tv": 270.4, "trd": NaN, "batb": [[0, 1.01, 7], [1, 1.01, 0]], "batl": NaN}, {"timestamp": 1631545866738, "ltp": 7.0, "tv": 270.4, "trd": NaN, "batb": [[0, 7, 10], [1, 1.01, 7]], "batl": NaN}, {"timestamp": 1631545868331, "ltp": 7.0, "tv": 270.4, "trd": NaN, "batb": [[0, 1.01, 7], [1, 1.01, 0]], "batl": NaN}, {"timestamp": 1631545873342, "ltp": 7.0, "tv": 270.4, "trd": NaN, "batb": [[0, 6, 10], [1, 1.01, 7]], "batl": NaN}, {"timestamp": 1631545992962, "ltp": 7.0, "tv": 270.4, "trd": NaN, "batb": [[0, 1.01, 7], [1, 1.01, 0]], "batl": NaN}, {"timestamp": 1631545997866, "ltp": 7.0, "tv": 270.4, "trd": NaN, "batb": [[0, 7.6, 10], [1, 1.01, 7]], "batl": NaN}, {"timestamp": 1631546027649, "ltp": 7.0, "tv": 270.4, "trd": NaN, "batb": [[0, 1.01, 7], [1, 1.01, 0]], "batl": NaN}, {"timestamp": 1631546032581, "ltp": 7.0, "tv": 270.4, "trd": NaN, "batb": [[0, 12, 10], [1, 1.01, 7]], "batl": NaN}, {"timestamp": 1631546055498, "ltp": 7.0, "tv": 270.4, "trd": NaN, "batb": [[0, 1.01, 7], [1, 1.01, 0]], "batl": NaN}, {"timestamp": 1631546060407, "ltp": 7.0, "tv": 270.4, "trd": NaN, "batb": [[0, 8, 10], [1, 1.01, 7]], "batl": NaN}, {"timestamp": 1631546080393, "ltp": 7.0, "tv": 270.4, "trd": NaN, "batb": [[0, 1.01, 7], [1, 1.01, 0]], "batl": NaN}, {"timestamp": 1631546085410, "ltp": 7.0, "tv": 270.4, "trd": NaN, "batb": [[0, 16, 10], [1, 1.01, 7]], "batl": NaN}, {"timestamp": 1631546087012, "ltp": 7.0, "tv": 270.4, "trd": NaN, "batb": NaN, "batl": [[0, 170, 32.52]]}, {"timestamp": 1631546109453, "ltp": 7.0, "tv": 270.4, "trd": NaN, "batb": [[0, 1.01, 7], [1, 1.01, 0]], "batl": NaN}]}]}