{"info": {"id": "1.187552453", "eventId": "30895271", "eventName": "Match Odds", "marketType": "MATCH_ODDS", "openDate": 1631458867084, "name": "E Silva v U Nebelska", "numberOfActiveRunner": 2, "countryCode": "", "sport": "TENNIS", "venue": "", "volume": {"total": 10848.71, "preMatch": 10021.9, "inPlay": 826.81}, "winner": {"id": 9183341, "name": "E Silva", "status": "WINNER", "position": 1}, "delay": 5}, "runners": [{"id": 9183341, "name": "E Silva", "status": "WINNER", "position": 1, "inPlayOdds": 1.01, "inPlayTime": 1631458867084, "avgPrematch": 1.03, "closedOdds": 1.01, "maxPrematch": 1.04, "minPrematch": 1.01, "maxInPlay": 1.02, "minInPlay": 1.01, "inPlayIndex": 31, "lengthOdds": 60, "lengthOddsPrematch": 31, "lengthOddsInPlay": 29, "tradedVolume": 10814.38, "preMatchVolume": 10018.49, "inPlayVolume": 795.89}, {"id": 25079846, "name": "U Nebelska", "status": "LOSER", "position": 2, "inPlayOdds": 75.0, "inPlayTime": 1631462689567, "avgPrematch": 0, "closedOdds": 100.0, "maxPrematch": -100, "minPrematch": 1001, "maxInPlay": 100.0, "minInPlay": 70.0, "inPlayIndex": 0, "lengthOdds": 55, "lengthOddsPrematch": 0, "lengthOddsInPlay": 55, "tradedVolume": 34.33, "preMatchVolume": 3.41, "inPlayVolume": 30.92}], "marketUpdates": [{"timestamp": 1631441187451000000, "openDate": "2021-09-12T15:00:00.000Z", "status": "OPEN", "betDelay": 0, "inPlay": false, "complete": true}, {"timestamp": 1631458867084000000, "openDate": "2021-09-12T15:00:00.000Z", "status": "OPEN", "betDelay": 5, "inPlay": true, "complete": true}, {"timestamp": 1631462648540000000, "openDate": "2021-09-12T16:04:06.000Z", "status": "OPEN", "betDelay": 5, "inPlay": true, "complete": true}, {"timestamp": 1631465623725000000, "openDate": "2021-09-12T16:04:06.000Z", "status": "SUSPENDED", "betDelay": 5, "inPlay": true, "complete": true}, {"timestamp": 1631465630761000000, "openDate": "2021-09-12T16:04:06.000Z", "status": "CLOSED", "betDelay": 5, "inPlay": true, "complete": true}], "odds": [{"runnerId": 9183341, "odds": [{"timestamp": 1631448707175, "ltp": 1.02, "tv": 909.81, "trd": [[1.02, 909.82]], "batb": [[0, 1.02, 153.54]], "batl": NaN}, {"timestamp": 1631448710196, "ltp": 1.02, "tv": 909.81, "trd": NaN, "batb": [[0, 1.02, 108.45]], "batl": NaN}, {"timestamp": 1631448717419, "ltp": 1.03, "tv": 1159.2, "trd": [[1.03, 249.38]], "batb": [[0, 1.03, 236.82], [1, 1.02, 108.45], [2, 1.01, 12]], "batl": NaN}, {"timestamp": 1631448717605, "ltp": 1.03, "tv": 1159.2, "trd": NaN, "batb": [[0, 1.05, 2.89], [1, 1.04, 2.89], [2, 1.03, 236.82]], "batl": NaN}, {"timestamp": 1631448718922, "ltp": 1.03, "tv": 1159.2, "trd": NaN, "batb": [[0, 1.04, 2.89], [1, 1.03, 236.82], [2, 1.02, 108.45]], "batl": NaN}, {"timestamp": 1631448721016, "ltp": 1.03, "tv": 1159.2, "trd": NaN, "batb": [[1, 1.02, 108.45], [2, 1.01, 12]], "batl": NaN}, {"timestamp": 1631448723410, "ltp": 1.03, "tv": 1159.2, "trd": NaN, "batb": [[1, 1.01, 12], [2, 1.01, 0]], "batl": NaN}, {"timestamp": 1631448723504, "ltp": 1.03, "tv": 1159.2, "trd": NaN, "batb": [[1, 1.01, 120.45]], "batl": NaN}, {"timestamp": 1631448730005, "ltp": 1.03, "tv": 1159.2, "trd": NaN, "batb": NaN, "batl": [[0, 1.08, 118.92], [1, 1.09, 43.98], [2, 1.21, 80]]}, {"timestamp": 1631448733544, "ltp": 1.03, "tv": 1159.2, "trd": NaN, "batb": NaN, "batl": [[0, 1.05, 105.52], [1, 1.08, 118.92], [2, 1.09, 43.98]]}, {"timestamp": 1631448921844, "ltp": 1.03, "tv": 1159.2, "trd": NaN, "batb": [[1, 1.01, 3536.63]], "batl": NaN}, {"timestamp": 1631448929265, "ltp": 1.04, "tv": 1164.98, "trd": [[1.04, 5.79]], "batb": [[0, 1.01, 3536.63], [1, 1.01, 0]], "batl": [[0, 1.05, 106.04]]}, {"timestamp": 1631448934256, "ltp": 1.04, "tv": 1164.98, "trd": NaN, "batb": NaN, "batl": [[0, 1.05, 105.52]]}, {"timestamp": 1631448945171, "ltp": 1.04, "tv": 1164.98, "trd": NaN, "batb": [[0, 1.02, 5.12], [1, 1.01, 3536.63]], "batl": NaN}, {"timestamp": 1631449048339, "ltp": 1.04, "tv": 1164.98, "trd": NaN, "batb": [[0, 1.02, 9.36]], "batl": [[0, 1.04, 3.13], [1, 1.05, 105.52], [2, 1.08, 118.92]]}, {"timestamp": 1631449453453, "ltp": 1.04, "tv": 1164.98, "trd": NaN, "batb": NaN, "batl": [[1, 1.08, 118.92], [2, 1.09, 43.98]]}, {"timestamp": 1631449453555, "ltp": 1.04, "tv": 1164.98, "trd": NaN, "batb": NaN, "batl": [[0, 1.04, 108.65]]}, {"timestamp": 1631450103938, "ltp": 1.04, "tv": 1164.98, "trd": NaN, "batb": [[0, 1.02, 4.24]], "batl": NaN}, {"timestamp": 1631450392880, "ltp": 1.04, "tv": 1164.98, "trd": NaN, "batb": [[1, 1.01, 120.45]], "batl": NaN}, {"timestamp": 1631452990040, "ltp": 1.04, "tv": 1164.98, "trd": NaN, "batb": [[1, 1.01, 3536.63]], "batl": NaN}, {"timestamp": 1631453233040, "ltp": 1.04, "tv": 1164.98, "trd": NaN, "batb": NaN, "batl": [[1, 1.07, 43.98], [2, 1.08, 118.92]]}, {"timestamp": 1631455393947, "ltp": 1.02, "tv": 1173.46, "trd": [[1.02, 918.3]], "batb": [[0, 1.01, 3536.63], [1, 1.01, 0]], "batl": [[0, 1.02, 5913.62], [1, 1.04, 108.65], [2, 1.07, 43.98]]}, {"timestamp": 1631456208378, "ltp": 1.02, "tv": 1213.94, "trd": [[1.02, 958.78]], "batb": NaN, "batl": [[0, 1.02, 5893.38]]}, {"timestamp": 1631456340652, "ltp": 1.02, "tv": 1213.94, "trd": NaN, "batb": [[0, 1.01, 4390.67]], "batl": NaN}, {"timestamp": 1631458010726, "ltp": 1.02, "tv": 1213.94, "trd": NaN, "batb": [[0, 1.01, 4402.16]], "batl": [[1, 1.04, 120.14]]}, {"timestamp": 1631458209875, "ltp": 1.02, "tv": 1213.94, "trd": NaN, "batb": NaN, "batl": [[0, 1.04, 120.14], [1, 1.07, 43.98], [2, 1.08, 118.92]]}, {"timestamp": 1631458211090, "ltp": 1.01, "tv": 10018.49, "trd": [[1.01, 8804.54]], "batb": NaN, "batl": [[0, 1.01, 1490.99], [1, 1.04, 120.14], [2, 1.07, 43.98]]}, {"timestamp": 1631458356860, "ltp": 1.01, "tv": 10018.49, "trd": NaN, "batb": NaN, "batl": [[1, 1.03, 4184.82], [2, 1.04, 120.14]]}, {"timestamp": 1631458636562, "ltp": 1.01, "tv": 10018.49, "trd": NaN, "batb": NaN, "batl": [[1, 1.04, 120.14], [2, 1.07, 54.77]]}, {"timestamp": 1631458651429, "ltp": 1.01, "tv": 10018.49, "trd": NaN, "batb": NaN, "batl": [[1, 1.02, 2135.11], [2, 1.04, 120.14]]}, {"timestamp": 1631458670859, "ltp": 1.01, "tv": 10018.49, "trd": NaN, "batb": NaN, "batl": [[2, 1.03, 1964.3]]}, {"timestamp": 1631458867084, "ltp": 1.01, "tv": 10018.49, "trd": NaN, "batb": NaN, "batl": [[0, 1.02, 2135.11], [1, 1.03, 1964.3], [2, 1.07, 10.8]]}, {"timestamp": 1631458989002, "ltp": 1.01, "tv": 10018.49, "trd": NaN, "batb": NaN, "batl": [[1, 1.07, 10.8], [2, 1.21, 80]]}, {"timestamp": 1631459152344, "ltp": 1.01, "tv": 10018.49, "trd": NaN, "batb": NaN, "batl": [[0, 1.07, 10.8], [1, 1.21, 80], [2, 1.21, 0]]}, {"timestamp": 1631459189499, "ltp": 1.01, "tv": 10018.49, "trd": NaN, "batb": NaN, "batl": [[0, 1.05, 854.04], [1, 1.07, 10.8], [2, 1.21, 80]]}, {"timestamp": 1631459333211, "ltp": 1.01, "tv": 10018.49, "trd": NaN, "batb": NaN, "batl": [[0, 1.02, 427.02], [1, 1.05, 854.04], [2, 1.07, 10.8]]}, {"timestamp": 1631462876147, "ltp": 1.01, "tv": 10018.49, "trd": NaN, "batb": NaN, "batl": [[1, 1.07, 10.8], [2, 1.1, 854.04]]}, {"timestamp": 1631462881256, "ltp": 1.01, "tv": 10018.49, "trd": NaN, "batb": NaN, "batl": [[1, 1.03, 854.04], [2, 1.07, 10.8]]}, {"timestamp": 1631463143818, "ltp": 1.01, "tv": 10018.49, "trd": NaN, "batb": [[0, 1.01, 2.89]], "batl": NaN}, {"timestamp": 1631463203515, "ltp": 1.02, "tv": 10024.27, "trd": [[1.02, 964.56]], "batb": NaN, "batl": [[0, 1.02, 424.13]]}, {"timestamp": 1631463540101, "ltp": 1.02, "tv": 10365.89, "trd": [[1.02, 1306.18]], "batb": NaN, "batl": [[0, 1.02, 253.32]]}, {"timestamp": 1631463708088, "ltp": 1.02, "tv": 10465.89, "trd": [[1.02, 1406.18]], "batb": NaN, "batl": [[0, 1.02, 203.31]]}, {"timestamp": 1631463945803, "ltp": 1.02, "tv": 10465.89, "trd": NaN, "batb": NaN, "batl": [[1, 1.07, 10.8], [2, 1.1, 854.04]]}, {"timestamp": 1631463950900, "ltp": 1.02, "tv": 10465.89, "trd": NaN, "batb": NaN, "batl": [[0, 1.02, 1057.36]]}, {"timestamp": 1631463966903, "ltp": 1.02, "tv": 10465.89, "trd": NaN, "batb": NaN, "batl": [[2, 1.2, 200.82]]}, {"timestamp": 1631464107830, "ltp": 1.02, "tv": 10465.89, "trd": NaN, "batb": NaN, "batl": [[2, 1.19, 436.42]]}, {"timestamp": 1631464139770, "ltp": 1.02, "tv": 10465.89, "trd": NaN, "batb": NaN, "batl": [[0, 1.01, 837.38], [1, 1.02, 1057.36], [2, 1.07, 10.8]]}, {"timestamp": 1631464231270, "ltp": 1.01, "tv": 10469.31, "trd": [[1.01, 8807.96]], "batb": NaN, "batl": [[0, 1.01, 835.67]]}, {"timestamp": 1631464263230, "ltp": 1.01, "tv": 10472.73, "trd": [[1.01, 8811.38]], "batb": NaN, "batl": [[0, 1.01, 833.96]]}, {"timestamp": 1631464374854, "ltp": 1.01, "tv": 10476.14, "trd": [[1.01, 8814.79]], "batb": NaN, "batl": [[0, 1.01, 832.26]]}, {"timestamp": 1631464377462, "ltp": 1.01, "tv": 10645.26, "trd": [[1.01, 8983.91]], "batb": NaN, "batl": [[0, 1.01, 663.14]]}, {"timestamp": 1631464412201, "ltp": 1.01, "tv": 10814.38, "trd": [[1.01, 9153.03]], "batb": NaN, "batl": [[0, 1.01, 494.02]]}, {"timestamp": 1631464429014, "ltp": 1.01, "tv": 10814.38, "trd": NaN, "batb": NaN, "batl": [[1, 1.07, 10.8], [2, 1.19, 436.42]]}, {"timestamp": 1631464481237, "ltp": 1.01, "tv": 10814.38, "trd": NaN, "batb": NaN, "batl": [[1, 1.05, 2265.78], [2, 1.07, 10.8]]}, {"timestamp": 1631464506213, "ltp": 1.01, "tv": 10814.38, "trd": NaN, "batb": NaN, "batl": [[0, 1.01, 1091.85]]}, {"timestamp": 1631464623210, "ltp": 1.01, "tv": 10814.38, "trd": NaN, "batb": NaN, "batl": [[0, 1.01, 494.02], [1, 1.07, 10.8], [2, 1.19, 436.42]]}, {"timestamp": 1631464726243, "ltp": 1.01, "tv": 10814.38, "trd": NaN, "batb": NaN, "batl": [[0, 1.01, 921.04]]}, {"timestamp": 1631464813586, "ltp": 1.01, "tv": 10814.38, "trd": NaN, "batb": NaN, "batl": [[0, 1.01, 494.02]]}, {"timestamp": 1631464958979, "ltp": 1.01, "tv": 10814.38, "trd": NaN, "batb": NaN, "batl": [[0, 1.01, 694.02]]}, {"timestamp": 1631464995858, "ltp": 1.01, "tv": 10814.38, "trd": NaN, "batb": NaN, "batl": [[0, 1.01, 887.51]]}]}, {"runnerId": 25079846, "odds": [{"timestamp": 1631462689567, "ltp": 75.0, "tv": 3.41, "trd": [[75, 3.42]], "batb": [[0, 75, 15.37]], "batl": NaN}, {"timestamp": 1631462733604, "ltp": 75.0, "tv": 3.41, "trd": NaN, "batb": NaN, "batl": [[0, 1000, 3.42]]}, {"timestamp": 1631462740534, "ltp": 75.0, "tv": 6.83, "trd": [[75, 6.83]], "batb": [[0, 75, 13.66]], "batl": NaN}, {"timestamp": 1631462873032, "ltp": 75.0, "tv": 6.83, "trd": NaN, "batb": NaN, "batl": [[0, 1000, 3.42]]}, {"timestamp": 1631462876147, "ltp": 75.0, "tv": 6.83, "trd": NaN, "batb": [[0, 55, 7.08], [1, 1.01, 12], [2, 1.01, 0]], "batl": NaN}, {"timestamp": 1631462879764, "ltp": 75.0, "tv": 6.83, "trd": NaN, "batb": NaN, "batl": [[0, 75, 1.14]]}, {"timestamp": 1631462881256, "ltp": 75.0, "tv": 6.83, "trd": NaN, "batb": [[0, 85, 13.66], [1, 55, 7.08], [2, 1.01, 12]], "batl": NaN}, {"timestamp": 1631463036425, "ltp": 75.0, "tv": 6.83, "trd": NaN, "batb": [[0, 55, 7.08], [1, 1.01, 12], [2, 1.01, 0]], "batl": NaN}, {"timestamp": 1631463041513, "ltp": 75.0, "tv": 6.83, "trd": NaN, "batb": [[0, 75, 13.66], [1, 55, 7.08], [2, 1.01, 12]], "batl": NaN}, {"timestamp": 1631463253501, "ltp": 75.0, "tv": 6.83, "trd": NaN, "batb": [[0, 55, 7.08], [1, 1.01, 12], [2, 1.01, 0]], "batl": NaN}, {"timestamp": 1631463258621, "ltp": 75.0, "tv": 6.83, "trd": NaN, "batb": [[0, 85, 13.66], [1, 55, 7.08], [2, 1.01, 12]], "batl": NaN}, {"timestamp": 1631463512774, "ltp": 75.0, "tv": 6.83, "trd": NaN, "batb": NaN, "batl": [[0, 1000, 3.42]]}, {"timestamp": 1631463519372, "ltp": 85.0, "tv": 9.83, "trd": [[85, 3.01]], "batb": [[0, 85, 12.16]], "batl": NaN}, {"timestamp": 1631463543307, "ltp": 85.0, "tv": 9.83, "trd": NaN, "batb": NaN, "batl": [[0, 1000, 3.42]]}, {"timestamp": 1631463550020, "ltp": 85.0, "tv": 11.85, "trd": [[85, 5.02]], "batb": [[0, 85, 11.15]], "batl": NaN}, {"timestamp": 1631463565413, "ltp": 85.0, "tv": 11.85, "trd": NaN, "batb": [[0, 55, 7.08], [1, 1.01, 12], [2, 1.01, 0]], "batl": NaN}, {"timestamp": 1631463568808, "ltp": 85.0, "tv": 11.85, "trd": NaN, "batb": NaN, "batl": [[0, 85, 2.64]]}, {"timestamp": 1631463570528, "ltp": 85.0, "tv": 11.85, "trd": NaN, "batb": [[0, 75, 11.15], [1, 55, 7.08], [2, 1.01, 12]], "batl": NaN}, {"timestamp": 1631463580870, "ltp": 75.0, "tv": 17.13, "trd": [[75, 12.11]], "batb": [[0, 75, 8.51]], "batl": NaN}, {"timestamp": 1631463636629, "ltp": 75.0, "tv": 17.13, "trd": NaN, "batb": [[0, 55, 7.08], [1, 1.01, 12], [2, 1.01, 0]], "batl": NaN}, {"timestamp": 1631463641722, "ltp": 75.0, "tv": 17.13, "trd": NaN, "batb": [[0, 85, 8.51], [1, 55, 7.08], [2, 1.01, 12]], "batl": NaN}, {"timestamp": 1631463725792, "ltp": 75.0, "tv": 17.13, "trd": NaN, "batb": NaN, "batl": [[0, 1000, 3.42]]}, {"timestamp": 1631463732114, "ltp": 85.0, "tv": 21.14, "trd": [[85, 9.04]], "batb": [[0, 85, 6.51]], "batl": NaN}, {"timestamp": 1631463782959, "ltp": 85.0, "tv": 21.14, "trd": NaN, "batb": [[0, 55, 7.08], [1, 1.01, 12], [2, 1.01, 0]], "batl": NaN}, {"timestamp": 1631463787980, "ltp": 85.0, "tv": 21.14, "trd": NaN, "batb": [[0, 70, 6.51], [1, 55, 7.08], [2, 1.01, 12]], "batl": NaN}, {"timestamp": 1631463817390, "ltp": 85.0, "tv": 21.14, "trd": NaN, "batb": NaN, "batl": [[0, 1000, 1.22]]}, {"timestamp": 1631463822708, "ltp": 70.0, "tv": 23.58, "trd": [[70, 2.44]], "batb": [[0, 70, 5.29]], "batl": NaN}, {"timestamp": 1631463847670, "ltp": 70.0, "tv": 23.58, "trd": NaN, "batb": NaN, "batl": [[0, 1000, 3.42]]}, {"timestamp": 1631463853991, "ltp": 70.0, "tv": 26.03, "trd": [[70, 4.89]], "batb": [[0, 70, 4.07]], "batl": NaN}, {"timestamp": 1631463855107, "ltp": 70.0, "tv": 26.03, "trd": NaN, "batb": [[2, 1.02, 14.46]], "batl": NaN}, {"timestamp": 1631463864328, "ltp": 70.0, "tv": 26.03, "trd": NaN, "batb": [[1, 1.02, 14.46], [2, 1.01, 12]], "batl": NaN}, {"timestamp": 1631463879610, "ltp": 70.0, "tv": 26.03, "trd": NaN, "batb": NaN, "batl": [[0, 1000, 3.42]]}, {"timestamp": 1631463885893, "ltp": 70.0, "tv": 28.47, "trd": [[70, 7.33]], "batb": [[0, 70, 2.84]], "batl": NaN}, {"timestamp": 1631463910156, "ltp": 70.0, "tv": 28.47, "trd": NaN, "batb": NaN, "batl": [[0, 1000, 3.42]]}, {"timestamp": 1631463916466, "ltp": 70.0, "tv": 30.91, "trd": [[70, 9.77]], "batb": [[0, 70, 1.62]], "batl": NaN}, {"timestamp": 1631463936901, "ltp": 70.0, "tv": 30.91, "trd": NaN, "batb": [[0, 1.02, 14.46], [1, 1.01, 12], [2, 1.01, 0]], "batl": NaN}, {"timestamp": 1631463987362, "ltp": 70.0, "tv": 30.91, "trd": NaN, "batb": [[0, 70, 8.54], [1, 1.02, 14.46], [2, 1.01, 12]], "batl": NaN}, {"timestamp": 1631464072504, "ltp": 70.0, "tv": 30.91, "trd": NaN, "batb": [[0, 1.02, 14.46], [1, 1.01, 12], [2, 1.01, 0]], "batl": NaN}, {"timestamp": 1631464077591, "ltp": 70.0, "tv": 30.91, "trd": NaN, "batb": [[0, 85, 8.54], [1, 1.02, 14.46], [2, 1.01, 12]], "batl": NaN}, {"timestamp": 1631464370948, "ltp": 70.0, "tv": 30.91, "trd": NaN, "batb": NaN, "batl": [[0, 1000, 3.42]]}, {"timestamp": 1631464377462, "ltp": 100.0, "tv": 32.62, "trd": [[100, 1.71]], "batb": NaN, "batl": NaN}, {"timestamp": 1631464404889, "ltp": 100.0, "tv": 32.62, "trd": NaN, "batb": NaN, "batl": [[0, 1000, 3.42]]}, {"timestamp": 1631464412201, "ltp": 100.0, "tv": 34.33, "trd": [[100, 3.42]], "batb": NaN, "batl": NaN}, {"timestamp": 1631464429014, "ltp": 100.0, "tv": 34.33, "trd": NaN, "batb": [[0, 1.02, 14.46], [1, 1.01, 12], [2, 1.01, 0]], "batl": NaN}, {"timestamp": 1631464693405, "ltp": 100.0, "tv": 34.33, "trd": NaN, "batb": [[0, 150, 12.81], [1, 1.02, 14.46], [2, 1.01, 12]], "batl": NaN}, {"timestamp": 1631464818798, "ltp": 100.0, "tv": 34.33, "trd": NaN, "batb": [[0, 1.02, 14.46], [1, 1.01, 12], [2, 1.01, 0]], "batl": NaN}, {"timestamp": 1631464823868, "ltp": 100.0, "tv": 34.33, "trd": NaN, "batb": [[0, 170, 12.81], [1, 1.02, 14.46], [2, 1.01, 12]], "batl": NaN}, {"timestamp": 1631464887966, "ltp": 100.0, "tv": 34.33, "trd": NaN, "batb": [[0, 1.02, 14.46], [1, 1.01, 12], [2, 1.01, 0]], "batl": NaN}, {"timestamp": 1631464893022, "ltp": 100.0, "tv": 34.33, "trd": NaN, "batb": [[0, 200, 12.81], [1, 1.02, 14.46], [2, 1.01, 12]], "batl": NaN}, {"timestamp": 1631464948006, "ltp": 100.0, "tv": 34.33, "trd": NaN, "batb": [[0, 1.02, 14.46], [1, 1.01, 12], [2, 1.01, 0]], "batl": NaN}, {"timestamp": 1631464967741, "ltp": 100.0, "tv": 34.33, "trd": NaN, "batb": [[0, 300, 9.39], [1, 1.02, 14.46], [2, 1.01, 12]], "batl": NaN}, {"timestamp": 1631465069115, "ltp": 100.0, "tv": 34.33, "trd": NaN, "batb": [[0, 1.02, 14.46], [1, 1.01, 12], [2, 1.01, 0]], "batl": NaN}, {"timestamp": 1631465074245, "ltp": 100.0, "tv": 34.33, "trd": NaN, "batb": [[0, 200, 9.39], [1, 1.02, 14.46], [2, 1.01, 12]], "batl": NaN}, {"timestamp": 1631465171043, "ltp": 100.0, "tv": 34.33, "trd": NaN, "batb": [[0, 1.02, 14.46], [1, 1.01, 12], [2, 1.01, 0]], "batl": NaN}, {"timestamp": 1631465176174, "ltp": 100.0, "tv": 34.33, "trd": NaN, "batb": [[0, 300, 9.39], [1, 1.02, 14.46], [2, 1.01, 12]], "batl": NaN}]}]}