{"info": {"id": "1.187551081", "eventId": "30895117", "eventName": "Match Odds", "marketType": "MATCH_ODDS", "openDate": 1631457454411, "name": "Eka Yashina v Bandecchi", "numberOfActiveRunner": 2, "countryCode": "", "sport": "TENNIS", "venue": "", "volume": {"total": 74636.33, "preMatch": 1800.02, "inPlay": 72836.31}, "winner": {"id": 9629022, "name": "Susan Bandecchi", "status": "WINNER", "position": 2}, "delay": 3}, "runners": [{"id": 7445998, "name": "Ekaterina Yashina", "status": "LOSER", "position": 1, "inPlayOdds": 8.0, "inPlayTime": 1631457454411, "avgPrematch": 6.57, "closedOdds": 55.0, "maxPrematch": 8.0, "minPrematch": 4.6, "maxInPlay": 100.0, "minInPlay": 3.35, "inPlayIndex": 58, "lengthOdds": 1853, "lengthOddsPrematch": 58, "lengthOddsInPlay": 1795, "tradedVolume": 2136.96, "preMatchVolume": 107.46, "inPlayVolume": 2029.5}, {"id": 9629022, "name": "Susan Bandecchi", "status": "WINNER", "position": 2, "inPlayOdds": 1.11, "inPlayTime": 1631457454411, "avgPrematch": 1.18, "closedOdds": 1.02, "maxPrematch": 1.28, "minPrematch": 1.11, "maxInPlay": 1.46, "minInPlay": 1.01, "inPlayIndex": 78, "lengthOdds": 2347, "lengthOddsPrematch": 78, "lengthOddsInPlay": 2269, "tradedVolume": 72499.37, "preMatchVolume": 1692.56, "inPlayVolume": 70806.81}], "marketUpdates": [{"timestamp": 1631436373680000000, "openDate": "2021-09-12T13:30:00.000Z", "status": "OPEN", "betDelay": 0, "inPlay": false, "complete": true}, {"timestamp": 1631453661764000000, "openDate": "2021-09-12T14:00:00.000Z", "status": "OPEN", "betDelay": 0, "inPlay": false, "complete": true}, {"timestamp": 1631455759251000000, "openDate": "2021-09-12T14:30:00.000Z", "status": "OPEN", "betDelay": 0, "inPlay": false, "complete": true}, {"timestamp": 1631457268787000000, "openDate": "2021-09-12T15:00:00.000Z", "status": "OPEN", "betDelay": 0, "inPlay": false, "complete": true}, {"timestamp": 1631457454411000000, "openDate": "2021-09-12T15:00:00.000Z", "status": "OPEN", "betDelay": 3, "inPlay": true, "complete": true}, {"timestamp": 1631463623537000000, "openDate": "2021-09-12T15:00:00.000Z", "status": "SUSPENDED", "betDelay": 3, "inPlay": true, "complete": true}, {"timestamp": 1631463669930000000, "openDate": "2021-09-12T15:00:00.000Z", "status": "CLOSED", "betDelay": 3, "inPlay": true, "complete": true}], "odds": [{"runnerId": 7445998, "odds": [{"timestamp": 1631443181342, "ltp": 6.4, "tv": 3.79, "trd": [[6.4, 3.79]], "batb": [[0, 6.4, 6.21]], "batl": NaN}, {"timestamp": 1631443185905, "ltp": 6.4, "tv": 3.79, "trd": NaN, "batb": [[0, 6.4, 10]], "batl": NaN}, {"timestamp": 1631443208722, "ltp": 6.4, "tv": 7.58, "trd": [[6.4, 7.58]], "batb": [[0, 6.4, 6.21]], "batl": NaN}, {"timestamp": 1631443211236, "ltp": 6.4, "tv": 7.58, "trd": NaN, "batb": [[0, 6.4, 10]], "batl": NaN}, {"timestamp": 1631443247218, "ltp": 6.4, "tv": 11.37, "trd": [[6.4, 11.37]], "batb": [[0, 6.4, 6.21]], "batl": NaN}, {"timestamp": 1631443251741, "ltp": 6.4, "tv": 11.37, "trd": NaN, "batb": [[0, 6.4, 10]], "batl": NaN}, {"timestamp": 1631443297733, "ltp": 6.4, "tv": 13.26, "trd": [[6.4, 13.26]], "batb": [[0, 6.4, 8.11]], "batl": NaN}, {"timestamp": 1631443302350, "ltp": 6.4, "tv": 13.26, "trd": NaN, "batb": [[0, 6.4, 10]], "batl": NaN}, {"timestamp": 1631443352363, "ltp": 6.4, "tv": 14.09, "trd": [[6.4, 14.09]], "batb": [[0, 6.4, 9.17]], "batl": NaN}, {"timestamp": 1631443352838, "ltp": 6.4, "tv": 14.09, "trd": NaN, "batb": [[0, 6.4, 10]], "batl": NaN}, {"timestamp": 1631443383133, "ltp": 6.4, "tv": 14.09, "trd": NaN, "batb": [[0, 5.5, 10]], "batl": NaN}, {"timestamp": 1631443398377, "ltp": 6.4, "tv": 14.09, "trd": NaN, "batb": [[0, 5, 10]], "batl": NaN}, {"timestamp": 1631443449482, "ltp": 5.0, "tv": 19.0, "trd": [[5, 4.91]], "batb": [[0, 5, 5.09]], "batl": NaN}, {"timestamp": 1631443454076, "ltp": 5.0, "tv": 19.0, "trd": NaN, "batb": [[0, 5, 10]], "batl": NaN}, {"timestamp": 1631443471136, "ltp": 5.0, "tv": 23.91, "trd": [[5, 9.82]], "batb": [[0, 5, 5.09]], "batl": NaN}, {"timestamp": 1631443474339, "ltp": 5.0, "tv": 23.91, "trd": NaN, "batb": [[0, 5, 10]], "batl": NaN}, {"timestamp": 1631443491719, "ltp": 5.0, "tv": 26.36, "trd": [[5, 12.28]], "batb": [[0, 5, 7.54]], "batl": NaN}, {"timestamp": 1631443494602, "ltp": 5.0, "tv": 26.36, "trd": NaN, "batb": [[0, 5, 10]], "batl": NaN}, {"timestamp": 1631443700243, "ltp": 5.0, "tv": 45.15, "trd": [[5, 31.06]], "batb": [[0, 1.01, 25.61], [1, 1.01, 0]], "batl": NaN}, {"timestamp": 1631443702172, "ltp": 5.0, "tv": 45.15, "trd": NaN, "batb": [[0, 1.01, 25]], "batl": NaN}, {"timestamp": 1631443756536, "ltp": 5.0, "tv": 45.15, "trd": NaN, "batb": [[0, 1.02, 15.37], [1, 1.01, 25]], "batl": NaN}, {"timestamp": 1631444490817, "ltp": 5.0, "tv": 45.15, "trd": NaN, "batb": [[1, 1.01, 30]], "batl": NaN}, {"timestamp": 1631445597107, "ltp": 5.0, "tv": 45.15, "trd": NaN, "batb": [[0, 1.01, 30], [1, 1.01, 0]], "batl": NaN}, {"timestamp": 1631446203825, "ltp": 5.0, "tv": 45.15, "trd": NaN, "batb": [[0, 3.75, 13.87], [1, 1.01, 30]], "batl": NaN}, {"timestamp": 1631448229352, "ltp": 5.0, "tv": 45.15, "trd": NaN, "batb": [[0, 4, 12.71]], "batl": NaN}, {"timestamp": 1631448254608, "ltp": 4.6, "tv": 52.97, "trd": [[4.6, 7.82]], "batb": [[0, 5, 2.18]], "batl": NaN}, {"timestamp": 1631448259715, "ltp": 4.6, "tv": 52.97, "trd": NaN, "batb": [[0, 5, 10]], "batl": NaN}, {"timestamp": 1631448435552, "ltp": 7.0, "tv": 71.03, "trd": [[6.6, 5.2], [7, 12.86]], "batb": NaN, "batl": NaN}, {"timestamp": 1631448436621, "ltp": 7.0, "tv": 89.09, "trd": [[7, 30.92]], "batb": [[0, 5, 11.27]], "batl": [[0, 7.2, 17.55], [1, 95, 48.37], [2, 990, 2.2]]}, {"timestamp": 1631448441844, "ltp": 7.0, "tv": 89.09, "trd": NaN, "batb": NaN, "batl": [[0, 95, 48.37], [1, 990, 2.2], [2, 990, 0]]}, {"timestamp": 1631448618920, "ltp": 7.0, "tv": 89.09, "trd": NaN, "batb": [[0, 5.5, 10.02]], "batl": NaN}, {"timestamp": 1631448644274, "ltp": 7.0, "tv": 89.09, "trd": NaN, "batb": [[0, 6, 10]], "batl": NaN}, {"timestamp": 1631448684723, "ltp": 7.0, "tv": 89.09, "trd": NaN, "batb": [[0, 5.5, 10.02]], "batl": NaN}, {"timestamp": 1631449675509, "ltp": 7.0, "tv": 89.09, "trd": NaN, "batb": [[0, 7.6, 51.45], [1, 5.5, 10.02], [2, 1.01, 30]], "batl": NaN}, {"timestamp": 1631449800605, "ltp": 7.0, "tv": 89.09, "trd": NaN, "batb": [[1, 7.2, 4.13], [2, 5.5, 10.02]], "batl": NaN}, {"timestamp": 1631452661281, "ltp": 7.0, "tv": 89.09, "trd": NaN, "batb": [[2, 1.01, 30]], "batl": NaN}, {"timestamp": 1631452662190, "ltp": 7.0, "tv": 89.09, "trd": NaN, "batb": [[1, 7.4, 4.01], [2, 7.2, 4.13]], "batl": NaN}, {"timestamp": 1631452667192, "ltp": 7.0, "tv": 89.09, "trd": NaN, "batb": [[1, 7.2, 4.13], [2, 5.5, 10.02]], "batl": NaN}, {"timestamp": 1631452747132, "ltp": 7.0, "tv": 89.09, "trd": NaN, "batb": [[2, 6.4, 10]], "batl": NaN}, {"timestamp": 1631452749332, "ltp": 7.0, "tv": 89.09, "trd": NaN, "batb": [[1, 7.4, 4.01], [2, 7.2, 4.13]], "batl": NaN}, {"timestamp": 1631452774368, "ltp": 7.0, "tv": 89.09, "trd": NaN, "batb": [[1, 6.4, 10], [2, 1.01, 30]], "batl": NaN}, {"timestamp": 1631452775258, "ltp": 7.0, "tv": 89.09, "trd": NaN, "batb": [[1, 7.4, 4.01], [2, 6.4, 10]], "batl": NaN}, {"timestamp": 1631452843222, "ltp": 7.0, "tv": 89.09, "trd": NaN, "batb": [[1, 6.4, 10], [2, 5.7, 31.91]], "batl": NaN}, {"timestamp": 1631452844311, "ltp": 7.0, "tv": 89.09, "trd": NaN, "batb": [[1, 7.4, 4.01], [2, 6.4, 10]], "batl": NaN}, {"timestamp": 1631452938749, "ltp": 7.6, "tv": 90.62, "trd": [[7.6, 1.53]], "batb": [[0, 7.6, 49.92]], "batl": NaN}, {"timestamp": 1631452949359, "ltp": 7.6, "tv": 90.62, "trd": NaN, "batb": NaN, "batl": [[0, 14, 7.23], [1, 95, 48.37], [2, 990, 2.2]]}, {"timestamp": 1631452955325, "ltp": 8.0, "tv": 94.86, "trd": [[8, 4.24]], "batb": NaN, "batl": [[0, 8, 12.6], [1, 14, 7.23], [2, 95, 48.37]]}, {"timestamp": 1631453247640, "ltp": 8.0, "tv": 107.46, "trd": [[8, 16.84]], "batb": [[0, 8.2, 3.56], [1, 7.6, 49.92], [2, 7.4, 4.01]], "batl": [[0, 14, 7.23], [1, 95, 48.37], [2, 990, 2.2]]}, {"timestamp": 1631453247947, "ltp": 8.0, "tv": 107.46, "trd": NaN, "batb": [[1, 7.8, 2.66], [2, 7.6, 49.92]], "batl": NaN}, {"timestamp": 1631453279493, "ltp": 8.0, "tv": 107.46, "trd": NaN, "batb": [[1, 8, 42.17], [2, 7.8, 2.66]], "batl": NaN}, {"timestamp": 1631453395139, "ltp": 8.0, "tv": 107.46, "trd": NaN, "batb": NaN, "batl": [[0, 10.5, 2], [1, 14, 7.23], [2, 95, 48.37]]}, {"timestamp": 1631453610299, "ltp": 8.0, "tv": 107.46, "trd": NaN, "batb": [[0, 8.4, 2.66]], "batl": NaN}, {"timestamp": 1631453612791, "ltp": 8.0, "tv": 107.46, "trd": NaN, "batb": [[1, 8, 45.84]], "batl": NaN}, {"timestamp": 1631456549654, "ltp": 8.0, "tv": 107.46, "trd": NaN, "batb": NaN, "batl": [[1, 95, 48.37], [2, 990, 2.2]]}, {"timestamp": 1631456550257, "ltp": 8.0, "tv": 107.46, "trd": NaN, "batb": NaN, "batl": [[1, 16, 7.23], [2, 95, 48.37]]}, {"timestamp": 1631457090364, "ltp": 8.0, "tv": 107.46, "trd": NaN, "batb": [[0, 8.6, 34], [1, 8.4, 2.66], [2, 8, 45.84]], "batl": NaN}, {"timestamp": 1631457304849, "ltp": 8.0, "tv": 107.46, "trd": NaN, "batb": [[2, 8, 3.66]], "batl": NaN}, {"timestamp": 1631457442690, "ltp": 8.0, "tv": 107.46, "trd": NaN, "batb": [[2, 8.2, 3.56]], "batl": NaN}, {"timestamp": 1631457454411, "ltp": 8.0, "tv": 107.46, "trd": NaN, "batb": [[0, 1.01, 30], [1, 8.4, 0], [2, 8.2, 0]], "batl": NaN}, {"timestamp": 1631457457623, "ltp": 8.0, "tv": 107.46, "trd": NaN, "batb": NaN, "batl": [[0, 11, 2]]}, {"timestamp": 1631457461302, "ltp": 8.0, "tv": 107.46, "trd": NaN, "batb": [[0, 1.8, 11.86], [1, 1.01, 502.85]], "batl": NaN}, {"timestamp": 1631457464531, "ltp": 8.0, "tv": 107.46, "trd": NaN, "batb": [[0, 2.2, 42.66], [1, 2, 11.86], [2, 1.8, 11.86]], "batl": NaN}, {"timestamp": 1631457467811, "ltp": 8.0, "tv": 107.46, "trd": NaN, "batb": [[0, 3, 5.93], [1, 2.6, 3.71], [2, 2.2, 42.66]], "batl": NaN}, {"timestamp": 1631457474434, "ltp": 8.0, "tv": 107.46, "trd": NaN, "batb": [[0, 7.6, 44.63], [1, 6.8, 57.7], [2, 3, 5.93]], "batl": NaN}, {"timestamp": 1631457475639, "ltp": 8.0, "tv": 107.46, "trd": NaN, "batb": NaN, "batl": [[0, 9, 2], [1, 11, 2]]}, {"timestamp": 1631457477649, "ltp": 8.0, "tv": 107.46, "trd": NaN, "batb": [[0, 8, 2], [1, 7.8, 2], [2, 7.6, 44.63]], "batl": [[1, 9.4, 2], [2, 11, 2]]}, {"timestamp": 1631457480657, "ltp": 8.0, "tv": 107.46, "trd": NaN, "batb": NaN, "batl": [[0, 8.2, 3], [1, 9, 2], [2, 9.4, 2]]}, {"timestamp": 1631457480922, "ltp": 8.0, "tv": 107.46, "trd": NaN, "batb": NaN, "batl": [[0, 9, 2], [1, 9.4, 2], [2, 11, 2]]}, {"timestamp": 1631457482658, "ltp": 8.0, "tv": 107.46, "trd": NaN, "batb": [[2, 6.8, 57.7]], "batl": NaN}, {"timestamp": 1631457489463, "ltp": 8.0, "tv": 107.46, "trd": NaN, "batb": [[1, 6.8, 57.7], [2, 3, 5.93]], "batl": NaN}, {"timestamp": 1631457492646, "ltp": 8.0, "tv": 107.46, "trd": NaN, "batb": [[1, 7.8, 2], [2, 6.8, 57.7]], "batl": NaN}, {"timestamp": 1631457498456, "ltp": 8.0, "tv": 107.46, "trd": NaN, "batb": NaN, "batl": [[0, 8.4, 1091.34], [1, 9.6, 2.24]]}, {"timestamp": 1631457499626, "ltp": 8.0, "tv": 107.46, "trd": NaN, "batb": [[0, 6.8, 57.7], [1, 6.2, 69.34], [2, 3, 5.93]], "batl": NaN}, {"timestamp": 1631457503473, "ltp": 8.0, "tv": 107.46, "trd": NaN, "batb": [[0, 6.8, 60.7], [1, 6.6, 2], [2, 6.2, 69.34]], "batl": [[0, 7.4, 12.05], [1, 8.2, 2], [2, 11, 2]]}, {"timestamp": 1631457503720, "ltp": 8.0, "tv": 107.46, "trd": NaN, "batb": NaN, "batl": [[0, 8.2, 2], [1, 11, 2], [2, 11, 0]]}, {"timestamp": 1631457506658, "ltp": 8.0, "tv": 107.46, "trd": NaN, "batb": [[0, 6.8, 3], [2, 6.2, 69.17]], "batl": [[0, 11, 2], [1, 11, 0]]}, {"timestamp": 1631457509664, "ltp": 8.0, "tv": 107.46, "trd": NaN, "batb": [[0, 7.2, 3], [1, 6.8, 3], [2, 6.6, 2]], "batl": NaN}, {"timestamp": 1631457512869, "ltp": 8.0, "tv": 107.46, "trd": NaN, "batb": [[1, 7, 2], [2, 6.8, 3]], "batl": NaN}, {"timestamp": 1631457521007, "ltp": 8.0, "tv": 107.46, "trd": NaN, "batb": [[2, 6.2, 69.17]], "batl": NaN}, {"timestamp": 1631457527619, "ltp": 8.0, "tv": 107.46, "trd": NaN, "batb": NaN, "batl": [[0, 9.4, 2], [1, 11, 2]]}, {"timestamp": 1631457528480, "ltp": 6.8, "tv": 121.43, "trd": [[6.8, 5.71], [7.2, 8.26]], "batb": [[0, 6.2, 69.17], [1, 5.9, 80.56], [2, 3, 5.93]], "batl": NaN}, {"timestamp": 1631457531497, "ltp": 6.8, "tv": 121.43, "trd": NaN, "batb": [[0, 6.8, 2], [1, 6.6, 3], [2, 6.2, 69.17]], "batl": NaN}, {"timestamp": 1631457535129, "ltp": 6.8, "tv": 121.43, "trd": NaN, "batb": [[0, 6.6, 3], [1, 5.9, 80.22], [2, 3, 5.93]], "batl": NaN}, {"timestamp": 1631457538336, "ltp": 6.8, "tv": 121.43, "trd": NaN, "batb": [[1, 6.4, 2], [2, 5.9, 80.22]], "batl": NaN}, {"timestamp": 1631457547352, "ltp": 6.8, "tv": 121.43, "trd": NaN, "batb": NaN, "batl": [[1, 11, 0]]}, {"timestamp": 1631457548638, "ltp": 6.8, "tv": 121.43, "trd": NaN, "batb": [[0, 6.8, 58.78], [1, 6.6, 3], [2, 6.4, 2]], "batl": NaN}, {"timestamp": 1631457551663, "ltp": 6.8, "tv": 121.43, "trd": NaN, "batb": [[0, 6.8, 60.78], [2, 6.2, 72.27]], "batl": NaN}, {"timestamp": 1631457552353, "ltp": 6.8, "tv": 121.43, "trd": NaN, "batb": [[1, 6.2, 72.27], [2, 3, 5.93]], "batl": NaN}, {"timestamp": 1631457554979, "ltp": 6.8, "tv": 121.43, "trd": NaN, "batb": [[1, 6.6, 3], [2, 6.2, 72.27]], "batl": NaN}, {"timestamp": 1631457563549, "ltp": 6.8, "tv": 121.43, "trd": NaN, "batb": [[0, 6.8, 2]], "batl": NaN}, {"timestamp": 1631457563764, "ltp": 6.8, "tv": 121.43, "trd": NaN, "batb": [[0, 6.2, 72.27], [1, 3, 5.93], [2, 2.6, 3.71]], "batl": NaN}, {"timestamp": 1631457565871, "ltp": 6.8, "tv": 123.9, "trd": [[6.8, 8.19]], "batb": NaN, "batl": [[0, 9.4, 2.28]]}, {"timestamp": 1631457566952, "ltp": 6.8, "tv": 123.9, "trd": NaN, "batb": [[0, 6.2, 74.27], [1, 6, 2], [2, 3, 5.93]], "batl": NaN}, {"timestamp": 1631457569399, "ltp": 6.8, "tv": 124.18, "trd": [[6.8, 8.47]], "batb": NaN, "batl": [[0, 9.4, 2]]}, {"timestamp": 1631457582692, "ltp": 6.8, "tv": 124.18, "trd": NaN, "batb": [[1, 3, 5.93], [2, 2.6, 3.71]], "batl": NaN}, {"timestamp": 1631457585922, "ltp": 6.8, "tv": 124.18, "trd": NaN, "batb": [[1, 6, 2], [2, 3, 5.93]], "batl": NaN}, {"timestamp": 1631457591581, "ltp": 6.8, "tv": 124.18, "trd": NaN, "batb": NaN, "batl": [[0, 8.8, 3], [1, 9.4, 2]]}, {"timestamp": 1631457596653, "ltp": 6.8, "tv": 124.18, "trd": NaN, "batb": [[2, 5.4, 48.23]], "batl": NaN}, {"timestamp": 1631457598670, "ltp": 6.8, "tv": 124.18, "trd": NaN, "batb": [[1, 5.4, 48.23], [2, 3, 5.93]], "batl": NaN}, {"timestamp": 1631457601870, "ltp": 6.8, "tv": 124.18, "trd": NaN, "batb": [[0, 6.4, 3], [1, 6.2, 74.27], [2, 5.4, 48.23]], "batl": NaN}, {"timestamp": 1631457604157, "ltp": 6.8, "tv": 124.18, "trd": NaN, "batb": NaN, "batl": [[1, 9.4, 0]]}, {"timestamp": 1631457625186, "ltp": 6.8, "tv": 124.18, "trd": NaN, "batb": [[1, 6.2, 72.27]], "batl": NaN}, {"timestamp": 1631457628400, "ltp": 6.8, "tv": 124.18, "trd": NaN, "batb": [[1, 6.2, 75.27]], "batl": NaN}, {"timestamp": 1631457642508, "ltp": 6.8, "tv": 124.18, "trd": NaN, "batb": [[1, 6.2, 72.27]], "batl": NaN}, {"timestamp": 1631457643586, "ltp": 6.8, "tv": 124.18, "trd": NaN, "batb": [[0, 5.4, 48.23], [1, 3, 5.93], [2, 2.6, 3.71]], "batl": NaN}, {"timestamp": 1631457645628, "ltp": 6.8, "tv": 124.18, "trd": NaN, "batb": [[0, 6.2, 2], [1, 5.4, 48.23], [2, 3, 5.93]], "batl": NaN}, {"timestamp": 1631457645917, "ltp": 6.8, "tv": 124.18, "trd": NaN, "batb": [[0, 5.4, 48.23], [1, 3, 5.93], [2, 2.6, 3.71]], "batl": NaN}, {"timestamp": 1631457646832, "ltp": 6.8, "tv": 124.18, "trd": NaN, "batb": [[0, 5.7, 2], [1, 5.6, 2], [2, 5.4, 48.23]], "batl": NaN}, {"timestamp": 1631457648622, "ltp": 6.8, "tv": 124.18, "trd": NaN, "batb": NaN, "batl": [[0, 7.6, 190.93], [1, 8.8, 3]]}, {"timestamp": 1631457648915, "ltp": 6.8, "tv": 124.18, "trd": NaN, "batb": NaN, "batl": [[0, 8.8, 3], [1, 8.8, 0]]}, {"timestamp": 1631457659537, "ltp": 6.8, "tv": 124.18, "trd": NaN, "batb": [[1, 5.4, 48.23], [2, 4.7, 66.57]], "batl": NaN}, {"timestamp": 1631457662525, "ltp": 6.8, "tv": 124.18, "trd": NaN, "batb": NaN, "batl": [[0, 7.8, 3], [1, 8.8, 3]]}, {"timestamp": 1631457663246, "ltp": 6.8, "tv": 124.18, "trd": NaN, "batb": [[1, 5.6, 3], [2, 5.4, 48.23]], "batl": NaN}, {"timestamp": 1631457665637, "ltp": 6.8, "tv": 124.18, "trd": NaN, "batb": [[0, 5.8, 2], [1, 5.7, 2], [2, 5.6, 3]], "batl": NaN}, {"timestamp": 1631457666455, "ltp": 6.8, "tv": 124.18, "trd": NaN, "batb": [[0, 5.9, 2], [1, 5.8, 2], [2, 5.7, 2]], "batl": NaN}, {"timestamp": 1631457669462, "ltp": 6.8, "tv": 124.18, "trd": NaN, "batb": [[0, 6.2, 2], [1, 6, 3], [2, 5.9, 2]], "batl": NaN}, {"timestamp": 1631457669946, "ltp": 6.8, "tv": 124.18, "trd": NaN, "batb": [[0, 4.7, 66.4], [1, 3, 5.93], [2, 2.6, 3.71]], "batl": NaN}, {"timestamp": 1631457673245, "ltp": 6.8, "tv": 124.18, "trd": NaN, "batb": NaN, "batl": [[0, 7.4, 2]]}, {"timestamp": 1631457694489, "ltp": 5.7, "tv": 141.16, "trd": [[5.7, 16.98]], "batb": NaN, "batl": NaN}, {"timestamp": 1631457695599, "ltp": 5.7, "tv": 141.16, "trd": NaN, "batb": [[0, 4.1, 90.35]], "batl": NaN}, {"timestamp": 1631457697304, "ltp": 5.7, "tv": 141.16, "trd": NaN, "batb": [[0, 4.7, 2], [1, 4.6, 3], [2, 4.1, 90.35]], "batl": NaN}, {"timestamp": 1631457698901, "ltp": 5.7, "tv": 141.16, "trd": NaN, "batb": [[2, 4.1, 93.35]], "batl": NaN}, {"timestamp": 1631457705376, "ltp": 5.7, "tv": 141.16, "trd": NaN, "batb": [[0, 4.1, 90.35], [1, 3.8, 56.52], [2, 2.6, 3.71]], "batl": NaN}, {"timestamp": 1631457713599, "ltp": 5.7, "tv": 141.16, "trd": NaN, "batb": [[0, 3.8, 56.52], [1, 2.6, 3.71], [2, 2.2, 42.66]], "batl": NaN}, {"timestamp": 1631457714509, "ltp": 4.7, "tv": 143.16, "trd": [[4.7, 2]], "batb": NaN, "batl": NaN}, {"timestamp": 1631457727634, "ltp": 4.7, "tv": 143.16, "trd": NaN, "batb": [[0, 4.4, 77.04], [1, 3.9, 105.43], [2, 3.8, 56.52]], "batl": NaN}, {"timestamp": 1631457727966, "ltp": 4.7, "tv": 143.16, "trd": NaN, "batb": [[2, 2.6, 3.71]], "batl": NaN}, {"timestamp": 1631457729450, "ltp": 4.7, "tv": 143.16, "trd": NaN, "batb": [[0, 3.9, 105.43], [1, 2.6, 3.71], [2, 2.2, 42.66]], "batl": NaN}, {"timestamp": 1631457731653, "ltp": 4.7, "tv": 143.16, "trd": NaN, "batb": NaN, "batl": [[0, 4.8, 12.1]]}, {"timestamp": 1631457740462, "ltp": 4.7, "tv": 143.16, "trd": NaN, "batb": [[1, 3.55, 65.65], [2, 2.6, 3.71]], "batl": NaN}, {"timestamp": 1631457741543, "ltp": 4.7, "tv": 143.16, "trd": NaN, "batb": NaN, "batl": [[0, 5.5, 116.95]]}, {"timestamp": 1631457744695, "ltp": 4.7, "tv": 143.16, "trd": NaN, "batb": [[2, 2.42, 388.03]], "batl": NaN}, {"timestamp": 1631457752485, "ltp": 4.7, "tv": 143.16, "trd": NaN, "batb": [[2, 2.2, 42.66]], "batl": NaN}, {"timestamp": 1631457770927, "ltp": 4.7, "tv": 143.16, "trd": NaN, "batb": [[0, 3.55, 65.65], [1, 2.2, 42.66], [2, 2, 11.86]], "batl": NaN}, {"timestamp": 1631457773626, "ltp": 4.7, "tv": 143.16, "trd": NaN, "batb": [[0, 3.6, 65.32], [1, 3.55, 65.65], [2, 2.2, 42.66]], "batl": NaN}, {"timestamp": 1631457773950, "ltp": 4.7, "tv": 143.16, "trd": NaN, "batb": [[1, 2.2, 42.66], [2, 2, 11.86]], "batl": NaN}, {"timestamp": 1631457789460, "ltp": 4.7, "tv": 143.16, "trd": NaN, "batb": [[0, 4.3, 81.64], [1, 3.9, 105.68], [2, 3.6, 65.32]], "batl": NaN}, {"timestamp": 1631457789788, "ltp": 4.7, "tv": 143.16, "trd": NaN, "batb": [[2, 2.2, 42.66]], "batl": NaN}, {"timestamp": 1631457791607, "ltp": 4.7, "tv": 143.16, "trd": NaN, "batb": [[2, 2.6, 3.71]], "batl": [[0, 6, 107.93]]}, {"timestamp": 1631457798176, "ltp": 4.7, "tv": 143.16, "trd": NaN, "batb": [[0, 3.9, 105.68], [1, 2.6, 3.71], [2, 2.52, 387.74]], "batl": NaN}, {"timestamp": 1631457821548, "ltp": 3.9, "tv": 143.91, "trd": [[3.9, 0.75]], "batb": [[0, 3.9, 104.93]], "batl": NaN}, {"timestamp": 1631457822528, "ltp": 3.9, "tv": 143.91, "trd": NaN, "batb": [[0, 4.9, 62.38], [1, 4.4, 79.13], [2, 3.9, 104.93]], "batl": NaN}, {"timestamp": 1631457822847, "ltp": 3.9, "tv": 143.91, "trd": NaN, "batb": [[2, 2.6, 3.71]], "batl": NaN}, {"timestamp": 1631457833131, "ltp": 3.9, "tv": 143.91, "trd": NaN, "batb": [[0, 4.4, 79.13], [1, 2.6, 3.71], [2, 2.52, 387.74]], "batl": NaN}, {"timestamp": 1631457835552, "ltp": 3.9, "tv": 143.91, "trd": NaN, "batb": NaN, "batl": [[0, 4.8, 50], [1, 6, 107.93]]}, {"timestamp": 1631457839733, "ltp": 3.9, "tv": 143.91, "trd": NaN, "batb": NaN, "batl": [[0, 6, 107.93], [1, 6, 0]]}, {"timestamp": 1631457842160, "ltp": 6.0, "tv": 144.29, "trd": [[6, 0.38]], "batb": NaN, "batl": [[0, 6, 107.55]]}, {"timestamp": 1631457843472, "ltp": 6.0, "tv": 144.29, "trd": NaN, "batb": [[2, 2.2, 42.66]], "batl": NaN}, {"timestamp": 1631457846382, "ltp": 6.0, "tv": 144.29, "trd": NaN, "batb": [[0, 5.4, 48.99], [1, 5, 58.7], [2, 4.4, 79.13]], "batl": NaN}, {"timestamp": 1631457847472, "ltp": 6.0, "tv": 144.29, "trd": NaN, "batb": NaN, "batl": [[0, 7.8, 89.36]]}, {"timestamp": 1631457861865, "ltp": 6.0, "tv": 144.29, "trd": NaN, "batb": [[0, 5, 58.53], [1, 3, 5.93], [2, 2.8, 381.52]], "batl": NaN}, {"timestamp": 1631457864584, "ltp": 5.7, "tv": 146.86, "trd": [[5.7, 19.55]], "batb": NaN, "batl": NaN}, {"timestamp": 1631457873709, "ltp": 5.0, "tv": 146.98, "trd": [[5, 31.19]], "batb": [[0, 5, 58.41]], "batl": NaN}, {"timestamp": 1631457884628, "ltp": 5.0, "tv": 146.98, "trd": NaN, "batb": [[1, 4.5, 73.69], [2, 3, 5.93]], "batl": NaN}, {"timestamp": 1631457886520, "ltp": 5.0, "tv": 146.98, "trd": NaN, "batb": NaN, "batl": [[0, 7.2, 91.36]]}, {"timestamp": 1631457895432, "ltp": 5.0, "tv": 146.98, "trd": NaN, "batb": [[0, 4.5, 73.69], [1, 3, 5.93], [2, 2.8, 381.52]], "batl": NaN}, {"timestamp": 1631457915175, "ltp": 5.0, "tv": 146.98, "trd": NaN, "batb": [[0, 5.7, 44.72], [1, 4.9, 61.55], [2, 4.5, 73.69]], "batl": NaN}, {"timestamp": 1631457916550, "ltp": 5.0, "tv": 146.98, "trd": NaN, "batb": NaN, "batl": [[0, 8.6, 81.32]]}, {"timestamp": 1631457925888, "ltp": 5.7, "tv": 147.47, "trd": [[5.7, 20.04]], "batb": [[0, 5.7, 44.47]], "batl": NaN}, {"timestamp": 1631457926796, "ltp": 5.7, "tv": 147.47, "trd": NaN, "batb": [[2, 3, 5.93]], "batl": NaN}, {"timestamp": 1631457938653, "ltp": 5.7, "tv": 183.13, "trd": [[5.7, 51.36], [6, 4.72]], "batb": [[0, 5.7, 28.81]], "batl": NaN}, {"timestamp": 1631457941494, "ltp": 5.7, "tv": 183.13, "trd": NaN, "batb": [[1, 5.6, 45.3], [2, 4.9, 61.55]], "batl": NaN}, {"timestamp": 1631457941810, "ltp": 5.7, "tv": 183.13, "trd": NaN, "batb": [[0, 5.6, 45.3], [1, 4.8, 62.38], [2, 3, 5.93]], "batl": NaN}, {"timestamp": 1631457960040, "ltp": 5.6, "tv": 204.92, "trd": [[5.6, 21.79]], "batb": [[0, 5.6, 23.52]], "batl": NaN}, {"timestamp": 1631457964135, "ltp": 5.6, "tv": 204.92, "trd": NaN, "batb": [[0, 5.5, 46.14]], "batl": NaN}, {"timestamp": 1631458029750, "ltp": 5.6, "tv": 204.92, "trd": NaN, "batb": [[0, 4.8, 62.38], [1, 3, 5.93], [2, 2.6, 3.71]], "batl": NaN}, {"timestamp": 1631458041708, "ltp": 4.8, "tv": 205.45, "trd": [[4.8, 0.53]], "batb": [[0, 4.8, 61.86]], "batl": NaN}, {"timestamp": 1631458054954, "ltp": 4.8, "tv": 214.47, "trd": [[4.8, 9.55]], "batb": [[0, 4.8, 57.35]], "batl": NaN}, {"timestamp": 1631458057552, "ltp": 4.8, "tv": 214.47, "trd": NaN, "batb": [[1, 4.1, 89.35], [2, 3, 5.93]], "batl": NaN}, {"timestamp": 1631458059267, "ltp": 4.8, "tv": 214.47, "trd": NaN, "batb": NaN, "batl": [[0, 7.2, 91.74]]}, {"timestamp": 1631458072990, "ltp": 4.8, "tv": 214.47, "trd": NaN, "batb": [[0, 4.1, 89.01], [1, 3, 5.93], [2, 2.6, 3.71]], "batl": NaN}, {"timestamp": 1631458080469, "ltp": 4.8, "tv": 214.47, "trd": NaN, "batb": NaN, "batl": [[0, 4.8, 2.16]]}, {"timestamp": 1631458081285, "ltp": 4.8, "tv": 214.47, "trd": NaN, "batb": [[1, 2.6, 3.71], [2, 2.2, 42.66]], "batl": [[1, 6.6, 98.5]]}, {"timestamp": 1631458091426, "ltp": 4.8, "tv": 214.47, "trd": NaN, "batb": NaN, "batl": [[1, 6.6, 0]]}, {"timestamp": 1631458093573, "ltp": 4.1, "tv": 232.06, "trd": [[4.1, 17.59]], "batb": [[0, 4.1, 80.22], [1, 3.7, 59.37], [2, 2.6, 3.71]], "batl": NaN}, {"timestamp": 1631458095511, "ltp": 4.1, "tv": 232.06, "trd": NaN, "batb": NaN, "batl": [[1, 6, 106.05]]}, {"timestamp": 1631458105341, "ltp": 4.1, "tv": 232.06, "trd": NaN, "batb": [[0, 3.7, 59.37], [1, 2.6, 3.71], [2, 2.2, 42.66]], "batl": NaN}, {"timestamp": 1631458118960, "ltp": 4.1, "tv": 232.06, "trd": NaN, "batb": [[1, 2.2, 42.66], [2, 2, 11.86]], "batl": NaN}, {"timestamp": 1631458122791, "ltp": 4.1, "tv": 232.06, "trd": NaN, "batb": NaN, "batl": [[1, 6, 0]]}, {"timestamp": 1631458125080, "ltp": 4.1, "tv": 232.06, "trd": NaN, "batb": [[1, 3.35, 74.53], [2, 2.2, 42.66]], "batl": NaN}, {"timestamp": 1631458126460, "ltp": 4.1, "tv": 232.06, "trd": NaN, "batb": [[2, 2.38, 400.04]], "batl": [[1, 5.3, 119.17]]}, {"timestamp": 1631458132479, "ltp": 3.7, "tv": 235.98, "trd": [[3.7, 3.92]], "batb": [[0, 3.7, 55.45]], "batl": NaN}, {"timestamp": 1631458138500, "ltp": 3.7, "tv": 239.91, "trd": [[3.7, 7.85]], "batb": [[0, 3.7, 51.52]], "batl": NaN}, {"timestamp": 1631458139092, "ltp": 3.7, "tv": 239.91, "trd": NaN, "batb": [[0, 3.35, 74.53], [1, 2.38, 400.04], [2, 2.2, 42.66]], "batl": NaN}, {"timestamp": 1631458160412, "ltp": 3.35, "tv": 242.04, "trd": [[3.35, 2.13]], "batb": [[0, 3.35, 72.39]], "batl": NaN}, {"timestamp": 1631458174340, "ltp": 3.35, "tv": 242.04, "trd": NaN, "batb": NaN, "batl": [[1, 5.3, 0]]}, {"timestamp": 1631458176569, "ltp": 3.35, "tv": 242.04, "trd": NaN, "batb": [[1, 3.05, 95.71], [2, 2.38, 400.04]], "batl": NaN}, {"timestamp": 1631458178176, "ltp": 3.35, "tv": 242.04, "trd": NaN, "batb": NaN, "batl": [[1, 4.9, 124.71]]}, {"timestamp": 1631458189661, "ltp": 3.35, "tv": 242.04, "trd": NaN, "batb": [[0, 3.05, 95.71], [1, 2.38, 400.04], [2, 2.2, 42.66]], "batl": NaN}, {"timestamp": 1631458190404, "ltp": 3.35, "tv": 242.04, "trd": NaN, "batb": [[0, 3.75, 12], [1, 3.05, 95.71], [2, 2.38, 400.04]], "batl": NaN}, {"timestamp": 1631458206718, "ltp": 3.75, "tv": 254.04, "trd": [[3.75, 12]], "batb": [[0, 3.05, 95.71], [1, 2.38, 400.04], [2, 2.2, 42.66]], "batl": NaN}, {"timestamp": 1631458208908, "ltp": 4.2, "tv": 274.04, "trd": [[3.75, 27.31], [4.2, 4.69]], "batb": NaN, "batl": NaN}, {"timestamp": 1631458221836, "ltp": 4.2, "tv": 274.04, "trd": NaN, "batb": NaN, "batl": [[1, 4.9, 0]]}, {"timestamp": 1631458224437, "ltp": 4.2, "tv": 274.04, "trd": NaN, "batb": [[1, 2.82, 47.06], [2, 2.38, 400.04]], "batl": NaN}, {"timestamp": 1631458225532, "ltp": 4.2, "tv": 274.04, "trd": NaN, "batb": [[0, 3.05, 95.46]], "batl": [[0, 4.2, 146.16], [1, 4.8, 2.16]]}, {"timestamp": 1631458239644, "ltp": 4.2, "tv": 274.04, "trd": NaN, "batb": [[0, 2.82, 47.06], [1, 2.38, 400.04], [2, 2.2, 42.66]], "batl": NaN}, {"timestamp": 1631458239962, "ltp": 4.2, "tv": 274.04, "trd": NaN, "batb": [[2, 2, 11.86]], "batl": NaN}, {"timestamp": 1631458253242, "ltp": 4.2, "tv": 274.04, "trd": NaN, "batb": NaN, "batl": [[0, 4.8, 2.16], [1, 4.8, 0]]}, {"timestamp": 1631458255588, "ltp": 4.2, "tv": 274.04, "trd": NaN, "batb": [[0, 3.35, 74.36], [1, 3, 97.22], [2, 2.82, 47.06]], "batl": NaN}, {"timestamp": 1631458256283, "ltp": 4.2, "tv": 274.04, "trd": NaN, "batb": [[2, 2.38, 400.04]], "batl": NaN}, {"timestamp": 1631458257680, "ltp": 4.2, "tv": 274.04, "trd": NaN, "batb": NaN, "batl": [[1, 4.9, 124.71]]}, {"timestamp": 1631458267636, "ltp": 3.35, "tv": 284.71, "trd": [[3.35, 12.81]], "batb": [[0, 3.35, 63.69]], "batl": NaN}, {"timestamp": 1631458269757, "ltp": 3.35, "tv": 284.71, "trd": NaN, "batb": [[0, 3, 97.22], [1, 2.38, 400.04], [2, 2, 11.86]], "batl": NaN}, {"timestamp": 1631458272657, "ltp": 3.35, "tv": 284.71, "trd": NaN, "batb": [[1, 2.94, 105.09], [2, 2.38, 400.04]], "batl": NaN}, {"timestamp": 1631458272943, "ltp": 3.35, "tv": 284.71, "trd": NaN, "batb": [[0, 2.94, 105.09], [1, 2.38, 400.04], [2, 2, 11.86]], "batl": NaN}, {"timestamp": 1631458280331, "ltp": 3.35, "tv": 284.71, "trd": NaN, "batb": NaN, "batl": [[1, 4.9, 0]]}, {"timestamp": 1631458283433, "ltp": 3.35, "tv": 284.71, "trd": NaN, "batb": [[1, 2.66, 54.09], [2, 2.38, 400.04]], "batl": NaN}, {"timestamp": 1631458283962, "ltp": 3.35, "tv": 284.71, "trd": NaN, "batb": NaN, "batl": [[0, 4.2, 146.16], [1, 4.8, 2.16]]}, {"timestamp": 1631458291868, "ltp": 3.35, "tv": 284.71, "trd": NaN, "batb": [[0, 2.66, 54.09], [1, 2.38, 400.04], [2, 2, 11.86]], "batl": NaN}, {"timestamp": 1631458293350, "ltp": 3.35, "tv": 284.71, "trd": NaN, "batb": [[0, 2.66, 57.3]], "batl": NaN}, {"timestamp": 1631458295663, "ltp": 3.35, "tv": 284.71, "trd": NaN, "batb": [[0, 2.7, 53.17], [1, 2.66, 3.21], [2, 2.38, 400.04]], "batl": NaN}, {"timestamp": 1631458298574, "ltp": 3.35, "tv": 284.71, "trd": NaN, "batb": NaN, "batl": [[0, 2.94, 19.29], [1, 4.2, 146.16], [2, 4.8, 2.16]]}, {"timestamp": 1631458303304, "ltp": 3.35, "tv": 284.71, "trd": NaN, "batb": NaN, "batl": [[0, 4.2, 146.16], [1, 4.8, 2.16], [2, 4.8, 0]]}, {"timestamp": 1631458322825, "ltp": 3.35, "tv": 284.71, "trd": NaN, "batb": NaN, "batl": [[0, 4.8, 2.16], [1, 4.8, 0]]}, {"timestamp": 1631458326441, "ltp": 3.35, "tv": 284.71, "trd": NaN, "batb": [[0, 3.3, 79.72], [1, 2.9, 44.3], [2, 2.66, 3.21]], "batl": NaN}, {"timestamp": 1631458327136, "ltp": 3.35, "tv": 284.71, "trd": NaN, "batb": NaN, "batl": [[1, 4.9, 124.71]]}, {"timestamp": 1631458329543, "ltp": 3.35, "tv": 284.71, "trd": NaN, "batb": NaN, "batl": [[0, 3.75, 27.58], [1, 4.8, 2.16], [2, 4.9, 124.71]]}, {"timestamp": 1631458329747, "ltp": 3.35, "tv": 284.71, "trd": NaN, "batb": NaN, "batl": [[0, 4.8, 2.16], [1, 4.9, 124.71], [2, 4.9, 0]]}, {"timestamp": 1631458348563, "ltp": 3.35, "tv": 284.71, "trd": NaN, "batb": [[0, 2.9, 44.3], [1, 2.66, 3.21], [2, 2.38, 400.04]], "batl": NaN}, {"timestamp": 1631458355396, "ltp": 3.35, "tv": 284.71, "trd": NaN, "batb": NaN, "batl": [[2, 810, 0.07]]}, {"timestamp": 1631458356289, "ltp": 3.35, "tv": 284.71, "trd": NaN, "batb": NaN, "batl": [[1, 810, 0.07], [2, 810, 0]]}, {"timestamp": 1631458359199, "ltp": 3.35, "tv": 284.71, "trd": NaN, "batb": [[0, 3.8, 56.36], [1, 3.3, 80.05], [2, 2.66, 3.21]], "batl": NaN}, {"timestamp": 1631458360517, "ltp": 3.8, "tv": 370.12, "trd": [[3.8, 85.4]], "batb": [[0, 3.8, 13.65]], "batl": [[1, 5.5, 113.67], [2, 810, 0.07]]}, {"timestamp": 1631458379666, "ltp": 3.8, "tv": 370.12, "trd": NaN, "batb": [[0, 3.3, 80.05], [1, 2.66, 3.21], [2, 2.38, 400.04]], "batl": NaN}, {"timestamp": 1631458382572, "ltp": 3.8, "tv": 370.12, "trd": NaN, "batb": [[1, 3.25, 81.81], [2, 2.66, 3.21]], "batl": NaN}, {"timestamp": 1631458382952, "ltp": 3.8, "tv": 370.12, "trd": NaN, "batb": [[0, 3.25, 81.81], [1, 2.66, 3.21], [2, 2.38, 400.04]], "batl": NaN}, {"timestamp": 1631458395963, "ltp": 3.8, "tv": 370.12, "trd": NaN, "batb": [[2, 2.2, 42.66]], "batl": [[1, 810, 0.07], [2, 810, 0]]}, {"timestamp": 1631458397288, "ltp": 3.8, "tv": 370.12, "trd": NaN, "batb": [[0, 4.3, 80.89], [1, 3.8, 54.93], [2, 2.66, 3.21]], "batl": NaN}, {"timestamp": 1631458399596, "ltp": 3.8, "tv": 370.12, "trd": NaN, "batb": NaN, "batl": [[1, 6.6, 97.86], [2, 810, 0.07]]}, {"timestamp": 1631458403576, "ltp": 4.3, "tv": 371.42, "trd": [[4.3, 1.3]], "batb": [[0, 4.3, 80.24]], "batl": NaN}, {"timestamp": 1631458417240, "ltp": 4.8, "tv": 372.78, "trd": [[4.8, 10.91]], "batb": NaN, "batl": [[0, 4.8, 1.48]]}, {"timestamp": 1631458429822, "ltp": 4.3, "tv": 388.01, "trd": [[4.3, 16.53]], "batb": [[0, 4.3, 65.01]], "batl": NaN}, {"timestamp": 1631458519351, "ltp": 4.8, "tv": 390.97, "trd": [[4.8, 13.87]], "batb": [[0, 4.8, 1.24], [1, 4.3, 65.01], [2, 3.8, 54.93]], "batl": [[0, 6.6, 97.86], [1, 810, 0.07], [2, 810, 0]]}, {"timestamp": 1631458526980, "ltp": 4.8, "tv": 390.97, "trd": NaN, "batb": [[0, 4.3, 65.01], [1, 3.8, 54.93], [2, 2.66, 3.21]], "batl": NaN}, {"timestamp": 1631458527880, "ltp": 4.8, "tv": 390.97, "trd": NaN, "batb": [[0, 3.8, 54.93], [1, 2.66, 3.21], [2, 2.62, 380.45]], "batl": NaN}, {"timestamp": 1631458530061, "ltp": 4.8, "tv": 390.97, "trd": NaN, "batb": [[0, 4.9, 1.24], [1, 3.8, 54.93], [2, 2.66, 3.21]], "batl": NaN}, {"timestamp": 1631458538475, "ltp": 4.8, "tv": 390.97, "trd": NaN, "batb": NaN, "batl": [[0, 810, 0.07], [1, 810, 0]]}, {"timestamp": 1631458541575, "ltp": 4.8, "tv": 390.97, "trd": NaN, "batb": [[0, 4.9, 61.7], [1, 4.3, 83.4]], "batl": NaN}, {"timestamp": 1631458542277, "ltp": 4.8, "tv": 390.97, "trd": NaN, "batb": NaN, "batl": [[0, 7.8, 87.04], [1, 810, 0.07]]}, {"timestamp": 1631458545300, "ltp": 5.6, "tv": 391.53, "trd": [[5.6, 22.35]], "batb": NaN, "batl": NaN}, {"timestamp": 1631458548499, "ltp": 5.6, "tv": 391.53, "trd": NaN, "batb": [[2, 3, 5.93]], "batl": NaN}, {"timestamp": 1631458555524, "ltp": 5.6, "tv": 391.53, "trd": NaN, "batb": [[0, 4.9, 1.24]], "batl": NaN}, {"timestamp": 1631458566517, "ltp": 4.9, "tv": 394.01, "trd": [[4.9, 2.48]], "batb": [[0, 4.3, 83.4], [1, 2.66, 3.21], [2, 2.62, 380.45]], "batl": [[0, 810, 0.07], [1, 810, 0]]}, {"timestamp": 1631458567631, "ltp": 4.9, "tv": 394.01, "trd": NaN, "batb": [[1, 3.7, 58.37], [2, 2.66, 3.21]], "batl": NaN}, {"timestamp": 1631458569432, "ltp": 4.9, "tv": 394.01, "trd": NaN, "batb": NaN, "batl": [[0, 6.6, 97.86], [1, 810, 0.07]]}, {"timestamp": 1631458571402, "ltp": 4.9, "tv": 394.67, "trd": [[4.9, 3.13]], "batb": NaN, "batl": NaN}, {"timestamp": 1631458579977, "ltp": 4.9, "tv": 394.67, "trd": NaN, "batb": [[0, 3.7, 58.37], [1, 2.66, 3.21], [2, 2.62, 380.45]], "batl": NaN}, {"timestamp": 1631458583194, "ltp": 4.9, "tv": 394.67, "trd": NaN, "batb": [[0, 3.75, 57.86]], "batl": NaN}, {"timestamp": 1631458587293, "ltp": 4.9, "tv": 394.67, "trd": NaN, "batb": [[0, 4.9, 60.04], [1, 4.2, 84.99], [2, 2.66, 3.21]], "batl": NaN}, {"timestamp": 1631458589993, "ltp": 4.9, "tv": 398.8, "trd": [[4.9, 7.27]], "batb": [[0, 4.9, 57.97]], "batl": NaN}, {"timestamp": 1631458598822, "ltp": 4.9, "tv": 398.8, "trd": NaN, "batb": [[0, 4.2, 84.99], [1, 2.66, 3.21], [2, 2.62, 380.45]], "batl": NaN}, {"timestamp": 1631458608151, "ltp": 4.9, "tv": 398.8, "trd": NaN, "batb": [[2, 2.6, 3.71]], "batl": [[0, 810, 0.07], [1, 810, 0]]}, {"timestamp": 1631458611642, "ltp": 4.9, "tv": 398.8, "trd": NaN, "batb": [[0, 5.6, 44.97], [1, 5, 57.61], [2, 4.2, 84.99]], "batl": NaN}, {"timestamp": 1631458611845, "ltp": 4.9, "tv": 398.8, "trd": NaN, "batb": NaN, "batl": [[0, 8.6, 81.16], [1, 810, 0.07]]}, {"timestamp": 1631458625468, "ltp": 4.9, "tv": 398.8, "trd": NaN, "batb": [[0, 5, 57.61], [1, 4.2, 84.99], [2, 3, 5.93]], "batl": NaN}, {"timestamp": 1631458626364, "ltp": 4.9, "tv": 398.8, "trd": NaN, "batb": [[1, 3, 5.93], [2, 2.9, 377.47]], "batl": NaN}, {"timestamp": 1631458642481, "ltp": 4.9, "tv": 398.8, "trd": NaN, "batb": NaN, "batl": [[0, 810, 0.07], [1, 810, 0]]}, {"timestamp": 1631458644282, "ltp": 5.7, "tv": 420.03, "trd": [[5.7, 72.59]], "batb": NaN, "batl": NaN}, {"timestamp": 1631458645505, "ltp": 5.7, "tv": 420.03, "trd": NaN, "batb": [[1, 4.2, 85.92], [2, 3, 5.93]], "batl": NaN}, {"timestamp": 1631458646092, "ltp": 5.7, "tv": 420.03, "trd": NaN, "batb": NaN, "batl": [[0, 7.8, 87.04], [1, 810, 0.07]]}, {"timestamp": 1631458655495, "ltp": 5.0, "tv": 426.78, "trd": [[5, 37.94]], "batb": [[0, 5, 52.86]], "batl": NaN}, {"timestamp": 1631458656014, "ltp": 5.0, "tv": 426.78, "trd": NaN, "batb": NaN, "batl": [[1, 810, 0]]}, {"timestamp": 1631458659508, "ltp": 5.0, "tv": 431.59, "trd": [[5, 42.75]], "batb": [[0, 5, 50.46]], "batl": NaN}, {"timestamp": 1631458660534, "ltp": 5.0, "tv": 431.59, "trd": NaN, "batb": [[0, 4.2, 85.92], [1, 3, 5.93], [2, 2.9, 377.47]], "batl": NaN}, {"timestamp": 1631458663607, "ltp": 5.0, "tv": 431.59, "trd": NaN, "batb": NaN, "batl": [[0, 5.1, 3], [1, 7.8, 87.04]]}, {"timestamp": 1631458665418, "ltp": 5.0, "tv": 431.59, "trd": NaN, "batb": [[0, 4.4, 2], [1, 4.3, 2], [2, 4.2, 85.92]], "batl": [[0, 7, 3]]}, {"timestamp": 1631458667109, "ltp": 5.0, "tv": 431.59, "trd": NaN, "batb": NaN, "batl": [[1, 7.2, 91.22]]}, {"timestamp": 1631458668331, "ltp": 4.3, "tv": 435.59, "trd": [[4.3, 18.53], [4.4, 2]], "batb": [[0, 4.2, 85.92], [1, 3, 5.93], [2, 2.9, 377.47]], "batl": NaN}, {"timestamp": 1631458668711, "ltp": 4.3, "tv": 435.59, "trd": NaN, "batb": [[1, 2.9, 377.47], [2, 2.2, 42.66]], "batl": NaN}, {"timestamp": 1631458671538, "ltp": 4.3, "tv": 435.59, "trd": NaN, "batb": [[0, 4.2, 87.92], [1, 4.1, 2], [2, 2.9, 377.47]], "batl": NaN}, {"timestamp": 1631458690654, "ltp": 4.3, "tv": 435.59, "trd": NaN, "batb": NaN, "batl": [[0, 4.9, 1517.22], [1, 5.4, 6.5], [2, 7, 3]]}, {"timestamp": 1631458691654, "ltp": 4.3, "tv": 435.59, "trd": NaN, "batb": [[1, 2.9, 377.47], [2, 2.2, 42.66]], "batl": [[0, 7, 3], [1, 7.2, 91.22], [2, 7, 0]]}, {"timestamp": 1631458694109, "ltp": 4.3, "tv": 435.59, "trd": NaN, "batb": [[1, 4.1, 3], [2, 2.9, 377.47]], "batl": NaN}, {"timestamp": 1631458703286, "ltp": 4.3, "tv": 435.59, "trd": NaN, "batb": [[2, 3, 5.93]], "batl": NaN}, {"timestamp": 1631458710476, "ltp": 4.3, "tv": 435.59, "trd": NaN, "batb": [[0, 4.2, 85.92], [1, 3, 5.93], [2, 2.9, 377.47]], "batl": NaN}, {"timestamp": 1631458711325, "ltp": 4.3, "tv": 435.59, "trd": NaN, "batb": NaN, "batl": [[1, 7.2, 0]]}, {"timestamp": 1631458713506, "ltp": 5.0, "tv": 437.59, "trd": [[5, 44.75]], "batb": [[1, 3.9, 2], [2, 3.85, 3]], "batl": NaN}, {"timestamp": 1631458714412, "ltp": 5.2, "tv": 523.17, "trd": [[5.2, 85.58]], "batb": [[0, 4.9, 58.95], [1, 4.2, 85.92], [2, 3.9, 2]], "batl": NaN}, {"timestamp": 1631458715628, "ltp": 5.2, "tv": 523.17, "trd": NaN, "batb": NaN, "batl": [[1, 9.8, 74.69]]}, {"timestamp": 1631458720437, "ltp": 5.2, "tv": 523.17, "trd": NaN, "batb": [[2, 4.1, 53.81]], "batl": [[0, 5.9, 43], [1, 6, 45.28], [2, 6.2, 51.35]]}, {"timestamp": 1631458721614, "ltp": 5.2, "tv": 523.17, "trd": NaN, "batb": [[0, 4.7, 65.57], [1, 4.1, 53.81], [2, 4, 54.16]], "batl": NaN}, {"timestamp": 1631458723446, "ltp": 5.9, "tv": 524.2, "trd": [[5.9, 1.03]], "batb": NaN, "batl": [[0, 5.9, 42.49]]}, {"timestamp": 1631458725616, "ltp": 5.9, "tv": 524.2, "trd": NaN, "batb": [[1, 3.9, 2], [2, 3.85, 3]], "batl": NaN}, {"timestamp": 1631458726525, "ltp": 5.9, "tv": 524.2, "trd": NaN, "batb": [[2, 3, 5.93]], "batl": NaN}, {"timestamp": 1631458728540, "ltp": 5.9, "tv": 524.2, "trd": NaN, "batb": NaN, "batl": [[0, 6, 45.28], [1, 6.2, 51.35], [2, 6.2, 0]]}, {"timestamp": 1631458729518, "ltp": 6.0, "tv": 635.13, "trd": [[6, 115.65]], "batb": [[0, 5.5, 46.89]], "batl": [[0, 6.2, 51.35], [1, 6.2, 0]]}, {"timestamp": 1631458731440, "ltp": 6.0, "tv": 635.13, "trd": NaN, "batb": [[1, 4.8, 2], [2, 4.7, 2]], "batl": [[1, 11.5, 69.66]]}, {"timestamp": 1631458737654, "ltp": 6.0, "tv": 635.13, "trd": NaN, "batb": NaN, "batl": [[0, 11.5, 69.66], [1, 11.5, 0]]}, {"timestamp": 1631458741194, "ltp": 6.0, "tv": 635.13, "trd": NaN, "batb": [[0, 5.3, 51]], "batl": [[0, 9.4, 2], [1, 11.5, 69.66]]}, {"timestamp": 1631458743251, "ltp": 6.0, "tv": 635.13, "trd": NaN, "batb": [[2, 3.15, 375.55]], "batl": NaN}, {"timestamp": 1631458744658, "ltp": 6.0, "tv": 635.13, "trd": NaN, "batb": NaN, "batl": [[1, 11.5, 0]]}, {"timestamp": 1631458747592, "ltp": 7.2, "tv": 641.13, "trd": [[7.2, 14.26]], "batb": [[0, 7.2, 45.74], [1, 6.2, 69.92], [2, 5.4, 2]], "batl": NaN}, {"timestamp": 1631458749089, "ltp": 7.2, "tv": 641.13, "trd": NaN, "batb": NaN, "batl": [[1, 14, 62.31]]}, {"timestamp": 1631458752999, "ltp": 7.2, "tv": 641.13, "trd": NaN, "batb": NaN, "batl": [[0, 8.8, 30.45], [1, 9, 39.23], [2, 9.2, 44.41]]}, {"timestamp": 1631458759420, "ltp": 7.2, "tv": 647.13, "trd": [[7.2, 20.26]], "batb": [[0, 7.2, 42.73]], "batl": NaN}, {"timestamp": 1631458759937, "ltp": 7.2, "tv": 647.13, "trd": NaN, "batb": [[0, 6.2, 69.92], [1, 5.4, 2], [2, 5.3, 35.69]], "batl": NaN}, {"timestamp": 1631458763490, "ltp": 7.2, "tv": 647.13, "trd": NaN, "batb": [[1, 6, 72.18], [2, 5.4, 2]], "batl": NaN}, {"timestamp": 1631458764279, "ltp": 7.2, "tv": 647.13, "trd": NaN, "batb": [[0, 6, 72.18], [1, 5.4, 2], [2, 5.3, 35.69]], "batl": [[0, 9.4, 2], [1, 14, 62.31], [2, 9.2, 0]]}, {"timestamp": 1631458766241, "ltp": 7.2, "tv": 647.13, "trd": NaN, "batb": NaN, "batl": [[1, 14, 0]]}, {"timestamp": 1631458769197, "ltp": 7.2, "tv": 647.13, "trd": NaN, "batb": NaN, "batl": [[0, 9.2, 2], [1, 9.4, 2]]}, {"timestamp": 1631458770394, "ltp": 7.2, "tv": 647.13, "trd": NaN, "batb": NaN, "batl": [[2, 11.5, 69.66]]}, {"timestamp": 1631458772411, "ltp": 6.4, "tv": 648.1, "trd": [[6.4, 15.06]], "batb": NaN, "batl": NaN}, {"timestamp": 1631458773970, "ltp": 6.4, "tv": 648.1, "trd": NaN, "batb": NaN, "batl": [[0, 7.8, 29.77], [1, 8, 32.83], [2, 8.2, 34.92]]}, {"timestamp": 1631458780312, "ltp": 6.4, "tv": 648.1, "trd": NaN, "batb": NaN, "batl": [[0, 6.4, 3], [1, 7.8, 29.77], [2, 8, 32.83]]}, {"timestamp": 1631458784612, "ltp": 6.4, "tv": 656.1, "trd": [[6.4, 23.06]], "batb": [[0, 5.4, 2], [1, 5.1, 54.35], [2, 4.5, 39.78]], "batl": [[0, 7.8, 29.77], [1, 8, 32.83], [2, 8.2, 34.92]]}, {"timestamp": 1631458789220, "ltp": 6.4, "tv": 656.1, "trd": NaN, "batb": [[0, 5.1, 54.35], [1, 4.5, 39.78], [2, 4.4, 50.98]], "batl": NaN}, {"timestamp": 1631458792418, "ltp": 6.4, "tv": 656.1, "trd": NaN, "batb": [[0, 5.1, 57.35], [1, 5, 3], [2, 4.5, 39.78]], "batl": NaN}, {"timestamp": 1631458810328, "ltp": 6.4, "tv": 656.1, "trd": NaN, "batb": [[1, 4.5, 39.78], [2, 4.4, 50.98]], "batl": [[0, 12.5, 65.62], [1, 8, 0], [2, 8.2, 0]]}, {"timestamp": 1631458813525, "ltp": 6.4, "tv": 656.1, "trd": NaN, "batb": [[0, 5.1, 54.35], [1, 5, 2], [2, 4.5, 39.78]], "batl": NaN}, {"timestamp": 1631458814375, "ltp": 6.4, "tv": 656.1, "trd": NaN, "batb": [[1, 4.5, 39.78], [2, 4.4, 50.98]], "batl": NaN}, {"timestamp": 1631458815543, "ltp": 6.4, "tv": 656.1, "trd": NaN, "batb": NaN, "batl": [[0, 9.8, 74.69]]}, {"timestamp": 1631458816242, "ltp": 6.4, "tv": 656.1, "trd": NaN, "batb": NaN, "batl": [[0, 5.3, 3], [1, 5.5, 3], [2, 9.2, 2]]}, {"timestamp": 1631458818175, "ltp": 5.3, "tv": 657.4, "trd": [[5.3, 1.3]], "batb": NaN, "batl": [[0, 5.3, 2.35]]}, {"timestamp": 1631458820145, "ltp": 5.3, "tv": 657.4, "trd": NaN, "batb": NaN, "batl": [[2, 6.8, 30.54]]}, {"timestamp": 1631458827557, "ltp": 5.3, "tv": 659.26, "trd": [[5.3, 3.16]], "batb": NaN, "batl": [[0, 5.3, 1.42]]}, {"timestamp": 1631458827789, "ltp": 5.3, "tv": 659.26, "trd": NaN, "batb": NaN, "batl": [[1, 6.8, 30.54], [2, 7, 42.39]]}, {"timestamp": 1631458836081, "ltp": 5.3, "tv": 659.26, "trd": NaN, "batb": [[0, 4.2, 84.49], [1, 3.95, 55.45], [2, 3.9, 56.16]], "batl": [[0, 6.8, 30.54], [1, 7, 42.39], [2, 7.2, 46.07]]}, {"timestamp": 1631458839290, "ltp": 5.3, "tv": 659.26, "trd": NaN, "batb": [[0, 4.2, 87.49], [1, 4.1, 3], [2, 3.95, 55.45]], "batl": [[0, 6.8, 33.54]]}, {"timestamp": 1631458851912, "ltp": 5.3, "tv": 659.26, "trd": NaN, "batb": [[1, 3.95, 55.45], [2, 3.9, 56.16]], "batl": NaN}, {"timestamp": 1631458855035, "ltp": 5.3, "tv": 659.26, "trd": NaN, "batb": [[1, 4.1, 3], [2, 3.95, 55.45]], "batl": NaN}, {"timestamp": 1631458866660, "ltp": 5.3, "tv": 659.26, "trd": NaN, "batb": [[1, 3.95, 55.45], [2, 3.9, 56.16]], "batl": [[0, 6.8, 3], [1, 9.8, 74.69], [2, 7.2, 0]]}, {"timestamp": 1631458868059, "ltp": 5.3, "tv": 659.26, "trd": NaN, "batb": NaN, "batl": [[1, 9.8, 0]]}, {"timestamp": 1631458869476, "ltp": 5.3, "tv": 659.26, "trd": NaN, "batb": [[0, 4.2, 84.49]], "batl": NaN}, {"timestamp": 1631458872385, "ltp": 5.3, "tv": 659.26, "trd": NaN, "batb": NaN, "batl": [[0, 4.5, 3], [1, 6.6, 2], [2, 6.8, 3]]}, {"timestamp": 1631458874518, "ltp": 4.5, "tv": 660.9, "trd": [[4.5, 1.64]], "batb": NaN, "batl": [[0, 4.5, 2.18]]}, {"timestamp": 1631458876513, "ltp": 4.5, "tv": 660.9, "trd": NaN, "batb": [[0, 4.2, 192.96]], "batl": [[1, 5.3, 46.96], [2, 5.4, 39.3]]}, {"timestamp": 1631458878017, "ltp": 4.5, "tv": 660.9, "trd": NaN, "batb": NaN, "batl": [[1, 4.6, 114.44], [2, 5.3, 46.96]]}, {"timestamp": 1631458882107, "ltp": 4.5, "tv": 660.9, "trd": NaN, "batb": [[0, 3.6, 62.47], [1, 3.45, 61.95], [2, 3.4, 60.33]], "batl": [[0, 5.3, 46.96], [1, 5.4, 39.3], [2, 5.5, 52.21]]}, {"timestamp": 1631458882722, "ltp": 4.5, "tv": 660.9, "trd": NaN, "batb": [[0, 4.6, 2], [1, 3.6, 62.47], [2, 3.45, 61.95]], "batl": NaN}, {"timestamp": 1631458885629, "ltp": 4.5, "tv": 660.9, "trd": NaN, "batb": [[1, 3.6, 64.47], [2, 3.55, 3]], "batl": [[0, 6.6, 2], [1, 7.2, 91.22], [2, 5.5, 0]]}, {"timestamp": 1631458885902, "ltp": 4.5, "tv": 660.9, "trd": NaN, "batb": [[0, 3.6, 64.47], [1, 3.55, 3], [2, 3.45, 61.95]], "batl": NaN}, {"timestamp": 1631458888533, "ltp": 4.5, "tv": 660.9, "trd": NaN, "batb": [[0, 3.6, 62.47], [1, 3.45, 61.95], [2, 3.4, 60.33]], "batl": [[1, 7.2, 0]]}, {"timestamp": 1631458889484, "ltp": 4.5, "tv": 660.9, "trd": NaN, "batb": NaN, "batl": [[1, 1000, 0.07]]}, {"timestamp": 1631458889705, "ltp": 4.5, "tv": 660.9, "trd": NaN, "batb": NaN, "batl": [[1, 1000, 0]]}, {"timestamp": 1631458891638, "ltp": 4.5, "tv": 660.9, "trd": NaN, "batb": [[2, 3.4, 63.33]], "batl": [[0, 5.7, 3], [1, 6.6, 2]]}, {"timestamp": 1631458892243, "ltp": 4.5, "tv": 660.9, "trd": NaN, "batb": NaN, "batl": [[0, 3.85, 3], [1, 3.9, 2], [2, 5.7, 3]]}, {"timestamp": 1631458893416, "ltp": 4.5, "tv": 660.9, "trd": NaN, "batb": NaN, "batl": [[2, 4.6, 65.77]]}, {"timestamp": 1631458893745, "ltp": 4.5, "tv": 660.9, "trd": NaN, "batb": NaN, "batl": [[2, 5.7, 3]]}, {"timestamp": 1631458900532, "ltp": 4.5, "tv": 660.9, "trd": NaN, "batb": [[0, 3.6, 170.08]], "batl": NaN}, {"timestamp": 1631458903315, "ltp": 4.5, "tv": 660.9, "trd": NaN, "batb": NaN, "batl": [[1, 6, 104.94], [2, 810, 0.07]]}, {"timestamp": 1631458906547, "ltp": 4.5, "tv": 660.9, "trd": NaN, "batb": NaN, "batl": [[1, 3.9, 116.15], [2, 6, 104.94]]}, {"timestamp": 1631458907444, "ltp": 3.85, "tv": 664.9, "trd": [[3.85, 4]], "batb": NaN, "batl": [[0, 3.85, 1]]}, {"timestamp": 1631458910157, "ltp": 3.9, "tv": 666.99, "trd": [[3.85, 6], [3.9, 0.84]], "batb": NaN, "batl": [[0, 3.9, 116.11], [1, 6, 104.94], [2, 810, 0.07]]}, {"timestamp": 1631458913345, "ltp": 3.9, "tv": 666.99, "trd": NaN, "batb": NaN, "batl": [[0, 3.85, 2], [1, 3.9, 116.11], [2, 6, 104.94]]}, {"timestamp": 1631458917658, "ltp": 3.85, "tv": 668.99, "trd": [[3.85, 8]], "batb": NaN, "batl": [[0, 3.9, 116.11], [1, 6, 104.94], [2, 810, 0.07]]}, {"timestamp": 1631458921471, "ltp": 3.85, "tv": 668.99, "trd": NaN, "batb": [[0, 3.6, 62.47]], "batl": [[0, 6, 104.94], [1, 810, 0.07], [2, 810, 0]]}, {"timestamp": 1631458924660, "ltp": 3.85, "tv": 668.99, "trd": NaN, "batb": [[0, 3.65, 61.71], [1, 3.6, 62.47], [2, 3.45, 61.95]], "batl": NaN}, {"timestamp": 1631458925262, "ltp": 3.85, "tv": 668.99, "trd": NaN, "batb": [[1, 3.4, 3], [2, 3.35, 3]], "batl": NaN}, {"timestamp": 1631458927783, "ltp": 3.85, "tv": 670.99, "trd": [[3.85, 10]], "batb": NaN, "batl": NaN}, {"timestamp": 1631458936077, "ltp": 3.85, "tv": 670.99, "trd": NaN, "batb": [[2, 3.15, 88.26]], "batl": NaN}, {"timestamp": 1631458939578, "ltp": 3.85, "tv": 670.99, "trd": NaN, "batb": [[2, 3.35, 2]], "batl": NaN}, {"timestamp": 1631458942452, "ltp": 3.85, "tv": 670.99, "trd": NaN, "batb": NaN, "batl": [[0, 3.85, 3], [1, 6, 104.94], [2, 810, 0.07]]}, {"timestamp": 1631458966022, "ltp": 3.85, "tv": 670.99, "trd": NaN, "batb": [[2, 3.15, 88.26]], "batl": NaN}, {"timestamp": 1631458969169, "ltp": 3.85, "tv": 670.99, "trd": NaN, "batb": [[2, 3.35, 3]], "batl": NaN}, {"timestamp": 1631458975196, "ltp": 3.7, "tv": 705.15, "trd": [[3.7, 42.01]], "batb": NaN, "batl": NaN}, {"timestamp": 1631458978880, "ltp": 3.7, "tv": 705.15, "trd": NaN, "batb": [[2, 3.35, 7.27]], "batl": [[1, 4.4, 2.59], [2, 4.8, 2.17]]}, {"timestamp": 1631459009649, "ltp": 3.7, "tv": 705.15, "trd": NaN, "batb": [[0, 3.35, 7.27], [1, 3.2, 4.02], [2, 3.15, 88.26]], "batl": [[0, 4.4, 2.59], [1, 4.8, 2.17], [2, 6, 104.94]]}, {"timestamp": 1631459010039, "ltp": 3.7, "tv": 705.15, "trd": NaN, "batb": [[0, 3.35, 3]], "batl": [[0, 4.8, 2.17], [1, 6, 104.94], [2, 810, 0.07]]}, {"timestamp": 1631459013661, "ltp": 3.7, "tv": 705.15, "trd": NaN, "batb": [[1, 3.3, 3], [2, 3.2, 4.02]], "batl": [[0, 4.4, 3], [1, 4.5, 3], [2, 4.8, 2.17]]}, {"timestamp": 1631459019545, "ltp": 3.7, "tv": 705.15, "trd": NaN, "batb": [[0, 4, 94.88], [1, 3.55, 64.65], [2, 3.35, 3]], "batl": NaN}, {"timestamp": 1631459020044, "ltp": 3.7, "tv": 705.15, "trd": NaN, "batb": [[2, 3.4, 3]], "batl": [[0, 4.3, 2], [1, 4.4, 3], [2, 4.5, 3]]}, {"timestamp": 1631459023245, "ltp": 4.3, "tv": 706.88, "trd": [[4.3, 20.27]], "batb": NaN, "batl": [[0, 4.3, 1.13]]}, {"timestamp": 1631459025558, "ltp": 4.3, "tv": 706.88, "trd": NaN, "batb": [[2, 3.45, 64.65]], "batl": [[1, 4.7, 46.22], [2, 4.8, 47.68]]}, {"timestamp": 1631459026244, "ltp": 4.3, "tv": 706.88, "trd": NaN, "batb": [[1, 3.75, 2.71], [2, 3.55, 68.04]], "batl": [[0, 4.5, 2.31]]}, {"timestamp": 1631459028773, "ltp": 4.3, "tv": 706.88, "trd": NaN, "batb": NaN, "batl": [[1, 4.6, 3], [2, 4.7, 46.22]]}, {"timestamp": 1631459031597, "ltp": 4.3, "tv": 706.88, "trd": NaN, "batb": NaN, "batl": [[1, 4.6, 5.41]]}, {"timestamp": 1631459033520, "ltp": 4.3, "tv": 706.88, "trd": NaN, "batb": NaN, "batl": [[0, 4.6, 2.41], [1, 4.7, 46.22], [2, 4.8, 47.68]]}, {"timestamp": 1631459034067, "ltp": 4.3, "tv": 706.88, "trd": NaN, "batb": [[0, 3.55, 68.04], [1, 3.45, 64.65], [2, 3.4, 59.12]], "batl": [[0, 4.7, 46.22], [1, 4.8, 47.68], [2, 4.9, 50.59]]}, {"timestamp": 1631459037601, "ltp": 4.3, "tv": 706.88, "trd": NaN, "batb": [[0, 3.75, 3], [1, 3.7, 3], [2, 3.55, 71.04]], "batl": [[1, 4.8, 45.51]]}, {"timestamp": 1631459038184, "ltp": 4.3, "tv": 706.88, "trd": NaN, "batb": NaN, "batl": [[0, 4.7, 46.31]]}, {"timestamp": 1631459040441, "ltp": 4.1, "tv": 706.98, "trd": [[4.1, 17.68]], "batb": NaN, "batl": [[0, 4.7, 46.22]]}, {"timestamp": 1631459050310, "ltp": 4.1, "tv": 706.98, "trd": NaN, "batb": [[1, 3.55, 68.04], [2, 3.45, 64.65]], "batl": NaN}, {"timestamp": 1631459053521, "ltp": 4.1, "tv": 706.98, "trd": NaN, "batb": [[1, 3.7, 3], [2, 3.55, 68.04]], "batl": NaN}, {"timestamp": 1631459067827, "ltp": 4.1, "tv": 706.98, "trd": NaN, "batb": [[1, 3.55, 68.04], [2, 3.45, 64.65]], "batl": NaN}, {"timestamp": 1631459071045, "ltp": 4.1, "tv": 706.98, "trd": NaN, "batb": [[1, 3.7, 3], [2, 3.55, 68.04]], "batl": NaN}, {"timestamp": 1631459083063, "ltp": 4.1, "tv": 706.98, "trd": NaN, "batb": [[1, 3.55, 68.04], [2, 2.2, 42.66]], "batl": NaN}, {"timestamp": 1631459085374, "ltp": 4.1, "tv": 706.98, "trd": NaN, "batb": [[0, 4.6, 71.43], [1, 4, 94.12], [2, 3.75, 3]], "batl": NaN}, {"timestamp": 1631459086570, "ltp": 4.1, "tv": 706.98, "trd": NaN, "batb": [[2, 3.8, 2]], "batl": NaN}, {"timestamp": 1631459089216, "ltp": 4.7, "tv": 708.6, "trd": [[4.7, 3.62]], "batb": NaN, "batl": [[0, 4.7, 45.41]]}, {"timestamp": 1631459091183, "ltp": 4.7, "tv": 708.6, "trd": NaN, "batb": [[2, 3.85, 44.69]], "batl": NaN}, {"timestamp": 1631459096694, "ltp": 4.7, "tv": 711.35, "trd": [[4.7, 6.37]], "batb": NaN, "batl": [[0, 4.7, 44.03]]}, {"timestamp": 1631459099325, "ltp": 4.7, "tv": 711.35, "trd": NaN, "batb": [[0, 4, 94.12], [1, 3.85, 44.69], [2, 3.8, 63.66]], "batl": [[0, 5, 4.31], [1, 5.1, 45.26], [2, 5.2, 47.09]]}, {"timestamp": 1631459100622, "ltp": 5.0, "tv": 717.73, "trd": [[5, 51.12]], "batb": [[0, 4, 97.3]], "batl": [[0, 5.1, 45.26], [1, 5.2, 47.09], [2, 5.3, 63.29]]}, {"timestamp": 1631459102599, "ltp": 5.0, "tv": 720.18, "trd": [[5, 53.57]], "batb": [[0, 4, 100.3], [1, 3.95, 2], [2, 3.85, 44.69]], "batl": NaN}, {"timestamp": 1631459103609, "ltp": 5.0, "tv": 720.18, "trd": NaN, "batb": [[0, 4.2, 2.77], [1, 4, 100.3], [2, 3.95, 2]], "batl": [[0, 5.1, 48.26]]}, {"timestamp": 1631459104525, "ltp": 5.0, "tv": 720.18, "trd": NaN, "batb": [[0, 4, 100.3], [1, 3.95, 2], [2, 3.85, 44.69]], "batl": NaN}, {"timestamp": 1631459106510, "ltp": 5.0, "tv": 720.18, "trd": NaN, "batb": [[0, 4.2, 2], [1, 4.1, 3], [2, 4, 100.3]], "batl": NaN}, {"timestamp": 1631459107208, "ltp": 5.0, "tv": 720.18, "trd": NaN, "batb": [[0, 4.2, 5.62]], "batl": NaN}, {"timestamp": 1631459110523, "ltp": 5.0, "tv": 720.18, "trd": NaN, "batb": [[0, 4.2, 2]], "batl": NaN}, {"timestamp": 1631459114353, "ltp": 5.0, "tv": 720.18, "trd": NaN, "batb": [[2, 4, 97.3]], "batl": NaN}, {"timestamp": 1631459116177, "ltp": 5.0, "tv": 720.18, "trd": NaN, "batb": [[0, 4.2, 12]], "batl": [[0, 5, 31.38], [1, 5.1, 48.26], [2, 5.2, 47.09]]}, {"timestamp": 1631459119560, "ltp": 5.0, "tv": 720.18, "trd": NaN, "batb": [[1, 4, 97.3], [2, 3.85, 44.69]], "batl": NaN}, {"timestamp": 1631459122953, "ltp": 5.0, "tv": 720.18, "trd": NaN, "batb": [[1, 4.1, 3], [2, 4, 97.3]], "batl": NaN}, {"timestamp": 1631459124565, "ltp": 5.0, "tv": 720.18, "trd": NaN, "batb": [[0, 4.2, 15.57]], "batl": NaN}, {"timestamp": 1631459125655, "ltp": 5.0, "tv": 720.18, "trd": NaN, "batb": [[0, 4.2, 12]], "batl": [[0, 5.1, 3], [1, 7.8, 87.04], [2, 810, 0.07]]}, {"timestamp": 1631459127583, "ltp": 5.0, "tv": 720.18, "trd": NaN, "batb": [[0, 4, 97.3], [1, 3.85, 44.69], [2, 3.8, 61.66]], "batl": [[1, 810, 0.07], [2, 810, 0]]}, {"timestamp": 1631459129373, "ltp": 5.0, "tv": 720.18, "trd": NaN, "batb": NaN, "batl": [[0, 5, 15], [1, 5.1, 3], [2, 810, 0.07]]}, {"timestamp": 1631459130587, "ltp": 5.0, "tv": 720.18, "trd": NaN, "batb": NaN, "batl": [[0, 4.3, 2], [1, 5, 17], [2, 5.1, 3]]}, {"timestamp": 1631459131188, "ltp": 5.0, "tv": 720.18, "trd": NaN, "batb": NaN, "batl": [[1, 5, 2]]}, {"timestamp": 1631459133298, "ltp": 4.3, "tv": 721.88, "trd": [[4.3, 21.97]], "batb": NaN, "batl": [[0, 4.3, 1.15]]}, {"timestamp": 1631459134297, "ltp": 4.3, "tv": 721.88, "trd": NaN, "batb": NaN, "batl": [[0, 4.2, 5.75], [1, 4.3, 1.15], [2, 5, 2]]}, {"timestamp": 1631459135195, "ltp": 4.3, "tv": 721.88, "trd": NaN, "batb": NaN, "batl": [[2, 4.6, 2.11]]}, {"timestamp": 1631459146604, "ltp": 4.3, "tv": 721.88, "trd": NaN, "batb": [[0, 3.5, 67.83], [1, 3.4, 60.28], [2, 3.35, 59.63]], "batl": [[0, 4.8, 41.99], [1, 4.9, 49.89], [2, 5, 62.85]]}, {"timestamp": 1631459149620, "ltp": 4.3, "tv": 721.88, "trd": NaN, "batb": [[0, 3.6, 3], [1, 3.55, 3], [2, 3.5, 67.83]], "batl": [[1, 4.9, 52.24]]}, {"timestamp": 1631459150597, "ltp": 4.2, "tv": 725.45, "trd": [[4.2, 8.26]], "batb": [[2, 3.5, 70.83]], "batl": NaN}, {"timestamp": 1631459153625, "ltp": 4.2, "tv": 725.45, "trd": NaN, "batb": NaN, "batl": [[0, 4.6, 2.71], [1, 4.8, 41.99], [2, 4.9, 52.24]]}, {"timestamp": 1631459154603, "ltp": 4.2, "tv": 725.45, "trd": NaN, "batb": [[0, 4.6, 69.75], [1, 4.3, 11.88], [2, 4.1, 91]], "batl": [[0, 4.7, 39.52], [1, 4.8, 43.99]]}, {"timestamp": 1631459155038, "ltp": 4.2, "tv": 725.45, "trd": NaN, "batb": NaN, "batl": [[0, 4.8, 43.99], [1, 4.9, 52.24], [2, 5, 62.85]]}, {"timestamp": 1631459158551, "ltp": 4.2, "tv": 725.45, "trd": NaN, "batb": NaN, "batl": [[0, 4.8, 57.75]]}, {"timestamp": 1631459160360, "ltp": 4.2, "tv": 725.45, "trd": NaN, "batb": [[2, 4.1, 95.64]], "batl": [[2, 5, 64.85]]}, {"timestamp": 1631459173247, "ltp": 4.2, "tv": 725.45, "trd": NaN, "batb": [[2, 4.1, 95.33]], "batl": NaN}, {"timestamp": 1631459176054, "ltp": 4.2, "tv": 725.45, "trd": NaN, "batb": [[1, 4.5, 115.14], [2, 4.3, 11.88]], "batl": NaN}, {"timestamp": 1631459177634, "ltp": 4.2, "tv": 725.45, "trd": NaN, "batb": [[0, 4.1, 90.69], [1, 3.9, 59.84], [2, 3.85, 70.1]], "batl": [[0, 5, 2], [1, 5.1, 42.87], [2, 5.2, 48.01]]}, {"timestamp": 1631459181170, "ltp": 4.2, "tv": 725.45, "trd": NaN, "batb": [[0, 4.1, 93.69], [1, 4, 3], [2, 3.9, 59.84]], "batl": [[0, 5, 4]]}, {"timestamp": 1631459183646, "ltp": 4.2, "tv": 725.45, "trd": NaN, "batb": NaN, "batl": [[0, 4.8, 20.27], [1, 5, 4], [2, 5.1, 42.87]]}, {"timestamp": 1631459184361, "ltp": 4.2, "tv": 725.45, "trd": NaN, "batb": [[0, 4.2, 18.17], [1, 4.1, 98.23], [2, 4, 3]], "batl": [[0, 4.9, 2.45]]}, {"timestamp": 1631459187272, "ltp": 4.2, "tv": 725.45, "trd": NaN, "batb": NaN, "batl": [[0, 4.8, 19.65], [1, 4.9, 2.45], [2, 5, 4]]}, {"timestamp": 1631459190473, "ltp": 4.2, "tv": 725.45, "trd": NaN, "batb": [[1, 4.1, 93.69]], "batl": [[0, 5, 4], [1, 5.1, 42.87], [2, 5.2, 48.01]]}, {"timestamp": 1631459191710, "ltp": 4.2, "tv": 725.45, "trd": NaN, "batb": [[0, 4.1, 93.69], [1, 4, 3], [2, 3.9, 59.84]], "batl": NaN}, {"timestamp": 1631459193389, "ltp": 4.2, "tv": 725.45, "trd": NaN, "batb": [[1, 3.9, 59.84], [2, 3.85, 70.1]], "batl": [[0, 4.9, 2.35], [1, 5, 4], [2, 5.1, 42.87]]}, {"timestamp": 1631459194084, "ltp": 4.2, "tv": 725.45, "trd": NaN, "batb": [[0, 4.1, 98.13]], "batl": [[0, 5, 4], [1, 5.1, 42.87], [2, 5.2, 48.01]]}, {"timestamp": 1631459196181, "ltp": 4.2, "tv": 725.45, "trd": NaN, "batb": [[1, 4, 2], [2, 3.9, 59.84]], "batl": NaN}, {"timestamp": 1631459198897, "ltp": 4.2, "tv": 725.45, "trd": NaN, "batb": NaN, "batl": [[1, 7.8, 87.04], [2, 5.2, 0]]}, {"timestamp": 1631459200510, "ltp": 4.2, "tv": 725.45, "trd": NaN, "batb": NaN, "batl": [[0, 4.9, 2.45], [1, 5, 4]]}, {"timestamp": 1631459201201, "ltp": 4.2, "tv": 725.45, "trd": NaN, "batb": [[0, 4.1, 95.13], [1, 3.9, 59.84], [2, 3.85, 70.1]], "batl": [[0, 5, 4], [1, 5, 0]]}, {"timestamp": 1631459203490, "ltp": 4.2, "tv": 725.45, "trd": NaN, "batb": NaN, "batl": [[0, 4.9, 20], [1, 5, 4]]}, {"timestamp": 1631459204405, "ltp": 4.2, "tv": 725.45, "trd": NaN, "batb": NaN, "batl": [[0, 4.9, 3], [2, 7.2, 91.22]]}, {"timestamp": 1631459205274, "ltp": 4.2, "tv": 725.45, "trd": NaN, "batb": [[0, 4.1, 90.69]], "batl": [[0, 4.4, 3], [1, 4.9, 3], [2, 5, 4]]}, {"timestamp": 1631459206602, "ltp": 4.4, "tv": 728.73, "trd": [[4.4, 5.28]], "batb": NaN, "batl": [[0, 4.4, 1.36]]}, {"timestamp": 1631459208502, "ltp": 4.4, "tv": 728.73, "trd": NaN, "batb": NaN, "batl": [[0, 4.3, 3], [1, 4.4, 1.36], [2, 4.9, 3]]}, {"timestamp": 1631459211131, "ltp": 4.4, "tv": 728.73, "trd": NaN, "batb": NaN, "batl": [[0, 4.3, 9.8]]}, {"timestamp": 1631459216613, "ltp": 4.4, "tv": 728.73, "trd": NaN, "batb": [[1, 3.7, 5.42], [2, 3.5, 5.72]], "batl": [[0, 4.3, 3], [1, 5, 34.67], [2, 5.1, 49.18]]}, {"timestamp": 1631459217122, "ltp": 4.4, "tv": 728.73, "trd": NaN, "batb": [[0, 3.5, 5.72], [1, 3.45, 69.67], [2, 3.4, 46.14]], "batl": [[0, 5, 34.67], [1, 5.1, 49.18], [2, 5.2, 60.22]]}, {"timestamp": 1631459220335, "ltp": 4.3, "tv": 731.13, "trd": [[4.3, 24.36]], "batb": [[0, 3.7, 5.42], [1, 3.5, 8.4], [2, 3.45, 71.67]], "batl": [[0, 4.1, 135.38], [1, 5, 34.67], [2, 5.1, 49.18]]}, {"timestamp": 1631459220710, "ltp": 4.3, "tv": 731.13, "trd": NaN, "batb": [[0, 3.5, 8.4], [1, 3.45, 71.67], [2, 3.4, 46.14]], "batl": NaN}, {"timestamp": 1631459222935, "ltp": 4.1, "tv": 731.76, "trd": [[4.1, 18.31]], "batb": NaN, "batl": [[0, 4.1, 135.06]]}, {"timestamp": 1631459224346, "ltp": 4.1, "tv": 731.76, "trd": NaN, "batb": [[0, 3.6, 3], [1, 3.55, 3], [2, 3.5, 8.4]], "batl": NaN}, {"timestamp": 1631459227532, "ltp": 4.1, "tv": 731.76, "trd": NaN, "batb": [[0, 3.7, 5.32], [1, 3.6, 3], [2, 3.55, 3]], "batl": [[0, 5, 34.67], [1, 5.1, 49.18], [2, 5.2, 60.22]]}, {"timestamp": 1631459227944, "ltp": 4.1, "tv": 731.76, "trd": NaN, "batb": [[0, 3.6, 3], [1, 3.55, 3], [2, 3.5, 8.4]], "batl": NaN}, {"timestamp": 1631459233447, "ltp": 4.1, "tv": 731.76, "trd": NaN, "batb": [[2, 3.5, 5.4]], "batl": NaN}, {"timestamp": 1631459234628, "ltp": 4.1, "tv": 731.76, "trd": NaN, "batb": [[0, 3.7, 5.62], [1, 3.6, 3], [2, 3.55, 3]], "batl": NaN}, {"timestamp": 1631459235254, "ltp": 4.1, "tv": 731.76, "trd": NaN, "batb": [[0, 3.6, 3], [1, 3.5, 5.4], [2, 3.45, 69.67]], "batl": NaN}, {"timestamp": 1631459237057, "ltp": 4.1, "tv": 731.76, "trd": NaN, "batb": NaN, "batl": [[0, 7.2, 91.22], [1, 5.1, 0], [2, 5.2, 0]]}, {"timestamp": 1631459238566, "ltp": 4.1, "tv": 731.76, "trd": NaN, "batb": [[1, 3.55, 3], [2, 3.5, 5.4]], "batl": NaN}, {"timestamp": 1631459240343, "ltp": 4.1, "tv": 731.76, "trd": NaN, "batb": [[0, 3.5, 5.4], [1, 3.45, 69.67], [2, 3.4, 46.14]], "batl": NaN}, {"timestamp": 1631459241557, "ltp": 4.1, "tv": 731.76, "trd": NaN, "batb": [[0, 3.5, 73.56], [1, 3.4, 46.14], [2, 3.35, 67.46]], "batl": [[0, 4.1, 55.52]]}, {"timestamp": 1631459242201, "ltp": 4.1, "tv": 731.76, "trd": NaN, "batb": NaN, "batl": [[0, 4.1, 5], [1, 5.5, 113.67]]}, {"timestamp": 1631459243491, "ltp": 4.1, "tv": 731.76, "trd": NaN, "batb": NaN, "batl": [[0, 3.6, 2], [1, 3.7, 3], [2, 5.5, 113.67]]}, {"timestamp": 1631459244390, "ltp": 3.6, "tv": 733.9, "trd": [[3.6, 2.14]], "batb": NaN, "batl": [[0, 3.7, 3.93], [1, 5.5, 113.67], [2, 5.5, 0]]}, {"timestamp": 1631459246511, "ltp": 3.6, "tv": 733.9, "trd": NaN, "batb": NaN, "batl": [[2, 1000, 2.17]]}, {"timestamp": 1631459246995, "ltp": 3.6, "tv": 733.9, "trd": NaN, "batb": NaN, "batl": [[0, 3.6, 5.58], [1, 3.7, 3], [2, 4.4, 47.74]]}, {"timestamp": 1631459255905, "ltp": 3.6, "tv": 733.9, "trd": NaN, "batb": NaN, "batl": [[1, 4.4, 47.74], [2, 4.5, 43.91]]}, {"timestamp": 1631459259981, "ltp": 3.5, "tv": 942.47, "trd": [[3.5, 171.12], [3.55, 37.46]], "batb": [[0, 3.4, 46.14], [1, 3.35, 67.46], [2, 3.3, 69.11]], "batl": NaN}, {"timestamp": 1631459265238, "ltp": 3.5, "tv": 942.47, "trd": NaN, "batb": NaN, "batl": [[0, 4.4, 47.74], [1, 4.5, 43.91], [2, 4.6, 64.1]]}, {"timestamp": 1631459266410, "ltp": 3.5, "tv": 942.47, "trd": NaN, "batb": [[0, 2.88, 44.63], [1, 2.84, 69.29], [2, 2.82, 83.78]], "batl": NaN}, {"timestamp": 1631459268453, "ltp": 3.5, "tv": 942.47, "trd": NaN, "batb": NaN, "batl": [[0, 3.6, 15.08], [1, 4.4, 47.74], [2, 4.5, 43.91]]}, {"timestamp": 1631459269637, "ltp": 3.5, "tv": 942.47, "trd": NaN, "batb": [[0, 2.9, 2], [1, 2.88, 3], [2, 2.86, 45.05]], "batl": [[0, 4.4, 47.74], [1, 4.5, 43.91], [2, 4.6, 64.1]]}, {"timestamp": 1631459271518, "ltp": 3.5, "tv": 942.47, "trd": NaN, "batb": [[2, 2.86, 47.05]], "batl": [[0, 4.4, 50.74]]}, {"timestamp": 1631459276025, "ltp": 3.5, "tv": 942.47, "trd": NaN, "batb": [[0, 3.9, 14.56], [1, 2.9, 2], [2, 2.88, 3]], "batl": NaN}, {"timestamp": 1631459277037, "ltp": 3.5, "tv": 942.47, "trd": NaN, "batb": [[0, 4.1, 91.27], [1, 3.9, 14.56], [2, 3.45, 69.59]], "batl": NaN}, {"timestamp": 1631459278049, "ltp": 3.5, "tv": 942.47, "trd": NaN, "batb": [[2, 3.45, 79.59]], "batl": [[0, 4.3, 14.98], [1, 4.4, 50.74], [2, 4.5, 43.91]]}, {"timestamp": 1631459279030, "ltp": 3.5, "tv": 942.47, "trd": NaN, "batb": NaN, "batl": [[0, 4.3, 16.98]]}, {"timestamp": 1631459280549, "ltp": 4.3, "tv": 944.22, "trd": [[4.3, 26.11]], "batb": NaN, "batl": [[0, 4.3, 6.78]]}, {"timestamp": 1631459283392, "ltp": 4.3, "tv": 944.22, "trd": NaN, "batb": [[2, 3.55, 3.99]], "batl": NaN}, {"timestamp": 1631459288311, "ltp": 4.3, "tv": 944.22, "trd": NaN, "batb": [[0, 4.1, 194.61]], "batl": NaN}, {"timestamp": 1631459290592, "ltp": 4.3, "tv": 944.22, "trd": NaN, "batb": [[0, 3.45, 69.59], [1, 3.35, 46.18], [2, 3.3, 58.33]], "batl": [[0, 4.9, 40.99], [1, 5, 52.79], [2, 5.1, 48.76]]}, {"timestamp": 1631459294288, "ltp": 4.3, "tv": 944.22, "trd": NaN, "batb": [[0, 3.45, 72.59], [1, 3.4, 2], [2, 3.35, 46.18]], "batl": NaN}, {"timestamp": 1631459296397, "ltp": 4.3, "tv": 944.22, "trd": NaN, "batb": [[0, 3.5, 63.09], [1, 3.45, 72.59], [2, 3.4, 2]], "batl": [[0, 4.8, 40.97], [1, 4.9, 40.99], [2, 5, 52.79]]}, {"timestamp": 1631459297505, "ltp": 4.3, "tv": 944.22, "trd": NaN, "batb": [[0, 3.55, 3.99], [1, 3.5, 63.09], [2, 3.45, 72.59]], "batl": [[0, 4.9, 40.99], [1, 5, 52.79], [2, 5.1, 48.76]]}, {"timestamp": 1631459297986, "ltp": 4.3, "tv": 944.22, "trd": NaN, "batb": [[1, 3.45, 72.59], [2, 3.4, 2]], "batl": NaN}, {"timestamp": 1631459300329, "ltp": 4.3, "tv": 944.22, "trd": NaN, "batb": NaN, "batl": [[0, 4.7, 46.03], [1, 4.9, 40.99], [2, 5, 52.79]]}, {"timestamp": 1631459301509, "ltp": 4.3, "tv": 944.22, "trd": NaN, "batb": NaN, "batl": [[0, 4.9, 40.99], [1, 5, 52.79], [2, 5.1, 48.76]]}, {"timestamp": 1631459302092, "ltp": 4.3, "tv": 944.22, "trd": NaN, "batb": [[0, 3.45, 72.59], [1, 3.4, 2], [2, 3.35, 46.18]], "batl": NaN}, {"timestamp": 1631459305488, "ltp": 4.3, "tv": 944.22, "trd": NaN, "batb": [[0, 3.5, 2], [1, 3.45, 69.59]], "batl": NaN}, {"timestamp": 1631459307092, "ltp": 4.3, "tv": 944.22, "trd": NaN, "batb": [[2, 3.3, 4.18]], "batl": [[0, 5.1, 48.76], [1, 880, 0.01], [2, 5.1, 0]]}, {"timestamp": 1631459309014, "ltp": 4.3, "tv": 944.22, "trd": NaN, "batb": [[1, 3.45, 72.59]], "batl": NaN}, {"timestamp": 1631459310307, "ltp": 4.3, "tv": 944.22, "trd": NaN, "batb": [[0, 4.3, 12.28], [1, 3.5, 2], [2, 3.45, 72.59]], "batl": [[0, 5, 2], [1, 5.1, 50.76], [2, 880, 0.01]]}, {"timestamp": 1631459311343, "ltp": 4.3, "tv": 944.22, "trd": NaN, "batb": [[0, 4.8, 64.23], [1, 4.3, 12.28], [2, 4.1, 93.45]], "batl": [[0, 5, 16.13]]}, {"timestamp": 1631459313148, "ltp": 4.3, "tv": 944.22, "trd": NaN, "batb": NaN, "batl": [[2, 7.2, 91.22]]}, {"timestamp": 1631459317550, "ltp": 4.3, "tv": 944.22, "trd": NaN, "batb": NaN, "batl": [[2, 5.9, 40.87]]}, {"timestamp": 1631459320457, "ltp": 5.0, "tv": 945.6, "trd": [[5, 54.96]], "batb": NaN, "batl": [[0, 5, 7.86]]}, {"timestamp": 1631459323501, "ltp": 5.0, "tv": 945.6, "trd": NaN, "batb": NaN, "batl": [[1, 5.1, 48.76]]}, {"timestamp": 1631459334341, "ltp": 4.7, "tv": 1151.37, "trd": [[4.7, 42.41], [4.8, 183.6]], "batb": [[0, 4.3, 12.28], [1, 4.1, 93.45], [2, 4, 3.43]], "batl": NaN}, {"timestamp": 1631459337549, "ltp": 4.7, "tv": 1151.37, "trd": NaN, "batb": [[0, 4.4, 22.56], [1, 4.3, 12.28], [2, 4.1, 93.45]], "batl": NaN}, {"timestamp": 1631459349273, "ltp": 4.7, "tv": 1151.37, "trd": NaN, "batb": [[0, 4.1, 93.45], [1, 4, 3.43], [2, 3.85, 58.34]], "batl": [[0, 5.9, 40.87], [1, 6, 48.3], [2, 6.2, 53.01]]}, {"timestamp": 1631459351377, "ltp": 4.7, "tv": 1151.37, "trd": NaN, "batb": [[1, 3.85, 58.34], [2, 3.8, 56.85]], "batl": NaN}, {"timestamp": 1631459352471, "ltp": 4.7, "tv": 1151.37, "trd": NaN, "batb": [[0, 3.95, 99.82]], "batl": [[0, 5.9, 43.87]]}, {"timestamp": 1631459354573, "ltp": 4.7, "tv": 1151.37, "trd": NaN, "batb": [[0, 4, 3.43], [1, 3.95, 99.82], [2, 3.85, 58.34]], "batl": NaN}, {"timestamp": 1631459355659, "ltp": 4.7, "tv": 1151.37, "trd": NaN, "batb": [[0, 4.2, 49.75], [1, 4, 2], [2, 3.95, 102.82]], "batl": [[0, 5.8, 33.23], [1, 5.9, 43.87], [2, 6, 48.3]]}, {"timestamp": 1631459355868, "ltp": 4.7, "tv": 1151.37, "trd": NaN, "batb": [[0, 4, 2], [1, 3.95, 102.82], [2, 3.85, 58.34]], "batl": NaN}, {"timestamp": 1631459358658, "ltp": 4.7, "tv": 1151.37, "trd": NaN, "batb": [[0, 4, 5.68], [2, 3.9, 2]], "batl": NaN}, {"timestamp": 1631459359475, "ltp": 4.7, "tv": 1151.37, "trd": NaN, "batb": NaN, "batl": [[0, 5.9, 43.87], [1, 6, 48.3], [2, 6.2, 53.01]]}, {"timestamp": 1631459359770, "ltp": 4.7, "tv": 1151.37, "trd": NaN, "batb": [[0, 4, 2]], "batl": NaN}, {"timestamp": 1631459363380, "ltp": 4.7, "tv": 1151.37, "trd": NaN, "batb": [[0, 4, 5.29]], "batl": NaN}, {"timestamp": 1631459366085, "ltp": 4.7, "tv": 1151.37, "trd": NaN, "batb": NaN, "batl": [[0, 5.9, 3], [1, 880, 0.01], [2, 6.2, 0]]}, {"timestamp": 1631459368598, "ltp": 4.7, "tv": 1151.37, "trd": NaN, "batb": NaN, "batl": [[0, 4.4, 271.74], [1, 5.9, 3], [2, 880, 0.01]]}, {"timestamp": 1631459369601, "ltp": 4.7, "tv": 1151.37, "trd": NaN, "batb": [[0, 4, 3.29], [1, 3.95, 99.82], [2, 3.85, 58.34]], "batl": [[0, 5.9, 3], [1, 880, 0.01], [2, 880, 0]]}, {"timestamp": 1631459370575, "ltp": 4.7, "tv": 1151.37, "trd": NaN, "batb": NaN, "batl": [[0, 4.9, 15], [1, 5.9, 3]]}, {"timestamp": 1631459371559, "ltp": 4.7, "tv": 1151.37, "trd": NaN, "batb": NaN, "batl": [[0, 4.3, 3], [1, 4.9, 15], [2, 5.9, 3]]}, {"timestamp": 1631459371881, "ltp": 4.7, "tv": 1151.37, "trd": NaN, "batb": NaN, "batl": [[1, 5.8, 2]]}, {"timestamp": 1631459373609, "ltp": 4.3, "tv": 1153.03, "trd": [[4.3, 27.77]], "batb": NaN, "batl": [[0, 4.3, 2.17], [1, 5.1, 64.09], [2, 5.8, 2]]}, {"timestamp": 1631459374388, "ltp": 4.3, "tv": 1153.03, "trd": NaN, "batb": NaN, "batl": [[1, 5.8, 2], [2, 5.9, 3]]}, {"timestamp": 1631459375517, "ltp": 4.3, "tv": 1153.03, "trd": NaN, "batb": NaN, "batl": [[1, 4.8, 2.02], [2, 5, 2]]}, {"timestamp": 1631459376405, "ltp": 4.3, "tv": 1153.03, "trd": NaN, "batb": NaN, "batl": [[2, 5, 49.83]]}, {"timestamp": 1631459378399, "ltp": 4.3, "tv": 1153.03, "trd": NaN, "batb": NaN, "batl": [[2, 4.9, 15]]}, {"timestamp": 1631459379516, "ltp": 4.3, "tv": 1153.03, "trd": NaN, "batb": [[0, 3.5, 74.74], [1, 3.45, 61.73], [2, 3.4, 65.85]], "batl": [[0, 5, 49.83], [1, 5.1, 42.1], [2, 5.2, 62.11]]}, {"timestamp": 1631459382629, "ltp": 4.3, "tv": 1153.03, "trd": NaN, "batb": NaN, "batl": [[0, 4.8, 2.27], [1, 5, 49.83], [2, 5.1, 42.1]]}, {"timestamp": 1631459383321, "ltp": 4.3, "tv": 1153.03, "trd": NaN, "batb": [[1, 3.45, 63.73]], "batl": [[0, 5, 49.83], [1, 5.1, 42.1], [2, 5.2, 62.11]]}, {"timestamp": 1631459386225, "ltp": 4.3, "tv": 1153.03, "trd": NaN, "batb": [[0, 3.7, 3.82], [1, 3.6, 3], [2, 3.55, 3]], "batl": [[0, 4.8, 2.22], [1, 5, 49.83], [2, 5.1, 42.1]]}, {"timestamp": 1631459389617, "ltp": 4.3, "tv": 1153.03, "trd": NaN, "batb": [[0, 3.75, 19.1], [1, 3.7, 3.82], [2, 3.6, 3]], "batl": [[0, 4.7, 11.1], [1, 4.8, 2.22], [2, 5, 49.83]]}, {"timestamp": 1631459391529, "ltp": 4.3, "tv": 1153.03, "trd": NaN, "batb": [[0, 3.6, 3], [1, 3.55, 3], [2, 3.5, 74.74]], "batl": [[0, 5, 49.83], [1, 5.1, 42.1], [2, 5.2, 62.11]]}, {"timestamp": 1631459394648, "ltp": 4.3, "tv": 1153.03, "trd": NaN, "batb": [[0, 3.7, 4.42], [1, 3.6, 3], [2, 3.55, 3]], "batl": NaN}, {"timestamp": 1631459395043, "ltp": 4.3, "tv": 1153.03, "trd": NaN, "batb": [[0, 3.6, 3], [1, 3.55, 3], [2, 3.5, 72.74]], "batl": NaN}, {"timestamp": 1631459398643, "ltp": 4.3, "tv": 1153.03, "trd": NaN, "batb": [[1, 3.5, 72.74], [2, 3.45, 61.73]], "batl": NaN}, {"timestamp": 1631459402570, "ltp": 4.3, "tv": 1153.03, "trd": NaN, "batb": [[1, 3.55, 2], [2, 3.5, 72.74]], "batl": NaN}, {"timestamp": 1631459405559, "ltp": 4.3, "tv": 1153.03, "trd": NaN, "batb": [[0, 4.4, 12.26], [1, 3.7, 4.22], [2, 3.6, 3]], "batl": [[0, 4.8, 2.47], [1, 5, 49.83], [2, 5.1, 42.1]]}, {"timestamp": 1631459406647, "ltp": 4.3, "tv": 1153.03, "trd": NaN, "batb": [[0, 4.7, 67.24], [1, 4.4, 12.26], [2, 4, 15]], "batl": [[0, 5, 63.94], [1, 5.1, 42.1], [2, 5.2, 62.11]]}, {"timestamp": 1631459410584, "ltp": 5.0, "tv": 1154.4, "trd": [[5, 56.33]], "batb": NaN, "batl": [[0, 5, 63.25]]}, {"timestamp": 1631459411469, "ltp": 5.0, "tv": 1154.4, "trd": NaN, "batb": [[0, 4.7, 158.62]], "batl": NaN}, {"timestamp": 1631459412585, "ltp": 5.0, "tv": 1154.4, "trd": NaN, "batb": [[2, 4, 20.36]], "batl": NaN}, {"timestamp": 1631459426501, "ltp": 5.0, "tv": 1154.4, "trd": NaN, "batb": [[0, 3.9, 103.33], [1, 3.75, 57.96], [2, 3.7, 66.82]], "batl": [[0, 6, 42.88], [1, 6.2, 43.98], [2, 6.4, 49.54]]}, {"timestamp": 1631459429878, "ltp": 5.0, "tv": 1154.4, "trd": NaN, "batb": [[0, 4, 5.36], [1, 3.9, 105.33], [2, 3.85, 2]], "batl": NaN}, {"timestamp": 1631459436652, "ltp": 5.0, "tv": 1154.4, "trd": NaN, "batb": [[1, 3.9, 103.33], [2, 3.75, 57.96]], "batl": NaN}, {"timestamp": 1631459437505, "ltp": 5.0, "tv": 1154.4, "trd": NaN, "batb": NaN, "batl": [[0, 4.9, 5]]}, {"timestamp": 1631459439415, "ltp": 5.0, "tv": 1154.4, "trd": NaN, "batb": NaN, "batl": [[0, 4.3, 2], [1, 4.9, 5]]}, {"timestamp": 1631459440384, "ltp": 5.0, "tv": 1154.4, "trd": NaN, "batb": [[0, 3.9, 103.33], [1, 3.75, 57.96], [2, 3.7, 66.82]], "batl": [[0, 4.2, 3], [1, 4.3, 2]]}, {"timestamp": 1631459441202, "ltp": 4.2, "tv": 1156.1, "trd": [[4.2, 9.96]], "batb": NaN, "batl": [[0, 4.2, 2.15]]}, {"timestamp": 1631459443221, "ltp": 4.2, "tv": 1156.1, "trd": NaN, "batb": NaN, "batl": [[0, 4.2, 12.15], [2, 5.1, 43.74]]}, {"timestamp": 1631459444521, "ltp": 4.2, "tv": 1156.1, "trd": NaN, "batb": [[0, 3.7, 4.22], [1, 3.65, 3], [2, 3.5, 5.98]], "batl": [[0, 4.2, 2.15]]}, {"timestamp": 1631459445217, "ltp": 3.5, "tv": 1174.48, "trd": [[3.5, 183.5], [3.65, 6]], "batb": [[0, 3.35, 140.38], [1, 3.3, 65.13], [2, 3.25, 74.35]], "batl": [[0, 5.1, 43.74], [1, 5.2, 41.67], [2, 5.3, 48.04]]}, {"timestamp": 1631459448539, "ltp": 3.5, "tv": 1174.48, "trd": NaN, "batb": [[0, 3.5, 8.44], [1, 3.45, 3], [2, 3.35, 140.38]], "batl": [[0, 5.1, 45.74]]}, {"timestamp": 1631459451622, "ltp": 3.5, "tv": 1174.48, "trd": NaN, "batb": [[0, 3.7, 5.22], [1, 3.5, 8.44], [2, 3.45, 3]], "batl": NaN}, {"timestamp": 1631459452109, "ltp": 3.5, "tv": 1174.48, "trd": NaN, "batb": [[0, 3.5, 8.44], [1, 3.45, 3], [2, 3.35, 74.36]], "batl": [[0, 5.1, 43.74]]}, {"timestamp": 1631459456520, "ltp": 3.5, "tv": 1174.48, "trd": NaN, "batb": [[0, 4.7, 66.99], [1, 3.75, 56.77], [2, 3.5, 8.44]], "batl": NaN}, {"timestamp": 1631459456946, "ltp": 3.5, "tv": 1174.48, "trd": NaN, "batb": [[1, 4, 42.2], [2, 3.75, 56.77]], "batl": [[0, 5.1, 56.94]]}, {"timestamp": 1631459459337, "ltp": 5.0, "tv": 1175.18, "trd": [[5, 57.03]], "batb": NaN, "batl": NaN}, {"timestamp": 1631459462543, "ltp": 5.0, "tv": 1175.18, "trd": NaN, "batb": [[1, 4, 46.6]], "batl": NaN}, {"timestamp": 1631459470158, "ltp": 4.8, "tv": 1175.33, "trd": [[4.8, 183.75]], "batb": NaN, "batl": NaN}, {"timestamp": 1631459472646, "ltp": 4.8, "tv": 1175.33, "trd": NaN, "batb": [[0, 3.75, 56.77], [1, 3.7, 4.42], [2, 2.2, 42.66]], "batl": NaN}, {"timestamp": 1631459479438, "ltp": 4.8, "tv": 1175.33, "trd": NaN, "batb": [[0, 4, 4.29], [1, 3.75, 56.77], [2, 3.7, 4.42]], "batl": NaN}, {"timestamp": 1631459479764, "ltp": 4.8, "tv": 1175.33, "trd": NaN, "batb": [[0, 3.75, 56.77], [1, 3.7, 4.42], [2, 2.2, 42.66]], "batl": NaN}, {"timestamp": 1631459486075, "ltp": 4.8, "tv": 1175.33, "trd": NaN, "batb": [[0, 6.2, 14.17], [1, 3.75, 56.77], [2, 3.7, 4.42]], "batl": [[0, 7, 2]]}, {"timestamp": 1631459487490, "ltp": 4.8, "tv": 1175.33, "trd": NaN, "batb": [[0, 6.2, 85.26], [1, 5.2, 48.08], [2, 4.7, 67.41]], "batl": [[1, 7.8, 5]]}, {"timestamp": 1631459488573, "ltp": 4.8, "tv": 1175.33, "trd": NaN, "batb": NaN, "batl": [[1, 11.5, 69.66]]}, {"timestamp": 1631459489073, "ltp": 4.8, "tv": 1175.33, "trd": NaN, "batb": NaN, "batl": [[0, 6.8, 3], [1, 7, 2], [2, 11.5, 69.66]]}, {"timestamp": 1631459490287, "ltp": 6.6, "tv": 1175.77, "trd": [[6.6, 5.63]], "batb": NaN, "batl": NaN}, {"timestamp": 1631459491481, "ltp": 6.6, "tv": 1175.77, "trd": NaN, "batb": NaN, "batl": [[0, 6.8, 13]]}, {"timestamp": 1631459492513, "ltp": 6.6, "tv": 1175.77, "trd": NaN, "batb": [[2, 4.7, 71.13]], "batl": [[0, 6.6, 2], [1, 6.8, 13], [2, 7, 2]]}, {"timestamp": 1631459496277, "ltp": 6.6, "tv": 1175.77, "trd": NaN, "batb": [[0, 5.2, 48.08], [1, 4.7, 71.13], [2, 4.2, 3.77]], "batl": NaN}, {"timestamp": 1631459497473, "ltp": 6.6, "tv": 1175.77, "trd": NaN, "batb": [[0, 6.2, 77.53], [1, 5.2, 48.08], [2, 4.7, 71.13]], "batl": NaN}, {"timestamp": 1631459497899, "ltp": 6.6, "tv": 1175.77, "trd": NaN, "batb": [[0, 5.2, 48.08], [1, 4.7, 71.13], [2, 4.2, 3.77]], "batl": [[0, 11.5, 69.66], [1, 6.8, 0], [2, 7, 0]]}, {"timestamp": 1631459499499, "ltp": 6.6, "tv": 1175.77, "trd": NaN, "batb": [[0, 5.3, 2], [1, 5.2, 50.08], [2, 4.7, 71.13]], "batl": NaN}, {"timestamp": 1631459499767, "ltp": 6.6, "tv": 1175.77, "trd": NaN, "batb": [[0, 4.7, 71.13], [1, 4.2, 3.77], [2, 3.15, 375.55]], "batl": NaN}, {"timestamp": 1631459501280, "ltp": 6.6, "tv": 1175.77, "trd": NaN, "batb": NaN, "batl": [[0, 11, 3], [1, 11.5, 69.66]]}, {"timestamp": 1631459503603, "ltp": 6.6, "tv": 1175.77, "trd": NaN, "batb": [[0, 4.8, 3], [1, 4.7, 74.13], [2, 4.2, 3.77]], "batl": NaN}, {"timestamp": 1631459504607, "ltp": 6.6, "tv": 1175.77, "trd": NaN, "batb": [[0, 4.7, 71.13], [1, 4.2, 3.77], [2, 3.15, 375.55]], "batl": [[0, 7.8, 15], [1, 11, 3]]}, {"timestamp": 1631459506406, "ltp": 5.2, "tv": 1223.85, "trd": [[5.2, 133.66]], "batb": [[2, 3.75, 56.52]], "batl": NaN}, {"timestamp": 1631459507585, "ltp": 5.2, "tv": 1223.85, "trd": NaN, "batb": NaN, "batl": [[1, 10, 3], [2, 11, 3]]}, {"timestamp": 1631459508496, "ltp": 5.2, "tv": 1223.85, "trd": NaN, "batb": NaN, "batl": [[0, 5.1, 2], [1, 7.2, 91.22], [2, 7.6, 2]]}, {"timestamp": 1631459510304, "ltp": 5.1, "tv": 1225.22, "trd": [[5.1, 1.38]], "batb": NaN, "batl": [[0, 5.1, 1.31]]}, {"timestamp": 1631459512301, "ltp": 5.1, "tv": 1225.22, "trd": NaN, "batb": [[2, 4, 4.36]], "batl": NaN}, {"timestamp": 1631459514499, "ltp": 5.1, "tv": 1225.22, "trd": NaN, "batb": NaN, "batl": [[0, 5, 15], [1, 5.1, 1.31], [2, 7.2, 91.22]]}, {"timestamp": 1631459514986, "ltp": 5.1, "tv": 1225.22, "trd": NaN, "batb": NaN, "batl": [[0, 5.1, 1.31], [1, 7.2, 91.22], [2, 7.6, 2]]}, {"timestamp": 1631459521621, "ltp": 5.1, "tv": 1225.22, "trd": NaN, "batb": NaN, "batl": [[0, 5, 13.12], [1, 5.1, 1.31], [2, 7.2, 91.22]]}, {"timestamp": 1631459522346, "ltp": 5.1, "tv": 1225.22, "trd": NaN, "batb": NaN, "batl": [[0, 5.1, 1.31], [1, 7.2, 91.22], [2, 7.2, 0]]}, {"timestamp": 1631459525512, "ltp": 5.1, "tv": 1225.22, "trd": NaN, "batb": NaN, "batl": [[0, 4.9, 12.38], [1, 5.1, 1.31], [2, 7.2, 91.22]]}, {"timestamp": 1631459525723, "ltp": 5.1, "tv": 1225.22, "trd": NaN, "batb": NaN, "batl": [[0, 5.1, 1.31], [1, 7.2, 91.22], [2, 7.2, 0]]}, {"timestamp": 1631459528450, "ltp": 5.1, "tv": 1225.22, "trd": NaN, "batb": [[0, 4, 4.36], [1, 3.75, 56.52], [2, 3.7, 4.12]], "batl": [[0, 7.2, 91.22], [1, 7.2, 0]]}, {"timestamp": 1631459529043, "ltp": 5.1, "tv": 1225.22, "trd": NaN, "batb": [[0, 3.75, 56.52], [1, 3.7, 4.12], [2, 3.15, 375.55]], "batl": NaN}, {"timestamp": 1631459532629, "ltp": 5.1, "tv": 1225.22, "trd": NaN, "batb": [[0, 3.8, 55.94], [1, 3.75, 56.52], [2, 3.7, 4.12]], "batl": [[0, 7.2, 3]]}, {"timestamp": 1631459533494, "ltp": 5.1, "tv": 1225.22, "trd": NaN, "batb": NaN, "batl": [[0, 4.2, 1668.06], [1, 4.6, 7.22], [2, 7.2, 3]]}, {"timestamp": 1631459534196, "ltp": 5.1, "tv": 1225.22, "trd": NaN, "batb": NaN, "batl": [[0, 7.2, 3], [1, 4.6, 0], [2, 7.2, 0]]}, {"timestamp": 1631459535610, "ltp": 5.1, "tv": 1225.22, "trd": NaN, "batb": NaN, "batl": [[0, 4.5, 47.86], [1, 7, 2], [2, 7.2, 3]]}, {"timestamp": 1631459536623, "ltp": 5.1, "tv": 1225.22, "trd": NaN, "batb": NaN, "batl": [[0, 4.1, 3], [1, 4.5, 15], [2, 6, 104.94]]}, {"timestamp": 1631459537427, "ltp": 5.1, "tv": 1225.22, "trd": NaN, "batb": NaN, "batl": [[1, 4.2, 2], [2, 4.5, 3]]}, {"timestamp": 1631459539508, "ltp": 4.1, "tv": 1227.08, "trd": [[4.1, 20.17]], "batb": NaN, "batl": [[0, 4.1, 2.07]]}, {"timestamp": 1631459540039, "ltp": 4.1, "tv": 1227.08, "trd": NaN, "batb": NaN, "batl": [[0, 4, 15], [1, 4.1, 2.07], [2, 4.2, 2]]}, {"timestamp": 1631459543627, "ltp": 4.0, "tv": 1228.06, "trd": [[4, 0.98]], "batb": NaN, "batl": [[0, 4, 14.02]]}, {"timestamp": 1631459544637, "ltp": 4.0, "tv": 1228.06, "trd": NaN, "batb": [[0, 3.55, 5.19], [1, 3.5, 5.7], [2, 3.35, 5.07]], "batl": [[0, 4.1, 2.07], [1, 4.2, 2], [2, 4.5, 3]]}, {"timestamp": 1631459545648, "ltp": 4.0, "tv": 1228.06, "trd": NaN, "batb": [[0, 3.35, 5.07], [1, 3.2, 61.07], [2, 3.15, 158.85]], "batl": [[0, 5.1, 43.6], [1, 5.2, 47.67], [2, 5.3, 45.78]]}, {"timestamp": 1631459548434, "ltp": 4.0, "tv": 1228.06, "trd": NaN, "batb": [[0, 3.4, 2], [1, 3.35, 7.07], [2, 3.2, 61.07]], "batl": NaN}, {"timestamp": 1631459548980, "ltp": 4.0, "tv": 1228.06, "trd": NaN, "batb": [[2, 3.3, 3]], "batl": [[0, 5.1, 46.6]]}, {"timestamp": 1631459551653, "ltp": 4.0, "tv": 1228.06, "trd": NaN, "batb": [[0, 3.55, 5.99], [1, 3.4, 2], [2, 3.35, 7.07]], "batl": NaN}, {"timestamp": 1631459551868, "ltp": 4.0, "tv": 1228.06, "trd": NaN, "batb": [[0, 3.4, 2], [1, 3.35, 7.07], [2, 3.3, 3]], "batl": NaN}, {"timestamp": 1631459562365, "ltp": 4.0, "tv": 1228.06, "trd": NaN, "batb": [[1, 3.35, 5.07], [2, 3.2, 61.07]], "batl": NaN}, {"timestamp": 1631459565597, "ltp": 4.0, "tv": 1228.06, "trd": NaN, "batb": [[0, 3.55, 5.79], [1, 3.4, 2], [2, 3.35, 7.07]], "batl": NaN}, {"timestamp": 1631459565884, "ltp": 4.0, "tv": 1228.06, "trd": NaN, "batb": [[0, 3.4, 2], [1, 3.35, 7.07], [2, 3.2, 61.07]], "batl": NaN}, {"timestamp": 1631459569390, "ltp": 4.0, "tv": 1228.06, "trd": NaN, "batb": [[2, 3.15, 86.25]], "batl": [[0, 5.1, 43.6]]}, {"timestamp": 1631459571624, "ltp": 4.0, "tv": 1228.06, "trd": NaN, "batb": NaN, "batl": [[0, 5.2, 47.67], [1, 5.3, 45.78], [2, 5.3, 0]]}, {"timestamp": 1631459572106, "ltp": 4.0, "tv": 1228.06, "trd": NaN, "batb": [[0, 4.7, 16.42], [1, 3.4, 2], [2, 3.35, 7.07]], "batl": NaN}, {"timestamp": 1631459573638, "ltp": 4.0, "tv": 1228.06, "trd": NaN, "batb": [[0, 4.7, 82.99], [1, 3.95, 10], [2, 3.8, 55.85]], "batl": NaN}, {"timestamp": 1631459574643, "ltp": 4.0, "tv": 1228.06, "trd": NaN, "batb": NaN, "batl": [[2, 7.2, 91.22]]}, {"timestamp": 1631459574798, "ltp": 4.0, "tv": 1228.06, "trd": NaN, "batb": NaN, "batl": [[0, 5.1, 3], [1, 5.2, 47.67], [2, 5.3, 45.78]]}, {"timestamp": 1631459579158, "ltp": 4.0, "tv": 1228.06, "trd": NaN, "batb": [[1, 4.1, 4.74], [2, 3.95, 10]], "batl": NaN}, {"timestamp": 1631459580308, "ltp": 5.0, "tv": 1246.45, "trd": [[5, 75.42]], "batb": NaN, "batl": NaN}, {"timestamp": 1631459599102, "ltp": 5.0, "tv": 1246.45, "trd": NaN, "batb": [[0, 4.7, 66.57]], "batl": NaN}, {"timestamp": 1631459600439, "ltp": 5.0, "tv": 1246.45, "trd": NaN, "batb": NaN, "batl": [[0, 5, 11.58], [1, 5.1, 3], [2, 5.2, 47.67]]}, {"timestamp": 1631459603643, "ltp": 5.0, "tv": 1246.45, "trd": NaN, "batb": [[0, 4.1, 4.74], [1, 3.85, 4.17], [2, 3.8, 55.85]], "batl": [[0, 5.1, 3], [1, 7.2, 91.22], [2, 5.2, 0]]}, {"timestamp": 1631459604234, "ltp": 5.0, "tv": 1246.45, "trd": NaN, "batb": [[0, 3.85, 4.17], [1, 3.8, 55.85], [2, 3.45, 3]], "batl": [[0, 7.2, 91.22], [1, 7.2, 0]]}, {"timestamp": 1631459607634, "ltp": 5.0, "tv": 1246.45, "trd": NaN, "batb": [[0, 3.9, 3], [1, 3.85, 7.17], [2, 3.8, 58.85]], "batl": [[0, 7.2, 94.22]]}, {"timestamp": 1631459609843, "ltp": 5.0, "tv": 1246.45, "trd": NaN, "batb": NaN, "batl": [[0, 7, 3], [1, 7.2, 94.22]]}, {"timestamp": 1631459619583, "ltp": 5.0, "tv": 1246.45, "trd": NaN, "batb": [[1, 3.85, 4.17], [2, 3.8, 55.85]], "batl": NaN}, {"timestamp": 1631459620564, "ltp": 5.0, "tv": 1246.45, "trd": NaN, "batb": [[0, 3.85, 4.17], [1, 3.8, 55.85], [2, 2.72, 379.61]], "batl": NaN}, {"timestamp": 1631459621664, "ltp": 5.0, "tv": 1246.45, "trd": NaN, "batb": [[0, 4.1, 4.54], [1, 3.85, 4.17], [2, 3.8, 55.85]], "batl": [[1, 7.2, 0]]}, {"timestamp": 1631459622349, "ltp": 5.0, "tv": 1246.45, "trd": NaN, "batb": [[0, 3.85, 4.17], [1, 3.8, 55.85], [2, 2.72, 379.61]], "batl": NaN}, {"timestamp": 1631459623600, "ltp": 5.0, "tv": 1246.45, "trd": NaN, "batb": [[2, 3.65, 3]], "batl": [[0, 4.3, 2], [1, 6.8, 3], [2, 7, 3]]}, {"timestamp": 1631459625576, "ltp": 5.0, "tv": 1246.45, "trd": NaN, "batb": NaN, "batl": [[0, 4.2, 3], [1, 4.3, 2], [2, 6, 104.94]]}, {"timestamp": 1631459629591, "ltp": 5.0, "tv": 1246.45, "trd": NaN, "batb": NaN, "batl": [[0, 4.1, 15], [1, 4.2, 3], [2, 4.3, 2]]}, {"timestamp": 1631459634583, "ltp": 3.9, "tv": 1246.76, "trd": [[3.9, 1.15]], "batb": NaN, "batl": NaN}, {"timestamp": 1631459637403, "ltp": 3.9, "tv": 1246.76, "trd": NaN, "batb": [[2, 3.6, 2]], "batl": [[2, 5.1, 45.77]]}, {"timestamp": 1631459644513, "ltp": 3.9, "tv": 1246.76, "trd": NaN, "batb": [[0, 3.35, 5.27], [1, 3.2, 60.79], [2, 3.15, 148.33]], "batl": [[0, 5.1, 45.77], [1, 5.2, 42.8], [2, 5.3, 57.44]]}, {"timestamp": 1631459647606, "ltp": 3.9, "tv": 1246.76, "trd": NaN, "batb": [[0, 3.55, 4.99], [1, 3.35, 5.27], [2, 3.2, 60.79]], "batl": [[0, 5.1, 48.77]]}, {"timestamp": 1631459647814, "ltp": 3.9, "tv": 1246.76, "trd": NaN, "batb": [[0, 3.35, 5.27], [1, 3.2, 60.79], [2, 3.15, 148.33]], "batl": NaN}, {"timestamp": 1631459654629, "ltp": 3.9, "tv": 1246.76, "trd": NaN, "batb": [[0, 3.55, 5.79], [1, 3.35, 5.27], [2, 3.2, 60.79]], "batl": NaN}, {"timestamp": 1631459654906, "ltp": 3.9, "tv": 1246.76, "trd": NaN, "batb": [[0, 3.35, 5.27], [1, 3.2, 60.79], [2, 3.15, 148.33]], "batl": NaN}, {"timestamp": 1631459660651, "ltp": 3.9, "tv": 1246.76, "trd": NaN, "batb": NaN, "batl": [[0, 5.1, 3], [1, 5.2, 0], [2, 5.3, 0]]}, {"timestamp": 1631459661627, "ltp": 3.9, "tv": 1246.76, "trd": NaN, "batb": [[0, 3.55, 5.79], [1, 3.35, 5.27], [2, 3.2, 60.79]], "batl": NaN}, {"timestamp": 1631459661832, "ltp": 3.9, "tv": 1246.76, "trd": NaN, "batb": [[0, 3.35, 5.27], [1, 3.2, 60.79], [2, 3.15, 148.33]], "batl": NaN}, {"timestamp": 1631459665625, "ltp": 3.9, "tv": 1246.76, "trd": NaN, "batb": NaN, "batl": [[0, 3.85, 15], [1, 5.1, 3]]}, {"timestamp": 1631459667619, "ltp": 3.9, "tv": 1246.76, "trd": NaN, "batb": NaN, "batl": [[1, 4.9, 124.71], [2, 5, 3]]}, {"timestamp": 1631459668537, "ltp": 3.9, "tv": 1246.76, "trd": NaN, "batb": NaN, "batl": [[1, 4, 81.68], [2, 4.9, 124.71]]}, {"timestamp": 1631459669028, "ltp": 3.9, "tv": 1246.76, "trd": NaN, "batb": NaN, "batl": [[1, 5, 3], [2, 5.1, 3]]}, {"timestamp": 1631459671147, "ltp": 3.9, "tv": 1246.76, "trd": NaN, "batb": NaN, "batl": [[1, 3.9, 59.86], [2, 3.95, 53.58]]}, {"timestamp": 1631459673270, "ltp": 3.9, "tv": 1246.76, "trd": NaN, "batb": [[1, 3.3, 127.25], [2, 3.2, 143.61]], "batl": NaN}, {"timestamp": 1631459674539, "ltp": 3.9, "tv": 1246.76, "trd": NaN, "batb": NaN, "batl": [[0, 3.45, 133.23]]}, {"timestamp": 1631459677824, "ltp": 3.9, "tv": 1246.76, "trd": NaN, "batb": NaN, "batl": [[0, 3.4, 17.45], [1, 3.45, 133.23], [2, 3.9, 59.86]]}, {"timestamp": 1631459681550, "ltp": 3.9, "tv": 1246.76, "trd": NaN, "batb": NaN, "batl": [[2, 3.55, 112.73]]}, {"timestamp": 1631459682640, "ltp": 3.9, "tv": 1246.76, "trd": NaN, "batb": [[1, 3.2, 143.61], [2, 3.15, 62]], "batl": [[1, 3.9, 59.86], [2, 3.95, 53.58]]}, {"timestamp": 1631459683379, "ltp": 3.9, "tv": 1246.76, "trd": NaN, "batb": NaN, "batl": [[0, 5, 3], [1, 3.9, 0], [2, 3.95, 0]]}, {"timestamp": 1631459686468, "ltp": 3.9, "tv": 1246.76, "trd": NaN, "batb": NaN, "batl": [[0, 3.85, 45.26], [1, 3.9, 66.03], [2, 3.95, 75.22]]}, {"timestamp": 1631459687657, "ltp": 3.9, "tv": 1246.76, "trd": NaN, "batb": NaN, "batl": [[0, 3.45, 87.11], [1, 3.5, 100.78], [2, 3.85, 45.26]]}, {"timestamp": 1631459689666, "ltp": 3.9, "tv": 1246.76, "trd": NaN, "batb": [[0, 3.35, 46.26], [1, 3.3, 49.53], [2, 3.2, 143.61]], "batl": NaN}, {"timestamp": 1631459692996, "ltp": 3.9, "tv": 1246.76, "trd": NaN, "batb": NaN, "batl": [[0, 3.4, 16.26], [1, 3.45, 87.11], [2, 3.5, 100.78]]}, {"timestamp": 1631459702438, "ltp": 3.9, "tv": 1246.76, "trd": NaN, "batb": [[2, 3.25, 82.15]], "batl": NaN}, {"timestamp": 1631459760249, "ltp": 3.9, "tv": 1246.76, "trd": NaN, "batb": NaN, "batl": [[0, 3.45, 87.11], [1, 3.5, 100.78], [2, 3.85, 45.26]]}, {"timestamp": 1631459766554, "ltp": 3.35, "tv": 1247.38, "trd": [[3.35, 13.43]], "batb": [[0, 3.35, 45.95]], "batl": NaN}, {"timestamp": 1631459779387, "ltp": 3.35, "tv": 1247.38, "trd": NaN, "batb": NaN, "batl": [[0, 3.4, 16.26], [1, 3.45, 87.11], [2, 3.5, 100.78]]}, {"timestamp": 1631459794419, "ltp": 3.35, "tv": 1247.38, "trd": NaN, "batb": [[0, 3, 2], [1, 2.88, 5.21], [2, 2.74, 109.2]], "batl": [[0, 3.85, 45.26], [1, 3.9, 66.03], [2, 3.95, 75.22]]}, {"timestamp": 1631459794814, "ltp": 3.35, "tv": 1247.38, "trd": NaN, "batb": [[1, 2.74, 109.2], [2, 2.72, 90.48]], "batl": NaN}, {"timestamp": 1631459797631, "ltp": 3.35, "tv": 1247.38, "trd": NaN, "batb": [[1, 2.76, 49.66], [2, 2.74, 58.87]], "batl": NaN}, {"timestamp": 1631459798333, "ltp": 3.35, "tv": 1247.38, "trd": NaN, "batb": [[2, 2.72, 5.34]], "batl": NaN}, {"timestamp": 1631459801236, "ltp": 3.35, "tv": 1247.38, "trd": NaN, "batb": NaN, "batl": [[0, 3.95, 75.22], [1, 5, 3], [2, 3.95, 0]]}, {"timestamp": 1631459802428, "ltp": 3.35, "tv": 1247.38, "trd": NaN, "batb": [[0, 3.75, 57.61], [1, 3.15, 96.92], [2, 3, 2]], "batl": NaN}, {"timestamp": 1631459803530, "ltp": 3.35, "tv": 1247.38, "trd": NaN, "batb": NaN, "batl": [[2, 5.5, 113.67]]}, {"timestamp": 1631459804490, "ltp": 3.35, "tv": 1247.38, "trd": NaN, "batb": NaN, "batl": [[0, 3.9, 13.88], [1, 3.95, 75.22], [2, 5, 3]]}, {"timestamp": 1631459806235, "ltp": 3.9, "tv": 1251.57, "trd": [[3.9, 5.34]], "batb": NaN, "batl": [[0, 3.9, 11.78]]}, {"timestamp": 1631459808130, "ltp": 3.9, "tv": 1251.57, "trd": NaN, "batb": [[0, 3.75, 139.6], [1, 3.7, 91.38], [2, 3.35, 3.67]], "batl": [[2, 4.2, 3.08]]}, {"timestamp": 1631459809515, "ltp": 3.9, "tv": 1251.57, "trd": NaN, "batb": [[0, 3.35, 3.67], [1, 3.15, 90.75], [2, 3.1, 59.42]], "batl": [[0, 4.2, 3.08], [1, 4.4, 45.36], [2, 4.5, 53.76]]}, {"timestamp": 1631459809827, "ltp": 3.9, "tv": 1251.57, "trd": NaN, "batb": [[0, 3.15, 90.75], [1, 3.1, 59.42], [2, 3.05, 60.92]], "batl": [[0, 4.4, 45.36], [1, 4.5, 53.76], [2, 4.6, 54.54]]}, {"timestamp": 1631459813329, "ltp": 3.9, "tv": 1251.57, "trd": NaN, "batb": [[0, 3.15, 93.75], [1, 3.1, 62.42]], "batl": NaN}, {"timestamp": 1631459815641, "ltp": 3.9, "tv": 1251.57, "trd": NaN, "batb": [[0, 3.2, 3], [1, 3.15, 93.75], [2, 3.1, 62.42]], "batl": NaN}, {"timestamp": 1631459816548, "ltp": 3.9, "tv": 1251.57, "trd": NaN, "batb": [[0, 3.35, 3.67], [1, 3.2, 3], [2, 3.15, 93.75]], "batl": [[0, 4.2, 2.58], [1, 4.4, 45.36], [2, 4.5, 53.76]]}, {"timestamp": 1631459816831, "ltp": 3.9, "tv": 1251.57, "trd": NaN, "batb": [[0, 3.2, 3], [1, 3.15, 93.75], [2, 3.1, 62.42]], "batl": [[0, 4.4, 45.36], [1, 4.5, 53.76], [2, 4.6, 54.54]]}, {"timestamp": 1631459824439, "ltp": 3.9, "tv": 1251.57, "trd": NaN, "batb": [[1, 3.15, 90.75], [2, 3.1, 59.42]], "batl": NaN}, {"timestamp": 1631459827630, "ltp": 3.9, "tv": 1251.57, "trd": NaN, "batb": [[0, 3.35, 3.87], [1, 3.2, 3], [2, 3.15, 93.75]], "batl": [[0, 4.2, 2.63], [1, 4.4, 45.36], [2, 4.5, 53.76]]}, {"timestamp": 1631459828058, "ltp": 3.9, "tv": 1251.57, "trd": NaN, "batb": [[0, 3.2, 3], [1, 3.15, 93.75], [2, 3.1, 59.42]], "batl": [[0, 4.4, 45.36], [1, 4.5, 53.76], [2, 4.6, 54.54]]}, {"timestamp": 1631459830449, "ltp": 3.9, "tv": 1251.57, "trd": NaN, "batb": [[2, 2.2, 42.66]], "batl": NaN}, {"timestamp": 1631459833243, "ltp": 3.9, "tv": 1251.57, "trd": NaN, "batb": [[0, 3.9, 10.36], [1, 3.2, 3], [2, 3.15, 93.75]], "batl": NaN}, {"timestamp": 1631459834335, "ltp": 3.9, "tv": 1251.57, "trd": NaN, "batb": [[0, 4.2, 84.83], [1, 3.9, 10.36], [2, 3.7, 58.28]], "batl": NaN}, {"timestamp": 1631459835479, "ltp": 3.9, "tv": 1251.57, "trd": NaN, "batb": NaN, "batl": [[0, 4.4, 56.68]]}, {"timestamp": 1631459838661, "ltp": 4.4, "tv": 1253.33, "trd": [[4.4, 7.04]], "batb": [[0, 4.2, 165.96], [1, 4.1, 91.38], [2, 3.9, 10.36]], "batl": [[0, 4.4, 55.8]]}, {"timestamp": 1631459840306, "ltp": 4.4, "tv": 1253.33, "trd": NaN, "batb": NaN, "batl": [[2, 4.6, 56.85]]}, {"timestamp": 1631459850436, "ltp": 4.4, "tv": 1253.33, "trd": NaN, "batb": [[0, 3.75, 3.15], [1, 3.7, 58.28], [2, 3.55, 53.92]], "batl": [[0, 4.6, 2.31], [1, 4.8, 50.9], [2, 4.9, 42.66]]}, {"timestamp": 1631459850716, "ltp": 4.4, "tv": 1253.33, "trd": NaN, "batb": [[0, 3.7, 58.28], [1, 3.55, 53.92], [2, 3.5, 67.58]], "batl": [[0, 4.8, 50.9], [1, 4.9, 42.66], [2, 5, 54.61]]}, {"timestamp": 1631459853615, "ltp": 4.4, "tv": 1253.33, "trd": NaN, "batb": NaN, "batl": [[0, 4.6, 2], [1, 4.8, 50.9], [2, 4.9, 42.66]]}, {"timestamp": 1631459854429, "ltp": 4.4, "tv": 1253.33, "trd": NaN, "batb": NaN, "batl": [[1, 4.8, 53.9]]}, {"timestamp": 1631459857422, "ltp": 4.4, "tv": 1253.33, "trd": NaN, "batb": [[0, 3.75, 35.28], [1, 3.7, 58.28], [2, 3.55, 53.92]], "batl": [[0, 4.5, 10], [1, 4.6, 2], [2, 4.8, 53.9]]}, {"timestamp": 1631459858053, "ltp": 4.4, "tv": 1253.33, "trd": NaN, "batb": [[0, 3.75, 3.27]], "batl": [[1, 4.6, 4.21]]}, {"timestamp": 1631459861442, "ltp": 4.4, "tv": 1253.33, "trd": NaN, "batb": [[0, 3.8, 16.35], [1, 3.75, 3.27], [2, 3.7, 58.28]], "batl": NaN}, {"timestamp": 1631459861727, "ltp": 4.4, "tv": 1253.33, "trd": NaN, "batb": [[0, 3.75, 3.27], [1, 3.7, 58.28], [2, 3.55, 53.92]], "batl": NaN}, {"timestamp": 1631459863715, "ltp": 4.4, "tv": 1253.33, "trd": NaN, "batb": [[0, 3.7, 58.28], [1, 3.55, 53.92], [2, 3.5, 67.58]], "batl": NaN}, {"timestamp": 1631459865271, "ltp": 4.4, "tv": 1253.33, "trd": NaN, "batb": NaN, "batl": [[2, 4.8, 50.9]]}, {"timestamp": 1631459868542, "ltp": 4.4, "tv": 1253.33, "trd": NaN, "batb": [[0, 3.85, 24.51], [1, 3.7, 58.28], [2, 3.55, 53.92]], "batl": [[0, 4.6, 4.21], [1, 4.8, 50.9], [2, 4.9, 42.66]]}, {"timestamp": 1631459869591, "ltp": 4.4, "tv": 1253.33, "trd": NaN, "batb": [[0, 3.7, 58.28], [1, 3.55, 53.92], [2, 3.5, 67.58]], "batl": [[0, 4.6, 2]]}, {"timestamp": 1631459870547, "ltp": 4.4, "tv": 1253.33, "trd": NaN, "batb": [[0, 3.75, 3.31], [1, 3.7, 58.28], [2, 3.55, 53.92]], "batl": NaN}, {"timestamp": 1631459871156, "ltp": 4.4, "tv": 1253.33, "trd": NaN, "batb": [[0, 3.7, 58.28], [1, 3.55, 53.92], [2, 3.5, 67.58]], "batl": NaN}, {"timestamp": 1631459876288, "ltp": 4.4, "tv": 1253.33, "trd": NaN, "batb": [[1, 3.55, 3.19], [2, 3.25, 2]], "batl": [[0, 4.6, 4.21]]}, {"timestamp": 1631459877655, "ltp": 4.4, "tv": 1253.33, "trd": NaN, "batb": [[0, 3.75, 3.27], [1, 3.7, 58.28], [2, 3.55, 3.19]], "batl": [[0, 4.8, 50.9], [1, 4.9, 42.66], [2, 5, 51.61]]}, {"timestamp": 1631459878565, "ltp": 4.4, "tv": 1253.33, "trd": NaN, "batb": [[0, 4.2, 9.62]], "batl": NaN}, {"timestamp": 1631459879594, "ltp": 4.4, "tv": 1253.33, "trd": NaN, "batb": [[0, 4.7, 65.99], [1, 4.3, 81.56], [2, 3.7, 58.28]], "batl": [[0, 4.9, 42.66], [1, 5, 51.61], [2, 6.6, 97.86]]}, {"timestamp": 1631459880422, "ltp": 4.4, "tv": 1253.33, "trd": NaN, "batb": [[2, 3.9, 64.1]], "batl": NaN}, {"timestamp": 1631459882000, "ltp": 4.4, "tv": 1253.33, "trd": NaN, "batb": [[1, 4.3, 83.56], [2, 4.2, 2]], "batl": [[0, 4.9, 55.42]]}, {"timestamp": 1631459883620, "ltp": 4.9, "tv": 1254.75, "trd": [[4.9, 8.69]], "batb": NaN, "batl": [[0, 4.9, 54.71]]}, {"timestamp": 1631459885667, "ltp": 4.9, "tv": 1254.75, "trd": NaN, "batb": NaN, "batl": [[1, 5, 53.61], [2, 5.1, 49.25]]}, {"timestamp": 1631459895494, "ltp": 4.9, "tv": 1254.75, "trd": NaN, "batb": [[0, 4.3, 81.56], [1, 4.1, 2.74], [2, 4, 45.21]], "batl": [[0, 5, 2], [1, 5.1, 49.25], [2, 5.2, 48.88]]}, {"timestamp": 1631459898422, "ltp": 4.9, "tv": 1254.75, "trd": NaN, "batb": NaN, "batl": [[0, 5, 5]]}, {"timestamp": 1631459899019, "ltp": 4.9, "tv": 1254.75, "trd": NaN, "batb": NaN, "batl": [[2, 5.2, 46.5]]}, {"timestamp": 1631459905623, "ltp": 4.9, "tv": 1254.75, "trd": NaN, "batb": NaN, "batl": [[0, 4.9, 2.25], [1, 5, 5], [2, 5.1, 49.25]]}, {"timestamp": 1631459906326, "ltp": 4.9, "tv": 1254.75, "trd": NaN, "batb": NaN, "batl": [[0, 5, 5], [1, 5.1, 49.25], [2, 5.2, 46.5]]}, {"timestamp": 1631459912629, "ltp": 4.9, "tv": 1254.75, "trd": NaN, "batb": NaN, "batl": [[0, 4.9, 2.15], [1, 5, 5], [2, 5.1, 49.25]]}, {"timestamp": 1631459912920, "ltp": 4.9, "tv": 1254.75, "trd": NaN, "batb": NaN, "batl": [[0, 5, 5], [1, 5.1, 49.25], [2, 5.2, 46.5]]}, {"timestamp": 1631459930506, "ltp": 4.9, "tv": 1254.75, "trd": NaN, "batb": [[2, 3.85, 2.97]], "batl": NaN}, {"timestamp": 1631459931493, "ltp": 4.9, "tv": 1254.75, "trd": NaN, "batb": NaN, "batl": [[0, 5, 2]]}, {"timestamp": 1631459933454, "ltp": 4.9, "tv": 1254.75, "trd": NaN, "batb": NaN, "batl": [[0, 4.9, 3], [1, 5, 2], [2, 5.1, 49.25]]}, {"timestamp": 1631459934493, "ltp": 5.0, "tv": 1283.92, "trd": [[5, 104.59]], "batb": [[0, 5, 29.44], [1, 4.5, 2], [2, 4.4, 3]], "batl": [[0, 5.3, 48.58], [1, 5, 0], [2, 5.1, 0]]}, {"timestamp": 1631459935565, "ltp": 5.0, "tv": 1283.92, "trd": NaN, "batb": [[2, 4.4, 36.18]], "batl": [[1, 7.8, 87.04]]}, {"timestamp": 1631459937667, "ltp": 5.0, "tv": 1297.86, "trd": [[5, 118.53]], "batb": [[0, 5, 22.47]], "batl": [[0, 5.2, 15.67], [1, 5.3, 48.58], [2, 7.8, 87.04]]}, {"timestamp": 1631459939566, "ltp": 5.0, "tv": 1297.86, "trd": NaN, "batb": [[0, 5, 65.76], [1, 4.9, 87.11], [2, 4.5, 2]], "batl": [[0, 5.2, 2], [1, 7.8, 87.04], [2, 7.8, 0]]}, {"timestamp": 1631459940175, "ltp": 5.0, "tv": 1297.86, "trd": NaN, "batb": [[0, 4.3, 80.97], [1, 4, 57.18], [2, 3.95, 48.69]], "batl": [[0, 6.4, 34.72], [1, 6.6, 38.96], [2, 6.8, 55.59]]}, {"timestamp": 1631459942567, "ltp": 5.0, "tv": 1297.86, "trd": NaN, "batb": [[0, 4.4, 79.13]], "batl": NaN}, {"timestamp": 1631459943608, "ltp": 5.0, "tv": 1297.86, "trd": NaN, "batb": NaN, "batl": [[0, 6.4, 2], [1, 7, 2], [2, 7.8, 87.04]]}, {"timestamp": 1631459943761, "ltp": 5.0, "tv": 1304.8, "trd": [[5, 125.47]], "batb": NaN, "batl": NaN}, {"timestamp": 1631459945399, "ltp": 5.0, "tv": 1304.8, "trd": NaN, "batb": NaN, "batl": [[2, 7.8, 0]]}, {"timestamp": 1631459947495, "ltp": 5.0, "tv": 1304.8, "trd": NaN, "batb": NaN, "batl": [[0, 5.1, 10], [1, 6.4, 2], [2, 7, 2]]}, {"timestamp": 1631459948476, "ltp": 5.0, "tv": 1304.8, "trd": NaN, "batb": [[1, 4, 59.18], [2, 3.95, 50.69]], "batl": [[0, 5, 3], [1, 6.2, 2], [2, 6.4, 2]]}, {"timestamp": 1631459951488, "ltp": 4.5, "tv": 1305.55, "trd": [[4.5, 2.39]], "batb": NaN, "batl": [[0, 4.6, 20.64], [1, 5, 3], [2, 6.2, 2]]}, {"timestamp": 1631459951700, "ltp": 4.5, "tv": 1305.55, "trd": NaN, "batb": NaN, "batl": [[0, 5, 3], [1, 6.2, 2], [2, 6.4, 2]]}, {"timestamp": 1631459953544, "ltp": 4.5, "tv": 1305.55, "trd": NaN, "batb": NaN, "batl": [[1, 5.3, 44.16], [2, 5.4, 51.44]]}, {"timestamp": 1631459955526, "ltp": 4.5, "tv": 1305.55, "trd": NaN, "batb": NaN, "batl": [[0, 4.9, 20.64], [1, 5, 3], [2, 5.3, 44.16]]}, {"timestamp": 1631459956563, "ltp": 4.5, "tv": 1305.55, "trd": NaN, "batb": [[1, 3.9, 4.46], [2, 3.85, 107.27]], "batl": [[0, 5.3, 44.16], [1, 5.4, 51.44], [2, 5.5, 54.18]]}, {"timestamp": 1631459956998, "ltp": 4.5, "tv": 1305.55, "trd": NaN, "batb": [[0, 3.85, 107.27], [1, 3.7, 4.12], [2, 3.6, 48.71]], "batl": NaN}, {"timestamp": 1631459958644, "ltp": 4.5, "tv": 1305.55, "trd": NaN, "batb": NaN, "batl": [[0, 4.5, 76.01], [1, 4.6, 99.07], [2, 5.3, 44.16]]}, {"timestamp": 1631459959394, "ltp": 4.5, "tv": 1305.55, "trd": NaN, "batb": NaN, "batl": [[0, 5.3, 44.16], [1, 5.4, 51.44], [2, 5.5, 54.18]]}, {"timestamp": 1631459960535, "ltp": 4.5, "tv": 1305.55, "trd": NaN, "batb": NaN, "batl": [[0, 5.3, 47.16]]}, {"timestamp": 1631459967544, "ltp": 4.5, "tv": 1305.55, "trd": NaN, "batb": [[0, 3.9, 4.96], [1, 3.85, 107.27], [2, 3.7, 4.12]], "batl": NaN}, {"timestamp": 1631459967880, "ltp": 4.5, "tv": 1305.55, "trd": NaN, "batb": [[0, 3.85, 107.27], [1, 3.7, 4.12], [2, 3.6, 48.71]], "batl": NaN}, {"timestamp": 1631459971430, "ltp": 4.5, "tv": 1305.55, "trd": NaN, "batb": [[2, 2.62, 380.45]], "batl": [[0, 5.3, 44.16]]}, {"timestamp": 1631459974240, "ltp": 3.85, "tv": 1311.61, "trd": [[3.85, 16.06]], "batb": [[0, 4.7, 14.72], [1, 3.9, 3], [2, 3.85, 107.24]], "batl": NaN}, {"timestamp": 1631459975568, "ltp": 3.85, "tv": 1311.61, "trd": NaN, "batb": [[0, 5.1, 54.26], [1, 4.7, 14.72], [2, 4.3, 80.81]], "batl": NaN}, {"timestamp": 1631459976166, "ltp": 3.85, "tv": 1311.61, "trd": NaN, "batb": NaN, "batl": [[0, 5.2, 10.69], [1, 5.3, 44.16], [2, 5.4, 51.44]]}, {"timestamp": 1631459979144, "ltp": 5.2, "tv": 1312.85, "trd": [[5.2, 134.9]], "batb": NaN, "batl": [[0, 5.2, 10.07]]}, {"timestamp": 1631459981252, "ltp": 5.2, "tv": 1312.85, "trd": NaN, "batb": [[2, 4.4, 4.21]], "batl": NaN}, {"timestamp": 1631459988665, "ltp": 5.2, "tv": 1312.85, "trd": NaN, "batb": [[0, 4.3, 80.81], [1, 4.1, 4.04], [2, 3.95, 59.08]], "batl": [[0, 6.6, 38.66], [1, 6.8, 37.98], [2, 7, 39.66]]}, {"timestamp": 1631459992161, "ltp": 5.2, "tv": 1312.85, "trd": NaN, "batb": NaN, "batl": [[0, 6.6, 41.66]]}, {"timestamp": 1631459993577, "ltp": 5.2, "tv": 1312.85, "trd": NaN, "batb": NaN, "batl": [[0, 4.5, 265.34], [1, 6.6, 3], [2, 8.6, 81.16]]}, {"timestamp": 1631459994285, "ltp": 5.2, "tv": 1312.85, "trd": NaN, "batb": NaN, "batl": [[0, 6.6, 3], [1, 8.6, 81.16], [2, 8.6, 0]]}, {"timestamp": 1631459995369, "ltp": 5.2, "tv": 1312.85, "trd": NaN, "batb": [[0, 4.4, 4.41], [1, 4.3, 80.81], [2, 4.1, 4.04]], "batl": [[1, 8.6, 0]]}, {"timestamp": 1631459996623, "ltp": 5.2, "tv": 1312.85, "trd": NaN, "batb": [[0, 4.3, 83.81], [1, 4.2, 2]], "batl": NaN}, {"timestamp": 1631459997452, "ltp": 5.2, "tv": 1312.85, "trd": NaN, "batb": [[0, 4.3, 80.81], [1, 4.1, 4.04], [2, 3.95, 59.08]], "batl": NaN}, {"timestamp": 1631459998117, "ltp": 5.2, "tv": 1312.85, "trd": NaN, "batb": [[2, 3.95, 62.08]], "batl": [[0, 5.1, 15], [1, 6.4, 2], [2, 6.6, 3]]}, {"timestamp": 1631459999516, "ltp": 5.2, "tv": 1312.85, "trd": NaN, "batb": NaN, "batl": [[0, 4.5, 2], [2, 6.6, 100.86]]}, {"timestamp": 1631460001221, "ltp": 4.5, "tv": 1314.3, "trd": [[4.5, 3.83]], "batb": NaN, "batl": [[0, 4.5, 1.28]]}, {"timestamp": 1631460002620, "ltp": 4.5, "tv": 1314.3, "trd": NaN, "batb": NaN, "batl": [[0, 4.4, 15], [1, 4.5, 1.28], [2, 6.4, 2]]}, {"timestamp": 1631460003488, "ltp": 4.5, "tv": 1314.3, "trd": NaN, "batb": [[0, 4.3, 149.75], [1, 4.2, 87.63], [2, 4.1, 4.04]], "batl": [[0, 4.4, 6.4], [2, 5.3, 42.79]]}, {"timestamp": 1631460005611, "ltp": 4.5, "tv": 1314.3, "trd": NaN, "batb": NaN, "batl": [[1, 4.5, 71.31], [2, 4.6, 91.38]]}, {"timestamp": 1631460006485, "ltp": 4.5, "tv": 1314.3, "trd": NaN, "batb": [[0, 3.75, 62.27], [1, 3.7, 4.82], [2, 3.5, 48.96]], "batl": [[0, 5.3, 42.79], [1, 5.4, 51.17], [2, 5.5, 47.18]]}, {"timestamp": 1631460009585, "ltp": 4.5, "tv": 1314.3, "trd": NaN, "batb": [[0, 3.9, 4.56], [1, 3.75, 62.27], [2, 3.7, 4.82]], "batl": NaN}, {"timestamp": 1631460009908, "ltp": 4.5, "tv": 1314.3, "trd": NaN, "batb": [[0, 3.75, 64.27], [1, 3.7, 6.82], [2, 3.5, 48.96]], "batl": NaN}, {"timestamp": 1631460017221, "ltp": 4.5, "tv": 1314.3, "trd": NaN, "batb": [[2, 2.9, 377.47]], "batl": NaN}, {"timestamp": 1631460020441, "ltp": 4.5, "tv": 1314.3, "trd": NaN, "batb": [[0, 4.8, 14.83], [1, 3.75, 64.27], [2, 3.7, 6.82]], "batl": [[0, 5.4, 51.17], [1, 5.5, 47.18], [2, 6.4, 2]]}, {"timestamp": 1631460021327, "ltp": 4.5, "tv": 1314.3, "trd": NaN, "batb": [[0, 5.2, 52.42], [1, 4.8, 14.83], [2, 4.2, 88.43]], "batl": NaN}, {"timestamp": 1631460022317, "ltp": 4.5, "tv": 1314.3, "trd": NaN, "batb": [[2, 4.2, 146.58]], "batl": [[0, 5.3, 12.74], [1, 5.4, 51.17], [2, 5.5, 47.18]]}, {"timestamp": 1631460023613, "ltp": 4.5, "tv": 1314.3, "trd": NaN, "batb": NaN, "batl": [[0, 5.3, 15.74]]}, {"timestamp": 1631460025233, "ltp": 5.3, "tv": 1315.52, "trd": [[5.3, 4.38]], "batb": NaN, "batl": [[0, 5.3, 15.13]]}, {"timestamp": 1631460026528, "ltp": 5.3, "tv": 1315.52, "trd": NaN, "batb": [[2, 4.4, 4.46]], "batl": NaN}, {"timestamp": 1631460027715, "ltp": 5.2, "tv": 1317.9, "trd": [[5.2, 137.29]], "batb": [[0, 5.2, 50.04]], "batl": NaN}, {"timestamp": 1631460028736, "ltp": 5.2, "tv": 1328.55, "trd": [[5.2, 147.93]], "batb": [[0, 5.2, 44.71]], "batl": NaN}, {"timestamp": 1631460031532, "ltp": 5.2, "tv": 1329.56, "trd": [[5.2, 148.95]], "batb": [[0, 5.2, 43.7]], "batl": NaN}, {"timestamp": 1631460032655, "ltp": 5.2, "tv": 1329.56, "trd": NaN, "batb": [[0, 4.2, 88.43], [1, 4.1, 3.94], [2, 3.8, 3]], "batl": [[0, 8.6, 81.16], [1, 5.4, 0], [2, 5.5, 0]]}, {"timestamp": 1631460035555, "ltp": 5.2, "tv": 1329.56, "trd": NaN, "batb": [[0, 4.2, 2], [1, 4.1, 95.87]], "batl": NaN}, {"timestamp": 1631460036245, "ltp": 5.2, "tv": 1329.56, "trd": NaN, "batb": NaN, "batl": [[0, 7.8, 3], [1, 8.6, 81.16]]}, {"timestamp": 1631460038558, "ltp": 5.2, "tv": 1329.56, "trd": NaN, "batb": [[2, 4, 2]], "batl": NaN}, {"timestamp": 1631460039362, "ltp": 5.2, "tv": 1329.56, "trd": NaN, "batb": NaN, "batl": [[0, 7.4, 3], [1, 7.8, 3], [2, 8.6, 81.16]]}, {"timestamp": 1631460042533, "ltp": 5.2, "tv": 1329.56, "trd": NaN, "batb": [[0, 4.4, 3.81], [1, 4.2, 2], [2, 4.1, 95.87]], "batl": NaN}, {"timestamp": 1631460043649, "ltp": 5.2, "tv": 1329.56, "trd": NaN, "batb": [[0, 4.2, 2], [1, 4.1, 95.87], [2, 4, 2]], "batl": NaN}, {"timestamp": 1631460048570, "ltp": 5.2, "tv": 1329.56, "trd": NaN, "batb": NaN, "batl": [[2, 8.6, 0]]}, {"timestamp": 1631460049568, "ltp": 5.2, "tv": 1329.56, "trd": NaN, "batb": [[0, 6.4, 12.46], [1, 4.2, 2], [2, 4.1, 92.87]], "batl": NaN}, {"timestamp": 1631460050666, "ltp": 5.2, "tv": 1329.56, "trd": NaN, "batb": [[0, 6.8, 55.52], [1, 6.4, 12.46], [2, 5.2, 52.42]], "batl": NaN}, {"timestamp": 1631460051482, "ltp": 5.2, "tv": 1329.56, "trd": NaN, "batb": [[2, 5.5, 10]], "batl": [[0, 7.2, 12.49], [1, 7.4, 3]]}, {"timestamp": 1631460052766, "ltp": 5.2, "tv": 1329.56, "trd": NaN, "batb": NaN, "batl": [[2, 12.5, 65.62]]}, {"timestamp": 1631460054661, "ltp": 7.0, "tv": 1330.0, "trd": [[7, 31.36]], "batb": NaN, "batl": NaN}, {"timestamp": 1631460056480, "ltp": 7.0, "tv": 1330.0, "trd": NaN, "batb": [[1, 6.4, 65.84], [2, 6.2, 73.43]], "batl": NaN}, {"timestamp": 1631460060895, "ltp": 7.0, "tv": 1330.0, "trd": NaN, "batb": NaN, "batl": [[1, 7.4, 50.66], [2, 7.8, 51.87]]}, {"timestamp": 1631460064287, "ltp": 7.0, "tv": 1330.0, "trd": NaN, "batb": [[0, 5.3, 3.08], [1, 5.2, 52.42], [2, 5.1, 3.04]], "batl": [[0, 12.5, 65.62], [1, 7.4, 0], [2, 7.8, 0]]}, {"timestamp": 1631460067395, "ltp": 7.0, "tv": 1330.0, "trd": NaN, "batb": NaN, "batl": [[0, 12.5, 67.62]]}, {"timestamp": 1631460070387, "ltp": 7.0, "tv": 1330.0, "trd": NaN, "batb": NaN, "batl": [[0, 8, 18.9], [1, 12.5, 67.62]]}, {"timestamp": 1631460071531, "ltp": 7.0, "tv": 1330.0, "trd": NaN, "batb": [[0, 5.8, 15.4], [1, 5.3, 3.08], [2, 5.2, 52.42]], "batl": [[0, 8.8, 25.64]]}, {"timestamp": 1631460072914, "ltp": 7.0, "tv": 1330.0, "trd": NaN, "batb": [[0, 5.3, 3.08], [1, 5.2, 52.42], [2, 5.1, 3.04]], "batl": [[0, 12.5, 67.62], [1, 12.5, 0]]}, {"timestamp": 1631460075782, "ltp": 7.0, "tv": 1330.0, "trd": NaN, "batb": [[0, 5.2, 52.42], [1, 5.1, 3.04], [2, 4.8, 2.93]], "batl": NaN}, {"timestamp": 1631460078609, "ltp": 7.0, "tv": 1330.0, "trd": NaN, "batb": [[1, 4.8, 2.93], [2, 4.3, 2]], "batl": NaN}, {"timestamp": 1631460080514, "ltp": 11.0, "tv": 1339.48, "trd": [[11, 9.48]], "batb": NaN, "batl": [[0, 12.5, 2]]}, {"timestamp": 1631460081668, "ltp": 11.0, "tv": 1339.48, "trd": NaN, "batb": [[0, 10, 58.53], [1, 8, 39.36], [2, 4.8, 2.93]], "batl": NaN}, {"timestamp": 1631460082622, "ltp": 11.0, "tv": 1339.48, "trd": NaN, "batb": [[1, 8, 54.26], [2, 5.4, 3]], "batl": [[0, 10.5, 2], [1, 12.5, 2]]}, {"timestamp": 1631460084424, "ltp": 11.0, "tv": 1339.48, "trd": NaN, "batb": NaN, "batl": [[2, 21, 53.46]]}, {"timestamp": 1631460087503, "ltp": 11.0, "tv": 1339.48, "trd": NaN, "batb": [[2, 6.6, 35.37]], "batl": [[2, 13, 19.87]]}, {"timestamp": 1631460088218, "ltp": 11.0, "tv": 1339.48, "trd": NaN, "batb": NaN, "batl": [[1, 11, 40.65], [2, 12.5, 52.04]]}, {"timestamp": 1631460089403, "ltp": 11.0, "tv": 1339.48, "trd": NaN, "batb": [[0, 10, 102.7], [1, 9.2, 59.99], [2, 8, 54.26]], "batl": NaN}, {"timestamp": 1631460092521, "ltp": 11.0, "tv": 1339.48, "trd": NaN, "batb": NaN, "batl": [[0, 10.5, 18.34]]}, {"timestamp": 1631460092842, "ltp": 10.0, "tv": 1363.47, "trd": [[10, 24]], "batb": [[0, 10, 90.7]], "batl": [[0, 10.5, 8.07]]}, {"timestamp": 1631460124076, "ltp": 10.0, "tv": 1363.47, "trd": NaN, "batb": NaN, "batl": [[2, 12.5, 50.04]]}, {"timestamp": 1631460141590, "ltp": 10.5, "tv": 1379.61, "trd": [[10.5, 16.14]], "batb": [[0, 10.5, 46.53], [1, 10, 44.17], [2, 9.2, 59.99]], "batl": [[0, 11, 40.65], [1, 12.5, 50.04], [2, 13, 19.87]]}, {"timestamp": 1631460145507, "ltp": 10.5, "tv": 1394.47, "trd": [[10.5, 31]], "batb": [[0, 10.5, 39.1]], "batl": NaN}, {"timestamp": 1631460157821, "ltp": 10.5, "tv": 1420.07, "trd": [[10.5, 56.6]], "batb": [[0, 10.5, 26.3]], "batl": NaN}, {"timestamp": 1631460159961, "ltp": 10.5, "tv": 1420.26, "trd": [[10.5, 56.79]], "batb": [[0, 10.5, 26.2]], "batl": NaN}, {"timestamp": 1631460165438, "ltp": 10.5, "tv": 1420.26, "trd": NaN, "batb": NaN, "batl": [[0, 11, 48.94]]}, {"timestamp": 1631460174623, "ltp": 10.5, "tv": 1434.72, "trd": [[10.5, 71.25]], "batb": [[0, 10.5, 18.97]], "batl": NaN}, {"timestamp": 1631460177580, "ltp": 10.5, "tv": 1434.72, "trd": NaN, "batb": NaN, "batl": [[0, 11, 40.65]]}, {"timestamp": 1631460199022, "ltp": 10.5, "tv": 1434.72, "trd": NaN, "batb": NaN, "batl": [[0, 11, 48.85]]}, {"timestamp": 1631460214059, "ltp": 10.5, "tv": 1434.72, "trd": NaN, "batb": [[0, 8.4, 36.09], [1, 8, 2], [2, 7.2, 2]], "batl": [[0, 13, 19.87], [1, 13.5, 30.21], [2, 14, 37.14]]}, {"timestamp": 1631460217441, "ltp": 10.5, "tv": 1434.72, "trd": NaN, "batb": [[0, 8.6, 34.08]], "batl": NaN}, {"timestamp": 1631460220448, "ltp": 10.5, "tv": 1434.72, "trd": NaN, "batb": [[0, 8.8, 11.4], [1, 8.6, 34.08], [2, 8, 2]], "batl": [[0, 12, 18.66], [1, 13, 19.87], [2, 13.5, 30.21]]}, {"timestamp": 1631460224922, "ltp": 10.5, "tv": 1434.72, "trd": NaN, "batb": [[0, 8.6, 34.08], [1, 8, 2], [2, 7.2, 2]], "batl": [[0, 13, 19.87], [1, 13.5, 30.21], [2, 14, 37.14]]}, {"timestamp": 1631460235624, "ltp": 10.5, "tv": 1434.72, "trd": NaN, "batb": NaN, "batl": [[0, 8.8, 1060.26], [1, 13, 19.87], [2, 13.5, 30.21]]}, {"timestamp": 1631460235821, "ltp": 10.5, "tv": 1434.72, "trd": NaN, "batb": NaN, "batl": [[0, 13, 19.87], [1, 13.5, 30.21], [2, 14, 37.14]]}, {"timestamp": 1631460237219, "ltp": 10.5, "tv": 1434.72, "trd": NaN, "batb": NaN, "batl": [[0, 18, 2], [1, 21, 53.46], [2, 990, 0.01]]}, {"timestamp": 1631460238401, "ltp": 10.5, "tv": 1434.72, "trd": NaN, "batb": NaN, "batl": [[1, 990, 0.01], [2, 990, 0]]}, {"timestamp": 1631460240325, "ltp": 10.5, "tv": 1434.72, "trd": NaN, "batb": NaN, "batl": [[0, 9.4, 2], [1, 15.5, 2], [2, 18, 2]]}, {"timestamp": 1631460241619, "ltp": 8.6, "tv": 1443.57, "trd": [[8.6, 8.85]], "batb": [[0, 8.6, 29.66]], "batl": NaN}, {"timestamp": 1631460242633, "ltp": 8.6, "tv": 1443.57, "trd": NaN, "batb": NaN, "batl": [[1, 14, 62.31], [2, 15.5, 2]]}, {"timestamp": 1631460243439, "ltp": 8.6, "tv": 1447.57, "trd": [[8.6, 12.85]], "batb": [[0, 8.6, 27.66]], "batl": NaN}, {"timestamp": 1631460244232, "ltp": 8.6, "tv": 1447.57, "trd": NaN, "batb": [[1, 7.2, 2], [2, 6.6, 96.59]], "batl": NaN}, {"timestamp": 1631460245248, "ltp": 8.6, "tv": 1447.57, "trd": NaN, "batb": NaN, "batl": [[0, 9.2, 10], [1, 9.4, 2], [2, 14, 62.31]]}, {"timestamp": 1631460247345, "ltp": 8.6, "tv": 1447.57, "trd": NaN, "batb": NaN, "batl": [[2, 11, 2]]}, {"timestamp": 1631460252447, "ltp": 8.6, "tv": 1447.57, "trd": NaN, "batb": [[0, 6.6, 61.21], [1, 6.2, 2.01], [2, 5.7, 31.65]], "batl": [[0, 11.5, 27.69], [1, 12, 33.76], [2, 12.5, 33.07]]}, {"timestamp": 1631460255667, "ltp": 8.6, "tv": 1447.57, "trd": NaN, "batb": [[0, 6.6, 63.21], [1, 6.4, 2]], "batl": [[0, 11, 2], [1, 11.5, 29.69], [2, 12, 33.76]]}, {"timestamp": 1631460256268, "ltp": 8.6, "tv": 1447.57, "trd": NaN, "batb": NaN, "batl": [[0, 11.5, 29.69], [1, 12, 33.76], [2, 12.5, 33.07]]}, {"timestamp": 1631460262371, "ltp": 8.0, "tv": 1455.57, "trd": [[8, 24.84]], "batb": NaN, "batl": NaN}, {"timestamp": 1631460267272, "ltp": 8.0, "tv": 1455.57, "trd": NaN, "batb": [[1, 5.7, 31.65], [2, 5.6, 39.71]], "batl": NaN}, {"timestamp": 1631460270456, "ltp": 8.0, "tv": 1455.57, "trd": NaN, "batb": [[1, 6.4, 2], [2, 5.7, 31.65]], "batl": NaN}, {"timestamp": 1631460275884, "ltp": 8.0, "tv": 1455.57, "trd": NaN, "batb": [[2, 5.5, 2.12]], "batl": NaN}, {"timestamp": 1631460279588, "ltp": 8.0, "tv": 1455.57, "trd": NaN, "batb": [[0, 10, 59.04], [1, 7.8, 74.17], [2, 6.6, 63.21]], "batl": [[0, 11, 14.78], [1, 11.5, 29.69], [2, 12, 33.76]]}, {"timestamp": 1631460280580, "ltp": 8.0, "tv": 1455.57, "trd": NaN, "batb": [[2, 6.8, 2]], "batl": [[0, 10.5, 2], [1, 11, 14.78], [2, 11.5, 29.69]]}, {"timestamp": 1631460280995, "ltp": 8.0, "tv": 1455.57, "trd": NaN, "batb": NaN, "batl": [[1, 11, 2]]}, {"timestamp": 1631460284532, "ltp": 8.0, "tv": 1455.57, "trd": NaN, "batb": NaN, "batl": [[0, 10.5, 63.46], [1, 11, 65.2]]}, {"timestamp": 1631460285599, "ltp": 8.0, "tv": 1455.57, "trd": NaN, "batb": [[1, 9.2, 45.26], [2, 9, 51.24]], "batl": NaN}, {"timestamp": 1631460291416, "ltp": 8.0, "tv": 1455.57, "trd": NaN, "batb": NaN, "batl": [[1, 11, 63.2], [2, 11.5, 27.69]]}, {"timestamp": 1631460298053, "ltp": 8.0, "tv": 1455.57, "trd": NaN, "batb": [[0, 7.8, 42.12], [1, 6.8, 2], [2, 6.2, 35.83]], "batl": [[0, 13.5, 21.52], [1, 14, 30.6], [2, 14.5, 27.95]]}, {"timestamp": 1631460301328, "ltp": 8.0, "tv": 1455.57, "trd": NaN, "batb": NaN, "batl": [[0, 13.5, 23.52]]}, {"timestamp": 1631460311244, "ltp": 8.0, "tv": 1455.57, "trd": NaN, "batb": NaN, "batl": [[0, 13.5, 4], [1, 21, 53.46], [2, 990, 0.01]]}, {"timestamp": 1631460313628, "ltp": 8.0, "tv": 1455.57, "trd": NaN, "batb": NaN, "batl": [[1, 990, 0.01], [2, 990, 0]]}, {"timestamp": 1631460314127, "ltp": 8.0, "tv": 1455.57, "trd": NaN, "batb": [[1, 6.2, 35.83], [2, 6, 36.78]], "batl": NaN}, {"timestamp": 1631460316661, "ltp": 7.8, "tv": 1459.57, "trd": [[7.8, 4]], "batb": [[0, 7.8, 40.12]], "batl": NaN}, {"timestamp": 1631460317052, "ltp": 7.8, "tv": 1459.57, "trd": NaN, "batb": NaN, "batl": [[0, 12.5, 65.62], [1, 13.5, 4], [2, 990, 0.01]]}, {"timestamp": 1631460318545, "ltp": 7.8, "tv": 1459.57, "trd": NaN, "batb": NaN, "batl": [[0, 8, 20], [1, 12.5, 65.62], [2, 13.5, 4]]}, {"timestamp": 1631460319037, "ltp": 7.8, "tv": 1459.57, "trd": NaN, "batb": NaN, "batl": [[0, 12.5, 65.62], [1, 13.5, 4], [2, 990, 0.01]]}, {"timestamp": 1631460320478, "ltp": 7.8, "tv": 1459.57, "trd": NaN, "batb": [[1, 7.6, 52.59], [2, 7.2, 73.47]], "batl": NaN}, {"timestamp": 1631460321659, "ltp": 7.8, "tv": 1459.57, "trd": NaN, "batb": NaN, "batl": [[0, 11, 2], [1, 12.5, 65.62], [2, 13.5, 4]]}, {"timestamp": 1631460322085, "ltp": 7.8, "tv": 1473.61, "trd": [[7.8, 18.04]], "batb": [[0, 7.8, 33.1]], "batl": [[0, 8.2, 52.24], [1, 8.8, 64.26], [2, 11, 2]]}, {"timestamp": 1631460338510, "ltp": 7.8, "tv": 1473.61, "trd": NaN, "batb": [[0, 5.9, 78.96], [1, 5.5, 2.12], [2, 4.8, 2.58]], "batl": [[0, 11, 2], [1, 12.5, 65.62], [2, 13.5, 4]]}, {"timestamp": 1631460338994, "ltp": 7.8, "tv": 1473.61, "trd": NaN, "batb": NaN, "batl": [[0, 12.5, 65.62], [1, 13.5, 4], [2, 15.5, 2]]}, {"timestamp": 1631460341662, "ltp": 7.8, "tv": 1473.61, "trd": NaN, "batb": [[1, 4.8, 2.58], [2, 3.6, 376.71]], "batl": NaN}, {"timestamp": 1631460342362, "ltp": 7.8, "tv": 1473.61, "trd": NaN, "batb": [[0, 5.9, 81.96], [1, 5.8, 2], [2, 4.8, 2.58]], "batl": [[0, 11, 2], [1, 12.5, 67.62], [2, 13.5, 4]]}, {"timestamp": 1631460345598, "ltp": 7.8, "tv": 1473.61, "trd": NaN, "batb": [[0, 6, 32.97], [1, 5.9, 81.96], [2, 5.8, 2]], "batl": [[0, 8.6, 10], [1, 11, 4], [2, 12.5, 67.62]]}, {"timestamp": 1631460347600, "ltp": 7.8, "tv": 1473.61, "trd": NaN, "batb": [[0, 5.9, 81.96], [1, 5.8, 2], [2, 5.5, 2.12]], "batl": [[0, 11, 4], [1, 12.5, 67.62], [2, 13.5, 4]]}, {"timestamp": 1631460348581, "ltp": 7.8, "tv": 1473.61, "trd": NaN, "batb": NaN, "batl": [[0, 11, 2]]}, {"timestamp": 1631460354317, "ltp": 7.8, "tv": 1473.61, "trd": NaN, "batb": [[1, 5.5, 2.12], [2, 4.8, 2.58]], "batl": [[1, 12.5, 65.62], [2, 13.5, 2]]}, {"timestamp": 1631460354710, "ltp": 7.8, "tv": 1473.61, "trd": NaN, "batb": NaN, "batl": [[0, 11, 4]]}, {"timestamp": 1631460375526, "ltp": 7.8, "tv": 1473.61, "trd": NaN, "batb": NaN, "batl": [[1, 13.5, 2], [2, 15.5, 2]]}, {"timestamp": 1631460377328, "ltp": 7.8, "tv": 1473.61, "trd": NaN, "batb": [[0, 9.6, 65.15], [1, 7, 53.59], [2, 5.9, 3]], "batl": NaN}, {"timestamp": 1631460377934, "ltp": 7.8, "tv": 1473.61, "trd": NaN, "batb": [[1, 7.6, 32.89], [2, 7, 53.59]], "batl": [[0, 10.5, 11.7], [1, 11, 4], [2, 13.5, 2]]}, {"timestamp": 1631460379443, "ltp": 7.8, "tv": 1473.61, "trd": NaN, "batb": [[1, 8.4, 3], [2, 8.2, 3]], "batl": [[0, 10.5, 14.7]]}, {"timestamp": 1631460381335, "ltp": 7.8, "tv": 1473.61, "trd": NaN, "batb": NaN, "batl": [[0, 10, 2], [1, 10.5, 3], [2, 11, 4]]}, {"timestamp": 1631460383663, "ltp": 7.8, "tv": 1473.61, "trd": NaN, "batb": [[1, 9.2, 42.83], [2, 8.6, 53.98]], "batl": NaN}, {"timestamp": 1631460384479, "ltp": 7.8, "tv": 1473.61, "trd": NaN, "batb": NaN, "batl": [[0, 9.8, 14.7], [1, 10, 2], [2, 10.5, 3]]}, {"timestamp": 1631460385340, "ltp": 7.8, "tv": 1473.61, "trd": NaN, "batb": NaN, "batl": [[0, 9.8, 8.32], [2, 10.5, 51.68]]}, {"timestamp": 1631460390759, "ltp": 7.8, "tv": 1473.61, "trd": NaN, "batb": NaN, "batl": [[2, 10.5, 48.68]]}, {"timestamp": 1631460394672, "ltp": 9.6, "tv": 1528.72, "trd": [[9.6, 55.11]], "batb": [[0, 9.6, 37.59]], "batl": NaN}, {"timestamp": 1631460397463, "ltp": 9.6, "tv": 1528.72, "trd": NaN, "batb": NaN, "batl": [[1, 10.5, 48.68], [2, 11, 55.8]]}, {"timestamp": 1631460401359, "ltp": 9.6, "tv": 1528.72, "trd": NaN, "batb": [[1, 8.4, 3], [2, 8.2, 2]], "batl": [[0, 9.8, 3], [1, 11, 2], [2, 13.5, 2]]}, {"timestamp": 1631460402161, "ltp": 9.6, "tv": 1528.72, "trd": NaN, "batb": [[0, 7, 53.59], [1, 6.2, 2.02], [2, 5.5, 2.12]], "batl": [[0, 17, 57.21], [1, 26, 2], [2, 990, 0.01]]}, {"timestamp": 1631460405382, "ltp": 9.6, "tv": 1528.72, "trd": NaN, "batb": [[0, 6.8, 55.77]], "batl": [[0, 15.5, 4], [1, 17, 59.21], [2, 26, 2]]}, {"timestamp": 1631460408301, "ltp": 9.6, "tv": 1528.72, "trd": NaN, "batb": [[1, 6.2, 2], [2, 6, 3]], "batl": NaN}, {"timestamp": 1631460409170, "ltp": 9.6, "tv": 1528.72, "trd": NaN, "batb": NaN, "batl": [[1, 17, 2]]}, {"timestamp": 1631460411581, "ltp": 9.6, "tv": 1528.72, "trd": NaN, "batb": [[0, 12.5, 35.42], [1, 9.2, 71.09], [2, 6.2, 2]], "batl": NaN}, {"timestamp": 1631460412003, "ltp": 9.6, "tv": 1528.72, "trd": NaN, "batb": [[1, 9.8, 25.51], [2, 9.2, 71.09]], "batl": [[0, 15, 13.29], [1, 15.5, 4], [2, 17, 2]]}, {"timestamp": 1631460414585, "ltp": 12.0, "tv": 1619.89, "trd": [[12, 20.33], [12.5, 70.84]], "batb": [[0, 9.8, 25.51], [1, 9.2, 71.09], [2, 7.8, 3]], "batl": [[0, 13, 2]]}, {"timestamp": 1631460415478, "ltp": 12.0, "tv": 1619.89, "trd": NaN, "batb": NaN, "batl": [[0, 12.5, 2], [1, 13, 2], [2, 15.5, 4]]}, {"timestamp": 1631460417412, "ltp": 12.0, "tv": 1619.89, "trd": NaN, "batb": [[1, 9.2, 73.09], [2, 8, 2]], "batl": [[1, 13, 15.29], [2, 15.5, 2]]}, {"timestamp": 1631460419598, "ltp": 12.0, "tv": 1619.89, "trd": NaN, "batb": [[0, 12, 45.22], [1, 11, 62.09], [2, 9.8, 25.51]], "batl": NaN}, {"timestamp": 1631460420507, "ltp": 12.5, "tv": 1620.23, "trd": [[12.5, 71.18]], "batb": NaN, "batl": [[0, 12.5, 1.83]]}, {"timestamp": 1631460425201, "ltp": 12.5, "tv": 1620.23, "trd": NaN, "batb": NaN, "batl": [[1, 13, 59.7], [2, 13.5, 58.93]]}, {"timestamp": 1631460427505, "ltp": 12.5, "tv": 1620.23, "trd": NaN, "batb": NaN, "batl": [[1, 13, 57.7]]}, {"timestamp": 1631460430420, "ltp": 12.5, "tv": 1620.23, "trd": NaN, "batb": [[0, 9.2, 73.09], [1, 8, 2], [2, 7.8, 3]], "batl": [[0, 18, 2], [1, 26, 2], [2, 30, 47.33]]}, {"timestamp": 1631460431310, "ltp": 12.5, "tv": 1620.23, "trd": NaN, "batb": [[0, 9.2, 71.09]], "batl": [[0, 26, 2], [1, 30, 47.33], [2, 990, 0.01]]}, {"timestamp": 1631460433532, "ltp": 12.5, "tv": 1620.23, "trd": NaN, "batb": [[1, 9, 30.4], [2, 8, 2]], "batl": NaN}, {"timestamp": 1631460434635, "ltp": 12.5, "tv": 1620.23, "trd": NaN, "batb": [[0, 9, 30.4], [1, 8, 2], [2, 7.8, 3]], "batl": [[0, 18, 2], [1, 21, 2], [2, 26, 4]]}, {"timestamp": 1631460435431, "ltp": 12.5, "tv": 1620.23, "trd": NaN, "batb": NaN, "batl": [[0, 21, 2], [1, 26, 4], [2, 990, 0.01]]}, {"timestamp": 1631460436630, "ltp": 12.5, "tv": 1620.23, "trd": NaN, "batb": NaN, "batl": [[0, 14, 133.44], [1, 21, 2], [2, 26, 4]]}, {"timestamp": 1631460437629, "ltp": 12.5, "tv": 1620.23, "trd": NaN, "batb": [[0, 9.2, 2], [1, 9, 30.4], [2, 8, 2]], "batl": [[0, 21, 2], [1, 26, 4], [2, 990, 0.01]]}, {"timestamp": 1631460438530, "ltp": 12.5, "tv": 1620.23, "trd": NaN, "batb": [[0, 9.2, 29.17]], "batl": [[0, 14, 10], [1, 18, 2], [2, 21, 2]]}, {"timestamp": 1631460439132, "ltp": 12.5, "tv": 1620.23, "trd": NaN, "batb": [[0, 9.2, 2]], "batl": NaN}, {"timestamp": 1631460442541, "ltp": 12.5, "tv": 1620.23, "trd": NaN, "batb": [[0, 9, 30.4], [1, 8, 2], [2, 7.8, 3]], "batl": [[0, 21, 2], [1, 24, 50.59], [2, 26, 4]]}, {"timestamp": 1631460445753, "ltp": 12.5, "tv": 1620.23, "trd": NaN, "batb": [[0, 9.2, 2], [1, 9, 30.4], [2, 8, 2]], "batl": [[0, 18, 2], [1, 21, 2], [2, 24, 50.59]]}, {"timestamp": 1631460456286, "ltp": 12.5, "tv": 1620.23, "trd": NaN, "batb": [[0, 9, 30.4], [1, 8, 2], [2, 7.8, 3]], "batl": NaN}, {"timestamp": 1631460457575, "ltp": 12.5, "tv": 1620.23, "trd": NaN, "batb": NaN, "batl": [[2, 26, 2]]}, {"timestamp": 1631460459560, "ltp": 12.5, "tv": 1620.23, "trd": NaN, "batb": NaN, "batl": [[0, 11, 2], [1, 18, 2], [2, 21, 2]]}, {"timestamp": 1631460461378, "ltp": 12.5, "tv": 1620.23, "trd": NaN, "batb": NaN, "batl": [[0, 10, 2], [1, 11, 2], [2, 17, 57.21]]}, {"timestamp": 1631460463384, "ltp": 12.5, "tv": 1620.23, "trd": NaN, "batb": NaN, "batl": [[1, 10.5, 10], [2, 11, 2]]}, {"timestamp": 1631460464184, "ltp": 12.5, "tv": 1620.23, "trd": NaN, "batb": NaN, "batl": [[0, 9.8, 2], [1, 10, 2]]}, {"timestamp": 1631460465515, "ltp": 12.5, "tv": 1620.23, "trd": NaN, "batb": [[0, 9.2, 48.65], [1, 9, 30.4], [2, 8.6, 65.42]], "batl": NaN}, {"timestamp": 1631460467173, "ltp": 12.5, "tv": 1620.23, "trd": NaN, "batb": NaN, "batl": [[0, 9.6, 2], [1, 9.8, 2], [2, 10, 2]]}, {"timestamp": 1631460470409, "ltp": 12.5, "tv": 1620.23, "trd": NaN, "batb": NaN, "batl": [[0, 9.4, 2], [1, 9.6, 12], [2, 9.8, 2]]}, {"timestamp": 1631460473595, "ltp": 12.5, "tv": 1620.23, "trd": NaN, "batb": [[0, 6.4, 63.31], [1, 5.3, 2.08], [2, 3.6, 376.71]], "batl": [[0, 13.5, 2], [1, 17, 57.21], [2, 18, 2]]}, {"timestamp": 1631460474097, "ltp": 12.5, "tv": 1620.23, "trd": NaN, "batb": [[1, 6, 2.04], [2, 5.1, 2.04]], "batl": [[0, 17, 57.21], [1, 18, 2], [2, 26, 2]]}, {"timestamp": 1631460477416, "ltp": 12.5, "tv": 1620.23, "trd": NaN, "batb": [[0, 6.4, 65.31], [1, 6.2, 3], [2, 5.3, 2.08]], "batl": [[0, 13.5, 2], [1, 15.5, 2], [2, 17, 59.21]]}, {"timestamp": 1631460480113, "ltp": 12.5, "tv": 1620.23, "trd": NaN, "batb": [[1, 6.2, 5.02]], "batl": NaN}, {"timestamp": 1631460490338, "ltp": 12.5, "tv": 1620.23, "trd": NaN, "batb": [[1, 6.2, 2.02]], "batl": [[2, 17, 57.21]]}, {"timestamp": 1631460492643, "ltp": 12.5, "tv": 1620.23, "trd": NaN, "batb": NaN, "batl": [[2, 18, 2]]}, {"timestamp": 1631460493546, "ltp": 12.5, "tv": 1620.23, "trd": NaN, "batb": [[0, 12, 39.69], [1, 8.8, 31.4], [2, 6.4, 65.31]], "batl": NaN}, {"timestamp": 1631460494525, "ltp": 12.5, "tv": 1620.23, "trd": NaN, "batb": [[1, 9.6, 26.04], [2, 8.8, 31.4]], "batl": [[0, 13, 7.41], [1, 13.5, 2], [2, 15.5, 2]]}, {"timestamp": 1631460495649, "ltp": 12.5, "tv": 1620.23, "trd": NaN, "batb": [[2, 9.4, 2]], "batl": NaN}, {"timestamp": 1631460496564, "ltp": 12.5, "tv": 1620.23, "trd": NaN, "batb": NaN, "batl": [[0, 13, 2]]}, {"timestamp": 1631460498281, "ltp": 12.5, "tv": 1620.23, "trd": NaN, "batb": NaN, "batl": [[0, 12.5, 2], [1, 13, 2], [2, 13.5, 2]]}, {"timestamp": 1631460499668, "ltp": 12.5, "tv": 1620.23, "trd": NaN, "batb": NaN, "batl": [[0, 12.5, 9.41]]}, {"timestamp": 1631460500263, "ltp": 12.5, "tv": 1620.23, "trd": NaN, "batb": [[1, 11, 45.78], [2, 10, 60.01]], "batl": NaN}, {"timestamp": 1631460508374, "ltp": 12.5, "tv": 1620.23, "trd": NaN, "batb": NaN, "batl": [[1, 13.5, 44.02], [2, 15.5, 52.7]]}, {"timestamp": 1631460511272, "ltp": 12.0, "tv": 1699.61, "trd": [[12, 99.72]], "batb": [[0, 11, 45.78], [1, 10, 60.01], [2, 9.6, 26.04]], "batl": [[0, 12, 1.98], [1, 12.5, 9.41], [2, 13.5, 44.02]]}, {"timestamp": 1631460511703, "ltp": 12.0, "tv": 1699.61, "trd": NaN, "batb": [[2, 9.4, 2]], "batl": NaN}, {"timestamp": 1631460514593, "ltp": 12.0, "tv": 1699.61, "trd": NaN, "batb": [[0, 8.8, 31.4], [1, 8, 2], [2, 6.2, 2.02]], "batl": [[1, 26, 2], [2, 30, 47.33]]}, {"timestamp": 1631460515363, "ltp": 12.0, "tv": 1699.61, "trd": NaN, "batb": [[1, 8.6, 2], [2, 8, 2]], "batl": NaN}, {"timestamp": 1631460517451, "ltp": 12.0, "tv": 1699.61, "trd": NaN, "batb": [[0, 8.6, 35.66], [1, 8, 2], [2, 7.6, 2]], "batl": NaN}, {"timestamp": 1631460517889, "ltp": 12.0, "tv": 1699.61, "trd": NaN, "batb": NaN, "batl": [[1, 18, 2], [2, 26, 2]]}, {"timestamp": 1631460526163, "ltp": 12.0, "tv": 1701.59, "trd": [[12, 101.7]], "batb": NaN, "batl": [[0, 18, 2], [1, 26, 2], [2, 30, 47.33]]}, {"timestamp": 1631460527566, "ltp": 12.0, "tv": 1701.59, "trd": NaN, "batb": [[0, 8.6, 33.66]], "batl": NaN}, {"timestamp": 1631460529403, "ltp": 12.0, "tv": 1701.59, "trd": NaN, "batb": NaN, "batl": [[2, 990, 0.01]]}, {"timestamp": 1631460531428, "ltp": 12.0, "tv": 1701.59, "trd": NaN, "batb": [[0, 15, 23.36], [1, 13, 33.16], [2, 9.4, 3]], "batl": [[0, 17.5, 2], [1, 18, 2], [2, 26, 2]]}, {"timestamp": 1631460532238, "ltp": 12.0, "tv": 1701.59, "trd": NaN, "batb": [[2, 12.5, 19.74]], "batl": NaN}, {"timestamp": 1631460534428, "ltp": 12.0, "tv": 1701.59, "trd": NaN, "batb": NaN, "batl": [[0, 17, 2], [1, 17.5, 2], [2, 18, 2]]}, {"timestamp": 1631460536471, "ltp": 12.0, "tv": 1701.59, "trd": NaN, "batb": [[1, 13.5, 34.78], [2, 13, 33.16]], "batl": NaN}, {"timestamp": 1631460537358, "ltp": 12.0, "tv": 1701.59, "trd": NaN, "batb": NaN, "batl": [[0, 16.5, 2], [1, 17, 2], [2, 17.5, 2]]}, {"timestamp": 1631460538634, "ltp": 12.0, "tv": 1701.59, "trd": NaN, "batb": NaN, "batl": [[0, 16.5, 9.25]]}, {"timestamp": 1631460540408, "ltp": 12.0, "tv": 1701.59, "trd": NaN, "batb": NaN, "batl": [[0, 16, 2], [1, 16.5, 9.25], [2, 17, 2]]}, {"timestamp": 1631460545546, "ltp": 15.0, "tv": 1702.21, "trd": [[15, 0.62]], "batb": [[0, 15, 23.05]], "batl": NaN}, {"timestamp": 1631460551835, "ltp": 15.0, "tv": 1702.21, "trd": NaN, "batb": NaN, "batl": [[1, 16.5, 7.25], [2, 18, 34.84]]}, {"timestamp": 1631460562887, "ltp": 15.0, "tv": 1702.21, "trd": NaN, "batb": NaN, "batl": [[0, 15.5, 37.67], [1, 16, 2], [2, 16.5, 7.25]]}, {"timestamp": 1631460587609, "ltp": 15.0, "tv": 1708.97, "trd": [[15, 7.38]], "batb": [[0, 15, 19.67]], "batl": NaN}, {"timestamp": 1631460591608, "ltp": 15.0, "tv": 1740.38, "trd": [[15, 38.79]], "batb": [[0, 15, 3.97]], "batl": NaN}, {"timestamp": 1631460599416, "ltp": 15.0, "tv": 1740.38, "trd": NaN, "batb": [[0, 15, 24.48]], "batl": NaN}, {"timestamp": 1631460599834, "ltp": 15.0, "tv": 1740.38, "trd": NaN, "batb": [[2, 12.5, 54.41]], "batl": NaN}, {"timestamp": 1631460615299, "ltp": 15.0, "tv": 1744.72, "trd": [[15, 43.13]], "batb": [[0, 15, 22.31]], "batl": NaN}, {"timestamp": 1631460619420, "ltp": 15.0, "tv": 1744.72, "trd": NaN, "batb": [[0, 14.5, 24.62]], "batl": NaN}, {"timestamp": 1631460619743, "ltp": 15.0, "tv": 1744.72, "trd": NaN, "batb": [[2, 12.5, 34.67]], "batl": NaN}, {"timestamp": 1631460623240, "ltp": 15.0, "tv": 1744.72, "trd": NaN, "batb": [[0, 14.5, 29.2]], "batl": NaN}, {"timestamp": 1631460656597, "ltp": 15.0, "tv": 1744.72, "trd": NaN, "batb": NaN, "batl": [[0, 15, 1.38], [1, 15.5, 37.67], [2, 16, 2]]}, {"timestamp": 1631460679610, "ltp": 15.0, "tv": 1744.72, "trd": NaN, "batb": NaN, "batl": [[0, 15.5, 37.67], [1, 16, 2], [2, 16.5, 7.25]]}, {"timestamp": 1631460682712, "ltp": 14.5, "tv": 1747.48, "trd": [[14.5, 2.76]], "batb": [[0, 14.5, 27.82]], "batl": NaN}, {"timestamp": 1631460718651, "ltp": 14.5, "tv": 1747.48, "trd": NaN, "batb": [[0, 14.5, 23.24], [1, 12.5, 34.67], [2, 9.4, 3]], "batl": [[0, 42, 43.97], [1, 990, 0.01], [2, 16.5, 0]]}, {"timestamp": 1631460718753, "ltp": 14.5, "tv": 1747.48, "trd": NaN, "batb": [[0, 12.5, 34.67], [1, 9.4, 3], [2, 3.6, 376.71]], "batl": NaN}, {"timestamp": 1631460722094, "ltp": 14.5, "tv": 1747.48, "trd": NaN, "batb": NaN, "batl": [[0, 26, 2], [1, 42, 43.97], [2, 990, 0.01]]}, {"timestamp": 1631460724307, "ltp": 14.5, "tv": 1747.48, "trd": NaN, "batb": [[2, 1.01, 30]], "batl": [[1, 990, 0.01], [2, 990, 0]]}, {"timestamp": 1631460727177, "ltp": 14.5, "tv": 1747.48, "trd": NaN, "batb": [[0, 13, 17.87], [1, 12.5, 34.67], [2, 9.4, 3]], "batl": [[0, 20, 10], [1, 26, 2], [2, 990, 0.01]]}, {"timestamp": 1631460728385, "ltp": 14.5, "tv": 1747.48, "trd": NaN, "batb": NaN, "batl": [[2, 65, 41.05]]}, {"timestamp": 1631460729259, "ltp": 14.5, "tv": 1747.48, "trd": NaN, "batb": [[0, 12.5, 34.67], [1, 9.4, 3], [2, 4.1, 377.07]], "batl": [[0, 26, 2], [1, 65, 41.05], [2, 990, 0.01]]}, {"timestamp": 1631460737459, "ltp": 14.5, "tv": 1747.48, "trd": NaN, "batb": NaN, "batl": [[1, 990, 0.01], [2, 990, 0]]}, {"timestamp": 1631460739398, "ltp": 14.5, "tv": 1747.48, "trd": NaN, "batb": [[0, 13, 2], [1, 12.5, 36.67], [2, 9.4, 3]], "batl": [[0, 20, 2], [1, 26, 2], [2, 990, 0.01]]}, {"timestamp": 1631460740209, "ltp": 14.5, "tv": 1747.48, "trd": NaN, "batb": [[0, 17, 17.42], [1, 14.5, 25.04], [2, 13, 2]], "batl": NaN}, {"timestamp": 1631460741664, "ltp": 14.5, "tv": 1747.48, "trd": NaN, "batb": NaN, "batl": [[2, 95, 39.22]]}, {"timestamp": 1631460742471, "ltp": 14.5, "tv": 1747.48, "trd": NaN, "batb": NaN, "batl": [[0, 19.5, 2], [1, 20, 2], [2, 26, 2]]}, {"timestamp": 1631460743578, "ltp": 14.5, "tv": 1747.48, "trd": NaN, "batb": [[0, 17, 18.32]], "batl": [[0, 19.5, 5.46]]}, {"timestamp": 1631460745492, "ltp": 14.5, "tv": 1747.48, "trd": NaN, "batb": [[1, 15, 2], [2, 14.5, 25.04]], "batl": [[2, 26, 4]]}, {"timestamp": 1631460746111, "ltp": 14.5, "tv": 1747.48, "trd": NaN, "batb": NaN, "batl": [[0, 19, 2], [1, 19.5, 5.46], [2, 20, 2]]}, {"timestamp": 1631460750421, "ltp": 14.5, "tv": 1747.48, "trd": NaN, "batb": [[0, 15, 2], [1, 14.5, 25.04], [2, 13.5, 2]], "batl": [[0, 24, 20.06], [1, 25, 17.24], [2, 26, 29.54]]}, {"timestamp": 1631460750804, "ltp": 14.5, "tv": 1747.48, "trd": NaN, "batb": [[0, 14.5, 25.04], [1, 13.5, 2], [2, 13, 2]], "batl": NaN}, {"timestamp": 1631460754315, "ltp": 14.5, "tv": 1747.48, "trd": NaN, "batb": [[0, 14.5, 27.04], [1, 14, 2], [2, 13.5, 2]], "batl": NaN}, {"timestamp": 1631460758307, "ltp": 14.5, "tv": 1747.48, "trd": NaN, "batb": [[0, 15, 2], [1, 14.5, 27.04], [2, 14, 2]], "batl": [[0, 23, 8.11], [1, 24, 20.06], [2, 25, 17.24]]}, {"timestamp": 1631460759543, "ltp": 14.5, "tv": 1747.48, "trd": NaN, "batb": [[0, 14.5, 27.04], [1, 14, 2], [2, 13.5, 2]], "batl": [[0, 24, 20.06], [1, 25, 17.24], [2, 26, 29.54]]}, {"timestamp": 1631460766626, "ltp": 14.5, "tv": 1747.48, "trd": NaN, "batb": [[0, 15, 2], [1, 14.5, 27.04]], "batl": [[0, 25, 17.24], [1, 26, 29.54], [2, 36, 2]]}, {"timestamp": 1631460767238, "ltp": 14.5, "tv": 1747.48, "trd": NaN, "batb": [[0, 20, 22.61], [1, 17.5, 34], [2, 15, 2]], "batl": NaN}, {"timestamp": 1631460769619, "ltp": 14.5, "tv": 1747.48, "trd": NaN, "batb": [[2, 15, 4]], "batl": [[0, 24, 2.91], [1, 25, 17.24], [2, 26, 29.54]]}, {"timestamp": 1631460770239, "ltp": 14.5, "tv": 1747.48, "trd": NaN, "batb": NaN, "batl": [[0, 24, 4.91]]}, {"timestamp": 1631460772655, "ltp": 14.5, "tv": 1747.48, "trd": NaN, "batb": [[0, 21, 3.26], [1, 20, 22.61], [2, 17.5, 34]], "batl": NaN}, {"timestamp": 1631460773435, "ltp": 14.5, "tv": 1747.48, "trd": NaN, "batb": [[2, 17.5, 36]], "batl": NaN}, {"timestamp": 1631460781541, "ltp": 14.5, "tv": 1747.48, "trd": NaN, "batb": [[0, 21, 35.63], [2, 17.5, 80.89]], "batl": [[2, 26, 27.54]]}, {"timestamp": 1631460788649, "ltp": 14.5, "tv": 1747.48, "trd": NaN, "batb": [[0, 20, 22.61], [1, 17.5, 36], [2, 15, 4]], "batl": [[0, 24, 2], [1, 29, 14.97], [2, 30, 21.45]]}, {"timestamp": 1631460788936, "ltp": 14.5, "tv": 1747.48, "trd": NaN, "batb": [[0, 17.5, 36], [1, 15, 4], [2, 13.5, 2]], "batl": [[0, 29, 14.97], [1, 30, 21.45], [2, 32, 22.8]]}, {"timestamp": 1631460794685, "ltp": 14.5, "tv": 1747.48, "trd": NaN, "batb": [[0, 18.5, 13.51], [1, 17.5, 36], [2, 15, 4]], "batl": [[0, 28, 6.21], [1, 29, 14.97], [2, 30, 21.45]]}, {"timestamp": 1631460798579, "ltp": 14.5, "tv": 1747.48, "trd": NaN, "batb": [[0, 17.5, 36], [1, 15, 4], [2, 13.5, 2]], "batl": [[0, 29, 14.97], [1, 30, 21.45], [2, 32, 22.8]]}, {"timestamp": 1631460801970, "ltp": 14.5, "tv": 1747.48, "trd": NaN, "batb": NaN, "batl": [[0, 21, 1.38], [1, 29, 14.97], [2, 30, 21.45]]}, {"timestamp": 1631460811160, "ltp": 14.5, "tv": 1747.48, "trd": NaN, "batb": NaN, "batl": [[0, 29, 14.97], [1, 30, 21.45], [2, 32, 22.8]]}, {"timestamp": 1631460814367, "ltp": 14.5, "tv": 1747.48, "trd": NaN, "batb": NaN, "batl": [[0, 27, 1.38], [1, 29, 14.97], [2, 30, 21.45]]}, {"timestamp": 1631460818091, "ltp": 14.5, "tv": 1747.48, "trd": NaN, "batb": NaN, "batl": [[0, 29, 14.97], [1, 30, 21.45], [2, 32, 22.8]]}, {"timestamp": 1631460819285, "ltp": 14.5, "tv": 1747.48, "trd": NaN, "batb": [[2, 4.1, 377.07]], "batl": NaN}, {"timestamp": 1631460822384, "ltp": 14.5, "tv": 1747.48, "trd": NaN, "batb": NaN, "batl": [[0, 32, 22.8], [1, 36, 2], [2, 55, 2]]}, {"timestamp": 1631460823578, "ltp": 14.5, "tv": 1747.48, "trd": NaN, "batb": [[0, 24, 12.53], [1, 22, 11.36], [2, 21, 19.41]], "batl": [[0, 29, 1.82], [1, 32, 22.8], [2, 36, 2]]}, {"timestamp": 1631460824494, "ltp": 14.5, "tv": 1747.48, "trd": NaN, "batb": [[1, 21, 19.41], [2, 17.5, 2]], "batl": [[0, 32, 22.8], [1, 36, 2], [2, 55, 2]]}, {"timestamp": 1631460825468, "ltp": 14.5, "tv": 1747.48, "trd": NaN, "batb": [[2, 18, 2]], "batl": [[0, 30, 2], [1, 32, 22.8], [2, 36, 2]]}, {"timestamp": 1631460827074, "ltp": 14.5, "tv": 1747.48, "trd": NaN, "batb": [[0, 25, 11.36], [1, 24, 12.53], [2, 21, 19.41]], "batl": [[0, 29, 1.82], [1, 30, 2], [2, 32, 22.8]]}, {"timestamp": 1631460828360, "ltp": 14.5, "tv": 1747.48, "trd": NaN, "batb": [[0, 24, 12.53], [1, 21, 21.41], [2, 18, 2]], "batl": NaN}, {"timestamp": 1631460829041, "ltp": 14.5, "tv": 1747.48, "trd": NaN, "batb": NaN, "batl": [[0, 29, 3.82]]}, {"timestamp": 1631460834216, "ltp": 14.5, "tv": 1747.48, "trd": NaN, "batb": [[0, 25, 4.13], [1, 24, 12.53], [2, 21, 21.41]], "batl": NaN}, {"timestamp": 1631460835619, "ltp": 14.5, "tv": 1747.48, "trd": NaN, "batb": [[0, 21, 21.41], [1, 18, 2], [2, 17.5, 4]], "batl": [[0, 34, 17.78], [1, 36, 15.71], [2, 38, 16.32]]}, {"timestamp": 1631460835747, "ltp": 14.5, "tv": 1747.48, "trd": NaN, "batb": NaN, "batl": [[1, 36, 13.71]]}, {"timestamp": 1631460838529, "ltp": 14.5, "tv": 1747.48, "trd": NaN, "batb": [[2, 17.5, 2]], "batl": NaN}, {"timestamp": 1631460838824, "ltp": 14.5, "tv": 1747.48, "trd": NaN, "batb": [[0, 24, 2], [1, 23, 2], [2, 21, 23.41]], "batl": NaN}, {"timestamp": 1631460845640, "ltp": 14.5, "tv": 1747.48, "trd": NaN, "batb": [[0, 25, 5.29], [1, 24, 2], [2, 23, 2]], "batl": [[0, 32, 3.8], [1, 34, 17.78], [2, 36, 13.71]]}, {"timestamp": 1631460847748, "ltp": 14.5, "tv": 1747.48, "trd": NaN, "batb": [[0, 24, 2], [1, 23, 2], [2, 21, 23.41]], "batl": [[0, 34, 17.78], [1, 36, 13.71], [2, 38, 16.32]]}, {"timestamp": 1631460850932, "ltp": 14.5, "tv": 1747.48, "trd": NaN, "batb": [[1, 21, 21.41], [2, 17.5, 2]], "batl": NaN}, {"timestamp": 1631460854158, "ltp": 14.5, "tv": 1747.48, "trd": NaN, "batb": [[1, 23, 2], [2, 21, 21.41]], "batl": NaN}, {"timestamp": 1631460855658, "ltp": 14.5, "tv": 1747.48, "trd": NaN, "batb": [[0, 25, 2], [1, 24, 2], [2, 23, 2]], "batl": NaN}, {"timestamp": 1631460856248, "ltp": 14.5, "tv": 1747.48, "trd": NaN, "batb": [[0, 28, 13.47], [1, 25, 2], [2, 24, 2]], "batl": NaN}, {"timestamp": 1631460859627, "ltp": 14.5, "tv": 1747.48, "trd": NaN, "batb": [[0, 29, 4.33], [1, 28, 13.47], [2, 25, 2]], "batl": NaN}, {"timestamp": 1631460878662, "ltp": 29.0, "tv": 1753.48, "trd": [[29, 6]], "batb": [[0, 28, 13.47], [1, 25, 2], [2, 23, 15.09]], "batl": NaN}, {"timestamp": 1631460881636, "ltp": 29.0, "tv": 1753.48, "trd": NaN, "batb": NaN, "batl": [[0, 34, 19.31]]}, {"timestamp": 1631460882825, "ltp": 29.0, "tv": 1753.48, "trd": NaN, "batb": [[0, 29, 4.03], [1, 28, 13.47], [2, 25, 2]], "batl": NaN}, {"timestamp": 1631460895143, "ltp": 29.0, "tv": 1753.48, "trd": NaN, "batb": [[2, 26, 26.13]], "batl": NaN}, {"timestamp": 1631460909590, "ltp": 29.0, "tv": 1753.48, "trd": NaN, "batb": [[0, 28, 13.47], [1, 23, 15.09], [2, 21, 2]], "batl": [[0, 55, 2], [1, 110, 2], [2, 990, 0.01]]}, {"timestamp": 1631460909892, "ltp": 29.0, "tv": 1753.48, "trd": NaN, "batb": [[0, 23, 15.09], [1, 21, 2], [2, 17.5, 2]], "batl": NaN}, {"timestamp": 1631460912584, "ltp": 29.0, "tv": 1753.48, "trd": NaN, "batb": [[1, 17.5, 2], [2, 4.1, 377.07]], "batl": NaN}, {"timestamp": 1631460915279, "ltp": 29.0, "tv": 1753.48, "trd": NaN, "batb": [[1, 21, 2], [2, 17.5, 2]], "batl": [[0, 55, 4]]}, {"timestamp": 1631460916596, "ltp": 29.0, "tv": 1753.48, "trd": NaN, "batb": [[0, 24, 10.42], [1, 23, 15.09], [2, 21, 2]], "batl": [[0, 38, 5.44], [1, 55, 4], [2, 110, 2]]}, {"timestamp": 1631460923613, "ltp": 29.0, "tv": 1753.48, "trd": NaN, "batb": [[0, 23, 15.09], [1, 21, 2], [2, 17.5, 2]], "batl": [[0, 55, 4], [1, 110, 2], [2, 990, 0.01]]}, {"timestamp": 1631460924609, "ltp": 29.0, "tv": 1753.48, "trd": NaN, "batb": NaN, "batl": [[0, 55, 2]]}, {"timestamp": 1631460927626, "ltp": 29.0, "tv": 1753.48, "trd": NaN, "batb": NaN, "batl": [[0, 55, 4]]}, {"timestamp": 1631460933629, "ltp": 29.0, "tv": 1753.48, "trd": NaN, "batb": [[0, 26, 17.23]], "batl": NaN}, {"timestamp": 1631460934118, "ltp": 29.0, "tv": 1753.48, "trd": NaN, "batb": [[0, 30, 8.33], [1, 26, 17.23], [2, 21, 2]], "batl": [[0, 48, 4.34], [1, 55, 4], [2, 110, 2]]}, {"timestamp": 1631460936325, "ltp": 29.0, "tv": 1753.48, "trd": NaN, "batb": [[2, 24, 2]], "batl": [[1, 50, 2], [2, 55, 4]]}, {"timestamp": 1631460937621, "ltp": 29.0, "tv": 1753.48, "trd": NaN, "batb": NaN, "batl": [[0, 46, 2], [1, 48, 4.34], [2, 50, 2]]}, {"timestamp": 1631460937929, "ltp": 29.0, "tv": 1753.48, "trd": NaN, "batb": NaN, "batl": [[1, 50, 2], [2, 55, 4]]}, {"timestamp": 1631460939222, "ltp": 29.0, "tv": 1753.48, "trd": NaN, "batb": [[1, 26, 21.23]], "batl": NaN}, {"timestamp": 1631460940324, "ltp": 29.0, "tv": 1753.48, "trd": NaN, "batb": NaN, "batl": [[0, 44, 2], [1, 46, 2], [2, 50, 2]]}, {"timestamp": 1631460943397, "ltp": 29.0, "tv": 1753.48, "trd": NaN, "batb": NaN, "batl": [[0, 42, 2], [1, 44, 2], [2, 46, 2]]}, {"timestamp": 1631460944402, "ltp": 29.0, "tv": 1753.48, "trd": NaN, "batb": NaN, "batl": [[0, 42, 6.34]]}, {"timestamp": 1631460950209, "ltp": 29.0, "tv": 1753.48, "trd": NaN, "batb": NaN, "batl": [[2, 55, 2]]}, {"timestamp": 1631460951295, "ltp": 29.0, "tv": 1753.48, "trd": NaN, "batb": [[0, 26, 21.23], [1, 24, 2], [2, 21, 2]], "batl": [[0, 55, 2], [1, 110, 2], [2, 990, 0.01]]}, {"timestamp": 1631460962676, "ltp": 29.0, "tv": 1753.48, "trd": NaN, "batb": [[2, 4.1, 377.07]], "batl": NaN}, {"timestamp": 1631460965624, "ltp": 29.0, "tv": 1753.48, "trd": NaN, "batb": [[0, 34, 2], [1, 26, 21.23], [2, 24, 2]], "batl": NaN}, {"timestamp": 1631460966518, "ltp": 29.0, "tv": 1753.48, "trd": NaN, "batb": [[1, 30, 8.04], [2, 26, 21.23]], "batl": [[0, 55, 4]]}, {"timestamp": 1631460966833, "ltp": 29.0, "tv": 1753.48, "trd": NaN, "batb": [[0, 36, 6.94], [1, 34, 2], [2, 30, 8.04]], "batl": [[0, 50, 2.02], [1, 55, 4], [2, 110, 2]]}, {"timestamp": 1631460969023, "ltp": 29.0, "tv": 1753.48, "trd": NaN, "batb": NaN, "batl": [[0, 50, 2]]}, {"timestamp": 1631460972138, "ltp": 29.0, "tv": 1753.48, "trd": NaN, "batb": NaN, "batl": [[0, 48, 2.02], [1, 50, 2], [2, 55, 4]]}, {"timestamp": 1631460975314, "ltp": 29.0, "tv": 1753.48, "trd": NaN, "batb": [[1, 34, 4]], "batl": NaN}, {"timestamp": 1631460977625, "ltp": 29.0, "tv": 1753.48, "trd": NaN, "batb": [[0, 34, 4], [1, 30, 8.04], [2, 26, 4]], "batl": [[0, 110, 2], [1, 990, 0.01], [2, 55, 0]]}, {"timestamp": 1631460977936, "ltp": 29.0, "tv": 1753.48, "trd": NaN, "batb": [[0, 34, 2]], "batl": NaN}, {"timestamp": 1631460981405, "ltp": 29.0, "tv": 1753.48, "trd": NaN, "batb": [[2, 26, 2]], "batl": [[0, 990, 0.01], [1, 990, 0]]}, {"timestamp": 1631460992555, "ltp": 29.0, "tv": 1753.48, "trd": NaN, "batb": [[0, 30, 8.04], [1, 26, 2], [2, 24, 2]], "batl": NaN}, {"timestamp": 1631460996645, "ltp": 29.0, "tv": 1753.48, "trd": NaN, "batb": [[0, 30, 10.04], [1, 29, 2], [2, 26, 2]], "batl": NaN}, {"timestamp": 1631461001155, "ltp": 29.0, "tv": 1753.48, "trd": NaN, "batb": [[0, 40, 6.25], [1, 30, 10.04], [2, 29, 2]], "batl": NaN}, {"timestamp": 1631461003360, "ltp": 29.0, "tv": 1753.48, "trd": NaN, "batb": [[1, 36, 2], [2, 34, 2]], "batl": [[0, 100, 2], [1, 990, 0.01]]}, {"timestamp": 1631461006565, "ltp": 29.0, "tv": 1753.48, "trd": NaN, "batb": NaN, "batl": [[0, 55, 1.05], [1, 100, 2], [2, 990, 0.01]]}, {"timestamp": 1631461007265, "ltp": 29.0, "tv": 1753.48, "trd": NaN, "batb": NaN, "batl": [[0, 95, 2]]}, {"timestamp": 1631461010386, "ltp": 29.0, "tv": 1753.48, "trd": NaN, "batb": NaN, "batl": [[0, 90, 2], [1, 95, 2], [2, 100, 2]]}, {"timestamp": 1631461011575, "ltp": 29.0, "tv": 1753.48, "trd": NaN, "batb": [[0, 36, 2], [1, 34, 2], [2, 30, 8.04]], "batl": NaN}, {"timestamp": 1631461011897, "ltp": 29.0, "tv": 1753.48, "trd": NaN, "batb": [[0, 30, 8.04], [1, 4.1, 377.07], [2, 1.01, 30]], "batl": NaN}, {"timestamp": 1631461013279, "ltp": 29.0, "tv": 1753.48, "trd": NaN, "batb": NaN, "batl": [[0, 85, 2], [1, 90, 2], [2, 95, 2]]}, {"timestamp": 1631461014868, "ltp": 29.0, "tv": 1753.48, "trd": NaN, "batb": [[0, 30, 10.04], [1, 29, 2], [2, 4.1, 377.07]], "batl": NaN}, {"timestamp": 1631461017197, "ltp": 29.0, "tv": 1753.48, "trd": NaN, "batb": [[0, 30, 2]], "batl": NaN}, {"timestamp": 1631461019085, "ltp": 29.0, "tv": 1753.48, "trd": NaN, "batb": NaN, "batl": [[2, 990, 0.01]]}, {"timestamp": 1631461020401, "ltp": 29.0, "tv": 1753.48, "trd": NaN, "batb": [[0, 46, 5.43], [1, 36, 2], [2, 34, 2]], "batl": [[0, 75, 3.06], [1, 80, 2], [2, 85, 2]]}, {"timestamp": 1631461023597, "ltp": 29.0, "tv": 1753.48, "trd": NaN, "batb": NaN, "batl": [[0, 70, 2]]}, {"timestamp": 1631461026290, "ltp": 29.0, "tv": 1753.48, "trd": NaN, "batb": NaN, "batl": [[0, 65, 5.06], [1, 70, 2], [2, 80, 2]]}, {"timestamp": 1631461029290, "ltp": 29.0, "tv": 1753.48, "trd": NaN, "batb": NaN, "batl": [[1, 70, 3.38]]}, {"timestamp": 1631461036524, "ltp": 29.0, "tv": 1753.48, "trd": NaN, "batb": [[2, 4.1, 377.07]], "batl": [[1, 990, 0.01], [2, 80, 0]]}, {"timestamp": 1631461039317, "ltp": 29.0, "tv": 1753.48, "trd": NaN, "batb": NaN, "batl": [[0, 60, 1.38], [1, 65, 5.06], [2, 990, 0.01]]}, {"timestamp": 1631461042523, "ltp": 29.0, "tv": 1753.48, "trd": NaN, "batb": [[0, 36, 2], [1, 4.1, 377.07], [2, 1.01, 30]], "batl": [[1, 990, 0.01], [2, 990, 0]]}, {"timestamp": 1631461044636, "ltp": 29.0, "tv": 1753.48, "trd": NaN, "batb": [[1, 34, 2], [2, 26, 2]], "batl": [[1, 110, 2], [2, 990, 0.01]]}, {"timestamp": 1631461045321, "ltp": 29.0, "tv": 1753.48, "trd": NaN, "batb": [[1, 34, 6], [2, 26, 4]], "batl": NaN}, {"timestamp": 1631461046007, "ltp": 29.0, "tv": 1753.48, "trd": NaN, "batb": [[1, 34, 4]], "batl": NaN}, {"timestamp": 1631461048614, "ltp": 29.0, "tv": 1753.48, "trd": NaN, "batb": [[0, 34, 4], [1, 26, 4], [2, 4.1, 377.07]], "batl": NaN}, {"timestamp": 1631461049420, "ltp": 29.0, "tv": 1753.48, "trd": NaN, "batb": [[1, 30, 7.49], [2, 26, 4]], "batl": NaN}, {"timestamp": 1631461051489, "ltp": 29.0, "tv": 1753.48, "trd": NaN, "batb": NaN, "batl": [[1, 100, 2], [2, 110, 2]]}, {"timestamp": 1631461051952, "ltp": 29.0, "tv": 1753.48, "trd": NaN, "batb": [[0, 34, 2]], "batl": [[0, 100, 2], [1, 110, 2], [2, 990, 0.01]]}, {"timestamp": 1631461055431, "ltp": 29.0, "tv": 1753.48, "trd": NaN, "batb": [[0, 34, 6]], "batl": [[0, 990, 0.01], [1, 110, 0], [2, 990, 0]]}, {"timestamp": 1631461055742, "ltp": 29.0, "tv": 1753.48, "trd": NaN, "batb": [[0, 34, 2], [2, 26, 2]], "batl": NaN}, {"timestamp": 1631461058046, "ltp": 29.0, "tv": 1753.48, "trd": NaN, "batb": [[1, 32, 2], [2, 30, 7.49]], "batl": NaN}, {"timestamp": 1631461060638, "ltp": 29.0, "tv": 1753.48, "trd": NaN, "batb": [[0, 30, 7.49], [1, 26, 2], [2, 4.1, 377.07]], "batl": [[0, 55, 2], [1, 990, 0.01]]}, {"timestamp": 1631461061564, "ltp": 29.0, "tv": 1753.48, "trd": NaN, "batb": [[0, 29, 11.15]], "batl": NaN}, {"timestamp": 1631461063728, "ltp": 29.0, "tv": 1753.48, "trd": NaN, "batb": NaN, "batl": [[0, 50, 2], [1, 55, 2], [2, 990, 0.01]]}, {"timestamp": 1631461067174, "ltp": 29.0, "tv": 1753.48, "trd": NaN, "batb": [[1, 26, 4]], "batl": [[0, 48, 2], [1, 50, 2], [2, 55, 2]]}, {"timestamp": 1631461070415, "ltp": 29.0, "tv": 1753.48, "trd": NaN, "batb": [[0, 34, 4], [1, 30, 2], [2, 29, 13.15]], "batl": [[0, 46, 2], [1, 48, 2], [2, 50, 2]]}, {"timestamp": 1631461071501, "ltp": 29.0, "tv": 1753.48, "trd": NaN, "batb": [[1, 29, 11.15], [2, 26, 4]], "batl": [[0, 110, 2], [1, 990, 0.01], [2, 50, 0]]}, {"timestamp": 1631461072106, "ltp": 29.0, "tv": 1753.48, "trd": NaN, "batb": [[0, 29, 11.15], [1, 26, 4], [2, 4.1, 377.07]], "batl": NaN}, {"timestamp": 1631461073411, "ltp": 29.0, "tv": 1753.48, "trd": NaN, "batb": NaN, "batl": [[0, 44, 2], [1, 110, 2], [2, 990, 0.01]]}, {"timestamp": 1631461073901, "ltp": 29.0, "tv": 1753.48, "trd": NaN, "batb": NaN, "batl": [[0, 110, 2], [1, 990, 0.01], [2, 990, 0]]}, {"timestamp": 1631461075427, "ltp": 29.0, "tv": 1753.48, "trd": NaN, "batb": [[0, 34, 2], [1, 29, 11.15], [2, 28, 2]], "batl": NaN}, {"timestamp": 1631461075705, "ltp": 29.0, "tv": 1753.48, "trd": NaN, "batb": [[0, 29, 11.15], [1, 28, 2], [2, 26, 4]], "batl": NaN}, {"timestamp": 1631461078390, "ltp": 29.0, "tv": 1753.48, "trd": NaN, "batb": [[0, 34, 2], [1, 29, 11.15], [2, 28, 2]], "batl": NaN}, {"timestamp": 1631461078990, "ltp": 29.0, "tv": 1753.48, "trd": NaN, "batb": [[0, 34, 4]], "batl": NaN}, {"timestamp": 1631461080501, "ltp": 29.0, "tv": 1753.48, "trd": NaN, "batb": [[1, 32, 7.81], [2, 29, 11.15]], "batl": [[0, 55, 4.55], [1, 110, 2], [2, 990, 0.01]]}, {"timestamp": 1631461081433, "ltp": 29.0, "tv": 1753.48, "trd": NaN, "batb": [[1, 29, 11.15], [2, 28, 2]], "batl": [[0, 110, 2], [1, 990, 0.01], [2, 990, 0]]}, {"timestamp": 1631461082309, "ltp": 29.0, "tv": 1753.48, "trd": NaN, "batb": [[0, 29, 11.15], [1, 28, 2], [2, 26, 4]], "batl": NaN}, {"timestamp": 1631461085313, "ltp": 29.0, "tv": 1753.48, "trd": NaN, "batb": [[0, 34, 4], [1, 29, 13.15], [2, 28, 2]], "batl": NaN}, {"timestamp": 1631461085911, "ltp": 29.0, "tv": 1753.48, "trd": NaN, "batb": [[0, 29, 13.15], [1, 28, 2], [2, 26, 4]], "batl": NaN}, {"timestamp": 1631461087910, "ltp": 29.0, "tv": 1753.48, "trd": NaN, "batb": [[2, 26, 2]], "batl": NaN}, {"timestamp": 1631461089177, "ltp": 29.0, "tv": 1753.48, "trd": NaN, "batb": [[0, 34, 4], [1, 29, 13.15], [2, 28, 2]], "batl": NaN}, {"timestamp": 1631461091323, "ltp": 29.0, "tv": 1753.48, "trd": NaN, "batb": [[1, 30, 7.83], [2, 29, 2]], "batl": NaN}, {"timestamp": 1631461092616, "ltp": 29.0, "tv": 1753.48, "trd": NaN, "batb": [[0, 36, 6.94], [1, 34, 4], [2, 30, 7.83]], "batl": [[0, 60, 3.69], [1, 110, 2], [2, 990, 0.01]]}, {"timestamp": 1631461094055, "ltp": 29.0, "tv": 1753.48, "trd": NaN, "batb": [[1, 34, 27.4]], "batl": NaN}, {"timestamp": 1631461095530, "ltp": 29.0, "tv": 1753.48, "trd": NaN, "batb": NaN, "batl": [[0, 55, 18.23], [1, 110, 16.18]]}, {"timestamp": 1631461098443, "ltp": 29.0, "tv": 1753.48, "trd": NaN, "batb": NaN, "batl": [[0, 50, 3.69], [1, 55, 18.23], [2, 110, 16.18]]}, {"timestamp": 1631461099641, "ltp": 29.0, "tv": 1753.48, "trd": NaN, "batb": [[0, 34, 2], [1, 30, 7.83], [2, 26, 4]], "batl": [[0, 110, 2], [1, 990, 0.01], [2, 110, 0]]}, {"timestamp": 1631461100525, "ltp": 29.0, "tv": 1753.48, "trd": NaN, "batb": [[0, 34, 4], [2, 26, 2]], "batl": [[0, 990, 0.01], [1, 990, 0]]}, {"timestamp": 1631461100847, "ltp": 29.0, "tv": 1753.48, "trd": NaN, "batb": [[0, 34, 2]], "batl": NaN}, {"timestamp": 1631461103244, "ltp": 29.0, "tv": 1753.48, "trd": NaN, "batb": [[1, 30, 9.83], [2, 28, 2]], "batl": NaN}, {"timestamp": 1631461104334, "ltp": 29.0, "tv": 1753.48, "trd": NaN, "batb": [[1, 30, 7.83], [2, 26, 2]], "batl": NaN}, {"timestamp": 1631461105424, "ltp": 29.0, "tv": 1753.48, "trd": NaN, "batb": [[0, 36, 6.94], [1, 34, 2], [2, 30, 7.83]], "batl": [[0, 110, 2], [1, 990, 0.01]]}, {"timestamp": 1631461106562, "ltp": 29.0, "tv": 1753.48, "trd": NaN, "batb": [[2, 30, 9.83]], "batl": NaN}, {"timestamp": 1631461107640, "ltp": 29.0, "tv": 1753.48, "trd": NaN, "batb": [[1, 34, 4], [2, 30, 11.83]], "batl": NaN}, {"timestamp": 1631461108642, "ltp": 29.0, "tv": 1753.48, "trd": NaN, "batb": NaN, "batl": [[0, 60, 3.62], [1, 110, 2], [2, 990, 0.01]]}, {"timestamp": 1631461112655, "ltp": 29.0, "tv": 1753.48, "trd": NaN, "batb": [[0, 34, 2], [1, 30, 7.83], [2, 26, 2]], "batl": [[0, 990, 0.01], [1, 110, 0], [2, 990, 0]]}, {"timestamp": 1631461116661, "ltp": 29.0, "tv": 1753.48, "trd": NaN, "batb": [[0, 34, 4], [1, 30, 11.83], [2, 28, 4]], "batl": NaN}, {"timestamp": 1631461117585, "ltp": 29.0, "tv": 1753.48, "trd": NaN, "batb": [[1, 30, 9.95]], "batl": [[0, 110, 2], [1, 990, 0.01]]}, {"timestamp": 1631461119661, "ltp": 29.0, "tv": 1753.48, "trd": NaN, "batb": [[0, 50, 2], [1, 34, 4], [2, 30, 9.95]], "batl": NaN}, {"timestamp": 1631461120654, "ltp": 29.0, "tv": 1753.48, "trd": NaN, "batb": [[1, 36, 2], [2, 34, 6]], "batl": NaN}, {"timestamp": 1631461121471, "ltp": 29.0, "tv": 1753.48, "trd": NaN, "batb": [[1, 46, 5.43], [2, 36, 2]], "batl": [[0, 75, 3.09], [1, 110, 2], [2, 990, 0.01]]}, {"timestamp": 1631461121746, "ltp": 29.0, "tv": 1753.48, "trd": NaN, "batb": [[1, 36, 2], [2, 34, 6]], "batl": NaN}, {"timestamp": 1631461123054, "ltp": 29.0, "tv": 1753.48, "trd": NaN, "batb": [[2, 34, 4]], "batl": [[1, 100, 2], [2, 110, 2]]}, {"timestamp": 1631461124481, "ltp": 29.0, "tv": 1753.48, "trd": NaN, "batb": NaN, "batl": [[1, 80, 5.92], [2, 100, 2]]}, {"timestamp": 1631461125195, "ltp": 29.0, "tv": 1753.48, "trd": NaN, "batb": [[0, 50, 2.98]], "batl": [[0, 70, 2], [1, 100, 2], [2, 110, 2]]}, {"timestamp": 1631461126277, "ltp": 29.0, "tv": 1753.48, "trd": NaN, "batb": [[2, 34, 6]], "batl": NaN}, {"timestamp": 1631461128181, "ltp": 29.0, "tv": 1753.48, "trd": NaN, "batb": NaN, "batl": [[0, 65, 5.09], [1, 70, 2], [2, 100, 2]]}, {"timestamp": 1631461132591, "ltp": 29.0, "tv": 1753.48, "trd": NaN, "batb": [[0, 50, 2], [1, 34, 4], [2, 30, 9.95]], "batl": [[0, 110, 2], [1, 990, 0.01], [2, 100, 0]]}, {"timestamp": 1631461142537, "ltp": 29.0, "tv": 1753.48, "trd": NaN, "batb": [[1, 34, 2], [2, 1.01, 30]], "batl": [[0, 990, 0.01], [1, 990, 0]]}, {"timestamp": 1631461145940, "ltp": 29.0, "tv": 1753.48, "trd": NaN, "batb": [[0, 65, 3.85], [1, 50, 2], [2, 34, 2]], "batl": NaN}, {"timestamp": 1631461147563, "ltp": 29.0, "tv": 1753.48, "trd": NaN, "batb": [[1, 34, 2], [2, 1.01, 30]], "batl": [[0, 100, 2], [1, 990, 0.01]]}, {"timestamp": 1631461150562, "ltp": 29.0, "tv": 1753.48, "trd": NaN, "batb": [[1, 50, 4], [2, 34, 4]], "batl": NaN}, {"timestamp": 1631461150874, "ltp": 29.0, "tv": 1753.48, "trd": NaN, "batb": [[1, 34, 4], [2, 1.01, 30]], "batl": [[0, 95, 3.45], [1, 100, 2], [2, 990, 0.01]]}, {"timestamp": 1631461153367, "ltp": 29.0, "tv": 1753.48, "trd": NaN, "batb": [[0, 34, 4], [1, 1.01, 30], [2, 1.01, 0]], "batl": [[0, 990, 0.01], [1, 100, 0], [2, 990, 0]]}, {"timestamp": 1631461154482, "ltp": 29.0, "tv": 1753.48, "trd": NaN, "batb": [[0, 34, 2]], "batl": NaN}, {"timestamp": 1631461156554, "ltp": 29.0, "tv": 1753.48, "trd": NaN, "batb": [[0, 34, 4], [1, 32, 2], [2, 1.01, 30]], "batl": NaN}, {"timestamp": 1631461162382, "ltp": 29.0, "tv": 1753.48, "trd": NaN, "batb": [[0, 34, 2], [1, 1.01, 30], [2, 1.01, 0]], "batl": NaN}, {"timestamp": 1631461164990, "ltp": 29.0, "tv": 1753.48, "trd": NaN, "batb": [[0, 100, 2], [1, 34, 2], [2, 1.01, 30]], "batl": NaN}, {"timestamp": 1631461279539, "ltp": 29.0, "tv": 1753.48, "trd": NaN, "batb": [[0, 1.01, 30], [1, 34, 0], [2, 1.01, 0]], "batl": NaN}, {"timestamp": 1631461303577, "ltp": 29.0, "tv": 1753.48, "trd": NaN, "batb": [[0, 4.7, 377.56], [1, 1.01, 30]], "batl": NaN}, {"timestamp": 1631461304577, "ltp": 29.0, "tv": 1753.48, "trd": NaN, "batb": [[0, 55, 2], [1, 50, 2], [2, 4.7, 377.56]], "batl": NaN}, {"timestamp": 1631461307746, "ltp": 29.0, "tv": 1753.48, "trd": NaN, "batb": [[0, 60, 2], [1, 55, 2], [2, 50, 2]], "batl": NaN}, {"timestamp": 1631461309362, "ltp": 29.0, "tv": 1753.48, "trd": NaN, "batb": NaN, "batl": [[0, 140, 1.55], [1, 990, 0.01]]}, {"timestamp": 1631461309701, "ltp": 29.0, "tv": 1753.48, "trd": NaN, "batb": NaN, "batl": [[0, 990, 0.01], [1, 990, 0]]}, {"timestamp": 1631461312619, "ltp": 29.0, "tv": 1753.48, "trd": NaN, "batb": [[0, 4.7, 377.56], [1, 1.01, 30], [2, 50, 0]], "batl": NaN}, {"timestamp": 1631461315578, "ltp": 29.0, "tv": 1753.48, "trd": NaN, "batb": [[0, 7.6, 3], [1, 7.4, 2], [2, 4.7, 377.56]], "batl": NaN}, {"timestamp": 1631461329591, "ltp": 29.0, "tv": 1753.48, "trd": NaN, "batb": [[1, 4.7, 377.56], [2, 1.01, 30]], "batl": NaN}, {"timestamp": 1631461329802, "ltp": 29.0, "tv": 1753.48, "trd": NaN, "batb": [[0, 70, 3.57], [1, 7.6, 3], [2, 4.7, 377.56]], "batl": NaN}, {"timestamp": 1631461336502, "ltp": 29.0, "tv": 1753.48, "trd": NaN, "batb": NaN, "batl": [[0, 110, 1.76], [1, 990, 0.01]]}, {"timestamp": 1631461336819, "ltp": 29.0, "tv": 1753.48, "trd": NaN, "batb": NaN, "batl": [[0, 990, 0.01], [1, 990, 0]]}, {"timestamp": 1631461340551, "ltp": 29.0, "tv": 1753.48, "trd": NaN, "batb": [[0, 7.6, 3], [1, 4.7, 377.56], [2, 1.01, 30]], "batl": NaN}, {"timestamp": 1631461345556, "ltp": 29.0, "tv": 1753.48, "trd": NaN, "batb": NaN, "batl": [[0, 990, 0.21]]}, {"timestamp": 1631461345710, "ltp": 29.0, "tv": 1753.48, "trd": NaN, "batb": NaN, "batl": [[0, 990, 0.01]]}, {"timestamp": 1631461346842, "ltp": 29.0, "tv": 1753.48, "trd": NaN, "batb": [[0, 65, 3.85], [1, 7.6, 3], [2, 4.7, 377.56]], "batl": NaN}, {"timestamp": 1631461348617, "ltp": 29.0, "tv": 1753.48, "trd": NaN, "batb": NaN, "batl": [[0, 110, 1.05], [1, 990, 0.01]]}, {"timestamp": 1631461349626, "ltp": 29.0, "tv": 1753.48, "trd": NaN, "batb": [[0, 7.6, 3], [1, 4.7, 377.56], [2, 1.01, 30]], "batl": [[0, 990, 0.01], [1, 990, 0]]}, {"timestamp": 1631461361633, "ltp": 29.0, "tv": 1753.48, "trd": NaN, "batb": [[0, 50, 5], [1, 30, 5.36], [2, 7.6, 3]], "batl": NaN}, {"timestamp": 1631461365590, "ltp": 29.0, "tv": 1753.48, "trd": NaN, "batb": NaN, "batl": [[0, 85, 4.48], [1, 990, 0.01]]}, {"timestamp": 1631461365951, "ltp": 29.0, "tv": 1753.48, "trd": NaN, "batb": NaN, "batl": [[0, 990, 0.01], [1, 990, 0]]}, {"timestamp": 1631461367378, "ltp": 29.0, "tv": 1753.48, "trd": NaN, "batb": [[1, 34, 4], [2, 30, 5.36]], "batl": [[0, 100, 2], [1, 110, 2], [2, 990, 0.01]]}, {"timestamp": 1631461368848, "ltp": 29.0, "tv": 1753.48, "trd": NaN, "batb": NaN, "batl": [[0, 80, 4.32], [1, 100, 2], [2, 110, 2]]}, {"timestamp": 1631461370561, "ltp": 29.0, "tv": 1753.48, "trd": NaN, "batb": NaN, "batl": [[1, 95, 2], [2, 100, 2]]}, {"timestamp": 1631461372288, "ltp": 29.0, "tv": 1753.48, "trd": NaN, "batb": [[0, 34, 4], [1, 30, 5.36], [2, 26, 4]], "batl": [[0, 110, 2], [1, 990, 0.01], [2, 100, 0]]}, {"timestamp": 1631461375357, "ltp": 29.0, "tv": 1753.48, "trd": NaN, "batb": [[0, 36, 2], [1, 34, 6], [2, 32, 2]], "batl": NaN}, {"timestamp": 1631461382484, "ltp": 29.0, "tv": 1753.48, "trd": NaN, "batb": [[0, 50, 2], [1, 36, 2], [2, 34, 6]], "batl": NaN}, {"timestamp": 1631461384311, "ltp": 29.0, "tv": 1753.48, "trd": NaN, "batb": [[0, 60, 4.17], [1, 50, 2], [2, 36, 2]], "batl": [[0, 95, 2.2], [1, 110, 2], [2, 990, 0.01]]}, {"timestamp": 1631461385612, "ltp": 29.0, "tv": 1753.48, "trd": NaN, "batb": NaN, "batl": [[1, 100, 2], [2, 110, 2]]}, {"timestamp": 1631461387394, "ltp": 29.0, "tv": 1753.48, "trd": NaN, "batb": NaN, "batl": [[0, 90, 2]]}, {"timestamp": 1631461390505, "ltp": 29.0, "tv": 1753.48, "trd": NaN, "batb": NaN, "batl": [[0, 85, 4.2], [1, 90, 2], [2, 100, 2]]}, {"timestamp": 1631461393519, "ltp": 29.0, "tv": 1753.48, "trd": NaN, "batb": [[0, 50, 2], [1, 36, 2], [2, 34, 2]], "batl": [[0, 110, 2], [1, 990, 0.01], [2, 100, 0]]}, {"timestamp": 1631461393704, "ltp": 29.0, "tv": 1753.48, "trd": NaN, "batb": [[2, 30, 12.06]], "batl": NaN}, {"timestamp": 1631461399614, "ltp": 29.0, "tv": 1753.48, "trd": NaN, "batb": NaN, "batl": [[0, 110, 2.2]]}, {"timestamp": 1631461400611, "ltp": 29.0, "tv": 1753.48, "trd": NaN, "batb": [[2, 34, 2]], "batl": [[0, 110, 2]]}, {"timestamp": 1631461401601, "ltp": 29.0, "tv": 1753.48, "trd": NaN, "batb": [[2, 34, 4]], "batl": NaN}, {"timestamp": 1631461409292, "ltp": 29.0, "tv": 1753.48, "trd": NaN, "batb": [[0, 36, 2], [1, 34, 4], [2, 30, 12.06]], "batl": NaN}, {"timestamp": 1631461412429, "ltp": 29.0, "tv": 1753.48, "trd": NaN, "batb": [[1, 34, 6]], "batl": NaN}, {"timestamp": 1631461413201, "ltp": 29.0, "tv": 1753.48, "trd": NaN, "batb": [[2, 30, 5.36]], "batl": NaN}, {"timestamp": 1631461418556, "ltp": 29.0, "tv": 1753.48, "trd": NaN, "batb": [[0, 38, 2], [1, 36, 2], [2, 34, 2]], "batl": [[0, 100, 2], [1, 110, 2], [2, 990, 0.01]]}, {"timestamp": 1631461421552, "ltp": 29.0, "tv": 1753.48, "trd": NaN, "batb": [[0, 44, 5.68], [1, 38, 2], [2, 36, 2]], "batl": [[0, 70, 3.14], [1, 100, 2], [2, 110, 2]]}, {"timestamp": 1631461421965, "ltp": 29.0, "tv": 1753.48, "trd": NaN, "batb": [[0, 38, 2], [1, 36, 2], [2, 34, 2]], "batl": NaN}, {"timestamp": 1631461425189, "ltp": 29.0, "tv": 1753.48, "trd": NaN, "batb": [[1, 34, 4], [2, 30, 5.36]], "batl": NaN}, {"timestamp": 1631461428390, "ltp": 29.0, "tv": 1753.48, "trd": NaN, "batb": [[0, 42, 5.95], [1, 38, 2], [2, 34, 4]], "batl": NaN}, {"timestamp": 1631461456188, "ltp": 29.0, "tv": 1753.48, "trd": NaN, "batb": NaN, "batl": [[0, 65, 2]]}, {"timestamp": 1631461459287, "ltp": 29.0, "tv": 1753.48, "trd": NaN, "batb": NaN, "batl": [[0, 60, 5.14], [1, 65, 2], [2, 100, 2]]}, {"timestamp": 1631461464586, "ltp": 29.0, "tv": 1753.48, "trd": NaN, "batb": [[0, 34, 4], [1, 30, 5.36], [2, 26, 4]], "batl": [[0, 110, 2], [1, 990, 0.01], [2, 100, 0]]}, {"timestamp": 1631461467695, "ltp": 29.0, "tv": 1753.48, "trd": NaN, "batb": [[0, 30, 5.36], [1, 26, 2], [2, 4.7, 377.56]], "batl": [[0, 990, 0.01], [1, 990, 0]]}, {"timestamp": 1631461470900, "ltp": 29.0, "tv": 1753.48, "trd": NaN, "batb": [[0, 30, 7.36], [1, 29, 2], [2, 26, 2]], "batl": NaN}, {"timestamp": 1631461482950, "ltp": 29.0, "tv": 1753.48, "trd": NaN, "batb": [[1, 26, 2], [2, 4.7, 377.56]], "batl": NaN}, {"timestamp": 1631461486667, "ltp": 29.0, "tv": 1753.48, "trd": NaN, "batb": [[0, 32, 2], [1, 30, 2], [2, 27, 15.63]], "batl": NaN}, {"timestamp": 1631461487541, "ltp": 29.0, "tv": 1753.48, "trd": NaN, "batb": [[0, 34, 7.35], [1, 32, 2], [2, 30, 2]], "batl": NaN}, {"timestamp": 1631461489244, "ltp": 29.0, "tv": 1753.48, "trd": NaN, "batb": NaN, "batl": [[0, 50, 2], [1, 990, 0.01]]}, {"timestamp": 1631461490553, "ltp": 29.0, "tv": 1753.48, "trd": NaN, "batb": NaN, "batl": [[1, 60, 7.58], [2, 990, 0.01]]}, {"timestamp": 1631461491062, "ltp": 29.0, "tv": 1753.48, "trd": NaN, "batb": NaN, "batl": [[1, 990, 0.01], [2, 990, 0]]}, {"timestamp": 1631461492277, "ltp": 29.0, "tv": 1753.48, "trd": NaN, "batb": NaN, "batl": [[0, 48, 4.44], [1, 50, 2], [2, 990, 0.01]]}, {"timestamp": 1631461493535, "ltp": 29.0, "tv": 1753.48, "trd": NaN, "batb": NaN, "batl": [[0, 48, 2]]}, {"timestamp": 1631461497268, "ltp": 29.0, "tv": 1753.48, "trd": NaN, "batb": [[2, 27, 15.63]], "batl": [[0, 46, 2.44], [1, 48, 2], [2, 50, 2]]}, {"timestamp": 1631461500486, "ltp": 29.0, "tv": 1753.48, "trd": NaN, "batb": [[0, 32, 2], [1, 27, 15.63], [2, 4.7, 377.56]], "batl": [[0, 990, 0.01], [1, 48, 0], [2, 50, 0]]}, {"timestamp": 1631461503380, "ltp": 29.0, "tv": 1753.48, "trd": NaN, "batb": [[1, 30, 2], [2, 27, 15.63]], "batl": NaN}, {"timestamp": 1631461508478, "ltp": 29.0, "tv": 1753.48, "trd": NaN, "batb": [[0, 27, 15.63], [1, 4.7, 377.56], [2, 1.01, 30]], "batl": NaN}, {"timestamp": 1631461509472, "ltp": 29.0, "tv": 1753.48, "trd": NaN, "batb": [[1, 23, 14.24], [2, 4.7, 377.56]], "batl": NaN}, {"timestamp": 1631461510552, "ltp": 29.0, "tv": 1753.48, "trd": NaN, "batb": [[0, 32, 3.17], [1, 27, 15.63], [2, 23, 14.24]], "batl": [[0, 50, 2], [1, 990, 0.01]]}, {"timestamp": 1631461510878, "ltp": 29.0, "tv": 1753.48, "trd": NaN, "batb": [[0, 28, 2], [1, 27, 17.63]], "batl": NaN}, {"timestamp": 1631461514081, "ltp": 29.0, "tv": 1753.48, "trd": NaN, "batb": [[0, 29, 7.59], [1, 28, 2], [2, 27, 17.63]], "batl": [[0, 44, 4.79], [1, 50, 2], [2, 990, 0.01]]}, {"timestamp": 1631461516454, "ltp": 29.0, "tv": 1753.48, "trd": NaN, "batb": [[0, 23, 14.24], [1, 4.7, 377.56], [2, 1.01, 30]], "batl": [[0, 990, 0.01], [1, 50, 0], [2, 990, 0]]}, {"timestamp": 1631461528499, "ltp": 29.0, "tv": 1753.48, "trd": NaN, "batb": [[0, 25, 20.22], [1, 23, 14.24], [2, 4.7, 377.56]], "batl": NaN}, {"timestamp": 1631461528815, "ltp": 29.0, "tv": 1753.48, "trd": NaN, "batb": [[1, 4.7, 377.56], [2, 1.01, 30]], "batl": NaN}, {"timestamp": 1631461530108, "ltp": 29.0, "tv": 1753.48, "trd": NaN, "batb": [[0, 34, 7.35], [1, 27, 2], [2, 26, 2]], "batl": [[0, 50, 2], [1, 990, 0.01]]}, {"timestamp": 1631461532592, "ltp": 29.0, "tv": 1753.48, "trd": NaN, "batb": NaN, "batl": [[1, 60, 9.08], [2, 990, 0.01]]}, {"timestamp": 1631461533593, "ltp": 29.0, "tv": 1753.48, "trd": NaN, "batb": NaN, "batl": [[0, 48, 2], [1, 50, 2]]}, {"timestamp": 1631461534204, "ltp": 29.0, "tv": 1753.48, "trd": NaN, "batb": [[2, 26, 6]], "batl": [[2, 110, 2]]}, {"timestamp": 1631461536720, "ltp": 29.0, "tv": 1753.48, "trd": NaN, "batb": NaN, "batl": [[0, 46, 2.54], [1, 48, 2], [2, 50, 2]]}, {"timestamp": 1631461538123, "ltp": 29.0, "tv": 1753.48, "trd": NaN, "batb": [[0, 26, 4], [1, 25, 20.22], [2, 4.7, 377.56]], "batl": [[0, 110, 2], [1, 990, 0.01], [2, 50, 0]]}, {"timestamp": 1631461544297, "ltp": 29.0, "tv": 1753.48, "trd": NaN, "batb": [[0, 26, 6], [1, 25, 22.22]], "batl": NaN}, {"timestamp": 1631461545417, "ltp": 29.0, "tv": 1753.48, "trd": NaN, "batb": [[0, 27, 9.26], [1, 26, 6], [2, 25, 22.22]], "batl": [[0, 44, 5.5], [1, 110, 2], [2, 990, 0.01]]}, {"timestamp": 1631461546518, "ltp": 29.0, "tv": 1753.48, "trd": NaN, "batb": [[0, 27, 11.26]], "batl": [[1, 100, 2], [2, 110, 2]]}, {"timestamp": 1631461547127, "ltp": 29.0, "tv": 1753.48, "trd": NaN, "batb": [[0, 27, 2]], "batl": [[1, 50, 2], [2, 100, 2]]}, {"timestamp": 1631461550642, "ltp": 29.0, "tv": 1753.48, "trd": NaN, "batb": [[0, 28, 9.26], [1, 27, 2], [2, 26, 6]], "batl": [[2, 55, 2]]}, {"timestamp": 1631461556631, "ltp": 29.0, "tv": 1753.48, "trd": NaN, "batb": [[0, 26, 4], [1, 25, 2], [2, 22, 16.28]], "batl": [[0, 55, 2], [1, 100, 2], [2, 110, 2]]}, {"timestamp": 1631461557149, "ltp": 29.0, "tv": 1753.48, "trd": NaN, "batb": [[0, 25, 2], [1, 22, 16.28], [2, 21, 2]], "batl": NaN}, {"timestamp": 1631461560545, "ltp": 29.0, "tv": 1753.48, "trd": NaN, "batb": [[1, 24, 2], [2, 22, 16.28]], "batl": NaN}, {"timestamp": 1631461561635, "ltp": 29.0, "tv": 1753.48, "trd": NaN, "batb": NaN, "batl": [[0, 32, 517.92], [1, 55, 2], [2, 100, 2]]}, {"timestamp": 1631461562657, "ltp": 29.0, "tv": 1753.48, "trd": NaN, "batb": NaN, "batl": [[0, 55, 2], [1, 100, 2], [2, 110, 2]]}, {"timestamp": 1631461563409, "ltp": 29.0, "tv": 1753.48, "trd": NaN, "batb": [[0, 22, 16.28], [1, 21, 2], [2, 4.7, 377.56]], "batl": [[0, 36, 2], [1, 55, 2], [2, 100, 2]]}, {"timestamp": 1631461564366, "ltp": 29.0, "tv": 1753.48, "trd": NaN, "batb": [[2, 17.5, 33.5]], "batl": NaN}, {"timestamp": 1631461565182, "ltp": 29.0, "tv": 1753.48, "trd": NaN, "batb": NaN, "batl": [[0, 36, 8.22]]}, {"timestamp": 1631461566635, "ltp": 29.0, "tv": 1753.48, "trd": NaN, "batb": [[0, 23, 2], [1, 22, 18.28], [2, 21, 2]], "batl": [[0, 34, 2], [1, 36, 8.22], [2, 50, 2]]}, {"timestamp": 1631461567058, "ltp": 29.0, "tv": 1753.48, "trd": NaN, "batb": NaN, "batl": [[1, 36, 2]]}, {"timestamp": 1631461570170, "ltp": 29.0, "tv": 1753.48, "trd": NaN, "batb": NaN, "batl": [[0, 32, 8.22], [1, 34, 2], [2, 36, 2]]}, {"timestamp": 1631461571933, "ltp": 29.0, "tv": 1753.48, "trd": NaN, "batb": [[0, 24, 7.89], [1, 23, 2], [2, 22, 18.28]], "batl": NaN}, {"timestamp": 1631461578571, "ltp": 29.0, "tv": 1753.48, "trd": NaN, "batb": [[2, 22, 16.28]], "batl": [[1, 36, 2], [2, 55, 2]]}, {"timestamp": 1631461580164, "ltp": 29.0, "tv": 1753.48, "trd": NaN, "batb": NaN, "batl": [[1, 36, 21.87], [2, 55, 20.43]]}, {"timestamp": 1631461661191, "ltp": 29.0, "tv": 1753.48, "trd": NaN, "batb": [[0, 23, 2], [1, 22, 16.28], [2, 21, 33.26]], "batl": [[0, 32, 2]]}, {"timestamp": 1631461670199, "ltp": 29.0, "tv": 1753.48, "trd": NaN, "batb": [[0, 24, 7.11], [1, 23, 2], [2, 22, 16.28]], "batl": [[0, 30, 2.59], [1, 32, 2], [2, 36, 21.87]]}, {"timestamp": 1631461677537, "ltp": 29.0, "tv": 1753.48, "trd": NaN, "batb": [[0, 23, 2], [1, 22, 16.28], [2, 21, 2]], "batl": [[0, 32, 2], [1, 36, 2], [2, 55, 2]]}, {"timestamp": 1631461677900, "ltp": 29.0, "tv": 1753.48, "trd": NaN, "batb": [[0, 17.5, 33.5], [1, 4.7, 377.56], [2, 1.01, 30]], "batl": [[0, 55, 2], [1, 110, 2], [2, 520, 36.07]]}, {"timestamp": 1631461684965, "ltp": 29.0, "tv": 1753.48, "trd": NaN, "batb": NaN, "batl": [[2, 990, 0.01]]}, {"timestamp": 1631461687629, "ltp": 29.0, "tv": 1753.48, "trd": NaN, "batb": [[0, 28, 22.34], [1, 21, 20.05], [2, 4.7, 377.56]], "batl": [[0, 46, 5.22], [1, 55, 2], [2, 110, 2]]}, {"timestamp": 1631461688138, "ltp": 29.0, "tv": 1753.48, "trd": NaN, "batb": [[0, 28, 13.41], [2, 18, 2]], "batl": NaN}, {"timestamp": 1631461689747, "ltp": 29.0, "tv": 1753.48, "trd": NaN, "batb": [[1, 27, 2], [2, 26, 2]], "batl": NaN}, {"timestamp": 1631461691663, "ltp": 29.0, "tv": 1753.48, "trd": NaN, "batb": [[0, 29, 8.93], [1, 28, 13.41], [2, 27, 2]], "batl": [[0, 44, 2]]}, {"timestamp": 1631461694454, "ltp": 29.0, "tv": 1753.48, "trd": NaN, "batb": [[0, 21, 20.05], [1, 18, 2], [2, 17.5, 2]], "batl": [[0, 55, 2], [1, 110, 2], [2, 990, 0.01]]}, {"timestamp": 1631461697321, "ltp": 29.0, "tv": 1753.48, "trd": NaN, "batb": NaN, "batl": [[0, 110, 2], [1, 990, 0.01], [2, 990, 0]]}, {"timestamp": 1631461700251, "ltp": 29.0, "tv": 1753.48, "trd": NaN, "batb": [[2, 4.7, 377.56]], "batl": [[0, 55, 2], [1, 110, 2], [2, 990, 0.01]]}, {"timestamp": 1631461700862, "ltp": 29.0, "tv": 1753.48, "trd": NaN, "batb": [[0, 26, 9.62], [1, 21, 20.05], [2, 18, 2]], "batl": [[0, 42, 5.29], [1, 55, 2], [2, 110, 2]]}, {"timestamp": 1631461703477, "ltp": 29.0, "tv": 1753.48, "trd": NaN, "batb": [[0, 21, 20.05], [1, 18, 2], [2, 4.7, 377.56]], "batl": [[0, 55, 2], [1, 110, 2], [2, 990, 0.01]]}, {"timestamp": 1631461703863, "ltp": 29.0, "tv": 1753.48, "trd": NaN, "batb": NaN, "batl": [[0, 110, 2], [1, 990, 0.01], [2, 990, 0]]}, {"timestamp": 1631461707101, "ltp": 29.0, "tv": 1753.48, "trd": NaN, "batb": NaN, "batl": [[0, 55, 2], [1, 110, 2], [2, 990, 0.01]]}, {"timestamp": 1631461712403, "ltp": 29.0, "tv": 1753.48, "trd": NaN, "batb": NaN, "batl": [[0, 36, 2.59], [1, 55, 2], [2, 110, 2]]}, {"timestamp": 1631461713224, "ltp": 29.0, "tv": 1753.48, "trd": NaN, "batb": [[0, 22, 9.59], [1, 21, 22.05], [2, 20, 2]], "batl": [[0, 34, 7.12], [1, 36, 2.59], [2, 55, 2]]}, {"timestamp": 1631461715516, "ltp": 29.0, "tv": 1753.48, "trd": NaN, "batb": [[0, 22, 11.59]], "batl": [[0, 34, 9.12]]}, {"timestamp": 1631461715900, "ltp": 29.0, "tv": 1753.48, "trd": NaN, "batb": [[0, 22, 2]], "batl": NaN}, {"timestamp": 1631461719528, "ltp": 29.0, "tv": 1753.48, "trd": NaN, "batb": [[0, 23, 9.59], [1, 22, 2], [2, 21, 22.05]], "batl": [[0, 32, 15.6], [1, 34, 28.38], [2, 36, 24.92]]}, {"timestamp": 1631461720301, "ltp": 29.0, "tv": 1753.48, "trd": NaN, "batb": NaN, "batl": [[1, 34, 21.26]]}, {"timestamp": 1631461722891, "ltp": 29.0, "tv": 1753.48, "trd": NaN, "batb": NaN, "batl": [[0, 30, 7.12], [1, 32, 15.6], [2, 34, 21.26]]}, {"timestamp": 1631461724532, "ltp": 29.0, "tv": 1753.48, "trd": NaN, "batb": NaN, "batl": [[0, 26, 27.33], [1, 30, 7.12], [2, 32, 15.6]]}, {"timestamp": 1631461725350, "ltp": 29.0, "tv": 1753.48, "trd": NaN, "batb": [[2, 21, 48.32]], "batl": NaN}, {"timestamp": 1631461770106, "ltp": 29.0, "tv": 1753.48, "trd": NaN, "batb": [[0, 16.5, 19.51], [1, 10.5, 27.77], [2, 10, 34.3]], "batl": [[0, 32, 15.6], [1, 34, 19.26], [2, 36, 22.33]]}, {"timestamp": 1631461773303, "ltp": 29.0, "tv": 1753.48, "trd": NaN, "batb": [[0, 16.5, 21.51], [1, 16, 2], [2, 10.5, 27.77]], "batl": NaN}, {"timestamp": 1631461776424, "ltp": 29.0, "tv": 1753.48, "trd": NaN, "batb": [[0, 19, 13.16], [1, 16.5, 21.51], [2, 16, 2]], "batl": [[0, 30, 7.19], [1, 32, 15.6], [2, 34, 19.26]]}, {"timestamp": 1631461779648, "ltp": 29.0, "tv": 1753.48, "trd": NaN, "batb": [[0, 16.5, 21.51], [1, 16, 2], [2, 10.5, 27.77]], "batl": [[0, 32, 15.6], [1, 34, 19.26], [2, 36, 22.33]]}, {"timestamp": 1631461799266, "ltp": 29.0, "tv": 1753.48, "trd": NaN, "batb": [[1, 4.7, 377.56], [2, 1.01, 30]], "batl": NaN}, {"timestamp": 1631461801600, "ltp": 29.0, "tv": 1753.48, "trd": NaN, "batb": NaN, "batl": [[0, 34, 19.26], [1, 36, 22.33], [2, 55, 2]]}, {"timestamp": 1631461803496, "ltp": 29.0, "tv": 1753.48, "trd": NaN, "batb": [[0, 27, 15.89], [1, 20, 23.28], [2, 16.5, 2]], "batl": NaN}, {"timestamp": 1631461804445, "ltp": 29.0, "tv": 1753.48, "trd": NaN, "batb": [[0, 27, 17.89], [1, 26, 2], [2, 20, 23.28]], "batl": NaN}, {"timestamp": 1631461805085, "ltp": 26.0, "tv": 1793.37, "trd": [[26, 4.11], [27, 35.78]], "batb": [[0, 20, 23.28], [1, 17, 2], [2, 16.5, 2]], "batl": NaN}, {"timestamp": 1631461806223, "ltp": 26.0, "tv": 1793.37, "trd": NaN, "batb": [[0, 28, 2], [1, 20, 23.28], [2, 17, 2]], "batl": NaN}, {"timestamp": 1631461808282, "ltp": 26.0, "tv": 1793.37, "trd": NaN, "batb": [[1, 21, 2], [2, 20, 26.28]], "batl": NaN}, {"timestamp": 1631461812525, "ltp": 26.0, "tv": 1793.37, "trd": NaN, "batb": [[1, 26, 27.98], [2, 21, 65.11]], "batl": NaN}, {"timestamp": 1631461813476, "ltp": 26.0, "tv": 1793.37, "trd": NaN, "batb": [[0, 29, 9.26], [1, 28, 2], [2, 26, 27.98]], "batl": NaN}, {"timestamp": 1631461824646, "ltp": 26.0, "tv": 1793.37, "trd": NaN, "batb": [[0, 28, 2], [1, 21, 2], [2, 20, 26.28]], "batl": [[0, 55, 2], [1, 110, 2], [2, 990, 0.01]]}, {"timestamp": 1631461824730, "ltp": 26.0, "tv": 1793.37, "trd": NaN, "batb": [[0, 20, 26.28], [1, 4.7, 377.56], [2, 1.01, 30]], "batl": NaN}, {"timestamp": 1631461827918, "ltp": 26.0, "tv": 1793.37, "trd": NaN, "batb": [[1, 19.5, 2], [2, 4.7, 377.56]], "batl": NaN}, {"timestamp": 1631461840245, "ltp": 26.0, "tv": 1793.37, "trd": NaN, "batb": [[1, 4.7, 377.56], [2, 1.01, 30]], "batl": NaN}, {"timestamp": 1631461843441, "ltp": 26.0, "tv": 1793.37, "trd": NaN, "batb": [[0, 30, 6.7], [1, 27, 15.78], [2, 20, 26.28]], "batl": [[0, 55, 4]]}, {"timestamp": 1631461844425, "ltp": 26.0, "tv": 1793.37, "trd": NaN, "batb": [[0, 36, 6.94], [1, 30, 6.7], [2, 27, 15.78]], "batl": [[0, 50, 1.88], [1, 55, 4], [2, 110, 2]]}, {"timestamp": 1631461846335, "ltp": 26.0, "tv": 1793.37, "trd": NaN, "batb": [[2, 27, 17.78]], "batl": NaN}, {"timestamp": 1631461847609, "ltp": 26.0, "tv": 1793.37, "trd": NaN, "batb": NaN, "batl": [[2, 70, 6.98]]}, {"timestamp": 1631461847825, "ltp": 26.0, "tv": 1793.37, "trd": NaN, "batb": NaN, "batl": [[2, 110, 2]]}, {"timestamp": 1631461850139, "ltp": 26.0, "tv": 1793.37, "trd": NaN, "batb": [[0, 27, 15.78], [1, 20, 3], [2, 4.7, 377.56]], "batl": [[0, 110, 2], [1, 990, 0.01], [2, 110, 0]]}, {"timestamp": 1631461853360, "ltp": 26.0, "tv": 1793.37, "trd": NaN, "batb": NaN, "batl": [[0, 55, 2], [1, 110, 2], [2, 990, 0.01]]}, {"timestamp": 1631461854165, "ltp": 26.0, "tv": 1793.37, "trd": NaN, "batb": NaN, "batl": [[0, 110, 2], [1, 990, 0.01], [2, 990, 0]]}, {"timestamp": 1631461858346, "ltp": 26.0, "tv": 1793.37, "trd": NaN, "batb": [[0, 36, 2], [1, 34, 2], [2, 30, 7.37]], "batl": [[0, 100, 2], [1, 110, 2], [2, 990, 0.01]]}, {"timestamp": 1631461859006, "ltp": 26.0, "tv": 1793.37, "trd": NaN, "batb": [[0, 46, 5.43], [1, 36, 2], [2, 34, 2]], "batl": [[0, 75, 2.92], [1, 100, 2], [2, 110, 2]]}, {"timestamp": 1631461861559, "ltp": 26.0, "tv": 1793.37, "trd": NaN, "batb": [[1, 38, 2], [2, 36, 2]], "batl": [[1, 95, 2], [2, 100, 2]]}, {"timestamp": 1631461862477, "ltp": 26.0, "tv": 1793.37, "trd": NaN, "batb": NaN, "batl": [[0, 70, 2]]}, {"timestamp": 1631461864295, "ltp": 26.0, "tv": 1793.37, "trd": NaN, "batb": NaN, "batl": [[0, 70, 12.24], [1, 75, 13.12], [2, 80, 11.48]]}, {"timestamp": 1631461865567, "ltp": 26.0, "tv": 1793.37, "trd": NaN, "batb": NaN, "batl": [[0, 65, 2.92], [1, 70, 12.24], [2, 75, 13.12]]}, {"timestamp": 1631461865759, "ltp": 26.0, "tv": 1793.37, "trd": NaN, "batb": NaN, "batl": [[0, 65, 1.41]]}, {"timestamp": 1631461877396, "ltp": 26.0, "tv": 1793.37, "trd": NaN, "batb": [[0, 34, 2], [1, 30, 7.37], [2, 28, 2]], "batl": [[0, 70, 10.24], [1, 75, 13.12], [2, 80, 11.48]]}, {"timestamp": 1631461883348, "ltp": 26.0, "tv": 1793.37, "trd": NaN, "batb": [[0, 30, 7.37], [1, 28, 2], [2, 26, 2]], "batl": [[0, 110, 2], [1, 990, 0.01], [2, 80, 0]]}, {"timestamp": 1631461886560, "ltp": 26.0, "tv": 1793.37, "trd": NaN, "batb": [[0, 34, 2], [1, 32, 2], [2, 30, 9.37]], "batl": [[0, 55, 2], [1, 110, 2], [2, 990, 0.01]]}, {"timestamp": 1631461888476, "ltp": 26.0, "tv": 1793.37, "trd": NaN, "batb": [[0, 36, 6.94], [1, 34, 2], [2, 32, 2]], "batl": NaN}, {"timestamp": 1631461888754, "ltp": 26.0, "tv": 1793.37, "trd": NaN, "batb": NaN, "batl": [[1, 100, 2], [2, 110, 2]]}, {"timestamp": 1631461891479, "ltp": 26.0, "tv": 1793.37, "trd": NaN, "batb": NaN, "batl": [[0, 50, 4.17], [1, 55, 2], [2, 100, 2]]}, {"timestamp": 1631461891956, "ltp": 26.0, "tv": 1793.37, "trd": NaN, "batb": NaN, "batl": [[0, 55, 2], [1, 100, 2], [2, 110, 2]]}, {"timestamp": 1631461893180, "ltp": 26.0, "tv": 1793.37, "trd": NaN, "batb": [[0, 27, 14.8], [1, 26, 2], [2, 4.7, 377.56]], "batl": [[0, 100, 2], [1, 110, 2], [2, 990, 0.01]]}, {"timestamp": 1631461895267, "ltp": 26.0, "tv": 1793.37, "trd": NaN, "batb": [[1, 4.7, 377.56], [2, 1.01, 30]], "batl": NaN}, {"timestamp": 1631461896479, "ltp": 26.0, "tv": 1793.37, "trd": NaN, "batb": NaN, "batl": [[0, 55, 2], [1, 100, 2], [2, 110, 2]]}, {"timestamp": 1631461896785, "ltp": 26.0, "tv": 1793.37, "trd": NaN, "batb": NaN, "batl": [[0, 100, 2], [1, 110, 2], [2, 990, 0.01]]}, {"timestamp": 1631461898858, "ltp": 26.0, "tv": 1793.37, "trd": NaN, "batb": [[0, 38, 6.58], [1, 27, 14.8], [2, 4.7, 377.56]], "batl": [[0, 60, 3.59], [1, 100, 2], [2, 110, 2]]}, {"timestamp": 1631461900285, "ltp": 26.0, "tv": 1793.37, "trd": NaN, "batb": NaN, "batl": [[0, 55, 2]]}, {"timestamp": 1631461903361, "ltp": 26.0, "tv": 1793.37, "trd": NaN, "batb": NaN, "batl": [[0, 55, 5.59]]}, {"timestamp": 1631461906505, "ltp": 38.0, "tv": 1793.66, "trd": [[38, 0.29]], "batb": [[0, 38, 6.29]], "batl": NaN}, {"timestamp": 1631461907208, "ltp": 38.0, "tv": 1793.66, "trd": NaN, "batb": NaN, "batl": [[0, 100, 2], [1, 110, 2], [2, 990, 0.01]]}, {"timestamp": 1631461908273, "ltp": 38.0, "tv": 1793.66, "trd": NaN, "batb": [[0, 27, 14.8], [1, 4.7, 377.56], [2, 1.01, 30]], "batl": NaN}, {"timestamp": 1631461913592, "ltp": 38.0, "tv": 1793.66, "trd": NaN, "batb": NaN, "batl": [[0, 55, 2], [1, 60, 2], [2, 100, 2]]}, {"timestamp": 1631461915400, "ltp": 38.0, "tv": 1793.66, "trd": NaN, "batb": [[0, 27, 16.8], [1, 26, 2], [2, 4.7, 377.56]], "batl": [[0, 36, 2.59], [1, 55, 2], [2, 60, 2]]}, {"timestamp": 1631461916294, "ltp": 38.0, "tv": 1793.66, "trd": NaN, "batb": [[0, 29, 8.62], [1, 27, 16.8], [2, 26, 2]], "batl": [[1, 46, 4.7], [2, 55, 2]]}, {"timestamp": 1631461916784, "ltp": 38.0, "tv": 1793.66, "trd": NaN, "batb": [[1, 28, 2], [2, 27, 16.8]], "batl": [[2, 50, 2]]}, {"timestamp": 1631461922329, "ltp": 38.0, "tv": 1793.66, "trd": NaN, "batb": NaN, "batl": [[1, 38, 13.19], [2, 40, 17.23]]}, {"timestamp": 1631461926295, "ltp": 38.0, "tv": 1793.66, "trd": NaN, "batb": [[0, 24, 12.8], [1, 13.5, 22.44], [2, 13, 25.41]], "batl": [[0, 38, 13.19], [1, 40, 17.23], [2, 42, 15.07]]}, {"timestamp": 1631461929547, "ltp": 38.0, "tv": 1793.66, "trd": NaN, "batb": [[0, 24, 14.8], [1, 23, 2], [2, 13.5, 22.44]], "batl": NaN}, {"timestamp": 1631461940288, "ltp": 38.0, "tv": 1793.66, "trd": NaN, "batb": [[2, 4.7, 377.56]], "batl": NaN}, {"timestamp": 1631461943529, "ltp": 38.0, "tv": 1793.66, "trd": NaN, "batb": [[1, 4.7, 377.56], [2, 1.01, 30]], "batl": [[0, 55, 2], [1, 990, 0.01], [2, 42, 0]]}, {"timestamp": 1631461943921, "ltp": 38.0, "tv": 1793.66, "trd": NaN, "batb": [[0, 34, 7.35], [1, 30, 8], [2, 26, 18.17]], "batl": NaN}, {"timestamp": 1631461946625, "ltp": 38.0, "tv": 1793.66, "trd": NaN, "batb": [[2, 27, 2]], "batl": [[0, 50, 4.98], [1, 55, 2], [2, 990, 0.01]]}, {"timestamp": 1631461947314, "ltp": 38.0, "tv": 1793.66, "trd": NaN, "batb": NaN, "batl": [[0, 50, 2]]}, {"timestamp": 1631461949505, "ltp": 38.0, "tv": 1793.66, "trd": NaN, "batb": NaN, "batl": [[2, 110, 2]]}, {"timestamp": 1631461950412, "ltp": 38.0, "tv": 1793.66, "trd": NaN, "batb": [[0, 34, 33.37]], "batl": [[0, 48, 2.98], [1, 50, 2], [2, 55, 2]]}, {"timestamp": 1631461956605, "ltp": 38.0, "tv": 1793.66, "trd": NaN, "batb": [[0, 26, 18.17], [1, 24, 2], [2, 4.7, 377.56]], "batl": [[0, 55, 2], [1, 110, 2], [2, 990, 0.01]]}, {"timestamp": 1631461956815, "ltp": 38.0, "tv": 1793.66, "trd": NaN, "batb": NaN, "batl": [[0, 110, 2], [1, 990, 0.01], [2, 990, 0]]}, {"timestamp": 1631461963635, "ltp": 38.0, "tv": 1793.66, "trd": NaN, "batb": NaN, "batl": [[0, 55, 2], [1, 110, 2], [2, 990, 0.01]]}, {"timestamp": 1631461964427, "ltp": 38.0, "tv": 1793.66, "trd": NaN, "batb": NaN, "batl": [[0, 110, 2], [1, 990, 0.01], [2, 990, 0]]}, {"timestamp": 1631461967415, "ltp": 38.0, "tv": 1793.66, "trd": NaN, "batb": NaN, "batl": [[0, 55, 2], [1, 110, 2], [2, 990, 0.01]]}, {"timestamp": 1631461970210, "ltp": 38.0, "tv": 1793.66, "trd": NaN, "batb": NaN, "batl": [[0, 36, 2.07], [1, 55, 2], [2, 110, 2]]}, {"timestamp": 1631461971552, "ltp": 38.0, "tv": 1793.66, "trd": NaN, "batb": [[0, 27, 9.26], [2, 23, 14.74]], "batl": [[1, 44, 5.5], [2, 55, 2]]}, {"timestamp": 1631461971829, "ltp": 38.0, "tv": 1793.66, "trd": NaN, "batb": NaN, "batl": [[1, 55, 2], [2, 110, 2]]}, {"timestamp": 1631461973529, "ltp": 38.0, "tv": 1793.66, "trd": NaN, "batb": [[0, 27, 11.26], [1, 26, 2], [2, 24, 2]], "batl": [[1, 50, 2], [2, 55, 2]]}, {"timestamp": 1631461974008, "ltp": 38.0, "tv": 1793.66, "trd": NaN, "batb": [[0, 27, 2], [2, 25, 2]], "batl": NaN}, {"timestamp": 1631461975236, "ltp": 38.0, "tv": 1793.66, "trd": NaN, "batb": [[0, 28, 2], [1, 27, 2], [2, 26, 2]], "batl": NaN}, {"timestamp": 1631461977329, "ltp": 38.0, "tv": 1793.66, "trd": NaN, "batb": [[0, 24, 2], [1, 23, 14.74], [2, 4.7, 377.56]], "batl": [[0, 55, 2], [1, 110, 2], [2, 990, 0.01]]}, {"timestamp": 1631461980163, "ltp": 38.0, "tv": 1793.66, "trd": NaN, "batb": NaN, "batl": [[0, 36, 2], [1, 55, 2], [2, 110, 2]]}, {"timestamp": 1631461999656, "ltp": 38.0, "tv": 1793.66, "trd": NaN, "batb": [[0, 30, 8.63], [1, 24, 14.66], [2, 23, 14.74]], "batl": [[0, 55, 2], [1, 110, 2], [2, 990, 0.01]]}, {"timestamp": 1631462000017, "ltp": 38.0, "tv": 1793.66, "trd": NaN, "batb": [[2, 4.7, 377.56]], "batl": NaN}, {"timestamp": 1631462000697, "ltp": 38.0, "tv": 1793.66, "trd": NaN, "batb": [[0, 32, 7.81], [1, 30, 8.63], [2, 24, 14.66]], "batl": NaN}, {"timestamp": 1631462002666, "ltp": 38.0, "tv": 1793.66, "trd": NaN, "batb": [[2, 27, 2]], "batl": [[0, 50, 2], [1, 55, 2], [2, 110, 2]]}, {"timestamp": 1631462003634, "ltp": 38.0, "tv": 1793.66, "trd": NaN, "batb": NaN, "batl": [[2, 60, 8.94]]}, {"timestamp": 1631462003832, "ltp": 38.0, "tv": 1793.66, "trd": NaN, "batb": NaN, "batl": [[2, 110, 2]]}, {"timestamp": 1631462005410, "ltp": 38.0, "tv": 1793.66, "trd": NaN, "batb": NaN, "batl": [[0, 48, 2], [1, 50, 2], [2, 55, 2]]}, {"timestamp": 1631462009112, "ltp": 38.0, "tv": 1793.66, "trd": NaN, "batb": NaN, "batl": [[0, 46, 3.82], [1, 48, 2], [2, 50, 2]]}, {"timestamp": 1631462010352, "ltp": 38.0, "tv": 1793.66, "trd": NaN, "batb": [[0, 24, 14.66], [1, 4.7, 377.56], [2, 1.01, 30]], "batl": [[0, 110, 2], [1, 990, 0.01], [2, 50, 0]]}, {"timestamp": 1631462013646, "ltp": 38.0, "tv": 1793.66, "trd": NaN, "batb": NaN, "batl": [[0, 55, 2], [1, 110, 2], [2, 990, 0.01]]}, {"timestamp": 1631462013867, "ltp": 38.0, "tv": 1793.66, "trd": NaN, "batb": NaN, "batl": [[0, 110, 2], [1, 990, 0.01], [2, 990, 0]]}, {"timestamp": 1631462019350, "ltp": 38.0, "tv": 1793.66, "trd": NaN, "batb": [[1, 23, 2], [2, 4.7, 377.56]], "batl": NaN}, {"timestamp": 1631462024140, "ltp": 38.0, "tv": 1793.66, "trd": NaN, "batb": NaN, "batl": [[0, 55, 2], [1, 110, 2], [2, 990, 0.01]]}, {"timestamp": 1631462027412, "ltp": 38.0, "tv": 1793.66, "trd": NaN, "batb": [[0, 25, 2], [1, 24, 14.66], [2, 23, 2]], "batl": [[0, 50, 2], [1, 100, 2], [2, 110, 2]]}, {"timestamp": 1631462027669, "ltp": 38.0, "tv": 1793.66, "trd": NaN, "batb": NaN, "batl": [[0, 100, 2], [1, 110, 2], [2, 990, 0.01]]}, {"timestamp": 1631462030388, "ltp": 38.0, "tv": 1793.66, "trd": NaN, "batb": [[1, 24, 12.66], [2, 4.7, 377.56]], "batl": [[0, 55, 2], [1, 100, 2], [2, 110, 2]]}, {"timestamp": 1631462032466, "ltp": 38.0, "tv": 1793.66, "trd": NaN, "batb": [[2, 18, 31.49]], "batl": [[0, 36, 2.07], [1, 55, 2], [2, 100, 2]]}, {"timestamp": 1631462033217, "ltp": 38.0, "tv": 1793.66, "trd": NaN, "batb": [[0, 26, 7.74], [1, 25, 2], [2, 24, 12.66]], "batl": NaN}, {"timestamp": 1631462036619, "ltp": 38.0, "tv": 1793.66, "trd": NaN, "batb": NaN, "batl": [[0, 34, 2.95], [1, 36, 2.07], [2, 44, 9.36]]}, {"timestamp": 1631462036797, "ltp": 38.0, "tv": 1793.66, "trd": NaN, "batb": NaN, "batl": [[2, 55, 2]]}, {"timestamp": 1631462097066, "ltp": 26.0, "tv": 1795.1, "trd": [[26, 5.55]], "batb": [[0, 26, 7.02]], "batl": NaN}, {"timestamp": 1631462100895, "ltp": 26.0, "tv": 1795.1, "trd": NaN, "batb": NaN, "batl": [[1, 36, 23.64], [2, 55, 21.51]]}, {"timestamp": 1631462103605, "ltp": 26.0, "tv": 1795.1, "trd": NaN, "batb": NaN, "batl": [[1, 36, 43.85], [2, 55, 42.51]]}, {"timestamp": 1631462107176, "ltp": 26.0, "tv": 1795.1, "trd": NaN, "batb": [[0, 26, 26.71]], "batl": NaN}, {"timestamp": 1631462110302, "ltp": 26.0, "tv": 1795.1, "trd": NaN, "batb": [[0, 27, 7.02], [1, 26, 26.71], [2, 25, 2]], "batl": NaN}, {"timestamp": 1631462114298, "ltp": 26.0, "tv": 1795.1, "trd": NaN, "batb": [[0, 25, 2], [1, 24, 12.66], [2, 18, 31.49]], "batl": [[1, 36, 2.07], [2, 55, 2]]}, {"timestamp": 1631462117592, "ltp": 26.0, "tv": 1795.1, "trd": NaN, "batb": [[0, 26, 7.64], [1, 25, 2], [2, 24, 12.66]], "batl": NaN}, {"timestamp": 1631462128426, "ltp": 26.0, "tv": 1795.1, "trd": NaN, "batb": [[0, 25, 2], [1, 24, 12.66], [2, 18, 31.49]], "batl": [[0, 36, 2.07], [1, 55, 2], [2, 100, 2]]}, {"timestamp": 1631462131615, "ltp": 26.0, "tv": 1795.1, "trd": NaN, "batb": [[0, 26, 2], [1, 25, 2], [2, 24, 12.66]], "batl": NaN}, {"timestamp": 1631462135845, "ltp": 26.0, "tv": 1795.1, "trd": NaN, "batb": [[0, 27, 5.6], [1, 26, 2], [2, 25, 2]], "batl": [[0, 34, 3.02], [1, 36, 2.07], [2, 55, 2]]}, {"timestamp": 1631462146566, "ltp": 26.0, "tv": 1795.1, "trd": NaN, "batb": [[2, 24, 12.66]], "batl": NaN}, {"timestamp": 1631462148395, "ltp": 26.0, "tv": 1795.1, "trd": NaN, "batb": [[0, 18, 31.49], [1, 4.7, 377.56], [2, 1.01, 30]], "batl": [[0, 55, 2], [1, 100, 2], [2, 110, 2]]}, {"timestamp": 1631462148698, "ltp": 26.0, "tv": 1795.1, "trd": NaN, "batb": NaN, "batl": [[0, 100, 2], [1, 110, 2], [2, 990, 0.01]]}, {"timestamp": 1631462152274, "ltp": 26.0, "tv": 1795.1, "trd": NaN, "batb": [[0, 18, 33.49], [1, 17.5, 2], [2, 4.7, 377.56]], "batl": NaN}, {"timestamp": 1631462154582, "ltp": 26.0, "tv": 1795.1, "trd": NaN, "batb": NaN, "batl": [[0, 36, 77.15], [1, 100, 2], [2, 110, 2]]}, {"timestamp": 1631462155595, "ltp": 26.0, "tv": 1795.1, "trd": NaN, "batb": NaN, "batl": [[0, 55, 2]]}, {"timestamp": 1631462156659, "ltp": 26.0, "tv": 1795.1, "trd": NaN, "batb": [[0, 22, 11.36], [1, 18, 33.49], [2, 17.5, 2]], "batl": [[0, 36, 6.56], [1, 55, 2], [2, 100, 2]]}, {"timestamp": 1631462157593, "ltp": 26.0, "tv": 1795.1, "trd": NaN, "batb": [[0, 18, 33.49], [1, 17.5, 2], [2, 4.7, 377.56]], "batl": [[0, 100, 2], [1, 110, 2], [2, 990, 0.01]]}, {"timestamp": 1631462160798, "ltp": 26.0, "tv": 1795.1, "trd": NaN, "batb": NaN, "batl": [[0, 55, 2], [1, 100, 2], [2, 110, 2]]}, {"timestamp": 1631462165177, "ltp": 26.0, "tv": 1795.1, "trd": NaN, "batb": [[1, 4.7, 377.56], [2, 1.01, 30]], "batl": NaN}, {"timestamp": 1631462168618, "ltp": 26.0, "tv": 1795.1, "trd": NaN, "batb": [[0, 30, 7.83], [1, 22, 16.35], [2, 18, 33.49]], "batl": [[0, 55, 4]]}, {"timestamp": 1631462169406, "ltp": 26.0, "tv": 1795.1, "trd": NaN, "batb": [[0, 34, 7.35], [1, 30, 7.83], [2, 27, 2]], "batl": [[0, 50, 2], [1, 55, 4], [2, 100, 2]]}, {"timestamp": 1631462172401, "ltp": 26.0, "tv": 1795.1, "trd": NaN, "batb": NaN, "batl": [[0, 48, 3.13], [1, 50, 2], [2, 55, 4]]}, {"timestamp": 1631462190544, "ltp": 26.0, "tv": 1795.1, "trd": NaN, "batb": [[0, 22, 16.35], [1, 18.5, 2], [2, 4.7, 377.56]], "batl": [[0, 55, 2], [1, 110, 2], [2, 990, 0.01]]}, {"timestamp": 1631462193504, "ltp": 26.0, "tv": 1795.1, "trd": NaN, "batb": [[0, 22, 18.35], [1, 21, 2], [2, 18.5, 2]], "batl": NaN}, {"timestamp": 1631462198233, "ltp": 26.0, "tv": 1795.1, "trd": NaN, "batb": [[0, 30, 8.33], [1, 22, 18.35], [2, 21, 2]], "batl": [[0, 48, 4.69], [1, 55, 2], [2, 110, 2]]}, {"timestamp": 1631462200608, "ltp": 26.0, "tv": 1795.1, "trd": NaN, "batb": [[0, 22, 18.35], [1, 21, 2], [2, 18.5, 2]], "batl": [[0, 55, 2], [1, 110, 2], [2, 990, 0.01]]}, {"timestamp": 1631462205638, "ltp": 26.0, "tv": 1795.1, "trd": NaN, "batb": [[1, 4.7, 377.56], [2, 1.01, 30]], "batl": NaN}, {"timestamp": 1631462207516, "ltp": 26.0, "tv": 1795.1, "trd": NaN, "batb": [[1, 16, 20.35], [2, 4.7, 377.56]], "batl": [[0, 36, 2.07], [1, 55, 2], [2, 110, 2]]}, {"timestamp": 1631462208519, "ltp": 26.0, "tv": 1795.1, "trd": NaN, "batb": [[0, 23, 10.78], [1, 22, 18.35], [2, 16, 20.35]], "batl": NaN}, {"timestamp": 1631462209429, "ltp": 26.0, "tv": 1795.1, "trd": NaN, "batb": [[0, 23, 2], [2, 21, 2]], "batl": [[0, 34, 2], [1, 36, 2.07], [2, 50, 2]]}, {"timestamp": 1631462211452, "ltp": 26.0, "tv": 1795.1, "trd": NaN, "batb": [[0, 24, 2], [1, 23, 2], [2, 22, 18.35]], "batl": [[0, 32, 8.49], [1, 34, 2], [2, 36, 2.07]]}, {"timestamp": 1631462215482, "ltp": 26.0, "tv": 1795.1, "trd": NaN, "batb": [[0, 25, 10.78], [1, 24, 2], [2, 23, 2]], "batl": NaN}, {"timestamp": 1631462220299, "ltp": 26.0, "tv": 1795.1, "trd": NaN, "batb": [[0, 16, 20.35], [1, 4.7, 377.56], [2, 1.01, 30]], "batl": [[0, 55, 2], [1, 110, 2], [2, 990, 0.01]]}, {"timestamp": 1631462220691, "ltp": 26.0, "tv": 1795.1, "trd": NaN, "batb": NaN, "batl": [[0, 110, 2], [1, 990, 0.01], [2, 990, 0]]}, {"timestamp": 1631462223862, "ltp": 26.0, "tv": 1795.1, "trd": NaN, "batb": NaN, "batl": [[0, 55, 2], [1, 110, 2], [2, 990, 0.01]]}, {"timestamp": 1631462225481, "ltp": 26.0, "tv": 1795.1, "trd": NaN, "batb": NaN, "batl": [[0, 110, 2], [1, 990, 0.01], [2, 990, 0]]}, {"timestamp": 1631462228299, "ltp": 34.0, "tv": 1795.25, "trd": [[34, 0.15]], "batb": NaN, "batl": NaN}, {"timestamp": 1631462229498, "ltp": 34.0, "tv": 1795.25, "trd": NaN, "batb": [[0, 20, 12.5], [1, 16, 20.35], [2, 4.7, 377.56]], "batl": [[0, 34, 7.35], [1, 55, 2], [2, 110, 2]]}, {"timestamp": 1631462230614, "ltp": 34.0, "tv": 1795.25, "trd": NaN, "batb": [[0, 16, 20.35], [1, 4.7, 377.56], [2, 1.01, 30]], "batl": [[0, 55, 2], [1, 110, 2], [2, 520, 36.07]]}, {"timestamp": 1631462231607, "ltp": 34.0, "tv": 1795.25, "trd": NaN, "batb": NaN, "batl": [[0, 110, 2], [1, 520, 36.07], [2, 990, 0.01]]}, {"timestamp": 1631462234106, "ltp": 34.0, "tv": 1795.25, "trd": NaN, "batb": NaN, "batl": [[0, 55, 2], [1, 110, 2], [2, 520, 36.07]]}, {"timestamp": 1631462238484, "ltp": 34.0, "tv": 1795.25, "trd": NaN, "batb": NaN, "batl": [[2, 990, 0.01]]}, {"timestamp": 1631462241598, "ltp": 34.0, "tv": 1795.25, "trd": NaN, "batb": [[0, 32, 7.81], [1, 30, 8.33], [2, 21, 19.73]], "batl": [[0, 50, 5.84], [1, 55, 2], [2, 110, 2]]}, {"timestamp": 1631462242591, "ltp": 34.0, "tv": 1795.25, "trd": NaN, "batb": [[2, 22, 2]], "batl": [[0, 50, 2]]}, {"timestamp": 1631462242923, "ltp": 34.0, "tv": 1795.25, "trd": NaN, "batb": [[2, 27, 2]], "batl": NaN}, {"timestamp": 1631462244514, "ltp": 34.0, "tv": 1796.96, "trd": [[34, 1.86]], "batb": NaN, "batl": NaN}, {"timestamp": 1631462245112, "ltp": 34.0, "tv": 1796.96, "trd": NaN, "batb": NaN, "batl": [[0, 48, 2], [1, 50, 2], [2, 55, 2]]}, {"timestamp": 1631462248210, "ltp": 34.0, "tv": 1796.96, "trd": NaN, "batb": NaN, "batl": [[0, 46, 3.84], [1, 48, 2], [2, 50, 2]]}, {"timestamp": 1631462251623, "ltp": 34.0, "tv": 1796.96, "trd": NaN, "batb": [[0, 30, 8.33], [1, 22, 2], [2, 21, 21.73]], "batl": [[0, 110, 2], [1, 990, 0.01], [2, 50, 0]]}, {"timestamp": 1631462252335, "ltp": 34.0, "tv": 1796.96, "trd": NaN, "batb": [[0, 22, 2], [1, 21, 21.73], [2, 18, 2]], "batl": [[0, 990, 0.01], [1, 990, 0]]}, {"timestamp": 1631462255524, "ltp": 34.0, "tv": 1796.96, "trd": NaN, "batb": [[1, 21, 19.73], [2, 4.7, 377.56]], "batl": NaN}, {"timestamp": 1631462256547, "ltp": 34.0, "tv": 1796.96, "trd": NaN, "batb": NaN, "batl": [[0, 48, 64.39], [1, 990, 0.01]]}, {"timestamp": 1631462257345, "ltp": 34.0, "tv": 1796.96, "trd": NaN, "batb": NaN, "batl": [[0, 990, 0.01], [1, 990, 0]]}, {"timestamp": 1631462258644, "ltp": 34.0, "tv": 1796.96, "trd": NaN, "batb": [[0, 30, 8.33], [1, 22, 2], [2, 21, 21.73]], "batl": [[0, 110, 2], [1, 990, 0.01]]}, {"timestamp": 1631462259642, "ltp": 34.0, "tv": 1796.96, "trd": NaN, "batb": NaN, "batl": [[0, 48, 2.15], [1, 110, 2], [2, 990, 0.01]]}, {"timestamp": 1631462260328, "ltp": 34.0, "tv": 1796.96, "trd": NaN, "batb": [[0, 22, 2], [1, 21, 21.73], [2, 4.7, 377.56]], "batl": [[0, 990, 0.01], [1, 110, 0], [2, 990, 0]]}, {"timestamp": 1631462264654, "ltp": 34.0, "tv": 1796.96, "trd": NaN, "batb": NaN, "batl": [[0, 110, 2], [1, 990, 0.01]]}, {"timestamp": 1631462267138, "ltp": 34.0, "tv": 1796.96, "trd": NaN, "batb": NaN, "batl": [[0, 36, 2.07], [1, 110, 2], [2, 990, 0.01]]}, {"timestamp": 1631462268472, "ltp": 34.0, "tv": 1796.96, "trd": NaN, "batb": [[0, 23, 7.44], [1, 22, 2], [2, 21, 21.73]], "batl": NaN}, {"timestamp": 1631462268858, "ltp": 34.0, "tv": 1796.96, "trd": NaN, "batb": NaN, "batl": [[2, 520, 36.07]]}, {"timestamp": 1631462270564, "ltp": 34.0, "tv": 1796.96, "trd": NaN, "batb": [[0, 23, 2], [1, 21, 19.73], [2, 14, 28.39]], "batl": [[0, 34, 2], [1, 36, 2.07], [2, 110, 2]]}, {"timestamp": 1631462271553, "ltp": 34.0, "tv": 1796.96, "trd": NaN, "batb": NaN, "batl": [[0, 30, 6.95], [1, 34, 2], [2, 36, 2.07]]}, {"timestamp": 1631462272078, "ltp": 34.0, "tv": 1796.96, "trd": NaN, "batb": NaN, "batl": [[0, 34, 2], [1, 36, 2.07], [2, 110, 2]]}, {"timestamp": 1631462273553, "ltp": 34.0, "tv": 1796.96, "trd": NaN, "batb": NaN, "batl": [[2, 55, 2]]}, {"timestamp": 1631462273669, "ltp": 34.0, "tv": 1796.96, "trd": NaN, "batb": [[0, 24, 7.44], [1, 23, 2], [2, 21, 19.73]], "batl": NaN}, {"timestamp": 1631462275051, "ltp": 34.0, "tv": 1796.96, "trd": NaN, "batb": NaN, "batl": [[0, 26, 25.72], [1, 32, 6.95], [2, 34, 2]]}, {"timestamp": 1631462278653, "ltp": 34.0, "tv": 1796.96, "trd": NaN, "batb": NaN, "batl": [[0, 32, 6.95], [1, 34, 2], [2, 36, 2.07]]}, {"timestamp": 1631462282166, "ltp": 34.0, "tv": 1796.96, "trd": NaN, "batb": NaN, "batl": [[0, 30, 2]]}, {"timestamp": 1631462285470, "ltp": 34.0, "tv": 1796.96, "trd": NaN, "batb": [[0, 14, 28.39], [1, 4.7, 377.56], [2, 1.01, 30]], "batl": [[0, 55, 2], [1, 110, 2], [2, 520, 36.07]]}, {"timestamp": 1631462286863, "ltp": 34.0, "tv": 1796.96, "trd": NaN, "batb": [[1, 1.01, 30], [2, 1.01, 0]], "batl": [[2, 990, 0.01]]}, {"timestamp": 1631462288287, "ltp": 34.0, "tv": 1796.96, "trd": NaN, "batb": [[0, 14, 30.39], [1, 13.5, 2], [2, 1.01, 30]], "batl": NaN}, {"timestamp": 1631462299090, "ltp": 34.0, "tv": 1796.96, "trd": NaN, "batb": [[2, 9.2, 70.93]], "batl": NaN}, {"timestamp": 1631462300524, "ltp": 34.0, "tv": 1796.96, "trd": NaN, "batb": [[0, 14.5, 11.04], [1, 14, 28.39]], "batl": [[0, 20, 2], [1, 21, 10], [2, 55, 2]]}, {"timestamp": 1631462300679, "ltp": 34.0, "tv": 1796.96, "trd": NaN, "batb": [[0, 14.5, 2]], "batl": [[1, 55, 2], [2, 65, 41.03]]}, {"timestamp": 1631462303020, "ltp": 34.0, "tv": 1796.96, "trd": NaN, "batb": [[0, 15, 2], [1, 14.5, 2], [2, 14, 28.39]], "batl": NaN}, {"timestamp": 1631462304499, "ltp": 34.0, "tv": 1796.96, "trd": NaN, "batb": [[0, 15, 11.04]], "batl": [[0, 19.5, 10], [1, 20, 2], [2, 26, 2]]}, {"timestamp": 1631462310515, "ltp": 34.0, "tv": 1796.96, "trd": NaN, "batb": [[0, 14, 28.39], [1, 9.2, 70.93], [2, 4.1, 377.46]], "batl": [[0, 26, 2], [1, 55, 2], [2, 65, 41.03]]}, {"timestamp": 1631462310939, "ltp": 34.0, "tv": 1796.96, "trd": NaN, "batb": [[0, 9.2, 70.93], [1, 4.1, 377.46], [2, 1.01, 30]], "batl": [[0, 55, 2], [1, 65, 41.03], [2, 110, 2]]}, {"timestamp": 1631462314243, "ltp": 34.0, "tv": 1796.96, "trd": NaN, "batb": [[0, 9.2, 72.93], [1, 9, 3], [2, 4.1, 377.46]], "batl": [[0, 26, 2], [1, 36, 2], [2, 55, 4]]}, {"timestamp": 1631462316522, "ltp": 34.0, "tv": 1796.96, "trd": NaN, "batb": NaN, "batl": [[0, 17.5, 116.1], [1, 26, 2], [2, 36, 2]]}, {"timestamp": 1631462317110, "ltp": 34.0, "tv": 1796.96, "trd": NaN, "batb": NaN, "batl": [[0, 26, 2], [1, 36, 2], [2, 55, 4]]}, {"timestamp": 1631462318014, "ltp": 34.0, "tv": 1796.96, "trd": NaN, "batb": [[0, 11.5, 21.74], [1, 9.2, 72.93], [2, 9, 3]], "batl": [[0, 18, 10], [1, 26, 2], [2, 36, 2]]}, {"timestamp": 1631462320460, "ltp": 34.0, "tv": 1796.96, "trd": NaN, "batb": [[0, 9.2, 72.93], [1, 9, 3], [2, 4.1, 377.46]], "batl": [[0, 26, 2], [1, 36, 2], [2, 55, 4]]}, {"timestamp": 1631462330349, "ltp": 34.0, "tv": 1796.96, "trd": NaN, "batb": [[1, 4.1, 377.46], [2, 1.01, 30]], "batl": [[2, 55, 2]]}, {"timestamp": 1631462332473, "ltp": 34.0, "tv": 1796.96, "trd": NaN, "batb": [[0, 20, 22.94], [1, 13.5, 30.65], [2, 9.2, 72.93]], "batl": NaN}, {"timestamp": 1631462333553, "ltp": 34.0, "tv": 1796.96, "trd": NaN, "batb": [[1, 15.5, 7.51], [2, 15, 2]], "batl": NaN}, {"timestamp": 1631462334656, "ltp": 34.0, "tv": 1796.96, "trd": NaN, "batb": [[0, 20, 35.44], [1, 18, 2], [2, 17.5, 3]], "batl": NaN}, {"timestamp": 1631462335354, "ltp": 34.0, "tv": 1796.96, "trd": NaN, "batb": [[0, 22, 2], [1, 21, 2], [2, 20, 22.94]], "batl": NaN}, {"timestamp": 1631462338440, "ltp": 34.0, "tv": 1796.96, "trd": NaN, "batb": [[0, 23, 12.5], [1, 22, 2], [2, 21, 2]], "batl": NaN}, {"timestamp": 1631462339067, "ltp": 34.0, "tv": 1796.96, "trd": NaN, "batb": [[0, 22, 2], [1, 21, 2], [2, 20, 22.94]], "batl": NaN}, {"timestamp": 1631462345772, "ltp": 34.0, "tv": 1796.96, "trd": NaN, "batb": [[0, 23, 5.85], [1, 22, 2], [2, 21, 2]], "batl": NaN}, {"timestamp": 1631462349578, "ltp": 34.0, "tv": 1796.96, "trd": NaN, "batb": NaN, "batl": [[0, 26, 31.69], [1, 36, 28.54]]}, {"timestamp": 1631462349779, "ltp": 34.0, "tv": 1796.96, "trd": NaN, "batb": [[2, 20, 22.94]], "batl": NaN}, {"timestamp": 1631462351294, "ltp": 34.0, "tv": 1796.96, "trd": NaN, "batb": [[0, 13.5, 30.65], [1, 4.1, 377.46], [2, 1.01, 30]], "batl": [[0, 520, 36.07], [1, 990, 0.01], [2, 55, 0]]}, {"timestamp": 1631462354496, "ltp": 34.0, "tv": 1796.96, "trd": NaN, "batb": NaN, "batl": [[0, 55, 4], [1, 110, 2], [2, 520, 36.07]]}, {"timestamp": 1631462355497, "ltp": 34.0, "tv": 1796.96, "trd": NaN, "batb": NaN, "batl": [[0, 55, 2], [2, 990, 0.01]]}, {"timestamp": 1631462358017, "ltp": 34.0, "tv": 1796.96, "trd": NaN, "batb": NaN, "batl": [[0, 55, 4]]}, {"timestamp": 1631462359512, "ltp": 34.0, "tv": 1796.96, "trd": NaN, "batb": [[0, 18.5, 13.51], [1, 13.5, 30.65], [2, 4.1, 377.46]], "batl": [[0, 29, 7.95], [1, 55, 4], [2, 110, 2]]}, {"timestamp": 1631462360912, "ltp": 34.0, "tv": 1796.96, "trd": NaN, "batb": [[0, 13.5, 30.65], [1, 4.1, 377.46], [2, 1.01, 30]], "batl": [[0, 55, 4], [1, 110, 2], [2, 160, 37.59]]}, {"timestamp": 1631462368520, "ltp": 34.0, "tv": 1796.96, "trd": NaN, "batb": NaN, "batl": [[2, 990, 0.01]]}, {"timestamp": 1631462369633, "ltp": 34.0, "tv": 1796.96, "trd": NaN, "batb": NaN, "batl": [[0, 15.5, 4.71], [1, 55, 4], [2, 110, 2]]}, {"timestamp": 1631462370442, "ltp": 34.0, "tv": 1796.96, "trd": NaN, "batb": [[0, 14, 9.66], [1, 13.5, 30.65], [2, 9, 29.73]], "batl": [[1, 19.5, 11.2], [2, 55, 4]]}, {"timestamp": 1631462372421, "ltp": 34.0, "tv": 1796.96, "trd": NaN, "batb": [[0, 14, 3], [1, 13.5, 32.65]], "batl": NaN}, {"timestamp": 1631462373542, "ltp": 34.0, "tv": 1796.96, "trd": NaN, "batb": [[0, 14.5, 2], [1, 14, 3], [2, 13.5, 32.65]], "batl": NaN}, {"timestamp": 1631462375434, "ltp": 34.0, "tv": 1796.96, "trd": NaN, "batb": [[0, 14.5, 11.66]], "batl": [[2, 26, 2]]}, {"timestamp": 1631462383344, "ltp": 34.0, "tv": 1796.96, "trd": NaN, "batb": [[0, 14.5, 2], [1, 13.5, 30.65], [2, 9, 29.73]], "batl": NaN}, {"timestamp": 1631462385664, "ltp": 34.0, "tv": 1796.96, "trd": NaN, "batb": [[0, 9, 29.73], [1, 8, 2], [2, 6.8, 2]], "batl": [[0, 26, 2], [1, 55, 4], [2, 65, 41.03]]}, {"timestamp": 1631462386287, "ltp": 34.0, "tv": 1796.96, "trd": NaN, "batb": NaN, "batl": [[0, 55, 4], [1, 65, 41.03], [2, 110, 2]]}, {"timestamp": 1631462389472, "ltp": 34.0, "tv": 1796.96, "trd": NaN, "batb": [[0, 9, 31.73], [1, 8.8, 3], [2, 8, 2]], "batl": [[0, 36, 2], [1, 55, 4], [2, 65, 41.03]]}, {"timestamp": 1631462392647, "ltp": 34.0, "tv": 1796.96, "trd": NaN, "batb": [[0, 11.5, 21.74], [1, 9, 31.73], [2, 8.8, 3]], "batl": [[0, 17.5, 12.18], [1, 26, 2], [2, 36, 2]]}, {"timestamp": 1631462393561, "ltp": 34.0, "tv": 1796.96, "trd": NaN, "batb": [[0, 9, 31.73], [1, 8.8, 3], [2, 8, 2]], "batl": [[0, 26, 2], [1, 36, 2], [2, 55, 4]]}, {"timestamp": 1631462393772, "ltp": 34.0, "tv": 1796.96, "trd": NaN, "batb": NaN, "batl": [[0, 36, 2], [1, 55, 4], [2, 65, 41.03]]}, {"timestamp": 1631462396965, "ltp": 34.0, "tv": 1796.96, "trd": NaN, "batb": NaN, "batl": [[0, 26, 2], [1, 36, 2], [2, 55, 4]]}, {"timestamp": 1631462401021, "ltp": 34.0, "tv": 1796.96, "trd": NaN, "batb": [[1, 8, 2], [2, 6.8, 2]], "batl": [[2, 55, 2]]}, {"timestamp": 1631462404263, "ltp": 34.0, "tv": 1796.96, "trd": NaN, "batb": [[1, 8.8, 2], [2, 8, 2]], "batl": NaN}, {"timestamp": 1631462413326, "ltp": 34.0, "tv": 1796.96, "trd": NaN, "batb": [[2, 6.4, 2.01]], "batl": NaN}, {"timestamp": 1631462415614, "ltp": 34.0, "tv": 1796.96, "trd": NaN, "batb": NaN, "batl": [[0, 10.5, 3.39], [1, 26, 2], [2, 36, 2]]}, {"timestamp": 1631462416631, "ltp": 34.0, "tv": 1796.96, "trd": NaN, "batb": [[1, 7.4, 45.47]], "batl": NaN}, {"timestamp": 1631462417535, "ltp": 34.0, "tv": 1796.96, "trd": NaN, "batb": [[0, 9.2, 12.85], [1, 9, 31.73], [2, 7.4, 45.47]], "batl": [[1, 12.5, 10], [2, 24, 50.55]]}, {"timestamp": 1631462418611, "ltp": 34.0, "tv": 1796.96, "trd": NaN, "batb": [[0, 9.2, 2]], "batl": NaN}, {"timestamp": 1631462419640, "ltp": 34.0, "tv": 1796.96, "trd": NaN, "batb": [[0, 9.4, 3], [1, 9.2, 2], [2, 9, 31.73]], "batl": NaN}, {"timestamp": 1631462420609, "ltp": 34.0, "tv": 1796.96, "trd": NaN, "batb": [[1, 9.2, 47.54]], "batl": [[2, 14.5, 33.69]]}, {"timestamp": 1631462421422, "ltp": 34.0, "tv": 1796.96, "trd": NaN, "batb": [[0, 9.4, 15.85]], "batl": [[2, 24, 50.55]]}, {"timestamp": 1631462422654, "ltp": 34.0, "tv": 1796.96, "trd": NaN, "batb": [[0, 9.4, 3]], "batl": [[2, 13.5, 2]]}, {"timestamp": 1631462424930, "ltp": 34.0, "tv": 1796.96, "trd": NaN, "batb": [[0, 9.6, 12.85], [1, 9.4, 3], [2, 9.2, 47.54]], "batl": NaN}, {"timestamp": 1631462432354, "ltp": 34.0, "tv": 1796.96, "trd": NaN, "batb": [[2, 9.2, 45.54]], "batl": NaN}, {"timestamp": 1631462444662, "ltp": 34.0, "tv": 1796.96, "trd": NaN, "batb": [[0, 9.4, 3], [1, 7.6, 2], [2, 7.4, 45.47]], "batl": [[0, 13.5, 2], [1, 15.5, 2], [2, 17, 57.15]]}, {"timestamp": 1631462445090, "ltp": 34.0, "tv": 1796.96, "trd": NaN, "batb": [[0, 7.6, 2], [1, 7.4, 45.47], [2, 6.8, 2]], "batl": [[0, 15.5, 2], [1, 17, 57.15], [2, 18, 2]]}, {"timestamp": 1631462446104, "ltp": 34.0, "tv": 1796.96, "trd": NaN, "batb": NaN, "batl": [[0, 9.6, 5], [1, 15.5, 2], [2, 17, 57.15]]}, {"timestamp": 1631462447569, "ltp": 9.6, "tv": 1800.96, "trd": [[9.6, 59.11]], "batb": NaN, "batl": [[0, 9.6, 3]]}, {"timestamp": 1631462448370, "ltp": 9.6, "tv": 1800.96, "trd": NaN, "batb": NaN, "batl": [[1, 13.5, 2], [2, 15.5, 4]]}, {"timestamp": 1631462451872, "ltp": 9.6, "tv": 1802.0, "trd": [[9.6, 60.15]], "batb": NaN, "batl": [[0, 9.6, 1.96]]}, {"timestamp": 1631462454375, "ltp": 9.6, "tv": 1802.0, "trd": NaN, "batb": NaN, "batl": [[0, 8.8, 2.02], [1, 9.6, 1.96], [2, 13.5, 2]]}, {"timestamp": 1631462455668, "ltp": 9.6, "tv": 1802.0, "trd": NaN, "batb": [[0, 7.8, 9.44], [1, 7.6, 4], [2, 7.4, 47.47]], "batl": NaN}, {"timestamp": 1631462456255, "ltp": 9.6, "tv": 1802.0, "trd": NaN, "batb": [[0, 7.8, 11.44]], "batl": [[2, 13, 2]]}, {"timestamp": 1631462457404, "ltp": 9.6, "tv": 1802.0, "trd": NaN, "batb": [[1, 7.6, 2]], "batl": NaN}, {"timestamp": 1631462459608, "ltp": 8.0, "tv": 1803.99, "trd": [[8, 26.83]], "batb": NaN, "batl": [[0, 8, 2.01], [1, 8.8, 2.02], [2, 9.6, 1.96]]}, {"timestamp": 1631462460625, "ltp": 8.0, "tv": 1805.41, "trd": [[8, 28.25]], "batb": NaN, "batl": [[0, 8.8, 2.61], [1, 9.6, 1.96], [2, 10.5, 2]]}, {"timestamp": 1631462461508, "ltp": 8.0, "tv": 1806.0, "trd": [[8, 28.84]], "batb": [[0, 8, 57.2], [1, 7.8, 11.44], [2, 7.6, 68.03]], "batl": [[0, 8.8, 2.02]]}, {"timestamp": 1631462462472, "ltp": 8.0, "tv": 1806.0, "trd": NaN, "batb": NaN, "batl": [[1, 10.5, 2], [2, 12.5, 2]]}, {"timestamp": 1631462462693, "ltp": 8.0, "tv": 1806.0, "trd": NaN, "batb": NaN, "batl": [[0, 8.8, 48.51], [1, 9.4, 58.31], [2, 10.5, 2]]}, {"timestamp": 1631462465605, "ltp": 8.0, "tv": 1806.0, "trd": NaN, "batb": NaN, "batl": [[0, 8.8, 58.31]]}, {"timestamp": 1631462467305, "ltp": 8.0, "tv": 1806.0, "trd": NaN, "batb": [[2, 7.6, 66.03]], "batl": NaN}, {"timestamp": 1631462477622, "ltp": 8.0, "tv": 1806.0, "trd": NaN, "batb": [[0, 7.8, 2], [1, 6.8, 2], [2, 6.2, 70.27]], "batl": [[0, 12.5, 2], [1, 13, 2], [2, 14, 62.24]]}, {"timestamp": 1631462480641, "ltp": 8.0, "tv": 1806.0, "trd": NaN, "batb": [[0, 6.8, 2], [1, 6.2, 70.27], [2, 4.1, 377.46]], "batl": [[0, 9.2, 2], [1, 12.5, 2], [2, 13, 2]]}, {"timestamp": 1631462481240, "ltp": 8.0, "tv": 1806.0, "trd": NaN, "batb": [[0, 6.2, 70.27], [1, 4.1, 377.46], [2, 1.01, 30]], "batl": [[0, 12.5, 2], [1, 13, 2], [2, 14, 62.24]]}, {"timestamp": 1631462484526, "ltp": 8.0, "tv": 1806.0, "trd": NaN, "batb": [[0, 6.4, 2], [1, 6.2, 72.27], [2, 4.1, 377.46]], "batl": [[0, 10.5, 2], [1, 12.5, 2], [2, 13, 2]]}, {"timestamp": 1631462485648, "ltp": 8.0, "tv": 1806.0, "trd": NaN, "batb": NaN, "batl": [[0, 12.5, 2], [1, 13, 2], [2, 14, 62.24]]}, {"timestamp": 1631462487523, "ltp": 8.0, "tv": 1806.0, "trd": NaN, "batb": [[0, 6.8, 2], [1, 6.4, 2], [2, 6.2, 72.27]], "batl": NaN}, {"timestamp": 1631462488659, "ltp": 8.0, "tv": 1806.0, "trd": NaN, "batb": [[0, 6.4, 2], [1, 6.2, 72.27], [2, 4.1, 377.46]], "batl": [[2, 990, 0.01]]}, {"timestamp": 1631462489535, "ltp": 8.0, "tv": 1806.0, "trd": NaN, "batb": [[0, 9, 29.56], [1, 7.2, 48.32], [2, 6.4, 2]], "batl": NaN}, {"timestamp": 1631462491016, "ltp": 8.0, "tv": 1806.0, "trd": NaN, "batb": [[1, 7.4, 2], [2, 7.2, 50.32]], "batl": [[0, 12, 10], [1, 12.5, 2], [2, 13, 2]]}, {"timestamp": 1631462492559, "ltp": 9.2, "tv": 1901.52, "trd": [[9.2, 91.52], [9.4, 4]], "batb": NaN, "batl"