{"info": {"id": "1.187557247", "eventId": "30896009", "eventName": "Match Odds", "marketType": "MATCH_ODDS", "openDate": 1631530653169, "name": "Ferrando v Yul Hatouka", "numberOfActiveRunner": 2, "countryCode": "", "sport": "TENNIS", "venue": "", "volume": {"total": 136664.48, "preMatch": 250.71, "inPlay": 136413.77}, "winner": {"id": 9304761, "name": "Cristiana Ferrando", "status": "WINNER", "position": 1}, "delay": 3}, "runners": [{"id": 9304761, "name": "Cristiana Ferrando", "status": "WINNER", "position": 1, "inPlayOdds": 2.84, "inPlayTime": 1631530653169, "avgPrematch": 2.9, "closedOdds": 1.01, "maxPrematch": 2.96, "minPrematch": 2.8, "maxInPlay": 4.4, "minInPlay": 1.01, "inPlayIndex": 130, "lengthOdds": 2620, "lengthOddsPrematch": 130, "lengthOddsInPlay": 2490, "tradedVolume": 63789.8, "preMatchVolume": 20.62, "inPlayVolume": 63769.18}, {"id": 10350473, "name": "Yuliya Hatouka", "status": "LOSER", "position": 2, "inPlayOdds": 1.55, "inPlayTime": 1631530653169, "avgPrematch": 1.53, "closedOdds": 50.0, "maxPrematch": 1.56, "minPrematch": 1.51, "maxInPlay": 50.0, "minInPlay": 1.28, "inPlayIndex": 56, "lengthOdds": 2303, "lengthOddsPrematch": 56, "lengthOddsInPlay": 2247, "tradedVolume": 72874.68, "preMatchVolume": 230.09, "inPlayVolume": 72644.59}], "marketUpdates": [{"timestamp": 1631459665770000000, "openDate": "2021-09-13T10:30:00.000Z", "status": "OPEN", "betDelay": 0, "inPlay": false, "complete": true}, {"timestamp": 1631529562633000000, "openDate": "2021-09-13T10:50:00.000Z", "status": "OPEN", "betDelay": 0, "inPlay": false, "complete": true}, {"timestamp": 1631530460524000000, "openDate": "2021-09-13T11:00:00.000Z", "status": "OPEN", "betDelay": 0, "inPlay": false, "complete": true}, {"timestamp": 1631530653169000000, "openDate": "2021-09-13T11:00:00.000Z", "status": "OPEN", "betDelay": 3, "inPlay": true, "complete": true}, {"timestamp": 1631536518613000000, "openDate": "2021-09-13T11:00:00.000Z", "status": "SUSPENDED", "betDelay": 3, "inPlay": true, "complete": true}, {"timestamp": 1631536571056000000, "openDate": "2021-09-13T11:00:00.000Z", "status": "CLOSED", "betDelay": 3, "inPlay": true, "complete": true}], "odds": [{"runnerId": 9304761, "odds": [{"timestamp": 1631475044618, "ltp": 2.96, "tv": 8.88, "trd": [[2.96, 8.88]], "batb": [[0, 2.9, 30.87], [2, 1.56, 6.46]], "batl": [[0, 990, 2.2], [1, 990, 0]]}, {"timestamp": 1631475045507, "ltp": 2.96, "tv": 8.88, "trd": NaN, "batb": [[0, 2.88, 11.99], [1, 2.78, 75.1]], "batl": [[0, 4.7, 143.88], [1, 990, 2.2]]}, {"timestamp": 1631475174594, "ltp": 2.96, "tv": 8.88, "trd": NaN, "batb": [[0, 2.78, 75.1], [1, 2.62, 13.91]], "batl": NaN}, {"timestamp": 1631477171256, "ltp": 2.96, "tv": 8.87, "trd": [[2.96, 8.88]], "batb": [[0, 2.78, 75.08]], "batl": NaN}, {"timestamp": 1631482394289, "ltp": 2.96, "tv": 8.87, "trd": NaN, "batb": NaN, "batl": [[0, 5.8, 131.08]]}, {"timestamp": 1631482694491, "ltp": 2.96, "tv": 8.87, "trd": NaN, "batb": NaN, "batl": [[0, 4.8, 261.44]]}, {"timestamp": 1631483594518, "ltp": 2.96, "tv": 8.87, "trd": NaN, "batb": NaN, "batl": [[0, 6.2, 135.39]]}, {"timestamp": 1631483601546, "ltp": 2.96, "tv": 8.87, "trd": NaN, "batb": NaN, "batl": [[0, 6, 3.42], [1, 6.2, 135.39], [2, 990, 2.2]]}, {"timestamp": 1631483811980, "ltp": 2.96, "tv": 8.87, "trd": NaN, "batb": NaN, "batl": [[0, 5.9, 136.32], [1, 6, 3.42]]}, {"timestamp": 1631483850652, "ltp": 2.96, "tv": 8.87, "trd": NaN, "batb": NaN, "batl": [[1, 990, 2.2], [2, 990, 0]]}, {"timestamp": 1631483912042, "ltp": 2.96, "tv": 8.87, "trd": NaN, "batb": NaN, "batl": [[0, 5.8, 3.42], [1, 5.9, 136.32], [2, 990, 2.2]]}, {"timestamp": 1631484194418, "ltp": 2.96, "tv": 8.88, "trd": [[2.96, 8.88]], "batb": [[0, 2.78, 75.09], [2, 1.56, 6.46]], "batl": [[0, 5.7, 153.6], [1, 5.8, 3.42]]}, {"timestamp": 1631484209153, "ltp": 2.96, "tv": 8.88, "trd": NaN, "batb": NaN, "batl": [[1, 990, 2.2], [2, 990, 0]]}, {"timestamp": 1631484954250, "ltp": 2.96, "tv": 8.88, "trd": NaN, "batb": [[0, 2.78, 78.69]], "batl": NaN}, {"timestamp": 1631487494599, "ltp": 2.96, "tv": 8.88, "trd": NaN, "batb": NaN, "batl": [[0, 5, 254.62]]}, {"timestamp": 1631488665721, "ltp": 2.96, "tv": 8.87, "trd": [[2.96, 8.88]], "batb": [[0, 2.78, 78.68]], "batl": NaN}, {"timestamp": 1631489618759, "ltp": 2.96, "tv": 8.87, "trd": NaN, "batb": [[2, 2.6, 3]], "batl": [[0, 990, 2.2], [1, 990, 0]]}, {"timestamp": 1631489618862, "ltp": 2.96, "tv": 8.87, "trd": NaN, "batb": NaN, "batl": [[0, 5, 252.45], [1, 990, 2.2]]}, {"timestamp": 1631492804165, "ltp": 2.96, "tv": 8.87, "trd": NaN, "batb": [[2, 1.56, 6.45]], "batl": NaN}, {"timestamp": 1631494967706, "ltp": 2.96, "tv": 8.87, "trd": [[2.96, 8.87]], "batb": [[0, 2.78, 78.64]], "batl": [[0, 990, 2.2], [1, 990, 0]]}, {"timestamp": 1631494967809, "ltp": 2.96, "tv": 8.87, "trd": NaN, "batb": NaN, "batl": [[0, 4.5, 150.15], [1, 990, 2.2]]}, {"timestamp": 1631495019680, "ltp": 2.96, "tv": 8.87, "trd": NaN, "batb": NaN, "batl": [[0, 5.6, 160.45]]}, {"timestamp": 1631495319241, "ltp": 2.96, "tv": 8.87, "trd": NaN, "batb": NaN, "batl": [[0, 5.5, 227.6]]}, {"timestamp": 1631496791368, "ltp": 2.96, "tv": 8.87, "trd": NaN, "batb": NaN, "batl": [[0, 4.7, 218.56]]}, {"timestamp": 1631497968145, "ltp": 2.96, "tv": 8.87, "trd": NaN, "batb": NaN, "batl": [[0, 4.6, 3.41], [1, 4.7, 218.56], [2, 990, 2.2]]}, {"timestamp": 1631497989074, "ltp": 2.96, "tv": 8.87, "trd": NaN, "batb": NaN, "batl": [[0, 4.5, 228.22], [1, 4.6, 3.41]]}, {"timestamp": 1631498102707, "ltp": 2.96, "tv": 8.87, "trd": NaN, "batb": NaN, "batl": [[1, 990, 2.2], [2, 990, 0]]}, {"timestamp": 1631502772709, "ltp": 2.96, "tv": 8.87, "trd": [[2.96, 8.87]], "batb": [[0, 2.78, 78.62], [2, 1.56, 6.45]], "batl": [[0, 990, 2.2], [1, 990, 0]]}, {"timestamp": 1631502773686, "ltp": 2.96, "tv": 8.87, "trd": NaN, "batb": NaN, "batl": [[0, 3.75, 211.9], [1, 990, 2.2]]}, {"timestamp": 1631502774713, "ltp": 2.96, "tv": 8.87, "trd": NaN, "batb": NaN, "batl": [[0, 990, 2.2], [1, 990, 0]]}, {"timestamp": 1631502775587, "ltp": 2.96, "tv": 8.87, "trd": NaN, "batb": NaN, "batl": [[0, 3.5, 159.99], [1, 990, 2.2]]}, {"timestamp": 1631503073683, "ltp": 2.96, "tv": 8.87, "trd": NaN, "batb": NaN, "batl": [[0, 990, 2.2], [1, 990, 0]]}, {"timestamp": 1631503073785, "ltp": 2.96, "tv": 8.87, "trd": NaN, "batb": NaN, "batl": [[0, 4.4, 869.67], [1, 990, 2.2]]}, {"timestamp": 1631503185457, "ltp": 2.96, "tv": 8.87, "trd": NaN, "batb": NaN, "batl": [[0, 4.1, 248.23]]}, {"timestamp": 1631503374017, "ltp": 2.96, "tv": 8.87, "trd": NaN, "batb": NaN, "batl": [[0, 5.7, 246.67]]}, {"timestamp": 1631503673919, "ltp": 2.96, "tv": 8.87, "trd": NaN, "batb": NaN, "batl": [[0, 5.3, 830.46]]}, {"timestamp": 1631504131676, "ltp": 2.96, "tv": 8.87, "trd": NaN, "batb": NaN, "batl": [[0, 4.9, 897.94]]}, {"timestamp": 1631506300375, "ltp": 2.96, "tv": 8.87, "trd": NaN, "batb": NaN, "batl": [[0, 4.1, 195.28]]}, {"timestamp": 1631506386509, "ltp": 2.96, "tv": 8.87, "trd": NaN, "batb": NaN, "batl": [[0, 5.2, 228.54]]}, {"timestamp": 1631507401218, "ltp": 2.96, "tv": 8.87, "trd": NaN, "batb": [[1, 2.62, 20.87]], "batl": NaN}, {"timestamp": 1631508879524, "ltp": 2.96, "tv": 8.87, "trd": NaN, "batb": [[1, 2.62, 23.87], [2, 2.6, 3]], "batl": NaN}, {"timestamp": 1631508941624, "ltp": 2.96, "tv": 8.87, "trd": NaN, "batb": [[2, 1.71, 24.93]], "batl": [[0, 3.45, 2.95], [1, 5.2, 228.54], [2, 990, 2.2]]}, {"timestamp": 1631508987388, "ltp": 2.96, "tv": 8.87, "trd": NaN, "batb": NaN, "batl": [[0, 3.35, 292.52], [1, 3.45, 2.95]]}, {"timestamp": 1631509900545, "ltp": 2.96, "tv": 8.87, "trd": NaN, "batb": [[0, 2.78, 78.63], [1, 2.62, 20.87], [2, 1.71, 24.95]], "batl": [[0, 3.45, 2.95], [1, 990, 2.2], [2, 990, 0]]}, {"timestamp": 1631509900852, "ltp": 2.96, "tv": 8.87, "trd": NaN, "batb": NaN, "batl": [[0, 3.3, 150.44], [1, 3.45, 2.95], [2, 990, 2.2]]}, {"timestamp": 1631510087613, "ltp": 2.96, "tv": 8.87, "trd": NaN, "batb": NaN, "batl": [[0, 3.35, 255.27]]}, {"timestamp": 1631510186708, "ltp": 2.96, "tv": 8.87, "trd": NaN, "batb": NaN, "batl": [[0, 3.45, 2.95], [1, 990, 2.2], [2, 990, 0]]}, {"timestamp": 1631510186808, "ltp": 2.96, "tv": 8.87, "trd": NaN, "batb": NaN, "batl": [[0, 3.35, 68.78], [1, 3.45, 2.95], [2, 990, 2.2]]}, {"timestamp": 1631510286700, "ltp": 2.96, "tv": 8.87, "trd": NaN, "batb": NaN, "batl": [[0, 3.4, 183.63]]}, {"timestamp": 1631510424669, "ltp": 2.96, "tv": 8.87, "trd": NaN, "batb": NaN, "batl": [[2, 29, 48.39]]}, {"timestamp": 1631510487050, "ltp": 2.96, "tv": 8.87, "trd": NaN, "batb": NaN, "batl": [[0, 3.4, 288.79]]}, {"timestamp": 1631510862985, "ltp": 2.96, "tv": 8.87, "trd": NaN, "batb": NaN, "batl": [[0, 3.4, 168.72]]}, {"timestamp": 1631511087140, "ltp": 2.96, "tv": 8.87, "trd": NaN, "batb": NaN, "batl": [[0, 3.35, 288.1]]}, {"timestamp": 1631511380402, "ltp": 2.96, "tv": 8.87, "trd": NaN, "batb": NaN, "batl": [[0, 3.45, 2.95], [1, 29, 48.39], [2, 990, 2.2]]}, {"timestamp": 1631511386906, "ltp": 2.96, "tv": 8.87, "trd": NaN, "batb": NaN, "batl": [[0, 3.35, 288.1], [1, 3.45, 2.95], [2, 29, 48.39]]}, {"timestamp": 1631516142545, "ltp": 2.96, "tv": 8.87, "trd": NaN, "batb": NaN, "batl": [[1, 3.45, 5.9]]}, {"timestamp": 1631516143057, "ltp": 2.96, "tv": 8.87, "trd": NaN, "batb": NaN, "batl": [[1, 3.45, 2.95]]}, {"timestamp": 1631517706432, "ltp": 2.96, "tv": 8.87, "trd": [[2.96, 8.87]], "batb": [[0, 2.8, 371.39], [1, 2.78, 78.64], [2, 2.72, 4]], "batl": [[0, 3.3, 352.44], [1, 3.45, 2.96], [2, 29, 48.45]]}, {"timestamp": 1631517707617, "ltp": 2.96, "tv": 8.87, "trd": NaN, "batb": [[0, 2.82, 4], [1, 2.8, 374.39], [2, 2.78, 78.64]], "batl": [[0, 3.4, 168.81]]}, {"timestamp": 1631517757684, "ltp": 2.96, "tv": 8.87, "trd": NaN, "batb": [[0, 2.84, 51.15], [1, 2.82, 4], [2, 2.78, 3.6]], "batl": NaN}, {"timestamp": 1631517757995, "ltp": 2.96, "tv": 8.87, "trd": NaN, "batb": [[1, 2.78, 3.6], [2, 1.71, 24.98]], "batl": NaN}, {"timestamp": 1631517760360, "ltp": 2.96, "tv": 8.87, "trd": NaN, "batb": [[2, 2.62, 20.87]], "batl": NaN}, {"timestamp": 1631517770488, "ltp": 2.96, "tv": 8.87, "trd": NaN, "batb": [[2, 2.74, 19.43]], "batl": NaN}, {"timestamp": 1631517857461, "ltp": 2.96, "tv": 8.87, "trd": NaN, "batb": [[0, 2.8, 509.72]], "batl": NaN}, {"timestamp": 1631517861742, "ltp": 2.96, "tv": 8.87, "trd": NaN, "batb": [[2, 1.71, 24.98]], "batl": NaN}, {"timestamp": 1631517906464, "ltp": 2.96, "tv": 8.87, "trd": NaN, "batb": NaN, "batl": [[0, 3.4, 290.29]]}, {"timestamp": 1631517976754, "ltp": 2.8, "tv": 9.82, "trd": [[2.8, 0.95]], "batb": [[0, 2.8, 508.77]], "batl": NaN}, {"timestamp": 1631518159648, "ltp": 2.8, "tv": 9.82, "trd": NaN, "batb": [[0, 2.8, 509.13]], "batl": NaN}, {"timestamp": 1631518213624, "ltp": 2.8, "tv": 9.82, "trd": NaN, "batb": [[1, 1.71, 24.98], [2, 1.56, 6.47]], "batl": NaN}, {"timestamp": 1631518220252, "ltp": 2.8, "tv": 9.82, "trd": NaN, "batb": [[0, 2.8, 512.71]], "batl": NaN}, {"timestamp": 1631518471310, "ltp": 2.8, "tv": 9.82, "trd": NaN, "batb": NaN, "batl": [[0, 3.35, 294.59]]}, {"timestamp": 1631518698525, "ltp": 2.8, "tv": 9.82, "trd": NaN, "batb": [[0, 2.82, 3.36], [1, 2.8, 515.35], [2, 1.71, 24.98]], "batl": NaN}, {"timestamp": 1631518757716, "ltp": 2.8, "tv": 9.82, "trd": NaN, "batb": [[0, 2.82, 445.36], [1, 2.8, 73.45]], "batl": NaN}, {"timestamp": 1631518757923, "ltp": 2.8, "tv": 9.82, "trd": NaN, "batb": [[1, 2.8, 70.45]], "batl": NaN}, {"timestamp": 1631518763439, "ltp": 2.8, "tv": 9.82, "trd": NaN, "batb": [[1, 2.8, 66.87]], "batl": NaN}, {"timestamp": 1631518770042, "ltp": 2.8, "tv": 9.82, "trd": NaN, "batb": [[0, 2.82, 448.92]], "batl": NaN}, {"timestamp": 1631518859240, "ltp": 2.8, "tv": 9.82, "trd": NaN, "batb": [[0, 2.84, 51.5], [1, 2.82, 448.56]], "batl": [[0, 3.35, 177.63]]}, {"timestamp": 1631518861962, "ltp": 2.8, "tv": 9.82, "trd": NaN, "batb": [[1, 2.82, 445]], "batl": NaN}, {"timestamp": 1631518908609, "ltp": 2.8, "tv": 9.82, "trd": NaN, "batb": [[0, 2.84, 55.02]], "batl": NaN}, {"timestamp": 1631518908813, "ltp": 2.8, "tv": 9.82, "trd": NaN, "batb": [[1, 2.82, 3]], "batl": NaN}, {"timestamp": 1631518912205, "ltp": 2.8, "tv": 9.82, "trd": NaN, "batb": [[2, 2.74, 19.43]], "batl": NaN}, {"timestamp": 1631519071631, "ltp": 2.8, "tv": 9.82, "trd": NaN, "batb": NaN, "batl": [[0, 3.4, 289.35]]}, {"timestamp": 1631519743158, "ltp": 2.8, "tv": 9.82, "trd": NaN, "batb": NaN, "batl": [[1, 3.6, 2.79]]}, {"timestamp": 1631519968754, "ltp": 2.8, "tv": 9.82, "trd": NaN, "batb": [[1, 2.74, 19.43], [2, 1.71, 24.98]], "batl": [[0, 3.6, 2.79], [1, 29, 48.45], [2, 990, 2.2]]}, {"timestamp": 1631519968958, "ltp": 2.8, "tv": 9.82, "trd": NaN, "batb": NaN, "batl": [[0, 3.3, 180.31], [1, 3.6, 2.79], [2, 29, 48.45]]}, {"timestamp": 1631519971573, "ltp": 2.8, "tv": 9.82, "trd": NaN, "batb": NaN, "batl": [[0, 3.55, 348.42]]}, {"timestamp": 1631520387963, "ltp": 2.8, "tv": 9.82, "trd": NaN, "batb": [[1, 2.74, 18]], "batl": NaN}, {"timestamp": 1631521342790, "ltp": 2.8, "tv": 9.82, "trd": NaN, "batb": [[2, 1.92, 21.29]], "batl": NaN}, {"timestamp": 1631521802800, "ltp": 2.8, "tv": 9.82, "trd": NaN, "batb": [[1, 2.74, 24]], "batl": NaN}, {"timestamp": 1631522153764, "ltp": 2.8, "tv": 9.82, "trd": NaN, "batb": NaN, "batl": [[0, 3.6, 2.79], [1, 29, 48.45], [2, 990, 2.2]]}, {"timestamp": 1631522153866, "ltp": 2.8, "tv": 9.82, "trd": NaN, "batb": NaN, "batl": [[0, 3.5, 405.18], [1, 3.6, 2.79], [2, 29, 48.45]]}, {"timestamp": 1631522160967, "ltp": 2.8, "tv": 9.82, "trd": NaN, "batb": NaN, "batl": [[0, 3.45, 285.13]]}, {"timestamp": 1631522376708, "ltp": 2.8, "tv": 9.82, "trd": NaN, "batb": NaN, "batl": [[0, 3.25, 222.18]]}, {"timestamp": 1631522556104, "ltp": 2.8, "tv": 9.82, "trd": NaN, "batb": NaN, "batl": [[1, 3.45, 53.23], [2, 3.6, 2.79]]}, {"timestamp": 1631522961762, "ltp": 2.8, "tv": 9.82, "trd": NaN, "batb": [[0, 2.84, 54.67]], "batl": NaN}, {"timestamp": 1631522961864, "ltp": 2.8, "tv": 9.82, "trd": NaN, "batb": [[0, 2.84, 55.02]], "batl": NaN}, {"timestamp": 1631523343612, "ltp": 2.8, "tv": 9.82, "trd": NaN, "batb": NaN, "batl": [[2, 29, 48.45]]}, {"timestamp": 1631523343921, "ltp": 2.8, "tv": 9.82, "trd": NaN, "batb": NaN, "batl": [[2, 3.6, 2.79]]}, {"timestamp": 1631523828168, "ltp": 2.8, "tv": 9.82, "trd": [[2.96, 8.88]], "batb": [[0, 2.84, 55.03], [2, 1.92, 21.27]], "batl": [[1, 3.45, 53.28], [2, 3.6, 2.79]]}, {"timestamp": 1631524393864, "ltp": 2.8, "tv": 9.82, "trd": NaN, "batb": [[2, 1.11, 718.61]], "batl": [[2, 29, 48.42]]}, {"timestamp": 1631525400458, "ltp": 2.8, "tv": 9.82, "trd": NaN, "batb": [[1, 2.78, 14.38], [2, 2.74, 24]], "batl": NaN}, {"timestamp": 1631525765152, "ltp": 2.9, "tv": 10.18, "trd": [[2.9, 0.36]], "batb": [[0, 2.84, 54.68]], "batl": NaN}, {"timestamp": 1631525842662, "ltp": 2.9, "tv": 10.18, "trd": NaN, "batb": NaN, "batl": [[0, 3.45, 53.28], [1, 29, 48.42], [2, 990, 2.2]]}, {"timestamp": 1631525842868, "ltp": 2.9, "tv": 10.18, "trd": NaN, "batb": NaN, "batl": [[0, 3.4, 289.26], [1, 3.45, 53.28], [2, 29, 48.42]]}, {"timestamp": 1631525874204, "ltp": 2.9, "tv": 10.18, "trd": NaN, "batb": [[0, 2.86, 2.66], [1, 2.84, 54.68], [2, 2.78, 14.38]], "batl": NaN}, {"timestamp": 1631526580101, "ltp": 2.9, "tv": 10.18, "trd": NaN, "batb": NaN, "batl": [[0, 3.35, 177.59]]}, {"timestamp": 1631526743037, "ltp": 2.9, "tv": 10.18, "trd": NaN, "batb": NaN, "batl": [[0, 3.4, 289.26]]}, {"timestamp": 1631527302643, "ltp": 2.9, "tv": 10.18, "trd": NaN, "batb": NaN, "batl": [[0, 3.35, 187.21]]}, {"timestamp": 1631527342975, "ltp": 2.9, "tv": 10.18, "trd": NaN, "batb": NaN, "batl": [[0, 3.35, 303.67]]}, {"timestamp": 1631527868339, "ltp": 2.9, "tv": 10.18, "trd": NaN, "batb": NaN, "batl": [[0, 2.96, 10.66]]}, {"timestamp": 1631528995797, "ltp": 2.9, "tv": 10.18, "trd": NaN, "batb": NaN, "batl": [[0, 2.96, 12.66]]}, {"timestamp": 1631529717792, "ltp": 2.94, "tv": 10.75, "trd": [[2.94, 0.57]], "batb": NaN, "batl": NaN}, {"timestamp": 1631529835696, "ltp": 2.94, "tv": 11.17, "trd": [[2.94, 1]], "batb": [[0, 2.86, 2.81]], "batl": NaN}, {"timestamp": 1631529835906, "ltp": 2.94, "tv": 11.45, "trd": [[2.94, 1.28]], "batb": [[0, 2.86, 2.66]], "batl": NaN}, {"timestamp": 1631529990718, "ltp": 2.96, "tv": 12.41, "trd": [[2.96, 9.83]], "batb": NaN, "batl": [[0, 2.96, 12.18]]}, {"timestamp": 1631530074723, "ltp": 2.96, "tv": 12.41, "trd": NaN, "batb": [[0, 2.86, 3.23]], "batl": NaN}, {"timestamp": 1631530074827, "ltp": 2.94, "tv": 13.55, "trd": [[2.94, 2.42]], "batb": [[0, 2.86, 2.66]], "batl": NaN}, {"timestamp": 1631530232117, "ltp": 2.94, "tv": 13.55, "trd": NaN, "batb": [[2, 2.82, 47.15]], "batl": NaN}, {"timestamp": 1631530392635, "ltp": 2.86, "tv": 14.26, "trd": [[2.86, 0.71]], "batb": [[0, 2.86, 1.95]], "batl": NaN}, {"timestamp": 1631530450610, "ltp": 2.86, "tv": 16.21, "trd": [[2.86, 2.66]], "batb": [[0, 2.84, 54.68], [1, 2.82, 47.15], [2, 2.74, 38.71]], "batl": NaN}, {"timestamp": 1631530454389, "ltp": 2.86, "tv": 16.21, "trd": NaN, "batb": [[2, 2.74, 14.71]], "batl": NaN}, {"timestamp": 1631530463590, "ltp": 2.86, "tv": 16.21, "trd": NaN, "batb": [[2, 2.78, 14.38]], "batl": NaN}, {"timestamp": 1631530476640, "ltp": 2.84, "tv": 20.62, "trd": [[2.84, 4.4]], "batb": [[0, 2.84, 70.99]], "batl": NaN}, {"timestamp": 1631530481710, "ltp": 2.84, "tv": 20.62, "trd": NaN, "batb": [[0, 2.84, 3.52]], "batl": NaN}, {"timestamp": 1631530482635, "ltp": 2.84, "tv": 20.62, "trd": NaN, "batb": [[2, 2.76, 14.55]], "batl": NaN}, {"timestamp": 1631530486459, "ltp": 2.84, "tv": 20.62, "trd": NaN, "batb": [[0, 2.82, 417.7], [1, 2.76, 14.55], [2, 2.74, 38.71]], "batl": NaN}, {"timestamp": 1631530492829, "ltp": 2.84, "tv": 20.62, "trd": NaN, "batb": [[0, 2.82, 421.26]], "batl": NaN}, {"timestamp": 1631530647533, "ltp": 2.84, "tv": 20.62, "trd": NaN, "batb": [[0, 2.88, 22.21], [1, 2.82, 421.26], [2, 2.76, 14.55]], "batl": NaN}, {"timestamp": 1631530648724, "ltp": 2.84, "tv": 20.62, "trd": NaN, "batb": [[2, 2.8, 14.23]], "batl": NaN}, {"timestamp": 1631530652640, "ltp": 2.84, "tv": 20.62, "trd": NaN, "batb": [[1, 2.82, 374.11]], "batl": NaN}, {"timestamp": 1631530653169, "ltp": 2.84, "tv": 20.62, "trd": NaN, "batb": [[0, 1.2, 2], [1, 1.01, 123.88], [2, 2.8, 0]], "batl": [[0, 3.45, 53.28], [1, 3.45, 0], [2, 29, 0]]}, {"timestamp": 1631530665665, "ltp": 2.84, "tv": 20.62, "trd": NaN, "batb": [[0, 3, 97.4], [1, 2.84, 46.23], [2, 2.4, 554.22]], "batl": NaN}, {"timestamp": 1631530667754, "ltp": 2.84, "tv": 20.62, "trd": NaN, "batb": [[1, 2.98, 3], [2, 2.96, 3]], "batl": NaN}, {"timestamp": 1631530671460, "ltp": 2.84, "tv": 20.62, "trd": NaN, "batb": NaN, "batl": [[0, 3.45, 98.96]]}, {"timestamp": 1631530674685, "ltp": 2.84, "tv": 20.62, "trd": NaN, "batb": [[0, 2.84, 46.23], [1, 2.52, 3], [2, 2.5, 4]], "batl": [[0, 3.45, 53.28]]}, {"timestamp": 1631530681673, "ltp": 2.84, "tv": 20.62, "trd": NaN, "batb": [[2, 1.2, 2]], "batl": NaN}, {"timestamp": 1631530690776, "ltp": 2.84, "tv": 20.62, "trd": NaN, "batb": [[1, 1.2, 2], [2, 1.01, 123.88]], "batl": NaN}, {"timestamp": 1631530693681, "ltp": 2.84, "tv": 20.62, "trd": NaN, "batb": NaN, "batl": [[1, 3.6, 5.56]]}, {"timestamp": 1631530694665, "ltp": 2.84, "tv": 20.62, "trd": NaN, "batb": [[1, 2.62, 56.36], [2, 1.2, 2]], "batl": [[0, 3.4, 226.02], [1, 3.45, 53.28], [2, 3.6, 5.56]]}, {"timestamp": 1631530695695, "ltp": 2.84, "tv": 20.62, "trd": NaN, "batb": [[1, 2.8, 3], [2, 2.78, 3]], "batl": NaN}, {"timestamp": 1631530698395, "ltp": 2.84, "tv": 20.62, "trd": NaN, "batb": NaN, "batl": [[0, 3.45, 53.28], [1, 3.6, 5.56], [2, 3.6, 0]]}, {"timestamp": 1631530701567, "ltp": 2.84, "tv": 20.62, "trd": NaN, "batb": [[0, 2.88, 458.17], [1, 2.84, 46.23], [2, 2.8, 3]], "batl": [[0, 3.4, 191.78], [1, 3.45, 53.28], [2, 3.6, 5.56]]}, {"timestamp": 1631530706694, "ltp": 2.84, "tv": 20.62, "trd": NaN, "batb": [[0, 2.8, 3], [1, 2.78, 3], [2, 2.62, 56.36]], "batl": [[0, 3.45, 53.28], [1, 3.45, 0], [2, 3.6, 0]]}, {"timestamp": 1631530706958, "ltp": 2.84, "tv": 20.62, "trd": NaN, "batb": [[0, 2.62, 56.36], [1, 1.2, 2], [2, 1.01, 123.88]], "batl": NaN}, {"timestamp": 1631530710147, "ltp": 2.84, "tv": 20.62, "trd": NaN, "batb": [[0, 2.62, 60.36], [1, 2.6, 3], [2, 1.2, 2]], "batl": NaN}, {"timestamp": 1631530723078, "ltp": 2.84, "tv": 20.62, "trd": NaN, "batb": [[1, 1.2, 2], [2, 1.01, 123.88]], "batl": NaN}, {"timestamp": 1631530726249, "ltp": 2.84, "tv": 20.62, "trd": NaN, "batb": [[1, 2.6, 3], [2, 1.2, 2]], "batl": NaN}, {"timestamp": 1631530730650, "ltp": 2.84, "tv": 20.62, "trd": NaN, "batb": [[0, 3.05, 1254.1], [1, 3, 1217.22], [2, 2.98, 1217.22]], "batl": [[0, 3.4, 1125], [1, 3.45, 1145.2], [2, 3.5, 1091.92]]}, {"timestamp": 1631530731688, "ltp": 2.84, "tv": 20.62, "trd": NaN, "batb": [[0, 3.05, 627.06], [1, 3, 608.6], [2, 2.98, 608.6]], "batl": [[0, 3.4, 309.37], [1, 3.45, 353.56], [2, 3.5, 300.28]]}, {"timestamp": 1631530732156, "ltp": 2.84, "tv": 20.62, "trd": NaN, "batb": [[0, 3.1, 92.54], [1, 3.05, 627.06], [2, 3, 608.6]], "batl": NaN}, {"timestamp": 1631530735685, "ltp": 2.84, "tv": 20.62, "trd": NaN, "batb": NaN, "batl": [[0, 3.3, 25.6], [1, 3.4, 309.37], [2, 3.45, 353.56]]}, {"timestamp": 1631530735891, "ltp": 2.84, "tv": 20.62, "trd": NaN, "batb": NaN, "batl": [[0, 3.4, 309.37], [1, 3.45, 353.56], [2, 3.5, 300.28]]}, {"timestamp": 1631530741713, "ltp": 2.84, "tv": 20.62, "trd": NaN, "batb": NaN, "batl": [[1, 3.45, 357.46]]}, {"timestamp": 1631530742597, "ltp": 2.84, "tv": 20.62, "trd": NaN, "batb": [[0, 2.88, 4.21], [1, 2.84, 45.72], [2, 2.78, 4.66]], "batl": [[0, 3.45, 57.18], [1, 3.65, 3.1], [2, 3.5, 0]]}, {"timestamp": 1631530743115, "ltp": 2.84, "tv": 20.62, "trd": NaN, "batb": [[0, 2.84, 45.72], [1, 2.78, 4.66], [2, 2.62, 4]], "batl": NaN}, {"timestamp": 1631530746319, "ltp": 2.84, "tv": 20.62, "trd": NaN, "batb": [[0, 2.84, 48.72], [1, 2.82, 3], [2, 2.78, 4.66]], "batl": NaN}, {"timestamp": 1631530749482, "ltp": 2.84, "tv": 20.62, "trd": NaN, "batb": [[0, 2.88, 4.46], [1, 2.84, 48.72], [2, 2.82, 3]], "batl": NaN}, {"timestamp": 1631530749789, "ltp": 2.84, "tv": 20.62, "trd": NaN, "batb": [[0, 2.84, 48.72], [1, 2.82, 3], [2, 2.78, 4.66]], "batl": NaN}, {"timestamp": 1631530758340, "ltp": 2.84, "tv": 20.62, "trd": NaN, "batb": [[1, 2.78, 4.66], [2, 1.2, 2]], "batl": NaN}, {"timestamp": 1631530760110, "ltp": 2.84, "tv": 20.62, "trd": NaN, "batb": [[0, 2.84, 45.72]], "batl": NaN}, {"timestamp": 1631530761620, "ltp": 2.84, "tv": 20.62, "trd": NaN, "batb": [[1, 2.82, 3], [2, 2.78, 4.66]], "batl": [[0, 3.05, 627.06], [1, 3.1, 608.6], [2, 3.15, 608.6]]}, {"timestamp": 1631530762406, "ltp": 2.84, "tv": 20.62, "trd": NaN, "batb": [[1, 2.78, 4.66], [2, 2.6, 58.29]], "batl": NaN}, {"timestamp": 1631530763029, "ltp": 2.84, "tv": 20.62, "trd": NaN, "batb": [[1, 2.8, 3], [2, 2.78, 4.66]], "batl": NaN}, {"timestamp": 1631530779747, "ltp": 2.84, "tv": 20.62, "trd": NaN, "batb": NaN, "batl": [[0, 3.05, 313.53], [1, 3.1, 304.3], [2, 3.15, 304.3]]}, {"timestamp": 1631530780266, "ltp": 2.84, "tv": 20.62, "trd": NaN, "batb": [[0, 2.6, 58.29], [1, 2.58, 5.06], [2, 1.2, 2]], "batl": [[0, 3.4, 3.29], [1, 3.45, 57.18], [2, 3.65, 3.1]]}, {"timestamp": 1631530783638, "ltp": 2.84, "tv": 20.62, "trd": NaN, "batb": [[0, 2.6, 61.29], [1, 2.58, 8.06]], "batl": NaN}, {"timestamp": 1631530786652, "ltp": 2.84, "tv": 20.62, "trd": NaN, "batb": [[0, 2.68, 3], [1, 2.66, 3], [2, 2.6, 61.29]], "batl": NaN}, {"timestamp": 1631530792368, "ltp": 2.84, "tv": 20.62, "trd": NaN, "batb": [[0, 3.15, 85.92], [1, 2.92, 7.81], [2, 2.86, 45.39]], "batl": [[0, 3.4, 12.97]]}, {"timestamp": 1631530793558, "ltp": 2.84, "tv": 20.62, "trd": NaN, "batb": [[0, 3.15, 88.92], [1, 3.1, 3]], "batl": [[0, 3.4, 3.29]]}, {"timestamp": 1631530796363, "ltp": 2.84, "tv": 20.62, "trd": NaN, "batb": [[2, 2.98, 7.57]], "batl": [[1, 3.45, 66.76]]}, {"timestamp": 1631530796992, "ltp": 2.84, "tv": 20.62, "trd": NaN, "batb": [[2, 2.86, 45.39]], "batl": [[1, 3.45, 57.18]]}, {"timestamp": 1631530798443, "ltp": 2.84, "tv": 20.62, "trd": NaN, "batb": [[2, 2.88, 3.96]], "batl": NaN}, {"timestamp": 1631530803478, "ltp": 2.84, "tv": 20.58, "trd": [[2.84, 4.4], [2.86, 2.66], [2.94, 2.41], [2.96, 9.81]], "batb": [[0, 3.15, 88.86]], "batl": [[1, 3.45, 57.06]]}, {"timestamp": 1631530804478, "ltp": 2.84, "tv": 20.58, "trd": NaN, "batb": [[0, 3.15, 3]], "batl": [[0, 3.45, 53.16], [1, 3.95, 2.7], [2, 4.6, 2.31]]}, {"timestamp": 1631530805472, "ltp": 2.84, "tv": 20.58, "trd": NaN, "batb": [[0, 2.86, 45.35], [1, 2.74, 5.29], [2, 2.58, 5.06]], "batl": NaN}, {"timestamp": 1631530811713, "ltp": 2.84, "tv": 20.58, "trd": NaN, "batb": NaN, "batl": [[1, 3.65, 5.48], [2, 3.95, 2.7]]}, {"timestamp": 1631530812758, "ltp": 2.84, "tv": 20.58, "trd": NaN, "batb": [[2, 2.6, 57.82]], "batl": NaN}, {"timestamp": 1631530813696, "ltp": 2.84, "tv": 20.58, "trd": NaN, "batb": [[1, 2.82, 3], [2, 2.8, 3]], "batl": NaN}, {"timestamp": 1631530814688, "ltp": 2.84, "tv": 20.58, "trd": NaN, "batb": NaN, "batl": [[0, 3.2, 3], [1, 3.45, 53.16], [2, 3.65, 5.48]]}, {"timestamp": 1631530817585, "ltp": 2.86, "tv": 21.66, "trd": [[2.86, 3.73]], "batb": [[0, 2.86, 44.28]], "batl": NaN}, {"timestamp": 1631530818476, "ltp": 2.86, "tv": 21.66, "trd": NaN, "batb": NaN, "batl": [[1, 3.35, 3.7], [2, 3.45, 53.16]]}, {"timestamp": 1631530820408, "ltp": 2.86, "tv": 61.76, "trd": [[2.86, 43.84]], "batb": [[0, 2.86, 4.17]], "batl": [[2, 3.45, 56.66]]}, {"timestamp": 1631530822706, "ltp": 2.86, "tv": 61.76, "trd": NaN, "batb": NaN, "batl": [[0, 3.2, 48.71]]}, {"timestamp": 1631530825522, "ltp": 2.86, "tv": 61.76, "trd": NaN, "batb": [[0, 2.6, 63.31], [1, 1.8, 11.85], [2, 1.2, 2]], "batl": [[0, 3.35, 3.7], [1, 3.45, 56.66], [2, 3.65, 3.1]]}, {"timestamp": 1631530828690, "ltp": 2.86, "tv": 61.76, "trd": NaN, "batb": [[0, 2.68, 3], [1, 2.66, 4], [2, 2.6, 9.49]], "batl": NaN}, {"timestamp": 1631530835707, "ltp": 2.86, "tv": 61.76, "trd": NaN, "batb": [[0, 3.15, 86.53], [1, 2.84, 45.61], [2, 2.68, 3]], "batl": NaN}, {"timestamp": 1631530837524, "ltp": 2.86, "tv": 61.76, "trd": NaN, "batb": [[0, 3.15, 89.53], [1, 3.1, 3], [2, 2.84, 45.61]], "batl": NaN}, {"timestamp": 1631530841323, "ltp": 2.86, "tv": 61.76, "trd": NaN, "batb": [[2, 2.88, 5.21]], "batl": NaN}, {"timestamp": 1631530842625, "ltp": 2.86, "tv": 61.76, "trd": NaN, "batb": NaN, "batl": [[0, 3.45, 53.16], [1, 3.95, 2.7], [2, 4.6, 2.31]]}, {"timestamp": 1631530843304, "ltp": 2.86, "tv": 61.76, "trd": NaN, "batb": [[0, 3.15, 3], [2, 2.84, 45.61]], "batl": NaN}, {"timestamp": 1631530845731, "ltp": 2.86, "tv": 61.76, "trd": NaN, "batb": [[0, 2.84, 45.61], [1, 2.74, 5.29], [2, 2.7, 3]], "batl": NaN}, {"timestamp": 1631530846524, "ltp": 2.86, "tv": 61.76, "trd": NaN, "batb": [[0, 2.88, 4.21], [1, 2.84, 45.61], [2, 2.74, 5.29]], "batl": NaN}, {"timestamp": 1631530847411, "ltp": 2.86, "tv": 61.76, "trd": NaN, "batb": [[0, 2.84, 45.61], [1, 2.74, 5.29], [2, 2.7, 3]], "batl": NaN}, {"timestamp": 1631530848707, "ltp": 2.86, "tv": 61.76, "trd": NaN, "batb": [[0, 2.84, 48.61], [1, 2.82, 3], [2, 2.74, 5.29]], "batl": NaN}, {"timestamp": 1631530853534, "ltp": 2.86, "tv": 61.76, "trd": NaN, "batb": [[0, 2.88, 4.46], [1, 2.84, 48.61], [2, 2.82, 3]], "batl": NaN}, {"timestamp": 1631530853843, "ltp": 2.86, "tv": 61.76, "trd": NaN, "batb": [[0, 2.84, 48.61], [1, 2.82, 3], [2, 2.74, 5.29]], "batl": NaN}, {"timestamp": 1631530858928, "ltp": 2.86, "tv": 61.76, "trd": NaN, "batb": [[0, 2.84, 45.61]], "batl": NaN}, {"timestamp": 1631530860754, "ltp": 2.86, "tv": 61.76, "trd": NaN, "batb": [[0, 2.88, 4.96], [1, 2.84, 45.61], [2, 2.82, 3]], "batl": NaN}, {"timestamp": 1631530861655, "ltp": 2.86, "tv": 61.76, "trd": NaN, "batb": [[0, 2.84, 45.61], [1, 2.82, 3], [2, 2.74, 5.29]], "batl": [[1, 3.65, 5.48], [2, 3.95, 2.7]]}, {"timestamp": 1631530863743, "ltp": 2.86, "tv": 61.76, "trd": NaN, "batb": [[2, 2.8, 3]], "batl": [[0, 3.2, 3], [1, 3.45, 53.16], [2, 3.65, 5.48]]}, {"timestamp": 1631530868569, "ltp": 2.86, "tv": 61.76, "trd": NaN, "batb": NaN, "batl": [[1, 3.35, 4.1], [2, 3.45, 53.16]]}, {"timestamp": 1631530882476, "ltp": 2.86, "tv": 61.76, "trd": NaN, "batb": [[0, 2.6, 58.16], [1, 2.56, 5.33], [2, 1.8, 11.85]], "batl": [[0, 3.35, 4.1], [1, 3.45, 53.16], [2, 3.65, 3.1]]}, {"timestamp": 1631530885672, "ltp": 2.86, "tv": 61.76, "trd": NaN, "batb": [[0, 2.66, 5.28], [1, 2.6, 58.16], [2, 2.56, 5.33]], "batl": NaN}, {"timestamp": 1631530886082, "ltp": 2.86, "tv": 61.76, "trd": NaN, "batb": [[0, 2.6, 58.16], [1, 2.56, 5.33], [2, 1.8, 11.85]], "batl": NaN}, {"timestamp": 1631530895685, "ltp": 2.86, "tv": 61.76, "trd": NaN, "batb": [[2, 2.46, 1554.88]], "batl": [[0, 2.72, 1406.24], [1, 2.74, 1364.88], [2, 2.76, 1364.88]]}, {"timestamp": 1631530896677, "ltp": 2.86, "tv": 61.76, "trd": NaN, "batb": [[2, 2.46, 777.44]], "batl": [[0, 2.72, 703.12], [1, 2.74, 682.44], [2, 2.76, 682.44]]}, {"timestamp": 1631530898607, "ltp": 2.86, "tv": 61.76, "trd": NaN, "batb": [[1, 2.56, 8.33], [2, 2.54, 3]], "batl": NaN}, {"timestamp": 1631530903906, "ltp": 2.6, "tv": 79.47, "trd": [[2.6, 17.7]], "batb": [[0, 2.6, 40.45]], "batl": NaN}, {"timestamp": 1631530910206, "ltp": 2.6, "tv": 79.47, "trd": NaN, "batb": [[2, 2.48, 6.01]], "batl": NaN}, {"timestamp": 1631530911719, "ltp": 2.6, "tv": 79.47, "trd": NaN, "batb": NaN, "batl": [[0, 2.94, 4.25], [1, 3.15, 4.5], [2, 3.35, 4.1]]}, {"timestamp": 1631530912339, "ltp": 2.6, "tv": 79.47, "trd": NaN, "batb": [[0, 2.42, 6.94], [1, 2.4, 71.8], [2, 1.8, 11.85]], "batl": NaN}, {"timestamp": 1631530913711, "ltp": 2.6, "tv": 79.47, "trd": NaN, "batb": NaN, "batl": [[0, 3.15, 4.5], [1, 3.35, 4.1], [2, 3.45, 53.16]]}, {"timestamp": 1631530915640, "ltp": 2.6, "tv": 79.47, "trd": NaN, "batb": [[0, 2.48, 6.51], [1, 2.42, 6.94], [2, 2.4, 71.8]], "batl": NaN}, {"timestamp": 1631530916527, "ltp": 2.6, "tv": 79.47, "trd": NaN, "batb": [[0, 2.42, 6.94], [1, 2.4, 71.8], [2, 1.8, 11.85]], "batl": [[0, 2.94, 7.75], [1, 3.1, 3], [2, 3.15, 4.5]]}, {"timestamp": 1631530917305, "ltp": 2.6, "tv": 79.47, "trd": NaN, "batb": NaN, "batl": [[0, 2.94, 3]]}, {"timestamp": 1631530918445, "ltp": 2.6, "tv": 79.47, "trd": NaN, "batb": NaN, "batl": [[1, 2.98, 2], [2, 3.1, 3]]}, {"timestamp": 1631530919731, "ltp": 2.6, "tv": 79.47, "trd": NaN, "batb": NaN, "batl": [[2, 3.05, 3]]}, {"timestamp": 1631530920040, "ltp": 2.6, "tv": 79.47, "trd": NaN, "batb": NaN, "batl": [[0, 2.94, 7.25]]}, {"timestamp": 1631530923440, "ltp": 2.6, "tv": 79.47, "trd": NaN, "batb": NaN, "batl": [[0, 2.94, 3]]}, {"timestamp": 1631530926643, "ltp": 2.6, "tv": 79.47, "trd": NaN, "batb": [[0, 2.48, 5.26], [1, 2.42, 6.94], [2, 2.4, 71.8]], "batl": NaN}, {"timestamp": 1631530926956, "ltp": 2.6, "tv": 79.47, "trd": NaN, "batb": [[0, 2.42, 6.94], [1, 2.4, 71.8], [2, 1.8, 11.85]], "batl": NaN}, {"timestamp": 1631530928761, "ltp": 2.6, "tv": 79.47, "trd": NaN, "batb": NaN, "batl": [[0, 2.98, 2], [1, 3.05, 3], [2, 3.15, 4.5]]}, {"timestamp": 1631530929544, "ltp": 2.6, "tv": 79.47, "trd": NaN, "batb": NaN, "batl": [[0, 2.94, 4.25], [1, 2.98, 2], [2, 3.05, 3]]}, {"timestamp": 1631530930534, "ltp": 2.6, "tv": 79.47, "trd": NaN, "batb": NaN, "batl": [[0, 2.98, 2], [1, 3.15, 4.5], [2, 3.45, 53.16]]}, {"timestamp": 1631530931519, "ltp": 2.6, "tv": 79.47, "trd": NaN, "batb": [[2, 2.3, 457.34]], "batl": [[1, 3.1, 6.45], [2, 3.15, 4.5]]}, {"timestamp": 1631530933026, "ltp": 2.6, "tv": 79.47, "trd": NaN, "batb": NaN, "batl": [[0, 2.92, 3], [1, 2.98, 2], [2, 3.1, 6.45]]}, {"timestamp": 1631530934368, "ltp": 2.46, "tv": 80.69, "trd": [[2.46, 1.22]], "batb": NaN, "batl": [[0, 2.6, 3], [1, 2.68, 3], [2, 2.92, 3]]}, {"timestamp": 1631530937431, "ltp": 2.52, "tv": 102.69, "trd": [[2.52, 22]], "batb": NaN, "batl": NaN}, {"timestamp": 1631530946476, "ltp": 2.52, "tv": 102.69, "trd": NaN, "batb": [[1, 2.4, 82.51]], "batl": [[1, 3.1, 6.45], [2, 3.15, 4.5]]}, {"timestamp": 1631530949661, "ltp": 2.52, "tv": 102.69, "trd": NaN, "batb": NaN, "batl": [[1, 2.7, 11.5], [2, 3.1, 6.45]]}, {"timestamp": 1631530967586, "ltp": 2.48, "tv": 102.72, "trd": [[2.48, 0.03]], "batb": NaN, "batl": NaN}, {"timestamp": 1631530985710, "ltp": 2.52, "tv": 124.22, "trd": [[2.52, 43.5]], "batb": NaN, "batl": NaN}, {"timestamp": 1631530987321, "ltp": 2.52, "tv": 124.22, "trd": NaN, "batb": [[0, 2.4, 10.71], [1, 2.22, 88.95], [2, 1.8, 11.85]], "batl": [[0, 2.7, 11.5], [1, 3.15, 4.5], [2, 3.45, 53.16]]}, {"timestamp": 1631530988425, "ltp": 2.52, "tv": 124.22, "trd": NaN, "batb": [[0, 2.22, 88.95], [1, 1.8, 11.85], [2, 1.7, 16.93]], "batl": [[0, 3.15, 4.5], [1, 3.45, 53.16], [2, 3.45, 0]]}, {"timestamp": 1631530990615, "ltp": 2.52, "tv": 124.22, "trd": NaN, "batb": [[1, 2.2, 7.17], [2, 1.8, 11.85]], "batl": [[0, 2.68, 5.14], [1, 2.8, 4.87], [2, 3.45, 53.16]]}, {"timestamp": 1631530991603, "ltp": 2.52, "tv": 124.22, "trd": NaN, "batb": [[0, 2.22, 92.95], [1, 2.2, 11.17]], "batl": NaN}, {"timestamp": 1631530993729, "ltp": 2.52, "tv": 124.22, "trd": NaN, "batb": [[0, 2.28, 3], [1, 2.26, 4], [2, 2.22, 92.95]], "batl": NaN}, {"timestamp": 1631530999033, "ltp": 2.52, "tv": 124.22, "trd": NaN, "batb": NaN, "batl": [[0, 2.8, 4.87], [1, 3.45, 53.16], [2, 3.45, 0]]}, {"timestamp": 1631531000701, "ltp": 2.42, "tv": 125.62, "trd": [[2.42, 1.4]], "batb": [[0, 2.22, 88.95], [1, 2.2, 11.17], [2, 1.8, 11.85]], "batl": [[0, 2.34, 2583.22], [1, 2.5, 6.26], [2, 2.8, 4.87]]}, {"timestamp": 1631531001746, "ltp": 2.42, "tv": 125.62, "trd": NaN, "batb": NaN, "batl": [[0, 2.4, 3.69], [1, 2.8, 4.87], [2, 2.86, 6.99]]}, {"timestamp": 1631531002741, "ltp": 2.42, "tv": 125.62, "trd": NaN, "batb": [[2, 2.06, 111.21]], "batl": NaN}, {"timestamp": 1631531003732, "ltp": 2.42, "tv": 125.62, "trd": NaN, "batb": [[0, 2.22, 101.24], [2, 2.18, 3]], "batl": [[1, 2.52, 12.16], [2, 2.68, 3]]}, {"timestamp": 1631531006751, "ltp": 2.42, "tv": 125.62, "trd": NaN, "batb": NaN, "batl": [[1, 2.68, 3], [2, 2.76, 147.23]]}, {"timestamp": 1631531007740, "ltp": 2.42, "tv": 125.62, "trd": NaN, "batb": NaN, "batl": [[2, 2.8, 4.87]]}, {"timestamp": 1631531009143, "ltp": 2.42, "tv": 125.62, "trd": NaN, "batb": NaN, "batl": [[1, 2.48, 12.32], [2, 2.5, 5.99]]}, {"timestamp": 1631531012561, "ltp": 2.42, "tv": 125.62, "trd": NaN, "batb": [[0, 2.22, 12.29], [1, 2.06, 111.21], [2, 2.02, 8.24]], "batl": [[0, 2.48, 12.32], [1, 2.64, 4.68], [2, 2.68, 3]]}, {"timestamp": 1631531013753, "ltp": 2.42, "tv": 125.62, "trd": NaN, "batb": [[0, 2.06, 111.21], [1, 2.02, 8.24], [2, 1.86, 404.12]], "batl": [[0, 2.64, 4.68], [1, 2.68, 3], [2, 2.8, 4.87]]}, {"timestamp": 1631531015742, "ltp": 2.42, "tv": 125.62, "trd": NaN, "batb": [[0, 2.08, 7.81], [1, 2.06, 111.21], [2, 2.02, 8.24]], "batl": [[0, 2.5, 5.45], [1, 2.64, 4.68], [2, 2.68, 3]]}, {"timestamp": 1631531016734, "ltp": 2.42, "tv": 125.62, "trd": NaN, "batb": [[0, 2.06, 116.21], [1, 2.04, 4]], "batl": [[0, 2.5, 9.45]]}, {"timestamp": 1631531018246, "ltp": 2.42, "tv": 125.62, "trd": NaN, "batb": NaN, "batl": [[0, 2.5, 5.45]]}, {"timestamp": 1631531019751, "ltp": 2.42, "tv": 125.62, "trd": NaN, "batb": [[0, 2.08, 621.74], [1, 2.06, 116.21], [2, 2.04, 4]], "batl": NaN}, {"timestamp": 1631531020745, "ltp": 2.42, "tv": 125.62, "trd": NaN, "batb": [[0, 2.36, 74.81], [1, 2.18, 93.89], [2, 2.08, 4]], "batl": NaN}, {"timestamp": 1631531021531, "ltp": 2.42, "tv": 125.62, "trd": NaN, "batb": [[0, 2.36, 85.83], [1, 2.24, 4], [2, 2.22, 4]], "batl": [[2, 2.68, 14.57]]}, {"timestamp": 1631531026145, "ltp": 2.42, "tv": 125.62, "trd": NaN, "batb": NaN, "batl": [[1, 2.58, 5.75], [2, 2.64, 4.68]]}, {"timestamp": 1631531028341, "ltp": 2.42, "tv": 125.62, "trd": NaN, "batb": [[2, 2.22, 10.84]], "batl": NaN}, {"timestamp": 1631531031378, "ltp": 2.36, "tv": 211.45, "trd": [[2.36, 85.83]], "batb": [[0, 2.24, 4], [1, 2.22, 10.84], [2, 2.18, 93.89]], "batl": NaN}, {"timestamp": 1631531032686, "ltp": 2.36, "tv": 211.45, "trd": NaN, "batb": [[0, 2.18, 93.89], [1, 2.14, 7.82], [2, 2.08, 4]], "batl": [[0, 2.58, 5.75], [1, 2.64, 4.68], [2, 2.68, 3]]}, {"timestamp": 1631531033366, "ltp": 2.36, "tv": 211.45, "trd": NaN, "batb": NaN, "batl": [[0, 2.64, 4.68], [1, 2.68, 3], [2, 2.7, 4.75]]}, {"timestamp": 1631531035652, "ltp": 2.36, "tv": 211.45, "trd": NaN, "batb": [[1, 2.16, 95.9], [2, 2.14, 7.82]], "batl": NaN}, {"timestamp": 1631531036488, "ltp": 2.36, "tv": 211.45, "trd": NaN, "batb": [[0, 2.18, 3], [1, 2.16, 98.9]], "batl": [[0, 2.58, 3], [1, 2.64, 8.68], [2, 2.68, 3]]}, {"timestamp": 1631531039680, "ltp": 2.36, "tv": 211.45, "trd": NaN, "batb": [[0, 2.22, 6.34], [1, 2.18, 3], [2, 2.16, 98.9]], "batl": [[0, 2.46, 20.25], [1, 2.58, 8.44], [2, 2.64, 8.68]]}, {"timestamp": 1631531040683, "ltp": 2.36, "tv": 211.45, "trd": NaN, "batb": [[0, 2.18, 3], [1, 2.16, 98.9], [2, 2.14, 7.82]], "batl": [[0, 2.58, 3], [1, 2.64, 8.68], [2, 2.68, 3]]}, {"timestamp": 1631531043683, "ltp": 2.36, "tv": 211.45, "trd": NaN, "batb": [[0, 2.22, 7.84], [1, 2.18, 3], [2, 2.16, 98.9]], "batl": [[0, 2.58, 7.94]]}, {"timestamp": 1631531044095, "ltp": 2.36, "tv": 211.45, "trd": NaN, "batb": NaN, "batl": [[0, 2.58, 3]]}, {"timestamp": 1631531045506, "ltp": 2.36, "tv": 211.45, "trd": NaN, "batb": [[0, 2.18, 3], [1, 2.16, 98.9], [2, 2.14, 7.82]], "batl": NaN}, {"timestamp": 1631531047268, "ltp": 2.36, "tv": 211.45, "trd": NaN, "batb": [[1, 2.16, 95.9]], "batl": [[0, 2.64, 8.68], [1, 2.7, 4.75], [2, 2.8, 4.87]]}, {"timestamp": 1631531048682, "ltp": 2.36, "tv": 211.45, "trd": NaN, "batb": [[0, 2.22, 7.43], [1, 2.18, 3], [2, 2.16, 95.9]], "batl": NaN}, {"timestamp": 1631531048996, "ltp": 2.36, "tv": 211.45, "trd": NaN, "batb": [[0, 2.18, 3], [1, 2.16, 95.9], [2, 2.14, 7.82]], "batl": NaN}, {"timestamp": 1631531050764, "ltp": 2.36, "tv": 211.45, "trd": NaN, "batb": [[1, 2.16, 98.9]], "batl": [[0, 2.58, 5.75], [1, 2.6, 3], [2, 2.64, 8.68]]}, {"timestamp": 1631531051389, "ltp": 2.36, "tv": 211.45, "trd": NaN, "batb": NaN, "batl": [[0, 2.6, 3], [1, 2.64, 8.68], [2, 2.7, 4.75]]}, {"timestamp": 1631531054622, "ltp": 2.36, "tv": 211.45, "trd": NaN, "batb": NaN, "batl": [[0, 2.58, 3], [1, 2.6, 3], [2, 2.64, 8.68]]}, {"timestamp": 1631531056297, "ltp": 2.36, "tv": 211.45, "trd": NaN, "batb": NaN, "batl": [[0, 2.64, 4.68], [1, 2.7, 4.75], [2, 2.8, 4.87]]}, {"timestamp": 1631531057700, "ltp": 2.36, "tv": 211.45, "trd": NaN, "batb": NaN, "batl": [[2, 2.72, 386.72]]}, {"timestamp": 1631531058588, "ltp": 2.36, "tv": 211.45, "trd": NaN, "batb": [[0, 2.52, 63.35], [1, 2.32, 78.74], [2, 2.18, 3]], "batl": NaN}, {"timestamp": 1631531059524, "ltp": 2.36, "tv": 211.45, "trd": NaN, "batb": [[2, 2.2, 3]], "batl": NaN}, {"timestamp": 1631531060417, "ltp": 2.36, "tv": 211.45, "trd": NaN, "batb": [[1, 2.5, 3], [2, 2.48, 4]], "batl": NaN}, {"timestamp": 1631531061624, "ltp": 2.36, "tv": 211.45, "trd": NaN, "batb": [[0, 2.54, 38.96], [1, 2.52, 66.35], [2, 2.5, 3]], "batl": NaN}, {"timestamp": 1631531072450, "ltp": 2.36, "tv": 211.45, "trd": NaN, "batb": [[2, 2.36, 5.93]], "batl": NaN}, {"timestamp": 1631531074215, "ltp": 2.36, "tv": 211.45, "trd": NaN, "batb": [[1, 2.36, 5.93], [2, 2.32, 78.58]], "batl": [[0, 2.74, 4.98], [1, 2.76, 5.27], [2, 2.8, 4.87]]}, {"timestamp": 1631531075645, "ltp": 2.54, "tv": 250.41, "trd": [[2.54, 38.96]], "batb": [[0, 2.5, 4], [1, 2.32, 78.58], [2, 2.28, 6.91]], "batl": NaN}, {"timestamp": 1631531075949, "ltp": 2.54, "tv": 250.41, "trd": NaN, "batb": [[0, 2.32, 78.58], [1, 2.28, 6.91], [2, 2.14, 7.82]], "batl": NaN}, {"timestamp": 1631531078549, "ltp": 2.54, "tv": 250.41, "trd": NaN, "batb": [[0, 2.34, 3], [1, 2.32, 81.58], [2, 2.28, 6.91]], "batl": NaN}, {"timestamp": 1631531081735, "ltp": 2.54, "tv": 250.41, "trd": NaN, "batb": [[0, 2.36, 6.93], [1, 2.34, 3], [2, 2.32, 81.58]], "batl": NaN}, {"timestamp": 1631531082725, "ltp": 2.54, "tv": 250.41, "trd": NaN, "batb": [[0, 2.32, 81.58], [1, 2.28, 6.91], [2, 2.14, 7.82]], "batl": [[0, 2.82, 4.75], [1, 3.45, 236.05], [2, 2.8, 0]]}, {"timestamp": 1631531083764, "ltp": 2.54, "tv": 250.41, "trd": NaN, "batb": NaN, "batl": [[0, 2.46, 777.44], [1, 2.48, 754.56], [2, 2.5, 754.56]]}, {"timestamp": 1631531084649, "ltp": 2.54, "tv": 250.41, "trd": NaN, "batb": [[2, 2.24, 48.38]], "batl": [[1, 2.48, 766.88]]}, {"timestamp": 1631531087259, "ltp": 2.54, "tv": 250.41, "trd": NaN, "batb": [[0, 2.34, 32.36], [1, 2.32, 81.58], [2, 2.28, 6.91]], "batl": NaN}, {"timestamp": 1631531088553, "ltp": 2.54, "tv": 250.41, "trd": NaN, "batb": NaN, "batl": [[1, 2.48, 754.56]]}, {"timestamp": 1631531091658, "ltp": 2.54, "tv": 250.41, "trd": NaN, "batb": NaN, "batl": [[0, 2.44, 12.5], [1, 2.46, 777.44], [2, 2.48, 754.56]]}, {"timestamp": 1631531093625, "ltp": 2.34, "tv": 282.77, "trd": [[2.34, 32.36]], "batb": [[0, 2.32, 81.58], [1, 2.28, 6.91], [2, 2.24, 48.38]], "batl": NaN}, {"timestamp": 1631531097644, "ltp": 2.34, "tv": 282.77, "trd": NaN, "batb": [[0, 2.34, 25.67], [1, 2.32, 81.58], [2, 2.28, 6.91]], "batl": NaN}, {"timestamp": 1631531100557, "ltp": 2.34, "tv": 282.77, "trd": NaN, "batb": [[0, 2.32, 3], [1, 2.24, 48.38], [2, 2.1, 112.29]], "batl": [[1, 2.6, 4.96], [2, 2.64, 4.93]]}, {"timestamp": 1631531101741, "ltp": 2.34, "tv": 282.77, "trd": NaN, "batb": [[0, 2.1, 112.29], [1, 2.02, 8.24], [2, 2, 23.08]], "batl": [[0, 2.54, 4.88]]}, {"timestamp": 1631531101954, "ltp": 2.34, "tv": 282.77, "trd": NaN, "batb": NaN, "batl": [[0, 2.64, 4.93], [1, 2.7, 4.75], [2, 2.72, 3]]}, {"timestamp": 1631531104735, "ltp": 2.34, "tv": 282.77, "trd": NaN, "batb": [[0, 2.12, 3], [1, 2.1, 116.29], [2, 2.02, 8.24]], "batl": NaN}, {"timestamp": 1631531106713, "ltp": 2.34, "tv": 282.77, "trd": NaN, "batb": NaN, "batl": [[0, 2.48, 4], [1, 2.64, 4.93], [2, 2.7, 4.75]]}, {"timestamp": 1631531107546, "ltp": 2.34, "tv": 282.77, "trd": NaN, "batb": NaN, "batl": [[0, 2.64, 4.93], [1, 2.7, 4.75], [2, 2.72, 3]]}, {"timestamp": 1631531108744, "ltp": 2.34, "tv": 282.77, "trd": NaN, "batb": [[0, 2.14, 15], [1, 2.12, 3], [2, 2.1, 116.29]], "batl": [[0, 2.6, 5.56], [1, 2.64, 4.93], [2, 2.7, 4.75]]}, {"timestamp": 1631531110564, "ltp": 2.34, "tv": 282.77, "trd": NaN, "batb": [[0, 2.12, 3], [1, 2.1, 116.29], [2, 2.02, 8.24]], "batl": NaN}, {"timestamp": 1631531111035, "ltp": 2.34, "tv": 282.77, "trd": NaN, "batb": NaN, "batl": [[0, 2.64, 4.93], [1, 2.7, 4.75], [2, 2.72, 3]]}, {"timestamp": 1631531116360, "ltp": 2.34, "tv": 282.77, "trd": NaN, "batb": [[1, 2.1, 112.29]], "batl": NaN}, {"timestamp": 1631531118656, "ltp": 2.34, "tv": 282.77, "trd": NaN, "batb": [[0, 2.1, 105.35], [1, 2.02, 8.24], [2, 2, 23.08]], "batl": NaN}, {"timestamp": 1631531119539, "ltp": 2.34, "tv": 282.77, "trd": NaN, "batb": [[0, 2.1, 109.35]], "batl": [[2, 2.72, 10.35]]}, {"timestamp": 1631531120474, "ltp": 2.34, "tv": 282.77, "trd": NaN, "batb": [[1, 2.06, 56.6], [2, 2.02, 8.24]], "batl": [[0, 2.26, 13.36], [1, 2.64, 4.93], [2, 2.7, 4.75]]}, {"timestamp": 1631531121572, "ltp": 2.34, "tv": 282.77, "trd": NaN, "batb": [[0, 2.12, 15], [1, 2.1, 109.35], [2, 2.08, 3]], "batl": [[1, 2.62, 3], [2, 2.64, 4.93]]}, {"timestamp": 1631531124656, "ltp": 2.18, "tv": 312.27, "trd": [[2.18, 29.51]], "batb": NaN, "batl": [[0, 2.24, 24.65], [1, 2.26, 13.36], [2, 2.62, 3]]}, {"timestamp": 1631531126367, "ltp": 2.18, "tv": 312.27, "trd": NaN, "batb": NaN, "batl": [[0, 2.36, 6.07], [1, 2.48, 6.24]]}, {"timestamp": 1631531127668, "ltp": 2.18, "tv": 312.27, "trd": NaN, "batb": NaN, "batl": [[1, 2.38, 6.25], [2, 2.48, 6.24]]}, {"timestamp": 1631531128764, "ltp": 2.12, "tv": 327.27, "trd": [[2.12, 15]], "batb": [[0, 2.1, 109.35], [1, 2.08, 3], [2, 2.06, 56.6]], "batl": NaN}, {"timestamp": 1631531129755, "ltp": 2.12, "tv": 327.27, "trd": NaN, "batb": NaN, "batl": [[0, 2.24, 36.92], [1, 2.36, 6.07], [2, 2.38, 6.25]]}, {"timestamp": 1631531132755, "ltp": 2.12, "tv": 327.27, "trd": NaN, "batb": [[0, 2.1, 137.23]], "batl": NaN}, {"timestamp": 1631531133750, "ltp": 2.12, "tv": 327.27, "trd": NaN, "batb": [[0, 2.06, 56.6], [1, 1.97, 400.31], [2, 1.89, 72.72]], "batl": [[0, 2.24, 13.47], [1, 2.48, 6.24], [2, 2.5, 6.31]]}, {"timestamp": 1631531134380, "ltp": 2.12, "tv": 327.27, "trd": NaN, "batb": [[0, 1.97, 400.31], [1, 1.89, 72.72], [2, 1.88, 27.21]], "batl": [[0, 2.48, 6.24], [1, 2.5, 6.31], [2, 2.62, 3]]}, {"timestamp": 1631531136565, "ltp": 2.12, "tv": 327.27, "trd": NaN, "batb": NaN, "batl": [[0, 2.36, 6.32], [1, 2.48, 6.24], [2, 2.5, 6.31]]}, {"timestamp": 1631531137268, "ltp": 2.12, "tv": 327.27, "trd": NaN, "batb": NaN, "batl": [[0, 2.48, 6.24], [1, 2.5, 6.31], [2, 2.62, 3]]}, {"timestamp": 1631531144155, "ltp": 2.12, "tv": 327.27, "trd": NaN, "batb": [[2, 1.8, 34.58]], "batl": NaN}, {"timestamp": 1631531145461, "ltp": 2.12, "tv": 327.27, "trd": NaN, "batb": [[0, 1.89, 72.72], [1, 1.8, 34.58], [2, 1.5, 106.65]], "batl": [[0, 2.62, 3], [1, 3.45, 53.16], [2, 2.62, 0]]}, {"timestamp": 1631531146677, "ltp": 2.12, "tv": 327.27, "trd": NaN, "batb": [[2, 1.4, 148.12]], "batl": NaN}, {"timestamp": 1631531147676, "ltp": 2.12, "tv": 327.27, "trd": NaN, "batb": [[1, 1.88, 117.45], [2, 1.86, 169.6]], "batl": [[0, 1.94, 109.42], [1, 1.96, 1122.62], [2, 1.97, 947.06]]}, {"timestamp": 1631531148564, "ltp": 1.94, "tv": 338.81, "trd": [[1.94, 11.54]], "batb": [[0, 1.89, 140.31], [1, 1.88, 121.45]], "batl": [[0, 1.96, 975.78], [1, 1.97, 947.06], [2, 1.98, 947.06]]}, {"timestamp": 1631531149393, "ltp": 1.94, "tv": 338.81, "trd": NaN, "batb": [[0, 1.89, 168.87]], "batl": NaN}, {"timestamp": 1631531150766, "ltp": 1.94, "tv": 338.81, "trd": NaN, "batb": [[0, 1.94, 6.3], [1, 1.89, 168.87], [2, 1.88, 121.45]], "batl": NaN}, {"timestamp": 1631531151761, "ltp": 1.95, "tv": 355.49, "trd": [[1.95, 16.68]], "batb": [[0, 1.89, 168.87], [1, 1.88, 121.45], [2, 1.86, 169.6]], "batl": [[0, 1.95, 167.65], [1, 1.96, 975.78], [2, 1.97, 1091.62]]}, {"timestamp": 1631531152694, "ltp": 1.95, "tv": 405.53, "trd": [[1.95, 66.72]], "batb": [[0, 1.89, 105.28]], "batl": [[0, 1.95, 142.63]]}, {"timestamp": 1631531153581, "ltp": 1.95, "tv": 438.89, "trd": [[1.95, 100.07]], "batb": NaN, "batl": [[0, 1.95, 125.95]]}, {"timestamp": 1631531154574, "ltp": 1.95, "tv": 472.41, "trd": [[1.95, 133.6]], "batb": NaN, "batl": [[0, 1.95, 109.19]]}, {"timestamp": 1631531155681, "ltp": 1.95, "tv": 676.25, "trd": [[1.95, 337.44]], "batb": [[1, 1.88, 138.38], [2, 1.87, 64.32]], "batl": [[0, 1.95, 7.28]]}, {"timestamp": 1631531156670, "ltp": 1.95, "tv": 690.82, "trd": [[1.95, 352]], "batb": [[0, 1.95, 31.37], [1, 1.89, 105.28], [2, 1.88, 4]], "batl": [[0, 1.96, 975.78], [1, 1.97, 947.06], [2, 1.98, 947.06]]}, {"timestamp": 1631531157704, "ltp": 1.95, "tv": 718.88, "trd": [[1.95, 380.06]], "batb": [[0, 1.95, 26.27]], "batl": NaN}, {"timestamp": 1631531158699, "ltp": 1.95, "tv": 769.4, "trd": [[1.95, 430.59]], "batb": [[0, 1.95, 39.73]], "batl": NaN}, {"timestamp": 1631531159587, "ltp": 1.95, "tv": 773.4, "trd": [[1.95, 434.59]], "batb": [[0, 1.95, 47.15], [1, 1.89, 252.7]], "batl": [[0, 1.96, 1100.95], [2, 1.98, 1089.41]]}, {"timestamp": 1631531160575, "ltp": 1.96, "tv": 790.08, "trd": [[1.96, 16.68]], "batb": [[0, 1.89, 252.7], [1, 1.87, 231.01], [2, 1.84, 603.64]], "batl": [[0, 1.96, 1092.61]]}, {"timestamp": 1631531161680, "ltp": 1.96, "tv": 823.44, "trd": [[1.96, 50.04]], "batb": NaN, "batl": [[0, 1.96, 1075.93]]}, {"timestamp": 1631531162611, "ltp": 1.96, "tv": 856.8, "trd": [[1.96, 83.4]], "batb": [[0, 1.89, 275.14]], "batl": [[0, 1.96, 1059.25]]}, {"timestamp": 1631531163709, "ltp": 1.96, "tv": 873.48, "trd": [[1.96, 100.07]], "batb": [[0, 1.9, 5], [1, 1.89, 275.14], [2, 1.87, 231.01]], "batl": [[0, 1.96, 1050.91]]}, {"timestamp": 1631531164594, "ltp": 1.96, "tv": 923.51, "trd": [[1.96, 150.11]], "batb": NaN, "batl": [[0, 1.96, 1025.89]]}, {"timestamp": 1631531164906, "ltp": 1.96, "tv": 1017.43, "trd": [[1.96, 244.03]], "batb": NaN, "batl": [[0, 1.96, 978.93]]}, {"timestamp": 1631531166677, "ltp": 1.96, "tv": 1204.93, "trd": [[1.96, 431.53]], "batb": [[1, 1.89, 246.58]], "batl": [[0, 1.96, 93.92], [1, 1.98, 142.35], [2, 2, 15]]}, {"timestamp": 1631531167306, "ltp": 1.96, "tv": 1204.93, "trd": NaN, "batb": [[0, 1.96, 31.25], [1, 1.87, 64.32], [2, 1.84, 31.97]], "batl": [[0, 2, 15], [1, 2.1, 4], [2, 2.14, 7.75]]}, {"timestamp": 1631531168612, "ltp": 1.96, "tv": 1204.93, "trd": NaN, "batb": [[0, 1.8, 84.85], [1, 1.78, 31.16], [2, 1.74, 409.86]], "batl": [[0, 2.1, 4], [1, 2.14, 7.75], [2, 2.92, 224.31]]}, {"timestamp": 1631531170701, "ltp": 1.96, "tv": 1204.93, "trd": NaN, "batb": [[0, 1.8, 265.58], [1, 1.78, 227.07]], "batl": [[0, 2.08, 7.94], [1, 2.1, 182.56], [2, 2.12, 116.42]]}, {"timestamp": 1631531171696, "ltp": 1.96, "tv": 1204.93, "trd": NaN, "batb": [[0, 1.8, 84.85], [1, 1.78, 31.16], [2, 1.77, 38.37]], "batl": [[0, 2.1, 4], [1, 2.14, 7.75], [2, 2.92, 224.31]]}, {"timestamp": 1631531172490, "ltp": 1.96, "tv": 1204.93, "trd": NaN, "batb": [[2, 1.74, 409.86]], "batl": [[0, 2.08, 2], [1, 2.1, 4], [2, 2.14, 7.75]]}, {"timestamp": 1631531173689, "ltp": 1.96, "tv": 1204.93, "trd": NaN, "batb": NaN, "batl": [[0, 1.98, 37.75], [1, 2.08, 2], [2, 2.1, 4]]}, {"timestamp": 1631531174206, "ltp": 1.96, "tv": 1204.93, "trd": NaN, "batb": [[0, 1.8, 85.6]], "batl": [[0, 2.08, 2], [1, 2.1, 4], [2, 2.14, 7.75]]}, {"timestamp": 1631531175720, "ltp": 1.96, "tv": 1204.93, "trd": NaN, "batb": [[0, 1.92, 126.03], [1, 1.9, 158.47], [2, 1.81, 99.7]], "batl": [[0, 1.99, 147.1], [1, 2.02, 202.11], [2, 2.06, 10]]}, {"timestamp": 1631531176397, "ltp": 1.96, "tv": 1204.93, "trd": NaN, "batb": [[0, 1.8, 85.6], [1, 1.78, 31.16], [2, 1.74, 409.86]], "batl": [[0, 2.08, 2], [1, 2.1, 4], [2, 2.14, 7.75]]}, {"timestamp": 1631531177397, "ltp": 1.96, "tv": 1204.93, "trd": NaN, "batb": NaN, "batl": [[0, 2.08, 10.44]]}, {"timestamp": 1631531177809, "ltp": 1.96, "tv": 1204.93, "trd": NaN, "batb": NaN, "batl": [[0, 2.08, 2]]}, {"timestamp": 1631531179323, "ltp": 1.96, "tv": 1204.93, "trd": NaN, "batb": [[0, 1.81, 18.83], [1, 1.8, 284.45], [2, 1.78, 227.1]], "batl": [[1, 2.1, 182.56], [2, 2.12, 116.42]]}, {"timestamp": 1631531181199, "ltp": 1.98, "tv": 1206.42, "trd": [[1.98, 1.49]], "batb": [[0, 1.81, 18.08]], "batl": [[0, 1.94, 7.06], [1, 2.08, 2], [2, 2.1, 182.56]]}, {"timestamp": 1631531184518, "ltp": 1.94, "tv": 1219.82, "trd": [[1.94, 24.94]], "batb": NaN, "batl": [[0, 2.08, 10.05], [1, 2.1, 178.56], [2, 2.12, 116.42]]}, {"timestamp": 1631531185714, "ltp": 1.94, "tv": 1219.82, "trd": NaN, "batb": [[1, 1.8, 84.85], [2, 1.78, 31.16]], "batl": [[0, 2.08, 2.36], [1, 2.14, 7.75], [2, 3.45, 53.16]]}, {"timestamp": 1631531187700, "ltp": 1.94, "tv": 1220.54, "trd": [[1.94, 25.66]], "batb": [[0, 2, 4290.73], [1, 1.99, 1856.24], [2, 1.98, 1856.24]], "batl": [[0, 2.14, 7.75], [1, 3.45, 53.16], [2, 3.45, 0]]}, {"timestamp": 1631531188729, "ltp": 1.94, "tv": 1220.54, "trd": NaN, "batb": [[0, 2, 1101.5], [1, 1.99, 928.12], [2, 1.98, 928.12]], "batl": [[1, 2.56, 7.81], [2, 3.45, 53.16]]}, {"timestamp": 1631531189720, "ltp": 1.94, "tv": 1220.54, "trd": NaN, "batb": NaN, "batl": [[0, 2.14, 21.79]]}, {"timestamp": 1631531190610, "ltp": 1.94, "tv": 1220.54, "trd": NaN, "batb": NaN, "batl": [[0, 2.14, 52.65], [2, 2.92, 224.31]]}, {"timestamp": 1631531194413, "ltp": 1.94, "tv": 1220.54, "trd": NaN, "batb": NaN, "batl": [[1, 2.2, 6.33], [2, 2.3, 6.45]]}, {"timestamp": 1631531196540, "ltp": 1.94, "tv": 1220.54, "trd": NaN, "batb": [[1, 1.99, 988.42]], "batl": [[2, 2.22, 7.25]]}, {"timestamp": 1631531199512, "ltp": 1.94, "tv": 1220.54, "trd": NaN, "batb": [[0, 2, 1111.79]], "batl": NaN}, {"timestamp": 1631531205548, "ltp": 1.94, "tv": 1220.54, "trd": NaN, "batb": [[0, 1.99, 60.3], [1, 1.91, 29.39], [2, 1.9, 71.21]], "batl": [[0, 2.14, 14.04]]}, {"timestamp": 1631531206653, "ltp": 1.94, "tv": 1220.54, "trd": NaN, "batb": [[0, 1.91, 29.39], [1, 1.9, 71.21], [2, 1.85, 30.97]], "batl": [[0, 3.45, 53.16], [1, 2.2, 0], [2, 2.22, 0]]}, {"timestamp": 1631531207228, "ltp": 1.94, "tv": 1220.54, "trd": NaN, "batb": [[0, 1.9, 71.21], [1, 1.85, 30.97], [2, 1.74, 409.86]], "batl": [[0, 2.72, 244.88], [1, 3.45, 53.16]]}, {"timestamp": 1631531208722, "ltp": 1.94, "tv": 1220.54, "trd": NaN, "batb": [[0, 2, 4], [1, 1.99, 5], [2, 1.9, 70.88]], "batl": [[0, 2.3, 6.25], [1, 2.72, 244.88], [2, 3.45, 53.16]]}, {"timestamp": 1631531209616, "ltp": 1.94, "tv": 1220.54, "trd": NaN, "batb": [[0, 1.93, 3], [1, 1.92, 4]], "batl": [[0, 2.22, 4], [1, 2.3, 6.25], [2, 2.72, 244.88]]}, {"timestamp": 1631531210726, "ltp": 1.94, "tv": 1220.54, "trd": NaN, "batb": [[0, 1.9, 70.88], [1, 1.85, 30.97], [2, 1.74, 409.86]], "batl": [[0, 2.24, 3]]}, {"timestamp": 1631531212670, "ltp": 1.94, "tv": 1220.54, "trd": NaN, "batb": [[0, 1.91, 98.11], [1, 1.9, 70.88], [2, 1.85, 30.97]], "batl": [[0, 2.18, 33.43], [1, 2.2, 7.13], [2, 2.24, 3]]}, {"timestamp": 1631531213656, "ltp": 1.94, "tv": 1220.54, "trd": NaN, "batb": [[0, 1.91, 123.5]], "batl": [[0, 2.2, 7.13], [1, 2.24, 3], [2, 2.26, 4]]}, {"timestamp": 1631531213970, "ltp": 1.94, "tv": 1220.54, "trd": NaN, "batb": [[0, 1.91, 25.39]], "batl": NaN}, {"timestamp": 1631531217061, "ltp": 1.94, "tv": 1220.54, "trd": NaN, "batb": [[0, 1.92, 98.11], [1, 1.91, 25.39], [2, 1.9, 70.88]], "batl": NaN}, {"timestamp": 1631531218678, "ltp": 1.94, "tv": 1220.54, "trd": NaN, "batb": [[0, 1.9, 70.88], [1, 1.85, 30.97], [2, 1.74, 409.86]], "batl": [[0, 2.24, 3], [1, 2.26, 4], [2, 2.3, 6.25]]}, {"timestamp": 1631531219982, "ltp": 1.9, "tv": 1244.54, "trd": [[1.9, 24]], "batb": [[0, 1.9, 58.88]], "batl": NaN}, {"timestamp": 1631531221767, "ltp": 1.9, "tv": 1244.54, "trd": NaN, "batb": [[0, 1.91, 124.5], [1, 1.9, 58.88], [2, 1.85, 30.97]], "batl": [[0, 2.2, 6.68], [1, 2.24, 3], [2, 2.26, 4]]}, {"timestamp": 1631531222655, "ltp": 1.9, "tv": 1244.54, "trd": NaN, "batb": [[0, 1.9, 58.88], [1, 1.85, 30.97], [2, 1.74, 409.86]], "batl": [[0, 2.22, 33.43]]}, {"timestamp": 1631531222861, "ltp": 1.9, "tv": 1244.54, "trd": NaN, "batb": NaN, "batl": [[0, 2.24, 3], [1, 2.26, 4], [2, 2.3, 6.25]]}, {"timestamp": 1631531225386, "ltp": 1.9, "tv": 1244.54, "trd": NaN, "batb": NaN, "batl": [[1, 2.3, 6.25], [2, 2.72, 244.88]]}, {"timestamp": 1631531227471, "ltp": 1.9, "tv": 1244.54, "trd": NaN, "batb": [[2, 1.5, 106.73]], "batl": [[2, 3.45, 53.16]]}, {"timestamp": 1631531228570, "ltp": 1.9, "tv": 1244.54, "trd": NaN, "batb": [[0, 1.91, 28.39], [1, 1.9, 58.88], [2, 1.85, 30.97]], "batl": [[0, 2.2, 7.48], [1, 2.24, 3], [2, 2.3, 6.25]]}, {"timestamp": 1631531229668, "ltp": 1.9, "tv": 1244.54, "trd": NaN, "batb": [[0, 1.9, 58.88], [1, 1.89, 184.59], [2, 1.87, 166.7]], "batl": [[0, 1.96, 110.94], [1, 1.98, 1108.27], [2, 1.99, 937.5]]}, {"timestamp": 1631531230560, "ltp": 1.96, "tv": 1255.85, "trd": [[1.96, 442.84]], "batb": [[0, 1.9, 89], [1, 1.88, 63.96], [2, 1.85, 599.55]], "batl": [[0, 1.98, 965.92], [1, 1.99, 937.5], [2, 2, 937.5]]}, {"timestamp": 1631531233578, "ltp": 1.96, "tv": 1255.85, "trd": NaN, "batb": [[0, 1.9, 199.21], [1, 1.88, 227.81]], "batl": [[0, 1.97, 175.35], [1, 1.98, 965.92], [2, 1.99, 1077.69]]}, {"timestamp": 1631531241407, "ltp": 1.96, "tv": 1255.85, "trd": NaN, "batb": [[0, 1.88, 63.96], [1, 1.8, 84.68], [2, 1.73, 37.13]], "batl": [[0, 2.02, 14.85], [1, 2.18, 10.25], [2, 2.2, 4]]}, {"timestamp": 1631531242507, "ltp": 1.96, "tv": 1255.85, "trd": NaN, "batb": [[0, 1.8, 84.68], [1, 1.73, 37.13], [2, 1.62, 421.17]], "batl": [[0, 2.18, 10.25], [1, 2.2, 4], [2, 2.24, 3]]}, {"timestamp": 1631531244595, "ltp": 1.96, "tv": 1255.85, "trd": NaN, "batb": [[0, 1.8, 117.61], [1, 1.79, 187.56], [2, 1.77, 199.68]], "batl": [[0, 2.1, 7.75], [1, 2.12, 181.17], [2, 2.14, 113.28]]}, {"timestamp": 1631531245693, "ltp": 1.96, "tv": 1255.85, "trd": NaN, "batb": [[0, 1.81, 33.29], [1, 1.8, 84.43], [2, 1.79, 187.56]], "batl": [[0, 2.12, 183.17], [1, 2.14, 113.28], [2, 2.18, 10.25]]}, {"timestamp": 1631531248496, "ltp": 1.96, "tv": 1255.85, "trd": NaN, "batb": [[0, 1.8, 84.43], [1, 1.79, 187.56], [2, 1.77, 199.68]], "batl": NaN}, {"timestamp": 1631531249213, "ltp": 1.96, "tv": 1255.85, "trd": NaN, "batb": [[0, 1.81, 18.08], [1, 1.8, 84.43], [2, 1.79, 187.56]], "batl": NaN}, {"timestamp": 1631531250406, "ltp": 1.96, "tv": 1255.85, "trd": NaN, "batb": [[0, 1.82, 18.08], [1, 1.81, 18.08], [2, 1.8, 84.43]], "batl": NaN}, {"timestamp": 1631531251707, "ltp": 1.96, "tv": 1255.85, "trd": NaN, "batb": [[1, 1.81, 49.37], [2, 1.8, 111.21]], "batl": [[0, 2.1, 6.75], [1, 2.12, 183.17], [2, 2.14, 113.28]]}, {"timestamp": 1631531252020, "ltp": 1.96, "tv": 1255.85, "trd": NaN, "batb": [[0, 1.81, 18.08], [1, 1.8, 84.43], [2, 1.79, 187.56]], "batl": [[0, 2.12, 183.17], [1, 2.14, 113.28], [2, 2.18, 10.25]]}, {"timestamp": 1631531254407, "ltp": 1.96, "tv": 1255.85, "trd": NaN, "batb": [[0, 2.04, 2439.6], [1, 1.81, 18.08], [2, 1.8, 84.43]], "batl": NaN}, {"timestamp": 1631531255598, "ltp": 1.96, "tv": 1255.85, "trd": NaN, "batb": [[1, 1.81, 45.37], [2, 1.8, 111.71]], "batl": NaN}, {"timestamp": 1631531257624, "ltp": 1.96, "tv": 1255.85, "trd": NaN, "batb": NaN, "batl": [[2, 2.18, 6.25]]}, {"timestamp": 1631531260532, "ltp": 1.96, "tv": 1255.85, "trd": NaN, "batb": NaN, "batl": [[0, 2.12, 2], [1, 2.18, 6.25], [2, 2.6, 261.12]]}, {"timestamp": 1631531262607, "ltp": 1.96, "tv": 1255.85, "trd": NaN, "batb": NaN, "batl": [[0, 2.18, 6.25], [1, 2.6, 261.12], [2, 3.45, 53.16]]}, {"timestamp": 1631531263695, "ltp": 1.96, "tv": 1255.85, "trd": NaN, "batb": [[0, 2, 2]], "batl": NaN}, {"timestamp": 1631531264728, "ltp": 1.96, "tv": 1255.85, "trd": NaN, "batb": [[0, 2.04, 114.89], [1, 2, 2], [2, 1.91, 69.45]], "batl": [[0, 2.16, 13.92], [1, 2.18, 6.25], [2, 2.6, 268.81]]}, {"timestamp": 1631531265741, "ltp": 1.96, "tv": 1255.85, "trd": NaN, "batb": [[0, 2.04, 144.1], [1, 2.02, 3], [2, 2, 2]], "batl": NaN}, {"timestamp": 1631531265818, "ltp": 1.96, "tv": 1255.85, "trd": NaN, "batb": NaN, "batl": [[0, 2.16, 39.77]]}, {"timestamp": 1631531267012, "ltp": 2.04, "tv": 1373.25, "trd": [[2.04, 117.4]], "batb": [[0, 2.04, 85.4]], "batl": NaN}, {"timestamp": 1631531268415, "ltp": 2.04, "tv": 1373.25, "trd": NaN, "batb": [[1, 2.02, 61.82]], "batl": NaN}, {"timestamp": 1631531270739, "ltp": 2.04, "tv": 1373.25, "trd": NaN, "batb": NaN, "batl": [[2, 2.2, 41.78]]}, {"timestamp": 1631531277628, "ltp": 2.04, "tv": 1373.25, "trd": NaN, "batb": [[0, 2.02, 58.82], [1, 1.91, 69.45], [2, 1.9, 23.46]], "batl": [[0, 2.16, 13.92], [1, 2.2, 41.78], [2, 2.42, 6.25]]}, {"timestamp": 1631531278559, "ltp": 2.04, "tv": 1373.25, "trd": NaN, "batb": [[0, 1.91, 69.45], [1, 1.82, 30.64], [2, 1.81, 27.29]], "batl": [[0, 2.42, 6.25], [1, 2.6, 261.12], [2, 3.45, 53.16]]}, {"timestamp": 1631531280736, "ltp": 2.04, "tv": 1373.25, "trd": NaN, "batb": NaN, "batl": [[0, 2.3, 7.05], [1, 2.42, 6.25], [2, 2.6, 261.12]]}, {"timestamp": 1631531281641, "ltp": 2.04, "tv": 1373.25, "trd": NaN, "batb": [[1, 1.9, 24.46], [2, 1.82, 30.64]], "batl": [[0, 2.3, 4]]}, {"timestamp": 1631531284758, "ltp": 2.04, "tv": 1373.25, "trd": NaN, "batb": [[1, 1.82, 30.64], [2, 1.81, 27.29]], "batl": [[1, 2.34, 4], [2, 2.42, 6.25]]}, {"timestamp": 1631531286332, "ltp": 2.04, "tv": 1373.25, "trd": NaN, "batb": [[2, 1.67, 415.42]], "batl": NaN}, {"timestamp": 1631531287672, "ltp": 2.04, "tv": 1373.25, "trd": NaN, "batb": [[1, 1.9, 185.02], [2, 1.88, 163.88]], "batl": [[0, 1.98, 173.61], [1, 2, 138.1], [2, 2.3, 4]]}, {"timestamp": 1631531288764, "ltp": 1.98, "tv": 1384.4, "trd": [[1.98, 12.64]], "batb": [[1, 1.9, 63.24], [2, 1.87, 1022.72]], "batl": [[0, 1.98, 162.46], [2, 2.06, 58.27]]}, {"timestamp": 1631531289443, "ltp": 1.98, "tv": 1384.4, "trd": NaN, "batb": [[0, 1.91, 98.5]], "batl": [[2, 2.22, 20]]}, {"timestamp": 1631531291666, "ltp": 1.98, "tv": 1384.4, "trd": NaN, "batb": [[0, 1.91, 210.41], [2, 1.89, 161.12]], "batl": NaN}, {"timestamp": 1631531292560, "ltp": 1.98, "tv": 1384.4, "trd": NaN, "batb": NaN, "batl": [[2, 2.04, 58.83]]}, {"timestamp": 1631531296559, "ltp": 1.98, "tv": 1384.4, "trd": NaN, "batb": [[0, 1.9, 63.24], [1, 1.79, 33.31], [2, 1.78, 87.36]], "batl": [[0, 2.04, 58.83], [1, 2.16, 6.47], [2, 2.18, 6.75]]}, {"timestamp": 1631531297486, "ltp": 1.98, "tv": 1384.4, "trd": NaN, "batb": [[0, 1.78, 87.36], [1, 1.71, 35.19], [2, 1.67, 415.42]], "batl": [[0, 2.26, 7.25], [1, 2.28, 4], [2, 2.6, 261.12]]}, {"timestamp": 1631531299678, "ltp": 1.98, "tv": 1384.4, "trd": NaN, "batb": [[0, 1.78, 234.72], [1, 1.76, 203.45], [2, 1.71, 35.19]], "batl": [[0, 2.16, 115.5], [1, 2.18, 107.36], [2, 2.26, 7.25]]}, {"timestamp": 1631531300678, "ltp": 1.98, "tv": 1384.4, "trd": NaN, "batb": [[0, 1.8, 31.28], [1, 1.79, 35.31], [2, 1.78, 234.72]], "batl": [[1, 2.18, 109.36]]}, {"timestamp": 1631531301366, "ltp": 1.98, "tv": 1384.4, "trd": NaN, "batb": NaN, "batl": [[0, 2.18, 2], [1, 2.26, 7.25], [2, 2.28, 4]]}, {"timestamp": 1631531303691, "ltp": 1.9, "tv": 1386.61, "trd": [[1.9, 26.21]], "batb": NaN, "batl": [[0, 2.16, 7.97], [1, 2.18, 2], [2, 2.26, 7.25]]}, {"timestamp": 1631531304580, "ltp": 1.9, "tv": 1386.61, "trd": NaN, "batb": [[0, 1.78, 234.72], [1, 1.76, 203.45], [2, 1.71, 35.19]], "batl": [[0, 1.84, 154.16], [1, 1.86, 1200.88], [2, 1.87, 997.98]]}, {"timestamp": 1631531305673, "ltp": 1.9, "tv": 1386.61, "trd": NaN, "batb": [[1, 1.77, 68.37], [2, 1.76, 203.45]], "batl": NaN}, {"timestamp": 1631531306563, "ltp": 1.84, "tv": 1389.49, "trd": [[1.84, 2.88]], "batb": NaN, "batl": [[0, 1.84, 152.72]]}, {"timestamp": 1631531307390, "ltp": 1.84, "tv": 1389.49, "trd": NaN, "batb": [[0, 1.78, 267.29]], "batl": NaN}, {"timestamp": 1631531313602, "ltp": 1.84, "tv": 1389.49, "trd": NaN, "batb": [[0, 1.77, 68.37], [1, 1.7, 35.02], [2, 1.68, 105.52]], "batl": [[0, 1.89, 60], [1, 1.98, 26.25], [2, 2.02, 7.75]]}, {"timestamp": 1631531314483, "ltp": 1.84, "tv": 1389.49, "trd": NaN, "batb": [[0, 1.7, 35.02], [1, 1.68, 105.52], [2, 1.67, 415.42]], "batl": [[0, 1.98, 26.25], [1, 2.02, 7.75], [2, 2.14, 4]]}, {"timestamp": 1631531315412, "ltp": 1.84, "tv": 1389.49, "trd": NaN, "batb": NaN, "batl": [[1, 1.99, 24.5], [2, 2.02, 7.75]]}, {"timestamp": 1631531316608, "ltp": 1.84, "tv": 1389.49, "trd": NaN, "batb": [[1, 1.69, 105.27], [2, 1.68, 169.46]], "batl": [[0, 1.98, 136.39], [2, 2, 138.1]]}, {"timestamp": 1631531317701, "ltp": 1.84, "tv": 1389.49, "trd": NaN, "batb": [[2, 1.67, 415.42]], "batl": [[0, 1.98, 30.25], [2, 2.02, 7.75]]}, {"timestamp": 1631531320709, "ltp": 1.84, "tv": 1389.49, "trd": NaN, "batb": [[0, 1.8, 196.85], [1, 1.78, 195.96], [2, 1.71, 108.51]], "batl": [[0, 1.87, 173.99], [1, 1.89, 164.16], [2, 1.93, 26.5]]}, {"timestamp": 1631531321597, "ltp": 1.84, "tv": 1389.49, "trd": NaN, "batb": [[2, 1.71, 18.08]], "batl": NaN}, {"timestamp": 1631531323108, "ltp": 1.84, "tv": 1389.49, "trd": NaN, "batb": [[0, 1.71, 18.08], [1, 1.7, 35.02], [2, 1.69, 105.27]], "batl": [[0, 1.98, 30.25], [1, 1.99, 24.5], [2, 2.02, 7.75]]}, {"timestamp": 1631531326710, "ltp": 1.84, "tv": 1389.49, "trd": NaN, "batb": [[0, 1.81, 18.08], [1, 1.71, 18.08], [2, 1.7, 35.02]], "batl": [[0, 1.98, 140.39], [2, 2, 138.1]]}, {"timestamp": 1631531327692, "ltp": 1.84, "tv": 1389.49, "trd": NaN, "batb": [[0, 1.71, 18.08], [1, 1.7, 35.02], [2, 1.69, 105.27]], "batl": NaN}, {"timestamp": 1631531333525, "ltp": 1.84, "tv": 1389.49, "trd": NaN, "batb": NaN, "batl": [[0, 1.93, 25.5], [1, 1.98, 140.39], [2, 1.99, 24.5]]}, {"timestamp": 1631531334714, "ltp": 1.84, "tv": 1389.49, "trd": NaN, "batb": NaN, "batl": [[0, 1.98, 140.39], [1, 1.99, 24.5], [2, 2, 138.1]]}, {"timestamp": 1631531335648, "ltp": 1.84, "tv": 1389.49, "trd": NaN, "batb": [[1, 1.69, 105.27], [2, 1.68, 169.46]], "batl": NaN}, {"timestamp": 1631531336019, "ltp": 1.84, "tv": 1389.49, "trd": NaN, "batb": [[2, 1.67, 415.42]], "batl": NaN}, {"timestamp": 1631531338719, "ltp": 1.98, "tv": 1391.72, "trd": [[1.98, 14.87]], "batb": [[0, 1.88, 2034.58], [1, 1.87, 1976.78], [2, 1.86, 1974.74]], "batl": [[0, 1.98, 134.16]]}, {"timestamp": 1631531339751, "ltp": 1.98, "tv": 1391.72, "trd": NaN, "batb": [[0, 1.93, 68.2], [1, 1.91, 170.65], [2, 1.89, 161.12]], "batl": NaN}, {"timestamp": 1631531341739, "ltp": 1.98, "tv": 1391.72, "trd": NaN, "batb": [[1, 1.92, 4], [2, 1.91, 174.65]], "batl": NaN}, {"timestamp": 1631531346449, "ltp": 1.98, "tv": 1396.82, "trd": [[1.98, 19.97]], "batb": NaN, "batl": [[0, 1.98, 129.06]]}, {"timestamp": 1631531351538, "ltp": 1.93, "tv": 1397.13, "trd": [[1.93, 0.31]], "batb": [[0, 1.93, 68.05]], "batl": NaN}, {"timestamp": 1631531357470, "ltp": 1.93, "tv": 1397.13, "trd": NaN, "batb": [[0, 1.9, 63.24], [1, 1.79, 85.86], [2, 1.7, 37.12]], "batl": [[0, 2.04, 58.83], [1, 2.18, 6.75], [2, 2.24, 6.48]]}, {"timestamp": 1631531358466, "ltp": 1.93, "tv": 1397.13, "trd": NaN, "batb": [[0, 1.79, 85.86], [1, 1.7, 37.12], [2, 1.67, 415.42]], "batl": [[0, 2.18, 6.75], [1, 2.24, 6.48], [2, 2.26, 7.25]]}, {"timestamp": 1631531358776, "ltp": 1.93, "tv": 1397.13, "trd": NaN, "batb": NaN, "batl": [[0, 2.28, 7.09], [1, 2.5, 278.33], [2, 3.45, 53.16]]}, {"timestamp": 1631531360657, "ltp": 1.93, "tv": 1397.13, "trd": NaN, "batb": [[0, 1.79, 115.17], [1, 1.78, 207.84], [2, 1.76, 203.59]], "batl": [[0, 2.18, 171.1], [1, 2.2, 104.7], [2, 2.28, 7.09]]}, {"timestamp": 1631531361652, "ltp": 1.93, "tv": 1397.13, "trd": NaN, "batb": [[0, 1.79, 85.86]], "batl": [[0, 2.18, 174.1]]}, {"timestamp": 1631531362274, "ltp": 1.93, "tv": 1397.13, "trd": NaN, "batb": NaN, "batl": [[0, 2.18, 3], [1, 2.28, 7.09], [2, 2.5, 278.33]]}, {"timestamp": 1631531364575, "ltp": 1.93, "tv": 1397.13, "trd": NaN, "batb": [[0, 1.79, 120.17]], "batl": [[0, 1.85, 1740.3], [1, 1.86, 2056.44], [2, 1.87, 1995.96]]}, {"timestamp": 1631531365669, "ltp": 1.93, "tv": 1397.13, "trd": NaN, "batb": [[0, 1.79, 85.86]], "batl": [[0, 1.85, 199.47], [1, 1.86, 1028.22], [2, 1.87, 1167.69]]}, {"timestamp": 1631531366662, "ltp": 1.93, "tv": 1397.13, "trd": NaN, "batb": [[0, 1.79, 115.92], [2, 1.77, 68.37]], "batl": NaN}, {"timestamp": 1631531371731, "ltp": 1.93, "tv": 1397.13, "trd": NaN, "batb": [[0, 1.8, 18.08], [1, 1.79, 115.92], [2, 1.78, 207.84]], "batl": NaN}, {"timestamp": 1631531376712, "ltp": 1.93, "tv": 1397.13, "trd": NaN, "batb": [[2, 1.77, 68.37]], "batl": [[0, 1.85, 182.92]]}, {"timestamp": 1631531379370, "ltp": 1.93, "tv": 1397.13, "trd": NaN, "batb": [[1, 1.77, 68.37], [2, 1.71, 37.19]], "batl": [[0, 1.88, 60], [1, 1.95, 28.5], [2, 1.98, 25.75]]}, {"timestamp": 1631531380515, "ltp": 1.93, "tv": 1397.13, "trd": NaN, "batb": [[0, 1.71, 37.19], [1, 1.7, 37.12], [2, 1.69, 104.01]], "batl": [[0, 2, 25.48], [1, 2.04, 7.88], [2, 2.16, 4]]}, {"timestamp": 1631531380831, "ltp": 1.93, "tv": 1397.13, "trd": NaN, "batb": [[0, 1.69, 104.01], [1, 1.67, 415.42], [2, 1.65, 42.73]], "batl": NaN}, {"timestamp": 1631531382750, "ltp": 1.93, "tv": 1397.13, "trd": NaN, "batb": [[0, 1.69, 103.76]], "batl": [[0, 1.99, 114.07], [1, 2, 25.48], [2, 2.02, 202.09]]}, {"timestamp": 1631531383429, "ltp": 1.93, "tv": 1397.13, "trd": NaN, "batb": [[0, 1.69, 226.72], [1, 1.67, 659.26]], "batl": NaN}, {"timestamp": 1631531384318, "ltp": 1.93, "tv": 1397.13, "trd": NaN, "batb": [[0, 1.85, 41.84], [1, 1.69, 230.72], [2, 1.68, 5]], "batl": [[0, 2.16, 4], [1, 2.5, 278.33], [2, 3.45, 53.16]]}, {"timestamp": 1631531385667, "ltp": 1.93, "tv": 1397.13, "trd": NaN, "batb": [[1, 1.71, 18.08], [2, 1.7, 18.08]], "batl": [[1, 3.45, 53.16], [2, 3.45, 0]]}, {"timestamp": 1631531386759, "ltp": 1.85, "tv": 1480.81, "trd": [[1.85, 83.68]], "batb": [[0, 1.71, 18.08], [1, 1.7, 18.08], [2, 1.69, 230.72]], "batl": [[0, 1.75, 2185.72], [1, 1.76, 2121.44], [2, 1.77, 2121.44]]}, {"timestamp": 1631531387743, "ltp": 1.85, "tv": 1480.81, "trd": NaN, "batb": NaN, "batl": [[0, 1.74, 162.35], [1, 1.75, 1092.86], [2, 1.76, 1267.18]]}, {"timestamp": 1631531388732, "ltp": 1.85, "tv": 1480.81, "trd": NaN, "batb": [[0, 1.7, 18.08], [1, 1.69, 230.72], [2, 1.68, 5]], "batl": NaN}, {"timestamp": 1631531395653, "ltp": 1.85, "tv": 1480.81, "trd": NaN, "batb": [[0, 1.7, 120.25], [2, 1.67, 243.84]], "batl": [[1, 1.75, 1152.86]]}, {"timestamp": 1631531396328, "ltp": 1.85, "tv": 1480.81, "trd": NaN, "batb": [[1, 1.69, 126.96]], "batl": NaN}, {"timestamp": 1631531399440, "ltp": 1.74, "tv": 1491.23, "trd": [[1.74, 10.42]], "batb": NaN, "batl": [[0, 1.74, 157.14]]}, {"timestamp": 1631531400642, "ltp": 1.7, "tv": 1492.96, "trd": [[1.7, 1.74]], "batb": [[0, 1.7, 101.31]], "batl": NaN}, {"timestamp": 1631531407164, "ltp": 1.7, "tv": 1634.14, "trd": [[1.7, 142.92]], "batb": [[0, 1.7, 30.72]], "batl": NaN}, {"timestamp": 1631531410452, "ltp": 1.74, "tv": 1834.14, "trd": [[1.74, 210.42]], "batb": NaN, "batl": [[0, 1.75, 1152.86], [1, 1.76, 1060.72], [2, 1.77, 1060.72]]}, {"timestamp": 1631531412690, "ltp": 1.74, "tv": 1834.14, "trd": NaN, "batb": [[0, 1.69, 230.47], [1, 1.67, 243.84], [2, 1.65, 754.65]], "batl": NaN}, {"timestamp": 1631531413373, "ltp": 1.74, "tv": 1834.14, "trd": NaN, "batb": [[0, 1.69, 297]], "batl": [[0, 1.75, 1354.76], [2, 1.77, 1262.98]]}, {"timestamp": 1631531415662, "ltp": 1.74, "tv": 1834.14, "trd": NaN, "batb": [[0, 1.69, 327.22]], "batl": NaN}, {"timestamp": 1631531418161, "ltp": 1.74, "tv": 1834.14, "trd": NaN, "batb": NaN, "batl": [[0, 1.7, 28.24], [1, 1.75, 1354.76], [2, 1.76, 1060.72]]}, {"timestamp": 1631531421377, "ltp": 1.69, "tv": 1838.16, "trd": [[1.69, 4.02]], "batb": [[0, 1.69, 325.21]], "batl": NaN}, {"timestamp": 1631531424599, "ltp": 1.69, "tv": 2437.11, "trd": [[1.69, 568.72], [1.7, 177.16]], "batb": [[0, 1.69, 42.86]], "batl": [[0, 1.7, 257.12]]}, {"timestamp": 1631531425404, "ltp": 1.69, "tv": 2437.11, "trd": NaN, "batb": [[0, 1.65, 754.65], [1, 1.64, 1125], [2, 1.63, 1125]], "batl": [[1, 1.75, 1152.86]]}, {"timestamp": 1631531428693, "ltp": 1.7, "tv": 2470.55, "trd": [[1.7, 210.6]], "batb": [[0, 1.69, 39.75], [1, 1.68, 323.08], [2, 1.66, 249.72]], "batl": [[0, 1.7, 240.4], [1, 1.74, 192.76], [2, 1.75, 1152.86]]}, {"timestamp": 1631531436714, "ltp": 1.7, "tv": 2476.24, "trd": [[1.7, 216.29]], "batb": NaN, "batl": [[0, 1.7, 234.71]]}, {"timestamp": 1631531440601, "ltp": 1.69, "tv": 2546.82, "trd": [[1.69, 639.3]], "batb": [[0, 1.69, 4.46], [1, 1.68, 318.08]], "batl": NaN}, {"timestamp": 1631531456218, "ltp": 1.68, "tv": 3182.11, "trd": [[1.68, 626.38], [1.69, 648.22]], "batb": [[0, 1.68, 4.9], [1, 1.66, 249.72], [2, 1.65, 754.65]], "batl": NaN}, {"timestamp": 1631531456840, "ltp": 1.68, "tv": 3182.11, "trd": NaN, "batb": [[1, 1.66, 125.94]], "batl": [[1, 1.75, 1152.86], [2, 1.76, 1060.72]]}, {"timestamp": 1631531459721, "ltp": 1.68, "tv": 3182.11, "trd": NaN, "batb": [[0, 1.69, 6], [1, 1.68, 9.9], [2, 1.67, 212.86]], "batl": [[1, 1.73, 206.01], [2, 1.75, 1363.8]]}, {"timestamp": 1631531460440, "ltp": 1.68, "tv": 3182.11, "trd": NaN, "batb": [[0, 1.69, 30.5]], "batl": NaN}, {"timestamp": 1631531461225, "ltp": 1.69, "tv": 3194.11, "trd": [[1.69, 660.22]], "batb": [[0, 1.68, 9.9], [1, 1.67, 212.86], [2, 1.66, 125.94]], "batl": [[0, 1.7, 235.54]]}, {"timestamp": 1631531464438, "ltp": 1.69, "tv": 3194.11, "trd": NaN, "batb": [[0, 1.68, 45.37]], "batl": NaN}, {"timestamp": 1631531467966, "ltp": 1.69, "tv": 3194.11, "trd": NaN, "batb": NaN, "batl": [[0, 1.69, 36.12], [1, 1.7, 234.71], [2, 1.73, 206.01]]}, {"timestamp": 1631531470154, "ltp": 1.69, "tv": 3194.11, "trd": NaN, "batb": [[2, 1.66, 2190.88]], "batl": NaN}, {"timestamp": 1631531474873, "ltp": 1.69, "tv": 3206.12, "trd": [[1.69, 672.23]], "batb": NaN, "batl": [[0, 1.69, 30.12]]}, {"timestamp": 1631531479154, "ltp": 1.69, "tv": 3207.55, "trd": [[1.69, 673.66]], "batb": NaN, "batl": [[0, 1.69, 28.69]]}, {"timestamp": 1631531483376, "ltp": 1.69, "tv": 3207.55, "trd": NaN, "batb": [[0, 1.68, 9.9]], "batl": NaN}, {"timestamp": 1631531485084, "ltp": 1.69, "tv": 3222.55, "trd": [[1.69, 688.66]], "batb": NaN, "batl": [[0, 1.69, 21.19]]}, {"timestamp": 1631531490500, "ltp": 1.69, "tv": 3236.21, "trd": [[1.69, 702.32]], "batb": [[0, 1.68, 45.37]], "batl": [[0, 1.69, 14.36]]}, {"timestamp": 1631531493680, "ltp": 1.69, "tv": 3246.83, "trd": [[1.69, 712.94]], "batb": NaN, "batl": [[0, 1.69, 9.05]]}, {"timestamp": 1631531499589, "ltp": 1.69, "tv": 3262.45, "trd": [[1.69, 728.56]], "batb": [[0, 1.68, 5], [1, 1.66, 2064.94], [2, 1.65, 74.42]], "batl": [[0, 1.69, 1.24], [2, 1.75, 60]]}, {"timestamp": 1631531500520, "ltp": 1.69, "tv": 3262.45, "trd": NaN, "batb": [[0, 1.66, 2064.94], [1, 1.63, 42.23], [2, 1.61, 123.68]], "batl": [[1, 1.77, 31.5], [2, 1.94, 4]]}, {"timestamp": 1631531501096, "ltp": 1.69, "tv": 3262.45, "trd": NaN, "batb": [[0, 1.61, 123.68], [1, 1.6, 40.44], [2, 1.3, 197.5]], "batl": NaN}, {"timestamp": 1631531502712, "ltp": 1.69, "tv": 3262.45, "trd": NaN, "batb": [[0, 1.61, 255.63], [1, 1.6, 310.69]], "batl": [[2, 1.79, 136.93]]}, {"timestamp": 1631531503700, "ltp": 1.69, "tv": 3262.45, "trd": NaN, "batb": [[0, 1.61, 131.95]], "batl": NaN}, {"timestamp": 1631531504702, "ltp": 1.69, "tv": 3262.45, "trd": NaN, "batb": [[0, 1.63, 6], [1, 1.62, 5], [2, 1.61, 137.95]], "batl": NaN}, {"timestamp": 1631531507608, "ltp": 1.69, "tv": 3262.45, "trd": NaN, "batb": [[0, 1.63, 518], [1, 1.62, 517]], "batl": NaN}, {"timestamp": 1631531507919, "ltp": 1.69, "tv": 3262.45, "trd": NaN, "batb": [[0, 1.63, 554.23], [1, 1.62, 535.08]], "batl": NaN}, {"timestamp": 1631531509425, "ltp": 1.77, "tv": 3284.56, "trd": [[1.69, 731.04], [1.77, 19.62]], "batb": [[1, 1.62, 517]], "batl": [[0, 1.77, 21.69], [1, 1.79, 136.93], [2, 1.81, 188.53]]}, {"timestamp": 1631531512698, "ltp": 1.77, "tv": 3284.56, "trd": NaN, "batb": [[0, 1.73, 8.04], [1, 1.63, 554.23], [2, 1.62, 517]], "batl": [[0, 1.79, 136.93], [1, 1.81, 188.53], [2, 1.94, 4]]}, {"timestamp": 1631531513216, "ltp": 1.77, "tv": 3284.56, "trd": NaN, "batb": [[0, 1.64, 18.08]], "batl": NaN}, {"timestamp": 1631531515716, "ltp": 1.77, "tv": 3284.56, "trd": NaN, "batb": [[0, 1.73, 213.8], [1, 1.71, 241.99], [2, 1.64, 18.08]], "batl": [[0, 1.79, 140.93]]}, {"timestamp": 1631531516498, "ltp": 1.77, "tv": 3284.56, "trd": NaN, "batb": [[0, 1.73, 309.45], [1, 1.71, 313.19], [2, 1.67, 109.04]], "batl": [[0, 1.79, 136.93], [2, 1.84, 60]]}, {"timestamp": 1631531518633, "ltp": 1.77, "tv": 3284.56, "trd": NaN, "batb": [[0, 1.74, 5], [1, 1.73, 315.45], [2, 1.72, 5]], "batl": NaN}, {"timestamp": 1631531521819, "ltp": 1.75, "tv": 3292.56, "trd": [[1.75, 8]], "batb": NaN, "batl": [[0, 1.75, 27.34], [1, 1.79, 136.93], [2, 1.81, 188.53]]}, {"timestamp": 1631531523703, "ltp": 1.75, "tv": 3347.24, "trd": [[1.75, 62.68]], "batb": [[0, 1.75, 63.06], [1, 1.74, 5], [2, 1.73, 385.67]], "batl": [[0, 1.79, 136.93], [1, 1.81, 188.53], [2, 1.84, 60]]}, {"timestamp": 1631531524743, "ltp": 1.75, "tv": 3347.24, "trd": NaN, "batb": [[0, 1.74, 5], [1, 1.73, 385.67], [2, 1.72, 5]], "batl": NaN}, {"timestamp": 1631531526730, "ltp": 1.73, "tv": 3817.15, "trd": [[1.73, 435.7], [1.74, 244.63]], "batb": [[0, 1.73, 167.82], [1, 1.72, 5], [2, 1.71, 229.8]], "batl": [[1, 1.8, 29.62], [2, 1.81, 188.53]]}, {"timestamp": 1631531527722, "ltp": 1.73, "tv": 3817.15, "trd": NaN, "batb": [[0, 1.73, 76.22], [2, 1.71, 5]], "batl": [[0, 1.8, 29.62], [1, 1.81, 33.5], [2, 1.84, 60]]}, {"timestamp": 1631531528610, "ltp": 1.73, "tv": 3817.15, "trd": NaN, "batb": [[0, 1.69, 312], [1, 1.68, 351.36], [2, 1.67, 109.04]], "batl": [[2, 1.94, 4]]}, {"timestamp": 1631531530736, "ltp": 1.73, "tv": 3817.15, "trd": NaN, "batb": [[0, 1.75, 2.32], [1, 1.69, 312], [2, 1.68, 351.36]], "batl": NaN}, {"timestamp": 1631531531415, "ltp": 1.73, "tv": 3817.15, "trd": NaN, "batb": NaN, "batl": [[2, 1.85, 194.51]]}, {"timestamp": 1631531533753, "ltp": 1.73, "tv": 3817.15, "trd": NaN, "batb": NaN, "batl": [[0, 1.78, 29.75], [1, 1.8, 29.62], [2, 1.81, 33.5]]}, {"timestamp": 1631531534117, "ltp": 1.73, "tv": 3817.15, "trd": NaN, "batb": NaN, "batl": [[0, 1.8, 29.62], [1, 1.81, 33.5], [2, 1.85, 194.51]]}, {"timestamp": 1631531536732, "ltp": 1.8, "tv": 3876.39, "trd": [[1.8, 59.24]], "batb": [[0, 1.8, 2116.16], [1, 1.79, 1312.84], [2, 1.78, 656.42]], "batl": [[0, 1.81, 33.5], [1, 1.85, 194.51], [2, 1.87, 169.63]]}, {"timestamp": 1631531537725, "ltp": 1.8, "tv": 3891.07, "trd": [[1.8, 73.92]], "batb": [[0, 1.8, 2104.48], [1, 1.79, 262.56], [2, 1.78, 326.63]], "batl": NaN}, {"timestamp": 1631531538553, "ltp": 1.81, "tv": 3924.57, "trd": [[1.81, 33.5]], "batb": [[1, 1.79, 348.08]], "batl": [[0, 1.85, 194.51], [1, 1.87, 169.63], [2, 2.26, 8.85]]}, {"timestamp": 1631531540535, "ltp": 1.81, "tv": 3924.57, "trd": NaN, "batb": [[0, 1.81, 5], [1, 1.8, 2108.48], [2, 1.79, 348.08]], "batl": NaN}, {"timestamp": 1631531541736, "ltp": 1.81, "tv": 3924.57, "trd": NaN, "batb": [[0, 1.79, 153.02], [1, 1.78, 195.35], [2, 1.76, 203.39]], "batl": [[2, 1.91, 86.52]]}, {"timestamp": 1631531542364, "ltp": 1.81, "tv": 3924.57, "trd": NaN, "batb": [[0, 1.75, 2.32], [1, 1.73, 96.99], [2, 1.65, 46.93]], "batl": [[0, 3.45, 53.16], [1, 1.87, 0], [2, 1.91, 0]]}, {"timestamp": 1631531543767, "ltp": 1.81, "tv": 3924.57, "trd": NaN, "batb": [[2, 1.71, 84.19]], "batl": NaN}, {"timestamp": 1631531544657, "ltp": 1.81, "tv": 3924.57, "trd": NaN, "batb": [[2, 1.65, 46.93]], "batl": [[0, 1.85, 4], [1, 3.45, 53.16]]}, {"timestamp": 1631531545543, "ltp": 1.81, "tv": 3924.57, "trd": NaN, "batb": [[2, 1.72, 204.46]], "batl": [[1, 1.87, 4], [2, 1.9, 135.9]]}, {"timestamp": 1631531550676, "ltp": 1.81, "tv": 3924.57, "trd": NaN, "batb": [[2, 1.71, 83.19]], "batl": [[2, 1.91, 4]]}, {"timestamp": 1631531550938, "ltp": 1.81, "tv": 3924.57, "trd": NaN, "batb": [[2, 1.65, 46.93]], "batl": NaN}, {"timestamp": 1631531553751, "ltp": 1.84, "tv": 3944.09, "trd": [[1.84, 22.4]], "batb": [[0, 1.77, 173.75], [1, 1.75, 209.74], [2, 1.73, 96.99]], "batl": [[0, 1.83, 137.45], [1, 1.85, 179.68], [2, 1.87, 4]]}, {"timestamp": 1631531556670, "ltp": 1.84, "tv": 3944.09, "trd": NaN, "batb": NaN, "batl": [[1, 1.84, 4], [2, 1.85, 179.68]]}, {"timestamp": 1631531558188, "ltp": 1.84, "tv": 3944.09, "trd": NaN, "batb": [[0, 1.75, 2.32], [1, 1.73, 96.99], [2, 1.65, 46.93]], "batl": [[0, 1.84, 4], [1, 3.45, 53.16], [2, 1.85, 0]]}, {"timestamp": 1631531559495, "ltp": 1.73, "tv": 4085.27, "trd": [[1.73, 572.24], [1.75, 67.32]], "batb": [[0, 1.73, 28.72], [1, 1.65, 46.93], [2, 1.3, 197.5]], "batl": NaN}, {"timestamp": 1631531561471, "ltp": 1.73, "tv": 4085.27, "trd": NaN, "batb": [[1, 1.72, 204.46], [2, 1.71, 86.19]], "batl": [[1, 1.9, 135.9], [2, 1.92, 156]]}, {"timestamp": 1631531561887, "ltp": 1.73, "tv": 4085.27, "trd": NaN, "batb": NaN, "batl": [[1, 3.45, 53.16], [2, 1.92, 0]]}, {"timestamp": 1631531562774, "ltp": 1.73, "tv": 4085.27, "trd": NaN, "batb": [[0, 1.72, 204.46], [1, 1.71, 86.19], [2, 1.7, 229.72]], "batl": NaN}, {"timestamp": 1631531564589, "ltp": 1.73, "tv": 4085.27, "trd": NaN, "batb": NaN, "batl": [[0, 1.78, 1841.92], [1, 1.79, 2136.88], [2, 1.8, 2074.02]]}, {"timestamp": 1631531565685, "ltp": 1.78, "tv": 4098.14, "trd": [[1.78, 12.87]], "batb": [[0, 1.72, 302.78]], "batl": [[0, 1.78, 161.56], [1, 1.79, 1068.44], [2, 1.8, 1229.2]]}, {"timestamp": 1631531566367, "ltp": 1.78, "tv": 4098.14, "trd": NaN, "batb": [[0, 1.72, 373.49]], "batl": NaN}, {"timestamp": 1631531567096, "ltp": 1.78, "tv": 4098.14, "trd": NaN, "batb": [[0, 1.73, 46.2], [1, 1.72, 373.49], [2, 1.71, 86.19]], "batl": NaN}, {"timestamp": 1631531568085, "ltp": 1.78, "tv": 4098.14, "trd": NaN, "batb": [[0, 1.73, 5], [1, 1.72, 377.49]], "batl": NaN}, {"timestamp": 1631531570593, "ltp": 1.78, "tv": 4098.14, "trd": NaN, "batb": [[0, 1.74, 4], [1, 1.73, 5], [2, 1.72, 377.49]], "batl": NaN}, {"timestamp": 1631531571484, "ltp": 1.78, "tv": 4098.14, "trd": NaN, "batb": [[0, 1.74, 24]], "batl": NaN}, {"timestamp": 1631531573718, "ltp": 1.78, "tv": 4098.14, "trd": NaN, "batb": [[0, 1.75, 4], [1, 1.74, 24], [2, 1.73, 5]], "batl": NaN}, {"timestamp": 1631531576686, "ltp": 1.78, "tv": 4098.14, "trd": NaN, "batb": NaN, "batl": [[0, 1.78, 156.91]]}, {"timestamp": 1631531577684, "ltp": 1.78, "tv": 4098.14, "trd": NaN, "batb": [[0, 1.72, 275.17], [1, 1.7, 229.72], [2, 1.67, 83.47]], "batl": [[1, 1.8, 192.18], [2, 1.83, 60]]}, {"timestamp": 1631531578515, "ltp": 1.78, "tv": 4098.14, "trd": NaN, "batb": [[0, 1.65, 6], [1, 1.64, 115.23], [2, 1.62, 79.54]], "batl": [[0, 3.45, 53.16], [1, 1.8, 0], [2, 1.83, 0]]}, {"timestamp": 1631531579294, "ltp": 1.78, "tv": 4098.14, "trd": NaN, "batb": [[0, 1.76, 2.32], [1, 1.65, 6], [2, 1.64, 115.23]], "batl": NaN}, {"timestamp": 1631531580691, "ltp": 1.78, "tv": 4098.14, "trd": NaN, "batb": [[1, 1.65, 287.9], [2, 1.64, 247.01]], "batl": [[0, 1.85, 130.52], [1, 1.87, 169.59], [2, 3.45, 53.16]]}, {"timestamp": 1631531581599, "ltp": 1.78, "tv": 4098.14, "trd": NaN, "batb": [[2, 1.64, 136.78]], "batl": [[0, 1.84, 5], [1, 1.85, 135.52], [2, 1.87, 169.59]]}, {"timestamp": 1631531581805, "ltp": 1.78, "tv": 4098.14, "trd": NaN, "batb": [[1, 1.65, 119.97], [2, 1.64, 5]], "batl": NaN}, {"timestamp": 1631531584723, "ltp": 1.78, "tv": 4098.14, "trd": NaN, "batb": [[0, 1.79, 1891.2], [1, 1.78, 2.32], [2, 1.77, 1080.52]], "batl": [[0, 1.85, 130.52], [1, 1.87, 169.59], [2, 3.45, 53.16]]}, {"timestamp": 1631531585711, "ltp": 1.78, "tv": 4098.14, "trd": NaN, "batb": [[0, 1.8, 85.02], [1, 1.79, 247.97], [2, 1.78, 2.32]], "batl": [[2, 2.28, 8.77]]}, {"timestamp": 1631531587488, "ltp": 1.85, "tv": 4117.66, "trd": [[1.85, 103.2]], "batb": [[0, 1.8, 89.02], [1, 1.79, 185.47]], "batl": [[0, 1.85, 120.76]]}, {"timestamp": 1631531588732, "ltp": 1.85, "tv": 4117.66, "trd": NaN, "batb": [[0, 1.81, 4], [1, 1.8, 89.02], [2, 1.79, 185.47]], "batl": NaN}, {"timestamp": 1631531590718, "ltp": 1.85, "tv": 4117.66, "trd": NaN, "batb": [[0, 1.81, 100.8]], "batl": NaN}, {"timestamp": 1631531592531, "ltp": 1.85, "tv": 4117.66, "trd": NaN, "batb": [[0, 1.82, 4], [1, 1.81, 100.8], [2, 1.8, 89.02]], "batl": NaN}, {"timestamp": 1631531595547, "ltp": 1.85, "tv": 4117.66, "trd": NaN, "batb": [[0, 1.81, 66.66], [1, 1.78, 2.32], [2, 1.76, 2.32]], "batl": [[0, 2.5, 278.33], [1, 3.45, 53.16], [2, 2.28, 0]]}, {"timestamp": 1631531596542, "ltp": 1.85, "tv": 4117.66, "trd": NaN, "batb": [[0, 1.78, 2.32], [1, 1.76, 2.32], [2, 1.73, 96.15]], "batl": NaN}, {"timestamp": 1631531598728, "ltp": 1.85, "tv": 4117.66, "trd": NaN, "batb": [[2, 1.73, 281.2]], "batl": [[0, 1.9, 5], [1, 1.91, 165.83], [2, 1.93, 214.36]]}, {"timestamp": 1631531599041, "ltp": 1.85, "tv": 4117.66, "trd": NaN, "batb": NaN, "batl": [[2, 1.93, 154.36]]}, {"timestamp": 1631531602517, "ltp": 1.85, "tv": 4117.66, "trd": NaN, "batb": [[2, 1.73, 96.15]], "batl": NaN}, {"timestamp": 1631531603658, "ltp": 1.85, "tv": 4117.66, "trd": NaN, "batb": [[0, 1.84, 2590.3], [1, 1.78, 2.32], [2, 1.76, 2.32]], "batl": NaN}, {"timestamp": 1631531603861, "ltp": 1.85, "tv": 4117.66, "trd": NaN, "batb": [[0, 1.78, 2.32], [1, 1.76, 2.32], [2, 1.73, 96.15]], "batl": NaN}, {"timestamp": 1631531605743, "ltp": 1.85, "tv": 4117.66, "trd": NaN, "batb": [[0, 1.85, 77.66], [1, 1.84, 173.1], [2, 1.82, 1232.21]], "batl": [[0, 1.91, 161.83], [1, 1.93, 154.36], [2, 1.94, 542.2]]}, {"timestamp": 1631531606728, "ltp": 1.85, "tv": 4117.66, "trd": NaN, "batb": [[0, 1.87, 64.32], [1, 1.85, 77.66], [2, 1.84, 173.1]], "batl": NaN}, {"timestamp": 1631531608233, "ltp": 1.85, "tv": 4117.66, "trd": NaN, "batb": [[1, 1.85, 81.66], [2, 1.84, 177.1]], "batl": NaN}, {"timestamp": 1631531609630, "ltp": 1.85, "tv": 4117.66, "trd": NaN, "batb": [[0, 1.88, 5], [1, 1.87, 68.32], [2, 1.86, 4]], "batl": NaN}, {"timestamp": 1631531610252, "ltp": 1.85, "tv": 4117.66, "trd": NaN, "batb": [[1, 1.87, 32.43]], "batl": NaN}, {"timestamp": 1631531613463, "ltp": 1.85, "tv": 4117.66, "trd": NaN, "batb": [[0, 1.89, 63.59], [1, 1.88, 5], [2, 1.87, 32.43]], "batl": NaN}, {"timestamp": 1631531621663, "ltp": 1.89, "tv": 4122.45, "trd": [[1.89, 4.78]], "batb": [[0, 1.89, 61.2], [2, 1.87, 28.43]], "batl": NaN}, {"timestamp": 1631531623576, "ltp": 1.89, "tv": 4132.49, "trd": [[1.89, 14.82]], "batb": [[0, 1.89, 56.18]], "batl": NaN}, {"timestamp": 1631531624665, "ltp": 1.89, "tv": 4132.49, "trd": NaN, "batb": [[0, 1.89, 58.57], [2, 1.78, 2.32]], "batl": [[0, 2.5, 278.33], [1, 3.45, 53.16], [2, 1.94, 0]]}, {"timestamp": 1631531625487, "ltp": 1.89, "tv": 4132.49, "trd": NaN, "batb": [[0, 1.78, 2.32], [1, 1.76, 93.37], [2, 1.63, 83.23]], "batl": NaN}, {"timestamp": 1631531627568, "ltp": 1.89, "tv": 4132.49, "trd": NaN, "batb": NaN, "batl": [[0, 2.02, 59.4], [1, 2.5, 278.33], [2, 3.45, 53.16]]}, {"timestamp": 1631531628288, "ltp": 1.89, "tv": 4132.49, "trd": NaN, "batb": NaN, "batl": [[0, 2.5, 278.33], [1, 3.45, 53.16], [2, 3.45, 0]]}, {"timestamp": 1631531630093, "ltp": 1.89, "tv": 4132.49, "trd": NaN, "batb": [[0, 1.87, 115.3], [1, 1.85, 171.91], [2, 1.78, 2.32]], "batl": [[0, 1.93, 117.7], [1, 1.95, 148.6], [2, 2.5, 278.33]]}, {"timestamp": 1631531631495, "ltp": 1.89, "tv": 4132.49, "trd": NaN, "batb": [[0, 1.79, 11.6], [1, 1.78, 2.32], [2, 1.76, 93.37]], "batl": [[2, 2, 28.7]]}, {"timestamp": 1631531631968, "ltp": 1.89, "tv": 4132.49, "trd": NaN, "batb": [[0, 1.78, 2.32], [1, 1.76, 93.37], [2, 1.72, 81.84]], "batl": [[0, 2.06, 3], [1, 2.5, 278.33], [2, 3.45, 53.16]]}, {"timestamp": 1631531636191, "ltp": 1.89, "tv": 4132.49, "trd": NaN, "batb": [[2, 1.75, 179.44]], "batl": [[0, 2.04, 146.17], [1, 2.06, 128.97], [2, 2.5, 278.33]]}, {"timestamp": 1631531637798, "ltp": 1.9, "tv": 4142.49, "trd": [[1.9, 36.21]], "batb": NaN, "batl": NaN}, {"timestamp": 1631531641106, "ltp": 1.9, "tv": 4142.49, "trd": NaN, "batb": [[2, 1.72, 81.84]], "batl": [[0, 2.06, 3], [1, 2.5, 278.33], [2, 3.45, 53.16]]}, {"timestamp": 1631531643496, "ltp": 1.9, "tv": 4142.49, "trd": NaN, "batb": NaN, "batl": [[0, 2.5, 278.33], [1, 3.45, 53.16], [2, 3.45, 0]]}, {"timestamp": 1631531644688, "ltp": 1.9, "tv": 4142.49, "trd": NaN, "batb": [[0, 1.95, 24.1], [1, 1.93, 990.94], [2, 1.92, 961.8]], "batl": NaN}, {"timestamp": 1631531645723, "ltp": 1.9, "tv": 4142.49, "trd": NaN, "batb": [[0, 1.99, 60.3], [1, 1.98, 125.77], [2, 1.95, 24.1]], "batl": [[0, 2.16, 55.7], [1, 2.46, 8.13], [2, 2.5, 278.33]]}, {"timestamp": 1631531646711, "ltp": 1.9, "tv": 4142.49, "trd": NaN, "batb": NaN, "batl": [[1, 2.32, 97.21], [2, 2.46, 8.13]]}, {"timestamp": 1631531647222, "ltp": 1.9, "tv": 4142.49, "trd": NaN, "batb": [[2, 1.97, 4]], "batl": [[1, 2.46, 8.13], [2, 2.5, 278.33]]}, {"timestamp": 1631531648620, "ltp": 1.9, "tv": 4142.49, "trd": NaN, "batb": [[0, 2, 4], [1, 1.99, 64.3], [2, 1.98, 129.77]], "batl": NaN}, {"timestamp": 1631531649299, "ltp": 1.9, "tv": 4142.49, "trd": NaN, "batb": [[0, 2, 29.45], [1, 1.99, 4]], "batl": NaN}, {"timestamp": 1631531650703, "ltp": 1.9, "tv": 4142.49, "trd": NaN, "batb": NaN, "batl": [[0, 2.14, 37.48], [1, 2.16, 155.78], [2, 2.46, 8.13]]}, {"timestamp": 1631531651318, "ltp": 1.9, "tv": 4142.49, "trd": NaN, "batb": NaN, "batl": [[1, 2.16, 55.7]]}, {"timestamp": 1631531652402, "ltp": 1.9, "tv": 4142.49, "trd": NaN, "batb": [[0, 2, 89.45]], "batl": NaN}, {"timestamp": 1631531660538, "ltp": 1.9, "tv": 4142.49, "trd": NaN, "batb": [[0, 2, 60], [1, 1.85, 76.74], [2, 1.78, 2.32]], "batl": [[0, 2.16, 55.7], [1, 2.5, 278.33], [2, 3.45, 53.16]]}, {"timestamp": 1631531661426, "ltp": 1.9, "tv": 4142.49, "trd": NaN, "batb": [[0, 1.85, 76.74], [1, 1.78, 2.32], [2, 1.76, 2.32]], "batl": [[0, 2.5, 278.33], [1, 3.45, 53.16], [2, 3.45, 0]]}, {"timestamp": 1631531663735, "ltp": 1.9, "tv": 4142.49, "trd": NaN, "batb": [[0, 1.86, 76.57]], "batl": NaN}, {"timestamp": 1631531664614, "ltp": 1.9, "tv": 4142.49, "trd": NaN, "batb": [[1, 1.82, 78.14], [2, 1.78, 2.32]], "batl": NaN}, {"timestamp": 1631531675241, "ltp": 1.9, "tv": 4142.49, "trd": NaN, "batb": [[1, 1.78, 2.32], [2, 1.76, 2.32]], "batl": NaN}, {"timestamp": 1631531676637, "ltp": 1.9, "tv": 4142.49, "trd": NaN, "batb": NaN, "batl": [[0, 3.45, 53.16], [1, 3.45, 0]]}, {"timestamp": 1631531677622, "ltp": 1.9, "tv": 4142.49, "trd": NaN, "batb": [[0, 2.1, 1821.42], [1, 2.08, 1767.86], [2, 2.06, 1767.86]], "batl": [[0, 2.26, 1692.48], [1, 2.28, 1642.7], [2, 2.3, 1642.7]]}, {"timestamp": 1631531678742, "ltp": 1.9, "tv": 4142.49, "trd": NaN, "batb": [[0, 2.14, 100], [1, 2.1, 910.7], [2, 2.08, 883.94]], "batl": [[0, 2.26, 465.43], [1, 2.28, 451.74], [2, 2.3, 451.74]]}, {"timestamp": 1631531679724, "ltp": 1.9, "tv": 4142.49, "trd": NaN, "batb": [[1, 2.12, 56.57], [2, 2.1, 914.7]], "batl": NaN}, {"timestamp": 1631531682634, "ltp": 1.9, "tv": 4142.49, "trd": NaN, "batb": [[0, 2.16, 4], [1, 2.14, 218.91], [2, 2.12, 56.57]], "batl": [[0, 2.24, 62.69], [1, 2.26, 465.43], [2, 2.28, 451.74]]}, {"timestamp": 1631531683253, "ltp": 1.9, "tv": 4142.49, "trd": NaN, "batb": [[2, 2.12, 3]], "batl": [[0, 2.26, 465.43], [1, 2.28, 451.74], [2, 2.3, 451.74]]}, {"timestamp": 1631531686463, "ltp": 1.9, "tv": 4142.49, "trd": NaN, "batb": [[1, 2.14, 156.63]], "batl": NaN}, {"timestamp": 1631531688757, "ltp": 1.9, "tv": 4142.49, "trd": NaN, "batb": [[0, 2.14, 52.63], [1, 2, 119.66], [2, 1.99, 68.51]], "batl": [[0, 2.32, 52.22], [1, 2.82, 234.47], [2, 3.45, 53.16]]}, {"timestamp": 1631531689577, "ltp": 1.9, "tv": 4142.49, "trd": NaN, "batb": [[0, 2, 119.66], [1, 1.99, 68.51], [2, 1.91, 69.39]], "batl": [[0, 2.82, 234.47], [1, 3.45, 53.16], [2, 3.45, 0]]}, {"timestamp": 1631531692635, "ltp": 1.9, "tv": 4142.49, "trd": NaN, "batb": NaN, "batl": [[0, 2.42, 4], [1, 2.82, 234.47], [2, 3.45, 53.16]]}, {"timestamp": 1631531704756, "ltp": 1.9, "tv": 4142.49, "trd": NaN, "batb": [[2, 1.97, 533.95]], "batl": [[1, 2.5, 8], [2, 2.82, 234.47]]}, {"timestamp": 1631531705690, "ltp": 1.9, "tv": 4142.49, "trd": NaN, "batb": [[0, 2.02, 58.82], [1, 2, 119.66], [2, 1.99, 68.51]], "batl": [[0, 2.2, 54.77], [1, 2.28, 144.64], [2, 2.42, 4]]}, {"timestamp": 1631531706369, "ltp": 1.9, "tv": 4142.49, "trd": NaN, "batb": [[0, 2.02, 87.92]], "batl": [[1, 2.42, 4], [2, 2.5, 8]]}, {"timestamp": 1631531707675, "ltp": 1.9, "tv": 4142.49, "trd": NaN, "batb": [[0, 2.02, 91.92], [1, 2, 124.66], [2, 1.97, 533.95]], "batl": NaN}, {"timestamp": 1631531708667, "ltp": 1.9, "tv": 4142.49, "trd": NaN, "batb": [[0, 2.04, 5], [1, 2.02, 91.92], [2, 2, 124.66]], "batl": NaN}, {"timestamp": 1631531709600, "ltp": 1.9, "tv": 4142.49, "trd": NaN, "batb": NaN, "batl": [[0, 2.18, 39.93], [1, 2.2, 54.77], [2, 2.42, 4]]}, {"timestamp": 1631531710601, "ltp": 1.9, "tv": 4142.49, "trd": NaN, "batb": NaN, "batl": [[0, 2.42, 4], [1, 2.5, 8], [2, 2.82, 234.47]]}, {"timestamp": 1631531712686, "ltp": 1.9, "tv": 4142.49, "trd": NaN, "batb": NaN, "batl": [[0, 2.2, 253.79], [1, 2.42, 4], [2, 2.5, 8]]}, {"timestamp": 1631531713685, "ltp": 1.9, "tv": 4142.49, "trd": NaN, "batb": NaN, "batl": [[0, 2.18, 55.23], [1, 2.2, 253.79], [2, 2.36, 39.93]]}, {"timestamp": 1631531714207, "ltp": 1.9, "tv": 4142.49, "trd": NaN, "batb": NaN, "batl": [[2, 2.42, 4]]}, {"timestamp": 1631531715714, "ltp": 2.04, "tv": 4147.49, "trd": [[2.04, 122.4]], "batb": [[0, 2.02, 33.1], [1, 2, 124.66], [2, 1.97, 533.95]], "batl": [[0, 2.2, 253.79], [1, 2.42, 4], [2, 2.5, 8]]}, {"timestamp": 1631531719669, "ltp": 2.04, "tv": 4147.49, "trd": NaN, "batb": [[2, 1.99, 60.3]], "batl": [[0, 2.16, 55.7], [1, 2.2, 253.79], [2, 2.42, 4]]}, {"timestamp": 1631531720704, "ltp": 2.04, "tv": 4147.49, "trd": NaN, "batb": [[1, 2, 119.66]], "batl": NaN}, {"timestamp": 1631531723575, "ltp": 2.04, "tv": 4147.49, "trd": NaN, "batb": [[0, 2.04, 4], [1, 2.02, 4]], "batl": [[1, 2.42, 4], [2, 2.82, 234.47]]}, {"timestamp": 1631531724507, "ltp": 2.04, "tv": 4147.49, "trd": NaN, "batb": [[0, 1.9, 63.66], [1, 1.87, 74.48], [2, 1.84, 73.72]], "batl": [[0, 2.42, 4], [1, 2.82, 234.47], [2, 3.45, 53.16]]}, {"timestamp": 1631531726697, "ltp": 2.04, "tv": 4147.49, "trd": NaN, "batb": [[1, 1.88, 74.06]], "batl": NaN}, {"timestamp": 1631531727689, "ltp": 2.04, "tv": 4147.49, "trd": NaN, "batb": NaN, "batl": [[0, 2.3, 3], [1, 2.42, 4], [2, 2.82, 234.47]]}, {"timestamp": 1631531730709, "ltp": 2.04, "tv": 4147.49, "trd": NaN, "batb": [[0, 1.91, 106.3], [1, 1.9, 63.66], [2, 1.88, 74.06]], "batl": NaN}, {"timestamp": 1631531733699, "ltp": 2.04, "tv": 4147.49, "trd": NaN, "batb": [[0, 1.9, 63.66], [1, 1.88, 74.06], [2, 1.84, 73.72]], "batl": NaN}, {"timestamp": 1631531734231, "ltp": 2.04, "tv": 4147.49, "trd": NaN, "batb": [[0, 1.88, 74.06], [1, 1.84, 73.72], [2, 1.78, 2.32]], "batl": NaN}, {"timestamp": 1631531737606, "ltp": 2.04, "tv": 4147.49, "trd": NaN, "batb": [[0, 1.89, 4], [1, 1.88, 79.06], [2, 1.87, 4]], "batl": NaN}, {"timestamp": 1631531739862, "ltp": 2.04, "tv": 4147.49, "trd": NaN, "batb": NaN, "batl": [[1, 2.82, 234.47], [2, 3.45, 53.16]]}, {"timestamp": 1631531751759, "ltp": 2.04, "tv": 4147.49, "trd": NaN, "batb": [[1, 1.88, 74.06], [2, 1.84, 73.72]], "batl": NaN}, {"timestamp": 1631531753641, "ltp": 2.04, "tv": 4147.49, "trd": NaN, "batb": NaN, "batl": [[0, 2.82, 234.47], [1, 3.45, 53.16], [2, 3.45, 0]]}, {"timestamp": 1631531754735, "ltp": 2.04, "tv": 4147.49, "trd": NaN, "batb": [[0, 2.2, 23.77], [1, 1.94, 626.63], [2, 1.89, 4]], "batl": [[0, 2.34, 449.53], [1, 2.36, 436.3], [2, 2.38, 436.3]]}, {"timestamp": 1631531755619, "ltp": 2.04, "tv": 4147.49, "trd": NaN, "batb": [[0, 2.2, 115.4], [1, 2.06, 110.46]], "batl": NaN}, {"timestamp": 1631531756759, "ltp": 2.04, "tv": 4147.49, "trd": NaN, "batb": [[0, 2.22, 3], [1, 2.2, 119.4], [2, 2.1, 54.54]], "batl": [[0, 2.3, 52.62], [1, 2.34, 449.53], [2, 2.36, 436.3]]}, {"timestamp": 1631531757748, "ltp": 2.22, "tv": 4150.49, "trd": [[2.22, 3]], "batb": [[0, 2.2, 119.4], [1, 2.1, 54.54], [2, 2.06, 110.46]], "batl": NaN}, {"timestamp": 1631531759667, "ltp": 2.22, "tv": 4150.49, "trd": NaN, "batb": NaN, "batl": [[1, 2.34, 537.77]]}, {"timestamp": 1631531760758, "ltp": 2.22, "tv": 4150.49, "trd": NaN, "batb": [[0, 2.2, 144.9], [1, 2.06, 110.46], [2, 1.89, 4]], "batl": NaN}, {"timestamp": 1631531761444, "ltp": 2.22, "tv": 4150.49, "trd": NaN, "batb": [[1, 2.08, 8.81], [2, 2.06, 110.46]], "batl": NaN}, {"timestamp": 1631531763677, "ltp": 2.22, "tv": 4150.49, "trd": NaN, "batb": [[1, 2.14, 52.63], [2, 2.08, 8.81]], "batl": NaN}, {"timestamp": 1631531771567, "ltp": 2.22, "tv": 4150.49, "trd": NaN, "batb": [[0, 2.14, 52.63], [1, 2.06, 110.46], [2, 2.04, 8.87]], "batl": [[1, 2.58, 5.44], [2, 2.82, 234.47]]}, {"timestamp": 1631531772471, "ltp": 2.22, "tv": 4150.49, "trd": NaN, "batb": [[0, 2.06, 110.46], [1, 2.04, 8.87], [2, 2.02, 8.24]], "batl": [[0, 2.52, 6.01], [2, 2.68, 4.64]]}, {"timestamp": 1631531772874, "ltp": 2.22, "tv": 4150.49, "trd": NaN, "batb": NaN, "batl": [[0, 2.58, 5.44], [1, 2.68, 4.64], [2, 2.82, 234.47]]}, {"timestamp": 1631531775679, "ltp": 2.22, "tv": 4150.49, "trd": NaN, "batb": NaN, "batl": [[0, 2.52, 3], [1, 2.58, 5.44], [2, 2.68, 4.64]]}, {"timestamp": 1631531777762, "ltp": 2.22, "tv": 4150.49, "trd": NaN, "batb": NaN, "batl": [[0, 2.46, 3], [1, 2.5, 3], [2, 2.52, 3]]}, {"timestamp": 1631531778172, "ltp": 2.28, "tv": 4150.94, "trd": [[2.28, 0.45]], "batb": NaN, "batl": [[0, 2.46, 9.25]]}, {"timestamp": 1631531779256, "ltp": 2.28, "tv": 4150.94, "trd": NaN, "batb": [[0, 2.08, 95.42], [1, 2.06, 110.46], [2, 2.04, 8.87]], "batl": NaN}, {"timestamp": 1631531780570, "ltp": 2.28, "tv": 4150.94, "trd": NaN, "batb": [[0, 2.06, 110.46], [1, 2.04, 8.87], [2, 2.02, 8.24]], "batl": NaN}, {"timestamp": 1631531781395, "ltp": 2.28, "tv": 4150.94, "trd": NaN, "batb": [[0, 2.08, 8.06], [1, 2.06, 110.46], [2, 2.04, 8.87]], "batl": [[0, 2.46, 3]]}, {"timestamp": 1631531782694, "ltp": 2.28, "tv": 4150.94, "trd": NaN, "batb": [[0, 2.06, 110.46], [1, 2.04, 8.87], [2, 2.02, 8.24]], "batl": [[0, 2.44, 37.97], [1, 2.46, 3], [2, 2.5, 3]]}, {"timestamp": 1631531783685, "ltp": 2.28, "tv": 4150.94, "trd": NaN, "batb": NaN, "batl": [[0, 2.46, 3], [1, 2.5, 3], [2, 2.52, 3]]}, {"timestamp": 1631531786002, "ltp": 2.28, "tv": 4150.94, "trd": NaN, "batb": [[0, 2.08, 8.81], [1, 2.06, 110.46], [2, 2.04, 8.87]], "batl": NaN}, {"timestamp": 1631531787264, "ltp": 2.28, "tv": 4150.94, "trd": NaN, "batb": [[0, 2.06, 110.46], [1, 2.04, 8.87], [2, 2.02, 8.24]], "batl": NaN}, {"timestamp": 1631531790485, "ltp": 2.28, "tv": 4150.94, "trd": NaN, "batb": [[0, 2.08, 8.31], [1, 2.06, 110.46], [2, 2.04, 8.87]], "batl": [[1, 2.58, 5.44], [2, 2.68, 4.64]]}, {"timestamp": 1631531791680, "ltp": 2.28, "tv": 4150.94, "trd": NaN, "batb": [[0, 2.06, 110.46], [1, 2.04, 8.87], [2, 2.02, 8.24]], "batl": NaN}, {"timestamp": 1631531793721, "ltp": 2.28, "tv": 4150.94, "trd": NaN, "batb": NaN, "batl": [[0, 2.58, 5.44], [1, 2.68, 4.64], [2, 2.82, 234.47]]}, {"timestamp": 1631531794717, "ltp": 2.28, "tv": 4150.94, "trd": NaN, "batb": [[0, 2.38, 16.46], [1, 2.08, 930.16], [2, 2.06, 110.46]], "batl": [[0, 2.56, 410.88], [1, 2.58, 404.24], [2, 2.6, 398.8]]}, {"timestamp": 1631531795608, "ltp": 2.28, "tv": 4150.94, "trd": NaN, "batb": [[0, 2.4, 72.13], [1, 2.38, 16.46], [2, 2.18, 93.14]], "batl": NaN}, {"timestamp": 1631531796696, "ltp": 2.28, "tv": 4150.94, "trd": NaN, "batb": [[2, 2.34, 3]], "batl": NaN}, {"timestamp": 1631531797680, "ltp": 2.28, "tv": 4150.94, "trd": NaN, "batb": [[0, 2.4, 75.13], [1, 2.38, 20.46]], "batl": NaN}, {"timestamp": 1631531800695, "ltp": 2.28, "tv": 4150.94, "trd": NaN, "batb": NaN, "batl": [[0, 2.54, 25.27], [1, 2.56, 410.88], [2, 2.58, 404.24]]}, {"timestamp": 1631531803605, "ltp": 2.28, "tv": 4150.94, "trd": NaN, "batb": [[1, 2.38, 93.35]], "batl": [[0, 2.48, 49.31], [1, 2.54, 25.27], [2, 2.56, 410.88]]}, {"timestamp": 1631531803921, "ltp": 2.28, "tv": 4150.94, "trd": NaN, "batb": [[0, 2.4, 3]], "batl": NaN}, {"timestamp": 1631531809744, "ltp": 2.48, "tv": 4158.1, "trd": [[2.48, 7.19]], "batb": [[1, 2.38, 89.35], [2, 2.18, 93.14]], "batl": [[0, 2.54, 25.27], [1, 2.56, 410.88], [2, 2.58, 404.24]]}, {"timestamp": 1631531813535, "ltp": 2.48, "tv": 4158.1, "trd": NaN, "batb": [[0, 2.4, 74.13], [1, 2.38, 16.46], [2, 2.34, 44.77]], "batl": [[0, 2.54, 73.61]]}, {"timestamp": 1631531823161, "ltp": 2.48, "tv": 4158.1, "trd": NaN, "batb": NaN, "batl": [[0, 2.54, 48.34]]}, {"timestamp": 1631531826437, "ltp": 2.42, "tv": 4161.1, "trd": [[2.42, 4.4]], "batb": [[0, 2.4, 95.56]], "batl": NaN}, {"timestamp": 1631531840336, "ltp": 2.42, "tv": 4165.1, "trd": [[2.42, 8.4]], "batb": NaN, "batl": NaN}, {"timestamp": 1631531855482, "ltp": 2.42, "tv": 4168.1, "trd": [[2.42, 11.4]], "batb": NaN, "batl": NaN}, {"timestamp": 1631531872020, "ltp": 2.42, "tv": 4172.1, "trd": [[2.42, 15.4]], "batb": NaN, "batl": NaN}, {"timestamp": 1631531886932, "ltp": 2.42, "tv": 4176.1, "trd": [[2.42, 19.4]], "batb": NaN, "batl": NaN}, {"timestamp": 1631531891639, "ltp": 2.42, "tv": 4176.1, "trd": NaN, "batb": [[0, 2.4, 74.13]], "batl": NaN}, {"timestamp": 1631531899531, "ltp": 2.42, "tv": 4176.1, "trd": NaN, "batb": [[0, 2.4, 95.56]], "batl": NaN}, {"timestamp": 1631531902760, "ltp": 2.42, "tv": 4180.1, "trd": [[2.42, 23.4]], "batb": NaN, "batl": NaN}, {"timestamp": 1631531906752, "ltp": 2.42, "tv": 4180.1, "trd": NaN, "batb": [[0, 2.34, 44.77], [1, 2.18, 93.39], [2, 2.14, 7.82]], "batl": [[1, 2.6, 5.46], [2, 2.7, 4.75]]}, {"timestamp": 1631531907639, "ltp": 2.42, "tv": 4180.1, "trd": NaN, "batb": [[0, 2.18, 93.39], [1, 2.14, 7.82], [2, 1.82, 406.77]], "batl": [[0, 2.7, 4.75], [1, 3.15, 203.19], [2, 3.45, 53.16]]}, {"timestamp": 1631531909558, "ltp": 2.42, "tv": 4180.1, "trd": NaN, "batb": [[0, 2.2, 6.87], [1, 2.18, 93.39], [2, 2.14, 7.82]], "batl": NaN}, {"timestamp": 1631531910754, "ltp": 2.42, "tv": 4180.1, "trd": NaN, "batb": [[0, 2.2, 3], [1, 2.18, 97.39]], "batl": NaN}, {"timestamp": 1631531911538, "ltp": 2.42, "tv": 4180.1, "trd": NaN, "batb": [[2, 2.16, 4]], "batl": NaN}, {"timestamp": 1631531914759, "ltp": 2.6, "tv": 4184.96, "trd": [[2.6, 22.56]], "batb": [[0, 2.5, 26.44], [1, 2.22, 1542.23], [2, 2.2, 3]], "batl": NaN}, {"timestamp": 1631531915755, "ltp": 2.6, "tv": 4184.96, "trd": NaN, "batb": [[0, 2.56, 59.83], [1, 2.5, 66.44], [2, 2.34, 76.23]], "batl": [[1, 2.78, 44.97], [2, 3.15, 209.54]]}, {"timestamp": 1631531916638, "ltp": 2.6, "tv": 4184.96, "trd": NaN, "batb": [[2, 2.44, 4]], "batl": NaN}, {"timestamp": 1631531917569, "ltp": 2.6, "tv": 4184.96, "trd": NaN, "batb": [[0, 2.6, 3], [1, 2.58, 3], [2, 2.56, 59.83]], "batl": NaN}, {"timestamp": 1631531919650, "ltp": 2.6, "tv": 4184.96, "trd": NaN, "batb": [[1, 2.58, 25.71]], "batl": NaN}, {"timestamp": 1631531921259, "ltp": 2.6, "tv": 4184.96, "trd": NaN, "batb": NaN, "batl": [[2, 2.8, 4.67]]}, {"timestamp": 1631531924687, "ltp": 2.6, "tv": 4184.96, "trd": NaN, "batb": [[1, 2.58, 3]], "batl": [[0, 2.78, 44.97], [1, 2.8, 4.67], [2, 2.9, 4.55]]}, {"timestamp": 1631531925363, "ltp": 2.6, "tv": 4184.96, "trd": NaN, "batb": [[2, 2.54, 41.96]], "batl": [[1, 2.9, 4.55], [2, 3.15, 203.19]]}, {"timestamp": 1631531926661, "ltp": 2.6, "tv": 4184.96, "trd": NaN, "batb": [[0, 2.5, 13.22], [1, 2.34, 76.23], [2, 2.32, 5.64]], "batl": [[0, 2.9, 4.55], [1, 3.15, 203.19], [2, 3.45, 53.16]]}, {"timestamp": 1631531928682, "ltp": 2.6, "tv": 4184.96, "trd": NaN, "batb": NaN, "batl": [[0, 2.8, 4.52], [1, 2.9, 4.55], [2, 3.15, 203.19]]}, {"timestamp": 1631531929728, "ltp": 2.6, "tv": 4184.96, "trd": NaN, "batb": NaN, "batl": [[0, 2.9, 7.55], [1, 3.15, 203.19], [2, 3.45, 53.16]]}, {"timestamp": 1631531930453, "ltp": 2.6, "tv": 4184.96, "trd": NaN, "batb": [[2, 2.32, 18.53]], "batl": NaN}, {"timestamp": 1631531932629, "ltp": 2.6, "tv": 4184.96, "trd": NaN, "batb": NaN, "batl": [[0, 2.8, 7.12], [1, 2.9, 7.55], [2, 3.15, 203.19]]}, {"timestamp": 1631531933669, "ltp": 2.6, "tv": 4184.96, "trd": NaN, "batb": NaN, "batl": [[0, 2.8, 3]]}, {"timestamp": 1631531934756, "ltp": 2.6, "tv": 4184.96, "trd": NaN, "batb": NaN, "batl": [[2, 3.45, 53.16]]}, {"timestamp": 1631531935757, "ltp": 2.5, "tv": 4198.18, "trd": [[2.5, 13.22]], "batb": [[0, 2.34, 76.23], [1, 2.32, 18.53], [2, 2.3, 1663.04]], "batl": [[1, 2.9, 14.45]]}, {"timestamp": 1631531936748, "ltp": 2.5, "tv": 4198.18, "trd": NaN, "batb": [[2, 2.3, 457.34]], "batl": NaN}, {"timestamp": 1631531937634, "ltp": 2.5, "tv": 4198.18, "trd": NaN, "batb": NaN, "batl": [[0, 2.56, 48.03], [1, 2.8, 3], [2, 2.9, 14.45]]}, {"timestamp": 1631531938663, "ltp": 2.5, "tv": 4198.18, "trd": NaN, "batb": [[0, 2.36, 4], [1, 2.34, 79.23], [2, 2.32, 18.53]], "batl": NaN}, {"timestamp": 1631531938978, "ltp": 2.5, "tv": 4198.18, "trd": NaN, "batb": [[0, 2.36, 29.69], [2, 2.32, 63.98]], "batl": NaN}, {"timestamp": 1631531940841, "ltp": 2.5, "tv": 4198.18, "trd": NaN, "batb": NaN, "batl": [[0, 2.54, 25.5], [1, 2.56, 48.03], [2, 2.8, 3]]}, {"timestamp": 1631531942252, "ltp": 2.5, "tv": 4198.18, "trd": NaN, "batb": [[0, 2.38, 4], [1, 2.36, 29.69], [2, 2.34, 79.23]], "batl": NaN}, {"timestamp": 1631531945475, "ltp": 2.5, "tv": 4198.18, "trd": NaN, "batb": NaN, "batl": [[0, 2.8, 3], [1, 2.9, 11.45], [2, 3, 216.4]]}, {"timestamp": 1631531948661, "ltp": 2.5, "tv": 4198.18, "trd": NaN, "batb": NaN, "batl": [[0, 2.52, 48.66], [1, 2.78, 598.33], [2, 2.8, 3]]}, {"timestamp": 1631531949759, "ltp": 2.5, "tv": 4198.18, "trd": NaN, "batb": [[1, 2.36, 4]], "batl": [[1, 2.8, 3], [2, 2.9, 4.55]]}, {"timestamp": 1631531950689, "ltp": 2.5, "tv": 4198.18, "trd": NaN, "batb": [[0, 2.32, 45.45], [1, 2.18, 7.36], [2, 2.14, 7.82]], "batl": [[2, 3, 216.4]]}, {"timestamp": 1631531951470, "ltp": 2.5, "tv": 4198.18, "trd": NaN, "batb": [[0, 2.18, 7.36], [1, 2.14, 7.82], [2, 2.12, 101.42]], "batl": [[0, 2.8, 3], [1, 3, 216.4], [2, 3.45, 53.16]]}, {"timestamp": 1631531955169, "ltp": 2.44, "tv": 4200.5, "trd": [[2.44, 2.32]], "batb": NaN, "batl": NaN}, {"timestamp": 1631531956466, "ltp": 2.44, "tv": 4200.5, "trd": NaN, "batb": NaN, "batl": [[0, 2.5, 409.59], [1, 2.8, 3], [2, 3, 216.4]]}, {"timestamp": 1631531957469, "ltp": 2.44, "tv": 4200.5, "trd": NaN, "batb": NaN, "batl": [[0, 2.8, 3], [1, 3, 216.4], [2, 3.45, 53.16]]}, {"timestamp": 1631531958090, "ltp": 2.44, "tv": 4200.5, "trd": NaN, "batb": [[0, 2.2, 36.8], [1, 2.18, 7.36], [2, 2.14, 7.82]], "batl": [[0, 2.74, 15], [1, 2.8, 3], [2, 3, 216.4]]}, {"timestamp": 1631531963978, "ltp": 2.44, "tv": 4200.5, "trd": NaN, "batb": [[0, 2.18, 7.36], [1, 2.14, 7.82], [2, 2.12, 101.42]], "batl": [[0, 2.8, 3], [1, 3, 216.4], [2, 3.45, 53.16]]}, {"timestamp": 1631531975668, "ltp": 2.44, "tv": 4200.5, "trd": NaN, "batb": [[0, 2.56, 17.08], [1, 2.54, 1505.9], [2, 2.52, 1461.62]], "batl": [[0, 2.78, 1375.9], [1, 2.8, 1338.44], [2, 2.82, 1335.44]]}, {"timestamp": 1631531976685, "ltp": 2.44, "tv": 4200.5, "trd": NaN, "batb": [[1, 2.54, 752.94], [2, 2.52, 730.82]], "batl": [[0, 2.78, 378.37], [1, 2.8, 367.25], [2, 2.82, 367.25]]}, {"timestamp": 1631531977721, "ltp": 2.44, "tv": 4200.5, "trd": NaN, "batb": [[0, 2.56, 77.08], [2, 2.52, 770.29]], "batl": [[0, 2.78, 438.34]]}, {"timestamp": 1631531977987, "ltp": 2.44, "tv": 4200.5, "trd": NaN, "batb": NaN, "batl": [[0, 2.78, 423.34]]}, {"timestamp": 1631531979384, "ltp": 2.44, "tv": 4200.5, "trd": NaN, "batb": [[0, 2.6, 3], [1, 2.58, 4], [2, 2.56, 81.08]], "batl": NaN}, {"timestamp": 1631531980577, "ltp": 2.44, "tv": 4200.5, "trd": NaN, "batb": NaN, "batl": [[0, 2.68, 58.57], [1, 2.78, 423.34], [2, 2.8, 367.25]]}, {"timestamp": 1631531981615, "ltp": 2.44, "tv": 4200.5, "trd": NaN, "batb": [[1, 2.58, 40.8]], "batl": [[0, 2.76, 19.6]]}, {"timestamp": 1631531984533, "ltp": 2.6, "tv": 4203.5, "trd": [[2.6, 25.56]], "batb": [[0, 2.58, 40.8], [1, 2.56, 81.08], [2, 2.54, 791.9]], "batl": NaN}, {"timestamp": 1631531986616, "ltp": 2.58, "tv": 4204.77, "trd": [[2.58, 1.27]], "batb": [[0, 2.58, 39.53]], "batl": NaN}, {"timestamp": 1631531987703, "ltp": 2.58, "tv": 4204.77, "trd": NaN, "batb": [[0, 2.58, 16.38]], "batl": [[0, 2.6, 17.04], [1, 2.76, 19.6], [2, 2.78, 423.34]]}, {"timestamp": 1631531991544, "ltp": 2.58, "tv": 4204.77, "trd": NaN, "batb": [[1, 2.56, 77.08]], "batl": NaN}, {"timestamp": 1631531992740, "ltp": 2.58, "tv": 4207.5, "trd": [[2.58, 4]], "batb": [[0, 2.56, 60], [1, 2.54, 38.96], [2, 2.4, 5.21]], "batl": [[1, 2.78, 44.97], [2, 2.82, 5.25]]}, {"timestamp": 1631531993049, "ltp": 2.58, "tv": 4207.5, "trd": NaN, "batb": [[0, 2.54, 38.96], [1, 2.4, 5.21], [2, 2.32, 85.13]], "batl": NaN}, {"timestamp": 1631531994719, "ltp": 2.6, "tv": 4213.5, "trd": [[2.6, 31.56]], "batb": [[0, 2.32, 85.13], [1, 1.82, 406.77], [2, 1.8, 11.88]], "batl": [[0, 2.6, 14.04], [1, 2.98, 5.25], [2, 3, 216.4]]}, {"timestamp": 1631531995708, "ltp": 2.6, "tv": 4213.5, "trd": NaN, "batb": [[0, 2.58, 3], [1, 2.32, 85.13], [2, 1.82, 406.77]], "batl": [[0, 2.98, 5.25], [1, 3, 216.4], [2, 3.45, 53.16]]}, {"timestamp": 1631531996743, "ltp": 2.6, "tv": 4213.5, "trd": NaN, "batb": [[0, 2.32, 85.13], [1, 1.82, 406.77], [2, 1.8, 11.88]], "batl": NaN}, {"timestamp": 1631531998617, "ltp": 2.6, "tv": 4213.5, "trd": NaN, "batb": [[0, 2.32, 89.13], [1, 2.3, 3], [2, 1.82, 406.77]], "batl": [[0, 2.94, 4], [1, 2.98, 5.25], [2, 3, 216.4]]}, {"timestamp": 1631532001742, "ltp": 2.6, "tv": 4213.5, "trd": NaN, "batb": [[0, 2.4, 5.81], [1, 2.32, 89.13], [2, 2.3, 3]], "batl": [[0, 2.82, 4.75], [1, 2.94, 4], [2, 2.98, 5.25]]}, {"timestamp": 1631532002526, "ltp": 2.6, "tv": 4213.5, "trd": NaN, "batb": [[0, 2.32, 89.13], [1, 2.3, 3], [2, 1.82, 406.77]], "batl": [[0, 2.94, 4], [1, 2.98, 5.25], [2, 3, 216.4]]}, {"timestamp": 1631532003679, "ltp": 2.6, "tv": 4213.5, "trd": NaN, "batb": NaN, "batl": [[0, 2.46, 777.44], [1, 2.48, 754.56], [2, 2.5, 754.56]]}, {"timestamp": 1631532004727, "ltp": 2.6, "tv": 4213.5, "trd": NaN, "batb": [[0, 2.32, 111.75], [1, 2.3, 49.15], [2, 2.04, 112.72]], "batl": NaN}, {"timestamp": 1631532005037, "ltp": 2.6, "tv": 4213.5, "trd": NaN, "batb": [[0, 2.32, 89.13]], "batl": NaN}, {"timestamp": 1631532006248, "ltp": 2.6, "tv": 4213.5, "trd": NaN, "batb": [[0, 2.34, 4], [1, 2.32, 89.13], [2, 2.3, 49.15]], "batl": NaN}, {"timestamp": 1631532008640, "ltp": 2.6, "tv": 4213.5, "trd": NaN, "batb": NaN, "batl": [[0, 2.46, 798.97]]}, {"timestamp": 1631532009733, "ltp": 2.6, "tv": 4213.5, "trd": NaN, "batb": [[0, 2.36, 3], [1, 2.34, 4], [2, 2.32, 85.13]], "batl": NaN}, {"timestamp": 1631532010557, "ltp": 2.6, "tv": 4213.5, "trd": NaN, "batb": NaN, "batl": [[2, 2.5, 803.54]]}, {"timestamp": 1631532011653, "ltp": 2.36, "tv": 4216.5, "trd": [[2.36, 88.83]], "batb": [[0, 2.34, 4], [1, 2.32, 85.13], [2, 2.3, 46.15]], "batl": NaN}, {"timestamp": 1631532021633, "ltp": 2.34, "tv": 4220.5, "trd": [[2.34, 36.36]], "batb": [[0, 2.32, 85.13], [1, 2.3, 46.15], [2, 2.08, 8.56]], "batl": NaN}, {"timestamp": 1631532023351, "ltp": 2.34, "tv": 4220.5, "trd": NaN, "batb": [[0, 2.3, 46.15], [1, 2.08, 8.56], [2, 2.06, 9.58]], "batl": [[0, 2.5, 48.98], [1, 2.68, 5.14], [2, 2.86, 4.25]]}, {"timestamp": 1631532024752, "ltp": 2.34, "tv": 4220.5, "trd": NaN, "batb": [[0, 2.04, 112.72], [1, 1.99, 23.51], [2, 1.97, 26.17]], "batl": [[0, 2.68, 5.14], [1, 2.86, 4.25], [2, 2.9, 4.55]]}, {"timestamp": 1631532025536, "ltp": 2.34, "tv": 4220.5, "trd": NaN, "batb": NaN, "batl": [[0, 2.6, 17.04], [1, 2.68, 5.14], [2, 2.86, 4.25]]}, {"timestamp": 1631532026572, "ltp": 2.34, "tv": 4220.5, "trd": NaN, "batb": [[0, 2.3, 3], [1, 2.04, 112.72], [2, 1.99, 23.51]], "batl": NaN}, {"timestamp": 1631532027247, "ltp": 2.34, "tv": 4220.5, "trd": NaN, "batb": [[0, 2.04, 112.72], [1, 1.99, 23.51], [2, 1.97, 26.17]], "batl": NaN}, {"timestamp": 1631532027970, "ltp": 2.34, "tv": 4220.5, "trd": NaN, "batb": [[0, 2.08, 7.81], [1, 2.04, 112.72], [2, 1.99, 23.51]], "batl": NaN}, {"timestamp": 1631532029075, "ltp": 2.34, "tv": 4220.5, "trd": NaN, "batb": [[0, 2.04, 112.72], [1, 1.99, 23.51], [2, 1.97, 26.17]], "batl": NaN}, {"timestamp": 1631532041002, "ltp": 2.34, "tv": 4220.5, "trd": NaN, "batb": NaN, "batl": [[0, 2.68, 5.14], [1, 2.86, 4.25], [2, 2.9, 4.55]]}, {"timestamp": 1631532048509, "ltp": 2.34, "tv": 4220.5, "trd": NaN, "batb": NaN, "batl": [[0, 2.54, 7.87], [1, 2.68, 5.14], [2, 2.86, 4.25]]}, {"timestamp": 1631532050706, "ltp": 2.34, "tv": 4220.5, "trd": NaN, "batb": [[0, 2.08, 4], [1, 2.06, 4], [2, 2.04, 196.98]], "batl": [[0, 2.26, 53.45], [1, 2.38, 3], [2, 2.54, 7.87]]}, {"timestamp": 1631532051700, "ltp": 2.34, "tv": 4220.5, "trd": NaN, "batb": [[2, 2.04, 200.98]], "batl": NaN}, {"timestamp": 1631532053692, "ltp": 2.34, "tv": 4220.5, "trd": NaN, "batb": NaN, "batl": [[0, 2.38, 3], [1, 2.54, 7.87], [2, 2.68, 5.14]]}, {"timestamp": 1631532055627, "ltp": 2.34, "tv": 4220.5, "trd": NaN, "batb": [[2, 2.04, 143.29]], "batl": [[0, 2.26, 91.72], [1, 2.38, 3], [2, 2.44, 5.58]]}, {"timestamp": 1631532057711, "ltp": 2.34, "tv": 4220.5, "trd": NaN, "batb": NaN, "batl": [[0, 2.24, 53.88], [1, 2.26, 91.72], [2, 2.38, 3]]}, {"timestamp": 1631532059222, "ltp": 2.34, "tv": 4220.5, "trd": NaN, "batb": [[1, 2.06, 60.6]], "batl": NaN}, {"timestamp": 1631532060587, "ltp": 2.34, "tv": 4220.5, "trd": NaN, "batb": NaN, "batl": [[0, 2.22, 54.44], [1, 2.24, 53.88], [2, 2.26, 91.72]]}, {"timestamp": 1631532065715, "ltp": 2.06, "tv": 4370.28, "trd": [[2.06, 141.78], [2.08, 8]], "batb": [[0, 2.04, 139.29], [1, 1.99, 23.51], [2, 1.97, 26.17]], "batl": [[1, 2.38, 3], [2, 2.44, 5.58]]}, {"timestamp": 1631532066229, "ltp": 2.06, "tv": 4370.28, "trd": NaN, "batb": NaN, "batl": [[0, 2.38, 3], [1, 2.44, 5.58], [2, 2.54, 7.87]]}, {"timestamp": 1631532068748, "ltp": 2.06, "tv": 4370.28, "trd": NaN, "batb": [[0, 2.08, 4], [1, 2.06, 3], [2, 2.04, 139.29]], "batl": NaN}, {"timestamp": 1631532069308, "ltp": 2.06, "tv": 4370.28, "trd": NaN, "batb": [[0, 2.06, 3], [1, 2.04, 143.29], [2, 2.02, 58.82]], "batl": [[0, 2.22, 54.32], [1, 2.38, 3], [2, 2.44, 5.58]]}, {"timestamp": 1631532071442, "ltp": 2.06, "tv": 4370.28, "trd": NaN, "batb": [[1, 2.04, 4]], "batl": NaN}, {"timestamp": 1631532072740, "ltp": 2.06, "tv": 4370.28, "trd": NaN, "batb": [[0, 1.81, 82.93], [1, 1.78, 2.32], [2, 1.76, 2.32]], "batl": [[0, 2.44, 5.58], [1, 2.68, 5.14], [2, 2.7, 5.05]]}, {"timestamp": 1631532074717, "ltp": 2.06, "tv": 4370.28, "trd": NaN, "batb": [[2, 1.77, 33.37]], "batl": NaN}, {"timestamp": 1631532077636, "ltp": 2.06, "tv": 4370.28, "trd": NaN, "batb": NaN, "batl": [[0, 2.16, 469.36], [1, 2.44, 5.58], [2, 2.68, 5.14]]}, {"timestamp": 1631532078722, "ltp": 2.06, "tv": 4370.28, "trd": NaN, "batb": NaN, "batl": [[0, 2.44, 5.58], [1, 2.68, 5.14], [2, 2.7, 5.05]]}, {"timestamp": 1631532079449, "ltp": 2.06, "tv": 4370.28, "trd": NaN, "batb": [[0, 1.83, 125.9], [1, 1.81, 82.93], [2, 1.78, 2.32]], "batl": [[0, 2.32, 27.9], [1, 2.44, 5.58], [2, 2.68, 5.14]]}, {"timestamp": 1631532081742, "ltp": 2.06, "tv": 4370.28, "trd": NaN, "batb": [[0, 1.81, 82.93], [1, 1.78, 2.32], [2, 1.77, 33.37]], "batl": [[0, 2.44, 5.58], [1, 2.68, 5.14], [2, 2.7, 5.05]]}, {"timestamp": 1631532100563, "ltp": 2.06, "tv": 4370.28, "trd": NaN, "batb": [[2, 1.76, 2.32]], "batl": NaN}, {"timestamp": 1631532102586, "ltp": 2.06, "tv": 4370.28, "trd": NaN, "batb": [[0, 2.28, 4.16], [1, 1.81, 82.93], [2, 1.78, 2.32]], "batl": NaN}, {"timestamp": 1631532103681, "ltp": 2.06, "tv": 4370.28, "trd": NaN, "batb": [[0, 2.3, 79.91], [1, 2.28, 4.16], [2, 2.04, 113.97]], "batl": NaN}, {"timestamp": 1631532104757, "ltp": 2.06, "tv": 4370.28, "trd": NaN, "batb": [[2, 2.22, 49.18]], "batl": [[0, 2.44, 55.58]]}, {"timestamp": 1631532106572, "ltp": 2.06, "tv": 4370.28, "trd": NaN, "batb": [[1, 2.28, 695.2]], "batl": NaN}, {"timestamp": 1631532107765, "ltp": 2.06, "tv": 4370.28, "trd": NaN, "batb": [[0, 2.3, 100.71], [1, 2.28, 4.16]], "batl": NaN}, {"timestamp": 1631532108554, "ltp": 2.06, "tv": 4370.28, "trd": NaN, "batb": [[2, 2.04, 116.97]], "batl": NaN}, {"timestamp": 1631532109277, "ltp": 2.06, "tv": 4370.28, "trd": NaN, "batb": [[2, 2.06, 7.58]], "batl": [[1, 2.62, 5.75], [2, 2.68, 5.14]]}, {"timestamp": 1631532111675, "ltp": 2.06, "tv": 4370.28, "trd": NaN, "batb": [[2, 2.24, 48.38]], "batl": NaN}, {"timestamp": 1631532122274, "ltp": 2.06, "tv": 4370.28, "trd": NaN, "batb": [[0, 2.32, 4], [1, 2.3, 103.71], [2, 2.28, 4.16]], "batl": NaN}, {"timestamp": 1631532124575, "ltp": 2.06, "tv": 4370.28, "trd": NaN, "batb": [[0, 2.24, 48.38], [1, 2.04, 116.97], [2, 1.97, 25.17]], "batl": [[0, 2.44, 50]]}, {"timestamp": 1631532125718, "ltp": 2.06, "tv": 4370.28, "trd": NaN, "batb": [[0, 2.04, 116.97], [1, 1.97, 25.17], [2, 1.95, 26.91]], "batl": [[0, 2.62, 5.75], [1, 2.68, 5.14], [2, 2.7, 5.05]]}, {"timestamp": 1631532129696, "ltp": 2.06, "tv": 4370.28, "trd": NaN, "batb": [[1, 2.02, 4], [2, 1.97, 25.17]], "batl": NaN}, {"timestamp": 1631532131720, "ltp": 2.06, "tv": 4370.28, "trd": NaN, "batb": [[0, 2.56, 3.83], [1, 2.52, 1517.86], [2, 2.5, 1473.22]], "batl": NaN}, {"timestamp": 1631532132715, "ltp": 2.06, "tv": 4370.28, "trd": NaN, "batb": [[0, 2.56, 63.75], [1, 2.52, 758.94], [2, 2.5, 736.6]], "batl": [[0, 2.7, 5.05], [1, 2.74, 383.89], [2, 2.76, 377.62]]}, {"timestamp": 1631532133390, "ltp": 2.06, "tv": 4370.28, "trd": NaN, "batb": NaN, "batl": [[1, 2.74, 429.37]]}, {"timestamp": 1631532134690, "ltp": 2.6, "tv": 4373.28, "trd": [[2.6, 34.56]], "batb": [[0, 2.58, 3], [1, 2.56, 63.75], [2, 2.52, 758.94]], "batl": NaN}, {"timestamp": 1631532136719, "ltp": 2.6, "tv": 4373.28, "trd": NaN, "batb": [[1, 2.56, 166.04]], "batl": NaN}, {"timestamp": 1631532145722, "ltp": 2.6, "tv": 4373.28, "trd": NaN, "batb": [[1, 2.56, 59.92], [2, 2.5, 40]], "batl": [[0, 2.74, 45.48], [1, 2.82, 4.25], [2, 2.86, 4.25]]}, {"timestamp": 1631532146612, "ltp": 2.6, "tv": 4373.28, "trd": NaN, "batb": [[0, 2.5, 40], [1, 2.36, 21.11], [2, 2.3, 81.42]], "batl": NaN}, {"timestamp": 1631532147706, "ltp": 2.6, "tv": 4373.28, "trd": NaN, "batb": [[0, 2.36, 21.11], [1, 2.3, 81.42], [2, 2.28, 21.82]], "batl": [[0, 2.94, 5.25], [1, 2.98, 5.25], [2, 3.3, 194.57]]}, {"timestamp": 1631532148695, "ltp": 2.66, "tv": 4373.73, "trd": [[2.66, 0.45]], "batb": [[0, 2.6, 3], [1, 2.36, 21.11], [2, 2.3, 81.42]], "batl": NaN}, {"timestamp": 1631532149624, "ltp": 2.66, "tv": 4373.73, "trd": NaN, "batb": [[0, 2.36, 21.11], [1, 2.3, 81.42], [2, 2.28, 21.82]], "batl": NaN}, {"timestamp": 1631532150612, "ltp": 2.66, "tv": 4378.34, "trd": [[2.66, 5.07]], "batb": NaN, "batl": [[0, 2.58, 12.42], [1, 2.82, 4], [2, 2.94, 5.25]]}, {"timestamp": 1631532151128, "ltp": 2.66, "tv": 4378.34, "trd": NaN, "batb": NaN, "batl": [[1, 2.82, 9.25], [2, 2.94, 8.25]]}, {"timestamp": 1631532155203, "ltp": 2.66, "tv": 4378.34, "trd": NaN, "batb": [[0, 2.3, 81.42], [1, 2.28, 21.82], [2, 2.26, 21.46]], "batl": NaN}, {"timestamp": 1631532156712, "ltp": 2.66, "tv": 4378.34, "trd": NaN, "batb": NaN, "batl": [[0, 2.82, 9.25], [1, 2.94, 8.25], [2, 2.98, 5.25]]}, {"timestamp": 1631532157703, "ltp": 2.66, "tv": 4378.34, "trd": NaN, "batb": NaN, "batl": [[0, 2.4, 796.88], [1, 2.42, 773.44], [2, 2.44, 773.44]]}, {"timestamp": 1631532160630, "ltp": 2.66, "tv": 4378.34, "trd": NaN, "batb": [[0, 2.32, 4], [1, 2.3, 85.42], [2, 2.28, 21.82]], "batl": NaN}, {"timestamp": 1631532162501, "ltp": 2.66, "tv": 4378.34, "trd": NaN, "batb": NaN, "batl": [[2, 2.44, 823.44]]}, {"timestamp": 1631532167435, "ltp": 2.32, "tv": 4381.28, "trd": [[2.32, 2.94]], "batb": [[0, 2.32, 2.53]], "batl": NaN}, {"timestamp": 1631532174233, "ltp": 2.32, "tv": 4381.28, "trd": NaN, "batb": [[1, 2.3, 81.42]], "batl": NaN}, {"timestamp": 1631532176615, "ltp": 2.32, "tv": 4381.28, "trd": NaN, "batb": [[1, 2.28, 15.16], [2, 2.26, 14.48]], "batl": [[0, 2.44, 50], [1, 2.58, 5.94], [2, 2.7, 5.35]]}, {"timestamp": 1631532177757, "ltp": 2.32, "tv": 4381.28, "trd": NaN, "batb": [[0, 2.04, 7.62], [1, 2.02, 116.48], [2, 1.97, 25.17]], "batl": [[0, 2.58, 5.94], [1, 2.7, 5.35], [2, 2.82, 9.25]]}, {"timestamp": 1631532191358, "ltp": 2.32, "tv": 4381.28, "trd": NaN, "batb": NaN, "batl": [[0, 2.7, 5.35], [1, 2.82, 9.25], [2, 2.94, 5.25]]}, {"timestamp": 1631532193739, "ltp": 2.32, "tv": 4381.28, "trd": NaN, "batb": [[0, 2.52, 1519.86], [1, 2.5, 1473.22], [2, 2.48, 1473.22]], "batl": [[1, 2.74, 1395.98], [2, 2.76, 1354.92]]}, {"timestamp": 1631532194724, "ltp": 2.32, "tv": 4381.28, "trd": NaN, "batb": [[0, 2.54, 61.84], [1, 2.52, 760.94], [2, 2.5, 736.6]], "batl": [[0, 2.68, 3], [1, 2.7, 5.35], [2, 2.74, 383.89]]}, {"timestamp": 1631532195764, "ltp": 2.32, "tv": 4381.28, "trd": NaN, "batb": NaN, "batl": [[0, 2.7, 5.35], [1, 2.72, 45.74]]}, {"timestamp": 1631532197368, "ltp": 2.32, "tv": 4381.28, "trd": NaN, "batb": [[0, 2.6, 3], [1, 2.58, 3], [2, 2.54, 61.84]], "batl": NaN}, {"timestamp": 1631532198567, "ltp": 2.32, "tv": 4381.28, "trd": NaN, "batb": NaN, "batl": [[0, 2.68, 59.81], [1, 2.7, 5.35], [2, 2.72, 45.74]]}, {"timestamp": 1631532199028, "ltp": 2.32, "tv": 4381.28, "trd": NaN, "batb": [[2, 2.54, 99.94]], "batl": [[0, 2.7, 5.35], [1, 2.72, 45.74], [2, 2.74, 383.89]]}, {"timestamp": 1631532204279, "ltp": 2.6, "tv": 4381.78, "trd": [[2.6, 35.06]], "batb": [[0, 2.6, 2.5]], "batl": NaN}, {"timestamp": 1631532205582, "ltp": 2.6, "tv": 4386.79, "trd": [[2.6, 40.07]], "batb": [[0, 2.58, 3], [1, 2.54, 99.94], [2, 2.52, 760.94]], "batl": [[0, 2.6, 14.53], [1, 2.7, 5.35], [2, 2.72, 45.74]]}, {"timestamp": 1631532207767, "ltp": 2.6, "tv": 4386.79, "trd": NaN, "batb": [[2, 2.52, 2]], "batl": NaN}, {"timestamp": 1631532208755, "ltp": 2.6, "tv": 4386.79, "trd": NaN, "batb": [[0, 2.5, 40], [1, 2.36, 6.18], [2, 2.28, 88.75]], "batl": [[1, 2.72, 45.74], [2, 2.8, 4.72]]}, {"timestamp": 1631532209485, "ltp": 2.6, "tv": 4386.79, "trd": NaN, "batb": [[0, 2.28, 88.75], [1, 2.26, 6.48], [2, 2.04, 7.62]], "batl": [[1, 2.82, 5.25], [2, 2.94, 5.25]]}, {"timestamp": 1631532210581, "ltp": 2.6, "tv": 4386.79, "trd": NaN, "batb": NaN, "batl": [[0, 2.6, 4.56]]}, {"timestamp": 1631532212557, "ltp": 2.6, "tv": 4386.79, "trd": NaN, "batb": [[0, 2.36, 6.18], [1, 2.28, 88.75], [2, 2.26, 6.48]], "batl": NaN}, {"timestamp": 1631532212870, "ltp": 2.6, "tv": 4386.79, "trd": NaN, "batb": [[0, 2.28, 88.75], [1, 2.26, 6.48], [2, 2.04, 7.62]], "batl": NaN}, {"timestamp": 1631532214696, "ltp": 2.6, "tv": 4386.79, "trd": NaN, "batb": NaN, "batl": [[1, 2.64, 19.43], [2, 2.82, 5.25]]}, {"timestamp": 1631532215478, "ltp": 2.6, "tv": 4386.79, "trd": NaN, "batb": NaN, "batl": [[1, 2.82, 5.25], [2, 2.94, 5.25]]}, {"timestamp": 1631532216575, "ltp": 2.6, "tv": 4386.79, "trd": NaN, "batb": [[0, 2.36, 5.43], [1, 2.3, 85.22], [2, 2.28, 88.75]], "batl": NaN}, {"timestamp": 1631532216879, "ltp": 2.6, "tv": 4386.79, "trd": NaN, "batb": [[1, 2.28, 88.75], [2, 2.26, 6.48]], "batl": NaN}, {"timestamp": 1631532224686, "ltp": 2.6, "tv": 4386.79, "trd": NaN, "batb": [[0, 2.28, 88.75], [1, 2.26, 6.48], [2, 2.04, 7.62]], "batl": [[0, 2.82, 5.25], [1, 2.94, 5.25], [2, 2.98, 5.25]]}, {"timestamp": 1631532230619, "ltp": 2.6, "tv": 4386.79, "trd": NaN, "batb": [[0, 2.36, 6.43], [1, 2.28, 88.75], [2, 2.26, 6.48]], "batl": NaN}, {"timestamp": 1631532230993, "ltp": 2.6, "tv": 4386.79, "trd": NaN, "batb": [[0, 2.28, 88.75], [1, 2.26, 6.48], [2, 2.04, 7.62]], "batl": NaN}, {"timestamp": 1631532232712, "ltp": 2.52, "tv": 4388.68, "trd": [[2.52, 45.39]], "batb": NaN, "batl": [[0, 2.52, 2.37], [1, 2.82, 5.25], [2, 2.94, 5.25]]}, {"timestamp": 1631532237614, "ltp": 2.52, "tv": 4388.68, "trd": NaN, "batb": [[0, 2.36, 6.68], [1, 2.28, 88.75], [2, 2.26, 6.48]], "batl": [[0, 2.82, 5.25], [1, 2.94, 5.25], [2, 2.98, 5.25]]}, {"timestamp": 1631532238504, "ltp": 2.52, "tv": 4388.68, "trd": NaN, "batb": [[0, 2.28, 88.75], [1, 2.26, 6.48], [2, 2.04, 7.62]], "batl": NaN}, {"timestamp": 1631532239713, "ltp": 2.52, "tv": 4388.68, "trd": NaN, "batb": [[2, 2.22, 473.81]], "batl": [[0, 2.4, 799.57], [1, 2.42, 773.44], [2, 2.44, 773.44]]}, {"timestamp": 1631532240707, "ltp": 2.52, "tv": 4388.68, "trd": NaN, "batb": [[2, 2.22, 522.99]], "batl": [[2, 2.44, 823.44]]}, {"timestamp": 1631532241903, "ltp": 2.38, "tv": 4390.68, "trd": [[2.38, 2]], "batb": NaN, "batl": NaN}, {"timestamp": 1631532244626, "ltp": 2.38, "tv": 4390.68, "trd": NaN, "batb": NaN, "batl": [[2, 2.44, 773.44]]}, {"timestamp": 1631532248535, "ltp": 2.38, "tv": 4390.68, "trd": NaN, "batb": NaN, "batl": [[1, 2.42, 823.79]]}, {"timestamp": 1631532252436, "ltp": 2.38, "tv": 4390.68, "trd": NaN, "batb": [[0, 2.22, 49.18], [1, 2.04, 7.62], [2, 2.02, 118.66]], "batl": [[0, 2.42, 50.35], [1, 2.6, 5.81], [2, 2.62, 5.25]]}, {"timestamp": 1631532253633, "ltp": 2.38, "tv": 4390.68, "trd": NaN, "batb": [[0, 2.04, 7.62], [1, 2.02, 118.66], [2, 1.97, 25.17]], "batl": [[0, 2.6, 5.81], [1, 2.62, 5.25], [2, 2.76, 4.77]]}, {"timestamp": 1631532261761, "ltp": 2.12, "tv": 4399.35, "trd": [[2.12, 19.37], [2.14, 4.3]], "batb": [[2, 1.98, 1931.82]], "batl": [[0, 2.12, 2826.15], [1, 2.52, 7.94], [2, 2.6, 5.81]]}, {"timestamp": 1631532262753, "ltp": 2.12, "tv": 4399.35, "trd": NaN, "batb": [[0, 2.02, 118.66], [1, 1.98, 531.26], [2, 1.97, 540.8]], "batl": [[0, 2.12, 3.21]]}, {"timestamp": 1631532263367, "ltp": 2.12, "tv": 4399.35, "trd": NaN, "batb": [[1, 2, 60], [2, 1.98, 531.26]], "batl": [[1, 2.18, 55.23], [2, 2.34, 29.05]]}, {"timestamp": 1631532263944, "ltp": 2.12, "tv": 4399.35, "trd": NaN, "batb": NaN, "batl": [[2, 2.36, 4]]}, {"timestamp": 1631532266749, "ltp": 2.12, "tv": 4399.35, "trd": NaN, "batb": NaN, "batl": [[1, 2.14, 81.33], [2, 2.18, 55.23]]}, {"timestamp": 1631532267262, "ltp": 2.12, "tv": 4399.35, "trd": NaN, "batb": NaN, "batl": [[0, 2.12, 32.26], [1, 2.36, 4], [2, 2.52, 7.94]]}, {"timestamp": 1631532269078, "ltp": 2.12, "tv": 4399.35, "trd": NaN, "batb": NaN, "batl": [[1, 2.34, 5.75], [2, 2.36, 4]]}, {"timestamp": 1631532270476, "ltp": 2.12, "tv": 4399.35, "trd": NaN, "batb": NaN, "batl": [[1, 2.16, 55.7], [2, 2.34, 5.75]]}, {"timestamp": 1631532271269, "ltp": 2.12, "tv": 4399.35, "trd": NaN, "batb": [[2, 1.99, 12.73]], "batl": NaN}, {"timestamp": 1631532275685, "ltp": 2.12, "tv": 4399.35, "trd": NaN, "batb": NaN, "batl": [[0, 2.12, 3.21]]}, {"timestamp": 1631532283207, "ltp": 2.12, "tv": 4399.35, "trd": NaN, "batb": [[0, 2, 60], [1, 1.99, 12.73], [2, 1.78, 89.6]], "batl": [[0, 2.16, 55.7], [1, 2.34, 5.75], [2, 2.36, 4]]}, {"timestamp": 1631532284664, "ltp": 2.12, "tv": 4399.35, "trd": NaN, "batb": [[0, 1.99, 12.73], [1, 1.78, 89.6], [2, 1.77, 34.37]], "batl": [[0, 2.36, 4], [1, 2.52, 6.01], [2, 2.82, 234.47]]}, {"timestamp": 1631532287870, "ltp": 2.12, "tv": 4399.35, "trd": NaN, "batb": NaN, "batl": [[0, 2.34, 6.25], [1, 2.36, 4], [2, 2.52, 6.01]]}, {"timestamp": 1631532289477, "ltp": 2.12, "tv": 4399.35, "trd": NaN, "batb": [[0, 1.78, 89.6], [1, 1.77, 34.37], [2, 1.76, 2.32]], "batl": NaN}, {"timestamp": 1631532289780, "ltp": 2.12, "tv": 4399.35, "trd": NaN, "batb": [[1, 1.76, 2.32], [2, 1.7, 414.97]], "batl": [[0, 2.36, 4], [1, 2.82, 234.47], [2, 3.45, 53.16]]}, {"timestamp": 1631532291175, "ltp": 2.12, "tv": 4399.35, "trd": NaN, "batb": [[2, 1.68, 42.11]], "batl": [[1, 3.45, 53.16], [2, 3.45, 0]]}, {"timestamp": 1631532292609, "ltp": 1.85, "tv": 4402.06, "trd": [[1.85, 105.91]], "batb": [[0, 1.78, 300.19], [1, 1.76, 208.35]], "batl": [[0, 1.85, 185.83], [1, 1.87, 423.13], [2, 1.88, 125.66]]}, {"timestamp": 1631532293578, "ltp": 1.85, "tv": 4414.19, "trd": [[1.85, 118.04]], "batb": [[0, 1.81, 66.66], [1, 1.78, 254.63], [2, 1.77, 82.51]], "batl": [[0, 1.85, 173.7]]}, {"timestamp": 1631532294707, "ltp": 1.85, "tv": 4414.19, "trd": NaN, "batb": [[1, 1.78, 284.84]], "batl": NaN}, {"timestamp": 1631532296513, "ltp": 1.85, "tv": 4414.19, "trd": NaN, "batb": [[0, 1.83, 8.61], [1, 1.82, 17.33], [2, 1.81, 92.79]], "batl": [[0, 1.84, 66.64], [1, 1.85, 173.7], [2, 1.87, 423.13]]}, {"timestamp": 1631532301705, "ltp": 1.84, "tv": 4418.84, "trd": [[1.84, 27.05]], "batb": [[0, 1.83, 94.76], [1, 1.82, 65.12], [2, 1.81, 66.66]], "batl": [[0, 1.84, 64.31]]}, {"timestamp": 1631532305115, "ltp": 1.84, "tv": 4418.84, "trd": NaN, "batb": NaN, "batl": [[0, 1.84, 173.31]]}, {"timestamp": 1631532313604, "ltp": 1.84, "tv": 4418.84, "trd": NaN, "batb": [[0, 1.81, 66.66], [1, 1.78, 1749.58], [2, 1.76, 2.32]], "batl": [[0, 1.84, 109], [1, 1.88, 13.14], [2, 1.96, 29.87]]}, {"timestamp": 1631532314531, "ltp": 1.84, "tv": 4418.84, "trd": NaN, "batb": [[0, 1.78, 1749.58], [1, 1.76, 2.32], [2, 1.74, 34.52]], "batl": [[0, 1.88, 13.14], [1, 2.02, 9.25], [2, 2.18, 4]]}, {"timestamp": 1631532315321, "ltp": 1.84, "tv": 4418.84, "trd": NaN, "batb": [[0, 1.78, 2.32], [2, 1.69, 53.4]], "batl": NaN}, {"timestamp": 1631532316737, "ltp": 1.84, "tv": 4418.84, "trd": NaN, "batb": [[2, 1.69, 253.18]], "batl": [[1, 1.97, 106.26], [2, 1.99, 141.84]]}, {"timestamp": 1631532317722, "ltp": 1.84, "tv": 4418.84, "trd": NaN, "batb": NaN, "batl": [[1, 1.96, 28.37], [2, 1.97, 106.26]]}, {"timestamp": 1631532318646, "ltp": 1.84, "tv": 4418.84, "trd": NaN, "batb": [[2, 1.74, 33.52]], "batl": [[1, 1.97, 106.26], [2, 1.99, 141.84]]}, {"timestamp": 1631532318915, "ltp": 1.84, "tv": 4418.84, "trd": NaN, "batb": [[2, 1.69, 253.18]], "batl": NaN}, {"timestamp": 1631532323223, "ltp": 1.84, "tv": 4418.84, "trd": NaN, "batb": [[2, 1.69, 239.99]], "batl": [[1, 2.02, 9.25], [2, 2.18, 4]]}, {"timestamp": 1631532326738, "ltp": 1.76, "tv": 4439.4, "trd": [[1.76, 4.64], [1.78, 17.51], [1.88, 11.28]], "batb": [[0, 1.69, 239.99], [1, 1.68, 105.52], [2, 1.67, 247.22]], "batl": [[0, 1.75, 211.04], [1, 1.76, 1086.64], [2, 1.77, 1270.53]]}, {"timestamp": 1631532327556, "ltp": 1.76, "tv": 4439.4, "trd": NaN, "batb": [[0, 1.71, 71.2], [1, 1.69, 239.99], [2, 1.68, 105.52]], "batl": NaN}, {"timestamp": 1631532330339, "ltp": 1.76, "tv": 4439.4, "trd": NaN, "batb": [[0, 1.73, 17.64], [1, 1.72, 35.49], [2, 1.71, 124.75]], "batl": [[0, 1.74, 66.69], [1, 1.75, 211.04], [2, 1.76, 1086.64]]}, {"timestamp": 1631532331659, "ltp": 1.75, "tv": 4602.66, "trd": [[1.74, 378], [1.75, 97.2]], "batb": NaN, "batl": [[0, 1.75, 196.1], [1, 1.76, 1086.64], [2, 1.77, 1270.53]]}, {"timestamp": 1631532333409, "ltp": 1.71, "tv": 4713.04, "trd": [[1.71, 4.1], [1.72, 70.99], [1.73, 607.52]], "batb": [[0, 1.71, 122.7], [1, 1.7, 71.18], [2, 1.69, 239.99]], "batl": NaN}, {"timestamp": 1631532335695, "ltp": 1.71, "tv": 4713.04, "trd": NaN, "batb": [[0, 1.73, 172.93], [1, 1.72, 76.58], [2, 1.71, 69.15]], "batl": [[0, 1.74, 75.9], [1, 1.75, 196.1], [2, 1.76, 1086.64]]}, {"timestamp": 1631532336627, "ltp": 1.71, "tv": 4713.04, "trd": NaN, "batb": [[2, 1.71, 71.2]], "batl": NaN}, {"timestamp": 1631532337046, "ltp": 1.73, "tv": 4854.21, "trd": [[1.73, 748.7]], "batb": [[0, 1.73, 102.34]], "batl": NaN}, {"timestamp": 1631532338703, "ltp": 1.73, "tv": 4863.97, "trd": [[1.73, 758.46]], "batb": [[0, 1.73, 97.46]], "batl": NaN}, {"timestamp": 1631532339731, "ltp": 1.74, "tv": 4898.01, "trd": [[1.74, 412.04]], "batb": NaN, "batl": [[0, 1.74, 268.88]]}, {"timestamp": 1631532342622, "ltp": 1.74, "tv": 4898.01, "trd": NaN, "batb": [[0, 1.71, 71.2], [1, 1.68, 9.97], [2, 1.66, 41.28]], "batl": [[0, 1.74, 210], [1, 1.81, 32.71], [2, 1.82, 32.25]]}, {"timestamp": 1631532343607, "ltp": 1.74, "tv": 4898.01, "trd": NaN, "batb": [[0, 1.68, 9.97], [1, 1.62, 38.04], [2, 1.61, 125.1]], "batl": [[0, 1.73, 24.59]]}, {"timestamp": 1631532345732, "ltp": 1.68, "tv": 4910.79, "trd": [[1.68, 639.16]], "batb": [[0, 1.68, 3.59], [2, 1.61, 363.68]], "batl": NaN}, {"timestamp": 1631532348121, "ltp": 1.73, "tv": 4929.48, "trd": [[1.73, 777.15]], "batb": NaN, "batl": [[0, 1.73, 15.25]]}, {"timestamp": 1631532350913, "ltp": 1.73, "tv": 4948.17, "trd": [[1.73, 795.84]], "batb": NaN, "batl": [[0, 1.73, 5.9]]}, {"timestamp": 1631532359116, "ltp": 1.73, "tv": 4948.17, "trd": NaN, "batb": NaN, "batl": [[0, 1.85, 28.5], [1, 1.86, 194.78], [2, 1.87, 3]]}, {"timestamp": 1631532362549, "ltp": 1.73, "tv": 4948.17, "trd": NaN, "batb": NaN, "batl": [[0, 1.85, 31.5]]}, {"timestamp": 1631532362962, "ltp": 1.73, "tv": 4948.17, "trd": NaN, "batb": [[2, 1.61, 123.18]], "batl": [[1, 1.86, 182.68]]}, {"timestamp": 1631532365767, "ltp": 1.85, "tv": 4949.01, "trd": [[1.85, 118.88]], "batb": [[0, 1.79, 2436.5], [1, 1.77, 2161.02], [2, 1.76, 2097.46]], "batl": [[0, 1.85, 30.66]]}, {"timestamp": 1631532366757, "ltp": 1.85, "tv": 4949.01, "trd": NaN, "batb": [[0, 1.8, 84.6], [1, 1.79, 226.44], [2, 1.77, 1282.6]], "batl": [[0, 1.85, 27.66], [2, 1.88, 168.89]]}, {"timestamp": 1631532367747, "ltp": 1.85, "tv": 4949.01, "trd": NaN, "batb": [[1, 1.79, 293.94]], "batl": NaN}, {"timestamp": 1631532370751, "ltp": 1.85, "tv": 4949.01, "trd": NaN, "batb": [[0, 1.82, 132.68], [1, 1.81, 72.72], [2, 1.8, 84.6]], "batl": [[0, 1.83, 59.76], [1, 1.84, 60.24], [2, 1.85, 27.66]]}, {"timestamp": 1631532370958, "ltp": 1.82, "tv": 4960.58, "trd": [[1.82, 11.57]], "batb": [[0, 1.82, 126.9]], "batl": NaN}, {"timestamp": 1631532373762, "ltp": 1.82, "tv": 5101.75, "trd": [[1.82, 152.75]], "batb": [[0, 1.82, 56.31]], "batl": NaN}, {"timestamp": 1631532374749, "ltp": 1.82, "tv": 5101.75, "trd": NaN, "batb": [[1, 1.81, 216.79]], "batl": [[0, 1.83, 44.21], [1, 1.84, 117.94]]}, {"timestamp": 1631532374957, "ltp": 1.82, "tv": 5101.75, "trd": NaN, "batb": [[1, 1.81, 139.38]], "batl": [[1, 1.84, 60.24]]}, {"timestamp": 1631532376465, "ltp": 1.82, "tv": 5101.75, "trd": NaN, "batb": NaN, "batl": [[0, 1.83, 145.21]]}, {"timestamp": 1631532378690, "ltp": 1.83, "tv": 5106.45, "trd": [[1.83, 4.69]], "batb": NaN, "batl": [[0, 1.83, 140.51]]}, {"timestamp": 1631532379679, "ltp": 1.83, "tv": 5110.45, "trd": [[1.83, 8.7]], "batb": NaN, "batl": [[0, 1.83, 138.51]]}, {"timestamp": 1631532380195, "ltp": 1.82, "tv": 5223.07, "trd": [[1.82, 265.37]], "batb": [[0, 1.81, 139.38], [1, 1.8, 84.6], [2, 1.79, 203.27]], "batl": [[0, 1.83, 138.67]]}, {"timestamp": 1631532383359, "ltp": 1.82, "tv": 5223.07, "trd": NaN, "batb": [[2, 1.78, 10.81]], "batl": NaN}, {"timestamp": 1631532385700, "ltp": 1.82, "tv": 5223.07, "trd": NaN, "batb": [[1, 1.8, 203.67], [2, 1.78, 208.95]], "batl": NaN}, {"timestamp": 1631532387568, "ltp": 1.83, "tv": 5256.19, "trd": [[1.82, 265.69], [1.83, 41.5]], "batb": [[0, 1.81, 66.66], [1, 1.78, 10.81], [2, 1.69, 104.35]], "batl": [[0, 1.83, 84.6], [1, 1.87, 9.4], [2, 1.97, 24.5]]}, {"timestamp": 1631532388501, "ltp": 1.83, "tv": 5256.19, "trd": NaN, "batb": [[0, 1.78, 10.81], [1, 1.69, 104.35], [2, 1.66, 36.78]], "batl": [[0, 1.87, 9.4], [1, 1.97, 24.5], [2, 2.02, 9.25]]}, {"timestamp": 1631532390477, "ltp": 1.83, "tv": 5256.19, "trd": NaN, "batb": NaN, "batl": [[0, 1.97, 24.5], [1, 2.02, 9.25], [2, 2.04, 8.88]]}, {"timestamp": 1631532394676, "ltp": 1.83, "tv": 5256.19, "trd": NaN, "batb": [[0, 1.82, 184], [1, 1.8, 191.01], [2, 1.78, 10.81]], "batl": [[0, 1.89, 172.83], [1, 1.91, 160.76], [2, 1.97, 24.5]]}, {"timestamp": 1631532395297, "ltp": 1.83, "tv": 5256.19, "trd": NaN, "batb": NaN, "batl": [[2, 1.96, 54.73]]}, {"timestamp": 1631532398424, "ltp": 1.83, "tv": 5256.19, "trd": NaN, "batb": [[0, 1.82, 232.53]], "batl": NaN}, {"timestamp": 1631532399517, "ltp": 1.83, "tv": 5256.19, "trd": NaN, "batb": [[0, 1.78, 10.81], [1, 1.69, 104.35], [2, 1.66, 36.78]], "batl": [[0, 2, 12.1], [1, 2.04, 8.88], [2, 2.5, 278.33]]}, {"timestamp": 1631532402719, "ltp": 1.83, "tv": 5256.19, "trd": NaN, "batb": [[1, 1.71, 38.19], [2, 1.69, 263.34]], "batl": [[0, 1.97, 30.83], [1, 1.99, 4], [2, 2, 12.1]]}, {"timestamp": 1631532403610, "ltp": 1.83, "tv": 5256.19, "trd": NaN, "batb": [[1, 1.71, 18.08]], "batl": [[0, 1.97, 5]]}, {"timestamp": 1631532408509, "ltp": 1.83, "tv": 5256.19, "trd": NaN, "batb": [[2, 1.69, 104.35]], "batl": [[2, 2.02, 215.14]]}, {"timestamp": 1631532409712, "ltp": 1.83, "tv": 5256.19, "trd": NaN, "batb": [[1, 1.71, 58.27]], "batl": [[0, 1.97, 32.5]]}, {"timestamp": 1631532410752, "ltp": 2.02, "tv": 5260.2, "trd": [[2.02, 4.01]], "batb": [[0, 1.92, 1992.18], [1, 1.91, 1933.6], [2, 1.9, 1933.6]], "batl": [[0, 2.02, 211.13], [1, 2.04, 140.59], [2, 2.5, 278.33]]}, {"timestamp": 1631532411739, "ltp": 2.02, "tv": 5260.2, "trd": NaN, "batb": [[0, 1.94, 114.01], [1, 1.92, 1151.14], [2, 1.91, 966.8]], "batl": [[2, 2.36, 8.47]]}, {"timestamp": 1631532412727, "ltp": 2.02, "tv": 5260.2, "trd": NaN, "batb": [[0, 1.94, 180.54], [2, 1.91, 1029.69]], "batl": [[2, 2.08, 57.73]]}, {"timestamp": 1631532415754, "ltp": 2.02, "tv": 5260.2, "trd": NaN, "batb": [[0, 1.96, 65.95], [1, 1.94, 180.54], [2, 1.92, 1151.14]], "batl": [[0, 1.97, 22.56], [1, 1.98, 44.89], [2, 1.99, 63.56]]}, {"timestamp": 1631532416231, "ltp": 2.02, "tv": 5260.2, "trd": NaN, "batb": [[1, 1.95, 78.74], [2, 1.94, 180.54]], "batl": NaN}, {"timestamp": 1631532420638, "ltp": 1.98, "tv": 5304.19, "trd": [[1.97, 27.07], [1.98, 36.89]], "batb": [[0, 1.96, 59.14]], "batl": [[0, 1.97, 1.86], [1, 1.98, 11.74], [2, 1.99, 90.36]]}, {"timestamp": 1631532421264, "ltp": 1.96, "tv": 5308.84, "trd": [[1.96, 447.49]], "batb": [[0, 1.96, 56.81]], "batl": [[0, 1.97, 158.86]]}, {"timestamp": 1631532423460, "ltp": 1.94, "tv": 5941.02, "trd": [[1.94, 386.74], [1.95, 592.07], [1.96, 561.11]], "batb": [[0, 1.92, 996.08], [1, 1.91, 966.8], [2, 1.9, 966.8]], "batl": [[0, 1.94, 389.79], [1, 1.97, 158.86], [2, 1.98, 11.74]]}, {"timestamp": 1631532425674, "ltp": 1.94, "tv": 5941.02, "trd": NaN, "batb": NaN, "batl": [[2, 2.02, 135.59]]}, {"timestamp": 1631532426651, "ltp": 1.94, "tv": 6720.6, "trd": [[1.94, 1166.32]], "batb": [[0, 1.94, 241.89], [1, 1.93, 184.36], [2, 1.92, 996.08]], "batl": [[0, 1.97, 158.86], [1, 2, 139.21]]}, {"timestamp": 1631532427745, "ltp": 1.94, "tv": 6720.6, "trd": NaN, "batb": [[0, 1.94, 353.45]], "batl": NaN}, {"timestamp": 1631532428737, "ltp": 1.94, "tv": 6720.6, "trd": NaN, "batb": [[0, 1.94, 297.49]], "batl": NaN}, {"timestamp": 1631532429672, "ltp": 1.97, "tv": 6721.34, "trd": [[1.97, 27.81]], "batb": [[1, 1.93, 246.57]], "batl": [[0, 1.97, 156.26]]}, {"timestamp": 1631532429834, "ltp": 1.97, "tv": 6721.34, "trd": NaN, "batb": [[0, 1.94, 185.93]], "batl": NaN}, {"timestamp": 1631532431658, "ltp": 1.97, "tv": 6721.34, "trd": NaN, "batb": [[0, 1.93, 192.52], [1, 1.92, 996.08], [2, 1.91, 1124.42]], "batl": NaN}, {"timestamp": 1631532432178, "ltp": 1.94, "tv": 6793.79, "trd": [[1.94, 1238.77]], "batb": NaN, "batl": NaN}, {"timestamp": 1631532433688, "ltp": 1.94, "tv": 6793.79, "trd": NaN, "batb": [[1, 1.91, 157.62], [2, 1.82, 10.5]], "batl": NaN}, {"timestamp": 1631532434678, "ltp": 1.94, "tv": 6793.79, "trd": NaN, "batb": [[0, 1.93, 62.21], [1, 1.82, 10.5], [2, 1.81, 83.43]], "batl": [[1, 2.14, 8.25], [2, 2.16, 6.97]]}, {"timestamp": 1631532435355, "ltp": 1.94, "tv": 6793.79, "trd": NaN, "batb": [[0, 1.82, 10.5], [1, 1.81, 83.43], [2, 1.8, 35.68]], "batl": [[0, 2.14, 8.25], [1, 2.16, 6.97], [2, 2.22, 7.25]]}, {"timestamp": 1631532437588, "ltp": 1.94, "tv": 6793.79, "trd": NaN, "batb": [[1, 1.8, 237.33], [2, 1.78, 198.22]], "batl": [[2, 2.18, 128.71]]}, {"timestamp": 1631532442462, "ltp": 1.94, "tv": 6793.79, "trd": NaN, "batb": [[0, 1.8, 237.33], [1, 1.78, 198.22], [2, 1.74, 31.52]], "batl": [[0, 1.86, 1477.14], [1, 2.14, 8.25], [2, 2.16, 6.97]]}, {"timestamp": 1631532445749, "ltp": 1.86, "tv": 7355.29, "trd": [[1.85, 131.08], [1.86, 549.3]], "batb": [[2, 1.75, 601.07]], "batl": [[0, 1.86, 171.24], [1, 1.88, 168.99], [2, 1.89, 1011.9]]}, {"timestamp": 1631532446596, "ltp": 1.86, "tv": 7553.5, "trd": [[1.86, 747.51]], "batb": [[0, 1.81, 150.34], [1, 1.8, 152.65], [2, 1.78, 198.22]], "batl": [[0, 1.86, 67.48]]}, {"timestamp": 1631532447586, "ltp": 1.86, "tv": 7553.5, "trd": NaN, "batb": NaN, "batl": [[0, 1.89, 1011.9], [1, 1.9, 982.14], [2, 1.91, 982.14]]}, {"timestamp": 1631532449567, "ltp": 1.86, "tv": 7553.5, "trd": NaN, "batb": [[0, 1.83, 67.35], [1, 1.81, 150.34], [2, 1.8, 152.65]], "batl": [[0, 1.84, 269.25], [1, 1.89, 1011.9], [2, 1.9, 982.14]]}, {"timestamp": 1631532450668, "ltp": 1.86, "tv": 7553.5, "trd": NaN, "batb": [[1, 1.82, 65.7], [2, 1.81, 150.34]], "batl": [[1, 1.85, 70.81], [2, 1.87, 192.13]]}, {"timestamp": 1631532453756, "ltp": 1.81, "tv": 7835.86, "trd": [[1.81, 49.76], [1.82, 397.09], [1.83, 176.2]], "batb": [[0, 1.81, 142.21], [1, 1.8, 218.9], [2, 1.78, 198.22]], "batl": NaN}, {"timestamp": 1631532454592, "ltp": 1.81, "tv": 7835.86, "trd": NaN, "batb": [[0, 1.82, 64.79], [1, 1.81, 142.21], [2, 1.8, 218.9]], "batl": [[0, 1.83, 32.73], [1, 1.84, 139.05], [2, 1.85, 167.93]]}, {"timestamp": 1631532455375, "ltp": 1.81, "tv": 7835.86, "trd": NaN, "batb": NaN, "batl": [[1, 1.84, 278.05]]}, {"timestamp": 1631532460306, "ltp": 1.81, "tv": 7835.86, "trd": NaN, "batb": [[0, 1.81, 66.66], [1, 1.79, 9.36], [2, 1.67, 562.86]], "batl": [[0, 1.84, 139], [1, 1.9, 12.84], [2, 2.04, 8.63]]}, {"timestamp": 1631532461508, "ltp": 1.84, "tv": 7840.6, "trd": [[1.84, 31.79]], "batb": [[0, 1.79, 9.36], [1, 1.67, 562.86], [2, 1.6, 39.44]], "batl": [[0, 1.84, 134.26]]}, {"timestamp": 1631532461771, "ltp": 1.84, "tv": 7887.99, "trd": [[1.84, 79.18]], "batb": NaN, "batl": [[0, 1.82, 56.47], [1, 1.84, 86.87], [2, 1.9, 12.84]]}, {"timestamp": 1631532463490, "ltp": 1.84, "tv": 7887.99, "trd": NaN, "batb": NaN, "batl": [[2, 2.02, 4]]}, {"timestamp": 1631532465416, "ltp": 1.84, "tv": 7887.99, "trd": NaN, "batb": NaN, "batl": [[0, 2.02, 4], [1, 2.04, 8.63], [2, 2.06, 7.25]]}, {"timestamp": 1631532466410, "ltp": 1.84, "tv": 7887.99, "trd": NaN, "batb": NaN, "batl": [[1, 2.14, 8.25], [2, 2.16, 6.97]]}, {"timestamp": 1631532467716, "ltp": 1.84, "tv": 7887.99, "trd": NaN, "batb": [[0, 1.84, 74.37], [1, 1.83, 204.82], [2, 1.81, 187.55]], "batl": [[0, 1.9, 156.22], [1, 1.92, 158.2], [2, 2.02, 4]]}, {"timestamp": 1631532468605, "ltp": 1.84, "tv": 7887.99, "trd": NaN, "batb": NaN, "batl": [[2, 2, 20]]}, {"timestamp": 1631532469180, "ltp": 1.84, "tv": 7946.56, "trd": [[1.84, 137.75]], "batb": [[0, 1.84, 45.09]], "batl": NaN}, {"timestamp": 1631532470478, "ltp": 1.84, "tv": 7946.56, "trd": NaN, "batb": [[0, 1.83, 204.82], [1, 1.81, 187.55], [2, 1.8, 44.02]], "batl": NaN}, {"timestamp": 1631532471723, "ltp": 1.84, "tv": 7946.56, "trd": NaN, "batb": [[0, 1.79, 9.36], [1, 1.67, 562.86], [2, 1.6, 39.44]], "batl": [[0, 1.9, 12.27], [1, 2.02, 4], [2, 2.14, 8.25]]}, {"timestamp": 1631532474284, "ltp": 1.84, "tv": 7946.56, "trd": NaN, "batb": [[1, 1.67, 725.44], [2, 1.66, 127.01]], "batl": [[2, 2.06, 157.36]]}, {"timestamp": 1631532478391, "ltp": 1.84, "tv": 7946.56, "trd": NaN, "batb": NaN, "batl": [[2, 2.04, 7.63]]}, {"timestamp": 1631532478816, "ltp": 1.84, "tv": 7946.56, "trd": NaN, "batb": NaN, "batl": [[2, 2.06, 157.36]]}, {"timestamp": 1631532485618, "ltp": 1.84, "tv": 7946.56, "trd": NaN, "batb": NaN, "batl": [[2, 2.04, 8.88]]}, {"timestamp": 1631532486396, "ltp": 1.84, "tv": 7946.56, "trd": NaN, "batb": [[1, 1.67, 562.86], [2, 1.6, 39.44]], "batl": [[0, 2.14, 8.25], [1, 2.16, 6.97], [2, 2.22, 7.25]]}, {"timestamp": 1631532488621, "ltp": 1.84, "tv": 7946.56, "trd": NaN, "batb": [[0, 1.98, 1830.22], [1, 1.79, 9.36], [2, 1.67, 562.86]], "batl": NaN}, {"timestamp": 1631532489718, "ltp": 1.84, "tv": 7946.56, "trd": NaN, "batb": [[0, 1.99, 124.18], [1, 1.96, 975.78], [2, 1.95, 947.06]], "batl": [[0, 2.04, 4], [1, 2.14, 8.25], [2, 2.16, 6.97]]}, {"timestamp": 1631532490707, "ltp": 1.84, "tv": 7946.56, "trd": NaN, "batb": NaN, "batl": [[0, 2.14, 8.25], [1, 2.16, 6.97], [2, 2.22, 7.25]]}, {"timestamp": 1631532492211, "ltp": 1.84, "tv": 7946.56, "trd": NaN, "batb": [[0, 1.99, 129.18], [1, 1.98, 5], [2, 1.97, 4]], "batl": NaN}, {"timestamp": 1631532493612, "ltp": 1.84, "tv": 7946.56, "trd": NaN, "batb": [[0, 2, 4], [1, 1.99, 129.18], [2, 1.98, 5]], "batl": NaN}, {"timestamp": 1631532494231, "ltp": 1.84, "tv": 7946.56, "trd": NaN, "batb": NaN, "batl": [[0, 2.12, 56.69], [1, 2.14, 8.25], [2, 2.16, 6.97]]}, {"timestamp": 1631532497301, "ltp": 1.84, "tv": 7946.56, "trd": NaN, "batb": NaN, "batl": [[0, 2.1, 41.25], [1, 2.12, 56.69], [2, 2.14, 8.25]]}, {"timestamp": 1631532499640, "ltp": 1.84, "tv": 7946.56, "trd": NaN, "batb": NaN, "batl": [[0, 2.14, 8.25], [1, 2.16, 6.97], [2, 2.22, 7.25]]}, {"timestamp": 1631532502619, "ltp": 2.0, "tv": 7948.1, "trd": [[2, 1.54]], "batb": [[0, 2, 3.23]], "batl": [[0, 2.1, 57.2], [1, 2.14, 234.84], [2, 2.16, 6.97]]}, {"timestamp": 1631532503630, "ltp": 2.0, "tv": 7948.1, "trd": NaN, "batb": [[1, 1.99, 124.18], [2, 1.97, 4]], "batl": NaN}, {"timestamp": 1631532504541, "ltp": 2.0, "tv": 7948.1, "trd": NaN, "batb": [[2, 1.96, 975.78]], "batl": NaN}, {"timestamp": 1631532505648, "ltp": 2.0, "tv": 7948.1, "trd": NaN, "batb": NaN, "batl": [[0, 2.08, 41.25], [1, 2.1, 57.2], [2, 2.14, 8.25]]}, {"timestamp": 1631532505963, "ltp": 1.99, "tv": 8133.27, "trd": [[1.99, 109.76], [2, 76.95]], "batb": [[0, 1.99, 69.3], [1, 1.96, 975.78], [2, 1.95, 1008.61]], "batl": NaN}, {"timestamp": 1631532510746, "ltp": 1.99, "tv": 8133.27, "trd": NaN, "batb": [[1, 1.95, 61.55], [2, 1.82, 11.84]], "batl": NaN}, {"timestamp": 1631532511055, "ltp": 1.99, "tv": 8133.27, "trd": NaN, "batb": [[0, 1.95, 61.55], [1, 1.82, 11.84], [2, 1.81, 83.6]], "batl": [[0, 2.1, 57.2], [1, 2.32, 6.11], [2, 2.5, 278.33]]}, {"timestamp": 1631532512451, "ltp": 1.99, "tv": 8133.27, "trd": NaN, "batb": [[0, 1.82, 11.84], [1, 1.81, 83.6], [2, 1.79, 32.31]], "batl": [[0, 2.32, 6.11], [1, 2.5, 278.33], [2, 2.54, 5.75]]}, {"timestamp": 1631532514621, "ltp": 1.99, "tv": 8133.27, "trd": NaN, "batb": [[1, 1.8, 84.52]], "batl": NaN}, {"timestamp": 1631532515447, "ltp": 1.99, "tv": 8133.27, "trd": NaN, "batb": [[2, 1.71, 33.19]], "batl": NaN}, {"timestamp": 1631532516334, "ltp": 1.99, "tv": 8133.27, "trd": NaN, "batb": NaN, "batl": [[1, 2.54, 5.75], [2, 3.45, 53.16]]}, {"timestamp": 1631532519533, "ltp": 1.99, "tv": 8133.27, "trd": NaN, "batb": [[0, 1.84, 59.2], [1, 1.82, 11.84], [2, 1.8, 84.52]], "batl": [[0, 2.3, 30.55], [1, 2.32, 6.11], [2, 2.54, 5.75]]}, {"timestamp": 1631532529366, "ltp": 1.99, "tv": 8133.27, "trd": NaN, "batb": NaN, "batl": [[0, 2.32, 6.11], [1, 2.54, 5.75], [2, 2.82, 234.95]]}, {"timestamp": 1631532531590, "ltp": 1.99, "tv": 8133.27, "trd": NaN, "batb": [[0, 1.88, 638.05], [1, 1.84, 59.2], [2, 1.82, 11.84]], "batl": [[0, 2.54, 5.75], [1, 2.82, 234.95], [2, 3.45, 53.16]]}, {"timestamp": 1631532532677, "ltp": 1.99, "tv": 8133.27, "trd": NaN, "batb": [[0, 2.22, 89.87], [1, 2, 119.41]], "batl": [[1, 2.74, 7.3], [2, 2.82, 234.95]]}, {"timestamp": 1631532533757, "ltp": 1.99, "tv": 8133.27, "trd": NaN, "batb": [[2, 1.71, 33.19]], "batl": NaN}, {"timestamp": 1631532534584, "ltp": 1.99, "tv": 8133.27, "trd": NaN, "batb": [[2, 1.77, 407]], "batl": [[0, 2.52, 28.75], [1, 2.54, 5.75], [2, 2.74, 7.3]]}, {"timestamp": 1631532535568, "ltp": 1.99, "tv": 8133.27, "trd": NaN, "batb": [[1, 2, 178.61]], "batl": NaN}, {"timestamp": 1631532536755, "ltp": 1.99, "tv": 8133.27, "trd": NaN, "batb": NaN, "batl": [[0, 2.34, 51.83]]}, {"timestamp": 1631532539706, "ltp": 1.99, "tv": 8133.27, "trd": NaN, "batb": NaN, "batl": [[0, 2.34, 80.58]]}, {"timestamp": 1631532540698, "ltp": 1.99, "tv": 8133.27, "trd": NaN, "batb": [[0, 2.2, 90.38]], "batl": NaN}, {"timestamp": 1631532540897, "ltp": 1.99, "tv": 8133.27, "trd": NaN, "batb": [[1, 2, 119.41]], "batl": NaN}, {"timestamp": 1631532542666, "ltp": 1.99, "tv": 8133.27, "trd": NaN, "batb": [[1, 2.16, 51.72], [2, 2, 119.41]], "batl": NaN}, {"timestamp": 1631532544589, "ltp": 1.99, "tv": 8133.27, "trd": NaN, "batb": [[0, 2.2, 112.95], [1, 2, 119.41], [2, 1.77, 407]], "batl": NaN}, {"timestamp": 1631532548677, "ltp": 1.99, "tv": 8133.27, "trd": NaN, "batb": [[1, 2.18, 50.84], [2, 2, 119.41]], "batl": NaN}, {"timestamp": 1631532550388, "ltp": 2.22, "tv": 8133.39, "trd": [[2.22, 3.12]], "batb": NaN, "batl": NaN}, {"timestamp": 1631532556594, "ltp": 2.22, "tv": 8133.39, "trd": NaN, "batb": NaN, "batl": [[0, 2.54, 5.75], [1, 2.74, 7.3], [2, 2.82, 234.95]]}, {"timestamp": 1631532559493, "ltp": 2.22, "tv": 8133.39, "trd": NaN, "batb": NaN, "batl": [[0, 2.36, 51.44], [1, 2.52, 28.75], [2, 2.54, 5.75]]}, {"timestamp": 1631532560426, "ltp": 2.22, "tv": 8133.39, "trd": NaN, "batb": [[0, 2.22, 89.71], [1, 2.2, 22.57], [2, 2.18, 50.84]], "batl": [[1, 2.54, 5.75], [2, 2.74, 7.3]]}, {"timestamp": 1631532562916, "ltp": 2.22, "tv": 8133.39, "trd": NaN, "batb": NaN, "batl": [[0, 2.34, 28.75], [1, 2.36, 51.44], [2, 2.54, 5.75]]}, {"timestamp": 1631532614474, "ltp": 2.22, "tv": 8223.09, "trd": [[2.22, 92.82]], "batb": [[0, 2.2, 22.57], [1, 2.18, 50.84], [2, 2, 119.24]], "batl": NaN}, {"timestamp": 1631532621972, "ltp": 2.22, "tv": 8223.09, "trd": NaN, "batb": NaN, "batl": [[1, 2.36, 58.26], [2, 2.44, 5.58]]}, {"timestamp": 1631532628994, "ltp": 2.22, "tv": 8223.09, "trd": NaN, "batb": [[0, 2.18, 50.84], [1, 2, 119.24], [2, 1.97, 25.17]], "batl": [[0, 2.36, 58.26], [1, 2.44, 5.58], [2, 2.54, 5.75]]}, {"timestamp": 1631532651399, "ltp": 2.22, "tv": 8223.09, "trd": NaN, "batb": NaN, "batl": [[0, 2.36, 51.44], [1, 2.82, 234.95], [2, 3.45, 53.16]]}, {"timestamp": 1631532652429, "ltp": 2.22, "tv": 8223.09, "trd": NaN, "batb": [[0, 2, 119.24], [1, 1.97, 25.17], [2, 1.88, 25.21]], "batl": [[0, 2.82, 234.95], [1, 3.45, 53.16], [2, 3.45, 0]]}, {"timestamp": 1631532653313, "ltp": 2.22, "tv": 8223.09, "trd": NaN, "batb": NaN, "batl": [[0, 2.38, 5.75], [1, 2.48, 6.24], [2, 2.82, 234.95]]}, {"timestamp": 1631532654613, "ltp": 2.22, "tv": 8223.09, "trd": NaN, "batb": NaN, "batl": [[0, 2.36, 6.57], [1, 2.44, 5.33], [2, 2.48, 6.24]]}, {"timestamp": 1631532656429, "ltp": 2.22, "tv": 8223.09, "trd": NaN, "batb": NaN, "batl": [[0, 2.44, 5.33], [1, 2.48, 6.24], [2, 2.82, 234.95]]}, {"timestamp": 1631532658299, "ltp": 2.22, "tv": 8223.09, "trd": NaN, "batb": NaN, "batl": [[2, 3.45, 53.16]]}, {"timestamp": 1631532659639, "ltp": 2.22, "tv": 8223.09, "trd": NaN, "batb": [[0, 2.02, 2941.17], [1, 2, 119.24], [2, 1.97, 25.17]], "batl": [[0, 2.44, 8.33], [2, 2.56, 410.88]]}, {"timestamp": 1631532660685, "ltp": 2.22, "tv": 8223.09, "trd": NaN, "batb": [[0, 2.38, 72.63], [1, 2.36, 44.11], [2, 2.16, 95.81]], "batl": [[0, 2.44, 5.33]]}, {"timestamp": 1631532664668, "ltp": 2.22, "tv": 8223.09, "trd": NaN, "batb": [[0, 2.38, 98.32], [1, 2.16, 95.81], [2, 1.97, 25.17]], "batl": NaN}, {"timestamp": 1631532666693, "ltp": 2.22, "tv": 8223.09, "trd": NaN, "batb": [[2, 2.14, 7.82]], "batl": NaN}, {"timestamp": 1631532667569, "ltp": 2.22, "tv": 8223.09, "trd": NaN, "batb": NaN, "batl": [[2, 2.54, 5.75]]}, {"timestamp": 1631532668761, "ltp": 2.22, "tv": 8223.09, "trd": NaN, "batb": [[0, 2.4, 42.85], [1, 2.38, 98.32], [2, 2.16, 95.81]], "batl": NaN}, {"timestamp": 1631532669693, "ltp": 2.22, "tv": 8223.09, "trd": NaN, "batb": [[1, 2.16, 95.81], [2, 2.14, 7.82]], "batl": [[0, 2.58, 5.44], [1, 2.62, 5.46], [2, 2.68, 5.89]]}, {"timestamp": 1631532670467, "ltp": 2.22, "tv": 8223.09, "trd": NaN, "batb": [[0, 2.16, 95.81], [1, 2.14, 7.82], [2, 2.06, 7.08]], "batl": [[0, 2.62, 5.46], [1, 2.64, 4.93], [2, 3.3, 195.03]]}, {"timestamp": 1631532672700, "ltp": 2.22, "tv": 8223.09, "trd": NaN, "batb": NaN, "batl": [[0, 2.54, 5.75], [1, 2.62, 5.46], [2, 2.64, 4.93]]}, {"timestamp": 1631532673276, "ltp": 2.22, "tv": 8223.09, "trd": NaN, "batb": [[1, 2.06, 7.08], [2, 2.04, 7.37]], "batl": [[0, 2.62, 5.46], [1, 2.64, 4.93], [2, 3.3, 195.03]]}, {"timestamp": 1631532675669, "ltp": 2.22, "tv": 8223.09, "trd": NaN, "batb": NaN, "batl": [[0, 2.48, 4], [1, 2.62, 5.46], [2, 2.64, 4.93]]}, {"timestamp": 1631532676710, "ltp": 2.22, "tv": 8223.09, "trd": NaN, "batb": [[0, 2.18, 84.72], [1, 2.16, 95.81], [2, 2.14, 7.32]], "batl": [[0, 2.54, 5.25], [1, 2.6, 27.3], [2, 2.62, 5.46]]}, {"timestamp": 1631532677607, "ltp": 2.22, "tv": 8223.09, "trd": NaN, "batb": [[0, 2.16, 95.81], [1, 2.06, 7.08], [2, 2.04, 7.37]], "batl": [[0, 2.62, 5.46], [1, 2.64, 4.93], [2, 3.3, 195.03]]}, {"timestamp": 1631532678008, "ltp": 2.22, "tv": 8223.09, "trd": NaN, "batb": NaN, "batl": [[0, 2.4, 2.56], [1, 2.62, 5.46], [2, 2.64, 4.93]]}, {"timestamp": 1631532679671, "ltp": 2.22, "tv": 8223.09, "trd": NaN, "batb": NaN, "batl": [[0, 2.62, 5.46], [1, 2.64, 4.93], [2, 3.3, 195.03]]}, {"timestamp": 1631532680604, "ltp": 2.22, "tv": 8223.09, "trd": NaN, "batb": [[1, 2.14, 7.82], [2, 2.06, 7.08]], "batl": [[0, 2.62, 6.18]]}, {"timestamp": 1631532686515, "ltp": 2.22, "tv": 8223.09, "trd": NaN, "batb": NaN, "batl": [[2, 3.45, 53.16]]}, {"timestamp": 1631532688731, "ltp": 2.22, "tv": 8223.09, "trd": NaN, "batb": [[2, 2.12, 496.17]], "batl": [[0, 2.6, 261.96], [1, 2.62, 5.46], [2, 2.64, 4.93]]}, {"timestamp": 1631532689715, "ltp": 2.22, "tv": 8223.09, "trd": NaN, "batb": [[0, 2.18, 50.84], [1, 2.16, 95.81], [2, 2.14, 7.82]], "batl": [[0, 2.38, 51.07], [1, 2.5, 3.72], [2, 2.62, 5.46]]}, {"timestamp": 1631532690284, "ltp": 2.22, "tv": 8223.09, "trd": NaN, "batb": [[1, 2.16, 125.58]], "batl": NaN}, {"timestamp": 1631532693492, "ltp": 2.22, "tv": 8223.09, "trd": NaN, "batb": NaN, "batl": [[0, 2.36, 40.56], [1, 2.38, 51.07], [2, 2.5, 3.72]]}, {"timestamp": 1631532694634, "ltp": 2.22, "tv": 8223.09, "trd": NaN, "batb": NaN, "batl": [[2, 2.42, 6.47]]}, {"timestamp": 1631532695096, "ltp": 2.22, "tv": 8223.09, "trd": NaN, "batb": NaN, "batl": [[0, 2.42, 6.47], [1, 2.5, 3], [2, 2.52, 5.26]]}, {"timestamp": 1631532696698, "ltp": 2.22, "tv": 8223.09, "trd": NaN, "batb": NaN, "batl": [[0, 2.4, 6.81], [1, 2.42, 5.75], [2, 2.5, 8.23]]}, {"timestamp": 1631532698505, "ltp": 2.22, "tv": 8223.09, "trd": NaN, "batb": NaN, "batl": [[0, 2.36, 51.44], [1, 2.4, 6.81], [2, 2.42, 624.43]]}, {"timestamp": 1631532701626, "ltp": 2.22, "tv": 8223.09, "trd": NaN, "batb": NaN, "batl": [[0, 2.34, 40.56], [1, 2.36, 51.44], [2, 2.4, 6.81]]}, {"timestamp": 1631532703751, "ltp": 2.22, "tv": 8223.09, "trd": NaN, "batb": [[1, 1.95, 130.71], [2, 1.93, 26.36]], "batl": [[0, 2.36, 51.44], [1, 2.42, 6.47], [2, 2.5, 8.23]]}, {"timestamp": 1631532704522, "ltp": 2.22, "tv": 8223.09, "trd": NaN, "batb": NaN, "batl": [[0, 2.5, 3.72], [1, 2.52, 5.26], [2, 2.62, 5.46]]}, {"timestamp": 1631532705457, "ltp": 2.22, "tv": 8223.09, "trd": NaN, "batb": [[0, 1.95, 130.71], [1, 1.93, 26.36], [2, 1.88, 25.21]], "batl": NaN}, {"timestamp": 1631532707739, "ltp": 2.22, "tv": 8223.09, "trd": NaN, "batb": NaN, "batl": [[0, 2.42, 5.97], [1, 2.5, 3], [2, 2.52, 5.26]]}, {"timestamp": 1631532708725, "ltp": 2.22, "tv": 8223.09, "trd": NaN, "batb": NaN, "batl": [[0, 2.5, 3.72], [1, 2.52, 5.26], [2, 2.62, 5.46]]}, {"timestamp": 1631532711716, "ltp": 2.22, "tv": 8223.09, "trd": NaN, "batb": [[0, 2.3, 2], [1, 1.95, 130.71], [2, 1.93, 26.36]], "batl": [[0, 2.52, 5.98], [1, 2.62, 5.46], [2, 2.64, 4.93]]}, {"timestamp": 1631532712648, "ltp": 2.4, "tv": 8224.53, "trd": [[2.4, 1.44]], "batb": [[0, 2.4, 71.66], [1, 2.3, 2], [2, 2.14, 97.82]], "batl": [[0, 2.52, 5.26]]}, {"timestamp": 1631532713631, "ltp": 2.4, "tv": 8224.53, "trd": NaN, "batb": [[1, 2.38, 43.47], [2, 2.3, 2]], "batl": [[1, 2.62, 52.6]]}, {"timestamp": 1631532717737, "ltp": 2.4, "tv": 8224.53, "trd": NaN, "batb": [[1, 2.3, 2], [2, 2.16, 111.62]], "batl": NaN}, {"timestamp": 1631532718561, "ltp": 2.4, "tv": 8224.53, "trd": NaN, "batb": [[2, 2.18, 6.36]], "batl": [[1, 2.58, 5.44], [2, 2.62, 52.6]]}, {"timestamp": 1631532720736, "ltp": 2.4, "tv": 8224.53, "trd": NaN, "batb": [[0, 2.4, 114.51]], "batl": NaN}, {"timestamp": 1631532722654, "ltp": 2.4, "tv": 8224.53, "trd": NaN, "batb": [[1, 2.18, 6.36], [2, 2.14, 97.82]], "batl": [[0, 2.62, 47.14], [1, 2.64, 4.93], [2, 2.68, 4.39]]}, {"timestamp": 1631532723642, "ltp": 2.42, "tv": 8233.05, "trd": [[2.42, 27.84], [2.44, 6.4]], "batb": [[0, 2.4, 42.85]], "batl": NaN}, {"timestamp": 1631532724460, "ltp": 2.42, "tv": 8233.05, "trd": NaN, "batb": [[0, 2.18, 6.36], [1, 2.14, 97.82], [2, 2.1, 8.84]], "batl": [[0, 2.64, 4.93], [1, 2.68, 4.39], [2, 2.76, 4.77]]}, {"timestamp": 1631532725752, "ltp": 2.42, "tv": 8242.16, "trd": [[2.42, 36.95]], "batb": NaN, "batl": NaN}, {"timestamp": 1631532732986, "ltp": 2.42, "tv": 8242.16, "trd": NaN, "batb": [[0, 2.14, 97.82], [1, 2.1, 8.84], [2, 2.08, 7.56]], "batl": NaN}, {"timestamp": 1631532734481, "ltp": 2.42, "tv": 8242.16, "trd": NaN, "batb": NaN, "batl": [[0, 2.64, 5.65]]}, {"timestamp": 1631532735672, "ltp": 2.42, "tv": 8242.16, "trd": NaN, "batb": NaN, "batl": [[1, 2.68, 11.85]]}, {"timestamp": 1631532736661, "ltp": 2.42, "tv": 8242.16, "trd": NaN, "batb": [[0, 2.16, 51.72], [1, 2.14, 125.05], [2, 2.1, 8.84]], "batl": [[0, 2.38, 51.07], [1, 2.52, 25.37], [2, 2.64, 4.93]]}, {"timestamp": 1631532737696, "ltp": 2.42, "tv": 8242.16, "trd": NaN, "batb": NaN, "batl": [[1, 2.46, 4.72]]}, {"timestamp": 1631532740654, "ltp": 2.42, "tv": 8242.16, "trd": NaN, "batb": NaN, "batl": [[0, 2.36, 50.36], [1, 2.38, 51.07], [2, 2.46, 4.72]]}, {"timestamp": 1631532741583, "ltp": 2.42, "tv": 8242.16, "trd": NaN, "batb": NaN, "batl": [[1, 2.38, 1169.51]]}, {"timestamp": 1631532742256, "ltp": 2.42, "tv": 8242.16, "trd": NaN, "batb": NaN, "batl": [[1, 2.38, 1118.44], [2, 2.44, 6.8]]}, {"timestamp": 1631532745360, "ltp": 2.42, "tv": 8242.16, "trd": NaN, "batb": NaN, "batl": [[0, 2.34, 51.83], [1, 2.44, 6.8], [2, 2.46, 4]]}, {"timestamp": 1631532748598, "ltp": 2.42, "tv": 8242.16, "trd": NaN, "batb": NaN, "batl": [[0, 2.32, 50.36], [1, 2.34, 135.22], [2, 2.44, 6.08]]}, {"timestamp": 1631532751292, "ltp": 2.42, "tv": 8242.16, "trd": NaN, "batb": [[1, 1.9, 98.59], [2, 1.88, 25.21]], "batl": [[0, 2.34, 51.83], [1, 2.44, 6.08], [2, 2.6, 4.66]]}, {"timestamp": 1631532752490, "ltp": 2.42, "tv": 8242.16, "trd": NaN, "batb": [[0, 1.9, 98.59], [1, 1.88, 25.21], [2, 1.86, 403.32]], "batl": [[0, 2.44, 6.08], [1, 2.6, 4.66], [2, 2.64, 4.93]]}, {"timestamp": 1631532761197, "ltp": 2.42, "tv": 8242.16, "trd": NaN, "batb": [[0, 1.9, 71.63], [1, 1.86, 403.32], [2, 1.84, 29.72]], "batl": NaN}, {"timestamp": 1631532763694, "ltp": 2.42, "tv": 8242.16, "trd": NaN, "batb": [[1, 1.85, 2067.56], [2, 1.84, 2036.48]], "batl": [[0, 1.98, 1931.82], [1, 1.99, 1875], [2, 2, 1875]]}, {"timestamp": 1631532764681, "ltp": 1.97, "tv": 8253.01, "trd": [[1.97, 38.66]], "batb": [[0, 1.9, 232.04], [1, 1.88, 166.41], [2, 1.85, 1033.78]], "batl": [[0, 1.97, 122.19], [1, 1.98, 965.92], [2, 1.99, 1079.89]]}, {"timestamp": 1631532765405, "ltp": 1.97, "tv": 8253.01, "trd": NaN, "batb": [[0, 1.91, 62.89], [1, 1.9, 232.04], [2, 1.88, 166.41]], "batl": NaN}, {"timestamp": 1631532768648, "ltp": 1.97, "tv": 8253.01, "trd": NaN, "batb": [[0, 1.93, 108.26], [1, 1.92, 69.68], [2, 1.91, 62.89]], "batl": [[0, 1.94, 58.43], [1, 1.95, 68.63], [2, 1.97, 122.19]]}, {"timestamp": 1631532769213, "ltp": 1.94, "tv": 8253.11, "trd": [[1.94, 1238.87]], "batb": [[2, 1.91, 118.97]], "batl": [[0, 1.94, 58.33], [2, 1.97, 182.74]]}, {"timestamp": 1631532771718, "ltp": 1.94, "tv": 8253.11, "trd": NaN, "batb": NaN, "batl": [[0, 1.94, 171.33]]}, {"timestamp": 1631532772702, "ltp": 1.94, "tv": 8253.11, "trd": NaN, "batb": [[0, 1.93, 132.11], [1, 1.92, 127.71]], "batl": [[0, 1.94, 147.64], [2, 1.96, 62.48]]}, {"timestamp": 1631532773224, "ltp": 1.94, "tv": 8253.11, "trd": NaN, "batb": [[0, 1.91, 62.89], [1, 1.9, 232.04], [2, 1.89, 12.46]], "batl": [[0, 1.94, 113], [1, 1.97, 122.19], [2, 1.98, 965.92]]}, {"timestamp": 1631532776708, "ltp": 1.94, "tv": 8254.66, "trd": [[1.94, 1240.42]], "batb": NaN, "batl": [[0, 1.94, 112.23]]}, {"timestamp": 1631532776811, "ltp": 1.94, "tv": 8307.75, "trd": [[1.94, 1293.51]], "batb": NaN, "batl": [[0, 1.94, 59.14]]}, {"timestamp": 1631532778524, "ltp": 1.94, "tv": 8320.49, "trd": [[1.94, 1306.25]], "batb": NaN, "batl": [[0, 1.94, 46.4]]}, {"timestamp": 1631532780236, "ltp": 1.94, "tv": 8321.45, "trd": [[1.94, 1307.21]], "batb": NaN, "batl": [[0, 1.94, 45.44]]}, {"timestamp": 1631532781650, "ltp": 1.94, "tv": 8326.09, "trd": [[1.94, 1311.85]], "batb": [[1, 1.89, 12.46], [2, 1.67, 414.63]], "batl": [[0, 1.94, 43.12], [1, 2.18, 7.75], [2, 2.2, 5.83]]}, {"timestamp": 1631532782433, "ltp": 1.94, "tv": 8326.09, "trd": NaN, "batb": [[0, 1.89, 12.46], [1, 1.67, 414.63], [2, 1.66, 112.05]], "batl": [[0, 2.18, 7.75], [1, 2.2, 5.83], [2, 2.26, 3]]}, {"timestamp": 1631532784720, "ltp": 1.94, "tv": 8326.09, "trd": NaN, "batb": [[0, 1.94, 2.32], [1, 1.89, 12.46], [2, 1.67, 617.93]], "batl": [[2, 2.24, 101.77]]}, {"timestamp": 1631532785654, "ltp": 1.94, "tv": 8326.09, "trd": NaN, "batb": [[1, 1.67, 617.93], [2, 1.66, 238.81]], "batl": NaN}, {"timestamp": 1631532786435, "ltp": 1.94, "tv": 8326.09, "trd": NaN, "batb": [[1, 1.67, 414.63], [2, 1.66, 112.05]], "batl": [[2, 2.26, 3]]}, {"timestamp": 1631532787740, "ltp": 1.94, "tv": 8326.09, "trd": NaN, "batb": NaN, "batl": [[0, 1.97, 18.83], [1, 2.18, 7.75], [2, 2.2, 5.83]]}, {"timestamp": 1631532788055, "ltp": 1.94, "tv": 8330.74, "trd": [[1.94, 1316.5]], "batb": [[0, 1.67, 414.63], [1, 1.66, 112.05], [2, 1.63, 42.23]], "batl": [[0, 2.18, 7.75], [1, 2.2, 5.83], [2, 2.26, 3]]}, {"timestamp": 1631532789354, "ltp": 1.94, "tv": 8330.74, "trd": NaN, "batb": [[0, 1.85, 166.67], [1, 1.83, 181.75], [2, 1.67, 414.63]], "batl": [[0, 1.92, 166.37], [1, 1.94, 154], [2, 2.12, 38.75]]}, {"timestamp": 1631532791018, "ltp": 1.94, "tv": 8330.74, "trd": NaN, "batb": [[2, 1.7, 134.69]], "batl": NaN}, {"timestamp": 1631532793250, "ltp": 1.94, "tv": 8330.74, "trd": NaN, "batb": [[0, 1.67, 414.63], [1, 1.66, 112.05], [2, 1.64, 9.14]], "batl": [[0, 2.18, 7.75], [1, 2.2, 5.83], [2, 2.26, 3]]}, {"timestamp": 1631532796163, "ltp": 1.94, "tv": 8330.74, "trd": NaN, "batb": [[0, 1.67, 617.93], [1, 1.66, 238.81]], "batl": [[2, 2.24, 101.77]]}, {"timestamp": 1631532800464, "ltp": 1.94, "tv": 8330.74, "trd": NaN, "batb": NaN, "batl": [[0, 2.24, 101.77], [1, 2.26, 100.99], [2, 2.3, 6.85]]}, {"timestamp": 1631532803727, "ltp": 1.94, "tv": 8330.74, "trd": NaN, "batb": NaN, "batl": [[0, 2.18, 7.25], [1, 2.24, 105.77], [2, 2.26, 100.99]]}, {"timestamp": 1631532804037, "ltp": 1.94, "tv": 8330.74, "trd": NaN, "batb": NaN, "batl": [[0, 2.24, 105.77], [1, 2.26, 100.99], [2, 2.3, 6.85]]}, {"timestamp": 1631532810662, "ltp": 1.94, "tv": 8330.74, "trd": NaN, "batb": NaN, "batl": [[0, 2.18, 8.25], [1, 2.24, 105.77], [2, 2.26, 100.99]]}, {"timestamp": 1631532810869, "ltp": 1.94, "tv": 8330.74, "trd": NaN, "batb": NaN, "batl": [[0, 2.24, 105.77], [1, 2.26, 100.99], [2, 2.3, 6.85]]}, {"timestamp": 1631532812749, "ltp": 1.94, "tv": 8330.74, "trd": NaN, "batb": [[2, 1.63, 42.23]], "batl": [[0, 2.24, 4], [1, 2.26, 3]]}, {"timestamp": 1631532813471, "ltp": 1.94, "tv": 8330.74, "trd": NaN, "batb": NaN, "batl": [[2, 2.6, 261.61]]}, {"timestamp": 1631532815755, "ltp": 1.94, "tv": 8330.74, "trd": NaN, "batb": [[0, 1.67, 203.3]], "batl": [[0, 1.72, 2732.56], [1, 1.73, 219.84], [2, 1.75, 214.8]]}, {"timestamp": 1631532816748, "ltp": 1.72, "tv": 8343.43, "trd": [[1.72, 83.68]], "batb": [[1, 1.66, 415.77], [2, 1.65, 88.48]], "batl": [[0, 1.72, 2719.87]]}, {"timestamp": 1631532818670, "ltp": 1.72, "tv": 8472.29, "trd": [[1.72, 212.54]], "batb": NaN, "batl": [[0, 1.72, 2655.44], [1, 1.73, 199.54]]}, {"timestamp": 1631532820748, "ltp": 1.7, "tv": 8476.94, "trd": [[1.7, 220.93]], "batb": [[0, 1.69, 117.79], [1, 1.68, 75.59], [2, 1.67, 226.81]], "batl": [[0, 1.7, 56.58], [1, 1.71, 73.21], [2, 1.72, 2655.44]]}, {"timestamp": 1631532822299, "ltp": 1.7, "tv": 8476.94, "trd": NaN, "batb": [[1, 1.68, 148.35]], "batl": NaN}, {"timestamp": 1631532824577, "ltp": 1.7, "tv": 8476.94, "trd": NaN, "batb": [[0, 1.69, 157.45], [1, 1.68, 211.36]], "batl": [[0, 1.7, 36.87], [1, 1.71, 133.48]]}, {"timestamp": 1631532825047, "ltp": 1.7, "tv": 8476.94, "trd": NaN, "batb": [[0, 1.69, 117.79], [1, 1.68, 148.35]], "batl": [[1, 1.71, 73.21]]}, {"timestamp": 1631532827699, "ltp": 1.7, "tv": 8476.94, "trd": NaN, "batb": NaN, "batl": [[0, 1.7, 203.87]]}, {"timestamp": 1631532836712, "ltp": 1.7, "tv": 8485.42, "trd": [[1.7, 229.42]], "batb": NaN, "batl": [[0, 1.7, 195.38], [2, 1.73, 199.54]]}, {"timestamp": 1631532837705, "ltp": 1.7, "tv": 8492.54, "trd": [[1.7, 236.54]], "batb": [[0, 1.68, 72.76], [1, 1.61, 45.09], [2, 1.57, 58.7]], "batl": [[0, 1.7, 167], [1, 1.74, 9.97], [2, 1.81, 33.5]]}, {"timestamp": 1631532838694, "ltp": 1.69, "tv": 8492.62, "trd": [[1.69, 731.12]], "batb": [[0, 1.57, 58.7], [1, 1.56, 137.74], [2, 1.52, 430.59]], "batl": [[0, 1.74, 9.97], [1, 1.81, 33.5], [2, 1.82, 29.25]]}, {"timestamp": 1631532840407, "ltp": 1.69, "tv": 8492.62, "trd": NaN, "batb": [[0, 1.59, 154.94], [1, 1.58, 153.66], [2, 1.57, 195.44]], "batl": NaN}, {"timestamp": 1631532843224, "ltp": 1.69, "tv": 8492.62, "trd": NaN, "batb": [[2, 1.57, 184.3]], "batl": NaN}, {"timestamp": 1631532844627, "ltp": 1.69, "tv": 8492.62, "trd": NaN, "batb": NaN, "batl": [[0, 1.64, 2091.48], [1, 1.74, 9.97], [2, 1.81, 33.5]]}, {"timestamp": 1631532845622, "ltp": 1.69, "tv": 8492.62, "trd": NaN, "batb": [[0, 1.61, 37.09], [1, 1.59, 154.94], [2, 1.58, 153.66]], "batl": [[0, 1.74, 9.97], [1, 1.81, 33.5], [2, 1.82, 29.25]]}, {"timestamp": 1631532846722, "ltp": 1.69, "tv": 8492.62, "trd": NaN, "batb": [[0, 1.59, 154.94], [1, 1.58, 153.66], [2, 1.57, 184.3]], "batl": [[0, 1.64, 253.56], [1, 1.65, 130.48], [2, 1.74, 9.97]]}, {"timestamp": 1631532847712, "ltp": 1.69, "tv": 8492.62, "trd": NaN, "batb": NaN, "batl": [[2, 1.73, 49.85]]}, {"timestamp": 1631532848702, "ltp": 1.62, "tv": 8493.15, "trd": [[1.62, 0.52]], "batb": NaN, "batl": [[2, 1.73, 4]]}, {"timestamp": 1631532849634, "ltp": 1.62, "tv": 8493.15, "trd": NaN, "batb": [[2, 1.57, 2575.29]], "batl": NaN}, {"timestamp": 1631532850415, "ltp": 1.62, "tv": 8493.15, "trd": NaN, "batb": [[0, 1.61, 155.61], [1, 1.6, 69.32], [2, 1.59, 154.94]], "batl": [[0, 1.62, 57], [1, 1.63, 58.89], [2, 1.64, 253.56]]}, {"timestamp": 1631532851718, "ltp": 1.62, "tv": 8493.15, "trd": NaN, "batb": [[2, 1.59, 233.05]], "batl": [[2, 1.64, 303.41]]}, {"timestamp": 1631532855658, "ltp": 1.62, "tv": 8493.15, "trd": NaN, "batb": [[0, 1.59, 78.11], [1, 1.53, 49.33], [2, 1.51, 12.16]], "batl": [[0, 1.68, 9.31], [1, 1.69, 60], [2, 1.73, 33.5]]}, {"timestamp": 1631532856442, "ltp": 1.62, "tv": 8493.15, "trd": NaN, "batb": [[0, 1.62, 2.32]], "batl": [[1, 1.73, 33.5], [2, 1.81, 33.5]]}, {"timestamp": 1631532858526, "ltp": 1.62, "tv": 8497.79, "trd": [[1.62, 5.17]], "batb": [[0, 1.51, 292.6], [1, 1.5, 241.92], [2, 1.49, 219.03]], "batl": [[1, 1.73, 174.24], [2, 1.75, 215.04]]}, {"timestamp": 1631532859728, "ltp": 1.62, "tv": 8497.79, "trd": NaN, "batb": [[0, 1.51, 12.16], [1, 1.49, 219.03], [2, 1.44, 441.39]], "batl": [[0, 1.73, 33.5], [1, 1.81, 33.5], [2, 1.82, 29.25]]}, {"timestamp": 1631532859831, "ltp": 1.62, "tv": 8497.79, "trd": NaN, "batb": NaN, "batl": [[0, 1.61, 141.18], [1, 1.73, 33.5], [2, 1.81, 33.5]]}, {"timestamp": 1631532862632, "ltp": 1.65, "tv": 8810.7, "trd": [[1.61, 282.36], [1.65, 30.55]], "batb": [[0, 1.6, 263.21], [1, 1.59, 150.43], [2, 1.51, 12.16]], "batl": [[0, 1.65, 106.26], [1, 1.66, 128.08], [2, 1.73, 33.5]]}, {"timestamp": 1631532863764, "ltp": 1.65, "tv": 8810.7, "trd": NaN, "batb": [[0, 1.6, 146.44], [1, 1.51, 12.16], [2, 1.49, 219.03]], "batl": [[0, 1.66, 128.08], [1, 1.73, 33.5], [2, 1.81, 33.5]]}, {"timestamp": 1631532864550, "ltp": 1.65, "tv": 8810.7, "trd": NaN, "batb": [[1, 1.52, 60.8], [2, 1.51, 12.16]], "batl": [[1, 1.72, 10.3], [2, 1.73, 33.5]]}, {"timestamp": 1631532865748, "ltp": 1.65, "tv": 8810.7, "trd": NaN, "batb": [[0, 1.51, 12.16], [1, 1.49, 219.03], [2, 1.44, 441.39]], "batl": [[0, 1.69, 39.5]]}, {"timestamp": 1631532866736, "ltp": 1.65, "tv": 8810.7, "trd": NaN, "batb": NaN, "batl": [[0, 1.72, 10.3], [1, 1.73, 33.5], [2, 1.81, 33.5]]}, {"timestamp": 1631532868756, "ltp": 1.65, "tv": 8810.7, "trd": NaN, "batb": [[0, 1.61, 1.45], [1, 1.51, 12.16], [2, 1.49, 219.03]], "batl": NaN}, {"timestamp": 1631532869436, "ltp": 1.65, "tv": 8810.7, "trd": NaN, "batb": NaN, "batl": [[0, 1.73, 33.5], [1, 1.87, 32.5], [2, 1.88, 29.29]]}, {"timestamp": 1631532871675, "ltp": 1.65, "tv": 8810.7, "trd": NaN, "batb": [[0, 1.68, 2963.18], [1, 1.65, 2328.71], [2, 1.64, 2250]], "batl": NaN}, {"timestamp": 1631532872669, "ltp": 1.65, "tv": 8810.7, "trd": NaN, "batb": [[0, 1.68, 197.09], [1, 1.67, 109.62], [2, 1.66, 254.64]], "batl": [[0, 1.73, 167.78], [1, 1.75, 215.07], [2, 1.87, 32.5]]}, {"timestamp": 1631532873561, "ltp": 1.65, "tv": 8810.7, "trd": NaN, "batb": [[1, 1.67, 182.92]], "batl": [[2, 1.79, 60]]}, {"timestamp": 1631532876758, "ltp": 1.65, "tv": 8810.7, "trd": NaN, "batb": [[0, 1.7, 78.11], [1, 1.69, 66.15], [2, 1.68, 429.24]], "batl": [[0, 1.71, 139.19], [1, 1.72, 64.09], [2, 1.73, 167.78]]}, {"timestamp": 1631532879677, "ltp": 1.65, "tv": 8810.7, "trd": NaN, "batb": [[2, 1.68, 197.09]], "batl": NaN}, {"timestamp": 1631532880470, "ltp": 1.7, "tv": 8815.35, "trd": [[1.7, 241.19]], "batb": [[0, 1.7, 75.78], [2, 1.68, 269.85]], "batl": [[0, 1.71, 278.19]]}, {"timestamp": 1631532882286, "ltp": 1.7, "tv": 8825.76, "trd": [[1.7, 251.6]], "batb": [[0, 1.7, 70.58]], "batl": NaN}, {"timestamp": 1631532883662, "ltp": 1.7, "tv": 8825.76, "trd": NaN, "batb": [[0, 1.69, 132.56], [1, 1.68, 241.67], [2, 1.67, 109.62]], "batl": [[0, 1.7, 58.9], [1, 1.71, 278.19], [2, 1.72, 64.09]]}, {"timestamp": 1631532884764, "ltp": 1.7, "tv": 8825.76, "trd": NaN, "batb": [[0, 1.69, 66.15]], "batl": [[1, 1.71, 139], [2, 1.73, 167.78]]}, {"timestamp": 1631532885545, "ltp": 1.7, "tv": 8825.76, "trd": NaN, "batb": [[0, 1.68, 72.76], [1, 1.65, 232.15], [2, 1.57, 13.22]], "batl": [[0, 1.71, 139], [1, 1.74, 11.64], [2, 1.77, 232.15]]}, {"timestamp": 1631532886383, "ltp": 1.7, "tv": 8825.76, "trd": NaN, "batb": [[0, 1.65, 232.15], [1, 1.57, 13.22], [2, 1.56, 420.23]], "batl": [[0, 1.74, 11.64], [1, 1.77, 232.15], [2, 1.84, 29.03]]}, {"timestamp": 1631532887582, "ltp": 1.7, "tv": 8825.76, "trd": NaN, "batb": NaN, "batl": [[2, 1.83, 31.5]]}, {"timestamp": 1631532888681, "ltp": 1.7, "tv": 8825.76, "trd": NaN, "batb": [[1, 1.58, 207.75], [2, 1.57, 170.81]], "batl": [[2, 1.84, 29.03]]}, {"timestamp": 1631532892559, "ltp": 1.7, "tv": 8825.76, "trd": NaN, "batb": [[1, 1.57, 13.22], [2, 1.56, 420.23]], "batl": [[0, 1.77, 232.15], [1, 1.84, 29.03], [2, 1.86, 119.01]]}, {"timestamp": 1631532893764, "ltp": 1.7, "tv": 8825.76, "trd": NaN, "batb": NaN, "batl": [[0, 1.84, 29.03], [1, 1.86, 119.01], [2, 1.87, 32.5]]}, {"timestamp": 1631532894183, "ltp": 1.7, "tv": 8825.76, "trd": NaN, "batb": NaN, "batl": [[0, 1.86, 119.01], [1, 1.87, 32.5], [2, 1.88, 199.89]]}, {"timestamp": 1631532895578, "ltp": 1.7, "tv": 8825.76, "trd": NaN, "batb": [[0, 1.8, 2478.55], [1, 1.79, 216.97], [2, 1.78, 200.13]], "batl": NaN}, {"timestamp": 1631532896688, "ltp": 1.7, "tv": 8825.76, "trd": NaN, "batb": [[0, 1.8, 280.01]], "batl": NaN}, {"timestamp": 1631532899551, "ltp": 1.7, "tv": 8825.76, "trd": NaN, "batb": [[0, 1.82, 56.5], [1, 1.8, 280.01], [2, 1.79, 216.97]], "batl": [[0, 1.83, 61.77], [1, 1.84, 78.77], [2, 1.86, 119.01]]}, {"timestamp": 1631532900765, "ltp": 1.7, "tv": 8825.76, "trd": NaN, "batb": [[1, 1.81, 78.95], [2, 1.8, 280.01]], "batl": [[2, 1.85, 73.5]]}, {"timestamp": 1631532900872, "ltp": 1.7, "tv": 8825.76, "trd": NaN, "batb": [[2, 1.8, 350.34]], "batl": NaN}, {"timestamp": 1631532907676, "ltp": 1.7, "tv": 8825.76, "trd": NaN, "batb": [[0, 1.82, 46.15], [2, 1.8, 258.09]], "batl": [[0, 1.83, 221.59], [1, 1.84, 109.49]]}, {"timestamp": 1631532912564, "ltp": 1.82, "tv": 8833.08, "trd": [[1.82, 404.4]], "batb": [[0, 1.82, 38.83], [2, 1.79, 216.97]], "batl": NaN}, {"timestamp": 1631532913392, "ltp": 1.82, "tv": 8833.08, "trd": NaN, "batb": [[0, 1.79, 216.97], [1, 1.68, 9.27], [2, 1.67, 108.37]], "batl": [[0, 1.89, 232.15], [1, 1.95, 12.53], [2, 1.99, 24.5]]}, {"timestamp": 1631532915742, "ltp": 1.82, "tv": 8833.08, "trd": NaN, "batb": [[1, 1.68, 226.69]], "batl": NaN}, {"timestamp": 1631532916269, "ltp": 1.82, "tv": 8833.08, "trd": NaN, "batb": [[1, 1.68, 9.27]], "batl": [[1, 1.99, 24.5], [2, 2.02, 4]]}, {"timestamp": 1631532917686, "ltp": 1.82, "tv": 8833.08, "trd": NaN, "batb": NaN, "batl": [[0, 1.99, 24.5], [1, 2.02, 4], [2, 2.08, 7.44]]}, {"timestamp": 1631532918159, "ltp": 1.82, "tv": 8833.08, "trd": NaN, "batb": NaN, "batl": [[0, 2.02, 4], [1, 2.08, 7.44], [2, 2.22, 3]]}, {"timestamp": 1631532919566, "ltp": 1.82, "tv": 8833.08, "trd": NaN, "batb": [[0, 1.83, 142.15], [1, 1.81, 189.29], [2, 1.79, 216.97]], "batl": [[0, 1.89, 125.41], [1, 1.91, 162.37], [2, 2.02, 4]]}, {"timestamp": 1631532920765, "ltp": 1.82, "tv": 8833.08, "trd": NaN, "batb": [[2, 1.8, 41.35]], "batl": [[2, 1.98, 10.3]]}, {"timestamp": 1631532921288, "ltp": 1.82, "tv": 8833.08, "trd": NaN, "batb": NaN, "batl": [[2, 1.96, 232.15]]}, {"timestamp": 1631532922693, "ltp": 1.82, "tv": 8833.08, "trd": NaN, "batb": [[0, 1.79, 216.97], [1, 1.68, 9.27], [2, 1.67, 108.37]], "batl": [[0, 1.96, 232.15], [1, 1.98, 10.3], [2, 1.99, 23.5]]}, {"timestamp": 1631532925502, "ltp": 1.79, "tv": 9256.59, "trd": [[1.79, 423.52]], "batb": [[0, 1.79, 5.21], [1, 1.68, 226.69]], "batl": NaN}, {"timestamp": 1631532937626, "ltp": 1.79, "tv": 9256.59, "trd": NaN, "batb": [[0, 1.68, 226.69], [1, 1.67, 108.37], [2, 1.66, 254.86]], "batl": [[0, 1.74, 1746.9], [2, 2.02, 148.28]]}, {"timestamp": 1631532938721, "ltp": 1.79, "tv": 9256.59, "trd": NaN, "batb": [[0, 1.68, 217.42]], "batl": [[2, 2.02, 4]]}, {"timestamp": 1631532940620, "ltp": 1.79, "tv": 9256.59, "trd": NaN, "batb": NaN, "batl": [[2, 1.99, 23.5]]}, {"timestamp": 1631532941608, "ltp": 1.79, "tv": 9256.59, "trd": NaN, "batb": NaN, "batl": [[0, 1.71, 216.97], [1, 1.74, 1943.17], [2, 1.75, 1092.86]]}, {"timestamp": 1631532942705, "ltp": 1.71, "tv": 9269.59, "trd": [[1.71, 17.1]], "batb": [[0, 1.68, 290.18]], "batl": [[0, 1.71, 203.97], [1, 1.74, 196.27]]}, {"timestamp": 1631532943904, "ltp": 1.71, "tv": 9269.59, "trd": NaN, "batb": [[0, 1.68, 217.42]], "batl": NaN}, {"timestamp": 1631532945696, "ltp": 1.71, "tv": 9269.59, "trd": NaN, "batb": [[0, 1.69, 77.43], [1, 1.68, 217.42], [2, 1.67, 108.37]], "batl": [[0, 1.7, 141.3], [1, 1.71, 203.97], [2, 1.74, 196.27]]}, {"timestamp": 1631532946692, "ltp": 1.71, "tv": 9269.59, "trd": NaN, "batb": [[1, 1.68, 288.22]], "batl": [[1, 1.71, 273.48]]}, {"timestamp": 1631532947739, "ltp": 1.7, "tv": 9408.93, "trd": [[1.7, 390.94]], "batb": [[2, 1.67, 169.96]], "batl": [[0, 1.7, 71.64], [1, 1.71, 330.48], [2, 1.72, 59.86]]}, {"timestamp": 1631532949718, "ltp": 1.7, "tv": 9413.58, "trd": [[1.7, 395.59]], "batb": NaN, "batl": [[0, 1.7, 69.31]]}, {"timestamp": 1631532950604, "ltp": 1.68, "tv": 9844.54, "trd": [[1.68, 907.82], [1.69, 885.98], [1.7, 403.03]], "batb": [[0, 1.68, 153.89], [1, 1.67, 169.96], [2, 1.66, 328.71]], "batl": [[0, 1.7, 65.49]]}, {"timestamp": 1631532952430, "ltp": 1.7, "tv": 9848.1, "trd": [[1.7, 406.59]], "batb": NaN, "batl": [[0, 1.7, 61.93]]}, {"timestamp": 1631532953730, "ltp": 1.7, "tv": 9855.22, "trd": [[1.7, 413.71]], "batb": [[0, 1.69, 59.18], [1, 1.68, 83.09], [2, 1.67, 108.37]], "batl": [[0, 1.7, 125.49], [1, 1.71, 260.97], [2, 1.73, 12.34]]}, {"timestamp": 1631532954251, "ltp": 1.7, "tv": 9859.87, "trd": [[1.7, 418.36]], "batb": [[1, 1.68, 131.54]], "batl": [[0, 1.7, 123.16], [2, 1.73, 183.41]]}, {"timestamp": 1631532955711, "ltp": 1.7, "tv": 9859.87, "trd": NaN, "batb": NaN, "batl": [[1, 1.71, 57]]}, {"timestamp": 1631532956665, "ltp": 1.7, "tv": 9859.87, "trd": NaN, "batb": [[0, 1.66, 73.85], [1, 1.65, 232.15], [2, 1.57, 9.85]], "batl": [[0, 1.71, 57], [1, 1.73, 12.34], [2, 1.76, 60]]}, {"timestamp": 1631532957457, "ltp": 1.7, "tv": 9859.87, "trd": NaN, "batb": [[0, 1.65, 232.15], [1, 1.57, 9.85], [2, 1.54, 146.36]], "batl": [[0, 1.73, 12.34], [1, 1.96, 25.87], [2, 1.97, 26.5]]}, {"timestamp": 1631532959454, "ltp": 1.7, "tv": 9859.87, "trd": NaN, "batb": [[2, 1.55, 293.99]], "batl": [[1, 1.9, 185.59], [2, 1.92, 159.89]]}, {"timestamp": 1631532960658, "ltp": 1.7, "tv": 9859.87, "trd": NaN, "batb": [[0, 1.57, 9.85], [1, 1.54, 146.36], [2, 1.52, 430.52]], "batl": [[1, 1.96, 25.87], [2, 1.97, 26.5]]}, {"timestamp": 1631532961236, "ltp": 1.7, "tv": 9859.87, "trd": NaN, "batb": [[0, 1.71, 3.62], [1, 1.57, 9.85], [2, 1.54, 146.36]], "batl": NaN}, {"timestamp": 1631532963751, "ltp": 1.7, "tv": 9859.87, "trd": NaN, "batb": [[1, 1.68, 131.54], [2, 1.66, 1108.4]], "batl": [[0, 1.73, 183.41], [1, 1.75, 215.28], [2, 1.96, 25.87]]}, {"timestamp": 1631532963956, "ltp": 1.7, "tv": 9859.87, "trd": NaN, "batb": [[2, 1.66, 254.87]], "batl": NaN}, {"timestamp": 1631532966045, "ltp": 1.7, "tv": 9859.87, "trd": NaN, "batb": [[0, 1.57, 9.85], [1, 1.54, 146.36], [2, 1.52, 430.52]], "batl": [[0, 1.73, 12.34], [1, 1.96, 25.87], [2, 1.97, 26.5]]}, {"timestamp": 1631532967025, "ltp": 1.73, "tv": 9863.42, "trd": [[1.73, 799.39]], "batb": NaN, "batl": [[0, 1.73, 8.79]]}, {"timestamp": 1631532971764, "ltp": 1.73, "tv": 9863.42, "trd": NaN, "batb": [[1, 1.55, 293.99], [2, 1.54, 316.91]], "batl": [[1, 1.9, 185.59], [2, 1.92, 159.89]]}, {"timestamp": 1631532973854, "ltp": 1.73, "tv": 9863.42, "trd": NaN, "batb": [[1, 1.54, 146.36], [2, 1.52, 430.52]], "batl": [[1, 1.96, 25.87], [2, 1.97, 26.5]]}, {"timestamp": 1631532977660, "ltp": 1.73, "tv": 9863.42, "trd": NaN, "batb": [[0, 1.68, 131.54], [1, 1.66, 254.87], [2, 1.59, 892.55]], "batl": [[0, 1.73, 179.86], [1, 1.75, 215.28], [2, 1.96, 25.87]]}, {"timestamp": 1631532985742, "ltp": 1.73, "tv": 9863.42, "trd": NaN, "batb": [[0, 1.57, 9.85], [1, 1.54, 146.36], [2, 1.52, 430.52]], "batl": [[0, 1.73, 8.79], [1, 1.96, 25.87], [2, 1.97, 26.5]]}, {"timestamp": 1631532986890, "ltp": 1.73, "tv": 9875.14, "trd": [[1.73, 811.1]], "batb": NaN, "batl": [[0, 1.73, 2.93]]}, {"timestamp": 1631532988673, "ltp": 1.73, "tv": 9875.14, "trd": NaN, "batb": [[1, 1.55, 293.99], [2, 1.54, 316.91]], "batl": [[1, 1.9, 185.59], [2, 1.92, 159.89]]}, {"timestamp": 1631532990872, "ltp": 1.73, "tv": 9875.14, "trd": NaN, "batb": [[1, 1.54, 146.36], [2, 1.52, 430.52]], "batl": [[0, 1.96, 25.87], [1, 1.97, 26.5], [2, 2.22, 334.11]]}, {"timestamp": 1631532994384, "ltp": 1.73, "tv": 9875.14, "trd": NaN, "batb": [[0, 1.7, 464.84], [1, 1.68, 244.63], [2, 1.57, 9.85]], "batl": [[0, 1.76, 159.37], [1, 1.78, 203.53], [2, 1.91, 4]]}, {"timestamp": 1631532997386, "ltp": 1.73, "tv": 9875.14, "trd": NaN, "batb": [[0, 1.7, 232.15], [1, 1.57, 9.85], [2, 1.54, 146.36]], "batl": [[0, 1.91, 4], [1, 1.96, 25.87], [2, 1.97, 26.5]]}, {"timestamp": 1631533000577, "ltp": 1.73, "tv": 9875.14, "trd": NaN, "batb": [[2, 1.55, 293.99]], "batl": [[0, 1.9, 190.59], [1, 1.91, 4], [2, 1.92, 159.89]]}, {"timestamp": 1631533001464, "ltp": 1.7, "tv": 10339.44, "trd": [[1.7, 882.66]], "batb": [[0, 1.57, 9.85], [1, 1.55, 293.99], [2, 1.54, 316.91]], "batl": [[0, 1.7, 191.38], [1, 1.9, 190.59], [2, 1.91, 4]]}, {"timestamp": 1631533004372, "ltp": 1.7, "tv": 10339.44, "trd": NaN, "batb": [[1, 1.54, 146.36], [2, 1.52, 430.52]], "batl": NaN}, {"timestamp": 1631533006678, "ltp": 1.7, "tv": 10722.2, "trd": [[1.7, 1265.42]], "batb": NaN, "batl": [[0, 1.9, 190.59], [1, 1.91, 4], [2, 1.92, 159.89]]}, {"timestamp": 1631533007713, "ltp": 1.7, "tv": 10722.2, "trd": NaN, "batb": [[0, 1.83, 164.95], [1, 1.82, 216.97], [2, 1.81, 189.51]], "batl": [[0, 1.9, 185.59], [1, 1.92, 159.89], [2, 1.93, 1486.4]]}, {"timestamp": 1631533008708, "ltp": 1.7, "tv": 10722.2, "trd": NaN, "batb": [[0, 1.84, 79.33], [1, 1.83, 164.95], [2, 1.82, 216.97]], "batl": NaN}, {"timestamp": 1631533010109, "ltp": 1.7, "tv": 10722.2, "trd": NaN, "batb": NaN, "batl": [[1, 1.91, 60], [2, 1.92, 159.89]]}, {"timestamp": 1631533011682, "ltp": 1.7, "tv": 10722.2, "trd": NaN, "batb": [[0, 1.86, 75.26], [1, 1.84, 79.33], [2, 1.83, 164.95]], "batl": [[0, 1.87, 48.08], [1, 1.88, 73.46], [2, 1.89, 60.56]]}, {"timestamp": 1631533012612, "ltp": 1.83, "tv": 11530.15, "trd": [[1.83, 540.65], [1.84, 296.41], [1.85, 252.07], [1.86, 911.36]], "batb": [[0, 1.83, 1624.73], [1, 1.82, 216.97], [2, 1.66, 110.46]], "batl": NaN}, {"timestamp": 1631533013292, "ltp": 1.83, "tv": 11530.15, "trd": NaN, "batb": [[0, 1.84, 70.37], [1, 1.83, 1624.73], [2, 1.82, 216.97]], "batl": NaN}, {"timestamp": 1631533013809, "ltp": 1.83, "tv": 11530.15, "trd": NaN, "batb": [[2, 1.66, 110.46]], "batl": NaN}, {"timestamp": 1631533015584, "ltp": 1.83, "tv": 11530.15, "trd": NaN, "batb": [[2, 1.82, 217.08]], "batl": [[0, 1.87, 189.08], [2, 1.89, 252.72]]}, {"timestamp": 1631533018623, "ltp": 1.87, "tv": 11533.01, "trd": [[1.87, 2.86]], "batb": [[0, 1.85, 2.52], [1, 1.84, 70.37]], "batl": [[0, 1.87, 186.22]]}, {"timestamp": 1631533019717, "ltp": 1.85, "tv": 11559.99, "trd": [[1.85, 273.84], [1.87, 8.07]], "batb": [[0, 1.84, 70.37], [1, 1.82, 217.08], [2, 1.81, 9.49]], "batl": [[0, 1.85, 176.2], [1, 1.86, 67.64], [2, 1.87, 141]]}, {"timestamp": 1631533021296, "ltp": 1.84, "tv": 11693.57, "trd": [[1.84, 429.98]], "batb": [[0, 1.82, 217.08], [1, 1.81, 9.49], [2, 1.8, 193.11]], "batl": [[0, 1.84, 7.39], [1, 1.85, 176.2], [2, 1.86, 67.64]]}, {"timestamp": 1631533022631, "ltp": 1.85, "tv": 12063.56, "trd": [[1.84, 444.76], [1.85, 629.06]], "batb": NaN, "batl": [[0, 1.85, 15.68], [1, 1.86, 69.96], [2, 1.87, 141]]}, {"timestamp": 1631533027342, "ltp": 1.85, "tv": 12063.56, "trd": NaN, "batb": [[0, 1.81, 9.49], [1, 1.79, 67.5], [2, 1.66, 110.46]], "batl": [[0, 1.84, 2.32], [1, 1.85, 15.68], [2, 1.86, 2.32]]}, {"timestamp": 1631533028448, "ltp": 1.85, "tv": 12063.56, "trd": NaN, "batb": [[1, 1.66, 110.46], [2, 1.52, 430.52]], "batl": NaN}, {"timestamp": 1631533030632, "ltp": 1.85, "tv": 12063.56, "trd": NaN, "batb": [[1, 1.67, 187.4], [2, 1.66, 238.97]], "batl": NaN}, {"timestamp": 1631533033035, "ltp": 1.85, "tv": 12063.56, "trd": NaN, "batb": [[1, 1.66, 110.46], [2, 1.52, 430.52]], "batl": NaN}, {"timestamp": 1631533036325, "ltp": 1.86, "tv": 12104.22, "trd": [[1.84, 449.41], [1.85, 660.42], [1.86, 916.01]], "batb": [[0, 1.86, 117.91], [1, 1.84, 179.61], [2, 1.81, 9.49]], "batl": [[0, 1.92, 128], [1, 1.94, 154.99], [2, 2.02, 4]]}, {"timestamp": 1631533037522, "ltp": 1.86, "tv": 12104.22, "trd": NaN, "batb": NaN, "batl": [[1, 1.93, 11.77], [2, 1.94, 154.99]]}, {"timestamp": 1631533038387, "ltp": 1.86, "tv": 12104.22, "trd": NaN, "batb": [[1, 1.84, 411.76]], "batl": NaN}, {"timestamp": 1631533040658, "ltp": 1.86, "tv": 12104.22, "trd": NaN, "batb": [[0, 1.84, 232.15], [1, 1.81, 9.49], [2, 1.66, 110.46]], "batl": [[0, 1.93, 11.77], [1, 2.02, 4], [2, 2.22, 334.11]]}, {"timestamp": 1631533041650, "ltp": 1.86, "tv": 12104.22, "trd": NaN, "batb": [[0, 1.81, 9.49], [1, 1.66, 110.46], [2, 1.52, 430.52]], "batl": NaN}, {"timestamp": 1631533042841, "ltp": 1.86, "tv": 12104.22, "trd": NaN, "batb": [[1, 1.67, 187.4], [2, 1.66, 238.97]], "batl": [[2, 2.1, 194.27]]}, {"timestamp": 1631533044252, "ltp": 1.86, "tv": 12104.22, "trd": NaN, "batb": NaN, "batl": [[0, 1.86, 352.94], [1, 1.93, 11.77], [2, 2.02, 4]]}, {"timestamp": 1631533046233, "ltp": 1.86, "tv": 12104.22, "trd": NaN, "batb": NaN, "batl": [[0, 1.93, 11.77], [1, 2.02, 4], [2, 2.1, 194.27]]}, {"timestamp": 1631533047532, "ltp": 2.0, "tv": 12131.77, "trd": [[1.93, 23.85], [2, 80.95]], "batb": [[0, 2, 1974.49], [1, 1.86, 111.56], [2, 1.81, 9.49]], "batl": [[0, 2.02, 4], [1, 2.1, 194.27], [2, 2.12, 118.9]]}, {"timestamp": 1631533048470, "ltp": 2.0, "tv": 12131.77, "trd": NaN, "batb": [[1, 1.86, 297.49], [2, 1.67, 187.4]], "batl": [[1, 2.22, 334.11], [2, 3.45, 53.16]]}, {"timestamp": 1631533050444, "ltp": 2.0, "tv": 12131.77, "trd": NaN, "batb": [[1, 1.86, 185.93]], "batl": NaN}, {"timestamp": 1631533051740, "ltp": 1.86, "tv": 16452.6, "trd": [[1.86, 1287.87], [2, 4029.93]], "batb": [[0, 1.67, 187.4], [1, 1.66, 238.97], [2, 1.52, 430.52]], "batl": [[0, 1.72, 128.3], [1, 1.74, 219.88], [2, 1.75, 1092.86]]}, {"timestamp": 1631533052696, "ltp": 1.72, "tv": 16465.41, "trd": [[1.72, 225.35]], "batb": [[2, 1.53, 148.2]], "batl": [[0, 1.75, 1092.86], [1, 1.76, 530.36], [2, 1.77, 530.36]]}, {"timestamp": 1631533054765, "ltp": 1.72, "tv": 16465.41, "trd": NaN, "batb": [[0, 1.67, 223.13]], "batl": NaN}, {"timestamp": 1631533055753, "ltp": 1.72, "tv": 16465.41, "trd": NaN, "batb": [[0, 1.69, 62.84], [1, 1.68, 64.53], [2, 1.67, 223.13]], "batl": [[0, 1.7, 78.92], [1, 1.71, 77.73], [2, 1.73, 231.95]]}, {"timestamp": 1631533056749, "ltp": 1.72, "tv": 16465.41, "trd": NaN, "batb": [[2, 1.67, 3103.02]], "batl": NaN}, {"timestamp": 1631533057468, "ltp": 1.72, "tv": 16465.41, "trd": NaN, "batb": [[2, 1.67, 2257.25]], "batl": NaN}, {"timestamp": 1631533058465, "ltp": 1.7, "tv": 16623.25, "trd": [[1.7, 1423.26]], "batb": NaN, "batl": [[0, 1.71, 77.73], [1, 1.73, 231.95], [2, 1.74, 66.1]]}, {"timestamp": 1631533059658, "ltp": 1.7, "tv": 16623.25, "trd": NaN, "batb": NaN, "batl": [[0, 1.7, 158], [1, 1.71, 77.73], [2, 1.73, 231.95]]}, {"timestamp": 1631533061580, "ltp": 1.7, "tv": 16623.44, "trd": [[1.7, 1423.44]], "batb": NaN, "batl": [[0, 1.7, 157.91]]}, {"timestamp": 1631533062256, "ltp": 1.69, "tv": 16627.07, "trd": [[1.69, 889.62]], "batb": [[0, 1.69, 59.21]], "batl": NaN}, {"timestamp": 1631533063492, "ltp": 1.69, "tv": 16639.05, "trd": [[1.69, 901.59]], "batb": [[0, 1.68, 64.53], [1, 1.67, 2069.85], [2, 1.66, 184.31]], "batl": [[0, 1.69, 67.51], [1, 1.7, 157.91], [2, 1.72, 10.37]]}, {"timestamp": 1631533064590, "ltp": 1.69, "tv": 16639.05, "trd": NaN, "batb": [[1, 1.66, 184.31], [2, 1.54, 10.02]], "batl": NaN}, {"timestamp": 1631533066971, "ltp": 1.69, "tv": 16642.8, "trd": [[1.69, 905.35]], "batb": NaN, "batl": [[0, 1.69, 63.75]]}, {"timestamp": 1631533068684, "ltp": 1.69, "tv": 16645.69, "trd": [[1.69, 908.23]], "batb": [[1, 1.66, 73.85]], "batl": [[0, 1.69, 60.87]]}, {"timestamp": 1631533069197, "ltp": 1.69, "tv": 16645.69, "trd": NaN, "batb": [[0, 1.66, 73.85], [1, 1.54, 10.02], [2, 1.52, 430.52]], "batl": [[0, 1.69, 56.47], [1, 1.72, 10.37], [2, 1.77, 60]]}, {"timestamp": 1631533070581, "ltp": 1.69, "tv": 16645.69, "trd": NaN, "batb": [[0, 1.54, 10.02], [1, 1.3, 198.07], [2, 1.2, 388.24]], "batl": [[0, 1.72, 10.37], [1, 2.02, 9.9], [2, 3.45, 53.16]]}, {"timestamp": 1631533071464, "ltp": 1.69, "tv": 16645.69, "trd": NaN, "batb": NaN, "batl": [[0, 2.02, 9.9], [1, 3.45, 53.16], [2, 810, 0.07]]}, {"timestamp": 1631533073600, "ltp": 1.69, "tv": 16645.69, "trd": NaN, "batb": [[0, 1.3, 198.07], [1, 1.2, 388.24], [2, 1.1, 297.11]], "batl": [[0, 1.91, 60], [1, 2.02, 9.9], [2, 3.45, 53.16]]}, {"timestamp": 1631533074697, "ltp": 1.69, "tv": 16645.69, "trd": NaN, "batb": [[0, 1.77, 68.37], [1, 1.3, 198.07], [2, 1.2, 388.24]], "batl": [[0, 2.02, 9.9], [1, 3.45, 53.16], [2, 810, 0.07]]}, {"timestamp": 1631533075585, "ltp": 1.69, "tv": 16645.69, "trd": NaN, "batb": [[0, 1.3, 198.07], [1, 1.2, 388.24], [2, 1.1, 297.11]], "batl": NaN}, {"timestamp": 1631533076970, "ltp": 1.69, "tv": 16645.69, "trd": NaN, "batb": NaN, "batl": [[1, 2.08, 57.73], [2, 3.45, 53.16]]}, {"timestamp": 1631533078372, "ltp": 1.69, "tv": 16645.69, "trd": NaN, "batb": [[0, 1.96, 464.31], [1, 1.91, 62.89], [2, 1.3, 198.07]], "batl": NaN}, {"timestamp": 1631533080713, "ltp": 1.69, "tv": 16645.69, "trd": NaN, "batb": [[1, 1.4, 148.56]], "batl": NaN}, {"timestamp": 1631533082284, "ltp": 1.96, "tv": 17007.69, "trd": [[1.96, 923.11]], "batb": [[0, 1.96, 283.31]], "batl": NaN}, {"timestamp": 1631533083895, "ltp": 1.96, "tv": 17007.69, "trd": NaN, "batb": [[1, 1.93, 62.21], [2, 1.4, 148.56]], "batl": NaN}, {"timestamp": 1631533087584, "ltp": 1.96, "tv": 17018.11, "trd": [[1.96, 933.53]], "batb": [[0, 1.96, 278.1]], "batl": NaN}, {"timestamp": 1631533091694, "ltp": 1.96, "tv": 17018.29, "trd": [[1.96, 933.71]], "batb": [[0, 1.96, 278.01]], "batl": NaN}, {"timestamp": 1631533096288, "ltp": 2.02, "tv": 17023.33, "trd": [[2.02, 9.05]], "batb": NaN, "batl": [[0, 2.02, 6.52]]}, {"timestamp": 1631533099506, "ltp": 2.02, "tv": 17023.33, "trd": NaN, "batb": [[0, 1.96, 510.16]], "batl": NaN}, {"timestamp": 1631533101527, "ltp": 1.96, "tv": 17032.29, "trd": [[1.96, 942.67]], "batb": [[0, 1.96, 501.21]], "batl": NaN}, {"timestamp": 1631533101933, "ltp": 1.96, "tv": 17041.24, "trd": [[1.96, 951.62]], "batb": [[0, 1.96, 492.25]], "batl": NaN}, {"timestamp": 1631533103815, "ltp": 1.96, "tv": 17043.92, "trd": [[1.96, 954.3]], "batb": [[0, 1.96, 489.57]], "batl": NaN}, {"timestamp": 1631533124665, "ltp": 2.02, "tv": 17050.44, "trd": [[2.02, 15.57]], "batb": NaN, "batl": [[0, 2.08, 57.73], [1, 3.45, 53.16], [2, 3.45, 0]]}, {"timestamp": 1631533131663, "ltp": 2.02, "tv": 17056.3, "trd": [[2.02, 21.43]], "batb": NaN, "batl": NaN}, {"timestamp": 1631533141996, "ltp": 2.02, "tv": 17056.3, "trd": NaN, "batb": NaN, "batl": [[0, 2.06, 196.85], [1, 2.08, 57.73], [2, 3.45, 53.16]]}, {"timestamp": 1631533143832, "ltp": 1.96, "tv": 17084.56, "trd": [[1.96, 980.82], [2.02, 23.17]], "batb": [[0, 1.96, 476.31]], "batl": NaN}, {"timestamp": 1631533159719, "ltp": 1.96, "tv": 17084.56, "trd": NaN, "batb": [[0, 2, 2.53], [1, 1.99, 5.09], [2, 1.98, 61.38]], "batl": [[0, 2.02, 77.32], [1, 2.04, 75.18], [2, 2.06, 196.85]]}, {"timestamp": 1631533168728, "ltp": 1.96, "tv": 17084.56, "trd": NaN, "batb": [[2, 1.98, 63.68]], "batl": NaN}, {"timestamp": 1631533169033, "ltp": 1.96, "tv": 17084.56, "trd": NaN, "batb": [[0, 1.98, 63.68], [1, 1.97, 3.08], [2, 1.96, 476.31]], "batl": NaN}, {"timestamp": 1631533191864, "ltp": 1.96, "tv": 17084.56, "trd": NaN, "batb": NaN, "batl": [[0, 2.06, 196.85], [1, 3.45, 53.16], [2, 2.06, 0]]}, {"timestamp": 1631533193427, "ltp": 1.96, "tv": 17084.56, "trd": NaN, "batb": [[0, 1.4, 148.56], [1, 1.3, 198.07], [2, 1.2, 388.24]], "batl": NaN}, {"timestamp": 1631533201062, "ltp": 1.96, "tv": 17084.56, "trd": NaN, "batb": NaN, "batl": [[0, 3.45, 53.16], [1, 3.45, 0]]}, {"timestamp": 1631533203675, "ltp": 1.96, "tv": 17084.56, "trd": NaN, "batb": [[0, 2.06, 216.97], [1, 1.97, 216.97], [2, 1.4, 148.56]], "batl": NaN}, {"timestamp": 1631533205366, "ltp": 1.96, "tv": 17084.56, "trd": NaN, "batb": [[0, 2.1, 54.54], [1, 2.06, 216.97], [2, 1.97, 216.97]], "batl": [[0, 2.3, 52.62], [1, 3.45, 53.16]]}, {"timestamp": 1631533207454, "ltp": 1.96, "tv": 17084.56, "trd": NaN, "batb": [[0, 2.06, 216.97], [1, 1.97, 216.97], [2, 1.4, 148.56]], "batl": [[0, 3.45, 53.16], [1, 3.45, 0]]}, {"timestamp": 1631533209477, "ltp": 1.96, "tv": 17084.56, "trd": NaN, "batb": [[1, 1.97, 344.75]], "batl": NaN}, {"timestamp": 1631533210268, "ltp": 1.96, "tv": 17084.56, "trd": NaN, "batb": NaN, "batl": [[0, 2.2, 196.13], [1, 3.45, 53.16]]}, {"timestamp": 1631533212668, "ltp": 1.96, "tv": 17084.56, "trd": NaN, "batb": [[0, 1.98, 10.51]], "batl": NaN}, {"timestamp": 1631533234511, "ltp": 1.96, "tv": 17084.56, "trd": NaN, "batb": [[0, 1.97, 344.75], [1, 1.4, 148.56], [2, 1.3, 198.07]], "batl": NaN}, {"timestamp": 1631533238897, "ltp": 1.96, "tv": 17084.56, "trd": NaN, "batb": [[1, 1.41, 13.53], [2, 1.4, 148.56]], "batl": NaN}, {"timestamp": 1631533241915, "ltp": 1.96, "tv": 17084.56, "trd": NaN, "batb": NaN, "batl": [[0, 3.45, 53.16], [1, 3.45, 0]]}, {"timestamp": 1631533244715, "ltp": 1.96, "tv": 17084.56, "trd": NaN, "batb": [[0, 2.2, 216.97], [1, 1.97, 344.75], [2, 1.41, 13.53]], "batl": NaN}, {"timestamp": 1631533245722, "ltp": 2.28, "tv": 17093.05, "trd": [[2.26, 6.67], [2.28, 2.27]], "batb": [[0, 2.42, 61.05], [1, 2.2, 307.34], [2, 1.97, 216.97]], "batl": NaN}, {"timestamp": 1631533249341, "ltp": 2.28, "tv": 17093.05, "trd": NaN, "batb": [[1, 2.34, 44.77], [2, 2.2, 307.34]], "batl": [[0, 2.58, 47.73], [1, 3.45, 53.16]]}, {"timestamp": 1631533250540, "ltp": 2.42, "tv": 17215.14, "trd": [[2.42, 159.04]], "batb": [[0, 2.2, 307.34], [1, 2.06, 239.73], [2, 1.97, 216.97]], "batl": [[0, 2.42, 117.26], [1, 2.46, 6.25], [2, 2.54, 5.75]]}, {"timestamp": 1631533251216, "ltp": 2.42, "tv": 17332.4, "trd": [[2.42, 276.3]], "batb": [[1, 2.06, 232.15]], "batl": [[0, 2.46, 6.25], [1, 2.54, 5.75], [2, 2.58, 47.73]]}, {"timestamp": 1631533253746, "ltp": 2.42, "tv": 17332.4, "trd": NaN, "batb": [[0, 2.42, 262.81], [1, 2.36, 44.11], [2, 2.2, 307.34]], "batl": NaN}, {"timestamp": 1631533254534, "ltp": 2.46, "tv": 17348.49, "trd": [[2.46, 17.31]], "batb": [[0, 2.46, 104.41], [1, 2.42, 262.81], [2, 2.36, 44.11]], "batl": [[0, 2.54, 5.75], [1, 2.58, 47.73], [2, 3.45, 53.16]]}, {"timestamp": 1631533255734, "ltp": 2.46, "tv": 17348.49, "trd": NaN, "batb": [[0, 2.46, 190.77], [1, 2.42, 46.48]], "batl": [[2, 2.6, 5.56]]}, {"timestamp": 1631533256550, "ltp": 2.46, "tv": 17365.53, "trd": [[2.46, 34.35]], "batb": [[0, 2.46, 182.26], [1, 2.36, 44.11], [2, 2.2, 307.34]], "batl": NaN}, {"timestamp": 1631533257539, "ltp": 2.46, "tv": 17365.53, "trd": NaN, "batb": [[0, 2.36, 44.11], [1, 2.2, 307.34], [2, 2.02, 7.74]], "batl": NaN}, {"timestamp": 1631533259664, "ltp": 2.46, "tv": 17365.53, "trd": NaN, "batb": [[0, 2.2, 307.34], [1, 2.02, 7.74], [2, 1.97, 216.97]], "batl": NaN}, {"timestamp": 1631533260766, "ltp": 2.46, "tv": 17365.53, "trd": NaN, "batb": NaN, "batl": [[0, 2.58, 47.73], [1, 2.76, 5.02], [2, 3.45, 53.16]]}, {"timestamp": 1631533261444, "ltp": 2.46, "tv": 17365.53, "trd": NaN, "batb": NaN, "batl": [[0, 2.76, 5.02], [1, 3.45, 53.16], [2, 3.45, 0]]}, {"timestamp": 1631533264731, "ltp": 2.46, "tv": 17365.53, "trd": NaN, "batb": NaN, "batl": [[0, 2.6, 4], [1, 2.76, 5.02], [2, 3.45, 53.16]]}, {"timestamp": 1631533266755, "ltp": 2.46, "tv": 17365.53, "trd": NaN, "batb": NaN, "batl": [[0, 2.46, 3], [1, 2.48, 4], [2, 2.6, 4]]}, {"timestamp": 1631533267258, "ltp": 2.46, "tv": 17365.53, "trd": NaN, "batb": NaN, "batl": [[1, 2.6, 4], [2, 2.76, 5.02]]}, {"timestamp": 1631533268750, "ltp": 2.46, "tv": 17365.53, "trd": NaN, "batb": [[0, 2.22, 102], [1, 2.2, 307.34], [2, 2.02, 7.74]], "batl": [[1, 2.6, 24], [2, 2.68, 4.39]]}, {"timestamp": 1631533272753, "ltp": 2.44, "tv": 17365.72, "trd": [[2.44, 6.6]], "batb": [[0, 2.2, 307.34], [1, 2.02, 7.74], [2, 1.98, 12.59]], "batl": [[1, 2.6, 4]]}, {"timestamp": 1631533273420, "ltp": 2.44, "tv": 17365.72, "trd": NaN, "batb": NaN, "batl": [[2, 2.76, 5.02]]}, {"timestamp": 1631533280696, "ltp": 2.44, "tv": 17365.72, "trd": NaN, "batb": NaN, "batl": [[1, 2.76, 5.02], [2, 3.45, 53.16]]}, {"timestamp": 1631533283708, "ltp": 2.44, "tv": 17369.72, "trd": [[2.44, 10.6]], "batb": NaN, "batl": [[0, 2.76, 5.02], [1, 3.45, 53.16], [2, 3.45, 0]]}, {"timestamp": 1631533284491, "ltp": 2.44, "tv": 17369.72, "trd": NaN, "batb": [[0, 2.5, 216.97], [1, 2.38, 8.46], [2, 2.2, 307.34]], "batl": [[1, 2.84, 370.38], [2, 2.86, 359.48]]}, {"timestamp": 1631533285744, "ltp": 2.44, "tv": 17369.72, "trd": NaN, "batb": [[0, 2.62, 56.15], [1, 2.5, 216.97], [2, 2.46, 66.61]], "batl": [[1, 2.84, 414.61]]}, {"timestamp": 1631533286627, "ltp": 2.44, "tv": 17369.72, "trd": NaN, "batb": [[1, 2.6, 3], [2, 2.58, 3]], "batl": NaN}, {"timestamp": 1631533287614, "ltp": 2.76, "tv": 17377.72, "trd": [[2.76, 8]], "batb": [[0, 2.74, 3], [1, 2.68, 3], [2, 2.66, 3]], "batl": [[0, 2.76, 1.02]]}, {"timestamp": 1631533288603, "ltp": 2.74, "tv": 17380.72, "trd": [[2.74, 3]], "batb": [[0, 2.68, 3], [1, 2.66, 3], [2, 2.62, 56.15]], "batl": NaN}, {"timestamp": 1631533291724, "ltp": 2.74, "tv": 17380.72, "trd": NaN, "batb": [[0, 2.72, 3], [1, 2.68, 3], [2, 2.66, 3]], "batl": NaN}, {"timestamp": 1631533292717, "ltp": 2.74, "tv": 17380.72, "trd": NaN, "batb": [[1, 2.7, 101.19], [2, 2.68, 1110.33]], "batl": NaN}, {"timestamp": 1631533293648, "ltp": 2.74, "tv": 17380.72, "trd": NaN, "batb": [[1, 2.68, 1110.33], [2, 2.66, 3]], "batl": NaN}, {"timestamp": 1631533296614, "ltp": 2.72, "tv": 17497.04, "trd": [[2.72, 116.32]], "batb": [[0, 2.68, 1107.33], [1, 2.62, 56.15], [2, 2.6, 37.5]], "batl": NaN}, {"timestamp": 1631533298447, "ltp": 2.68, "tv": 17502.15, "trd": [[2.68, 5.11]], "batb": [[0, 2.68, 1104.77]], "batl": NaN}, {"timestamp": 1631533299542, "ltp": 2.68, "tv": 17502.15, "trd": NaN, "batb": [[0, 2.7, 46.03]], "batl": NaN}, {"timestamp": 1631533300530, "ltp": 2.68, "tv": 17502.15, "trd": NaN, "batb": [[0, 2.62, 56.15], [1, 2.6, 37.5], [2, 2.46, 66.61]], "batl": NaN}, {"timestamp": 1631533301726, "ltp": 2.68, "tv": 17502.15, "trd": NaN, "batb": NaN, "batl": [[0, 2.84, 44.23], [1, 3.45, 53.16], [2, 2.86, 0]]}, {"timestamp": 1631533302476, "ltp": 2.68, "tv": 17502.15, "trd": NaN, "batb": [[0, 2.6, 37.5], [1, 2.46, 66.61], [2, 2.26, 7.48]], "batl": NaN}, {"timestamp": 1631533303733, "ltp": 2.68, "tv": 17502.15, "trd": NaN, "batb": [[0, 2.46, 66.61], [1, 2.26, 7.48], [2, 1.4, 148.56]], "batl": [[0, 2.68, 2.56]]}, {"timestamp": 1631533305653, "ltp": 2.68, "tv": 17502.15, "trd": NaN, "batb": [[0, 2.5, 64.69], [1, 2.38, 5.96], [2, 2.26, 7.48]], "batl": [[1, 2.84, 3], [2, 3.45, 53.16]]}, {"timestamp": 1631533306647, "ltp": 2.68, "tv": 17502.15, "trd": NaN, "batb": NaN, "batl": [[2, 2.9, 3]]}, {"timestamp": 1631533308426, "ltp": 2.68, "tv": 17502.15, "trd": NaN, "batb": [[1, 2.26, 7.48], [2, 1.4, 148.56]], "batl": NaN}, {"timestamp": 1631533309833, "ltp": 2.68, "tv": 17502.15, "trd": NaN, "batb": NaN, "batl": [[0, 2.68, 4.88]]}, {"timestamp": 1631533311662, "ltp": 2.68, "tv": 17507.03, "trd": [[2.68, 9.99]], "batb": [[1, 2.38, 6.17], [2, 2.26, 7.48]], "batl": [[0, 2.84, 3], [1, 2.9, 3], [2, 3.45, 53.16]]}, {"timestamp": 1631533314735, "ltp": 2.68, "tv": 17507.03, "trd": NaN, "batb": [[1, 2.26, 7.48], [2, 1.4, 148.56]], "batl": NaN}, {"timestamp": 1631533317754, "ltp": 2.68, "tv": 17507.03, "trd": NaN, "batb": [[1, 2.38, 5.46], [2, 2.26, 7.48]], "batl": NaN}, {"timestamp": 1631533319151, "ltp": 2.62, "tv": 17510.99, "trd": [[2.62, 3.96]], "batb": NaN, "batl": [[1, 3.45, 53.16], [2, 3.45, 0]]}, {"timestamp": 1631533326465, "ltp": 2.62, "tv": 17510.99, "trd": NaN, "batb": [[1, 2.44, 783.82], [2, 2.42, 418.42]], "batl": [[0, 2.66, 718.98], [1, 2.68, 697.84], [2, 2.7, 697.84]]}, {"timestamp": 1631533327765, "ltp": 2.62, "tv": 17510.99, "trd": NaN, "batb": [[0, 2.52, 21.78], [1, 2.5, 64.69], [2, 2.44, 783.82]], "batl": [[0, 2.66, 765.54]]}, {"timestamp": 1631533331578, "ltp": 2.62, "tv": 17510.99, "trd": NaN, "batb": [[1, 2.5, 1512.73]], "batl": [[0, 2.66, 718.98]]}, {"timestamp": 1631533334697, "ltp": 2.62, "tv": 17510.99, "trd": NaN, "batb": NaN, "batl": [[0, 2.62, 47.14], [1, 2.66, 718.98], [2, 2.68, 697.84]]}, {"timestamp": 1631533338669, "ltp": 2.62, "tv": 17510.99, "trd": NaN, "batb": [[0, 2.5, 1448.04], [1, 2.4, 42.85], [2, 2.28, 5.91]], "batl": [[1, 3.45, 53.16], [2, 2.68, 0]]}, {"timestamp": 1631533339498, "ltp": 2.62, "tv": 17510.99, "trd": NaN, "batb": [[0, 2.28, 5.91], [1, 2.26, 91.58], [2, 1.4, 148.56]], "batl": [[0, 3.45, 53.16], [1, 3.45, 0]]}, {"timestamp": 1631533342470, "ltp": 2.62, "tv": 17510.99, "trd": NaN, "batb": [[2, 2.16, 6.78]], "batl": NaN}, {"timestamp": 1631533350694, "ltp": 2.62, "tv": 17510.99, "trd": NaN, "batb": [[0, 2.7, 708.32], [1, 2.68, 687.5], [2, 2.66, 687.5]], "batl": [[0, 2.8, 3], [1, 2.98, 641.78], [2, 3, 342.6]]}, {"timestamp": 1631533351696, "ltp": 2.62, "tv": 17510.99, "trd": NaN, "batb": [[0, 2.7, 760.54]], "batl": [[0, 2.98, 641.78], [1, 3, 342.6], [2, 3.05, 342.6]]}, {"timestamp": 1631533355516, "ltp": 2.78, "tv": 17602.75, "trd": [[2.78, 91.76]], "batb": [[0, 2.74, 1107.33], [1, 2.7, 760.54], [2, 2.68, 687.5]], "batl": [[0, 2.96, 42.85], [1, 2.98, 641.78], [2, 3, 342.6]]}, {"timestamp": 1631533358700, "ltp": 2.78, "tv": 17631.57, "trd": [[2.78, 120.57]], "batb": [[0, 2.74, 1136.88]], "batl": [[0, 2.94, 71.69], [1, 2.96, 42.85], [2, 2.98, 641.78]]}, {"timestamp": 1631533358910, "ltp": 2.78, "tv": 17631.57, "trd": NaN, "batb": NaN, "batl": [[0, 2.94, 17.89]]}, {"timestamp": 1631533360540, "ltp": 2.78, "tv": 17639.56, "trd": [[2.78, 128.57]], "batb": NaN, "batl": [[1, 2.98, 641.78], [2, 3, 342.6]]}, {"timestamp": 1631533361594, "ltp": 2.78, "tv": 17639.56, "trd": NaN, "batb": NaN, "batl": [[0, 2.98, 641.78], [1, 3, 342.6], [2, 3.05, 342.6]]}, {"timestamp": 1631533363696, "ltp": 2.78, "tv": 17639.56, "trd": NaN, "batb": NaN, "batl": [[0, 2.92, 43.3], [1, 2.98, 641.78], [2, 3, 342.6]]}, {"timestamp": 1631533364530, "ltp": 2.78, "tv": 17639.56, "trd": NaN, "batb": NaN, "batl": [[1, 2.96, 21.27], [2, 2.98, 641.78]]}, {"timestamp": 1631533366413, "ltp": 2.78, "tv": 17639.56, "trd": NaN, "batb": [[0, 2.74, 1107.33], [1, 2.66, 36.14], [2, 2.42, 76.32]], "batl": [[1, 3.45, 53.16], [2, 3.65, 173.19]]}, {"timestamp": 1631533367512, "ltp": 2.78, "tv": 17639.56, "trd": NaN, "batb": [[0, 2.42, 70.88], [1, 2.28, 5.91], [2, 2.26, 7.48]], "batl": [[0, 3.45, 53.16], [1, 3.65, 173.19], [2, 3.65, 0]]}, {"timestamp": 1631533370708, "ltp": 2.78, "tv": 17639.56, "trd": NaN, "batb": [[0, 2.44, 69.12], [1, 2.42, 5.63], [2, 2.28, 5.91]], "batl": [[0, 3.2, 2], [1, 3.45, 53.16], [2, 3.65, 173.19]]}, {"timestamp": 1631533374045, "ltp": 2.78, "tv": 17639.56, "trd": NaN, "batb": [[1, 2.28, 5.91], [2, 1.97, 399.51]], "batl": NaN}, {"timestamp": 1631533374830, "ltp": 2.78, "tv": 17639.56, "trd": NaN, "batb": [[2, 1.4, 148.56]], "batl": [[2, 3.65, 0]]}, {"timestamp": 1631533376754, "ltp": 2.78, "tv": 17639.56, "trd": NaN, "batb": [[0, 3.05, 627.06], [1, 3, 624.58], [2, 2.98, 608.6]], "batl": [[0, 3.4, 309.37], [1, 3.45, 599.12], [2, 3.5, 545.96]]}, {"timestamp": 1631533377744, "ltp": 2.78, "tv": 17639.56, "trd": NaN, "batb": [[0, 3.05, 721.12]], "batl": NaN}, {"timestamp": 1631533378628, "ltp": 2.78, "tv": 17639.56, "trd": NaN, "batb": NaN, "batl": [[0, 3.3, 39.56], [1, 3.4, 309.37], [2, 3.45, 599.12]]}, {"timestamp": 1631533379726, "ltp": 2.78, "tv": 17639.56, "trd": NaN, "batb": NaN, "batl": [[1, 3.4, 328.41]]}, {"timestamp": 1631533381719, "ltp": 2.78, "tv": 17639.56, "trd": NaN, "batb": [[0, 3.1, 86.3], [1, 3.05, 721.12], [2, 3, 624.58]], "batl": [[0, 3.4, 328.41], [1, 3.45, 599.12], [2, 3.5, 545.96]]}, {"timestamp": 1631533382762, "ltp": 2.78, "tv": 17639.56, "trd": NaN, "batb": [[0, 3.1, 23.75]], "batl": NaN}, {"timestamp": 1631533384321, "ltp": 2.78, "tv": 17639.56, "trd": NaN, "batb": NaN, "batl": [[0, 3.4, 367.13]]}, {"timestamp": 1631533385147, "ltp": 2.78, "tv": 17639.56, "trd": NaN, "batb": [[2, 3, 654.58]], "batl": NaN}, {"timestamp": 1631533387544, "ltp": 2.78, "tv": 17639.56, "trd": NaN, "batb": [[0, 3.1, 480.11]], "batl": NaN}, {"timestamp": 1631533390454, "ltp": 2.78, "tv": 17639.56, "trd": NaN, "batb": [[0, 3.1, 23.75]], "batl": NaN}, {"timestamp": 1631533391240, "ltp": 2.78, "tv": 17639.56, "trd": NaN, "batb": NaN, "batl": [[0, 3.4, 348.09]]}, {"timestamp": 1631533392131, "ltp": 3.1, "tv": 17639.74, "trd": [[3.1, 0.18]], "batb": [[0, 3.1, 23.66]], "batl": NaN}, {"timestamp": 1631533394739, "ltp": 3.1, "tv": 17639.74, "trd": NaN, "batb": [[0, 3, 30], [1, 2.74, 5.29], [2, 2.72, 51.38]], "batl": [[0, 3.4, 38.72], [1, 3.45, 53.16], [2, 4.2, 150.47]]}, {"timestamp": 1631533395518, "ltp": 3.1, "tv": 17639.74, "trd": NaN, "batb": [[0, 2.74, 5.29], [1, 2.72, 51.38], [2, 2.6, 5.24]], "batl": [[0, 3.45, 53.16], [1, 4.2, 150.47], [2, 4.2, 0]]}, {"timestamp": 1631533396159, "ltp": 3.1, "tv": 17639.74, "trd": NaN, "batb": [[0, 2.72, 51.38], [1, 2.6, 5.24], [2, 2.12, 393.24]], "batl": NaN}, {"timestamp": 1631533399752, "ltp": 3.1, "tv": 17639.74, "trd": NaN, "batb": NaN, "batl": [[0, 3.25, 18.54], [1, 3.45, 53.16], [2, 4.2, 150.47]]}, {"timestamp": 1631533400685, "ltp": 3.15, "tv": 17639.84, "trd": [[3.15, 0.09]], "batb": NaN, "batl": [[0, 3.45, 53.16], [1, 4.2, 150.47], [2, 4.2, 0]]}, {"timestamp": 1631533401581, "ltp": 3.15, "tv": 17639.84, "trd": NaN, "batb": [[0, 2.86, 85.5], [1, 2.72, 51.38], [2, 2.6, 5.24]], "batl": [[0, 3.45, 68.06]]}, {"timestamp": 1631533402685, "ltp": 3.15, "tv": 17639.84, "trd": NaN, "batb": [[1, 2.74, 5.02], [2, 2.72, 51.38]], "batl": NaN}, {"timestamp": 1631533403361, "ltp": 3.15, "tv": 17639.84, "trd": NaN, "batb": [[0, 2.74, 5.02], [1, 2.72, 51.38], [2, 2.6, 5.24]], "batl": NaN}, {"timestamp": 1631533406671, "ltp": 3.15, "tv": 17639.84, "trd": NaN, "batb": [[0, 2.72, 51.38], [1, 2.6, 5.24], [2, 2.12, 393.24]], "batl": [[0, 3.45, 53.16]]}, {"timestamp": 1631533413583, "ltp": 3.15, "tv": 17639.84, "trd": NaN, "batb": [[0, 2.74, 5.02], [1, 2.72, 51.38], [2, 2.6, 5.24]], "batl": NaN}, {"timestamp": 1631533414572, "ltp": 3.15, "tv": 17639.84, "trd": NaN, "batb": [[0, 2.72, 51.38], [1, 2.6, 5.24], [2, 2.12, 393.24]], "batl": NaN}, {"timestamp": 1631533417067, "ltp": 3.15, "tv": 17639.84, "trd": NaN, "batb": [[0, 2.74, 4.56], [1, 2.72, 51.38], [2, 2.6, 5.24]], "batl": NaN}, {"timestamp": 1631533418723, "ltp": 3.15, "tv": 17639.84, "trd": NaN, "batb": [[0, 2.72, 51.38], [1, 2.6, 5.24], 