{"info": {"id": "1.187612427", "eventId": "30898447", "eventName": "Match Odds", "marketType": "MATCH_ODDS", "openDate": 1631550042033, "name": "C Dinu v J Bouzas Maneiro", "numberOfActiveRunner": 2, "countryCode": "", "sport": "TENNIS", "venue": "", "volume": {"total": 272.91, "preMatch": 2.31, "inPlay": 270.6}, "winner": {"id": 9627400, "name": "C Dinu", "status": "WINNER", "position": 1}, "delay": 5}, "runners": [{"id": 9627400, "name": "C Dinu", "status": "WINNER", "position": 1, "inPlayOdds": 1.65, "inPlayTime": 1631550546815, "avgPrematch": 0, "closedOdds": 1.01, "maxPrematch": -100, "minPrematch": 1001, "maxInPlay": 1.65, "minInPlay": 1.01, "inPlayIndex": 0, "lengthOdds": 238, "lengthOddsPrematch": 0, "lengthOddsInPlay": 238, "tradedVolume": 267.0, "preMatchVolume": 1.4, "inPlayVolume": 265.6}, {"id": 25977944, "name": "J Bouzas Maneiro", "status": "LOSER", "position": 2, "inPlayOdds": 2.54, "inPlayTime": 1631550546815, "avgPrematch": 0, "closedOdds": 4.6, "maxPrematch": -100, "minPrematch": 1001, "maxInPlay": 4.6, "minInPlay": 2.54, "inPlayIndex": 0, "lengthOdds": 248, "lengthOddsPrematch": 0, "lengthOddsInPlay": 248, "tradedVolume": 5.91, "preMatchVolume": 0.91, "inPlayVolume": 5.0}], "marketUpdates": [{"timestamp": 1631528540989000000, "openDate": "2021-09-13T16:00:00.000Z", "status": "OPEN", "betDelay": 0, "inPlay": false, "complete": true}, {"timestamp": 1631543049791000000, "openDate": "2021-09-13T15:55:00.000Z", "status": "OPEN", "betDelay": 0, "inPlay": false, "complete": true}, {"timestamp": 1631544168709000000, "openDate": "2021-09-13T16:10:00.000Z", "status": "OPEN", "betDelay": 0, "inPlay": false, "complete": true}, {"timestamp": 1631549237922000000, "openDate": "2021-09-13T16:20:00.000Z", "status": "OPEN", "betDelay": 0, "inPlay": false, "complete": true}, {"timestamp": 1631550042033000000, "openDate": "2021-09-13T16:20:00.000Z", "status": "OPEN", "betDelay": 5, "inPlay": true, "complete": true}, {"timestamp": 1631550496858000000, "openDate": "2021-09-13T16:28:14.000Z", "status": "OPEN", "betDelay": 5, "inPlay": true, "complete": true}, {"timestamp": 1631556686104000000, "openDate": "2021-09-13T16:28:14.000Z", "status": "SUSPENDED", "betDelay": 5, "inPlay": true, "complete": true}, {"timestamp": 1631556692145000000, "openDate": "2021-09-13T16:28:14.000Z", "status": "CLOSED", "betDelay": 5, "inPlay": true, "complete": true}], "odds": [{"runnerId": 9627400, "odds": [{"timestamp": 1631550546815, "ltp": 1.65, "tv": 1.4, "trd": [[1.65, 1.4]], "batb": [[0, 1.45, 66.66]], "batl": NaN}, {"timestamp": 1631550556968, "ltp": 1.65, "tv": 1.4, "trd": NaN, "batb": [[0, 1.01, 12], [1, 1.01, 0]], "batl": NaN}, {"timestamp": 1631550561978, "ltp": 1.65, "tv": 1.4, "trd": NaN, "batb": [[0, 1.51, 58.82], [1, 1.01, 12]], "batl": NaN}, {"timestamp": 1631550580391, "ltp": 1.65, "tv": 1.4, "trd": NaN, "batb": [[0, 1.01, 12], [1, 1.01, 0]], "batl": NaN}, {"timestamp": 1631550585288, "ltp": 1.65, "tv": 1.4, "trd": NaN, "batb": [[0, 1.45, 66.66], [1, 1.01, 12]], "batl": NaN}, {"timestamp": 1631550604827, "ltp": 1.65, "tv": 1.4, "trd": NaN, "batb": [[0, 1.01, 12], [1, 1.01, 0]], "batl": NaN}, {"timestamp": 1631550609848, "ltp": 1.65, "tv": 1.4, "trd": NaN, "batb": [[0, 1.38, 78.94], [1, 1.01, 12]], "batl": NaN}, {"timestamp": 1631550698670, "ltp": 1.65, "tv": 1.4, "trd": NaN, "batb": [[0, 1.01, 12], [1, 1.01, 0]], "batl": NaN}, {"timestamp": 1631550703565, "ltp": 1.65, "tv": 1.4, "trd": NaN, "batb": [[0, 1.34, 88.23], [1, 1.01, 12]], "batl": NaN}, {"timestamp": 1631550729196, "ltp": 1.65, "tv": 1.4, "trd": NaN, "batb": [[0, 1.01, 12], [1, 1.01, 0]], "batl": NaN}, {"timestamp": 1631550734134, "ltp": 1.65, "tv": 1.4, "trd": NaN, "batb": [[0, 1.28, 107.14], [1, 1.01, 12]], "batl": NaN}, {"timestamp": 1631550768569, "ltp": 1.65, "tv": 1.4, "trd": NaN, "batb": [[0, 1.01, 12], [1, 1.01, 0]], "batl": NaN}, {"timestamp": 1631550773461, "ltp": 1.65, "tv": 1.4, "trd": NaN, "batb": [[0, 1.27, 111.11], [1, 1.01, 12]], "batl": NaN}, {"timestamp": 1631550807026, "ltp": 1.65, "tv": 1.4, "trd": NaN, "batb": [[0, 1.01, 12], [1, 1.01, 0]], "batl": NaN}, {"timestamp": 1631550812055, "ltp": 1.65, "tv": 1.4, "trd": NaN, "batb": [[0, 1.31, 96.77], [1, 1.01, 12]], "batl": NaN}, {"timestamp": 1631550837704, "ltp": 1.65, "tv": 1.4, "trd": NaN, "batb": [[0, 1.01, 12], [1, 1.01, 0]], "batl": NaN}, {"timestamp": 1631550842600, "ltp": 1.65, "tv": 1.4, "trd": NaN, "batb": [[0, 1.27, 111.11], [1, 1.01, 12]], "batl": NaN}, {"timestamp": 1631550872660, "ltp": 1.65, "tv": 1.4, "trd": NaN, "batb": [[0, 1.01, 12], [1, 1.01, 0]], "batl": NaN}, {"timestamp": 1631550877566, "ltp": 1.65, "tv": 1.4, "trd": NaN, "batb": [[0, 1.31, 96.77], [1, 1.01, 12]], "batl": NaN}, {"timestamp": 1631550900894, "ltp": 1.65, "tv": 1.4, "trd": NaN, "batb": [[0, 1.01, 12], [1, 1.01, 0]], "batl": NaN}, {"timestamp": 1631550905840, "ltp": 1.65, "tv": 1.4, "trd": NaN, "batb": [[0, 1.34, 88.23], [1, 1.01, 12]], "batl": NaN}, {"timestamp": 1631550925726, "ltp": 1.65, "tv": 1.4, "trd": NaN, "batb": [[0, 1.01, 12], [1, 1.01, 0]], "batl": NaN}, {"timestamp": 1631550930676, "ltp": 1.65, "tv": 1.4, "trd": NaN, "batb": [[0, 1.38, 78.94], [1, 1.01, 12]], "batl": NaN}, {"timestamp": 1631551094778, "ltp": 1.65, "tv": 1.4, "trd": NaN, "batb": [[0, 1.01, 12], [1, 1.01, 0]], "batl": NaN}, {"timestamp": 1631551099686, "ltp": 1.65, "tv": 1.4, "trd": NaN, "batb": [[0, 1.34, 88.23], [1, 1.01, 12]], "batl": NaN}, {"timestamp": 1631551158590, "ltp": 1.65, "tv": 1.4, "trd": NaN, "batb": [[0, 1.01, 12], [1, 1.01, 0]], "batl": NaN}, {"timestamp": 1631551163409, "ltp": 1.65, "tv": 1.4, "trd": NaN, "batb": [[0, 1.31, 96.77], [1, 1.01, 12]], "batl": NaN}, {"timestamp": 1631551209288, "ltp": 1.65, "tv": 1.4, "trd": NaN, "batb": [[0, 1.01, 12], [1, 1.01, 0]], "batl": NaN}, {"timestamp": 1631551214297, "ltp": 1.65, "tv": 1.4, "trd": NaN, "batb": [[0, 1.28, 107.14], [1, 1.01, 12]], "batl": NaN}, {"timestamp": 1631551232712, "ltp": 1.65, "tv": 1.4, "trd": NaN, "batb": [[0, 1.01, 12], [1, 1.01, 0]], "batl": NaN}, {"timestamp": 1631551237602, "ltp": 1.65, "tv": 1.4, "trd": NaN, "batb": [[0, 1.27, 111.11], [1, 1.01, 12]], "batl": NaN}, {"timestamp": 1631551291134, "ltp": 1.65, "tv": 1.4, "trd": NaN, "batb": [[0, 1.01, 12], [1, 1.01, 0]], "batl": NaN}, {"timestamp": 1631551296101, "ltp": 1.65, "tv": 1.4, "trd": NaN, "batb": [[0, 1.28, 107.14], [1, 1.01, 12]], "batl": NaN}, {"timestamp": 1631551317024, "ltp": 1.65, "tv": 1.4, "trd": NaN, "batb": [[0, 1.01, 12], [1, 1.01, 0]], "batl": NaN}, {"timestamp": 1631551322067, "ltp": 1.65, "tv": 1.4, "trd": NaN, "batb": [[0, 1.31, 96.77], [1, 1.01, 12]], "batl": NaN}, {"timestamp": 1631551363236, "ltp": 1.65, "tv": 1.4, "trd": NaN, "batb": [[0, 1.01, 12], [1, 1.01, 0]], "batl": NaN}, {"timestamp": 1631551368117, "ltp": 1.65, "tv": 1.4, "trd": NaN, "batb": [[0, 1.28, 107.14], [1, 1.01, 12]], "batl": NaN}, {"timestamp": 1631551377751, "ltp": 1.65, "tv": 1.4, "trd": NaN, "batb": [[0, 1.01, 12], [1, 1.01, 0]], "batl": NaN}, {"timestamp": 1631551382649, "ltp": 1.65, "tv": 1.4, "trd": NaN, "batb": [[0, 1.34, 88.23], [1, 1.01, 12]], "batl": NaN}, {"timestamp": 1631551401078, "ltp": 1.65, "tv": 1.4, "trd": NaN, "batb": [[0, 1.01, 12], [1, 1.01, 0]], "batl": NaN}, {"timestamp": 1631551405914, "ltp": 1.65, "tv": 1.4, "trd": NaN, "batb": [[0, 1.38, 78.94], [1, 1.01, 12]], "batl": NaN}, {"timestamp": 1631551522099, "ltp": 1.65, "tv": 1.4, "trd": NaN, "batb": [[0, 1.01, 12], [1, 1.01, 0]], "batl": NaN}, {"timestamp": 1631551527036, "ltp": 1.65, "tv": 1.4, "trd": NaN, "batb": [[0, 1.34, 88.23], [1, 1.01, 12]], "batl": NaN}, {"timestamp": 1631551540434, "ltp": 1.34, "tv": 4.81, "trd": [[1.34, 3.42]], "batb": [[0, 1.01, 12], [1, 1.01, 0]], "batl": NaN}, {"timestamp": 1631551545333, "ltp": 1.34, "tv": 4.81, "trd": NaN, "batb": [[0, 1.34, 88.23], [1, 1.01, 12]], "batl": NaN}, {"timestamp": 1631551570207, "ltp": 1.34, "tv": 4.81, "trd": NaN, "batb": [[0, 1.01, 12], [1, 1.01, 0]], "batl": NaN}, {"timestamp": 1631551575225, "ltp": 1.34, "tv": 4.81, "trd": NaN, "batb": [[0, 1.38, 78.94], [1, 1.01, 12]], "batl": NaN}, {"timestamp": 1631551602542, "ltp": 1.34, "tv": 4.81, "trd": NaN, "batb": [[0, 1.01, 12], [1, 1.01, 0]], "batl": NaN}, {"timestamp": 1631551607362, "ltp": 1.34, "tv": 4.81, "trd": NaN, "batb": [[0, 1.34, 88.23], [1, 1.01, 12]], "batl": NaN}, {"timestamp": 1631551622393, "ltp": 1.34, "tv": 4.81, "trd": NaN, "batb": [[0, 1.01, 12], [1, 1.01, 0]], "batl": NaN}, {"timestamp": 1631551627318, "ltp": 1.34, "tv": 4.81, "trd": NaN, "batb": [[0, 1.27, 111.11], [1, 1.01, 12]], "batl": NaN}, {"timestamp": 1631551643140, "ltp": 1.34, "tv": 4.81, "trd": NaN, "batb": [[0, 1.01, 12], [1, 1.01, 0]], "batl": NaN}, {"timestamp": 1631551648034, "ltp": 1.34, "tv": 4.81, "trd": NaN, "batb": [[0, 1.23, 130.43], [1, 1.01, 12]], "batl": NaN}, {"timestamp": 1631551692500, "ltp": 1.34, "tv": 4.81, "trd": NaN, "batb": [[0, 1.01, 12], [1, 1.01, 0]], "batl": NaN}, {"timestamp": 1631551697392, "ltp": 1.34, "tv": 4.81, "trd": NaN, "batb": [[0, 1.27, 111.11], [1, 1.01, 12]], "batl": NaN}, {"timestamp": 1631551719059, "ltp": 1.34, "tv": 4.81, "trd": NaN, "batb": [[0, 1.01, 12], [1, 1.01, 0]], "batl": NaN}, {"timestamp": 1631551724068, "ltp": 1.34, "tv": 4.81, "trd": NaN, "batb": [[0, 1.28, 107.14], [1, 1.01, 12]], "batl": NaN}, {"timestamp": 1631551747196, "ltp": 1.34, "tv": 4.81, "trd": NaN, "batb": [[0, 1.01, 12], [1, 1.01, 0]], "batl": NaN}, {"timestamp": 1631551752120, "ltp": 1.34, "tv": 4.81, "trd": NaN, "batb": [[0, 1.27, 111.11], [1, 1.01, 12]], "batl": NaN}, {"timestamp": 1631551769121, "ltp": 1.34, "tv": 4.81, "trd": NaN, "batb": [[0, 1.01, 12], [1, 1.01, 0]], "batl": NaN}, {"timestamp": 1631551774112, "ltp": 1.34, "tv": 4.81, "trd": NaN, "batb": [[0, 1.23, 130.43], [1, 1.01, 12]], "batl": NaN}, {"timestamp": 1631551812870, "ltp": 1.34, "tv": 4.81, "trd": NaN, "batb": [[0, 1.01, 12], [1, 1.01, 0]], "batl": NaN}, {"timestamp": 1631551817776, "ltp": 1.34, "tv": 4.81, "trd": NaN, "batb": [[0, 1.18, 166.66], [1, 1.01, 12]], "batl": NaN}, {"timestamp": 1631551853061, "ltp": 1.34, "tv": 4.81, "trd": NaN, "batb": [[0, 1.01, 12], [1, 1.01, 0]], "batl": NaN}, {"timestamp": 1631551857950, "ltp": 1.34, "tv": 4.81, "trd": NaN, "batb": [[0, 1.15, 200], [1, 1.01, 12]], "batl": NaN}, {"timestamp": 1631551909427, "ltp": 1.15, "tv": 8.81, "trd": [[1.15, 4]], "batb": [[0, 1.15, 198]], "batl": NaN}, {"timestamp": 1631551909632, "ltp": 1.15, "tv": 8.81, "trd": NaN, "batb": [[0, 1.01, 12], [1, 1.01, 0]], "batl": NaN}, {"timestamp": 1631551914646, "ltp": 1.15, "tv": 8.81, "trd": NaN, "batb": [[0, 1.15, 200], [1, 1.01, 12]], "batl": NaN}, {"timestamp": 1631551998663, "ltp": 1.15, "tv": 8.81, "trd": NaN, "batb": [[0, 1.01, 12], [1, 1.01, 0]], "batl": NaN}, {"timestamp": 1631552003555, "ltp": 1.15, "tv": 8.81, "trd": NaN, "batb": [[0, 1.12, 249.99], [1, 1.01, 12]], "batl": NaN}, {"timestamp": 1631552032881, "ltp": 1.15, "tv": 8.81, "trd": NaN, "batb": [[0, 1.01, 12], [1, 1.01, 0]], "batl": NaN}, {"timestamp": 1631552037783, "ltp": 1.15, "tv": 8.81, "trd": NaN, "batb": [[0, 1.15, 200], [1, 1.01, 12]], "batl": NaN}, {"timestamp": 1631552071449, "ltp": 1.15, "tv": 8.81, "trd": NaN, "batb": [[0, 1.01, 12], [1, 1.01, 0]], "batl": NaN}, {"timestamp": 1631552076351, "ltp": 1.15, "tv": 8.81, "trd": NaN, "batb": [[0, 1.18, 166.66], [1, 1.01, 12]], "batl": NaN}, {"timestamp": 1631552142135, "ltp": 1.15, "tv": 8.81, "trd": NaN, "batb": [[0, 1.01, 12], [1, 1.01, 0]], "batl": NaN}, {"timestamp": 1631552147140, "ltp": 1.15, "tv": 8.81, "trd": NaN, "batb": [[0, 1.2, 150], [1, 1.01, 12]], "batl": NaN}, {"timestamp": 1631552177980, "ltp": 1.15, "tv": 8.81, "trd": NaN, "batb": [[0, 1.01, 12], [1, 1.01, 0]], "batl": NaN}, {"timestamp": 1631552182988, "ltp": 1.15, "tv": 8.81, "trd": NaN, "batb": [[0, 1.23, 130.43], [1, 1.01, 12]], "batl": NaN}, {"timestamp": 1631552199131, "ltp": 1.15, "tv": 8.81, "trd": NaN, "batb": [[0, 1.01, 12], [1, 1.01, 0]], "batl": NaN}, {"timestamp": 1631552204033, "ltp": 1.15, "tv": 8.81, "trd": NaN, "batb": [[0, 1.2, 150], [1, 1.01, 12]], "batl": NaN}, {"timestamp": 1631552223553, "ltp": 1.15, "tv": 8.81, "trd": NaN, "batb": [[0, 1.01, 12], [1, 1.01, 0]], "batl": NaN}, {"timestamp": 1631552228450, "ltp": 1.15, "tv": 8.81, "trd": NaN, "batb": [[0, 1.23, 130.43], [1, 1.01, 12]], "batl": NaN}, {"timestamp": 1631552245388, "ltp": 1.15, "tv": 8.81, "trd": NaN, "batb": [[0, 1.01, 12], [1, 1.01, 0]], "batl": NaN}, {"timestamp": 1631552250390, "ltp": 1.15, "tv": 8.81, "trd": NaN, "batb": [[0, 1.27, 111.11], [1, 1.01, 12]], "batl": NaN}, {"timestamp": 1631552279410, "ltp": 1.15, "tv": 8.81, "trd": NaN, "batb": [[0, 1.01, 12], [1, 1.01, 0]], "batl": NaN}, {"timestamp": 1631552284422, "ltp": 1.15, "tv": 8.81, "trd": NaN, "batb": [[0, 1.23, 130.43], [1, 1.01, 12]], "batl": NaN}, {"timestamp": 1631552303932, "ltp": 1.15, "tv": 8.81, "trd": NaN, "batb": [[0, 1.01, 12], [1, 1.01, 0]], "batl": NaN}, {"timestamp": 1631552308944, "ltp": 1.15, "tv": 8.81, "trd": NaN, "batb": [[0, 1.28, 107.14], [1, 1.01, 12]], "batl": NaN}, {"timestamp": 1631552340908, "ltp": 1.28, "tv": 26.78, "trd": [[1.28, 17.97]], "batb": [[0, 1.01, 12], [1, 1.01, 0]], "batl": NaN}, {"timestamp": 1631552345806, "ltp": 1.28, "tv": 26.78, "trd": NaN, "batb": [[0, 1.28, 107.14], [1, 1.01, 12]], "batl": NaN}, {"timestamp": 1631552456037, "ltp": 1.28, "tv": 26.78, "trd": [[1.34, 3.42], [1.65, 1.4]], "batb": [[0, 1.01, 12], [1, 1.01, 0]], "batl": NaN}, {"timestamp": 1631552461041, "ltp": 1.28, "tv": 26.78, "trd": NaN, "batb": [[0, 1.38, 78.94], [1, 1.01, 12]], "batl": NaN}, {"timestamp": 1631552497872, "ltp": 1.28, "tv": 26.78, "trd": NaN, "batb": [[0, 1.01, 12], [1, 1.01, 0]], "batl": NaN}, {"timestamp": 1631552502791, "ltp": 1.28, "tv": 26.78, "trd": NaN, "batb": [[0, 1.48, 62.5], [1, 1.01, 12]], "batl": NaN}, {"timestamp": 1631552523836, "ltp": 1.28, "tv": 26.78, "trd": NaN, "batb": [[0, 1.01, 12], [1, 1.01, 0]], "batl": NaN}, {"timestamp": 1631552528729, "ltp": 1.28, "tv": 26.78, "trd": NaN, "batb": [[0, 1.6, 49.99], [1, 1.01, 12]], "batl": NaN}, {"timestamp": 1631552558288, "ltp": 1.28, "tv": 26.78, "trd": NaN, "batb": [[0, 1.01, 12], [1, 1.01, 0]], "batl": NaN}, {"timestamp": 1631552563278, "ltp": 1.28, "tv": 26.78, "trd": NaN, "batb": [[0, 1.51, 58.82], [1, 1.01, 12]], "batl": NaN}, {"timestamp": 1631552584913, "ltp": 1.28, "tv": 26.78, "trd": NaN, "batb": [[0, 1.01, 12], [1, 1.01, 0]], "batl": NaN}, {"timestamp": 1631552589938, "ltp": 1.28, "tv": 26.78, "trd": NaN, "batb": [[0, 1.65, 46.15], [1, 1.01, 12]], "batl": NaN}, {"timestamp": 1631552591820, "ltp": 1.65, "tv": 27.0, "trd": [[1.65, 1.62]], "batb": [[0, 1.01, 12], [1, 1.01, 0]], "batl": NaN}, {"timestamp": 1631552596870, "ltp": 1.65, "tv": 27.0, "trd": NaN, "batb": [[0, 1.65, 46.15], [1, 1.01, 12]], "batl": NaN}, {"timestamp": 1631552621777, "ltp": 1.65, "tv": 27.0, "trd": NaN, "batb": [[0, 1.01, 12], [1, 1.01, 0]], "batl": NaN}, {"timestamp": 1631552626760, "ltp": 1.65, "tv": 27.0, "trd": NaN, "batb": [[0, 1.55, 54.54], [1, 1.01, 12]], "batl": NaN}, {"timestamp": 1631552640996, "ltp": 1.65, "tv": 27.0, "trd": NaN, "batb": [[0, 1.01, 12], [1, 1.01, 0]], "batl": NaN}, {"timestamp": 1631552645883, "ltp": 1.65, "tv": 27.0, "trd": NaN, "batb": [[0, 1.51, 58.82], [1, 1.01, 12]], "batl": NaN}, {"timestamp": 1631552657286, "ltp": 1.65, "tv": 27.0, "trd": NaN, "batb": [[0, 1.01, 12], [1, 1.01, 0]], "batl": NaN}, {"timestamp": 1631552662285, "ltp": 1.65, "tv": 27.0, "trd": NaN, "batb": [[0, 1.42, 71.42], [1, 1.01, 12]], "batl": NaN}, {"timestamp": 1631552678844, "ltp": 1.65, "tv": 27.0, "trd": NaN, "batb": [[0, 1.01, 12], [1, 1.01, 0]], "batl": NaN}, {"timestamp": 1631552683821, "ltp": 1.65, "tv": 27.0, "trd": NaN, "batb": [[0, 1.51, 58.82], [1, 1.01, 12]], "batl": NaN}, {"timestamp": 1631552745413, "ltp": 1.65, "tv": 27.0, "trd": NaN, "batb": [[0, 1.01, 12], [1, 1.01, 0]], "batl": NaN}, {"timestamp": 1631552750317, "ltp": 1.65, "tv": 27.0, "trd": NaN, "batb": [[0, 1.63, 47.61], [1, 1.01, 12]], "batl": NaN}, {"timestamp": 1631552765422, "ltp": 1.65, "tv": 27.0, "trd": NaN, "batb": [[0, 1.01, 12], [1, 1.01, 0]], "batl": NaN}, {"timestamp": 1631552770455, "ltp": 1.65, "tv": 27.0, "trd": NaN, "batb": [[0, 1.48, 62.5], [1, 1.01, 12]], "batl": NaN}, {"timestamp": 1631552785833, "ltp": 1.65, "tv": 27.0, "trd": NaN, "batb": [[0, 1.01, 12], [1, 1.01, 0]], "batl": NaN}, {"timestamp": 1631552790887, "ltp": 1.65, "tv": 27.0, "trd": NaN, "batb": [[0, 1.34, 88.23], [1, 1.01, 12]], "batl": NaN}, {"timestamp": 1631552889185, "ltp": 1.65, "tv": 27.0, "trd": NaN, "batb": [[0, 1.01, 12], [1, 1.01, 0]], "batl": NaN}, {"timestamp": 1631552894200, "ltp": 1.65, "tv": 27.0, "trd": NaN, "batb": [[0, 1.27, 111.11], [1, 1.01, 12]], "batl": NaN}, {"timestamp": 1631552924434, "ltp": 1.65, "tv": 27.0, "trd": NaN, "batb": [[0, 1.01, 12], [1, 1.01, 0]], "batl": NaN}, {"timestamp": 1631552929335, "ltp": 1.65, "tv": 27.0, "trd": NaN, "batb": [[0, 1.2, 150], [1, 1.01, 12]], "batl": NaN}, {"timestamp": 1631552967279, "ltp": 1.65, "tv": 27.0, "trd": NaN, "batb": [[0, 1.01, 12], [1, 1.01, 0]], "batl": NaN}, {"timestamp": 1631552972320, "ltp": 1.65, "tv": 27.0, "trd": NaN, "batb": [[0, 1.27, 111.11], [1, 1.01, 12]], "batl": NaN}, {"timestamp": 1631553005591, "ltp": 1.65, "tv": 27.0, "trd": NaN, "batb": [[0, 1.01, 12], [1, 1.01, 0]], "batl": NaN}, {"timestamp": 1631553010447, "ltp": 1.65, "tv": 27.0, "trd": NaN, "batb": [[0, 1.34, 88.23], [1, 1.01, 12]], "batl": NaN}, {"timestamp": 1631553076556, "ltp": 1.65, "tv": 27.0, "trd": NaN, "batb": [[0, 1.01, 12], [1, 1.01, 0]], "batl": NaN}, {"timestamp": 1631553081539, "ltp": 1.65, "tv": 27.0, "trd": NaN, "batb": [[0, 1.48, 62.5], [1, 1.01, 12]], "batl": NaN}, {"timestamp": 1631553142589, "ltp": 1.65, "tv": 27.0, "trd": NaN, "batb": [[0, 1.01, 12], [1, 1.01, 0]], "batl": NaN}, {"timestamp": 1631553147485, "ltp": 1.65, "tv": 27.0, "trd": NaN, "batb": [[0, 1.34, 88.23], [1, 1.01, 12]], "batl": NaN}, {"timestamp": 1631553203899, "ltp": 1.65, "tv": 27.0, "trd": NaN, "batb": [[0, 1.01, 12], [1, 1.01, 0]], "batl": NaN}, {"timestamp": 1631553208884, "ltp": 1.65, "tv": 27.0, "trd": NaN, "batb": [[0, 1.27, 111.11], [1, 1.01, 12]], "batl": NaN}, {"timestamp": 1631553255593, "ltp": 1.65, "tv": 27.0, "trd": NaN, "batb": [[0, 1.01, 12], [1, 1.01, 0]], "batl": NaN}, {"timestamp": 1631553260564, "ltp": 1.65, "tv": 27.0, "trd": NaN, "batb": [[0, 1.34, 88.23], [1, 1.01, 12]], "batl": NaN}, {"timestamp": 1631553297236, "ltp": 1.65, "tv": 27.0, "trd": NaN, "batb": [[0, 1.01, 12], [1, 1.01, 0]], "batl": NaN}, {"timestamp": 1631553302125, "ltp": 1.65, "tv": 27.0, "trd": NaN, "batb": [[0, 1.27, 111.11], [1, 1.01, 12]], "batl": NaN}, {"timestamp": 1631553361002, "ltp": 1.65, "tv": 27.0, "trd": NaN, "batb": [[0, 1.01, 12], [1, 1.01, 0]], "batl": NaN}, {"timestamp": 1631553366085, "ltp": 1.65, "tv": 27.0, "trd": NaN, "batb": [[0, 1.34, 88.23], [1, 1.01, 12]], "batl": NaN}, {"timestamp": 1631553413454, "ltp": 1.65, "tv": 27.0, "trd": NaN, "batb": [[0, 1.01, 12], [1, 1.01, 0]], "batl": NaN}, {"timestamp": 1631553418341, "ltp": 1.65, "tv": 27.0, "trd": NaN, "batb": [[0, 1.27, 111.11], [1, 1.01, 12]], "batl": NaN}, {"timestamp": 1631553496431, "ltp": 1.65, "tv": 27.0, "trd": NaN, "batb": [[0, 1.01, 12], [1, 1.01, 0]], "batl": NaN}, {"timestamp": 1631553501333, "ltp": 1.65, "tv": 27.0, "trd": NaN, "batb": [[0, 1.34, 88.23], [1, 1.01, 12]], "batl": NaN}, {"timestamp": 1631553555512, "ltp": 1.65, "tv": 27.0, "trd": NaN, "batb": [[0, 1.01, 12], [1, 1.01, 0]], "batl": NaN}, {"timestamp": 1631553560505, "ltp": 1.65, "tv": 27.0, "trd": NaN, "batb": [[0, 1.27, 111.11], [1, 1.01, 12]], "batl": NaN}, {"timestamp": 1631553595645, "ltp": 1.65, "tv": 27.0, "trd": NaN, "batb": [[0, 1.01, 12], [1, 1.01, 0]], "batl": NaN}, {"timestamp": 1631553600565, "ltp": 1.65, "tv": 27.0, "trd": NaN, "batb": [[0, 1.18, 166.66], [1, 1.01, 12]], "batl": NaN}, {"timestamp": 1631553816324, "ltp": 1.18, "tv": 33.0, "trd": [[1.18, 6]], "batb": [[0, 1.01, 12], [1, 1.01, 0]], "batl": NaN}, {"timestamp": 1631553821352, "ltp": 1.18, "tv": 33.0, "trd": NaN, "batb": [[0, 1.18, 166.66], [1, 1.01, 12]], "batl": NaN}, {"timestamp": 1631553954213, "ltp": 1.18, "tv": 33.0, "trd": NaN, "batb": [[0, 1.01, 12], [1, 1.01, 0]], "batl": NaN}, {"timestamp": 1631553959205, "ltp": 1.18, "tv": 33.0, "trd": NaN, "batb": [[0, 1.2, 150], [1, 1.01, 12]], "batl": NaN}, {"timestamp": 1631553982447, "ltp": 1.18, "tv": 33.0, "trd": NaN, "batb": [[0, 1.01, 12], [1, 1.01, 0]], "batl": NaN}, {"timestamp": 1631553987351, "ltp": 1.18, "tv": 33.0, "trd": NaN, "batb": [[0, 1.18, 166.66], [1, 1.01, 12]], "batl": NaN}, {"timestamp": 1631554002094, "ltp": 1.18, "tv": 33.0, "trd": NaN, "batb": [[0, 1.01, 12], [1, 1.01, 0]], "batl": NaN}, {"timestamp": 1631554006985, "ltp": 1.18, "tv": 33.0, "trd": NaN, "batb": [[0, 1.15, 200], [1, 1.01, 12]], "batl": NaN}, {"timestamp": 1631554018396, "ltp": 1.18, "tv": 33.0, "trd": NaN, "batb": [[0, 1.01, 12], [1, 1.01, 0]], "batl": NaN}, {"timestamp": 1631554023290, "ltp": 1.18, "tv": 33.0, "trd": NaN, "batb": [[0, 1.18, 166.66], [1, 1.01, 12]], "batl": NaN}, {"timestamp": 1631554045528, "ltp": 1.18, "tv": 33.0, "trd": NaN, "batb": [[0, 1.01, 12], [1, 1.01, 0]], "batl": NaN}, {"timestamp": 1631554050419, "ltp": 1.18, "tv": 33.0, "trd": NaN, "batb": [[0, 1.2, 150], [1, 1.01, 12]], "batl": NaN}, {"timestamp": 1631554076678, "ltp": 1.18, "tv": 33.0, "trd": NaN, "batb": [[0, 1.01, 12], [1, 1.01, 0]], "batl": NaN}, {"timestamp": 1631554081694, "ltp": 1.18, "tv": 33.0, "trd": NaN, "batb": [[0, 1.18, 166.66], [1, 1.01, 12]], "batl": NaN}, {"timestamp": 1631554119796, "ltp": 1.18, "tv": 33.0, "trd": NaN, "batb": [[0, 1.01, 12], [1, 1.01, 0]], "batl": NaN}, {"timestamp": 1631554124732, "ltp": 1.18, "tv": 33.0, "trd": NaN, "batb": [[0, 1.2, 150], [1, 1.01, 12]], "batl": NaN}, {"timestamp": 1631554153830, "ltp": 1.18, "tv": 33.0, "trd": NaN, "batb": [[0, 1.01, 12], [1, 1.01, 0]], "batl": NaN}, {"timestamp": 1631554158754, "ltp": 1.18, "tv": 33.0, "trd": NaN, "batb": [[0, 1.18, 166.66], [1, 1.01, 12]], "batl": NaN}, {"timestamp": 1631554203318, "ltp": 1.18, "tv": 33.0, "trd": NaN, "batb": [[0, 1.01, 12], [1, 1.01, 0]], "batl": NaN}, {"timestamp": 1631554208343, "ltp": 1.18, "tv": 33.0, "trd": NaN, "batb": [[0, 1.12, 249.99], [1, 1.01, 12]], "batl": NaN}, {"timestamp": 1631554231926, "ltp": 1.18, "tv": 33.0, "trd": NaN, "batb": [[0, 1.01, 12], [1, 1.01, 0]], "batl": NaN}, {"timestamp": 1631554236869, "ltp": 1.18, "tv": 33.0, "trd": NaN, "batb": [[0, 1.11, 272.72], [1, 1.01, 12]], "batl": NaN}, {"timestamp": 1631554243249, "ltp": 1.18, "tv": 33.0, "trd": NaN, "batb": [[0, 1.01, 12], [1, 1.01, 0]], "batl": NaN}, {"timestamp": 1631554248277, "ltp": 1.18, "tv": 33.0, "trd": NaN, "batb": [[0, 1.18, 166.66], [1, 1.01, 12]], "batl": NaN}, {"timestamp": 1631554267587, "ltp": 1.18, "tv": 33.0, "trd": NaN, "batb": [[0, 1.01, 12], [1, 1.01, 0]], "batl": NaN}, {"timestamp": 1631554272472, "ltp": 1.18, "tv": 33.0, "trd": NaN, "batb": [[0, 1.15, 200], [1, 1.01, 12]], "batl": NaN}, {"timestamp": 1631554285895, "ltp": 1.18, "tv": 33.0, "trd": NaN, "batb": [[0, 1.01, 12], [1, 1.01, 0]], "batl": NaN}, {"timestamp": 1631554290935, "ltp": 1.18, "tv": 33.0, "trd": NaN, "batb": [[0, 1.12, 249.99], [1, 1.01, 12]], "batl": NaN}, {"timestamp": 1631554305341, "ltp": 1.18, "tv": 33.0, "trd": NaN, "batb": [[0, 1.01, 12], [1, 1.01, 0]], "batl": NaN}, {"timestamp": 1631554310329, "ltp": 1.18, "tv": 33.0, "trd": NaN, "batb": [[0, 1.11, 272.72], [1, 1.01, 12]], "batl": NaN}, {"timestamp": 1631554316175, "ltp": 1.18, "tv": 33.0, "trd": NaN, "batb": [[0, 1.01, 12], [1, 1.01, 0]], "batl": NaN}, {"timestamp": 1631554321140, "ltp": 1.18, "tv": 33.0, "trd": NaN, "batb": [[0, 1.08, 374.99], [1, 1.01, 12]], "batl": NaN}, {"timestamp": 1631554402281, "ltp": 1.18, "tv": 33.0, "trd": NaN, "batb": [[0, 1.01, 12], [1, 1.01, 0]], "batl": NaN}, {"timestamp": 1631554407185, "ltp": 1.18, "tv": 33.0, "trd": NaN, "batb": [[0, 1.05, 599.99], [1, 1.01, 12]], "batl": NaN}, {"timestamp": 1631554429215, "ltp": 1.18, "tv": 33.0, "trd": NaN, "batb": [[0, 1.01, 12], [1, 1.01, 0]], "batl": NaN}, {"timestamp": 1631554434117, "ltp": 1.18, "tv": 33.0, "trd": NaN, "batb": [[0, 1.08, 374.99], [1, 1.01, 12]], "batl": NaN}, {"timestamp": 1631554469658, "ltp": 1.18, "tv": 33.0, "trd": NaN, "batb": [[0, 1.01, 12], [1, 1.01, 0]], "batl": NaN}, {"timestamp": 1631554474643, "ltp": 1.18, "tv": 33.0, "trd": NaN, "batb": [[0, 1.05, 599.99], [1, 1.01, 12]], "batl": NaN}, {"timestamp": 1631554534843, "ltp": 1.18, "tv": 33.0, "trd": NaN, "batb": [[0, 1.01, 12], [1, 1.01, 0]], "batl": NaN}, {"timestamp": 1631554539894, "ltp": 1.18, "tv": 33.0, "trd": NaN, "batb": [[0, 1.08, 374.99], [1, 1.01, 12]], "batl": NaN}, {"timestamp": 1631554575699, "ltp": 1.18, "tv": 33.0, "trd": NaN, "batb": [[0, 1.01, 12], [1, 1.01, 0]], "batl": NaN}, {"timestamp": 1631554580687, "ltp": 1.18, "tv": 33.0, "trd": NaN, "batb": [[0, 1.05, 599.99], [1, 1.01, 12]], "batl": NaN}, {"timestamp": 1631554597307, "ltp": 1.18, "tv": 33.0, "trd": NaN, "batb": [[0, 1.07, 84.27], [1, 1.05, 599.99], [2, 1.01, 12]], "batl": NaN}, {"timestamp": 1631554598310, "ltp": 1.18, "tv": 33.0, "trd": NaN, "batb": [[1, 1.06, 56.18], [2, 1.05, 599.99]], "batl": NaN}, {"timestamp": 1631554599485, "ltp": 1.18, "tv": 33.0, "trd": NaN, "batb": [[0, 1.07, 112.36], [1, 1.06, 168.54]], "batl": NaN}, {"timestamp": 1631554600280, "ltp": 1.18, "tv": 33.0, "trd": NaN, "batb": [[1, 1.06, 252.81]], "batl": NaN}, {"timestamp": 1631554601111, "ltp": 1.18, "tv": 33.0, "trd": NaN, "batb": [[1, 1.06, 337.08]], "batl": NaN}, {"timestamp": 1631554616429, "ltp": 1.18, "tv": 33.0, "trd": NaN, "batb": [[2, 1.01, 12]], "batl": NaN}, {"timestamp": 1631554620344, "ltp": 1.18, "tv": 33.0, "trd": NaN, "batb": [[0, 1.06, 337.08], [1, 1.01, 12], [2, 1.01, 0]], "batl": NaN}, {"timestamp": 1631554621405, "ltp": 1.18, "tv": 33.0, "trd": NaN, "batb": [[0, 1.03, 999.99]], "batl": NaN}, {"timestamp": 1631554627211, "ltp": 1.18, "tv": 33.0, "trd": NaN, "batb": [[0, 1.05, 112.36], [1, 1.03, 999.99], [2, 1.01, 12]], "batl": NaN}, {"timestamp": 1631554628417, "ltp": 1.18, "tv": 33.0, "trd": NaN, "batb": [[0, 1.05, 224.72]], "batl": NaN}, {"timestamp": 1631554629213, "ltp": 1.18, "tv": 33.0, "trd": NaN, "batb": [[0, 1.05, 365.17]], "batl": NaN}, {"timestamp": 1631554629742, "ltp": 1.18, "tv": 33.0, "trd": NaN, "batb": [[0, 1.05, 393.26]], "batl": NaN}, {"timestamp": 1631554655039, "ltp": 1.18, "tv": 33.0, "trd": NaN, "batb": [[1, 1.01, 12], [2, 1.01, 0]], "batl": NaN}, {"timestamp": 1631554659956, "ltp": 1.18, "tv": 33.0, "trd": NaN, "batb": [[0, 1.05, 993.25]], "batl": NaN}, {"timestamp": 1631554676266, "ltp": 1.18, "tv": 33.0, "trd": NaN, "batb": [[0, 1.05, 393.26]], "batl": NaN}, {"timestamp": 1631554681280, "ltp": 1.18, "tv": 33.0, "trd": NaN, "batb": [[1, 1.03, 999.99], [2, 1.01, 12]], "batl": NaN}, {"timestamp": 1631554704635, "ltp": 1.18, "tv": 33.0, "trd": NaN, "batb": [[1, 1.01, 12], [2, 1.01, 0]], "batl": NaN}, {"timestamp": 1631554709626, "ltp": 1.18, "tv": 33.0, "trd": NaN, "batb": [[0, 1.05, 993.25]], "batl": NaN}, {"timestamp": 1631554738770, "ltp": 1.18, "tv": 33.0, "trd": NaN, "batb": [[0, 1.05, 393.26]], "batl": NaN}, {"timestamp": 1631554743651, "ltp": 1.18, "tv": 33.0, "trd": NaN, "batb": [[0, 1.06, 499.99], [1, 1.05, 393.26], [2, 1.01, 12]], "batl": NaN}, {"timestamp": 1631554753684, "ltp": 1.18, "tv": 33.0, "trd": NaN, "batb": [[1, 1.01, 12], [2, 1.01, 0]], "batl": NaN}, {"timestamp": 1631554769489, "ltp": 1.18, "tv": 33.0, "trd": NaN, "batb": [[0, 1.01, 12], [1, 1.01, 0]], "batl": NaN}, {"timestamp": 1631554774515, "ltp": 1.18, "tv": 33.0, "trd": NaN, "batb": [[0, 1.08, 374.99], [1, 1.01, 12]], "batl": NaN}, {"timestamp": 1631554890482, "ltp": 1.18, "tv": 33.0, "trd": NaN, "batb": [[0, 1.01, 12], [1, 1.01, 0]], "batl": NaN}, {"timestamp": 1631554895477, "ltp": 1.18, "tv": 33.0, "trd": NaN, "batb": [[0, 1.05, 599.99], [1, 1.01, 12]], "batl": NaN}, {"timestamp": 1631554959187, "ltp": 1.18, "tv": 33.0, "trd": NaN, "batb": [[0, 1.01, 12], [1, 1.01, 0]], "batl": NaN}, {"timestamp": 1631554964170, "ltp": 1.18, "tv": 33.0, "trd": NaN, "batb": [[0, 1.08, 374.99], [1, 1.01, 12]], "batl": NaN}, {"timestamp": 1631555006345, "ltp": 1.18, "tv": 33.0, "trd": NaN, "batb": [[0, 1.01, 12], [1, 1.01, 0]], "batl": NaN}, {"timestamp": 1631555011289, "ltp": 1.18, "tv": 33.0, "trd": NaN, "batb": [[0, 1.05, 599.99], [1, 1.01, 12]], "batl": NaN}, {"timestamp": 1631555040790, "ltp": 1.18, "tv": 33.0, "trd": NaN, "batb": [[0, 1.01, 12], [1, 1.01, 0]], "batl": NaN}, {"timestamp": 1631555045760, "ltp": 1.18, "tv": 33.0, "trd": NaN, "batb": [[0, 1.04, 749.99], [1, 1.01, 12]], "batl": NaN}, {"timestamp": 1631555092369, "ltp": 1.18, "tv": 33.0, "trd": NaN, "batb": [[0, 1.01, 12], [1, 1.01, 0]], "batl": NaN}, {"timestamp": 1631555097251, "ltp": 1.18, "tv": 33.0, "trd": NaN, "batb": [[0, 1.05, 599.99], [1, 1.01, 12]], "batl": NaN}, {"timestamp": 1631555248232, "ltp": 1.18, "tv": 33.0, "trd": NaN, "batb": [[0, 1.01, 12], [1, 1.01, 0]], "batl": NaN}, {"timestamp": 1631555253292, "ltp": 1.18, "tv": 33.0, "trd": NaN, "batb": [[0, 1.08, 374.99], [1, 1.01, 12]], "batl": NaN}, {"timestamp": 1631555284677, "ltp": 1.18, "tv": 33.0, "trd": NaN, "batb": [[0, 1.01, 12], [1, 1.01, 0]], "batl": NaN}, {"timestamp": 1631555289697, "ltp": 1.18, "tv": 33.0, "trd": NaN, "batb": [[0, 1.05, 599.99], [1, 1.01, 12]], "batl": NaN}, {"timestamp": 1631555314959, "ltp": 1.18, "tv": 33.0, "trd": NaN, "batb": [[0, 1.01, 12], [1, 1.01, 0]], "batl": NaN}, {"timestamp": 1631555319845, "ltp": 1.18, "tv": 33.0, "trd": NaN, "batb": [[0, 1.03, 999.99], [1, 1.01, 12]], "batl": NaN}, {"timestamp": 1631555390908, "ltp": 1.18, "tv": 33.0, "trd": NaN, "batb": [[0, 1.01, 12], [1, 1.01, 0]], "batl": NaN}, {"timestamp": 1631555671254, "ltp": 1.01, "tv": 57.0, "trd": [[1.01, 24]], "batb": NaN, "batl": [[0, 1.01, 93], [1, 1.71, 0.52]]}, {"timestamp": 1631555710446, "ltp": 1.01, "tv": 243.0, "trd": [[1.01, 210]], "batb": [[0, 1.01, 19.36]], "batl": [[0, 1.71, 0.52], [1, 1.71, 0]]}, {"timestamp": 1631555710874, "ltp": 1.01, "tv": 243.0, "trd": NaN, "batb": [[0, 1.01, 47.45]], "batl": NaN}, {"timestamp": 1631555751001, "ltp": 1.01, "tv": 267.0, "trd": [[1.01, 234]], "batb": [[0, 1.01, 35.45]], "batl": NaN}, {"timestamp": 1631555769243, "ltp": 1.01, "tv": 267.0, "trd": NaN, "batb": [[0, 1.01, 175.9]], "batl": NaN}, {"timestamp": 1631555770036, "ltp": 1.01, "tv": 267.0, "trd": NaN, "batb": [[0, 1.01, 316.35]], "batl": NaN}, {"timestamp": 1631556085367, "ltp": 1.01, "tv": 267.0, "trd": NaN, "batb": [[0, 1.02, 1499.99]], "batl": NaN}, {"timestamp": 1631556100268, "ltp": 1.01, "tv": 267.0, "trd": NaN, "batb": [[0, 1.04, 108.16], [1, 1.02, 1499.99]], "batl": NaN}, {"timestamp": 1631556100640, "ltp": 1.01, "tv": 267.0, "trd": NaN, "batb": [[0, 1.04, 162.24]], "batl": NaN}, {"timestamp": 1631556105944, "ltp": 1.01, "tv": 267.0, "trd": NaN, "batb": [[0, 1.02, 1499.99], [1, 1.02, 0]], "batl": NaN}, {"timestamp": 1631556140637, "ltp": 1.01, "tv": 267.0, "trd": NaN, "batb": [[0, 1.04, 749.99]], "batl": NaN}, {"timestamp": 1631556169150, "ltp": 1.01, "tv": 267.0, "trd": NaN, "batb": [[0, 1.02, 1499.99]], "batl": NaN}]}, {"runnerId": 25977944, "odds": [{"timestamp": 1631550546815, "ltp": 2.54, "tv": 0.91, "trd": [[2.54, 0.91]], "batb": NaN, "batl": NaN}, {"timestamp": 1631550551728, "ltp": 2.54, "tv": 0.91, "trd": NaN, "batb": [[0, 2.58, 18.98], [1, 1.01, 12]], "batl": NaN}, {"timestamp": 1631550556968, "ltp": 2.54, "tv": 0.91, "trd": NaN, "batb": [[0, 1.01, 12], [1, 1.01, 0]], "batl": NaN}, {"timestamp": 1631550561978, "ltp": 2.54, "tv": 0.91, "trd": NaN, "batb": [[0, 2.42, 21.12], [1, 1.01, 12]], "batl": NaN}, {"timestamp": 1631550580391, "ltp": 2.54, "tv": 0.91, "trd": NaN, "batb": [[0, 1.01, 12], [1, 1.01, 0]], "batl": NaN}, {"timestamp": 1631550585288, "ltp": 2.54, "tv": 0.91, "trd": NaN, "batb": [[0, 2.58, 18.98], [1, 1.01, 12]], "batl": NaN}, {"timestamp": 1631550604827, "ltp": 2.54, "tv": 0.91, "trd": NaN, "batb": [[0, 1.01, 12], [1, 1.01, 0]], "batl": NaN}, {"timestamp": 1631550609848, "ltp": 2.54, "tv": 0.91, "trd": NaN, "batb": [[0, 2.84, 16.3], [1, 1.01, 12]], "batl": NaN}, {"timestamp": 1631550698670, "ltp": 2.54, "tv": 0.91, "trd": NaN, "batb": [[0, 1.01, 12], [1, 1.01, 0]], "batl": NaN}, {"timestamp": 1631550703565, "ltp": 2.54, "tv": 0.91, "trd": NaN, "batb": [[0, 3, 15], [1, 1.01, 12]], "batl": NaN}, {"timestamp": 1631550729196, "ltp": 2.54, "tv": 0.91, "trd": NaN, "batb": [[0, 1.01, 12], [1, 1.01, 0]], "batl": NaN}, {"timestamp": 1631550734134, "ltp": 2.54, "tv": 0.91, "trd": NaN, "batb": [[0, 3.3, 13.04], [1, 1.01, 12]], "batl": NaN}, {"timestamp": 1631550768569, "ltp": 2.54, "tv": 0.91, "trd": NaN, "batb": [[0, 1.01, 12], [1, 1.01, 0]], "batl": NaN}, {"timestamp": 1631550773461, "ltp": 2.54, "tv": 0.91, "trd": NaN, "batb": [[0, 3.4, 12.5], [1, 1.01, 12]], "batl": NaN}, {"timestamp": 1631550807026, "ltp": 2.54, "tv": 0.91, "trd": NaN, "batb": [[0, 1.01, 12], [1, 1.01, 0]], "batl": NaN}, {"timestamp": 1631550812055, "ltp": 2.54, "tv": 0.91, "trd": NaN, "batb": [[0, 3.15, 13.95], [1, 1.01, 12]], "batl": NaN}, {"timestamp": 1631550837704, "ltp": 2.54, "tv": 0.91, "trd": NaN, "batb": [[0, 1.01, 12], [1, 1.01, 0]], "batl": NaN}, {"timestamp": 1631550842600, "ltp": 2.54, "tv": 0.91, "trd": NaN, "batb": [[0, 3.4, 12.5], [1, 1.01, 12]], "batl": NaN}, {"timestamp": 1631550872660, "ltp": 2.54, "tv": 0.91, "trd": NaN, "batb": [[0, 1.01, 12], [1, 1.01, 0]], "batl": NaN}, {"timestamp": 1631550877566, "ltp": 2.54, "tv": 0.91, "trd": NaN, "batb": [[0, 3.15, 13.95], [1, 1.01, 12]], "batl": NaN}, {"timestamp": 1631550900894, "ltp": 2.54, "tv": 0.91, "trd": NaN, "batb": [[0, 1.01, 12], [1, 1.01, 0]], "batl": NaN}, {"timestamp": 1631550905840, "ltp": 2.54, "tv": 0.91, "trd": NaN, "batb": [[0, 3, 15], [1, 1.01, 12]], "batl": NaN}, {"timestamp": 1631550925726, "ltp": 2.54, "tv": 0.91, "trd": NaN, "batb": [[0, 1.01, 12], [1, 1.01, 0]], "batl": NaN}, {"timestamp": 1631550930676, "ltp": 2.54, "tv": 0.91, "trd": NaN, "batb": [[0, 2.84, 16.3], [1, 1.01, 12]], "batl": NaN}, {"timestamp": 1631551094778, "ltp": 2.54, "tv": 0.91, "trd": NaN, "batb": [[0, 1.01, 12], [1, 1.01, 0]], "batl": NaN}, {"timestamp": 1631551099686, "ltp": 2.54, "tv": 0.91, "trd": NaN, "batb": [[0, 3, 15], [1, 1.01, 12]], "batl": NaN}, {"timestamp": 1631551158590, "ltp": 2.54, "tv": 0.91, "trd": NaN, "batb": [[0, 1.01, 12], [1, 1.01, 0]], "batl": NaN}, {"timestamp": 1631551163409, "ltp": 2.54, "tv": 0.91, "trd": NaN, "batb": [[0, 3.15, 13.95], [1, 1.01, 12]], "batl": NaN}, {"timestamp": 1631551209288, "ltp": 2.54, "tv": 0.91, "trd": NaN, "batb": [[0, 1.01, 12], [1, 1.01, 0]], "batl": NaN}, {"timestamp": 1631551214297, "ltp": 2.54, "tv": 0.91, "trd": NaN, "batb": [[0, 3.3, 13.04], [1, 1.01, 12]], "batl": NaN}, {"timestamp": 1631551232712, "ltp": 2.54, "tv": 0.91, "trd": NaN, "batb": [[0, 1.01, 12], [1, 1.01, 0]], "batl": NaN}, {"timestamp": 1631551237602, "ltp": 2.54, "tv": 0.91, "trd": NaN, "batb": [[0, 3.4, 12.5], [1, 1.01, 12]], "batl": NaN}, {"timestamp": 1631551291134, "ltp": 2.54, "tv": 0.91, "trd": NaN, "batb": [[0, 1.01, 12], [1, 1.01, 0]], "batl": NaN}, {"timestamp": 1631551296101, "ltp": 2.54, "tv": 0.91, "trd": NaN, "batb": [[0, 3.3, 13.04], [1, 1.01, 12]], "batl": NaN}, {"timestamp": 1631551317024, "ltp": 2.54, "tv": 0.91, "trd": NaN, "batb": [[0, 1.01, 12], [1, 1.01, 0]], "batl": NaN}, {"timestamp": 1631551322067, "ltp": 2.54, "tv": 0.91, "trd": NaN, "batb": [[0, 3.15, 13.95], [1, 1.01, 12]], "batl": NaN}, {"timestamp": 1631551363236, "ltp": 2.54, "tv": 0.91, "trd": NaN, "batb": [[0, 1.01, 12], [1, 1.01, 0]], "batl": NaN}, {"timestamp": 1631551368117, "ltp": 2.54, "tv": 0.91, "trd": NaN, "batb": [[0, 3.3, 13.04], [1, 1.01, 12]], "batl": NaN}, {"timestamp": 1631551377751, "ltp": 2.54, "tv": 0.91, "trd": NaN, "batb": [[0, 1.01, 12], [1, 1.01, 0]], "batl": NaN}, {"timestamp": 1631551382649, "ltp": 2.54, "tv": 0.91, "trd": NaN, "batb": [[0, 3, 15], [1, 1.01, 12]], "batl": NaN}, {"timestamp": 1631551401078, "ltp": 2.54, "tv": 0.91, "trd": NaN, "batb": [[0, 1.01, 12], [1, 1.01, 0]], "batl": NaN}, {"timestamp": 1631551405914, "ltp": 2.54, "tv": 0.91, "trd": NaN, "batb": [[0, 2.84, 16.3], [1, 1.01, 12]], "batl": NaN}, {"timestamp": 1631551522099, "ltp": 2.54, "tv": 0.91, "trd": NaN, "batb": [[0, 1.01, 12], [1, 1.01, 0]], "batl": NaN}, {"timestamp": 1631551527036, "ltp": 2.54, "tv": 0.91, "trd": NaN, "batb": [[0, 3, 15], [1, 1.01, 12]], "batl": NaN}, {"timestamp": 1631551546435, "ltp": 2.54, "tv": 0.91, "trd": NaN, "batb": [[0, 1.01, 12], [1, 1.01, 0]], "batl": NaN}, {"timestamp": 1631551551355, "ltp": 2.54, "tv": 0.91, "trd": NaN, "batb": [[0, 3.15, 13.95], [1, 1.01, 12]], "batl": NaN}, {"timestamp": 1631551570207, "ltp": 2.54, "tv": 0.91, "trd": NaN, "batb": [[0, 1.01, 12], [1, 1.01, 0]], "batl": NaN}, {"timestamp": 1631551575225, "ltp": 2.54, "tv": 0.91, "trd": NaN, "batb": [[0, 2.84, 16.3], [1, 1.01, 12]], "batl": NaN}, {"timestamp": 1631551602542, "ltp": 2.54, "tv": 0.91, "trd": NaN, "batb": [[0, 1.01, 12], [1, 1.01, 0]], "batl": NaN}, {"timestamp": 1631551607362, "ltp": 2.54, "tv": 0.91, "trd": NaN, "batb": [[0, 3, 15], [1, 1.01, 12]], "batl": NaN}, {"timestamp": 1631551622393, "ltp": 2.54, "tv": 0.91, "trd": NaN, "batb": [[0, 1.01, 12], [1, 1.01, 0]], "batl": NaN}, {"timestamp": 1631551627318, "ltp": 2.54, "tv": 0.91, "trd": NaN, "batb": [[0, 3.4, 12.5], [1, 1.01, 12]], "batl": NaN}, {"timestamp": 1631551643140, "ltp": 2.54, "tv": 0.91, "trd": NaN, "batb": [[0, 1.01, 12], [1, 1.01, 0]], "batl": NaN}, {"timestamp": 1631551648034, "ltp": 2.54, "tv": 0.91, "trd": NaN, "batb": [[0, 3.7, 11.11], [1, 1.01, 12]], "batl": NaN}, {"timestamp": 1631551692500, "ltp": 2.54, "tv": 0.91, "trd": NaN, "batb": [[0, 1.01, 12], [1, 1.01, 0]], "batl": NaN}, {"timestamp": 1631551697392, "ltp": 2.54, "tv": 0.91, "trd": NaN, "batb": [[0, 3.4, 12.5], [1, 1.01, 12]], "batl": NaN}, {"timestamp": 1631551719059, "ltp": 2.54, "tv": 0.91, "trd": NaN, "batb": [[0, 1.01, 12], [1, 1.01, 0]], "batl": NaN}, {"timestamp": 1631551724068, "ltp": 2.54, "tv": 0.91, "trd": NaN, "batb": [[0, 3.3, 13.04], [1, 1.01, 12]], "batl": NaN}, {"timestamp": 1631551747196, "ltp": 2.54, "tv": 0.91, "trd": NaN, "batb": [[0, 1.01, 12], [1, 1.01, 0]], "batl": NaN}, {"timestamp": 1631551752120, "ltp": 2.54, "tv": 0.91, "trd": NaN, "batb": [[0, 3.4, 12.5], [1, 1.01, 12]], "batl": NaN}, {"timestamp": 1631551769121, "ltp": 2.54, "tv": 0.91, "trd": NaN, "batb": [[0, 1.01, 12], [1, 1.01, 0]], "batl": NaN}, {"timestamp": 1631551774112, "ltp": 2.54, "tv": 0.91, "trd": NaN, "batb": [[0, 3.7, 11.11], [1, 1.01, 12]], "batl": NaN}, {"timestamp": 1631551789666, "ltp": 2.54, "tv": 0.91, "trd": NaN, "batb": [[0, 1.01, 12], [1, 1.01, 0]], "batl": NaN}, {"timestamp": 1631551794529, "ltp": 2.54, "tv": 0.91, "trd": NaN, "batb": [[0, 3.95, 10.16], [1, 1.01, 12]], "batl": NaN}, {"timestamp": 1631551812870, "ltp": 2.54, "tv": 0.91, "trd": NaN, "batb": [[0, 1.01, 12], [1, 1.01, 0]], "batl": NaN}, {"timestamp": 1631551817776, "ltp": 2.54, "tv": 0.91, "trd": NaN, "batb": [[0, 4.1, 10], [1, 1.01, 12]], "batl": NaN}, {"timestamp": 1631551853061, "ltp": 2.54, "tv": 0.91, "trd": NaN, "batb": [[0, 1.01, 12], [1, 1.01, 0]], "batl": NaN}, {"timestamp": 1631551857950, "ltp": 2.54, "tv": 0.91, "trd": NaN, "batb": [[0, 4.8, 10], [1, 1.01, 12]], "batl": NaN}, {"timestamp": 1631551998663, "ltp": 2.54, "tv": 0.91, "trd": NaN, "batb": [[0, 1.01, 12], [1, 1.01, 0]], "batl": NaN}, {"timestamp": 1631552003555, "ltp": 2.54, "tv": 0.91, "trd": NaN, "batb": [[0, 5.3, 10], [1, 1.01, 12]], "batl": NaN}, {"timestamp": 1631552032881, "ltp": 2.54, "tv": 0.91, "trd": NaN, "batb": [[0, 1.01, 12], [1, 1.01, 0]], "batl": NaN}, {"timestamp": 1631552037783, "ltp": 2.54, "tv": 0.91, "trd": NaN, "batb": [[0, 4.8, 10], [1, 1.01, 12]], "batl": NaN}, {"timestamp": 1631552071449, "ltp": 2.54, "tv": 0.91, "trd": NaN, "batb": [[0, 1.01, 12], [1, 1.01, 0]], "batl": NaN}, {"timestamp": 1631552076351, "ltp": 2.54, "tv": 0.91, "trd": NaN, "batb": [[0, 4.3, 10], [1, 1.01, 12]], "batl": NaN}, {"timestamp": 1631552142135, "ltp": 2.54, "tv": 0.91, "trd": NaN, "batb": [[0, 1.01, 12], [1, 1.01, 0]], "batl": NaN}, {"timestamp": 1631552147140, "ltp": 2.54, "tv": 0.91, "trd": NaN, "batb": [[0, 4, 10], [1, 1.01, 12]], "batl": NaN}, {"timestamp": 1631552177980, "ltp": 2.54, "tv": 0.91, "trd": NaN, "batb": [[0, 1.01, 12], [1, 1.01, 0]], "batl": NaN}, {"timestamp": 1631552182988, "ltp": 2.54, "tv": 0.91, "trd": NaN, "batb": [[0, 3.7, 11.11], [1, 1.01, 12]], "batl": NaN}, {"timestamp": 1631552199131, "ltp": 2.54, "tv": 0.91, "trd": NaN, "batb": [[0, 1.01, 12], [1, 1.01, 0]], "batl": NaN}, {"timestamp": 1631552204033, "ltp": 2.54, "tv": 0.91, "trd": NaN, "batb": [[0, 4, 10], [1, 1.01, 12]], "batl": NaN}, {"timestamp": 1631552223553, "ltp": 2.54, "tv": 0.91, "trd": NaN, "batb": [[0, 1.01, 12], [1, 1.01, 0]], "batl": NaN}, {"timestamp": 1631552228450, "ltp": 2.54, "tv": 0.91, "trd": NaN, "batb": [[0, 3.7, 11.11], [1, 1.01, 12]], "batl": NaN}, {"timestamp": 1631552245388, "ltp": 2.54, "tv": 0.91, "trd": NaN, "batb": [[0, 1.01, 12], [1, 1.01, 0]], "batl": NaN}, {"timestamp": 1631552250390, "ltp": 2.54, "tv": 0.91, "trd": NaN, "batb": [[0, 3.4, 12.5], [1, 1.01, 12]], "batl": NaN}, {"timestamp": 1631552279410, "ltp": 2.54, "tv": 0.91, "trd": NaN, "batb": [[0, 1.01, 12], [1, 1.01, 0]], "batl": NaN}, {"timestamp": 1631552284422, "ltp": 2.54, "tv": 0.91, "trd": NaN, "batb": [[0, 3.7, 11.11], [1, 1.01, 12]], "batl": NaN}, {"timestamp": 1631552303932, "ltp": 2.54, "tv": 0.91, "trd": NaN, "batb": [[0, 1.01, 12], [1, 1.01, 0]], "batl": NaN}, {"timestamp": 1631552308944, "ltp": 2.54, "tv": 0.91, "trd": NaN, "batb": [[0, 3.3, 13.04], [1, 1.01, 12]], "batl": NaN}, {"timestamp": 1631552340908, "ltp": 4.6, "tv": 5.91, "trd": [[4.6, 5]], "batb": NaN, "batl": NaN}, {"timestamp": 1631552456037, "ltp": 4.6, "tv": 5.91, "trd": NaN, "batb": [[0, 1.01, 12], [1, 1.01, 0]], "batl": NaN}, {"timestamp": 1631552461041, "ltp": 4.6, "tv": 5.91, "trd": NaN, "batb": [[0, 2.84, 16.3], [1, 1.01, 12]], "batl": NaN}, {"timestamp": 1631552497872, "ltp": 4.6, "tv": 5.91, "trd": NaN, "batb": [[0, 1.01, 12], [1, 1.01, 0]], "batl": NaN}, {"timestamp": 1631552502791, "ltp": 4.6, "tv": 5.91, "trd": NaN, "batb": [[0, 2.5, 20], [1, 1.01, 12]], "batl": NaN}, {"timestamp": 1631552523836, "ltp": 4.6, "tv": 5.91, "trd": NaN, "batb": [[0, 1.01, 12], [1, 1.01, 0]], "batl": NaN}, {"timestamp": 1631552528729, "ltp": 4.6, "tv": 5.91, "trd": NaN, "batb": [[0, 2.2, 24.99], [1, 1.01, 12]], "batl": NaN}, {"timestamp": 1631552542013, "ltp": 4.6, "tv": 5.91, "trd": NaN, "batb": [[0, 1.01, 12], [1, 1.01, 0]], "batl": NaN}, {"timestamp": 1631552546950, "ltp": 4.6, "tv": 5.91, "trd": NaN, "batb": [[0, 2.16, 25.86], [1, 1.01, 12]], "batl": NaN}, {"timestamp": 1631552558288, "ltp": 4.6, "tv": 5.91, "trd": NaN, "batb": [[0, 1.01, 12], [1, 1.01, 0]], "batl": NaN}, {"timestamp": 1631552563278, "ltp": 4.6, "tv": 5.91, "trd": NaN, "batb": [[0, 2.42, 21.12], [1, 1.01, 12]], "batl": NaN}, {"timestamp": 1631552584913, "ltp": 4.6, "tv": 5.91, "trd": NaN, "batb": [[0, 1.01, 12], [1, 1.01, 0]], "batl": NaN}, {"timestamp": 1631552589938, "ltp": 4.6, "tv": 5.91, "trd": NaN, "batb": [[0, 2.1, 27.27], [1, 1.01, 12]], "batl": NaN}, {"timestamp": 1631552621777, "ltp": 4.6, "tv": 5.91, "trd": NaN, "batb": [[0, 1.01, 12], [1, 1.01, 0]], "batl": NaN}, {"timestamp": 1631552626760, "ltp": 4.6, "tv": 5.91, "trd": NaN, "batb": [[0, 2.34, 22.38], [1, 1.01, 12]], "batl": NaN}, {"timestamp": 1631552640996, "ltp": 4.6, "tv": 5.91, "trd": NaN, "batb": [[0, 1.01, 12], [1, 1.01, 0]], "batl": NaN}, {"timestamp": 1631552645883, "ltp": 4.6, "tv": 5.91, "trd": NaN, "batb": [[0, 2.42, 21.12], [1, 1.01, 12]], "batl": NaN}, {"timestamp": 1631552657286, "ltp": 4.6, "tv": 5.91, "trd": NaN, "batb": [[0, 1.01, 12], [1, 1.01, 0]], "batl": NaN}, {"timestamp": 1631552662285, "ltp": 4.6, "tv": 5.91, "trd": NaN, "batb": [[0, 2.66, 18.07], [1, 1.01, 12]], "batl": NaN}, {"timestamp": 1631552678844, "ltp": 4.6, "tv": 5.91, "trd": NaN, "batb": [[0, 1.01, 12], [1, 1.01, 0]], "batl": NaN}, {"timestamp": 1631552683821, "ltp": 4.6, "tv": 5.91, "trd": NaN, "batb": [[0, 2.42, 21.12], [1, 1.01, 12]], "batl": NaN}, {"timestamp": 1631552745413, "ltp": 4.6, "tv": 5.91, "trd": NaN, "batb": [[0, 1.01, 12], [1, 1.01, 0]], "batl": NaN}, {"timestamp": 1631552750317, "ltp": 4.6, "tv": 5.91, "trd": NaN, "batb": [[0, 2.16, 25.86], [1, 1.01, 12]], "batl": NaN}, {"timestamp": 1631552765422, "ltp": 4.6, "tv": 5.91, "trd": NaN, "batb": [[0, 1.01, 12], [1, 1.01, 0]], "batl": NaN}, {"timestamp": 1631552770455, "ltp": 4.6, "tv": 5.91, "trd": NaN, "batb": [[0, 2.5, 20], [1, 1.01, 12]], "batl": NaN}, {"timestamp": 1631552785833, "ltp": 4.6, "tv": 5.91, "trd": NaN, "batb": [[0, 1.01, 12], [1, 1.01, 0]], "batl": NaN}, {"timestamp": 1631552790887, "ltp": 4.6, "tv": 5.91, "trd": NaN, "batb": [[0, 3, 15], [1, 1.01, 12]], "batl": NaN}, {"timestamp": 1631552889185, "ltp": 4.6, "tv": 5.91, "trd": NaN, "batb": [[0, 1.01, 12], [1, 1.01, 0]], "batl": NaN}, {"timestamp": 1631552894200, "ltp": 4.6, "tv": 5.91, "trd": NaN, "batb": [[0, 3.4, 12.5], [1, 1.01, 12]], "batl": NaN}, {"timestamp": 1631552924434, "ltp": 4.6, "tv": 5.91, "trd": NaN, "batb": [[0, 1.01, 12], [1, 1.01, 0]], "batl": NaN}, {"timestamp": 1631552929335, "ltp": 4.6, "tv": 5.91, "trd": NaN, "batb": [[0, 4, 10], [1, 1.01, 12]], "batl": NaN}, {"timestamp": 1631552967279, "ltp": 4.6, "tv": 5.91, "trd": NaN, "batb": [[0, 1.01, 12], [1, 1.01, 0]], "batl": NaN}, {"timestamp": 1631552972320, "ltp": 4.6, "tv": 5.91, "trd": NaN, "batb": [[0, 3.4, 12.5], [1, 1.01, 12]], "batl": NaN}, {"timestamp": 1631553005591, "ltp": 4.6, "tv": 5.91, "trd": NaN, "batb": [[0, 1.01, 12], [1, 1.01, 0]], "batl": NaN}, {"timestamp": 1631553010447, "ltp": 4.6, "tv": 5.91, "trd": NaN, "batb": [[0, 3, 15], [1, 1.01, 12]], "batl": NaN}, {"timestamp": 1631553076556, "ltp": 4.6, "tv": 5.91, "trd": NaN, "batb": [[0, 1.01, 12], [1, 1.01, 0]], "batl": NaN}, {"timestamp": 1631553081539, "ltp": 4.6, "tv": 5.91, "trd": NaN, "batb": [[0, 2.5, 20], [1, 1.01, 12]], "batl": NaN}, {"timestamp": 1631553142589, "ltp": 4.6, "tv": 5.91, "trd": NaN, "batb": [[0, 1.01, 12], [1, 1.01, 0]], "batl": NaN}, {"timestamp": 1631553147485, "ltp": 4.6, "tv": 5.91, "trd": NaN, "batb": [[0, 3, 15], [1, 1.01, 12]], "batl": NaN}, {"timestamp": 1631553203899, "ltp": 4.6, "tv": 5.91, "trd": NaN, "batb": [[0, 1.01, 12], [1, 1.01, 0]], "batl": NaN}, {"timestamp": 1631553208884, "ltp": 4.6, "tv": 5.91, "trd": NaN, "batb": [[0, 3.4, 12.5], [1, 1.01, 12]], "batl": NaN}, {"timestamp": 1631553255593, "ltp": 4.6, "tv": 5.91, "trd": NaN, "batb": [[0, 1.01, 12], [1, 1.01, 0]], "batl": NaN}, {"timestamp": 1631553260564, "ltp": 4.6, "tv": 5.91, "trd": NaN, "batb": [[0, 3, 15], [1, 1.01, 12]], "batl": NaN}, {"timestamp": 1631553297236, "ltp": 4.6, "tv": 5.91, "trd": NaN, "batb": [[0, 1.01, 12], [1, 1.01, 0]], "batl": NaN}, {"timestamp": 1631553302125, "ltp": 4.6, "tv": 5.91, "trd": NaN, "batb": [[0, 3.4, 12.5], [1, 1.01, 12]], "batl": NaN}, {"timestamp": 1631553361002, "ltp": 4.6, "tv": 5.91, "trd": NaN, "batb": [[0, 1.01, 12], [1, 1.01, 0]], "batl": NaN}, {"timestamp": 1631553366085, "ltp": 4.6, "tv": 5.91, "trd": NaN, "batb": [[0, 3, 15], [1, 1.01, 12]], "batl": NaN}, {"timestamp": 1631553413454, "ltp": 4.6, "tv": 5.91, "trd": NaN, "batb": [[0, 1.01, 12], [1, 1.01, 0]], "batl": NaN}, {"timestamp": 1631553418341, "ltp": 4.6, "tv": 5.91, "trd": NaN, "batb": [[0, 3.4, 12.5], [1, 1.01, 12]], "batl": NaN}, {"timestamp": 1631553496431, "ltp": 4.6, "tv": 5.91, "trd": NaN, "batb": [[0, 1.01, 12], [1, 1.01, 0]], "batl": NaN}, {"timestamp": 1631553501333, "ltp": 4.6, "tv": 5.91, "trd": NaN, "batb": [[0, 3, 15], [1, 1.01, 12]], "batl": NaN}, {"timestamp": 1631553555512, "ltp": 4.6, "tv": 5.91, "trd": NaN, "batb": [[0, 1.01, 12], [1, 1.01, 0]], "batl": NaN}, {"timestamp": 1631553560505, "ltp": 4.6, "tv": 5.91, "trd": NaN, "batb": [[0, 3.4, 12.5], [1, 1.01, 12]], "batl": NaN}, {"timestamp": 1631553595645, "ltp": 4.6, "tv": 5.91, "trd": NaN, "batb": [[0, 1.01, 12], [1, 1.01, 0]], "batl": NaN}, {"timestamp": 1631553600565, "ltp": 4.6, "tv": 5.91, "trd": NaN, "batb": [[0, 4.1, 10], [1, 1.01, 12]], "batl": NaN}, {"timestamp": 1631553954213, "ltp": 4.6, "tv": 5.91, "trd": NaN, "batb": [[0, 1.01, 12], [1, 1.01, 0]], "batl": NaN}, {"timestamp": 1631553959205, "ltp": 4.6, "tv": 5.91, "trd": NaN, "batb": [[0, 3.95, 10.16], [1, 1.01, 12]], "batl": NaN}, {"timestamp": 1631553982447, "ltp": 4.6, "tv": 5.91, "trd": NaN, "batb": [[0, 1.01, 12], [1, 1.01, 0]], "batl": NaN}, {"timestamp": 1631553987351, "ltp": 4.6, "tv": 5.91, "trd": NaN, "batb": [[0, 4.3, 10], [1, 1.01, 12]], "batl": NaN}, {"timestamp": 1631554002094, "ltp": 4.6, "tv": 5.91, "trd": NaN, "batb": [[0, 1.01, 12], [1, 1.01, 0]], "batl": NaN}, {"timestamp": 1631554006985, "ltp": 4.6, "tv": 5.91, "trd": NaN, "batb": [[0, 4.8, 10], [1, 1.01, 12]], "batl": NaN}, {"timestamp": 1631554018396, "ltp": 4.6, "tv": 5.91, "trd": NaN, "batb": [[0, 1.01, 12], [1, 1.01, 0]], "batl": NaN}, {"timestamp": 1631554023290, "ltp": 4.6, "tv": 5.91, "trd": NaN, "batb": [[0, 4.3, 10], [1, 1.01, 12]], "batl": NaN}, {"timestamp": 1631554045528, "ltp": 4.6, "tv": 5.91, "trd": NaN, "batb": [[0, 1.01, 12], [1, 1.01, 0]], "batl": NaN}, {"timestamp": 1631554050419, "ltp": 4.6, "tv": 5.91, "trd": NaN, "batb": [[0, 3.95, 10.16], [1, 1.01, 12]], "batl": NaN}, {"timestamp": 1631554076678, "ltp": 4.6, "tv": 5.91, "trd": NaN, "batb": [[0, 1.01, 12], [1, 1.01, 0]], "batl": NaN}, {"timestamp": 1631554081694, "ltp": 4.6, "tv": 5.91, "trd": NaN, "batb": [[0, 4.3, 10], [1, 1.01, 12]], "batl": NaN}, {"timestamp": 1631554119796, "ltp": 4.6, "tv": 5.91, "trd": NaN, "batb": [[0, 1.01, 12], [1, 1.01, 0]], "batl": NaN}, {"timestamp": 1631554124732, "ltp": 4.6, "tv": 5.91, "trd": NaN, "batb": [[0, 3.95, 10.16], [1, 1.01, 12]], "batl": NaN}, {"timestamp": 1631554153830, "ltp": 4.6, "tv": 5.91, "trd": NaN, "batb": [[0, 1.01, 12], [1, 1.01, 0]], "batl": NaN}, {"timestamp": 1631554158754, "ltp": 4.6, "tv": 5.91, "trd": NaN, "batb": [[0, 4.3, 10], [1, 1.01, 12]], "batl": NaN}, {"timestamp": 1631554203318, "ltp": 4.6, "tv": 5.91, "trd": NaN, "batb": [[0, 1.01, 12], [1, 1.01, 0]], "batl": NaN}, {"timestamp": 1631554208343, "ltp": 4.6, "tv": 5.91, "trd": NaN, "batb": [[0, 5.3, 10], [1, 1.01, 12]], "batl": NaN}, {"timestamp": 1631554231926, "ltp": 4.6, "tv": 5.91, "trd": NaN, "batb": [[0, 1.01, 12], [1, 1.01, 0]], "batl": NaN}, {"timestamp": 1631554236869, "ltp": 4.6, "tv": 5.91, "trd": NaN, "batb": [[0, 5.8, 10], [1, 1.01, 12]], "batl": NaN}, {"timestamp": 1631554243249, "ltp": 4.6, "tv": 5.91, "trd": NaN, "batb": [[0, 1.01, 12], [1, 1.01, 0]], "batl": NaN}, {"timestamp": 1631554248277, "ltp": 4.6, "tv": 5.91, "trd": NaN, "batb": [[0, 4.3, 10], [1, 1.01, 12]], "batl": NaN}, {"timestamp": 1631554267587, "ltp": 4.6, "tv": 5.91, "trd": NaN, "batb": [[0, 1.01, 12], [1, 1.01, 0]], "batl": NaN}, {"timestamp": 1631554272472, "ltp": 4.6, "tv": 5.91, "trd": NaN, "batb": [[0, 4.8, 10], [1, 1.01, 12]], "batl": NaN}, {"timestamp": 1631554285895, "ltp": 4.6, "tv": 5.91, "trd": NaN, "batb": [[0, 1.01, 12], [1, 1.01, 0]], "batl": NaN}, {"timestamp": 1631554290935, "ltp": 4.6, "tv": 5.91, "trd": NaN, "batb": [[0, 5.3, 10], [1, 1.01, 12]], "batl": NaN}, {"timestamp": 1631554316175, "ltp": 4.6, "tv": 5.91, "trd": NaN, "batb": [[0, 1.01, 12], [1, 1.01, 0]], "batl": NaN}, {"timestamp": 1631554321140, "ltp": 4.6, "tv": 5.91, "trd": NaN, "batb": [[0, 6, 10], [1, 1.01, 12]], "batl": NaN}, {"timestamp": 1631554402281, "ltp": 4.6, "tv": 5.91, "trd": NaN, "batb": [[0, 1.01, 12], [1, 1.01, 0]], "batl": NaN}, {"timestamp": 1631554407185, "ltp": 4.6, "tv": 5.91, "trd": NaN, "batb": [[0, 7.6, 10], [1, 1.01, 12]], "batl": NaN}, {"timestamp": 1631554429215, "ltp": 4.6, "tv": 5.91, "trd": NaN, "batb": [[0, 1.01, 12], [1, 1.01, 0]], "batl": NaN}, {"timestamp": 1631554434117, "ltp": 4.6, "tv": 5.91, "trd": NaN, "batb": [[0, 6, 10], [1, 1.01, 12]], "batl": NaN}, {"timestamp": 1631554469658, "ltp": 4.6, "tv": 5.91, "trd": NaN, "batb": [[0, 1.01, 12], [1, 1.01, 0]], "batl": NaN}, {"timestamp": 1631554474643, "ltp": 4.6, "tv": 5.91, "trd": NaN, "batb": [[0, 7.6, 10], [1, 1.01, 12]], "batl": NaN}, {"timestamp": 1631554534843, "ltp": 4.6, "tv": 5.91, "trd": NaN, "batb": [[0, 1.01, 12], [1, 1.01, 0]], "batl": NaN}, {"timestamp": 1631554539894, "ltp": 4.6, "tv": 5.91, "trd": NaN, "batb": [[0, 6, 10], [1, 1.01, 12]], "batl": NaN}, {"timestamp": 1631554575699, "ltp": 4.6, "tv": 5.91, "trd": NaN, "batb": [[0, 1.01, 12], [1, 1.01, 0]], "batl": NaN}, {"timestamp": 1631554580687, "ltp": 4.6, "tv": 5.91, "trd": NaN, "batb": [[0, 7.6, 10], [1, 1.01, 12]], "batl": NaN}, {"timestamp": 1631554616429, "ltp": 4.6, "tv": 5.91, "trd": NaN, "batb": [[0, 1.01, 12], [1, 1.01, 0]], "batl": NaN}, {"timestamp": 1631554621405, "ltp": 4.6, "tv": 5.91, "trd": NaN, "batb": [[0, 9.6, 10], [1, 1.01, 12]], "batl": NaN}, {"timestamp": 1631554655039, "ltp": 4.6, "tv": 5.91, "trd": NaN, "batb": [[0, 1.01, 12], [1, 1.01, 0]], "batl": NaN}, {"timestamp": 1631554659956, "ltp": 4.6, "tv": 5.91, "trd": NaN, "batb": [[0, 7.6, 10], [1, 1.01, 12]], "batl": NaN}, {"timestamp": 1631554676266, "ltp": 4.6, "tv": 5.91, "trd": NaN, "batb": [[0, 1.01, 12], [1, 1.01, 0]], "batl": NaN}, {"timestamp": 1631554681280, "ltp": 4.6, "tv": 5.91, "trd": NaN, "batb": [[0, 8.6, 10], [1, 1.01, 12]], "batl": NaN}, {"timestamp": 1631554704635, "ltp": 4.6, "tv": 5.91, "trd": NaN, "batb": [[0, 1.01, 12], [1, 1.01, 0]], "batl": NaN}, {"timestamp": 1631554709626, "ltp": 4.6, "tv": 5.91, "trd": NaN, "batb": [[0, 7.6, 10], [1, 1.01, 12]], "batl": NaN}, {"timestamp": 1631554738770, "ltp": 4.6, "tv": 5.91, "trd": NaN, "batb": [[0, 1.01, 12], [1, 1.01, 0]], "batl": NaN}, {"timestamp": 1631554743651, "ltp": 4.6, "tv": 5.91, "trd": NaN, "batb": [[0, 7, 10], [1, 1.01, 12]], "batl": NaN}, {"timestamp": 1631554769489, "ltp": 4.6, "tv": 5.91, "trd": NaN, "batb": [[0, 1.01, 12], [1, 1.01, 0]], "batl": NaN}, {"timestamp": 1631554774515, "ltp": 4.6, "tv": 5.91, "trd": NaN, "batb": [[0, 6, 10], [1, 1.01, 12]], "batl": NaN}, {"timestamp": 1631554890482, "ltp": 4.6, "tv": 5.91, "trd": NaN, "batb": [[0, 1.01, 12], [1, 1.01, 0]], "batl": NaN}, {"timestamp": 1631554895477, "ltp": 4.6, "tv": 5.91, "trd": NaN, "batb": [[0, 7.6, 10], [1, 1.01, 12]], "batl": NaN}, {"timestamp": 1631554959187, "ltp": 4.6, "tv": 5.91, "trd": NaN, "batb": [[0, 1.01, 12], [1, 1.01, 0]], "batl": NaN}, {"timestamp": 1631554964170, "ltp": 4.6, "tv": 5.91, "trd": NaN, "batb": [[0, 6, 10], [1, 1.01, 12]], "batl": NaN}, {"timestamp": 1631555006345, "ltp": 4.6, "tv": 5.91, "trd": NaN, "batb": [[0, 1.01, 12], [1, 1.01, 0]], "batl": NaN}, {"timestamp": 1631555011289, "ltp": 4.6, "tv": 5.91, "trd": NaN, "batb": [[0, 7.6, 10], [1, 1.01, 12]], "batl": NaN}, {"timestamp": 1631555040790, "ltp": 4.6, "tv": 5.91, "trd": NaN, "batb": [[0, 1.01, 12], [1, 1.01, 0]], "batl": NaN}, {"timestamp": 1631555045760, "ltp": 4.6, "tv": 5.91, "trd": NaN, "batb": [[0, 8.6, 10], [1, 1.01, 12]], "batl": NaN}, {"timestamp": 1631555062507, "ltp": 4.6, "tv": 5.91, "trd": NaN, "batb": [[0, 1.01, 12], [1, 1.01, 0]], "batl": NaN}, {"timestamp": 1631555067423, "ltp": 4.6, "tv": 5.91, "trd": NaN, "batb": [[0, 8, 10], [1, 1.01, 12]], "batl": NaN}, {"timestamp": 1631555092369, "ltp": 4.6, "tv": 5.91, "trd": NaN, "batb": [[0, 1.01, 12], [1, 1.01, 0]], "batl": NaN}, {"timestamp": 1631555097251, "ltp": 4.6, "tv": 5.91, "trd": NaN, "batb": [[0, 7.6, 10], [1, 1.01, 12]], "batl": NaN}, {"timestamp": 1631555248232, "ltp": 4.6, "tv": 5.91, "trd": NaN, "batb": [[0, 1.01, 12], [1, 1.01, 0]], "batl": NaN}, {"timestamp": 1631555253292, "ltp": 4.6, "tv": 5.91, "trd": NaN, "batb": [[0, 6, 10], [1, 1.01, 12]], "batl": NaN}, {"timestamp": 1631555284677, "ltp": 4.6, "tv": 5.91, "trd": NaN, "batb": [[0, 1.01, 12], [1, 1.01, 0]], "batl": NaN}, {"timestamp": 1631555289697, "ltp": 4.6, "tv": 5.91, "trd": NaN, "batb": [[0, 7.6, 10], [1, 1.01, 12]], "batl": NaN}, {"timestamp": 1631555314959, "ltp": 4.6, "tv": 5.91, "trd": NaN, "batb": [[0, 1.01, 12], [1, 1.01, 0]], "batl": NaN}, {"timestamp": 1631555319845, "ltp": 4.6, "tv": 5.91, "trd": NaN, "batb": [[0, 9.6, 10], [1, 1.01, 12]], "batl": NaN}, {"timestamp": 1631555390908, "ltp": 4.6, "tv": 5.91, "trd": NaN, "batb": [[0, 1.01, 12], [1, 1.01, 0]], "batl": NaN}, {"timestamp": 1631555395831, "ltp": 4.6, "tv": 5.91, "trd": NaN, "batb": [[0, 11, 10], [1, 1.01, 12]], "batl": NaN}, {"timestamp": 1631555470224, "ltp": 4.6, "tv": 5.91, "trd": NaN, "batb": [[0, 1.01, 12], [1, 1.01, 0]], "batl": NaN}, {"timestamp": 1631555475108, "ltp": 4.6, "tv": 5.91, "trd": NaN, "batb": [[0, 14, 10], [1, 1.01, 12]], "batl": NaN}, {"timestamp": 1631555525721, "ltp": 4.6, "tv": 5.91, "trd": NaN, "batb": [[0, 1.01, 12], [1, 1.01, 0]], "batl": NaN}, {"timestamp": 1631555530674, "ltp": 4.6, "tv": 5.91, "trd": NaN, "batb": [[0, 12, 10], [1, 1.01, 12]], "batl": NaN}, {"timestamp": 1631555549019, "ltp": 4.6, "tv": 5.91, "trd": NaN, "batb": [[0, 1.01, 12], [1, 1.01, 0]], "batl": NaN}, {"timestamp": 1631555553926, "ltp": 4.6, "tv": 5.91, "trd": NaN, "batb": [[0, 16, 10], [1, 1.01, 12]], "batl": NaN}, {"timestamp": 1631555597669, "ltp": 4.6, "tv": 5.91, "trd": NaN, "batb": [[0, 1.01, 12], [1, 1.01, 0]], "batl": NaN}, {"timestamp": 1631555602658, "ltp": 4.6, "tv": 5.91, "trd": NaN, "batb": [[0, 12, 10], [1, 1.01, 12]], "batl": NaN}, {"timestamp": 1631555641345, "ltp": 4.6, "tv": 5.91, "trd": NaN, "batb": [[0, 1.01, 12], [1, 1.01, 0]], "batl": NaN}, {"timestamp": 1631555646215, "ltp": 4.6, "tv": 5.91, "trd": NaN, "batb": [[0, 19.5, 10], [1, 1.01, 12]], "batl": NaN}, {"timestamp": 1631555826511, "ltp": 4.6, "tv": 5.91, "trd": NaN, "batb": [[0, 1.01, 12], [1, 1.01, 0]], "batl": NaN}, {"timestamp": 1631555831523, "ltp": 4.6, "tv": 5.91, "trd": NaN, "batb": [[0, 14, 10], [1, 1.01, 12]], "batl": NaN}, {"timestamp": 1631555871563, "ltp": 4.6, "tv": 5.91, "trd": NaN, "batb": [[0, 1.01, 12], [1, 1.01, 0]], "batl": NaN}, {"timestamp": 1631555876444, "ltp": 4.6, "tv": 5.91, "trd": NaN, "batb": [[0, 11, 10], [1, 1.01, 12]], "batl": NaN}, {"timestamp": 1631555916305, "ltp": 4.6, "tv": 5.91, "trd": NaN, "batb": [[0, 1.01, 12], [1, 1.01, 0]], "batl": NaN}, {"timestamp": 1631555921339, "ltp": 4.6, "tv": 5.91, "trd": NaN, "batb": [[0, 14, 10], [1, 1.01, 12]], "batl": NaN}, {"timestamp": 1631555950639, "ltp": 4.6, "tv": 5.91, "trd": NaN, "batb": [[0, 1.01, 12], [1, 1.01, 0]], "batl": NaN}, {"timestamp": 1631555955652, "ltp": 4.6, "tv": 5.91, "trd": NaN, "batb": [[0, 12, 10], [1, 1.01, 12]], "batl": NaN}, {"timestamp": 1631555982184, "ltp": 4.6, "tv": 5.91, "trd": NaN, "batb": [[0, 1.01, 12], [1, 1.01, 0]], "batl": NaN}, {"timestamp": 1631555987102, "ltp": 4.6, "tv": 5.91, "trd": NaN, "batb": [[0, 19.5, 10], [1, 1.01, 12]], "batl": NaN}, {"timestamp": 1631556037784, "ltp": 4.6, "tv": 5.91, "trd": NaN, "batb": [[0, 1.01, 12], [1, 1.01, 0]], "batl": NaN}, {"timestamp": 1631556042725, "ltp": 4.6, "tv": 5.91, "trd": NaN, "batb": [[0, 12, 10], [1, 1.01, 12]], "batl": NaN}, {"timestamp": 1631556080435, "ltp": 4.6, "tv": 5.91, "trd": NaN, "batb": [[0, 1.01, 12], [1, 1.01, 0]], "batl": NaN}, {"timestamp": 1631556085367, "ltp": 4.6, "tv": 5.91, "trd": NaN, "batb": [[0, 10, 10], [1, 1.01, 12]], "batl": NaN}, {"timestamp": 1631556135624, "ltp": 4.6, "tv": 5.91, "trd": NaN, "batb": [[0, 1.01, 12], [1, 1.01, 0]], "batl": NaN}, {"timestamp": 1631556140637, "ltp": 4.6, "tv": 5.91, "trd": NaN, "batb": [[0, 8.6, 10], [1, 1.01, 12]], "batl": NaN}, {"timestamp": 1631556164219, "ltp": 4.6, "tv": 5.91, "trd": NaN, "batb": [[0, 1.01, 12], [1, 1.01, 0]], "batl": NaN}, {"timestamp": 1631556169150, "ltp": 4.6, "tv": 5.91, "trd": NaN, "batb": [[0, 10, 10], [1, 1.01, 12]], "batl": NaN}, {"timestamp": 1631556209622, "ltp": 4.6, "tv": 5.91, "trd": NaN, "batb": [[0, 1.01, 12], [1, 1.01, 0]], "batl": NaN}, {"timestamp": 1631556214525, "ltp": 4.6, "tv": 5.91, "trd": NaN, "batb": [[0, 14, 10], [1, 1.01, 12]], "batl": NaN}, {"timestamp": 1631556248468, "ltp": 4.6, "tv": 5.91, "trd": NaN, "batb": [[0, 1.01, 12], [1, 1.01, 0]], "batl": NaN}, {"timestamp": 1631556253473, "ltp": 4.6, "tv": 5.91, "trd": NaN, "batb": [[0, 19.5, 10], [1, 1.01, 12]], "batl": NaN}, {"timestamp": 1631556274912, "ltp": 4.6, "tv": 5.91, "trd": NaN, "batb": [[0, 1.01, 12], [1, 1.01, 0]], "batl": NaN}, {"timestamp": 1631556279902, "ltp": 4.6, "tv": 5.91, "trd": NaN, "batb": [[0, 24, 10], [1, 1.01, 12]], "batl": NaN}, {"timestamp": 1631556408500, "ltp": 4.6, "tv": 5.91, "trd": NaN, "batb": [[0, 1.01, 12], [1, 1.01, 0]], "batl": NaN}]}]}