{"info": {"id": "1.187595436", "eventId": "30897919", "eventName": "Match Odds", "marketType": "MATCH_ODDS", "openDate": 1631532650985, "name": "J Fourlis v A Prisacariu", "numberOfActiveRunner": 2, "countryCode": "", "sport": "TENNIS", "venue": "", "volume": {"total": 1588.09, "preMatch": 5.34, "inPlay": 1582.75}, "winner": {"id": 9637020, "name": "A Prisacariu", "status": "WINNER", "position": 2}, "delay": 5}, "runners": [{"id": 9638604, "name": "J Fourlis", "status": "LOSER", "position": 1, "inPlayOdds": 1.67, "inPlayTime": 1631534400825, "avgPrematch": 0, "closedOdds": 46.0, "maxPrematch": -100, "minPrematch": 1001, "maxInPlay": 46.0, "minInPlay": 1.67, "inPlayIndex": 0, "lengthOdds": 185, "lengthOddsPrematch": 0, "lengthOddsInPlay": 185, "tradedVolume": 76.86, "preMatchVolume": 0.03, "inPlayVolume": 76.83}, {"id": 9637020, "name": "A Prisacariu", "status": "WINNER", "position": 2, "inPlayOdds": 2.1, "inPlayTime": 1631532650985, "avgPrematch": 2.1, "closedOdds": 1.01, "maxPrematch": 2.1, "minPrematch": 2.1, "maxInPlay": 2.1, "minInPlay": 1.01, "inPlayIndex": 3, "lengthOdds": 152, "lengthOddsPrematch": 3, "lengthOddsInPlay": 149, "tradedVolume": 1511.23, "preMatchVolume": 5.31, "inPlayVolume": 1505.92}], "marketUpdates": [{"timestamp": 1631518765810000000, "openDate": "2021-09-13T11:00:00.000Z", "status": "OPEN", "betDelay": 0, "inPlay": false, "complete": true}, {"timestamp": 1631530679736000000, "openDate": "2021-09-13T11:10:00.000Z", "status": "OPEN", "betDelay": 0, "inPlay": false, "complete": true}, {"timestamp": 1631531145179000000, "openDate": "2021-09-13T11:20:00.000Z", "status": "OPEN", "betDelay": 0, "inPlay": false, "complete": true}, {"timestamp": 1631531755505000000, "openDate": "2021-09-13T11:30:00.000Z", "status": "OPEN", "betDelay": 0, "inPlay": false, "complete": true}, {"timestamp": 1631532650985000000, "openDate": "2021-09-13T11:30:00.000Z", "status": "OPEN", "betDelay": 5, "inPlay": true, "complete": true}, {"timestamp": 1631533192455000000, "openDate": "2021-09-13T11:39:48.000Z", "status": "OPEN", "betDelay": 5, "inPlay": true, "complete": true}, {"timestamp": 1631540212100000000, "openDate": "2021-09-13T11:39:48.000Z", "status": "SUSPENDED", "betDelay": 5, "inPlay": true, "complete": true}, {"timestamp": 1631540221152000000, "openDate": "2021-09-13T11:39:48.000Z", "status": "CLOSED", "betDelay": 5, "inPlay": true, "complete": true}], "odds": [{"runnerId": 9638604, "odds": [{"timestamp": 1631534400825, "ltp": 1.67, "tv": 0.03, "trd": [[1.67, 0.03]], "batb": [[0, 1.67, 415.4]], "batl": NaN}, {"timestamp": 1631534441357, "ltp": 1.67, "tv": 0.03, "trd": NaN, "batb": [[0, 1.01, 7], [1, 1.01, 0]], "batl": NaN}, {"timestamp": 1631534447013, "ltp": 1.67, "tv": 0.03, "trd": NaN, "batb": [[0, 1.52, 431.35], [1, 1.01, 7]], "batl": [[0, 2.36, 303.31]]}, {"timestamp": 1631534471027, "ltp": 1.67, "tv": 0.03, "trd": NaN, "batb": [[0, 1.01, 7], [1, 1.01, 0]], "batl": NaN}, {"timestamp": 1631534476336, "ltp": 1.67, "tv": 0.03, "trd": NaN, "batb": [[0, 1.44, 442.18], [1, 1.01, 7]], "batl": [[0, 2.16, 347.56]]}, {"timestamp": 1631534530472, "ltp": 1.67, "tv": 0.03, "trd": NaN, "batb": [[0, 1.01, 7], [1, 1.01, 0]], "batl": NaN}, {"timestamp": 1631534536457, "ltp": 1.67, "tv": 0.03, "trd": NaN, "batb": [[0, 1.5, 432.78], [1, 1.01, 7]], "batl": NaN}, {"timestamp": 1631534560222, "ltp": 1.67, "tv": 0.03, "trd": NaN, "batb": [[0, 1.01, 7], [1, 1.01, 0]], "batl": NaN}, {"timestamp": 1631534566017, "ltp": 1.67, "tv": 0.03, "trd": NaN, "batb": [[0, 1.58, 422.19], [1, 1.01, 7]], "batl": [[0, 2.5, 278.34]]}, {"timestamp": 1631534609813, "ltp": 1.67, "tv": 0.03, "trd": NaN, "batb": NaN, "batl": [[0, 2.3, 314.03]]}, {"timestamp": 1631534671878, "ltp": 1.67, "tv": 0.03, "trd": NaN, "batb": [[0, 1.01, 7], [1, 1.01, 0]], "batl": NaN}, {"timestamp": 1631534677939, "ltp": 1.67, "tv": 0.03, "trd": NaN, "batb": [[0, 1.67, 415.4], [1, 1.01, 7]], "batl": [[0, 2.72, 244.89]]}, {"timestamp": 1631534702789, "ltp": 1.67, "tv": 0.03, "trd": NaN, "batb": [[0, 1.01, 7], [1, 1.01, 0]], "batl": NaN}, {"timestamp": 1631534708312, "ltp": 1.67, "tv": 0.03, "trd": NaN, "batb": [[0, 1.74, 409.85], [1, 1.01, 7]], "batl": NaN}, {"timestamp": 1631534823550, "ltp": 1.67, "tv": 0.03, "trd": NaN, "batb": [[0, 1.01, 7], [1, 1.01, 0]], "batl": NaN}, {"timestamp": 1631534829686, "ltp": 1.67, "tv": 0.03, "trd": NaN, "batb": [[0, 1.86, 404.11], [1, 1.01, 7]], "batl": [[0, 3.3, 194.57]]}, {"timestamp": 1631534853718, "ltp": 1.67, "tv": 0.03, "trd": NaN, "batb": NaN, "batl": [[0, 3, 216.41]]}, {"timestamp": 1631534916225, "ltp": 1.67, "tv": 0.03, "trd": NaN, "batb": [[0, 1.01, 7], [1, 1.01, 0]], "batl": NaN}, {"timestamp": 1631534921816, "ltp": 1.67, "tv": 0.03, "trd": NaN, "batb": [[0, 2.04, 399.52], [1, 1.01, 7]], "batl": [[0, 3.9, 160.43]]}, {"timestamp": 1631534954072, "ltp": 1.67, "tv": 0.03, "trd": NaN, "batb": [[0, 1.01, 7], [1, 1.01, 0]], "batl": NaN}, {"timestamp": 1631535115679, "ltp": 1.67, "tv": 0.03, "trd": NaN, "batb": [[0, 2.42, 386.98], [1, 1.01, 7]], "batl": [[0, 5.5, 116.65]]}, {"timestamp": 1631535307831, "ltp": 1.67, "tv": 0.03, "trd": NaN, "batb": [[0, 1.01, 7], [1, 1.01, 0]], "batl": NaN}, {"timestamp": 1631535313597, "ltp": 1.67, "tv": 0.03, "trd": NaN, "batb": [[0, 2.62, 384.48], [1, 1.01, 7]], "batl": [[0, 6.6, 100.32]]}, {"timestamp": 1631535424322, "ltp": 1.67, "tv": 0.03, "trd": NaN, "batb": [[0, 1.01, 7], [1, 1.01, 0]], "batl": NaN}, {"timestamp": 1631535430251, "ltp": 1.67, "tv": 0.03, "trd": NaN, "batb": [[0, 2.84, 380.59], [1, 1.01, 7]], "batl": [[0, 8.2, 86.64]]}, {"timestamp": 1631535441675, "ltp": 1.67, "tv": 0.03, "trd": NaN, "batb": [[0, 1.01, 7], [1, 1.01, 0]], "batl": NaN}, {"timestamp": 1631535740542, "ltp": 1.67, "tv": 0.03, "trd": NaN, "batb": [[0, 2.98, 379.44], [1, 1.01, 7]], "batl": [[0, 9.4, 79.12]]}, {"timestamp": 1631535754769, "ltp": 1.67, "tv": 0.03, "trd": NaN, "batb": NaN, "batl": [[0, 8.2, 86.64]]}, {"timestamp": 1631535765785, "ltp": 1.67, "tv": 0.03, "trd": NaN, "batb": NaN, "batl": [[0, 10.5, 73.32]]}, {"timestamp": 1631535786834, "ltp": 1.67, "tv": 0.03, "trd": NaN, "batb": [[0, 1.01, 7], [1, 1.01, 0]], "batl": NaN}, {"timestamp": 1631535792229, "ltp": 1.67, "tv": 0.03, "trd": NaN, "batb": [[0, 3.3, 378.07], [1, 1.01, 7]], "batl": [[0, 13.5, 64.97]]}, {"timestamp": 1631535821773, "ltp": 1.67, "tv": 0.03, "trd": NaN, "batb": NaN, "batl": [[0, 10.5, 73.32]]}, {"timestamp": 1631535867537, "ltp": 1.67, "tv": 0.03, "trd": NaN, "batb": NaN, "batl": [[0, 13.5, 64.97]]}, {"timestamp": 1631535947606, "ltp": 1.67, "tv": 0.03, "trd": NaN, "batb": NaN, "batl": [[0, 10.5, 73.32]]}, {"timestamp": 1631535968150, "ltp": 1.67, "tv": 0.03, "trd": NaN, "batb": NaN, "batl": [[0, 13.5, 64.97]]}, {"timestamp": 1631535988611, "ltp": 1.67, "tv": 0.03, "trd": NaN, "batb": NaN, "batl": [[0, 18, 56.98]]}, {"timestamp": 1631536020640, "ltp": 1.67, "tv": 0.03, "trd": NaN, "batb": [[0, 1.01, 7], [1, 1.01, 0]], "batl": NaN}, {"timestamp": 1631536026144, "ltp": 1.67, "tv": 0.03, "trd": NaN, "batb": [[0, 3.7, 375.92], [1, 1.01, 7]], "batl": [[0, 23, 51.95]]}, {"timestamp": 1631536049638, "ltp": 1.67, "tv": 0.03, "trd": NaN, "batb": NaN, "batl": [[0, 34, 46.71]]}, {"timestamp": 1631536086083, "ltp": 1.67, "tv": 0.03, "trd": NaN, "batb": NaN, "batl": [[0, 46, 43.55]]}, {"timestamp": 1631536115677, "ltp": 1.67, "tv": 0.03, "trd": NaN, "batb": NaN, "batl": [[0, 34, 46.71]]}, {"timestamp": 1631536164358, "ltp": 1.67, "tv": 0.03, "trd": NaN, "batb": NaN, "batl": [[0, 46, 43.55]]}, {"timestamp": 1631536184476, "ltp": 1.67, "tv": 0.03, "trd": NaN, "batb": [[0, 1.01, 7], [1, 1.01, 0]], "batl": NaN}, {"timestamp": 1631536190117, "ltp": 1.67, "tv": 0.03, "trd": NaN, "batb": [[0, 4.2, 376.06], [1, 1.01, 7]], "batl": [[0, 85, 39.67]]}, {"timestamp": 1631536222572, "ltp": 1.67, "tv": 0.03, "trd": NaN, "batb": NaN, "batl": [[0, 170, 37.49]]}, {"timestamp": 1631536345583, "ltp": 1.67, "tv": 0.03, "trd": NaN, "batb": NaN, "batl": [[0, 340, 36.38]]}, {"timestamp": 1631536359614, "ltp": 1.67, "tv": 0.03, "trd": NaN, "batb": [[0, 12, 2], [1, 4.2, 376.06], [2, 1.01, 7]], "batl": NaN}, {"timestamp": 1631536377245, "ltp": 1.67, "tv": 0.03, "trd": NaN, "batb": NaN, "batl": [[0, 170, 37.49]]}, {"timestamp": 1631536494637, "ltp": 1.67, "tv": 0.03, "trd": NaN, "batb": NaN, "batl": [[0, 60, 41.54]]}, {"timestamp": 1631536522997, "ltp": 1.67, "tv": 0.03, "trd": NaN, "batb": NaN, "batl": [[0, 170, 37.49]]}, {"timestamp": 1631536562566, "ltp": 1.67, "tv": 0.03, "trd": NaN, "batb": NaN, "batl": [[0, 60, 41.54]]}, {"timestamp": 1631536593795, "ltp": 1.67, "tv": 0.03, "trd": NaN, "batb": NaN, "batl": [[0, 170, 37.49]]}, {"timestamp": 1631536622036, "ltp": 1.67, "tv": 0.03, "trd": NaN, "batb": NaN, "batl": [[0, 60, 41.54]]}, {"timestamp": 1631536661769, "ltp": 1.67, "tv": 0.03, "trd": NaN, "batb": NaN, "batl": [[0, 170, 37.49]]}, {"timestamp": 1631536697218, "ltp": 1.67, "tv": 0.03, "trd": NaN, "batb": NaN, "batl": [[0, 60, 41.54]]}, {"timestamp": 1631536724537, "ltp": 1.67, "tv": 0.03, "trd": NaN, "batb": NaN, "batl": [[0, 46, 43.55]]}, {"timestamp": 1631536769159, "ltp": 1.67, "tv": 0.03, "trd": NaN, "batb": NaN, "batl": [[0, 60, 41.54]]}, {"timestamp": 1631536786577, "ltp": 1.67, "tv": 0.03, "trd": NaN, "batb": NaN, "batl": [[0, 46, 43.55]]}, {"timestamp": 1631536818715, "ltp": 1.67, "tv": 0.03, "trd": NaN, "batb": NaN, "batl": [[0, 85, 39.67]]}, {"timestamp": 1631536854993, "ltp": 1.67, "tv": 0.03, "trd": NaN, "batb": NaN, "batl": [[0, 60, 41.54]]}, {"timestamp": 1631536909885, "ltp": 1.67, "tv": 0.03, "trd": NaN, "batb": NaN, "batl": [[0, 46, 43.55]]}, {"timestamp": 1631536918002, "ltp": 1.67, "tv": 0.03, "trd": NaN, "batb": NaN, "batl": [[0, 34, 46.71]]}, {"timestamp": 1631536942130, "ltp": 1.67, "tv": 0.03, "trd": NaN, "batb": NaN, "batl": [[0, 60, 41.54]]}, {"timestamp": 1631536963284, "ltp": 1.67, "tv": 0.03, "trd": NaN, "batb": NaN, "batl": [[0, 85, 39.67]]}, {"timestamp": 1631536982532, "ltp": 1.67, "tv": 0.03, "trd": NaN, "batb": NaN, "batl": [[0, 34, 46.71]]}, {"timestamp": 1631537007069, "ltp": 1.67, "tv": 0.03, "trd": NaN, "batb": NaN, "batl": [[0, 60, 41.54]]}, {"timestamp": 1631537014384, "ltp": 1.67, "tv": 0.03, "trd": NaN, "batb": [[1, 1.01, 7], [2, 1.01, 0]], "batl": NaN}, {"timestamp": 1631537190070, "ltp": 1.67, "tv": 0.03, "trd": NaN, "batb": [[1, 3.4, 381.29], [2, 1.01, 7]], "batl": [[0, 15.5, 60.46]]}, {"timestamp": 1631537205597, "ltp": 12.0, "tv": 4.01, "trd": [[12, 3.98]], "batb": [[0, 3.4, 381.3], [1, 1.01, 7], [2, 1.01, 0]], "batl": NaN}, {"timestamp": 1631537211121, "ltp": 12.0, "tv": 4.01, "trd": NaN, "batb": NaN, "batl": [[0, 13.5, 64.97]]}, {"timestamp": 1631537296500, "ltp": 12.0, "tv": 4.03, "trd": [[12, 4]], "batb": [[0, 3.4, 381.29]], "batl": NaN}, {"timestamp": 1631537326538, "ltp": 12.0, "tv": 4.03, "trd": NaN, "batb": NaN, "batl": [[0, 13.5, 64.96]]}, {"timestamp": 1631537359584, "ltp": 12.0, "tv": 4.03, "trd": NaN, "batb": NaN, "batl": [[0, 21, 54.22]]}, {"timestamp": 1631537410456, "ltp": 12.0, "tv": 4.03, "trd": NaN, "batb": NaN, "batl": [[0, 15.5, 60.45]]}, {"timestamp": 1631537442730, "ltp": 12.0, "tv": 4.03, "trd": NaN, "batb": NaN, "batl": [[0, 21, 54.22]]}, {"timestamp": 1631537478052, "ltp": 12.0, "tv": 4.03, "trd": NaN, "batb": NaN, "batl": [[0, 15.5, 60.45]]}, {"timestamp": 1631537514520, "ltp": 12.0, "tv": 4.03, "trd": NaN, "batb": NaN, "batl": [[0, 10.5, 73.31]]}, {"timestamp": 1631537552860, "ltp": 12.0, "tv": 4.03, "trd": NaN, "batb": NaN, "batl": [[0, 15.5, 60.45]]}, {"timestamp": 1631537563487, "ltp": 3.4, "tv": 9.05, "trd": [[3.4, 5.02]], "batb": [[0, 3.4, 378.77]], "batl": NaN}, {"timestamp": 1631537625413, "ltp": 3.4, "tv": 9.05, "trd": NaN, "batb": NaN, "batl": [[0, 10.5, 74.14]]}, {"timestamp": 1631537658881, "ltp": 3.4, "tv": 9.05, "trd": NaN, "batb": NaN, "batl": [[0, 8.2, 87.71]]}, {"timestamp": 1631537687753, "ltp": 3.4, "tv": 9.05, "trd": NaN, "batb": [[0, 1.01, 7], [1, 1.01, 0]], "batl": NaN}, {"timestamp": 1631537694161, "ltp": 3.4, "tv": 9.05, "trd": NaN, "batb": [[0, 2.72, 380.32], [1, 1.01, 7]], "batl": [[0, 7.2, 94.64]]}, {"timestamp": 1631537734639, "ltp": 3.4, "tv": 9.05, "trd": NaN, "batb": NaN, "batl": [[0, 8.2, 87.71]]}, {"timestamp": 1631537776113, "ltp": 3.4, "tv": 9.05, "trd": NaN, "batb": NaN, "batl": [[0, 6.6, 101.63]]}, {"timestamp": 1631537818571, "ltp": 3.4, "tv": 9.05, "trd": NaN, "batb": NaN, "batl": [[0, 8.2, 87.71]]}, {"timestamp": 1631537841835, "ltp": 3.4, "tv": 9.05, "trd": NaN, "batb": NaN, "batl": [[0, 7.2, 94.64]]}, {"timestamp": 1631537850150, "ltp": 3.4, "tv": 9.05, "trd": NaN, "batb": [[0, 1.01, 7], [1, 1.01, 0]], "batl": NaN}, {"timestamp": 1631537856022, "ltp": 3.4, "tv": 9.05, "trd": NaN, "batb": [[0, 3.1, 376.19], [1, 1.01, 7]], "batl": [[0, 10.5, 74.14]]}, {"timestamp": 1631537880991, "ltp": 3.4, "tv": 9.05, "trd": NaN, "batb": NaN, "batl": [[0, 8.2, 87.71]]}, {"timestamp": 1631537901234, "ltp": 3.4, "tv": 9.05, "trd": NaN, "batb": NaN, "batl": [[0, 10.5, 74.14]]}, {"timestamp": 1631537926666, "ltp": 3.4, "tv": 9.05, "trd": NaN, "batb": NaN, "batl": [[0, 9.4, 80.04]]}, {"timestamp": 1631537940883, "ltp": 3.4, "tv": 9.05, "trd": NaN, "batb": NaN, "batl": [[0, 13.5, 65.61]]}, {"timestamp": 1631538044966, "ltp": 3.4, "tv": 9.05, "trd": [[3.4, 5.02]], "batb": [[0, 3.1, 376.13]], "batl": NaN}, {"timestamp": 1631538050999, "ltp": 3.4, "tv": 9.05, "trd": NaN, "batb": NaN, "batl": [[0, 10.5, 74.13]]}, {"timestamp": 1631538091564, "ltp": 3.4, "tv": 9.05, "trd": NaN, "batb": [[0, 1.01, 7], [1, 1.01, 0]], "batl": NaN}, {"timestamp": 1631538097257, "ltp": 3.4, "tv": 9.05, "trd": NaN, "batb": [[0, 3.4, 378.73], [1, 1.01, 7]], "batl": [[0, 15.5, 61]]}, {"timestamp": 1631538133571, "ltp": 3.4, "tv": 9.05, "trd": NaN, "batb": NaN, "batl": [[0, 21, 54.63]]}, {"timestamp": 1631538162616, "ltp": 3.4, "tv": 9.05, "trd": NaN, "batb": [[0, 1.01, 7], [1, 1.01, 0]], "batl": NaN}, {"timestamp": 1631538168620, "ltp": 3.4, "tv": 9.05, "trd": NaN, "batb": [[0, 3.9, 372.89], [1, 1.01, 7]], "batl": NaN}, {"timestamp": 1631538211602, "ltp": 3.4, "tv": 9.05, "trd": NaN, "batb": NaN, "batl": [[0, 10.5, 74.13]]}, {"timestamp": 1631538241732, "ltp": 3.4, "tv": 9.05, "trd": NaN, "batb": NaN, "batl": [[0, 15.5, 61]]}, {"timestamp": 1631538273304, "ltp": 3.4, "tv": 9.05, "trd": NaN, "batb": NaN, "batl": [[0, 23, 52.32]]}, {"timestamp": 1631538296492, "ltp": 3.4, "tv": 9.05, "trd": NaN, "batb": [[0, 1.01, 7], [1, 1.01, 0]], "batl": NaN}, {"timestamp": 1631538319900, "ltp": 3.4, "tv": 9.05, "trd": NaN, "batb": [[0, 3.4, 378.73], [1, 1.01, 7]], "batl": [[0, 15.5, 61]]}, {"timestamp": 1631538346030, "ltp": 3.4, "tv": 9.05, "trd": NaN, "batb": NaN, "batl": [[0, 10.5, 74.13]]}, {"timestamp": 1631538377402, "ltp": 3.4, "tv": 9.05, "trd": NaN, "batb": NaN, "batl": [[0, 8.2, 87.69]]}, {"timestamp": 1631538406470, "ltp": 3.4, "tv": 9.05, "trd": NaN, "batb": NaN, "batl": [[0, 5, 25.55], [1, 8.2, 87.69]]}, {"timestamp": 1631538437741, "ltp": 3.4, "tv": 9.05, "trd": NaN, "batb": [[0, 1.01, 7], [1, 1.01, 0]], "batl": [[1, 8.2, 0]]}, {"timestamp": 1631538443427, "ltp": 3.4, "tv": 9.05, "trd": NaN, "batb": [[0, 2.52, 383.24], [1, 1.01, 7]], "batl": [[1, 6, 109.05]]}, {"timestamp": 1631538459152, "ltp": 3.4, "tv": 9.05, "trd": NaN, "batb": [[0, 1.01, 7], [1, 1.01, 0]], "batl": [[1, 6, 0]]}, {"timestamp": 1631538464654, "ltp": 3.4, "tv": 9.05, "trd": NaN, "batb": [[0, 2.72, 380.25], [1, 1.01, 7]], "batl": [[1, 7.2, 94.63]]}, {"timestamp": 1631538497347, "ltp": 3.4, "tv": 9.05, "trd": NaN, "batb": [[0, 1.01, 7], [1, 1.01, 0]], "batl": [[1, 7.2, 0]]}, {"timestamp": 1631538503454, "ltp": 5.0, "tv": 34.11, "trd": [[5, 25.06]], "batb": [[0, 3.1, 376.13], [1, 1.01, 7]], "batl": [[0, 10.5, 74.62]]}, {"timestamp": 1631538504350, "ltp": 5.0, "tv": 34.6, "trd": [[5, 25.55]], "batb": NaN, "batl": [[0, 10.5, 74.13]]}, {"timestamp": 1631538515169, "ltp": 5.0, "tv": 34.6, "trd": NaN, "batb": NaN, "batl": [[0, 9.4, 80.03]]}, {"timestamp": 1631538527282, "ltp": 5.0, "tv": 34.6, "trd": NaN, "batb": NaN, "batl": [[0, 7.2, 94.63]]}, {"timestamp": 1631538555741, "ltp": 5.0, "tv": 34.6, "trd": NaN, "batb": NaN, "batl": [[0, 10.5, 74.13]]}, {"timestamp": 1631538578085, "ltp": 5.0, "tv": 34.6, "trd": NaN, "batb": [[0, 1.01, 7], [1, 1.01, 0]], "batl": NaN}, {"timestamp": 1631538584471, "ltp": 5.0, "tv": 34.6, "trd": NaN, "batb": [[0, 3.4, 378.73], [1, 1.01, 7]], "batl": [[0, 15.5, 61]]}, {"timestamp": 1631538704585, "ltp": 5.0, "tv": 34.6, "trd": NaN, "batb": NaN, "batl": [[0, 12, 69.43]]}, {"timestamp": 1631538751875, "ltp": 5.0, "tv": 34.6, "trd": NaN, "batb": NaN, "batl": [[0, 9.4, 80.03]]}, {"timestamp": 1631538779717, "ltp": 5.0, "tv": 34.6, "trd": NaN, "batb": [[0, 1.01, 7], [1, 1.01, 0]], "batl": NaN}, {"timestamp": 1631538937795, "ltp": 5.0, "tv": 34.6, "trd": NaN, "batb": [[0, 2.84, 377.52], [1, 1.01, 7]], "batl": [[0, 8.2, 87.69]]}, {"timestamp": 1631538979503, "ltp": 5.0, "tv": 34.6, "trd": NaN, "batb": NaN, "batl": [[0, 9.4, 80.03]]}, {"timestamp": 1631539018392, "ltp": 5.0, "tv": 34.6, "trd": NaN, "batb": [[0, 1.01, 7], [1, 1.01, 0]], "batl": NaN}, {"timestamp": 1631539024182, "ltp": 5.0, "tv": 34.6, "trd": NaN, "batb": [[0, 3.2, 376.77], [1, 1.01, 7]], "batl": [[0, 12, 69.43]]}, {"timestamp": 1631539068961, "ltp": 5.0, "tv": 34.6, "trd": NaN, "batb": NaN, "batl": [[0, 15.5, 61]]}, {"timestamp": 1631539103028, "ltp": 5.0, "tv": 34.6, "trd": NaN, "batb": NaN, "batl": [[0, 13.5, 65.6]]}, {"timestamp": 1631539152897, "ltp": 5.0, "tv": 34.6, "trd": NaN, "batb": NaN, "batl": [[0, 10.5, 74.13]]}, {"timestamp": 1631539182462, "ltp": 5.1, "tv": 47.38, "trd": [[5.1, 12.77]], "batb": NaN, "batl": NaN}, {"timestamp": 1631539186178, "ltp": 5.1, "tv": 47.38, "trd": NaN, "batb": NaN, "batl": [[0, 7.2, 94.63]]}, {"timestamp": 1631539206218, "ltp": 5.1, "tv": 47.38, "trd": NaN, "batb": [[0, 1.01, 7], [1, 1.01, 0]], "batl": NaN}, {"timestamp": 1631539212222, "ltp": 5.1, "tv": 47.38, "trd": NaN, "batb": [[0, 2.42, 383.37], [1, 1.01, 7]], "batl": [[0, 5.5, 118.2]]}, {"timestamp": 1631539255999, "ltp": 5.1, "tv": 47.38, "trd": NaN, "batb": [[0, 1.01, 7], [1, 1.01, 0]], "batl": NaN}, {"timestamp": 1631539262090, "ltp": 5.1, "tv": 47.38, "trd": NaN, "batb": [[0, 2.04, 395.2], [1, 1.01, 7]], "batl": [[0, 3.9, 162.6]]}, {"timestamp": 1631539283911, "ltp": 5.1, "tv": 47.38, "trd": NaN, "batb": NaN, "batl": [[0, 2.7, 42.58], [1, 3.9, 162.6]]}, {"timestamp": 1631539370779, "ltp": 5.1, "tv": 47.38, "trd": NaN, "batb": NaN, "batl": [[1, 3.9, 0]]}, {"timestamp": 1631539376483, "ltp": 5.1, "tv": 47.38, "trd": NaN, "batb": NaN, "batl": [[0, 3.65, 175.09]]}, {"timestamp": 1631539394827, "ltp": 2.24, "tv": 58.09, "trd": [[2.24, 10.71]], "batb": NaN, "batl": NaN}, {"timestamp": 1631539467483, "ltp": 2.24, "tv": 58.09, "trd": NaN, "batb": [[0, 1.01, 7], [1, 1.01, 0]], "batl": NaN}, {"timestamp": 1631539473790, "ltp": 2.24, "tv": 58.09, "trd": NaN, "batb": [[0, 2.3, 386.58], [1, 1.01, 7]], "batl": [[0, 4.9, 129.75]]}, {"timestamp": 1631539540784, "ltp": 2.24, "tv": 58.09, "trd": NaN, "batb": [[0, 1.01, 7], [1, 1.01, 0]], "batl": NaN}, {"timestamp": 1631539546714, "ltp": 2.24, "tv": 58.09, "trd": NaN, "batb": [[0, 2.52, 383.24], [1, 1.01, 7]], "batl": [[0, 6, 109.05]]}, {"timestamp": 1631539587564, "ltp": 2.24, "tv": 58.09, "trd": NaN, "batb": NaN, "batl": [[0, 3.7, 42.58], [1, 6, 109.05]]}, {"timestamp": 1631539589594, "ltp": 2.24, "tv": 58.09, "trd": NaN, "batb": NaN, "batl": [[0, 6, 109.05], [1, 6, 0]]}, {"timestamp": 1631539621522, "ltp": 2.24, "tv": 58.09, "trd": NaN, "batb": NaN, "batl": [[0, 5.3, 122.04]]}, {"timestamp": 1631539663492, "ltp": 3.25, "tv": 67.55, "trd": [[3.25, 9.46]], "batb": NaN, "batl": NaN}, {"timestamp": 1631539665583, "ltp": 3.25, "tv": 67.55, "trd": NaN, "batb": [[0, 1.01, 7], [1, 1.01, 0]], "batl": NaN}, {"timestamp": 1631539666617, "ltp": 3.25, "tv": 67.55, "trd": NaN, "batb": [[0, 3.25, 11.24], [1, 1.01, 7]], "batl": NaN}, {"timestamp": 1631539667508, "ltp": 3.25, "tv": 67.55, "trd": NaN, "batb": [[0, 3.25, 30.05]], "batl": NaN}, {"timestamp": 1631539668402, "ltp": 3.25, "tv": 67.55, "trd": NaN, "batb": [[0, 3.25, 22.48]], "batl": NaN}, {"timestamp": 1631539668818, "ltp": 3.25, "tv": 67.55, "trd": NaN, "batb": [[0, 3.25, 11.24]], "batl": NaN}, {"timestamp": 1631539669702, "ltp": 3.25, "tv": 67.55, "trd": NaN, "batb": [[0, 1.01, 7], [1, 1.01, 0]], "batl": NaN}, {"timestamp": 1631539672405, "ltp": 3.75, "tv": 76.68, "trd": [[3.75, 9.13]], "batb": [[0, 2.72, 380.41], [1, 1.01, 7]], "batl": [[0, 7.2, 94.63]]}, {"timestamp": 1631539673502, "ltp": 3.75, "tv": 76.68, "trd": NaN, "batb": [[0, 3.75, 48.73], [1, 2.72, 380.25], [2, 1.01, 7]], "batl": NaN}, {"timestamp": 1631539674596, "ltp": 3.75, "tv": 76.68, "trd": NaN, "batb": [[0, 3.75, 29.37]], "batl": NaN}, {"timestamp": 1631539675483, "ltp": 3.75, "tv": 76.68, "trd": NaN, "batb": [[0, 3.75, 15.32]], "batl": NaN}, {"timestamp": 1631539676629, "ltp": 3.75, "tv": 76.68, "trd": NaN, "batb": [[0, 3.75, 18.23]], "batl": NaN}, {"timestamp": 1631539678190, "ltp": 3.75, "tv": 76.68, "trd": NaN, "batb": [[0, 2.72, 380.25], [1, 1.01, 7], [2, 1.01, 0]], "batl": NaN}, {"timestamp": 1631539744955, "ltp": 3.75, "tv": 76.68, "trd": NaN, "batb": [[0, 1.01, 7], [1, 1.01, 0]], "batl": NaN}, {"timestamp": 1631539750948, "ltp": 3.75, "tv": 76.68, "trd": NaN, "batb": [[0, 3.1, 376.13], [1, 1.01, 7]], "batl": [[0, 10.5, 74.13]]}, {"timestamp": 1631539783408, "ltp": 3.75, "tv": 76.68, "trd": NaN, "batb": [[0, 1.01, 7], [1, 1.01, 0]], "batl": NaN}, {"timestamp": 1631539789319, "ltp": 3.75, "tv": 76.68, "trd": NaN, "batb": [[0, 3.5, 378.9], [1, 1.01, 7]], "batl": [[0, 18, 57.46]]}, {"timestamp": 1631539804744, "ltp": 3.75, "tv": 76.68, "trd": NaN, "batb": [[0, 1.01, 7], [1, 1.01, 0]], "batl": NaN}, {"timestamp": 1631539842866, "ltp": 3.75, "tv": 76.68, "trd": NaN, "batb": [[0, 3.9, 372.89], [1, 1.01, 7]], "batl": [[0, 34, 46.97]]}, {"timestamp": 1631539868709, "ltp": 3.75, "tv": 76.68, "trd": NaN, "batb": [[0, 1.01, 7], [1, 1.01, 0]], "batl": NaN}, {"timestamp": 1631539890126, "ltp": 3.75, "tv": 76.68, "trd": NaN, "batb": [[0, 3.5, 378.9], [1, 1.01, 7]], "batl": [[0, 18, 57.46]]}, {"timestamp": 1631539902074, "ltp": 3.75, "tv": 76.68, "trd": NaN, "batb": [[0, 1.01, 7], [1, 1.01, 0]], "batl": NaN}, {"timestamp": 1631539921601, "ltp": 3.75, "tv": 76.68, "trd": NaN, "batb": [[0, 4, 376.78], [1, 1.01, 7]], "batl": [[0, 46, 43.74]]}, {"timestamp": 1631539942031, "ltp": 46.0, "tv": 76.86, "trd": [[46, 0.19]], "batb": NaN, "batl": [[0, 46, 43.55]]}, {"timestamp": 1631539943745, "ltp": 46.0, "tv": 76.86, "trd": NaN, "batb": [[0, 1.01, 7], [1, 1.01, 0]], "batl": NaN}, {"timestamp": 1631539952058, "ltp": 46.0, "tv": 76.86, "trd": NaN, "batb": [[0, 4.1, 377.53], [1, 1.01, 7]], "batl": [[0, 60, 41.53]]}, {"timestamp": 1631539953051, "ltp": 46.0, "tv": 76.86, "trd": NaN, "batb": [[0, 1.01, 7], [1, 1.01, 0]], "batl": NaN}, {"timestamp": 1631539965275, "ltp": 46.0, "tv": 76.86, "trd": NaN, "batb": [[0, 3.6, 379.33], [1, 1.01, 7]], "batl": [[0, 21, 54.21]]}, {"timestamp": 1631540031066, "ltp": 46.0, "tv": 76.86, "trd": NaN, "batb": [[0, 1.01, 7], [1, 1.01, 0]], "batl": NaN}, {"timestamp": 1631540049019, "ltp": 46.0, "tv": 76.86, "trd": NaN, "batb": [[0, 3.2, 379.43], [1, 1.01, 7]], "batl": [[0, 12, 68.7]]}, {"timestamp": 1631540064412, "ltp": 46.0, "tv": 76.86, "trd": NaN, "batb": [[0, 1.01, 7], [1, 1.01, 0]], "batl": NaN}, {"timestamp": 1631540082545, "ltp": 46.0, "tv": 76.86, "trd": NaN, "batb": NaN, "batl": [[0, 26, 50.05]]}, {"timestamp": 1631540082690, "ltp": 46.0, "tv": 76.86, "trd": NaN, "batb": [[0, 3.75, 378.18], [1, 1.01, 7]], "batl": NaN}, {"timestamp": 1631540097766, "ltp": 46.0, "tv": 76.86, "trd": NaN, "batb": [[0, 1.01, 7], [1, 1.01, 0]], "batl": NaN}, {"timestamp": 1631540110475, "ltp": 46.0, "tv": 76.86, "trd": NaN, "batb": [[0, 4.4, 378.65], [1, 1.01, 7]], "batl": NaN}, {"timestamp": 1631540136447, "ltp": 46.0, "tv": 76.86, "trd": NaN, "batb": [[0, 1.01, 7], [1, 1.01, 0]], "batl": NaN}, {"timestamp": 1631540155949, "ltp": 46.0, "tv": 76.86, "trd": NaN, "batb": [[0, 4.5, 379.16], [1, 1.01, 7]], "batl": NaN}, {"timestamp": 1631540157740, "ltp": 46.0, "tv": 76.86, "trd": NaN, "batb": [[0, 1.01, 7], [1, 1.01, 0]], "batl": NaN}]}, {"runnerId": 9637020, "odds": [{"timestamp": 1631532325326, "ltp": 2.1, "tv": 5.31, "trd": [[2.1, 5.32]], "batb": [[0, 2.1, 35.31], [1, 2.08, 2.66]], "batl": NaN}, {"timestamp": 1631532326885, "ltp": 2.1, "tv": 5.31, "trd": NaN, "batb": [[0, 2.1, 37.97]], "batl": NaN}, {"timestamp": 1631532550031, "ltp": 2.1, "tv": 5.31, "trd": NaN, "batb": NaN, "batl": [[0, 3.95, 3.28]]}, {"timestamp": 1631532650985, "ltp": 2.1, "tv": 5.31, "trd": NaN, "batb": [[0, 1.01, 7], [1, 2.08, 0], [2, 1.01, 0]], "batl": NaN}, {"timestamp": 1631538044966, "ltp": 2.1, "tv": 5.32, "trd": [[2.1, 5.32]], "batb": NaN, "batl": NaN}, {"timestamp": 1631538453052, "ltp": 2.1, "tv": 5.32, "trd": NaN, "batb": NaN, "batl": [[0, 1.5, 57.65]]}, {"timestamp": 1631538454471, "ltp": 2.1, "tv": 5.32, "trd": NaN, "batb": [[0, 1.26, 57.65], [1, 1.01, 7]], "batl": NaN}, {"timestamp": 1631538455562, "ltp": 2.1, "tv": 5.32, "trd": NaN, "batb": [[0, 1.26, 172.95]], "batl": NaN}, {"timestamp": 1631538461743, "ltp": 2.1, "tv": 5.32, "trd": NaN, "batb": [[0, 1.01, 7], [1, 1.01, 0]], "batl": NaN}, {"timestamp": 1631538467788, "ltp": 2.1, "tv": 5.32, "trd": NaN, "batb": NaN, "batl": [[0, 1.4, 255.49], [1, 1.5, 57.65]]}, {"timestamp": 1631538470558, "ltp": 2.1, "tv": 5.32, "trd": NaN, "batb": NaN, "batl": [[1, 1.5, 0]]}, {"timestamp": 1631538477317, "ltp": 2.1, "tv": 5.32, "trd": NaN, "batb": NaN, "batl": [[0, 1.36, 57.65], [1, 1.4, 255.49]]}, {"timestamp": 1631538497347, "ltp": 2.1, "tv": 5.32, "trd": NaN, "batb": NaN, "batl": [[0, 1.4, 255.49], [1, 1.4, 0]]}, {"timestamp": 1631538503454, "ltp": 1.25, "tv": 105.55, "trd": [[1.25, 100.23]], "batb": NaN, "batl": NaN}, {"timestamp": 1631538504350, "ltp": 1.25, "tv": 107.52, "trd": [[1.25, 102.21]], "batb": NaN, "batl": [[0, 1.25, 274.81]]}, {"timestamp": 1631538505082, "ltp": 1.25, "tv": 107.52, "trd": NaN, "batb": NaN, "batl": [[0, 1.23, 255.49], [1, 1.25, 291.84]]}, {"timestamp": 1631538506440, "ltp": 1.25, "tv": 107.52, "trd": NaN, "batb": NaN, "batl": [[1, 1.25, 338.68]]}, {"timestamp": 1631538507271, "ltp": 1.25, "tv": 107.52, "trd": NaN, "batb": NaN, "batl": [[1, 1.25, 332.72]]}, {"timestamp": 1631538508574, "ltp": 1.25, "tv": 107.52, "trd": NaN, "batb": NaN, "batl": [[1, 1.25, 253.52]]}, {"timestamp": 1631538509466, "ltp": 1.25, "tv": 107.52, "trd": NaN, "batb": NaN, "batl": [[0, 1.25, 253.52], [1, 1.25, 0]]}, {"timestamp": 1631538512181, "ltp": 1.25, "tv": 107.52, "trd": NaN, "batb": [[0, 1.12, 255.49], [1, 1.01, 7]], "batl": NaN}, {"timestamp": 1631538515169, "ltp": 1.25, "tv": 107.52, "trd": NaN, "batb": [[0, 1.23, 2.01], [1, 1.12, 255.49], [2, 1.01, 7]], "batl": NaN}, {"timestamp": 1631538521172, "ltp": 1.25, "tv": 107.52, "trd": NaN, "batb": NaN, "batl": [[0, 1.28, 255.49]]}, {"timestamp": 1631538527282, "ltp": 1.25, "tv": 107.52, "trd": NaN, "batb": [[0, 1.28, 1.93], [1, 1.23, 2.01], [2, 1.12, 255.49]], "batl": NaN}, {"timestamp": 1631538528881, "ltp": 1.25, "tv": 107.52, "trd": NaN, "batb": NaN, "batl": [[0, 1.42, 255.49]]}, {"timestamp": 1631538532391, "ltp": 1.25, "tv": 107.52, "trd": NaN, "batb": [[1, 1.12, 255.49], [2, 1.01, 7]], "batl": NaN}, {"timestamp": 1631538550828, "ltp": 1.25, "tv": 107.52, "trd": NaN, "batb": [[0, 1.12, 255.49], [1, 1.01, 7], [2, 1.01, 0]], "batl": NaN}, {"timestamp": 1631538553706, "ltp": 1.25, "tv": 107.52, "trd": NaN, "batb": NaN, "batl": [[0, 1.24, 255.49], [1, 1.42, 255.49]]}, {"timestamp": 1631538558215, "ltp": 1.25, "tv": 107.52, "trd": NaN, "batb": [[0, 1.2, 2.06], [1, 1.12, 255.49], [2, 1.01, 7]], "batl": NaN}, {"timestamp": 1631538580400, "ltp": 1.25, "tv": 107.52, "trd": NaN, "batb": [[0, 1.12, 255.49], [1, 1.01, 7], [2, 1.01, 0]], "batl": NaN}, {"timestamp": 1631538582487, "ltp": 1.25, "tv": 107.52, "trd": NaN, "batb": NaN, "batl": [[1, 1.42, 0]]}, {"timestamp": 1631538583269, "ltp": 1.25, "tv": 107.52, "trd": NaN, "batb": [[0, 1.01, 7], [1, 1.01, 0]], "batl": NaN}, {"timestamp": 1631538585984, "ltp": 1.25, "tv": 107.52, "trd": NaN, "batb": NaN, "batl": [[0, 1.16, 255.49], [1, 1.24, 255.49]]}, {"timestamp": 1631538588977, "ltp": 1.25, "tv": 107.52, "trd": NaN, "batb": [[0, 1.08, 255.49], [1, 1.01, 7]], "batl": NaN}, {"timestamp": 1631538599607, "ltp": 1.25, "tv": 107.52, "trd": NaN, "batb": [[0, 1.09, 115.3], [1, 1.08, 255.49], [2, 1.01, 7]], "batl": NaN}, {"timestamp": 1631538600398, "ltp": 1.25, "tv": 107.52, "trd": NaN, "batb": [[0, 1.09, 172.95]], "batl": NaN}, {"timestamp": 1631538650106, "ltp": 1.25, "tv": 107.52, "trd": NaN, "batb": [[0, 1.09, 230.6]], "batl": NaN}, {"timestamp": 1631538699482, "ltp": 1.25, "tv": 107.52, "trd": NaN, "batb": NaN, "batl": [[0, 1.24, 255.49], [1, 1.24, 0]]}, {"timestamp": 1631538706682, "ltp": 1.25, "tv": 107.52, "trd": NaN, "batb": [[0, 1.2, 2.06], [1, 1.09, 230.6], [2, 1.08, 255.49]], "batl": NaN}, {"timestamp": 1631538733824, "ltp": 1.25, "tv": 107.52, "trd": NaN, "batb": [[1, 1.08, 255.49], [2, 1.01, 7]], "batl": NaN}, {"timestamp": 1631538842519, "ltp": 1.25, "tv": 107.52, "trd": NaN, "batb": [[0, 1.08, 255.49], [1, 1.01, 7], [2, 1.01, 0]], "batl": NaN}, {"timestamp": 1631538846867, "ltp": 1.25, "tv": 107.52, "trd": NaN, "batb": NaN, "batl": [[0, 1.2, 255.49]]}, {"timestamp": 1631538898732, "ltp": 1.25, "tv": 107.52, "trd": NaN, "batb": NaN, "batl": [[0, 1.3, 255.49]]}, {"timestamp": 1631538900029, "ltp": 1.25, "tv": 107.52, "trd": NaN, "batb": [[0, 1.2, 2.17], [1, 1.08, 255.49], [2, 1.01, 7]], "batl": NaN}, {"timestamp": 1631538938829, "ltp": 1.25, "tv": 107.52, "trd": NaN, "batb": [[1, 1.01, 7], [2, 1.01, 0]], "batl": NaN}, {"timestamp": 1631538940302, "ltp": 1.25, "tv": 107.52, "trd": NaN, "batb": NaN, "batl": [[0, 1.34, 255.49]]}, {"timestamp": 1631538940715, "ltp": 1.25, "tv": 107.52, "trd": NaN, "batb": NaN, "batl": [[1, 1.35, 255.49]]}, {"timestamp": 1631538942612, "ltp": 1.25, "tv": 107.52, "trd": NaN, "batb": [[1, 1.17, 255.49], [2, 1.16, 255.49]], "batl": NaN}, {"timestamp": 1631538949523, "ltp": 1.25, "tv": 107.52, "trd": NaN, "batb": [[0, 1.17, 255.49], [1, 1.16, 255.49], [2, 1.01, 7]], "batl": NaN}, {"timestamp": 1631538970715, "ltp": 1.25, "tv": 107.52, "trd": NaN, "batb": [[1, 1.01, 7], [2, 1.01, 0]], "batl": NaN}, {"timestamp": 1631538975511, "ltp": 1.25, "tv": 107.52, "trd": NaN, "batb": NaN, "batl": [[1, 1.35, 0]]}, {"timestamp": 1631538979745, "ltp": 1.25, "tv": 107.52, "trd": NaN, "batb": NaN, "batl": [[0, 1.28, 255.49]]}, {"timestamp": 1631539019643, "ltp": 1.25, "tv": 107.52, "trd": NaN, "batb": [[0, 1.01, 7], [1, 1.01, 0]], "batl": NaN}, {"timestamp": 1631539023291, "ltp": 1.25, "tv": 107.52, "trd": NaN, "batb": NaN, "batl": [[0, 1.17, 255.49], [1, 1.28, 255.49]]}, {"timestamp": 1631539025375, "ltp": 1.25, "tv": 107.52, "trd": NaN, "batb": [[0, 1.11, 255.49], [1, 1.01, 7]], "batl": [[0, 1.28, 255.49], [1, 1.28, 0]]}, {"timestamp": 1631539027099, "ltp": 1.25, "tv": 107.52, "trd": NaN, "batb": NaN, "batl": [[0, 1.22, 255.49], [1, 1.28, 255.49]]}, {"timestamp": 1631539068169, "ltp": 1.25, "tv": 107.52, "trd": NaN, "batb": [[0, 1.01, 7], [1, 1.01, 0]], "batl": NaN}, {"timestamp": 1631539073768, "ltp": 1.25, "tv": 107.52, "trd": NaN, "batb": [[0, 1.08, 255.49], [1, 1.01, 7]], "batl": NaN}, {"timestamp": 1631539147293, "ltp": 1.25, "tv": 107.52, "trd": NaN, "batb": NaN, "batl": [[0, 1.28, 255.49], [1, 1.28, 0]]}, {"timestamp": 1631539162413, "ltp": 1.25, "tv": 107.52, "trd": NaN, "batb": NaN, "batl": [[0, 1.24, 255.49], [1, 1.28, 255.49]]}, {"timestamp": 1631539182462, "ltp": 1.24, "tv": 160.06, "trd": [[1.24, 52.54]], "batb": NaN, "batl": [[0, 1.24, 202.96]]}, {"timestamp": 1631539186178, "ltp": 1.24, "tv": 160.06, "trd": NaN, "batb": NaN, "batl": [[0, 1.28, 255.49], [1, 1.28, 0]]}, {"timestamp": 1631539191292, "ltp": 1.24, "tv": 160.06, "trd": NaN, "batb": [[0, 1.24, 54.53], [1, 1.08, 255.49], [2, 1.01, 7]], "batl": NaN}, {"timestamp": 1631539192769, "ltp": 1.24, "tv": 160.06, "trd": NaN, "batb": NaN, "batl": [[0, 1.44, 255.49]]}, {"timestamp": 1631539194501, "ltp": 1.24, "tv": 160.06, "trd": NaN, "batb": [[0, 1.3, 52.01], [1, 1.24, 54.53], [2, 1.08, 255.49]], "batl": NaN}, {"timestamp": 1631539213901, "ltp": 1.24, "tv": 160.06, "trd": NaN, "batb": [[0, 1.36, 255.49], [1, 1.3, 52.01], [2, 1.24, 54.53]], "batl": NaN}, {"timestamp": 1631539214730, "ltp": 1.24, "tv": 160.06, "trd": NaN, "batb": [[0, 1.42, 47.62], [1, 1.36, 255.49], [2, 1.3, 52.01]], "batl": NaN}, {"timestamp": 1631539216615, "ltp": 1.24, "tv": 160.06, "trd": NaN, "batb": NaN, "batl": [[0, 1.55, 255.49]]}, {"timestamp": 1631539224331, "ltp": 1.24, "tv": 160.06, "trd": NaN, "batb": [[1, 1.3, 52.01], [2, 1.22, 1.81]], "batl": NaN}, {"timestamp": 1631539235551, "ltp": 1.42, "tv": 164.06, "trd": [[1.42, 4]], "batb": [[0, 1.42, 45.61]], "batl": NaN}, {"timestamp": 1631539262767, "ltp": 1.42, "tv": 164.06, "trd": NaN, "batb": [[0, 1.47, 255.49], [1, 1.42, 45.61], [2, 1.3, 52.01]], "batl": NaN}, {"timestamp": 1631539265169, "ltp": 1.42, "tv": 164.06, "trd": NaN, "batb": [[1, 1.3, 52.01], [2, 1.22, 1.81]], "batl": NaN}, {"timestamp": 1631539266476, "ltp": 1.42, "tv": 164.06, "trd": NaN, "batb": [[0, 1.56, 41.53], [1, 1.47, 255.49], [2, 1.3, 52.01]], "batl": NaN}, {"timestamp": 1631539268666, "ltp": 1.42, "tv": 164.06, "trd": NaN, "batb": NaN, "batl": [[0, 1.7, 255.49]]}, {"timestamp": 1631539273894, "ltp": 1.42, "tv": 164.06, "trd": NaN, "batb": [[1, 1.3, 52.01], [2, 1.22, 1.81]], "batl": NaN}, {"timestamp": 1631539275199, "ltp": 1.42, "tv": 164.06, "trd": NaN, "batb": [[1, 1.22, 1.81], [2, 1.08, 255.49]], "batl": NaN}, {"timestamp": 1631539288811, "ltp": 1.42, "tv": 164.06, "trd": NaN, "batb": [[0, 1.22, 1.81], [1, 1.08, 255.49], [2, 1.01, 7]], "batl": NaN}, {"timestamp": 1631539291951, "ltp": 1.42, "tv": 164.06, "trd": NaN, "batb": [[0, 1.61, 40.23], [1, 1.22, 1.81], [2, 1.08, 255.49]], "batl": NaN}, {"timestamp": 1631539345949, "ltp": 1.61, "tv": 176.07, "trd": [[1.61, 12]], "batb": [[0, 1.61, 34.23]], "batl": NaN}, {"timestamp": 1631539368585, "ltp": 1.61, "tv": 176.07, "trd": NaN, "batb": [[1, 1.08, 255.49], [2, 1.01, 7]], "batl": NaN}, {"timestamp": 1631539378360, "ltp": 1.7, "tv": 216.06, "trd": [[1.7, 40]], "batb": [[0, 1.7, 12.42], [1, 1.61, 34.23], [2, 1.08, 255.49]], "batl": NaN}, {"timestamp": 1631539379085, "ltp": 1.7, "tv": 216.06, "trd": NaN, "batb": [[1, 1.08, 255.49], [2, 1.01, 7]], "batl": NaN}, {"timestamp": 1631539379979, "ltp": 1.7, "tv": 216.06, "trd": NaN, "batb": NaN, "batl": [[0, 1.8, 255.49]]}, {"timestamp": 1631539394827, "ltp": 1.8, "tv": 229.39, "trd": [[1.8, 13.33]], "batb": NaN, "batl": [[0, 1.8, 242.16]]}, {"timestamp": 1631539412642, "ltp": 1.8, "tv": 229.39, "trd": NaN, "batb": [[1, 1.37, 25], [2, 1.08, 255.49]], "batl": NaN}, {"timestamp": 1631539419141, "ltp": 1.7, "tv": 239.39, "trd": [[1.7, 50]], "batb": [[0, 1.7, 7.42]], "batl": NaN}, {"timestamp": 1631539424285, "ltp": 1.7, "tv": 239.39, "trd": NaN, "batb": [[0, 1.37, 25], [1, 1.08, 255.49], [2, 1.01, 7]], "batl": NaN}, {"timestamp": 1631539429777, "ltp": 1.7, "tv": 239.39, "trd": NaN, "batb": NaN, "batl": [[0, 1.7, 255.49], [1, 1.8, 242.16]]}, {"timestamp": 1631539432087, "ltp": 1.7, "tv": 239.39, "trd": NaN, "batb": [[0, 1.6, 22.88], [1, 1.37, 25], [2, 1.08, 255.49]], "batl": NaN}, {"timestamp": 1631539467483, "ltp": 1.7, "tv": 239.39, "trd": NaN, "batb": [[0, 1.37, 25], [1, 1.08, 255.49], [2, 1.01, 7]], "batl": NaN}, {"timestamp": 1631539473378, "ltp": 1.7, "tv": 239.39, "trd": NaN, "batb": NaN, "batl": [[0, 1.6, 255.49], [1, 1.7, 255.49], [2, 1.8, 242.16]]}, {"timestamp": 1631539479587, "ltp": 1.7, "tv": 239.39, "trd": NaN, "batb": NaN, "batl": [[1, 1.7, 0], [2, 1.8, 0]]}, {"timestamp": 1631539481303, "ltp": 1.7, "tv": 239.39, "trd": NaN, "batb": [[0, 1.44, 25.42], [1, 1.37, 25], [2, 1.08, 255.49]], "batl": NaN}, {"timestamp": 1631539485488, "ltp": 1.7, "tv": 239.39, "trd": NaN, "batb": NaN, "batl": [[0, 1.5, 255.49]]}, {"timestamp": 1631539540784, "ltp": 1.7, "tv": 239.39, "trd": NaN, "batb": [[0, 1.37, 25], [1, 1.08, 255.49], [2, 1.01, 7]], "batl": NaN}, {"timestamp": 1631539550996, "ltp": 1.7, "tv": 239.39, "trd": NaN, "batb": NaN, "batl": [[0, 1.45, 255.49], [1, 1.5, 255.49]]}, {"timestamp": 1631539552094, "ltp": 1.7, "tv": 239.39, "trd": NaN, "batb": [[0, 1.37, 51.72]], "batl": NaN}, {"timestamp": 1631539615192, "ltp": 1.7, "tv": 239.39, "trd": NaN, "batb": NaN, "batl": [[0, 1.5, 255.49], [1, 1.5, 0]]}, {"timestamp": 1631539621522, "ltp": 1.7, "tv": 239.39, "trd": NaN, "batb": [[0, 1.45, 25.24], [1, 1.37, 51.72], [2, 1.08, 255.49]], "batl": NaN}, {"timestamp": 1631539663492, "ltp": 1.45, "tv": 260.6, "trd": [[1.45, 21.21]], "batb": [[0, 1.45, 4.04]], "batl": NaN}, {"timestamp": 1631539666617, "ltp": 1.45, "tv": 260.6, "trd": NaN, "batb": [[0, 1.37, 51.72], [1, 1.08, 255.49], [2, 1.01, 7]], "batl": NaN}, {"timestamp": 1631539667508, "ltp": 1.45, "tv": 260.6, "trd": NaN, "batb": [[0, 1.37, 25]], "batl": NaN}, {"timestamp": 1631539672405, "ltp": 1.37, "tv": 285.6, "trd": [[1.37, 25]], "batb": [[0, 1.08, 255.49], [1, 1.01, 7], [2, 1.01, 0]], "batl": NaN}, {"timestamp": 1631539674596, "ltp": 1.37, "tv": 285.6, "trd": NaN, "batb": NaN, "batl": [[0, 1.4, 255.49], [1, 1.5, 255.49]]}, {"timestamp": 1631539675483, "ltp": 1.37, "tv": 285.6, "trd": NaN, "batb": NaN, "batl": [[0, 1.37, 5.4], [1, 1.4, 255.49], [2, 1.5, 255.49]]}, {"timestamp": 1631539678190, "ltp": 1.37, "tv": 285.6, "trd": NaN, "batb": NaN, "batl": [[0, 1.4, 255.49], [1, 1.5, 255.49], [2, 1.5, 0]]}, {"timestamp": 1631539682107, "ltp": 1.37, "tv": 285.6, "trd": NaN, "batb": [[0, 1.2, 57.65], [1, 1.08, 255.49], [2, 1.01, 7]], "batl": NaN}, {"timestamp": 1631539682936, "ltp": 1.37, "tv": 285.6, "trd": NaN, "batb": [[0, 1.2, 115.3]], "batl": NaN}, {"timestamp": 1631539688246, "ltp": 1.37, "tv": 285.6, "trd": NaN, "batb": [[0, 1.3, 4.51], [1, 1.2, 115.3], [2, 1.08, 255.49]], "batl": NaN}, {"timestamp": 1631539690451, "ltp": 1.37, "tv": 285.6, "trd": NaN, "batb": [[1, 1.2, 230.6]], "batl": [[1, 1.5, 0]]}, {"timestamp": 1631539738028, "ltp": 1.37, "tv": 285.6, "trd": NaN, "batb": [[1, 1.08, 255.49], [2, 1.01, 7]], "batl": NaN}, {"timestamp": 1631539746835, "ltp": 1.37, "tv": 285.6, "trd": NaN, "batb": [[0, 1.08, 255.49], [1, 1.01, 7], [2, 1.01, 0]], "batl": NaN}, {"timestamp": 1631539752557, "ltp": 1.37, "tv": 285.6, "trd": NaN, "batb": NaN, "batl": [[0, 1.3, 31]]}, {"timestamp": 1631539753448, "ltp": 1.37, "tv": 285.6, "trd": NaN, "batb": NaN, "batl": [[0, 1.3, 286.49]]}, {"timestamp": 1631539754274, "ltp": 1.37, "tv": 285.6, "trd": NaN, "batb": NaN, "batl": [[0, 1.24, 255.49], [1, 1.3, 255.49]]}, {"timestamp": 1631539759457, "ltp": 1.37, "tv": 285.6, "trd": NaN, "batb": [[0, 1.12, 57.65], [1, 1.08, 255.49], [2, 1.01, 7]], "batl": NaN}, {"timestamp": 1631539759878, "ltp": 1.37, "tv": 285.6, "trd": NaN, "batb": [[0, 1.12, 172.95]], "batl": NaN}, {"timestamp": 1631539770593, "ltp": 1.37, "tv": 285.6, "trd": NaN, "batb": [[0, 1.12, 230.6]], "batl": NaN}, {"timestamp": 1631539784300, "ltp": 1.37, "tv": 285.6, "trd": NaN, "batb": [[1, 1.01, 7], [2, 1.01, 0]], "batl": NaN}, {"timestamp": 1631539787432, "ltp": 1.37, "tv": 285.6, "trd": NaN, "batb": NaN, "batl": [[1, 1.3, 0]]}, {"timestamp": 1631539790935, "ltp": 1.37, "tv": 285.6, "trd": NaN, "batb": NaN, "batl": [[0, 1.15, 255.49], [1, 1.24, 255.49]]}, {"timestamp": 1631539801234, "ltp": 1.37, "tv": 285.6, "trd": NaN, "batb": [[0, 1.01, 7], [1, 1.01, 0]], "batl": NaN}, {"timestamp": 1631539818702, "ltp": 1.37, "tv": 285.6, "trd": NaN, "batb": [[0, 1.13, 5.19], [1, 1.01, 7]], "batl": NaN}, {"timestamp": 1631539838643, "ltp": 1.37, "tv": 285.6, "trd": NaN, "batb": [[0, 1.01, 7], [1, 1.01, 0]], "batl": NaN}, {"timestamp": 1631539841140, "ltp": 1.37, "tv": 285.6, "trd": NaN, "batb": NaN, "batl": [[1, 1.24, 0]]}, {"timestamp": 1631539844535, "ltp": 1.37, "tv": 285.6, "trd": NaN, "batb": NaN, "batl": [[0, 1.13, 255.49], [1, 1.15, 255.49]]}, {"timestamp": 1631539845261, "ltp": 1.37, "tv": 285.6, "trd": NaN, "batb": [[0, 1.04, 115.3], [1, 1.01, 7]], "batl": NaN}, {"timestamp": 1631539846162, "ltp": 1.37, "tv": 285.6, "trd": NaN, "batb": [[0, 1.04, 172.95], [1, 1.03, 57.65], [2, 1.01, 7]], "batl": NaN}, {"timestamp": 1631539847579, "ltp": 1.37, "tv": 285.6, "trd": NaN, "batb": [[0, 1.04, 428.44], [1, 1.03, 115.3], [2, 1.02, 115.3]], "batl": NaN}, {"timestamp": 1631539880529, "ltp": 1.04, "tv": 289.6, "trd": [[1.04, 4]], "batb": [[0, 1.04, 426.44]], "batl": NaN}, {"timestamp": 1631539881258, "ltp": 1.04, "tv": 289.6, "trd": NaN, "batb": [[0, 1.04, 255.49], [1, 1.01, 7], [2, 1.02, 0]], "batl": NaN}, {"timestamp": 1631539886217, "ltp": 1.04, "tv": 289.6, "trd": NaN, "batb": NaN, "batl": [[0, 1.15, 255.49], [1, 1.15, 0]]}, {"timestamp": 1631539892537, "ltp": 1.04, "tv": 289.6, "trd": NaN, "batb": [[0, 1.07, 230.6], [1, 1.04, 255.49], [2, 1.01, 7]], "batl": NaN}, {"timestamp": 1631539892745, "ltp": 1.04, "tv": 289.6, "trd": NaN, "batb": [[0, 1.07, 288.25]], "batl": NaN}, {"timestamp": 1631539917685, "ltp": 1.04, "tv": 289.6, "trd": NaN, "batb": [[0, 1.04, 255.49], [1, 1.01, 7], [2, 1.01, 0]], "batl": NaN}, {"timestamp": 1631539930194, "ltp": 1.04, "tv": 289.6, "trd": NaN, "batb": [[0, 1.01, 7], [1, 1.01, 0]], "batl": NaN}, {"timestamp": 1631539942031, "ltp": 1.02, "tv": 298.11, "trd": [[1.02, 8.52]], "batb": NaN, "batl": NaN}, {"timestamp": 1631539967570, "ltp": 1.02, "tv": 298.11, "trd": NaN, "batb": [[0, 1.07, 200], [1, 1.01, 7]], "batl": NaN}, {"timestamp": 1631539967988, "ltp": 1.02, "tv": 298.11, "trd": NaN, "batb": [[0, 1.07, 400]], "batl": NaN}, {"timestamp": 1631540044699, "ltp": 1.02, "tv": 298.11, "trd": NaN, "batb": [[0, 1.01, 7], [1, 1.01, 0]], "batl": NaN}, {"timestamp": 1631540102568, "ltp": 1.01, "tv": 312.11, "trd": [[1.01, 14]], "batb": NaN, "batl": [[0, 1.01, 1.52]]}, {"timestamp": 1631540111271, "ltp": 1.01, "tv": 312.11, "trd": NaN, "batb": [[0, 1.01, 100]], "batl": [[0, 1.09, 255.49]]}, {"timestamp": 1631540112370, "ltp": 1.01, "tv": 312.11, "trd": NaN, "batb": [[0, 1.01, 400]], "batl": NaN}, {"timestamp": 1631540113679, "ltp": 1.01, "tv": 312.11, "trd": NaN, "batb": [[0, 1.01, 500]], "batl": NaN}, {"timestamp": 1631540115478, "ltp": 1.01, "tv": 312.11, "trd": NaN, "batb": [[0, 1.01, 600]], "batl": NaN}, {"timestamp": 1631540126221, "ltp": 1.01, "tv": 1511.23, "trd": [[1.01, 1213.12]], "batb": [[0, 1.01, 0.44]], "batl": NaN}, {"timestamp": 1631540138128, "ltp": 1.01, "tv": 1511.23, "trd": NaN, "batb": [[0, 1.01, 400.44]], "batl": NaN}, {"timestamp": 1631540159207, "ltp": 1.01, "tv": 1511.23, "trd": NaN, "batb": NaN, "batl": [[0, 1.1, 2]]}, {"timestamp": 1631540160154, "ltp": 1.01, "tv": 1511.23, "trd": NaN, "batb": NaN, "batl": [[0, 1.1, 10]]}, {"timestamp": 1631540162487, "ltp": 1.01, "tv": 1511.23, "trd": NaN, "batb": NaN, "batl": [[0, 1.1, 16]]}, {"timestamp": 1631540177101, "ltp": 1.01, "tv": 1511.23, "trd": NaN, "batb": NaN, "batl": [[0, 1.01, 600]]}, {"timestamp": 1631540189624, "ltp": 1.01, "tv": 1511.23, "trd": NaN, "batb": NaN, "batl": [[1, 1.09, 43.55]]}]}]}