{"info": {"id": "1.187594318", "eventId": "30897871", "eventName": "Match Odds", "marketType": "MATCH_ODDS", "openDate": 1631530857316, "name": "E Silva v H Kuwata", "numberOfActiveRunner": 2, "countryCode": "", "sport": "TENNIS", "venue": "", "volume": {"total": 725.41, "preMatch": 72.96, "inPlay": 652.45}, "winner": {"id": 9183341, "name": "E Silva", "status": "WINNER", "position": 1}, "delay": 5}, "runners": [{"id": 9183341, "name": "E Silva", "status": "WINNER", "position": 1, "inPlayOdds": 1.5, "inPlayTime": 1631531919593, "avgPrematch": 0, "closedOdds": 1.01, "maxPrematch": -100, "minPrematch": 1001, "maxInPlay": 3.95, "minInPlay": 1.01, "inPlayIndex": 0, "lengthOdds": 171, "lengthOddsPrematch": 0, "lengthOddsInPlay": 171, "tradedVolume": 342.26, "preMatchVolume": 48.64, "inPlayVolume": 293.62}, {"id": 9628686, "name": "H Kuwata", "status": "LOSER", "position": 2, "inPlayOdds": 3.0, "inPlayTime": 1631531919593, "avgPrematch": 0, "closedOdds": 2.42, "maxPrematch": -100, "minPrematch": 1001, "maxInPlay": 3.0, "minInPlay": 1.22, "inPlayIndex": 0, "lengthOdds": 189, "lengthOddsPrematch": 0, "lengthOddsInPlay": 189, "tradedVolume": 383.15, "preMatchVolume": 24.32, "inPlayVolume": 358.83}], "marketUpdates": [{"timestamp": 1631518387236000000, "openDate": "2021-09-13T10:30:00.000Z", "status": "OPEN", "betDelay": 0, "inPlay": false, "complete": true}, {"timestamp": 1631522764138000000, "openDate": "2021-09-13T11:00:00.000Z", "status": "OPEN", "betDelay": 0, "inPlay": false, "complete": true}, {"timestamp": 1631526208625000000, "openDate": "2021-09-13T11:15:00.000Z", "status": "OPEN", "betDelay": 0, "inPlay": false, "complete": true}, {"timestamp": 1631527853934000000, "openDate": "2021-09-13T11:35:00.000Z", "status": "OPEN", "betDelay": 0, "inPlay": false, "complete": true}, {"timestamp": 1631530622442000000, "openDate": "2021-09-13T11:00:00.000Z", "status": "OPEN", "betDelay": 0, "inPlay": false, "complete": true}, {"timestamp": 1631530857316000000, "openDate": "2021-09-13T11:00:00.000Z", "status": "OPEN", "betDelay": 5, "inPlay": true, "complete": true}, {"timestamp": 1631531633842000000, "openDate": "2021-09-13T11:10:00.000Z", "status": "OPEN", "betDelay": 5, "inPlay": true, "complete": true}, {"timestamp": 1631531820848000000, "openDate": "2021-09-13T11:16:57.000Z", "status": "OPEN", "betDelay": 5, "inPlay": true, "complete": true}, {"timestamp": 1631537837933000000, "openDate": "2021-09-13T11:16:57.000Z", "status": "SUSPENDED", "betDelay": 5, "inPlay": true, "complete": true}, {"timestamp": 1631537842965000000, "openDate": "2021-09-13T11:16:57.000Z", "status": "CLOSED", "betDelay": 5, "inPlay": true, "complete": true}], "odds": [{"runnerId": 9183341, "odds": [{"timestamp": 1631531919593, "ltp": 1.5, "tv": 48.64, "trd": [[1.5, 48.64]], "batb": NaN, "batl": [[0, 1.5, 1.36]]}, {"timestamp": 1631531921571, "ltp": 1.5, "tv": 50.0, "trd": [[1.5, 50]], "batb": NaN, "batl": [[0, 1.57, 50], [1, 1.57, 0]]}, {"timestamp": 1631531944490, "ltp": 1.57, "tv": 100.0, "trd": [[1.57, 50]], "batb": NaN, "batl": NaN}, {"timestamp": 1631532614619, "ltp": 1.57, "tv": 100.0, "trd": NaN, "batb": [[0, 1.11, 216.97], [1, 1.01, 7]], "batl": NaN}, {"timestamp": 1631533375191, "ltp": 2.46, "tv": 113.82, "trd": [[2.46, 13.82]], "batb": NaN, "batl": NaN}, {"timestamp": 1631533612728, "ltp": 2.46, "tv": 113.82, "trd": NaN, "batb": [[0, 1.7, 10.85], [1, 1.11, 216.97], [2, 1.01, 7]], "batl": NaN}, {"timestamp": 1631533850103, "ltp": 2.46, "tv": 113.82, "trd": NaN, "batb": [[0, 1.11, 216.97], [1, 1.01, 7], [2, 1.01, 0]], "batl": NaN}, {"timestamp": 1631533855249, "ltp": 2.46, "tv": 113.82, "trd": NaN, "batb": [[0, 1.6, 10.85], [1, 1.11, 216.97], [2, 1.01, 7]], "batl": NaN}, {"timestamp": 1631534157105, "ltp": 2.46, "tv": 113.82, "trd": NaN, "batb": [[1, 1.01, 7], [2, 1.01, 0]], "batl": NaN}, {"timestamp": 1631534186156, "ltp": 2.46, "tv": 113.82, "trd": NaN, "batb": [[0, 1.61, 2], [1, 1.6, 10.85], [2, 1.01, 7]], "batl": NaN}, {"timestamp": 1631534215829, "ltp": 2.46, "tv": 113.82, "trd": NaN, "batb": [[0, 1.6, 10.85], [1, 1.01, 7], [2, 1.01, 0]], "batl": NaN}, {"timestamp": 1631535163250, "ltp": 2.46, "tv": 113.82, "trd": NaN, "batb": [[0, 3.4, 12.5], [1, 1.6, 10.85], [2, 1.01, 7]], "batl": NaN}, {"timestamp": 1631535174777, "ltp": 2.46, "tv": 113.82, "trd": NaN, "batb": [[0, 1.6, 10.85], [1, 1.01, 7], [2, 1.01, 0]], "batl": NaN}, {"timestamp": 1631535179665, "ltp": 2.46, "tv": 113.82, "trd": NaN, "batb": [[0, 4, 10], [1, 1.6, 10.85], [2, 1.01, 7]], "batl": NaN}, {"timestamp": 1631535212536, "ltp": 2.46, "tv": 113.82, "trd": NaN, "batb": [[0, 1.6, 10.85], [1, 1.01, 7], [2, 1.01, 0]], "batl": NaN}, {"timestamp": 1631535217545, "ltp": 2.46, "tv": 113.82, "trd": NaN, "batb": [[0, 3.7, 11.11], [1, 1.6, 10.85], [2, 1.01, 7]], "batl": NaN}, {"timestamp": 1631535304287, "ltp": 2.46, "tv": 113.82, "trd": NaN, "batb": [[0, 1.6, 10.85], [1, 1.01, 7], [2, 1.01, 0]], "batl": NaN}, {"timestamp": 1631535309311, "ltp": 2.46, "tv": 113.82, "trd": NaN, "batb": [[0, 4.1, 10], [1, 1.6, 10.85], [2, 1.01, 7]], "batl": NaN}, {"timestamp": 1631535404998, "ltp": 2.46, "tv": 113.82, "trd": NaN, "batb": [[0, 1.6, 10.85], [1, 1.01, 7], [2, 1.01, 0]], "batl": NaN}, {"timestamp": 1631535409870, "ltp": 2.46, "tv": 113.82, "trd": NaN, "batb": [[0, 3.4, 12.5], [1, 1.6, 10.85], [2, 1.01, 7]], "batl": NaN}, {"timestamp": 1631535430358, "ltp": 2.46, "tv": 113.82, "trd": NaN, "batb": [[0, 1.6, 10.85], [1, 1.01, 7], [2, 1.01, 0]], "batl": NaN}, {"timestamp": 1631535435254, "ltp": 2.46, "tv": 113.82, "trd": NaN, "batb": [[0, 4.1, 10], [1, 1.6, 10.85], [2, 1.01, 7]], "batl": NaN}, {"timestamp": 1631535468259, "ltp": 2.46, "tv": 113.82, "trd": NaN, "batb": [[0, 1.6, 10.85], [1, 1.01, 7], [2, 1.01, 0]], "batl": NaN}, {"timestamp": 1631535473184, "ltp": 2.46, "tv": 113.82, "trd": NaN, "batb": [[0, 3.4, 12.5], [1, 1.6, 10.85], [2, 1.01, 7]], "batl": NaN}, {"timestamp": 1631535492807, "ltp": 2.46, "tv": 113.82, "trd": NaN, "batb": [[0, 1.6, 10.85], [1, 1.01, 7], [2, 1.01, 0]], "batl": NaN}, {"timestamp": 1631535497705, "ltp": 2.46, "tv": 113.82, "trd": NaN, "batb": [[0, 3, 15], [1, 1.6, 10.85], [2, 1.01, 7]], "batl": NaN}, {"timestamp": 1631535509946, "ltp": 2.46, "tv": 113.82, "trd": NaN, "batb": [[0, 1.6, 10.85], [1, 1.01, 7], [2, 1.01, 0]], "batl": NaN}, {"timestamp": 1631535514859, "ltp": 2.46, "tv": 113.82, "trd": NaN, "batb": [[0, 3.4, 12.5], [1, 1.6, 10.85], [2, 1.01, 7]], "batl": NaN}, {"timestamp": 1631535533080, "ltp": 2.46, "tv": 113.82, "trd": NaN, "batb": [[0, 1.6, 10.85], [1, 1.01, 7], [2, 1.01, 0]], "batl": NaN}, {"timestamp": 1631535537890, "ltp": 2.46, "tv": 113.82, "trd": NaN, "batb": [[0, 4.3, 10], [1, 1.6, 10.85], [2, 1.01, 7]], "batl": NaN}, {"timestamp": 1631535551778, "ltp": 2.46, "tv": 113.82, "trd": NaN, "batb": [[0, 1.6, 10.85], [1, 1.01, 7], [2, 1.01, 0]], "batl": NaN}, {"timestamp": 1631535556697, "ltp": 2.46, "tv": 113.82, "trd": NaN, "batb": [[0, 4.8, 10], [1, 1.6, 10.85], [2, 1.01, 7]], "batl": NaN}, {"timestamp": 1631535561723, "ltp": 2.46, "tv": 113.82, "trd": NaN, "batb": [[0, 1.6, 10.85], [1, 1.01, 7], [2, 1.01, 0]], "batl": NaN}, {"timestamp": 1631535566633, "ltp": 2.46, "tv": 113.82, "trd": NaN, "batb": [[0, 6, 10], [1, 1.6, 10.85], [2, 1.01, 7]], "batl": NaN}, {"timestamp": 1631535581923, "ltp": 2.46, "tv": 113.82, "trd": NaN, "batb": [[0, 1.6, 10.85], [1, 1.01, 7], [2, 1.01, 0]], "batl": NaN}, {"timestamp": 1631535586857, "ltp": 2.46, "tv": 113.82, "trd": NaN, "batb": [[0, 4.3, 10], [1, 1.6, 10.85], [2, 1.01, 7]], "batl": NaN}, {"timestamp": 1631535605867, "ltp": 2.46, "tv": 113.82, "trd": NaN, "batb": [[0, 1.6, 10.85], [1, 1.01, 7], [2, 1.01, 0]], "batl": NaN}, {"timestamp": 1631535610894, "ltp": 2.46, "tv": 113.82, "trd": NaN, "batb": [[0, 4.8, 10], [1, 1.6, 10.85], [2, 1.01, 7]], "batl": NaN}, {"timestamp": 1631535618304, "ltp": 2.46, "tv": 113.82, "trd": NaN, "batb": [[0, 1.6, 10.85], [1, 1.01, 7], [2, 1.01, 0]], "batl": NaN}, {"timestamp": 1631535623234, "ltp": 2.46, "tv": 113.82, "trd": NaN, "batb": [[0, 3.4, 12.5], [1, 1.6, 10.85], [2, 1.01, 7]], "batl": NaN}, {"timestamp": 1631535638353, "ltp": 2.46, "tv": 113.82, "trd": NaN, "batb": [[0, 1.6, 10.85], [1, 1.01, 7], [2, 1.01, 0]], "batl": NaN}, {"timestamp": 1631535643244, "ltp": 2.46, "tv": 113.82, "trd": NaN, "batb": [[0, 4.3, 10]], "batl": NaN}, {"timestamp": 1631535675124, "ltp": 2.46, "tv": 113.82, "trd": NaN, "batb": [[0, 1.01, 7], [1, 1.01, 0]], "batl": NaN}, {"timestamp": 1631535680044, "ltp": 2.46, "tv": 113.82, "trd": NaN, "batb": [[0, 6, 10], [1, 1.01, 7]], "batl": NaN}, {"timestamp": 1631535707107, "ltp": 2.46, "tv": 113.82, "trd": NaN, "batb": [[0, 1.01, 7], [1, 1.01, 0]], "batl": NaN}, {"timestamp": 1631535711976, "ltp": 2.46, "tv": 113.82, "trd": NaN, "batb": [[0, 4.3, 10], [1, 1.01, 7]], "batl": NaN}, {"timestamp": 1631535725433, "ltp": 2.46, "tv": 113.82, "trd": NaN, "batb": [[0, 1.01, 7], [1, 1.01, 0]], "batl": NaN}, {"timestamp": 1631535730320, "ltp": 2.46, "tv": 113.82, "trd": NaN, "batb": [[0, 3.4, 12.5], [1, 1.01, 7]], "batl": NaN}, {"timestamp": 1631535755653, "ltp": 2.46, "tv": 113.82, "trd": NaN, "batb": [[0, 1.01, 7], [1, 1.01, 0]], "batl": NaN}, {"timestamp": 1631535760557, "ltp": 2.46, "tv": 113.82, "trd": NaN, "batb": [[0, 2.84, 16.3], [1, 1.01, 7]], "batl": NaN}, {"timestamp": 1631535766460, "ltp": 3.65, "tv": 143.67, "trd": [[3.65, 29.85]], "batb": [[0, 3.65, 14.11], [1, 2.84, 16.3], [2, 1.01, 7]], "batl": NaN}, {"timestamp": 1631535766673, "ltp": 3.65, "tv": 143.67, "trd": NaN, "batb": [[0, 2.84, 16.3], [1, 1.01, 7], [2, 1.01, 0]], "batl": NaN}, {"timestamp": 1631535802566, "ltp": 3.65, "tv": 143.67, "trd": NaN, "batb": [[0, 1.01, 7], [1, 1.01, 0]], "batl": NaN}, {"timestamp": 1631535807432, "ltp": 3.65, "tv": 143.67, "trd": NaN, "batb": [[0, 3.4, 12.5], [1, 1.01, 7]], "batl": NaN}, {"timestamp": 1631535821293, "ltp": 3.65, "tv": 143.67, "trd": NaN, "batb": [[0, 1.01, 7], [1, 1.01, 0]], "batl": NaN}, {"timestamp": 1631535826075, "ltp": 3.65, "tv": 143.67, "trd": NaN, "batb": [[0, 4.1, 10], [1, 1.01, 7]], "batl": NaN}, {"timestamp": 1631535837500, "ltp": 3.65, "tv": 143.67, "trd": NaN, "batb": [[0, 1.01, 7], [1, 1.01, 0]], "batl": NaN}, {"timestamp": 1631535842410, "ltp": 3.65, "tv": 143.67, "trd": NaN, "batb": [[0, 4, 10], [1, 1.01, 7]], "batl": NaN}, {"timestamp": 1631535847414, "ltp": 3.65, "tv": 143.67, "trd": NaN, "batb": [[0, 1.01, 7], [1, 1.01, 0]], "batl": NaN}, {"timestamp": 1631535852355, "ltp": 3.65, "tv": 143.67, "trd": NaN, "batb": [[0, 3.4, 12.5], [1, 1.01, 7]], "batl": NaN}, {"timestamp": 1631535876466, "ltp": 3.65, "tv": 143.67, "trd": NaN, "batb": [[0, 1.01, 7], [1, 1.01, 0]], "batl": NaN}, {"timestamp": 1631535881380, "ltp": 3.65, "tv": 143.67, "trd": NaN, "batb": [[0, 2.84, 16.3], [1, 1.01, 7]], "batl": NaN}, {"timestamp": 1631535904891, "ltp": 3.65, "tv": 143.67, "trd": NaN, "batb": [[0, 1.01, 7], [1, 1.01, 0]], "batl": NaN}, {"timestamp": 1631535909889, "ltp": 3.65, "tv": 143.67, "trd": NaN, "batb": [[0, 3.7, 11.11], [1, 1.01, 7]], "batl": NaN}, {"timestamp": 1631535941398, "ltp": 3.65, "tv": 143.67, "trd": NaN, "batb": [[0, 1.01, 7], [1, 1.01, 0]], "batl": NaN}, {"timestamp": 1631535946312, "ltp": 3.65, "tv": 143.67, "trd": NaN, "batb": [[0, 5.3, 10], [1, 1.01, 7]], "batl": NaN}, {"timestamp": 1631536034703, "ltp": 3.65, "tv": 143.67, "trd": NaN, "batb": [[0, 1.01, 7], [1, 1.01, 0]], "batl": NaN}, {"timestamp": 1631536039725, "ltp": 3.65, "tv": 143.67, "trd": NaN, "batb": [[0, 4, 10], [1, 1.01, 7]], "batl": NaN}, {"timestamp": 1631536062652, "ltp": 3.65, "tv": 143.67, "trd": NaN, "batb": [[0, 1.01, 7], [1, 1.01, 0]], "batl": NaN}, {"timestamp": 1631536067558, "ltp": 3.65, "tv": 143.67, "trd": NaN, "batb": [[0, 3.3, 13.04], [1, 1.01, 7]], "batl": NaN}, {"timestamp": 1631536086405, "ltp": 3.65, "tv": 143.67, "trd": NaN, "batb": [[0, 1.01, 7], [1, 1.01, 0]], "batl": NaN}, {"timestamp": 1631536091213, "ltp": 3.65, "tv": 143.67, "trd": NaN, "batb": [[0, 3.95, 10.16], [1, 1.01, 7]], "batl": NaN}, {"timestamp": 1631536107853, "ltp": 3.65, "tv": 143.67, "trd": NaN, "batb": [[0, 1.01, 7], [1, 1.01, 0]], "batl": NaN}, {"timestamp": 1631536112722, "ltp": 3.65, "tv": 143.67, "trd": NaN, "batb": [[0, 3.15, 13.95], [1, 1.01, 7]], "batl": NaN}, {"timestamp": 1631536141185, "ltp": 3.65, "tv": 143.67, "trd": NaN, "batb": [[0, 1.01, 7], [1, 1.01, 0]], "batl": NaN}, {"timestamp": 1631536146090, "ltp": 3.65, "tv": 143.67, "trd": NaN, "batb": [[0, 3.7, 11.11], [1, 1.01, 7]], "batl": NaN}, {"timestamp": 1631536163262, "ltp": 3.65, "tv": 143.67, "trd": NaN, "batb": [[0, 1.01, 7], [1, 1.01, 0]], "batl": NaN}, {"timestamp": 1631536168262, "ltp": 3.65, "tv": 143.67, "trd": NaN, "batb": [[0, 3, 15], [1, 1.01, 7]], "batl": NaN}, {"timestamp": 1631536174584, "ltp": 3.95, "tv": 166.25, "trd": [[3.95, 22.58]], "batb": NaN, "batl": NaN}, {"timestamp": 1631536175067, "ltp": 3.95, "tv": 173.6, "trd": [[3.95, 29.93]], "batb": NaN, "batl": NaN}, {"timestamp": 1631536205123, "ltp": 3.0, "tv": 173.84, "trd": [[3, 0.24]], "batb": [[0, 1.01, 7], [1, 1.01, 0]], "batl": NaN}, {"timestamp": 1631536210009, "ltp": 3.0, "tv": 173.84, "trd": NaN, "batb": [[0, 3, 15], [1, 1.01, 7]], "batl": NaN}, {"timestamp": 1631536219368, "ltp": 3.0, "tv": 173.84, "trd": NaN, "batb": [[0, 1.01, 7], [1, 1.01, 0]], "batl": NaN}, {"timestamp": 1631536224243, "ltp": 3.0, "tv": 173.84, "trd": NaN, "batb": [[0, 3.4, 12.5], [1, 1.01, 7]], "batl": NaN}, {"timestamp": 1631536252402, "ltp": 3.0, "tv": 173.84, "trd": NaN, "batb": [[0, 1.01, 7], [1, 1.01, 0]], "batl": NaN}, {"timestamp": 1631536257312, "ltp": 3.0, "tv": 173.84, "trd": NaN, "batb": [[0, 4.1, 10], [1, 1.01, 7]], "batl": NaN}, {"timestamp": 1631536278535, "ltp": 3.0, "tv": 173.84, "trd": NaN, "batb": [[0, 1.01, 7], [1, 1.01, 0]], "batl": NaN}, {"timestamp": 1631536283345, "ltp": 3.0, "tv": 173.84, "trd": NaN, "batb": [[0, 4, 10], [1, 1.01, 7]], "batl": NaN}, {"timestamp": 1631536295871, "ltp": 3.0, "tv": 173.84, "trd": NaN, "batb": [[0, 1.01, 7], [1, 1.01, 0]], "batl": NaN}, {"timestamp": 1631536300879, "ltp": 3.0, "tv": 173.84, "trd": NaN, "batb": [[0, 4.8, 10], [1, 1.01, 7]], "batl": NaN}, {"timestamp": 1631536337465, "ltp": 3.0, "tv": 173.84, "trd": NaN, "batb": [[0, 1.01, 7], [1, 1.01, 0]], "batl": NaN}, {"timestamp": 1631536342381, "ltp": 3.0, "tv": 173.84, "trd": NaN, "batb": [[0, 5.3, 10], [1, 1.01, 7]], "batl": NaN}, {"timestamp": 1631536426902, "ltp": 3.0, "tv": 173.84, "trd": NaN, "batb": [[0, 1.01, 7], [1, 1.01, 0]], "batl": NaN}, {"timestamp": 1631536431821, "ltp": 3.0, "tv": 173.84, "trd": NaN, "batb": [[0, 5.8, 10], [1, 1.01, 7]], "batl": NaN}, {"timestamp": 1631536444374, "ltp": 3.0, "tv": 173.84, "trd": NaN, "batb": [[0, 1.01, 7], [1, 1.01, 0]], "batl": NaN}, {"timestamp": 1631536449261, "ltp": 3.0, "tv": 173.84, "trd": NaN, "batb": [[0, 4.3, 10], [1, 1.01, 7]], "batl": NaN}, {"timestamp": 1631536486454, "ltp": 3.0, "tv": 173.84, "trd": NaN, "batb": [[0, 1.01, 7], [1, 1.01, 0]], "batl": NaN}, {"timestamp": 1631536491358, "ltp": 3.0, "tv": 173.84, "trd": NaN, "batb": [[0, 5.8, 10], [1, 1.01, 7]], "batl": NaN}, {"timestamp": 1631536510776, "ltp": 3.0, "tv": 173.84, "trd": NaN, "batb": [[0, 1.01, 7], [1, 1.01, 0]], "batl": NaN}, {"timestamp": 1631536515809, "ltp": 3.0, "tv": 173.84, "trd": NaN, "batb": [[0, 7.6, 10], [1, 1.01, 7]], "batl": NaN}, {"timestamp": 1631536531513, "ltp": 3.0, "tv": 173.84, "trd": NaN, "batb": [[0, 1.01, 7], [1, 1.01, 0]], "batl": NaN}, {"timestamp": 1631536536311, "ltp": 3.0, "tv": 173.84, "trd": NaN, "batb": [[0, 5.8, 10], [1, 1.01, 7]], "batl": NaN}, {"timestamp": 1631536563458, "ltp": 3.0, "tv": 173.84, "trd": NaN, "batb": [[0, 1.01, 7], [1, 1.01, 0]], "batl": NaN}, {"timestamp": 1631536568277, "ltp": 3.0, "tv": 173.84, "trd": NaN, "batb": [[0, 3.95, 10.16], [1, 1.01, 7]], "batl": NaN}, {"timestamp": 1631536592801, "ltp": 3.0, "tv": 173.84, "trd": NaN, "batb": [[0, 1.01, 7], [1, 1.01, 0]], "batl": NaN}, {"timestamp": 1631536597706, "ltp": 3.0, "tv": 173.84, "trd": NaN, "batb": [[0, 3.15, 13.95], [1, 1.01, 7]], "batl": NaN}, {"timestamp": 1631536653433, "ltp": 3.0, "tv": 173.84, "trd": NaN, "batb": [[0, 1.01, 7], [1, 1.01, 0]], "batl": NaN}, {"timestamp": 1631536658300, "ltp": 3.0, "tv": 173.84, "trd": NaN, "batb": [[0, 2.5, 20], [1, 1.01, 7]], "batl": NaN}, {"timestamp": 1631536689083, "ltp": 3.0, "tv": 173.84, "trd": NaN, "batb": [[0, 1.01, 7], [1, 1.01, 0]], "batl": NaN}, {"timestamp": 1631536694128, "ltp": 3.0, "tv": 173.84, "trd": NaN, "batb": [[0, 2.16, 25.86], [1, 1.01, 7]], "batl": NaN}, {"timestamp": 1631536710743, "ltp": 3.0, "tv": 173.84, "trd": NaN, "batb": [[0, 1.01, 7], [1, 1.01, 0]], "batl": NaN}, {"timestamp": 1631536715611, "ltp": 3.0, "tv": 173.84, "trd": NaN, "batb": [[0, 2.26, 23.8], [1, 1.01, 7]], "batl": NaN}, {"timestamp": 1631536724328, "ltp": 3.0, "tv": 173.84, "trd": NaN, "batb": [[0, 1.01, 7], [1, 1.01, 0]], "batl": NaN}, {"timestamp": 1631536729251, "ltp": 3.0, "tv": 173.84, "trd": NaN, "batb": [[0, 2.58, 18.98], [1, 1.01, 7]], "batl": NaN}, {"timestamp": 1631536761634, "ltp": 3.0, "tv": 173.84, "trd": NaN, "batb": [[0, 1.01, 7], [1, 1.01, 0]], "batl": NaN}, {"timestamp": 1631536766515, "ltp": 3.0, "tv": 173.84, "trd": NaN, "batb": [[0, 2.1, 27.27], [1, 1.01, 7]], "batl": NaN}, {"timestamp": 1631536800905, "ltp": 3.0, "tv": 173.84, "trd": NaN, "batb": [[0, 1.01, 7], [1, 1.01, 0]], "batl": NaN}, {"timestamp": 1631536805833, "ltp": 3.0, "tv": 173.84, "trd": NaN, "batb": [[0, 1.85, 35.29], [1, 1.01, 7]], "batl": NaN}, {"timestamp": 1631536829359, "ltp": 3.0, "tv": 173.84, "trd": NaN, "batb": [[0, 1.01, 7], [1, 1.01, 0]], "batl": NaN}, {"timestamp": 1631536834238, "ltp": 3.0, "tv": 173.84, "trd": NaN, "batb": [[0, 1.63, 47.61], [1, 1.01, 7]], "batl": NaN}, {"timestamp": 1631536860532, "ltp": 1.63, "tv": 176.59, "trd": [[1.63, 2.75]], "batb": [[0, 1.01, 7], [1, 1.01, 0]], "batl": NaN}, {"timestamp": 1631536865445, "ltp": 1.63, "tv": 176.59, "trd": NaN, "batb": [[0, 1.63, 47.61], [1, 1.01, 7]], "batl": NaN}, {"timestamp": 1631536884135, "ltp": 1.63, "tv": 176.59, "trd": NaN, "batb": [[0, 1.01, 7], [1, 1.01, 0]], "batl": NaN}, {"timestamp": 1631536889070, "ltp": 1.63, "tv": 176.59, "trd": NaN, "batb": [[0, 1.65, 46.15], [1, 1.01, 7]], "batl": NaN}, {"timestamp": 1631536894658, "ltp": 1.63, "tv": 176.59, "trd": NaN, "batb": [[0, 1.01, 7], [1, 1.01, 0]], "batl": NaN}, {"timestamp": 1631536899558, "ltp": 1.63, "tv": 176.59, "trd": NaN, "batb": [[0, 1.55, 54.54], [1, 1.01, 7]], "batl": NaN}, {"timestamp": 1631536928716, "ltp": 1.63, "tv": 176.59, "trd": NaN, "batb": [[0, 1.01, 7], [1, 1.01, 0]], "batl": NaN}, {"timestamp": 1631536933595, "ltp": 1.63, "tv": 176.59, "trd": NaN, "batb": [[0, 1.63, 47.61], [1, 1.01, 7]], "batl": NaN}, {"timestamp": 1631536960151, "ltp": 1.63, "tv": 176.59, "trd": NaN, "batb": [[0, 1.01, 7], [1, 1.01, 0]], "batl": NaN}, {"timestamp": 1631536965068, "ltp": 1.63, "tv": 176.59, "trd": NaN, "batb": [[0, 1.51, 58.82], [1, 1.01, 7]], "batl": NaN}, {"timestamp": 1631537189083, "ltp": 1.63, "tv": 176.59, "trd": NaN, "batb": [[0, 1.01, 7], [1, 1.01, 0]], "batl": NaN}, {"timestamp": 1631537194089, "ltp": 1.63, "tv": 176.59, "trd": NaN, "batb": [[0, 1.45, 66.66], [1, 1.01, 7]], "batl": NaN}, {"timestamp": 1631537227221, "ltp": 1.63, "tv": 176.59, "trd": NaN, "batb": [[0, 1.01, 7], [1, 1.01, 0]], "batl": NaN}, {"timestamp": 1631537232264, "ltp": 1.63, "tv": 176.59, "trd": NaN, "batb": [[0, 1.55, 54.54], [1, 1.01, 7]], "batl": NaN}, {"timestamp": 1631537237544, "ltp": 1.55, "tv": 285.67, "trd": [[1.55, 109.08]], "batb": [[0, 1.01, 7], [1, 1.01, 0]], "batl": [[0, 1.55, 53.91]]}, {"timestamp": 1631537237962, "ltp": 1.55, "tv": 285.67, "trd": NaN, "batb": NaN, "batl": [[0, 1.55, 2]]}, {"timestamp": 1631537242256, "ltp": 1.55, "tv": 285.67, "trd": NaN, "batb": NaN, "batl": [[0, 1.55, 25.55]]}, {"timestamp": 1631537243445, "ltp": 1.55, "tv": 285.67, "trd": NaN, "batb": [[0, 1.48, 62.5], [1, 1.01, 7]], "batl": [[0, 1.55, 72.4]]}, {"timestamp": 1631537251120, "ltp": 1.48, "tv": 328.26, "trd": [[1.48, 42.58]], "batb": [[0, 1.01, 7], [1, 1.01, 0]], "batl": NaN}, {"timestamp": 1631537256124, "ltp": 1.48, "tv": 328.26, "trd": NaN, "batb": [[0, 1.48, 62.5], [1, 1.01, 7]], "batl": NaN}, {"timestamp": 1631537265331, "ltp": 1.48, "tv": 328.26, "trd": NaN, "batb": [[0, 1.01, 7], [1, 1.01, 0]], "batl": NaN}, {"timestamp": 1631537270207, "ltp": 1.48, "tv": 328.26, "trd": NaN, "batb": [[0, 1.38, 78.94], [1, 1.01, 7]], "batl": NaN}, {"timestamp": 1631537288965, "ltp": 1.48, "tv": 328.26, "trd": NaN, "batb": [[0, 1.01, 7], [1, 1.01, 0]], "batl": NaN}, {"timestamp": 1631537293860, "ltp": 1.48, "tv": 328.26, "trd": NaN, "batb": [[0, 1.31, 96.77], [1, 1.01, 7]], "batl": NaN}, {"timestamp": 1631537312925, "ltp": 1.48, "tv": 328.26, "trd": NaN, "batb": NaN, "batl": [[0, 1.45, 36.44]]}, {"timestamp": 1631537316104, "ltp": 1.48, "tv": 328.26, "trd": NaN, "batb": [[1, 1.28, 36.44], [2, 1.01, 7]], "batl": NaN}, {"timestamp": 1631537316925, "ltp": 1.48, "tv": 328.26, "trd": NaN, "batb": [[1, 1.28, 72.88]], "batl": NaN}, {"timestamp": 1631537322126, "ltp": 1.48, "tv": 328.26, "trd": NaN, "batb": [[0, 1.28, 72.88], [1, 1.01, 7], [2, 1.01, 0]], "batl": NaN}, {"timestamp": 1631537324140, "ltp": 1.48, "tv": 328.26, "trd": NaN, "batb": [[0, 1.01, 7], [1, 1.01, 0]], "batl": NaN}, {"timestamp": 1631537348668, "ltp": 1.48, "tv": 328.26, "trd": NaN, "batb": NaN, "batl": [[0, 1.35, 36.44]]}, {"timestamp": 1631537350275, "ltp": 1.48, "tv": 328.26, "trd": NaN, "batb": [[0, 1.16, 109.32], [1, 1.01, 7]], "batl": NaN}, {"timestamp": 1631537368477, "ltp": 1.48, "tv": 328.26, "trd": NaN, "batb": [[0, 1.01, 7], [1, 1.01, 0]], "batl": NaN}, {"timestamp": 1631537372498, "ltp": 1.48, "tv": 328.26, "trd": NaN, "batb": NaN, "batl": [[0, 1.45, 36.44]]}, {"timestamp": 1631537376517, "ltp": 1.48, "tv": 328.26, "trd": NaN, "batb": [[0, 1.25, 36.44], [1, 1.01, 7]], "batl": NaN}, {"timestamp": 1631537376883, "ltp": 1.48, "tv": 328.26, "trd": NaN, "batb": [[0, 1.25, 145.76]], "batl": NaN}, {"timestamp": 1631537430316, "ltp": 1.48, "tv": 328.26, "trd": NaN, "batb": [[0, 1.01, 7], [1, 1.01, 0]], "batl": NaN}, {"timestamp": 1631537436094, "ltp": 1.48, "tv": 328.26, "trd": NaN, "batb": [[0, 1.4, 72.88], [1, 1.01, 7]], "batl": NaN}, {"timestamp": 1631537438808, "ltp": 1.48, "tv": 328.26, "trd": NaN, "batb": NaN, "batl": [[0, 1.66, 36.44]]}, {"timestamp": 1631537472141, "ltp": 1.48, "tv": 328.26, "trd": NaN, "batb": [[0, 1.01, 7], [1, 1.01, 0]], "batl": NaN}, {"timestamp": 1631537482575, "ltp": 1.48, "tv": 328.26, "trd": NaN, "batb": [[0, 1.24, 36.44], [1, 1.01, 7]], "batl": NaN}, {"timestamp": 1631537483080, "ltp": 1.48, "tv": 328.26, "trd": NaN, "batb": [[0, 1.24, 145.76]], "batl": NaN}, {"timestamp": 1631537485687, "ltp": 1.48, "tv": 328.26, "trd": NaN, "batb": NaN, "batl": [[0, 1.44, 36.44]]}, {"timestamp": 1631537509826, "ltp": 1.48, "tv": 328.26, "trd": NaN, "batb": [[0, 1.01, 7], [1, 1.01, 0]], "batl": NaN}, {"timestamp": 1631537518657, "ltp": 1.48, "tv": 328.26, "trd": NaN, "batb": NaN, "batl": [[0, 1.7, 36.44]]}, {"timestamp": 1631537521627, "ltp": 1.48, "tv": 328.26, "trd": NaN, "batb": [[0, 1.48, 36.44], [1, 1.01, 7]], "batl": NaN}, {"timestamp": 1631537521833, "ltp": 1.48, "tv": 328.26, "trd": NaN, "batb": [[0, 1.48, 72.88]], "batl": NaN}, {"timestamp": 1631537539061, "ltp": 1.48, "tv": 328.26, "trd": NaN, "batb": [[0, 1.01, 7], [1, 1.01, 0]], "batl": NaN}, {"timestamp": 1631537544573, "ltp": 1.48, "tv": 328.26, "trd": NaN, "batb": NaN, "batl": [[0, 1.48, 204.21], [1, 1.7, 36.44]]}, {"timestamp": 1631537544948, "ltp": 1.48, "tv": 328.26, "trd": NaN, "batb": NaN, "batl": [[0, 1.7, 36.44], [1, 1.7, 0]]}, {"timestamp": 1631537716203, "ltp": 1.01, "tv": 342.26, "trd": [[1.01, 14]], "batb": NaN, "batl": [[0, 1.01, 10.03]]}, {"timestamp": 1631537719599, "ltp": 1.01, "tv": 342.26, "trd": NaN, "batb": NaN, "batl": [[0, 1.01, 27.07]]}]}, {"runnerId": 9628686, "odds": [{"timestamp": 1631531919593, "ltp": 3.0, "tv": 24.32, "trd": [[3, 24.32]], "batb": NaN, "batl": NaN}, {"timestamp": 1631531921571, "ltp": 3.0, "tv": 25.0, "trd": [[3, 25]], "batb": NaN, "batl": NaN}, {"timestamp": 1631531944490, "ltp": 2.74, "tv": 53.65, "trd": [[2.74, 28.65]], "batb": NaN, "batl": [[0, 2.74, 14.8]]}, {"timestamp": 1631531952516, "ltp": 2.74, "tv": 53.65, "trd": NaN, "batb": NaN, "batl": [[0, 2.74, 7.06]]}, {"timestamp": 1631531998574, "ltp": 2.74, "tv": 53.65, "trd": NaN, "batb": NaN, "batl": [[0, 2.74, 3.62]]}, {"timestamp": 1631532317191, "ltp": 2.74, "tv": 53.65, "trd": NaN, "batb": [[0, 1.22, 108.48], [1, 1.01, 7]], "batl": NaN}, {"timestamp": 1631533272492, "ltp": 1.22, "tv": 108.77, "trd": [[1.22, 55.12]], "batb": [[0, 1.22, 80.92]], "batl": NaN}, {"timestamp": 1631533307388, "ltp": 1.22, "tv": 108.77, "trd": NaN, "batb": NaN, "batl": [[0, 1.7, 20.25], [1, 2.74, 3.62]]}, {"timestamp": 1631533327201, "ltp": 1.22, "tv": 108.77, "trd": NaN, "batb": [[0, 1.01, 7], [1, 1.01, 0]], "batl": NaN}, {"timestamp": 1631533332316, "ltp": 1.22, "tv": 108.77, "trd": NaN, "batb": [[0, 1.14, 80.92], [1, 1.01, 7]], "batl": NaN}, {"timestamp": 1631533338315, "ltp": 1.22, "tv": 108.77, "trd": NaN, "batb": NaN, "batl": [[0, 2.74, 3.62], [1, 2.74, 0]]}, {"timestamp": 1631533343417, "ltp": 1.22, "tv": 108.77, "trd": NaN, "batb": NaN, "batl": [[0, 1.6, 20.25], [1, 2.74, 3.62]]}, {"timestamp": 1631533348247, "ltp": 1.22, "tv": 108.77, "trd": NaN, "batb": NaN, "batl": [[0, 2.74, 3.62], [1, 2.74, 0]]}, {"timestamp": 1631533350553, "ltp": 1.22, "tv": 108.77, "trd": NaN, "batb": [[0, 1.6, 10.39], [1, 1.14, 80.92], [2, 1.01, 7]], "batl": NaN}, {"timestamp": 1631533353439, "ltp": 1.22, "tv": 108.77, "trd": NaN, "batb": NaN, "batl": [[0, 1.68, 20.25], [1, 2.74, 3.62]]}, {"timestamp": 1631533353644, "ltp": 1.22, "tv": 108.77, "trd": NaN, "batb": [[0, 1.14, 80.92], [1, 1.01, 7], [2, 1.01, 0]], "batl": NaN}, {"timestamp": 1631533375191, "ltp": 1.68, "tv": 129.01, "trd": [[1.68, 20.24]], "batb": NaN, "batl": [[0, 2.74, 3.62], [1, 2.74, 0]]}, {"timestamp": 1631533810870, "ltp": 1.68, "tv": 129.01, "trd": NaN, "batb": [[0, 1.2, 29.05], [1, 1.14, 80.92], [2, 1.01, 7]], "batl": NaN}, {"timestamp": 1631533819387, "ltp": 1.68, "tv": 129.01, "trd": NaN, "batb": [[1, 1.01, 7], [2, 1.01, 0]], "batl": NaN}, {"timestamp": 1631533824473, "ltp": 1.68, "tv": 129.01, "trd": NaN, "batb": [[0, 1.22, 80.92], [1, 1.2, 29.05], [2, 1.01, 7]], "batl": NaN}, {"timestamp": 1631533832816, "ltp": 1.68, "tv": 129.01, "trd": NaN, "batb": [[1, 1.01, 7], [2, 1.01, 0]], "batl": NaN}, {"timestamp": 1631533837947, "ltp": 1.68, "tv": 129.01, "trd": NaN, "batb": [[0, 1.23, 29.05], [1, 1.22, 80.92], [2, 1.01, 7]], "batl": NaN}, {"timestamp": 1631533844833, "ltp": 1.68, "tv": 129.01, "trd": NaN, "batb": NaN, "batl": [[0, 2.74, 3.62]]}, {"timestamp": 1631533860631, "ltp": 1.68, "tv": 129.01, "trd": NaN, "batb": [[1, 1.01, 7], [2, 1.01, 0]], "batl": NaN}, {"timestamp": 1631533865766, "ltp": 1.68, "tv": 129.01, "trd": NaN, "batb": [[0, 1.25, 80.92], [1, 1.23, 29.05], [2, 1.01, 7]], "batl": NaN}, {"timestamp": 1631533902825, "ltp": 1.68, "tv": 129.01, "trd": NaN, "batb": [[1, 1.01, 7], [2, 1.01, 0]], "batl": NaN}, {"timestamp": 1631533907897, "ltp": 1.68, "tv": 129.01, "trd": NaN, "batb": [[0, 1.27, 29.05], [1, 1.25, 80.92], [2, 1.01, 7]], "batl": NaN}, {"timestamp": 1631533914814, "ltp": 1.68, "tv": 129.01, "trd": NaN, "batb": [[1, 1.01, 7], [2, 1.01, 0]], "batl": NaN}, {"timestamp": 1631533919933, "ltp": 1.68, "tv": 129.01, "trd": NaN, "batb": [[0, 1.3, 80.92], [1, 1.27, 29.05], [2, 1.01, 7]], "batl": NaN}, {"timestamp": 1631533933649, "ltp": 1.68, "tv": 129.01, "trd": NaN, "batb": [[1, 1.01, 7], [2, 1.01, 0]], "batl": NaN}, {"timestamp": 1631534043831, "ltp": 1.68, "tv": 129.01, "trd": NaN, "batb": [[0, 1.01, 7], [1, 1.01, 0]], "batl": NaN}, {"timestamp": 1631534048961, "ltp": 1.68, "tv": 129.01, "trd": NaN, "batb": [[0, 1.21, 80.92], [1, 1.01, 7]], "batl": NaN}, {"timestamp": 1631534145200, "ltp": 1.68, "tv": 129.01, "trd": NaN, "batb": [[0, 1.01, 7], [1, 1.01, 0]], "batl": NaN}, {"timestamp": 1631534150306, "ltp": 1.68, "tv": 129.01, "trd": NaN, "batb": [[0, 1.11, 80.92], [1, 1.01, 7]], "batl": NaN}, {"timestamp": 1631534381288, "ltp": 1.68, "tv": 129.01, "trd": NaN, "batb": [[0, 1.01, 7], [1, 1.01, 0]], "batl": NaN}, {"timestamp": 1631534386354, "ltp": 1.68, "tv": 129.01, "trd": NaN, "batb": [[0, 1.08, 80.92], [1, 1.01, 7]], "batl": NaN}, {"timestamp": 1631535027093, "ltp": 1.68, "tv": 129.01, "trd": NaN, "batb": [[0, 1.01, 7], [1, 1.01, 0]], "batl": NaN}, {"timestamp": 1631535032214, "ltp": 1.68, "tv": 129.01, "trd": NaN, "batb": [[0, 1.16, 80.92], [1, 1.01, 7]], "batl": NaN}, {"timestamp": 1631535156454, "ltp": 1.68, "tv": 129.01, "trd": NaN, "batb": [[0, 1.2, 208.08], [1, 1.16, 80.92], [2, 1.01, 7]], "batl": NaN}, {"timestamp": 1631535158560, "ltp": 1.68, "tv": 129.01, "trd": NaN, "batb": NaN, "batl": [[0, 1.66, 52.02], [1, 2.74, 3.62]]}, {"timestamp": 1631535163250, "ltp": 1.68, "tv": 129.01, "trd": NaN, "batb": [[0, 1.27, 111.11], [1, 1.2, 208.08], [2, 1.16, 80.92]], "batl": NaN}, {"timestamp": 1631535174777, "ltp": 1.68, "tv": 129.01, "trd": NaN, "batb": [[0, 1.2, 208.08], [1, 1.16, 80.92], [2, 1.01, 7]], "batl": NaN}, {"timestamp": 1631535179665, "ltp": 1.68, "tv": 129.01, "trd": NaN, "batb": [[0, 1.2, 358.08]], "batl": NaN}, {"timestamp": 1631535210016, "ltp": 1.68, "tv": 129.01, "trd": NaN, "batb": NaN, "batl": [[0, 2.74, 3.62], [1, 2.74, 0]]}, {"timestamp": 1631535212536, "ltp": 1.68, "tv": 129.01, "trd": NaN, "batb": [[0, 1.2, 208.08]], "batl": NaN}, {"timestamp": 1631535217545, "ltp": 1.68, "tv": 129.01, "trd": NaN, "batb": [[0, 1.23, 130.43], [1, 1.2, 208.08], [2, 1.16, 80.92]], "batl": NaN}, {"timestamp": 1631535275634, "ltp": 1.68, "tv": 129.01, "trd": NaN, "batb": [[1, 1.16, 80.92], [2, 1.01, 7]], "batl": NaN}, {"timestamp": 1631535281527, "ltp": 1.68, "tv": 129.01, "trd": NaN, "batb": [[1, 1.01, 7], [2, 1.01, 0]], "batl": NaN}, {"timestamp": 1631535286667, "ltp": 1.68, "tv": 129.01, "trd": NaN, "batb": [[1, 1.11, 80.92], [2, 1.01, 7]], "batl": NaN}, {"timestamp": 1631535304287, "ltp": 1.68, "tv": 129.01, "trd": NaN, "batb": [[0, 1.11, 80.92], [1, 1.01, 7], [2, 1.01, 0]], "batl": NaN}, {"timestamp": 1631535309311, "ltp": 1.68, "tv": 129.01, "trd": NaN, "batb": [[0, 1.18, 166.66], [1, 1.11, 80.92], [2, 1.01, 7]], "batl": NaN}, {"timestamp": 1631535379324, "ltp": 1.68, "tv": 129.01, "trd": NaN, "batb": [[1, 1.01, 7], [2, 1.01, 0]], "batl": NaN}, {"timestamp": 1631535384468, "ltp": 1.68, "tv": 129.01, "trd": NaN, "batb": [[1, 1.08, 80.92], [2, 1.01, 7]], "batl": NaN}, {"timestamp": 1631535404998, "ltp": 1.68, "tv": 129.01, "trd": NaN, "batb": [[0, 1.08, 80.92], [1, 1.01, 7], [2, 1.01, 0]], "batl": NaN}, {"timestamp": 1631535409870, "ltp": 1.68, "tv": 129.01, "trd": NaN, "batb": [[0, 1.27, 111.11], [1, 1.08, 80.92], [2, 1.01, 7]], "batl": NaN}, {"timestamp": 1631535430358, "ltp": 1.68, "tv": 129.01, "trd": NaN, "batb": [[0, 1.08, 80.92], [1, 1.01, 7], [2, 1.01, 0]], "batl": NaN}, {"timestamp": 1631535435254, "ltp": 1.68, "tv": 129.01, "trd": NaN, "batb": [[0, 1.18, 166.66], [1, 1.08, 80.92], [2, 1.01, 7]], "batl": NaN}, {"timestamp": 1631535468259, "ltp": 1.68, "tv": 129.01, "trd": NaN, "batb": [[0, 1.08, 80.92], [1, 1.01, 7], [2, 1.01, 0]], "batl": NaN}, {"timestamp": 1631535473184, "ltp": 1.68, "tv": 129.01, "trd": NaN, "batb": [[0, 1.27, 111.11], [1, 1.08, 80.92], [2, 1.01, 7]], "batl": NaN}, {"timestamp": 1631535492807, "ltp": 1.68, "tv": 129.01, "trd": NaN, "batb": [[0, 1.08, 80.92], [1, 1.01, 7], [2, 1.01, 0]], "batl": NaN}, {"timestamp": 1631535497705, "ltp": 1.68, "tv": 129.01, "trd": NaN, "batb": [[0, 1.34, 88.23], [1, 1.08, 80.92], [2, 1.01, 7]], "batl": NaN}, {"timestamp": 1631535509946, "ltp": 1.68, "tv": 129.01, "trd": NaN, "batb": [[0, 1.08, 80.92], [1, 1.01, 7], [2, 1.01, 0]], "batl": NaN}, {"timestamp": 1631535514859, "ltp": 1.68, "tv": 129.01, "trd": NaN, "batb": [[0, 1.27, 111.11], [1, 1.08, 80.92], [2, 1.01, 7]], "batl": NaN}, {"timestamp": 1631535533080, "ltp": 1.68, "tv": 129.01, "trd": NaN, "batb": [[0, 1.08, 80.92], [1, 1.01, 7], [2, 1.01, 0]], "batl": NaN}, {"timestamp": 1631535537890, "ltp": 1.68, "tv": 129.01, "trd": NaN, "batb": [[0, 1.18, 166.66], [1, 1.08, 80.92], [2, 1.01, 7]], "batl": NaN}, {"timestamp": 1631535551778, "ltp": 1.68, "tv": 129.01, "trd": NaN, "batb": [[0, 1.08, 80.92], [1, 1.01, 7], [2, 1.01, 0]], "batl": NaN}, {"timestamp": 1631535556697, "ltp": 1.68, "tv": 129.01, "trd": NaN, "batb": [[0, 1.15, 200], [1, 1.08, 80.92], [2, 1.01, 7]], "batl": NaN}, {"timestamp": 1631535561723, "ltp": 1.68, "tv": 129.01, "trd": NaN, "batb": [[0, 1.08, 80.92], [1, 1.01, 7], [2, 1.01, 0]], "batl": NaN}, {"timestamp": 1631535566633, "ltp": 1.68, "tv": 129.01, "trd": NaN, "batb": [[0, 1.08, 455.91]], "batl": NaN}, {"timestamp": 1631535581923, "ltp": 1.68, "tv": 129.01, "trd": NaN, "batb": [[0, 1.08, 80.92]], "batl": NaN}, {"timestamp": 1631535582753, "ltp": 1.68, "tv": 129.01, "trd": NaN, "batb": [[0, 1.01, 7], [1, 1.01, 0]], "batl": NaN}, {"timestamp": 1631535586857, "ltp": 1.68, "tv": 129.01, "trd": NaN, "batb": [[0, 1.18, 166.66], [1, 1.01, 7]], "batl": NaN}, {"timestamp": 1631535587849, "ltp": 1.68, "tv": 129.01, "trd": NaN, "batb": [[1, 1.02, 80.92], [2, 1.01, 7]], "batl": NaN}, {"timestamp": 1631535605867, "ltp": 1.68, "tv": 129.01, "trd": NaN, "batb": [[0, 1.02, 80.92], [1, 1.01, 7], [2, 1.01, 0]], "batl": NaN}, {"timestamp": 1631535610894, "ltp": 1.68, "tv": 129.01, "trd": NaN, "batb": [[0, 1.15, 200], [1, 1.02, 80.92], [2, 1.01, 7]], "batl": NaN}, {"timestamp": 1631535618304, "ltp": 1.68, "tv": 129.01, "trd": NaN, "batb": [[0, 1.02, 80.92], [1, 1.01, 7], [2, 1.01, 0]], "batl": NaN}, {"timestamp": 1631535623234, "ltp": 1.68, "tv": 129.01, "trd": NaN, "batb": [[0, 1.27, 111.11], [1, 1.02, 80.92], [2, 1.01, 7]], "batl": NaN}, {"timestamp": 1631535638353, "ltp": 1.68, "tv": 129.01, "trd": NaN, "batb": [[0, 1.02, 80.92], [1, 1.01, 7], [2, 1.01, 0]], "batl": NaN}, {"timestamp": 1631535643244, "ltp": 1.68, "tv": 129.01, "trd": NaN, "batb": [[0, 1.18, 166.66]], "batl": NaN}, {"timestamp": 1631535675124, "ltp": 1.68, "tv": 129.01, "trd": NaN, "batb": [[0, 1.01, 7], [1, 1.01, 0]], "batl": NaN}, {"timestamp": 1631535680044, "ltp": 1.68, "tv": 129.01, "trd": NaN, "batb": [[0, 1.08, 374.99], [1, 1.01, 7]], "batl": NaN}, {"timestamp": 1631535707107, "ltp": 1.68, "tv": 129.01, "trd": NaN, "batb": [[0, 1.01, 7], [1, 1.01, 0]], "batl": NaN}, {"timestamp": 1631535711976, "ltp": 1.68, "tv": 129.01, "trd": NaN, "batb": [[0, 1.18, 166.66], [1, 1.01, 7]], "batl": NaN}, {"timestamp": 1631535725433, "ltp": 1.68, "tv": 129.01, "trd": NaN, "batb": [[0, 1.01, 7], [1, 1.01, 0]], "batl": NaN}, {"timestamp": 1631535730320, "ltp": 1.68, "tv": 129.01, "trd": NaN, "batb": [[0, 1.27, 111.11], [1, 1.01, 7]], "batl": NaN}, {"timestamp": 1631535755653, "ltp": 1.68, "tv": 129.01, "trd": NaN, "batb": [[0, 1.01, 7], [1, 1.01, 0]], "batl": NaN}, {"timestamp": 1631535760557, "ltp": 1.68, "tv": 129.01, "trd": NaN, "batb": [[0, 1.38, 78.94], [1, 1.01, 7]], "batl": NaN}, {"timestamp": 1631535766460, "ltp": 1.38, "tv": 207.95, "trd": [[1.38, 78.94]], "batb": [[0, 1.01, 7], [1, 1.01, 0]], "batl": [[0, 1.38, 88.83], [1, 2.74, 3.62]]}, {"timestamp": 1631535766673, "ltp": 1.38, "tv": 207.95, "trd": NaN, "batb": NaN, "batl": [[0, 2.74, 3.62], [1, 2.74, 0]]}, {"timestamp": 1631535771693, "ltp": 1.38, "tv": 207.95, "trd": NaN, "batb": [[0, 1.31, 96.77], [1, 1.01, 7]], "batl": NaN}, {"timestamp": 1631535802566, "ltp": 1.38, "tv": 207.95, "trd": NaN, "batb": [[0, 1.01, 7], [1, 1.01, 0]], "batl": NaN}, {"timestamp": 1631535807432, "ltp": 1.38, "tv": 207.95, "trd": NaN, "batb": [[0, 1.27, 111.11], [1, 1.01, 7]], "batl": NaN}, {"timestamp": 1631535821293, "ltp": 1.38, "tv": 207.95, "trd": NaN, "batb": [[0, 1.01, 7], [1, 1.01, 0]], "batl": NaN}, {"timestamp": 1631535826075, "ltp": 1.38, "tv": 207.95, "trd": NaN, "batb": [[0, 1.18, 166.66], [1, 1.01, 7]], "batl": NaN}, {"timestamp": 1631535837500, "ltp": 1.38, "tv": 207.95, "trd": NaN, "batb": [[0, 1.01, 7], [1, 1.01, 0]], "batl": NaN}, {"timestamp": 1631535842410, "ltp": 1.38, "tv": 207.95, "trd": NaN, "batb": [[0, 1.2, 150], [1, 1.01, 7]], "batl": NaN}, {"timestamp": 1631535847414, "ltp": 1.38, "tv": 207.95, "trd": NaN, "batb": [[0, 1.01, 7], [1, 1.01, 0]], "batl": NaN}, {"timestamp": 1631535852355, "ltp": 1.38, "tv": 207.95, "trd": NaN, "batb": [[0, 1.27, 111.11], [1, 1.01, 7]], "batl": NaN}, {"timestamp": 1631535876466, "ltp": 1.38, "tv": 207.95, "trd": NaN, "batb": [[0, 1.01, 7], [1, 1.01, 0]], "batl": NaN}, {"timestamp": 1631535881380, "ltp": 1.38, "tv": 207.95, "trd": NaN, "batb": [[0, 1.38, 78.94], [1, 1.01, 7]], "batl": NaN}, {"timestamp": 1631535904891, "ltp": 1.38, "tv": 207.95, "trd": NaN, "batb": [[0, 1.01, 7], [1, 1.01, 0]], "batl": NaN}, {"timestamp": 1631535909889, "ltp": 1.38, "tv": 207.95, "trd": NaN, "batb": [[0, 1.23, 130.43], [1, 1.01, 7]], "batl": NaN}, {"timestamp": 1631535941398, "ltp": 1.38, "tv": 207.95, "trd": NaN, "batb": [[0, 1.01, 7], [1, 1.01, 0]], "batl": NaN}, {"timestamp": 1631535946312, "ltp": 1.38, "tv": 207.95, "trd": NaN, "batb": [[0, 1.12, 249.99], [1, 1.01, 7]], "batl": NaN}, {"timestamp": 1631536034703, "ltp": 1.38, "tv": 207.95, "trd": NaN, "batb": [[0, 1.01, 7], [1, 1.01, 0]], "batl": NaN}, {"timestamp": 1631536039725, "ltp": 1.38, "tv": 207.95, "trd": NaN, "batb": [[0, 1.2, 150], [1, 1.01, 7]], "batl": NaN}, {"timestamp": 1631536062652, "ltp": 1.38, "tv": 207.95, "trd": NaN, "batb": [[0, 1.01, 7], [1, 1.01, 0]], "batl": NaN}, {"timestamp": 1631536067558, "ltp": 1.38, "tv": 207.95, "trd": NaN, "batb": [[0, 1.28, 107.14], [1, 1.01, 7]], "batl": NaN}, {"timestamp": 1631536086405, "ltp": 1.38, "tv": 207.95, "trd": NaN, "batb": [[0, 1.01, 7], [1, 1.01, 0]], "batl": NaN}, {"timestamp": 1631536091213, "ltp": 1.38, "tv": 207.95, "trd": NaN, "batb": [[0, 1.2, 150], [1, 1.01, 7]], "batl": NaN}, {"timestamp": 1631536107853, "ltp": 1.38, "tv": 207.95, "trd": NaN, "batb": [[0, 1.01, 7], [1, 1.01, 0]], "batl": NaN}, {"timestamp": 1631536112722, "ltp": 1.38, "tv": 207.95, "trd": NaN, "batb": [[0, 1.31, 96.77], [1, 1.01, 7]], "batl": NaN}, {"timestamp": 1631536141185, "ltp": 1.38, "tv": 207.95, "trd": NaN, "batb": [[0, 1.01, 7], [1, 1.01, 0]], "batl": NaN}, {"timestamp": 1631536146090, "ltp": 1.38, "tv": 207.95, "trd": NaN, "batb": [[0, 1.23, 130.43], [1, 1.01, 7]], "batl": NaN}, {"timestamp": 1631536163262, "ltp": 1.38, "tv": 207.95, "trd": NaN, "batb": [[0, 1.01, 7], [1, 1.01, 0]], "batl": NaN}, {"timestamp": 1631536168262, "ltp": 1.38, "tv": 207.95, "trd": NaN, "batb": [[0, 1.34, 88.23], [1, 1.01, 7]], "batl": NaN}, {"timestamp": 1631536174584, "ltp": 1.34, "tv": 274.51, "trd": [[1.34, 66.56]], "batb": [[0, 1.34, 21.67]], "batl": NaN}, {"timestamp": 1631536175067, "ltp": 1.34, "tv": 296.18, "trd": [[1.34, 88.23]], "batb": [[0, 1.01, 7], [1, 1.01, 0]], "batl": NaN}, {"timestamp": 1631536179779, "ltp": 1.34, "tv": 296.18, "trd": NaN, "batb": [[0, 1.34, 88.23], [1, 1.01, 7]], "batl": NaN}, {"timestamp": 1631536219368, "ltp": 1.34, "tv": 296.18, "trd": NaN, "batb": [[0, 1.01, 7], [1, 1.01, 0]], "batl": NaN}, {"timestamp": 1631536224243, "ltp": 1.34, "tv": 296.18, "trd": NaN, "batb": [[0, 1.27, 111.11], [1, 1.01, 7]], "batl": NaN}, {"timestamp": 1631536252402, "ltp": 1.34, "tv": 296.18, "trd": NaN, "batb": [[0, 1.01, 7], [1, 1.01, 0]], "batl": NaN}, {"timestamp": 1631536257312, "ltp": 1.34, "tv": 296.18, "trd": NaN, "batb": [[0, 1.18, 166.66], [1, 1.01, 7]], "batl": NaN}, {"timestamp": 1631536278535, "ltp": 1.34, "tv": 296.18, "trd": NaN, "batb": [[0, 1.01, 7], [1, 1.01, 0]], "batl": NaN}, {"timestamp": 1631536283345, "ltp": 1.34, "tv": 296.18, "trd": NaN, "batb": [[0, 1.2, 150], [1, 1.01, 7]], "batl": NaN}, {"timestamp": 1631536295871, "ltp": 1.34, "tv": 296.18, "trd": NaN, "batb": [[0, 1.01, 7], [1, 1.01, 0]], "batl": NaN}, {"timestamp": 1631536300879, "ltp": 1.34, "tv": 296.18, "trd": NaN, "batb": [[0, 1.15, 200], [1, 1.01, 7]], "batl": NaN}, {"timestamp": 1631536337465, "ltp": 1.34, "tv": 296.18, "trd": NaN, "batb": [[0, 1.01, 7], [1, 1.01, 0]], "batl": NaN}, {"timestamp": 1631536342381, "ltp": 1.34, "tv": 296.18, "trd": NaN, "batb": [[0, 1.12, 249.99], [1, 1.01, 7]], "batl": NaN}, {"timestamp": 1631536426902, "ltp": 1.34, "tv": 296.18, "trd": NaN, "batb": [[0, 1.01, 7], [1, 1.01, 0]], "batl": NaN}, {"timestamp": 1631536431821, "ltp": 1.34, "tv": 296.18, "trd": NaN, "batb": [[0, 1.11, 272.72], [1, 1.01, 7]], "batl": NaN}, {"timestamp": 1631536444374, "ltp": 1.34, "tv": 296.18, "trd": NaN, "batb": [[0, 1.01, 7], [1, 1.01, 0]], "batl": NaN}, {"timestamp": 1631536449261, "ltp": 1.34, "tv": 296.18, "trd": NaN, "batb": [[0, 1.18, 166.66], [1, 1.01, 7]], "batl": NaN}, {"timestamp": 1631536486454, "ltp": 1.34, "tv": 296.18, "trd": NaN, "batb": [[0, 1.01, 7], [1, 1.01, 0]], "batl": NaN}, {"timestamp": 1631536491358, "ltp": 1.34, "tv": 296.18, "trd": NaN, "batb": [[0, 1.11, 272.72], [1, 1.01, 7]], "batl": NaN}, {"timestamp": 1631536510776, "ltp": 1.34, "tv": 296.18, "trd": NaN, "batb": [[0, 1.01, 7], [1, 1.01, 0]], "batl": NaN}, {"timestamp": 1631536515809, "ltp": 1.34, "tv": 296.18, "trd": NaN, "batb": [[0, 1.05, 599.99], [1, 1.01, 7]], "batl": NaN}, {"timestamp": 1631536531513, "ltp": 1.34, "tv": 296.18, "trd": NaN, "batb": [[0, 1.01, 7], [1, 1.01, 0]], "batl": NaN}, {"timestamp": 1631536536311, "ltp": 1.34, "tv": 296.18, "trd": NaN, "batb": [[0, 1.11, 272.72], [1, 1.01, 7]], "batl": NaN}, {"timestamp": 1631536563458, "ltp": 1.34, "tv": 296.18, "trd": NaN, "batb": [[0, 1.01, 7], [1, 1.01, 0]], "batl": NaN}, {"timestamp": 1631536568277, "ltp": 1.34, "tv": 296.18, "trd": NaN, "batb": [[0, 1.2, 150], [1, 1.01, 7]], "batl": NaN}, {"timestamp": 1631536592801, "ltp": 1.34, "tv": 296.18, "trd": NaN, "batb": [[0, 1.01, 7], [1, 1.01, 0]], "batl": NaN}, {"timestamp": 1631536597706, "ltp": 1.34, "tv": 296.18, "trd": NaN, "batb": [[0, 1.31, 96.77], [1, 1.01, 7]], "batl": NaN}, {"timestamp": 1631536653433, "ltp": 1.34, "tv": 296.18, "trd": NaN, "batb": [[0, 1.01, 7], [1, 1.01, 0]], "batl": NaN}, {"timestamp": 1631536658300, "ltp": 1.34, "tv": 296.18, "trd": NaN, "batb": [[0, 1.48, 62.5], [1, 1.01, 7]], "batl": NaN}, {"timestamp": 1631536689083, "ltp": 1.34, "tv": 296.18, "trd": NaN, "batb": [[0, 1.01, 7], [1, 1.01, 0]], "batl": NaN}, {"timestamp": 1631536694128, "ltp": 1.34, "tv": 296.18, "trd": NaN, "batb": [[0, 1.63, 47.61], [1, 1.01, 7]], "batl": NaN}, {"timestamp": 1631536710743, "ltp": 1.34, "tv": 296.18, "trd": NaN, "batb": [[0, 1.01, 7], [1, 1.01, 0]], "batl": NaN}, {"timestamp": 1631536715611, "ltp": 1.34, "tv": 296.18, "trd": NaN, "batb": [[0, 1.58, 51.72], [1, 1.01, 7]], "batl": NaN}, {"timestamp": 1631536724328, "ltp": 1.34, "tv": 296.18, "trd": NaN, "batb": [[0, 1.01, 7], [1, 1.01, 0]], "batl": NaN}, {"timestamp": 1631536729251, "ltp": 1.34, "tv": 296.18, "trd": NaN, "batb": [[0, 1.45, 66.66], [1, 1.01, 7]], "batl": NaN}, {"timestamp": 1631536761634, "ltp": 1.34, "tv": 296.18, "trd": NaN, "batb": [[0, 1.01, 7], [1, 1.01, 0]], "batl": NaN}, {"timestamp": 1631536766515, "ltp": 1.34, "tv": 296.18, "trd": NaN, "batb": [[0, 1.65, 46.15], [1, 1.01, 7]], "batl": NaN}, {"timestamp": 1631536800905, "ltp": 1.34, "tv": 296.18, "trd": NaN, "batb": [[0, 1.01, 7], [1, 1.01, 0]], "batl": NaN}, {"timestamp": 1631536805833, "ltp": 1.34, "tv": 296.18, "trd": NaN, "batb": [[0, 1.88, 34.09], [1, 1.01, 7]], "batl": NaN}, {"timestamp": 1631536829359, "ltp": 1.34, "tv": 296.18, "trd": NaN, "batb": [[0, 1.01, 7], [1, 1.01, 0]], "batl": NaN}, {"timestamp": 1631536834238, "ltp": 1.34, "tv": 296.18, "trd": NaN, "batb": [[0, 2.16, 25.86], [1, 1.01, 7]], "batl": NaN}, {"timestamp": 1631536884135, "ltp": 1.34, "tv": 296.18, "trd": NaN, "batb": [[0, 1.01, 7], [1, 1.01, 0]], "batl": NaN}, {"timestamp": 1631536889070, "ltp": 1.34, "tv": 296.18, "trd": NaN, "batb": [[0, 2.1, 27.27], [1, 1.01, 7]], "batl": NaN}, {"timestamp": 1631536894658, "ltp": 1.34, "tv": 296.18, "trd": NaN, "batb": [[0, 1.01, 7], [1, 1.01, 0]], "batl": NaN}, {"timestamp": 1631536899558, "ltp": 1.34, "tv": 296.18, "trd": NaN, "batb": [[0, 2.34, 22.38], [1, 1.01, 7]], "batl": NaN}, {"timestamp": 1631536920613, "ltp": 2.34, "tv": 340.93, "trd": [[2.34, 44.75]], "batb": [[0, 1.01, 7.01], [1, 1.01, 0]], "batl": NaN}, {"timestamp": 1631536920991, "ltp": 2.34, "tv": 340.93, "trd": NaN, "batb": [[0, 1.01, 7]], "batl": NaN}, {"timestamp": 1631536925589, "ltp": 2.34, "tv": 340.93, "trd": NaN, "batb": NaN, "batl": [[0, 2.34, 13.17]]}, {"timestamp": 1631536925896, "ltp": 2.34, "tv": 340.93, "trd": NaN, "batb": [[0, 2.2, 24.99], [1, 1.01, 7]], "batl": NaN}, {"timestamp": 1631536928716, "ltp": 2.34, "tv": 340.93, "trd": NaN, "batb": [[0, 1.01, 7], [1, 1.01, 0]], "batl": NaN}, {"timestamp": 1631536933595, "ltp": 2.34, "tv": 340.93, "trd": NaN, "batb": [[0, 2.16, 25.86], [1, 1.01, 7]], "batl": NaN}, {"timestamp": 1631536960151, "ltp": 2.34, "tv": 340.93, "trd": NaN, "batb": [[0, 1.01, 7], [1, 1.01, 0]], "batl": NaN}, {"timestamp": 1631536965068, "ltp": 2.34, "tv": 340.93, "trd": NaN, "batb": [[0, 2.42, 21.12], [1, 1.01, 7]], "batl": NaN}, {"timestamp": 1631536988223, "ltp": 2.42, "tv": 383.15, "trd": [[2.42, 42.23]], "batb": [[0, 1.01, 7], [1, 1.01, 0]], "batl": NaN}, {"timestamp": 1631536993222, "ltp": 2.42, "tv": 383.15, "trd": NaN, "batb": [[0, 2.28, 23.43], [1, 1.01, 7]], "batl": NaN}, {"timestamp": 1631537189083, "ltp": 2.42, "tv": 383.15, "trd": NaN, "batb": [[0, 1.01, 7], [1, 1.01, 0]], "batl": NaN}, {"timestamp": 1631537194089, "ltp": 2.42, "tv": 383.15, "trd": NaN, "batb": [[0, 2.58, 18.98], [1, 1.01, 7]], "batl": NaN}, {"timestamp": 1631537227221, "ltp": 2.42, "tv": 383.15, "trd": NaN, "batb": [[0, 1.01, 7], [1, 1.01, 0]], "batl": NaN}, {"timestamp": 1631537232264, "ltp": 2.42, "tv": 383.15, "trd": NaN, "batb": [[0, 2.34, 22.38], [1, 1.01, 7]], "batl": NaN}, {"timestamp": 1631537239641, "ltp": 2.42, "tv": 383.15, "trd": NaN, "batb": [[0, 1.01, 7], [1, 1.01, 0]], "batl": NaN}, {"timestamp": 1631537244689, "ltp": 2.42, "tv": 383.15, "trd": NaN, "batb": [[0, 2.5, 20], [1, 1.01, 7]], "batl": NaN}, {"timestamp": 1631537265331, "ltp": 2.42, "tv": 383.15, "trd": NaN, "batb": [[0, 1.01, 7], [1, 1.01, 0]], "batl": NaN}, {"timestamp": 1631537270207, "ltp": 2.42, "tv": 383.15, "trd": NaN, "batb": [[0, 2.84, 16.3], [1, 1.01, 7]], "batl": NaN}, {"timestamp": 1631537288965, "ltp": 2.42, "tv": 383.15, "trd": NaN, "batb": [[0, 1.01, 7], [1, 1.01, 0]], "batl": NaN}, {"timestamp": 1631537293860, "ltp": 2.42, "tv": 383.15, "trd": NaN, "batb": [[0, 3.15, 13.95], [1, 1.01, 7]], "batl": NaN}, {"timestamp": 1631537322126, "ltp": 2.42, "tv": 383.15, "trd": NaN, "batb": [[0, 1.01, 7], [1, 1.01, 0]], "batl": NaN}, {"timestamp": 1631537368477, "ltp": 2.42, "tv": 383.15, "trd": NaN, "batb": [[0, 2.02, 26.47], [1, 1.01, 7]], "batl": NaN}, {"timestamp": 1631537444000, "ltp": 2.42, "tv": 383.15, "trd": NaN, "batb": [[0, 1.01, 7], [1, 1.01, 0]], "batl": NaN}, {"timestamp": 1631537515544, "ltp": 2.42, "tv": 383.15, "trd": NaN, "batb": NaN, "batl": [[0, 3.25, 99.32]]}, {"timestamp": 1631537516640, "ltp": 2.42, "tv": 383.15, "trd": NaN, "batb": NaN, "batl": [[0, 3.25, 64.05]]}, {"timestamp": 1631537708781, "ltp": 2.42, "tv": 383.15, "trd": NaN, "batb": [[0, 1.08, 80.89], [1, 1.01, 7]], "batl": NaN}, {"timestamp": 1631537830006, "ltp": 2.42, "tv": 383.15, "trd": NaN, "batb": [[0, 1.01, 7], [1, 1.01, 0]], "batl": NaN}, {"timestamp": 1631537835307, "ltp": 2.42, "tv": 383.15, "trd": NaN, "batb": [[0, 1.05, 80.89], [1, 1.01, 7]], "batl": NaN}]}]}