{"info": {"id": "1.187595434", "eventId": "30897890", "eventName": "Match Odds", "marketType": "MATCH_ODDS", "openDate": 1631525290150, "name": "A Carreras v O Selekhmeteva", "numberOfActiveRunner": 2, "countryCode": "", "sport": "TENNIS", "venue": "", "volume": {"total": 1957.47, "preMatch": 85.63, "inPlay": 1871.84}, "winner": {"id": 21397559, "name": "O Selekhmeteva", "status": "WINNER", "position": 2}, "delay": 5}, "runners": [{"id": 9589287, "name": "A Carreras", "status": "LOSER", "position": 1, "inPlayOdds": 4.5, "inPlayTime": 1631525990580, "avgPrematch": 0, "closedOdds": 2.74, "maxPrematch": -100, "minPrematch": 1001, "maxInPlay": 5.5, "minInPlay": 2.74, "inPlayIndex": 0, "lengthOdds": 71, "lengthOddsPrematch": 0, "lengthOddsInPlay": 71, "tradedVolume": 89.58, "preMatchVolume": 18.96, "inPlayVolume": 70.62}, {"id": 21397559, "name": "O Selekhmeteva", "status": "WINNER", "position": 2, "inPlayOdds": 1.28, "inPlayTime": 1631525990580, "avgPrematch": 0, "closedOdds": 1.01, "maxPrematch": -100, "minPrematch": 1001, "maxInPlay": 1.57, "minInPlay": 1.01, "inPlayIndex": 0, "lengthOdds": 189, "lengthOddsPrematch": 0, "lengthOddsInPlay": 189, "tradedVolume": 1867.89, "preMatchVolume": 66.67, "inPlayVolume": 1801.22}], "marketUpdates": [{"timestamp": 1631518765916000000, "openDate": "2021-09-13T09:30:00.000Z", "status": "OPEN", "betDelay": 0, "inPlay": false, "complete": true}, {"timestamp": 1631525178551000000, "openDate": "2021-09-13T09:25:00.000Z", "status": "OPEN", "betDelay": 0, "inPlay": false, "complete": true}, {"timestamp": 1631525290150000000, "openDate": "2021-09-13T09:25:00.000Z", "status": "OPEN", "betDelay": 5, "inPlay": true, "complete": true}, {"timestamp": 1631525932282000000, "openDate": "2021-09-13T09:38:48.000Z", "status": "OPEN", "betDelay": 5, "inPlay": true, "complete": true}, {"timestamp": 1631529565645000000, "openDate": "2021-09-13T09:38:48.000Z", "status": "SUSPENDED", "betDelay": 5, "inPlay": true, "complete": true}, {"timestamp": 1631529571675000000, "openDate": "2021-09-13T09:38:48.000Z", "status": "CLOSED", "betDelay": 5, "inPlay": true, "complete": true}], "odds": [{"runnerId": 9589287, "odds": [{"timestamp": 1631525990580, "ltp": 4.5, "tv": 18.96, "trd": [[4.5, 18.96]], "batb": NaN, "batl": NaN}, {"timestamp": 1631525996497, "ltp": 4.5, "tv": 24.97, "trd": [[4.5, 24.97]], "batb": NaN, "batl": [[0, 4.5, 2.99]]}, {"timestamp": 1631526319942, "ltp": 5.5, "tv": 27.12, "trd": [[5.5, 2.15]], "batb": NaN, "batl": NaN}, {"timestamp": 1631526345987, "ltp": 5.5, "tv": 27.12, "trd": NaN, "batb": [[0, 2.42, 387.76], [1, 1.01, 7]], "batl": [[0, 5.5, 116.87]]}, {"timestamp": 1631526412860, "ltp": 5.5, "tv": 27.12, "trd": NaN, "batb": NaN, "batl": [[0, 4.9, 128.27]]}, {"timestamp": 1631526516076, "ltp": 5.5, "tv": 27.12, "trd": NaN, "batb": [[0, 1.01, 7], [1, 1.01, 0]], "batl": NaN}, {"timestamp": 1631526522298, "ltp": 5.5, "tv": 27.12, "trd": NaN, "batb": [[0, 2.12, 394.79], [1, 1.01, 7]], "batl": [[0, 4.2, 150.36]]}, {"timestamp": 1631526567924, "ltp": 5.5, "tv": 27.12, "trd": NaN, "batb": [[0, 1.01, 7], [1, 1.01, 0]], "batl": NaN}, {"timestamp": 1631526573829, "ltp": 5.5, "tv": 27.12, "trd": NaN, "batb": [[0, 2.38, 388.33], [1, 1.01, 7]], "batl": [[0, 5.3, 120.66]]}, {"timestamp": 1631526631997, "ltp": 5.5, "tv": 27.12, "trd": NaN, "batb": NaN, "batl": [[0, 4.6, 138.2]]}, {"timestamp": 1631526657663, "ltp": 5.5, "tv": 27.12, "trd": NaN, "batb": NaN, "batl": [[0, 5.5, 116.87]]}, {"timestamp": 1631526672482, "ltp": 5.5, "tv": 27.12, "trd": NaN, "batb": [[0, 1.01, 7], [1, 1.01, 0]], "batl": NaN}, {"timestamp": 1631526678312, "ltp": 5.5, "tv": 27.12, "trd": NaN, "batb": [[0, 2.52, 387.48], [1, 1.01, 7]], "batl": NaN}, {"timestamp": 1631526886968, "ltp": 5.5, "tv": 27.12, "trd": NaN, "batb": NaN, "batl": [[0, 6.6, 100.51]]}, {"timestamp": 1631526902293, "ltp": 5.5, "tv": 27.12, "trd": NaN, "batb": NaN, "batl": [[0, 5.3, 120.66]]}, {"timestamp": 1631526924737, "ltp": 5.5, "tv": 27.12, "trd": NaN, "batb": [[0, 1.01, 7], [1, 1.01, 0]], "batl": NaN}, {"timestamp": 1631526930516, "ltp": 5.5, "tv": 27.12, "trd": NaN, "batb": [[0, 2.22, 390.59], [1, 1.01, 7]], "batl": [[0, 4.6, 138.2]]}, {"timestamp": 1631527040107, "ltp": 5.5, "tv": 27.12, "trd": NaN, "batb": NaN, "batl": [[0, 3.9, 160.74]]}, {"timestamp": 1631527070333, "ltp": 5.5, "tv": 27.12, "trd": NaN, "batb": [[0, 1.01, 7], [1, 1.01, 0]], "batl": NaN}, {"timestamp": 1631527076542, "ltp": 5.5, "tv": 27.12, "trd": NaN, "batb": [[0, 1.97, 401.09], [1, 1.01, 7]], "batl": [[0, 3.65, 173.1]]}, {"timestamp": 1631527085355, "ltp": 2.74, "tv": 89.58, "trd": [[2.74, 21.5], [2.92, 40.96]], "batb": NaN, "batl": NaN}, {"timestamp": 1631527101756, "ltp": 2.74, "tv": 89.58, "trd": NaN, "batb": NaN, "batl": [[0, 3.15, 203.58]]}, {"timestamp": 1631527232458, "ltp": 2.74, "tv": 89.58, "trd": NaN, "batb": NaN, "batl": [[0, 3.65, 173.1]]}, {"timestamp": 1631527234338, "ltp": 2.74, "tv": 89.58, "trd": NaN, "batb": [[0, 2.3, 167.42], [1, 1.97, 401.09], [2, 1.01, 7]], "batl": NaN}, {"timestamp": 1631527235540, "ltp": 2.74, "tv": 89.58, "trd": NaN, "batb": [[0, 2.3, 151.01]], "batl": NaN}, {"timestamp": 1631527236384, "ltp": 2.74, "tv": 89.58, "trd": NaN, "batb": [[0, 1.97, 401.09], [1, 1.01, 7], [2, 1.01, 0]], "batl": NaN}, {"timestamp": 1631527282409, "ltp": 2.74, "tv": 89.58, "trd": NaN, "batb": [[0, 1.01, 7], [1, 1.01, 0]], "batl": NaN}, {"timestamp": 1631527288099, "ltp": 2.74, "tv": 89.58, "trd": NaN, "batb": [[0, 2.12, 394.79], [1, 1.01, 7]], "batl": [[0, 4.2, 150.36]]}, {"timestamp": 1631527371698, "ltp": 2.74, "tv": 89.58, "trd": NaN, "batb": [[0, 1.01, 7], [1, 1.01, 0]], "batl": NaN}, {"timestamp": 1631527377246, "ltp": 2.74, "tv": 89.58, "trd": NaN, "batb": [[0, 2.3, 391.17], [1, 1.01, 7]], "batl": [[0, 4.9, 128.27]]}, {"timestamp": 1631527395369, "ltp": 2.74, "tv": 89.58, "trd": NaN, "batb": NaN, "batl": [[0, 5.5, 116.87]]}, {"timestamp": 1631527415493, "ltp": 2.74, "tv": 89.58, "trd": NaN, "batb": [[0, 1.01, 7], [1, 1.01, 0]], "batl": NaN}, {"timestamp": 1631527421687, "ltp": 2.74, "tv": 89.58, "trd": NaN, "batb": [[0, 2.52, 387.48], [1, 1.01, 7]], "batl": NaN}, {"timestamp": 1631527458510, "ltp": 2.74, "tv": 89.58, "trd": NaN, "batb": NaN, "batl": [[0, 6.6, 100.51]]}, {"timestamp": 1631527484480, "ltp": 2.74, "tv": 89.58, "trd": NaN, "batb": [[0, 1.01, 7], [1, 1.01, 0]], "batl": NaN}, {"timestamp": 1631527490687, "ltp": 2.74, "tv": 89.58, "trd": NaN, "batb": [[0, 2.84, 381.34], [1, 1.01, 7]], "batl": [[0, 8.2, 86.81]]}, {"timestamp": 1631527509813, "ltp": 2.74, "tv": 89.58, "trd": NaN, "batb": NaN, "batl": [[0, 6.6, 100.51]]}, {"timestamp": 1631527533032, "ltp": 2.74, "tv": 89.58, "trd": NaN, "batb": NaN, "batl": [[0, 8.2, 86.81]]}, {"timestamp": 1631527560685, "ltp": 2.74, "tv": 89.58, "trd": NaN, "batb": [[0, 1.01, 7], [1, 1.01, 0]], "batl": NaN}, {"timestamp": 1631527566590, "ltp": 2.74, "tv": 89.58, "trd": NaN, "batb": [[0, 3.1, 379.68], [1, 1.01, 7]], "batl": [[0, 10.5, 73.47]]}, {"timestamp": 1631527586828, "ltp": 2.74, "tv": 89.58, "trd": NaN, "batb": NaN, "batl": [[0, 12, 68.85]]}, {"timestamp": 1631527598816, "ltp": 2.74, "tv": 89.58, "trd": NaN, "batb": NaN, "batl": [[0, 9.4, 79.27]]}, {"timestamp": 1631527635356, "ltp": 2.74, "tv": 89.58, "trd": NaN, "batb": NaN, "batl": [[0, 13.5, 65.08]]}, {"timestamp": 1631527714888, "ltp": 2.74, "tv": 89.58, "trd": NaN, "batb": [[0, 1.01, 7], [1, 1.01, 0]], "batl": NaN}, {"timestamp": 1631527720375, "ltp": 2.74, "tv": 89.58, "trd": NaN, "batb": [[0, 3.5, 382.15], [1, 1.01, 7]], "batl": [[0, 18, 57.1]]}, {"timestamp": 1631527738621, "ltp": 2.74, "tv": 89.58, "trd": NaN, "batb": NaN, "batl": [[0, 23, 52.05]]}, {"timestamp": 1631527753947, "ltp": 2.74, "tv": 89.58, "trd": NaN, "batb": NaN, "batl": [[0, 21, 54.32]]}, {"timestamp": 1631527769137, "ltp": 2.74, "tv": 89.58, "trd": NaN, "batb": NaN, "batl": [[0, 26, 50.16]]}, {"timestamp": 1631527807603, "ltp": 2.74, "tv": 89.58, "trd": NaN, "batb": NaN, "batl": [[0, 34, 46.8]]}, {"timestamp": 1631527839039, "ltp": 2.74, "tv": 89.58, "trd": NaN, "batb": NaN, "batl": [[0, 26, 50.16]]}, {"timestamp": 1631527933703, "ltp": 2.74, "tv": 89.58, "trd": NaN, "batb": [[0, 1.01, 7], [1, 1.01, 0]], "batl": NaN}, {"timestamp": 1631528078962, "ltp": 2.74, "tv": 89.58, "trd": NaN, "batb": [[0, 4.2, 376.8], [1, 1.01, 7]], "batl": [[0, 85, 39.75]]}, {"timestamp": 1631528116504, "ltp": 2.74, "tv": 89.58, "trd": NaN, "batb": NaN, "batl": [[0, 60, 41.62]]}, {"timestamp": 1631528146973, "ltp": 2.74, "tv": 89.58, "trd": NaN, "batb": NaN, "batl": [[0, 46, 43.64]]}, {"timestamp": 1631528179495, "ltp": 2.74, "tv": 89.58, "trd": NaN, "batb": NaN, "batl": [[0, 85, 39.75]]}, {"timestamp": 1631528251697, "ltp": 2.74, "tv": 89.58, "trd": NaN, "batb": NaN, "batl": [[0, 170, 37.56]]}, {"timestamp": 1631528269917, "ltp": 2.74, "tv": 89.58, "trd": NaN, "batb": NaN, "batl": [[0, 85, 39.75]]}, {"timestamp": 1631528285259, "ltp": 2.74, "tv": 89.58, "trd": NaN, "batb": NaN, "batl": [[0, 340, 36.45]]}, {"timestamp": 1631528315795, "ltp": 2.74, "tv": 89.58, "trd": NaN, "batb": NaN, "batl": [[0, 170, 37.56]]}, {"timestamp": 1631528350246, "ltp": 2.74, "tv": 89.58, "trd": NaN, "batb": NaN, "batl": [[0, 340, 36.45]]}, {"timestamp": 1631528379783, "ltp": 2.74, "tv": 89.58, "trd": NaN, "batb": NaN, "batl": [[0, 170, 37.56]]}, {"timestamp": 1631528405232, "ltp": 2.74, "tv": 89.58, "trd": NaN, "batb": NaN, "batl": [[0, 340, 36.45]]}, {"timestamp": 1631528471383, "ltp": 2.74, "tv": 89.58, "trd": NaN, "batb": NaN, "batl": [[0, 340, 36.45]]}, {"timestamp": 1631528812474, "ltp": 2.74, "tv": 89.58, "trd": NaN, "batb": [[0, 1.01, 7], [1, 1.01, 0]], "batl": NaN}, {"timestamp": 1631528874542, "ltp": 2.74, "tv": 89.58, "trd": NaN, "batb": [[0, 4.7, 377.45], [1, 1.01, 7]], "batl": NaN}, {"timestamp": 1631529208591, "ltp": 2.74, "tv": 89.58, "trd": NaN, "batb": NaN, "batl": [[0, 340, 36.45]]}, {"timestamp": 1631529260904, "ltp": 2.74, "tv": 89.58, "trd": NaN, "batb": [[0, 1.01, 7], [1, 1.01, 0]], "batl": NaN}, {"timestamp": 1631529284709, "ltp": 2.74, "tv": 89.58, "trd": NaN, "batb": [[0, 4.7, 377.45], [1, 1.01, 7]], "batl": NaN}, {"timestamp": 1631529294532, "ltp": 2.74, "tv": 89.58, "trd": NaN, "batb": [[0, 1.01, 7], [1, 1.01, 0]], "batl": NaN}, {"timestamp": 1631529307045, "ltp": 2.74, "tv": 89.58, "trd": NaN, "batb": [[0, 4.8, 372.55], [1, 1.01, 7]], "batl": NaN}, {"timestamp": 1631529393769, "ltp": 2.74, "tv": 89.58, "trd": NaN, "batb": [[0, 1.01, 7], [1, 1.01, 0]], "batl": NaN}]}, {"runnerId": 21397559, "odds": [{"timestamp": 1631525990580, "ltp": 1.28, "tv": 66.67, "trd": [[1.28, 66.67]], "batb": NaN, "batl": [[0, 1.28, 33.33]]}, {"timestamp": 1631525995412, "ltp": 1.28, "tv": 91.04, "trd": [[1.28, 91.05]], "batb": NaN, "batl": [[0, 1.28, 21.14]]}, {"timestamp": 1631525996497, "ltp": 1.28, "tv": 112.18, "trd": [[1.28, 112.19]], "batb": NaN, "batl": NaN}, {"timestamp": 1631526022158, "ltp": 1.28, "tv": 112.18, "trd": NaN, "batb": [[0, 1.27, 256.04], [1, 1.18, 256.04], [2, 1.01, 7]], "batl": NaN}, {"timestamp": 1631526204089, "ltp": 1.28, "tv": 112.18, "trd": NaN, "batb": [[0, 1.18, 256.04], [1, 1.01, 7], [2, 1.01, 0]], "batl": NaN}, {"timestamp": 1631526206218, "ltp": 1.28, "tv": 112.18, "trd": NaN, "batb": [[0, 1.01, 7], [1, 1.01, 0]], "batl": NaN}, {"timestamp": 1631526209803, "ltp": 1.28, "tv": 112.18, "trd": NaN, "batb": [[0, 1.24, 256.04], [1, 1.01, 7]], "batl": NaN}, {"timestamp": 1631526245836, "ltp": 1.28, "tv": 112.18, "trd": NaN, "batb": [[0, 1.01, 7], [1, 1.01, 0]], "batl": NaN}, {"timestamp": 1631526251576, "ltp": 1.28, "tv": 112.18, "trd": NaN, "batb": [[0, 1.18, 256.04], [1, 1.01, 7]], "batl": NaN}, {"timestamp": 1631526254175, "ltp": 1.28, "tv": 112.18, "trd": NaN, "batb": NaN, "batl": [[0, 1.43, 256.04]]}, {"timestamp": 1631526286710, "ltp": 1.18, "tv": 624.26, "trd": [[1.18, 512.08]], "batb": [[0, 1.01, 7], [1, 1.01, 0]], "batl": [[0, 1.18, 20.21]]}, {"timestamp": 1631526290733, "ltp": 1.18, "tv": 624.26, "trd": NaN, "batb": NaN, "batl": [[1, 1.51, 256.04]]}, {"timestamp": 1631526295490, "ltp": 1.18, "tv": 664.69, "trd": [[1.18, 552.51]], "batb": [[0, 1.18, 33.35], [1, 1.01, 7]], "batl": [[0, 1.51, 256.04], [1, 1.51, 0]]}, {"timestamp": 1631526296625, "ltp": 1.18, "tv": 664.69, "trd": NaN, "batb": [[0, 1.18, 245.36]], "batl": [[0, 1.27, 237.89], [1, 1.51, 256.04]]}, {"timestamp": 1631526297532, "ltp": 1.18, "tv": 664.69, "trd": NaN, "batb": [[0, 1.18, 212.18]], "batl": NaN}, {"timestamp": 1631526298409, "ltp": 1.18, "tv": 664.69, "trd": NaN, "batb": [[0, 1.19, 256.04], [1, 1.18, 173.42], [2, 1.01, 7]], "batl": NaN}, {"timestamp": 1631526299538, "ltp": 1.18, "tv": 664.69, "trd": NaN, "batb": [[1, 1.18, 53.75]], "batl": NaN}, {"timestamp": 1631526300531, "ltp": 1.18, "tv": 664.69, "trd": NaN, "batb": [[1, 1.18, 180]], "batl": NaN}, {"timestamp": 1631526301626, "ltp": 1.18, "tv": 664.69, "trd": NaN, "batb": [[1, 1.18, 120]], "batl": NaN}, {"timestamp": 1631526302416, "ltp": 1.18, "tv": 664.69, "trd": NaN, "batb": [[1, 1.18, 20]], "batl": NaN}, {"timestamp": 1631526303035, "ltp": 1.18, "tv": 664.69, "trd": NaN, "batb": [[0, 1.2, 256.04], [1, 1.19, 256.04]], "batl": NaN}, {"timestamp": 1631526305825, "ltp": 1.18, "tv": 664.69, "trd": NaN, "batb": [[0, 1.19, 256.04], [1, 1.01, 7], [2, 1.01, 0]], "batl": NaN}, {"timestamp": 1631526309333, "ltp": 1.18, "tv": 664.69, "trd": NaN, "batb": NaN, "batl": [[0, 1.51, 256.04], [1, 1.51, 0]]}, {"timestamp": 1631526313414, "ltp": 1.18, "tv": 664.69, "trd": NaN, "batb": NaN, "batl": [[0, 1.22, 247.64], [1, 1.51, 256.04]]}, {"timestamp": 1631526316569, "ltp": 1.18, "tv": 664.69, "trd": NaN, "batb": [[1, 1.15, 256.04], [2, 1.1, 256.04]], "batl": NaN}, {"timestamp": 1631526319942, "ltp": 1.22, "tv": 674.39, "trd": [[1.22, 9.7]], "batb": NaN, "batl": [[0, 1.22, 237.94]]}, {"timestamp": 1631526336662, "ltp": 1.22, "tv": 814.3, "trd": [[1.22, 149.61]], "batb": NaN, "batl": [[0, 1.22, 167.99]]}, {"timestamp": 1631526340286, "ltp": 1.22, "tv": 814.3, "trd": NaN, "batb": NaN, "batl": [[0, 1.51, 256.04], [1, 1.51, 0]]}, {"timestamp": 1631526346878, "ltp": 1.22, "tv": 814.3, "trd": NaN, "batb": NaN, "batl": [[0, 1.3, 157.65], [1, 1.51, 256.04]]}, {"timestamp": 1631526348183, "ltp": 1.22, "tv": 814.3, "trd": NaN, "batb": [[0, 1.25, 256.04], [1, 1.23, 256.04], [2, 1.19, 256.04]], "batl": NaN}, {"timestamp": 1631526375506, "ltp": 1.22, "tv": 814.3, "trd": NaN, "batb": NaN, "batl": [[0, 1.51, 256.04], [1, 1.51, 0]]}, {"timestamp": 1631526384211, "ltp": 1.22, "tv": 814.3, "trd": NaN, "batb": NaN, "batl": [[0, 1.3, 157.65], [1, 1.51, 256.04]]}, {"timestamp": 1631526391134, "ltp": 1.22, "tv": 814.3, "trd": NaN, "batb": [[1, 1.19, 256.04], [2, 1.15, 256.04]], "batl": NaN}, {"timestamp": 1631526404716, "ltp": 1.3, "tv": 945.6, "trd": [[1.3, 131.3]], "batb": NaN, "batl": [[0, 1.3, 92]]}, {"timestamp": 1631526408143, "ltp": 1.3, "tv": 945.6, "trd": NaN, "batb": NaN, "batl": [[0, 1.51, 256.04], [1, 1.51, 0]]}, {"timestamp": 1631526413948, "ltp": 1.3, "tv": 945.6, "trd": NaN, "batb": [[1, 1.15, 256.04], [2, 1.1, 256.04]], "batl": NaN}, {"timestamp": 1631526414933, "ltp": 1.3, "tv": 945.6, "trd": NaN, "batb": [[1, 1.1, 256.04], [2, 1.01, 7]], "batl": [[0, 1.35, 88.6], [1, 1.51, 256.04]]}, {"timestamp": 1631526418150, "ltp": 1.3, "tv": 945.6, "trd": NaN, "batb": [[0, 1.3, 256.04], [1, 1.25, 256.04], [2, 1.1, 256.04]], "batl": NaN}, {"timestamp": 1631526421061, "ltp": 1.3, "tv": 945.6, "trd": NaN, "batb": [[2, 1.17, 256.04]], "batl": NaN}, {"timestamp": 1631526421740, "ltp": 1.3, "tv": 945.6, "trd": NaN, "batb": [[2, 1.2, 256.04]], "batl": NaN}, {"timestamp": 1631526516962, "ltp": 1.3, "tv": 945.6, "trd": NaN, "batb": NaN, "batl": [[0, 1.51, 256.04], [1, 1.51, 0]]}, {"timestamp": 1631526522896, "ltp": 1.3, "tv": 945.6, "trd": NaN, "batb": [[0, 1.4, 256.04], [1, 1.3, 256.04], [2, 1.25, 256.04]], "batl": NaN}, {"timestamp": 1631526527402, "ltp": 1.3, "tv": 945.6, "trd": NaN, "batb": NaN, "batl": [[0, 1.45, 82.49]]}, {"timestamp": 1631526550133, "ltp": 1.3, "tv": 945.6, "trd": NaN, "batb": [[0, 1.3, 256.04], [1, 1.25, 256.04], [2, 1.2, 256.04]], "batl": NaN}, {"timestamp": 1631526558347, "ltp": 1.3, "tv": 945.6, "trd": NaN, "batb": NaN, "batl": [[0, 1.4, 85.43]]}, {"timestamp": 1631526571838, "ltp": 1.3, "tv": 945.6, "trd": NaN, "batb": [[0, 1.25, 256.04], [1, 1.2, 256.04], [2, 1.17, 256.04]], "batl": NaN}, {"timestamp": 1631526578547, "ltp": 1.3, "tv": 945.6, "trd": NaN, "batb": NaN, "batl": [[0, 1.3, 92], [1, 1.4, 85.43]]}, {"timestamp": 1631526579542, "ltp": 1.3, "tv": 945.6, "trd": NaN, "batb": NaN, "batl": [[1, 1.4, 0]]}, {"timestamp": 1631526580255, "ltp": 1.3, "tv": 945.6, "trd": NaN, "batb": [[0, 1.28, 256.04], [1, 1.25, 256.04], [2, 1.2, 256.04]], "batl": NaN}, {"timestamp": 1631526593354, "ltp": 1.3, "tv": 945.6, "trd": NaN, "batb": NaN, "batl": [[0, 1.33, 89.93]]}, {"timestamp": 1631526633025, "ltp": 1.3, "tv": 945.6, "trd": NaN, "batb": [[0, 1.36, 256.04], [1, 1.28, 256.04], [2, 1.25, 256.04]], "batl": NaN}, {"timestamp": 1631526634419, "ltp": 1.3, "tv": 945.6, "trd": NaN, "batb": NaN, "batl": [[0, 1.41, 84.83]]}, {"timestamp": 1631526653644, "ltp": 1.3, "tv": 945.6, "trd": NaN, "batb": [[0, 1.28, 256.04], [1, 1.25, 256.04], [2, 1.2, 256.04]], "batl": NaN}, {"timestamp": 1631526659261, "ltp": 1.3, "tv": 945.6, "trd": NaN, "batb": [[0, 1.25, 256.04], [1, 1.2, 256.04], [2, 1.17, 256.04]], "batl": NaN}, {"timestamp": 1631526663467, "ltp": 1.3, "tv": 945.6, "trd": NaN, "batb": NaN, "batl": [[0, 1.3, 92], [1, 1.41, 84.83]]}, {"timestamp": 1631526676201, "ltp": 1.3, "tv": 945.6, "trd": NaN, "batb": [[0, 1.2, 256.04], [1, 1.17, 256.04], [2, 1.1, 256.04]], "batl": NaN}, {"timestamp": 1631526679202, "ltp": 1.3, "tv": 945.6, "trd": NaN, "batb": NaN, "batl": [[0, 1.41, 84.83], [1, 1.41, 0]]}, {"timestamp": 1631526682508, "ltp": 1.3, "tv": 945.6, "trd": NaN, "batb": [[0, 1.23, 256.04], [1, 1.2, 256.04], [2, 1.17, 256.04]], "batl": NaN}, {"timestamp": 1631526683799, "ltp": 1.3, "tv": 945.6, "trd": NaN, "batb": NaN, "batl": [[0, 1.28, 93.45]]}, {"timestamp": 1631526715776, "ltp": 1.3, "tv": 945.6, "trd": NaN, "batb": NaN, "batl": [[0, 1.3, 92]]}, {"timestamp": 1631526722677, "ltp": 1.3, "tv": 945.6, "trd": NaN, "batb": [[0, 1.27, 256.04], [1, 1.23, 256.04], [2, 1.2, 256.04]], "batl": NaN}, {"timestamp": 1631526745907, "ltp": 1.3, "tv": 945.6, "trd": NaN, "batb": [[0, 1.23, 256.04], [1, 1.2, 256.04], [2, 1.17, 256.04]], "batl": NaN}, {"timestamp": 1631526750090, "ltp": 1.3, "tv": 945.6, "trd": NaN, "batb": NaN, "batl": [[0, 1.25, 95.68], [1, 1.3, 92]]}, {"timestamp": 1631526768440, "ltp": 1.3, "tv": 945.6, "trd": NaN, "batb": NaN, "batl": [[0, 1.3, 92], [1, 1.3, 0]]}, {"timestamp": 1631526798384, "ltp": 1.3, "tv": 945.6, "trd": NaN, "batb": [[0, 1.2, 256.04], [1, 1.17, 256.04], [2, 1.1, 256.04]], "batl": NaN}, {"timestamp": 1631526805806, "ltp": 1.3, "tv": 945.6, "trd": NaN, "batb": NaN, "batl": [[0, 1.26, 94.92], [1, 1.3, 92]]}, {"timestamp": 1631526828539, "ltp": 1.3, "tv": 945.6, "trd": NaN, "batb": NaN, "batl": [[0, 1.3, 92], [1, 1.3, 0]]}, {"timestamp": 1631526836414, "ltp": 1.3, "tv": 945.6, "trd": NaN, "batb": NaN, "batl": [[0, 1.33, 89.93]]}, {"timestamp": 1631526837031, "ltp": 1.3, "tv": 945.6, "trd": NaN, "batb": [[0, 1.3, 256.04], [1, 1.2, 256.04], [2, 1.17, 256.04]], "batl": NaN}, {"timestamp": 1631526849956, "ltp": 1.3, "tv": 945.6, "trd": NaN, "batb": [[0, 1.2, 256.04], [1, 1.17, 256.04], [2, 1.1, 256.04]], "batl": NaN}, {"timestamp": 1631526857660, "ltp": 1.3, "tv": 945.6, "trd": NaN, "batb": NaN, "batl": [[0, 1.28, 93.45]]}, {"timestamp": 1631526893006, "ltp": 1.3, "tv": 945.6, "trd": NaN, "batb": NaN, "batl": [[0, 1.22, 98.04]]}, {"timestamp": 1631526905096, "ltp": 1.3, "tv": 945.6, "trd": NaN, "batb": NaN, "batl": [[0, 1.34, 89.25]]}, {"timestamp": 1631526906080, "ltp": 1.3, "tv": 945.6, "trd": NaN, "batb": [[0, 1.3, 256.04], [1, 1.2, 256.04], [2, 1.17, 256.04]], "batl": NaN}, {"timestamp": 1631526932326, "ltp": 1.3, "tv": 945.6, "trd": NaN, "batb": [[0, 1.34, 11.95], [1, 1.3, 256.04], [2, 1.2, 256.04]], "batl": NaN}, {"timestamp": 1631526933046, "ltp": 1.3, "tv": 945.6, "trd": NaN, "batb": [[0, 1.3, 256.04], [1, 1.2, 256.04], [2, 1.17, 256.04]], "batl": NaN}, {"timestamp": 1631526934125, "ltp": 1.3, "tv": 945.6, "trd": NaN, "batb": NaN, "batl": [[0, 1.4, 85.43]]}, {"timestamp": 1631526936353, "ltp": 1.3, "tv": 945.6, "trd": NaN, "batb": [[0, 1.36, 256.04], [1, 1.35, 256.04], [2, 1.3, 256.04]], "batl": NaN}, {"timestamp": 1631526995297, "ltp": 1.3, "tv": 945.6, "trd": NaN, "batb": [[1, 1.3, 256.04], [2, 1.2, 256.04]], "batl": NaN}, {"timestamp": 1631527041199, "ltp": 1.3, "tv": 945.6, "trd": NaN, "batb": [[0, 1.44, 256.04], [1, 1.36, 256.04], [2, 1.3, 256.04]], "batl": NaN}, {"timestamp": 1631527042910, "ltp": 1.3, "tv": 945.6, "trd": NaN, "batb": NaN, "batl": [[0, 1.48, 80.81]]}, {"timestamp": 1631527076954, "ltp": 1.3, "tv": 945.6, "trd": NaN, "batb": [[0, 1.5, 256.04], [1, 1.44, 256.04], [2, 1.36, 256.04]], "batl": NaN}, {"timestamp": 1631527078344, "ltp": 1.3, "tv": 945.6, "trd": NaN, "batb": NaN, "batl": [[0, 1.57, 76.18]]}, {"timestamp": 1631527082863, "ltp": 1.3, "tv": 945.6, "trd": NaN, "batb": NaN, "batl": [[0, 1.52, 78.69], [1, 1.57, 76.18]]}, {"timestamp": 1631527084363, "ltp": 1.3, "tv": 945.6, "trd": NaN, "batb": NaN, "batl": [[2, 1000, 0.12]]}, {"timestamp": 1631527085355, "ltp": 1.57, "tv": 1061.81, "trd": [[1.52, 78.69], [1.57, 37.52]], "batb": NaN, "batl": NaN}, {"timestamp": 1631527089741, "ltp": 1.5, "tv": 1062.05, "trd": [[1.5, 0.24]], "batb": [[0, 1.5, 255.92]], "batl": NaN}, {"timestamp": 1631527090674, "ltp": 1.5, "tv": 1062.05, "trd": NaN, "batb": [[2, 1.3, 256.04]], "batl": NaN}, {"timestamp": 1631527092781, "ltp": 1.5, "tv": 1062.05, "trd": NaN, "batb": [[0, 1.54, 38.25], [1, 1.5, 255.92], [2, 1.44, 256.04]], "batl": NaN}, {"timestamp": 1631527094755, "ltp": 1.5, "tv": 1062.05, "trd": NaN, "batb": [[1, 1.53, 256.04], [2, 1.5, 255.92]], "batl": NaN}, {"timestamp": 1631527100191, "ltp": 1.5, "tv": 1062.05, "trd": NaN, "batb": NaN, "batl": [[0, 1.73, 256.04]]}, {"timestamp": 1631527101385, "ltp": 1.5, "tv": 1062.05, "trd": NaN, "batb": [[0, 1.5, 255.92], [1, 1.44, 256.04], [2, 1.3, 256.04]], "batl": NaN}, {"timestamp": 1631527102947, "ltp": 1.5, "tv": 1062.05, "trd": NaN, "batb": [[0, 1.62, 256.04], [1, 1.5, 255.92]], "batl": NaN}, {"timestamp": 1631527104075, "ltp": 1.5, "tv": 1062.05, "trd": NaN, "batb": [[0, 1.7, 34.55], [1, 1.62, 256.04], [2, 1.5, 255.92]], "batl": NaN}, {"timestamp": 1631527117987, "ltp": 1.5, "tv": 1062.05, "trd": NaN, "batb": NaN, "batl": [[0, 1.83, 256.04]]}, {"timestamp": 1631527120785, "ltp": 1.5, "tv": 1062.05, "trd": NaN, "batb": [[0, 1.75, 33.56], [1, 1.7, 34.55], [2, 1.62, 256.04]], "batl": NaN}, {"timestamp": 1631527124203, "ltp": 1.5, "tv": 1062.05, "trd": NaN, "batb": [[0, 1.8, 256.04], [1, 1.75, 33.56], [2, 1.7, 34.55]], "batl": NaN}, {"timestamp": 1631527127472, "ltp": 1.5, "tv": 1062.05, "trd": NaN, "batb": [[0, 1.75, 33.56], [1, 1.62, 256.04], [2, 1.5, 255.92]], "batl": NaN}, {"timestamp": 1631527128509, "ltp": 1.5, "tv": 1062.05, "trd": NaN, "batb": [[1, 1.5, 255.92], [2, 1.01, 7]], "batl": NaN}, {"timestamp": 1631527129700, "ltp": 1.5, "tv": 1062.05, "trd": NaN, "batb": NaN, "batl": [[0, 2, 256.04]]}, {"timestamp": 1631527130685, "ltp": 1.5, "tv": 1062.05, "trd": NaN, "batb": [[1, 1.01, 7], [2, 1.01, 0]], "batl": NaN}, {"timestamp": 1631527136429, "ltp": 1.5, "tv": 1062.05, "trd": NaN, "batb": [[0, 1.01, 7], [1, 1.01, 0]], "batl": NaN}, {"timestamp": 1631527138600, "ltp": 1.5, "tv": 1062.05, "trd": NaN, "batb": [[0, 1.8, 32.63], [1, 1.01, 7]], "batl": NaN}, {"timestamp": 1631527139228, "ltp": 1.5, "tv": 1062.05, "trd": NaN, "batb": [[0, 1.01, 7], [1, 1.01, 0]], "batl": NaN}, {"timestamp": 1631527142599, "ltp": 1.5, "tv": 1062.05, "trd": NaN, "batb": [[0, 1.73, 33.94], [1, 1.01, 7]], "batl": NaN}, {"timestamp": 1631527148334, "ltp": 1.5, "tv": 1062.05, "trd": NaN, "batb": [[1, 1.56, 256.04], [2, 1.01, 7]], "batl": NaN}, {"timestamp": 1631527149109, "ltp": 1.5, "tv": 1062.05, "trd": NaN, "batb": [[1, 1.57, 256.04], [2, 1.56, 256.04]], "batl": NaN}, {"timestamp": 1631527158414, "ltp": 1.5, "tv": 1062.05, "trd": NaN, "batb": [[0, 1.57, 256.04], [1, 1.56, 256.04], [2, 1.01, 7]], "batl": NaN}, {"timestamp": 1631527162724, "ltp": 1.5, "tv": 1062.05, "trd": NaN, "batb": [[0, 1.8, 32.63], [1, 1.57, 256.04], [2, 1.56, 256.04]], "batl": NaN}, {"timestamp": 1631527167743, "ltp": 1.5, "tv": 1062.05, "trd": NaN, "batb": [[2, 1.01, 7]], "batl": NaN}, {"timestamp": 1631527210911, "ltp": 1.5, "tv": 1062.05, "trd": NaN, "batb": [[0, 1.57, 256.04], [1, 1.01, 7], [2, 1.01, 0]], "batl": NaN}, {"timestamp": 1631527217545, "ltp": 1.5, "tv": 1062.05, "trd": NaN, "batb": [[0, 1.77, 33.18], [1, 1.57, 256.04], [2, 1.01, 7]], "batl": NaN}, {"timestamp": 1631527228933, "ltp": 1.5, "tv": 1062.05, "trd": NaN, "batb": [[0, 1.57, 256.04], [1, 1.01, 7], [2, 1.01, 0]], "batl": NaN}, {"timestamp": 1631527231526, "ltp": 1.5, "tv": 1062.05, "trd": NaN, "batb": [[0, 1.01, 7], [1, 1.01, 0]], "batl": NaN}, {"timestamp": 1631527235540, "ltp": 1.5, "tv": 1062.05, "trd": NaN, "batb": [[0, 1.7, 34.55], [1, 1.01, 7]], "batl": NaN}, {"timestamp": 1631527237236, "ltp": 1.5, "tv": 1062.05, "trd": NaN, "batb": NaN, "batl": [[0, 1.8, 256.04], [1, 2, 256.04]]}, {"timestamp": 1631527264773, "ltp": 1.5, "tv": 1062.05, "trd": NaN, "batb": [[0, 1.01, 7], [1, 1.01, 0]], "batl": NaN}, {"timestamp": 1631527268592, "ltp": 1.5, "tv": 1062.05, "trd": NaN, "batb": NaN, "batl": [[1, 2, 0]]}, {"timestamp": 1631527271500, "ltp": 1.5, "tv": 1062.05, "trd": NaN, "batb": [[0, 1.6, 36.71], [1, 1.01, 7]], "batl": NaN}, {"timestamp": 1631527272575, "ltp": 1.5, "tv": 1062.05, "trd": NaN, "batb": NaN, "batl": [[0, 1.7, 256.04], [1, 1.8, 256.04]]}, {"timestamp": 1631527284375, "ltp": 1.5, "tv": 1062.05, "trd": NaN, "batb": [[0, 1.01, 7], [1, 1.01, 0]], "batl": NaN}, {"timestamp": 1631527288099, "ltp": 1.5, "tv": 1062.05, "trd": NaN, "batb": NaN, "batl": [[1, 1.8, 0]]}, {"timestamp": 1631527291975, "ltp": 1.5, "tv": 1062.05, "trd": NaN, "batb": NaN, "batl": [[0, 1.6, 256.04], [1, 1.7, 256.04]]}, {"timestamp": 1631527295296, "ltp": 1.5, "tv": 1062.05, "trd": NaN, "batb": [[0, 1.5, 39.15], [1, 1.01, 7]], "batl": NaN}, {"timestamp": 1631527373145, "ltp": 1.5, "tv": 1062.05, "trd": NaN, "batb": [[0, 1.01, 7], [1, 1.01, 0]], "batl": NaN}, {"timestamp": 1631527379008, "ltp": 1.5, "tv": 1062.05, "trd": NaN, "batb": NaN, "batl": [[0, 1.47, 256.04], [1, 1.6, 256.04], [2, 1.7, 256.04]]}, {"timestamp": 1631527381713, "ltp": 1.5, "tv": 1062.05, "trd": NaN, "batb": [[0, 1.45, 40.51], [1, 1.01, 7]], "batl": NaN}, {"timestamp": 1631527392771, "ltp": 1.5, "tv": 1062.05, "trd": NaN, "batb": [[0, 1.01, 7], [1, 1.01, 0]], "batl": NaN}, {"timestamp": 1631527401770, "ltp": 1.5, "tv": 1062.05, "trd": NaN, "batb": [[0, 1.38, 42.55], [1, 1.01, 7]], "batl": NaN}, {"timestamp": 1631527403845, "ltp": 1.5, "tv": 1062.05, "trd": NaN, "batb": NaN, "batl": [[2, 1.7, 0]]}, {"timestamp": 1631527404779, "ltp": 1.5, "tv": 1062.05, "trd": NaN, "batb": NaN, "batl": [[1, 1.6, 0]]}, {"timestamp": 1631527453747, "ltp": 1.5, "tv": 1062.05, "trd": NaN, "batb": [[0, 1.01, 7], [1, 1.01, 0]], "batl": NaN}, {"timestamp": 1631527458510, "ltp": 1.5, "tv": 1062.05, "trd": NaN, "batb": NaN, "batl": [[0, 1.38, 25.6], [1, 1.47, 256.04]]}, {"timestamp": 1631527459605, "ltp": 1.5, "tv": 1062.05, "trd": NaN, "batb": NaN, "batl": [[0, 1.38, 425.75]]}, {"timestamp": 1631527460327, "ltp": 1.5, "tv": 1062.05, "trd": NaN, "batb": [[0, 1.34, 43.83], [1, 1.01, 7]], "batl": [[0, 1.38, 320.18]]}, {"timestamp": 1631527461521, "ltp": 1.38, "tv": 1066.05, "trd": [[1.38, 4]], "batb": NaN, "batl": [[0, 1.38, 28]]}, {"timestamp": 1631527462247, "ltp": 1.38, "tv": 1066.05, "trd": NaN, "batb": NaN, "batl": [[0, 1.47, 256.04], [1, 1.47, 0]]}, {"timestamp": 1631527463440, "ltp": 1.38, "tv": 1066.05, "trd": NaN, "batb": NaN, "batl": [[0, 1.42, 256.04], [1, 1.47, 256.04]]}, {"timestamp": 1631527489964, "ltp": 1.34, "tv": 1153.7, "trd": [[1.34, 87.65]], "batb": [[0, 1.01, 7], [1, 1.01, 0]], "batl": NaN}, {"timestamp": 1631527503193, "ltp": 1.34, "tv": 1153.7, "trd": NaN, "batb": NaN, "batl": [[1, 1.47, 0]]}, {"timestamp": 1631527507020, "ltp": 1.34, "tv": 1153.7, "trd": NaN, "batb": NaN, "batl": [[0, 1.3, 256.04], [1, 1.42, 256.04]]}, {"timestamp": 1631527508618, "ltp": 1.34, "tv": 1153.7, "trd": NaN, "batb": NaN, "batl": [[0, 1.42, 256.04], [1, 1.42, 0]]}, {"timestamp": 1631527511524, "ltp": 1.34, "tv": 1153.7, "trd": NaN, "batb": [[0, 1.17, 256.04], [1, 1.14, 256.04], [2, 1.01, 7]], "batl": NaN}, {"timestamp": 1631527512402, "ltp": 1.34, "tv": 1153.7, "trd": NaN, "batb": [[0, 1.25, 256.04], [1, 1.17, 256.04], [2, 1.14, 256.04]], "batl": NaN}, {"timestamp": 1631527527151, "ltp": 1.34, "tv": 1153.7, "trd": NaN, "batb": [[0, 1.17, 256.04], [1, 1.14, 256.04], [2, 1.01, 7]], "batl": NaN}, {"timestamp": 1631527534424, "ltp": 1.34, "tv": 1153.7, "trd": NaN, "batb": NaN, "batl": [[0, 1.3, 256.04], [1, 1.42, 256.04]]}, {"timestamp": 1631527564018, "ltp": 1.34, "tv": 1153.7, "trd": NaN, "batb": [[0, 1.14, 256.04], [1, 1.01, 7], [2, 1.01, 0]], "batl": NaN}, {"timestamp": 1631527566590, "ltp": 1.34, "tv": 1153.7, "trd": NaN, "batb": [[0, 1.01, 7], [1, 1.01, 0]], "batl": NaN}, {"timestamp": 1631527570214, "ltp": 1.34, "tv": 1153.7, "trd": NaN, "batb": NaN, "batl": [[0, 1.24, 256.04], [1, 1.42, 0]]}, {"timestamp": 1631527571607, "ltp": 1.34, "tv": 1153.7, "trd": NaN, "batb": [[0, 1.13, 256.04], [1, 1.01, 7]], "batl": NaN}, {"timestamp": 1631527572124, "ltp": 1.34, "tv": 1153.7, "trd": NaN, "batb": [[1, 1.12, 256.04], [2, 1.01, 7]], "batl": NaN}, {"timestamp": 1631527601035, "ltp": 1.34, "tv": 1153.7, "trd": NaN, "batb": NaN, "batl": [[0, 1.3, 256.04]]}, {"timestamp": 1631527615283, "ltp": 1.34, "tv": 1153.7, "trd": NaN, "batb": [[1, 1.01, 7], [2, 1.01, 0]], "batl": NaN}, {"timestamp": 1631527619157, "ltp": 1.34, "tv": 1153.7, "trd": NaN, "batb": [[0, 1.15, 256.04], [1, 1.13, 256.04], [2, 1.01, 7]], "batl": NaN}, {"timestamp": 1631527622062, "ltp": 1.34, "tv": 1153.7, "trd": NaN, "batb": [[1, 1.01, 7], [2, 1.01, 0]], "batl": NaN}, {"timestamp": 1631527630700, "ltp": 1.34, "tv": 1153.7, "trd": NaN, "batb": [[0, 1.01, 7], [1, 1.01, 0]], "batl": NaN}, {"timestamp": 1631527636956, "ltp": 1.34, "tv": 1153.7, "trd": NaN, "batb": NaN, "batl": [[0, 1.21, 256.04]]}, {"timestamp": 1631527638506, "ltp": 1.34, "tv": 1153.7, "trd": NaN, "batb": NaN, "batl": [[0, 1.2, 256.04], [1, 1.21, 256.04]]}, {"timestamp": 1631527639594, "ltp": 1.34, "tv": 1153.7, "trd": NaN, "batb": [[0, 1.1, 256.04], [1, 1.01, 7]], "batl": NaN}, {"timestamp": 1631527639696, "ltp": 1.34, "tv": 1153.7, "trd": NaN, "batb": NaN, "batl": [[1, 1.21, 0]]}, {"timestamp": 1631527715873, "ltp": 1.34, "tv": 1153.7, "trd": NaN, "batb": [[0, 1.01, 7], [1, 1.01, 0]], "batl": NaN}, {"timestamp": 1631527722295, "ltp": 1.34, "tv": 1153.7, "trd": NaN, "batb": [[0, 1.07, 256.04], [1, 1.01, 7]], "batl": NaN}, {"timestamp": 1631527723382, "ltp": 1.34, "tv": 1153.7, "trd": NaN, "batb": NaN, "batl": [[0, 1.14, 256.04], [1, 1.15, 256.04], [2, 1.2, 256.04]]}, {"timestamp": 1631527730977, "ltp": 1.34, "tv": 1153.7, "trd": NaN, "batb": NaN, "batl": [[1, 1.2, 256.04], [2, 1.2, 0]]}, {"timestamp": 1631527731702, "ltp": 1.34, "tv": 1153.7, "trd": NaN, "batb": NaN, "batl": [[1, 1.2, 0]]}, {"timestamp": 1631527741025, "ltp": 1.34, "tv": 1153.7, "trd": NaN, "batb": [[1, 1.05, 256.04], [2, 1.01, 7]], "batl": NaN}, {"timestamp": 1631527743423, "ltp": 1.34, "tv": 1153.7, "trd": NaN, "batb": [[2, 1.04, 256.04]], "batl": NaN}, {"timestamp": 1631527746321, "ltp": 1.34, "tv": 1153.7, "trd": NaN, "batb": [[1, 1.06, 256.04], [2, 1.05, 256.04]], "batl": NaN}, {"timestamp": 1631527748348, "ltp": 1.34, "tv": 1153.7, "trd": NaN, "batb": NaN, "batl": [[0, 1.12, 256.04], [1, 1.14, 256.04]]}, {"timestamp": 1631527750941, "ltp": 1.34, "tv": 1153.7, "trd": NaN, "batb": NaN, "batl": [[1, 1.14, 0]]}, {"timestamp": 1631527763849, "ltp": 1.34, "tv": 1153.7, "trd": NaN, "batb": [[0, 1.06, 256.04], [1, 1.05, 256.04], [2, 1.04, 256.04]], "batl": NaN}, {"timestamp": 1631528028293, "ltp": 1.34, "tv": 1153.7, "trd": NaN, "batb": [[0, 1.04, 256.04], [1, 1.03, 256.04], [2, 1.02, 256.04]], "batl": NaN}, {"timestamp": 1631528054366, "ltp": 1.34, "tv": 1153.7, "trd": NaN, "batb": [[0, 1.03, 256.04], [1, 1.02, 256.04], [2, 1.01, 263.04]], "batl": NaN}, {"timestamp": 1631528077879, "ltp": 1.34, "tv": 1153.7, "trd": NaN, "batb": [[0, 1.02, 256.04], [1, 1.01, 263.04], [2, 1.01, 0]], "batl": NaN}, {"timestamp": 1631528084293, "ltp": 1.34, "tv": 1153.7, "trd": NaN, "batb": NaN, "batl": [[0, 1.11, 256.04], [1, 1.12, 256.04]]}, {"timestamp": 1631528084772, "ltp": 1.34, "tv": 1153.7, "trd": NaN, "batb": NaN, "batl": [[0, 1.1, 256.04], [1, 1.11, 256.04], [2, 1.12, 256.04]]}, {"timestamp": 1631528145672, "ltp": 1.34, "tv": 1153.7, "trd": NaN, "batb": NaN, "batl": [[0, 1.11, 256.04], [1, 1.12, 256.04], [2, 1.12, 0]]}, {"timestamp": 1631528146973, "ltp": 1.34, "tv": 1153.7, "trd": NaN, "batb": NaN, "batl": [[0, 1.12, 256.04], [1, 1.12, 0]]}, {"timestamp": 1631528152960, "ltp": 1.34, "tv": 1153.7, "trd": NaN, "batb": [[0, 1.03, 256.04], [1, 1.02, 256.04], [2, 1.01, 263.04]], "batl": NaN}, {"timestamp": 1631528180492, "ltp": 1.34, "tv": 1153.7, "trd": NaN, "batb": [[0, 1.02, 256.04], [1, 1.01, 263.04], [2, 1.01, 0]], "batl": NaN}, {"timestamp": 1631528432844, "ltp": 1.34, "tv": 1153.7, "trd": NaN, "batb": [[0, 1.01, 263.04], [1, 1.01, 0]], "batl": NaN}, {"timestamp": 1631528433935, "ltp": 1.34, "tv": 1153.7, "trd": NaN, "batb": [[0, 1.01, 7]], "batl": NaN}, {"timestamp": 1631528440560, "ltp": 1.34, "tv": 1153.7, "trd": NaN, "batb": NaN, "batl": [[0, 1.09, 256.04], [1, 1.1, 256.04], [2, 1.12, 256.04]]}, {"timestamp": 1631528448364, "ltp": 1.34, "tv": 1153.7, "trd": NaN, "batb": NaN, "batl": [[1, 1.1, 0], [2, 1.12, 0]]}, {"timestamp": 1631528630406, "ltp": 1.01, "tv": 1167.71, "trd": [[1.01, 14.01]], "batb": NaN, "batl": [[0, 1.01, 1273.18]]}, {"timestamp": 1631528908603, "ltp": 1.01, "tv": 1167.71, "trd": NaN, "batb": NaN, "batl": [[0, 1.01, 1290.25]]}, {"timestamp": 1631529114187, "ltp": 1.01, "tv": 1467.79, "trd": [[1.01, 314.09]], "batb": NaN, "batl": [[0, 1.01, 1140.17]]}, {"timestamp": 1631529129617, "ltp": 1.01, "tv": 1867.89, "trd": [[1.01, 714.19]], "batb": NaN, "batl": [[0, 1.01, 940.07]]}, {"timestamp": 1631529516309, "ltp": 1.01, "tv": 1867.89, "trd": NaN, "batb": NaN, "batl": [[0, 1.01, 17.07]]}]}]}