{"info": {"id": "1.187548829", "eventId": "30894999", "eventName": "Match Odds", "marketType": "MATCH_ODDS", "openDate": 1631449886237, "name": "M Di Giuseppe v A Carreras", "numberOfActiveRunner": 2, "countryCode": "", "sport": "TENNIS", "venue": "", "volume": {"total": 234.53, "preMatch": 82.86, "inPlay": 151.67}, "winner": {"id": 9589287, "name": "A Carreras", "status": "WINNER", "position": 2}, "delay": 5}, "runners": [{"id": 9626703, "name": "M Di Giuseppe", "status": "LOSER", "position": 1, "inPlayOdds": 1.38, "inPlayTime": 1631451672852, "avgPrematch": 0, "closedOdds": 6.0, "maxPrematch": -100, "minPrematch": 1001, "maxInPlay": 6.0, "minInPlay": 1.38, "inPlayIndex": 0, "lengthOdds": 152, "lengthOddsPrematch": 0, "lengthOddsInPlay": 152, "tradedVolume": 131.67, "preMatchVolume": 80.0, "inPlayVolume": 51.67}, {"id": 9589287, "name": "A Carreras", "status": "WINNER", "position": 2, "inPlayOdds": 1.96, "inPlayTime": 1631453243755, "avgPrematch": 0, "closedOdds": 1.2, "maxPrematch": -100, "minPrematch": 1001, "maxInPlay": 1.96, "minInPlay": 1.2, "inPlayIndex": 0, "lengthOdds": 3, "lengthOddsPrematch": 0, "lengthOddsInPlay": 3, "tradedVolume": 102.86, "preMatchVolume": 2.86, "inPlayVolume": 100.0}], "marketUpdates": [{"timestamp": 1631432584138000000, "openDate": "2021-09-12T12:30:00.000Z", "status": "OPEN", "betDelay": 0, "inPlay": false, "complete": true}, {"timestamp": 1631449886237000000, "openDate": "2021-09-12T12:30:00.000Z", "status": "OPEN", "betDelay": 5, "inPlay": true, "complete": true}, {"timestamp": 1631451095507000000, "openDate": "2021-09-12T12:51:32.000Z", "status": "OPEN", "betDelay": 5, "inPlay": true, "complete": true}, {"timestamp": 1631455826678000000, "openDate": "2021-09-12T12:51:32.000Z", "status": "SUSPENDED", "betDelay": 5, "inPlay": true, "complete": true}, {"timestamp": 1631455832715000000, "openDate": "2021-09-12T12:51:32.000Z", "status": "CLOSED", "betDelay": 5, "inPlay": true, "complete": true}], "odds": [{"runnerId": 9626703, "odds": [{"timestamp": 1631451672852, "ltp": 1.38, "tv": 80.0, "trd": [[1.38, 80]], "batb": [[0, 1.38, 415.83]], "batl": NaN}, {"timestamp": 1631451673761, "ltp": 1.38, "tv": 80.0, "trd": NaN, "batb": [[0, 1.01, 12], [1, 1.01, 0]], "batl": NaN}, {"timestamp": 1631451679546, "ltp": 1.38, "tv": 80.0, "trd": NaN, "batb": [[0, 1.44, 443.37], [1, 1.01, 12]], "batl": NaN}, {"timestamp": 1631451702197, "ltp": 1.38, "tv": 80.0, "trd": NaN, "batb": [[0, 1.01, 12], [1, 1.01, 0]], "batl": NaN}, {"timestamp": 1631451708186, "ltp": 1.38, "tv": 80.0, "trd": NaN, "batb": [[0, 1.5, 397.22], [1, 1.01, 12]], "batl": [[0, 2.3, 338.84]]}, {"timestamp": 1631451730771, "ltp": 1.38, "tv": 80.0, "trd": NaN, "batb": [[0, 1.01, 12], [1, 1.01, 0]], "batl": NaN}, {"timestamp": 1631451736453, "ltp": 1.38, "tv": 80.0, "trd": NaN, "batb": [[0, 1.55, 391.99], [1, 1.01, 12]], "batl": NaN}, {"timestamp": 1631451998315, "ltp": 1.38, "tv": 80.0, "trd": NaN, "batb": [[0, 1.01, 12], [1, 1.01, 0]], "batl": NaN}, {"timestamp": 1631452003695, "ltp": 1.38, "tv": 80.0, "trd": NaN, "batb": [[0, 1.67, 383.76], [1, 1.01, 12]], "batl": [[0, 2.72, 265.79]]}, {"timestamp": 1631452021668, "ltp": 1.38, "tv": 80.0, "trd": NaN, "batb": [[0, 1.01, 12], [1, 1.01, 0]], "batl": NaN}, {"timestamp": 1631452027266, "ltp": 1.38, "tv": 80.0, "trd": NaN, "batb": [[0, 1.74, 379.62], [1, 1.01, 12]], "batl": NaN}, {"timestamp": 1631452078089, "ltp": 1.38, "tv": 80.0, "trd": NaN, "batb": [[0, 1.01, 12], [1, 1.01, 0]], "batl": NaN}, {"timestamp": 1631452146367, "ltp": 1.38, "tv": 80.0, "trd": NaN, "batb": [[0, 1.86, 375.99], [1, 1.01, 12]], "batl": [[0, 3.3, 211.99]]}, {"timestamp": 1631452159491, "ltp": 1.38, "tv": 80.0, "trd": NaN, "batb": [[0, 1.01, 12], [1, 1.01, 0]], "batl": NaN}, {"timestamp": 1631452165631, "ltp": 1.38, "tv": 80.0, "trd": NaN, "batb": [[0, 1.97, 373.9], [1, 1.01, 12]], "batl": [[0, 3.65, 188.46]]}, {"timestamp": 1631452242439, "ltp": 1.38, "tv": 80.0, "trd": NaN, "batb": NaN, "batl": [[0, 3.45, 199.41]]}, {"timestamp": 1631452249761, "ltp": 1.38, "tv": 80.0, "trd": NaN, "batb": [[0, 1.01, 12], [1, 1.01, 0]], "batl": NaN}, {"timestamp": 1631452255550, "ltp": 1.38, "tv": 80.0, "trd": NaN, "batb": [[0, 1.74, 379.62], [1, 1.01, 12]], "batl": [[0, 2.92, 243.87]]}, {"timestamp": 1631452259952, "ltp": 1.38, "tv": 80.0, "trd": NaN, "batb": [[0, 1.01, 12], [1, 1.01, 0]], "batl": NaN}, {"timestamp": 1631452265664, "ltp": 1.38, "tv": 80.0, "trd": NaN, "batb": [[0, 1.92, 373.24], [1, 1.01, 12]], "batl": [[0, 3.45, 199.41]]}, {"timestamp": 1631452278198, "ltp": 1.38, "tv": 80.0, "trd": NaN, "batb": [[0, 1.01, 12], [1, 1.01, 0]], "batl": NaN}, {"timestamp": 1631452283908, "ltp": 1.38, "tv": 80.0, "trd": NaN, "batb": [[0, 1.74, 379.62], [1, 1.01, 12]], "batl": [[0, 2.92, 243.87]]}, {"timestamp": 1631452304533, "ltp": 1.38, "tv": 80.0, "trd": NaN, "batb": [[0, 1.01, 12], [1, 1.01, 0]], "batl": NaN}, {"timestamp": 1631452477305, "ltp": 1.38, "tv": 80.0, "trd": NaN, "batb": [[0, 1.58, 388.65], [1, 1.01, 12]], "batl": [[0, 2.5, 301.24]]}, {"timestamp": 1631452514116, "ltp": 1.38, "tv": 80.0, "trd": NaN, "batb": [[0, 1.01, 12], [1, 1.01, 0]], "batl": NaN}, {"timestamp": 1631452520435, "ltp": 1.38, "tv": 80.0, "trd": NaN, "batb": [[0, 1.62, 388.35], [1, 1.01, 12]], "batl": NaN}, {"timestamp": 1631452574802, "ltp": 1.38, "tv": 80.0, "trd": NaN, "batb": [[0, 1.01, 12], [1, 1.01, 0]], "batl": NaN}, {"timestamp": 1631452580585, "ltp": 1.38, "tv": 80.0, "trd": NaN, "batb": [[0, 1.67, 383.76], [1, 1.01, 12]], "batl": NaN}, {"timestamp": 1631452649707, "ltp": 1.38, "tv": 80.0, "trd": NaN, "batb": [[0, 1.01, 12], [1, 1.01, 0]], "batl": NaN}, {"timestamp": 1631452655448, "ltp": 1.38, "tv": 80.0, "trd": NaN, "batb": [[0, 1.46, 404.9], [1, 1.01, 12]], "batl": [[0, 2.22, 359.34]]}, {"timestamp": 1631452680063, "ltp": 1.38, "tv": 80.0, "trd": NaN, "batb": [[0, 1.01, 12], [1, 1.01, 0]], "batl": NaN}, {"timestamp": 1631452685953, "ltp": 1.38, "tv": 80.0, "trd": NaN, "batb": NaN, "batl": [[0, 2.5, 301.24]]}, {"timestamp": 1631452686051, "ltp": 1.38, "tv": 80.0, "trd": NaN, "batb": [[0, 1.58, 388.65], [1, 1.01, 12]], "batl": NaN}, {"timestamp": 1631452706400, "ltp": 1.38, "tv": 80.0, "trd": NaN, "batb": [[0, 1.01, 12], [1, 1.01, 0]], "batl": NaN}, {"timestamp": 1631452712215, "ltp": 1.38, "tv": 80.0, "trd": NaN, "batb": [[0, 1.46, 404.9], [1, 1.01, 12]], "batl": [[0, 2.22, 359.34]]}, {"timestamp": 1631452733752, "ltp": 1.38, "tv": 80.0, "trd": NaN, "batb": [[0, 1.01, 12], [1, 1.01, 0]], "batl": NaN}, {"timestamp": 1631452739365, "ltp": 1.38, "tv": 80.0, "trd": NaN, "batb": [[0, 1.58, 388.65], [1, 1.01, 12]], "batl": [[0, 2.5, 301.24]]}, {"timestamp": 1631452754013, "ltp": 1.38, "tv": 80.0, "trd": NaN, "batb": [[0, 1.01, 12], [1, 1.01, 0]], "batl": NaN}, {"timestamp": 1631452759598, "ltp": 1.38, "tv": 80.0, "trd": NaN, "batb": [[0, 1.46, 404.9], [1, 1.01, 12]], "batl": [[0, 2.22, 359.34]]}, {"timestamp": 1631452782435, "ltp": 1.38, "tv": 80.0, "trd": NaN, "batb": [[0, 1.01, 12], [1, 1.01, 0]], "batl": NaN}, {"timestamp": 1631452788945, "ltp": 1.38, "tv": 80.0, "trd": NaN, "batb": [[0, 1.38, 415.73], [1, 1.01, 12]], "batl": [[0, 2.04, 416.53]]}, {"timestamp": 1631452901835, "ltp": 1.38, "tv": 80.0, "trd": NaN, "batb": [[0, 1.01, 12], [1, 1.01, 0]], "batl": NaN}, {"timestamp": 1631452907786, "ltp": 1.38, "tv": 80.0, "trd": NaN, "batb": [[0, 1.44, 405.03], [1, 1.01, 12]], "batl": NaN}, {"timestamp": 1631452928136, "ltp": 1.38, "tv": 80.0, "trd": NaN, "batb": [[0, 1.01, 12], [1, 1.01, 0]], "batl": NaN}, {"timestamp": 1631452933935, "ltp": 1.38, "tv": 80.0, "trd": NaN, "batb": [[0, 1.38, 415.73], [1, 1.01, 12]], "batl": NaN}, {"timestamp": 1631452950368, "ltp": 1.38, "tv": 80.0, "trd": NaN, "batb": [[0, 1.01, 12], [1, 1.01, 0]], "batl": NaN}, {"timestamp": 1631452955869, "ltp": 1.38, "tv": 80.0, "trd": NaN, "batb": [[0, 1.46, 404.9], [1, 1.01, 12]], "batl": NaN}, {"timestamp": 1631452974624, "ltp": 1.38, "tv": 80.0, "trd": NaN, "batb": [[0, 1.01, 12], [1, 1.01, 0]], "batl": NaN}, {"timestamp": 1631452980433, "ltp": 1.38, "tv": 80.0, "trd": NaN, "batb": [[0, 1.38, 415.73], [1, 1.01, 12]], "batl": NaN}, {"timestamp": 1631452994836, "ltp": 1.38, "tv": 80.0, "trd": NaN, "batb": [[0, 1.01, 12], [1, 1.01, 0]], "batl": NaN}, {"timestamp": 1631453000553, "ltp": 1.38, "tv": 80.0, "trd": NaN, "batb": [[0, 1.46, 404.9], [1, 1.01, 12]], "batl": NaN}, {"timestamp": 1631453025179, "ltp": 1.38, "tv": 80.0, "trd": NaN, "batb": [[0, 1.01, 12], [1, 1.01, 0]], "batl": NaN}, {"timestamp": 1631453030763, "ltp": 1.38, "tv": 80.0, "trd": NaN, "batb": [[0, 1.38, 415.73], [1, 1.01, 12]], "batl": NaN}, {"timestamp": 1631453059538, "ltp": 1.38, "tv": 80.0, "trd": NaN, "batb": [[0, 1.01, 12], [1, 1.01, 0]], "batl": NaN}, {"timestamp": 1631453065253, "ltp": 1.38, "tv": 80.0, "trd": NaN, "batb": [[0, 1.46, 404.9], [1, 1.01, 12]], "batl": NaN}, {"timestamp": 1631453096083, "ltp": 1.46, "tv": 108.92, "trd": [[1.46, 28.92]], "batb": [[0, 1.46, 390.44]], "batl": NaN}, {"timestamp": 1631453098092, "ltp": 1.46, "tv": 108.92, "trd": NaN, "batb": [[0, 1.01, 12], [1, 1.01, 0]], "batl": NaN}, {"timestamp": 1631453103796, "ltp": 1.46, "tv": 108.92, "trd": NaN, "batb": [[0, 1.5, 383.02], [1, 1.01, 12]], "batl": [[0, 2.3, 348.03]]}, {"timestamp": 1631453119397, "ltp": 1.46, "tv": 108.92, "trd": NaN, "batb": [[0, 1.01, 12], [1, 1.01, 0]], "batl": NaN}, {"timestamp": 1631453124935, "ltp": 1.46, "tv": 108.92, "trd": NaN, "batb": [[0, 1.58, 375.22], [1, 1.01, 12]], "batl": NaN}, {"timestamp": 1631453147642, "ltp": 1.46, "tv": 108.92, "trd": NaN, "batb": [[0, 1.01, 12], [1, 1.01, 0]], "batl": NaN}, {"timestamp": 1631453153151, "ltp": 1.46, "tv": 108.92, "trd": NaN, "batb": [[0, 1.67, 371.07], [1, 1.01, 12]], "batl": [[0, 2.72, 273.54]]}, {"timestamp": 1631453175001, "ltp": 1.46, "tv": 108.92, "trd": NaN, "batb": [[0, 1.01, 12], [1, 1.01, 0]], "batl": NaN}, {"timestamp": 1631453181477, "ltp": 1.46, "tv": 108.92, "trd": NaN, "batb": [[0, 1.77, 366.24], [1, 1.01, 12]], "batl": NaN}, {"timestamp": 1631453192279, "ltp": 1.46, "tv": 108.92, "trd": NaN, "batb": [[0, 1.01, 12], [1, 1.01, 0]], "batl": NaN}, {"timestamp": 1631453198607, "ltp": 1.46, "tv": 108.92, "trd": NaN, "batb": [[0, 1.86, 364.69], [1, 1.01, 12]], "batl": [[0, 3.3, 218.46]]}, {"timestamp": 1631453223657, "ltp": 1.46, "tv": 108.92, "trd": NaN, "batb": [[0, 1.01, 12], [1, 1.01, 0]], "batl": NaN}, {"timestamp": 1631453243755, "ltp": 2.04, "tv": 111.67, "trd": [[2.04, 2.76]], "batb": NaN, "batl": NaN}, {"timestamp": 1631453361225, "ltp": 2.04, "tv": 111.67, "trd": NaN, "batb": [[0, 1.82, 366.34], [1, 1.01, 12]], "batl": [[0, 3.15, 227.96]]}, {"timestamp": 1631453385262, "ltp": 2.04, "tv": 111.67, "trd": NaN, "batb": NaN, "batl": [[0, 2.82, 262.21]]}, {"timestamp": 1631453413500, "ltp": 2.04, "tv": 111.67, "trd": NaN, "batb": NaN, "batl": [[0, 3.15, 227.96]]}, {"timestamp": 1631453447348, "ltp": 2.04, "tv": 111.67, "trd": NaN, "batb": [[0, 1.01, 12], [1, 1.01, 0]], "batl": NaN}, {"timestamp": 1631453452872, "ltp": 2.04, "tv": 111.67, "trd": NaN, "batb": [[0, 1.97, 363.24], [1, 1.01, 12]], "batl": [[0, 3.65, 194.29]]}, {"timestamp": 1631453487730, "ltp": 2.04, "tv": 111.67, "trd": NaN, "batb": [[0, 1.01, 12], [1, 1.01, 0]], "batl": NaN}, {"timestamp": 1631453493256, "ltp": 2.04, "tv": 111.67, "trd": NaN, "batb": [[0, 2.22, 357.45], [1, 1.01, 12]], "batl": [[0, 4.6, 155.23]]}, {"timestamp": 1631453538408, "ltp": 2.04, "tv": 111.67, "trd": NaN, "batb": [[0, 1.01, 12], [1, 1.01, 0]], "batl": NaN}, {"timestamp": 1631453544510, "ltp": 2.04, "tv": 111.67, "trd": NaN, "batb": [[0, 2.52, 358.54], [1, 1.01, 12]], "batl": [[0, 6, 120.71]]}, {"timestamp": 1631453612787, "ltp": 6.0, "tv": 131.67, "trd": [[6, 20]], "batb": NaN, "batl": [[0, 6, 100.71]]}, {"timestamp": 1631453683864, "ltp": 6.0, "tv": 131.67, "trd": NaN, "batb": NaN, "batl": [[0, 5.5, 108.98]]}, {"timestamp": 1631453727758, "ltp": 6.0, "tv": 131.67, "trd": NaN, "batb": [[0, 1.01, 12], [1, 1.01, 0]], "batl": NaN}, {"timestamp": 1631453733743, "ltp": 6.0, "tv": 131.67, "trd": NaN, "batb": [[0, 2.72, 401.45], [1, 1.01, 12]], "batl": [[0, 7.2, 87.62]]}, {"timestamp": 1631453763872, "ltp": 6.0, "tv": 131.67, "trd": NaN, "batb": NaN, "batl": [[0, 8.2, 81.39]]}, {"timestamp": 1631453797216, "ltp": 6.0, "tv": 131.67, "trd": NaN, "batb": NaN, "batl": [[0, 7.2, 87.62]]}, {"timestamp": 1631453821382, "ltp": 6.0, "tv": 131.67, "trd": NaN, "batb": NaN, "batl": [[0, 6, 100.65]]}, {"timestamp": 1631453843587, "ltp": 6.0, "tv": 131.67, "trd": NaN, "batb": NaN, "batl": [[0, 5.3, 112.48]]}, {"timestamp": 1631453868325, "ltp": 6.0, "tv": 131.67, "trd": NaN, "batb": [[0, 1.01, 12], [1, 1.01, 0]], "batl": NaN}, {"timestamp": 1631453873763, "ltp": 6.0, "tv": 131.67, "trd": NaN, "batb": [[0, 2.22, 411.12], [1, 1.01, 12]], "batl": [[0, 4.6, 128.76]]}, {"timestamp": 1631453877439, "ltp": 6.0, "tv": 131.67, "trd": NaN, "batb": [[0, 1.01, 12], [1, 1.01, 0]], "batl": NaN}, {"timestamp": 1631454018240, "ltp": 6.0, "tv": 131.67, "trd": NaN, "batb": NaN, "batl": [[0, 3.9, 149.87]]}, {"timestamp": 1631454030047, "ltp": 6.0, "tv": 131.67, "trd": NaN, "batb": NaN, "batl": [[0, 4.6, 128.76]]}, {"timestamp": 1631454218630, "ltp": 6.0, "tv": 131.67, "trd": NaN, "batb": [[0, 2.84, 397.91], [1, 1.01, 12]], "batl": [[0, 8.2, 81.39]]}, {"timestamp": 1631454239879, "ltp": 6.0, "tv": 131.67, "trd": NaN, "batb": NaN, "batl": [[0, 9.4, 74.54]]}, {"timestamp": 1631454369146, "ltp": 6.0, "tv": 131.67, "trd": NaN, "batb": NaN, "batl": [[0, 8.2, 81.39]]}, {"timestamp": 1631454430612, "ltp": 6.0, "tv": 131.67, "trd": NaN, "batb": NaN, "batl": [[0, 7.2, 87.62]]}, {"timestamp": 1631454451946, "ltp": 6.0, "tv": 131.67, "trd": NaN, "batb": NaN, "batl": [[0, 8.2, 81.39]]}, {"timestamp": 1631454478984, "ltp": 6.0, "tv": 131.67, "trd": NaN, "batb": NaN, "batl": [[0, 9.4, 74.54]]}, {"timestamp": 1631454510310, "ltp": 6.0, "tv": 131.67, "trd": NaN, "batb": NaN, "batl": [[0, 7.2, 87.62]]}, {"timestamp": 1631454570860, "ltp": 6.0, "tv": 131.67, "trd": NaN, "batb": NaN, "batl": [[0, 9.4, 74.54]]}, {"timestamp": 1631454601221, "ltp": 6.0, "tv": 131.67, "trd": NaN, "batb": NaN, "batl": [[0, 7.2, 87.62]]}, {"timestamp": 1631454612632, "ltp": 6.0, "tv": 131.67, "trd": NaN, "batb": NaN, "batl": [[0, 6, 100.65]]}, {"timestamp": 1631454650571, "ltp": 6.0, "tv": 131.67, "trd": NaN, "batb": NaN, "batl": [[0, 7.2, 87.62]]}, {"timestamp": 1631454668193, "ltp": 6.0, "tv": 131.67, "trd": NaN, "batb": NaN, "batl": [[0, 6, 100.65]]}, {"timestamp": 1631454693639, "ltp": 6.0, "tv": 131.67, "trd": NaN, "batb": [[0, 1.01, 12], [1, 1.01, 0]], "batl": NaN}, {"timestamp": 1631454699442, "ltp": 6.0, "tv": 131.67, "trd": NaN, "batb": [[0, 2.38, 407.67], [1, 1.01, 12]], "batl": [[0, 5.3, 112.48]]}, {"timestamp": 1631454719963, "ltp": 6.0, "tv": 131.67, "trd": NaN, "batb": [[0, 1.01, 12], [1, 1.01, 0]], "batl": NaN}, {"timestamp": 1631454726851, "ltp": 6.0, "tv": 131.67, "trd": NaN, "batb": [[0, 2.52, 405.91], [1, 1.01, 12]], "batl": [[0, 6, 100.65]]}, {"timestamp": 1631454739326, "ltp": 6.0, "tv": 131.67, "trd": NaN, "batb": [[0, 1.01, 12], [1, 1.01, 0]], "batl": NaN}, {"timestamp": 1631454745701, "ltp": 6.0, "tv": 131.67, "trd": NaN, "batb": [[0, 2.72, 401.45], [1, 1.01, 12]], "batl": [[0, 7.2, 87.62]]}, {"timestamp": 1631454780724, "ltp": 6.0, "tv": 131.67, "trd": NaN, "batb": NaN, "batl": [[0, 6, 100.65]]}, {"timestamp": 1631454811317, "ltp": 6.0, "tv": 131.67, "trd": NaN, "batb": NaN, "batl": [[0, 7.2, 87.62]]}, {"timestamp": 1631454847670, "ltp": 6.0, "tv": 131.67, "trd": NaN, "batb": [[0, 1.01, 12], [1, 1.01, 0]], "batl": NaN}, {"timestamp": 1631454853658, "ltp": 6.0, "tv": 131.67, "trd": NaN, "batb": [[0, 2.98, 396.1], [1, 1.01, 12]], "batl": [[0, 9.4, 74.54]]}, {"timestamp": 1631454968812, "ltp": 6.0, "tv": 131.67, "trd": NaN, "batb": NaN, "batl": [[0, 12, 65.12]]}, {"timestamp": 1631454985117, "ltp": 6.0, "tv": 131.67, "trd": NaN, "batb": [[0, 1.01, 12], [1, 1.01, 0]], "batl": NaN}, {"timestamp": 1631454990954, "ltp": 6.0, "tv": 131.67, "trd": NaN, "batb": [[0, 3.3, 393.42], [1, 1.01, 12]], "batl": NaN}, {"timestamp": 1631454995938, "ltp": 6.0, "tv": 131.67, "trd": NaN, "batb": NaN, "batl": [[0, 15.5, 57.69]]}, {"timestamp": 1631455028149, "ltp": 6.0, "tv": 131.67, "trd": NaN, "batb": NaN, "batl": [[0, 21, 52.1]]}, {"timestamp": 1631455051387, "ltp": 6.0, "tv": 131.67, "trd": NaN, "batb": NaN, "batl": [[0, 18, 54.57]]}, {"timestamp": 1631455063198, "ltp": 6.0, "tv": 131.67, "trd": NaN, "batb": [[0, 1.01, 12], [1, 1.01, 0]], "batl": NaN}, {"timestamp": 1631455069523, "ltp": 6.0, "tv": 131.67, "trd": NaN, "batb": [[0, 3.7, 389.95], [1, 1.01, 12]], "batl": [[0, 23, 50.07]]}, {"timestamp": 1631455129785, "ltp": 6.0, "tv": 131.67, "trd": NaN, "batb": NaN, "batl": [[0, 18, 54.57]]}, {"timestamp": 1631455137903, "ltp": 6.0, "tv": 131.67, "trd": NaN, "batb": NaN, "batl": [[0, 13.5, 61.74]]}, {"timestamp": 1631455159290, "ltp": 6.0, "tv": 131.67, "trd": NaN, "batb": NaN, "batl": [[0, 12, 65.12]]}, {"timestamp": 1631455200709, "ltp": 6.0, "tv": 131.67, "trd": NaN, "batb": NaN, "batl": [[0, 10.5, 69.28]]}, {"timestamp": 1631455309502, "ltp": 6.0, "tv": 131.67, "trd": NaN, "batb": NaN, "batl": [[0, 12, 65.12]]}, {"timestamp": 1631455325717, "ltp": 6.0, "tv": 131.67, "trd": NaN, "batb": NaN, "batl": [[0, 15.5, 57.69]]}, {"timestamp": 1631455349030, "ltp": 6.0, "tv": 131.67, "trd": NaN, "batb": NaN, "batl": [[0, 21, 52.1]]}, {"timestamp": 1631455373163, "ltp": 6.0, "tv": 131.67, "trd": NaN, "batb": NaN, "batl": [[0, 34, 45.41]]}, {"timestamp": 1631455408412, "ltp": 6.0, "tv": 131.67, "trd": NaN, "batb": NaN, "batl": [[0, 46, 42.6]]}, {"timestamp": 1631455441320, "ltp": 6.0, "tv": 131.67, "trd": NaN, "batb": [[0, 1.01, 12], [1, 1.01, 0]], "batl": NaN}, {"timestamp": 1631455446856, "ltp": 6.0, "tv": 131.67, "trd": NaN, "batb": NaN, "batl": [[0, 85, 39.17]]}, {"timestamp": 1631455446990, "ltp": 6.0, "tv": 131.67, "trd": NaN, "batb": [[0, 4.2, 388.81], [1, 1.01, 12]], "batl": NaN}, {"timestamp": 1631455455462, "ltp": 6.0, "tv": 131.67, "trd": NaN, "batb": [[0, 1.01, 12], [1, 1.01, 0]], "batl": NaN}, {"timestamp": 1631455472977, "ltp": 6.0, "tv": 131.67, "trd": NaN, "batb": [[0, 4, 392.22], [1, 1.01, 12]], "batl": [[0, 46, 42.6]]}, {"timestamp": 1631455482797, "ltp": 6.0, "tv": 131.67, "trd": NaN, "batb": [[0, 1.01, 12], [1, 1.01, 0]], "batl": NaN}, {"timestamp": 1631455494159, "ltp": 6.0, "tv": 131.67, "trd": NaN, "batb": [[0, 3.75, 392.14], [1, 1.01, 12]], "batl": [[0, 26, 48.39]]}, {"timestamp": 1631455522447, "ltp": 6.0, "tv": 131.67, "trd": NaN, "batb": NaN, "batl": [[0, 46, 42.6]]}, {"timestamp": 1631455529246, "ltp": 6.0, "tv": 131.67, "trd": NaN, "batb": [[0, 1.01, 12], [1, 1.01, 0]], "batl": NaN}, {"timestamp": 1631455546579, "ltp": 6.0, "tv": 131.67, "trd": NaN, "batb": [[0, 3.7, 389.95], [1, 1.01, 12]], "batl": [[0, 23, 50.07]]}, {"timestamp": 1631455604847, "ltp": 6.0, "tv": 131.67, "trd": NaN, "batb": NaN, "batl": [[0, 46, 42.6]]}, {"timestamp": 1631455612217, "ltp": 6.0, "tv": 131.67, "trd": NaN, "batb": [[0, 1.01, 12], [1, 1.01, 0]], "batl": NaN}, {"timestamp": 1631455622295, "ltp": 6.0, "tv": 131.67, "trd": NaN, "batb": [[0, 4.4, 384.58], [1, 1.01, 12]], "batl": [[0, 340, 36.27]]}, {"timestamp": 1631455638471, "ltp": 6.0, "tv": 131.67, "trd": NaN, "batb": [[0, 1.01, 12], [1, 1.01, 0]], "batl": NaN}, {"timestamp": 1631455650223, "ltp": 6.0, "tv": 131.67, "trd": NaN, "batb": [[0, 4, 392.22], [1, 1.01, 12]], "batl": [[0, 46, 42.6]]}, {"timestamp": 1631455654630, "ltp": 6.0, "tv": 131.67, "trd": NaN, "batb": [[0, 1.01, 12], [1, 1.01, 0]], "batl": NaN}, {"timestamp": 1631455666558, "ltp": 6.0, "tv": 131.67, "trd": NaN, "batb": [[0, 4.4, 384.58], [1, 1.01, 12]], "batl": [[0, 340, 36.27]]}, {"timestamp": 1631455676851, "ltp": 6.0, "tv": 131.67, "trd": NaN, "batb": [[0, 1.01, 12], [1, 1.01, 0]], "batl": NaN}, {"timestamp": 1631455690781, "ltp": 6.0, "tv": 131.67, "trd": NaN, "batb": [[0, 4, 392.22], [1, 1.01, 12]], "batl": [[0, 46, 42.6]]}, {"timestamp": 1631455698194, "ltp": 6.0, "tv": 131.67, "trd": NaN, "batb": [[0, 1.01, 12], [1, 1.01, 0]], "batl": NaN}, {"timestamp": 1631455715902, "ltp": 6.0, "tv": 131.67, "trd": NaN, "batb": NaN, "batl": [[0, 340, 36.27]]}, {"timestamp": 1631455716004, "ltp": 6.0, "tv": 131.67, "trd": NaN, "batb": [[0, 4.4, 384.58], [1, 1.01, 12]], "batl": NaN}, {"timestamp": 1631455733515, "ltp": 6.0, "tv": 131.67, "trd": NaN, "batb": [[0, 1.01, 12], [1, 1.01, 0]], "batl": NaN}]}, {"runnerId": 9589287, "odds": [{"timestamp": 1631453243755, "ltp": 1.96, "tv": 2.86, "trd": [[1.96, 2.87]], "batb": NaN, "batl": [[0, 1.96, 4.26]]}, {"timestamp": 1631453612787, "ltp": 1.2, "tv": 102.86, "trd": [[1.2, 100]], "batb": NaN, "batl": NaN}, {"timestamp": 1631453739059, "ltp": 1.2, "tv": 102.86, "trd": NaN, "batb": NaN, "batl": [[0, 11.5, 8.68]]}]}]}