{"info": {"id": "1.187560634", "eventId": "30896276", "eventName": "Match Odds", "marketType": "MATCH_ODDS", "openDate": 1631545680116, "name": "Brouwer v Ri Hijikata", "numberOfActiveRunner": 2, "countryCode": "", "sport": "TENNIS", "venue": "", "volume": {"total": 18656.67, "preMatch": 230.13, "inPlay": 18426.54}, "winner": {"id": 12343905, "name": "Rinky Hijikata", "status": "WINNER", "position": 2}, "delay": 3}, "runners": [{"id": 9629296, "name": "Gijs Brouwer", "status": "LOSER", "position": 1, "inPlayOdds": 1.96, "inPlayTime": 1631545680116, "avgPrematch": 1.89, "closedOdds": 15.0, "maxPrematch": 2.2, "minPrematch": 1.83, "maxInPlay": 15.0, "minInPlay": 1.58, "inPlayIndex": 36, "lengthOdds": 1363, "lengthOddsPrematch": 36, "lengthOddsInPlay": 1327, "tradedVolume": 4731.2, "preMatchVolume": 111.9, "inPlayVolume": 4619.3}, {"id": 12343905, "name": "Rinky Hijikata", "status": "WINNER", "position": 2, "inPlayOdds": 1.96, "inPlayTime": 1631545680116, "avgPrematch": 1.91, "closedOdds": 1.06, "maxPrematch": 2.08, "minPrematch": 1.81, "maxInPlay": 2.72, "minInPlay": 1.06, "inPlayIndex": 36, "lengthOdds": 1676, "lengthOddsPrematch": 36, "lengthOddsInPlay": 1640, "tradedVolume": 13925.47, "preMatchVolume": 118.23, "inPlayVolume": 13807.24}], "marketUpdates": [{"timestamp": 1631469486062000000, "openDate": "2021-09-13T15:00:00.000Z", "status": "OPEN", "betDelay": 0, "inPlay": false, "complete": true}, {"timestamp": 1631545024154000000, "openDate": "2021-09-13T14:55:00.000Z", "status": "OPEN", "betDelay": 0, "inPlay": false, "complete": true}, {"timestamp": 1631545680116000000, "openDate": "2021-09-13T14:55:00.000Z", "status": "OPEN", "betDelay": 3, "inPlay": true, "complete": true}, {"timestamp": 1631551555125000000, "openDate": "2021-09-13T14:55:00.000Z", "status": "SUSPENDED", "betDelay": 3, "inPlay": true, "complete": true}, {"timestamp": 1631551603081000000, "openDate": "2021-09-13T14:55:00.000Z", "status": "CLOSED", "betDelay": 3, "inPlay": true, "complete": true}], "odds": [{"runnerId": 9629296, "odds": [{"timestamp": 1631535795198, "ltp": 2.2, "tv": 50.0, "trd": [[2.2, 50]], "batb": NaN, "batl": [[0, 2.56, 2.66], [1, 3.5, 42.59], [2, 46, 29.02]]}, {"timestamp": 1631536019957, "ltp": 2.2, "tv": 50.0, "trd": NaN, "batb": NaN, "batl": [[0, 2.54, 2.72], [1, 2.56, 2.66], [2, 3.5, 42.59]]}, {"timestamp": 1631536618893, "ltp": 1.92, "tv": 55.38, "trd": [[1.92, 4.83], [1.94, 0.56]], "batb": NaN, "batl": [[0, 2.56, 2.66], [1, 3.5, 42.59], [2, 46, 29.02]]}, {"timestamp": 1631536742507, "ltp": 1.92, "tv": 55.38, "trd": NaN, "batb": NaN, "batl": [[0, 2.48, 2.77], [1, 2.56, 2.66], [2, 3.5, 42.59]]}, {"timestamp": 1631536866668, "ltp": 1.92, "tv": 55.38, "trd": NaN, "batb": NaN, "batl": [[0, 2.56, 2.66], [1, 3.5, 42.59], [2, 46, 29.02]]}, {"timestamp": 1631537125798, "ltp": 1.92, "tv": 55.38, "trd": NaN, "batb": NaN, "batl": [[0, 2.52, 2.68], [1, 2.56, 2.66], [2, 3.5, 42.59]]}, {"timestamp": 1631537761607, "ltp": 1.92, "tv": 55.38, "trd": NaN, "batb": [[2, 1.45, 43.57]], "batl": NaN}, {"timestamp": 1631538001248, "ltp": 1.92, "tv": 55.38, "trd": NaN, "batb": [[1, 1.83, 50.32]], "batl": NaN}, {"timestamp": 1631538640698, "ltp": 1.92, "tv": 55.38, "trd": [[2.2, 50]], "batb": [[2, 1.45, 43.54]], "batl": [[0, 2.56, 2.66], [1, 3.5, 42.58], [2, 46, 29]]}, {"timestamp": 1631538909941, "ltp": 1.92, "tv": 55.38, "trd": NaN, "batb": NaN, "batl": [[0, 2.46, 2.65], [1, 2.56, 2.66], [2, 3.5, 42.58]]}, {"timestamp": 1631539224750, "ltp": 1.92, "tv": 55.38, "trd": NaN, "batb": NaN, "batl": [[2, 46, 29]]}, {"timestamp": 1631539678394, "ltp": 1.83, "tv": 69.2, "trd": [[1.83, 3.34], [1.91, 10.48]], "batb": [[0, 1.83, 48.65], [1, 1.45, 43.54], [2, 1.42, 34.92]], "batl": NaN}, {"timestamp": 1631539682984, "ltp": 1.83, "tv": 69.2, "trd": NaN, "batb": [[0, 1.83, 50.32]], "batl": NaN}, {"timestamp": 1631540164693, "ltp": 1.83, "tv": 69.2, "trd": NaN, "batb": [[0, 1.83, 50.84]], "batl": NaN}, {"timestamp": 1631541601126, "ltp": 1.83, "tv": 69.2, "trd": NaN, "batb": [[0, 1.84, 15.73], [1, 1.83, 50.32], [2, 1.45, 43.54]], "batl": NaN}, {"timestamp": 1631543584093, "ltp": 1.83, "tv": 69.2, "trd": NaN, "batb": [[2, 1.8, 3.61]], "batl": NaN}, {"timestamp": 1631544635642, "ltp": 1.83, "tv": 69.2, "trd": NaN, "batb": [[0, 1.91, 45.89], [1, 1.84, 15.73]], "batl": NaN}, {"timestamp": 1631544636325, "ltp": 1.83, "tv": 69.2, "trd": NaN, "batb": [[0, 1.92, 13.88], [1, 1.91, 45.89], [2, 1.84, 15.73]], "batl": NaN}, {"timestamp": 1631544821081, "ltp": 1.83, "tv": 69.2, "trd": NaN, "batb": [[0, 1.92, 14.41], [2, 1.84, 15.21]], "batl": NaN}, {"timestamp": 1631545024154, "ltp": 1.83, "tv": 69.2, "trd": NaN, "batb": NaN, "batl": [[0, 2.56, 2.66], [1, 46, 29], [2, 990, 2.2]]}, {"timestamp": 1631545026994, "ltp": 1.83, "tv": 69.2, "trd": NaN, "batb": NaN, "batl": [[0, 2.46, 4.32], [1, 2.56, 2.66], [2, 46, 29]]}, {"timestamp": 1631545031652, "ltp": 1.83, "tv": 69.2, "trd": NaN, "batb": [[0, 1.96, 13.31], [1, 1.95, 48.36], [2, 1.92, 14.41]], "batl": NaN}, {"timestamp": 1631545097127, "ltp": 1.83, "tv": 69.2, "trd": NaN, "batb": [[0, 2, 41.76], [1, 1.96, 13.31], [2, 1.95, 48.36]], "batl": NaN}, {"timestamp": 1631545200990, "ltp": 1.83, "tv": 69.2, "trd": NaN, "batb": [[0, 2, 42.28]], "batl": NaN}, {"timestamp": 1631545201890, "ltp": 1.83, "tv": 69.2, "trd": NaN, "batb": [[0, 2, 55.06]], "batl": NaN}, {"timestamp": 1631545208684, "ltp": 1.83, "tv": 69.25, "trd": [[1.83, 3.35], [1.91, 10.49], [1.92, 4.83], [2.2, 50.03]], "batb": [[0, 2, 55.07], [1, 1.96, 13.33], [2, 1.95, 48.48]], "batl": [[2, 46, 28.97]]}, {"timestamp": 1631545214369, "ltp": 1.83, "tv": 69.25, "trd": NaN, "batb": [[0, 2, 13.31]], "batl": NaN}, {"timestamp": 1631545214889, "ltp": 1.83, "tv": 69.25, "trd": NaN, "batb": [[0, 1.96, 13.85], [1, 1.95, 48.48], [2, 1.92, 13.9]], "batl": NaN}, {"timestamp": 1631545378198, "ltp": 1.83, "tv": 69.25, "trd": NaN, "batb": [[0, 2.08, 11.84], [1, 1.96, 13.85], [2, 1.95, 48.48]], "batl": [[0, 2.56, 2.66], [1, 46, 28.97], [2, 990, 2.2]]}, {"timestamp": 1631545408671, "ltp": 1.83, "tv": 69.25, "trd": NaN, "batb": [[1, 1.96, 62]], "batl": NaN}, {"timestamp": 1631545409038, "ltp": 1.83, "tv": 69.25, "trd": NaN, "batb": [[0, 1.96, 62], [1, 1.92, 13.9], [2, 1.83, 50.32]], "batl": [[0, 2.46, 4.24], [1, 2.56, 2.66], [2, 46, 28.97]]}, {"timestamp": 1631545515679, "ltp": 1.83, "tv": 69.25, "trd": NaN, "batb": [[0, 1.96, 61.47]], "batl": NaN}, {"timestamp": 1631545630661, "ltp": 1.96, "tv": 111.9, "trd": [[1.96, 41.97], [2.04, 0.67]], "batb": [[0, 1.96, 40.49]], "batl": NaN}, {"timestamp": 1631545631444, "ltp": 1.96, "tv": 111.9, "trd": NaN, "batb": [[0, 1.97, 13.18], [1, 1.96, 40.49], [2, 1.92, 13.9]], "batl": NaN}, {"timestamp": 1631545670277, "ltp": 1.96, "tv": 111.9, "trd": NaN, "batb": [[0, 1.96, 53.81], [1, 1.92, 13.9], [2, 1.9, 46.4]], "batl": NaN}, {"timestamp": 1631545679581, "ltp": 1.96, "tv": 111.9, "trd": NaN, "batb": [[0, 1.96, 13.33]], "batl": NaN}, {"timestamp": 1631545680116, "ltp": 1.96, "tv": 111.9, "trd": NaN, "batb": [[0, 1.25, 28.88], [1, 1.01, 577.96], [2, 1.9, 0]], "batl": NaN}, {"timestamp": 1631545684597, "ltp": 1.96, "tv": 111.9, "trd": NaN, "batb": NaN, "batl": [[0, 2.12, 240.82]]}, {"timestamp": 1631545700513, "ltp": 1.96, "tv": 111.9, "trd": NaN, "batb": NaN, "batl": [[0, 1.89, 13.79], [1, 1.92, 129.07], [2, 2.06, 6.96]]}, {"timestamp": 1631545700722, "ltp": 1.96, "tv": 111.9, "trd": NaN, "batb": NaN, "batl": [[2, 2.06, 0]]}, {"timestamp": 1631545701928, "ltp": 1.96, "tv": 111.9, "trd": NaN, "batb": [[0, 1.84, 29.19], [1, 1.72, 36.74], [2, 1.25, 28.88]], "batl": NaN}, {"timestamp": 1631545705546, "ltp": 1.96, "tv": 111.9, "trd": NaN, "batb": NaN, "batl": [[2, 1.94, 46.24]]}, {"timestamp": 1631545705753, "ltp": 1.96, "tv": 111.9, "trd": NaN, "batb": NaN, "batl": [[2, 1.94, 0]]}, {"timestamp": 1631545718162, "ltp": 1.96, "tv": 111.9, "trd": NaN, "batb": [[0, 1.72, 36.74], [1, 1.25, 28.88], [2, 1.01, 577.96]], "batl": NaN}, {"timestamp": 1631545726458, "ltp": 1.96, "tv": 111.9, "trd": NaN, "batb": [[0, 1.94, 7.02], [1, 1.72, 36.74], [2, 1.25, 28.88]], "batl": [[0, 1.98, 10.67], [1, 2.02, 104.49]]}, {"timestamp": 1631545727647, "ltp": 1.96, "tv": 111.9, "trd": NaN, "batb": [[1, 1.93, 50.5], [2, 1.8, 31.45]], "batl": NaN}, {"timestamp": 1631545739495, "ltp": 1.96, "tv": 111.9, "trd": NaN, "batb": [[0, 1.8, 31.45], [1, 1.25, 28.88], [2, 1.05, 477.24]], "batl": NaN}, {"timestamp": 1631545742303, "ltp": 1.96, "tv": 111.9, "trd": NaN, "batb": [[2, 1.11, 271.16]], "batl": NaN}, {"timestamp": 1631545748177, "ltp": 2.02, "tv": 132.4, "trd": [[2.02, 20.5]], "batb": NaN, "batl": NaN}, {"timestamp": 1631545768226, "ltp": 2.02, "tv": 132.4, "trd": NaN, "batb": [[2, 1.2, 387.76]], "batl": NaN}, {"timestamp": 1631545771504, "ltp": 2.02, "tv": 132.4, "trd": NaN, "batb": [[1, 1.4, 149.14], [2, 1.3, 198.84]], "batl": NaN}, {"timestamp": 1631545777635, "ltp": 2.02, "tv": 132.4, "trd": NaN, "batb": [[1, 1.74, 177.42], [2, 1.4, 149.14]], "batl": [[0, 1.83, 11.53], [1, 1.89, 257.24], [2, 1.9, 39.68]]}, {"timestamp": 1631545778613, "ltp": 1.89, "tv": 319.68, "trd": [[1.83, 26.41], [1.89, 164.22]], "batb": [[1, 1.76, 85.24], [2, 1.75, 42.62]], "batl": [[0, 1.89, 175.13], [1, 1.9, 7.94], [2, 1.91, 7.94]]}, {"timestamp": 1631545779335, "ltp": 1.89, "tv": 319.68, "trd": NaN, "batb": [[1, 1.76, 17.04], [2, 1.75, 8.52]], "batl": NaN}, {"timestamp": 1631545781415, "ltp": 1.89, "tv": 319.68, "trd": NaN, "batb": [[0, 1.88, 83.96], [1, 1.86, 85.7], [2, 1.8, 31.45]], "batl": NaN}, {"timestamp": 1631545782621, "ltp": 1.89, "tv": 319.68, "trd": NaN, "batb": NaN, "batl": [[0, 1.89, 221.97]]}, {"timestamp": 1631545782731, "ltp": 1.89, "tv": 319.68, "trd": NaN, "batb": NaN, "batl": [[0, 1.89, 175.13]]}, {"timestamp": 1631545784806, "ltp": 1.89, "tv": 375.42, "trd": [[1.89, 219.96]], "batb": NaN, "batl": [[0, 1.89, 147.26]]}, {"timestamp": 1631545791356, "ltp": 1.88, "tv": 407.12, "trd": [[1.88, 31.7]], "batb": [[0, 1.88, 68.11]], "batl": NaN}, {"timestamp": 1631545794417, "ltp": 1.88, "tv": 407.12, "trd": NaN, "batb": [[0, 1.88, 75.2]], "batl": NaN}, {"timestamp": 1631545804664, "ltp": 1.88, "tv": 407.12, "trd": NaN, "batb": [[0, 1.76, 17.04], [1, 1.75, 8.52], [2, 1.74, 8.52]], "batl": [[0, 1.9, 7.94], [1, 1.91, 7.94], [2, 1.91, 0]]}, {"timestamp": 1631545807534, "ltp": 1.88, "tv": 407.12, "trd": NaN, "batb": NaN, "batl": [[2, 2.08, 67.2]]}, {"timestamp": 1631545812478, "ltp": 1.88, "tv": 407.12, "trd": NaN, "batb": NaN, "batl": [[2, 2.08, 0]]}, {"timestamp": 1631545815489, "ltp": 2.0, "tv": 431.52, "trd": [[1.9, 7.94], [1.91, 18.43], [2, 8.52]], "batb": NaN, "batl": [[0, 2, 61.55], [1, 1.91, 0]]}, {"timestamp": 1631545816575, "ltp": 2.0, "tv": 431.52, "trd": NaN, "batb": [[0, 1.9, 26.59], [1, 1.76, 17.04], [2, 1.75, 43.5]], "batl": NaN}, {"timestamp": 1631545828595, "ltp": 2.0, "tv": 431.52, "trd": NaN, "batb": NaN, "batl": [[1, 2.02, 8.14]]}, {"timestamp": 1631545837670, "ltp": 2.0, "tv": 431.52, "trd": NaN, "batb": [[1, 1.75, 34.98], [2, 1.4, 149.14]], "batl": NaN}, {"timestamp": 1631545837780, "ltp": 2.0, "tv": 431.52, "trd": NaN, "batb": [[0, 1.75, 34.98], [1, 1.4, 149.14], [2, 1.3, 198.84]], "batl": NaN}, {"timestamp": 1631545845673, "ltp": 2.0, "tv": 431.52, "trd": NaN, "batb": [[0, 2.02, 44.04], [1, 1.89, 27.09], [2, 1.75, 34.98]], "batl": [[0, 2.16, 135.9]]}, {"timestamp": 1631545845988, "ltp": 2.0, "tv": 431.52, "trd": NaN, "batb": [[2, 1.4, 149.14]], "batl": NaN}, {"timestamp": 1631545847987, "ltp": 2.0, "tv": 431.52, "trd": NaN, "batb": [[2, 1.5, 107.38]], "batl": NaN}, {"timestamp": 1631545868640, "ltp": 2.0, "tv": 431.52, "trd": NaN, "batb": [[0, 1.89, 27.09], [1, 1.5, 107.38], [2, 1.4, 149.14]], "batl": NaN}, {"timestamp": 1631545881610, "ltp": 2.0, "tv": 431.52, "trd": NaN, "batb": NaN, "batl": [[0, 2, 169.17], [1, 2.02, 74.26], [2, 2.04, 37.14]]}, {"timestamp": 1631545882642, "ltp": 2.0, "tv": 431.52, "trd": NaN, "batb": [[0, 1.91, 78.52], [1, 1.9, 39.26], [2, 1.89, 66.35]], "batl": [[1, 2.02, 14.86], [2, 2.04, 7.42]]}, {"timestamp": 1631545882750, "ltp": 2.0, "tv": 431.52, "trd": NaN, "batb": [[0, 1.91, 15.7], [1, 1.9, 7.86], [2, 1.89, 34.95]], "batl": NaN}, {"timestamp": 1631545897337, "ltp": 2.0, "tv": 432.35, "trd": [[2, 9.35]], "batb": NaN, "batl": [[0, 2, 168.34]]}, {"timestamp": 1631545907466, "ltp": 2.0, "tv": 432.35, "trd": NaN, "batb": [[0, 1.73, 36.07], [1, 1.5, 107.38], [2, 1.4, 149.14]], "batl": NaN}, {"timestamp": 1631545912191, "ltp": 2.0, "tv": 432.35, "trd": NaN, "batb": [[0, 1.93, 70.05], [1, 1.91, 78.78], [2, 1.73, 36.07]], "batl": [[0, 2, 65.78], [1, 2.02, 67.76]]}, {"timestamp": 1631545918763, "ltp": 2.0, "tv": 432.35, "trd": NaN, "batb": [[0, 1.73, 36.07], [1, 1.5, 107.38], [2, 1.4, 149.14]], "batl": NaN}, {"timestamp": 1631545921680, "ltp": 2.0, "tv": 432.35, "trd": NaN, "batb": [[0, 1.79, 58.7], [1, 1.77, 100.78], [2, 1.73, 36.07]], "batl": [[0, 2.2, 90.09], [1, 2.22, 51.64]]}, {"timestamp": 1631545939220, "ltp": 2.0, "tv": 432.35, "trd": NaN, "batb": NaN, "batl": [[0, 1.83, 16.38], [1, 1.84, 48.91], [2, 1.85, 114.47]]}, {"timestamp": 1631545940315, "ltp": 2.0, "tv": 432.35, "trd": NaN, "batb": [[2, 1.75, 17.14]], "batl": [[1, 1.84, 16.3], [2, 1.85, 98.17]]}, {"timestamp": 1631545941992, "ltp": 1.83, "tv": 439.59, "trd": [[1.83, 33.64]], "batb": NaN, "batl": [[0, 1.83, 12.76]]}, {"timestamp": 1631545948528, "ltp": 1.83, "tv": 465.07, "trd": [[1.83, 59.12]], "batb": NaN, "batl": [[0, 1.84, 16.32], [1, 1.85, 98.17], [2, 1.86, 72.67]]}, {"timestamp": 1631545949635, "ltp": 1.83, "tv": 465.1, "trd": [[1.83, 59.16]], "batb": [[0, 1.83, 127.37], [1, 1.79, 58.7], [2, 1.77, 100.78]], "batl": [[0, 1.84, 16.3]]}, {"timestamp": 1631545950641, "ltp": 1.83, "tv": 465.1, "trd": NaN, "batb": [[0, 1.83, 188.72]], "batl": NaN}, {"timestamp": 1631545951530, "ltp": 1.83, "tv": 465.1, "trd": NaN, "batb": [[0, 1.83, 38.14]], "batl": NaN}, {"timestamp": 1631545952629, "ltp": 1.83, "tv": 465.1, "trd": NaN, "batb": [[0, 1.83, 88.01]], "batl": NaN}, {"timestamp": 1631545953517, "ltp": 1.83, "tv": 465.1, "trd": NaN, "batb": [[0, 1.79, 58.7], [1, 1.77, 100.78], [2, 1.75, 17.14]], "batl": NaN}, {"timestamp": 1631545955538, "ltp": 1.84, "tv": 497.71, "trd": [[1.84, 32.6]], "batb": [[0, 1.84, 16.18], [1, 1.79, 58.7], [2, 1.77, 100.78]], "batl": [[0, 1.85, 98.17], [1, 1.86, 88.32], [2, 1.87, 85.71]]}, {"timestamp": 1631545956436, "ltp": 1.84, "tv": 497.71, "trd": NaN, "batb": [[0, 1.84, 58.41]], "batl": NaN}, {"timestamp": 1631545957518, "ltp": 1.84, "tv": 497.71, "trd": NaN, "batb": [[0, 1.84, 31.87]], "batl": NaN}, {"timestamp": 1631545958034, "ltp": 1.84, "tv": 497.71, "trd": NaN, "batb": [[0, 1.84, 64.93]], "batl": NaN}, {"timestamp": 1631545959537, "ltp": 1.84, "tv": 497.71, "trd": NaN, "batb": [[0, 1.79, 58.7], [1, 1.77, 100.78], [2, 1.75, 17.14]], "batl": [[1, 1.86, 72.67]]}, {"timestamp": 1631545962302, "ltp": 1.85, "tv": 578.96, "trd": [[1.85, 81.25]], "batb": NaN, "batl": [[0, 1.85, 57.55]]}, {"timestamp": 1631545963602, "ltp": 1.85, "tv": 694.05, "trd": [[1.85, 196.35]], "batb": [[0, 1.85, 15.68], [1, 1.79, 58.7], [2, 1.77, 100.78]], "batl": [[0, 1.86, 14.83], [1, 1.87, 85.71], [2, 1.87, 0]]}, {"timestamp": 1631545964387, "ltp": 1.85, "tv": 694.05, "trd": NaN, "batb": [[0, 1.85, 35.74], [1, 1.55, 53.01], [2, 1.4, 149.14]], "batl": NaN}, {"timestamp": 1631545965585, "ltp": 1.85, "tv": 709.19, "trd": [[1.85, 211.49]], "batb": [[0, 1.55, 53.01], [1, 1.4, 149.14], [2, 1.3, 198.84]], "batl": NaN}, {"timestamp": 1631545967274, "ltp": 1.85, "tv": 709.19, "trd": NaN, "batb": [[0, 1.59, 78.27], [1, 1.58, 75.73], [2, 1.55, 53.01]], "batl": [[0, 2.04, 75.09], [1, 2.06, 63.92]]}, {"timestamp": 1631545969610, "ltp": 1.85, "tv": 709.19, "trd": NaN, "batb": [[0, 1.55, 53.01], [1, 1.4, 149.14], [2, 1.3, 198.84]], "batl": NaN}, {"timestamp": 1631545972514, "ltp": 1.85, "tv": 709.19, "trd": NaN, "batb": [[0, 1.75, 87.76], [1, 1.73, 108.83], [2, 1.55, 53.01]], "batl": [[0, 1.81, 79.45], [1, 1.83, 91.68]]}, {"timestamp": 1631545979194, "ltp": 1.85, "tv": 709.19, "trd": NaN, "batb": [[0, 1.55, 53.01], [1, 1.4, 149.14], [2, 1.3, 198.84]], "batl": NaN}, {"timestamp": 1631545982216, "ltp": 1.85, "tv": 709.19, "trd": NaN, "batb": [[0, 1.59, 83.16], [1, 1.58, 75.74], [2, 1.55, 53.01]], "batl": [[0, 2.04, 71.3], [1, 2.06, 63.92]]}, {"timestamp": 1631545985648, "ltp": 1.85, "tv": 709.19, "trd": NaN, "batb": NaN, "batl": [[2, 1000, 2.17]]}, {"timestamp": 1631545986126, "ltp": 1.85, "tv": 709.19, "trd": NaN, "batb": NaN, "batl": [[2, 1000, 0]]}, {"timestamp": 1631545989223, "ltp": 1.85, "tv": 709.19, "trd": NaN, "batb": NaN, "batl": [[2, 810, 0.07]]}, {"timestamp": 1631545992538, "ltp": 1.85, "tv": 709.19, "trd": NaN, "batb": NaN, "batl": [[2, 1000, 2.24]]}, {"timestamp": 1631545992955, "ltp": 1.85, "tv": 709.19, "trd": NaN, "batb": NaN, "batl": [[2, 810, 0.07]]}, {"timestamp": 1631545996048, "ltp": 1.85, "tv": 709.19, "trd": NaN, "batb": NaN, "batl": [[2, 820, 0.14]]}, {"timestamp": 1631546002276, "ltp": 1.85, "tv": 709.19, "trd": NaN, "batb": NaN, "batl": [[0, 820, 0.14], [1, 2.06, 0], [2, 820, 0]]}, {"timestamp": 1631546005340, "ltp": 1.85, "tv": 709.19, "trd": NaN, "batb": NaN, "batl": [[0, 1.62, 212.99], [1, 1.64, 119.16], [2, 1.65, 64.27]]}, {"timestamp": 1631546020471, "ltp": 1.62, "tv": 819.48, "trd": [[1.62, 110.28]], "batb": NaN, "batl": [[0, 1.62, 157.85]]}, {"timestamp": 1631546020683, "ltp": 1.62, "tv": 850.36, "trd": [[1.62, 141.16]], "batb": NaN, "batl": [[0, 1.62, 142.41]]}, {"timestamp": 1631546024397, "ltp": 1.62, "tv": 960.38, "trd": [[1.62, 251.19]], "batb": NaN, "batl": [[0, 1.62, 87.4]]}, {"timestamp": 1631546027007, "ltp": 1.62, "tv": 980.38, "trd": [[1.62, 271.19]], "batb": NaN, "batl": [[0, 1.62, 77.4]]}, {"timestamp": 1631546031015, "ltp": 1.62, "tv": 1014.46, "trd": [[1.62, 305.27]], "batb": NaN, "batl": [[0, 1.62, 60.36]]}, {"timestamp": 1631546031841, "ltp": 1.59, "tv": 1015.64, "trd": [[1.59, 1.18]], "batb": [[0, 1.59, 82.57]], "batl": NaN}, {"timestamp": 1631546042452, "ltp": 1.59, "tv": 1015.64, "trd": NaN, "batb": [[0, 1.55, 53.01], [1, 1.5, 604.51], [2, 1.3, 198.84]], "batl": [[1, 2.3, 314.34], [2, 810, 0.07]]}, {"timestamp": 1631546044249, "ltp": 1.62, "tv": 1049.72, "trd": [[1.62, 339.35]], "batb": NaN, "batl": [[0, 1.62, 43.32]]}, {"timestamp": 1631546045352, "ltp": 1.62, "tv": 1049.72, "trd": NaN, "batb": [[1, 1.54, 72.51], [2, 1.53, 85.65]], "batl": [[1, 1.74, 101.72], [2, 1.76, 103.94]]}, {"timestamp": 1631546055380, "ltp": 1.58, "tv": 1049.85, "trd": [[1.58, 0.13]], "batb": NaN, "batl": NaN}, {"timestamp": 1631546058983, "ltp": 1.62, "tv": 1083.51, "trd": [[1.62, 373.01]], "batb": NaN, "batl": [[0, 1.62, 26.49]]}, {"timestamp": 1631546062576, "ltp": 1.62, "tv": 1117.17, "trd": [[1.62, 406.67]], "batb": NaN, "batl": [[0, 1.62, 9.66]]}, {"timestamp": 1631546065489, "ltp": 1.62, "tv": 1117.17, "trd": NaN, "batb": NaN, "batl": [[0, 1.74, 101.72], [1, 1.76, 103.94], [2, 2.3, 314.34]]}, {"timestamp": 1631546068470, "ltp": 1.62, "tv": 1117.17, "trd": NaN, "batb": NaN, "batl": [[0, 1.62, 9.79], [1, 1.74, 101.72], [2, 1.76, 103.94]]}, {"timestamp": 1631546069672, "ltp": 1.62, "tv": 1117.17, "trd": NaN, "batb": [[0, 1.54, 72.51], [1, 1.53, 85.65], [2, 1.5, 493.21]], "batl": [[0, 1.74, 101.72], [1, 1.76, 103.94], [2, 2.3, 314.34]]}, {"timestamp": 1631546082999, "ltp": 1.62, "tv": 1117.17, "trd": NaN, "batb": [[0, 1.5, 493.21], [1, 1.3, 198.84], [2, 1.25, 28.88]], "batl": NaN}, {"timestamp": 1631546085605, "ltp": 1.62, "tv": 1117.17, "trd": NaN, "batb": [[0, 1.5, 59.97]], "batl": NaN}, {"timestamp": 1631546086604, "ltp": 1.62, "tv": 1117.17, "trd": NaN, "batb": [[0, 1.68, 103.07], [1, 1.66, 125.73], [2, 1.64, 43.62]], "batl": [[0, 1.74, 208.91]]}, {"timestamp": 1631546096598, "ltp": 1.62, "tv": 1117.17, "trd": NaN, "batb": NaN, "batl": [[0, 1.74, 101.72]]}, {"timestamp": 1631546097121, "ltp": 1.62, "tv": 1117.17, "trd": NaN, "batb": [[0, 1.58, 422.65], [1, 1.57, 50.41], [2, 1.3, 198.84]], "batl": [[0, 2.3, 314.34], [1, 810, 0.07], [2, 2.3, 0]]}, {"timestamp": 1631546099898, "ltp": 1.62, "tv": 1117.17, "trd": NaN, "batb": [[0, 1.61, 93.99], [1, 1.6, 72.3], [2, 1.58, 422.65]], "batl": [[0, 1.88, 84.17], [1, 1.9, 81.49], [2, 2.3, 314.34]]}, {"timestamp": 1631546109754, "ltp": 1.62, "tv": 1117.17, "trd": NaN, "batb": [[0, 1.58, 422.65], [1, 1.57, 50.41], [2, 1.3, 198.84]], "batl": NaN}, {"timestamp": 1631546111024, "ltp": 1.62, "tv": 1117.17, "trd": NaN, "batb": [[0, 1.57, 50.41], [1, 1.3, 198.84], [2, 1.25, 28.88]], "batl": [[2, 810, 0.07]]}, {"timestamp": 1631546112644, "ltp": 1.62, "tv": 1117.17, "trd": NaN, "batb": [[0, 1.81, 82.88], [1, 1.8, 41.44], [2, 1.79, 41.44]], "batl": [[1, 1.89, 18.49], [2, 1.9, 81.49]]}, {"timestamp": 1631546113533, "ltp": 1.62, "tv": 1117.17, "trd": NaN, "batb": [[0, 1.81, 149.18], [1, 1.8, 24.86], [2, 1.79, 121.94]], "batl": NaN}, {"timestamp": 1631546113742, "ltp": 1.62, "tv": 1117.17, "trd": NaN, "batb": [[0, 1.81, 116.03], [1, 1.8, 8.28], [2, 1.79, 105.36]], "batl": NaN}, {"timestamp": 1631546117663, "ltp": 1.81, "tv": 1226.65, "trd": [[1.81, 109.48]], "batb": [[0, 1.81, 61.29]], "batl": NaN}, {"timestamp": 1631546117818, "ltp": 1.81, "tv": 1226.65, "trd": NaN, "batb": NaN, "batl": [[0, 1.89, 18.49], [1, 2.72, 245.13], [2, 810, 0.07]]}, {"timestamp": 1631546120742, "ltp": 1.81, "tv": 1226.65, "trd": NaN, "batb": [[0, 1.81, 78.36]], "batl": [[0, 1.87, 62.89], [1, 1.89, 101.4], [2, 2.72, 245.13]]}, {"timestamp": 1631546126912, "ltp": 1.81, "tv": 1226.65, "trd": NaN, "batb": NaN, "batl": [[1, 1.89, 82.91]]}, {"timestamp": 1631546130605, "ltp": 1.81, "tv": 1226.65, "trd": NaN, "batb": [[0, 1.67, 456.52], [1, 1.3, 198.84], [2, 1.25, 28.88]], "batl": [[0, 2.72, 245.13], [1, 810, 0.07], [2, 2.72, 0]]}, {"timestamp": 1631546133530, "ltp": 1.81, "tv": 1226.65, "trd": NaN, "batb": [[0, 1.72, 79.63], [1, 1.7, 115.61], [2, 1.67, 456.52]], "batl": [[0, 2.06, 112.15], [1, 2.08, 62.17], [2, 2.72, 245.13]]}, {"timestamp": 1631546133840, "ltp": 1.81, "tv": 1226.65, "trd": NaN, "batb": [[0, 1.67, 456.52], [1, 1.3, 198.84], [2, 1.25, 28.88]], "batl": [[0, 2.72, 245.13], [1, 810, 0.07], [2, 2.72, 0]]}, {"timestamp": 1631546135499, "ltp": 1.81, "tv": 1226.65, "trd": NaN, "batb": [[0, 1.84, 76.91], [1, 1.82, 91.92], [2, 1.67, 456.52]], "batl": [[0, 1.91, 92.69], [1, 1.93, 77.68], [2, 2.72, 245.13]]}, {"timestamp": 1631546139153, "ltp": 1.81, "tv": 1226.65, "trd": NaN, "batb": [[0, 1.67, 456.52], [1, 1.3, 198.84], [2, 1.25, 28.88]], "batl": [[0, 2.72, 245.13], [1, 810, 0.07], [2, 2.72, 0]]}, {"timestamp": 1631546142814, "ltp": 1.81, "tv": 1226.65, "trd": NaN, "batb": [[0, 1.67, 40.68]], "batl": NaN}, {"timestamp": 1631546144333, "ltp": 1.81, "tv": 1226.65, "trd": NaN, "batb": [[0, 1.96, 76.52], [1, 1.95, 58.78], [2, 1.94, 38.26]], "batl": [[0, 2.04, 10.44], [1, 2.12, 164.46], [2, 2.72, 245.13]]}, {"timestamp": 1631546145444, "ltp": 1.81, "tv": 1226.65, "trd": NaN, "batb": [[0, 1.96, 15.3], [1, 1.95, 28.18], [2, 1.94, 7.66]], "batl": NaN}, {"timestamp": 1631546149241, "ltp": 1.96, "tv": 1270.07, "trd": [[1.96, 71.49], [1.98, 13.9]], "batb": [[0, 1.95, 28.72], [1, 1.94, 7.66], [2, 1.89, 27.01]], "batl": NaN}, {"timestamp": 1631546155572, "ltp": 1.96, "tv": 1270.07, "trd": NaN, "batb": [[0, 1.81, 30.78], [1, 1.74, 410.28], [2, 1.4, 149.14]], "batl": [[0, 2.72, 245.13], [1, 810, 0.07], [2, 2.72, 0]]}, {"timestamp": 1631546166365, "ltp": 1.96, "tv": 1270.07, "trd": NaN, "batb": [[1, 1.4, 149.14], [2, 1.3, 198.84]], "batl": [[0, 810, 0.07], [1, 810, 0]]}, {"timestamp": 1631546167667, "ltp": 1.96, "tv": 1270.07, "trd": NaN, "batb": NaN, "batl": [[0, 2.2, 15.93], [1, 2.28, 100.71], [2, 810, 0.07]]}, {"timestamp": 1631546168557, "ltp": 1.96, "tv": 1270.07, "trd": NaN, "batb": [[0, 2, 44.29], [1, 1.88, 27.34], [2, 1.4, 149.14]], "batl": NaN}, {"timestamp": 1631546169655, "ltp": 1.96, "tv": 1270.07, "trd": NaN, "batb": [[2, 1.82, 407.19]], "batl": [[2, 3.15, 203.39]]}, {"timestamp": 1631546172377, "ltp": 2.12, "tv": 1289.58, "trd": [[2.12, 19.51]], "batb": NaN, "batl": NaN}, {"timestamp": 1631546203602, "ltp": 2.12, "tv": 1289.58, "trd": NaN, "batb": NaN, "batl": [[0, 3.15, 203.39], [1, 810, 0.07], [2, 3.15, 0]]}, {"timestamp": 1631546203707, "ltp": 2.12, "tv": 1289.58, "trd": NaN, "batb": [[0, 1.88, 27.34], [1, 1.82, 407.19], [2, 1.4, 149.14]], "batl": NaN}, {"timestamp": 1631546215326, "ltp": 2.12, "tv": 1289.58, "trd": NaN, "batb": [[1, 1.4, 149.14], [2, 1.3, 198.84]], "batl": NaN}, {"timestamp": 1631546217138, "ltp": 2.12, "tv": 1289.58, "trd": NaN, "batb": [[0, 2.22, 40.54], [1, 2.2, 20.27], [2, 2.18, 20.27]], "batl": [[0, 2.28, 5.96], [1, 3.15, 203.39], [2, 810, 0.07]]}, {"timestamp": 1631546222030, "ltp": 2.22, "tv": 1325.3, "trd": [[2.22, 35.72]], "batb": [[0, 2.22, 22.68]], "batl": NaN}, {"timestamp": 1631546228559, "ltp": 2.22, "tv": 1339.9, "trd": [[2.22, 50.32]], "batb": [[0, 2.22, 15.38]], "batl": NaN}, {"timestamp": 1631546247575, "ltp": 2.22, "tv": 1339.9, "trd": NaN, "batb": [[0, 1.98, 46.72], [1, 1.92, 400.77], [2, 1.6, 99.42]], "batl": [[0, 3.15, 203.39], [1, 810, 0.07], [2, 810, 0]]}, {"timestamp": 1631546252186, "ltp": 2.22, "tv": 1339.9, "trd": NaN, "batb": NaN, "batl": [[0, 810, 0.07], [1, 810, 0]]}, {"timestamp": 1631546254182, "ltp": 2.22, "tv": 1339.9, "trd": NaN, "batb": [[0, 2.32, 98.96], [1, 2.3, 100], [2, 2.28, 6.52]], "batl": [[0, 2.5, 88.9], [1, 810, 0.07]]}, {"timestamp": 1631546255278, "ltp": 2.22, "tv": 1339.9, "trd": NaN, "batb": NaN, "batl": [[0, 2.46, 12.2], [1, 2.48, 6.1], [2, 2.5, 95]]}, {"timestamp": 1631546258905, "ltp": 2.32, "tv": 1355.42, "trd": [[2.32, 15.52]], "batb": [[0, 2.32, 91.2]], "batl": NaN}, {"timestamp": 1631546275108, "ltp": 2.32, "tv": 1355.42, "trd": NaN, "batb": [[0, 2.1, 39.17], [1, 1.92, 400.77], [2, 1.7, 17.05]], "batl": [[0, 3.65, 172.94], [1, 810, 0.07], [2, 2.5, 0]]}, {"timestamp": 1631546280609, "ltp": 2.32, "tv": 1355.42, "trd": NaN, "batb": NaN, "batl": [[0, 2.42, 212.49], [1, 3.65, 172.94], [2, 810, 0.07]]}, {"timestamp": 1631546280933, "ltp": 2.32, "tv": 1355.42, "trd": NaN, "batb": NaN, "batl": [[0, 3.65, 172.94], [1, 810, 0.07], [2, 810, 0]]}, {"timestamp": 1631546289554, "ltp": 2.32, "tv": 1355.42, "trd": NaN, "batb": NaN, "batl": [[1, 810, 0]]}, {"timestamp": 1631546293435, "ltp": 2.32, "tv": 1355.42, "trd": NaN, "batb": [[2, 1.6, 99.42]], "batl": NaN}, {"timestamp": 1631546294536, "ltp": 2.32, "tv": 1355.42, "trd": NaN, "batb": [[0, 2.14, 14.02], [1, 2.12, 7], [2, 2.1, 46.17]], "batl": NaN}, {"timestamp": 1631546295947, "ltp": 2.32, "tv": 1355.42, "trd": NaN, "batb": NaN, "batl": [[0, 3.3, 194.76]]}, {"timestamp": 1631546298334, "ltp": 2.2, "tv": 1362.79, "trd": [[2.2, 57.4]], "batb": NaN, "batl": NaN}, {"timestamp": 1631546304485, "ltp": 2.2, "tv": 1362.79, "trd": NaN, "batb": NaN, "batl": [[0, 3.2, 5.13], [1, 3.3, 194.76]]}, {"timestamp": 1631546317590, "ltp": 2.2, "tv": 1362.79, "trd": NaN, "batb": [[0, 1.95, 48.65], [1, 1.92, 400.77], [2, 1.6, 99.42]], "batl": [[0, 3.3, 194.76], [1, 3.3, 0]]}, {"timestamp": 1631546330498, "ltp": 2.2, "tv": 1362.79, "trd": NaN, "batb": NaN, "batl": [[0, 2.46, 72.28]]}, {"timestamp": 1631546331592, "ltp": 2.2, "tv": 1362.79, "trd": NaN, "batb": [[0, 2.2, 33.8], [1, 2.1, 39.09], [2, 1.95, 48.65]], "batl": [[0, 2.44, 12.3], [1, 2.46, 78.42], [2, 2.48, 6.14]]}, {"timestamp": 1631546332006, "ltp": 2.2, "tv": 1362.79, "trd": NaN, "batb": [[2, 1.92, 400.77]], "batl": NaN}, {"timestamp": 1631546335390, "ltp": 2.3, "tv": 1369.73, "trd": [[2.3, 6.94]], "batb": NaN, "batl": NaN}, {"timestamp": 1631546355652, "ltp": 2.3, "tv": 1369.73, "trd": NaN, "batb": NaN, "batl": [[1, 2.46, 6.14]]}, {"timestamp": 1631546356123, "ltp": 2.3, "tv": 1369.73, "trd": NaN, "batb": [[0, 2.1, 39.09], [1, 1.92, 400.77], [2, 1.7, 17.05]], "batl": [[0, 3.65, 172.94], [1, 2.46, 0], [2, 2.48, 0]]}, {"timestamp": 1631546363334, "ltp": 2.3, "tv": 1369.73, "trd": NaN, "batb": [[0, 2.36, 8.28], [1, 2.1, 39.09], [2, 1.92, 400.77]], "batl": [[0, 2.42, 6.78], [1, 2.56, 93.81], [2, 3.65, 172.94]]}, {"timestamp": 1631546364376, "ltp": 2.3, "tv": 1369.73, "trd": NaN, "batb": [[1, 2.28, 30.87], [2, 2.16, 35.98]], "batl": NaN}, {"timestamp": 1631546368144, "ltp": 2.4, "tv": 1372.7, "trd": [[2.4, 2.97]], "batb": NaN, "batl": NaN}, {"timestamp": 1631546386119, "ltp": 2.42, "tv": 1373.4, "trd": [[2.42, 0.7]], "batb": NaN, "batl": [[0, 2.42, 6.08]]}, {"timestamp": 1631546396315, "ltp": 2.42, "tv": 1373.4, "trd": NaN, "batb": [[0, 2.28, 30.87], [1, 2.16, 35.98], [2, 2.1, 39.09]], "batl": [[0, 2.56, 93.81], [1, 3.65, 172.94], [2, 3.65, 0]]}, {"timestamp": 1631546399218, "ltp": 2.42, "tv": 1373.4, "trd": NaN, "batb": [[0, 2.36, 9], [1, 2.28, 30.87], [2, 2.16, 35.98]], "batl": [[0, 2.42, 6.08], [1, 2.56, 93.81], [2, 3.65, 172.94]]}, {"timestamp": 1631546465302, "ltp": 2.42, "tv": 1373.4, "trd": NaN, "batb": [[0, 2.16, 35.98], [1, 1.92, 400.77], [2, 1.7, 17.05]], "batl": [[0, 3.65, 172.94], [1, 2.56, 0], [2, 3.65, 0]]}, {"timestamp": 1631546476642, "ltp": 2.42, "tv": 1373.4, "trd": NaN, "batb": [[2, 1.6, 99.42]], "batl": [[0, 2.46, 147.59]]}, {"timestamp": 1631546477423, "ltp": 2.42, "tv": 1373.4, "trd": NaN, "batb": [[0, 2.2, 68.18], [1, 2.18, 34.1], [2, 2.16, 70.08]], "batl": NaN}, {"timestamp": 1631546478119, "ltp": 2.42, "tv": 1373.4, "trd": NaN, "batb": [[0, 2.2, 13.64], [1, 2.18, 6.82], [2, 2.16, 42.8]], "batl": NaN}, {"timestamp": 1631546479422, "ltp": 2.42, "tv": 1373.4, "trd": NaN, "batb": NaN, "batl": [[1, 3.45, 183.07]]}, {"timestamp": 1631546481642, "ltp": 2.26, "tv": 1383.95, "trd": [[2.26, 10.55]], "batb": NaN, "batl": NaN}, {"timestamp": 1631546485526, "ltp": 2.26, "tv": 1383.95, "trd": NaN, "batb": [[0, 2.16, 35.98], [1, 2.06, 41.1], [2, 1.92, 400.77]], "batl": [[0, 3.45, 183.07], [1, 3.45, 0]]}, {"timestamp": 1631546485951, "ltp": 2.26, "tv": 1383.95, "trd": NaN, "batb": [[0, 2.06, 41.1], [1, 1.92, 400.77], [2, 1.6, 99.42]], "batl": NaN}, {"timestamp": 1631546511089, "ltp": 2.26, "tv": 1383.95, "trd": NaN, "batb": NaN, "batl": [[0, 2.2, 7.87], [1, 2.24, 53.57]]}, {"timestamp": 1631546512098, "ltp": 2.26, "tv": 1383.95, "trd": NaN, "batb": [[0, 2.1, 14.28], [1, 2.08, 7.14], [2, 2.06, 48.24]], "batl": NaN}, {"timestamp": 1631546513594, "ltp": 2.26, "tv": 1383.95, "trd": NaN, "batb": NaN, "batl": [[2, 3.3, 194.76]]}, {"timestamp": 1631546515966, "ltp": 2.16, "tv": 1396.26, "trd": [[2.16, 12.31]], "batb": NaN, "batl": NaN}, {"timestamp": 1631546518260, "ltp": 2.16, "tv": 1415.6, "trd": [[2.16, 31.65]], "batb": NaN, "batl": NaN}, {"timestamp": 1631546521575, "ltp": 2.16, "tv": 1415.6, "trd": NaN, "batb": [[0, 2.06, 41.1], [1, 1.99, 45.46], [2, 1.92, 400.77]], "batl": [[0, 3.3, 194.76], [1, 2.24, 0], [2, 3.3, 0]]}, {"timestamp": 1631546521995, "ltp": 2.16, "tv": 1415.6, "trd": NaN, "batb": [[0, 1.99, 45.46], [1, 1.92, 400.77], [2, 1.6, 99.42]], "batl": NaN}, {"timestamp": 1631546533979, "ltp": 2.16, "tv": 1415.6, "trd": NaN, "batb": [[0, 2.2, 10], [1, 1.99, 45.46], [2, 1.92, 400.77]], "batl": NaN}, {"timestamp": 1631546534715, "ltp": 2.2, "tv": 1435.52, "trd": [[2.2, 77.32]], "batb": [[0, 1.99, 45.5], [1, 1.92, 400.77], [2, 1.6, 99.42]], "batl": NaN}, {"timestamp": 1631546539010, "ltp": 2.2, "tv": 1685.16, "trd": [[2.2, 326.96]], "batb": [[0, 1.99, 45.46]], "batl": [[0, 2.16, 1.33], [1, 2.24, 111.02], [2, 3.3, 194.76]]}, {"timestamp": 1631546540336, "ltp": 2.2, "tv": 1685.16, "trd": NaN, "batb": [[1, 1.95, 48.82], [2, 1.92, 400.77]], "batl": NaN}, {"timestamp": 1631546541900, "ltp": 2.16, "tv": 1687.82, "trd": [[2.16, 34.31]], "batb": NaN, "batl": [[0, 2.24, 111.02], [1, 3.3, 194.76], [2, 3.3, 0]]}, {"timestamp": 1631546551643, "ltp": 2.16, "tv": 1687.82, "trd": NaN, "batb": NaN, "batl": [[0, 3.3, 194.76], [1, 3.3, 0]]}, {"timestamp": 1631546552012, "ltp": 2.16, "tv": 1687.82, "trd": NaN, "batb": [[0, 1.95, 48.82], [1, 1.92, 400.77], [2, 1.5, 107.38]], "batl": NaN}, {"timestamp": 1631546570675, "ltp": 2.16, "tv": 1687.82, "trd": NaN, "batb": [[1, 1.5, 107.38], [2, 1.4, 149.14]], "batl": [[0, 2.12, 94.34], [1, 2.16, 15.81]]}, {"timestamp": 1631546571473, "ltp": 2.16, "tv": 1687.82, "trd": NaN, "batb": [[0, 1.99, 75.38], [1, 1.98, 37.68], [2, 1.97, 37.68]], "batl": NaN}, {"timestamp": 1631546571985, "ltp": 2.16, "tv": 1687.82, "trd": NaN, "batb": [[0, 1.99, 15.08], [1, 1.98, 7.54], [2, 1.97, 7.54]], "batl": NaN}, {"timestamp": 1631546573564, "ltp": 2.16, "tv": 1687.82, "trd": NaN, "batb": NaN, "batl": [[2, 3, 216.62]]}, {"timestamp": 1631546601632, "ltp": 2.16, "tv": 1687.82, "trd": NaN, "batb": [[0, 1.81, 30.78], [1, 1.77, 408.24], [2, 1.5, 107.38]], "batl": [[0, 3, 216.62], [1, 2.16, 0], [2, 3, 0]]}, {"timestamp": 1631546604418, "ltp": 2.16, "tv": 1687.82, "trd": NaN, "batb": [[2, 1.4, 149.14]], "batl": [[0, 1.94, 2.48], [1, 3, 216.62]]}, {"timestamp": 1631546605314, "ltp": 1.94, "tv": 1687.9, "trd": [[1.94, 0.64]], "batb": NaN, "batl": [[0, 1.94, 2.4]]}, {"timestamp": 1631546608445, "ltp": 1.94, "tv": 1692.78, "trd": [[1.94, 5.52]], "batb": NaN, "batl": [[0, 3, 216.62], [1, 810, 0.07]]}, {"timestamp": 1631546611543, "ltp": 1.94, "tv": 1692.78, "trd": NaN, "batb": [[2, 1.5, 107.39]], "batl": NaN}, {"timestamp": 1631546619622, "ltp": 1.94, "tv": 1692.78, "trd": NaN, "batb": NaN, "batl": [[0, 810, 0.07], [1, 810, 0]]}, {"timestamp": 1631546621133, "ltp": 1.94, "tv": 1692.78, "trd": NaN, "batb": [[0, 1.88, 72.86], [1, 1.86, 85.65], [2, 1.81, 30.78]], "batl": [[0, 1.95, 80.55], [1, 1.97, 72.99], [2, 1.98, 57.73]]}, {"timestamp": 1631546622138, "ltp": 1.94, "tv": 1692.78, "trd": NaN, "batb": [[0, 1.88, 88.82], [1, 1.87, 7.98], [2, 1.86, 93.63]], "batl": NaN}, {"timestamp": 1631546626053, "ltp": 1.92, "tv": 1700.73, "trd": [[1.92, 12.78]], "batb": NaN, "batl": NaN}, {"timestamp": 1631546631612, "ltp": 1.95, "tv": 1702.44, "trd": [[1.95, 1.7]], "batb": NaN, "batl": [[0, 1.95, 79.7]]}, {"timestamp": 1631546633403, "ltp": 1.95, "tv": 1804.44, "trd": [[1.95, 103.7]], "batb": [[0, 1.88, 15.96], [2, 1.86, 7.98]], "batl": [[0, 1.98, 57.73], [1, 1.99, 22.73], [2, 2, 22.73]]}, {"timestamp": 1631546636309, "ltp": 1.95, "tv": 1804.44, "trd": NaN, "batb": [[0, 1.89, 60.68], [1, 1.88, 15.96], [2, 1.87, 92.15]], "batl": [[0, 1.96, 88.51], [1, 1.98, 117.33], [2, 1.99, 22.73]]}, {"timestamp": 1631546637714, "ltp": 1.95, "tv": 1804.44, "trd": NaN, "batb": [[0, 1.95, 235.29], [1, 1.89, 60.68], [2, 1.88, 15.96]], "batl": NaN}, {"timestamp": 1631546639011, "ltp": 1.95, "tv": 1804.44, "trd": NaN, "batb": NaN, "batl": [[0, 1.96, 100.02]]}, {"timestamp": 1631546648337, "ltp": 1.95, "tv": 1804.44, "trd": NaN, "batb": [[1, 1.77, 408.24], [2, 1.67, 40.68]], "batl": [[0, 2.72, 245.13], [1, 810, 0.07], [2, 1.99, 0]]}, {"timestamp": 1631546650333, "ltp": 1.95, "tv": 1855.82, "trd": [[1.95, 155.08]], "batb": [[0, 1.95, 209.6]], "batl": NaN}, {"timestamp": 1631546651114, "ltp": 1.95, "tv": 1855.82, "trd": NaN, "batb": [[2, 1.73, 64.19]], "batl": [[0, 2.08, 55.19], [1, 2.1, 60.41], [2, 2.72, 245.13]]}, {"timestamp": 1631546654350, "ltp": 1.95, "tv": 1855.82, "trd": NaN, "batb": [[2, 1.67, 40.68]], "batl": [[0, 2.72, 245.13], [1, 810, 0.07], [2, 2.72, 0]]}, {"timestamp": 1631546657436, "ltp": 1.95, "tv": 1855.82, "trd": NaN, "batb": NaN, "batl": [[0, 2.08, 10.89], [1, 2.16, 137.78], [2, 2.72, 245.13]]}, {"timestamp": 1631546658642, "ltp": 1.95, "tv": 1855.82, "trd": NaN, "batb": [[1, 1.91, 51.59], [2, 1.77, 441.87]], "batl": NaN}, {"timestamp": 1631546675571, "ltp": 1.95, "tv": 1855.82, "trd": NaN, "batb": [[1, 1.77, 441.87], [2, 1.4, 149.14]], "batl": [[0, 2.72, 245.13], [1, 810, 0.07], [2, 2.72, 0]]}, {"timestamp": 1631546678647, "ltp": 1.95, "tv": 1855.82, "trd": NaN, "batb": [[2, 1.5, 107.39]], "batl": NaN}, {"timestamp": 1631546688596, "ltp": 1.95, "tv": 1855.82, "trd": NaN, "batb": [[0, 2.04, 51], [1, 1.95, 209.6], [2, 1.77, 441.87]], "batl": NaN}, {"timestamp": 1631546691096, "ltp": 1.95, "tv": 1855.82, "trd": NaN, "batb": [[0, 1.95, 209.6], [1, 1.77, 441.87], [2, 1.5, 107.39]], "batl": NaN}, {"timestamp": 1631546694181, "ltp": 1.95, "tv": 1855.82, "trd": NaN, "batb": [[0, 2.06, 51], [1, 1.95, 209.6], [2, 1.77, 441.87]], "batl": NaN}, {"timestamp": 1631546696792, "ltp": 1.95, "tv": 1855.82, "trd": NaN, "batb": [[0, 1.95, 209.6], [1, 1.77, 441.87], [2, 1.5, 107.39]], "batl": NaN}, {"timestamp": 1631546698773, "ltp": 1.95, "tv": 1875.92, "trd": [[1.95, 175.18]], "batb": [[0, 1.95, 199.55]], "batl": NaN}, {"timestamp": 1631546699867, "ltp": 1.95, "tv": 1875.92, "trd": NaN, "batb": [[0, 2, 51], [1, 1.95, 199.55], [2, 1.77, 441.87]], "batl": NaN}, {"timestamp": 1631546702600, "ltp": 1.95, "tv": 1875.92, "trd": NaN, "batb": [[0, 1.95, 199.55], [1, 1.77, 441.87], [2, 1.5, 107.39]], "batl": NaN}, {"timestamp": 1631546705701, "ltp": 1.95, "tv": 1875.92, "trd": NaN, "batb": [[0, 1.98, 51], [1, 1.95, 199.55], [2, 1.77, 441.87]], "batl": NaN}, {"timestamp": 1631546713600, "ltp": 1.95, "tv": 1875.92, "trd": NaN, "batb": [[0, 1.95, 199.55], [1, 1.77, 441.87], [2, 1.5, 107.39]], "batl": NaN}, {"timestamp": 1631546716728, "ltp": 1.95, "tv": 1875.92, "trd": NaN, "batb": [[0, 2, 51], [1, 1.95, 199.55], [2, 1.77, 441.87]], "batl": NaN}, {"timestamp": 1631546719035, "ltp": 1.95, "tv": 1875.92, "trd": NaN, "batb": [[0, 1.95, 199.55], [1, 1.77, 441.87], [2, 1.5, 107.39]], "batl": NaN}, {"timestamp": 1631546722313, "ltp": 1.95, "tv": 1875.92, "trd": NaN, "batb": [[0, 1.98, 51], [1, 1.95, 199.55], [2, 1.77, 441.87]], "batl": NaN}, {"timestamp": 1631546725339, "ltp": 1.95, "tv": 2377.02, "trd": [[1.95, 574.28], [1.98, 115.9]], "batb": [[0, 1.86, 7.61], [1, 1.83, 84.53], [2, 1.81, 93.56]], "batl": [[0, 1.89, 7.5], [1, 1.9, 89.51], [2, 1.92, 94.52]]}, {"timestamp": 1631546726225, "ltp": 1.95, "tv": 2377.02, "trd": NaN, "batb": [[2, 1.82, 16.48]], "batl": NaN}, {"timestamp": 1631546736251, "ltp": 1.89, "tv": 2387.02, "trd": [[1.89, 229.96]], "batb": NaN, "batl": [[0, 1.89, 2.5]]}, {"timestamp": 1631546746361, "ltp": 1.89, "tv": 2387.02, "trd": NaN, "batb": [[0, 1.83, 84.53], [1, 1.82, 16.48], [2, 1.81, 101.8]], "batl": [[0, 1.9, 89.51], [1, 1.92, 94.52], [2, 1.93, 7.82]]}, {"timestamp": 1631546749591, "ltp": 1.81, "tv": 2664.31, "trd": [[1.81, 184.76], [1.82, 32.96], [1.83, 228.22]], "batb": [[0, 1.81, 8.24], [1, 1.8, 8.24], [2, 1.77, 441.87]], "batl": [[0, 1.9, 81.62], [1, 1.92, 32.31]]}, {"timestamp": 1631546752452, "ltp": 1.81, "tv": 2664.31, "trd": NaN, "batb": [[0, 1.82, 63.57], [1, 1.81, 8.24], [2, 1.8, 103.59]], "batl": [[0, 1.88, 73.49], [1, 1.9, 81.62], [2, 1.92, 32.31]]}, {"timestamp": 1631546754373, "ltp": 1.81, "tv": 2664.31, "trd": NaN, "batb": [[0, 1.77, 441.87], [1, 1.61, 46.55], [2, 1.4, 149.14]], "batl": [[0, 2.72, 245.13], [1, 810, 0.07], [2, 1.92, 0]]}, {"timestamp": 1631546754685, "ltp": 1.81, "tv": 2664.31, "trd": NaN, "batb": [[0, 1.77, 408.24]], "batl": NaN}, {"timestamp": 1631546757287, "ltp": 1.81, "tv": 2664.31, "trd": NaN, "batb": [[1, 1.64, 100.11], [2, 1.63, 67.72]], "batl": [[0, 2.04, 111.61], [1, 2.06, 63.96], [2, 2.72, 245.13]]}, {"timestamp": 1631546762187, "ltp": 1.81, "tv": 2664.31, "trd": NaN, "batb": NaN, "batl": [[0, 2.72, 245.13], [1, 810, 0.07], [2, 2.72, 0]]}, {"timestamp": 1631546764210, "ltp": 1.81, "tv": 2664.31, "trd": NaN, "batb": [[0, 1.64, 100.11], [1, 1.63, 67.72], [2, 1.61, 46.55]], "batl": [[0, 810, 0.07], [1, 810, 0]]}, {"timestamp": 1631546765202, "ltp": 1.81, "tv": 2664.31, "trd": NaN, "batb": [[0, 1.68, 11.28], [1, 1.64, 100.11], [2, 1.63, 67.72]], "batl": [[0, 1.69, 72.94], [1, 1.71, 114.93], [2, 1.72, 23.26]]}, {"timestamp": 1631546772913, "ltp": 1.68, "tv": 2664.47, "trd": [[1.68, 0.16]], "batb": [[0, 1.68, 11.2]], "batl": NaN}, {"timestamp": 1631546783115, "ltp": 1.68, "tv": 2664.47, "trd": NaN, "batb": [[0, 1.64, 100.11], [1, 1.63, 67.72], [2, 1.61, 46.55]], "batl": NaN}, {"timestamp": 1631546786223, "ltp": 1.68, "tv": 2664.47, "trd": NaN, "batb": [[0, 1.55, 426.74], [1, 1.48, 63.75], [2, 1.3, 198.84]], "batl": [[0, 2.42, 290.77], [1, 810, 0.07], [2, 1.72, 0]]}, {"timestamp": 1631546788616, "ltp": 1.68, "tv": 2664.47, "trd": NaN, "batb": [[0, 1.48, 63.75], [1, 1.3, 198.84], [2, 1.25, 28.88]], "batl": [[0, 810, 0.07], [1, 810, 0]]}, {"timestamp": 1631546790239, "ltp": 1.68, "tv": 2664.47, "trd": NaN, "batb": NaN, "batl": [[0, 1.95, 7.27], [1, 810, 0.07]]}, {"timestamp": 1631546791127, "ltp": 1.68, "tv": 2664.47, "trd": NaN, "batb": [[0, 1.61, 111.1], [1, 1.6, 72.56], [2, 1.48, 63.75]], "batl": [[0, 1.66, 80.5], [1, 1.68, 122.09], [2, 1.95, 7.27]]}, {"timestamp": 1631546797637, "ltp": 1.68, "tv": 2664.47, "trd": NaN, "batb": [[0, 1.48, 63.75], [1, 1.3, 198.84], [2, 1.25, 28.88]], "batl": [[0, 1.95, 7.27], [1, 810, 0.07], [2, 1.95, 0]]}, {"timestamp": 1631546800563, "ltp": 1.68, "tv": 2664.47, "trd": NaN, "batb": [[0, 1.51, 74.03], [1, 1.5, 93.08], [2, 1.48, 63.75]], "batl": [[0, 1.81, 99.29], [1, 1.83, 91.81], [2, 1.95, 7.27]]}, {"timestamp": 1631546802143, "ltp": 1.68, "tv": 2664.47, "trd": NaN, "batb": [[0, 1.48, 63.75], [1, 1.3, 198.84], [2, 1.25, 28.88]], "batl": NaN}, {"timestamp": 1631546805275, "ltp": 1.68, "tv": 2664.47, "trd": NaN, "batb": [[0, 1.75, 67.62], [1, 1.74, 51.72], [2, 1.73, 134.81]], "batl": [[1, 1.83, 104.44], [2, 1.89, 176.55]]}, {"timestamp": 1631546806260, "ltp": 1.68, "tv": 2664.47, "trd": NaN, "batb": [[1, 1.74, 17.24], [2, 1.73, 117.57]], "batl": NaN}, {"timestamp": 1631546812175, "ltp": 1.83, "tv": 2779.25, "trd": [[1.81, 284.05], [1.83, 243.71]], "batb": NaN, "batl": [[0, 1.83, 88.95], [1, 1.89, 176.55], [2, 1.95, 7.27]]}, {"timestamp": 1631546812806, "ltp": 1.83, "tv": 2779.25, "trd": NaN, "batb": [[0, 1.74, 17.24], [1, 1.73, 8.62], [2, 1.72, 8.62]], "batl": [[0, 1.83, 12.63]]}, {"timestamp": 1631546816495, "ltp": 1.78, "tv": 2790.08, "trd": [[1.78, 10.83]], "batb": [[0, 1.76, 80.31], [1, 1.74, 123.94], [2, 1.73, 8.62]], "batl": [[0, 1.82, 82.04], [1, 1.83, 12.63], [2, 1.84, 90.11]]}, {"timestamp": 1631546824399, "ltp": 1.82, "tv": 2954.16, "trd": [[1.82, 197.04]], "batb": [[0, 1.82, 37.96], [1, 1.74, 17.24]], "batl": [[0, 1.83, 12.63], [1, 1.89, 176.55], [2, 1.95, 7.27]]}, {"timestamp": 1631546827393, "ltp": 1.82, "tv": 2954.16, "trd": NaN, "batb": [[1, 1.77, 75.23], [2, 1.75, 104.53]], "batl": [[0, 1.83, 82.11], [1, 1.85, 88.47], [2, 1.89, 176.55]]}, {"timestamp": 1631546827913, "ltp": 1.82, "tv": 2954.16, "trd": NaN, "batb": [[0, 1.77, 75.23], [1, 1.75, 104.53], [2, 1.74, 17.24]], "batl": NaN}, {"timestamp": 1631546829597, "ltp": 1.82, "tv": 2954.16, "trd": NaN, "batb": [[1, 1.76, 17.2], [2, 1.75, 104.53]], "batl": NaN}, {"timestamp": 1631546833525, "ltp": 1.82, "tv": 2954.16, "trd": NaN, "batb": [[0, 1.51, 59.39], [1, 1.3, 198.84], [2, 1.25, 28.88]], "batl": [[0, 1.95, 7.27], [1, 810, 0.07], [2, 1.89, 0]]}, {"timestamp": 1631546836511, "ltp": 1.82, "tv": 2954.16, "trd": NaN, "batb": NaN, "batl": [[1, 2.04, 75.7], [2, 2.06, 63.87]]}, {"timestamp": 1631546839195, "ltp": 1.95, "tv": 2961.44, "trd": [[1.95, 581.56]], "batb": [[0, 1.96, 90.22], [1, 1.94, 178.05], [2, 1.91, 15.7]], "batl": [[0, 2, 5.06]]}, {"timestamp": 1631546840238, "ltp": 1.95, "tv": 2961.44, "trd": NaN, "batb": NaN, "batl": [[1, 2.02, 14.86], [2, 2.04, 83.12]]}, {"timestamp": 1631546855658, "ltp": 2.04, "tv": 2991.75, "trd": [[2, 14.41], [2.02, 35.36], [2.04, 11.06]], "batb": [[0, 1.96, 6.96], [1, 1.94, 103.1]], "batl": [[0, 2.04, 7.42], [1, 2.06, 7.42], [2, 2.08, 100.94]]}, {"timestamp": 1631546864539, "ltp": 2.04, "tv": 2991.75, "trd": NaN, "batb": [[0, 1.88, 27.43], [1, 1.69, 38.67], [2, 1.4, 149.15]], "batl": [[0, 810, 0.07], [1, 2.06, 0], [2, 2.08, 0]]}, {"timestamp": 1631546864860, "ltp": 2.04, "tv": 2991.75, "trd": NaN, "batb": [[0, 1.69, 38.67], [1, 1.4, 149.15], [2, 1.3, 198.84]], "batl": NaN}, {"timestamp": 1631546870493, "ltp": 2.04, "tv": 2991.75, "trd": NaN, "batb": [[0, 2.1, 166.68], [1, 2.08, 35.72], [2, 2.06, 35.72]], "batl": [[0, 2.2, 15.5], [1, 2.24, 99.8], [2, 810, 0.07]]}, {"timestamp": 1631546871594, "ltp": 2.04, "tv": 2991.75, "trd": NaN, "batb": [[0, 2.1, 109.52], [1, 2.08, 7.14], [2, 2.06, 7.14]], "batl": NaN}, {"timestamp": 1631546891603, "ltp": 2.04, "tv": 2991.75, "trd": NaN, "batb": [[0, 2.02, 43.79], [1, 1.87, 28.02], [2, 1.4, 149.15]], "batl": [[0, 810, 0.07], [1, 2.24, 0], [2, 810, 0]]}, {"timestamp": 1631546891809, "ltp": 2.04, "tv": 2991.75, "trd": NaN, "batb": [[0, 1.87, 28.02], [1, 1.4, 149.15], [2, 1.3, 198.84]], "batl": NaN}, {"timestamp": 1631546894932, "ltp": 2.04, "tv": 2991.75, "trd": NaN, "batb": [[1, 1.5, 107.39], [2, 1.4, 149.15]], "batl": NaN}, {"timestamp": 1631546913346, "ltp": 2.04, "tv": 2991.75, "trd": NaN, "batb": [[0, 1.95, 53.74], [1, 1.93, 76.16], [2, 1.87, 28.02]], "batl": [[0, 2, 104.63], [1, 2.02, 74.79], [2, 2.04, 65.72]]}, {"timestamp": 1631546914372, "ltp": 2.04, "tv": 2991.75, "trd": NaN, "batb": [[2, 1.92, 15.62]], "batl": NaN}, {"timestamp": 1631546937615, "ltp": 2.04, "tv": 2991.75, "trd": NaN, "batb": [[2, 1.87, 28.02]], "batl": [[0, 2.02, 74.79], [1, 2.04, 65.72], [2, 2.04, 0]]}, {"timestamp": 1631546937787, "ltp": 2.04, "tv": 2991.75, "trd": NaN, "batb": [[0, 1.69, 39.26], [1, 1.5, 107.39], [2, 1.4, 149.15]], "batl": NaN}, {"timestamp": 1631546940581, "ltp": 2.04, "tv": 2991.75, "trd": NaN, "batb": [[0, 1.74, 85.62], [1, 1.72, 110.88], [2, 1.69, 39.26]], "batl": [[0, 2.2, 84.15], [1, 2.22, 51.59]]}, {"timestamp": 1631546940787, "ltp": 2.04, "tv": 2991.75, "trd": NaN, "batb": [[0, 1.69, 39.26], [1, 1.5, 107.39], [2, 1.4, 149.15]], "batl": NaN}, {"timestamp": 1631546942499, "ltp": 2.04, "tv": 2991.75, "trd": NaN, "batb": NaN, "batl": [[0, 2.04, 250.96]]}, {"timestamp": 1631546942812, "ltp": 2.04, "tv": 2991.75, "trd": NaN, "batb": [[0, 1.9, 75.6], [1, 1.88, 82.71], [2, 1.69, 39.26]], "batl": [[0, 1.97, 70.36], [1, 1.99, 70.73]]}, {"timestamp": 1631546944215, "ltp": 2.04, "tv": 2991.75, "trd": NaN, "batb": NaN, "batl": [[2, 2.72, 245.13]]}, {"timestamp": 1631546949930, "ltp": 2.04, "tv": 2991.75, "trd": NaN, "batb": [[0, 1.69, 39.26], [1, 1.67, 415.84], [2, 1.5, 107.39]], "batl": [[0, 2.72, 245.13], [1, 1.99, 0], [2, 2.72, 0]]}, {"timestamp": 1631546952826, "ltp": 2.04, "tv": 2991.75, "trd": NaN, "batb": [[0, 1.74, 85.62], [1, 1.72, 110.88], [2, 1.69, 39.26]], "batl": [[0, 2.2, 84.15], [1, 2.22, 51.59], [2, 2.72, 245.13]]}, {"timestamp": 1631546959901, "ltp": 2.04, "tv": 2991.75, "trd": NaN, "batb": NaN, "batl": [[2, 2.72, 0]]}, {"timestamp": 1631546965351, "ltp": 2.04, "tv": 2991.75, "trd": NaN, "batb": [[0, 1.69, 39.26], [1, 1.5, 107.39], [2, 1.4, 149.15]], "batl": NaN}, {"timestamp": 1631546968516, "ltp": 2.04, "tv": 2991.75, "trd": NaN, "batb": [[0, 2.08, 14.42], [1, 2.06, 96.32], [2, 2.04, 7.22]], "batl": [[0, 2.16, 11.29]]}, {"timestamp": 1631546969501, "ltp": 2.04, "tv": 2991.75, "trd": NaN, "batb": NaN, "batl": [[1, 2.2, 13.64], [2, 2.22, 6.82]]}, {"timestamp": 1631546973447, "ltp": 2.12, "tv": 2995.62, "trd": [[2.12, 23.38]], "batb": NaN, "batl": NaN}, {"timestamp": 1631546990962, "ltp": 2.12, "tv": 2995.62, "trd": NaN, "batb": [[0, 1.86, 28.52], [1, 1.5, 107.39], [2, 1.4, 149.15]], "batl": NaN}, {"timestamp": 1631547004292, "ltp": 2.12, "tv": 2995.62, "trd": NaN, "batb": [[0, 1.94, 7.24], [1, 1.93, 58.99], [2, 1.91, 78.68]], "batl": [[0, 1.98, 10.34], [1, 1.99, 60.3], [2, 2, 76.12]]}, {"timestamp": 1631547005556, "ltp": 2.12, "tv": 2995.62, "trd": NaN, "batb": [[2, 1.91, 125.79]], "batl": NaN}, {"timestamp": 1631547007283, "ltp": 2.12, "tv": 2995.62, "trd": NaN, "batb": [[2, 1.91, 94.38]], "batl": NaN}, {"timestamp": 1631547017325, "ltp": 1.98, "tv": 3000.68, "trd": [[1.98, 120.96]], "batb": NaN, "batl": [[0, 1.98, 7.81]]}, {"timestamp": 1631547027321, "ltp": 1.98, "tv": 3000.68, "trd": NaN, "batb": [[0, 1.67, 40.26], [1, 1.4, 149.15], [2, 1.3, 198.84]], "batl": NaN}, {"timestamp": 1631547032329, "ltp": 1.98, "tv": 3000.68, "trd": NaN, "batb": [[0, 1.88, 86.2], [1, 1.86, 85.59], [2, 1.67, 40.26]], "batl": [[0, 1.95, 67.48], [1, 1.97, 72.92]]}, {"timestamp": 1631547039239, "ltp": 1.98, "tv": 3000.68, "trd": NaN, "batb": [[0, 1.67, 40.26], [1, 1.4, 149.15], [2, 1.3, 198.84]], "batl": NaN}, {"timestamp": 1631547042474, "ltp": 1.98, "tv": 3000.68, "trd": NaN, "batb": [[0, 1.73, 62.8], [1, 1.71, 113.04], [2, 1.67, 40.26]], "batl": [[0, 2.18, 91.2], [1, 2.2, 52.93]]}, {"timestamp": 1631547048284, "ltp": 1.98, "tv": 3000.68, "trd": NaN, "batb": [[0, 1.67, 40.26], [1, 1.4, 149.15], [2, 1.3, 198.84]], "batl": NaN}, {"timestamp": 1631547051399, "ltp": 1.98, "tv": 3000.68, "trd": NaN, "batb": [[0, 2.06, 72.82], [1, 2.04, 36.4], [2, 2.02, 36.4]], "batl": [[0, 2.16, 17.3], [1, 2.2, 127.14]]}, {"timestamp": 1631547052488, "ltp": 1.98, "tv": 3000.68, "trd": NaN, "batb": [[0, 2.06, 14.56], [1, 2.04, 7.28], [2, 2.02, 7.28]], "batl": NaN}, {"timestamp": 1631547083137, "ltp": 1.98, "tv": 3000.68, "trd": NaN, "batb": [[0, 1.84, 29.53], [1, 1.4, 149.15], [2, 1.3, 198.84]], "batl": NaN}, {"timestamp": 1631547087602, "ltp": 1.98, "tv": 3000.68, "trd": NaN, "batb": NaN, "batl": [[0, 2.2, 233.43]]}, {"timestamp": 1631547108657, "ltp": 1.98, "tv": 3000.68, "trd": NaN, "batb": [[0, 2.22, 67.56], [1, 2.2, 41.03], [2, 2.18, 33.78]], "batl": NaN}, {"timestamp": 1631547109536, "ltp": 1.98, "tv": 3000.68, "trd": NaN, "batb": [[0, 2.22, 13.52], [1, 2.2, 14.01], [2, 2.18, 6.76]], "batl": NaN}, {"timestamp": 1631547111556, "ltp": 1.98, "tv": 3000.68, "trd": NaN, "batb": NaN, "batl": [[0, 3.15, 203.39]]}, {"timestamp": 1631547113576, "ltp": 2.22, "tv": 3013.78, "trd": [[2.22, 63.42]], "batb": [[0, 2.22, 6.97]], "batl": NaN}, {"timestamp": 1631547121558, "ltp": 2.22, "tv": 3013.78, "trd": NaN, "batb": NaN, "batl": [[0, 3.1, 7.12], [1, 3.15, 203.39]]}, {"timestamp": 1631547137198, "ltp": 2.2, "tv": 3061.08, "trd": [[2.2, 360.32], [2.22, 77.36]], "batb": [[0, 2.18, 6.76], [1, 2.1, 38.5], [2, 2, 45.38]], "batl": NaN}, {"timestamp": 1631547150208, "ltp": 2.2, "tv": 3061.08, "trd": NaN, "batb": NaN, "batl": [[0, 2.24, 12.22]]}, {"timestamp": 1631547152400, "ltp": 2.2, "tv": 3061.08, "trd": NaN, "batb": NaN, "batl": [[0, 2.24, 38.21]]}, {"timestamp": 1631547163519, "ltp": 2.2, "tv": 3061.08, "trd": NaN, "batb": NaN, "batl": [[0, 2.24, 12.22]]}, {"timestamp": 1631547166640, "ltp": 2.2, "tv": 3061.08, "trd": NaN, "batb": NaN, "batl": [[1, 2.26, 25.99], [2, 3.15, 203.39]]}, {"timestamp": 1631547177058, "ltp": 2.24, "tv": 3073.3, "trd": [[2.24, 12.22]], "batb": NaN, "batl": [[0, 2.26, 25.99], [1, 3.15, 203.39], [2, 3.15, 0]]}, {"timestamp": 1631547185464, "ltp": 2.26, "tv": 3085.02, "trd": [[2.26, 22.27]], "batb": NaN, "batl": [[0, 2.26, 14.27]]}, {"timestamp": 1631547190160, "ltp": 2.26, "tv": 3085.02, "trd": NaN, "batb": NaN, "batl": [[1, 2.28, 11.65], [2, 3.15, 203.39]]}, {"timestamp": 1631547209596, "ltp": 2.26, "tv": 3085.02, "trd": NaN, "batb": [[0, 2.1, 38.5], [1, 2, 45.38], [2, 1.9, 16.76]], "batl": [[1, 3.15, 203.39], [2, 3.15, 0]]}, {"timestamp": 1631547210019, "ltp": 2.26, "tv": 3085.02, "trd": NaN, "batb": [[0, 2, 45.38], [1, 1.9, 16.76], [2, 1.82, 407.19]], "batl": NaN}, {"timestamp": 1631547264014, "ltp": 2.26, "tv": 3085.02, "trd": NaN, "batb": [[2, 1.6, 99.43]], "batl": NaN}, {"timestamp": 1631547265274, "ltp": 2.26, "tv": 3099.29, "trd": [[2.26, 36.54]], "batb": [[0, 2.32, 116.75], [1, 2, 45.38], [2, 1.9, 16.76]], "batl": [[0, 2.5, 9.59], [1, 2.56, 112.18], [2, 3.15, 203.39]]}, {"timestamp": 1631547266590, "ltp": 2.26, "tv": 3099.29, "trd": NaN, "batb": [[1, 2.3, 29.95], [2, 2.14, 36.66]], "batl": [[1, 2.56, 123.9], [2, 2.58, 5.86]]}, {"timestamp": 1631547280008, "ltp": 2.26, "tv": 3099.29, "trd": NaN, "batb": NaN, "batl": [[0, 2.56, 123.9], [1, 2.58, 5.86], [2, 2.6, 5.86]]}, {"timestamp": 1631547283035, "ltp": 2.26, "tv": 3099.29, "trd": NaN, "batb": [[0, 2.4, 7.04], [1, 2.32, 116.75], [2, 2.3, 29.95]], "batl": [[0, 2.46, 7.42], [1, 2.56, 123.9], [2, 2.58, 5.86]]}, {"timestamp": 1631547287236, "ltp": 2.26, "tv": 3099.29, "trd": NaN, "batb": [[0, 2.14, 36.66], [1, 1.9, 16.76], [2, 1.7, 17.05]], "batl": NaN}, {"timestamp": 1631547304060, "ltp": 2.26, "tv": 3099.29, "trd": NaN, "batb": [[0, 2.72, 5.21], [1, 2.68, 85.82], [2, 2.66, 5.6]], "batl": [[0, 2.78, 5.3], [1, 2.92, 101.86]]}, {"timestamp": 1631547305328, "ltp": 2.26, "tv": 3099.29, "trd": NaN, "batb": NaN, "batl": [[1, 2.88, 10.42], [2, 2.9, 5.2]]}, {"timestamp": 1631547312351, "ltp": 2.9, "tv": 3189.47, "trd": [[2.78, 10.6], [2.88, 20.84], [2.9, 58.74]], "batb": [[0, 2.9, 58.64], [1, 2.72, 5.21], [2, 2.68, 85.82]], "batl": [[0, 2.92, 107.06], [1, 2.88, 0], [2, 2.9, 0]]}, {"timestamp": 1631547315237, "ltp": 2.9, "tv": 3306.75, "trd": [[2.9, 176.02]], "batb": [[0, 2.72, 5.21], [1, 2.68, 85.82], [2, 2.66, 5.6]], "batl": NaN}, {"timestamp": 1631547317475, "ltp": 2.9, "tv": 3306.75, "trd": NaN, "batb": [[0, 2.38, 27.34], [1, 1.9, 16.76], [2, 1.7, 17.05]], "batl": NaN}, {"timestamp": 1631547325989, "ltp": 2.9, "tv": 3306.75, "trd": NaN, "batb": NaN, "batl": [[0, 2.9, 14.44]]}, {"timestamp": 1631547330589, "ltp": 2.9, "tv": 3335.63, "trd": [[2.9, 204.9]], "batb": [[0, 3.25, 47.1], [1, 3.15, 9.52], [2, 3.1, 4.76]], "batl": [[0, 3.4, 79.36]]}, {"timestamp": 1631547334211, "ltp": 2.9, "tv": 3335.63, "trd": NaN, "batb": NaN, "batl": [[1, 4.9, 128.15]]}, {"timestamp": 1631547343179, "ltp": 2.9, "tv": 3335.63, "trd": NaN, "batb": [[0, 2.74, 18.54], [1, 2.3, 390.8], [2, 1.9, 16.76]], "batl": [[0, 4.9, 128.15], [1, 4.9, 0]]}, {"timestamp": 1631547350418, "ltp": 2.9, "tv": 3335.63, "trd": NaN, "batb": [[0, 2.96, 5.36], [1, 2.74, 18.54], [2, 2.3, 390.8]], "batl": [[0, 3.05, 7.31], [1, 3.1, 65.59]]}, {"timestamp": 1631547351638, "ltp": 2.9, "tv": 3335.63, "trd": NaN, "batb": [[1, 2.9, 51.72], [2, 2.88, 25.86]], "batl": [[2, 3.6, 14.44]]}, {"timestamp": 1631547352413, "ltp": 2.9, "tv": 3335.63, "trd": NaN, "batb": [[1, 2.9, 10.34], [2, 2.88, 5.18]], "batl": NaN}, {"timestamp": 1631547357626, "ltp": 2.9, "tv": 3335.63, "trd": NaN, "batb": [[0, 2.9, 10.34], [1, 2.88, 5.18], [2, 2.86, 5.18]], "batl": [[0, 3.6, 14.44], [1, 4.6, 138.07], [2, 3.6, 0]]}, {"timestamp": 1631547358107, "ltp": 2.9, "tv": 3335.63, "trd": NaN, "batb": [[0, 2.48, 24.33], [1, 2.3, 390.8], [2, 1.9, 16.76]], "batl": NaN}, {"timestamp": 1631547379031, "ltp": 2.9, "tv": 3335.63, "trd": NaN, "batb": NaN, "batl": [[1, 4.6, 0]]}, {"timestamp": 1631547380434, "ltp": 2.9, "tv": 3335.63, "trd": NaN, "batb": [[0, 3.5, 4.49], [1, 3.4, 26.47], [2, 3.35, 49.06]], "batl": [[1, 3.7, 9.31], [2, 3.85, 95.36]]}, {"timestamp": 1631547381639, "ltp": 2.9, "tv": 3335.63, "trd": NaN, "batb": [[1, 3.4, 8.82], [2, 3.35, 40.24]], "batl": [[2, 3.75, 8]]}, {"timestamp": 1631547392243, "ltp": 2.9, "tv": 3335.63, "trd": NaN, "batb": NaN, "batl": [[0, 3.7, 9.31], [1, 3.75, 8], [2, 3.8, 4]]}, {"timestamp": 1631547395666, "ltp": 2.9, "tv": 3335.63, "trd": NaN, "batb": NaN, "batl": [[0, 3.55, 14.44], [1, 3.7, 9.31], [2, 3.75, 8]]}, {"timestamp": 1631547406473, "ltp": 3.7, "tv": 3359.38, "trd": [[3.55, 14.44], [3.7, 9.31]], "batb": NaN, "batl": [[0, 3.75, 8], [1, 3.8, 4], [2, 3.85, 99.36]]}, {"timestamp": 1631547411384, "ltp": 3.7, "tv": 3359.38, "trd": NaN, "batb": [[0, 2.84, 41.6], [1, 2.3, 390.8], [2, 2, 11.93]], "batl": [[0, 5.5, 116.76], [1, 3.8, 0], [2, 3.85, 0]]}, {"timestamp": 1631547442013, "ltp": 3.7, "tv": 3359.38, "trd": NaN, "batb": [[1, 2, 11.93], [2, 1.9, 16.76]], "batl": NaN}, {"timestamp": 1631547443423, "ltp": 3.7, "tv": 3359.38, "trd": NaN, "batb": [[0, 3.75, 10.66], [1, 3.6, 91.45], [2, 2.84, 41.6]], "batl": [[0, 4.1, 83.16], [1, 5.5, 116.76]]}, {"timestamp": 1631547444499, "ltp": 3.7, "tv": 3359.38, "trd": NaN, "batb": [[2, 3.45, 25.42]], "batl": [[1, 4.2, 7.14], [2, 4.3, 3.58]]}, {"timestamp": 1631547459836, "ltp": 3.7, "tv": 3359.38, "trd": NaN, "batb": NaN, "batl": [[0, 4.1, 76.42]]}, {"timestamp": 1631547462827, "ltp": 3.7, "tv": 3359.38, "trd": NaN, "batb": [[0, 3.9, 6.55], [1, 3.75, 10.66], [2, 3.6, 91.45]], "batl": [[0, 4.1, 84.39]]}, {"timestamp": 1631547464800, "ltp": 3.9, "tv": 3365.93, "trd": [[3.9, 6.55]], "batb": [[0, 3.75, 10.66], [1, 3.6, 91.45], [2, 3.45, 25.42]], "batl": NaN}, {"timestamp": 1631547474332, "ltp": 3.9, "tv": 3365.93, "trd": NaN, "batb": [[0, 3.05, 33.64], [1, 2.52, 387.12], [2, 2.2, 42.6]], "batl": [[0, 5.5, 116.76], [1, 4.2, 0], [2, 4.3, 0]]}, {"timestamp": 1631547481658, "ltp": 3.9, "tv": 3365.93, "trd": NaN, "batb": [[0, 3.3, 60.85], [1, 3.05, 33.64], [2, 2.52, 387.12]], "batl": [[0, 3.7, 99.45], [1, 3.75, 4.06], [2, 3.8, 4.06]]}, {"timestamp": 1631547482649, "ltp": 3.9, "tv": 3365.93, "trd": NaN, "batb": [[0, 3.35, 8.96], [1, 3.3, 65.33], [2, 3.25, 4.48]], "batl": NaN}, {"timestamp": 1631547504007, "ltp": 3.9, "tv": 3365.93, "trd": NaN, "batb": [[0, 2.76, 18.29], [1, 2.52, 387.12], [2, 2.2, 42.6]], "batl": [[0, 5.5, 116.76], [1, 3.75, 0], [2, 3.8, 0]]}, {"timestamp": 1631547505621, "ltp": 3.9, "tv": 3365.93, "trd": NaN, "batb": [[0, 3.1, 4.44], [1, 3, 5], [2, 2.76, 18.29]], "batl": NaN}, {"timestamp": 1631547507196, "ltp": 3.9, "tv": 3365.93, "trd": NaN, "batb": NaN, "batl": [[0, 4.4, 2.14], [1, 5.5, 116.76]]}, {"timestamp": 1631547511400, "ltp": 3.9, "tv": 3365.93, "trd": NaN, "batb": NaN, "batl": [[0, 3.5, 21.99], [1, 4.4, 2.14], [2, 5.5, 116.76]]}, {"timestamp": 1631547511714, "ltp": 3.9, "tv": 3365.93, "trd": NaN, "batb": NaN, "batl": [[0, 4.4, 2.14], [1, 5.5, 116.76], [2, 5.5, 0]]}, {"timestamp": 1631547527217, "ltp": 3.9, "tv": 3365.93, "trd": NaN, "batb": NaN, "batl": [[1, 5.5, 0]]}, {"timestamp": 1631547528470, "ltp": 3.9, "tv": 3365.93, "trd": NaN, "batb": [[0, 3, 10.43], [1, 2.88, 82.84]], "batl": [[0, 3.2, 86.42], [1, 3.25, 4.68], [2, 3.3, 4.68]]}, {"timestamp": 1631547529466, "ltp": 3.9, "tv": 3365.93, "trd": NaN, "batb": [[1, 2.94, 10.2], [2, 2.92, 5.1]], "batl": NaN}, {"timestamp": 1631547538253, "ltp": 3.9, "tv": 3365.93, "trd": NaN, "batb": [[0, 3, 5]], "batl": NaN}, {"timestamp": 1631547551488, "ltp": 3.9, "tv": 3365.93, "trd": NaN, "batb": [[0, 2.76, 18.29], [1, 2.68, 5.11], [2, 2.58, 5.56]], "batl": [[0, 3.6, 2.96], [1, 3.8, 3.32], [2, 4.4, 2.14]]}, {"timestamp": 1631547551697, "ltp": 3.9, "tv": 3365.93, "trd": NaN, "batb": [[0, 2.68, 5.11], [1, 2.58, 5.56], [2, 2.4, 26.76]], "batl": [[0, 3.8, 3.32], [1, 4.6, 138.07], [2, 4.4, 0]]}, {"timestamp": 1631547554671, "ltp": 3.9, "tv": 3365.93, "trd": NaN, "batb": NaN, "batl": [[1, 4.6, 0]]}, {"timestamp": 1631547556596, "ltp": 3.9, "tv": 3365.93, "trd": NaN, "batb": [[0, 3.4, 8.24], [1, 3.35, 44.78], [2, 3.3, 22.4]], "batl": [[0, 3.55, 71.77], [1, 3.8, 3.32]]}, {"timestamp": 1631547557592, "ltp": 3.9, "tv": 3365.93, "trd": NaN, "batb": [[1, 3.35, 8.96], [2, 3.3, 4.48]], "batl": [[1, 3.7, 40.54], [2, 3.75, 20.26]]}, {"timestamp": 1631547558478, "ltp": 3.9, "tv": 3365.93, "trd": NaN, "batb": NaN, "batl": [[1, 3.7, 8.1], [2, 3.75, 4.06]]}, {"timestamp": 1631547561508, "ltp": 3.35, "tv": 3399.99, "trd": [[3.35, 17.58], [3.4, 16.48]], "batb": [[0, 3.3, 4.65], [1, 3.25, 4.48], [2, 3.15, 63.5]], "batl": NaN}, {"timestamp": 1631547571601, "ltp": 3.35, "tv": 3399.99, "trd": NaN, "batb": NaN, "batl": [[0, 3.55, 64.93]]}, {"timestamp": 1631547574627, "ltp": 3.35, "tv": 3399.99, "trd": NaN, "batb": [[0, 3.35, 5.5], [1, 3.3, 4.48], [2, 3.25, 4.48]], "batl": [[0, 3.5, 5.01], [1, 3.55, 64.93], [2, 3.7, 8.1]]}, {"timestamp": 1631547584651, "ltp": 3.35, "tv": 3399.99, "trd": NaN, "batb": [[0, 3.3, 2.41], [1, 3.25, 2.24], [2, 3.15, 31.75]], "batl": [[0, 3.7, 4.05], [1, 3.75, 2.03], [2, 3.8, 5.35]]}, {"timestamp": 1631547585019, "ltp": 3.35, "tv": 3399.99, "trd": NaN, "batb": [[0, 2.74, 4.52], [1, 2.62, 21.05], [2, 2, 11.93]], "batl": [[0, 4.3, 2.65], [1, 3.75, 0], [2, 3.8, 0]]}, {"timestamp": 1631547589561, "ltp": 3.35, "tv": 3399.99, "trd": NaN, "batb": NaN, "batl": [[0, 3.55, 157.9], [1, 4.3, 2.65]]}, {"timestamp": 1631547589932, "ltp": 3.35, "tv": 3399.99, "trd": NaN, "batb": NaN, "batl": [[0, 4.3, 2.65], [1, 4.3, 0]]}, {"timestamp": 1631547591644, "ltp": 3.35, "tv": 3399.99, "trd": NaN, "batb": [[0, 2.88, 4.71], [1, 2.74, 4.52], [2, 2.62, 21.05]], "batl": [[0, 3.95, 2.9], [1, 4.3, 2.65]]}, {"timestamp": 1631547592840, "ltp": 3.35, "tv": 3399.99, "trd": NaN, "batb": NaN, "batl": [[2, 4.9, 128.15]]}, {"timestamp": 1631547597270, "ltp": 3.35, "tv": 3399.99, "trd": NaN, "batb": [[0, 2.74, 4.52], [1, 2.62, 21.05], [2, 2, 11.93]], "batl": [[0, 4.3, 2.65], [1, 4.9, 128.15], [2, 4.9, 0]]}, {"timestamp": 1631547600671, "ltp": 3.35, "tv": 3399.99, "trd": NaN, "batb": [[0, 2.88, 3.96], [1, 2.74, 4.52], [2, 2.62, 21.05]], "batl": [[0, 3.95, 2.9], [1, 4.3, 2.65], [2, 4.9, 128.15]]}, {"timestamp": 1631547601567, "ltp": 3.35, "tv": 3399.99, "trd": NaN, "batb": [[0, 2.74, 4.52], [1, 2.62, 21.05], [2, 2, 11.93]], "batl": [[0, 4.3, 2.65], [1, 4.9, 128.15], [2, 4.9, 0]]}, {"timestamp": 1631547607645, "ltp": 3.35, "tv": 3399.99, "trd": NaN, "batb": [[0, 2.88, 5.21], [1, 2.74, 4.52], [2, 2.62, 21.05]], "batl": [[0, 3.95, 3.1], [1, 4.3, 2.65], [2, 4.9, 128.15]]}, {"timestamp": 1631547607855, "ltp": 3.35, "tv": 3399.99, "trd": NaN, "batb": [[0, 2.74, 4.52], [1, 2.62, 21.05], [2, 2, 11.93]], "batl": [[0, 4.3, 2.65], [1, 4.9, 128.15], [2, 4.9, 0]]}, {"timestamp": 1631547612580, "ltp": 3.35, "tv": 3399.99, "trd": NaN, "batb": NaN, "batl": [[1, 4.9, 0]]}, {"timestamp": 1631547614674, "ltp": 3.35, "tv": 3399.99, "trd": NaN, "batb": [[0, 3.75, 5.37], [1, 3.65, 63.02], [2, 3.6, 4.12]], "batl": [[0, 3.9, 6.51], [1, 4, 60.06], [2, 4.1, 36.6]]}, {"timestamp": 1631547615149, "ltp": 3.35, "tv": 3399.99, "trd": NaN, "batb": NaN, "batl": [[2, 4.1, 7.32]]}, {"timestamp": 1631547627722, "ltp": 3.9, "tv": 3406.5, "trd": [[3.9, 13.06]], "batb": NaN, "batl": [[0, 4, 60.06], [1, 4.1, 7.32], [2, 4.2, 3.66]]}, {"timestamp": 1631547637530, "ltp": 3.9, "tv": 3406.5, "trd": NaN, "batb": [[0, 3.4, 29.45], [1, 3.3, 3.98], [2, 3.25, 3.77]], "batl": [[0, 4.3, 2.65], [1, 4.4, 2.39], [2, 4.5, 2.67]]}, {"timestamp": 1631547638000, "ltp": 3.9, "tv": 3406.5, "trd": NaN, "batb": [[0, 3.3, 3.98], [1, 3, 36.24], [2, 2.52, 387.12]], "batl": [[0, 4.5, 2.67], [1, 6, 107.75], [2, 4.5, 0]]}, {"timestamp": 1631547642013, "ltp": 3.9, "tv": 3406.5, "trd": NaN, "batb": NaN, "batl": [[1, 6, 0]]}, {"timestamp": 1631547644826, "ltp": 3.9, "tv": 3406.5, "trd": NaN, "batb": [[0, 3.4, 3.81], [1, 3.3, 3.98], [2, 3, 36.24]], "batl": [[0, 4.3, 2.45], [1, 4.5, 2.67]]}, {"timestamp": 1631547646436, "ltp": 3.9, "tv": 3406.5, "trd": NaN, "batb": NaN, "batl": [[2, 5.5, 116.76]]}, {"timestamp": 1631547650137, "ltp": 3.9, "tv": 3406.5, "trd": NaN, "batb": [[0, 3.3, 3.98], [1, 3, 36.24], [2, 2.52, 387.12]], "batl": [[0, 4.5, 2.67], [1, 5.5, 116.76], [2, 5.5, 0]]}, {"timestamp": 1631547655625, "ltp": 3.9, "tv": 3406.5, "trd": NaN, "batb": NaN, "batl": [[1, 5.5, 0]]}, {"timestamp": 1631547657641, "ltp": 3.9, "tv": 3406.5, "trd": NaN, "batb": [[0, 3.35, 7.6], [1, 3.3, 3.98], [2, 3.15, 73.74]], "batl": [[0, 3.5, 3.99], [1, 4, 309.03], [2, 4.5, 2.67]]}, {"timestamp": 1631547662537, "ltp": 3.35, "tv": 3419.08, "trd": [[3.35, 30.16]], "batb": [[0, 3.35, 1.31]], "batl": NaN}, {"timestamp": 1631547664233, "ltp": 3.35, "tv": 3419.08, "trd": NaN, "batb": NaN, "batl": [[1, 3.9, 2.95], [2, 4, 309.03]]}, {"timestamp": 1631547672735, "ltp": 3.35, "tv": 3419.08, "trd": NaN, "batb": [[0, 3.3, 3.98], [1, 3.15, 73.74], [2, 3, 36.24]], "batl": [[0, 3.9, 2.95], [1, 4, 309.03], [2, 4.1, 2.85]]}, {"timestamp": 1631547675636, "ltp": 3.35, "tv": 3419.08, "trd": NaN, "batb": [[0, 3.3, 10.84]], "batl": NaN}, {"timestamp": 1631547682135, "ltp": 3.35, "tv": 3419.08, "trd": NaN, "batb": [[0, 2.72, 4.84], [1, 2.58, 21.72], [2, 2.52, 387.12]], "batl": [[0, 4.2, 2.33], [1, 4.5, 2.67], [2, 4.9, 128.15]]}, {"timestamp": 1631547686934, "ltp": 3.35, "tv": 3419.08, "trd": NaN, "batb": NaN, "batl": [[2, 4.9, 0]]}, {"timestamp": 1631547688551, "ltp": 3.35, "tv": 3419.08, "trd": NaN, "batb": NaN, "batl": [[0, 3.85, 6.36], [1, 4.2, 2.33], [2, 4.5, 2.67]]}, {"timestamp": 1631547689484, "ltp": 3.35, "tv": 3419.08, "trd": NaN, "batb": [[0, 3.35, 27.26], [1, 2.94, 38], [2, 2.72, 4.84]], "batl": [[1, 4, 7.5], [2, 4.1, 3.76]]}, {"timestamp": 1631547693175, "ltp": 3.75, "tv": 3428.83, "trd": [[3.75, 9.75]], "batb": NaN, "batl": NaN}, {"timestamp": 1631547695152, "ltp": 3.75, "tv": 3428.83, "trd": NaN, "batb": [[0, 3.35, 30.93], [1, 3.25, 3.93], [2, 2.94, 38]], "batl": NaN}, {"timestamp": 1631547710388, "ltp": 3.75, "tv": 3428.83, "trd": NaN, "batb": [[0, 3.25, 3.93], [1, 2.94, 38], [2, 2.52, 387.12]], "batl": [[0, 4.4, 2.34], [1, 4.5, 2.67], [2, 5.5, 116.76]]}, {"timestamp": 1631547710705, "ltp": 3.75, "tv": 3428.83, "trd": NaN, "batb": NaN, "batl": [[1, 5.5, 116.76], [2, 5.5, 0]]}, {"timestamp": 1631547713575, "ltp": 3.75, "tv": 3428.83, "trd": NaN, "batb": [[0, 3.35, 3.47], [1, 3.25, 3.93], [2, 2.94, 38]], "batl": [[0, 4.2, 2.63], [1, 4.4, 2.34], [2, 5.5, 116.76]]}, {"timestamp": 1631547713884, "ltp": 3.75, "tv": 3428.83, "trd": NaN, "batb": [[0, 3.25, 3.93], [1, 2.94, 38], [2, 2.52, 387.12]], "batl": [[0, 4.4, 2.34], [1, 5.5, 116.76], [2, 5.5, 0]]}, {"timestamp": 1631547715602, "ltp": 3.75, "tv": 3428.83, "trd": NaN, "batb": NaN, "batl": [[0, 3.9, 19.65], [1, 3.95, 146.82], [2, 4.4, 2.34]]}, {"timestamp": 1631547715903, "ltp": 3.75, "tv": 3428.83, "trd": NaN, "batb": NaN, "batl": [[0, 4.4, 2.34], [1, 5.5, 116.76], [2, 4.4, 0]]}, {"timestamp": 1631547717106, "ltp": 3.75, "tv": 3428.83, "trd": NaN, "batb": [[0, 3.35, 3.67], [1, 3.25, 3.93], [2, 2.94, 38]], "batl": [[0, 4.2, 2.63], [1, 4.4, 2.34], [2, 5.5, 116.76]]}, {"timestamp": 1631547722515, "ltp": 3.75, "tv": 3428.83, "trd": NaN, "batb": [[0, 3.25, 3.93], [1, 2.94, 38], [2, 2.52, 387.12]], "batl": [[0, 4.4, 2.34], [1, 5.5, 116.76], [2, 5.5, 0]]}, {"timestamp": 1631547725785, "ltp": 3.75, "tv": 3428.83, "trd": NaN, "batb": [[0, 3.35, 4.27], [1, 3.25, 3.93], [2, 2.94, 38]], "batl": [[0, 4.2, 2.78], [1, 4.4, 2.34], [2, 5.5, 116.76]]}, {"timestamp": 1631547726884, "ltp": 3.75, "tv": 3428.83, "trd": NaN, "batb": [[0, 3.25, 3.93], [1, 2.94, 38], [2, 2.52, 387.12]], "batl": [[0, 4.4, 2.34], [1, 4.4, 0], [2, 5.5, 0]]}, {"timestamp": 1631547728602, "ltp": 3.75, "tv": 3428.83, "trd": NaN, "batb": [[0, 3.25, 10.97], [1, 3.1, 77.95], [2, 2.94, 38]], "batl": [[0, 3.5, 48.79], [1, 4.4, 2.34]]}, {"timestamp": 1631547730111, "ltp": 3.75, "tv": 3428.83, "trd": NaN, "batb": NaN, "batl": [[2, 4.9, 128.15]]}, {"timestamp": 1631547733598, "ltp": 3.25, "tv": 3451.97, "trd": [[3.25, 23.14]], "batb": [[0, 3.1, 77.95], [1, 2.94, 38], [2, 2.56, 22.23]], "batl": NaN}, {"timestamp": 1631547734793, "ltp": 3.25, "tv": 3451.97, "trd": NaN, "batb": [[2, 2.8, 4.43]], "batl": [[1, 3.9, 2.75], [2, 4.2, 2.93]]}, {"timestamp": 1631547746246, "ltp": 3.25, "tv": 3451.97, "trd": NaN, "batb": [[0, 3.2, 5.92], [1, 3.1, 77.95], [2, 2.94, 38]], "batl": [[0, 3.3, 5.66], [1, 3.5, 48.79], [2, 3.9, 2.75]]}, {"timestamp": 1631547754649, "ltp": 3.25, "tv": 3451.97, "trd": NaN, "batb": [[0, 2.94, 38], [1, 2.68, 5.11], [2, 2.66, 5.28]], "batl": [[0, 3.9, 2.75], [1, 4.2, 2.93], [2, 4.4, 2.34]]}, {"timestamp": 1631547755061, "ltp": 3.25, "tv": 3451.97, "trd": NaN, "batb": [[0, 2.66, 5.28], [1, 2.56, 22.23], [2, 2.52, 387.12]], "batl": [[0, 4.2, 2.93], [1, 4.4, 2.34], [2, 4.9, 128.15]]}, {"timestamp": 1631547757654, "ltp": 3.25, "tv": 3451.97, "trd": NaN, "batb": [[0, 2.74, 4.79], [1, 2.66, 5.28], [2, 2.62, 5.04]], "batl": NaN}, {"timestamp": 1631547758550, "ltp": 3.25, "tv": 3451.97, "trd": NaN, "batb": [[0, 2.66, 5.28], [1, 2.62, 5.04], [2, 2.56, 22.23]], "batl": NaN}, {"timestamp": 1631547764661, "ltp": 3.25, "tv": 3451.97, "trd": NaN, "batb": [[0, 2.78, 4.66], [1, 2.66, 5.28], [2, 2.62, 5.04]], "batl": [[2, 4.9, 0]]}, {"timestamp": 1631547765661, "ltp": 3.25, "tv": 3451.97, "trd": NaN, "batb": [[0, 2.66, 5.28], [1, 2.62, 5.04], [2, 2.56, 22.23]], "batl": [[0, 2.84, 11.49], [1, 2.92, 1130.1], [2, 2.94, 25.68]]}, {"timestamp": 1631547766657, "ltp": 3.25, "tv": 3451.97, "trd": NaN, "batb": NaN, "batl": [[1, 2.9, 2], [2, 2.92, 10.28]]}, {"timestamp": 1631547793620, "ltp": 3.25, "tv": 3451.97, "trd": NaN, "batb": [[0, 2.56, 22.23], [1, 2.24, 6.27], [2, 2.14, 43.56]], "batl": [[0, 3.45, 3.7], [1, 3.8, 3.02], [2, 3.9, 160.59]]}, {"timestamp": 1631547794309, "ltp": 3.25, "tv": 3451.97, "trd": NaN, "batb": [[0, 2.14, 43.56], [1, 2.04, 399.94], [2, 1.9, 16.76]], "batl": NaN}, {"timestamp": 1631547797000, "ltp": 3.25, "tv": 3451.97, "trd": NaN, "batb": [[0, 2.16, 7.78], [1, 2.14, 43.56], [2, 2.04, 399.94]], "batl": [[0, 3.8, 3.02], [1, 3.9, 160.59], [2, 4.2, 2.93]]}, {"timestamp": 1631547799627, "ltp": 3.25, "tv": 3451.97, "trd": NaN, "batb": NaN, "batl": [[0, 2.8, 18.67], [1, 3.8, 3.02], [2, 3.9, 160.59]]}, {"timestamp": 1631547800203, "ltp": 3.25, "tv": 3451.97, "trd": NaN, "batb": [[0, 2.28, 6.66], [1, 2.16, 7.78], [2, 2.14, 43.56]], "batl": [[0, 3.45, 3.9]]}, {"timestamp": 1631547807528, "ltp": 3.25, "tv": 3451.97, "trd": NaN, "batb": [[0, 2.16, 7.78], [1, 2.14, 43.56], [2, 2.04, 399.94]], "batl": [[0, 3.25, 4.8], [1, 3.45, 3.9], [2, 3.8, 3.02]]}, {"timestamp": 1631547808526, "ltp": 3.25, "tv": 3451.97, "trd": NaN, "batb": NaN, "batl": [[1, 3.8, 3.02], [2, 3.9, 160.59]]}, {"timestamp": 1631547811740, "ltp": 3.25, "tv": 3451.97, "trd": NaN, "batb": NaN, "batl": [[1, 3.45, 3.5], [2, 3.8, 3.02]]}, {"timestamp": 1631547820636, "ltp": 3.25, "tv": 3451.97, "trd": NaN, "batb": [[0, 2.28, 6.41], [1, 2.16, 7.78], [2, 2.14, 43.56]], "batl": [[1, 3.8, 3.02], [2, 3.9, 160.59]]}, {"timestamp": 1631547821155, "ltp": 3.25, "tv": 3451.97, "trd": NaN, "batb": [[0, 2.16, 7.78], [1, 2.14, 43.56], [2, 1.9, 16.76]], "batl": [[2, 3.9, 0]]}, {"timestamp": 1631547822655, "ltp": 3.25, "tv": 3451.97, "trd": NaN, "batb": NaN, "batl": [[0, 2.32, 1304.64], [1, 2.38, 63.04], [2, 2.4, 31.52]]}, {"timestamp": 1631547823556, "ltp": 3.25, "tv": 3451.97, "trd": NaN, "batb": [[0, 2.24, 66.96], [1, 2.22, 33.48], [2, 2.2, 33.48]], "batl": [[0, 2.38, 37.82], [1, 2.4, 18.91], [2, 2.42, 139.6]]}, {"timestamp": 1631547824132, "ltp": 3.25, "tv": 3451.97, "trd": NaN, "batb": [[0, 2.24, 13.4], [1, 2.22, 6.7], [2, 2.2, 6.7]], "batl": NaN}, {"timestamp": 1631547827528, "ltp": 3.25, "tv": 3451.97, "trd": NaN, "batb": NaN, "batl": [[0, 2.26, 6.9], [1, 2.38, 37.82], [2, 2.4, 18.91]]}, {"timestamp": 1631547827738, "ltp": 3.25, "tv": 3451.97, "trd": NaN, "batb": NaN, "batl": [[0, 2.38, 37.82], [1, 2.4, 18.91], [2, 2.42, 139.6]]}, {"timestamp": 1631547831541, "ltp": 3.25, "tv": 3451.97, "trd": NaN, "batb": [[0, 2.26, 6.77], [1, 2.24, 13.4], [2, 2.22, 6.7]], "batl": NaN}, {"timestamp": 1631547854903, "ltp": 2.26, "tv": 3455.97, "trd": [[2.26, 40.54]], "batb": [[0, 2.26, 4.77]], "batl": NaN}, {"timestamp": 1631547859705, "ltp": 2.26, "tv": 3455.97, "trd": NaN, "batb": [[0, 2.28, 18.77], [1, 2.26, 4.77], [2, 2.24, 13.4]], "batl": NaN}, {"timestamp": 1631547865917, "ltp": 2.28, "tv": 3467.02, "trd": [[2.28, 11.04]], "batb": [[0, 2.28, 13.25]], "batl": NaN}, {"timestamp": 1631547923271, "ltp": 2.28, "tv": 3467.02, "trd": NaN, "batb": [[2, 2.16, 7.78]], "batl": [[0, 2.94, 4.25], [1, 3.25, 4.8], [2, 2.42, 0]]}, {"timestamp": 1631547926589, "ltp": 2.28, "tv": 3467.02, "trd": NaN, "batb": NaN, "batl": [[0, 2.74, 5.25], [1, 2.94, 4.25], [2, 3.25, 4.8]]}, {"timestamp": 1631547930160, "ltp": 2.28, "tv": 3467.02, "trd": NaN, "batb": [[2, 2.2, 6.72]], "batl": NaN}, {"timestamp": 1631547930899, "ltp": 2.28, "tv": 3467.02, "trd": NaN, "batb": [[2, 2.16, 7.78]], "batl": NaN}, {"timestamp": 1631547933170, "ltp": 2.28, "tv": 3467.02, "trd": NaN, "batb": [[1, 2.16, 7.78], [2, 2, 60.53]], "batl": NaN}, {"timestamp": 1631547935386, "ltp": 2.28, "tv": 3467.02, "trd": NaN, "batb": [[0, 2.3, 6.56], [1, 2.28, 13.25], [2, 2.16, 7.78]], "batl": NaN}, {"timestamp": 1631547940610, "ltp": 2.28, "tv": 3467.02, "trd": NaN, "batb": [[0, 2.5, 36], [1, 2.48, 18], [2, 2.46, 18]], "batl": [[0, 2.6, 6.52], [1, 2.66, 95.83], [2, 2.74, 5.25]]}, {"timestamp": 1631547941618, "ltp": 2.28, "tv": 3467.02, "trd": NaN, "batb": NaN, "batl": [[2, 2.68, 11.2]]}, {"timestamp": 1631547950512, "ltp": 2.28, "tv": 3467.02, "trd": NaN, "batb": [[0, 2.32, 6.39], [1, 2.18, 35.15], [2, 2.04, 399.94]], "batl": [[0, 3.25, 4.8], [1, 3.3, 3.25], [2, 3.9, 160.59]]}, {"timestamp": 1631547954128, "ltp": 2.28, "tv": 3467.02, "trd": NaN, "batb": NaN, "batl": [[2, 3.9, 0]]}, {"timestamp": 1631547956124, "ltp": 2.28, "tv": 3467.02, "trd": NaN, "batb": [[0, 2.32, 19.96]], "batl": [[0, 2.4, 7.39], [1, 2.44, 2], [2, 3.25, 4.8]]}, {"timestamp": 1631547961125, "ltp": 2.32, "tv": 3478.08, "trd": [[2.32, 26.58]], "batb": [[0, 2.32, 14.43]], "batl": NaN}, {"timestamp": 1631547962301, "ltp": 2.32, "tv": 3478.08, "trd": NaN, "batb": [[1, 2.2, 7.22], [2, 2.18, 35.15]], "batl": [[2, 2.74, 4.98]]}, {"timestamp": 1631547965616, "ltp": 2.32, "tv": 3478.08, "trd": NaN, "batb": [[0, 2.16, 7.78], [1, 2.04, 399.94], [2, 2, 60.11]], "batl": [[0, 2.74, 4.98], [1, 2.9, 4.55], [2, 3.25, 4.8]]}, {"timestamp": 1631547965826, "ltp": 2.32, "tv": 3478.08, "trd": NaN, "batb": NaN, "batl": [[0, 2.9, 4.55], [1, 3.25, 4.8], [2, 3.45, 183.07]]}, {"timestamp": 1631547972540, "ltp": 2.32, "tv": 3478.08, "trd": NaN, "batb": [[0, 2.2, 7.17], [1, 2.16, 7.78]], "batl": [[0, 2.74, 4.75], [1, 2.9, 4.55], [2, 3.25, 4.8]]}, {"timestamp": 1631547973646, "ltp": 2.32, "tv": 3478.08, "trd": NaN, "batb": [[0, 2.16, 7.78], [1, 2, 60.11], [2, 1.7, 17.05]], "batl": [[0, 2.24, 79.24], [1, 2.26, 33.48], [2, 2.28, 154.72]]}, {"timestamp": 1631547974649, "ltp": 2.32, "tv": 3478.08, "trd": NaN, "batb": [[2, 1.9, 26.67]], "batl": [[0, 2.24, 25.68], [1, 2.26, 6.7], [2, 2.28, 127.94]]}, {"timestamp": 1631547980665, "ltp": 2.32, "tv": 3478.08, "trd": NaN, "batb": [[1, 2.08, 7.06], [2, 2.04, 8.12]], "batl": NaN}, {"timestamp": 1631547981664, "ltp": 2.32, "tv": 3478.08, "trd": NaN, "batb": NaN, "batl": [[0, 2.24, 2.73], [1, 2.4, 6.24], [2, 2.48, 6.49]]}, {"timestamp": 1631547982074, "ltp": 2.32, "tv": 3478.08, "trd": NaN, "batb": [[0, 2, 15.91], [1, 1.9, 26.67], [2, 1.82, 407.19]], "batl": [[0, 2.48, 6.49], [1, 3.15, 203.39], [2, 3.25, 4.8]]}, {"timestamp": 1631547985462, "ltp": 2.32, "tv": 3478.08, "trd": NaN, "batb": [[0, 2.04, 7.62], [1, 2, 15.91], [2, 1.9, 26.67]], "batl": NaN}, {"timestamp": 1631547987473, "ltp": 2.32, "tv": 3478.08, "trd": NaN, "batb": [[0, 2.1, 21.66], [1, 2.04, 7.62], [2, 2, 15.91]], "batl": NaN}, {"timestamp": 1631547988660, "ltp": 2.32, "tv": 3478.08, "trd": NaN, "batb": [[1, 2.08, 8.31], [2, 2.04, 7.62]], "batl": [[0, 2.4, 6.49], [1, 2.48, 6.49], [2, 3.15, 203.39]]}, {"timestamp": 1631547988973, "ltp": 2.32, "tv": 3478.08, "trd": NaN, "batb": [[1, 2.04, 7.62], [2, 2, 15.91]], "batl": [[0, 2.48, 6.49], [1, 3.15, 203.39], [2, 3.25, 4.8]]}, {"timestamp": 1631547996484, "ltp": 2.04, "tv": 3551.36, "trd": [[2.04, 41.02], [2.1, 43.32]], "batb": [[0, 2, 15.91], [1, 1.9, 26.67], [2, 1.6, 99.43]], "batl": [[1, 3.25, 4.8], [2, 3.25, 0]]}, {"timestamp": 1631547997662, "ltp": 2.04, "tv": 3551.36, "trd": NaN, "batb": [[0, 2, 69.1]], "batl": [[0, 2.08, 96.16], [1, 2.12, 12.33], [2, 2.16, 1539.3]]}, {"timestamp": 1631547998595, "ltp": 2.04, "tv": 3551.36, "trd": NaN, "batb": [[2, 1.4, 149.15]], "batl": [[0, 2.08, 19.24], [2, 2.16, 137.46]]}, {"timestamp": 1631547999658, "ltp": 2.04, "tv": 3551.36, "trd": NaN, "batb": [[2, 1.82, 30.2]], "batl": NaN}, {"timestamp": 1631548001384, "ltp": 2.08, "tv": 3598.5, "trd": [[2.08, 47.14]], "batb": NaN, "batl": [[0, 2.12, 12.33], [1, 2.16, 137.46], [2, 2.48, 6.49]]}, {"timestamp": 1631548002599, "ltp": 2.04, "tv": 3621.85, "trd": [[2.04, 45.31], [2.08, 66.2]], "batb": NaN, "batl": NaN}, {"timestamp": 1631548004484, "ltp": 2.04, "tv": 3621.85, "trd": NaN, "batb": [[0, 2, 92.68], [1, 1.99, 26.51], [2, 1.9, 26.67]], "batl": [[2, 2.18, 6.75]]}, {"timestamp": 1631548006290, "ltp": 2.04, "tv": 3621.85, "trd": NaN, "batb": [[0, 2, 15.91], [1, 1.82, 30.2], [2, 1.4, 149.15]], "batl": [[0, 3.25, 4.8], [1, 2.16, 0], [2, 2.18, 0]]}, {"timestamp": 1631548009478, "ltp": 2.04, "tv": 3621.85, "trd": NaN, "batb": [[0, 2, 38.94], [1, 1.99, 26.51], [2, 1.82, 30.2]], "batl": [[0, 2.18, 7.25], [1, 2.22, 6.75], [2, 3.25, 4.8]]}, {"timestamp": 1631548009793, "ltp": 2.04, "tv": 3621.85, "trd": NaN, "batb": [[0, 2, 15.91]], "batl": [[0, 2.22, 6.75], [1, 3.25, 4.8], [2, 3.25, 0]]}, {"timestamp": 1631548016502, "ltp": 2.04, "tv": 3621.85, "trd": NaN, "batb": [[0, 2, 39.49]], "batl": [[0, 2.18, 7.25], [1, 2.22, 6.75], [2, 3.25, 4.8]]}, {"timestamp": 1631548016976, "ltp": 2.04, "tv": 3621.85, "trd": NaN, "batb": [[0, 2, 15.91]], "batl": [[0, 2.22, 6.75], [1, 3.25, 4.8], [2, 3.25, 0]]}, {"timestamp": 1631548021409, "ltp": 1.99, "tv": 3706.69, "trd": [[1.99, 53.02], [2, 46.23]], "batb": [[0, 1.92, 54.06], [1, 1.9, 80.32]], "batl": [[0, 1.99, 42.8], [1, 2.02, 184.94], [2, 2.04, 37.14]]}, {"timestamp": 1631548022627, "ltp": 1.99, "tv": 3706.69, "trd": NaN, "batb": [[1, 1.91, 15.7], [2, 1.9, 88.18]], "batl": [[1, 2.02, 125.54], [2, 2.04, 7.42]]}, {"timestamp": 1631548025230, "ltp": 1.99, "tv": 3706.69, "trd": NaN, "batb": [[0, 1.92, 78.43]], "batl": [[0, 1.99, 61.74]]}, {"timestamp": 1631548030411, "ltp": 2.02, "tv": 3854.08, "trd": [[1.99, 114.76], [2.02, 121.01]], "batb": [[2, 1.9, 7.86]], "batl": [[0, 2.02, 39.89], [1, 2.04, 7.42], [2, 2.06, 14.67]]}, {"timestamp": 1631548030933, "ltp": 1.98, "tv": 3856.37, "trd": [[1.98, 123.25]], "batb": NaN, "batl": NaN}, {"timestamp": 1631548033451, "ltp": 1.98, "tv": 3856.37, "trd": NaN, "batb": [[0, 1.94, 71.7], [1, 1.92, 78.43], [2, 1.91, 15.7]], "batl": [[0, 2.02, 95.08], [1, 2.04, 73.39]]}, {"timestamp": 1631548043254, "ltp": 1.98, "tv": 3856.37, "trd": NaN, "batb": NaN, "batl": [[1, 2.04, 84]]}, {"timestamp": 1631548048420, "ltp": 1.98, "tv": 3856.37, "trd": NaN, "batb": NaN, "batl": [[1, 2.04, 73.39]]}, {"timestamp": 1631548051356, "ltp": 1.98, "tv": 3856.37, "trd": NaN, "batb": NaN, "batl": [[1, 2.04, 84]]}, {"timestamp": 1631548052573, "ltp": 1.98, "tv": 3856.37, "trd": NaN, "batb": [[2, 1.82, 30.2]], "batl": [[1, 2.04, 65.97], [2, 2.06, 7.25]]}, {"timestamp": 1631548053364, "ltp": 1.98, "tv": 3856.37, "trd": NaN, "batb": [[0, 1.67, 456.69], [1, 1.4, 149.15], [2, 1.3, 198.84]], "batl": [[0, 2.24, 6.43], [1, 3.25, 4.8], [2, 2.06, 0]]}, {"timestamp": 1631548056467, "ltp": 1.98, "tv": 3856.37, "trd": NaN, "batb": [[0, 1.76, 93.35], [1, 1.74, 141.42], [2, 1.67, 456.69]], "batl": [[0, 2.16, 51.45], [1, 2.18, 62.77], [2, 2.24, 6.23]]}, {"timestamp": 1631548057259, "ltp": 1.94, "tv": 3856.77, "trd": [[1.94, 5.92]], "batb": [[0, 1.96, 35.9], [1, 1.76, 93.35], [2, 1.74, 141.42]], "batl": [[0, 2.16, 51.25], [1, 2.18, 54.52]]}, {"timestamp": 1631548058063, "ltp": 1.94, "tv": 3856.77, "trd": NaN, "batb": [[1, 1.74, 34.52], [2, 1.67, 456.69]], "batl": [[0, 2.24, 6.23], [1, 3.25, 4.8], [2, 2.24, 0]]}, {"timestamp": 1631548059443, "ltp": 1.94, "tv": 3856.77, "trd": NaN, "batb": [[1, 1.8, 27.78], [2, 1.74, 34.52]], "batl": NaN}, {"timestamp": 1631548060651, "ltp": 1.94, "tv": 3856.77, "trd": NaN, "batb": [[0, 1.74, 34.52], [1, 1.67, 40.85], [2, 1.4, 149.15]], "batl": NaN}, {"timestamp": 1631548062566, "ltp": 1.94, "tv": 3856.77, "trd": NaN, "batb": [[0, 1.95, 48.9], [1, 1.8, 31.62], [2, 1.74, 444.8]], "batl": NaN}, {"timestamp": 1631548067560, "ltp": 1.94, "tv": 3856.77, "trd": NaN, "batb": [[0, 1.99, 22.51], [1, 1.95, 65.34], [2, 1.93, 25.93]], "batl": [[1, 2.28, 6.84], [2, 2.32, 7.11]]}, {"timestamp": 1631548070471, "ltp": 2.12, "tv": 3856.86, "trd": [[2.12, 23.47]], "batb": NaN, "batl": NaN}, {"timestamp": 1631548080662, "ltp": 2.12, "tv": 3856.86, "trd": NaN, "batb": [[0, 1.95, 48.9], [1, 1.8, 31.62], [2, 1.74, 410.28]], "batl": [[0, 2.28, 6.84], [1, 2.32, 7.11], [2, 3.25, 4.8]]}, {"timestamp": 1631548080977, "ltp": 2.12, "tv": 3856.86, "trd": NaN, "batb": [[0, 1.8, 31.62], [1, 1.74, 410.28], [2, 1.4, 149.15]], "batl": [[0, 2.32, 7.11], [1, 3.25, 4.8], [2, 3.25, 0]]}, {"timestamp": 1631548084355, "ltp": 2.12, "tv": 3856.86, "trd": NaN, "batb": [[0, 1.93, 29.93], [1, 1.8, 31.62], [2, 1.74, 410.28]], "batl": NaN}, {"timestamp": 1631548086384, "ltp": 2.12, "tv": 3856.86, "trd": NaN, "batb": NaN, "batl": [[0, 2.14, 20.75], [1, 2.32, 7.11], [2, 3.25, 4.8]]}, {"timestamp": 1631548087666, "ltp": 2.12, "tv": 3856.86, "trd": NaN, "batb": NaN, "batl": [[0, 2.28, 7.34]]}, {"timestamp": 1631548097582, "ltp": 2.12, "tv": 3856.86, "trd": NaN, "batb": [[0, 1.99, 22.51], [1, 1.93, 29.93], [2, 1.8, 31.62]], "batl": NaN}, {"timestamp": 1631548098624, "ltp": 2.12, "tv": 3856.86, "trd": NaN, "batb": [[0, 1.94, 28.88]], "batl": NaN}, {"timestamp": 1631548104634, "ltp": 2.12, "tv": 3856.86, "trd": NaN, "batb": [[0, 1.99, 23.51], [1, 1.94, 28.88], [2, 1.93, 29.93]], "batl": NaN}, {"timestamp": 1631548104903, "ltp": 2.12, "tv": 3856.86, "trd": NaN, "batb": [[0, 1.94, 28.88], [1, 1.93, 29.93], [2, 1.8, 31.62]], "batl": NaN}, {"timestamp": 1631548109345, "ltp": 2.12, "tv": 3856.86, "trd": NaN, "batb": [[2, 1.9, 94.84]], "batl": [[0, 1.97, 52.81], [1, 1.99, 71], [2, 2, 19.28]]}, {"timestamp": 1631548110305, "ltp": 2.12, "tv": 3856.86, "trd": NaN, "batb": [[2, 1.9, 110.64]], "batl": NaN}, {"timestamp": 1631548113519, "ltp": 1.97, "tv": 3873.12, "trd": [[1.97, 16.26]], "batb": [[2, 1.9, 15.8]], "batl": [[0, 2, 19.28], [1, 2.2, 437.07], [2, 2.28, 7.34]]}, {"timestamp": 1631548115645, "ltp": 1.97, "tv": 3873.12, "trd": NaN, "batb": NaN, "batl": [[1, 2.14, 7.75], [2, 2.2, 445.1]]}, {"timestamp": 1631548116452, "ltp": 1.97, "tv": 3873.12, "trd": NaN, "batb": [[2, 1.91, 63.46]], "batl": [[0, 1.98, 79.47], [1, 2, 89.2], [2, 2.14, 7.75]]}, {"timestamp": 1631548117255, "ltp": 1.98, "tv": 3904.55, "trd": [[1.98, 154.68]], "batb": NaN, "batl": [[0, 1.98, 63.71]]}, {"timestamp": 1631548120135, "ltp": 1.98, "tv": 3904.55, "trd": NaN, "batb": [[2, 1.91, 72.44]], "batl": [[0, 1.98, 70.72]]}, {"timestamp": 1631548126955, "ltp": 1.98, "tv": 3906.29, "trd": [[1.98, 156.42]], "batb": NaN, "batl": [[0, 1.98, 68.98]]}, {"timestamp": 1631548131652, "ltp": 1.98, "tv": 3906.29, "trd": NaN, "batb": [[1, 1.91, 72.44], [2, 1.89, 81.63]], "batl": [[1, 2, 69.92]]}, {"timestamp": 1631548132434, "ltp": 1.98, "tv": 3906.29, "trd": NaN, "batb": [[0, 1.94, 28.97], [1, 1.74, 410.28], [2, 1.63, 44.37]], "batl": [[0, 2.2, 8.03], [1, 3.25, 4.8], [2, 2.14, 0]]}, {"timestamp": 1631548135375, "ltp": 1.98, "tv": 3906.29, "trd": NaN, "batb": [[2, 1.71, 85.3]], "batl": [[0, 2.16, 71.47], [1, 2.18, 54.54], [2, 2.2, 8.03]]}, {"timestamp": 1631548138662, "ltp": 1.98, "tv": 3906.29, "trd": NaN, "batb": NaN, "batl": [[0, 2.14, 6.75], [1, 2.16, 71.47], [2, 2.18, 54.54]]}, {"timestamp": 1631548139496, "ltp": 1.98, "tv": 3906.29, "trd": NaN, "batb": [[2, 1.63, 44.37]], "batl": [[0, 2.2, 8.03], [1, 3.25, 4.8], [2, 2.18, 0]]}, {"timestamp": 1631548142474, "ltp": 1.98, "tv": 3906.29, "trd": NaN, "batb": NaN, "batl": [[0, 2.16, 11.94], [1, 2.2, 115.81], [2, 3.25, 4.8]]}, {"timestamp": 1631548143578, "ltp": 1.98, "tv": 3906.29, "trd": NaN, "batb": [[0, 1.94, 78.13], [1, 1.78, 32.71], [2, 1.74, 410.28]], "batl": NaN}, {"timestamp": 1631548146570, "ltp": 1.98, "tv": 3906.29, "trd": NaN, "batb": [[0, 1.94, 78.03]], "batl": NaN}, {"timestamp": 1631548149459, "ltp": 1.98, "tv": 3906.29, "trd": NaN, "batb": [[0, 1.95, 24.11], [1, 1.94, 78.03], [2, 1.9, 23.26]], "batl": [[2, 2.26, 6.75]]}, {"timestamp": 1631548152187, "ltp": 2.08, "tv": 3906.38, "trd": [[2.08, 66.3]], "batb": NaN, "batl": NaN}, {"timestamp": 1631548155355, "ltp": 2.08, "tv": 3906.38, "trd": NaN, "batb": [[1, 1.94, 49.15]], "batl": NaN}, {"timestamp": 1631548158506, "ltp": 2.08, "tv": 3906.38, "trd": NaN, "batb": [[0, 1.95, 52.99]], "batl": NaN}, {"timestamp": 1631548162403, "ltp": 2.08, "tv": 3906.38, "trd": NaN, "batb": NaN, "batl": [[0, 2.2, 115.81], [1, 2.26, 6.75], [2, 2.3, 5.95]]}, {"timestamp": 1631548165291, "ltp": 2.08, "tv": 3906.38, "trd": NaN, "batb": NaN, "batl": [[0, 2.16, 12.03], [1, 2.2, 115.81], [2, 2.26, 6.75]]}, {"timestamp": 1631548171507, "ltp": 2.08, "tv": 3906.38, "trd": NaN, "batb": [[0, 1.95, 28.88], [1, 1.9, 23.26], [2, 1.78, 32.71]], "batl": [[0, 2.3, 5.95], [1, 3.25, 4.8], [2, 2.26, 0]]}, {"timestamp": 1631548174503, "ltp": 2.08, "tv": 3906.38, "trd": NaN, "batb": [[0, 1.95, 53.59]], "batl": [[0, 2.26, 7.25], [1, 2.3, 5.95], [2, 3.25, 4.8]]}, {"timestamp": 1631548174812, "ltp": 2.08, "tv": 3906.38, "trd": NaN, "batb": [[0, 1.95, 28.88]], "batl": [[0, 2.3, 5.95], [1, 3.25, 4.8], [2, 3.25, 0]]}, {"timestamp": 1631548181599, "ltp": 2.08, "tv": 3906.38, "trd": NaN, "batb": [[0, 1.95, 55.19]], "batl": [[0, 2.26, 7.25], [1, 2.3, 5.95], [2, 3.25, 4.8]]}, {"timestamp": 1631548181816, "ltp": 2.08, "tv": 3906.38, "trd": NaN, "batb": [[0, 1.95, 28.88]], "batl": [[0, 2.3, 5.95], [1, 3.25, 4.8], [2, 3.25, 0]]}, {"timestamp": 1631548183341, "ltp": 2.08, "tv": 3906.38, "trd": NaN, "batb": [[0, 2.24, 6.01], [1, 1.95, 28.88], [2, 1.9, 23.26]], "batl": NaN}, {"timestamp": 1631548184343, "ltp": 2.08, "tv": 3906.38, "trd": NaN, "batb": [[1, 2.08, 39.51], [2, 1.96, 48.15]], "batl": NaN}, {"timestamp": 1631548186138, "ltp": 2.08, "tv": 3906.38, "trd": NaN, "batb": NaN, "batl": [[1, 3.15, 193.68], [2, 3.25, 4.8]]}, {"timestamp": 1631548189822, "ltp": 2.08, "tv": 3906.38, "trd": NaN, "batb": [[1, 2.14, 6.82], [2, 2.1, 7.14]], "batl": [[1, 2.36, 6.57], [2, 2.4, 6.89]]}, {"timestamp": 1631548205334, "ltp": 2.08, "tv": 3906.38, "trd": NaN, "batb": [[0, 2.14, 6.82], [1, 2.1, 7.14], [2, 2.08, 39.51]], "batl": [[2, 2.38, 5.75]]}, {"timestamp": 1631548209253, "ltp": 2.08, "tv": 3906.38, "trd": NaN, "batb": [[0, 2.1, 7.14], [1, 1.96, 48.15], [2, 1.95, 28.88]], "batl": [[0, 2.42, 5.75], [1, 3.15, 193.68], [2, 3.25, 4.8]]}, {"timestamp": 1631548215846, "ltp": 2.08, "tv": 3906.38, "trd": NaN, "batb": [[0, 2.14, 7.32], [1, 2.1, 7.14], [2, 1.96, 48.15]], "batl": [[0, 2.38, 6.25], [1, 2.42, 5.75], [2, 3.15, 193.68]]}, {"timestamp": 1631548219787, "ltp": 2.08, "tv": 3906.38, "trd": NaN, "batb": [[0, 2.1, 7.14], [1, 1.96, 48.15], [2, 1.95, 28.88]], "batl": NaN}, {"timestamp": 1631548220940, "ltp": 2.08, "tv": 3906.38, "trd": NaN, "batb": NaN, "batl": [[0, 2.42, 5.75], [1, 3.15, 193.68], [2, 3.25, 4.8]]}, {"timestamp": 1631548226495, "ltp": 2.08, "tv": 3906.38, "trd": NaN, "batb": [[0, 2.14, 8.32], [1, 2.1, 7.14], [2, 1.96, 48.15]], "batl": NaN}, {"timestamp": 1631548226755, "ltp": 2.08, "tv": 3906.38, "trd": NaN, "batb": [[0, 2.1, 7.14], [1, 1.96, 48.15], [2, 1.95, 28.88]], "batl": NaN}, {"timestamp": 1631548228586, "ltp": 2.08, "tv": 3906.38, "trd": NaN, "batb": [[0, 2.32, 13.38], [1, 2.1, 7.14], [2, 1.96, 48.15]], "batl": [[0, 2.4, 7.58], [1, 2.42, 91.79], [2, 3.15, 193.68]]}, {"timestamp": 1631548229589, "ltp": 2.08, "tv": 3906.38, "trd": NaN, "batb": [[1, 2.18, 34.56], [2, 2.1, 7.14]], "batl": NaN}, {"timestamp": 1631548234271, "ltp": 2.42, "tv": 3920.09, "trd": [[2.4, 10.55], [2.42, 6.83]], "batb": NaN, "batl": [[0, 2.42, 85.66], [1, 3.15, 193.68], [2, 3.25, 4.8]]}, {"timestamp": 1631548240880, "ltp": 2.42, "tv": 3950.3, "trd": [[2.42, 37.04]], "batb": NaN, "batl": [[0, 2.42, 55.45]]}, {"timestamp": 1631548243877, "ltp": 2.42, "tv": 3950.3, "trd": NaN, "batb": [[0, 2.18, 34.56], [1, 2.1, 7.14], [2, 2.02, 43.03]], "batl": NaN}, {"timestamp": 1631548247183, "ltp": 2.42, "tv": 3950.3, "trd": NaN, "batb": [[0, 2.36, 10.29], [1, 2.18, 34.56], [2, 2.1, 7.14]], "batl": NaN}, {"timestamp": 1631548259329, "ltp": 2.4, "tv": 3954.33, "trd": [[2.4, 14.57]], "batb": NaN, "batl": NaN}, {"timestamp": 1631548267133, "ltp": 2.4, "tv": 3954.33, "trd": NaN, "batb": NaN, "batl": [[0, 2.4, 5.63], [1, 2.42, 55.45], [2, 3.15, 193.68]]}, {"timestamp": 1631548268128, "ltp": 2.4, "tv": 3954.33, "trd": NaN, "batb": [[0, 2.18, 34.56], [1, 2.1, 7.14], [2, 2.02, 43.03]], "batl": NaN}, {"timestamp": 1631548271638, "ltp": 2.4, "tv": 3954.33, "trd": NaN, "batb": [[0, 2.36, 10.31], [1, 2.18, 34.56], [2, 2.1, 7.14]], "batl": [[0, 2.42, 55.45], [1, 3.15, 193.68], [2, 3.25, 4.8]]}, {"timestamp": 1631548274762, "ltp": 2.36, "tv": 3965.59, "trd": [[2.36, 11.26]], "batb": [[0, 2.36, 4.68]], "batl": NaN}, {"timestamp": 1631548284946, "ltp": 2.36, "tv": 3965.59, "trd": NaN, "batb": [[0, 2.18, 34.56], [1, 2.1, 7.14], [2, 2.02, 43.03]], "batl": NaN}, {"timestamp": 1631548288146, "ltp": 2.36, "tv": 3965.59, "trd": NaN, "batb": [[0, 2.2, 13.96], [1, 2.18, 34.56], [2, 2.1, 7.14]], "batl": [[0, 2.42, 65.87]]}, {"timestamp": 1631548295646, "ltp": 2.36, "tv": 3965.59, "trd": NaN, "batb": [[0, 2.3, 6.56], [1, 2.2, 13.96], [2, 2.18, 34.56]], "batl": NaN}, {"timestamp": 1631548295759, "ltp": 2.36, "tv": 3965.59, "trd": NaN, "batb": [[1, 2.18, 34.56], [2, 2.1, 7.14]], "batl": NaN}, {"timestamp": 1631548317667, "ltp": 2.36, "tv": 3965.59, "trd": NaN, "batb": [[1, 2.1, 7.14], [2, 2.02, 43.03]], "batl": [[0, 3.15, 193.68], [1, 3.25, 4.8], [2, 3.25, 0]]}, {"timestamp": 1631548317929, "ltp": 2.36, "tv": 3965.59, "trd": NaN, "batb": [[1, 2.02, 43.03], [2, 1.95, 28.88]], "batl": NaN}, {"timestamp": 1631548319660, "ltp": 2.36, "tv": 3965.59, "trd": NaN, "batb": [[1, 2.16, 7.78], [2, 2.12, 7.79]], "batl": [[0, 2.74, 4.48], [1, 2.9, 4.25], [2, 3.15, 193.68]]}, {"timestamp": 1631548320645, "ltp": 2.36, "tv": 3965.59, "trd": NaN, "batb": [[1, 2.12, 7.79], [2, 2.02, 43.03]], "batl": [[0, 2.9, 4.25], [1, 3.15, 193.68], [2, 3.25, 4.8]]}, {"timestamp": 1631548344415, "ltp": 2.36, "tv": 3965.59, "trd": NaN, "batb": [[1, 2.16, 6.78], [2, 2.12, 7.79]], "batl": [[0, 2.74, 4.98], [1, 2.9, 4.25], [2, 3.15, 193.68]]}, {"timestamp": 1631548344886, "ltp": 2.36, "tv": 3965.59, "trd": NaN, "batb": [[1, 2.12, 7.79], [2, 2.02, 43.03]], "batl": [[0, 2.9, 4.25], [1, 3.15, 193.68], [2, 3.25, 4.8]]}, {"timestamp": 1631548349115, "ltp": 2.36, "tv": 3965.59, "trd": NaN, "batb": NaN, "batl": [[1, 3.25, 4.8], [2, 3.25, 0]]}, {"timestamp": 1631548351415, "ltp": 2.3, "tv": 3982.72, "trd": [[2.3, 21.36], [2.32, 29.3]], "batb": [[0, 2.12, 7.79], [1, 2.02, 43.03], [2, 1.95, 28.88]], "batl": [[0, 2.24, 6.44], [1, 2.26, 42.84], [2, 2.28, 111.23]]}, {"timestamp": 1631548356015, "ltp": 2.16, "tv": 3988.94, "trd": [[2.16, 40.53]], "batb": NaN, "batl": NaN}, {"timestamp": 1631548357805, "ltp": 2.16, "tv": 3988.94, "trd": NaN, "batb": [[1, 2.08, 7.81], [2, 2.04, 7.37]], "batl": NaN}, {"timestamp": 1631548362634, "ltp": 2.16, "tv": 3988.94, "trd": NaN, "batb": [[0, 1.95, 28.88], [1, 1.92, 51.17], [2, 1.82, 424.02]], "batl": [[0, 2.46, 6.25], [1, 3, 216.62], [2, 3.25, 4.8]]}, {"timestamp": 1631548365622, "ltp": 2.16, "tv": 3988.94, "trd": NaN, "batb": [[0, 2.08, 9.06], [1, 2.04, 8.12], [2, 1.95, 28.88]], "batl": [[0, 2.38, 6.25], [1, 2.46, 6.25], [2, 3, 216.62]]}, {"timestamp": 1631548366136, "ltp": 2.16, "tv": 3988.94, "trd": NaN, "batb": [[0, 2.04, 8.12], [1, 1.95, 28.88], [2, 1.92, 51.17]], "batl": [[0, 2.46, 6.25], [1, 3, 216.62], [2, 3.25, 4.8]]}, {"timestamp": 1631548369216, "ltp": 2.16, "tv": 3988.94, "trd": NaN, "batb": NaN, "batl": [[0, 2.38, 5.75], [1, 2.46, 6.25], [2, 3, 216.62]]}, {"timestamp": 1631548370410, "ltp": 2.16, "tv": 3988.94, "trd": NaN, "batb": NaN, "batl": [[0, 2.46, 6.25], [1, 3, 216.62], [2, 3.25, 4.8]]}, {"timestamp": 1631548373625, "ltp": 2.16, "tv": 3988.94, "trd": NaN, "batb": NaN, "batl": [[0, 2.38, 6.25], [1, 2.46, 6.25], [2, 3, 216.62]]}, {"timestamp": 1631548373932, "ltp": 2.16, "tv": 3988.94, "trd": NaN, "batb": NaN, "batl": [[0, 2.46, 6.25], [1, 3, 216.62], [2, 3.25, 4.8]]}, {"timestamp": 1631548376437, "ltp": 2.16, "tv": 3988.94, "trd": NaN, "batb": NaN, "batl": [[1, 3.25, 4.8], [2, 3.25, 0]]}, {"timestamp": 1631548378659, "ltp": 2.16, "tv": 3988.94, "trd": NaN, "batb": [[0, 2.08, 8.02], [1, 2.04, 8.12], [2, 1.95, 28.88]], "batl": [[0, 2.12, 23.77], [1, 2.14, 7.08], [2, 2.16, 112.81]]}, {"timestamp": 1631548379552, "ltp": 2.16, "tv": 3988.94, "trd": NaN, "batb": [[2, 2, 15]], "batl": NaN}, {"timestamp": 1631548383481, "ltp": 2.08, "tv": 4004.98, "trd": [[2.08, 82.34]], "batb": [[0, 2.04, 8.12], [1, 2, 15], [2, 1.99, 7.5]], "batl": NaN}, {"timestamp": 1631548386447, "ltp": 2.08, "tv": 4004.98, "trd": NaN, "batb": [[1, 2.02, 8.74], [2, 2, 36.35]], "batl": NaN}, {"timestamp": 1631548393392, "ltp": 2.08, "tv": 4004.98, "trd": NaN, "batb": [[0, 1.95, 28.88], [1, 1.85, 29.19], [2, 1.82, 424.02]], "batl": [[0, 2.82, 234.71], [1, 3.25, 4.8], [2, 2.16, 0]]}, {"timestamp": 1631548396604, "ltp": 2.08, "tv": 4004.98, "trd": NaN, "batb": [[0, 1.99, 24.51], [1, 1.95, 28.88], [2, 1.85, 29.19]], "batl": [[0, 2.28, 6.34], [1, 2.82, 234.71], [2, 3.25, 4.8]]}, {"timestamp": 1631548399557, "ltp": 2.08, "tv": 4004.98, "trd": NaN, "batb": NaN, "batl": [[0, 2.1, 21.25], [1, 2.28, 6.34], [2, 2.82, 234.71]]}, {"timestamp": 1631548400594, "ltp": 2.08, "tv": 4004.98, "trd": NaN, "batb": [[0, 2, 25.16], [1, 1.99, 24.51], [2, 1.95, 28.88]], "batl": [[0, 2.22, 6.25]]}, {"timestamp": 1631548401011, "ltp": 2.08, "tv": 4004.98, "trd": NaN, "batb": [[0, 1.99, 24.51], [1, 1.95, 28.88], [2, 1.85, 29.19]], "batl": [[0, 2.28, 6.34], [1, 2.82, 234.71], [2, 3.25, 4.8]]}, {"timestamp": 1631548410589, "ltp": 2.08, "tv": 4004.98, "trd": NaN, "batb": [[0, 2.2, 6.18], [1, 2.18, 41.28], [2, 2.16, 20.64]], "batl": [[0, 2.24, 6.15], [1, 2.28, 6.34], [2, 2.82, 234.71]]}, {"timestamp": 1631548411589, "ltp": 2.08, "tv": 4004.98, "trd": NaN, "batb": [[1, 2.18, 13.76], [2, 2.16, 6.88]], "batl": NaN}, {"timestamp": 1631548417627, "ltp": 2.08, "tv": 4004.98, "trd": NaN, "batb": NaN, "batl": [[2, 2.44, 5.58]]}, {"timestamp": 1631548417830, "ltp": 2.2, "tv": 4009.32, "trd": [[2.2, 364.66]], "batb": [[0, 2.2, 4.01]], "batl": NaN}, {"timestamp": 1631548420431, "ltp": 2.2, "tv": 4009.32, "trd": NaN, "batb": [[0, 2.02, 8.74], [1, 1.95, 28.88], [2, 1.91, 51.59]], "batl": [[0, 2.52, 5.51], [1, 2.82, 234.71], [2, 3.25, 4.8]]}, {"timestamp": 1631548423621, "ltp": 2.2, "tv": 4009.32, "trd": NaN, "batb": [[0, 2.06, 9.58], [1, 2.02, 8.74], [2, 1.95, 28.88]], "batl": [[0, 2.44, 5.58], [1, 2.52, 5.51], [2, 2.82, 234.71]]}, {"timestamp": 1631548423833, "ltp": 2.2, "tv": 4009.32, "trd": NaN, "batb": [[0, 2.02, 8.74], [1, 1.95, 28.88], [2, 1.91, 51.59]], "batl": [[0, 2.52, 5.51], [1, 2.82, 234.71], [2, 3.25, 4.8]]}, {"timestamp": 1631548430450, "ltp": 2.2, "tv": 4009.32, "trd": NaN, "batb": [[0, 2.06, 8.58], [1, 2.02, 8.74], [2, 1.95, 28.88]], "batl": [[0, 2.44, 6.33], [1, 2.52, 5.51], [2, 2.82, 234.71]]}, {"timestamp": 1631548430726, "ltp": 2.2, "tv": 4009.32, "trd": NaN, "batb": [[0, 2.02, 8.74], [1, 1.95, 28.88], [2, 1.91, 51.59]], "batl": [[0, 2.52, 5.51], [1, 2.82, 234.71], [2, 3.25, 4.8]]}, {"timestamp": 1631548435451, "ltp": 2.2, "tv": 4009.32, "trd": NaN, "batb": NaN, "batl": [[1, 3.25, 4.8], [2, 3.25, 0]]}, {"timestamp": 1631548437656, "ltp": 2.2, "tv": 4009.32, "trd": NaN, "batb": NaN, "batl": [[0, 2.44, 6.33], [1, 2.52, 5.51], [2, 3.25, 4.8]]}, {"timestamp": 1631548438064, "ltp": 2.2, "tv": 4009.32, "trd": NaN, "batb": NaN, "batl": [[0, 2.52, 5.51], [1, 3.25, 4.8], [2, 3.25, 0]]}, {"timestamp": 1631548440242, "ltp": 2.2, "tv": 4009.32, "trd": NaN, "batb": NaN, "batl": [[1, 3.15, 203.39], [2, 3.25, 4.8]]}, {"timestamp": 1631548443268, "ltp": 2.2, "tv": 4009.32, "trd": NaN, "batb": NaN, "batl": [[0, 2.5, 6.78], [1, 2.52, 5.51], [2, 2.6, 89.01]]}, {"timestamp": 1631548444364, "ltp": 2.2, "tv": 4009.32, "trd": NaN, "batb": [[0, 2.3, 29.95], [1, 2.04, 42.44], [2, 2.02, 8.74]], "batl": NaN}, {"timestamp": 1631548450562, "ltp": 2.2, "tv": 4009.32, "trd": NaN, "batb": [[1, 2.14, 7.32], [2, 2.06, 8.08]], "batl": NaN}, {"timestamp": 1631548458661, "ltp": 2.2, "tv": 4009.32, "trd": NaN, "batb": [[0, 2.04, 42.44], [1, 1.95, 28.88], [2, 1.92, 400.77]], "batl": [[0, 3.15, 203.39], [1, 3.25, 8.38], [2, 3.65, 3.1]]}, {"timestamp": 1631548461965, "ltp": 2.2, "tv": 4009.32, "trd": NaN, "batb": [[0, 2.06, 8.58], [1, 2.04, 42.44], [2, 1.95, 28.88]], "batl": [[0, 3.25, 8.38], [1, 3.65, 3.1], [2, 3.75, 3.26]]}, {"timestamp": 1631548466290, "ltp": 2.2, "tv": 4009.32, "trd": NaN, "batb": NaN, "batl": [[1, 3.65, 176.04]]}, {"timestamp": 1631548470184, "ltp": 2.2, "tv": 4009.32, "trd": NaN, "batb": [[2, 1.98, 14.44]], "batl": NaN}, {"timestamp": 1631548470706, "ltp": 2.2, "tv": 4009.32, "trd": NaN, "batb": NaN, "batl": [[1, 3.65, 3.1]]}, {"timestamp": 1631548472481, "ltp": 2.2, "tv": 4009.32, "trd": NaN, "batb": [[0, 2.96, 9.44], [1, 2.9, 72.41], [2, 2.88, 15.52]], "batl": NaN}, {"timestamp": 1631548473490, "ltp": 2.2, "tv": 4009.32, "trd": NaN, "batb": NaN, "batl": [[0, 3.15, 4.76], [1, 3.2, 2.38], [2, 3.25, 7.18]]}, {"timestamp": 1631548475301, "ltp": 2.2, "tv": 4009.32, "trd": NaN, "batb": [[1, 2.9, 51.72], [2, 2.88, 5.18]], "batl": [[0, 3.15, 9.52], [1, 3.2, 4.76], [2, 3.25, 9.56]]}, {"timestamp": 1631548484527, "ltp": 3.0, "tv": 4012.05, "trd": [[3, 2.73]], "batb": [[0, 2.32, 29.19], [1, 2.26, 6.98], [2, 2.24, 6.77]], "batl": [[0, 3.25, 4.8], [1, 4.6, 138.07], [2, 5.2, 2.08]]}, {"timestamp": 1631548488407, "ltp": 3.0, "tv": 4012.05, "trd": NaN, "batb": [[0, 2.38, 5.67], [1, 2.32, 29.19], [2, 2.26, 6.98]], "batl": NaN}, {"timestamp": 1631548491999, "ltp": 3.0, "tv": 4012.05, "trd": NaN, "batb": [[0, 2.32, 29.19], [1, 2.26, 6.98], [2, 2.24, 6.77]], "batl": NaN}, {"timestamp": 1631548495395, "ltp": 3.0, "tv": 4012.05, "trd": NaN, "batb": [[0, 2.38, 6.46], [1, 2.32, 29.19], [2, 2.26, 6.98]], "batl": NaN}, {"timestamp": 1631548498721, "ltp": 3.0, "tv": 4012.05, "trd": NaN, "batb": [[0, 2.32, 29.19], [1, 2.26, 6.98], [2, 2.24, 6.77]], "batl": NaN}, {"timestamp": 1631548502034, "ltp": 3.0, "tv": 4012.05, "trd": NaN, "batb": [[0, 2.38, 5.46], [1, 2.32, 29.19], [2, 2.26, 6.98]], "batl": NaN}, {"timestamp": 1631548503141, "ltp": 3.0, "tv": 4012.05, "trd": NaN, "batb": NaN, "batl": [[1, 5.2, 2.08], [2, 7.4, 2]]}, {"timestamp": 1631548504337, "ltp": 3.0, "tv": 4012.05, "trd": NaN, "batb": [[0, 2.38, 62.6], [1, 2.36, 200.96], [2, 2.34, 55.46]], "batl": [[0, 2.54, 2.88], [1, 2.56, 12.67], [2, 2.62, 52.3]]}, {"timestamp": 1631548510656, "ltp": 3.0, "tv": 4012.05, "trd": NaN, "batb": [[0, 2.38, 34.03], [1, 2.36, 27.73], [2, 2.34, 27.73]], "batl": [[1, 2.62, 26.15], [2, 2.66, 25.38]]}, {"timestamp": 1631548511232, "ltp": 3.0, "tv": 4012.05, "trd": NaN, "batb": [[0, 2.08, 7.06], [1, 2.04, 41.6], [2, 1.98, 14.44]], "batl": [[0, 3.25, 4.8], [1, 3.65, 172.94], [2, 3.75, 3.26]]}, {"timestamp": 1631548514536, "ltp": 3.0, "tv": 4012.05, "trd": NaN, "batb": NaN, "batl": [[1, 3.3, 3.75], [2, 3.65, 172.94]]}, {"timestamp": 1631548515665, "ltp": 3.0, "tv": 4012.05, "trd": NaN, "batb": NaN, "batl": [[1, 3.65, 172.94], [2, 3.75, 3.26]]}, {"timestamp": 1631548517626, "ltp": 3.0, "tv": 4012.05, "trd": NaN, "batb": [[0, 2.16, 7.28], [1, 2.08, 7.06], [2, 2.04, 41.6]], "batl": NaN}, {"timestamp": 1631548518248, "ltp": 3.0, "tv": 4012.05, "trd": NaN, "batb": [[0, 2.08, 7.06], [1, 2.04, 41.6], [2, 1.98, 14.44]], "batl": NaN}, {"timestamp": 1631548521570, "ltp": 3.0, "tv": 4012.05, "trd": NaN, "batb": NaN, "batl": [[1, 3.3, 4.05], [2, 3.65, 172.94]]}, {"timestamp": 1631548521834, "ltp": 3.0, "tv": 4012.05, "trd": NaN, "batb": NaN, "batl": [[1, 3.65, 172.94], [2, 3.75, 3.26]]}, {"timestamp": 1631548524553, "ltp": 3.0, "tv": 4012.05, "trd": NaN, "batb": [[0, 2.16, 7.28], [1, 2.08, 7.06], [2, 2.04, 41.6]], "batl": NaN}, {"timestamp": 1631548525355, "ltp": 3.0, "tv": 4012.05, "trd": NaN, "batb": [[0, 2.08, 7.06], [1, 2.04, 41.6], [2, 1.98, 14.44]], "batl": NaN}, {"timestamp": 1631548528578, "ltp": 3.0, "tv": 4012.05, "trd": NaN, "batb": NaN, "batl": [[1, 3.3, 3.35]]}, {"timestamp": 1631548529673, "ltp": 3.0, "tv": 4012.05, "trd": NaN, "batb": [[0, 2.16, 96.11], [1, 2.08, 7.06], [2, 2.04, 41.6]], "batl": [[0, 2.26, 3.25], [1, 2.28, 78.46], [2, 2.3, 1131.75]]}, {"timestamp": 1631548530664, "ltp": 3.0, "tv": 4012.05, "trd": NaN, "batb": NaN, "batl": [[1, 2.28, 25.82], [2, 2.3, 6.58]]}, {"timestamp": 1631548536462, "ltp": 3.0, "tv": 4012.05, "trd": NaN, "batb": [[2, 2.06, 8.08]], "batl": NaN}, {"timestamp": 1631548551418, "ltp": 3.0, "tv": 4012.05, "trd": NaN, "batb": [[0, 1.98, 14.44], [1, 1.97, 400.72], [2, 1.95, 28.88]], "batl": [[0, 2.6, 5.11], [1, 3.15, 203.39], [2, 3.25, 4.8]]}, {"timestamp": 1631548554608, "ltp": 3.0, "tv": 4012.05, "trd": NaN, "batb": [[0, 2.06, 9.08], [1, 2.02, 8.74], [2, 1.98, 14.44]], "batl": [[0, 2.48, 5.49], [1, 2.6, 5.11], [2, 3.15, 203.39]]}, {"timestamp": 1631548554923, "ltp": 3.0, "tv": 4012.05, "trd": NaN, "batb": [[0, 2.02, 8.74], [1, 1.98, 14.44], [2, 1.97, 400.72]], "batl": [[0, 2.6, 5.11], [1, 3.15, 203.39], [2, 3.25, 4.8]]}, {"timestamp": 1631548561410, "ltp": 3.0, "tv": 4012.05, "trd": NaN, "batb": [[0, 2.06, 7.58], [1, 2.02, 8.74], [2, 1.98, 14.44]], "batl": NaN}, {"timestamp": 1631548562025, "ltp": 3.0, "tv": 4012.05, "trd": NaN, "batb": [[0, 2.02, 8.74], [1, 1.98, 14.44], [2, 1.97, 400.72]], "batl": NaN}, {"timestamp": 1631548562821, "ltp": 3.0, "tv": 4012.05, "trd": NaN, "batb": NaN, "batl": [[1, 3.25, 4.8], [2, 3.75, 3.26]]}, {"timestamp": 1631548564322, "ltp": 3.0, "tv": 4012.05, "trd": NaN, "batb": [[0, 2.5, 7.4], [1, 2.02, 8.74], [2, 1.98, 14.44]], "batl": [[0, 2.56, 5.64], [1, 2.6, 5.11], [2, 2.72, 139.39]]}, {"timestamp": 1631548565426, "ltp": 3.0, "tv": 4012.05, "trd": NaN, "batb": [[1, 2.34, 28.77], [2, 2.06, 40.85]], "batl": [[2, 2.62, 11.44]]}, {"timestamp": 1631548572225, "ltp": 3.0, "tv": 4012.05, "trd": NaN, "batb": [[2, 2.2, 6.77]], "batl": NaN}, {"timestamp": 1631548574624, "ltp": 3.0, "tv": 4012.05, "trd": NaN, "batb": [[0, 2.34, 28.77], [1, 2.2, 6.77], [2, 2.14, 7.82]], "batl": [[0, 2.6, 5.11], [1, 3.25, 4.8], [2, 3.35, 3.3]]}, {"timestamp": 1631548575141, "ltp": 3.0, "tv": 4012.05, "trd": NaN, "batb": [[0, 2.14, 7.82], [1, 2.06, 40.85], [2, 2, 5]], "batl": [[0, 3.25, 4.8], [1, 3.65, 172.94], [2, 3.75, 3.26]]}, {"timestamp": 1631548575935, "ltp": 3.0, "tv": 4012.05, "trd": NaN, "batb": NaN, "batl": [[0, 3.25, 4.82]]}, {"timestamp": 1631548578545, "ltp": 3.0, "tv": 4012.05, "trd": NaN, "batb": NaN, "batl": [[1, 3.35, 3.9], [2, 3.65, 172.94]]}, {"timestamp": 1631548580646, "ltp": 3.0, "tv": 4012.05, "trd": NaN, "batb": NaN, "batl": [[0, 3.25, 4.8]]}, {"timestamp": 1631548582054, "ltp": 3.0, "tv": 4012.05, "trd": NaN, "batb": NaN, "batl": [[2, 3.75, 3.26]]}, {"timestamp": 1631548583159, "ltp": 3.0, "tv": 4012.05, "trd": NaN, "batb": [[0, 3.05, 8.37], [1, 2.98, 10.06], [2, 2.96, 5.04]], "batl": [[0, 3.15, 4.7], [1, 3.25, 4.8], [2, 3.35, 90.19]]}, {"timestamp": 1631548584154, "ltp": 3.0, "tv": 4012.05, "trd": NaN, "batb": NaN, "batl": [[1, 3.25, 14.04], [2, 3.3, 4.62]]}, {"timestamp": 1631548585256, "ltp": 3.05, "tv": 4013.61, "trd": [[3.05, 1.56]], "batb": [[0, 3.05, 7.59]], "batl": NaN}, {"timestamp": 1631548591793, "ltp": 3.05, "tv": 4013.65, "trd": [[3.05, 1.6]], "batb": [[0, 3.05, 7.57]], "batl": NaN}, {"timestamp": 1631548594670, "ltp": 3.05, "tv": 4013.65, "trd": NaN, "batb": [[0, 2.86, 41.1], [1, 2.48, 6.51], [2, 2.36, 6.68]], "batl": [[0, 3.25, 4.8], [1, 3.35, 3.9], [2, 3.75, 3.26]]}, {"timestamp": 1631548595089, "ltp": 3.05, "tv": 4013.65, "trd": NaN, "batb": [[0, 2.36, 6.68], [1, 2.34, 28.44], [2, 2.22, 390.22]], "batl": [[1, 4.6, 138.07], [2, 5.4, 2.04]]}, {"timestamp": 1631548598274, "ltp": 3.05, "tv": 4013.65, "trd": NaN, "batb": [[0, 2.48, 5.76], [1, 2.36, 6.68], [2, 2.34, 28.44]], "batl": NaN}, {"timestamp": 1631548602399, "ltp": 3.05, "tv": 4013.65, "trd": NaN, "batb": NaN, "batl": [[1, 5.4, 2.04], [2, 7.4, 2]]}, {"timestamp": 1631548604586, "ltp": 3.05, "tv": 4013.65, "trd": NaN, "batb": [[1, 2.46, 55.28], [2, 2.44, 53.66]], "batl": [[0, 2.7, 50.74], [1, 2.74, 49.26], [2, 2.76, 49.26]]}, {"timestamp": 1631548607201, "ltp": 3.05, "tv": 4013.65, "trd": NaN, "batb": NaN, "batl": [[0, 2.6, 8.19], [1, 2.7, 50.74], [2, 2.74, 49.26]]}, {"timestamp": 1631548611632, "ltp": 3.05, "tv": 4013.65, "trd": NaN, "batb": [[0, 2.14, 7.82], [1, 2.08, 39.93], [2, 2, 5]], "batl": [[0, 3.25, 4.8], [1, 3.65, 172.94], [2, 3.9, 2.95]]}, {"timestamp": 1631548613518, "ltp": 3.05, "tv": 4013.65, "trd": NaN, "batb": [[0, 2.14, 7.84]], "batl": NaN}, {"timestamp": 1631548614534, "ltp": 3.05, "tv": 4013.65, "trd": NaN, "batb": NaN, "batl": [[1, 3.4, 3.24], [2, 3.65, 172.94]]}, {"timestamp": 1631548620336, "ltp": 3.05, "tv": 4013.65, "trd": NaN, "batb": NaN, "batl": [[1, 3.65, 172.94], [2, 3.9, 2.95]]}, {"timestamp": 1631548621637, "ltp": 3.05, "tv": 4013.65, "trd": NaN, "batb": NaN, "batl": [[1, 3.9, 2.95], [2, 5.4, 2.04]]}, {"timestamp": 1631548623415, "ltp": 2.24, "tv": 4023.78, "trd": [[2.24, 22.31], [2.64, 0.04]], "batb": [[0, 2.14, 7.82]], "batl": [[0, 2.24, 17.86], [1, 2.4, 93.15], [2, 3.25, 4.8]]}, {"timestamp": 1631548624552, "ltp": 2.24, "tv": 4023.78, "trd": NaN, "batb": [[0, 2.22, 14.44], [1, 2.14, 7.82], [2, 2.08, 39.93]], "batl": NaN}, {"timestamp": 1631548625335, "ltp": 2.24, "tv": 4023.78, "trd": NaN, "batb": NaN, "batl": [[2, 3.15, 203.39]]}, {"timestamp": 1631548629617, "ltp": 2.24, "tv": 4023.78, "trd": NaN, "batb": NaN, "batl": [[2, 2.54, 5.75]]}, {"timestamp": 1631548634667, "ltp": 2.24, "tv": 4023.78, "trd": NaN, "batb": NaN, "batl": [[0, 2.54, 5.75], [1, 2.68, 4.89], [2, 3.15, 203.39]]}, {"timestamp": 1631548635237, "ltp": 2.24, "tv": 4023.78, "trd": NaN, "batb": [[1, 2, 5], [2, 1.97, 400.72]], "batl": [[0, 2.68, 4.89], [1, 3.15, 203.39], [2, 3.25, 4.8]]}, {"timestamp": 1631548638534, "ltp": 2.24, "tv": 4023.78, "trd": NaN, "batb": [[1, 2.02, 8.74], [2, 2, 5]], "batl": [[0, 2.54, 6.25], [1, 2.68, 4.89], [2, 3.15, 203.39]]}, {"timestamp": 1631548639670, "ltp": 2.24, "tv": 4023.78, "trd": NaN, "batb": NaN, "batl": [[0, 2.3, 19.35]]}, {"timestamp": 1631548639731, "ltp": 2.24, "tv": 4023.78, "trd": NaN, "batb": NaN, "batl": [[0, 2.68, 4.89], [1, 3.15, 203.39], [2, 3.25, 4.8]]}, {"timestamp": 1631548659664, "ltp": 2.24, "tv": 4023.78, "trd": NaN, "batb": [[0, 2.02, 8.74], [1, 2, 5], [2, 1.97, 400.72]], "batl": [[0, 2.54, 5.75], [1, 2.68, 4.89], [2, 3.15, 203.39]]}, {"timestamp": 1631548660076, "ltp": 2.24, "tv": 4023.78, "trd": NaN, "batb": NaN, "batl": [[0, 2.68, 4.89], [1, 3.25, 4.8], [2, 3.9, 2.95]]}, {"timestamp": 1631548661590, "ltp": 2.24, "tv": 4023.78, "trd": NaN, "batb": NaN, "batl": [[0, 2.6, 10.26], [1, 2.68, 4.89], [2, 2.78, 124.33]]}, {"timestamp": 1631548663090, "ltp": 2.24, "tv": 4023.78, "trd": NaN, "batb": [[0, 2.36, 27.68], [1, 2.08, 39.34], [2, 2.02, 8.74]], "batl": NaN}, {"timestamp": 1631548668405, "ltp": 2.24, "tv": 4023.78, "trd": NaN, "batb": [[1, 2.24, 6.27], [2, 2.16, 7.28]], "batl": NaN}, {"timestamp": 1631548672591, "ltp": 2.24, "tv": 4023.78, "trd": NaN, "batb": [[0, 2.16, 7.28], [1, 2.08, 39.34], [2, 2, 5]], "batl": [[0, 3.25, 4.8], [1, 3.9, 163.54], [2, 5.4, 2.04]]}, {"timestamp": 1631548675539, "ltp": 2.24, "tv": 4023.78, "trd": NaN, "batb": [[0, 2.24, 6.77], [1, 2.16, 7.28], [2, 2.08, 39.34]], "batl": NaN}, {"timestamp": 1631548676162, "ltp": 2.24, "tv": 4023.78, "trd": NaN, "batb": [[0, 2.16, 7.28], [1, 2.08, 39.34], [2, 2, 5]], "batl": NaN}, {"timestamp": 1631548679350, "ltp": 2.24, "tv": 4023.78, "trd": NaN, "batb": NaN, "batl": [[0, 2.56, 9.02], [1, 3.25, 4.8], [2, 3.4, 3.54]]}, {"timestamp": 1631548680666, "ltp": 2.24, "tv": 4023.78, "trd": NaN, "batb": NaN, "batl": [[0, 2.26, 88.5], [1, 2.32, 3.11], [2, 2.36, 1286.22]]}, {"timestamp": 1631548681672, "ltp": 2.24, "tv": 4023.78, "trd": NaN, "batb": NaN, "batl": [[2, 2.56, 9.02]]}, {"timestamp": 1631548684045, "ltp": 2.24, "tv": 4023.78, "trd": NaN, "batb": NaN, "batl": [[2, 3.25, 4.8]]}, {"timestamp": 1631548685571, "ltp": 2.24, "tv": 4029.39, "trd": [[2.24, 27.92]], "batb": NaN, "batl": NaN}, {"timestamp": 1631548687363, "ltp": 2.24, "tv": 4029.39, "trd": NaN, "batb": [[1, 2.08, 46.65], [2, 2.04, 8.62]], "batl": [[2, 2.58, 5.75]]}, {"timestamp": 1631548690879, "ltp": 2.26, "tv": 4030.97, "trd": [[2.26, 42.12]], "batb": NaN, "batl": [[0, 2.26, 86.92]]}, {"timestamp": 1631548697060, "ltp": 2.26, "tv": 4038.11, "trd": [[2.26, 49.26]], "batb": NaN, "batl": [[0, 2.26, 79.78]]}, {"timestamp": 1631548698676, "ltp": 2.26, "tv": 4038.17, "trd": [[2.26, 49.32]], "batb": [[0, 2, 5], [1, 1.97, 400.72], [2, 1.95, 28.88]], "batl": [[0, 2.28, 6.97], [1, 2.7, 5.05], [2, 3.25, 4.8]]}, {"timestamp": 1631548699562, "ltp": 2.26, "tv": 4038.17, "trd": NaN, "batb": [[0, 2.06, 7.58], [1, 2.02, 8.24], [2, 2, 5]], "batl": [[0, 2.7, 5.05], [1, 2.74, 4.48]]}, {"timestamp": 1631548699773, "ltp": 2.26, "tv": 4038.17, "trd": NaN, "batb": [[0, 2.02, 8.24], [1, 2, 5], [2, 1.97, 400.72]], "batl": NaN}, {"timestamp": 1631548701653, "ltp": 2.26, "tv": 4038.17, "trd": NaN, "batb": [[0, 2.04, 7.87], [1, 2.02, 8.24], [2, 2, 5]], "batl": [[0, 2.58, 5.75], [1, 2.7, 5.05], [2, 2.74, 4.48]]}, {"timestamp": 1631548701966, "ltp": 2.26, "tv": 4038.17, "trd": NaN, "batb": NaN, "batl": [[0, 2.7, 5.05], [1, 2.74, 4.48], [2, 3.25, 4.8]]}, {"timestamp": 1631548708598, "ltp": 2.26, "tv": 4038.17, "trd": NaN, "batb": [[0, 2.08, 8.06], [1, 2.04, 7.87], [2, 2.02, 8.24]], "batl": [[0, 2.58, 5.44], [1, 2.7, 5.05], [2, 2.74, 4.48]]}, {"timestamp": 1631548708863, "ltp": 2.26, "tv": 4038.17, "trd": NaN, "batb": [[0, 2.04, 7.87], [1, 2.02, 8.24], [2, 2, 5]], "batl": [[0, 2.7, 5.05], [1, 2.74, 4.48], [2, 3.25, 4.8]]}, {"timestamp": 1631548715586, "ltp": 2.26, "tv": 4038.17, "trd": NaN, "batb": [[0, 2.08, 8.06], [1, 2.04, 7.87], [2, 2.02, 8.24]], "batl": NaN}, {"timestamp": 1631548715897, "ltp": 2.26, "tv": 4038.17, "trd": NaN, "batb": [[0, 2.04, 7.87], [1, 2.02, 8.24], [2, 2, 5]], "batl": NaN}, {"timestamp": 1631548722576, "ltp": 2.26, "tv": 4038.17, "trd": NaN, "batb": [[0, 2.08, 7.06], [1, 2.04, 7.87], [2, 2.02, 8.24]], "batl": [[0, 2.58, 5.94], [1, 2.7, 5.05], [2, 2.74, 4.48]]}, {"timestamp": 1631548723304, "ltp": 2.26, "tv": 4038.17, "trd": NaN, "batb": [[0, 2.04, 7.87], [1, 2.02, 8.24], [2, 2, 5]], "batl": [[0, 2.7, 5.05], [1, 2.74, 4.48], [2, 3.25, 4.8]]}, {"timestamp": 1631548726223, "ltp": 2.26, "tv": 4038.17, "trd": NaN, "batb": NaN, "batl": [[0, 2.6, 8.75], [1, 2.7, 5.05], [2, 2.74, 4.48]]}, {"timestamp": 1631548727210, "ltp": 2.26, "tv": 4038.17, "trd": NaN, "batb": [[0, 2.38, 27.09], [1, 2.1, 38.5], [2, 2.04, 7.87]], "batl": NaN}, {"timestamp": 1631548732430, "ltp": 2.26, "tv": 4038.17, "trd": NaN, "batb": [[1, 2.24, 5.77], [2, 2.16, 7.53]], "batl": NaN}, {"timestamp": 1631548736349, "ltp": 2.58, "tv": 4045.29, "trd": [[2.58, 7.12]], "batb": NaN, "batl": NaN}, {"timestamp": 1631548745635, "ltp": 2.58, "tv": 4054.31, "trd": [[2.58, 16.14]], "batb": NaN, "batl": NaN}, {"timestamp": 1631548748626, "ltp": 2.58, "tv": 4054.31, "trd": NaN, "batb": [[0, 2.16, 7.53], [1, 2.1, 38.5], [2, 2, 5]], "batl": [[0, 3.25, 4.8], [1, 3.4, 3.64], [2, 3.9, 2.95]]}, {"timestamp": 1631548763072, "ltp": 2.58, "tv": 4054.31, "trd": NaN, "batb": NaN, "batl": [[0, 2.28, 52.63], [1, 2.32, 3.11], [2, 2.36, 38.14]]}, {"timestamp": 1631548764171, "ltp": 2.58, "tv": 4054.31, "trd": NaN, "batb": [[0, 2.22, 13.52], [1, 2.2, 6.76], [2, 2.18, 6.76]], "batl": [[2, 2.36, 12.72]]}, {"timestamp": 1631548774679, "ltp": 2.28, "tv": 4074.16, "trd": [[2.28, 30.89]], "batb": NaN, "batl": [[0, 2.28, 32.78]]}, {"timestamp": 1631548776656, "ltp": 2.28, "tv": 4074.16, "trd": NaN, "batb": [[0, 2.22, 6.76], [1, 2.2, 3.38], [2, 2.18, 3.38]], "batl": [[0, 2.28, 8.77], [2, 2.36, 6.36]]}, {"timestamp": 1631548777558, "ltp": 2.28, "tv": 4074.16, "trd": NaN, "batb": [[0, 2, 5], [1, 1.95, 77.95], [2, 1.6, 99.43]], "batl": [[0, 2.68, 5.64], [1, 3.25, 4.8], [2, 3.4, 3.64]]}, {"timestamp": 1631548780592, "ltp": 2.28, "tv": 4074.16, "trd": NaN, "batb": [[0, 2.04, 9.37], [1, 2, 5], [2, 1.95, 77.95]], "batl": NaN}, {"timestamp": 1631548784469, "ltp": 2.28, "tv": 4074.16, "trd": NaN, "batb": NaN, "batl": [[0, 2.54, 5.25], [1, 2.68, 5.64], [2, 3.25, 4.8]]}, {"timestamp": 1631548786191, "ltp": 2.28, "tv": 4074.16, "trd": NaN, "batb": NaN, "batl": [[0, 2.68, 5.64], [1, 3.25, 4.8], [2, 3.4, 3.64]]}, {"timestamp": 1631548788592, "ltp": 2.28, "tv": 4074.16, "trd": NaN, "batb": NaN, "batl": [[0, 2.12, 2.96], [1, 2.16, 12.92], [2, 2.28, 116.76]]}, {"timestamp": 1631548795200, "ltp": 2.28, "tv": 4074.16, "trd": NaN, "batb": NaN, "batl": [[2, 2.26, 7.75]]}, {"timestamp": 1631548799106, "ltp": 2.28, "tv": 4074.16, "trd": NaN, "batb": [[2, 1.95, 49.07]], "batl": NaN}, {"timestamp": 1631548818358, "ltp": 2.1, "tv": 4081.34, "trd": [[2.1, 50.5]], "batb": NaN, "batl": NaN}, {"timestamp": 1631548820659, "ltp": 2.1, "tv": 4081.34, "trd": NaN, "batb": [[0, 2, 5], [1, 1.95, 49.07], [2, 1.9, 27.06]], "batl": [[0, 2.26, 7.75], [1, 2.32, 6.86], [2, 2.68, 5.64]]}, {"timestamp": 1631548821545, "ltp": 2.1, "tv": 4081.34, "trd": NaN, "batb": [[1, 1.9, 27.06], [2, 1.88, 25.96]], "batl": [[0, 2.32, 6.86], [1, 3.25, 4.8], [2, 3.4, 3.64]]}, {"timestamp": 1631548828450, "ltp": 2.1, "tv": 4081.34, "trd": NaN, "batb": [[0, 2.24, 7.83], [1, 2, 5], [2, 1.9, 27.06]], "batl": [[1, 2.42, 74.96], [2, 3.25, 4.8]]}, {"timestamp": 1631548829340, "ltp": 2.1, "tv": 4081.34, "trd": NaN, "batb": [[1, 2.06, 40.51], [2, 2, 5]], "batl": NaN}, {"timestamp": 1631548832270, "ltp": 2.2, "tv": 4189.17, "trd": [[2.2, 386.15], [2.24, 114.26]], "batb": [[0, 2.06, 40.51], [1, 2, 5], [2, 1.91, 52.09]], "batl": NaN}, {"timestamp": 1631548835256, "ltp": 2.2, "tv": 4189.17, "trd": NaN, "batb": [[0, 2.06, 48.59], [1, 2.02, 8.74], [2, 2, 5]], "batl": [[1, 2.42, 80.21], [2, 2.48, 5.49]]}, {"timestamp": 1631548837185, "ltp": 2.2, "tv": 4189.17, "trd": NaN, "batb": [[1, 2.04, 7.87], [2, 2.02, 8.74]], "batl": [[1, 2.38, 5.75], [2, 2.42, 80.21]]}, {"timestamp": 1631548841615, "ltp": 2.2, "tv": 4189.17, "trd": NaN, "batb": [[0, 2.06, 60.17]], "batl": NaN}, {"timestamp": 1631548845370, "ltp": 2.2, "tv": 4189.17, "trd": NaN, "batb": NaN, "batl": [[0, 2.28, 11.59], [1, 2.32, 6.86], [2, 2.38, 5.75]]}, {"timestamp": 1631548848659, "ltp": 2.2, "tv": 4189.17, "trd": NaN, "batb": [[0, 2.06, 48.59]], "batl": [[0, 2.32, 6.86], [1, 2.38, 5.75], [2, 2.42, 5.25]]}, {"timestamp": 1631548849560, "ltp": 2.2, "tv": 4189.17, "trd": NaN, "batb": [[0, 2.02, 8.74], [1, 2, 5], [2, 1.91, 52.09]], "batl": [[0, 2.4, 5.14], [1, 2.46, 6.25], [2, 3.25, 4.8]]}, {"timestamp": 1631548850474, "ltp": 2.2, "tv": 4189.17, "trd": NaN, "batb": NaN, "batl": [[0, 2.46, 6.25], [1, 3.25, 4.8], [2, 3.25, 0]]}, {"timestamp": 1631548852462, "ltp": 2.2, "tv": 4189.17, "trd": NaN, "batb": NaN, "batl": [[0, 2.42, 6.75], [1, 2.46, 6.25], [2, 2.48, 5.74]]}, {"timestamp": 1631548857707, "ltp": 2.2, "tv": 4189.17, "trd": NaN, "batb": NaN, "batl": [[0, 2.46, 6.25], [1, 2.48, 5.74], [2, 3.25, 4.8]]}, {"timestamp": 1631548859603, "ltp": 2.2, "tv": 4189.17, "trd": NaN, "batb": [[0, 2.34, 15.54], [1, 2.32, 106.02], [2, 2.3, 6.4]], "batl": [[0, 2.4, 7.42], [1, 2.46, 6.25], [2, 2.48, 5.74]]}, {"timestamp": 1631548865374, "ltp": 2.4, "tv": 4196.59, "trd": [[2.4, 21.99]], "batb": NaN, "batl": [[0, 2.46, 6.25], [1, 2.48, 5.74], [2, 2.5, 12]]}, {"timestamp": 1631548871022, "ltp": 2.4, "tv": 4196.59, "trd": NaN, "batb": NaN, "batl": [[2, 2.5, 17.39]]}, {"timestamp": 1631548875416, "ltp": 2.36, "tv": 4196.69, "trd": [[2.36, 11.36]], "batb": [[1, 2.32, 92.6]], "batl": NaN}, {"timestamp": 1631548878024, "ltp": 2.36, "tv": 4196.69, "trd": NaN, "batb": [[0, 2.36, 10.24], [1, 2.34, 15.54], [2, 2.32, 92.6]], "batl": NaN}, {"timestamp": 1631548884029, "ltp": 2.36, "tv": 4196.83, "trd": [[2.36, 11.5]], "batb": [[0, 2.36, 10.17]], "batl": NaN}, {"timestamp": 1631548886519, "ltp": 2.36, "tv": 4196.83, "trd": NaN, "batb": [[0, 2.34, 9.13], [1, 2.32, 46.3], [2, 2.3, 3.2]], "batl": [[2, 2.5, 11.39]]}, {"timestamp": 1631548887150, "ltp": 2.36, "tv": 4196.83, "trd": NaN, "batb": [[0, 2.24, 7.02], [1, 2.2, 6.82], [2, 2.18, 7.86]], "batl": [[0, 2.54, 5.75], [1, 3.25, 4.8], [2, 2.5, 0]]}, {"timestamp": 1631548896458, "ltp": 2.36, "tv": 4196.83, "trd": NaN, "batb": [[0, 2.46, 48.78], [1, 2.44, 2.42], [2, 2.24, 7.02]], "batl": NaN}, {"timestamp": 1631548897659, "ltp": 2.36, "tv": 4196.83, "trd": NaN, "batb": [[2, 2.32, 29.19]], "batl": NaN}, {"timestamp": 1631548899248, "ltp": 2.36, "tv": 4196.83, "trd": NaN, "batb": NaN, "batl": [[1, 2.56, 12.74], [2, 3.25, 4.8]]}, {"timestamp": 1631548903158, "ltp": 2.36, "tv": 4196.83, "trd": NaN, "batb": [[2, 2.38, 5.96]], "batl": [[2, 2.58, 5.25]]}, {"timestamp": 1631548915581, "ltp": 2.36, "tv": 4196.83, "trd": NaN, "batb": [[0, 2.46, 40.65]], "batl": [[1, 2.58, 5.25], [2, 2.6, 5.46]]}, {"timestamp": 1631548915954, "ltp": 2.36, "tv": 4196.83, "trd": NaN, "batb": [[0, 2.38, 5.96], [1, 2.34, 6.22], [2, 2.24, 7.02]], "batl": [[0, 3.25, 4.8], [1, 2.58, 0], [2, 2.6, 0]]}, {"timestamp": 1631548919454, "ltp": 2.36, "tv": 4196.83, "trd": NaN, "batb": NaN, "batl": [[0, 2.6, 5.81], [1, 3.25, 4.8]]}, {"timestamp": 1631548921597, "ltp": 2.36, "tv": 4196.83, "trd": NaN, "batb": [[0, 2.34, 6.22], [1, 2.24, 7.02], [2, 2.2, 40.79]], "batl": [[0, 2.52, 21.76], [1, 2.6, 5.81], [2, 3.25, 4.8]]}, {"timestamp": 1631548921870, "ltp": 2.36, "tv": 4196.83, "trd": NaN, "batb": NaN, "batl": [[0, 2.6, 5.81], [1, 3.25, 4.8], [2, 3.25, 0]]}, {"timestamp": 1631548924070, "ltp": 2.36, "tv": 4196.83, "trd": NaN, "batb": [[0, 2.38, 6.17], [1, 2.34, 6.22], [2, 2.24, 7.02]], "batl": NaN}, {"timestamp": 1631548934299, "ltp": 2.36, "tv": 4196.83, "trd": NaN, "batb": [[0, 2.34, 6.22], [1, 2.24, 7.02], [2, 2.2, 40.79]], "batl": NaN}, {"timestamp": 1631548936324, "ltp": 2.36, "tv": 4196.83, "trd": NaN, "batb": [[0, 2.36, 9.1], [1, 2.34, 6.22], [2, 2.32, 101.69]], "batl": [[0, 2.42, 6.01], [1, 2.5, 77.29], [2, 2.6, 5.81]]}, {"timestamp": 1631548944220, "ltp": 2.42, "tv": 4202.84, "trd": [[2.42, 43.05]], "batb": NaN, "batl": [[0, 2.5, 77.29], [1, 2.52, 6.26], [2, 2.58, 4.94]]}, {"timestamp": 1631548946413, "ltp": 2.42, "tv": 4202.84, "trd": NaN, "batb": [[0, 2.42, 4], [1, 2.36, 9.1], [2, 2.34, 6.22]], "batl": NaN}, {"timestamp": 1631548951424, "ltp": 2.42, "tv": 4202.84, "trd": NaN, "batb": NaN, "batl": [[2, 2.54, 5.75]]}, {"timestamp": 1631548954346, "ltp": 2.42, "tv": 4202.84, "trd": NaN, "batb": [[1, 2.34, 6.22], [2, 2.32, 101.69]], "batl": NaN}, {"timestamp": 1631548956610, "ltp": 2.42, "tv": 4202.84, "trd": NaN, "batb": [[1, 2.3, 6.78], [2, 2.28, 6.66]], "batl": [[0, 2.54, 5.75], [1, 2.58, 4.94], [2, 2.6, 5.81]]}, {"timestamp": 1631548957538, "ltp": 2.42, "tv": 4202.84, "trd": NaN, "batb": NaN, "batl": [[0, 2.6, 5.81], [1, 3.25, 4.8], [2, 2.6, 0]]}, {"timestamp": 1631548962721, "ltp": 2.42, "tv": 4202.84, "trd": NaN, "batb": [[0, 2.3, 6.78], [1, 2.28, 6.66], [2, 2.26, 5.98]], "batl": NaN}, {"timestamp": 1631548966274, "ltp": 2.42, "tv": 4202.84, "trd": NaN, "batb": [[0, 2.28, 6.66], [1, 2.26, 5.98], [2, 2.24, 7.02]], "batl": NaN}, {"timestamp": 1631548969148, "ltp": 2.42, "tv": 4202.84, "trd": NaN, "batb": NaN, "batl": [[0, 2.36, 63.56], [1, 2.38, 31.78], [2, 2.4, 31.78]]}, {"timestamp": 1631548970448, "ltp": 2.42, "tv": 4202.84, "trd": NaN, "batb": NaN, "batl": [[0, 2.36, 38.14], [1, 2.38, 19.07], [2, 2.4, 19.07]]}, {"timestamp": 1631548971835, "ltp": 2.42, "tv": 4202.84, "trd": NaN, "batb": [[0, 2.26, 5.98], [1, 2.22, 13.52], [2, 2.2, 13.58]], "batl": NaN}, {"timestamp": 1631548977338, "ltp": 2.42, "tv": 4202.84, "trd": NaN, "batb": [[0, 2.32, 3], [1, 2.26, 5.98], [2, 2.22, 13.52]], "batl": NaN}, {"timestamp": 1631548980568, "ltp": 2.42, "tv": 4202.84, "trd": NaN, "batb": [[0, 2.26, 5.98], [1, 2.22, 13.52], [2, 2.2, 13.58]], "batl": NaN}, {"timestamp": 1631548983477, "ltp": 2.34, "tv": 4205.84, "trd": [[2.34, 3]], "batb": NaN, "batl": NaN}, {"timestamp": 1631548995269, "ltp": 2.34, "tv": 4214.37, "trd": [[2.34, 11.53]], "batb": NaN, "batl": NaN}, {"timestamp": 1631548996669, "ltp": 2.34, "tv": 4214.37, "trd": NaN, "batb": [[0, 2.02, 8.24], [1, 2, 5], [2, 1.87, 27.85]], "batl": [[0, 2.54, 5.25], [1, 2.6, 5.81], [2, 2.62, 5.25]]}, {"timestamp": 1631548996876, "ltp": 2.34, "tv": 4214.37, "trd": NaN, "batb": NaN, "batl": [[0, 2.6, 5.81], [1, 2.62, 5.25], [2, 3.25, 4.8]]}, {"timestamp": 1631548999471, "ltp": 2.34, "tv": 4214.37, "trd": NaN, "batb": [[0, 2.04, 8.37], [1, 2.02, 8.24], [2, 2, 5]], "batl": NaN}, {"timestamp": 1631549003574, "ltp": 2.34, "tv": 4214.37, "trd": NaN, "batb": [[0, 2.08, 8.06], [1, 2.04, 8.37], [2, 2.02, 8.24]], "batl": [[0, 2.52, 4.76], [1, 2.6, 5.81], [2, 2.62, 5.25]]}, {"timestamp": 1631549003680, "ltp": 2.34, "tv": 4214.37, "trd": NaN, "batb": [[0, 2.04, 8.37], [1, 2.02, 8.24], [2, 2, 5]], "batl": NaN}, {"timestamp": 1631549008283, "ltp": 2.34, "tv": 4214.37, "trd": NaN, "batb": NaN, "batl": [[0, 2.6, 5.81], [1, 2.62, 5.25], [2, 3.25, 4.8]]}, {"timestamp": 1631549015581, "ltp": 2.34, "tv": 4214.37, "trd": NaN, "batb": [[0, 2.48, 2.51], [1, 2.34, 85.48], [2, 2.28, 208.91]], "batl": [[0, 2.56, 115.14], [1, 2.6, 5.81], [2, 2.62, 5.25]]}, {"timestamp": 1631549016515, "ltp": 2.34, "tv": 4214.37, "trd": NaN, "batb": [[1, 2.34, 51.29]], "batl": NaN}, {"timestamp": 1631549031531, "ltp": 2.5, "tv": 4214.43, "trd": [[2.5, 0.06]], "batb": NaN, "batl": NaN}, {"timestamp": 1631549033625, "ltp": 2.5, "tv": 4216.6, "trd": [[2.5, 2.23]], "batb": NaN, "batl": NaN}, {"timestamp": 1631549038540, "ltp": 2.5, "tv": 4216.6, "trd": NaN, "batb": NaN, "batl": [[0, 2.56, 126.18]]}, {"timestamp": 1631549038745, "ltp": 2.5, "tv": 4216.6, "trd": NaN, "batb": NaN, "batl": [[0, 2.56, 115.14]]}, {"timestamp": 1631549042240, "ltp": 2.48, "tv": 4221.94, "trd": [[2.48, 5.34]], "batb": [[0, 2.34, 51.29], [1, 2.28, 208.91], [2, 2.26, 31.62]], "batl": NaN}, {"timestamp": 1631549063431, "ltp": 2.48, "tv": 4223.65, "trd": [[2.48, 7.05]], "batb": NaN, "batl": NaN}, {"timestamp": 1631549089501, "ltp": 2.48, "tv": 4224.1, "trd": [[2.48, 7.5]], "batb": NaN, "batl": NaN}, {"timestamp": 1631549107838, "ltp": 2.48, "tv": 4224.1, "trd": NaN, "batb": [[0, 2.34, 58.01], [1, 2.28, 215.57]], "batl": NaN}, {"timestamp": 1631549109412, "ltp": 2.48, "tv": 4226.26, "trd": [[2.48, 9.66]], "batb": NaN, "batl": NaN}, {"timestamp": 1631549110630, "ltp": 2.48, "tv": 4226.26, "trd": NaN, "batb": [[0, 2.34, 6.72], [1, 2.26, 31.62], [2, 2.08, 39.34]], "batl": [[0, 2.94, 4.25], [1, 3.15, 3.9], [2, 3.25, 4.8]]}, {"timestamp": 1631549111102, "ltp": 2.48, "tv": 4226.26, "trd": NaN, "batb": [[0, 2.08, 39.34], [1, 2, 5], [2, 1.01, 105.79]], "batl": [[0, 3.15, 3.9], [1, 3.25, 4.8], [2, 990, 0.01]]}, {"timestamp": 1631549114236, "ltp": 2.48, "tv": 4226.26, "trd": NaN, "batb": [[0, 2.28, 6.16], [1, 2.08, 39.34], [2, 2, 5]], "batl": NaN}, {"timestamp": 1631549116120, "ltp": 2.48, "tv": 4226.26, "trd": NaN, "batb": NaN, "batl": [[0, 2.48, 19.84], [1, 3.15, 3.9], [2, 3.25, 4.8]]}, {"timestamp": 1631549117420, "ltp": 2.48, "tv": 4226.26, "trd": NaN, "batb": [[0, 2.34, 5.72], [1, 2.28, 6.16], [2, 2.08, 39.34]], "batl": [[1, 2.94, 4.25], [2, 3.15, 3.9]]}, {"timestamp": 1631549118627, "ltp": 2.48, "tv": 4246.1, "trd": [[2.48, 29.5]], "batb": [[0, 2.78, 2]], "batl": [[0, 2.88, 7.85], [1, 2.92, 93.26]]}, {"timestamp": 1631549119457, "ltp": 2.48, "tv": 4246.1, "trd": NaN, "batb": [[1, 2.54, 22.65], [2, 2.3, 30.11]], "batl": NaN}, {"timestamp": 1631549125738, "ltp": 2.48, "tv": 4246.1, "trd": NaN, "batb": [[1, 2.56, 5.83], [2, 2.54, 22.65]], "batl": NaN}, {"timestamp": 1631549129621, "ltp": 2.48, "tv": 4246.1, "trd": NaN, "batb": [[0, 2.3, 30.11], [1, 2, 5], [2, 1.01, 105.79]], "batl": [[0, 3.25, 4.8], [1, 3.6, 3.11], [2, 3.95, 2.7]]}, {"timestamp": 1631549133142, "ltp": 2.48, "tv": 4246.1, "trd": NaN, "batb": [[0, 2.48, 5.26], [1, 2.3, 30.11], [2, 2, 5]], "batl": NaN}, {"timestamp": 1631549136365, "ltp": 2.48, "tv": 4246.1, "trd": NaN, "batb": [[0, 2.56, 5.83], [1, 2.48, 5.26], [2, 2.3, 30.11]], "batl": NaN}, {"timestamp": 1631549137464, "ltp": 2.48, "tv": 4246.1, "trd": NaN, "batb": [[0, 2.48, 5.26], [1, 2.3, 30.11], [2, 2, 5]], "batl": NaN}, {"timestamp": 1631549143482, "ltp": 2.48, "tv": 4246.1, "trd": NaN, "batb": [[0, 2.56, 5.83], [1, 2.48, 5.26], [2, 2.3, 30.11]], "batl": NaN}, {"timestamp": 1631549143750, "ltp": 2.48, "tv": 4246.1, "trd": NaN, "batb": [[0, 2.48, 5.26], [1, 2.3, 30.11], [2, 2, 5]], "batl": NaN}, {"timestamp": 1631549147586, "ltp": 2.48, "tv": 4246.1, "trd": NaN, "batb": [[0, 2.56, 6.08], [1, 2.48, 5.26], [2, 2.4, 90.05]], "batl": [[0, 2.6, 8.04], [1, 2.62, 1176.96], [2, 3.25, 4.8]]}, {"timestamp": 1631549148588, "ltp": 2.48, "tv": 4246.1, "trd": NaN, "batb": [[0, 2.48, 5.26], [1, 2.4, 90.05], [2, 2.3, 30.11]], "batl": [[1, 3.25, 4.8], [2, 3.6, 3.11]]}, {"timestamp": 1631549156411, "ltp": 2.48, "tv": 4246.1, "trd": NaN, "batb": [[0, 2.28, 7.66], [1, 2.1, 38.58], [2, 2, 5]], "batl": [[0, 3.25, 4.8], [1, 3.35, 3.7], [2, 990, 0.01]]}, {"timestamp": 1631549164498, "ltp": 2.48, "tv": 4246.1, "trd": NaN, "batb": [[0, 2.92, 2], [1, 2.82, 42.55], [2, 2.28, 7.66]], "batl": [[0, 3.05, 9.31], [1, 3.25, 4.8], [2, 3.35, 3.7]]}, {"timestamp": 1631549165522, "ltp": 2.48, "tv": 4246.1, "trd": NaN, "batb": [[2, 2.68, 19.8]], "batl": NaN}, {"timestamp": 1631549172427, "ltp": 2.96, "tv": 4247.72, "trd": [[2.96, 1.62]], "batb": NaN, "batl": NaN}, {"timestamp": 1631549175228, "ltp": 2.96, "tv": 4247.72, "trd": NaN, "batb": [[0, 2.48, 5.26], [1, 2.36, 28.02], [2, 2, 5]], "batl": [[0, 3.25, 5.3], [1, 4.8, 2.27], [2, 990, 0.01]]}, {"timestamp": 1631549178624, "ltp": 2.96, "tv": 4247.72, "trd": NaN, "batb": NaN, "batl": [[1, 4.1, 2.85], [2, 4.8, 2.27]]}, {"timestamp": 1631549185441, "ltp": 2.96, "tv": 4247.72, "trd": NaN, "batb": [[0, 2.58, 5.56], [1, 2.48, 5.26], [2, 2.36, 28.02]], "batl": NaN}, {"timestamp": 1631549185755, "ltp": 2.96, "tv": 4247.72, "trd": NaN, "batb": [[0, 2.48, 5.26], [1, 2.36, 28.02], [2, 2, 5]], "batl": NaN}, {"timestamp": 1631549189662, "ltp": 3.25, "tv": 4253.02, "trd": [[2.96, 2.12], [3.25, 27.94]], "batb": [[0, 3.6, 43.68], [1, 3.55, 20.84], [2, 3.5, 20.84]], "batl": [[0, 3.85, 7.45]]}, {"timestamp": 1631549190630, "ltp": 3.25, "tv": 4253.02, "trd": NaN, "batb": [[0, 3.6, 27.01], [1, 3.55, 12.5], [2, 3.5, 12.5]], "batl": NaN}, {"timestamp": 1631549201638, "ltp": 3.85, "tv": 4255.11, "trd": [[3.85, 2.09]], "batb": [[0, 3.15, 3.63], [1, 3, 5], [2, 2.84, 42.02]], "batl": [[0, 5.4, 2.04], [1, 6.4, 2], [2, 990, 0.01]]}, {"timestamp": 1631549201745, "ltp": 3.85, "tv": 4255.11, "trd": NaN, "batb": [[0, 3, 5], [1, 2.84, 42.02], [2, 2, 5]], "batl": [[0, 6.4, 2], [1, 990, 0.01], [2, 990, 0]]}, {"timestamp": 1631549204965, "ltp": 3.85, "tv": 4255.11, "trd": NaN, "batb": [[0, 3.15, 4.23], [1, 3, 5], [2, 2.84, 42.02]], "batl": [[0, 5.4, 2.04], [1, 6.4, 2], [2, 990, 0.01]]}, {"timestamp": 1631549210663, "ltp": 3.85, "tv": 4255.11, "trd": NaN, "batb": NaN, "batl": [[0, 6.4, 2], [1, 990, 0.01], [2, 990, 0]]}, {"timestamp": 1631549213387, "ltp": 3.85, "tv": 4255.11, "trd": NaN, "batb": [[2, 2.96, 106.45]], "batl": [[0, 3.9, 370.29], [1, 6.4, 2], [2, 990, 0.01]]}, {"timestamp": 1631549215861, "ltp": 3.85, "tv": 4255.11, "trd": NaN, "batb": [[0, 3.2, 7.01], [1, 3.15, 4.23], [2, 3, 5]], "batl": [[0, 3.3, 4.71], [1, 3.9, 370.29], [2, 6.4, 2]]}, {"timestamp": 1631549219891, "ltp": 3.85, "tv": 4255.11, "trd": NaN, "batb": NaN, "batl": [[2, 5.6, 2.01]]}, {"timestamp": 1631549224674, "ltp": 3.85, "tv": 4255.11, "trd": NaN, "batb": [[0, 2.84, 42.02], [1, 2.62, 5.04], [2, 2.5, 5.94]], "batl": [[0, 5.6, 2.01], [1, 6.4, 2], [2, 7.8, 2]]}, {"timestamp": 1631549225185, "ltp": 3.85, "tv": 4255.11, "trd": NaN, "batb": [[0, 2.5, 5.94], [1, 2.36, 27.68], [2, 2, 5]], "batl": NaN}, {"timestamp": 1631549227600, "ltp": 3.85, "tv": 4255.11, "trd": NaN, "batb": NaN, "batl": [[0, 3.2, 1.71], [1, 5.4, 4.57], [2, 5.6, 2.01]]}, {"timestamp": 1631549228384, "ltp": 3.85, "tv": 4255.11, "trd": NaN, "batb": NaN, "batl": [[1, 5.6, 2.01], [2, 6.4, 2]]}, {"timestamp": 1631549229487, "ltp": 3.2, "tv": 4256.82, "trd": [[3.2, 1.71]], "batb": NaN, "batl": [[0, 5.6, 2.01], [1, 6.4, 2], [2, 7.8, 2]]}, {"timestamp": 1631549231682, "ltp": 3.2, "tv": 4256.82, "trd": NaN, "batb": [[0, 2.62, 5.54], [1, 2.5, 5.94], [2, 2.36, 27.68]], "batl": NaN}, {"timestamp": 1631549234600, "ltp": 3.2, "tv": 4256.82, "trd": NaN, "batb": [[0, 2.5, 5.94], [1, 2.36, 27.68], [2, 2, 5]], "batl": NaN}, {"timestamp": 1631549246620, "ltp": 3.2, "tv": 4256.82, "trd": NaN, "batb": NaN, "batl": [[0, 2.7, 74.08], [1, 2.72, 9.07], [2, 2.78, 184.68]]}, {"timestamp": 1631549247407, "ltp": 3.2, "tv": 4256.82, "trd": NaN, "batb": NaN, "batl": [[2, 2.78, 141.52]]}, {"timestamp": 1631549248028, "ltp": 3.2, "tv": 4256.82, "trd": NaN, "batb": [[2, 2.1, 38.67]], "batl": NaN}, {"timestamp": 1631549253989, "ltp": 3.2, "tv": 4256.82, "trd": NaN, "batb": [[2, 2.34, 6.72]], "batl": NaN}, {"timestamp": 1631549267620, "ltp": 3.2, "tv": 4256.82, "trd": NaN, "batb": [[0, 2.36, 27.68], [1, 2.34, 6.72], [2, 2.26, 6.48]], "batl": [[0, 3.5, 3.05], [1, 4.1, 3.05], [2, 5.6, 2.01]]}, {"timestamp": 1631549267933, "ltp": 3.2, "tv": 4256.82, "trd": NaN, "batb": [[0, 2.26, 6.48], [1, 2.1, 38.67], [2, 1.01, 105.79]], "batl": [[0, 4.1, 3.05], [1, 990, 0.01], [2, 5.6, 0]]}, {"timestamp": 1631549274727, "ltp": 3.2, "tv": 4256.82, "trd": NaN, "batb": [[0, 2.34, 6.72], [1, 2.26, 6.48], [2, 2.1, 38.67]], "batl": [[0, 3.5, 3.45], [1, 4.1, 3.05], [2, 990, 0.01]]}, {"timestamp": 1631549276038, "ltp": 3.2, "tv": 4256.82, "trd": NaN, "batb": [[0, 2.26, 6.48], [1, 2.1, 38.67], [2, 1.01, 105.79]], "batl": [[0, 4.1, 3.05], [1, 990, 0.01], [2, 990, 0]]}, {"timestamp": 1631549284473, "ltp": 3.2, "tv": 4256.82, "trd": NaN, "batb": [[0, 2.34, 6.72], [1, 2.26, 6.48], [2, 2.1, 38.67]], "batl": [[0, 3.5, 3.49], [1, 4.1, 3.05], [2, 990, 0.01]]}, {"timestamp": 1631549285662, "ltp": 3.2, "tv": 4256.82, "trd": NaN, "batb": [[0, 3.25, 5.8], [1, 3.2, 2], [2, 3.15, 28.57]], "batl": [[0, 3.35, 5.48]]}, {"timestamp": 1631549293432, "ltp": 3.2, "tv": 4256.82, "trd": NaN, "batb": NaN, "batl": [[2, 5.8, 2.02]]}, {"timestamp": 1631549297940, "ltp": 3.35, "tv": 4259.35, "trd": [[3.35, 32.69]], "batb": NaN, "batl": [[0, 3.35, 2.95]]}, {"timestamp": 1631549299648, "ltp": 3.35, "tv": 4259.35, "trd": NaN, "batb": [[0, 3.2, 2], [1, 3.15, 4.76], [2, 3.1, 2.38]], "batl": [[0, 4.1, 3.05], [1, 5.8, 2.02], [2, 8.2, 2]]}, {"timestamp": 1631549300271, "ltp": 3.35, "tv": 4259.35, "trd": NaN, "batb": [[0, 2.52, 5.99], [1, 2.38, 27.26], [2, 1.01, 105.79]], "batl": [[0, 5.8, 2.02], [1, 8.2, 2], [2, 990, 0.01]]}, {"timestamp": 1631549306882, "ltp": 3.35, "tv": 4259.35, "trd": NaN, "batb": [[0, 2.66, 4.78], [1, 2.52, 5.99], [2, 2.38, 27.26]], "batl": NaN}, {"timestamp": 1631549310171, "ltp": 3.35, "tv": 4259.35, "trd": NaN, "batb": [[0, 2.52, 5.99], [1, 2.38, 27.26], [2, 1.01, 105.79]], "batl": NaN}, {"timestamp": 1631549317571, "ltp": 3.35, "tv": 4259.35, "trd": NaN, "batb": NaN, "batl": [[0, 2.68, 44.77], [1, 2.78, 10.83], [2, 5.8, 2.02]]}, {"timestamp": 1631549318657, "ltp": 3.35, "tv": 4259.35, "trd": NaN, "batb": [[0, 2.62, 11.44], [1, 2.6, 5.72], [2, 2.58, 5.72]], "batl": NaN}, {"timestamp": 1631549324597, "ltp": 3.35, "tv": 4259.35, "trd": NaN, "batb": [[0, 2.52, 5.99], [1, 2.38, 27.26], [2, 2.12, 37.91]], "batl": [[0, 5.8, 2.02], [1, 8.2, 2], [2, 990, 0.01]]}, {"timestamp": 1631549325484, "ltp": 3.35, "tv": 4259.35, "trd": NaN, "batb": [[0, 2.36, 6.43], [1, 2.28, 6.16]], "batl": [[0, 3.6, 3.11], [1, 4.2, 2.78]]}, {"timestamp": 1631549325797, "ltp": 3.35, "tv": 4259.35, "trd": NaN, "batb": [[0, 2.28, 6.16], [1, 2.12, 37.91], [2, 1.01, 105.79]], "batl": [[0, 4.2, 2.78], [1, 990, 0.01], [2, 990, 0]]}, {"timestamp": 1631549341332, "ltp": 3.35, "tv": 4259.35, "trd": NaN, "batb": [[0, 3.3, 7.12], [1, 3.2, 2], [2, 3, 57.34]], "batl": [[0, 3.5, 51.97], [1, 4.2, 2.78], [2, 990, 0.01]]}, {"timestamp": 1631549347705, "ltp": 3.35, "tv": 4259.35, "trd": NaN, "batb": NaN, "batl": [[2, 5.8, 2.02]]}, {"timestamp": 1631549362555, "ltp": 3.35, "tv": 4259.35, "trd": NaN, "batb": [[0, 2.5, 7.36], [1, 2.38, 26.93], [2, 1.01, 105.79]], "batl": [[0, 5.8, 2.02], [1, 8.2, 2], [2, 990, 0.01]]}, {"timestamp": 1631549368609, "ltp": 3.35, "tv": 4259.35, "trd": NaN, "batb": NaN, "batl": [[0, 8.2, 2], [1, 990, 0.01], [2, 990, 0]]}, {"timestamp": 1631549370672, "ltp": 3.35, "tv": 4259.35, "trd": NaN, "batb": [[0, 4.6, 19.56], [1, 4.5, 36.44], [2, 4.4, 9.78]], "batl": [[0, 5.5, 101.44], [1, 8.2, 2], [2, 990, 0.01]]}, {"timestamp": 1631549371777, "ltp": 3.35, "tv": 4259.35, "trd": NaN, "batb": [[0, 4.6, 6.52], [1, 4.5, 29.92], [2, 4.4, 3.26]], "batl": NaN}, {"timestamp": 1631549386211, "ltp": 3.35, "tv": 4259.35, "trd": NaN, "batb": NaN, "batl": [[0, 4.9, 25.58], [1, 5.5, 101.44], [2, 8.2, 2]]}, {"timestamp": 1631549392502, "ltp": 4.9, "tv": 4260.39, "trd": [[4.9, 1.04]], "batb": NaN, "batl": [[0, 4.9, 24.54]]}, {"timestamp": 1631549393018, "ltp": 4.9, "tv": 4260.39, "trd": NaN, "batb": NaN, "batl": [[0, 5.5, 101.44], [1, 8.2, 2], [2, 990, 0.01]]}, {"timestamp": 1631549396558, "ltp": 4.9, "tv": 4260.39, "trd": NaN, "batb": [[0, 4.8, 4.99], [1, 4.6, 6.52], [2, 4.5, 29.92]], "batl": [[0, 5, 4.01], [1, 5.5, 101.44], [2, 8.2, 2]]}, {"timestamp": 1631549406659, "ltp": 4.7, "tv": 4314.83, "trd": [[4.7, 0.02], [4.8, 54.43]], "batb": [[0, 4.6, 6.52], [1, 4.5, 29.92], [2, 4.4, 3.26]], "batl": NaN}, {"timestamp": 1631549417168, "ltp": 4.7, "tv": 4350.64, "trd": [[4.7, 35.83]], "batb": NaN, "batl": [[0, 5.5, 101.44], [1, 8.2, 2], [2, 990, 0.01]]}, {"timestamp": 1631549420660, "ltp": 4.7, "tv": 4350.64, "trd": NaN, "batb": NaN, "batl": [[0, 5, 4.4], [1, 5.5, 101.44], [2, 8.2, 2]]}, {"timestamp": 1631549441824, "ltp": 4.7, "tv": 4351.03, "trd": [[4.7, 36.22]], "batb": NaN, "batl": NaN}, {"timestamp": 1631549446522, "ltp": 4.7, "tv": 4352.73, "trd": [[4.7, 37.92]], "batb": NaN, "batl": NaN}, {"timestamp": 1631549492406, "ltp": 4.7, "tv": 4352.73, "trd": NaN, "batb": NaN, "batl": [[0, 5.5, 101.44], [1, 8.2, 2], [2, 990, 0.01]]}, {"timestamp": 1631549495285, "ltp": 4.7, "tv": 4352.73, "trd": NaN, "batb": NaN, "batl": [[0, 5, 3.96], [1, 5.5, 101.44], [2, 8.2, 2]]}, {"timestamp": 1631549517247, "ltp": 4.7, "tv": 4352.73, "trd": NaN, "batb": [[0, 3.65, 21.98], [1, 1.01, 105.79], [2, 4.4, 0]], "batl": [[0, 990, 0.01], [1, 5.5, 0], [2, 8.2, 0]]}, {"timestamp": 1631549549381, "ltp": 4.7, "tv": 4352.73, "trd": NaN, "batb": [[0, 4, 34], [1, 3.95, 33], [2, 3.9, 33]], "batl": [[0, 4.3, 3.9], [1, 4.5, 60.89], [2, 990, 0.01]]}, {"timestamp": 1631549555635, "ltp": 4.7, "tv": 4352.73, "trd": NaN, "batb": NaN, "batl": [[2, 4.9, 2.25]]}, {"timestamp": 1631549573619, "ltp": 4.7, "tv": 4352.73, "trd": NaN, "batb": [[0, 3.65, 21.98], [1, 3.6, 2.84], [2, 3.4, 3.56]], "batl": [[0, 4.9, 2.25], [1, 5.2, 2.13], [2, 990, 0.01]]}, {"timestamp": 1631549574038, "ltp": 4.7, "tv": 4352.73, "trd": NaN, "batb": [[0, 3.4, 3.56], [1, 3.3, 28.44], [2, 1.01, 105.79]], "batl": NaN}, {"timestamp": 1631549575131, "ltp": 4.7, "tv": 4352.73, "trd": NaN, "batb": NaN, "batl": [[0, 5.2, 2.13], [1, 990, 0.01], [2, 990, 0]]}, {"timestamp": 1631549579520, "ltp": 4.7, "tv": 4352.73, "trd": NaN, "batb": [[0, 4.5, 44.44], [1, 4.4, 61.09], [2, 4.3, 3.4]], "batl": [[0, 4.8, 5.43], [1, 5, 30.17], [2, 5.2, 2.13]]}, {"timestamp": 1631549580634, "ltp": 4.7, "tv": 4352.73, "trd": NaN, "batb": NaN, "batl": [[1, 5, 36.17], [2, 5.1, 3]]}, {"timestamp": 1631549596660, "ltp": 4.7, "tv": 4352.73, "trd": NaN, "batb": [[0, 3.85, 2.97], [1, 3.6, 22.9], [2, 3.4, 3.56]], "batl": [[0, 5.4, 2.04], [1, 5.6, 2.01], [2, 990, 0.01]]}, {"timestamp": 1631549596972, "ltp": 4.7, "tv": 4352.73, "trd": NaN, "batb": [[2, 1.01, 105.79]], "batl": [[1, 990, 0.01], [2, 990, 0]]}, {"timestamp": 1631549599647, "ltp": 4.7, "tv": 4352.73, "trd": NaN, "batb": NaN, "batl": [[0, 5.2, 2.03], [1, 5.4, 2.04], [2, 990, 0.01]]}, {"timestamp": 1631549600258, "ltp": 4.7, "tv": 4352.73, "trd": NaN, "batb": NaN, "batl": [[0, 5.4, 2.04], [1, 990, 0.01], [2, 990, 0]]}, {"timestamp": 1631549601672, "ltp": 4.7, "tv": 4352.73, "trd": NaN, "batb": NaN, "batl": [[0, 4.9, 20.65], [1, 5.4, 2.04], [2, 990, 0.01]]}, {"timestamp": 1631549601883, "ltp": 4.7, "tv": 4352.73, "trd": NaN, "batb": NaN, "batl": [[0, 5.4, 2.04], [1, 990, 0.01], [2, 990, 0]]}, {"timestamp": 1631549603459, "ltp": 4.7, "tv": 4352.73, "trd": NaN, "batb": [[0, 4, 2.68], [1, 3.85, 2.97], [2, 3.6, 22.9]], "batl": [[0, 5.2, 2.23], [1, 5.4, 2.04], [2, 990, 0.01]]}, {"timestamp": 1631549607268, "ltp": 4.7, "tv": 4352.73, "trd": NaN, "batb": NaN, "batl": [[0, 5.4, 2.04], [1, 990, 0.01], [2, 990, 0]]}, {"timestamp": 1631549610473, "ltp": 4.7, "tv": 4352.73, "trd": NaN, "batb": NaN, "batl": [[0, 5.2, 2.03], [1, 5.4, 2.04], [2, 990, 0.01]]}, {"timestamp": 1631549610981, "ltp": 4.7, "tv": 4352.73, "trd": NaN, "batb": NaN, "batl": [[0, 5.4, 2.04], [1, 990, 0.01], [2, 990, 0]]}, {"timestamp": 1631549614508, "ltp": 4.7, "tv": 4352.73, "trd": NaN, "batb": [[0, 5.1, 26.66], [1, 5, 25.88], [2, 4.9, 25.88]], "batl": [[1, 5.5, 42.84], [2, 5.9, 23.04]]}, {"timestamp": 1631549620285, "ltp": 4.7, "tv": 4352.73, "trd": NaN, "batb": NaN, "batl": [[2, 5.6, 2.01]]}, {"timestamp": 1631549634416, "ltp": 4.7, "tv": 4352.73, "trd": NaN, "batb": [[0, 4.3, 2.58], [1, 3.95, 35.82], [2, 3.85, 2.97]], "batl": [[0, 5.8, 2.02], [1, 990, 0.01], [2, 5.6, 0]]}, {"timestamp": 1631549636619, "ltp": 4.7, "tv": 4352.73, "trd": NaN, "batb": [[2, 1.01, 105.79]], "batl": NaN}, {"timestamp": 1631549637609, "ltp": 4.7, "tv": 4352.73, "trd": NaN, "batb": [[0, 4.5, 2.58], [1, 4.3, 2.58], [2, 3.95, 35.82]], "batl": [[0, 5.6, 2.01], [1, 5.8, 2.02], [2, 990, 0.01]]}, {"timestamp": 1631549637924, "ltp": 4.7, "tv": 4352.73, "trd": NaN, "batb": [[0, 4.3, 2.58], [1, 3.95, 35.82], [2, 1.01, 105.79]], "batl": [[0, 5.8, 2.02], [1, 990, 0.01], [2, 990, 0]]}, {"timestamp": 1631549639655, "ltp": 4.7, "tv": 4352.73, "trd": NaN, "batb": [[0, 5.3, 56.42], [1, 5.2, 41.3], [2, 5.1, 2.84]], "batl": [[0, 5.7, 5.39], [1, 5.8, 2.02], [2, 6, 18.69]]}, {"timestamp": 1631549646036, "ltp": 4.7, "tv": 4352.73, "trd": NaN, "batb": [[2, 5.1, 4.88]], "batl": [[2, 6, 20.7]]}, {"timestamp": 1631549652462, "ltp": 4.7, "tv": 4352.73, "trd": NaN, "batb": [[0, 5, 2.05], [1, 4.4, 27.26], [2, 1.01, 105.79]], "batl": [[0, 6.4, 2], [1, 990, 0.01], [2, 6, 0]]}, {"timestamp": 1631549663664, "ltp": 4.7, "tv": 4352.73, "trd": NaN, "batb": [[1, 4.7, 28.94], [2, 4.6, 28.1]], "batl": [[0, 5.5, 67.78], [1, 5.6, 24], [2, 5.7, 24]]}, {"timestamp": 1631549688401, "ltp": 4.7, "tv": 4352.73, "trd": NaN, "batb": [[0, 4.2, 2.37], [1, 3.9, 37.07], [2, 1.01, 105.79]], "batl": [[0, 6.4, 2], [1, 990, 0.01], [2, 5.7, 0]]}, {"timestamp": 1631549691616, "ltp": 4.7, "tv": 4352.73, "trd": NaN, "batb": [[0, 4.4, 2.51], [1, 4.2, 2.37], [2, 3.9, 37.07]], "batl": [[0, 5.8, 2.02], [1, 6.4, 2], [2, 990, 0.01]]}, {"timestamp": 1631549691937, "ltp": 4.7, "tv": 4352.73, "trd": NaN, "batb": [[0, 4.2, 2.37], [1, 3.9, 37.07], [2, 1.01, 105.79]], "batl": [[0, 6.4, 2], [1, 990, 0.01], [2, 990, 0]]}, {"timestamp": 1631549696509, "ltp": 4.7, "tv": 4352.73, "trd": NaN, "batb": [[0, 5.5, 30.43], [1, 5.4, 24], [2, 5.3, 24]], "batl": [[0, 6.2, 53.88], [1, 6.4, 2], [2, 6.8, 20]]}, {"timestamp": 1631549697351, "ltp": 4.7, "tv": 4352.73, "trd": NaN, "batb": [[0, 5.5, 28.43]], "batl": NaN}, {"timestamp": 1631549719478, "ltp": 5.5, "tv": 4431.16, "trd": [[5.5, 78.43]], "batb": [[0, 5.4, 24], [1, 5.3, 24], [2, 4.8, 21.22]], "batl": NaN}, {"timestamp": 1631549722671, "ltp": 5.5, "tv": 4431.16, "trd": NaN, "batb": NaN, "batl": [[0, 6.2, 58.26]]}, {"timestamp": 1631549732598, "ltp": 5.5, "tv": 4431.16, "trd": NaN, "batb": NaN, "batl": [[0, 5.7, 6.36], [1, 6.2, 58.26], [2, 6.4, 2]]}, {"timestamp": 1631549733491, "ltp": 5.5, "tv": 4431.32, "trd": [[5.5, 78.58]], "batb": NaN, "batl": NaN}, {"timestamp": 1631549739888, "ltp": 5.5, "tv": 4431.32, "trd": NaN, "batb": NaN, "batl": [[0, 6.2, 58.26], [1, 6.4, 2], [2, 6.8, 20]]}, {"timestamp": 1631549742918, "ltp": 5.5, "tv": 4431.32, "trd": NaN, "batb": NaN, "batl": [[0, 5.7, 6.34], [1, 6.2, 58.26], [2, 6.4, 2]]}, {"timestamp": 1631549755453, "ltp": 5.4, "tv": 4431.4, "trd": [[5.4, 0.08]], "batb": [[0, 5.4, 23.96]], "batl": NaN}, {"timestamp": 1631549756753, "ltp": 5.4, "tv": 4431.4, "trd": NaN, "batb": [[2, 5, 2]], "batl": NaN}, {"timestamp": 1631549762668, "ltp": 5.4, "tv": 4431.4, "trd": NaN, "batb": [[0, 5, 2], [1, 4.8, 23.55], [2, 4.4, 26.93]], "batl": [[0, 6.4, 2], [1, 7, 2], [2, 7.8, 2]]}, {"timestamp": 1631549763662, "ltp": 5.4, "tv": 4431.4, "trd": NaN, "batb": [[0, 4.8, 2.33], [1, 4.4, 26.93], [2, 1.01, 105.79]], "batl": [[0, 7.8, 2], [1, 990, 0.01], [2, 7.8, 0]]}, {"timestamp": 1631549768642, "ltp": 5.4, "tv": 4431.4, "trd": NaN, "batb": NaN, "batl": [[0, 5.1, 3.99], [1, 5.3, 28.3], [2, 5.4, 14.16]]}, {"timestamp": 1631549769638, "ltp": 5.4, "tv": 4431.4, "trd": NaN, "batb": [[2, 4.1, 32.38]], "batl": [[1, 5.3, 5.66], [2, 5.4, 2.84]]}, {"timestamp": 1631549775717, "ltp": 5.4, "tv": 4431.4, "trd": NaN, "batb": [[1, 4.7, 2.32], [2, 4.5, 2.58]], "batl": NaN}, {"timestamp": 1631549777495, "ltp": 5.4, "tv": 4431.4, "trd": NaN, "batb": [[0, 4.7, 2.32], [1, 4.5, 2.58], [2, 4.4, 26.93]], "batl": [[0, 5.8, 2.02], [1, 6.4, 2], [2, 7.8, 2]]}, {"timestamp": 1631549777919, "ltp": 5.4, "tv": 4431.4, "trd": NaN, "batb": [[0, 4.5, 2.58], [1, 4.1, 32.38], [2, 1.01, 105.79]], "batl": [[0, 6.4, 2], [1, 7.8, 2], [2, 990, 0.01]]}, {"timestamp": 1631549783621, "ltp": 5.4, "tv": 4431.4, "trd": NaN, "batb": NaN, "batl": [[0, 5.2, 19.28], [1, 6.4, 2], [2, 7.8, 2]]}, {"timestamp": 1631549784623, "ltp": 5.4, "tv": 4431.4, "trd": NaN, "batb": [[0, 4.7, 2.32], [1, 4.5, 2.58], [2, 4.1, 32.38]], "batl": [[0, 5.8, 2.02]]}, {"timestamp": 1631549785713, "ltp": 5.4, "tv": 4431.4, "trd": NaN, "batb": [[0, 4.5, 2.58], [1, 4.1, 32.38], [2, 1.01, 105.79]], "batl": [[0, 6.4, 2], [1, 7.8, 2], [2, 990, 0.01]]}, {"timestamp": 1631549792443, "ltp": 5.4, "tv": 4431.4, "trd": NaN, "batb": [[0, 4.7, 2.32], [1, 4.5, 2.58], [2, 4.1, 32.38]], "batl": [[0, 5.8, 2.02], [1, 6.4, 2], [2, 7.8, 2]]}, {"timestamp": 1631549793599, "ltp": 5.4, "tv": 4431.4, "trd": NaN, "batb": [[0, 4.5, 9.4], [1, 4.3, 63.26], [2, 4.2, 61.4]], "batl": [[0, 4.8, 7.7], [1, 5.1, 43.85], [2, 6.4, 2]]}, {"timestamp": 1631549794535, "ltp": 5.4, "tv": 4431.4, "trd": NaN, "batb": [[1, 4.3, 31.64], [2, 4.2, 30.7]], "batl": NaN}, {"timestamp": 1631549800750, "ltp": 5.4, "tv": 4431.4, "trd": NaN, "batb": [[1, 4.4, 2.16], [2, 4.3, 34.42]], "batl": [[2, 5.2, 2.08]]}, {"timestamp": 1631549803621, "ltp": 5.4, "tv": 4431.4, "trd": NaN, "batb": [[0, 4.4, 2.16], [1, 4.3, 2.78], [2, 4.1, 32.38]], "batl": [[0, 5.2, 2.08], [1, 5.4, 2.04], [2, 6.4, 2]]}, {"timestamp": 1631549803834, "ltp": 5.4, "tv": 4431.4, "trd": NaN, "batb": [[0, 4.3, 2.78], [1, 3.9, 36.99], [2, 1.01, 105.79]], "batl": [[0, 5.4, 2.04], [1, 6.4, 2], [2, 7.8, 2]]}, {"timestamp": 1631549810633, "ltp": 5.4, "tv": 4431.4, "trd": NaN, "batb": [[0, 4.4, 2.61], [1, 4.3, 2.78], [2, 3.9, 36.99]], "batl": [[0, 5.2, 2.03], [1, 5.4, 2.04], [2, 6.4, 2]]}, {"timestamp": 1631549810838, "ltp": 5.4, "tv": 4431.4, "trd": NaN, "batb": [[0, 4.3, 2.78], [1, 3.9, 36.99], [2, 1.01, 105.79]], "batl": [[0, 5.4, 2.04], [1, 6.4, 2], [2, 7.8, 2]]}, {"timestamp": 1631549814571, "ltp": 5.4, "tv": 4431.4, "trd": NaN, "batb": [[0, 4.4, 2.36], [1, 4.3, 2.78], [2, 3.9, 36.99]], "batl": [[0, 5.2, 2.13], [1, 5.4, 2.04], [2, 6.4, 2]]}, {"timestamp": 1631549814775, "ltp": 5.4, "tv": 4431.4, "trd": NaN, "batb": [[0, 4.3, 2.78], [1, 3.9, 36.99], [2, 1.01, 105.79]], "batl": [[0, 5.4, 2.04], [1, 6.4, 2], [2, 7.8, 2]]}, {"timestamp": 1631549816580, "ltp": 5.4, "tv": 4431.4, "trd": NaN, "batb": [[0, 4.3, 8.06]], "batl": [[0, 4.5, 5.69], [1, 4.7, 74.48], [2, 4.8, 57.17]]}, {"timestamp": 1631549817571, "ltp": 5.4, "tv": 4431.4, "trd": NaN, "batb": [[2, 3.75, 40.68]], "batl": [[1, 4.7, 44.69], [2, 4.8, 50.79]]}, {"timestamp": 1631549817786, "ltp": 5.4, "tv": 4431.4, "trd": NaN, "batb": NaN, "batl": [[1, 4.7, 31.92], [2, 4.8, 44.41]]}, {"timestamp": 1631549824505, "ltp": 5.4, "tv": 4431.4, "trd": NaN, "batb": [[1, 4.2, 2.57], [2, 3.9, 36.99]], "batl": NaN}, {"timestamp": 1631549834404, "ltp": 4.3, "tv": 4439.2, "trd": [[4.3, 7.8]], "batb": [[0, 4.3, 4.16]], "batl": NaN}, {"timestamp": 1631549837827, "ltp": 4.3, "tv": 4439.2, "trd": NaN, "batb": [[0, 4.3, 6.64]], "batl": NaN}, {"timestamp": 1631549844643, "ltp": 4.3, "tv": 4439.2, "trd": NaN, "batb": [[0, 4.3, 2.48]], "batl": [[0, 4.7, 31.92], [1, 4.8, 44.41], [2, 4.9, 5.25]]}, {"timestamp": 1631549847619, "ltp": 4.3, "tv": 4439.2, "trd": NaN, "batb": [[0, 4.3, 6.64]], "batl": NaN}, {"timestamp": 1631549849351, "ltp": 4.3, "tv": 4439.2, "trd": NaN, "batb": [[0, 3.9, 36.99], [1, 3.75, 40.68], [2, 1.01, 105.79]], "batl": [[0, 4.9, 2.05], [1, 5.4, 2.04], [2, 6.4, 2]]}, {"timestamp": 1631549849827, "ltp": 4.3, "tv": 4439.2, "trd": NaN, "batb": [[0, 3.75, 40.68], [1, 1.01, 105.79], [2, 1.01, 0]], "batl": NaN}, {"timestamp": 1631549852539, "ltp": 4.3, "tv": 4439.2, "trd": NaN, "batb": [[0, 4.3, 2.58], [1, 4.2, 2.47], [2, 3.75, 40.68]], "batl": NaN}, {"timestamp": 1631549852753, "ltp": 4.3, "tv": 4439.2, "trd": NaN, "batb": [[0, 4.2, 2.47], [1, 3.75, 40.68], [2, 1.01, 105.79]], "batl": NaN}, {"timestamp": 1631549858133, "ltp": 4.3, "tv": 4439.2, "trd": NaN, "batb": NaN, "batl": [[0, 4.3, 3.63], [1, 4.6, 2], [2, 4.7, 61.1]]}, {"timestamp": 1631549859270, "ltp": 4.3, "tv": 4439.2, "trd": NaN, "batb": [[1, 4, 7.5], [2, 3.95, 3.76]], "batl": NaN}, {"timestamp": 1631549870053, "ltp": 4.3, "tv": 4439.84, "trd": [[4.3, 8.44]], "batb": NaN, "batl": [[0, 4.3, 2.99]]}, {"timestamp": 1631549872255, "ltp": 4.2, "tv": 4440.21, "trd": [[4.2, 0.38]], "batb": [[0, 4.2, 2.28]], "batl": NaN}, {"timestamp": 1631549873193, "ltp": 4.2, "tv": 4442.01, "trd": [[4.2, 2.18]], "batb": [[0, 4.2, 1.38]], "batl": NaN}, {"timestamp": 1631549874673, "ltp": 4.3, "tv": 4445.0, "trd": [[4.3, 11.43]], "batb": NaN, "batl": [[0, 4.6, 2], [1, 4.7, 61.1], [2, 4.9, 2.05]]}, {"timestamp": 1631549883276, "ltp": 4.3, "tv": 4445.0, "trd": NaN, "batb": NaN, "batl": [[0, 4.4, 5.64], [1, 4.6, 2], [2, 4.7, 61.1]]}, {"timestamp": 1631549884269, "ltp": 4.3, "tv": 4445.0, "trd": NaN, "batb": NaN, "batl": [[0, 4.6, 2], [1, 4.7, 61.1], [2, 4.9, 2.05]]}, {"timestamp": 1631549887619, "ltp": 4.3, "tv": 4445.0, "trd": NaN, "batb": [[0, 3.85, 3.17], [1, 3.75, 3.07], [2, 3.7, 3.32]], "batl": [[0, 4.9, 2.05], [1, 5.2, 2.18], [2, 5.4, 2.04]]}, {"timestamp": 1631549887890, "ltp": 4.3, "tv": 4445.0, "trd": NaN, "batb": [[0, 3.7, 3.32], [1, 3.35, 27.18], [2, 1.01, 105.79]], "batl": [[0, 5.2, 2.18], [1, 6.4, 2], [2, 7.8, 2]]}, {"timestamp": 1631549892503, "ltp": 4.3, "tv": 4445.0, "trd": NaN, "batb": NaN, "batl": [[0, 4.5, 40.65], [1, 5.2, 2.18], [2, 6.4, 2]]}, {"timestamp": 1631549892820, "ltp": 4.3, "tv": 4445.0, "trd": NaN, "batb": NaN, "batl": [[0, 5.2, 2.18], [1, 6.4, 2], [2, 7.8, 2]]}, {"timestamp": 1631549894495, "ltp": 4.3, "tv": 4445.0, "trd": NaN, "batb": [[0, 3.85, 2.97], [1, 3.7, 3.32], [2, 3.35, 27.18]], "batl": [[0, 4.9, 2.05], [1, 5.2, 2.18], [2, 6.4, 2]]}, {"timestamp": 1631549897692, "ltp": 4.3, "tv": 4445.0, "trd": NaN, "batb": [[0, 3.7, 3.32], [1, 3.35, 27.18], [2, 1.01, 105.79]], "batl": [[0, 5.2, 2.18], [1, 6.4, 2], [2, 7.8, 2]]}, {"timestamp": 1631549900996, "ltp": 4.3, "tv": 4445.0, "trd": NaN, "batb": [[0, 3.85, 2.97], [1, 3.7, 3.32], [2, 3.35, 27.18]], "batl": [[0, 4.9, 2.15], [1, 5.2, 2.18], [2, 6.4, 2]]}, {"timestamp": 1631549901986, "ltp": 4.3, "tv": 4445.0, "trd": NaN, "batb": [[0, 3.7, 3.32], [1, 3.35, 27.18], [2, 1.01, 105.79]], "batl": [[0, 5.2, 2.18], [1, 6.4, 2], [2, 7.8, 2]]}, {"timestamp": 1631549905123, "ltp": 4.3, "tv": 4445.0, "trd": NaN, "batb": [[0, 4.5, 33.32], [1, 4.4, 16.66], [2, 4.3, 16.66]], "batl": [[0, 4.8, 4.53], [1, 5.2, 2.18], [2, 6.4, 2]]}, {"timestamp": 1631549906135, "ltp": 4.3, "tv": 4445.0, "trd": NaN, "batb": [[0, 4.5, 6.66], [1, 4.4, 3.34], [2, 4.3, 3.34]], "batl": [[1, 5.1, 5.88], [2, 5.2, 5.12]]}, {"timestamp": 1631549922837, "ltp": 4.3, "tv": 4445.0, "trd": NaN, "batb": NaN, "batl": [[0, 5.1, 5.88], [1, 5.2, 5.12], [2, 5.3, 2.94]]}, {"timestamp": 1631549924510, "ltp": 4.3, "tv": 4445.0, "trd": NaN, "batb": [[0, 4, 2.79], [1, 3.65, 21.89], [2, 1.01, 105.79]], "batl": [[0, 5.4, 2.04], [1, 6.4, 2], [2, 7.8, 2]]}, {"timestamp": 1631549927536, "ltp": 4.3, "tv": 4445.0, "trd": NaN, "batb": [[0, 4.2, 2.57], [1, 4, 2.79], [2, 3.65, 21.89]], "batl": [[0, 5.2, 2.03], [1, 5.4, 2.04], [2, 6.4, 2]]}, {"timestamp": 1631549927748, "ltp": 4.3, "tv": 4445.0, "trd": NaN, "batb": [[0, 4, 2.79], [1, 3.65, 21.89], [2, 1.01, 105.79]], "batl": [[0, 5.4, 2.04], [1, 6.4, 2], [2, 7.8, 2]]}, {"timestamp": 1631549931041, "ltp": 4.3, "tv": 4445.0, "trd": NaN, "batb": [[0, 4.2, 2.77], [1, 4, 2.79], [2, 3.65, 21.89]], "batl": [[0, 5.2, 2.08], [1, 5.4, 2.04], [2, 6.4, 2]]}, {"timestamp": 1631549933533, "ltp": 4.3, "tv": 4445.0, "trd": NaN, "batb": [[0, 4, 2.79], [1, 3.65, 21.89], [2, 1.01, 105.79]], "batl": [[0, 5.4, 2.04], [1, 6.4, 2], [2, 7.8, 2]]}, {"timestamp": 1631549940466, "ltp": 4.3, "tv": 4445.0, "trd": NaN, "batb": [[0, 4.2, 2.57], [1, 4, 2.79], [2, 3.65, 21.89]], "batl": [[0, 5.2, 2.08], [1, 5.4, 2.04], [2, 6.4, 2]]}, {"timestamp": 1631549940736, "ltp": 4.3, "tv": 4445.0, "trd": NaN, "batb": [[0, 4, 2.79], [1, 3.65, 21.89], [2, 1.01, 105.79]], "batl": [[0, 5.4, 2.04], [1, 6.4, 2], [2, 7.8, 2]]}, {"timestamp": 1631549942659, "ltp": 4.3, "tv": 4445.0, "trd": NaN, "batb": [[0, 4.1, 4.75], [1, 4, 2.79], [2, 3.65, 21.89]], "batl": [[0, 4.3, 823.39], [1, 4.4, 34.1], [2, 4.5, 17.04]]}, {"timestamp": 1631549943651, "ltp": 4.3, "tv": 4445.0, "trd": NaN, "batb": [[2, 3.95, 37.96]], "batl": [[0, 4.3, 7.51], [1, 4.4, 6.82], [2, 4.5, 5.4]]}, {"timestamp": 1631549943963, "ltp": 4.3, "tv": 4445.0, "trd": NaN, "batb": [[2, 3.95, 7.6]], "batl": NaN}, {"timestamp": 1631549961462, "ltp": 4.3, "tv": 4445.0, "trd": NaN, "batb": [[0, 3.35, 3.47], [1, 3.2, 30.45], [2, 1.01, 105.79]], "batl": [[0, 4.9, 2.35], [1, 5.2, 2.08], [2, 5.4, 2.04]]}, {"timestamp": 1631549961771, "ltp": 4.3, "tv": 4445.0, "trd": NaN, "batb": NaN, "batl": [[0, 5.2, 2.08], [1, 5.4, 2.04], [2, 6.4, 2]]}, {"timestamp": 1631549964583, "ltp": 4.3, "tv": 4445.0, "trd": NaN, "batb": [[0, 3.55, 3.39], [1, 3.35, 3.47], [2, 3.2, 30.45]], "batl": NaN}, {"timestamp": 1631549965368, "ltp": 4.3, "tv": 4445.0, "trd": NaN, "batb": [[0, 3.35, 3.47], [1, 3.2, 30.45], [2, 1.01, 105.79]], "batl": NaN}, {"timestamp": 1631549966672, "ltp": 4.3, "tv": 4445.0, "trd": NaN, "batb": NaN, "batl": [[0, 4.3, 20.65], [1, 5.2, 2.08], [2, 5.4, 2.04]]}, {"timestamp": 1631549966989, "ltp": 4.3, "tv": 4445.0, "trd": NaN, "batb": NaN, "batl": [[0, 5.2, 2.08], [1, 5.4, 2.04], [2, 6.4, 2]]}, {"timestamp": 1631549968592, "ltp": 4.3, "tv": 4445.0, "trd": NaN, "batb": [[0, 3.55, 3.39], [1, 3.35, 3.47], [2, 3.2, 30.45]], "batl": [[0, 4.9, 2.45], [1, 5.2, 2.08], [2, 5.4, 2.04]]}, {"timestamp": 1631549971472, "ltp": 4.3, "tv": 4445.0, "trd": NaN, "batb": [[0, 3.35, 3.47], [1, 3.2, 30.45], [2, 1.01, 105.79]], "batl": [[0, 5.2, 2.08], [1, 5.4, 2.04], [2, 6.4, 2]]}, {"timestamp": 1631549974909, "ltp": 4.3, "tv": 4445.0, "trd": NaN, "batb": NaN, "batl": [[0, 4.9, 2.15], [1, 5.2, 2.08], [2, 5.4, 2.04]]}, {"timestamp": 1631549977399, "ltp": 4.3, "tv": 4445.0, "trd": NaN, "batb": NaN, "batl": [[0, 5.2, 2.08], [1, 5.4, 2.04], [2, 6.4, 2]]}, {"timestamp": 1631549980106, "ltp": 4.3, "tv": 4445.0, "trd": NaN, "batb": [[0, 3.5, 36.07], [1, 3.35, 3.47], [2, 3.2, 30.45]], "batl": [[0, 3.7, 63.05], [1, 3.8, 9.9], [2, 3.85, 3.94]]}, {"timestamp": 1631549981192, "ltp": 4.3, "tv": 4445.0, "trd": NaN, "batb": [[1, 3.45, 8.7], [2, 3.4, 4.34]], "batl": NaN}, {"timestamp": 1631549984898, "ltp": 3.5, "tv": 4465.0, "trd": [[3.5, 20]], "batb": [[0, 3.5, 26.07]], "batl": NaN}, {"timestamp": 1631549994804, "ltp": 3.5, "tv": 4465.0, "trd": NaN, "batb": NaN, "batl": [[0, 3.7, 54.06]]}, {"timestamp": 1631549997824, "ltp": 3.5, "tv": 4465.0, "trd": NaN, "batb": NaN, "batl": [[0, 3.6, 4.72], [1, 3.7, 54.06], [2, 3.8, 9.9]]}, {"timestamp": 1631550002642, "ltp": 3.5, "tv": 4465.0, "trd": NaN, "batb": [[0, 3.2, 30.45], [1, 2.84, 4.22], [2, 2.78, 17.78]], "batl": [[0, 4.6, 2.36], [1, 5.2, 2.08], [2, 5.4, 2.04]]}, {"timestamp": 1631550002842, "ltp": 3.5, "tv": 4465.0, "trd": NaN, "batb": [[0, 2.84, 4.22], [1, 2.78, 17.78], [2, 1.01, 105.79]], "batl": NaN}, {"timestamp": 1631550006142, "ltp": 3.5, "tv": 4465.0, "trd": NaN, "batb": [[1, 2.8, 17.53]], "batl": [[0, 4.3, 2.65], [1, 4.6, 2.36], [2, 5.2, 2.08]]}, {"timestamp": 1631550011558, "ltp": 3.5, "tv": 4465.0, "trd": NaN, "batb": [[0, 3.8, 7.9], [1, 3.75, 3.94], [2, 3.7, 3.94]], "batl": [[0, 4.1, 6.17], [1, 4.3, 2.65], [2, 4.6, 2.36]]}, {"timestamp": 1631550012657, "ltp": 3.5, "tv": 4465.0, "trd": NaN, "batb": NaN, "batl": [[1, 4.2, 7.14], [2, 4.3, 6.23]]}, {"timestamp": 1631550023322, "ltp": 3.5, "tv": 4465.0, "trd": NaN, "batb": [[0, 3.15, 4.03], [1, 3.05, 34.31], [2, 1.01, 105.79]], "batl": [[0, 5, 2.12], [1, 5.4, 2.04], [2, 6.4, 2]]}, {"timestamp": 1631550026616, "ltp": 3.5, "tv": 4465.0, "trd": NaN, "batb": NaN, "batl": [[0, 5, 2.2]]}, {"timestamp": 1631550029301, "ltp": 3.9, "tv": 4465.08, "trd": [[3.9, 13.14]], "batb": [[0, 4.5, 58.25], [1, 3.15, 4.03], [2, 3.05, 34.31]], "batl": [[0, 4.7, 5.15], [1, 5, 2.12], [2, 5.4, 2.04]]}, {"timestamp": 1631550030293, "ltp": 3.9, "tv": 4465.08, "trd": NaN, "batb": [[1, 4, 33.89], [2, 3.55, 23.4]], "batl": NaN}, {"timestamp": 1631550035638, "ltp": 3.9, "tv": 4465.08, "trd": NaN, "batb": [[1, 4, 36.93], [2, 3.85, 3.37]], "batl": [[2, 5.2, 2.08]]}, {"timestamp": 1631550044435, "ltp": 4.7, "tv": 4465.23, "trd": [[4.7, 38.07]], "batb": NaN, "batl": [[0, 4.7, 5]]}, {"timestamp": 1631550046523, "ltp": 4.7, "tv": 4465.23, "trd": NaN, "batb": [[0, 3.85, 3.37], [1, 3.55, 23.4], [2, 1.01, 105.79]], "batl": [[0, 5.6, 2.01], [1, 6.4, 2], [2, 7.8, 2]]}, {"timestamp": 1631550049541, "ltp": 4.7, "tv": 4465.23, "trd": NaN, "batb": [[0, 4, 2.79], [1, 3.85, 3.37], [2, 3.55, 23.4]], "batl": [[0, 5.2, 2.03], [1, 5.6, 2.01], [2, 6.4, 2]]}, {"timestamp": 1631550049858, "ltp": 4.7, "tv": 4465.23, "trd": NaN, "batb": [[0, 3.85, 3.37], [1, 3.55, 23.4], [2, 1.01, 105.79]], "batl": [[0, 5.6, 2.01], [1, 6.4, 2], [2, 7.8, 2]]}, {"timestamp": 1631550053430, "ltp": 4.7, "tv": 4465.23, "trd": NaN, "batb": NaN, "batl": [[1, 990, 0.01], [2, 7.8, 0]]}, {"timestamp": 1631550056463, "ltp": 4.7, "tv": 4465.23, "trd": NaN, "batb": [[0, 4.8, 25], [1, 3.85, 3.37], [2, 3.55, 23.4]], "batl": [[1, 5.7, 50.44], [2, 990, 0.01]]}, {"timestamp": 1631550057348, "ltp": 4.7, "tv": 4465.23, "trd": NaN, "batb": [[1, 4.4, 26.84], [2, 4, 33.55]], "batl": [[0, 5.5, 5.46], [1, 5.6, 4.73], [2, 5.7, 53.16]]}, {"timestamp": 1631550059286, "ltp": 4.7, "tv": 4465.23, "trd": NaN, "batb": NaN, "batl": [[0, 5.3, 7.73], [1, 5.5, 5.46], [2, 5.6, 4.73]]}, {"timestamp": 1631550093213, "ltp": 5.3, "tv": 4475.23, "trd": [[5.3, 10]], "batb": NaN, "batl": [[0, 5.3, 2.73]]}, {"timestamp": 1631550103329, "ltp": 5.3, "tv": 4475.23, "trd": NaN, "batb": NaN, "batl": [[0, 5.5, 5.46], [1, 5.6, 4.73], [2, 5.7, 53.16]]}, {"timestamp": 1631550106306, "ltp": 5.3, "tv": 4475.23, "trd": NaN, "batb": [[0, 5.1, 4.94], [1, 4.8, 25], [2, 4.4, 26.84]], "batl": NaN}, {"timestamp": 1631550146650, "ltp": 5.3, "tv": 4475.23, "trd": NaN, "batb": [[2, 4.5, 2.58]], "batl": NaN}, {"timestamp": 1631550155373, "ltp": 5.3, "tv": 4475.23, "trd": NaN, "batb": [[0, 4.3, 2.48], [1, 4, 33.55], [2, 1.01, 105.79]], "batl": [[0, 6.4, 2], [1, 7, 2], [2, 990, 0.01]]}, {"timestamp": 1631550155683, "ltp": 5.3, "tv": 4475.23, "trd": NaN, "batb": NaN, "batl": [[0, 7, 2], [1, 990, 0.01], [2, 990, 0]]}, {"timestamp": 1631550158605, "ltp": 5.3, "tv": 4475.23, "trd": NaN, "batb": [[0, 4.5, 2.64], [1, 4.3, 2.48], [2, 4, 33.55]], "batl": NaN}, {"timestamp": 1631550159073, "ltp": 5.3, "tv": 4475.23, "trd": NaN, "batb": [[0, 4.3, 2.48], [1, 4, 33.55], [2, 1.01, 105.79]], "batl": NaN}, {"timestamp": 1631550160579, "ltp": 5.3, "tv": 4475.23, "trd": NaN, "batb": NaN, "batl": [[0, 5.4, 38.54], [1, 7, 2], [2, 990, 0.01]]}, {"timestamp": 1631550160892, "ltp": 5.3, "tv": 4475.23, "trd": NaN, "batb": NaN, "batl": [[0, 7, 2], [1, 990, 0.01], [2, 990, 0]]}, {"timestamp": 1631550162295, "ltp": 5.3, "tv": 4475.23, "trd": NaN, "batb": [[0, 4.5, 2.58], [1, 4.3, 2.48], [2, 4, 33.55]], "batl": [[0, 6.4, 2], [1, 7, 2], [2, 990, 0.01]]}, {"timestamp": 1631550164894, "ltp": 5.3, "tv": 4475.23, "trd": NaN, "batb": [[0, 4.3, 2.48], [1, 4, 33.55], [2, 1.01, 105.79]], "batl": [[0, 7, 2], [1, 990, 0.01], [2, 990, 0]]}, {"timestamp": 1631550173420, "ltp": 5.3, "tv": 4475.23, "trd": NaN, "batb": [[1, 1.01, 105.79], [2, 1.01, 0]], "batl": NaN}, {"timestamp": 1631550175195, "ltp": 5.3, "tv": 4475.23, "trd": NaN, "batb": [[0, 4.5, 2.58], [1, 4.3, 2.48], [2, 1.01, 105.79]], "batl": [[0, 6.4, 2], [1, 7, 2], [2, 990, 0.01]]}, {"timestamp": 1631550176603, "ltp": 5.3, "tv": 4475.23, "trd": NaN, "batb": [[0, 4.5, 67.4], [1, 4.3, 34.12], [2, 4.2, 30.7]], "batl": [[0, 4.9, 2], [1, 5, 27.2], [2, 5.1, 26.4]]}, {"timestamp": 1631550182700, "ltp": 5.3, "tv": 4475.23, "trd": NaN, "batb": [[2, 4.2, 33.22]], "batl": NaN}, {"timestamp": 1631550191444, "ltp": 5.3, "tv": 4475.23, "trd": NaN, "batb": [[0, 4.2, 2.52], [1, 1.01, 105.79], [2, 4.2, 0]], "batl": [[0, 5.4, 2.04], [1, 990, 0.01], [2, 5.1, 0]]}, {"timestamp": 1631550194549, "ltp": 5.3, "tv": 4475.23, "trd": NaN, "batb": [[0, 4.3, 2.48], [1, 4.2, 2.52], [2, 1.01, 105.79]], "batl": [[0, 5.2, 2.03], [1, 5.4, 2.04], [2, 990, 0.01]]}, {"timestamp": 1631550194819, "ltp": 5.3, "tv": 4475.23, "trd": NaN, "batb": [[0, 4.2, 2.52], [1, 1.01, 105.79], [2, 1.01, 0]], "batl": [[0, 5.4, 2.04], [1, 990, 0.01], [2, 990, 0]]}, {"timestamp": 1631550198622, "ltp": 5.3, "tv": 4475.23, "trd": NaN, "batb": [[0, 4.3, 5.39], [1, 4.2, 2.52], [2, 4, 68]], "batl": [[0, 4.5, 5.76], [1, 4.7, 43.02], [2, 5.4, 2.04]]}, {"timestamp": 1631550199246, "ltp": 5.3, "tv": 4475.23, "trd": NaN, "batb": [[2, 4, 34]], "batl": [[0, 4.5, 7.76]]}, {"timestamp": 1631550205245, "ltp": 5.3, "tv": 4475.23, "trd": NaN, "batb": [[2, 4.1, 2.64]], "batl": [[2, 4.8, 2.32]]}, {"timestamp": 1631550212626, "ltp": 5.3, "tv": 4475.23, "trd": NaN, "batb": [[0, 1.01, 105.79], [1, 4.2, 0], [2, 4.1, 0]], "batl": [[0, 4.9, 2.15], [1, 990, 0.01], [2, 4.8, 0]]}, {"timestamp": 1631550215544, "ltp": 5.3, "tv": 4475.23, "trd": NaN, "batb": [[0, 4.1, 3.04], [1, 1.01, 105.79]], "batl": [[0, 4.8, 2.02], [1, 4.9, 2.15], [2, 990, 0.01]]}, {"timestamp": 1631550215854, "ltp": 5.3, "tv": 4475.23, "trd": NaN, "batb": NaN, "batl": [[0, 4.9, 2.15], [1, 990, 0.01], [2, 990, 0]]}, {"timestamp": 1631550219090, "ltp": 5.3, "tv": 4475.23, "trd": NaN, "batb": NaN, "batl": [[0, 4.8, 2.02], [1, 4.9, 2.15], [2, 990, 0.01]]}, {"timestamp": 1631550222571, "ltp": 5.3, "tv": 4475.23, "trd": NaN, "batb": NaN, "batl": [[0, 4.9, 2.15], [1, 990, 0.01], [2, 990, 0]]}, {"timestamp": 1631550225597, "ltp": 5.3, "tv": 4475.23, "trd": NaN, "batb": NaN, "batl": [[0, 4.8, 2.32], [1, 4.9, 2.15], [2, 990, 0.01]]}, {"timestamp": 1631550226270, "ltp": 5.3, "tv": 4475.23, "trd": NaN, "batb": NaN, "batl": [[0, 4.9, 2.15], [1, 990, 0.01], [2, 990, 0]]}, {"timestamp": 1631550228195, "ltp": 5.3, "tv": 4475.23, "trd": NaN, "batb": [[0, 4.1, 7.64]], "batl": [[0, 4.3, 7.77], [1, 4.4, 2], [2, 4.9, 2.15]]}, {"timestamp": 1631550234493, "ltp": 5.3, "tv": 4475.23, "trd": NaN, "batb": [[1, 4, 2.68], [2, 3.9, 3.26]], "batl": [[2, 4.5, 2.35]]}, {"timestamp": 1631550237507, "ltp": 5.3, "tv": 4475.23, "trd": NaN, "batb": [[0, 3.9, 3.26], [1, 3.6, 22.4], [2, 1.01, 105.79]], "batl": [[0, 4.5, 2.35], [1, 990, 0.01], [2, 4.5, 0]]}, {"timestamp": 1631550240416, "ltp": 5.3, "tv": 4475.23, "trd": NaN, "batb": [[0, 4, 2.68], [1, 3.9, 3.26], [2, 3.6, 22.4]], "batl": [[0, 4.4, 2.04], [1, 4.5, 2.35], [2, 990, 0.01]]}, {"timestamp": 1631550242609, "ltp": 5.3, "tv": 4475.23, "trd": NaN, "batb": [[0, 3.9, 3.26], [1, 3.6, 22.4], [2, 1.01, 105.79]], "batl": [[0, 4.5, 2.35], [1, 990, 0.01], [2, 990, 0]]}, {"timestamp": 1631550245358, "ltp": 5.3, "tv": 4475.23, "trd": NaN, "batb": NaN, "batl": [[0, 4.2, 7.14], [1, 4.3, 96.36], [2, 4.4, 3.58]]}, {"timestamp": 1631550246563, "ltp": 5.3, "tv": 4475.23, "trd": NaN, "batb": [[1, 3.8, 7.9], [2, 3.75, 3.94]], "batl": NaN}, {"timestamp": 1631550269780, "ltp": 5.3, "tv": 4475.23, "trd": NaN, "batb": NaN, "batl": [[0, 4.2, 11.93]]}, {"timestamp": 1631550284596, "ltp": 5.3, "tv": 4475.23, "trd": NaN, "batb": [[0, 3.6, 22.4], [1, 3.2, 30.7], [2, 1.01, 105.79]], "batl": [[0, 4.9, 2.45], [1, 990, 0.01], [2, 4.4, 0]]}, {"timestamp": 1631550285380, "ltp": 5.3, "tv": 4475.23, "trd": NaN, "batb": [[0, 3.2, 30.45], [1, 1.01, 105.79], [2, 1.01, 0]], "batl": NaN}, {"timestamp": 1631550287676, "ltp": 5.3, "tv": 4475.23, "trd": NaN, "batb": [[0, 3.35, 3.87], [1, 3.2, 30.45], [2, 1.01, 105.79]], "batl": NaN}, {"timestamp": 1631550288299, "ltp": 5.3, "tv": 4475.23, "trd": NaN, "batb": [[0, 3.4, 3.26], [1, 3.35, 3.87], [2, 3.2, 30.45]], "batl": NaN}, {"timestamp": 1631550291381, "ltp": 5.3, "tv": 4475.23, "trd": NaN, "batb": [[0, 3.55, 3.79], [1, 3.4, 3.26], [2, 3.35, 3.87]], "batl": [[0, 4.6, 2.46], [1, 4.9, 2.45], [2, 990, 0.01]]}, {"timestamp": 1631550297222, "ltp": 5.3, "tv": 4475.23, "trd": NaN, "batb": [[0, 3.4, 3.26], [1, 3.35, 3.87], [2, 3.2, 30.45]], "batl": [[0, 4.9, 2.45], [1, 990, 0.01], [2, 990, 0]]}, {"timestamp": 1631550300394, "ltp": 5.3, "tv": 4475.23, "trd": NaN, "batb": NaN, "batl": [[0, 4.6, 2.06], [1, 4.9, 2.45], [2, 990, 0.01]]}, {"timestamp": 1631550303599, "ltp": 5.3, "tv": 4475.23, "trd": NaN, "batb": [[0, 3.55, 3.39], [1, 3.4, 3.26], [2, 3.35, 3.87]], "batl": NaN}, {"timestamp": 1631550303818, "ltp": 5.3, "tv": 4475.23, "trd": NaN, "batb": [[0, 3.4, 3.26], [1, 3.35, 3.87], [2, 3.2, 30.45]], "batl": NaN}, {"timestamp": 1631550307428, "ltp": 5.3, "tv": 4475.23, "trd": NaN, "batb": [[0, 3.55, 3.59], [1, 3.4, 3.26], [2, 3.35, 3.87]], "batl": NaN}, {"timestamp": 1631550307743, "ltp": 5.3, "tv": 4475.23, "trd": NaN, "batb": [[0, 3.4, 3.26], [1, 3.35, 3.87], [2, 3.2, 30.45]], "batl": NaN}, {"timestamp": 1631550310942, "ltp": 5.3, "tv": 4475.23, "trd": NaN, "batb": [[0, 3.55, 3.79], [1, 3.4, 3.26], [2, 3.35, 3.87]], "batl": NaN}, {"timestamp": 1631550312425, "ltp": 5.3, "tv": 4475.23, "trd": NaN, "batb": [[0, 3.4, 3.26], [1, 3.35, 3.87], [2, 3.2, 30.45]], "batl": NaN}, {"timestamp": 1631550315508, "ltp": 5.3, "tv": 4475.23, "trd": NaN, "batb": [[0, 4.4, 6.23], [1, 4.3, 20.93], [2, 4.2, 10.46]], "batl": [[1, 4.7, 9.44], [2, 4.8, 58.69]]}, {"timestamp": 1631550316555, "ltp": 5.3, "tv": 4475.23, "trd": NaN, "batb": [[1, 4.3, 6.98], [2, 4.2, 3.48]], "batl": [[2, 4.8, 64.93]]}, {"timestamp": 1631550338538, "ltp": 5.3, "tv": 4475.23, "trd": NaN, "batb": [[0, 4, 2.79], [1, 3.95, 35.9], [2, 3.85, 3.17]], "batl": [[1, 4.9, 2.45], [2, 5, 2.12]]}, {"timestamp": 1631550339267, "ltp": 5.3, "tv": 4475.23, "trd": NaN, "batb": [[0, 3.85, 3.17], [1, 3.5, 23.82], [2, 1.01, 105.79]], "batl": [[0, 5, 2.12], [1, 990, 0.01], [2, 5, 0]]}, {"timestamp": 1631550345656, "ltp": 5.3, "tv": 4475.23, "trd": NaN, "batb": [[0, 4, 2.79], [1, 3.85, 3.17], [2, 3.5, 23.82]], "batl": [[0, 4.9, 2.25], [1, 5, 2.12], [2, 990, 0.01]]}, {"timestamp": 1631550346288, "ltp": 5.3, "tv": 4475.23, "trd": NaN, "batb": [[0, 3.85, 3.17], [1, 3.5, 23.82], [2, 1.01, 105.79]], "batl": NaN}, {"timestamp": 1631550348595, "ltp": 5.3, "tv": 4475.23, "trd": NaN, "batb": NaN, "batl": [[0, 5, 2.12], [1, 990, 0.01], [2, 990, 0]]}, {"timestamp": 1631550356370, "ltp": 5.3, "tv": 4475.23, "trd": NaN, "batb": [[0, 4, 2.79], [1, 3.85, 3.17], [2, 3.5, 23.82]], "batl": NaN}, {"timestamp": 1631550356685, "ltp": 5.3, "tv": 4475.23, "trd": NaN, "batb": [[0, 3.85, 3.17], [1, 3.5, 23.82], [2, 1.01, 105.79]], "batl": NaN}, {"timestamp": 1631550359565, "ltp": 5.3, "tv": 4475.23, "trd": NaN, "batb": [[0, 4.5, 30.22], [1, 4.4, 29.34], [2, 4.3, 29.34]], "batl": [[0, 5, 7.71], [1, 5.3, 25.66], [2, 5.4, 24.9]]}, {"timestamp": 1631550365580, "ltp": 5.3, "tv": 4475.23, "trd": NaN, "batb": [[1, 4.4, 31.95], [2, 4.3, 31.72]], "batl": [[1, 5.2, 2.08], [2, 5.3, 25.66]]}, {"timestamp": 1631550380599, "ltp": 5.3, "tv": 4475.23, "trd": NaN, "batb": [[0, 4.3, 2.38], [1, 3.85, 38], [2, 1.01, 105.79]], "batl": [[0, 5.4, 2.04], [1, 990, 0.01], [2, 5.3, 0]]}, {"timestamp": 1631550387342, "ltp": 5.3, "tv": 4475.23, "trd": NaN, "batb": [[0, 4.9, 18.36], [1, 4.8, 9.18], [2, 4.7, 9.18]], "batl": [[0, 5.3, 6.04], [1, 5.4, 2.04], [2, 5.5, 58.86]]}, {"timestamp": 1631550388234, "ltp": 5.3, "tv": 4475.23, "trd": NaN, "batb": [[0, 4.9, 6.12], [1, 4.8, 3.06], [2, 4.7, 3.06]], "batl": [[2, 5.5, 64.32]]}, {"timestamp": 1631550393522, "ltp": 5.3, "tv": 4475.23, "trd": NaN, "batb": [[1, 4.8, 5.19], [2, 4.7, 5.08]], "batl": [[0, 5.2, 2.03], [1, 5.3, 6.04], [2, 5.4, 2.04]]}, {"timestamp": 1631550393840, "ltp": 5.3, "tv": 4475.23, "trd": NaN, "batb": [[1, 4.8, 3.06]], "batl": NaN}, {"timestamp": 1631550397727, "ltp": 5.3, "tv": 4475.23, "trd": NaN, "batb": [[1, 4.8, 5.29]], "batl": NaN}, {"timestamp": 1631550400549, "ltp": 5.3, "tv": 4475.23, "trd": NaN, "batb": [[0, 4.8, 2.23], [1, 4.7, 2.02], [2, 4.5, 25.5]], "batl": [[1, 5.4, 2.04], [2, 990, 0.01]]}, {"timestamp": 1631550401171, "ltp": 5.3, "tv": 4475.23, "trd": NaN, "batb": [[0, 4.7, 2.02], [1, 4.2, 30.53], [2, 1.01, 105.79]], "batl": [[0, 5.4, 2.04], [1, 990, 0.01], [2, 990, 0]]}, {"timestamp": 1631550407461, "ltp": 5.3, "tv": 4475.23, "trd": NaN, "batb": NaN, "batl": [[0, 5.2, 2.03], [1, 5.4, 2.04], [2, 990, 0.01]]}, {"timestamp": 1631550408665, "ltp": 5.0, "tv": 4475.25, "trd": [[5, 0.02]], "batb": [[2, 3.8, 38.75]], "batl": [[0, 5, 7.88], [1, 5.1, 44.65], [2, 5.2, 2.94]]}, {"timestamp": 1631550409078, "ltp": 5.0, "tv": 4475.25, "trd": NaN, "batb": [[1, 4.5, 6.66], [2, 4.4, 3.34]], "batl": NaN}, {"timestamp": 1631550414382, "ltp": 5.0, "tv": 4475.25, "trd": NaN, "batb": [[1, 4.5, 9.24], [2, 4.4, 5.9]], "batl": [[2, 5.2, 5.07]]}, {"timestamp": 1631550424669, "ltp": 5.0, "tv": 4475.25, "trd": NaN, "batb": [[0, 4.4, 2.56], [1, 3.8, 38.75], [2, 1.01, 105.79]], "batl": [[0, 5.4, 2.04], [1, 990, 0.01], [2, 5.2, 0]]}, {"timestamp": 1631550427667, "ltp": 5.0, "tv": 4475.25, "trd": NaN, "batb": [[0, 4.5, 2.58], [1, 4.4, 2.56], [2, 3.8, 38.75]], "batl": NaN}, {"timestamp": 1631550428251, "ltp": 5.0, "tv": 4475.25, "trd": NaN, "batb": [[0, 4.4, 2.56], [1, 3.8, 38.75], [2, 1.01, 105.79]], "batl": NaN}, {"timestamp": 1631550431655, "ltp": 5.0, "tv": 4475.25, "trd": NaN, "batb": [[0, 4.8, 28.34], [1, 4.7, 27.5], [2, 4.6, 27.5]], "batl": [[0, 5.3, 6.91], [1, 5.4, 2.04], [2, 5.5, 64.4]]}, {"timestamp": 1631550454670, "ltp": 5.0, "tv": 4476.6, "trd": [[5, 1.37]], "batb": NaN, "batl": NaN}, {"timestamp": 1631550464905, "ltp": 5.0, "tv": 4476.6, "trd": NaN, "batb": NaN, "batl": [[0, 5.4, 2.04], [1, 5.5, 64.4], [2, 5.7, 23.86]]}, {"timestamp": 1631550500075, "ltp": 4.8, "tv": 4478.46, "trd": [[4.8, 56.29]], "batb": [[0, 4.8, 27.41]], "batl": NaN}, {"timestamp": 1631550512389, "ltp": 4.8, "tv": 4485.54, "trd": [[4.8, 63.37]], "batb": [[0, 4.8, 23.87]], "batl": NaN}, {"timestamp": 1631550515582, "ltp": 4.8, "tv": 4485.54, "trd": NaN, "batb": NaN, "batl": [[0, 5.2, 2.62], [1, 5.4, 2.04], [2, 5.5, 64.4]]}, {"timestamp": 1631550524587, "ltp": 4.8, "tv": 4485.54, "trd": NaN, "batb": [[0, 4.4, 2.56], [1, 4, 33.38], [2, 1.01, 105.79]], "batl": [[0, 7, 2], [1, 990, 0.01], [2, 5.5, 0]]}, {"timestamp": 1631550527561, "ltp": 4.8, "tv": 4485.54, "trd": NaN, "batb": [[0, 4.5, 2.58], [1, 4.4, 2.56], [2, 4, 33.38]], "batl": NaN}, {"timestamp": 1631550528290, "ltp": 4.8, "tv": 4485.54, "trd": NaN, "batb": [[0, 4.4, 2.56], [1, 4, 33.38], [2, 1.01, 105.79]], "batl": NaN}, {"timestamp": 1631550531482, "ltp": 4.8, "tv": 4485.54, "trd": NaN, "batb": [[0, 4.5, 6.53], [1, 4.4, 2.56], [2, 4, 33.38]], "batl": [[0, 4.7, 3.69], [1, 5, 39.2], [2, 6.4, 2]]}, {"timestamp": 1631550532489, "ltp": 4.8, "tv": 4485.54, "trd": NaN, "batb": NaN, "batl": [[1, 4.8, 5.07], [2, 5, 39.2]]}, {"timestamp": 1631550538337, "ltp": 4.8, "tv": 4485.54, "trd": NaN, "batb": [[2, 4.2, 2.82]], "batl": NaN}, {"timestamp": 1631550543518, "ltp": 4.8, "tv": 4485.54, "trd": NaN, "batb": [[0, 4.2, 2.82], [1, 4.1, 3.04], [2, 4, 33.38]], "batl": [[0, 5.2, 2.03], [1, 5.6, 2.06], [2, 6.4, 2]]}, {"timestamp": 1631550544402, "ltp": 4.8, "tv": 4485.54, "trd": NaN, "batb": [[0, 4.1, 3.04], [1, 3.75, 40.35], [2, 1.01, 105.79]], "batl": [[0, 5.6, 2.06], [1, 7, 2], [2, 990, 0.01]]}, {"timestamp": 1631550550591, "ltp": 4.8, "tv": 4485.54, "trd": NaN, "batb": [[0, 4.2, 2.67], [1, 4.1, 3.04], [2, 3.75, 40.35]], "batl": [[0, 5.2, 2.03], [1, 5.6, 2.06], [2, 7, 2]]}, {"timestamp": 1631550550903, "ltp": 4.8, "tv": 4485.54, "trd": NaN, "batb": [[0, 4.1, 3.04], [1, 3.75, 40.35], [2, 1.01, 105.79]], "batl": [[0, 5.6, 2.06], [1, 7, 2], [2, 990, 0.01]]}, {"timestamp": 1631550558609, "ltp": 4.8, "tv": 4485.54, "trd": NaN, "batb": [[0, 4.2, 5.18], [1, 4.1, 3.04], [2, 3.9, 34.88]], "batl": [[0, 4.4, 6.69], [1, 4.5, 54.03], [2, 5.6, 2.06]]}, {"timestamp": 1631550565313, "ltp": 4.8, "tv": 4485.54, "trd": NaN, "batb": NaN, "batl": [[2, 4.8, 2.17]]}, {"timestamp": 1631550568505, "ltp": 4.8, "tv": 4485.54, "trd": NaN, "batb": [[2, 4, 2.68]], "batl": NaN}, {"timestamp": 1631550570645, "ltp": 4.8, "tv": 4485.54, "trd": NaN, "batb": [[0, 3.6, 22.56], [1, 1.01, 105.79], [2, 4, 0]], "batl": [[0, 4.9, 2.15], [1, 7, 2], [2, 990, 0.01]]}, {"timestamp": 1631550573638, "ltp": 4.8, "tv": 4485.54, "trd": NaN, "batb": [[0, 4.1, 2.44], [1, 4, 2.93], [2, 3.6, 22.56]], "batl": NaN}, {"timestamp": 1631550574268, "ltp": 4.8, "tv": 4485.54, "trd": NaN, "batb": [[0, 4, 2.93], [1, 3.6, 22.56], [2, 1.01, 105.79]], "batl": NaN}, {"timestamp": 1631550577557, "ltp": 4.8, "tv": 4485.54, "trd": NaN, "batb": NaN, "batl": [[0, 4.8, 2.12], [1, 4.9, 2.15], [2, 7, 2]]}, {"timestamp": 1631550578655, "ltp": 4.8, "tv": 4485.54, "trd": NaN, "batb": [[0, 4, 7.78], [1, 3.65, 37.26], [2, 3.6, 58.72]], "batl": [[0, 4.2, 8.38], [1, 4.3, 64.8], [2, 4.9, 2.15]]}, {"timestamp": 1631550584868, "ltp": 4.8, "tv": 4485.54, "trd": NaN, "batb": [[1, 3.9, 2.76], [2, 3.65, 37.26]], "batl": [[2, 4.4, 2.59]]}, {"timestamp": 1631550589536, "ltp": 4.0, "tv": 4489.88, "trd": [[4, 4.34]], "batb": [[0, 4, 5.61]], "batl": NaN}, {"timestamp": 1631550596650, "ltp": 4.0, "tv": 4489.88, "trd": NaN, "batb": [[0, 3.9, 3.52], [1, 3.6, 22.56], [2, 3.45, 24.91]], "batl": [[0, 4.4, 2.59], [1, 4.5, 3.01], [2, 4.9, 2.15]]}, {"timestamp": 1631550597373, "ltp": 4.0, "tv": 4489.88, "trd": NaN, "batb": [[0, 3.45, 24.91], [1, 1.01, 105.79], [2, 3.45, 0]], "batl": [[0, 4.5, 3.01], [1, 7, 2], [2, 990, 0.01]]}, {"timestamp": 1631550600587, "ltp": 4.0, "tv": 4489.88, "trd": NaN, "batb": [[0, 3.9, 2.76], [1, 3.45, 24.91], [2, 1.01, 105.79]], "batl": NaN}, {"timestamp": 1631550605602, "ltp": 4.0, "tv": 4489.88, "trd": NaN, "batb": [[0, 4.1, 36.6], [1, 4, 18.3], [2, 3.95, 18.3]], "batl": [[0, 4.4, 6.46], [1, 4.5, 52.94], [2, 7, 2]]}, {"timestamp": 1631550606582, "ltp": 4.0, "tv": 4489.88, "trd": NaN, "batb": [[0, 4.1, 21.96], [1, 4, 10.98], [2, 3.95, 10.98]], "batl": NaN}, {"timestamp": 1631550606792, "ltp": 4.0, "tv": 4489.88, "trd": NaN, "batb": [[0, 4.1, 7.32], [1, 4, 3.66], [2, 3.95, 3.66]], "batl": NaN}, {"timestamp": 1631550612588, "ltp": 4.0, "tv": 4489.88, "trd": NaN, "batb": [[0, 3.9, 2.76], [1, 3.6, 22.23], [2, 1.01, 105.79]], "batl": [[0, 4.8, 2.52], [1, 7, 2], [2, 990, 0.01]]}, {"timestamp": 1631550615596, "ltp": 4.0, "tv": 4489.88, "trd": NaN, "batb": [[0, 4, 2.68], [1, 3.9, 2.76], [2, 3.6, 22.23]], "batl": NaN}, {"timestamp": 1631550616076, "ltp": 4.0, "tv": 4489.88, "trd": NaN, "batb": [[0, 3.9, 2.76], [1, 3.6, 22.23], [2, 1.01, 105.79]], "batl": NaN}, {"timestamp": 1631550619492, "ltp": 4.0, "tv": 4489.88, "trd": NaN, "batb": [[0, 3.9, 49.07]], "batl": [[0, 4.2, 7.22], [1, 4.3, 67.54], [2, 4.6, 2.81]]}, {"timestamp": 1631550620188, "ltp": 4.0, "tv": 4489.88, "trd": NaN, "batb": [[2, 3.15, 31.54]], "batl": NaN}, {"timestamp": 1631550626320, "ltp": 4.0, "tv": 4489.88, "trd": NaN, "batb": [[2, 3.4, 3.41]], "batl": NaN}, {"timestamp": 1631550642586, "ltp": 4.0, "tv": 4489.88, "trd": NaN, "batb": [[0, 3.25, 3.37], [1, 3.15, 31.54], [2, 1.01, 105.79]], "batl": [[0, 4.8, 2.52], [1, 4.9, 2.65], [2, 7, 2]]}, {"timestamp": 1631550642787, "ltp": 4.0, "tv": 4489.88, "trd": NaN, "batb": NaN, "batl": [[0, 4.9, 2.65], [1, 7, 2], [2, 990, 0.01]]}, {"timestamp": 1631550647558, "ltp": 4.0, "tv": 4489.88, "trd": NaN, "batb": [[0, 4.3, 20.93], [1, 4.2, 10.46], [2, 4.1, 39.73]], "batl": [[0, 4.7, 8.91], [1, 4.8, 55.35], [2, 4.9, 2.65]]}, {"timestamp": 1631550648503, "ltp": 4.0, "tv": 4489.88, "trd": NaN, "batb": NaN, "batl": [[1, 4.8, 61.59], [2, 4.9, 5.77]]}, {"timestamp": 1631550656671, "ltp": 4.0, "tv": 4489.88, "trd": NaN, "batb": [[0, 4, 34.89], [1, 3.75, 2.83], [2, 3.5, 24.33]], "batl": [[0, 5.4, 2.34], [1, 7, 2], [2, 990, 0.01]]}, {"timestamp": 1631550657097, "ltp": 4.0, "tv": 4489.88, "trd": NaN, "batb": [[0, 3.75, 2.83], [1, 3.5, 24.33], [2, 1.01, 105.79]], "batl": NaN}, {"timestamp": 1631550661507, "ltp": 4.0, "tv": 4489.88, "trd": NaN, "batb": NaN, "batl": [[0, 4.7, 130.48], [1, 5.4, 2.34], [2, 7, 2]]}, {"timestamp": 1631550662497, "ltp": 4.0, "tv": 4489.88, "trd": NaN, "batb": NaN, "batl": [[0, 4.6, 19.26]]}, {"timestamp": 1631550663284, "ltp": 4.0, "tv": 4489.88, "trd": NaN, "batb": [[0, 3.9, 2.86], [1, 3.75, 2.83], [2, 3.5, 24.33]], "batl": [[0, 5, 2.58]]}, {"timestamp": 1631550667326, "ltp": 4.0, "tv": 4489.88, "trd": NaN, "batb": [[0, 3.75, 2.83], [1, 3.5, 24.33], [2, 1.01, 105.79]], "batl": [[0, 5.4, 2.34], [1, 7, 2], [2, 990, 0.01]]}, {"timestamp": 1631550670598, "ltp": 4.0, "tv": 4489.88, "trd": NaN, "batb": [[0, 3.9, 3.06], [1, 3.75, 2.83], [2, 3.5, 24.33]], "batl": [[0, 5, 2.72], [1, 5.4, 2.34], [2, 7, 2]]}, {"timestamp": 1631550670909, "ltp": 4.0, "tv": 4489.88, "trd": NaN, "batb": [[0, 3.75, 2.83], [1, 3.5, 24.33], [2, 1.01, 105.79]], "batl": [[0, 5.4, 2.34], [1, 7, 2], [2, 990, 0.01]]}, {"timestamp": 1631550684637, "ltp": 4.0, "tv": 4489.88, "trd": NaN, "batb": [[0, 3.9, 2.96], [1, 3.75, 2.83], [2, 3.5, 24.33]], "batl": [[0, 5, 2.63], [1, 5.4, 2.34], [2, 7, 2]]}, {"timestamp": 1631550685415, "ltp": 4.0, "tv": 4489.88, "trd": NaN, "batb": [[0, 3.9, 4.57], [2, 3.55, 38.3]], "batl": [[0, 4.2, 71.83]]}, {"timestamp": 1631550692046, "ltp": 4.0, "tv": 4489.88, "trd": NaN, "batb": NaN, "batl": [[1, 4.6, 2.76], [2, 4.9, 2.35]]}, {"timestamp": 1631550697152, "ltp": 3.9, "tv": 4499.02, "trd": [[3.9, 22.28]], "batb": [[0, 3.75, 2.83], [1, 3.55, 38.3], [2, 3.5, 61.51]], "batl": [[0, 3.9, 17.81], [1, 4.2, 71.83], [2, 4.6, 2.76]]}, {"timestamp": 1631550699042, "ltp": 3.9, "tv": 4499.02, "trd": NaN, "batb": NaN, "batl": [[0, 4.2, 71.83], [1, 4.6, 2.76], [2, 4.9, 2.35]]}, {"timestamp": 1631550706504, "ltp": 3.9, "tv": 4499.02, "trd": NaN, "batb": [[0, 3.5, 24.33], [1, 2.96, 37.41], [2, 1.01, 105.79]], "batl": [[0, 4.6, 2.76], [1, 4.9, 2.35], [2, 5, 2.35]]}, {"timestamp": 1631550707231, "ltp": 3.9, "tv": 4499.02, "trd": NaN, "batb": [[0, 2.96, 37.41], [1, 1.01, 105.79], [2, 1.01, 0]], "batl": [[0, 5, 2.35], [1, 5.4, 2.34], [2, 7, 2]]}, {"timestamp": 1631550710340, "ltp": 3.9, "tv": 4499.02, "trd": NaN, "batb": NaN, "batl": [[0, 4.6, 2.61], [1, 5, 2.35], [2, 5.4, 2.34]]}, {"timestamp": 1631550711604, "ltp": 3.9, "tv": 4499.02, "trd": NaN, "batb": NaN, "batl": [[0, 3.75, 17.33], [1, 4.6, 2.61], [2, 5, 2.35]]}, {"timestamp": 1631550711917, "ltp": 3.75, "tv": 4516.35, "trd": [[3.75, 27.08]], "batb": NaN, "batl": [[0, 4.6, 2.61], [1, 5, 2.35], [2, 5.4, 2.34]]}, {"timestamp": 1631550716616, "ltp": 3.75, "tv": 4516.35, "trd": NaN, "batb": [[0, 4.1, 36.6], [1, 4, 68.3], [2, 3.95, 18.3]], "batl": [[0, 4.5, 5.31], [1, 4.6, 2.61], [2, 4.8, 68.17]]}, {"timestamp": 1631550717611, "ltp": 3.75, "tv": 4516.35, "trd": NaN, "batb": [[0, 4.1, 21.96], [1, 4, 40.98], [2, 3.95, 10.98]], "batl": NaN}, {"timestamp": 1631550717715, "ltp": 3.75, "tv": 4516.35, "trd": NaN, "batb": [[0, 4.1, 7.32], [1, 4, 33.66], [2, 3.95, 3.66]], "batl": NaN}, {"timestamp": 1631550737674, "ltp": 3.75, "tv": 4516.35, "trd": NaN, "batb": [[0, 4.1, 3.66], [1, 4, 6.83], [2, 3.95, 1.83]], "batl": NaN}, {"timestamp": 1631550738472, "ltp": 3.75, "tv": 4516.35, "trd": NaN, "batb": [[0, 3.7, 3.22], [1, 3.35, 27.01], [2, 1.01, 105.79]], "batl": [[0, 5.2, 2.38], [1, 7, 2], [2, 990, 0.01]]}, {"timestamp": 1631550741467, "ltp": 3.75, "tv": 4516.35, "trd": NaN, "batb": [[0, 3.85, 3.17], [1, 3.7, 3.22], [2, 3.35, 27.01]], "batl": [[0, 4.9, 2.85], [1, 5.2, 2.38], [2, 7, 2]]}, {"timestamp": 1631550741767, "ltp": 3.75, "tv": 4516.35, "trd": NaN, "batb": [[0, 3.7, 3.22], [1, 3.35, 27.01], [2, 1.01, 105.79]], "batl": [[0, 5.2, 2.38], [1, 7, 2], [2, 990, 0.01]]}, {"timestamp": 1631550743541, "ltp": 3.75, "tv": 4516.35, "trd": NaN, "batb": NaN, "batl": [[0, 4.6, 132.44], [1, 5.2, 2.38], [2, 7, 2]]}, {"timestamp": 1631550744583, "ltp": 3.75, "tv": 4516.35, "trd": NaN, "batb": NaN, "batl": [[0, 5.2, 2.38], [1, 7, 2], [2, 990, 0.01]]}, {"timestamp": 1631550744966, "ltp": 3.75, "tv": 4516.35, "trd": NaN, "batb": [[0, 3.85, 2.97], [1, 3.7, 3.22], [2, 3.35, 27.01]], "batl": [[0, 4.9, 2.85], [1, 5.2, 2.38], [2, 7, 2]]}, {"timestamp": 1631550748158, "ltp": 3.75, "tv": 4516.35, "trd": NaN, "batb": [[0, 3.7, 3.22], [1, 3.35, 27.01], [2, 1.01, 105.79]], "batl": [[0, 5.2, 2.38], [1, 7, 2], [2, 990, 0.01]]}, {"timestamp": 1631550761598, "ltp": 3.75, "tv": 4516.35, "trd": NaN, "batb": [[0, 3.85, 3.37], [1, 3.7, 3.22], [2, 3.35, 27.01]], "batl": [[0, 4.9, 2.65], [1, 5.2, 2.38], [2, 7, 2]]}, {"timestamp": 1631550761862, "ltp": 3.75, "tv": 4516.35, "trd": NaN, "batb": [[0, 3.7, 3.22], [1, 3.35, 27.01], [2, 1.01, 105.79]], "batl": [[0, 5.2, 2.38], [1, 7, 2], [2, 990, 0.01]]}, {"timestamp": 1631550764180, "ltp": 3.75, "tv": 4516.35, "trd": NaN, "batb": [[0, 4.5, 30.22], [1, 4.4, 29.34], [2, 4.3, 29.34]], "batl": [[0, 5, 5.37], [1, 5.2, 2.38], [2, 5.3, 82.75]]}, {"timestamp": 1631550771892, "ltp": 3.75, "tv": 4516.35, "trd": NaN, "batb": [[1, 4.4, 31.95], [2, 4.3, 31.92]], "batl": NaN}, {"timestamp": 1631550785588, "ltp": 3.75, "tv": 4516.35, "trd": NaN, "batb": [[0, 4.3, 2.58], [1, 3.85, 37.91], [2, 3.7, 3.22]], "batl": [[0, 5.4, 2.49], [1, 7, 2], [2, 990, 0.01]]}, {"timestamp": 1631550788614, "ltp": 3.75, "tv": 4516.35, "trd": NaN, "batb": [[0, 4.4, 2.41], [1, 4.3, 2.58], [2, 3.85, 37.91]], "batl": [[0, 5.2, 2.43], [1, 5.4, 2.49], [2, 7, 2]]}, {"timestamp": 1631550788924, "ltp": 3.75, "tv": 4516.35, "trd": NaN, "batb": [[0, 4.3, 2.58], [1, 3.85, 37.91], [2, 3.7, 3.22]], "batl": [[0, 5.4, 2.49], [1, 7, 2], [2, 990, 0.01]]}, {"timestamp": 1631550794625, "ltp": 3.75, "tv": 4516.35, "trd": NaN, "batb": NaN, "batl": [[0, 4.6, 8.61], [1, 4.7, 57.88], [2, 4.8, 56.18]]}, {"timestamp": 1631550795616, "ltp": 3.75, "tv": 4516.35, "trd": NaN, "batb": NaN, "batl": [[1, 4.7, 28.94], [2, 4.8, 28.1]]}, {"timestamp": 1631550797544, "ltp": 3.75, "tv": 4516.35, "trd": NaN, "batb": NaN, "batl": [[0, 4.4, 5.93], [1, 4.6, 8.61], [2, 4.7, 28.94]]}, {"timestamp": 1631550799642, "ltp": 3.75, "tv": 4516.35, "trd": NaN, "batb": [[2, 3.3, 28.35]], "batl": NaN}, {"timestamp": 1631550806551, "ltp": 3.75, "tv": 4516.35, "trd": NaN, "batb": [[0, 3.85, 37.91], [1, 3.3, 28.35], [2, 1.01, 105.79]], "batl": [[0, 5.4, 2.49], [1, 7, 2], [2, 990, 0.01]]}, {"timestamp": 1631550806712, "ltp": 3.75, "tv": 4516.35, "trd": NaN, "batb": [[0, 3.3, 28.35], [1, 1.01, 105.79], [2, 1.01, 0]], "batl": NaN}, {"timestamp": 1631550815961, "ltp": 3.75, "tv": 4516.35, "trd": NaN, "batb": NaN, "batl": [[1, 990, 0.01], [2, 990, 0]]}, {"timestamp": 1631550818629, "ltp": 3.75, "tv": 4516.35, "trd": NaN, "batb": NaN, "batl": [[0, 5, 3.56], [1, 5.4, 2.49], [2, 5.5, 114.04]]}, {"timestamp": 1631550819669, "ltp": 3.75, "tv": 4516.35, "trd": NaN, "batb": [[0, 4.3, 28.85], [1, 3.9, 36.74], [2, 3.3, 28.35]], "batl": [[2, 5.5, 89.3]]}, {"timestamp": 1631550819832, "ltp": 3.75, "tv": 4516.35, "trd": NaN, "batb": [[2, 1.01, 105.79]], "batl": NaN}, {"timestamp": 1631550829643, "ltp": 5.0, "tv": 4519.91, "trd": [[5, 4.93]], "batb": NaN, "batl": [[0, 5.4, 2.49], [1, 5.5, 89.3], [2, 5.6, 24]]}, {"timestamp": 1631550842764, "ltp": 5.0, "tv": 4519.91, "trd": NaN, "batb": NaN, "batl": [[0, 5.1, 4.08], [1, 5.4, 2.49], [2, 5.5, 89.3]]}, {"timestamp": 1631550845477, "ltp": 4.8, "tv": 4521.61, "trd": [[4.8, 65.07]], "batb": NaN, "batl": NaN}, {"timestamp": 1631550855590, "ltp": 5.1, "tv": 4526.69, "trd": [[5.1, 5.08]], "batb": NaN, "batl": [[0, 5.4, 2.49], [1, 5.5, 89.3], [2, 5.6, 24]]}, {"timestamp": 1631550865436, "ltp": 5.1, "tv": 4530.48, "trd": [[5.1, 8.87]], "batb": NaN, "batl": NaN}, {"timestamp": 1631550867938, "ltp": 5.3, "tv": 4535.62, "trd": [[5.3, 15.14]], "batb": [[0, 5, 3.45], [1, 4.3, 28.85], [2, 3.9, 36.74]], "batl": NaN}, {"timestamp": 1631550869144, "ltp": 5.3, "tv": 4535.62, "trd": NaN, "batb": [[0, 4.3, 28.85], [1, 3.9, 36.74], [2, 1.01, 105.79]], "batl": NaN}, {"timestamp": 1631550872242, "ltp": 5.3, "tv": 4535.62, "trd": NaN, "batb": NaN, "batl": [[1, 5.5, 96.62]]}, {"timestamp": 1631550878144, "ltp": 5.3, "tv": 4535.62, "trd": NaN, "batb": [[0, 4.4, 9.41], [1, 4.3, 28.85], [2, 3.9, 36.74]], "batl": [[1, 5.5, 89.3]]}, {"timestamp": 1631550880080, "ltp": 5.0, "tv": 4537.33, "trd": [[5, 6.64]], "batb": NaN, "batl": NaN}, {"timestamp": 1631550881131, "ltp": 5.0, "tv": 4537.33, "trd": NaN, "batb": NaN, "batl": [[1, 5.5, 96.62]]}, {"timestamp": 1631550897264, "ltp": 5.0, "tv": 4537.33, "trd": NaN, "batb": NaN, "batl": [[1, 5.5, 89.3]]}, {"timestamp": 1631550900469, "ltp": 5.0, "tv": 4537.33, "trd": NaN, "batb": [[0, 5, 3.45]], "batl": [[0, 5.3, 5.14], [1, 5.4, 2.49], [2, 5.5, 89.3]]}, {"timestamp": 1631550906879, "ltp": 5.0, "tv": 4537.33, "trd": NaN, "batb": [[0, 4.3, 28.85], [1, 3.9, 36.74], [2, 1.01, 105.79]], "batl": [[0, 5.4, 2.49], [1, 5.5, 89.3], [2, 5.6, 24]]}, {"timestamp": 1631550909074, "ltp": 5.0, "tv": 4537.33, "trd": NaN, "batb": [[0, 4.4, 2.76], [1, 4.3, 28.85], [2, 4.2, 2.52]], "batl": NaN}, {"timestamp": 1631550910496, "ltp": 5.3, "tv": 4537.42, "trd": [[5.3, 15.23]], "batb": NaN, "batl": NaN}, {"timestamp": 1631550912586, "ltp": 5.3, "tv": 4537.42, "trd": NaN, "batb": [[0, 4.2, 2.52], [1, 3.9, 36.74], [2, 1.01, 105.79]], "batl": [[0, 7.8, 2], [1, 990, 0.01], [2, 5.6, 0]]}, {"timestamp": 1631550915299, "ltp": 5.3, "tv": 4537.42, "trd": NaN, "batb": [[0, 4.4, 2.76], [1, 4.2, 2.52], [2, 3.9, 36.74]], "batl": NaN}, {"timestamp": 1631550916322, "ltp": 5.3, "tv": 4537.42, "trd": NaN, "batb": NaN, "batl": [[0, 7, 2], [1, 7.8, 2], [2, 990, 0.01]]}, {"timestamp": 1631550918414, "ltp": 5.3, "tv": 4537.42, "trd": NaN, "batb": NaN, "batl": [[0, 7.8, 2], [1, 990, 0.01], [2, 990, 0]]}, {"timestamp": 1631550921489, "ltp": 5.3, "tv": 4537.42, "trd": NaN, "batb": [[1, 4.3, 31.64], [2, 4.2, 33.22]], "batl": [[0, 4.8, 46.5], [1, 4.9, 3.25], [2, 5, 27.2]]}, {"timestamp": 1631550924303, "ltp": 5.3, "tv": 4537.42, "trd": NaN, "batb": [[0, 4.5, 6.05]], "batl": [[0, 4.7, 4.29], [1, 4.8, 46.5], [2, 4.9, 3.25]]}, {"timestamp": 1631550931611, "ltp": 5.3, "tv": 4537.42, "trd": NaN, "batb": [[0, 4.1, 2.84], [1, 3.9, 36.74], [2, 3.6, 22.23]], "batl": [[0, 5.4, 2.04], [1, 5.8, 2.02], [2, 7.8, 2]]}, {"timestamp": 1631550932142, "ltp": 5.3, "tv": 4537.42, "trd": NaN, "batb": [[1, 3.6, 22.23], [2, 1.01, 105.79]], "batl": [[0, 5.8, 2.02], [1, 7.8, 2], [2, 990, 0.01]]}, {"timestamp": 1631550938229, "ltp": 5.3, "tv": 4537.42, "trd": NaN, "batb": [[0, 4.2, 2.62], [1, 4.1, 2.84], [2, 3.6, 22.23]], "batl": NaN}, {"timestamp": 1631550938909, "ltp": 5.3, "tv": 4537.42, "trd": NaN, "batb": NaN, "batl": [[0, 5.4, 2.04], [1, 5.8, 2.02], [2, 7.8, 2]]}, {"timestamp": 1631550944320, "ltp": 5.3, "tv": 4537.42, "trd": NaN, "batb": [[0, 4.1, 2.84], [1, 3.6, 22.23], [2, 1.01, 105.79]], "batl": [[0, 5.8, 2.27], [1, 7.8, 2], [2, 990, 0.01]]}, {"timestamp": 1631550947530, "ltp": 5.3, "tv": 4537.42, "trd": NaN, "batb": [[0, 4.2, 2.52], [1, 4.1, 2.84], [2, 3.6, 22.23]], "batl": [[0, 5.4, 2.29], [1, 5.8, 2.02], [2, 7.8, 2]]}, {"timestamp": 1631550947739, "ltp": 5.3, "tv": 4537.42, "trd": NaN, "batb": [[0, 4.1, 2.84], [1, 3.6, 22.23], [2, 1.01, 105.79]], "batl": [[0, 5.8, 2.27], [1, 7.8, 2], [2, 990, 0.01]]}, {"timestamp": 1631550951952, "ltp": 4.5, "tv": 4537.67, "trd": [[4.5, 0.25]], "batb": NaN, "batl": [[0, 5.8, 2.02]]}, {"timestamp": 1631550953534, "ltp": 4.1, "tv": 4560.51, "trd": [[4.1, 22.83], [4.7, 38.08]], "batb": [[0, 3.6, 22.23], [1, 1.01, 105.79], [2, 1.01, 0]], "batl": NaN}, {"timestamp": 1631550954432, "ltp": 4.1, "tv": 4560.51, "trd": NaN, "batb": [[0, 4.2, 2.42], [1, 3.6, 22.23], [2, 1.01, 105.79]], "batl": [[0, 5.4, 2], [1, 5.8, 2.02], [2, 7.8, 2]]}, {"timestamp": 1631550955064, "ltp": 4.1, "tv": 4560.51, "trd": NaN, "batb": [[0, 3.6, 22.23], [1, 1.01, 105.79], [2, 1.01, 0]], "batl": [[0, 5.8, 2.02], [1, 7.8, 2], [2, 990, 0.01]]}, {"timestamp": 1631550956741, "ltp": 4.1, "tv": 4560.51, "trd": NaN, "batb": [[0, 4.1, 2.54], [1, 3.6, 22.23], [2, 1.01, 105.79]], "batl": NaN}, {"timestamp": 1631550959669, "ltp": 4.1, "tv": 4560.51, "trd": NaN, "batb": [[0, 5.2, 26.16], [1, 5.1, 25.38], [2, 5, 25.38]], "batl": [[0, 5.5, 4.8], [1, 5.7, 56.75], [2, 5.8, 2.02]]}, {"timestamp": 1631550969485, "ltp": 4.1, "tv": 4560.51, "trd": NaN, "batb": [[0, 4.2, 2.92], [1, 4, 34.64], [2, 1.01, 105.79]], "batl": [[0, 9.4, 2], [1, 990, 0.01], [2, 5.8, 0]]}, {"timestamp": 1631550976468, "ltp": 4.1, "tv": 4560.51, "trd": NaN, "batb": [[0, 4.4, 2.41], [1, 4.2, 2.92], [2, 4, 34.64]], "batl": [[0, 7.8, 2], [1, 9.4, 2], [2, 990, 0.01]]}, {"timestamp": 1631550979470, "ltp": 4.1, "tv": 4560.51, "trd": NaN, "batb": [[0, 4.2, 2.92], [1, 4, 34.64], [2, 1.01, 105.79]], "batl": [[0, 9.4, 2], [1, 990, 0.01], [2, 990, 0]]}, {"timestamp": 1631550982697, "ltp": 4.1, "tv": 4560.51, "trd": NaN, "batb": [[0, 4.4, 2.51], [1, 4.2, 2.92], [2, 4, 34.64]], "batl": [[0, 7.8, 2], [1, 9.4, 2], [2, 990, 0.01]]}, {"timestamp": 1631550987811, "ltp": 4.1, "tv": 4560.51, "trd": NaN, "batb": [[0, 4.2, 2.92], [1, 4, 34.64], [2, 1.01, 105.79]], "batl": NaN}, {"timestamp": 1631550990598, "ltp": 4.1, "tv": 4560.51, "trd": NaN, "batb": [[0, 6.8, 3.8], [1, 6.6, 41.22], [2, 6.4, 40]], "batl": [[0, 7.2, 4.41], [1, 7.6, 51.27], [2, 7.8, 2]]}, {"timestamp": 1631550991386, "ltp": 4.1, "tv": 4560.51, "trd": NaN, "batb": [[1, 6.6, 20.62], [2, 6.4, 20]], "batl": NaN}, {"timestamp": 1631551004508, "ltp": 4.1, "tv": 4560.51, "trd": NaN, "batb": [[0, 4.7, 22.65], [1, 1.01, 105.79], [2, 6.4, 0]], "batl": [[0, 13.5, 2], [1, 21, 2], [2, 990, 0.01]]}, {"timestamp": 1631551004918, "ltp": 4.1, "tv": 4560.51, "trd": NaN, "batb": NaN, "batl": [[0, 21, 2], [1, 990, 0.01], [2, 990, 0]]}, {"timestamp": 1631551011613, "ltp": 7.2, "tv": 4560.96, "trd": [[7.2, 0.45]], "batb": NaN, "batl": [[0, 13.5, 2], [1, 21, 2], [2, 990, 0.01]]}, {"timestamp": 1631551012608, "ltp": 7.2, "tv": 4560.96, "trd": NaN, "batb": NaN, "batl": [[0, 21, 2], [1, 990, 0.01], [2, 990, 0]]}, {"timestamp": 1631551016129, "ltp": 7.2, "tv": 4560.96, "trd": NaN, "batb": NaN, "batl": [[0, 13.5, 2], [1, 21, 2], [2, 990, 0.01]]}, {"timestamp": 1631551029618, "ltp": 7.2, "tv": 4560.96, "trd": NaN, "batb": [[0, 5, 36.64], [1, 4.7, 22.65], [2, 1.01, 105.79]], "batl": [[0, 5.7, 4.02], [1, 6, 56.11], [2, 6.2, 44.76]]}, {"timestamp": 1631551030670, "ltp": 7.2, "tv": 4560.96, "trd": NaN, "batb": [[0, 5.3, 28.3], [1, 5.2, 14.16], [2, 5.1, 14.16]], "batl": [[1, 5.8, 5.27], [2, 6, 36.11]]}, {"timestamp": 1631551031041, "ltp": 7.2, "tv": 4560.96, "trd": NaN, "batb": [[0, 5.3, 5.66], [1, 5.2, 2.84], [2, 5.1, 2.84]], "batl": NaN}, {"timestamp": 1631551040634, "ltp": 7.2, "tv": 4560.96, "trd": NaN, "batb": [[0, 4.7, 22.65], [1, 4, 34.14], [2, 1.01, 105.79]], "batl": [[0, 5.8, 5.27], [1, 10.5, 2], [2, 13.5, 2]]}, {"timestamp": 1631551041265, "ltp": 7.2, "tv": 4560.96, "trd": NaN, "batb": [[0, 4, 34.14], [1, 1.01, 105.79], [2, 1.01, 0]], "batl": [[0, 13.5, 2], [1, 15.5, 2], [2, 21, 2]]}, {"timestamp": 1631551043647, "ltp": 7.2, "tv": 4560.96, "trd": NaN, "batb": [[0, 5, 6.03], [1, 4, 34.14], [2, 1.01, 105.79]], "batl": NaN}, {"timestamp": 1631551044582, "ltp": 7.2, "tv": 4560.96, "trd": NaN, "batb": [[0, 4, 34.59], [1, 1.01, 105.79], [2, 1.01, 0]], "batl": [[0, 10.5, 2], [1, 13.5, 2], [2, 15.5, 2]]}, {"timestamp": 1631551055685, "ltp": 7.2, "tv": 4560.96, "trd": NaN, "batb": [[0, 4, 34.14]], "batl": NaN}, {"timestamp": 1631551065463, "ltp": 7.2, "tv": 4560.96, "trd": NaN, "batb": NaN, "batl": [[0, 13.5, 2], [1, 15.5, 2], [2, 21, 2]]}, {"timestamp": 1631551068385, "ltp": 7.2, "tv": 4560.96, "trd": NaN, "batb": [[0, 4.5, 5.97], [1, 4, 34.14], [2, 1.01, 105.79]], "batl": [[0, 4.7, 4.36], [1, 4.8, 41.66], [2, 4.9, 24.61]]}, {"timestamp": 1631551069276, "ltp": 7.2, "tv": 4560.96, "trd": NaN, "batb": [[1, 4.4, 6.82], [2, 4.3, 3.4]], "batl": NaN}, {"timestamp": 1631551080485, "ltp": 4.7, "tv": 4561.45, "trd": [[4.7, 38.57]], "batb": NaN, "batl": [[0, 4.7, 3.87]]}, {"timestamp": 1631551084620, "ltp": 4.7, "tv": 4562.8, "trd": [[4.7, 39.92]], "batb": [[0, 4.1, 2.99], [1, 4, 34.14], [2, 3.9, 3.26]], "batl": [[0, 5.6, 2.01], [1, 6, 2.01], [2, 13.5, 2]]}, {"timestamp": 1631551085195, "ltp": 4.7, "tv": 4562.8, "trd": NaN, "batb": [[0, 3.9, 3.71], [1, 3.6, 22.14], [2, 1.01, 105.79]], "batl": [[0, 6, 2.01], [1, 13.5, 2], [2, 15.5, 2]]}, {"timestamp": 1631551088504, "ltp": 4.7, "tv": 4562.8, "trd": NaN, "batb": NaN, "batl": [[0, 5.6, 2.01], [1, 6, 2.01], [2, 13.5, 2]]}, {"timestamp": 1631551089609, "ltp": 4.7, "tv": 4562.8, "trd": NaN, "batb": NaN, "batl": [[0, 6, 2.01], [1, 13.5, 2], [2, 15.5, 2]]}, {"timestamp": 1631551090607, "ltp": 4.7, "tv": 4562.8, "trd": NaN, "batb": NaN, "batl": [[0, 4.9, 19.15], [1, 6, 2.01], [2, 13.5, 2]]}, {"timestamp": 1631551091601, "ltp": 4.7, "tv": 4562.8, "trd": NaN, "batb": [[0, 4.1, 3.29], [1, 3.9, 3.26], [2, 3.6, 22.14]], "batl": [[0, 6, 2.01], [1, 13.5, 2], [2, 15.5, 2]]}, {"timestamp": 1631551092439, "ltp": 4.7, "tv": 4562.8, "trd": NaN, "batb": [[0, 3.9, 3.71], [1, 3.6, 22.14], [2, 1.01, 105.79]], "batl": NaN}, {"timestamp": 1631551095606, "ltp": 4.7, "tv": 4562.8, "trd": NaN, "batb": [[0, 4.1, 2.89], [1, 3.9, 3.26], [2, 3.6, 22.14]], "batl": [[0, 5.6, 2.01], [1, 6, 2.01], [2, 13.5, 2]]}, {"timestamp": 1631551095922, "ltp": 4.7, "tv": 4562.8, "trd": NaN, "batb": [[0, 3.9, 3.71], [1, 3.6, 22.14], [2, 1.01, 105.79]], "batl": [[0, 6, 2.01], [1, 13.5, 2], [2, 15.5, 2]]}, {"timestamp": 1631551098592, "ltp": 4.7, "tv": 4563.25, "trd": [[4.7, 40.37]], "batb": [[0, 4.1, 4.2], [1, 3.9, 3.26], [2, 3.6, 22.14]], "batl": [[0, 4.3, 64.67], [1, 6, 2.01], [2, 13.5, 2]]}, {"timestamp": 1631551105495, "ltp": 4.7, "tv": 4563.25, "trd": NaN, "batb": NaN, "batl": [[1, 4.9, 2.35], [2, 5.2, 2.03]]}, {"timestamp": 1631551115645, "ltp": 4.7, "tv": 4563.25, "trd": NaN, "batb": [[0, 4.1, 17.17]], "batl": NaN}, {"timestamp": 1631551115914, "ltp": 4.7, "tv": 4563.25, "trd": NaN, "batb": [[0, 4.1, 4.2]], "batl": NaN}, {"timestamp": 1631551117636, "ltp": 4.7, "tv": 4563.25, "trd": NaN, "batb": [[0, 3.9, 3.26], [1, 3.6, 22.14], [2, 3.4, 3.46]], "batl": NaN}, {"timestamp": 1631551120451, "ltp": 4.7, "tv": 4563.25, "trd": NaN, "batb": NaN, "batl": [[0, 4.3, 69.27]]}, {"timestamp": 1631551121028, "ltp": 4.3, "tv": 4575.08, "trd": [[4.3, 23.26]], "batb": NaN, "batl": [[0, 4.3, 63.35]]}, {"timestamp": 1631551124640, "ltp": 4.3, "tv": 4575.08, "trd": NaN, "batb": NaN, "batl": [[0, 4.9, 2.35], [1, 5.2, 2.03], [2, 6, 2.01]]}, {"timestamp": 1631551125362, "ltp": 4.3, "tv": 4575.08, "trd": NaN, "batb": [[0, 3.25, 3.69], [1, 3.05, 34.14], [2, 1.01, 105.79]], "batl": [[0, 5.2, 2.03], [1, 6, 2.01], [2, 13.5, 2]]}, {"timestamp": 1631551128655, "ltp": 4.3, "tv": 4575.08, "trd": NaN, "batb": [[0, 3.4, 3.46], [1, 3.25, 3.69], [2, 3.05, 34.14]], "batl": [[0, 4.9, 2.05], [1, 5.2, 2.03], [2, 6, 2.01]]}, {"timestamp": 1631551129450, "ltp": 4.3, "tv": 4575.08, "trd": NaN, "batb": [[0, 3.25, 3.69], [1, 3.05, 34.14], [2, 1.01, 105.79]], "batl": [[0, 5.2, 2.03], [1, 6, 2.01], [2, 13.5, 2]]}, {"timestamp": 1631551132662, "ltp": 3.85, "tv": 4575.16, "trd": [[3.85, 2.17]], "batb": NaN, "batl": [[0, 3.6, 38.09], [1, 3.65, 8.5], [2, 4.4, 386.18]]}, {"timestamp": 1631551133554, "ltp": 3.85, "tv": 4575.16, "trd": NaN, "batb": [[0, 3.4, 8.82], [1, 3.35, 4.42], [2, 3.3, 4.42]], "batl": [[2, 4.1, 1.8]]}, {"timestamp": 1631551134276, "ltp": 3.85, "tv": 4575.16, "trd": NaN, "batb": NaN, "batl": [[2, 3.85, 18.05]]}, {"timestamp": 1631551138083, "ltp": 3.85, "tv": 4575.16, "trd": NaN, "batb": NaN, "batl": [[2, 4.1, 1.8]]}, {"timestamp": 1631551146648, "ltp": 3.5, "tv": 4577.54, "trd": [[3.5, 22.38]], "batb": NaN, "batl": [[0, 3.5, 15.67], [1, 3.6, 38.09], [2, 3.65, 8.5]]}, {"timestamp": 1631551147481, "ltp": 3.5, "tv": 4577.54, "trd": NaN, "batb": [[0, 3.05, 34.14], [1, 2.56, 22.06], [2, 1.01, 105.79]], "batl": [[1, 4.1, 1.8], [2, 4.3, 4.45]]}, {"timestamp": 1631551147962, "ltp": 3.5, "tv": 4577.54, "trd": NaN, "batb": [[0, 2.56, 22.06], [1, 1.01, 105.79], [2, 1.01, 0]], "batl": NaN}, {"timestamp": 1631551148688, "ltp": 3.5, "tv": 4577.54, "trd": NaN, "batb": NaN, "batl": [[0, 4.1, 1.8], [1, 4.3, 4.45], [2, 4.6, 4.41]]}, {"timestamp": 1631551150582, "ltp": 3.5, "tv": 4577.54, "trd": NaN, "batb": [[0, 2.78, 4.66], [1, 2.68, 4.86], [2, 2.62, 5.54]], "batl": NaN}, {"timestamp": 1631551150895, "ltp": 3.5, "tv": 4577.54, "trd": NaN, "batb": [[0, 2.68, 4.86], [1, 2.62, 5.54], [2, 2.56, 22.06]], "batl": NaN}, {"timestamp": 1631551153292, "ltp": 3.5, "tv": 4577.54, "trd": NaN, "batb": [[0, 2.84, 4.97], [1, 2.68, 4.86], [2, 2.62, 5.54]], "batl": NaN}, {"timestamp": 1631551159477, "ltp": 3.5, "tv": 4577.54, "trd": NaN, "batb": [[0, 2.68, 4.86], [1, 2.62, 5.54], [2, 2.56, 22.06]], "batl": [[1, 4.3, 2.45]]}, {"timestamp": 1631551159798, "ltp": 3.5, "tv": 4577.54, "trd": NaN, "batb": NaN, "batl": [[1, 4.6, 4.41], [2, 990, 0.01]]}, {"timestamp": 1631551162998, "ltp": 3.5, "tv": 4577.54, "trd": NaN, "batb": NaN, "batl": [[1, 4.3, 4.65], [2, 4.6, 4.41]]}, {"timestamp": 1631551171201, "ltp": 3.5, "tv": 4577.54, "trd": NaN, "batb": NaN, "batl": [[0, 2.96, 19.49], [1, 4.1, 1.8], [2, 4.3, 4.65]]}, {"timestamp": 1631551174617, "ltp": 2.96, "tv": 4597.03, "trd": [[2.96, 21.61]], "batb": [[0, 3.6, 55.56], [1, 2.68, 4.86], [2, 2.62, 5.54]], "batl": [[0, 4.1, 1.8], [1, 4.2, 70.07]]}, {"timestamp": 1631551175400, "ltp": 2.96, "tv": 4597.03, "trd": NaN, "batb": [[1, 3.5, 24.33], [2, 2.88, 40.01]], "batl": [[1, 4.2, 105.79], [2, 4.3, 22.51]]}, {"timestamp": 1631551175817, "ltp": 2.96, "tv": 4597.03, "trd": NaN, "batb": NaN, "batl": [[1, 4.2, 77.21], [2, 4.3, 8.23]]}, {"timestamp": 1631551182737, "ltp": 2.96, "tv": 4597.03, "trd": NaN, "batb": [[2, 3.15, 3.83]], "batl": NaN}, {"timestamp": 1631551186830, "ltp": 3.9, "tv": 4599.74, "trd": [[3.9, 24.99]], "batb": NaN, "batl": NaN}, {"timestamp": 1631551193908, "ltp": 3.9, "tv": 4599.74, "trd": NaN, "batb": NaN, "batl": [[0, 4.2, 77.21], [1, 4.3, 8.23], [2, 4.4, 3.58]]}, {"timestamp": 1631551196628, "ltp": 3.9, "tv": 4599.74, "trd": NaN, "batb": [[0, 3.1, 3.64], [1, 3, 5], [2, 2.96, 4.63]], "batl": [[0, 4.6, 2], [1, 4.8, 2.02], [2, 5, 2]]}, {"timestamp": 1631551196934, "ltp": 3.9, "tv": 4599.74, "trd": NaN, "batb": [[0, 2.96, 4.63], [1, 2.88, 40.01], [2, 1.01, 105.79]], "batl": [[0, 5.2, 2.03], [1, 990, 0.01], [2, 5, 0]]}, {"timestamp": 1631551200431, "ltp": 3.9, "tv": 4599.74, "trd": NaN, "batb": [[0, 3.1, 3.84], [1, 2.96, 4.63], [2, 2.88, 40.01]], "batl": NaN}, {"timestamp": 1631551203638, "ltp": 3.9, "tv": 4599.74, "trd": NaN, "batb": NaN, "batl": [[0, 4.8, 2.12], [1, 5.2, 2.03], [2, 990, 0.01]]}, {"timestamp": 1631551204631, "ltp": 3.9, "tv": 4599.74, "trd": NaN, "batb": NaN, "batl": [[0, 4.7, 7]]}, {"timestamp": 1631551205625, "ltp": 3.9, "tv": 4599.74, "trd": NaN, "batb": [[0, 3.95, 35.9], [1, 3.35, 27.18], [2, 3.1, 3.84]], "batl": [[1, 4.8, 18.74], [2, 4.9, 9.37]]}, {"timestamp": 1631551205728, "ltp": 3.9, "tv": 4599.74, "trd": NaN, "batb": NaN, "batl": [[1, 4.8, 6.24], [2, 4.9, 3.12]]}, {"timestamp": 1631551212629, "ltp": 3.9, "tv": 4599.74, "trd": NaN, "batb": [[1, 3.85, 2.77], [2, 3.7, 3.22]], "batl": NaN}, {"timestamp": 1631551216039, "ltp": 4.4, "tv": 4603.35, "trd": [[4.4, 3.61]], "batb": NaN, "batl": NaN}, {"timestamp": 1631551225471, "ltp": 4.4, "tv": 4603.35, "trd": NaN, "batb": [[0, 3.85, 2.77], [1, 3.7, 3.22], [2, 3.35, 27.18]], "batl": [[0, 5.6, 2], [1, 990, 0.01], [2, 4.9, 0]]}, {"timestamp": 1631551226364, "ltp": 4.4, "tv": 4603.35, "trd": NaN, "batb": [[0, 3.7, 3.22], [1, 3.6, 2.89]], "batl": [[1, 5.8, 2.02], [2, 990, 0.01]]}, {"timestamp": 1631551232554, "ltp": 4.4, "tv": 4603.35, "trd": NaN, "batb": [[0, 3.85, 2.97], [1, 3.7, 3.22], [2, 3.6, 2.89]], "batl": [[0, 5.2, 2.03], [1, 5.6, 2], [2, 5.8, 2.02]]}, {"timestamp": 1631551236614, "ltp": 4.4, "tv": 4603.35, "trd": NaN, "batb": [[0, 3.7, 3.22], [1, 3.6, 2.89], [2, 3.35, 27.18]], "batl": [[0, 5.6, 2], [1, 5.8, 2.02], [2, 990, 0.01]]}, {"timestamp": 1631551241382, "ltp": 4.4, "tv": 4603.35, "trd": NaN, "batb": NaN, "batl": [[0, 4.7, 2.52], [1, 5.6, 2], [2, 5.8, 2.02]]}, {"timestamp": 1631551244539, "ltp": 4.4, "tv": 4603.35, "trd": NaN, "batb": [[2, 3.55, 38.3]], "batl": [[0, 3.85, 7.38], [1, 4.1, 5.75], [2, 4.4, 40]]}, {"timestamp": 1631551257633, "ltp": 3.85, "tv": 4608.04, "trd": [[3.85, 6.86]], "batb": NaN, "batl": [[0, 3.85, 2.69]]}, {"timestamp": 1631551264660, "ltp": 3.85, "tv": 4608.04, "trd": NaN, "batb": [[0, 3.35, 27.18], [1, 2.64, 20.63], [2, 1.01, 105.79]], "batl": [[0, 4.4, 40], [1, 4.7, 2.52], [2, 4.8, 2.27]]}, {"timestamp": 1631551264760, "ltp": 3.85, "tv": 4608.04, "trd": NaN, "batb": [[0, 2.64, 20.63], [1, 1.01, 105.79], [2, 1.01, 0]], "batl": NaN}, {"timestamp": 1631551286251, "ltp": 3.85, "tv": 4608.04, "trd": NaN, "batb": [[1, 1.9, 3], [2, 1.01, 105.79]], "batl": NaN}, {"timestamp": 1631551293570, "ltp": 4.4, "tv": 4648.04, "trd": [[4.4, 43.61]], "batb": [[0, 4.4, 6.82], [1, 4.3, 3.4], [2, 4.2, 3.4]], "batl": [[0, 4.7, 2.52], [1, 4.8, 7.13], [2, 5, 30.89]]}, {"timestamp": 1631551294579, "ltp": 4.4, "tv": 4648.04, "trd": NaN, "batb": NaN, "batl": [[2, 4.9, 6.12]]}, {"timestamp": 1631551302098, "ltp": 4.7, "tv": 4648.44, "trd": [[4.7, 40.77]], "batb": NaN, "batl": [[0, 4.7, 2.11]]}, {"timestamp": 1631551310896, "ltp": 4.7, "tv": 4650.56, "trd": [[4.7, 42.89]], "batb": NaN, "batl": [[0, 4.8, 7.13], [1, 4.9, 6.12], [2, 5, 33.95]]}, {"timestamp": 1631551315086, "ltp": 4.5, "tv": 4650.62, "trd": [[4.5, 0.31]], "batb": NaN, "batl": NaN}, {"timestamp": 1631551316502, "ltp": 4.5, "tv": 4650.62, "trd": NaN, "batb": [[0, 3.95, 35.57], [1, 3.25, 28.69], [2, 1.9, 3]], "batl": [[0, 5.2, 2.18], [1, 5.4, 2.44], [2, 5.6, 2]]}, {"timestamp": 1631551317177, "ltp": 4.5, "tv": 4650.62, "trd": NaN, "batb": [[0, 3.25, 28.69], [1, 1.9, 3], [2, 1.01, 105.79]], "batl": [[0, 6, 2.36], [1, 990, 0.01], [2, 5.6, 0]]}, {"timestamp": 1631551319592, "ltp": 4.5, "tv": 4650.62, "trd": NaN, "batb": [[0, 4, 10.53], [1, 3.25, 28.69], [2, 1.9, 3]], "batl": NaN}, {"timestamp": 1631551320386, "ltp": 4.5, "tv": 4650.62, "trd": NaN, "batb": [[0, 3.25, 28.69], [1, 1.9, 3], [2, 1.01, 105.79]], "batl": [[0, 5.6, 2.26], [1, 6, 2.36], [2, 990, 0.01]]}, {"timestamp": 1631551321276, "ltp": 4.5, "tv": 4650.62, "trd": NaN, "batb": NaN, "batl": [[0, 6, 2.36], [1, 990, 0.01], [2, 990, 0]]}, {"timestamp": 1631551322598, "ltp": 4.5, "tv": 4650.62, "trd": NaN, "batb": [[0, 5.1, 39.22], [1, 5, 26.2], [2, 3.25, 28.69]], "batl": [[0, 5.5, 3.97], [1, 6, 2.36], [2, 990, 0.01]]}, {"timestamp": 1631551323594, "ltp": 4.5, "tv": 4650.62, "trd": NaN, "batb": [[2, 4.5, 25.58]], "batl": [[1, 5.8, 25.86], [2, 5.9, 12.92]]}, {"timestamp": 1631551324007, "ltp": 4.5, "tv": 4650.62, "trd": NaN, "batb": NaN, "batl": [[1, 5.8, 5.18], [2, 5.9, 2.58]]}, {"timestamp": 1631551325318, "ltp": 4.5, "tv": 4650.62, "trd": NaN, "batb": NaN, "batl": [[0, 5.8, 5.18], [1, 5.9, 2.58], [2, 6, 4.94]]}, {"timestamp": 1631551328214, "ltp": 4.5, "tv": 4650.62, "trd": NaN, "batb": NaN, "batl": [[0, 5.5, 3.97], [1, 5.8, 5.18], [2, 5.9, 2.58]]}, {"timestamp": 1631551334636, "ltp": 5.5, "tv": 4654.59, "trd": [[5.5, 82.55]], "batb": NaN, "batl": [[0, 5.8, 5.18], [1, 5.9, 2.58], [2, 6, 4.94]]}, {"timestamp": 1631551350550, "ltp": 5.5, "tv": 4654.59, "trd": NaN, "batb": NaN, "batl": [[0, 5.7, 6.68], [1, 5.8, 5.18], [2, 5.9, 2.58]]}, {"timestamp": 1631551372862, "ltp": 5.3, "tv": 4655.4, "trd": [[5.3, 16.04]], "batb": NaN, "batl": NaN}, {"timestamp": 1631551383068, "ltp": 5.3, "tv": 4655.4, "trd": NaN, "batb": NaN, "batl": [[0, 5.8, 5.18], [1, 5.9, 2.58], [2, 6, 4.94]]}, {"timestamp": 1631551385970, "ltp": 5.3, "tv": 4655.4, "trd": NaN, "batb": NaN, "batl": [[0, 5.7, 7.43], [1, 5.8, 5.18], [2, 5.9, 2.58]]}, {"timestamp": 1631551393742, "ltp": 5.1, "tv": 4671.76, "trd": [[5.1, 20.49], [5.3, 20.78]], "batb": [[0, 5.1, 33.41]], "batl": NaN}, {"timestamp": 1631551404367, "ltp": 5.1, "tv": 4671.76, "trd": NaN, "batb": NaN, "batl": [[0, 5.8, 5.18], [1, 5.9, 2.58], [2, 6, 4.94]]}, {"timestamp": 1631551406871, "ltp": 5.1, "tv": 4671.76, "trd": NaN, "batb": NaN, "batl": [[0, 5.5, 5.35], [1, 5.8, 5.18], [2, 5.9, 2.58]]}, {"timestamp": 163155