{"info": {"id": "1.187562121", "eventId": "30896488", "eventName": "Match Odds", "marketType": "MATCH_ODDS", "openDate": 1631545615553, "name": "Sh Mochizuki v E Song", "numberOfActiveRunner": 2, "countryCode": "", "sport": "TENNIS", "venue": "", "volume": {"total": 26302.52, "preMatch": 2223.62, "inPlay": 24078.9}, "winner": {"id": 20955040, "name": "Shintaro Mochizuki", "status": "WINNER", "position": 1}, "delay": 3}, "runners": [{"id": 20955040, "name": "Shintaro Mochizuki", "status": "WINNER", "position": 1, "inPlayOdds": 1.52, "inPlayTime": 1631545615553, "avgPrematch": 1.53, "closedOdds": 1.01, "maxPrematch": 1.59, "minPrematch": 1.48, "maxInPlay": 1.74, "minInPlay": 1.01, "inPlayIndex": 59, "lengthOdds": 1604, "lengthOddsPrematch": 59, "lengthOddsInPlay": 1545, "tradedVolume": 22359.83, "preMatchVolume": 2135.5, "inPlayVolume": 20224.33}, {"id": 9625551, "name": "Evan Song", "status": "LOSER", "position": 2, "inPlayOdds": 3.05, "inPlayTime": 1631545615553, "avgPrematch": 2.81, "closedOdds": 6.4, "maxPrematch": 3.05, "minPrematch": 2.74, "maxInPlay": 7.8, "minInPlay": 2.38, "inPlayIndex": 62, "lengthOdds": 1326, "lengthOddsPrematch": 62, "lengthOddsInPlay": 1264, "tradedVolume": 3942.69, "preMatchVolume": 88.12, "inPlayVolume": 3854.57}], "marketUpdates": [{"timestamp": 1631474813317000000, "openDate": "2021-09-13T15:00:00.000Z", "status": "OPEN", "betDelay": 0, "inPlay": false, "complete": true}, {"timestamp": 1631545020214000000, "openDate": "2021-09-13T14:56:00.000Z", "status": "OPEN", "betDelay": 0, "inPlay": false, "complete": true}, {"timestamp": 1631545615553000000, "openDate": "2021-09-13T14:56:00.000Z", "status": "OPEN", "betDelay": 3, "inPlay": true, "complete": true}, {"timestamp": 1631550724673000000, "openDate": "2021-09-13T14:56:00.000Z", "status": "SUSPENDED", "betDelay": 3, "inPlay": true, "complete": true}, {"timestamp": 1631550805601000000, "openDate": "2021-09-13T14:56:00.000Z", "status": "CLOSED", "betDelay": 3, "inPlay": true, "complete": true}], "odds": [{"runnerId": 20955040, "odds": [{"timestamp": 1631531699488, "ltp": 1.57, "tv": 166.28, "trd": [[1.57, 166.29]], "batb": [[0, 1.23, 77.28], [1, 1.17, 63.81], [2, 1.11, 34.07]], "batl": [[0, 1.57, 1040.52], [1, 1.8, 25], [2, 3.3, 42.59]]}, {"timestamp": 1631531700579, "ltp": 1.57, "tv": 166.28, "trd": NaN, "batb": [[0, 1.49, 63.93], [1, 1.23, 77.28], [2, 1.17, 63.81]], "batl": NaN}, {"timestamp": 1631531707204, "ltp": 1.57, "tv": 166.28, "trd": NaN, "batb": NaN, "batl": [[0, 1.59, 1040.52]]}, {"timestamp": 1631532276985, "ltp": 1.57, "tv": 166.28, "trd": NaN, "batb": [[2, 1.18, 766.61]], "batl": NaN}, {"timestamp": 1631533273735, "ltp": 1.59, "tv": 174.69, "trd": [[1.59, 8.4]], "batb": NaN, "batl": [[0, 1.59, 1036.32]]}, {"timestamp": 1631535165537, "ltp": 1.59, "tv": 174.69, "trd": NaN, "batb": NaN, "batl": [[2, 2.16, 2.66]]}, {"timestamp": 1631536793067, "ltp": 1.59, "tv": 174.69, "trd": NaN, "batb": NaN, "batl": [[0, 1.52, 3.44], [1, 1.59, 1036.32], [2, 1.8, 25]]}, {"timestamp": 1631537009030, "ltp": 1.52, "tv": 181.5, "trd": [[1.52, 6.81]], "batb": NaN, "batl": [[0, 1.59, 1036.34], [1, 1.8, 25], [2, 2.16, 2.66]]}, {"timestamp": 1631537014805, "ltp": 1.52, "tv": 181.56, "trd": [[1.52, 6.87]], "batb": [[0, 1.52, 7.71], [1, 1.49, 63.93], [2, 1.23, 77.28]], "batl": [[0, 1.59, 1036.32]]}, {"timestamp": 1631537034605, "ltp": 1.52, "tv": 181.56, "trd": NaN, "batb": [[0, 1.49, 63.93], [1, 1.23, 77.28], [2, 1.18, 766.61]], "batl": NaN}, {"timestamp": 1631537755961, "ltp": 1.52, "tv": 181.56, "trd": NaN, "batb": [[1, 1.25, 78.43], [2, 1.23, 77.28]], "batl": NaN}, {"timestamp": 1631537811785, "ltp": 1.59, "tv": 210.56, "trd": [[1.59, 37.4]], "batb": NaN, "batl": [[0, 1.59, 1021.81]]}, {"timestamp": 1631538001227, "ltp": 1.59, "tv": 210.56, "trd": NaN, "batb": [[0, 1.49, 85.24]], "batl": NaN}, {"timestamp": 1631538156577, "ltp": 1.59, "tv": 210.54, "trd": [[1.52, 6.87], [1.57, 166.27], [1.59, 37.4]], "batb": [[1, 1.25, 78.38], [2, 1.23, 77.23]], "batl": [[0, 1.59, 1021.65], [2, 2.16, 2.66]]}, {"timestamp": 1631538203739, "ltp": 1.59, "tv": 210.54, "trd": NaN, "batb": NaN, "batl": [[0, 1.57, 1021.65], [1, 1.74, 122.52], [2, 1.8, 25]]}, {"timestamp": 1631538204150, "ltp": 1.59, "tv": 210.54, "trd": NaN, "batb": NaN, "batl": [[1, 1.8, 25], [2, 2.16, 2.66]]}, {"timestamp": 1631539261886, "ltp": 1.59, "tv": 210.54, "trd": NaN, "batb": [[1, 1.27, 157.31], [2, 1.25, 78.38]], "batl": NaN}, {"timestamp": 1631540096570, "ltp": 1.59, "tv": 210.54, "trd": NaN, "batb": NaN, "batl": [[0, 1.56, 1021.65]]}, {"timestamp": 1631540156644, "ltp": 1.56, "tv": 230.05, "trd": [[1.56, 19.51]], "batb": NaN, "batl": [[0, 1.56, 1011.89]]}, {"timestamp": 1631540356970, "ltp": 1.56, "tv": 230.05, "trd": NaN, "batb": NaN, "batl": [[2, 2.1, 43.7]]}, {"timestamp": 1631541601374, "ltp": 1.56, "tv": 230.05, "trd": NaN, "batb": [[1, 1.47, 27.18], [2, 1.27, 157.31]], "batl": NaN}, {"timestamp": 1631541757669, "ltp": 1.56, "tv": 230.05, "trd": NaN, "batb": NaN, "batl": [[0, 1.56, 1024.67]]}, {"timestamp": 1631542545340, "ltp": 1.56, "tv": 230.05, "trd": NaN, "batb": NaN, "batl": [[1, 1.6, 2.06], [2, 1.8, 25]]}, {"timestamp": 1631542610840, "ltp": 1.56, "tv": 230.05, "trd": NaN, "batb": [[2, 1.28, 182.49]], "batl": NaN}, {"timestamp": 1631543724424, "ltp": 1.56, "tv": 230.05, "trd": NaN, "batb": NaN, "batl": [[0, 1.53, 2.5], [1, 1.56, 1024.67], [2, 1.6, 2.06]]}, {"timestamp": 1631543747666, "ltp": 1.56, "tv": 230.05, "trd": NaN, "batb": NaN, "batl": [[0, 1.56, 1024.67], [1, 1.6, 2.06], [2, 1.8, 25]]}, {"timestamp": 1631543759151, "ltp": 1.49, "tv": 233.34, "trd": [[1.49, 1.58], [1.5, 1.71]], "batb": [[0, 1.49, 84.45]], "batl": NaN}, {"timestamp": 1631543762995, "ltp": 1.49, "tv": 233.34, "trd": NaN, "batb": [[0, 1.49, 85.24]], "batl": NaN}, {"timestamp": 1631544008837, "ltp": 1.49, "tv": 233.34, "trd": NaN, "batb": [[1, 1.47, 32.99]], "batl": NaN}, {"timestamp": 1631544088843, "ltp": 1.49, "tv": 233.34, "trd": NaN, "batb": [[2, 1.3, 157.31]], "batl": NaN}, {"timestamp": 1631544398780, "ltp": 1.49, "tv": 233.34, "trd": NaN, "batb": NaN, "batl": [[0, 1.54, 1011.89], [1, 1.56, 12.77], [2, 1.6, 2.06]]}, {"timestamp": 1631544539961, "ltp": 1.49, "tv": 233.34, "trd": NaN, "batb": NaN, "batl": [[0, 1.52, 2.55], [1, 1.54, 1011.89], [2, 1.56, 12.77]]}, {"timestamp": 1631544543428, "ltp": 1.49, "tv": 233.34, "trd": NaN, "batb": NaN, "batl": [[0, 1.51, 2.55]]}, {"timestamp": 1631544544733, "ltp": 1.49, "tv": 233.34, "trd": NaN, "batb": [[1, 1.47, 5.81], [2, 1.44, 29.03]], "batl": NaN}, {"timestamp": 1631544546551, "ltp": 1.49, "tv": 233.34, "trd": NaN, "batb": NaN, "batl": [[0, 1.5, 2.55]]}, {"timestamp": 1631544549844, "ltp": 1.49, "tv": 233.34, "trd": NaN, "batb": NaN, "batl": [[0, 1.54, 1011.89], [1, 1.56, 12.77], [2, 1.6, 2.06]]}, {"timestamp": 1631544550251, "ltp": 1.49, "tv": 238.46, "trd": [[1.49, 6.69]], "batb": [[0, 1.49, 82.68], [1, 1.47, 32.99]], "batl": NaN}, {"timestamp": 1631544554629, "ltp": 1.49, "tv": 238.46, "trd": NaN, "batb": [[0, 1.49, 85.24]], "batl": NaN}, {"timestamp": 1631544900460, "ltp": 1.49, "tv": 244.28, "trd": [[1.49, 12.51]], "batb": [[0, 1.49, 82.33]], "batl": NaN}, {"timestamp": 1631544904090, "ltp": 1.49, "tv": 244.28, "trd": NaN, "batb": [[0, 1.49, 85.24]], "batl": NaN}, {"timestamp": 1631544905760, "ltp": 1.54, "tv": 253.15, "trd": [[1.54, 8.87]], "batb": NaN, "batl": [[0, 1.54, 1007.46]]}, {"timestamp": 1631544921788, "ltp": 1.54, "tv": 258.59, "trd": [[1.54, 14.31]], "batb": NaN, "batl": [[0, 1.54, 1004.74]]}, {"timestamp": 1631544933609, "ltp": 1.54, "tv": 258.59, "trd": NaN, "batb": [[2, 1.4, 375]], "batl": NaN}, {"timestamp": 1631544948561, "ltp": 1.54, "tv": 272.0, "trd": [[1.54, 27.72]], "batb": [[1, 1.48, 26.61], [2, 1.47, 32.99]], "batl": [[0, 1.54, 998.04]]}, {"timestamp": 1631545017767, "ltp": 1.52, "tv": 368.94, "trd": [[1.52, 103.81]], "batb": NaN, "batl": [[0, 1.52, 901.1]]}, {"timestamp": 1631545018656, "ltp": 1.52, "tv": 368.94, "trd": NaN, "batb": [[1, 1.47, 5.81], [2, 1.46, 27.77]], "batl": NaN}, {"timestamp": 1631545034490, "ltp": 1.52, "tv": 368.94, "trd": NaN, "batb": NaN, "batl": [[0, 1.52, 903.1]]}, {"timestamp": 1631545061716, "ltp": 1.49, "tv": 369.14, "trd": [[1.49, 12.71]], "batb": [[0, 1.49, 85.14]], "batl": NaN}, {"timestamp": 1631545066510, "ltp": 1.49, "tv": 369.14, "trd": NaN, "batb": [[0, 1.49, 85.24]], "batl": NaN}, {"timestamp": 1631545246807, "ltp": 1.52, "tv": 372.72, "trd": [[1.49, 12.72], [1.52, 107.22], [1.54, 27.74], [1.56, 19.52], [1.57, 166.4], [1.59, 37.42]], "batb": [[2, 1.46, 27.81]], "batl": [[0, 1.52, 900.94], [1, 1.56, 12.79]]}, {"timestamp": 1631545299858, "ltp": 1.52, "tv": 372.72, "trd": NaN, "batb": [[0, 1.47, 5.81], [1, 1.46, 27.81], [2, 1.44, 69.79]], "batl": NaN}, {"timestamp": 1631545300846, "ltp": 1.52, "tv": 372.72, "trd": NaN, "batb": [[0, 1.48, 13.29], [1, 1.47, 5.81], [2, 1.44, 98.86]], "batl": NaN}, {"timestamp": 1631545339463, "ltp": 1.52, "tv": 372.72, "trd": NaN, "batb": NaN, "batl": [[0, 1.49, 2.66], [1, 1.52, 900.94], [2, 1.56, 12.79]]}, {"timestamp": 1631545339981, "ltp": 1.52, "tv": 372.72, "trd": NaN, "batb": [[2, 1.44, 69.79]], "batl": NaN}, {"timestamp": 1631545361706, "ltp": 1.52, "tv": 2095.1, "trd": [[1.49, 18.04], [1.52, 1824.27]], "batb": NaN, "batl": [[0, 1.52, 42.41], [1, 1.56, 12.79], [2, 1.6, 2.06]]}, {"timestamp": 1631545362117, "ltp": 1.52, "tv": 2095.1, "trd": NaN, "batb": [[2, 1.44, 98.86]], "batl": NaN}, {"timestamp": 1631545372439, "ltp": 1.48, "tv": 2096.28, "trd": [[1.48, 1.18]], "batb": [[0, 1.48, 12.7]], "batl": NaN}, {"timestamp": 1631545411336, "ltp": 1.52, "tv": 2135.5, "trd": [[1.52, 1863.49]], "batb": NaN, "batl": [[0, 1.52, 22.8]]}, {"timestamp": 1631545517613, "ltp": 1.52, "tv": 2135.5, "trd": NaN, "batb": NaN, "batl": [[0, 1.52, 1169.51]]}, {"timestamp": 1631545615553, "ltp": 1.52, "tv": 2135.5, "trd": NaN, "batb": [[0, 1.17, 42.47], [1, 1.01, 577.96], [2, 1.44, 0]], "batl": [[0, 1.52, 1167.51], [2, 1.6, 0]]}, {"timestamp": 1631545641147, "ltp": 1.52, "tv": 2135.5, "trd": NaN, "batb": [[0, 1.5, 6.89], [1, 1.17, 42.47], [2, 1.01, 577.96]], "batl": [[1, 1.54, 380.83], [2, 1.56, 12.79]]}, {"timestamp": 1631545642643, "ltp": 1.52, "tv": 2135.5, "trd": NaN, "batb": [[1, 1.4, 78.93], [2, 1.37, 86.06]], "batl": NaN}, {"timestamp": 1631545646251, "ltp": 1.5, "tv": 2156.18, "trd": [[1.5, 22.39]], "batb": [[0, 1.4, 78.93], [1, 1.37, 86.06], [2, 1.17, 42.47]], "batl": NaN}, {"timestamp": 1631545649259, "ltp": 1.5, "tv": 2156.18, "trd": NaN, "batb": [[0, 1.41, 13.98], [1, 1.4, 78.93], [2, 1.37, 86.06]], "batl": NaN}, {"timestamp": 1631545655390, "ltp": 1.5, "tv": 2156.18, "trd": NaN, "batb": [[0, 1.37, 86.06], [1, 1.17, 42.47], [2, 1.01, 577.96]], "batl": [[1, 1.56, 12.79], [2, 1.56, 0]]}, {"timestamp": 1631545663672, "ltp": 1.45, "tv": 2170.06, "trd": [[1.45, 13.88]], "batb": [[0, 1.45, 432.47], [1, 1.37, 86.06], [2, 1.17, 42.47]], "batl": [[0, 1.52, 1832.61]]}, {"timestamp": 1631545664809, "ltp": 1.45, "tv": 2170.06, "trd": NaN, "batb": [[2, 1.35, 92.69]], "batl": NaN}, {"timestamp": 1631545675693, "ltp": 1.45, "tv": 2170.06, "trd": NaN, "batb": [[0, 1.37, 86.06], [1, 1.35, 92.69], [2, 1.17, 42.47]], "batl": [[0, 1.52, 1167.51]]}, {"timestamp": 1631545676103, "ltp": 1.45, "tv": 2170.06, "trd": NaN, "batb": [[0, 1.35, 92.69], [1, 1.17, 42.47], [2, 1.01, 577.96]], "batl": NaN}, {"timestamp": 1631545680624, "ltp": 1.35, "tv": 2220.06, "trd": [[1.35, 50]], "batb": [[0, 1.35, 67.69]], "batl": NaN}, {"timestamp": 1631545684425, "ltp": 1.42, "tv": 2227.1, "trd": [[1.42, 7.04]], "batb": [[0, 1.43, 16.39], [1, 1.35, 67.69], [2, 1.17, 42.47]], "batl": [[0, 1.45, 10.26], [1, 1.46, 20.54], [2, 1.47, 10.28]]}, {"timestamp": 1631545685691, "ltp": 1.42, "tv": 2227.1, "trd": NaN, "batb": [[2, 1.33, 98.73]], "batl": NaN}, {"timestamp": 1631545691195, "ltp": 1.45, "tv": 2237.36, "trd": [[1.45, 24.14]], "batb": NaN, "batl": [[0, 1.46, 20.54], [1, 1.47, 10.28], [2, 1.48, 420.2]]}, {"timestamp": 1631545692911, "ltp": 1.44, "tv": 2257.38, "trd": [[1.44, 20.02]], "batb": [[0, 1.33, 98.73], [1, 1.17, 42.47], [2, 1.01, 577.96]], "batl": [[0, 1.52, 1167.51], [1, 1.56, 12.79], [2, 1.48, 0]]}, {"timestamp": 1631545695527, "ltp": 1.44, "tv": 2257.38, "trd": NaN, "batb": [[0, 1.34, 97.13]], "batl": NaN}, {"timestamp": 1631545707320, "ltp": 1.44, "tv": 2257.38, "trd": NaN, "batb": [[0, 1.43, 139.86], [1, 1.34, 97.13], [2, 1.17, 42.47]], "batl": [[0, 1.5, 7], [1, 1.52, 1553.55], [2, 1.56, 12.79]]}, {"timestamp": 1631545708415, "ltp": 1.47, "tv": 2264.28, "trd": [[1.47, 6.9]], "batb": [[1, 1.39, 83.71], [2, 1.37, 89.92]], "batl": NaN}, {"timestamp": 1631545711848, "ltp": 1.47, "tv": 2264.28, "trd": NaN, "batb": NaN, "batl": [[0, 1.5, 127]]}, {"timestamp": 1631545712833, "ltp": 1.47, "tv": 2270.79, "trd": [[1.47, 13.41]], "batb": NaN, "batl": [[0, 1.5, 7]]}, {"timestamp": 1631545716865, "ltp": 1.47, "tv": 2270.79, "trd": NaN, "batb": NaN, "batl": [[0, 1.52, 1167.51], [1, 1.56, 12.79], [2, 1.56, 0]]}, {"timestamp": 1631545717432, "ltp": 1.47, "tv": 2270.79, "trd": NaN, "batb": [[0, 1.37, 89.92], [1, 1.17, 42.47], [2, 1.05, 477.24]], "batl": NaN}, {"timestamp": 1631545720444, "ltp": 1.47, "tv": 2270.79, "trd": NaN, "batb": [[2, 1.11, 271.16]], "batl": NaN}, {"timestamp": 1631545748488, "ltp": 1.47, "tv": 2270.79, "trd": NaN, "batb": [[0, 1.5, 20], [1, 1.49, 144.22], [2, 1.48, 10]], "batl": [[1, 1.54, 15.23], [2, 1.56, 12.79]]}, {"timestamp": 1631545749885, "ltp": 1.51, "tv": 2277.5, "trd": [[1.51, 6.71]], "batb": NaN, "batl": NaN}, {"timestamp": 1631545752894, "ltp": 1.52, "tv": 2406.51, "trd": [[1.52, 1992.49]], "batb": NaN, "batl": [[0, 1.52, 1038.51]]}, {"timestamp": 1631545753519, "ltp": 1.51, "tv": 2504.78, "trd": [[1.51, 104.98]], "batb": NaN, "batl": NaN}, {"timestamp": 1631545756780, "ltp": 1.51, "tv": 2504.78, "trd": NaN, "batb": NaN, "batl": [[0, 1.52, 1223.51]]}, {"timestamp": 1631545761194, "ltp": 1.52, "tv": 2522.1, "trd": [[1.52, 2009.82]], "batb": NaN, "batl": [[0, 1.52, 1214.85]]}, {"timestamp": 1631545766627, "ltp": 1.52, "tv": 2522.1, "trd": NaN, "batb": [[0, 1.39, 83.21], [1, 1.2, 387.76], [2, 1.17, 42.47]], "batl": [[1, 1.56, 12.79], [2, 1.56, 0]]}, {"timestamp": 1631545766932, "ltp": 1.52, "tv": 2522.1, "trd": NaN, "batb": NaN, "batl": [[0, 1.52, 1029.85]]}, {"timestamp": 1631545769528, "ltp": 1.52, "tv": 2522.1, "trd": NaN, "batb": [[1, 1.25, 238.62], [2, 1.2, 387.76]], "batl": NaN}, {"timestamp": 1631545792341, "ltp": 1.45, "tv": 2535.9, "trd": [[1.45, 37.94]], "batb": [[0, 1.47, 8.45], [1, 1.39, 83.21], [2, 1.25, 238.62]], "batl": [[0, 1.49, 20.14], [1, 1.5, 19.92], [2, 1.51, 10.06]]}, {"timestamp": 1631545793737, "ltp": 1.45, "tv": 2535.9, "trd": NaN, "batb": [[2, 1.34, 98.89]], "batl": NaN}, {"timestamp": 1631545797115, "ltp": 1.46, "tv": 2602.15, "trd": [[1.46, 49.35], [1.47, 30.31]], "batb": [[0, 1.39, 83.21], [1, 1.34, 98.89], [2, 1.25, 238.62]], "batl": NaN}, {"timestamp": 1631545800240, "ltp": 1.46, "tv": 2602.15, "trd": NaN, "batb": NaN, "batl": [[0, 1.49, 120.14]]}, {"timestamp": 1631545802221, "ltp": 1.46, "tv": 2602.15, "trd": NaN, "batb": NaN, "batl": [[1, 1.5, 10.06]]}, {"timestamp": 1631545805138, "ltp": 1.46, "tv": 2602.15, "trd": NaN, "batb": [[0, 1.46, 12.57], [1, 1.39, 83.21], [2, 1.34, 98.89]], "batl": [[0, 1.48, 12.04], [1, 1.49, 120.14], [2, 1.5, 10.06]]}, {"timestamp": 1631545807264, "ltp": 1.46, "tv": 2602.15, "trd": NaN, "batb": [[0, 1.39, 83.21], [1, 1.34, 98.89], [2, 1.25, 238.62]], "batl": [[0, 1.49, 120.14], [1, 1.5, 10.06], [2, 1.51, 10.06]]}, {"timestamp": 1631545810135, "ltp": 1.46, "tv": 2602.15, "trd": NaN, "batb": [[0, 1.46, 12.57], [1, 1.39, 83.21], [2, 1.34, 98.89]], "batl": [[0, 1.48, 12.04], [1, 1.49, 120.14], [2, 1.5, 10.06]]}, {"timestamp": 1631545812675, "ltp": 1.46, "tv": 2602.15, "trd": NaN, "batb": [[0, 1.47, 5], [1, 1.46, 12.57], [2, 1.39, 83.21]], "batl": NaN}, {"timestamp": 1631545828586, "ltp": 1.46, "tv": 2602.15, "trd": NaN, "batb": [[0, 1.46, 12.57], [1, 1.39, 83.21], [2, 1.34, 98.89]], "batl": NaN}, {"timestamp": 1631545831651, "ltp": 1.48, "tv": 2612.15, "trd": [[1.48, 11.18]], "batb": NaN, "batl": [[0, 1.48, 7.04]]}, {"timestamp": 1631545841881, "ltp": 1.48, "tv": 2612.15, "trd": NaN, "batb": [[0, 1.39, 83.21], [1, 1.34, 98.89], [2, 1.25, 238.62]], "batl": [[0, 1.49, 120.14], [1, 1.5, 10.06], [2, 1.51, 10.06]]}, {"timestamp": 1631545847881, "ltp": 1.48, "tv": 2612.15, "trd": NaN, "batb": [[0, 1.34, 98.89], [1, 1.25, 238.62], [2, 1.2, 387.76]], "batl": [[0, 1.52, 1029.85], [1, 1.56, 12.79], [2, 1.51, 0]]}, {"timestamp": 1631545861794, "ltp": 1.4, "tv": 2619.29, "trd": [[1.4, 7.14]], "batb": [[1, 1.2, 387.76], [2, 1.17, 42.47]], "batl": [[0, 1.43, 160.84], [1, 1.44, 10.5], [2, 1.45, 10.5]]}, {"timestamp": 1631545862782, "ltp": 1.4, "tv": 2619.29, "trd": NaN, "batb": [[0, 1.38, 21.74], [1, 1.37, 10.88], [2, 1.36, 10.88]], "batl": NaN}, {"timestamp": 1631545866581, "ltp": 1.4, "tv": 2624.94, "trd": [[1.4, 12.79]], "batb": NaN, "batl": NaN}, {"timestamp": 1631545869740, "ltp": 1.39, "tv": 2809.23, "trd": [[1.39, 184.29]], "batb": NaN, "batl": NaN}, {"timestamp": 1631545870832, "ltp": 1.42, "tv": 2817.9, "trd": [[1.42, 15.7]], "batb": [[0, 1.38, 10.87], [1, 1.37, 5.44], [2, 1.36, 5.44]], "batl": [[0, 1.43, 80.42], [1, 1.44, 5.25], [2, 1.45, 5.25]]}, {"timestamp": 1631545871208, "ltp": 1.42, "tv": 2817.9, "trd": NaN, "batb": [[0, 1.28, 121.79], [1, 1.25, 512.59], [2, 1.2, 387.76]], "batl": [[0, 1.52, 1029.85], [1, 1.56, 12.79], [2, 1.77, 508.04]]}, {"timestamp": 1631545886424, "ltp": 1.42, "tv": 2817.9, "trd": NaN, "batb": [[1, 1.2, 387.76], [2, 1.17, 42.47]], "batl": NaN}, {"timestamp": 1631545887849, "ltp": 1.42, "tv": 2817.9, "trd": NaN, "batb": [[0, 1.43, 20.98], [1, 1.42, 10.5], [2, 1.41, 10.5]], "batl": [[0, 1.5, 259.95], [1, 1.52, 1029.85], [2, 1.56, 12.79]]}, {"timestamp": 1631545888912, "ltp": 1.44, "tv": 2824.84, "trd": [[1.44, 26.96]], "batb": NaN, "batl": NaN}, {"timestamp": 1631545895727, "ltp": 1.44, "tv": 2824.84, "trd": NaN, "batb": NaN, "batl": [[0, 1.45, 180], [1, 1.5, 259.95], [2, 1.52, 1029.85]]}, {"timestamp": 1631545901643, "ltp": 1.44, "tv": 2824.84, "trd": NaN, "batb": [[0, 1.44, 11.29], [1, 1.43, 20.98], [2, 1.42, 10.5]], "batl": [[1, 1.46, 14.83], [2, 1.5, 259.95]]}, {"timestamp": 1631545901954, "ltp": 1.43, "tv": 3008.04, "trd": [[1.43, 160.62], [1.44, 49.54]], "batb": [[0, 1.42, 10.5], [1, 1.41, 10.5], [2, 1.38, 85.81]], "batl": NaN}, {"timestamp": 1631545908861, "ltp": 1.43, "tv": 3008.04, "trd": NaN, "batb": [[0, 1.32, 104.6], [1, 1.28, 493.1], [2, 1.2, 387.76]], "batl": [[0, 1.52, 1029.85], [1, 1.56, 12.79], [2, 1.77, 508.04]]}, {"timestamp": 1631545913756, "ltp": 1.43, "tv": 3008.04, "trd": NaN, "batb": NaN, "batl": [[0, 1.48, 370.81], [1, 1.52, 1029.85], [2, 1.56, 12.79]]}, {"timestamp": 1631545913963, "ltp": 1.43, "tv": 3008.04, "trd": NaN, "batb": NaN, "batl": [[0, 1.52, 1029.85], [1, 1.56, 12.79], [2, 1.77, 508.04]]}, {"timestamp": 1631545923856, "ltp": 1.43, "tv": 3008.04, "trd": NaN, "batb": [[1, 1.2, 387.76], [2, 1.17, 42.47]], "batl": NaN}, {"timestamp": 1631545925473, "ltp": 1.43, "tv": 3008.04, "trd": NaN, "batb": [[0, 1.48, 438.47], [1, 1.47, 61.22], [2, 1.46, 30.61]], "batl": [[0, 1.5, 6.76], [1, 1.52, 1029.85], [2, 1.56, 12.79]]}, {"timestamp": 1631545926879, "ltp": 1.48, "tv": 3021.56, "trd": [[1.48, 24.7]], "batb": [[0, 1.48, 431.71], [1, 1.47, 20.4], [2, 1.46, 10.2]], "batl": NaN}, {"timestamp": 1631545933376, "ltp": 1.48, "tv": 3021.56, "trd": NaN, "batb": NaN, "batl": [[0, 1.49, 237], [1, 1.5, 6.76], [2, 1.52, 1029.85]]}, {"timestamp": 1631545934161, "ltp": 1.48, "tv": 3884.98, "trd": [[1.48, 888.12]], "batb": [[0, 1.47, 20.4], [1, 1.46, 10.2], [2, 1.45, 10.2]], "batl": [[0, 1.48, 274.17], [1, 1.49, 237], [2, 1.5, 6.76]]}, {"timestamp": 1631545939696, "ltp": 1.48, "tv": 3884.98, "trd": NaN, "batb": NaN, "batl": [[0, 1.49, 237], [1, 1.5, 6.76], [2, 1.52, 1029.85]]}, {"timestamp": 1631545943907, "ltp": 1.48, "tv": 3884.98, "trd": NaN, "batb": NaN, "batl": [[1, 1.52, 1029.85], [2, 1.56, 12.79]]}, {"timestamp": 1631545944893, "ltp": 1.48, "tv": 3884.98, "trd": NaN, "batb": [[0, 1.37, 89.08], [1, 1.31, 484.59], [2, 1.2, 387.76]], "batl": [[0, 1.52, 1029.85], [1, 1.56, 12.79], [2, 1.77, 508.04]]}, {"timestamp": 1631545952312, "ltp": 1.48, "tv": 3884.98, "trd": NaN, "batb": [[1, 1.2, 387.76], [2, 1.17, 42.47]], "batl": [[2, 44, 7.22]]}, {"timestamp": 1631545954233, "ltp": 1.48, "tv": 3884.98, "trd": NaN, "batb": [[0, 1.49, 134.22], [1, 1.37, 89.08], [2, 1.2, 387.76]], "batl": [[2, 1.58, 589.87]]}, {"timestamp": 1631545955912, "ltp": 1.48, "tv": 3884.98, "trd": NaN, "batb": [[1, 1.46, 66.68], [2, 1.42, 75.32]], "batl": [[1, 1.53, 6.54], [2, 1.56, 12.79]]}, {"timestamp": 1631545962625, "ltp": 1.48, "tv": 3884.98, "trd": NaN, "batb": [[0, 1.46, 66.68], [1, 1.42, 75.32], [2, 1.34, 472.33]], "batl": [[1, 1.56, 12.79], [2, 1.95, 415.94]]}, {"timestamp": 1631545962951, "ltp": 1.48, "tv": 3884.98, "trd": NaN, "batb": [[0, 1.42, 75.32], [1, 1.34, 472.33], [2, 1.25, 238.62]], "batl": NaN}, {"timestamp": 1631545969619, "ltp": 1.48, "tv": 3884.98, "trd": NaN, "batb": [[1, 1.25, 238.62], [2, 1.2, 387.76]], "batl": NaN}, {"timestamp": 1631545970852, "ltp": 1.52, "tv": 5061.88, "trd": [[1.52, 3186.73]], "batb": [[0, 1.54, 341.46], [1, 1.51, 49.02], [2, 1.42, 75.32]], "batl": [[0, 1.56, 12.79], [1, 1.58, 24.19], [2, 1.6, 343.95]]}, {"timestamp": 1631545971845, "ltp": 1.52, "tv": 5061.88, "trd": NaN, "batb": [[1, 1.51, 9.8]], "batl": [[0, 1.56, 19.2], [2, 1.59, 94.34]]}, {"timestamp": 1631545972254, "ltp": 1.54, "tv": 5065.88, "trd": [[1.54, 31.74]], "batb": [[0, 1.54, 339.46], [2, 1.5, 61.15]], "batl": [[2, 1.59, 18.86]]}, {"timestamp": 1631545975850, "ltp": 1.54, "tv": 5065.88, "trd": NaN, "batb": [[1, 1.52, 2], [2, 1.51, 9.8]], "batl": [[1, 1.57, 34.92], [2, 1.58, 24.19]]}, {"timestamp": 1631545976049, "ltp": 1.54, "tv": 5065.88, "trd": NaN, "batb": NaN, "batl": [[1, 1.58, 24.19], [2, 1.59, 18.86]]}, {"timestamp": 1631545978363, "ltp": 1.54, "tv": 5065.88, "trd": NaN, "batb": NaN, "batl": [[0, 1.56, 180.2]]}, {"timestamp": 1631545979046, "ltp": 1.54, "tv": 5756.18, "trd": [[1.54, 722.04]], "batb": [[0, 1.52, 2], [1, 1.51, 9.8], [2, 1.5, 61.15]], "batl": [[0, 1.54, 355.04], [1, 1.56, 180.2], [2, 1.58, 24.19]]}, {"timestamp": 1631545981646, "ltp": 1.54, "tv": 5756.18, "trd": NaN, "batb": NaN, "batl": [[0, 1.56, 180.2], [1, 1.58, 24.19], [2, 1.59, 18.86]]}, {"timestamp": 1631545989224, "ltp": 1.54, "tv": 5756.18, "trd": NaN, "batb": NaN, "batl": [[1, 1.59, 18.86], [2, 1.6, 353.39]]}, {"timestamp": 1631545990853, "ltp": 1.54, "tv": 5756.18, "trd": NaN, "batb": [[1, 1.46, 68.11], [2, 1.38, 455.1]], "batl": [[0, 1.56, 173.79], [1, 1.95, 415.94], [2, 44, 7.22]]}, {"timestamp": 1631545991848, "ltp": 1.54, "tv": 5756.18, "trd": NaN, "batb": NaN, "batl": [[0, 1.56, 12.79]]}, {"timestamp": 1631545999069, "ltp": 1.54, "tv": 5756.18, "trd": NaN, "batb": [[2, 1.25, 238.62]], "batl": [[1, 44, 7.22], [2, 810, 0.07]]}, {"timestamp": 1631546000859, "ltp": 1.56, "tv": 5768.97, "trd": [[1.56, 32.31]], "batb": [[0, 1.62, 9.99], [1, 1.61, 55.9], [2, 1.6, 27.95]], "batl": [[0, 1.66, 22.59]]}, {"timestamp": 1631546001753, "ltp": 1.62, "tv": 5772.97, "trd": [[1.62, 4]], "batb": [[0, 1.62, 7.99], [1, 1.61, 18.64], [2, 1.6, 9.32]], "batl": [[0, 1.64, 6.1], [1, 1.66, 22.59], [2, 1.68, 17.86]]}, {"timestamp": 1631546011655, "ltp": 1.62, "tv": 5772.97, "trd": NaN, "batb": [[0, 1.61, 18.64], [1, 1.6, 9.32], [2, 1.59, 84.79]], "batl": [[1, 1.68, 17.86], [2, 1.69, 8.92]]}, {"timestamp": 1631546014845, "ltp": 1.62, "tv": 5772.97, "trd": NaN, "batb": [[0, 1.58, 2], [1, 1.52, 59.79], [2, 1.51, 48.99]], "batl": [[0, 2.16, 347.9], [1, 44, 7.22], [2, 810, 0.07]]}, {"timestamp": 1631546015526, "ltp": 1.62, "tv": 5772.97, "trd": NaN, "batb": NaN, "batl": [[0, 1.74, 31.25], [1, 2.16, 347.9], [2, 44, 7.22]]}, {"timestamp": 1631546017838, "ltp": 1.62, "tv": 5772.97, "trd": NaN, "batb": NaN, "batl": [[0, 1.72, 36.91], [1, 1.74, 31.25], [2, 1.75, 30.86]]}, {"timestamp": 1631546018259, "ltp": 1.62, "tv": 5772.97, "trd": NaN, "batb": NaN, "batl": [[0, 1.74, 31.25], [1, 1.75, 30.86], [2, 2.16, 347.9]]}, {"timestamp": 1631546020829, "ltp": 1.62, "tv": 5772.97, "trd": NaN, "batb": NaN, "batl": [[0, 1.65, 18.7], [1, 1.74, 31.25], [2, 1.75, 30.86]]}, {"timestamp": 1631546021831, "ltp": 1.62, "tv": 5772.97, "trd": NaN, "batb": NaN, "batl": [[0, 1.74, 31.25], [1, 1.75, 30.86], [2, 2.16, 347.9]]}, {"timestamp": 1631546024748, "ltp": 1.62, "tv": 5772.97, "trd": NaN, "batb": NaN, "batl": [[0, 1.72, 36.16], [1, 1.74, 31.25], [2, 1.75, 30.86]]}, {"timestamp": 1631546025269, "ltp": 1.62, "tv": 5772.97, "trd": NaN, "batb": NaN, "batl": [[0, 1.74, 31.25], [1, 1.75, 30.86], [2, 2.16, 347.9]]}, {"timestamp": 1631546031899, "ltp": 1.62, "tv": 5772.97, "trd": NaN, "batb": NaN, "batl": [[0, 1.72, 34.91], [1, 1.74, 31.25], [2, 1.75, 30.86]]}, {"timestamp": 1631546032716, "ltp": 1.74, "tv": 5797.95, "trd": [[1.74, 24.98]], "batb": NaN, "batl": [[0, 1.74, 18.76], [1, 1.75, 30.86], [2, 1.78, 13.12]]}, {"timestamp": 1631546033716, "ltp": 1.72, "tv": 5799.95, "trd": [[1.72, 2]], "batb": [[0, 1.7, 38.5], [1, 1.62, 46.22], [2, 1.58, 2]], "batl": [[2, 1.76, 5.68]]}, {"timestamp": 1631546036874, "ltp": 1.72, "tv": 5799.95, "trd": NaN, "batb": [[1, 1.66, 2], [2, 1.62, 46.22]], "batl": NaN}, {"timestamp": 1631546039461, "ltp": 1.72, "tv": 5799.95, "trd": NaN, "batb": [[2, 1.63, 38.23]], "batl": NaN}, {"timestamp": 1631546041772, "ltp": 1.72, "tv": 5808.61, "trd": [[1.72, 10.66]], "batb": NaN, "batl": NaN}, {"timestamp": 1631546046887, "ltp": 1.72, "tv": 5808.61, "trd": NaN, "batb": [[0, 1.66, 2], [1, 1.62, 46.22], [2, 1.59, 41.11]], "batl": [[0, 1.9, 28.65], [1, 2.16, 347.9], [2, 810, 0.07]]}, {"timestamp": 1631546049911, "ltp": 1.72, "tv": 5808.61, "trd": NaN, "batb": [[1, 1.63, 44.23], [2, 1.62, 46.22]], "batl": NaN}, {"timestamp": 1631546050336, "ltp": 1.72, "tv": 5808.61, "trd": NaN, "batb": [[1, 1.62, 46.22], [2, 1.59, 41.11]], "batl": NaN}, {"timestamp": 1631546051120, "ltp": 1.72, "tv": 5808.61, "trd": NaN, "batb": NaN, "batl": [[0, 1.72, 1146.71], [1, 1.9, 28.65], [2, 2.16, 347.9]]}, {"timestamp": 1631546053598, "ltp": 1.72, "tv": 5808.61, "trd": NaN, "batb": NaN, "batl": [[1, 1.86, 32.75], [2, 1.9, 28.65]]}, {"timestamp": 1631546056828, "ltp": 1.72, "tv": 5808.61, "trd": NaN, "batb": [[1, 1.63, 37.23], [2, 1.62, 46.22]], "batl": [[0, 1.9, 28.65], [1, 2.16, 347.9], [2, 810, 0.07]]}, {"timestamp": 1631546057238, "ltp": 1.72, "tv": 5808.61, "trd": NaN, "batb": [[1, 1.62, 46.22], [2, 1.59, 41.11]], "batl": NaN}, {"timestamp": 1631546060356, "ltp": 1.72, "tv": 5808.61, "trd": NaN, "batb": NaN, "batl": [[0, 1.68, 41.59], [1, 1.69, 8.92], [2, 1.7, 8.92]]}, {"timestamp": 1631546061474, "ltp": 1.72, "tv": 5808.61, "trd": NaN, "batb": [[2, 1.61, 18.64]], "batl": NaN}, {"timestamp": 1631546068825, "ltp": 1.72, "tv": 5808.61, "trd": NaN, "batb": NaN, "batl": [[0, 1.68, 152.59]]}, {"timestamp": 1631546074837, "ltp": 1.72, "tv": 5808.61, "trd": NaN, "batb": [[1, 1.58, 2], [2, 1.57, 37.57]], "batl": [[0, 1.82, 31.75], [1, 1.86, 28.25], [2, 1.87, 29.5]]}, {"timestamp": 1631546075046, "ltp": 1.72, "tv": 5808.61, "trd": NaN, "batb": NaN, "batl": [[0, 1.87, 29.5], [1, 2.16, 347.9], [2, 810, 0.07]]}, {"timestamp": 1631546077661, "ltp": 1.66, "tv": 5812.61, "trd": [[1.66, 4]], "batb": [[0, 1.58, 2], [1, 1.54, 100.06], [2, 1.52, 2]], "batl": [[0, 1.64, 571.36], [1, 1.87, 29.5], [2, 2.16, 347.9]]}, {"timestamp": 1631546078238, "ltp": 1.66, "tv": 5812.61, "trd": NaN, "batb": NaN, "batl": [[1, 1.82, 32.25], [2, 1.87, 29.5]]}, {"timestamp": 1631546080852, "ltp": 1.64, "tv": 5845.41, "trd": [[1.64, 32.8]], "batb": NaN, "batl": [[0, 1.64, 538.56]]}, {"timestamp": 1631546082736, "ltp": 1.64, "tv": 5845.41, "trd": NaN, "batb": NaN, "batl": [[0, 1.87, 29.5], [1, 2.16, 347.9], [2, 810, 0.07]]}, {"timestamp": 1631546089883, "ltp": 1.64, "tv": 5845.41, "trd": NaN, "batb": NaN, "batl": [[2, 820, 0.14]]}, {"timestamp": 1631546090043, "ltp": 1.64, "tv": 5845.41, "trd": NaN, "batb": NaN, "batl": [[2, 810, 0.07]]}, {"timestamp": 1631546095796, "ltp": 1.64, "tv": 5845.41, "trd": NaN, "batb": NaN, "batl": [[0, 1.6, 28.09], [1, 1.87, 29.5], [2, 2.16, 347.9]]}, {"timestamp": 1631546096690, "ltp": 1.64, "tv": 5845.41, "trd": NaN, "batb": [[1, 1.55, 96.76], [2, 1.54, 148.44]], "batl": NaN}, {"timestamp": 1631546096954, "ltp": 1.64, "tv": 5845.41, "trd": NaN, "batb": [[1, 1.55, 19.36], [2, 1.54, 109.74]], "batl": NaN}, {"timestamp": 1631546102069, "ltp": 1.64, "tv": 5845.41, "trd": NaN, "batb": NaN, "batl": [[1, 1.73, 34.5], [2, 1.78, 33.25]]}, {"timestamp": 1631546103706, "ltp": 1.64, "tv": 5845.41, "trd": NaN, "batb": NaN, "batl": [[0, 1.6, 180.09]]}, {"timestamp": 1631546108500, "ltp": 1.6, "tv": 5890.12, "trd": [[1.6, 44.71]], "batb": NaN, "batl": [[0, 1.6, 146.21]]}, {"timestamp": 1631546115874, "ltp": 1.6, "tv": 5890.12, "trd": NaN, "batb": [[1, 1.52, 2], [2, 1.51, 47.99]], "batl": [[0, 1.73, 34.5], [1, 1.78, 33.25], [2, 1.87, 29.5]]}, {"timestamp": 1631546116187, "ltp": 1.6, "tv": 5890.12, "trd": NaN, "batb": NaN, "batl": [[0, 1.78, 33.25], [1, 2.16, 347.9], [2, 810, 0.07]]}, {"timestamp": 1631546121828, "ltp": 1.6, "tv": 5890.12, "trd": NaN, "batb": NaN, "batl": [[0, 1.62, 18.75], [1, 1.78, 33.25], [2, 2.16, 347.9]]}, {"timestamp": 1631546122824, "ltp": 1.6, "tv": 5890.12, "trd": NaN, "batb": NaN, "batl": [[0, 1.73, 37.5]]}, {"timestamp": 1631546123032, "ltp": 1.6, "tv": 5890.12, "trd": NaN, "batb": NaN, "batl": [[0, 1.78, 33.25], [1, 2.16, 347.9], [2, 810, 0.07]]}, {"timestamp": 1631546129716, "ltp": 1.6, "tv": 5890.12, "trd": NaN, "batb": NaN, "batl": [[0, 1.73, 36.5], [1, 1.78, 33.25], [2, 2.16, 347.9]]}, {"timestamp": 1631546130028, "ltp": 1.6, "tv": 5890.12, "trd": NaN, "batb": NaN, "batl": [[0, 1.78, 33.25], [1, 2.16, 347.9], [2, 810, 0.07]]}, {"timestamp": 1631546136807, "ltp": 1.6, "tv": 5890.12, "trd": NaN, "batb": NaN, "batl": [[0, 1.73, 34.5], [1, 1.78, 33.25], [2, 2.16, 347.9]]}, {"timestamp": 1631546137123, "ltp": 1.6, "tv": 5890.12, "trd": NaN, "batb": NaN, "batl": [[0, 1.78, 33.25], [1, 2.16, 347.9], [2, 810, 0.07]]}, {"timestamp": 1631546138425, "ltp": 1.6, "tv": 5890.12, "trd": NaN, "batb": [[0, 1.69, 6.92], [1, 1.58, 2], [2, 1.52, 2]], "batl": [[0, 1.78, 52.18], [1, 1.83, 600.31], [2, 2.16, 347.9]]}, {"timestamp": 1631546139418, "ltp": 1.6, "tv": 5890.12, "trd": NaN, "batb": [[1, 1.68, 40.6], [2, 1.58, 2]], "batl": [[0, 1.74, 5.75], [1, 1.78, 52.18], [2, 1.79, 16.76]]}, {"timestamp": 1631546144649, "ltp": 1.6, "tv": 5890.12, "trd": NaN, "batb": [[2, 1.59, 47.11]], "batl": NaN}, {"timestamp": 1631546146837, "ltp": 1.6, "tv": 5890.12, "trd": NaN, "batb": [[0, 1.68, 40.6], [1, 1.58, 2], [2, 1.55, 53.35]], "batl": [[0, 2.08, 7.94], [1, 2.16, 347.9], [2, 810, 0.07]]}, {"timestamp": 1631546147850, "ltp": 1.6, "tv": 5890.12, "trd": NaN, "batb": [[0, 1.58, 2], [1, 1.55, 53.35], [2, 1.54, 43.12]], "batl": NaN}, {"timestamp": 1631546151756, "ltp": 1.6, "tv": 5890.12, "trd": NaN, "batb": NaN, "batl": [[0, 2.16, 347.9], [1, 810, 0.07], [2, 810, 0]]}, {"timestamp": 1631546153768, "ltp": 1.6, "tv": 5890.12, "trd": NaN, "batb": [[0, 1.59, 44.11], [1, 1.58, 2], [2, 1.55, 53.35]], "batl": [[0, 2, 24.53], [1, 2.16, 347.9], [2, 810, 0.07]]}, {"timestamp": 1631546154774, "ltp": 1.6, "tv": 5902.34, "trd": [[1.6, 56.93]], "batb": [[0, 1.58, 2], [1, 1.55, 53.35], [2, 1.54, 43.12]], "batl": [[0, 1.6, 112.78], [1, 1.62, 6.17], [2, 1.64, 19.71]]}, {"timestamp": 1631546159680, "ltp": 1.6, "tv": 5909.0, "trd": [[1.6, 63.59]], "batb": NaN, "batl": [[0, 1.6, 106.12]]}, {"timestamp": 1631546162977, "ltp": 1.6, "tv": 5909.0, "trd": NaN, "batb": NaN, "batl": [[0, 1.6, 247.12]]}, {"timestamp": 1631546164679, "ltp": 1.6, "tv": 5909.0, "trd": NaN, "batb": [[1, 1.52, 52.99], [2, 1.51, 47.99]], "batl": [[0, 1.6, 141], [1, 1.75, 31.7], [2, 1.8, 30.92]]}, {"timestamp": 1631546165893, "ltp": 1.6, "tv": 5909.0, "trd": NaN, "batb": NaN, "batl": [[0, 1.75, 31.7], [1, 1.8, 30.92], [2, 2.16, 347.9]]}, {"timestamp": 1631546166253, "ltp": 1.6, "tv": 5909.0, "trd": NaN, "batb": NaN, "batl": [[0, 1.8, 30.92], [1, 2.16, 347.9], [2, 810, 0.07]]}, {"timestamp": 1631546172908, "ltp": 1.6, "tv": 5909.0, "trd": NaN, "batb": NaN, "batl": [[0, 1.75, 35.3], [1, 1.8, 30.92], [2, 2.16, 347.9]]}, {"timestamp": 1631546173213, "ltp": 1.6, "tv": 5909.0, "trd": NaN, "batb": NaN, "batl": [[0, 1.8, 30.92], [1, 2.16, 347.9], [2, 810, 0.07]]}, {"timestamp": 1631546184721, "ltp": 1.6, "tv": 5909.0, "trd": NaN, "batb": NaN, "batl": [[1, 810, 0.07], [2, 810, 0]]}, {"timestamp": 1631546186626, "ltp": 1.58, "tv": 5913.0, "trd": [[1.58, 4]], "batb": [[0, 1.52, 2], [1, 1.51, 47.99], [2, 1.49, 54.01]], "batl": [[0, 1.54, 10.72], [1, 1.55, 6.45], [2, 1.62, 1094.16]]}, {"timestamp": 1631546192435, "ltp": 1.58, "tv": 5913.0, "trd": NaN, "batb": NaN, "batl": [[0, 1.54, 202.72]]}, {"timestamp": 1631546193538, "ltp": 1.58, "tv": 5913.0, "trd": NaN, "batb": NaN, "batl": [[2, 1.6, 41.56]]}, {"timestamp": 1631546196830, "ltp": 1.51, "tv": 6445.12, "trd": [[1.51, 623.36], [1.52, 3200.47]], "batb": [[0, 1.49, 54.01], [1, 1.48, 137.63], [2, 1.47, 10.14]], "batl": [[0, 1.51, 223.75], [1, 1.54, 202.72], [2, 1.55, 6.45]]}, {"timestamp": 1631546199927, "ltp": 1.51, "tv": 6460.44, "trd": [[1.51, 638.68]], "batb": NaN, "batl": [[0, 1.51, 216.09]]}, {"timestamp": 1631546203811, "ltp": 1.51, "tv": 6460.44, "trd": NaN, "batb": [[0, 1.43, 72.81], [1, 1.38, 455.1], [2, 1.25, 238.62]], "batl": [[1, 1.6, 41.56], [2, 1.63, 40.5]]}, {"timestamp": 1631546204653, "ltp": 1.51, "tv": 6460.44, "trd": NaN, "batb": NaN, "batl": [[0, 1.63, 40.5], [1, 2.04, 388.69], [2, 810, 0.07]]}, {"timestamp": 1631546206848, "ltp": 1.51, "tv": 6460.44, "trd": NaN, "batb": [[0, 1.44, 63.17], [1, 1.43, 72.81], [2, 1.38, 455.1]], "batl": NaN}, {"timestamp": 1631546207846, "ltp": 1.51, "tv": 6460.44, "trd": NaN, "batb": NaN, "batl": [[0, 1.6, 40.11], [1, 1.63, 40.5], [2, 2.04, 388.69]]}, {"timestamp": 1631546208053, "ltp": 1.51, "tv": 6460.44, "trd": NaN, "batb": NaN, "batl": [[0, 1.63, 40.5], [1, 2.04, 388.69], [2, 810, 0.07]]}, {"timestamp": 1631546212207, "ltp": 1.51, "tv": 6460.44, "trd": NaN, "batb": NaN, "batl": [[0, 2.04, 388.69], [1, 810, 0.07], [2, 810, 0]]}, {"timestamp": 1631546214905, "ltp": 1.51, "tv": 6460.44, "trd": NaN, "batb": [[0, 1.45, 500.84], [1, 1.44, 63.17], [2, 1.43, 72.81]], "batl": [[0, 1.5, 2153.41], [1, 1.54, 1044.08], [2, 1.56, 9.85]]}, {"timestamp": 1631546215905, "ltp": 1.51, "tv": 6460.44, "trd": NaN, "batb": [[2, 1.43, 177.71]], "batl": [[0, 1.49, 17.99], [1, 1.5, 6.67], [2, 1.54, 1044.08]]}, {"timestamp": 1631546216324, "ltp": 1.51, "tv": 6460.44, "trd": NaN, "batb": [[2, 1.43, 93.79]], "batl": NaN}, {"timestamp": 1631546223089, "ltp": 1.51, "tv": 6460.44, "trd": NaN, "batb": NaN, "batl": [[0, 1.48, 273], [1, 1.49, 17.99], [2, 1.5, 6.67]]}, {"timestamp": 1631546227515, "ltp": 1.45, "tv": 7292.05, "trd": [[1.45, 854.1], [1.46, 64.8]], "batb": [[0, 1.45, 92.76]], "batl": NaN}, {"timestamp": 1631546237705, "ltp": 1.45, "tv": 7477.57, "trd": [[1.45, 1039.62]], "batb": [[0, 1.44, 63.17], [1, 1.43, 93.79], [2, 1.42, 10.5]], "batl": [[0, 1.45, 613.12], [1, 1.48, 273], [2, 1.49, 17.99]]}, {"timestamp": 1631546240624, "ltp": 1.45, "tv": 7491.58, "trd": [[1.45, 1053.63]], "batb": NaN, "batl": [[0, 1.45, 599.11]]}, {"timestamp": 1631546246935, "ltp": 1.45, "tv": 7491.58, "trd": NaN, "batb": NaN, "batl": [[0, 1.48, 273], [1, 1.49, 17.99], [2, 1.5, 6.67]]}, {"timestamp": 1631546264662, "ltp": 1.43, "tv": 7827.57, "trd": [[1.43, 356.39], [1.44, 189.76]], "batb": [[0, 1.42, 10.5], [1, 1.41, 10.5], [2, 1.38, 455.1]], "batl": [[0, 1.43, 280.12], [1, 1.48, 273], [2, 1.49, 17.99]]}, {"timestamp": 1631546267862, "ltp": 1.43, "tv": 7894.33, "trd": [[1.43, 423.15]], "batb": NaN, "batl": [[0, 1.43, 246.74]]}, {"timestamp": 1631546268646, "ltp": 1.43, "tv": 7894.33, "trd": NaN, "batb": [[0, 1.42, 85.32]], "batl": NaN}, {"timestamp": 1631546277763, "ltp": 1.43, "tv": 7908.13, "trd": [[1.43, 436.95]], "batb": NaN, "batl": [[0, 1.43, 232.94]]}, {"timestamp": 1631546292803, "ltp": 1.43, "tv": 7908.13, "trd": NaN, "batb": NaN, "batl": [[0, 1.48, 273], [1, 1.49, 17.99], [2, 1.5, 6.67]]}, {"timestamp": 1631546295901, "ltp": 1.41, "tv": 8292.34, "trd": [[1.41, 21], [1.42, 200.03], [1.43, 615.84]], "batb": [[0, 1.38, 455.1], [1, 1.36, 91.43], [2, 1.2, 487.76]], "batl": [[0, 1.41, 33.99], [1, 1.48, 273], [2, 1.49, 17.99]]}, {"timestamp": 1631546299008, "ltp": 1.41, "tv": 8331.54, "trd": [[1.41, 60.2]], "batb": NaN, "batl": [[0, 1.41, 14.39]]}, {"timestamp": 1631546306421, "ltp": 1.41, "tv": 8360.33, "trd": [[1.41, 88.99]], "batb": [[0, 1.41, 38.94], [1, 1.38, 455.1], [2, 1.36, 91.43]], "batl": [[0, 1.49, 17.99], [1, 1.5, 6.67], [2, 1.52, 50.01]]}, {"timestamp": 1631546310704, "ltp": 1.41, "tv": 8360.33, "trd": NaN, "batb": [[0, 1.41, 44.72]], "batl": NaN}, {"timestamp": 1631546313824, "ltp": 1.41, "tv": 8360.33, "trd": NaN, "batb": [[0, 1.41, 38.94]], "batl": [[0, 2.04, 388.69], [1, 1.5, 0], [2, 1.52, 0]]}, {"timestamp": 1631546314199, "ltp": 1.41, "tv": 8360.33, "trd": NaN, "batb": [[2, 1.37, 69.77]], "batl": [[0, 1.55, 50.3], [1, 2.04, 388.69]]}, {"timestamp": 1631546320726, "ltp": 1.41, "tv": 8360.33, "trd": NaN, "batb": NaN, "batl": [[0, 1.52, 47.51], [1, 1.55, 50.3], [2, 2.04, 388.69]]}, {"timestamp": 1631546320933, "ltp": 1.41, "tv": 8360.33, "trd": NaN, "batb": NaN, "batl": [[0, 1.55, 50.3], [1, 2.04, 388.69], [2, 2.04, 0]]}, {"timestamp": 1631546324421, "ltp": 1.41, "tv": 8360.33, "trd": NaN, "batb": NaN, "batl": [[0, 2.04, 388.69], [1, 2.04, 0]]}, {"timestamp": 1631546326715, "ltp": 1.41, "tv": 8360.33, "trd": NaN, "batb": [[0, 1.45, 62.06], [1, 1.44, 31.03], [2, 1.43, 31.03]], "batl": NaN}, {"timestamp": 1631546327816, "ltp": 1.41, "tv": 8360.33, "trd": NaN, "batb": [[0, 1.45, 89.13], [1, 1.44, 10.34], [2, 1.43, 10.34]], "batl": [[0, 1.54, 465.99], [1, 1.55, 6.45], [2, 2.04, 388.69]]}, {"timestamp": 1631546332837, "ltp": 1.41, "tv": 8360.33, "trd": NaN, "batb": NaN, "batl": [[0, 1.51, 53], [1, 1.54, 465.99], [2, 1.55, 6.45]]}, {"timestamp": 1631546334137, "ltp": 1.41, "tv": 8360.33, "trd": NaN, "batb": [[0, 1.45, 144.94], [2, 1.43, 78.77]], "batl": [[1, 1.54, 518.24]]}, {"timestamp": 1631546337448, "ltp": 1.41, "tv": 8360.33, "trd": NaN, "batb": [[0, 1.43, 68.43], [1, 1.41, 38.94], [2, 1.39, 80.61]], "batl": [[0, 1.56, 42.42], [1, 2.04, 388.69], [2, 1.55, 0]]}, {"timestamp": 1631546343756, "ltp": 1.41, "tv": 8360.33, "trd": NaN, "batb": NaN, "batl": [[0, 1.5, 21.79], [1, 1.54, 43.75], [2, 1.56, 42.42]]}, {"timestamp": 1631546344385, "ltp": 1.41, "tv": 8360.33, "trd": NaN, "batb": NaN, "batl": [[0, 1.56, 42.42], [1, 2.04, 388.69], [2, 1.56, 0]]}, {"timestamp": 1631546347662, "ltp": 1.41, "tv": 8360.33, "trd": NaN, "batb": [[0, 1.45, 57.41], [1, 1.43, 68.43], [2, 1.41, 38.94]], "batl": [[0, 1.54, 50.75], [1, 1.56, 42.42], [2, 2.04, 388.69]]}, {"timestamp": 1631546347981, "ltp": 1.41, "tv": 8360.33, "trd": NaN, "batb": [[0, 1.43, 68.43], [1, 1.41, 38.94], [2, 1.39, 80.61]], "batl": [[0, 1.56, 42.42], [1, 2.04, 388.69], [2, 2.04, 0]]}, {"timestamp": 1631546354760, "ltp": 1.41, "tv": 8360.33, "trd": NaN, "batb": [[0, 1.45, 57.81], [1, 1.43, 68.43], [2, 1.41, 38.94]], "batl": [[0, 1.54, 48.25], [1, 1.56, 42.42], [2, 2.04, 388.69]]}, {"timestamp": 1631546355074, "ltp": 1.41, "tv": 8360.33, "trd": NaN, "batb": [[0, 1.43, 68.43], [1, 1.41, 38.94], [2, 1.39, 80.61]], "batl": [[0, 1.56, 42.42], [1, 2.04, 388.69], [2, 2.04, 0]]}, {"timestamp": 1631546361770, "ltp": 1.41, "tv": 8360.33, "trd": NaN, "batb": [[0, 1.45, 58.81], [1, 1.43, 68.43], [2, 1.41, 38.94]], "batl": [[0, 1.54, 46.75], [1, 1.56, 42.42], [2, 2.04, 388.69]]}, {"timestamp": 1631546362185, "ltp": 1.41, "tv": 8360.33, "trd": NaN, "batb": [[0, 1.43, 68.43], [1, 1.41, 38.94], [2, 1.39, 80.61]], "batl": [[0, 1.56, 42.42], [1, 2.04, 388.69], [2, 2.04, 0]]}, {"timestamp": 1631546368875, "ltp": 1.41, "tv": 8360.33, "trd": NaN, "batb": [[0, 1.45, 51.21], [1, 1.43, 68.43], [2, 1.41, 38.94]], "batl": [[0, 1.54, 49.75]]}, {"timestamp": 1631546369705, "ltp": 1.41, "tv": 8360.33, "trd": NaN, "batb": [[0, 1.43, 68.43], [1, 1.41, 38.94], [2, 1.39, 80.61]], "batl": NaN}, {"timestamp": 1631546370695, "ltp": 1.43, "tv": 8364.03, "trd": [[1.43, 619.54]], "batb": [[0, 1.43, 64.73], [1, 1.41, 685.11], [2, 1.4, 13.74]], "batl": [[0, 1.45, 62.06], [1, 1.46, 31.03], [2, 1.47, 85.53]]}, {"timestamp": 1631546371688, "ltp": 1.43, "tv": 8364.03, "trd": NaN, "batb": NaN, "batl": [[0, 1.45, 20.68], [1, 1.46, 10.34], [2, 1.47, 64.84]]}, {"timestamp": 1631546376704, "ltp": 1.43, "tv": 8364.03, "trd": NaN, "batb": [[1, 1.41, 646.17]], "batl": NaN}, {"timestamp": 1631546380685, "ltp": 1.43, "tv": 8364.03, "trd": NaN, "batb": [[2, 1.39, 80.61]], "batl": [[0, 1.45, 189.68]]}, {"timestamp": 1631546383877, "ltp": 1.45, "tv": 8428.03, "trd": [[1.45, 1117.63]], "batb": NaN, "batl": [[0, 1.46, 10.34], [1, 1.47, 64.84], [2, 1.49, 57.21]]}, {"timestamp": 1631546387890, "ltp": 1.45, "tv": 8428.03, "trd": NaN, "batb": [[0, 1.33, 102.08], [1, 1.31, 484.59], [2, 1.2, 487.76]], "batl": [[0, 1.44, 383], [1, 1.49, 50.5], [2, 1.51, 56.5]]}, {"timestamp": 1631546388768, "ltp": 1.45, "tv": 8428.03, "trd": NaN, "batb": NaN, "batl": [[0, 1.49, 50.5], [1, 1.51, 56.5], [2, 1.89, 441.74]]}, {"timestamp": 1631546388979, "ltp": 1.45, "tv": 8428.03, "trd": NaN, "batb": NaN, "batl": [[0, 1.51, 56.5], [1, 1.89, 441.74], [2, 1.89, 0]]}, {"timestamp": 1631546390493, "ltp": 1.45, "tv": 8428.03, "trd": NaN, "batb": [[0, 1.33, 176.61]], "batl": NaN}, {"timestamp": 1631546393722, "ltp": 1.45, "tv": 8428.03, "trd": NaN, "batb": [[0, 1.36, 80.68], [1, 1.33, 176.61], [2, 1.31, 484.59]], "batl": NaN}, {"timestamp": 1631546395696, "ltp": 1.45, "tv": 8428.03, "trd": NaN, "batb": [[0, 1.33, 176.61], [1, 1.31, 484.59], [2, 1.2, 487.76]], "batl": [[0, 1.49, 54.5], [1, 1.51, 56.5], [2, 1.89, 441.74]]}, {"timestamp": 1631546396009, "ltp": 1.45, "tv": 8428.03, "trd": NaN, "batb": NaN, "batl": [[0, 1.51, 56.5], [1, 1.89, 441.74], [2, 1.89, 0]]}, {"timestamp": 1631546397719, "ltp": 1.45, "tv": 8428.03, "trd": NaN, "batb": [[0, 1.44, 7.47], [1, 1.33, 176.61], [2, 1.31, 484.59]], "batl": NaN}, {"timestamp": 1631546398802, "ltp": 1.45, "tv": 8428.03, "trd": NaN, "batb": [[2, 1.2, 487.76]], "batl": [[1, 1.89, 0]]}, {"timestamp": 1631546399790, "ltp": 1.44, "tv": 8442.97, "trd": [[1.44, 204.7]], "batb": [[0, 1.34, 741.81], [2, 1.2, 100]], "batl": [[0, 1.38, 152.17], [1, 1.39, 100.12], [2, 1.4, 309.58]]}, {"timestamp": 1631546400729, "ltp": 1.44, "tv": 8442.97, "trd": NaN, "batb": [[2, 1.26, 133.87]], "batl": [[0, 1.38, 108.69], [1, 1.39, 78.38], [2, 1.4, 287.84]]}, {"timestamp": 1631546404826, "ltp": 1.44, "tv": 8442.97, "trd": NaN, "batb": NaN, "batl": [[0, 1.37, 111], [1, 1.38, 108.69], [2, 1.39, 78.38]]}, {"timestamp": 1631546406397, "ltp": 1.44, "tv": 8442.97, "trd": NaN, "batb": [[2, 1.28, 87.91]], "batl": NaN}, {"timestamp": 1631546408128, "ltp": 1.44, "tv": 8442.97, "trd": NaN, "batb": [[2, 1.3, 83.68]], "batl": NaN}, {"timestamp": 1631546412935, "ltp": 1.44, "tv": 8442.97, "trd": NaN, "batb": NaN, "batl": [[0, 1.38, 108.69], [1, 1.39, 78.38], [2, 1.4, 287.84]]}, {"timestamp": 1631546416024, "ltp": 1.44, "tv": 8442.97, "trd": NaN, "batb": NaN, "batl": [[0, 1.36, 291], [1, 1.38, 108.69], [2, 1.39, 78.38]]}, {"timestamp": 1631546421856, "ltp": 1.44, "tv": 8442.97, "trd": NaN, "batb": [[0, 1.26, 133.87], [1, 1.25, 607.24], [2, 1.2, 100]], "batl": [[0, 1.44, 59.58], [1, 1.46, 56.25], [2, 1.47, 55.5]]}, {"timestamp": 1631546422169, "ltp": 1.44, "tv": 8442.97, "trd": NaN, "batb": NaN, "batl": [[0, 1.47, 55.5], [1, 1.77, 508.04], [2, 44, 7.22]]}, {"timestamp": 1631546424845, "ltp": 1.44, "tv": 8442.97, "trd": NaN, "batb": [[0, 1.28, 85.16], [1, 1.26, 133.87], [2, 1.25, 607.24]], "batl": NaN}, {"timestamp": 1631546425632, "ltp": 1.44, "tv": 8442.97, "trd": NaN, "batb": [[0, 1.26, 133.87], [1, 1.25, 607.24], [2, 1.2, 100]], "batl": NaN}, {"timestamp": 1631546428828, "ltp": 1.44, "tv": 8442.97, "trd": NaN, "batb": NaN, "batl": [[0, 1.44, 62.33], [1, 1.47, 55.5], [2, 1.77, 508.04]]}, {"timestamp": 1631546429351, "ltp": 1.44, "tv": 8442.97, "trd": NaN, "batb": NaN, "batl": [[0, 1.77, 508.04], [1, 44, 7.22], [2, 1.77, 0]]}, {"timestamp": 1631546430458, "ltp": 1.44, "tv": 8442.97, "trd": NaN, "batb": [[1, 1.25, 94.65]], "batl": NaN}, {"timestamp": 1631546431879, "ltp": 1.44, "tv": 8442.97, "trd": NaN, "batb": [[0, 1.28, 100.91], [1, 1.26, 133.87], [2, 1.25, 94.65]], "batl": NaN}, {"timestamp": 1631546432457, "ltp": 1.44, "tv": 8442.97, "trd": NaN, "batb": [[0, 1.28, 19.21]], "batl": [[0, 1.3, 23.08], [1, 1.31, 11.54], [2, 1.32, 81.9]]}, {"timestamp": 1631546433668, "ltp": 1.44, "tv": 8442.97, "trd": NaN, "batb": [[1, 1.26, 157.67], [2, 1.25, 106.55]], "batl": NaN}, {"timestamp": 1631546440764, "ltp": 1.44, "tv": 8442.97, "trd": NaN, "batb": NaN, "batl": [[0, 1.3, 440.08]]}, {"timestamp": 1631546448482, "ltp": 1.3, "tv": 8443.09, "trd": [[1.3, 0.12]], "batb": NaN, "batl": [[0, 1.3, 440.02]]}, {"timestamp": 1631546449784, "ltp": 1.3, "tv": 8445.23, "trd": [[1.3, 2.26]], "batb": [[0, 1.22, 638.1], [1, 1.2, 275.9], [2, 1.19, 103]], "batl": [[0, 1.36, 69.57], [1, 1.39, 66.5], [2, 1.77, 508.04]]}, {"timestamp": 1631546449986, "ltp": 1.3, "tv": 8445.23, "trd": NaN, "batb": NaN, "batl": [[0, 1.39, 66.5], [1, 1.77, 508.04], [2, 44, 7.22]]}, {"timestamp": 1631546451875, "ltp": 1.3, "tv": 8445.23, "trd": NaN, "batb": NaN, "batl": [[2, 8.8, 7.22]]}, {"timestamp": 1631546456698, "ltp": 1.3, "tv": 8445.23, "trd": NaN, "batb": NaN, "batl": [[0, 1.36, 72.32], [1, 1.39, 66.5], [2, 1.77, 508.04]]}, {"timestamp": 1631546457530, "ltp": 1.3, "tv": 8445.23, "trd": NaN, "batb": NaN, "batl": [[0, 1.34, 13.29], [1, 1.37, 717.41], [2, 1.39, 66.5]]}, {"timestamp": 1631546458628, "ltp": 1.3, "tv": 8445.23, "trd": NaN, "batb": [[0, 1.3, 112.15], [1, 1.22, 638.1], [2, 1.21, 165.75]], "batl": NaN}, {"timestamp": 1631546459314, "ltp": 1.3, "tv": 8445.23, "trd": NaN, "batb": NaN, "batl": [[2, 1.39, 73.69]]}, {"timestamp": 1631546462423, "ltp": 1.34, "tv": 8458.52, "trd": [[1.34, 13.29]], "batb": NaN, "batl": [[0, 1.37, 717.41], [1, 1.39, 73.69], [2, 1.77, 508.04]]}, {"timestamp": 1631546463787, "ltp": 1.34, "tv": 8458.52, "trd": NaN, "batb": NaN, "batl": [[0, 1.34, 131], [1, 1.37, 717.41], [2, 1.39, 73.69]]}, {"timestamp": 1631546468800, "ltp": 1.34, "tv": 8458.52, "trd": NaN, "batb": [[0, 1.22, 530.76], [1, 1.21, 165.75], [2, 1.2, 100]], "batl": [[0, 1.41, 51.5], [1, 1.42, 64.25], [2, 1.44, 52.83]]}, {"timestamp": 1631546469326, "ltp": 1.34, "tv": 8458.52, "trd": NaN, "batb": NaN, "batl": [[0, 1.44, 52.83], [1, 1.77, 508.04], [2, 8.8, 7.22]]}, {"timestamp": 1631546475694, "ltp": 1.34, "tv": 8458.52, "trd": NaN, "batb": NaN, "batl": [[0, 1.41, 55.5], [1, 1.44, 52.83], [2, 1.77, 508.04]]}, {"timestamp": 1631546476018, "ltp": 1.34, "tv": 8458.52, "trd": NaN, "batb": NaN, "batl": [[0, 1.44, 52.83], [1, 1.77, 508.04], [2, 8.8, 7.22]]}, {"timestamp": 1631546479819, "ltp": 1.34, "tv": 8458.52, "trd": NaN, "batb": NaN, "batl": [[0, 1.35, 439.39], [1, 1.44, 52.83], [2, 1.77, 508.04]]}, {"timestamp": 1631546480339, "ltp": 1.34, "tv": 8458.52, "trd": NaN, "batb": NaN, "batl": [[0, 1.44, 52.83], [1, 1.77, 508.04], [2, 8.8, 7.22]]}, {"timestamp": 1631546489909, "ltp": 1.34, "tv": 8458.52, "trd": NaN, "batb": [[0, 1.34, 45], [1, 1.22, 530.76], [2, 1.21, 165.75]], "batl": NaN}, {"timestamp": 1631546496662, "ltp": 1.34, "tv": 8458.52, "trd": NaN, "batb": NaN, "batl": [[0, 1.41, 66.5], [1, 1.44, 52.83], [2, 1.77, 508.04]]}, {"timestamp": 1631546496923, "ltp": 1.34, "tv": 8458.52, "trd": NaN, "batb": NaN, "batl": [[0, 1.44, 52.83], [1, 1.77, 508.04], [2, 8.8, 7.22]]}, {"timestamp": 1631546500643, "ltp": 1.34, "tv": 8458.52, "trd": NaN, "batb": NaN, "batl": [[0, 1.77, 508.04], [1, 8.8, 7.22], [2, 44, 7.22]]}, {"timestamp": 1631546502740, "ltp": 1.34, "tv": 8458.52, "trd": NaN, "batb": [[1, 1.21, 165.75], [2, 1.2, 100]], "batl": [[0, 8.8, 7.22], [1, 44, 7.22], [2, 50, 7.22]]}, {"timestamp": 1631546503740, "ltp": 1.34, "tv": 8548.52, "trd": [[1.34, 103.29]], "batb": [[0, 1.21, 1339.22], [1, 1.2, 100], [2, 1.19, 103]], "batl": [[0, 1.26, 82.75], [1, 1.28, 7.81], [2, 1.34, 2]]}, {"timestamp": 1631546504739, "ltp": 1.34, "tv": 8548.52, "trd": NaN, "batb": [[0, 1.22, 8.2], [1, 1.21, 1339.22], [2, 1.2, 100]], "batl": NaN}, {"timestamp": 1631546507057, "ltp": 1.25, "tv": 8550.52, "trd": [[1.25, 2]], "batb": NaN, "batl": NaN}, {"timestamp": 1631546510254, "ltp": 1.25, "tv": 8550.52, "trd": NaN, "batb": [[0, 1.22, 116.54], [1, 1.21, 1455.91]], "batl": [[2, 1.3, 87.45]]}, {"timestamp": 1631546515390, "ltp": 1.23, "tv": 8559.11, "trd": [[1.23, 8.59]], "batb": NaN, "batl": NaN}, {"timestamp": 1631546517165, "ltp": 1.23, "tv": 8559.11, "trd": NaN, "batb": NaN, "batl": [[0, 1.25, 300], [1, 1.26, 82.75], [2, 1.28, 7.81]]}, {"timestamp": 1631546522363, "ltp": 1.23, "tv": 8559.11, "trd": NaN, "batb": [[2, 1.2, 229.67]], "batl": NaN}, {"timestamp": 1631546523193, "ltp": 1.23, "tv": 8559.11, "trd": NaN, "batb": NaN, "batl": [[0, 1.25, 312.93]]}, {"timestamp": 1631546525766, "ltp": 1.23, "tv": 8559.11, "trd": NaN, "batb": [[0, 1.24, 3.04], [1, 1.22, 116.54], [2, 1.21, 1455.91]], "batl": [[0, 1.25, 300]]}, {"timestamp": 1631546528492, "ltp": 1.23, "tv": 8559.11, "trd": NaN, "batb": NaN, "batl": [[0, 1.25, 312.93]]}, {"timestamp": 1631546530416, "ltp": 1.25, "tv": 8566.33, "trd": [[1.25, 9.22]], "batb": NaN, "batl": [[0, 1.25, 309.32]]}, {"timestamp": 1631546539685, "ltp": 1.25, "tv": 8566.33, "trd": NaN, "batb": [[1, 1.21, 116.69], [2, 1.2, 100]], "batl": [[0, 1.25, 296.39], [1, 1.3, 87.45], [2, 1.32, 73.86]]}, {"timestamp": 1631546540801, "ltp": 1.25, "tv": 8566.33, "trd": NaN, "batb": NaN, "batl": [[0, 1.3, 87.45], [1, 1.32, 73.86], [2, 1.34, 2]]}, {"timestamp": 1631546541112, "ltp": 1.25, "tv": 8566.33, "trd": NaN, "batb": NaN, "batl": [[0, 1.32, 73.86], [1, 1.34, 2], [2, 1.62, 623.52]]}, {"timestamp": 1631546542726, "ltp": 1.25, "tv": 8566.33, "trd": NaN, "batb": [[1, 1.22, 110.34], [2, 1.21, 116.69]], "batl": NaN}, {"timestamp": 1631546542996, "ltp": 1.25, "tv": 8566.33, "trd": NaN, "batb": [[1, 1.21, 116.69], [2, 1.2, 100]], "batl": NaN}, {"timestamp": 1631546545800, "ltp": 1.25, "tv": 8566.33, "trd": NaN, "batb": NaN, "batl": [[0, 1.26, 40.25], [1, 1.32, 73.86], [2, 1.34, 2]]}, {"timestamp": 1631546546211, "ltp": 1.25, "tv": 8566.33, "trd": NaN, "batb": [[1, 1.22, 131.84], [2, 1.21, 116.69]], "batl": [[0, 1.32, 73.86], [1, 1.34, 2], [2, 1.62, 623.52]]}, {"timestamp": 1631546554823, "ltp": 1.25, "tv": 8566.33, "trd": NaN, "batb": NaN, "batl": [[0, 1.3, 83.65], [1, 1.32, 73.86], [2, 1.34, 2]]}, {"timestamp": 1631546555711, "ltp": 1.25, "tv": 8566.33, "trd": NaN, "batb": NaN, "batl": [[0, 1.32, 73.86], [1, 1.34, 2], [2, 1.62, 623.52]]}, {"timestamp": 1631546556704, "ltp": 1.25, "tv": 8566.33, "trd": NaN, "batb": [[0, 1.22, 131.84], [1, 1.21, 116.69], [2, 1.2, 100]], "batl": NaN}, {"timestamp": 1631546557121, "ltp": 1.25, "tv": 8566.33, "trd": NaN, "batb": [[0, 1.21, 116.69], [1, 1.2, 100], [2, 1.19, 290.14]], "batl": NaN}, {"timestamp": 1631546559734, "ltp": 1.25, "tv": 8566.33, "trd": NaN, "batb": [[1, 1.2, 483]], "batl": [[0, 1.23, 36.05], [1, 1.24, 161.3], [2, 1.25, 68.22]]}, {"timestamp": 1631546560727, "ltp": 1.25, "tv": 8566.33, "trd": NaN, "batb": [[1, 1.2, 491.33]], "batl": NaN}, {"timestamp": 1631546566725, "ltp": 1.25, "tv": 8566.33, "trd": NaN, "batb": [[1, 1.2, 624.1], [2, 1.19, 415.85]], "batl": NaN}, {"timestamp": 1631546567660, "ltp": 1.21, "tv": 8568.95, "trd": [[1.21, 2.62]], "batb": [[0, 1.21, 115.38]], "batl": [[0, 1.23, 110.05]]}, {"timestamp": 1631546571837, "ltp": 1.21, "tv": 8568.95, "trd": NaN, "batb": [[0, 1.22, 21.66], [1, 1.21, 115.38], [2, 1.2, 232.77]], "batl": [[0, 1.23, 74], [1, 1.25, 68.22], [2, 1.26, 88.75]]}, {"timestamp": 1631546572831, "ltp": 1.21, "tv": 8568.95, "trd": NaN, "batb": [[1, 1.2, 100], [2, 1.19, 228.71]], "batl": [[0, 1.28, 88.59], [1, 1.32, 73.86], [2, 1.34, 2]]}, {"timestamp": 1631546578777, "ltp": 1.21, "tv": 8568.95, "trd": NaN, "batb": [[0, 1.2, 235.62], [1, 1.19, 228.71], [2, 1.18, 663.88]], "batl": [[0, 1.26, 82.75], [1, 1.28, 88.59], [2, 1.32, 73.86]]}, {"timestamp": 1631546578978, "ltp": 1.21, "tv": 8568.95, "trd": NaN, "batb": [[0, 1.2, 100]], "batl": [[0, 1.28, 88.59], [1, 1.32, 73.86], [2, 1.34, 2]]}, {"timestamp": 1631546582751, "ltp": 1.21, "tv": 8568.95, "trd": NaN, "batb": NaN, "batl": [[1, 1.34, 2], [2, 1.62, 623.52]]}, {"timestamp": 1631546583100, "ltp": 1.21, "tv": 8568.95, "trd": NaN, "batb": [[2, 1.18, 106]], "batl": [[2, 8.8, 7.22]]}, {"timestamp": 1631546585593, "ltp": 1.21, "tv": 8568.95, "trd": NaN, "batb": NaN, "batl": [[0, 1.21, 30.01], [1, 1.22, 973.34], [2, 1.23, 68.5]]}, {"timestamp": 1631546586766, "ltp": 1.21, "tv": 8568.95, "trd": NaN, "batb": [[2, 1.18, 114.47]], "batl": NaN}, {"timestamp": 1631546590508, "ltp": 1.21, "tv": 8598.96, "trd": [[1.21, 32.63]], "batb": NaN, "batl": [[0, 1.22, 973.34], [1, 1.23, 68.5], [2, 1.24, 8.06]]}, {"timestamp": 1631546591878, "ltp": 1.21, "tv": 8598.96, "trd": NaN, "batb": [[2, 1.18, 236.83]], "batl": [[2, 1.24, 110.54]]}, {"timestamp": 1631546592304, "ltp": 1.2, "tv": 8643.68, "trd": [[1.2, 44.72]], "batb": [[0, 1.2, 77.64]], "batl": NaN}, {"timestamp": 1631546593580, "ltp": 1.2, "tv": 8643.68, "trd": NaN, "batb": NaN, "batl": [[0, 1.21, 260], [1, 1.22, 973.34], [2, 1.23, 68.5]]}, {"timestamp": 1631546594103, "ltp": 1.2, "tv": 8643.68, "trd": NaN, "batb": [[0, 1.2, 191.26]], "batl": NaN}, {"timestamp": 1631546602901, "ltp": 1.2, "tv": 8643.68, "trd": NaN, "batb": [[0, 1.2, 77.64], [1, 1.19, 103], [2, 1.18, 228.36]], "batl": [[0, 1.24, 102.48], [1, 1.28, 88.59], [2, 1.34, 2]]}, {"timestamp": 1631546603584, "ltp": 1.2, "tv": 8643.68, "trd": NaN, "batb": NaN, "batl": [[1, 1.34, 2], [2, 1.53, 724.69]]}, {"timestamp": 1631546605785, "ltp": 1.2, "tv": 8643.68, "trd": NaN, "batb": NaN, "batl": [[0, 1.23, 120.5], [1, 1.24, 102.48], [2, 1.34, 2]]}, {"timestamp": 1631546606200, "ltp": 1.2, "tv": 8643.68, "trd": NaN, "batb": NaN, "batl": [[0, 1.24, 102.48], [1, 1.34, 2], [2, 1.53, 724.69]]}, {"timestamp": 1631546609702, "ltp": 1.2, "tv": 8643.68, "trd": NaN, "batb": NaN, "batl": [[0, 1.22, 131], [1, 1.23, 120.5], [2, 1.24, 102.48]]}, {"timestamp": 1631546611812, "ltp": 1.2, "tv": 8643.68, "trd": NaN, "batb": NaN, "batl": [[0, 1.23, 120.5], [1, 1.24, 102.48], [2, 1.34, 2]]}, {"timestamp": 1631546612125, "ltp": 1.2, "tv": 8643.68, "trd": NaN, "batb": NaN, "batl": [[0, 1.24, 102.48], [1, 1.34, 2], [2, 1.53, 724.69]]}, {"timestamp": 1631546616996, "ltp": 1.2, "tv": 8643.68, "trd": NaN, "batb": NaN, "batl": [[0, 1.34, 2], [1, 1.53, 724.69], [2, 8.8, 7.22]]}, {"timestamp": 1631546618725, "ltp": 1.2, "tv": 8643.68, "trd": NaN, "batb": [[0, 1.19, 103], [1, 1.18, 228.36], [2, 1.17, 109]], "batl": NaN}, {"timestamp": 1631546619827, "ltp": 1.2, "tv": 8643.68, "trd": NaN, "batb": NaN, "batl": [[0, 1.21, 3475.93], [1, 1.22, 1854.28], [2, 1.23, 8.13]]}, {"timestamp": 1631546620723, "ltp": 1.2, "tv": 8643.68, "trd": NaN, "batb": [[2, 1.17, 117.55]], "batl": [[0, 1.21, 115.45]]}, {"timestamp": 1631546626837, "ltp": 1.2, "tv": 8643.68, "trd": NaN, "batb": [[0, 1.19, 226.71]], "batl": [[1, 1.22, 1967.53]]}, {"timestamp": 1631546627939, "ltp": 1.2, "tv": 8643.68, "trd": NaN, "batb": NaN, "batl": [[0, 1.21, 213.45]]}, {"timestamp": 1631546631827, "ltp": 1.2, "tv": 8643.68, "trd": NaN, "batb": [[0, 1.19, 103], [2, 1.17, 109]], "batl": [[0, 1.22, 113.25], [1, 1.34, 2], [2, 1.53, 724.69]]}, {"timestamp": 1631546634818, "ltp": 1.19, "tv": 8753.68, "trd": [[1.19, 110]], "batb": [[0, 1.19, 48]], "batl": NaN}, {"timestamp": 1631546635834, "ltp": 1.19, "tv": 8753.68, "trd": NaN, "batb": [[0, 1.21, 2.13], [1, 1.19, 48], [2, 1.18, 228.36]], "batl": NaN}, {"timestamp": 1631546636625, "ltp": 1.19, "tv": 8853.93, "trd": [[1.19, 206], [1.21, 36.89]], "batb": [[0, 1.18, 228.36], [1, 1.17, 109], [2, 1.16, 113]], "batl": [[0, 1.19, 671.84]]}, {"timestamp": 1631546637825, "ltp": 1.19, "tv": 8853.93, "trd": NaN, "batb": [[0, 1.18, 122.36]], "batl": NaN}, {"timestamp": 1631546638852, "ltp": 1.19, "tv": 9113.35, "trd": [[1.19, 465.42]], "batb": NaN, "batl": [[0, 1.19, 542.13], [1, 1.2, 19.73], [2, 1.21, 3677.54]]}, {"timestamp": 1631546639858, "ltp": 1.19, "tv": 9113.35, "trd": NaN, "batb": [[2, 1.16, 121.62]], "batl": [[1, 1.2, 92.56], [2, 1.21, 215.67]]}, {"timestamp": 1631546640644, "ltp": 1.19, "tv": 9319.36, "trd": [[1.19, 671.42]], "batb": NaN, "batl": [[0, 1.19, 439.13], [2, 1.21, 217.67]]}, {"timestamp": 1631546642353, "ltp": 1.19, "tv": 9362.67, "trd": [[1.19, 714.74]], "batb": NaN, "batl": [[0, 1.19, 417.47]]}, {"timestamp": 1631546645865, "ltp": 1.19, "tv": 9362.67, "trd": NaN, "batb": NaN, "batl": [[0, 1.19, 579.47]]}, {"timestamp": 1631546648071, "ltp": 1.19, "tv": 9362.67, "trd": NaN, "batb": NaN, "batl": [[0, 1.19, 162]]}, {"timestamp": 1631546651166, "ltp": 1.18, "tv": 9623.67, "trd": [[1.18, 260.99]], "batb": [[0, 1.17, 109], [1, 1.16, 121.62], [2, 1.15, 359.5]], "batl": [[0, 1.18, 278.84], [1, 1.19, 162], [2, 1.2, 92.56]]}, {"timestamp": 1631546652571, "ltp": 1.18, "tv": 9623.67, "trd": NaN, "batb": NaN, "batl": [[0, 1.18, 278.92]]}, {"timestamp": 1631546660795, "ltp": 1.18, "tv": 9623.67, "trd": NaN, "batb": NaN, "batl": [[0, 1.19, 162.08], [1, 1.2, 92.56], [2, 1.21, 217.67]]}, {"timestamp": 1631546663887, "ltp": 1.17, "tv": 9878.64, "trd": [[1.17, 254.98]], "batb": [[0, 1.16, 121.62], [1, 1.15, 359.5], [2, 1.14, 121]], "batl": [[0, 1.17, 132.86], [1, 1.19, 162.08], [2, 1.2, 92.56]]}, {"timestamp": 1631546664780, "ltp": 1.17, "tv": 9878.64, "trd": NaN, "batb": NaN, "batl": [[1, 1.19, 162]]}, {"timestamp": 1631546667869, "ltp": 1.17, "tv": 9878.64, "trd": NaN, "batb": NaN, "batl": [[0, 1.17, 132.94]]}, {"timestamp": 1631546675624, "ltp": 1.17, "tv": 9878.64, "trd": NaN, "batb": NaN, "batl": [[0, 1.19, 162.08], [1, 1.2, 92.56], [2, 1.21, 217.67]]}, {"timestamp": 1631546678697, "ltp": 1.16, "tv": 10133.13, "trd": [[1.16, 254.48]], "batb": [[0, 1.15, 359.5], [1, 1.14, 121], [2, 1.13, 399.78]], "batl": NaN}, {"timestamp": 1631546681994, "ltp": 1.17, "tv": 10133.29, "trd": [[1.17, 255.13]], "batb": [[0, 1.17, 108.92], [1, 1.16, 113], [2, 1.15, 359.5]], "batl": [[0, 1.19, 162]]}, {"timestamp": 1631546698411, "ltp": 1.17, "tv": 10133.29, "trd": NaN, "batb": [[0, 1.16, 113], [1, 1.15, 359.5], [2, 1.14, 121]], "batl": NaN}, {"timestamp": 1631546729351, "ltp": 1.17, "tv": 10133.29, "trd": NaN, "batb": [[0, 1.17, 154.97], [1, 1.16, 291.28], [2, 1.15, 359.5]], "batl": NaN}, {"timestamp": 1631546733593, "ltp": 1.17, "tv": 10133.29, "trd": NaN, "batb": NaN, "batl": [[2, 1.21, 215.67]]}, {"timestamp": 1631546736571, "ltp": 1.17, "tv": 10133.29, "trd": NaN, "batb": NaN, "batl": [[1, 1.2, 303.56]]}, {"timestamp": 1631546739692, "ltp": 1.17, "tv": 10133.29, "trd": NaN, "batb": [[0, 1.16, 113], [1, 1.15, 117], [2, 1.14, 121]], "batl": [[1, 1.2, 211], [2, 1.21, 116.5]]}, {"timestamp": 1631546740892, "ltp": 1.17, "tv": 10133.29, "trd": NaN, "batb": [[0, 1.14, 121], [1, 1.13, 399.78], [2, 1.12, 133]], "batl": [[0, 1.21, 116.5], [1, 1.22, 169.75], [2, 1.34, 2]]}, {"timestamp": 1631546741203, "ltp": 1.17, "tv": 10133.29, "trd": NaN, "batb": NaN, "batl": [[0, 1.22, 169.75], [1, 1.34, 2], [2, 1.39, 17.9]]}, {"timestamp": 1631546742815, "ltp": 1.17, "tv": 10133.29, "trd": NaN, "batb": [[0, 1.17, 145.97], [1, 1.16, 153.53], [2, 1.14, 121]], "batl": NaN}, {"timestamp": 1631546742981, "ltp": 1.17, "tv": 10133.29, "trd": NaN, "batb": [[0, 1.16, 153.53], [1, 1.14, 121], [2, 1.13, 399.78]], "batl": NaN}, {"timestamp": 1631546747882, "ltp": 1.17, "tv": 10133.29, "trd": NaN, "batb": NaN, "batl": [[0, 1.21, 169.5], [1, 1.22, 169.75], [2, 1.34, 2]]}, {"timestamp": 1631546748198, "ltp": 1.17, "tv": 10133.29, "trd": NaN, "batb": NaN, "batl": [[0, 1.22, 169.75], [1, 1.34, 2], [2, 1.39, 17.9]]}, {"timestamp": 1631546751882, "ltp": 1.17, "tv": 10133.29, "trd": NaN, "batb": NaN, "batl": [[0, 1.34, 2], [1, 1.39, 17.9], [2, 1.53, 724.69]]}, {"timestamp": 1631546753384, "ltp": 1.17, "tv": 10133.29, "trd": NaN, "batb": [[0, 1.18, 950.72], [1, 1.17, 72.11], [2, 1.16, 217.09]], "batl": [[0, 1.21, 751.25], [1, 1.34, 2], [2, 1.39, 17.9]]}, {"timestamp": 1631546754900, "ltp": 1.17, "tv": 10133.29, "trd": NaN, "batb": [[0, 1.18, 955.02], [1, 1.17, 130.27], [2, 1.16, 502.71]], "batl": [[0, 1.21, 960.25], [1, 1.23, 8.13], [2, 1.34, 2]]}, {"timestamp": 1631546761614, "ltp": 1.17, "tv": 10133.29, "trd": NaN, "batb": [[0, 1.19, 129.71], [1, 1.18, 1099.38], [2, 1.17, 130.27]], "batl": [[0, 1.21, 1311.75], [1, 1.22, 168.25], [2, 1.23, 198.63]]}, {"timestamp": 1631546768907, "ltp": 1.17, "tv": 10133.29, "trd": NaN, "batb": [[0, 1.17, 109], [1, 1.16, 266.53], [2, 1.15, 117]], "batl": [[0, 1.21, 192.5], [2, 1.23, 190.5]]}, {"timestamp": 1631546769127, "ltp": 1.17, "tv": 10133.29, "trd": NaN, "batb": NaN, "batl": [[0, 1.22, 168.25], [1, 1.34, 2], [2, 1.39, 17.9]]}, {"timestamp": 1631546771520, "ltp": 1.17, "tv": 10133.29, "trd": NaN, "batb": [[0, 1.19, 113.71], [1, 1.18, 128.36], [2, 1.17, 109]], "batl": NaN}, {"timestamp": 1631546772705, "ltp": 1.17, "tv": 10133.29, "trd": NaN, "batb": [[0, 1.18, 128.36], [1, 1.17, 109], [2, 1.16, 266.53]], "batl": NaN}, {"timestamp": 1631546776817, "ltp": 1.17, "tv": 10133.29, "trd": NaN, "batb": NaN, "batl": [[0, 1.21, 101], [1, 1.22, 168.25], [2, 1.34, 2]]}, {"timestamp": 1631546777228, "ltp": 1.17, "tv": 10133.29, "trd": NaN, "batb": [[0, 1.18, 234.36]], "batl": NaN}, {"timestamp": 1631546781342, "ltp": 1.17, "tv": 10133.29, "trd": NaN, "batb": NaN, "batl": [[0, 1.22, 168.25], [1, 1.34, 2], [2, 1.39, 17.9]]}, {"timestamp": 1631546791654, "ltp": 1.17, "tv": 10133.29, "trd": NaN, "batb": [[0, 1.19, 117.71], [1, 1.18, 234.36], [2, 1.17, 109]], "batl": [[0, 1.21, 207.5], [1, 1.22, 168.25], [2, 1.34, 2]]}, {"timestamp": 1631546791963, "ltp": 1.17, "tv": 10133.29, "trd": NaN, "batb": [[0, 1.18, 234.36], [1, 1.17, 109], [2, 1.16, 266.53]], "batl": [[0, 1.22, 168.25], [1, 1.34, 2], [2, 1.39, 17.9]]}, {"timestamp": 1631546795457, "ltp": 1.19, "tv": 10176.03, "trd": [[1.19, 757.48]], "batb": [[0, 1.18, 253.08]], "batl": [[0, 1.2, 204.43], [1, 1.21, 181.5], [2, 1.22, 8.2]]}, {"timestamp": 1631546796656, "ltp": 1.19, "tv": 10176.03, "trd": NaN, "batb": [[2, 1.16, 275.15]], "batl": NaN}, {"timestamp": 1631546797584, "ltp": 1.18, "tv": 10182.03, "trd": [[1.18, 266.99]], "batb": [[0, 1.18, 250.08], [2, 1.16, 121.62]], "batl": [[0, 1.2, 415.43]]}, {"timestamp": 1631546800886, "ltp": 1.18, "tv": 10182.03, "trd": NaN, "batb": NaN, "batl": [[0, 1.19, 272], [1, 1.2, 415.43], [2, 1.21, 181.5]]}, {"timestamp": 1631546805276, "ltp": 1.18, "tv": 10182.03, "trd": NaN, "batb": [[0, 1.18, 231.36]], "batl": NaN}, {"timestamp": 1631546808304, "ltp": 1.18, "tv": 10182.03, "trd": NaN, "batb": NaN, "batl": [[1, 1.2, 433.56]]}, {"timestamp": 1631546812806, "ltp": 1.18, "tv": 10182.03, "trd": NaN, "batb": [[2, 1.16, 113]], "batl": [[1, 1.2, 415.43]]}, {"timestamp": 1631546813909, "ltp": 1.18, "tv": 10182.03, "trd": NaN, "batb": [[0, 1.17, 109], [1, 1.16, 113], [2, 1.15, 117]], "batl": [[0, 1.21, 181.5], [1, 1.34, 2], [2, 1.39, 17.9]]}, {"timestamp": 1631546820818, "ltp": 1.18, "tv": 10182.03, "trd": NaN, "batb": [[0, 1.19, 25.2], [1, 1.18, 12.6], [2, 1.17, 130.15]], "batl": [[0, 1.21, 1180.74]]}, {"timestamp": 1631546821822, "ltp": 1.18, "tv": 10182.03, "trd": NaN, "batb": NaN, "batl": [[1, 1.23, 8.13], [2, 1.34, 2]]}, {"timestamp": 1631546822194, "ltp": 1.18, "tv": 10182.03, "trd": NaN, "batb": [[0, 1.19, 128.2]], "batl": [[0, 1.21, 1389.74]]}, {"timestamp": 1631546828600, "ltp": 1.18, "tv": 10182.03, "trd": NaN, "batb": NaN, "batl": [[1, 1.22, 199.75], [2, 1.23, 191.63]]}, {"timestamp": 1631546832837, "ltp": 1.18, "tv": 10182.03, "trd": NaN, "batb": [[0, 1.19, 103], [1, 1.17, 109], [2, 1.16, 337.97]], "batl": [[0, 1.21, 209], [1, 1.23, 183.5], [2, 1.34, 2]]}, {"timestamp": 1631546833214, "ltp": 1.18, "tv": 10182.03, "trd": NaN, "batb": [[0, 1.17, 109], [1, 1.16, 113], [2, 1.15, 117]], "batl": [[0, 1.23, 183.5], [1, 1.34, 2], [2, 1.39, 17.9]]}, {"timestamp": 1631546839551, "ltp": 1.18, "tv": 10182.03, "trd": NaN, "batb": NaN, "batl": [[0, 1.22, 184.25], [1, 1.23, 183.5], [2, 1.34, 2]]}, {"timestamp": 1631546843724, "ltp": 1.18, "tv": 10182.03, "trd": NaN, "batb": [[0, 1.18, 21.09], [1, 1.17, 109], [2, 1.16, 864.9]], "batl": [[0, 1.19, 994.79], [1, 1.2, 221.03], [2, 1.21, 8.26]]}, {"timestamp": 1631546845744, "ltp": 1.18, "tv": 10182.03, "trd": NaN, "batb": NaN, "batl": [[1, 1.2, 432.03]]}, {"timestamp": 1631546849847, "ltp": 1.18, "tv": 10182.03, "trd": NaN, "batb": NaN, "batl": [[0, 1.19, 1144.79]]}, {"timestamp": 1631546853024, "ltp": 1.18, "tv": 10182.03, "trd": NaN, "batb": NaN, "batl": [[2, 1.21, 184.76]]}, {"timestamp": 1631546870586, "ltp": 1.18, "tv": 10182.03, "trd": NaN, "batb": [[0, 1.16, 113], [1, 1.15, 117], [2, 1.14, 121]], "batl": [[0, 1.19, 150], [1, 1.21, 176.5], [2, 1.22, 184.25]]}, {"timestamp": 1631546871169, "ltp": 1.18, "tv": 10182.03, "trd": NaN, "batb": NaN, "batl": [[0, 1.21, 176.5], [1, 1.34, 2], [2, 1.39, 17.9]]}, {"timestamp": 1631546876892, "ltp": 1.18, "tv": 10182.03, "trd": NaN, "batb": [[0, 1.15, 117], [1, 1.14, 121], [2, 1.13, 127]], "batl": [[0, 1.2, 208.23], [1, 1.21, 176.5], [2, 1.34, 2]]}, {"timestamp": 1631546877479, "ltp": 1.18, "tv": 10182.03, "trd": NaN, "batb": NaN, "batl": [[0, 1.21, 176.5], [1, 1.34, 2], [2, 1.39, 17.9]]}, {"timestamp": 1631546883888, "ltp": 1.18, "tv": 10182.03, "trd": NaN, "batb": NaN, "batl": [[0, 1.2, 211.33], [1, 1.21, 176.5], [2, 1.34, 2]]}, {"timestamp": 1631546884198, "ltp": 1.18, "tv": 10182.03, "trd": NaN, "batb": NaN, "batl": [[0, 1.21, 176.5], [1, 1.34, 2], [2, 1.39, 17.9]]}, {"timestamp": 1631546887899, "ltp": 1.18, "tv": 10182.03, "trd": NaN, "batb": NaN, "batl": [[0, 1.2, 207.38], [1, 1.21, 176.5], [2, 1.34, 2]]}, {"timestamp": 1631546888314, "ltp": 1.18, "tv": 10182.03, "trd": NaN, "batb": NaN, "batl": [[0, 1.21, 176.5], [1, 1.34, 2], [2, 1.39, 17.9]]}, {"timestamp": 1631546889711, "ltp": 1.15, "tv": 10195.6, "trd": [[1.15, 13.57]], "batb": [[0, 1.15, 103.43]], "batl": NaN}, {"timestamp": 1631546890716, "ltp": 1.15, "tv": 10195.6, "trd": NaN, "batb": [[0, 1.19, 126.04], [1, 1.18, 63.02], [2, 1.17, 71.57]], "batl": [[0, 1.21, 1340.64]]}, {"timestamp": 1631546891810, "ltp": 1.15, "tv": 10195.6, "trd": NaN, "batb": [[0, 1.19, 25.2], [1, 1.18, 12.6], [2, 1.17, 21.15]], "batl": [[1, 1.23, 8.13], [2, 1.34, 2]]}, {"timestamp": 1631546892495, "ltp": 1.15, "tv": 10195.6, "trd": NaN, "batb": [[0, 1.19, 128.2], [2, 1.17, 130.15]], "batl": [[0, 1.21, 1549.64]]}, {"timestamp": 1631546897741, "ltp": 1.15, "tv": 10195.6, "trd": NaN, "batb": NaN, "batl": [[1, 1.22, 189.25], [2, 1.23, 8.13]]}, {"timestamp": 1631546904662, "ltp": 1.15, "tv": 10195.6, "trd": NaN, "batb": NaN, "batl": [[0, 1.2, 329], [1, 1.21, 1549.64], [2, 1.22, 189.25]]}, {"timestamp": 1631546908620, "ltp": 1.15, "tv": 10195.6, "trd": NaN, "batb": [[0, 1.19, 103], [1, 1.17, 109], [2, 1.16, 340.73]], "batl": [[1, 1.21, 385.5]]}, {"timestamp": 1631546909143, "ltp": 1.15, "tv": 10195.6, "trd": NaN, "batb": [[0, 1.17, 109], [1, 1.16, 113], [2, 1.15, 103.43]], "batl": [[1, 1.21, 176.5]]}, {"timestamp": 1631546910125, "ltp": 1.15, "tv": 10195.6, "trd": NaN, "batb": NaN, "batl": [[0, 1.22, 189.25], [1, 1.34, 2], [2, 1.39, 17.9]]}, {"timestamp": 1631546916874, "ltp": 1.15, "tv": 10195.6, "trd": NaN, "batb": NaN, "batl": [[0, 1.21, 197.5], [1, 1.22, 189.25], [2, 1.34, 2]]}, {"timestamp": 1631546917138, "ltp": 1.15, "tv": 10195.6, "trd": NaN, "batb": NaN, "batl": [[0, 1.22, 189.25], [1, 1.34, 2], [2, 1.39, 17.9]]}, {"timestamp": 1631546927880, "ltp": 1.21, "tv": 10244.42, "trd": [[1.21, 85.71]], "batb": [[0, 1.18, 8.47], [1, 1.17, 109], [2, 1.16, 113]], "batl": [[0, 1.22, 1008.02]]}, {"timestamp": 1631546928868, "ltp": 1.21, "tv": 10244.42, "trd": NaN, "batb": [[1, 1.17, 317.69]], "batl": [[1, 1.23, 121.96], [2, 1.24, 69.04]]}, {"timestamp": 1631546929384, "ltp": 1.21, "tv": 10244.42, "trd": NaN, "batb": [[0, 1.2, 100], [1, 1.18, 114.47], [2, 1.17, 317.69]], "batl": [[0, 1.22, 1230.02], [1, 1.23, 24.4], [2, 1.24, 20.26]]}, {"timestamp": 1631546935970, "ltp": 1.21, "tv": 10244.42, "trd": NaN, "batb": NaN, "batl": [[0, 1.22, 1311.02]]}, {"timestamp": 1631546940786, "ltp": 1.21, "tv": 10244.42, "trd": NaN, "batb": [[0, 1.2, 118.52]], "batl": [[0, 1.22, 1343.41]]}, {"timestamp": 1631546942805, "ltp": 1.21, "tv": 10244.42, "trd": NaN, "batb": [[0, 1.2, 100]], "batl": [[0, 1.22, 1311.02]]}, {"timestamp": 1631546945778, "ltp": 1.21, "tv": 10244.42, "trd": NaN, "batb": [[0, 1.2, 118.52]], "batl": [[0, 1.22, 1343.41]]}, {"timestamp": 1631546955909, "ltp": 1.21, "tv": 10244.42, "trd": NaN, "batb": [[0, 1.2, 100], [1, 1.18, 106], [2, 1.17, 109]], "batl": [[0, 1.22, 303], [1, 1.25, 157.82], [2, 1.27, 169.5]]}, {"timestamp": 1631546956822, "ltp": 1.21, "tv": 10244.42, "trd": NaN, "batb": [[0, 1.18, 106], [1, 1.17, 109], [2, 1.16, 113]], "batl": [[0, 1.27, 169.5], [1, 1.34, 2], [2, 1.39, 17.9]]}, {"timestamp": 1631546959739, "ltp": 1.21, "tv": 10244.42, "trd": NaN, "batb": NaN, "batl": [[0, 1.25, 157.82], [1, 1.27, 169.5], [2, 1.34, 2]]}, {"timestamp": 1631546960223, "ltp": 1.21, "tv": 10244.42, "trd": NaN, "batb": NaN, "batl": [[0, 1.27, 169.5], [1, 1.34, 2], [2, 1.39, 17.9]]}, {"timestamp": 1631546962442, "ltp": 1.21, "tv": 10244.42, "trd": NaN, "batb": NaN, "batl": [[0, 1.2, 672.23], [1, 1.22, 8.2], [2, 1.27, 169.5]]}, {"timestamp": 1631546963849, "ltp": 1.21, "tv": 10244.42, "trd": NaN, "batb": [[2, 1.16, 121.62]], "batl": [[0, 1.2, 898.23]]}, {"timestamp": 1631546969135, "ltp": 1.21, "tv": 10244.42, "trd": NaN, "batb": [[1, 1.17, 247.97], [2, 1.16, 255.15]], "batl": [[1, 1.22, 161.95], [2, 1.23, 164.5]]}, {"timestamp": 1631546972347, "ltp": 1.21, "tv": 10244.42, "trd": NaN, "batb": NaN, "batl": [[0, 1.2, 1013.23]]}, {"timestamp": 1631546974541, "ltp": 1.21, "tv": 10244.42, "trd": NaN, "batb": [[2, 1.16, 246.53]], "batl": [[0, 1.2, 341], [1, 1.22, 153.75]]}, {"timestamp": 1631546975214, "ltp": 1.21, "tv": 10244.42, "trd": NaN, "batb": [[0, 1.17, 109], [1, 1.16, 246.53], [2, 1.15, 103.43]], "batl": [[0, 1.23, 164.5], [1, 1.34, 2], [2, 1.39, 17.9]]}, {"timestamp": 1631546988856, "ltp": 1.21, "tv": 10244.42, "trd": NaN, "batb": [[0, 1.17, 252.97]], "batl": [[0, 1.22, 160.75], [1, 1.23, 164.5], [2, 1.34, 2]]}, {"timestamp": 1631546989168, "ltp": 1.21, "tv": 10244.42, "trd": NaN, "batb": [[0, 1.17, 109]], "batl": [[0, 1.23, 164.5], [1, 1.34, 2], [2, 1.39, 17.9]]}, {"timestamp": 1631547002881, "ltp": 1.21, "tv": 10244.42, "trd": NaN, "batb": [[0, 1.17, 253.97]], "batl": [[0, 1.22, 160.75], [1, 1.23, 164.5], [2, 1.34, 2]]}, {"timestamp": 1631547003768, "ltp": 1.21, "tv": 10244.42, "trd": NaN, "batb": [[0, 1.21, 24.8], [1, 1.2, 12.4], [2, 1.19, 20.8]], "batl": [[0, 1.23, 846.6], [1, 1.34, 2], [2, 3.8, 27.43]]}, {"timestamp": 1631547004874, "ltp": 1.21, "tv": 10244.42, "trd": NaN, "batb": [[1, 1.2, 112.4]], "batl": [[0, 1.23, 1066.6], [1, 1.25, 8], [2, 1.34, 2]]}, {"timestamp": 1631547011507, "ltp": 1.21, "tv": 10244.42, "trd": NaN, "batb": NaN, "batl": [[0, 1.23, 1163.6]]}, {"timestamp": 1631547012494, "ltp": 1.21, "tv": 10244.42, "trd": NaN, "batb": NaN, "batl": [[2, 1.27, 153.5]]}, {"timestamp": 1631547013068, "ltp": 1.23, "tv": 10244.6, "trd": [[1.23, 8.77]], "batb": NaN, "batl": [[0, 1.23, 1163.51]]}, {"timestamp": 1631547023895, "ltp": 1.23, "tv": 10244.6, "trd": NaN, "batb": [[0, 1.18, 106], [1, 1.17, 109], [2, 1.16, 113]], "batl": [[0, 1.23, 97], [1, 1.27, 153.5], [2, 1.29, 148.5]]}, {"timestamp": 1631547024887, "ltp": 1.23, "tv": 10244.6, "trd": NaN, "batb": NaN, "batl": [[0, 1.29, 148.5], [1, 1.34, 2], [2, 3.8, 27.43]]}, {"timestamp": 1631547034515, "ltp": 1.23, "tv": 10244.6, "trd": NaN, "batb": NaN, "batl": [[0, 1.27, 147.5], [1, 1.29, 148.5], [2, 1.34, 2]]}, {"timestamp": 1631547035842, "ltp": 1.26, "tv": 10246.6, "trd": [[1.26, 2]], "batb": [[0, 1.24, 738.84], [1, 1.23, 8.13], [2, 1.18, 106]], "batl": [[0, 1.28, 22.06]]}, {"timestamp": 1631547036831, "ltp": 1.26, "tv": 10246.6, "trd": NaN, "batb": [[1, 1.23, 159.2], [2, 1.19, 184.03]], "batl": [[2, 1.3, 30.77]]}, {"timestamp": 1631547037247, "ltp": 1.26, "tv": 10246.6, "trd": NaN, "batb": [[2, 1.2, 100]], "batl": [[0, 1.27, 213], [1, 1.28, 22.06], [2, 1.29, 148.5]]}, {"timestamp": 1631547039187, "ltp": 1.26, "tv": 10246.6, "trd": NaN, "batb": [[2, 1.22, 2]], "batl": NaN}, {"timestamp": 1631547046046, "ltp": 1.26, "tv": 10246.6, "trd": NaN, "batb": NaN, "batl": [[1, 1.29, 148.5], [2, 1.3, 30.77]]}, {"timestamp": 1631547049374, "ltp": 1.26, "tv": 10246.6, "trd": NaN, "batb": NaN, "batl": [[1, 1.28, 24.04], [2, 1.29, 148.5]]}, {"timestamp": 1631547051812, "ltp": 1.26, "tv": 10246.6, "trd": NaN, "batb": [[0, 1.23, 151.07], [1, 1.22, 2], [2, 1.2, 100]], "batl": [[1, 1.34, 137.75], [2, 1.36, 127.07]]}, {"timestamp": 1631547052486, "ltp": 1.26, "tv": 10246.6, "trd": NaN, "batb": [[0, 1.22, 2], [1, 1.2, 100], [2, 1.19, 287.03]], "batl": [[0, 1.34, 2], [1, 1.36, 127.07], [2, 1.37, 121.5]]}, {"timestamp": 1631547058805, "ltp": 1.26, "tv": 10246.6, "trd": NaN, "batb": NaN, "batl": [[0, 1.33, 138.5], [1, 1.34, 2], [2, 1.36, 127.07]]}, {"timestamp": 1631547059066, "ltp": 1.26, "tv": 10246.6, "trd": NaN, "batb": NaN, "batl": [[0, 1.34, 2], [1, 1.36, 127.07], [2, 1.37, 121.5]]}, {"timestamp": 1631547063715, "ltp": 1.34, "tv": 10248.6, "trd": [[1.34, 105.29]], "batb": [[0, 1.34, 15.55], [1, 1.25, 1998.76], [2, 1.22, 2]], "batl": [[0, 1.36, 148.25], [1, 1.37, 851.39], [2, 3.8, 27.43]]}, {"timestamp": 1631547064711, "ltp": 1.34, "tv": 10252.6, "trd": [[1.34, 109.29]], "batb": [[0, 1.34, 13.55], [1, 1.3, 110.89], [2, 1.26, 133.62]], "batl": [[1, 1.37, 873.29], [2, 1.38, 18.19]]}, {"timestamp": 1631547065286, "ltp": 1.34, "tv": 10252.6, "trd": NaN, "batb": NaN, "batl": [[0, 1.36, 347.25]]}, {"timestamp": 1631547067881, "ltp": 1.34, "tv": 10252.6, "trd": NaN, "batb": [[2, 1.28, 2]], "batl": NaN}, {"timestamp": 1631547074818, "ltp": 1.34, "tv": 10256.6, "trd": [[1.34, 113.29]], "batb": [[0, 1.3, 110.89], [1, 1.28, 2], [2, 1.26, 133.62]], "batl": [[0, 1.36, 326.07]]}, {"timestamp": 1631547075027, "ltp": 1.36, "tv": 10329.64, "trd": [[1.36, 73.04]], "batb": NaN, "batl": [[0, 1.36, 253.03]]}, {"timestamp": 1631547077841, "ltp": 1.36, "tv": 10329.64, "trd": NaN, "batb": [[0, 1.34, 13.55]], "batl": [[0, 1.36, 222.14], [1, 1.43, 143.5], [2, 1.46, 117.25]]}, {"timestamp": 1631547078407, "ltp": 1.36, "tv": 10329.64, "trd": NaN, "batb": [[0, 1.28, 4], [1, 1.26, 133.62], [2, 1.22, 2]], "batl": [[0, 1.46, 117.25], [1, 3.8, 27.43], [2, 8.8, 7.22]]}, {"timestamp": 1631547081623, "ltp": 1.36, "tv": 10329.64, "trd": NaN, "batb": NaN, "batl": [[0, 1.43, 93.5], [1, 1.46, 117.25], [2, 3.8, 27.43]]}, {"timestamp": 1631547081935, "ltp": 1.36, "tv": 10329.64, "trd": NaN, "batb": NaN, "batl": [[0, 1.46, 117.25], [1, 3.8, 27.43], [2, 8.8, 7.22]]}, {"timestamp": 1631547086720, "ltp": 1.36, "tv": 10329.64, "trd": NaN, "batb": NaN, "batl": [[0, 1.32, 137.86], [1, 1.33, 7.52], [2, 1.46, 117.25]]}, {"timestamp": 1631547087812, "ltp": 1.36, "tv": 10329.64, "trd": NaN, "batb": [[0, 1.28, 74.32], [1, 1.27, 35.16], [2, 1.26, 168.78]], "batl": NaN}, {"timestamp": 1631547088749, "ltp": 1.36, "tv": 10329.64, "trd": NaN, "batb": [[0, 1.28, 27.44], [1, 1.27, 11.72], [2, 1.26, 145.34]], "batl": [[0, 1.32, 342.86]]}, {"timestamp": 1631547089739, "ltp": 1.36, "tv": 10329.64, "trd": NaN, "batb": [[0, 1.29, 18.27], [1, 1.28, 27.44], [2, 1.27, 11.72]], "batl": [[0, 1.31, 26.48], [1, 1.32, 342.86], [2, 1.33, 7.52]]}, {"timestamp": 1631547097725, "ltp": 1.36, "tv": 10329.64, "trd": NaN, "batb": [[0, 1.28, 4], [1, 1.22, 2], [2, 1.2, 279.08]], "batl": [[0, 1.42, 96.25], [1, 1.46, 117.25], [2, 3.8, 27.43]]}, {"timestamp": 1631547098037, "ltp": 1.36, "tv": 10329.64, "trd": NaN, "batb": NaN, "batl": [[0, 1.46, 117.25], [1, 3.8, 27.43], [2, 8.8, 7.22]]}, {"timestamp": 1631547102856, "ltp": 1.36, "tv": 10329.64, "trd": NaN, "batb": NaN, "batl": [[0, 1.42, 94.25], [1, 1.46, 117.25], [2, 3.8, 27.43]]}, {"timestamp": 1631547103378, "ltp": 1.36, "tv": 10329.64, "trd": NaN, "batb": [[2, 1.2, 179.08]], "batl": [[0, 3.8, 27.43], [1, 8.8, 7.22], [2, 44, 7.22]]}, {"timestamp": 1631547104669, "ltp": 1.28, "tv": 10337.64, "trd": [[1.28, 8]], "batb": [[0, 1.23, 18.43], [2, 1.2, 946.78]], "batl": [[0, 1.25, 156.9], [1, 1.26, 1195.83], [2, 1.27, 7.87]]}, {"timestamp": 1631547105703, "ltp": 1.28, "tv": 10337.64, "trd": NaN, "batb": [[2, 1.2, 955.11]], "batl": NaN}, {"timestamp": 1631547106326, "ltp": 1.28, "tv": 10337.64, "trd": NaN, "batb": NaN, "batl": [[0, 1.25, 373.9]]}, {"timestamp": 1631547114614, "ltp": 1.25, "tv": 10337.84, "trd": [[1.25, 9.42]], "batb": NaN, "batl": [[0, 1.25, 373.8]]}, {"timestamp": 1631547118734, "ltp": 1.25, "tv": 10337.84, "trd": NaN, "batb": [[0, 1.22, 2], [1, 1.2, 955.11], [2, 1.18, 106]], "batl": NaN}, {"timestamp": 1631547122847, "ltp": 1.25, "tv": 10337.84, "trd": NaN, "batb": [[1, 1.18, 106], [2, 1.17, 109]], "batl": [[0, 1.25, 217], [1, 1.32, 107.61], [2, 1.35, 87.3]]}, {"timestamp": 1631547123580, "ltp": 1.25, "tv": 10337.84, "trd": NaN, "batb": NaN, "batl": [[0, 1.35, 87.3], [1, 1.56, 685.62], [2, 3.8, 27.43]]}, {"timestamp": 1631547126734, "ltp": 1.25, "tv": 10337.84, "trd": NaN, "batb": NaN, "batl": [[0, 1.32, 101.11], [1, 1.35, 87.3], [2, 1.56, 685.62]]}, {"timestamp": 1631547126944, "ltp": 1.25, "tv": 10337.84, "trd": NaN, "batb": NaN, "batl": [[0, 1.35, 87.3], [1, 1.56, 685.62], [2, 3.8, 27.43]]}, {"timestamp": 1631547133664, "ltp": 1.25, "tv": 10337.84, "trd": NaN, "batb": NaN, "batl": [[0, 1.32, 102.36], [1, 1.35, 87.3], [2, 1.56, 685.62]]}, {"timestamp": 1631547133963, "ltp": 1.25, "tv": 10337.84, "trd": NaN, "batb": NaN, "batl": [[0, 1.35, 87.3], [1, 1.56, 685.62], [2, 3.8, 27.43]]}, {"timestamp": 1631547140676, "ltp": 1.25, "tv": 10337.84, "trd": NaN, "batb": NaN, "batl": [[0, 1.32, 100.86], [1, 1.35, 87.3], [2, 1.56, 685.62]]}, {"timestamp": 1631547140989, "ltp": 1.25, "tv": 10337.84, "trd": NaN, "batb": NaN, "batl": [[0, 1.35, 87.3], [1, 1.56, 685.62], [2, 3.8, 27.43]]}, {"timestamp": 1631547147695, "ltp": 1.25, "tv": 10337.84, "trd": NaN, "batb": NaN, "batl": [[0, 1.32, 105.11], [1, 1.35, 87.3], [2, 1.56, 685.62]]}, {"timestamp": 1631547147961, "ltp": 1.25, "tv": 10337.84, "trd": NaN, "batb": NaN, "batl": [[0, 1.35, 87.3], [1, 1.56, 685.62], [2, 3.8, 27.43]]}, {"timestamp": 1631547149269, "ltp": 1.25, "tv": 10337.84, "trd": NaN, "batb": NaN, "batl": [[1, 3.8, 27.43], [2, 8.8, 7.22]]}, {"timestamp": 1631547150304, "ltp": 1.25, "tv": 10337.84, "trd": NaN, "batb": [[1, 1.17, 109], [2, 1.16, 331.59]], "batl": NaN}, {"timestamp": 1631547151606, "ltp": 1.22, "tv": 10341.84, "trd": [[1.22, 4]], "batb": [[0, 1.17, 109], [1, 1.16, 331.59], [2, 1.15, 103.43]], "batl": [[0, 1.21, 177.65], [1, 1.23, 8.13], [2, 1.25, 1437.48]]}, {"timestamp": 1631547152900, "ltp": 1.22, "tv": 10341.84, "trd": NaN, "batb": [[0, 1.17, 117.55]], "batl": NaN}, {"timestamp": 1631547153162, "ltp": 1.22, "tv": 10341.84, "trd": NaN, "batb": [[0, 1.19, 103], [1, 1.17, 117.55], [2, 1.16, 331.59]], "batl": [[0, 1.21, 401.65]]}, {"timestamp": 1631547156906, "ltp": 1.22, "tv": 10341.84, "trd": NaN, "batb": NaN, "batl": [[0, 1.21, 480.65]]}, {"timestamp": 1631547159708, "ltp": 1.22, "tv": 10341.84, "trd": NaN, "batb": [[1, 1.18, 158.86], [2, 1.17, 273.52]], "batl": [[2, 1.25, 1557.86]]}, {"timestamp": 1631547168705, "ltp": 1.19, "tv": 10359.7, "trd": [[1.19, 775.33]], "batb": [[0, 1.19, 94.07]], "batl": NaN}, {"timestamp": 1631547177831, "ltp": 1.19, "tv": 10359.7, "trd": NaN, "batb": NaN, "batl": [[0, 1.21, 457.5], [2, 1.25, 120.38]]}, {"timestamp": 1631547178828, "ltp": 1.19, "tv": 10359.7, "trd": NaN, "batb": [[0, 1.17, 109], [1, 1.16, 113], [2, 1.15, 103.43]], "batl": [[0, 1.27, 98.5], [1, 1.49, 772.97], [2, 3.8, 27.43]]}, {"timestamp": 1631547181616, "ltp": 1.19, "tv": 10359.7, "trd": NaN, "batb": [[0, 1.17, 259.97]], "batl": NaN}, {"timestamp": 1631547184824, "ltp": 1.19, "tv": 10359.7, "trd": NaN, "batb": [[0, 1.18, 122.36], [1, 1.17, 259.97], [2, 1.16, 113]], "batl": NaN}, {"timestamp": 1631547185853, "ltp": 1.19, "tv": 10359.7, "trd": NaN, "batb": [[0, 1.17, 259.97], [1, 1.16, 113], [2, 1.15, 103.43]], "batl": NaN}, {"timestamp": 1631547189156, "ltp": 1.19, "tv": 10359.7, "trd": NaN, "batb": NaN, "batl": [[0, 1.25, 117.26], [1, 1.27, 98.5], [2, 1.49, 772.97]]}, {"timestamp": 1631547191837, "ltp": 1.19, "tv": 10359.7, "trd": NaN, "batb": [[0, 1.18, 140.86], [1, 1.17, 259.97], [2, 1.16, 113]], "batl": [[0, 1.49, 772.97], [1, 3.8, 27.43], [2, 8.8, 7.22]]}, {"timestamp": 1631547192255, "ltp": 1.19, "tv": 10359.7, "trd": NaN, "batb": [[0, 1.17, 259.97], [1, 1.16, 113], [2, 1.15, 103.43]], "batl": NaN}, {"timestamp": 1631547193617, "ltp": 1.19, "tv": 10359.7, "trd": NaN, "batb": NaN, "batl": [[0, 1.19, 807.8], [1, 1.2, 141.58], [2, 1.21, 8.26]]}, {"timestamp": 1631547194831, "ltp": 1.19, "tv": 10359.7, "trd": NaN, "batb": [[2, 1.15, 112.13]], "batl": NaN}, {"timestamp": 1631547195143, "ltp": 1.19, "tv": 10359.7, "trd": NaN, "batb": NaN, "batl": [[0, 1.19, 1039.8], [1, 1.2, 373.58]]}, {"timestamp": 1631547201560, "ltp": 1.19, "tv": 10359.7, "trd": NaN, "batb": NaN, "batl": [[0, 1.19, 1116.8]]}, {"timestamp": 1631547237072, "ltp": 1.17, "tv": 10535.7, "trd": [[1.17, 431.13]], "batb": [[0, 1.17, 171.97]], "batl": NaN}, {"timestamp": 1631547244369, "ltp": 1.17, "tv": 10535.7, "trd": NaN, "batb": [[0, 1.17, 150.97]], "batl": NaN}, {"timestamp": 1631547247359, "ltp": 1.17, "tv": 10535.7, "trd": NaN, "batb": [[0, 1.18, 106], [1, 1.17, 150.97], [2, 1.16, 113]], "batl": NaN}, {"timestamp": 1631547254559, "ltp": 1.17, "tv": 10535.7, "trd": NaN, "batb": [[0, 1.17, 150.97], [1, 1.16, 113], [2, 1.15, 112.13]], "batl": NaN}, {"timestamp": 1631547257699, "ltp": 1.17, "tv": 10535.7, "trd": NaN, "batb": [[0, 1.17, 259.97]], "batl": NaN}, {"timestamp": 1631547263182, "ltp": 1.17, "tv": 10535.7, "trd": NaN, "batb": NaN, "batl": [[0, 1.19, 1116.81]]}, {"timestamp": 1631547285133, "ltp": 1.17, "tv": 10535.7, "trd": NaN, "batb": [[1, 1.16, 268.53]], "batl": [[2, 1.21, 133.76]]}, {"timestamp": 1631547291864, "ltp": 1.17, "tv": 10535.7, "trd": NaN, "batb": [[0, 1.16, 268.53], [1, 1.15, 103.43], [2, 1.14, 121]], "batl": [[0, 1.19, 77.01], [1, 1.2, 232], [2, 1.21, 125.5]]}, {"timestamp": 1631547292969, "ltp": 1.17, "tv": 10535.7, "trd": NaN, "batb": NaN, "batl": [[0, 1.2, 232.01], [1, 1.21, 125.5], [2, 3.8, 27.43]]}, {"timestamp": 1631547294658, "ltp": 1.17, "tv": 10535.7, "trd": NaN, "batb": [[0, 1.17, 168.97], [1, 1.16, 268.53], [2, 1.15, 103.43]], "batl": [[0, 1.2, 368.89]]}, {"timestamp": 1631547294960, "ltp": 1.17, "tv": 10535.7, "trd": NaN, "batb": [[0, 1.16, 268.53], [1, 1.15, 103.43], [2, 1.14, 121]], "batl": NaN}, {"timestamp": 1631547301685, "ltp": 1.17, "tv": 10535.7, "trd": NaN, "batb": [[0, 1.17, 154.97], [1, 1.16, 268.53], [2, 1.15, 103.43]], "batl": NaN}, {"timestamp": 1631547301976, "ltp": 1.17, "tv": 10535.7, "trd": NaN, "batb": [[0, 1.16, 268.53], [1, 1.15, 103.43], [2, 1.14, 121]], "batl": NaN}, {"timestamp": 1631547308266, "ltp": 1.17, "tv": 10535.7, "trd": NaN, "batb": NaN, "batl": [[0, 1.2, 232.01], [1, 3.8, 27.43], [2, 8.8, 7.22]]}, {"timestamp": 1631547310880, "ltp": 1.18, "tv": 10535.71, "trd": [[1.18, 267.01]], "batb": [[0, 1.18, 127.11], [1, 1.17, 63.56], [2, 1.16, 340.71]], "batl": [[0, 1.2, 616.56]]}, {"timestamp": 1631547311879, "ltp": 1.18, "tv": 10535.71, "trd": NaN, "batb": [[0, 1.18, 25.42], [1, 1.17, 12.72], [2, 1.16, 289.87]], "batl": [[1, 1.21, 24.8], [2, 1.22, 20.6]]}, {"timestamp": 1631547312577, "ltp": 1.18, "tv": 10535.71, "trd": NaN, "batb": [[1, 1.17, 121.72]], "batl": NaN}, {"timestamp": 1631547318684, "ltp": 1.18, "tv": 10535.71, "trd": NaN, "batb": [[0, 1.18, 170.28], [1, 1.17, 252.69]], "batl": [[0, 1.2, 755.09], [1, 1.21, 150.3]]}, {"timestamp": 1631547319881, "ltp": 1.18, "tv": 10535.71, "trd": NaN, "batb": NaN, "batl": [[0, 1.2, 826.09], [2, 1.22, 140.85]]}, {"timestamp": 1631547322865, "ltp": 1.18, "tv": 10535.71, "trd": NaN, "batb": [[0, 1.16, 268.53], [1, 1.15, 103.43], [2, 1.14, 380.36]], "batl": [[0, 1.2, 232], [1, 1.21, 125.5], [2, 1.22, 120.25]]}, {"timestamp": 1631547322972, "ltp": 1.18, "tv": 10535.71, "trd": NaN, "batb": [[0, 1.16, 113]], "batl": NaN}, {"timestamp": 1631547325689, "ltp": 1.18, "tv": 10535.71, "trd": NaN, "batb": [[0, 1.18, 135.86], [1, 1.17, 148.97], [2, 1.16, 113]], "batl": NaN}, {"timestamp": 1631547325990, "ltp": 1.18, "tv": 10535.71, "trd": NaN, "batb": [[0, 1.17, 148.97], [1, 1.16, 113], [2, 1.15, 103.43]], "batl": NaN}, {"timestamp": 1631547336169, "ltp": 1.18, "tv": 10535.71, "trd": NaN, "batb": [[0, 1.18, 129.36], [1, 1.17, 148.97], [2, 1.16, 113]], "batl": NaN}, {"timestamp": 1631547337681, "ltp": 1.18, "tv": 10535.71, "trd": NaN, "batb": [[0, 1.17, 148.97], [1, 1.16, 113], [2, 1.15, 103.43]], "batl": NaN}, {"timestamp": 1631547340872, "ltp": 1.18, "tv": 10535.71, "trd": NaN, "batb": [[0, 1.19, 25.2], [1, 1.18, 1078.32], [2, 1.17, 170.12]], "batl": [[1, 1.21, 850.39]]}, {"timestamp": 1631547341911, "ltp": 1.18, "tv": 10535.71, "trd": NaN, "batb": [[0, 1.19, 128.2], [1, 1.18, 1184.32], [2, 1.17, 279.12]], "batl": NaN}, {"timestamp": 1631547348285, "ltp": 1.18, "tv": 10535.71, "trd": NaN, "batb": [[0, 1.19, 252.91], [1, 1.18, 1325.18]], "batl": NaN}, {"timestamp": 1631547357832, "ltp": 1.18, "tv": 10535.71, "trd": NaN, "batb": [[0, 1.19, 103], [1, 1.18, 246.86], [2, 1.17, 257.97]], "batl": [[1, 1.21, 125.5]]}, {"timestamp": 1631547358715, "ltp": 1.18, "tv": 10535.71, "trd": NaN, "batb": [[0, 1.18, 246.86], [1, 1.17, 257.97], [2, 1.16, 113]], "batl": [[0, 1.21, 125.5], [1, 3.8, 27.43], [2, 8.8, 7.22]]}, {"timestamp": 1631547367631, "ltp": 1.18, "tv": 10535.71, "trd": NaN, "batb": NaN, "batl": [[0, 1.2, 18.43], [1, 1.21, 125.5], [2, 3.8, 27.43]]}, {"timestamp": 1631547368313, "ltp": 1.18, "tv": 10535.71, "trd": NaN, "batb": NaN, "batl": [[0, 1.21, 125.5], [1, 3.8, 27.43], [2, 8.8, 7.22]]}, {"timestamp": 1631547371646, "ltp": 1.18, "tv": 10535.71, "trd": NaN, "batb": [[0, 1.19, 134.71], [1, 1.18, 246.86], [2, 1.17, 257.97]], "batl": NaN}, {"timestamp": 1631547371914, "ltp": 1.18, "tv": 10535.71, "trd": NaN, "batb": [[0, 1.18, 246.86], [1, 1.17, 257.97], [2, 1.16, 113]], "batl": NaN}, {"timestamp": 1631547380853, "ltp": 1.18, "tv": 10535.71, "trd": NaN, "batb": [[0, 1.2, 22.48], [1, 1.19, 917.42], [2, 1.18, 255.33]], "batl": [[1, 1.22, 762.38], [2, 3.8, 27.43]]}, {"timestamp": 1631547381746, "ltp": 1.18, "tv": 10535.71, "trd": NaN, "batb": [[1, 1.19, 850.2]], "batl": [[2, 1.24, 8.06]]}, {"timestamp": 1631547382739, "ltp": 1.18, "tv": 10535.71, "trd": NaN, "batb": [[1, 1.19, 953.2]], "batl": [[0, 1.21, 363.5]]}, {"timestamp": 1631547387487, "ltp": 1.18, "tv": 10535.71, "trd": NaN, "batb": [[1, 1.19, 1088.91]], "batl": [[1, 1.22, 896.13]]}, {"timestamp": 1631547397807, "ltp": 1.18, "tv": 10535.71, "trd": NaN, "batb": [[0, 1.18, 246.86], [1, 1.17, 257.97], [2, 1.16, 336.96]], "batl": [[0, 1.21, 125.5], [1, 1.22, 133.75], [2, 3.8, 27.43]]}, {"timestamp": 1631547398013, "ltp": 1.18, "tv": 10535.71, "trd": NaN, "batb": NaN, "batl": [[0, 1.22, 133.75], [1, 3.8, 27.43], [2, 8.8, 7.22]]}, {"timestamp": 1631547400828, "ltp": 1.18, "tv": 10535.71, "trd": NaN, "batb": [[0, 1.19, 149.71], [1, 1.18, 246.86], [2, 1.17, 257.97]], "batl": NaN}, {"timestamp": 1631547401502, "ltp": 1.18, "tv": 10535.71, "trd": NaN, "batb": [[0, 1.18, 246.86], [1, 1.17, 257.97], [2, 1.16, 336.96]], "batl": NaN}, {"timestamp": 1631547404906, "ltp": 1.18, "tv": 10535.71, "trd": NaN, "batb": NaN, "batl": [[0, 1.21, 153], [1, 1.22, 133.75], [2, 3.8, 27.43]]}, {"timestamp": 1631547405113, "ltp": 1.18, "tv": 10535.71, "trd": NaN, "batb": NaN, "batl": [[0, 1.22, 133.75], [1, 3.8, 27.43], [2, 8.8, 7.22]]}, {"timestamp": 1631547415640, "ltp": 1.18, "tv": 10535.71, "trd": NaN, "batb": NaN, "batl": [[0, 1.21, 141.5], [1, 1.22, 133.75], [2, 3.8, 27.43]]}, {"timestamp": 1631547417311, "ltp": 1.18, "tv": 10535.71, "trd": NaN, "batb": NaN, "batl": [[0, 1.21, 1159.92], [2, 1.23, 8.13]]}, {"timestamp": 1631547418825, "ltp": 1.18, "tv": 10535.71, "trd": NaN, "batb": [[1, 1.17, 266.52]], "batl": [[0, 1.21, 1397.92]]}, {"timestamp": 1631547424355, "ltp": 1.18, "tv": 10535.71, "trd": NaN, "batb": [[0, 1.19, 126.71], [1, 1.18, 246.86], [2, 1.17, 266.52]], "batl": NaN}, {"timestamp": 1631547425817, "ltp": 1.18, "tv": 10535.71, "trd": NaN, "batb": NaN, "batl": [[0, 1.21, 1485.92]]}, {"timestamp": 1631547432766, "ltp": 1.18, "tv": 10535.71, "trd": NaN, "batb": [[2, 1.17, 257.97]], "batl": [[0, 1.21, 467.5], [2, 3.8, 27.43]]}, {"timestamp": 1631547433734, "ltp": 1.18, "tv": 10535.71, "trd": NaN, "batb": [[0, 1.18, 106], [1, 1.17, 257.97], [2, 1.16, 113]], "batl": [[0, 1.21, 88]]}, {"timestamp": 1631547433930, "ltp": 1.18, "tv": 10535.71, "trd": NaN, "batb": NaN, "batl": [[0, 1.22, 133.75], [1, 3.8, 27.43], [2, 8.8, 7.22]]}, {"timestamp": 1631547436465, "ltp": 1.18, "tv": 10535.71, "trd": NaN, "batb": [[0, 1.18, 252.86]], "batl": NaN}, {"timestamp": 1631547440446, "ltp": 1.18, "tv": 10535.71, "trd": NaN, "batb": NaN, "batl": [[0, 1.21, 138.5], [1, 1.22, 133.75], [2, 3.8, 27.43]]}, {"timestamp": 1631547441854, "ltp": 1.18, "tv": 10535.71, "trd": NaN, "batb": [[0, 1.18, 146.86]], "batl": [[0, 1.22, 133.75], [1, 3.8, 27.43], [2, 8.8, 7.22]]}, {"timestamp": 1631547442844, "ltp": 1.18, "tv": 10535.71, "trd": NaN, "batb": [[0, 1.18, 155.33], [1, 1.17, 109]], "batl": NaN}, {"timestamp": 1631547443849, "ltp": 1.18, "tv": 10535.71, "trd": NaN, "batb": NaN, "batl": [[1, 1.24, 8.06], [2, 3.8, 27.43]]}, {"timestamp": 1631547444852, "ltp": 1.2, "tv": 10537.71, "trd": [[1.2, 46.72]], "batb": [[0, 1.19, 103], [1, 1.18, 155.33], [2, 1.17, 320.38]], "batl": [[0, 1.21, 238], [1, 1.22, 133.75], [2, 1.24, 8.06]]}, {"timestamp": 1631547447868, "ltp": 1.2, "tv": 10537.71, "trd": NaN, "batb": [[1, 1.18, 157.33]], "batl": [[2, 1.24, 270.51]]}, {"timestamp": 1631547447972, "ltp": 1.2, "tv": 10537.71, "trd": NaN, "batb": NaN, "batl": [[2, 1.24, 8.06]]}, {"timestamp": 1631547449588, "ltp": 1.2, "tv": 10537.71, "trd": NaN, "batb": [[2, 1.17, 455.35]], "batl": NaN}, {"timestamp": 1631547465420, "ltp": 1.21, "tv": 10544.34, "trd": [[1.21, 92.33]], "batb": NaN, "batl": [[0, 1.21, 234.69]]}, {"timestamp": 1631547480705, "ltp": 1.21, "tv": 10544.34, "trd": NaN, "batb": [[1, 1.18, 148.86], [2, 1.17, 243.97]], "batl": [[1, 1.25, 117.7], [2, 1.26, 103.25]]}, {"timestamp": 1631547481500, "ltp": 1.21, "tv": 10544.34, "trd": NaN, "batb": [[0, 1.18, 2], [1, 1.17, 243.97], [2, 1.16, 113]], "batl": [[0, 1.27, 105.5], [1, 3.8, 27.43], [2, 8.8, 7.22]]}, {"timestamp": 1631547491749, "ltp": 1.21, "tv": 10544.34, "trd": NaN, "batb": [[0, 1.18, 141.86]], "batl": [[0, 1.25, 109.62], [1, 1.27, 105.5], [2, 3.8, 27.43]]}, {"timestamp": 1631547491959, "ltp": 1.21, "tv": 10544.34, "trd": NaN, "batb": [[0, 1.18, 2]], "batl": [[0, 1.27, 105.5], [1, 3.8, 27.43], [2, 8.8, 7.22]]}, {"timestamp": 1631547495769, "ltp": 1.21, "tv": 10544.34, "trd": NaN, "batb": [[0, 1.18, 150.86]], "batl": [[0, 1.25, 108.14], [1, 1.27, 105.5], [2, 3.8, 27.43]]}, {"timestamp": 1631547496140, "ltp": 1.21, "tv": 10544.34, "trd": NaN, "batb": [[0, 1.18, 2]], "batl": [[0, 1.27, 105.5], [1, 3.8, 27.43], [2, 8.8, 7.22]]}, {"timestamp": 1631547502862, "ltp": 1.21, "tv": 10544.34, "trd": NaN, "batb": [[0, 1.18, 140.86]], "batl": [[0, 1.25, 111.3], [1, 1.27, 105.5], [2, 3.8, 27.43]]}, {"timestamp": 1631547503642, "ltp": 1.21, "tv": 10544.34, "trd": NaN, "batb": [[0, 1.23, 162.6], [1, 1.22, 8.2], [2, 1.18, 2]], "batl": [[0, 1.26, 23.77]]}, {"timestamp": 1631547504846, "ltp": 1.24, "tv": 10546.34, "trd": [[1.24, 2]], "batb": [[0, 1.23, 97.56], [1, 1.22, 170.42], [2, 1.18, 198.45]], "batl": [[2, 1.28, 7.81]]}, {"timestamp": 1631547505256, "ltp": 1.24, "tv": 10546.34, "trd": NaN, "batb": [[2, 1.2, 100]], "batl": [[0, 1.26, 250.77]]}, {"timestamp": 1631547507149, "ltp": 1.24, "tv": 10546.34, "trd": NaN, "batb": [[2, 1.2, 102]], "batl": NaN}, {"timestamp": 1631547511868, "ltp": 1.24, "tv": 10546.34, "trd": NaN, "batb": [[2, 1.2, 108.12]], "batl": NaN}, {"timestamp": 1631547514167, "ltp": 1.24, "tv": 10546.34, "trd": NaN, "batb": NaN, "batl": [[0, 1.26, 227]]}, {"timestamp": 1631547517881, "ltp": 1.24, "tv": 10546.34, "trd": NaN, "batb": [[0, 1.2, 102], [1, 1.19, 103], [2, 1.18, 311.81]], "batl": [[0, 1.32, 113.61], [1, 1.35, 103.1], [2, 3.8, 27.43]]}, {"timestamp": 1631547518875, "ltp": 1.24, "tv": 10546.34, "trd": NaN, "batb": NaN, "batl": [[0, 1.31, 114.5], [1, 1.33, 106.5], [2, 1.35, 103.1]]}, {"timestamp": 1631547519186, "ltp": 1.24, "tv": 10546.34, "trd": NaN, "batb": NaN, "batl": [[0, 1.33, 106.5], [1, 1.35, 103.1], [2, 3.8, 27.43]]}, {"timestamp": 1631547520801, "ltp": 1.24, "tv": 10546.34, "trd": NaN, "batb": [[0, 1.2, 108.07]], "batl": NaN}, {"timestamp": 1631547521481, "ltp": 1.24, "tv": 10546.34, "trd": NaN, "batb": [[0, 1.2, 102]], "batl": NaN}, {"timestamp": 1631547527792, "ltp": 1.24, "tv": 10546.34, "trd": NaN, "batb": [[0, 1.2, 107.82]], "batl": NaN}, {"timestamp": 1631547528104, "ltp": 1.24, "tv": 10546.34, "trd": NaN, "batb": [[0, 1.2, 102]], "batl": NaN}, {"timestamp": 1631547530792, "ltp": 1.31, "tv": 10550.34, "trd": [[1.31, 4]], "batb": [[0, 1.31, 11.09], [1, 1.3, 92.3], [2, 1.29, 4.12]], "batl": NaN}, {"timestamp": 1631547531682, "ltp": 1.31, "tv": 10550.34, "trd": NaN, "batb": NaN, "batl": [[0, 1.32, 217], [1, 1.33, 106.5], [2, 1.35, 110.51]]}, {"timestamp": 1631547534600, "ltp": 1.31, "tv": 10561.43, "trd": [[1.31, 15.09]], "batb": [[0, 1.3, 92.3], [1, 1.29, 4.12], [2, 1.28, 120.45]], "batl": NaN}, {"timestamp": 1631547545909, "ltp": 1.31, "tv": 10561.43, "trd": NaN, "batb": [[0, 1.29, 4.12], [1, 1.25, 6.69], [2, 1.24, 146.2]], "batl": [[1, 1.39, 96.5], [2, 1.4, 98.94]]}, {"timestamp": 1631547546428, "ltp": 1.31, "tv": 10561.43, "trd": NaN, "batb": [[1, 1.25, 2]], "batl": [[0, 1.42, 88.25], [1, 1.66, 831.03], [2, 3.8, 27.43]]}, {"timestamp": 1631547547695, "ltp": 1.31, "tv": 10561.43, "trd": NaN, "batb": NaN, "batl": [[0, 1.32, 21.01], [1, 1.42, 88.25], [2, 1.66, 831.03]]}, {"timestamp": 1631547548010, "ltp": 1.31, "tv": 10561.43, "trd": NaN, "batb": NaN, "batl": [[0, 1.42, 88.25], [1, 1.66, 831.03], [2, 3.8, 27.43]]}, {"timestamp": 1631547549719, "ltp": 1.31, "tv": 10561.43, "trd": NaN, "batb": NaN, "batl": [[0, 1.39, 99.5], [1, 1.42, 88.25], [2, 1.66, 831.03]]}, {"timestamp": 1631547550823, "ltp": 1.31, "tv": 10561.43, "trd": NaN, "batb": NaN, "batl": [[0, 1.42, 88.25], [1, 1.66, 831.03], [2, 3.8, 27.43]]}, {"timestamp": 1631547556646, "ltp": 1.31, "tv": 10561.43, "trd": NaN, "batb": [[1, 1.25, 7.33]], "batl": NaN}, {"timestamp": 1631547557688, "ltp": 1.31, "tv": 10561.43, "trd": NaN, "batb": [[0, 1.25, 2], [1, 1.24, 146.2], [2, 1.23, 5.02]], "batl": [[0, 1.39, 109.5], [1, 1.42, 88.25], [2, 1.66, 831.03]]}, {"timestamp": 1631547558001, "ltp": 1.31, "tv": 10561.43, "trd": NaN, "batb": NaN, "batl": [[0, 1.42, 88.25], [1, 1.66, 831.03], [2, 3.8, 27.43]]}, {"timestamp": 1631547560673, "ltp": 1.31, "tv": 10561.43, "trd": NaN, "batb": NaN, "batl": [[1, 3.8, 27.43], [2, 8.8, 7.22]]}, {"timestamp": 1631547563902, "ltp": 1.31, "tv": 10561.43, "trd": NaN, "batb": [[0, 1.25, 7.41]], "batl": NaN}, {"timestamp": 1631547564689, "ltp": 1.31, "tv": 10561.43, "trd": NaN, "batb": [[0, 1.25, 2]], "batl": [[0, 1.39, 100.5], [1, 1.42, 88.25], [2, 3.8, 27.43]]}, {"timestamp": 1631547565003, "ltp": 1.31, "tv": 10561.43, "trd": NaN, "batb": NaN, "batl": [[0, 1.42, 88.25], [1, 3.8, 27.43], [2, 8.8, 7.22]]}, {"timestamp": 1631547570782, "ltp": 1.31, "tv": 10561.43, "trd": NaN, "batb": [[0, 1.25, 7.05]], "batl": NaN}, {"timestamp": 1631547571803, "ltp": 1.31, "tv": 10561.43, "trd": NaN, "batb": [[0, 1.26, 19.03], [1, 1.25, 2], [2, 1.24, 146.2]], "batl": [[0, 1.28, 176.04], [1, 1.31, 160.31], [2, 1.39, 101.5]]}, {"timestamp": 1631547572899, "ltp": 1.31, "tv": 10561.43, "trd": NaN, "batb": [[2, 1.24, 154.26]], "batl": NaN}, {"timestamp": 1631547573313, "ltp": 1.31, "tv": 10561.43, "trd": NaN, "batb": NaN, "batl": [[0, 1.28, 400.04]]}, {"timestamp": 1631547578819, "ltp": 1.31, "tv": 10561.43, "trd": NaN, "batb": NaN, "batl": [[2, 1.36, 106.32]]}, {"timestamp": 1631547586480, "ltp": 1.28, "tv": 10605.43, "trd": [[1.28, 52]], "batb": NaN, "batl": [[0, 1.28, 378.04]]}, {"timestamp": 1631547589715, "ltp": 1.28, "tv": 10605.43, "trd": NaN, "batb": [[0, 1.25, 2], [1, 1.24, 146.2], [2, 1.23, 5.02]], "batl": [[0, 1.28, 224], [1, 1.36, 106.32], [2, 1.39, 101.5]]}, {"timestamp": 1631547590188, "ltp": 1.28, "tv": 10605.43, "trd": NaN, "batb": [[1, 1.2, 102], [2, 1.19, 286.61]], "batl": [[0, 1.39, 101.5], [1, 3.8, 27.43], [2, 8.8, 7.22]]}, {"timestamp": 1631547594827, "ltp": 1.28, "tv": 10605.43, "trd": NaN, "batb": NaN, "batl": [[0, 1.29, 20.5], [1, 1.39, 101.5], [2, 3.8, 27.43]]}, {"timestamp": 1631547595090, "ltp": 1.28, "tv": 10605.43, "trd": NaN, "batb": NaN, "batl": [[0, 1.39, 101.5], [1, 3.8, 27.43], [2, 8.8, 7.22]]}, {"timestamp": 1631547596906, "ltp": 1.28, "tv": 10605.43, "trd": NaN, "batb": NaN, "batl": [[0, 1.36, 96.82], [1, 1.39, 101.5], [2, 3.8, 27.43]]}, {"timestamp": 1631547597425, "ltp": 1.28, "tv": 10605.43, "trd": NaN, "batb": [[0, 1.28, 2.71], [1, 1.25, 2], [2, 1.2, 102]], "batl": [[0, 1.39, 101.5], [1, 3.8, 27.43], [2, 8.8, 7.22]]}, {"timestamp": 1631547602825, "ltp": 1.28, "tv": 10605.43, "trd": NaN, "batb": NaN, "batl": [[0, 1.38, 24.1], [1, 1.39, 101.5], [2, 3.8, 27.43]]}, {"timestamp": 1631547603821, "ltp": 1.28, "tv": 10605.43, "trd": NaN, "batb": [[0, 1.33, 105.53], [1, 1.28, 2.71], [2, 1.27, 126.32]], "batl": [[1, 1.39, 108.69]]}, {"timestamp": 1631547604345, "ltp": 1.28, "tv": 10605.43, "trd": NaN, "batb": NaN, "batl": [[2, 1.73, 769.67]]}, {"timestamp": 1631547605723, "ltp": 1.28, "tv": 10605.43, "trd": NaN, "batb": [[1, 1.27, 126.32], [2, 1.25, 2]], "batl": [[1, 1.39, 314.69]]}, {"timestamp": 1631547607849, "ltp": 1.28, "tv": 10605.43, "trd": NaN, "batb": NaN, "batl": [[0, 1.38, 192.97]]}, {"timestamp": 1631547608009, "ltp": 1.28, "tv": 10605.43, "trd": NaN, "batb": NaN, "batl": [[0, 1.38, 24.1]]}, {"timestamp": 1631547609951, "ltp": 1.28, "tv": 10605.43, "trd": NaN, "batb": [[1, 1.28, 4.66], [2, 1.27, 126.32]], "batl": [[2, 1.47, 102.5]]}, {"timestamp": 1631547611634, "ltp": 1.28, "tv": 10605.43, "trd": NaN, "batb": NaN, "batl": [[2, 1.46, 96.75]]}, {"timestamp": 1631547614831, "ltp": 1.28, "tv": 10605.43, "trd": NaN, "batb": NaN, "batl": [[0, 1.39, 307.5], [1, 1.46, 96.75], [2, 1.47, 102.5]]}, {"timestamp": 1631547615834, "ltp": 1.28, "tv": 10605.43, "trd": NaN, "batb": [[0, 1.33, 3.53], [1, 1.27, 126.32], [2, 1.25, 6.73]], "batl": [[0, 1.5, 83.01], [1, 1.73, 769.67], [2, 3.8, 27.43]]}, {"timestamp": 1631547618796, "ltp": 1.28, "tv": 10605.43, "trd": NaN, "batb": [[1, 1.28, 4.66], [2, 1.27, 126.32]], "batl": NaN}, {"timestamp": 1631547619793, "ltp": 1.28, "tv": 10605.43, "trd": NaN, "batb": [[1, 1.27, 126.32], [2, 1.25, 6.73]], "batl": NaN}, {"timestamp": 1631547625690, "ltp": 1.28, "tv": 10605.43, "trd": NaN, "batb": [[1, 1.28, 4.41], [2, 1.27, 126.32]], "batl": NaN}, {"timestamp": 1631547626835, "ltp": 1.28, "tv": 10605.43, "trd": NaN, "batb": [[1, 1.27, 126.32], [2, 1.25, 6.73]], "batl": NaN}, {"timestamp": 1631547630900, "ltp": 1.28, "tv": 10605.43, "trd": NaN, "batb": [[0, 1.27, 126.32], [1, 1.25, 6.73], [2, 1.2, 102]], "batl": [[1, 3.8, 27.43], [2, 8.8, 7.22]]}, {"timestamp": 1631547631838, "ltp": 1.28, "tv": 10605.43, "trd": NaN, "batb": [[0, 1.29, 17.16], [1, 1.27, 126.32], [2, 1.25, 6.73]], "batl": [[0, 1.32, 2717.82], [1, 1.34, 156.72], [2, 1.5, 83.01]]}, {"timestamp": 1631547632833, "ltp": 1.28, "tv": 10605.43, "trd": NaN, "batb": [[1, 1.28, 117.2], [2, 1.27, 184.92]], "batl": [[0, 1.32, 140.61]]}, {"timestamp": 1631547633837, "ltp": 1.28, "tv": 10605.43, "trd": NaN, "batb": [[1, 1.28, 23.44], [2, 1.27, 138.04]], "batl": [[0, 1.31, 218], [1, 1.32, 140.61], [2, 1.34, 156.72]]}, {"timestamp": 1631547636804, "ltp": 1.28, "tv": 10605.43, "trd": NaN, "batb": NaN, "batl": [[2, 1.33, 197.76]]}, {"timestamp": 1631547637011, "ltp": 1.28, "tv": 10605.43, "trd": NaN, "batb": NaN, "batl": [[2, 1.34, 156.72]]}, {"timestamp": 1631547642857, "ltp": 1.28, "tv": 10605.43, "trd": NaN, "batb": [[0, 1.25, 6.73], [1, 1.2, 480.16], [2, 1.19, 103]], "batl": [[1, 1.47, 77.5], [2, 1.5, 83.01]]}, {"timestamp": 1631547643423, "ltp": 1.28, "tv": 10605.43, "trd": NaN, "batb": NaN, "batl": [[0, 1.53, 75.5], [1, 1.66, 831.03], [2, 3.8, 27.43]]}, {"timestamp": 1631547644206, "ltp": 1.28, "tv": 10605.43, "trd": NaN, "batb": NaN, "batl": [[1, 3.8, 27.43], [2, 8.8, 7.22]]}, {"timestamp": 1631547645240, "ltp": 1.28, "tv": 10605.43, "trd": NaN, "batb": NaN, "batl": [[0, 1.52, 69.01], [1, 1.53, 75.5], [2, 3.8, 27.43]]}, {"timestamp": 1631547646644, "ltp": 1.28, "tv": 10605.43, "trd": NaN, "batb": [[0, 1.25, 2]], "batl": [[0, 1.47, 88.5], [1, 1.52, 69.01], [2, 1.53, 75.5]]}, {"timestamp": 1631547647847, "ltp": 1.28, "tv": 10605.43, "trd": NaN, "batb": NaN, "batl": [[0, 3.8, 27.43], [1, 8.8, 7.22], [2, 44, 7.22]]}, {"timestamp": 1631547649355, "ltp": 1.28, "tv": 10605.43, "trd": NaN, "batb": [[1, 1.2, 179.41], [2, 1.18, 2]], "batl": NaN}, {"timestamp": 1631547650659, "ltp": 1.25, "tv": 10723.42, "trd": [[1.25, 13.42], [1.28, 59.03], [1.31, 122.05]], "batb": [[0, 1.2, 831.52], [1, 1.18, 2], [2, 1.17, 109]], "batl": [[0, 1.24, 22.31], [1, 1.25, 156.9], [2, 1.26, 95.24]]}, {"timestamp": 1631547651813, "ltp": 1.25, "tv": 10723.42, "trd": NaN, "batb": [[0, 1.22, 24.6], [1, 1.21, 12.3], [2, 1.2, 852.15]], "batl": [[0, 1.25, 156.9], [1, 1.26, 95.24], [2, 1.27, 7.87]]}, {"timestamp": 1631547652652, "ltp": 1.25, "tv": 10723.42, "trd": NaN, "batb": NaN, "batl": [[0, 1.24, 231], [1, 1.25, 156.9], [2, 1.26, 95.24]]}, {"timestamp": 1631547654791, "ltp": 1.25, "tv": 10723.42, "trd": NaN, "batb": NaN, "batl": [[0, 1.24, 253.31]]}, {"timestamp": 1631547655828, "ltp": 1.25, "tv": 10723.42, "trd": NaN, "batb": NaN, "batl": [[2, 1.26, 340.47]]}, {"timestamp": 1631547655933, "ltp": 1.25, "tv": 10723.42, "trd": NaN, "batb": NaN, "batl": [[2, 1.26, 95.24]]}, {"timestamp": 1631547669739, "ltp": 1.25, "tv": 10723.42, "trd": NaN, "batb": [[0, 1.2, 179.41], [1, 1.18, 2], [2, 1.17, 109]], "batl": [[0, 1.24, 231], [1, 1.33, 101.5], [2, 1.37, 86.5]]}, {"timestamp": 1631547670634, "ltp": 1.25, "tv": 10723.42, "trd": NaN, "batb": [[0, 1.2, 2]], "batl": [[0, 1.37, 86.5], [1, 3.8, 27.43], [2, 8.8, 7.22]]}, {"timestamp": 1631547678779, "ltp": 1.25, "tv": 10723.42, "trd": NaN, "batb": NaN, "batl": [[1, 1.58, 903.84], [2, 3.8, 27.43]]}, {"timestamp": 1631547682883, "ltp": 1.25, "tv": 10723.42, "trd": NaN, "batb": NaN, "batl": [[1, 3.8, 27.43], [2, 8.8, 7.22]]}, {"timestamp": 1631547689744, "ltp": 1.25, "tv": 10723.42, "trd": NaN, "batb": [[0, 1.29, 27.38], [1, 1.28, 11.62], [2, 1.27, 11.62]], "batl": [[0, 1.32, 20.23], [1, 1.37, 86.5], [2, 3.8, 27.43]]}, {"timestamp": 1631547690571, "ltp": 1.25, "tv": 10723.42, "trd": NaN, "batb": [[1, 1.28, 133.5]], "batl": [[1, 1.33, 22.56], [2, 1.34, 11.28]]}, {"timestamp": 1631547690988, "ltp": 1.28, "tv": 11071.98, "trd": [[1.28, 182.88], [1.29, 54.76], [1.3, 172.21]], "batb": [[0, 1.28, 50.31], [1, 1.27, 11.62], [2, 1.21, 170.95]], "batl": NaN}, {"timestamp": 1631547696084, "ltp": 1.28, "tv": 11071.98, "trd": NaN, "batb": [[2, 1.23, 5.76]], "batl": NaN}, {"timestamp": 1631547701872, "ltp": 1.28, "tv": 11071.98, "trd": NaN, "batb": [[1, 1.27, 5.81]], "batl": [[0, 1.33, 11.28], [1, 1.34, 5.64], [2, 1.35, 5.64]]}, {"timestamp": 1631547702861, "ltp": 1.28, "tv": 11071.98, "trd": NaN, "batb": [[0, 1.21, 170.95], [1, 1.2, 308.53], [2, 1.19, 103]], "batl": [[0, 1.54, 76.75], [1, 1.66, 831.03], [2, 3.8, 27.43]]}, {"timestamp": 1631547704571, "ltp": 1.28, "tv": 11071.98, "trd": NaN, "batb": NaN, "batl": [[1, 3.8, 27.43], [2, 8.8, 7.22]]}, {"timestamp": 1631547705773, "ltp": 1.28, "tv": 11071.98, "trd": NaN, "batb": [[0, 1.2, 483.17], [1, 1.19, 103], [2, 1.18, 108]], "batl": [[0, 1.48, 83.99], [1, 1.54, 76.75], [2, 3.8, 27.43]]}, {"timestamp": 1631547706399, "ltp": 1.28, "tv": 11071.98, "trd": NaN, "batb": NaN, "batl": [[0, 1.54, 76.75], [1, 3.8, 27.43], [2, 8.8, 7.22]]}, {"timestamp": 1631547712897, "ltp": 1.28, "tv": 11071.98, "trd": NaN, "batb": NaN, "batl": [[0, 1.48, 75.99]]}, {"timestamp": 1631547713510, "ltp": 1.28, "tv": 11071.98, "trd": NaN, "batb": NaN, "batl": [[0, 3.8, 27.43], [1, 8.8, 7.22], [2, 44, 7.22]]}, {"timestamp": 1631547714497, "ltp": 1.28, "tv": 11071.98, "trd": NaN, "batb": [[0, 1.2, 282.41], [1, 1.18, 108], [2, 1.17, 109]], "batl": NaN}, {"timestamp": 1631547715721, "ltp": 1.28, "tv": 11071.98, "trd": NaN, "batb": [[0, 1.21, 919.7], [1, 1.2, 282.41], [2, 1.18, 108]], "batl": [[0, 1.24, 21.91], [1, 1.25, 317.02], [2, 1.27, 7.87]]}, {"timestamp": 1631547716590, "ltp": 1.28, "tv": 11071.98, "trd": NaN, "batb": [[0, 1.21, 927.96]], "batl": NaN}, {"timestamp": 1631547717303, "ltp": 1.28, "tv": 11071.98, "trd": NaN, "batb": NaN, "batl": [[0, 1.23, 2], [1, 1.24, 21.91], [2, 1.25, 317.02]]}, {"timestamp": 1631547724903, "ltp": 1.28, "tv": 11071.98, "trd": NaN, "batb": [[0, 1.2, 107.77], [1, 1.18, 108], [2, 1.17, 109]], "batl": [[1, 1.34, 97.25], [2, 1.38, 88.75]]}, {"timestamp": 1631547725726, "ltp": 1.28, "tv": 11071.98, "trd": NaN, "batb": [[0, 1.2, 2]], "batl": [[0, 1.38, 88.75], [1, 3.8, 27.43], [2, 8.8, 7.22]]}, {"timestamp": 1631547731721, "ltp": 1.28, "tv": 11071.98, "trd": NaN, "batb": NaN, "batl": [[0, 1.34, 88.75], [1, 1.38, 88.75], [2, 3.8, 27.43]]}, {"timestamp": 1631547731923, "ltp": 1.28, "tv": 11071.98, "trd": NaN, "batb": NaN, "batl": [[0, 1.38, 88.75], [1, 3.8, 27.43], [2, 8.8, 7.22]]}, {"timestamp": 1631547737808, "ltp": 1.28, "tv": 11071.98, "trd": NaN, "batb": [[2, 1.16, 333.94]], "batl": NaN}, {"timestamp": 1631547738833, "ltp": 1.2, "tv": 11119.77, "trd": [[1.2, 50.72], [1.24, 45.79]], "batb": [[0, 1.18, 108], [1, 1.16, 333.94], [2, 1.15, 103.43]], "batl": [[0, 1.2, 8.97], [1, 1.21, 3356.53], [2, 1.23, 8.13]]}, {"timestamp": 1631547739827, "ltp": 1.2, "tv": 11119.77, "trd": NaN, "batb": [[1, 1.17, 8.55], [2, 1.16, 333.94]], "batl": [[1, 1.21, 149.5]]}, {"timestamp": 1631547740606, "ltp": 1.2, "tv": 11119.77, "trd": NaN, "batb": NaN, "batl": [[0, 1.19, 91], [1, 1.2, 109.97], [2, 1.21, 149.5]]}, {"timestamp": 1631547745420, "ltp": 1.2, "tv": 11119.77, "trd": NaN, "batb": [[2, 1.16, 341.72]], "batl": NaN}, {"timestamp": 1631547749035, "ltp": 1.2, "tv": 11119.77, "trd": NaN, "batb": NaN, "batl": [[1, 1.2, 101]]}, {"timestamp": 1631547752046, "ltp": 1.19, "tv": 11156.69, "trd": [[1.19, 812.25]], "batb": NaN, "batl": [[0, 1.19, 72.54], [1, 1.2, 110.97]]}, {"timestamp": 1631547753825, "ltp": 1.19, "tv": 11164.26, "trd": [[1.19, 819.82]], "batb": NaN, "batl": [[0, 1.19, 64.97]]}, {"timestamp": 1631547756733, "ltp": 1.19, "tv": 11164.26, "trd": NaN, "batb": [[1, 1.16, 120.78], [2, 1.15, 112.06]], "batl": [[1, 1.2, 101], [2, 1.24, 108.98]]}, {"timestamp": 1631547757246, "ltp": 1.19, "tv": 11164.26, "trd": NaN, "batb": [[0, 1.18, 2], [1, 1.16, 113]], "batl": [[0, 1.26, 109.25], [1, 1.53, 963.96], [2, 3.8, 27.43]]}, {"timestamp": 1631547758235, "ltp": 1.19, "tv": 11164.26, "trd": NaN, "batb": NaN, "batl": [[1, 3.8, 27.43], [2, 8.8, 7.22]]}, {"timestamp": 1631547766755, "ltp": 1.19, "tv": 11164.26, "trd": NaN, "batb": [[2, 1.15, 103.43]], "batl": NaN}, {"timestamp": 1631547768845, "ltp": 1.18, "tv": 11168.26, "trd": [[1.18, 271.01]], "batb": [[0, 1.16, 113], [1, 1.15, 103.43], [2, 1.14, 121]], "batl": [[0, 1.18, 3664.96], [1, 1.19, 1056.08], [2, 1.2, 166.66]]}, {"timestamp": 1631547769831, "ltp": 1.18, "tv": 11168.26, "trd": NaN, "batb": [[1, 1.15, 112.13], [2, 1.14, 172.83]], "batl": [[0, 1.19, 1056.08], [1, 1.2, 166.66], [2, 1.21, 8.26]]}, {"timestamp": 1631547770762, "ltp": 1.18, "tv": 11168.26, "trd": NaN, "batb": [[1, 1.15, 8.7]], "batl": NaN}, {"timestamp": 1631547773879, "ltp": 1.18, "tv": 11188.26, "trd": [[1.18, 291.01]], "batb": NaN, "batl": [[0, 1.18, 107], [1, 1.19, 1423.06], [2, 1.2, 268.66]]}, {"timestamp": 1631547774659, "ltp": 1.18, "tv": 11188.26, "trd": NaN, "batb": NaN, "batl": [[1, 1.19, 1149.08]]}, {"timestamp": 1631547780655, "ltp": 1.16, "tv": 11196.06, "trd": [[1.16, 262.28]], "batb": [[0, 1.16, 109.1]], "batl": NaN}, {"timestamp": 1631547784765, "ltp": 1.16, "tv": 11244.6, "trd": [[1.16, 310.82]], "batb": [[0, 1.16, 84.83]], "batl": NaN}, {"timestamp": 1631547786497, "ltp": 1.16, "tv": 11244.6, "trd": NaN, "batb": NaN, "batl": [[0, 1.18, 142.63]]}, {"timestamp": 1631547793308, "ltp": 1.16, "tv": 11244.6, "trd": NaN, "batb": [[0, 1.17, 14.44], [1, 1.16, 84.83], [2, 1.15, 8.7]], "batl": [[0, 1.18, 107]]}, {"timestamp": 1631547795971, "ltp": 1.16, "tv": 11244.6, "trd": NaN, "batb": NaN, "batl": [[0, 1.18, 142.63]]}, {"timestamp": 1631547832633, "ltp": 1.18, "tv": 11251.66, "trd": [[1.18, 298.07]], "batb": NaN, "batl": [[0, 1.18, 139.1]]}, {"timestamp": 1631547856512, "ltp": 1.17, "tv": 11251.82, "trd": [[1.17, 431.29]], "batb": [[0, 1.17, 14.36]], "batl": NaN}, {"timestamp": 1631547882191, "ltp": 1.17, "tv": 11264.82, "trd": [[1.17, 444.29]], "batb": [[0, 1.17, 7.86]], "batl": NaN}, {"timestamp": 1631547890727, "ltp": 1.17, "tv": 11264.82, "trd": NaN, "batb": [[2, 1.14, 121]], "batl": [[0, 1.18, 103.47], [1, 1.19, 93], [2, 1.2, 102]]}, {"timestamp": 1631547901947, "ltp": 1.18, "tv": 11267.59, "trd": [[1.18, 300.85]], "batb": NaN, "batl": [[0, 1.18, 102.08]]}, {"timestamp": 1631547910146, "ltp": 1.18, "tv": 11267.59, "trd": NaN, "batb": NaN, "batl": [[0, 1.2, 102], [1, 1.39, 17.9], [2, 1.49, 489.22]]}, {"timestamp": 1631547911409, "ltp": 1.18, "tv": 11267.59, "trd": NaN, "batb": [[0, 1.17, 16.41], [1, 1.16, 135.77]], "batl": [[0, 1.2, 117.99], [1, 1.21, 933.35], [2, 1.25, 47.27]]}, {"timestamp": 1631547912730, "ltp": 1.18, "tv": 11267.59, "trd": NaN, "batb": [[2, 1.15, 233.19]], "batl": [[2, 1.23, 8.13]]}, {"timestamp": 1631547913621, "ltp": 1.18, "tv": 11267.59, "trd": NaN, "batb": [[0, 1.18, 106], [1, 1.17, 16.41], [2, 1.16, 135.77]], "batl": NaN}, {"timestamp": 1631547917829, "ltp": 1.18, "tv": 11267.59, "trd": NaN, "batb": [[2, 1.16, 288.05]], "batl": [[1, 1.21, 1051.85], [2, 1.22, 129.75]]}, {"timestamp": 1631547917933, "ltp": 1.18, "tv": 11267.59, "trd": NaN, "batb": [[2, 1.16, 295.58]], "batl": NaN}, {"timestamp": 1631547924763, "ltp": 1.18, "tv": 11267.59, "trd": NaN, "batb": [[1, 1.17, 7.86]], "batl": [[0, 1.2, 102], [1, 1.21, 118.5]]}, {"timestamp": 1631547925711, "ltp": 1.18, "tv": 11267.59, "trd": NaN, "batb": [[0, 1.17, 7.86], [1, 1.16, 84.83], [2, 1.15, 307.86]], "batl": [[0, 1.22, 129.75], [1, 1.39, 17.9], [2, 1.49, 489.22]]}, {"timestamp": 1631547928895, "ltp": 1.18, "tv": 11267.59, "trd": NaN, "batb": [[1, 1.16, 255.89]], "batl": [[0, 1.21, 119.5], [1, 1.22, 129.75], [2, 1.39, 17.9]]}, {"timestamp": 1631547929310, "ltp": 1.18, "tv": 11267.59, "trd": NaN, "batb": [[1, 1.16, 84.83]], "batl": [[0, 1.22, 129.75], [1, 1.39, 17.9], [2, 1.49, 489.22]]}, {"timestamp": 1631547935909, "ltp": 1.18, "tv": 11267.59, "trd": NaN, "batb": [[1, 1.16, 242.61]], "batl": [[0, 1.21, 120.5], [1, 1.22, 129.75], [2, 1.39, 17.9]]}, {"timestamp": 1631547936386, "ltp": 1.18, "tv": 11267.59, "trd": NaN, "batb": [[1, 1.16, 84.83]], "batl": [[0, 1.22, 129.75], [1, 1.39, 17.9], [2, 1.49, 489.22]]}, {"timestamp": 1631547937909, "ltp": 1.18, "tv": 11267.59, "trd": NaN, "batb": [[0, 1.2, 22.65], [1, 1.19, 100.84], [2, 1.18, 8.47]], "batl": [[0, 1.22, 166.05], [1, 1.23, 983.09], [2, 1.27, 46.53]]}, {"timestamp": 1631547938801, "ltp": 1.18, "tv": 11267.59, "trd": NaN, "batb": NaN, "batl": [[1, 1.23, 1007.49], [2, 1.24, 12.2]]}, {"timestamp": 1631547939809, "ltp": 1.18, "tv": 11267.59, "trd": NaN, "batb": [[1, 1.19, 203.84], [2, 1.18, 114.47]], "batl": [[0, 1.22, 168.05]]}, {"timestamp": 1631547944205, "ltp": 1.18, "tv": 11267.59, "trd": NaN, "batb": [[2, 1.18, 281.69]], "batl": [[1, 1.23, 1136.99]]}, {"timestamp": 1631547948201, "ltp": 1.22, "tv": 11435.64, "trd": [[1.22, 172.05]], "batb": NaN, "batl": [[0, 1.23, 1136.99], [1, 1.24, 12.2], [2, 1.25, 20.2]]}, {"timestamp": 1631547949725, "ltp": 1.22, "tv": 11435.64, "trd": NaN, "batb": [[0, 1.2, 5.62], [1, 1.19, 103], [2, 1.18, 273.22]], "batl": [[0, 1.23, 129.5], [1, 1.27, 46.53], [2, 1.49, 489.22]]}, {"timestamp": 1631547950621, "ltp": 1.22, "tv": 11435.64, "trd": NaN, "batb": [[1, 1.18, 273.22], [2, 1.17, 254.8]], "batl": [[0, 1.49, 489.22], [1, 3.8, 27.43], [2, 8.8, 7.22]]}, {"timestamp": 1631547951613, "ltp": 1.22, "tv": 11435.64, "trd": NaN, "batb": [[1, 1.18, 106]], "batl": [[0, 1.24, 112.73], [1, 1.25, 102.98], [2, 1.49, 489.22]]}, {"timestamp": 1631547952092, "ltp": 1.22, "tv": 11435.64, "trd": NaN, "batb": NaN, "batl": [[0, 1.25, 102.98], [1, 1.49, 489.22], [2, 3.8, 27.43]]}, {"timestamp": 1631547953191, "ltp": 1.22, "tv": 11471.34, "trd": [[1.22, 207.75]], "batb": NaN, "batl": [[0, 1.23, 122.5], [1, 1.25, 102.98], [2, 1.49, 489.22]]}, {"timestamp": 1631547961824, "ltp": 1.22, "tv": 11471.34, "trd": NaN, "batb": [[1, 1.18, 113.47]], "batl": NaN}, {"timestamp": 1631547962147, "ltp": 1.22, "tv": 11471.34, "trd": NaN, "batb": [[1, 1.18, 106]], "batl": NaN}, {"timestamp": 1631547965723, "ltp": 1.22, "tv": 11471.34, "trd": NaN, "batb": [[0, 1.18, 106], [1, 1.17, 254.8], [2, 1.16, 269.14]], "batl": NaN}, {"timestamp": 1631547973114, "ltp": 1.23, "tv": 11473.22, "trd": [[1.23, 10.65]], "batb": NaN, "batl": [[0, 1.23, 120.62]]}, {"timestamp": 1631547976857, "ltp": 1.23, "tv": 11473.22, "trd": NaN, "batb": [[0, 1.2, 657.15], [1, 1.18, 106], [2, 1.17, 254.8]], "batl": [[1, 1.24, 713.28], [2, 1.25, 102.98]]}, {"timestamp": 1631547977857, "ltp": 1.23, "tv": 11473.22, "trd": NaN, "batb": [[1, 1.19, 240.82], [2, 1.18, 106]], "batl": NaN}, {"timestamp": 1631547978760, "ltp": 1.23, "tv": 11473.22, "trd": NaN, "batb": [[0, 1.2, 757.15], [1, 1.19, 343.82]], "batl": [[0, 1.23, 122.62]]}, {"timestamp": 1631547981762, "ltp": 1.23, "tv": 11473.22, "trd": NaN, "batb": NaN, "batl": [[2, 1.25, 367.41]]}, {"timestamp": 1631547981970, "ltp": 1.23, "tv": 11473.22, "trd": NaN, "batb": NaN, "batl": [[2, 1.25, 102.98]]}, {"timestamp": 1631547983254, "ltp": 1.23, "tv": 11473.22, "trd": NaN, "batb": [[0, 1.2, 879.32]], "batl": [[1, 1.24, 817.51]]}, {"timestamp": 1631547995655, "ltp": 1.23, "tv": 11473.22, "trd": NaN, "batb": [[0, 1.2, 222.17]], "batl": [[1, 1.24, 104.23]]}, {"timestamp": 1631547996866, "ltp": 1.23, "tv": 11473.22, "trd": NaN, "batb": [[1, 1.19, 103]], "batl": [[0, 1.24, 104.23], [1, 3.8, 27.43], [2, 8.8, 7.22]]}, {"timestamp": 1631548002849, "ltp": 1.23, "tv": 11473.22, "trd": NaN, "batb": NaN, "batl": [[0, 1.23, 117.5], [1, 1.24, 104.23], [2, 3.8, 27.43]]}, {"timestamp": 1631548003077, "ltp": 1.23, "tv": 11473.22, "trd": NaN, "batb": NaN, "batl": [[0, 1.24, 104.23], [1, 3.8, 27.43], [2, 8.8, 7.22]]}, {"timestamp": 1631548009795, "ltp": 1.23, "tv": 11473.22, "trd": NaN, "batb": NaN, "batl": [[0, 1.23, 62.4], [1, 1.24, 124.49], [2, 1.25, 172.2]]}, {"timestamp": 1631548010796, "ltp": 1.23, "tv": 11473.22, "trd": NaN, "batb": [[1, 1.19, 128.2], [2, 1.18, 127.07]], "batl": NaN}, {"timestamp": 1631548011483, "ltp": 1.23, "tv": 11473.22, "trd": NaN, "batb": NaN, "batl": [[0, 1.23, 64.4]]}, {"timestamp": 1631548016402, "ltp": 1.23, "tv": 11473.22, "trd": NaN, "batb": [[1, 1.19, 278.91]], "batl": NaN}, {"timestamp": 1631548017804, "ltp": 1.23, "tv": 11473.22, "trd": NaN, "batb": NaN, "batl": [[0, 1.23, 146.4]]}, {"timestamp": 1631548019581, "ltp": 1.23, "tv": 11473.22, "trd": NaN, "batb": NaN, "batl": [[0, 1.23, 256.9]]}, {"timestamp": 1631548025805, "ltp": 1.23, "tv": 11473.22, "trd": NaN, "batb": [[0, 1.2, 100], [1, 1.19, 253.71], [2, 1.18, 106]], "batl": [[0, 1.23, 84], [1, 3.8, 27.43], [2, 8.8, 7.22]]}, {"timestamp": 1631548026901, "ltp": 1.23, "tv": 11473.22, "trd": NaN, "batb": [[0, 1.19, 253.71], [1, 1.18, 106], [2, 1.17, 246.94]], "batl": [[0, 3.8, 27.43], [1, 8.8, 7.22], [2, 44, 7.22]]}, {"timestamp": 1631548028730, "ltp": 1.23, "tv": 11473.22, "trd": NaN, "batb": [[0, 1.2, 125.87], [1, 1.19, 253.71], [2, 1.18, 106]], "batl": [[0, 1.23, 112.5], [1, 1.24, 91.48], [2, 3.8, 27.43]]}, {"timestamp": 1631548028994, "ltp": 1.23, "tv": 11473.22, "trd": NaN, "batb": [[0, 1.19, 253.71], [1, 1.18, 106], [2, 1.17, 246.94]], "batl": [[0, 1.24, 91.48], [1, 3.8, 27.43], [2, 8.8, 7.22]]}, {"timestamp": 1631548032717, "ltp": 1.23, "tv": 11473.22, "trd": NaN, "batb": [[0, 1.2, 140.92], [1, 1.19, 253.71], [2, 1.18, 106]], "batl": [[0, 1.23, 106.5], [1, 1.24, 91.48], [2, 3.8, 27.43]]}, {"timestamp": 1631548033245, "ltp": 1.23, "tv": 11473.22, "trd": NaN, "batb": [[0, 1.19, 253.71], [1, 1.18, 106], [2, 1.17, 246.94]], "batl": [[0, 1.24, 91.48], [1, 3.8, 27.43], [2, 8.8, 7.22]]}, {"timestamp": 1631548039671, "ltp": 1.23, "tv": 11473.22, "trd": NaN, "batb": NaN, "batl": [[0, 1.23, 55], [1, 1.24, 91.48], [2, 3.8, 27.43]]}, {"timestamp": 1631548040257, "ltp": 1.23, "tv": 11473.22, "trd": NaN, "batb": NaN, "batl": [[0, 1.24, 91.48], [1, 3.8, 27.43], [2, 8.8, 7.22]]}, {"timestamp": 1631548052736, "ltp": 1.23, "tv": 11473.22, "trd": NaN, "batb": [[0, 1.19, 150.71], [1, 1.17, 137.94], [2, 1.16, 184.31]], "batl": NaN}, {"timestamp": 1631548053049, "ltp": 1.23, "tv": 11473.22, "trd": NaN, "batb": [[1, 1.17, 6.97], [2, 1.16, 7.28]], "batl": NaN}, {"timestamp": 1631548059276, "ltp": 1.23, "tv": 11473.22, "trd": NaN, "batb": [[0, 1.19, 174.81], [2, 1.16, 58.22]], "batl": [[0, 1.21, 1391.08], [1, 1.22, 8.2], [2, 1.24, 91.48]]}, {"timestamp": 1631548060386, "ltp": 1.23, "tv": 11473.22, "trd": NaN, "batb": [[2, 1.16, 66.84]], "batl": NaN}, {"timestamp": 1631548065791, "ltp": 1.23, "tv": 11473.22, "trd": NaN, "batb": [[1, 1.17, 172.94], [2, 1.16, 199.12]], "batl": [[2, 1.23, 113.5]]}, {"timestamp": 1631548069088, "ltp": 1.23, "tv": 11473.22, "trd": NaN, "batb": NaN, "batl": [[0, 1.21, 1455.08]]}, {"timestamp": 1631548079913, "ltp": 1.23, "tv": 11473.22, "trd": NaN, "batb": [[0, 1.12, 302.3], [1, 1.11, 694.47], [2, 1.01, 107.79]], "batl": [[0, 1.21, 64], [1, 1.23, 113.5], [2, 1.24, 91.48]]}, {"timestamp": 1631548080876, "ltp": 1.23, "tv": 11473.22, "trd": NaN, "batb": NaN, "batl": [[0, 1.23, 113.5], [1, 1.24, 91.48], [2, 3.8, 27.43]]}, {"timestamp": 1631548081189, "ltp": 1.23, "tv": 11473.22, "trd": NaN, "batb": NaN, "batl": [[0, 1.24, 91.48], [1, 3.8, 27.43], [2, 8.8, 7.22]]}, {"timestamp": 1631548082702, "ltp": 1.23, "tv": 11473.22, "trd": NaN, "batb": [[0, 1.17, 166.97], [1, 1.16, 136.53], [2, 1.12, 302.3]], "batl": NaN}, {"timestamp": 1631548082970, "ltp": 1.23, "tv": 11473.22, "trd": NaN, "batb": [[0, 1.16, 136.53], [1, 1.12, 302.3], [2, 1.11, 694.47]], "batl": NaN}, {"timestamp": 1631548084676, "ltp": 1.23, "tv": 11473.22, "trd": NaN, "batb": NaN, "batl": [[0, 1.23, 98.5], [1, 1.24, 91.48], [2, 3.8, 27.43]]}, {"timestamp": 1631548084994, "ltp": 1.23, "tv": 11473.22, "trd": NaN, "batb": NaN, "batl": [[0, 1.24, 91.48], [1, 3.8, 27.43], [2, 8.8, 7.22]]}, {"timestamp": 1631548087184, "ltp": 1.23, "tv": 11473.22, "trd": NaN, "batb": [[2, 1.01, 107.79]], "batl": NaN}, {"timestamp": 1631548088889, "ltp": 1.21, "tv": 11475.22, "trd": [[1.21, 94.33]], "batb": [[0, 1.18, 58.55], [1, 1.16, 136.53], [2, 1.12, 302.3]], "batl": [[0, 1.23, 1143.83], [1, 1.24, 91.48], [2, 1.28, 46.16]]}, {"timestamp": 1631548089789, "ltp": 1.21, "tv": 11475.22, "trd": NaN, "batb": [[1, 1.17, 212.3], [2, 1.16, 136.53]], "batl": [[2, 1.25, 8]]}, {"timestamp": 1631548091904, "ltp": 1.21, "tv": 11475.22, "trd": NaN, "batb": NaN, "batl": [[0, 1.23, 1035.33]]}, {"timestamp": 1631548092110, "ltp": 1.21, "tv": 11475.22, "trd": NaN, "batb": [[0, 1.19, 2], [1, 1.18, 58.55], [2, 1.17, 212.3]], "batl": NaN}, {"timestamp": 1631548093904, "ltp": 1.21, "tv": 11475.22, "trd": NaN, "batb": NaN, "batl": [[0, 1.23, 1117.33]]}, {"timestamp": 1631548096807, "ltp": 1.21, "tv": 11475.3, "trd": [[1.21, 94.41]], "batb": NaN, "batl": NaN}, {"timestamp": 1631548099102, "ltp": 1.21, "tv": 11475.3, "trd": NaN, "batb": NaN, "batl": [[0, 1.23, 1084.3]]}, {"timestamp": 1631548102000, "ltp": 1.21, "tv": 11475.3, "trd": NaN, "batb": NaN, "batl": [[0, 1.23, 1119.37]]}, {"timestamp": 1631548107084, "ltp": 1.21, "tv": 11475.3, "trd": NaN, "batb": NaN, "batl": [[0, 1.23, 1084.3]]}, {"timestamp": 1631548109940, "ltp": 1.21, "tv": 11475.3, "trd": NaN, "batb": NaN, "batl": [[0, 1.23, 1119.37]]}, {"timestamp": 1631548125758, "ltp": 1.21, "tv": 11475.3, "trd": NaN, "batb": [[1, 1.18, 8.47]], "batl": NaN}, {"timestamp": 1631548148991, "ltp": 1.21, "tv": 11475.3, "trd": NaN, "batb": [[0, 1.2, 123.57], [1, 1.19, 134.71], [2, 1.18, 8.47]], "batl": NaN}, {"timestamp": 1631548154887, "ltp": 1.21, "tv": 11475.3, "trd": NaN, "batb": [[2, 1.15, 235.87]], "batl": [[0, 1.29, 76.5], [1, 3.8, 27.43], [2, 8.8, 7.22]]}, {"timestamp": 1631548164718, "ltp": 1.21, "tv": 11475.3, "trd": NaN, "batb": NaN, "batl": [[0, 1.27, 91.5], [1, 1.29, 76.5], [2, 3.8, 27.43]]}, {"timestamp": 1631548164987, "ltp": 1.21, "tv": 11475.3, "trd": NaN, "batb": NaN, "batl": [[0, 1.29, 76.5], [1, 3.8, 27.43], [2, 8.8, 7.22]]}, {"timestamp": 1631548171813, "ltp": 1.21, "tv": 11475.3, "trd": NaN, "batb": NaN, "batl": [[0, 1.27, 82.5], [1, 1.29, 76.5], [2, 3.8, 27.43]]}, {"timestamp": 1631548172084, "ltp": 1.21, "tv": 11475.3, "trd": NaN, "batb": NaN, "batl": [[0, 1.29, 76.5], [1, 3.8, 27.43], [2, 8.8, 7.22]]}, {"timestamp": 1631548173809, "ltp": 1.25, "tv": 11477.3, "trd": [[1.25, 15.42]], "batb": [[0, 1.22, 8.2], [1, 1.21, 48.84], [2, 1.2, 123.57]], "batl": [[0, 1.27, 881.12], [1, 1.29, 76.5], [2, 1.32, 44.76]]}, {"timestamp": 1631548174394, "ltp": 1.25, "tv": 11477.3, "trd": NaN, "batb": [[2, 1.2, 296.53]], "batl": [[1, 1.29, 84.25]]}, {"timestamp": 1631548177912, "ltp": 1.25, "tv": 11477.3, "trd": NaN, "batb": [[1, 1.21, 50.84]], "batl": [[1, 1.28, 240.75], [2, 1.29, 84.25]]}, {"timestamp": 1631548178126, "ltp": 1.25, "tv": 11477.3, "trd": NaN, "batb": NaN, "batl": [[1, 1.29, 84.25], [2, 1.32, 44.76]]}, {"timestamp": 1631548179495, "ltp": 1.25, "tv": 11477.3, "trd": NaN, "batb": [[0, 1.22, 121.04]], "batl": [[2, 1.32, 129.62]]}, {"timestamp": 1631548180226, "ltp": 1.25, "tv": 11477.3, "trd": NaN, "batb": NaN, "batl": [[0, 1.27, 953.12]]}, {"timestamp": 1631548183812, "ltp": 1.25, "tv": 11477.3, "trd": NaN, "batb": [[0, 1.21, 2], [1, 1.2, 123.57], [2, 1.19, 134.71]], "batl": [[0, 1.34, 72.25], [1, 3.8, 27.43], [2, 8.8, 7.22]]}, {"timestamp": 1631548197733, "ltp": 1.25, "tv": 11477.3, "trd": NaN, "batb": [[0, 1.22, 105.34], [1, 1.21, 2], [2, 1.2, 123.57]], "batl": [[0, 1.32, 80.86], [1, 1.34, 72.25], [2, 3.8, 27.43]]}, {"timestamp": 1631548198839, "ltp": 1.25, "tv": 11477.3, "trd": NaN, "batb": [[0, 1.21, 2], [1, 1.2, 554.04], [2, 1.19, 134.71]], "batl": [[0, 1.24, 3211.79], [1, 1.26, 7.94], [2, 1.27, 2637.55]]}, {"timestamp": 1631548199740, "ltp": 1.25, "tv": 11477.3, "trd": NaN, "batb": [[2, 1.19, 192.77]], "batl": [[0, 1.24, 81.29]]}, {"timestamp": 1631548204853, "ltp": 1.22, "tv": 11479.01, "trd": [[1.22, 209.46]], "batb": NaN, "batl": NaN}, {"timestamp": 1631548205861, "ltp": 1.22, "tv": 11479.01, "trd": NaN, "batb": [[2, 1.19, 184.37]], "batl": [[1, 1.27, 2637.55], [2, 1.28, 82.84]]}, {"timestamp": 1631548206342, "ltp": 1.22, "tv": 11479.01, "trd": NaN, "batb": [[1, 1.2, 123.57], [2, 1.19, 134.71]], "batl": [[0, 1.3, 84.45], [1, 1.34, 72.25], [2, 3.8, 27.43]]}, {"timestamp": 1631548209797, "ltp": 1.22, "tv": 11479.01, "trd": NaN, "batb": NaN, "batl": [[0, 1.28, 75.59], [1, 1.3, 84.45], [2, 1.34, 72.25]]}, {"timestamp": 1631548210171, "ltp": 1.22, "tv": 11479.01, "trd": NaN, "batb": NaN, "batl": [[0, 1.3, 84.45], [1, 1.34, 72.25], [2, 3.8, 27.43]]}, {"timestamp": 1631548216370, "ltp": 1.22, "tv": 11479.01, "trd": NaN, "batb": [[0, 1.25, 96], [1, 1.23, 56.17], [2, 1.21, 2]], "batl": [[0, 1.29, 780.44], [1, 1.3, 84.45], [2, 1.34, 116.35]]}, {"timestamp": 1631548217479, "ltp": 1.22, "tv": 11479.01, "trd": NaN, "batb": [[2, 1.22, 158.03]], "batl": [[1, 1.3, 92.14]]}, {"timestamp": 1631548222874, "ltp": 1.22, "tv": 11479.01, "trd": NaN, "batb": [[1, 1.23, 166.8]], "batl": NaN}, {"timestamp": 1631548227382, "ltp": 1.23, "tv": 11857.51, "trd": [[1.23, 133.29], [1.25, 232.15], [1.26, 25.77], [1.27, 15.36]], "batb": [[0, 1.23, 105.48], [1, 1.22, 158.03], [2, 1.21, 121.69]], "batl": NaN}, {"timestamp": 1631548230904, "ltp": 1.23, "tv": 11857.51, "trd": NaN, "batb": [[0, 1.21, 121.69], [1, 1.2, 123.57], [2, 1.19, 324.28]], "batl": [[0, 1.36, 76.82], [1, 1.39, 60.5], [2, 3.8, 27.43]]}, {"timestamp": 1631548231280, "ltp": 1.23, "tv": 11857.51, "trd": NaN, "batb": NaN, "batl": [[0, 1.39, 60.5], [1, 3.8, 27.43], [2, 8.8, 7.22]]}, {"timestamp": 1631548233903, "ltp": 1.23, "tv": 11857.51, "trd": NaN, "batb": [[0, 1.23, 105.63], [1, 1.21, 121.69], [2, 1.2, 123.57]], "batl": NaN}, {"timestamp": 1631548234112, "ltp": 1.23, "tv": 11857.51, "trd": NaN, "batb": [[0, 1.21, 121.69], [1, 1.2, 123.57], [2, 1.19, 324.28]], "batl": NaN}, {"timestamp": 1631548239828, "ltp": 1.23, "tv": 11857.51, "trd": NaN, "batb": NaN, "batl": [[0, 1.36, 67.32], [1, 1.39, 60.5], [2, 3.8, 27.43]]}, {"timestamp": 1631548240881, "ltp": 1.23, "tv": 11857.51, "trd": NaN, "batb": [[0, 1.23, 116.63], [1, 1.21, 121.69], [2, 1.2, 123.57]], "batl": [[0, 1.39, 60.5], [1, 3.8, 27.43], [2, 8.8, 7.22]]}, {"timestamp": 1631548241672, "ltp": 1.23, "tv": 11857.51, "trd": NaN, "batb": [[0, 1.21, 121.69], [1, 1.2, 123.57], [2, 1.19, 324.28]], "batl": NaN}, {"timestamp": 1631548244661, "ltp": 1.23, "tv": 11857.51, "trd": NaN, "batb": [[1, 1.2, 662.31]], "batl": [[1, 1.66, 588.41], [2, 3.8, 27.43]]}, {"timestamp": 1631548246862, "ltp": 1.23, "tv": 11857.51, "trd": NaN, "batb": NaN, "batl": [[0, 1.36, 65.07], [1, 1.39, 60.5], [2, 1.66, 588.41]]}, {"timestamp": 1631548247904, "ltp": 1.23, "tv": 11857.51, "trd": NaN, "batb": [[0, 1.23, 106.63], [1, 1.21, 121.69], [2, 1.2, 662.31]], "batl": [[0, 1.39, 60.5], [1, 1.66, 588.41], [2, 3.8, 27.43]]}, {"timestamp": 1631548248065, "ltp": 1.23, "tv": 11857.51, "trd": NaN, "batb": [[0, 1.21, 121.69], [1, 1.2, 662.31], [2, 1.19, 324.28]], "batl": NaN}, {"timestamp": 1631548250684, "ltp": 1.23, "tv": 11857.51, "trd": NaN, "batb": [[1, 1.2, 123.57]], "batl": NaN}, {"timestamp": 1631548251682, "ltp": 1.23, "tv": 11857.51, "trd": NaN, "batb": [[0, 1.32, 90.91], [1, 1.28, 46.16], [2, 1.26, 23.45]], "batl": [[0, 1.36, 26.42], [1, 1.37, 677.23], [2, 1.39, 60.5]]}, {"timestamp": 1631548252671, "ltp": 1.33, "tv": 11859.51, "trd": [[1.33, 2]], "batb": [[1, 1.28, 166.28]], "batl": [[2, 1.38, 7.25]]}, {"timestamp": 1631548255289, "ltp": 1.33, "tv": 11859.51, "trd": NaN, "batb": [[2, 1.27, 2]], "batl": NaN}, {"timestamp": 1631548260901, "ltp": 1.36, "tv": 11861.77, "trd": [[1.36, 75.3]], "batb": [[1, 1.29, 78.81], [2, 1.28, 166.28]], "batl": [[0, 1.36, 24.16]]}, {"timestamp": 1631548262314, "ltp": 1.36, "tv": 11861.77, "trd": NaN, "batb": NaN, "batl": [[0, 1.37, 677.23], [1, 1.38, 7.25], [2, 1.39, 60.5]]}, {"timestamp": 1631548265199, "ltp": 1.36, "tv": 11861.77, "trd": NaN, "batb": NaN, "batl": [[0, 1.36, 26.13], [1, 1.37, 677.23], [2, 1.38, 7.25]]}, {"timestamp": 1631548266820, "ltp": 1.36, "tv": 11861.77, "trd": NaN, "batb": [[0, 1.27, 96.87], [1, 1.24, 142.26], [2, 1.23, 524.14]], "batl": [[0, 1.46, 56.25], [1, 1.66, 588.41], [2, 3.8, 27.43]]}, {"timestamp": 1631548267020, "ltp": 1.36, "tv": 11861.77, "trd": NaN, "batb": NaN, "batl": [[0, 1.35, 7.22], [1, 1.46, 56.25], [2, 1.66, 588.41]]}, {"timestamp": 1631548269802, "ltp": 1.36, "tv": 11861.77, "trd": NaN, "batb": [[0, 1.29, 82.81], [1, 1.27, 96.87], [2, 1.24, 142.26]], "batl": [[1, 1.43, 64.5], [2, 1.46, 56.25]]}, {"timestamp": 1631548270009, "ltp": 1.36, "tv": 11861.77, "trd": NaN, "batb": [[0, 1.27, 96.87], [1, 1.24, 142.26], [2, 1.23, 524.14]], "batl": [[0, 1.46, 56.25], [1, 1.66, 588.41], [2, 3.8, 27.43]]}, {"timestamp": 1631548276727, "ltp": 1.36, "tv": 11861.77, "trd": NaN, "batb": [[0, 1.29, 80.81], [1, 1.27, 96.87], [2, 1.24, 142.26]], "batl": [[0, 1.43, 59.5], [1, 1.46, 56.25], [2, 1.66, 588.41]]}, {"timestamp": 1631548277303, "ltp": 1.36, "tv": 11861.77, "trd": NaN, "batb": [[0, 1.27, 96.87], [1, 1.24, 142.26], [2, 1.23, 524.14]], "batl": [[0, 1.46, 56.25], [1, 1.66, 588.41], [2, 3.8, 27.43]]}, {"timestamp": 1631548279154, "ltp": 1.36, "tv": 11861.77, "trd": NaN, "batb": [[2, 1.21, 121.69]], "batl": [[1, 3.8, 27.43], [2, 8.8, 7.22]]}, {"timestamp": 1631548280626, "ltp": 1.43, "tv": 11887.67, "trd": [[1.43, 645.44]], "batb": [[0, 1.41, 63.83], [1, 1.4, 117.63], [2, 1.39, 31.91]], "batl": [[0, 1.45, 14.34], [1, 1.46, 56.25], [2, 1.47, 627.93]]}, {"timestamp": 1631548281530, "ltp": 1.43, "tv": 11887.67, "trd": NaN, "batb": NaN, "batl": [[1, 1.46, 83.64], [2, 1.47, 638.21]]}, {"timestamp": 1631548288724, "ltp": 1.43, "tv": 11887.67, "trd": NaN, "batb": NaN, "batl": [[0, 1.45, 65.24]]}, {"timestamp": 1631548290760, "ltp": 1.43, "tv": 11887.67, "trd": NaN, "batb": NaN, "batl": [[0, 1.45, 50.9], [2, 1.47, 692.71]]}, {"timestamp": 1631548292264, "ltp": 1.47, "tv": 12974.57, "trd": [[1.45, 1219.43], [1.46, 304.8], [1.47, 775.41]], "batb": NaN, "batl": [[0, 1.47, 320.16], [1, 1.48, 50.21], [2, 1.5, 19.7]]}, {"timestamp": 1631548293363, "ltp": 1.47, "tv": 12974.57, "trd": NaN, "batb": [[0, 1.42, 14.51], [1, 1.41, 63.83], [2, 1.4, 117.63]], "batl": [[0, 1.44, 13.86], [1, 1.47, 320.16], [2, 1.48, 50.21]]}, {"timestamp": 1631548295639, "ltp": 1.47, "tv": 12974.57, "trd": NaN, "batb": NaN, "batl": [[1, 1.46, 56.75], [2, 1.47, 320.16]]}, {"timestamp": 1631548298871, "ltp": 1.47, "tv": 12974.57, "trd": NaN, "batb": NaN, "batl": [[0, 1.44, 110.86]]}, {"timestamp": 1631548299360, "ltp": 1.44, "tv": 12976.13, "trd": [[1.44, 206.26]], "batb": NaN, "batl": [[0, 1.44, 110.08]]}, {"timestamp": 1631548307649, "ltp": 1.44, "tv": 12976.15, "trd": [[1.44, 206.28]], "batb": NaN, "batl": [[0, 1.44, 110.07]]}, {"timestamp": 1631548309510, "ltp": 1.44, "tv": 12976.15, "trd": NaN, "batb": [[0, 1.41, 63.83], [1, 1.4, 117.63], [2, 1.39, 31.91]], "batl": [[0, 1.44, 97]]}, {"timestamp": 1631548310709, "ltp": 1.44, "tv": 12976.15, "trd": NaN, "batb": [[0, 1.31, 559.38], [1, 1.3, 110.13], [2, 1.29, 79.81]], "batl": [[1, 1.89, 441.74], [2, 3.8, 27.43]]}, {"timestamp": 1631548310918, "ltp": 1.44, "tv": 12976.15, "trd": NaN, "batb": NaN, "batl": [[0, 1.89, 441.74], [1, 3.8, 27.43], [2, 8.8, 7.22]]}, {"timestamp": 1631548313823, "ltp": 1.44, "tv": 12976.15, "trd": NaN, "batb": [[0, 1.31, 666.75]], "batl": [[0, 1.47, 53.5], [1, 1.48, 46.74], [2, 1.89, 441.74]]}, {"timestamp": 1631548314135, "ltp": 1.44, "tv": 12976.15, "trd": NaN, "batb": [[1, 1.29, 79.81], [2, 1.27, 96.87]], "batl": NaN}, {"timestamp": 1631548321837, "ltp": 1.44, "tv": 12976.15, "trd": NaN, "batb": [[0, 1.34, 75.22], [1, 1.31, 666.75], [2, 1.29, 79.81]], "batl": NaN}, {"timestamp": 1631548322358, "ltp": 1.44, "tv": 12976.15, "trd": NaN, "batb": [[0, 1.31, 666.75], [1, 1.29, 79.81], [2, 1.27, 96.87]], "batl": NaN}, {"timestamp": 1631548330836, "ltp": 1.44, "tv": 12976.15, "trd": NaN, "batb": NaN, "batl": [[0, 1.46, 56.75], [1, 1.47, 53.5], [2, 1.48, 46.74]]}, {"timestamp": 1631548331150, "ltp": 1.44, "tv": 12976.15, "trd": NaN, "batb": NaN, "batl": [[0, 1.47, 53.5], [1, 1.48, 46.74], [2, 1.89, 441.74]]}, {"timestamp": 1631548335898, "ltp": 1.44, "tv": 12976.15, "trd": NaN, "batb": [[0, 1.34, 75.72], [1, 1.31, 666.75], [2, 1.29, 79.81]], "batl": NaN}, {"timestamp": 1631548336164, "ltp": 1.44, "tv": 12976.15, "trd": NaN, "batb": [[0, 1.31, 666.75], [1, 1.29, 79.81], [2, 1.27, 96.87]], "batl": NaN}, {"timestamp": 1631548337877, "ltp": 1.44, "tv": 12976.15, "trd": NaN, "batb": NaN, "batl": [[0, 1.46, 55.25], [1, 1.47, 53.5], [2, 1.48, 46.74]]}, {"timestamp": 1631548338186, "ltp": 1.44, "tv": 12976.15, "trd": NaN, "batb": NaN, "batl": [[0, 1.47, 53.5], [1, 1.48, 46.74], [2, 1.89, 441.74]]}, {"timestamp": 1631548344576, "ltp": 1.44, "tv": 12976.15, "trd": NaN, "batb": [[0, 1.31, 182.16], [1, 1.3, 45.45], [2, 1.29, 79.81]], "batl": [[0, 1.38, 15.43], [1, 1.39, 21.58], [2, 1.4, 10.8]]}, {"timestamp": 1631548345565, "ltp": 1.44, "tv": 12976.15, "trd": NaN, "batb": [[0, 1.34, 22.38], [1, 1.33, 11.2], [2, 1.32, 11.2]], "batl": NaN}, {"timestamp": 1631548352458, "ltp": 1.44, "tv": 12976.15, "trd": NaN, "batb": NaN, "batl": [[0, 1.38, 136.43]]}, {"timestamp": 1631548360871, "ltp": 1.44, "tv": 12976.15, "trd": NaN, "batb": [[0, 1.31, 182.16], [1, 1.3, 128.13], [2, 1.29, 79.81]], "batl": [[0, 1.38, 121], [1, 1.41, 70.5], [2, 1.42, 41.61]]}, {"timestamp": 1631548361494, "ltp": 1.44, "tv": 12976.15, "trd": NaN, "batb": [[0, 1.27, 96.87], [1, 1.26, 132.87], [2, 1.25, 512.59]], "batl": [[0, 1.43, 54.5], [1, 1.77, 508.04], [2, 3.8, 27.43]]}, {"timestamp": 1631548364885, "ltp": 1.44, "tv": 12976.15, "trd": NaN, "batb": NaN, "batl": [[0, 1.41, 67.5], [1, 1.43, 54.5], [2, 1.77, 508.04]]}, {"timestamp": 1631548365720, "ltp": 1.44, "tv": 12976.15, "trd": NaN, "batb": NaN, "batl": [[0, 1.43, 54.5], [1, 1.77, 508.04], [2, 3.8, 27.43]]}, {"timestamp": 1631548366395, "ltp": 1.44, "tv": 12976.15, "trd": NaN, "batb": [[2, 1.21, 121.69]], "batl": NaN}, {"timestamp": 1631548368319, "ltp": 1.44, "tv": 12976.15, "trd": NaN, "batb": [[0, 1.41, 141.84], [1, 1.4, 301.35], [2, 1.39, 27.91]], "batl": [[1, 1.46, 491.49], [2, 1.47, 40.2]]}, {"timestamp": 1631548369472, "ltp": 1.44, "tv": 12976.15, "trd": NaN, "batb": NaN, "batl": [[1, 1.45, 6.9], [2, 1.46, 491.49]]}, {"timestamp": 1631548375655, "ltp": 1.44, "tv": 12976.15, "trd": NaN, "batb": NaN, "batl": [[2, 1.46, 549.74]]}, {"timestamp": 1631548378710, "ltp": 1.41, "tv": 12996.15, "trd": [[1.41, 108.99]], "batb": [[0, 1.41, 131.84]], "batl": NaN}, {"timestamp": 1631548380857, "ltp": 1.41, "tv": 12996.15, "trd": NaN, "batb": [[0, 1.29, 115.17], [1, 1.28, 493.1], [2, 1.27, 96.87]], "batl": [[0, 1.77, 508.04], [1, 3.8, 27.43], [2, 8.8, 7.22]]}, {"timestamp": 1631548384252, "ltp": 1.41, "tv": 12996.15, "trd": NaN, "batb": [[0, 1.31, 74.79], [1, 1.29, 115.17], [2, 1.28, 493.1]], "batl": [[0, 1.48, 52.99], [1, 1.77, 508.04], [2, 3.8, 27.43]]}, {"timestamp": 1631548388736, "ltp": 1.41, "tv": 12996.15, "trd": NaN, "batb": [[2, 1.27, 96.87]], "batl": NaN}, {"timestamp": 1631548389838, "ltp": 1.41, "tv": 12996.15, "trd": NaN, "batb": [[0, 1.45, 470.56], [1, 1.44, 104.16], [2, 1.43, 79.51]], "batl": NaN}, {"timestamp": 1631548390773, "ltp": 1.41, "tv": 12996.15, "trd": NaN, "batb": [[1, 1.44, 20.84], [2, 1.43, 37.85]], "batl": [[1, 1.49, 6.71], [2, 1.52, 38.88]]}, {"timestamp": 1631548394735, "ltp": 1.41, "tv": 12996.15, "trd": NaN, "batb": NaN, "batl": [[0, 1.46, 144.45], [1, 1.48, 52.99], [2, 1.49, 6.71]]}, {"timestamp": 1631548394942, "ltp": 1.41, "tv": 12996.15, "trd": NaN, "batb": NaN, "batl": [[0, 1.48, 52.99], [1, 1.49, 6.71], [2, 1.52, 38.88]]}, {"timestamp": 1631548396448, "ltp": 1.41, "tv": 12996.15, "trd": NaN, "batb": NaN, "batl": [[2, 1.5, 54.01]]}, {"timestamp": 1631548404558, "ltp": 1.41, "tv": 12996.15, "trd": NaN, "batb": [[0, 1.38, 71.96], [1, 1.34, 98.31], [2, 1.31, 559.38]], "batl": [[0, 1.48, 88], [1, 1.52, 46.76], [2, 1.77, 508.04]]}, {"timestamp": 1631548404972, "ltp": 1.41, "tv": 12996.15, "trd": NaN, "batb": NaN, "batl": [[0, 1.52, 46.76], [1, 1.77, 508.04], [2, 3.8, 27.43]]}, {"timestamp": 1631548414814, "ltp": 1.41, "tv": 12996.15, "trd": NaN, "batb": [[0, 1.4, 71.61], [1, 1.38, 71.96], [2, 1.34, 98.31]], "batl": [[0, 1.5, 46.63], [1, 1.52, 46.76], [2, 1.77, 508.04]]}, {"timestamp": 1631548415072, "ltp": 1.41, "tv": 12996.15, "trd": NaN, "batb": [[0, 1.38, 71.96], [1, 1.34, 98.31], [2, 1.31, 559.38]], "batl": [[0, 1.52, 46.76], [1, 1.77, 508.04], [2, 3.8, 27.43]]}, {"timestamp": 1631548417313, "ltp": 1.41, "tv": 12996.15, "trd": NaN, "batb": [[2, 1.27, 2]], "batl": [[1, 3.8, 27.43], [2, 8.8, 7.22]]}, {"timestamp": 1631548418823, "ltp": 1.41, "tv": 12996.15, "trd": NaN, "batb": [[0, 1.5, 8.36], [1, 1.48, 236.5], [2, 1.47, 77.35]], "batl": [[1, 1.56, 472.62], [2, 3.8, 27.43]]}, {"timestamp": 1631548419809, "ltp": 1.41, "tv": 12996.15, "trd": NaN, "batb": [[1, 1.48, 141.9], [2, 1.47, 57.08]], "batl": [[1, 1.53, 6.54], [2, 1.54, 97.4]]}, {"timestamp": 1631548420484, "ltp": 1.41, "tv": 12996.15, "trd": NaN, "batb": [[1, 1.48, 101.36], [2, 1.47, 36.81]], "batl": [[2, 1.54, 19.48]]}, {"timestamp": 1631548423826, "ltp": 1.5, "tv": 13021.23, "trd": [[1.5, 47.47]], "batb": [[0, 1.48, 101.36], [1, 1.47, 36.81], [2, 1.46, 10.14]], "batl": [[0, 1.5, 120.84], [1, 1.52, 46.76], [2, 1.53, 6.54]]}, {"timestamp": 1631548423985, "ltp": 1.5, "tv": 13021.23, "trd": NaN, "batb": NaN, "batl": [[0, 1.52, 46.76], [1, 1.53, 6.54], [2, 1.54, 19.48]]}, {"timestamp": 1631548426493, "ltp": 1.5, "tv": 13021.23, "trd": NaN, "batb": [[2, 1.46, 62.02]], "batl": [[1, 1.53, 61.04], [2, 1.54, 72.73]]}, {"timestamp": 1631548427226, "ltp": 1.5, "tv": 13021.23, "trd": NaN, "batb": NaN, "batl": [[0, 1.51, 49.5], [1, 1.52, 46.76], [2, 1.53, 61.04]]}, {"timestamp": 1631548438844, "ltp": 1.5, "tv": 13021.23, "trd": NaN, "batb": [[0, 1.44, 52.17], [1, 1.39, 82.62], [2, 1.34, 472.33]], "batl": [[0, 1.95, 415.94], [1, 3.8, 27.43], [2, 8.8, 7.22]]}, {"timestamp": 1631548441858, "ltp": 1.52, "tv": 13070.24, "trd": [[1.52, 3249.48]], "batb": [[0, 1.46, 51.88], [1, 1.44, 52.17], [2, 1.39, 82.62]], "batl": [[0, 1.53, 50.5], [1, 1.95, 415.94], [2, 3.8, 27.43]]}, {"timestamp": 1631548447441, "ltp": 1.52, "tv": 13070.24, "trd": NaN, "batb": [[0, 1.5, 59.6], [1, 1.49, 80.53], [2, 1.46, 51.88]], "batl": [[1, 1.54, 12.37], [2, 1.59, 37.16]]}, {"timestamp": 1631548448438, "ltp": 1.52, "tv": 13070.24, "trd": NaN, "batb": [[2, 1.48, 63.58]], "batl": [[2, 1.56, 6.41]]}, {"timestamp": 1631548455675, "ltp": 1.52, "tv": 13076.89, "trd": [[1.52, 3256.13]], "batb": NaN, "batl": NaN}, {"timestamp": 1631548477860, "ltp": 1.51, "tv": 13083.93, "trd": [[1.51, 645.72]], "batb": NaN, "batl": NaN}, {"timestamp": 1631548484995, "ltp": 1.53, "tv": 13134.43, "trd": [[1.53, 50.5]], "batb": NaN, "batl": [[0, 1.54, 12.37], [1, 1.56, 6.41], [2, 1.59, 37.16]]}, {"timestamp": 1631548488087, "ltp": 1.53, "tv": 13134.43, "trd": NaN, "batb": NaN, "batl": [[0, 1.56, 6.41], [1, 1.59, 37.16], [2, 1.6, 639.25]]}, {"timestamp": 1631548494190, "ltp": 1.53, "tv": 13134.43, "trd": NaN, "batb": NaN, "batl": [[0, 1.56, 199.41]]}, {"timestamp": 1631548496378, "ltp": 1.53, "tv": 13134.43, "trd": NaN, "batb": NaN, "batl": [[0, 1.56, 6.41]]}, {"timestamp": 1631548499184, "ltp": 1.56, "tv": 13140.84, "trd": [[1.56, 38.72]], "batb": NaN, "batl": [[0, 1.59, 37.16], [1, 1.6, 639.25], [2, 1.61, 18.35]]}, {"timestamp": 1631548502396, "ltp": 1.56, "tv": 13161.63, "trd": [[1.56, 59.51]], "batb": NaN, "batl": NaN}, {"timestamp": 1631548504438, "ltp": 1.56, "tv": 13161.63, "trd": NaN, "batb": NaN, "batl": [[0, 1.57, 219], [1, 1.59, 37.16], [2, 1.6, 639.25]]}, {"timestamp": 1631548514316, "ltp": 1.56, "tv": 13161.63, "trd": NaN, "batb": NaN, "batl": [[0, 1.59, 37.16], [1, 1.6, 639.25], [2, 1.61, 18.35]]}, {"timestamp": 1631548517226, "ltp": 1.56, "tv": 13178.08, "trd": [[1.56, 75.96]], "batb": NaN, "batl": NaN}, {"timestamp": 1631548519951, "ltp": 1.56, "tv": 13178.08, "trd": NaN, "batb": NaN, "batl": [[0, 1.58, 226], [1, 1.59, 37.16], [2, 1.6, 639.25]]}, {"timestamp": 1631548527428, "ltp": 1.56, "tv": 13178.08, "trd": NaN, "batb": NaN, "batl": [[0, 1.59, 37.16], [1, 1.6, 639.25], [2, 1.61, 18.35]]}, {"timestamp": 1631548530340, "ltp": 1.56, "tv": 13178.08, "trd": NaN, "batb": NaN, "batl": [[0, 1.58, 18.9], [1, 1.59, 37.16], [2, 1.6, 639.25]]}, {"timestamp": 1631548532449, "ltp": 1.58, "tv": 13178.24, "trd": [[1.58, 4.16]], "batb": NaN, "batl": [[0, 1.58, 18.82]]}, {"timestamp": 1631548534375, "ltp": 1.58, "tv": 13178.24, "trd": NaN, "batb": NaN, "batl": [[1, 1.6, 639.25], [2, 1.95, 415.94]]}, {"timestamp": 1631548535833, "ltp": 1.58, "tv": 13178.24, "trd": NaN, "batb": NaN, "batl": [[0, 1.58, 203.82]]}, {"timestamp": 1631548538859, "ltp": 1.58, "tv": 13178.24, "trd": NaN, "batb": [[2, 1.48, 146.34]], "batl": [[2, 1.62, 39.25]]}, {"timestamp": 1631548542859, "ltp": 1.58, "tv": 13178.24, "trd": NaN, "batb": [[1, 1.48, 146.34], [2, 1.46, 51.88]], "batl": [[0, 1.58, 185], [1, 1.62, 39.25], [2, 1.64, 44.18]]}, {"timestamp": 1631548543854, "ltp": 1.58, "tv": 13178.24, "trd": NaN, "batb": [[0, 1.48, 82.76], [1, 1.45, 147.68], [2, 1.38, 455.1]], "batl": [[0, 1.62, 39.25], [1, 1.64, 44.18], [2, 1.95, 415.94]]}, {"timestamp": 1631548544892, "ltp": 1.58, "tv": 13178.24, "trd": NaN, "batb": NaN, "batl": [[0, 1.64, 44.18], [1, 1.95, 415.94], [2, 3.8, 27.43]]}, {"timestamp": 1631548545779, "ltp": 1.58, "tv": 13178.24, "trd": NaN, "batb": [[0, 1.45, 147.68], [1, 1.38, 455.1], [2, 1.27, 2]], "batl": NaN}, {"timestamp": 1631548548352, "ltp": 1.58, "tv": 13178.24, "trd": NaN, "batb": [[0, 1.48, 77.51], [1, 1.45, 147.68], [2, 1.38, 455.1]], "batl": NaN}, {"timestamp": 1631548550693, "ltp": 1.58, "tv": 13178.24, "trd": NaN, "batb": NaN, "batl": [[0, 1.62, 42.75], [1, 1.64, 44.18], [2, 1.95, 415.94]]}, {"timestamp": 1631548550951, "ltp": 1.58, "tv": 13178.24, "trd": NaN, "batb": NaN, "batl": [[0, 1.64, 44.18], [1, 1.95, 415.94], [2, 3.8, 27.43]]}, {"timestamp": 1631548557899, "ltp": 1.58, "tv": 13178.24, "trd": NaN, "batb": NaN, "batl": [[0, 1.62, 41.75], [1, 1.64, 44.18], [2, 1.95, 415.94]]}, {"timestamp": 1631548558206, "ltp": 1.58, "tv": 13178.24, "trd": NaN, "batb": NaN, "batl": [[0, 1.64, 44.18], [1, 1.95, 415.94], [2, 3.8, 27.43]]}, {"timestamp": 1631548562819, "ltp": 1.58, "tv": 13178.24, "trd": NaN, "batb": [[2, 1.27, 2]], "batl": NaN}, {"timestamp": 1631548564694, "ltp": 1.58, "tv": 13178.24, "trd": NaN, "batb": [[0, 1.48, 117.44], [1, 1.46, 20.24], [2, 1.45, 147.68]], "batl": [[0, 1.64, 80.21], [1, 1.66, 627.53], [2, 1.95, 415.94]]}, {"timestamp": 1631548565586, "ltp": 1.58, "tv": 13178.24, "trd": NaN, "batb": [[0, 1.54, 55.36], [1, 1.5, 61.23], [2, 1.48, 117.44]], "batl": [[0, 1.61, 6.21], [1, 1.64, 80.21], [2, 1.66, 627.53]]}, {"timestamp": 1631548569491, "ltp": 1.58, "tv": 13300.81, "trd": [[1.58, 115.99], [1.6, 74.33]], "batb": NaN, "batl": NaN}, {"timestamp": 1631548572701, "ltp": 1.58, "tv": 13300.81, "trd": NaN, "batb": [[1, 1.53, 89.33], [2, 1.51, 78.99]], "batl": [[0, 1.61, 84.21], [2, 1.66, 670.78]]}, {"timestamp": 1631548578590, "ltp": 1.61, "tv": 13385.02, "trd": [[1.61, 84.21]], "batb": NaN, "batl": [[0, 1.64, 80.21], [1, 1.66, 670.78], [2, 1.67, 43.5]]}, {"timestamp": 1631548579636, "ltp": 1.61, "tv": 13385.02, "trd": NaN, "batb": NaN, "batl": [[1, 1.65, 38.3], [2, 1.66, 670.78]]}, {"timestamp": 1631548580843, "ltp": 1.61, "tv": 13385.02, "trd": NaN, "batb": [[0, 1.53, 89.33], [1, 1.51, 78.99], [2, 1.5, 141.23]], "batl": [[0, 1.95, 415.94], [1, 3.8, 27.43], [2, 8.8, 7.22]]}, {"timestamp": 1631548582738, "ltp": 1.62, "tv": 13398.7, "trd": [[1.62, 17.68]], "batb": NaN, "batl": NaN}, {"timestamp": 1631548583842, "ltp": 1.62, "tv": 13398.7, "trd": NaN, "batb": NaN, "batl": [[0, 1.67, 38.5], [1, 1.71, 31.5], [2, 1.95, 415.94]]}, {"timestamp": 1631548590663, "ltp": 1.62, "tv": 13398.7, "trd": NaN, "batb": NaN, "batl": [[0, 1.65, 41.1], [1, 1.67, 38.5], [2, 1.71, 31.5]]}, {"timestamp": 1631548590964, "ltp": 1.62, "tv": 13398.7, "trd": NaN, "batb": NaN, "batl": [[0, 1.67, 38.5], [1, 1.71, 31.5], [2, 1.95, 415.94]]}, {"timestamp": 1631548592736, "ltp": 1.61, "tv": 13420.93, "trd": [[1.61, 106.44]], "batb": NaN, "batl": [[0, 1.57, 6.37], [1, 1.6, 426.46], [2, 1.62, 18.24]]}, {"timestamp": 1631548595865, "ltp": 1.61, "tv": 13420.93, "trd": NaN, "batb": NaN, "batl": [[0, 1.57, 261.37], [1, 1.6, 446.83]]}, {"timestamp": 1631548597168, "ltp": 1.54, "tv": 13475.06, "trd": [[1.54, 741.74], [1.55, 19.37], [1.56, 91.02]], "batb": NaN, "batl": NaN}, {"timestamp": 1631548598849, "ltp": 1.54, "tv": 13475.06, "trd": NaN, "batb": [[1, 1.52, 91.74], [2, 1.51, 78.99]], "batl": [[2, 1.62, 59.49]]}, {"timestamp": 1631548600881, "ltp": 1.54, "tv": 13475.06, "trd": NaN, "batb": NaN, "batl": [[2, 1.61, 42.5]]}, {"timestamp": 1631548606248, "ltp": 1.54, "tv": 13475.06, "trd": NaN, "batb": [[0, 1.54, 216.59], [1, 1.53, 89.33], [2, 1.52, 91.74]], "batl": NaN}, {"timestamp": 1631548607194, "ltp": 1.54, "tv": 13475.06, "trd": NaN, "batb": NaN, "batl": [[1, 1.6, 426.46]]}, {"timestamp": 1631548608499, "ltp": 1.54, "tv": 13475.06, "trd": NaN, "batb": [[1, 1.52, 91.74], [2, 1.51, 78.99]], "batl": [[0, 1.57, 255], [1, 1.61, 42.5], [2, 1.62, 41.25]]}, {"timestamp": 1631548609756, "ltp": 1.54, "tv": 13475.06, "trd": NaN, "batb": [[0, 1.52, 91.74], [1, 1.51, 78.99], [2, 1.46, 67.36]], "batl": [[0, 1.63, 44.5], [1, 1.95, 415.94], [2, 3.8, 27.43]]}, {"timestamp": 1631548624815, "ltp": 1.54, "tv": 13475.06, "trd": NaN, "batb": [[2, 1.5, 231.45]], "batl": [[0, 1.54, 20.74], [1, 1.55, 2051.64], [2, 1.58, 709.44]]}, {"timestamp": 1631548625909, "ltp": 1.54, "tv": 13475.06, "trd": NaN, "batb": NaN, "batl": [[1, 1.56, 37.88], [2, 1.58, 728.14]]}, {"timestamp": 1631548628827, "ltp": 1.54, "tv": 13516.54, "trd": [[1.54, 783.22]], "batb": [[0, 1.54, 21.13], [1, 1.52, 91.74], [2, 1.51, 78.99]], "batl": [[0, 1.56, 37.88], [1, 1.58, 728.14], [2, 1.63, 44.5]]}, {"timestamp": 1631548629816, "ltp": 1.52, "tv": 13669.23, "trd": [[1.52, 3366.55], [1.54, 825.48]], "batb": [[0, 1.52, 36.53], [1, 1.51, 78.99], [2, 1.5, 231.45]], "batl": NaN}, {"timestamp": 1631548630231, "ltp": 1.52, "tv": 13673.52, "trd": [[1.52, 3370.84]], "batb": [[0, 1.52, 34.38]], "batl": NaN}, {"timestamp": 1631548631328, "ltp": 1.52, "tv": 13673.52, "trd": NaN, "batb": [[2, 1.5, 313.13]], "batl": [[1, 1.57, 44.5], [2, 1.58, 728.14]]}, {"timestamp": 1631548632521, "ltp": 1.52, "tv": 13673.52, "trd": NaN, "batb": NaN, "batl": [[2, 1.58, 769.89]]}, {"timestamp": 1631548633928, "ltp": 1.52, "tv": 13673.52, "trd": NaN, "batb": NaN, "batl": [[0, 1.56, 96.88]]}, {"timestamp": 1631548641916, "ltp": 1.52, "tv": 13673.52, "trd": NaN, "batb": NaN, "batl": [[0, 1.56, 116.72]]}, {"timestamp": 1631548646713, "ltp": 1.52, "tv": 13673.52, "trd": NaN, "batb": [[0, 1.46, 67.36], [1, 1.43, 72.89], [2, 1.4, 457.69]], "batl": [[0, 1.56, 59], [1, 1.95, 415.94], [2, 3.8, 27.43]]}, {"timestamp": 1631548646922, "ltp": 1.52, "tv": 13673.52, "trd": NaN, "batb": [[0, 1.43, 72.89], [1, 1.4, 457.69], [2, 1.27, 2]], "batl": [[0, 1.95, 415.94], [1, 3.8, 27.43], [2, 8.8, 7.22]]}, {"timestamp": 1631548650451, "ltp": 1.52, "tv": 13673.52, "trd": NaN, "batb": [[0, 1.51, 51.99], [1, 1.43, 72.89], [2, 1.4, 457.69]], "batl": [[0, 1.58, 44.75], [1, 1.95, 415.94], [2, 3.8, 27.43]]}, {"timestamp": 1631548659864, "ltp": 1.52, "tv": 13673.52, "trd": NaN, "batb": NaN, "batl": [[0, 1.55, 20.7], [1, 1.58, 44.75], [2, 1.95, 415.94]]}, {"timestamp": 1631548660645, "ltp": 1.52, "tv": 13673.52, "trd": NaN, "batb": [[0, 1.52, 60.24], [1, 1.51, 51.99], [2, 1.43, 72.89]], "batl": [[0, 1.57, 43.5]]}, {"timestamp": 1631548660958, "ltp": 1.52, "tv": 13673.52, "trd": NaN, "batb": [[0, 1.51, 51.99], [1, 1.43, 72.89], [2, 1.4, 457.69]], "batl": [[0, 1.58, 44.75], [1, 1.95, 415.94], [2, 3.8, 27.43]]}, {"timestamp": 1631548667831, "ltp": 1.52, "tv": 13673.52, "trd": NaN, "batb": [[0, 1.52, 55.74], [1, 1.51, 51.99], [2, 1.43, 72.89]], "batl": [[0, 1.57, 43.5], [1, 1.58, 44.75], [2, 1.95, 415.94]]}, {"timestamp": 1631548668147, "ltp": 1.52, "tv": 13673.52, "trd": NaN, "batb": [[0, 1.51, 51.99], [1, 1.43, 72.89], [2, 1.4, 457.69]], "batl": [[0, 1.58, 44.75], [1, 1.95, 415.94], [2, 3.8, 27.43]]}, {"timestamp": 1631548678565, "ltp": 1.52, "tv": 13673.52, "trd": NaN, "batb": [[0, 1.52, 55.99], [1, 1.51, 51.99], [2, 1.43, 72.89]], "batl": [[0, 1.57, 45.5], [1, 1.58, 44.75], [2, 1.95, 415.94]]}, {"timestamp": 1631548679354, "ltp": 1.52, "tv": 13673.52, "trd": NaN, "batb": [[0, 1.51, 51.99], [1, 1.43, 72.89], [2, 1.27, 2]], "batl": [[0, 1.58, 44.75], [1, 1.95, 415.94], [2, 3.8, 27.43]]}, {"timestamp": 1631548680668, "ltp": 1.52, "tv": 13673.52, "trd": NaN, "batb": [[2, 1.4, 42.21]], "batl": [[0, 1.52, 6.58], [1, 1.54, 38.37], [2, 1.56, 953.6]]}, {"timestamp": 1631548681778, "ltp": 1.52, "tv": 13673.52, "trd": NaN, "batb": [[1, 1.48, 20.28], [2, 1.47, 10.14]], "batl": NaN}, {"timestamp": 1631548685582, "ltp": 1.48, "tv": 13811.15, "trd": [[1.48, 901.4], [1.5, 67.84], [1.51, 749.69]], "batb": [[0, 1.48, 13.64], [1, 1.47, 10.14], [2, 1.46, 10.14]], "batl": NaN}, {"timestamp": 1631548686994, "ltp": 1.48, "tv": 13811.15, "trd": NaN, "batb": [[0, 1.5, 55.2], [1, 1.49, 59.01], [2, 1.48, 13.64]], "batl": [[2, 1.55, 42.9]]}, {"timestamp": 1631548689096, "ltp": 1.48, "tv": 13811.15, "trd": NaN, "batb": [[2, 1.48, 67.9]], "batl": NaN}, {"timestamp": 1631548697476, "ltp": 1.48, "tv": 13811.15, "trd": NaN, "batb": [[0, 1.41, 77.92], [1, 1.34, 472.33], [2, 1.27, 2]], "batl": [[0, 1.57, 41.5], [1, 1.95, 415.94], [2, 3.8, 27.43]]}, {"timestamp": 1631548700765, "ltp": 1.48, "tv": 13811.15, "trd": NaN, "batb": [[0, 1.49, 51.01], [1, 1.41, 77.92], [2, 1.34, 472.33]], "batl": NaN}, {"timestamp": 1631548702907, "ltp": 1.48, "tv": 13811.15, "trd": NaN, "batb": [[0, 1.52, 1.6], [1, 1.49, 51.01], [2, 1.42, 72.2]], "batl": NaN}, {"timestamp": 1631548703068, "ltp": 1.48, "tv": 13811.15, "trd": NaN, "batb": [[2, 1.42, 144.39]], "batl": NaN}, {"timestamp": 1631548704904, "ltp": 1.52, "tv": 13814.35, "trd": [[1.52, 3374.04]], "batb": [[0, 1.49, 51.01], [1, 1.42, 144.39], [2, 1.41, 77.92]], "batl": NaN}, {"timestamp": 1631548708913, "ltp": 1.52, "tv": 13814.35, "trd": NaN, "batb": [[0, 1.55, 23.1], [1, 1.49, 51.01], [2, 1.42, 144.39]], "batl": NaN}, {"timestamp": 1631548710902, "ltp": 1.55, "tv": 13860.55, "trd": [[1.55, 65.57]], "batb": [[0, 1.5, 51.26]], "batl": [[0, 1.55, 20], [1, 1.57, 41.5], [2, 1.95, 415.94]]}, {"timestamp": 1631548711109, "ltp": 1.55, "tv": 13860.55, "trd": NaN, "batb": [[0, 1.49, 51.01], [1, 1.42, 144.39], [2, 1.41, 77.92]], "batl": [[0, 1.57, 41.5], [1, 1.95, 415.94], [2, 3.8, 27.43]]}, {"timestamp": 1631548724819, "ltp": 1.55, "tv": 13860.55, "trd": NaN, "batb": NaN, "batl": [[1, 3.8, 27.43], [2, 8.8, 7.22]]}, {"timestamp": 1631548728837, "ltp": 1.55, "tv": 13860.55, "trd": NaN, "batb": [[1, 1.47, 14.83], [2, 1.46, 412.85]], "batl": [[0, 1.5, 17.18], [1, 1.52, 170.46], [2, 1.54, 19.19]]}, {"timestamp": 1631548729829, "ltp": 1.55, "tv": 13860.55, "trd": NaN, "batb": [[2, 1.46, 515.59]], "batl": NaN}, {"timestamp": 1631548729935, "ltp": 1.55, "tv": 13860.55, "trd": NaN, "batb": [[2, 1.46, 433.39]], "batl": NaN}, {"timestamp": 1631548733836, "ltp": 1.49, "tv": 13944.73, "trd": [[1.49, 102.22]], "batb": [[0, 1.49, 8.92]], "batl": NaN}, {"timestamp": 1631548734827, "ltp": 1.49, "tv": 13962.57, "trd": [[1.49, 120.06]], "batb": [[0, 1.47, 14.83], [1, 1.46, 433.39], [2, 1.45, 10.28]], "batl": [[0, 1.49, 7.08], [1, 1.5, 17.18], [2, 1.52, 170.46]]}, {"timestamp": 1631548737611, "ltp": 1.49, "tv": 13976.73, "trd": [[1.49, 134.22]], "batb": NaN, "batl": [[0, 1.5, 17.18], [1, 1.52, 170.46], [2, 1.54, 19.19]]}, {"timestamp": 1631548741343, "ltp": 1.49, "tv": 13976.73, "trd": NaN, "batb": NaN, "batl": [[0, 1.5, 172.18]]}, {"timestamp": 1631548744638, "ltp": 1.5, "tv": 13976.83, "trd": [[1.5, 67.94]], "batb": NaN, "batl": [[0, 1.5, 172.13]]}, {"timestamp": 1631548765874, "ltp": 1.5, "tv": 13976.83, "trd": NaN, "batb": [[0, 1.46, 433.39], [1, 1.45, 10.28], [2, 1.44, 10.28]], "batl": [[0, 1.5, 161.62], [1, 1.52, 131.58], [2, 1.56, 43.42]]}, {"timestamp": 1631548766874, "ltp": 1.5, "tv": 13976.83, "trd": NaN, "batb": [[0, 1.39, 55.91], [1, 1.35, 94.87], [2, 1.27, 2]], "batl": [[0, 1.5, 155], [1, 1.56, 43.42], [2, 1.57, 41.5]]}, {"timestamp": 1631548767501, "ltp": 1.5, "tv": 13976.83, "trd": NaN, "batb": NaN, "batl": [[0, 1.59, 42.5], [1, 3.8, 27.43], [2, 8.8, 7.22]]}, {"timestamp": 1631548768866, "ltp": 1.5, "tv": 13976.83, "trd": NaN, "batb": NaN, "batl": [[0, 1.5, 8.51], [1, 1.59, 42.5], [2, 3.8, 27.43]]}, {"timestamp": 1631548769826, "ltp": 1.5, "tv": 13976.83, "trd": NaN, "batb": [[0, 1.42, 57.94], [1, 1.39, 55.91], [2, 1.35, 94.87]], "batl": [[0, 1.59, 42.5], [1, 3.8, 27.43], [2, 8.8, 7.22]]}, {"timestamp": 1631548770666, "ltp": 1.5, "tv": 13976.83, "trd": NaN, "batb": [[0, 1.39, 55.91], [1, 1.35, 94.87], [2, 1.27, 2]], "batl": [[0, 1.56, 42.92], [1, 1.59, 42.5], [2, 3.8, 27.43]]}, {"timestamp": 1631548770986, "ltp": 1.5, "tv": 13976.83, "trd": NaN, "batb": NaN, "batl": [[0, 1.59, 42.5], [1, 3.8, 27.43], [2, 8.8, 7.22]]}, {"timestamp": 1631548774781, "ltp": 1.5, "tv": 13976.83, "trd": NaN, "batb": NaN, "batl": [[0, 1.5, 40.19], [1, 1.59, 42.5], [2, 3.8, 27.43]]}, {"timestamp": 1631548775086, "ltp": 1.5, "tv": 13976.83, "trd": NaN, "batb": NaN, "batl": [[0, 1.59, 42.5], [1, 3.8, 27.43], [2, 8.8, 7.22]]}, {"timestamp": 1631548777869, "ltp": 1.5, "tv": 13976.83, "trd": NaN, "batb": NaN, "batl": [[0, 1.56, 45.67], [1, 1.59, 42.5], [2, 3.8, 27.43]]}, {"timestamp": 1631548778181, "ltp": 1.5, "tv": 13976.83, "trd": NaN, "batb": NaN, "batl": [[0, 1.59, 42.5], [1, 3.8, 27.43], [2, 8.8, 7.22]]}, {"timestamp": 1631548780905, "ltp": 1.5, "tv": 13976.83, "trd": NaN, "batb": NaN, "batl": [[0, 3.8, 27.43], [1, 8.8, 7.22], [2, 44, 7.22]]}, {"timestamp": 1631548783895, "ltp": 1.5, "tv": 13976.83, "trd": NaN, "batb": [[0, 1.4, 12.4], [1, 1.39, 55.91], [2, 1.35, 94.87]], "batl": [[0, 1.44, 6.94], [1, 1.45, 62.06], [2, 1.46, 153.69]]}, {"timestamp": 1631548784888, "ltp": 1.5, "tv": 13976.83, "trd": NaN, "batb": NaN, "batl": [[1, 1.45, 20.68], [2, 1.46, 133]]}, {"timestamp": 1631548795786, "ltp": 1.5, "tv": 13976.83, "trd": NaN, "batb": [[0, 1.35, 94.87], [1, 1.31, 74.79], [2, 1.29, 120.79]], "batl": [[0, 1.53, 53.5], [1, 3.8, 27.43], [2, 8.8, 7.22]]}, {"timestamp": 1631548796207, "ltp": 1.5, "tv": 13976.83, "trd": NaN, "batb": [[0, 1.31, 74.79], [1, 1.29, 120.79], [2, 1.27, 2]], "batl": NaN}, {"timestamp": 1631548798790, "ltp": 1.5, "tv": 13976.83, "trd": NaN, "batb": NaN, "batl": [[0, 1.43, 132], [1, 1.53, 53.5], [2, 3.8, 27.43]]}, {"timestamp": 1631548799316, "ltp": 1.5, "tv": 13976.83, "trd": NaN, "batb": NaN, "batl": [[0, 1.53, 53.5], [1, 3.8, 27.43], [2, 8.8, 7.22]]}, {"timestamp": 1631548816633, "ltp": 1.5, "tv": 13976.83, "trd": NaN, "batb": [[0, 1.34, 77.72], [1, 1.31, 74.79], [2, 1.29, 120.79]], "batl": [[0, 1.5, 45.51], [1, 1.53, 53.5], [2, 3.8, 27.43]]}, {"timestamp": 1631548817421, "ltp": 1.5, "tv": 13976.83, "trd": NaN, "batb": [[0, 1.31, 74.79], [1, 1.29, 120.79], [2, 1.27, 2]], "batl": [[0, 1.53, 53.5], [1, 3.8, 27.43], [2, 8.8, 7.22]]}, {"timestamp": 1631548822644, "ltp": 1.5, "tv": 13976.83, "trd": NaN, "batb": NaN, "batl": [[0, 3.8, 27.43], [1, 8.8, 7.22], [2, 44, 7.22]]}, {"timestamp": 1631548823638, "ltp": 1.5, "tv": 13976.83, "trd": NaN, "batb": [[0, 1.34, 69.72], [1, 1.31, 74.79], [2, 1.29, 120.79]], "batl": [[0, 1.5, 47.93], [1, 3.8, 27.43], [2, 8.8, 7.22]]}, {"timestamp": 1631548823950, "ltp": 1.5, "tv": 13976.83, "trd": NaN, "batb": [[0, 1.31, 74.79], [1, 1.29, 120.79], [2, 1.27, 2]], "batl": [[0, 3.8, 27.43], [1, 8.8, 7.22], [2, 44, 7.22]]}, {"timestamp": 1631548825566, "ltp": 1.5, "tv": 13976.83, "trd": NaN, "batb": [[2, 1.27, 48.53]], "batl": [[0, 1.35, 14.35], [1, 1.37, 7.3], [2, 1.39, 42.51]]}, {"timestamp": 1631548826669, "ltp": 1.5, "tv": 13976.83, "trd": NaN, "batb": [[0, 1.32, 22.72], [1, 1.31, 86.15], [2, 1.3, 11.36]], "batl": NaN}, {"timestamp": 1631548833843, "ltp": 1.5, "tv": 13976.83, "trd": NaN, "batb": NaN, "batl": [[0, 1.35, 139.35]]}, {"timestamp": 1631548842480, "ltp": 1.5, "tv": 13976.83, "trd": NaN, "batb": NaN, "batl": [[2, 1.43, 58.5]]}, {"timestamp": 1631548849669, "ltp": 1.5, "tv": 13976.83, "trd": NaN, "batb": [[0, 1.29, 119.61], [1, 1.27, 84.87], [2, 1.24, 95.77]], "batl": [[0, 1.35, 125], [1, 1.43, 58.5], [2, 1.46, 49.25]]}, {"timestamp": 1631548850164, "ltp": 1.5, "tv": 13976.83, "trd": NaN, "batb": [[0, 1.27, 2], [1, 1.24, 95.77], [2, 1.23, 154.42]], "batl": [[0, 1.46, 49.25], [1, 3.8, 27.43], [2, 8.8, 7.22]]}, {"timestamp": 1631548862016, "ltp": 1.5, "tv": 13976.83, "trd": NaN, "batb": NaN, "batl": [[0, 3.8, 27.43], [1, 8.8, 7.22], [2, 44, 7.22]]}, {"timestamp": 1631548863907, "ltp": 1.5, "tv": 13976.83, "trd": NaN, "batb": [[0, 1.27, 90.87]], "batl": [[0, 1.43, 52.5], [1, 3.8, 27.43], [2, 8.8, 7.22]]}, {"timestamp": 1631548864588, "ltp": 1.5, "tv": 13976.83, "trd": NaN, "batb": [[0, 1.27, 2], [1, 1.25, 428.72], [2, 1.24, 95.77]], "batl": [[0, 1.29, 93.02], [1, 1.3, 664.16], [2, 1.31, 7.63]]}, {"timestamp": 1631548865590, "ltp": 1.5, "tv": 13976.83, "trd": NaN, "batb": [[2, 1.24, 103.83]], "batl": NaN}, {"timestamp": 1631548872593, "ltp": 1.5, "tv": 13976.83, "trd": NaN, "batb": NaN, "batl": [[0, 1.29, 448.02]]}, {"timestamp": 1631548876406, "ltp": 1.27, "tv": 13978.83, "trd": [[1.27, 17.36]], "batb": [[0, 1.25, 428.72], [1, 1.24, 103.83], [2, 1.23, 154.42]], "batl": NaN}, {"timestamp": 1631548878811, "ltp": 1.27, "tv": 13978.83, "trd": NaN, "batb": [[0, 1.24, 95.77], [1, 1.23, 154.42], [2, 1.22, 168.77]], "batl": [[0, 1.29, 355], [1, 1.33, 44.43], [2, 1.35, 99.98]]}, {"timestamp": 1631548879336, "ltp": 1.27, "tv": 13978.83, "trd": NaN, "batb": [[0, 1.22, 120.34], [1, 1.21, 2], [2, 1.19, 189.64]], "batl": [[0, 1.38, 61.25], [1, 3.8, 27.43], [2, 8.8, 7.22]]}, {"timestamp": 1631548880426, "ltp": 1.27, "tv": 13978.83, "trd": NaN, "batb": [[1, 1.21, 115.69]], "batl": NaN}, {"timestamp": 1631548885842, "ltp": 1.27, "tv": 13978.83, "trd": NaN, "batb": [[0, 1.24, 98.02], [1, 1.22, 120.34], [2, 1.21, 115.69]], "batl": NaN}, {"timestamp": 1631548886418, "ltp": 1.27, "tv": 13978.83, "trd": NaN, "batb": [[0, 1.22, 120.34], [1, 1.21, 115.69], [2, 1.19, 189.64]], "batl": NaN}, {"timestamp": 1631548889724, "ltp": 1.27, "tv": 13978.83, "trd": NaN, "batb": NaN, "batl": [[0, 1.35, 69.1], [1, 1.38, 61.25], [2, 3.8, 27.43]]}, {"timestamp": 1631548889932, "ltp": 1.27, "tv": 13978.83, "trd": NaN, "batb": NaN, "batl": [[0, 1.38, 61.25], [1, 3.8, 27.43], [2, 8.8, 7.22]]}, {"timestamp": 1631548894129, "ltp": 1.22, "tv": 13982.71, "trd": [[1.22, 213.33]], "batb": [[0, 1.22, 118.4]], "batl": NaN}, {"timestamp": 1631548895730, "ltp": 1.22, "tv": 14219.51, "trd": [[1.22, 450.13]], "batb": [[0, 1.21, 115.69], [1, 1.2, 621.21]], "batl": [[0, 1.22, 45.54], [1, 1.23, 29.94], [2, 1.24, 120.96]]}, {"timestamp": 1631548896731, "ltp": 1.22, "tv": 14219.51, "trd": NaN, "batb": [[1, 1.2, 629.54], [2, 1.19, 239.3]], "batl": [[0, 1.22, 16.39], [2, 1.24, 72.58]]}, {"timestamp": 1631548897036, "ltp": 1.22, "tv": 14219.51, "trd": NaN, "batb": NaN, "batl": [[2, 1.24, 24.2]]}, {"timestamp": 1631548898932, "ltp": 1.22, "tv": 14252.28, "trd": [[1.22, 482.9]], "batb": NaN, "batl": [[0, 1.23, 29.94], [1, 1.24, 24.2], [2, 1.25, 12.1]]}, {"timestamp": 1631548900735, "ltp": 1.23, "tv": 14282.22, "trd": [[1.23, 163.23]], "batb": NaN, "batl": [[0, 1.24, 24.2], [1, 1.25, 12.1], [2, 1.26, 20.04]]}, {"timestamp": 1631548907551, "ltp": 1.24, "tv": 14302.31, "trd": [[1.24, 65.88]], "batb": NaN, "batl": [[0, 1.24, 14.15]]}, {"timestamp": 1631548913906, "ltp": 1.24, "tv": 14302.31, "trd": NaN, "batb": NaN, "batl": [[0, 1.24, 43.98]]}, {"timestamp": 1631548937779, "ltp": 1.22, "tv": 14327.41, "trd": [[1.22, 508]], "batb": NaN, "batl": [[0, 1.22, 909.13], [1, 1.24, 43.98], [2, 1.25, 12.1]]}, {"timestamp": 1631548948053, "ltp": 1.22, "tv": 14327.41, "trd": NaN, "batb": NaN, "batl": [[1, 1.24, 14.15]]}, {"timestamp": 1631548949947, "ltp": 1.21, "tv": 14330.11, "trd": [[1.21, 97.11]], "batb": [[0, 1.21, 114.34]], "batl": NaN}, {"timestamp": 1631548950946, "ltp": 1.21, "tv": 14330.11, "trd": NaN, "batb": NaN, "batl": [[1, 1.23, 24.89], [2, 1.24, 14.15]]}, {"timestamp": 1631548970186, "ltp": 1.21, "tv": 14330.11, "trd": NaN, "batb": [[0, 1.21, 113.69], [2, 1.19, 237.3]], "batl": NaN}, {"timestamp": 1631548973039, "ltp": 1.22, "tv": 14337.3, "trd": [[1.22, 515.19]], "batb": NaN, "batl": [[0, 1.22, 905.54]]}, {"timestamp": 1631548983061, "ltp": 1.22, "tv": 14337.3, "trd": NaN, "batb": [[2, 1.19, 187.64]], "batl": NaN}, {"timestamp": 1631548986451, "ltp": 1.22, "tv": 14337.3, "trd": NaN, "batb": [[2, 1.19, 327.35]], "batl": NaN}, {"timestamp": 1631548996879, "ltp": 1.22, "tv": 14337.3, "trd": NaN, "batb": [[0, 1.18, 143.86], [1, 1.17, 216.24], [2, 1.01, 107.79]], "batl": [[1, 1.33, 84], [2, 1.37, 71]]}, {"timestamp": 1631548999888, "ltp": 1.22, "tv": 14339.1, "trd": [[1.22, 517]], "batb": NaN, "batl": [[0, 1.22, 904.64]]}, {"timestamp": 1631549010517, "ltp": 1.22, "tv": 15243.74, "trd": [[1.22, 1421.63]], "batb": [[0, 1.26, 19.14], [1, 1.24, 8.06], [2, 1.23, 48.04]], "batl": [[0, 1.28, 32.63], [2, 1.34, 44.1]]}, {"timestamp": 1631549011408, "ltp": 1.22, "tv": 15243.74, "trd": NaN, "batb": [[1, 1.24, 158.21]], "batl": [[1, 1.31, 7.63], [2, 1.33, 84]]}, {"timestamp": 1631549016829, "ltp": 1.22, "tv": 15243.74, "trd": NaN, "batb": [[1, 1.24, 247.98], [2, 1.23, 165.67]], "batl": NaN}, {"timestamp": 1631549019905, "ltp": 1.22, "tv": 15243.74, "trd": NaN, "batb": [[0, 1.23, 117.63], [1, 1.22, 113.34], [2, 1.2, 178.16]], "batl": [[0, 1.36, 69.32], [1, 1.37, 71], [2, 1.39, 58.5]]}, {"timestamp": 1631549020219, "ltp": 1.22, "tv": 15243.74, "trd": NaN, "batb": [[1, 1.2, 178.16], [2, 1.18, 143.86]], "batl": [[0, 1.39, 58.5], [1, 3.8, 27.43], [2, 8.8, 7.22]]}, {"timestamp": 1631549023710, "ltp": 1.22, "tv": 15243.74, "trd": NaN, "batb": NaN, "batl": [[0, 1.36, 60.07], [1, 1.39, 58.5], [2, 3.8, 27.43]]}, {"timestamp": 1631549024608, "ltp": 1.22, "tv": 15243.74, "trd": NaN, "batb": NaN, "batl": [[0, 1.39, 59.4], [1, 3.8, 27.43], [2, 8.8, 7.22]]}, {"timestamp": 1631549028859, "ltp": 1.26, "tv": 15244.64, "trd": [[1.26, 26.67]], "batb": NaN, "batl": [[0, 1.34, 12.23], [1, 1.37, 756.1], [2, 1.39, 58.5]]}, {"timestamp": 1631549029749, "ltp": 1.26, "tv": 15244.64, "trd": NaN, "batb": [[0, 1.3, 115.17], [1, 1.29, 45.81], [2, 1.27, 23.26]], "batl": [[2, 1.38, 7.25]]}, {"timestamp": 1631549036614, "ltp": 1.26, "tv": 15244.64, "trd": NaN, "batb": [[2, 1.28, 89.66]], "batl": NaN}, {"timestamp": 1631549040732, "ltp": 1.26, "tv": 15244.64, "trd": NaN, "batb": [[0, 1.26, 242.29], [1, 1.23, 117.63], [2, 1.18, 143.86]], "batl": [[0, 1.44, 60.33], [1, 3.8, 27.43], [2, 8.8, 7.22]]}, {"timestamp": 1631549050887, "ltp": 1.26, "tv": 15244.64, "trd": NaN, "batb": [[0, 1.28, 21.49], [1, 1.26, 242.29], [2, 1.23, 117.63]], "batl": [[0, 1.3, 64.73], [1, 1.31, 114.5], [2, 1.32, 907.76]]}, {"timestamp": 1631549051879, "ltp": 1.26, "tv": 15244.64, "trd": NaN, "batb": [[2, 1.25, 47.27]], "batl": [[1, 1.31, 22.9], [2, 1.32, 861.96]]}, {"timestamp": 1631549062663, "ltp": 1.26, "tv": 15244.64, "trd": NaN, "batb": [[0, 1.22, 126.84], [1, 1.21, 169.86], [2, 1.18, 143.86]], "batl": [[0, 1.41, 57.5], [1, 3.8, 27.43], [2, 8.8, 7.22]]}, {"timestamp": 1631549065886, "ltp": 1.26, "tv": 15244.64, "trd": NaN, "batb": [[0, 1.24, 88.52], [1, 1.22, 126.84], [2, 1.21, 169.86]], "batl": [[0, 1.38, 68.75], [1, 1.41, 57.5], [2, 3.8, 27.43]]}, {"timestamp": 1631549066356, "ltp": 1.26, "tv": 15244.64, "trd": NaN, "batb": [[0, 1.22, 126.84], [1, 1.21, 169.86], [2, 1.18, 143.86]], "batl": [[0, 1.41, 57.5], [1, 3.8, 27.43], [2, 8.8, 7.22]]}, {"timestamp": 1631549076699, "ltp": 1.26, "tv": 15244.64, "trd": NaN, "batb": [[0, 1.24, 115.02], [1, 1.22, 126.84], [2, 1.21, 169.86]], "batl": [[0, 1.38, 65.75], [1, 1.41, 57.5], [2, 3.8, 27.43]]}, {"timestamp": 1631549076961, "ltp": 1.26, "tv": 15244.64, "trd": NaN, "batb": [[0, 1.22, 126.84], [1, 1.21, 169.86], [2, 1.18, 143.86]], "batl": [[0, 1.41, 57.5], [1, 3.8, 27.43], [2, 8.8, 7.22]]}, {"timestamp": 1631549080768, "ltp": 1.26, "tv": 15244.64, "trd": NaN, "batb": [[0, 1.24, 101.52], [1, 1.22, 126.84], [2, 1.21, 169.86]], "batl": [[0, 1.38, 58.75], [1, 1.41, 57.5], [2, 3.8, 27.43]]}, {"timestamp": 1631549080989, "ltp": 1.26, "tv": 15244.64, "trd": NaN, "batb": [[0, 1.22, 126.84], [1, 1.21, 169.86], [2, 1.18, 143.86]], "batl": [[0, 1.41, 57.5], [1, 3.8, 27.43], [2, 8.8, 7.22]]}, {"timestamp": 1631549087701, "ltp": 1.26, "tv": 15244.64, "trd": NaN, "batb": [[0, 1.24, 110.02], [1, 1.22, 126.84], [2, 1.21, 169.86]], "batl": [[0, 1.38, 70.25], [1, 1.41, 57.5], [2, 3.8, 27.43]]}, {"timestamp": 1631549089536, "ltp": 1.26, "tv": 15244.64, "trd": NaN, "batb": [[0, 1.22, 126.84], [1, 1.21, 169.86], [2, 1.18, 143.86]], "batl": [[0, 1.41, 57.5], [1, 3.8, 27.43], [2, 8.8, 7.22]]}, {"timestamp": 1631549092809, "ltp": 1.26, "tv": 15244.64, "trd": NaN, "batb": [[0, 1.24, 112.52], [1, 1.22, 126.84], [2, 1.21, 169.86]], "batl": [[0, 1.38, 61.75], [1, 1.41, 57.5], [2, 3.8, 27.43]]}, {"timestamp": 1631549093387, "ltp": 1.26, "tv": 15244.64, "trd": NaN, "batb": [[0, 1.34, 29.86], [1, 1.32, 44.76], [2, 1.3, 22.73]], "batl": [[0, 1.39, 19.2], [2, 1.42, 705.55]]}, {"timestamp": 1631549094385, "ltp": 1.26, "tv": 15244.64, "trd": NaN, "batb": [[1, 1.33, 100.32], [2, 1.32, 44.76]], "batl": [[2, 1.42, 712.59]]}, {"timestamp": 1631549115856, "ltp": 1.26, "tv": 15244.64, "trd": NaN, "batb": [[0, 1.28, 123.3], [1, 1.27, 86.87], [2, 1.22, 126.84]], "batl": [[0, 1.51, 51.5], [1, 3.8, 27.43], [2, 8.8, 7.22]]}, {"timestamp": 1631549122727, "ltp": 1.26, "tv": 15244.64, "trd": NaN, "batb": [[0, 1.3, 88.68], [1, 1.28, 123.3], [2, 1.27, 86.87]], "batl": NaN}, {"timestamp": 1631549122934, "ltp": 1.26, "tv": 15244.64, "trd": NaN, "batb": [[0, 1.28, 123.3], [1, 1.27, 86.87], [2, 1.22, 126.84]], "batl": NaN}, {"timestamp": 1631549129488, "ltp": 1.26, "tv": 15244.64, "trd": NaN, "batb": [[0, 1.48, 11.28], [1, 1.45, 686.77], [2, 1.4, 42.21]], "batl": [[0, 1.5, 6.33], [1, 1.51, 51.5], [2, 1.54, 598.44]]}, {"timestamp": 1631549130686, "ltp": 1.26, "tv": 15244.64, "trd": NaN, "batb": [[2, 1.43, 74.57]], "batl": [[2, 1.53, 6.54]]}, {"timestamp": 1631549142661, "ltp": 1.48, "tv": 15254.09, "trd": [[1.48, 910.85]], "batb": [[0, 1.48, 1.83]], "batl": NaN}, {"timestamp": 1631549152770, "ltp": 1.48, "tv": 15254.09, "trd": NaN, "batb": [[0, 1.45, 686.77], [1, 1.43, 74.57], [2, 1.4, 42.21]], "batl": [[0, 1.51, 51.5], [1, 1.53, 6.54], [2, 1.54, 645.19]]}, {"timestamp": 1631549154586, "ltp": 1.48, "tv": 15254.09, "trd": NaN, "batb": [[0, 1.36, 91.51], [1, 1.33, 88.53], [2, 1.27, 86.87]], "batl": [[0, 1.56, 46.92], [1, 3.8, 27.43], [2, 8.8, 7.22]]}, {"timestamp": 1631549157782, "ltp": 1.48, "tv": 15254.09, "trd": NaN, "batb": [[0, 1.37, 160.69]], "batl": [[0, 1.54, 44.75], [1, 1.56, 46.92], [2, 3.8, 27.43]]}, {"timestamp": 1631549157990, "ltp": 1.48, "tv": 15254.09, "trd": NaN, "batb": [[0, 1.37, 89.92]], "batl": [[0, 1.56, 46.92], [1, 3.8, 27.43], [2, 8.8, 7.22]]}, {"timestamp": 1631549161817, "ltp": 1.48, "tv": 15254.09, "trd": NaN, "batb": [[0, 1.53, 130.72], [1, 1.45, 40.75], [2, 1.43, 20.66]], "batl": [[0, 1.56, 71.83], [1, 1.6, 728.68], [2, 1.62, 18.24]]}, {"timestamp": 1631549162872, "ltp": 1.48, "tv": 15254.09, "trd": NaN, "batb": [[0, 1.53, 78.43], [1, 1.48, 64.5], [2, 1.45, 40.75]], "batl": [[1, 1.58, 6.33], [2, 1.6, 728.68]]}, {"timestamp": 1631549169813, "ltp": 1.48, "tv": 15254.09, "trd": NaN, "batb": NaN, "batl": [[2, 1.59, 41.5]]}, {"timestamp": 1631549174608, "ltp": 1.48, "tv": 15254.09, "trd": NaN, "batb": [[0, 1.48, 64.5], [1, 1.45, 40.75], [2, 1.44, 57.42]], "batl": [[0, 1.6, 36.93], [1, 1.61, 38.5], [2, 1.62, 18.24]]}, {"timestamp": 1631549175328, "ltp": 1.48, "tv": 15254.09, "trd": NaN, "batb": [[0, 1.42, 76.58], [1, 1.4, 65.41], [2, 1.33, 88.53]], "batl": [[0, 1.61, 38.5], [1, 3.8, 27.43], [2, 8.8, 7.22]]}, {"timestamp": 1631549177841, "ltp": 1.48, "tv": 15254.09, "trd": NaN, "batb": NaN, "batl": [[0, 1.59, 40.5], [1, 1.61, 38.5], [2, 3.8, 27.43]]}, {"timestamp": 1631549178727, "ltp": 1.48, "tv": 15254.09, "trd": NaN, "batb": [[0, 1.41, 77.84]], "batl": [[0, 1.61, 38.5], [1, 3.8, 27.43], [2, 8.8, 7.22]]}, {"timestamp": 1631549181399, "ltp": 1.48, "tv": 15254.09, "trd": NaN, "batb": NaN, "batl": [[0, 1.59, 44.5], [1, 1.61, 38.5], [2, 3.8, 27.43]]}, {"timestamp": 1631549182197, "ltp": 1.48, "tv": 15254.09, "trd": NaN, "batb": NaN, "batl": [[0, 1.61, 38.5], [1, 3.8, 27.43], [2, 8.8, 7.22]]}, {"timestamp": 1631549184401, "ltp": 1.48, "tv": 15254.09, "trd": NaN, "batb": [[0, 1.56, 76.92], [1, 1.49, 39.66], [2, 1.47, 20.1]], "batl": [[0, 1.6, 13], [1, 1.61, 38.5], [2, 1.64, 423.3]]}, {"timestamp": 1631549185547, "ltp": 1.48, "tv": 15254.09, "trd": NaN, "batb": [[1, 1.52, 57.29], [2, 1.49, 39.66]], "batl": [[2, 1.62, 6.17]]}, {"timestamp": 1631549190844, "ltp": 1.48, "tv": 15254.09, "trd": NaN, "batb": [[2, 1.51, 49.99]], "batl": [[2, 1.62, 45.92]]}, {"timestamp": 1631549192719, "ltp": 1.48, "tv": 15254.09, "trd": NaN, "batb": NaN, "batl": [[0, 1.6, 52.81]]}, {"timestamp": 1631549196736, "ltp": 1.48, "tv": 15254.09, "trd": NaN, "batb": [[0, 1.52, 57.29], [1, 1.49, 39.66], [2, 1.47, 86.7]], "batl": [[0, 1.65, 35.81], [1, 1.67, 17.69], [2, 3.8, 27.43]]}, {"timestamp": 1631549197048, "ltp": 1.48, "tv": 15254.09, "trd": NaN, "batb": [[0, 1.47, 66.6], [1, 1.33, 88.53], [2, 1.27, 86.87]], "batl": [[0, 3.8, 27.43], [1, 8.8, 7.22], [2, 44, 7.22]]}, {"timestamp": 1631549200327, "ltp": 1.48, "tv": 15254.09, "trd": NaN, "batb": [[0, 1.48, 52.26], [1, 1.47, 66.6], [2, 1.33, 88.53]], "batl": [[0, 1.62, 38.25], [1, 3.8, 27.43], [2, 8.8, 7.22]]}, {"timestamp": 1631549204764, "ltp": 1.48, "tv": 15254.09, "trd": NaN, "batb": [[0, 1.51, 47.99], [1, 1.48, 52.26], [2, 1.47, 66.6]], "batl": [[0, 1.61, 44.5], [1, 1.62, 38.25], [2, 3.8, 27.43]]}, {"timestamp": 1631549205025, "ltp": 1.48, "tv": 15254.09, "trd": NaN, "batb": [[0, 1.48, 52.26], [1, 1.47, 66.6], [2, 1.33, 88.53]], "batl": [[0, 1.62, 38.25], [1, 3.8, 27.43], [2, 8.8, 7.22]]}, {"timestamp": 1631549210876, "ltp": 1.48, "tv": 15254.09, "trd": NaN, "batb": [[0, 1.59, 94.34], [1, 1.58, 47.18], [2, 1.57, 47.18]], "batl": [[1, 1.64, 12.64], [2, 1.68, 393.18]]}, {"timestamp": 1631549211866, "ltp": 1.48, "tv": 15254.09, "trd": NaN, "batb": [[2, 1.57, 98.93]], "batl": [[2, 1.66, 6.02]]}, {"timestamp": 1631549212071, "ltp": 1.48, "tv": 15254.09, "trd": NaN, "batb": [[0, 1.59, 56.6], [1, 1.58, 28.31], [2, 1.57, 80.06]], "batl": NaN}, {"timestamp": 1631549214346, "ltp": 1.62, "tv": 15292.34, "trd": [[1.62, 55.93]], "batb": NaN, "batl": [[0, 1.64, 12.64], [1, 1.66, 6.02], [2, 1.68, 393.18]]}, {"timestamp": 1631549217577, "ltp": 1.62, "tv": 15292.34, "trd": NaN, "batb": NaN, "batl": [[0, 1.63, 47.5], [1, 1.64, 50.32], [2, 1.66, 6.02]]}, {"timestamp": 1631549218882, "ltp": 1.62, "tv": 15292.34, "trd": NaN, "batb": NaN, "batl": [[2, 1.65, 39.5]]}, {"timestamp": 1631549226491, "ltp": 1.62, "tv": 15292.34, "trd": NaN, "batb": [[0, 1.55, 42.19], [1, 1.52, 57.88], [2, 1.48, 52.26]], "batl": [[0, 3.8, 27.43], [1, 8.8, 7.22], [2, 44, 7.22]]}, {"timestamp": 1631549227545, "ltp": 1.62, "tv": 15292.34, "trd": NaN, "batb": [[0, 1.55, 42.73]], "batl": NaN}, {"timestamp": 1631549229694, "ltp": 1.64, "tv": 15293.42, "trd": [[1.64, 33.88]], "batb": [[0, 1.55, 42.19]], "batl": [[0, 1.64, 37.14], [1, 1.65, 34.5], [2, 3.8, 27.43]]}, {"timestamp": 1631549230017, "ltp": 1.64, "tv": 15293.42, "trd": NaN, "batb": [[2, 1.01, 107.79]], "batl": [[0, 1.65, 34.5], [1, 3.8, 27.43], [2, 8.8, 7.22]]}, {"timestamp": 1631549231888, "ltp": 1.64, "tv": 15293.42, "trd": NaN, "batb": [[0, 1.55, 80.31], [1, 1.53, 19.31], [2, 1.52, 57.88]], "batl": [[1, 1.66, 8.78], [2, 1.7, 319.88]]}, {"timestamp": 1631549232879, "ltp": 1.64, "tv": 15293.42, "trd": NaN, "batb": [[0, 1.6, 48.23], [1, 1.56, 52.42], [2, 1.55, 80.31]], "batl": [[2, 1.68, 5.95]]}, {"timestamp": 1631549243116, "ltp": 1.65, "tv": 15327.92, "trd": [[1.65, 34.5]], "batb": NaN, "batl": [[0, 1.66, 8.78], [1, 1.68, 5.95], [2, 1.7, 337.52]]}, {"timestamp": 1631549252737, "ltp": 1.7, "tv": 15606.4, "trd": [[1.66, 12.78], [1.68, 5.95], [1.7, 263.75]], "batb": NaN, "batl": [[0, 1.7, 73.77], [1, 1.71, 8.82], [2, 1.72, 43.17]]}, {"timestamp": 1631549259791, "ltp": 1.65, "tv": 15606.94, "trd": [[1.65, 35.04]], "batb": NaN, "batl": NaN}, {"timestamp": 1631549261986, "ltp": 1.65, "tv": 15609.07, "trd": [[1.65, 37.17]], "batb": NaN, "batl": NaN}, {"timestamp": 1631549265940, "ltp": 1.65, "tv": 15609.07, "trd": NaN, "batb": NaN, "batl": [[0, 1.68, 15.31], [1, 1.7, 73.77], [2, 1.71, 8.82]]}, {"timestamp": 1631549279856, "ltp": 1.65, "tv": 15609.07, "trd": NaN, "batb": [[0, 1.66, 14.44], [1, 1.6, 48.23], [2, 1.56, 52.42]], "batl": NaN}, {"timestamp": 1631549289355, "ltp": 1.65, "tv": 15609.07, "trd": NaN, "batb": [[1, 1.65, 8.66], [2, 1.6, 48.23]], "batl": NaN}, {"timestamp": 1631549293746, "ltp": 1.66, "tv": 15621.33, "trd": [[1.66, 25.04]], "batb": [[0, 1.66, 8.31]], "batl": NaN}, {"timestamp": 1631549308501, "ltp": 1.66, "tv": 15621.49, "trd": [[1.66, 25.2]], "batb": [[0, 1.66, 8.23]], "batl": NaN}, {"timestamp": 1631549323501, "ltp": 1.66, "tv": 15621.49, "trd": NaN, "batb": NaN, "batl": [[2, 1.71, 41.63]]}, {"timestamp": 1631549333613, "ltp": 1.68, "tv": 15623.64, "trd": [[1.68, 8.11]], "batb": [[0, 1.65, 8.66], [1, 1.6, 48.23], [2, 1.57, 43.57]], "batl": [[0, 1.68, 14.23]]}, {"timestamp": 1631549336736, "ltp": 1.68, "tv": 15623.64, "trd": NaN, "batb": [[0, 1.67, 8.23], [1, 1.65, 8.66], [2, 1.6, 48.23]], "batl": NaN}, {"timestamp": 1631549337732, "ltp": 1.68, "tv": 15623.64, "trd": NaN, "batb": NaN, "batl": [[0, 3.8, 27.43], [1, 8.8, 7.22], [2, 44, 7.22]]}, {"timestamp": 1631549338044, "ltp": 1.68, "tv": 15623.64, "trd": NaN, "batb": [[2, 1.58, 37.56]], "batl": NaN}, {"timestamp": 1631549341226, "ltp": 1.68, "tv": 15623.64, "trd": NaN, "batb": NaN, "batl": [[0, 1.72, 35.41], [1, 3.8, 27.43], [2, 8.8, 7.22]]}, {"timestamp": 1631549351844, "ltp": 1.67, "tv": 15640.11, "trd": [[1.67, 16.47]], "batb": [[0, 1.65, 8.66], [1, 1.62, 390.67]], "batl": [[0, 1.66, 18.49], [1, 1.68, 17.86], [2, 1.69, 43.88]]}, {"timestamp": 1631549352366, "ltp": 1.67, "tv": 15640.11, "trd": NaN, "batb": [[2, 1.61, 18.64]], "batl": NaN}, {"timestamp": 1631549356557, "ltp": 1.65, "tv": 15688.27, "trd": [[1.65, 85.32]], "batb": [[0, 1.65, 91.84]], "batl": NaN}, {"timestamp": 1631549359847, "ltp": 1.65, "tv": 15688.27, "trd": NaN, "batb": [[1, 1.54, 55.61], [2, 1.01, 107.79]], "batl": [[0, 1.67, 41.5], [1, 1.69, 36.5], [2, 3.8, 27.43]]}, {"timestamp": 1631549360358, "ltp": 1.65, "tv": 15689.05, "trd": [[1.65, 86.1]], "batb": [[0, 1.54, 55.61], [1, 1.01, 107.79], [2, 1.01, 0]], "batl": [[0, 1.69, 36.5], [1, 3.8, 27.43], [2, 8.8, 7.22]]}, {"timestamp": 1631549362762, "ltp": 1.65, "tv": 15689.05, "trd": NaN, "batb": [[0, 1.6, 35.39], [1, 1.58, 41.56], [2, 1.54, 55.61]], "batl": [[0, 1.68, 36.64], [1, 1.69, 36.5], [2, 3.8, 27.43]]}, {"timestamp": 1631549363657, "ltp": 1.65, "tv": 15689.05, "trd": NaN, "batb": [[0, 1.67, 91.45]], "batl": [[0, 1.69, 36.5], [1, 3.8, 27.43], [2, 8.8, 7.22]]}, {"timestamp": 1631549366835, "ltp": 1.67, "tv": 15730.64, "trd": [[1.67, 58.06]], "batb": [[0, 1.67, 70.65], [1, 1.6, 34.94], [2, 1.58, 41.56]], "batl": [[0, 1.68, 38.89], [1, 1.69, 36.5], [2, 3.8, 27.43]]}, {"timestamp": 1631549367148, "ltp": 1.67, "tv": 15730.64, "trd": NaN, "batb": [[1, 1.58, 41.56], [2, 1.54, 55.61]], "batl": [[0, 1.69, 36.5], [1, 3.8, 27.43], [2, 8.8, 7.22]]}, {"timestamp": 1631549370771, "ltp": 1.67, "tv": 15730.64, "trd": NaN, "batb": [[0, 1.58, 41.56], [1, 1.54, 55.61], [2, 1.01, 107.79]], "batl": NaN}, {"timestamp": 1631549371773, "ltp": 1.67, "tv": 15730.64, "trd": NaN, "batb": [[0, 1.6, 343.8], [1, 1.58, 41.56], [2, 1.54, 55.61]], "batl": [[0, 1.64, 6.1], [1, 1.66, 125.96], [2, 1.67, 45.18]]}, {"timestamp": 1631549372774, "ltp": 1.67, "tv": 15730.64, "trd": NaN, "batb": [[1, 1.59, 18.86], [2, 1.58, 69.87]], "batl": [[1, 1.66, 53.68], [2, 1.67, 9.04]]}, {"timestamp": 1631549373870, "ltp": 1.65, "tv": 15767.07, "trd": [[1.64, 46.08], [1.65, 110.33]], "batb": [[0, 1.65, 40.32], [1, 1.6, 343.8], [2, 1.59, 18.86]], "batl": [[0, 1.66, 53.68], [1, 1.67, 9.04], [2, 1.68, 26.62]]}, {"timestamp": 1631549376778, "ltp": 1.62, "tv": 15868.8, "trd": [[1.62, 77.02], [1.65, 190.97]], "batb": [[0, 1.6, 343.8], [1, 1.59, 18.86], [2, 1.58, 51]], "batl": [[0, 1.64, 101.68], [1, 1.66, 53.68], [2, 1.67, 9.04]]}, {"timestamp": 1631549378489, "ltp": 1.62, "tv": 15868.8, "trd": NaN, "batb": [[1, 1.59, 58.97]], "batl": [[2, 1.67, 51.54]]}, {"timestamp": 1631549379682, "ltp": 1.64, "tv": 15868.96, "trd": [[1.64, 46.24]], "batb": [[0, 1.6, 388.89]], "batl": [[0, 1.64, 101.6], [1, 1.65, 40.3], [2, 1.66, 88.43]]}, {"timestamp": 1631549380881, "ltp": 1.64, "tv": 15868.96, "trd": NaN, "batb": [[0, 1.51, 59.81], [1, 1.01, 107.79], [2, 1.58, 0]], "batl": [[2, 1.66, 34.75]]}, {"timestamp": 1631549381249, "ltp": 1.64, "tv": 15868.96, "trd": NaN, "batb": NaN, "batl": [[0, 1.65, 40.3], [1, 3.8, 27.43], [2, 8.8, 7.22]]}, {"timestamp": 1631549383766, "ltp": 1.64, "tv": 15868.96, "trd": NaN, "batb": [[0, 1.6, 41.19], [1, 1.51, 59.81], [2, 1.01, 107.79]], "batl": NaN}, {"timestamp": 1631549386898, "ltp": 1.64, "tv": 15868.96, "trd": NaN, "batb": NaN, "batl": [[0, 1.62, 17.99], [1, 1.63, 92.02], [2, 1.64, 46]]}, {"timestamp": 1631549387882, "ltp": 1.64, "tv": 15868.96, "trd": NaN, "batb": [[2, 1.49, 63.16]], "batl": [[2, 1.64, 82.03]]}, {"timestamp": 1631549388220, "ltp": 1.64, "tv": 15868.96, "trd": NaN, "batb": NaN, "batl": [[1, 1.63, 55.21], [2, 1.64, 63.63]]}, {"timestamp": 1631549391885, "ltp": 1.6, "tv": 15904.72, "trd": [[1.6, 110.09]], "batb": [[0, 1.6, 23.31]], "batl": NaN}, {"timestamp": 1631549393285, "ltp": 1.6, "tv": 15904.72, "trd": NaN, "batb": NaN, "batl": [[0, 1.62, 163.99]]}, {"timestamp": 1631549395476, "ltp": 1.6, "tv": 15904.72, "trd": NaN, "batb": [[0, 1.59, 45.11], [1, 1.49, 63.16], [2, 1.01, 107.79]], "batl": [[0, 1.62, 146], [1, 1.63, 38.5], [2, 1.64, 35.18]]}, {"timestamp": 1631549396300, "ltp": 1.6, "tv": 15904.72, "trd": NaN, "batb": NaN, "batl": [[0, 1.64, 35.18], [1, 3.8, 27.43], [2, 8.8, 7.22]]}, {"timestamp": 1631549398903, "ltp": 1.6, "tv": 15912.27, "trd": [[1.6, 117.64]], "batb": NaN, "batl": NaN}, {"timestamp": 1631549416814, "ltp": 1.6, "tv": 15912.27, "trd": NaN, "batb": [[0, 1.62, 11.75], [1, 1.61, 98.43], [2, 1.6, 46.58]], "batl": [[1, 1.66, 20.97], [2, 1.67, 35.38]]}, {"timestamp": 1631549417699, "ltp": 1.6, "tv": 15912.27, "trd": NaN, "batb": [[1, 1.61, 23.91], [2, 1.6, 9.32]], "batl": [[1, 1.65, 6.06], [2, 1.66, 20.97]]}, {"timestamp": 1631549421502, "ltp": 1.61, "tv": 15959.89, "trd": [[1.61, 132.52], [1.62, 98.56]], "batb": [[0, 1.61, 10.87], [1, 1.6, 9.32], [2, 1.59, 54.43]], "batl": NaN}, {"timestamp": 1631549423318, "ltp": 1.61, "tv": 15959.89, "trd": NaN, "batb": NaN, "batl": [[0, 1.64, 169.18], [1, 1.65, 48.36], [2, 1.66, 59.22]]}, {"timestamp": 1631549426906, "ltp": 1.61, "tv": 15959.89, "trd": NaN, "batb": [[0, 1.55, 54.27], [1, 1.52, 58.21], [2, 1.51, 39.13]], "batl": [[0, 1.64, 134], [1, 1.65, 42.3], [2, 1.66, 38.25]]}, {"timestamp": 1631549427219, "ltp": 1.61, "tv": 15959.89, "trd": NaN, "batb": [[0, 1.52, 58.21], [1, 1.01, 107.79], [2, 1.51, 0]], "batl": [[2, 3.8, 27.43]]}, {"timestamp": 1631549427947, "ltp": 1.61, "tv": 15959.89, "trd": NaN, "batb": NaN, "batl": [[0, 1.65, 42.3], [1, 3.8, 27.43], [2, 8.8, 7.22]]}, {"timestamp": 1631549429821, "ltp": 1.61, "tv": 15959.89, "trd": NaN, "batb": [[0, 1.6, 40.74], [1, 1.52, 58.21], [2, 1.01, 107.79]], "batl": NaN}, {"timestamp": 1631549431028, "ltp": 1.61, "tv": 15959.89, "trd": NaN, "batb": [[0, 1.62, 14.44], [1, 1.6, 40.74], [2, 1.52, 58.21]], "batl": NaN}, {"timestamp": 1631549433739, "ltp": 1.61, "tv": 15959.89, "trd": NaN, "batb": [[1, 1.61, 39.09], [2, 1.6, 40.74]], "batl": [[0, 1.64, 38.68], [1, 1.65, 42.3], [2, 3.8, 27.43]]}, {"timestamp": 1631549434049, "ltp": 1.61, "tv": 15959.89, "trd": NaN, "batb": [[1, 1.6, 40.74], [2, 1.52, 58.21]], "batl": [[0, 1.65, 42.3], [1, 3.8, 27.43], [2, 8.8, 7.22]]}, {"timestamp": 1631549440844, "ltp": 1.61, "tv": 15959.89, "trd": NaN, "batb": [[1, 1.61, 38.09], [2, 1.6, 40.74]], "batl": [[0, 1.64, 37.43], [1, 1.65, 42.3], [2, 3.8, 27.43]]}, {"timestamp": 1631549441152, "ltp": 1.61, "tv": 15959.89, "trd": NaN, "batb": [[1, 1.6, 40.74], [2, 1.52, 58.21]], "batl": [[0, 1.65, 42.3], [1, 3.8, 27.43], [2, 8.8, 7.22]]}, {"timestamp": 1631549443768, "ltp": 1.62, "tv": 15988.78, "trd": [[1.62, 127.45]], "batb": [[0, 1.6, 40.74], [1, 1.52, 58.21], [2, 1.01, 107.79]], "batl": [[0, 1.62, 1.24], [1, 1.63, 6.13], [2, 1.64, 91.46]]}, {"timestamp": 1631549444763, "ltp": 1.62, "tv": 15988.78, "trd": NaN, "batb": [[1, 1.57, 95.54], [2, 1.56, 47.78]], "batl": [[2, 1.64, 54.88]]}, {"timestamp": 1631549445375, "ltp": 1.62, "tv": 15988.78, "trd": NaN, "batb": [[1, 1.58, 9.02], [2, 1.57, 19.1]], "batl": NaN}, {"timestamp": 1631549450451, "ltp": 1.63, "tv": 16003.52, "trd": [[1.62, 129.93], [1.63, 12.26]], "batb": [[0, 1.63, 1.28], [1, 1.6, 40.74], [2, 1.58, 9.02]], "batl": [[0, 1.64, 54.88], [1, 1.65, 105.54], [2, 1.66, 459.51]]}, {"timestamp": 1631549452584, "ltp": 1.63, "tv": 16003.52, "trd": NaN, "batb": [[0, 1.6, 40.74], [1, 1.58, 9.02], [2, 1.57, 19.1]], "batl": NaN}, {"timestamp": 1631549456873, "ltp": 1.63, "tv": 16003.52, "trd": NaN, "batb": NaN, "batl": [[0, 1.64, 71.52]]}, {"timestamp": 1631549457345, "ltp": 1.63, "tv": 16003.52, "trd": NaN, "batb": NaN, "batl": [[0, 1.63, 1.11], [1, 1.64, 71.52], [2, 1.65, 105.54]]}, {"timestamp": 1631549459868, "ltp": 1.64, "tv": 16006.08, "trd": [[1.63, 14.48], [1.64, 46.58]], "batb": NaN, "batl": [[0, 1.64, 71.35], [1, 1.65, 105.54], [2, 1.66, 459.51]]}, {"timestamp": 1631549460591, "ltp": 1.64, "tv": 16006.08, "trd": NaN, "batb": NaN, "batl": [[0, 1.64, 54.71]]}, {"timestamp": 1631549463180, "ltp": 1.64, "tv": 16006.08, "trd": NaN, "batb": NaN, "batl": [[0, 1.64, 71.35]]}, {"timestamp": 1631549466365, "ltp": 1.64, "tv": 16006.22, "trd": [[1.64, 46.72]], "batb": NaN, "batl": [[0, 1.64, 71.21]]}, {"timestamp": 1631549469870, "ltp": 1.64, "tv": 16006.22, "trd": NaN, "batb": [[0, 1.58, 9.02], [1, 1.52, 104.7], [2, 1.51, 49.99]], "batl": [[0, 1.65, 35.81], [1, 1.67, 17.69], [2, 1.68, 36.89]]}, {"timestamp": 1631549470127, "ltp": 1.64, "tv": 16006.22, "trd": NaN, "batb": [[1, 1.52, 46.49]], "batl": [[0, 1.7, 31.85], [1, 3.8, 27.43], [2, 8.8, 7.22]]}, {"timestamp": 1631549476905, "ltp": 1.64, "tv": 16006.22, "trd": NaN, "batb": NaN, "batl": [[0, 1.68, 38.39], [1, 1.7, 31.85], [2, 3.8, 27.43]]}, {"timestamp": 1631549477320, "ltp": 1.64, "tv": 16006.22, "trd": NaN, "batb": NaN, "batl": [[0, 1.7, 31.85], [1, 3.8, 27.43], [2, 8.8, 7.22]]}, {"timestamp": 1631549480534, "ltp": 1.64, "tv": 16006.22, "trd": NaN, "batb": NaN, "batl": [[0, 1.68, 36.14], [1, 1.7, 31.85], [2, 3.8, 27.43]]}, {"timestamp": 1631549481688, "ltp": 1.64, "tv": 16006.22, "trd": NaN, "batb": [[0, 1.68, 8.88], [1, 1.65, 90.92], [2, 1.64, 45.46]], "batl": [[0, 1.7, 31.85], [1, 3.8, 27.43], [2, 8.8, 7.22]]}, {"timestamp": 1631549482720, "ltp": 1.64, "tv": 16006.22, "trd": NaN, "batb": [[1, 1.67, 5.47], [2, 1.65, 54.55]], "batl": [[0, 1.69, 5.92], [1, 1.7, 31.85], [2, 1.72, 34.35]]}, {"timestamp": 1631549483294, "ltp": 1.64, "tv": 16006.22, "trd": NaN, "batb": [[2, 1.65, 18.18]], "batl": NaN}, {"timestamp": 1631549486811, "ltp": 1.66, "tv": 16035.04, "trd": [[1.66, 25.32], [1.67, 69], [1.68, 25.87]], "batb": [[0, 1.65, 18.18], [1, 1.64, 9.1], [2, 1.63, 9.1]], "batl": NaN}, {"timestamp": 1631549491891, "ltp": 1.66, "tv": 16035.04, "trd": NaN, "batb": [[0, 1.6, 46.09], [1, 1.58, 58.43], [2, 1.57, 42.57]], "batl": [[0, 1.69, 96]]}, {"timestamp": 1631549492305, "ltp": 1.66, "tv": 16035.04, "trd": NaN, "batb": [[0, 1.58, 9.02], [1, 1.57, 42.57], [2, 1.5, 61.57]], "batl": [[1, 1.75, 28.98], [2, 3.8, 27.43]]}, {"timestamp": 1631549493042, "ltp": 1.66, "tv": 16035.04, "trd": NaN, "batb": NaN, "batl": [[0, 1.75, 28.98], [1, 3.8, 27.43], [2, 8.8, 7.22]]}, {"timestamp": 1631549498744, "ltp": 1.66, "tv": 16035.04, "trd": NaN, "batb": NaN, "batl": [[0, 1.73, 31.5], [1, 1.75, 28.98], [2, 3.8, 27.43]]}, {"timestamp": 1631549499217, "ltp": 1.66, "tv": 16035.04, "trd": NaN, "batb": NaN, "batl": [[0, 1.75, 28.98], [1, 3.8, 27.43], [2, 8.8, 7.22]]}, {"timestamp": 1631549505878, "ltp": 1.66, "tv": 16035.04, "trd": NaN, "batb": NaN, "batl": [[0, 1.73, 36.5], [1, 1.75, 28.98], [2, 3.8, 27.43]]}, {"timestamp": 1631549506191, "ltp": 1.66, "tv": 16035.04, "trd": NaN, "batb": NaN, "batl": [[0, 1.75, 28.98], [1, 3.8, 27.43], [2, 8.8, 7.22]]}, {"timestamp": 1631549509487, "ltp": 1.66, "tv": 16035.04, "trd": NaN, "batb": [[0, 1.58, 18.29]], "batl": [[0, 1.6, 9.21], [1, 1.61, 6.21], [2, 1.62, 55.56]]}, {"timestamp": 1631549510576, "ltp": 1.66, "tv": 16035.04, "trd": NaN, "batb": NaN, "batl": [[2, 1.62, 18.52]]}, {"timestamp": 1631549514488, "ltp": 1.58, "tv": 16042.69, "trd": [[1.58, 123.65]], "batb": [[0, 1.58, 14.47]], "batl": NaN}, {"timestamp": 1631549523800, "ltp": 1.58, "tv": 16042.69, "trd": NaN, "batb": [[0, 1.44, 55.67], [1, 1.4, 80.02], [2, 1.01, 107.79]], "batl": [[0, 3.8, 27.43], [1, 8.8, 7.22], [2, 44, 7.22]]}, {"timestamp": 1631549526725, "ltp": 1.58, "tv": 16042.69, "trd": NaN, "batb": [[0, 1.6, 5.2], [1, 1.44, 55.67], [2, 1.4, 80.02]], "batl": [[0, 1.68, 36.39], [1, 1.71, 31.81], [2, 3.8, 27.43]]}, {"timestamp": 1631549527135, "ltp": 1.58, "tv": 16042.69, "trd": NaN, "batb": NaN, "batl": [[0, 1.71, 31.81], [1, 3.8, 27.43], [2, 8.8, 7.22]]}, {"timestamp": 1631549529714, "ltp": 1.58, "tv": 16042.69, "trd": NaN, "batb": [[0, 1.6, 5.74]], "batl": NaN}, {"timestamp": 1631549533820, "ltp": 1.58, "tv": 16042.69, "trd": NaN, "batb": NaN, "batl": [[0, 1.68, 36.39], [1, 1.71, 31.81], [2, 3.8, 27.43]]}, {"timestamp": 1631549534544, "ltp": 1.6, "tv": 16054.17, "trd": [[1.6, 129.12]], "batb": [[0, 1.47, 13.58], [1, 1.45, 644.44], [2, 1.44, 55.67]], "batl": [[0, 1.5, 11.31], [1, 1.51, 6.62], [2, 1.54, 38.37]]}, {"timestamp": 1631549539327, "ltp": 1.6, "tv": 16054.17, "trd": NaN, "batb": [[0, 1.47, 235.58]], "batl": NaN}, {"timestamp": 1631549543021, "ltp": 1.5, "tv": 16059.95, "trd": [[1.5, 73.72]], "batb": NaN, "batl": [[0, 1.5, 8.42]]}, {"timestamp": 1631549550584, "ltp": 1.5, "tv": 16060.15, "trd": [[1.5, 73.92]], "batb": NaN, "batl": [[0, 1.5, 8.32]]}, {"timestamp": 1631549551733, "ltp": 1.5, "tv": 16060.15, "trd": NaN, "batb": [[0, 1.47, 222], [1, 1.36, 71.68], [2, 1.32, 71.64]], "batl": [[0, 3.8, 27.43], [1, 8.8, 7.22], [2, 44, 7.22]]}, {"timestamp": 1631549553295, "ltp": 1.47, "tv": 16452.2, "trd": [[1.47, 1167.45]], "batb": [[0, 1.47, 25.92], [1, 1.32, 71.64], [2, 1.31, 110.89]], "batl": NaN}, {"timestamp": 1631549554911, "ltp": 1.47, "tv": 16452.2, "trd": NaN, "batb": [[0, 1.32, 71.64], [1, 1.31, 110.89], [2, 1.01, 107.79]], "batl": [[0, 1.64, 35.68], [1, 3.8, 27.43], [2, 8.8, 7.22]]}, {"timestamp": 1631549558400, "ltp": 1.47, "tv": 16452.2, "trd": NaN, "batb": NaN, "batl": [[0, 1.59, 181.28], [1, 1.64, 35.68], [2, 3.8, 27.43]]}, {"timestamp": 1631549559128, "ltp": 1.47, "tv": 16452.2, "trd": NaN, "batb": NaN, "batl": [[0, 1.64, 35.68], [1, 3.8, 27.43], [2, 8.8, 7.22]]}, {"timestamp": 1631549560699, "ltp": 1.47, "tv": 16452.2, "trd": NaN, "batb": [[0, 1.54, 581.17], [1, 1.53, 107.65], [2, 1.52, 29.22]], "batl": [[0, 1.62, 36.48], [1, 1.64, 53.69], [2, 3.8, 27.43]]}, {"timestamp": 1631549561532, "ltp": 1.47, "tv": 16452.2, "trd": NaN, "batb": [[0, 1.54, 542.21], [1, 1.53, 88.17], [2, 1.52, 9.74]], "batl": [[0, 1.59, 6.29], [1, 1.62, 36.48], [2, 1.64, 53.69]]}, {"timestamp": 1631549563729, "ltp": 1.47, "tv": 16452.2, "trd": NaN, "batb": NaN, "batl": [[1, 1.6, 23.77], [2, 1.62, 36.48]]}, {"timestamp": 1631549564412, "ltp": 1.47, "tv": 16452.2, "trd": NaN, "batb": NaN, "batl": [[0, 1.59, 187.57]]}, {"timestamp": 1631549573826, "ltp": 1.47, "tv": 16452.2, "trd": NaN, "batb": [[0, 1.48, 64.25], [1, 1.38, 57.46], [2, 1.37, 89.58]], "batl": [[0, 1.59, 181.28], [1, 1.68, 41.14], [2, 1.72, 31.41]]}, {"timestamp": 1631549573933, "ltp": 1.47, "tv": 16452.2, "trd": NaN, "batb": [[0, 1.38, 57.46], [1, 1.37, 89.58], [2, 1.01, 107.79]], "batl": NaN}, {"timestamp": 1631549576860, "ltp": 1.47, "tv": 16452.2, "trd": NaN, "batb": [[0, 1.43, 60.43], [1, 1.38, 57.46], [2, 1.37, 89.58]], "batl": NaN}, {"timestamp": 1631549577172, "ltp": 1.47, "tv": 16452.2, "trd": NaN, "batb": [[0, 1.38, 57.46], [1, 1.37, 89.58], [2, 1.01, 107.79]], "batl": NaN}, {"timestamp": 1631549578732, "ltp": 1.47, "tv": 16452.2, "trd": NaN, "batb": NaN, "batl": [[0, 1.72, 31.41], [1, 3.8, 27.43], [2, 8.8, 7.22]]}, {"timestamp": 1631549580258, "ltp": 1.47, "tv": 16452.2, "trd": NaN, "batb": [[0, 1.66, 2.37], [1, 1.63, 122.7], [2, 1.55, 38.12]], "batl": [[0, 1.7, 13.53], [1, 1.72, 65.76], [2, 1.74, 16.98]]}, {"timestamp": 1631549581260, "ltp": 1.47, "tv": 16452.2, "trd": NaN, "batb": [[2, 1.56, 51.84]], "batl": [[0, 1.69, 5.92], [1, 1.7, 13.53], [2, 1.72, 65.76]]}, {"timestamp": 1631549584572, "ltp": 1.47, "tv": 16452.2, "trd": NaN, "batb": NaN, "batl": [[1, 1.7, 183.08]]}, {"timestamp": 1631549586646, "ltp": 1.47, "tv": 16452.2, "trd": NaN, "batb": [[2, 1.57, 46.57]], "batl": NaN}, {"timestamp": 1631549593891, "ltp": 1.47, "tv": 16452.2, "trd": NaN, "batb": [[1, 1.57, 46.57], [2, 1.56, 51.84]], "batl": [[0, 1.7, 169.55], [1, 1.72, 65.76], [2, 1.74, 52.23]]}, {"timestamp": 1631549594396, "ltp": 1.47, "tv": 16452.2, "trd": NaN, "batb": [[0, 1.57, 46.57], [1, 1.54, 51.62], [2, 1.53, 47.33]], "batl": [[1, 1.75, 33.94], [2, 1.77, 38.5]]}, {"timestamp": 1631549597285, "ltp": 1.69, "tv": 16452.74, "trd": [[1.69, 0.54]], "batb": NaN, "batl": NaN}, {"timestamp": 1631549601666, "ltp": 1.69, "tv": 16452.74, "trd": NaN, "batb": NaN, "batl": [[1, 1.71, 304.39], [2, 1.75, 33.94]]}, {"timestamp": 1631549602877, "ltp": 1.69, "tv": 16452.74, "trd": NaN, "batb": [[0, 1.53, 47.33], [1, 1.47, 66.35], [2, 1.01, 107.79]], "batl": [[1, 1.75, 33.94], [2, 1.77, 38.5]]}, {"timestamp": 1631549604678, "ltp": 1.69, "tv": 16452.74, "trd": NaN, "batb": NaN, "batl": [[0, 1.68, 222]]}, {"timestamp": 1631549608584, "ltp": 1.69, "tv": 16452.74, "trd": NaN, "batb": NaN, "batl": [[1, 1.78, 30.25], [2, 3.8, 27.43]]}, {"timestamp": 1631549609681, "ltp": 1.69, "tv": 16452.74, "trd": NaN, "batb": [[0, 1.57, 44.57], [1, 1.53, 47.33], [2, 1.47, 66.35]], "batl": NaN}, {"timestamp": 1631549609998, "ltp": 1.69, "tv": 16452.74, "trd": NaN, "batb": [[0, 1.53, 47.33], [1, 1.47, 66.35], [2, 1.01, 107.79]], "batl": NaN}, {"timestamp": 1631549622811, "ltp": 1.69, "tv": 16452.74, "trd": NaN, "batb": NaN, "batl": [[0, 1.78, 30.25], [1, 3.8, 27.43], [2, 8.8, 7.22]]}, {"timestamp": 1631549625906, "ltp": 1.68, "tv": 16455.67, "trd": [[1.68, 28.8]], "batb": NaN, "batl": [[0, 1.58, 139.99], [1, 1.59, 1977.89], [2, 1.6, 93.76]]}, {"timestamp": 1631549626906, "ltp": 1.68, "tv": 16455.67, "trd": NaN, "batb": [[2, 1.46, 40.47]], "batl": [[0, 1.58, 89.36], [1, 1.59, 6.29], [2, 1.6, 56.26]]}, {"timestamp": 1631549627794, "ltp": 1.68, "tv": 16455.67, "trd": NaN, "batb": NaN, "batl": [[2, 1.6, 18.76]]}, {"timestamp": 1631549630891, "ltp": 1.68, "tv": 16455.67, "trd": NaN, "batb": NaN, "batl": [[0, 1.57, 19.73], [1, 1.58, 89.36], [2, 1.59, 6.29]]}, {"timestamp": 1631549631097, "ltp": 1.68, "tv": 16455.67, "trd": NaN, "batb": NaN, "batl": [[0, 1.58, 89.36], [1, 1.59, 6.29], [2, 1.6, 18.76]]}, {"timestamp": 1631549632423, "ltp": 1.68, "tv": 16455.67, "trd": NaN, "batb": NaN, "batl": [[0, 1.57, 183.59], [1, 1.58, 89.36], [2, 1.59, 6.29]]}, {"timestamp": 1631549634102, "ltp": 1.57, "tv": 16499.91, "trd": [[1.57, 210.65]], "batb": NaN, "batl": [[0, 1.57, 161.46]]}, {"timestamp": 1631549638711, "ltp": 1.57, "tv": 16508.53, "trd": [[1.57, 219.27]], "batb": NaN, "batl": [[0, 1.57, 157.15]]}, {"timestamp": 1631549643252, "ltp": 1.57, "tv": 16508.53, "trd": NaN, "batb": [[2, 1.36, 92.18]], "batl": NaN}, {"timestamp": 1631549645139, "ltp": 1.57, "tv": 16512.13, "trd": [[1.57, 222.87]], "batb": NaN, "batl": [[0, 1.57, 155.35]]}, {"timestamp": 1631549646771, "ltp": 1.57, "tv": 16512.13, "trd": NaN, "batb": [[0, 1.47, 66.35], [1, 1.36, 92.18], [2, 1.01, 107.79]], "batl": [[1, 3.8, 27.43], [2, 8.8, 7.22]]}, {"timestamp": 1631549647083, "ltp": 1.57, "tv": 16512.13, "trd": NaN, "batb": [[0, 1.36, 91.6], [1, 1.01, 107.79], [2, 1.01, 0]], "batl": NaN}, {"timestamp": 1631549654765, "ltp": 1.57, "tv": 16512.13, "trd": NaN, "batb": [[0, 1.42, 17.58], [1, 1.4, 336.86], [2, 1.36, 91.6]], "batl": [[0, 1.44, 11], [1, 1.46, 109.59], [2, 1.47, 2273.1]]}, {"timestamp": 1631549655760, "ltp": 1.57, "tv": 16512.13, "trd": NaN, "batb": [[1, 1.4, 444], [2, 1.39, 53.58]], "batl": [[1, 1.46, 68.49], [2, 1.47, 30.82]]}, {"timestamp": 1631549656081, "ltp": 1.57, "tv": 16512.13, "trd": NaN, "batb": [[1, 1.4, 358.28], [2, 1.39, 10.72]], "batl": NaN}, {"timestamp": 1631549659789, "ltp": 1.42, "tv": 16547.29, "trd": [[1.42, 235.19]], "batb": [[0, 1.4, 358.28], [1, 1.39, 10.72], [2, 1.38, 10.72]], "batl": [[0, 1.42, 154.18], [1, 1.44, 11], [2, 1.45, 24.64]]}, {"timestamp": 1631549659948, "ltp": 1.42, "tv": 16547.29, "trd": NaN, "batb": NaN, "batl": [[2, 1.46, 68.49]]}, {"timestamp": 1631549669772, "ltp": 1.42, "tv": 16547.29, "trd": NaN, "batb": NaN, "batl": [[1, 1.46, 68.49], [2, 1.47, 30.82]]}, {"timestamp": 1631549671607, "ltp": 1.42, "tv": 16547.29, "trd": NaN, "batb": [[0, 1.36, 91.6], [1, 1.26, 93.98], [2, 1.24, 147.29]], "batl": [[1, 1.57, 40.5], [2, 1.62, 37.25]]}, {"timestamp": 1631549672603, "ltp": 1.42, "tv": 16549.41, "trd": [[1.42, 237.31]], "batb": [[0, 1.41, 15.19], [1, 1.24, 147.29], [2, 1.21, 121.69]], "batl": [[0, 1.42, 152.06], [1, 1.43, 14.49], [2, 1.57, 40.5]]}, {"timestamp": 1631549672914, "ltp": 1.42, "tv": 16549.41, "trd": NaN, "batb": [[0, 1.24, 147.29], [1, 1.21, 121.69], [2, 1.01, 107.79]], "batl": [[1, 1.57, 40.5], [2, 1.62, 37.25]]}, {"timestamp": 1631549677366, "ltp": 1.42, "tv": 16549.41, "trd": NaN, "batb": NaN, "batl": [[1, 3.8, 27.43], [2, 8.8, 7.22]]}, {"timestamp": 1631549678890, "ltp": 1.42, "tv": 16549.41, "trd": NaN, "batb": [[0, 1.26, 109.98], [1, 1.24, 147.29], [2, 1.21, 121.69]], "batl": NaN}, {"timestamp": 1631549679046, "ltp": 1.42, "tv": 16549.41, "trd": NaN, "batb": [[0, 1.24, 147.29], [1, 1.21, 121.69], [2, 1.01, 107.79]], "batl": NaN}, {"timestamp": 1631549680866, "ltp": 1.42, "tv": 16549.41, "trd": NaN, "batb": [[0, 1.25, 594.23], [1, 1.24, 194.95], [2, 1.22, 24.22]], "batl": [[0, 1.28, 14.38], [1, 1.32, 7.58], [2, 1.36, 43.45]]}, {"timestamp": 1631549684816, "ltp": 1.42, "tv": 16549.41, "trd": NaN, "batb": NaN, "batl": [[0, 1.28, 183.07]]}, {"timestamp": 1631549685289, "ltp": 1.28, "tv": 16567.66, "trd": [[1.28, 201.13]], "batb": NaN, "batl": [[0, 1.28, 164.82]]}, {"timestamp": 1631549689715, "ltp": 1.26, "tv": 16578.24, "trd": [[1.26, 37.25]], "batb": NaN, "batl": NaN}, {"timestamp": 1631549692732, "ltp": 1.28, "tv": 16586.86, "trd": [[1.28, 209.75]], "batb": NaN, "batl": [[0, 1.28, 160.51]]}, {"timestamp": 1631549695249, "ltp": 1.28, "tv": 16588.66, "trd": [[1.28, 211.55]], "batb": NaN, "batl": [[0, 1.28, 159.61]]}, {"timestamp": 1631549704837, "ltp": 1.28, "tv": 16588.66, "trd": NaN, "batb": NaN, "batl": [[0, 1.28, 381.61]]}, {"timestamp": 1631549757145, "ltp": 1.28, "tv": 16594.08, "trd": [[1.28, 216.97]], "batb": NaN, "batl": [[0, 1.28, 378.9]]}, {"timestamp": 1631549760830, "ltp": 1.28, "tv": 16595.88, "trd": [[1.28, 218.77]], "batb": NaN, "batl": [[0, 1.28, 378]]}, {"timestamp": 1631549767229, "ltp": 1.28, "tv": 16595.88, "trd": NaN, "batb": [[1, 1.24, 147.29], [2, 1.21, 121.69]], "batl": [[2, 1.53, 15.36]]}, {"timestamp": 1631549770469, "ltp": 1.28, "tv": 16595.88, "trd": NaN, "batb": [[1, 1.24, 242.56], [2, 1.22, 111.34]], "batl": [[2, 1.41, 67.5]]}, {"timestamp": 1631549776873, "ltp": 1.28, "tv": 16595.88, "trd": NaN, "batb": [[0, 1.24, 242.56], [1, 1.22, 111.34], [2, 1.21, 121.69]], "batl": [[1, 1.41, 67.5], [2, 1.46, 56.75]]}, {"timestamp": 1631549777608, "ltp": 1.28, "tv": 16595.88, "trd": NaN, "batb": [[0, 1.22, 111.34], [1, 1.2, 179.25], [2, 1.01, 107.79]], "batl": NaN}, {"timestamp": 1631549780377, "ltp": 1.28, "tv": 16595.88, "trd": NaN, "batb": [[0, 1.24, 100.52], [1, 1.22, 111.34], [2, 1.2, 179.25]], "batl": NaN}, {"timestamp": 1631549781212, "ltp": 1.28, "tv": 16596.27, "trd": [[1.28, 219.16]], "batb": [[0, 1.22, 111.34], [1, 1.2, 179.25], [2, 1.01, 107.79]], "batl": [[0, 1.28, 377.81]]}, {"timestamp": 1631549787796, "ltp": 1.28, "tv": 16596.27, "trd": NaN, "batb": [[0, 1.24, 107.27], [1, 1.22, 111.34], [2, 1.2, 179.25]], "batl": NaN}, {"timestamp": 1631549788105, "ltp": 1.28, "tv": 16596.27, "trd": NaN, "batb": [[0, 1.22, 111.34], [1, 1.2, 179.25], [2, 1.01, 107.79]], "batl": NaN}, {"timestamp": 1631549791291, "ltp": 1.28, "tv": 16596.27, "trd": NaN, "batb": NaN, "batl": [[2, 1.53, 15.36]]}, {"timestamp": 1631549793804, "ltp": 1.28, "tv": 16621.67, "trd": [[1.28, 244.56]], "batb": NaN, "batl": [[0, 1.28, 352.41]]}, {"timestamp": 1631549794704, "ltp": 1.28, "tv": 16621.67, "trd": NaN, "batb": [[0, 1.23, 656.9], [1, 1.22, 111.34], [2, 1.21, 48.84]], "batl": [[0, 1.25, 109.17], [1, 1.27, 745.29], [2, 1.28, 360.22]]}, {"timestamp": 1631549795441, "ltp": 1.28, "tv": 16621.67, "trd": NaN, "batb": [[1, 1.22, 135.94], [2, 1.21, 69.4]], "batl": NaN}, {"timestamp": 1631549798712, "ltp": 1.28, "tv": 16621.67, "trd": NaN, "batb": NaN, "batl": [[2, 1.28, 7.81]]}, {"timestamp": 1631549799339, "ltp": 1.25, "tv": 16717.99, "trd": [[1.25, 328.47]], "batb": NaN, "batl": [[0, 1.25, 12.85]]}, {"timestamp": 1631549800797, "ltp": 1.25, "tv": 16717.99, "trd": NaN, "batb": [[2, 1.21, 191.09]], "batl": NaN}, {"timestamp": 1631549802823, "ltp": 1.25, "tv": 16717.99, "trd": NaN, "batb": NaN, "batl": [[1, 1.26, 132.48], [2, 1.27, 745.29]]}, {"timestamp": 1631549804817, "ltp": 1.25, "tv": 16717.99, "trd": NaN, "batb": [[0, 1.2, 139.42], [1, 1.17, 213.64], [2, 1.01, 107.79]], "batl": [[0, 1.26, 132.48], [1, 1.32, 79.61], [2, 1.35, 65.9]]}, {"timestamp": 1631549807845, "ltp": 1.25, "tv": 16717.99, "trd": NaN, "batb": [[0, 1.21, 108.69], [1, 1.2, 139.42], [2, 1.17, 213.64]], "batl": NaN}, {"timestamp": 1631549808109, "ltp": 1.25, "tv": 16717.99, "trd": NaN, "batb": [[0, 1.2, 139.42], [1, 1.17, 213.64], [2, 1.01, 107.79]], "batl": NaN}, {"timestamp": 1631549810047, "ltp": 1.25, "tv": 16717.99, "trd": NaN, "batb": NaN, "batl": [[1, 1.31, 222], [2, 1.32, 79.61]]}, {"timestamp": 1631549826290, "ltp": 1.25, "tv": 16717.99, "trd": NaN, "batb": NaN, "batl": [[0, 1.35, 65.9], [1, 1.41, 67.5], [2, 1.53, 15.36]]}, {"timestamp": 1631549828288, "ltp": 1.25, "tv": 16717.99, "trd": NaN, "batb": [[0, 1.28, 3.16], [1, 1.27, 157.48], [2, 1.26, 46.9]], "batl": [[0, 1.3, 17.75], [1, 1.33, 778.44], [2, 1.35, 65.9]]}, {"timestamp": 1631549829386, "ltp": 1.25, "tv": 16717.99, "trd": NaN, "batb": NaN, "batl": [[1, 1.33, 785.96]]}, {"timestamp": 1631549832130, "ltp": 1.25, "tv": 16717.99, "trd": NaN, "batb": NaN, "batl": [[1, 1.32, 126.46], [2, 1.33, 785.96]]}, {"timestamp": 1631549843749, "ltp": 1.28, "tv": 16719.79, "trd": [[1.28, 246.36]], "batb": [[0, 1.28, 2.26]], "batl": NaN}, {"timestamp": 1631549845739, "ltp": 1.28, "tv": 16719.79, "trd": NaN, "batb": [[0, 1.22, 95.34], [1, 1.21, 174.22], [2, 1.2, 139.42]], "batl": [[0, 1.32, 126.46], [1, 1.41, 67.5], [2, 1.45, 47.7]]}, {"timestamp": 1631549848817, "ltp": 1.28, "tv": 16719.79, "trd": NaN, "batb": [[1, 1.2, 175.56], [2, 1.01, 107.79]], "batl": NaN}, {"timestamp": 1631549849738, "ltp": 1.28, "tv": 16719.79, "trd": NaN, "batb": NaN, "batl": [[0, 1.45, 47.7], [1, 1.53, 15.36], [2, 3.8, 27.43]]}, {"timestamp": 1631549852747, "ltp": 1.28, "tv": 16719.79, "trd": NaN, "batb": [[0, 1.24, 102.77], [1, 1.22, 95.34], [2, 1.2, 175.56]], "batl": [[0, 1.41, 62.5], [1, 1.45, 47.7], [2, 1.53, 15.36]]}, {"timestamp": 1631549853069, "ltp": 1.28, "tv": 16719.79, "trd": NaN, "batb": [[0, 1.22, 95.34], [1, 1.2, 175.56], [2, 1.01, 107.79]], "batl": [[0, 1.35, 123.65]]}, {"timestamp": 1631549856663, "ltp": 1.28, "tv": 16719.79, "trd": NaN, "batb": NaN, "batl": [[1, 1.41, 65.5], [2, 1.45, 47.7]]}, {"timestamp": 1631549859844, "ltp": 1.28, "tv": 16719.79, "trd": NaN, "batb": [[0, 1.24, 90.02], [1, 1.22, 95.34], [2, 1.2, 175.56]], "batl": NaN}, {"timestamp": 1631549860162, "ltp": 1.28, "tv": 16719.79, "trd": NaN, "batb": [[0, 1.22, 95.34], [1, 1.2, 175.56], [2, 1.01, 107.79]], "batl": NaN}, {"timestamp": 1631549862725, "ltp": 1.28, "tv": 16719.79, "trd": NaN, "batb": [[0, 1.24, 15.67], [1, 1.22, 95.34], [2, 1.21, 48.84]], "batl": [[0, 1.26, 40.85], [1, 1.28, 967.43], [2, 1.31, 45.11]]}, {"timestamp": 1631549863765, "ltp": 1.28, "tv": 16719.79, "trd": NaN, "batb": [[1, 1.22, 103.54]], "batl": NaN}, {"timestamp": 1631549868838, "ltp": 1.28, "tv": 16719.79, "trd": NaN, "batb": NaN, "batl": [[1, 1.27, 131.44], [2, 1.28, 967.43]]}, {"timestamp": 1631549869258, "ltp": 1.28, "tv": 16719.79, "trd": NaN, "batb": [[2, 1.21, 154.53]]