{"info": {"id": "1.187595435", "eventId": "30897896", "eventName": "Match Odds", "marketType": "MATCH_ODDS", "openDate": 1631529985401, "name": "M Gutierrez Carrasco v I Ghioroaie", "numberOfActiveRunner": 2, "countryCode": "", "sport": "TENNIS", "venue": "", "volume": {"total": 26677.27, "preMatch": 36.76, "inPlay": 26640.51}, "winner": {"id": 11252269, "name": "I Ghioroaie", "status": "WINNER", "position": 2}, "delay": 5}, "runners": [{"id": 9634224, "name": "M Gutierrez Carrasco", "status": "LOSER", "position": 1, "inPlayOdds": 2.84, "inPlayTime": 1631530751396, "avgPrematch": 0, "closedOdds": 12.0, "maxPrematch": -100, "minPrematch": 1001, "maxInPlay": 21.0, "minInPlay": 2.0, "inPlayIndex": 0, "lengthOdds": 406, "lengthOddsPrematch": 0, "lengthOddsInPlay": 406, "tradedVolume": 315.53, "preMatchVolume": 8.66, "inPlayVolume": 306.87}, {"id": 11252269, "name": "I Ghioroaie", "status": "WINNER", "position": 2, "inPlayOdds": 1.54, "inPlayTime": 1631531266803, "avgPrematch": 0, "closedOdds": 1.01, "maxPrematch": -100, "minPrematch": 1001, "maxInPlay": 1.87, "minInPlay": 1.01, "inPlayIndex": 0, "lengthOdds": 506, "lengthOddsPrematch": 0, "lengthOddsInPlay": 506, "tradedVolume": 26361.74, "preMatchVolume": 28.1, "inPlayVolume": 26333.64}], "marketUpdates": [{"timestamp": 1631518765917000000, "openDate": "2021-09-13T11:00:00.000Z", "status": "OPEN", "betDelay": 0, "inPlay": false, "complete": true}, {"timestamp": 1631525178551000000, "openDate": "2021-09-13T10:55:00.000Z", "status": "OPEN", "betDelay": 0, "inPlay": false, "complete": true}, {"timestamp": 1631526089043000000, "openDate": "2021-09-13T11:05:00.000Z", "status": "OPEN", "betDelay": 0, "inPlay": false, "complete": true}, {"timestamp": 1631529685245000000, "openDate": "2021-09-13T10:45:00.000Z", "status": "OPEN", "betDelay": 0, "inPlay": false, "complete": true}, {"timestamp": 1631529985401000000, "openDate": "2021-09-13T10:45:00.000Z", "status": "OPEN", "betDelay": 5, "inPlay": true, "complete": true}, {"timestamp": 1631530349885000000, "openDate": "2021-09-13T10:52:26.000Z", "status": "OPEN", "betDelay": 5, "inPlay": true, "complete": true}, {"timestamp": 1631538408171000000, "openDate": "2021-09-13T10:52:26.000Z", "status": "SUSPENDED", "betDelay": 5, "inPlay": true, "complete": true}, {"timestamp": 1631538416217000000, "openDate": "2021-09-13T10:52:26.000Z", "status": "CLOSED", "betDelay": 5, "inPlay": true, "complete": true}], "odds": [{"runnerId": 9634224, "odds": [{"timestamp": 1631530751396, "ltp": 2.84, "tv": 8.66, "trd": [[2.84, 8.66]], "batb": NaN, "batl": [[0, 2.84, 102.22]]}, {"timestamp": 1631530752012, "ltp": 2.84, "tv": 8.66, "trd": NaN, "batb": NaN, "batl": [[1, 4.2, 150.36]]}, {"timestamp": 1631530759015, "ltp": 2.84, "tv": 98.81, "trd": [[2.84, 98.82]], "batb": NaN, "batl": [[0, 2.84, 57.14]]}, {"timestamp": 1631530797666, "ltp": 2.84, "tv": 98.81, "trd": NaN, "batb": NaN, "batl": [[1, 4.2, 0]]}, {"timestamp": 1631530803580, "ltp": 2.84, "tv": 98.61, "trd": [[2.84, 98.62]], "batb": [[0, 2.04, 399.53]], "batl": [[0, 2.84, 57.02], [1, 3.65, 172.76]]}, {"timestamp": 1631530829111, "ltp": 2.84, "tv": 98.61, "trd": NaN, "batb": NaN, "batl": [[1, 3.65, 0]]}, {"timestamp": 1631530834826, "ltp": 2.84, "tv": 98.61, "trd": NaN, "batb": NaN, "batl": [[1, 3.45, 182.89]]}, {"timestamp": 1631530866644, "ltp": 2.84, "tv": 98.61, "trd": NaN, "batb": [[0, 1.01, 7], [1, 1.01, 0]], "batl": [[1, 3.45, 0]]}, {"timestamp": 1631530871996, "ltp": 2.84, "tv": 98.61, "trd": NaN, "batb": [[0, 1.82, 406.77], [1, 1.01, 7]], "batl": [[1, 3.15, 203.19]]}, {"timestamp": 1631530986595, "ltp": 2.84, "tv": 98.61, "trd": NaN, "batb": NaN, "batl": [[1, 3.15, 0]]}, {"timestamp": 1631530992536, "ltp": 2.84, "tv": 98.61, "trd": NaN, "batb": NaN, "batl": [[1, 3, 216.4]]}, {"timestamp": 1631531025250, "ltp": 2.84, "tv": 98.61, "trd": NaN, "batb": [[0, 1.01, 7], [1, 1.01, 0]], "batl": [[1, 3, 0]]}, {"timestamp": 1631531030958, "ltp": 2.84, "tv": 98.61, "trd": NaN, "batb": [[0, 1.97, 400.31], [1, 1.01, 7]], "batl": [[1, 3.65, 172.76]]}, {"timestamp": 1631531254927, "ltp": 2.84, "tv": 98.61, "trd": NaN, "batb": [[0, 1.01, 7], [1, 1.01, 0]], "batl": [[1, 3.65, 0]]}, {"timestamp": 1631531260689, "ltp": 2.84, "tv": 98.61, "trd": NaN, "batb": [[0, 2.22, 389.82], [1, 1.01, 7]], "batl": [[1, 4.6, 137.93]]}, {"timestamp": 1631531266803, "ltp": 2.84, "tv": 113.86, "trd": [[2.84, 113.86]], "batb": NaN, "batl": [[0, 2.84, 41.78]]}, {"timestamp": 1631531292339, "ltp": 2.84, "tv": 113.86, "trd": NaN, "batb": [[0, 1.01, 7], [1, 1.01, 0]], "batl": [[1, 4.6, 0]]}, {"timestamp": 1631531298582, "ltp": 2.84, "tv": 124.6, "trd": [[2.84, 124.61]], "batb": [[0, 2.38, 387.57], [1, 1.01, 7]], "batl": [[0, 2.84, 36.4], [1, 5.3, 120.43]]}, {"timestamp": 1631531299551, "ltp": 2.84, "tv": 178.35, "trd": [[2.84, 178.35]], "batb": NaN, "batl": [[0, 2.84, 9.53]]}, {"timestamp": 1631531300574, "ltp": 2.84, "tv": 197.41, "trd": [[2.84, 197.42]], "batb": [[0, 2.84, 76.19], [1, 2.38, 387.57], [2, 1.01, 7]], "batl": [[0, 5.3, 120.43], [1, 5.3, 0]]}, {"timestamp": 1631531301570, "ltp": 2.84, "tv": 197.41, "trd": NaN, "batb": [[0, 2.84, 331.29]], "batl": NaN}, {"timestamp": 1631531302555, "ltp": 2.84, "tv": 197.41, "trd": NaN, "batb": [[0, 2.84, 256.1]], "batl": NaN}, {"timestamp": 1631531303586, "ltp": 2.84, "tv": 197.41, "trd": NaN, "batb": [[0, 2.84, 130]], "batl": NaN}, {"timestamp": 1631531304580, "ltp": 2.84, "tv": 197.41, "trd": NaN, "batb": [[0, 2.84, 141.96]], "batl": NaN}, {"timestamp": 1631531305366, "ltp": 2.84, "tv": 197.41, "trd": NaN, "batb": [[0, 2.84, 85.47]], "batl": NaN}, {"timestamp": 1631531306501, "ltp": 2.84, "tv": 197.41, "trd": NaN, "batb": [[0, 2.38, 387.57], [1, 1.01, 7], [2, 1.01, 0]], "batl": NaN}, {"timestamp": 1631531333208, "ltp": 2.84, "tv": 197.41, "trd": NaN, "batb": NaN, "batl": [[0, 4.6, 137.93]]}, {"timestamp": 1631531367557, "ltp": 2.84, "tv": 197.41, "trd": NaN, "batb": NaN, "batl": [[0, 5.5, 116.64]]}, {"timestamp": 1631531403839, "ltp": 2.84, "tv": 197.41, "trd": NaN, "batb": [[0, 1.01, 7], [1, 1.01, 0]], "batl": NaN}, {"timestamp": 1631531410187, "ltp": 2.84, "tv": 197.41, "trd": NaN, "batb": [[0, 2.52, 386.72], [1, 1.01, 7]], "batl": NaN}, {"timestamp": 1631531444436, "ltp": 2.84, "tv": 197.41, "trd": NaN, "batb": [[0, 1.01, 7], [1, 1.01, 0]], "batl": NaN}, {"timestamp": 1631531591434, "ltp": 2.84, "tv": 197.41, "trd": NaN, "batb": [[0, 2.52, 386.72], [1, 1.01, 7]], "batl": [[0, 6, 107.64]]}, {"timestamp": 1631531631760, "ltp": 2.84, "tv": 197.41, "trd": NaN, "batb": NaN, "batl": [[0, 5.3, 120.43]]}, {"timestamp": 1631531662410, "ltp": 2.84, "tv": 197.41, "trd": NaN, "batb": [[0, 1.01, 7], [1, 1.01, 0]], "batl": NaN}, {"timestamp": 1631531668138, "ltp": 2.84, "tv": 197.41, "trd": NaN, "batb": [[0, 2.22, 389.82], [1, 1.01, 7]], "batl": [[0, 4.6, 137.93]]}, {"timestamp": 1631531710079, "ltp": 2.84, "tv": 197.41, "trd": NaN, "batb": [[0, 1.01, 7], [1, 1.01, 0]], "batl": NaN}, {"timestamp": 1631531715714, "ltp": 2.84, "tv": 197.41, "trd": NaN, "batb": [[0, 2.38, 387.57], [1, 1.01, 7]], "batl": [[0, 5.3, 120.43]]}, {"timestamp": 1631531758267, "ltp": 2.84, "tv": 197.41, "trd": NaN, "batb": NaN, "batl": [[0, 4.6, 137.93]]}, {"timestamp": 1631531799395, "ltp": 2.84, "tv": 197.41, "trd": NaN, "batb": [[0, 1.01, 7], [1, 1.01, 0]], "batl": NaN}, {"timestamp": 1631531805629, "ltp": 2.84, "tv": 197.41, "trd": NaN, "batb": [[0, 2.04, 399.53], [1, 1.01, 7]], "batl": [[0, 3.9, 160.43]]}, {"timestamp": 1631531907948, "ltp": 2.84, "tv": 197.41, "trd": NaN, "batb": [[0, 1.01, 7], [1, 1.01, 0]], "batl": NaN}, {"timestamp": 1631531914092, "ltp": 2.84, "tv": 197.41, "trd": NaN, "batb": [[0, 2.22, 389.82], [1, 1.01, 7]], "batl": [[0, 4.6, 137.93]]}, {"timestamp": 1631531945371, "ltp": 2.84, "tv": 197.41, "trd": NaN, "batb": NaN, "batl": [[0, 3.9, 160.43]]}, {"timestamp": 1631531969800, "ltp": 2.84, "tv": 197.41, "trd": NaN, "batb": NaN, "batl": [[0, 4.6, 137.93]]}, {"timestamp": 1631532009637, "ltp": 2.84, "tv": 197.41, "trd": NaN, "batb": [[0, 1.01, 7], [1, 1.01, 0]], "batl": NaN}, {"timestamp": 1631532015142, "ltp": 2.84, "tv": 197.41, "trd": NaN, "batb": [[0, 2.38, 387.57], [1, 1.01, 7]], "batl": [[0, 5.3, 120.43]]}, {"timestamp": 1631532044197, "ltp": 2.84, "tv": 197.41, "trd": NaN, "batb": [[0, 1.01, 7], [1, 1.01, 0]], "batl": NaN}, {"timestamp": 1631532050396, "ltp": 2.84, "tv": 197.41, "trd": NaN, "batb": [[0, 2.52, 386.72], [1, 1.01, 7]], "batl": [[0, 6, 107.64]]}, {"timestamp": 1631532165044, "ltp": 2.84, "tv": 197.41, "trd": NaN, "batb": NaN, "batl": [[0, 5.3, 120.43]]}, {"timestamp": 1631532199136, "ltp": 2.84, "tv": 197.41, "trd": NaN, "batb": NaN, "batl": [[0, 6, 107.64]]}, {"timestamp": 1631532241538, "ltp": 2.84, "tv": 197.41, "trd": NaN, "batb": [[0, 1.01, 7], [1, 1.01, 0]], "batl": NaN}, {"timestamp": 1631532247440, "ltp": 2.84, "tv": 197.41, "trd": NaN, "batb": [[0, 2.72, 383.47], [1, 1.01, 7]], "batl": [[0, 7.2, 93.45]]}, {"timestamp": 1631532324922, "ltp": 2.84, "tv": 197.41, "trd": NaN, "batb": NaN, "batl": [[0, 6, 107.64]]}, {"timestamp": 1631532347237, "ltp": 2.84, "tv": 197.41, "trd": NaN, "batb": NaN, "batl": [[0, 5.3, 120.43]]}, {"timestamp": 1631532388397, "ltp": 2.84, "tv": 197.41, "trd": NaN, "batb": NaN, "batl": [[0, 6, 107.64]]}, {"timestamp": 1631532458419, "ltp": 2.84, "tv": 197.41, "trd": NaN, "batb": NaN, "batl": [[0, 8.2, 86.64]]}, {"timestamp": 1631532590818, "ltp": 2.84, "tv": 197.41, "trd": NaN, "batb": NaN, "batl": [[0, 7.2, 93.45]]}, {"timestamp": 1631532626480, "ltp": 2.84, "tv": 197.41, "trd": NaN, "batb": NaN, "batl": [[0, 8.2, 86.64]]}, {"timestamp": 1631532663050, "ltp": 2.84, "tv": 197.41, "trd": NaN, "batb": [[0, 1.01, 7], [1, 1.01, 0]], "batl": NaN}, {"timestamp": 1631532669693, "ltp": 2.84, "tv": 197.41, "trd": NaN, "batb": [[0, 2.98, 379.45], [1, 1.01, 7]], "batl": [[0, 9.4, 79.11]]}, {"timestamp": 1631532719646, "ltp": 2.84, "tv": 197.41, "trd": NaN, "batb": NaN, "batl": [[0, 10.5, 73.32]]}, {"timestamp": 1631532759288, "ltp": 2.84, "tv": 197.41, "trd": NaN, "batb": NaN, "batl": [[0, 12, 68.71]]}, {"timestamp": 1631532958144, "ltp": 2.84, "tv": 197.41, "trd": NaN, "batb": [[0, 1.01, 7], [1, 1.01, 0]], "batl": NaN}, {"timestamp": 1631532963851, "ltp": 2.84, "tv": 197.41, "trd": NaN, "batb": [[0, 3.4, 381.29], [1, 1.01, 7]], "batl": [[0, 15.5, 60.46]]}, {"timestamp": 1631532983244, "ltp": 2.84, "tv": 197.41, "trd": NaN, "batb": NaN, "batl": [[0, 13.5, 64.96]]}, {"timestamp": 1631532995255, "ltp": 2.84, "tv": 197.41, "trd": NaN, "batb": NaN, "batl": [[0, 15.5, 60.46]]}, {"timestamp": 1631533033818, "ltp": 2.84, "tv": 197.41, "trd": NaN, "batb": NaN, "batl": [[0, 18, 56.98]]}, {"timestamp": 1631533070681, "ltp": 2.84, "tv": 197.41, "trd": NaN, "batb": NaN, "batl": [[0, 21, 54.22]]}, {"timestamp": 1631533155313, "ltp": 17.5, "tv": 197.62, "trd": [[17.5, 0.2]], "batb": NaN, "batl": NaN}, {"timestamp": 1631533174210, "ltp": 17.5, "tv": 197.62, "trd": NaN, "batb": NaN, "batl": [[0, 18, 56.78]]}, {"timestamp": 1631533187231, "ltp": 17.5, "tv": 197.62, "trd": NaN, "batb": NaN, "batl": [[0, 21, 54.04]]}, {"timestamp": 1631533199266, "ltp": 17.5, "tv": 197.62, "trd": NaN, "batb": [[0, 1.01, 7], [1, 1.01, 0]], "batl": NaN}, {"timestamp": 1631533357914, "ltp": 17.5, "tv": 197.62, "trd": NaN, "batb": [[0, 3.6, 380.36], [1, 1.01, 7]], "batl": [[0, 21, 54.04]]}, {"timestamp": 1631533392338, "ltp": 17.5, "tv": 197.62, "trd": NaN, "batb": NaN, "batl": [[0, 34, 46.6]]}, {"timestamp": 1631533420078, "ltp": 17.5, "tv": 197.62, "trd": NaN, "batb": NaN, "batl": [[0, 21, 54.04]]}, {"timestamp": 1631533450669, "ltp": 17.5, "tv": 197.62, "trd": NaN, "batb": NaN, "batl": [[0, 15.5, 60.22]]}, {"timestamp": 1631533480077, "ltp": 17.5, "tv": 197.62, "trd": NaN, "batb": NaN, "batl": [[0, 21, 54.04]]}, {"timestamp": 1631533512675, "ltp": 17.5, "tv": 197.62, "trd": NaN, "batb": NaN, "batl": [[0, 15.5, 60.22]]}, {"timestamp": 1631533540297, "ltp": 17.5, "tv": 197.62, "trd": NaN, "batb": NaN, "batl": [[0, 12, 68.41]]}, {"timestamp": 1631533628891, "ltp": 17.5, "tv": 197.62, "trd": NaN, "batb": NaN, "batl": [[0, 15.5, 60.22]]}, {"timestamp": 1631533651406, "ltp": 17.5, "tv": 197.62, "trd": NaN, "batb": NaN, "batl": [[0, 21, 54.04]]}, {"timestamp": 1631533673829, "ltp": 17.5, "tv": 197.62, "trd": NaN, "batb": NaN, "batl": [[0, 18, 56.78]]}, {"timestamp": 1631533694155, "ltp": 17.5, "tv": 197.62, "trd": NaN, "batb": NaN, "batl": [[0, 21, 54.04]]}, {"timestamp": 1631533798256, "ltp": 17.5, "tv": 197.62, "trd": NaN, "batb": NaN, "batl": [[0, 26, 49.92]]}, {"timestamp": 1631533823689, "ltp": 17.5, "tv": 197.62, "trd": NaN, "batb": NaN, "batl": [[0, 21, 54.04]]}, {"timestamp": 1631533849211, "ltp": 17.5, "tv": 197.62, "trd": NaN, "batb": NaN, "batl": [[0, 34, 46.6]]}, {"timestamp": 1631533886068, "ltp": 17.5, "tv": 197.62, "trd": NaN, "batb": NaN, "batl": [[0, 46, 43.48]]}, {"timestamp": 1631533931930, "ltp": 17.5, "tv": 197.62, "trd": NaN, "batb": NaN, "batl": [[0, 34, 46.6]]}, {"timestamp": 1631533973516, "ltp": 17.5, "tv": 197.62, "trd": NaN, "batb": NaN, "batl": [[0, 21, 54.04]]}, {"timestamp": 1631534009852, "ltp": 21.0, "tv": 197.8, "trd": [[21, 0.18]], "batb": NaN, "batl": [[0, 21, 53.86]]}, {"timestamp": 1631534023581, "ltp": 21.0, "tv": 197.8, "trd": NaN, "batb": NaN, "batl": [[0, 34, 46.48]]}, {"timestamp": 1631534057915, "ltp": 21.0, "tv": 197.8, "trd": NaN, "batb": NaN, "batl": [[0, 21, 53.85]]}, {"timestamp": 1631534088163, "ltp": 21.0, "tv": 197.8, "trd": NaN, "batb": NaN, "batl": [[0, 15.5, 59.98]]}, {"timestamp": 1631534116174, "ltp": 21.0, "tv": 197.8, "trd": NaN, "batb": NaN, "batl": [[0, 12, 68.09]]}, {"timestamp": 1631534166020, "ltp": 21.0, "tv": 197.8, "trd": NaN, "batb": NaN, "batl": [[0, 9.4, 78.33]]}, {"timestamp": 1631534213989, "ltp": 21.0, "tv": 197.8, "trd": NaN, "batb": NaN, "batl": [[0, 12, 68.09]]}, {"timestamp": 1631534251517, "ltp": 21.0, "tv": 197.8, "trd": NaN, "batb": NaN, "batl": [[0, 10.5, 72.62]]}, {"timestamp": 1631534267817, "ltp": 21.0, "tv": 197.8, "trd": NaN, "batb": NaN, "batl": [[0, 9.4, 78.33]]}, {"timestamp": 1631534307985, "ltp": 21.0, "tv": 197.8, "trd": NaN, "batb": [[0, 1.01, 7], [1, 1.01, 0]], "batl": NaN}, {"timestamp": 1631534313588, "ltp": 21.0, "tv": 197.8, "trd": NaN, "batb": [[0, 2.72, 386.13], [1, 1.01, 7]], "batl": [[0, 7.2, 92.44]]}, {"timestamp": 1631534346036, "ltp": 21.0, "tv": 197.8, "trd": NaN, "batb": NaN, "batl": [[0, 8.2, 85.73]]}, {"timestamp": 1631534381880, "ltp": 21.0, "tv": 197.8, "trd": NaN, "batb": NaN, "batl": [[0, 6.6, 99.21]]}, {"timestamp": 1631534401312, "ltp": 2.72, "tv": 200.59, "trd": [[2.72, 2.79]], "batb": [[0, 2.72, 384.74]], "batl": NaN}, {"timestamp": 1631534522190, "ltp": 2.72, "tv": 200.59, "trd": NaN, "batb": [[0, 1.01, 7], [1, 1.01, 0]], "batl": NaN}, {"timestamp": 1631534528424, "ltp": 2.72, "tv": 200.59, "trd": NaN, "batb": [[0, 2.98, 380.61], [1, 1.01, 7]], "batl": [[0, 9.4, 78.75]]}, {"timestamp": 1631534565960, "ltp": 2.72, "tv": 200.59, "trd": NaN, "batb": NaN, "batl": [[0, 8.2, 86.22]]}, {"timestamp": 1631534592424, "ltp": 2.72, "tv": 200.59, "trd": NaN, "batb": NaN, "batl": [[0, 6.6, 99.8]]}, {"timestamp": 1631534632062, "ltp": 2.72, "tv": 200.59, "trd": NaN, "batb": NaN, "batl": [[0, 8.2, 86.22]]}, {"timestamp": 1631534670822, "ltp": 2.72, "tv": 200.59, "trd": NaN, "batb": NaN, "batl": [[0, 10.5, 72.99]]}, {"timestamp": 1631534710890, "ltp": 2.72, "tv": 200.59, "trd": NaN, "batb": [[0, 1.01, 7], [1, 1.01, 0]], "batl": NaN}, {"timestamp": 1631534716398, "ltp": 2.72, "tv": 200.59, "trd": NaN, "batb": [[0, 3.3, 379.13], [1, 1.01, 7]], "batl": [[0, 13.5, 64.69]]}, {"timestamp": 1631534757269, "ltp": 2.72, "tv": 200.59, "trd": NaN, "batb": NaN, "batl": [[0, 10.5, 72.99]]}, {"timestamp": 1631534798913, "ltp": 2.72, "tv": 200.59, "trd": NaN, "batb": NaN, "batl": [[0, 13.5, 64.69]]}, {"timestamp": 1631534840677, "ltp": 2.72, "tv": 200.59, "trd": NaN, "batb": NaN, "batl": [[0, 10.5, 72.99]]}, {"timestamp": 1631534871985, "ltp": 2.72, "tv": 200.59, "trd": NaN, "batb": NaN, "batl": [[0, 9.4, 78.75]]}, {"timestamp": 1631534878548, "ltp": 2.72, "tv": 200.59, "trd": NaN, "batb": [[0, 1.01, 7], [1, 1.01, 0]], "batl": NaN}, {"timestamp": 1631534884159, "ltp": 2.72, "tv": 200.59, "trd": NaN, "batb": [[0, 2.72, 384.74], [1, 1.01, 7]], "batl": [[0, 7.2, 92.97]]}, {"timestamp": 1631534913237, "ltp": 2.72, "tv": 200.59, "trd": NaN, "batb": [[0, 1.01, 7], [1, 1.01, 0]], "batl": NaN}, {"timestamp": 1631534918837, "ltp": 2.72, "tv": 200.59, "trd": NaN, "batb": [[0, 3.1, 380.06], [1, 1.01, 7]], "batl": [[0, 10.5, 72.99]]}, {"timestamp": 1631534943952, "ltp": 2.72, "tv": 200.59, "trd": NaN, "batb": NaN, "batl": [[0, 9.4, 78.75]]}, {"timestamp": 1631534953970, "ltp": 2.72, "tv": 200.59, "trd": NaN, "batb": [[0, 1.01, 7], [1, 1.01, 0]], "batl": NaN}, {"timestamp": 1631535122517, "ltp": 2.72, "tv": 200.59, "trd": NaN, "batb": [[0, 3.5, 382.4], [1, 1.01, 7]], "batl": [[0, 18, 56.79]]}, {"timestamp": 1631535158044, "ltp": 2.72, "tv": 200.59, "trd": NaN, "batb": [[0, 7.6, 10], [1, 3.5, 382.4], [2, 1.01, 7]], "batl": NaN}, {"timestamp": 1631535227041, "ltp": 2.72, "tv": 200.59, "trd": NaN, "batb": NaN, "batl": [[0, 21, 54.05]]}, {"timestamp": 1631535233059, "ltp": 2.72, "tv": 200.59, "trd": NaN, "batb": [[0, 3.5, 382.4], [1, 1.01, 7], [2, 1.01, 0]], "batl": NaN}, {"timestamp": 1631535238046, "ltp": 2.72, "tv": 200.59, "trd": NaN, "batb": [[0, 6, 10], [1, 3.5, 382.4], [2, 1.01, 7]], "batl": NaN}, {"timestamp": 1631535240526, "ltp": 2.72, "tv": 200.59, "trd": NaN, "batb": NaN, "batl": [[0, 15.5, 60.23]]}, {"timestamp": 1631535260089, "ltp": 2.72, "tv": 200.59, "trd": NaN, "batb": [[0, 3.5, 382.4], [1, 1.01, 7], [2, 1.01, 0]], "batl": NaN}, {"timestamp": 1631535264989, "ltp": 2.72, "tv": 200.59, "trd": NaN, "batb": [[0, 5.3, 10], [1, 3.5, 382.4], [2, 1.01, 7]], "batl": NaN}, {"timestamp": 1631535266872, "ltp": 2.72, "tv": 200.59, "trd": NaN, "batb": NaN, "batl": [[0, 12, 68.42]]}, {"timestamp": 1631535292163, "ltp": 2.72, "tv": 200.59, "trd": NaN, "batb": [[0, 3.5, 382.4], [1, 1.01, 7], [2, 1.01, 0]], "batl": NaN}, {"timestamp": 1631535297083, "ltp": 2.72, "tv": 200.59, "trd": NaN, "batb": [[0, 6, 10], [1, 3.5, 382.4], [2, 1.01, 7]], "batl": NaN}, {"timestamp": 1631535325526, "ltp": 2.72, "tv": 200.59, "trd": NaN, "batb": NaN, "batl": [[0, 15.5, 60.23]]}, {"timestamp": 1631535356950, "ltp": 2.72, "tv": 200.59, "trd": NaN, "batb": NaN, "batl": [[0, 13.5, 64.69]]}, {"timestamp": 1631535380585, "ltp": 2.72, "tv": 200.59, "trd": NaN, "batb": [[0, 3.5, 382.4], [1, 1.01, 7], [2, 1.01, 0]], "batl": NaN}, {"timestamp": 1631535385509, "ltp": 2.72, "tv": 200.59, "trd": NaN, "batb": [[0, 5.3, 10], [1, 3.5, 382.4], [2, 1.01, 7]], "batl": NaN}, {"timestamp": 1631535388721, "ltp": 2.72, "tv": 200.59, "trd": NaN, "batb": NaN, "batl": [[0, 10.5, 72.99]]}, {"timestamp": 1631535411180, "ltp": 5.3, "tv": 210.16, "trd": [[5.3, 9.57]], "batb": [[0, 3.5, 382.4], [1, 1.01, 7], [2, 1.01, 0]], "batl": NaN}, {"timestamp": 1631535421217, "ltp": 5.3, "tv": 210.16, "trd": NaN, "batb": [[0, 4.8, 10], [1, 3.5, 382.4], [2, 1.01, 7]], "batl": NaN}, {"timestamp": 1631535422208, "ltp": 5.3, "tv": 210.16, "trd": NaN, "batb": NaN, "batl": [[0, 9.4, 78.75]]}, {"timestamp": 1631535441621, "ltp": 5.3, "tv": 210.16, "trd": NaN, "batb": [[1, 1.01, 7], [2, 1.01, 0]], "batl": NaN}, {"timestamp": 1631535457953, "ltp": 5.3, "tv": 210.16, "trd": NaN, "batb": [[0, 1.01, 7], [1, 1.01, 0]], "batl": NaN}, {"timestamp": 1631535462860, "ltp": 5.3, "tv": 210.16, "trd": NaN, "batb": [[0, 3.95, 10.16], [1, 1.01, 7]], "batl": NaN}, {"timestamp": 1631535478590, "ltp": 5.3, "tv": 210.16, "trd": NaN, "batb": [[0, 1.01, 7], [1, 1.01, 0]], "batl": NaN}, {"timestamp": 1631535483461, "ltp": 5.3, "tv": 210.16, "trd": NaN, "batb": [[0, 3.7, 11.11], [1, 1.01, 7]], "batl": NaN}, {"timestamp": 1631535493994, "ltp": 5.3, "tv": 210.16, "trd": NaN, "batb": [[0, 1.01, 7], [1, 1.01, 0]], "batl": NaN}, {"timestamp": 1631535498906, "ltp": 5.3, "tv": 210.16, "trd": NaN, "batb": [[0, 3.15, 13.95], [1, 1.01, 7]], "batl": NaN}, {"timestamp": 1631535544291, "ltp": 5.3, "tv": 210.16, "trd": NaN, "batb": [[0, 1.01, 7], [1, 1.01, 0]], "batl": NaN}, {"timestamp": 1631535548633, "ltp": 5.3, "tv": 210.16, "trd": NaN, "batb": [[0, 2.84, 16.3], [1, 1.01, 7]], "batl": NaN}, {"timestamp": 1631535578259, "ltp": 5.3, "tv": 210.16, "trd": NaN, "batb": [[0, 1.01, 7], [1, 1.01, 0]], "batl": NaN}, {"timestamp": 1631535583484, "ltp": 5.3, "tv": 210.16, "trd": NaN, "batb": [[0, 3, 15], [1, 1.01, 7]], "batl": NaN}, {"timestamp": 1631535591163, "ltp": 5.3, "tv": 210.16, "trd": NaN, "batb": [[0, 3.65, 5.32], [1, 3, 15], [2, 1.01, 7]], "batl": NaN}, {"timestamp": 1631535629121, "ltp": 5.3, "tv": 210.16, "trd": NaN, "batb": [[1, 1.01, 7], [2, 1.01, 0]], "batl": NaN}, {"timestamp": 1631535634329, "ltp": 3.65, "tv": 215.48, "trd": [[3.65, 5.32]], "batb": [[0, 2.58, 18.98]], "batl": NaN}, {"timestamp": 1631535635059, "ltp": 3.65, "tv": 215.48, "trd": NaN, "batb": [[1, 2.22, 391.36], [2, 1.01, 7]], "batl": [[0, 4.6, 137.18]]}, {"timestamp": 1631535679422, "ltp": 3.65, "tv": 215.48, "trd": NaN, "batb": [[0, 2.22, 391.36], [1, 1.01, 7], [2, 1.01, 0]], "batl": NaN}, {"timestamp": 1631535682430, "ltp": 3.65, "tv": 215.48, "trd": NaN, "batb": [[0, 1.01, 7], [1, 1.01, 0]], "batl": NaN}, {"timestamp": 1631535728478, "ltp": 3.65, "tv": 215.48, "trd": NaN, "batb": [[0, 2.58, 18.98], [1, 1.01, 7]], "batl": NaN}, {"timestamp": 1631535760557, "ltp": 3.65, "tv": 215.48, "trd": NaN, "batb": [[0, 1.01, 7], [1, 1.01, 0]], "batl": NaN}, {"timestamp": 1631535765470, "ltp": 3.65, "tv": 215.48, "trd": NaN, "batb": [[0, 2.42, 21.12], [1, 1.01, 7]], "batl": NaN}, {"timestamp": 1631535766775, "ltp": 3.65, "tv": 215.48, "trd": NaN, "batb": [[1, 2.04, 401.22], [2, 1.01, 7]], "batl": [[0, 3.9, 159.57]]}, {"timestamp": 1631535806338, "ltp": 3.65, "tv": 215.48, "trd": NaN, "batb": [[0, 2.04, 401.22], [1, 1.01, 7], [2, 1.01, 0]], "batl": NaN}, {"timestamp": 1631535808216, "ltp": 3.65, "tv": 215.48, "trd": NaN, "batb": [[0, 1.01, 7], [1, 1.01, 0]], "batl": NaN}, {"timestamp": 1631535811217, "ltp": 3.65, "tv": 215.48, "trd": NaN, "batb": [[0, 2.58, 18.98], [1, 1.01, 7]], "batl": NaN}, {"timestamp": 1631535814625, "ltp": 3.65, "tv": 215.48, "trd": NaN, "batb": [[1, 2.22, 391.36], [2, 1.01, 7]], "batl": [[0, 4.6, 137.18]]}, {"timestamp": 1631535832943, "ltp": 3.65, "tv": 215.48, "trd": NaN, "batb": [[0, 2.22, 391.36], [1, 1.01, 7], [2, 1.01, 0]], "batl": NaN}, {"timestamp": 1631535833677, "ltp": 3.65, "tv": 215.48, "trd": NaN, "batb": [[0, 1.01, 7], [1, 1.01, 0]], "batl": NaN}, {"timestamp": 1631535837862, "ltp": 3.65, "tv": 215.48, "trd": NaN, "batb": [[0, 3, 15], [1, 1.01, 7]], "batl": NaN}, {"timestamp": 1631535840177, "ltp": 3.65, "tv": 215.48, "trd": NaN, "batb": [[1, 2.42, 388.42], [2, 1.01, 7]], "batl": [[0, 5.5, 116.02]]}, {"timestamp": 1631535863078, "ltp": 3.65, "tv": 215.48, "trd": NaN, "batb": [[0, 2.42, 388.42], [1, 1.01, 7], [2, 1.01, 0]], "batl": NaN}, {"timestamp": 1631535867957, "ltp": 3.65, "tv": 215.48, "trd": NaN, "batb": [[0, 3.15, 13.95], [1, 2.42, 388.42], [2, 1.01, 7]], "batl": NaN}, {"timestamp": 1631535877463, "ltp": 3.65, "tv": 215.48, "trd": NaN, "batb": [[0, 1.01, 7], [1, 2.42, 0], [2, 1.01, 0]], "batl": NaN}, {"timestamp": 1631535882165, "ltp": 3.65, "tv": 215.48, "trd": NaN, "batb": [[0, 3.7, 11.11], [1, 1.01, 7]], "batl": NaN}, {"timestamp": 1631535883671, "ltp": 3.65, "tv": 215.48, "trd": NaN, "batb": [[1, 2.72, 384.74], [2, 1.01, 7]], "batl": [[0, 7.2, 92.97]]}, {"timestamp": 1631535904629, "ltp": 3.65, "tv": 215.48, "trd": NaN, "batb": [[0, 2.72, 384.74], [1, 1.01, 7], [2, 1.01, 0]], "batl": NaN}, {"timestamp": 1631535909527, "ltp": 3.65, "tv": 215.48, "trd": NaN, "batb": [[0, 3.95, 10.16], [1, 2.72, 384.74], [2, 1.01, 7]], "batl": NaN}, {"timestamp": 1631535921844, "ltp": 3.65, "tv": 215.48, "trd": NaN, "batb": [[0, 2.72, 384.74], [1, 1.01, 7], [2, 1.01, 0]], "batl": NaN}, {"timestamp": 1631535923768, "ltp": 3.65, "tv": 215.48, "trd": NaN, "batb": [[0, 1.01, 7], [1, 1.01, 0]], "batl": NaN}, {"timestamp": 1631535927584, "ltp": 3.65, "tv": 215.48, "trd": NaN, "batb": [[0, 4.3, 10], [1, 1.01, 7]], "batl": NaN}, {"timestamp": 1631535929546, "ltp": 3.65, "tv": 215.48, "trd": NaN, "batb": [[1, 2.98, 380.61], [2, 1.01, 7]], "batl": [[0, 9.4, 78.75]]}, {"timestamp": 1631535966229, "ltp": 3.65, "tv": 215.48, "trd": NaN, "batb": [[0, 2.98, 380.61], [1, 1.01, 7], [2, 1.01, 0]], "batl": NaN}, {"timestamp": 1631535971237, "ltp": 3.65, "tv": 215.48, "trd": NaN, "batb": [[0, 5.8, 10], [1, 2.98, 380.61], [2, 1.01, 7]], "batl": NaN}, {"timestamp": 1631535973210, "ltp": 3.65, "tv": 215.48, "trd": NaN, "batb": NaN, "batl": [[0, 12, 68.42]]}, {"timestamp": 1631536008122, "ltp": 3.65, "tv": 215.48, "trd": NaN, "batb": [[0, 2.98, 380.61], [1, 1.01, 7], [2, 1.01, 0]], "batl": NaN}, {"timestamp": 1631536013046, "ltp": 3.65, "tv": 215.48, "trd": NaN, "batb": [[0, 4.3, 10], [1, 2.98, 380.61], [2, 1.01, 7]], "batl": NaN}, {"timestamp": 1631536014935, "ltp": 3.65, "tv": 215.48, "trd": NaN, "batb": NaN, "batl": [[0, 9.4, 78.75]]}, {"timestamp": 1631536041227, "ltp": 3.65, "tv": 215.48, "trd": NaN, "batb": NaN, "batl": [[0, 8.2, 86.22]]}, {"timestamp": 1631536049026, "ltp": 3.65, "tv": 215.48, "trd": NaN, "batb": [[0, 2.98, 380.61], [1, 1.01, 7], [2, 1.01, 0]], "batl": NaN}, {"timestamp": 1631536053909, "ltp": 3.65, "tv": 215.48, "trd": NaN, "batb": [[0, 5.8, 10], [1, 2.98, 380.61], [2, 1.01, 7]], "batl": NaN}, {"timestamp": 1631536056596, "ltp": 3.65, "tv": 215.48, "trd": NaN, "batb": NaN, "batl": [[0, 12, 68.42]]}, {"timestamp": 1631536086178, "ltp": 3.65, "tv": 215.48, "trd": NaN, "batb": NaN, "batl": [[0, 10.5, 72.99]]}, {"timestamp": 1631536095166, "ltp": 3.65, "tv": 215.48, "trd": NaN, "batb": [[0, 2.98, 380.61], [1, 1.01, 7], [2, 1.01, 0]], "batl": NaN}, {"timestamp": 1631536096281, "ltp": 3.65, "tv": 215.48, "trd": NaN, "batb": [[0, 1.01, 7], [1, 1.01, 0]], "batl": NaN}, {"timestamp": 1631536100186, "ltp": 3.65, "tv": 215.48, "trd": NaN, "batb": [[0, 6, 10], [1, 1.01, 7]], "batl": NaN}, {"timestamp": 1631536102163, "ltp": 3.65, "tv": 215.48, "trd": NaN, "batb": [[1, 3.4, 382.33], [2, 1.01, 7]], "batl": [[0, 15.5, 60.23]]}, {"timestamp": 1631536122595, "ltp": 3.65, "tv": 215.48, "trd": NaN, "batb": [[0, 3.4, 382.33], [1, 1.01, 7], [2, 1.01, 0]], "batl": NaN}, {"timestamp": 1631536127617, "ltp": 3.65, "tv": 215.48, "trd": NaN, "batb": [[0, 7.6, 10], [1, 3.4, 382.33], [2, 1.01, 7]], "batl": NaN}, {"timestamp": 1631536129599, "ltp": 3.65, "tv": 215.48, "trd": NaN, "batb": NaN, "batl": [[0, 21, 54.05]]}, {"timestamp": 1631536146314, "ltp": 7.6, "tv": 225.05, "trd": [[7.6, 9.57]], "batb": [[0, 3.4, 382.33], [1, 1.01, 7], [2, 1.01, 0]], "batl": NaN}, {"timestamp": 1631536151365, "ltp": 7.6, "tv": 225.05, "trd": NaN, "batb": [[0, 7.6, 10], [1, 3.4, 382.33], [2, 1.01, 7]], "batl": NaN}, {"timestamp": 1631536226330, "ltp": 7.6, "tv": 225.05, "trd": NaN, "batb": [[0, 3.4, 382.33], [1, 1.01, 7], [2, 1.01, 0]], "batl": NaN}, {"timestamp": 1631536231353, "ltp": 7.6, "tv": 225.05, "trd": NaN, "batb": [[0, 6, 10], [1, 3.4, 382.33], [2, 1.01, 7]], "batl": NaN}, {"timestamp": 1631536233655, "ltp": 7.6, "tv": 225.05, "trd": NaN, "batb": NaN, "batl": [[0, 15.5, 60.23]]}, {"timestamp": 1631536269788, "ltp": 7.6, "tv": 225.05, "trd": NaN, "batb": [[0, 3.4, 382.33], [1, 1.01, 7], [2, 1.01, 0]], "batl": NaN}, {"timestamp": 1631536274702, "ltp": 7.6, "tv": 225.05, "trd": NaN, "batb": [[0, 5.3, 10], [1, 3.4, 382.33], [2, 1.01, 7]], "batl": NaN}, {"timestamp": 1631536278217, "ltp": 7.6, "tv": 225.05, "trd": NaN, "batb": NaN, "batl": [[0, 10.5, 72.99]]}, {"timestamp": 1631536301833, "ltp": 7.6, "tv": 225.05, "trd": NaN, "batb": NaN, "batl": [[0, 12, 68.42]]}, {"timestamp": 1631536313764, "ltp": 7.6, "tv": 225.05, "trd": NaN, "batb": [[0, 3.4, 382.33], [1, 1.01, 7], [2, 1.01, 0]], "batl": NaN}, {"timestamp": 1631536318777, "ltp": 7.6, "tv": 225.05, "trd": NaN, "batb": [[0, 6, 10], [1, 3.4, 382.33], [2, 1.01, 7]], "batl": NaN}, {"timestamp": 1631536354483, "ltp": 7.6, "tv": 225.05, "trd": NaN, "batb": [[0, 3.4, 382.33], [1, 1.01, 7], [2, 1.01, 0]], "batl": NaN}, {"timestamp": 1631536359395, "ltp": 7.6, "tv": 225.05, "trd": NaN, "batb": [[0, 7.6, 10], [1, 3.4, 382.33], [2, 1.01, 7]], "batl": NaN}, {"timestamp": 1631536361597, "ltp": 7.6, "tv": 225.05, "trd": NaN, "batb": NaN, "batl": [[0, 21, 54.05]]}, {"timestamp": 1631536383714, "ltp": 7.6, "tv": 225.05, "trd": NaN, "batb": [[1, 1.01, 7], [2, 1.01, 0]], "batl": NaN}, {"timestamp": 1631536385912, "ltp": 9.2, "tv": 230.37, "trd": [[9.2, 5.32]], "batb": NaN, "batl": NaN}, {"timestamp": 1631536389884, "ltp": 9.2, "tv": 230.37, "trd": NaN, "batb": [[0, 1.01, 7], [1, 1.01, 0]], "batl": NaN}, {"timestamp": 1631536394780, "ltp": 9.2, "tv": 230.37, "trd": NaN, "batb": [[0, 5.8, 10], [1, 1.01, 7]], "batl": NaN}, {"timestamp": 1631536396314, "ltp": 9.2, "tv": 230.37, "trd": NaN, "batb": [[1, 3.3, 379.13], [2, 1.01, 7]], "batl": [[0, 13.5, 64.69]]}, {"timestamp": 1631536418222, "ltp": 9.2, "tv": 230.37, "trd": NaN, "batb": [[0, 3.3, 379.13], [1, 1.01, 7], [2, 1.01, 0]], "batl": NaN}, {"timestamp": 1631536423238, "ltp": 9.2, "tv": 230.37, "trd": NaN, "batb": [[0, 4.3, 10], [1, 3.3, 379.13], [2, 1.01, 7]], "batl": NaN}, {"timestamp": 1631536425431, "ltp": 9.2, "tv": 230.37, "trd": NaN, "batb": NaN, "batl": [[0, 8.2, 86.22]]}, {"timestamp": 1631536463506, "ltp": 9.2, "tv": 230.37, "trd": NaN, "batb": [[0, 3.3, 379.13], [1, 1.01, 7], [2, 1.01, 0]], "batl": NaN}, {"timestamp": 1631536468510, "ltp": 9.2, "tv": 230.37, "trd": NaN, "batb": [[0, 5.8, 10], [1, 3.3, 379.13], [2, 1.01, 7]], "batl": NaN}, {"timestamp": 1631536471993, "ltp": 9.2, "tv": 230.37, "trd": NaN, "batb": NaN, "batl": [[0, 12, 68.42]]}, {"timestamp": 1631536507662, "ltp": 9.2, "tv": 230.37, "trd": NaN, "batb": [[0, 3.3, 379.13], [1, 1.01, 7], [2, 1.01, 0]], "batl": NaN}, {"timestamp": 1631536513376, "ltp": 9.2, "tv": 230.37, "trd": NaN, "batb": [[0, 4.3, 10], [1, 3.3, 379.13], [2, 1.01, 7]], "batl": NaN}, {"timestamp": 1631536514872, "ltp": 9.2, "tv": 230.37, "trd": NaN, "batb": NaN, "batl": [[0, 8.2, 86.22]]}, {"timestamp": 1631536537303, "ltp": 9.2, "tv": 230.37, "trd": NaN, "batb": [[0, 3.3, 379.13], [1, 1.01, 7], [2, 1.01, 0]], "batl": NaN}, {"timestamp": 1631536537790, "ltp": 9.2, "tv": 230.37, "trd": NaN, "batb": [[0, 1.01, 7], [1, 1.01, 0]], "batl": NaN}, {"timestamp": 1631536542190, "ltp": 9.2, "tv": 230.37, "trd": NaN, "batb": [[0, 3.4, 12.5], [1, 1.01, 7]], "batl": NaN}, {"timestamp": 1631536543502, "ltp": 9.2, "tv": 230.37, "trd": NaN, "batb": [[1, 2.62, 385.81], [2, 1.01, 7]], "batl": [[0, 6.6, 99.8]]}, {"timestamp": 1631536571516, "ltp": 3.5, "tv": 239.94, "trd": [[3.5, 9.57]], "batb": NaN, "batl": NaN}, {"timestamp": 1631536573720, "ltp": 3.5, "tv": 239.94, "trd": NaN, "batb": [[0, 2.62, 385.81], [1, 1.01, 7], [2, 1.01, 0]], "batl": NaN}, {"timestamp": 1631536575445, "ltp": 3.5, "tv": 244.35, "trd": [[3.5, 13.98]], "batb": [[0, 3.5, 16.03], [1, 2.62, 385.81], [2, 1.01, 7]], "batl": NaN}, {"timestamp": 1631536576442, "ltp": 3.5, "tv": 244.35, "trd": NaN, "batb": [[0, 3.5, 70.55]], "batl": NaN}, {"timestamp": 1631536577556, "ltp": 3.5, "tv": 244.35, "trd": NaN, "batb": [[0, 3.5, 70.87]], "batl": NaN}, {"timestamp": 1631536578554, "ltp": 3.5, "tv": 244.35, "trd": NaN, "batb": [[0, 3.5, 36.6]], "batl": NaN}, {"timestamp": 1631536579548, "ltp": 3.5, "tv": 244.35, "trd": NaN, "batb": [[0, 3.5, 21.99], [1, 3.3, 13.04], [2, 2.62, 385.81]], "batl": NaN}, {"timestamp": 1631536580627, "ltp": 3.5, "tv": 244.35, "trd": NaN, "batb": [[0, 3.5, 22]], "batl": NaN}, {"timestamp": 1631536581256, "ltp": 3.5, "tv": 244.35, "trd": NaN, "batb": [[0, 3.3, 13.04], [1, 2.62, 385.81], [2, 1.01, 7]], "batl": NaN}, {"timestamp": 1631536582145, "ltp": 3.5, "tv": 244.35, "trd": NaN, "batb": NaN, "batl": [[0, 6, 107.07]]}, {"timestamp": 1631536590143, "ltp": 3.5, "tv": 244.35, "trd": NaN, "batb": [[0, 2.62, 385.81], [1, 1.01, 7], [2, 1.01, 0]], "batl": NaN}, {"timestamp": 1631536595047, "ltp": 3.5, "tv": 244.35, "trd": NaN, "batb": [[0, 2.84, 16.3], [1, 2.62, 385.81], [2, 1.01, 7]], "batl": NaN}, {"timestamp": 1631536597962, "ltp": 3.5, "tv": 244.35, "trd": NaN, "batb": NaN, "batl": [[0, 4.9, 127.33]]}, {"timestamp": 1631536623426, "ltp": 3.5, "tv": 244.35, "trd": NaN, "batb": [[0, 2.62, 385.81], [1, 1.01, 7], [2, 1.01, 0]], "batl": NaN}, {"timestamp": 1631536628386, "ltp": 3.5, "tv": 244.35, "trd": NaN, "batb": [[0, 2.66, 18.07], [1, 2.62, 385.81], [2, 1.01, 7]], "batl": NaN}, {"timestamp": 1631536645593, "ltp": 3.5, "tv": 244.35, "trd": NaN, "batb": [[0, 2.62, 385.81], [1, 1.01, 7], [2, 1.01, 0]], "batl": NaN}, {"timestamp": 1631536650514, "ltp": 3.5, "tv": 244.35, "trd": NaN, "batb": [[0, 3.15, 13.95], [1, 2.62, 385.81], [2, 1.01, 7]], "batl": NaN}, {"timestamp": 1631536653385, "ltp": 3.5, "tv": 244.35, "trd": NaN, "batb": NaN, "batl": [[0, 6, 107.07]]}, {"timestamp": 1631536707969, "ltp": 3.5, "tv": 244.35, "trd": NaN, "batb": [[0, 2.62, 385.81], [1, 1.01, 7], [2, 1.01, 0]], "batl": NaN}, {"timestamp": 1631536710648, "ltp": 3.5, "tv": 244.35, "trd": NaN, "batb": [[0, 1.01, 7], [1, 1.01, 0]], "batl": NaN}, {"timestamp": 1631536712887, "ltp": 3.5, "tv": 244.35, "trd": NaN, "batb": [[0, 4.3, 10], [1, 1.01, 7]], "batl": NaN}, {"timestamp": 1631536716495, "ltp": 3.5, "tv": 244.35, "trd": NaN, "batb": [[1, 2.84, 381.81], [2, 1.01, 7]], "batl": [[0, 8.2, 86.22]]}, {"timestamp": 1631536762367, "ltp": 3.5, "tv": 244.35, "trd": NaN, "batb": [[1, 1.01, 7], [2, 1.01, 0]], "batl": NaN}, {"timestamp": 1631536769940, "ltp": 3.5, "tv": 244.35, "trd": NaN, "batb": [[1, 2.98, 380.61], [2, 1.01, 7]], "batl": [[0, 9.4, 78.75]]}, {"timestamp": 1631536776923, "ltp": 3.5, "tv": 244.35, "trd": NaN, "batb": [[0, 2.98, 380.61], [1, 1.01, 7], [2, 1.01, 0]], "batl": NaN}, {"timestamp": 1631536778549, "ltp": 3.5, "tv": 244.35, "trd": NaN, "batb": [[0, 1.01, 7], [1, 1.01, 0]], "batl": NaN}, {"timestamp": 1631536781827, "ltp": 3.5, "tv": 244.35, "trd": NaN, "batb": [[0, 6, 10], [1, 1.01, 7]], "batl": NaN}, {"timestamp": 1631536784532, "ltp": 3.5, "tv": 244.35, "trd": NaN, "batb": [[1, 3.4, 382.33], [2, 1.01, 7]], "batl": [[0, 15.5, 60.23]]}, {"timestamp": 1631536804946, "ltp": 3.5, "tv": 244.35, "trd": NaN, "batb": [[1, 1.01, 7], [2, 1.01, 0]], "batl": NaN}, {"timestamp": 1631536814582, "ltp": 3.5, "tv": 244.35, "trd": NaN, "batb": [[1, 3.3, 379.13], [2, 1.01, 7]], "batl": [[0, 13.5, 64.69]]}, {"timestamp": 1631536818183, "ltp": 3.5, "tv": 244.35, "trd": NaN, "batb": [[1, 1.01, 7], [2, 1.01, 0]], "batl": NaN}, {"timestamp": 1631536841090, "ltp": 3.5, "tv": 244.35, "trd": NaN, "batb": [[0, 1.01, 7], [1, 1.01, 0]], "batl": NaN}, {"timestamp": 1631536845996, "ltp": 3.5, "tv": 244.35, "trd": NaN, "batb": [[0, 4.3, 10], [1, 1.01, 7]], "batl": NaN}, {"timestamp": 1631536847916, "ltp": 3.5, "tv": 244.35, "trd": NaN, "batb": [[1, 2.84, 381.81], [2, 1.01, 7]], "batl": [[0, 8.2, 86.22]]}, {"timestamp": 1631536849431, "ltp": 3.5, "tv": 244.35, "trd": NaN, "batb": NaN, "batl": [[1, 13.5, 85.8]]}, {"timestamp": 1631536850629, "ltp": 3.5, "tv": 244.35, "trd": NaN, "batb": NaN, "batl": [[0, 6, 4.78], [1, 8.2, 86.22]]}, {"timestamp": 1631536854735, "ltp": 3.5, "tv": 244.35, "trd": NaN, "batb": NaN, "batl": [[0, 8.2, 86.22], [1, 8.2, 0]]}, {"timestamp": 1631536859822, "ltp": 3.5, "tv": 244.35, "trd": NaN, "batb": NaN, "batl": [[1, 13.5, 4.78]]}, {"timestamp": 1631536872124, "ltp": 3.5, "tv": 244.35, "trd": NaN, "batb": [[1, 1.01, 7], [2, 1.01, 0]], "batl": [[0, 13.5, 4.78], [1, 13.5, 0]]}, {"timestamp": 1631536879273, "ltp": 3.5, "tv": 244.35, "trd": NaN, "batb": [[0, 1.01, 7], [1, 1.01, 0]], "batl": NaN}, {"timestamp": 1631536884280, "ltp": 3.5, "tv": 244.35, "trd": NaN, "batb": [[0, 4, 10], [1, 1.01, 7]], "batl": NaN}, {"timestamp": 1631536885594, "ltp": 3.5, "tv": 244.35, "trd": NaN, "batb": [[1, 2.72, 384.74], [2, 1.01, 7]], "batl": [[0, 7.2, 92.97], [1, 13.5, 4.78]]}, {"timestamp": 1631536886208, "ltp": 3.5, "tv": 244.35, "trd": NaN, "batb": [[1, 1.01, 7], [2, 1.01, 0]], "batl": [[0, 13.5, 4.78], [1, 13.5, 0]]}, {"timestamp": 1631536892215, "ltp": 3.5, "tv": 244.35, "trd": NaN, "batb": [[0, 1.01, 7], [1, 1.01, 0]], "batl": NaN}, {"timestamp": 1631536897129, "ltp": 3.5, "tv": 244.35, "trd": NaN, "batb": [[0, 3, 15], [1, 1.01, 7]], "batl": NaN}, {"timestamp": 1631536898935, "ltp": 3.5, "tv": 244.35, "trd": NaN, "batb": [[0, 3.05, 13.24], [1, 3, 15], [2, 1.01, 7]], "batl": NaN}, {"timestamp": 1631536899926, "ltp": 3.5, "tv": 244.35, "trd": NaN, "batb": [[2, 2.38, 389.01]], "batl": [[0, 5.3, 119.78], [1, 13.5, 4.78]]}, {"timestamp": 1631536901898, "ltp": 3.5, "tv": 244.35, "trd": NaN, "batb": [[0, 3, 15], [1, 2.38, 389.01], [2, 1.01, 7]], "batl": NaN}, {"timestamp": 1631536926739, "ltp": 3.5, "tv": 244.35, "trd": NaN, "batb": [[0, 2.38, 389.01], [1, 1.01, 7], [2, 1.01, 0]], "batl": NaN}, {"timestamp": 1631536928461, "ltp": 3.5, "tv": 244.35, "trd": NaN, "batb": [[0, 1.01, 7], [1, 1.01, 0]], "batl": [[0, 13.5, 4.78], [1, 13.5, 0]]}, {"timestamp": 1631536930767, "ltp": 3.5, "tv": 244.35, "trd": NaN, "batb": [[0, 2.4, 19.42], [1, 1.01, 7]], "batl": NaN}, {"timestamp": 1631536931660, "ltp": 3.5, "tv": 244.35, "trd": NaN, "batb": [[1, 2.34, 22.38], [2, 1.01, 7]], "batl": NaN}, {"timestamp": 1631536934169, "ltp": 3.5, "tv": 244.35, "trd": NaN, "batb": [[0, 2.34, 22.38], [1, 2.04, 401.22]], "batl": [[0, 3.9, 159.57], [1, 13.5, 4.78]]}, {"timestamp": 1631536959208, "ltp": 3.5, "tv": 244.35, "trd": NaN, "batb": [[0, 2.04, 401.22], [1, 1.01, 7], [2, 1.01, 0]], "batl": [[1, 13.5, 0]]}, {"timestamp": 1631536961508, "ltp": 3.5, "tv": 244.35, "trd": NaN, "batb": [[0, 1.01, 7], [1, 1.01, 0]], "batl": NaN}, {"timestamp": 1631536964079, "ltp": 3.5, "tv": 244.35, "trd": NaN, "batb": [[0, 2.84, 16.3], [1, 1.01, 7]], "batl": NaN}, {"timestamp": 1631536967516, "ltp": 3.5, "tv": 244.35, "trd": NaN, "batb": [[1, 2.3, 391.9], [2, 1.01, 7]], "batl": [[0, 4.9, 127.33]]}, {"timestamp": 1631536991006, "ltp": 3.5, "tv": 244.35, "trd": NaN, "batb": [[1, 1.01, 7], [2, 1.01, 0]], "batl": NaN}, {"timestamp": 1631536996375, "ltp": 3.5, "tv": 244.35, "trd": NaN, "batb": [[0, 1.01, 7], [1, 1.01, 0]], "batl": NaN}, {"timestamp": 1631537001267, "ltp": 3.5, "tv": 244.35, "trd": NaN, "batb": [[0, 4.1, 10], [1, 1.01, 7]], "batl": NaN}, {"timestamp": 1631537003386, "ltp": 3.5, "tv": 244.35, "trd": NaN, "batb": [[1, 2.84, 381.81], [2, 1.01, 7]], "batl": [[0, 8.2, 86.22]]}, {"timestamp": 1631537014389, "ltp": 3.5, "tv": 244.35, "trd": NaN, "batb": [[1, 1.01, 7], [2, 1.01, 0]], "batl": NaN}, {"timestamp": 1631537065741, "ltp": 3.5, "tv": 244.35, "trd": NaN, "batb": [[0, 1.01, 7], [1, 1.01, 0]], "batl": NaN}, {"timestamp": 1631537070678, "ltp": 3.5, "tv": 244.35, "trd": NaN, "batb": [[0, 3.95, 10.16], [1, 1.01, 7]], "batl": NaN}, {"timestamp": 1631537080397, "ltp": 3.5, "tv": 244.35, "trd": NaN, "batb": [[0, 1.01, 7], [1, 1.01, 0]], "batl": NaN}, {"timestamp": 1631537085589, "ltp": 3.5, "tv": 244.35, "trd": NaN, "batb": [[0, 7.6, 10], [1, 1.01, 7]], "batl": NaN}, {"timestamp": 1631537111400, "ltp": 3.5, "tv": 244.35, "trd": NaN, "batb": [[0, 1.01, 7], [1, 1.01, 0]], "batl": NaN}, {"timestamp": 1631537116406, "ltp": 3.5, "tv": 244.35, "trd": NaN, "batb": [[0, 8, 10], [1, 1.01, 7]], "batl": NaN}, {"timestamp": 1631537119912, "ltp": 3.5, "tv": 244.35, "trd": NaN, "batb": NaN, "batl": [[0, 17.5, 2.66]]}, {"timestamp": 1631537123418, "ltp": 17.5, "tv": 247.01, "trd": [[17.5, 2.86]], "batb": NaN, "batl": NaN}, {"timestamp": 1631537130725, "ltp": 17.5, "tv": 247.01, "trd": NaN, "batb": [[0, 1.01, 7], [1, 1.01, 0]], "batl": NaN}, {"timestamp": 1631537135658, "ltp": 17.5, "tv": 247.01, "trd": NaN, "batb": [[0, 4.1, 10], [1, 1.01, 7]], "batl": NaN}, {"timestamp": 1631537142136, "ltp": 6.6, "tv": 249.01, "trd": [[6.6, 2]], "batb": NaN, "batl": NaN}, {"timestamp": 1631537170304, "ltp": 6.6, "tv": 249.01, "trd": NaN, "batb": [[0, 1.01, 7], [1, 1.01, 0]], "batl": NaN}, {"timestamp": 1631537175507, "ltp": 6.6, "tv": 249.01, "trd": NaN, "batb": [[0, 2.84, 16.3], [1, 1.01, 7]], "batl": NaN}, {"timestamp": 1631537176494, "ltp": 6.6, "tv": 249.01, "trd": NaN, "batb": [[1, 2.3, 391.9], [2, 1.01, 7]], "batl": [[0, 4.9, 127.33]]}, {"timestamp": 1631537205248, "ltp": 3.65, "tv": 275.59, "trd": [[3.65, 31.89]], "batb": NaN, "batl": NaN}, {"timestamp": 1631537211552, "ltp": 3.65, "tv": 275.59, "trd": NaN, "batb": [[0, 2.3, 391.9], [1, 1.01, 7], [2, 1.01, 0]], "batl": NaN}, {"timestamp": 1631537212533, "ltp": 3.65, "tv": 275.59, "trd": NaN, "batb": [[0, 1.01, 7], [1, 1.01, 0]], "batl": NaN}, {"timestamp": 1631537216474, "ltp": 3.65, "tv": 275.59, "trd": NaN, "batb": [[0, 2, 30], [1, 1.01, 7]], "batl": NaN}, {"timestamp": 1631537218153, "ltp": 3.65, "tv": 275.59, "trd": NaN, "batb": [[1, 1.82, 408.65], [2, 1.01, 7]], "batl": [[0, 3.15, 202.13]]}, {"timestamp": 1631537222055, "ltp": 2.0, "tv": 281.37, "trd": [[2, 5.78]], "batb": [[0, 1.82, 408.65], [1, 1.01, 7], [2, 1.01, 0]], "batl": NaN}, {"timestamp": 1631537227490, "ltp": 2.0, "tv": 281.37, "trd": NaN, "batb": [[0, 2, 30], [1, 1.82, 408.65], [2, 1.01, 7]], "batl": NaN}, {"timestamp": 1631537570658, "ltp": 2.0, "tv": 281.37, "trd": NaN, "batb": [[0, 1.82, 408.65], [1, 1.01, 7], [2, 1.01, 0]], "batl": NaN}, {"timestamp": 1631537575576, "ltp": 2.0, "tv": 281.37, "trd": NaN, "batb": [[0, 2.1, 27.27], [1, 1.82, 408.65], [2, 1.01, 7]], "batl": NaN}, {"timestamp": 1631537597393, "ltp": 2.0, "tv": 281.37, "trd": NaN, "batb": [[0, 1.82, 408.65], [1, 1.01, 7], [2, 1.01, 0]], "batl": NaN}, {"timestamp": 1631537598486, "ltp": 2.0, "tv": 281.37, "trd": NaN, "batb": [[0, 1.01, 7], [1, 1.01, 0]], "batl": NaN}, {"timestamp": 1631537602291, "ltp": 2.0, "tv": 281.37, "trd": NaN, "batb": [[0, 2.58, 18.98], [1, 1.01, 7]], "batl": NaN}, {"timestamp": 1631537604310, "ltp": 2.0, "tv": 281.37, "trd": NaN, "batb": [[1, 2.12, 395.62], [2, 1.01, 7]], "batl": [[0, 4.2, 149.26]]}, {"timestamp": 1631537645119, "ltp": 2.0, "tv": 281.37, "trd": NaN, "batb": [[0, 2.12, 395.62], [1, 1.01, 7], [2, 1.01, 0]], "batl": NaN}, {"timestamp": 1631537646158, "ltp": 2.0, "tv": 281.37, "trd": NaN, "batb": [[0, 1.01, 7], [1, 1.01, 0]], "batl": NaN}, {"timestamp": 1631537650173, "ltp": 2.0, "tv": 281.37, "trd": NaN, "batb": [[0, 3.3, 13.04], [1, 1.01, 7]], "batl": NaN}, {"timestamp": 1631537651737, "ltp": 2.0, "tv": 281.37, "trd": NaN, "batb": [[1, 2.52, 388.09], [2, 1.01, 7]], "batl": [[0, 6, 107.07]]}, {"timestamp": 1631537680573, "ltp": 2.0, "tv": 281.37, "trd": NaN, "batb": [[0, 1.01, 7], [1, 2.52, 0], [2, 1.01, 0]], "batl": NaN}, {"timestamp": 1631537685308, "ltp": 2.0, "tv": 281.37, "trd": NaN, "batb": [[0, 2.5, 20], [1, 1.01, 7]], "batl": NaN}, {"timestamp": 1631537686614, "ltp": 2.0, "tv": 281.37, "trd": NaN, "batb": NaN, "batl": [[0, 4.2, 149.26]]}, {"timestamp": 1631537686979, "ltp": 2.0, "tv": 281.37, "trd": NaN, "batb": [[1, 2.12, 395.62], [2, 1.01, 7]], "batl": NaN}, {"timestamp": 1631537711907, "ltp": 2.0, "tv": 281.37, "trd": NaN, "batb": [[0, 1.01, 7], [1, 2.12, 0], [2, 1.01, 0]], "batl": NaN}, {"timestamp": 1631537717409, "ltp": 2.0, "tv": 281.37, "trd": NaN, "batb": [[0, 3.3, 13.04], [1, 2.52, 388.09], [2, 1.01, 7]], "batl": [[0, 6, 107.07]]}, {"timestamp": 1631537720536, "ltp": 2.0, "tv": 281.37, "trd": NaN, "batb": [[1, 2.7, 50.99], [2, 2.52, 388.09]], "batl": NaN}, {"timestamp": 1631537721217, "ltp": 2.0, "tv": 281.37, "trd": NaN, "batb": [[1, 2.52, 388.09], [2, 1.01, 7]], "batl": NaN}, {"timestamp": 1631537728930, "ltp": 2.0, "tv": 281.37, "trd": NaN, "batb": NaN, "batl": [[0, 5, 57.94], [1, 6, 107.07]]}, {"timestamp": 1631537742260, "ltp": 2.0, "tv": 281.37, "trd": NaN, "batb": NaN, "batl": [[0, 6, 107.07], [1, 6, 0]]}, {"timestamp": 1631537775411, "ltp": 2.0, "tv": 281.37, "trd": NaN, "batb": [[0, 1.01, 7], [1, 2.52, 0], [2, 1.01, 0]], "batl": [[0, 3.75, 57.94]]}, {"timestamp": 1631537780296, "ltp": 2.0, "tv": 281.37, "trd": NaN, "batb": [[0, 2.66, 18.07], [1, 1.01, 7]], "batl": NaN}, {"timestamp": 1631537781287, "ltp": 2.0, "tv": 281.37, "trd": NaN, "batb": [[1, 2.22, 391.36], [2, 1.01, 7]], "batl": [[1, 4.6, 137.18]]}, {"timestamp": 1631537809329, "ltp": 2.0, "tv": 281.37, "trd": NaN, "batb": [[0, 2.22, 391.36], [1, 1.01, 7], [2, 1.01, 0]], "batl": NaN}, {"timestamp": 1631537810581, "ltp": 2.0, "tv": 281.37, "trd": NaN, "batb": [[0, 1.01, 7], [1, 1.01, 0]], "batl": NaN}, {"timestamp": 1631537814286, "ltp": 2.0, "tv": 281.37, "trd": NaN, "batb": [[0, 3.4, 12.5], [1, 1.01, 7]], "batl": NaN}, {"timestamp": 1631537816682, "ltp": 2.0, "tv": 281.37, "trd": NaN, "batb": [[1, 2.62, 385.81], [2, 1.01, 7]], "batl": [[0, 6.6, 99.8]]}, {"timestamp": 1631537820529, "ltp": 2.0, "tv": 281.37, "trd": NaN, "batb": NaN, "batl": [[0, 5.5, 57.94], [1, 6.6, 99.8]]}, {"timestamp": 1631537825511, "ltp": 3.5, "tv": 292.0, "trd": [[3.5, 24.61]], "batb": NaN, "batl": NaN}, {"timestamp": 1631537841245, "ltp": 3.5, "tv": 292.0, "trd": NaN, "batb": NaN, "batl": [[0, 6.6, 99.8], [1, 6.6, 0]]}, {"timestamp": 1631537878475, "ltp": 3.5, "tv": 292.0, "trd": NaN, "batb": [[0, 1.01, 7], [1, 2.62, 0], [2, 1.01, 0]], "batl": NaN}, {"timestamp": 1631537882783, "ltp": 3.5, "tv": 292.0, "trd": NaN, "batb": [[0, 5.3, 10], [1, 1.01, 7]], "batl": NaN}, {"timestamp": 1631537884373, "ltp": 3.5, "tv": 292.0, "trd": NaN, "batb": [[1, 3.1, 380.06], [2, 1.01, 7]], "batl": [[0, 10.5, 72.99]]}, {"timestamp": 1631537904814, "ltp": 3.5, "tv": 292.0, "trd": NaN, "batb": [[1, 1.01, 7], [2, 1.01, 0]], "batl": NaN}, {"timestamp": 1631537910826, "ltp": 3.5, "tv": 292.0, "trd": NaN, "batb": [[0, 1.01, 7], [1, 1.01, 0]], "batl": NaN}, {"timestamp": 1631537915712, "ltp": 3.5, "tv": 292.0, "trd": NaN, "batb": [[0, 3.7, 11.11], [1, 1.01, 7]], "batl": NaN}, {"timestamp": 1631537917226, "ltp": 3.5, "tv": 292.0, "trd": NaN, "batb": [[1, 2.62, 385.81], [2, 1.01, 7]], "batl": [[0, 6.6, 99.8]]}, {"timestamp": 1631537918127, "ltp": 3.5, "tv": 292.0, "trd": NaN, "batb": NaN, "batl": [[0, 5.3, 5.32], [1, 6.6, 99.8]]}, {"timestamp": 1631537924244, "ltp": 3.5, "tv": 292.0, "trd": NaN, "batb": NaN, "batl": [[1, 5.5, 57.94], [2, 6.6, 99.8]]}, {"timestamp": 1631537934221, "ltp": 3.5, "tv": 292.0, "trd": NaN, "batb": [[1, 1.01, 7], [2, 1.01, 0]], "batl": [[2, 6.6, 0]]}, {"timestamp": 1631537935327, "ltp": 3.5, "tv": 292.0, "trd": NaN, "batb": NaN, "batl": [[1, 5.5, 0]]}, {"timestamp": 1631537950074, "ltp": 3.5, "tv": 292.0, "trd": NaN, "batb": [[0, 1.01, 7], [1, 1.01, 0]], "batl": NaN}, {"timestamp": 1631537955156, "ltp": 3.5, "tv": 292.0, "trd": NaN, "batb": [[0, 2.84, 16.3], [1, 1.01, 7]], "batl": NaN}, {"timestamp": 1631537955887, "ltp": 3.5, "tv": 292.0, "trd": NaN, "batb": [[1, 2.22, 391.36], [2, 1.01, 7]], "batl": [[0, 4.6, 137.18], [1, 5.3, 5.32]]}, {"timestamp": 1631537957186, "ltp": 3.5, "tv": 292.0, "trd": NaN, "batb": NaN, "batl": [[0, 3.7, 57.94], [1, 4.6, 137.18], [2, 5.3, 5.32]]}, {"timestamp": 1631537961560, "ltp": 3.5, "tv": 292.0, "trd": NaN, "batb": NaN, "batl": [[0, 4.6, 137.18], [1, 5.3, 5.32], [2, 5.3, 0]]}, {"timestamp": 1631537991508, "ltp": 3.5, "tv": 292.0, "trd": NaN, "batb": [[0, 1.01, 7], [1, 2.22, 0], [2, 1.01, 0]], "batl": [[0, 5.3, 5.32], [1, 5.3, 0]]}, {"timestamp": 1631537995729, "ltp": 3.5, "tv": 292.0, "trd": NaN, "batb": [[0, 1.98, 30.61], [1, 1.01, 7]], "batl": NaN}, {"timestamp": 1631537997518, "ltp": 3.5, "tv": 292.0, "trd": NaN, "batb": [[1, 1.77, 409.74], [2, 1.01, 7]], "batl": [[0, 3, 215.29], [1, 5.3, 5.32]]}, {"timestamp": 1631538000722, "ltp": 3.5, "tv": 292.0, "trd": NaN, "batb": NaN, "batl": [[0, 2.5, 57.94], [1, 3, 215.29], [2, 5.3, 5.32]]}, {"timestamp": 1631538006335, "ltp": 3.5, "tv": 292.22, "trd": [[2, 5.78], [2.72, 2.79], [2.84, 197.55], [3.5, 24.64], [3.65, 31.94], [5.3, 9.58], [7.6, 9.58], [9.2, 5.32], [17.5, 2.87]], "batb": [[1, 1.77, 409.67]], "batl": [[1, 3, 215.25], [2, 5.3, 5.32]]}, {"timestamp": 1631538013470, "ltp": 3.5, "tv": 292.22, "trd": NaN, "batb": [[1, 1.01, 7], [2, 1.01, 0]], "batl": [[1, 5.3, 5.32], [2, 5.3, 0]]}, {"timestamp": 1631538015917, "ltp": 3.5, "tv": 292.22, "trd": NaN, "batb": [[0, 1.01, 7], [1, 1.01, 0]], "batl": NaN}, {"timestamp": 1631538020892, "ltp": 3.5, "tv": 292.22, "trd": NaN, "batb": [[0, 1.88, 34.09], [1, 1.01, 7]], "batl": NaN}, {"timestamp": 1631538021827, "ltp": 3.5, "tv": 292.22, "trd": NaN, "batb": [[1, 1.7, 416.91], [2, 1.01, 7]], "batl": [[1, 2.82, 233.26], [2, 5.3, 5.32]]}, {"timestamp": 1631538023229, "ltp": 3.5, "tv": 292.22, "trd": NaN, "batb": NaN, "batl": [[0, 2.82, 233.26], [1, 5.3, 5.32], [2, 5.3, 0]]}, {"timestamp": 1631538025596, "ltp": 3.5, "tv": 292.22, "trd": NaN, "batb": [[1, 1.01, 7], [2, 1.01, 0]], "batl": [[0, 5.3, 5.32], [1, 5.3, 0]]}, {"timestamp": 1631538040109, "ltp": 3.5, "tv": 292.22, "trd": NaN, "batb": [[0, 1.01, 7], [1, 1.01, 0]], "batl": NaN}, {"timestamp": 1631538045109, "ltp": 3.5, "tv": 292.22, "trd": NaN, "batb": [[0, 2.66, 18.07], [1, 1.01, 7]], "batl": NaN}, {"timestamp": 1631538046260, "ltp": 3.5, "tv": 292.22, "trd": NaN, "batb": [[1, 2.12, 395.55], [2, 1.01, 7]], "batl": [[0, 4.2, 149.23], [1, 5.3, 5.32]]}, {"timestamp": 1631538064159, "ltp": 3.5, "tv": 292.22, "trd": NaN, "batb": NaN, "batl": [[0, 3.35, 36.44], [1, 4.2, 149.23], [2, 5.3, 5.32]]}, {"timestamp": 1631538079288, "ltp": 3.5, "tv": 292.22, "trd": NaN, "batb": [[1, 1.01, 7], [2, 1.01, 0]], "batl": [[1, 5.3, 5.32], [2, 5.3, 0]]}, {"timestamp": 1631538080495, "ltp": 3.5, "tv": 292.22, "trd": NaN, "batb": NaN, "batl": [[0, 5.3, 5.32], [1, 5.3, 0]]}, {"timestamp": 1631538098790, "ltp": 3.5, "tv": 292.22, "trd": NaN, "batb": [[0, 1.01, 7], [1, 1.01, 0]], "batl": NaN}, {"timestamp": 1631538104502, "ltp": 3.5, "tv": 292.22, "trd": NaN, "batb": [[0, 4.3, 10], [1, 2.84, 381.75], [2, 1.01, 7]], "batl": [[1, 8.2, 86.2]]}, {"timestamp": 1631538133203, "ltp": 5.3, "tv": 297.55, "trd": [[5.3, 14.9]], "batb": NaN, "batl": [[0, 8.2, 86.2], [1, 8.2, 0]]}, {"timestamp": 1631538163554, "ltp": 5.3, "tv": 297.55, "trd": NaN, "batb": [[1, 1.01, 7], [2, 1.01, 0]], "batl": NaN}, {"timestamp": 1631538177286, "ltp": 5.3, "tv": 297.55, "trd": NaN, "batb": [[0, 1.01, 7], [1, 1.01, 0]], "batl": NaN}, {"timestamp": 1631538182278, "ltp": 5.3, "tv": 297.55, "trd": NaN, "batb": [[0, 8, 10], [1, 1.01, 7]], "batl": NaN}, {"timestamp": 1631538183279, "ltp": 5.3, "tv": 297.55, "trd": NaN, "batb": [[1, 3.7, 376.81], [2, 1.01, 7]], "batl": [[0, 23, 51.79]]}, {"timestamp": 1631538205139, "ltp": 5.3, "tv": 297.55, "trd": NaN, "batb": [[1, 1.01, 7], [2, 1.01, 0]], "batl": NaN}, {"timestamp": 1631538206597, "ltp": 8.6, "tv": 302.87, "trd": [[8.6, 5.32]], "batb": NaN, "batl": NaN}, {"timestamp": 1631538217724, "ltp": 8.6, "tv": 302.87, "trd": NaN, "batb": [[0, 1.01, 7], [1, 1.01, 0]], "batl": NaN}, {"timestamp": 1631538222739, "ltp": 8.6, "tv": 302.87, "trd": NaN, "batb": [[0, 5.3, 10], [1, 1.01, 7]], "batl": NaN}, {"timestamp": 1631538225132, "ltp": 8.6, "tv": 302.87, "trd": NaN, "batb": [[1, 2.98, 380.55], [2, 1.01, 7]], "batl": [[0, 9.4, 78.73]]}, {"timestamp": 1631538244769, "ltp": 8.6, "tv": 302.87, "trd": NaN, "batb": [[1, 1.01, 7], [2, 1.01, 0]], "batl": NaN}, {"timestamp": 1631538249678, "ltp": 8.6, "tv": 302.87, "trd": NaN, "batb": [[0, 1.01, 7], [1, 1.01, 0]], "batl": NaN}, {"timestamp": 1631538254790, "ltp": 8.6, "tv": 302.87, "trd": NaN, "batb": [[0, 4.3, 10], [1, 2.84, 381.75], [2, 1.01, 7]], "batl": [[0, 8.2, 86.2]]}, {"timestamp": 1631538258876, "ltp": 8.6, "tv": 302.87, "trd": NaN, "batb": [[1, 1.01, 7], [2, 1.01, 0]], "batl": NaN}, {"timestamp": 1631538266692, "ltp": 8.6, "tv": 302.87, "trd": NaN, "batb": [[0, 1.01, 7], [1, 1.01, 0]], "batl": NaN}, {"timestamp": 1631538272003, "ltp": 8.6, "tv": 302.87, "trd": NaN, "batb": [[0, 12, 10], [1, 4, 379.77], [2, 1.01, 7]], "batl": [[0, 46, 43.47]]}, {"timestamp": 1631538298529, "ltp": 8.6, "tv": 302.87, "trd": NaN, "batb": [[1, 1.01, 7], [2, 1.01, 0]], "batl": NaN}, {"timestamp": 1631538304551, "ltp": 8.6, "tv": 302.87, "trd": NaN, "batb": [[0, 1.01, 7], [1, 1.01, 0]], "batl": NaN}, {"timestamp": 1631538309396, "ltp": 8.6, "tv": 302.87, "trd": NaN, "batb": [[0, 7.6, 10], [1, 1.01, 7]], "batl": NaN}, {"timestamp": 1631538311079, "ltp": 8.6, "tv": 302.87, "trd": NaN, "batb": [[1, 3.4, 382.26], [2, 1.01, 7]], "batl": [[0, 15.5, 60.22]]}, {"timestamp": 1631538312160, "ltp": 7.6, "tv": 312.87, "trd": [[7.6, 19.58]], "batb": [[0, 3.4, 382.26], [1, 1.01, 7], [2, 1.01, 0]], "batl": NaN}, {"timestamp": 1631538315051, "ltp": 7.6, "tv": 312.87, "trd": NaN, "batb": NaN, "batl": [[0, 12, 2.66], [1, 15.5, 60.22]]}, {"timestamp": 1631538317865, "ltp": 7.6, "tv": 312.87, "trd": NaN, "batb": [[0, 1.01, 7], [1, 1.01, 0]], "batl": [[1, 15.5, 0]]}, {"timestamp": 1631538333065, "ltp": 7.6, "tv": 312.87, "trd": NaN, "batb": [[0, 4.1, 10], [1, 1.01, 7]], "batl": NaN}, {"timestamp": 1631538334066, "ltp": 7.6, "tv": 312.87, "trd": NaN, "batb": [[1, 2.72, 384.67], [2, 1.01, 7]], "batl": [[0, 7.2, 92.96], [1, 12, 2.66]]}, {"timestamp": 1631538365609, "ltp": 7.6, "tv": 312.87, "trd": NaN, "batb": [[1, 1.01, 7], [2, 1.01, 0]], "batl": [[0, 12, 2.66], [1, 12, 0]]}, {"timestamp": 1631538386399, "ltp": 7.6, "tv": 312.87, "trd": NaN, "batb": [[0, 1.01, 7], [1, 1.01, 0]], "batl": NaN}, {"timestamp": 1631538399746, "ltp": 12.0, "tv": 315.53, "trd": [[12, 2.66]], "batb": NaN, "batl": NaN}]}, {"runnerId": 11252269, "odds": [{"timestamp": 1631531266803, "ltp": 1.54, "tv": 28.1, "trd": [[1.54, 28.11]], "batb": NaN, "batl": NaN}, {"timestamp": 1631531301570, "ltp": 1.54, "tv": 28.1, "trd": NaN, "batb": NaN, "batl": [[0, 1.54, 331.28]]}, {"timestamp": 1631532507158, "ltp": 1.54, "tv": 28.1, "trd": NaN, "batb": NaN, "batl": [[0, 1.4, 255.54]]}, {"timestamp": 1631532773798, "ltp": 1.54, "tv": 28.1, "trd": NaN, "batb": NaN, "batl": [[0, 1.11, 5.06], [1, 1.4, 255.54]]}, {"timestamp": 1631532785548, "ltp": 1.11, "tv": 38.23, "trd": [[1.11, 10.12]], "batb": [[0, 1.11, 250.48], [1, 1.01, 7]], "batl": NaN}, {"timestamp": 1631532788890, "ltp": 1.11, "tv": 38.23, "trd": NaN, "batb": NaN, "batl": [[0, 1.22, 255.54]]}, {"timestamp": 1631532912092, "ltp": 1.22, "tv": 41.63, "trd": [[1.22, 3.41]], "batb": NaN, "batl": [[0, 1.22, 253.83]]}, {"timestamp": 1631533079986, "ltp": 1.22, "tv": 41.63, "trd": NaN, "batb": [[0, 1.01, 7], [1, 1.01, 0]], "batl": NaN}, {"timestamp": 1631533085814, "ltp": 1.22, "tv": 41.63, "trd": NaN, "batb": NaN, "batl": [[0, 1.06, 3.34]]}, {"timestamp": 1631533090122, "ltp": 1.22, "tv": 41.63, "trd": NaN, "batb": NaN, "batl": [[1, 1.16, 255.54], [2, 1.17, 255.54]]}, {"timestamp": 1631533111248, "ltp": 1.22, "tv": 41.63, "trd": NaN, "batb": NaN, "batl": [[2, 1.17, 0]]}, {"timestamp": 1631533155313, "ltp": 1.06, "tv": 44.97, "trd": [[1.06, 3.34]], "batb": NaN, "batl": [[0, 1.16, 255.54], [1, 1.16, 0]]}, {"timestamp": 1631533843476, "ltp": 1.06, "tv": 44.97, "trd": NaN, "batb": NaN, "batl": [[0, 1.15, 255.54]]}, {"timestamp": 1631534009852, "ltp": 1.05, "tv": 48.59, "trd": [[1.05, 3.62]], "batb": NaN, "batl": NaN}, {"timestamp": 1631534018875, "ltp": 1.05, "tv": 48.59, "trd": NaN, "batb": NaN, "batl": [[0, 1.15, 255.54]]}, {"timestamp": 1631534357715, "ltp": 1.05, "tv": 48.59, "trd": NaN, "batb": [[0, 1.16, 255.54], [1, 1.01, 7]], "batl": NaN}, {"timestamp": 1631534378130, "ltp": 1.05, "tv": 48.59, "trd": NaN, "batb": [[0, 1.01, 7], [1, 1.01, 0]], "batl": NaN}, {"timestamp": 1631534384666, "ltp": 1.05, "tv": 48.59, "trd": NaN, "batb": [[0, 1.2, 255.54], [1, 1.01, 7]], "batl": NaN}, {"timestamp": 1631534409814, "ltp": 1.05, "tv": 48.59, "trd": NaN, "batb": NaN, "batl": [[0, 1.46, 255.54]]}, {"timestamp": 1631534410719, "ltp": 1.05, "tv": 48.59, "trd": NaN, "batb": NaN, "batl": [[0, 1.4, 255.54], [1, 1.46, 255.54]]}, {"timestamp": 1631534517920, "ltp": 1.05, "tv": 48.59, "trd": NaN, "batb": NaN, "batl": [[0, 1.46, 255.54], [1, 1.46, 0]]}, {"timestamp": 1631534531129, "ltp": 1.05, "tv": 48.59, "trd": NaN, "batb": [[0, 1.01, 7], [1, 1.01, 0]], "batl": NaN}, {"timestamp": 1631534593108, "ltp": 1.05, "tv": 48.59, "trd": NaN, "batb": [[0, 1.22, 255.54], [1, 1.01, 7]], "batl": NaN}, {"timestamp": 1631534636996, "ltp": 1.05, "tv": 48.59, "trd": NaN, "batb": [[0, 1.01, 7], [1, 1.01, 0]], "batl": NaN}, {"timestamp": 1631534642673, "ltp": 1.05, "tv": 48.59, "trd": NaN, "batb": NaN, "batl": [[0, 1.35, 255.54]]}, {"timestamp": 1631534801234, "ltp": 1.05, "tv": 48.59, "trd": NaN, "batb": NaN, "batl": [[0, 1.25, 255.54], [1, 1.35, 255.54]]}, {"timestamp": 1631534803706, "ltp": 1.05, "tv": 48.59, "trd": NaN, "batb": [[0, 1.1, 255.54], [1, 1.01, 7]], "batl": NaN}, {"timestamp": 1631534827488, "ltp": 1.05, "tv": 48.59, "trd": NaN, "batb": NaN, "batl": [[1, 1.35, 0]]}, {"timestamp": 1631534831584, "ltp": 1.05, "tv": 48.59, "trd": NaN, "batb": NaN, "batl": [[0, 1.2, 255.54], [1, 1.25, 255.54]]}, {"timestamp": 1631534839998, "ltp": 1.05, "tv": 48.59, "trd": NaN, "batb": NaN, "batl": [[0, 1.25, 255.54], [1, 1.25, 0]]}, {"timestamp": 1631534869951, "ltp": 1.05, "tv": 48.59, "trd": NaN, "batb": [[0, 1.01, 7], [1, 1.01, 0]], "batl": NaN}, {"timestamp": 1631534959679, "ltp": 1.05, "tv": 48.59, "trd": NaN, "batb": NaN, "batl": [[0, 1.11, 2]]}, {"timestamp": 1631534981724, "ltp": 1.05, "tv": 48.59, "trd": NaN, "batb": [[0, 1.08, 255.54], [1, 1.01, 7]], "batl": NaN}, {"timestamp": 1631535016946, "ltp": 1.08, "tv": 52.59, "trd": [[1.08, 4]], "batb": [[0, 1.08, 253.53]], "batl": NaN}, {"timestamp": 1631535027095, "ltp": 1.08, "tv": 52.59, "trd": NaN, "batb": NaN, "batl": [[0, 1.12, 1.93]]}, {"timestamp": 1631535028515, "ltp": 1.08, "tv": 52.59, "trd": NaN, "batb": NaN, "batl": [[1, 1.24, 255.54]]}, {"timestamp": 1631535028937, "ltp": 1.08, "tv": 52.59, "trd": NaN, "batb": NaN, "batl": [[1, 1.23, 255.54], [2, 1.24, 255.54]]}, {"timestamp": 1631535083580, "ltp": 1.08, "tv": 52.59, "trd": NaN, "batb": NaN, "batl": [[1, 1.23, 0], [2, 1.24, 0]]}, {"timestamp": 1631535087302, "ltp": 1.08, "tv": 52.59, "trd": NaN, "batb": NaN, "batl": [[1, 1.2, 255.54]]}, {"timestamp": 1631535158044, "ltp": 1.08, "tv": 52.59, "trd": NaN, "batb": [[1, 1.05, 599.99], [2, 1.01, 7]], "batl": NaN}, {"timestamp": 1631535233059, "ltp": 1.08, "tv": 52.59, "trd": NaN, "batb": [[1, 1.01, 7], [2, 1.01, 0]], "batl": NaN}, {"timestamp": 1631535238046, "ltp": 1.08, "tv": 52.59, "trd": NaN, "batb": [[0, 1.08, 628.52]], "batl": NaN}, {"timestamp": 1631535254468, "ltp": 1.08, "tv": 52.59, "trd": NaN, "batb": [[1, 1.04, 2.89], [2, 1.01, 7]], "batl": NaN}, {"timestamp": 1631535256074, "ltp": 1.08, "tv": 52.59, "trd": NaN, "batb": [[1, 1.01, 7], [2, 1.01, 0]], "batl": NaN}, {"timestamp": 1631535260089, "ltp": 1.08, "tv": 52.59, "trd": NaN, "batb": [[0, 1.08, 253.53]], "batl": NaN}, {"timestamp": 1631535264607, "ltp": 1.08, "tv": 52.59, "trd": NaN, "batb": [[1, 1.04, 1446.45], [2, 1.01, 7]], "batl": NaN}, {"timestamp": 1631535272781, "ltp": 1.08, "tv": 52.59, "trd": NaN, "batb": [[1, 1.01, 7], [2, 1.01, 0]], "batl": NaN}, {"timestamp": 1631535280160, "ltp": 1.08, "tv": 52.59, "trd": NaN, "batb": [[0, 1.1, 1446.45], [1, 1.08, 253.53], [2, 1.01, 7]], "batl": NaN}, {"timestamp": 1631535282466, "ltp": 1.1, "tv": 2944.28, "trd": [[1.1, 2891.69]], "batb": [[0, 1.08, 254.29], [1, 1.01, 7], [2, 1.01, 0]], "batl": NaN}, {"timestamp": 1631535290288, "ltp": 1.1, "tv": 2944.28, "trd": NaN, "batb": [[0, 1.08, 253.53]], "batl": NaN}, {"timestamp": 1631535297083, "ltp": 1.1, "tv": 2944.28, "trd": NaN, "batb": [[0, 1.08, 628.52]], "batl": NaN}, {"timestamp": 1631535306996, "ltp": 1.1, "tv": 2944.28, "trd": NaN, "batb": NaN, "batl": [[1, 1.19, 1446.45], [2, 1.2, 255.54]]}, {"timestamp": 1631535309412, "ltp": 1.19, "tv": 5835.97, "trd": [[1.12, 3.85], [1.19, 2887.85]], "batb": NaN, "batl": [[0, 1.19, 2.68], [1, 1.2, 255.54], [2, 1.2, 0]]}, {"timestamp": 1631535315216, "ltp": 1.19, "tv": 5835.97, "trd": NaN, "batb": NaN, "batl": [[0, 1.2, 255.54], [1, 1.2, 0]]}, {"timestamp": 1631535322613, "ltp": 1.19, "tv": 5835.97, "trd": NaN, "batb": [[0, 1.1, 104.04], [1, 1.08, 374.99], [2, 1.01, 7]], "batl": NaN}, {"timestamp": 1631535323441, "ltp": 1.19, "tv": 5835.97, "trd": NaN, "batb": [[0, 1.1, 312.12]], "batl": NaN}, {"timestamp": 1631535323925, "ltp": 1.19, "tv": 5835.97, "trd": NaN, "batb": [[0, 1.1, 416.16]], "batl": NaN}, {"timestamp": 1631535333626, "ltp": 1.19, "tv": 5835.97, "trd": NaN, "batb": NaN, "batl": [[0, 1.36, 1000]]}, {"timestamp": 1631535379066, "ltp": 1.19, "tv": 5835.97, "trd": NaN, "batb": [[1, 1.09, 3001.37], [2, 1.08, 374.99]], "batl": NaN}, {"timestamp": 1631535380585, "ltp": 1.19, "tv": 5835.97, "trd": NaN, "batb": [[2, 1.01, 7]], "batl": NaN}, {"timestamp": 1631535382990, "ltp": 1.19, "tv": 5835.97, "trd": NaN, "batb": [[1, 1.01, 7], [2, 1.01, 0]], "batl": NaN}, {"timestamp": 1631535385509, "ltp": 1.19, "tv": 5835.97, "trd": NaN, "batb": [[0, 1.12, 249.99], [1, 1.1, 416.16], [2, 1.01, 7]], "batl": NaN}, {"timestamp": 1631535395184, "ltp": 1.19, "tv": 5835.97, "trd": NaN, "batb": [[1, 1.01, 7], [2, 1.01, 0]], "batl": NaN}, {"timestamp": 1631535399364, "ltp": 1.13, "tv": 8727.66, "trd": [[1.13, 2891.69]], "batb": [[0, 1.12, 250.75]], "batl": NaN}, {"timestamp": 1631535410600, "ltp": 1.13, "tv": 8727.66, "trd": NaN, "batb": [[0, 1.12, 249.99]], "batl": NaN}, {"timestamp": 1631535416409, "ltp": 1.13, "tv": 8727.66, "trd": NaN, "batb": [[0, 1.01, 7], [1, 1.01, 0]], "batl": NaN}, {"timestamp": 1631535421217, "ltp": 1.13, "tv": 8727.66, "trd": NaN, "batb": [[0, 1.15, 200], [1, 1.01, 7]], "batl": NaN}, {"timestamp": 1631535423614, "ltp": 1.13, "tv": 8727.66, "trd": NaN, "batb": [[1, 1.14, 260.1], [2, 1.01, 7]], "batl": NaN}, {"timestamp": 1631535424000, "ltp": 1.13, "tv": 8727.66, "trd": NaN, "batb": [[1, 1.14, 364.14]], "batl": NaN}, {"timestamp": 1631535434941, "ltp": 1.13, "tv": 8727.66, "trd": NaN, "batb": NaN, "batl": [[0, 1.25, 1446.45]]}, {"timestamp": 1631535438804, "ltp": 1.25, "tv": 11619.34, "trd": [[1.25, 2891.69]], "batb": NaN, "batl": [[0, 1.25, 0.76]]}, {"timestamp": 1631535448562, "ltp": 1.25, "tv": 11619.34, "trd": NaN, "batb": [[1, 1.01, 7], [2, 1.01, 0]], "batl": NaN}, {"timestamp": 1631535457953, "ltp": 1.25, "tv": 11619.34, "trd": NaN, "batb": [[0, 1.01, 7], [1, 1.01, 0]], "batl": NaN}, {"timestamp": 1631535462860, "ltp": 1.25, "tv": 11619.34, "trd": NaN, "batb": [[0, 1.2, 150], [1, 1.01, 7]], "batl": NaN}, {"timestamp": 1631535491083, "ltp": 1.25, "tv": 11619.34, "trd": NaN, "batb": [[0, 1.21, 1446.45], [1, 1.2, 150], [2, 1.01, 7]], "batl": NaN}, {"timestamp": 1631535493176, "ltp": 1.21, "tv": 14511.03, "trd": [[1.21, 2891.69]], "batb": [[0, 1.2, 150.76], [1, 1.01, 7], [2, 1.01, 0]], "batl": NaN}, {"timestamp": 1631535493994, "ltp": 1.21, "tv": 14511.03, "trd": NaN, "batb": [[0, 1.01, 7.76], [1, 1.01, 0]], "batl": NaN}, {"timestamp": 1631535497499, "ltp": 1.21, "tv": 14511.03, "trd": NaN, "batb": [[0, 1.01, 7]], "batl": NaN}, {"timestamp": 1631535498906, "ltp": 1.21, "tv": 14511.03, "trd": NaN, "batb": [[0, 1.31, 96.77], [1, 1.01, 7]], "batl": NaN}, {"timestamp": 1631535502234, "ltp": 1.21, "tv": 14511.03, "trd": NaN, "batb": [[1, 1.23, 255.54], [2, 1.01, 7]], "batl": NaN}, {"timestamp": 1631535503629, "ltp": 1.21, "tv": 14511.03, "trd": NaN, "batb": [[1, 1.25, 255.54], [2, 1.23, 255.54]], "batl": [[0, 1.46, 255.54]]}, {"timestamp": 1631535504000, "ltp": 1.21, "tv": 14511.03, "trd": NaN, "batb": NaN, "batl": [[0, 1.45, 255.54], [1, 1.46, 255.54]]}, {"timestamp": 1631535505547, "ltp": 1.21, "tv": 14511.03, "trd": NaN, "batb": NaN, "batl": [[0, 1.4, 52.02], [1, 1.45, 255.54], [2, 1.46, 255.54]]}, {"timestamp": 1631535506633, "ltp": 1.21, "tv": 14511.03, "trd": NaN, "batb": NaN, "batl": [[0, 1.45, 255.54], [1, 1.46, 255.54], [2, 1.46, 0]]}, {"timestamp": 1631535512529, "ltp": 1.31, "tv": 14615.07, "trd": [[1.31, 104.04]], "batb": [[0, 1.31, 44.75]], "batl": NaN}, {"timestamp": 1631535512730, "ltp": 1.31, "tv": 14615.07, "trd": NaN, "batb": [[0, 1.25, 255.54], [1, 1.23, 255.54], [2, 1.01, 7]], "batl": NaN}, {"timestamp": 1631535517740, "ltp": 1.31, "tv": 14615.07, "trd": NaN, "batb": [[0, 1.31, 96.77], [1, 1.25, 255.54], [2, 1.23, 255.54]], "batl": NaN}, {"timestamp": 1631535529041, "ltp": 1.31, "tv": 14615.07, "trd": NaN, "batb": NaN, "batl": [[0, 1.43, 1446.45], [1, 1.45, 255.54], [2, 1.46, 255.54]]}, {"timestamp": 1631535531249, "ltp": 1.43, "tv": 17506.75, "trd": [[1.43, 2891.69]], "batb": NaN, "batl": [[0, 1.45, 256.3], [1, 1.46, 255.54], [2, 1.46, 0]]}, {"timestamp": 1631535535746, "ltp": 1.43, "tv": 17506.75, "trd": NaN, "batb": NaN, "batl": [[1, 1.46, 0]]}, {"timestamp": 1631535537676, "ltp": 1.43, "tv": 17506.75, "trd": NaN, "batb": NaN, "batl": [[0, 1.45, 255.54]]}, {"timestamp": 1631535544291, "ltp": 1.43, "tv": 17506.75, "trd": NaN, "batb": [[0, 1.25, 255.54], [1, 1.23, 255.54], [2, 1.01, 7]], "batl": NaN}, {"timestamp": 1631535548633, "ltp": 1.43, "tv": 17506.75, "trd": NaN, "batb": [[0, 1.38, 78.94], [1, 1.25, 255.54], [2, 1.23, 255.54]], "batl": NaN}, {"timestamp": 1631535550519, "ltp": 1.43, "tv": 17506.75, "trd": NaN, "batb": [[1, 1.33, 255.54], [2, 1.25, 255.54]], "batl": NaN}, {"timestamp": 1631535551827, "ltp": 1.43, "tv": 17506.75, "trd": NaN, "batb": NaN, "batl": [[0, 1.5, 255.54]]}, {"timestamp": 1631535562050, "ltp": 1.43, "tv": 17506.75, "trd": NaN, "batb": [[0, 1.39, 1446.45], [1, 1.38, 78.94], [2, 1.33, 255.54]], "batl": NaN}, {"timestamp": 1631535564450, "ltp": 1.39, "tv": 20398.44, "trd": [[1.39, 2891.69]], "batb": [[0, 1.38, 79.7], [1, 1.33, 255.54], [2, 1.25, 255.54]], "batl": NaN}, {"timestamp": 1631535570359, "ltp": 1.39, "tv": 20398.44, "trd": NaN, "batb": [[0, 1.38, 78.94]], "batl": NaN}, {"timestamp": 1631535578259, "ltp": 1.39, "tv": 20398.44, "trd": NaN, "batb": [[0, 1.33, 255.54], [1, 1.25, 255.54], [2, 1.23, 255.54]], "batl": NaN}, {"timestamp": 1631535583484, "ltp": 1.39, "tv": 20398.44, "trd": NaN, "batb": [[0, 1.34, 88.23]], "batl": NaN}, {"timestamp": 1631535588947, "ltp": 1.39, "tv": 20398.44, "trd": NaN, "batb": [[1, 1.29, 255.54], [2, 1.25, 255.54]], "batl": NaN}, {"timestamp": 1631535620404, "ltp": 1.39, "tv": 20398.44, "trd": NaN, "batb": [[0, 1.35, 506.26], [1, 1.34, 88.23], [2, 1.29, 255.54]], "batl": NaN}, {"timestamp": 1631535622709, "ltp": 1.35, "tv": 21398.33, "trd": [[1.35, 999.89]], "batb": [[0, 1.35, 6.36]], "batl": NaN}, {"timestamp": 1631535629121, "ltp": 1.35, "tv": 21398.33, "trd": NaN, "batb": [[1, 1.29, 255.54], [2, 1.25, 255.54]], "batl": NaN}, {"timestamp": 1631535630234, "ltp": 1.35, "tv": 21406.33, "trd": [[1.35, 1007.89]], "batb": [[0, 1.35, 2.36]], "batl": NaN}, {"timestamp": 1631535632748, "ltp": 1.35, "tv": 21411.07, "trd": [[1.35, 1012.63]], "batb": [[0, 1.29, 255.54], [1, 1.25, 255.54], [2, 1.23, 255.54]], "batl": [[0, 1.35, 1.63], [1, 1.5, 255.54]]}, {"timestamp": 1631535634329, "ltp": 1.38, "tv": 21425.14, "trd": [[1.38, 14.07]], "batb": NaN, "batl": [[0, 1.5, 255.54], [1, 1.5, 0]]}, {"timestamp": 1631535639354, "ltp": 1.38, "tv": 21425.14, "trd": NaN, "batb": [[0, 1.45, 66.66], [1, 1.29, 255.54], [2, 1.25, 255.54]], "batl": NaN}, {"timestamp": 1631535643037, "ltp": 1.38, "tv": 21425.14, "trd": NaN, "batb": [[1, 1.36, 255.54], [2, 1.29, 255.54]], "batl": NaN}, {"timestamp": 1631535644668, "ltp": 1.38, "tv": 21425.14, "trd": NaN, "batb": NaN, "batl": [[0, 1.55, 255.54]]}, {"timestamp": 1631535667301, "ltp": 1.38, "tv": 21425.14, "trd": NaN, "batb": NaN, "batl": [[0, 1.54, 1346.48], [1, 1.55, 255.54]]}, {"timestamp": 1631535672701, "ltp": 1.54, "tv": 24115.63, "trd": [[1.54, 2718.6]], "batb": NaN, "batl": [[0, 1.54, 1.38]]}, {"timestamp": 1631535679422, "ltp": 1.54, "tv": 24115.63, "trd": NaN, "batb": [[0, 1.36, 255.54], [1, 1.29, 255.54], [2, 1.25, 255.54]], "batl": NaN}, {"timestamp": 1631535681233, "ltp": 1.54, "tv": 24115.63, "trd": NaN, "batb": [[1, 1.25, 255.54], [2, 1.23, 255.54]], "batl": NaN}, {"timestamp": 1631535682430, "ltp": 1.54, "tv": 24115.63, "trd": NaN, "batb": [[1, 1.23, 255.54], [2, 1.01, 7]], "batl": NaN}, {"timestamp": 1631535683011, "ltp": 1.54, "tv": 24115.63, "trd": NaN, "batb": [[1, 1.01, 7], [2, 1.01, 0]], "batl": NaN}, {"timestamp": 1631535696511, "ltp": 1.54, "tv": 24118.39, "trd": [[1.54, 2721.36]], "batb": [[0, 1.54, 2.62], [1, 1.36, 255.54], [2, 1.01, 7]], "batl": [[0, 1.55, 255.54], [1, 1.55, 0]]}, {"timestamp": 1631535697449, "ltp": 1.54, "tv": 24118.39, "trd": NaN, "batb": [[0, 1.36, 255.54], [1, 1.01, 7], [2, 1.01, 0]], "batl": NaN}, {"timestamp": 1631535728478, "ltp": 1.54, "tv": 24118.39, "trd": NaN, "batb": [[0, 1.45, 66.66], [1, 1.36, 255.54], [2, 1.01, 7]], "batl": NaN}, {"timestamp": 1631535760557, "ltp": 1.54, "tv": 24118.39, "trd": NaN, "batb": [[0, 1.36, 255.54], [1, 1.01, 7], [2, 1.01, 0]], "batl": NaN}, {"timestamp": 1631535765470, "ltp": 1.54, "tv": 24118.39, "trd": NaN, "batb": [[0, 1.51, 58.82], [1, 1.36, 255.54], [2, 1.01, 7]], "batl": NaN}, {"timestamp": 1631535783998, "ltp": 1.54, "tv": 24118.39, "trd": NaN, "batb": [[1, 1.45, 255.54], [2, 1.36, 255.54]], "batl": NaN}, {"timestamp": 1631535786882, "ltp": 1.54, "tv": 24118.39, "trd": NaN, "batb": NaN, "batl": [[0, 1.66, 255.54]]}, {"timestamp": 1631535806338, "ltp": 1.54, "tv": 24118.39, "trd": NaN, "batb": [[0, 1.45, 255.54], [1, 1.36, 255.54], [2, 1.01, 7]], "batl": NaN}, {"timestamp": 1631535809842, "ltp": 1.54, "tv": 24118.39, "trd": NaN, "batb": [[0, 1.36, 255.54], [1, 1.01, 7], [2, 1.01, 0]], "batl": NaN}, {"timestamp": 1631535811217, "ltp": 1.54, "tv": 24118.39, "trd": NaN, "batb": [[0, 1.45, 66.66], [1, 1.36, 255.54], [2, 1.01, 7]], "batl": NaN}, {"timestamp": 1631535832943, "ltp": 1.54, "tv": 24118.39, "trd": NaN, "batb": [[0, 1.36, 255.54], [1, 1.01, 7], [2, 1.01, 0]], "batl": NaN}, {"timestamp": 1631535837862, "ltp": 1.54, "tv": 24118.39, "trd": NaN, "batb": [[1, 1.34, 88.23], [2, 1.01, 7]], "batl": NaN}, {"timestamp": 1631535840177, "ltp": 1.54, "tv": 24118.39, "trd": NaN, "batb": [[0, 1.34, 88.23], [1, 1.01, 7], [2, 1.01, 0]], "batl": NaN}, {"timestamp": 1631535846106, "ltp": 1.54, "tv": 24118.39, "trd": NaN, "batb": [[1, 1.28, 255.54], [2, 1.01, 7]], "batl": NaN}, {"timestamp": 1631535863078, "ltp": 1.54, "tv": 24118.39, "trd": NaN, "batb": [[0, 1.28, 255.54], [1, 1.01, 7], [2, 1.01, 0]], "batl": NaN}, {"timestamp": 1631535867957, "ltp": 1.54, "tv": 24118.39, "trd": NaN, "batb": [[0, 1.31, 96.77], [1, 1.28, 255.54], [2, 1.01, 7]], "batl": NaN}, {"timestamp": 1631535877463, "ltp": 1.54, "tv": 24118.39, "trd": NaN, "batb": [[0, 1.28, 255.54], [1, 1.01, 7], [2, 1.01, 0]], "batl": NaN}, {"timestamp": 1631535882165, "ltp": 1.54, "tv": 24118.39, "trd": NaN, "batb": [[0, 1.23, 130.43]], "batl": NaN}, {"timestamp": 1631535888610, "ltp": 1.54, "tv": 24118.39, "trd": NaN, "batb": [[1, 1.2, 255.54], [2, 1.01, 7]], "batl": NaN}, {"timestamp": 1631535890069, "ltp": 1.54, "tv": 24118.39, "trd": NaN, "batb": NaN, "batl": [[0, 1.4, 255.54], [1, 1.66, 255.54]]}, {"timestamp": 1631535921844, "ltp": 1.54, "tv": 24118.39, "trd": NaN, "batb": [[0, 1.2, 255.54], [1, 1.01, 7], [2, 1.01, 0]], "batl": NaN}, {"timestamp": 1631535927584, "ltp": 1.54, "tv": 24118.39, "trd": NaN, "batb": [[0, 1.18, 166.66]], "batl": NaN}, {"timestamp": 1631535931472, "ltp": 1.54, "tv": 24118.39, "trd": NaN, "batb": NaN, "batl": [[0, 1.66, 255.54], [1, 1.66, 0]]}, {"timestamp": 1631535934477, "ltp": 1.54, "tv": 24118.39, "trd": NaN, "batb": [[1, 1.15, 255.54], [2, 1.01, 7]], "batl": NaN}, {"timestamp": 1631535935662, "ltp": 1.54, "tv": 24118.39, "trd": NaN, "batb": NaN, "batl": [[0, 1.3, 255.54], [1, 1.66, 255.54]]}, {"timestamp": 1631535966229, "ltp": 1.54, "tv": 24118.39, "trd": NaN, "batb": [[0, 1.15, 255.54], [1, 1.01, 7], [2, 1.01, 0]], "batl": NaN}, {"timestamp": 1631535969722, "ltp": 1.54, "tv": 24118.39, "trd": NaN, "batb": [[0, 1.01, 7], [1, 1.01, 0]], "batl": NaN}, {"timestamp": 1631535971237, "ltp": 1.54, "tv": 24118.39, "trd": NaN, "batb": [[0, 1.11, 272.72], [1, 1.01, 7]], "batl": NaN}, {"timestamp": 1631535973729, "ltp": 1.54, "tv": 24118.39, "trd": NaN, "batb": NaN, "batl": [[0, 1.2, 255.54], [1, 1.3, 255.54]]}, {"timestamp": 1631535975708, "ltp": 1.54, "tv": 24118.39, "trd": NaN, "batb": [[1, 1.09, 255.54], [2, 1.01, 7]], "batl": NaN}, {"timestamp": 1631536008122, "ltp": 1.54, "tv": 24118.39, "trd": NaN, "batb": [[0, 1.09, 255.54], [1, 1.01, 7], [2, 1.01, 0]], "batl": NaN}, {"timestamp": 1631536011052, "ltp": 1.54, "tv": 24118.39, "trd": NaN, "batb": NaN, "batl": [[0, 1.3, 255.54], [1, 1.3, 0]]}, {"timestamp": 1631536013046, "ltp": 1.54, "tv": 24118.39, "trd": NaN, "batb": [[0, 1.18, 166.66], [1, 1.09, 255.54], [2, 1.01, 7]], "batl": NaN}, {"timestamp": 1631536049026, "ltp": 1.54, "tv": 24118.39, "trd": NaN, "batb": [[0, 1.09, 255.54], [1, 1.01, 7], [2, 1.01, 0]], "batl": NaN}, {"timestamp": 1631536053909, "ltp": 1.54, "tv": 24118.39, "trd": NaN, "batb": [[0, 1.11, 272.72], [1, 1.09, 255.54], [2, 1.01, 7]], "batl": NaN}, {"timestamp": 1631536057562, "ltp": 1.54, "tv": 24118.39, "trd": NaN, "batb": NaN, "batl": [[0, 1.2, 255.54], [1, 1.3, 255.54]]}, {"timestamp": 1631536077862, "ltp": 1.54, "tv": 24118.39, "trd": NaN, "batb": [[0, 1.09, 255.54], [1, 1.01, 7], [2, 1.01, 0]], "batl": NaN}, {"timestamp": 1631536082759, "ltp": 1.54, "tv": 24118.39, "trd": NaN, "batb": [[0, 1.12, 249.99], [1, 1.09, 255.54], [2, 1.01, 7]], "batl": NaN}, {"timestamp": 1631536095166, "ltp": 1.54, "tv": 24118.39, "trd": NaN, "batb": [[0, 1.09, 255.54], [1, 1.01, 7], [2, 1.01, 0]], "batl": NaN}, {"timestamp": 1631536099078, "ltp": 1.54, "tv": 24118.39, "trd": NaN, "batb": [[0, 1.01, 7], [1, 1.01, 0]], "batl": NaN}, {"timestamp": 1631536100186, "ltp": 1.54, "tv": 24118.39, "trd": NaN, "batb": [[0, 1.08, 374.99], [1, 1.01, 7]], "batl": NaN}, {"timestamp": 1631536104573, "ltp": 1.54, "tv": 24118.39, "trd": NaN, "batb": [[1, 1.07, 255.54], [2, 1.01, 7]], "batl": NaN}, {"timestamp": 1631536105573, "ltp": 1.54, "tv": 24118.39, "trd": NaN, "batb": [[0, 1.08, 630.53], [2, 1.06, 255.54]], "batl": [[1, 1.3, 0]]}, {"timestamp": 1631536108694, "ltp": 1.54, "tv": 24118.39, "trd": NaN, "batb": NaN, "batl": [[0, 1.16, 255.54]]}, {"timestamp": 1631536111380, "ltp": 1.54, "tv": 24118.39, "trd": NaN, "batb": NaN, "batl": [[1, 1.17, 255.54]]}, {"timestamp": 1631536122595, "ltp": 1.54, "tv": 24118.39, "trd": NaN, "batb": [[0, 1.08, 255.54]], "batl": NaN}, {"timestamp": 1631536124518, "ltp": 1.54, "tv": 24118.39, "trd": NaN, "batb": [[0, 1.07, 255.54], [1, 1.06, 255.54], [2, 1.05, 255.54]], "batl": NaN}, {"timestamp": 1631536124892, "ltp": 1.54, "tv": 24118.39, "trd": NaN, "batb": [[0, 1.06, 255.54], [1, 1.05, 255.54], [2, 1.04, 511.07]], "batl": NaN}, {"timestamp": 1631536127617, "ltp": 1.54, "tv": 24118.39, "trd": NaN, "batb": [[1, 1.05, 855.53]], "batl": NaN}, {"timestamp": 1631536226330, "ltp": 1.54, "tv": 24118.39, "trd": NaN, "batb": [[1, 1.05, 255.54]], "batl": NaN}, {"timestamp": 1631536231353, "ltp": 1.54, "tv": 24118.39, "trd": NaN, "batb": [[0, 1.08, 374.99], [1, 1.06, 255.54], [2, 1.05, 255.54]], "batl": NaN}, {"timestamp": 1631536236212, "ltp": 1.54, "tv": 24118.39, "trd": NaN, "batb": NaN, "batl": [[0, 1.2, 255.54]]}, {"timestamp": 1631536269788, "ltp": 1.54, "tv": 24118.39, "trd": NaN, "batb": [[0, 1.06, 255.54], [1, 1.05, 255.54], [2, 1.04, 511.07]], "batl": NaN}, {"timestamp": 1631536274702, "ltp": 1.54, "tv": 24118.39, "trd": NaN, "batb": [[0, 1.12, 249.99], [1, 1.06, 255.54], [2, 1.05, 255.54]], "batl": NaN}, {"timestamp": 1631536278217, "ltp": 1.54, "tv": 24118.39, "trd": NaN, "batb": NaN, "batl": [[0, 1.24, 255.54]]}, {"timestamp": 1631536279898, "ltp": 1.54, "tv": 24118.39, "trd": NaN, "batb": [[0, 1.13, 255.54], [1, 1.12, 249.99], [2, 1.06, 255.54]], "batl": NaN}, {"timestamp": 1631536313764, "ltp": 1.54, "tv": 24118.39, "trd": NaN, "batb": [[1, 1.06, 255.54], [2, 1.05, 255.54]], "batl": NaN}, {"timestamp": 1631536316786, "ltp": 1.54, "tv": 24118.39, "trd": NaN, "batb": [[0, 1.06, 255.54], [1, 1.05, 255.54], [2, 1.04, 511.07]], "batl": NaN}, {"timestamp": 1631536318777, "ltp": 1.54, "tv": 24118.39, "trd": NaN, "batb": [[0, 1.08, 374.99], [1, 1.06, 255.54], [2, 1.05, 255.54]], "batl": NaN}, {"timestamp": 1631536322581, "ltp": 1.54, "tv": 24118.39, "trd": NaN, "batb": [[0, 1.11, 255.54], [1, 1.1, 255.54], [2, 1.08, 374.99]], "batl": NaN}, {"timestamp": 1631536354483, "ltp": 1.54, "tv": 24118.39, "trd": NaN, "batb": [[2, 1.06, 255.54]], "batl": NaN}, {"timestamp": 1631536357561, "ltp": 1.54, "tv": 24118.39, "trd": NaN, "batb": [[0, 1.06, 255.54], [1, 1.05, 255.54], [2, 1.04, 511.07]], "batl": NaN}, {"timestamp": 1631536359395, "ltp": 1.54, "tv": 24118.39, "trd": NaN, "batb": [[1, 1.05, 855.53]], "batl": NaN}, {"timestamp": 1631536363950, "ltp": 1.54, "tv": 24118.39, "trd": NaN, "batb": NaN, "batl": [[0, 1.12, 255.54], [1, 1.24, 255.54]]}, {"timestamp": 1631536385912, "ltp": 1.12, "tv": 24162.08, "trd": [[1.12, 47.54]], "batb": NaN, "batl": [[0, 1.12, 211.84]]}, {"timestamp": 1631536389884, "ltp": 1.12, "tv": 24162.08, "trd": NaN, "batb": [[1, 1.05, 255.54]], "batl": NaN}, {"timestamp": 1631536392179, "ltp": 1.12, "tv": 24162.08, "trd": NaN, "batb": NaN, "batl": [[0, 1.24, 255.54], [1, 1.24, 0]]}, {"timestamp": 1631536394780, "ltp": 1.12, "tv": 24162.08, "trd": NaN, "batb": [[0, 1.11, 272.72], [1, 1.06, 255.54], [2, 1.05, 255.54]], "batl": NaN}, {"timestamp": 1631536397515, "ltp": 1.12, "tv": 24162.08, "trd": NaN, "batb": [[0, 1.12, 43.7], [1, 1.11, 272.72], [2, 1.06, 255.54]], "batl": NaN}, {"timestamp": 1631536399809, "ltp": 1.12, "tv": 24162.08, "trd": NaN, "batb": NaN, "batl": [[0, 1.21, 255.54], [1, 1.24, 255.54]]}, {"timestamp": 1631536401997, "ltp": 1.12, "tv": 24162.08, "trd": NaN, "batb": [[0, 1.17, 41.82], [1, 1.12, 43.7], [2, 1.11, 272.72]], "batl": NaN}, {"timestamp": 1631536415206, "ltp": 1.12, "tv": 24162.08, "trd": NaN, "batb": NaN, "batl": [[0, 1.24, 255.54], [1, 1.24, 0]]}, {"timestamp": 1631536418222, "ltp": 1.12, "tv": 24162.08, "trd": NaN, "batb": [[2, 1.06, 255.54]], "batl": NaN}, {"timestamp": 1631536423238, "ltp": 1.12, "tv": 24162.08, "trd": NaN, "batb": [[0, 1.18, 166.66], [1, 1.17, 41.82], [2, 1.12, 43.7]], "batl": NaN}, {"timestamp": 1631536423753, "ltp": 1.12, "tv": 24162.08, "trd": NaN, "batb": [[0, 1.21, 40.44], [1, 1.18, 166.66], [2, 1.17, 41.82]], "batl": NaN}, {"timestamp": 1631536425644, "ltp": 1.12, "tv": 24162.08, "trd": NaN, "batb": NaN, "batl": [[0, 1.32, 255.54]]}, {"timestamp": 1631536427947, "ltp": 1.12, "tv": 24162.08, "trd": NaN, "batb": [[2, 1.12, 43.7]], "batl": NaN}, {"timestamp": 1631536428838, "ltp": 1.12, "tv": 24162.08, "trd": NaN, "batb": [[2, 1.06, 255.54]], "batl": NaN}, {"timestamp": 1631536433854, "ltp": 1.12, "tv": 24162.08, "trd": NaN, "batb": [[2, 1.12, 1.86]], "batl": NaN}, {"timestamp": 1631536463506, "ltp": 1.12, "tv": 24162.08, "trd": NaN, "batb": [[1, 1.12, 1.86], [2, 1.06, 255.54]], "batl": NaN}, {"timestamp": 1631536466694, "ltp": 1.12, "tv": 24162.08, "trd": NaN, "batb": [[0, 1.12, 1.86], [1, 1.06, 255.54], [2, 1.05, 255.54]], "batl": NaN}, {"timestamp": 1631536468510, "ltp": 1.12, "tv": 24162.08, "trd": NaN, "batb": [[1, 1.11, 272.72], [2, 1.06, 255.54]], "batl": NaN}, {"timestamp": 1631536473399, "ltp": 1.12, "tv": 24162.08, "trd": NaN, "batb": NaN, "batl": [[0, 1.21, 255.54], [1, 1.32, 255.54]]}, {"timestamp": 1631536475518, "ltp": 1.12, "tv": 24162.08, "trd": NaN, "batb": [[0, 1.14, 42.93], [1, 1.12, 1.86], [2, 1.11, 272.72]], "batl": NaN}, {"timestamp": 1631536507662, "ltp": 1.12, "tv": 24162.08, "trd": NaN, "batb": [[2, 1.06, 255.54]], "batl": NaN}, {"timestamp": 1631536509250, "ltp": 1.12, "tv": 24162.08, "trd": NaN, "batb": NaN, "batl": [[0, 1.32, 255.54], [1, 1.32, 0]]}, {"timestamp": 1631536513376, "ltp": 1.12, "tv": 24162.08, "trd": NaN, "batb": [[0, 1.21, 40.44], [1, 1.18, 166.66], [2, 1.14, 42.93]], "batl": NaN}, {"timestamp": 1631536537303, "ltp": 1.12, "tv": 24162.08, "trd": NaN, "batb": [[1, 1.14, 42.93], [2, 1.12, 1.86]], "batl": NaN}, {"timestamp": 1631536542190, "ltp": 1.12, "tv": 24162.08, "trd": NaN, "batb": [[0, 1.27, 111.11], [1, 1.21, 40.44], [2, 1.14, 42.93]], "batl": NaN}, {"timestamp": 1631536543502, "ltp": 1.12, "tv": 24162.08, "trd": NaN, "batb": [[0, 1.31, 37.36], [1, 1.27, 111.11], [2, 1.21, 40.44]], "batl": NaN}, {"timestamp": 1631536544080, "ltp": 1.12, "tv": 24162.08, "trd": NaN, "batb": [[0, 1.32, 37.07], [1, 1.31, 37.36], [2, 1.27, 111.11]], "batl": NaN}, {"timestamp": 1631536546815, "ltp": 1.12, "tv": 24162.08, "trd": NaN, "batb": NaN, "batl": [[0, 1.46, 255.54]]}, {"timestamp": 1631536554203, "ltp": 1.12, "tv": 24162.08, "trd": NaN, "batb": [[1, 1.27, 111.11], [2, 1.21, 40.44]], "batl": NaN}, {"timestamp": 1631536556502, "ltp": 1.12, "tv": 24162.08, "trd": NaN, "batb": [[2, 1.12, 1.86]], "batl": NaN}, {"timestamp": 1631536561223, "ltp": 1.12, "tv": 24162.08, "trd": NaN, "batb": [[0, 1.27, 111.11], [1, 1.12, 1.86], [2, 1.06, 255.54]], "batl": NaN}, {"timestamp": 1631536565345, "ltp": 1.12, "tv": 24162.08, "trd": NaN, "batb": [[0, 1.4, 34.96], [1, 1.27, 111.11], [2, 1.12, 1.86]], "batl": NaN}, {"timestamp": 1631536571516, "ltp": 1.4, "tv": 24186.02, "trd": [[1.4, 23.94]], "batb": [[0, 1.4, 11.02]], "batl": NaN}, {"timestamp": 1631536573720, "ltp": 1.4, "tv": 24186.02, "trd": NaN, "batb": [[1, 1.12, 1.86], [2, 1.06, 255.54]], "batl": NaN}, {"timestamp": 1631536575445, "ltp": 1.4, "tv": 24197.04, "trd": [[1.4, 34.96]], "batb": [[0, 1.12, 1.86], [1, 1.06, 255.54], [2, 1.05, 255.54]], "batl": NaN}, {"timestamp": 1631536579548, "ltp": 1.4, "tv": 24197.04, "trd": NaN, "batb": [[0, 1.28, 107.14], [1, 1.12, 1.86], [2, 1.06, 255.54]], "batl": NaN}, {"timestamp": 1631536581256, "ltp": 1.4, "tv": 24197.04, "trd": NaN, "batb": [[1, 1.06, 255.54], [2, 1.05, 255.54]], "batl": [[0, 1.5, 255.54]]}, {"timestamp": 1631536582145, "ltp": 1.4, "tv": 24197.04, "trd": NaN, "batb": [[0, 1.31, 255.54], [1, 1.28, 107.14], [2, 1.06, 255.54]], "batl": NaN}, {"timestamp": 1631536582832, "ltp": 1.4, "tv": 24197.04, "trd": NaN, "batb": [[2, 1.23, 255.54]], "batl": NaN}, {"timestamp": 1631536590143, "ltp": 1.4, "tv": 24197.04, "trd": NaN, "batb": [[1, 1.23, 255.54], [2, 1.06, 255.54]], "batl": NaN}, {"timestamp": 1631536595047, "ltp": 1.4, "tv": 24197.04, "trd": NaN, "batb": [[0, 1.38, 78.94], [1, 1.31, 255.54], [2, 1.23, 255.54]], "batl": NaN}, {"timestamp": 1631536599295, "ltp": 1.4, "tv": 24197.04, "trd": NaN, "batb": [[1, 1.36, 255.54], [2, 1.31, 255.54]], "batl": NaN}, {"timestamp": 1631536623426, "ltp": 1.4, "tv": 24197.04, "trd": NaN, "batb": [[0, 1.36, 255.54], [1, 1.31, 255.54], [2, 1.23, 255.54]], "batl": NaN}, {"timestamp": 1631536628386, "ltp": 1.4, "tv": 24197.04, "trd": NaN, "batb": [[0, 1.42, 71.42], [1, 1.36, 255.54], [2, 1.31, 255.54]], "batl": NaN}, {"timestamp": 1631536645593, "ltp": 1.4, "tv": 24197.04, "trd": NaN, "batb": [[0, 1.36, 255.54], [1, 1.31, 255.54], [2, 1.23, 255.54]], "batl": NaN}, {"timestamp": 1631536648717, "ltp": 1.4, "tv": 24197.04, "trd": NaN, "batb": [[0, 1.31, 255.54], [1, 1.23, 255.54], [2, 1.06, 255.54]], "batl": NaN}, {"timestamp": 1631536650514, "ltp": 1.4, "tv": 24197.04, "trd": NaN, "batb": [[0, 1.31, 96.77]], "batl": NaN}, {"timestamp": 1631536655324, "ltp": 1.4, "tv": 24197.04, "trd": NaN, "batb": [[1, 1.26, 255.54], [2, 1.23, 255.54]], "batl": NaN}, {"timestamp": 1631536657208, "ltp": 1.4, "tv": 24197.04, "trd": NaN, "batb": NaN, "batl": [[0, 1.44, 255.54], [1, 1.45, 255.54]]}, {"timestamp": 1631536683949, "ltp": 1.4, "tv": 24197.04, "trd": NaN, "batb": NaN, "batl": [[1, 1.45, 0]]}, {"timestamp": 1631536707969, "ltp": 1.4, "tv": 24197.04, "trd": NaN, "batb": [[0, 1.26, 255.54], [1, 1.23, 255.54], [2, 1.06, 255.54]], "batl": NaN}, {"timestamp": 1631536710599, "ltp": 1.4, "tv": 24197.04, "trd": NaN, "batb": [[0, 1.06, 255.54], [1, 1.05, 255.54], [2, 1.04, 511.07]], "batl": NaN}, {"timestamp": 1631536712887, "ltp": 1.4, "tv": 24197.04, "trd": NaN, "batb": [[0, 1.18, 166.66], [1, 1.06, 255.54], [2, 1.05, 255.54]], "batl": NaN}, {"timestamp": 1631536713777, "ltp": 1.4, "tv": 24197.04, "trd": NaN, "batb": NaN, "batl": [[0, 1.3, 255.54], [1, 1.44, 255.54]]}, {"timestamp": 1631536756058, "ltp": 1.18, "tv": 24250.21, "trd": [[1.18, 53.17]], "batb": [[0, 1.06, 255.54], [1, 1.05, 255.54], [2, 1.04, 511.07]], "batl": NaN}, {"timestamp": 1631536760953, "ltp": 1.18, "tv": 24250.21, "trd": NaN, "batb": [[0, 1.18, 166.66], [1, 1.06, 255.54], [2, 1.05, 255.54]], "batl": NaN}, {"timestamp": 1631536776923, "ltp": 1.18, "tv": 24250.21, "trd": NaN, "batb": [[0, 1.06, 255.54], [1, 1.05, 255.54], [2, 1.04, 511.07]], "batl": NaN}, {"timestamp": 1631536781827, "ltp": 1.18, "tv": 24250.21, "trd": NaN, "batb": [[0, 1.08, 374.99], [1, 1.06, 255.54], [2, 1.05, 255.54]], "batl": NaN}, {"timestamp": 1631536783437, "ltp": 1.18, "tv": 24250.21, "trd": NaN, "batb": NaN, "batl": [[0, 1.16, 255.54], [1, 1.3, 255.54], [2, 1.44, 255.54]]}, {"timestamp": 1631536809071, "ltp": 1.18, "tv": 24250.21, "trd": NaN, "batb": NaN, "batl": [[0, 1.3, 255.54], [1, 1.44, 255.54], [2, 1.44, 0]]}, {"timestamp": 1631536812184, "ltp": 1.18, "tv": 24250.21, "trd": NaN, "batb": NaN, "batl": [[1, 1.44, 0]]}, {"timestamp": 1631536814582, "ltp": 1.18, "tv": 24250.21, "trd": NaN, "batb": NaN, "batl": [[0, 1.2, 255.54]]}, {"timestamp": 1631536836592, "ltp": 1.18, "tv": 24250.21, "trd": NaN, "batb": NaN, "batl": [[0, 1.09, 2.89], [1, 1.2, 255.54]]}, {"timestamp": 1631536841090, "ltp": 1.18, "tv": 24250.21, "trd": NaN, "batb": [[0, 1.06, 255.54], [1, 1.05, 255.54], [2, 1.04, 511.07]], "batl": NaN}, {"timestamp": 1631536843220, "ltp": 1.18, "tv": 24250.21, "trd": NaN, "batb": NaN, "batl": [[1, 1.2, 0]]}, {"timestamp": 1631536843800, "ltp": 1.18, "tv": 24250.21, "trd": NaN, "batb": NaN, "batl": [[0, 1.08, 88.43], [1, 1.09, 2.89]]}, {"timestamp": 1631536844891, "ltp": 1.18, "tv": 24250.21, "trd": NaN, "batb": NaN, "batl": [[1, 1.09, 0]]}, {"timestamp": 1631536847397, "ltp": 1.18, "tv": 24250.21, "trd": NaN, "batb": [[0, 1.16, 255.54], [1, 1.06, 255.54], [2, 1.05, 255.54]], "batl": NaN}, {"timestamp": 1631536849431, "ltp": 1.18, "tv": 24250.21, "trd": NaN, "batb": [[0, 1.17, 255.54], [1, 1.16, 255.54], [2, 1.06, 255.54]], "batl": NaN}, {"timestamp": 1631536850629, "ltp": 1.18, "tv": 24250.21, "trd": NaN, "batb": [[2, 1.08, 221.47]], "batl": [[0, 1.3, 255.54]]}, {"timestamp": 1631536851512, "ltp": 1.18, "tv": 24250.21, "trd": NaN, "batb": [[2, 1.08, 138.42]], "batl": NaN}, {"timestamp": 1631536852506, "ltp": 1.18, "tv": 24250.21, "trd": NaN, "batb": [[0, 1.18, 166.66], [1, 1.17, 255.54], [2, 1.16, 255.54]], "batl": NaN}, {"timestamp": 1631536870145, "ltp": 1.18, "tv": 24427.06, "trd": [[1.18, 230.02]], "batb": [[0, 1.17, 255.54], [1, 1.16, 255.54], [2, 1.07, 255.54]], "batl": NaN}, {"timestamp": 1631536872124, "ltp": 1.18, "tv": 24427.06, "trd": NaN, "batb": [[0, 1.28, 2.17], [1, 1.17, 255.54], [2, 1.16, 255.54]], "batl": NaN}, {"timestamp": 1631536872750, "ltp": 1.18, "tv": 24427.06, "trd": NaN, "batb": [[2, 1.07, 255.54]], "batl": NaN}, {"timestamp": 1631536875152, "ltp": 1.18, "tv": 24427.06, "trd": NaN, "batb": [[2, 1.11, 272.72]], "batl": NaN}, {"timestamp": 1631536877348, "ltp": 1.18, "tv": 24427.06, "trd": NaN, "batb": [[0, 1.17, 255.54], [1, 1.11, 272.72], [2, 1.07, 255.54]], "batl": NaN}, {"timestamp": 1631536879273, "ltp": 1.18, "tv": 24427.06, "trd": NaN, "batb": [[1, 1.07, 255.54], [2, 1.06, 255.54]], "batl": NaN}, {"timestamp": 1631536884280, "ltp": 1.18, "tv": 24427.06, "trd": NaN, "batb": [[0, 1.2, 150], [1, 1.17, 255.54], [2, 1.07, 255.54]], "batl": NaN}, {"timestamp": 1631536887511, "ltp": 1.18, "tv": 24427.06, "trd": NaN, "batb": NaN, "batl": [[0, 1.4, 255.54]]}, {"timestamp": 1631536888306, "ltp": 1.18, "tv": 24427.06, "trd": NaN, "batb": [[0, 1.23, 255.54], [1, 1.2, 150], [2, 1.17, 255.54]], "batl": NaN}, {"timestamp": 1631536889395, "ltp": 1.18, "tv": 24427.06, "trd": NaN, "batb": [[2, 1.07, 255.54]], "batl": NaN}, {"timestamp": 1631536892215, "ltp": 1.18, "tv": 24427.06, "trd": NaN, "batb": [[1, 1.07, 255.54], [2, 1.06, 255.54]], "batl": NaN}, {"timestamp": 1631536897129, "ltp": 1.18, "tv": 24427.06, "trd": NaN, "batb": [[0, 1.34, 88.23], [1, 1.23, 255.54], [2, 1.07, 255.54]], "batl": NaN}, {"timestamp": 1631536899926, "ltp": 1.18, "tv": 24427.06, "trd": NaN, "batb": [[0, 1.36, 255.54], [1, 1.34, 88.23], [2, 1.23, 255.54]], "batl": NaN}, {"timestamp": 1631536901015, "ltp": 1.18, "tv": 24427.06, "trd": NaN, "batb": NaN, "batl": [[0, 1.53, 255.54]]}, {"timestamp": 1631536926739, "ltp": 1.18, "tv": 24427.06, "trd": NaN, "batb": [[1, 1.23, 255.54], [2, 1.07, 255.54]], "batl": NaN}, {"timestamp": 1631536934169, "ltp": 1.18, "tv": 24427.06, "trd": NaN, "batb": [[0, 1.55, 54.54], [1, 1.43, 255.54], [2, 1.23, 255.54]], "batl": NaN}, {"timestamp": 1631536934652, "ltp": 1.18, "tv": 24427.06, "trd": NaN, "batb": [[1, 1.46, 255.54], [2, 1.43, 255.54]], "batl": NaN}, {"timestamp": 1631536935962, "ltp": 1.18, "tv": 24427.06, "trd": NaN, "batb": NaN, "batl": [[0, 1.7, 255.54]]}, {"timestamp": 1631536939864, "ltp": 1.18, "tv": 24427.06, "trd": NaN, "batb": [[1, 1.5, 255.54], [2, 1.46, 255.54]], "batl": NaN}, {"timestamp": 1631536959208, "ltp": 1.18, "tv": 24427.06, "trd": NaN, "batb": [[0, 1.5, 255.54], [1, 1.46, 255.54], [2, 1.43, 255.54]], "batl": NaN}, {"timestamp": 1631536961508, "ltp": 1.18, "tv": 24427.06, "trd": NaN, "batb": [[0, 1.46, 255.54], [1, 1.43, 255.54], [2, 1.23, 255.54]], "batl": NaN}, {"timestamp": 1631536963188, "ltp": 1.18, "tv": 24427.06, "trd": NaN, "batb": [[0, 1.23, 255.54], [1, 1.07, 255.54], [2, 1.06, 255.54]], "batl": NaN}, {"timestamp": 1631536964079, "ltp": 1.18, "tv": 24427.06, "trd": NaN, "batb": [[0, 1.38, 78.94], [1, 1.23, 255.54], [2, 1.07, 255.54]], "batl": NaN}, {"timestamp": 1631536969306, "ltp": 1.18, "tv": 24427.06, "trd": NaN, "batb": NaN, "batl": [[0, 1.53, 255.54], [1, 1.7, 255.54]]}, {"timestamp": 1631536970388, "ltp": 1.18, "tv": 24427.06, "trd": NaN, "batb": [[1, 1.35, 255.54], [2, 1.23, 255.54]], "batl": NaN}, {"timestamp": 1631536990168, "ltp": 1.18, "tv": 24427.06, "trd": NaN, "batb": NaN, "batl": [[1, 1.7, 0]]}, {"timestamp": 1631536996375, "ltp": 1.18, "tv": 24427.06, "trd": NaN, "batb": [[0, 1.35, 255.54], [1, 1.23, 255.54], [2, 1.07, 255.54]], "batl": NaN}, {"timestamp": 1631536997793, "ltp": 1.18, "tv": 24427.06, "trd": NaN, "batb": [[0, 1.23, 255.54], [1, 1.07, 255.54], [2, 1.06, 255.54]], "batl": NaN}, {"timestamp": 1631537000473, "ltp": 1.18, "tv": 24427.06, "trd": NaN, "batb": [[0, 1.07, 255.54], [1, 1.06, 255.54], [2, 1.05, 255.54]], "batl": NaN}, {"timestamp": 1631537001267, "ltp": 1.18, "tv": 24427.06, "trd": NaN, "batb": [[0, 1.18, 166.66], [1, 1.07, 255.54], [2, 1.06, 255.54]], "batl": NaN}, {"timestamp": 1631537003386, "ltp": 1.18, "tv": 24427.06, "trd": NaN, "batb": NaN, "batl": [[0, 1.35, 255.54], [1, 1.53, 255.54]]}, {"timestamp": 1631537004291, "ltp": 1.18, "tv": 24427.06, "trd": NaN, "batb": NaN, "batl": [[0, 1.3, 255.54], [1, 1.35, 255.54]]}, {"timestamp": 1631537005874, "ltp": 1.18, "tv": 24427.06, "trd": NaN, "batb": [[1, 1.17, 255.54], [2, 1.07, 255.54]], "batl": NaN}, {"timestamp": 1631537018896, "ltp": 1.18, "tv": 24427.06, "trd": NaN, "batb": NaN, "batl": [[1, 1.35, 0]]}, {"timestamp": 1631537064474, "ltp": 1.3, "tv": 24453.65, "trd": [[1.3, 26.59]], "batb": NaN, "batl": [[0, 1.3, 242.24]]}, {"timestamp": 1631537065741, "ltp": 1.3, "tv": 24453.65, "trd": NaN, "batb": [[0, 1.17, 255.54], [1, 1.07, 255.54], [2, 1.06, 255.54]], "batl": NaN}, {"timestamp": 1631537069463, "ltp": 1.3, "tv": 24453.65, "trd": NaN, "batb": [[0, 1.07, 255.54], [1, 1.06, 255.54], [2, 1.05, 255.54]], "batl": NaN}, {"timestamp": 1631537070678, "ltp": 1.3, "tv": 24453.65, "trd": NaN, "batb": [[0, 1.2, 150], [1, 1.07, 255.54], [2, 1.06, 255.54]], "batl": NaN}, {"timestamp": 1631537073153, "ltp": 1.3, "tv": 24453.65, "trd": NaN, "batb": [[0, 1.25, 13.82], [1, 1.2, 150], [2, 1.07, 255.54]], "batl": NaN}, {"timestamp": 1631537080397, "ltp": 1.3, "tv": 24453.65, "trd": NaN, "batb": [[1, 1.07, 255.54], [2, 1.06, 255.54]], "batl": NaN}, {"timestamp": 1631537080977, "ltp": 1.3, "tv": 24453.65, "trd": NaN, "batb": [[0, 1.07, 255.54], [1, 1.06, 255.54], [2, 1.05, 255.54]], "batl": NaN}, {"timestamp": 1631537084181, "ltp": 1.3, "tv": 24453.65, "trd": NaN, "batb": [[0, 1.06, 255.54], [1, 1.05, 255.54], [2, 1.03, 255.54]], "batl": NaN}, {"timestamp": 1631537085589, "ltp": 1.3, "tv": 24453.65, "trd": NaN, "batb": [[1, 1.05, 855.53]], "batl": [[0, 1.16, 255.54], [1, 1.2, 255.54], [2, 1.3, 242.24]]}, {"timestamp": 1631537087094, "ltp": 1.3, "tv": 24453.65, "trd": NaN, "batb": [[1, 1.05, 599.99]], "batl": NaN}, {"timestamp": 1631537088091, "ltp": 1.3, "tv": 24453.65, "trd": NaN, "batb": [[2, 1.01, 7]], "batl": NaN}, {"timestamp": 1631537091490, "ltp": 1.3, "tv": 24453.65, "trd": NaN, "batb": NaN, "batl": [[2, 1.3, 0]]}, {"timestamp": 1631537092273, "ltp": 1.3, "tv": 24453.65, "trd": NaN, "batb": NaN, "batl": [[1, 1.2, 0]]}, {"timestamp": 1631537098359, "ltp": 1.3, "tv": 24453.65, "trd": NaN, "batb": NaN, "batl": [[0, 1.14, 255.54], [1, 1.16, 255.54]]}, {"timestamp": 1631537100514, "ltp": 1.06, "tv": 24964.68, "trd": [[1.06, 514.37]], "batb": [[0, 1.05, 599.99], [1, 1.01, 7], [2, 1.01, 0]], "batl": [[0, 1.06, 244.51], [1, 1.14, 255.54], [2, 1.16, 255.54]]}, {"timestamp": 1631537102711, "ltp": 1.06, "tv": 25017.84, "trd": [[1.06, 567.53]], "batb": NaN, "batl": [[0, 1.06, 217.92]]}, {"timestamp": 1631537104614, "ltp": 1.06, "tv": 25017.84, "trd": NaN, "batb": NaN, "batl": [[2, 1.16, 0]]}, {"timestamp": 1631537105075, "ltp": 1.06, "tv": 25017.84, "trd": NaN, "batb": NaN, "batl": [[1, 1.07, 2.89]]}, {"timestamp": 1631537105721, "ltp": 1.06, "tv": 25453.68, "trd": [[1.06, 1003.37]], "batb": NaN, "batl": [[0, 1.07, 2.89], [1, 1.07, 0]]}, {"timestamp": 1631537108718, "ltp": 1.06, "tv": 25453.68, "trd": NaN, "batb": NaN, "batl": [[0, 1.06, 239.23]]}, {"timestamp": 1631537111400, "ltp": 1.06, "tv": 25453.68, "trd": NaN, "batb": [[0, 1.01, 7], [1, 1.01, 0]], "batl": NaN}, {"timestamp": 1631537116406, "ltp": 1.06, "tv": 25453.68, "trd": NaN, "batb": [[0, 1.04, 749.99], [1, 1.01, 7]], "batl": NaN}, {"timestamp": 1631537123418, "ltp": 1.04, "tv": 25897.41, "trd": [[1.04, 399.81], [1.06, 1047.28]], "batb": [[0, 1.04, 550.1]], "batl": NaN}, {"timestamp": 1631537123719, "ltp": 1.04, "tv": 25897.41, "trd": NaN, "batb": [[0, 1.01, 7], [1, 1.01, 0]], "batl": NaN}, {"timestamp": 1631537128632, "ltp": 1.04, "tv": 25897.41, "trd": NaN, "batb": [[0, 1.04, 749.99], [1, 1.01, 7]], "batl": NaN}, {"timestamp": 1631537130725, "ltp": 1.04, "tv": 25897.41, "trd": NaN, "batb": [[0, 1.01, 7], [1, 1.01, 0]], "batl": NaN}, {"timestamp": 1631537135658, "ltp": 1.04, "tv": 25897.41, "trd": NaN, "batb": [[0, 1.18, 166.66], [1, 1.01, 7]], "batl": NaN}, {"timestamp": 1631537137222, "ltp": 1.04, "tv": 25897.41, "trd": NaN, "batb": [[1, 1.11, 425.89], [2, 1.01, 7]], "batl": NaN}, {"timestamp": 1631537139161, "ltp": 1.04, "tv": 25897.41, "trd": NaN, "batb": [[1, 1.16, 425.89], [2, 1.15, 425.89]], "batl": NaN}, {"timestamp": 1631537141140, "ltp": 1.04, "tv": 25897.41, "trd": NaN, "batb": NaN, "batl": [[0, 1.3, 425.89]]}, {"timestamp": 1631537142136, "ltp": 1.18, "tv": 25908.6, "trd": [[1.18, 241.21]], "batb": [[0, 1.16, 425.89], [1, 1.15, 425.89], [2, 1.11, 425.89]], "batl": NaN}, {"timestamp": 1631537144579, "ltp": 1.18, "tv": 25908.6, "trd": NaN, "batb": [[1, 1.11, 425.89], [2, 1.01, 7]], "batl": NaN}, {"timestamp": 1631537145469, "ltp": 1.18, "tv": 25908.6, "trd": NaN, "batb": [[1, 1.01, 7], [2, 1.01, 0]], "batl": NaN}, {"timestamp": 1631537147057, "ltp": 1.18, "tv": 25908.6, "trd": NaN, "batb": [[0, 1.18, 166.66], [1, 1.16, 425.89], [2, 1.01, 7]], "batl": NaN}, {"timestamp": 1631537170304, "ltp": 1.18, "tv": 25908.6, "trd": NaN, "batb": [[0, 1.16, 425.89], [1, 1.01, 7], [2, 1.01, 0]], "batl": NaN}, {"timestamp": 1631537175507, "ltp": 1.18, "tv": 25908.6, "trd": NaN, "batb": [[0, 1.31, 425.89], [1, 1.16, 425.89], [2, 1.01, 7]], "batl": NaN}, {"timestamp": 1631537176494, "ltp": 1.18, "tv": 25908.6, "trd": NaN, "batb": [[0, 1.38, 78.94], [1, 1.31, 425.89], [2, 1.16, 425.89]], "batl": NaN}, {"timestamp": 1631537177321, "ltp": 1.18, "tv": 25908.6, "trd": NaN, "batb": [[1, 1.37, 425.89], [2, 1.31, 425.89]], "batl": NaN}, {"timestamp": 1631537179499, "ltp": 1.18, "tv": 25908.6, "trd": NaN, "batb": [[2, 1.16, 425.89]], "batl": [[0, 1.56, 425.89]]}, {"timestamp": 1631537205248, "ltp": 1.38, "tv": 25978.94, "trd": [[1.38, 84.41]], "batb": [[0, 1.38, 8.6]], "batl": NaN}, {"timestamp": 1631537205666, "ltp": 1.38, "tv": 25978.94, "trd": NaN, "batb": [[0, 1.37, 425.89], [1, 1.16, 425.89], [2, 1.01, 7]], "batl": NaN}, {"timestamp": 1631537210584, "ltp": 1.38, "tv": 25978.94, "trd": NaN, "batb": [[1, 1.31, 96.77], [2, 1.16, 425.89]], "batl": NaN}, {"timestamp": 1631537211552, "ltp": 1.38, "tv": 25978.94, "trd": NaN, "batb": [[1, 1.16, 425.89], [2, 1.01, 7]], "batl": NaN}, {"timestamp": 1631537216858, "ltp": 1.38, "tv": 25978.94, "trd": NaN, "batb": [[0, 1.5, 425.89], [1, 1.37, 425.89], [2, 1.16, 425.89]], "batl": NaN}, {"timestamp": 1631537218153, "ltp": 1.38, "tv": 25978.94, "trd": NaN, "batb": [[0, 1.73, 41.09], [1, 1.5, 425.89], [2, 1.37, 425.89]], "batl": NaN}, {"timestamp": 1631537222055, "ltp": 1.38, "tv": 25978.94, "trd": NaN, "batb": [[1, 1.5, 851.79]], "batl": NaN}, {"timestamp": 1631537226388, "ltp": 1.38, "tv": 25978.94, "trd": NaN, "batb": NaN, "batl": [[0, 1.93, 425.89]]}, {"timestamp": 1631537227490, "ltp": 1.38, "tv": 25978.94, "trd": NaN, "batb": [[1, 1.37, 425.89], [2, 1.16, 425.89]], "batl": NaN}, {"timestamp": 1631537229470, "ltp": 1.38, "tv": 25978.94, "trd": NaN, "batb": NaN, "batl": [[0, 1.87, 255.54], [1, 1.93, 425.89]]}, {"timestamp": 1631537229682, "ltp": 1.38, "tv": 25978.94, "trd": NaN, "batb": [[1, 1.16, 425.89], [2, 1.01, 7]], "batl": NaN}, {"timestamp": 1631537230867, "ltp": 1.38, "tv": 25978.94, "trd": NaN, "batb": [[1, 1.01, 7], [2, 1.01, 0]], "batl": NaN}, {"timestamp": 1631537233376, "ltp": 1.73, "tv": 25985.62, "trd": [[1.73, 6.68]], "batb": [[0, 1.73, 37.75]], "batl": NaN}, {"timestamp": 1631537233692, "ltp": 1.73, "tv": 25985.62, "trd": NaN, "batb": [[0, 1.01, 7], [1, 1.01, 0]], "batl": NaN}, {"timestamp": 1631537238709, "ltp": 1.73, "tv": 25985.62, "trd": NaN, "batb": [[0, 1.73, 41.09], [1, 1.01, 7]], "batl": NaN}, {"timestamp": 1631537241696, "ltp": 1.73, "tv": 25985.62, "trd": NaN, "batb": [[1, 1.61, 255.54], [2, 1.01, 7]], "batl": NaN}, {"timestamp": 1631537274573, "ltp": 1.73, "tv": 25985.62, "trd": NaN, "batb": [[0, 1.75, 38.94], [1, 1.73, 41.09], [2, 1.61, 255.54]], "batl": NaN}, {"timestamp": 1631537287557, "ltp": 1.73, "tv": 25985.62, "trd": NaN, "batb": [[0, 1.73, 41.09], [1, 1.61, 255.54], [2, 1.01, 7]], "batl": NaN}, {"timestamp": 1631537294889, "ltp": 1.87, "tv": 26058.51, "trd": [[1.87, 72.89]], "batb": NaN, "batl": [[0, 1.87, 219.09], [1, 1.93, 0]]}, {"timestamp": 1631537303581, "ltp": 1.87, "tv": 26058.51, "trd": NaN, "batb": [[0, 1.8, 38.36], [1, 1.73, 41.09], [2, 1.61, 255.54]], "batl": NaN}, {"timestamp": 1631537305188, "ltp": 1.87, "tv": 26058.51, "trd": NaN, "batb": [[1, 1.76, 39.22], [2, 1.73, 41.09]], "batl": NaN}, {"timestamp": 1631537306387, "ltp": 1.87, "tv": 26058.51, "trd": NaN, "batb": [[1, 1.73, 41.09], [2, 1.01, 7]], "batl": NaN}, {"timestamp": 1631537308501, "ltp": 1.87, "tv": 26058.51, "trd": NaN, "batb": [[2, 1.64, 255.54]], "batl": NaN}, {"timestamp": 1631537327801, "ltp": 1.87, "tv": 26058.51, "trd": NaN, "batb": NaN, "batl": [[0, 1.97, 255.54]]}, {"timestamp": 1631537426230, "ltp": 1.87, "tv": 26058.51, "trd": NaN, "batb": [[0, 1.73, 41.09], [1, 1.64, 255.54], [2, 1.01, 7]], "batl": NaN}, {"timestamp": 1631537430159, "ltp": 1.87, "tv": 26058.51, "trd": NaN, "batb": [[0, 1.84, 37.52], [1, 1.73, 41.09], [2, 1.64, 255.54]], "batl": NaN}, {"timestamp": 1631537568065, "ltp": 1.87, "tv": 26058.51, "trd": NaN, "batb": NaN, "batl": [[0, 1.93, 36.44], [1, 1.97, 255.54]]}, {"timestamp": 1631537570658, "ltp": 1.87, "tv": 26058.51, "trd": NaN, "batb": [[1, 1.64, 255.54], [2, 1.01, 7]], "batl": NaN}, {"timestamp": 1631537572571, "ltp": 1.87, "tv": 26058.51, "trd": NaN, "batb": NaN, "batl": [[0, 1.97, 255.54], [1, 1.97, 0]]}, {"timestamp": 1631537575576, "ltp": 1.87, "tv": 26058.51, "trd": NaN, "batb": [[1, 1.65, 46.15], [2, 1.64, 255.54]], "batl": NaN}, {"timestamp": 1631537579362, "ltp": 1.87, "tv": 26058.51, "trd": NaN, "batb": [[0, 1.65, 46.15], [1, 1.64, 255.54], [2, 1.01, 7]], "batl": NaN}, {"timestamp": 1631537597393, "ltp": 1.87, "tv": 26058.51, "trd": NaN, "batb": [[0, 1.64, 255.54], [1, 1.01, 7], [2, 1.01, 0]], "batl": NaN}, {"timestamp": 1631537598486, "ltp": 1.87, "tv": 26058.51, "trd": NaN, "batb": [[0, 1.01, 7], [1, 1.01, 0]], "batl": NaN}, {"timestamp": 1631537602291, "ltp": 1.87, "tv": 26058.51, "trd": NaN, "batb": [[0, 1.45, 66.66], [1, 1.01, 7]], "batl": NaN}, {"timestamp": 1631537602810, "ltp": 1.87, "tv": 26058.51, "trd": NaN, "batb": NaN, "batl": [[0, 1.64, 255.54], [1, 1.97, 255.54]]}, {"timestamp": 1631537610381, "ltp": 1.87, "tv": 26058.51, "trd": NaN, "batb": NaN, "batl": [[0, 1.61, 36.44], [1, 1.64, 255.54], [2, 1.97, 255.54]]}, {"timestamp": 1631537613300, "ltp": 1.87, "tv": 26058.51, "trd": NaN, "batb": [[0, 1.46, 72.88], [1, 1.45, 66.66], [2, 1.01, 7]], "batl": NaN}, {"timestamp": 1631537621204, "ltp": 1.87, "tv": 26058.51, "trd": NaN, "batb": NaN, "batl": [[0, 1.6, 255.54], [1, 1.61, 36.44], [2, 1.64, 255.54]]}, {"timestamp": 1631537622404, "ltp": 1.87, "tv": 26058.51, "trd": NaN, "batb": [[0, 1.52, 45.42], [1, 1.46, 72.88], [2, 1.45, 66.66]], "batl": NaN}, {"timestamp": 1631537624120, "ltp": 1.87, "tv": 26058.51, "trd": NaN, "batb": [[1, 1.45, 66.66], [2, 1.01, 7]], "batl": [[1, 1.64, 255.54], [2, 1.97, 255.54]]}, {"timestamp": 1631537645119, "ltp": 1.87, "tv": 26058.51, "trd": NaN, "batb": [[1, 1.01, 7], [2, 1.01, 0]], "batl": NaN}, {"timestamp": 1631537646158, "ltp": 1.87, "tv": 26058.51, "trd": NaN, "batb": [[0, 1.01, 7], [1, 1.01, 0]], "batl": NaN}, {"timestamp": 1631537650173, "ltp": 1.87, "tv": 26058.51, "trd": NaN, "batb": [[0, 1.28, 107.14], [1, 1.01, 7]], "batl": NaN}, {"timestamp": 1631537665976, "ltp": 1.87, "tv": 26058.51, "trd": NaN, "batb": NaN, "batl": [[0, 1.4, 36.44], [1, 1.6, 255.54], [2, 1.64, 255.54]]}, {"timestamp": 1631537680573, "ltp": 1.87, "tv": 26058.51, "trd": NaN, "batb": [[0, 1.01, 7], [1, 1.01, 0]], "batl": NaN}, {"timestamp": 1631537681302, "ltp": 1.87, "tv": 26058.51, "trd": NaN, "batb": NaN, "batl": [[0, 1.6, 255.54], [1, 1.64, 255.54], [2, 1.97, 255.54]]}, {"timestamp": 1631537685308, "ltp": 1.87, "tv": 26058.51, "trd": NaN, "batb": NaN, "batl": [[0, 1.64, 255.54], [1, 1.97, 255.54], [2, 1.97, 0]]}, {"timestamp": 1631537686614, "ltp": 1.87, "tv": 26058.51, "trd": NaN, "batb": [[0, 1.48, 62.5], [1, 1.01, 7]], "batl": [[0, 1.97, 255.54], [1, 1.97, 0]]}, {"timestamp": 1631537689473, "ltp": 1.87, "tv": 26058.51, "trd": NaN, "batb": [[1, 1.47, 46.96], [2, 1.01, 7]], "batl": NaN}, {"timestamp": 1631537691406, "ltp": 1.87, "tv": 26058.51, "trd": NaN, "batb": NaN, "batl": [[0, 1.59, 36.44], [1, 1.97, 255.54]]}, {"timestamp": 1631537692399, "ltp": 1.59, "tv": 26131.4, "trd": [[1.59, 72.89]], "batb": [[0, 1.59, 6.97], [1, 1.48, 62.5], [2, 1.47, 46.96]], "batl": [[0, 1.97, 255.54], [1, 1.97, 0]]}, {"timestamp": 1631537711907, "ltp": 1.59, "tv": 26131.4, "trd": NaN, "batb": [[1, 1.47, 46.96], [2, 1.01, 7]], "batl": NaN}, {"timestamp": 1631537712850, "ltp": 1.59, "tv": 26131.4, "trd": NaN, "batb": [[1, 1.01, 7], [2, 1.01, 0]], "batl": NaN}, {"timestamp": 1631537714735, "ltp": 1.59, "tv": 26131.4, "trd": NaN, "batb": [[0, 1.01, 7], [1, 1.01, 0]], "batl": NaN}, {"timestamp": 1631537717409, "ltp": 1.59, "tv": 26131.4, "trd": NaN, "batb": [[0, 1.28, 107.14], [1, 1.01, 7]], "batl": NaN}, {"timestamp": 1631537718816, "ltp": 1.59, "tv": 26131.4, "trd": NaN, "batb": NaN, "batl": [[0, 1.4, 255.54]]}, {"timestamp": 1631537720536, "ltp": 1.59, "tv": 26131.4, "trd": NaN, "batb": NaN, "batl": [[1, 1.59, 327.45]]}, {"timestamp": 1631537721217, "ltp": 1.59, "tv": 26131.4, "trd": NaN, "batb": NaN, "batl": [[1, 1.59, 13.8]]}, {"timestamp": 1631537721949, "ltp": 1.59, "tv": 26131.4, "trd": NaN, "batb": NaN, "batl": [[1, 1.59, 0]]}, {"timestamp": 1631537732815, "ltp": 1.59, "tv": 26131.4, "trd": NaN, "batb": [[1, 1.25, 255.54], [2, 1.01, 7]], "batl": NaN}, {"timestamp": 1631537734954, "ltp": 1.59, "tv": 26131.4, "trd": NaN, "batb": NaN, "batl": [[0, 1.46, 255.54]]}, {"timestamp": 1631537775411, "ltp": 1.59, "tv": 26131.4, "trd": NaN, "batb": [[0, 1.25, 255.54], [1, 1.01, 7], [2, 1.01, 0]], "batl": NaN}, {"timestamp": 1631537780296, "ltp": 1.59, "tv": 26131.4, "trd": NaN, "batb": [[0, 1.42, 71.42], [1, 1.25, 255.54], [2, 1.01, 7]], "batl": NaN}, {"timestamp": 1631537782596, "ltp": 1.59, "tv": 26131.4, "trd": NaN, "batb": [[1, 1.37, 255.54], [2, 1.25, 255.54]], "batl": NaN}, {"timestamp": 1631537783689, "ltp": 1.59, "tv": 26131.4, "trd": NaN, "batb": NaN, "batl": [[0, 1.59, 255.54]]}, {"timestamp": 1631537809329, "ltp": 1.59, "tv": 26131.4, "trd": NaN, "batb": [[0, 1.37, 255.54], [1, 1.25, 255.54], [2, 1.01, 7]], "batl": NaN}, {"timestamp": 1631537810581, "ltp": 1.59, "tv": 26131.4, "trd": NaN, "batb": [[0, 1.25, 255.54], [1, 1.01, 7], [2, 1.01, 0]], "batl": NaN}, {"timestamp": 1631537814286, "ltp": 1.59, "tv": 26131.4, "trd": NaN, "batb": [[0, 1.27, 111.11], [1, 1.25, 255.54], [2, 1.01, 7]], "batl": [[0, 1.4, 255.54], [1, 1.59, 255.54]]}, {"timestamp": 1631537825511, "ltp": 1.4, "tv": 26158.0, "trd": [[1.4, 61.56]], "batb": NaN, "batl": [[0, 1.4, 228.94]]}, {"timestamp": 1631537864654, "ltp": 1.4, "tv": 26158.0, "trd": NaN, "batb": [[1, 1.01, 7], [2, 1.01, 0]], "batl": NaN}, {"timestamp": 1631537868670, "ltp": 1.4, "tv": 26158.0, "trd": NaN, "batb": [[0, 1.34, 36.06], [1, 1.27, 111.11], [2, 1.01, 7]], "batl": NaN}, {"timestamp": 1631537878475, "ltp": 1.4, "tv": 26158.0, "trd": NaN, "batb": [[0, 1.01, 7], [1, 1.27, 0], [2, 1.01, 0]], "batl": NaN}, {"timestamp": 1631537881161, "ltp": 1.4, "tv": 26158.0, "trd": NaN, "batb": NaN, "batl": [[1, 1.59, 0]]}, {"timestamp": 1631537882783, "ltp": 1.4, "tv": 26158.0, "trd": NaN, "batb": [[0, 1.12, 249.99], [1, 1.01, 7]], "batl": NaN}, {"timestamp": 1631537884373, "ltp": 1.4, "tv": 26158.0, "trd": NaN, "batb": NaN, "batl": [[0, 1.27, 255.54], [1, 1.4, 228.94]]}, {"timestamp": 1631537886493, "ltp": 1.4, "tv": 26158.0, "trd": NaN, "batb": NaN, "batl": [[1, 1.4, 0]]}, {"timestamp": 1631537890167, "ltp": 1.4, "tv": 26158.0, "trd": NaN, "batb": NaN, "batl": [[0, 1.23, 255.54]]}, {"timestamp": 1631537902772, "ltp": 1.4, "tv": 26158.0, "trd": NaN, "batb": [[0, 1.13, 255.54], [1, 1.12, 249.99], [2, 1.01, 7]], "batl": NaN}, {"timestamp": 1631537910826, "ltp": 1.4, "tv": 26158.0, "trd": NaN, "batb": [[1, 1.01, 7], [2, 1.01, 0]], "batl": NaN}, {"timestamp": 1631537917226, "ltp": 1.4, "tv": 26158.0, "trd": NaN, "batb": [[0, 1.23, 130.43], [1, 1.13, 255.54], [2, 1.01, 7]], "batl": NaN}, {"timestamp": 1631537918127, "ltp": 1.4, "tv": 26158.0, "trd": NaN, "batb": [[0, 1.23, 169.71]], "batl": NaN}, {"timestamp": 1631537919322, "ltp": 1.23, "tv": 26164.0, "trd": [[1.23, 6]], "batb": [[0, 1.23, 39.28]], "batl": [[0, 1.46, 255.54]]}, {"timestamp": 1631537924244, "ltp": 1.23, "tv": 26164.0, "trd": NaN, "batb": [[0, 1.23, 169.71]], "batl": NaN}, {"timestamp": 1631537941425, "ltp": 1.23, "tv": 26164.0, "trd": NaN, "batb": [[0, 1.23, 130.43]], "batl": NaN}, {"timestamp": 1631537942162, "ltp": 1.23, "tv": 26164.0, "trd": NaN, "batb": [[1, 1.01, 7], [2, 1.01, 0]], "batl": NaN}, {"timestamp": 1631537945560, "ltp": 1.23, "tv": 26164.0, "trd": NaN, "batb": [[0, 1.31, 36.89], [1, 1.23, 130.43], [2, 1.01, 7]], "batl": NaN}, {"timestamp": 1631537950074, "ltp": 1.23, "tv": 26164.0, "trd": NaN, "batb": [[1, 1.01, 7], [2, 1.01, 0]], "batl": NaN}, {"timestamp": 1631537955156, "ltp": 1.23, "tv": 26164.0, "trd": NaN, "batb": [[0, 1.43, 33.79], [1, 1.38, 78.94], [2, 1.31, 36.89]], "batl": NaN}, {"timestamp": 1631537959567, "ltp": 1.23, "tv": 26164.0, "trd": NaN, "batb": [[2, 1.01, 7]], "batl": NaN}, {"timestamp": 1631537963567, "ltp": 1.23, "tv": 26164.0, "trd": NaN, "batb": [[0, 1.5, 32.21], [1, 1.43, 33.79], [2, 1.38, 78.94]], "batl": NaN}, {"timestamp": 1631537965770, "ltp": 1.23, "tv": 26164.0, "trd": NaN, "batb": [[1, 1.38, 78.94], [2, 1.01, 7]], "batl": NaN}, {"timestamp": 1631537967484, "ltp": 1.23, "tv": 26164.0, "trd": NaN, "batb": NaN, "batl": [[0, 1.6, 255.54]]}, {"timestamp": 1631537991508, "ltp": 1.23, "tv": 26164.0, "trd": NaN, "batb": [[1, 1.01, 7], [2, 1.01, 0]], "batl": NaN}, {"timestamp": 1631537993329, "ltp": 1.5, "tv": 26172.51, "trd": [[1.5, 8.52]], "batb": [[0, 1.5, 27.96]], "batl": NaN}, {"timestamp": 1631537997518, "ltp": 1.5, "tv": 26172.51, "trd": NaN, "batb": [[0, 1.78, 38.46], [1, 1.64, 29.46], [2, 1.5, 27.96]], "batl": NaN}, {"timestamp": 1631537998288, "ltp": 1.5, "tv": 26172.51, "trd": NaN, "batb": [[1, 1.71, 255.54], [2, 1.69, 255.54]], "batl": NaN}, {"timestamp": 1631538000508, "ltp": 1.5, "tv": 26172.51, "trd": NaN, "batb": [[2, 1.5, 27.96]], "batl": NaN}, {"timestamp": 1631538001759, "ltp": 1.5, "tv": 26172.51, "trd": NaN, "batb": NaN, "batl": [[0, 1.96, 255.54]]}, {"timestamp": 1631538002817, "ltp": 1.5, "tv": 26172.51, "trd": NaN, "batb": [[2, 1.01, 7]], "batl": NaN}, {"timestamp": 1631538006335, "ltp": 1.5, "tv": 26163.8, "trd": [[1.04, 399.78], [1.05, 3.61], [1.06, 1047.27], [1.1, 2890.64], [1.11, 10.12], [1.12, 47.53], [1.13, 2890.64], [1.18, 241.23], [1.19, 2886.81], [1.21, 2890.64], [1.25, 2890.64], [1.3, 26.6], [1.35, 1012.26], [1.39, 2890.64], [1.4, 61.55], [1.43, 2890.64], [1.5, 8.52], [1.54, 2720.38], [1.59, 72.88], [1.73, 6.68], [1.87, 72.88]], "batb": [[0, 1.8, 23.29], [1, 1.78, 38.46], [2, 1.71, 255.49]], "batl": [[0, 1.96, 255.49]]}, {"timestamp": 1631538015917, "ltp": 1.5, "tv": 26163.8, "trd": NaN, "batb": [[1, 1.71, 255.49], [2, 1.01, 7]], "batl": NaN}, {"timestamp": 1631538020892, "ltp": 1.5, "tv": 26163.8, "trd": NaN, "batb": [[0, 1.85, 35.29], [1, 1.8, 23.29], [2, 1.71, 255.49]], "batl": NaN}, {"timestamp": 1631538024008, "ltp": 1.5, "tv": 26163.8, "trd": NaN, "batb": NaN, "batl": [[0, 2.18, 255.49]]}, {"timestamp": 1631538025596, "ltp": 1.5, "tv": 26163.8, "trd": NaN, "batb": [[0, 1.87, 255.49], [1, 1.85, 35.29], [2, 1.01, 7]], "batl": NaN}, {"timestamp": 1631538031836, "ltp": 1.5, "tv": 26163.8, "trd": NaN, "batb": [[0, 2.02, 20.75], [1, 1.87, 255.49], [2, 1.85, 35.29]], "batl": NaN}, {"timestamp": 1631538040109, "ltp": 1.5, "tv": 26163.8, "trd": NaN, "batb": [[2, 1.01, 7]], "batl": NaN}, {"timestamp": 1631538040956, "ltp": 1.5, "tv": 26163.8, "trd": NaN, "batb": [[1, 1.01, 7], [2, 1.01, 0]], "batl": NaN}, {"timestamp": 1631538041936, "ltp": 1.5, "tv": 26163.8, "trd": NaN, "batb": [[0, 1.01, 7], [1, 1.01, 0]], "batl": NaN}, {"timestamp": 1631538045109, "ltp": 1.5, "tv": 26163.8, "trd": NaN, "batb": [[0, 1.42, 71.42], [1, 1.01, 7]], "batl": NaN}, {"timestamp": 1631538047821, "ltp": 1.5, "tv": 26163.8, "trd": NaN, "batb": NaN, "batl": [[0, 1.85, 255.49], [1, 2.18, 255.49]]}, {"timestamp": 1631538050119, "ltp": 1.5, "tv": 26163.8, "trd": NaN, "batb": NaN, "batl": [[1, 2.18, 0]]}, {"timestamp": 1631538052150, "ltp": 1.5, "tv": 26163.8, "trd": NaN, "batb": [[0, 1.42, 326.91]], "batl": NaN}, {"timestamp": 1631538056056, "ltp": 1.5, "tv": 26163.8, "trd": NaN, "batb": NaN, "batl": [[0, 1.7, 255.49], [1, 1.85, 255.49]]}, {"timestamp": 1631538056835, "ltp": 1.5, "tv": 26163.8, "trd": NaN, "batb": NaN, "batl": [[0, 1.7, 510.99]]}, {"timestamp": 1631538059968, "ltp": 1.5, "tv": 26163.8, "trd": NaN, "batb": [[0, 1.52, 27.58], [1, 1.42, 326.91], [2, 1.01, 7]], "batl": NaN}, {"timestamp": 1631538075275, "ltp": 1.5, "tv": 26163.8, "trd": NaN, "batb": NaN, "batl": [[1, 1.85, 0]]}, {"timestamp": 1631538098790, "ltp": 1.5, "tv": 26163.8, "trd": NaN, "batb": [[1, 1.42, 255.49]], "batl": NaN}, {"timestamp": 1631538100231, "ltp": 1.5, "tv": 26163.8, "trd": NaN, "batb": [[0, 1.01, 7], [1, 1.42, 0], [2, 1.01, 0]], "batl": NaN}, {"timestamp": 1631538103614, "ltp": 1.5, "tv": 26163.8, "trd": NaN, "batb": NaN, "batl": [[0, 1.4, 255.49], [1, 1.7, 510.99]]}, {"timestamp": 1631538104502, "ltp": 1.5, "tv": 26163.8, "trd": NaN, "batb": [[0, 1.18, 166.66], [1, 1.01, 7]], "batl": NaN}, {"timestamp": 1631538106326, "ltp": 1.5, "tv": 26163.8, "trd": NaN, "batb": NaN, "batl": [[1, 1.52, 35.77], [2, 1.7, 510.99]]}, {"timestamp": 1631538107423, "ltp": 1.5, "tv": 26163.8, "trd": NaN, "batb": NaN, "batl": [[2, 1.7, 0]]}, {"timestamp": 1631538109622, "ltp": 1.5, "tv": 26163.8, "trd": NaN, "batb": [[1, 1.16, 255.49], [2, 1.01, 7]], "batl": NaN}, {"timestamp": 1631538110245, "ltp": 1.5, "tv": 26163.8, "trd": NaN, "batb": [[0, 1.18, 422.15]], "batl": NaN}, {"timestamp": 1631538113645, "ltp": 1.5, "tv": 26163.8, "trd": NaN, "batb": NaN, "batl": [[0, 1.3, 255.49], [1, 1.4, 255.49], [2, 1.52, 35.77]]}, {"timestamp": 1631538125313, "ltp": 1.5, "tv": 26163.8, "trd": NaN, "batb": [[1, 1.01, 7], [2, 1.01, 0]], "batl": NaN}, {"timestamp": 1631538127879, "ltp": 1.5, "tv": 26163.8, "trd": NaN, "batb": NaN, "batl": [[2, 1.52, 0]]}, {"timestamp": 1631538133203, "ltp": 1.18, "tv": 26212.4, "trd": [[1.18, 266.9], [1.23, 28.93]], "batb": [[0, 1.18, 255.49]], "batl": NaN}, {"timestamp": 1631538134195, "ltp": 1.18, "tv": 26212.4, "trd": NaN, "batb": NaN, "batl": [[1, 1.4, 0]]}, {"timestamp": 1631538135822, "ltp": 1.18, "tv": 26212.4, "trd": NaN, "batb": [[0, 1.25, 33.55], [1, 1.18, 255.49], [2, 1.01, 7]], "batl": NaN}, {"timestamp": 1631538138181, "ltp": 1.18, "tv": 26212.4, "trd": NaN, "batb": [[1, 1.18, 422.15]], "batl": NaN}, {"timestamp": 1631538177286, "ltp": 1.18, "tv": 26212.4, "trd": NaN, "batb": [[0, 1.18, 255.49], [1, 1.01, 7], [2, 1.01, 0]], "batl": NaN}, {"timestamp": 1631538177757, "ltp": 1.18, "tv": 26212.4, "trd": NaN, "batb": [[0, 1.01, 7], [1, 1.01, 0]], "batl": NaN}, {"timestamp": 1631538181590, "ltp": 1.18, "tv": 26212.4, "trd": NaN, "batb": NaN, "batl": [[0, 1.13, 255.49], [1, 1.3, 255.49]]}, {"timestamp": 1631538182278, "ltp": 1.18, "tv": 26212.4, "trd": NaN, "batb": [[0, 1.04, 749.99], [1, 1.01, 7]], "batl": NaN}, {"timestamp": 1631538183279, "ltp": 1.18, "tv": 26212.4, "trd": NaN, "batb": NaN, "batl": [[1, 1.3, 0]]}, {"timestamp": 1631538185993, "ltp": 1.18, "tv": 26212.4, "trd": NaN, "batb": NaN, "batl": [[0, 1.13, 510.99]]}, {"timestamp": 1631538190528, "ltp": 1.18, "tv": 26212.4, "trd": NaN, "batb": [[0, 1.05, 255.49], [1, 1.04, 1005.48], [2, 1.03, 255.49]], "batl": NaN}, {"timestamp": 1631538194482, "ltp": 1.18, "tv": 26212.4, "trd": NaN, "batb": NaN, "batl": [[0, 1.13, 255.49]]}, {"timestamp": 1631538200387, "ltp": 1.18, "tv": 26212.4, "trd": NaN, "batb": [[0, 1.06, 109.32], [1, 1.05, 255.49], [2, 1.04, 1005.48]], "batl": NaN}, {"timestamp": 1631538206597, "ltp": 1.13, "tv": 26252.92, "trd": [[1.13, 2931.15]], "batb": NaN, "batl": [[0, 1.13, 214.98]]}, {"timestamp": 1631538217724, "ltp": 1.13, "tv": 26252.92, "trd": NaN, "batb": [[2, 1.04, 255.49]], "batl": NaN}, {"timestamp": 1631538222739, "ltp": 1.13, "tv": 26252.92, "trd": NaN, "batb": [[0, 1.12, 249.99], [1, 1.06, 109.32], [2, 1.05, 255.49]], "batl": NaN}, {"timestamp": 1631538224143, "ltp": 1.13, "tv": 26252.92, "trd": NaN, "batb": [[0, 1.15, 72.88], [1, 1.12, 249.99], [2, 1.06, 109.32]], "batl": NaN}, {"timestamp": 1631538225132, "ltp": 1.13, "tv": 26252.92, "trd": NaN, "batb": [[0, 1.18, 74.33], [1, 1.15, 109.32], [2, 1.12, 249.99]], "batl": NaN}, {"timestamp": 1631538227570, "ltp": 1.13, "tv": 26252.92, "trd": NaN, "batb": [[0, 1.2, 73.09]], "batl": [[0, 1.3, 255.49]]}, {"timestamp": 1631538230556, "ltp": 1.13, "tv": 26252.92, "trd": NaN, "batb": [[1, 1.15, 364.81], [2, 1.14, 255.49]], "batl": NaN}, {"timestamp": 1631538231966, "ltp": 1.13, "tv": 26252.92, "trd": NaN, "batb": [[2, 1.14, 328.37]], "batl": NaN}, {"timestamp": 1631538237345, "ltp": 1.13, "tv": 26252.92, "trd": NaN, "batb": [[2, 1.14, 72.88]], "batl": NaN}, {"timestamp": 1631538247298, "ltp": 1.13, "tv": 26252.92, "trd": NaN, "batb": [[1, 1.15, 255.49], [2, 1.12, 249.99]], "batl": NaN}, {"timestamp": 1631538249678, "ltp": 1.13, "tv": 26252.92, "trd": NaN, "batb": [[2, 1.05, 255.49]], "batl": NaN}, {"timestamp": 1631538254790, "ltp": 1.13, "tv": 26252.92, "trd": NaN, "batb": [[1, 1.18, 166.66], [2, 1.15, 255.49]], "batl": NaN}, {"timestamp": 1631538255672, "ltp": 1.13, "tv": 26252.92, "trd": NaN, "batb": [[0, 1.23, 71.31], [1, 1.2, 73.09], [2, 1.18, 166.66]], "batl": NaN}, {"timestamp": 1631538257295, "ltp": 1.13, "tv": 26252.92, "trd": NaN, "batb": NaN, "batl": [[0, 1.35, 255.49]]}, {"timestamp": 1631538266692, "ltp": 1.13, "tv": 26252.92, "trd": NaN, "batb": [[2, 1.15, 255.49]], "batl": NaN}, {"timestamp": 1631538267683, "ltp": 1.13, "tv": 26252.92, "trd": NaN, "batb": [[0, 1.01, 7], [1, 1.2, 0], [2, 1.15, 0]], "batl": NaN}, {"timestamp": 1631538274294, "ltp": 1.13, "tv": 26252.92, "trd": NaN, "batb": NaN, "batl": [[0, 1.11, 255.49]]}, {"timestamp": 1631538275597, "ltp": 1.13, "tv": 26252.92, "trd": NaN, "batb": NaN, "batl": [[0, 1.1, 255.49], [1, 1.11, 255.49]]}, {"timestamp": 1631538276480, "ltp": 1.13, "tv": 26252.92, "trd": NaN, "batb": [[0, 1.03, 200], [1, 1.01, 7]], "batl": NaN}, {"timestamp": 1631538277626, "ltp": 1.13, "tv": 26252.92, "trd": NaN, "batb": [[0, 1.03, 455.49]], "batl": [[1, 1.11, 0]]}, {"timestamp": 1631538283122, "ltp": 1.13, "tv": 26252.92, "trd": NaN, "batb": [[0, 1.03, 655.49]], "batl": NaN}, {"timestamp": 1631538295619, "ltp": 1.13, "tv": 26252.92, "trd": NaN, "batb": [[0, 1.03, 255.49]], "batl": NaN}, {"timestamp": 1631538309396, "ltp": 1.13, "tv": 26252.92, "trd": NaN, "batb": [[0, 1.05, 599.99], [1, 1.03, 255.49], [2, 1.01, 7]], "batl": NaN}, {"timestamp": 1631538309982, "ltp": 1.13, "tv": 26252.92, "trd": NaN, "batb": [[0, 1.1, 79.73], [1, 1.05, 599.99], [2, 1.03, 255.49]], "batl": NaN}, {"timestamp": 1631538311079, "ltp": 1.13, "tv": 26252.92, "trd": NaN, "batb": [[0, 1.05, 599.99], [1, 1.03, 255.49], [2, 1.01, 7]], "batl": NaN}, {"timestamp": 1631538312160, "ltp": 1.16, "tv": 26318.43, "trd": [[1.16, 65.52]], "batb": [[0, 1.16, 10.09], [1, 1.05, 599.99], [2, 1.03, 255.49]], "batl": NaN}, {"timestamp": 1631538317250, "ltp": 1.16, "tv": 26318.43, "trd": NaN, "batb": [[2, 1.01, 7]], "batl": NaN}, {"timestamp": 1631538317865, "ltp": 1.16, "tv": 26318.43, "trd": NaN, "batb": [[1, 1.1, 200], [2, 1.05, 599.99]], "batl": NaN}, {"timestamp": 1631538318969, "ltp": 1.16, "tv": 26318.43, "trd": NaN, "batb": [[0, 1.1, 200], [1, 1.05, 599.99], [2, 1.01, 7]], "batl": NaN}, {"timestamp": 1631538328283, "ltp": 1.16, "tv": 26318.43, "trd": NaN, "batb": [[1, 1.01, 7], [2, 1.01, 0]], "batl": NaN}, {"timestamp": 1631538329968, "ltp": 1.16, "tv": 26318.43, "trd": NaN, "batb": [[0, 1.01, 7], [1, 1.01, 0]], "batl": NaN}, {"timestamp": 1631538333065, "ltp": 1.16, "tv": 26318.43, "trd": NaN, "batb": [[0, 1.18, 166.66], [1, 1.01, 7]], "batl": NaN}, {"timestamp": 1631538339496, "ltp": 1.16, "tv": 26318.43, "trd": NaN, "batb": [[0, 1.2, 200], [1, 1.18, 166.66], [2, 1.01, 7]], "batl": NaN}, {"timestamp": 1631538344306, "ltp": 1.16, "tv": 26318.43, "trd": NaN, "batb": [[0, 1.18, 166.66], [1, 1.01, 7], [2, 1.01, 0]], "batl": NaN}, {"timestamp": 1631538353254, "ltp": 1.16, "tv": 26318.43, "trd": NaN, "batb": [[0, 1.2, 100], [1, 1.18, 166.66], [2, 1.01, 7]], "batl": NaN}, {"timestamp": 1631538366602, "ltp": 1.16, "tv": 26318.43, "trd": NaN, "batb": [[0, 1.18, 166.66], [1, 1.01, 7], [2, 1.01, 0]], "batl": NaN}, {"timestamp": 1631538382146, "ltp": 1.16, "tv": 26318.43, "trd": NaN, "batb": [[0, 1.3, 3], [1, 1.18, 166.66], [2, 1.01, 7]], "batl": NaN}, {"timestamp": 1631538386399, "ltp": 1.16, "tv": 26318.43, "trd": NaN, "batb": [[1, 1.01, 7], [2, 1.01, 0]], "batl": NaN}, {"timestamp": 1631538393313, "ltp": 1.16, "tv": 26318.43, "trd": NaN, "batb": [[0, 1.01, 7], [1, 1.01, 0]], "batl": NaN}, {"timestamp": 1631538399746, "ltp": 1.01, "tv": 26361.74, "trd": [[1.01, 14], [1.09, 29.31]], "batb": NaN, "batl": [[0, 1.01, 815.34]]}, {"timestamp": 1631538404773, "ltp": 1.01, "tv": 26361.74, "trd": NaN, "batb": NaN, "batl": [[1, 1.17, 3]]}]}]}