{"info": {"id": "1.187594319", "eventId": "30897887", "eventName": "Match Odds", "marketType": "MATCH_ODDS", "openDate": 1631536261246, "name": "W Falkowska v A Barnett", "numberOfActiveRunner": 2, "countryCode": "", "sport": "TENNIS", "venue": "", "volume": {"total": 1349.7, "preMatch": 7.19, "inPlay": 1342.51}, "winner": {"id": 13310360, "name": "W Falkowska", "status": "WINNER", "position": 1}, "delay": 5}, "runners": [{"id": 13310360, "name": "W Falkowska", "status": "WINNER", "position": 1, "inPlayOdds": 1.08, "inPlayTime": 1631536261246, "avgPrematch": 1.1, "closedOdds": 1.36, "maxPrematch": 1.17, "minPrematch": 1.08, "maxInPlay": 1.36, "minInPlay": 1.01, "inPlayIndex": 5, "lengthOdds": 382, "lengthOddsPrematch": 5, "lengthOddsInPlay": 377, "tradedVolume": 1275.41, "preMatchVolume": 0.1, "inPlayVolume": 1275.31}, {"id": 9628382, "name": "A Barnett", "status": "LOSER", "position": 2, "inPlayOdds": 12.0, "inPlayTime": 1631537870400, "avgPrematch": 0, "closedOdds": 3.75, "maxPrematch": -100, "minPrematch": 1001, "maxInPlay": 16.0, "minInPlay": 3.75, "inPlayIndex": 0, "lengthOdds": 224, "lengthOddsPrematch": 0, "lengthOddsInPlay": 224, "tradedVolume": 74.29, "preMatchVolume": 7.09, "inPlayVolume": 67.2}], "marketUpdates": [{"timestamp": 1631518387208000000, "openDate": "2021-09-13T10:30:00.000Z", "status": "OPEN", "betDelay": 0, "inPlay": false, "complete": true}, {"timestamp": 1631522764139000000, "openDate": "2021-09-13T12:30:00.000Z", "status": "OPEN", "betDelay": 0, "inPlay": false, "complete": true}, {"timestamp": 1631526089042000000, "openDate": "2021-09-13T12:40:00.000Z", "status": "OPEN", "betDelay": 0, "inPlay": false, "complete": true}, {"timestamp": 1631529806864000000, "openDate": "2021-09-13T12:30:00.000Z", "status": "OPEN", "betDelay": 0, "inPlay": false, "complete": true}, {"timestamp": 1631531511221000000, "openDate": "2021-09-13T12:40:00.000Z", "status": "OPEN", "betDelay": 0, "inPlay": false, "complete": true}, {"timestamp": 1631534548664000000, "openDate": "2021-09-13T12:30:00.000Z", "status": "OPEN", "betDelay": 0, "inPlay": false, "complete": true}, {"timestamp": 1631536261246000000, "openDate": "2021-09-13T12:30:00.000Z", "status": "OPEN", "betDelay": 5, "inPlay": true, "complete": true}, {"timestamp": 1631536816550000000, "openDate": "2021-09-13T12:40:12.000Z", "status": "OPEN", "betDelay": 5, "inPlay": true, "complete": true}, {"timestamp": 1631550163024000000, "openDate": "2021-09-13T12:40:12.000Z", "status": "SUSPENDED", "betDelay": 5, "inPlay": true, "complete": true}, {"timestamp": 1631550198227000000, "openDate": "2021-09-13T12:40:12.000Z", "status": "CLOSED", "betDelay": 5, "inPlay": true, "complete": true}], "odds": [{"runnerId": 13310360, "odds": [{"timestamp": 1631534677521, "ltp": 1.17, "tv": 0.01, "trd": [[1.17, 0.02]], "batb": NaN, "batl": NaN}, {"timestamp": 1631534722824, "ltp": 1.08, "tv": 0.1, "trd": [[1.08, 0.08]], "batb": [[0, 1.08, 85.14]], "batl": NaN}, {"timestamp": 1631535037372, "ltp": 1.08, "tv": 0.1, "trd": NaN, "batb": [[2, 1.06, 2.66]], "batl": NaN}, {"timestamp": 1631535265982, "ltp": 1.08, "tv": 0.1, "trd": NaN, "batb": [[1, 1.06, 502.66], [2, 1.02, 2198.78]], "batl": NaN}, {"timestamp": 1631535267295, "ltp": 1.08, "tv": 0.1, "trd": NaN, "batb": [[0, 1.07, 85.18]], "batl": NaN}, {"timestamp": 1631536261246, "ltp": 1.08, "tv": 0.1, "trd": NaN, "batb": [[0, 1.01, 7], [1, 1.06, 0], [2, 1.02, 0]], "batl": [[1, 1.66, 0], [2, 1.68, 0]]}, {"timestamp": 1631536266420, "ltp": 1.08, "tv": 0.1, "trd": NaN, "batb": [[0, 1.04, 749.99], [1, 1.01, 7]], "batl": NaN}, {"timestamp": 1631536813534, "ltp": 1.08, "tv": 0.1, "trd": NaN, "batb": [[0, 1.01, 7], [1, 1.01, 0]], "batl": NaN}, {"timestamp": 1631536818235, "ltp": 1.08, "tv": 0.1, "trd": NaN, "batb": [[0, 1.05, 599.99], [1, 1.01, 7]], "batl": NaN}, {"timestamp": 1631536837945, "ltp": 1.08, "tv": 0.1, "trd": NaN, "batb": [[0, 1.01, 7], [1, 1.01, 0]], "batl": NaN}, {"timestamp": 1631536842960, "ltp": 1.08, "tv": 0.1, "trd": NaN, "batb": [[0, 1.04, 749.99], [1, 1.01, 7]], "batl": NaN}, {"timestamp": 1631536870192, "ltp": 1.08, "tv": 0.1, "trd": NaN, "batb": [[0, 1.01, 7], [1, 1.01, 0]], "batl": NaN}, {"timestamp": 1631536875104, "ltp": 1.08, "tv": 0.1, "trd": NaN, "batb": [[0, 1.05, 599.99], [1, 1.01, 7]], "batl": NaN}, {"timestamp": 1631536916589, "ltp": 1.08, "tv": 0.1, "trd": NaN, "batb": [[0, 1.01, 7], [1, 1.01, 0]], "batl": NaN}, {"timestamp": 1631536921502, "ltp": 1.08, "tv": 0.1, "trd": NaN, "batb": [[0, 1.04, 749.99], [1, 1.01, 7]], "batl": NaN}, {"timestamp": 1631536954769, "ltp": 1.08, "tv": 0.1, "trd": NaN, "batb": [[0, 1.01, 7], [1, 1.01, 0]], "batl": NaN}, {"timestamp": 1631536959681, "ltp": 1.08, "tv": 0.1, "trd": NaN, "batb": [[0, 1.05, 599.99], [1, 1.01, 7]], "batl": NaN}, {"timestamp": 1631536983102, "ltp": 1.08, "tv": 0.1, "trd": NaN, "batb": [[0, 1.01, 7], [1, 1.01, 0]], "batl": NaN}, {"timestamp": 1631536988012, "ltp": 1.08, "tv": 0.1, "trd": NaN, "batb": [[0, 1.08, 374.99], [1, 1.01, 7]], "batl": NaN}, {"timestamp": 1631536989545, "ltp": 1.08, "tv": 0.1, "trd": NaN, "batb": [[0, 1.09, 763.45], [1, 1.08, 374.99], [2, 1.01, 7]], "batl": [[1, 1.46, 834.89]]}, {"timestamp": 1631537014382, "ltp": 1.08, "tv": 0.1, "trd": NaN, "batb": [[0, 1.08, 374.99], [1, 1.01, 7], [2, 1.01, 0]], "batl": [[1, 1.46, 0]]}, {"timestamp": 1631537023074, "ltp": 1.08, "tv": 0.1, "trd": NaN, "batb": [[0, 1.01, 7], [1, 1.01, 0]], "batl": NaN}, {"timestamp": 1631537028009, "ltp": 1.08, "tv": 0.1, "trd": NaN, "batb": [[0, 1.05, 599.99], [1, 1.01, 7]], "batl": NaN}, {"timestamp": 1631537055356, "ltp": 1.08, "tv": 0.1, "trd": NaN, "batb": [[0, 1.01, 7], [1, 1.01, 0]], "batl": NaN}, {"timestamp": 1631537060386, "ltp": 1.08, "tv": 0.1, "trd": NaN, "batb": [[0, 1.04, 749.99], [1, 1.01, 7]], "batl": NaN}, {"timestamp": 1631537099414, "ltp": 1.08, "tv": 0.1, "trd": NaN, "batb": [[0, 1.01, 7], [1, 1.01, 0]], "batl": NaN}, {"timestamp": 1631537104445, "ltp": 1.08, "tv": 0.1, "trd": NaN, "batb": [[0, 1.05, 599.99], [1, 1.01, 7]], "batl": NaN}, {"timestamp": 1631537162915, "ltp": 1.08, "tv": 0.1, "trd": NaN, "batb": [[0, 1.01, 7], [1, 1.01, 0]], "batl": NaN}, {"timestamp": 1631537168632, "ltp": 1.08, "tv": 0.1, "trd": NaN, "batb": [[0, 1.09, 763.45], [1, 1.08, 374.99], [2, 1.01, 7]], "batl": [[1, 1.46, 834.89]]}, {"timestamp": 1631537194866, "ltp": 1.08, "tv": 0.1, "trd": NaN, "batb": [[0, 1.01, 7], [1, 1.08, 0], [2, 1.01, 0]], "batl": NaN}, {"timestamp": 1631537200203, "ltp": 1.08, "tv": 0.1, "trd": NaN, "batb": [[0, 1.11, 272.72], [1, 1.1, 733.19], [2, 1.01, 7]], "batl": NaN}, {"timestamp": 1631537218603, "ltp": 1.11, "tv": 5.2, "trd": [[1.11, 5.11]], "batb": [[0, 1.1, 733.19], [1, 1.01, 7], [2, 1.01, 0]], "batl": NaN}, {"timestamp": 1631537223512, "ltp": 1.11, "tv": 5.2, "trd": NaN, "batb": [[0, 1.11, 272.72], [1, 1.1, 733.19], [2, 1.01, 7]], "batl": NaN}, {"timestamp": 1631537281550, "ltp": 1.11, "tv": 5.2, "trd": NaN, "batb": [[0, 1.1, 733.19], [1, 1.01, 7], [2, 1.01, 0]], "batl": NaN}, {"timestamp": 1631537282230, "ltp": 1.11, "tv": 5.2, "trd": NaN, "batb": [[0, 1.01, 7], [1, 1.01, 0]], "batl": NaN}, {"timestamp": 1631537286366, "ltp": 1.11, "tv": 5.2, "trd": NaN, "batb": [[0, 1.08, 374.99], [1, 1.01, 7]], "batl": NaN}, {"timestamp": 1631537287930, "ltp": 1.11, "tv": 5.2, "trd": NaN, "batb": [[0, 1.09, 763.45], [1, 1.08, 374.99], [2, 1.01, 7]], "batl": NaN}, {"timestamp": 1631537488588, "ltp": 1.11, "tv": 5.2, "trd": NaN, "batb": [[1, 1.01, 7], [2, 1.01, 0]], "batl": NaN}, {"timestamp": 1631537489996, "ltp": 1.11, "tv": 5.2, "trd": NaN, "batb": [[0, 1.01, 7], [1, 1.01, 0]], "batl": NaN}, {"timestamp": 1631537493753, "ltp": 1.11, "tv": 5.2, "trd": NaN, "batb": [[0, 1.06, 499.99], [1, 1.01, 7]], "batl": NaN}, {"timestamp": 1631537496315, "ltp": 1.11, "tv": 5.2, "trd": NaN, "batb": [[0, 1.06, 1507.6]], "batl": NaN}, {"timestamp": 1631537521254, "ltp": 1.11, "tv": 5.2, "trd": NaN, "batb": [[0, 1.06, 1007.61]], "batl": NaN}, {"timestamp": 1631537522451, "ltp": 1.11, "tv": 5.2, "trd": NaN, "batb": [[0, 1.01, 7], [1, 1.01, 0]], "batl": [[1, 1.46, 0]]}, {"timestamp": 1631537526157, "ltp": 1.11, "tv": 5.2, "trd": NaN, "batb": [[0, 1.05, 599.99], [1, 1.01, 7]], "batl": NaN}, {"timestamp": 1631537528652, "ltp": 1.11, "tv": 5.2, "trd": NaN, "batb": [[0, 1.05, 1684.33]], "batl": [[1, 1.38, 986.38]]}, {"timestamp": 1631537572830, "ltp": 1.11, "tv": 5.2, "trd": NaN, "batb": [[0, 1.05, 1084.34]], "batl": NaN}, {"timestamp": 1631537574177, "ltp": 1.11, "tv": 5.2, "trd": NaN, "batb": [[0, 1.01, 7], [1, 1.01, 0]], "batl": NaN}, {"timestamp": 1631537577858, "ltp": 1.11, "tv": 5.2, "trd": NaN, "batb": [[0, 1.06, 499.99], [1, 1.01, 7]], "batl": NaN}, {"timestamp": 1631537579774, "ltp": 1.11, "tv": 5.2, "trd": NaN, "batb": [[0, 1.06, 1449.72]], "batl": NaN}, {"timestamp": 1631537588407, "ltp": 1.11, "tv": 5.2, "trd": NaN, "batb": NaN, "batl": [[0, 1.09, 200], [1, 1.21, 100], [2, 1.38, 986.38]]}, {"timestamp": 1631537607639, "ltp": 1.11, "tv": 5.2, "trd": NaN, "batb": [[0, 1.06, 499.99]], "batl": NaN}, {"timestamp": 1631537607947, "ltp": 1.11, "tv": 5.2, "trd": NaN, "batb": [[0, 1.01, 7], [1, 1.01, 0]], "batl": NaN}, {"timestamp": 1631537613353, "ltp": 1.11, "tv": 5.2, "trd": NaN, "batb": [[0, 1.05, 1684.33], [1, 1.01, 7]], "batl": NaN}, {"timestamp": 1631537631391, "ltp": 1.11, "tv": 5.2, "trd": NaN, "batb": [[0, 1.01, 7], [1, 1.01, 0]], "batl": NaN}, {"timestamp": 1631537636588, "ltp": 1.11, "tv": 5.2, "trd": NaN, "batb": [[0, 1.04, 2001.57], [1, 1.01, 7]], "batl": NaN}, {"timestamp": 1631537747405, "ltp": 1.11, "tv": 5.2, "trd": NaN, "batb": [[0, 1.04, 1251.58]], "batl": NaN}, {"timestamp": 1631537748510, "ltp": 1.11, "tv": 5.2, "trd": NaN, "batb": [[0, 1.01, 7], [1, 1.01, 0]], "batl": NaN}, {"timestamp": 1631537752326, "ltp": 1.11, "tv": 5.2, "trd": NaN, "batb": [[0, 1.05, 599.99], [1, 1.01, 7]], "batl": NaN}, {"timestamp": 1631537754614, "ltp": 1.11, "tv": 5.2, "trd": NaN, "batb": [[0, 1.05, 1684.33]], "batl": NaN}, {"timestamp": 1631537779263, "ltp": 1.11, "tv": 5.2, "trd": NaN, "batb": [[0, 1.05, 1084.34]], "batl": NaN}, {"timestamp": 1631537780042, "ltp": 1.11, "tv": 5.2, "trd": NaN, "batb": [[0, 1.01, 7], [1, 1.01, 0]], "batl": NaN}, {"timestamp": 1631537784274, "ltp": 1.11, "tv": 5.2, "trd": NaN, "batb": [[0, 1.08, 374.99], [1, 1.01, 7]], "batl": NaN}, {"timestamp": 1631537786162, "ltp": 1.11, "tv": 5.2, "trd": NaN, "batb": [[1, 1.06, 949.73], [2, 1.01, 7]], "batl": NaN}, {"timestamp": 1631537790867, "ltp": 1.08, "tv": 9.2, "trd": [[1.08, 4.08]], "batb": [[0, 1.06, 949.73], [1, 1.01, 7], [2, 1.01, 0]], "batl": NaN}, {"timestamp": 1631537795806, "ltp": 1.08, "tv": 9.2, "trd": NaN, "batb": [[0, 1.08, 374.99], [1, 1.06, 949.73], [2, 1.01, 7]], "batl": NaN}, {"timestamp": 1631537808390, "ltp": 1.08, "tv": 9.2, "trd": NaN, "batb": [[1, 1.01, 7], [2, 1.01, 0]], "batl": NaN}, {"timestamp": 1631537814608, "ltp": 1.08, "tv": 9.2, "trd": NaN, "batb": [[1, 1.06, 1007.61], [2, 1.01, 7]], "batl": NaN}, {"timestamp": 1631537841458, "ltp": 1.08, "tv": 9.2, "trd": NaN, "batb": [[0, 1.01, 7], [1, 1.06, 0], [2, 1.01, 0]], "batl": NaN}, {"timestamp": 1631537846955, "ltp": 1.08, "tv": 9.2, "trd": NaN, "batb": [[0, 1.08, 812.01], [1, 1.01, 7]], "batl": NaN}, {"timestamp": 1631537870400, "ltp": 1.09, "tv": 87.3, "trd": [[1.09, 78.1]], "batb": NaN, "batl": [[0, 1.09, 121.9]]}, {"timestamp": 1631537874430, "ltp": 1.09, "tv": 87.3, "trd": NaN, "batb": [[0, 1.01, 7], [1, 1.01, 0]], "batl": NaN}, {"timestamp": 1631537880516, "ltp": 1.09, "tv": 331.12, "trd": [[1.09, 321.92]], "batb": [[0, 1.09, 26.5], [1, 1.01, 7]], "batl": [[0, 1.21, 100], [1, 1.38, 986.38], [2, 1.38, 0]]}, {"timestamp": 1631537881618, "ltp": 1.09, "tv": 331.12, "trd": NaN, "batb": [[0, 1.09, 267.83]], "batl": NaN}, {"timestamp": 1631537882618, "ltp": 1.09, "tv": 331.12, "trd": NaN, "batb": [[0, 1.09, 274.46]], "batl": NaN}, {"timestamp": 1631537883621, "ltp": 1.09, "tv": 331.12, "trd": NaN, "batb": [[0, 1.09, 147.65]], "batl": NaN}, {"timestamp": 1631537884630, "ltp": 1.09, "tv": 331.12, "trd": NaN, "batb": [[0, 1.09, 186.66]], "batl": NaN}, {"timestamp": 1631537885633, "ltp": 1.09, "tv": 331.12, "trd": NaN, "batb": [[0, 1.15, 200], [1, 1.09, 404.43], [2, 1.01, 7]], "batl": NaN}, {"timestamp": 1631537886530, "ltp": 1.09, "tv": 331.12, "trd": NaN, "batb": [[1, 1.09, 93.33]], "batl": NaN}, {"timestamp": 1631537886849, "ltp": 1.09, "tv": 331.12, "trd": NaN, "batb": [[1, 1.01, 7], [2, 1.01, 0]], "batl": NaN}, {"timestamp": 1631537901554, "ltp": 1.09, "tv": 331.12, "trd": NaN, "batb": [[1, 1.12, 539.63], [2, 1.01, 7]], "batl": NaN}, {"timestamp": 1631537911631, "ltp": 1.09, "tv": 331.12, "trd": NaN, "batb": [[0, 1.12, 539.63], [1, 1.01, 7], [2, 1.01, 0]], "batl": NaN}, {"timestamp": 1631537911896, "ltp": 1.09, "tv": 331.12, "trd": NaN, "batb": [[0, 1.01, 7], [1, 1.01, 0]], "batl": [[1, 1.38, 0]]}, {"timestamp": 1631537916584, "ltp": 1.09, "tv": 331.12, "trd": NaN, "batb": [[0, 1.18, 166.66], [1, 1.01, 7]], "batl": NaN}, {"timestamp": 1631537917750, "ltp": 1.09, "tv": 331.12, "trd": NaN, "batb": [[1, 1.14, 501.06], [2, 1.01, 7]], "batl": [[1, 1.55, 785.49]]}, {"timestamp": 1631537947450, "ltp": 1.09, "tv": 331.12, "trd": NaN, "batb": [[0, 1.01, 7], [1, 1.14, 0], [2, 1.01, 0]], "batl": NaN}, {"timestamp": 1631537949386, "ltp": 1.21, "tv": 337.59, "trd": [[1.21, 6.47]], "batb": NaN, "batl": [[0, 1.21, 93.53]]}, {"timestamp": 1631537952079, "ltp": 1.21, "tv": 337.59, "trd": NaN, "batb": [[0, 1.15, 200], [1, 1.01, 7]], "batl": NaN}, {"timestamp": 1631537952964, "ltp": 1.21, "tv": 337.59, "trd": NaN, "batb": [[1, 1.12, 539.63], [2, 1.01, 7]], "batl": NaN}, {"timestamp": 1631538000250, "ltp": 1.21, "tv": 337.59, "trd": NaN, "batb": [[0, 1.01, 7], [1, 1.12, 0], [2, 1.01, 0]], "batl": [[1, 1.55, 0]]}, {"timestamp": 1631538004744, "ltp": 1.21, "tv": 337.57, "trd": [[1.09, 321.9]], "batb": [[0, 1.12, 249.99], [1, 1.01, 7]], "batl": NaN}, {"timestamp": 1631538006281, "ltp": 1.21, "tv": 337.57, "trd": NaN, "batb": [[1, 1.1, 606.51], [2, 1.01, 7]], "batl": [[1, 1.48, 884.7]]}, {"timestamp": 1631538041409, "ltp": 1.21, "tv": 337.57, "trd": NaN, "batb": [[0, 1.1, 606.51], [1, 1.01, 7], [2, 1.01, 0]], "batl": NaN}, {"timestamp": 1631538042824, "ltp": 1.21, "tv": 337.57, "trd": NaN, "batb": [[0, 1.01, 7], [1, 1.01, 0]], "batl": NaN}, {"timestamp": 1631538046307, "ltp": 1.21, "tv": 337.57, "trd": NaN, "batb": [[0, 1.11, 272.72], [1, 1.01, 7]], "batl": NaN}, {"timestamp": 1631538049021, "ltp": 1.21, "tv": 337.57, "trd": NaN, "batb": [[1, 1.08, 685.55], [2, 1.01, 7]], "batl": NaN}, {"timestamp": 1631538072005, "ltp": 1.21, "tv": 337.57, "trd": NaN, "batb": [[0, 1.08, 685.55], [1, 1.01, 7], [2, 1.01, 0]], "batl": NaN}, {"timestamp": 1631538073262, "ltp": 1.21, "tv": 337.57, "trd": NaN, "batb": [[0, 1.01, 7], [1, 1.01, 0]], "batl": NaN}, {"timestamp": 1631538077009, "ltp": 1.21, "tv": 337.57, "trd": NaN, "batb": [[0, 1.12, 249.99], [1, 1.01, 7]], "batl": NaN}, {"timestamp": 1631538079197, "ltp": 1.21, "tv": 337.57, "trd": NaN, "batb": [[1, 1.1, 606.51], [2, 1.01, 7]], "batl": NaN}, {"timestamp": 1631538098943, "ltp": 1.21, "tv": 337.57, "trd": NaN, "batb": [[0, 1.1, 606.51], [1, 1.01, 7], [2, 1.01, 0]], "batl": NaN}, {"timestamp": 1631538099737, "ltp": 1.21, "tv": 337.57, "trd": NaN, "batb": [[0, 1.01, 7], [1, 1.01, 0]], "batl": NaN}, {"timestamp": 1631538103832, "ltp": 1.21, "tv": 337.57, "trd": NaN, "batb": [[0, 1.18, 166.66], [1, 1.01, 7]], "batl": NaN}, {"timestamp": 1631538105542, "ltp": 1.21, "tv": 337.57, "trd": NaN, "batb": [[1, 1.14, 500.97], [2, 1.01, 7]], "batl": NaN}, {"timestamp": 1631538123262, "ltp": 1.21, "tv": 337.57, "trd": NaN, "batb": [[0, 1.14, 500.97], [1, 1.01, 7], [2, 1.01, 0]], "batl": NaN}, {"timestamp": 1631538128297, "ltp": 1.21, "tv": 337.57, "trd": NaN, "batb": [[0, 1.15, 200], [1, 1.14, 500.97], [2, 1.01, 7]], "batl": NaN}, {"timestamp": 1631538206435, "ltp": 1.21, "tv": 337.57, "trd": NaN, "batb": [[0, 1.14, 500.97], [1, 1.01, 7], [2, 1.01, 0]], "batl": NaN}, {"timestamp": 1631538207114, "ltp": 1.21, "tv": 337.57, "trd": NaN, "batb": [[0, 1.01, 7], [1, 1.01, 0]], "batl": NaN}, {"timestamp": 1631538211342, "ltp": 1.21, "tv": 337.57, "trd": NaN, "batb": [[0, 1.12, 249.99], [1, 1.01, 7]], "batl": NaN}, {"timestamp": 1631538212649, "ltp": 1.21, "tv": 337.57, "trd": NaN, "batb": [[0, 1.12, 789.53]], "batl": NaN}, {"timestamp": 1631538228943, "ltp": 1.21, "tv": 337.57, "trd": NaN, "batb": [[0, 1.12, 539.54]], "batl": NaN}, {"timestamp": 1631538230553, "ltp": 1.21, "tv": 337.57, "trd": NaN, "batb": [[0, 1.01, 7], [1, 1.01, 0]], "batl": NaN}, {"timestamp": 1631538233852, "ltp": 1.21, "tv": 337.57, "trd": NaN, "batb": [[0, 1.08, 374.99], [1, 1.01, 7]], "batl": NaN}, {"timestamp": 1631538236769, "ltp": 1.21, "tv": 337.57, "trd": NaN, "batb": [[0, 1.09, 638.16], [1, 1.08, 374.99], [2, 1.01, 7]], "batl": NaN}, {"timestamp": 1631538413788, "ltp": 1.21, "tv": 337.57, "trd": NaN, "batb": [[1, 1.01, 7], [2, 1.01, 0]], "batl": NaN}, {"timestamp": 1631538415410, "ltp": 1.21, "tv": 337.57, "trd": NaN, "batb": [[0, 1.01, 7], [1, 1.01, 0]], "batl": NaN}, {"timestamp": 1631538418825, "ltp": 1.21, "tv": 337.57, "trd": NaN, "batb": [[0, 1.11, 272.72], [1, 1.01, 7]], "batl": NaN}, {"timestamp": 1631538421003, "ltp": 1.21, "tv": 337.57, "trd": NaN, "batb": [[1, 1.1, 606.51], [2, 1.01, 7]], "batl": NaN}, {"timestamp": 1631538432919, "ltp": 1.21, "tv": 337.57, "trd": NaN, "batb": [[0, 1.1, 606.51], [1, 1.01, 7], [2, 1.01, 0]], "batl": NaN}, {"timestamp": 1631538433654, "ltp": 1.21, "tv": 337.57, "trd": NaN, "batb": [[0, 1.01, 7], [1, 1.01, 0]], "batl": NaN}, {"timestamp": 1631538437850, "ltp": 1.21, "tv": 337.57, "trd": NaN, "batb": [[0, 1.12, 249.99], [1, 1.01, 7]], "batl": NaN}, {"timestamp": 1631538439329, "ltp": 1.21, "tv": 337.57, "trd": NaN, "batb": [[0, 1.12, 789.53]], "batl": NaN}, {"timestamp": 1631538463203, "ltp": 1.21, "tv": 337.57, "trd": NaN, "batb": [[0, 1.12, 539.54]], "batl": NaN}, {"timestamp": 1631538464090, "ltp": 1.21, "tv": 337.57, "trd": NaN, "batb": [[0, 1.01, 7], [1, 1.01, 0]], "batl": NaN}, {"timestamp": 1631538468259, "ltp": 1.21, "tv": 337.57, "trd": NaN, "batb": [[0, 1.11, 272.72], [1, 1.01, 7]], "batl": NaN}, {"timestamp": 1631538469615, "ltp": 1.21, "tv": 337.57, "trd": NaN, "batb": [[1, 1.1, 606.51], [2, 1.01, 7]], "batl": NaN}, {"timestamp": 1631538483640, "ltp": 1.21, "tv": 337.57, "trd": NaN, "batb": [[0, 1.1, 606.51], [1, 1.01, 7], [2, 1.01, 0]], "batl": NaN}, {"timestamp": 1631538484437, "ltp": 1.21, "tv": 337.57, "trd": NaN, "batb": [[0, 1.01, 7], [1, 1.01, 0]], "batl": NaN}, {"timestamp": 1631538488555, "ltp": 1.21, "tv": 337.57, "trd": NaN, "batb": [[0, 1.15, 200], [1, 1.01, 7]], "batl": NaN}, {"timestamp": 1631538489654, "ltp": 1.21, "tv": 337.57, "trd": NaN, "batb": [[1, 1.14, 500.97], [2, 1.01, 7]], "batl": NaN}, {"timestamp": 1631538499637, "ltp": 1.21, "tv": 337.57, "trd": NaN, "batb": [[1, 1.01, 7], [2, 1.01, 0]], "batl": NaN}, {"timestamp": 1631538505762, "ltp": 1.21, "tv": 337.57, "trd": NaN, "batb": [[1, 1.12, 539.54], [2, 1.01, 7]], "batl": NaN}, {"timestamp": 1631538515374, "ltp": 1.21, "tv": 337.57, "trd": NaN, "batb": [[0, 1.12, 539.54], [1, 1.01, 7], [2, 1.01, 0]], "batl": NaN}, {"timestamp": 1631538516003, "ltp": 1.21, "tv": 337.57, "trd": NaN, "batb": [[0, 1.01, 7], [1, 1.01, 0]], "batl": NaN}, {"timestamp": 1631538520287, "ltp": 1.21, "tv": 337.57, "trd": NaN, "batb": [[0, 1.18, 166.66], [1, 1.01, 7]], "batl": NaN}, {"timestamp": 1631538522005, "ltp": 1.21, "tv": 337.57, "trd": NaN, "batb": [[1, 1.14, 500.97], [2, 1.01, 7]], "batl": NaN}, {"timestamp": 1631538625700, "ltp": 1.21, "tv": 337.57, "trd": NaN, "batb": [[1, 1.01, 7], [2, 1.01, 0]], "batl": NaN}, {"timestamp": 1631538631646, "ltp": 1.21, "tv": 337.57, "trd": NaN, "batb": [[1, 1.16, 469.27], [2, 1.01, 7]], "batl": NaN}, {"timestamp": 1631538639207, "ltp": 1.21, "tv": 337.57, "trd": NaN, "batb": [[0, 1.16, 469.27], [1, 1.01, 7], [2, 1.01, 0]], "batl": NaN}, {"timestamp": 1631538640075, "ltp": 1.21, "tv": 337.57, "trd": NaN, "batb": [[0, 1.01, 7], [1, 1.01, 0]], "batl": NaN}, {"timestamp": 1631538644260, "ltp": 1.21, "tv": 337.57, "trd": NaN, "batb": [[0, 1.15, 200], [1, 1.01, 7]], "batl": NaN}, {"timestamp": 1631538645831, "ltp": 1.21, "tv": 337.57, "trd": NaN, "batb": [[1, 1.12, 539.54], [2, 1.01, 7]], "batl": NaN}, {"timestamp": 1631538664162, "ltp": 1.21, "tv": 337.57, "trd": NaN, "batb": [[0, 1.12, 539.54], [1, 1.01, 7], [2, 1.01, 0]], "batl": NaN}, {"timestamp": 1631538665373, "ltp": 1.21, "tv": 337.57, "trd": NaN, "batb": [[0, 1.01, 7], [1, 1.01, 0]], "batl": NaN}, {"timestamp": 1631538669159, "ltp": 1.21, "tv": 337.57, "trd": NaN, "batb": [[0, 1.11, 272.72], [1, 1.01, 7]], "batl": NaN}, {"timestamp": 1631538671009, "ltp": 1.21, "tv": 337.57, "trd": NaN, "batb": [[1, 1.1, 606.51], [2, 1.01, 7]], "batl": NaN}, {"timestamp": 1631538703172, "ltp": 1.21, "tv": 337.57, "trd": NaN, "batb": [[1, 1.01, 7], [2, 1.01, 0]], "batl": NaN}, {"timestamp": 1631538709386, "ltp": 1.21, "tv": 337.57, "trd": NaN, "batb": [[1, 1.09, 638.16], [2, 1.01, 7]], "batl": NaN}, {"timestamp": 1631538749157, "ltp": 1.21, "tv": 337.57, "trd": NaN, "batb": [[0, 1.09, 638.16], [1, 1.01, 7], [2, 1.01, 0]], "batl": NaN}, {"timestamp": 1631538754126, "ltp": 1.21, "tv": 337.57, "trd": NaN, "batb": [[1, 1.08, 374.99], [2, 1.01, 7]], "batl": NaN}, {"timestamp": 1631538779605, "ltp": 1.21, "tv": 337.57, "trd": NaN, "batb": [[0, 1.08, 374.99], [1, 1.01, 7], [2, 1.01, 0]], "batl": [[1, 1.48, 0]]}, {"timestamp": 1631538796527, "ltp": 1.21, "tv": 337.57, "trd": NaN, "batb": [[0, 1.01, 7], [1, 1.01, 0]], "batl": NaN}, {"timestamp": 1631538801526, "ltp": 1.21, "tv": 337.57, "trd": NaN, "batb": [[0, 1.12, 249.99], [1, 1.01, 7]], "batl": NaN}, {"timestamp": 1631538815679, "ltp": 1.21, "tv": 337.57, "trd": NaN, "batb": [[0, 1.01, 7], [1, 1.01, 0]], "batl": NaN}, {"timestamp": 1631538820569, "ltp": 1.21, "tv": 337.57, "trd": NaN, "batb": [[0, 1.15, 200], [1, 1.01, 7]], "batl": NaN}, {"timestamp": 1631538834107, "ltp": 1.21, "tv": 337.57, "trd": NaN, "batb": [[0, 1.01, 7], [1, 1.01, 0]], "batl": NaN}, {"timestamp": 1631538838913, "ltp": 1.21, "tv": 337.57, "trd": NaN, "batb": [[0, 1.12, 249.99], [1, 1.01, 7]], "batl": NaN}, {"timestamp": 1631538856719, "ltp": 1.21, "tv": 337.57, "trd": NaN, "batb": [[0, 1.01, 7], [1, 1.01, 0]], "batl": NaN}, {"timestamp": 1631538861646, "ltp": 1.21, "tv": 337.57, "trd": NaN, "batb": [[0, 1.08, 374.99], [1, 1.01, 7]], "batl": NaN}, {"timestamp": 1631538899034, "ltp": 1.21, "tv": 337.57, "trd": NaN, "batb": [[0, 1.01, 7], [1, 1.01, 0]], "batl": NaN}, {"timestamp": 1631538903950, "ltp": 1.21, "tv": 337.57, "trd": NaN, "batb": [[0, 1.15, 200], [1, 1.01, 7]], "batl": NaN}, {"timestamp": 1631538924886, "ltp": 1.21, "tv": 337.57, "trd": NaN, "batb": [[0, 1.01, 7], [1, 1.01, 0]], "batl": NaN}, {"timestamp": 1631538931794, "ltp": 1.21, "tv": 337.57, "trd": NaN, "batb": [[0, 1.08, 685.55], [1, 1.01, 7]], "batl": [[1, 1.44, 961.06]]}, {"timestamp": 1631538932692, "ltp": 1.21, "tv": 337.57, "trd": NaN, "batb": [[0, 1.01, 7], [1, 1.01, 0]], "batl": NaN}, {"timestamp": 1631538934986, "ltp": 1.21, "tv": 337.57, "trd": NaN, "batb": [[0, 1.15, 200], [1, 1.01, 7]], "batl": NaN}, {"timestamp": 1631538938109, "ltp": 1.21, "tv": 337.57, "trd": NaN, "batb": [[0, 1.01, 7], [1, 1.01, 0]], "batl": NaN}, {"timestamp": 1631538943026, "ltp": 1.21, "tv": 337.57, "trd": NaN, "batb": [[0, 1.08, 374.99], [1, 1.01, 7]], "batl": NaN}, {"timestamp": 1631538943809, "ltp": 1.21, "tv": 337.57, "trd": NaN, "batb": [[0, 1.08, 1060.54]], "batl": NaN}, {"timestamp": 1631538978871, "ltp": 1.21, "tv": 337.57, "trd": NaN, "batb": [[0, 1.08, 685.55]], "batl": NaN}, {"timestamp": 1631538979657, "ltp": 1.21, "tv": 337.57, "trd": NaN, "batb": [[0, 1.01, 7], [1, 1.01, 0]], "batl": NaN}, {"timestamp": 1631538983773, "ltp": 1.21, "tv": 337.57, "trd": NaN, "batb": [[0, 1.05, 599.99], [1, 1.01, 7]], "batl": NaN}, {"timestamp": 1631538985888, "ltp": 1.21, "tv": 337.57, "trd": NaN, "batb": [[0, 1.05, 1551.1]], "batl": NaN}, {"timestamp": 1631539015462, "ltp": 1.21, "tv": 337.57, "trd": NaN, "batb": [[0, 1.05, 951.11]], "batl": NaN}, {"timestamp": 1631539020480, "ltp": 1.21, "tv": 337.57, "trd": NaN, "batb": [[1, 1.04, 749.99], [2, 1.01, 7]], "batl": NaN}, {"timestamp": 1631539024482, "ltp": 1.21, "tv": 337.57, "trd": NaN, "batb": [[0, 1.01, 7], [1, 1.04, 0], [2, 1.01, 0]], "batl": [[1, 1.44, 0]]}, {"timestamp": 1631539029202, "ltp": 1.21, "tv": 337.57, "trd": NaN, "batb": [[0, 1.02, 1499.99], [1, 1.01, 7]], "batl": NaN}, {"timestamp": 1631539030401, "ltp": 1.21, "tv": 337.57, "trd": NaN, "batb": [[0, 1.03, 1419.65], [1, 1.02, 1499.99], [2, 1.01, 7]], "batl": [[1, 1.35, 1185.3]]}, {"timestamp": 1631539150308, "ltp": 1.21, "tv": 337.57, "trd": NaN, "batb": [[1, 1.01, 7], [2, 1.01, 0]], "batl": NaN}, {"timestamp": 1631539151376, "ltp": 1.21, "tv": 337.57, "trd": NaN, "batb": [[0, 1.01, 7], [1, 1.01, 0]], "batl": NaN}, {"timestamp": 1631539155202, "ltp": 1.21, "tv": 337.57, "trd": NaN, "batb": [[0, 1.04, 749.99], [1, 1.01, 7]], "batl": NaN}, {"timestamp": 1631539177146, "ltp": 1.21, "tv": 337.57, "trd": NaN, "batb": [[0, 1.01, 7], [1, 1.01, 0]], "batl": NaN}, {"timestamp": 1631539182051, "ltp": 1.21, "tv": 337.57, "trd": NaN, "batb": [[0, 1.03, 999.99], [1, 1.01, 7]], "batl": NaN}, {"timestamp": 1631539183147, "ltp": 1.21, "tv": 337.57, "trd": NaN, "batb": [[0, 1.03, 2419.64]], "batl": NaN}, {"timestamp": 1631539215991, "ltp": 1.21, "tv": 337.57, "trd": NaN, "batb": [[0, 1.03, 1419.65]], "batl": NaN}, {"timestamp": 1631539217294, "ltp": 1.21, "tv": 337.57, "trd": NaN, "batb": [[0, 1.01, 7], [1, 1.01, 0]], "batl": NaN}, {"timestamp": 1631539223334, "ltp": 1.21, "tv": 337.57, "trd": NaN, "batb": [[0, 1.02, 2026.61], [1, 1.01, 7]], "batl": NaN}, {"timestamp": 1631539265065, "ltp": 1.21, "tv": 337.57, "trd": NaN, "batb": [[0, 1.01, 7], [1, 1.01, 0]], "batl": NaN}, {"timestamp": 1631539269404, "ltp": 1.21, "tv": 337.57, "trd": NaN, "batb": [[0, 1.03, 999.99], [1, 1.01, 7]], "batl": NaN}, {"timestamp": 1631539271072, "ltp": 1.21, "tv": 337.57, "trd": NaN, "batb": [[0, 1.03, 2419.64]], "batl": NaN}, {"timestamp": 1631539309477, "ltp": 1.21, "tv": 337.57, "trd": NaN, "batb": [[0, 1.03, 1419.65]], "batl": NaN}, {"timestamp": 1631539310468, "ltp": 1.21, "tv": 337.57, "trd": NaN, "batb": [[0, 1.01, 7], [1, 1.01, 0]], "batl": NaN}, {"timestamp": 1631539314405, "ltp": 1.21, "tv": 337.57, "trd": NaN, "batb": [[0, 1.05, 599.99], [1, 1.01, 7]], "batl": NaN}, {"timestamp": 1631539315601, "ltp": 1.21, "tv": 337.57, "trd": NaN, "batb": [[0, 1.06, 823.54], [1, 1.05, 599.99], [2, 1.01, 7]], "batl": NaN}, {"timestamp": 1631539333212, "ltp": 1.21, "tv": 337.57, "trd": NaN, "batb": [[0, 1.01, 7], [1, 1.05, 0], [2, 1.01, 0]], "batl": NaN}, {"timestamp": 1631539337640, "ltp": 1.21, "tv": 337.57, "trd": NaN, "batb": [[0, 1.12, 249.99], [1, 1.01, 7]], "batl": NaN}, {"timestamp": 1631539338947, "ltp": 1.21, "tv": 337.57, "trd": NaN, "batb": [[1, 1.09, 638.16], [2, 1.01, 7]], "batl": NaN}, {"timestamp": 1631539355335, "ltp": 1.21, "tv": 360.14, "trd": [[1.21, 29.04]], "batb": NaN, "batl": [[0, 1.21, 70.96]]}, {"timestamp": 1631539376013, "ltp": 1.21, "tv": 360.14, "trd": NaN, "batb": [[0, 1.01, 7], [1, 1.09, 0], [2, 1.01, 0]], "batl": [[1, 1.35, 0]]}, {"timestamp": 1631539381594, "ltp": 1.21, "tv": 360.14, "trd": NaN, "batb": [[0, 1.15, 200], [1, 1.12, 539.54], [2, 1.01, 7]], "batl": [[1, 1.51, 838.52]]}, {"timestamp": 1631539405571, "ltp": 1.21, "tv": 360.14, "trd": NaN, "batb": [[0, 1.12, 539.54], [1, 1.01, 7], [2, 1.01, 0]], "batl": NaN}, {"timestamp": 1631539407375, "ltp": 1.21, "tv": 360.14, "trd": NaN, "batb": [[0, 1.01, 7], [1, 1.01, 0]], "batl": NaN}, {"timestamp": 1631539410507, "ltp": 1.21, "tv": 360.14, "trd": NaN, "batb": [[0, 1.18, 166.66], [1, 1.01, 7]], "batl": NaN}, {"timestamp": 1631539412700, "ltp": 1.21, "tv": 360.14, "trd": NaN, "batb": [[1, 1.16, 469.27], [2, 1.01, 7]], "batl": NaN}, {"timestamp": 1631539415090, "ltp": 1.21, "tv": 377.26, "trd": [[1.21, 46.16]], "batb": NaN, "batl": [[0, 1.21, 62.4]]}, {"timestamp": 1631539425328, "ltp": 1.21, "tv": 403.62, "trd": [[1.21, 72.52]], "batb": NaN, "batl": [[0, 1.21, 49.22]]}, {"timestamp": 1631539433848, "ltp": 1.21, "tv": 403.62, "trd": NaN, "batb": [[0, 1.16, 469.27], [1, 1.01, 7], [2, 1.01, 0]], "batl": NaN}, {"timestamp": 1631539434838, "ltp": 1.21, "tv": 403.62, "trd": NaN, "batb": [[0, 1.01, 7], [1, 1.01, 0]], "batl": NaN}, {"timestamp": 1631539438856, "ltp": 1.21, "tv": 403.62, "trd": NaN, "batb": [[0, 1.2, 150], [1, 1.01, 7]], "batl": NaN}, {"timestamp": 1631539441050, "ltp": 1.21, "tv": 403.62, "trd": NaN, "batb": [[1, 1.18, 445.2], [2, 1.01, 7]], "batl": NaN}, {"timestamp": 1631539442947, "ltp": 1.21, "tv": 452.84, "trd": [[1.21, 121.74]], "batb": NaN, "batl": [[0, 1.51, 838.52], [1, 1.51, 0]]}, {"timestamp": 1631539452577, "ltp": 1.21, "tv": 452.84, "trd": NaN, "batb": [[0, 1.2, 150.08]], "batl": NaN}, {"timestamp": 1631539484701, "ltp": 1.21, "tv": 452.84, "trd": NaN, "batb": [[0, 1.18, 445.28], [1, 1.01, 7], [2, 1.01, 0]], "batl": NaN}, {"timestamp": 1631539486687, "ltp": 1.21, "tv": 452.84, "trd": NaN, "batb": [[0, 1.01, 7.08], [1, 1.01, 0]], "batl": NaN}, {"timestamp": 1631539489721, "ltp": 1.21, "tv": 452.84, "trd": NaN, "batb": [[0, 1.18, 166.74], [1, 1.01, 7]], "batl": NaN}, {"timestamp": 1631539492910, "ltp": 1.21, "tv": 452.84, "trd": NaN, "batb": [[1, 1.14, 500.97], [2, 1.01, 7]], "batl": NaN}, {"timestamp": 1631539514447, "ltp": 1.21, "tv": 452.84, "trd": NaN, "batb": [[0, 1.14, 501.05], [1, 1.01, 7], [2, 1.01, 0]], "batl": NaN}, {"timestamp": 1631539515129, "ltp": 1.21, "tv": 452.84, "trd": NaN, "batb": [[0, 1.01, 7.08], [1, 1.01, 0]], "batl": NaN}, {"timestamp": 1631539519575, "ltp": 1.21, "tv": 452.92, "trd": [[1.21, 121.82]], "batb": [[0, 1.11, 272.72], [1, 1.01, 7]], "batl": NaN}, {"timestamp": 1631539521036, "ltp": 1.21, "tv": 452.92, "trd": NaN, "batb": [[1, 1.09, 638.16], [2, 1.01, 7]], "batl": NaN}, {"timestamp": 1631539558813, "ltp": 1.21, "tv": 452.92, "trd": NaN, "batb": [[0, 1.09, 638.16], [1, 1.01, 7], [2, 1.01, 0]], "batl": NaN}, {"timestamp": 1631539560015, "ltp": 1.21, "tv": 452.92, "trd": NaN, "batb": [[0, 1.01, 7], [1, 1.01, 0]], "batl": NaN}, {"timestamp": 1631539563831, "ltp": 1.21, "tv": 452.92, "trd": NaN, "batb": [[0, 1.18, 166.66], [1, 1.01, 7]], "batl": NaN}, {"timestamp": 1631539565718, "ltp": 1.21, "tv": 452.92, "trd": NaN, "batb": [[1, 1.14, 500.97], [2, 1.01, 7]], "batl": NaN}, {"timestamp": 1631539579266, "ltp": 1.21, "tv": 452.92, "trd": NaN, "batb": [[0, 1.14, 500.97], [1, 1.01, 7], [2, 1.01, 0]], "batl": NaN}, {"timestamp": 1631539580365, "ltp": 1.21, "tv": 452.92, "trd": NaN, "batb": [[0, 1.01, 7], [1, 1.01, 0]], "batl": NaN}, {"timestamp": 1631539584288, "ltp": 1.21, "tv": 452.92, "trd": NaN, "batb": [[0, 1.11, 272.72], [1, 1.01, 7]], "batl": NaN}, {"timestamp": 1631539586065, "ltp": 1.21, "tv": 452.92, "trd": NaN, "batb": [[1, 1.09, 638.16], [2, 1.01, 7]], "batl": NaN}, {"timestamp": 1631539599201, "ltp": 1.21, "tv": 452.92, "trd": NaN, "batb": [[0, 1.09, 638.16], [1, 1.01, 7], [2, 1.01, 0]], "batl": NaN}, {"timestamp": 1631539600708, "ltp": 1.21, "tv": 452.92, "trd": NaN, "batb": [[0, 1.01, 7], [1, 1.01, 0]], "batl": NaN}, {"timestamp": 1631539604102, "ltp": 1.21, "tv": 452.92, "trd": NaN, "batb": [[0, 1.18, 166.66], [1, 1.01, 7]], "batl": NaN}, {"timestamp": 1631539606229, "ltp": 1.21, "tv": 452.92, "trd": NaN, "batb": [[1, 1.14, 500.97], [2, 1.01, 7]], "batl": NaN}, {"timestamp": 1631539610932, "ltp": 1.21, "tv": 452.92, "trd": NaN, "batb": [[0, 1.14, 500.97], [1, 1.01, 7], [2, 1.01, 0]], "batl": NaN}, {"timestamp": 1631539615918, "ltp": 1.21, "tv": 452.92, "trd": NaN, "batb": [[0, 1.15, 200], [1, 1.14, 500.97], [2, 1.01, 7]], "batl": NaN}, {"timestamp": 1631539625539, "ltp": 1.21, "tv": 452.92, "trd": NaN, "batb": [[0, 1.14, 500.97], [1, 1.01, 7], [2, 1.01, 0]], "batl": NaN}, {"timestamp": 1631539625952, "ltp": 1.21, "tv": 452.92, "trd": NaN, "batb": [[0, 1.01, 7], [1, 1.01, 0]], "batl": NaN}, {"timestamp": 1631539630468, "ltp": 1.21, "tv": 452.92, "trd": NaN, "batb": [[0, 1.23, 130.43], [1, 1.01, 7]], "batl": NaN}, {"timestamp": 1631539631249, "ltp": 1.21, "tv": 452.92, "trd": NaN, "batb": [[1, 1.18, 445.2], [2, 1.01, 7]], "batl": NaN}, {"timestamp": 1631539731765, "ltp": 1.21, "tv": 452.92, "trd": NaN, "batb": [[1, 1.01, 7], [2, 1.01, 0]], "batl": NaN}, {"timestamp": 1631539737862, "ltp": 1.21, "tv": 452.92, "trd": NaN, "batb": [[1, 1.2, 427.96], [2, 1.01, 7]], "batl": [[0, 1.66, 667.28]]}, {"timestamp": 1631539748599, "ltp": 1.21, "tv": 452.92, "trd": NaN, "batb": [[0, 1.2, 427.96], [1, 1.01, 7], [2, 1.01, 0]], "batl": NaN}, {"timestamp": 1631539750003, "ltp": 1.21, "tv": 452.92, "trd": NaN, "batb": [[0, 1.01, 7], [1, 1.01, 0]], "batl": NaN}, {"timestamp": 1631539753501, "ltp": 1.21, "tv": 452.92, "trd": NaN, "batb": [[0, 1.31, 96.77], [1, 1.01, 7]], "batl": NaN}, {"timestamp": 1631539756375, "ltp": 1.21, "tv": 452.92, "trd": NaN, "batb": [[1, 1.23, 414.27], [2, 1.01, 7]], "batl": NaN}, {"timestamp": 1631539770229, "ltp": 1.21, "tv": 452.92, "trd": NaN, "batb": [[0, 1.01, 7], [1, 1.23, 0], [2, 1.01, 0]], "batl": NaN}, {"timestamp": 1631539775132, "ltp": 1.21, "tv": 452.92, "trd": NaN, "batb": [[0, 1.23, 130.43], [1, 1.01, 7]], "batl": NaN}, {"timestamp": 1631539776330, "ltp": 1.21, "tv": 452.92, "trd": NaN, "batb": [[1, 1.2, 427.96], [2, 1.01, 7]], "batl": NaN}, {"timestamp": 1631539796466, "ltp": 1.21, "tv": 452.92, "trd": NaN, "batb": [[0, 1.2, 427.96], [1, 1.01, 7], [2, 1.01, 0]], "batl": NaN}, {"timestamp": 1631539797568, "ltp": 1.21, "tv": 452.92, "trd": NaN, "batb": [[0, 1.01, 7], [1, 1.01, 0]], "batl": NaN}, {"timestamp": 1631539801496, "ltp": 1.21, "tv": 452.92, "trd": NaN, "batb": [[0, 1.18, 166.66], [1, 1.01, 7]], "batl": NaN}, {"timestamp": 1631539803479, "ltp": 1.21, "tv": 452.92, "trd": NaN, "batb": [[1, 1.16, 469.27], [2, 1.01, 7]], "batl": [[0, 1.58, 742.74]]}, {"timestamp": 1631539820694, "ltp": 1.21, "tv": 452.92, "trd": NaN, "batb": [[0, 1.16, 469.27], [1, 1.01, 7], [2, 1.01, 0]], "batl": NaN}, {"timestamp": 1631539821995, "ltp": 1.21, "tv": 452.92, "trd": NaN, "batb": [[0, 1.01, 7], [1, 1.01, 0]], "batl": NaN}, {"timestamp": 1631539825738, "ltp": 1.21, "tv": 452.92, "trd": NaN, "batb": [[0, 1.15, 200], [1, 1.01, 7]], "batl": NaN}, {"timestamp": 1631539827620, "ltp": 1.21, "tv": 452.92, "trd": NaN, "batb": [[1, 1.12, 539.54], [2, 1.01, 7]], "batl": [[0, 1.51, 838.52]]}, {"timestamp": 1631539848359, "ltp": 1.21, "tv": 452.92, "trd": NaN, "batb": [[1, 1.01, 7], [2, 1.01, 0]], "batl": NaN}, {"timestamp": 1631539848680, "ltp": 1.21, "tv": 452.92, "trd": NaN, "batb": [[0, 1.01, 7], [1, 1.01, 0]], "batl": NaN}, {"timestamp": 1631539853941, "ltp": 1.21, "tv": 452.92, "trd": NaN, "batb": [[0, 1.12, 249.99], [1, 1.1, 606.51], [2, 1.01, 7]], "batl": NaN}, {"timestamp": 1631539901866, "ltp": 1.21, "tv": 452.92, "trd": NaN, "batb": [[0, 1.1, 606.51], [1, 1.01, 7], [2, 1.01, 0]], "batl": NaN}, {"timestamp": 1631539903063, "ltp": 1.21, "tv": 452.92, "trd": NaN, "batb": [[0, 1.01, 7], [1, 1.01, 0]], "batl": NaN}, {"timestamp": 1631539906871, "ltp": 1.21, "tv": 452.92, "trd": NaN, "batb": [[0, 1.18, 166.66], [1, 1.01, 7]], "batl": NaN}, {"timestamp": 1631539909165, "ltp": 1.21, "tv": 452.92, "trd": NaN, "batb": [[1, 1.14, 500.97], [2, 1.01, 7]], "batl": NaN}, {"timestamp": 1631539928405, "ltp": 1.21, "tv": 452.92, "trd": NaN, "batb": [[1, 1.01, 7], [2, 1.01, 0]], "batl": NaN}, {"timestamp": 1631539934715, "ltp": 1.21, "tv": 452.92, "trd": NaN, "batb": [[1, 1.16, 469.27], [2, 1.01, 7]], "batl": NaN}, {"timestamp": 1631539939531, "ltp": 1.21, "tv": 452.92, "trd": NaN, "batb": [[0, 1.16, 469.27], [1, 1.01, 7], [2, 1.01, 0]], "batl": NaN}, {"timestamp": 1631539940727, "ltp": 1.21, "tv": 452.92, "trd": NaN, "batb": [[0, 1.01, 7], [1, 1.01, 0]], "batl": NaN}, {"timestamp": 1631539944548, "ltp": 1.21, "tv": 452.92, "trd": NaN, "batb": [[0, 1.27, 111.11], [1, 1.01, 7]], "batl": NaN}, {"timestamp": 1631539946905, "ltp": 1.21, "tv": 452.92, "trd": NaN, "batb": [[1, 1.2, 427.96], [2, 1.01, 7]], "batl": [[0, 1.66, 667.28]]}, {"timestamp": 1631539968980, "ltp": 1.21, "tv": 452.92, "trd": NaN, "batb": [[0, 1.2, 427.96], [1, 1.01, 7], [2, 1.01, 0]], "batl": NaN}, {"timestamp": 1631539970173, "ltp": 1.21, "tv": 452.92, "trd": NaN, "batb": [[0, 1.01, 7], [1, 1.01, 0]], "batl": NaN}, {"timestamp": 1631539973877, "ltp": 1.21, "tv": 452.92, "trd": NaN, "batb": [[0, 1.2, 150], [1, 1.01, 7]], "batl": NaN}, {"timestamp": 1631539976466, "ltp": 1.21, "tv": 452.92, "trd": NaN, "batb": [[1, 1.16, 469.27], [2, 1.01, 7]], "batl": [[0, 1.58, 742.74]]}, {"timestamp": 1631540004508, "ltp": 1.21, "tv": 452.92, "trd": NaN, "batb": [[0, 1.16, 469.27], [1, 1.01, 7], [2, 1.01, 0]], "batl": NaN}, {"timestamp": 1631540005636, "ltp": 1.21, "tv": 452.92, "trd": NaN, "batb": [[0, 1.01, 7], [1, 1.01, 0]], "batl": NaN}, {"timestamp": 1631540009441, "ltp": 1.21, "tv": 452.92, "trd": NaN, "batb": [[0, 1.15, 200], [1, 1.01, 7]], "batl": NaN}, {"timestamp": 1631540011527, "ltp": 1.21, "tv": 452.92, "trd": NaN, "batb": [[1, 1.12, 539.54], [2, 1.01, 7]], "batl": [[0, 1.51, 838.52]]}, {"timestamp": 1631540031173, "ltp": 1.21, "tv": 452.92, "trd": NaN, "batb": [[0, 1.12, 539.54], [1, 1.01, 7], [2, 1.01, 0]], "batl": NaN}, {"timestamp": 1631540031951, "ltp": 1.21, "tv": 452.92, "trd": NaN, "batb": [[0, 1.01, 7], [1, 1.01, 0]], "batl": NaN}, {"timestamp": 1631540036071, "ltp": 1.21, "tv": 452.92, "trd": NaN, "batb": [[0, 1.2, 150], [1, 1.01, 7]], "batl": NaN}, {"timestamp": 1631540037799, "ltp": 1.21, "tv": 452.92, "trd": NaN, "batb": [[1, 1.16, 469.27], [2, 1.01, 7]], "batl": NaN}, {"timestamp": 1631540064410, "ltp": 1.21, "tv": 452.92, "trd": NaN, "batb": [[1, 1.01, 7], [2, 1.01, 0]], "batl": NaN}, {"timestamp": 1631540070127, "ltp": 1.21, "tv": 452.92, "trd": NaN, "batb": [[1, 1.18, 445.2], [2, 1.01, 7]], "batl": NaN}, {"timestamp": 1631540088165, "ltp": 1.21, "tv": 452.92, "trd": NaN, "batb": [[0, 1.18, 445.2], [1, 1.01, 7], [2, 1.01, 0]], "batl": NaN}, {"timestamp": 1631540089776, "ltp": 1.21, "tv": 452.92, "trd": NaN, "batb": [[0, 1.01, 7], [1, 1.01, 0]], "batl": NaN}, {"timestamp": 1631540093083, "ltp": 1.21, "tv": 452.92, "trd": NaN, "batb": [[0, 1.15, 200], [1, 1.01, 7]], "batl": NaN}, {"timestamp": 1631540095059, "ltp": 1.21, "tv": 452.92, "trd": NaN, "batb": [[1, 1.12, 539.54], [2, 1.01, 7]], "batl": NaN}, {"timestamp": 1631540169081, "ltp": 1.21, "tv": 452.92, "trd": NaN, "batb": [[0, 1.12, 539.54], [1, 1.01, 7], [2, 1.01, 0]], "batl": NaN}, {"timestamp": 1631540169863, "ltp": 1.21, "tv": 452.92, "trd": NaN, "batb": [[0, 1.01, 7], [1, 1.01, 0]], "batl": NaN}, {"timestamp": 1631540174064, "ltp": 1.21, "tv": 452.92, "trd": NaN, "batb": [[0, 1.08, 374.99], [1, 1.01, 7]], "batl": NaN}, {"timestamp": 1631540175995, "ltp": 1.21, "tv": 452.92, "trd": NaN, "batb": [[0, 1.08, 1060.54]], "batl": [[0, 1.44, 961.06]]}, {"timestamp": 1631540226099, "ltp": 1.21, "tv": 452.92, "trd": NaN, "batb": [[0, 1.08, 685.55]], "batl": NaN}, {"timestamp": 1631540227664, "ltp": 1.21, "tv": 452.92, "trd": NaN, "batb": [[0, 1.01, 7], [1, 1.01, 0]], "batl": NaN}, {"timestamp": 1631540230962, "ltp": 1.21, "tv": 452.92, "trd": NaN, "batb": [[0, 1.04, 749.99], [1, 1.01, 7]], "batl": NaN}, {"timestamp": 1631540233586, "ltp": 1.21, "tv": 452.92, "trd": NaN, "batb": [[0, 1.04, 1901.12]], "batl": [[0, 1.37, 1110.7]]}, {"timestamp": 1631540244989, "ltp": 1.21, "tv": 452.92, "trd": NaN, "batb": [[0, 1.04, 749.99]], "batl": NaN}, {"timestamp": 1631540258015, "ltp": 1.21, "tv": 452.92, "trd": NaN, "batb": [[0, 1.01, 7], [1, 1.01, 0]], "batl": NaN}, {"timestamp": 1631540263044, "ltp": 1.21, "tv": 452.92, "trd": NaN, "batb": [[0, 1.02, 2026.61], [1, 1.01, 7]], "batl": [[0, 1.33, 1235.43]]}, {"timestamp": 1631540304919, "ltp": 1.21, "tv": 452.92, "trd": NaN, "batb": [[0, 1.01, 7], [1, 1.01, 0]], "batl": NaN}, {"timestamp": 1631540310543, "ltp": 1.21, "tv": 452.92, "trd": NaN, "batb": [[0, 1.01, 3809.99]], "batl": NaN}, {"timestamp": 1631540421849, "ltp": 1.21, "tv": 452.92, "trd": NaN, "batb": [[0, 1.05, 200], [1, 1.01, 3809.99]], "batl": NaN}, {"timestamp": 1631540456276, "ltp": 1.21, "tv": 452.92, "trd": NaN, "batb": [[1, 1.01, 7]], "batl": NaN}, {"timestamp": 1631540481616, "ltp": 1.21, "tv": 452.92, "trd": NaN, "batb": [[0, 1.01, 7], [1, 1.01, 0]], "batl": NaN}, {"timestamp": 1631540681223, "ltp": 1.21, "tv": 452.92, "trd": NaN, "batb": [[0, 1.01, 3930.11]], "batl": [[0, 1.32, 1269.71]]}, {"timestamp": 1631540785547, "ltp": 1.21, "tv": 452.92, "trd": NaN, "batb": [[0, 1.01, 7]], "batl": NaN}, {"timestamp": 1631540788820, "ltp": 1.21, "tv": 452.92, "trd": NaN, "batb": [[0, 1.02, 1499.99], [1, 1.01, 7]], "batl": NaN}, {"timestamp": 1631540791053, "ltp": 1.21, "tv": 452.92, "trd": NaN, "batb": [[0, 1.03, 1419.65], [1, 1.02, 1499.99], [2, 1.01, 7]], "batl": NaN}, {"timestamp": 1631540841298, "ltp": 1.21, "tv": 452.92, "trd": NaN, "batb": [[1, 1.01, 7], [2, 1.01, 0]], "batl": NaN}, {"timestamp": 1631540842395, "ltp": 1.21, "tv": 452.92, "trd": NaN, "batb": [[0, 1.01, 7], [1, 1.01, 0]], "batl": NaN}, {"timestamp": 1631540847810, "ltp": 1.21, "tv": 452.92, "trd": NaN, "batb": [[0, 1.02, 2026.61], [1, 1.01, 7]], "batl": NaN}, {"timestamp": 1631540876744, "ltp": 1.21, "tv": 452.92, "trd": NaN, "batb": [[0, 1.01, 7], [1, 1.01, 0]], "batl": NaN}, {"timestamp": 1631540882973, "ltp": 1.21, "tv": 452.92, "trd": NaN, "batb": [[0, 1.01, 3809.99]], "batl": NaN}, {"timestamp": 1631540948773, "ltp": 1.21, "tv": 452.92, "trd": NaN, "batb": [[0, 1.01, 7]], "batl": NaN}, {"timestamp": 1631541123159, "ltp": 1.21, "tv": 452.92, "trd": NaN, "batb": [[0, 1.02, 1499.99], [1, 1.01, 7]], "batl": NaN}, {"timestamp": 1631541146419, "ltp": 1.21, "tv": 452.92, "trd": NaN, "batb": [[0, 1.01, 7], [1, 1.01, 0]], "batl": NaN}, {"timestamp": 1631541380171, "ltp": 1.08, "tv": 582.55, "trd": [[1.08, 133.71]], "batb": [[0, 1.08, 420.37], [1, 1.01, 7]], "batl": NaN}, {"timestamp": 1631541406691, "ltp": 1.08, "tv": 707.55, "trd": [[1.08, 258.71]], "batb": [[0, 1.08, 295.37]], "batl": NaN}, {"timestamp": 1631541409014, "ltp": 1.08, "tv": 707.55, "trd": NaN, "batb": NaN, "batl": [[0, 1.3, 1344.81]]}, {"timestamp": 1631541420106, "ltp": 1.08, "tv": 865.25, "trd": [[1.08, 416.42]], "batb": [[0, 1.08, 216.52]], "batl": NaN}, {"timestamp": 1631541451869, "ltp": 1.08, "tv": 890.25, "trd": [[1.08, 441.42]], "batb": [[0, 1.08, 191.52]], "batl": NaN}, {"timestamp": 1631541485897, "ltp": 1.08, "tv": 1047.96, "trd": [[1.08, 599.12]], "batb": [[0, 1.08, 112.67]], "batl": NaN}, {"timestamp": 1631541515957, "ltp": 1.08, "tv": 1205.66, "trd": [[1.08, 756.83]], "batb": [[0, 1.08, 33.82]], "batl": NaN}, {"timestamp": 1631541534469, "ltp": 1.08, "tv": 1239.48, "trd": [[1.08, 790.65]], "batb": [[0, 1.01, 7], [1, 1.01, 0]], "batl": NaN}, {"timestamp": 1631541535397, "ltp": 1.08, "tv": 1239.48, "trd": NaN, "batb": [[0, 1.01, 3930.11]], "batl": NaN}, {"timestamp": 1631541543917, "ltp": 1.08, "tv": 1239.48, "trd": NaN, "batb": [[0, 1.01, 7]], "batl": NaN}, {"timestamp": 1631541549620, "ltp": 1.08, "tv": 1239.48, "trd": NaN, "batb": [[0, 1.01, 3809.99]], "batl": NaN}, {"timestamp": 1631541560215, "ltp": 1.08, "tv": 1239.48, "trd": NaN, "batb": [[0, 1.01, 7]], "batl": NaN}, {"timestamp": 1631541565737, "ltp": 1.08, "tv": 1239.48, "trd": NaN, "batb": [[0, 1.02, 2026.61], [1, 1.01, 7]], "batl": NaN}, {"timestamp": 1631541582546, "ltp": 1.08, "tv": 1239.48, "trd": NaN, "batb": [[0, 1.01, 7], [1, 1.01, 0]], "batl": NaN}, {"timestamp": 1631541587955, "ltp": 1.08, "tv": 1239.48, "trd": NaN, "batb": [[0, 1.01, 3930.11]], "batl": NaN}, {"timestamp": 1631541603886, "ltp": 1.08, "tv": 1239.48, "trd": NaN, "batb": [[0, 1.01, 7]], "batl": NaN}, {"timestamp": 1631541610196, "ltp": 1.08, "tv": 1239.48, "trd": NaN, "batb": [[0, 1.01, 3809.99]], "batl": NaN}, {"timestamp": 1631541632293, "ltp": 1.08, "tv": 1239.48, "trd": NaN, "batb": [[0, 1.01, 7]], "batl": NaN}, {"timestamp": 1631541677190, "ltp": 1.08, "tv": 1239.48, "trd": NaN, "batb": [[0, 1.01, 3930.11]], "batl": NaN}, {"timestamp": 1631541702412, "ltp": 1.08, "tv": 1239.48, "trd": NaN, "batb": [[0, 1.01, 7]], "batl": NaN}, {"timestamp": 1631541772333, "ltp": 1.08, "tv": 1239.48, "trd": NaN, "batb": NaN, "batl": [[0, 1.28, 1429.36]]}, {"timestamp": 1631541785371, "ltp": 1.08, "tv": 1239.48, "trd": NaN, "batb": NaN, "batl": [[0, 1.3, 1344.81]]}, {"timestamp": 1631542117523, "ltp": 1.08, "tv": 1239.48, "trd": NaN, "batb": NaN, "batl": [[0, 1.28, 1469.32]]}, {"timestamp": 1631542223669, "ltp": 1.01, "tv": 1253.47, "trd": [[1.01, 13.99]], "batb": NaN, "batl": [[0, 1.01, 10.04], [1, 1.28, 1469.32]]}, {"timestamp": 1631542571895, "ltp": 1.01, "tv": 1253.47, "trd": NaN, "batb": NaN, "batl": [[1, 1.28, 0]]}, {"timestamp": 1631542713308, "ltp": 1.01, "tv": 1253.47, "trd": NaN, "batb": NaN, "batl": [[1, 1.27, 1497.1]]}, {"timestamp": 1631542726021, "ltp": 1.01, "tv": 1253.47, "trd": NaN, "batb": NaN, "batl": [[1, 1.27, 0]]}, {"timestamp": 1631542735746, "ltp": 1.01, "tv": 1253.47, "trd": NaN, "batb": NaN, "batl": [[1, 1.28, 1469.32]]}, {"timestamp": 1631542784941, "ltp": 1.01, "tv": 1253.47, "trd": NaN, "batb": NaN, "batl": [[1, 1.28, 0]]}, {"timestamp": 1631542797580, "ltp": 1.01, "tv": 1253.47, "trd": NaN, "batb": NaN, "batl": [[1, 1.28, 1455.25]]}, {"timestamp": 1631542799186, "ltp": 1.01, "tv": 1253.47, "trd": NaN, "batb": NaN, "batl": [[1, 1.28, 0]]}, {"timestamp": 1631542876180, "ltp": 1.01, "tv": 1273.56, "trd": [[1.01, 34.08]], "batb": [[0, 1.02, 39.95]], "batl": NaN}, {"timestamp": 1631542884582, "ltp": 1.01, "tv": 1273.56, "trd": NaN, "batb": [[0, 1.01, 100]], "batl": NaN}, {"timestamp": 1631542884892, "ltp": 1.01, "tv": 1273.56, "trd": NaN, "batb": [[0, 1.01, 200]], "batl": NaN}, {"timestamp": 1631542885724, "ltp": 1.01, "tv": 1273.56, "trd": NaN, "batb": [[0, 1.01, 250]], "batl": NaN}, {"timestamp": 1631542947538, "ltp": 1.01, "tv": 1273.56, "trd": NaN, "batb": [[0, 1.01, 150]], "batl": NaN}, {"timestamp": 1631542998194, "ltp": 1.01, "tv": 1273.56, "trd": NaN, "batb": [[0, 1.01, 300]], "batl": NaN}, {"timestamp": 1631543122276, "ltp": 1.01, "tv": 1273.56, "trd": NaN, "batb": [[0, 1.02, 2.17], [1, 1.01, 300]], "batl": NaN}, {"timestamp": 1631543164661, "ltp": 1.01, "tv": 1273.56, "trd": NaN, "batb": [[0, 1.01, 300], [1, 1.01, 0]], "batl": NaN}, {"timestamp": 1631543837660, "ltp": 1.01, "tv": 1273.56, "trd": NaN, "batb": NaN, "batl": [[0, 1.39, 38.32]]}, {"timestamp": 1631544395904, "ltp": 1.01, "tv": 1273.56, "trd": NaN, "batb": NaN, "batl": [[0, 1.32, 38.32]]}, {"timestamp": 1631544982750, "ltp": 1.01, "tv": 1273.56, "trd": NaN, "batb": [[0, 1.02, 1.7], [1, 1.01, 300]], "batl": NaN}, {"timestamp": 1631545548491, "ltp": 1.01, "tv": 1274.04, "trd": [[1.01, 34.1], [1.08, 790.93], [1.09, 322.04], [1.11, 5.11], [1.21, 121.85]], "batb": [[0, 1.02, 1.71]], "batl": NaN}, {"timestamp": 1631545689734, "ltp": 1.01, "tv": 1274.04, "trd": NaN, "batb": NaN, "batl": [[0, 1.39, 43.5]]}, {"timestamp": 1631548956657, "ltp": 1.01, "tv": 1274.04, "trd": NaN, "batb": NaN, "batl": [[0, 1.3, 5.03], [1, 1.39, 43.5]]}, {"timestamp": 1631549019949, "ltp": 1.01, "tv": 1274.04, "trd": NaN, "batb": NaN, "batl": [[0, 1.39, 43.5], [1, 1.39, 0]]}, {"timestamp": 1631549025033, "ltp": 1.01, "tv": 1274.04, "trd": NaN, "batb": NaN, "batl": [[0, 1.36, 5.03], [1, 1.39, 43.5]]}, {"timestamp": 1631549087127, "ltp": 1.01, "tv": 1274.04, "trd": NaN, "batb": [[1, 1.01, 305]], "batl": NaN}, {"timestamp": 1631549247663, "ltp": 1.36, "tv": 1275.41, "trd": [[1.36, 1.37]], "batb": NaN, "batl": [[0, 1.36, 3.65]]}, {"timestamp": 1631549382863, "ltp": 1.36, "tv": 1275.41, "trd": NaN, "batb": NaN, "batl": [[1, 1.39, 0]]}, {"timestamp": 1631549387978, "ltp": 1.36, "tv": 1275.41, "trd": NaN, "batb": NaN, "batl": [[0, 1.35, 43.5], [1, 1.36, 3.65]]}, {"timestamp": 1631549415722, "ltp": 1.36, "tv": 1275.41, "trd": NaN, "batb": NaN, "batl": [[0, 1.34, 5.03], [1, 1.35, 43.5], [2, 1.36, 3.65]]}, {"timestamp": 1631549671392, "ltp": 1.36, "tv": 1275.41, "trd": NaN, "batb": NaN, "batl": [[0, 1.33, 61.39], [1, 1.34, 5.03], [2, 1.35, 43.5]]}, {"timestamp": 1631549765660, "ltp": 1.36, "tv": 1275.41, "trd": NaN, "batb": NaN, "batl": [[0, 1.31, 47.75], [1, 1.33, 61.39], [2, 1.34, 5.03]]}, {"timestamp": 1631549774762, "ltp": 1.36, "tv": 1275.41, "trd": NaN, "batb": NaN, "batl": [[2, 1.35, 43.5]]}, {"timestamp": 1631549779849, "ltp": 1.36, "tv": 1275.41, "trd": NaN, "batb": NaN, "batl": [[0, 1.31, 52.77]]}, {"timestamp": 1631549803714, "ltp": 1.36, "tv": 1275.41, "trd": NaN, "batb": NaN, "batl": [[2, 1.36, 3.65]]}, {"timestamp": 1631549808889, "ltp": 1.36, "tv": 1275.41, "trd": NaN, "batb": NaN, "batl": [[0, 1.29, 43.5], [1, 1.31, 52.77], [2, 1.33, 61.39]]}, {"timestamp": 1631549927169, "ltp": 1.36, "tv": 1275.41, "trd": NaN, "batb": NaN, "batl": [[1, 1.31, 5.03]]}, {"timestamp": 1631549932285, "ltp": 1.36, "tv": 1275.41, "trd": NaN, "batb": NaN, "batl": [[0, 1.28, 47.75], [1, 1.29, 43.5], [2, 1.31, 5.03]]}, {"timestamp": 1631549996684, "ltp": 1.36, "tv": 1275.41, "trd": NaN, "batb": NaN, "batl": [[1, 1.31, 5.03], [2, 1.33, 61.39]]}, {"timestamp": 1631550001783, "ltp": 1.36, "tv": 1275.41, "trd": NaN, "batb": NaN, "batl": [[0, 1.27, 43.5], [1, 1.28, 47.75], [2, 1.31, 5.03]]}, {"timestamp": 1631550008011, "ltp": 1.36, "tv": 1275.41, "trd": NaN, "batb": NaN, "batl": [[1, 1.31, 5.03], [2, 1.33, 61.39]]}, {"timestamp": 1631550013081, "ltp": 1.36, "tv": 1275.41, "trd": NaN, "batb": NaN, "batl": [[0, 1.26, 47.75], [1, 1.27, 43.5], [2, 1.31, 5.03]]}, {"timestamp": 1631550021633, "ltp": 1.36, "tv": 1275.41, "trd": NaN, "batb": [[0, 1.02, 1501.7]], "batl": NaN}, {"timestamp": 1631550021803, "ltp": 1.36, "tv": 1275.41, "trd": NaN, "batb": [[0, 1.02, 1.71]], "batl": NaN}, {"timestamp": 1631550047869, "ltp": 1.36, "tv": 1275.41, "trd": NaN, "batb": [[0, 1.04, 1.79], [1, 1.02, 1.71], [2, 1.01, 305]], "batl": NaN}, {"timestamp": 1631550099824, "ltp": 1.36, "tv": 1275.41, "trd": NaN, "batb": NaN, "batl": [[0, 1.24, 3.66], [1, 1.26, 47.75], [2, 1.27, 43.5]]}, {"timestamp": 1631550119942, "ltp": 1.36, "tv": 1275.41, "trd": NaN, "batb": [[0, 1.02, 1.71], [1, 1.01, 305], [2, 1.01, 0]], "batl": [[0, 1.26, 47.75], [1, 1.27, 43.5], [2, 1.33, 61.39]]}, {"timestamp": 1631550157717, "ltp": 1.36, "tv": 1275.41, "trd": NaN, "batb": NaN, "batl": [[1, 1.33, 61.39], [2, 1.33, 0]]}]}, {"runnerId": 9628382, "odds": [{"timestamp": 1631537870400, "ltp": 12.0, "tv": 7.09, "trd": [[12, 7.1]], "batb": NaN, "batl": NaN}, {"timestamp": 1631537872910, "ltp": 12.0, "tv": 7.09, "trd": NaN, "batb": [[0, 1.01, 7], [1, 1.01, 0]], "batl": NaN}, {"timestamp": 1631537877833, "ltp": 12.0, "tv": 7.09, "trd": NaN, "batb": [[0, 4.8, 10], [1, 1.01, 7]], "batl": NaN}, {"timestamp": 1631537911631, "ltp": 12.0, "tv": 7.09, "trd": NaN, "batb": [[0, 1.01, 7], [1, 1.01, 0]], "batl": NaN}, {"timestamp": 1631537916584, "ltp": 12.0, "tv": 7.09, "trd": NaN, "batb": [[0, 4.3, 10], [1, 1.01, 7]], "batl": NaN}, {"timestamp": 1631537949386, "ltp": 5.7, "tv": 8.47, "trd": [[5.7, 1.38]], "batb": NaN, "batl": NaN}, {"timestamp": 1631538000250, "ltp": 5.7, "tv": 8.47, "trd": NaN, "batb": [[0, 1.01, 7], [1, 1.01, 0]], "batl": NaN}, {"timestamp": 1631538004744, "ltp": 5.7, "tv": 8.47, "trd": [[5.7, 1.38], [12, 7.09]], "batb": [[0, 5.3, 10], [1, 1.01, 7]], "batl": NaN}, {"timestamp": 1631538041409, "ltp": 5.7, "tv": 8.47, "trd": NaN, "batb": [[0, 1.01, 7], [1, 1.01, 0]], "batl": NaN}, {"timestamp": 1631538046307, "ltp": 5.7, "tv": 8.47, "trd": NaN, "batb": [[0, 5.8, 10], [1, 1.01, 7]], "batl": NaN}, {"timestamp": 1631538072005, "ltp": 5.7, "tv": 8.47, "trd": NaN, "batb": [[0, 1.01, 7], [1, 1.01, 0]], "batl": NaN}, {"timestamp": 1631538077009, "ltp": 5.7, "tv": 8.47, "trd": NaN, "batb": [[0, 5.3, 10], [1, 1.01, 7]], "batl": NaN}, {"timestamp": 1631538098943, "ltp": 5.7, "tv": 8.47, "trd": NaN, "batb": [[0, 1.01, 7], [1, 1.01, 0]], "batl": NaN}, {"timestamp": 1631538103832, "ltp": 5.7, "tv": 8.47, "trd": NaN, "batb": [[0, 4.3, 10], [1, 1.01, 7]], "batl": NaN}, {"timestamp": 1631538123262, "ltp": 5.7, "tv": 8.47, "trd": NaN, "batb": [[0, 1.01, 7], [1, 1.01, 0]], "batl": NaN}, {"timestamp": 1631538128297, "ltp": 5.7, "tv": 8.47, "trd": NaN, "batb": [[0, 4.8, 10], [1, 1.01, 7]], "batl": NaN}, {"timestamp": 1631538206435, "ltp": 5.7, "tv": 8.47, "trd": NaN, "batb": [[0, 1.01, 7], [1, 1.01, 0]], "batl": NaN}, {"timestamp": 1631538211342, "ltp": 5.7, "tv": 8.47, "trd": NaN, "batb": [[0, 5.3, 10], [1, 1.01, 7]], "batl": NaN}, {"timestamp": 1631538228943, "ltp": 5.7, "tv": 8.47, "trd": NaN, "batb": [[0, 1.01, 7], [1, 1.01, 0]], "batl": NaN}, {"timestamp": 1631538233852, "ltp": 5.7, "tv": 8.47, "trd": NaN, "batb": [[0, 6, 10], [1, 1.01, 7]], "batl": NaN}, {"timestamp": 1631538413788, "ltp": 5.7, "tv": 8.47, "trd": NaN, "batb": [[0, 1.01, 7], [1, 1.01, 0]], "batl": NaN}, {"timestamp": 1631538418825, "ltp": 5.7, "tv": 8.47, "trd": NaN, "batb": [[0, 5.8, 10], [1, 1.01, 7]], "batl": NaN}, {"timestamp": 1631538432919, "ltp": 5.7, "tv": 8.47, "trd": NaN, "batb": [[0, 1.01, 7], [1, 1.01, 0]], "batl": NaN}, {"timestamp": 1631538437850, "ltp": 5.7, "tv": 8.47, "trd": NaN, "batb": [[0, 5.3, 10], [1, 1.01, 7]], "batl": NaN}, {"timestamp": 1631538463203, "ltp": 5.7, "tv": 8.47, "trd": NaN, "batb": [[0, 1.01, 7], [1, 1.01, 0]], "batl": NaN}, {"timestamp": 1631538468259, "ltp": 5.7, "tv": 8.47, "trd": NaN, "batb": [[0, 5.8, 10], [1, 1.01, 7]], "batl": NaN}, {"timestamp": 1631538483640, "ltp": 5.7, "tv": 8.47, "trd": NaN, "batb": [[0, 1.01, 7], [1, 1.01, 0]], "batl": NaN}, {"timestamp": 1631538488555, "ltp": 5.7, "tv": 8.47, "trd": NaN, "batb": [[0, 4.8, 10], [1, 1.01, 7]], "batl": NaN}, {"timestamp": 1631538515374, "ltp": 5.7, "tv": 8.47, "trd": NaN, "batb": [[0, 1.01, 7], [1, 1.01, 0]], "batl": NaN}, {"timestamp": 1631538520287, "ltp": 5.7, "tv": 8.47, "trd": NaN, "batb": [[0, 4.3, 10], [1, 1.01, 7]], "batl": NaN}, {"timestamp": 1631538639207, "ltp": 5.7, "tv": 8.47, "trd": NaN, "batb": [[0, 1.01, 7], [1, 1.01, 0]], "batl": NaN}, {"timestamp": 1631538644260, "ltp": 5.7, "tv": 8.47, "trd": NaN, "batb": [[0, 4.8, 10], [1, 1.01, 7]], "batl": NaN}, {"timestamp": 1631538664162, "ltp": 5.7, "tv": 8.47, "trd": NaN, "batb": [[0, 1.01, 7], [1, 1.01, 0]], "batl": NaN}, {"timestamp": 1631538669159, "ltp": 5.7, "tv": 8.47, "trd": NaN, "batb": [[0, 5.8, 10], [1, 1.01, 7]], "batl": NaN}, {"timestamp": 1631538796527, "ltp": 5.7, "tv": 8.47, "trd": NaN, "batb": [[0, 1.01, 7], [1, 1.01, 0]], "batl": NaN}, {"timestamp": 1631538801526, "ltp": 5.7, "tv": 8.47, "trd": NaN, "batb": [[0, 5.3, 10], [1, 1.01, 7]], "batl": NaN}, {"timestamp": 1631538815679, "ltp": 5.7, "tv": 8.47, "trd": NaN, "batb": [[0, 1.01, 7], [1, 1.01, 0]], "batl": NaN}, {"timestamp": 1631538820569, "ltp": 5.7, "tv": 8.47, "trd": NaN, "batb": [[0, 4.8, 10], [1, 1.01, 7]], "batl": NaN}, {"timestamp": 1631538834107, "ltp": 5.7, "tv": 8.47, "trd": NaN, "batb": [[0, 1.01, 7], [1, 1.01, 0]], "batl": NaN}, {"timestamp": 1631538838913, "ltp": 5.7, "tv": 8.47, "trd": NaN, "batb": [[0, 5.3, 10], [1, 1.01, 7]], "batl": NaN}, {"timestamp": 1631538856719, "ltp": 5.7, "tv": 8.47, "trd": NaN, "batb": [[0, 1.01, 7], [1, 1.01, 0]], "batl": NaN}, {"timestamp": 1631538861646, "ltp": 5.7, "tv": 8.47, "trd": NaN, "batb": [[0, 6, 10], [1, 1.01, 7]], "batl": NaN}, {"timestamp": 1631538899034, "ltp": 5.7, "tv": 8.47, "trd": NaN, "batb": [[0, 1.01, 7], [1, 1.01, 0]], "batl": NaN}, {"timestamp": 1631538903950, "ltp": 5.7, "tv": 8.47, "trd": NaN, "batb": [[0, 4.8, 10], [1, 1.01, 7]], "batl": NaN}, {"timestamp": 1631538924886, "ltp": 5.7, "tv": 8.47, "trd": NaN, "batb": [[0, 1.01, 7], [1, 1.01, 0]], "batl": NaN}, {"timestamp": 1631538934986, "ltp": 5.7, "tv": 8.47, "trd": NaN, "batb": [[0, 4.8, 10], [1, 1.01, 7]], "batl": NaN}, {"timestamp": 1631538938109, "ltp": 5.7, "tv": 8.47, "trd": NaN, "batb": [[0, 1.01, 7], [1, 1.01, 0]], "batl": NaN}, {"timestamp": 1631538943026, "ltp": 5.7, "tv": 8.47, "trd": NaN, "batb": [[0, 6, 10], [1, 1.01, 7]], "batl": NaN}, {"timestamp": 1631538978871, "ltp": 5.7, "tv": 8.47, "trd": NaN, "batb": [[0, 1.01, 7], [1, 1.01, 0]], "batl": NaN}, {"timestamp": 1631538983773, "ltp": 5.7, "tv": 8.47, "trd": NaN, "batb": [[0, 7.6, 10], [1, 1.01, 7]], "batl": NaN}, {"timestamp": 1631539015462, "ltp": 5.7, "tv": 8.47, "trd": NaN, "batb": [[0, 1.01, 7], [1, 1.01, 0]], "batl": NaN}, {"timestamp": 1631539020480, "ltp": 5.7, "tv": 8.47, "trd": NaN, "batb": [[0, 8, 10], [1, 1.01, 7]], "batl": NaN}, {"timestamp": 1631539024482, "ltp": 5.7, "tv": 8.47, "trd": NaN, "batb": [[0, 1.01, 7], [1, 1.01, 0]], "batl": NaN}, {"timestamp": 1631539029202, "ltp": 5.7, "tv": 8.47, "trd": NaN, "batb": [[0, 10, 10], [1, 1.01, 7]], "batl": NaN}, {"timestamp": 1631539150308, "ltp": 5.7, "tv": 8.47, "trd": NaN, "batb": [[0, 1.01, 7], [1, 1.01, 0]], "batl": NaN}, {"timestamp": 1631539155202, "ltp": 5.7, "tv": 8.47, "trd": NaN, "batb": [[0, 8, 10], [1, 1.01, 7]], "batl": NaN}, {"timestamp": 1631539177146, "ltp": 5.7, "tv": 8.47, "trd": NaN, "batb": [[0, 1.01, 7], [1, 1.01, 0]], "batl": NaN}, {"timestamp": 1631539182051, "ltp": 5.7, "tv": 8.47, "trd": NaN, "batb": [[0, 9.6, 10], [1, 1.01, 7]], "batl": NaN}, {"timestamp": 1631539215991, "ltp": 5.7, "tv": 8.47, "trd": NaN, "batb": [[0, 1.01, 7], [1, 1.01, 0]], "batl": NaN}, {"timestamp": 1631539221029, "ltp": 5.7, "tv": 8.47, "trd": NaN, "batb": [[0, 12, 10], [1, 1.01, 7]], "batl": NaN}, {"timestamp": 1631539241462, "ltp": 5.7, "tv": 8.47, "trd": NaN, "batb": [[0, 1.01, 7], [1, 1.01, 0]], "batl": NaN}, {"timestamp": 1631539246257, "ltp": 5.7, "tv": 8.47, "trd": NaN, "batb": [[0, 11, 10], [1, 1.01, 7]], "batl": NaN}, {"timestamp": 1631539264494, "ltp": 5.7, "tv": 8.47, "trd": NaN, "batb": [[0, 1.01, 7], [1, 1.01, 0]], "batl": NaN}, {"timestamp": 1631539269404, "ltp": 5.7, "tv": 8.47, "trd": NaN, "batb": [[0, 9.6, 10], [1, 1.01, 7]], "batl": NaN}, {"timestamp": 1631539305579, "ltp": 9.6, "tv": 13.79, "trd": [[9.6, 5.32]], "batb": [[0, 1.01, 7], [1, 1.01, 0]], "batl": NaN}, {"timestamp": 1631539310468, "ltp": 9.6, "tv": 13.79, "trd": NaN, "batb": [[0, 9.6, 10], [1, 1.01, 7]], "batl": NaN}, {"timestamp": 1631539310781, "ltp": 9.6, "tv": 13.79, "trd": NaN, "batb": [[0, 1.01, 7], [1, 1.01, 0]], "batl": NaN}, {"timestamp": 1631539315704, "ltp": 9.6, "tv": 13.79, "trd": NaN, "batb": [[0, 7.6, 10], [1, 1.01, 7]], "batl": NaN}, {"timestamp": 1631539333212, "ltp": 9.6, "tv": 13.79, "trd": NaN, "batb": [[0, 1.01, 7], [1, 1.01, 0]], "batl": NaN}, {"timestamp": 1631539337640, "ltp": 9.6, "tv": 13.79, "trd": NaN, "batb": [[0, 5.3, 10], [1, 1.01, 7]], "batl": NaN}, {"timestamp": 1631539355335, "ltp": 5.7, "tv": 18.58, "trd": [[5.7, 6.17]], "batb": NaN, "batl": NaN}, {"timestamp": 1631539376013, "ltp": 5.7, "tv": 18.58, "trd": NaN, "batb": [[0, 1.01, 7], [1, 1.01, 0]], "batl": NaN}, {"timestamp": 1631539381594, "ltp": 5.7, "tv": 18.58, "trd": NaN, "batb": [[0, 4.8, 10], [1, 1.01, 7]], "batl": NaN}, {"timestamp": 1631539405571, "ltp": 5.7, "tv": 18.58, "trd": NaN, "batb": [[0, 1.01, 7], [1, 1.01, 0]], "batl": NaN}, {"timestamp": 1631539410507, "ltp": 5.7, "tv": 18.58, "trd": NaN, "batb": [[0, 4.1, 10], [1, 1.01, 7]], "batl": NaN}, {"timestamp": 1631539433848, "ltp": 5.7, "tv": 18.58, "trd": NaN, "batb": [[0, 1.01, 7], [1, 1.01, 0]], "batl": NaN}, {"timestamp": 1631539438856, "ltp": 5.7, "tv": 18.58, "trd": NaN, "batb": [[0, 3.95, 10.16], [1, 1.01, 7]], "batl": NaN}, {"timestamp": 1631539442947, "ltp": 5.7, "tv": 29.03, "trd": [[5.7, 16.62]], "batb": NaN, "batl": NaN}, {"timestamp": 1631539462166, "ltp": 5.7, "tv": 29.03, "trd": NaN, "batb": [[0, 1.01, 7], [1, 1.01, 0]], "batl": NaN}, {"timestamp": 1631539467072, "ltp": 5.7, "tv": 29.03, "trd": NaN, "batb": [[0, 4, 10], [1, 1.01, 7]], "batl": NaN}, {"timestamp": 1631539484701, "ltp": 5.7, "tv": 29.03, "trd": NaN, "batb": [[0, 1.01, 7], [1, 1.01, 0]], "batl": NaN}, {"timestamp": 1631539489721, "ltp": 5.7, "tv": 29.03, "trd": NaN, "batb": [[0, 4.3, 10], [1, 1.01, 7]], "batl": NaN}, {"timestamp": 1631539514447, "ltp": 5.7, "tv": 29.03, "trd": NaN, "batb": [[0, 1.01, 7], [1, 1.01, 0]], "batl": NaN}, {"timestamp": 1631539519575, "ltp": 5.8, "tv": 29.05, "trd": [[5.8, 0.02]], "batb": NaN, "batl": NaN}, {"timestamp": 1631539524545, "ltp": 5.8, "tv": 29.05, "trd": NaN, "batb": [[0, 5.8, 10], [1, 1.01, 7]], "batl": NaN}, {"timestamp": 1631539558813, "ltp": 5.8, "tv": 29.05, "trd": NaN, "batb": [[0, 1.01, 7], [1, 1.01, 0]], "batl": NaN}, {"timestamp": 1631539563831, "ltp": 5.8, "tv": 29.05, "trd": NaN, "batb": [[0, 4.3, 10], [1, 1.01, 7]], "batl": NaN}, {"timestamp": 1631539579266, "ltp": 5.8, "tv": 29.05, "trd": NaN, "batb": [[0, 1.01, 7], [1, 1.01, 0]], "batl": NaN}, {"timestamp": 1631539584288, "ltp": 5.8, "tv": 29.05, "trd": NaN, "batb": [[0, 5.8, 10], [1, 1.01, 7]], "batl": NaN}, {"timestamp": 1631539599201, "ltp": 5.8, "tv": 29.05, "trd": NaN, "batb": [[0, 1.01, 7], [1, 1.01, 0]], "batl": NaN}, {"timestamp": 1631539604102, "ltp": 5.8, "tv": 29.05, "trd": NaN, "batb": [[0, 4.3, 10], [1, 1.01, 7]], "batl": NaN}, {"timestamp": 1631539610932, "ltp": 5.8, "tv": 29.05, "trd": NaN, "batb": [[0, 1.01, 7], [1, 1.01, 0]], "batl": NaN}, {"timestamp": 1631539615918, "ltp": 5.8, "tv": 29.05, "trd": NaN, "batb": [[0, 4.8, 10], [1, 1.01, 7]], "batl": NaN}, {"timestamp": 1631539625539, "ltp": 5.8, "tv": 29.05, "trd": NaN, "batb": [[0, 1.01, 7], [1, 1.01, 0]], "batl": NaN}, {"timestamp": 1631539630468, "ltp": 5.8, "tv": 29.05, "trd": NaN, "batb": [[0, 3.7, 11.11], [1, 1.01, 7]], "batl": NaN}, {"timestamp": 1631539748599, "ltp": 5.8, "tv": 29.05, "trd": NaN, "batb": [[0, 1.01, 7], [1, 1.01, 0]], "batl": NaN}, {"timestamp": 1631539753501, "ltp": 5.8, "tv": 29.05, "trd": NaN, "batb": [[0, 3.15, 13.95], [1, 1.01, 7]], "batl": NaN}, {"timestamp": 1631539770229, "ltp": 5.8, "tv": 29.05, "trd": NaN, "batb": [[0, 1.01, 7], [1, 1.01, 0]], "batl": NaN}, {"timestamp": 1631539775132, "ltp": 5.8, "tv": 29.05, "trd": NaN, "batb": [[0, 3.7, 11.11], [1, 1.01, 7]], "batl": NaN}, {"timestamp": 1631539796466, "ltp": 5.8, "tv": 29.05, "trd": NaN, "batb": [[0, 1.01, 7], [1, 1.01, 0]], "batl": NaN}, {"timestamp": 1631539801496, "ltp": 5.8, "tv": 29.05, "trd": NaN, "batb": [[0, 4.1, 10], [1, 1.01, 7]], "batl": NaN}, {"timestamp": 1631539820694, "ltp": 5.8, "tv": 29.05, "trd": NaN, "batb": [[0, 1.01, 7], [1, 1.01, 0]], "batl": NaN}, {"timestamp": 1631539825738, "ltp": 5.8, "tv": 29.05, "trd": NaN, "batb": [[0, 4.8, 10], [1, 1.01, 7]], "batl": NaN}, {"timestamp": 1631539848680, "ltp": 5.8, "tv": 29.05, "trd": NaN, "batb": [[0, 1.01, 7], [1, 1.01, 0]], "batl": NaN}, {"timestamp": 1631539853941, "ltp": 5.8, "tv": 29.05, "trd": NaN, "batb": [[0, 5.3, 10], [1, 1.01, 7]], "batl": NaN}, {"timestamp": 1631539901866, "ltp": 5.8, "tv": 29.05, "trd": NaN, "batb": [[0, 1.01, 7], [1, 1.01, 0]], "batl": NaN}, {"timestamp": 1631539906871, "ltp": 5.8, "tv": 29.05, "trd": NaN, "batb": [[0, 4.3, 10], [1, 1.01, 7]], "batl": NaN}, {"timestamp": 1631539927267, "ltp": 5.8, "tv": 29.05, "trd": NaN, "batb": [[0, 1.01, 7], [1, 1.01, 0]], "batl": NaN}, {"timestamp": 1631539932317, "ltp": 5.8, "tv": 29.05, "trd": NaN, "batb": [[0, 4.1, 10], [1, 1.01, 7]], "batl": NaN}, {"timestamp": 1631539939531, "ltp": 5.8, "tv": 29.05, "trd": NaN, "batb": [[0, 1.01, 7], [1, 1.01, 0]], "batl": NaN}, {"timestamp": 1631539944548, "ltp": 5.8, "tv": 29.05, "trd": NaN, "batb": [[0, 3.4, 12.5], [1, 1.01, 7]], "batl": NaN}, {"timestamp": 1631539968980, "ltp": 5.8, "tv": 29.05, "trd": NaN, "batb": [[0, 1.01, 7], [1, 1.01, 0]], "batl": NaN}, {"timestamp": 1631539973877, "ltp": 5.8, "tv": 29.05, "trd": NaN, "batb": [[0, 4, 10], [1, 1.01, 7]], "batl": NaN}, {"timestamp": 1631540004508, "ltp": 5.8, "tv": 29.05, "trd": NaN, "batb": [[0, 1.01, 7], [1, 1.01, 0]], "batl": NaN}, {"timestamp": 1631540009441, "ltp": 5.8, "tv": 29.05, "trd": NaN, "batb": [[0, 4.8, 10], [1, 1.01, 7]], "batl": NaN}, {"timestamp": 1631540031173, "ltp": 5.8, "tv": 29.05, "trd": NaN, "batb": [[0, 1.01, 7], [1, 1.01, 0]], "batl": NaN}, {"timestamp": 1631540036071, "ltp": 5.8, "tv": 29.05, "trd": NaN, "batb": [[0, 4, 10], [1, 1.01, 7]], "batl": NaN}, {"timestamp": 1631540062904, "ltp": 5.8, "tv": 29.05, "trd": NaN, "batb": [[0, 1.01, 7], [1, 1.01, 0]], "batl": NaN}, {"timestamp": 1631540067823, "ltp": 5.8, "tv": 29.05, "trd": NaN, "batb": [[0, 3.95, 10.16], [1, 1.01, 7]], "batl": NaN}, {"timestamp": 1631540088165, "ltp": 5.8, "tv": 29.05, "trd": NaN, "batb": [[0, 1.01, 7], [1, 1.01, 0]], "batl": NaN}, {"timestamp": 1631540093083, "ltp": 5.8, "tv": 29.05, "trd": NaN, "batb": [[0, 4.8, 10], [1, 1.01, 7]], "batl": NaN}, {"timestamp": 1631540169081, "ltp": 5.8, "tv": 29.05, "trd": NaN, "batb": [[0, 1.01, 7], [1, 1.01, 0]], "batl": NaN}, {"timestamp": 1631540174064, "ltp": 5.8, "tv": 29.05, "trd": NaN, "batb": [[0, 6, 10], [1, 1.01, 7]], "batl": NaN}, {"timestamp": 1631540226099, "ltp": 5.8, "tv": 29.05, "trd": NaN, "batb": [[0, 1.01, 7], [1, 1.01, 0]], "batl": NaN}, {"timestamp": 1631540230962, "ltp": 5.8, "tv": 29.05, "trd": NaN, "batb": [[0, 8.6, 10], [1, 1.01, 7]], "batl": NaN}, {"timestamp": 1631540258015, "ltp": 5.8, "tv": 29.05, "trd": NaN, "batb": [[0, 1.01, 7], [1, 1.01, 0]], "batl": NaN}, {"timestamp": 1631540263044, "ltp": 5.8, "tv": 29.05, "trd": NaN, "batb": [[0, 11, 10], [1, 1.01, 7]], "batl": NaN}, {"timestamp": 1631540304027, "ltp": 5.8, "tv": 29.05, "trd": NaN, "batb": [[0, 1.01, 7], [1, 1.01, 0]], "batl": NaN}, {"timestamp": 1631540308926, "ltp": 5.8, "tv": 29.05, "trd": NaN, "batb": [[0, 14, 10], [1, 1.01, 7]], "batl": NaN}, {"timestamp": 1631540455280, "ltp": 5.8, "tv": 29.05, "trd": NaN, "batb": [[0, 1.01, 7], [1, 1.01, 0]], "batl": NaN}, {"timestamp": 1631540460190, "ltp": 5.8, "tv": 29.05, "trd": NaN, "batb": [[0, 16, 10], [1, 1.01, 7]], "batl": NaN}, {"timestamp": 1631540462408, "ltp": 5.8, "tv": 29.05, "trd": NaN, "batb": NaN, "batl": [[0, 170, 36.65]]}, {"timestamp": 1631540478843, "ltp": 5.8, "tv": 29.05, "trd": NaN, "batb": [[0, 1.01, 7], [1, 1.01, 0]], "batl": NaN}, {"timestamp": 1631540483752, "ltp": 5.8, "tv": 29.05, "trd": NaN, "batb": [[0, 19.5, 10], [1, 1.01, 7]], "batl": NaN}, {"timestamp": 1631540486735, "ltp": 5.8, "tv": 29.05, "trd": NaN, "batb": NaN, "batl": [[0, 340, 35.94]]}, {"timestamp": 1631540631871, "ltp": 5.8, "tv": 29.05, "trd": NaN, "batb": [[0, 1.01, 7], [1, 1.01, 0]], "batl": NaN}, {"timestamp": 1631540636750, "ltp": 5.8, "tv": 29.05, "trd": NaN, "batb": [[0, 16, 10], [1, 1.01, 7]], "batl": NaN}, {"timestamp": 1631540674511, "ltp": 5.8, "tv": 29.05, "trd": NaN, "batb": [[0, 1.01, 7], [1, 1.01, 0]], "batl": NaN}, {"timestamp": 1631540679512, "ltp": 5.8, "tv": 29.05, "trd": NaN, "batb": [[0, 14, 10], [1, 1.01, 7]], "batl": NaN}, {"timestamp": 1631540714882, "ltp": 5.8, "tv": 29.05, "trd": NaN, "batb": [[0, 1.01, 7], [1, 1.01, 0]], "batl": NaN}, {"timestamp": 1631540719721, "ltp": 5.8, "tv": 29.05, "trd": NaN, "batb": [[0, 12, 10], [1, 1.01, 7]], "batl": NaN}, {"timestamp": 1631540783822, "ltp": 5.8, "tv": 29.05, "trd": NaN, "batb": [[0, 1.01, 7], [1, 1.01, 0]], "batl": NaN}, {"timestamp": 1631540788820, "ltp": 5.8, "tv": 29.05, "trd": NaN, "batb": [[0, 10, 10], [1, 1.01, 7]], "batl": NaN}, {"timestamp": 1631540841298, "ltp": 5.8, "tv": 29.05, "trd": NaN, "batb": [[0, 1.01, 7], [1, 1.01, 0]], "batl": NaN}, {"timestamp": 1631540846187, "ltp": 5.8, "tv": 29.05, "trd": NaN, "batb": [[0, 11, 10], [1, 1.01, 7]], "batl": NaN}, {"timestamp": 1631540875243, "ltp": 5.8, "tv": 29.05, "trd": NaN, "batb": [[0, 1.01, 7], [1, 1.01, 0]], "batl": NaN}, {"timestamp": 1631540880178, "ltp": 5.8, "tv": 29.05, "trd": NaN, "batb": [[0, 14, 10], [1, 1.01, 7]], "batl": NaN}, {"timestamp": 1631540948569, "ltp": 5.8, "tv": 29.05, "trd": NaN, "batb": [[0, 1.01, 7], [1, 1.01, 0]], "batl": NaN}, {"timestamp": 1631540953573, "ltp": 5.8, "tv": 29.05, "trd": NaN, "batb": [[0, 16, 10], [1, 1.01, 7]], "batl": NaN}, {"timestamp": 1631540954878, "ltp": 5.8, "tv": 29.05, "trd": NaN, "batb": NaN, "batl": [[0, 170, 36.65]]}, {"timestamp": 1631541010479, "ltp": 16.0, "tv": 49.05, "trd": [[16, 20]], "batb": [[0, 1.01, 7], [1, 1.01, 0]], "batl": NaN}, {"timestamp": 1631541051252, "ltp": 16.0, "tv": 49.05, "trd": NaN, "batb": [[0, 14, 10], [1, 1.01, 7]], "batl": NaN}, {"timestamp": 1631541056660, "ltp": 16.0, "tv": 49.05, "trd": NaN, "batb": [[1, 1.02, 10], [2, 1.01, 7]], "batl": NaN}, {"timestamp": 1631541083890, "ltp": 16.0, "tv": 49.05, "trd": NaN, "batb": [[0, 1.02, 10], [1, 1.01, 7], [2, 1.01, 0]], "batl": NaN}, {"timestamp": 1631541088795, "ltp": 16.0, "tv": 49.05, "trd": NaN, "batb": [[0, 12, 10], [1, 1.02, 10], [2, 1.01, 7]], "batl": NaN}, {"timestamp": 1631541118273, "ltp": 16.0, "tv": 49.05, "trd": NaN, "batb": [[0, 1.02, 10], [1, 1.01, 7], [2, 1.01, 0]], "batl": NaN}, {"timestamp": 1631541123159, "ltp": 16.0, "tv": 49.05, "trd": NaN, "batb": [[0, 10, 10], [1, 1.02, 10], [2, 1.01, 7]], "batl": NaN}, {"timestamp": 1631541146419, "ltp": 16.0, "tv": 49.05, "trd": NaN, "batb": [[0, 1.02, 10], [1, 1.01, 7], [2, 1.01, 0]], "batl": NaN}, {"timestamp": 1631541151337, "ltp": 16.0, "tv": 49.05, "trd": NaN, "batb": [[0, 11, 10], [1, 1.02, 10], [2, 1.01, 7]], "batl": NaN}, {"timestamp": 1631541173634, "ltp": 16.0, "tv": 49.05, "trd": NaN, "batb": [[0, 1.02, 10], [1, 1.01, 7], [2, 1.01, 0]], "batl": NaN}, {"timestamp": 1631541178650, "ltp": 16.0, "tv": 49.05, "trd": NaN, "batb": [[0, 12, 10], [1, 1.02, 10], [2, 1.01, 7]], "batl": NaN}, {"timestamp": 1631541189344, "ltp": 16.0, "tv": 49.05, "trd": NaN, "batb": [[0, 1.02, 10], [1, 1.01, 7], [2, 1.01, 0]], "batl": NaN}, {"timestamp": 1631541194387, "ltp": 16.0, "tv": 49.05, "trd": NaN, "batb": [[0, 14, 10], [1, 1.02, 10], [2, 1.01, 7]], "batl": NaN}, {"timestamp": 1631541220988, "ltp": 16.0, "tv": 49.05, "trd": NaN, "batb": [[0, 1.02, 10], [1, 1.01, 7], [2, 1.01, 0]], "batl": NaN}, {"timestamp": 1631541225934, "ltp": 16.0, "tv": 49.05, "trd": NaN, "batb": [[0, 11, 10], [1, 1.02, 10], [2, 1.01, 7]], "batl": NaN}, {"timestamp": 1631541266475, "ltp": 16.0, "tv": 49.05, "trd": NaN, "batb": [[0, 1.02, 10], [1, 1.01, 7], [2, 1.01, 0]], "batl": NaN}, {"timestamp": 1631541271262, "ltp": 16.0, "tv": 49.05, "trd": NaN, "batb": [[0, 12, 10], [1, 1.02, 10], [2, 1.01, 7]], "batl": NaN}, {"timestamp": 1631541289304, "ltp": 16.0, "tv": 49.05, "trd": NaN, "batb": [[0, 1.02, 10], [1, 1.01, 7], [2, 1.01, 0]], "batl": NaN}, {"timestamp": 1631541294345, "ltp": 16.0, "tv": 49.05, "trd": NaN, "batb": [[0, 14, 10], [1, 1.02, 10], [2, 1.01, 7]], "batl": NaN}, {"timestamp": 1631541380171, "ltp": 14.0, "tv": 59.05, "trd": [[14, 10]], "batb": [[0, 1.02, 10], [1, 1.01, 7], [2, 1.01, 0]], "batl": NaN}, {"timestamp": 1631541406691, "ltp": 13.5, "tv": 69.05, "trd": [[13.5, 10]], "batb": NaN, "batl": NaN}, {"timestamp": 1631541409014, "ltp": 13.5, "tv": 69.05, "trd": NaN, "batb": NaN, "batl": [[0, 170, 36.65]]}, {"timestamp": 1631541451869, "ltp": 13.5, "tv": 71.05, "trd": [[13.5, 12]], "batb": NaN, "batl": NaN}, {"timestamp": 1631541534469, "ltp": 13.5, "tv": 73.76, "trd": [[13.5, 14.71]], "batb": [[0, 5, 10], [1, 1.02, 10], [2, 1.01, 7]], "batl": NaN}, {"timestamp": 1631541539287, "ltp": 13.5, "tv": 73.76, "trd": NaN, "batb": [[0, 14, 10], [1, 5, 10], [2, 1.02, 10]], "batl": NaN}, {"timestamp": 1631541542989, "ltp": 13.5, "tv": 73.76, "trd": NaN, "batb": [[1, 1.01, 7], [2, 1.02, 0]], "batl": NaN}, {"timestamp": 1631541559017, "ltp": 13.5, "tv": 73.76, "trd": NaN, "batb": [[0, 1.01, 7], [1, 1.01, 0]], "batl": NaN}, {"timestamp": 1631541563914, "ltp": 13.5, "tv": 73.76, "trd": NaN, "batb": [[0, 11, 10], [1, 1.01, 7]], "batl": NaN}, {"timestamp": 1631541580153, "ltp": 13.5, "tv": 73.76, "trd": NaN, "batb": [[0, 1.01, 7], [1, 1.01, 0]], "batl": NaN}, {"timestamp": 1631541585033, "ltp": 13.5, "tv": 73.76, "trd": NaN, "batb": [[0, 12, 10], [1, 1.01, 7]], "batl": NaN}, {"timestamp": 1631541630210, "ltp": 13.5, "tv": 73.76, "trd": NaN, "batb": [[0, 1.01, 7], [1, 1.01, 0]], "batl": NaN}, {"timestamp": 1631541635204, "ltp": 13.5, "tv": 73.76, "trd": NaN, "batb": [[0, 16, 10], [1, 1.01, 7]], "batl": NaN}, {"timestamp": 1631541638501, "ltp": 13.5, "tv": 73.76, "trd": NaN, "batb": NaN, "batl": [[0, 170, 36.65]]}, {"timestamp": 1631541669171, "ltp": 13.5, "tv": 73.76, "trd": NaN, "batb": [[0, 1.01, 7], [1, 1.01, 0]], "batl": NaN}, {"timestamp": 1631541674174, "ltp": 13.5, "tv": 73.76, "trd": NaN, "batb": [[0, 12, 10], [1, 1.01, 7]], "batl": NaN}, {"timestamp": 1631541701008, "ltp": 13.5, "tv": 73.76, "trd": NaN, "batb": [[0, 1.01, 7], [1, 1.01, 0]], "batl": NaN}, {"timestamp": 1631541705947, "ltp": 13.5, "tv": 73.76, "trd": NaN, "batb": [[0, 16, 10], [1, 1.01, 7]], "batl": NaN}, {"timestamp": 1631541708458, "ltp": 13.5, "tv": 73.76, "trd": NaN, "batb": NaN, "batl": [[0, 170, 36.65]]}, {"timestamp": 1631541732556, "ltp": 13.5, "tv": 73.76, "trd": NaN, "batb": [[0, 1.01, 7], [1, 1.01, 0]], "batl": NaN}, {"timestamp": 1631541737491, "ltp": 13.5, "tv": 73.76, "trd": NaN, "batb": [[0, 19.5, 10], [1, 1.01, 7]], "batl": NaN}, {"timestamp": 1631541777847, "ltp": 13.5, "tv": 73.76, "trd": NaN, "batb": [[0, 1.01, 7], [1, 1.01, 0]], "batl": NaN}, {"timestamp": 1631541782861, "ltp": 13.5, "tv": 73.76, "trd": NaN, "batb": [[0, 16, 10], [1, 1.01, 7]], "batl": NaN}, {"timestamp": 1631541785371, "ltp": 13.5, "tv": 73.76, "trd": NaN, "batb": NaN, "batl": [[0, 170, 36.65]]}, {"timestamp": 1631541818534, "ltp": 13.5, "tv": 73.76, "trd": NaN, "batb": [[0, 1.01, 7], [1, 1.01, 0]], "batl": NaN}, {"timestamp": 1631541823021, "ltp": 13.5, "tv": 73.76, "trd": NaN, "batb": [[0, 19.5, 10], [1, 1.01, 7]], "batl": NaN}, {"timestamp": 1631541875132, "ltp": 13.5, "tv": 73.76, "trd": NaN, "batb": [[0, 1.01, 7], [1, 1.01, 0]], "batl": NaN}, {"timestamp": 1631542070254, "ltp": 13.5, "tv": 73.76, "trd": NaN, "batb": [[0, 19.5, 10], [1, 1.01, 7]], "batl": NaN}, {"timestamp": 1631542110810, "ltp": 13.5, "tv": 73.76, "trd": NaN, "batb": [[0, 1.01, 7], [1, 1.01, 0]], "batl": NaN}, {"timestamp": 1631542849656, "ltp": 13.5, "tv": 73.76, "trd": NaN, "batb": [[0, 19.5, 10], [1, 1.01, 7]], "batl": NaN}, {"timestamp": 1631542859138, "ltp": 13.5, "tv": 73.76, "trd": NaN, "batb": [[0, 1.01, 7], [1, 1.01, 0]], "batl": NaN}, {"timestamp": 1631542864075, "ltp": 13.5, "tv": 73.76, "trd": NaN, "batb": [[0, 14, 10], [1, 1.01, 7]], "batl": NaN}, {"timestamp": 1631542942996, "ltp": 13.5, "tv": 73.76, "trd": NaN, "batb": [[0, 1.01, 7], [1, 1.01, 0]], "batl": NaN}, {"timestamp": 1631544270219, "ltp": 13.5, "tv": 73.76, "trd": NaN, "batb": [[0, 4, 10], [1, 1.01, 7]], "batl": NaN}, {"timestamp": 1631545548491, "ltp": 13.5, "tv": 73.79, "trd": [[5.7, 16.64], [12, 7.1]], "batb": [[0, 1.01, 7], [1, 1.01, 0]], "batl": NaN}, {"timestamp": 1631549087127, "ltp": 13.5, "tv": 73.79, "trd": NaN, "batb": [[0, 1.01, 12]], "batl": NaN}, {"timestamp": 1631549247663, "ltp": 3.75, "tv": 74.29, "trd": [[3.75, 0.5]], "batb": NaN, "batl": NaN}, {"timestamp": 1631549928373, "ltp": 3.75, "tv": 74.29, "trd": NaN, "batb": [[0, 14, 10], [1, 1.01, 12]], "batl": NaN}, {"timestamp": 1631549930262, "ltp": 3.75, "tv": 74.29, "trd": NaN, "batb": [[0, 1.01, 12], [1, 1.01, 0]], "batl": NaN}, {"timestamp": 1631549935197, "ltp": 3.75, "tv": 74.29, "trd": NaN, "batb": [[0, 11, 10], [1, 1.01, 12]], "batl": NaN}, {"timestamp": 1631549937695, "ltp": 3.75, "tv": 74.29, "trd": NaN, "batb": [[0, 1.01, 12], [1, 1.01, 0]], "batl": NaN}, {"timestamp": 1631549948015, "ltp": 3.75, "tv": 74.29, "trd": NaN, "batb": [[0, 19.5, 10], [1, 1.01, 12]], "batl": NaN}, {"timestamp": 1631549960453, "ltp": 3.75, "tv": 74.29, "trd": NaN, "batb": [[0, 1.01, 12], [1, 1.01, 0]], "batl": NaN}, {"timestamp": 1631549965415, "ltp": 3.75, "tv": 74.29, "trd": NaN, "batb": [[0, 14, 10], [1, 1.01, 12]], "batl": NaN}, {"timestamp": 1631550016582, "ltp": 3.75, "tv": 74.29, "trd": NaN, "batb": [[0, 1.01, 12], [1, 1.01, 0]], "batl": NaN}, {"timestamp": 1631550021633, "ltp": 3.75, "tv": 74.29, "trd": NaN, "batb": [[0, 10, 10], [1, 1.01, 12]], "batl": NaN}, {"timestamp": 1631550021803, "ltp": 3.75, "tv": 74.29, "trd": NaN, "batb": [[0, 1.01, 12], [1, 1.01, 0]], "batl": NaN}, {"timestamp": 1631550026835, "ltp": 3.75, "tv": 74.29, "trd": NaN, "batb": [[0, 19.5, 10], [1, 1.01, 12]], "batl": NaN}, {"timestamp": 1631550053852, "ltp": 3.75, "tv": 74.29, "trd": NaN, "batb": [[0, 1.01, 12], [1, 1.01, 0]], "batl": NaN}, {"timestamp": 1631550058763, "ltp": 3.75, "tv": 74.29, "trd": NaN, "batb": [[0, 14, 10], [1, 1.01, 12]], "batl": NaN}, {"timestamp": 1631550085008, "ltp": 3.75, "tv": 74.29, "trd": NaN, "batb": [[0, 1.01, 12], [1, 1.01, 0]], "batl": NaN}, {"timestamp": 1631550089928, "ltp": 3.75, "tv": 74.29, "trd": NaN, "batb": [[0, 19.5, 10], [1, 1.01, 12]], "batl": NaN}, {"timestamp": 1631550103539, "ltp": 3.75, "tv": 74.29, "trd": NaN, "batb": [[0, 1.01, 12], [1, 1.01, 0]], "batl": NaN}, {"timestamp": 1631550108543, "ltp": 3.75, "tv": 74.29, "trd": NaN, "batb": [[0, 24, 10], [1, 1.01, 12]], "batl": NaN}, {"timestamp": 1631550123863, "ltp": 3.75, "tv": 74.29, "trd": NaN, "batb": [[0, 1.01, 12], [1, 1.01, 0]], "batl": NaN}]}]}