{"info": {"id": "1.187557985", "eventId": "30896136", "eventName": "Match Odds", "marketType": "MATCH_ODDS", "openDate": 1631532303320, "name": "Krunic v Bandecchi", "numberOfActiveRunner": 2, "countryCode": "", "sport": "TENNIS", "venue": "", "volume": {"total": 120111.97, "preMatch": 1579.38, "inPlay": 118532.59}, "winner": {"id": 5300820, "name": "Aleksandra Krunic", "status": "WINNER", "position": 1}, "delay": 3}, "runners": [{"id": 5300820, "name": "Aleksandra Krunic", "status": "WINNER", "position": 1, "inPlayOdds": 1.47, "inPlayTime": 1631532303320, "avgPrematch": 1.49, "closedOdds": 1.01, "maxPrematch": 1.55, "minPrematch": 1.45, "maxInPlay": 3.55, "minInPlay": 1.01, "inPlayIndex": 74, "lengthOdds": 3244, "lengthOddsPrematch": 74, "lengthOddsInPlay": 3170, "tradedVolume": 97285.59, "preMatchVolume": 1292.49, "inPlayVolume": 95993.1}, {"id": 9629022, "name": "Susan Bandecchi", "status": "LOSER", "position": 2, "inPlayOdds": 3.05, "inPlayTime": 1631532303320, "avgPrematch": 2.85, "closedOdds": 15.0, "maxPrematch": 3.05, "minPrematch": 2.74, "maxInPlay": 100.0, "minInPlay": 1.38, "inPlayIndex": 62, "lengthOdds": 2681, "lengthOddsPrematch": 62, "lengthOddsInPlay": 2619, "tradedVolume": 22826.38, "preMatchVolume": 286.89, "inPlayVolume": 22539.49}], "marketUpdates": [{"timestamp": 1631463863807000000, "openDate": "2021-09-13T10:30:00.000Z", "status": "OPEN", "betDelay": 0, "inPlay": false, "complete": true}, {"timestamp": 1631529561629000000, "openDate": "2021-09-13T10:40:00.000Z", "status": "OPEN", "betDelay": 0, "inPlay": false, "complete": true}, {"timestamp": 1631529860132000000, "openDate": "2021-09-13T10:50:00.000Z", "status": "OPEN", "betDelay": 0, "inPlay": false, "complete": true}, {"timestamp": 1631530461500000000, "openDate": "2021-09-13T11:00:00.000Z", "status": "OPEN", "betDelay": 0, "inPlay": false, "complete": true}, {"timestamp": 1631530761306000000, "openDate": "2021-09-13T11:10:00.000Z", "status": "OPEN", "betDelay": 0, "inPlay": false, "complete": true}, {"timestamp": 1631531360656000000, "openDate": "2021-09-13T11:20:00.000Z", "status": "OPEN", "betDelay": 0, "inPlay": false, "complete": true}, {"timestamp": 1631531960570000000, "openDate": "2021-09-13T11:25:00.000Z", "status": "OPEN", "betDelay": 0, "inPlay": false, "complete": true}, {"timestamp": 1631532303320000000, "openDate": "2021-09-13T11:25:00.000Z", "status": "OPEN", "betDelay": 3, "inPlay": true, "complete": true}, {"timestamp": 1631532564411000000, "openDate": "2021-09-13T11:30:00.000Z", "status": "OPEN", "betDelay": 3, "inPlay": true, "complete": true}, {"timestamp": 1631539109079000000, "openDate": "2021-09-13T11:30:00.000Z", "status": "SUSPENDED", "betDelay": 3, "inPlay": true, "complete": true}, {"timestamp": 1631539162285000000, "openDate": "2021-09-13T11:30:00.000Z", "status": "CLOSED", "betDelay": 3, "inPlay": true, "complete": true}], "odds": [{"runnerId": 5300820, "odds": [{"timestamp": 1631513620509, "ltp": 1.45, "tv": 28.93, "trd": [[1.45, 28.94]], "batb": [[0, 1.45, 85.94]], "batl": NaN}, {"timestamp": 1631514662991, "ltp": 1.45, "tv": 28.93, "trd": NaN, "batb": [[2, 1.2, 219.96]], "batl": NaN}, {"timestamp": 1631514698228, "ltp": 1.54, "tv": 37.06, "trd": [[1.54, 8.13]], "batb": NaN, "batl": [[0, 1.55, 853.17], [1, 1.56, 853.17], [2, 1.57, 853.17]]}, {"timestamp": 1631514699251, "ltp": 1.55, "tv": 79.02, "trd": [[1.55, 41.96]], "batb": NaN, "batl": [[0, 1.55, 832.19]]}, {"timestamp": 1631516631606, "ltp": 1.55, "tv": 79.05, "trd": [[1.45, 28.96], [1.54, 8.13], [1.55, 41.97]], "batb": [[0, 1.47, 189.44], [1, 1.45, 85.95], [2, 1.44, 76.86]], "batl": [[0, 1.55, 832.33], [1, 1.56, 853.32], [2, 1.57, 853.32]]}, {"timestamp": 1631516642341, "ltp": 1.55, "tv": 79.05, "trd": NaN, "batb": [[0, 1.48, 23.33], [1, 1.47, 189.44], [2, 1.45, 4.27]], "batl": NaN}, {"timestamp": 1631518243131, "ltp": 1.48, "tv": 83.05, "trd": [[1.48, 4]], "batb": [[0, 1.48, 21.33]], "batl": NaN}, {"timestamp": 1631520541501, "ltp": 1.48, "tv": 83.05, "trd": NaN, "batb": NaN, "batl": [[0, 1.54, 853.32], [1, 1.55, 832.33], [2, 1.56, 853.32]]}, {"timestamp": 1631521424665, "ltp": 1.48, "tv": 83.05, "trd": NaN, "batb": NaN, "batl": [[0, 1.54, 853.84]]}, {"timestamp": 1631522358696, "ltp": 1.48, "tv": 83.05, "trd": NaN, "batb": NaN, "batl": [[0, 1.54, 853.32]]}, {"timestamp": 1631522583325, "ltp": 1.48, "tv": 83.05, "trd": NaN, "batb": [[0, 1.48, 210.77], [1, 1.45, 4.27], [2, 1.44, 94.92]], "batl": NaN}, {"timestamp": 1631522639604, "ltp": 1.48, "tv": 83.05, "trd": NaN, "batb": [[0, 1.48, 189.44]], "batl": NaN}, {"timestamp": 1631522639708, "ltp": 1.48, "tv": 83.05, "trd": NaN, "batb": [[1, 1.45, 89.44]], "batl": NaN}, {"timestamp": 1631523368876, "ltp": 1.48, "tv": 84.72, "trd": [[1.48, 5.67]], "batb": [[0, 1.48, 188.6]], "batl": NaN}, {"timestamp": 1631523408242, "ltp": 1.48, "tv": 84.72, "trd": NaN, "batb": [[2, 1.44, 100.92]], "batl": NaN}, {"timestamp": 1631523690415, "ltp": 1.48, "tv": 84.72, "trd": [[1.45, 28.95], [1.48, 5.67], [1.54, 8.13], [1.55, 41.97]], "batb": [[0, 1.48, 188.63], [1, 1.45, 89.45]], "batl": [[0, 1.54, 853.46], [1, 1.55, 832.47], [2, 1.56, 853.46]]}, {"timestamp": 1631523852331, "ltp": 1.48, "tv": 84.72, "trd": NaN, "batb": NaN, "batl": [[0, 1.54, 854.31]]}, {"timestamp": 1631524616367, "ltp": 1.48, "tv": 84.72, "trd": NaN, "batb": NaN, "batl": [[0, 1.54, 857.76]]}, {"timestamp": 1631525400457, "ltp": 1.48, "tv": 84.72, "trd": NaN, "batb": [[1, 1.46, 55.66], [2, 1.45, 89.45]], "batl": NaN}, {"timestamp": 1631525437531, "ltp": 1.48, "tv": 84.72, "trd": NaN, "batb": [[1, 1.47, 43.63], [2, 1.46, 55.66]], "batl": NaN}, {"timestamp": 1631525714700, "ltp": 1.48, "tv": 93.87, "trd": [[1.48, 14.82]], "batb": [[0, 1.48, 184.06]], "batl": NaN}, {"timestamp": 1631526978484, "ltp": 1.53, "tv": 94.73, "trd": [[1.53, 0.85]], "batb": NaN, "batl": [[0, 1.54, 856.9]]}, {"timestamp": 1631528132140, "ltp": 1.53, "tv": 94.73, "trd": NaN, "batb": [[1, 1.47, 62.11]], "batl": NaN}, {"timestamp": 1631528202559, "ltp": 1.54, "tv": 375.78, "trd": [[1.54, 289.18]], "batb": NaN, "batl": [[0, 1.54, 575.85]]}, {"timestamp": 1631528203592, "ltp": 1.54, "tv": 375.78, "trd": NaN, "batb": [[0, 1.49, 71.03], [1, 1.48, 184.06]], "batl": NaN}, {"timestamp": 1631528349939, "ltp": 1.54, "tv": 375.78, "trd": NaN, "batb": [[1, 1.46, 55.66], [2, 1.45, 4.27]], "batl": NaN}, {"timestamp": 1631528367563, "ltp": 1.49, "tv": 517.83, "trd": [[1.49, 142.05]], "batb": [[0, 1.47, 68.12]], "batl": [[0, 1.49, 195.36], [1, 1.54, 575.85], [2, 1.55, 832.47]]}, {"timestamp": 1631528368079, "ltp": 1.49, "tv": 517.83, "trd": NaN, "batb": [[1, 1.45, 4.27], [2, 1.44, 94.92]], "batl": NaN}, {"timestamp": 1631528368855, "ltp": 1.49, "tv": 874.57, "trd": [[1.49, 498.79]], "batb": NaN, "batl": [[0, 1.49, 16.99]]}, {"timestamp": 1631528397521, "ltp": 1.49, "tv": 874.57, "trd": NaN, "batb": [[1, 1.45, 15.74]], "batl": [[0, 1.48, 16.99]]}, {"timestamp": 1631528402104, "ltp": 1.47, "tv": 908.55, "trd": [[1.47, 33.98]], "batb": [[0, 1.47, 51.13], [1, 1.45, 72.64]], "batl": [[0, 1.54, 575.85], [1, 1.55, 832.47], [2, 1.56, 853.46]]}, {"timestamp": 1631528437191, "ltp": 1.47, "tv": 908.55, "trd": NaN, "batb": [[0, 1.46, 82.82]], "batl": NaN}, {"timestamp": 1631528448263, "ltp": 1.47, "tv": 908.55, "trd": NaN, "batb": [[0, 1.47, 85.35], [1, 1.46, 82.82], [2, 1.45, 72.64]], "batl": NaN}, {"timestamp": 1631528720177, "ltp": 1.47, "tv": 908.75, "trd": [[1.47, 34.18]], "batb": [[0, 1.47, 85.24]], "batl": NaN}, {"timestamp": 1631528751407, "ltp": 1.47, "tv": 908.75, "trd": NaN, "batb": [[0, 1.48, 31.97], [1, 1.47, 85.24], [2, 1.46, 138.48]], "batl": NaN}, {"timestamp": 1631528765349, "ltp": 1.47, "tv": 908.75, "trd": NaN, "batb": [[0, 1.49, 31.97]], "batl": NaN}, {"timestamp": 1631528995587, "ltp": 1.47, "tv": 908.75, "trd": NaN, "batb": NaN, "batl": [[0, 1.54, 577.85]]}, {"timestamp": 1631529213630, "ltp": 1.47, "tv": 908.75, "trd": NaN, "batb": [[1, 1.47, 87.24]], "batl": NaN}, {"timestamp": 1631529216944, "ltp": 1.47, "tv": 908.75, "trd": NaN, "batb": [[1, 1.47, 88.24]], "batl": NaN}, {"timestamp": 1631529222226, "ltp": 1.47, "tv": 908.75, "trd": NaN, "batb": [[1, 1.47, 86.24]], "batl": NaN}, {"timestamp": 1631529510557, "ltp": 1.54, "tv": 912.75, "trd": [[1.54, 293.18]], "batb": NaN, "batl": [[0, 1.54, 575.85]]}, {"timestamp": 1631529663567, "ltp": 1.54, "tv": 912.75, "trd": NaN, "batb": [[1, 1.47, 171.59]], "batl": NaN}, {"timestamp": 1631529809706, "ltp": 1.54, "tv": 912.75, "trd": NaN, "batb": NaN, "batl": [[0, 1.54, 572.41]]}, {"timestamp": 1631529815112, "ltp": 1.54, "tv": 912.75, "trd": NaN, "batb": NaN, "batl": [[0, 1.51, 3.44], [1, 1.54, 572.41], [2, 1.55, 832.47]]}, {"timestamp": 1631529816098, "ltp": 1.54, "tv": 912.75, "trd": NaN, "batb": [[2, 1.46, 82.82]], "batl": NaN}, {"timestamp": 1631530081114, "ltp": 1.54, "tv": 912.75, "trd": NaN, "batb": [[0, 1.5, 25], [1, 1.49, 31.97], [2, 1.47, 171.59]], "batl": NaN}, {"timestamp": 1631530086072, "ltp": 1.54, "tv": 912.75, "trd": NaN, "batb": [[2, 1.48, 29.84]], "batl": NaN}, {"timestamp": 1631530272414, "ltp": 1.49, "tv": 962.79, "trd": [[1.49, 498.81], [1.5, 50.01]], "batb": [[0, 1.49, 31.96], [1, 1.48, 29.84], [2, 1.47, 171.59]], "batl": [[0, 1.51, 430.17]]}, {"timestamp": 1631530274016, "ltp": 1.49, "tv": 962.79, "trd": NaN, "batb": NaN, "batl": [[1, 1.52, 426.73], [2, 1.54, 572.41]]}, {"timestamp": 1631530275308, "ltp": 1.49, "tv": 1026.69, "trd": [[1.49, 562.72]], "batb": [[0, 1.48, 29.84], [1, 1.47, 171.59], [2, 1.45, 72.64]], "batl": NaN}, {"timestamp": 1631530276397, "ltp": 1.49, "tv": 1026.69, "trd": NaN, "batb": [[2, 1.45, 15.74]], "batl": [[2, 1.53, 426.73]]}, {"timestamp": 1631530279828, "ltp": 1.49, "tv": 1026.69, "trd": NaN, "batb": NaN, "batl": [[0, 1.51, 426.73]]}, {"timestamp": 1631530284308, "ltp": 1.49, "tv": 1026.69, "trd": NaN, "batb": NaN, "batl": [[0, 1.49, 3.44], [1, 1.51, 426.73], [2, 1.52, 426.73]]}, {"timestamp": 1631530444600, "ltp": 1.48, "tv": 1031.82, "trd": [[1.48, 19.94]], "batb": [[0, 1.47, 171.59], [1, 1.46, 83.41]], "batl": NaN}, {"timestamp": 1631530458604, "ltp": 1.48, "tv": 1031.82, "trd": NaN, "batb": [[0, 1.47, 182.15]], "batl": NaN}, {"timestamp": 1631530459632, "ltp": 1.48, "tv": 1031.82, "trd": NaN, "batb": [[1, 1.46, 94.13]], "batl": NaN}, {"timestamp": 1631530630119, "ltp": 1.48, "tv": 1034.48, "trd": [[1.48, 22.61]], "batb": NaN, "batl": NaN}, {"timestamp": 1631530740193, "ltp": 1.48, "tv": 1034.48, "trd": NaN, "batb": [[0, 1.47, 171.59], [1, 1.46, 83.41]], "batl": NaN}, {"timestamp": 1631530758500, "ltp": 1.48, "tv": 1034.48, "trd": NaN, "batb": [[0, 1.47, 182.85], [1, 1.46, 94.7]], "batl": NaN}, {"timestamp": 1631531100348, "ltp": 1.48, "tv": 1032.45, "trd": [[1.45, 28.91], [1.47, 34.11], [1.48, 22.57], [1.49, 561.54], [1.5, 49.97], [1.53, 0.85], [1.54, 292.61], [1.55, 41.89]], "batb": [[0, 1.47, 182.52], [1, 1.46, 94.54], [2, 1.45, 27.09]], "batl": [[0, 1.49, 3.44], [1, 1.51, 425.89], [2, 1.52, 425.89]]}, {"timestamp": 1631531159111, "ltp": 1.48, "tv": 1032.45, "trd": NaN, "batb": NaN, "batl": [[1, 1.5, 100], [2, 1.51, 425.89]]}, {"timestamp": 1631531340227, "ltp": 1.48, "tv": 1032.45, "trd": NaN, "batb": [[0, 1.47, 171.26], [1, 1.46, 83.25], [2, 1.45, 15.71]], "batl": NaN}, {"timestamp": 1631531357533, "ltp": 1.48, "tv": 1032.45, "trd": NaN, "batb": [[0, 1.47, 180.01]], "batl": [[1, 1.5, 108.63]]}, {"timestamp": 1631531357735, "ltp": 1.48, "tv": 1032.45, "trd": NaN, "batb": [[1, 1.46, 92.05]], "batl": [[2, 1.51, 434.57]]}, {"timestamp": 1631531739887, "ltp": 1.47, "tv": 1260.74, "trd": [[1.47, 262.4]], "batb": [[0, 1.47, 65.86], [2, 1.45, 25.1]], "batl": NaN}, {"timestamp": 1631531749537, "ltp": 1.47, "tv": 1261.91, "trd": [[1.47, 263.57]], "batb": [[0, 1.47, 65.27]], "batl": NaN}, {"timestamp": 1631531940162, "ltp": 1.47, "tv": 1261.91, "trd": NaN, "batb": [[0, 1.47, 56.52], [1, 1.46, 83.25], [2, 1.45, 15.71]], "batl": [[1, 1.5, 100], [2, 1.51, 425.89]]}, {"timestamp": 1631531949657, "ltp": 1.47, "tv": 1288.15, "trd": [[1.47, 289.81]], "batb": [[0, 1.47, 43.41]], "batl": NaN}, {"timestamp": 1631531957678, "ltp": 1.47, "tv": 1288.15, "trd": NaN, "batb": [[1, 1.46, 92.42]], "batl": [[1, 1.5, 109.04]]}, {"timestamp": 1631532013529, "ltp": 1.47, "tv": 1292.49, "trd": [[1.47, 294.15]], "batb": [[0, 1.47, 41.24], [2, 1.45, 24.92]], "batl": [[2, 1.51, 434.97]]}, {"timestamp": 1631532029588, "ltp": 1.47, "tv": 1292.49, "trd": NaN, "batb": [[0, 1.47, 135.88]], "batl": NaN}, {"timestamp": 1631532185769, "ltp": 1.47, "tv": 1292.49, "trd": NaN, "batb": [[1, 1.46, 9.17]], "batl": NaN}, {"timestamp": 1631532240232, "ltp": 1.47, "tv": 1292.49, "trd": NaN, "batb": [[0, 1.47, 126.41], [1, 1.45, 15.71], [2, 1.44, 283.62]], "batl": [[1, 1.5, 100], [2, 1.51, 425.89]]}, {"timestamp": 1631532285955, "ltp": 1.47, "tv": 1292.49, "trd": NaN, "batb": [[2, 1.44, 188.7]], "batl": NaN}, {"timestamp": 1631532303320, "ltp": 1.47, "tv": 1292.49, "trd": NaN, "batb": [[0, 1.45, 4.26], [1, 1.27, 2.17], [2, 1.2, 2]], "batl": [[0, 1.5, 100], [1, 1.51, 425.89], [2, 1.52, 425.89]]}, {"timestamp": 1631532306517, "ltp": 1.47, "tv": 1292.49, "trd": NaN, "batb": NaN, "batl": [[0, 1.5, 105]]}, {"timestamp": 1631532306677, "ltp": 1.47, "tv": 1292.49, "trd": NaN, "batb": NaN, "batl": [[0, 1.5, 100]]}, {"timestamp": 1631532320509, "ltp": 1.51, "tv": 1818.39, "trd": [[1.5, 149.97], [1.51, 425.89]], "batb": NaN, "batl": [[0, 1.52, 425.89], [1, 1.53, 425.89], [2, 1.54, 569.29]]}, {"timestamp": 1631532322485, "ltp": 1.51, "tv": 1818.39, "trd": NaN, "batb": [[0, 1.51, 55.87], [1, 1.5, 231.58], [2, 1.45, 4.26]], "batl": NaN}, {"timestamp": 1631532323625, "ltp": 1.51, "tv": 1818.39, "trd": NaN, "batb": [[0, 1.51, 130.24], [1, 1.5, 371.4], [2, 1.46, 1165.88]], "batl": NaN}, {"timestamp": 1631532324505, "ltp": 1.51, "tv": 1818.39, "trd": NaN, "batb": [[0, 1.51, 83.76], [1, 1.5, 301.49], [2, 1.45, 4.26]], "batl": NaN}, {"timestamp": 1631532325329, "ltp": 1.52, "tv": 1834.15, "trd": [[1.52, 15.77]], "batb": [[0, 1.51, 79.37], [1, 1.5, 231.58]], "batl": [[0, 1.52, 415.13]]}, {"timestamp": 1631532326212, "ltp": 1.52, "tv": 2623.58, "trd": [[1.52, 805.19]], "batb": [[0, 1.51, 5], [1, 1.5, 161.67]], "batl": [[0, 1.53, 425.89], [1, 1.54, 569.29], [2, 1.55, 956.36]]}, {"timestamp": 1631532329429, "ltp": 1.53, "tv": 3490.1, "trd": [[1.53, 867.38]], "batb": [[0, 1.53, 31.51], [1, 1.51, 5], [2, 1.5, 161.67]], "batl": [[0, 1.54, 569.29], [1, 1.55, 956.36], [2, 1.56, 851.79]]}, {"timestamp": 1631532332465, "ltp": 1.53, "tv": 3529.72, "trd": [[1.53, 907]], "batb": [[0, 1.53, 204.24], [1, 1.52, 177.18], [2, 1.51, 5]], "batl": NaN}, {"timestamp": 1631532338240, "ltp": 1.53, "tv": 3529.72, "trd": NaN, "batb": [[0, 1.45, 4.26], [1, 1.44, 191.21], [2, 1.27, 2.17]], "batl": NaN}, {"timestamp": 1631532341435, "ltp": 1.53, "tv": 3529.72, "trd": NaN, "batb": [[0, 1.45, 9.26], [1, 1.44, 199.21]], "batl": NaN}, {"timestamp": 1631532344643, "ltp": 1.53, "tv": 3529.72, "trd": NaN, "batb": [[0, 1.47, 7], [1, 1.46, 7], [2, 1.45, 9.26]], "batl": NaN}, {"timestamp": 1631532345162, "ltp": 1.53, "tv": 3529.72, "trd": NaN, "batb": [[0, 1.52, 160.31], [1, 1.51, 181.6], [2, 1.47, 7]], "batl": [[2, 1.56, 1055.75]]}, {"timestamp": 1631532346832, "ltp": 1.53, "tv": 3529.72, "trd": NaN, "batb": [[0, 1.47, 7], [1, 1.46, 7], [2, 1.45, 9.26]], "batl": [[2, 1.56, 851.79]]}, {"timestamp": 1631532349831, "ltp": 1.53, "tv": 3529.72, "trd": NaN, "batb": [[0, 1.47, 153.63], [1, 1.46, 215.49]], "batl": NaN}, {"timestamp": 1631532357462, "ltp": 1.53, "tv": 3529.72, "trd": NaN, "batb": [[0, 1.47, 146.63], [1, 1.46, 208.49], [2, 1.45, 4.26]], "batl": NaN}, {"timestamp": 1631532358450, "ltp": 1.53, "tv": 3529.72, "trd": NaN, "batb": NaN, "batl": [[0, 1.53, 100], [1, 1.54, 569.29], [2, 1.55, 956.36]]}, {"timestamp": 1631532359480, "ltp": 1.47, "tv": 3557.12, "trd": [[1.47, 321.55]], "batb": [[0, 1.47, 132.93]], "batl": [[0, 1.51, 298.05], [1, 1.52, 1432.88], [2, 1.53, 1321.22]]}, {"timestamp": 1631532360469, "ltp": 1.47, "tv": 3557.12, "trd": NaN, "batb": [[0, 1.46, 208.49], [1, 1.45, 4.26], [2, 1.44, 191.21]], "batl": NaN}, {"timestamp": 1631532363596, "ltp": 1.47, "tv": 3557.12, "trd": NaN, "batb": [[0, 1.46, 348.57], [1, 1.45, 220.53]], "batl": NaN}, {"timestamp": 1631532367697, "ltp": 1.46, "tv": 3571.12, "trd": [[1.46, 14]], "batb": [[0, 1.46, 341.57]], "batl": NaN}, {"timestamp": 1631532375587, "ltp": 1.46, "tv": 3571.12, "trd": NaN, "batb": [[0, 1.45, 4.26], [1, 1.43, 2377.09], [2, 1.38, 231.96]], "batl": [[0, 1.53, 100], [1, 1.54, 569.29], [2, 1.55, 956.36]]}, {"timestamp": 1631532375896, "ltp": 1.46, "tv": 3571.12, "trd": NaN, "batb": [[1, 1.38, 231.96], [2, 1.27, 2.17]], "batl": NaN}, {"timestamp": 1631532378490, "ltp": 1.46, "tv": 3571.12, "trd": NaN, "batb": [[1, 1.4, 200.84], [2, 1.39, 259.63]], "batl": NaN}, {"timestamp": 1631532378699, "ltp": 1.46, "tv": 3571.12, "trd": NaN, "batb": [[1, 1.38, 231.96], [2, 1.27, 2.17]], "batl": NaN}, {"timestamp": 1631532381290, "ltp": 1.46, "tv": 3571.12, "trd": NaN, "batb": [[0, 1.45, 268.94], [1, 1.44, 222.19], [2, 1.38, 231.96]], "batl": [[0, 1.49, 224.9], [1, 1.5, 184.58], [2, 1.53, 100]]}, {"timestamp": 1631532383620, "ltp": 1.46, "tv": 3571.12, "trd": NaN, "batb": [[0, 1.45, 4.26], [1, 1.38, 231.96], [2, 1.27, 2.17]], "batl": [[0, 1.53, 100], [1, 1.54, 569.29], [2, 1.55, 956.36]]}, {"timestamp": 1631532386528, "ltp": 1.46, "tv": 3571.12, "trd": NaN, "batb": [[1, 1.4, 200.84], [2, 1.39, 259.63]], "batl": NaN}, {"timestamp": 1631532391013, "ltp": 1.46, "tv": 3571.12, "trd": NaN, "batb": [[1, 1.38, 231.96], [2, 1.27, 2.17]], "batl": NaN}, {"timestamp": 1631532393635, "ltp": 1.53, "tv": 3771.12, "trd": [[1.53, 1107]], "batb": NaN, "batl": [[0, 1.54, 569.29], [1, 1.55, 956.36], [2, 1.56, 851.79]]}, {"timestamp": 1631532394628, "ltp": 1.53, "tv": 3771.12, "trd": NaN, "batb": [[0, 1.53, 227.46], [1, 1.52, 177.3], [2, 1.5, 161.5]], "batl": NaN}, {"timestamp": 1631532395302, "ltp": 1.53, "tv": 3797.62, "trd": [[1.53, 1133.5]], "batb": [[0, 1.53, 214.21]], "batl": NaN}, {"timestamp": 1631532396137, "ltp": 1.53, "tv": 3797.62, "trd": NaN, "batb": [[1, 1.52, 184.3], [2, 1.51, 5]], "batl": NaN}, {"timestamp": 1631532398632, "ltp": 1.53, "tv": 3797.62, "trd": NaN, "batb": NaN, "batl": [[2, 1.56, 932.99]]}, {"timestamp": 1631532398841, "ltp": 1.53, "tv": 3797.62, "trd": NaN, "batb": NaN, "batl": [[2, 1.56, 851.79]]}, {"timestamp": 1631532407473, "ltp": 1.53, "tv": 3797.62, "trd": NaN, "batb": [[0, 1.49, 2781.35], [1, 1.45, 11.26], [2, 1.44, 192.8]], "batl": NaN}, {"timestamp": 1631532408253, "ltp": 1.53, "tv": 3797.62, "trd": NaN, "batb": [[0, 1.45, 11.26], [1, 1.44, 192.8], [2, 1.27, 2.17]], "batl": NaN}, {"timestamp": 1631532410344, "ltp": 1.53, "tv": 3797.62, "trd": NaN, "batb": [[0, 1.46, 219.31], [1, 1.45, 226.63], [2, 1.44, 192.8]], "batl": NaN}, {"timestamp": 1631532411434, "ltp": 1.53, "tv": 3797.62, "trd": NaN, "batb": [[0, 1.45, 11.26], [1, 1.44, 198.8], [2, 1.27, 2.17]], "batl": NaN}, {"timestamp": 1631532415082, "ltp": 1.53, "tv": 3797.62, "trd": NaN, "batb": [[0, 1.52, 137.95], [1, 1.51, 181.58], [2, 1.45, 11.26]], "batl": [[2, 1.56, 1077.48]]}, {"timestamp": 1631532416074, "ltp": 1.53, "tv": 3797.62, "trd": NaN, "batb": [[0, 1.45, 11.26], [1, 1.44, 198.8], [2, 1.27, 2.17]], "batl": [[2, 1.56, 851.79]]}, {"timestamp": 1631532419067, "ltp": 1.53, "tv": 3797.62, "trd": NaN, "batb": [[0, 1.46, 219.31], [1, 1.45, 226.63], [2, 1.44, 198.8]], "batl": NaN}, {"timestamp": 1631532425145, "ltp": 1.53, "tv": 3797.62, "trd": NaN, "batb": [[2, 1.44, 192.8]], "batl": [[0, 1.52, 2.32], [1, 1.54, 569.29], [2, 1.55, 956.36]]}, {"timestamp": 1631532431558, "ltp": 1.53, "tv": 3797.62, "trd": NaN, "batb": [[0, 1.45, 11.26], [1, 1.44, 192.8], [2, 1.27, 2.17]], "batl": NaN}, {"timestamp": 1631532433485, "ltp": 1.56, "tv": 6177.39, "trd": [[1.52, 807.52], [1.54, 861.91], [1.55, 998.26], [1.56, 851.79]], "batb": NaN, "batl": [[0, 1.57, 851.79], [1, 1.58, 851.79], [2, 1.6, 851.79]]}, {"timestamp": 1631532434584, "ltp": 1.6, "tv": 8196.81, "trd": [[1.57, 851.79], [1.58, 851.79], [1.6, 315.84]], "batb": [[0, 1.59, 148.76], [1, 1.45, 11.26], [2, 1.44, 192.8]], "batl": [[0, 1.6, 693.87], [1, 1.62, 851.79], [2, 1.65, 237.01]]}, {"timestamp": 1631532435572, "ltp": 1.59, "tv": 8222.61, "trd": [[1.59, 25.8]], "batb": [[0, 1.59, 135.86], [1, 1.56, 138.66], [2, 1.51, 159.16]], "batl": [[2, 1.65, 129.79]]}, {"timestamp": 1631532436454, "ltp": 1.59, "tv": 8222.61, "trd": NaN, "batb": [[2, 1.55, 250.63]], "batl": NaN}, {"timestamp": 1631532437486, "ltp": 1.59, "tv": 8222.61, "trd": NaN, "batb": [[1, 1.57, 6], [2, 1.56, 144.66]], "batl": NaN}, {"timestamp": 1631532438174, "ltp": 1.59, "tv": 8222.61, "trd": NaN, "batb": [[0, 1.59, 206.98], [1, 1.58, 152.91], [2, 1.57, 6]], "batl": [[2, 1.64, 193.02]]}, {"timestamp": 1631532448579, "ltp": 1.6, "tv": 8227.26, "trd": [[1.6, 320.49]], "batb": NaN, "batl": [[0, 1.6, 691.54]]}, {"timestamp": 1631532451201, "ltp": 1.6, "tv": 8227.26, "trd": NaN, "batb": [[0, 1.51, 159.16], [1, 1.45, 4.26], [2, 1.27, 2.17]], "batl": [[2, 1.64, 0]]}, {"timestamp": 1631532454391, "ltp": 1.6, "tv": 8227.26, "trd": NaN, "batb": [[0, 1.53, 263.31], [1, 1.52, 178], [2, 1.51, 165.16]], "batl": [[2, 1.69, 123.81]]}, {"timestamp": 1631532456371, "ltp": 1.6, "tv": 8227.26, "trd": NaN, "batb": NaN, "batl": [[1, 1.62, 425.89]]}, {"timestamp": 1631532457577, "ltp": 1.6, "tv": 8227.26, "trd": NaN, "batb": [[0, 1.51, 165.16], [1, 1.5, 7], [2, 1.45, 4.26]], "batl": NaN}, {"timestamp": 1631532460632, "ltp": 1.62, "tv": 9344.7, "trd": [[1.6, 1012.03], [1.62, 425.89]], "batb": [[0, 1.64, 226.64], [1, 1.63, 136.22], [2, 1.51, 165.16]], "batl": [[0, 1.69, 123.81], [1, 1.71, 231.16], [2, 1.69, 0]]}, {"timestamp": 1631532461615, "ltp": 1.64, "tv": 9389.03, "trd": [[1.64, 44.33]], "batb": [[0, 1.64, 198.97], [2, 1.61, 123.93]], "batl": NaN}, {"timestamp": 1631532462610, "ltp": 1.64, "tv": 9786.97, "trd": [[1.64, 442.27]], "batb": [[0, 1.63, 136.22], [1, 1.62, 56.34]], "batl": [[0, 1.64, 226.93], [1, 1.71, 0]]}, {"timestamp": 1631532463597, "ltp": 1.64, "tv": 9786.97, "trd": NaN, "batb": [[1, 1.62, 97.5], [2, 1.61, 128.93]], "batl": NaN}, {"timestamp": 1631532464598, "ltp": 1.64, "tv": 9786.97, "trd": NaN, "batb": [[0, 1.63, 140.22], [1, 1.62, 50.55]], "batl": NaN}, {"timestamp": 1631532465531, "ltp": 1.64, "tv": 9786.97, "trd": NaN, "batb": [[0, 1.63, 242.27], [1, 1.62, 144.74]], "batl": [[1, 1.68, 126.12], [2, 1.7, 236.51]]}, {"timestamp": 1631532471885, "ltp": 1.64, "tv": 9786.97, "trd": NaN, "batb": NaN, "batl": [[0, 1.64, 56.57]]}, {"timestamp": 1631532474504, "ltp": 1.63, "tv": 9844.97, "trd": [[1.63, 58]], "batb": [[0, 1.63, 213.27]], "batl": NaN}, {"timestamp": 1631532474813, "ltp": 1.63, "tv": 9858.96, "trd": [[1.63, 72]], "batb": [[0, 1.63, 206.27]], "batl": NaN}, {"timestamp": 1631532478236, "ltp": 1.63, "tv": 9858.96, "trd": NaN, "batb": [[0, 1.63, 222.38], [1, 1.62, 139.74], [2, 1.61, 123.93]], "batl": [[1, 1.68, 141.66]]}, {"timestamp": 1631532481212, "ltp": 1.63, "tv": 9858.96, "trd": NaN, "batb": NaN, "batl": [[0, 1.68, 141.66], [1, 1.7, 236.51], [2, 1.7, 0]]}, {"timestamp": 1631532498133, "ltp": 1.63, "tv": 9858.96, "trd": NaN, "batb": [[0, 1.63, 4], [1, 1.61, 123.93], [2, 1.6, 2271.44]], "batl": NaN}, {"timestamp": 1631532500936, "ltp": 1.63, "tv": 9858.96, "trd": NaN, "batb": NaN, "batl": [[0, 1.79, 174.19], [1, 1.81, 191.82], [2, 2.24, 302.67]]}, {"timestamp": 1631532502359, "ltp": 1.63, "tv": 9858.96, "trd": NaN, "batb": [[2, 1.57, 140.05]], "batl": NaN}, {"timestamp": 1631532525379, "ltp": 1.63, "tv": 9858.96, "trd": NaN, "batb": NaN, "batl": [[2, 2.24, 0]]}, {"timestamp": 1631532531487, "ltp": 1.63, "tv": 9858.96, "trd": NaN, "batb": [[0, 1.61, 123.93], [1, 1.57, 140.05], [2, 1.56, 160.79]], "batl": NaN}, {"timestamp": 1631532531694, "ltp": 1.63, "tv": 9858.96, "trd": NaN, "batb": [[0, 1.57, 140.05], [1, 1.56, 160.79], [2, 1.55, 141.67]], "batl": NaN}, {"timestamp": 1631532534275, "ltp": 1.63, "tv": 9858.96, "trd": NaN, "batb": [[0, 1.55, 141.67], [1, 1.5, 7], [2, 1.45, 4.26]], "batl": [[0, 1.63, 2.32], [1, 1.81, 0]]}, {"timestamp": 1631532534896, "ltp": 1.63, "tv": 9858.96, "trd": NaN, "batb": NaN, "batl": [[1, 1.74, 5]]}, {"timestamp": 1631532537583, "ltp": 1.65, "tv": 9868.25, "trd": [[1.63, 76.64], [1.65, 4.64]], "batb": [[0, 1.65, 193.83], [1, 1.64, 133.54], [2, 1.55, 141.67]], "batl": [[0, 1.7, 141.41], [1, 1.72, 227.27], [2, 1.74, 5]]}, {"timestamp": 1631532539290, "ltp": 1.65, "tv": 9872.89, "trd": [[1.65, 9.29]], "batb": [[0, 1.65, 191.51]], "batl": NaN}, {"timestamp": 1631532540376, "ltp": 1.65, "tv": 9872.89, "trd": NaN, "batb": [[0, 1.55, 141.67], [1, 1.5, 7], [2, 1.45, 4.26]], "batl": [[0, 1.7, 4], [1, 1.74, 5], [2, 1.74, 0]]}, {"timestamp": 1631532543761, "ltp": 1.65, "tv": 9872.89, "trd": NaN, "batb": [[0, 1.57, 136.01], [1, 1.56, 160.79], [2, 1.55, 141.67]], "batl": [[2, 1.79, 177.71]]}, {"timestamp": 1631532545003, "ltp": 1.65, "tv": 9872.89, "trd": NaN, "batb": NaN, "batl": [[2, 1.79, 0]]}, {"timestamp": 1631532546662, "ltp": 1.65, "tv": 9872.89, "trd": NaN, "batb": NaN, "batl": [[0, 1.6, 3926.88], [1, 1.66, 17.98], [2, 1.7, 4]]}, {"timestamp": 1631532547488, "ltp": 1.57, "tv": 9898.87, "trd": [[1.57, 877.77]], "batb": [[0, 1.56, 160.79], [1, 1.55, 141.67], [2, 1.5, 7]], "batl": [[0, 1.7, 4], [1, 1.74, 5], [2, 1.7, 0]]}, {"timestamp": 1631532548572, "ltp": 1.57, "tv": 9898.87, "trd": NaN, "batb": [[2, 1.5, 168.75]], "batl": [[0, 1.61, 165.92], [1, 1.62, 139.24], [2, 1.7, 4]]}, {"timestamp": 1631532550593, "ltp": 1.57, "tv": 9898.87, "trd": NaN, "batb": [[0, 1.56, 290.52], [1, 1.55, 307.21]], "batl": [[2, 1.69, 244.44]]}, {"timestamp": 1631532550698, "ltp": 1.57, "tv": 9898.87, "trd": NaN, "batb": NaN, "batl": [[2, 1.69, 6]]}, {"timestamp": 1631532552296, "ltp": 1.57, "tv": 9898.87, "trd": NaN, "batb": [[2, 1.5, 161.75]], "batl": NaN}, {"timestamp": 1631532555088, "ltp": 1.57, "tv": 9898.87, "trd": NaN, "batb": [[0, 1.58, 20.68], [1, 1.56, 290.52], [2, 1.55, 307.21]], "batl": NaN}, {"timestamp": 1631532558300, "ltp": 1.61, "tv": 9903.52, "trd": [[1.61, 4.64]], "batb": NaN, "batl": [[0, 1.61, 163.6], [2, 1.67, 34.5]]}, {"timestamp": 1631532562501, "ltp": 1.61, "tv": 9903.52, "trd": NaN, "batb": [[1, 1.5, 161.75], [2, 1.45, 4.26]], "batl": [[0, 1.67, 34.5], [1, 1.69, 6], [2, 1.7, 33.55]]}, {"timestamp": 1631532562709, "ltp": 1.61, "tv": 9903.52, "trd": NaN, "batb": NaN, "batl": [[0, 1.69, 6], [1, 1.71, 33.5], [2, 2.04, 388.3]]}, {"timestamp": 1631532564411, "ltp": 1.61, "tv": 9903.52, "trd": NaN, "batb": [[1, 1.54, 48.12], [2, 1.5, 161.75]], "batl": NaN}, {"timestamp": 1631532565297, "ltp": 1.61, "tv": 9903.52, "trd": NaN, "batb": [[2, 1.51, 255.23]], "batl": [[1, 1.7, 195.13], [2, 1.71, 33.5]]}, {"timestamp": 1631532566228, "ltp": 1.61, "tv": 9903.52, "trd": NaN, "batb": [[2, 1.5, 161.75]], "batl": [[0, 1.67, 5], [1, 1.69, 6]]}, {"timestamp": 1631532568614, "ltp": 1.61, "tv": 9903.52, "trd": NaN, "batb": NaN, "batl": [[1, 1.68, 4], [2, 1.69, 6]]}, {"timestamp": 1631532569132, "ltp": 1.61, "tv": 9903.52, "trd": NaN, "batb": [[1, 1.56, 291.84], [2, 1.55, 165.55]], "batl": [[0, 1.61, 171.64], [1, 1.62, 139.24], [2, 1.67, 5]]}, {"timestamp": 1631532571254, "ltp": 1.61, "tv": 9903.52, "trd": NaN, "batb": [[1, 1.54, 48.12], [2, 1.5, 161.75]], "batl": [[0, 1.67, 5], [1, 1.68, 4], [2, 1.69, 6]]}, {"timestamp": 1631532571931, "ltp": 1.61, "tv": 9903.52, "trd": NaN, "batb": [[0, 1.54, 48.12], [1, 1.5, 161.75], [2, 1.45, 4.26]], "batl": NaN}, {"timestamp": 1631532574126, "ltp": 1.61, "tv": 9903.52, "trd": NaN, "batb": [[1, 1.51, 255.23], [2, 1.5, 350.26]], "batl": NaN}, {"timestamp": 1631532575012, "ltp": 1.61, "tv": 9903.52, "trd": NaN, "batb": [[0, 1.61, 20.68], [1, 1.54, 48.12], [2, 1.51, 255.23]], "batl": NaN}, {"timestamp": 1631532576621, "ltp": 1.67, "tv": 9908.16, "trd": [[1.67, 4.64]], "batb": NaN, "batl": [[0, 1.67, 2.68]]}, {"timestamp": 1631532579419, "ltp": 1.67, "tv": 9908.16, "trd": NaN, "batb": NaN, "batl": [[0, 1.68, 4], [1, 1.71, 33.5], [2, 2.04, 388.3]]}, {"timestamp": 1631532581648, "ltp": 1.54, "tv": 9976.02, "trd": [[1.54, 888.41], [1.61, 46]], "batb": [[0, 1.54, 34.87], [1, 1.51, 255.23], [2, 1.5, 350.26]], "batl": [[0, 1.56, 293.08], [1, 1.57, 155.71], [2, 1.61, 20.5]]}, {"timestamp": 1631532582533, "ltp": 1.54, "tv": 9976.02, "trd": NaN, "batb": NaN, "batl": [[2, 1.68, 4]]}, {"timestamp": 1631532584455, "ltp": 1.54, "tv": 9976.02, "trd": NaN, "batb": NaN, "batl": [[2, 1.67, 4]]}, {"timestamp": 1631532587853, "ltp": 1.54, "tv": 9976.02, "trd": NaN, "batb": NaN, "batl": [[0, 1.56, 419.08]]}, {"timestamp": 1631532595554, "ltp": 1.54, "tv": 9976.02, "trd": NaN, "batb": [[0, 1.46, 179.08], [1, 1.45, 4.26], [2, 1.38, 454.63]], "batl": [[0, 1.67, 4], [1, 1.68, 4], [2, 1.71, 33.5]]}, {"timestamp": 1631532595803, "ltp": 1.54, "tv": 9976.02, "trd": NaN, "batb": NaN, "batl": [[2, 2.04, 388.3]]}, {"timestamp": 1631532598506, "ltp": 1.54, "tv": 9976.02, "trd": NaN, "batb": [[0, 1.5, 7], [1, 1.49, 6], [2, 1.46, 186.08]], "batl": [[1, 2.04, 388.3], [2, 2.04, 0]]}, {"timestamp": 1631532598712, "ltp": 1.54, "tv": 9976.02, "trd": NaN, "batb": NaN, "batl": [[0, 1.64, 4], [1, 1.67, 4], [2, 2.04, 388.3]]}, {"timestamp": 1631532601649, "ltp": 1.54, "tv": 9976.02, "trd": NaN, "batb": [[2, 1.47, 6]], "batl": NaN}, {"timestamp": 1631532602119, "ltp": 1.54, "tv": 9976.02, "trd": NaN, "batb": [[0, 1.52, 277.01], [1, 1.51, 183.6], [2, 1.5, 7]], "batl": [[0, 1.57, 253.74], [1, 1.58, 152.24], [2, 1.64, 4]]}, {"timestamp": 1631532604646, "ltp": 1.54, "tv": 9976.02, "trd": NaN, "batb": [[1, 1.51, 188.6]], "batl": NaN}, {"timestamp": 1631532604757, "ltp": 1.54, "tv": 9976.02, "trd": NaN, "batb": [[0, 1.51, 5], [1, 1.5, 7], [2, 1.49, 6]], "batl": [[0, 1.64, 4], [1, 1.67, 4], [2, 2.04, 388.3]]}, {"timestamp": 1631532607947, "ltp": 1.54, "tv": 9976.02, "trd": NaN, "batb": NaN, "batl": [[0, 1.62, 223.54], [1, 1.63, 136], [2, 1.64, 4]]}, {"timestamp": 1631532610630, "ltp": 1.54, "tv": 9976.02, "trd": NaN, "batb": [[0, 1.57, 220.99], [1, 1.56, 161.17], [2, 1.51, 5]], "batl": [[2, 1.65, 637.5]]}, {"timestamp": 1631532611642, "ltp": 1.57, "tv": 10002.0, "trd": [[1.57, 903.75]], "batb": [[0, 1.57, 208], [1, 1.56, 301.25]], "batl": NaN}, {"timestamp": 1631532613582, "ltp": 1.57, "tv": 10002.0, "trd": NaN, "batb": [[1, 1.56, 306.25], [2, 1.55, 7]], "batl": NaN}, {"timestamp": 1631532623548, "ltp": 1.57, "tv": 10002.0, "trd": NaN, "batb": [[0, 1.5, 160.33], [1, 1.45, 4.26], [2, 1.4, 7]], "batl": [[0, 2.04, 388.3], [1, 1.63, 0], [2, 1.65, 0]]}, {"timestamp": 1631532626529, "ltp": 1.57, "tv": 10002.0, "trd": NaN, "batb": [[0, 1.51, 225.65], [1, 1.5, 348.71], [2, 1.45, 4.26]], "batl": [[0, 1.72, 226.22], [1, 1.74, 218.3], [2, 2.04, 388.3]]}, {"timestamp": 1631532626742, "ltp": 1.57, "tv": 10002.0, "trd": NaN, "batb": [[1, 1.5, 353.71], [2, 1.49, 7]], "batl": [[0, 1.67, 5], [1, 1.72, 226.22], [2, 1.74, 218.3]]}, {"timestamp": 1631532628151, "ltp": 1.57, "tv": 10002.0, "trd": NaN, "batb": NaN, "batl": [[1, 2.04, 388.3], [2, 1.74, 0]]}, {"timestamp": 1631532630188, "ltp": 1.57, "tv": 10002.0, "trd": NaN, "batb": [[0, 1.51, 230.65]], "batl": NaN}, {"timestamp": 1631532631453, "ltp": 1.51, "tv": 10028.66, "trd": [[1.51, 452.55]], "batb": [[0, 1.51, 217.32]], "batl": [[0, 1.55, 161.99], [1, 1.56, 1386.14], [2, 1.57, 1189.9]]}, {"timestamp": 1631532637566, "ltp": 1.51, "tv": 10028.66, "trd": NaN, "batb": [[0, 1.51, 264.31], [1, 1.5, 402.63]], "batl": NaN}, {"timestamp": 1631532639959, "ltp": 1.51, "tv": 10069.16, "trd": [[1.51, 493.05]], "batb": [[0, 1.51, 244.06], [1, 1.5, 397.63], [2, 1.48, 710.72]], "batl": NaN}, {"timestamp": 1631532642556, "ltp": 1.51, "tv": 10069.16, "trd": NaN, "batb": [[2, 1.46, 178.66]], "batl": [[1, 1.56, 160.18], [2, 1.6, 42.51]]}, {"timestamp": 1631532643593, "ltp": 1.51, "tv": 10069.16, "trd": NaN, "batb": [[0, 1.5, 48.92], [1, 1.46, 178.66], [2, 1.45, 4.26]], "batl": [[0, 1.64, 43.68], [1, 1.66, 5], [2, 1.67, 5]]}, {"timestamp": 1631532646614, "ltp": 1.51, "tv": 10069.16, "trd": NaN, "batb": NaN, "batl": [[0, 1.61, 5], [1, 1.64, 47.68], [2, 1.66, 5]]}, {"timestamp": 1631532650193, "ltp": 1.51, "tv": 10069.16, "trd": NaN, "batb": [[0, 1.52, 222.92], [1, 1.51, 183.45], [2, 1.5, 48.92]], "batl": [[0, 1.56, 149.85], [1, 1.57, 156.51], [2, 1.61, 5]]}, {"timestamp": 1631532653575, "ltp": 1.51, "tv": 10069.16, "trd": NaN, "batb": [[0, 1.5, 48.92], [1, 1.46, 178.66], [2, 1.45, 4.26]], "batl": [[0, 1.61, 5], [1, 1.64, 47.68], [2, 1.66, 5]]}, {"timestamp": 1631532656591, "ltp": 1.51, "tv": 10069.16, "trd": NaN, "batb": [[0, 1.51, 48.99], [1, 1.5, 48.92], [2, 1.46, 178.66]], "batl": [[0, 1.61, 162.67], [1, 1.62, 139.39], [2, 1.64, 47.68]]}, {"timestamp": 1631532657209, "ltp": 1.51, "tv": 10069.16, "trd": NaN, "batb": [[0, 1.5, 48.92], [1, 1.46, 178.66], [2, 1.45, 4.26]], "batl": NaN}, {"timestamp": 1631532658610, "ltp": 1.51, "tv": 10069.16, "trd": NaN, "batb": [[0, 1.57, 145.15], [1, 1.56, 160.97], [2, 1.5, 48.92]], "batl": [[0, 1.61, 157.67], [2, 1.63, 1173.32]]}, {"timestamp": 1631532659596, "ltp": 1.57, "tv": 10095.3, "trd": [[1.57, 929.89]], "batb": [[0, 1.57, 132.08], [1, 1.56, 300.88]], "batl": NaN}, {"timestamp": 1631532661480, "ltp": 1.57, "tv": 10095.3, "trd": NaN, "batb": [[2, 1.55, 5]], "batl": NaN}, {"timestamp": 1631532675621, "ltp": 1.57, "tv": 10095.3, "trd": NaN, "batb": [[0, 1.54, 48.62], [1, 1.51, 56.99], [2, 1.5, 48.92]], "batl": [[0, 1.64, 43.68], [1, 1.66, 32.75], [2, 1.7, 31.65]]}, {"timestamp": 1631532675927, "ltp": 1.57, "tv": 10095.3, "trd": NaN, "batb": [[0, 1.51, 56.99], [1, 1.49, 164.93], [2, 1.45, 4.26]], "batl": [[0, 1.7, 31.65], [1, 2.04, 388.3], [2, 1.7, 0]]}, {"timestamp": 1631532678527, "ltp": 1.57, "tv": 10095.3, "trd": NaN, "batb": [[1, 1.5, 176.19], [2, 1.49, 358.4]], "batl": [[1, 1.72, 129.45], [2, 1.74, 218.83]]}, {"timestamp": 1631532679622, "ltp": 1.57, "tv": 10095.3, "trd": NaN, "batb": [[1, 1.5, 5], [2, 1.49, 164.93]], "batl": [[0, 1.7, 36.65], [1, 2.04, 388.3], [2, 1.74, 0]]}, {"timestamp": 1631532682525, "ltp": 1.57, "tv": 10095.3, "trd": NaN, "batb": [[0, 1.54, 48.12], [1, 1.51, 56.99], [2, 1.5, 5]], "batl": [[0, 1.66, 37.25], [1, 1.67, 4], [2, 1.7, 36.65]]}, {"timestamp": 1631532682834, "ltp": 1.57, "tv": 10095.3, "trd": NaN, "batb": [[0, 1.59, 133.27], [1, 1.58, 153.29], [2, 1.51, 56.99]], "batl": [[0, 1.63, 146.23], [1, 1.64, 133.44], [2, 1.66, 5]]}, {"timestamp": 1631532685425, "ltp": 1.57, "tv": 10095.3, "trd": NaN, "batb": [[0, 1.51, 56.99], [1, 1.5, 5], [2, 1.49, 164.93]], "batl": [[0, 1.66, 5], [1, 1.67, 4], [2, 1.7, 36.65]]}, {"timestamp": 1631532687804, "ltp": 1.57, "tv": 10095.3, "trd": NaN, "batb": [[1, 1.5, 181.19], [2, 1.49, 358.4]], "batl": NaN}, {"timestamp": 1631532692516, "ltp": 1.57, "tv": 10095.3, "trd": NaN, "batb": [[1, 1.49, 164.93], [2, 1.45, 4.26]], "batl": NaN}, {"timestamp": 1631532693244, "ltp": 1.67, "tv": 10193.37, "trd": [[1.66, 82.05], [1.67, 20.66]], "batb": NaN, "batl": [[0, 1.7, 36.65], [1, 1.72, 129.45], [2, 1.74, 218.83]]}, {"timestamp": 1631532694538, "ltp": 1.67, "tv": 10193.37, "trd": NaN, "batb": NaN, "batl": [[0, 1.7, 31.65]]}, {"timestamp": 1631532695613, "ltp": 1.67, "tv": 10222.86, "trd": [[1.67, 50.15]], "batb": [[0, 1.67, 172.15], [1, 1.66, 127.92], [2, 1.65, 112.97]], "batl": NaN}, {"timestamp": 1631532698352, "ltp": 1.67, "tv": 10222.86, "trd": NaN, "batb": [[2, 1.65, 116.97]], "batl": NaN}, {"timestamp": 1631532714361, "ltp": 1.67, "tv": 10222.86, "trd": NaN, "batb": [[0, 1.58, 45.56], [1, 1.56, 137.65], [2, 1.53, 54.33]], "batl": [[0, 1.84, 32.03], [1, 1.91, 27.5], [2, 2.04, 388.3]]}, {"timestamp": 1631532714673, "ltp": 1.67, "tv": 10222.86, "trd": NaN, "batb": [[0, 1.56, 137.65], [1, 1.53, 54.33], [2, 1.52, 7]], "batl": [[0, 1.91, 27.5], [1, 2.04, 388.3], [2, 2.04, 0]]}, {"timestamp": 1631532717585, "ltp": 1.67, "tv": 10222.86, "trd": NaN, "batb": NaN, "batl": [[0, 1.84, 5], [1, 1.91, 27.5], [2, 2.04, 388.3]]}, {"timestamp": 1631532718461, "ltp": 1.67, "tv": 10222.86, "trd": NaN, "batb": [[0, 1.57, 236.92], [1, 1.56, 299.07], [2, 1.53, 54.33]], "batl": [[1, 1.85, 4], [2, 1.9, 4]]}, {"timestamp": 1631532721577, "ltp": 1.57, "tv": 10248.84, "trd": [[1.57, 955.87]], "batb": [[0, 1.57, 223.93]], "batl": [[0, 1.6, 1762.5], [1, 1.62, 209.25], [2, 1.63, 136.21]]}, {"timestamp": 1631532728093, "ltp": 1.6, "tv": 10252.84, "trd": [[1.6, 1016.03]], "batb": [[2, 1.54, 48.62]], "batl": [[0, 1.6, 1760.5]]}, {"timestamp": 1631532738526, "ltp": 1.6, "tv": 10252.84, "trd": NaN, "batb": [[0, 1.54, 48.62], [1, 1.53, 54.33], [2, 1.52, 7]], "batl": [[0, 1.66, 40.25], [1, 1.7, 34.15], [2, 1.83, 4]]}, {"timestamp": 1631532738734, "ltp": 1.6, "tv": 10252.84, "trd": NaN, "batb": [[0, 1.51, 50.99], [1, 1.5, 161.92], [2, 1.45, 4.26]], "batl": [[0, 1.7, 34.15], [1, 1.83, 4], [2, 1.91, 27.5]]}, {"timestamp": 1631532741532, "ltp": 1.6, "tv": 10252.84, "trd": NaN, "batb": [[1, 1.5, 425.32], [2, 1.49, 194.08]], "batl": [[1, 1.73, 156.97], [2, 1.75, 214.65]]}, {"timestamp": 1631532742516, "ltp": 1.6, "tv": 10252.84, "trd": NaN, "batb": [[0, 1.51, 57.99], [1, 1.5, 167.92], [2, 1.45, 4.26]], "batl": [[0, 1.66, 5], [1, 1.67, 5], [2, 1.7, 39.15]]}, {"timestamp": 1631532745626, "ltp": 1.6, "tv": 10252.84, "trd": NaN, "batb": [[0, 1.59, 223.94], [1, 1.58, 153.7], [2, 1.54, 47.12]], "batl": [[0, 1.64, 192.75], [1, 1.65, 130.5], [2, 1.66, 44.25]]}, {"timestamp": 1631532745723, "ltp": 1.6, "tv": 10252.84, "trd": NaN, "batb": [[2, 1.51, 57.99]], "batl": [[2, 1.66, 5]]}, {"timestamp": 1631532747315, "ltp": 1.6, "tv": 10252.84, "trd": NaN, "batb": [[0, 1.51, 57.99], [1, 1.5, 167.92], [2, 1.45, 4.26]], "batl": [[0, 1.66, 5], [1, 1.67, 5], [2, 1.7, 39.15]]}, {"timestamp": 1631532750249, "ltp": 1.6, "tv": 10252.84, "trd": NaN, "batb": [[1, 1.5, 431.32], [2, 1.49, 194.08]], "batl": NaN}, {"timestamp": 1631532756175, "ltp": 1.6, "tv": 10252.84, "trd": NaN, "batb": [[1, 1.5, 425.32]], "batl": [[1, 1.7, 34.15], [2, 1.73, 156.97]]}, {"timestamp": 1631532759600, "ltp": 1.6, "tv": 10252.84, "trd": NaN, "batb": [[1, 1.5, 429.32]], "batl": NaN}, {"timestamp": 1631532759704, "ltp": 1.6, "tv": 10252.84, "trd": NaN, "batb": [[1, 1.5, 165.92], [2, 1.45, 4.26]], "batl": NaN}, {"timestamp": 1631532761087, "ltp": 1.67, "tv": 10267.33, "trd": [[1.66, 92.05], [1.67, 54.64]], "batb": NaN, "batl": [[0, 1.7, 34.15], [1, 1.73, 156.97], [2, 1.75, 214.65]]}, {"timestamp": 1631532762603, "ltp": 1.67, "tv": 10267.33, "trd": NaN, "batb": [[0, 1.65, 1172.03], [1, 1.64, 1125], [2, 1.63, 1125]], "batl": NaN}, {"timestamp": 1631532763589, "ltp": 1.68, "tv": 10292.17, "trd": [[1.68, 24.84]], "batb": [[0, 1.68, 137.67], [1, 1.67, 125.16], [2, 1.66, 110.71]], "batl": NaN}, {"timestamp": 1631532764472, "ltp": 1.68, "tv": 10292.17, "trd": NaN, "batb": [[0, 1.68, 142.67], [1, 1.67, 129.16]], "batl": NaN}, {"timestamp": 1631532765613, "ltp": 1.68, "tv": 10292.17, "trd": NaN, "batb": [[2, 1.66, 116.71]], "batl": NaN}, {"timestamp": 1631532776394, "ltp": 1.68, "tv": 10292.17, "trd": NaN, "batb": [[0, 1.65, 2096.71], [1, 1.59, 42.11], [2, 1.58, 134.14]], "batl": [[0, 1.91, 27.5], [1, 2.04, 388.3], [2, 810, 0.07]]}, {"timestamp": 1631532777591, "ltp": 1.68, "tv": 10292.17, "trd": NaN, "batb": [[0, 1.58, 134.14], [1, 1.54, 47.12], [2, 1.52, 5]], "batl": NaN}, {"timestamp": 1631532779618, "ltp": 1.68, "tv": 10292.17, "trd": NaN, "batb": NaN, "batl": [[0, 1.84, 34.03], [1, 1.85, 4], [2, 1.9, 4]]}, {"timestamp": 1631532780499, "ltp": 1.68, "tv": 10292.17, "trd": NaN, "batb": NaN, "batl": [[0, 1.84, 4]]}, {"timestamp": 1631532782325, "ltp": 1.68, "tv": 10292.17, "trd": NaN, "batb": NaN, "batl": [[2, 1.89, 4]]}, {"timestamp": 1631532783213, "ltp": 1.68, "tv": 10292.17, "trd": NaN, "batb": [[0, 1.7, 234.08], [1, 1.68, 243.88], [2, 1.58, 134.14]], "batl": [[0, 1.76, 161.48], [1, 1.78, 202.89], [2, 1.84, 31.03]]}, {"timestamp": 1631532784615, "ltp": 1.68, "tv": 10292.17, "trd": NaN, "batb": [[0, 1.59, 48.11], [1, 1.58, 134.14], [2, 1.54, 47.12]], "batl": [[0, 1.84, 4], [1, 1.85, 4], [2, 1.89, 4]]}, {"timestamp": 1631532785340, "ltp": 1.68, "tv": 10292.17, "trd": NaN, "batb": [[0, 1.58, 134.14], [1, 1.54, 47.12], [2, 1.52, 5]], "batl": NaN}, {"timestamp": 1631532787113, "ltp": 1.68, "tv": 10292.17, "trd": NaN, "batb": [[0, 1.58, 304.97], [1, 1.57, 157.29], [2, 1.54, 47.12]], "batl": [[2, 1.89, 141.48]]}, {"timestamp": 1631532788216, "ltp": 1.68, "tv": 10292.17, "trd": NaN, "batb": NaN, "batl": [[0, 1.83, 4], [1, 1.84, 4], [2, 1.85, 4]]}, {"timestamp": 1631532791643, "ltp": 1.68, "tv": 10292.17, "trd": NaN, "batb": NaN, "batl": [[1, 1.89, 141.48], [2, 1.91, 189.52]]}, {"timestamp": 1631532794646, "ltp": 1.68, "tv": 10292.17, "trd": NaN, "batb": NaN, "batl": [[1, 1.84, 30.78], [2, 1.89, 4]]}, {"timestamp": 1631532795633, "ltp": 1.68, "tv": 10292.17, "trd": NaN, "batb": NaN, "batl": [[1, 1.89, 4], [2, 1.91, 27.5]]}, {"timestamp": 1631532797655, "ltp": 1.58, "tv": 10318.15, "trd": [[1.58, 877.77]], "batb": [[0, 1.58, 291.98], [2, 1.55, 678.63]], "batl": [[0, 1.63, 272.56], [1, 1.64, 133.16], [2, 1.65, 1159.1]]}, {"timestamp": 1631532799270, "ltp": 1.58, "tv": 10318.15, "trd": NaN, "batb": [[0, 1.59, 34.69], [1, 1.58, 291.98], [2, 1.57, 157.29]], "batl": NaN}, {"timestamp": 1631532809155, "ltp": 1.58, "tv": 10318.15, "trd": NaN, "batb": NaN, "batl": [[0, 1.63, 257.58]]}, {"timestamp": 1631532822661, "ltp": 1.58, "tv": 10318.15, "trd": NaN, "batb": [[0, 1.55, 40.99], [1, 1.54, 47.12], [2, 1.52, 55.24]], "batl": [[0, 1.72, 38.66], [1, 1.83, 4], [2, 1.91, 27.5]]}, {"timestamp": 1631532822868, "ltp": 1.58, "tv": 10318.15, "trd": NaN, "batb": [[0, 1.52, 55.24], [1, 1.5, 160.92], [2, 1.45, 4.26]], "batl": NaN}, {"timestamp": 1631532825407, "ltp": 1.58, "tv": 10318.15, "trd": NaN, "batb": [[1, 1.51, 169.58], [2, 1.5, 349.25]], "batl": [[1, 1.74, 176.01], [2, 1.76, 210.57]]}, {"timestamp": 1631532826506, "ltp": 1.58, "tv": 10318.15, "trd": NaN, "batb": [[0, 1.52, 50.24], [1, 1.5, 160.92], [2, 1.45, 4.26]], "batl": [[0, 1.71, 6], [1, 1.72, 38.66], [2, 1.83, 4]]}, {"timestamp": 1631532828582, "ltp": 1.58, "tv": 10318.15, "trd": NaN, "batb": NaN, "batl": [[0, 1.63, 18.77], [1, 1.71, 6], [2, 1.72, 43.66]]}, {"timestamp": 1631532829611, "ltp": 1.58, "tv": 10318.15, "trd": NaN, "batb": [[0, 1.6, 171.16], [1, 1.59, 149.91], [2, 1.52, 50.24]], "batl": [[0, 1.65, 229.5], [1, 1.66, 127.66], [2, 1.68, 47.64]]}, {"timestamp": 1631532830492, "ltp": 1.58, "tv": 10318.15, "trd": NaN, "batb": [[2, 1.55, 50.59]], "batl": [[2, 1.68, 5]]}, {"timestamp": 1631532832410, "ltp": 1.58, "tv": 10318.15, "trd": NaN, "batb": [[0, 1.55, 50.59], [1, 1.52, 50.24], [2, 1.5, 160.92]], "batl": [[0, 1.68, 5], [1, 1.69, 5], [2, 1.71, 6]]}, {"timestamp": 1631532833608, "ltp": 1.58, "tv": 10318.15, "trd": NaN, "batb": [[0, 1.61, 126.6]], "batl": NaN}, {"timestamp": 1631532833814, "ltp": 1.58, "tv": 10318.15, "trd": NaN, "batb": [[0, 1.52, 50.24], [1, 1.5, 160.92], [2, 1.45, 4.26]], "batl": NaN}, {"timestamp": 1631532835317, "ltp": 1.58, "tv": 10318.15, "trd": NaN, "batb": [[1, 1.51, 169.58], [2, 1.5, 349.25]], "batl": NaN}, {"timestamp": 1631532837285, "ltp": 1.58, "tv": 10318.15, "trd": NaN, "batb": NaN, "batl": [[2, 1.72, 43.66]]}, {"timestamp": 1631532839523, "ltp": 1.58, "tv": 10318.15, "trd": NaN, "batb": [[0, 1.55, 42.19], [1, 1.52, 50.24], [2, 1.51, 169.58]], "batl": NaN}, {"timestamp": 1631532840509, "ltp": 1.58, "tv": 10318.15, "trd": NaN, "batb": [[0, 1.52, 50.24], [1, 1.51, 169.58], [2, 1.5, 349.25]], "batl": [[0, 1.69, 5], [1, 1.72, 38.66], [2, 1.74, 176.01]]}, {"timestamp": 1631532842404, "ltp": 1.58, "tv": 10318.15, "trd": NaN, "batb": [[1, 1.5, 160.92], [2, 1.45, 4.26]], "batl": NaN}, {"timestamp": 1631532843638, "ltp": 1.58, "tv": 10318.15, "trd": NaN, "batb": NaN, "batl": [[0, 1.68, 38.89], [1, 1.69, 5], [2, 1.72, 38.66]]}, {"timestamp": 1631532844633, "ltp": 1.68, "tv": 10395.93, "trd": [[1.68, 102.62]], "batb": NaN, "batl": [[0, 1.69, 5], [1, 1.72, 38.66], [2, 1.74, 176.01]]}, {"timestamp": 1631532845622, "ltp": 1.68, "tv": 10395.93, "trd": NaN, "batb": [[0, 1.68, 243.39], [1, 1.67, 125.38], [2, 1.66, 1152.12]], "batl": [[0, 1.72, 38.66], [1, 1.74, 176.01], [2, 1.76, 210.57]]}, {"timestamp": 1631532846512, "ltp": 1.68, "tv": 10420.77, "trd": [[1.68, 127.46]], "batb": [[0, 1.68, 230.97], [1, 1.67, 234]], "batl": NaN}, {"timestamp": 1631532847509, "ltp": 1.68, "tv": 10432.77, "trd": [[1.68, 139.46]], "batb": [[0, 1.68, 224.97]], "batl": NaN}, {"timestamp": 1631532848643, "ltp": 1.68, "tv": 10432.77, "trd": NaN, "batb": [[1, 1.67, 240], [2, 1.66, 1158.12]], "batl": NaN}, {"timestamp": 1631532854626, "ltp": 1.68, "tv": 10432.77, "trd": NaN, "batb": [[0, 1.7, 42.47], [1, 1.68, 224.97], [2, 1.67, 240]], "batl": NaN}, {"timestamp": 1631532854835, "ltp": 1.68, "tv": 10432.77, "trd": NaN, "batb": [[0, 1.68, 224.97], [1, 1.67, 240], [2, 1.66, 1158.12]], "batl": NaN}, {"timestamp": 1631532858391, "ltp": 1.68, "tv": 10432.77, "trd": NaN, "batb": [[0, 1.69, 42.47], [1, 1.68, 224.97], [2, 1.67, 240]], "batl": NaN}, {"timestamp": 1631532864646, "ltp": 1.68, "tv": 10432.77, "trd": NaN, "batb": [[0, 1.61, 47.09], [1, 1.6, 295.12], [2, 1.59, 335.76]], "batl": [[0, 1.86, 32.25], [1, 1.88, 246.24], [2, 1.89, 226.15]]}, {"timestamp": 1631532864857, "ltp": 1.68, "tv": 10432.77, "trd": NaN, "batb": [[0, 1.6, 295.12], [1, 1.59, 335.76], [2, 1.58, 447.53]], "batl": [[0, 1.88, 246.24], [1, 1.89, 226.15], [2, 1.9, 354.45]]}, {"timestamp": 1631532867455, "ltp": 1.68, "tv": 10432.77, "trd": NaN, "batb": [[2, 1.58, 709.83]], "batl": [[2, 1.9, 498.56]]}, {"timestamp": 1631532868554, "ltp": 1.68, "tv": 10432.77, "trd": NaN, "batb": [[2, 1.58, 447.53]], "batl": [[0, 1.86, 5], [1, 1.87, 4], [2, 1.88, 250.24]]}, {"timestamp": 1631532871467, "ltp": 1.68, "tv": 10432.77, "trd": NaN, "batb": [[0, 1.71, 203.04], [1, 1.69, 238.75], [2, 1.6, 295.12]], "batl": [[0, 1.77, 180.13], [1, 1.79, 199.18], [2, 1.86, 5]]}, {"timestamp": 1631532872565, "ltp": 1.68, "tv": 10432.77, "trd": NaN, "batb": [[2, 1.61, 44.09]], "batl": [[2, 1.85, 25]]}, {"timestamp": 1631532874355, "ltp": 1.68, "tv": 10432.77, "trd": NaN, "batb": [[0, 1.6, 295.12], [1, 1.59, 335.76], [2, 1.58, 447.53]], "batl": [[0, 1.86, 5], [1, 1.87, 4], [2, 1.88, 250.24]]}, {"timestamp": 1631532877578, "ltp": 1.68, "tv": 10432.77, "trd": NaN, "batb": [[2, 1.58, 709.83]], "batl": NaN}, {"timestamp": 1631532881086, "ltp": 1.68, "tv": 10432.77, "trd": NaN, "batb": NaN, "batl": [[1, 1.93, 25.5], [2, 2.04, 388.3]]}, {"timestamp": 1631532884494, "ltp": 1.6, "tv": 10458.75, "trd": [[1.6, 1042.01]], "batb": [[0, 1.59, 335.76], [1, 1.58, 709.83], [2, 1.57, 157.68]], "batl": [[0, 1.63, 185.95], [1, 1.64, 133.48], [2, 1.65, 1159.1]]}, {"timestamp": 1631532887582, "ltp": 1.6, "tv": 10458.75, "trd": NaN, "batb": [[0, 1.59, 376.54]], "batl": NaN}, {"timestamp": 1631532895786, "ltp": 1.6, "tv": 10458.75, "trd": NaN, "batb": NaN, "batl": [[0, 1.63, 170.77]]}, {"timestamp": 1631532908569, "ltp": 1.6, "tv": 10458.75, "trd": NaN, "batb": [[0, 1.58, 395.27], [1, 1.57, 157.68], [2, 1.55, 39.99]], "batl": [[2, 1.68, 32.14]]}, {"timestamp": 1631532909045, "ltp": 1.6, "tv": 10458.75, "trd": NaN, "batb": [[0, 1.52, 50.24], [1, 1.51, 157.49], [2, 1.45, 4.26]], "batl": [[0, 1.72, 34.91], [1, 1.85, 5], [2, 1.93, 25.5]]}, {"timestamp": 1631532912567, "ltp": 1.6, "tv": 10458.75, "trd": NaN, "batb": NaN, "batl": [[0, 1.69, 4], [1, 1.7, 5], [2, 1.72, 34.91]]}, {"timestamp": 1631532914588, "ltp": 1.6, "tv": 10458.75, "trd": NaN, "batb": [[0, 1.6, 261.48], [1, 1.59, 150.25], [2, 1.52, 50.24]], "batl": [[0, 1.65, 143.58], [1, 1.66, 127.94], [2, 1.69, 4]]}, {"timestamp": 1631532915284, "ltp": 1.6, "tv": 10458.75, "trd": NaN, "batb": [[2, 1.53, 132.65]], "batl": NaN}, {"timestamp": 1631532916060, "ltp": 1.6, "tv": 10458.75, "trd": NaN, "batb": [[2, 1.55, 44.99]], "batl": [[2, 1.68, 34.14]]}, {"timestamp": 1631532922595, "ltp": 1.6, "tv": 10458.75, "trd": NaN, "batb": [[0, 1.52, 55.24], [1, 1.51, 163.49], [2, 1.45, 4.26]], "batl": [[0, 1.69, 4], [1, 1.7, 5], [2, 1.72, 34.91]]}, {"timestamp": 1631532924574, "ltp": 1.6, "tv": 10458.75, "trd": NaN, "batb": [[1, 1.51, 420.57], [2, 1.5, 188.87]], "batl": NaN}, {"timestamp": 1631532925605, "ltp": 1.6, "tv": 10458.75, "trd": NaN, "batb": NaN, "batl": [[0, 1.69, 53.68], [1, 1.72, 34.91], [2, 1.75, 199.92]]}, {"timestamp": 1631532926189, "ltp": 1.6, "tv": 10458.75, "trd": NaN, "batb": [[1, 1.51, 414.57]], "batl": [[0, 1.69, 24]]}, {"timestamp": 1631532929432, "ltp": 1.6, "tv": 10458.75, "trd": NaN, "batb": [[0, 1.53, 132.65], [1, 1.52, 55.24], [2, 1.51, 421.57]], "batl": NaN}, {"timestamp": 1631532932580, "ltp": 1.6, "tv": 10458.75, "trd": NaN, "batb": [[0, 1.53, 5]], "batl": NaN}, {"timestamp": 1631532942597, "ltp": 1.6, "tv": 10458.75, "trd": NaN, "batb": [[0, 1.55, 108.17], [1, 1.53, 5], [2, 1.52, 50.24]], "batl": NaN}, {"timestamp": 1631532943117, "ltp": 1.6, "tv": 10458.75, "trd": NaN, "batb": [[0, 1.53, 5], [1, 1.52, 50.24], [2, 1.51, 414.57]], "batl": NaN}, {"timestamp": 1631532946534, "ltp": 1.6, "tv": 10458.75, "trd": NaN, "batb": [[1, 1.52, 56.24]], "batl": NaN}, {"timestamp": 1631532947424, "ltp": 1.6, "tv": 10458.75, "trd": NaN, "batb": NaN, "batl": [[0, 1.69, 4]]}, {"timestamp": 1631532949608, "ltp": 1.6, "tv": 10458.75, "trd": NaN, "batb": [[0, 1.56, 96.39], [1, 1.53, 5], [2, 1.52, 56.24]], "batl": [[0, 1.68, 35.14], [1, 1.69, 4], [2, 1.72, 34.91]]}, {"timestamp": 1631532950133, "ltp": 1.6, "tv": 10458.75, "trd": NaN, "batb": [[0, 1.53, 5], [1, 1.52, 56.24], [2, 1.51, 414.57]], "batl": [[0, 1.69, 4], [1, 1.72, 34.91], [2, 1.75, 199.92]]}, {"timestamp": 1631532953420, "ltp": 1.6, "tv": 10458.75, "trd": NaN, "batb": [[0, 1.55, 43.99], [1, 1.53, 5], [2, 1.52, 56.24]], "batl": NaN}, {"timestamp": 1631532953736, "ltp": 1.6, "tv": 10458.75, "trd": NaN, "batb": [[0, 1.53, 5], [1, 1.52, 56.24], [2, 1.51, 414.57]], "batl": NaN}, {"timestamp": 1631532956544, "ltp": 1.6, "tv": 10458.75, "trd": NaN, "batb": NaN, "batl": [[0, 1.68, 34.89], [1, 1.69, 4], [2, 1.72, 34.91]]}, {"timestamp": 1631532957454, "ltp": 1.6, "tv": 10458.75, "trd": NaN, "batb": [[1, 1.52, 50.24]], "batl": [[0, 1.69, 4], [1, 1.72, 34.91], [2, 1.75, 199.92]]}, {"timestamp": 1631532960607, "ltp": 1.6, "tv": 10458.75, "trd": NaN, "batb": [[0, 1.55, 50.99], [1, 1.53, 5], [2, 1.52, 54.24]], "batl": NaN}, {"timestamp": 1631532960924, "ltp": 1.6, "tv": 10458.75, "trd": NaN, "batb": [[0, 1.53, 5], [1, 1.52, 54.24], [2, 1.51, 157.49]], "batl": NaN}, {"timestamp": 1631532962647, "ltp": 1.69, "tv": 10466.75, "trd": [[1.69, 8]], "batb": [[0, 1.69, 468.25], [1, 1.53, 5], [2, 1.52, 54.24]], "batl": [[0, 1.72, 34.91], [1, 1.75, 199.92], [2, 1.77, 206.61]]}, {"timestamp": 1631532963642, "ltp": 1.69, "tv": 10466.75, "trd": NaN, "batb": [[0, 1.65, 26.73]], "batl": [[0, 1.68, 40.14], [1, 1.72, 34.91], [2, 1.78, 2148.88]]}, {"timestamp": 1631532964641, "ltp": 1.67, "tv": 10568.01, "trd": [[1.67, 67.06], [1.68, 219.74], [1.69, 16.56]], "batb": [[0, 1.68, 107.36], [1, 1.65, 26.73], [2, 1.59, 131.04]], "batl": [[0, 1.72, 34.91], [1, 1.78, 590.94], [2, 1.79, 1042.84]]}, {"timestamp": 1631532965626, "ltp": 1.67, "tv": 10568.01, "trd": NaN, "batb": NaN, "batl": [[0, 1.7, 6], [1, 1.72, 34.91], [2, 1.78, 590.94]]}, {"timestamp": 1631532966660, "ltp": 1.67, "tv": 10568.01, "trd": NaN, "batb": [[0, 1.68, 111.36], [1, 1.67, 5], [2, 1.65, 26.73]], "batl": [[0, 1.72, 34.91], [1, 1.78, 590.94], [2, 1.79, 1042.84]]}, {"timestamp": 1631532967444, "ltp": 1.67, "tv": 10568.01, "trd": NaN, "batb": [[0, 1.68, 107.36], [1, 1.65, 26.73], [2, 1.59, 131.04]], "batl": NaN}, {"timestamp": 1631532968531, "ltp": 1.67, "tv": 10568.01, "trd": NaN, "batb": NaN, "batl": [[0, 1.72, 102.6]]}, {"timestamp": 1631532968741, "ltp": 1.67, "tv": 10568.01, "trd": NaN, "batb": NaN, "batl": [[0, 1.72, 34.91]]}, {"timestamp": 1631532970043, "ltp": 1.67, "tv": 10568.01, "trd": NaN, "batb": [[2, 1.6, 53.84]], "batl": NaN}, {"timestamp": 1631532971661, "ltp": 1.67, "tv": 10568.01, "trd": NaN, "batb": [[2, 1.61, 48.09]], "batl": NaN}, {"timestamp": 1631532974949, "ltp": 1.67, "tv": 10568.01, "trd": NaN, "batb": [[0, 1.69, 179.21], [1, 1.68, 107.36], [2, 1.67, 249.06]], "batl": [[1, 1.74, 119.6], [2, 1.76, 210.91]]}, {"timestamp": 1631532975980, "ltp": 1.67, "tv": 10568.01, "trd": NaN, "batb": NaN, "batl": [[2, 1.76, 218.41]]}, {"timestamp": 1631532984340, "ltp": 1.74, "tv": 10624.6, "trd": [[1.72, 34.91], [1.74, 21.68]], "batb": NaN, "batl": [[0, 1.76, 7.5], [1, 1.78, 590.94], [2, 1.79, 1042.84]]}, {"timestamp": 1631532987571, "ltp": 1.74, "tv": 10624.6, "trd": NaN, "batb": [[1, 1.67, 249.06], [2, 1.61, 48.09]], "batl": [[0, 1.75, 213.85], [1, 1.76, 7.5], [2, 1.77, 206.63]]}, {"timestamp": 1631532988361, "ltp": 1.74, "tv": 10624.6, "trd": NaN, "batb": [[0, 1.59, 131.04], [1, 1.56, 52.33], [2, 1.52, 50.24]], "batl": [[0, 1.93, 25.5], [1, 2.04, 388.3], [2, 810, 0.07]]}, {"timestamp": 1631532990563, "ltp": 1.74, "tv": 10624.6, "trd": NaN, "batb": [[1, 1.58, 131.21], [2, 1.56, 52.33]], "batl": NaN}, {"timestamp": 1631532991558, "ltp": 1.74, "tv": 10624.6, "trd": NaN, "batb": [[0, 1.59, 191.94], [1, 1.58, 284.9]], "batl": [[0, 1.91, 158.65], [1, 1.93, 182.42], [2, 2.04, 388.3]]}, {"timestamp": 1631532992491, "ltp": 1.74, "tv": 10624.6, "trd": NaN, "batb": NaN, "batl": [[0, 1.91, 3], [1, 1.93, 25.5]]}, {"timestamp": 1631532994577, "ltp": 1.74, "tv": 10624.6, "trd": NaN, "batb": [[2, 1.56, 57.33]], "batl": [[0, 1.64, 6.26], [1, 1.91, 3], [2, 1.93, 25.5]]}, {"timestamp": 1631532995466, "ltp": 1.59, "tv": 10650.4, "trd": [[1.59, 51.6]], "batb": [[0, 1.59, 179.04]], "batl": [[0, 1.64, 2192.94], [1, 1.65, 130.5], [2, 1.91, 3]]}, {"timestamp": 1631532996659, "ltp": 1.59, "tv": 10650.4, "trd": NaN, "batb": NaN, "batl": [[0, 1.64, 239.37], [2, 1.66, 7.5]]}, {"timestamp": 1631532997282, "ltp": 1.59, "tv": 10650.4, "trd": NaN, "batb": [[0, 1.6, 38.14], [1, 1.59, 179.04], [2, 1.58, 284.9]], "batl": NaN}, {"timestamp": 1631533000580, "ltp": 1.59, "tv": 10650.4, "trd": NaN, "batb": NaN, "batl": [[2, 1.8, 15]]}, {"timestamp": 1631533002188, "ltp": 1.59, "tv": 10650.4, "trd": NaN, "batb": NaN, "batl": [[2, 1.69, 31.79]]}, {"timestamp": 1631533003594, "ltp": 1.59, "tv": 10650.4, "trd": NaN, "batb": NaN, "batl": [[1, 1.65, 138]]}, {"timestamp": 1631533004579, "ltp": 1.59, "tv": 10650.4, "trd": NaN, "batb": [[0, 1.59, 179.04], [1, 1.58, 284.9], [2, 1.56, 52.33]], "batl": [[0, 1.64, 223.74]]}, {"timestamp": 1631533005576, "ltp": 1.59, "tv": 10650.4, "trd": NaN, "batb": [[0, 1.53, 76.33], [1, 1.52, 154.98], [2, 1.45, 4.26]], "batl": [[0, 1.69, 31.79], [1, 1.73, 28.87], [2, 1.9, 4]]}, {"timestamp": 1631533005781, "ltp": 1.59, "tv": 10650.4, "trd": NaN, "batb": NaN, "batl": [[0, 1.73, 28.87], [1, 1.9, 4], [2, 1.91, 3]]}, {"timestamp": 1631533007663, "ltp": 1.59, "tv": 10650.4, "trd": NaN, "batb": [[1, 1.52, 300.84], [2, 1.51, 183.35]], "batl": [[1, 1.75, 130.87], [2, 1.77, 206.93]]}, {"timestamp": 1631533008498, "ltp": 1.59, "tv": 10650.4, "trd": NaN, "batb": [[0, 1.56, 71.08], [1, 1.53, 76.33], [2, 1.52, 300.84]], "batl": NaN}, {"timestamp": 1631533009383, "ltp": 1.59, "tv": 10650.4, "trd": NaN, "batb": [[0, 1.53, 76.33], [1, 1.52, 300.84], [2, 1.51, 183.35]], "batl": [[0, 1.7, 4], [1, 1.73, 28.87], [2, 1.75, 130.87]]}, {"timestamp": 1631533012613, "ltp": 1.59, "tv": 10650.4, "trd": NaN, "batb": [[0, 1.56, 76.58], [1, 1.53, 76.33], [2, 1.52, 300.84]], "batl": [[0, 1.69, 38.5], [1, 1.7, 4], [2, 1.73, 28.87]]}, {"timestamp": 1631533013601, "ltp": 1.59, "tv": 10650.4, "trd": NaN, "batb": [[0, 1.53, 76.33], [1, 1.52, 300.84], [2, 1.51, 183.35]], "batl": [[0, 1.7, 4], [1, 1.73, 28.87], [2, 1.75, 130.87]]}, {"timestamp": 1631533019508, "ltp": 1.59, "tv": 10650.4, "trd": NaN, "batb": [[1, 1.52, 154.98], [2, 1.45, 4.26]], "batl": [[0, 1.69, 32.5], [1, 1.7, 4], [2, 1.73, 28.87]]}, {"timestamp": 1631533020508, "ltp": 1.7, "tv": 10662.71, "trd": [[1.7, 12.31]], "batb": NaN, "batl": [[0, 1.73, 28.87], [1, 1.75, 130.87], [2, 1.77, 206.93]]}, {"timestamp": 1631533021504, "ltp": 1.7, "tv": 10662.71, "trd": NaN, "batb": [[0, 1.65, 75.53], [1, 1.53, 76.33], [2, 1.52, 154.98]], "batl": NaN}, {"timestamp": 1631533022615, "ltp": 1.7, "tv": 10687.41, "trd": [[1.7, 37.01]], "batb": [[0, 1.7, 128.2], [1, 1.68, 349.51], [2, 1.65, 75.53]], "batl": NaN}, {"timestamp": 1631533023615, "ltp": 1.7, "tv": 10687.41, "trd": NaN, "batb": NaN, "batl": [[1, 1.75, 138.37]]}, {"timestamp": 1631533024615, "ltp": 1.7, "tv": 10687.41, "trd": NaN, "batb": [[1, 1.68, 353.51], [2, 1.67, 4]], "batl": NaN}, {"timestamp": 1631533025195, "ltp": 1.7, "tv": 10687.41, "trd": NaN, "batb": NaN, "batl": [[1, 1.75, 155.01]]}, {"timestamp": 1631533026607, "ltp": 1.7, "tv": 10687.41, "trd": NaN, "batb": [[0, 1.71, 141.68], [1, 1.7, 128.2], [2, 1.68, 353.51]], "batl": NaN}, {"timestamp": 1631533027558, "ltp": 1.7, "tv": 10687.41, "trd": NaN, "batb": [[0, 1.7, 128.2], [1, 1.68, 353.51], [2, 1.67, 4]], "batl": NaN}, {"timestamp": 1631533032514, "ltp": 1.7, "tv": 10701.87, "trd": [[1.7, 51.47]], "batb": [[0, 1.7, 120.97]], "batl": NaN}, {"timestamp": 1631533033508, "ltp": 1.7, "tv": 10701.87, "trd": NaN, "batb": [[0, 1.71, 36.67], [1, 1.7, 120.97], [2, 1.68, 353.51]], "batl": NaN}, {"timestamp": 1631533034025, "ltp": 1.71, "tv": 10716.02, "trd": [[1.71, 14.15]], "batb": [[0, 1.71, 22.52]], "batl": NaN}, {"timestamp": 1631533037630, "ltp": 1.75, "tv": 10849.59, "trd": [[1.73, 28.87], [1.75, 104.7]], "batb": [[0, 1.7, 120.97], [1, 1.68, 353.51], [2, 1.65, 75.53]], "batl": [[0, 1.75, 50.31], [1, 1.77, 206.93], [2, 1.89, 265.1]]}, {"timestamp": 1631533038251, "ltp": 1.75, "tv": 10849.59, "trd": NaN, "batb": [[0, 1.68, 4], [1, 1.62, 74.04], [2, 1.6, 281.41]], "batl": [[0, 1.75, 7.5], [1, 1.89, 265.1], [2, 1.9, 290.94]]}, {"timestamp": 1631533039448, "ltp": 1.75, "tv": 10849.59, "trd": NaN, "batb": [[0, 1.73, 100], [1, 1.68, 4], [2, 1.62, 74.04]], "batl": [[0, 1.89, 265.1], [1, 1.9, 290.94], [2, 1.91, 247.78]]}, {"timestamp": 1631533040551, "ltp": 1.75, "tv": 10849.59, "trd": NaN, "batb": [[1, 1.62, 74.04], [2, 1.6, 281.41]], "batl": NaN}, {"timestamp": 1631533042117, "ltp": 1.75, "tv": 10849.59, "trd": NaN, "batb": [[2, 1.6, 444.76]], "batl": NaN}, {"timestamp": 1631533042944, "ltp": 1.75, "tv": 10849.59, "trd": NaN, "batb": NaN, "batl": [[0, 1.89, 270.1]]}, {"timestamp": 1631533043938, "ltp": 1.75, "tv": 10849.59, "trd": NaN, "batb": NaN, "batl": [[0, 1.84, 4], [1, 1.89, 270.1], [2, 1.9, 290.94]]}, {"timestamp": 1631533048568, "ltp": 1.75, "tv": 10849.59, "trd": NaN, "batb": [[0, 1.62, 74.04], [1, 1.6, 444.76], [2, 1.59, 558.81]], "batl": NaN}, {"timestamp": 1631533048832, "ltp": 1.75, "tv": 10849.59, "trd": NaN, "batb": [[0, 1.6, 444.76], [1, 1.59, 558.81], [2, 1.58, 402.86]], "batl": NaN}, {"timestamp": 1631533053145, "ltp": 1.75, "tv": 10849.59, "trd": NaN, "batb": [[0, 1.6, 281.41], [1, 1.59, 408.88]], "batl": NaN}, {"timestamp": 1631533054241, "ltp": 1.75, "tv": 10849.59, "trd": NaN, "batb": NaN, "batl": [[0, 1.73, 60], [1, 1.84, 4], [2, 1.89, 270.1]]}, {"timestamp": 1631533055647, "ltp": 1.75, "tv": 10849.59, "trd": NaN, "batb": [[0, 1.62, 95.04], [1, 1.6, 281.41], [2, 1.59, 408.88]], "batl": NaN}, {"timestamp": 1631533056637, "ltp": 1.73, "tv": 10969.59, "trd": [[1.73, 148.87]], "batb": [[0, 1.73, 109.46], [1, 1.71, 229.09], [2, 1.6, 281.41]], "batl": [[0, 1.84, 4], [1, 1.89, 265.1], [2, 1.9, 290.94]]}, {"timestamp": 1631533057255, "ltp": 1.73, "tv": 10969.59, "trd": NaN, "batb": [[0, 1.6, 281.41], [1, 1.59, 408.88], [2, 1.58, 402.86]], "batl": NaN}, {"timestamp": 1631533061157, "ltp": 1.73, "tv": 10969.59, "trd": NaN, "batb": [[1, 1.59, 686.97], [2, 1.58, 556.92]], "batl": NaN}, {"timestamp": 1631533062560, "ltp": 1.73, "tv": 10969.59, "trd": NaN, "batb": [[0, 1.62, 95.04], [1, 1.6, 281.41], [2, 1.59, 686.97]], "batl": NaN}, {"timestamp": 1631533062765, "ltp": 1.73, "tv": 10969.59, "trd": NaN, "batb": [[0, 1.6, 281.41], [1, 1.59, 686.97], [2, 1.58, 556.92]], "batl": NaN}, {"timestamp": 1631533068577, "ltp": 1.73, "tv": 10969.59, "trd": NaN, "batb": [[0, 1.59, 129.96], [1, 1.57, 70.57], [2, 1.53, 76.33]], "batl": NaN}, {"timestamp": 1631533069564, "ltp": 1.73, "tv": 10969.59, "trd": NaN, "batb": NaN, "batl": [[0, 1.89, 265.1], [1, 1.9, 290.94], [2, 1.91, 247.78]]}, {"timestamp": 1631533071565, "ltp": 1.73, "tv": 10969.59, "trd": NaN, "batb": [[0, 1.85, 2147.98], [1, 1.83, 1318.5], [2, 1.82, 1014.34]], "batl": [[0, 1.9, 290.94], [1, 1.91, 247.78], [2, 1.92, 163.12]]}, {"timestamp": 1631533072654, "ltp": 1.85, "tv": 10992.85, "trd": [[1.85, 23.26]], "batb": [[0, 1.85, 178.37], [2, 1.82, 1095.68]], "batl": [[1, 1.91, 255.28]]}, {"timestamp": 1631533073589, "ltp": 1.85, "tv": 10992.85, "trd": NaN, "batb": [[0, 1.86, 31.3], [1, 1.85, 178.37], [2, 1.83, 1318.5]], "batl": NaN}, {"timestamp": 1631533074588, "ltp": 1.85, "tv": 10992.85, "trd": NaN, "batb": [[0, 1.86, 35.3], [1, 1.85, 182.37]], "batl": NaN}, {"timestamp": 1631533075477, "ltp": 1.85, "tv": 10992.85, "trd": NaN, "batb": [[0, 1.86, 4]], "batl": NaN}, {"timestamp": 1631533078261, "ltp": 1.85, "tv": 10992.85, "trd": NaN, "batb": [[0, 1.87, 31.3], [1, 1.86, 4], [2, 1.85, 182.37]], "batl": NaN}, {"timestamp": 1631533083366, "ltp": 1.85, "tv": 10992.85, "trd": NaN, "batb": [[2, 1.85, 178.34]], "batl": NaN}, {"timestamp": 1631533088305, "ltp": 1.9, "tv": 11131.62, "trd": [[1.9, 138.76]], "batb": [[2, 1.85, 174.34]], "batl": [[0, 1.9, 152.17]]}, {"timestamp": 1631533091580, "ltp": 1.9, "tv": 11131.62, "trd": NaN, "batb": [[0, 1.82, 81.34], [1, 1.81, 8.33], [2, 1.71, 76.19]], "batl": [[0, 1.91, 7.5], [1, 2.3, 314.02], [2, 1.92, 0]]}, {"timestamp": 1631533092525, "ltp": 1.9, "tv": 11131.62, "trd": NaN, "batb": [[0, 1.69, 104.35], [1, 1.64, 79.57], [2, 1.63, 75.23]], "batl": [[0, 2.3, 314.02], [1, 2.3, 0]]}, {"timestamp": 1631533094510, "ltp": 1.9, "tv": 11131.62, "trd": NaN, "batb": [[0, 1.7, 229.6], [1, 1.69, 104.35], [2, 1.68, 244.09]], "batl": [[0, 2.16, 128.48], [1, 2.18, 109.49], [2, 2.3, 314.02]]}, {"timestamp": 1631533095749, "ltp": 1.9, "tv": 11131.62, "trd": NaN, "batb": [[1, 1.69, 110.35], [2, 1.68, 250.09]], "batl": [[0, 2.14, 4], [1, 2.16, 128.48], [2, 2.18, 109.49]]}, {"timestamp": 1631533098612, "ltp": 1.9, "tv": 11131.62, "trd": NaN, "batb": [[0, 1.71, 82.19], [1, 1.7, 229.6], [2, 1.69, 110.35]], "batl": NaN}, {"timestamp": 1631533098923, "ltp": 1.9, "tv": 11131.62, "trd": NaN, "batb": [[0, 1.7, 229.6], [1, 1.69, 110.35], [2, 1.68, 250.09]], "batl": NaN}, {"timestamp": 1631533104223, "ltp": 1.9, "tv": 11131.62, "trd": NaN, "batb": [[0, 1.69, 104.35], [1, 1.64, 79.57], [2, 1.63, 75.23]], "batl": [[1, 2.3, 314.02], [2, 2.18, 0]]}, {"timestamp": 1631533106614, "ltp": 1.69, "tv": 11156.32, "trd": [[1.69, 41.26]], "batb": [[0, 1.69, 92], [1, 1.67, 629.86], [2, 1.66, 611.35]], "batl": NaN}, {"timestamp": 1631533107602, "ltp": 1.69, "tv": 11156.32, "trd": NaN, "batb": [[0, 1.7, 229.6], [1, 1.69, 101.02], [2, 1.68, 244.09]], "batl": [[0, 1.76, 166.38], [1, 1.78, 203.08], [2, 1.81, 7.5]]}, {"timestamp": 1631533109426, "ltp": 1.69, "tv": 11156.32, "trd": NaN, "batb": [[0, 1.7, 233.6]], "batl": [[2, 1.96, 20]]}, {"timestamp": 1631533111513, "ltp": 1.69, "tv": 11156.32, "trd": NaN, "batb": [[0, 1.71, 48.22], [1, 1.7, 233.6], [2, 1.69, 101.02]], "batl": NaN}, {"timestamp": 1631533112614, "ltp": 1.69, "tv": 11156.32, "trd": NaN, "batb": NaN, "batl": [[2, 1.79, 7.5]]}, {"timestamp": 1631533120450, "ltp": 1.69, "tv": 11156.32, "trd": NaN, "batb": [[0, 1.73, 100], [1, 1.71, 20], [2, 1.7, 4]], "batl": [[0, 1.76, 149.19]]}, {"timestamp": 1631533122535, "ltp": 1.69, "tv": 11156.32, "trd": NaN, "batb": [[1, 1.69, 9.02], [2, 1.64, 79.57]], "batl": [[0, 1.79, 7.5], [1, 2.12, 3], [2, 2.3, 314.02]]}, {"timestamp": 1631533123469, "ltp": 1.69, "tv": 11156.32, "trd": NaN, "batb": [[1, 1.64, 79.57], [2, 1.63, 75.23]], "batl": [[0, 2.12, 3], [1, 2.3, 314.02], [2, 2.3, 0]]}, {"timestamp": 1631533123982, "ltp": 1.69, "tv": 11156.32, "trd": NaN, "batb": [[0, 1.6, 91.69], [1, 1.59, 128.7], [2, 1.58, 87.56]], "batl": NaN}, {"timestamp": 1631533125657, "ltp": 1.69, "tv": 11156.32, "trd": NaN, "batb": [[0, 1.6, 314.39], [1, 1.59, 368]], "batl": [[0, 1.93, 163.53], [1, 1.95, 152.12], [2, 2.12, 3]]}, {"timestamp": 1631533126652, "ltp": 1.69, "tv": 11156.32, "trd": NaN, "batb": NaN, "batl": [[0, 1.93, 4], [1, 2.12, 3], [2, 2.3, 314.02]]}, {"timestamp": 1631533127281, "ltp": 1.69, "tv": 11156.32, "trd": NaN, "batb": [[0, 1.76, 100], [1, 1.64, 85.07], [2, 1.6, 314.39]], "batl": NaN}, {"timestamp": 1631533128584, "ltp": 1.76, "tv": 11190.12, "trd": [[1.76, 33.8]], "batb": [[0, 1.76, 83.1], [1, 1.6, 314.39], [2, 1.59, 368]], "batl": NaN}, {"timestamp": 1631533129568, "ltp": 1.6, "tv": 11382.12, "trd": [[1.6, 1067.81], [1.76, 200]], "batb": [[0, 1.6, 301.49], [1, 1.59, 368], [2, 1.58, 87.56]], "batl": [[0, 1.65, 2088.04], [1, 1.66, 127.9], [2, 1.93, 4]]}, {"timestamp": 1631533130564, "ltp": 1.6, "tv": 11382.12, "trd": NaN, "batb": [[0, 1.6, 305.49], [1, 1.59, 371]], "batl": [[0, 1.65, 195.18], [2, 1.76, 162.87]]}, {"timestamp": 1631533131551, "ltp": 1.6, "tv": 11382.12, "trd": NaN, "batb": NaN, "batl": [[2, 1.76, 465.57]]}, {"timestamp": 1631533132573, "ltp": 1.6, "tv": 11382.12, "trd": NaN, "batb": [[0, 1.61, 38.47], [1, 1.6, 305.49], [2, 1.59, 380.76]], "batl": [[2, 1.76, 497.46]]}, {"timestamp": 1631533133574, "ltp": 1.6, "tv": 11382.12, "trd": NaN, "batb": NaN, "batl": [[2, 1.69, 7.5]]}, {"timestamp": 1631533134571, "ltp": 1.6, "tv": 11382.12, "trd": NaN, "batb": NaN, "batl": [[2, 1.76, 31.89]]}, {"timestamp": 1631533135185, "ltp": 1.6, "tv": 11382.12, "trd": NaN, "batb": NaN, "batl": [[2, 1.76, 4]]}, {"timestamp": 1631533136281, "ltp": 1.6, "tv": 11382.12, "trd": NaN, "batb": NaN, "batl": [[2, 1.71, 35.5]]}, {"timestamp": 1631533137069, "ltp": 1.6, "tv": 11382.12, "trd": NaN, "batb": NaN, "batl": [[2, 1.68, 7.5]]}, {"timestamp": 1631533141356, "ltp": 1.6, "tv": 11382.12, "trd": NaN, "batb": NaN, "batl": [[0, 1.65, 179.4]]}, {"timestamp": 1631533141671, "ltp": 1.6, "tv": 11382.12, "trd": NaN, "batb": [[2, 1.59, 377.76]], "batl": NaN}, {"timestamp": 1631533143559, "ltp": 1.6, "tv": 11382.12, "trd": NaN, "batb": [[0, 1.6, 305.49], [1, 1.59, 377.76], [2, 1.58, 87.56]], "batl": NaN}, {"timestamp": 1631533144108, "ltp": 1.6, "tv": 11382.12, "trd": NaN, "batb": [[0, 1.59, 9.76], [1, 1.55, 83.19], [2, 1.52, 152.8]], "batl": [[0, 1.68, 7.5], [1, 1.75, 32.06], [2, 2.16, 347.55]]}, {"timestamp": 1631533145397, "ltp": 1.6, "tv": 11382.12, "trd": NaN, "batb": [[0, 1.55, 83.19], [1, 1.52, 152.8], [2, 1.45, 4.26]], "batl": [[0, 1.75, 32.06], [1, 2.16, 347.55], [2, 2.16, 0]]}, {"timestamp": 1631533147581, "ltp": 1.6, "tv": 11382.12, "trd": NaN, "batb": [[1, 1.53, 153.39], [2, 1.52, 331.35]], "batl": [[1, 1.77, 166.94], [2, 1.79, 199.35]]}, {"timestamp": 1631533148577, "ltp": 1.6, "tv": 11382.12, "trd": NaN, "batb": [[0, 1.55, 88.19], [1, 1.54, 6], [2, 1.52, 152.8]], "batl": [[1, 2.16, 347.55], [2, 1.79, 0]]}, {"timestamp": 1631533151379, "ltp": 1.6, "tv": 11382.12, "trd": NaN, "batb": [[0, 1.62, 233.8], [1, 1.61, 143.35], [2, 1.57, 5]], "batl": [[0, 1.67, 144.4], [1, 1.69, 241.97], [2, 1.75, 32.06]]}, {"timestamp": 1631533152481, "ltp": 1.6, "tv": 11382.12, "trd": NaN, "batb": NaN, "batl": [[2, 1.74, 56.65]]}, {"timestamp": 1631533152895, "ltp": 1.6, "tv": 11382.12, "trd": NaN, "batb": [[0, 1.57, 5], [1, 1.56, 5], [2, 1.55, 88.19]], "batl": [[0, 1.75, 32.06], [1, 2.16, 347.55], [2, 1000, 2.89]]}, {"timestamp": 1631533154623, "ltp": 1.6, "tv": 11382.12, "trd": NaN, "batb": NaN, "batl": [[0, 1.71, 31.5], [1, 1.75, 32.06], [2, 2.16, 347.55]]}, {"timestamp": 1631533155568, "ltp": 1.6, "tv": 11382.12, "trd": NaN, "batb": NaN, "batl": [[0, 1.75, 32.06], [1, 1.77, 166.94], [2, 1.79, 199.35]]}, {"timestamp": 1631533161602, "ltp": 1.6, "tv": 11382.12, "trd": NaN, "batb": [[2, 1.55, 83.19]], "batl": NaN}, {"timestamp": 1631533162486, "ltp": 1.6, "tv": 11382.12, "trd": NaN, "batb": [[1, 1.55, 83.19], [2, 1.53, 153.39]], "batl": [[0, 2.16, 347.55], [1, 1.77, 0], [2, 1.79, 0]]}, {"timestamp": 1631533165446, "ltp": 1.57, "tv": 11568.8, "trd": [[1.57, 965.43], [1.58, 1054.89]], "batb": [[0, 1.55, 83.19], [1, 1.53, 153.39], [2, 1.52, 331.35]], "batl": [[0, 1.57, 117.94], [1, 1.58, 152.83], [2, 1.71, 33.5]]}, {"timestamp": 1631533167479, "ltp": 1.57, "tv": 11568.8, "trd": NaN, "batb": NaN, "batl": [[2, 1.71, 167.99]]}, {"timestamp": 1631533168519, "ltp": 1.57, "tv": 11686.66, "trd": [[1.57, 1083.29]], "batb": NaN, "batl": [[0, 1.57, 59.01], [2, 1.7, 5]]}, {"timestamp": 1631533169612, "ltp": 1.57, "tv": 11686.66, "trd": NaN, "batb": [[1, 1.53, 201.84]], "batl": [[0, 1.58, 152.83], [1, 1.59, 7.5]]}, {"timestamp": 1631533170402, "ltp": 1.57, "tv": 11686.66, "trd": NaN, "batb": NaN, "batl": [[1, 1.7, 5], [2, 1.71, 167.99]]}, {"timestamp": 1631533172242, "ltp": 1.57, "tv": 11686.66, "trd": NaN, "batb": [[1, 1.53, 235.31]], "batl": [[0, 1.58, 275.09], [1, 1.59, 148.64], [2, 1.63, 42.5]]}, {"timestamp": 1631533173227, "ltp": 1.57, "tv": 11686.66, "trd": NaN, "batb": NaN, "batl": [[0, 1.58, 282.59]]}, {"timestamp": 1631533178222, "ltp": 1.57, "tv": 11686.66, "trd": NaN, "batb": NaN, "batl": [[0, 1.58, 303.27]]}, {"timestamp": 1631533179619, "ltp": 1.58, "tv": 11786.66, "trd": [[1.58, 1154.89]], "batb": NaN, "batl": [[0, 1.58, 253.27]]}, {"timestamp": 1631533182907, "ltp": 1.58, "tv": 11786.66, "trd": NaN, "batb": [[1, 1.53, 271.67]], "batl": NaN}, {"timestamp": 1631533193052, "ltp": 1.58, "tv": 11786.66, "trd": NaN, "batb": NaN, "batl": [[0, 1.58, 232.59]]}, {"timestamp": 1631533196053, "ltp": 1.58, "tv": 11786.66, "trd": NaN, "batb": NaN, "batl": [[0, 1.57, 20.68], [1, 1.58, 232.59], [2, 1.59, 148.64]]}, {"timestamp": 1631533199221, "ltp": 1.58, "tv": 11786.66, "trd": NaN, "batb": [[0, 1.51, 20.25], [1, 1.49, 52.01], [2, 1.48, 314.54]], "batl": [[1, 1.58, 7.5], [2, 1.63, 42.5]]}, {"timestamp": 1631533200436, "ltp": 1.58, "tv": 11786.66, "trd": NaN, "batb": NaN, "batl": [[1, 1.63, 42.5], [2, 1.65, 226.64]]}, {"timestamp": 1631533202426, "ltp": 1.58, "tv": 11786.66, "trd": NaN, "batb": [[1, 1.48, 314.54], [2, 1.47, 413.91]], "batl": [[2, 1.65, 417.83]]}, {"timestamp": 1631533203369, "ltp": 1.57, "tv": 11791.3, "trd": [[1.57, 1087.93]], "batb": NaN, "batl": [[0, 1.57, 18.36], [2, 1.7, 5]]}, {"timestamp": 1631533203957, "ltp": 1.57, "tv": 11795.3, "trd": [[1.57, 1091.93]], "batb": NaN, "batl": [[0, 1.57, 16.36]]}, {"timestamp": 1631533205567, "ltp": 1.57, "tv": 11795.3, "trd": NaN, "batb": [[1, 1.49, 58.01], [2, 1.48, 314.54]], "batl": NaN}, {"timestamp": 1631533206359, "ltp": 1.5, "tv": 11881.34, "trd": [[1.47, 349.13], [1.5, 167.93], [1.51, 533.55]], "batb": [[0, 1.47, 400.12], [1, 1.46, 590.85], [2, 1.45, 460.79]], "batl": [[0, 1.5, 239.94], [1, 1.51, 1447.87], [2, 1.52, 1229.32]]}, {"timestamp": 1631533209170, "ltp": 1.5, "tv": 11881.34, "trd": NaN, "batb": [[1, 1.46, 597.85], [2, 1.45, 466.79]], "batl": NaN}, {"timestamp": 1631533214645, "ltp": 1.5, "tv": 11881.34, "trd": NaN, "batb": NaN, "batl": [[0, 1.5, 292.94], [1, 1.51, 1455.37]]}, {"timestamp": 1631533221147, "ltp": 1.5, "tv": 11881.34, "trd": NaN, "batb": [[2, 1.45, 460.79]], "batl": [[0, 1.49, 7.23], [1, 1.5, 292.94], [2, 1.51, 1455.37]]}, {"timestamp": 1631533223488, "ltp": 1.5, "tv": 11881.34, "trd": NaN, "batb": [[0, 1.45, 4.26], [1, 1.44, 11.3], [2, 1.41, 60.89]], "batl": [[1, 1.5, 53], [2, 1.51, 7.5]]}, {"timestamp": 1631533224574, "ltp": 1.5, "tv": 11881.34, "trd": NaN, "batb": [[0, 1.45, 11.26], [1, 1.41, 60.89], [2, 1.4, 286.63]], "batl": [[1, 1.57, 395.27], [2, 1.58, 329.94]]}, {"timestamp": 1631533224685, "ltp": 1.5, "tv": 11881.34, "trd": NaN, "batb": [[0, 1.45, 4.26]], "batl": NaN}, {"timestamp": 1631533226455, "ltp": 1.5, "tv": 11881.34, "trd": NaN, "batb": NaN, "batl": [[0, 1.57, 616.98], [1, 1.58, 482.18], [2, 1.59, 428.71]]}, {"timestamp": 1631533234565, "ltp": 1.5, "tv": 11881.34, "trd": NaN, "batb": [[2, 1.39, 279.97]], "batl": NaN}, {"timestamp": 1631533235396, "ltp": 1.5, "tv": 11881.34, "trd": NaN, "batb": [[2, 1.38, 226.94]], "batl": [[0, 1.57, 395.27], [1, 1.58, 329.94]]}, {"timestamp": 1631533237480, "ltp": 1.5, "tv": 11881.34, "trd": NaN, "batb": [[0, 1.52, 44.74], [1, 1.45, 4.26], [2, 1.41, 60.89]], "batl": [[2, 1.59, 2834.37]]}, {"timestamp": 1631533238579, "ltp": 1.52, "tv": 11908.0, "trd": [[1.52, 834.18]], "batb": [[0, 1.52, 341.56], [1, 1.51, 339.51], [2, 1.45, 4.26]], "batl": [[0, 1.57, 616.98], [1, 1.58, 482.18], [2, 1.59, 1090.27]]}, {"timestamp": 1631533239357, "ltp": 1.52, "tv": 11908.0, "trd": NaN, "batb": [[2, 1.5, 10.6]], "batl": [[2, 1.59, 1097.77]]}, {"timestamp": 1631533240971, "ltp": 1.52, "tv": 11908.0, "trd": NaN, "batb": NaN, "batl": [[0, 1.57, 571.48]]}, {"timestamp": 1631533242582, "ltp": 1.52, "tv": 11908.0, "trd": NaN, "batb": NaN, "batl": [[0, 1.57, 659.98]]}, {"timestamp": 1631533242684, "ltp": 1.52, "tv": 11908.0, "trd": NaN, "batb": [[2, 1.46, 7]], "batl": [[0, 1.57, 571.48]]}, {"timestamp": 1631533243980, "ltp": 1.52, "tv": 11908.0, "trd": NaN, "batb": [[0, 1.53, 37.25], [1, 1.52, 341.56], [2, 1.51, 339.51]], "batl": NaN}, {"timestamp": 1631533245911, "ltp": 1.52, "tv": 11908.0, "trd": NaN, "batb": [[2, 1.51, 350.01]], "batl": NaN}, {"timestamp": 1631533252506, "ltp": 1.52, "tv": 11908.0, "trd": NaN, "batb": [[0, 1.51, 10.5], [1, 1.46, 57.38], [2, 1.45, 10.26]], "batl": [[0, 1.57, 16.36], [1, 1.59, 7.5], [2, 1.64, 39.68]]}, {"timestamp": 1631533253393, "ltp": 1.52, "tv": 11908.0, "trd": NaN, "batb": [[0, 1.46, 57.38], [1, 1.45, 10.26], [2, 1.44, 56.67]], "batl": [[1, 1.64, 39.68], [2, 1.64, 0]]}, {"timestamp": 1631533254424, "ltp": 1.52, "tv": 11908.0, "trd": NaN, "batb": [[0, 1.45, 10.26], [1, 1.43, 194.39], [2, 1.41, 60.89]], "batl": NaN}, {"timestamp": 1631533255520, "ltp": 1.52, "tv": 11908.0, "trd": NaN, "batb": [[1, 1.44, 324.78], [2, 1.43, 426.05]], "batl": [[2, 1.65, 184.74]]}, {"timestamp": 1631533256911, "ltp": 1.52, "tv": 11908.0, "trd": NaN, "batb": [[0, 1.46, 54.88], [1, 1.45, 10.26], [2, 1.44, 330.78]], "batl": NaN}, {"timestamp": 1631533259510, "ltp": 1.52, "tv": 11908.0, "trd": NaN, "batb": NaN, "batl": [[2, 1.65, 0]]}, {"timestamp": 1631533262590, "ltp": 1.46, "tv": 12072.15, "trd": [[1.46, 41.78], [1.56, 988.16]], "batb": [[0, 1.45, 4.26], [1, 1.44, 330.78], [2, 1.43, 426.05]], "batl": [[0, 1.48, 212.15], [1, 1.49, 191.66], [2, 1.57, 16.36]]}, {"timestamp": 1631533263525, "ltp": 1.46, "tv": 12072.15, "trd": NaN, "batb": [[0, 1.45, 15.44]], "batl": [[2, 1.53, 7.5]]}, {"timestamp": 1631533264620, "ltp": 1.46, "tv": 12072.15, "trd": NaN, "batb": NaN, "batl": [[2, 1.57, 16.36]]}, {"timestamp": 1631533265618, "ltp": 1.46, "tv": 12072.15, "trd": NaN, "batb": [[0, 1.45, 36.74]], "batl": [[2, 1.56, 81.8]]}, {"timestamp": 1631533269531, "ltp": 1.46, "tv": 12072.15, "trd": NaN, "batb": NaN, "batl": [[2, 1.52, 40.26]]}, {"timestamp": 1631533270618, "ltp": 1.46, "tv": 12072.15, "trd": NaN, "batb": NaN, "batl": [[2, 1.51, 7.5]]}, {"timestamp": 1631533271612, "ltp": 1.46, "tv": 12072.15, "trd": NaN, "batb": NaN, "batl": [[0, 1.46, 10], [1, 1.48, 212.15], [2, 1.49, 191.66]]}, {"timestamp": 1631533272544, "ltp": 1.45, "tv": 12076.5, "trd": [[1.45, 33.25]], "batb": [[0, 1.45, 34.57]], "batl": [[0, 1.46, 10.72]]}, {"timestamp": 1631533273524, "ltp": 1.45, "tv": 12079.39, "trd": [[1.45, 36.15]], "batb": [[0, 1.45, 33.12]], "batl": NaN}, {"timestamp": 1631533274611, "ltp": 1.45, "tv": 12085.17, "trd": [[1.45, 41.93]], "batb": [[0, 1.45, 30.23]], "batl": [[1, 1.48, 196.55]]}, {"timestamp": 1631533275550, "ltp": 1.45, "tv": 12086.62, "trd": [[1.45, 43.37]], "batb": [[0, 1.45, 21.3]], "batl": [[0, 1.46, 10]]}, {"timestamp": 1631533277112, "ltp": 1.45, "tv": 12086.62, "trd": NaN, "batb": [[0, 1.44, 6], [1, 1.43, 33.63], [2, 1.38, 307.73]], "batl": [[1, 1.51, 7.5], [2, 1.52, 40.26]]}, {"timestamp": 1631533278617, "ltp": 1.45, "tv": 12086.62, "trd": NaN, "batb": [[0, 1.38, 307.73], [1, 1.37, 515.55], [2, 1.36, 754.02]], "batl": [[0, 1.46, 10.72], [1, 1.52, 40.26], [2, 1.55, 42.7]]}, {"timestamp": 1631533280439, "ltp": 1.45, "tv": 12086.62, "trd": NaN, "batb": [[1, 1.37, 711.21], [2, 1.36, 1045.57]], "batl": [[0, 1.46, 10]]}, {"timestamp": 1631533282521, "ltp": 1.45, "tv": 12086.62, "trd": NaN, "batb": [[0, 1.4, 8], [1, 1.39, 8], [2, 1.38, 307.73]], "batl": [[0, 1.55, 42.7], [1, 1.56, 535.62], [2, 1.57, 475.38]]}, {"timestamp": 1631533285222, "ltp": 1.45, "tv": 12086.62, "trd": NaN, "batb": NaN, "batl": [[1, 1.57, 16.36], [2, 1.57, 0]]}, {"timestamp": 1631533288344, "ltp": 1.38, "tv": 12262.6, "trd": [[1.38, 12.98], [1.39, 16], [1.4, 147]], "batb": [[0, 1.37, 711.21], [1, 1.36, 1045.57], [2, 1.33, 75.53]], "batl": [[0, 1.4, 259.97], [1, 1.41, 242.11], [2, 1.55, 42.7]]}, {"timestamp": 1631533289449, "ltp": 1.38, "tv": 12262.6, "trd": NaN, "batb": [[0, 1.37, 760.52]], "batl": [[2, 1.45, 7.5]]}, {"timestamp": 1631533291564, "ltp": 1.4, "tv": 12323.3, "trd": [[1.4, 207.7]], "batb": [[0, 1.37, 800.56]], "batl": [[0, 1.4, 229.62]]}, {"timestamp": 1631533293131, "ltp": 1.4, "tv": 12323.3, "trd": NaN, "batb": NaN, "batl": [[2, 1.49, 158.18]]}, {"timestamp": 1631533295262, "ltp": 1.4, "tv": 12323.3, "trd": NaN, "batb": NaN, "batl": [[2, 1.43, 66.5]]}, {"timestamp": 1631533298659, "ltp": 1.37, "tv": 12353.3, "trd": [[1.37, 30]], "batb": [[0, 1.37, 785.56]], "batl": [[0, 1.4, 321.62]]}, {"timestamp": 1631533302582, "ltp": 1.37, "tv": 12353.3, "trd": NaN, "batb": [[0, 1.37, 302.91], [1, 1.36, 536.4]], "batl": NaN}, {"timestamp": 1631533303633, "ltp": 1.37, "tv": 12353.3, "trd": NaN, "batb": [[0, 1.37, 51.48], [1, 1.32, 442.12], [2, 1.31, 727.22]], "batl": [[0, 1.43, 66.5], [1, 1.46, 339.75], [2, 1.47, 301.8]]}, {"timestamp": 1631533304461, "ltp": 1.37, "tv": 12353.3, "trd": NaN, "batb": [[0, 1.37, 2.17]], "batl": [[0, 1.46, 339.75], [1, 1.47, 301.8], [2, 1.48, 365.34]]}, {"timestamp": 1631533306336, "ltp": 1.37, "tv": 12353.3, "trd": NaN, "batb": [[2, 1.31, 1125.64]], "batl": [[0, 1.46, 629.6], [1, 1.47, 503.63]]}, {"timestamp": 1631533307640, "ltp": 1.37, "tv": 12353.3, "trd": NaN, "batb": NaN, "batl": [[0, 1.44, 16.36], [1, 1.46, 631.6], [2, 1.47, 503.63]]}, {"timestamp": 1631533308267, "ltp": 1.37, "tv": 12353.3, "trd": NaN, "batb": [[2, 1.31, 727.22]], "batl": [[1, 1.46, 341.75], [2, 1.47, 301.8]]}, {"timestamp": 1631533310461, "ltp": 1.37, "tv": 12353.3, "trd": NaN, "batb": NaN, "batl": [[0, 1.4, 19.34], [1, 1.43, 58.5], [2, 1.44, 16.36]]}, {"timestamp": 1631533310775, "ltp": 1.37, "tv": 12353.3, "trd": NaN, "batb": [[1, 1.36, 181.12], [2, 1.35, 301.99]], "batl": [[0, 1.39, 297.65], [1, 1.4, 249.43]]}, {"timestamp": 1631533314476, "ltp": 1.37, "tv": 12353.3, "trd": NaN, "batb": [[1, 1.32, 442.12], [2, 1.31, 727.22]], "batl": [[0, 1.44, 16.36], [1, 1.46, 341.75], [2, 1.47, 301.8]]}, {"timestamp": 1631533317653, "ltp": 1.37, "tv": 12353.3, "trd": NaN, "batb": [[2, 1.31, 1125.64]], "batl": [[0, 1.43, 59.5], [1, 1.44, 16.36], [2, 1.46, 631.6]]}, {"timestamp": 1631533317964, "ltp": 1.37, "tv": 12353.3, "trd": NaN, "batb": NaN, "batl": [[0, 1.44, 16.36], [1, 1.46, 631.6], [2, 1.47, 503.63]]}, {"timestamp": 1631533318786, "ltp": 1.37, "tv": 12353.3, "trd": NaN, "batb": NaN, "batl": [[0, 1.43, 7.23], [1, 1.44, 16.36], [2, 1.46, 631.6]]}, {"timestamp": 1631533320199, "ltp": 1.37, "tv": 12353.3, "trd": NaN, "batb": NaN, "batl": [[0, 1.44, 16.36], [1, 1.46, 631.6], [2, 1.47, 503.63]]}, {"timestamp": 1631533321201, "ltp": 1.37, "tv": 12353.3, "trd": NaN, "batb": NaN, "batl": [[0, 1.43, 63.5], [1, 1.44, 16.36], [2, 1.46, 631.6]]}, {"timestamp": 1631533321777, "ltp": 1.37, "tv": 12353.3, "trd": NaN, "batb": NaN, "batl": [[0, 1.44, 16.36], [1, 1.46, 631.6], [2, 1.47, 503.63]]}, {"timestamp": 1631533328392, "ltp": 1.37, "tv": 12353.3, "trd": NaN, "batb": NaN, "batl": [[0, 1.43, 65.5], [1, 1.44, 16.36], [2, 1.46, 631.6]]}, {"timestamp": 1631533328701, "ltp": 1.37, "tv": 12353.3, "trd": NaN, "batb": NaN, "batl": [[0, 1.44, 16.36], [1, 1.46, 631.6], [2, 1.47, 503.63]]}, {"timestamp": 1631533337104, "ltp": 1.37, "tv": 12353.3, "trd": NaN, "batb": NaN, "batl": [[1, 1.46, 63.25], [2, 44, 7.23]]}, {"timestamp": 1631533339603, "ltp": 1.37, "tv": 12357.64, "trd": [[1.37, 34.34]], "batb": [[0, 1.32, 442.12], [1, 1.31, 1125.64], [2, 1.3, 954.77]], "batl": NaN}, {"timestamp": 1631533340389, "ltp": 1.37, "tv": 12357.64, "trd": NaN, "batb": NaN, "batl": [[0, 1.34, 251.73], [1, 1.35, 296.99], [2, 1.44, 16.36]]}, {"timestamp": 1631533341426, "ltp": 1.37, "tv": 12357.64, "trd": NaN, "batb": [[0, 1.32, 495.15]], "batl": [[2, 1.4, 7.5]]}, {"timestamp": 1631533341899, "ltp": 1.37, "tv": 12357.64, "trd": NaN, "batb": NaN, "batl": [[2, 1.42, 81.8]]}, {"timestamp": 1631533344183, "ltp": 1.37, "tv": 12357.64, "trd": NaN, "batb": NaN, "batl": [[0, 1.34, 678.72]]}, {"timestamp": 1631533345599, "ltp": 1.37, "tv": 12357.64, "trd": NaN, "batb": NaN, "batl": [[0, 1.34, 761.72]]}, {"timestamp": 1631533346897, "ltp": 1.37, "tv": 12357.64, "trd": NaN, "batb": [[1, 1.31, 1154.7]], "batl": [[2, 1.41, 303.63]]}, {"timestamp": 1631533349596, "ltp": 1.37, "tv": 12357.64, "trd": NaN, "batb": NaN, "batl": [[2, 1.38, 7.5]]}, {"timestamp": 1631533350013, "ltp": 1.34, "tv": 12391.08, "trd": [[1.34, 33.44]], "batb": NaN, "batl": [[0, 1.34, 745]]}, {"timestamp": 1631533353895, "ltp": 1.32, "tv": 12459.8, "trd": [[1.32, 68.72]], "batb": [[0, 1.32, 460.79]], "batl": NaN}, {"timestamp": 1631533355041, "ltp": 1.32, "tv": 12484.8, "trd": [[1.32, 93.72]], "batb": [[0, 1.32, 448.29]], "batl": NaN}, {"timestamp": 1631533365209, "ltp": 1.32, "tv": 12484.8, "trd": NaN, "batb": [[0, 1.32, 463.29]], "batl": NaN}, {"timestamp": 1631533384426, "ltp": 1.32, "tv": 12484.8, "trd": NaN, "batb": [[0, 1.32, 448.29]], "batl": NaN}, {"timestamp": 1631533387543, "ltp": 1.34, "tv": 12514.96, "trd": [[1.32, 93.88], [1.34, 63.44]], "batb": [[0, 1.32, 448.21]], "batl": [[0, 1.34, 730]]}, {"timestamp": 1631533417479, "ltp": 1.32, "tv": 12515.12, "trd": [[1.32, 94.04]], "batb": [[0, 1.32, 448.13]], "batl": NaN}, {"timestamp": 1631533425600, "ltp": 1.32, "tv": 12919.42, "trd": [[1.32, 494.05], [1.34, 67.74]], "batb": [[0, 1.32, 248.13]], "batl": [[0, 1.34, 727.85]]}, {"timestamp": 1631533430125, "ltp": 1.32, "tv": 12919.42, "trd": NaN, "batb": NaN, "batl": [[2, 1.38, 75]]}, {"timestamp": 1631533483200, "ltp": 1.32, "tv": 12919.42, "trd": NaN, "batb": [[0, 1.32, 53.03], [1, 1.29, 464.8], [2, 1.28, 523.22]], "batl": [[0, 1.34, 83], [1, 1.38, 75], [2, 1.41, 367.85]]}, {"timestamp": 1631533484396, "ltp": 1.32, "tv": 12919.42, "trd": NaN, "batb": [[0, 1.29, 464.8], [1, 1.28, 523.22], [2, 1.27, 1039.85]], "batl": [[0, 1.41, 367.85], [1, 1.42, 321.63], [2, 1.43, 470.75]]}, {"timestamp": 1631533487634, "ltp": 1.32, "tv": 12919.42, "trd": NaN, "batb": [[0, 1.29, 472.8], [1, 1.28, 531.22]], "batl": [[0, 1.38, 6], [1, 1.39, 9], [2, 1.41, 373.85]]}, {"timestamp": 1631533489578, "ltp": 1.32, "tv": 12919.42, "trd": NaN, "batb": NaN, "batl": [[2, 1.4, 7]]}, {"timestamp": 1631533490457, "ltp": 1.32, "tv": 12919.42, "trd": NaN, "batb": [[0, 1.32, 449.86], [1, 1.31, 356.43], [2, 1.29, 472.8]], "batl": [[0, 1.35, 156.36], [1, 1.36, 287.14], [2, 1.38, 12.75]]}, {"timestamp": 1631533491131, "ltp": 1.32, "tv": 12919.42, "trd": NaN, "batb": NaN, "batl": [[2, 1.38, 84]]}, {"timestamp": 1631533493478, "ltp": 1.32, "tv": 12919.42, "trd": NaN, "batb": [[0, 1.29, 472.8], [1, 1.28, 531.22], [2, 1.27, 1039.85]], "batl": [[0, 1.38, 6], [1, 1.39, 9], [2, 1.4, 262.54]]}, {"timestamp": 1631533496238, "ltp": 1.32, "tv": 12919.42, "trd": NaN, "batb": [[1, 1.28, 768.5], [2, 1.27, 1459.16]], "batl": [[2, 1.4, 490.36]]}, {"timestamp": 1631533500544, "ltp": 1.32, "tv": 12919.42, "trd": NaN, "batb": [[1, 1.28, 760.5]], "batl": [[0, 1.4, 490.36], [1, 1.41, 610.22], [2, 1.42, 321.63]]}, {"timestamp": 1631533502596, "ltp": 1.32, "tv": 12919.42, "trd": NaN, "batb": [[0, 1.29, 95.81], [1, 1.27, 444.31], [2, 1.23, 255.54]], "batl": NaN}, {"timestamp": 1631533502858, "ltp": 1.32, "tv": 12919.42, "trd": NaN, "batb": [[0, 1.29, 8]], "batl": NaN}, {"timestamp": 1631533504651, "ltp": 1.32, "tv": 12919.42, "trd": NaN, "batb": [[0, 1.37, 13.14], [1, 1.29, 8], [2, 1.28, 10]], "batl": [[0, 1.39, 7], [1, 1.4, 490.36], [2, 1.41, 610.22]]}, {"timestamp": 1631533505589, "ltp": 1.32, "tv": 12919.42, "trd": NaN, "batb": [[0, 1.37, 226.8], [1, 1.36, 3104.39], [2, 1.35, 2729.78]], "batl": [[0, 1.4, 483.36], [1, 1.41, 610.22], [2, 1.42, 321.63]]}, {"timestamp": 1631533506584, "ltp": 1.32, "tv": 12919.42, "trd": NaN, "batb": [[1, 1.36, 1945.18], [2, 1.35, 1364.88]], "batl": [[0, 1.38, 14.49], [1, 1.4, 483.36], [2, 1.41, 610.22]]}, {"timestamp": 1631533507577, "ltp": 1.32, "tv": 12919.42, "trd": NaN, "batb": [[1, 1.36, 1995.18]], "batl": NaN}, {"timestamp": 1631533508564, "ltp": 1.32, "tv": 12919.42, "trd": NaN, "batb": [[0, 1.37, 233.8], [1, 1.36, 2001.18]], "batl": NaN}, {"timestamp": 1631533510602, "ltp": 1.32, "tv": 12919.42, "trd": NaN, "batb": [[1, 1.36, 1951.18]], "batl": NaN}, {"timestamp": 1631533511584, "ltp": 1.32, "tv": 12919.42, "trd": NaN, "batb": [[0, 1.37, 279.94]], "batl": NaN}, {"timestamp": 1631533513101, "ltp": 1.32, "tv": 12919.42, "trd": NaN, "batb": [[0, 1.37, 329.25]], "batl": NaN}, {"timestamp": 1631533519614, "ltp": 1.32, "tv": 12919.42, "trd": NaN, "batb": [[0, 1.37, 49.31], [1, 1.33, 377.11], [2, 1.32, 741.28]], "batl": [[0, 1.4, 255.54], [1, 1.41, 6.72], [2, 1.43, 7.5]]}, {"timestamp": 1631533520613, "ltp": 1.32, "tv": 12919.42, "trd": NaN, "batb": [[0, 1.33, 377.11], [1, 1.32, 741.28], [2, 1.31, 416.54]], "batl": [[2, 1.44, 77.19]]}, {"timestamp": 1631533522515, "ltp": 1.32, "tv": 12919.42, "trd": NaN, "batb": [[1, 1.32, 1118], [2, 1.31, 771.85]], "batl": NaN}, {"timestamp": 1631533523613, "ltp": 1.32, "tv": 12919.42, "trd": NaN, "batb": [[0, 1.33, 386.11], [1, 1.32, 1127]], "batl": NaN}, {"timestamp": 1631533524293, "ltp": 1.32, "tv": 12919.42, "trd": NaN, "batb": NaN, "batl": [[0, 1.44, 16.36], [1, 1.47, 199.3], [2, 1.48, 720.97]]}, {"timestamp": 1631533527597, "ltp": 1.32, "tv": 12919.42, "trd": NaN, "batb": NaN, "batl": [[0, 1.44, 77.69]]}, {"timestamp": 1631533528424, "ltp": 1.32, "tv": 12919.42, "trd": NaN, "batb": [[0, 1.33, 9], [1, 1.32, 378.08], [2, 1.3, 255.54]], "batl": [[0, 1.44, 21.36]]}, {"timestamp": 1631533530093, "ltp": 1.44, "tv": 12948.7, "trd": [[1.44, 29.28]], "batb": NaN, "batl": [[0, 1.44, 1.72]]}, {"timestamp": 1631533531414, "ltp": 1.44, "tv": 12952.14, "trd": [[1.44, 32.72]], "batb": [[0, 1.44, 164.73], [1, 1.43, 231.01], [2, 1.34, 1675]], "batl": [[0, 1.47, 199.3], [1, 1.48, 720.97], [2, 1.49, 315.43]]}, {"timestamp": 1631533532524, "ltp": 1.44, "tv": 12980.12, "trd": [[1.44, 60.7]], "batb": [[0, 1.44, 150.74], [1, 1.43, 429.75], [2, 1.41, 46.85]], "batl": NaN}, {"timestamp": 1631533534619, "ltp": 1.44, "tv": 12980.12, "trd": NaN, "batb": [[0, 1.44, 158.74], [1, 1.43, 436.75]], "batl": NaN}, {"timestamp": 1631533536644, "ltp": 1.44, "tv": 12980.12, "trd": NaN, "batb": [[0, 1.44, 203.74], [2, 1.42, 255.54]], "batl": NaN}, {"timestamp": 1631533538636, "ltp": 1.47, "tv": 13080.12, "trd": [[1.47, 449.13]], "batb": NaN, "batl": [[0, 1.47, 149.3]]}, {"timestamp": 1631533540624, "ltp": 1.47, "tv": 13080.12, "trd": NaN, "batb": [[2, 1.42, 301.83]], "batl": NaN}, {"timestamp": 1631533542543, "ltp": 1.44, "tv": 13084.7, "trd": [[1.44, 65.28]], "batb": [[0, 1.44, 199.16]], "batl": NaN}, {"timestamp": 1631533546616, "ltp": 1.44, "tv": 13084.7, "trd": NaN, "batb": NaN, "batl": [[0, 1.47, 201.3]]}, {"timestamp": 1631533546833, "ltp": 1.44, "tv": 13084.7, "trd": NaN, "batb": [[1, 1.43, 429.75]], "batl": NaN}, {"timestamp": 1631533550037, "ltp": 1.44, "tv": 13084.7, "trd": NaN, "batb": [[1, 1.43, 437.75]], "batl": NaN}, {"timestamp": 1631533551657, "ltp": 1.44, "tv": 13084.7, "trd": NaN, "batb": [[0, 1.42, 301.83], [1, 1.4, 255.54], [2, 1.39, 376.48]], "batl": [[0, 1.48, 255.54], [1, 1.5, 7.5], [2, 1.53, 46.5]]}, {"timestamp": 1631533552452, "ltp": 1.44, "tv": 13084.7, "trd": NaN, "batb": [[0, 1.42, 255.54]], "batl": [[1, 1.53, 46.5], [2, 1.56, 324.64]]}, {"timestamp": 1631533553644, "ltp": 1.44, "tv": 13084.7, "trd": NaN, "batb": [[0, 1.39, 376.48], [1, 1.38, 588.8], [2, 1.37, 600.67]], "batl": [[0, 1.53, 46.5], [1, 1.56, 324.64], [2, 1.57, 346.45]]}, {"timestamp": 1631533554535, "ltp": 1.44, "tv": 13084.7, "trd": NaN, "batb": [[1, 1.38, 978], [2, 1.37, 884.37]], "batl": [[0, 1.55, 169.96], [1, 1.56, 485.44]]}, {"timestamp": 1631533556469, "ltp": 1.44, "tv": 13084.7, "trd": NaN, "batb": NaN, "batl": [[0, 1.57, 46.5], [1, 1.77, 507.52], [2, 44, 7.23]]}, {"timestamp": 1631533557339, "ltp": 1.44, "tv": 13084.7, "trd": NaN, "batb": NaN, "batl": [[0, 1.54, 7], [1, 1.55, 7], [2, 1.56, 5]]}, {"timestamp": 1631533559648, "ltp": 1.39, "tv": 13113.48, "trd": [[1.39, 44.78]], "batb": [[0, 1.39, 362.1]], "batl": [[0, 1.42, 290.76], [1, 1.43, 227.42], [2, 1.54, 7]]}, {"timestamp": 1631533560433, "ltp": 1.39, "tv": 13113.48, "trd": NaN, "batb": [[2, 1.37, 933.68]], "batl": [[2, 1.45, 7.5]]}, {"timestamp": 1631533561556, "ltp": 1.39, "tv": 13113.48, "trd": NaN, "batb": [[0, 1.39, 400.1]], "batl": NaN}, {"timestamp": 1631533563644, "ltp": 1.39, "tv": 13113.48, "trd": NaN, "batb": NaN, "batl": [[1, 1.43, 482.96]]}, {"timestamp": 1631533564572, "ltp": 1.39, "tv": 13113.48, "trd": NaN, "batb": NaN, "batl": [[0, 1.42, 377.76], [2, 1.52, 35]]}, {"timestamp": 1631533566437, "ltp": 1.39, "tv": 13113.48, "trd": NaN, "batb": NaN, "batl": [[2, 1.49, 51.5]]}, {"timestamp": 1631533568583, "ltp": 1.39, "tv": 13113.48, "trd": NaN, "batb": NaN, "batl": [[2, 1.44, 7.5]]}, {"timestamp": 1631533571284, "ltp": 1.39, "tv": 13113.48, "trd": NaN, "batb": NaN, "batl": [[0, 1.42, 374.73]]}, {"timestamp": 1631533579583, "ltp": 1.39, "tv": 13113.48, "trd": NaN, "batb": [[0, 1.38, 622.92], [1, 1.37, 333.01], [2, 1.33, 76.53]], "batl": NaN}, {"timestamp": 1631533580057, "ltp": 1.39, "tv": 13113.48, "trd": NaN, "batb": [[0, 1.37, 49.31], [1, 1.32, 364.82], [2, 1.3, 255.54]], "batl": [[0, 1.43, 255.54], [1, 1.44, 7.5], [2, 1.49, 51.5]]}, {"timestamp": 1631533581390, "ltp": 1.39, "tv": 13113.48, "trd": NaN, "batb": [[0, 1.32, 364.82], [1, 1.3, 255.54], [2, 1.29, 81.81]], "batl": [[1, 1.49, 51.5], [2, 1.53, 47.5]]}, {"timestamp": 1631533583266, "ltp": 1.39, "tv": 13113.48, "trd": NaN, "batb": [[0, 1.33, 356.78], [1, 1.32, 704.91], [2, 1.3, 255.54]], "batl": [[2, 1.51, 298.86]]}, {"timestamp": 1631533584569, "ltp": 1.39, "tv": 13113.48, "trd": NaN, "batb": [[1, 1.32, 713.91], [2, 1.31, 8]], "batl": [[0, 1.51, 298.86], [1, 1.52, 176.96], [2, 1.53, 47.5]]}, {"timestamp": 1631533586507, "ltp": 1.39, "tv": 13113.48, "trd": NaN, "batb": [[0, 1.33, 365.78]], "batl": NaN}, {"timestamp": 1631533587513, "ltp": 1.39, "tv": 13113.48, "trd": NaN, "batb": NaN, "batl": [[0, 1.49, 55.5], [1, 1.5, 5], [2, 1.51, 304.86]]}, {"timestamp": 1631533587778, "ltp": 1.39, "tv": 13113.48, "trd": NaN, "batb": NaN, "batl": [[0, 1.49, 7], [2, 1.51, 6]]}, {"timestamp": 1631533590420, "ltp": 1.39, "tv": 13113.48, "trd": NaN, "batb": NaN, "batl": [[0, 1.35, 14.81], [1, 1.37, 2791.98], [2, 1.38, 2709.86]]}, {"timestamp": 1631533591614, "ltp": 1.39, "tv": 13113.48, "trd": NaN, "batb": NaN, "batl": [[1, 1.36, 284.47], [2, 1.37, 1671.83]]}, {"timestamp": 1631533592531, "ltp": 1.39, "tv": 13113.48, "trd": NaN, "batb": [[0, 1.33, 415.75], [1, 1.32, 766.94]], "batl": NaN}, {"timestamp": 1631533595558, "ltp": 1.39, "tv": 13113.48, "trd": NaN, "batb": NaN, "batl": [[1, 1.36, 540.01]]}, {"timestamp": 1631533597543, "ltp": 1.39, "tv": 13113.48, "trd": NaN, "batb": [[1, 1.32, 757.94], [2, 1.3, 255.54]], "batl": NaN}, {"timestamp": 1631533600143, "ltp": 1.35, "tv": 13133.0, "trd": [[1.35, 19.52]], "batb": NaN, "batl": [[0, 1.35, 5.05]]}, {"timestamp": 1631533607258, "ltp": 1.35, "tv": 13143.1, "trd": [[1.35, 29.62]], "batb": [[0, 1.35, 8.73], [1, 1.33, 415.75], [2, 1.32, 757.94]], "batl": [[0, 1.36, 540.01], [1, 1.37, 1671.83], [2, 1.38, 1362.42]]}, {"timestamp": 1631533608471, "ltp": 1.35, "tv": 13143.1, "trd": NaN, "batb": [[1, 1.32, 53.03], [2, 1.3, 255.54]], "batl": [[0, 1.36, 255.54], [1, 1.38, 7.5], [2, 1.43, 6.5]]}, {"timestamp": 1631533609460, "ltp": 1.35, "tv": 13143.1, "trd": NaN, "batb": [[1, 1.29, 487.86], [2, 1.28, 554.11]], "batl": [[1, 1.43, 6.5], [2, 1.45, 261.94]]}, {"timestamp": 1631533610526, "ltp": 1.35, "tv": 13160.56, "trd": [[1.35, 47.08]], "batb": [[0, 1.29, 487.86], [1, 1.28, 554.11], [2, 1.27, 885.95]], "batl": NaN}, {"timestamp": 1631533611478, "ltp": 1.35, "tv": 13160.56, "trd": NaN, "batb": [[1, 1.28, 756.07], [2, 1.27, 1304.78]], "batl": [[1, 1.43, 73], [2, 1.44, 64.16]]}, {"timestamp": 1631533612583, "ltp": 1.35, "tv": 13160.56, "trd": NaN, "batb": [[1, 1.28, 554.11], [2, 1.27, 885.95]], "batl": NaN}, {"timestamp": 1631533614151, "ltp": 1.35, "tv": 13160.56, "trd": NaN, "batb": NaN, "batl": [[0, 1.45, 261.94], [1, 1.46, 410.13], [2, 1.47, 525.57]]}, {"timestamp": 1631533616281, "ltp": 1.35, "tv": 13160.56, "trd": NaN, "batb": [[0, 1.34, 441.59], [1, 1.33, 329.32], [2, 1.29, 487.86]], "batl": [[0, 1.38, 371.61], [1, 1.39, 256.96], [2, 1.45, 261.94]]}, {"timestamp": 1631533617434, "ltp": 1.35, "tv": 13160.56, "trd": NaN, "batb": NaN, "batl": [[2, 1.42, 93.32]]}, {"timestamp": 1631533617963, "ltp": 1.35, "tv": 13160.56, "trd": NaN, "batb": [[0, 1.36, 2.32], [1, 1.34, 441.59], [2, 1.33, 329.32]], "batl": NaN}, {"timestamp": 1631533619378, "ltp": 1.35, "tv": 13160.56, "trd": NaN, "batb": [[1, 1.34, 697.13]], "batl": NaN}, {"timestamp": 1631533620481, "ltp": 1.35, "tv": 13160.56, "trd": NaN, "batb": [[1, 1.35, 151.69], [2, 1.34, 697.13]], "batl": NaN}, {"timestamp": 1631533621585, "ltp": 1.35, "tv": 13160.56, "trd": NaN, "batb": [[2, 1.34, 441.59]], "batl": NaN}, {"timestamp": 1631533622575, "ltp": 1.35, "tv": 13160.56, "trd": NaN, "batb": [[2, 1.29, 487.86]], "batl": [[0, 1.42, 93.32], [1, 1.43, 67.5], [2, 1.45, 267.94]]}, {"timestamp": 1631533622841, "ltp": 1.35, "tv": 13160.56, "trd": NaN, "batb": [[1, 1.29, 487.86], [2, 1.28, 554.11]], "batl": [[0, 1.43, 6], [1, 1.45, 267.94], [2, 1.46, 410.13]]}, {"timestamp": 1631533625351, "ltp": 1.35, "tv": 13160.56, "trd": NaN, "batb": [[2, 1.28, 756.07]], "batl": [[1, 1.45, 597.32], [2, 1.46, 618.04]]}, {"timestamp": 1631533629468, "ltp": 1.35, "tv": 13160.56, "trd": NaN, "batb": NaN, "batl": [[0, 1.43, 58.5], [1, 1.45, 591.32]]}, {"timestamp": 1631533630096, "ltp": 1.35, "tv": 13160.56, "trd": NaN, "batb": NaN, "batl": [[0, 1.43, 6]]}, {"timestamp": 1631533631657, "ltp": 1.35, "tv": 13160.56, "trd": NaN, "batb": [[1, 1.29, 81.81], [2, 1.27, 450.83]], "batl": NaN}, {"timestamp": 1631533632593, "ltp": 1.35, "tv": 13160.56, "trd": NaN, "batb": [[1, 1.27, 450.83], [2, 1.26, 357.52]], "batl": NaN}, {"timestamp": 1631533634609, "ltp": 1.35, "tv": 13160.56, "trd": NaN, "batb": [[0, 1.41, 277.5], [1, 1.4, 2987.16], [2, 1.39, 2651.78]], "batl": [[0, 1.45, 591.32], [1, 1.46, 618.04], [2, 1.47, 3127.61]]}, {"timestamp": 1631533635618, "ltp": 1.35, "tv": 13160.56, "trd": NaN, "batb": [[1, 1.4, 1837.33], [2, 1.39, 1325.88]], "batl": [[0, 1.42, 14.08], [1, 1.45, 591.32], [2, 1.46, 618.04]]}, {"timestamp": 1631533636400, "ltp": 1.35, "tv": 13160.56, "trd": NaN, "batb": NaN, "batl": [[2, 1.46, 625.54]]}, {"timestamp": 1631533637600, "ltp": 1.35, "tv": 13160.56, "trd": NaN, "batb": [[0, 1.41, 334.2], [1, 1.4, 1844.33]], "batl": NaN}, {"timestamp": 1631533639639, "ltp": 1.35, "tv": 13160.56, "trd": NaN, "batb": [[0, 1.41, 589.74]], "batl": NaN}, {"timestamp": 1631533640637, "ltp": 1.35, "tv": 13160.56, "trd": NaN, "batb": NaN, "batl": [[1, 1.45, 593.23]]}, {"timestamp": 1631533641558, "ltp": 1.35, "tv": 13160.56, "trd": NaN, "batb": [[0, 1.41, 1019.89]], "batl": NaN}, {"timestamp": 1631533642352, "ltp": 1.35, "tv": 13160.56, "trd": NaN, "batb": [[2, 1.39, 1373.91]], "batl": [[1, 1.45, 591.32]]}, {"timestamp": 1631533643441, "ltp": 1.41, "tv": 13186.94, "trd": [[1.41, 26.38]], "batb": [[0, 1.41, 1006.7]], "batl": NaN}, {"timestamp": 1631533652352, "ltp": 1.41, "tv": 13186.94, "trd": NaN, "batb": [[1, 1.4, 1837.33]], "batl": NaN}, {"timestamp": 1631533654502, "ltp": 1.41, "tv": 13186.94, "trd": NaN, "batb": [[0, 1.41, 255.54], [1, 1.39, 48.03], [2, 1.34, 521.46]], "batl": [[0, 1.46, 7.5], [1, 1.47, 6.16], [2, 1.48, 6.74]]}, {"timestamp": 1631533655476, "ltp": 1.41, "tv": 13186.94, "trd": NaN, "batb": [[1, 1.34, 521.46], [2, 1.33, 722.93]], "batl": [[0, 1.49, 255.54], [1, 1.55, 50.1], [2, 1.57, 46.5]]}, {"timestamp": 1631533656564, "ltp": 1.41, "tv": 13186.94, "trd": NaN, "batb": [[0, 1.34, 521.46], [1, 1.33, 467.39], [2, 1.32, 819.37]], "batl": [[0, 1.58, 269.38], [1, 1.59, 294.28], [2, 1.6, 419.73]]}, {"timestamp": 1631533657592, "ltp": 1.41, "tv": 13186.94, "trd": NaN, "batb": [[1, 1.33, 917.85], [2, 1.32, 1161.95]], "batl": [[0, 1.57, 219.27], [1, 1.58, 422.45], [2, 1.59, 294.28]]}, {"timestamp": 1631533659579, "ltp": 1.41, "tv": 13186.94, "trd": NaN, "batb": NaN, "batl": [[0, 1.54, 6], [1, 1.55, 6], [2, 1.57, 219.27]]}, {"timestamp": 1631533660460, "ltp": 1.41, "tv": 13186.94, "trd": NaN, "batb": [[1, 1.33, 467.39], [2, 1.32, 819.37]], "batl": [[0, 1.56, 7], [1, 1.57, 5], [2, 1.58, 269.38]]}, {"timestamp": 1631533663370, "ltp": 1.41, "tv": 13186.94, "trd": NaN, "batb": NaN, "batl": [[0, 1.55, 43.7], [1, 1.56, 7], [2, 1.57, 5]]}, {"timestamp": 1631533664567, "ltp": 1.41, "tv": 13186.94, "trd": NaN, "batb": NaN, "batl": [[0, 1.56, 7], [1, 1.57, 5], [2, 1.58, 269.38]]}, {"timestamp": 1631533667187, "ltp": 1.41, "tv": 13186.94, "trd": NaN, "batb": [[1, 1.33, 917.85], [2, 1.32, 1161.95]], "batl": [[1, 1.57, 224.27], [2, 1.58, 422.45]]}, {"timestamp": 1631533674410, "ltp": 1.41, "tv": 13186.94, "trd": NaN, "batb": NaN, "batl": [[0, 1.55, 6], [1, 1.77, 507.52], [2, 44, 7.23]]}, {"timestamp": 1631533676622, "ltp": 1.41, "tv": 13186.94, "trd": NaN, "batb": NaN, "batl": [[0, 1.37, 2345.76], [1, 1.55, 6], [2, 1.77, 507.52]]}, {"timestamp": 1631533677609, "ltp": 1.41, "tv": 13186.94, "trd": NaN, "batb": NaN, "batl": [[0, 1.35, 14.81], [1, 1.37, 1797.7], [2, 1.38, 1620.17]]}, {"timestamp": 1631533678595, "ltp": 1.41, "tv": 13186.94, "trd": NaN, "batb": [[2, 1.32, 1214.98]], "batl": NaN}, {"timestamp": 1631533679525, "ltp": 1.41, "tv": 13186.94, "trd": NaN, "batb": [[0, 1.34, 560.64]], "batl": NaN}, {"timestamp": 1631533683626, "ltp": 1.41, "tv": 13186.94, "trd": NaN, "batb": NaN, "batl": [[2, 1.38, 1631.45]]}, {"timestamp": 1631533688923, "ltp": 1.35, "tv": 13191.58, "trd": [[1.35, 51.73]], "batb": NaN, "batl": [[0, 1.35, 12.49]]}, {"timestamp": 1631533690118, "ltp": 1.34, "tv": 13391.58, "trd": [[1.34, 267.74]], "batb": [[0, 1.34, 460.64]], "batl": NaN}, {"timestamp": 1631533694622, "ltp": 1.35, "tv": 13397.09, "trd": [[1.35, 57.24]], "batb": NaN, "batl": [[0, 1.35, 6.98]]}, {"timestamp": 1631533699233, "ltp": 1.35, "tv": 13397.09, "trd": NaN, "batb": [[0, 1.32, 53.03], [1, 1.29, 538.19], [2, 1.28, 388.12]], "batl": [[0, 1.38, 11.28], [1, 1.43, 60], [2, 1.46, 352.41]]}, {"timestamp": 1631533700435, "ltp": 1.35, "tv": 13397.09, "trd": NaN, "batb": [[0, 1.29, 538.19], [1, 1.28, 388.12], [2, 1.27, 1008.41]], "batl": [[0, 1.38, 3.78], [1, 1.46, 352.41], [2, 1.47, 353.94]]}, {"timestamp": 1631533700799, "ltp": 1.35, "tv": 13397.09, "trd": NaN, "batb": NaN, "batl": [[0, 1.46, 352.41], [1, 1.47, 353.94], [2, 1.48, 450.96]]}, {"timestamp": 1631533702619, "ltp": 1.35, "tv": 13397.09, "trd": NaN, "batb": [[0, 1.33, 9], [1, 1.32, 10], [2, 1.29, 538.19]], "batl": NaN}, {"timestamp": 1631533703607, "ltp": 1.35, "tv": 13397.09, "trd": NaN, "batb": [[0, 1.31, 4], [1, 1.3, 4], [2, 1.29, 542.19]], "batl": NaN}, {"timestamp": 1631533703920, "ltp": 1.35, "tv": 13397.09, "trd": NaN, "batb": [[0, 1.29, 538.19], [1, 1.28, 388.12], [2, 1.27, 1008.41]], "batl": [[0, 1.46, 359.41]]}, {"timestamp": 1631533705536, "ltp": 1.35, "tv": 13397.09, "trd": NaN, "batb": [[0, 1.35, 292.08], [1, 1.34, 315.05], [2, 1.29, 538.19]], "batl": [[0, 1.38, 216.67], [1, 1.39, 258.73], [2, 1.45, 5]]}, {"timestamp": 1631533706524, "ltp": 1.35, "tv": 13397.09, "trd": NaN, "batb": NaN, "batl": [[2, 1.43, 69.28]]}, {"timestamp": 1631533708645, "ltp": 1.35, "tv": 13397.09, "trd": NaN, "batb": [[0, 1.29, 538.19], [1, 1.28, 388.12], [2, 1.27, 1008.41]], "batl": [[0, 1.36, 218], [1, 1.43, 8], [2, 1.44, 6]]}, {"timestamp": 1631533708850, "ltp": 1.35, "tv": 13397.09, "trd": NaN, "batb": NaN, "batl": [[0, 1.43, 8], [1, 1.44, 6], [2, 1.45, 5]]}, {"timestamp": 1631533711521, "ltp": 1.35, "tv": 13397.09, "trd": NaN, "batb": [[1, 1.28, 759.21], [2, 1.27, 1430.58]], "batl": [[0, 1.43, 66.35], [2, 1.45, 191.98]]}, {"timestamp": 1631533712163, "ltp": 1.35, "tv": 13397.09, "trd": NaN, "batb": [[0, 1.27, 446.4], [1, 1.26, 101.98], [2, 1.23, 523.6]], "batl": [[0, 1.43, 8]]}, {"timestamp": 1631533713660, "ltp": 1.35, "tv": 13397.09, "trd": NaN, "batb": [[0, 1.41, 832.92], [1, 1.27, 446.4], [2, 1.26, 101.98]], "batl": NaN}, {"timestamp": 1631533714521, "ltp": 1.35, "tv": 13397.09, "trd": NaN, "batb": [[0, 1.4, 2732.14], [1, 1.39, 2651.78], [2, 1.38, 2651.78]], "batl": [[0, 1.45, 186.98], [1, 1.46, 561.48], [2, 1.47, 2955.98]]}, {"timestamp": 1631533715561, "ltp": 1.42, "tv": 13425.25, "trd": [[1.42, 28.16]], "batb": [[0, 1.42, 148.09], [1, 1.41, 246.02], [2, 1.4, 1366.08]], "batl": [[2, 1.47, 1069.5]]}, {"timestamp": 1631533716550, "ltp": 1.42, "tv": 13425.25, "trd": NaN, "batb": [[1, 1.41, 457.31]], "batl": [[1, 1.46, 568.98]]}, {"timestamp": 1631533716959, "ltp": 1.42, "tv": 13425.25, "trd": NaN, "batb": [[0, 1.42, 156.09], [1, 1.41, 463.31]], "batl": NaN}, {"timestamp": 1631533717944, "ltp": 1.42, "tv": 13425.25, "trd": NaN, "batb": [[2, 1.4, 1374.08]], "batl": NaN}, {"timestamp": 1631533719556, "ltp": 1.42, "tv": 13425.25, "trd": NaN, "batb": NaN, "batl": [[1, 1.46, 674.77]]}, {"timestamp": 1631533720138, "ltp": 1.42, "tv": 13425.25, "trd": NaN, "batb": NaN, "batl": [[1, 1.46, 568.98]]}, {"timestamp": 1631533731590, "ltp": 1.42, "tv": 13425.25, "trd": NaN, "batb": [[0, 1.42, 148.09], [1, 1.41, 457.31], [2, 1.39, 48.03]], "batl": [[1, 1.46, 216.57], [2, 1.47, 6.33]]}, {"timestamp": 1631533732477, "ltp": 1.42, "tv": 13425.25, "trd": NaN, "batb": [[0, 1.34, 359.05], [1, 1.33, 729.79], [2, 1.32, 554.45]], "batl": [[0, 1.58, 310.78], [1, 1.59, 302.57], [2, 1.6, 410.06]]}, {"timestamp": 1631533735581, "ltp": 1.42, "tv": 13425.25, "trd": NaN, "batb": NaN, "batl": [[0, 1.57, 40.5], [1, 1.58, 310.78], [2, 1.59, 302.57]]}, {"timestamp": 1631533736591, "ltp": 1.42, "tv": 13425.25, "trd": NaN, "batb": NaN, "batl": [[0, 1.58, 316.78], [1, 1.59, 302.57], [2, 1.6, 410.06]]}, {"timestamp": 1631533739257, "ltp": 1.42, "tv": 13425.25, "trd": NaN, "batb": [[0, 1.44, 190.33], [1, 1.43, 231.35], [2, 1.34, 359.05]], "batl": [[0, 1.48, 323.68], [1, 1.49, 191.4], [2, 1.57, 44.5]]}, {"timestamp": 1631533740384, "ltp": 1.42, "tv": 13425.25, "trd": NaN, "batb": [[0, 1.34, 359.05], [1, 1.33, 729.79], [2, 1.32, 554.45]], "batl": [[0, 1.57, 44.5], [1, 1.58, 316.78], [2, 1.59, 302.57]]}, {"timestamp": 1631533741188, "ltp": 1.42, "tv": 13425.25, "trd": NaN, "batb": NaN, "batl": [[0, 1.57, 5]]}, {"timestamp": 1631533743183, "ltp": 1.42, "tv": 13425.25, "trd": NaN, "batb": [[0, 1.34, 637.17], [1, 1.33, 1056.96]], "batl": [[1, 1.58, 580.49], [2, 1.59, 451.94]]}, {"timestamp": 1631533746507, "ltp": 1.42, "tv": 13425.25, "trd": NaN, "batb": [[0, 1.33, 345.01], [1, 1.28, 585.76], [2, 1.27, 97.87]], "batl": NaN}, {"timestamp": 1631533747507, "ltp": 1.42, "tv": 13425.25, "trd": NaN, "batb": NaN, "batl": [[0, 1.57, 47.5]]}, {"timestamp": 1631533748297, "ltp": 1.42, "tv": 13425.25, "trd": NaN, "batb": [[1, 1.28, 93.16]], "batl": [[0, 1.58, 574.49], [1, 1.59, 451.94], [2, 1.6, 410.06]]}, {"timestamp": 1631533749488, "ltp": 1.42, "tv": 13425.25, "trd": NaN, "batb": [[0, 1.53, 248.81], [1, 1.52, 179.47], [2, 1.38, 1043.71]], "batl": [[2, 1.6, 1067.49]]}, {"timestamp": 1631533750386, "ltp": 1.53, "tv": 13451.75, "trd": [[1.53, 1160]], "batb": [[0, 1.53, 235.56], [2, 1.51, 156.48]], "batl": [[0, 1.54, 7.5], [1, 1.58, 574.49], [2, 1.59, 451.94]]}, {"timestamp": 1631533752380, "ltp": 1.53, "tv": 13451.75, "trd": NaN, "batb": [[1, 1.52, 184.47], [2, 1.51, 162.48]], "batl": [[0, 1.58, 574.49], [1, 1.59, 451.94], [2, 1.6, 1067.49]]}, {"timestamp": 1631533754576, "ltp": 1.53, "tv": 13451.75, "trd": NaN, "batb": NaN, "batl": [[0, 1.58, 464.39], [1, 1.59, 302.57]]}, {"timestamp": 1631533755635, "ltp": 1.53, "tv": 13451.75, "trd": NaN, "batb": NaN, "batl": [[0, 1.56, 7.5], [1, 1.58, 464.39], [2, 1.59, 302.57]]}, {"timestamp": 1631533756529, "ltp": 1.53, "tv": 13451.75, "trd": NaN, "batb": NaN, "batl": [[2, 1.59, 342.07]]}, {"timestamp": 1631533757417, "ltp": 1.53, "tv": 13451.75, "trd": NaN, "batb": NaN, "batl": [[1, 1.57, 133.54], [2, 1.58, 464.39]]}, {"timestamp": 1631533761824, "ltp": 1.53, "tv": 13479.19, "trd": [[1.53, 1187.44]], "batb": [[0, 1.53, 221.84]], "batl": NaN}, {"timestamp": 1631533763392, "ltp": 1.53, "tv": 13479.19, "trd": NaN, "batb": [[0, 1.54, 35.87], [1, 1.53, 221.84], [2, 1.52, 184.47]], "batl": NaN}, {"timestamp": 1631533767512, "ltp": 1.54, "tv": 13479.43, "trd": [[1.54, 888.64]], "batb": [[0, 1.54, 35.75]], "batl": NaN}, {"timestamp": 1631533776634, "ltp": 1.54, "tv": 13479.43, "trd": NaN, "batb": [[0, 1.44, 190.96], [1, 1.43, 57.43], [2, 1.38, 65.96]], "batl": [[1, 1.61, 36.5], [2, 1.62, 39.75]]}, {"timestamp": 1631533777429, "ltp": 1.54, "tv": 13479.43, "trd": NaN, "batb": NaN, "batl": [[0, 1.64, 36.18], [1, 1.95, 415.52], [2, 44, 7.23]]}, {"timestamp": 1631533779620, "ltp": 1.54, "tv": 13479.43, "trd": NaN, "batb": [[0, 1.48, 43.3], [1, 1.45, 292.52], [2, 1.44, 416.37]], "batl": [[1, 1.66, 230.05], [2, 1.67, 125.53]]}, {"timestamp": 1631533780645, "ltp": 1.54, "tv": 13479.43, "trd": NaN, "batb": [[0, 1.44, 190.96], [1, 1.43, 57.43], [2, 1.38, 65.96]], "batl": [[0, 1.63, 6], [1, 1.64, 36.18], [2, 1.95, 415.52]]}, {"timestamp": 1631533783429, "ltp": 1.54, "tv": 13479.43, "trd": NaN, "batb": NaN, "batl": [[0, 1.61, 44.5], [1, 1.62, 5], [2, 1.63, 6]]}, {"timestamp": 1631533784625, "ltp": 1.54, "tv": 13479.43, "trd": NaN, "batb": [[0, 1.51, 292.65], [1, 1.5, 189.77], [2, 1.45, 137.81]], "batl": [[0, 1.56, 260.16], [1, 1.57, 156.74], [2, 1.61, 6]]}, {"timestamp": 1631533785347, "ltp": 1.54, "tv": 13479.43, "trd": NaN, "batb": [[0, 1.44, 190.96], [1, 1.43, 57.43], [2, 1.38, 65.96]], "batl": [[0, 1.61, 6], [1, 1.62, 5], [2, 1.63, 6]]}, {"timestamp": 1631533788230, "ltp": 1.54, "tv": 13479.43, "trd": NaN, "batb": [[0, 1.45, 292.52], [1, 1.44, 416.37], [2, 1.43, 57.43]], "batl": NaN}, {"timestamp": 1631533789322, "ltp": 1.54, "tv": 13479.43, "trd": NaN, "batb": [[0, 1.44, 190.96], [1, 1.43, 57.43], [2, 1.38, 65.96]], "batl": NaN}, {"timestamp": 1631533790461, "ltp": 1.54, "tv": 13479.43, "trd": NaN, "batb": NaN, "batl": [[0, 1.61, 51.5]]}, {"timestamp": 1631533791628, "ltp": 1.54, "tv": 13479.43, "trd": NaN, "batb": NaN, "batl": [[0, 1.61, 6]]}, {"timestamp": 1631533792661, "ltp": 1.54, "tv": 13479.43, "trd": NaN, "batb": [[0, 1.61, 157.5], [1, 1.6, 147], [2, 1.44, 190.96]], "batl": [[0, 1.64, 36.18], [1, 1.66, 230.05], [2, 1.67, 125.53]]}, {"timestamp": 1631533793450, "ltp": 1.61, "tv": 13505.07, "trd": [[1.61, 71.64]], "batb": [[0, 1.61, 144.68], [2, 1.58, 131.13]], "batl": [[1, 1.66, 237.55]]}, {"timestamp": 1631533800571, "ltp": 1.61, "tv": 13511.87, "trd": [[1.61, 78.44]], "batb": [[0, 1.61, 141.28]], "batl": NaN}, {"timestamp": 1631533805653, "ltp": 1.61, "tv": 13511.87, "trd": NaN, "batb": [[0, 1.56, 40.08], [1, 1.54, 286.65], [2, 1.53, 327.92]], "batl": [[0, 1.66, 7.5], [1, 1.71, 32.81], [2, 1.73, 274.37]]}, {"timestamp": 1631533806636, "ltp": 1.61, "tv": 13511.87, "trd": NaN, "batb": [[0, 1.54, 286.65], [1, 1.53, 327.92], [2, 1.52, 318.29]], "batl": [[0, 1.71, 32.81], [1, 1.73, 274.37], [2, 1.74, 256.81]]}, {"timestamp": 1631533808365, "ltp": 1.61, "tv": 13511.87, "trd": NaN, "batb": [[2, 1.52, 586.93]], "batl": [[2, 1.74, 403.13]]}, {"timestamp": 1631533809164, "ltp": 1.61, "tv": 13511.87, "trd": NaN, "batb": [[2, 1.52, 318.29]], "batl": [[2, 1.74, 256.81]]}, {"timestamp": 1631533809888, "ltp": 1.61, "tv": 13511.87, "trd": NaN, "batb": NaN, "batl": [[0, 1.71, 36.81]]}, {"timestamp": 1631533812358, "ltp": 1.61, "tv": 13511.87, "trd": NaN, "batb": [[0, 1.59, 188.06], [1, 1.58, 154.27], [2, 1.54, 286.65]], "batl": [[0, 1.64, 227.87], [1, 1.65, 130.98], [2, 1.68, 38.39]]}, {"timestamp": 1631533813352, "ltp": 1.61, "tv": 13511.87, "trd": NaN, "batb": NaN, "batl": [[2, 1.68, 63.39]]}, {"timestamp": 1631533814489, "ltp": 1.61, "tv": 13511.87, "trd": NaN, "batb": [[0, 1.54, 286.65], [1, 1.53, 327.92], [2, 1.52, 318.29]], "batl": [[0, 1.68, 38.39], [1, 1.71, 36.81], [2, 1.73, 274.37]]}, {"timestamp": 1631533814867, "ltp": 1.61, "tv": 13511.87, "trd": NaN, "batb": NaN, "batl": [[0, 1.68, 5]]}, {"timestamp": 1631533816569, "ltp": 1.61, "tv": 13511.87, "trd": NaN, "batb": [[0, 1.6, 92.31], [1, 1.54, 286.65], [2, 1.53, 327.92]], "batl": NaN}, {"timestamp": 1631533817395, "ltp": 1.61, "tv": 13511.87, "trd": NaN, "batb": [[0, 1.54, 286.65], [1, 1.53, 327.92], [2, 1.52, 586.93]], "batl": NaN}, {"timestamp": 1631533819598, "ltp": 1.61, "tv": 13511.87, "trd": NaN, "batb": [[0, 1.5, 160.5], [1, 1.45, 56.61], [2, 1.38, 454.63]], "batl": NaN}, {"timestamp": 1631533819968, "ltp": 1.61, "tv": 13511.87, "trd": NaN, "batb": [[2, 1.25, 237.69]], "batl": NaN}, {"timestamp": 1631533822601, "ltp": 1.61, "tv": 13511.87, "trd": NaN, "batb": [[0, 1.69, 151.59], [1, 1.67, 249.97], [2, 1.66, 1152.12]], "batl": [[0, 1.71, 32.81], [1, 1.73, 274.37], [2, 1.74, 403.13]]}, {"timestamp": 1631533823381, "ltp": 1.69, "tv": 13536.57, "trd": [[1.69, 65.96]], "batb": [[0, 1.69, 139.24], [2, 1.66, 1262.24]], "batl": NaN}, {"timestamp": 1631533825304, "ltp": 1.69, "tv": 13536.57, "trd": NaN, "batb": [[1, 1.68, 5], [2, 1.67, 253.97]], "batl": NaN}, {"timestamp": 1631533827607, "ltp": 1.69, "tv": 13536.57, "trd": NaN, "batb": [[0, 1.7, 139.15], [1, 1.69, 139.24], [2, 1.68, 5]], "batl": NaN}, {"timestamp": 1631533828495, "ltp": 1.69, "tv": 13536.57, "trd": NaN, "batb": [[0, 1.7, 32.24]], "batl": NaN}, {"timestamp": 1631533829305, "ltp": 1.69, "tv": 13536.57, "trd": NaN, "batb": NaN, "batl": [[2, 1.74, 441.38]]}, {"timestamp": 1631533831522, "ltp": 1.7, "tv": 13540.17, "trd": [[1.7, 55.07]], "batb": [[0, 1.7, 30.44]], "batl": NaN}, {"timestamp": 1631533838256, "ltp": 1.7, "tv": 13547.9, "trd": [[1.7, 62.81]], "batb": [[0, 1.7, 26.57]], "batl": NaN}, {"timestamp": 1631533841609, "ltp": 1.7, "tv": 13547.9, "trd": NaN, "batb": [[0, 1.66, 36.92], [1, 1.63, 237.61], [2, 1.62, 352.72]], "batl": [[0, 1.76, 37.02], [1, 1.78, 35.25], [2, 1.8, 275.26]]}, {"timestamp": 1631533842436, "ltp": 1.7, "tv": 13547.9, "trd": NaN, "batb": [[0, 1.63, 237.61], [1, 1.62, 352.72], [2, 1.61, 294.15]], "batl": [[0, 1.78, 35.25], [1, 1.8, 275.26], [2, 1.81, 244.97]]}, {"timestamp": 1631533843222, "ltp": 1.7, "tv": 13547.9, "trd": NaN, "batb": [[0, 1.73, 20.67], [1, 1.63, 237.61], [2, 1.62, 352.72]], "batl": NaN}, {"timestamp": 1631533844625, "ltp": 1.7, "tv": 13547.9, "trd": NaN, "batb": NaN, "batl": [[0, 1.75, 5], [1, 1.78, 35.25], [2, 1.8, 275.26]]}, {"timestamp": 1631533845630, "ltp": 1.7, "tv": 13547.9, "trd": NaN, "batb": NaN, "batl": [[1, 1.76, 5], [2, 1.77, 5]]}, {"timestamp": 1631533846516, "ltp": 1.73, "tv": 13551.52, "trd": [[1.73, 152.49]], "batb": [[0, 1.73, 18.86]], "batl": NaN}, {"timestamp": 1631533848433, "ltp": 1.73, "tv": 13589.24, "trd": [[1.73, 190.21]], "batb": [[0, 1.67, 192.61], [1, 1.66, 128.61], [2, 1.63, 237.61]], "batl": [[0, 1.72, 127.11], [1, 1.74, 220], [2, 1.75, 35.1]]}, {"timestamp": 1631533849638, "ltp": 1.73, "tv": 13589.24, "trd": NaN, "batb": NaN, "batl": [[2, 1.75, 163.1]]}, {"timestamp": 1631533850629, "ltp": 1.73, "tv": 13589.24, "trd": NaN, "batb": [[0, 1.63, 237.61], [1, 1.62, 352.72], [2, 1.61, 294.15]], "batl": [[0, 1.75, 5], [1, 1.76, 5], [2, 1.77, 5]]}, {"timestamp": 1631533853444, "ltp": 1.73, "tv": 13589.24, "trd": NaN, "batb": [[2, 1.61, 466.96]], "batl": NaN}, {"timestamp": 1631533855249, "ltp": 1.73, "tv": 13589.24, "trd": NaN, "batb": [[0, 1.58, 131.29], [1, 1.54, 43.62], [2, 1.53, 45.33]], "batl": NaN}, {"timestamp": 1631533857647, "ltp": 1.73, "tv": 13589.24, "trd": NaN, "batb": [[0, 1.74, 2198.28], [1, 1.73, 2133.62], [2, 1.72, 2133.62]], "batl": [[0, 1.75, 31.14], [1, 1.78, 35.25], [2, 1.8, 275.26]]}, {"timestamp": 1631533858652, "ltp": 1.76, "tv": 13613.34, "trd": [[1.76, 224.1]], "batb": [[0, 1.76, 157.02], [1, 1.74, 1315.88], [2, 1.73, 1162.8]], "batl": [[0, 1.78, 35.25], [1, 1.8, 275.26], [2, 1.81, 244.97]]}, {"timestamp": 1631533859425, "ltp": 1.76, "tv": 13613.34, "trd": NaN, "batb": [[1, 1.74, 1350.75]], "batl": NaN}, {"timestamp": 1631533860531, "ltp": 1.76, "tv": 13613.34, "trd": NaN, "batb": [[1, 1.75, 5], [2, 1.74, 1355.75]], "batl": NaN}, {"timestamp": 1631533862619, "ltp": 1.76, "tv": 13616.88, "trd": [[1.76, 227.64]], "batb": [[0, 1.76, 155.25]], "batl": [[0, 1.78, 101.24]]}, {"timestamp": 1631533863527, "ltp": 1.76, "tv": 13616.88, "trd": NaN, "batb": [[0, 1.77, 34.98], [1, 1.76, 155.25], [2, 1.75, 5]], "batl": [[0, 1.78, 35.25]]}, {"timestamp": 1631533865139, "ltp": 1.76, "tv": 13616.88, "trd": NaN, "batb": NaN, "batl": [[1, 1.79, 35.5], [2, 1.8, 307.78]]}, {"timestamp": 1631533866549, "ltp": 1.76, "tv": 13616.88, "trd": NaN, "batb": [[2, 1.75, 39.64]], "batl": NaN}, {"timestamp": 1631533868364, "ltp": 1.76, "tv": 13616.88, "trd": NaN, "batb": [[0, 1.75, 34.64], [1, 1.71, 239.28], [2, 1.7, 248.96]], "batl": [[0, 1.82, 142.54], [1, 1.84, 230.64], [2, 1.85, 264.11]]}, {"timestamp": 1631533869459, "ltp": 1.76, "tv": 13616.88, "trd": NaN, "batb": [[0, 1.71, 239.28], [1, 1.7, 248.96], [2, 1.69, 374.11]], "batl": NaN}, {"timestamp": 1631533871536, "ltp": 1.76, "tv": 13616.88, "trd": NaN, "batb": [[1, 1.7, 417.5]], "batl": [[0, 1.8, 30.67], [1, 1.81, 5], [2, 1.82, 146.54]]}, {"timestamp": 1631533872369, "ltp": 1.76, "tv": 13616.88, "trd": NaN, "batb": NaN, "batl": [[0, 1.81, 5], [1, 1.82, 146.54], [2, 1.84, 230.64]]}, {"timestamp": 1631533873261, "ltp": 1.76, "tv": 13616.88, "trd": NaN, "batb": [[1, 1.7, 248.96]], "batl": NaN}, {"timestamp": 1631533876175, "ltp": 1.76, "tv": 13616.88, "trd": NaN, "batb": [[0, 1.75, 141.58], [1, 1.73, 221], [2, 1.71, 239.28]], "batl": [[0, 1.81, 203.87], [2, 1.83, 186.26]]}, {"timestamp": 1631533878164, "ltp": 1.76, "tv": 13616.88, "trd": NaN, "batb": [[0, 1.71, 239.28], [1, 1.7, 248.96], [2, 1.69, 374.11]], "batl": [[0, 1.81, 5], [2, 1.84, 230.64]]}, {"timestamp": 1631533881169, "ltp": 1.76, "tv": 13616.88, "trd": NaN, "batb": [[1, 1.7, 417.5]], "batl": NaN}, {"timestamp": 1631533882630, "ltp": 1.76, "tv": 13616.88, "trd": NaN, "batb": [[0, 1.67, 108.53], [1, 1.65, 36.73], [2, 1.59, 6]], "batl": [[0, 1.82, 142.54], [1, 1.84, 230.64], [2, 1.85, 264.11]]}, {"timestamp": 1631533885546, "ltp": 1.76, "tv": 13616.88, "trd": NaN, "batb": [[0, 1.81, 193.89], [1, 1.79, 197.06], [2, 1.67, 108.53]], "batl": [[0, 1.82, 29.25]]}, {"timestamp": 1631533886642, "ltp": 1.81, "tv": 13640.54, "trd": [[1.81, 23.66]], "batb": [[0, 1.81, 182.06], [1, 1.79, 283.25], [2, 1.69, 104.6]], "batl": NaN}, {"timestamp": 1631533887630, "ltp": 1.81, "tv": 13640.54, "trd": NaN, "batb": [[1, 1.79, 288.25], [2, 1.78, 4]], "batl": NaN}, {"timestamp": 1631533888621, "ltp": 1.81, "tv": 13640.54, "trd": NaN, "batb": [[1, 1.8, 5], [2, 1.79, 288.25]], "batl": [[1, 1.83, 113.29], [2, 1.84, 230.64]]}, {"timestamp": 1631533889614, "ltp": 1.82, "tv": 13698.72, "trd": [[1.82, 58.18]], "batb": NaN, "batl": [[0, 1.83, 113.45], [1, 1.84, 230.64], [2, 1.85, 264.11]]}, {"timestamp": 1631533890294, "ltp": 1.82, "tv": 13782.62, "trd": [[1.82, 142.08]], "batb": [[0, 1.82, 30.01], [1, 1.81, 182.06], [2, 1.8, 5]], "batl": [[0, 1.83, 113.29]]}, {"timestamp": 1631533896650, "ltp": 1.82, "tv": 13782.62, "trd": NaN, "batb": [[1, 1.81, 215.39]], "batl": [[1, 1.86, 347.63], [2, 1.88, 180.47]]}, {"timestamp": 1631533899623, "ltp": 1.82, "tv": 13842.64, "trd": [[1.82, 202.1]], "batb": [[0, 1.81, 215.39], [1, 1.8, 5], [2, 1.79, 288.25]], "batl": [[0, 1.82, 19.99], [1, 1.83, 113.29], [2, 1.86, 347.63]]}, {"timestamp": 1631533900430, "ltp": 1.82, "tv": 13842.64, "trd": NaN, "batb": [[2, 1.79, 283.25]], "batl": NaN}, {"timestamp": 1631533904130, "ltp": 1.82, "tv": 13882.62, "trd": [[1.82, 242.08]], "batb": NaN, "batl": [[0, 1.83, 113.29], [1, 1.86, 347.63], [2, 1.88, 180.47]]}, {"timestamp": 1631533905649, "ltp": 1.82, "tv": 13882.62, "trd": NaN, "batb": [[0, 1.81, 182.06]], "batl": NaN}, {"timestamp": 1631533907362, "ltp": 1.81, "tv": 13886.63, "trd": [[1.81, 27.66]], "batb": [[0, 1.81, 180.06]], "batl": NaN}, {"timestamp": 1631533908356, "ltp": 1.83, "tv": 13932.49, "trd": [[1.83, 45.86]], "batb": [[0, 1.81, 211.94]], "batl": [[0, 1.83, 90.36]]}, {"timestamp": 1631533909032, "ltp": 1.83, "tv": 14022.85, "trd": [[1.83, 136.22]], "batb": NaN, "batl": [[0, 1.88, 180.47], [1, 1.9, 165.48], [2, 1.99, 231.42]]}, {"timestamp": 1631533911584, "ltp": 1.83, "tv": 14027.85, "trd": [[1.83, 141.22]], "batb": NaN, "batl": NaN}, {"timestamp": 1631533911955, "ltp": 1.83, "tv": 14027.85, "trd": NaN, "batb": NaN, "batl": [[2, 1.93, 7.5]]}, {"timestamp": 1631533923291, "ltp": 1.83, "tv": 14029.85, "trd": [[1.83, 143.22]], "batb": NaN, "batl": NaN}, {"timestamp": 1631533946124, "ltp": 1.83, "tv": 14030.12, "trd": [[1.83, 143.49]], "batb": NaN, "batl": NaN}, {"timestamp": 1631533971168, "ltp": 1.83, "tv": 14030.12, "trd": NaN, "batb": [[0, 1.81, 212.8]], "batl": NaN}, {"timestamp": 1631533980576, "ltp": 1.87, "tv": 14069.12, "trd": [[1.87, 39]], "batb": NaN, "batl": NaN}, {"timestamp": 1631533981882, "ltp": 1.87, "tv": 14069.12, "trd": NaN, "batb": [[0, 1.81, 180.92]], "batl": NaN}, {"timestamp": 1631533995586, "ltp": 1.87, "tv": 14069.12, "trd": NaN, "batb": NaN, "batl": [[0, 1.86, 3.84], [1, 1.88, 180.47], [2, 1.9, 165.48]]}, {"timestamp": 1631534000086, "ltp": 1.87, "tv": 14069.12, "trd": NaN, "batb": [[0, 1.81, 210.69]], "batl": NaN}, {"timestamp": 1631534007516, "ltp": 1.87, "tv": 14069.12, "trd": NaN, "batb": [[0, 1.77, 35.04], [1, 1.72, 263.33], [2, 1.71, 357.28]], "batl": [[1, 1.93, 7.5], [2, 1.99, 231.42]]}, {"timestamp": 1631534008487, "ltp": 1.87, "tv": 14069.12, "trd": NaN, "batb": [[0, 1.72, 264.19], [1, 1.71, 357.28], [2, 1.7, 385.32]], "batl": [[1, 1.99, 231.42], [2, 2, 232.66]]}, {"timestamp": 1631534010426, "ltp": 1.87, "tv": 14069.12, "trd": NaN, "batb": [[1, 1.71, 555.8]], "batl": NaN}, {"timestamp": 1631534012016, "ltp": 1.87, "tv": 14069.12, "trd": NaN, "batb": NaN, "batl": [[0, 1.86, 4.8]]}, {"timestamp": 1631534017043, "ltp": 1.87, "tv": 14069.12, "trd": NaN, "batb": NaN, "batl": [[0, 1.86, 3.84]]}, {"timestamp": 1631534019552, "ltp": 1.87, "tv": 14069.12, "trd": NaN, "batb": [[0, 1.71, 35.05], [1, 1.69, 104.6], [2, 1.64, 40.07]], "batl": NaN}, {"timestamp": 1631534020229, "ltp": 1.87, "tv": 14069.12, "trd": NaN, "batb": [[0, 1.69, 104.6], [1, 1.64, 40.07], [2, 1.3, 198.07]], "batl": NaN}, {"timestamp": 1631534021334, "ltp": 1.86, "tv": 14076.8, "trd": [[1.86, 7.68]], "batb": NaN, "batl": [[0, 2, 232.66], [1, 2.02, 312.17], [2, 2.04, 184.34]]}, {"timestamp": 1631534022642, "ltp": 1.86, "tv": 14076.8, "trd": NaN, "batb": [[0, 1.96, 138.54], [1, 1.94, 152.05], [2, 1.93, 990.94]], "batl": NaN}, {"timestamp": 1631534023635, "ltp": 1.96, "tv": 14099.28, "trd": [[1.96, 22.48]], "batb": [[0, 1.96, 127.3]], "batl": NaN}, {"timestamp": 1631534025565, "ltp": 1.96, "tv": 14099.28, "trd": NaN, "batb": [[1, 1.94, 156.05], [2, 1.93, 994.94]], "batl": NaN}, {"timestamp": 1631534026621, "ltp": 1.96, "tv": 14099.28, "trd": NaN, "batb": NaN, "batl": [[0, 2, 207.47]]}, {"timestamp": 1631534027457, "ltp": 1.96, "tv": 14177.07, "trd": [[1.96, 100.27]], "batb": [[0, 1.96, 88.41]], "batl": NaN}, {"timestamp": 1631534030649, "ltp": 1.96, "tv": 14177.07, "trd": NaN, "batb": [[0, 1.96, 110]], "batl": [[2, 2.04, 211.77]]}, {"timestamp": 1631534037649, "ltp": 1.96, "tv": 14177.07, "trd": NaN, "batb": [[1, 1.94, 152.05], [2, 1.92, 69.04]], "batl": [[0, 2.04, 211.77], [1, 2.06, 129.63], [2, 2.08, 7.21]]}, {"timestamp": 1631534038646, "ltp": 1.96, "tv": 14177.07, "trd": NaN, "batb": [[0, 1.84, 281.35], [1, 1.83, 270.58], [2, 1.82, 343.07]], "batl": [[0, 2.2, 163.25], [1, 2.22, 265.63], [2, 2.24, 270.1]]}, {"timestamp": 1631534040575, "ltp": 1.96, "tv": 14177.07, "trd": NaN, "batb": [[2, 1.82, 547.3]], "batl": [[2, 2.24, 440.02]]}, {"timestamp": 1631534042053, "ltp": 1.96, "tv": 14177.07, "trd": NaN, "batb": [[2, 1.82, 343.07]], "batl": [[0, 2.2, 166.25], [2, 2.24, 270.1]]}, {"timestamp": 1631534044570, "ltp": 1.96, "tv": 14177.07, "trd": NaN, "batb": NaN, "batl": [[0, 2.02, 20.25], [1, 2.2, 166.25], [2, 2.22, 265.63]]}, {"timestamp": 1631534045462, "ltp": 1.96, "tv": 14177.07, "trd": NaN, "batb": NaN, "batl": [[0, 2.18, 6.25]]}, {"timestamp": 1631534046563, "ltp": 1.96, "tv": 14177.07, "trd": NaN, "batb": [[0, 1.85, 109.29], [1, 1.84, 281.35], [2, 1.83, 270.58]], "batl": [[0, 2.18, 57.55]]}, {"timestamp": 1631534048654, "ltp": 1.96, "tv": 14177.07, "trd": NaN, "batb": [[0, 1.84, 281.35], [1, 1.83, 270.58], [2, 1.82, 343.07]], "batl": [[0, 2.2, 166.25], [1, 2.22, 265.63], [2, 2.24, 270.1]]}, {"timestamp": 1631534056604, "ltp": 1.96, "tv": 14177.07, "trd": NaN, "batb": NaN, "batl": [[0, 2.18, 4], [1, 2.2, 166.25], [2, 2.22, 265.63]]}, {"timestamp": 1631534061477, "ltp": 1.96, "tv": 14177.07, "trd": NaN, "batb": NaN, "batl": [[1, 2.2, 3], [2, 2.28, 6.34]]}, {"timestamp": 1631534064409, "ltp": 1.84, "tv": 14200.59, "trd": [[1.84, 23.52]], "batb": [[0, 1.82, 547.3], [1, 1.8, 278.57], [2, 1.77, 35.37]], "batl": [[0, 1.89, 163.37], [1, 1.91, 162.85], [2, 1.94, 2028.8]]}, {"timestamp": 1631534065501, "ltp": 1.84, "tv": 14200.59, "trd": NaN, "batb": [[1, 1.81, 162.29], [2, 1.8, 359.72]], "batl": NaN}, {"timestamp": 1631534067584, "ltp": 1.84, "tv": 14200.59, "trd": NaN, "batb": [[0, 1.82, 579.95]], "batl": NaN}, {"timestamp": 1631534068468, "ltp": 1.84, "tv": 14200.59, "trd": NaN, "batb": NaN, "batl": [[0, 1.89, 167.37]]}, {"timestamp": 1631534069606, "ltp": 1.82, "tv": 14204.42, "trd": [[1.82, 245.92]], "batb": [[0, 1.82, 578.03]], "batl": NaN}, {"timestamp": 1631534070599, "ltp": 1.82, "tv": 14204.42, "trd": NaN, "batb": [[0, 1.82, 545.38]], "batl": NaN}, {"timestamp": 1631534072610, "ltp": 1.82, "tv": 14204.42, "trd": NaN, "batb": NaN, "batl": [[0, 1.84, 4], [1, 1.89, 167.37], [2, 1.91, 162.85]]}, {"timestamp": 1631534073405, "ltp": 1.82, "tv": 14204.42, "trd": NaN, "batb": [[0, 1.83, 32.65], [1, 1.82, 545.38], [2, 1.81, 162.29]], "batl": NaN}, {"timestamp": 1631534075415, "ltp": 1.82, "tv": 14204.42, "trd": NaN, "batb": NaN, "batl": [[1, 1.85, 5], [2, 1.89, 167.37]]}, {"timestamp": 1631534084925, "ltp": 1.82, "tv": 14204.42, "trd": NaN, "batb": NaN, "batl": [[0, 1.89, 163.37], [1, 1.91, 162.85], [2, 1.93, 7.5]]}, {"timestamp": 1631534092634, "ltp": 1.82, "tv": 14204.42, "trd": NaN, "batb": [[0, 1.82, 204.23], [1, 1.8, 278.57], [2, 1.77, 34.18]], "batl": [[0, 1.89, 161.37]]}, {"timestamp": 1631534093051, "ltp": 1.82, "tv": 14204.42, "trd": NaN, "batb": [[0, 1.77, 34.18], [1, 1.71, 32.19], [2, 1.69, 104.27]], "batl": [[0, 1.93, 7.5], [1, 2.04, 7.88], [2, 2.06, 7.75]]}, {"timestamp": 1631534094514, "ltp": 1.82, "tv": 14204.42, "trd": NaN, "batb": [[0, 1.71, 32.19], [1, 1.69, 104.27], [2, 1.67, 415.42]], "batl": [[0, 2.04, 7.88], [1, 2.06, 7.75], [2, 2.14, 7.25]]}, {"timestamp": 1631534094721, "ltp": 1.82, "tv": 14204.42, "trd": NaN, "batb": NaN, "batl": [[0, 2.14, 7.25], [1, 2.28, 6.34], [2, 2.5, 278.33]]}, {"timestamp": 1631534096437, "ltp": 1.82, "tv": 14204.42, "trd": NaN, "batb": [[0, 1.71, 192.64], [1, 1.69, 344.06]], "batl": [[0, 2.08, 187.26], [1, 2.1, 122.54], [2, 2.14, 7.25]]}, {"timestamp": 1631534098151, "ltp": 1.82, "tv": 14204.42, "trd": NaN, "batb": [[0, 1.71, 196.64], [1, 1.7, 4], [2, 1.69, 344.06]], "batl": [[0, 2.04, 3], [1, 2.08, 190.26], [2, 2.1, 122.54]]}, {"timestamp": 1631534099654, "ltp": 1.82, "tv": 14204.42, "trd": NaN, "batb": [[0, 1.75, 34.31], [1, 1.71, 36.19], [2, 1.7, 4]], "batl": [[1, 2.08, 3], [2, 2.14, 7.25]]}, {"timestamp": 1631534099913, "ltp": 1.82, "tv": 14204.42, "trd": NaN, "batb": [[0, 1.71, 36.19], [1, 1.7, 4], [2, 1.69, 104.27]], "batl": NaN}, {"timestamp": 1631534101640, "ltp": 1.82, "tv": 14204.42, "trd": NaN, "batb": [[0, 1.99, 1922.1], [1, 1.98, 4391.08], [2, 1.97, 1865.58]], "batl": [[0, 2.14, 7.25], [1, 2.28, 6.34], [2, 2.5, 278.33]]}, {"timestamp": 1631534102632, "ltp": 2.0, "tv": 14215.47, "trd": [[2, 11.05]], "batb": [[0, 1.99, 961.06], [1, 1.98, 956.81], [2, 1.97, 932.8]], "batl": NaN}, {"timestamp": 1631534103634, "ltp": 2.0, "tv": 14215.47, "trd": NaN, "batb": NaN, "batl": [[0, 2.1, 7.15], [1, 2.14, 7.25], [2, 2.28, 6.34]]}, {"timestamp": 1631534105038, "ltp": 2.0, "tv": 14215.47, "trd": NaN, "batb": [[0, 2, 3], [1, 1.99, 965.06], [2, 1.98, 956.81]], "batl": [[1, 2.12, 30.32], [2, 2.14, 7.25]]}, {"timestamp": 1631534106665, "ltp": 1.99, "tv": 14282.25, "trd": [[1.99, 55.78], [2, 22.05]], "batb": [[0, 1.99, 937.17], [1, 1.98, 956.81], [2, 1.97, 932.8]], "batl": NaN}, {"timestamp": 1631534107445, "ltp": 2.0, "tv": 14285.71, "trd": [[2, 25.51]], "batb": NaN, "batl": NaN}, {"timestamp": 1631534112252, "ltp": 2.0, "tv": 14285.71, "trd": NaN, "batb": [[0, 1.99, 966.55]], "batl": NaN}, {"timestamp": 1631534114448, "ltp": 2.0, "tv": 14285.71, "trd": NaN, "batb": [[0, 1.92, 31.27], [1, 1.85, 29.77], [2, 1.81, 83.01]], "batl": [[1, 2.32, 7.11], [2, 2.52, 6.51]]}, {"timestamp": 1631534115491, "ltp": 2.0, "tv": 14285.71, "trd": NaN, "batb": [[0, 1.85, 29.77], [1, 1.81, 83.01], [2, 1.79, 29.31]], "batl": [[0, 2.32, 7.11], [1, 2.52, 6.51], [2, 2.58, 5.44]]}, {"timestamp": 1631534115754, "ltp": 2.0, "tv": 14285.71, "trd": NaN, "batb": NaN, "batl": [[0, 2.52, 6.51], [1, 2.58, 5.44], [2, 2.82, 234.47]]}, {"timestamp": 1631534118164, "ltp": 2.0, "tv": 14285.71, "trd": NaN, "batb": [[2, 1.72, 5]], "batl": NaN}, {"timestamp": 1631534122560, "ltp": 2.0, "tv": 14285.71, "trd": NaN, "batb": [[0, 1.85, 33.77], [1, 1.84, 4], [2, 1.81, 83.01]], "batl": [[0, 2.3, 4], [1, 2.32, 5.36], [2, 2.52, 6.51]]}, {"timestamp": 1631534123388, "ltp": 2.0, "tv": 14285.71, "trd": NaN, "batb": NaN, "batl": [[1, 2.52, 6.51], [2, 2.58, 5.44]]}, {"timestamp": 1631534126373, "ltp": 2.0, "tv": 14285.71, "trd": NaN, "batb": NaN, "batl": [[1, 2.32, 6.61], [2, 2.52, 6.51]]}, {"timestamp": 1631534126682, "ltp": 2.0, "tv": 14285.71, "trd": NaN, "batb": NaN, "batl": [[1, 2.52, 6.51], [2, 2.58, 5.44]]}, {"timestamp": 1631534128873, "ltp": 2.0, "tv": 14285.71, "trd": NaN, "batb": [[0, 1.85, 29.77]], "batl": NaN}, {"timestamp": 1631534131360, "ltp": 1.85, "tv": 14309.11, "trd": [[1.85, 46.66]], "batb": [[0, 1.85, 18.07], [1, 1.84, 147.62], [2, 1.82, 186.48]], "batl": [[0, 1.9, 121.34], [1, 1.92, 1163.41], [2, 1.93, 966.8]]}, {"timestamp": 1631534132359, "ltp": 1.9, "tv": 14321.15, "trd": [[1.9, 150.8]], "batb": NaN, "batl": [[0, 1.9, 109.3]]}, {"timestamp": 1631534135402, "ltp": 1.85, "tv": 14324.86, "trd": [[1.85, 50.38]], "batb": [[0, 1.85, 16.21]], "batl": NaN}, {"timestamp": 1631534136399, "ltp": 1.9, "tv": 14374.2, "trd": [[1.85, 82.8], [1.9, 167.72]], "batb": [[0, 1.84, 147.62], [1, 1.82, 186.48], [2, 1.81, 83.01]], "batl": [[0, 1.9, 100.84]]}, {"timestamp": 1631534137881, "ltp": 1.9, "tv": 14374.2, "trd": NaN, "batb": NaN, "batl": [[1, 1.91, 6.34], [2, 1.92, 1163.41]]}, {"timestamp": 1631534142179, "ltp": 1.9, "tv": 14374.2, "trd": NaN, "batb": [[0, 1.84, 178.87]], "batl": NaN}, {"timestamp": 1631534143491, "ltp": 1.9, "tv": 14440.4, "trd": [[1.9, 233.92]], "batb": [[0, 1.9, 16.66], [1, 1.84, 178.87], [2, 1.82, 186.48]], "batl": [[0, 1.91, 6.34], [1, 1.92, 1003.14], [2, 1.93, 974.3]]}, {"timestamp": 1631534144111, "ltp": 1.9, "tv": 14440.4, "trd": NaN, "batb": [[0, 1.9, 17.51]], "batl": NaN}, {"timestamp": 1631534145618, "ltp": 1.9, "tv": 14440.4, "trd": NaN, "batb": [[0, 1.84, 178.87], [1, 1.82, 186.48], [2, 1.81, 83.01]], "batl": NaN}, {"timestamp": 1631534146307, "ltp": 1.9, "tv": 14440.4, "trd": NaN, "batb": [[0, 1.84, 200.26]], "batl": [[0, 1.91, 187.49], [2, 1.93, 1131.96]]}, {"timestamp": 1631534150610, "ltp": 1.91, "tv": 14475.22, "trd": [[1.91, 34.82]], "batb": NaN, "batl": [[0, 1.91, 170.09]]}, {"timestamp": 1631534151612, "ltp": 1.91, "tv": 14509.15, "trd": [[1.91, 68.74]], "batb": NaN, "batl": [[0, 1.91, 153.13]]}, {"timestamp": 1631534153601, "ltp": 1.91, "tv": 14509.15, "trd": NaN, "batb": [[0, 1.84, 215.86]], "batl": NaN}, {"timestamp": 1631534162331, "ltp": 1.91, "tv": 14509.15, "trd": NaN, "batb": [[0, 1.78, 33.96], [1, 1.74, 409.86], [2, 1.73, 39.13]], "batl": [[0, 1.93, 7.5], [1, 2.28, 3], [2, 2.32, 6.11]]}, {"timestamp": 1631534163453, "ltp": 1.91, "tv": 14509.15, "trd": NaN, "batb": [[0, 1.74, 409.86], [1, 1.73, 39.13], [2, 1.72, 34.34]], "batl": [[0, 2.28, 3], [1, 2.32, 6.11], [2, 2.52, 6.51]]}, {"timestamp": 1631534165539, "ltp": 1.91, "tv": 14509.15, "trd": NaN, "batb": [[0, 1.78, 36.66], [1, 1.74, 409.86], [2, 1.73, 39.13]], "batl": [[0, 2.16, 202.42], [1, 2.18, 116.85], [2, 2.28, 3]]}, {"timestamp": 1631534166640, "ltp": 1.91, "tv": 14509.15, "trd": NaN, "batb": [[0, 1.74, 414.86], [1, 1.73, 43.13], [2, 1.72, 34.34]], "batl": [[0, 2.14, 4], [1, 2.16, 202.42], [2, 2.18, 116.85]]}, {"timestamp": 1631534168435, "ltp": 1.91, "tv": 14509.15, "trd": NaN, "batb": NaN, "batl": [[1, 2.18, 6.75], [2, 2.28, 3]]}, {"timestamp": 1631534169326, "ltp": 1.91, "tv": 14509.15, "trd": NaN, "batb": NaN, "batl": [[0, 2.28, 3], [1, 2.32, 6.11], [2, 2.52, 6.51]]}, {"timestamp": 1631534172551, "ltp": 2.06, "tv": 14519.96, "trd": [[2.06, 10.81]], "batb": [[0, 2.02, 118.83], [1, 1.93, 31.1], [2, 1.89, 25]], "batl": [[0, 2.14, 7.02], [1, 2.26, 15], [2, 2.28, 3]]}, {"timestamp": 1631534173134, "ltp": 2.06, "tv": 14519.96, "trd": NaN, "batb": [[0, 2.06, 4], [1, 2.04, 4], [2, 2.02, 118.83]], "batl": NaN}, {"timestamp": 1631534176639, "ltp": 2.06, "tv": 14549.54, "trd": [[2.06, 40.4]], "batb": [[0, 2.04, 4], [1, 2.02, 118.83], [2, 1.82, 82.26]], "batl": NaN}, {"timestamp": 1631534177840, "ltp": 2.06, "tv": 14549.54, "trd": NaN, "batb": [[2, 1.91, 29.39]], "batl": NaN}, {"timestamp": 1631534179557, "ltp": 2.06, "tv": 14549.54, "trd": NaN, "batb": [[0, 2.06, 33.67], [1, 2.04, 4], [2, 2.02, 118.83]], "batl": NaN}, {"timestamp": 1631534181655, "ltp": 2.06, "tv": 14549.54, "trd": NaN, "batb": [[0, 2.04, 4], [1, 2.02, 118.83], [2, 1.95, 30.77]], "batl": [[1, 2.28, 3], [2, 2.32, 6.11]]}, {"timestamp": 1631534182653, "ltp": 2.06, "tv": 14549.54, "trd": NaN, "batb": [[1, 1.95, 30.77], [2, 1.91, 29.39]], "batl": [[2, 2.62, 5.25]]}, {"timestamp": 1631534183444, "ltp": 2.06, "tv": 14549.54, "trd": NaN, "batb": [[1, 1.91, 29.39], [2, 1.84, 28.47]], "batl": [[0, 2.08, 50]]}, {"timestamp": 1631534185367, "ltp": 2.06, "tv": 14549.54, "trd": NaN, "batb": [[0, 1.84, 28.47], [1, 1.82, 82.26], [2, 1.79, 5]], "batl": [[1, 2.62, 5.25], [2, 2.82, 234.47]]}, {"timestamp": 1631534188565, "ltp": 2.06, "tv": 14549.54, "trd": NaN, "batb": [[0, 1.91, 31.39], [1, 1.84, 33.47], [2, 1.83, 5]], "batl": [[1, 2.6, 5.76], [2, 2.62, 5.25]]}, {"timestamp": 1631534188764, "ltp": 2.06, "tv": 14549.54, "trd": NaN, "batb": [[0, 1.84, 33.47], [1, 1.83, 5], [2, 1.82, 82.26]], "batl": NaN}, {"timestamp": 1631534193173, "ltp": 2.06, "tv": 14549.54, "trd": NaN, "batb": NaN, "batl": [[0, 2.62, 5.25], [1, 2.82, 234.47], [2, 3.1, 3.75]]}, {"timestamp": 1631534195379, "ltp": 2.06, "tv": 14549.54, "trd": NaN, "batb": NaN, "batl": [[1, 3.1, 3.75], [2, 100, 0.96]]}, {"timestamp": 1631534196579, "ltp": 2.04, "tv": 14599.54, "trd": [[2.04, 50]], "batb": NaN, "batl": [[1, 100, 0.96], [2, 100, 0]]}, {"timestamp": 1631534197648, "ltp": 2.4, "tv": 14609.06, "trd": [[2.4, 9.52]], "batb": [[0, 2.34, 78.74], [1, 2.14, 100.25], [2, 1.84, 33.47]], "batl": NaN}, {"timestamp": 1631534198653, "ltp": 2.4, "tv": 14615.39, "trd": [[2.4, 15.85]], "batb": [[2, 1.85, 5]], "batl": [[0, 2.6, 26.25], [1, 2.62, 5.25], [2, 100, 0.96]]}, {"timestamp": 1631534199546, "ltp": 2.4, "tv": 14615.39, "trd": NaN, "batb": [[2, 2.04, 4]], "batl": [[2, 3.45, 182.89]]}, {"timestamp": 1631534201610, "ltp": 2.4, "tv": 14615.39, "trd": NaN, "batb": [[0, 2.36, 33.62], [1, 2.34, 78.74], [2, 2.14, 100.25]], "batl": [[0, 2.38, 6.22], [1, 2.6, 26.25], [2, 2.62, 5.25]]}, {"timestamp": 1631534202655, "ltp": 2.4, "tv": 14615.39, "trd": NaN, "batb": [[0, 2.38, 3], [1, 2.36, 4], [2, 2.34, 78.74]], "batl": [[0, 2.5, 24.49]]}, {"timestamp": 1631534205647, "ltp": 2.4, "tv": 14615.39, "trd": NaN, "batb": [[2, 2.34, 82.74]], "batl": NaN}, {"timestamp": 1631534208441, "ltp": 2.4, "tv": 14615.39, "trd": NaN, "batb": [[0, 2.4, 15], [1, 2.38, 3], [2, 2.36, 4]], "batl": NaN}, {"timestamp": 1631534209228, "ltp": 2.4, "tv": 14616.17, "trd": [[2.4, 16.63]], "batb": [[0, 2.4, 14.61]], "batl": NaN}, {"timestamp": 1631534215467, "ltp": 2.4, "tv": 14616.17, "trd": NaN, "batb": NaN, "batl": [[0, 2.6, 26.25], [1, 2.62, 5.25], [2, 2.64, 5.18]]}, {"timestamp": 1631534215731, "ltp": 2.4, "tv": 14616.17, "trd": NaN, "batb": [[2, 2.34, 82.74]], "batl": NaN}, {"timestamp": 1631534218543, "ltp": 2.4, "tv": 14616.17, "trd": NaN, "batb": NaN, "batl": [[0, 2.54, 24.17], [1, 2.6, 26.25], [2, 2.62, 5.25]]}, {"timestamp": 1631534218758, "ltp": 2.4, "tv": 14616.17, "trd": NaN, "batb": [[2, 2.34, 78.74]], "batl": NaN}, {"timestamp": 1631534223567, "ltp": 2.4, "tv": 14616.17, "trd": NaN, "batb": [[0, 2.38, 3], [1, 2.34, 78.74], [2, 2.3, 23.07]], "batl": [[1, 2.64, 5.18], [2, 2.8, 4.52]]}, {"timestamp": 1631534223988, "ltp": 2.4, "tv": 14616.17, "trd": NaN, "batb": [[0, 2.3, 23.07], [1, 2.18, 7.36], [2, 2.14, 108.57]], "batl": [[1, 2.8, 4.52], [2, 2.82, 5.25]]}, {"timestamp": 1631534225451, "ltp": 2.4, "tv": 14616.17, "trd": NaN, "batb": [[0, 2.14, 100.25], [1, 2.12, 7.54], [2, 1.92, 400.36]], "batl": [[0, 2.8, 4.52], [1, 2.82, 5.25], [2, 3.45, 182.89]]}, {"timestamp": 1631534228589, "ltp": 2.4, "tv": 14616.17, "trd": NaN, "batb": [[0, 2.18, 6.36], [1, 2.14, 103.25], [2, 2.12, 11.54]], "batl": [[0, 2.7, 3], [1, 2.8, 4.52], [2, 2.82, 5.25]]}, {"timestamp": 1631534228800, "ltp": 2.4, "tv": 14616.17, "trd": NaN, "batb": [[0, 2.14, 103.25], [1, 2.12, 11.54], [2, 1.92, 400.36]], "batl": NaN}, {"timestamp": 1631534231568, "ltp": 2.4, "tv": 14616.17, "trd": NaN, "batb": [[2, 1.4, 148.56]], "batl": [[0, 2.8, 4.52], [1, 2.82, 5.25], [2, 100, 0.96]]}, {"timestamp": 1631534232567, "ltp": 2.58, "tv": 14625.26, "trd": [[2.58, 9.09]], "batb": [[0, 2.52, 64.1], [1, 2.32, 81.42], [2, 2.14, 103.25]], "batl": NaN}, {"timestamp": 1631534233562, "ltp": 2.58, "tv": 14625.26, "trd": NaN, "batb": [[2, 2.14, 3]], "batl": NaN}, {"timestamp": 1631534234663, "ltp": 2.58, "tv": 14625.26, "trd": NaN, "batb": [[0, 2.54, 4], [1, 2.52, 67.1], [2, 2.32, 81.42]], "batl": NaN}, {"timestamp": 1631534235407, "ltp": 2.58, "tv": 14625.26, "trd": NaN, "batb": [[0, 2.58, 3], [1, 2.56, 3], [2, 2.54, 4]], "batl": [[0, 2.78, 21.85], [1, 2.8, 4.52], [2, 2.82, 5.25]]}, {"timestamp": 1631534237577, "ltp": 2.58, "tv": 14625.26, "trd": NaN, "batb": NaN, "batl": [[0, 2.78, 22.48]]}, {"timestamp": 1631534238200, "ltp": 2.58, "tv": 14642.12, "trd": [[2.58, 25.95]], "batb": [[0, 2.56, 3], [1, 2.54, 4], [2, 2.52, 67.1]], "batl": NaN}, {"timestamp": 1631534240565, "ltp": 2.58, "tv": 14642.12, "trd": NaN, "batb": [[0, 2.58, 15], [1, 2.56, 3], [2, 2.54, 4]], "batl": [[0, 2.76, 21.85], [1, 2.78, 22.48], [2, 2.8, 4.52]]}, {"timestamp": 1631534243590, "ltp": 2.58, "tv": 14642.12, "trd": NaN, "batb": [[0, 2.52, 83.83], [1, 2.46, 5.38], [2, 2.38, 6.67]], "batl": [[0, 2.78, 22.48], [1, 2.82, 5.25], [2, 2.94, 4.25]]}, {"timestamp": 1631534244486, "ltp": 2.58, "tv": 14642.12, "trd": NaN, "batb": [[0, 2.38, 6.67], [1, 2.32, 81.42], [2, 2.2, 4]], "batl": [[0, 2.94, 4.25], [1, 3.9, 160.43], [2, 100, 0.96]]}, {"timestamp": 1631534247599, "ltp": 2.58, "tv": 14642.12, "trd": NaN, "batb": [[0, 2.46, 5.88], [1, 2.38, 6.67], [2, 2.36, 79.33]], "batl": NaN}, {"timestamp": 1631534247897, "ltp": 2.58, "tv": 14642.12, "trd": NaN, "batb": [[0, 2.38, 6.67], [1, 2.36, 79.33], [2, 2.2, 4]], "batl": [[0, 2.94, 7.25]]}, {"timestamp": 1631534250621, "ltp": 2.58, "tv": 14642.12, "trd": NaN, "batb": NaN, "batl": [[0, 2.82, 8.25], [1, 2.94, 7.25]]}, {"timestamp": 1631534251515, "ltp": 2.58, "tv": 14642.12, "trd": NaN, "batb": NaN, "batl": [[0, 2.82, 3], [1, 2.86, 3], [2, 2.94, 7.25]]}, {"timestamp": 1631534252615, "ltp": 2.38, "tv": 14658.41, "trd": [[2.38, 16.29]], "batb": [[0, 2.36, 79.33], [1, 2.3, 457.34], [2, 2.28, 443.88]], "batl": [[0, 2.52, 5.76], [1, 2.58, 50], [2, 2.82, 3]]}, {"timestamp": 1631534253604, "ltp": 2.38, "tv": 14658.41, "trd": NaN, "batb": [[1, 2.32, 22.72], [2, 2.3, 457.34]], "batl": [[1, 2.56, 24.01], [2, 2.58, 50]]}, {"timestamp": 1631534254603, "ltp": 2.38, "tv": 14658.41, "trd": NaN, "batb": [[0, 2.36, 83.33], [1, 2.34, 3], [2, 2.32, 22.72]], "batl": NaN}, {"timestamp": 1631534255594, "ltp": 2.38, "tv": 14658.41, "trd": NaN, "batb": [[0, 2.36, 108.31]], "batl": NaN}, {"timestamp": 1631534256582, "ltp": 2.38, "tv": 14658.41, "trd": NaN, "batb": NaN, "batl": [[0, 2.52, 42.01]]}, {"timestamp": 1631534257418, "ltp": 2.38, "tv": 14662.82, "trd": [[2.38, 20.7]], "batb": NaN, "batl": [[1, 2.58, 50], [2, 2.8, 4]]}, {"timestamp": 1631534258406, "ltp": 2.38, "tv": 14662.82, "trd": NaN, "batb": NaN, "batl": [[2, 2.68, 5.64]]}, {"timestamp": 1631534260604, "ltp": 2.38, "tv": 14662.82, "trd": NaN, "batb": NaN, "batl": [[0, 2.52, 66.34]]}, {"timestamp": 1631534265403, "ltp": 2.38, "tv": 14662.82, "trd": NaN, "batb": [[0, 2.32, 22.72], [1, 2.24, 5.77], [2, 2.16, 6.78]], "batl": [[0, 2.52, 24.33]]}, {"timestamp": 1631534266445, "ltp": 2.38, "tv": 14662.82, "trd": NaN, "batb": [[0, 2.24, 5.77], [1, 2.16, 6.78], [2, 2.14, 104.1]], "batl": [[0, 2.58, 50], [1, 2.8, 8.77], [2, 2.94, 4.25]]}, {"timestamp": 1631534266710, "ltp": 2.38, "tv": 14662.82, "trd": NaN, "batb": [[0, 2.16, 6.78], [1, 2.14, 104.1], [2, 2.12, 7.54]], "batl": NaN}, {"timestamp": 1631534268323, "ltp": 2.38, "tv": 14662.82, "trd": NaN, "batb": NaN, "batl": [[0, 2.8, 8.77], [1, 2.94, 4.25], [2, 3.45, 182.89]]}, {"timestamp": 1631534271139, "ltp": 2.38, "tv": 14662.82, "trd": NaN, "batb": NaN, "batl": [[0, 2.74, 4], [1, 2.8, 8.77], [2, 2.94, 4.25]]}, {"timestamp": 1631534272551, "ltp": 2.38, "tv": 14662.82, "trd": NaN, "batb": [[0, 2.18, 914.12], [1, 2.16, 6.78], [2, 2.14, 104.1]], "batl": [[0, 2.8, 4.77], [1, 2.94, 4.25], [2, 100, 0.96]]}, {"timestamp": 1631534273646, "ltp": 2.58, "tv": 14671.83, "trd": [[2.58, 34.96]], "batb": [[0, 2.58, 62.93], [1, 2.5, 20], [2, 2.34, 81.42]], "batl": [[0, 2.78, 22.48], [1, 2.8, 4.77], [2, 2.94, 4.25]]}, {"timestamp": 1631534277459, "ltp": 2.58, "tv": 14687.63, "trd": [[2.58, 50.76]], "batb": [[0, 2.58, 55.03]], "batl": NaN}, {"timestamp": 1631534278615, "ltp": 2.58, "tv": 14687.63, "trd": NaN, "batb": [[0, 2.58, 88.93], [1, 2.46, 5.88], [2, 2.38, 5.96]], "batl": [[2, 2.9, 4.05]]}, {"timestamp": 1631534279031, "ltp": 2.58, "tv": 14687.63, "trd": NaN, "batb": NaN, "batl": [[0, 2.76, 23.85], [1, 2.78, 22.48], [2, 2.8, 4.77]]}, {"timestamp": 1631534281841, "ltp": 2.58, "tv": 14687.63, "trd": NaN, "batb": [[1, 2.54, 19.48], [2, 2.46, 5.88]], "batl": NaN}, {"timestamp": 1631534287544, "ltp": 2.58, "tv": 14687.63, "trd": NaN, "batb": [[0, 2.58, 55.03]], "batl": [[0, 2.78, 22.48], [1, 2.9, 4.05], [2, 2.94, 4.25]]}, {"timestamp": 1631534287978, "ltp": 2.58, "tv": 14687.63, "trd": NaN, "batb": [[0, 2.54, 19.48], [1, 2.38, 5.96], [2, 2.34, 81.42]], "batl": [[1, 3.05, 4.1], [2, 3.9, 160.43]]}, {"timestamp": 1631534289452, "ltp": 2.58, "tv": 14687.63, "trd": NaN, "batb": [[0, 2.38, 5.96], [1, 2.34, 81.42], [2, 2.16, 6.78]], "batl": [[0, 3.05, 4.1], [1, 3.9, 160.43], [2, 3.9, 0]]}, {"timestamp": 1631534292662, "ltp": 2.58, "tv": 14687.63, "trd": NaN, "batb": NaN, "batl": [[0, 3, 2.96], [1, 3.05, 4.1], [2, 3.9, 160.43]]}, {"timestamp": 1631534294548, "ltp": 2.58, "tv": 14687.63, "trd": NaN, "batb": [[0, 2.46, 5.51], [1, 2.38, 5.96], [2, 2.34, 81.42]], "batl": [[0, 2.9, 9.41], [1, 2.98, 3], [2, 3, 2]]}, {"timestamp": 1631534294759, "ltp": 2.58, "tv": 14687.63, "trd": NaN, "batb": [[0, 2.38, 5.96], [1, 2.34, 81.42], [2, 2.16, 6.78]], "batl": [[0, 2.9, 4.96]]}, {"timestamp": 1631534297396, "ltp": 2.58, "tv": 14687.63, "trd": NaN, "batb": [[2, 2.04, 399.53]], "batl": NaN}, {"timestamp": 1631534299453, "ltp": 2.62, "tv": 14688.59, "trd": [[2.62, 0.96]], "batb": NaN, "batl": [[0, 2.9, 4]]}, {"timestamp": 1631534300568, "ltp": 2.62, "tv": 14688.59, "trd": NaN, "batb": [[0, 2.48, 852.04], [1, 2.38, 5.96], [2, 2.34, 81.42]], "batl": [[0, 3.05, 4.1], [1, 3.9, 160.43], [2, 3, 0]]}, {"timestamp": 1631534301470, "ltp": 2.8, "tv": 14697.06, "trd": [[2.8, 8.47]], "batb": [[0, 2.82, 49.96], [1, 2.6, 61.34], [2, 2.38, 5.96]], "batl": NaN}, {"timestamp": 1631534302362, "ltp": 2.8, "tv": 14697.06, "trd": NaN, "batb": [[1, 2.78, 16.85], [2, 2.6, 61.34]], "batl": [[1, 3.1, 20.7], [2, 3.9, 160.43]]}, {"timestamp": 1631534303256, "ltp": 2.8, "tv": 14697.06, "trd": NaN, "batb": [[1, 2.8, 3], [2, 2.78, 19.85]], "batl": [[0, 3.05, 24.6]]}, {"timestamp": 1631534305478, "ltp": 2.8, "tv": 14697.06, "trd": NaN, "batb": [[0, 2.82, 79.76]], "batl": NaN}, {"timestamp": 1631534306469, "ltp": 2.8, "tv": 14697.06, "trd": NaN, "batb": [[2, 2.78, 3]], "batl": NaN}, {"timestamp": 1631534307361, "ltp": 2.8, "tv": 14697.06, "trd": NaN, "batb": NaN, "batl": [[1, 3.1, 24.75], [2, 3.25, 4.06]]}, {"timestamp": 1631534309825, "ltp": 2.8, "tv": 14697.06, "trd": NaN, "batb": [[0, 2.82, 96.24]], "batl": NaN}, {"timestamp": 1631534315583, "ltp": 2.8, "tv": 14697.06, "trd": NaN, "batb": [[0, 2.82, 66.44], [2, 2.74, 5.02]], "batl": [[0, 3.05, 4.1]]}, {"timestamp": 1631534316416, "ltp": 2.8, "tv": 14697.06, "trd": NaN, "batb": [[0, 2.82, 16.48], [1, 2.74, 5.02], [2, 2.68, 4.86]], "batl": [[0, 3.1, 24.75], [1, 3.25, 4.06], [2, 3.9, 160.43]]}, {"timestamp": 1631534317436, "ltp": 2.8, "tv": 14697.06, "trd": NaN, "batb": [[0, 2.68, 4.86], [1, 2.6, 61.34], [2, 2.38, 5.96]], "batl": [[0, 3.25, 4.06], [1, 3.9, 160.43], [2, 3.9, 0]]}, {"timestamp": 1631534318608, "ltp": 2.8, "tv": 14697.06, "trd": NaN, "batb": NaN, "batl": [[0, 3, 3], [1, 3.25, 4.06], [2, 3.9, 160.43]]}, {"timestamp": 1631534319601, "ltp": 2.8, "tv": 14697.06, "trd": NaN, "batb": [[1, 2.64, 59.5]], "batl": [[0, 3.1, 3]]}, {"timestamp": 1631534320612, "ltp": 2.8, "tv": 14697.06, "trd": NaN, "batb": NaN, "batl": [[0, 3.15, 3]]}, {"timestamp": 1631534320706, "ltp": 2.8, "tv": 14697.06, "trd": NaN, "batb": NaN, "batl": [[1, 3.25, 7.06]]}, {"timestamp": 1631534322492, "ltp": 2.8, "tv": 14697.06, "trd": NaN, "batb": NaN, "batl": [[0, 3.05, 3], [1, 3.15, 3], [2, 3.25, 7.06]]}, {"timestamp": 1631534323528, "ltp": 2.8, "tv": 14697.06, "trd": NaN, "batb": [[0, 2.74, 5.02], [1, 2.68, 4.86], [2, 2.64, 59.5]], "batl": [[1, 3.1, 4.45], [2, 3.15, 3]]}, {"timestamp": 1631534324435, "ltp": 2.8, "tv": 14697.06, "trd": NaN, "batb": [[0, 2.68, 4.86], [1, 2.64, 59.5], [2, 2.38, 5.96]], "batl": [[1, 3.15, 3], [2, 3.2, 3]]}, {"timestamp": 1631534325628, "ltp": 2.68, "tv": 14710.77, "trd": [[2.68, 13.71]], "batb": [[0, 2.64, 59.5], [1, 2.38, 5.96], [2, 2.04, 399.53]], "batl": [[0, 2.8, 683.04], [1, 2.82, 662.94], [2, 2.84, 662.94]]}, {"timestamp": 1631534326431, "ltp": 2.68, "tv": 14710.77, "trd": NaN, "batb": [[1, 2.58, 18.98], [2, 2.38, 5.96]], "batl": NaN}, {"timestamp": 1631534328630, "ltp": 2.68, "tv": 14710.77, "trd": NaN, "batb": [[1, 2.6, 4], [2, 2.58, 21.98]], "batl": NaN}, {"timestamp": 1631534330616, "ltp": 2.68, "tv": 14711.9, "trd": [[2.68, 14.84]], "batb": NaN, "batl": NaN}, {"timestamp": 1631534331238, "ltp": 2.68, "tv": 14711.9, "trd": NaN, "batb": NaN, "batl": [[0, 2.78, 17.59], [1, 2.8, 683.04], [2, 2.82, 662.94]]}, {"timestamp": 1631534333590, "ltp": 2.68, "tv": 14711.9, "trd": NaN, "batb": NaN, "batl": [[2, 2.82, 685.17]]}, {"timestamp": 1631534334021, "ltp": 2.68, "tv": 14711.9, "trd": NaN, "batb": [[1, 2.58, 21.98], [2, 2.48, 6.51]], "batl": NaN}, {"timestamp": 1631534341620, "ltp": 2.68, "tv": 14711.9, "trd": NaN, "batb": [[0, 2.58, 18.98], [1, 2.38, 5.96], [2, 2.36, 188.45]], "batl": [[0, 2.82, 22.23], [1, 3, 175.15], [2, 3.05, 163.81]]}, {"timestamp": 1631534342468, "ltp": 2.68, "tv": 14711.9, "trd": NaN, "batb": [[0, 2.38, 5.96], [1, 2.36, 188.45], [2, 2.34, 311.99]], "batl": [[0, 3, 175.15], [1, 3.05, 163.81], [2, 3.1, 199.44]]}, {"timestamp": 1631534345608, "ltp": 2.68, "tv": 14711.9, "trd": NaN, "batb": [[0, 2.4, 3], [1, 2.38, 9.96], [2, 2.36, 188.45]], "batl": NaN}, {"timestamp": 1631534345715, "ltp": 2.68, "tv": 14711.9, "trd": NaN, "batb": NaN, "batl": [[0, 3, 178.15]]}, {"timestamp": 1631534350333, "ltp": 2.68, "tv": 14711.9, "trd": NaN, "batb": [[0, 2.42, 15], [1, 2.4, 3], [2, 2.38, 9.96]], "batl": [[0, 2.98, 64.89], [1, 3, 178.15], [2, 3.05, 163.81]]}, {"timestamp": 1631534352165, "ltp": 2.68, "tv": 14711.9, "trd": NaN, "batb": [[0, 2.48, 6.26]], "batl": NaN}, {"timestamp": 1631534354253, "ltp": 2.68, "tv": 14711.9, "trd": NaN, "batb": [[0, 2.4, 3], [1, 2.38, 9.96], [2, 2.36, 188.45]], "batl": [[0, 3, 178.15], [1, 3.05, 163.81], [2, 3.1, 199.44]]}, {"timestamp": 1631534357664, "ltp": 2.68, "tv": 14711.9, "trd": NaN, "batb": [[0, 2.48, 6.01], [1, 2.4, 3], [2, 2.38, 5.96]], "batl": [[0, 3, 3], [1, 3.1, 4.45], [2, 3.25, 4.06]]}, {"timestamp": 1631534357927, "ltp": 2.68, "tv": 14711.9, "trd": NaN, "batb": [[0, 2.4, 3], [1, 2.38, 5.96], [2, 2.36, 188.45]], "batl": [[1, 3.25, 4.06], [2, 3.35, 3.7]]}, {"timestamp": 1631534359660, "ltp": 2.68, "tv": 14711.9, "trd": NaN, "batb": [[0, 2.38, 5.96], [1, 2.36, 188.45], [2, 2.34, 311.99]], "batl": NaN}, {"timestamp": 1631534360652, "ltp": 2.38, "tv": 14727.48, "trd": [[2.38, 36.28]], "batb": [[0, 2.36, 188.45], [1, 2.34, 311.99], [2, 2.32, 226.74]], "batl": [[0, 2.48, 771.18], [1, 2.5, 748.48], [2, 2.52, 748.48]]}, {"timestamp": 1631534361654, "ltp": 2.38, "tv": 14727.48, "trd": NaN, "batb": [[2, 2.32, 249.46]], "batl": NaN}, {"timestamp": 1631534365633, "ltp": 2.38, "tv": 14733.5, "trd": [[2.38, 42.3]], "batb": NaN, "batl": NaN}, {"timestamp": 1631534366574, "ltp": 2.38, "tv": 14733.5, "trd": NaN, "batb": NaN, "batl": [[0, 2.46, 20.96], [1, 2.48, 771.18], [2, 2.5, 748.48]]}, {"timestamp": 1631534376558, "ltp": 2.38, "tv": 14733.69, "trd": [[2.38, 42.49]], "batb": NaN, "batl": NaN}, {"timestamp": 1631534386579, "ltp": 2.38, "tv": 14733.69, "trd": NaN, "batb": [[0, 2.32, 22.72], [1, 2.1, 185.82], [2, 2.08, 366.52]], "batl": [[0, 2.52, 24.33], [1, 2.7, 144.63], [2, 2.72, 175.51]]}, {"timestamp": 1631534387416, "ltp": 2.38, "tv": 14733.69, "trd": NaN, "batb": [[0, 2.1, 185.82], [1, 2.08, 366.52], [2, 2.06, 245.95]], "batl": [[0, 2.38, 10]]}, {"timestamp": 1631534390596, "ltp": 2.38, "tv": 14733.69, "trd": NaN, "batb": [[0, 2.1, 189.82], [1, 2.08, 369.52]], "batl": NaN}, {"timestamp": 1631534396537, "ltp": 2.38, "tv": 14733.69, "trd": NaN, "batb": NaN, "batl": [[1, 2.86, 5.25], [2, 2.98, 2]]}, {"timestamp": 1631534398540, "ltp": 2.38, "tv": 14733.69, "trd": NaN, "batb": [[0, 2.1, 185.82], [1, 2.08, 366.52]], "batl": NaN}, {"timestamp": 1631534399658, "ltp": 2.1, "tv": 14754.75, "trd": [[2.1, 21.06]], "batb": [[0, 2.1, 175.29]], "batl": [[0, 2.3, 18.85], [1, 2.38, 10], [2, 2.86, 5.25]]}, {"timestamp": 1631534400559, "ltp": 2.1, "tv": 14754.75, "trd": NaN, "batb": [[0, 2.1, 202.56]], "batl": [[0, 2.3, 45.16], [1, 2.34, 259.13], [2, 2.38, 10]]}, {"timestamp": 1631534401533, "ltp": 2.1, "tv": 14754.75, "trd": NaN, "batb": NaN, "batl": [[2, 2.36, 4]]}, {"timestamp": 1631534404645, "ltp": 2.1, "tv": 14770.88, "trd": [[2.1, 37.19]], "batb": [[0, 2.1, 194.49]], "batl": [[0, 2.28, 62.89], [1, 2.3, 45.16], [2, 2.34, 259.13]]}, {"timestamp": 1631534405540, "ltp": 2.1, "tv": 14770.88, "trd": NaN, "batb": NaN, "batl": [[2, 2.36, 4]]}, {"timestamp": 1631534408544, "ltp": 2.08, "tv": 15343.45, "trd": [[2.08, 180.66], [2.1, 429.1]], "batb": [[0, 2.08, 276.16], [1, 2.06, 245.95], [2, 1.87, 79.25]], "batl": NaN}, {"timestamp": 1631534409657, "ltp": 2.08, "tv": 15343.45, "trd": NaN, "batb": NaN, "batl": [[1, 2.3, 18.85]]}, {"timestamp": 1631534412576, "ltp": 2.08, "tv": 15343.45, "trd": NaN, "batb": [[2, 2.02, 29.41]], "batl": [[0, 2.24, 26.94]]}, {"timestamp": 1631534413475, "ltp": 2.08, "tv": 15343.45, "trd": NaN, "batb": NaN, "batl": [[0, 2.1, 100], [1, 2.24, 26.94], [2, 2.3, 18.85]]}, {"timestamp": 1631534414272, "ltp": 2.08, "tv": 15343.45, "trd": NaN, "batb": [[0, 2.02, 29.41], [1, 1.87, 79.25], [2, 1.86, 404.12]], "batl": [[2, 2.36, 4]]}, {"timestamp": 1631534415582, "ltp": 2.08, "tv": 15343.45, "trd": NaN, "batb": [[0, 1.87, 79.25], [1, 1.86, 404.12], [2, 1.85, 248.83]], "batl": [[1, 2.38, 10], [2, 2.42, 196.9]]}, {"timestamp": 1631534417594, "ltp": 2.08, "tv": 15343.45, "trd": NaN, "batb": [[0, 1.86, 485.13], [1, 1.85, 248.83], [2, 1.84, 213.97]], "batl": [[0, 2.08, 316]]}, {"timestamp": 1631534419590, "ltp": 2.08, "tv": 15343.45, "trd": NaN, "batb": NaN, "batl": [[1, 2.22, 457.47], [2, 2.38, 10]]}, {"timestamp": 1631534420175, "ltp": 2.08, "tv": 15343.45, "trd": NaN, "batb": NaN, "batl": [[0, 2.38, 10], [1, 2.42, 196.9], [2, 2.44, 183.26]]}, {"timestamp": 1631534421543, "ltp": 2.08, "tv": 15343.45, "trd": NaN, "batb": [[0, 1.86, 489.13], [1, 1.85, 252.83]], "batl": NaN}, {"timestamp": 1631534422382, "ltp": 2.08, "tv": 15343.45, "trd": NaN, "batb": [[0, 1.87, 105.57], [1, 1.86, 489.13], [2, 1.85, 252.83]], "batl": NaN}, {"timestamp": 1631534423590, "ltp": 2.08, "tv": 15343.45, "trd": NaN, "batb": [[0, 1.86, 489.13], [1, 1.85, 252.83], [2, 1.84, 213.97]], "batl": NaN}, {"timestamp": 1631534433402, "ltp": 2.08, "tv": 15343.45, "trd": NaN, "batb": [[1, 1.85, 248.83]], "batl": NaN}, {"timestamp": 1631534435417, "ltp": 2.08, "tv": 15343.45, "trd": NaN, "batb": [[1, 1.5, 106.96], [2, 1.4, 148.56]], "batl": NaN}, {"timestamp": 1631534436632, "ltp": 2.08, "tv": 15343.45, "trd": NaN, "batb": [[1, 1.85, 2], [2, 1.5, 106.96]], "batl": NaN}, {"timestamp": 1631534438622, "ltp": 2.08, "tv": 15343.45, "trd": NaN, "batb": [[0, 2.3, 831.52], [1, 2.28, 807.06], [2, 2.26, 807.06]], "batl": NaN}, {"timestamp": 1631534439416, "ltp": 2.3, "tv": 15362.69, "trd": [[2.3, 19.24]], "batb": [[0, 2.32, 84.85], [1, 2.3, 821.9], [2, 2.28, 807.06]], "batl": [[2, 2.44, 208.26]]}, {"timestamp": 1631534440406, "ltp": 2.32, "tv": 15366.69, "trd": [[2.32, 4]], "batb": [[0, 2.32, 82.85]], "batl": NaN}, {"timestamp": 1631534453359, "ltp": 2.32, "tv": 15366.69, "trd": NaN, "batb": [[0, 2.08, 181.53], [1, 2.06, 352.49], [2, 2.04, 310.61]], "batl": [[1, 2.44, 25], [2, 2.66, 197.73]]}, {"timestamp": 1631534454448, "ltp": 2.32, "tv": 15366.69, "trd": NaN, "batb": NaN, "batl": [[1, 2.66, 197.73], [2, 2.68, 226.65]]}, {"timestamp": 1631534461338, "ltp": 2.32, "tv": 15366.69, "trd": NaN, "batb": [[0, 2.1, 75.63], [1, 2.08, 181.53], [2, 2.06, 352.49]], "batl": [[0, 2.36, 23.37], [1, 2.38, 10], [2, 2.66, 197.73]]}, {"timestamp": 1631534462352, "ltp": 2.32, "tv": 15366.69, "trd": NaN, "batb": [[0, 2.08, 181.53], [1, 2.06, 352.49], [2, 2.04, 310.61]], "batl": [[0, 2.38, 10], [1, 2.66, 197.73], [2, 2.68, 226.65]]}, {"timestamp": 1631534466773, "ltp": 2.32, "tv": 15366.69, "trd": NaN, "batb": [[0, 2.06, 117.57], [1, 1.87, 5], [2, 1.86, 404.12]], "batl": NaN}, {"timestamp": 1631534467871, "ltp": 2.32, "tv": 15366.69, "trd": NaN, "batb": [[2, 1.7, 16.97]], "batl": NaN}, {"timestamp": 1631534469656, "ltp": 2.38, "tv": 15376.69, "trd": [[2.38, 52.49]], "batb": NaN, "batl": [[0, 2.7, 221.18], [1, 2.76, 4.77], [2, 3.05, 4.1]]}, {"timestamp": 1631534470664, "ltp": 2.58, "tv": 15385.62, "trd": [[2.58, 59.69]], "batb": [[0, 2.58, 63.1], [1, 2.28, 87.7], [2, 2.06, 117.57]], "batl": NaN}, {"timestamp": 1631534471605, "ltp": 2.58, "tv": 15409.93, "trd": [[2.58, 84]], "batb": [[0, 2.58, 50.94], [1, 2.38, 4], [2, 2.36, 4]], "batl": NaN}, {"timestamp": 1631534472653, "ltp": 2.58, "tv": 15409.93, "trd": NaN, "batb": NaN, "batl": [[1, 2.74, 22.74], [2, 2.76, 4.77]]}, {"timestamp": 1631534473279, "ltp": 2.58, "tv": 15409.93, "trd": NaN, "batb": [[1, 2.52, 3], [2, 2.5, 3]], "batl": [[0, 2.7, 239.98]]}, {"timestamp": 1631534474484, "ltp": 2.58, "tv": 15416.93, "trd": [[2.58, 91]], "batb": [[0, 2.58, 47.44]], "batl": NaN}, {"timestamp": 1631534486287, "ltp": 2.58, "tv": 15416.93, "trd": NaN, "batb": [[2, 2.28, 192.99]], "batl": NaN}, {"timestamp": 1631534488490, "ltp": 2.58, "tv": 15416.93, "trd": NaN, "batb": [[0, 2.28, 87.7], [1, 1.97, 400.31], [2, 1.7, 16.97]], "batl": [[0, 2.74, 22.74], [1, 3.1, 4.35], [2, 3.2, 4.13]]}, {"timestamp": 1631534489492, "ltp": 2.58, "tv": 15416.93, "trd": NaN, "batb": NaN, "batl": [[0, 3.1, 4.35], [1, 3.2, 4.13], [2, 3.65, 172.76]]}, {"timestamp": 1631534491598, "ltp": 2.58, "tv": 15416.93, "trd": NaN, "batb": [[0, 2.44, 20.83], [1, 2.28, 87.7], [2, 1.97, 400.31]], "batl": NaN}, {"timestamp": 1631534491915, "ltp": 2.58, "tv": 15416.93, "trd": NaN, "batb": [[0, 2.28, 87.7], [1, 1.97, 400.31], [2, 1.7, 16.97]], "batl": NaN}, {"timestamp": 1631534492910, "ltp": 2.58, "tv": 15416.93, "trd": NaN, "batb": NaN, "batl": [[0, 3.05, 3], [1, 3.1, 4.35], [2, 3.2, 4.13]]}, {"timestamp": 1631534495387, "ltp": 2.58, "tv": 15416.93, "trd": NaN, "batb": NaN, "batl": [[0, 2.98, 3], [1, 3.05, 3], [2, 3.1, 4.35]]}, {"timestamp": 1631534498613, "ltp": 2.58, "tv": 15416.93, "trd": NaN, "batb": [[0, 2.86, 1337.42], [1, 2.84, 1298.08], [2, 2.82, 1298.08]], "batl": [[0, 3.1, 4.35], [1, 3.2, 1199.45], [2, 3.25, 1160.16]]}, {"timestamp": 1631534499602, "ltp": 2.86, "tv": 15433.45, "trd": [[2.86, 16.52]], "batb": [[0, 2.88, 47.78], [1, 2.86, 660.44], [2, 2.84, 649.04]], "batl": [[1, 3.2, 332.84], [2, 3.25, 319.04]]}, {"timestamp": 1631534500494, "ltp": 2.86, "tv": 15433.45, "trd": NaN, "batb": NaN, "batl": [[0, 3.1, 25.05]]}, {"timestamp": 1631534501593, "ltp": 2.88, "tv": 15433.63, "trd": [[2.88, 0.19]], "batb": [[0, 2.88, 47.69]], "batl": NaN}, {"timestamp": 1631534501800, "ltp": 2.88, "tv": 15433.63, "trd": NaN, "batb": NaN, "batl": [[0, 3.05, 21.75], [1, 3.1, 25.05], [2, 3.2, 332.84]]}, {"timestamp": 1631534503621, "ltp": 2.88, "tv": 15437.64, "trd": [[2.88, 4.19]], "batb": [[0, 2.88, 45.69]], "batl": NaN}, {"timestamp": 1631534523238, "ltp": 2.88, "tv": 15442.26, "trd": [[2.88, 8.81]], "batb": [[0, 2.88, 43.38]], "batl": NaN}, {"timestamp": 1631534549472, "ltp": 2.88, "tv": 15445.15, "trd": [[2.88, 11.7]], "batb": [[0, 2.88, 41.93]], "batl": NaN}, {"timestamp": 1631534550057, "ltp": 2.88, "tv": 15448.05, "trd": [[2.88, 14.6]], "batb": [[0, 2.88, 40.48]], "batl": NaN}, {"timestamp": 1631534572594, "ltp": 3.0, "tv": 15451.19, "trd": [[3, 3.14]], "batb": NaN, "batl": NaN}, {"timestamp": 1631534595807, "ltp": 3.0, "tv": 15451.19, "trd": NaN, "batb": NaN, "batl": [[0, 3.1, 25.05], [1, 3.2, 332.84], [2, 3.25, 319.04]]}, {"timestamp": 1631534605214, "ltp": 3.0, "tv": 15451.19, "trd": NaN, "batb": NaN, "batl": [[0, 3.05, 29.87], [1, 3.1, 25.05], [2, 3.2, 332.84]]}, {"timestamp": 1631534615536, "ltp": 3.0, "tv": 15451.19, "trd": NaN, "batb": [[1, 2.8, 4.38], [2, 2.76, 17.04]], "batl": [[0, 3.1, 25.05], [1, 3.25, 3.94], [2, 3.65, 172.76]]}, {"timestamp": 1631534616415, "ltp": 3.0, "tv": 15451.19, "trd": NaN, "batb": [[0, 2.76, 17.04], [1, 2.74, 8.02], [2, 2.72, 3]], "batl": [[0, 3.1, 20.7]]}, {"timestamp": 1631534617405, "ltp": 3.0, "tv": 15451.19, "trd": NaN, "batb": [[0, 2.74, 8.02], [1, 2.72, 3], [2, 2.7, 55.98]], "batl": [[0, 3.25, 3.94], [1, 3.65, 172.76], [2, 3.65, 0]]}, {"timestamp": 1631534619600, "ltp": 3.0, "tv": 15451.19, "trd": NaN, "batb": NaN, "batl": [[0, 3.1, 3], [1, 3.25, 3.94], [2, 3.65, 172.76]]}, {"timestamp": 1631534621584, "ltp": 3.0, "tv": 15451.19, "trd": NaN, "batb": NaN, "batl": [[0, 2.88, 2183.34], [1, 3.1, 12.68], [2, 3.15, 3]]}, {"timestamp": 1631534622600, "ltp": 3.0, "tv": 15451.19, "trd": NaN, "batb": [[0, 2.74, 5.02], [1, 2.7, 55.98], [2, 1.97, 400.31]], "batl": [[0, 3.05, 3], [1, 3.1, 3]]}, {"timestamp": 1631534623495, "ltp": 2.74, "tv": 15464.68, "trd": [[2.74, 13.49]], "batb": [[0, 2.7, 55.98], [1, 2.64, 398.44], [2, 2.62, 386.72]], "batl": [[0, 2.9, 673.93], [1, 2.92, 640.08], [2, 2.94, 640.08]]}, {"timestamp": 1631534624602, "ltp": 2.74, "tv": 15464.68, "trd": NaN, "batb": NaN, "batl": [[1, 2.92, 661.73]]}, {"timestamp": 1631534626120, "ltp": 2.74, "tv": 15464.68, "trd": NaN, "batb": NaN, "batl": [[0, 2.88, 3], [1, 2.9, 673.93], [2, 2.92, 661.73]]}, {"timestamp": 1631534626912, "ltp": 2.74, "tv": 15464.68, "trd": NaN, "batb": NaN, "batl": [[2, 2.92, 640.08]]}, {"timestamp": 1631534630644, "ltp": 2.74, "tv": 15464.68, "trd": NaN, "batb": [[0, 2.6, 4], [1, 2.58, 237.98], [2, 2.56, 213.09]], "batl": [[0, 2.88, 21.87], [1, 2.94, 143.81], [2, 2.96, 162.32]]}, {"timestamp": 1631534631643, "ltp": 2.74, "tv": 15464.68, "trd": NaN, "batb": [[1, 2.58, 219]], "batl": [[0, 2.94, 143.81], [1, 2.96, 162.32], [2, 2.98, 183.49]]}, {"timestamp": 1631534634423, "ltp": 2.74, "tv": 15464.68, "trd": NaN, "batb": NaN, "batl": [[2, 2.98, 178.24]]}, {"timestamp": 1631534637625, "ltp": 2.74, "tv": 15464.68, "trd": NaN, "batb": [[0, 2.62, 3], [1, 2.58, 216]], "batl": NaN}, {"timestamp": 1631534640518, "ltp": 2.74, "tv": 15464.68, "trd": NaN, "batb": [[1, 2.6, 3], [2, 2.58, 216]], "batl": NaN}, {"timestamp": 1631534652345, "ltp": 2.74, "tv": 15464.68, "trd": NaN, "batb": [[1, 2.58, 216], [2, 2.56, 213.09]], "batl": NaN}, {"timestamp": 1631534655438, "ltp": 2.74, "tv": 15464.68, "trd": NaN, "batb": [[1, 2.6, 3], [2, 2.58, 216]], "batl": NaN}, {"timestamp": 1631534657454, "ltp": 2.74, "tv": 15464.68, "trd": NaN, "batb": [[2, 2.58, 63.76]], "batl": NaN}, {"timestamp": 1631534660661, "ltp": 2.74, "tv": 15464.68, "trd": NaN, "batb": [[0, 2.82, 833.32], [1, 2.8, 416.66], [2, 2.78, 416.66]], "batl": [[0, 2.98, 178.24], [1, 3.1, 4.85], [2, 3.2, 328.71]]}, {"timestamp": 1631534661395, "ltp": 2.84, "tv": 15472.88, "trd": [[2.84, 8.2]], "batb": [[0, 2.88, 47.36], [1, 2.82, 833.32], [2, 2.8, 416.66]], "batl": NaN}, {"timestamp": 1631534663081, "ltp": 2.84, "tv": 15472.88, "trd": NaN, "batb": NaN, "batl": [[0, 2.98, 196.54], [1, 3.1, 25.55]]}, {"timestamp": 1631534687538, "ltp": 2.84, "tv": 15472.88, "trd": NaN, "batb": [[0, 2.76, 17.04], [1, 2.7, 55.9], [2, 2.34, 2.89]], "batl": [[0, 3.1, 20.7], [1, 3.65, 172.76], [2, 3.2, 0]]}, {"timestamp": 1631534688472, "ltp": 2.84, "tv": 15472.88, "trd": NaN, "batb": [[0, 2.7, 55.9], [1, 2.34, 2.89], [2, 1.97, 400.31]], "batl": [[0, 3.65, 172.76], [1, 3.65, 0]]}, {"timestamp": 1631534691652, "ltp": 2.84, "tv": 15472.88, "trd": NaN, "batb": [[0, 2.7, 59.9], [1, 2.68, 3], [2, 2.34, 2.89]], "batl": [[0, 3.15, 3], [1, 3.35, 3], [2, 3.65, 172.76]]}, {"timestamp": 1631534693636, "ltp": 2.84, "tv": 15472.88, "trd": NaN, "batb": NaN, "batl": [[1, 3.3, 3], [2, 3.35, 3]]}, {"timestamp": 1631534696465, "ltp": 2.84, "tv": 15472.88, "trd": NaN, "batb": [[0, 2.72, 40.28], [1, 2.7, 59.9], [2, 2.68, 3]], "batl": [[0, 3.1, 15], [1, 3.15, 3], [2, 3.3, 3]]}, {"timestamp": 1631534699656, "ltp": 2.84, "tv": 15472.88, "trd": NaN, "batb": [[0, 2.7, 59.9], [1, 2.68, 3], [2, 2.34, 2.89]], "batl": [[0, 3.15, 3], [1, 3.3, 3], [2, 3.35, 3]]}, {"timestamp": 1631534712664, "ltp": 2.7, "tv": 15475.54, "trd": [[2.7, 2.66]], "batb": [[0, 2.7, 58.57]], "batl": NaN}, {"timestamp": 1631534713192, "ltp": 2.7, "tv": 15475.54, "trd": NaN, "batb": [[1, 2.34, 2.89], [2, 1.97, 400.31]], "batl": [[1, 3.65, 172.76], [2, 3.35, 0]]}, {"timestamp": 1631534715607, "ltp": 2.7, "tv": 15492.48, "trd": [[2.7, 19.61]], "batb": [[0, 2.7, 46.09], [1, 2.64, 398.44], [2, 2.62, 386.72]], "batl": [[0, 2.9, 659.48], [1, 2.92, 640.08], [2, 2.94, 640.08]]}, {"timestamp": 1631534716599, "ltp": 2.7, "tv": 15492.48, "trd": NaN, "batb": NaN, "batl": [[1, 2.92, 661.73]]}, {"timestamp": 1631534718465, "ltp": 2.7, "tv": 15492.48, "trd": NaN, "batb": NaN, "batl": [[0, 2.88, 3], [1, 2.9, 659.48], [2, 2.92, 661.73]]}, {"timestamp": 1631534720618, "ltp": 2.7, "tv": 15492.48, "trd": NaN, "batb": NaN, "batl": [[0, 2.88, 37.55], [2, 2.92, 640.08]]}, {"timestamp": 1631534721609, "ltp": 2.7, "tv": 15492.48, "trd": NaN, "batb": NaN, "batl": [[0, 2.88, 3]]}, {"timestamp": 1631534724175, "ltp": 2.7, "tv": 15492.48, "trd": NaN, "batb": NaN, "batl": [[0, 2.88, 24.87]]}, {"timestamp": 1631534727390, "ltp": 2.7, "tv": 15492.48, "trd": NaN, "batb": NaN, "batl": [[0, 2.86, 31.12], [1, 2.88, 24.87], [2, 2.9, 659.48]]}, {"timestamp": 1631534731528, "ltp": 2.7, "tv": 15492.48, "trd": NaN, "batb": [[0, 2.56, 84.25], [1, 2.34, 2.89], [2, 1.97, 400.31]], "batl": [[0, 2.88, 21.87], [1, 3, 4.86], [2, 3.1, 5.05]]}, {"timestamp": 1631534732624, "ltp": 2.7, "tv": 15492.48, "trd": NaN, "batb": [[0, 2.56, 65.02]], "batl": [[0, 3.1, 5.05], [1, 3.2, 4.53], [2, 3.65, 172.76]]}, {"timestamp": 1631534734611, "ltp": 2.7, "tv": 15492.48, "trd": NaN, "batb": [[1, 2.54, 65.19], [2, 2.34, 2.89]], "batl": NaN}, {"timestamp": 1631534735606, "ltp": 2.7, "tv": 15492.48, "trd": NaN, "batb": [[0, 2.56, 4], [1, 2.54, 68.19]], "batl": NaN}, {"timestamp": 1631534736596, "ltp": 2.7, "tv": 15492.48, "trd": NaN, "batb": NaN, "batl": [[0, 3.05, 3], [1, 3.1, 5.05], [2, 3.2, 4.53]]}, {"timestamp": 1631534736702, "ltp": 2.7, "tv": 15492.48, "trd": NaN, "batb": NaN, "batl": [[0, 2.7, 13.43], [1, 3.05, 3], [2, 3.1, 5.05]]}, {"timestamp": 1631534740615, "ltp": 2.7, "tv": 15492.48, "trd": NaN, "batb": NaN, "batl": [[0, 3.05, 3], [1, 3.1, 5.05], [2, 3.2, 4.53]]}, {"timestamp": 1631534742443, "ltp": 2.56, "tv": 15505.18, "trd": [[2.56, 12.7]], "batb": [[0, 2.54, 68.19], [1, 2.5, 420.75], [2, 2.48, 408.37]], "batl": [[0, 2.74, 697.98], [1, 2.76, 677.46], [2, 2.78, 677.46]]}, {"timestamp": 1631534743442, "ltp": 2.56, "tv": 15505.18, "trd": NaN, "batb": NaN, "batl": [[0, 2.72, 22.87], [1, 2.74, 697.98], [2, 2.76, 677.46]]}, {"timestamp": 1631534746001, "ltp": 2.56, "tv": 15505.18, "trd": NaN, "batb": [[0, 2.58, 2.89], [1, 2.54, 68.19], [2, 2.5, 420.75]], "batl": NaN}, {"timestamp": 1631534747530, "ltp": 2.56, "tv": 15505.18, "trd": NaN, "batb": [[1, 2.54, 65.19]], "batl": [[0, 2.7, 31.54], [1, 2.72, 22.87], [2, 2.74, 697.98]]}, {"timestamp": 1631534752635, "ltp": 2.56, "tv": 15505.18, "trd": NaN, "batb": [[2, 2.44, 72.22]], "batl": [[0, 2.86, 15.75], [1, 3, 4.59], [2, 3.1, 5.05]]}, {"timestamp": 1631534753160, "ltp": 2.56, "tv": 15505.18, "trd": NaN, "batb": [[1, 2.44, 72.22], [2, 1.97, 400.31]], "batl": [[0, 3, 4.59], [1, 3.1, 5.05], [2, 3.2, 4.53]]}, {"timestamp": 1631534756529, "ltp": 2.56, "tv": 15505.18, "trd": NaN, "batb": NaN, "batl": [[0, 2.86, 5.25], [1, 3, 4.59], [2, 3.1, 5.05]]}, {"timestamp": 1631534758623, "ltp": 2.56, "tv": 15505.18, "trd": NaN, "batb": [[0, 2.44, 72.22], [1, 1.97, 400.31], [2, 1.8, 11.88]], "batl": NaN}, {"timestamp": 1631534760625, "ltp": 2.56, "tv": 15505.18, "trd": NaN, "batb": NaN, "batl": [[0, 2.84, 26.25], [1, 2.86, 5.25], [2, 3, 4.59]]}, {"timestamp": 1631534761261, "ltp": 2.56, "tv": 15505.18, "trd": NaN, "batb": [[0, 2.48, 2.89], [1, 2.44, 72.22], [2, 1.97, 400.31]], "batl": NaN}, {"timestamp": 1631534764563, "ltp": 2.56, "tv": 15505.18, "trd": NaN, "batb": [[0, 2.5, 14.45], [1, 2.48, 2.89], [2, 2.44, 72.22]], "batl": NaN}, {"timestamp": 1631534766136, "ltp": 2.56, "tv": 15505.18, "trd": NaN, "batb": [[0, 2.48, 2.89], [1, 2.44, 72.22], [2, 1.97, 400.31]], "batl": [[0, 2.86, 5.25], [1, 3, 4.59], [2, 3.1, 5.05]]}, {"timestamp": 1631534779567, "ltp": 2.56, "tv": 15505.18, "trd": NaN, "batb": [[0, 2.64, 724.44], [1, 2.62, 703.12], [2, 2.6, 703.12]], "batl": [[1, 2.9, 659.48], [2, 2.92, 352.04]]}, {"timestamp": 1631534780468, "ltp": 2.68, "tv": 15522.13, "trd": [[2.68, 31.78]], "batb": [[0, 2.68, 48.34], [1, 2.64, 724.44], [2, 2.62, 703.12]], "batl": NaN}, {"timestamp": 1631534781559, "ltp": 2.68, "tv": 15522.13, "trd": NaN, "batb": NaN, "batl": [[0, 2.86, 27.24]]}, {"timestamp": 1631534782085, "ltp": 2.68, "tv": 15522.13, "trd": NaN, "batb": NaN, "batl": [[0, 2.84, 26.25], [1, 2.86, 27.24], [2, 2.9, 659.48]]}, {"timestamp": 1631534790580, "ltp": 2.68, "tv": 15522.13, "trd": NaN, "batb": [[1, 2.58, 2.89], [2, 2.56, 19.23]], "batl": [[0, 2.86, 21.99], [1, 2.98, 5.25], [2, 3, 4.59]]}, {"timestamp": 1631534791368, "ltp": 2.68, "tv": 15522.13, "trd": NaN, "batb": [[0, 2.58, 2.89], [1, 2.54, 66.02], [2, 1.97, 400.31]], "batl": [[0, 2.98, 5.25], [1, 3, 4.59], [2, 3.1, 5.05]]}, {"timestamp": 1631534791684, "ltp": 2.68, "tv": 15522.13, "trd": NaN, "batb": NaN, "batl": [[0, 3.1, 5.05], [1, 3.2, 4.53], [2, 3.65, 172.76]]}, {"timestamp": 1631534794079, "ltp": 2.68, "tv": 15522.13, "trd": NaN, "batb": [[1, 2.52, 66.19]], "batl": NaN}, {"timestamp": 1631534796599, "ltp": 2.68, "tv": 15522.13, "trd": NaN, "batb": NaN, "batl": [[0, 2.76, 18.52], [1, 3.1, 5.05], [2, 3.2, 4.53]]}, {"timestamp": 1631534796704, "ltp": 2.68, "tv": 15522.13, "trd": NaN, "batb": NaN, "batl": [[0, 3.1, 5.05], [1, 3.2, 4.53], [2, 3.65, 172.76]]}, {"timestamp": 1631534798594, "ltp": 2.68, "tv": 15522.13, "trd": NaN, "batb": [[0, 2.6, 14.45], [1, 2.58, 2.89], [2, 2.52, 66.19]], "batl": [[0, 2.98, 4.75], [1, 3.1, 5.05], [2, 3.2, 4.53]]}, {"timestamp": 1631534799597, "ltp": 2.68, "tv": 15522.13, "trd": NaN, "batb": [[0, 2.58, 2.89], [1, 2.52, 66.19], [2, 1.97, 400.31]], "batl": NaN}, {"timestamp": 1631534799911, "ltp": 2.68, "tv": 15522.13, "trd": NaN, "batb": NaN, "batl": [[0, 3.1, 5.05], [1, 3.2, 4.53], [2, 3.65, 172.76]]}, {"timestamp": 1631534804380, "ltp": 2.68, "tv": 15522.13, "trd": NaN, "batb": NaN, "batl": [[0, 3.05, 3], [1, 3.1, 5.05], [2, 3.2, 4.53]]}, {"timestamp": 1631534804900, "ltp": 2.68, "tv": 15522.13, "trd": NaN, "batb": NaN, "batl": [[0, 2.96, 3], [1, 3.05, 3], [2, 3.1, 5.05]]}, {"timestamp": 1631534806482, "ltp": 2.68, "tv": 15522.13, "trd": NaN, "batb": NaN, "batl": [[1, 2.98, 8.25], [2, 3.05, 3]]}, {"timestamp": 1631534806754, "ltp": 2.68, "tv": 15522.13, "trd": NaN, "batb": NaN, "batl": [[1, 2.98, 3]]}, {"timestamp": 1631534811645, "ltp": 2.68, "tv": 15522.13, "trd": NaN, "batb": NaN, "batl": [[0, 3.1, 5.05], [1, 3.2, 4.53], [2, 3.65, 172.76]]}, {"timestamp": 1631534812642, "ltp": 2.68, "tv": 15522.13, "trd": NaN, "batb": [[0, 2.86, 668.7], [1, 2.84, 649.04], [2, 2.82, 649.04]], "batl": [[1, 3.2, 333.24], [2, 3.25, 319.04]]}, {"timestamp": 1631534813645, "ltp": 2.88, "tv": 15530.26, "trd": [[2.88, 22.73]], "batb": [[0, 2.88, 47.61], [1, 2.86, 668.7], [2, 2.84, 649.04]], "batl": [[0, 3.1, 25.75]]}, {"timestamp": 1631534814850, "ltp": 2.88, "tv": 15530.26, "trd": NaN, "batb": NaN, "batl": [[0, 3.05, 24.01], [1, 3.1, 25.75], [2, 3.2, 333.24]]}, {"timestamp": 1631534830581, "ltp": 2.88, "tv": 15530.26, "trd": NaN, "batb": [[0, 2.76, 17.04], [1, 2.66, 57.4], [2, 2.6, 3]], "batl": [[0, 3.1, 20.7], [1, 3.4, 4.19], [2, 3.65, 172.76]]}, {"timestamp": 1631534831469, "ltp": 2.88, "tv": 15530.26, "trd": NaN, "batb": [[0, 2.66, 57.4], [1, 2.6, 3], [2, 2.58, 2.89]], "batl": [[0, 3.4, 4.19], [1, 3.65, 172.76], [2, 3.65, 0]]}, {"timestamp": 1631534833559, "ltp": 2.88, "tv": 15530.26, "trd": NaN, "batb": NaN, "batl": [[0, 3.1, 3], [1, 3.4, 4.19], [2, 3.65, 172.76]]}, {"timestamp": 1631534834654, "ltp": 2.88, "tv": 15530.26, "trd": NaN, "batb": [[0, 2.66, 61.4], [1, 2.64, 3], [2, 2.6, 3]], "batl": [[1, 3.15, 3], [2, 3.4, 7.19]]}, {"timestamp": 1631534836549, "ltp": 2.88, "tv": 15530.26, "trd": NaN, "batb": [[0, 2.68, 3], [1, 2.66, 61.4], [2, 2.64, 3]], "batl": NaN}, {"timestamp": 1631534837180, "ltp": 2.88, "tv": 15530.26, "trd": NaN, "batb": NaN, "batl": [[2, 3.25, 4.14]]}, {"timestamp": 1631534838495, "ltp": 2.88, "tv": 15530.26, "trd": NaN, "batb": NaN, "batl": [[2, 3.4, 7.19]]}, {"timestamp": 1631534846271, "ltp": 2.88, "tv": 15530.26, "trd": NaN, "batb": [[1, 2.66, 57.4], [2, 2.58, 2.89]], "batl": [[1, 3.4, 4.19], [2, 3.65, 172.76]]}, {"timestamp": 1631534848359, "ltp": 2.88, "tv": 15530.26, "trd": NaN, "batb": [[0, 2.66, 57.4], [1, 2.58, 2.89], [2, 1.97, 400.31]], "batl": NaN}, {"timestamp": 1631534849465, "ltp": 2.68, "tv": 15538.73, "trd": [[2.68, 40.25]], "batb": [[0, 2.66, 60.4], [1, 2.64, 724.44], [2, 2.62, 386.72]], "batl": [[0, 2.86, 16.25], [1, 2.9, 659.48], [2, 2.92, 640.08]]}, {"timestamp": 1631534850461, "ltp": 2.68, "tv": 15538.73, "trd": NaN, "batb": [[0, 2.66, 57.4]], "batl": [[1, 2.9, 681.24]]}, {"timestamp": 1631534852612, "ltp": 2.68, "tv": 15538.73, "trd": NaN, "batb": NaN, "batl": [[1, 2.88, 3], [2, 2.9, 681.24]]}, {"timestamp": 1631534854403, "ltp": 2.68, "tv": 15538.73, "trd": NaN, "batb": NaN, "batl": [[0, 2.84, 27.6], [1, 2.86, 16.25], [2, 2.88, 3]]}, {"timestamp": 1631534857390, "ltp": 2.68, "tv": 15538.73, "trd": NaN, "batb": NaN, "batl": [[1, 2.86, 38.24]]}, {"timestamp": 1631534866480, "ltp": 2.68, "tv": 15538.73, "trd": NaN, "batb": [[0, 2.58, 2.89], [1, 2.56, 19.23], [2, 2.52, 66.61]], "batl": [[0, 2.86, 21.99], [1, 2.94, 5.25], [2, 3.05, 4.5]]}, {"timestamp": 1631534867577, "ltp": 2.68, "tv": 15538.73, "trd": NaN, "batb": [[1, 2.52, 66.61], [2, 1.97, 400.31]], "batl": [[0, 3.05, 4.5], [1, 3.4, 4.19], [2, 3.65, 172.76]]}, {"timestamp": 1631534870986, "ltp": 2.68, "tv": 15538.73, "trd": NaN, "batb": NaN, "batl": [[0, 2.9, 3], [1, 2.94, 3], [2, 3.05, 4.5]]}, {"timestamp": 1631534873389, "ltp": 2.68, "tv": 15538.73, "trd": NaN, "batb": NaN, "batl": [[2, 3.05, 7.5]]}, {"timestamp": 1631534874217, "ltp": 2.68, "tv": 15538.73, "trd": NaN, "batb": NaN, "batl": [[1, 2.94, 8.25]]}, {"timestamp": 1631534875106, "ltp": 2.68, "tv": 15538.73, "trd": NaN, "batb": [[0, 2.6, 14.45], [1, 2.58, 2.89], [2, 2.52, 66.61]], "batl": [[0, 2.88, 15], [1, 2.9, 3], [2, 2.94, 8.25]]}, {"timestamp": 1631534877605, "ltp": 2.68, "tv": 15538.73, "trd": NaN, "batb": [[0, 2.58, 2.89], [1, 2.52, 66.61], [2, 1.97, 400.31]], "batl": [[0, 2.9, 3], [1, 2.94, 8.25], [2, 3.05, 7.5]]}, {"timestamp": 1631534878497, "ltp": 2.68, "tv": 15538.73, "trd": NaN, "batb": NaN, "batl": [[1, 2.94, 3]]}, {"timestamp": 1631534881431, "ltp": 2.68, "tv": 15538.73, "trd": NaN, "batb": NaN, "batl": [[0, 3.05, 4.5], [1, 3.4, 4.19], [2, 3.65, 172.76]]}, {"timestamp": 1631534888445, "ltp": 2.68, "tv": 15538.73, "trd": NaN, "batb": [[0, 2.86, 1337.42], [1, 2.84, 1298.08], [2, 2.82, 1298.08]], "batl": [[1, 3.2, 1195.32], [2, 3.25, 1160.16]]}, {"timestamp": 1631534889447, "ltp": 2.88, "tv": 15546.86, "trd": [[2.88, 30.86]], "batb": [[0, 2.86, 668.7], [1, 2.84, 649.04], [2, 2.82, 649.04]], "batl": [[1, 3.2, 328.71], [2, 3.25, 319.04]]}, {"timestamp": 1631534890642, "ltp": 2.88, "tv": 15546.86, "trd": NaN, "batb": [[0, 2.88, 47.53], [1, 2.86, 668.7], [2, 2.84, 649.04]], "batl": [[1, 3.15, 20.45], [2, 3.2, 328.71]]}, {"timestamp": 1631534898235, "ltp": 2.88, "tv": 15546.86, "trd": NaN, "batb": NaN, "batl": [[0, 3.05, 28.51]]}, {"timestamp": 1631534903648, "ltp": 2.88, "tv": 15546.86, "trd": NaN, "batb": [[1, 2.76, 17.04], [2, 2.66, 57.49]], "batl": [[0, 3.05, 4.5], [2, 3.25, 4.62]]}, {"timestamp": 1631534904168, "ltp": 2.88, "tv": 15546.86, "trd": NaN, "batb": [[0, 2.76, 17.04], [1, 2.66, 57.49], [2, 2.58, 2.89]], "batl": [[0, 3.15, 20.45], [1, 3.4, 4.19], [2, 3.65, 172.76]]}, {"timestamp": 1631534905436, "ltp": 2.88, "tv": 15546.86, "trd": NaN, "batb": [[0, 2.66, 57.49], [1, 2.58, 2.89], [2, 1.97, 400.31]], "batl": [[0, 3.4, 4.19], [1, 3.65, 172.76], [2, 3.65, 0]]}, {"timestamp": 1631534907365, "ltp": 2.88, "tv": 15546.86, "trd": NaN, "batb": NaN, "batl": [[0, 3.15, 3], [1, 3.25, 4.54], [2, 3.4, 4.19]]}, {"timestamp": 1631534907728, "ltp": 2.88, "tv": 15546.86, "trd": NaN, "batb": NaN, "batl": [[1, 3.4, 4.19], [2, 3.65, 172.76]]}, {"timestamp": 1631534909456, "ltp": 2.88, "tv": 15546.86, "trd": NaN, "batb": [[0, 2.66, 60.49], [1, 2.64, 4], [2, 2.58, 2.89]], "batl": [[1, 3.4, 7.19]]}, {"timestamp": 1631534909939, "ltp": 2.88, "tv": 15546.86, "trd": NaN, "batb": [[0, 2.68, 4], [1, 2.66, 60.49], [2, 2.64, 4]], "batl": NaN}, {"timestamp": 1631534911358, "ltp": 2.88, "tv": 15546.86, "trd": NaN, "batb": NaN, "batl": [[0, 3.4, 7.19], [1, 3.4, 0], [2, 3.65, 0]]}, {"timestamp": 1631534913648, "ltp": 3.15, "tv": 15554.49, "trd": [[3.15, 7.63]], "batb": [[0, 3.1, 95.31], [1, 2.96, 15.3], [2, 2.88, 47.7]], "batl": NaN}, {"timestamp": 1631534914546, "ltp": 3.15, "tv": 15554.49, "trd": NaN, "batb": NaN, "batl": [[0, 3.35, 21.74], [1, 3.4, 7.19]]}, {"timestamp": 1631534915650, "ltp": 3.15, "tv": 15554.49, "trd": NaN, "batb": [[1, 3.05, 3], [2, 3, 3]], "batl": [[2, 4.6, 137.93]]}, {"timestamp": 1631534915964, "ltp": 3.15, "tv": 15554.49, "trd": NaN, "batb": NaN, "batl": [[1, 3.4, 4.19]]}, {"timestamp": 1631534917477, "ltp": 3.15, "tv": 15554.49, "trd": NaN, "batb": NaN, "batl": [[1, 3.4, 23.55]]}, {"timestamp": 1631534919307, "ltp": 3.15, "tv": 15554.49, "trd": NaN, "batb": NaN, "batl": [[2, 3.65, 111.04]]}, {"timestamp": 1631534921604, "ltp": 3.15, "tv": 15554.49, "trd": NaN, "batb": [[2, 3, 18]], "batl": NaN}, {"timestamp": 1631534925618, "ltp": 3.15, "tv": 15554.49, "trd": NaN, "batb": [[1, 3, 15], [2, 2.92, 148.56]], "batl": [[0, 3.4, 23.55], [1, 3.65, 111.04], [2, 3.7, 152.7]]}, {"timestamp": 1631534926614, "ltp": 3.15, "tv": 15554.49, "trd": NaN, "batb": [[0, 3, 15], [1, 2.92, 148.56], [2, 2.9, 164.22]], "batl": [[0, 3.4, 19.36]]}, {"timestamp": 1631534927406, "ltp": 3.15, "tv": 15554.49, "trd": NaN, "batb": [[0, 2.92, 152.75], [1, 2.9, 164.22], [2, 2.88, 241.02]], "batl": [[0, 3.65, 106.94], [1, 3.7, 152.7], [2, 3.75, 173.38]]}, {"timestamp": 1631534933399, "ltp": 3.15, "tv": 15554.49, "trd": NaN, "batb": NaN, "batl": [[0, 3.65, 4.3], [1, 3.9, 3.65], [2, 3.95, 3.7]]}, {"timestamp": 1631534934605, "ltp": 3.15, "tv": 15554.49, "trd": NaN, "batb": NaN, "batl": [[0, 3.9, 3.65], [1, 3.95, 3.7], [2, 3.95, 0]]}, {"timestamp": 1631534936530, "ltp": 2.92, "tv": 15567.58, "trd": [[2.92, 10.06], [3, 6.17]], "batb": [[0, 2.92, 147.72]], "batl": [[0, 3.1, 15.05], [1, 3.15, 616.94], [2, 3.25, 598.8]]}, {"timestamp": 1631534937524, "ltp": 2.92, "tv": 15567.58, "trd": NaN, "batb": NaN, "batl": [[2, 3.2, 20.22]]}, {"timestamp": 1631534938209, "ltp": 2.92, "tv": 15567.58, "trd": NaN, "batb": NaN, "batl": [[2, 3.25, 598.8]]}, {"timestamp": 1631534941539, "ltp": 2.92, "tv": 15567.58, "trd": NaN, "batb": NaN, "batl": [[0, 3.05, 22.44], [1, 3.1, 15.05], [2, 3.15, 616.94]]}, {"timestamp": 1631534944635, "ltp": 2.92, "tv": 15567.58, "trd": NaN, "batb": NaN, "batl": [[1, 3.1, 35.75]]}, {"timestamp": 1631534949631, "ltp": 2.92, "tv": 15567.58, "trd": NaN, "batb": [[0, 2.92, 4.19], [1, 2.88, 47.7], [2, 2.76, 17.04]], "batl": [[0, 3.1, 35.75], [1, 3.35, 4.5], [2, 3.6, 4.16]]}, {"timestamp": 1631534950045, "ltp": 2.92, "tv": 15567.58, "trd": NaN, "batb": [[0, 2.76, 17.04], [1, 2.7, 3], [2, 2.66, 57.49]], "batl": [[0, 3.1, 20.7]]}, {"timestamp": 1631534951457, "ltp": 2.92, "tv": 15567.58, "trd": NaN, "batb": [[0, 2.7, 3], [1, 2.66, 57.49], [2, 2.58, 2.89]], "batl": [[0, 3.35, 4.5], [1, 3.6, 4.16], [2, 3.9, 164.08]]}, {"timestamp": 1631534953441, "ltp": 2.92, "tv": 15567.58, "trd": NaN, "batb": [[0, 2.76, 4], [1, 2.74, 3], [2, 2.7, 3]], "batl": NaN}, {"timestamp": 1631534954649, "ltp": 2.92, "tv": 15567.58, "trd": NaN, "batb": [[2, 2.72, 3]], "batl": [[0, 3.3, 3], [1, 3.35, 4.5], [2, 3.6, 4.16]]}, {"timestamp": 1631534958626, "ltp": 2.92, "tv": 15567.58, "trd": NaN, "batb": [[0, 2.78, 657.72], [1, 2.76, 4], [2, 2.74, 3]], "batl": [[0, 3.35, 4.5], [1, 3.6, 4.16], [2, 3.9, 3.65]]}, {"timestamp": 1631534959571, "ltp": 3.15, "tv": 15575.21, "trd": [[3.15, 15.26]], "batb": [[0, 3.1, 95.73], [1, 2.96, 15.3], [2, 2.84, 48.79]], "batl": [[1, 3.4, 19.36], [2, 3.6, 4.16]]}, {"timestamp": 1631534961662, "ltp": 3.15, "tv": 15575.21, "trd": NaN, "batb": NaN, "batl": [[0, 3.35, 24.8]]}, {"timestamp": 1631534962448, "ltp": 3.15, "tv": 15575.21, "trd": NaN, "batb": [[1, 3.05, 3], [2, 3, 4]], "batl": NaN}, {"timestamp": 1631534963643, "ltp": 3.15, "tv": 15583.87, "trd": [[3.15, 23.92]], "batb": NaN, "batl": NaN}, {"timestamp": 1631534967658, "ltp": 3.15, "tv": 15583.87, "trd": NaN, "batb": [[2, 3, 19]], "batl": NaN}, {"timestamp": 1631534974590, "ltp": 3.15, "tv": 15583.87, "trd": NaN, "batb": [[2, 3, 15]], "batl": NaN}, {"timestamp": 1631534975052, "ltp": 3.15, "tv": 15583.87, "trd": NaN, "batb": [[0, 3.05, 3], [1, 3, 15], [2, 2.92, 178.07]], "batl": [[0, 3.4, 19.36], [1, 3.65, 120.34], [2, 3.7, 149.25]]}, {"timestamp": 1631534976455, "ltp": 3.15, "tv": 15583.87, "trd": NaN, "batb": [[0, 2.92, 178.07], [1, 2.9, 182.42], [2, 2.88, 176.18]], "batl": [[0, 3.65, 116.44], [1, 3.7, 149.25], [2, 3.75, 186.89]]}, {"timestamp": 1631534977606, "ltp": 3.15, "tv": 15583.87, "trd": NaN, "batb": [[0, 3, 3], [1, 2.92, 178.07], [2, 2.9, 182.42]], "batl": NaN}, {"timestamp": 1631534978184, "ltp": 3.15, "tv": 15583.87, "trd": NaN, "batb": [[0, 2.92, 178.07], [1, 2.9, 182.42], [2, 2.88, 176.18]], "batl": NaN}, {"timestamp": 1631534979588, "ltp": 3.15, "tv": 15583.87, "trd": NaN, "batb": [[0, 2.92, 180.07], [1, 2.9, 184.42]], "batl": NaN}, {"timestamp": 1631534980374, "ltp": 3.15, "tv": 15583.87, "trd": NaN, "batb": NaN, "batl": [[0, 3.3, 18.35], [1, 3.65, 116.44], [2, 3.7, 149.25]]}, {"timestamp": 1631534980681, "ltp": 3.15, "tv": 15583.87, "trd": NaN, "batb": NaN, "batl": [[0, 3.65, 116.44], [1, 3.7, 149.25], [2, 3.75, 186.89]]}, {"timestamp": 1631534982562, "ltp": 3.15, "tv": 15583.87, "trd": NaN, "batb": [[0, 2.94, 54.1], [1, 2.92, 180.07], [2, 2.9, 184.42]], "batl": [[0, 3.6, 38.15], [1, 3.65, 120.34], [2, 3.7, 149.25]]}, {"timestamp": 1631534987466, "ltp": 3.15, "tv": 15583.87, "trd": NaN, "batb": [[0, 2.92, 180.07], [1, 2.9, 184.42], [2, 2.88, 176.18]], "batl": [[0, 3.65, 120.34], [1, 3.7, 149.25], [2, 3.75, 186.89]]}, {"timestamp": 1631534987992, "ltp": 3.15, "tv": 15583.87, "trd": NaN, "batb": NaN, "batl": [[0, 3.65, 116.44]]}, {"timestamp": 1631534990914, "ltp": 3.15, "tv": 15583.87, "trd": NaN, "batb": NaN, "batl": [[0, 3.65, 120.34]]}, {"timestamp": 1631534992586, "ltp": 3.15, "tv": 15583.87, "trd": NaN, "batb": NaN, "batl": [[0, 3.65, 116.44]]}, {"timestamp": 1631534992893, "ltp": 3.15, "tv": 15583.87, "trd": NaN, "batb": [[1, 2.9, 182.42]], "batl": NaN}, {"timestamp": 1631534995524, "ltp": 3.15, "tv": 15583.87, "trd": NaN, "batb": [[0, 2.92, 2], [1, 2.84, 48.79], [2, 2.58, 2.89]], "batl": NaN}, {"timestamp": 1631534998630, "ltp": 3.15, "tv": 15583.87, "trd": NaN, "batb": [[0, 3.55, 546.44], [1, 3.45, 530.36], [2, 3.4, 530.36]], "batl": [[0, 3.7, 149.25], [1, 3.75, 186.89], [2, 3.95, 3.7]]}, {"timestamp": 1631534999518, "ltp": 3.55, "tv": 15597.95, "trd": [[3.55, 14.08]], "batb": [[0, 3.55, 539.4], [1, 3.5, 70.63], [2, 3.45, 530.36]], "batl": [[0, 3.75, 186.89], [1, 3.95, 3.7], [2, 3.95, 0]]}, {"timestamp": 1631535000616, "ltp": 3.55, "tv": 15597.95, "trd": NaN, "batb": NaN, "batl": [[0, 3.75, 204.98]]}, {"timestamp": 1631535002579, "ltp": 3.55, "tv": 15597.95, "trd": NaN, "batb": NaN, "batl": [[0, 3.75, 221.81]]}, {"timestamp": 1631535005610, "ltp": 3.55, "tv": 15597.95, "trd": NaN, "batb": NaN, "batl": [[0, 3.75, 204.98], [2, 4.1, 103.34]]}, {"timestamp": 1631535007602, "ltp": 3.55, "tv": 15597.95, "trd": NaN, "batb": [[0, 3.55, 608.85], [1, 3.5, 164.91]], "batl": NaN}, {"timestamp": 1631535008589, "ltp": 3.55, "tv": 15597.95, "trd": NaN, "batb": NaN, "batl": [[0, 3.7, 16.83], [1, 3.75, 204.98], [2, 3.95, 3.7]]}, {"timestamp": 1631535030522, "ltp": 3.55, "tv": 15597.95, "trd": NaN, "batb": NaN, "batl": [[0, 3.75, 204.98], [1, 3.95, 3.7], [2, 4.1, 103.34]]}, {"timestamp": 1631535037634, "ltp": 3.55, "tv": 15602.29, "trd": [[3.55, 18.42]], "batb": [[0, 3.55, 606.68]], "batl": NaN}, {"timestamp": 1631535051344, "ltp": 3.55, "tv": 15602.29, "trd": NaN, "batb": NaN, "batl": [[0, 3.7, 24.32], [1, 3.75, 204.98], [2, 3.95, 3.7]]}, {"timestamp": 1631535066278, "ltp": 3.55, "tv": 15602.29, "trd": NaN, "batb": NaN, "batl": [[0, 3.75, 204.98], [1, 3.95, 3.7], [2, 4.1, 103.34]]}, {"timestamp": 1631535074481, "ltp": 3.55, "tv": 15627.84, "trd": [[3.55, 43.97]], "batb": [[0, 3.55, 593.91]], "batl": NaN}, {"timestamp": 1631535077991, "ltp": 3.55, "tv": 15629.28, "trd": [[3.55, 45.41]], "batb": [[0, 3.55, 593.19]], "batl": NaN}, {"timestamp": 1631535080860, "ltp": 3.55, "tv": 15630.73, "trd": [[3.55, 46.85]], "batb": [[0, 3.55, 592.47]], "batl": NaN}, {"timestamp": 1631535090502, "ltp": 3.55, "tv": 15630.73, "trd": NaN, "batb": NaN, "batl": [[0, 3.75, 379.56]]}, {"timestamp": 1631535093294, "ltp": 3.55, "tv": 15816.46, "trd": [[3.55, 232.58]], "batb": [[0, 3.55, 499.59]], "batl": NaN}, {"timestamp": 1631535112217, "ltp": 3.55, "tv": 15852.08, "trd": [[3.55, 268.2]], "batb": [[0, 3.55, 481.78]], "batl": [[0, 3.75, 361.47]]}, {"timestamp": 1631535115431, "ltp": 3.55, "tv": 15852.08, "trd": NaN, "batb": NaN, "batl": [[1, 3.8, 17.92], [2, 3.95, 3.7]]}, {"timestamp": 1631535130952, "ltp": 3.55, "tv": 15852.1, "trd": [[3.55, 268.22]], "batb": [[0, 3.55, 481.77]], "batl": NaN}, {"timestamp": 1631535139864, "ltp": 3.55, "tv": 15852.1, "trd": NaN, "batb": NaN, "batl": [[0, 3.7, 27.86], [1, 3.75, 361.47], [2, 3.8, 17.92]]}, {"timestamp": 1631535147654, "ltp": 3.55, "tv": 15852.1, "trd": NaN, "batb": [[0, 3.55, 69.45], [2, 3.15, 250.73]], "batl": NaN}, {"timestamp": 1631535148658, "ltp": 3.55, "tv": 15852.1, "trd": NaN, "batb": [[0, 3.15, 250.73], [1, 3.1, 160.07], [2, 3.05, 212.46]], "batl": [[0, 3.8, 17.92], [1, 4.1, 103.34], [2, 4.2, 112.26]]}, {"timestamp": 1631535149490, "ltp": 3.55, "tv": 15852.1, "trd": NaN, "batb": NaN, "batl": [[0, 4.1, 103.34], [1, 4.2, 112.26], [2, 4.3, 124.22]]}, {"timestamp": 1631535152658, "ltp": 3.55, "tv": 15852.1, "trd": NaN, "batb": [[0, 3.15, 253.73], [1, 3.1, 163.07]], "batl": NaN}, {"timestamp": 1631535158409, "ltp": 3.55, "tv": 15852.1, "trd": NaN, "batb": NaN, "batl": [[0, 990, 0.01], [1, 4.2, 0], [2, 4.3, 0]]}, {"timestamp": 1631535160419, "ltp": 3.55, "tv": 15852.1, "trd": NaN, "batb": [[0, 3.15, 250.73], [1, 3.1, 160.07]], "batl": NaN}, {"timestamp": 1631535161520, "ltp": 3.15, "tv": 15867.26, "trd": [[3.15, 39.08]], "batb": [[0, 3.15, 243.15], [2, 3.05, 557.34]], "batl": [[0, 3.35, 14.1], [1, 3.4, 562.5], [2, 3.45, 545.96]]}, {"timestamp": 1631535162627, "ltp": 3.15, "tv": 15867.26, "trd": NaN, "batb": NaN, "batl": [[2, 3.45, 565.12]]}, {"timestamp": 1631535163620, "ltp": 3.15, "tv": 15867.26, "trd": NaN, "batb": NaN, "batl": [[0, 3.3, 3], [1, 3.35, 14.1], [2, 3.4, 562.5]]}, {"timestamp": 1631535164520, "ltp": 3.15, "tv": 15867.26, "trd": NaN, "batb": NaN, "batl": [[1, 3.35, 17.1]]}, {"timestamp": 1631535166596, "ltp": 3.15, "tv": 15880.34, "trd": [[3.15, 52.17]], "batb": [[0, 3.15, 236.61]], "batl": [[0, 3.25, 3], [1, 3.3, 3], [2, 3.35, 17.1]]}, {"timestamp": 1631535167640, "ltp": 3.15, "tv": 15880.34, "trd": NaN, "batb": NaN, "batl": [[0, 3.25, 44.64]]}, {"timestamp": 1631535168432, "ltp": 3.15, "tv": 15880.34, "trd": NaN, "batb": NaN, "batl": [[0, 3.25, 3]]}, {"timestamp": 1631535169536, "ltp": 3.15, "tv": 15880.34, "trd": NaN, "batb": NaN, "batl": [[1, 3.3, 204.08]]}, {"timestamp": 1631535171219, "ltp": 3.15, "tv": 15880.34, "trd": NaN, "batb": NaN, "batl": [[0, 3.2, 15], [1, 3.25, 3], [2, 3.3, 204.08]]}, {"timestamp": 1631535177656, "ltp": 3.15, "tv": 15880.34, "trd": NaN, "batb": [[0, 3.15, 75.66], [1, 2.98, 15.15], [2, 2.92, 46.02]], "batl": [[0, 3.4, 19.36], [1, 3.6, 139.76], [2, 3.65, 178.45]]}, {"timestamp": 1631535178444, "ltp": 3.15, "tv": 15880.34, "trd": NaN, "batb": [[0, 2.92, 46.02], [1, 2.88, 1.45], [2, 2.82, 145.68]], "batl": [[0, 3.6, 139.76], [1, 3.65, 178.45], [2, 3.7, 144.03]]}, {"timestamp": 1631535178919, "ltp": 3.15, "tv": 15880.34, "trd": NaN, "batb": NaN, "batl": [[0, 3.6, 135.6]]}, {"timestamp": 1631535181453, "ltp": 3.15, "tv": 15880.34, "trd": NaN, "batb": [[0, 2.9, 46.28], [1, 2.88, 2.17]], "batl": NaN}, {"timestamp": 1631535185633, "ltp": 3.15, "tv": 15880.34, "trd": NaN, "batb": NaN, "batl": [[0, 3.6, 139.91]]}, {"timestamp": 1631535185951, "ltp": 3.15, "tv": 15880.34, "trd": NaN, "batb": NaN, "batl": [[0, 3.6, 135.6]]}, {"timestamp": 1631535190649, "ltp": 3.15, "tv": 15880.34, "trd": NaN, "batb": NaN, "batl": [[0, 3.55, 3.98], [1, 3.6, 135.6], [2, 3.65, 178.45]]}, {"timestamp": 1631535192541, "ltp": 3.15, "tv": 15880.34, "trd": NaN, "batb": NaN, "batl": [[1, 3.6, 139.31]]}, {"timestamp": 1631535192753, "ltp": 3.15, "tv": 15880.34, "trd": NaN, "batb": NaN, "batl": [[1, 3.6, 135.6]]}, {"timestamp": 1631535199390, "ltp": 3.15, "tv": 15880.34, "trd": NaN, "batb": NaN, "batl": [[1, 3.6, 139.71]]}, {"timestamp": 1631535200393, "ltp": 3.15, "tv": 15880.34, "trd": NaN, "batb": NaN, "batl": [[1, 3.6, 135.6]]}, {"timestamp": 1631535201496, "ltp": 3.15, "tv": 15880.34, "trd": NaN, "batb": [[2, 2.58, 2.89]], "batl": NaN}, {"timestamp": 1631535204618, "ltp": 3.15, "tv": 15880.34, "trd": NaN, "batb": [[0, 3.45, 554.34], [1, 3.4, 538.04], [2, 3.35, 538.04]], "batl": [[1, 3.65, 178.45], [2, 3.7, 144.03]]}, {"timestamp": 1631535205480, "ltp": 3.45, "tv": 15894.52, "trd": [[3.45, 14.18]], "batb": [[0, 3.45, 619.55]], "batl": NaN}, {"timestamp": 1631535206475, "ltp": 3.45, "tv": 15894.52, "trd": NaN, "batb": NaN, "batl": [[0, 3.55, 22.94]]}, {"timestamp": 1631535213423, "ltp": 3.45, "tv": 15894.52, "trd": NaN, "batb": NaN, "batl": [[0, 3.55, 3.98]]}, {"timestamp": 1631535216323, "ltp": 3.45, "tv": 15894.52, "trd": NaN, "batb": NaN, "batl": [[0, 3.5, 18.96], [1, 3.55, 3.98], [2, 3.65, 178.45]]}, {"timestamp": 1631535218595, "ltp": 3.45, "tv": 15894.52, "trd": NaN, "batb": [[0, 3.45, 72.3], [1, 3.3, 13.04], [2, 3.05, 243.61]], "batl": NaN}, {"timestamp": 1631535219592, "ltp": 3.45, "tv": 15894.52, "trd": NaN, "batb": [[0, 3.3, 13.04], [1, 3.05, 243.61], [2, 3, 158.78]], "batl": [[0, 3.55, 3.98], [1, 4, 103.64], [2, 4.1, 148.11]]}, {"timestamp": 1631535220590, "ltp": 3.45, "tv": 15894.52, "trd": NaN, "batb": [[0, 3.05, 243.61], [1, 3, 158.78], [2, 2.98, 228.14]], "batl": NaN}, {"timestamp": 1631535222490, "ltp": 3.45, "tv": 15894.52, "trd": NaN, "batb": NaN, "batl": [[0, 3.35, 1.7], [1, 3.55, 3.98], [2, 4, 103.64]]}, {"timestamp": 1631535223602, "ltp": 3.45, "tv": 15894.52, "trd": NaN, "batb": NaN, "batl": [[0, 3.45, 2.32]]}, {"timestamp": 1631535223815, "ltp": 3.45, "tv": 15894.52, "trd": NaN, "batb": [[0, 3.05, 245.61], [1, 3, 160.78]], "batl": NaN}, {"timestamp": 1631535226516, "ltp": 3.45, "tv": 15894.52, "trd": NaN, "batb": NaN, "batl": [[2, 4.2, 3.48]]}, {"timestamp": 1631535228627, "ltp": 3.45, "tv": 15894.52, "trd": NaN, "batb": [[0, 3.05, 243.61], [1, 3, 158.78]], "batl": NaN}, {"timestamp": 1631535229629, "ltp": 3.05, "tv": 15909.91, "trd": [[3.05, 15.38]], "batb": [[0, 3.05, 235.91]], "batl": [[0, 3.25, 588.46], [1, 3.3, 571.16], [2, 3.35, 571.16]]}, {"timestamp": 1631535231633, "ltp": 3.05, "tv": 15909.91, "trd": NaN, "batb": NaN, "batl": [[0, 3.2, 3], [1, 3.25, 588.46], [2, 3.3, 571.16]]}, {"timestamp": 1631535232420, "ltp": 3.05, "tv": 15909.91, "trd": NaN, "batb": NaN, "batl": [[0, 3.15, 3], [1, 3.2, 3], [2, 3.25, 588.46]]}, {"timestamp": 1631535234631, "ltp": 3.05, "tv": 15909.91, "trd": NaN, "batb": NaN, "batl": [[1, 3.2, 40.31]]}, {"timestamp": 1631535235627, "ltp": 3.05, "tv": 15909.91, "trd": NaN, "batb": NaN, "batl": [[1, 3.2, 3]]}, {"timestamp": 1631535238516, "ltp": 3.05, "tv": 15909.91, "trd": NaN, "batb": [[0, 3.05, 89.54]], "batl": NaN}, {"timestamp": 1631535241531, "ltp": 3.05, "tv": 15909.91, "trd": NaN, "batb": NaN, "batl": [[0, 3.1, 15], [1, 3.15, 3], [2, 3.2, 3]]}, {"timestamp": 1631535244634, "ltp": 3.05, "tv": 15913.32, "trd": [[3.05, 18.79]], "batb": [[0, 2.96, 15.3], [1, 2.78, 50.96], [2, 2.3, 390.4]], "batl": [[0, 3.35, 19.56], [1, 3.45, 2.32], [2, 3.55, 3.98]]}, {"timestamp": 1631535245525, "ltp": 3.05, "tv": 15913.32, "trd": NaN, "batb": [[0, 2.78, 50.96], [1, 2.3, 390.4], [2, 1.2, 62]], "batl": [[0, 3.45, 2.32], [1, 3.55, 3.98], [2, 3.9, 3.75]]}, {"timestamp": 1631535247624, "ltp": 3.05, "tv": 15913.32, "trd": NaN, "batb": NaN, "batl": [[2, 3.6, 4.01]]}, {"timestamp": 1631535248460, "ltp": 3.05, "tv": 15913.32, "trd": NaN, "batb": NaN, "batl": [[2, 3.9, 3.75]]}, {"timestamp": 1631535249038, "ltp": 3.05, "tv": 15913.32, "trd": NaN, "batb": [[1, 2.3, 391.12]], "batl": NaN}, {"timestamp": 1631535250349, "ltp": 3.05, "tv": 15913.32, "trd": NaN, "batb": [[1, 2.58, 2.17], [2, 2.3, 390.4]], "batl": NaN}, {"timestamp": 1631535251449, "ltp": 3.05, "tv": 15913.32, "trd": NaN, "batb": [[1, 2.58, 2.89]], "batl": NaN}, {"timestamp": 1631535251868, "ltp": 3.05, "tv": 15913.32, "trd": NaN, "batb": [[1, 2.58, 3.62]], "batl": NaN}, {"timestamp": 1631535254657, "ltp": 3.05, "tv": 15913.32, "trd": NaN, "batb": NaN, "batl": [[2, 3.6, 4.16]]}, {"timestamp": 1631535254924, "ltp": 3.05, "tv": 15913.32, "trd": NaN, "batb": NaN, "batl": [[2, 3.9, 3.75]]}, {"timestamp": 1631535257073, "ltp": 3.05, "tv": 15913.32, "trd": NaN, "batb": [[1, 2.58, 4.34]], "batl": NaN}, {"timestamp": 1631535261545, "ltp": 3.05, "tv": 15913.32, "trd": NaN, "batb": [[0, 3.35, 1141.78], [1, 3.3, 1108.2], [2, 3.25, 1108.2]], "batl": NaN}, {"timestamp": 1631535262551, "ltp": 3.4, "tv": 15927.5, "trd": [[3.4, 14.18]], "batb": [[0, 3.4, 67.55], [1, 3.35, 570.9], [2, 3.3, 554.1]], "batl": NaN}, {"timestamp": 1631535263346, "ltp": 3.4, "tv": 15927.5, "trd": NaN, "batb": NaN, "batl": [[0, 3.45, 13.92]]}, {"timestamp": 1631535267643, "ltp": 3.4, "tv": 15927.5, "trd": NaN, "batb": NaN, "batl": [[0, 3.45, 2.32]]}, {"timestamp": 1631535270155, "ltp": 3.4, "tv": 15927.5, "trd": NaN, "batb": [[2, 3.3, 567.14]], "batl": NaN}, {"timestamp": 1631535270787, "ltp": 3.4, "tv": 15950.71, "trd": [[3.4, 37.39]], "batb": [[0, 3.4, 55.94]], "batl": NaN}, {"timestamp": 1631535283571, "ltp": 3.4, "tv": 15967.75, "trd": [[3.4, 54.43]], "batb": [[0, 3.3, 13.04], [1, 2.96, 105.69], [2, 2.9, 156.61]], "batl": [[2, 3.95, 3.9]]}, {"timestamp": 1631535284365, "ltp": 3.4, "tv": 15967.75, "trd": NaN, "batb": [[0, 2.96, 105.69], [1, 2.9, 156.61], [2, 2.88, 163.47]], "batl": [[2, 4, 134.96]]}, {"timestamp": 1631535286566, "ltp": 3.4, "tv": 15967.75, "trd": NaN, "batb": [[1, 2.94, 106.61], [2, 2.9, 156.61]], "batl": NaN}, {"timestamp": 1631535287561, "ltp": 3.4, "tv": 15967.75, "trd": NaN, "batb": [[0, 2.96, 3], [1, 2.94, 108.61]], "batl": NaN}, {"timestamp": 1631535290605, "ltp": 3.4, "tv": 15967.75, "trd": NaN, "batb": [[2, 2.92, 4]], "batl": [[2, 3.95, 3.5]]}, {"timestamp": 1631535290873, "ltp": 3.4, "tv": 15967.75, "trd": NaN, "batb": NaN, "batl": [[2, 4, 134.96]]}, {"timestamp": 1631535295480, "ltp": 3.4, "tv": 15967.75, "trd": NaN, "batb": NaN, "batl": [[2, 4.4, 3.44]]}, {"timestamp": 1631535296609, "ltp": 3.4, "tv": 15967.75, "trd": NaN, "batb": [[1, 2.94, 2]], "batl": NaN}, {"timestamp": 1631535298501, "ltp": 2.94, "tv": 15980.06, "trd": [[2.94, 2.74], [2.96, 9.57]], "batb": [[0, 2.9, 156.61], [1, 2.88, 163.47], [2, 2.86, 239.16]], "batl": [[0, 3.1, 632.39], [1, 3.15, 598.8], [2, 3.2, 598.8]]}, {"timestamp": 1631535299569, "ltp": 2.94, "tv": 15980.06, "trd": NaN, "batb": [[0, 2.92, 107.03], [1, 2.9, 172.39], [2, 2.88, 163.47]], "batl": NaN}, {"timestamp": 1631535301268, "ltp": 2.94, "tv": 15980.06, "trd": NaN, "batb": NaN, "batl": [[0, 3, 3], [1, 3.05, 3], [2, 3.1, 632.39]]}, {"timestamp": 1631535303605, "ltp": 2.92, "tv": 15982.13, "trd": [[2.92, 12.14]], "batb": [[0, 2.92, 105.99]], "batl": NaN}, {"timestamp": 1631535304502, "ltp": 2.92, "tv": 15982.13, "trd": NaN, "batb": NaN, "batl": [[0, 2.98, 3], [1, 3, 3], [2, 3.05, 3]]}, {"timestamp": 1631535310203, "ltp": 2.92, "tv": 15982.13, "trd": NaN, "batb": NaN, "batl": [[0, 2.96, 15], [1, 2.98, 3], [2, 3, 3]]}, {"timestamp": 1631535313425, "ltp": 2.92, "tv": 15982.13, "trd": NaN, "batb": [[1, 2.9, 156.61]], "batl": [[2, 3.1, 632.39]]}, {"timestamp": 1631535314528, "ltp": 2.92, "tv": 15982.13, "trd": NaN, "batb": [[0, 2.56, 60.84], [1, 2.48, 145.86], [2, 2.46, 173.89]], "batl": [[0, 3.45, 140.69], [1, 3.5, 144.82], [2, 3.55, 150.79]]}, {"timestamp": 1631535316632, "ltp": 2.92, "tv": 15982.13, "trd": NaN, "batb": [[0, 2.66, 3], [1, 2.56, 60.84], [2, 2.48, 145.86]], "batl": NaN}, {"timestamp": 1631535317534, "ltp": 2.92, "tv": 15982.13, "trd": NaN, "batb": [[0, 2.56, 60.84], [1, 2.48, 145.86], [2, 2.46, 173.89]], "batl": NaN}, {"timestamp": 1631535324641, "ltp": 2.92, "tv": 15982.13, "trd": NaN, "batb": NaN, "batl": [[0, 3.45, 144.59]]}, {"timestamp": 1631535325133, "ltp": 2.92, "tv": 15982.13, "trd": NaN, "batb": NaN, "batl": [[0, 3.45, 140.69]]}, {"timestamp": 1631535326411, "ltp": 2.92, "tv": 15982.13, "trd": NaN, "batb": NaN, "batl": [[0, 3.45, 2.32], [1, 3.55, 3.98], [2, 3.8, 3.42]]}, {"timestamp": 1631535328447, "ltp": 2.92, "tv": 15982.13, "trd": NaN, "batb": [[1, 2.5, 1.45], [2, 2.48, 145.86]], "batl": NaN}, {"timestamp": 1631535329641, "ltp": 2.56, "tv": 15999.84, "trd": [[2.56, 30.41]], "batb": [[0, 2.56, 51.98]], "batl": [[0, 3.15, 126.77], [1, 3.45, 2.32], [2, 3.55, 3.98]]}, {"timestamp": 1631535330648, "ltp": 2.56, "tv": 15999.84, "trd": NaN, "batb": NaN, "batl": [[0, 2.8, 11.6], [1, 3.15, 126.77], [2, 3.45, 2.32]]}, {"timestamp": 1631535331647, "ltp": 2.56, "tv": 16007.84, "trd": [[2.56, 38.41]], "batb": [[0, 2.56, 47.98]], "batl": [[1, 3.45, 2.32], [2, 3.55, 3.98]]}, {"timestamp": 1631535332530, "ltp": 2.56, "tv": 16046.34, "trd": [[2.56, 76.91]], "batb": [[0, 2.56, 9.48]], "batl": NaN}, {"timestamp": 1631535333663, "ltp": 2.56, "tv": 16046.34, "trd": NaN, "batb": NaN, "batl": [[0, 2.58, 3], [1, 2.8, 11.6], [2, 3.45, 2.32]]}, {"timestamp": 1631535334553, "ltp": 2.56, "tv": 16046.34, "trd": NaN, "batb": [[1, 2.52, 19.73], [2, 2.5, 1.45]], "batl": [[1, 2.82, 22.23]]}, {"timestamp": 1631535336552, "ltp": 2.56, "tv": 16046.34, "trd": NaN, "batb": NaN, "batl": [[1, 2.8, 153.45], [2, 2.82, 198.42]]}, {"timestamp": 1631535337242, "ltp": 2.56, "tv": 16065.29, "trd": [[2.56, 95.86]], "batb": [[0, 2.52, 19.73], [1, 2.48, 145.86], [2, 2.46, 173.89]], "batl": [[0, 2.56, 5.53], [1, 2.58, 3], [2, 2.8, 153.45]]}, {"timestamp": 1631535338638, "ltp": 2.56, "tv": 16065.29, "trd": NaN, "batb": [[0, 2.54, 62.01], [1, 2.52, 19.73], [2, 2.48, 145.86]], "batl": NaN}, {"timestamp": 1631535339170, "ltp": 2.56, "tv": 16065.29, "trd": NaN, "batb": NaN, "batl": [[2, 2.76, 22.61]]}, {"timestamp": 1631535340159, "ltp": 2.56, "tv": 16068.18, "trd": [[2.56, 98.74]], "batb": NaN, "batl": [[0, 2.58, 3], [1, 2.76, 22.61], [2, 2.8, 153.45]]}, {"timestamp": 1631535343577, "ltp": 2.54, "tv": 16068.24, "trd": [[2.54, 0.06]], "batb": [[0, 2.54, 61.95]], "batl": NaN}, {"timestamp": 1631535344571, "ltp": 2.54, "tv": 16068.24, "trd": NaN, "batb": NaN, "batl": [[0, 2.56, 15], [1, 2.58, 3], [2, 2.76, 22.61]]}, {"timestamp": 1631535347410, "ltp": 2.54, "tv": 16153.43, "trd": [[2.54, 85.26]], "batb": [[0, 2.54, 19.34]], "batl": NaN}, {"timestamp": 1631535351588, "ltp": 2.54, "tv": 16157.79, "trd": [[2.54, 89.62]], "batb": [[0, 2.54, 16.44], [1, 2.48, 145.86], [2, 2.46, 173.89]], "batl": [[2, 2.8, 153.45]]}, {"timestamp": 1631535354598, "ltp": 2.54, "tv": 16157.79, "trd": NaN, "batb": NaN, "batl": [[2, 2.66, 23.28]]}, {"timestamp": 1631535355017, "ltp": 2.54, "tv": 16157.79, "trd": NaN, "batb": NaN, "batl": [[2, 2.8, 153.45]]}, {"timestamp": 1631535358197, "ltp": 2.56, "tv": 16159.24, "trd": [[2.56, 100.19]], "batb": NaN, "batl": [[0, 2.56, 14.28], [2, 2.64, 23.42]]}, {"timestamp": 1631535358931, "ltp": 2.46, "tv": 16565.1, "trd": [[2.46, 81.31], [2.48, 291.69], [2.54, 122.49]], "batb": [[0, 2.46, 133.24], [1, 2.44, 237.16], [2, 2.42, 434.66]], "batl": NaN}, {"timestamp": 1631535360398, "ltp": 2.56, "tv": 16566.55, "trd": [[2.56, 101.63]], "batb": NaN, "batl": [[0, 2.58, 3], [1, 2.64, 23.42], [2, 2.8, 153.45]]}, {"timestamp": 1631535363493, "ltp": 2.56, "tv": 16566.55, "trd": NaN, "batb": NaN, "batl": [[0, 2.54, 13.56], [1, 2.58, 3], [2, 2.64, 23.42]]}, {"timestamp": 1631535363702, "ltp": 2.56, "tv": 16566.55, "trd": NaN, "batb": NaN, "batl": [[0, 2.58, 3], [1, 2.64, 23.42], [2, 2.8, 153.45]]}, {"timestamp": 1631535366934, "ltp": 2.56, "tv": 16566.55, "trd": NaN, "batb": NaN, "batl": [[0, 2.56, 15], [1, 2.58, 3], [2, 2.64, 23.42]]}, {"timestamp": 1631535368548, "ltp": 2.56, "tv": 16566.55, "trd": NaN, "batb": NaN, "batl": [[0, 2.54, 13.78], [1, 2.56, 15], [2, 2.58, 3]]}, {"timestamp": 1631535369642, "ltp": 2.56, "tv": 16566.55, "trd": NaN, "batb": NaN, "batl": [[1, 2.56, 3]]}, {"timestamp": 1631535370008, "ltp": 2.56, "tv": 16566.55, "trd": NaN, "batb": [[2, 2.42, 455.78]], "batl": NaN}, {"timestamp": 1631535372613, "ltp": 2.56, "tv": 16566.55, "trd": NaN, "batb": NaN, "batl": [[0, 2.52, 20.75]]}, {"timestamp": 1631535373237, "ltp": 2.56, "tv": 16566.55, "trd": NaN, "batb": NaN, "batl": [[0, 2.56, 3], [1, 2.58, 3], [2, 2.64, 23.42]]}, {"timestamp": 1631535376021, "ltp": 2.56, "tv": 16566.55, "trd": NaN, "batb": NaN, "batl": [[0, 2.54, 20.75], [1, 2.56, 3], [2, 2.58, 3]]}, {"timestamp": 1631535379539, "ltp": 2.56, "tv": 16566.55, "trd": NaN, "batb": [[0, 2.42, 21.12], [1, 2.34, 246.92], [2, 2.32, 201.27]], "batl": [[0, 2.64, 23.42], [1, 2.8, 153.45], [2, 2.82, 198.42]]}, {"timestamp": 1631535380426, "ltp": 2.56, "tv": 16566.55, "trd": NaN, "batb": [[0, 2.34, 246.92], [1, 2.32, 201.27], [2, 2.3, 245.84]], "batl": [[0, 2.8, 153.45], [1, 2.82, 198.42], [2, 2.84, 206.47]]}, {"timestamp": 1631535382455, "ltp": 2.56, "tv": 16566.55, "trd": NaN, "batb": [[1, 2.32, 280.34]], "batl": [[0, 2.46, 13.78], [1, 2.8, 153.45], [2, 2.82, 198.42]]}, {"timestamp": 1631535383665, "ltp": 2.56, "tv": 16566.55, "trd": NaN, "batb": [[0, 2.34, 173.85]], "batl": NaN}, {"timestamp": 1631535385049, "ltp": 2.56, "tv": 16566.55, "trd": NaN, "batb": NaN, "batl": [[0, 2.8, 153.45], [1, 2.82, 198.42], [2, 2.84, 206.47]]}, {"timestamp": 1631535398204, "ltp": 2.56, "tv": 16566.55, "trd": NaN, "batb": [[0, 2.34, 3], [1, 2.32, 79.08], [2, 1.97, 400.31]], "batl": NaN}, {"timestamp": 1631535399406, "ltp": 2.56, "tv": 16566.55, "trd": NaN, "batb": NaN, "batl": [[0, 2.84, 206.47], [1, 2.86, 5.25], [2, 3.1, 4.05]]}, {"timestamp": 1631535400665, "ltp": 2.56, "tv": 16566.55, "trd": NaN, "batb": [[0, 2.62, 2530.48], [1, 2.6, 448.48], [2, 2.58, 448.48]], "batl": NaN}, {"timestamp": 1631535401599, "ltp": 2.56, "tv": 16566.55, "trd": NaN, "batb": [[0, 2.7, 52.05], [1, 2.62, 1223.66], [2, 2.6, 448.48]], "batl": NaN}, {"timestamp": 1631535402605, "ltp": 2.72, "tv": 16574.88, "trd": [[2.72, 8.33]], "batb": NaN, "batl": [[0, 2.82, 3], [1, 2.84, 206.47], [2, 2.86, 5.25]]}, {"timestamp": 1631535405580, "ltp": 2.72, "tv": 16574.88, "trd": NaN, "batb": NaN, "batl": [[0, 2.78, 21.91], [1, 2.82, 3], [2, 2.84, 206.47]]}, {"timestamp": 1631535406208, "ltp": 2.7, "tv": 16577.39, "trd": [[2.7, 22.12]], "batb": [[0, 2.7, 50.79]], "batl": [[0, 2.78, 5.05]]}, {"timestamp": 1631535409512, "ltp": 2.7, "tv": 16577.39, "trd": NaN, "batb": [[1, 2.64, 18.29], [2, 2.62, 1223.66]], "batl": NaN}, {"timestamp": 1631535413528, "ltp": 2.7, "tv": 16577.39, "trd": NaN, "batb": [[0, 2.64, 18.29], [1, 2.5, 64.69], [2, 2.46, 3.93]], "batl": [[0, 2.78, 1.45], [1, 2.9, 21.76], [2, 3.05, 4.7]]}, {"timestamp": 1631535414625, "ltp": 2.7, "tv": 16577.39, "trd": NaN, "batb": [[0, 2.5, 64.69], [1, 2.46, 3.93], [2, 2.36, 4]], "batl": [[0, 2.7, 2.32], [1, 2.78, 1.45], [2, 3.25, 4.58]]}, {"timestamp": 1631535415514, "ltp": 2.7, "tv": 16577.39, "trd": NaN, "batb": NaN, "batl": [[1, 3.25, 4.58], [2, 3.45, 2.32]]}, {"timestamp": 1631535419635, "ltp": 2.7, "tv": 16579.71, "trd": [[2.7, 24.44]], "batb": [[2, 1.97, 400.31]], "batl": [[0, 2.78, 20.75]]}, {"timestamp": 1631535420627, "ltp": 2.7, "tv": 16579.71, "trd": NaN, "batb": NaN, "batl": [[0, 3.05, 4.7]]}, {"timestamp": 1631535420837, "ltp": 2.7, "tv": 16579.71, "trd": NaN, "batb": NaN, "batl": [[0, 3.25, 4.58], [1, 3.45, 2.32], [2, 3.9, 160.43]]}, {"timestamp": 1631535427516, "ltp": 2.7, "tv": 16579.71, "trd": NaN, "batb": NaN, "batl": [[0, 3.05, 4.9], [1, 3.25, 4.58], [2, 3.45, 2.32]]}, {"timestamp": 1631535427724, "ltp": 2.7, "tv": 16579.71, "trd": NaN, "batb": NaN, "batl": [[0, 3.25, 4.58], [1, 3.45, 2.32], [2, 3.9, 160.43]]}, {"timestamp": 1631535429325, "ltp": 2.7, "tv": 16579.71, "trd": NaN, "batb": NaN, "batl": [[2, 990, 0.01]]}, {"timestamp": 1631535430629, "ltp": 2.5, "tv": 16597.26, "trd": [[2.5, 17.55]], "batb": [[0, 2.5, 55.91], [2, 2.44, 1567.62]], "batl": [[0, 2.64, 17.68], [1, 2.66, 1437.96], [2, 2.68, 1395.68]]}, {"timestamp": 1631535431516, "ltp": 2.5, "tv": 16597.26, "trd": NaN, "batb": [[2, 2.44, 431.1]], "batl": [[1, 2.66, 718.98], [2, 2.68, 697.84]]}, {"timestamp": 1631535432446, "ltp": 2.5, "tv": 16597.26, "trd": NaN, "batb": [[2, 2.44, 451.93]], "batl": [[2, 2.68, 720.98]]}, {"timestamp": 1631535433644, "ltp": 2.5, "tv": 16597.26, "trd": NaN, "batb": NaN, "batl": [[0, 2.6, 4], [1, 2.64, 21.68], [2, 2.66, 718.98]]}, {"timestamp": 1631535435632, "ltp": 2.5, "tv": 16599.99, 