{"info": {"id": "1.187557653", "eventId": "30896062", "eventName": "Match Odds", "marketType": "MATCH_ODDS", "openDate": 1631531431830, "name": "Vi Sachko v Bobrov", "numberOfActiveRunner": 2, "countryCode": "", "sport": "TENNIS", "venue": "", "volume": {"total": 17349.87, "preMatch": 185.84, "inPlay": 17164.03}, "winner": {"id": 9433864, "name": "Vitaliy Sachko", "status": "WINNER", "position": 1}, "delay": 3}, "runners": [{"id": 9433864, "name": "Vitaliy Sachko", "status": "WINNER", "position": 1, "inPlayOdds": 1.33, "inPlayTime": 1631531431830, "avgPrematch": 1.39, "closedOdds": 1.01, "maxPrematch": 1.4, "minPrematch": 1.33, "maxInPlay": 4.1, "minInPlay": 1.01, "inPlayIndex": 36, "lengthOdds": 1687, "lengthOddsPrematch": 36, "lengthOddsInPlay": 1651, "tradedVolume": 12775.64, "preMatchVolume": 143.75, "inPlayVolume": 12631.89}, {"id": 9632596, "name": "Bogdan Bobrov", "status": "LOSER", "position": 2, "inPlayOdds": 4.0, "inPlayTime": 1631531431830, "avgPrematch": 3.81, "closedOdds": 50.0, "maxPrematch": 4.0, "minPrematch": 3.5, "maxInPlay": 50.0, "minInPlay": 1.3, "inPlayIndex": 13, "lengthOdds": 1374, "lengthOddsPrematch": 13, "lengthOddsInPlay": 1361, "tradedVolume": 4574.23, "preMatchVolume": 42.09, "inPlayVolume": 4532.14}], "marketUpdates": [{"timestamp": 1631462218712000000, "openDate": "2021-09-13T09:00:00.000Z", "status": "OPEN", "betDelay": 0, "inPlay": false, "complete": true}, {"timestamp": 1631462220320000000, "openDate": "2021-09-13T11:00:00.000Z", "status": "OPEN", "betDelay": 0, "inPlay": false, "complete": true}, {"timestamp": 1631523422610000000, "openDate": "2021-09-13T10:56:00.000Z", "status": "OPEN", "betDelay": 0, "inPlay": false, "complete": true}, {"timestamp": 1631530660642000000, "openDate": "2021-09-13T11:00:00.000Z", "status": "OPEN", "betDelay": 0, "inPlay": false, "complete": true}, {"timestamp": 1631530921994000000, "openDate": "2021-09-13T10:58:00.000Z", "status": "OPEN", "betDelay": 0, "inPlay": false, "complete": true}, {"timestamp": 1631531431830000000, "openDate": "2021-09-13T10:58:00.000Z", "status": "OPEN", "betDelay": 3, "inPlay": true, "complete": true}, {"timestamp": 1631539993857000000, "openDate": "2021-09-13T10:58:00.000Z", "status": "SUSPENDED", "betDelay": 3, "inPlay": true, "complete": true}, {"timestamp": 1631540097446000000, "openDate": "2021-09-13T10:58:00.000Z", "status": "CLOSED", "betDelay": 3, "inPlay": true, "complete": true}], "odds": [{"runnerId": 9433864, "odds": [{"timestamp": 1631512357878, "ltp": 1.4, "tv": 4.0, "trd": [[1.4, 4]], "batb": [[0, 1.4, 12.46], [1, 1.13, 136.27], [2, 1.1, 108.5]], "batl": NaN}, {"timestamp": 1631514017267, "ltp": 1.4, "tv": 4.0, "trd": NaN, "batb": NaN, "batl": [[1, 1.6, 12.06], [2, 1.82, 2.66]]}, {"timestamp": 1631514820911, "ltp": 1.4, "tv": 4.0, "trd": NaN, "batb": [[1, 1.2, 219.96], [2, 1.13, 136.27]], "batl": NaN}, {"timestamp": 1631517434492, "ltp": 1.4, "tv": 4.0, "trd": [[1.4, 4.01]], "batb": [[0, 1.4, 12.48], [1, 1.2, 220.22], [2, 1.13, 136.46]], "batl": [[1, 1.6, 12.07], [2, 1.82, 2.66]]}, {"timestamp": 1631517617118, "ltp": 1.4, "tv": 4.0, "trd": NaN, "batb": NaN, "batl": [[1, 1.82, 2.66], [2, 1.88, 44.04]]}, {"timestamp": 1631517618200, "ltp": 1.4, "tv": 4.0, "trd": NaN, "batb": NaN, "batl": [[1, 1.6, 12.07], [2, 1.82, 2.66]]}, {"timestamp": 1631522994634, "ltp": 1.4, "tv": 4.0, "trd": NaN, "batb": [[1, 1.13, 136.46], [2, 1.1, 108.65]], "batl": NaN}, {"timestamp": 1631523420646, "ltp": 1.4, "tv": 4.0, "trd": NaN, "batb": [[1, 1.2, 97.91], [2, 1.13, 136.46]], "batl": NaN}, {"timestamp": 1631523626773, "ltp": 1.4, "tv": 4.0, "trd": [[1.4, 4]], "batb": [[0, 1.4, 12.47], [1, 1.2, 97.84], [2, 1.13, 136.36]], "batl": [[1, 1.6, 12.07], [2, 1.82, 2.66]]}, {"timestamp": 1631523976988, "ltp": 1.4, "tv": 4.0, "trd": NaN, "batb": NaN, "batl": [[0, 1.43, 1.28], [1, 1.44, 25], [2, 1.6, 12.07]]}, {"timestamp": 1631524397977, "ltp": 1.4, "tv": 4.0, "trd": NaN, "batb": [[1, 1.2, 317.93]], "batl": NaN}, {"timestamp": 1631524435159, "ltp": 1.4, "tv": 4.0, "trd": NaN, "batb": [[1, 1.2, 220.09], [2, 1.05, 42.62]], "batl": [[2, 1.82, 2.66]]}, {"timestamp": 1631524435566, "ltp": 1.4, "tv": 4.0, "trd": NaN, "batb": NaN, "batl": [[2, 1.59, 60]]}, {"timestamp": 1631524668193, "ltp": 1.4, "tv": 4.0, "trd": NaN, "batb": NaN, "batl": [[1, 1.44, 28.44]]}, {"timestamp": 1631524720641, "ltp": 1.4, "tv": 4.0, "trd": NaN, "batb": NaN, "batl": [[1, 1.44, 36.98]]}, {"timestamp": 1631526548997, "ltp": 1.4, "tv": 28.94, "trd": [[1.4, 28.95]], "batb": [[0, 1.22, 135.79]], "batl": [[0, 1.4, 187.53], [1, 1.43, 1.28], [2, 1.44, 36.98]]}, {"timestamp": 1631526848978, "ltp": 1.4, "tv": 28.94, "trd": NaN, "batb": [[0, 1.2, 220.09], [1, 1.05, 42.62], [2, 1.01, 113.88]], "batl": NaN}, {"timestamp": 1631526960703, "ltp": 1.4, "tv": 28.94, "trd": NaN, "batb": [[0, 1.32, 40.01], [1, 1.2, 220.09], [2, 1.05, 42.62]], "batl": NaN}, {"timestamp": 1631527339853, "ltp": 1.4, "tv": 28.94, "trd": NaN, "batb": [[1, 1.05, 42.62], [2, 1.01, 113.88]], "batl": NaN}, {"timestamp": 1631527348729, "ltp": 1.4, "tv": 28.94, "trd": NaN, "batb": [[1, 1.14, 308.12], [2, 1.05, 42.62]], "batl": NaN}, {"timestamp": 1631527914608, "ltp": 1.4, "tv": 28.94, "trd": NaN, "batb": NaN, "batl": [[2, 1.44, 28.44]]}, {"timestamp": 1631528569513, "ltp": 1.4, "tv": 28.94, "trd": NaN, "batb": [[1, 1.28, 2.66], [2, 1.14, 308.12]], "batl": NaN}, {"timestamp": 1631529849339, "ltp": 1.4, "tv": 39.6, "trd": [[1.4, 39.6]], "batb": NaN, "batl": [[0, 1.4, 182.2]]}, {"timestamp": 1631529961798, "ltp": 1.4, "tv": 39.6, "trd": NaN, "batb": [[2, 1.27, 555.56]], "batl": NaN}, {"timestamp": 1631530553841, "ltp": 1.4, "tv": 39.6, "trd": NaN, "batb": NaN, "batl": [[0, 1.4, 184.2]]}, {"timestamp": 1631530683805, "ltp": 1.4, "tv": 39.6, "trd": NaN, "batb": [[0, 1.29, 409.32]], "batl": [[0, 1.36, 2.56], [1, 1.4, 184.2], [2, 1.43, 1.28]]}, {"timestamp": 1631530687186, "ltp": 1.4, "tv": 39.6, "trd": NaN, "batb": NaN, "batl": [[0, 1.34, 2.56]]}, {"timestamp": 1631530690929, "ltp": 1.33, "tv": 42.16, "trd": [[1.33, 2.56]], "batb": [[0, 1.32, 40.01], [1, 1.29, 44.14], [2, 1.28, 2.66]], "batl": [[0, 1.4, 184.2], [1, 1.43, 1.28], [2, 1.44, 28.44]]}, {"timestamp": 1631530832271, "ltp": 1.33, "tv": 42.13, "trd": [[1.33, 2.56], [1.4, 39.58]], "batb": [[0, 1.32, 39.93], [1, 1.31, 108.28], [2, 1.29, 44.05]], "batl": [[1, 1.43, 1.28], [2, 1.44, 28.44]]}, {"timestamp": 1631531016058, "ltp": 1.4, "tv": 51.78, "trd": [[1.4, 49.23]], "batb": NaN, "batl": [[0, 1.4, 174.55]]}, {"timestamp": 1631531067545, "ltp": 1.4, "tv": 51.78, "trd": NaN, "batb": [[1, 1.31, 107.28]], "batl": NaN}, {"timestamp": 1631531353718, "ltp": 1.33, "tv": 56.78, "trd": [[1.33, 7.56]], "batb": NaN, "batl": NaN}, {"timestamp": 1631531410189, "ltp": 1.33, "tv": 143.75, "trd": [[1.33, 94.53]], "batb": NaN, "batl": [[0, 1.33, 92.54], [1, 1.4, 2], [2, 1.43, 1.28]]}, {"timestamp": 1631531410498, "ltp": 1.33, "tv": 143.75, "trd": NaN, "batb": [[0, 1.31, 107.28], [1, 1.28, 48.29], [2, 1.27, 555.56]], "batl": NaN}, {"timestamp": 1631531411289, "ltp": 1.33, "tv": 143.75, "trd": NaN, "batb": [[1, 1.28, 2.66]], "batl": NaN}, {"timestamp": 1631531431094, "ltp": 1.33, "tv": 143.75, "trd": NaN, "batb": [[0, 1.28, 2.66], [1, 1.27, 555.56], [2, 1.14, 307.83]], "batl": NaN}, {"timestamp": 1631531431830, "ltp": 1.33, "tv": 143.75, "trd": NaN, "batb": [[0, 1.06, 766.61], [1, 1.01, 113.7], [2, 1.14, 0]], "batl": [[1, 1.5, 60], [2, 1.43, 0]]}, {"timestamp": 1631531438941, "ltp": 1.33, "tv": 143.75, "trd": NaN, "batb": [[1, 1.01, 586.68]], "batl": [[2, 44, 7.23]]}, {"timestamp": 1631531445162, "ltp": 1.33, "tv": 236.29, "trd": [[1.33, 187.07]], "batb": NaN, "batl": [[0, 1.41, 19.33]]}, {"timestamp": 1631531446367, "ltp": 1.33, "tv": 236.29, "trd": NaN, "batb": [[0, 1.36, 89.71], [1, 1.32, 104.35], [2, 1.06, 766.61]], "batl": NaN}, {"timestamp": 1631531455284, "ltp": 1.33, "tv": 236.29, "trd": NaN, "batb": NaN, "batl": [[0, 1.5, 60], [1, 44, 7.23], [2, 44, 0]]}, {"timestamp": 1631531456789, "ltp": 1.37, "tv": 261.29, "trd": [[1.37, 25]], "batb": NaN, "batl": NaN}, {"timestamp": 1631531458786, "ltp": 1.37, "tv": 261.29, "trd": NaN, "batb": [[2, 1.11, 269.5]], "batl": NaN}, {"timestamp": 1631531462065, "ltp": 1.37, "tv": 261.29, "trd": NaN, "batb": [[2, 1.17, 313.89]], "batl": NaN}, {"timestamp": 1631531464965, "ltp": 1.37, "tv": 261.29, "trd": NaN, "batb": [[0, 1.32, 104.35], [1, 1.17, 313.89], [2, 1.11, 269.5]], "batl": NaN}, {"timestamp": 1631531482122, "ltp": 1.32, "tv": 277.17, "trd": [[1.32, 15.88]], "batb": [[0, 1.32, 96.41]], "batl": [[0, 1.35, 13.52], [1, 1.4, 209.73], [2, 1.5, 60]]}, {"timestamp": 1631531483222, "ltp": 1.32, "tv": 277.17, "trd": NaN, "batb": [[1, 1.28, 121], [2, 1.2, 8.33]], "batl": NaN}, {"timestamp": 1631531496218, "ltp": 1.32, "tv": 277.17, "trd": NaN, "batb": NaN, "batl": [[0, 1.35, 159.52]]}, {"timestamp": 1631531502662, "ltp": 1.32, "tv": 277.17, "trd": NaN, "batb": [[0, 1.28, 121], [1, 1.17, 313.89], [2, 1.11, 269.5]], "batl": [[0, 1.35, 146], [1, 1.5, 60], [2, 44, 7.23]]}, {"timestamp": 1631531503549, "ltp": 1.32, "tv": 277.17, "trd": NaN, "batb": NaN, "batl": [[0, 1.5, 60], [1, 44, 7.23], [2, 44, 0]]}, {"timestamp": 1631531514673, "ltp": 1.32, "tv": 277.17, "trd": NaN, "batb": [[0, 1.38, 160.1], [1, 1.28, 121], [2, 1.23, 8.13]], "batl": [[0, 1.44, 145.22], [1, 1.5, 60], [2, 44, 7.23]]}, {"timestamp": 1631531515773, "ltp": 1.39, "tv": 284.86, "trd": [[1.39, 7.69]], "batb": [[0, 1.38, 245.71], [1, 1.33, 101.92]], "batl": NaN}, {"timestamp": 1631531522664, "ltp": 1.39, "tv": 284.86, "trd": NaN, "batb": NaN, "batl": [[0, 1.41, 72], [1, 1.44, 145.22], [2, 1.5, 60]]}, {"timestamp": 1631531528976, "ltp": 1.39, "tv": 284.86, "trd": NaN, "batb": NaN, "batl": [[0, 1.41, 85.95]]}, {"timestamp": 1631531535267, "ltp": 1.39, "tv": 284.86, "trd": NaN, "batb": [[0, 1.33, 101.92], [1, 1.17, 313.89], [2, 1.11, 269.5]], "batl": [[0, 1.41, 72], [1, 1.5, 60], [2, 44, 7.23]]}, {"timestamp": 1631531535478, "ltp": 1.39, "tv": 284.86, "trd": NaN, "batb": NaN, "batl": [[0, 1.5, 60], [1, 44, 7.23], [2, 44, 0]]}, {"timestamp": 1631531541276, "ltp": 1.33, "tv": 300.6, "trd": [[1.33, 202.81]], "batb": [[0, 1.33, 94.05]], "batl": [[0, 1.36, 15.32], [1, 1.4, 142.86], [2, 1.5, 60]]}, {"timestamp": 1631531542033, "ltp": 1.33, "tv": 300.6, "trd": NaN, "batb": [[1, 1.29, 116.28], [2, 1.28, 181.15]], "batl": NaN}, {"timestamp": 1631531542312, "ltp": 1.33, "tv": 300.6, "trd": NaN, "batb": [[1, 1.29, 23.26], [2, 1.28, 134.63]], "batl": NaN}, {"timestamp": 1631531549211, "ltp": 1.33, "tv": 300.6, "trd": NaN, "batb": NaN, "batl": [[0, 1.36, 83.32]]}, {"timestamp": 1631531559185, "ltp": 1.33, "tv": 300.6, "trd": NaN, "batb": [[1, 1.28, 123.01], [2, 1.17, 313.89]], "batl": [[0, 1.36, 68], [1, 1.5, 60], [2, 44, 7.23]]}, {"timestamp": 1631531559499, "ltp": 1.33, "tv": 300.6, "trd": NaN, "batb": [[0, 1.28, 123.01], [1, 1.17, 313.89], [2, 1.11, 269.5]], "batl": [[0, 1.5, 60], [1, 44, 7.23], [2, 44, 0]]}, {"timestamp": 1631531590248, "ltp": 1.28, "tv": 331.72, "trd": [[1.28, 16.12], [1.5, 15]], "batb": [[0, 1.3, 13.12], [1, 1.29, 179.72], [2, 1.28, 114.95]], "batl": [[0, 1.33, 112.78], [1, 1.34, 258.12], [2, 1.35, 56.4]]}, {"timestamp": 1631531591281, "ltp": 1.28, "tv": 331.72, "trd": NaN, "batb": NaN, "batl": [[0, 1.33, 22.56], [1, 1.34, 213], [2, 1.35, 11.28]]}, {"timestamp": 1631531598364, "ltp": 1.28, "tv": 331.72, "trd": NaN, "batb": NaN, "batl": [[0, 1.32, 86], [1, 1.33, 22.56], [2, 1.34, 213]]}, {"timestamp": 1631531609885, "ltp": 1.28, "tv": 331.72, "trd": NaN, "batb": [[0, 1.24, 143.68], [1, 1.17, 313.89], [2, 1.11, 269.5]], "batl": [[1, 1.5, 52.5], [2, 44, 7.23]]}, {"timestamp": 1631531610508, "ltp": 1.28, "tv": 331.72, "trd": NaN, "batb": NaN, "batl": [[0, 1.5, 52.5], [1, 44, 7.23], [2, 44, 0]]}, {"timestamp": 1631531617110, "ltp": 1.24, "tv": 348.12, "trd": [[1.24, 16.4]], "batb": [[0, 1.27, 13.74], [1, 1.24, 135.48], [2, 1.17, 313.89]], "batl": [[0, 1.29, 23.26], [1, 1.3, 11.62], [2, 1.31, 11.62]]}, {"timestamp": 1631531617685, "ltp": 1.24, "tv": 348.12, "trd": NaN, "batb": [[2, 1.21, 168.28]], "batl": NaN}, {"timestamp": 1631531625812, "ltp": 1.24, "tv": 348.12, "trd": NaN, "batb": NaN, "batl": [[0, 1.29, 94.26]]}, {"timestamp": 1631531675966, "ltp": 1.24, "tv": 348.12, "trd": NaN, "batb": [[0, 1.21, 168.28], [1, 1.17, 313.89], [2, 1.11, 269.5]], "batl": [[0, 1.29, 71], [1, 1.5, 52.5], [2, 8.8, 7.23]]}, {"timestamp": 1631531676481, "ltp": 1.24, "tv": 348.12, "trd": NaN, "batb": NaN, "batl": [[0, 1.5, 52.5], [1, 8.8, 7.23], [2, 44, 7.23]]}, {"timestamp": 1631531728156, "ltp": 1.23, "tv": 364.78, "trd": [[1.23, 16.66]], "batb": [[0, 1.23, 11.74], [1, 1.21, 168.28], [2, 1.06, 1260.69]], "batl": NaN}, {"timestamp": 1631531729040, "ltp": 1.23, "tv": 364.78, "trd": NaN, "batb": [[2, 1.18, 557.31]], "batl": [[1, 1.62, 622.88], [2, 8.8, 7.23]]}, {"timestamp": 1631531732123, "ltp": 1.23, "tv": 364.78, "trd": NaN, "batb": NaN, "batl": [[0, 1.25, 82], [1, 1.5, 52.5], [2, 1.62, 622.88]]}, {"timestamp": 1631531737860, "ltp": 1.23, "tv": 364.78, "trd": NaN, "batb": [[0, 1.21, 168.28], [1, 1.18, 557.31], [2, 1.17, 203.93]], "batl": NaN}, {"timestamp": 1631531738849, "ltp": 1.23, "tv": 364.78, "trd": NaN, "batb": [[0, 1.18, 557.31], [1, 1.17, 203.93], [2, 1.06, 1260.69]], "batl": [[1, 1.36, 36.8], [2, 1.5, 52.5]]}, {"timestamp": 1631531739573, "ltp": 1.23, "tv": 364.78, "trd": NaN, "batb": NaN, "batl": [[0, 1.36, 36.8], [1, 1.5, 52.5], [2, 1.62, 622.88]]}, {"timestamp": 1631531742553, "ltp": 1.23, "tv": 364.78, "trd": NaN, "batb": [[0, 1.17, 203.93], [1, 1.06, 1260.69], [2, 1.05, 474.33]], "batl": NaN}, {"timestamp": 1631531744164, "ltp": 1.23, "tv": 364.78, "trd": NaN, "batb": [[0, 1.26, 15.83], [1, 1.17, 203.93], [2, 1.16, 8.62]], "batl": [[0, 1.28, 33.83], [1, 1.3, 220.24], [2, 1.36, 36.8]]}, {"timestamp": 1631531745050, "ltp": 1.27, "tv": 372.98, "trd": [[1.27, 8.2]], "batb": [[1, 1.24, 145.35], [2, 1.2, 174.47]], "batl": [[1, 1.29, 23.26], [2, 1.3, 231.86]]}, {"timestamp": 1631531746044, "ltp": 1.27, "tv": 372.98, "trd": NaN, "batb": [[2, 1.2, 712.66]], "batl": NaN}, {"timestamp": 1631531752077, "ltp": 1.27, "tv": 372.98, "trd": NaN, "batb": NaN, "batl": [[0, 1.28, 134.83]]}, {"timestamp": 1631531754272, "ltp": 1.27, "tv": 372.98, "trd": NaN, "batb": [[0, 1.2, 712.66], [1, 1.06, 1260.69], [2, 1.05, 474.33]], "batl": [[0, 1.28, 101], [1, 1.36, 36.8], [2, 1.5, 52.5]]}, {"timestamp": 1631531754578, "ltp": 1.27, "tv": 372.98, "trd": NaN, "batb": NaN, "batl": [[0, 1.36, 36.8], [1, 1.5, 52.5], [2, 1.62, 622.88]]}, {"timestamp": 1631531762084, "ltp": 1.2, "tv": 389.78, "trd": [[1.2, 16.8]], "batb": [[0, 1.2, 704.26]], "batl": [[0, 1.23, 17.48], [1, 1.26, 315.34], [2, 1.36, 36.8]]}, {"timestamp": 1631531763270, "ltp": 1.2, "tv": 389.78, "trd": NaN, "batb": [[1, 1.17, 214.47], [2, 1.13, 8.85]], "batl": NaN}, {"timestamp": 1631531770268, "ltp": 1.2, "tv": 389.78, "trd": NaN, "batb": NaN, "batl": [[0, 1.23, 609.48]]}, {"timestamp": 1631531771197, "ltp": 1.2, "tv": 389.78, "trd": NaN, "batb": [[2, 1.06, 1260.69]], "batl": [[0, 1.23, 592], [1, 1.36, 36.8], [2, 1.5, 52.5]]}, {"timestamp": 1631531771512, "ltp": 1.2, "tv": 389.78, "trd": NaN, "batb": [[0, 1.2, 538.19]], "batl": [[0, 1.36, 36.8], [1, 1.5, 52.5], [2, 1.62, 622.88]]}, {"timestamp": 1631531778590, "ltp": 1.2, "tv": 389.78, "trd": NaN, "batb": [[0, 1.26, 158.74], [1, 1.24, 24.2], [2, 1.23, 12.1]], "batl": [[0, 1.27, 25.98], [1, 1.29, 178.75], [2, 1.36, 36.8]]}, {"timestamp": 1631531779685, "ltp": 1.26, "tv": 406.3, "trd": [[1.26, 16.52]], "batb": [[0, 1.26, 150.48], [1, 1.24, 171.65]], "batl": NaN}, {"timestamp": 1631531787220, "ltp": 1.26, "tv": 406.3, "trd": NaN, "batb": NaN, "batl": [[0, 1.36, 36.8], [1, 1.5, 52.5], [2, 1.62, 622.88]]}, {"timestamp": 1631531787733, "ltp": 1.26, "tv": 406.3, "trd": NaN, "batb": [[0, 1.2, 538.19], [1, 1.19, 183.85], [2, 1.06, 1260.69]], "batl": NaN}, {"timestamp": 1631531794245, "ltp": 1.26, "tv": 406.3, "trd": NaN, "batb": [[1, 1.19, 185.85]], "batl": NaN}, {"timestamp": 1631531800636, "ltp": 1.26, "tv": 406.3, "trd": NaN, "batb": [[0, 1.19, 186.85], [1, 1.06, 1260.69], [2, 1.05, 474.33]], "batl": NaN}, {"timestamp": 1631531802108, "ltp": 1.26, "tv": 406.3, "trd": NaN, "batb": [[0, 1.29, 198.5], [1, 1.28, 11.62], [2, 1.27, 11.62]], "batl": [[0, 1.31, 16.47], [1, 1.34, 200.87], [2, 1.36, 36.8]]}, {"timestamp": 1631531803197, "ltp": 1.29, "tv": 422.42, "trd": [[1.29, 16.12]], "batb": [[0, 1.29, 15.2]], "batl": [[0, 1.33, 22.56], [1, 1.34, 11.28], [2, 1.35, 11.28]]}, {"timestamp": 1631531813539, "ltp": 1.29, "tv": 422.42, "trd": NaN, "batb": [[0, 1.24, 147.11], [1, 1.23, 523.6], [2, 1.19, 1]], "batl": [[0, 1.36, 36.8], [1, 1.5, 52.5], [2, 1.62, 622.88]]}, {"timestamp": 1631531816228, "ltp": 1.29, "tv": 422.42, "trd": NaN, "batb": NaN, "batl": [[0, 1.33, 51], [1, 1.36, 36.8], [2, 1.5, 52.5]]}, {"timestamp": 1631531816332, "ltp": 1.29, "tv": 422.42, "trd": NaN, "batb": NaN, "batl": [[0, 1.36, 36.8], [1, 1.5, 52.5], [2, 1.62, 622.88]]}, {"timestamp": 1631531818711, "ltp": 1.29, "tv": 422.42, "trd": NaN, "batb": NaN, "batl": [[0, 1.5, 52.5], [1, 1.62, 622.88], [2, 8.8, 7.23]]}, {"timestamp": 1631531821952, "ltp": 1.29, "tv": 422.42, "trd": NaN, "batb": NaN, "batl": [[0, 1.43, 36.8], [1, 1.5, 52.5], [2, 1.62, 622.88]]}, {"timestamp": 1631531834879, "ltp": 1.29, "tv": 422.42, "trd": NaN, "batb": [[1, 1.19, 1], [2, 1.06, 1260.69]], "batl": NaN}, {"timestamp": 1631531836269, "ltp": 1.24, "tv": 438.94, "trd": [[1.24, 32.92]], "batb": [[0, 1.24, 138.85]], "batl": [[0, 1.27, 3090.82], [1, 1.28, 117.2], [2, 1.29, 58.6]]}, {"timestamp": 1631531837276, "ltp": 1.24, "tv": 438.94, "trd": NaN, "batb": [[2, 1.15, 8.7]], "batl": [[0, 1.27, 94.49], [1, 1.28, 70.32], [2, 1.29, 35.16]]}, {"timestamp": 1631531837647, "ltp": 1.24, "tv": 438.94, "trd": NaN, "batb": [[1, 1.19, 185.77]], "batl": [[1, 1.28, 23.44], [2, 1.29, 11.72]]}, {"timestamp": 1631531839090, "ltp": 1.24, "tv": 438.94, "trd": NaN, "batb": [[1, 1.2, 538.19], [2, 1.19, 185.77]], "batl": NaN}, {"timestamp": 1631531841267, "ltp": 1.24, "tv": 438.94, "trd": NaN, "batb": NaN, "batl": [[1, 1.28, 199.81]]}, {"timestamp": 1631531841574, "ltp": 1.24, "tv": 438.94, "trd": NaN, "batb": NaN, "batl": [[0, 1.27, 149.49], [1, 1.28, 23.44]]}, {"timestamp": 1631531847065, "ltp": 1.24, "tv": 438.94, "trd": NaN, "batb": [[0, 1.2, 538.19], [1, 1.19, 185.77], [2, 1.06, 1260.69]], "batl": [[0, 1.27, 55], [1, 1.43, 36.8], [2, 1.5, 52.5]]}, {"timestamp": 1631531847476, "ltp": 1.24, "tv": 438.94, "trd": NaN, "batb": NaN, "batl": [[0, 1.43, 36.8], [1, 1.5, 52.5], [2, 1.62, 622.88]]}, {"timestamp": 1631531855175, "ltp": 1.25, "tv": 442.99, "trd": [[1.25, 4.05]], "batb": NaN, "batl": NaN}, {"timestamp": 1631531858288, "ltp": 1.2, "tv": 487.94, "trd": [[1.2, 61.75]], "batb": [[0, 1.2, 493.24]], "batl": NaN}, {"timestamp": 1631531871192, "ltp": 1.2, "tv": 487.94, "trd": NaN, "batb": [[0, 1.28, 117.2], [1, 1.27, 58.6], [2, 1.26, 58.6]], "batl": NaN}, {"timestamp": 1631531872286, "ltp": 1.29, "tv": 496.0, "trd": [[1.29, 24.18]], "batb": [[0, 1.28, 238.12]], "batl": [[0, 1.33, 112.78], [1, 1.34, 56.4], [2, 1.35, 56.4]]}, {"timestamp": 1631531872394, "ltp": 1.29, "tv": 496.0, "trd": NaN, "batb": [[0, 1.28, 191.24], [1, 1.27, 35.16], [2, 1.26, 35.16]], "batl": [[0, 1.33, 22.56], [1, 1.34, 11.28], [2, 1.35, 11.28]]}, {"timestamp": 1631531876111, "ltp": 1.29, "tv": 496.0, "trd": NaN, "batb": NaN, "batl": [[0, 1.32, 147.67], [1, 1.33, 22.56], [2, 1.34, 11.28]]}, {"timestamp": 1631531876316, "ltp": 1.29, "tv": 496.0, "trd": NaN, "batb": NaN, "batl": [[0, 1.33, 22.56], [1, 1.34, 11.28], [2, 1.35, 11.28]]}, {"timestamp": 1631531879311, "ltp": 1.29, "tv": 496.0, "trd": NaN, "batb": NaN, "batl": [[0, 1.31, 141], [1, 1.33, 22.56], [2, 1.34, 11.28]]}, {"timestamp": 1631531883925, "ltp": 1.29, "tv": 496.0, "trd": NaN, "batb": [[0, 1.23, 627.02], [1, 1.19, 1], [2, 1.06, 1260.69]], "batl": [[0, 1.29, 4.05], [1, 1.31, 141], [2, 1.43, 36.8]]}, {"timestamp": 1631531885221, "ltp": 1.29, "tv": 500.04, "trd": [[1.29, 28.23]], "batb": NaN, "batl": [[0, 1.31, 18.45], [1, 1.43, 36.8], [2, 1.5, 52.5]]}, {"timestamp": 1631531885436, "ltp": 1.29, "tv": 500.04, "trd": NaN, "batb": NaN, "batl": [[0, 1.43, 36.8], [1, 1.5, 52.5], [2, 1.62, 622.88]]}, {"timestamp": 1631531888028, "ltp": 1.29, "tv": 500.04, "trd": NaN, "batb": NaN, "batl": [[0, 1.32, 458.36], [1, 1.43, 36.8], [2, 1.5, 52.5]]}, {"timestamp": 1631531888334, "ltp": 1.29, "tv": 500.04, "trd": NaN, "batb": NaN, "batl": [[0, 1.43, 36.8], [1, 1.5, 52.5], [2, 1.62, 622.88]]}, {"timestamp": 1631531902862, "ltp": 1.29, "tv": 500.04, "trd": NaN, "batb": [[0, 1.23, 148.11]], "batl": NaN}, {"timestamp": 1631531904267, "ltp": 1.23, "tv": 516.56, "trd": [[1.23, 33.18]], "batb": [[0, 1.24, 206.37], [1, 1.23, 139.85], [2, 1.19, 1]], "batl": [[0, 1.26, 175.41], [1, 1.27, 3067.6], [2, 1.28, 59.06]]}, {"timestamp": 1631531905259, "ltp": 1.23, "tv": 516.56, "trd": NaN, "batb": [[1, 1.23, 261.81], [2, 1.22, 60.98]], "batl": [[0, 1.26, 111.91], [1, 1.27, 70.87], [2, 1.28, 35.44]]}, {"timestamp": 1631531905670, "ltp": 1.23, "tv": 516.56, "trd": NaN, "batb": [[1, 1.23, 164.25], [2, 1.22, 12.2]], "batl": NaN}, {"timestamp": 1631531909248, "ltp": 1.23, "tv": 516.56, "trd": NaN, "batb": NaN, "batl": [[2, 1.28, 227.05]]}, {"timestamp": 1631531909462, "ltp": 1.23, "tv": 516.56, "trd": NaN, "batb": NaN, "batl": [[2, 1.28, 35.44]]}, {"timestamp": 1631531920167, "ltp": 1.23, "tv": 516.56, "trd": NaN, "batb": [[0, 1.23, 139.85], [1, 1.2, 493.12], [2, 1.19, 188.11]], "batl": [[0, 1.43, 36.8], [1, 1.5, 52.5], [2, 1.62, 622.88]]}, {"timestamp": 1631531920374, "ltp": 1.23, "tv": 516.56, "trd": NaN, "batb": [[0, 1.2, 493.12], [1, 1.19, 188.11], [2, 1.06, 1260.69]], "batl": NaN}, {"timestamp": 1631531943604, "ltp": 1.23, "tv": 516.56, "trd": NaN, "batb": [[0, 1.19, 188.11], [1, 1.06, 1260.69], [2, 1.05, 474.33]], "batl": NaN}, {"timestamp": 1631531944692, "ltp": 1.23, "tv": 516.56, "trd": NaN, "batb": [[0, 1.28, 195.44], [1, 1.19, 188.11], [2, 1.18, 8.47]], "batl": [[0, 1.33, 204.21], [1, 1.43, 36.8], [2, 1.5, 52.5]]}, {"timestamp": 1631531945906, "ltp": 1.28, "tv": 532.68, "trd": [[1.28, 32.24]], "batb": [[0, 1.28, 309.05], [1, 1.23, 149.96], [2, 1.19, 1]], "batl": [[0, 1.32, 22.72], [1, 1.33, 215.57], [2, 1.34, 11.36]]}, {"timestamp": 1631531947197, "ltp": 1.28, "tv": 532.68, "trd": NaN, "batb": [[2, 1.22, 485.14]], "batl": NaN}, {"timestamp": 1631531952609, "ltp": 1.28, "tv": 532.68, "trd": NaN, "batb": NaN, "batl": [[0, 1.31, 61], [1, 1.32, 22.72], [2, 1.33, 215.57]]}, {"timestamp": 1631531972241, "ltp": 1.28, "tv": 532.68, "trd": NaN, "batb": [[0, 1.28, 121.67]], "batl": [[2, 1.33, 11.36]]}, {"timestamp": 1631531972763, "ltp": 1.28, "tv": 532.68, "trd": NaN, "batb": [[0, 1.23, 149.96], [1, 1.22, 485.14], [2, 1.19, 1]], "batl": [[1, 1.43, 36.8], [2, 1.5, 52.5]]}, {"timestamp": 1631531973649, "ltp": 1.28, "tv": 532.68, "trd": NaN, "batb": NaN, "batl": [[0, 1.43, 36.8], [1, 1.5, 52.5], [2, 1.62, 622.88]]}, {"timestamp": 1631531976159, "ltp": 1.28, "tv": 532.68, "trd": NaN, "batb": [[1, 1.19, 1], [2, 1.06, 1260.69]], "batl": NaN}, {"timestamp": 1631531978036, "ltp": 1.28, "tv": 532.68, "trd": NaN, "batb": [[0, 1.32, 151.52], [1, 1.23, 149.96], [2, 1.2, 8.33]], "batl": [[0, 1.34, 13.61], [1, 1.37, 192.38], [2, 1.43, 36.8]]}, {"timestamp": 1631531979174, "ltp": 1.33, "tv": 548.56, "trd": [[1.33, 218.69]], "batb": [[0, 1.33, 93.73], [1, 1.32, 151.52], [2, 1.29, 117.99]], "batl": NaN}, {"timestamp": 1631532025217, "ltp": 1.33, "tv": 548.56, "trd": NaN, "batb": [[1, 1.32, 75.76]], "batl": [[0, 1.43, 36.8], [1, 1.5, 52.5], [2, 1.62, 622.88]]}, {"timestamp": 1631532025740, "ltp": 1.33, "tv": 548.56, "trd": NaN, "batb": [[0, 1.29, 117.99], [1, 1.25, 468.07], [2, 1.19, 1]], "batl": NaN}, {"timestamp": 1631532049243, "ltp": 1.33, "tv": 548.56, "trd": NaN, "batb": [[1, 1.19, 1], [2, 1.1, 297.11]], "batl": [[2, 8.8, 7.23]]}, {"timestamp": 1631532051230, "ltp": 1.33, "tv": 548.56, "trd": NaN, "batb": [[0, 1.38, 14.85], [1, 1.29, 117.99], [2, 1.23, 8.13]], "batl": [[0, 1.4, 8.31], [1, 1.43, 192.04], [2, 1.5, 52.5]]}, {"timestamp": 1631532052220, "ltp": 1.38, "tv": 563.94, "trd": [[1.38, 15.38]], "batb": [[0, 1.38, 92.18], [1, 1.33, 99.33]], "batl": NaN}, {"timestamp": 1631532054051, "ltp": 1.38, "tv": 563.94, "trd": NaN, "batb": [[2, 1.31, 442.37]], "batl": [[1, 1.43, 155.24]]}, {"timestamp": 1631532062156, "ltp": 1.38, "tv": 563.94, "trd": NaN, "batb": [[0, 1.38, 85.02]], "batl": [[0, 1.43, 155.24], [1, 1.5, 52.5], [2, 1.89, 469.65]]}, {"timestamp": 1631532065276, "ltp": 1.38, "tv": 563.94, "trd": NaN, "batb": NaN, "batl": [[0, 1.43, 423.07]]}, {"timestamp": 1631532065381, "ltp": 1.38, "tv": 563.94, "trd": NaN, "batb": NaN, "batl": [[0, 1.43, 155.24]]}, {"timestamp": 1631532070657, "ltp": 1.38, "tv": 563.94, "trd": NaN, "batb": [[0, 1.33, 99.33], [1, 1.31, 442.37], [2, 1.19, 1]], "batl": [[0, 1.5, 52.5], [1, 1.89, 469.65], [2, 8.8, 7.23]]}, {"timestamp": 1631532083668, "ltp": 1.38, "tv": 563.94, "trd": NaN, "batb": NaN, "batl": [[1, 1.54, 36.8], [2, 1.89, 469.65]]}, {"timestamp": 1631532127764, "ltp": 1.38, "tv": 563.94, "trd": NaN, "batb": [[1, 1.19, 1], [2, 1.17, 314.59]], "batl": [[1, 1.89, 469.65], [2, 8.8, 7.23]]}, {"timestamp": 1631532129068, "ltp": 1.38, "tv": 563.94, "trd": NaN, "batb": [[0, 1.45, 12.86], [1, 1.33, 99.33], [2, 1.19, 1]], "batl": [[0, 1.47, 12.64], [1, 1.5, 52.5], [2, 1.52, 177.39]]}, {"timestamp": 1631532130160, "ltp": 1.45, "tv": 578.64, "trd": [[1.45, 14.7]], "batb": [[0, 1.45, 73.46], [1, 1.4, 79.16]], "batl": NaN}, {"timestamp": 1631532132240, "ltp": 1.45, "tv": 578.64, "trd": NaN, "batb": [[2, 1.34, 431.32]], "batl": NaN}, {"timestamp": 1631532139946, "ltp": 1.45, "tv": 578.64, "trd": NaN, "batb": [[0, 1.45, 67.95]], "batl": [[0, 1.5, 52.5], [1, 1.52, 177.39], [2, 1.89, 469.65]]}, {"timestamp": 1631532154267, "ltp": 1.45, "tv": 578.64, "trd": NaN, "batb": [[0, 1.4, 79.16], [1, 1.34, 431.32], [2, 1.19, 1]], "batl": [[1, 1.89, 469.65], [2, 8.8, 7.23]]}, {"timestamp": 1631532158970, "ltp": 1.45, "tv": 578.64, "trd": NaN, "batb": [[1, 1.19, 1], [2, 1.17, 314.59]], "batl": NaN}, {"timestamp": 1631532161100, "ltp": 1.45, "tv": 578.64, "trd": NaN, "batb": NaN, "batl": [[1, 1.61, 1762.11], [2, 1.89, 469.65]]}, {"timestamp": 1631532162811, "ltp": 1.45, "tv": 578.64, "trd": NaN, "batb": [[1, 1.38, 415.85], [2, 1.19, 1]], "batl": NaN}, {"timestamp": 1631532167020, "ltp": 1.45, "tv": 578.64, "trd": NaN, "batb": NaN, "batl": [[1, 1.89, 469.65], [2, 8.8, 7.23]]}, {"timestamp": 1631532167695, "ltp": 1.45, "tv": 578.64, "trd": NaN, "batb": [[1, 1.19, 1], [2, 1.17, 314.59]], "batl": [[1, 1.63, 18.4], [2, 1.89, 469.65]]}, {"timestamp": 1631532169196, "ltp": 1.32, "tv": 744.55, "trd": [[1.32, 23.46], [1.4, 207.55]], "batb": [[0, 1.19, 1], [1, 1.17, 314.59], [2, 1.1, 297.11]], "batl": [[0, 1.4, 63.7], [1, 1.41, 10.93], [2, 1.42, 783.16]]}, {"timestamp": 1631532170239, "ltp": 1.32, "tv": 744.55, "trd": NaN, "batb": [[0, 1.34, 96.32], [1, 1.19, 1], [2, 1.17, 314.59]], "batl": [[0, 1.4, 14.29], [2, 1.47, 261.31]]}, {"timestamp": 1631532170914, "ltp": 1.32, "tv": 744.55, "trd": NaN, "batb": [[1, 1.31, 442.37], [2, 1.19, 1]], "batl": NaN}, {"timestamp": 1631532174233, "ltp": 1.4, "tv": 772.67, "trd": [[1.4, 235.67]], "batb": NaN, "batl": [[0, 1.41, 11.16], [1, 1.43, 2.31]]}, {"timestamp": 1631532174337, "ltp": 1.4, "tv": 772.67, "trd": NaN, "batb": NaN, "batl": [[1, 1.47, 261.31], [2, 1.5, 52.5]]}, {"timestamp": 1631532184828, "ltp": 1.4, "tv": 772.83, "trd": [[1.4, 235.83]], "batb": NaN, "batl": [[0, 1.41, 11.08]]}, {"timestamp": 1631532188147, "ltp": 1.41, "tv": 794.61, "trd": [[1.4, 236.13], [1.41, 21.48]], "batb": NaN, "batl": [[0, 1.47, 261.5], [1, 1.5, 52.5], [2, 1.63, 18.4]]}, {"timestamp": 1631532189131, "ltp": 1.41, "tv": 794.61, "trd": NaN, "batb": NaN, "batl": [[0, 1.5, 52.5], [1, 1.63, 18.4], [2, 1.89, 469.65]]}, {"timestamp": 1631532191256, "ltp": 1.41, "tv": 794.61, "trd": NaN, "batb": NaN, "batl": [[0, 1.46, 1336.84], [1, 1.5, 52.5], [2, 1.63, 18.4]]}, {"timestamp": 1631532191570, "ltp": 1.41, "tv": 794.61, "trd": NaN, "batb": NaN, "batl": [[0, 1.5, 52.5], [1, 1.63, 18.4], [2, 1.89, 469.65]]}, {"timestamp": 1631532192860, "ltp": 1.41, "tv": 794.61, "trd": NaN, "batb": [[0, 1.33, 98.99]], "batl": NaN}, {"timestamp": 1631532200950, "ltp": 1.33, "tv": 810.23, "trd": [[1.33, 234.31]], "batb": [[0, 1.34, 187.61], [1, 1.33, 91.18], [2, 1.31, 442.37]], "batl": NaN}, {"timestamp": 1631532202098, "ltp": 1.33, "tv": 810.23, "trd": NaN, "batb": [[1, 1.33, 113.74], [2, 1.32, 11.28]], "batl": NaN}, {"timestamp": 1631532203765, "ltp": 1.33, "tv": 810.23, "trd": NaN, "batb": [[0, 1.35, 11.79], [1, 1.34, 187.61], [2, 1.33, 113.74]], "batl": NaN}, {"timestamp": 1631532210268, "ltp": 1.33, "tv": 810.23, "trd": NaN, "batb": NaN, "batl": [[0, 1.46, 908.73], [1, 1.5, 52.5], [2, 1.63, 18.4]]}, {"timestamp": 1631532221508, "ltp": 1.33, "tv": 810.23, "trd": NaN, "batb": [[0, 1.31, 442.37], [1, 1.28, 121.67], [2, 1.19, 1]], "batl": [[0, 1.5, 52.5], [1, 1.63, 18.4], [2, 1.89, 469.65]]}, {"timestamp": 1631532235377, "ltp": 1.33, "tv": 810.23, "trd": NaN, "batb": [[0, 1.28, 121.67], [1, 1.19, 1], [2, 1.17, 314.59]], "batl": NaN}, {"timestamp": 1631532236681, "ltp": 1.33, "tv": 810.23, "trd": NaN, "batb": [[0, 1.44, 10.51], [1, 1.28, 121.67], [2, 1.19, 1]], "batl": [[0, 1.46, 15.52], [1, 1.5, 143.75], [2, 1.63, 18.4]]}, {"timestamp": 1631532237822, "ltp": 1.44, "tv": 825.05, "trd": [[1.44, 14.82]], "batb": [[0, 1.44, 3.1], [1, 1.42, 75.48], [2, 1.34, 96.99]], "batl": NaN}, {"timestamp": 1631532238920, "ltp": 1.44, "tv": 825.05, "trd": NaN, "batb": [[2, 1.34, 528.31]], "batl": NaN}, {"timestamp": 1631532247804, "ltp": 1.44, "tv": 825.05, "trd": NaN, "batb": [[0, 1.42, 75.48], [1, 1.34, 528.31], [2, 1.19, 1]], "batl": [[0, 1.5, 143.75], [1, 1.63, 18.4], [2, 1.89, 469.65]]}, {"timestamp": 1631532251032, "ltp": 1.44, "tv": 825.05, "trd": NaN, "batb": [[0, 1.43, 16.96], [1, 1.42, 75.48], [2, 1.34, 528.31]], "batl": NaN}, {"timestamp": 1631532257123, "ltp": 1.44, "tv": 825.05, "trd": NaN, "batb": NaN, "batl": [[0, 1.5, 207.63]]}, {"timestamp": 1631532261246, "ltp": 1.44, "tv": 825.05, "trd": NaN, "batb": [[0, 1.42, 75.48], [1, 1.34, 528.31], [2, 1.19, 1]], "batl": [[0, 1.5, 116.38], [1, 1.89, 469.65], [2, 8.8, 7.23]]}, {"timestamp": 1631532261713, "ltp": 1.44, "tv": 825.05, "trd": NaN, "batb": [[0, 1.34, 528.31], [1, 1.19, 1], [2, 1.17, 314.59]], "batl": [[0, 1.5, 52.5]]}, {"timestamp": 1631532274851, "ltp": 1.44, "tv": 825.05, "trd": NaN, "batb": [[0, 1.34, 96.99]], "batl": NaN}, {"timestamp": 1631532275848, "ltp": 1.34, "tv": 840.55, "trd": [[1.34, 15.5]], "batb": [[0, 1.34, 89.24]], "batl": [[0, 1.37, 145.98], [1, 1.38, 26.81], [2, 1.39, 21.58]]}, {"timestamp": 1631532276936, "ltp": 1.34, "tv": 840.55, "trd": NaN, "batb": [[0, 1.34, 111.62], [1, 1.33, 11.2], [2, 1.32, 11.2]], "batl": NaN}, {"timestamp": 1631532299256, "ltp": 1.34, "tv": 840.55, "trd": NaN, "batb": [[0, 1.29, 118.74], [1, 1.28, 450.13], [2, 1.19, 1]], "batl": [[0, 1.5, 52.5], [1, 1.8, 18.4], [2, 1.89, 469.65]]}, {"timestamp": 1631532302266, "ltp": 1.34, "tv": 840.55, "trd": NaN, "batb": [[1, 1.28, 569.21]], "batl": NaN}, {"timestamp": 1631532303199, "ltp": 1.34, "tv": 840.55, "trd": NaN, "batb": [[0, 1.28, 569.21], [1, 1.19, 1], [2, 1.17, 314.59]], "batl": NaN}, {"timestamp": 1631532319581, "ltp": 1.34, "tv": 840.55, "trd": NaN, "batb": [[0, 1.28, 119.08]], "batl": NaN}, {"timestamp": 1631532320921, "ltp": 1.34, "tv": 840.55, "trd": NaN, "batb": [[0, 1.44, 16.15], [1, 1.43, 177.82], [2, 1.28, 119.08]], "batl": [[0, 1.46, 10.16], [1, 1.5, 52.5], [2, 1.8, 18.4]]}, {"timestamp": 1631532321918, "ltp": 1.44, "tv": 855.37, "trd": [[1.44, 29.64]], "batb": [[0, 1.44, 8.74], [2, 1.42, 74.39]], "batl": [[1, 1.48, 20.28], [2, 1.49, 10.14]]}, {"timestamp": 1631532332010, "ltp": 1.44, "tv": 855.37, "trd": NaN, "batb": [[0, 1.43, 177.82], [1, 1.42, 74.39], [2, 1.35, 94.64]], "batl": [[0, 1.48, 20.28], [1, 1.49, 10.14], [2, 1.5, 62.64]]}, {"timestamp": 1631532346148, "ltp": 1.44, "tv": 855.37, "trd": NaN, "batb": [[0, 1.35, 94.64], [1, 1.34, 431.32], [2, 1.31, 3.23]], "batl": [[0, 1.5, 52.5], [1, 1.8, 18.4], [2, 1.89, 469.65]]}, {"timestamp": 1631532348947, "ltp": 1.44, "tv": 855.37, "trd": NaN, "batb": [[1, 1.31, 3.23], [2, 1.19, 1]], "batl": NaN}, {"timestamp": 1631532353322, "ltp": 1.44, "tv": 855.37, "trd": NaN, "batb": [[0, 1.38, 415.85], [1, 1.35, 94.64], [2, 1.31, 3.23]], "batl": NaN}, {"timestamp": 1631532362129, "ltp": 1.44, "tv": 855.37, "trd": NaN, "batb": [[0, 1.35, 94.64], [1, 1.31, 3.23], [2, 1.19, 1]], "batl": [[2, 8.8, 7.23]]}, {"timestamp": 1631532364266, "ltp": 1.5, "tv": 907.87, "trd": [[1.5, 67.5]], "batb": NaN, "batl": [[0, 1.62, 23.44], [1, 1.68, 155.86], [2, 1.8, 18.4]]}, {"timestamp": 1631532365250, "ltp": 1.58, "tv": 914.67, "trd": [[1.58, 6.8]], "batb": [[0, 1.55, 53.05], [1, 1.47, 64.69], [2, 1.35, 94.64]], "batl": [[1, 1.63, 92.02], [2, 1.64, 46]]}, {"timestamp": 1631532365667, "ltp": 1.58, "tv": 914.67, "trd": NaN, "batb": [[2, 1.31, 3.23]], "batl": [[1, 1.63, 18.4], [2, 1.64, 9.2]]}, {"timestamp": 1631532366345, "ltp": 1.58, "tv": 914.67, "trd": NaN, "batb": [[2, 1.44, 405.13]], "batl": NaN}, {"timestamp": 1631532367956, "ltp": 1.58, "tv": 914.67, "trd": NaN, "batb": [[1, 1.5, 26.75], [2, 1.47, 64.69]], "batl": NaN}, {"timestamp": 1631532369253, "ltp": 1.58, "tv": 914.67, "trd": NaN, "batb": NaN, "batl": [[0, 1.61, 63.46], [1, 1.62, 23.44], [2, 1.63, 18.4]]}, {"timestamp": 1631532369357, "ltp": 1.58, "tv": 914.67, "trd": NaN, "batb": [[1, 1.47, 64.69], [2, 1.44, 405.13]], "batl": [[0, 1.62, 23.44], [1, 1.63, 18.4], [2, 1.64, 9.2]]}, {"timestamp": 1631532375892, "ltp": 1.58, "tv": 914.67, "trd": NaN, "batb": NaN, "batl": [[0, 1.63, 18.4], [1, 1.64, 9.2], [2, 1.65, 9.2]]}, {"timestamp": 1631532378484, "ltp": 1.58, "tv": 914.67, "trd": NaN, "batb": NaN, "batl": [[0, 1.6, 13.04], [1, 1.63, 18.4], [2, 1.64, 9.2]]}, {"timestamp": 1631532393578, "ltp": 1.57, "tv": 924.67, "trd": [[1.57, 10]], "batb": NaN, "batl": NaN}, {"timestamp": 1631532456885, "ltp": 1.57, "tv": 924.67, "trd": NaN, "batb": [[0, 1.47, 64.69], [1, 1.44, 405.13], [2, 1.25, 237.69]], "batl": [[0, 1.8, 18.4], [1, 2.16, 372.43], [2, 8.8, 7.23]]}, {"timestamp": 1631532469281, "ltp": 1.57, "tv": 924.67, "trd": NaN, "batb": [[0, 1.63, 92.02], [1, 1.62, 46], [2, 1.61, 46]], "batl": NaN}, {"timestamp": 1631532470268, "ltp": 1.64, "tv": 931.29, "trd": [[1.64, 6.62]], "batb": [[0, 1.63, 18.4], [1, 1.62, 9.2], [2, 1.61, 9.2]], "batl": [[0, 1.68, 15.39], [1, 1.8, 18.4], [2, 2.16, 372.43]]}, {"timestamp": 1631532470684, "ltp": 1.64, "tv": 931.29, "trd": NaN, "batb": [[1, 1.62, 54.14]], "batl": NaN}, {"timestamp": 1631532474282, "ltp": 1.64, "tv": 931.29, "trd": NaN, "batb": NaN, "batl": [[0, 1.68, 76.53]]}, {"timestamp": 1631532474492, "ltp": 1.64, "tv": 931.29, "trd": NaN, "batb": NaN, "batl": [[0, 1.68, 15.39]]}, {"timestamp": 1631532479017, "ltp": 1.64, "tv": 931.29, "trd": NaN, "batb": [[0, 1.62, 44.94], [1, 1.54, 54.31], [2, 1.5, 397.3]], "batl": [[0, 1.8, 18.4], [1, 2.16, 372.43], [2, 8.8, 7.23]]}, {"timestamp": 1631532479431, "ltp": 1.64, "tv": 931.29, "trd": NaN, "batb": [[0, 1.54, 54.31], [1, 1.5, 397.3], [2, 1.25, 237.69]], "batl": NaN}, {"timestamp": 1631532487222, "ltp": 1.64, "tv": 931.29, "trd": NaN, "batb": [[0, 1.7, 17.64], [1, 1.69, 8.82], [2, 1.68, 8.82]], "batl": [[0, 1.74, 10.3], [1, 1.8, 18.4], [2, 1.83, 109.06]]}, {"timestamp": 1631532488209, "ltp": 1.7, "tv": 944.11, "trd": [[1.7, 12.82]], "batb": [[0, 1.7, 11.23], [1, 1.69, 47.06]], "batl": [[1, 1.78, 84.28], [2, 1.79, 25.28]]}, {"timestamp": 1631532488939, "ltp": 1.7, "tv": 944.11, "trd": NaN, "batb": NaN, "batl": [[1, 1.78, 16.86], [2, 1.79, 8.42]]}, {"timestamp": 1631532496268, "ltp": 1.7, "tv": 944.11, "trd": NaN, "batb": [[0, 1.69, 38.24], [1, 1.62, 44.69], [2, 1.5, 397.3]], "batl": [[0, 2.16, 372.43], [1, 810, 0.07], [2, 1.79, 0]]}, {"timestamp": 1631532496739, "ltp": 1.7, "tv": 944.11, "trd": NaN, "batb": [[0, 1.62, 44.69], [1, 1.5, 397.3], [2, 1.3, 198.07]], "batl": NaN}, {"timestamp": 1631532500293, "ltp": 1.7, "tv": 944.11, "trd": NaN, "batb": [[1, 1.3, 198.07], [2, 1.25, 237.69]], "batl": [[0, 810, 0.07], [1, 810, 0]]}, {"timestamp": 1631532502051, "ltp": 1.7, "tv": 944.11, "trd": NaN, "batb": [[0, 1.8, 97.3], [1, 1.77, 113], [2, 1.76, 18.1]], "batl": [[0, 1.92, 155.88], [1, 810, 0.07]]}, {"timestamp": 1631532503254, "ltp": 1.8, "tv": 956.61, "trd": [[1.8, 12.5]], "batb": [[0, 1.8, 91.05], [1, 1.77, 100.6]], "batl": [[0, 1.84, 81.52], [1, 1.85, 40.76], [2, 1.86, 40.76]]}, {"timestamp": 1631532503951, "ltp": 1.8, "tv": 956.61, "trd": NaN, "batb": NaN, "batl": [[0, 1.84, 16.3], [1, 1.85, 8.16], [2, 1.86, 8.16]]}, {"timestamp": 1631532509285, "ltp": 1.8, "tv": 956.61, "trd": NaN, "batb": [[0, 1.71, 37.07], [1, 1.55, 392.04], [2, 1.3, 198.07]], "batl": [[0, 1.9, 36.8], [1, 2.42, 312.73], [2, 810, 0.07]]}, {"timestamp": 1631532517066, "ltp": 1.8, "tv": 956.61, "trd": NaN, "batb": NaN, "batl": [[0, 1.8, 5.7], [1, 1.9, 36.8], [2, 2.42, 312.73]]}, {"timestamp": 1631532522795, "ltp": 1.74, "tv": 979.14, "trd": [[1.71, 12.74], [1.74, 9.79]], "batb": [[0, 1.71, 30.7]], "batl": [[1, 1.83, 117.21], [2, 1.9, 36.8]]}, {"timestamp": 1631532523677, "ltp": 1.74, "tv": 979.14, "trd": NaN, "batb": [[1, 1.69, 17.76], [2, 1.68, 8.88]], "batl": NaN}, {"timestamp": 1631532528081, "ltp": 1.74, "tv": 979.14, "trd": NaN, "batb": NaN, "batl": [[0, 1.83, 117.21], [1, 1.9, 36.8], [2, 2.42, 312.73]]}, {"timestamp": 1631532528702, "ltp": 1.74, "tv": 979.14, "trd": NaN, "batb": NaN, "batl": [[2, 1.98, 36.8]]}, {"timestamp": 1631532531180, "ltp": 1.74, "tv": 979.14, "trd": NaN, "batb": NaN, "batl": [[0, 1.83, 231.63]]}, {"timestamp": 1631532535987, "ltp": 1.74, "tv": 979.14, "trd": NaN, "batb": [[0, 1.63, 43.85], [1, 1.55, 392.04], [2, 1.3, 198.07]], "batl": [[0, 1.9, 36.8], [1, 1.98, 36.8], [2, 2.42, 312.73]]}, {"timestamp": 1631532547912, "ltp": 1.74, "tv": 979.14, "trd": NaN, "batb": [[0, 1.72, 402.74], [1, 1.71, 116.96], [2, 1.63, 43.85]], "batl": [[0, 1.83, 15.3], [1, 1.89, 82.07], [2, 1.9, 36.8]]}, {"timestamp": 1631532549199, "ltp": 1.78, "tv": 985.35, "trd": [[1.78, 6.21]], "batb": [[0, 1.77, 32.8], [1, 1.72, 402.74], [2, 1.71, 116.96]], "batl": [[1, 1.87, 16.04], [2, 1.88, 8.02]]}, {"timestamp": 1631532557738, "ltp": 1.78, "tv": 992.25, "trd": [[1.78, 13.11]], "batb": NaN, "batl": NaN}, {"timestamp": 1631532573970, "ltp": 1.78, "tv": 992.25, "trd": NaN, "batb": [[1, 1.71, 116.96], [2, 1.7, 37.49]], "batl": [[0, 1.87, 16.04], [1, 1.88, 8.02], [2, 1.89, 8.02]]}, {"timestamp": 1631532590251, "ltp": 1.78, "tv": 992.25, "trd": NaN, "batb": [[0, 1.7, 37.49], [1, 1.3, 198.07], [2, 1.25, 237.69]], "batl": [[0, 1.9, 36.8], [1, 1.98, 36.8], [2, 810, 0.07]]}, {"timestamp": 1631532597053, "ltp": 1.78, "tv": 992.25, "trd": NaN, "batb": [[1, 1.58, 388.69], [2, 1.3, 198.07]], "batl": [[2, 2.5, 299.95]]}, {"timestamp": 1631532607993, "ltp": 1.78, "tv": 992.25, "trd": NaN, "batb": [[1, 1.3, 198.07], [2, 1.25, 237.69]], "batl": NaN}, {"timestamp": 1631532609216, "ltp": 1.9, "tv": 1065.84, "trd": [[1.9, 73.6]], "batb": [[0, 1.9, 42.16], [1, 1.89, 39.48], [2, 1.88, 39.48]], "batl": [[0, 1.98, 36.8], [1, 2.02, 103.06]]}, {"timestamp": 1631532610211, "ltp": 1.9, "tv": 1077.82, "trd": [[1.9, 85.58]], "batb": [[0, 1.9, 33.49], [1, 1.89, 23.69], [2, 1.88, 23.69]], "batl": NaN}, {"timestamp": 1631532610784, "ltp": 1.9, "tv": 1077.82, "trd": NaN, "batb": [[0, 1.9, 1.91], [1, 1.89, 7.9], [2, 1.88, 34.85]], "batl": [[0, 2.02, 103.06], [1, 2.5, 299.95], [2, 2.5, 0]]}, {"timestamp": 1631532614200, "ltp": 1.9, "tv": 1077.82, "trd": NaN, "batb": NaN, "batl": [[0, 1.91, 54.28], [1, 2.02, 103.06], [2, 2.5, 299.95]]}, {"timestamp": 1631532614409, "ltp": 1.9, "tv": 1077.82, "trd": NaN, "batb": NaN, "batl": [[0, 2.02, 103.06], [1, 2.5, 299.95], [2, 2.5, 0]]}, {"timestamp": 1631532634117, "ltp": 1.9, "tv": 1077.82, "trd": NaN, "batb": [[0, 1.79, 31.63], [1, 1.62, 388.38], [2, 1.4, 148.56]], "batl": [[0, 2.5, 299.95], [1, 2.5, 0]]}, {"timestamp": 1631532643642, "ltp": 1.9, "tv": 1077.82, "trd": NaN, "batb": [[1, 1.4, 148.56], [2, 1.3, 198.07]], "batl": NaN}, {"timestamp": 1631532645148, "ltp": 1.9, "tv": 1077.82, "trd": NaN, "batb": NaN, "batl": [[0, 2.06, 6.58], [1, 2.2, 145.64], [2, 2.5, 299.95]]}, {"timestamp": 1631532646140, "ltp": 2.04, "tv": 1083.47, "trd": [[2.04, 5.65]], "batb": [[0, 2, 43.93], [1, 1.9, 51.88], [2, 1.4, 148.56]], "batl": NaN}, {"timestamp": 1631532647547, "ltp": 2.04, "tv": 1083.47, "trd": NaN, "batb": [[2, 1.67, 383.76]], "batl": NaN}, {"timestamp": 1631532649832, "ltp": 2.04, "tv": 1097.44, "trd": [[2.04, 19.62]], "batb": NaN, "batl": NaN}, {"timestamp": 1631532666171, "ltp": 2.04, "tv": 1097.44, "trd": NaN, "batb": [[0, 1.9, 51.88], [1, 1.67, 383.76], [2, 1.4, 148.56]], "batl": [[0, 2.5, 299.95], [1, 2.2, 0], [2, 2.5, 0]]}, {"timestamp": 1631532673170, "ltp": 2.04, "tv": 1097.44, "trd": NaN, "batb": NaN, "batl": [[0, 2.82, 253.59]]}, {"timestamp": 1631532690283, "ltp": 1.9, "tv": 1109.14, "trd": [[1.9, 97.28]], "batb": [[0, 1.9, 46.03]], "batl": [[0, 1.97, 1530.36], [1, 1.99, 75.38], [2, 2, 37.68]]}, {"timestamp": 1631532690593, "ltp": 1.9, "tv": 1109.14, "trd": NaN, "batb": NaN, "batl": [[0, 1.99, 45.23], [1, 2, 22.61], [2, 2.02, 22.61]]}, {"timestamp": 1631532691782, "ltp": 1.9, "tv": 1109.14, "trd": NaN, "batb": [[1, 1.8, 31.13], [2, 1.67, 383.76]], "batl": NaN}, {"timestamp": 1631532702710, "ltp": 1.9, "tv": 1109.14, "trd": NaN, "batb": [[1, 1.86, 36.8], [2, 1.8, 31.13]], "batl": NaN}, {"timestamp": 1631532713270, "ltp": 1.9, "tv": 1109.14, "trd": NaN, "batb": [[0, 1.86, 36.8], [1, 1.8, 31.13], [2, 1.67, 383.76]], "batl": [[0, 2.6, 281.81], [1, 2, 0], [2, 2.02, 0]]}, {"timestamp": 1631532722139, "ltp": 1.9, "tv": 1109.14, "trd": NaN, "batb": [[2, 1.4, 148.56]], "batl": NaN}, {"timestamp": 1631532725285, "ltp": 1.9, "tv": 1109.14, "trd": NaN, "batb": NaN, "batl": [[0, 3.6, 332.39]]}, {"timestamp": 1631532731956, "ltp": 1.9, "tv": 1109.14, "trd": NaN, "batb": NaN, "batl": [[0, 3.2, 151.46]]}, {"timestamp": 1631532759155, "ltp": 1.9, "tv": 1109.14, "trd": NaN, "batb": NaN, "batl": [[0, 2.16, 16.75]]}, {"timestamp": 1631532760234, "ltp": 2.08, "tv": 1114.63, "trd": [[2.08, 5.49]], "batb": [[0, 2.06, 40.59], [1, 1.94, 48.62], [2, 1.86, 36.8]], "batl": NaN}, {"timestamp": 1631532761621, "ltp": 2.08, "tv": 1114.63, "trd": NaN, "batb": NaN, "batl": [[1, 2.82, 253.59]]}, {"timestamp": 1631532764161, "ltp": 2.08, "tv": 1114.63, "trd": NaN, "batb": [[0, 1.94, 48.62], [1, 1.86, 36.8], [2, 1.7, 383.83]], "batl": [[0, 2.82, 253.59], [1, 2.82, 0]]}, {"timestamp": 1631532790187, "ltp": 1.94, "tv": 1126.05, "trd": [[1.94, 11.42]], "batb": [[0, 1.94, 42.91]], "batl": [[0, 2.02, 8.1], [1, 2.06, 97.08], [2, 2.12, 98.14]]}, {"timestamp": 1631532791283, "ltp": 1.94, "tv": 1126.05, "trd": NaN, "batb": [[2, 1.8, 31.13]], "batl": [[1, 2.06, 58.25]]}, {"timestamp": 1631532804094, "ltp": 1.94, "tv": 1126.05, "trd": NaN, "batb": NaN, "batl": [[0, 2.82, 253.59], [1, 2.06, 0], [2, 2.12, 0]]}, {"timestamp": 1631532804502, "ltp": 1.94, "tv": 1126.05, "trd": NaN, "batb": [[0, 1.86, 36.8], [1, 1.8, 31.13], [2, 1.7, 383.83]], "batl": NaN}, {"timestamp": 1631532805903, "ltp": 1.94, "tv": 1126.05, "trd": NaN, "batb": [[0, 2, 36.8], [1, 1.86, 36.8], [2, 1.8, 31.13]], "batl": NaN}, {"timestamp": 1631532809891, "ltp": 1.94, "tv": 1126.05, "trd": NaN, "batb": [[0, 1.86, 36.8], [1, 1.8, 31.13], [2, 1.4, 148.56]], "batl": NaN}, {"timestamp": 1631532811910, "ltp": 1.94, "tv": 1126.05, "trd": NaN, "batb": NaN, "batl": [[0, 2.28, 9.89], [1, 2.42, 103.06], [2, 2.82, 253.59]]}, {"timestamp": 1631532813214, "ltp": 2.2, "tv": 1131.2, "trd": [[2.2, 5.15]], "batb": [[0, 2.18, 34.73], [1, 2.04, 41.67], [2, 1.86, 36.8]], "batl": NaN}, {"timestamp": 1631532822717, "ltp": 2.2, "tv": 1131.2, "trd": NaN, "batb": NaN, "batl": [[0, 2.42, 103.06], [1, 2.82, 253.59], [2, 2.82, 0]]}, {"timestamp": 1631532858781, "ltp": 2.2, "tv": 1131.2, "trd": NaN, "batb": [[2, 1.77, 378.13]], "batl": NaN}, {"timestamp": 1631532861178, "ltp": 2.2, "tv": 1131.2, "trd": NaN, "batb": NaN, "batl": [[0, 2.28, 8.8], [1, 2.42, 103.06], [2, 2.82, 253.59]]}, {"timestamp": 1631532891248, "ltp": 2.2, "tv": 1131.2, "trd": NaN, "batb": NaN, "batl": [[0, 2.82, 253.59], [1, 2.42, 0], [2, 2.82, 0]]}, {"timestamp": 1631532891510, "ltp": 2.2, "tv": 1131.2, "trd": NaN, "batb": [[0, 2.04, 41.67], [1, 1.77, 378.13], [2, 1.4, 148.56]], "batl": NaN}, {"timestamp": 1631532908882, "ltp": 2.04, "tv": 1141.96, "trd": [[2.04, 30.38]], "batb": [[0, 2.04, 36.29]], "batl": [[0, 2.16, 13.58], [1, 2.24, 81.09], [2, 2.82, 253.59]]}, {"timestamp": 1631532909876, "ltp": 2.04, "tv": 1141.96, "trd": NaN, "batb": [[0, 2.06, 14.56], [1, 2.04, 43.57], [2, 2.02, 7.28]], "batl": NaN}, {"timestamp": 1631532929119, "ltp": 2.04, "tv": 1141.96, "trd": NaN, "batb": [[0, 1.93, 49.87], [1, 1.77, 378.13], [2, 1.4, 148.56]], "batl": [[0, 2.82, 253.59], [1, 2.24, 0], [2, 2.82, 0]]}, {"timestamp": 1631532951650, "ltp": 2.04, "tv": 1141.96, "trd": NaN, "batb": [[0, 2.18, 68.8], [1, 2.16, 52.92], [2, 2.14, 34.4]], "batl": NaN}, {"timestamp": 1631532952751, "ltp": 2.2, "tv": 1147.14, "trd": [[2.2, 10.33]], "batb": [[0, 2.18, 41.28], [1, 2.16, 74.47], [2, 2.14, 20.64]], "batl": [[0, 2.32, 12.94], [1, 2.34, 6.46], [2, 2.36, 6.46]]}, {"timestamp": 1631532965469, "ltp": 2.2, "tv": 1147.14, "trd": NaN, "batb": NaN, "batl": [[0, 2.24, 9.39], [1, 2.32, 12.94], [2, 2.34, 6.46]]}, {"timestamp": 1631532969784, "ltp": 2.2, "tv": 1147.14, "trd": NaN, "batb": [[0, 2.02, 43.51], [1, 1.77, 378.13], [2, 1.4, 148.56]], "batl": [[0, 2.82, 253.59], [1, 2.32, 0], [2, 2.34, 0]]}, {"timestamp": 1631532973179, "ltp": 2.2, "tv": 1147.14, "trd": NaN, "batb": [[0, 2, 43.68]], "batl": NaN}, {"timestamp": 1631532976199, "ltp": 2.2, "tv": 1147.14, "trd": NaN, "batb": NaN, "batl": [[0, 2.5, 96.38]]}, {"timestamp": 1631532976776, "ltp": 2.28, "tv": 1152.09, "trd": [[2.28, 4.95]], "batb": [[0, 2.28, 29.96], [1, 2.14, 36.48], [2, 1.77, 378.13]], "batl": NaN}, {"timestamp": 1631532978286, "ltp": 2.28, "tv": 1152.09, "trd": NaN, "batb": NaN, "batl": [[1, 3.15, 220.27]]}, {"timestamp": 1631532982200, "ltp": 2.28, "tv": 1152.09, "trd": NaN, "batb": NaN, "batl": [[0, 2.48, 109.68], [1, 2.5, 96.38], [2, 3.15, 220.27]]}, {"timestamp": 1631532982407, "ltp": 2.28, "tv": 1152.09, "trd": NaN, "batb": NaN, "batl": [[0, 2.5, 96.38], [1, 3.15, 220.27], [2, 3.15, 0]]}, {"timestamp": 1631532985591, "ltp": 2.28, "tv": 1152.09, "trd": NaN, "batb": NaN, "batl": [[0, 2.48, 109.68], [1, 2.5, 96.38], [2, 3.15, 220.27]]}, {"timestamp": 1631532987201, "ltp": 2.28, "tv": 1152.09, "trd": NaN, "batb": NaN, "batl": [[1, 3.15, 220.27], [2, 3.15, 0]]}, {"timestamp": 1631532988204, "ltp": 2.28, "tv": 1152.09, "trd": NaN, "batb": [[0, 2.14, 36.32], [1, 1.77, 378.13], [2, 1.4, 148.56]], "batl": [[0, 3.15, 220.27], [1, 3.15, 0]]}, {"timestamp": 1631533004116, "ltp": 2.16, "tv": 1157.3, "trd": [[2.16, 5.21]], "batb": NaN, "batl": [[0, 2.24, 16.9], [1, 2.28, 87.72]]}, {"timestamp": 1631533005257, "ltp": 2.16, "tv": 1157.3, "trd": NaN, "batb": [[1, 1.98, 46.28], [2, 1.77, 378.13]], "batl": NaN}, {"timestamp": 1631533005938, "ltp": 2.16, "tv": 1157.3, "trd": NaN, "batb": NaN, "batl": [[2, 2.92, 242.8]]}, {"timestamp": 1631533019048, "ltp": 2.16, "tv": 1157.3, "trd": NaN, "batb": [[0, 1.98, 46.28], [1, 1.77, 378.13], [2, 1.4, 148.56]], "batl": [[0, 2.92, 242.8], [1, 2.28, 0], [2, 2.92, 0]]}, {"timestamp": 1631533039978, "ltp": 1.98, "tv": 1168.34, "trd": [[1.98, 11.04]], "batb": [[0, 2, 75.23], [1, 1.98, 40.75], [2, 1.77, 378.13]], "batl": [[0, 2.06, 109.34], [1, 2.16, 90.22]]}, {"timestamp": 1631533041288, "ltp": 1.98, "tv": 1168.34, "trd": NaN, "batb": [[2, 1.97, 15.22]], "batl": [[2, 2.72, 264.63]]}, {"timestamp": 1631533066034, "ltp": 1.98, "tv": 1168.34, "trd": NaN, "batb": [[0, 1.84, 28.87], [1, 1.77, 378.13], [2, 1.4, 148.56]], "batl": [[0, 2.72, 264.63], [1, 2.16, 0], [2, 2.72, 0]]}, {"timestamp": 1631533124767, "ltp": 1.98, "tv": 1168.34, "trd": NaN, "batb": [[1, 1.4, 148.56], [2, 1.3, 198.07]], "batl": NaN}, {"timestamp": 1631533125863, "ltp": 1.84, "tv": 1180.18, "trd": [[1.84, 11.84]], "batb": [[0, 1.84, 22.95]], "batl": [[0, 1.89, 10.26], [1, 1.92, 15.62], [2, 1.93, 7.82]]}, {"timestamp": 1631533127181, "ltp": 1.84, "tv": 1180.18, "trd": NaN, "batb": [[1, 1.82, 16.48], [2, 1.81, 8.24]], "batl": NaN}, {"timestamp": 1631533147682, "ltp": 1.84, "tv": 1180.18, "trd": NaN, "batb": [[0, 1.85, 18.4], [1, 1.84, 22.95], [2, 1.82, 16.48]], "batl": NaN}, {"timestamp": 1631533149507, "ltp": 1.85, "tv": 1197.22, "trd": [[1.85, 17.04]], "batb": [[0, 1.85, 9.88]], "batl": NaN}, {"timestamp": 1631533178838, "ltp": 1.85, "tv": 1197.22, "trd": NaN, "batb": [[0, 1.84, 22.95], [1, 1.82, 16.48], [2, 1.81, 8.24]], "batl": NaN}, {"timestamp": 1631533180144, "ltp": 1.85, "tv": 1197.22, "trd": NaN, "batb": [[1, 1.75, 34.14], [2, 1.62, 388.38]], "batl": [[0, 2.6, 281.81], [1, 1.92, 0], [2, 1.93, 0]]}, {"timestamp": 1631533180657, "ltp": 1.85, "tv": 1197.22, "trd": NaN, "batb": [[0, 1.75, 34.14], [1, 1.62, 388.38], [2, 1.4, 148.56]], "batl": [[0, 2.6, 282.51]]}, {"timestamp": 1631533181959, "ltp": 1.85, "tv": 1198.63, "trd": [[1.85, 18.45]], "batb": [[0, 1.89, 9.18], [1, 1.75, 34.14], [2, 1.62, 388.38]], "batl": [[0, 2.6, 281.81]]}, {"timestamp": 1631533196772, "ltp": 1.85, "tv": 1198.63, "trd": NaN, "batb": [[0, 1.75, 34.14], [1, 1.62, 388.38], [2, 1.4, 148.56]], "batl": NaN}, {"timestamp": 1631533197866, "ltp": 1.75, "tv": 1210.75, "trd": [[1.75, 12.12]], "batb": [[0, 1.75, 28.08]], "batl": [[0, 1.83, 18.25], [1, 1.84, 21.74], [2, 1.89, 85.93]]}, {"timestamp": 1631533199271, "ltp": 1.75, "tv": 1210.75, "trd": NaN, "batb": [[0, 1.75, 45.22], [1, 1.74, 8.58], [2, 1.73, 8.58]], "batl": NaN}, {"timestamp": 1631533211715, "ltp": 1.83, "tv": 1240.19, "trd": [[1.83, 29.44]], "batb": NaN, "batl": [[0, 1.83, 3.53]]}, {"timestamp": 1631533212711, "ltp": 1.78, "tv": 1240.89, "trd": [[1.78, 13.81]], "batb": NaN, "batl": NaN}, {"timestamp": 1631533219943, "ltp": 1.78, "tv": 1240.89, "trd": NaN, "batb": [[0, 1.68, 39.25], [1, 1.4, 148.56], [2, 1.3, 198.07]], "batl": NaN}, {"timestamp": 1631533230621, "ltp": 1.78, "tv": 1240.89, "trd": NaN, "batb": [[0, 1.76, 7.36], [1, 1.68, 39.25], [2, 1.4, 148.56]], "batl": NaN}, {"timestamp": 1631533237164, "ltp": 1.78, "tv": 1240.89, "trd": NaN, "batb": [[0, 1.84, 108.7], [1, 1.8, 380.3], [2, 1.76, 7.36]], "batl": [[0, 1.94, 10.28], [1, 2, 48.79]]}, {"timestamp": 1631533238161, "ltp": 1.89, "tv": 1246.74, "trd": [[1.89, 5.85]], "batb": [[0, 1.85, 28.62], [1, 1.84, 65.22], [2, 1.8, 380.3]], "batl": [[1, 1.96, 76.52], [2, 1.97, 38.26]]}, {"timestamp": 1631533238578, "ltp": 1.89, "tv": 1246.74, "trd": NaN, "batb": NaN, "batl": [[1, 1.96, 15.3], [2, 1.97, 7.66]]}, {"timestamp": 1631533248191, "ltp": 1.89, "tv": 1246.74, "trd": NaN, "batb": NaN, "batl": [[0, 1.96, 15.3], [1, 1.97, 7.66], [2, 1.98, 7.66]]}, {"timestamp": 1631533251056, "ltp": 1.89, "tv": 1246.74, "trd": NaN, "batb": [[0, 1.89, 8.12], [1, 1.85, 28.62], [2, 1.84, 65.22]], "batl": NaN}, {"timestamp": 1631533259977, "ltp": 1.89, "tv": 1246.74, "trd": NaN, "batb": [[0, 1.76, 7.36], [1, 1.75, 34.31], [2, 1.4, 148.56]], "batl": NaN}, {"timestamp": 1631533263683, "ltp": 1.89, "tv": 1246.74, "trd": NaN, "batb": [[2, 1.7, 36.8]], "batl": NaN}, {"timestamp": 1631533268181, "ltp": 1.76, "tv": 1258.78, "trd": [[1.76, 12.04]], "batb": [[0, 1.8, 109.75], [1, 1.76, 1.34], [2, 1.75, 34.31]], "batl": [[0, 1.86, 20.28], [1, 1.87, 48.12], [2, 1.88, 24.06]]}, {"timestamp": 1631533292046, "ltp": 1.76, "tv": 1258.78, "trd": NaN, "batb": [[0, 1.76, 1.34], [1, 1.75, 34.31], [2, 1.7, 36.8]], "batl": NaN}, {"timestamp": 1631533292980, "ltp": 1.76, "tv": 1258.78, "trd": NaN, "batb": [[1, 1.7, 36.8], [2, 1.67, 40.25]], "batl": NaN}, {"timestamp": 1631533300749, "ltp": 1.76, "tv": 1266.29, "trd": [[1.76, 19.55]], "batb": [[0, 1.74, 109.95]], "batl": [[0, 1.78, 14.67], [1, 1.79, 111.74], [2, 1.83, 96.43]]}, {"timestamp": 1631533302856, "ltp": 1.76, "tv": 1266.29, "trd": NaN, "batb": [[1, 1.67, 40.25], [2, 1.62, 44.69]], "batl": NaN}, {"timestamp": 1631533307286, "ltp": 1.74, "tv": 1281.42, "trd": [[1.74, 20.85], [1.76, 23.62]], "batb": [[0, 1.74, 104.42]], "batl": NaN}, {"timestamp": 1631533319686, "ltp": 1.74, "tv": 1281.42, "trd": NaN, "batb": [[1, 1.67, 77.05]], "batl": NaN}, {"timestamp": 1631533322208, "ltp": 1.74, "tv": 1281.42, "trd": NaN, "batb": [[0, 1.67, 36.8], [1, 1.62, 44.69], [2, 1.4, 148.56]], "batl": NaN}, {"timestamp": 1631533332213, "ltp": 1.7, "tv": 1293.92, "trd": [[1.7, 25.32]], "batb": [[0, 1.7, 99.93], [1, 1.67, 36.8], [2, 1.62, 44.69]], "batl": [[0, 1.75, 200], [1, 1.76, 42.86], [2, 1.77, 328.64]]}, {"timestamp": 1631533333035, "ltp": 1.7, "tv": 1293.92, "trd": NaN, "batb": [[1, 1.67, 126.62], [2, 1.66, 44.9]], "batl": [[0, 1.75, 120], [1, 1.76, 25.72], [2, 1.77, 25.72]]}, {"timestamp": 1631533333410, "ltp": 1.7, "tv": 1293.92, "trd": NaN, "batb": [[1, 1.67, 54.76], [2, 1.66, 8.98]], "batl": NaN}, {"timestamp": 1631533337011, "ltp": 1.7, "tv": 1293.92, "trd": NaN, "batb": NaN, "batl": [[2, 1.77, 75.56]]}, {"timestamp": 1631533337324, "ltp": 1.7, "tv": 1293.92, "trd": NaN, "batb": NaN, "batl": [[2, 1.77, 25.72]]}, {"timestamp": 1631533354639, "ltp": 1.74, "tv": 1293.97, "trd": [[1.74, 20.89]], "batb": NaN, "batl": NaN}, {"timestamp": 1631533364847, "ltp": 1.74, "tv": 1293.97, "trd": NaN, "batb": [[0, 1.7, 89.93]], "batl": NaN}, {"timestamp": 1631533367772, "ltp": 1.74, "tv": 1293.97, "trd": NaN, "batb": [[0, 1.7, 99.98]], "batl": NaN}, {"timestamp": 1631533405860, "ltp": 1.74, "tv": 1293.97, "trd": NaN, "batb": [[1, 1.67, 17.96]], "batl": NaN}, {"timestamp": 1631533419252, "ltp": 1.74, "tv": 1293.97, "trd": NaN, "batb": [[0, 1.7, 89.93]], "batl": NaN}, {"timestamp": 1631533422161, "ltp": 1.74, "tv": 1293.97, "trd": NaN, "batb": [[0, 1.7, 101.07]], "batl": NaN}, {"timestamp": 1631533427685, "ltp": 1.74, "tv": 1293.97, "trd": NaN, "batb": [[0, 1.52, 396.29], [1, 1.51, 58.07], [2, 1.3, 198.07]], "batl": [[0, 2.36, 326.18], [1, 1.76, 0], [2, 1.77, 0]]}, {"timestamp": 1631533442396, "ltp": 1.74, "tv": 1293.97, "trd": NaN, "batb": [[0, 1.51, 58.07], [1, 1.3, 198.07], [2, 1.25, 237.69]], "batl": NaN}, {"timestamp": 1631533444115, "ltp": 1.74, "tv": 1293.97, "trd": NaN, "batb": NaN, "batl": [[0, 1.86, 20.85], [1, 1.92, 150.53], [2, 2.36, 326.18]]}, {"timestamp": 1631533444997, "ltp": 1.8, "tv": 1299.92, "trd": [[1.8, 18.45]], "batb": [[0, 1.72, 35.82], [1, 1.61, 45.94], [2, 1.3, 198.07]], "batl": NaN}, {"timestamp": 1631533446508, "ltp": 1.8, "tv": 1299.92, "trd": NaN, "batb": [[2, 1.58, 388.69]], "batl": NaN}, {"timestamp": 1631533453055, "ltp": 1.8, "tv": 1299.92, "trd": NaN, "batb": [[0, 1.72, 2179.84]], "batl": NaN}, {"timestamp": 1631533455039, "ltp": 1.8, "tv": 1299.92, "trd": NaN, "batb": [[0, 1.72, 35.82]], "batl": [[0, 1.92, 150.53], [1, 2.36, 326.18], [2, 2.36, 0]]}, {"timestamp": 1631533458132, "ltp": 1.8, "tv": 1299.92, "trd": NaN, "batb": [[0, 1.72, 1341.71]], "batl": [[0, 1.83, 10.59], [1, 1.92, 150.53], [2, 2.36, 326.18]]}, {"timestamp": 1631533458341, "ltp": 1.8, "tv": 1299.92, "trd": NaN, "batb": [[0, 1.72, 35.82]], "batl": NaN}, {"timestamp": 1631533459748, "ltp": 1.8, "tv": 1299.92, "trd": NaN, "batb": [[0, 1.61, 45.94], [1, 1.58, 388.69], [2, 1.3, 198.07]], "batl": [[0, 2.36, 326.18], [1, 1.92, 0], [2, 2.36, 0]]}, {"timestamp": 1631533466950, "ltp": 1.8, "tv": 1299.92, "trd": NaN, "batb": [[1, 1.3, 198.07], [2, 1.25, 237.69]], "batl": NaN}, {"timestamp": 1631533469287, "ltp": 1.8, "tv": 1299.92, "trd": NaN, "batb": [[0, 1.87, 123], [1, 1.86, 8.02], [2, 1.85, 8.02]], "batl": [[0, 1.94, 10.64], [1, 2.02, 96.87]]}, {"timestamp": 1631533469651, "ltp": 1.89, "tv": 1305.63, "trd": [[1.89, 11.56]], "batb": [[2, 1.85, 36.56]], "batl": [[1, 1.97, 15.22], [2, 1.98, 7.62]]}, {"timestamp": 1631533478984, "ltp": 1.89, "tv": 1305.63, "trd": NaN, "batb": [[0, 1.85, 28.54], [1, 1.73, 35.23], [2, 1.62, 388.38]], "batl": [[0, 2.6, 281.81], [1, 1.97, 0], [2, 1.98, 0]]}, {"timestamp": 1631533480280, "ltp": 1.89, "tv": 1305.63, "trd": NaN, "batb": [[0, 1.73, 35.23], [1, 1.62, 388.38], [2, 1.4, 148.56]], "batl": NaN}, {"timestamp": 1631533501013, "ltp": 1.89, "tv": 1305.63, "trd": NaN, "batb": [[1, 1.4, 148.56], [2, 1.3, 198.07]], "batl": NaN}, {"timestamp": 1631533502613, "ltp": 1.89, "tv": 1305.63, "trd": NaN, "batb": [[0, 1.93, 62.17], [1, 1.73, 35.23], [2, 1.4, 148.56]], "batl": [[0, 2.02, 10.38], [1, 2.12, 96.71], [2, 2.6, 281.81]]}, {"timestamp": 1631533504225, "ltp": 1.96, "tv": 1311.12, "trd": [[1.96, 5.49]], "batb": [[0, 1.96, 47.78], [1, 1.93, 62.17], [2, 1.87, 27.28]], "batl": NaN}, {"timestamp": 1631533513925, "ltp": 1.96, "tv": 1311.12, "trd": NaN, "batb": [[0, 1.87, 27.28], [1, 1.67, 383.76], [2, 1.4, 148.56]], "batl": [[0, 2.6, 281.81], [1, 2.12, 0], [2, 2.6, 0]]}, {"timestamp": 1631533523244, "ltp": 1.87, "tv": 1322.42, "trd": [[1.87, 11.3]], "batb": [[0, 1.87, 21.63]], "batl": [[0, 1.94, 12.63], [1, 1.95, 46.15], [2, 1.96, 23.08]]}, {"timestamp": 1631533524233, "ltp": 1.87, "tv": 1322.42, "trd": NaN, "batb": [[1, 1.85, 16.22], [2, 1.84, 8.1]], "batl": [[1, 1.95, 15.38], [2, 1.96, 7.7]]}, {"timestamp": 1631533527952, "ltp": 1.94, "tv": 1335.05, "trd": [[1.94, 24.05]], "batb": NaN, "batl": [[0, 1.95, 15.38], [1, 1.96, 7.7], [2, 1.97, 7.7]]}, {"timestamp": 1631533534075, "ltp": 1.94, "tv": 1335.05, "trd": NaN, "batb": [[0, 1.75, 33.89], [1, 1.67, 383.76], [2, 1.4, 148.56]], "batl": [[0, 2.6, 281.81], [1, 1.96, 0], [2, 1.97, 0]]}, {"timestamp": 1631533548774, "ltp": 1.94, "tv": 1335.05, "trd": NaN, "batb": [[0, 2, 6.09], [1, 1.97, 15.22], [2, 1.96, 7.62]], "batl": [[0, 2.06, 12.13], [1, 2.12, 85.78], [2, 2.6, 281.81]]}, {"timestamp": 1631533549975, "ltp": 2.0, "tv": 1345.97, "trd": [[2, 10.92]], "batb": [[0, 1.98, 46.74]], "batl": NaN}, {"timestamp": 1631533559697, "ltp": 2.0, "tv": 1345.97, "trd": NaN, "batb": [[0, 1.98, 46.11]], "batl": [[0, 2.12, 85.78], [1, 2.6, 281.81], [2, 2.6, 0]]}, {"timestamp": 1631533562999, "ltp": 2.0, "tv": 1345.97, "trd": NaN, "batb": NaN, "batl": [[0, 2.04, 9.68], [1, 2.12, 85.78], [2, 2.6, 281.81]]}, {"timestamp": 1631533572816, "ltp": 2.0, "tv": 1345.97, "trd": NaN, "batb": NaN, "batl": [[0, 2.02, 4.26], [1, 2.04, 9.68], [2, 2.12, 85.78]]}, {"timestamp": 1631533586556, "ltp": 2.0, "tv": 1345.97, "trd": NaN, "batb": NaN, "batl": [[0, 2.04, 9.68], [1, 2.12, 85.78], [2, 2.6, 281.81]]}, {"timestamp": 1631533590253, "ltp": 2.0, "tv": 1345.97, "trd": NaN, "batb": [[0, 1.89, 26.44], [1, 1.67, 383.76], [2, 1.4, 148.56]], "batl": [[0, 2, 4.26], [1, 2.6, 281.81], [2, 2.6, 0]]}, {"timestamp": 1631533595291, "ltp": 2.0, "tv": 1345.97, "trd": NaN, "batb": NaN, "batl": [[0, 2.6, 281.81], [1, 2.6, 0]]}, {"timestamp": 1631533611997, "ltp": 1.89, "tv": 1357.15, "trd": [[1.89, 22.74]], "batb": [[0, 1.89, 20.85]], "batl": [[0, 1.99, 45.23], [1, 2, 22.61], [2, 2.02, 22.61]]}, {"timestamp": 1631533612994, "ltp": 1.89, "tv": 1357.15, "trd": NaN, "batb": [[1, 1.88, 15.96], [2, 1.87, 7.98]], "batl": [[0, 1.99, 15.08], [1, 2, 7.54], [2, 2.02, 7.54]]}, {"timestamp": 1631533629831, "ltp": 1.89, "tv": 1357.15, "trd": NaN, "batb": NaN, "batl": [[0, 1.98, 8.15], [1, 1.99, 15.08], [2, 2, 7.54]]}, {"timestamp": 1631533632021, "ltp": 1.89, "tv": 1357.15, "trd": NaN, "batb": [[0, 1.82, 29.96], [1, 1.67, 383.76], [2, 1.4, 148.56]], "batl": [[0, 2.6, 281.81], [1, 1.99, 0], [2, 2, 0]]}, {"timestamp": 1631533638235, "ltp": 1.82, "tv": 1368.57, "trd": [[1.82, 11.42]], "batb": [[0, 1.82, 24.25]], "batl": [[0, 1.92, 8.25], [1, 1.95, 46.15], [2, 1.96, 23.08]]}, {"timestamp": 1631533639179, "ltp": 1.82, "tv": 1368.57, "trd": NaN, "batb": [[0, 1.85, 16.22], [1, 1.84, 8.1], [2, 1.83, 8.1]], "batl": [[1, 1.95, 15.38], [2, 1.96, 7.7]]}, {"timestamp": 1631533656980, "ltp": 1.82, "tv": 1368.57, "trd": NaN, "batb": [[0, 1.77, 32.89], [1, 1.67, 383.76], [2, 1.4, 148.56]], "batl": [[0, 2.6, 281.81], [1, 1.95, 0], [2, 1.96, 0]]}, {"timestamp": 1631533666096, "ltp": 1.82, "tv": 1368.57, "trd": NaN, "batb": NaN, "batl": [[0, 2, 5.31], [1, 2.06, 97.83], [2, 2.6, 281.81]]}, {"timestamp": 1631533667283, "ltp": 1.94, "tv": 1374.13, "trd": [[1.94, 29.61]], "batb": [[0, 1.9, 52.05], [1, 1.82, 30.04], [2, 1.67, 383.76]], "batl": NaN}, {"timestamp": 1631533686844, "ltp": 1.94, "tv": 1374.13, "trd": NaN, "batb": [[0, 1.82, 30.04], [1, 1.67, 383.76], [2, 1.4, 148.56]], "batl": [[0, 2.6, 281.81], [1, 2.06, 0], [2, 2.6, 0]]}, {"timestamp": 1631533721193, "ltp": 1.94, "tv": 1374.13, "trd": NaN, "batb": [[0, 2.06, 7.88], [1, 2.04, 81.3], [2, 1.82, 30.04]], "batl": [[0, 2.12, 14.34], [1, 2.2, 141.23], [2, 2.6, 281.81]]}, {"timestamp": 1631533722106, "ltp": 2.06, "tv": 1384.83, "trd": [[2.06, 10.7]], "batb": [[0, 2.06, 2.53], [2, 2.02, 43.43]], "batl": NaN}, {"timestamp": 1631533732109, "ltp": 2.06, "tv": 1384.83, "trd": NaN, "batb": [[0, 2.04, 81.3], [1, 2.02, 43.43], [2, 1.89, 26.44]], "batl": [[0, 2.2, 141.23], [1, 2.6, 281.81], [2, 2.6, 0]]}, {"timestamp": 1631533741443, "ltp": 2.06, "tv": 1384.83, "trd": NaN, "batb": NaN, "batl": [[0, 2.2, 183.81]]}, {"timestamp": 1631533749173, "ltp": 2.06, "tv": 1384.83, "trd": NaN, "batb": [[0, 2.02, 43.43], [1, 1.89, 26.44], [2, 1.67, 383.76]], "batl": [[0, 2.6, 281.81], [1, 2.6, 0]]}, {"timestamp": 1631533750065, "ltp": 2.06, "tv": 1384.83, "trd": NaN, "batb": [[0, 1.89, 26.44], [1, 1.67, 383.76], [2, 1.4, 148.56]], "batl": NaN}, {"timestamp": 1631533778093, "ltp": 1.89, "tv": 1395.95, "trd": [[1.89, 33.86]], "batb": [[0, 1.89, 20.88]], "batl": [[0, 2, 7.22], [1, 2.02, 44.56], [2, 2.04, 22.28]]}, {"timestamp": 1631533779086, "ltp": 1.89, "tv": 1395.95, "trd": NaN, "batb": [[0, 1.91, 15.7], [1, 1.9, 7.86], [2, 1.89, 28.74]], "batl": NaN}, {"timestamp": 1631533805275, "ltp": 1.89, "tv": 1395.95, "trd": NaN, "batb": [[0, 1.89, 20.88], [1, 1.8, 30.79], [2, 1.67, 383.76]], "batl": [[0, 2.6, 281.81], [1, 2.02, 0], [2, 2.04, 0]]}, {"timestamp": 1631533805542, "ltp": 1.89, "tv": 1395.95, "trd": NaN, "batb": [[0, 1.8, 30.79], [1, 1.67, 383.76], [2, 1.4, 148.56]], "batl": NaN}, {"timestamp": 1631533823693, "ltp": 1.89, "tv": 1395.95, "trd": NaN, "batb": NaN, "batl": [[0, 2.12, 13.79], [1, 2.2, 106.3], [2, 2.6, 281.81]]}, {"timestamp": 1631533824787, "ltp": 2.06, "tv": 1401.27, "trd": [[2.06, 16.02]], "batb": [[0, 2.02, 42.59], [1, 1.9, 26.19], [2, 1.67, 383.76]], "batl": [[1, 2.16, 13.88], [2, 2.18, 6.94]]}, {"timestamp": 1631533844110, "ltp": 2.06, "tv": 1401.27, "trd": NaN, "batb": NaN, "batl": [[0, 2.6, 281.81], [1, 2.16, 0], [2, 2.18, 0]]}, {"timestamp": 1631533844528, "ltp": 2.06, "tv": 1401.27, "trd": NaN, "batb": [[0, 1.9, 26.19], [1, 1.67, 383.76], [2, 1.4, 148.56]], "batl": NaN}, {"timestamp": 1631533846623, "ltp": 2.06, "tv": 1401.27, "trd": NaN, "batb": [[1, 1.4, 148.56], [2, 1.3, 198.07]], "batl": NaN}, {"timestamp": 1631533851212, "ltp": 2.06, "tv": 1401.27, "trd": NaN, "batb": [[1, 1.74, 379.61], [2, 1.4, 148.56]], "batl": [[0, 2.92, 242.8]]}, {"timestamp": 1631533862050, "ltp": 2.06, "tv": 1401.27, "trd": NaN, "batb": [[1, 1.4, 148.56], [2, 1.3, 198.07]], "batl": NaN}, {"timestamp": 1631533864255, "ltp": 2.06, "tv": 1401.27, "trd": NaN, "batb": [[0, 2.22, 32.13], [1, 2.04, 42.09], [2, 1.9, 26.19]], "batl": [[0, 2.28, 9.8], [1, 2.92, 242.8]]}, {"timestamp": 1631533864664, "ltp": 2.26, "tv": 1406.27, "trd": [[2.26, 5]], "batb": [[2, 1.4, 148.56]], "batl": NaN}, {"timestamp": 1631533865557, "ltp": 2.26, "tv": 1406.27, "trd": NaN, "batb": [[2, 1.82, 377.89]], "batl": NaN}, {"timestamp": 1631533888100, "ltp": 2.26, "tv": 1406.27, "trd": NaN, "batb": NaN, "batl": [[0, 2.92, 242.8], [1, 2.92, 0]]}, {"timestamp": 1631533888470, "ltp": 2.26, "tv": 1406.27, "trd": NaN, "batb": [[0, 2.04, 42.09], [1, 1.82, 377.89], [2, 1.4, 148.56]], "batl": NaN}, {"timestamp": 1631533897277, "ltp": 2.04, "tv": 1416.85, "trd": [[2.04, 40.96]], "batb": [[0, 2.04, 36.8]], "batl": [[0, 2.12, 64.8], [1, 2.92, 242.8]]}, {"timestamp": 1631533898207, "ltp": 2.04, "tv": 1416.85, "trd": NaN, "batb": [[0, 2.06, 72.82], [1, 2.04, 73.2], [2, 2.02, 36.4]], "batl": NaN}, {"timestamp": 1631533898415, "ltp": 2.04, "tv": 1416.85, "trd": NaN, "batb": [[0, 2.06, 14.56], [1, 2.04, 44.08], [2, 2.02, 7.28]], "batl": NaN}, {"timestamp": 1631533913525, "ltp": 2.04, "tv": 1416.85, "trd": NaN, "batb": NaN, "batl": [[0, 2.12, 56.6]]}, {"timestamp": 1631533922027, "ltp": 2.04, "tv": 1416.85, "trd": NaN, "batb": [[0, 1.9, 51.97], [1, 1.82, 377.89], [2, 1.4, 148.56]], "batl": [[0, 2.92, 242.8], [1, 2.92, 0]]}, {"timestamp": 1631533931038, "ltp": 2.04, "tv": 1416.85, "trd": NaN, "batb": [[1, 1.4, 148.56], [2, 1.3, 198.07]], "batl": NaN}, {"timestamp": 1631533932143, "ltp": 1.9, "tv": 1427.77, "trd": [[1.9, 108.2]], "batb": [[0, 1.9, 46.51]], "batl": [[0, 1.98, 6.98], [1, 1.99, 60.3], [2, 2.06, 109.11]]}, {"timestamp": 1631533933180, "ltp": 1.9, "tv": 1427.77, "trd": NaN, "batb": [[0, 1.92, 15.62], [1, 1.91, 7.82], [2, 1.9, 54.33]], "batl": NaN}, {"timestamp": 1631533936984, "ltp": 1.98, "tv": 1434.75, "trd": [[1.98, 18.02]], "batb": NaN, "batl": [[0, 1.99, 60.3], [1, 2.06, 109.11], [2, 2.72, 264.63]]}, {"timestamp": 1631533943061, "ltp": 1.99, "tv": 1442.69, "trd": [[1.94, 30.32], [1.99, 7.24]], "batb": NaN, "batl": [[0, 1.99, 53.06]]}, {"timestamp": 1631533949884, "ltp": 1.99, "tv": 1442.69, "trd": NaN, "batb": NaN, "batl": [[1, 2, 4.61], [2, 2.06, 109.11]]}, {"timestamp": 1631533952917, "ltp": 1.99, "tv": 1442.69, "trd": NaN, "batb": [[0, 1.81, 30.38], [1, 1.67, 383.76], [2, 1.4, 148.56]], "batl": [[0, 2.72, 264.63], [1, 2, 0], [2, 2.06, 0]]}, {"timestamp": 1631533961820, "ltp": 1.81, "tv": 1453.93, "trd": [[1.81, 11.24]], "batb": [[0, 1.89, 8.06], [1, 1.81, 24.76], [2, 1.67, 383.76]], "batl": [[0, 1.94, 61.86], [1, 1.95, 46.15], [2, 1.96, 23.08]]}, {"timestamp": 1631533962914, "ltp": 1.81, "tv": 1453.93, "trd": NaN, "batb": [[1, 1.85, 16.22], [2, 1.84, 8.1]], "batl": [[1, 1.95, 15.38], [2, 1.96, 7.7]]}, {"timestamp": 1631533976634, "ltp": 1.81, "tv": 1453.93, "trd": NaN, "batb": [[0, 1.85, 16.22], [1, 1.84, 8.1], [2, 1.83, 8.1]], "batl": NaN}, {"timestamp": 1631534067893, "ltp": 1.81, "tv": 1453.93, "trd": NaN, "batb": [[0, 1.67, 383.76], [1, 1.64, 42.76], [2, 1.4, 148.56]], "batl": [[0, 2.72, 264.63], [1, 1.95, 0], [2, 1.96, 0]]}, {"timestamp": 1631534074484, "ltp": 1.81, "tv": 1453.93, "trd": NaN, "batb": NaN, "batl": [[0, 2.6, 281.81]]}, {"timestamp": 1631534092700, "ltp": 1.81, "tv": 1453.93, "trd": NaN, "batb": [[0, 1.97, 101.52], [1, 1.67, 383.76], [2, 1.64, 42.76]], "batl": [[0, 2.12, 8.65], [1, 2.6, 281.81]]}, {"timestamp": 1631534093626, "ltp": 2.06, "tv": 1459.17, "trd": [[2.06, 21.26]], "batb": [[0, 1.99, 45.52], [1, 1.97, 101.52], [2, 1.79, 31.46]], "batl": [[1, 2.14, 14.02], [2, 2.16, 7]]}, {"timestamp": 1631534104040, "ltp": 2.06, "tv": 1459.17, "trd": NaN, "batb": NaN, "batl": [[0, 2.14, 14.02], [1, 2.16, 7], [2, 2.18, 7]]}, {"timestamp": 1631534106415, "ltp": 2.06, "tv": 1459.17, "trd": NaN, "batb": NaN, "batl": [[0, 2.12, 13.73], [1, 2.14, 14.02], [2, 2.16, 7]]}, {"timestamp": 1631534110947, "ltp": 2.06, "tv": 1459.17, "trd": NaN, "batb": [[1, 1.79, 31.46], [2, 1.67, 383.76]], "batl": [[0, 2.6, 281.81], [1, 2.14, 0], [2, 2.16, 0]]}, {"timestamp": 1631534111367, "ltp": 2.06, "tv": 1459.17, "trd": NaN, "batb": [[0, 1.79, 31.46], [1, 1.67, 383.76], [2, 1.4, 148.56]], "batl": NaN}, {"timestamp": 1631534128870, "ltp": 2.06, "tv": 1459.17, "trd": NaN, "batb": [[1, 1.4, 148.56], [2, 1.3, 198.07]], "batl": NaN}, {"timestamp": 1631534130146, "ltp": 2.06, "tv": 1459.17, "trd": NaN, "batb": NaN, "batl": [[0, 2.28, 6.37]]}, {"timestamp": 1631534131088, "ltp": 2.2, "tv": 1464.07, "trd": [[2.2, 15.23]], "batb": [[0, 2.18, 34.56], [1, 1.99, 45.61], [2, 1.4, 148.56]], "batl": [[1, 2.34, 12.82], [2, 2.36, 6.4]]}, {"timestamp": 1631534132461, "ltp": 2.2, "tv": 1464.07, "trd": NaN, "batb": [[2, 1.82, 377.89]], "batl": NaN}, {"timestamp": 1631534142072, "ltp": 2.2, "tv": 1464.07, "trd": NaN, "batb": [[0, 1.99, 45.61], [1, 1.82, 377.89], [2, 1.4, 148.56]], "batl": [[0, 3.15, 220.27], [1, 2.34, 0], [2, 2.36, 0]]}, {"timestamp": 1631534147786, "ltp": 2.2, "tv": 1464.07, "trd": NaN, "batb": NaN, "batl": [[0, 3, 234.38]]}, {"timestamp": 1631534160114, "ltp": 1.99, "tv": 1474.55, "trd": [[1.99, 17.72]], "batb": [[0, 2, 67.66], [1, 1.99, 40.37], [2, 1.82, 377.89]], "batl": [[0, 2.12, 84.34], [1, 2.14, 35.38], [2, 2.16, 124.78]]}, {"timestamp": 1631534161123, "ltp": 1.99, "tv": 1474.55, "trd": NaN, "batb": NaN, "batl": [[0, 2.12, 27.74], [1, 2.14, 7.08], [2, 2.16, 96.48]]}, {"timestamp": 1631534178880, "ltp": 1.99, "tv": 1474.55, "trd": NaN, "batb": [[0, 1.82, 377.89], [1, 1.77, 32.8], [2, 1.4, 148.56]], "batl": [[0, 2.82, 253.59], [1, 2.14, 0], [2, 2.16, 0]]}, {"timestamp": 1631534189970, "ltp": 1.99, "tv": 1474.55, "trd": NaN, "batb": [[0, 2.22, 13.52], [1, 2.2, 6.76], [2, 2.18, 6.76]], "batl": NaN}, {"timestamp": 1631534190918, "ltp": 2.24, "tv": 1479.4, "trd": [[2.24, 4.85]], "batb": [[1, 2.2, 39.81]], "batl": NaN}, {"timestamp": 1631534193703, "ltp": 2.24, "tv": 1479.4, "trd": NaN, "batb": NaN, "batl": [[0, 3.15, 220.27]]}, {"timestamp": 1631534203703, "ltp": 2.24, "tv": 1479.4, "trd": NaN, "batb": [[0, 2.24, 8.8], [1, 2.22, 13.52], [2, 2.2, 39.81]], "batl": NaN}, {"timestamp": 1631534206220, "ltp": 2.24, "tv": 1479.4, "trd": NaN, "batb": [[0, 2.02, 43.1], [1, 1.82, 377.89], [2, 1.4, 148.56]], "batl": NaN}, {"timestamp": 1631534221623, "ltp": 2.02, "tv": 1489.7, "trd": [[2.02, 10.3]], "batb": [[0, 2.08, 7.07], [1, 2.02, 37.95], [2, 1.82, 377.89]], "batl": [[0, 2.12, 7.52], [1, 2.16, 97.22], [2, 2.18, 20.83]]}, {"timestamp": 1631534223141, "ltp": 2.02, "tv": 1489.7, "trd": NaN, "batb": NaN, "batl": [[1, 2.16, 69.44], [2, 2.18, 6.94]]}, {"timestamp": 1631534225028, "ltp": 2.12, "tv": 1504.28, "trd": [[2.12, 14.58]], "batb": NaN, "batl": [[0, 2.16, 69.67], [1, 2.18, 6.94], [2, 2.2, 6.94]]}, {"timestamp": 1631534226435, "ltp": 2.12, "tv": 1504.51, "trd": [[2.12, 14.81]], "batb": NaN, "batl": [[0, 2.16, 69.44]]}, {"timestamp": 1631534234029, "ltp": 2.12, "tv": 1504.51, "trd": NaN, "batb": [[0, 1.82, 377.89], [1, 1.76, 33.72], [2, 1.4, 148.56]], "batl": [[0, 2.92, 242.8], [1, 880, 0.01], [2, 2.2, 0]]}, {"timestamp": 1631534237247, "ltp": 2.12, "tv": 1504.51, "trd": NaN, "batb": [[1, 1.75, 33.81]], "batl": NaN}, {"timestamp": 1631534241968, "ltp": 2.12, "tv": 1504.51, "trd": NaN, "batb": [[2, 1.19, 1]], "batl": NaN}, {"timestamp": 1631534267073, "ltp": 2.12, "tv": 1504.51, "trd": NaN, "batb": [[0, 1.75, 33.81], [1, 1.19, 1], [2, 1.03, 494.08]], "batl": [[0, 880, 0.01], [1, 880, 0]]}, {"timestamp": 1631534268112, "ltp": 2.12, "tv": 1504.51, "trd": NaN, "batb": NaN, "batl": [[0, 2.4, 6.28], [1, 2.5, 115.07], [2, 880, 0.01]]}, {"timestamp": 1631534269206, "ltp": 2.34, "tv": 1509.18, "trd": [[2.34, 4.67]], "batb": [[0, 2.32, 28.79], [1, 2.18, 34.06], [2, 1.19, 1]], "batl": [[1, 2.44, 12.3], [2, 2.46, 6.14]]}, {"timestamp": 1631534270201, "ltp": 2.34, "tv": 1509.18, "trd": NaN, "batb": [[2, 1.75, 3061.22]], "batl": NaN}, {"timestamp": 1631534271088, "ltp": 2.34, "tv": 1509.18, "trd": NaN, "batb": [[2, 1.92, 373.16]], "batl": NaN}, {"timestamp": 1631534279134, "ltp": 2.34, "tv": 1509.18, "trd": NaN, "batb": NaN, "batl": [[0, 2.44, 12.3], [1, 2.46, 6.14], [2, 2.48, 6.14]]}, {"timestamp": 1631534281997, "ltp": 2.34, "tv": 1509.18, "trd": NaN, "batb": [[0, 2.32, 38.86]], "batl": NaN}, {"timestamp": 1631534284210, "ltp": 2.32, "tv": 1511.94, "trd": [[2.32, 2.76]], "batb": [[0, 2.32, 37.48]], "batl": NaN}, {"timestamp": 1631534289819, "ltp": 2.46, "tv": 1553.9, "trd": [[2.4, 8.04], [2.44, 24.6], [2.46, 9.32]], "batb": NaN, "batl": [[0, 2.46, 1.48], [1, 2.48, 6.14], [2, 2.5, 115.07]]}, {"timestamp": 1631534293232, "ltp": 2.32, "tv": 1572.86, "trd": [[2.32, 21.72]], "batb": [[0, 2.32, 18.51]], "batl": NaN}, {"timestamp": 1631534297134, "ltp": 2.46, "tv": 1574.24, "trd": [[2.46, 10.7]], "batb": [[0, 2.32, 10.07], [1, 2.3, 29.2], [2, 2.18, 34.06]], "batl": [[0, 2.48, 6.24], [1, 2.5, 115.07], [2, 3.45, 198.52]]}, {"timestamp": 1631534299926, "ltp": 2.46, "tv": 1574.24, "trd": NaN, "batb": [[0, 2.3, 29.2], [1, 2.18, 34.06], [2, 1.92, 373.16]], "batl": NaN}, {"timestamp": 1631534303253, "ltp": 2.46, "tv": 1574.24, "trd": NaN, "batb": [[0, 2.36, 7.49], [1, 2.3, 29.2], [2, 2.18, 34.06]], "batl": [[0, 2.42, 7.72], [1, 2.48, 6.24], [2, 2.5, 115.07]]}, {"timestamp": 1631534309484, "ltp": 2.46, "tv": 1574.24, "trd": NaN, "batb": [[2, 2.16, 34.81]], "batl": NaN}, {"timestamp": 1631534310854, "ltp": 2.42, "tv": 1581.96, "trd": [[2.42, 7.72]], "batb": NaN, "batl": [[0, 2.48, 6.24], [1, 2.5, 115.07], [2, 3.45, 198.52]]}, {"timestamp": 1631534320755, "ltp": 2.42, "tv": 1581.96, "trd": NaN, "batb": [[0, 2.3, 29.2], [1, 2.16, 34.81], [2, 1.92, 373.16]], "batl": NaN}, {"timestamp": 1631534323789, "ltp": 2.42, "tv": 1581.96, "trd": NaN, "batb": NaN, "batl": [[0, 2.46, 9.67], [1, 2.48, 6.14], [2, 2.5, 115.07]]}, {"timestamp": 1631534325786, "ltp": 2.46, "tv": 1589.64, "trd": [[2.46, 18.38]], "batb": NaN, "batl": [[0, 2.46, 1.99]]}, {"timestamp": 1631534335997, "ltp": 2.48, "tv": 1596.61, "trd": [[2.46, 20.37], [2.48, 4.98]], "batb": NaN, "batl": [[0, 2.48, 1.16], [1, 2.5, 115.07], [2, 3.45, 198.52]]}, {"timestamp": 1631534338872, "ltp": 2.48, "tv": 1596.61, "trd": NaN, "batb": [[0, 2.42, 7.71], [1, 2.3, 29.2], [2, 2.16, 34.81]], "batl": [[1, 2.5, 126.24]]}, {"timestamp": 1631534346232, "ltp": 2.48, "tv": 1596.61, "trd": NaN, "batb": [[0, 2.3, 29.2], [1, 2.16, 34.81], [2, 1.92, 373.16]], "batl": [[1, 2.5, 115.07]]}, {"timestamp": 1631534349122, "ltp": 2.48, "tv": 1596.61, "trd": NaN, "batb": NaN, "batl": [[1, 2.5, 124.29]]}, {"timestamp": 1631534356445, "ltp": 2.48, "tv": 1597.77, "trd": [[2.48, 6.14]], "batb": NaN, "batl": [[0, 2.5, 124.29], [1, 3.45, 198.52], [2, 990, 0.01]]}, {"timestamp": 1631534370742, "ltp": 2.5, "tv": 1598.32, "trd": [[2.5, 0.55]], "batb": NaN, "batl": [[0, 2.5, 123.74]]}, {"timestamp": 1631534399392, "ltp": 2.5, "tv": 1598.32, "trd": NaN, "batb": NaN, "batl": [[1, 990, 0.01], [2, 990, 0]]}, {"timestamp": 1631534402099, "ltp": 2.5, "tv": 1598.32, "trd": NaN, "batb": [[2, 1.19, 1]], "batl": NaN}, {"timestamp": 1631534404323, "ltp": 2.5, "tv": 1598.32, "trd": NaN, "batb": NaN, "batl": [[1, 3, 234.38], [2, 990, 0.01]]}, {"timestamp": 1631534405322, "ltp": 2.5, "tv": 1598.32, "trd": NaN, "batb": [[2, 1.77, 378.13]], "batl": NaN}, {"timestamp": 1631534408024, "ltp": 2.5, "tv": 1598.32, "trd": NaN, "batb": [[0, 2.16, 34.81], [1, 1.77, 378.13], [2, 1.19, 1]], "batl": [[0, 3, 234.38], [1, 990, 0.01], [2, 990, 0]]}, {"timestamp": 1631534420959, "ltp": 2.16, "tv": 1608.13, "trd": [[2.16, 15.01]], "batb": [[0, 2.16, 29.91]], "batl": [[0, 2.38, 50.42], [1, 2.4, 37.5], [2, 2.42, 18.74]]}, {"timestamp": 1631534422064, "ltp": 2.16, "tv": 1608.13, "trd": NaN, "batb": [[1, 2.06, 40.25], [2, 1.77, 378.13]], "batl": [[1, 2.4, 12.5], [2, 2.42, 6.24]]}, {"timestamp": 1631534433660, "ltp": 2.16, "tv": 1608.13, "trd": NaN, "batb": NaN, "batl": [[0, 2.3, 2.56], [1, 2.38, 50.42], [2, 2.4, 12.5]]}, {"timestamp": 1631534439079, "ltp": 2.16, "tv": 1608.13, "trd": NaN, "batb": NaN, "batl": [[1, 3, 234.38], [2, 990, 0.01]]}, {"timestamp": 1631534439456, "ltp": 2.16, "tv": 1608.13, "trd": NaN, "batb": [[0, 2.06, 40.25], [1, 1.77, 378.13], [2, 1.19, 1]], "batl": NaN}, {"timestamp": 1631534448200, "ltp": 2.06, "tv": 1618.29, "trd": [[2.06, 31.42]], "batb": [[0, 2.06, 35.17]], "batl": [[0, 2.2, 85.61], [1, 2.24, 14.1]]}, {"timestamp": 1631534449201, "ltp": 2.06, "tv": 1618.29, "trd": NaN, "batb": [[1, 1.98, 45.86], [2, 1.77, 378.13]], "batl": NaN}, {"timestamp": 1631534451192, "ltp": 2.06, "tv": 1618.29, "trd": NaN, "batb": NaN, "batl": [[2, 2.72, 264.63]]}, {"timestamp": 1631534453191, "ltp": 2.06, "tv": 1618.29, "trd": NaN, "batb": NaN, "batl": [[2, 2.28, 46.11]]}, {"timestamp": 1631534453400, "ltp": 2.06, "tv": 1618.29, "trd": NaN, "batb": NaN, "batl": [[2, 2.72, 264.63]]}, {"timestamp": 1631534456381, "ltp": 2.06, "tv": 1618.29, "trd": NaN, "batb": [[0, 2.06, 118.66]], "batl": NaN}, {"timestamp": 1631534464608, "ltp": 2.06, "tv": 1618.29, "trd": NaN, "batb": [[0, 1.98, 45.86], [1, 1.77, 378.13], [2, 1.19, 1]], "batl": [[0, 2.72, 264.63], [1, 990, 0.01], [2, 2.72, 0]]}, {"timestamp": 1631534487073, "ltp": 2.06, "tv": 1618.29, "trd": NaN, "batb": [[0, 2.24, 40.18], [1, 2.22, 20.09], [2, 2.2, 20.09]], "batl": NaN}, {"timestamp": 1631534487965, "ltp": 2.28, "tv": 1623.14, "trd": [[2.28, 9.8]], "batb": NaN, "batl": [[0, 2.38, 12.6], [1, 2.4, 6.3], [2, 2.42, 6.3]]}, {"timestamp": 1631534511921, "ltp": 2.28, "tv": 1623.14, "trd": NaN, "batb": [[0, 2.06, 40.92], [1, 1.77, 378.13], [2, 1.19, 1]], "batl": [[0, 2.72, 264.63], [1, 990, 0.01], [2, 2.42, 0]]}, {"timestamp": 1631534522140, "ltp": 2.06, "tv": 1633.3, "trd": [[2.06, 41.59]], "batb": [[0, 2.16, 6.85], [1, 2.06, 35.84], [2, 1.77, 378.13]], "batl": [[0, 2.2, 6.35], [1, 2.26, 66.36], [2, 2.28, 33.18]]}, {"timestamp": 1631534523235, "ltp": 2.06, "tv": 1633.3, "trd": NaN, "batb": [[2, 1.98, 45.86]], "batl": [[1, 2.26, 39.82], [2, 2.28, 19.91]]}, {"timestamp": 1631534523450, "ltp": 2.06, "tv": 1633.3, "trd": NaN, "batb": NaN, "batl": [[1, 2.26, 13.28], [2, 2.28, 6.64]]}, {"timestamp": 1631534527163, "ltp": 2.06, "tv": 1633.3, "trd": NaN, "batb": NaN, "batl": [[2, 2.28, 66.91]]}, {"timestamp": 1631534527336, "ltp": 2.06, "tv": 1633.3, "trd": NaN, "batb": NaN, "batl": [[2, 2.28, 6.64]]}, {"timestamp": 1631534541272, "ltp": 2.06, "tv": 1633.3, "trd": NaN, "batb": [[0, 2.06, 35.84], [1, 1.98, 45.86], [2, 1.77, 378.13]], "batl": [[0, 2.72, 264.63], [1, 990, 0.01], [2, 2.28, 0]]}, {"timestamp": 1631534541683, "ltp": 2.06, "tv": 1633.3, "trd": NaN, "batb": [[0, 1.98, 45.86], [1, 1.77, 378.13], [2, 1.19, 1]], "batl": NaN}, {"timestamp": 1631534548003, "ltp": 2.06, "tv": 1633.3, "trd": NaN, "batb": [[0, 2.24, 66.96], [1, 2.22, 33.48], [2, 2.2, 33.48]], "batl": NaN}, {"timestamp": 1631534549101, "ltp": 2.24, "tv": 1643.0, "trd": [[2.24, 14.55]], "batb": [[0, 2.24, 35.33], [1, 2.22, 20.09], [2, 2.2, 20.09]], "batl": [[0, 2.38, 37.82], [1, 2.4, 18.91], [2, 2.42, 18.91]]}, {"timestamp": 1631534549476, "ltp": 2.24, "tv": 1643.0, "trd": NaN, "batb": [[0, 2.24, 8.55], [1, 2.22, 6.7], [2, 2.2, 6.7]], "batl": [[0, 2.38, 12.6], [1, 2.4, 6.3], [2, 2.42, 6.3]]}, {"timestamp": 1631534568117, "ltp": 2.24, "tv": 1643.0, "trd": NaN, "batb": [[0, 2.02, 42.34], [1, 1.77, 378.13], [2, 1.19, 1]], "batl": [[0, 2.72, 264.63], [1, 990, 0.01], [2, 2.42, 0]]}, {"timestamp": 1631534571081, "ltp": 2.24, "tv": 1643.0, "trd": NaN, "batb": NaN, "batl": [[0, 2.62, 99.82], [1, 2.72, 264.63], [2, 990, 0.01]]}, {"timestamp": 1631534571471, "ltp": 2.24, "tv": 1643.0, "trd": NaN, "batb": NaN, "batl": [[0, 2.72, 264.63], [1, 990, 0.01], [2, 990, 0]]}, {"timestamp": 1631534576236, "ltp": 2.24, "tv": 1643.0, "trd": NaN, "batb": [[0, 2.44, 61.48], [1, 2.42, 30.74], [2, 2.4, 30.74]], "batl": [[0, 2.6, 103.31]]}, {"timestamp": 1631534577229, "ltp": 2.5, "tv": 1647.5, "trd": [[2.5, 5.05]], "batb": [[0, 2.44, 36.89], [1, 2.42, 18.44], [2, 2.4, 18.44]], "batl": [[0, 2.6, 160.99], [1, 2.62, 28.84], [2, 2.64, 28.84]]}, {"timestamp": 1631534577547, "ltp": 2.5, "tv": 1647.5, "trd": NaN, "batb": NaN, "batl": [[0, 2.6, 114.85], [1, 2.62, 5.76], [2, 2.64, 5.76]]}, {"timestamp": 1631534587269, "ltp": 2.5, "tv": 1647.5, "trd": NaN, "batb": NaN, "batl": [[0, 2.6, 103.46]]}, {"timestamp": 1631534590152, "ltp": 2.5, "tv": 1647.5, "trd": NaN, "batb": [[0, 2.5, 5.53], [1, 2.44, 36.89], [2, 2.42, 18.44]], "batl": [[0, 2.56, 7.54], [1, 2.6, 103.46], [2, 2.62, 5.76]]}, {"timestamp": 1631534595274, "ltp": 2.5, "tv": 1647.5, "trd": NaN, "batb": [[0, 2.38, 26.69], [1, 2.18, 34.14], [2, 1.77, 378.13]], "batl": [[0, 3.15, 220.27], [1, 990, 0.01], [2, 2.62, 0]]}, {"timestamp": 1631534595793, "ltp": 2.5, "tv": 1647.5, "trd": NaN, "batb": [[0, 2.18, 34.14], [1, 1.77, 378.13], [2, 1.19, 1]], "batl": NaN}, {"timestamp": 1631534602059, "ltp": 2.5, "tv": 1647.5, "trd": NaN, "batb": NaN, "batl": [[0, 990, 0.01], [1, 990, 0]]}, {"timestamp": 1631534603276, "ltp": 2.18, "tv": 1657.2, "trd": [[2.18, 9.7]], "batb": [[0, 2.18, 29.29]], "batl": [[0, 2.32, 86.2], [1, 2.36, 1288.86], [2, 2.38, 63.04]]}, {"timestamp": 1631534604279, "ltp": 2.18, "tv": 1657.2, "trd": NaN, "batb": [[1, 2.04, 41.17], [2, 1.77, 378.13]], "batl": [[0, 2.32, 51.72], [1, 2.38, 37.82], [2, 2.4, 18.91]]}, {"timestamp": 1631534605165, "ltp": 2.18, "tv": 1657.2, "trd": NaN, "batb": NaN, "batl": [[1, 2.38, 12.6], [2, 2.4, 6.3]]}, {"timestamp": 1631534616416, "ltp": 2.22, "tv": 1677.2, "trd": [[2.22, 5.01], [2.24, 29.54]], "batb": NaN, "batl": NaN}, {"timestamp": 1631534626026, "ltp": 2.22, "tv": 1677.2, "trd": NaN, "batb": [[0, 2.04, 41.17], [1, 1.77, 378.13], [2, 1.19, 1]], "batl": [[0, 2.82, 253.59], [1, 990, 0.01], [2, 2.4, 0]]}, {"timestamp": 1631534640047, "ltp": 2.04, "tv": 1687.31, "trd": [[2.04, 51.06]], "batb": [[0, 2.06, 87.06], [1, 2.04, 36.12], [2, 1.77, 378.13]], "batl": [[0, 2.16, 15.25], [1, 2.2, 54.54], [2, 2.82, 253.59]]}, {"timestamp": 1631534641059, "ltp": 2.04, "tv": 1687.31, "trd": NaN, "batb": [[2, 1.92, 50.79]], "batl": NaN}, {"timestamp": 1631534644972, "ltp": 2.16, "tv": 1702.56, "trd": [[2.16, 30.26]], "batb": NaN, "batl": [[0, 2.2, 54.54], [1, 2.82, 253.59], [2, 990, 0.01]]}, {"timestamp": 1631534649070, "ltp": 2.16, "tv": 1702.56, "trd": NaN, "batb": [[2, 1.91, 50.96]], "batl": NaN}, {"timestamp": 1631534657873, "ltp": 2.16, "tv": 1702.56, "trd": NaN, "batb": NaN, "batl": [[0, 2.2, 67.6]]}, {"timestamp": 1631534710102, "ltp": 2.16, "tv": 1702.56, "trd": NaN, "batb": [[0, 1.91, 50.96], [1, 1.77, 378.13], [2, 1.19, 1]], "batl": [[0, 2.82, 253.59], [1, 990, 0.01], [2, 990, 0]]}, {"timestamp": 1631534718104, "ltp": 2.16, "tv": 1702.56, "trd": NaN, "batb": [[1, 1.19, 1], [2, 1.01, 113.7]], "batl": [[0, 990, 0.01], [1, 990, 0]]}, {"timestamp": 1631534720205, "ltp": 1.91, "tv": 1713.26, "trd": [[1.91, 10.7]], "batb": [[0, 1.91, 45.61]], "batl": [[0, 2.04, 14.34], [1, 2.06, 72.82], [2, 2.08, 36.4]]}, {"timestamp": 1631534721090, "ltp": 1.91, "tv": 1713.26, "trd": NaN, "batb": [[0, 1.95, 104.73], [1, 1.94, 38.46], [2, 1.93, 38.46]], "batl": NaN}, {"timestamp": 1631534721827, "ltp": 1.91, "tv": 1713.26, "trd": NaN, "batb": [[0, 1.95, 43.19], [1, 1.94, 7.7], [2, 1.93, 7.7]], "batl": [[1, 2.06, 14.56], [2, 2.08, 7.28]]}, {"timestamp": 1631534725916, "ltp": 1.91, "tv": 1713.26, "trd": NaN, "batb": [[0, 1.79, 31.38], [1, 1.58, 388.69], [2, 1.19, 1]], "batl": [[0, 2.5, 299.95], [1, 990, 0.01], [2, 2.08, 0]]}, {"timestamp": 1631534753859, "ltp": 1.91, "tv": 1713.26, "trd": NaN, "batb": [[1, 1.19, 1], [2, 1.01, 113.7]], "batl": NaN}, {"timestamp": 1631534755174, "ltp": 1.91, "tv": 1713.26, "trd": NaN, "batb": NaN, "batl": [[0, 2.16, 8.05], [1, 2.2, 131.92], [2, 2.5, 299.95]]}, {"timestamp": 1631534756171, "ltp": 2.1, "tv": 1718.36, "trd": [[2.1, 5.1]], "batb": [[0, 2.02, 42.93], [1, 1.89, 26.78], [2, 1.19, 1]], "batl": NaN}, {"timestamp": 1631534757379, "ltp": 2.1, "tv": 1718.36, "trd": NaN, "batb": [[2, 1.67, 383.76]], "batl": NaN}, {"timestamp": 1631534771003, "ltp": 2.1, "tv": 1718.36, "trd": NaN, "batb": [[0, 1.89, 26.78], [1, 1.67, 383.76], [2, 1.19, 1]], "batl": [[0, 2.5, 299.95], [1, 990, 0.01], [2, 2.5, 0]]}, {"timestamp": 1631534789221, "ltp": 1.89, "tv": 1729.22, "trd": [[1.89, 44.72]], "batb": [[0, 1.89, 21.34]], "batl": [[0, 2.02, 1705.1], [1, 2.04, 37.14], [2, 2.06, 134.22]]}, {"timestamp": 1631534790224, "ltp": 1.89, "tv": 1729.22, "trd": NaN, "batb": [[0, 1.92, 28.24], [1, 1.91, 78.52], [2, 1.9, 39.26]], "batl": [[0, 2.02, 184.4], [1, 2.04, 22.28], [2, 2.06, 80.53]]}, {"timestamp": 1631534790523, "ltp": 1.89, "tv": 1729.22, "trd": NaN, "batb": [[1, 1.91, 15.7], [2, 1.9, 7.86]], "batl": [[0, 2.02, 154.7], [1, 2.04, 7.42], [2, 2.06, 65.67]]}, {"timestamp": 1631534806440, "ltp": 1.89, "tv": 1729.22, "trd": NaN, "batb": [[0, 1.91, 15.7], [1, 1.9, 7.86], [2, 1.89, 29.2]], "batl": NaN}, {"timestamp": 1631534807850, "ltp": 1.89, "tv": 1729.22, "trd": NaN, "batb": NaN, "batl": [[0, 2, 4.2], [1, 2.02, 154.7], [2, 2.04, 7.42]]}, {"timestamp": 1631534811245, "ltp": 1.89, "tv": 1729.22, "trd": NaN, "batb": [[0, 1.75, 34.06], [1, 1.67, 383.76], [2, 1.19, 1]], "batl": [[0, 2.5, 299.95], [1, 990, 0.01], [2, 2.04, 0]]}, {"timestamp": 1631534837288, "ltp": 1.89, "tv": 1729.22, "trd": NaN, "batb": [[0, 2, 163.66], [1, 1.75, 34.06], [2, 1.67, 383.76]], "batl": [[0, 2.16, 99], [1, 2.5, 299.95], [2, 990, 0.01]]}, {"timestamp": 1631534838280, "ltp": 2.12, "tv": 1739.48, "trd": [[2.12, 25.07]], "batb": [[0, 2.12, 1.47], [1, 2, 163.66], [2, 1.75, 34.06]], "batl": [[0, 2.16, 106.29]]}, {"timestamp": 1631534838655, "ltp": 2.12, "tv": 1739.48, "trd": NaN, "batb": [[1, 2, 208.09], [2, 1.84, 28.87]], "batl": NaN}, {"timestamp": 1631534840102, "ltp": 2.12, "tv": 1739.48, "trd": NaN, "batb": [[0, 2, 144.43], [1, 1.84, 28.87], [2, 1.67, 383.76]], "batl": [[0, 2.5, 299.95], [1, 990, 0.01], [2, 990, 0]]}, {"timestamp": 1631534840775, "ltp": 2.12, "tv": 1739.48, "trd": NaN, "batb": [[0, 2, 100]], "batl": NaN}, {"timestamp": 1631534845177, "ltp": 2.12, "tv": 1739.48, "trd": NaN, "batb": NaN, "batl": [[0, 2.12, 2.72], [1, 2.5, 299.95], [2, 990, 0.01]]}, {"timestamp": 1631534852193, "ltp": 2.12, "tv": 1739.48, "trd": NaN, "batb": [[0, 1.84, 28.87], [1, 1.67, 383.76], [2, 1.19, 1]], "batl": NaN}, {"timestamp": 1631534858122, "ltp": 2.12, "tv": 1739.48, "trd": NaN, "batb": NaN, "batl": [[1, 990, 0.01], [2, 990, 0]]}, {"timestamp": 1631534858602, "ltp": 2.12, "tv": 1739.48, "trd": NaN, "batb": NaN, "batl": [[0, 990, 0.01], [1, 990, 0]]}, {"timestamp": 1631534860223, "ltp": 2.12, "tv": 1739.48, "trd": NaN, "batb": [[0, 2.18, 91.74], [1, 1.84, 28.87], [2, 1.67, 383.76]], "batl": [[0, 2.36, 87.58], [1, 990, 0.01]]}, {"timestamp": 1631534861212, "ltp": 2.28, "tv": 1744.29, "trd": [[2.28, 14.61]], "batb": [[1, 2.16, 34.81], [2, 1.99, 45.61]], "batl": [[0, 2.34, 64.1], [1, 2.36, 119.62], [2, 2.38, 32.04]]}, {"timestamp": 1631534862130, "ltp": 2.28, "tv": 1744.29, "trd": NaN, "batb": NaN, "batl": [[0, 2.34, 12.82], [1, 2.36, 93.98], [2, 2.38, 6.4]]}, {"timestamp": 1631534874219, "ltp": 2.28, "tv": 1744.29, "trd": NaN, "batb": [[0, 2.16, 34.81], [1, 1.99, 45.61], [2, 1.67, 383.76]], "batl": [[0, 2.82, 253.59], [1, 990, 0.01], [2, 2.38, 0]]}, {"timestamp": 1631534874530, "ltp": 2.28, "tv": 1744.29, "trd": NaN, "batb": [[0, 1.99, 45.61], [1, 1.67, 383.76], [2, 1.19, 1]], "batl": NaN}, {"timestamp": 1631534882636, "ltp": 2.28, "tv": 1744.29, "trd": NaN, "batb": NaN, "batl": [[0, 990, 0.01], [1, 990, 0]]}, {"timestamp": 1631534883951, "ltp": 1.99, "tv": 1754.6, "trd": [[1.99, 28.02]], "batb": [[0, 2, 47.21], [1, 1.99, 40.45], [2, 1.67, 383.76]], "batl": [[0, 2.1, 95.24], [1, 2.12, 8.14], [2, 990, 0.01]]}, {"timestamp": 1631534885157, "ltp": 1.99, "tv": 1754.6, "trd": NaN, "batb": [[2, 1.82, 29.96]], "batl": NaN}, {"timestamp": 1631534886150, "ltp": 1.99, "tv": 1754.6, "trd": NaN, "batb": NaN, "batl": [[2, 2.6, 281.81]]}, {"timestamp": 1631534888970, "ltp": 2.1, "tv": 1781.04, "trd": [[2.1, 31.54]], "batb": NaN, "batl": [[0, 2.1, 68.8]]}, {"timestamp": 1631534900082, "ltp": 2.1, "tv": 1781.04, "trd": NaN, "batb": [[0, 1.82, 29.96], [1, 1.67, 383.76], [2, 1.19, 1]], "batl": [[0, 2.6, 281.81], [1, 990, 0.01], [2, 2.6, 0]]}, {"timestamp": 1631534919205, "ltp": 2.1, "tv": 1781.04, "trd": NaN, "batb": [[1, 1.19, 1], [2, 1.01, 113.7]], "batl": [[0, 990, 0.01], [1, 990, 0]]}, {"timestamp": 1631534921816, "ltp": 1.82, "tv": 1792.22, "trd": [[1.82, 22.6]], "batb": [[0, 1.87, 29], [1, 1.82, 24.36], [2, 1.19, 1]], "batl": [[0, 1.92, 12.15], [1, 1.94, 125.73], [2, 1.95, 7.74]]}, {"timestamp": 1631534922909, "ltp": 1.82, "tv": 1792.22, "trd": NaN, "batb": [[1, 1.84, 16.3], [2, 1.83, 8.16]], "batl": NaN}, {"timestamp": 1631534926509, "ltp": 1.92, "tv": 1804.37, "trd": [[1.92, 12.15]], "batb": NaN, "batl": [[0, 1.94, 125.73], [1, 1.95, 7.74], [2, 1.96, 7.74]]}, {"timestamp": 1631534933130, "ltp": 1.92, "tv": 1804.37, "trd": NaN, "batb": [[1, 1.82, 24.36], [2, 1.67, 40.08]], "batl": [[0, 2.42, 312.73], [1, 990, 0.01], [2, 1.96, 0]]}, {"timestamp": 1631534933550, "ltp": 1.92, "tv": 1804.37, "trd": NaN, "batb": [[0, 1.67, 40.08], [1, 1.55, 392.04], [2, 1.19, 1]], "batl": NaN}, {"timestamp": 1631534938732, "ltp": 1.92, "tv": 1804.37, "trd": NaN, "batb": [[1, 1.19, 1], [2, 1.01, 113.7]], "batl": NaN}, {"timestamp": 1631534939839, "ltp": 1.92, "tv": 1804.37, "trd": NaN, "batb": [[0, 1.89, 377.95], [1, 1.67, 40.08], [2, 1.19, 1]], "batl": [[0, 2.16, 139.79], [1, 2.42, 312.73], [2, 990, 0.01]]}, {"timestamp": 1631534940947, "ltp": 2.06, "tv": 1809.55, "trd": [[2.06, 46.77]], "batb": [[0, 1.97, 46.61], [1, 1.89, 377.95], [2, 1.81, 30.38]], "batl": [[0, 2.14, 14.02], [1, 2.16, 146.79], [2, 2.18, 7]]}, {"timestamp": 1631534942540, "ltp": 2.06, "tv": 1809.55, "trd": NaN, "batb": NaN, "batl": [[1, 2.16, 161.82]]}, {"timestamp": 1631534953285, "ltp": 2.06, "tv": 1809.55, "trd": NaN, "batb": [[1, 1.81, 30.38], [2, 1.62, 388.38]], "batl": [[0, 2.42, 312.73], [1, 990, 0.01], [2, 2.18, 0]]}, {"timestamp": 1631534954072, "ltp": 2.06, "tv": 1809.55, "trd": NaN, "batb": [[0, 1.81, 30.38], [1, 1.19, 1], [2, 1.01, 113.7]], "batl": [[0, 990, 0.11], [1, 990, 0]]}, {"timestamp": 1631534970779, "ltp": 2.08, "tv": 1809.65, "trd": [[2.08, 5.59]], "batb": [[0, 2.22, 40.54], [1, 2.2, 20.27], [2, 2.18, 20.27]], "batl": [[0, 990, 0.01]]}, {"timestamp": 1631534971813, "ltp": 2.28, "tv": 1814.46, "trd": [[2.28, 19.42]], "batb": [[0, 2.22, 13.52], [1, 2.2, 6.76], [2, 2.18, 6.76]], "batl": NaN}, {"timestamp": 1631535006290, "ltp": 2.28, "tv": 1814.46, "trd": NaN, "batb": NaN, "batl": [[0, 2.28, 8.75], [1, 990, 0.01]]}, {"timestamp": 1631535013091, "ltp": 2.28, "tv": 1814.46, "trd": NaN, "batb": [[0, 1.95, 47.87], [1, 1.19, 1], [2, 1.01, 113.7]], "batl": [[0, 990, 0.01], [1, 990, 0]]}, {"timestamp": 1631535021087, "ltp": 2.28, "tv": 1814.46, "trd": NaN, "batb": [[0, 2.4, 5.77], [1, 2.36, 84.74], [2, 2.34, 64.1]], "batl": [[0, 2.46, 8.68], [1, 990, 0.01]]}, {"timestamp": 1631535022085, "ltp": 2.4, "tv": 1823.56, "trd": [[2.4, 17.14]], "batb": [[0, 2.4, 1.22], [2, 2.34, 12.82]], "batl": [[1, 2.5, 60], [2, 2.52, 30]]}, {"timestamp": 1631535022398, "ltp": 2.4, "tv": 1823.56, "trd": NaN, "batb": NaN, "batl": [[1, 2.5, 12], [2, 2.52, 6]]}, {"timestamp": 1631535032691, "ltp": 2.4, "tv": 1823.56, "trd": NaN, "batb": [[0, 2.36, 84.74], [1, 2.34, 12.82], [2, 2.32, 94.55]], "batl": [[0, 2.4, 7.23]]}, {"timestamp": 1631535035230, "ltp": 2.4, "tv": 1823.56, "trd": NaN, "batb": [[0, 2.36, 96.22]], "batl": NaN}, {"timestamp": 1631535041221, "ltp": 2.36, "tv": 1841.99, "trd": [[2.36, 18.43]], "batb": [[0, 2.36, 77.79]], "batl": NaN}, {"timestamp": 1631535043845, "ltp": 2.36, "tv": 1847.1, "trd": [[2.36, 23.54]], "batb": [[0, 2.36, 75.24]], "batl": [[0, 2.5, 12], [1, 2.52, 6], [2, 2.54, 6]]}, {"timestamp": 1631535048145, "ltp": 2.36, "tv": 1854.31, "trd": [[2.36, 30.75]], "batb": [[0, 2.36, 68.03]], "batl": NaN}, {"timestamp": 1631535057053, "ltp": 2.36, "tv": 1854.31, "trd": NaN, "batb": [[0, 2.16, 35.15], [1, 1.19, 1], [2, 1.01, 113.7]], "batl": [[0, 990, 0.01], [1, 2.52, 0], [2, 2.54, 0]]}, {"timestamp": 1631535067277, "ltp": 2.16, "tv": 1863.83, "trd": [[2.16, 39.79]], "batb": [[0, 2.16, 30.38]], "batl": [[0, 2.28, 7.16], [1, 2.32, 64.66], [2, 2.34, 32.32]]}, {"timestamp": 1631535068061, "ltp": 2.16, "tv": 1863.83, "trd": NaN, "batb": [[1, 2.04, 41.51], [2, 1.19, 1]], "batl": [[1, 2.32, 38.8], [2, 2.34, 19.39]]}, {"timestamp": 1631535068375, "ltp": 2.16, "tv": 1863.83, "trd": NaN, "batb": NaN, "batl": [[1, 2.32, 12.94], [2, 2.34, 6.46]]}, {"timestamp": 1631535072085, "ltp": 2.28, "tv": 1870.99, "trd": [[2.28, 26.58]], "batb": NaN, "batl": [[0, 2.32, 12.94], [1, 2.34, 6.46], [2, 2.36, 6.46]]}, {"timestamp": 1631535085937, "ltp": 2.28, "tv": 1870.99, "trd": NaN, "batb": [[0, 2.04, 41.51], [1, 1.19, 1], [2, 1.01, 113.7]], "batl": [[0, 990, 0.01], [1, 2.34, 0], [2, 2.36, 0]]}, {"timestamp": 1631535092445, "ltp": 2.28, "tv": 1870.99, "trd": NaN, "batb": [[1, 1.74, 379.61], [2, 1.19, 1]], "batl": [[0, 2.92, 242.8], [1, 990, 0.01]]}, {"timestamp": 1631535106050, "ltp": 2.28, "tv": 1870.99, "trd": NaN, "batb": NaN, "batl": [[0, 990, 0.01], [1, 990, 0]]}, {"timestamp": 1631535108260, "ltp": 2.04, "tv": 1880.89, "trd": [[2.04, 60.97]], "batb": [[0, 2.04, 36.55], [1, 1.97, 46.94], [2, 1.74, 379.61]], "batl": [[0, 2.2, 102.14], [1, 990, 0.01]]}, {"timestamp": 1631535109240, "ltp": 2.04, "tv": 1880.89, "trd": NaN, "batb": NaN, "batl": [[1, 3.75, 247.82], [2, 990, 0.01]]}, {"timestamp": 1631535109548, "ltp": 2.04, "tv": 1880.89, "trd": NaN, "batb": NaN, "batl": [[1, 2.72, 264.63]]}, {"timestamp": 1631535112476, "ltp": 2.2, "tv": 1890.66, "trd": [[2.2, 25]], "batb": NaN, "batl": [[0, 2.2, 92.37]]}, {"timestamp": 1631535116180, "ltp": 2.2, "tv": 1893.4, "trd": [[2.2, 27.74]], "batb": [[0, 2.04, 119.29]], "batl": [[0, 2.2, 89.63]]}, {"timestamp": 1631535126283, "ltp": 2.2, "tv": 1893.4, "trd": NaN, "batb": [[0, 2.04, 36.55]], "batl": NaN}, {"timestamp": 1631535128176, "ltp": 2.2, "tv": 1893.4, "trd": NaN, "batb": [[0, 1.97, 46.94], [1, 1.74, 379.61], [2, 1.19, 1]], "batl": [[0, 2.72, 264.63], [1, 990, 0.01], [2, 990, 0]]}, {"timestamp": 1631535131108, "ltp": 2.2, "tv": 1893.4, "trd": NaN, "batb": [[1, 1.96, 47.11], [2, 1.74, 379.61]], "batl": NaN}, {"timestamp": 1631535131384, "ltp": 2.2, "tv": 1893.4, "trd": NaN, "batb": [[0, 1.96, 47.11], [1, 1.74, 379.61], [2, 1.19, 1]], "batl": NaN}, {"timestamp": 1631535140231, "ltp": 2.2, "tv": 1893.4, "trd": NaN, "batb": [[0, 2.22, 67.56], [1, 2.2, 33.78], [2, 2.18, 125.52]], "batl": [[0, 2.28, 9.42], [1, 2.72, 264.63], [2, 990, 0.01]]}, {"timestamp": 1631535141229, "ltp": 2.22, "tv": 1902.92, "trd": [[2.22, 14.53]], "batb": [[0, 2.22, 35.78], [1, 2.2, 20.27], [2, 2.18, 109.54]], "batl": [[0, 2.72, 264.63], [1, 990, 0.01], [2, 990, 0]]}, {"timestamp": 1631535143341, "ltp": 2.22, "tv": 1902.92, "trd": NaN, "batb": NaN, "batl": [[0, 2.28, 9.42], [1, 2.72, 264.63], [2, 990, 0.01]]}, {"timestamp": 1631535145202, "ltp": 2.28, "tv": 1912.34, "trd": [[2.28, 36]], "batb": NaN, "batl": [[0, 2.42, 61.3]]}, {"timestamp": 1631535145410, "ltp": 2.28, "tv": 1912.34, "trd": NaN, "batb": NaN, "batl": [[0, 2.72, 264.63], [1, 990, 0.01], [2, 990, 0]]}, {"timestamp": 1631535165160, "ltp": 2.28, "tv": 1912.34, "trd": NaN, "batb": [[0, 2.18, 34.23], [1, 2.04, 41.84], [2, 1.74, 379.61]], "batl": NaN}, {"timestamp": 1631535165440, "ltp": 2.28, "tv": 1912.34, "trd": NaN, "batb": [[0, 2.04, 41.84], [1, 1.74, 379.61], [2, 1.19, 1]], "batl": NaN}, {"timestamp": 1631535168271, "ltp": 2.28, "tv": 1912.34, "trd": NaN, "batb": NaN, "batl": [[0, 2.7, 122.85], [1, 2.72, 264.63], [2, 990, 0.01]]}, {"timestamp": 1631535168436, "ltp": 2.28, "tv": 1912.34, "trd": NaN, "batb": NaN, "batl": [[0, 2.72, 264.63], [1, 990, 0.01], [2, 990, 0]]}, {"timestamp": 1631535187894, "ltp": 2.08, "tv": 1922.24, "trd": [[2.08, 15.49]], "batb": [[0, 2.08, 79.88], [1, 2.04, 41.84], [2, 1.74, 379.61]], "batl": [[0, 2.2, 16.26], [1, 2.72, 264.63], [2, 990, 0.01]]}, {"timestamp": 1631535188871, "ltp": 2.08, "tv": 1922.24, "trd": NaN, "batb": [[0, 2.1, 14.28], [1, 2.08, 87.02], [2, 2.06, 7.14]], "batl": NaN}, {"timestamp": 1631535192808, "ltp": 2.2, "tv": 1932.21, "trd": [[2.2, 37.71]], "batb": NaN, "batl": [[0, 2.2, 6.29]]}, {"timestamp": 1631535202916, "ltp": 2.2, "tv": 1932.21, "trd": NaN, "batb": NaN, "batl": [[0, 2.72, 264.63], [1, 990, 0.01], [2, 990, 0]]}, {"timestamp": 1631535206121, "ltp": 2.2, "tv": 1932.21, "trd": NaN, "batb": [[0, 2.16, 6.84], [1, 2.1, 14.28], [2, 2.08, 87.02]], "batl": [[0, 2.2, 6.29], [1, 2.46, 32.18], [2, 2.72, 264.63]]}, {"timestamp": 1631535206328, "ltp": 2.2, "tv": 1932.21, "trd": NaN, "batb": NaN, "batl": [[1, 2.72, 264.63], [2, 990, 0.01]]}, {"timestamp": 1631535213120, "ltp": 2.2, "tv": 1932.21, "trd": NaN, "batb": [[0, 2.04, 41.84], [1, 1.97, 47.03], [2, 1.74, 379.61]], "batl": [[0, 2.72, 264.63], [1, 990, 0.01], [2, 990, 0]]}, {"timestamp": 1631535213344, "ltp": 2.2, "tv": 1932.21, "trd": NaN, "batb": [[0, 1.97, 47.03], [1, 1.74, 379.61], [2, 1.19, 1]], "batl": NaN}, {"timestamp": 1631535218863, "ltp": 1.97, "tv": 1942.37, "trd": [[1.97, 10.16]], "batb": [[0, 1.97, 41.95]], "batl": [[0, 2.16, 73.86], [1, 2.24, 277.98], [2, 2.72, 264.63]]}, {"timestamp": 1631535219857, "ltp": 1.97, "tv": 1942.37, "trd": NaN, "batb": [[1, 1.84, 29.04], [2, 1.74, 379.61]], "batl": NaN}, {"timestamp": 1631535227849, "ltp": 1.97, "tv": 1942.37, "trd": NaN, "batb": [[0, 1.96, 47.11]], "batl": NaN}, {"timestamp": 1631535239995, "ltp": 2.08, "tv": 1948.32, "trd": [[2.08, 21.44]], "batb": NaN, "batl": NaN}, {"timestamp": 1631535250300, "ltp": 2.08, "tv": 1948.32, "trd": NaN, "batb": NaN, "batl": [[0, 2.16, 55.56]]}, {"timestamp": 1631535253195, "ltp": 2.08, "tv": 1948.32, "trd": NaN, "batb": NaN, "batl": [[0, 2.12, 10.48], [1, 2.16, 55.56], [2, 2.24, 277.98]]}, {"timestamp": 1631535290079, "ltp": 2.06, "tv": 1950.03, "trd": [[2.06, 48.47]], "batb": NaN, "batl": NaN}, {"timestamp": 1631535300306, "ltp": 2.06, "tv": 1950.03, "trd": NaN, "batb": NaN, "batl": [[0, 2.16, 55.56], [1, 2.24, 277.98], [2, 2.72, 264.63]]}, {"timestamp": 1631535303173, "ltp": 2.06, "tv": 1950.03, "trd": NaN, "batb": NaN, "batl": [[0, 2.12, 12.13], [1, 2.16, 55.56], [2, 2.24, 277.98]]}, {"timestamp": 1631535318935, "ltp": 2.06, "tv": 1950.03, "trd": NaN, "batb": [[0, 1.84, 29.04], [1, 1.74, 379.61], [2, 1.19, 1]], "batl": [[0, 2.72, 264.63], [1, 990, 0.01], [2, 2.24, 0]]}, {"timestamp": 1631535324237, "ltp": 2.06, "tv": 1950.03, "trd": NaN, "batb": [[1, 1.19, 1], [2, 1.01, 113.7]], "batl": [[0, 990, 0.01], [1, 990, 0]]}, {"timestamp": 1631535326046, "ltp": 1.85, "tv": 1955.44, "trd": [[1.85, 23.86]], "batb": [[0, 1.91, 28.39], [1, 1.84, 29.04], [2, 1.19, 1]], "batl": [[0, 1.96, 113.85], [1, 1.99, 15.08], [2, 2, 73.59]]}, {"timestamp": 1631535327141, "ltp": 1.85, "tv": 1955.44, "trd": NaN, "batb": [[2, 1.72, 36.4]], "batl": NaN}, {"timestamp": 1631535331054, "ltp": 1.96, "tv": 1964.77, "trd": [[1.96, 14.82]], "batb": NaN, "batl": [[0, 1.96, 104.52]]}, {"timestamp": 1631535336769, "ltp": 1.96, "tv": 1964.77, "trd": NaN, "batb": [[0, 1.72, 36.4], [1, 1.58, 388.69], [2, 1.19, 1]], "batl": [[0, 2.5, 299.95], [1, 990, 0.01], [2, 2, 0]]}, {"timestamp": 1631535374223, "ltp": 1.96, "tv": 1964.77, "trd": NaN, "batb": [[1, 1.19, 1], [2, 1.01, 113.7]], "batl": NaN}, {"timestamp": 1631535376241, "ltp": 1.96, "tv": 1964.77, "trd": NaN, "batb": [[0, 2, 15], [1, 1.99, 7.5], [2, 1.98, 7.5]], "batl": [[0, 2.12, 92.08], [1, 2.5, 299.95], [2, 990, 0.01]]}, {"timestamp": 1631535376611, "ltp": 2.04, "tv": 1969.9, "trd": [[2.04, 66.1]], "batb": NaN, "batl": [[0, 2.12, 106.24], [1, 2.14, 7.08], [2, 2.16, 7.08]]}, {"timestamp": 1631535389432, "ltp": 2.04, "tv": 1969.9, "trd": NaN, "batb": NaN, "batl": [[0, 2.12, 123.85]]}, {"timestamp": 1631535390531, "ltp": 2.04, "tv": 1969.9, "trd": NaN, "batb": NaN, "batl": [[0, 2.12, 106.24]]}, {"timestamp": 1631535393456, "ltp": 2.04, "tv": 1969.9, "trd": NaN, "batb": NaN, "batl": [[0, 2.12, 123.85]]}, {"timestamp": 1631535410075, "ltp": 2.04, "tv": 1969.9, "trd": NaN, "batb": [[0, 1.8, 30.96], [1, 1.62, 388.38], [2, 1.19, 1]], "batl": [[0, 2.5, 299.95], [1, 990, 0.01], [2, 2.16, 0]]}, {"timestamp": 1631535428345, "ltp": 2.04, "tv": 1969.9, "trd": NaN, "batb": [[1, 1.19, 1], [2, 1.01, 113.7]], "batl": [[0, 990, 0.01], [1, 990, 0]]}, {"timestamp": 1631535430151, "ltp": 2.04, "tv": 1969.9, "trd": NaN, "batb": [[0, 2.14, 93.46], [1, 1.8, 30.96], [2, 1.19, 1]], "batl": [[0, 2.28, 82.78], [1, 990, 0.01]]}, {"timestamp": 1631535431141, "ltp": 2.2, "tv": 1974.71, "trd": [[2.2, 42.52]], "batb": [[1, 2.08, 39.41], [2, 1.92, 50.21]], "batl": NaN}, {"timestamp": 1631535432756, "ltp": 2.2, "tv": 1974.71, "trd": NaN, "batb": NaN, "batl": [[1, 2.82, 253.59], [2, 990, 0.01]]}, {"timestamp": 1631535441675, "ltp": 2.2, "tv": 1974.71, "trd": NaN, "batb": NaN, "batl": [[1, 990, 0.01], [2, 990, 0]]}, {"timestamp": 1631535443970, "ltp": 2.2, "tv": 1974.71, "trd": NaN, "batb": NaN, "batl": [[0, 2.28, 96.21]]}, {"timestamp": 1631535445075, "ltp": 2.2, "tv": 1974.71, "trd": NaN, "batb": NaN, "batl": [[0, 2.28, 82.78]]}, {"timestamp": 1631535448054, "ltp": 2.2, "tv": 1974.71, "trd": NaN, "batb": NaN, "batl": [[0, 2.28, 96.21]]}, {"timestamp": 1631535450248, "ltp": 2.2, "tv": 1974.71, "trd": NaN, "batb": [[0, 2.08, 39.41], [1, 1.92, 50.21], [2, 1.19, 1]], "batl": [[0, 990, 0.01], [1, 990, 0]]}, {"timestamp": 1631535450631, "ltp": 2.2, "tv": 1974.71, "trd": NaN, "batb": [[0, 1.92, 50.21], [1, 1.19, 1], [2, 1.01, 113.7]], "batl": NaN}, {"timestamp": 1631535467140, "ltp": 1.94, "tv": 1979.86, "trd": [[1.94, 35.47]], "batb": [[0, 2.04, 6.76], [1, 1.92, 50.21], [2, 1.19, 1]], "batl": [[0, 2.08, 8.71], [1, 2.1, 1199.25], [2, 2.12, 136.92]]}, {"timestamp": 1631535468259, "ltp": 1.94, "tv": 1979.86, "trd": NaN, "batb": [[2, 1.75, 33.89]], "batl": [[1, 2.12, 136.92], [2, 2.16, 92.6]]}, {"timestamp": 1631535486678, "ltp": 2.08, "tv": 1982.28, "trd": [[2.08, 23.86]], "batb": NaN, "batl": [[0, 2.08, 6.29]]}, {"timestamp": 1631535489875, "ltp": 2.08, "tv": 1982.28, "trd": NaN, "batb": [[0, 1.75, 33.89], [1, 1.19, 1], [2, 1.01, 113.7]], "batl": [[0, 990, 0.01], [1, 2.12, 0], [2, 2.16, 0]]}, {"timestamp": 1631535510209, "ltp": 2.08, "tv": 1982.28, "trd": NaN, "batb": [[0, 2.24, 6.22], [1, 2.18, 13.76], [2, 2.16, 6.88]], "batl": NaN}, {"timestamp": 1631535511224, "ltp": 2.24, "tv": 1991.8, "trd": [[2.24, 39.06]], "batb": [[0, 2.24, 1.46]], "batl": NaN}, {"timestamp": 1631535521066, "ltp": 2.24, "tv": 1991.8, "trd": NaN, "batb": [[0, 2.18, 13.76], [1, 2.16, 6.88], [2, 2.14, 6.88]], "batl": NaN}, {"timestamp": 1631535524231, "ltp": 2.24, "tv": 1991.8, "trd": NaN, "batb": NaN, "batl": [[0, 2.28, 10.32], [1, 2.94, 107.06], [2, 990, 0.01]]}, {"timestamp": 1631535524494, "ltp": 2.24, "tv": 1991.8, "trd": NaN, "batb": NaN, "batl": [[1, 990, 0.01], [2, 990, 0]]}, {"timestamp": 1631535531196, "ltp": 2.24, "tv": 1991.8, "trd": NaN, "batb": [[0, 1.9, 52.05], [1, 1.19, 1], [2, 1.01, 113.7]], "batl": [[0, 990, 0.01], [1, 990, 0]]}, {"timestamp": 1631535549206, "ltp": 1.93, "tv": 1996.98, "trd": [[1.93, 5.18]], "batb": NaN, "batl": [[0, 2.06, 66.27], [1, 990, 0.01]]}, {"timestamp": 1631535550203, "ltp": 1.93, "tv": 1996.98, "trd": NaN, "batb": [[0, 1.99, 15.08], [1, 1.98, 7.54], [2, 1.97, 7.54]], "batl": NaN}, {"timestamp": 1631535554121, "ltp": 2.06, "tv": 2001.5, "trd": [[2.06, 52.99]], "batb": NaN, "batl": [[0, 2.06, 61.75]]}, {"timestamp": 1631535573650, "ltp": 2.02, "tv": 2005.11, "trd": [[2.02, 13.92]], "batb": NaN, "batl": NaN}, {"timestamp": 1631535575222, "ltp": 2.02, "tv": 2005.11, "trd": NaN, "batb": [[0, 1.9, 52.05], [1, 1.74, 34.64], [2, 1.19, 1]], "batl": [[0, 990, 0.01], [1, 990, 0]]}, {"timestamp": 1631535575534, "ltp": 2.02, "tv": 2005.11, "trd": NaN, "batb": [[0, 1.74, 34.64], [1, 1.19, 1], [2, 1.01, 113.7]], "batl": NaN}, {"timestamp": 1631535613201, "ltp": 1.77, "tv": 2010.76, "trd": [[1.77, 5.65]], "batb": [[0, 1.83, 29.63], [1, 1.74, 213.33], [2, 1.59, 47.87]], "batl": [[0, 1.86, 17.48], [1, 1.89, 111.11], [2, 1.9, 23.81]]}, {"timestamp": 1631535613627, "ltp": 1.77, "tv": 2010.76, "trd": NaN, "batb": [[1, 1.8, 16.66], [2, 1.79, 8.34]], "batl": [[1, 1.89, 79.37], [2, 1.9, 7.94]]}, {"timestamp": 1631535622500, "ltp": 1.77, "tv": 2010.76, "trd": NaN, "batb": NaN, "batl": [[0, 1.89, 79.37], [1, 1.9, 7.94], [2, 1.91, 7.94]]}, {"timestamp": 1631535625443, "ltp": 1.77, "tv": 2010.76, "trd": NaN, "batb": [[1, 1.8, 27.1]], "batl": NaN}, {"timestamp": 1631535634164, "ltp": 1.77, "tv": 2010.76, "trd": NaN, "batb": [[0, 1.59, 47.87], [1, 1.19, 1], [2, 1.01, 113.7]], "batl": [[0, 990, 0.01], [1, 1.9, 0], [2, 1.91, 0]]}, {"timestamp": 1631535669238, "ltp": 1.6, "tv": 2017.01, "trd": [[1.6, 6.25]], "batb": NaN, "batl": [[0, 1.64, 12.6], [1, 1.68, 166.87], [2, 1.69, 118.34]]}, {"timestamp": 1631535670238, "ltp": 1.6, "tv": 2017.01, "trd": NaN, "batb": [[0, 1.65, 32.86], [1, 1.59, 47.87], [2, 1.53, 54.48]], "batl": [[0, 1.69, 23.66], [1, 1.84, 29.47], [2, 990, 0.01]]}, {"timestamp": 1631535674122, "ltp": 1.6, "tv": 2017.01, "trd": NaN, "batb": NaN, "batl": [[1, 1.76, 112.53], [2, 1.84, 29.47]]}, {"timestamp": 1631535674337, "ltp": 1.6, "tv": 2017.01, "trd": NaN, "batb": NaN, "batl": [[1, 1.84, 29.47], [2, 2.16, 372.43]]}, {"timestamp": 1631535682341, "ltp": 1.65, "tv": 2054.4, "trd": [[1.65, 37.39]], "batb": [[0, 1.65, 14.17]], "batl": NaN}, {"timestamp": 1631535686199, "ltp": 1.65, "tv": 2054.4, "trd": NaN, "batb": [[0, 1.53, 54.48], [1, 1.44, 405.13], [2, 1.19, 1]], "batl": [[1, 2.16, 372.43], [2, 990, 0.01]]}, {"timestamp": 1631535699658, "ltp": 1.65, "tv": 2054.4, "trd": NaN, "batb": NaN, "batl": [[0, 1.65, 8.52], [1, 1.69, 23.66], [2, 2.16, 372.43]]}, {"timestamp": 1631535701990, "ltp": 1.65, "tv": 2054.4, "trd": NaN, "batb": NaN, "batl": [[1, 2.16, 372.43], [2, 990, 0.01]]}, {"timestamp": 1631535709515, "ltp": 1.65, "tv": 2054.4, "trd": NaN, "batb": [[1, 1.19, 1], [2, 1.01, 113.7]], "batl": [[1, 990, 0.01], [2, 990, 0]]}, {"timestamp": 1631535712797, "ltp": 1.65, "tv": 2062.92, "trd": [[1.65, 45.91]], "batb": [[0, 1.73, 31.34], [1, 1.72, 9.12], [2, 1.71, 15.85]], "batl": [[0, 1.94, 27.95], [1, 1.96, 13.83], [2, 990, 0.01]]}, {"timestamp": 1631535713792, "ltp": 1.73, "tv": 2074.9, "trd": [[1.73, 11.98]], "batb": [[0, 1.73, 25.36]], "batl": NaN}, {"timestamp": 1631535717995, "ltp": 1.73, "tv": 2089.3, "trd": [[1.73, 26.37]], "batb": [[0, 1.73, 18.16]], "batl": [[2, 2.22, 357.84]]}, {"timestamp": 1631535720713, "ltp": 1.73, "tv": 2089.3, "trd": NaN, "batb": NaN, "batl": [[0, 1.84, 34.25], [1, 1.94, 27.95], [2, 1.96, 13.83]]}, {"timestamp": 1631535729856, "ltp": 1.76, "tv": 2090.35, "trd": [[1.76, 24.68]], "batb": [[0, 1.72, 9.12], [1, 1.68, 53.57], [2, 1.67, 66.36]], "batl": [[1, 2.22, 357.84], [2, 990, 0.01]]}, {"timestamp": 1631535736044, "ltp": 1.76, "tv": 2090.35, "trd": NaN, "batb": [[0, 1.61, 46.02], [1, 1.46, 404.98], [2, 1.19, 1]], "batl": [[0, 2.22, 357.84], [1, 990, 0.01], [2, 990, 0]]}, {"timestamp": 1631535745171, "ltp": 1.76, "tv": 2090.35, "trd": NaN, "batb": [[1, 1.19, 1], [2, 1.01, 113.7]], "batl": NaN}, {"timestamp": 1631535745962, "ltp": 1.76, "tv": 2090.35, "trd": NaN, "batb": [[0, 1.84, 29.47], [1, 1.82, 141.27], [2, 1.81, 8.24]], "batl": [[0, 1.89, 118.66], [1, 2.22, 357.84], [2, 990, 0.01]]}, {"timestamp": 1631535746867, "ltp": 1.84, "tv": 2101.59, "trd": [[1.84, 23.08]], "batb": [[0, 1.84, 23.85]], "batl": [[1, 1.92, 15.62], [2, 1.93, 7.82]]}, {"timestamp": 1631535762972, "ltp": 1.84, "tv": 2101.59, "trd": NaN, "batb": [[0, 1.82, 126.38], [1, 1.81, 8.24], [2, 1.8, 8.24]], "batl": NaN}, {"timestamp": 1631535767196, "ltp": 1.89, "tv": 2141.59, "trd": [[1.89, 84.72]], "batb": [[0, 1.79, 31.88], [1, 1.7, 37.41], [2, 1.55, 392.04]], "batl": [[0, 2.22, 357.84], [1, 990, 0.01], [2, 1.93, 0]]}, {"timestamp": 1631535767506, "ltp": 1.89, "tv": 2141.59, "trd": NaN, "batb": [[0, 1.7, 37.41], [1, 1.55, 392.04], [2, 1.19, 1]], "batl": NaN}, {"timestamp": 1631535777280, "ltp": 1.71, "tv": 2153.29, "trd": [[1.71, 24.44]], "batb": [[0, 1.76, 30.8], [1, 1.74, 28.64], [2, 1.7, 37.41]], "batl": [[0, 1.8, 130.55], [1, 1.87, 106.96], [2, 1.98, 27.39]]}, {"timestamp": 1631535778285, "ltp": 1.71, "tv": 2153.29, "trd": NaN, "batb": [[2, 1.73, 17.34]], "batl": NaN}, {"timestamp": 1631535782111, "ltp": 1.8, "tv": 2161.24, "trd": [[1.8, 26.4]], "batb": NaN, "batl": [[0, 1.8, 122.6], [2, 1.89, 101.17]]}, {"timestamp": 1631535782317, "ltp": 1.8, "tv": 2161.24, "trd": NaN, "batb": NaN, "batl": [[2, 1.98, 27.39]]}, {"timestamp": 1631535787216, "ltp": 1.8, "tv": 2161.24, "trd": NaN, "batb": [[1, 1.74, 15.58]], "batl": [[0, 1.8, 104.1]]}, {"timestamp": 1631535790188, "ltp": 1.8, "tv": 2161.24, "trd": NaN, "batb": [[1, 1.74, 28.65]], "batl": [[0, 1.78, 12.32], [1, 1.8, 104.1], [2, 1.87, 106.96]]}, {"timestamp": 1631535791730, "ltp": 1.76, "tv": 2166.96, "trd": [[1.76, 30.4]], "batb": [[0, 1.76, 27.94]], "batl": NaN}, {"timestamp": 1631535794430, "ltp": 1.76, "tv": 2166.96, "trd": NaN, "batb": [[0, 1.74, 13.07], [1, 1.73, 17.34], [2, 1.72, 8.68]], "batl": NaN}, {"timestamp": 1631535849227, "ltp": 1.76, "tv": 2166.96, "trd": NaN, "batb": [[0, 1.62, 44.52], [1, 1.55, 392.04], [2, 1.19, 1]], "batl": [[0, 2.22, 357.84], [1, 990, 0.01], [2, 1.87, 0]]}, {"timestamp": 1631535859243, "ltp": 1.76, "tv": 2166.96, "trd": NaN, "batb": NaN, "batl": [[0, 990, 0.01], [1, 990, 0]]}, {"timestamp": 1631535860028, "ltp": 1.76, "tv": 2166.96, "trd": NaN, "batb": [[0, 1.9, 28.53], [1, 1.88, 14.42], [2, 1.87, 48.12]], "batl": [[0, 1.94, 9.83], [1, 1.98, 111.97], [2, 990, 0.01]]}, {"timestamp": 1631535861075, "ltp": 1.9, "tv": 2177.82, "trd": [[1.9, 119.06]], "batb": [[0, 1.9, 23.11], [2, 1.87, 16.04]], "batl": [[1, 1.97, 15.22], [2, 1.98, 119.59]]}, {"timestamp": 1631535870251, "ltp": 1.94, "tv": 2185.36, "trd": [[1.94, 43]], "batb": NaN, "batl": [[0, 1.94, 6.06]]}, {"timestamp": 1631535877043, "ltp": 1.94, "tv": 2185.36, "trd": NaN, "batb": [[0, 1.87, 16.04], [1, 1.86, 8.02], [2, 1.85, 72.88]], "batl": NaN}, {"timestamp": 1631535880492, "ltp": 1.94, "tv": 2185.36, "trd": NaN, "batb": NaN, "batl": [[0, 1.97, 15.22], [1, 1.98, 119.59], [2, 1.99, 7.62]]}, {"timestamp": 1631535882056, "ltp": 1.94, "tv": 2185.36, "trd": NaN, "batb": [[0, 1.75, 34.23], [1, 1.55, 392.04], [2, 1.19, 1]], "batl": [[0, 2.5, 299.95], [1, 990, 0.01], [2, 1.99, 0]]}, {"timestamp": 1631535886895, "ltp": 1.94, "tv": 2185.36, "trd": NaN, "batb": NaN, "batl": [[0, 990, 0.01], [1, 990, 0]]}, {"timestamp": 1631535888088, "ltp": 1.76, "tv": 2191.04, "trd": [[1.76, 36.08]], "batb": [[0, 1.81, 29.95], [1, 1.79, 15.14], [2, 1.75, 34.23]], "batl": [[0, 1.86, 37.12], [1, 1.87, 8.06], [2, 1.88, 8.06]]}, {"timestamp": 1631535888766, "ltp": 1.76, "tv": 2191.04, "trd": NaN, "batb": [[2, 1.77, 16.96]], "batl": NaN}, {"timestamp": 1631535892480, "ltp": 1.86, "tv": 2193.99, "trd": [[1.86, 2.95]], "batb": NaN, "batl": [[0, 1.86, 34.17]]}, {"timestamp": 1631535897616, "ltp": 1.86, "tv": 2193.99, "trd": NaN, "batb": NaN, "batl": [[0, 1.86, 13.19]]}, {"timestamp": 1631535900521, "ltp": 1.86, "tv": 2193.99, "trd": NaN, "batb": NaN, "batl": [[0, 1.83, 10.39], [1, 1.86, 13.19], [2, 1.87, 8.06]]}, {"timestamp": 1631535904680, "ltp": 1.86, "tv": 2193.99, "trd": NaN, "batb": [[0, 1.77, 16.96], [1, 1.76, 8.48], [2, 1.75, 42.71]], "batl": NaN}, {"timestamp": 1631535905930, "ltp": 1.86, "tv": 2193.99, "trd": NaN, "batb": [[0, 1.63, 43.35], [1, 1.55, 392.04], [2, 1.19, 1]], "batl": [[0, 2.36, 326.18], [1, 990, 0.01], [2, 1.87, 0]]}, {"timestamp": 1631535913422, "ltp": 1.86, "tv": 2193.99, "trd": NaN, "batb": [[1, 1.19, 1], [2, 1.01, 113.7]], "batl": [[0, 990, 0.01], [1, 990, 0]]}, {"timestamp": 1631535914721, "ltp": 1.64, "tv": 2206.19, "trd": [[1.64, 18.82]], "batb": [[0, 1.68, 32.27], [1, 1.66, 20.01], [2, 1.63, 43.35]], "batl": [[0, 1.72, 154.23], [1, 1.89, 28.69], [2, 1.91, 14.19]]}, {"timestamp": 1631535924534, "ltp": 1.64, "tv": 2206.19, "trd": NaN, "batb": [[1, 1.66, 16.34]], "batl": NaN}, {"timestamp": 1631535927464, "ltp": 1.68, "tv": 2229.16, "trd": [[1.68, 22.97]], "batb": [[0, 1.68, 20.79]], "batl": NaN}, {"timestamp": 1631535931578, "ltp": 1.68, "tv": 2229.16, "trd": NaN, "batb": [[0, 1.63, 43.35], [1, 1.62, 132.65], [2, 1.55, 52.89]], "batl": [[1, 2.22, 357.84], [2, 990, 0.01]]}, {"timestamp": 1631535940927, "ltp": 1.68, "tv": 2229.16, "trd": NaN, "batb": [[1, 1.55, 52.89], [2, 1.46, 404.98]], "batl": [[0, 2.22, 357.84], [1, 990, 0.01], [2, 990, 0]]}, {"timestamp": 1631535941504, "ltp": 1.68, "tv": 2229.16, "trd": NaN, "batb": [[0, 1.55, 52.89], [1, 1.46, 404.98], [2, 1.19, 1]], "batl": NaN}, {"timestamp": 1631535944112, "ltp": 1.68, "tv": 2229.16, "trd": NaN, "batb": NaN, "batl": [[0, 2.2, 1007.9], [1, 2.22, 357.84], [2, 990, 0.01]]}, {"timestamp": 1631535944305, "ltp": 1.68, "tv": 2229.16, "trd": NaN, "batb": NaN, "batl": [[0, 2.22, 357.84], [1, 990, 0.01], [2, 990, 0]]}, {"timestamp": 1631535953335, "ltp": 1.68, "tv": 2229.16, "trd": NaN, "batb": [[1, 1.19, 1], [2, 1.01, 113.7]], "batl": NaN}, {"timestamp": 1631535955227, "ltp": 1.68, "tv": 2229.16, "trd": NaN, "batb": [[0, 1.82, 29.79], [1, 1.8, 15.06], [2, 1.55, 52.89]], "batl": [[0, 1.86, 15.76], [1, 1.89, 148.62], [2, 2.22, 357.84]]}, {"timestamp": 1631535956233, "ltp": 1.82, "tv": 2240.45, "trd": [[1.82, 33.9]], "batb": [[0, 1.82, 24.14], [2, 1.76, 33.3]], "batl": NaN}, {"timestamp": 1631535972269, "ltp": 1.82, "tv": 2249.47, "trd": [[1.82, 42.92]], "batb": [[0, 1.76, 33.3], [1, 1.65, 42.18], [2, 1.52, 396.29]], "batl": NaN}, {"timestamp": 1631535982178, "ltp": 1.82, "tv": 2249.47, "trd": NaN, "batb": NaN, "batl": [[0, 2.22, 357.84], [1, 990, 0.01], [2, 2.22, 0]]}, {"timestamp": 1631535982492, "ltp": 1.82, "tv": 2249.47, "trd": NaN, "batb": [[0, 1.65, 42.18], [1, 1.52, 396.29], [2, 1.19, 1]], "batl": [[1, 990, 0]]}, {"timestamp": 1631536012155, "ltp": 1.65, "tv": 2261.6, "trd": [[1.65, 58.03]], "batb": [[0, 1.69, 32.09], [1, 1.67, 16.23], [2, 1.65, 36.11]], "batl": [[0, 1.7, 125.79], [1, 1.74, 17.24], [2, 1.75, 8.62]]}, {"timestamp": 1631536013252, "ltp": 1.65, "tv": 2261.6, "trd": NaN, "batb": [[2, 1.66, 18.08]], "batl": NaN}, {"timestamp": 1631536029277, "ltp": 1.65, "tv": 2261.6, "trd": NaN, "batb": [[0, 1.66, 18.08], [1, 1.65, 45.15], [2, 1.64, 9.04]], "batl": NaN}, {"timestamp": 1631536041815, "ltp": 1.65, "tv": 2261.6, "trd": NaN, "batb": [[0, 1.56, 51.3], [1, 1.52, 396.29], [2, 1.19, 1]], "batl": [[0, 2.22, 357.84], [1, 1.74, 0], [2, 1.75, 0]]}, {"timestamp": 1631536064265, "ltp": 1.65, "tv": 2261.6, "trd": NaN, "batb": [[0, 1.76, 144.79], [1, 1.56, 51.3], [2, 1.52, 396.29]], "batl": [[0, 1.86, 10.26], [1, 1.89, 116.49], [2, 2.22, 357.84]]}, {"timestamp": 1631536065261, "ltp": 1.83, "tv": 2272.89, "trd": [[1.83, 40.73]], "batb": [[0, 1.83, 23.98], [1, 1.81, 14.98], [2, 1.78, 32.38]], "batl": NaN}, {"timestamp": 1631536069279, "ltp": 1.83, "tv": 2272.89, "trd": NaN, "batb": NaN, "batl": [[2, 1.97, 103.17]]}, {"timestamp": 1631536069452, "ltp": 1.83, "tv": 2272.89, "trd": NaN, "batb": NaN, "batl": [[2, 2.22, 357.84]]}, {"timestamp": 1631536081699, "ltp": 1.83, "tv": 2272.89, "trd": NaN, "batb": [[0, 1.78, 32.38], [1, 1.76, 144.79], [2, 1.65, 41.67]], "batl": NaN}, {"timestamp": 1631536094906, "ltp": 1.83, "tv": 2272.89, "trd": NaN, "batb": [[1, 1.65, 41.67], [2, 1.52, 396.29]], "batl": [[0, 2.22, 357.84], [1, 1.89, 0], [2, 2.22, 0]]}, {"timestamp": 1631536095340, "ltp": 1.83, "tv": 2272.89, "trd": NaN, "batb": [[0, 1.65, 41.67], [1, 1.52, 396.29], [2, 1.19, 1]], "batl": NaN}, {"timestamp": 1631536108218, "ltp": 1.83, "tv": 2272.89, "trd": NaN, "batb": [[0, 2.08, 7.06], [1, 1.65, 41.67]], "batl": [[0, 2.12, 7.54], [1, 2.2, 158.17]]}, {"timestamp": 1631536109216, "ltp": 2.08, "tv": 2282.79, "trd": [[2.08, 33.76]], "batb": [[0, 2.08, 2.11], [1, 1.97, 46.44], [2, 1.83, 29.2]], "batl": [[1, 2.16, 69.44], [2, 2.18, 34.72]]}, {"timestamp": 1631536109530, "ltp": 2.08, "tv": 2282.79, "trd": NaN, "batb": NaN, "batl": [[1, 2.16, 13.88], [2, 2.18, 6.94]]}, {"timestamp": 1631536119482, "ltp": 2.08, "tv": 2282.79, "trd": NaN, "batb": [[0, 1.97, 46.44], [1, 1.83, 29.2], [2, 1.67, 383.76]], "batl": [[0, 2.16, 13.88], [1, 2.18, 6.94], [2, 2.2, 165.11]]}, {"timestamp": 1631536122368, "ltp": 2.08, "tv": 2282.79, "trd": NaN, "batb": NaN, "batl": [[0, 2.12, 12.39], [1, 2.16, 13.88], [2, 2.18, 6.94]]}, {"timestamp": 1631536192903, "ltp": 2.12, "tv": 2286.03, "trd": [[2.12, 28.31]], "batb": NaN, "batl": [[0, 2.12, 9.15]]}, {"timestamp": 1631536196416, "ltp": 2.12, "tv": 2289.27, "trd": [[2.12, 31.55]], "batb": NaN, "batl": [[0, 2.12, 5.91]]}, {"timestamp": 1631536200222, "ltp": 2.12, "tv": 2291.76, "trd": [[2.12, 34.04]], "batb": NaN, "batl": [[0, 2.12, 3.42]]}, {"timestamp": 1631536203128, "ltp": 2.12, "tv": 2291.76, "trd": NaN, "batb": NaN, "batl": [[0, 2.16, 13.88], [1, 2.18, 6.94], [2, 2.2, 165.11]]}, {"timestamp": 1631536203814, "ltp": 2.16, "tv": 2293.48, "trd": [[2.16, 41.51]], "batb": NaN, "batl": [[0, 2.16, 12.16]]}, {"timestamp": 1631536206010, "ltp": 2.16, "tv": 2293.48, "trd": NaN, "batb": NaN, "batl": [[0, 2.16, 29.26]]}, {"timestamp": 1631536206640, "ltp": 2.16, "tv": 2293.48, "trd": NaN, "batb": NaN, "batl": [[0, 2.16, 12.16]]}, {"timestamp": 1631536209536, "ltp": 2.16, "tv": 2293.48, "trd": NaN, "batb": NaN, "batl": [[0, 2.16, 29.26]]}, {"timestamp": 1631536210429, "ltp": 2.16, "tv": 2293.48, "trd": NaN, "batb": NaN, "batl": [[0, 2.16, 12.16]]}, {"timestamp": 1631536213353, "ltp": 2.16, "tv": 2293.48, "trd": NaN, "batb": NaN, "batl": [[0, 2.16, 29.26]]}, {"timestamp": 1631536216239, "ltp": 2.16, "tv": 2293.48, "trd": NaN, "batb": NaN, "batl": [[0, 2.72, 264.63], [1, 2.18, 0], [2, 2.2, 0]]}, {"timestamp": 1631536216656, "ltp": 2.16, "tv": 2293.48, "trd": NaN, "batb": [[0, 1.83, 29.2], [1, 1.67, 383.76], [2, 1.19, 1]], "batl": NaN}, {"timestamp": 1631536226862, "ltp": 2.16, "tv": 2293.48, "trd": NaN, "batb": [[0, 2.24, 7.09], [1, 1.83, 29.2]], "batl": NaN}, {"timestamp": 1631536227868, "ltp": 2.24, "tv": 2302.82, "trd": [[2.24, 48.4]], "batb": [[0, 2.24, 2.42], [1, 2.12, 37.41], [2, 1.96, 47.53]], "batl": [[0, 2.34, 12.82], [1, 2.36, 6.4], [2, 2.38, 6.4]]}, {"timestamp": 1631536237785, "ltp": 2.24, "tv": 2302.82, "trd": NaN, "batb": [[0, 2.12, 37.41], [1, 1.96, 47.53], [2, 1.74, 379.61]], "batl": NaN}, {"timestamp": 1631536240804, "ltp": 2.24, "tv": 2302.82, "trd": NaN, "batb": NaN, "batl": [[0, 2.28, 9.36], [1, 2.34, 12.82], [2, 2.36, 6.4]]}, {"timestamp": 1631536248187, "ltp": 2.24, "tv": 2302.82, "trd": NaN, "batb": NaN, "batl": [[0, 2.72, 264.63], [1, 2.34, 0], [2, 2.36, 0]]}, {"timestamp": 1631536248401, "ltp": 2.24, "tv": 2302.82, "trd": NaN, "batb": [[0, 1.96, 47.53], [1, 1.74, 379.61], [2, 1.19, 1]], "batl": NaN}, {"timestamp": 1631536256099, "ltp": 1.99, "tv": 2307.85, "trd": [[1.99, 33.05]], "batb": NaN, "batl": [[0, 2.12, 15.96], [1, 2.72, 264.63]]}, {"timestamp": 1631536257207, "ltp": 1.99, "tv": 2307.85, "trd": NaN, "batb": [[1, 1.81, 30.71], [2, 1.74, 379.61]], "batl": NaN}, {"timestamp": 1631536263443, "ltp": 2.12, "tv": 2312.08, "trd": [[2.12, 38.27]], "batb": NaN, "batl": [[0, 2.12, 11.73]]}, {"timestamp": 1631536266043, "ltp": 2.12, "tv": 2312.08, "trd": NaN, "batb": NaN, "batl": [[0, 2.72, 264.63], [1, 2.72, 0]]}, {"timestamp": 1631536269221, "ltp": 2.12, "tv": 2312.08, "trd": NaN, "batb": NaN, "batl": [[0, 2.12, 16.45], [1, 2.7, 173.09], [2, 2.72, 264.63]]}, {"timestamp": 1631536269427, "ltp": 2.12, "tv": 2312.08, "trd": NaN, "batb": NaN, "batl": [[1, 2.72, 264.63], [2, 2.72, 0]]}, {"timestamp": 1631536270941, "ltp": 2.12, "tv": 2315.32, "trd": [[2.12, 41.51]], "batb": NaN, "batl": [[0, 2.12, 13.21]]}, {"timestamp": 1631536273656, "ltp": 2.12, "tv": 2315.32, "trd": NaN, "batb": NaN, "batl": [[0, 2.72, 264.63], [1, 2.72, 0]]}, {"timestamp": 1631536277059, "ltp": 2.12, "tv": 2315.32, "trd": NaN, "batb": NaN, "batl": [[0, 2.12, 13.21], [1, 2.72, 264.63]]}, {"timestamp": 1631536281149, "ltp": 2.12, "tv": 2315.32, "trd": NaN, "batb": NaN, "batl": [[0, 2.72, 264.63], [1, 2.72, 0]]}, {"timestamp": 1631536284075, "ltp": 2.12, "tv": 2315.32, "trd": NaN, "batb": NaN, "batl": [[0, 2.12, 13.21], [1, 2.72, 264.63]]}, {"timestamp": 1631536291167, "ltp": 2.12, "tv": 2315.32, "trd": NaN, "batb": [[0, 1.81, 30.71], [1, 1.74, 379.61], [2, 1.19, 1]], "batl": [[0, 2.72, 264.63], [1, 2.72, 0]]}, {"timestamp": 1631536293673, "ltp": 2.12, "tv": 2315.32, "trd": NaN, "batb": [[1, 1.19, 1], [2, 1.01, 113.7]], "batl": NaN}, {"timestamp": 1631536297803, "ltp": 2.12, "tv": 2315.32, "trd": NaN, "batb": [[1, 1.62, 388.38], [2, 1.19, 1]], "batl": [[0, 2.6, 281.81]]}, {"timestamp": 1631536313228, "ltp": 1.84, "tv": 2320.75, "trd": [[1.84, 28.51]], "batb": NaN, "batl": [[0, 1.92, 114.24], [1, 1.96, 76.52], [2, 1.97, 38.26]]}, {"timestamp": 1631536314116, "ltp": 1.84, "tv": 2320.75, "trd": NaN, "batb": [[0, 1.88, 28.84], [1, 1.86, 14.58], [2, 1.81, 30.71]], "batl": [[1, 1.96, 15.3], [2, 1.97, 7.66]]}, {"timestamp": 1631536323352, "ltp": 1.84, "tv": 2320.75, "trd": NaN, "batb": NaN, "batl": [[0, 1.92, 104.16]]}, {"timestamp": 1631536326135, "ltp": 1.84, "tv": 2320.75, "trd": NaN, "batb": NaN, "batl": [[0, 1.92, 119.44]]}, {"timestamp": 1631536328276, "ltp": 1.84, "tv": 2320.75, "trd": NaN, "batb": NaN, "batl": [[0, 1.92, 15.28], [1, 2.5, 299.95], [2, 1.97, 0]]}, {"timestamp": 1631536328851, "ltp": 1.84, "tv": 2320.75, "trd": NaN, "batb": [[0, 1.66, 40.5], [1, 1.62, 388.38], [2, 1.19, 1]], "batl": [[0, 2.5, 299.95], [1, 2.5, 0]]}, {"timestamp": 1631536339768, "ltp": 1.84, "tv": 2320.75, "trd": NaN, "batb": [[1, 1.19, 1], [2, 1.01, 113.7]], "batl": NaN}, {"timestamp": 1631536341081, "ltp": 1.7, "tv": 2326.63, "trd": [[1.7, 31.2]], "batb": [[0, 1.72, 31.52], [1, 1.7, 15.95], [2, 1.66, 168.88]], "batl": [[0, 1.78, 84.28], [1, 1.79, 42.14], [2, 1.8, 42.14]]}, {"timestamp": 1631536342175, "ltp": 1.7, "tv": 2326.63, "trd": NaN, "batb": NaN, "batl": [[0, 1.78, 16.86], [1, 1.79, 8.42], [2, 1.8, 8.42]]}, {"timestamp": 1631536351009, "ltp": 1.72, "tv": 2333.86, "trd": [[1.72, 7.23]], "batb": [[0, 1.72, 27.91]], "batl": NaN}, {"timestamp": 1631536353921, "ltp": 1.72, "tv": 2333.86, "trd": NaN, "batb": [[1, 1.7, 24.12]], "batl": NaN}, {"timestamp": 1631536358204, "ltp": 1.72, "tv": 2333.86, "trd": NaN, "batb": [[0, 1.66, 40.5], [1, 1.57, 49.87], [2, 1.5, 397.3]], "batl": [[0, 2.3, 337.41], [1, 1.79, 0], [2, 1.8, 0]]}, {"timestamp": 1631536358415, "ltp": 1.72, "tv": 2333.86, "trd": NaN, "batb": [[0, 1.57, 49.87], [1, 1.5, 397.3], [2, 1.19, 1]], "batl": NaN}, {"timestamp": 1631536364942, "ltp": 1.72, "tv": 2333.86, "trd": NaN, "batb": [[0, 1.59, 3.62], [1, 1.57, 49.87], [2, 1.5, 397.3]], "batl": NaN}, {"timestamp": 1631536369243, "ltp": 1.72, "tv": 2333.86, "trd": NaN, "batb": NaN, "batl": [[0, 1.72, 8.55], [1, 2.3, 337.41]]}, {"timestamp": 1631536370237, "ltp": 1.62, "tv": 2389.26, "trd": [[1.59, 12.57], [1.62, 42.83]], "batb": [[0, 1.62, 9.39], [1, 1.6, 16.95], [2, 1.57, 49.87]], "batl": [[0, 1.81, 29.95], [1, 1.83, 14.82], [2, 2.3, 337.41]]}, {"timestamp": 1631536371651, "ltp": 1.62, "tv": 2389.26, "trd": NaN, "batb": NaN, "batl": [[2, 2.3, 0]]}, {"timestamp": 1631536375260, "ltp": 1.62, "tv": 2389.26, "trd": NaN, "batb": NaN, "batl": [[2, 2.1, 394.06]]}, {"timestamp": 1631536378068, "ltp": 1.62, "tv": 2389.26, "trd": NaN, "batb": NaN, "batl": [[0, 1.73, 851.31], [1, 1.81, 29.95], [2, 1.83, 14.82]]}, {"timestamp": 1631536383048, "ltp": 1.62, "tv": 2389.26, "trd": NaN, "batb": NaN, "batl": [[0, 1.64, 16.32]]}, {"timestamp": 1631536399664, "ltp": 1.62, "tv": 2402.72, "trd": [[1.62, 56.28]], "batb": [[0, 1.62, 2.67]], "batl": NaN}, {"timestamp": 1631536406577, "ltp": 1.62, "tv": 2402.72, "trd": NaN, "batb": [[0, 1.57, 49.87], [1, 1.51, 57.99], [2, 1.4, 418.5]], "batl": [[1, 2.1, 394.06], [2, 1.83, 0]]}, {"timestamp": 1631536415204, "ltp": 1.62, "tv": 2402.72, "trd": NaN, "batb": [[0, 1.51, 57.99], [1, 1.4, 418.5], [2, 1.19, 1]], "batl": [[0, 2.1, 394.06], [1, 2.1, 0]]}, {"timestamp": 1631536424014, "ltp": 1.62, "tv": 2402.72, "trd": NaN, "batb": [[0, 1.64, 15], [1, 1.51, 57.99], [2, 1.4, 418.5]], "batl": NaN}, {"timestamp": 1631536426113, "ltp": 1.64, "tv": 2432.72, "trd": [[1.64, 48.82]], "batb": [[0, 1.51, 57.99], [1, 1.5, 85.18]], "batl": [[0, 1.55, 6.45], [1, 1.58, 17.6], [2, 1.61, 1930.14]]}, {"timestamp": 1631536427214, "ltp": 1.55, "tv": 2445.61, "trd": [[1.55, 12.9]], "batb": [[0, 1.56, 28.31], [1, 1.54, 17.61], [2, 1.51, 57.99]], "batl": [[0, 1.58, 17.6], [1, 1.64, 450.05], [2, 1.74, 31.16]]}, {"timestamp": 1631536431139, "ltp": 1.55, "tv": 2445.61, "trd": NaN, "batb": NaN, "batl": [[2, 1.67, 123.11]]}, {"timestamp": 1631536431350, "ltp": 1.55, "tv": 2445.61, "trd": NaN, "batb": NaN, "batl": [[2, 1.74, 31.16]]}, {"timestamp": 1631536441458, "ltp": 1.58, "tv": 2455.61, "trd": [[1.58, 16.8]], "batb": NaN, "batl": [[0, 1.58, 12.6]]}, {"timestamp": 1631536443441, "ltp": 1.58, "tv": 2455.61, "trd": NaN, "batb": [[0, 1.51, 57.99], [1, 1.5, 85.18], [2, 1.46, 66.28]], "batl": [[2, 2.1, 394.06]]}, {"timestamp": 1631536445258, "ltp": 1.58, "tv": 2455.61, "trd": NaN, "batb": [[1, 1.46, 66.28], [2, 1.4, 418.5]], "batl": [[0, 2.1, 394.06], [1, 1.64, 0], [2, 2.1, 0]]}, {"timestamp": 1631536445575, "ltp": 1.58, "tv": 2455.61, "trd": NaN, "batb": [[0, 1.46, 66.28], [1, 1.4, 418.5], [2, 1.19, 1]], "batl": NaN}, {"timestamp": 1631536454151, "ltp": 1.58, "tv": 2455.61, "trd": NaN, "batb": [[1, 1.19, 1], [2, 1.01, 113.7]], "batl": NaN}, {"timestamp": 1631536455565, "ltp": 1.51, "tv": 2462.23, "trd": [[1.51, 6.62]], "batb": [[0, 1.51, 35.91], [1, 1.49, 18.2], [2, 1.46, 66.28]], "batl": [[0, 1.58, 430.14], [1, 1.68, 32.27], [2, 1.7, 15.95]]}, {"timestamp": 1631536456761, "ltp": 1.51, "tv": 2462.23, "trd": NaN, "batb": [[2, 1.48, 20.28]], "batl": NaN}, {"timestamp": 1631536460269, "ltp": 1.51, "tv": 2462.23, "trd": NaN, "batb": NaN, "batl": [[1, 1.63, 138.88], [2, 1.68, 32.27]]}, {"timestamp": 1631536460482, "ltp": 1.51, "tv": 2462.23, "trd": NaN, "batb": NaN, "batl": [[1, 1.68, 32.27], [2, 1.7, 15.95]]}, {"timestamp": 1631536468873, "ltp": 1.51, "tv": 2462.23, "trd": NaN, "batb": [[1, 1.5, 7.71], [2, 1.49, 18.2]], "batl": NaN}, {"timestamp": 1631536472611, "ltp": 1.51, "tv": 2462.23, "trd": NaN, "batb": [[0, 1.5, 7.71], [1, 1.48, 20.28], [2, 1.47, 10.14]], "batl": [[1, 1.95, 443.02], [2, 1.7, 0]]}, {"timestamp": 1631536479097, "ltp": 1.51, "tv": 2462.23, "trd": NaN, "batb": [[0, 1.42, 73.89], [1, 1.34, 431.32], [2, 1.19, 1]], "batl": [[0, 1.95, 443.02], [1, 1.95, 0]]}, {"timestamp": 1631536487120, "ltp": 1.51, "tv": 2462.23, "trd": NaN, "batb": [[0, 1.48, 36.64], [1, 1.47, 15.12], [2, 1.46, 18.57]], "batl": [[0, 1.49, 6.71], [1, 1.5, 10.07], [2, 1.64, 33.06]]}, {"timestamp": 1631536501078, "ltp": 1.51, "tv": 2462.23, "trd": NaN, "batb": [[0, 1.42, 73.89], [1, 1.39, 80.58], [2, 1.34, 431.32]], "batl": [[0, 1.95, 443.02], [1, 1.5, 0], [2, 1.64, 0]]}, {"timestamp": 1631536501472, "ltp": 1.51, "tv": 2462.23, "trd": NaN, "batb": [[0, 1.39, 80.58], [1, 1.34, 431.32], [2, 1.19, 1]], "batl": NaN}, {"timestamp": 1631536518288, "ltp": 1.51, "tv": 2462.23, "trd": NaN, "batb": [[0, 1.46, 37.14], [1, 1.44, 18.82], [2, 1.39, 80.58]], "batl": [[0, 1.47, 100.25], [1, 1.48, 6.76], [2, 1.49, 20.14]]}, {"timestamp": 1631536529812, "ltp": 1.46, "tv": 2469.13, "trd": [[1.46, 6.9]], "batb": [[0, 1.46, 33.69]], "batl": NaN}, {"timestamp": 1631536557380, "ltp": 1.46, "tv": 2536.52, "trd": [[1.46, 74.28]], "batb": [[0, 1.44, 18.82], [1, 1.39, 80.58], [2, 1.36, 90.54]], "batl": [[0, 1.46, 110.95], [1, 1.47, 100.25], [2, 1.48, 6.76]]}, {"timestamp": 1631536604715, "ltp": 1.46, "tv": 2536.52, "trd": NaN, "batb": [[0, 1.39, 80.58], [1, 1.36, 90.54], [2, 1.34, 431.32]], "batl": NaN}, {"timestamp": 1631536609242, "ltp": 1.46, "tv": 2536.52, "trd": NaN, "batb": [[0, 1.36, 90.54], [1, 1.34, 431.32], [2, 1.19, 1]], "batl": [[1, 1.95, 443.02], [2, 1.48, 0]]}, {"timestamp": 1631536611160, "ltp": 1.46, "tv": 2536.52, "trd": NaN, "batb": [[0, 1.4, 191.29], [1, 1.36, 90.54], [2, 1.34, 431.32]], "batl": NaN}, {"timestamp": 1631536611321, "ltp": 1.46, "tv": 2536.52, "trd": NaN, "batb": [[0, 1.36, 90.54], [1, 1.34, 431.32], [2, 1.19, 1]], "batl": NaN}, {"timestamp": 1631536625777, "ltp": 1.46, "tv": 2758.44, "trd": [[1.46, 296.21]], "batb": [[0, 1.49, 36.39], [1, 1.48, 7.38], [2, 1.47, 18.45]], "batl": [[0, 1.5, 52.15], [1, 1.65, 32.86], [2, 1.67, 16.23]]}, {"timestamp": 1631536626894, "ltp": 1.46, "tv": 2758.44, "trd": NaN, "batb": NaN, "batl": [[0, 1.5, 58.82]]}, {"timestamp": 1631536628596, "ltp": 1.49, "tv": 2762.44, "trd": [[1.49, 4]], "batb": [[0, 1.49, 34.39]], "batl": NaN}, {"timestamp": 1631536635713, "ltp": 1.49, "tv": 2762.44, "trd": NaN, "batb": [[1, 1.47, 18.45], [2, 1.45, 148.84]], "batl": NaN}, {"timestamp": 1631536639218, "ltp": 1.49, "tv": 2762.44, "trd": NaN, "batb": [[0, 1.43, 72.47], [1, 1.39, 80.92], [2, 1.36, 90.54]], "batl": [[0, 1.95, 443.02], [1, 1.65, 0], [2, 1.67, 0]]}, {"timestamp": 1631536639593, "ltp": 1.49, "tv": 2762.44, "trd": NaN, "batb": [[0, 1.39, 80.92], [1, 1.34, 431.32], [2, 1.19, 1]], "batl": NaN}, {"timestamp": 1631536642209, "ltp": 1.49, "tv": 2762.44, "trd": NaN, "batb": NaN, "batl": [[0, 1.61, 2009.74], [1, 1.95, 443.02]]}, {"timestamp": 1631536642414, "ltp": 1.49, "tv": 2762.44, "trd": NaN, "batb": NaN, "batl": [[0, 1.95, 443.02], [1, 1.95, 0]]}, {"timestamp": 1631536646011, "ltp": 1.49, "tv": 2762.89, "trd": [[1.49, 4.44]], "batb": [[0, 1.51, 35.91], [1, 1.5, 7.59], [2, 1.49, 38.34]], "batl": [[0, 1.68, 32.27], [1, 1.7, 15.96], [2, 1.95, 443.02]]}, {"timestamp": 1631536647004, "ltp": 1.49, "tv": 2762.89, "trd": NaN, "batb": NaN, "batl": [[0, 1.52, 6.58], [1, 1.68, 32.27], [2, 1.7, 15.96]]}, {"timestamp": 1631536671272, "ltp": 1.49, "tv": 2762.89, "trd": NaN, "batb": [[1, 1.49, 18.2], [2, 1.47, 64.77]], "batl": [[0, 1.68, 32.27], [1, 1.7, 15.96], [2, 1.95, 443.02]]}, {"timestamp": 1631536671658, "ltp": 1.49, "tv": 2762.89, "trd": NaN, "batb": [[0, 1.43, 71.8], [1, 1.34, 431.32], [2, 1.19, 1]], "batl": [[0, 1.95, 443.02], [1, 1.7, 0], [2, 1.95, 0]]}, {"timestamp": 1631536674266, "ltp": 1.49, "tv": 2762.89, "trd": NaN, "batb": NaN, "batl": [[0, 1.67, 396.46], [1, 1.95, 443.02]]}, {"timestamp": 1631536674494, "ltp": 1.49, "tv": 2762.89, "trd": NaN, "batb": NaN, "batl": [[0, 1.95, 443.02], [1, 1.95, 0]]}, {"timestamp": 1631536676078, "ltp": 1.49, "tv": 2762.89, "trd": NaN, "batb": [[0, 1.43, 71.88]], "batl": NaN}, {"timestamp": 1631536686213, "ltp": 1.49, "tv": 2762.89, "trd": NaN, "batb": [[1, 1.19, 1], [2, 1.01, 113.7]], "batl": NaN}, {"timestamp": 1631536687861, "ltp": 1.49, "tv": 2762.89, "trd": NaN, "batb": [[0, 1.54, 35.21], [1, 1.52, 17.91], [2, 1.43, 71.8]], "batl": [[0, 1.56, 166.46], [1, 1.71, 31.72], [2, 1.73, 15.67]]}, {"timestamp": 1631536688822, "ltp": 1.54, "tv": 2775.96, "trd": [[1.54, 13.08]], "batb": [[0, 1.54, 28.67], [1, 1.52, 17.83], [2, 1.5, 59.25]], "batl": NaN}, {"timestamp": 1631536691518, "ltp": 1.54, "tv": 2775.96, "trd": NaN, "batb": [[0, 1.54, 28.75]], "batl": NaN}, {"timestamp": 1631536700006, "ltp": 1.54, "tv": 2775.96, "trd": NaN, "batb": NaN, "batl": [[0, 1.71, 31.72], [1, 1.73, 15.67], [2, 1.95, 443.02]]}, {"timestamp": 1631536700492, "ltp": 1.54, "tv": 2775.96, "trd": NaN, "batb": [[0, 1.47, 64.76], [1, 1.38, 415.85], [2, 1.19, 1]], "batl": [[0, 1.95, 443.02], [1, 1.73, 0], [2, 1.95, 0]]}, {"timestamp": 1631536717746, "ltp": 1.54, "tv": 2776.12, "trd": [[1.54, 13.24]], "batb": [[0, 1.51, 35.91], [1, 1.5, 7.46], [2, 1.49, 18.2]], "batl": [[0, 1.52, 6.5], [1, 1.55, 19.36], [2, 1.56, 9.68]]}, {"timestamp": 1631536718736, "ltp": 1.54, "tv": 2776.12, "trd": NaN, "batb": [[2, 1.49, 38.34]], "batl": NaN}, {"timestamp": 1631536720515, "ltp": 1.52, "tv": 2789.12, "trd": [[1.52, 13]], "batb": NaN, "batl": [[0, 1.55, 19.36], [1, 1.56, 9.68], [2, 1.57, 9.68]]}, {"timestamp": 1631536732178, "ltp": 1.52, "tv": 2789.12, "trd": NaN, "batb": [[2, 1.49, 18.2]], "batl": [[0, 1.68, 32.27], [1, 1.7, 15.96], [2, 1.95, 443.02]]}, {"timestamp": 1631536732765, "ltp": 1.52, "tv": 2789.12, "trd": NaN, "batb": [[0, 1.43, 71.88], [1, 1.38, 415.85], [2, 1.19, 1]], "batl": [[0, 1.95, 443.02], [1, 1.7, 0], [2, 1.95, 0]]}, {"timestamp": 1631536743279, "ltp": 1.52, "tv": 2789.12, "trd": NaN, "batb": [[0, 1.53, 35.44], [1, 1.51, 17.95], [2, 1.5, 58.91]], "batl": [[0, 1.56, 172.79], [1, 1.71, 31.72], [2, 1.73, 15.67]]}, {"timestamp": 1631536743903, "ltp": 1.53, "tv": 2802.2, "trd": [[1.53, 13.08]], "batb": [[0, 1.53, 28.9]], "batl": [[1, 1.58, 18.98], [2, 1.59, 9.5]]}, {"timestamp": 1631536745790, "ltp": 1.53, "tv": 2806.2, "trd": [[1.53, 17.08]], "batb": [[0, 1.53, 26.9]], "batl": NaN}, {"timestamp": 1631536764415, "ltp": 1.56, "tv": 2806.22, "trd": [[1.56, 0.02]], "batb": NaN, "batl": [[0, 1.56, 172.77]]}, {"timestamp": 1631536777873, "ltp": 1.56, "tv": 2806.22, "trd": NaN, "batb": [[0, 1.45, 68.2], [1, 1.38, 415.85], [2, 1.23, 2]], "batl": [[0, 1.95, 443.02], [1, 1.58, 0], [2, 1.59, 0]]}, {"timestamp": 1631536779866, "ltp": 1.56, "tv": 2806.22, "trd": NaN, "batb": [[0, 1.45, 68.9]], "batl": NaN}, {"timestamp": 1631536781048, "ltp": 1.56, "tv": 2806.22, "trd": NaN, "batb": [[0, 1.45, 68.56]], "batl": NaN}, {"timestamp": 1631536781984, "ltp": 1.56, "tv": 2807.62, "trd": [[1.56, 1.41]], "batb": [[0, 1.45, 67.86]], "batl": [[0, 1.53, 12.42], [1, 1.95, 443.02]]}, {"timestamp": 1631536788688, "ltp": 1.56, "tv": 2807.62, "trd": NaN, "batb": NaN, "batl": [[0, 1.95, 443.02], [1, 1.95, 0]]}, {"timestamp": 1631536797916, "ltp": 1.56, "tv": 2807.62, "trd": NaN, "batb": [[0, 1.48, 36.64], [1, 1.47, 12.92], [2, 1.46, 18.57]], "batl": [[0, 1.49, 6.71], [1, 1.5, 75.7], [2, 1.65, 32.86]]}, {"timestamp": 1631536809912, "ltp": 1.56, "tv": 2807.62, "trd": NaN, "batb": [[0, 1.41, 77.57], [1, 1.38, 415.85], [2, 1.23, 2]], "batl": [[0, 1.95, 443.02], [1, 1.5, 0], [2, 1.65, 0]]}, {"timestamp": 1631536831246, "ltp": 1.56, "tv": 2807.62, "trd": NaN, "batb": [[0, 1.55, 34.98], [1, 1.54, 12.07], [2, 1.53, 17.72]], "batl": [[0, 1.58, 148.78], [1, 1.73, 31.35], [2, 1.75, 15.49]]}, {"timestamp": 1631536832138, "ltp": 1.55, "tv": 2820.51, "trd": [[1.55, 25.8]], "batb": [[0, 1.55, 28.53], [2, 1.53, 73.45]], "batl": NaN}, {"timestamp": 1631536848280, "ltp": 1.55, "tv": 2820.51, "trd": NaN, "batb": [[0, 1.54, 12.07], [1, 1.53, 55.73], [2, 1.5, 79.93]], "batl": [[1, 1.95, 443.02], [2, 1.75, 0]]}, {"timestamp": 1631536850890, "ltp": 1.57, "tv": 2821.75, "trd": [[1.57, 11.24]], "batb": NaN, "batl": NaN}, {"timestamp": 1631536851302, "ltp": 1.57, "tv": 2821.75, "trd": NaN, "batb": NaN, "batl": [[0, 1.55, 2.32], [1, 1.58, 148.78], [2, 1.95, 443.02]]}, {"timestamp": 1631536853904, "ltp": 1.57, "tv": 2821.75, "trd": NaN, "batb": [[0, 1.53, 55.73], [1, 1.46, 66.36], [2, 1.38, 415.85]], "batl": [[1, 1.95, 443.02], [2, 1.95, 0]]}, {"timestamp": 1631536854374, "ltp": 1.57, "tv": 2821.75, "trd": NaN, "batb": [[0, 1.46, 66.36], [1, 1.38, 415.85], [2, 1.23, 2]], "batl": NaN}, {"timestamp": 1631536882827, "ltp": 1.55, "tv": 2823.15, "trd": [[1.55, 27.2]], "batb": NaN, "batl": [[0, 1.55, 1.62]]}, {"timestamp": 1631536884238, "ltp": 1.55, "tv": 2823.15, "trd": NaN, "batb": [[1, 1.44, 156.14], [2, 1.38, 415.85]], "batl": [[0, 1.5, 15.13], [1, 1.52, 2113.14], [2, 1.55, 1.62]]}, {"timestamp": 1631536885270, "ltp": 1.55, "tv": 2823.15, "trd": NaN, "batb": [[0, 1.49, 36.39], [1, 1.47, 18.45], [2, 1.46, 66.36]], "batl": [[1, 1.55, 1.62], [2, 1.58, 557.91]]}, {"timestamp": 1631536901687, "ltp": 1.55, "tv": 2823.15, "trd": NaN, "batb": [[0, 1.46, 66.36], [1, 1.44, 156.14], [2, 1.41, 77.4]], "batl": NaN}, {"timestamp": 1631536912080, "ltp": 1.55, "tv": 2823.15, "trd": NaN, "batb": [[0, 1.41, 77.4], [1, 1.38, 415.85], [2, 1.23, 2]], "batl": [[0, 1.55, 1.62], [1, 1.95, 443.02], [2, 1.58, 0]]}, {"timestamp": 1631536917279, "ltp": 1.55, "tv": 2823.15, "trd": NaN, "batb": [[1, 1.23, 2], [2, 1.19, 1]], "batl": [[0, 1.46, 6.85], [1, 1.47, 20.4], [2, 1.48, 10.2]]}, {"timestamp": 1631536918106, "ltp": 1.55, "tv": 2823.15, "trd": NaN, "batb": [[0, 1.44, 37.65], [1, 1.42, 19.09], [2, 1.41, 77.4]], "batl": NaN}, {"timestamp": 1631536934531, "ltp": 1.55, "tv": 2823.15, "trd": NaN, "batb": [[0, 1.41, 77.4], [1, 1.37, 87.45], [2, 1.31, 442.37]], "batl": NaN}, {"timestamp": 1631536938241, "ltp": 1.55, "tv": 2823.15, "trd": NaN, "batb": [[0, 1.37, 87.45], [1, 1.31, 442.37], [2, 1.23, 2]], "batl": [[0, 1.55, 1.62], [1, 1.95, 443.02], [2, 1.48, 0]]}, {"timestamp": 1631536949230, "ltp": 1.55, "tv": 2823.15, "trd": NaN, "batb": NaN, "batl": [[1, 1.7, 0.01]]}, {"timestamp": 1631536950062, "ltp": 1.55, "tv": 2823.15, "trd": NaN, "batb": NaN, "batl": [[0, 1.42, 125.18], [1, 1.44, 6.94], [2, 1.55, 1.62]]}, {"timestamp": 1631536951155, "ltp": 1.55, "tv": 2823.15, "trd": NaN, "batb": [[0, 1.41, 38.45], [1, 1.39, 19.5], [2, 1.37, 87.45]], "batl": NaN}, {"timestamp": 1631536964589, "ltp": 1.42, "tv": 2823.6, "trd": [[1.42, 0.44]], "batb": NaN, "batl": [[0, 1.42, 124.96]]}, {"timestamp": 1631536972301, "ltp": 1.42, "tv": 2823.6, "trd": NaN, "batb": [[1, 1.4, 11.5], [2, 1.39, 19.5]], "batl": NaN}, {"timestamp": 1631536998649, "ltp": 1.42, "tv": 2835.55, "trd": [[1.42, 12.4]], "batb": NaN, "batl": [[0, 1.42, 118.98]]}, {"timestamp": 1631537003555, "ltp": 1.42, "tv": 2852.18, "trd": [[1.42, 29.03]], "batb": NaN, "batl": [[0, 1.42, 102.35]]}, {"timestamp": 1631537007069, "ltp": 1.41, "tv": 2872.18, "trd": [[1.41, 41.47]], "batb": [[0, 1.41, 28.46]], "batl": NaN}, {"timestamp": 1631537010983, "ltp": 1.41, "tv": 2872.18, "trd": NaN, "batb": NaN, "batl": [[2, 1.57, 34.54]]}, {"timestamp": 1631537013752, "ltp": 1.41, "tv": 2872.18, "trd": NaN, "batb": [[1, 1.39, 19.5], [2, 1.37, 87.45]], "batl": NaN}, {"timestamp": 1631537014950, "ltp": 1.42, "tv": 2881.2, "trd": [[1.42, 38.05]], "batb": NaN, "batl": [[0, 1.42, 97.84]]}, {"timestamp": 1631537092114, "ltp": 1.42, "tv": 2881.2, "trd": NaN, "batb": NaN, "batl": [[0, 1.57, 34.54], [1, 1.59, 17.05], [2, 1.7, 0.01]]}, {"timestamp": 1631537092533, "ltp": 1.42, "tv": 2881.2, "trd": NaN, "batb": [[0, 1.29, 114.89], [1, 1.23, 2], [2, 1.19, 1]], "batl": [[0, 1.7, 0.01], [1, 1.59, 0], [2, 1.7, 0]]}, {"timestamp": 1631537106127, "ltp": 1.42, "tv": 2881.2, "trd": NaN, "batb": [[0, 1.49, 36.39], [1, 1.47, 18.45], [2, 1.46, 102.74]], "batl": [[0, 1.65, 32.86], [1, 1.67, 16.23], [2, 1.7, 0.01]]}, {"timestamp": 1631537107133, "ltp": 1.42, "tv": 2881.2, "trd": NaN, "batb": [[2, 1.46, 61.64]], "batl": [[0, 1.5, 6.67], [1, 1.52, 98.68], [2, 1.53, 49.34]]}, {"timestamp": 1631537107341, "ltp": 1.42, "tv": 2881.2, "trd": NaN, "batb": [[2, 1.46, 20.54]], "batl": [[1, 1.52, 19.74], [2, 1.53, 9.86]]}, {"timestamp": 1631537114256, "ltp": 1.42, "tv": 2881.2, "trd": NaN, "batb": [[2, 1.44, 69.37]], "batl": [[0, 1.65, 32.86], [1, 1.67, 16.23], [2, 1.7, 0.01]]}, {"timestamp": 1631537114951, "ltp": 1.42, "tv": 2881.2, "trd": NaN, "batb": [[0, 1.36, 89.29], [1, 1.23, 2], [2, 1.19, 1]], "batl": [[0, 1.7, 0.01], [1, 1.67, 0], [2, 1.7, 0]]}, {"timestamp": 1631537148190, "ltp": 1.42, "tv": 2881.2, "trd": NaN, "batb": [[0, 1.4, 51.3], [1, 1.38, 19.64], [2, 1.36, 283.75]], "batl": [[0, 1.43, 90.91], [1, 1.44, 62.5], [2, 1.45, 31.25]]}, {"timestamp": 1631537149186, "ltp": 1.42, "tv": 2881.2, "trd": NaN, "batb": [[1, 1.39, 21.58], [2, 1.38, 30.44]], "batl": [[1, 1.44, 20.84], [2, 1.45, 10.42]]}, {"timestamp": 1631537156925, "ltp": 1.42, "tv": 2881.2, "trd": NaN, "batb": [[0, 1.4, 51.31]], "batl": NaN}, {"timestamp": 1631537168216, "ltp": 1.42, "tv": 2881.2, "trd": NaN, "batb": [[0, 1.28, 121.85], [1, 1.23, 2], [2, 1.19, 1]], "batl": [[0, 1.7, 0.01], [1, 1.44, 0], [2, 1.45, 0]]}, {"timestamp": 1631537182288, "ltp": 1.42, "tv": 2881.2, "trd": NaN, "batb": [[0, 1.49, 36.39], [1, 1.47, 18.45], [2, 1.45, 175.4]], "batl": [[0, 1.52, 15.99], [1, 1.66, 32.67], [2, 1.68, 16.14]]}, {"timestamp": 1631537183172, "ltp": 1.42, "tv": 2881.2, "trd": NaN, "batb": [[2, 1.45, 243.93]], "batl": [[0, 1.51, 6.62], [1, 1.52, 15.99], [2, 1.66, 32.67]]}, {"timestamp": 1631537198702, "ltp": 1.51, "tv": 2884.2, "trd": [[1.51, 9.62]], "batb": NaN, "batl": [[0, 1.51, 3.62]]}, {"timestamp": 1631537201184, "ltp": 1.51, "tv": 2884.2, "trd": NaN, "batb": [[0, 1.36, 90.47], [1, 1.34, 431.32], [2, 1.23, 2]], "batl": [[0, 1.95, 443.02], [1, 1.52, 0], [2, 1.66, 0]]}, {"timestamp": 1631537204187, "ltp": 1.51, "tv": 2884.2, "trd": NaN, "batb": NaN, "batl": [[0, 1.95, 443.02]]}, {"timestamp": 1631537207109, "ltp": 1.51, "tv": 2884.2, "trd": NaN, "batb": [[0, 1.36, 90.46]], "batl": NaN}, {"timestamp": 1631537207995, "ltp": 1.51, "tv": 2884.2, "trd": NaN, "batb": [[1, 1.23, 2], [2, 1.19, 1]], "batl": NaN}, {"timestamp": 1631537209928, "ltp": 1.51, "tv": 2884.2, "trd": NaN, "batb": [[0, 1.4, 38.73], [1, 1.38, 19.64], [2, 1.36, 90.46]], "batl": [[0, 1.42, 7.04], [1, 1.43, 167.21], [2, 1.54, 35.21]]}, {"timestamp": 1631537211121, "ltp": 1.51, "tv": 2884.2, "trd": NaN, "batb": [[1, 1.38, 41.38], [2, 1.37, 10.88]], "batl": NaN}, {"timestamp": 1631537217198, "ltp": 1.42, "tv": 2898.08, "trd": [[1.42, 51.93]], "batb": NaN, "batl": [[0, 1.43, 167.31], [1, 1.54, 35.21], [2, 1.56, 17.38]]}, {"timestamp": 1631537226019, "ltp": 1.42, "tv": 2898.08, "trd": NaN, "batb": [[0, 1.28, 450.13], [1, 1.25, 135.48], [2, 1.23, 2]], "batl": [[0, 1.82, 505.01], [1, 1.54, 0], [2, 1.56, 0]]}, {"timestamp": 1631537236445, "ltp": 1.42, "tv": 2898.08, "trd": NaN, "batb": [[0, 1.25, 135.48], [1, 1.23, 2], [2, 1.19, 1]], "batl": NaN}, {"timestamp": 1631537237857, "ltp": 1.42, "tv": 2898.08, "trd": NaN, "batb": [[0, 1.51, 35.91], [1, 1.49, 38.34], [2, 1.48, 10.06]], "batl": [[0, 1.56, 204.47], [1, 1.68, 32.27], [2, 1.7, 15.95]]}, {"timestamp": 1631537238645, "ltp": 1.52, "tv": 2904.66, "trd": [[1.52, 19.58]], "batb": NaN, "batl": NaN}, {"timestamp": 1631537249210, "ltp": 1.52, "tv": 2904.66, "trd": NaN, "batb": [[0, 1.35, 92.3], [1, 1.34, 431.32], [2, 1.23, 2]], "batl": [[0, 1.82, 505.01], [1, 1.68, 0], [2, 1.7, 0]]}, {"timestamp": 1631537261836, "ltp": 1.52, "tv": 2904.66, "trd": NaN, "batb": [[1, 1.23, 2], [2, 1.19, 1]], "batl": NaN}, {"timestamp": 1631537262719, "ltp": 1.52, "tv": 2904.66, "trd": NaN, "batb": [[0, 1.61, 33.68], [1, 1.59, 17.05], [2, 1.5, 300.51]], "batl": [[0, 1.66, 16.33], [1, 1.81, 29.95], [2, 1.83, 14.82]]}, {"timestamp": 1631537263614, "ltp": 1.62, "tv": 2910.83, "trd": [[1.62, 62.45]], "batb": [[2, 1.58, 48.62]], "batl": NaN}, {"timestamp": 1631537273742, "ltp": 1.62, "tv": 2910.83, "trd": NaN, "batb": NaN, "batl": [[0, 1.81, 29.96], [1, 1.83, 14.82], [2, 2.16, 372.43]]}, {"timestamp": 1631537277021, "ltp": 1.62, "tv": 2910.85, "trd": [[1.62, 62.47]], "batb": [[0, 1.62, 9.37], [1, 1.61, 33.68], [2, 1.59, 17.05]], "batl": [[0, 1.66, 22.34], [1, 1.81, 29.95], [2, 1.83, 14.82]]}, {"timestamp": 1631537283364, "ltp": 1.62, "tv": 2910.85, "trd": NaN, "batb": NaN, "batl": [[0, 1.64, 8.37], [1, 1.66, 22.34], [2, 1.81, 29.95]]}, {"timestamp": 1631537286667, "ltp": 1.62, "tv": 2910.85, "trd": NaN, "batb": [[0, 1.61, 33.68], [1, 1.59, 17.05], [2, 1.58, 48.62]], "batl": [[1, 1.81, 29.95], [2, 1.83, 14.82]]}, {"timestamp": 1631537289545, "ltp": 1.62, "tv": 2910.85, "trd": NaN, "batb": [[0, 1.62, 9.37], [1, 1.61, 33.68], [2, 1.59, 17.05]], "batl": [[1, 1.66, 22.35], [2, 1.81, 29.95]]}, {"timestamp": 1631537299679, "ltp": 1.62, "tv": 2910.85, "trd": NaN, "batb": [[1, 1.58, 48.62], [2, 1.5, 300.51]], "batl": [[2, 2.16, 372.43]]}, {"timestamp": 1631537311624, "ltp": 1.64, "tv": 2926.2, "trd": [[1.64, 64.18]], "batb": NaN, "batl": [[0, 1.66, 22.35], [1, 2.16, 372.43], [2, 2.16, 0]]}, {"timestamp": 1631537337049, "ltp": 1.62, "tv": 2929.3, "trd": [[1.62, 65.57]], "batb": [[0, 1.62, 7.82]], "batl": NaN}, {"timestamp": 1631537344185, "ltp": 1.62, "tv": 2929.3, "trd": NaN, "batb": [[0, 1.49, 60.33], [1, 1.44, 405.13], [2, 1.23, 2]], "batl": [[0, 2.16, 372.43], [1, 2.16, 0]]}, {"timestamp": 1631537348153, "ltp": 1.62, "tv": 2929.3, "trd": NaN, "batb": [[0, 1.5, 60.17]], "batl": NaN}, {"timestamp": 1631537365401, "ltp": 1.62, "tv": 2929.3, "trd": NaN, "batb": [[1, 1.23, 2], [2, 1.19, 1]], "batl": NaN}, {"timestamp": 1631537367278, "ltp": 1.62, "tv": 2929.3, "trd": NaN, "batb": [[0, 1.76, 125.22], [1, 1.75, 85.72], [2, 1.74, 42.86]], "batl": [[0, 1.8, 12.57], [1, 1.83, 132.15], [2, 2.16, 372.43]]}, {"timestamp": 1631537368215, "ltp": 1.76, "tv": 2940.72, "trd": [[1.76, 47.5]], "batb": [[0, 1.76, 104.85], [1, 1.75, 51.43], [2, 1.74, 41.3]], "batl": [[2, 1.84, 81.52]]}, {"timestamp": 1631537369001, "ltp": 1.76, "tv": 2940.72, "trd": NaN, "batb": [[1, 1.75, 17.14], [2, 1.74, 24.16]], "batl": [[2, 1.84, 16.3]]}, {"timestamp": 1631537372811, "ltp": 1.76, "tv": 2944.72, "trd": [[1.76, 51.5]], "batb": [[0, 1.76, 102.85]], "batl": NaN}, {"timestamp": 1631537384537, "ltp": 1.76, "tv": 2944.72, "trd": NaN, "batb": [[0, 1.76, 72.05], [2, 1.74, 8.58]], "batl": NaN}, {"timestamp": 1631537391027, "ltp": 1.76, "tv": 2944.72, "trd": NaN, "batb": [[0, 1.73, 35.4], [1, 1.61, 45.69], [2, 1.52, 396.29]], "batl": [[0, 2.16, 372.43], [1, 1.83, 0], [2, 1.84, 0]]}, {"timestamp": 1631537392123, "ltp": 1.76, "tv": 2944.72, "trd": NaN, "batb": [[0, 1.61, 45.69], [1, 1.52, 396.29], [2, 1.46, 2]], "batl": [[0, 2.16, 373.21]]}, {"timestamp": 1631537395820, "ltp": 1.76, "tv": 2944.72, "trd": NaN, "batb": NaN, "batl": [[0, 1.76, 22.08], [1, 2.16, 372.43]]}, {"timestamp": 1631537407470, "ltp": 1.76, "tv": 2944.72, "trd": NaN, "batb": NaN, "batl": [[0, 1.76, 22.07]]}, {"timestamp": 1631537412856, "ltp": 1.76, "tv": 2944.72, "trd": NaN, "batb": [[1, 1.46, 2], [2, 1.23, 2]], "batl": [[1, 2.16, 0]]}, {"timestamp": 1631537414269, "ltp": 1.76, "tv": 2966.79, "trd": [[1.76, 73.57]], "batb": [[0, 1.97, 76.14], [1, 1.96, 38.08], [2, 1.95, 38.08]], "batl": [[0, 2.04, 11.3], [1, 2.08, 110.29]]}, {"timestamp": 1631537415267, "ltp": 2.0, "tv": 2971.84, "trd": [[2, 15.97]], "batb": [[0, 1.98, 27.39], [1, 1.97, 15.22], [2, 1.96, 21.45]], "batl": NaN}, {"timestamp": 1631537416575, "ltp": 2.0, "tv": 2971.84, "trd": NaN, "batb": NaN, "batl": [[2, 2.6, 281.81]]}, {"timestamp": 1631537419194, "ltp": 2.0, "tv": 2971.84, "trd": NaN, "batb": NaN, "batl": [[2, 2.2, 94.08]]}, {"timestamp": 1631537419391, "ltp": 2.0, "tv": 2971.84, "trd": NaN, "batb": NaN, "batl": [[2, 2.6, 281.81]]}, {"timestamp": 1631537422991, "ltp": 2.0, "tv": 2971.85, "trd": [[2, 15.98]], "batb": NaN, "batl": NaN}, {"timestamp": 1631537431491, "ltp": 2.0, "tv": 2971.85, "trd": NaN, "batb": [[0, 1.97, 15.22], [1, 1.96, 7.62], [2, 1.95, 56.07]], "batl": NaN}, {"timestamp": 1631537436710, "ltp": 2.0, "tv": 2971.85, "trd": NaN, "batb": [[0, 1.79, 31.63], [1, 1.62, 388.38], [2, 1.46, 2]], "batl": [[0, 2.6, 281.81], [1, 2.08, 0], [2, 2.6, 0]]}, {"timestamp": 1631537455542, "ltp": 2.0, "tv": 2971.85, "trd": NaN, "batb": [[1, 1.46, 2], [2, 1.23, 2]], "batl": NaN}, {"timestamp": 1631537459934, "ltp": 2.0, "tv": 2971.85, "trd": NaN, "batb": [[1, 1.67, 383.76], [2, 1.46, 2]], "batl": NaN}, {"timestamp": 1631537472867, "ltp": 2.0, "tv": 2971.85, "trd": NaN, "batb": [[1, 1.46, 2], [2, 1.23, 2]], "batl": NaN}, {"timestamp": 1631537473969, "ltp": 1.82, "tv": 2982.83, "trd": [[1.82, 53.9]], "batb": [[0, 1.83, 2.19], [1, 1.82, 29.79], [2, 1.8, 15.06]], "batl": [[0, 1.86, 8.47], [1, 1.89, 105.99], [2, 1.9, 47.38]]}, {"timestamp": 1631537474949, "ltp": 1.82, "tv": 2982.83, "trd": NaN, "batb": [[2, 1.81, 16.58]], "batl": [[2, 1.9, 15.8]]}, {"timestamp": 1631537483972, "ltp": 1.82, "tv": 2982.83, "trd": NaN, "batb": [[0, 1.82, 29.79], [1, 1.81, 16.58], [2, 1.8, 23.34]], "batl": [[0, 1.89, 105.99], [1, 1.9, 15.8], [2, 1.91, 7.9]]}, {"timestamp": 1631537486773, "ltp": 1.82, "tv": 2982.83, "trd": NaN, "batb": NaN, "batl": [[0, 1.86, 13.84], [1, 1.89, 105.99], [2, 1.9, 15.8]]}, {"timestamp": 1631537490996, "ltp": 1.82, "tv": 2982.83, "trd": NaN, "batb": [[0, 1.81, 16.58], [1, 1.8, 8.28], [2, 1.79, 39.91]], "batl": NaN}, {"timestamp": 1631537498085, "ltp": 1.82, "tv": 2982.83, "trd": NaN, "batb": [[0, 1.79, 31.63], [1, 1.63, 43.26], [2, 1.55, 392.04]], "batl": [[0, 2.42, 312.73], [1, 1.89, 0], [2, 1.9, 0]]}, {"timestamp": 1631537498699, "ltp": 1.82, "tv": 2982.83, "trd": NaN, "batb": [[0, 1.63, 43.26], [1, 1.55, 392.04], [2, 1.46, 2]], "batl": NaN}, {"timestamp": 1631537539679, "ltp": 1.82, "tv": 2982.83, "trd": NaN, "batb": [[1, 1.46, 2], [2, 1.23, 2]], "batl": NaN}, {"timestamp": 1631537541151, "ltp": 1.82, "tv": 2982.83, "trd": NaN, "batb": [[0, 2.1, 42.86], [1, 2.08, 21.43], [2, 2.06, 21.43]], "batl": [[0, 2.2, 14.51], [1, 2.28, 144.96]]}, {"timestamp": 1631537542182, "ltp": 1.82, "tv": 2982.83, "trd": NaN, "batb": [[0, 2.1, 14.28], [1, 2.08, 46.8], [2, 2.06, 7.14]], "batl": [[0, 2.14, 4.67], [1, 2.2, 14.51], [2, 2.28, 144.96]]}, {"timestamp": 1631537561917, "ltp": 2.14, "tv": 2987.01, "trd": [[2.14, 4.18]], "batb": NaN, "batl": [[0, 2.2, 15], [1, 2.28, 144.96], [2, 2.82, 253.59]]}, {"timestamp": 1631537577023, "ltp": 2.14, "tv": 2987.01, "trd": NaN, "batb": [[0, 2.08, 39.66], [1, 1.88, 26.78], [2, 1.7, 383.83]], "batl": [[0, 2.82, 253.59], [1, 2.28, 0], [2, 2.82, 0]]}, {"timestamp": 1631537577442, "ltp": 2.14, "tv": 2987.01, "trd": NaN, "batb": [[0, 1.88, 26.78], [1, 1.7, 383.83], [2, 1.46, 2]], "batl": NaN}, {"timestamp": 1631537599157, "ltp": 2.14, "tv": 2987.01, "trd": NaN, "batb": [[0, 2.6, 76.92], [1, 2.54, 11.82], [2, 2.52, 5.9]], "batl": [[0, 2.78, 144.89]]}, {"timestamp": 1631537600250, "ltp": 2.14, "tv": 2987.01, "trd": NaN, "batb": NaN, "batl": [[0, 2.62, 3.82], [1, 2.78, 144.89]]}, {"timestamp": 1631537602084, "ltp": 2.14, "tv": 2987.01, "trd": NaN, "batb": NaN, "batl": [[2, 3.45, 198.52]]}, {"timestamp": 1631537604053, "ltp": 2.62, "tv": 2988.73, "trd": [[2.62, 1.72]], "batb": NaN, "batl": [[0, 2.62, 2.1]]}, {"timestamp": 1631537611059, "ltp": 2.62, "tv": 2992.93, "trd": [[2.62, 5.92]], "batb": [[0, 2.62, 3.89], [1, 2.6, 76.92], [2, 2.54, 11.82]], "batl": [[0, 2.78, 144.89], [1, 3.45, 198.52], [2, 3.45, 0]]}, {"timestamp": 1631537612777, "ltp": 2.62, "tv": 2992.93, "trd": NaN, "batb": [[0, 2.6, 76.92], [1, 2.54, 11.82], [2, 2.52, 5.9]], "batl": NaN}, {"timestamp": 1631537614108, "ltp": 2.62, "tv": 2992.93, "trd": NaN, "batb": NaN, "batl": [[0, 2.78, 225.11]]}, {"timestamp": 1631537614289, "ltp": 2.62, "tv": 2992.93, "trd": NaN, "batb": NaN, "batl": [[0, 2.78, 144.89]]}, {"timestamp": 1631537616996, "ltp": 2.62, "tv": 2992.93, "trd": NaN, "batb": NaN, "batl": [[0, 2.66, 9.11], [1, 2.78, 144.89], [2, 3.45, 198.52]]}, {"timestamp": 1631537625992, "ltp": 2.78, "tv": 3022.15, "trd": [[2.66, 9.11], [2.78, 20.11]], "batb": NaN, "batl": [[0, 2.78, 124.78], [1, 3.45, 198.52], [2, 3.45, 0]]}, {"timestamp": 1631537628230, "ltp": 2.78, "tv": 3022.15, "trd": NaN, "batb": [[0, 2.42, 25.36], [1, 2.14, 36.4], [2, 1.92, 373.16]], "batl": [[0, 3.45, 198.52], [1, 3.45, 0]]}, {"timestamp": 1631537628909, "ltp": 2.78, "tv": 3022.15, "trd": NaN, "batb": [[0, 2.14, 36.4], [1, 1.92, 373.16], [2, 1.46, 2]], "batl": NaN}, {"timestamp": 1631537631910, "ltp": 2.78, "tv": 3022.15, "trd": NaN, "batb": [[0, 2.16, 35.56]], "batl": NaN}, {"timestamp": 1631537634036, "ltp": 2.78, "tv": 3022.15, "trd": NaN, "batb": NaN, "batl": [[0, 3.05, 2.13], [1, 3.45, 198.52]]}, {"timestamp": 1631537638550, "ltp": 2.66, "tv": 3022.45, "trd": [[2.66, 9.41]], "batb": NaN, "batl": NaN}, {"timestamp": 1631537647151, "ltp": 2.66, "tv": 3022.45, "trd": NaN, "batb": [[1, 1.46, 2], [2, 1.23, 2]], "batl": [[1, 3.45, 0]]}, {"timestamp": 1631537649281, "ltp": 3.0, "tv": 3024.88, "trd": [[3, 2.43]], "batb": [[0, 2.76, 17.74], [1, 2.42, 25.61], [2, 1.46, 2]], "batl": [[0, 3.05, 3.1]]}, {"timestamp": 1631537650848, "ltp": 3.0, "tv": 3024.88, "trd": NaN, "batb": [[2, 2.04, 373.96]], "batl": [[1, 3.9, 174.3]]}, {"timestamp": 1631537653148, "ltp": 3.05, "tv": 3027.98, "trd": [[2.94, 0.97], [3.05, 2.13]], "batb": NaN, "batl": [[0, 3.3, 59.32]]}, {"timestamp": 1631537653358, "ltp": 3.05, "tv": 3027.98, "trd": NaN, "batb": NaN, "batl": [[0, 3.9, 174.3], [1, 3.9, 0]]}, {"timestamp": 1631537654669, "ltp": 3.05, "tv": 3027.98, "trd": NaN, "batb": [[0, 2.78, 39.73], [1, 2.76, 17.74], [2, 2.42, 25.61]], "batl": NaN}, {"timestamp": 1631537656283, "ltp": 3.05, "tv": 3027.98, "trd": NaN, "batb": NaN, "batl": [[0, 3.3, 195.35], [1, 3.9, 174.3]]}, {"timestamp": 1631537656491, "ltp": 3.05, "tv": 3027.98, "trd": NaN, "batb": NaN, "batl": [[0, 3.9, 174.3], [1, 3.9, 0]]}, {"timestamp": 1631537659674, "ltp": 3.05, "tv": 3027.98, "trd": NaN, "batb": NaN, "batl": [[0, 3.8, 131.25], [1, 3.9, 174.3]]}, {"timestamp": 1631537662288, "ltp": 3.05, "tv": 3027.98, "trd": NaN, "batb": [[0, 3, 4.54], [1, 2.78, 39.73], [2, 2.76, 17.74]], "batl": NaN}, {"timestamp": 1631537663008, "ltp": 3.0, "tv": 3032.52, "trd": [[3, 6.97]], "batb": [[0, 2.76, 17.74], [1, 2.42, 25.61], [2, 2.04, 373.96]], "batl": NaN}, {"timestamp": 1631537663479, "ltp": 3.0, "tv": 3032.52, "trd": NaN, "batb": NaN, "batl": [[0, 3.9, 174.3], [1, 3.9, 0]]}, {"timestamp": 1631537665607, "ltp": 3.0, "tv": 3032.52, "trd": NaN, "batb": [[0, 2.78, 39.73], [1, 2.76, 17.74], [2, 2.42, 25.61]], "batl": NaN}, {"timestamp": 1631537666598, "ltp": 3.1, "tv": 3037.7, "trd": [[3.1, 5.18]], "batb": [[0, 3, 4.22]], "batl": [[0, 3.6, 52.95], [1, 3.9, 174.3]]}, {"timestamp": 1631537672604, "ltp": 3.1, "tv": 3037.7, "trd": NaN, "batb": [[0, 2.76, 17.74], [1, 2.42, 25.61], [2, 2.04, 373.96]], "batl": NaN}, {"timestamp": 1631537676090, "ltp": 3.1, "tv": 3037.7, "trd": NaN, "batb": NaN, "batl": [[0, 3.9, 174.3], [1, 3.9, 0]]}, {"timestamp": 1631537679223, "ltp": 3.1, "tv": 3037.7, "trd": NaN, "batb": [[0, 2.42, 25.61], [1, 2.04, 373.96], [2, 1.46, 2]], "batl": NaN}, {"timestamp": 1631537680001, "ltp": 3.1, "tv": 3037.7, "trd": NaN, "batb": [[2, 2.02, 2.13]], "batl": NaN}, {"timestamp": 1631537698845, "ltp": 3.1, "tv": 3037.7, "trd": NaN, "batb": [[1, 2.02, 2.13], [2, 1.46, 2]], "batl": NaN}, {"timestamp": 1631537700142, "ltp": 3.1, "tv": 3037.7, "trd": NaN, "batb": [[0, 3.35, 44.78], [1, 3.3, 98.51], [2, 3.25, 22.4]], "batl": [[0, 3.6, 4.48], [1, 3.7, 60.18]]}, {"timestamp": 1631537701148, "ltp": 3.4, "tv": 3040.73, "trd": [[3.4, 0.53], [3.5, 2.5]], "batb": [[0, 3.35, 26.87], [1, 3.3, 89.55], [2, 3.25, 13.44]], "batl": [[2, 3.75, 40]]}, {"timestamp": 1631537702149, "ltp": 3.4, "tv": 3040.73, "trd": NaN, "batb": NaN, "batl": [[2, 3.75, 8]]}, {"timestamp": 1631537705170, "ltp": 3.4, "tv": 3040.73, "trd": NaN, "batb": NaN, "batl": [[1, 3.7, 105.62]]}, {"timestamp": 1631537705371, "ltp": 3.4, "tv": 3040.73, "trd": NaN, "batb": NaN, "batl": [[1, 3.7, 60.18]]}, {"timestamp": 1631537711287, "ltp": 3.4, "tv": 3040.73, "trd": NaN, "batb": NaN, "batl": [[0, 3.7, 60.18], [1, 3.75, 8], [2, 3.8, 4]]}, {"timestamp": 1631537713178, "ltp": 3.4, "tv": 3040.73, "trd": NaN, "batb": [[0, 3.15, 31.46], [1, 2.78, 43.6], [2, 2.22, 366.63]], "batl": [[0, 4.6, 149.87], [1, 3.75, 0], [2, 3.8, 0]]}, {"timestamp": 1631537713383, "ltp": 3.4, "tv": 3040.73, "trd": NaN, "batb": [[0, 2.78, 43.6], [1, 2.22, 366.63], [2, 2.02, 2.13]], "batl": NaN}, {"timestamp": 1631537714996, "ltp": 3.4, "tv": 3040.73, "trd": NaN, "batb": [[0, 3, 5], [1, 2.78, 43.6], [2, 2.22, 366.63]], "batl": NaN}, {"timestamp": 1631537716203, "ltp": 3.4, "tv": 3040.73, "trd": NaN, "batb": NaN, "batl": [[0, 4.1, 68.78], [1, 4.6, 149.87]]}, {"timestamp": 1631537717199, "ltp": 3.4, "tv": 3040.73, "trd": NaN, "batb": NaN, "batl": [[0, 3.6, 153.38], [1, 4.1, 3.15], [2, 4.6, 149.87]]}, {"timestamp": 1631537718192, "ltp": 3.4, "tv": 3040.73, "trd": NaN, "batb": [[0, 3.1, 4.14], [1, 3, 5], [2, 2.78, 43.6]], "batl": [[0, 4.1, 3.15], [1, 4.6, 149.87], [2, 4.6, 0]]}, {"timestamp": 1631537718399, "ltp": 3.4, "tv": 3040.73, "trd": NaN, "batb": [[0, 3, 5], [1, 2.78, 43.6], [2, 2.22, 366.63]], "batl": NaN}, {"timestamp": 1631537725116, "ltp": 3.4, "tv": 3040.73, "trd": NaN, "batb": [[0, 3.1, 3.74], [1, 3, 5], [2, 2.78, 43.6]], "batl": NaN}, {"timestamp": 1631537725490, "ltp": 3.4, "tv": 3040.73, "trd": NaN, "batb": [[0, 3, 5], [1, 2.78, 43.6], [2, 2.22, 366.63]], "batl": NaN}, {"timestamp": 1631537728721, "ltp": 3.4, "tv": 3040.73, "trd": NaN, "batb": [[0, 3.1, 4.14], [1, 3, 5], [2, 2.78, 43.6]], "batl": [[1, 4.6, 0]]}, {"timestamp": 1631537729814, "ltp": 3.4, "tv": 3040.73, "trd": NaN, "batb": [[0, 3.75, 57.85]], "batl": [[0, 4, 4.14], [1, 4.1, 3.15], [2, 4.2, 77.98]]}, {"timestamp": 1631537731023, "ltp": 3.85, "tv": 3043.47, "trd": [[3.85, 2.74]], "batb": [[1, 3.55, 23.18], [2, 3.2, 29.29]], "batl": [[2, 4.2, 85.12]]}, {"timestamp": 1631537737466, "ltp": 3.85, "tv": 3043.47, "trd": NaN, "batb": [[1, 3.6, 3.04], [2, 3.55, 23.18]], "batl": [[2, 4.2, 87.8]]}, {"timestamp": 1631537740724, "ltp": 3.85, "tv": 3043.47, "trd": NaN, "batb": NaN, "batl": [[0, 4.1, 3.15], [1, 4.2, 87.8], [2, 4.3, 6.13]]}, {"timestamp": 1631537743719, "ltp": 3.85, "tv": 3043.47, "trd": NaN, "batb": [[0, 3.85, 4.3], [1, 3.75, 57.85], [2, 3.6, 3.04]], "batl": [[0, 4, 6.78], [1, 4.1, 3.15], [2, 4.2, 87.8]]}, {"timestamp": 1631537749230, "ltp": 3.85, "tv": 3043.47, "trd": NaN, "batb": [[0, 3.2, 29.29], [1, 2.38, 366.06], [2, 2.02, 2.13]], "batl": [[0, 4.3, 2.55], [1, 5.3, 130.72], [2, 4.2, 0]]}, {"timestamp": 1631537752159, "ltp": 3.85, "tv": 3043.47, "trd": NaN, "batb": [[0, 3.6, 3.59], [1, 3.5, 3.28], [2, 3.2, 29.29]], "batl": [[0, 4.2, 2.38], [1, 4.3, 2.55], [2, 5.3, 130.72]]}, {"timestamp": 1631537752369, "ltp": 3.85, "tv": 3043.47, "trd": NaN, "batb": [[0, 3.5, 3.28], [1, 3.2, 29.29], [2, 2.38, 366.06]], "batl": [[0, 4.3, 2.55], [1, 5.3, 130.72], [2, 5.3, 0]]}, {"timestamp": 1631537765990, "ltp": 3.85, "tv": 3043.47, "trd": NaN, "batb": [[0, 3.6, 3.09], [1, 3.5, 3.28], [2, 3.2, 29.29]], "batl": [[0, 4.2, 2.78], [1, 4.3, 2.55], [2, 5.3, 130.72]]}, {"timestamp": 1631537766304, "ltp": 3.85, "tv": 3043.47, "trd": NaN, "batb": [[0, 3.5, 3.28], [1, 3.2, 29.29], [2, 2.38, 366.06]], "batl": [[0, 4.3, 2.55], [1, 5.3, 130.72], [2, 5.3, 0]]}, {"timestamp": 1631537769594, "ltp": 3.85, "tv": 3043.47, "trd": NaN, "batb": [[0, 3.6, 2.94], [1, 3.5, 3.28], [2, 3.2, 29.29]], "batl": [[0, 4.2, 2.83], [1, 4.3, 2.55], [2, 5.3, 130.72]]}, {"timestamp": 1631537770973, "ltp": 3.85, "tv": 3043.47, "trd": NaN, "batb": NaN, "batl": [[2, 5.3, 0]]}, {"timestamp": 1631537776217, "ltp": 3.85, "tv": 3043.47, "trd": NaN, "batb": [[0, 3.2, 29.29], [1, 2.02, 2.13], [2, 1.46, 2]], "batl": [[0, 4.3, 2.55], [1, 4.3, 0]]}, {"timestamp": 1631537779093, "ltp": 3.85, "tv": 3043.47, "trd": NaN, "batb": NaN, "batl": [[0, 3.95, 19.7], [1, 4.3, 2.55]]}, {"timestamp": 1631537779615, "ltp": 3.85, "tv": 3043.47, "trd": NaN, "batb": [[0, 3.5, 3.24], [1, 3.2, 29.29], [2, 2.02, 2.13]], "batl": [[0, 4.3, 2.55], [1, 4.3, 0]]}, {"timestamp": 1631537783897, "ltp": 3.5, "tv": 3049.27, "trd": [[3.5, 8.3]], "batb": [[0, 3.2, 29.63], [1, 2.02, 2.13], [2, 1.46, 2]], "batl": [[0, 3.7, 6.96], [1, 3.85, 23.38], [2, 3.9, 11.69]]}, {"timestamp": 1631537785201, "ltp": 3.5, "tv": 3049.27, "trd": NaN, "batb": [[0, 3.45, 43.82], [1, 3.4, 13.04], [2, 3.35, 13.04]], "batl": [[1, 3.85, 7.8], [2, 3.9, 3.9]]}, {"timestamp": 1631537785832, "ltp": 3.5, "tv": 3049.27, "trd": NaN, "batb": [[0, 3.45, 26.43]], "batl": NaN}, {"timestamp": 1631537787724, "ltp": 3.85, "tv": 3078.79, "trd": [[3.7, 13.92], [3.85, 18.34]], "batb": [[0, 3.45, 9.28], [1, 3.4, 4.34], [2, 3.35, 4.34]], "batl": [[0, 3.9, 3.9], [1, 3.95, 34.28], [2, 4, 139.98]]}, {"timestamp": 1631537788714, "ltp": 3.85, "tv": 3079.27, "trd": [[3.85, 18.82]], "batb": [[0, 3.45, 9.04]], "batl": NaN}, {"timestamp": 1631537798051, "ltp": 3.85, "tv": 3079.27, "trd": NaN, "batb": [[0, 3.2, 3.97], [1, 2.84, 41.17], [2, 2.3, 368.04]], "batl": [[0, 4.1, 2.65], [1, 4.3, 2.55], [2, 4.9, 139.05]]}, {"timestamp": 1631537799143, "ltp": 3.85, "tv": 3079.27, "trd": NaN, "batb": NaN, "batl": [[0, 4.3, 2.55], [1, 4.9, 139.05], [2, 4.9, 0]]}, {"timestamp": 1631537801125, "ltp": 3.85, "tv": 3079.27, "trd": NaN, "batb": [[0, 3.3, 4.28], [1, 3.2, 3.97], [2, 2.84, 41.17]], "batl": NaN}, {"timestamp": 1631537801437, "ltp": 3.85, "tv": 3079.27, "trd": NaN, "batb": [[0, 3.2, 3.97], [1, 2.84, 41.17], [2, 2.3, 368.04]], "batl": NaN}, {"timestamp": 1631537808285, "ltp": 3.85, "tv": 3079.27, "trd": NaN, "batb": [[0, 3.3, 3.78], [1, 3.2, 3.97], [2, 2.84, 41.17]], "batl": NaN}, {"timestamp": 1631537808450, "ltp": 3.85, "tv": 3079.27, "trd": NaN, "batb": [[0, 3.2, 3.97], [1, 2.84, 41.17], [2, 2.3, 368.04]], "batl": [[1, 4.9, 0]]}, {"timestamp": 1631537809957, "ltp": 3.2, "tv": 3086.07, "trd": [[3.2, 6.46], [3.7, 14.26]], "batb": [[0, 3.05, 71.14]], "batl": [[0, 3.3, 60.6], [1, 3.4, 8.82], [2, 3.45, 4.42]]}, {"timestamp": 1631537810945, "ltp": 3.2, "tv": 3086.07, "trd": NaN, "batb": [[2, 2.36, 27.36]], "batl": NaN}, {"timestamp": 1631537816679, "ltp": 3.2, "tv": 3086.07, "trd": NaN, "batb": [[2, 2.68, 4.61]], "batl": NaN}, {"timestamp": 1631537829383, "ltp": 3.2, "tv": 3086.07, "trd": NaN, "batb": [[2, 2.72, 4.84]], "batl": NaN}, {"timestamp": 1631537832296, "ltp": 3.2, "tv": 3086.07, "trd": NaN, "batb": [[0, 3.05, 146.7]], "batl": NaN}, {"timestamp": 1631537836197, "ltp": 3.2, "tv": 3086.07, "trd": NaN, "batb": [[0, 3.05, 76.3]], "batl": [[0, 4.2, 163.07], [1, 4.3, 2.55], [2, 3.45, 0]]}, {"timestamp": 1631537836820, "ltp": 3.2, "tv": 3086.07, "trd": NaN, "batb": [[0, 2.56, 4.83], [1, 2.36, 27.36], [2, 2.3, 368.04]], "batl": [[1, 4.3, 0]]}, {"timestamp": 1631537857224, "ltp": 3.2, "tv": 3086.07, "trd": NaN, "batb": [[0, 2.68, 5.36], [1, 2.56, 4.83], [2, 2.36, 27.36]], "batl": NaN}, {"timestamp": 1631537857638, "ltp": 3.2, "tv": 3086.07, "trd": NaN, "batb": [[0, 2.56, 4.83], [1, 2.36, 27.36], [2, 2.3, 368.04]], "batl": NaN}, {"timestamp": 1631537869891, "ltp": 3.2, "tv": 3086.07, "trd": NaN, "batb": [[0, 3.85, 6.97], [1, 3.8, 23.69], [2, 3.75, 11.84]], "batl": [[0, 4.2, 5.74], [1, 4.3, 82.32]]}, {"timestamp": 1631537870881, "ltp": 4.0, "tv": 3088.77, "trd": [[4, 2.7]], "batb": [[1, 3.8, 7.9], [2, 3.75, 3.94]], "batl": [[0, 4.2, 12.88], [1, 4.3, 85.9], [2, 4.4, 3.58]]}, {"timestamp": 1631537880684, "ltp": 4.0, "tv": 3088.77, "trd": NaN, "batb": NaN, "batl": [[0, 4.2, 7.14]]}, {"timestamp": 1631537883618, "ltp": 4.0, "tv": 3088.77, "trd": NaN, "batb": [[0, 4, 5.29], [1, 3.85, 6.97], [2, 3.8, 7.9]], "batl": [[0, 4.2, 15.45]]}, {"timestamp": 1631537894732, "ltp": 4.0, "tv": 3099.35, "trd": [[4, 13.28]], "batb": [[0, 3.85, 6.97], [1, 3.8, 7.9], [2, 3.75, 3.94]], "batl": [[0, 4, 11.75], [1, 4.2, 15.45], [2, 4.3, 85.9]]}, {"timestamp": 1631537897245, "ltp": 4.0, "tv": 3099.35, "trd": NaN, "batb": NaN, "batl": [[0, 4.2, 15.45], [1, 4.3, 85.9], [2, 4.4, 3.58]]}, {"timestamp": 1631537905061, "ltp": 4.0, "tv": 3099.35, "trd": NaN, "batb": NaN, "batl": [[0, 4.2, 7.14]]}, {"timestamp": 1631537906837, "ltp": 3.85, "tv": 3118.06, "trd": [[3.85, 35.25], [4, 15.56]], "batb": [[0, 3.8, 7.9], [1, 3.75, 3.94], [2, 3.7, 3.94]], "batl": NaN}, {"timestamp": 1631537907936, "ltp": 3.85, "tv": 3118.06, "trd": NaN, "batb": NaN, "batl": [[0, 4.1, 6.89], [1, 4.2, 7.14], [2, 4.3, 85.9]]}, {"timestamp": 1631537916532, "ltp": 4.1, "tv": 3124.95, "trd": [[4.1, 6.89]], "batb": NaN, "batl": [[0, 4.2, 7.14], [1, 4.3, 85.9], [2, 4.4, 3.58]]}, {"timestamp": 1631537923672, "ltp": 4.1, "tv": 3124.95, "trd": NaN, "batb": NaN, "batl": [[0, 4.1, 4.12], [1, 4.2, 7.14], [2, 4.3, 85.9]]}, {"timestamp": 1631537926971, "ltp": 4.1, "tv": 3124.95, "trd": NaN, "batb": NaN, "batl": [[0, 4.2, 7.14], [1, 4.3, 85.9], [2, 4.4, 3.58]]}, {"timestamp": 1631537932897, "ltp": 4.1, "tv": 3124.95, "trd": NaN, "batb": [[0, 3.9, 6.01], [1, 3.8, 7.9], [2, 3.75, 3.94]], "batl": [[0, 4.1, 8.19], [1, 4.2, 7.14], [2, 4.3, 85.9]]}, {"timestamp": 1631537933690, "ltp": 4.1, "tv": 3124.95, "trd": NaN, "batb": [[0, 3.8, 7.9], [1, 3.75, 3.94], [2, 3.7, 3.94]], "batl": [[0, 4.2, 7.14], [1, 4.3, 85.9], [2, 4.4, 3.58]]}, {"timestamp": 1631537936577, "ltp": 4.1, "tv": 3124.95, "trd": NaN, "batb": [[0, 3.9, 6.01], [1, 3.8, 7.9], [2, 3.75, 3.94]], "batl": [[0, 4.1, 8.19], [1, 4.2, 7.14], [2, 4.3, 85.9]]}, {"timestamp": 1631537952744, "ltp": 4.1, "tv": 3133.14, "trd": [[4.1, 15.08]], "batb": NaN, "batl": [[0, 4.2, 7.14], [1, 4.3, 85.9], [2, 4.4, 3.58]]}, {"timestamp": 1631537959198, "ltp": 4.1, "tv": 3133.14, "trd": NaN, "batb": NaN, "batl": [[0, 4.2, 40.14]]}, {"timestamp": 1631537960143, "ltp": 4.1, "tv": 3133.14, "trd": NaN, "batb": NaN, "batl": [[0, 4.2, 7.14]]}, {"timestamp": 1631537963255, "ltp": 4.1, "tv": 3133.14, "trd": NaN, "batb": [[0, 3.8, 7.9], [1, 3.75, 3.94], [2, 3.7, 3.94]], "batl": NaN}, {"timestamp": 1631537965813, "ltp": 4.1, "tv": 3133.14, "trd": NaN, "batb": NaN, "batl": [[0, 4.2, 13.77]]}, {"timestamp": 1631537988046, "ltp": 4.1, "tv": 3133.14, "trd": NaN, "batb": [[0, 3.15, 31.38], [1, 2.3, 368.04], [2, 2.02, 2.13]], "batl": [[0, 5.3, 130.72], [1, 5.8, 2], [2, 4.4, 0]]}, {"timestamp": 1631537991281, "ltp": 4.1, "tv": 3133.14, "trd": NaN, "batb": [[0, 3.5, 3.04], [1, 3.15, 30.54], [2, 2.3, 368.04]], "batl": [[0, 5.2, 2.18], [1, 5.3, 130.72], [2, 5.8, 2]]}, {"timestamp": 1631537991491, "ltp": 4.1, "tv": 3133.14, "trd": NaN, "batb": NaN, "batl": [[0, 5.3, 130.72], [1, 5.8, 2], [2, 5.8, 0]]}, {"timestamp": 1631537994158, "ltp": 4.1, "tv": 3133.14, "trd": NaN, "batb": [[0, 3.6, 3.54], [1, 3.5, 3.04], [2, 3.15, 30.54]], "batl": NaN}, {"timestamp": 1631537994889, "ltp": 4.1, "tv": 3133.14, "trd": NaN, "batb": [[0, 3.5, 3.04], [1, 3.15, 30.54], [2, 2.3, 368.04]], "batl": NaN}, {"timestamp": 1631537996199, "ltp": 4.1, "tv": 3133.14, "trd": NaN, "batb": NaN, "batl": [[0, 5.8, 2], [1, 5.8, 0]]}, {"timestamp": 1631537997976, "ltp": 3.6, "tv": 3139.02, "trd": [[3.6, 5.88]], "batb": [[0, 3.6, 5.74], [1, 3.5, 3.04], [2, 3.35, 70.73]], "batl": [[0, 3.75, 77.2], [1, 3.9, 53.85], [2, 3.95, 11.54]]}, {"timestamp": 1631537998972, "ltp": 3.6, "tv": 3139.02, "trd": NaN, "batb": [[1, 3.5, 11.62], [2, 3.45, 4.28]], "batl": [[1, 3.9, 38.47], [2, 3.95, 3.84]]}, {"timestamp": 1631538005807, "ltp": 3.6, "tv": 3138.99, "trd": [[1.2, 61.74], [1.23, 33.18], [1.24, 32.92], [1.25, 4.05], [1.28, 32.24], [1.29, 28.23], [1.32, 23.46], [1.33, 234.3], [1.34, 15.5], [1.4, 236.11], [1.41, 41.49], [1.42, 51.93], [1.46, 296.15], [1.49, 4.44], [1.53, 17.09], [1.54, 13.25], [1.55, 27.21], [1.59, 12.58], [1.62, 65.61], [1.64, 64.17], [1.65, 58.05], [1.68, 22.99], [1.71, 24.44], [1.72, 7.23], [1.73, 26.39], [1.75, 12.12], [1.76, 73.56], [1.81, 11.24], [1.82, 53.91], [1.83, 40.73], [1.84, 28.52], [1.85, 23.85], [1.87, 11.3], [1.89, 84.72], [1.9, 119.04], [1.91, 10.7], [1.94, 43], [1.97, 10.16], [1.98, 18.02], [1.99, 33.05], [2.02, 13.91], [2.04, 66.09], [2.06, 52.99], [2.16, 41.5], [2.18, 9.7], [3.85, 35.25], [4, 15.56]], "batb": NaN, "batl": NaN}, {"timestamp": 1631538016232, "ltp": 3.6, "tv": 3138.99, "trd": NaN, "batb": [[1, 3.5, 3.04], [2, 3.35, 74]], "batl": [[1, 4.2, 2.23], [2, 4.4, 2.79]]}, {"timestamp": 1631538017027, "ltp": 3.6, "tv": 3138.99, "trd": NaN, "batb": [[0, 3.25, 3.85], [1, 2.92, 38.23], [2, 2.3, 367.98]], "batl": [[0, 4.4, 2.79], [1, 4.6, 149.85], [2, 5.8, 2]]}, {"timestamp": 1631538020227, "ltp": 3.6, "tv": 3138.99, "trd": NaN, "batb": NaN, "batl": [[0, 4.2, 2.73], [1, 4.4, 2.79], [2, 4.6, 149.85]]}, {"timestamp": 1631538020536, "ltp": 3.6, "tv": 3138.99, "trd": NaN, "batb": NaN, "batl": [[0, 4.4, 2.79], [1, 4.6, 149.85], [2, 5.8, 2]]}, {"timestamp": 1631538023241, "ltp": 3.6, "tv": 3138.99, "trd": NaN, "batb": [[0, 3.35, 3.27], [1, 3.25, 3.85], [2, 2.92, 38.23]], "batl": NaN}, {"timestamp": 1631538024009, "ltp": 3.6, "tv": 3138.99, "trd": NaN, "batb": [[0, 3.25, 3.85], [1, 2.92, 38.23], [2, 2.3, 367.98]], "batl": NaN}, {"timestamp": 1631538027258, "ltp": 3.6, "tv": 3138.99, "trd": NaN, "batb": NaN, "batl": [[0, 4.2, 2.38], [1, 4.4, 2.79], [2, 4.6, 149.85]]}, {"timestamp": 1631538027458, "ltp": 3.6, "tv": 3138.99, "trd": NaN, "batb": NaN, "batl": [[0, 4.4, 2.79], [1, 4.6, 149.85], [2, 5.8, 2]]}, {"timestamp": 1631538034274, "ltp": 3.6, "tv": 3138.99, "trd": NaN, "batb": NaN, "batl": [[0, 4.2, 2.53], [1, 4.4, 2.79], [2, 4.6, 149.85]]}, {"timestamp": 1631538034592, "ltp": 3.6, "tv": 3138.99, "trd": NaN, "batb": NaN, "batl": [[0, 4.4, 2.79], [1, 4.6, 149.85], [2, 5.8, 2]]}, {"timestamp": 1631538041278, "ltp": 3.6, "tv": 3138.99, "trd": NaN, "batb": NaN, "batl": [[0, 4.2, 2.53], [1, 4.4, 2.79], [2, 4.6, 149.85]]}, {"timestamp": 1631538041584, "ltp": 3.6, "tv": 3138.99, "trd": NaN, "batb": NaN, "batl": [[0, 4.4, 2.79], [1, 4.6, 149.85], [2, 5.8, 2]]}, {"timestamp": 1631538048202, "ltp": 3.6, "tv": 3138.99, "trd": NaN, "batb": NaN, "batl": [[0, 4.2, 2.58], [1, 4.4, 2.79], [2, 4.6, 149.85]]}, {"timestamp": 1631538048500, "ltp": 3.6, "tv": 3138.99, "trd": NaN, "batb": NaN, "batl": [[0, 4.4, 2.79], [1, 4.6, 149.85], [2, 5.8, 2]]}, {"timestamp": 1631538069116, "ltp": 3.6, "tv": 3138.99, "trd": NaN, "batb": [[0, 3.35, 3.67], [1, 3.25, 3.85], [2, 2.92, 38.23]], "batl": NaN}, {"timestamp": 1631538069702, "ltp": 3.6, "tv": 3138.99, "trd": NaN, "batb": [[0, 3.25, 3.85], [1, 2.92, 38.23], [2, 2.3, 367.98]], "batl": NaN}, {"timestamp": 1631538076219, "ltp": 3.6, "tv": 3138.99, "trd": NaN, "batb": [[0, 3.35, 3.87], [1, 3.25, 3.85], [2, 2.92, 38.23]], "batl": NaN}, {"timestamp": 1631538076842, "ltp": 3.6, "tv": 3138.99, "trd": NaN, "batb": [[0, 3.25, 3.85], [1, 2.92, 38.23], [2, 2.3, 367.98]], "batl": NaN}, {"timestamp": 1631538080233, "ltp": 3.25, "tv": 3145.23, "trd": [[3.25, 6.24]], "batb": [[0, 3.3, 6.84], [1, 3.1, 69.04], [2, 2.92, 38.23]], "batl": [[0, 3.4, 57.13], [1, 3.6, 926.52], [2, 3.9, 4.07]]}, {"timestamp": 1631538081125, "ltp": 3.25, "tv": 3145.23, "trd": NaN, "batb": NaN, "batl": [[1, 4.4, 2.79], [2, 5.8, 2]]}, {"timestamp": 1631538083525, "ltp": 3.25, "tv": 3145.23, "trd": NaN, "batb": NaN, "batl": [[1, 4.2, 163.05], [2, 4.4, 2.79]]}, {"timestamp": 1631538088369, "ltp": 3.25, "tv": 3145.23, "trd": NaN, "batb": [[1, 3.2, 4.45], [2, 3.15, 3.43]], "batl": [[1, 3.65, 3.3], [2, 3.8, 2.72]]}, {"timestamp": 1631538097671, "ltp": 3.25, "tv": 3145.23, "trd": NaN, "batb": [[0, 3.2, 4.45], [1, 3.15, 3.43], [2, 3.1, 68.31]], "batl": NaN}, {"timestamp": 1631538101477, "ltp": 3.25, "tv": 3145.23, "trd": NaN, "batb": [[2, 3.1, 72.35]], "batl": NaN}, {"timestamp": 1631538105077, "ltp": 3.25, "tv": 3145.23, "trd": NaN, "batb": [[0, 2.76, 17.74], [1, 2.3, 367.98], [2, 2.02, 2.13]], "batl": [[0, 3.65, 3.3], [1, 3.8, 2.72], [2, 4.2, 163.05]]}, {"timestamp": 1631538105909, "ltp": 3.25, "tv": 3145.23, "trd": NaN, "batb": NaN, "batl": [[0, 3.8, 2.72], [1, 4.2, 163.05], [2, 4.4, 2.79]]}, {"timestamp": 1631538108205, "ltp": 3.25, "tv": 3145.23, "trd": NaN, "batb": [[0, 3.15, 3.83], [1, 2.76, 17.74], [2, 2.3, 367.98]], "batl": NaN}, {"timestamp": 1631538112124, "ltp": 3.25, "tv": 3145.23, "trd": NaN, "batb": NaN, "batl": [[0, 3.65, 3.5], [1, 3.8, 2.72], [2, 4.2, 163.05]]}, {"timestamp": 1631538112498, "ltp": 3.25, "tv": 3145.23, "trd": NaN, "batb": NaN, "batl": [[0, 3.8, 2.72], [1, 4.2, 163.05], [2, 4.4, 2.79]]}, {"timestamp": 1631538116824, "ltp": 3.15, "tv": 3178.5, "trd": [[3.15, 33.27]], "batb": [[0, 2.76, 17.74], [1, 2.3, 367.98], [2, 2.02, 2.13]], "batl": [[0, 3.15, 108.32], [1, 3.8, 2.72], [2, 4.2, 163.05]]}, {"timestamp": 1631538119117, "ltp": 3.15, "tv": 3208.19, "trd": [[3.15, 62.96]], "batb": NaN, "batl": [[0, 3.15, 82.05], [1, 3.65, 3.5], [2, 3.8, 2.72]]}, {"timestamp": 1631538120113, "ltp": 3.15, "tv": 3238.84, "trd": [[3.15, 93.61]], "batb": NaN, "batl": [[0, 3.15, 55.42]]}, {"timestamp": 1631538124630, "ltp": 3.15, "tv": 3238.84, "trd": NaN, "batb": NaN, "batl": [[0, 3.8, 2.72], [1, 4.2, 163.05], [2, 4.4, 2.79]]}, {"timestamp": 1631538134248, "ltp": 3.15, "tv": 3238.84, "trd": NaN, "batb": [[0, 3.45, 43.48], [1, 3.4, 21.74], [2, 3.35, 21.74]], "batl": [[0, 3.75, 76.4], [1, 3.8, 2.72], [2, 4.2, 163.05]]}, {"timestamp": 1631538134667, "ltp": 3.6, "tv": 3241.78, "trd": [[3.6, 8.82]], "batb": [[0, 3.45, 8.7], [1, 3.4, 4.34], [2, 3.35, 4.34]], "batl": [[2, 3.85, 7.8]]}, {"timestamp": 1631538144531, "ltp": 3.6, "tv": 3241.78, "trd": NaN, "batb": NaN, "batl": [[0, 3.75, 70.51]]}, {"timestamp": 1631538147471, "ltp": 3.6, "tv": 3241.78, "trd": NaN, "batb": [[0, 3.6, 4.46], [1, 3.45, 8.7], [2, 3.4, 4.34]], "batl": [[0, 3.7, 4.49], [1, 3.75, 70.51], [2, 3.8, 2.72]]}, {"timestamp": 1631538149195, "ltp": 3.6, "tv": 3241.78, "trd": NaN, "batb": [[0, 3.2, 29.87], [1, 2.9, 38.99], [2, 2.3, 367.98]], "batl": [[0, 4.2, 163.05], [1, 4.4, 2.79], [2, 4.8, 2.47]]}, {"timestamp": 1631538149565, "ltp": 3.6, "tv": 3241.78, "trd": NaN, "batb": [[0, 2.9, 38.99], [1, 2.3, 367.98], [2, 2.02, 2.13]], "batl": NaN}, {"timestamp": 1631538152288, "ltp": 3.6, "tv": 3241.78, "trd": NaN, "batb": NaN, "batl": [[1, 4.3, 2.35], [2, 4.4, 2.79]]}, {"timestamp": 1631538152871, "ltp": 3.6, "tv": 3241.78, "trd": NaN, "batb": NaN, "batl": [[0, 4.4, 2.79], [1, 4.6, 2.26], [2, 5.8, 2]]}, {"timestamp": 1631538155269, "ltp": 3.6, "tv": 3241.78, "trd": NaN, "batb": NaN, "batl": [[0, 3.75, 21.42], [1, 4.4, 2.79], [2, 4.6, 2.26]]}, {"timestamp": 1631538156106, "ltp": 3.6, "tv": 3241.78, "trd": NaN, "batb": NaN, "batl": [[0, 4.2, 2.43]]}, {"timestamp": 1631538156578, "ltp": 3.6, "tv": 3241.78, "trd": NaN, "batb": NaN, "batl": [[0, 4.4, 2.79], [1, 4.6, 2.26], [2, 4.9, 139.02]]}, {"timestamp": 1631538184267, "ltp": 3.6, "tv": 3241.78, "trd": NaN, "batb": NaN, "batl": [[2, 5.8, 2]]}, {"timestamp": 1631538185258, "ltp": 3.15, "tv": 3248.12, "trd": [[3.15, 99.95]], "batb": [[0, 3.25, 3], [1, 3.05, 76.37], [2, 2.9, 38.99]], "batl": [[0, 3.35, 65.01], [1, 3.4, 9.19], [2, 3.75, 269.68]]}, {"timestamp": 1631538186252, "ltp": 3.15, "tv": 3248.12, "trd": NaN, "batb": [[1, 3.2, 46.88], [2, 3.15, 23.44]], "batl": [[0, 3.35, 41.13]]}, {"timestamp": 1631538186635, "ltp": 3.15, "tv": 3248.12, "trd": NaN, "batb": [[1, 3.2, 9.38], [2, 3.15, 4.68]], "batl": NaN}, {"timestamp": 1631538192154, "ltp": 3.15, "tv": 3248.12, "trd": NaN, "batb": NaN, "batl": [[2, 3.6, 3.71]]}, {"timestamp": 1631538195176, "ltp": 3.15, "tv": 3248.12, "trd": NaN, "batb": [[0, 3.2, 9.38], [1, 3.15, 4.68], [2, 3.1, 4.68]], "batl": [[0, 3.35, 35.82]]}, {"timestamp": 1631538205292, "ltp": 3.2, "tv": 3273.24, "trd": [[3.2, 31.58]], "batb": [[0, 3.15, 4.68], [1, 3.1, 4.68], [2, 3.05, 76.37]], "batl": [[0, 3.2, 53.14], [1, 3.35, 35.82], [2, 3.4, 9.19]]}, {"timestamp": 1631538213013, "ltp": 3.2, "tv": 3273.24, "trd": NaN, "batb": [[0, 2.9, 38.99], [1, 2.76, 17.99], [2, 2.3, 367.98]], "batl": [[1, 3.6, 3.71], [2, 3.75, 3.02]]}, {"timestamp": 1631538213324, "ltp": 3.2, "tv": 3273.24, "trd": NaN, "batb": [[0, 2.76, 17.99], [1, 2.3, 367.98], [2, 2.02, 2.13]], "batl": NaN}, {"timestamp": 1631538216146, "ltp": 3.2, "tv": 3273.24, "trd": NaN, "batb": NaN, "batl": [[0, 3.6, 3.71], [1, 3.75, 3.02], [2, 3.8, 2.97]]}, {"timestamp": 1631538217089, "ltp": 3.2, "tv": 3273.24, "trd": NaN, "batb": NaN, "batl": [[0, 3.8, 2.97], [1, 4.2, 163.05], [2, 4.4, 2.79]]}, {"timestamp": 1631538218136, "ltp": 3.2, "tv": 3273.24, "trd": NaN, "batb": NaN, "batl": [[0, 3.25, 19.14], [1, 3.8, 2.97], [2, 4.2, 163.05]]}, {"timestamp": 1631538218498, "ltp": 3.2, "tv": 3273.24, "trd": NaN, "batb": NaN, "batl": [[0, 3.8, 2.97], [1, 4.2, 163.05], [2, 4.4, 2.79]]}, {"timestamp": 1631538223150, "ltp": 3.2, "tv": 3273.24, "trd": NaN, "batb": NaN, "batl": [[0, 3.6, 3.06], [1, 3.8, 2.97], [2, 4.2, 163.05]]}, {"timestamp": 1631538223409, "ltp": 3.2, "tv": 3273.24, "trd": NaN, "batb": NaN, "batl": [[0, 3.8, 2.97], [1, 4.2, 163.05], [2, 4.4, 2.79]]}, {"timestamp": 1631538227023, "ltp": 3.2, "tv": 3273.24, "trd": NaN, "batb": NaN, "batl": [[0, 3.6, 3.16], [1, 3.8, 2.97], [2, 4.2, 163.05]]}, {"timestamp": 1631538227344, "ltp": 3.2, "tv": 3273.24, "trd": NaN, "batb": NaN, "batl": [[0, 3.8, 2.97], [1, 4.2, 163.05], [2, 4.4, 2.79]]}, {"timestamp": 1631538230239, "ltp": 3.2, "tv": 3273.24, "trd": NaN, "batb": [[0, 3, 4.39], [1, 2.76, 17.99]], "batl": [[0, 3.05, 3.28], [1, 3.1, 4.86], [2, 3.15, 63.5]]}, {"timestamp": 1631538231232, "ltp": 3.2, "tv": 3273.24, "trd": NaN, "batb": [[2, 2.34, 27.69]], "batl": NaN}, {"timestamp": 1631538235155, "ltp": 3.1, "tv": 3281.38, "trd": [[3.05, 5.41], [3.1, 10.04]], "batb": NaN, "batl": [[0, 3.15, 63.5], [1, 3.25, 9.3], [2, 3.8, 2.97]]}, {"timestamp": 1631538236559, "ltp": 3.1, "tv": 3281.38, "trd": NaN, "batb": NaN, "batl": [[2, 3.65, 2.9]]}, {"timestamp": 1631538245132, "ltp": 3.1, "tv": 3281.38, "trd": NaN, "batb": [[0, 2.76, 17.99], [1, 2.34, 27.69], [2, 2.04, 373.9]], "batl": NaN}, {"timestamp": 1631538248081, "ltp": 3.0, "tv": 3287.76, "trd": [[3, 13.35]], "batb": NaN, "batl": [[0, 3.15, 70.37]]}, {"timestamp": 1631538250765, "ltp": 3.0, "tv": 3287.76, "trd": NaN, "batb": NaN, "batl": [[0, 3.15, 63.5]]}, {"timestamp": 1631538254261, "ltp": 3.0, "tv": 3291.24, "trd": [[3, 16.83]], "batb": [[0, 2.78, 54.72], [1, 2.76, 17.99], [2, 2.34, 27.69]], "batl": [[0, 3.1, 6.63], [1, 3.15, 63.5], [2, 3.25, 9.3]]}, {"timestamp": 1631538256974, "ltp": 2.92, "tv": 3325.68, "trd": [[2.92, 34.44]], "batb": NaN, "batl": NaN}, {"timestamp": 1631538257501, "ltp": 3.0, "tv": 3327.85, "trd": [[3, 18.99]], "batb": NaN, "batl": NaN}, {"timestamp": 1631538258304, "ltp": 3.0, "tv": 3327.85, "trd": NaN, "batb": NaN, "batl": [[0, 3.15, 63.5], [1, 3.25, 9.3], [2, 3.65, 2.9]]}, {"timestamp": 1631538261181, "ltp": 3.0, "tv": 3327.85, "trd": NaN, "batb": [[0, 2.96, 5.74], [1, 2.78, 54.72], [2, 2.76, 17.99]], "batl": [[0, 3.05, 6.85], [1, 3.15, 63.5], [2, 3.25, 9.3]]}, {"timestamp": 1631538261701, "ltp": 3.0, "tv": 3327.85, "trd": NaN, "batb": [[1, 2.76, 17.99], [2, 2.34, 27.69]], "batl": NaN}, {"timestamp": 1631538263889, "ltp": 3.0, "tv": 3327.85, "trd": NaN, "batb": [[0, 2.76, 17.99], [1, 2.34, 27.69], [2, 2.04, 373.9]], "batl": [[0, 3.15, 63.5], [1, 3.25, 9.3], [2, 3.65, 2.9]]}, {"timestamp": 1631538267215, "ltp": 3.0, "tv": 3327.85, "trd": NaN, "batb": NaN, "batl": [[0, 3.65, 2.9], [1, 3.75, 2.9], [2, 3.8, 2.97]]}, {"timestamp": 1631538267597, "ltp": 3.0, "tv": 3327.85, "trd": NaN, "batb": [[0, 2.34, 27.69], [1, 2.04, 373.9], [2, 1.46, 2]], "batl": NaN}, {"timestamp": 1631538269927, "ltp": 3.0, "tv": 3327.85, "trd": NaN, "batb": NaN, "batl": [[0, 3.9, 174.27], [1, 3.95, 2.7], [2, 4.4, 2.79]]}, {"timestamp": 1631538273085, "ltp": 3.0, "tv": 3327.85, "trd": NaN, "batb": NaN, "batl": [[0, 3.65, 3.5], [1, 3.9, 174.27], [2, 3.95, 2.7]]}, {"timestamp": 1631538273416, "ltp": 3.0, "tv": 3327.85, "trd": NaN, "batb": NaN, "batl": [[0, 3.9, 174.27], [1, 3.95, 2.7], [2, 4.4, 2.79]]}, {"timestamp": 1631538281255, "ltp": 3.0, "tv": 3327.85, "trd": NaN, "batb": [[1, 1.46, 2], [2, 1.23, 2]], "batl": [[0, 3.95, 2.7], [1, 4.4, 2.79], [2, 4.6, 2.26]]}, {"timestamp": 1631538282834, "ltp": 3.0, "tv": 3327.85, "trd": NaN, "batb": [[0, 2.5, 8.29], [1, 2.42, 94.42], [2, 2.34, 27.69]], "batl": [[0, 2.56, 3.91], [1, 2.6, 25.74], [2, 2.72, 134.42]]}, {"timestamp": 1631538299061, "ltp": 2.5, "tv": 3328.05, "trd": [[2.5, 5.25]], "batb": [[0, 2.5, 8.19]], "batl": NaN}, {"timestamp": 1631538302054, "ltp": 2.5, "tv": 3328.05, "trd": NaN, "batb": [[0, 2.02, 42.42], [1, 1.86, 375.87], [2, 1.46, 2]], "batl": [[0, 3.05, 3.7], [1, 3.3, 214.76], [2, 3.95, 2.7]]}, {"timestamp": 1631538302573, "ltp": 2.5, "tv": 3328.05, "trd": NaN, "batb": NaN, "batl": [[0, 3.3, 214.76], [1, 3.95, 2.7], [2, 4.4, 2.79]]}, {"timestamp": 1631538309184, "ltp": 2.5, "tv": 3328.05, "trd": NaN, "batb": NaN, "batl": [[0, 3.05, 3.7], [1, 3.3, 214.76], [2, 3.95, 2.7]]}, {"timestamp": 1631538310493, "ltp": 2.5, "tv": 3328.05, "trd": NaN, "batb": NaN, "batl": [[0, 3.3, 214.76], [1, 3.95, 2.7], [2, 4.4, 2.79]]}, {"timestamp": 1631538320992, "ltp": 2.5, "tv": 3328.05, "trd": NaN, "batb": NaN, "batl": [[0, 3.05, 4.7], [1, 3.3, 214.76], [2, 3.95, 2.7]]}, {"timestamp": 1631538321307, "ltp": 2.5, "tv": 3328.05, "trd": NaN, "batb": NaN, "batl": [[0, 3.3, 214.76], [1, 3.95, 2.7], [2, 4.4, 2.79]]}, {"timestamp": 1631538327237, "ltp": 2.5, "tv": 3328.05, "trd": NaN, "batb": [[1, 1.46, 2], [2, 1.23, 2]], "batl": [[0, 3.3, 3.75], [1, 4.4, 2.79], [2, 4.6, 2.26]]}, {"timestamp": 1631538328023, "ltp": 2.5, "tv": 3328.05, "trd": NaN, "batb": [[0, 2.08, 111.91], [1, 2.02, 42.42], [2, 1.46, 2]], "batl": [[0, 2.18, 4.59], [1, 2.2, 24.94], [2, 2.6, 538.89]]}, {"timestamp": 1631538329117, "ltp": 2.5, "tv": 3328.05, "trd": NaN, "batb": [[2, 1.82, 29.95]], "batl": NaN}, {"timestamp": 1631538335826, "ltp": 2.5, "tv": 3328.05, "trd": NaN, "batb": NaN, "batl": [[2, 2.5, 5.87]]}, {"timestamp": 1631538348040, "ltp": 2.5, "tv": 3328.05, "trd": NaN, "batb": [[0, 1.82, 29.95], [1, 1.7, 383.77], [2, 1.46, 2]], "batl": [[0, 2.5, 5.87], [1, 2.64, 4.93], [2, 2.82, 253.55]]}, {"timestamp": 1631538348356, "ltp": 2.5, "tv": 3328.05, "trd": NaN, "batb": NaN, "batl": [[0, 2.64, 4.93], [1, 2.82, 253.55], [2, 3.3, 3.75]]}, {"timestamp": 1631538351743, "ltp": 2.5, "tv": 3328.05, "trd": NaN, "batb": [[0, 1.82, 30.85]], "batl": NaN}, {"timestamp": 1631538358078, "ltp": 2.5, "tv": 3328.05, "trd": NaN, "batb": [[0, 1.82, 29.95]], "batl": NaN}, {"timestamp": 1631538358389, "ltp": 2.5, "tv": 3328.05, "trd": NaN, "batb": NaN, "batl": [[0, 2.5, 5.67], [1, 2.64, 4.93], [2, 2.82, 253.55]]}, {"timestamp": 1631538361686, "ltp": 2.5, "tv": 3328.05, "trd": NaN, "batb": NaN, "batl": [[0, 2.64, 4.93], [1, 2.82, 253.55], [2, 3.3, 3.75]]}, {"timestamp": 1631538364983, "ltp": 2.5, "tv": 3328.05, "trd": NaN, "batb": NaN, "batl": [[0, 2.5, 5.75], [1, 2.64, 4.93], [2, 2.82, 253.55]]}, {"timestamp": 1631538392529, "ltp": 2.5, "tv": 3328.05, "trd": NaN, "batb": NaN, "batl": [[0, 2.64, 4.93], [1, 2.82, 253.55], [2, 3.3, 3.75]]}, {"timestamp": 1631538394158, "ltp": 2.5, "tv": 3328.05, "trd": NaN, "batb": [[1, 1.46, 2], [2, 1.23, 2]], "batl": [[1, 3.3, 3.75], [2, 4.4, 2.79]]}, {"timestamp": 1631538395263, "ltp": 2.5, "tv": 3328.05, "trd": NaN, "batb": [[0, 2.4, 9.67], [1, 2.32, 123.14], [2, 1.82, 29.95]], "batl": [[0, 2.56, 87.4], [1, 2.64, 4.93], [2, 3.3, 3.75]]}, {"timestamp": 1631538396038, "ltp": 2.5, "tv": 3328.05, "trd": NaN, "batb": [[2, 2.28, 30.37]], "batl": [[0, 2.46, 4.07], [1, 2.56, 87.4], [2, 2.64, 4.93]]}, {"timestamp": 1631538400166, "ltp": 2.46, "tv": 3330.99, "trd": [[2.46, 23.31]], "batb": NaN, "batl": [[0, 2.46, 1.13]]}, {"timestamp": 1631538407791, "ltp": 2.4, "tv": 3331.19, "trd": [[2.4, 17.34]], "batb": [[0, 2.4, 9.57]], "batl": NaN}, {"timestamp": 1631538409053, "ltp": 2.4, "tv": 3331.19, "trd": NaN, "batb": [[0, 2.32, 123.14], [1, 2.28, 30.37], [2, 1.93, 50.03]], "batl": NaN}, {"timestamp": 1631538413265, "ltp": 2.4, "tv": 3331.19, "trd": NaN, "batb": [[0, 1.93, 50.03], [1, 1.82, 377.82], [2, 1.46, 2]], "batl": [[0, 3.1, 4.35], [1, 3.15, 224.34], [2, 3.3, 3.75]]}, {"timestamp": 1631538413995, "ltp": 2.4, "tv": 3331.19, "trd": NaN, "batb": NaN, "batl": [[0, 2.4, 1.17], [1, 3.1, 4.35], [2, 3.15, 220.24]]}, {"timestamp": 1631538415100, "ltp": 2.4, "tv": 3332.36, "trd": [[2.4, 18.51]], "batb": NaN, "batl": [[0, 2.5, 6.81]]}, {"timestamp": 1631538416199, "ltp": 2.4, "tv": 3332.36, "trd": NaN, "batb": NaN, "batl": [[0, 2.4, 1.8]]}, {"timestamp": 1631538433232, "ltp": 2.4, "tv": 3332.36, "trd": NaN, "batb": [[0, 1.97, 27.56], [1, 1.95, 13.93], [2, 1.93, 50.03]], "batl": [[0, 2.04, 63.72], [1, 2.06, 16.75], [2, 2.08, 11.83]]}, {"timestamp": 1631538442535, "ltp": 2.02, "tv": 3335.97, "trd": [[2.02, 17.53]], "batb": NaN, "batl": NaN}, {"timestamp": 1631538450247, "ltp": 2.04, "tv": 3335.98, "trd": [[2.04, 66.1]], "batb": [[0, 1.93, 50.03], [1, 1.74, 34.97], [2, 1.67, 383.7]], "batl": [[0, 2.04, 63.71]]}, {"timestamp": 1631538453061, "ltp": 2.04, "tv": 3335.98, "trd": NaN, "batb": NaN, "batl": [[2, 2.16, 144.41]]}, {"timestamp": 1631538453636, "ltp": 1.97, "tv": 3338.68, "trd": [[1.97, 12.86]], "batb": NaN, "batl": [[0, 1.97, 14.58], [1, 2.02, 3.5], [2, 2.04, 63.71]]}, {"timestamp": 1631538456234, "ltp": 1.97, "tv": 3358.42, "trd": [[1.97, 32.6]], "batb": [[0, 1.74, 34.97], [1, 1.67, 383.7], [2, 1.46, 2]], "batl": [[0, 1.97, 1.4], [2, 2.38, 6.25]]}, {"timestamp": 1631538459043, "ltp": 1.97, "tv": 3358.42, "trd": NaN, "batb": NaN, "batl": [[2, 2.36, 7.32]]}, {"timestamp": 1631538459461, "ltp": 1.97, "tv": 3358.42, "trd": NaN, "batb": NaN, "batl": [[2, 2.28, 5.84]]}, {"timestamp": 1631538461952, "ltp": 1.97, "tv": 3358.42, "trd": NaN, "batb": NaN, "batl": [[2, 2.36, 7.32]]}, {"timestamp": 1631538463149, "ltp": 1.97, "tv": 3358.42, "trd": NaN, "batb": [[1, 1.46, 2], [2, 1.23, 2]], "batl": NaN}, {"timestamp": 1631538465275, "ltp": 2.02, "tv": 3363.32, "trd": [[1.97, 34], [2.02, 21.03]], "batb": [[0, 2.2, 95.76], [1, 1.74, 34.97], [2, 1.46, 2]], "batl": [[0, 2.28, 12.72], [1, 2.36, 7.32], [2, 2.38, 6.25]]}, {"timestamp": 1631538466183, "ltp": 2.02, "tv": 3363.32, "trd": NaN, "batb": [[1, 2.16, 35.47], [2, 1.77, 32.79]], "batl": [[0, 2.28, 4.39]]}, {"timestamp": 1631538466755, "ltp": 2.02, "tv": 3363.32, "trd": NaN, "batb": [[2, 1.77, 392.45]], "batl": NaN}, {"timestamp": 1631538468783, "ltp": 2.02, "tv": 3363.32, "trd": NaN, "batb": NaN, "batl": [[0, 2.28, 17.11]]}, {"timestamp": 1631538477680, "ltp": 2.2, "tv": 3463.82, "trd": [[2.2, 143.02]], "batb": [[0, 2.2, 45.51]], "batl": NaN}, {"timestamp": 1631538480027, "ltp": 2.2, "tv": 3463.82, "trd": NaN, "batb": [[0, 2.16, 35.47], [1, 1.77, 392.45], [2, 1.46, 2]], "batl": [[0, 2.4, 1.8], [1, 2.72, 264.59], [2, 2.82, 5.25]]}, {"timestamp": 1631538480344, "ltp": 2.2, "tv": 3463.82, "trd": NaN, "batb": [[0, 1.77, 392.45], [1, 1.46, 2], [2, 1.23, 2]], "batl": NaN}, {"timestamp": 1631538484387, "ltp": 2.2, "tv": 3463.82, "trd": NaN, "batb": [[0, 1.77, 32.79]], "batl": [[1, 2.82, 5.25], [2, 3.1, 4.35]]}, {"timestamp": 1631538485690, "ltp": 2.4, "tv": 3465.62, "trd": [[2.4, 20.31]], "batb": [[0, 2.74, 32.84], [1, 2.72, 16.43], [2, 2.7, 16.43]], "batl": [[0, 2.84, 6.02], [1, 3.1, 4.35], [2, 3.15, 3.9]]}, {"timestamp": 1631538486795, "ltp": 2.4, "tv": 3465.62, "trd": NaN, "batb": [[0, 2.74, 10.94], [1, 2.72, 5.48], [2, 2.7, 5.48]], "batl": [[0, 2.92, 3.42], [1, 2.96, 10.14], [2, 2.98, 5.06]]}, {"timestamp": 1631538489607, "ltp": 2.4, "tv": 3465.62, "trd": NaN, "batb": NaN, "batl": [[0, 2.84, 6.02], [1, 2.92, 3.42], [2, 2.96, 10.14]]}, {"timestamp": 1631538508946, "ltp": 2.74, "tv": 3476.56, "trd": [[2.74, 10.94]], "batb": [[0, 2.72, 5.48], [1, 2.7, 5.48], [2, 2.68, 19.41]], "batl": NaN}, {"timestamp": 1631538518880, "ltp": 2.74, "tv": 3476.56, "trd": NaN, "batb": NaN, "batl": [[0, 2.74, 16.97]]}, {"timestamp": 1631538521796, "ltp": 2.74, "tv": 3476.56, "trd": NaN, "batb": NaN, "batl": [[1, 2.78, 9.5], [2, 2.92, 3.42]]}, {"timestamp": 1631538526289, "ltp": 2.72, "tv": 3478.9, "trd": [[2.72, 2.34]], "batb": [[0, 2.72, 4.31]], "batl": NaN}, {"timestamp": 1631538532805, "ltp": 2.72, "tv": 3478.9, "trd": NaN, "batb": NaN, "batl": [[0, 2.78, 9.5], [1, 2.92, 3.42], [2, 2.96, 10.14]]}, {"timestamp": 1631538542200, "ltp": 2.72, "tv": 3478.9, "trd": NaN, "batb": [[0, 2.14, 36.31], [1, 2.04, 353.71], [2, 1.46, 2]], "batl": [[0, 3.5, 3.13], [1, 3.6, 3.31], [2, 3.9, 184.87]]}, {"timestamp": 1631538542511, "ltp": 2.72, "tv": 3478.9, "trd": NaN, "batb": NaN, "batl": [[0, 3.9, 184.87], [1, 3.95, 2.9], [2, 4.1, 2.65]]}, {"timestamp": 1631538549101, "ltp": 2.72, "tv": 3478.9, "trd": NaN, "batb": NaN, "batl": [[0, 3.5, 2.87], [1, 3.9, 184.87], [2, 3.95, 2.9]]}, {"timestamp": 1631538549412, "ltp": 2.72, "tv": 3478.9, "trd": NaN, "batb": NaN, "batl": [[0, 3.9, 184.87], [1, 3.95, 2.9], [2, 4.1, 2.65]]}, {"timestamp": 1631538550618, "ltp": 2.72, "tv": 3478.9, "trd": NaN, "batb": [[0, 2.16, 3.59], [1, 2.14, 36.31], [2, 2.04, 353.71]], "batl": NaN}, {"timestamp": 1631538554644, "ltp": 2.14, "tv": 3532.33, "trd": [[2.14, 50.43], [2.16, 48.69]], "batb": [[0, 2.14, 13.19], [1, 2.04, 353.71], [2, 1.46, 2]], "batl": NaN}, {"timestamp": 1631538556112, "ltp": 2.14, "tv": 3532.33, "trd": NaN, "batb": NaN, "batl": [[0, 3.5, 3.91], [1, 3.9, 184.87], [2, 3.95, 2.9]]}, {"timestamp": 1631538556423, "ltp": 2.14, "tv": 3532.33, "trd": NaN, "batb": NaN, "batl": [[0, 3.9, 184.87], [1, 3.95, 2.9], [2, 4.1, 2.65]]}, {"timestamp": 1631538563261, "ltp": 2.14, "tv": 3532.33, "trd": NaN, "batb": NaN, "batl": [[0, 3.5, 3.29], [1, 3.9, 184.87], [2, 3.95, 2.9]]}, {"timestamp": 1631538564047, "ltp": 2.14, "tv": 3532.33, "trd": NaN, "batb": [[0, 2.04, 353.71], [1, 1.46, 2], [2, 1.23, 2]], "batl": [[0, 3.9, 184.87], [1, 3.95, 2.9], [2, 4.1, 2.65]]}, {"timestamp": 1631538565138, "ltp": 2.14, "tv": 3532.33, "trd": NaN, "batb": [[0, 1.46, 2], [1, 1.23, 2], [2, 1.19, 1]], "batl": [[0, 3.95, 2.9], [1, 3.95, 0], [2, 4.1, 0]]}, {"timestamp": 1631538566123, "ltp": 2.14, "tv": 3532.33, "trd": NaN, "batb": NaN, "batl": [[0, 2.2, 12.54], [1, 2.26, 1426.5], [2, 2.28, 4.39]]}, {"timestamp": 1631538567268, "ltp": 2.14, "tv": 3532.33, "trd": NaN, "batb": [[0, 2.12, 36.89], [1, 1.75, 33.8], [2, 1.46, 2]], "batl": [[1, 2.22, 16.25], [2, 2.26, 53.1]]}, {"timestamp": 1631538568725, "ltp": 2.14, "tv": 3532.33, "trd": NaN, "batb": [[2, 1.74, 360.53]], "batl": NaN}, {"timestamp": 1631538581967, "ltp": 2.2, "tv": 3535.21, "trd": [[2.2, 145.9]], "batb": NaN, "batl": [[0, 2.2, 11.1]]}, {"timestamp": 1631538587187, "ltp": 2.2, "tv": 3535.21, "trd": NaN, "batb": NaN, "batl": [[2, 2.8, 5.02]]}, {"timestamp": 1631538588082, "ltp": 2.2, "tv": 3535.21, "trd": NaN, "batb": [[0, 1.75, 33.8], [1, 1.74, 360.53], [2, 1.46, 2]], "batl": [[0, 2.92, 254.12], [1, 3.15, 4.5], [2, 3.2, 3.33]]}, {"timestamp": 1631538592102, "ltp": 2.2, "tv": 3535.6, "trd": [[2.2, 146.29]], "batb": NaN, "batl": NaN}, {"timestamp": 1631538594997, "ltp": 2.2, "tv": 3535.6, "trd": NaN, "batb": NaN, "batl": [[0, 2.78, 4.75], [1, 2.92, 254.12], [2, 3.15, 4.5]]}, {"timestamp": 1631538595305, "ltp": 2.2, "tv": 3535.6, "trd": NaN, "batb": NaN, "batl": [[0, 2.92, 254.12], [1, 3.15, 4.5], [2, 3.2, 3.33]]}, {"timestamp": 1631538598193, "ltp": 2.2, "tv": 3535.6, "trd": NaN, "batb": NaN, "batl": [[0, 2.8, 4.72], [1, 2.92, 254.12], [2, 3.15, 4.5]]}, {"timestamp": 1631538598505, "ltp": 2.2, "tv": 3535.6, "trd": NaN, "batb": NaN, "batl": [[0, 2.92, 254.12], [1, 3.15, 4.5], [2, 3.2, 3.33]]}, {"timestamp": 1631538607240, "ltp": 2.2, "tv": 3535.6, "trd": NaN, "batb": [[0, 2.62, 11.44], [1, 2.6, 5.72], [2, 2.58, 5.72]], "batl": [[0, 2.78, 9.71], [1, 3.2, 3.33], [2, 3.2, 0]]}, {"timestamp": 1631538608027, "ltp": 2.2, "tv": 3535.6, "trd": NaN, "batb": [[0, 2.62, 31.77]], "batl": [[1, 2.84, 52.82], [2, 2.86, 26.42]]}, {"timestamp": 1631538608606, "ltp": 2.2, "tv": 3535.6, "trd": NaN, "batb": NaN, "batl": [[1, 2.84, 10.56], [2, 2.86, 5.28]]}, {"timestamp": 1631538612159, "ltp": 2.84, "tv": 3549.47, "trd": [[2.78, 29.82], [2.84, 4.16]], "batb": NaN, "batl": [[0, 2.84, 6.4], [1, 2.86, 5.28], [2, 2.88, 5.28]]}, {"timestamp": 1631538625234, "ltp": 2.72, "tv": 3550.82, "trd": [[2.72, 3.69]], "batb": NaN, "batl": [[0, 2.84, 16.18]]}, {"timestamp": 1631538634260, "ltp": 2.72, "tv": 3550.82, "trd": NaN, "batb": [[0, 2.62, 20.33], [1, 2.1, 37.73], [2, 2.04, 354.13]], "batl": [[0, 3.9, 184.64], [1, 3.95, 2.9], [2, 4.1, 2.95]]}, {"timestamp": 1631538634933, "ltp": 2.72, "tv": 3550.82, "trd": NaN, "batb": [[0, 2.1, 37.73], [1, 2.04, 354.13], [2, 1.46, 2]], "batl": NaN}, {"timestamp": 1631538637274, "ltp": 2.72, "tv": 3550.82, "trd": NaN, "batb": NaN, "batl": [[1, 4.1, 2.95], [2, 4.1, 0]]}, {"timestamp": 1631538641035, "ltp": 2.72, "tv": 3550.82, "trd": NaN, "batb": NaN, "batl": [[0, 3.6, 3.11], [1, 3.9, 184.64], [2, 4.1, 2.95]]}, {"timestamp": 1631538641415, "ltp": 2.72, "tv": 3550.82, "trd": NaN, "batb": NaN, "batl": [[0, 3.9, 184.64], [1, 4.1, 2.95], [2, 4.1, 0]]}, {"timestamp": 1631538647971, "ltp": 2.72, "tv": 3550.82, "trd": NaN, "batb": NaN, "batl": [[0, 3.6, 3.46], [1, 3.9, 184.64], [2, 4.1, 2.95]]}, {"timestamp": 1631538649377, "ltp": 2.72, "tv": 3550.82, "trd": NaN, "batb": NaN, "batl": [[0, 3.9, 184.64], [1, 4.1, 2.95], [2, 4.1, 0]]}, {"timestamp": 1631538652192, "ltp": 2.72, "tv": 3550.82, "trd": NaN, "batb": [[1, 1.46, 2], [2, 1.23, 2]], "batl": [[0, 2.18, 55.04], [1, 2.22, 16.25], [2, 2.24, 14.21]]}, {"timestamp": 1631538653180, "ltp": 2.72, "tv": 3550.82, "trd": NaN, "batb": [[1, 1.75, 34.38], [2, 1.46, 2]], "batl": NaN}, {"timestamp": 1631538654908, "ltp": 2.72, "tv": 3550.82, "trd": NaN, "batb": [[2, 1.74, 360.53]], "batl": NaN}, {"timestamp": 1631538669224, "ltp": 2.18, "tv": 3554.42, "trd": [[2.18, 13.3]], "batb": NaN, "batl": [[0, 2.18, 53.24]]}, {"timestamp": 1631538670230, "ltp": 2.18, "tv": 3554.42, "trd": NaN, "batb": NaN, "batl": [[0, 2.22, 16.25], [1, 2.24, 14.21], [2, 2.4, 130.07]]}, {"timestamp": 1631538671121, "ltp": 2.18, "tv": 3554.42, "trd": NaN, "batb": [[0, 1.75, 34.38], [1, 1.74, 360.53], [2, 1.46, 2]], "batl": [[0, 2.92, 254.12], [1, 3.1, 4.15], [2, 4.1, 2.95]]}, {"timestamp": 1631538674625, "ltp": 2.18, "tv": 3554.42, "trd": NaN, "batb": [[1, 1.46, 2], [2, 1.23, 2]], "batl": [[0, 3.1, 4.15], [1, 4.1, 2.95], [2, 4.1, 0]]}, {"timestamp": 1631538675931, "ltp": 2.18, "tv": 3554.42, "trd": NaN, "batb": [[0, 2.64, 11.36], [1, 2.62, 5.68], [2, 2.6, 5.68]], "batl": [[0, 2.84, 12.38], [1, 3.1, 4.15]]}, {"timestamp": 1631538676819, "ltp": 2.18, "tv": 3554.42, "trd": NaN, "batb": [[2, 2.6, 26.43]], "batl": [[0, 2.84, 22.94], [1, 2.86, 5.28], [2, 2.88, 5.28]]}, {"timestamp": 1631538680747, "ltp": 2.84, "tv": 3560.98, "trd": [[2.84, 10.72]], "batb": NaN, "batl": [[0, 2.84, 16.38]]}, {"timestamp": 1631538690754, "ltp": 2.84, "tv": 3560.98, "trd": NaN, "batb": NaN, "batl": [[0, 2.84, 10.56]]}, {"timestamp": 1631538693287, "ltp": 2.84, "tv": 3560.98, "trd": NaN, "batb": [[0, 2.6, 20.75], [1, 2.1, 38.4], [2, 2.04, 354.13]], "batl": [[0, 3.1, 4.15], [1, 3.6, 3.06], [2, 3.9, 184.64]]}, {"timestamp": 1631538693866, "ltp": 2.84, "tv": 3560.98, "trd": NaN, "batb": [[0, 2.1, 38.4], [1, 2.04, 354.13], [2, 1.46, 2]], "batl": [[0, 3.6, 3.06], [1, 3.9, 184.64], [2, 4.1, 2.95]]}, {"timestamp": 1631538694442, "ltp": 2.84, "tv": 3560.98, "trd": NaN, "batb": NaN, "batl": [[0, 3.9, 184.64], [1, 4.1, 2.95], [2, 4.1, 0]]}, {"timestamp": 1631538696092, "ltp": 2.84, "tv": 3560.98, "trd": NaN, "batb": NaN, "batl": [[0, 2.72, 1.8]]}, {"timestamp": 1631538698181, "ltp": 2.84, "tv": 3560.98, "trd": NaN, "batb": NaN, "batl": [[1, 2.82, 21.75], [2, 4.1, 2.95]]}, {"timestamp": 1631538698493, "ltp": 2.84, "tv": 3560.98, "trd": NaN, "batb": NaN, "batl": [[1, 4.1, 2.95], [2, 4.1, 0]]}, {"timestamp": 1631538699482, "ltp": 2.84, "tv": 3560.98, "trd": NaN, "batb": NaN, "batl": [[1, 3.65, 198.3], [2, 4.1, 2.95]]}, {"timestamp": 1631538700776, "ltp": 2.84, "tv": 3560.98, "trd": NaN, "batb": NaN, "batl": [[1, 3.6, 3.31], [2, 3.65, 198.3]]}, {"timestamp": 1631538710320, "ltp": 2.84, "tv": 3560.98, "trd": NaN, "batb": [[1, 1.46, 2], [2, 1.23, 2]], "batl": [[2, 4.1, 2.95]]}, {"timestamp": 1631538711785, "ltp": 2.18, "tv": 3561.63, "trd": [[2.18, 13.95]], "batb": NaN, "batl": [[0, 2.18, 54.39], [1, 2.22, 16.25], [2, 2.24, 7.36]]}, {"timestamp": 1631538713097, "ltp": 2.18, "tv": 3561.63, "trd": NaN, "batb": [[1, 1.74, 34.89], [2, 1.46, 2]], "batl": NaN}, {"timestamp": 1631538714414, "ltp": 2.18, "tv": 3561.63, "trd": NaN, "batb": [[1, 1.74, 395.41]], "batl": NaN}, {"timestamp": 1631538725764, "ltp": 2.18, "tv": 3567.05, "trd": [[2.18, 19.37]], "batb": NaN, "batl": [[0, 2.18, 51.68]]}, {"timestamp": 1631538735263, "ltp": 2.18, "tv": 3567.05, "trd": NaN, "batb": NaN, "batl": [[0, 2.22, 16.25], [1, 2.24, 7.36], [2, 2.76, 4.52]]}, {"timestamp": 1631538735871, "ltp": 2.18, "tv": 3567.05, "trd": NaN, "batb": [[0, 1.74, 395.41], [1, 1.46, 2], [2, 1.23, 2]], "batl": [[0, 2.92, 254.12], [1, 3.1, 4.05], [2, 3.6, 3.31]]}, {"timestamp": 1631538746561, "ltp": 2.18, "tv": 3567.05, "trd": NaN, "batb": NaN, "batl": [[1, 3.1, 0], [2, 3.6, 0]]}, {"timestamp": 1631538749161, "ltp": 2.18, "tv": 3567.05, "trd": NaN, "batb": [[0, 1.76, 14.08], [1, 1.74, 34.89], [2, 1.46, 2]], "batl": [[0, 1.77, 1722.78], [1, 1.78, 117.98], [2, 1.8, 10.34]]}, {"timestamp": 1631538750258, "ltp": 2.18, "tv": 3567.05, "trd": NaN, "batb": [[1, 1.75, 31.03], [2, 1.74, 34.89]], "batl": [[0, 1.78, 73.04], [1, 1.8, 10.34], [2, 1.92, 215.66]]}, {"timestamp": 1631538754170, "ltp": 2.18, "tv": 3567.05, "trd": NaN, "batb": NaN, "batl": [[2, 1.92, 332.21]]}, {"timestamp": 1631538754381, "ltp": 2.18, "tv": 3567.05, "trd": NaN, "batb": NaN, "batl": [[2, 1.92, 215.66]]}, {"timestamp": 1631538764994, "ltp": 1.71, "tv": 3958.44, "trd": [[1.71, 224.47], [1.73, 57.77], [1.74, 90.66], [1.75, 74.17], [1.76, 101.72]], "batb": [[0, 1.69, 17.76], [1, 1.68, 8.88], [2, 1.67, 8.88]], "batl": [[0, 1.7, 932.88], [1, 1.78, 73.04], [2, 1.8, 10.34]]}, {"timestamp": 1631538767014, "ltp": 1.71, "tv": 3958.44, "trd": NaN, "batb": NaN, "batl": [[1, 1.76, 1.16], [2, 1.78, 73.04]]}, {"timestamp": 1631538768215, "ltp": 1.7, "tv": 4542.25, "trd": [[1.7, 615.01]], "batb": NaN, "batl": [[0, 1.7, 640.98]]}, {"timestamp": 1631538769110, "ltp": 1.7, "tv": 4613.19, "trd": [[1.7, 685.95]], "batb": NaN, "batl": [[0, 1.7, 605.51], [1, 1.76, 15.62]]}, {"timestamp": 1631538769585, "ltp": 1.7, "tv": 4673.19, "trd": [[1.7, 745.95]], "batb": NaN, "batl": [[0, 1.7, 575.51]]}, {"timestamp": 1631538771813, "ltp": 1.7, "tv": 4673.19, "trd": NaN, "batb": [[0, 1.69, 334.76]], "batl": NaN}, {"timestamp": 1631538776908, "ltp": 1.7, "tv": 4745.47, "trd": [[1.7, 818.23]], "batb": NaN, "batl": [[0, 1.7, 539.37]]}, {"timestamp": 1631538778108, "ltp": 1.7, "tv": 4772.12, "trd": [[1.7, 844.88]], "batb": NaN, "batl": [[0, 1.7, 526.05], [2, 1.78, 85.4]]}, {"timestamp": 1631538784930, "ltp": 1.7, "tv": 4845.58, "trd": [[1.7, 918.33]], "batb": NaN, "batl": [[0, 1.7, 489.32]]}, {"timestamp": 1631538788614, "ltp": 1.69, "tv": 4881.35, "trd": [[1.69, 35.78]], "batb": [[0, 1.69, 316.87]], "batl": [[2, 1.78, 73.04]]}, {"timestamp": 1631538791359, "ltp": 1.7, "tv": 4908.92, "trd": [[1.7, 945.9]], "batb": NaN, "batl": [[0, 1.7, 475.54]]}, {"timestamp": 1631538793036, "ltp": 1.7, "tv": 4983.7, "trd": [[1.7, 1020.68]], "batb": NaN, "batl": [[0, 1.7, 438.14]]}, {"timestamp": 1631538799180, "ltp": 1.7, "tv": 4983.86, "trd": [[1.7, 1020.84]], "batb": NaN, "batl": [[0, 1.7, 438.06]]}, {"timestamp": 1631538801058, "ltp": 1.7, "tv": 4983.86, "trd": NaN, "batb": [[0, 1.69, 354.94]], "batl": NaN}, {"timestamp": 1631538805065, "ltp": 1.7, "tv": 4995.04, "trd": [[1.7, 1032.02]], "batb": NaN, "batl": [[0, 1.7, 426.89], [1, 1.76, 1.16]]}, {"timestamp": 1631538806288, "ltp": 1.7, "tv": 4995.2, "trd": [[1.7, 1032.18]], "batb": NaN, "batl": [[0, 1.7, 426.81]]}, {"timestamp": 1631538808198, "ltp": 1.69, "tv": 5024.1, "trd": [[1.69, 64.68]], "batb": [[0, 1.69, 340.49]], "batl": NaN}, {"timestamp": 1631538812990, "ltp": 1.69, "tv": 5705.07, "trd": [[1.69, 745.65]], "batb": [[0, 1.68, 8.88], [1, 1.67, 8.88], [2, 1.57, 49.36]], "batl": [[0, 1.69, 42.28], [1, 1.7, 426.81], [2, 1.76, 1.16]]}, {"timestamp": 1631538817910, "ltp": 1.69, "tv": 5705.07, "trd": NaN, "batb": [[0, 1.68, 246.88]], "batl": [[2, 1.72, 11.03]]}, {"timestamp": 1631538824097, "ltp": 1.69, "tv": 5705.85, "trd": [[1.69, 746.43]], "batb": NaN, "batl": [[0, 1.69, 41.5]]}, {"timestamp": 1631538837304, "ltp": 1.69, "tv": 5733.72, "trd": [[1.69, 774.3]], "batb": NaN, "batl": [[0, 1.69, 27.56]]}, {"timestamp": 1631538853172, "ltp": 1.69, "tv": 5733.72, "trd": NaN, "batb": NaN, "batl": [[1, 1.72, 11.03], [2, 1.76, 1.16]]}, {"timestamp": 1631538854947, "ltp": 1.69, "tv": 5733.72, "trd": NaN, "batb": NaN, "batl": [[0, 1.72, 11.03], [1, 1.76, 1.16], [2, 1.78, 73.04]]}, {"timestamp": 1631538856141, "ltp": 1.69, "tv": 5733.72, "trd": NaN, "batb": [[0, 1.69, 6.97], [1, 1.68, 246.88], [2, 1.67, 8.88]], "batl": NaN}, {"timestamp": 1631538858172, "ltp": 1.68, "tv": 5753.72, "trd": [[1.68, 29.05], [1.69, 788.24]], "batb": [[0, 1.68, 243.85], [1, 1.67, 8.88], [2, 1.57, 49.36]], "batl": NaN}, {"timestamp": 1631538861287, "ltp": 1.68, "tv": 5753.72, "trd": NaN, "batb": NaN, "batl": [[0, 1.76, 1.16], [1, 1.78, 73.04], [2, 1.92, 215.66]]}, {"timestamp": 1631538861598, "ltp": 1.68, "tv": 5753.72, "trd": NaN, "batb": [[0, 1.68, 5.85]], "batl": NaN}, {"timestamp": 1631538863055, "ltp": 1.68, "tv": 5753.72, "trd": NaN, "batb": [[0, 1.68, 6.22]], "batl": NaN}, {"timestamp": 1631538864199, "ltp": 1.68, "tv": 5753.72, "trd": NaN, "batb": [[0, 1.68, 15.37]], "batl": NaN}, {"timestamp": 1631538868679, "ltp": 1.68, "tv": 5753.72, "trd": NaN, "batb": [[0, 1.68, 15]], "batl": NaN}, {"timestamp": 1631538875196, "ltp": 1.71, "tv": 5754.09, "trd": [[1.71, 224.84]], "batb": NaN, "batl": NaN}, {"timestamp": 1631538883935, "ltp": 1.71, "tv": 5754.09, "trd": NaN, "batb": [[0, 1.57, 49.36], [1, 1.46, 2], [2, 1.23, 2]], "batl": [[1, 2.02, 2.13], [2, 2.18, 7.25]]}, {"timestamp": 1631538885504, "ltp": 1.71, "tv": 5754.09, "trd": NaN, "batb": [[0, 1.71, 6.97], [1, 1.57, 49.36], [2, 1.46, 2]], "batl": NaN}, {"timestamp": 1631538887201, "ltp": 1.71, "tv": 5754.09, "trd": NaN, "batb": [[1, 1.56, 51.12]], "batl": NaN}, {"timestamp": 1631538895251, "ltp": 1.71, "tv": 5754.09, "trd": NaN, "batb": NaN, "batl": [[2, 2.06, 7.25]]}, {"timestamp": 1631538895514, "ltp": 1.71, "tv": 5754.09, "trd": NaN, "batb": NaN, "batl": [[2, 2.18, 7.25]]}, {"timestamp": 1631538897444, "ltp": 1.71, "tv": 5768.02, "trd": [[1.71, 238.77]], "batb": [[0, 1.56, 51.12], [1, 1.46, 2], [2, 1.23, 2]]