{"info": {"id": "1.187553973", "eventId": "30895619", "eventName": "Match Odds", "marketType": "MATCH_ODDS", "openDate": 1631458877242, "name": "M Kobori v E Bogdan", "numberOfActiveRunner": 2, "countryCode": "", "sport": "TENNIS", "venue": "", "volume": {"total": 310.07, "preMatch": 46.51, "inPlay": 263.56}, "winner": {"id": 7429606, "name": "E Bogdan", "status": "WINNER", "position": 2}, "delay": 5}, "runners": [{"id": 9631578, "name": "M Kobori", "status": "LOSER", "position": 1, "inPlayOdds": 1.17, "inPlayTime": 1631465711894, "avgPrematch": 0, "closedOdds": 1.59, "maxPrematch": -100, "minPrematch": 1001, "maxInPlay": 1.59, "minInPlay": 1.17, "inPlayIndex": 0, "lengthOdds": 37, "lengthOddsPrematch": 0, "lengthOddsInPlay": 37, "tradedVolume": 258.27, "preMatchVolume": 32.29, "inPlayVolume": 225.98}, {"id": 7429606, "name": "E Bogdan", "status": "WINNER", "position": 2, "inPlayOdds": 12.0, "inPlayTime": 1631464661151, "avgPrematch": 0, "closedOdds": 1.01, "maxPrematch": -100, "minPrematch": 1001, "maxInPlay": 12.0, "minInPlay": 1.01, "inPlayIndex": 0, "lengthOdds": 34, "lengthOddsPrematch": 0, "lengthOddsInPlay": 34, "tradedVolume": 51.8, "preMatchVolume": 14.22, "inPlayVolume": 37.58}], "marketUpdates": [{"timestamp": 1631450276579000000, "openDate": "2021-09-12T15:00:00.000Z", "status": "OPEN", "betDelay": 0, "inPlay": false, "complete": true}, {"timestamp": 1631458877242000000, "openDate": "2021-09-12T15:00:00.000Z", "status": "OPEN", "betDelay": 5, "inPlay": true, "complete": true}, {"timestamp": 1631462175189000000, "openDate": "2021-09-12T15:55:48.000Z", "status": "OPEN", "betDelay": 5, "inPlay": true, "complete": true}, {"timestamp": 1631467465098000000, "openDate": "2021-09-12T15:55:48.000Z", "status": "SUSPENDED", "betDelay": 5, "inPlay": true, "complete": true}, {"timestamp": 1631467471138000000, "openDate": "2021-09-12T15:55:48.000Z", "status": "CLOSED", "betDelay": 5, "inPlay": true, "complete": true}], "odds": [{"runnerId": 9631578, "odds": [{"timestamp": 1631465711894, "ltp": 1.17, "tv": 32.29, "trd": [[1.17, 32.3]], "batb": NaN, "batl": [[0, 1.21, 78.75], [1, 1.27, 43.52], [2, 1.5, 1.38]]}, {"timestamp": 1631465712686, "ltp": 1.17, "tv": 32.29, "trd": NaN, "batb": [[0, 1.17, 61.74], [1, 1.01, 7]], "batl": NaN}, {"timestamp": 1631465731645, "ltp": 1.21, "tv": 64.81, "trd": [[1.21, 32.52]], "batb": NaN, "batl": [[0, 1.21, 62.49]]}, {"timestamp": 1631465761776, "ltp": 1.21, "tv": 64.81, "trd": NaN, "batb": [[0, 1.01, 7], [1, 1.01, 0]], "batl": NaN}, {"timestamp": 1631465766924, "ltp": 1.21, "tv": 188.29, "trd": [[1.21, 156]], "batb": NaN, "batl": [[0, 1.27, 44.27], [1, 1.5, 1.38], [2, 1.5, 0]]}, {"timestamp": 1631465958244, "ltp": 1.21, "tv": 188.29, "trd": NaN, "batb": NaN, "batl": [[0, 1.27, 43.52]]}, {"timestamp": 1631465963376, "ltp": 1.21, "tv": 188.29, "trd": NaN, "batb": NaN, "batl": [[0, 1.27, 20.9]]}, {"timestamp": 1631466134463, "ltp": 1.27, "tv": 213.98, "trd": [[1.27, 25.69]], "batb": NaN, "batl": [[0, 1.27, 8.05]]}, {"timestamp": 1631466138289, "ltp": 1.27, "tv": 230.09, "trd": [[1.27, 41.8]], "batb": [[0, 1.27, 45.2], [1, 1.01, 7]], "batl": [[0, 1.5, 1.38], [1, 1.5, 0]]}, {"timestamp": 1631466139295, "ltp": 1.27, "tv": 230.09, "trd": NaN, "batb": [[0, 1.27, 12.84]], "batl": NaN}, {"timestamp": 1631466139400, "ltp": 1.27, "tv": 230.09, "trd": NaN, "batb": [[0, 1.01, 7], [1, 1.01, 0]], "batl": NaN}, {"timestamp": 1631466223186, "ltp": 1.27, "tv": 230.09, "trd": NaN, "batb": NaN, "batl": [[1, 1.88, 13.99]]}, {"timestamp": 1631466238501, "ltp": 1.27, "tv": 230.09, "trd": NaN, "batb": NaN, "batl": [[2, 5.9, 14.16]]}, {"timestamp": 1631466245305, "ltp": 1.27, "tv": 230.09, "trd": NaN, "batb": NaN, "batl": [[2, 5.9, 0]]}, {"timestamp": 1631466250392, "ltp": 1.27, "tv": 230.09, "trd": NaN, "batb": NaN, "batl": [[2, 4.7, 14.16]]}, {"timestamp": 1631466258505, "ltp": 1.27, "tv": 230.09, "trd": NaN, "batb": NaN, "batl": [[2, 4.7, 31.43]]}, {"timestamp": 1631466591128, "ltp": 1.27, "tv": 230.09, "trd": NaN, "batb": NaN, "batl": [[1, 4.7, 31.43], [2, 4.7, 0]]}, {"timestamp": 1631466596215, "ltp": 1.27, "tv": 230.09, "trd": NaN, "batb": NaN, "batl": [[1, 1.68, 13.99], [2, 4.7, 31.43]]}, {"timestamp": 1631466662493, "ltp": 1.27, "tv": 230.09, "trd": NaN, "batb": NaN, "batl": [[1, 1.68, 0], [2, 4.7, 0]]}, {"timestamp": 1631466668609, "ltp": 1.27, "tv": 230.09, "trd": NaN, "batb": [[0, 1.25, 10.85], [1, 1.01, 7]], "batl": NaN}, {"timestamp": 1631466675805, "ltp": 1.25, "tv": 246.35, "trd": [[1.25, 16.26]], "batb": [[0, 1.25, 2.71]], "batl": NaN}, {"timestamp": 1631466678305, "ltp": 1.25, "tv": 251.77, "trd": [[1.25, 21.68]], "batb": [[0, 1.01, 7], [1, 1.01, 0]], "batl": [[0, 1.25, 7.21], [1, 1.5, 1.38]]}, {"timestamp": 1631466678673, "ltp": 1.25, "tv": 251.77, "trd": NaN, "batb": NaN, "batl": [[0, 1.5, 1.38], [1, 1.5, 0]]}, {"timestamp": 1631466688621, "ltp": 1.25, "tv": 251.77, "trd": NaN, "batb": [[0, 1.15, 18.08], [1, 1.01, 7]], "batl": NaN}, {"timestamp": 1631466701905, "ltp": 1.25, "tv": 251.77, "trd": NaN, "batb": NaN, "batl": [[1, 1.67, 7.23]]}, {"timestamp": 1631466720221, "ltp": 1.25, "tv": 251.77, "trd": NaN, "batb": [[1, 1.02, 25.31], [2, 1.01, 7]], "batl": NaN}, {"timestamp": 1631466724760, "ltp": 1.25, "tv": 251.77, "trd": NaN, "batb": NaN, "batl": [[1, 1.67, 0]]}, {"timestamp": 1631466729859, "ltp": 1.25, "tv": 251.77, "trd": NaN, "batb": NaN, "batl": [[1, 1.59, 7.23]]}, {"timestamp": 1631466762386, "ltp": 1.25, "tv": 251.77, "trd": NaN, "batb": [[0, 1.15, 13.74]], "batl": NaN}, {"timestamp": 1631466958319, "ltp": 1.25, "tv": 251.77, "trd": NaN, "batb": [[0, 1.02, 25.31], [1, 1.01, 7], [2, 1.01, 0]], "batl": NaN}, {"timestamp": 1631466962111, "ltp": 1.25, "tv": 251.77, "trd": NaN, "batb": [[0, 1.02, 18.08]], "batl": NaN}, {"timestamp": 1631466972623, "ltp": 1.25, "tv": 251.77, "trd": NaN, "batb": NaN, "batl": [[0, 1.59, 7.23], [1, 1.59, 0]]}, {"timestamp": 1631467023096, "ltp": 1.25, "tv": 251.77, "trd": NaN, "batb": NaN, "batl": [[0, 1.59, 6.51]]}, {"timestamp": 1631467062151, "ltp": 1.59, "tv": 258.27, "trd": [[1.59, 6.49]], "batb": NaN, "batl": [[0, 1.59, 0.01]]}, {"timestamp": 1631467211919, "ltp": 1.59, "tv": 258.27, "trd": NaN, "batb": [[0, 1.02, 7.23]], "batl": NaN}, {"timestamp": 1631467415909, "ltp": 1.59, "tv": 258.27, "trd": NaN, "batb": [[0, 1.15, 10.85], [1, 1.02, 7.23], [2, 1.01, 7]], "batl": NaN}, {"timestamp": 1631467439120, "ltp": 1.59, "tv": 258.27, "trd": NaN, "batb": [[0, 2, 13.01], [1, 1.15, 10.85], [2, 1.02, 7.23]], "batl": NaN}]}, {"runnerId": 7429606, "odds": [{"timestamp": 1631464661151, "ltp": 12.0, "tv": 14.22, "trd": [[12, 14.23]], "batb": [[0, 12, 5.32]], "batl": NaN}, {"timestamp": 1631464673775, "ltp": 12.0, "tv": 14.22, "trd": NaN, "batb": [[0, 6, 14.51], [1, 4, 13.47], [2, 1.01, 7]], "batl": NaN}, {"timestamp": 1631464699279, "ltp": 12.0, "tv": 14.22, "trd": NaN, "batb": [[0, 4, 13.47], [1, 1.01, 7], [2, 1.01, 0]], "batl": NaN}, {"timestamp": 1631464704424, "ltp": 12.0, "tv": 14.22, "trd": NaN, "batb": [[0, 7, 14.51], [1, 4, 13.47], [2, 1.01, 7]], "batl": NaN}, {"timestamp": 1631464734028, "ltp": 12.0, "tv": 14.22, "trd": NaN, "batb": [[0, 4, 13.47], [1, 1.01, 7], [2, 1.01, 0]], "batl": NaN}, {"timestamp": 1631464739105, "ltp": 12.0, "tv": 14.22, "trd": NaN, "batb": [[0, 7.8, 14.51], [1, 4, 13.47], [2, 1.01, 7]], "batl": NaN}, {"timestamp": 1631464949949, "ltp": 12.0, "tv": 14.22, "trd": NaN, "batb": [[0, 4, 13.47], [1, 1.01, 7], [2, 1.01, 0]], "batl": NaN}, {"timestamp": 1631464955015, "ltp": 12.0, "tv": 14.22, "trd": NaN, "batb": [[0, 6.8, 14.51], [1, 4, 13.47], [2, 1.01, 7]], "batl": NaN}, {"timestamp": 1631464961022, "ltp": 12.0, "tv": 14.22, "trd": NaN, "batb": [[0, 6.8, 7.08]], "batl": NaN}, {"timestamp": 1631465401463, "ltp": 6.8, "tv": 22.76, "trd": [[6.8, 8.54]], "batb": [[0, 6.8, 2.81]], "batl": NaN}, {"timestamp": 1631465536893, "ltp": 6.8, "tv": 22.76, "trd": NaN, "batb": [[0, 4, 13.47], [1, 1.01, 7], [2, 1.01, 0]], "batl": NaN}, {"timestamp": 1631465542000, "ltp": 6.8, "tv": 22.76, "trd": NaN, "batb": [[0, 5.8, 2.81], [1, 4, 13.47], [2, 1.01, 7]], "batl": NaN}, {"timestamp": 1631465648757, "ltp": 6.8, "tv": 22.76, "trd": NaN, "batb": [[2, 1.25, 11.57]], "batl": NaN}, {"timestamp": 1631465711894, "ltp": 6.8, "tv": 28.32, "trd": [[6.8, 14.1]], "batb": NaN, "batl": NaN}, {"timestamp": 1631465734726, "ltp": 6.8, "tv": 28.32, "trd": NaN, "batb": NaN, "batl": [[0, 1000, 3.42]]}, {"timestamp": 1631465740816, "ltp": 5.8, "tv": 33.94, "trd": [[5.8, 5.62]], "batb": [[0, 4, 13.47], [1, 1.25, 11.57], [2, 1.01, 7]], "batl": NaN}, {"timestamp": 1631465972245, "ltp": 5.8, "tv": 33.94, "trd": NaN, "batb": [[0, 1.25, 11.57], [1, 1.01, 7], [2, 1.01, 0]], "batl": NaN}, {"timestamp": 1631465977361, "ltp": 5.8, "tv": 33.94, "trd": NaN, "batb": [[0, 3.85, 13.47], [1, 1.25, 11.57], [2, 1.01, 7]], "batl": NaN}, {"timestamp": 1631465983208, "ltp": 5.8, "tv": 33.94, "trd": NaN, "batb": [[0, 1.25, 11.57], [1, 1.01, 7], [2, 1.01, 0]], "batl": NaN}, {"timestamp": 1631465988274, "ltp": 5.8, "tv": 33.94, "trd": NaN, "batb": [[0, 3.65, 13.47], [1, 1.25, 11.57], [2, 1.01, 7]], "batl": NaN}, {"timestamp": 1631466207891, "ltp": 5.8, "tv": 33.94, "trd": NaN, "batb": [[0, 1.25, 11.57], [1, 1.01, 7], [2, 1.01, 0]], "batl": NaN}, {"timestamp": 1631466622037, "ltp": 5.8, "tv": 33.94, "trd": NaN, "batb": [[0, 1.01, 7], [1, 1.01, 0]], "batl": NaN}, {"timestamp": 1631466627134, "ltp": 5.8, "tv": 33.94, "trd": NaN, "batb": [[0, 1.29, 11.57], [1, 1.01, 7]], "batl": NaN}, {"timestamp": 1631466966730, "ltp": 5.8, "tv": 33.94, "trd": NaN, "batb": [[0, 1.01, 7], [1, 1.01, 0]], "batl": NaN}, {"timestamp": 1631466971824, "ltp": 5.8, "tv": 33.94, "trd": NaN, "batb": [[0, 1.12, 11.57], [1, 1.01, 7]], "batl": NaN}, {"timestamp": 1631467062151, "ltp": 2.68, "tv": 37.8, "trd": [[2.68, 3.85]], "batb": NaN, "batl": NaN}, {"timestamp": 1631467096086, "ltp": 2.68, "tv": 37.8, "trd": NaN, "batb": [[0, 1.12, 7.95]], "batl": NaN}, {"timestamp": 1631467157250, "ltp": 2.68, "tv": 37.8, "trd": NaN, "batb": [[0, 1.5, 2.89], [1, 1.12, 7.95], [2, 1.01, 7]], "batl": NaN}, {"timestamp": 1631467390560, "ltp": 2.68, "tv": 37.8, "trd": NaN, "batb": [[1, 1.12, 6.51]], "batl": NaN}, {"timestamp": 1631467403978, "ltp": 2.68, "tv": 37.8, "trd": NaN, "batb": [[0, 1.12, 6.51], [1, 1.01, 7], [2, 1.01, 0]], "batl": NaN}, {"timestamp": 1631467405388, "ltp": 2.68, "tv": 37.8, "trd": NaN, "batb": [[0, 1.01, 7], [1, 1.01, 0]], "batl": NaN}, {"timestamp": 1631467428099, "ltp": 2.68, "tv": 37.8, "trd": NaN, "batb": [[0, 1.05, 2.89], [1, 1.01, 7]], "batl": NaN}, {"timestamp": 1631467429541, "ltp": 2.68, "tv": 37.8, "trd": NaN, "batb": [[0, 1.01, 7], [1, 1.01, 0]], "batl": NaN}, {"timestamp": 1631467459250, "ltp": 1.01, "tv": 51.8, "trd": [[1.01, 14]], "batb": NaN, "batl": [[0, 1.01, 6634.9]]}]}]}