{"info": {"id": "1.187557759", "eventId": "30896122", "eventName": "Match Odds", "marketType": "MATCH_ODDS", "openDate": 1631535419336, "name": "Kuhn v Martineau", "numberOfActiveRunner": 2, "countryCode": "", "sport": "TENNIS", "venue": "", "volume": {"total": 43035.91, "preMatch": 2192.03, "inPlay": 40843.88}, "winner": {"id": 9634485, "name": "Nicola Kuhn", "status": "WINNER", "position": 1}, "delay": 3}, "runners": [{"id": 9634485, "name": "Nicola Kuhn", "status": "WINNER", "position": 1, "inPlayOdds": 1.69, "inPlayTime": 1631535419336, "avgPrematch": 1.82, "closedOdds": 1.01, "maxPrematch": 2.3, "minPrematch": 1.67, "maxInPlay": 1.95, "minInPlay": 1.01, "inPlayIndex": 132, "lengthOdds": 1668, "lengthOddsPrematch": 132, "lengthOddsInPlay": 1536, "tradedVolume": 41316.71, "preMatchVolume": 1275.95, "inPlayVolume": 40040.76}, {"id": 9712888, "name": "Matteo Martineau", "status": "LOSER", "position": 2, "inPlayOdds": 2.46, "inPlayTime": 1631535419336, "avgPrematch": 2.15, "closedOdds": 140.0, "maxPrematch": 2.48, "minPrematch": 1.76, "maxInPlay": 140.0, "minInPlay": 2.06, "inPlayIndex": 93, "lengthOdds": 966, "lengthOddsPrematch": 93, "lengthOddsInPlay": 873, "tradedVolume": 1719.2, "preMatchVolume": 916.08, "inPlayVolume": 803.12}], "marketUpdates": [{"timestamp": 1631462832250000000, "openDate": "2021-09-13T11:00:00.000Z", "status": "OPEN", "betDelay": 0, "inPlay": false, "complete": true}, {"timestamp": 1631523421630000000, "openDate": "2021-09-13T10:54:00.000Z", "status": "OPEN", "betDelay": 0, "inPlay": false, "complete": true}, {"timestamp": 1631530662649000000, "openDate": "2021-09-13T11:09:00.000Z", "status": "OPEN", "betDelay": 0, "inPlay": false, "complete": true}, {"timestamp": 1631531519289000000, "openDate": "2021-09-13T11:24:00.000Z", "status": "OPEN", "betDelay": 0, "inPlay": false, "complete": true}, {"timestamp": 1631532419326000000, "openDate": "2021-09-13T11:39:00.000Z", "status": "OPEN", "betDelay": 0, "inPlay": false, "complete": true}, {"timestamp": 1631533320164000000, "openDate": "2021-09-13T11:54:00.000Z", "status": "OPEN", "betDelay": 0, "inPlay": false, "complete": true}, {"timestamp": 1631534256138000000, "openDate": "2021-09-13T12:09:00.000Z", "status": "OPEN", "betDelay": 0, "inPlay": false, "complete": true}, {"timestamp": 1631534819053000000, "openDate": "2021-09-13T12:06:00.000Z", "status": "OPEN", "betDelay": 0, "inPlay": false, "complete": true}, {"timestamp": 1631535419336000000, "openDate": "2021-09-13T12:06:00.000Z", "status": "OPEN", "betDelay": 3, "inPlay": true, "complete": true}, {"timestamp": 1631540505757000000, "openDate": "2021-09-13T12:06:00.000Z", "status": "SUSPENDED", "betDelay": 3, "inPlay": true, "complete": true}, {"timestamp": 1631540556996000000, "openDate": "2021-09-13T12:06:00.000Z", "status": "CLOSED", "betDelay": 3, "inPlay": true, "complete": true}], "odds": [{"runnerId": 9634485, "odds": [{"timestamp": 1631495087165, "ltp": 1.67, "tv": 23.24, "trd": [[1.67, 18.94], [1.68, 4.3]], "batb": [[0, 1.67, 30.18], [1, 1.31, 29.01], [2, 1.3, 767.98]], "batl": NaN}, {"timestamp": 1631495091409, "ltp": 1.67, "tv": 23.24, "trd": NaN, "batb": [[0, 1.67, 39.65]], "batl": NaN}, {"timestamp": 1631501873395, "ltp": 1.67, "tv": 23.24, "trd": NaN, "batb": [[0, 1.67, 41.03]], "batl": NaN}, {"timestamp": 1631502011889, "ltp": 1.67, "tv": 23.23, "trd": NaN, "batb": [[1, 1.31, 29.01], [2, 1.3, 767.79]], "batl": NaN}, {"timestamp": 1631504968726, "ltp": 1.9, "tv": 48.23, "trd": [[1.9, 25]], "batb": NaN, "batl": [[0, 2.2, 47.98]]}, {"timestamp": 1631504969748, "ltp": 1.9, "tv": 48.23, "trd": NaN, "batb": [[0, 1.74, 9.31], [1, 1.67, 41.03], [2, 1.31, 29.01]], "batl": [[0, 3.85, 56.23]]}, {"timestamp": 1631504970520, "ltp": 1.9, "tv": 48.23, "trd": NaN, "batb": NaN, "batl": [[0, 3.8, 27.32]]}, {"timestamp": 1631505269422, "ltp": 1.9, "tv": 48.23, "trd": NaN, "batb": NaN, "batl": [[0, 2.6, 107.83]]}, {"timestamp": 1631505480039, "ltp": 1.9, "tv": 48.23, "trd": NaN, "batb": NaN, "batl": [[0, 2.52, 40.52]]}, {"timestamp": 1631505923776, "ltp": 1.9, "tv": 48.23, "trd": NaN, "batb": [[0, 1.67, 41.03], [1, 1.31, 29.01], [2, 1.3, 767.79]], "batl": [[0, 990, 2.2], [1, 990, 0]]}, {"timestamp": 1631505924083, "ltp": 1.9, "tv": 48.23, "trd": NaN, "batb": [[0, 1.77, 23.8], [1, 1.67, 41.03], [2, 1.31, 29.01]], "batl": [[0, 3.75, 59.8], [1, 990, 2.2]]}, {"timestamp": 1631507224277, "ltp": 1.9, "tv": 76.07, "trd": [[1.9, 52.84]], "batb": NaN, "batl": NaN}, {"timestamp": 1631507484619, "ltp": 1.9, "tv": 215.25, "trd": [[1.9, 192.01]], "batb": NaN, "batl": NaN}, {"timestamp": 1631507485438, "ltp": 1.9, "tv": 215.25, "trd": NaN, "batb": [[0, 1.67, 41.03], [1, 1.31, 29.01], [2, 1.3, 767.79]], "batl": NaN}, {"timestamp": 1631508385342, "ltp": 1.9, "tv": 215.25, "trd": NaN, "batb": [[0, 1.7, 10.6], [1, 1.67, 41.03], [2, 1.31, 29.01]], "batl": NaN}, {"timestamp": 1631508385957, "ltp": 1.9, "tv": 215.25, "trd": NaN, "batb": [[0, 1.67, 41.03], [1, 1.31, 29.01], [2, 1.3, 767.79]], "batl": NaN}, {"timestamp": 1631508685376, "ltp": 1.9, "tv": 215.25, "trd": NaN, "batb": [[0, 1.71, 10.53], [1, 1.67, 41.03], [2, 1.31, 29.01]], "batl": NaN}, {"timestamp": 1631508685888, "ltp": 1.9, "tv": 215.25, "trd": NaN, "batb": [[0, 1.67, 41.03], [1, 1.31, 29.01], [2, 1.3, 767.79]], "batl": NaN}, {"timestamp": 1631509202665, "ltp": 1.9, "tv": 215.25, "trd": NaN, "batb": [[0, 1.67, 57.85]], "batl": NaN}, {"timestamp": 1631509285445, "ltp": 1.9, "tv": 215.08, "trd": [[1.67, 18.95], [1.68, 4.31], [1.9, 191.84]], "batb": [[0, 1.7, 10.6], [1, 1.67, 57.85], [2, 1.31, 29.01]], "batl": NaN}, {"timestamp": 1631509285854, "ltp": 1.9, "tv": 215.08, "trd": NaN, "batb": [[0, 1.67, 57.85], [1, 1.31, 29.01], [2, 1.3, 767.85]], "batl": NaN}, {"timestamp": 1631509585568, "ltp": 1.9, "tv": 215.08, "trd": NaN, "batb": [[0, 1.7, 10.6], [1, 1.67, 57.85], [2, 1.31, 29.01]], "batl": NaN}, {"timestamp": 1631509586338, "ltp": 1.9, "tv": 215.08, "trd": NaN, "batb": [[0, 1.68, 26.14]], "batl": [[0, 3.25, 77.01]]}, {"timestamp": 1631509824348, "ltp": 1.9, "tv": 215.08, "trd": NaN, "batb": NaN, "batl": [[0, 2.52, 132.54]]}, {"timestamp": 1631510664766, "ltp": 1.9, "tv": 215.08, "trd": NaN, "batb": [[2, 1.36, 49.21]], "batl": NaN}, {"timestamp": 1631511241834, "ltp": 1.9, "tv": 215.08, "trd": NaN, "batb": [[0, 1.67, 57.85], [1, 1.36, 49.21], [2, 1.31, 29.01]], "batl": [[0, 2, 3]]}, {"timestamp": 1631511241937, "ltp": 1.9, "tv": 215.08, "trd": NaN, "batb": [[0, 1.68, 26.14], [1, 1.67, 57.85], [2, 1.36, 49.21]], "batl": NaN}, {"timestamp": 1631511394054, "ltp": 1.9, "tv": 215.08, "trd": NaN, "batb": NaN, "batl": [[0, 2, 3.1]]}, {"timestamp": 1631511402368, "ltp": 1.9, "tv": 215.18, "trd": [[1.9, 191.94]], "batb": NaN, "batl": [[0, 2, 3]]}, {"timestamp": 1631511456672, "ltp": 1.9, "tv": 215.18, "trd": NaN, "batb": NaN, "batl": [[1, 46, 29.03], [2, 990, 2.2]]}, {"timestamp": 1631512006467, "ltp": 1.9, "tv": 215.18, "trd": NaN, "batb": NaN, "batl": [[1, 2.34, 2.66], [2, 46, 29.03]]}, {"timestamp": 1631512496119, "ltp": 2.0, "tv": 218.18, "trd": [[2, 3]], "batb": NaN, "batl": [[0, 2.3, 66.11]]}, {"timestamp": 1631512613541, "ltp": 2.0, "tv": 221.18, "trd": [[2, 6]], "batb": NaN, "batl": NaN}, {"timestamp": 1631512796204, "ltp": 2.0, "tv": 221.18, "trd": NaN, "batb": NaN, "batl": [[0, 2.34, 2.66], [1, 46, 29.03], [2, 990, 2.2]]}, {"timestamp": 1631513503353, "ltp": 2.0, "tv": 221.18, "trd": NaN, "batb": [[0, 1.67, 57.85], [1, 1.36, 49.21], [2, 1.31, 29.01]], "batl": NaN}, {"timestamp": 1631513642306, "ltp": 2.0, "tv": 221.18, "trd": NaN, "batb": [[0, 1.69, 10.66], [1, 1.67, 57.85], [2, 1.36, 49.21]], "batl": [[0, 2.3, 4.74], [1, 2.34, 2.66], [2, 46, 29.03]]}, {"timestamp": 1631514445554, "ltp": 2.0, "tv": 221.18, "trd": NaN, "batb": [[0, 1.67, 57.85], [1, 1.36, 49.21], [2, 1.31, 29.01]], "batl": NaN}, {"timestamp": 1631514542479, "ltp": 2.0, "tv": 221.18, "trd": NaN, "batb": [[0, 1.69, 10.66], [1, 1.67, 57.85], [2, 1.36, 49.21]], "batl": [[0, 2.32, 198.39]]}, {"timestamp": 1631514675717, "ltp": 2.0, "tv": 221.18, "trd": NaN, "batb": [[0, 1.67, 57.85], [1, 1.36, 49.21], [2, 1.31, 29.01]], "batl": NaN}, {"timestamp": 1631514793633, "ltp": 2.0, "tv": 221.18, "trd": NaN, "batb": [[1, 1.42, 97.66], [2, 1.36, 49.21]], "batl": NaN}, {"timestamp": 1631516036711, "ltp": 2.0, "tv": 221.18, "trd": NaN, "batb": [[0, 1.67, 7.38], [1, 1.62, 54.54], [2, 1.42, 97.66]], "batl": [[0, 2.34, 2.66], [1, 46, 29.03], [2, 990, 2.2]]}, {"timestamp": 1631516042207, "ltp": 2.0, "tv": 221.18, "trd": NaN, "batb": [[0, 1.68, 5.31], [1, 1.67, 7.38], [2, 1.62, 54.54]], "batl": NaN}, {"timestamp": 1631516276997, "ltp": 2.0, "tv": 221.18, "trd": NaN, "batb": [[0, 1.67, 7.38], [1, 1.62, 54.54], [2, 1.42, 97.66]], "batl": NaN}, {"timestamp": 1631516642283, "ltp": 2.0, "tv": 221.54, "trd": [[1.67, 18.97], [1.68, 4.31], [1.9, 192.27]], "batb": [[0, 1.68, 5.31], [1, 1.67, 7.38], [2, 1.62, 54.54]], "batl": [[0, 2.34, 2.66], [1, 46, 29.07]]}, {"timestamp": 1631516757974, "ltp": 2.0, "tv": 221.54, "trd": NaN, "batb": [[0, 1.67, 7.38], [1, 1.62, 54.54], [2, 1.42, 97.78]], "batl": NaN}, {"timestamp": 1631516995949, "ltp": 2.0, "tv": 221.54, "trd": NaN, "batb": [[0, 1.9, 28.16], [1, 1.67, 7.38], [2, 1.62, 54.54]], "batl": NaN}, {"timestamp": 1631519482424, "ltp": 2.0, "tv": 221.54, "trd": NaN, "batb": [[0, 1.91, 3.04], [1, 1.9, 28.16], [2, 1.67, 7.38]], "batl": [[1, 2.7, 4.26], [2, 46, 29.07]]}, {"timestamp": 1631519509568, "ltp": 2.3, "tv": 227.09, "trd": [[2.3, 5.55]], "batb": NaN, "batl": [[0, 2.3, 2.99], [1, 2.34, 2.66], [2, 2.7, 4.26]]}, {"timestamp": 1631519509980, "ltp": 2.3, "tv": 227.09, "trd": NaN, "batb": [[0, 1.9, 28.16], [1, 1.67, 7.38], [2, 1.62, 54.54]], "batl": NaN}, {"timestamp": 1631519515465, "ltp": 2.06, "tv": 234.35, "trd": [[2.06, 7.26]], "batb": NaN, "batl": [[0, 2.06, 78.07], [1, 2.3, 2.99], [2, 2.34, 2.66]]}, {"timestamp": 1631519521590, "ltp": 1.9, "tv": 236.11, "trd": [[1.9, 194.03]], "batb": [[0, 1.9, 26.39]], "batl": NaN}, {"timestamp": 1631519526776, "ltp": 1.9, "tv": 262.51, "trd": [[1.9, 220.42]], "batb": [[0, 1.67, 7.38], [1, 1.62, 54.54], [2, 1.36, 49.28]], "batl": NaN}, {"timestamp": 1631519531595, "ltp": 1.9, "tv": 262.51, "trd": NaN, "batb": NaN, "batl": [[0, 2.06, 83.61]]}, {"timestamp": 1631519533600, "ltp": 1.9, "tv": 262.51, "trd": NaN, "batb": NaN, "batl": [[0, 2, 72.43], [1, 2.06, 83.61], [2, 2.3, 2.99]]}, {"timestamp": 1631519552743, "ltp": 1.7, "tv": 269.75, "trd": [[1.7, 7.24]], "batb": NaN, "batl": [[0, 2.06, 172.98], [1, 2.3, 2.99], [2, 2.34, 2.66]]}, {"timestamp": 1631519553052, "ltp": 1.7, "tv": 269.75, "trd": NaN, "batb": NaN, "batl": [[0, 2.06, 83.61]]}, {"timestamp": 1631519565330, "ltp": 1.7, "tv": 269.75, "trd": NaN, "batb": [[0, 1.71, 3.8], [1, 1.67, 7.38], [2, 1.62, 54.54]], "batl": NaN}, {"timestamp": 1631520387962, "ltp": 1.7, "tv": 269.75, "trd": NaN, "batb": [[2, 1.62, 50.52]], "batl": NaN}, {"timestamp": 1631520971726, "ltp": 1.7, "tv": 269.75, "trd": NaN, "batb": [[0, 1.67, 7.38], [1, 1.62, 50.52], [2, 1.36, 49.28]], "batl": NaN}, {"timestamp": 1631521722870, "ltp": 1.7, "tv": 269.75, "trd": NaN, "batb": NaN, "batl": [[0, 2.06, 5.54], [1, 2.34, 2.66], [2, 46, 29.07]]}, {"timestamp": 1631521894699, "ltp": 1.7, "tv": 269.75, "trd": NaN, "batb": [[0, 1.83, 34.13], [1, 1.67, 7.38], [2, 1.62, 50.52]], "batl": [[0, 2.34, 2.66], [1, 46, 29.07], [2, 990, 2.2]]}, {"timestamp": 1631521895009, "ltp": 1.7, "tv": 269.75, "trd": NaN, "batb": NaN, "batl": [[0, 2.2, 215.1], [1, 2.34, 2.66], [2, 46, 29.07]]}, {"timestamp": 1631521988689, "ltp": 1.7, "tv": 269.75, "trd": NaN, "batb": NaN, "batl": [[0, 2.34, 75.21], [1, 46, 29.07], [2, 990, 2.2]]}, {"timestamp": 1631521989411, "ltp": 1.7, "tv": 269.75, "trd": NaN, "batb": NaN, "batl": [[0, 2.34, 2.66]]}, {"timestamp": 1631521990801, "ltp": 1.7, "tv": 269.75, "trd": NaN, "batb": NaN, "batl": [[0, 2.32, 116.18], [1, 2.34, 2.66], [2, 46, 29.07]]}, {"timestamp": 1631522290829, "ltp": 1.7, "tv": 269.75, "trd": NaN, "batb": NaN, "batl": [[0, 2.34, 2.66], [1, 46, 29.07], [2, 990, 2.2]]}, {"timestamp": 1631522291341, "ltp": 1.7, "tv": 269.75, "trd": NaN, "batb": NaN, "batl": [[0, 2.26, 119.21], [1, 2.34, 2.66], [2, 46, 29.07]]}, {"timestamp": 1631522326965, "ltp": 1.7, "tv": 269.75, "trd": NaN, "batb": NaN, "batl": [[0, 2.22, 296.27]]}, {"timestamp": 1631522339214, "ltp": 1.7, "tv": 269.75, "trd": NaN, "batb": NaN, "batl": [[0, 2.2, 121.45]]}, {"timestamp": 1631522348637, "ltp": 1.7, "tv": 269.75, "trd": NaN, "batb": NaN, "batl": [[0, 2.2, 184.93]]}, {"timestamp": 1631522349153, "ltp": 1.7, "tv": 269.75, "trd": NaN, "batb": NaN, "batl": [[0, 2.2, 74.09]]}, {"timestamp": 1631522386076, "ltp": 1.7, "tv": 269.75, "trd": NaN, "batb": [[1, 1.67, 54.13], [2, 1.36, 49.28]], "batl": NaN}, {"timestamp": 1631522429754, "ltp": 1.88, "tv": 272.24, "trd": [[1.88, 2.49]], "batb": NaN, "batl": NaN}, {"timestamp": 1631522591193, "ltp": 1.88, "tv": 272.24, "trd": NaN, "batb": NaN, "batl": [[0, 2.08, 39.83]]}, {"timestamp": 1631522754782, "ltp": 1.88, "tv": 272.24, "trd": NaN, "batb": [[2, 1.42, 97.78]], "batl": [[2, 2.8, 44.04]]}, {"timestamp": 1631522763787, "ltp": 1.88, "tv": 272.24, "trd": NaN, "batb": [[2, 1.36, 49.28]], "batl": [[2, 46, 29.07]]}, {"timestamp": 1631523092829, "ltp": 1.88, "tv": 272.24, "trd": NaN, "batb": [[2, 1.42, 46.62]], "batl": NaN}, {"timestamp": 1631523093036, "ltp": 1.88, "tv": 272.24, "trd": NaN, "batb": NaN, "batl": [[0, 2.06, 6.83], [1, 2.08, 39.83], [2, 2.34, 2.66]]}, {"timestamp": 1631523191199, "ltp": 1.88, "tv": 272.24, "trd": NaN, "batb": NaN, "batl": [[0, 2.04, 40.61], [1, 2.06, 6.83]]}, {"timestamp": 1631523421630, "ltp": 1.88, "tv": 272.24, "trd": NaN, "batb": NaN, "batl": [[0, 2.06, 6.83], [1, 2.34, 2.66], [2, 46, 29.07]]}, {"timestamp": 1631523431657, "ltp": 1.88, "tv": 272.24, "trd": NaN, "batb": NaN, "batl": [[0, 2.04, 39.02], [1, 2.06, 6.83], [2, 2.34, 2.66]]}, {"timestamp": 1631523542446, "ltp": 1.88, "tv": 272.24, "trd": NaN, "batb": [[1, 1.67, 69.71]], "batl": NaN}, {"timestamp": 1631523635346, "ltp": 1.88, "tv": 272.37, "trd": [[1.67, 18.96], [1.68, 4.31], [1.7, 7.24], [1.9, 220.56], [2.06, 7.26]], "batb": [[0, 1.83, 34.14], [1, 1.67, 69.71], [2, 1.42, 46.59]], "batl": [[1, 2.06, 6.83], [2, 2.34, 2.66]]}, {"timestamp": 1631523955523, "ltp": 1.88, "tv": 272.37, "trd": NaN, "batb": NaN, "batl": [[0, 2.04, 39.87]]}, {"timestamp": 1631524369849, "ltp": 1.88, "tv": 272.37, "trd": NaN, "batb": [[2, 1.42, 144.31]], "batl": NaN}, {"timestamp": 1631524450171, "ltp": 1.88, "tv": 272.37, "trd": NaN, "batb": [[2, 1.42, 97.72]], "batl": [[1, 2.34, 2.66], [2, 2.8, 44.02]]}, {"timestamp": 1631524549654, "ltp": 1.88, "tv": 272.37, "trd": NaN, "batb": NaN, "batl": [[0, 1.87, 10.85]]}, {"timestamp": 1631524656152, "ltp": 1.88, "tv": 272.37, "trd": NaN, "batb": NaN, "batl": [[0, 1.87, 14.3]]}, {"timestamp": 1631526065733, "ltp": 1.88, "tv": 272.37, "trd": NaN, "batb": [[0, 1.7, 34.14]], "batl": NaN}, {"timestamp": 1631526082658, "ltp": 1.88, "tv": 272.37, "trd": NaN, "batb": [[0, 1.7, 82.79]], "batl": NaN}, {"timestamp": 1631526195412, "ltp": 1.87, "tv": 282.37, "trd": [[1.87, 10]], "batb": NaN, "batl": [[0, 1.87, 9.29]]}, {"timestamp": 1631526840679, "ltp": 1.87, "tv": 282.37, "trd": NaN, "batb": [[0, 1.71, 18.03], [1, 1.7, 82.79], [2, 1.67, 69.71]], "batl": NaN}, {"timestamp": 1631526950614, "ltp": 1.87, "tv": 282.37, "trd": NaN, "batb": [[0, 1.71, 100.82], [1, 1.67, 69.71], [2, 1.42, 97.72]], "batl": NaN}, {"timestamp": 1631527048602, "ltp": 1.71, "tv": 288.16, "trd": [[1.71, 5.79]], "batb": [[0, 1.71, 97.93]], "batl": NaN}, {"timestamp": 1631528010174, "ltp": 1.71, "tv": 339.37, "trd": [[1.71, 57]], "batb": [[0, 1.71, 72.32]], "batl": NaN}, {"timestamp": 1631528010955, "ltp": 1.71, "tv": 339.37, "trd": NaN, "batb": [[0, 1.72, 17.78], [1, 1.71, 72.32], [2, 1.67, 69.71]], "batl": NaN}, {"timestamp": 1631528153733, "ltp": 1.71, "tv": 339.37, "trd": NaN, "batb": [[0, 1.72, 90.1], [1, 1.67, 69.71], [2, 1.42, 97.72]], "batl": NaN}, {"timestamp": 1631528549473, "ltp": 1.71, "tv": 339.37, "trd": NaN, "batb": [[1, 1.68, 2.66], [2, 1.67, 69.71]], "batl": NaN}, {"timestamp": 1631529441949, "ltp": 1.71, "tv": 339.37, "trd": NaN, "batb": NaN, "batl": [[1, 1.9, 2], [2, 2.34, 2.66]]}, {"timestamp": 1631529656795, "ltp": 1.71, "tv": 339.37, "trd": NaN, "batb": NaN, "batl": [[0, 1.86, 11.48], [1, 1.87, 9.29], [2, 1.9, 2]]}, {"timestamp": 1631529657002, "ltp": 1.71, "tv": 339.37, "trd": NaN, "batb": [[2, 1.67, 81.19]], "batl": NaN}, {"timestamp": 1631530317013, "ltp": 1.71, "tv": 339.37, "trd": NaN, "batb": NaN, "batl": [[1, 1.87, 5.85]]}, {"timestamp": 1631530324810, "ltp": 1.71, "tv": 339.37, "trd": NaN, "batb": NaN, "batl": [[0, 1.74, 3.44], [1, 1.86, 11.48], [2, 1.87, 5.85]]}, {"timestamp": 1631530324915, "ltp": 1.74, "tv": 346.25, "trd": [[1.74, 6.88]], "batb": NaN, "batl": [[0, 1.86, 11.48], [1, 1.87, 5.85], [2, 1.9, 2]]}, {"timestamp": 1631530754292, "ltp": 1.72, "tv": 373.56, "trd": [[1.72, 27.31]], "batb": [[0, 1.72, 76.44]], "batl": NaN}, {"timestamp": 1631530793609, "ltp": 1.72, "tv": 374.96, "trd": [[1.72, 28.71]], "batb": [[0, 1.72, 75.74]], "batl": NaN}, {"timestamp": 1631530918289, "ltp": 1.72, "tv": 374.31, "trd": [[1.67, 18.95], [1.68, 4.3], [1.7, 7.24], [1.71, 56.89], [1.72, 28.65], [1.74, 6.88], [1.87, 10], [1.88, 2.49], [1.9, 220.13], [2.06, 7.25], [2.3, 5.54]], "batb": [[0, 1.72, 75.6], [1, 1.7, 70.7], [2, 1.68, 2.66]], "batl": [[0, 1.86, 11.45]]}, {"timestamp": 1631531219826, "ltp": 1.85, "tv": 374.46, "trd": [[1.85, 0.15]], "batb": NaN, "batl": NaN}, {"timestamp": 1631532290461, "ltp": 1.7, "tv": 748.3, "trd": [[1.7, 148.48], [1.72, 261.25]], "batb": [[0, 1.68, 2.73], [1, 1.67, 81.16], [2, 1.63, 238.1]], "batl": [[0, 1.72, 415.28], [1, 1.86, 11.45], [2, 1.87, 5.85]]}, {"timestamp": 1631532291066, "ltp": 1.7, "tv": 748.3, "trd": NaN, "batb": NaN, "batl": [[0, 1.72, 417.28]]}, {"timestamp": 1631532403609, "ltp": 1.7, "tv": 748.3, "trd": NaN, "batb": [[0, 1.68, 87.91]], "batl": NaN}, {"timestamp": 1631532445646, "ltp": 1.7, "tv": 748.3, "trd": NaN, "batb": NaN, "batl": [[0, 1.72, 2]]}, {"timestamp": 1631532481205, "ltp": 1.68, "tv": 836.21, "trd": [[1.68, 92.14], [1.7, 148.56]], "batb": [[0, 1.67, 81.16], [1, 1.63, 238.1], [2, 1.43, 99.05]], "batl": NaN}, {"timestamp": 1631532484428, "ltp": 1.68, "tv": 836.21, "trd": NaN, "batb": [[0, 1.67, 18.83]], "batl": NaN}, {"timestamp": 1631532629712, "ltp": 1.68, "tv": 839.72, "trd": [[1.68, 95.65]], "batb": NaN, "batl": NaN}, {"timestamp": 1631532654040, "ltp": 1.68, "tv": 843.23, "trd": [[1.68, 99.16]], "batb": NaN, "batl": NaN}, {"timestamp": 1631532729890, "ltp": 1.68, "tv": 843.23, "trd": NaN, "batb": [[1, 1.66, 283.65], [2, 1.63, 238.1]], "batl": NaN}, {"timestamp": 1631532776760, "ltp": 1.68, "tv": 846.75, "trd": [[1.68, 102.68]], "batb": NaN, "batl": NaN}, {"timestamp": 1631532784187, "ltp": 1.68, "tv": 882.53, "trd": [[1.68, 138.46]], "batb": NaN, "batl": NaN}, {"timestamp": 1631532791104, "ltp": 1.68, "tv": 1166.17, "trd": [[1.68, 422.1]], "batb": [[1, 1.63, 238.1], [2, 1.43, 99.05]], "batl": NaN}, {"timestamp": 1631532803105, "ltp": 1.68, "tv": 1226.66, "trd": [[1.68, 482.59]], "batb": [[0, 1.68, 67.28], [1, 1.67, 18.83], [2, 1.63, 238.1]], "batl": NaN}, {"timestamp": 1631532804810, "ltp": 1.68, "tv": 1226.66, "trd": NaN, "batb": [[1, 1.67, 81.16]], "batl": NaN}, {"timestamp": 1631532820328, "ltp": 1.68, "tv": 1226.66, "trd": NaN, "batb": [[1, 1.67, 18.83]], "batl": NaN}, {"timestamp": 1631532823228, "ltp": 1.68, "tv": 1226.66, "trd": NaN, "batb": [[2, 1.66, 255.54]], "batl": NaN}, {"timestamp": 1631532985591, "ltp": 1.68, "tv": 1226.66, "trd": NaN, "batb": [[0, 1.69, 67.28], [1, 1.67, 20.94], [2, 1.66, 257.65]], "batl": NaN}, {"timestamp": 1631533080288, "ltp": 1.68, "tv": 1226.66, "trd": NaN, "batb": [[1, 1.67, 18.83], [2, 1.66, 255.54]], "batl": NaN}, {"timestamp": 1631534464294, "ltp": 1.69, "tv": 1229.36, "trd": [[1.69, 2.7]], "batb": [[0, 1.69, 65.93]], "batl": NaN}, {"timestamp": 1631534606994, "ltp": 1.69, "tv": 1270.84, "trd": [[1.69, 44.19]], "batb": [[0, 1.69, 45.18]], "batl": NaN}, {"timestamp": 1631534813128, "ltp": 1.69, "tv": 1270.84, "trd": NaN, "batb": NaN, "batl": [[2, 1.89, 338.16]]}, {"timestamp": 1631535197402, "ltp": 1.69, "tv": 1275.95, "trd": [[1.69, 49.3]], "batb": [[0, 1.69, 42.62]], "batl": NaN}, {"timestamp": 1631535293475, "ltp": 1.69, "tv": 1275.95, "trd": NaN, "batb": [[2, 1.63, 282.03]], "batl": NaN}, {"timestamp": 1631535418711, "ltp": 1.69, "tv": 1275.95, "trd": NaN, "batb": [[2, 1.63, 238.1]], "batl": NaN}, {"timestamp": 1631535419336, "ltp": 1.69, "tv": 1275.95, "trd": NaN, "batb": [[0, 1.67, 1.38], [1, 1.01, 115.4], [2, 1.63, 0]], "batl": [[0, 1.9, 2], [1, 1.86, 0], [2, 1.89, 0]]}, {"timestamp": 1631535427624, "ltp": 1.69, "tv": 1275.95, "trd": NaN, "batb": [[1, 1.57, 49.71], [2, 1.53, 55.31]], "batl": NaN}, {"timestamp": 1631535431555, "ltp": 1.68, "tv": 1286.08, "trd": [[1.68, 492.72]], "batb": NaN, "batl": NaN}, {"timestamp": 1631535432348, "ltp": 1.68, "tv": 1286.08, "trd": NaN, "batb": [[1, 1.65, 127.18], [2, 1.64, 66.05]], "batl": [[0, 1.71, 96.9], [1, 1.73, 109.88], [2, 1.9, 2]]}, {"timestamp": 1631535443186, "ltp": 1.68, "tv": 1286.08, "trd": NaN, "batb": [[1, 1.53, 55.31], [2, 1.05, 475.37]], "batl": [[0, 1.9, 2], [1, 1.73, 0], [2, 1.9, 0]]}, {"timestamp": 1631535445793, "ltp": 1.68, "tv": 1286.08, "trd": NaN, "batb": [[1, 1.61, 90.88], [2, 1.6, 72.15]], "batl": [[0, 1.8, 91.61], [1, 1.82, 93.16], [2, 1.9, 2]]}, {"timestamp": 1631535449650, "ltp": 1.68, "tv": 1286.08, "trd": NaN, "batb": NaN, "batl": [[0, 1.9, 2], [1, 1.82, 0], [2, 1.9, 0]]}, {"timestamp": 1631535452631, "ltp": 1.61, "tv": 1298.59, "trd": [[1.61, 9.76], [1.67, 21.69]], "batb": [[0, 1.62, 9.16], [1, 1.61, 86]], "batl": [[0, 1.66, 120.66], [1, 1.68, 121.35], [2, 1.9, 2]]}, {"timestamp": 1631535467459, "ltp": 1.61, "tv": 1298.59, "trd": NaN, "batb": [[0, 1.5, 59.66], [1, 1.3, 198.07], [2, 1.25, 237.69]], "batl": [[0, 1.9, 2], [1, 1.68, 0], [2, 1.9, 0]]}, {"timestamp": 1631535472637, "ltp": 1.61, "tv": 1298.59, "trd": NaN, "batb": [[0, 1.62, 97.36], [1, 1.61, 70.55], [2, 1.5, 59.66]], "batl": [[0, 1.67, 85.89], [1, 1.69, 119], [2, 1.9, 2]]}, {"timestamp": 1631535478588, "ltp": 1.61, "tv": 1298.59, "trd": NaN, "batb": [[0, 1.66, 34.07], [1, 1.5, 59.66], [2, 1.3, 198.07]], "batl": [[0, 1.9, 2], [1, 1.69, 0], [2, 1.9, 0]]}, {"timestamp": 1631535481301, "ltp": 1.61, "tv": 1298.59, "trd": NaN, "batb": [[1, 1.58, 70.48], [2, 1.57, 77.38]], "batl": [[0, 1.72, 77.33], [1, 1.74, 107.91], [2, 1.9, 2]]}, {"timestamp": 1631535496818, "ltp": 1.61, "tv": 1298.59, "trd": NaN, "batb": [[1, 1.5, 59.66], [2, 1.3, 198.07]], "batl": NaN}, {"timestamp": 1631535499695, "ltp": 1.61, "tv": 1298.59, "trd": NaN, "batb": [[0, 1.67, 77.49], [1, 1.66, 97.18], [2, 1.5, 59.66]], "batl": NaN}, {"timestamp": 1631535500809, "ltp": 1.68, "tv": 1304.65, "trd": [[1.68, 498.78]], "batb": [[2, 1.58, 48.53]], "batl": NaN}, {"timestamp": 1631535513744, "ltp": 1.68, "tv": 1304.65, "trd": NaN, "batb": [[0, 1.68, 8.83], [1, 1.67, 77.49], [2, 1.66, 97.18]], "batl": NaN}, {"timestamp": 1631535527061, "ltp": 1.72, "tv": 1321.71, "trd": [[1.71, 65.38], [1.72, 269.81]], "batb": NaN, "batl": [[0, 1.72, 73.05]]}, {"timestamp": 1631535529367, "ltp": 1.72, "tv": 1321.71, "trd": NaN, "batb": [[0, 1.66, 34.07], [1, 1.54, 54.06], [2, 1.3, 198.07]], "batl": [[0, 1.9, 2], [1, 1.74, 0], [2, 1.9, 0]]}, {"timestamp": 1631535533774, "ltp": 1.72, "tv": 1321.71, "trd": NaN, "batb": [[0, 1.69, 69.6], [1, 1.67, 122.77], [2, 1.66, 34.07]], "batl": [[0, 1.74, 75.15], [1, 1.76, 103.9], [2, 1.9, 2]]}, {"timestamp": 1631535538469, "ltp": 1.72, "tv": 1321.71, "trd": NaN, "batb": [[0, 1.66, 34.07], [1, 1.54, 54.06], [2, 1.3, 198.07]], "batl": [[0, 1.9, 2], [1, 1.76, 0], [2, 1.9, 0]]}, {"timestamp": 1631535541476, "ltp": 1.72, "tv": 1321.71, "trd": NaN, "batb": [[1, 1.61, 127.91], [2, 1.6, 72.3]], "batl": [[0, 1.83, 98.29], [1, 1.85, 88.45], [2, 1.9, 2]]}, {"timestamp": 1631535546386, "ltp": 1.72, "tv": 1321.71, "trd": NaN, "batb": [[1, 1.54, 54.06], [2, 1.3, 198.07]], "batl": NaN}, {"timestamp": 1631535549785, "ltp": 1.72, "tv": 1321.71, "trd": NaN, "batb": [[0, 1.77, 84.76], [1, 1.76, 648.6], [2, 1.75, 42.38]], "batl": [[0, 1.83, 109.16], [2, 1.89, 450.52]]}, {"timestamp": 1631535550516, "ltp": 1.78, "tv": 1327.46, "trd": [[1.78, 5.75]], "batb": [[0, 1.77, 16.96], [1, 1.76, 614.7], [2, 1.75, 8.48]], "batl": NaN}, {"timestamp": 1631535554176, "ltp": 1.78, "tv": 1361.43, "trd": [[1.78, 39.72]], "batb": NaN, "batl": NaN}, {"timestamp": 1631535564183, "ltp": 1.78, "tv": 1361.43, "trd": NaN, "batb": NaN, "batl": [[0, 1.83, 98.29]]}, {"timestamp": 1631535567104, "ltp": 1.78, "tv": 1361.43, "trd": NaN, "batb": [[1, 1.76, 627.87]], "batl": [[0, 1.8, 11.03], [1, 1.83, 98.29], [2, 1.85, 88.45]]}, {"timestamp": 1631535570293, "ltp": 1.78, "tv": 1361.43, "trd": NaN, "batb": [[0, 1.77, 100.96]], "batl": NaN}, {"timestamp": 1631535574539, "ltp": 1.78, "tv": 1361.43, "trd": NaN, "batb": [[0, 1.59, 47.78], [1, 1.3, 198.07], [2, 1.25, 237.69]], "batl": [[0, 1.9, 2], [1, 1.83, 0], [2, 1.85, 0]]}, {"timestamp": 1631535575121, "ltp": 1.78, "tv": 1361.43, "trd": NaN, "batb": NaN, "batl": [[0, 1.77, 8.43], [1, 1.9, 2]]}, {"timestamp": 1631535577840, "ltp": 1.78, "tv": 1361.43, "trd": NaN, "batb": NaN, "batl": [[0, 1.9, 2], [1, 1.9, 0]]}, {"timestamp": 1631535579514, "ltp": 1.78, "tv": 1361.43, "trd": NaN, "batb": [[0, 1.8, 68.29], [1, 1.78, 98.77], [2, 1.59, 47.78]], "batl": [[0, 1.86, 76.24], [1, 1.88, 84.16], [2, 1.9, 2]]}, {"timestamp": 1631535586435, "ltp": 1.78, "tv": 1361.43, "trd": NaN, "batb": [[0, 1.59, 47.78], [1, 1.3, 198.07], [2, 1.25, 237.69]], "batl": [[0, 1.9, 2], [1, 1.88, 0], [2, 1.9, 0]]}, {"timestamp": 1631535589468, "ltp": 1.78, "tv": 1361.43, "trd": NaN, "batb": [[0, 1.67, 96.19], [1, 1.66, 63.15], [2, 1.59, 47.78]], "batl": [[1, 2.02, 96.7], [2, 2.04, 65.77]]}, {"timestamp": 1631535599353, "ltp": 1.78, "tv": 1361.43, "trd": NaN, "batb": [[0, 1.59, 47.78], [1, 1.3, 198.07], [2, 1.25, 237.69]], "batl": NaN}, {"timestamp": 1631535602788, "ltp": 1.9, "tv": 1363.43, "trd": [[1.9, 222.13]], "batb": [[0, 1.94, 69.13], [1, 1.92, 77.49], [2, 1.91, 120.42]], "batl": [[0, 1.98, 11.98]]}, {"timestamp": 1631535603605, "ltp": 1.94, "tv": 1374.07, "trd": [[1.94, 10.64]], "batb": [[0, 1.94, 63.81]], "batl": [[1, 2.02, 111.56], [2, 2.04, 73.19]]}, {"timestamp": 1631535607595, "ltp": 1.94, "tv": 1439.11, "trd": [[1.94, 75.68]], "batb": [[0, 1.91, 120.42], [1, 1.9, 7.86], [2, 1.89, 7.86]], "batl": NaN}, {"timestamp": 1631535610578, "ltp": 1.94, "tv": 1439.11, "trd": NaN, "batb": [[0, 1.93, 86.8], [1, 1.91, 199.19], [2, 1.9, 7.86]], "batl": [[1, 2.02, 131.67]]}, {"timestamp": 1631535613995, "ltp": 1.94, "tv": 1439.11, "trd": NaN, "batb": NaN, "batl": [[0, 1.94, 2.56], [1, 1.98, 11.98], [2, 2.02, 131.67]]}, {"timestamp": 1631535623022, "ltp": 1.94, "tv": 1439.11, "trd": NaN, "batb": NaN, "batl": [[0, 1.98, 11.98], [1, 2.02, 131.67], [2, 2.04, 73.19]]}, {"timestamp": 1631535624714, "ltp": 1.94, "tv": 1439.11, "trd": NaN, "batb": [[0, 1.68, 39.25], [1, 1.53, 2.53], [2, 1.4, 148.56]], "batl": NaN}, {"timestamp": 1631535626130, "ltp": 1.94, "tv": 1439.11, "trd": NaN, "batb": NaN, "batl": [[0, 1.93, 2.56]]}, {"timestamp": 1631535629331, "ltp": 1.93, "tv": 1441.66, "trd": [[1.93, 2.56]], "batb": NaN, "batl": NaN}, {"timestamp": 1631535639353, "ltp": 1.93, "tv": 1441.66, "trd": NaN, "batb": NaN, "batl": [[0, 1.98, 0.12]]}, {"timestamp": 1631535646262, "ltp": 1.75, "tv": 1447.37, "trd": [[1.75, 5.71]], "batb": [[0, 1.77, 103.36], [1, 1.75, 104.68], [2, 1.68, 39.25]], "batl": [[0, 1.8, 66.67], [1, 1.83, 17.55], [2, 1.84, 99.82]]}, {"timestamp": 1631535647271, "ltp": 1.75, "tv": 1447.37, "trd": NaN, "batb": [[1, 1.76, 17.04], [2, 1.75, 113.2]], "batl": NaN}, {"timestamp": 1631535671337, "ltp": 1.75, "tv": 1447.37, "trd": NaN, "batb": [[0, 1.6, 46.61], [1, 1.53, 2.53], [2, 1.4, 148.56]], "batl": NaN}, {"timestamp": 1631535674234, "ltp": 1.75, "tv": 1447.37, "trd": NaN, "batb": [[0, 1.68, 77.96], [1, 1.66, 125.52], [2, 1.6, 46.61]], "batl": [[0, 1.77, 8.43], [1, 2.02, 59.51], [2, 2.04, 65.78]]}, {"timestamp": 1631535675332, "ltp": 1.75, "tv": 1447.37, "trd": NaN, "batb": [[0, 1.6, 46.61], [1, 1.53, 2.53], [2, 1.4, 148.56]], "batl": [[1, 2.02, 0], [2, 2.04, 0]]}, {"timestamp": 1631535678250, "ltp": 1.77, "tv": 1464.24, "trd": [[1.77, 16.86]], "batb": [[0, 1.81, 55.24], [1, 1.79, 96.98], [2, 1.6, 46.61]], "batl": [[0, 1.87, 76.84], [1, 1.89, 82.81]]}, {"timestamp": 1631535679425, "ltp": 1.77, "tv": 1464.24, "trd": NaN, "batb": NaN, "batl": [[2, 2.42, 290.48]]}, {"timestamp": 1631535682952, "ltp": 1.77, "tv": 1464.24, "trd": NaN, "batb": [[0, 1.6, 46.61], [1, 1.55, 426.3], [2, 1.53, 2.53]], "batl": [[0, 2.42, 290.48], [1, 1.89, 0], [2, 2.42, 0]]}, {"timestamp": 1631535686199, "ltp": 1.77, "tv": 1464.24, "trd": NaN, "batb": [[0, 1.68, 73.04], [1, 1.66, 125.51], [2, 1.6, 46.61]], "batl": [[0, 2.02, 63.6], [1, 2.04, 65.79], [2, 2.42, 290.48]]}, {"timestamp": 1631535689874, "ltp": 1.77, "tv": 1464.24, "trd": NaN, "batb": [[0, 1.6, 46.61], [1, 1.55, 426.3], [2, 1.53, 2.53]], "batl": NaN}, {"timestamp": 1631535692756, "ltp": 1.77, "tv": 1464.24, "trd": NaN, "batb": [[0, 1.95, 65.61], [1, 1.93, 76.25], [2, 1.92, 46.87]], "batl": [[0, 2, 5.76], [1, 2.02, 63.6], [2, 2.04, 65.79]]}, {"timestamp": 1631535693761, "ltp": 1.95, "tv": 1474.82, "trd": [[1.95, 10.58]], "batb": [[0, 1.95, 60.32], [2, 1.92, 15.62]], "batl": [[1, 2.02, 78.46], [2, 2.04, 73.21]]}, {"timestamp": 1631535709515, "ltp": 1.95, "tv": 1475.05, "trd": [[1.95, 10.82]], "batb": [[0, 1.95, 60.2]], "batl": NaN}, {"timestamp": 1631535715616, "ltp": 1.95, "tv": 1475.05, "trd": NaN, "batb": [[0, 1.69, 38.41], [1, 1.53, 2.53], [2, 1.4, 148.56]], "batl": NaN}, {"timestamp": 1631535718515, "ltp": 1.95, "tv": 1475.05, "trd": NaN, "batb": [[0, 1.79, 61.3], [1, 1.77, 100.67], [2, 1.69, 38.41]], "batl": [[0, 2.36, 68.58], [1, 2.4, 84.1]]}, {"timestamp": 1631535722711, "ltp": 1.79, "tv": 1486.41, "trd": [[1.79, 11.36]], "batb": [[0, 1.8, 388.42], [1, 1.79, 55.62], [2, 1.77, 100.67]], "batl": [[0, 1.81, 66.3], [1, 1.83, 7.82], [2, 1.85, 87.17]]}, {"timestamp": 1631535723511, "ltp": 1.79, "tv": 1486.41, "trd": NaN, "batb": [[2, 1.77, 117.63]], "batl": NaN}, {"timestamp": 1631535727431, "ltp": 1.8, "tv": 1551.83, "trd": [[1.8, 65.42]], "batb": [[0, 1.8, 355.71]], "batl": NaN}, {"timestamp": 1631535737347, "ltp": 1.8, "tv": 1551.83, "trd": NaN, "batb": NaN, "batl": [[1, 1.85, 87.17], [2, 1.87, 85.59]]}, {"timestamp": 1631535738339, "ltp": 1.8, "tv": 1571.83, "trd": [[1.8, 85.42]], "batb": [[0, 1.8, 345.71]], "batl": NaN}, {"timestamp": 1631535740542, "ltp": 1.8, "tv": 1571.83, "trd": NaN, "batb": [[0, 1.8, 472.71]], "batl": [[1, 1.83, 16.86], [2, 1.85, 87.17]]}, {"timestamp": 1631535753674, "ltp": 1.8, "tv": 1571.83, "trd": NaN, "batb": [[0, 1.69, 38.41], [1, 1.6, 46.28], [2, 1.55, 426.3]], "batl": [[0, 2.42, 290.48], [1, 810, 0.07], [2, 1.85, 0]]}, {"timestamp": 1631535753892, "ltp": 1.8, "tv": 1571.83, "trd": NaN, "batb": [[0, 1.6, 46.28], [1, 1.55, 426.3], [2, 1.53, 2.53]], "batl": NaN}, {"timestamp": 1631535756586, "ltp": 1.8, "tv": 1571.83, "trd": NaN, "batb": [[0, 1.69, 72.64], [1, 1.67, 122.89], [2, 1.6, 46.28]], "batl": [[0, 2.04, 78.21], [1, 2.06, 63.94], [2, 2.42, 290.48]]}, {"timestamp": 1631535757681, "ltp": 1.8, "tv": 1571.83, "trd": NaN, "batb": [[0, 1.6, 46.28], [1, 1.55, 426.3], [2, 1.53, 2.53]], "batl": [[0, 2.42, 290.48], [1, 1000, 2.24], [2, 2.42, 0]]}, {"timestamp": 1631535758373, "ltp": 1.8, "tv": 1571.83, "trd": NaN, "batb": NaN, "batl": [[1, 810, 0.07]]}, {"timestamp": 1631535760557, "ltp": 1.8, "tv": 1571.83, "trd": NaN, "batb": [[0, 1.82, 70.49], [1, 1.8, 95.26], [2, 1.6, 46.28]], "batl": [[0, 1.88, 66.51], [1, 1.9, 81.51], [2, 2.42, 290.48]]}, {"timestamp": 1631535765159, "ltp": 1.8, "tv": 1571.83, "trd": NaN, "batb": [[0, 1.6, 46.28], [1, 1.55, 426.3], [2, 1.53, 2.53]], "batl": [[0, 2.42, 290.48], [1, 820, 0.14], [2, 2.42, 0]]}, {"timestamp": 1631535768084, "ltp": 1.8, "tv": 1571.83, "trd": NaN, "batb": [[0, 1.69, 72.64], [1, 1.67, 122.89], [2, 1.6, 46.28]], "batl": [[0, 2.04, 78.21], [1, 2.06, 63.94], [2, 2.42, 290.48]]}, {"timestamp": 1631535799271, "ltp": 1.8, "tv": 1571.83, "trd": NaN, "batb": NaN, "batl": [[0, 2.42, 290.48], [1, 820, 0.14], [2, 2.42, 0]]}, {"timestamp": 1631535801171, "ltp": 1.8, "tv": 1571.83, "trd": NaN, "batb": NaN, "batl": [[0, 820, 0.14], [1, 820, 0]]}, {"timestamp": 1631535802844, "ltp": 1.69, "tv": 1583.73, "trd": [[1.69, 61.2]], "batb": [[0, 1.69, 66.69], [2, 1.66, 45.18]], "batl": [[0, 1.74, 89.74], [1, 1.75, 8.62], [2, 1.76, 112.64]]}, {"timestamp": 1631535803359, "ltp": 1.69, "tv": 1583.73, "trd": NaN, "batb": [[2, 1.66, 18.08]], "batl": NaN}, {"timestamp": 1631535810170, "ltp": 1.69, "tv": 1583.73, "trd": NaN, "batb": [[0, 1.7, 127], [1, 1.69, 66.69], [2, 1.67, 122.89]], "batl": NaN}, {"timestamp": 1631535812677, "ltp": 1.72, "tv": 1592.25, "trd": [[1.72, 278.33]], "batb": NaN, "batl": NaN}, {"timestamp": 1631535812967, "ltp": 1.72, "tv": 1592.25, "trd": NaN, "batb": [[0, 1.69, 66.69], [1, 1.67, 122.89], [2, 1.66, 18.08]], "batl": NaN}, {"timestamp": 1631535816051, "ltp": 1.72, "tv": 1592.25, "trd": NaN, "batb": [[0, 1.71, 138], [1, 1.69, 66.69], [2, 1.67, 122.89]], "batl": NaN}, {"timestamp": 1631535825797, "ltp": 1.72, "tv": 1592.25, "trd": NaN, "batb": [[1, 1.7, 9.25], [2, 1.69, 66.69]], "batl": NaN}, {"timestamp": 1631535832788, "ltp": 1.71, "tv": 1594.11, "trd": [[1.71, 67.24]], "batb": [[0, 1.71, 137.07], [1, 1.55, 478.77], [2, 1.53, 2.53]], "batl": [[0, 2.3, 314.02], [1, 810, 0.07], [2, 1.76, 0]]}, {"timestamp": 1631535833301, "ltp": 1.71, "tv": 1594.11, "trd": NaN, "batb": [[0, 1.55, 478.77], [1, 1.53, 2.53], [2, 1.3, 198.07]], "batl": NaN}, {"timestamp": 1631535835717, "ltp": 1.71, "tv": 1594.11, "trd": NaN, "batb": [[0, 1.62, 115.45], [1, 1.61, 70.7], [2, 1.55, 478.77]], "batl": [[0, 1.86, 69.22], [1, 1.88, 84.24], [2, 2.3, 314.02]]}, {"timestamp": 1631535835924, "ltp": 1.71, "tv": 1594.11, "trd": NaN, "batb": [[0, 1.55, 478.77], [1, 1.53, 2.53], [2, 1.3, 198.07]], "batl": [[0, 2.3, 314.02], [1, 810, 0.07], [2, 2.3, 0]]}, {"timestamp": 1631535837911, "ltp": 1.71, "tv": 1594.11, "trd": NaN, "batb": [[0, 1.71, 75.75], [1, 1.69, 117.91], [2, 1.55, 478.77]], "batl": [[0, 1.76, 60.43], [1, 1.78, 100.3], [2, 2.3, 314.02]]}, {"timestamp": 1631535844035, "ltp": 1.71, "tv": 1594.11, "trd": NaN, "batb": [[0, 1.55, 478.77], [1, 1.53, 2.53], [2, 1.3, 198.07]], "batl": [[0, 2.3, 314.02], [1, 810, 0.07], [2, 2.3, 0]]}, {"timestamp": 1631535846937, "ltp": 1.71, "tv": 1594.11, "trd": NaN, "batb": [[0, 1.62, 115.45], [1, 1.61, 70.7], [2, 1.55, 478.77]], "batl": [[0, 1.86, 69.22], [1, 1.88, 84.24], [2, 2.3, 314.02]]}, {"timestamp": 1631535854809, "ltp": 1.71, "tv": 1594.11, "trd": NaN, "batb": NaN, "batl": [[0, 2.3, 314.02], [1, 810, 0.07], [2, 2.3, 0]]}, {"timestamp": 1631535856215, "ltp": 1.71, "tv": 1594.11, "trd": NaN, "batb": [[2, 1.55, 52.47]], "batl": [[0, 810, 0.07], [1, 810, 0]]}, {"timestamp": 1631535857830, "ltp": 1.67, "tv": 1649.04, "trd": [[1.62, 12.34], [1.66, 22.24], [1.67, 42.03]], "batb": [[0, 1.62, 109.28]], "batl": [[0, 1.67, 58.86], [1, 1.68, 53.57], [2, 1.69, 146.04]]}, {"timestamp": 1631535858825, "ltp": 1.67, "tv": 1649.04, "trd": NaN, "batb": [[1, 1.61, 126.6], [2, 1.6, 9.32]], "batl": [[1, 1.68, 17.86], [2, 1.69, 128.18]]}, {"timestamp": 1631535858929, "ltp": 1.67, "tv": 1649.04, "trd": NaN, "batb": [[1, 1.61, 89.34]], "batl": NaN}, {"timestamp": 1631535861131, "ltp": 1.67, "tv": 1649.04, "trd": NaN, "batb": [[0, 1.62, 117.84]], "batl": [[0, 1.67, 66.72]]}, {"timestamp": 1631535870669, "ltp": 1.67, "tv": 1649.04, "trd": NaN, "batb": NaN, "batl": [[1, 1.68, 32.69]]}, {"timestamp": 1631535874948, "ltp": 1.67, "tv": 1649.33, "trd": [[1.67, 42.32]], "batb": NaN, "batl": [[0, 1.67, 66.43]]}, {"timestamp": 1631535883097, "ltp": 1.67, "tv": 1649.47, "trd": [[1.67, 42.46]], "batb": NaN, "batl": [[0, 1.67, 66.29]]}, {"timestamp": 1631535894974, "ltp": 1.67, "tv": 1649.47, "trd": NaN, "batb": [[0, 1.61, 18.64], [1, 1.6, 9.32], [2, 1.59, 9.32]], "batl": [[0, 1.68, 32.69], [1, 1.69, 8.92], [2, 1.7, 8.92]]}, {"timestamp": 1631535896111, "ltp": 1.67, "tv": 1649.47, "trd": NaN, "batb": [[0, 1.64, 65], [1, 1.61, 18.64], [2, 1.6, 9.32]], "batl": NaN}, {"timestamp": 1631535940509, "ltp": 1.68, "tv": 1713.94, "trd": [[1.68, 563.25]], "batb": [[0, 1.61, 18.64], [1, 1.6, 9.32], [2, 1.59, 9.32]], "batl": [[0, 1.69, 9.38], [1, 1.7, 8.92], [2, 1.74, 94.3]]}, {"timestamp": 1631535946205, "ltp": 1.7, "tv": 1810.65, "trd": [[1.68, 564.17], [1.69, 79.04], [1.7, 226.51]], "batb": NaN, "batl": [[0, 1.74, 94.3], [1, 1.76, 103.93], [2, 2.16, 347.55]]}, {"timestamp": 1631535952817, "ltp": 1.7, "tv": 1810.65, "trd": NaN, "batb": [[0, 1.61, 9.32], [1, 1.6, 4.66], [2, 1.59, 4.66]], "batl": NaN}, {"timestamp": 1631535953544, "ltp": 1.7, "tv": 1838.95, "trd": [[1.7, 254.8]], "batb": [[0, 1.54, 119.87], [1, 1.53, 88.37], [2, 1.48, 62.59]], "batl": NaN}, {"timestamp": 1631535961328, "ltp": 1.7, "tv": 1838.95, "trd": NaN, "batb": [[0, 1.53, 2.53], [1, 1.48, 62.59], [2, 1.44, 442.2]], "batl": NaN}, {"timestamp": 1631535962556, "ltp": 1.7, "tv": 1838.95, "trd": NaN, "batb": [[2, 1.3, 198.07]], "batl": NaN}, {"timestamp": 1631535964445, "ltp": 1.74, "tv": 1854.35, "trd": [[1.74, 22.28]], "batb": [[0, 1.68, 110.74], [1, 1.66, 125.74], [2, 1.53, 2.53]], "batl": [[0, 1.74, 86.6], [2, 1.8, 388.45]]}, {"timestamp": 1631535965538, "ltp": 1.7, "tv": 1860.34, "trd": [[1.7, 260.79]], "batb": [[2, 1.61, 45.86]], "batl": [[2, 1.79, 16.76]]}, {"timestamp": 1631535967644, "ltp": 1.74, "tv": 1875.74, "trd": [[1.74, 37.68]], "batb": NaN, "batl": [[0, 1.74, 78.9]]}, {"timestamp": 1631535970648, "ltp": 1.74, "tv": 1875.74, "trd": NaN, "batb": [[0, 1.68, 119.57]], "batl": NaN}, {"timestamp": 1631535972060, "ltp": 1.7, "tv": 1875.83, "trd": [[1.7, 260.89]], "batb": NaN, "batl": NaN}, {"timestamp": 1631535980258, "ltp": 1.7, "tv": 1875.83, "trd": NaN, "batb": NaN, "batl": [[2, 1.78, 19.63]]}, {"timestamp": 1631535982388, "ltp": 1.7, "tv": 1875.83, "trd": NaN, "batb": [[0, 1.54, 54.23], [1, 1.53, 2.53], [2, 1.5, 432.79]], "batl": [[0, 2.16, 347.55], [1, 810, 0.07], [2, 1.78, 0]]}, {"timestamp": 1631535985207, "ltp": 1.7, "tv": 1875.83, "trd": NaN, "batb": [[0, 1.61, 72.12], [1, 1.6, 72.14], [2, 1.54, 54.23]], "batl": [[0, 1.8, 82.36], [1, 1.82, 93.24], [2, 2.16, 347.55]]}, {"timestamp": 1631535994288, "ltp": 1.7, "tv": 1875.83, "trd": NaN, "batb": NaN, "batl": [[0, 2.16, 347.55], [1, 810, 0.07], [2, 2.16, 0]]}, {"timestamp": 1631535997729, "ltp": 1.64, "tv": 1882.04, "trd": [[1.64, 6.21]], "batb": NaN, "batl": [[0, 1.66, 116.35], [1, 1.67, 53.89], [2, 1.68, 165.1]]}, {"timestamp": 1631535998724, "ltp": 1.64, "tv": 1882.04, "trd": NaN, "batb": NaN, "batl": [[1, 1.67, 17.96], [2, 1.68, 147.14]]}, {"timestamp": 1631536000296, "ltp": 1.66, "tv": 1925.53, "trd": [[1.66, 65.73]], "batb": NaN, "batl": [[0, 1.66, 94.61]]}, {"timestamp": 1631536002144, "ltp": 1.64, "tv": 1932.02, "trd": [[1.64, 12.7]], "batb": NaN, "batl": NaN}, {"timestamp": 1631536003830, "ltp": 1.64, "tv": 1932.02, "trd": NaN, "batb": [[0, 1.61, 84.52]], "batl": [[0, 1.66, 104.33]]}, {"timestamp": 1631536006023, "ltp": 1.66, "tv": 1937.86, "trd": [[1.66, 71.57]], "batb": NaN, "batl": [[0, 1.66, 98.49]]}, {"timestamp": 1631536007237, "ltp": 1.66, "tv": 1937.86, "trd": NaN, "batb": NaN, "batl": [[2, 1.68, 130.33]]}, {"timestamp": 1631536010840, "ltp": 1.66, "tv": 2128.82, "trd": [[1.66, 262.53]], "batb": [[0, 1.61, 72.12], [1, 1.54, 54.23], [2, 1.53, 2.53]], "batl": [[0, 1.66, 14.65], [2, 1.68, 8.98]]}, {"timestamp": 1631536011839, "ltp": 1.66, "tv": 2128.82, "trd": NaN, "batb": NaN, "batl": [[0, 2.16, 347.55], [1, 810, 0.07], [2, 1.68, 0]]}, {"timestamp": 1631536012262, "ltp": 1.66, "tv": 2128.82, "trd": NaN, "batb": [[0, 1.53, 2.53], [1, 1.5, 432.79], [2, 1.45, 67.36]], "batl": NaN}, {"timestamp": 1631536013728, "ltp": 1.66, "tv": 2128.82, "trd": NaN, "batb": [[0, 1.62, 71.56], [1, 1.53, 2.53], [2, 1.5, 432.79]], "batl": [[0, 1.67, 109.65], [1, 1.69, 118.52], [2, 2.16, 347.55]]}, {"timestamp": 1631536013940, "ltp": 1.66, "tv": 2128.82, "trd": NaN, "batb": [[0, 1.53, 2.53], [1, 1.5, 432.79], [2, 1.45, 67.36]], "batl": [[0, 2.16, 347.55], [1, 810, 0.07], [2, 2.16, 0]]}, {"timestamp": 1631536014935, "ltp": 1.66, "tv": 2128.82, "trd": NaN, "batb": [[1, 1.52, 142.63], [2, 1.51, 90.19]], "batl": [[0, 1.74, 75.95], [1, 1.76, 103.65], [2, 2.16, 347.55]]}, {"timestamp": 1631536026978, "ltp": 1.66, "tv": 2128.82, "trd": NaN, "batb": [[1, 1.5, 432.79], [2, 1.45, 67.36]], "batl": NaN}, {"timestamp": 1631536028760, "ltp": 1.53, "tv": 2130.0, "trd": [[1.53, 1.18]], "batb": [[0, 1.53, 1.94]], "batl": NaN}, {"timestamp": 1631536029752, "ltp": 1.53, "tv": 2130.0, "trd": NaN, "batb": [[0, 1.69, 121.34], [1, 1.68, 26.63], [2, 1.67, 149.11]], "batl": [[2, 1.78, 316.61]]}, {"timestamp": 1631536030376, "ltp": 1.68, "tv": 2483.96, "trd": [[1.68, 667.11], [1.69, 321.72], [1.7, 269.23]], "batb": [[0, 1.67, 8.88], [1, 1.59, 47.28], [2, 1.53, 1.94]], "batl": NaN}, {"timestamp": 1631536033401, "ltp": 1.68, "tv": 2483.96, "trd": NaN, "batb": [[0, 1.68, 90.99], [1, 1.67, 8.88], [2, 1.66, 125.41]], "batl": [[0, 1.74, 112.52]]}, {"timestamp": 1631536043121, "ltp": 1.68, "tv": 2483.96, "trd": NaN, "batb": NaN, "batl": [[0, 1.72, 10.78], [1, 1.74, 112.52], [2, 1.76, 103.65]]}, {"timestamp": 1631536052640, "ltp": 1.68, "tv": 2483.96, "trd": NaN, "batb": [[0, 1.53, 1.94], [1, 1.52, 56.57], [2, 1.5, 432.79]], "batl": [[0, 2.16, 347.55], [1, 1.74, 0], [2, 1.76, 0]]}, {"timestamp": 1631536057770, "ltp": 1.68, "tv": 2483.96, "trd": NaN, "batb": [[0, 1.66, 104.66], [1, 1.65, 64.51], [2, 1.53, 1.94]], "batl": [[0, 1.72, 111.64], [1, 1.74, 107.65], [2, 2.16, 347.55]]}, {"timestamp": 1631536064374, "ltp": 1.68, "tv": 2483.96, "trd": NaN, "batb": [[0, 1.53, 1.94], [1, 1.52, 56.57], [2, 1.5, 432.79]], "batl": [[0, 2.16, 347.55], [1, 1.74, 0], [2, 2.16, 0]]}, {"timestamp": 1631536067347, "ltp": 1.68, "tv": 2483.96, "trd": NaN, "batb": [[0, 1.59, 122.82], [1, 1.58, 75.7], [2, 1.53, 1.94]], "batl": [[0, 1.8, 67.78], [1, 1.82, 93.16], [2, 2.16, 347.55]]}, {"timestamp": 1631536076868, "ltp": 1.68, "tv": 2483.96, "trd": NaN, "batb": NaN, "batl": [[2, 1.89, 255.54]]}, {"timestamp": 1631536082290, "ltp": 1.68, "tv": 2483.96, "trd": NaN, "batb": NaN, "batl": [[0, 1.89, 255.54], [1, 2.16, 347.55], [2, 1.89, 0]]}, {"timestamp": 1631536085717, "ltp": 1.59, "tv": 2496.54, "trd": [[1.59, 12.58]], "batb": [[0, 1.6, 9.81], [1, 1.59, 116.53], [2, 1.58, 75.7]], "batl": [[0, 1.64, 80.54], [1, 1.65, 64.22], [2, 1.68, 71.42]]}, {"timestamp": 1631536098514, "ltp": 1.64, "tv": 2547.67, "trd": [[1.64, 63.83]], "batb": NaN, "batl": [[0, 1.64, 29.41]]}, {"timestamp": 1631536099130, "ltp": 1.64, "tv": 2547.67, "trd": NaN, "batb": [[1, 1.59, 73.64], [2, 1.53, 1.94]], "batl": [[0, 1.65, 64.22], [1, 1.68, 71.42], [2, 1.89, 255.54]]}, {"timestamp": 1631536102042, "ltp": 1.64, "tv": 2547.67, "trd": NaN, "batb": [[0, 1.6, 84.19]], "batl": [[0, 1.65, 119.57], [1, 1.66, 62.66], [2, 1.68, 71.42]]}, {"timestamp": 1631536108640, "ltp": 1.64, "tv": 2547.67, "trd": NaN, "batb": [[0, 1.6, 74.38]], "batl": NaN}, {"timestamp": 1631536111620, "ltp": 1.64, "tv": 2547.67, "trd": NaN, "batb": NaN, "batl": [[0, 1.64, 12.05], [1, 1.65, 119.57], [2, 1.66, 62.66]]}, {"timestamp": 1631536116386, "ltp": 1.64, "tv": 2547.67, "trd": NaN, "batb": NaN, "batl": [[0, 1.65, 119.57], [1, 1.66, 62.66], [2, 1.89, 255.54]]}, {"timestamp": 1631536116860, "ltp": 1.64, "tv": 2547.67, "trd": NaN, "batb": [[0, 1.53, 1.94], [1, 1.5, 432.79], [2, 1.43, 73.05]], "batl": [[0, 1.89, 255.54], [1, 2.16, 347.55], [2, 1.89, 0]]}, {"timestamp": 1631536119846, "ltp": 1.64, "tv": 2547.67, "trd": NaN, "batb": [[1, 1.43, 73.05], [2, 1.3, 198.07]], "batl": NaN}, {"timestamp": 1631536120946, "ltp": 1.64, "tv": 2547.67, "trd": NaN, "batb": [[0, 1.57, 125.44], [1, 1.56, 79.36], [2, 1.53, 1.94]], "batl": [[0, 1.62, 91.63], [1, 1.63, 66.91], [2, 1.89, 255.54]]}, {"timestamp": 1631536128177, "ltp": 1.64, "tv": 2547.67, "trd": NaN, "batb": [[0, 1.53, 1.94], [1, 1.43, 73.05], [2, 1.4, 457.22]], "batl": [[0, 1.89, 255.54], [1, 2.16, 347.55], [2, 1.89, 0]]}, {"timestamp": 1631536131101, "ltp": 1.64, "tv": 2547.67, "trd": NaN, "batb": [[1, 1.48, 165.83], [2, 1.47, 100.88]], "batl": [[0, 1.74, 89.96], [1, 1.76, 103.64], [2, 1.89, 255.54]]}, {"timestamp": 1631536140604, "ltp": 1.64, "tv": 2547.67, "trd": NaN, "batb": NaN, "batl": [[0, 1.89, 255.54], [1, 2.16, 347.55], [2, 1.89, 0]]}, {"timestamp": 1631536141497, "ltp": 1.64, "tv": 2547.67, "trd": NaN, "batb": NaN, "batl": [[1, 2.16, 0]]}, {"timestamp": 1631536143799, "ltp": 1.5, "tv": 2556.28, "trd": [[1.5, 6.67], [1.53, 3.12]], "batb": [[0, 1.48, 688.7], [1, 1.47, 100.88], [2, 1.43, 73.05]], "batl": [[0, 1.52, 9.34], [1, 1.53, 132.99], [2, 1.54, 82.19]]}, {"timestamp": 1631536151510, "ltp": 1.5, "tv": 2556.28, "trd": NaN, "batb": [[0, 1.5, 124], [1, 1.48, 688.7], [2, 1.47, 100.88]], "batl": NaN}, {"timestamp": 1631536153488, "ltp": 1.52, "tv": 2558.92, "trd": [[1.52, 2.64]], "batb": NaN, "batl": [[0, 1.53, 132.99], [1, 1.54, 82.19], [2, 1.66, 2024.71]]}, {"timestamp": 1631536154337, "ltp": 1.5, "tv": 2566.15, "trd": [[1.5, 13.91]], "batb": [[0, 1.5, 120.38]], "batl": NaN}, {"timestamp": 1631536156396, "ltp": 1.5, "tv": 2566.15, "trd": NaN, "batb": NaN, "batl": [[0, 1.52, 13.29], [1, 1.53, 132.99], [2, 1.54, 82.19]]}, {"timestamp": 1631536156929, "ltp": 1.5, "tv": 2566.15, "trd": NaN, "batb": [[1, 1.48, 620.27], [2, 1.43, 73.05]], "batl": NaN}, {"timestamp": 1631536159826, "ltp": 1.5, "tv": 2566.15, "trd": NaN, "batb": [[1, 1.49, 70.38], [2, 1.48, 620.27]], "batl": NaN}, {"timestamp": 1631536160656, "ltp": 1.5, "tv": 2566.15, "trd": NaN, "batb": [[2, 1.48, 97.4]], "batl": [[0, 1.53, 132.99], [1, 1.54, 82.19], [2, 1.89, 255.54]]}, {"timestamp": 1631536161239, "ltp": 1.5, "tv": 2566.15, "trd": NaN, "batb": [[0, 1.34, 471.85], [1, 1.32, 103.6], [2, 1.25, 237.69]], "batl": [[0, 1.89, 255.54], [1, 1.95, 415.52], [2, 1.89, 0]]}, {"timestamp": 1631536163849, "ltp": 1.5, "tv": 2566.15, "trd": NaN, "batb": [[0, 1.36, 167.84], [1, 1.35, 148.1], [2, 1.34, 471.85]], "batl": [[0, 1.64, 117.98], [1, 1.65, 63.99], [2, 1.89, 255.54]]}, {"timestamp": 1631536164838, "ltp": 1.5, "tv": 2566.15, "trd": NaN, "batb": [[0, 1.34, 471.85], [1, 1.32, 103.6], [2, 1.25, 237.69]], "batl": [[0, 1.54, 349.86], [1, 1.89, 255.54], [2, 1.95, 415.52]]}, {"timestamp": 1631536165258, "ltp": 1.5, "tv": 2566.15, "trd": NaN, "batb": [[0, 1.46, 109.28], [1, 1.45, 106.42], [2, 1.34, 471.85]], "batl": [[0, 1.5, 119.92], [1, 1.51, 88.74], [2, 1.89, 255.54]]}, {"timestamp": 1631536169367, "ltp": 1.5, "tv": 2566.15, "trd": NaN, "batb": [[0, 1.34, 471.85], [1, 1.32, 103.6], [2, 1.25, 237.69]], "batl": [[0, 1.89, 255.54], [1, 1.95, 415.52], [2, 1.89, 0]]}, {"timestamp": 1631536172567, "ltp": 1.5, "tv": 2566.15, "trd": NaN, "batb": [[0, 1.36, 167.84], [1, 1.35, 148.1], [2, 1.34, 471.85]], "batl": NaN}, {"timestamp": 1631536173765, "ltp": 1.5, "tv": 2566.15, "trd": NaN, "batb": [[0, 1.36, 831.55], [2, 1.32, 103.6]], "batl": [[0, 1.39, 7.19], [1, 1.4, 10.42], [2, 1.41, 2382.24]]}, {"timestamp": 1631536174759, "ltp": 1.5, "tv": 2566.15, "trd": NaN, "batb": NaN, "batl": [[1, 1.4, 197.55], [2, 1.41, 117.13]]}, {"timestamp": 1631536178779, "ltp": 1.5, "tv": 2566.15, "trd": NaN, "batb": NaN, "batl": [[0, 1.39, 77.3]]}, {"timestamp": 1631536179089, "ltp": 1.5, "tv": 2566.15, "trd": NaN, "batb": NaN, "batl": [[0, 1.39, 7.19]]}, {"timestamp": 1631536182073, "ltp": 1.5, "tv": 2566.15, "trd": NaN, "batb": [[0, 1.37, 247], [1, 1.36, 831.55], [2, 1.35, 148.1]], "batl": NaN}, {"timestamp": 1631536186091, "ltp": 1.39, "tv": 2580.53, "trd": [[1.39, 14.38]], "batb": [[0, 1.39, 14.65], [1, 1.37, 247], [2, 1.36, 831.55]], "batl": [[0, 1.4, 197.55], [1, 1.41, 117.13], [2, 1.82, 475.58]]}, {"timestamp": 1631536200530, "ltp": 1.4, "tv": 2584.09, "trd": [[1.4, 3.56]], "batb": NaN, "batl": [[0, 1.4, 195.77]]}, {"timestamp": 1631536208750, "ltp": 1.4, "tv": 2584.09, "trd": NaN, "batb": [[0, 1.37, 247], [1, 1.36, 831.55], [2, 1.35, 148.1]], "batl": NaN}, {"timestamp": 1631536210746, "ltp": 1.4, "tv": 2584.09, "trd": NaN, "batb": NaN, "batl": [[0, 1.4, 187.13]]}, {"timestamp": 1631536211843, "ltp": 1.4, "tv": 2584.09, "trd": NaN, "batb": [[0, 1.4, 14.65], [1, 1.37, 247], [2, 1.36, 663.71]], "batl": [[0, 1.82, 475.58], [1, 1.89, 255.54], [2, 1.82, 0]]}, {"timestamp": 1631536213716, "ltp": 1.4, "tv": 2618.27, "trd": [[1.4, 27.74], [1.41, 10]], "batb": [[0, 1.38, 11.76]], "batl": NaN}, {"timestamp": 1631536214826, "ltp": 1.4, "tv": 2618.27, "trd": NaN, "batb": NaN, "batl": [[0, 1.46, 160.06], [1, 1.47, 98.46], [2, 1.82, 475.58]]}, {"timestamp": 1631536215239, "ltp": 1.4, "tv": 2620.27, "trd": [[1.4, 29.74]], "batb": NaN, "batl": NaN}, {"timestamp": 1631536223928, "ltp": 1.4, "tv": 2620.27, "trd": NaN, "batb": [[0, 1.37, 247], [1, 1.36, 663.71], [2, 1.33, 158.87]], "batl": NaN}, {"timestamp": 1631536226475, "ltp": 1.4, "tv": 2620.27, "trd": NaN, "batb": [[1, 1.33, 158.87], [2, 1.32, 165.71]], "batl": NaN}, {"timestamp": 1631536227376, "ltp": 1.4, "tv": 2620.27, "trd": NaN, "batb": [[0, 1.33, 158.87], [1, 1.32, 165.71], [2, 1.29, 116.15]], "batl": NaN}, {"timestamp": 1631536232674, "ltp": 1.4, "tv": 2620.27, "trd": NaN, "batb": [[0, 1.29, 116.15], [1, 1.28, 492.6], [2, 1.2, 386.24]], "batl": NaN}, {"timestamp": 1631536233464, "ltp": 1.4, "tv": 2620.27, "trd": NaN, "batb": [[1, 1.2, 386.24], [2, 1.17, 314.59]], "batl": NaN}, {"timestamp": 1631536235658, "ltp": 1.4, "tv": 2620.27, "trd": NaN, "batb": [[0, 1.45, 13.8], [1, 1.43, 20.98], [2, 1.42, 121.03]], "batl": [[1, 1.47, 109.39], [2, 1.5, 332.31]]}, {"timestamp": 1631536236793, "ltp": 1.45, "tv": 2634.15, "trd": [[1.45, 13.88]], "batb": [[0, 1.45, 6.86]], "batl": NaN}, {"timestamp": 1631536240490, "ltp": 1.45, "tv": 2647.87, "trd": [[1.45, 27.6]], "batb": [[0, 1.43, 20.98], [1, 1.42, 121.03], [2, 1.41, 272.59]], "batl": NaN}, {"timestamp": 1631536243200, "ltp": 1.45, "tv": 2647.87, "trd": NaN, "batb": [[0, 1.45, 149], [1, 1.43, 20.98], [2, 1.42, 121.03]], "batl": NaN}, {"timestamp": 1631536246496, "ltp": 1.45, "tv": 2647.87, "trd": NaN, "batb": NaN, "batl": [[1, 1.47, 98.46]]}, {"timestamp": 1631536249385, "ltp": 1.45, "tv": 2647.87, "trd": NaN, "batb": [[1, 1.44, 13.11], [2, 1.43, 20.98]], "batl": [[0, 1.46, 172.6]]}, {"timestamp": 1631536250104, "ltp": 1.45, "tv": 2647.87, "trd": NaN, "batb": [[1, 1.43, 20.98], [2, 1.42, 121.03]], "batl": [[0, 1.46, 160.06]]}, {"timestamp": 1631536256099, "ltp": 1.45, "tv": 2647.87, "trd": NaN, "batb": [[1, 1.44, 13.11], [2, 1.43, 20.98]], "batl": [[0, 1.46, 172.6]]}, {"timestamp": 1631536259821, "ltp": 1.45, "tv": 2647.87, "trd": NaN, "batb": [[1, 1.42, 110.53], [2, 1.41, 120.25]], "batl": [[0, 1.46, 160.06], [2, 1.82, 475.58]]}, {"timestamp": 1631536260330, "ltp": 1.45, "tv": 2647.87, "trd": NaN, "batb": [[0, 1.33, 99.16], [1, 1.31, 484.1], [2, 1.2, 386.24]], "batl": [[0, 1.82, 475.58], [1, 1.89, 255.54], [2, 1.82, 0]]}, {"timestamp": 1631536263605, "ltp": 1.45, "tv": 2647.87, "trd": NaN, "batb": NaN, "batl": [[2, 1000, 2.17]]}, {"timestamp": 1631536264808, "ltp": 1.45, "tv": 2647.87, "trd": NaN, "batb": [[0, 1.43, 163.83], [1, 1.42, 117.02], [2, 1.33, 99.16]], "batl": [[0, 1.47, 98.84], [1, 1.48, 96.28], [2, 1.82, 475.58]]}, {"timestamp": 1631536268439, "ltp": 1.45, "tv": 2647.87, "trd": NaN, "batb": [[2, 1.34, 471.85]], "batl": NaN}, {"timestamp": 1631536271541, "ltp": 1.45, "tv": 2647.87, "trd": NaN, "batb": [[0, 1.44, 106], [1, 1.43, 163.83], [2, 1.42, 117.02]], "batl": NaN}, {"timestamp": 1631536272825, "ltp": 1.45, "tv": 2647.87, "trd": NaN, "batb": [[0, 1.34, 471.85], [1, 1.33, 99.16], [2, 1.2, 386.24]], "batl": [[0, 1.82, 475.58], [1, 1.89, 255.54], [2, 810, 0.07]]}, {"timestamp": 1631536275342, "ltp": 1.45, "tv": 2647.87, "trd": NaN, "batb": [[0, 1.37, 208.7], [1, 1.36, 143.39], [2, 1.33, 99.16]], "batl": NaN}, {"timestamp": 1631536276846, "ltp": 1.45, "tv": 2647.87, "trd": NaN, "batb": [[0, 1.38, 546.28], [1, 1.37, 208.7], [2, 1.36, 143.39]], "batl": [[0, 1.4, 7.14], [1, 1.41, 12.33], [2, 1.42, 2351.88]]}, {"timestamp": 1631536277843, "ltp": 1.45, "tv": 2647.87, "trd": NaN, "batb": [[0, 1.38, 654.98], [1, 1.37, 263.06], [2, 1.36, 197.75]], "batl": [[1, 1.41, 146.16], [2, 1.42, 114.13]]}, {"timestamp": 1631536278535, "ltp": 1.45, "tv": 2647.87, "trd": NaN, "batb": [[0, 1.38, 568.02], [1, 1.37, 219.58], [2, 1.36, 154.27]], "batl": NaN}, {"timestamp": 1631536285067, "ltp": 1.45, "tv": 2647.87, "trd": NaN, "batb": [[0, 1.39, 171], [1, 1.38, 568.02], [2, 1.37, 219.58]], "batl": NaN}, {"timestamp": 1631536286887, "ltp": 1.4, "tv": 2647.99, "trd": [[1.4, 29.86]], "batb": NaN, "batl": [[0, 1.4, 7.02]]}, {"timestamp": 1631536295298, "ltp": 1.4, "tv": 2647.99, "trd": NaN, "batb": [[0, 1.29, 114.73], [1, 1.28, 492.6], [2, 1.2, 386.24]], "batl": [[0, 1.82, 475.58], [1, 1.89, 255.54], [2, 44, 7.23]]}, {"timestamp": 1631536300410, "ltp": 1.4, "tv": 2647.99, "trd": NaN, "batb": [[0, 1.39, 111.68], [1, 1.38, 132.68], [2, 1.29, 114.73]], "batl": [[0, 1.42, 85.22], [1, 1.43, 111.22], [2, 1.82, 475.58]]}, {"timestamp": 1631536307440, "ltp": 1.4, "tv": 2647.99, "trd": NaN, "batb": [[0, 1.29, 114.73], [1, 1.28, 492.6], [2, 1.2, 386.24]], "batl": [[0, 1.82, 475.58], [1, 1.89, 255.54], [2, 44, 7.23]]}, {"timestamp": 1631536310402, "ltp": 1.4, "tv": 2647.99, "trd": NaN, "batb": [[0, 1.34, 104.63], [1, 1.33, 158.63], [2, 1.29, 114.73]], "batl": [[0, 1.48, 89.65], [1, 1.49, 93.78], [2, 1.82, 475.58]]}, {"timestamp": 1631536320726, "ltp": 1.4, "tv": 2647.99, "trd": NaN, "batb": NaN, "batl": [[0, 1.82, 475.58], [1, 1.89, 255.54], [2, 44, 7.23]]}, {"timestamp": 1631536323722, "ltp": 1.4, "tv": 2647.99, "trd": NaN, "batb": [[0, 1.34, 631.44]], "batl": [[0, 1.37, 177.06], [1, 1.38, 129.42], [2, 1.39, 631.18]]}, {"timestamp": 1631536329265, "ltp": 1.4, "tv": 2647.99, "trd": NaN, "batb": [[0, 1.35, 120], [1, 1.34, 631.44], [2, 1.33, 158.63]], "batl": NaN}, {"timestamp": 1631536335299, "ltp": 1.4, "tv": 2647.99, "trd": NaN, "batb": [[0, 1.34, 631.44], [1, 1.33, 158.63], [2, 1.29, 114.73]], "batl": NaN}, {"timestamp": 1631536338504, "ltp": 1.4, "tv": 2647.99, "trd": NaN, "batb": [[0, 1.36, 380], [1, 1.34, 631.44], [2, 1.33, 158.63]], "batl": NaN}, {"timestamp": 1631536348709, "ltp": 1.36, "tv": 2653.09, "trd": [[1.36, 5.11]], "batb": [[0, 1.36, 377.45], [1, 1.29, 114.73], [2, 1.28, 492.6]], "batl": [[0, 1.82, 475.58], [1, 1.89, 255.54], [2, 44, 7.23]]}, {"timestamp": 1631536349293, "ltp": 1.36, "tv": 2653.09, "trd": NaN, "batb": [[0, 1.28, 492.6], [1, 1.27, 127.86], [2, 1.17, 314.59]], "batl": NaN}, {"timestamp": 1631536351720, "ltp": 1.36, "tv": 2653.09, "trd": NaN, "batb": [[0, 1.31, 132.19], [1, 1.3, 179.15], [2, 1.28, 492.6]], "batl": [[0, 1.43, 182.13], [1, 1.44, 107.05], [2, 1.82, 475.58]]}, {"timestamp": 1631536355109, "ltp": 1.36, "tv": 2653.09, "trd": NaN, "batb": NaN, "batl": [[0, 1.43, 182.18]]}, {"timestamp": 1631536365734, "ltp": 1.35, "tv": 2653.14, "trd": [[1.35, 0.05]], "batb": NaN, "batl": [[0, 1.43, 182.13]]}, {"timestamp": 1631536369033, "ltp": 1.35, "tv": 2653.14, "trd": NaN, "batb": [[0, 1.28, 492.6], [1, 1.27, 127.86], [2, 1.17, 314.59]], "batl": [[0, 1.82, 475.58], [1, 1.89, 255.54], [2, 44, 7.23]]}, {"timestamp": 1631536371651, "ltp": 1.35, "tv": 2653.14, "trd": NaN, "batb": [[0, 1.4, 10.74], [1, 1.39, 1964.57], [2, 1.38, 197.1]], "batl": [[0, 1.45, 187.58], [1, 1.46, 182.06], [2, 1.47, 182.06]]}, {"timestamp": 1631536372646, "ltp": 1.35, "tv": 2653.14, "trd": NaN, "batb": [[1, 1.39, 285.19], [2, 1.38, 231.4]], "batl": [[0, 1.41, 7.09], [1, 1.43, 182.13], [2, 1.44, 107.05]]}, {"timestamp": 1631536376660, "ltp": 1.35, "tv": 2653.14, "trd": NaN, "batb": NaN, "batl": [[1, 1.42, 96.54], [2, 1.43, 182.13]]}, {"timestamp": 1631536376928, "ltp": 1.35, "tv": 2653.14, "trd": NaN, "batb": NaN, "batl": [[1, 1.43, 182.13], [2, 1.44, 107.05]]}, {"timestamp": 1631536379852, "ltp": 1.35, "tv": 2653.14, "trd": NaN, "batb": [[0, 1.4, 168.74]], "batl": NaN}, {"timestamp": 1631536383766, "ltp": 1.35, "tv": 2653.14, "trd": NaN, "batb": [[1, 1.39, 126.41]], "batl": NaN}, {"timestamp": 1631536400595, "ltp": 1.35, "tv": 2653.14, "trd": NaN, "batb": [[0, 1.4, 158], [1, 1.31, 484.1], [2, 1.3, 113.39]], "batl": [[0, 1.82, 475.58], [1, 1.89, 255.54], [2, 44, 7.23]]}, {"timestamp": 1631536401326, "ltp": 1.35, "tv": 2653.14, "trd": NaN, "batb": [[0, 1.31, 484.1], [1, 1.3, 113.39], [2, 1.17, 314.59]], "batl": NaN}, {"timestamp": 1631536403504, "ltp": 1.35, "tv": 2653.14, "trd": NaN, "batb": [[0, 1.34, 139.63], [1, 1.33, 159.15], [2, 1.31, 484.1]], "batl": [[0, 1.52, 92.51], [1, 1.53, 84.51], [2, 1.82, 475.58]]}, {"timestamp": 1631536408296, "ltp": 1.35, "tv": 2653.14, "trd": NaN, "batb": [[0, 1.31, 484.1], [1, 1.3, 113.39], [2, 1.17, 314.59]], "batl": NaN}, {"timestamp": 1631536410319, "ltp": 1.35, "tv": 2653.14, "trd": NaN, "batb": [[0, 1.3, 113.39], [1, 1.17, 314.59], [2, 1.15, 356.53]], "batl": NaN}, {"timestamp": 1631536411313, "ltp": 1.35, "tv": 2653.14, "trd": NaN, "batb": [[0, 1.49, 134.22], [1, 1.48, 119.33], [2, 1.47, 120.93]], "batl": [[0, 1.52, 107.79], [2, 1.56, 564.91]]}, {"timestamp": 1631536412302, "ltp": 1.49, "tv": 2666.56, "trd": [[1.49, 13.42]], "batb": [[0, 1.49, 127.51]], "batl": NaN}, {"timestamp": 1631536416077, "ltp": 1.49, "tv": 2707.49, "trd": [[1.49, 54.35]], "batb": [[0, 1.49, 107.05]], "batl": NaN}, {"timestamp": 1631536429621, "ltp": 1.49, "tv": 2921.61, "trd": [[1.49, 268.47]], "batb": [[0, 1.48, 119.33], [1, 1.47, 120.93], [2, 1.46, 10.2]], "batl": [[0, 1.49, 106.73], [1, 1.52, 107.79], [2, 1.53, 84.51]]}, {"timestamp": 1631536432754, "ltp": 1.49, "tv": 2964.4, "trd": [[1.49, 311.26]], "batb": [[0, 1.35, 93.14], [1, 1.34, 471.85], [2, 1.17, 314.59]], "batl": [[0, 1.49, 85.33], [1, 1.82, 475.58], [2, 1.89, 255.54]]}, {"timestamp": 1631536435359, "ltp": 1.49, "tv": 2964.4, "trd": NaN, "batb": [[0, 1.4, 106.24], [1, 1.39, 128.26], [2, 1.35, 93.14]], "batl": [[1, 1.69, 116.33], [2, 1.71, 113.9]]}, {"timestamp": 1631536436721, "ltp": 1.49, "tv": 2964.4, "trd": NaN, "batb": [[0, 1.35, 93.14], [1, 1.34, 471.85], [2, 1.17, 314.59]], "batl": NaN}, {"timestamp": 1631536437756, "ltp": 1.49, "tv": 2964.4, "trd": NaN, "batb": [[1, 1.17, 314.59], [2, 1.15, 356.53]], "batl": NaN}, {"timestamp": 1631536439734, "ltp": 1.49, "tv": 3135.05, "trd": [[1.49, 481.91]], "batb": [[0, 1.64, 1394.41], [1, 1.63, 120.09], [2, 1.62, 68.89]], "batl": [[0, 1.66, 9.19]]}, {"timestamp": 1631536440723, "ltp": 1.64, "tv": 3147.39, "trd": [[1.64, 76.17]], "batb": [[0, 1.64, 111.08]], "batl": NaN}, {"timestamp": 1631536444529, "ltp": 1.64, "tv": 3147.39, "trd": NaN, "batb": [[0, 1.64, 208.08]], "batl": NaN}, {"timestamp": 1631536451488, "ltp": 1.64, "tv": 3147.39, "trd": NaN, "batb": [[0, 1.64, 97]], "batl": NaN}, {"timestamp": 1631536455396, "ltp": 1.64, "tv": 3150.43, "trd": [[1.64, 79.21]], "batb": [[0, 1.64, 95.48]], "batl": NaN}, {"timestamp": 1631536467263, "ltp": 1.64, "tv": 3150.43, "trd": NaN, "batb": NaN, "batl": [[2, 1.71, 113.95]]}, {"timestamp": 1631536515185, "ltp": 1.64, "tv": 3150.69, "trd": [[1.64, 79.47]], "batb": [[0, 1.64, 95.35]], "batl": NaN}, {"timestamp": 1631536534227, "ltp": 1.64, "tv": 3150.69, "trd": NaN, "batb": [[0, 1.47, 63.76], [1, 1.44, 442.2], [2, 1.43, 1.7]], "batl": [[0, 1.89, 255.58], [1, 2.16, 347.55], [2, 44, 7.23]]}, {"timestamp": 1631536537249, "ltp": 1.64, "tv": 3150.69, "trd": NaN, "batb": [[0, 1.55, 67.41], [1, 1.54, 83.11], [2, 1.47, 63.76]], "batl": [[0, 1.76, 88.21], [1, 1.78, 99.87], [2, 1.89, 255.54]]}, {"timestamp": 1631536553353, "ltp": 1.64, "tv": 3150.69, "trd": NaN, "batb": NaN, "batl": [[0, 1.89, 255.58], [1, 2.16, 347.55], [2, 44, 7.23]]}, {"timestamp": 1631536555079, "ltp": 1.64, "tv": 3150.69, "trd": NaN, "batb": NaN, "batl": [[1, 44, 7.23], [2, 810, 0.07]]}, {"timestamp": 1631536556750, "ltp": 1.55, "tv": 3163.67, "trd": [[1.55, 12.98]], "batb": [[0, 1.54, 83.11], [1, 1.47, 63.76], [2, 1.43, 1.7]], "batl": [[0, 1.58, 20.42], [1, 1.59, 90.67], [2, 1.6, 71.52]]}, {"timestamp": 1631536559275, "ltp": 1.55, "tv": 3163.67, "trd": NaN, "batb": [[0, 1.54, 147.35], [1, 1.53, 85.69], [2, 1.47, 63.76]], "batl": NaN}, {"timestamp": 1631536560842, "ltp": 1.55, "tv": 3163.67, "trd": NaN, "batb": NaN, "batl": [[0, 1.57, 58.4], [1, 1.58, 20.42], [2, 1.59, 90.67]]}, {"timestamp": 1631536561155, "ltp": 1.55, "tv": 3163.67, "trd": NaN, "batb": NaN, "batl": [[0, 1.58, 20.42], [1, 1.59, 90.67], [2, 1.6, 71.52]]}, {"timestamp": 1631536576807, "ltp": 1.55, "tv": 3163.67, "trd": NaN, "batb": NaN, "batl": [[0, 1.59, 90.67], [1, 1.6, 71.52], [2, 1.89, 255.54]]}, {"timestamp": 1631536577072, "ltp": 1.55, "tv": 3163.67, "trd": NaN, "batb": [[0, 1.43, 1.7], [1, 1.4, 79.16], [2, 1.38, 454.63]], "batl": [[0, 1.89, 255.54], [1, 2.04, 388.3], [2, 44, 7.23]]}, {"timestamp": 1631536581621, "ltp": 1.55, "tv": 3163.67, "trd": NaN, "batb": [[0, 1.53, 77.44], [1, 1.52, 87.54], [2, 1.43, 1.7]], "batl": [[0, 1.57, 94.23], [1, 1.58, 74.88], [2, 1.89, 255.54]]}, {"timestamp": 1631536584811, "ltp": 1.55, "tv": 3163.67, "trd": NaN, "batb": [[0, 1.43, 1.7], [1, 1.4, 79.16], [2, 1.38, 454.63]], "batl": [[0, 1.89, 255.54], [1, 2.04, 388.3], [2, 44, 7.23]]}, {"timestamp": 1631536587702, "ltp": 1.55, "tv": 3163.67, "trd": NaN, "batb": [[0, 1.46, 84.63], [1, 1.45, 106.25], [2, 1.43, 1.7]], "batl": [[0, 1.67, 107.51], [1, 1.69, 118.62], [2, 1.89, 255.54]]}, {"timestamp": 1631536588826, "ltp": 1.55, "tv": 3163.67, "trd": NaN, "batb": [[0, 1.43, 1.7], [1, 1.4, 79.16], [2, 1.38, 454.63]], "batl": [[0, 1.89, 255.54], [1, 2.04, 388.3], [2, 44, 7.23]]}, {"timestamp": 1631536590708, "ltp": 1.55, "tv": 3163.67, "trd": NaN, "batb": [[2, 1.37, 2.63]], "batl": [[1, 44, 7.23], [2, 44, 0]]}, {"timestamp": 1631536591804, "ltp": 1.55, "tv": 3163.67, "trd": NaN, "batb": [[0, 1.46, 96.71], [1, 1.45, 106.25], [2, 1.43, 1.7]], "batl": [[0, 1.47, 6.8], [1, 1.48, 12.13], [2, 1.5, 143.34]]}, {"timestamp": 1631536592696, "ltp": 1.55, "tv": 3163.67, "trd": NaN, "batb": [[2, 1.44, 20.84]], "batl": NaN}, {"timestamp": 1631536596607, "ltp": 1.55, "tv": 3163.67, "trd": NaN, "batb": [[0, 1.46, 212.71]], "batl": NaN}, {"timestamp": 1631536611843, "ltp": 1.55, "tv": 3163.67, "trd": NaN, "batb": [[0, 1.46, 200.63], [2, 1.4, 79.16]], "batl": [[0, 1.5, 143.34], [1, 1.51, 88.62], [2, 1.89, 696.82]]}, {"timestamp": 1631536612263, "ltp": 1.55, "tv": 3163.67, "trd": NaN, "batb": [[0, 1.37, 2.63], [1, 1.33, 98.83], [2, 1.31, 484.1]], "batl": [[0, 1.89, 696.82], [1, 44, 7.23], [2, 1.89, 0]]}, {"timestamp": 1631536614826, "ltp": 1.55, "tv": 3163.67, "trd": NaN, "batb": [[0, 1.38, 156.62], [1, 1.37, 140.5], [2, 1.33, 98.83]], "batl": [[0, 1.56, 76.18], [1, 1.57, 76.76], [2, 1.89, 696.82]]}, {"timestamp": 1631536627465, "ltp": 1.55, "tv": 3163.67, "trd": NaN, "batb": [[0, 1.37, 2.63], [1, 1.33, 98.83], [2, 1.31, 484.1]], "batl": NaN}, {"timestamp": 1631536628294, "ltp": 1.55, "tv": 3163.67, "trd": NaN, "batb": [[2, 1.25, 237.69]], "batl": NaN}, {"timestamp": 1631536629697, "ltp": 1.55, "tv": 3163.67, "trd": NaN, "batb": [[0, 1.5, 528.92], [1, 1.49, 50], [2, 1.48, 50]], "batl": [[2, 1.58, 446.16]]}, {"timestamp": 1631536630688, "ltp": 1.52, "tv": 3176.83, "trd": [[1.52, 15.8]], "batb": [[0, 1.52, 97.11], [1, 1.51, 90.03], [2, 1.5, 448.92]], "batl": NaN}, {"timestamp": 1631536634668, "ltp": 1.52, "tv": 3176.83, "trd": NaN, "batb": NaN, "batl": [[0, 1.54, 49.84], [1, 1.56, 76.18], [2, 1.57, 76.76]]}, {"timestamp": 1631536634871, "ltp": 1.52, "tv": 3176.83, "trd": NaN, "batb": NaN, "batl": [[0, 1.56, 76.18], [1, 1.57, 76.76], [2, 1.58, 446.16]]}, {"timestamp": 1631536649499, "ltp": 1.52, "tv": 3176.83, "trd": NaN, "batb": [[0, 1.52, 59], [1, 1.38, 454.63], [2, 1.37, 89.91]], "batl": [[0, 1.89, 696.82], [1, 44, 7.23], [2, 1.58, 0]]}, {"timestamp": 1631536650305, "ltp": 1.52, "tv": 3176.83, "trd": NaN, "batb": [[0, 1.38, 454.63], [1, 1.37, 89.91], [2, 1.25, 237.69]], "batl": NaN}, {"timestamp": 1631536653644, "ltp": 1.52, "tv": 3176.83, "trd": NaN, "batb": [[0, 1.5, 94.65], [1, 1.49, 94.97], [2, 1.38, 454.63]], "batl": [[0, 1.54, 99.81], [1, 1.55, 80.43], [2, 1.89, 696.82]]}, {"timestamp": 1631536658621, "ltp": 1.52, "tv": 3176.83, "trd": NaN, "batb": [[0, 1.38, 454.63], [1, 1.37, 87.28], [2, 1.25, 237.69]], "batl": [[0, 1.89, 696.82], [1, 44, 7.23], [2, 1.89, 0]]}, {"timestamp": 1631536661552, "ltp": 1.52, "tv": 3176.83, "trd": NaN, "batb": [[0, 1.42, 128.28], [1, 1.41, 120.49], [2, 1.38, 454.63]], "batl": [[0, 1.65, 87.22], [1, 1.66, 62.8], [2, 1.89, 696.82]]}, {"timestamp": 1631536662336, "ltp": 1.52, "tv": 3176.83, "trd": NaN, "batb": [[0, 1.38, 454.63], [1, 1.37, 87.28], [2, 1.25, 237.69]], "batl": [[0, 1.89, 696.82], [1, 44, 7.23], [2, 1.89, 0]]}, {"timestamp": 1631536662914, "ltp": 1.52, "tv": 3176.83, "trd": NaN, "batb": [[0, 1.37, 87.28], [1, 1.25, 237.69], [2, 1.2, 386.24]], "batl": NaN}, {"timestamp": 1631536665542, "ltp": 1.52, "tv": 3176.83, "trd": NaN, "batb": [[0, 1.42, 128.28], [1, 1.41, 120.49], [2, 1.4, 406.6]], "batl": [[0, 1.44, 6.94], [1, 1.46, 205.28], [2, 1.47, 129.49]]}, {"timestamp": 1631536666848, "ltp": 1.52, "tv": 3176.83, "trd": NaN, "batb": [[1, 1.41, 141.77], [2, 1.4, 417.24]], "batl": [[1, 1.46, 164.18], [2, 1.47, 108.95]]}, {"timestamp": 1631536673381, "ltp": 1.52, "tv": 3176.83, "trd": NaN, "batb": [[0, 1.42, 200.28]], "batl": NaN}, {"timestamp": 1631536682473, "ltp": 1.52, "tv": 3176.83, "trd": NaN, "batb": [[1, 1.41, 120.49], [2, 1.37, 87.28]], "batl": [[0, 1.46, 143.64], [1, 1.47, 98.67], [2, 1.89, 696.82]]}, {"timestamp": 1631536683386, "ltp": 1.52, "tv": 3176.83, "trd": NaN, "batb": [[0, 1.31, 484.1], [1, 1.3, 110.12], [2, 1.2, 386.24]], "batl": [[0, 1.89, 696.82], [1, 44, 7.23], [2, 1.89, 0]]}, {"timestamp": 1631536685802, "ltp": 1.52, "tv": 3176.83, "trd": NaN, "batb": [[0, 1.34, 223.77], [1, 1.33, 160.46], [2, 1.31, 484.1]], "batl": [[0, 1.53, 150.92], [1, 1.54, 82.12], [2, 1.89, 696.82]]}, {"timestamp": 1631536703219, "ltp": 1.52, "tv": 3176.83, "trd": NaN, "batb": NaN, "batl": [[0, 1.89, 696.82], [1, 44, 7.23], [2, 1.89, 0]]}, {"timestamp": 1631536706616, "ltp": 1.52, "tv": 3176.83, "trd": NaN, "batb": [[0, 1.34, 152.43], [1, 1.3, 110.12], [2, 1.17, 314.59]], "batl": [[0, 1.37, 23.45], [1, 1.38, 153.41], [2, 1.39, 135.97]]}, {"timestamp": 1631536707508, "ltp": 1.52, "tv": 3176.83, "trd": NaN, "batb": [[2, 1.27, 125.86]], "batl": NaN}, {"timestamp": 1631536709541, "ltp": 1.52, "tv": 3176.83, "trd": NaN, "batb": [[0, 1.35, 109.42], [1, 1.34, 152.43], [2, 1.3, 110.12]], "batl": NaN}, {"timestamp": 1631536712737, "ltp": 1.52, "tv": 3176.83, "trd": NaN, "batb": [[0, 1.35, 180.42]], "batl": NaN}, {"timestamp": 1631536724641, "ltp": 1.35, "tv": 3254.32, "trd": [[1.35, 77.54]], "batb": [[0, 1.35, 141.67]], "batl": NaN}, {"timestamp": 1631536727937, "ltp": 1.35, "tv": 3254.32, "trd": NaN, "batb": [[0, 1.35, 158.79]], "batl": [[1, 1.38, 174.59]]}, {"timestamp": 1631536733812, "ltp": 1.37, "tv": 3258.26, "trd": [[1.37, 3.94]], "batb": NaN, "batl": [[0, 1.37, 21.48]]}, {"timestamp": 1631536736696, "ltp": 1.37, "tv": 3258.46, "trd": [[1.37, 4.14]], "batb": NaN, "batl": [[0, 1.37, 21.28]]}, {"timestamp": 1631536739674, "ltp": 1.37, "tv": 3258.46, "trd": NaN, "batb": NaN, "batl": [[0, 1.38, 152.85], [1, 1.39, 125.09], [2, 1.77, 507.52]]}, {"timestamp": 1631536740295, "ltp": 1.37, "tv": 3258.46, "trd": NaN, "batb": [[0, 1.27, 125.86], [1, 1.25, 512.06], [2, 1.17, 314.59]], "batl": [[0, 1.77, 507.52], [1, 1.89, 255.54], [2, 44, 7.23]]}, {"timestamp": 1631536742806, "ltp": 1.37, "tv": 3258.46, "trd": NaN, "batb": [[0, 1.31, 189.88], [1, 1.3, 180.12], [2, 1.27, 125.86]], "batl": [[0, 1.44, 110.64], [1, 1.45, 104.45], [2, 1.77, 507.52]]}, {"timestamp": 1631536743069, "ltp": 1.37, "tv": 3258.46, "trd": NaN, "batb": [[0, 1.27, 125.86], [1, 1.25, 512.06], [2, 1.17, 314.59]], "batl": [[0, 1.77, 507.52], [1, 1.89, 255.54], [2, 44, 7.23]]}, {"timestamp": 1631536745480, "ltp": 1.37, "tv": 3258.46, "trd": NaN, "batb": [[0, 1.36, 105.28], [1, 1.35, 147.14], [2, 1.27, 125.86]], "batl": [[0, 1.39, 123.94], [1, 1.4, 121.46], [2, 1.77, 507.52]]}, {"timestamp": 1631536752519, "ltp": 1.37, "tv": 3258.46, "trd": NaN, "batb": [[0, 1.27, 125.86], [1, 1.25, 512.06], [2, 1.17, 314.59]], "batl": [[0, 1.77, 507.52], [1, 1.89, 255.54], [2, 44, 7.23]]}, {"timestamp": 1631536755436, "ltp": 1.37, "tv": 3258.46, "trd": NaN, "batb": [[0, 1.31, 189.88], [1, 1.3, 180.12], [2, 1.27, 125.86]], "batl": [[0, 1.44, 110.64], [1, 1.45, 104.45], [2, 1.77, 507.52]]}, {"timestamp": 1631536764240, "ltp": 1.37, "tv": 3258.46, "trd": NaN, "batb": NaN, "batl": [[0, 1.77, 507.52], [1, 1.89, 255.54], [2, 44, 7.23]]}, {"timestamp": 1631536766832, "ltp": 1.37, "tv": 3258.46, "trd": NaN, "batb": [[2, 1.29, 210.86]], "batl": [[0, 1.34, 1364.65], [1, 1.77, 507.52], [2, 1.89, 255.54]]}, {"timestamp": 1631536767822, "ltp": 1.37, "tv": 3258.46, "trd": NaN, "batb": [[2, 1.29, 105.42]], "batl": [[0, 1.33, 13.63], [1, 1.34, 232.73], [2, 1.35, 596.54]]}, {"timestamp": 1631536771829, "ltp": 1.37, "tv": 3258.46, "trd": NaN, "batb": NaN, "batl": [[1, 1.34, 344.75]]}, {"timestamp": 1631536772037, "ltp": 1.37, "tv": 3258.46, "trd": NaN, "batb": NaN, "batl": [[1, 1.34, 232.73]]}, {"timestamp": 1631536775058, "ltp": 1.37, "tv": 3258.46, "trd": NaN, "batb": [[0, 1.31, 284.88]], "batl": NaN}, {"timestamp": 1631536779278, "ltp": 1.37, "tv": 3258.46, "trd": NaN, "batb": [[0, 1.31, 189.88]], "batl": [[1, 1.34, 123.04]]}, {"timestamp": 1631536782360, "ltp": 1.37, "tv": 3258.46, "trd": NaN, "batb": [[0, 1.32, 381], [1, 1.31, 189.88], [2, 1.3, 180.12]], "batl": NaN}, {"timestamp": 1631536787778, "ltp": 1.32, "tv": 3258.62, "trd": [[1.32, 0.16]], "batb": [[0, 1.32, 380.92]], "batl": NaN}, {"timestamp": 1631536795684, "ltp": 1.32, "tv": 3258.62, "trd": NaN, "batb": NaN, "batl": [[0, 1.34, 115.58], [1, 1.35, 143.98], [2, 1.77, 507.52]]}, {"timestamp": 1631536796310, "ltp": 1.32, "tv": 3258.62, "trd": NaN, "batb": [[0, 1.24, 143.68], [1, 1.22, 365.72], [2, 1.17, 314.59]], "batl": [[0, 1.77, 507.52], [1, 1.89, 255.54], [2, 44, 7.23]]}, {"timestamp": 1631536798805, "ltp": 1.32, "tv": 3258.62, "trd": NaN, "batb": [[0, 1.28, 262.35], [1, 1.27, 206.71], [2, 1.24, 143.68]], "batl": [[0, 1.39, 105.5], [1, 1.4, 121.68], [2, 1.77, 507.52]]}, {"timestamp": 1631536818824, "ltp": 1.32, "tv": 3258.62, "trd": NaN, "batb": [[0, 1.24, 143.68], [1, 1.22, 365.72], [2, 1.17, 314.59]], "batl": NaN}, {"timestamp": 1631536820851, "ltp": 1.32, "tv": 3258.62, "trd": NaN, "batb": NaN, "batl": [[0, 1.28, 4.13], [1, 1.39, 105.5], [2, 1.4, 121.68]]}, {"timestamp": 1631536821843, "ltp": 1.28, "tv": 3266.88, "trd": [[1.28, 8.26]], "batb": [[0, 1.36, 3084.62], [1, 1.35, 248.14], [2, 1.34, 97.78]], "batl": [[0, 1.38, 14.42]]}, {"timestamp": 1631536822734, "ltp": 1.28, "tv": 3266.88, "trd": NaN, "batb": [[0, 1.36, 364.09]], "batl": [[0, 1.38, 21.67]]}, {"timestamp": 1631536829724, "ltp": 1.28, "tv": 3266.88, "trd": NaN, "batb": [[0, 1.36, 436.09]], "batl": NaN}, {"timestamp": 1631536831455, "ltp": 1.28, "tv": 3266.88, "trd": NaN, "batb": [[0, 1.36, 72], [1, 1.27, 125.19], [2, 1.25, 349.29]], "batl": [[0, 1.37, 3.85], [1, 1.77, 507.52], [2, 1.89, 255.54]]}, {"timestamp": 1631536832348, "ltp": 1.28, "tv": 3266.88, "trd": NaN, "batb": [[0, 1.27, 125.19], [1, 1.25, 349.29], [2, 1.17, 314.59]], "batl": NaN}, {"timestamp": 1631536834342, "ltp": 1.28, "tv": 3266.88, "trd": NaN, "batb": [[0, 1.32, 115.08], [1, 1.31, 171.7], [2, 1.27, 125.19]], "batl": [[1, 1.47, 145.49], [2, 1.48, 95.72]]}, {"timestamp": 1631536840556, "ltp": 1.28, "tv": 3266.88, "trd": NaN, "batb": NaN, "batl": [[1, 1.77, 507.52], [2, 1.89, 255.54]]}, {"timestamp": 1631536843588, "ltp": 1.28, "tv": 3266.88, "trd": NaN, "batb": [[0, 1.32, 129.96], [1, 1.31, 724.25]], "batl": [[0, 1.34, 30.58], [1, 1.35, 236.14], [2, 1.36, 774.01]]}, {"timestamp": 1631536847290, "ltp": 1.28, "tv": 3266.88, "trd": NaN, "batb": [[0, 1.33, 284], [1, 1.32, 129.96], [2, 1.31, 724.25]], "batl": NaN}, {"timestamp": 1631536849902, "ltp": 1.28, "tv": 3266.88, "trd": NaN, "batb": NaN, "batl": [[1, 1.35, 262.63]]}, {"timestamp": 1631536852503, "ltp": 1.28, "tv": 3266.88, "trd": NaN, "batb": NaN, "batl": [[1, 1.35, 236.14]]}, {"timestamp": 1631536855618, "ltp": 1.33, "tv": 3319.86, "trd": [[1.33, 52.98]], "batb": [[0, 1.33, 257.51]], "batl": NaN}, {"timestamp": 1631536870608, "ltp": 1.33, "tv": 3327.8, "trd": [[1.33, 60.92]], "batb": [[0, 1.33, 253.54]], "batl": NaN}, {"timestamp": 1631536877448, "ltp": 1.33, "tv": 3327.8, "trd": NaN, "batb": [[1, 1.25, 349.29], [2, 1.24, 143.34]], "batl": [[0, 1.77, 507.52], [1, 1.89, 255.54], [2, 8.8, 7.23]]}, {"timestamp": 1631536878337, "ltp": 1.33, "tv": 3327.8, "trd": NaN, "batb": [[0, 1.25, 349.29], [1, 1.24, 143.34], [2, 1.17, 314.59]], "batl": NaN}, {"timestamp": 1631536880259, "ltp": 1.33, "tv": 3327.8, "trd": NaN, "batb": [[0, 1.29, 92.86], [1, 1.28, 194.46], [2, 1.25, 349.29]], "batl": [[0, 1.41, 175.15], [1, 1.42, 113.58], [2, 1.77, 507.52]]}, {"timestamp": 1631536889435, "ltp": 1.33, "tv": 3327.8, "trd": NaN, "batb": [[0, 1.25, 349.29], [1, 1.24, 143.34], [2, 1.17, 314.59]], "batl": [[0, 1.77, 507.52], [1, 1.89, 255.54], [2, 8.8, 7.23]]}, {"timestamp": 1631536892580, "ltp": 1.33, "tv": 3327.8, "trd": NaN, "batb": [[0, 1.37, 163.62], [1, 1.36, 705.02], [2, 1.25, 349.29]], "batl": [[0, 1.39, 12.74], [1, 1.41, 175.15], [2, 1.42, 113.58]]}, {"timestamp": 1631536893565, "ltp": 1.33, "tv": 3327.8, "trd": NaN, "batb": [[2, 1.32, 102.68]], "batl": [[0, 1.39, 19.93], [2, 1.42, 134.7]]}, {"timestamp": 1631536900389, "ltp": 1.33, "tv": 3327.8, "trd": NaN, "batb": [[0, 1.37, 254.62]], "batl": NaN}, {"timestamp": 1631536911668, "ltp": 1.33, "tv": 3327.8, "trd": NaN, "batb": [[0, 1.37, 163.62]], "batl": NaN}, {"timestamp": 1631536914800, "ltp": 1.33, "tv": 3327.8, "trd": NaN, "batb": [[0, 1.38, 381], [1, 1.37, 163.62], [2, 1.36, 705.02]], "batl": NaN}, {"timestamp": 1631536916482, "ltp": 1.33, "tv": 3327.8, "trd": NaN, "batb": [[1, 1.27, 125.6], [2, 1.25, 349.29]], "batl": [[0, 1.77, 507.52], [1, 1.89, 255.54], [2, 8.8, 7.23]]}, {"timestamp": 1631536917279, "ltp": 1.33, "tv": 3327.8, "trd": NaN, "batb": [[0, 1.27, 125.6], [1, 1.25, 349.29], [2, 1.17, 314.59]], "batl": NaN}, {"timestamp": 1631536919410, "ltp": 1.33, "tv": 3327.8, "trd": NaN, "batb": [[0, 1.32, 122.19], [1, 1.31, 171.86], [2, 1.27, 125.6]], "batl": [[0, 1.51, 156.08], [1, 1.52, 86.04], [2, 1.77, 507.52]]}, {"timestamp": 1631536924011, "ltp": 1.33, "tv": 3327.8, "trd": NaN, "batb": NaN, "batl": [[0, 1.77, 507.52], [1, 1.89, 255.54], [2, 8.8, 7.23]]}, {"timestamp": 1631536926796, "ltp": 1.33, "tv": 3327.8, "trd": NaN, "batb": [[0, 1.32, 136.03]], "batl": [[0, 1.34, 441.42], [1, 1.35, 111.12], [2, 1.36, 794.57]]}, {"timestamp": 1631536927830, "ltp": 1.33, "tv": 3327.8, "trd": NaN, "batb": NaN, "batl": [[0, 1.34, 7.46], [1, 1.35, 185.11], [2, 1.36, 888.5]]}, {"timestamp": 1631536934531, "ltp": 1.33, "tv": 3327.8, "trd": NaN, "batb": [[0, 1.33, 274], [1, 1.32, 136.03], [2, 1.31, 171.86]], "batl": NaN}, {"timestamp": 1631536939231, "ltp": 1.33, "tv": 3393.8, "trd": [[1.33, 126.92]], "batb": [[0, 1.33, 241]], "batl": NaN}, {"timestamp": 1631536959794, "ltp": 1.33, "tv": 3393.8, "trd": NaN, "batb": [[1, 1.32, 122.19]], "batl": [[0, 1.35, 174], [1, 1.36, 217.46], [2, 1.37, 5.56]]}, {"timestamp": 1631536960151, "ltp": 1.33, "tv": 3393.8, "trd": NaN, "batb": [[1, 1.25, 349.29], [2, 1.24, 146.36]], "batl": [[0, 1.77, 507.52], [1, 1.89, 255.54], [2, 8.8, 7.23]]}, {"timestamp": 1631536961353, "ltp": 1.33, "tv": 3393.8, "trd": NaN, "batb": [[0, 1.25, 349.29], [1, 1.24, 146.36], [2, 1.17, 314.59]], "batl": NaN}, {"timestamp": 1631536965381, "ltp": 1.33, "tv": 3393.8, "trd": NaN, "batb": [[0, 1.33, 150.92], [1, 1.32, 165.56], [2, 1.25, 349.29]], "batl": [[0, 1.36, 120.94], [1, 1.37, 134.21], [2, 1.77, 507.52]]}, {"timestamp": 1631536972508, "ltp": 1.33, "tv": 3393.8, "trd": NaN, "batb": [[0, 1.25, 349.29], [1, 1.24, 146.36], [2, 1.17, 314.59]], "batl": [[0, 1.77, 507.52], [1, 1.89, 255.54], [2, 8.8, 7.23]]}, {"timestamp": 1631536975525, "ltp": 1.33, "tv": 3393.8, "trd": NaN, "batb": [[0, 1.28, 187.25], [1, 1.27, 205.32], [2, 1.25, 349.29]], "batl": [[0, 1.42, 184.05], [1, 1.43, 110.11], [2, 1.77, 507.52]]}, {"timestamp": 1631536983209, "ltp": 1.33, "tv": 3393.8, "trd": NaN, "batb": [[0, 1.25, 349.29], [1, 1.24, 146.36], [2, 1.17, 314.59]], "batl": NaN}, {"timestamp": 1631536984838, "ltp": 1.33, "tv": 3393.8, "trd": NaN, "batb": [[0, 1.24, 146.36], [1, 1.17, 314.59], [2, 1.15, 356.53]], "batl": NaN}, {"timestamp": 1631536986638, "ltp": 1.33, "tv": 3393.8, "trd": NaN, "batb": [[0, 1.38, 352.22], [1, 1.37, 137.46], [2, 1.24, 146.36]], "batl": [[0, 1.4, 8.64], [1, 1.42, 184.05], [2, 1.43, 110.11]]}, {"timestamp": 1631536987533, "ltp": 1.33, "tv": 3393.8, "trd": NaN, "batb": [[2, 1.33, 100.58]], "batl": [[0, 1.39, 7.19], [1, 1.4, 8.64], [2, 1.42, 184.05]]}, {"timestamp": 1631536993746, "ltp": 1.38, "tv": 3742.94, "trd": [[1.38, 349.14]], "batb": [[0, 1.37, 137.46], [1, 1.33, 100.58], [2, 1.28, 459.41]], "batl": [[2, 1.42, 114.69]]}, {"timestamp": 1631536994335, "ltp": 1.38, "tv": 3742.94, "trd": NaN, "batb": [[0, 1.38, 114], [1, 1.37, 137.46], [2, 1.33, 100.58]], "batl": NaN}, {"timestamp": 1631536996745, "ltp": 1.38, "tv": 3742.94, "trd": NaN, "batb": [[1, 1.37, 201.6], [2, 1.36, 144.05]], "batl": [[2, 1.41, 143.12]]}, {"timestamp": 1631537002341, "ltp": 1.38, "tv": 3782.94, "trd": [[1.38, 389.14]], "batb": [[0, 1.38, 94]], "batl": NaN}, {"timestamp": 1631537003661, "ltp": 1.38, "tv": 3782.94, "trd": NaN, "batb": NaN, "batl": [[1, 1.41, 143.12], [2, 1.42, 114.69]]}, {"timestamp": 1631537006569, "ltp": 1.38, "tv": 3782.94, "trd": NaN, "batb": NaN, "batl": [[0, 1.39, 22.89]]}, {"timestamp": 1631537010573, "ltp": 1.38, "tv": 3782.94, "trd": NaN, "batb": [[1, 1.33, 100.58], [2, 1.28, 459.41]], "batl": [[0, 1.77, 507.52], [1, 1.89, 255.54], [2, 8.8, 7.23]]}, {"timestamp": 1631537011370, "ltp": 1.38, "tv": 3782.94, "trd": NaN, "batb": [[0, 1.28, 459.41], [1, 1.17, 314.59], [2, 1.15, 356.53]], "batl": NaN}, {"timestamp": 1631537014384, "ltp": 1.38, "tv": 3782.94, "trd": NaN, "batb": [[0, 1.28, 123.6]], "batl": [[0, 1.89, 255.54], [1, 8.8, 7.23], [2, 44, 7.23]]}, {"timestamp": 1631537015680, "ltp": 1.38, "tv": 3782.94, "trd": NaN, "batb": [[0, 1.39, 161.69], [1, 1.38, 133.89], [2, 1.28, 123.6]], "batl": [[0, 1.43, 151.54], [1, 1.44, 107.9], [2, 1.89, 255.54]]}, {"timestamp": 1631537016468, "ltp": 1.38, "tv": 3782.94, "trd": NaN, "batb": [[0, 1.39, 135.61]], "batl": NaN}, {"timestamp": 1631537019468, "ltp": 1.38, "tv": 3782.94, "trd": NaN, "batb": [[0, 1.4, 133], [1, 1.39, 135.61], [2, 1.38, 133.89]], "batl": [[0, 1.43, 176.95]]}, {"timestamp": 1631537022497, "ltp": 1.38, "tv": 3782.94, "trd": NaN, "batb": [[1, 1.28, 123.6], [2, 1.17, 314.59]], "batl": [[0, 1.89, 255.54], [1, 8.8, 7.23], [2, 44, 7.23]]}, {"timestamp": 1631537022871, "ltp": 1.38, "tv": 3782.94, "trd": NaN, "batb": [[0, 1.28, 123.6], [1, 1.17, 314.59], [2, 1.15, 356.53]], "batl": NaN}, {"timestamp": 1631537025369, "ltp": 1.38, "tv": 3782.94, "trd": NaN, "batb": [[0, 1.32, 133.88], [1, 1.31, 173.45], [2, 1.28, 123.6]], "batl": [[0, 1.51, 156.9], [1, 1.52, 86.82], [2, 1.89, 255.54]]}, {"timestamp": 1631537038250, "ltp": 1.32, "tv": 3786.34, "trd": [[1.32, 3.56]], "batb": [[0, 1.32, 132.18]], "batl": NaN}, {"timestamp": 1631537039501, "ltp": 1.32, "tv": 3786.34, "trd": NaN, "batb": [[0, 1.28, 123.6], [1, 1.17, 314.59], [2, 1.15, 356.53]], "batl": NaN}, {"timestamp": 1631537042717, "ltp": 1.32, "tv": 3786.34, "trd": NaN, "batb": [[0, 1.46, 166.29], [1, 1.45, 107.53], [2, 1.28, 123.6]], "batl": NaN}, {"timestamp": 1631537043811, "ltp": 1.32, "tv": 3786.34, "trd": NaN, "batb": [[2, 1.41, 77.15]], "batl": [[0, 1.47, 6.8], [1, 1.51, 156.9], [2, 1.52, 86.82]]}, {"timestamp": 1631537068363, "ltp": 1.32, "tv": 3786.34, "trd": NaN, "batb": [[0, 1.33, 99.58], [1, 1.17, 314.59], [2, 1.15, 356.53]], "batl": [[0, 1.89, 255.54], [1, 8.8, 7.23], [2, 44, 7.23]]}, {"timestamp": 1631537071301, "ltp": 1.32, "tv": 3786.34, "trd": NaN, "batb": [[0, 1.38, 137.43], [1, 1.37, 138.62], [2, 1.33, 99.58]], "batl": [[0, 1.66, 91.34], [1, 1.68, 121.71], [2, 1.89, 255.54]]}, {"timestamp": 1631537074777, "ltp": 1.32, "tv": 3786.34, "trd": NaN, "batb": [[0, 1.33, 99.58], [1, 1.17, 314.59], [2, 1.15, 356.53]], "batl": [[0, 1.89, 255.54], [1, 8.8, 7.23], [2, 44, 7.23]]}, {"timestamp": 1631537077691, "ltp": 1.32, "tv": 3786.34, "trd": NaN, "batb": [[0, 1.49, 129.94], [1, 1.48, 98.39], [2, 1.33, 99.58]], "batl": [[0, 1.5, 19.83], [1, 1.53, 76.21], [2, 1.54, 83.04]]}, {"timestamp": 1631537077893, "ltp": 1.32, "tv": 3786.34, "trd": NaN, "batb": NaN, "batl": [[0, 1.53, 76.21], [1, 1.54, 83.04], [2, 1.89, 255.54]]}, {"timestamp": 1631537084900, "ltp": 1.32, "tv": 3786.34, "trd": NaN, "batb": [[0, 1.33, 99.58], [1, 1.17, 314.59], [2, 1.15, 356.53]], "batl": [[0, 1.89, 255.54], [1, 8.8, 7.23], [2, 44, 7.23]]}, {"timestamp": 1631537087823, "ltp": 1.32, "tv": 3786.34, "trd": NaN, "batb": [[0, 1.38, 137.43], [1, 1.37, 138.62], [2, 1.33, 99.58]], "batl": [[0, 1.66, 91.34], [1, 1.68, 121.71], [2, 1.89, 255.54]]}, {"timestamp": 1631537094223, "ltp": 1.32, "tv": 3786.34, "trd": NaN, "batb": [[0, 1.33, 99.58], [1, 1.17, 314.59], [2, 1.15, 356.53]], "batl": NaN}, {"timestamp": 1631537097318, "ltp": 1.32, "tv": 3786.34, "trd": NaN, "batb": [[0, 1.61, 98.91], [1, 1.6, 72.38], [2, 1.56, 19.24]], "batl": [[0, 1.62, 18.94], [1, 1.66, 91.34], [2, 1.68, 661.37]]}, {"timestamp": 1631537098217, "ltp": 1.61, "tv": 3798.84, "trd": [[1.61, 22.26]], "batb": [[0, 1.61, 92.66]], "batl": NaN}, {"timestamp": 1631537104722, "ltp": 1.61, "tv": 3799.18, "trd": [[1.61, 22.6]], "batb": [[0, 1.61, 92.49]], "batl": NaN}, {"timestamp": 1631537112231, "ltp": 1.61, "tv": 3802.53, "trd": [[1.61, 25.96]], "batb": [[0, 1.61, 90.81]], "batl": NaN}, {"timestamp": 1631537133867, "ltp": 1.62, "tv": 3806.79, "trd": [[1.62, 16.6]], "batb": NaN, "batl": [[0, 1.62, 16.81]]}, {"timestamp": 1631537144103, "ltp": 1.62, "tv": 3806.79, "trd": NaN, "batb": NaN, "batl": [[0, 1.66, 91.34], [1, 1.68, 661.37], [2, 1.89, 255.54]]}, {"timestamp": 1631537147618, "ltp": 1.62, "tv": 3806.79, "trd": NaN, "batb": NaN, "batl": [[0, 1.62, 16.81], [1, 1.66, 91.34], [2, 1.68, 661.37]]}, {"timestamp": 1631537150689, "ltp": 1.61, "tv": 3811.9, "trd": [[1.61, 31.06]], "batb": [[0, 1.61, 88.26]], "batl": NaN}, {"timestamp": 1631537160002, "ltp": 1.61, "tv": 3812.06, "trd": [[1.61, 31.22]], "batb": [[0, 1.61, 88.18]], "batl": NaN}, {"timestamp": 1631537179437, "ltp": 1.61, "tv": 3832.06, "trd": [[1.61, 51.22]], "batb": [[0, 1.61, 78.18]], "batl": NaN}, {"timestamp": 1631537182861, "ltp": 1.61, "tv": 3832.06, "trd": NaN, "batb": [[0, 1.61, 87.45]], "batl": [[1, 1.66, 102.47]]}, {"timestamp": 1631537187683, "ltp": 1.61, "tv": 3832.06, "trd": NaN, "batb": NaN, "batl": [[2, 1.67, 40.5]]}, {"timestamp": 1631537210706, "ltp": 1.61, "tv": 3832.06, "trd": NaN, "batb": [[0, 1.54, 54.31], [1, 1.45, 67.7], [2, 1.25, 237.69]], "batl": [[0, 1.67, 40.5], [1, 1.69, 32.5], [2, 1.89, 255.54]]}, {"timestamp": 1631537211018, "ltp": 1.61, "tv": 3832.06, "trd": NaN, "batb": [[0, 1.45, 67.7], [1, 1.25, 237.69], [2, 1.2, 386.24]], "batl": [[0, 1.69, 32.5], [1, 1.89, 255.54], [2, 8.8, 7.23]]}, {"timestamp": 1631537212421, "ltp": 1.61, "tv": 3832.06, "trd": NaN, "batb": [[0, 1.47, 50.67], [1, 1.45, 67.7], [2, 1.25, 237.69]], "batl": NaN}, {"timestamp": 1631537213614, "ltp": 1.61, "tv": 3832.06, "trd": NaN, "batb": [[0, 1.52, 83.98], [1, 1.51, 90.46], [2, 1.47, 50.67]], "batl": [[1, 1.74, 84.52], [2, 1.76, 104.14]]}, {"timestamp": 1631537217719, "ltp": 1.61, "tv": 3832.06, "trd": NaN, "batb": NaN, "batl": [[0, 1.67, 34.5], [1, 1.69, 32.5], [2, 1.74, 84.52]]}, {"timestamp": 1631537218032, "ltp": 1.61, "tv": 3832.06, "trd": NaN, "batb": NaN, "batl": [[0, 1.69, 32.5], [1, 1.74, 84.52], [2, 1.76, 104.14]]}, {"timestamp": 1631537219445, "ltp": 1.61, "tv": 3832.06, "trd": NaN, "batb": [[0, 1.47, 50.67], [1, 1.45, 67.7], [2, 1.25, 237.69]], "batl": NaN}, {"timestamp": 1631537222257, "ltp": 1.61, "tv": 3832.06, "trd": NaN, "batb": [[0, 1.68, 121.56], [1, 1.66, 150.62], [2, 1.65, 9.04]], "batl": [[1, 1.7, 17.25], [2, 1.74, 84.52]]}, {"timestamp": 1631537223514, "ltp": 1.68, "tv": 3844.1, "trd": [[1.68, 679.15]], "batb": [[0, 1.68, 115.54]], "batl": [[2, 1.74, 101.76]]}, {"timestamp": 1631537228626, "ltp": 1.68, "tv": 3844.1, "trd": NaN, "batb": NaN, "batl": [[2, 1.74, 137.51]]}, {"timestamp": 1631537230134, "ltp": 1.68, "tv": 3844.1, "trd": NaN, "batb": [[0, 1.68, 216.54]], "batl": NaN}, {"timestamp": 1631537231326, "ltp": 1.68, "tv": 3844.26, "trd": [[1.68, 679.31]], "batb": [[0, 1.68, 216.46]], "batl": NaN}, {"timestamp": 1631537246657, "ltp": 1.68, "tv": 3844.26, "trd": NaN, "batb": [[0, 1.56, 46.83], [1, 1.52, 56.07], [2, 1.46, 291.71]], "batl": [[0, 1.76, 37.77], [1, 1.89, 255.54], [2, 2.22, 431.6]]}, {"timestamp": 1631537251584, "ltp": 1.68, "tv": 3844.26, "trd": NaN, "batb": [[0, 1.67, 62.75], [1, 1.66, 63.24], [2, 1.56, 46.83]], "batl": [[0, 1.72, 92.25], [1, 1.74, 108.15], [2, 1.76, 37.77]]}, {"timestamp": 1631537255023, "ltp": 1.68, "tv": 3844.26, "trd": NaN, "batb": [[0, 1.56, 46.83], [1, 1.52, 56.07], [2, 1.46, 291.71]], "batl": [[0, 1.76, 37.77], [1, 1.89, 255.54], [2, 2.22, 431.6]]}, {"timestamp": 1631537256806, "ltp": 1.68, "tv": 3844.26, "trd": NaN, "batb": [[0, 1.59, 41.11], [1, 1.56, 46.83], [2, 1.52, 56.07]], "batl": NaN}, {"timestamp": 1631537257115, "ltp": 1.68, "tv": 3844.26, "trd": NaN, "batb": [[0, 1.56, 46.83], [1, 1.52, 56.07], [2, 1.46, 291.71]], "batl": NaN}, {"timestamp": 1631537258790, "ltp": 1.68, "tv": 3844.26, "trd": NaN, "batb": [[2, 1.3, 198.07]], "batl": [[1, 1.82, 83.89], [2, 1.84, 90.21]]}, {"timestamp": 1631537260793, "ltp": 1.76, "tv": 3919.8, "trd": [[1.76, 75.54]], "batb": [[0, 1.73, 17.34], [1, 1.72, 514.01], [2, 1.71, 125.64]], "batl": [[0, 1.78, 17.91], [1, 1.83, 375.85], [2, 1.89, 255.54]]}, {"timestamp": 1631537261629, "ltp": 1.73, "tv": 3931.42, "trd": [[1.73, 11.62]], "batb": [[0, 1.73, 11.53]], "batl": NaN}, {"timestamp": 1631537263822, "ltp": 1.73, "tv": 3931.42, "trd": NaN, "batb": [[0, 1.75, 110.88], [1, 1.73, 120.65], [2, 1.72, 514.01]], "batl": [[1, 1.81, 57.88], [2, 1.83, 467.77]]}, {"timestamp": 1631537265846, "ltp": 1.75, "tv": 3973.28, "trd": [[1.75, 47.57]], "batb": [[0, 1.75, 89.95]], "batl": NaN}, {"timestamp": 1631537266932, "ltp": 1.75, "tv": 3973.28, "trd": NaN, "batb": NaN, "batl": [[1, 1.79, 31.69], [2, 1.81, 89.38]]}, {"timestamp": 1631537268634, "ltp": 1.75, "tv": 3973.28, "trd": NaN, "batb": [[0, 1.75, 99.32]], "batl": [[2, 1.8, 30.67]]}, {"timestamp": 1631537270207, "ltp": 1.75, "tv": 3973.5, "trd": [[1.75, 47.79]], "batb": [[0, 1.75, 99.21]], "batl": NaN}, {"timestamp": 1631537275348, "ltp": 1.75, "tv": 3973.98, "trd": [[1.75, 48.27]], "batb": [[0, 1.75, 98.73]], "batl": NaN}, {"timestamp": 1631537283637, "ltp": 1.75, "tv": 3973.98, "trd": NaN, "batb": [[0, 1.63, 36.23], [1, 1.6, 46.36], [2, 1.5, 287.3]], "batl": [[0, 1.89, 255.54], [1, 2.22, 431.6], [2, 1.8, 0]]}, {"timestamp": 1631537286830, "ltp": 1.75, "tv": 3973.98, "trd": NaN, "batb": [[0, 1.66, 35.28], [1, 1.63, 36.23], [2, 1.6, 46.36]], "batl": [[0, 1.82, 34.27], [1, 1.88, 81.52], [2, 1.89, 255.54]]}, {"timestamp": 1631537287144, "ltp": 1.75, "tv": 3973.98, "trd": NaN, "batb": [[0, 1.63, 36.23], [1, 1.6, 46.36], [2, 1.3, 198.07]], "batl": NaN}, {"timestamp": 1631537288760, "ltp": 1.75, "tv": 3974.02, "trd": [[1.75, 48.31]], "batb": [[0, 1.81, 102.89], [1, 1.8, 8.72], [2, 1.79, 97.29]], "batl": [[0, 1.82, 34.25], [1, 1.83, 8.28], [2, 1.88, 81.52]]}, {"timestamp": 1631537289757, "ltp": 1.81, "tv": 3985.32, "trd": [[1.81, 11.3]], "batb": [[0, 1.81, 97.24]], "batl": NaN}, {"timestamp": 1631537291467, "ltp": 1.81, "tv": 4002.76, "trd": [[1.81, 28.74]], "batb": [[0, 1.81, 88.52]], "batl": NaN}, {"timestamp": 1631537293589, "ltp": 1.81, "tv": 4035.36, "trd": [[1.81, 61.34]], "batb": [[0, 1.81, 72.22]], "batl": NaN}, {"timestamp": 1631537294785, "ltp": 1.81, "tv": 4035.36, "trd": NaN, "batb": NaN, "batl": [[2, 1.88, 7.64]]}, {"timestamp": 1631537295789, "ltp": 1.81, "tv": 4035.36, "trd": NaN, "batb": NaN, "batl": [[1, 1.83, 40.78], [2, 1.84, 31.03]]}, {"timestamp": 1631537296874, "ltp": 1.81, "tv": 4035.36, "trd": NaN, "batb": [[0, 1.81, 85.94]], "batl": NaN}, {"timestamp": 1631537303308, "ltp": 1.81, "tv": 4035.36, "trd": NaN, "batb": [[0, 1.7, 37.92], [1, 1.68, 39.33], [2, 1.55, 285.97]], "batl": [[0, 1.89, 255.54], [1, 2.22, 431.6], [2, 1.84, 0]]}, {"timestamp": 1631537306795, "ltp": 1.81, "tv": 4035.36, "trd": NaN, "batb": [[0, 1.75, 97.47], [1, 1.73, 109.15], [2, 1.7, 37.92]], "batl": [[0, 1.84, 31.78], [1, 1.89, 255.54], [2, 1.92, 59.89]]}, {"timestamp": 1631537309802, "ltp": 1.81, "tv": 4035.36, "trd": NaN, "batb": NaN, "batl": [[0, 1.83, 28.5], [1, 1.84, 31.78], [2, 1.89, 255.54]]}, {"timestamp": 1631537310321, "ltp": 1.81, "tv": 4035.36, "trd": NaN, "batb": NaN, "batl": [[0, 1.84, 31.78], [1, 1.89, 255.54], [2, 1.92, 59.89]]}, {"timestamp": 1631537313498, "ltp": 1.81, "tv": 4035.36, "trd": NaN, "batb": [[1, 1.73, 149.28]], "batl": NaN}, {"timestamp": 1631537313912, "ltp": 1.81, "tv": 4035.36, "trd": NaN, "batb": [[1, 1.73, 109.15]], "batl": NaN}, {"timestamp": 1631537316828, "ltp": 1.81, "tv": 4035.36, "trd": NaN, "batb": NaN, "batl": [[0, 1.83, 33.5], [1, 1.84, 31.78], [2, 1.89, 255.54]]}, {"timestamp": 1631537317503, "ltp": 1.81, "tv": 4035.36, "trd": NaN, "batb": [[0, 1.7, 37.92], [1, 1.68, 39.33], [2, 1.55, 285.97]], "batl": [[0, 1.84, 31.78], [1, 1.89, 255.54], [2, 1.92, 59.89]]}, {"timestamp": 1631537320508, "ltp": 1.85, "tv": 4105.17, "trd": [[1.84, 63.56], [1.85, 6.4]], "batb": [[0, 1.86, 25.04], [1, 1.84, 88.87], [2, 1.82, 65.94]], "batl": [[0, 1.89, 270.6], [1, 1.92, 59.89], [2, 1.94, 367.96]]}, {"timestamp": 1631537321607, "ltp": 1.83, "tv": 4110.73, "trd": [[1.83, 5.56]], "batb": [[0, 1.82, 65.94], [1, 1.78, 32.13], [2, 1.77, 20.37]], "batl": NaN}, {"timestamp": 1631537323833, "ltp": 1.83, "tv": 4110.73, "trd": NaN, "batb": [[0, 1.85, 86.42], [1, 1.83, 90.51], [2, 1.82, 65.94]], "batl": [[1, 1.92, 80.04]]}, {"timestamp": 1631537325363, "ltp": 1.85, "tv": 4128.93, "trd": [[1.85, 24.6]], "batb": [[0, 1.85, 77.32]], "batl": NaN}, {"timestamp": 1631537331957, "ltp": 1.85, "tv": 4128.93, "trd": NaN, "batb": [[0, 1.86, 191.41], [1, 1.85, 77.32], [2, 1.83, 90.51]], "batl": NaN}, {"timestamp": 1631537334245, "ltp": 1.86, "tv": 4147.21, "trd": [[1.86, 18.28]], "batb": [[0, 1.86, 182.27]], "batl": NaN}, {"timestamp": 1631537336370, "ltp": 1.86, "tv": 4147.21, "trd": NaN, "batb": [[0, 1.86, 236.27]], "batl": NaN}, {"timestamp": 1631537346847, "ltp": 1.86, "tv": 4147.21, "trd": NaN, "batb": [[0, 1.86, 237.11]], "batl": NaN}, {"timestamp": 1631537348668, "ltp": 1.89, "tv": 4147.31, "trd": [[1.89, 0.1]], "batb": NaN, "batl": [[0, 1.89, 270.55]]}, {"timestamp": 1631537349185, "ltp": 1.89, "tv": 4147.31, "trd": NaN, "batb": NaN, "batl": [[0, 1.89, 15.06]]}, {"timestamp": 1631537352277, "ltp": 1.86, "tv": 4621.53, "trd": [[1.86, 490.84], [1.88, 4.15]], "batb": [[0, 1.85, 77.32], [1, 1.83, 90.51], [2, 1.82, 65.94]], "batl": [[0, 1.86, 18.36], [1, 1.89, 15.06], [2, 1.92, 80.04]]}, {"timestamp": 1631537354786, "ltp": 1.86, "tv": 4621.53, "trd": NaN, "batb": [[2, 1.78, 32.13]], "batl": [[0, 1.92, 80.04], [1, 1.94, 76.65], [2, 2.22, 431.74]]}, {"timestamp": 1631537354998, "ltp": 1.86, "tv": 4621.53, "trd": NaN, "batb": [[0, 1.68, 38.91], [1, 1.55, 285.97], [2, 1.3, 198.07]], "batl": [[0, 2.22, 431.74], [1, 1.94, 0], [2, 2.22, 0]]}, {"timestamp": 1631537356450, "ltp": 1.86, "tv": 4621.53, "trd": NaN, "batb": NaN, "batl": [[0, 2.08, 8.09], [1, 2.22, 431.6]]}, {"timestamp": 1631537357804, "ltp": 1.86, "tv": 4621.53, "trd": NaN, "batb": [[0, 1.75, 88.2], [1, 1.73, 109.2], [2, 1.68, 38.91]], "batl": [[1, 2.1, 85.54], [2, 2.12, 58.94]]}, {"timestamp": 1631537358497, "ltp": 1.86, "tv": 4621.53, "trd": NaN, "batb": [[2, 1.72, 41.59]], "batl": [[2, 2.12, 67.4]]}, {"timestamp": 1631537361672, "ltp": 1.86, "tv": 4621.53, "trd": NaN, "batb": NaN, "batl": [[0, 2.06, 8.4], [1, 2.08, 7.94], [2, 2.1, 85.54]]}, {"timestamp": 1631537361981, "ltp": 1.86, "tv": 4621.53, "trd": NaN, "batb": NaN, "batl": [[0, 2.08, 8.09], [1, 2.1, 85.54], [2, 2.12, 67.4]]}, {"timestamp": 1631537363368, "ltp": 1.75, "tv": 4646.83, "trd": [[1.75, 73.61]], "batb": [[0, 1.75, 75.55]], "batl": [[1, 2.12, 8.46], [2, 2.22, 431.6]]}, {"timestamp": 1631537366390, "ltp": 1.75, "tv": 4658.45, "trd": [[1.75, 85.23]], "batb": [[0, 1.75, 69.74], [1, 1.74, 366.42], [2, 1.73, 109.2]], "batl": [[0, 1.78, 11.51], [1, 1.81, 80.05], [2, 1.83, 92]]}, {"timestamp": 1631537369781, "ltp": 1.75, "tv": 4658.45, "trd": NaN, "batb": [[0, 1.75, 78]], "batl": [[1, 1.81, 89.91]]}, {"timestamp": 1631537371611, "ltp": 1.75, "tv": 4693.07, "trd": [[1.75, 119.85]], "batb": [[0, 1.75, 60.69]], "batl": NaN}, {"timestamp": 1631537374529, "ltp": 1.75, "tv": 4693.07, "trd": NaN, "batb": [[0, 1.75, 68.43]], "batl": [[1, 1.81, 99.15]]}, {"timestamp": 1631537389832, "ltp": 1.75, "tv": 4693.07, "trd": NaN, "batb": [[1, 1.73, 109.2], [2, 1.72, 41.59]], "batl": [[0, 1.81, 99.15], [1, 1.83, 92], [2, 1.86, 28.26]]}, {"timestamp": 1631537390349, "ltp": 1.75, "tv": 4693.07, "trd": NaN, "batb": [[0, 1.66, 39.28], [1, 1.61, 45.86], [2, 1.55, 285.97]], "batl": [[0, 1.89, 24.51], [1, 2.22, 431.74], [2, 1.86, 0]]}, {"timestamp": 1631537392811, "ltp": 1.75, "tv": 4693.07, "trd": NaN, "batb": [[0, 1.67, 94.39], [1, 1.66, 102.81], [2, 1.61, 45.86]], "batl": [[1, 1.94, 71.12], [2, 1.96, 74.34]]}, {"timestamp": 1631537397638, "ltp": 1.86, "tv": 4693.08, "trd": [[1.86, 490.85]], "batb": NaN, "batl": [[0, 1.89, 24.5]]}, {"timestamp": 1631537400761, "ltp": 1.86, "tv": 4693.08, "trd": NaN, "batb": [[0, 1.66, 39.28], [1, 1.61, 45.86], [2, 1.55, 285.97]], "batl": NaN}, {"timestamp": 1631537403660, "ltp": 1.86, "tv": 4693.08, "trd": NaN, "batb": [[0, 1.87, 87.49], [1, 1.85, 136.06], [2, 1.84, 24.32]], "batl": [[1, 1.92, 17.01], [2, 1.94, 71.12]]}, {"timestamp": 1631537404755, "ltp": 1.87, "tv": 4704.06, "trd": [[1.87, 20.98]], "batb": [[0, 1.87, 82], [1, 1.85, 103.63], [2, 1.84, 8.1]], "batl": NaN}, {"timestamp": 1631537408774, "ltp": 1.87, "tv": 4726.12, "trd": [[1.87, 43.04]], "batb": [[0, 1.87, 70.97]], "batl": NaN}, {"timestamp": 1631537411660, "ltp": 1.87, "tv": 4726.12, "trd": NaN, "batb": [[0, 1.87, 78.37]], "batl": [[2, 1.94, 79.91]]}, {"timestamp": 1631537412748, "ltp": 1.89, "tv": 4735.27, "trd": [[1.89, 9.25]], "batb": NaN, "batl": [[0, 1.89, 15.35]]}, {"timestamp": 1631537417299, "ltp": 1.89, "tv": 4735.27, "trd": NaN, "batb": NaN, "batl": [[1, 1.94, 79.91], [2, 1.96, 74.34]]}, {"timestamp": 1631537420182, "ltp": 1.89, "tv": 4735.27, "trd": NaN, "batb": NaN, "batl": [[0, 1.89, 29.42]]}, {"timestamp": 1631537430808, "ltp": 1.89, "tv": 4735.27, "trd": NaN, "batb": [[0, 1.8, 31.21], [1, 1.75, 40.11], [2, 1.71, 38.19]], "batl": [[0, 2.5, 368.89], [1, 1.94, 0], [2, 1.96, 0]]}, {"timestamp": 1631537431108, "ltp": 1.89, "tv": 4735.27, "trd": NaN, "batb": [[0, 1.71, 38.19], [1, 1.68, 39.08], [2, 1.55, 285.97]], "batl": NaN}, {"timestamp": 1631537433587, "ltp": 1.89, "tv": 4735.27, "trd": NaN, "batb": [[0, 1.75, 93.05], [1, 1.73, 109.29], [2, 1.71, 38.19]], "batl": [[0, 2.16, 87.87], [1, 2.18, 54.43], [2, 2.5, 368.76]]}, {"timestamp": 1631537434587, "ltp": 1.89, "tv": 4735.27, "trd": NaN, "batb": NaN, "batl": [[0, 2.14, 7.89], [1, 2.16, 87.73], [2, 2.18, 54.43]]}, {"timestamp": 1631537436203, "ltp": 1.89, "tv": 4735.27, "trd": NaN, "batb": NaN, "batl": [[1, 2.5, 368.76], [2, 2.18, 0]]}, {"timestamp": 1631537437815, "ltp": 1.89, "tv": 4735.27, "trd": NaN, "batb": [[0, 1.75, 142.12]], "batl": [[1, 2.5, 0]]}, {"timestamp": 1631537438808, "ltp": 1.75, "tv": 4746.83, "trd": [[1.75, 131.41]], "batb": [[0, 1.75, 87.27]], "batl": [[0, 1.8, 1774.06], [1, 1.81, 41.66], [2, 1.82, 41.66]]}, {"timestamp": 1631537439809, "ltp": 1.75, "tv": 4746.83, "trd": NaN, "batb": [[1, 1.74, 423.31], [2, 1.73, 109.29]], "batl": [[0, 1.78, 19.53], [1, 1.8, 16.66], [2, 1.81, 83.95]]}, {"timestamp": 1631537443832, "ltp": 1.75, "tv": 4746.83, "trd": NaN, "batb": NaN, "batl": [[0, 1.76, 17.92], [1, 1.78, 19.53], [2, 1.8, 16.66]]}, {"timestamp": 1631537444106, "ltp": 1.75, "tv": 4746.83, "trd": NaN, "batb": NaN, "batl": [[0, 1.78, 19.53], [1, 1.8, 16.66], [2, 1.81, 83.95]]}, {"timestamp": 1631537461767, "ltp": 1.75, "tv": 4746.83, "trd": NaN, "batb": [[1, 1.73, 109.29], [2, 1.72, 8.72]], "batl": [[0, 1.8, 8.33], [1, 1.81, 79.78], [2, 1.82, 4.17]]}, {"timestamp": 1631537462333, "ltp": 1.75, "tv": 4746.83, "trd": NaN, "batb": [[0, 1.66, 48.78], [1, 1.6, 46.36], [2, 1.55, 285.97]], "batl": [[0, 1.92, 25.31], [1, 2.36, 396.03], [2, 1.82, 0]]}, {"timestamp": 1631537465736, "ltp": 1.75, "tv": 4746.83, "trd": NaN, "batb": [[0, 1.69, 53.21], [1, 1.66, 163.06], [2, 1.65, 65]], "batl": [[0, 1.88, 28.79], [1, 1.92, 25.31], [2, 1.97, 86.69]]}, {"timestamp": 1631537466769, "ltp": 1.75, "tv": 4746.83, "trd": NaN, "batb": [[0, 1.66, 163.06], [1, 1.65, 65], [2, 1.6, 46.36]], "batl": [[0, 1.92, 25.31], [1, 2, 0.14], [2, 1.97, 0]]}, {"timestamp": 1631537468754, "ltp": 1.66, "tv": 4758.87, "trd": [[1.66, 274.57]], "batb": [[0, 1.66, 547.4]], "batl": [[0, 1.68, 12.75], [1, 1.71, 52.63], [2, 1.72, 131.4]]}, {"timestamp": 1631537469851, "ltp": 1.66, "tv": 4758.87, "trd": NaN, "batb": NaN, "batl": [[1, 1.71, 17.54], [2, 1.72, 113.86]]}, {"timestamp": 1631537476780, "ltp": 1.66, "tv": 4758.87, "trd": NaN, "batb": [[2, 1.64, 51.07]], "batl": NaN}, {"timestamp": 1631537481591, "ltp": 1.66, "tv": 4758.87, "trd": NaN, "batb": [[0, 1.64, 51.07], [1, 1.63, 48.23], [2, 1.55, 52.13]], "batl": [[0, 1.76, 32.27], [1, 1.79, 28.5], [2, 1.92, 25.31]]}, {"timestamp": 1631537482779, "ltp": 1.66, "tv": 4758.87, "trd": NaN, "batb": [[0, 1.63, 48.23], [1, 1.55, 52.13], [2, 1.46, 294.69]], "batl": [[0, 1.66, 8.52], [2, 2.22, 429.8]]}, {"timestamp": 1631537486195, "ltp": 1.66, "tv": 4767.39, "trd": [[1.66, 283.09]], "batb": [[0, 1.68, 83.13], [1, 1.67, 62.18], [2, 1.63, 48.23]], "batl": [[0, 1.73, 68.75], [1, 1.75, 106.61], [2, 1.79, 28.5]]}, {"timestamp": 1631537488695, "ltp": 1.66, "tv": 4767.39, "trd": NaN, "batb": [[2, 1.64, 46.82]], "batl": [[2, 1.76, 32.77]]}, {"timestamp": 1631537488994, "ltp": 1.66, "tv": 4767.39, "trd": NaN, "batb": [[2, 1.63, 48.23]], "batl": NaN}, {"timestamp": 1631537493306, "ltp": 1.66, "tv": 4767.39, "trd": NaN, "batb": [[0, 1.63, 48.23], [1, 1.55, 52.13], [2, 1.46, 294.69]], "batl": [[0, 1.79, 28.5], [1, 2.22, 429.8], [2, 1.76, 0]]}, {"timestamp": 1631537495593, "ltp": 1.66, "tv": 4767.39, "trd": NaN, "batb": [[0, 1.64, 47.57], [1, 1.63, 48.23], [2, 1.55, 52.13]], "batl": NaN}, {"timestamp": 1631537496791, "ltp": 1.66, "tv": 4767.39, "trd": NaN, "batb": [[0, 1.63, 48.23], [1, 1.61, 115.51], [2, 1.6, 72.78]], "batl": [[1, 1.8, 71.04], [2, 1.82, 93.75]]}, {"timestamp": 1631537499416, "ltp": 1.66, "tv": 4767.39, "trd": NaN, "batb": [[1, 1.55, 52.13], [2, 1.46, 294.69]], "batl": NaN}, {"timestamp": 1631537501189, "ltp": 1.66, "tv": 4767.39, "trd": NaN, "batb": [[2, 1.3, 198.07]], "batl": NaN}, {"timestamp": 1631537502219, "ltp": 1.66, "tv": 4767.39, "trd": NaN, "batb": [[0, 1.75, 22.86], [1, 1.74, 463.68], [2, 1.72, 213.26]], "batl": NaN}, {"timestamp": 1631537503609, "ltp": 1.75, "tv": 4779.01, "trd": [[1.75, 143.03]], "batb": [[0, 1.75, 17.05], [2, 1.72, 143.5]], "batl": [[1, 1.8, 87.7], [2, 1.81, 8.34]]}, {"timestamp": 1631537507126, "ltp": 1.75, "tv": 4813.11, "trd": [[1.75, 177.13]], "batb": [[0, 1.74, 463.68], [1, 1.72, 143.5], [2, 1.71, 58.91]], "batl": NaN}, {"timestamp": 1631537523818, "ltp": 1.75, "tv": 4813.11, "trd": NaN, "batb": [[0, 1.63, 48.23], [1, 1.58, 48.45], [2, 1.52, 290.46]], "batl": [[0, 1.92, 25.81], [1, 2.22, 429.66], [2, 1.81, 0]]}, {"timestamp": 1631537527827, "ltp": 1.75, "tv": 4813.11, "trd": NaN, "batb": [[0, 1.77, 104.49], [1, 1.75, 105.21], [2, 1.63, 48.23]], "batl": [[0, 1.78, 21.75], [1, 1.84, 100.18], [2, 1.86, 87.41]]}, {"timestamp": 1631537528146, "ltp": 1.75, "tv": 4813.11, "trd": NaN, "batb": NaN, "batl": [[0, 1.84, 100.18], [1, 1.86, 87.41], [2, 1.92, 25.81]]}, {"timestamp": 1631537529654, "ltp": 1.75, "tv": 4813.11, "trd": NaN, "batb": [[1, 1.75, 105.13]], "batl": NaN}, {"timestamp": 1631537530430, "ltp": 1.75, "tv": 4813.11, "trd": NaN, "batb": [[2, 1.66, 48.78]], "batl": [[2, 1.88, 28.29]]}, {"timestamp": 1631537532476, "ltp": 1.75, "tv": 4813.11, "trd": NaN, "batb": [[0, 1.77, 104.57]], "batl": NaN}, {"timestamp": 1631537535253, "ltp": 1.75, "tv": 4813.11, "trd": NaN, "batb": [[0, 1.63, 48.31], [1, 1.58, 48.45], [2, 1.52, 290.46]], "batl": [[0, 1.92, 25.81], [1, 2.22, 429.66], [2, 1.88, 0]]}, {"timestamp": 1631537538751, "ltp": 1.75, "tv": 4813.11, "trd": NaN, "batb": [[0, 1.64, 108.72], [1, 1.63, 116.17], [2, 1.58, 48.45]], "batl": [[1, 1.98, 67.5], [2, 2, 69.96]]}, {"timestamp": 1631537539848, "ltp": 1.75, "tv": 4813.11, "trd": NaN, "batb": NaN, "batl": [[1, 2.22, 429.66], [2, 2, 0]]}, {"timestamp": 1631537539949, "ltp": 1.75, "tv": 4813.11, "trd": NaN, "batb": NaN, "batl": [[0, 2.22, 429.66], [1, 2.22, 0]]}, {"timestamp": 1631537542759, "ltp": 1.64, "tv": 4825.47, "trd": [[1.64, 91.67], [1.77, 17.02]], "batb": [[0, 1.64, 102.54]], "batl": [[0, 1.66, 11.79], [1, 1.68, 89.28], [2, 1.69, 348.81]]}, {"timestamp": 1631537543750, "ltp": 1.64, "tv": 4825.47, "trd": NaN, "batb": [[2, 1.61, 18.64]], "batl": [[1, 1.68, 17.86], [2, 1.69, 74.54]]}, {"timestamp": 1631537547590, "ltp": 1.64, "tv": 4825.47, "trd": NaN, "batb": NaN, "batl": [[0, 1.66, 17.14]]}, {"timestamp": 1631537547856, "ltp": 1.64, "tv": 4825.47, "trd": NaN, "batb": NaN, "batl": [[0, 1.66, 11.79]]}, {"timestamp": 1631537551881, "ltp": 1.66, "tv": 4825.5, "trd": [[1.66, 283.12]], "batb": NaN, "batl": [[0, 1.66, 11.76]]}, {"timestamp": 1631537558413, "ltp": 1.64, "tv": 4827.4, "trd": [[1.64, 93.57]], "batb": [[0, 1.64, 101.59]], "batl": NaN}, {"timestamp": 1631537562081, "ltp": 1.64, "tv": 4827.4, "trd": NaN, "batb": NaN, "batl": [[0, 1.68, 17.86], [1, 1.69, 74.54], [2, 1.7, 8.92]]}, {"timestamp": 1631537563899, "ltp": 1.64, "tv": 4827.4, "trd": NaN, "batb": [[0, 1.64, 101.8]], "batl": NaN}, {"timestamp": 1631537564992, "ltp": 1.64, "tv": 4827.4, "trd": NaN, "batb": NaN, "batl": [[0, 1.66, 11.76], [1, 1.68, 17.86], [2, 1.69, 74.54]]}, {"timestamp": 1631537570809, "ltp": 1.66, "tv": 4835.9, "trd": [[1.66, 291.62]], "batb": NaN, "batl": [[0, 1.66, 3.26]]}, {"timestamp": 1631537581442, "ltp": 1.66, "tv": 4835.9, "trd": NaN, "batb": NaN, "batl": [[0, 1.68, 17.86], [1, 1.69, 74.54], [2, 1.7, 8.92]]}, {"timestamp": 1631537610799, "ltp": 1.67, "tv": 4836.37, "trd": [[1.67, 42.93]], "batb": NaN, "batl": NaN}, {"timestamp": 1631537619485, "ltp": 1.64, "tv": 4839.41, "trd": [[1.64, 96.19], [1.65, 0.42]], "batb": [[0, 1.64, 100.28]], "batl": NaN}, {"timestamp": 1631537624585, "ltp": 1.68, "tv": 4839.43, "trd": [[1.68, 679.33]], "batb": NaN, "batl": [[0, 1.68, 34.13]]}, {"timestamp": 1631537641467, "ltp": 1.64, "tv": 4840.33, "trd": [[1.64, 97.09]], "batb": [[0, 1.64, 99.83]], "batl": NaN}, {"timestamp": 1631537642666, "ltp": 1.64, "tv": 4840.33, "trd": NaN, "batb": [[0, 1.52, 290.46], [1, 1.51, 52.99], [2, 1.48, 62.34]], "batl": [[0, 1.77, 29.63], [1, 2.22, 429.66], [2, 2.56, 0.14]]}, {"timestamp": 1631537645638, "ltp": 1.64, "tv": 4840.33, "trd": NaN, "batb": [[0, 1.55, 50.79], [1, 1.53, 137.74], [2, 1.52, 379.35]], "batl": [[0, 1.74, 35.75], [1, 1.77, 29.63], [2, 1.79, 106.8]]}, {"timestamp": 1631537645951, "ltp": 1.64, "tv": 4840.33, "trd": NaN, "batb": [[0, 1.53, 137.74], [1, 1.52, 379.35], [2, 1.51, 52.99]], "batl": [[0, 1.77, 29.63], [1, 1.79, 106.8], [2, 1.81, 95.35]]}, {"timestamp": 1631537648661, "ltp": 1.64, "tv": 4840.33, "trd": NaN, "batb": [[0, 1.52, 290.46], [1, 1.51, 52.99], [2, 1.48, 62.34]], "batl": [[1, 2.22, 429.66], [2, 2.56, 0.14]]}, {"timestamp": 1631537650175, "ltp": 1.64, "tv": 4840.33, "trd": NaN, "batb": [[0, 1.51, 52.99], [1, 1.48, 62.34], [2, 1.3, 198.07]], "batl": NaN}, {"timestamp": 1631537651674, "ltp": 1.64, "tv": 4840.33, "trd": NaN, "batb": [[0, 1.62, 86.75], [1, 1.61, 71.04], [2, 1.51, 52.99]], "batl": [[0, 1.67, 98.47], [1, 1.69, 119.89], [2, 1.77, 29.63]]}, {"timestamp": 1631537652782, "ltp": 1.64, "tv": 4840.33, "trd": NaN, "batb": [[2, 1.55, 48.59]], "batl": [[2, 1.74, 35.75]]}, {"timestamp": 1631537653670, "ltp": 1.64, "tv": 4840.33, "trd": NaN, "batb": [[2, 1.51, 52.99]], "batl": NaN}, {"timestamp": 1631537654457, "ltp": 1.64, "tv": 4840.33, "trd": NaN, "batb": [[0, 1.51, 52.99], [1, 1.48, 62.34], [2, 1.44, 298]], "batl": [[0, 1.77, 29.63], [1, 2.22, 429.66], [2, 2.56, 0.14]]}, {"timestamp": 1631537656960, "ltp": 1.64, "tv": 4840.33, "trd": NaN, "batb": [[0, 1.53, 137.74], [1, 1.52, 88.89], [2, 1.51, 52.99]], "batl": [[1, 1.79, 106.8], [2, 1.81, 95.35]]}, {"timestamp": 1631537663790, "ltp": 1.64, "tv": 4840.33, "trd": NaN, "batb": [[0, 1.55, 53.19], [1, 1.53, 137.74], [2, 1.52, 88.89]], "batl": NaN}, {"timestamp": 1631537663996, "ltp": 1.64, "tv": 4840.33, "trd": NaN, "batb": [[0, 1.53, 137.74], [1, 1.52, 88.89], [2, 1.51, 52.99]], "batl": NaN}, {"timestamp": 1631537669401, "ltp": 1.64, "tv": 4840.33, "trd": NaN, "batb": [[0, 1.51, 52.99], [1, 1.48, 62.34], [2, 1.44, 298]], "batl": NaN}, {"timestamp": 1631537670714, "ltp": 1.64, "tv": 4840.33, "trd": NaN, "batb": [[0, 1.55, 51.39], [1, 1.51, 52.99], [2, 1.48, 62.34]], "batl": NaN}, {"timestamp": 1631537671501, "ltp": 1.64, "tv": 4840.33, "trd": NaN, "batb": [[0, 1.51, 52.99], [1, 1.48, 62.34], [2, 1.3, 198.07]], "batl": NaN}, {"timestamp": 1631537672604, "ltp": 1.64, "tv": 4840.33, "trd": NaN, "batb": [[0, 1.73, 70.82], [1, 1.72, 536.52], [2, 1.71, 113.72]], "batl": NaN}, {"timestamp": 1631537673801, "ltp": 1.73, "tv": 4852.03, "trd": [[1.73, 23.32]], "batb": [[0, 1.73, 64.97]], "batl": [[2, 1.8, 16.66]]}, {"timestamp": 1631537674007, "ltp": 1.73, "tv": 4852.03, "trd": NaN, "batb": NaN, "batl": [[1, 1.8, 16.66], [2, 1.81, 8.34]]}, {"timestamp": 1631537677403, "ltp": 1.73, "tv": 4852.03, "trd": NaN, "batb": NaN, "batl": [[1, 1.78, 61.04], [2, 1.8, 113.88]]}, {"timestamp": 1631537681047, "ltp": 1.73, "tv": 4852.03, "trd": NaN, "batb": NaN, "batl": [[2, 1.8, 148.3]]}, {"timestamp": 1631537692757, "ltp": 1.73, "tv": 4852.03, "trd": NaN, "batb": [[1, 1.72, 50.09]], "batl": [[2, 1.8, 131.64]]}, {"timestamp": 1631537693136, "ltp": 1.73, "tv": 4852.03, "trd": NaN, "batb": [[0, 1.62, 45.04], [1, 1.56, 50.71], [2, 1.5, 288.58]], "batl": [[0, 1.83, 27.5], [1, 2.22, 429.66], [2, 1.8, 0]]}, {"timestamp": 1631537694846, "ltp": 1.73, "tv": 4852.03, "trd": NaN, "batb": NaN, "batl": [[0, 1.83, 27.7]]}, {"timestamp": 1631537695843, "ltp": 1.73, "tv": 4852.03, "trd": NaN, "batb": [[0, 1.62, 140.39], [1, 1.61, 71.08], [2, 1.56, 50.71]], "batl": [[1, 1.87, 68.68], [2, 1.89, 83.2]]}, {"timestamp": 1631537696657, "ltp": 1.73, "tv": 4852.03, "trd": NaN, "batb": NaN, "batl": [[0, 1.83, 27.5]]}, {"timestamp": 1631537697550, "ltp": 1.73, "tv": 4852.03, "trd": NaN, "batb": NaN, "batl": [[1, 2.22, 429.66], [2, 1.89, 0]]}, {"timestamp": 1631537699770, "ltp": 1.73, "tv": 4852.03, "trd": NaN, "batb": NaN, "batl": [[0, 1.81, 30.5], [1, 1.83, 27.5], [2, 2.22, 429.66]]}, {"timestamp": 1631537700462, "ltp": 1.62, "tv": 4864.37, "trd": [[1.62, 28.94]], "batb": [[0, 1.62, 553.97]], "batl": [[0, 1.66, 16.66], [1, 1.67, 90.3], [2, 1.69, 119.95]]}, {"timestamp": 1631537714783, "ltp": 1.62, "tv": 4864.37, "trd": NaN, "batb": [[0, 1.5, 288.58], [1, 1.47, 59.67], [2, 1.45, 67.7]], "batl": [[0, 1.78, 34.25], [1, 2.22, 429.66], [2, 1.69, 0]]}, {"timestamp": 1631537717775, "ltp": 1.62, "tv": 4864.37, "trd": NaN, "batb": [[0, 1.51, 55.99], [1, 1.5, 395.02], [2, 1.49, 96.22]], "batl": [[0, 1.78, 140.05], [1, 1.8, 97.09], [2, 2.22, 429.66]]}, {"timestamp": 1631537718192, "ltp": 1.62, "tv": 4864.37, "trd": NaN, "batb": [[0, 1.5, 395.02], [1, 1.49, 96.22], [2, 1.47, 59.67]], "batl": NaN}, {"timestamp": 1631537719181, "ltp": 1.62, "tv": 4864.37, "trd": NaN, "batb": [[0, 1.5, 288.58], [1, 1.47, 59.67], [2, 1.45, 67.7]], "batl": NaN}, {"timestamp": 1631537721792, "ltp": 1.62, "tv": 4864.37, "trd": NaN, "batb": [[0, 1.72, 11.17], [1, 1.71, 87.72], [2, 1.7, 43.86]], "batl": [[2, 1.83, 472.17]]}, {"timestamp": 1631537722786, "ltp": 1.72, "tv": 4876.07, "trd": [[1.72, 290.03]], "batb": [[0, 1.72, 82.56], [1, 1.71, 65.73], [2, 1.7, 124.87]], "batl": [[1, 1.79, 83.8], [2, 1.8, 138.99]]}, {"timestamp": 1631537723492, "ltp": 1.72, "tv": 4876.07, "trd": NaN, "batb": NaN, "batl": [[1, 1.79, 16.76], [2, 1.8, 105.47]]}, {"timestamp": 1631537726794, "ltp": 1.72, "tv": 4876.07, "trd": NaN, "batb": NaN, "batl": [[0, 1.74, 14.78], [1, 1.78, 140.05], [2, 1.79, 16.76]]}, {"timestamp": 1631537727001, "ltp": 1.72, "tv": 4876.07, "trd": NaN, "batb": NaN, "batl": [[0, 1.78, 140.05], [1, 1.79, 16.76], [2, 1.8, 105.47]]}, {"timestamp": 1631537733020, "ltp": 1.72, "tv": 4876.07, "trd": NaN, "batb": [[0, 1.72, 77.24]], "batl": NaN}, {"timestamp": 1631537735948, "ltp": 1.72, "tv": 4876.07, "trd": NaN, "batb": NaN, "batl": [[0, 1.74, 7.95], [1, 1.78, 140.05], [2, 1.79, 16.76]]}, {"timestamp": 1631537738516, "ltp": 1.72, "tv": 4876.07, "trd": NaN, "batb": [[0, 1.61, 48.09], [1, 1.6, 45.79], [2, 1.55, 52.64]], "batl": [[0, 1.84, 29.78], [1, 1.85, 30.5], [2, 2.22, 429.66]]}, {"timestamp": 1631537741730, "ltp": 1.72, "tv": 4876.07, "trd": NaN, "batb": [[0, 1.64, 41.82], [1, 1.61, 48.09], [2, 1.6, 45.79]], "batl": [[0, 1.82, 31.75], [1, 1.84, 29.78], [2, 1.85, 30.5]]}, {"timestamp": 1631537742732, "ltp": 1.72, "tv": 4876.07, "trd": NaN, "batb": [[0, 1.69, 107.89], [1, 1.67, 123.73], [2, 1.61, 48.09]], "batl": [[0, 1.75, 114.69], [1, 1.77, 102.61], [2, 1.84, 29.78]]}, {"timestamp": 1631537743043, "ltp": 1.72, "tv": 4876.07, "trd": NaN, "batb": NaN, "batl": [[0, 1.75, 93.03]]}, {"timestamp": 1631537745240, "ltp": 1.72, "tv": 4876.07, "trd": NaN, "batb": [[2, 1.64, 43.32]], "batl": [[2, 1.82, 29.25]]}, {"timestamp": 1631537747233, "ltp": 1.72, "tv": 4876.07, "trd": NaN, "batb": [[0, 1.61, 48.09], [1, 1.6, 45.79], [2, 1.55, 52.64]], "batl": [[0, 1.84, 29.78], [1, 1.85, 30.5], [2, 2.22, 429.66]]}, {"timestamp": 1631537750742, "ltp": 1.72, "tv": 4876.07, "trd": NaN, "batb": [[1, 1.6, 139.96], [2, 1.59, 74.47]], "batl": NaN}, {"timestamp": 1631537752263, "ltp": 1.61, "tv": 4888.49, "trd": [[1.61, 63.64]], "batb": [[0, 1.61, 41.88], [1, 1.6, 584.61]], "batl": [[0, 1.64, 18.3], [1, 1.65, 113.32], [2, 1.66, 72.55]]}, {"timestamp": 1631537769697, "ltp": 1.61, "tv": 4888.49, "trd": NaN, "batb": [[1, 1.6, 139.96]], "batl": [[0, 1.64, 9.15], [1, 1.65, 108.75], [2, 1.66, 67.98]]}, {"timestamp": 1631537770114, "ltp": 1.61, "tv": 4888.49, "trd": NaN, "batb": [[0, 1.5, 288.58], [1, 1.45, 56.01], [2, 1.41, 75.9]], "batl": [[0, 2.22, 429.66], [1, 1.65, 0], [2, 1.66, 0]]}, {"timestamp": 1631537774314, "ltp": 1.61, "tv": 4888.49, "trd": NaN, "batb": [[0, 1.41, 75.9], [1, 1.39, 61.91], [2, 1.3, 198.07]], "batl": NaN}, {"timestamp": 1631537775694, "ltp": 1.61, "tv": 4888.49, "trd": NaN, "batb": [[0, 1.57, 84.95], [1, 1.56, 80.04], [2, 1.41, 75.9]], "batl": [[0, 1.61, 65.09], [1, 1.62, 69.3]]}, {"timestamp": 1631537778095, "ltp": 1.61, "tv": 4888.49, "trd": NaN, "batb": NaN, "batl": [[2, 2.1, 467.37]]}, {"timestamp": 1631537780399, "ltp": 1.61, "tv": 4888.49, "trd": NaN, "batb": [[0, 1.41, 75.9], [1, 1.4, 306.86], [2, 1.39, 61.91]], "batl": [[0, 2.1, 467.37], [1, 1.62, 0], [2, 2.1, 0]]}, {"timestamp": 1631537783529, "ltp": 1.61, "tv": 4888.49, "trd": NaN, "batb": [[0, 1.45, 157.16], [1, 1.44, 111.56], [2, 1.41, 75.9]], "batl": NaN}, {"timestamp": 1631537785306, "ltp": 1.61, "tv": 4888.49, "trd": NaN, "batb": [[0, 1.46, 14.78], [1, 1.45, 157.16], [2, 1.44, 111.56]], "batl": [[0, 1.48, 16.5], [1, 1.49, 89.99], [2, 1.5, 92.68]]}, {"timestamp": 1631537786731, "ltp": 1.61, "tv": 4888.49, "trd": NaN, "batb": [[1, 1.45, 219.22], [2, 1.44, 163.28]], "batl": NaN}, {"timestamp": 1631537787724, "ltp": 1.61, "tv": 4888.49, "trd": NaN, "batb": [[1, 1.45, 177.84], [2, 1.44, 121.9]], "batl": NaN}, {"timestamp": 1631537789701, "ltp": 1.61, "tv": 4888.49, "trd": NaN, "batb": [[0, 1.47, 103], [1, 1.46, 14.78], [2, 1.45, 177.84]], "batl": NaN}, {"timestamp": 1631537794814, "ltp": 1.48, "tv": 4902.39, "trd": [[1.48, 13.9]], "batb": NaN, "batl": [[0, 1.48, 9.55]]}, {"timestamp": 1631537802632, "ltp": 1.48, "tv": 4902.5, "trd": [[1.48, 14.01]], "batb": NaN, "batl": [[0, 1.48, 9.44]]}, {"timestamp": 1631537805140, "ltp": 1.48, "tv": 4902.5, "trd": NaN, "batb": [[1, 1.45, 177.84], [2, 1.44, 121.9]], "batl": [[0, 1.49, 89.99], [1, 1.5, 92.68], [2, 1.95, 515.54]]}, {"timestamp": 1631537806773, "ltp": 1.48, "tv": 4902.5, "trd": NaN, "batb": [[1, 1.34, 323.42], [2, 1.29, 78.81]], "batl": [[0, 1.95, 515.54], [1, 880, 0.01], [2, 1.95, 0]]}, {"timestamp": 1631537807349, "ltp": 1.48, "tv": 4902.5, "trd": NaN, "batb": [[0, 1.34, 323.42], [1, 1.29, 78.81], [2, 1.27, 124.94]], "batl": NaN}, {"timestamp": 1631537811749, "ltp": 1.48, "tv": 4902.5, "trd": NaN, "batb": NaN, "batl": [[0, 1.49, 367.05], [1, 1.95, 515.54], [2, 880, 0.01]]}, {"timestamp": 1631537812672, "ltp": 1.48, "tv": 4902.5, "trd": NaN, "batb": [[0, 1.42, 135.09], [1, 1.41, 122.31], [2, 1.34, 323.42]], "batl": [[0, 1.46, 143.59], [1, 1.47, 100.22], [2, 1.95, 515.54]]}, {"timestamp": 1631537816266, "ltp": 1.48, "tv": 4902.5, "trd": NaN, "batb": [[0, 1.42, 232.09]], "batl": NaN}, {"timestamp": 1631537819354, "ltp": 1.48, "tv": 4902.5, "trd": NaN, "batb": [[0, 1.34, 323.42], [1, 1.29, 78.81], [2, 1.27, 124.94]], "batl": [[0, 1.95, 515.54], [1, 880, 0.01], [2, 1.95, 0]]}, {"timestamp": 1631537822461, "ltp": 1.48, "tv": 4902.5, "trd": NaN, "batb": [[1, 1.3, 227.52], [2, 1.29, 270.97]], "batl": [[0, 1.64, 112.8], [1, 1.65, 64.73], [2, 1.95, 515.54]]}, {"timestamp": 1631537826367, "ltp": 1.48, "tv": 4902.5, "trd": NaN, "batb": [[1, 1.29, 78.81], [2, 1.27, 124.94]], "batl": NaN}, {"timestamp": 1631537828760, "ltp": 1.48, "tv": 4902.5, "trd": NaN, "batb": [[0, 1.29, 78.81], [1, 1.27, 124.94], [2, 1.24, 104.02]], "batl": [[2, 880, 0.01]]}, {"timestamp": 1631537829798, "ltp": 1.48, "tv": 4902.5, "trd": NaN, "batb": [[0, 1.6, 49.29], [1, 1.59, 92.2], [2, 1.58, 76.25]], "batl": [[0, 1.62, 14.57], [1, 1.64, 112.8], [2, 1.65, 64.73]]}, {"timestamp": 1631537830481, "ltp": 1.6, "tv": 4915.0, "trd": [[1.6, 12.5]], "batb": [[0, 1.6, 43.04]], "batl": NaN}, {"timestamp": 1631537836197, "ltp": 1.6, "tv": 4915.0, "trd": NaN, "batb": [[0, 1.61, 107], [1, 1.6, 43.04], [2, 1.59, 92.2]], "batl": NaN}, {"timestamp": 1631537857167, "ltp": 1.6, "tv": 4915.0, "trd": NaN, "batb": [[1, 1.59, 92.2], [2, 1.58, 76.25]], "batl": NaN}, {"timestamp": 1631537865771, "ltp": 1.6, "tv": 4915.0, "trd": NaN, "batb": [[1, 1.55, 52.8], [2, 1.45, 47.01]], "batl": [[0, 1.78, 34.25], [1, 2.16, 443.34], [2, 880, 0.01]]}, {"timestamp": 1631537866688, "ltp": 1.6, "tv": 4915.0, "trd": NaN, "batb": [[0, 1.44, 356.42], [1, 1.41, 76.74], [2, 1.4, 60.56]], "batl": NaN}, {"timestamp": 1631537868786, "ltp": 1.6, "tv": 4915.0, "trd": NaN, "batb": NaN, "batl": [[0, 1.77, 87.88], [1, 1.78, 34.25], [2, 1.79, 98.91]]}, {"timestamp": 1631537869478, "ltp": 1.6, "tv": 4915.0, "trd": NaN, "batb": [[0, 1.41, 76.74], [1, 1.4, 60.56], [2, 1.24, 104.02]], "batl": NaN}, {"timestamp": 1631537870777, "ltp": 1.6, "tv": 4915.0, "trd": NaN, "batb": [[0, 1.72, 41.84], [1, 1.41, 76.74], [2, 1.4, 60.56]], "batl": NaN}, {"timestamp": 1631537871796, "ltp": 1.72, "tv": 4926.7, "trd": [[1.72, 301.73]], "batb": [[0, 1.72, 35.99], [1, 1.71, 101.53], [2, 1.69, 118.6]], "batl": NaN}, {"timestamp": 1631537875690, "ltp": 1.72, "tv": 4926.7, "trd": NaN, "batb": NaN, "batl": [[0, 1.74, 9.06], [1, 1.77, 87.88], [2, 1.78, 34.25]]}, {"timestamp": 1631537875892, "ltp": 1.72, "tv": 4926.7, "trd": NaN, "batb": NaN, "batl": [[0, 1.77, 87.88], [1, 1.78, 34.25], [2, 1.79, 98.91]]}, {"timestamp": 1631537883792, "ltp": 1.72, "tv": 4926.98, "trd": [[1.72, 302.01]], "batb": [[0, 1.72, 35.85]], "batl": NaN}, {"timestamp": 1631537884415, "ltp": 1.72, "tv": 4926.98, "trd": NaN, "batb": [[0, 1.58, 39.06], [1, 1.54, 54.06], [2, 1.5, 285.57]], "batl": [[0, 1.85, 31.5], [1, 2.16, 443.34], [2, 880, 0.01]]}, {"timestamp": 1631537887698, "ltp": 1.72, "tv": 4926.98, "trd": NaN, "batb": [[0, 1.62, 37.54], [1, 1.58, 125.23], [2, 1.57, 78.09]], "batl": [[0, 1.82, 28.25], [1, 1.85, 31.5], [2, 1.89, 85.79]]}, {"timestamp": 1631537888105, "ltp": 1.72, "tv": 4926.98, "trd": NaN, "batb": [[0, 1.58, 125.23], [1, 1.57, 78.09], [2, 1.54, 54.06]], "batl": [[0, 1.85, 31.5], [1, 1.89, 85.79], [2, 1.91, 80.49]]}, {"timestamp": 1631537890798, "ltp": 1.72, "tv": 4926.98, "trd": NaN, "batb": [[0, 1.58, 39.06], [1, 1.54, 54.06], [2, 1.5, 285.57]], "batl": NaN}, {"timestamp": 1631537891631, "ltp": 1.72, "tv": 4926.98, "trd": NaN, "batb": [[2, 1.4, 60.56]], "batl": NaN}, {"timestamp": 1631537892797, "ltp": 1.72, "tv": 4926.98, "trd": NaN, "batb": [[0, 1.81, 110.5], [1, 1.58, 39.06], [2, 1.54, 54.06]], "batl": [[1, 1.86, 17.52], [2, 1.89, 85.79]]}, {"timestamp": 1631537893798, "ltp": 1.82, "tv": 4938.02, "trd": [[1.82, 11.04]], "batb": [[0, 1.82, 88.66], [1, 1.81, 110.5], [2, 1.8, 95.64]], "batl": NaN}, {"timestamp": 1631537897826, "ltp": 1.82, "tv": 4938.02, "trd": NaN, "batb": NaN, "batl": [[0, 1.84, 9.8], [1, 1.85, 31.5], [2, 1.86, 17.52]]}, {"timestamp": 1631537898034, "ltp": 1.82, "tv": 4938.02, "trd": NaN, "batb": NaN, "batl": [[0, 1.85, 31.5], [1, 1.86, 17.52], [2, 1.89, 85.79]]}, {"timestamp": 1631537910561, "ltp": 1.82, "tv": 4938.36, "trd": [[1.82, 11.38]], "batb": [[0, 1.82, 88.49]], "batl": NaN}, {"timestamp": 1631537912828, "ltp": 1.82, "tv": 4938.81, "trd": [[1.82, 11.83]], "batb": [[0, 1.82, 88.1]], "batl": NaN}, {"timestamp": 1631537926772, "ltp": 1.82, "tv": 4938.81, "trd": NaN, "batb": [[0, 1.68, 34.11], [1, 1.66, 40.84], [2, 1.55, 285.97]], "batl": [[0, 2.12, 7.96], [1, 2.42, 382.9], [2, 1.89, 0]]}, {"timestamp": 1631537931381, "ltp": 1.82, "tv": 4938.81, "trd": NaN, "batb": [[0, 1.86, 66.46], [1, 1.84, 88.96], [2, 1.68, 34.11]], "batl": [[0, 1.92, 56.88], [1, 1.94, 76.74], [2, 2.12, 7.96]]}, {"timestamp": 1631537933690, "ltp": 1.82, "tv": 4938.81, "trd": NaN, "batb": [[2, 1.72, 34.09]], "batl": NaN}, {"timestamp": 1631537934370, "ltp": 1.86, "tv": 4945.75, "trd": [[1.86, 497.79]], "batb": [[0, 1.86, 59.52]], "batl": NaN}, {"timestamp": 1631537938675, "ltp": 1.86, "tv": 4945.75, "trd": NaN, "batb": [[0, 1.68, 34.11], [1, 1.66, 40.84], [2, 1.55, 285.97]], "batl": [[0, 2.12, 7.96], [1, 2.42, 382.9], [2, 2.12, 0]]}, {"timestamp": 1631537941410, "ltp": 1.86, "tv": 4945.75, "trd": NaN, "batb": [[0, 1.71, 94.83], [1, 1.69, 118.59], [2, 1.68, 34.11]], "batl": [[0, 2.1, 95.89], [1, 2.12, 66.92], [2, 2.42, 382.9]]}, {"timestamp": 1631537945395, "ltp": 1.86, "tv": 4945.75, "trd": NaN, "batb": [[0, 1.72, 36.09], [1, 1.71, 94.83], [2, 1.69, 118.59]], "batl": NaN}, {"timestamp": 1631537946388, "ltp": 1.86, "tv": 4945.75, "trd": NaN, "batb": [[0, 1.71, 94.83], [1, 1.69, 118.59], [2, 1.68, 34.11]], "batl": [[0, 2.12, 7.96], [1, 2.42, 382.9], [2, 2.42, 0]]}, {"timestamp": 1631537947595, "ltp": 1.86, "tv": 4945.75, "trd": NaN, "batb": NaN, "batl": [[0, 2.04, 8.63], [1, 2.12, 7.96]]}, {"timestamp": 1631537948806, "ltp": 1.86, "tv": 4945.75, "trd": NaN, "batb": NaN, "batl": [[0, 1.83, 7.92]]}, {"timestamp": 1631537949334, "ltp": 1.71, "tv": 4957.45, "trd": [[1.71, 78.94]], "batb": [[0, 1.71, 88.98]], "batl": [[0, 1.76, 17.04], [1, 1.77, 102.85], [2, 1.78, 8.52]]}, {"timestamp": 1631537950333, "ltp": 1.71, "tv": 4957.45, "trd": NaN, "batb": [[2, 1.68, 51.97]], "batl": NaN}, {"timestamp": 1631537959514, "ltp": 1.71, "tv": 5124.64, "trd": [[1.71, 246.13]], "batb": [[0, 1.68, 51.97], [1, 1.67, 8.92], [2, 1.66, 49.76]], "batl": [[1, 1.77, 8.52]]}, {"timestamp": 1631537962446, "ltp": 1.71, "tv": 5124.64, "trd": NaN, "batb": [[0, 1.7, 104.15], [1, 1.68, 173.29], [2, 1.67, 8.92]], "batl": [[0, 1.76, 108.51], [2, 1.78, 109.44]]}, {"timestamp": 1631537981664, "ltp": 1.71, "tv": 5124.64, "trd": NaN, "batb": [[0, 1.62, 37.54], [1, 1.58, 48.79], [2, 1.55, 285.97]], "batl": [[0, 1.87, 25.73], [1, 2.3, 407.85], [2, 1.78, 0]]}, {"timestamp": 1631537984380, "ltp": 1.71, "tv": 5124.64, "trd": NaN, "batb": [[0, 1.62, 145.07], [1, 1.61, 71.26], [2, 1.58, 48.79]], "batl": [[1, 1.91, 86.11], [2, 1.93, 78.05]]}, {"timestamp": 1631537989454, "ltp": 1.71, "tv": 5124.64, "trd": NaN, "batb": NaN, "batl": [[1, 2.3, 407.85], [2, 1.93, 0]]}, {"timestamp": 1631537991178, "ltp": 1.71, "tv": 5124.64, "trd": NaN, "batb": NaN, "batl": [[1, 2.3, 0]]}, {"timestamp": 1631537992379, "ltp": 1.71, "tv": 5124.64, "trd": NaN, "batb": [[0, 1.62, 157.37]], "batl": [[0, 1.64, 6.1], [1, 1.66, 19.63], [2, 1.67, 79.36]]}, {"timestamp": 1631537999179, "ltp": 1.71, "tv": 5124.64, "trd": NaN, "batb": [[2, 1.59, 43.11]], "batl": NaN}, {"timestamp": 1631538000291, "ltp": 1.71, "tv": 5124.64, "trd": NaN, "batb": [[0, 1.62, 159.37]], "batl": NaN}, {"timestamp": 1631538003890, "ltp": 1.71, "tv": 5124.78, "trd": [[1.28, 8.27], [1.35, 77.51], [1.37, 4.14], [1.39, 14.38], [1.4, 29.86], [1.48, 14.01], [1.49, 481.87], [1.5, 13.9], [1.53, 3.12], [1.61, 63.64], [1.64, 97.09], [1.66, 291.59], [1.67, 42.97], [1.68, 679.26], [1.69, 321.75], [1.7, 269.19], [1.71, 246.12], [1.72, 302.15], [1.75, 177.12], [1.77, 17.02], [1.86, 497.72], [1.88, 4.15], [1.9, 222.36], [2.06, 7.25]], "batb": [[0, 1.62, 146.72]], "batl": NaN}, {"timestamp": 1631538007810, "ltp": 1.71, "tv": 5124.78, "trd": NaN, "batb": [[0, 1.62, 2], [1, 1.52, 55.97], [2, 1.44, 294.47]], "batl": [[0, 1.73, 38.5], [1, 1.77, 34.5], [2, 1.87, 25.73]]}, {"timestamp": 1631538008077, "ltp": 1.71, "tv": 5124.78, "trd": NaN, "batb": NaN, "batl": [[0, 1.77, 34.5], [1, 2.16, 445.57], [2, 1.87, 0]]}, {"timestamp": 1631538010819, "ltp": 1.71, "tv": 5124.78, "trd": NaN, "batb": [[1, 1.57, 79.43], [2, 1.56, 80.24]], "batl": [[0, 1.76, 61.14], [1, 1.77, 34.5], [2, 1.78, 101.08]]}, {"timestamp": 1631538011591, "ltp": 1.71, "tv": 5124.78, "trd": NaN, "batb": [[1, 1.57, 125]], "batl": NaN}, {"timestamp": 1631538014614, "ltp": 1.71, "tv": 5124.78, "trd": NaN, "batb": [[1, 1.59, 44.11], [2, 1.57, 125]], "batl": NaN}, {"timestamp": 1631538015628, "ltp": 1.71, "tv": 5124.78, "trd": NaN, "batb": [[1, 1.57, 125], [2, 1.56, 80.24]], "batl": NaN}, {"timestamp": 1631538017534, "ltp": 1.71, "tv": 5124.78, "trd": NaN, "batb": NaN, "batl": [[0, 1.77, 34.5], [1, 2.16, 445.57], [2, 1.78, 0]]}, {"timestamp": 1631538020536, "ltp": 1.62, "tv": 5128.78, "trd": [[1.62, 32.94]], "batb": [[0, 1.57, 125], [1, 1.56, 80.24], [2, 1.52, 55.97]], "batl": [[0, 1.59, 4.29], [1, 1.6, 17.3], [2, 1.61, 71.25]]}, {"timestamp": 1631538021736, "ltp": 1.62, "tv": 5128.78, "trd": NaN, "batb": [[2, 1.54, 19.48]], "batl": NaN}, {"timestamp": 1631538028448, "ltp": 1.62, "tv": 5128.78, "trd": NaN, "batb": [[1, 1.56, 120.07], [2, 1.55, 38.79]], "batl": NaN}, {"timestamp": 1631538042784, "ltp": 1.59, "tv": 5130.02, "trd": [[1.59, 13.82]], "batb": NaN, "batl": [[0, 1.59, 3.67]]}, {"timestamp": 1631538043664, "ltp": 1.59, "tv": 5130.02, "trd": NaN, "batb": [[0, 1.49, 60.57], [1, 1.44, 294.47], [2, 1.3, 197.93]], "batl": [[0, 1.66, 41.25], [1, 2.16, 445.57], [2, 1.61, 0]]}, {"timestamp": 1631538046794, "ltp": 1.59, "tv": 5130.02, "trd": NaN, "batb": [[0, 1.56, 45.83], [1, 1.55, 40.99], [2, 1.54, 86.94]], "batl": [[0, 1.66, 103.84], [1, 1.67, 62.38], [2, 2.16, 445.57]]}, {"timestamp": 1631538047195, "ltp": 1.59, "tv": 5130.02, "trd": NaN, "batb": [[0, 1.55, 40.99], [1, 1.54, 86.94], [2, 1.53, 86.61]], "batl": NaN}, {"timestamp": 1631538048202, "ltp": 1.59, "tv": 5130.02, "trd": NaN, "batb": NaN, "batl": [[0, 1.66, 41.25], [1, 2.16, 445.57], [2, 2.16, 0]]}, {"timestamp": 1631538050794, "ltp": 1.59, "tv": 5130.02, "trd": NaN, "batb": [[1, 1.54, 99.03]], "batl": [[0, 1.57, 6.37], [1, 1.6, 1962.12], [2, 1.62, 453.01]]}, {"timestamp": 1631538051797, "ltp": 1.59, "tv": 5130.02, "trd": NaN, "batb": NaN, "batl": [[1, 1.58, 83.1], [2, 1.59, 74.36]]}, {"timestamp": 1631538056314, "ltp": 1.59, "tv": 5130.02, "trd": NaN, "batb": [[0, 1.55, 136.99]], "batl": NaN}, {"timestamp": 1631538069325, "ltp": 1.59, "tv": 5130.02, "trd": NaN, "batb": NaN, "batl": [[0, 1.56, 228.19], [1, 1.57, 6.37], [2, 1.58, 83.1]]}, {"timestamp": 1631538098271, "ltp": 1.55, "tv": 5130.94, "trd": [[1.55, 13.9]], "batb": [[0, 1.55, 136.53]], "batl": NaN}, {"timestamp": 1631538098892, "ltp": 1.56, "tv": 5142.33, "trd": [[1.56, 11.39]], "batb": NaN, "batl": [[0, 1.56, 216.8]]}, {"timestamp": 1631538103402, "ltp": 1.56, "tv": 5142.33, "trd": NaN, "batb": NaN, "batl": [[0, 1.57, 6.37], [1, 1.58, 83.1], [2, 1.59, 74.36]]}, {"timestamp": 1631538106590, "ltp": 1.55, "tv": 5415.38, "trd": [[1.55, 286.96]], "batb": [[0, 1.54, 99.03], [1, 1.53, 86.61], [2, 1.49, 60.57]], "batl": [[0, 1.55, 81.67], [1, 1.57, 6.37], [2, 1.58, 83.1]]}, {"timestamp": 1631538107688, "ltp": 1.55, "tv": 5415.38, "trd": NaN, "batb": [[0, 1.54, 86.94]], "batl": NaN}, {"timestamp": 1631538109618, "ltp": 1.55, "tv": 5419.72, "trd": [[1.55, 291.3]], "batb": NaN, "batl": [[0, 1.55, 79.5]]}, {"timestamp": 1631538110714, "ltp": 1.55, "tv": 5419.72, "trd": NaN, "batb": NaN, "batl": [[2, 1.58, 99.94]]}, {"timestamp": 1631538110976, "ltp": 1.55, "tv": 5419.72, "trd": NaN, "batb": NaN, "batl": [[2, 1.58, 83.1]]}, {"timestamp": 1631538113903, "ltp": 1.55, "tv": 5419.72, "trd": NaN, "batb": NaN, "batl": [[2, 1.58, 99.94]]}, {"timestamp": 1631538118494, "ltp": 1.55, "tv": 5419.89, "trd": [[1.55, 291.47]], "batb": NaN, "batl": [[0, 1.55, 79.33]]}, {"timestamp": 1631538119430, "ltp": 1.55, "tv": 5419.89, "trd": NaN, "batb": NaN, "batl": [[0, 1.57, 6.37], [1, 1.58, 99.94], [2, 1.59, 74.36]]}, {"timestamp": 1631538120532, "ltp": 1.55, "tv": 5419.89, "trd": NaN, "batb": [[0, 1.54, 186.94]], "batl": NaN}, {"timestamp": 1631538122627, "ltp": 1.54, "tv": 5579.92, "trd": [[1.54, 160.02]], "batb": [[0, 1.54, 106.93]], "batl": NaN}, {"timestamp": 1631538123042, "ltp": 1.54, "tv": 5579.92, "trd": NaN, "batb": [[0, 1.54, 100]], "batl": NaN}, {"timestamp": 1631538125952, "ltp": 1.54, "tv": 5579.92, "trd": NaN, "batb": [[1, 1.53, 129.64], [2, 1.52, 89.34]], "batl": [[1, 1.58, 143.02]]}, {"timestamp": 1631538152697, "ltp": 1.54, "tv": 5579.92, "trd": NaN, "batb": NaN, "batl": [[0, 1.58, 126.18], [1, 1.59, 74.36], [2, 1.67, 43]]}, {"timestamp": 1631538153601, "ltp": 1.54, "tv": 5579.92, "trd": NaN, "batb": [[0, 1.4, 59.01], [1, 1.39, 80.9], [2, 1.38, 301.29]], "batl": [[0, 1.71, 39.5], [1, 2.04, 492.16], [2, 1.67, 0]]}, {"timestamp": 1631538155795, "ltp": 1.54, "tv": 5579.92, "trd": NaN, "batb": [[0, 1.43, 85.94], [1, 1.42, 118.79], [2, 1.4, 59.01]], "batl": [[0, 1.67, 111.51], [1, 1.69, 120.45], [2, 1.71, 39.5]]}, {"timestamp": 1631538156782, "ltp": 1.54, "tv": 5579.92, "trd": NaN, "batb": [[0, 1.4, 59.01], [1, 1.39, 80.9], [2, 1.38, 301.29]], "batl": [[0, 1.71, 39.5], [1, 2.04, 492.16], [2, 1.71, 0]]}, {"timestamp": 1631538159809, "ltp": 1.54, "tv": 5579.92, "trd": NaN, "batb": NaN, "batl": [[0, 1.67, 6.53], [1, 1.71, 39.5], [2, 2.04, 492.16]]}, {"timestamp": 1631538160392, "ltp": 1.54, "tv": 5579.92, "trd": NaN, "batb": [[0, 1.51, 110.76], [1, 1.5, 94.16], [2, 1.44, 56.42]], "batl": [[0, 1.55, 82.91], [1, 1.56, 80.07], [2, 1.71, 39.5]]}, {"timestamp": 1631538163616, "ltp": 1.54, "tv": 5579.92, "trd": NaN, "batb": NaN, "batl": [[2, 1.67, 36.5]]}, {"timestamp": 1631538163922, "ltp": 1.54, "tv": 5579.92, "trd": NaN, "batb": NaN, "batl": [[2, 1.71, 39.5]]}, {"timestamp": 1631538166729, "ltp": 1.54, "tv": 5579.92, "trd": NaN, "batb": [[0, 1.4, 59.01], [1, 1.39, 80.9], [2, 1.38, 301.29]], "batl": [[0, 1.67, 6.5], [1, 1.71, 39.5], [2, 2.04, 492.16]]}, {"timestamp": 1631538167722, "ltp": 1.54, "tv": 5579.92, "trd": NaN, "batb": NaN, "batl": [[0, 1.71, 39.5], [1, 2.04, 492.16], [2, 2.04, 0]]}, {"timestamp": 1631538169406, "ltp": 1.54, "tv": 5579.92, "trd": NaN, "batb": [[0, 1.43, 85.94], [1, 1.42, 118.79], [2, 1.4, 59.01]], "batl": [[0, 1.67, 111.51], [1, 1.69, 120.45], [2, 1.71, 39.5]]}, {"timestamp": 1631538170611, "ltp": 1.54, "tv": 5579.92, "trd": NaN, "batb": NaN, "batl": [[2, 1.71, 46]]}, {"timestamp": 1631538180751, "ltp": 1.54, "tv": 5579.92, "trd": NaN, "batb": [[0, 1.44, 61.17], [1, 1.43, 85.94], [2, 1.42, 118.79]], "batl": NaN}, {"timestamp": 1631538181338, "ltp": 1.54, "tv": 5579.92, "trd": NaN, "batb": [[0, 1.43, 85.94], [1, 1.42, 118.79], [2, 1.4, 59.01]], "batl": [[0, 1.67, 147.01]]}, {"timestamp": 1631538182854, "ltp": 1.54, "tv": 5579.92, "trd": NaN, "batb": NaN, "batl": [[0, 1.67, 111.51]]}, {"timestamp": 1631538187770, "ltp": 1.54, "tv": 5579.92, "trd": NaN, "batb": [[0, 1.44, 59.67], [1, 1.43, 85.94], [2, 1.42, 118.79]], "batl": NaN}, {"timestamp": 1631538188041, "ltp": 1.54, "tv": 5579.92, "trd": NaN, "batb": [[0, 1.43, 85.94], [1, 1.42, 118.79], [2, 1.4, 59.01]], "batl": NaN}, {"timestamp": 1631538190846, "ltp": 1.54, "tv": 5579.92, "trd": NaN, "batb": NaN, "batl": [[0, 1.67, 118.1]]}, {"timestamp": 1631538191566, "ltp": 1.54, "tv": 5579.92, "trd": NaN, "batb": NaN, "batl": [[0, 1.67, 111.51]]}, {"timestamp": 1631538195750, "ltp": 1.54, "tv": 5579.92, "trd": NaN, "batb": [[0, 1.4, 59.01], [1, 1.39, 80.9], [2, 1.38, 301.29]], "batl": NaN}, {"timestamp": 1631538196586, "ltp": 1.54, "tv": 5579.92, "trd": NaN, "batb": NaN, "batl": [[0, 1.67, 145.01]]}, {"timestamp": 1631538197056, "ltp": 1.54, "tv": 5579.92, "trd": NaN, "batb": [[2, 1.2, 385.96]], "batl": [[0, 1.67, 111.51]]}, {"timestamp": 1631538198770, "ltp": 1.54, "tv": 5579.92, "trd": NaN, "batb": [[0, 1.62, 94.36], [1, 1.61, 71.35], [2, 1.59, 125.78]], "batl": NaN}, {"timestamp": 1631538199755, "ltp": 1.54, "tv": 5579.92, "trd": NaN, "batb": NaN, "batl": [[0, 1.65, 6.06], [1, 1.67, 111.51], [2, 1.69, 209.21]]}, {"timestamp": 1631538200588, "ltp": 1.54, "tv": 5579.92, "trd": NaN, "batb": NaN, "batl": [[2, 1.69, 138.21]]}, {"timestamp": 1631538206487, "ltp": 1.62, "tv": 5587.92, "trd": [[1.62, 40.94]], "batb": [[0, 1.62, 90.36]], "batl": NaN}, {"timestamp": 1631538220798, "ltp": 1.62, "tv": 5587.92, "trd": NaN, "batb": [[0, 1.62, 74.82], [2, 1.58, 49.19]], "batl": [[0, 1.67, 111.51], [1, 1.69, 120.45], [2, 1.71, 46]]}, {"timestamp": 1631538221322, "ltp": 1.62, "tv": 5587.92, "trd": NaN, "batb": [[0, 1.52, 47.24], [1, 1.47, 63.83], [2, 1.44, 354.18]], "batl": [[0, 1.74, 29.75], [1, 2.04, 492.16], [2, 1.71, 0]]}, {"timestamp": 1631538223826, "ltp": 1.62, "tv": 5587.92, "trd": NaN, "batb": [[1, 1.51, 132.6], [2, 1.5, 94.29]], "batl": [[1, 1.75, 70.98], [2, 1.77, 103.16]]}, {"timestamp": 1631538224812, "ltp": 1.62, "tv": 5587.92, "trd": NaN, "batb": [[1, 1.47, 63.83], [2, 1.44, 354.18]], "batl": [[1, 2.04, 492.16], [2, 1.77, 0]]}, {"timestamp": 1631538225648, "ltp": 1.62, "tv": 5587.92, "trd": NaN, "batb": [[0, 1.59, 135.94], [1, 1.58, 76.8], [2, 1.52, 47.24]], "batl": [[0, 1.64, 72.94], [1, 1.65, 84.11], [2, 1.74, 29.75]]}, {"timestamp": 1631538226013, "ltp": 1.62, "tv": 5587.92, "trd": NaN, "batb": NaN, "batl": [[1, 1.65, 65.21]]}, {"timestamp": 1631538227823, "ltp": 1.62, "tv": 5587.92, "trd": NaN, "batb": [[2, 1.55, 46.59]], "batl": NaN}, {"timestamp": 1631538229664, "ltp": 1.62, "tv": 5587.92, "trd": NaN, "batb": [[0, 1.55, 46.59], [1, 1.52, 47.24], [2, 1.47, 63.83]], "batl": [[0, 1.74, 29.75], [1, 2.04, 492.16], [2, 1.74, 0]]}, {"timestamp": 1631538229927, "ltp": 1.62, "tv": 5587.92, "trd": NaN, "batb": [[0, 1.52, 47.24], [1, 1.47, 63.83], [2, 1.44, 354.18]], "batl": NaN}, {"timestamp": 1631538231649, "ltp": 1.62, "tv": 5587.92, "trd": NaN, "batb": NaN, "batl": [[0, 1.71, 38.5], [1, 1.74, 29.75], [2, 2.04, 492.16]]}, {"timestamp": 1631538232649, "ltp": 1.62, "tv": 5587.92, "trd": NaN, "batb": [[1, 1.51, 131.67], [2, 1.5, 94.29]], "batl": [[0, 1.74, 29.75], [1, 1.75, 71.98], [2, 1.77, 103.16]]}, {"timestamp": 1631538238651, "ltp": 1.62, "tv": 5587.92, "trd": NaN, "batb": NaN, "batl": [[0, 1.71, 37.5], [1, 1.74, 29.75], [2, 2.04, 492.16]]}, {"timestamp": 1631538239745, "ltp": 1.62, "tv": 5587.92, "trd": NaN, "batb": NaN, "batl": [[0, 1.74, 29.75], [1, 2.04, 492.16], [2, 2.04, 0]]}, {"timestamp": 1631538240734, "ltp": 1.55, "tv": 5600.82, "trd": [[1.55, 304.37]], "batb": NaN, "batl": [[0, 1.56, 178.15], [1, 1.57, 94.01], [2, 1.58, 9.62]]}, {"timestamp": 1631538241837, "ltp": 1.55, "tv": 5600.82, "trd": NaN, "batb": [[2, 1.5, 114.29]], "batl": NaN}, {"timestamp": 1631538260551, "ltp": 1.55, "tv": 5600.82, "trd": NaN, "batb": [[0, 1.53, 81], [1, 1.52, 47.24], [2, 1.51, 131.67]], "batl": NaN}, {"timestamp": 1631538266705, "ltp": 1.55, "tv": 5600.82, "trd": NaN, "batb": [[1, 1.38, 301.29], [2, 1.36, 155.11]], "batl": [[0, 1.57, 6.5], [1, 1.67, 39.5], [2, 2.04, 492.16]]}, {"timestamp": 1631538267377, "ltp": 1.55, "tv": 5600.82, "trd": NaN, "batb": [[0, 1.38, 301.29], [1, 1.36, 155.11], [2, 1.2, 385.96]], "batl": NaN}, {"timestamp": 1631538269622, "ltp": 1.55, "tv": 5600.82, "trd": NaN, "batb": [[0, 1.39, 177.67], [1, 1.38, 437.7], [2, 1.36, 155.11]], "batl": [[0, 1.66, 96.44], [1, 1.67, 101.94]]}, {"timestamp": 1631538270178, "ltp": 1.55, "tv": 5600.82, "trd": NaN, "batb": NaN, "batl": [[0, 1.64, 125], [1, 1.66, 96.44], [2, 1.67, 101.94]]}, {"timestamp": 1631538273727, "ltp": 1.55, "tv": 5600.82, "trd": NaN, "batb": NaN, "batl": [[2, 1.67, 108.44]]}, {"timestamp": 1631538276842, "ltp": 1.55, "tv": 5600.82, "trd": NaN, "batb": [[0, 1.41, 64.89], [1, 1.39, 177.67], [2, 1.38, 437.7]], "batl": [[0, 1.64, 160.18]]}, {"timestamp": 1631538277256, "ltp": 1.55, "tv": 5600.82, "trd": NaN, "batb": [[0, 1.39, 177.67], [1, 1.38, 437.7], [2, 1.36, 155.11]], "batl": [[0, 1.64, 125]]}, {"timestamp": 1631538280841, "ltp": 1.55, "tv": 5600.82, "trd": NaN, "batb": NaN, "batl": [[1, 1.67, 46], [2, 2.04, 492.16]]}, {"timestamp": 1631538281255, "ltp": 1.55, "tv": 5600.82, "trd": NaN, "batb": [[1, 1.38, 136.41]], "batl": [[2, 2.04, 0]]}, {"timestamp": 1631538282834, "ltp": 1.55, "tv": 5600.82, "trd": NaN, "batb": [[0, 1.4, 341.29], [1, 1.39, 177.67], [2, 1.38, 136.41]], "batl": [[0, 1.43, 145.12], [1, 1.44, 255.84], [2, 1.45, 20.68]]}, {"timestamp": 1631538283647, "ltp": 1.55, "tv": 5600.82, "trd": NaN, "batb": [[0, 1.4, 448.43], [1, 1.39, 231.25], [2, 1.38, 189.99]], "batl": [[2, 1.45, 26.38]]}, {"timestamp": 1631538283961, "ltp": 1.55, "tv": 5600.82, "trd": NaN, "batb": [[0, 1.4, 362.71], [1, 1.39, 188.39], [2, 1.38, 147.13]], "batl": NaN}, {"timestamp": 1631538290834, "ltp": 1.55, "tv": 5600.82, "trd": NaN, "batb": [[0, 1.41, 235], [1, 1.4, 362.71], [2, 1.39, 188.39]], "batl": NaN}, {"timestamp": 1631538293860, "ltp": 1.55, "tv": 5600.82, "trd": NaN, "batb": [[2, 1.39, 167.98]], "batl": NaN}, {"timestamp": 1631538296865, "ltp": 1.55, "tv": 5600.82, "trd": NaN, "batb": NaN, "batl": [[0, 1.43, 164.97]]}, {"timestamp": 1631538301367, "ltp": 1.43, "tv": 5687.32, "trd": [[1.43, 86.5]], "batb": [[2, 1.39, 141.31]], "batl": [[0, 1.43, 78.47]]}, {"timestamp": 1631538303584, "ltp": 1.43, "tv": 5687.32, "trd": NaN, "batb": [[1, 1.28, 426.66], [2, 1.25, 139.04]], "batl": [[0, 1.45, 5.7], [1, 1.52, 67], [2, 1.58, 42.25]]}, {"timestamp": 1631538304562, "ltp": 1.43, "tv": 5687.32, "trd": NaN, "batb": [[0, 1.28, 426.66], [1, 1.25, 139.04], [2, 1.23, 105.63]], "batl": NaN}, {"timestamp": 1631538306769, "ltp": 1.43, "tv": 5687.32, "trd": NaN, "batb": NaN, "batl": [[2, 1.54, 6.38]]}, {"timestamp": 1631538307678, "ltp": 1.43, "tv": 5687.32, "trd": NaN, "batb": NaN, "batl": [[2, 1.58, 42.25]]}, {"timestamp": 1631538308693, "ltp": 1.43, "tv": 5687.32, "trd": NaN, "batb": [[0, 1.37, 144.13], [1, 1.36, 145.62], [2, 1.28, 426.66]], "batl": [[0, 1.4, 84.3], [1, 1.41, 120.93], [2, 1.45, 5.7]]}, {"timestamp": 1631538310702, "ltp": 1.43, "tv": 5687.32, "trd": NaN, "batb": NaN, "batl": [[2, 1.52, 67]]}, {"timestamp": 1631538315778, "ltp": 1.43, "tv": 5687.32, "trd": NaN, "batb": [[0, 1.28, 426.66], [1, 1.25, 139.04], [2, 1.23, 105.63]], "batl": [[0, 1.52, 67], [1, 1.54, 52.63], [2, 1.58, 48.5]]}, {"timestamp": 1631538316406, "ltp": 1.43, "tv": 5687.32, "trd": NaN, "batb": NaN, "batl": [[1, 1.58, 42.25], [2, 1.82, 585.75]]}, {"timestamp": 1631538317813, "ltp": 1.43, "tv": 5687.32, "trd": NaN, "batb": NaN, "batl": [[0, 1.58, 42.25], [1, 1.82, 585.75], [2, 1.82, 0]]}, {"timestamp": 1631538318700, "ltp": 1.43, "tv": 5687.32, "trd": NaN, "batb": [[0, 1.28, 567.75], [1, 1.27, 209.02], [2, 1.25, 139.04]], "batl": [[0, 1.54, 122.43], [1, 1.55, 81.78], [2, 1.58, 42.25]]}, {"timestamp": 1631538319589, "ltp": 1.43, "tv": 5687.32, "trd": NaN, "batb": NaN, "batl": [[2, 1.58, 49]]}, {"timestamp": 1631538322819, "ltp": 1.43, "tv": 5687.32, "trd": NaN, "batb": NaN, "batl": [[0, 1.54, 182.93]]}, {"timestamp": 1631538323339, "ltp": 1.43, "tv": 5687.32, "trd": NaN, "batb": NaN, "batl": [[0, 1.54, 122.43]]}, {"timestamp": 1631538324429, "ltp": 1.43, "tv": 5687.32, "trd": NaN, "batb": NaN, "batl": [[0, 1.58, 42.25], [1, 1.82, 585.75], [2, 1.58, 0]]}, {"timestamp": 1631538325208, "ltp": 1.43, "tv": 5687.32, "trd": NaN, "batb": [[0, 1.28, 141.09]], "batl": [[1, 1.82, 0]]}, {"timestamp": 1631538326818, "ltp": 1.43, "tv": 5687.32, "trd": NaN, "batb": [[0, 1.31, 13.68], [1, 1.28, 141.09], [2, 1.27, 209.02]], "batl": [[0, 1.33, 2825.16], [1, 1.34, 56.4], [2, 1.35, 56.4]]}, {"timestamp": 1631538327814, "ltp": 1.31, "tv": 5714.68, "trd": [[1.31, 27.36]], "batb": [[0, 1.29, 116.28], [1, 1.28, 199.23], [2, 1.27, 267.16]], "batl": [[0, 1.31, 215.11], [1, 1.32, 163.17], [2, 1.33, 145.86]]}, {"timestamp": 1631538328438, "ltp": 1.31, "tv": 5714.68, "trd": NaN, "batb": [[0, 1.29, 23.26], [1, 1.28, 152.71], [2, 1.27, 220.64]], "batl": [[2, 1.33, 55.64]]}, {"timestamp": 1631538330846, "ltp": 1.31, "tv": 5714.74, "trd": [[1.31, 27.42]], "batb": NaN, "batl": [[0, 1.31, 215.05]]}, {"timestamp": 1631538331850, "ltp": 1.31, "tv": 5714.74, "trd": NaN, "batb": [[0, 1.29, 317.26]], "batl": [[2, 1.33, 104.02]]}, {"timestamp": 1631538332014, "ltp": 1.31, "tv": 5714.74, "trd": NaN, "batb": NaN, "batl": [[2, 1.33, 55.64]]}, {"timestamp": 1631538335143, "ltp": 1.31, "tv": 5714.92, "trd": [[1.31, 27.6]], "batb": NaN, "batl": [[0, 1.31, 214.87]]}, {"timestamp": 1631538337761, "ltp": 1.31, "tv": 5714.92, "trd": NaN, "batb": NaN, "batl": [[2, 1.33, 30.08]]}, {"timestamp": 1631538340224, "ltp": 1.31, "tv": 5714.92, "trd": NaN, "batb": NaN, "batl": [[1, 1.32, 183.3]]}, {"timestamp": 1631538341844, "ltp": 1.31, "tv": 5714.92, "trd": NaN, "batb": NaN, "batl": [[2, 1.33, 22.56]]}, {"timestamp": 1631538342473, "ltp": 1.31, "tv": 5714.92, "trd": NaN, "batb": [[0, 1.29, 294], [1, 1.22, 372.57], [2, 1.2, 113.62]], "batl": [[0, 1.39, 67], [1, 1.42, 67], [2, 1.44, 53.58]]}, {"timestamp": 1631538343361, "ltp": 1.31, "tv": 5714.92, "trd": NaN, "batb": [[0, 1.22, 372.57], [1, 1.2, 113.62], [2, 1.17, 377.98]], "batl": NaN}, {"timestamp": 1631538344462, "ltp": 1.31, "tv": 5714.92, "trd": NaN, "batb": NaN, "batl": [[2, 1.43, 67.5]]}, {"timestamp": 1631538345663, "ltp": 1.31, "tv": 5714.92, "trd": NaN, "batb": [[2, 1.19, 315.94]], "batl": [[0, 1.38, 86.53], [1, 1.39, 195.85], [2, 1.4, 65.89]]}, {"timestamp": 1631538352573, "ltp": 1.31, "tv": 5714.92, "trd": NaN, "batb": [[1, 1.19, 315.94], [2, 1.18, 266.84]], "batl": [[0, 1.39, 67], [1, 1.42, 67], [2, 1.71, 659.22]]}, {"timestamp": 1631538354549, "ltp": 1.31, "tv": 5714.92, "trd": NaN, "batb": [[0, 1.19, 315.94], [1, 1.18, 266.84], [2, 1.17, 377.98]], "batl": [[2, 880, 0.01]]}, {"timestamp": 1631538355792, "ltp": 1.22, "tv": 5750.92, "trd": [[1.22, 36]], "batb": [[0, 1.2, 811.87], [1, 1.19, 315.94], [2, 1.18, 255.85]], "batl": [[0, 1.22, 260.02], [1, 1.25, 8], [2, 1.31, 43.88]]}, {"timestamp": 1631538356673, "ltp": 1.22, "tv": 5750.92, "trd": NaN, "batb": [[2, 1.18, 264.32]], "batl": NaN}, {"timestamp": 1631538358712, "ltp": 1.22, "tv": 5750.92, "trd": NaN, "batb": NaN, "batl": [[0, 1.22, 337.64], [1, 1.23, 225.34], [2, 1.25, 8]]}, {"timestamp": 1631538361267, "ltp": 1.22, "tv": 5750.92, "trd": NaN, "batb": [[0, 1.2, 950.87]], "batl": NaN}, {"timestamp": 1631538368781, "ltp": 1.22, "tv": 5750.92, "trd": NaN, "batb": NaN, "batl": [[1, 1.23, 255.97]]}, {"timestamp": 1631538370613, "ltp": 1.22, "tv": 5790.92, "trd": [[1.22, 76]], "batb": [[2, 1.18, 252.86]], "batl": [[0, 1.22, 317.64]]}, {"timestamp": 1631538371288, "ltp": 1.22, "tv": 5790.92, "trd": NaN, "batb": [[0, 1.2, 811.87]], "batl": NaN}, {"timestamp": 1631538372805, "ltp": 1.22, "tv": 5800.92, "trd": [[1.22, 86]], "batb": NaN, "batl": [[0, 1.22, 312.64]]}, {"timestamp": 1631538373484, "ltp": 1.22, "tv": 5800.92, "trd": NaN, "batb": [[1, 1.19, 336.73]], "batl": [[1, 1.23, 266.93]]}, {"timestamp": 1631538374436, "ltp": 1.22, "tv": 5800.92, "trd": NaN, "batb": [[0, 1.21, 178], [1, 1.2, 811.87], [2, 1.19, 336.73]], "batl": NaN}, {"timestamp": 1631538376303, "ltp": 1.22, "tv": 5800.92, "trd": NaN, "batb": NaN, "batl": [[0, 1.22, 323.82]]}, {"timestamp": 1631538377717, "ltp": 1.21, "tv": 5805.82, "trd": [[1.21, 4], [1.22, 86.9]], "batb": [[0, 1.21, 176]], "batl": [[0, 1.22, 323.37]]}, {"timestamp": 1631538380015, "ltp": 1.22, "tv": 5805.99, "trd": [[1.22, 87.07]], "batb": NaN, "batl": [[0, 1.22, 323.2]]}, {"timestamp": 1631538408687, "ltp": 1.22, "tv": 5848.06, "trd": [[1.22, 129.14]], "batb": NaN, "batl": [[0, 1.22, 281.13]]}, {"timestamp": 1631538412261, "ltp": 1.22, "tv": 5848.44, "trd": [[1.22, 129.52]], "batb": [[2, 1.19, 363.82]], "batl": [[0, 1.22, 300.04]]}, {"timestamp": 1631538417567, "ltp": 1.22, "tv": 5928.44, "trd": [[1.22, 209.52]], "batb": NaN, "batl": [[0, 1.22, 260.04]]}, {"timestamp": 1631538419782, "ltp": 1.22, "tv": 5931.92, "trd": [[1.22, 213]], "batb": NaN, "batl": [[0, 1.22, 258.3]]}, {"timestamp": 1631538420586, "ltp": 1.22, "tv": 5931.92, "trd": NaN, "batb": [[2, 1.19, 385.4]], "batl": [[0, 1.22, 277.51]]}, {"timestamp": 1631538422081, "ltp": 1.22, "tv": 5931.92, "trd": NaN, "batb": [[0, 1.21, 179.61]], "batl": [[0, 1.22, 364.23]]}, {"timestamp": 1631538424404, "ltp": 1.22, "tv": 5931.92, "trd": NaN, "batb": [[0, 1.21, 176]], "batl": NaN}, {"timestamp": 1631538456338, "ltp": 1.22, "tv": 5932.0, "trd": [[1.22, 213.08]], "batb": NaN, "batl": [[0, 1.22, 364.15]]}, {"timestamp": 1631538475389, "ltp": 1.21, "tv": 6308.02, "trd": [[1.21, 380.02]], "batb": [[0, 1.2, 811.87], [1, 1.19, 385.4], [2, 1.18, 203.77]], "batl": [[0, 1.21, 644.09], [1, 1.22, 364.15], [2, 1.23, 266.93]]}, {"timestamp": 1631538479301, "ltp": 1.21, "tv": 6308.02, "trd": NaN, "batb": [[0, 1.2, 1039.87]], "batl": NaN}, {"timestamp": 1631538480344, "ltp": 1.21, "tv": 6308.02, "trd": NaN, "batb": NaN, "batl": [[1, 1.22, 277.43]]}, {"timestamp": 1631538482010, "ltp": 1.21, "tv": 6308.02, "trd": NaN, "batb": NaN, "batl": [[0, 1.22, 277.43], [1, 1.23, 266.93], [2, 1.25, 8]]}, {"timestamp": 1631538483384, "ltp": 1.21, "tv": 6308.02, "trd": NaN, "batb": NaN, "batl": [[0, 1.21, 86.72], [1, 1.22, 277.43], [2, 1.23, 266.93]]}, {"timestamp": 1631538485634, "ltp": 1.2, "tv": 7596.2, "trd": [[1.2, 1288.18]], "batb": [[0, 1.2, 395.78]], "batl": [[2, 1.23, 236.3]]}, {"timestamp": 1631538488509, "ltp": 1.2, "tv": 7596.2, "trd": NaN, "batb": [[0, 1.2, 418.87]], "batl": [[1, 1.22, 301.25]]}, {"timestamp": 1631538495769, "ltp": 1.21, "tv": 7596.29, "trd": [[1.21, 380.11]], "batb": [[0, 1.2, 275.91], [1, 1.17, 215.01], [2, 1.15, 244.2]], "batl": [[0, 1.21, 86.64], [1, 1.28, 75], [2, 1.3, 67]]}, {"timestamp": 1631538496406, "ltp": 1.21, "tv": 7599.7, "trd": [[1.21, 383.52]], "batb": [[0, 1.15, 244.2], [1, 1.14, 431.42], [2, 1.01, 115.38]], "batl": [[0, 1.21, 84.93]]}, {"timestamp": 1631538498652, "ltp": 1.21, "tv": 7599.7, "trd": NaN, "batb": [[0, 1.17, 342.82], [1, 1.16, 248.27], [2, 1.15, 244.2]], "batl": [[1, 1.26, 206.03], [2, 1.27, 199.45]]}, {"timestamp": 1631538500359, "ltp": 1.21, "tv": 7616.73, "trd": [[1.21, 400.55]], "batb": NaN, "batl": [[0, 1.21, 76.42]]}, {"timestamp": 1631538502776, "ltp": 1.21, "tv": 7621.06, "trd": [[1.21, 404.88]], "batb": NaN, "batl": [[0, 1.21, 74.25]]}, {"timestamp": 1631538504452, "ltp": 1.21, "tv": 7621.06, "trd": NaN, "batb": NaN, "batl": [[1, 1.25, 75], [2, 1.26, 206.03]]}, {"timestamp": 1631538509569, "ltp": 1.21, "tv": 7621.06, "trd": NaN, "batb": NaN, "batl": [[2, 1.28, 75]]}, {"timestamp": 1631538512449, "ltp": 1.21, "tv": 7621.06, "trd": NaN, "batb": [[0, 1.18, 916.06], [1, 1.17, 342.82], [2, 1.16, 248.27]], "batl": [[0, 1.19, 129.8], [1, 1.2, 287.12], [2, 1.21, 74.25]]}, {"timestamp": 1631538513281, "ltp": 1.21, "tv": 7621.06, "trd": NaN, "batb": [[2, 1.16, 256.89]], "batl": NaN}, {"timestamp": 1631538517573, "ltp": 1.19, "tv": 7731.62, "trd": [[1.19, 110.56]], "batb": [[2, 1.16, 194.1]], "batl": [[0, 1.2, 287.12], [1, 1.21, 74.25], [2, 1.23, 8.13]]}, {"timestamp": 1631538518676, "ltp": 1.19, "tv": 7731.62, "trd": NaN, "batb": [[1, 1.17, 485.79], [2, 1.16, 342.13]], "batl": [[2, 1.23, 106.63]]}, {"timestamp": 1631538520493, "ltp": 1.19, "tv": 7731.62, "trd": NaN, "batb": [[0, 1.18, 1067.06], [1, 1.17, 548.04]], "batl": [[0, 1.2, 355.27], [1, 1.21, 291.41]]}, {"timestamp": 1631538524781, "ltp": 1.19, "tv": 7731.62, "trd": NaN, "batb": [[0, 1.18, 916.06], [1, 1.17, 496.52], [2, 1.16, 156.65]], "batl": [[0, 1.2, 314.32]]}, {"timestamp": 1631538527700, "ltp": 1.19, "tv": 7731.62, "trd": NaN, "batb": [[0, 1.19, 381], [1, 1.18, 977.13], [2, 1.17, 496.52]], "batl": [[1, 1.21, 332.02]]}, {"timestamp": 1631538530406, "ltp": 1.19, "tv": 7731.62, "trd": NaN, "batb": NaN, "batl": [[0, 1.2, 328.28]]}, {"timestamp": 1631538535107, "ltp": 1.19, "tv": 7731.62, "trd": NaN, "batb": NaN, "batl": [[2, 1.22, 82]]}, {"timestamp": 1631538538786, "ltp": 1.19, "tv": 7731.62, "trd": NaN, "batb": [[1, 1.17, 142.97], [2, 1.16, 148.03]], "batl": [[0, 1.21, 74.25], [1, 1.22, 82], [2, 1.24, 109.73]]}, {"timestamp": 1631538539725, "ltp": 1.19, "tv": 7731.62, "trd": NaN, "batb": [[0, 1.16, 148.03], [1, 1.13, 915.8], [2, 1.01, 115.38]], "batl": [[2, 1.25, 166.46]]}, {"timestamp": 1631538541510, "ltp": 1.19, "tv": 7731.62, "trd": NaN, "batb": [[0, 1.16, 327.85], [1, 1.15, 412.13], [2, 1.13, 915.8]], "batl": [[2, 1.23, 190.58]]}, {"timestamp": 1631538543510, "ltp": 1.19, "tv": 7731.62, "trd": NaN, "batb": NaN, "batl": [[2, 1.25, 166.46]]}, {"timestamp": 1631538545601, "ltp": 1.19, "tv": 7731.62, "trd": NaN, "batb": [[2, 1.13, 277.25]], "batl": [[2, 1.23, 111.5]]}, {"timestamp": 1631538546538, "ltp": 1.19, "tv": 7731.62, "trd": NaN, "batb": [[0, 1.16, 377.41]], "batl": [[0, 1.18, 343.77], [1, 1.19, 270.47], [2, 1.2, 681.19]]}, {"timestamp": 1631538547322, "ltp": 1.19, "tv": 7731.62, "trd": NaN, "batb": [[1, 1.15, 420.83]], "batl": NaN}, {"timestamp": 1631538548630, "ltp": 1.19, "tv": 7731.62, "trd": NaN, "batb": NaN, "batl": [[2, 1.2, 763.19]]}, {"timestamp": 1631538550301, "ltp": 1.19, "tv": 7731.62, "trd": NaN, "batb": [[0, 1.17, 321], [1, 1.16, 377.41], [2, 1.15, 420.83]], "batl": NaN}, {"timestamp": 1631538552396, "ltp": 1.19, "tv": 7731.62, "trd": NaN, "batb": [[2, 1.15, 573.06]], "batl": [[2, 1.2, 880.42]]}, {"timestamp": 1631538557051, "ltp": 1.19, "tv": 7731.62, "trd": NaN, "batb": [[2, 1.15, 532.08]], "batl": [[0, 1.18, 298.33]]}, {"timestamp": 1631538559934, "ltp": 1.19, "tv": 7731.62, "trd": NaN, "batb": [[1, 1.16, 423.68]], "batl": [[1, 1.19, 294.33]]}, {"timestamp": 1631538562427, "ltp": 1.19, "tv": 7731.62, "trd": NaN, "batb": [[1, 1.16, 148.03], [2, 1.15, 294.06]], "batl": [[0, 1.2, 82], [1, 1.21, 195.75], [2, 1.22, 82]]}, {"timestamp": 1631538563630, "ltp": 1.19, "tv": 7731.62, "trd": NaN, "batb": [[0, 1.15, 294.06], [1, 1.11, 1000.76], [2, 1.01, 115.38]], "batl": NaN}, {"timestamp": 1631538565656, "ltp": 1.19, "tv": 7731.62, "trd": NaN, "batb": [[1, 1.14, 441.39], [2, 1.11, 1000.76]], "batl": [[0, 1.2, 336.9], [1, 1.21, 461.76]]}, {"timestamp": 1631538566433, "ltp": 1.19, "tv": 7731.62, "trd": NaN, "batb": [[0, 1.15, 152.23], [1, 1.11, 1000.76], [2, 1.01, 115.38]], "batl": NaN}, {"timestamp": 1631538567838, "ltp": 1.19, "tv": 7731.62, "trd": NaN, "batb": NaN, "batl": [[0, 1.2, 254.9]]}, {"timestamp": 1631538568149, "ltp": 1.19, "tv": 7731.62, "trd": NaN, "batb": [[1, 1.11, 307.11]], "batl": [[0, 1.2, 144.92]]}, {"timestamp": 1631538569556, "ltp": 1.19, "tv": 7731.62, "trd": NaN, "batb": [[0, 1.19, 36.81], [1, 1.18, 1360.69], [2, 1.17, 320.82]], "batl": [[0, 1.2, 154.43], [2, 1.22, 1044.8]]}, {"timestamp": 1631538575990, "ltp": 1.19, "tv": 7731.62, "trd": NaN, "batb": [[2, 1.17, 449.79]], "batl": [[2, 1.22, 1157.55]]}, {"timestamp": 1631538577458, "ltp": 1.19, "tv": 7731.62, "trd": NaN, "batb": [[0, 1.19, 163.81]], "batl": NaN}, {"timestamp": 1631538586820, "ltp": 1.19, "tv": 7731.62, "trd": NaN, "batb": [[0, 1.19, 145.71], [1, 1.18, 323.06], [2, 1.17, 441.24]], "batl": [[0, 1.2, 144.92], [2, 1.22, 194.75]]}, {"timestamp": 1631538587712, "ltp": 1.19, "tv": 7731.62, "trd": NaN, "batb": [[0, 1.19, 127], [1, 1.17, 128.97], [2, 1.16, 160.53]], "batl": [[0, 1.21, 74.25], [1, 1.22, 82], [2, 1.23, 103.5]]}, {"timestamp": 1631538588710, "ltp": 1.19, "tv": 7731.62, "trd": NaN, "batb": [[0, 1.16, 160.53], [1, 1.13, 913.54], [2, 1.01, 115.38]], "batl": NaN}, {"timestamp": 1631538592102, "ltp": 1.19, "tv": 7731.62, "trd": NaN, "batb": [[0, 1.19, 175.41], [1, 1.18, 332.28], [2, 1.17, 142.97]], "batl": [[0, 1.21, 277.45], [1, 1.22, 332.17]]}, {"timestamp": 1631538594100, "ltp": 1.19, "tv": 7731.62, "trd": NaN, "batb": NaN, "batl": [[1, 1.22, 453.42]]}, {"timestamp": 1631538595305, "ltp": 1.19, "tv": 7731.78, "trd": [[1.19, 110.72]], "batb": [[0, 1.19, 325.33]], "batl": NaN}, {"timestamp": 1631538599188, "ltp": 1.21, "tv": 7742.4, "trd": [[1.21, 415.51]], "batb": [[0, 1.19, 150], [1, 1.17, 142.97], [2, 1.16, 160.53]], "batl": [[0, 1.21, 68.94], [1, 1.22, 82]]}, {"timestamp": 1631538600609, "ltp": 1.21, "tv": 7742.4, "trd": NaN, "batb": [[0, 1.16, 160.53], [1, 1.13, 913.54], [2, 1.01, 115.38]], "batl": NaN}, {"timestamp": 1631538601400, "ltp": 1.21, "tv": 7742.4, "trd": NaN, "batb": NaN, "batl": [[0, 1.21, 69.02]]}, {"timestamp": 1631538602718, "ltp": 1.21, "tv": 7742.4, "trd": NaN, "batb": [[0, 1.16, 421.71], [1, 1.15, 335.75], [2, 1.13, 913.54]], "batl": NaN}, {"timestamp": 1631538603825, "ltp": 1.21, "tv": 7742.4, "trd": NaN, "batb": [[0, 1.17, 149.97], [1, 1.16, 421.71], [2, 1.15, 335.75]], "batl": NaN}, {"timestamp": 1631538604143, "ltp": 1.21, "tv": 7742.4, "trd": NaN, "batb": [[0, 1.16, 421.71], [1, 1.15, 335.75], [2, 1.13, 913.54]], "batl": NaN}, {"timestamp": 1631538608708, "ltp": 1.21, "tv": 7742.4, "trd": NaN, "batb": [[0, 1.16, 160.53], [1, 1.13, 913.54], [2, 1.01, 115.38]], "batl": NaN}, {"timestamp": 1631538609807, "ltp": 1.21, "tv": 7742.4, "trd": NaN, "batb": NaN, "batl": [[1, 1.22, 207.75]]}, {"timestamp": 1631538610641, "ltp": 1.21, "tv": 7742.4, "trd": NaN, "batb": [[1, 1.13, 274.99]], "batl": [[1, 1.23, 103.5], [2, 1.24, 143.78]]}, {"timestamp": 1631538611736, "ltp": 1.21, "tv": 7880.44, "trd": [[1.19, 110.88], [1.21, 553.38]], "batb": [[0, 1.22, 200.83], [1, 1.21, 351.55], [2, 1.2, 117.41]], "batl": [[0, 1.23, 103.5], [1, 1.24, 166.49], [2, 1.25, 291.57]]}, {"timestamp": 1631538612742, "ltp": 1.21, "tv": 7880.44, "trd": NaN, "batb": [[1, 1.21, 332.86]], "batl": NaN}, {"timestamp": 1631538613422, "ltp": 1.21, "tv": 7880.44, "trd": NaN, "batb": NaN, "batl": [[2, 1.25, 216.57]]}, {"timestamp": 1631538616508, "ltp": 1.21, "tv": 7880.44, "trd": NaN, "batb": [[0, 1.22, 348.83]], "batl": NaN}, {"timestamp": 1631538636550, "ltp": 1.21, "tv": 7880.44, "trd": NaN, "batb": [[0, 1.22, 148], [1, 1.18, 325.62], [2, 1.16, 744.51]], "batl": [[0, 1.26, 125], [1, 1.29, 83.5], [2, 1.31, 78.5]]}, {"timestamp": 1631538637489, "ltp": 1.21, "tv": 7880.44, "trd": NaN, "batb": [[0, 1.16, 744.51], [1, 1.15, 238.6], [2, 1.01, 115.38]], "batl": NaN}, {"timestamp": 1631538639575, "ltp": 1.21, "tv": 7880.44, "trd": NaN, "batb": [[0, 1.18, 274.61], [1, 1.17, 312.01], [2, 1.16, 744.51]], "batl": [[2, 1.31, 221.53]]}, {"timestamp": 1631538640704, "ltp": 1.21, "tv": 7880.44, "trd": NaN, "batb": [[0, 1.18, 137.86], [1, 1.16, 744.51], [2, 1.15, 238.6]], "batl": [[2, 1.31, 78.5]]}, {"timestamp": 1631538641035, "ltp": 1.21, "tv": 7880.44, "trd": NaN, "batb": [[0, 1.16, 744.51], [1, 1.15, 238.6], [2, 1.01, 115.38]], "batl": NaN}, {"timestamp": 1631538642280, "ltp": 1.21, "tv": 7880.44, "trd": NaN, "batb": [[0, 1.23, 207.84], [1, 1.22, 263.28], [2, 1.16, 744.51]], "batl": [[0, 1.26, 404.04], [1, 1.27, 194.48], [2, 1.29, 83.5]]}, {"timestamp": 1631538644261, "ltp": 1.21, "tv": 7880.44, "trd": NaN, "batb": [[2, 1.18, 134.86]], "batl": NaN}, {"timestamp": 1631538649486, "ltp": 1.21, "tv": 7880.44, "trd": NaN, "batb": [[0, 1.16, 744.51], [1, 1.15, 238.6], [2, 1.01, 115.38]], "batl": [[0, 1.26, 125], [1, 1.29, 83.5], [2, 1.31, 78.5]]}, {"timestamp": 1631538652717, "ltp": 1.21, "tv": 7880.44, "trd": NaN, "batb": [[0, 1.18, 399.47], [1, 1.17, 312.01], [2, 1.16, 744.51]], "batl": [[2, 1.31, 221.53]]}, {"timestamp": 1631538654700, "ltp": 1.21, "tv": 7880.44, "trd": NaN, "batb": NaN, "batl": [[0, 1.29, 83.5], [1, 1.31, 221.53], [2, 1.32, 160.5]]}, {"timestamp": 1631538655012, "ltp": 1.21, "tv": 7880.44, "trd": NaN, "batb": NaN, "batl": [[0, 1.31, 221.53], [1, 1.32, 160.5], [2, 1.49, 772.05]]}, {"timestamp": 1631538657586, "ltp": 1.21, "tv": 7880.44, "trd": NaN, "batb": NaN, "batl": [[0, 1.31, 78.5], [1, 1.49, 772.05], [2, 3.8, 27.46]]}, {"timestamp": 1631538659410, "ltp": 1.21, "tv": 7880.44, "trd": NaN, "batb": [[2, 1.16, 160.53]], "batl": NaN}, {"timestamp": 1631538660700, "ltp": 1.21, "tv": 7880.44, "trd": NaN, "batb": [[0, 1.18, 1280.42]], "batl": [[0, 1.2, 156.95], [1, 1.21, 266.01], [2, 1.22, 1004.22]]}, {"timestamp": 1631538661802, "ltp": 1.21, "tv": 7880.44, "trd": NaN, "batb": [[2, 1.16, 169.15]], "batl": NaN}, {"timestamp": 1631538668635, "ltp": 1.21, "tv": 7880.44, "trd": NaN, "batb": [[0, 1.19, 167], [1, 1.18, 1280.42], [2, 1.17, 312.01]], "batl": NaN}, {"timestamp": 1631538678851, "ltp": 1.21, "tv": 7880.44, "trd": NaN, "batb": [[1, 1.16, 160.53], [2, 1.15, 174.23]], "batl": [[0, 1.23, 97], [1, 1.25, 203.1], [2, 1.3, 67]]}, {"timestamp": 1631538679754, "ltp": 1.21, "tv": 7880.44, "trd": NaN, "batb": [[0, 1.14, 201.82], [1, 1.13, 919.57], [2, 1.01, 115.38]], "batl": NaN}, {"timestamp": 1631538681536, "ltp": 1.21, "tv": 7880.44, "trd": NaN, "batb": [[0, 1.16, 105.54], [1, 1.15, 406.57], [2, 1.14, 201.82]], "batl": [[1, 1.25, 431.43], [2, 1.26, 204.65]]}, {"timestamp": 1631538682847, "ltp": 1.21, "tv": 7880.44, "trd": NaN, "batb": NaN, "batl": [[1, 1.24, 88.48], [2, 1.25, 97]]}, {"timestamp": 1631538683526, "ltp": 1.21, "tv": 7880.44, "trd": NaN, "batb": NaN, "batl": [[0, 1.23, 97.19]]}, {"timestamp": 1631538685830, "ltp": 1.21, "tv": 7880.44, "trd": NaN, "batb": [[0, 1.16, 155.1]], "batl": [[0, 1.18, 3106.92], [1, 1.19, 207.17], [2, 1.2, 8.52]]}, {"timestamp": 1631538686762, "ltp": 1.21, "tv": 7880.44, "trd": NaN, "batb": [[2, 1.14, 210.59]], "batl": [[0, 1.18, 595.63]]}, {"timestamp": 1631538694461, "ltp": 1.21, "tv": 7880.44, "trd": NaN, "batb": [[0, 1.16, 271.1]], "batl": NaN}, {"timestamp": 1631538696358, "ltp": 1.21, "tv": 7880.44, "trd": NaN, "batb": [[0, 1.16, 155.1]], "batl": NaN}, {"timestamp": 1631538697598, "ltp": 1.16, "tv": 8035.54, "trd": [[1.16, 155.1]], "batb": [[0, 1.15, 406.57], [1, 1.14, 210.59], [2, 1.13, 281.01]], "batl": [[0, 1.18, 374.81]]}, {"timestamp": 1631538697871, "ltp": 1.16, "tv": 8035.54, "trd": NaN, "batb": NaN, "batl": [[0, 1.18, 321.55], [1, 1.2, 8.52], [2, 1.24, 88.48]]}, {"timestamp": 1631538699482, "ltp": 1.16, "tv": 8122.86, "trd": [[1.16, 242.42]], "batb": [[0, 1.17, 332.68], [1, 1.15, 406.57], [2, 1.14, 210.59]], "batl": NaN}, {"timestamp": 1631538700775, "ltp": 1.17, "tv": 8345.94, "trd": [[1.17, 223.08]], "batb": [[0, 1.17, 221.14], [1, 1.15, 454.05], [2, 1.14, 356.78]], "batl": NaN}, {"timestamp": 1631538701085, "ltp": 1.17, "tv": 8345.94, "trd": NaN, "batb": [[1, 1.15, 406.57], [2, 1.14, 210.59]], "batl": NaN}, {"timestamp": 1631538704008, "ltp": 1.17, "tv": 8345.94, "trd": NaN, "batb": [[1, 1.16, 109.38], [2, 1.15, 406.57]], "batl": [[0, 1.18, 371.05], [1, 1.19, 210.9], [2, 1.2, 8.52]]}, {"timestamp": 1631538710588, "ltp": 1.17, "tv": 8424.14, "trd": [[1.17, 301.28]], "batb": [[0, 1.17, 182.04]], "batl": NaN}, {"timestamp": 1631538712826, "ltp": 1.18, "tv": 8464.14, "trd": [[1.18, 40]], "batb": NaN, "batl": [[0, 1.18, 351.05]]}, {"timestamp": 1631538713726, "ltp": 1.18, "tv": 8556.58, "trd": [[1.18, 132.44]], "batb": NaN, "batl": [[0, 1.18, 304.83]]}, {"timestamp": 1631538716304, "ltp": 1.18, "tv": 8556.58, "trd": NaN, "batb": [[0, 1.17, 370], [1, 1.16, 120.63]], "batl": [[1, 1.19, 221.87]]}, {"timestamp": 1631538717132, "ltp": 1.18, "tv": 8556.58, "trd": NaN, "batb": [[1, 1.16, 146.63]], "batl": [[0, 1.18, 334.45], [1, 1.19, 247.19]]}, {"timestamp": 1631538723739, "ltp": 1.18, "tv": 8556.58, "trd": NaN, "batb": [[1, 1.14, 210.59], [2, 1.13, 281.01]], "batl": [[0, 1.18, 40.55], [1, 1.2, 8.52], [2, 1.24, 88.48]]}, {"timestamp": 1631538725823, "ltp": 1.18, "tv": 8556.58, "trd": NaN, "batb": [[2, 1.13, 475.25]], "batl": [[1, 1.2, 151], [2, 1.21, 264.71]]}, {"timestamp": 1631538745746, "ltp": 1.18, "tv": 8556.58, "trd": NaN, "batb": [[2, 1.13, 670.98]], "batl": [[1, 1.19, 134.5], [2, 1.2, 279.08]]}, {"timestamp": 1631538747091, "ltp": 1.18, "tv": 8556.58, "trd": NaN, "batb": NaN, "batl": [[2, 1.2, 279.3]]}, {"timestamp": 1631538758582, "ltp": 1.18, "tv": 8556.58, "trd": NaN, "batb": [[1, 1.13, 389.97], [2, 1.12, 628.83]], "batl": [[0, 1.2, 270.97], [1, 1.21, 264.71], [2, 1.39, 17.79]]}, {"timestamp": 1631538759572, "ltp": 1.18, "tv": 8556.58, "trd": NaN, "batb": [[0, 1.13, 194.24], [1, 1.12, 628.83], [2, 1.11, 693.65]], "batl": NaN}, {"timestamp": 1631538760877, "ltp": 1.18, "tv": 8556.58, "trd": NaN, "batb": [[0, 1.12, 209.79], [1, 1.11, 693.65], [2, 1.1, 350.12]], "batl": NaN}, {"timestamp": 1631538762385, "ltp": 1.18, "tv": 8556.58, "trd": NaN, "batb": [[1, 1.1, 350.12], [2, 1.01, 115.38]], "batl": NaN}, {"timestamp": 1631538763686, "ltp": 1.18, "tv": 8556.58, "trd": NaN, "batb": [[0, 1.19, 20.03], [1, 1.18, 741.91], [2, 1.17, 170.94]], "batl": [[0, 1.2, 279.3]]}, {"timestamp": 1631538764782, "ltp": 1.18, "tv": 8556.58, "trd": NaN, "batb": [[1, 1.18, 1064.5], [2, 1.17, 434.52]], "batl": [[2, 1.22, 8.2]]}, {"timestamp": 1631538768688, "ltp": 1.18, "tv": 8556.58, "trd": NaN, "batb": NaN, "batl": [[2, 1.22, 203.21]]}, {"timestamp": 1631538768895, "ltp": 1.18, "tv": 8556.58, "trd": NaN, "batb": NaN, "batl": [[2, 1.22, 8.2]]}, {"timestamp": 1631538771918, "ltp": 1.18, "tv": 8556.58, "trd": NaN, "batb": NaN, "batl": [[1, 1.21, 404.21], [2, 1.22, 116.45]]}, {"timestamp": 1631538774513, "ltp": 1.18, "tv": 8556.58, "trd": NaN, "batb": [[0, 1.19, 205.03]], "batl": NaN}, {"timestamp": 1631538781027, "ltp": 1.18, "tv": 8556.58, "trd": NaN, "batb": [[1, 1.18, 1015.78]], "batl": NaN}, {"timestamp": 1631538782738, "ltp": 1.18, "tv": 8556.58, "trd": NaN, "batb": [[0, 1.19, 185], [1, 1.16, 142.78], [2, 1.15, 175.03]], "batl": [[0, 1.22, 108.66], [1, 1.39, 17.79], [2, 3.8, 27.46]]}, {"timestamp": 1631538783843, "ltp": 1.2, "tv": 8556.99, "trd": [[1.2, 1288.59]], "batb": [[0, 1.15, 175.03], [1, 1.12, 498.33], [2, 1.01, 115.38]], "batl": [[0, 1.22, 108.25]]}, {"timestamp": 1631538785340, "ltp": 1.2, "tv": 8556.99, "trd": NaN, "batb": [[0, 1.15, 552.58], [1, 1.14, 223.36], [2, 1.12, 498.33]], "batl": [[1, 1.23, 267.89], [2, 1.24, 222.86]]}, {"timestamp": 1631538786845, "ltp": 1.2, "tv": 8556.99, "trd": NaN, "batb": [[0, 1.16, 154.03], [1, 1.15, 552.58], [2, 1.14, 223.36]], "batl": NaN}, {"timestamp": 1631538787156, "ltp": 1.2, "tv": 8556.99, "trd": NaN, "batb": [[0, 1.15, 552.58], [1, 1.14, 223.36], [2, 1.12, 498.33]], "batl": NaN}, {"timestamp": 1631538791359, "ltp": 1.2, "tv": 8556.99, "trd": NaN, "batb": NaN, "batl": [[1, 1.39, 17.79], [2, 3.8, 27.46]]}, {"timestamp": 1631538793755, "ltp": 1.2, "tv": 8556.99, "trd": NaN, "batb": [[0, 1.16, 178.03], [1, 1.15, 552.58], [2, 1.14, 223.36]], "batl": [[0, 1.21, 125.5], [1, 1.22, 108.25], [2, 1.39, 17.79]]}, {"timestamp": 1631538794751, "ltp": 1.2, "tv": 8558.59, "trd": [[1.2, 1290.19]], "batb": [[0, 1.15, 602.57], [1, 1.14, 223.36], [2, 1.13, 25.44]], "batl": [[0, 1.17, 439.54], [1, 1.18, 315.28], [2, 1.2, 8.33]]}, {"timestamp": 1631538795164, "ltp": 1.2, "tv": 8558.59, "trd": NaN, "batb": [[1, 1.14, 232.13]], "batl": NaN}, {"timestamp": 1631538796571, "ltp": 1.2, "tv": 8558.59, "trd": NaN, "batb": NaN, "batl": [[2, 1.2, 105.33]]}, {"timestamp": 1631538800278, "ltp": 1.2, "tv": 8558.59, "trd": NaN, "batb": [[0, 1.16, 280], [1, 1.15, 602.57], [2, 1.14, 232.13]], "batl": NaN}, {"timestamp": 1631538800955, "ltp": 1.2, "tv": 8558.59, "trd": NaN, "batb": NaN, "batl": [[2, 1.19, 151.5]]}, {"timestamp": 1631538803857, "ltp": 1.2, "tv": 8558.59, "trd": NaN, "batb": NaN, "batl": [[2, 1.19, 276.5]]}, {"timestamp": 1631538806185, "ltp": 1.2, "tv": 8558.59, "trd": NaN, "batb": NaN, "batl": [[0, 1.17, 190.85]]}, {"timestamp": 1631538808094, "ltp": 1.17, "tv": 8559.49, "trd": [[1.17, 302.18]], "batb": NaN, "batl": [[0, 1.17, 189.95]]}, {"timestamp": 1631538810799, "ltp": 1.17, "tv": 8559.49, "trd": NaN, "batb": [[1, 1.15, 225.02], [2, 1.13, 25.44]], "batl": [[0, 1.19, 276.5], [1, 1.2, 216.93], [2, 1.22, 108.25]]}, {"timestamp": 1631538811795, "ltp": 1.17, "tv": 8559.49, "trd": NaN, "batb": [[0, 1.1, 273.74], [1, 1.09, 369.78], [2, 1.01, 115.38]], "batl": [[0, 1.19, 125]]}, {"timestamp": 1631538813712, "ltp": 1.17, "tv": 8559.49, "trd": NaN, "batb": [[0, 1.12, 293.48], [1, 1.11, 324.43], [2, 1.1, 273.74]], "batl": [[1, 1.2, 386.19], [2, 1.21, 263.85]]}, {"timestamp": 1631538814802, "ltp": 1.17, "tv": 8559.49, "trd": NaN, "batb": [[0, 1.1, 273.74], [1, 1.09, 369.78], [2, 1.01, 115.38]], "batl": [[0, 1.19, 125.5], [1, 1.2, 289.19]]}, {"timestamp": 1631538815784, "ltp": 1.17, "tv": 8559.49, "trd": NaN, "batb": [[0, 1.19, 17.49], [1, 1.18, 263.99], [2, 1.17, 342.01]], "batl": [[0, 1.2, 298.72], [1, 1.21, 263.85], [2, 1.22, 108.25]]}, {"timestamp": 1631538816842, "ltp": 1.17, "tv": 8559.49, "trd": NaN, "batb": [[1, 1.18, 312.71]], "batl": [[2, 1.22, 116.45]]}, {"timestamp": 1631538818226, "ltp": 1.17, "tv": 8559.49, "trd": NaN, "batb": [[0, 1.18, 312.71], [1, 1.17, 342.01], [2, 1.16, 33.4]], "batl": [[0, 1.2, 289.19]]}, {"timestamp": 1631538819186, "ltp": 1.17, "tv": 8559.49, "trd": NaN, "batb": NaN, "batl": [[1, 1.21, 388.85]]}, {"timestamp": 1631538820720, "ltp": 1.17, "tv": 8559.49, "trd": NaN, "batb": NaN, "batl": [[2, 1.22, 315.11]]}, {"timestamp": 1631538821517, "ltp": 1.17, "tv": 8559.49, "trd": NaN, "batb": [[0, 1.19, 17.49], [1, 1.18, 312.71], [2, 1.17, 342.01]], "batl": [[0, 1.2, 298.72], [2, 1.22, 116.45]]}, {"timestamp": 1631538822421, "ltp": 1.17, "tv": 8559.49, "trd": NaN, "batb": [[1, 1.18, 405.71]], "batl": NaN}, {"timestamp": 1631538822999, "ltp": 1.17, "tv": 8559.49, "trd": NaN, "batb": NaN, "batl": [[1, 1.21, 509.35]]}, {"timestamp": 1631538825402, "ltp": 1.17, "tv": 8559.49, "trd": NaN, "batb": [[1, 1.18, 312.71]], "batl": NaN}, {"timestamp": 1631538827795, "ltp": 1.17, "tv": 8559.49, "trd": NaN, "batb": [[0, 1.18, 263.99], [1, 1.17, 342.01], [2, 1.16, 138.28]], "batl": [[0, 1.2, 289.19], [2, 1.22, 108.25]]}, {"timestamp": 1631538828733, "ltp": 1.17, "tv": 8559.49, "trd": NaN, "batb": [[0, 1.15, 152.83], [1, 1.12, 297.08], [2, 1.1, 273.74]], "batl": [[0, 1.21, 125], [1, 1.22, 108.25], [2, 1.23, 97]]}, {"timestamp": 1631538831714, "ltp": 1.17, "tv": 8559.49, "trd": NaN, "batb": [[0, 1.15, 354.63], [1, 1.14, 400.65], [2, 1.12, 297.08]], "batl": [[2, 1.23, 311.77]]}, {"timestamp": 1631538838546, "ltp": 1.17, "tv": 8559.49, "trd": NaN, "batb": [[0, 1.16, 164.28], [1, 1.15, 354.63], [2, 1.14, 400.65]], "batl": [[0, 1.21, 252.5]]}, {"timestamp": 1631538838859, "ltp": 1.17, "tv": 8559.49, "trd": NaN, "batb": [[0, 1.15, 354.63], [1, 1.14, 400.65], [2, 1.12, 297.08]], "batl": [[0, 1.21, 125]]}, {"timestamp": 1631538841209, "ltp": 1.17, "tv": 8559.49, "trd": NaN, "batb": [[0, 1.15, 152.83], [1, 1.12, 297.08], [2, 1.1, 273.74]], "batl": NaN}, {"timestamp": 1631538842364, "ltp": 1.17, "tv": 8559.49, "trd": NaN, "batb": NaN, "batl": [[0, 1.22, 108.25], [1, 1.23, 311.77], [2, 1.24, 224.31]]}, {"timestamp": 1631538844841, "ltp": 1.17, "tv": 8559.49, "trd": NaN, "batb": [[0, 1.21, 99.81], [1, 1.2, 1203.02], [2, 1.18, 32.83]], "batl": [[1, 1.23, 335.54], [2, 1.24, 874.05]]}, {"timestamp": 1631538850774, "ltp": 1.17, "tv": 8559.49, "trd": NaN, "batb": [[2, 1.18, 156.19]], "batl": [[1, 1.23, 447.04], [2, 1.24, 981.53]]}, {"timestamp": 1631538852336, "ltp": 1.17, "tv": 8559.49, "trd": NaN, "batb": [[0, 1.21, 261.81]], "batl": NaN}, {"timestamp": 1631538855986, "ltp": 1.17, "tv": 8559.49, "trd": NaN, "batb": [[1, 1.2, 895.78]], "batl": NaN}, {"timestamp": 1631538858466, "ltp": 1.17, "tv": 8559.49, "trd": NaN, "batb": [[0, 1.21, 162], [1, 1.18, 123.36], [2, 1.16, 165.78]], "batl": [[0, 1.23, 97], [1, 1.24, 107.48], [2, 3.8, 27.46]]}, {"timestamp": 1631538859566, "ltp": 1.17, "tv": 8559.49, "trd": NaN, "batb": [[0, 1.16, 165.78], [1, 1.15, 388.08], [2, 1.1, 273.74]], "batl": NaN}, {"timestamp": 1631538861650, "ltp": 1.17, "tv": 8559.49, "trd": NaN, "batb": NaN, "batl": [[0, 1.23, 204.5]]}, {"timestamp": 1631538862796, "ltp": 1.17, "tv": 8559.49, "trd": NaN, "batb": [[0, 1.18, 149.36], [1, 1.17, 165.97], [2, 1.16, 165.78]], "batl": [[0, 1.23, 97], [1, 1.24, 648.43]]}, {"timestamp": 1631538863366, "ltp": 1.17, "tv": 8559.49, "trd": NaN, "batb": [[0, 1.2, 254.42], [1, 1.19, 313.22]], "batl": [[0, 1.22, 98.55], [1, 1.23, 336.17], [2, 1.24, 107.48]]}, {"timestamp": 1631538865186, "ltp": 1.17, "tv": 8559.49, "trd": NaN, "batb": NaN, "batl": [[1, 1.23, 458.67]]}, {"timestamp": 1631538866279, "ltp": 1.17, "tv": 8559.49, "trd": NaN, "batb": [[2, 1.18, 140.36]], "batl": NaN}, {"timestamp": 1631538868576, "ltp": 1.17, "tv": 8559.49, "trd": NaN, "batb": [[0, 1.18, 140.36], [1, 1.16, 165.78], [2, 1.15, 388.08]], "batl": [[0, 1.23, 219.5], [1, 1.24, 107.48], [2, 1.26, 108]]}, {"timestamp": 1631538869511, "ltp": 1.17, "tv": 8559.49, "trd": NaN, "batb": [[0, 1.2, 84]], "batl": [[0, 1.23, 97]]}, {"timestamp": 1631538869987, "ltp": 1.17, "tv": 8559.49, "trd": NaN, "batb": [[0, 1.16, 165.78], [1, 1.15, 388.08], [2, 1.1, 273.74]], "batl": NaN}, {"timestamp": 1631538871705, "ltp": 1.23, "tv": 8559.89, "trd": [[1.23, 0.4]], "batb": [[0, 1.18, 326.14], [1, 1.17, 259.8], [2, 1.16, 165.78]], "batl": [[0, 1.23, 96.6], [2, 1.25, 214.61]]}, {"timestamp": 1631538872284, "ltp": 1.23, "tv": 8559.89, "trd": NaN, "batb": [[0, 1.18, 454], [1, 1.17, 417.77]], "batl": [[2, 1.26, 108]]}, {"timestamp": 1631538872909, "ltp": 1.23, "tv": 8559.89, "trd": NaN, "batb": NaN, "batl": [[0, 1.21, 212.91], [1, 1.23, 96.6], [2, 1.24, 107.48]]}, {"timestamp": 1631538875716, "ltp": 1.23, "tv": 8559.89, "trd": NaN, "batb": [[0, 1.18, 1416.91], [2, 1.16, 190.56]], "batl": [[0, 1.2, 308.25], [1, 1.21, 521.46], [2, 1.22, 8.2]]}, {"timestamp": 1631538876402, "ltp": 1.23, "tv": 8559.89, "trd": NaN, "batb": [[2, 1.16, 199.18]], "batl": NaN}, {"timestamp": 1631538880293, "ltp": 1.23, "tv": 8559.89, "trd": NaN, "batb": [[0, 1.19, 191], [1, 1.18, 1416.91], [2, 1.17, 417.77]], "batl": NaN}, {"timestamp": 1631538887201, "ltp": 1.23, "tv": 8559.89, "trd": NaN, "batb": NaN, "batl": [[0, 1.2, 94.79]]}, {"timestamp": 1631538892340, "ltp": 1.23, "tv": 8559.89, "trd": NaN, "batb": [[1, 1.18, 1368.19]], "batl": NaN}, {"timestamp": 1631538895664, "ltp": 1.23, "tv": 8559.89, "trd": NaN, "batb": [[1, 1.16, 165.78], [2, 1.15, 152.83]], "batl": [[0, 1.21, 212.91], [1, 1.23, 193.1], [2, 1.24, 107.48]]}, {"timestamp": 1631538896447, "ltp": 1.23, "tv": 8559.89, "trd": NaN, "batb": [[0, 1.16, 165.78], [1, 1.15, 152.83], [2, 1.14, 196.32]], "batl": NaN}, {"timestamp": 1631538896853, "ltp": 1.23, "tv": 8559.89, "trd": NaN, "batb": [[0, 1.14, 196.32], [1, 1.12, 300.76], [2, 1.1, 273.74]], "batl": NaN}, {"timestamp": 1631538898267, "ltp": 1.23, "tv": 8559.89, "trd": NaN, "batb": [[0, 1.15, 112.58], [1, 1.14, 634.26], [2, 1.12, 300.76]], "batl": [[2, 1.24, 376.23]]}, {"timestamp": 1631538899829, "ltp": 1.23, "tv": 8559.89, "trd": NaN, "batb": [[0, 1.2, 210.52], [1, 1.15, 112.58], [2, 1.14, 634.26]], "batl": [[2, 1.24, 107.48]]}, {"timestamp": 1631538900760, "ltp": 1.23, "tv": 8559.89, "trd": NaN, "batb": [[0, 1.2, 210.71], [1, 1.16, 151.28], [2, 1.15, 277.21]], "batl": NaN}, {"timestamp": 1631538902655, "ltp": 1.2, "tv": 8981.3, "trd": [[1.2, 1711.61]], "batb": [[0, 1.16, 151.28], [1, 1.15, 277.21], [2, 1.14, 634.26]], "batl": [[0, 1.17, 2870.74], [1, 1.18, 1161.11], [2, 1.19, 8.4]]}, {"timestamp": 1631538903755, "ltp": 1.2, "tv": 8981.3, "trd": NaN, "batb": [[0, 1.15, 112.58], [1, 1.14, 684.69], [2, 1.13, 8.85]], "batl": [[0, 1.17, 696.27], [1, 1.18, 1338.24]]}, {"timestamp": 1631538907651, "ltp": 1.2, "tv": 8981.3, "trd": NaN, "batb": NaN, "batl": [[2, 1.19, 275.11]]}, {"timestamp": 1631538907875, "ltp": 1.2, "tv": 8981.3, "trd": NaN, "batb": NaN, "batl": [[2, 1.19, 8.4]]}, {"timestamp": 1631538910978, "ltp": 1.2, "tv": 8981.3, "trd": NaN, "batb": [[0, 1.15, 248.58]], "batl": NaN}, {"timestamp": 1631538912491, "ltp": 1.17, "tv": 8981.52, "trd": [[1.17, 302.4]], "batb": NaN, "batl": [[0, 1.17, 696.05]]}, {"timestamp": 1631538914680, "ltp": 1.17, "tv": 8981.52, "trd": NaN, "batb": NaN, "batl": [[0, 1.17, 455.71]]}, {"timestamp": 1631538918784, "ltp": 1.17, "tv": 8981.52, "trd": NaN, "batb": [[0, 1.15, 136], [1, 1.14, 246.75], [2, 1.12, 326.42]], "batl": [[0, 1.2, 225.38], [1, 1.21, 338.41], [2, 1.23, 193.1]]}, {"timestamp": 1631538919562, "ltp": 1.17, "tv": 8981.52, "trd": NaN, "batb": [[0, 1.09, 243.61], [1, 1.08, 415.7], [2, 1.01, 115.38]], "batl": [[0, 1.2, 108]]}, {"timestamp": 1631538921796, "ltp": 1.17, "tv": 8981.52, "trd": NaN, "batb": [[0, 1.11, 94.54], [1, 1.1, 530.8], [2, 1.09, 243.61]], "batl": [[0, 1.2, 266.65], [1, 1.21, 602.68]]}, {"timestamp": 1631538922788, "ltp": 1.17, "tv": 8981.52, "trd": NaN, "batb": [[0, 1.11, 201.59], [1, 1.1, 261.14]], "batl": [[0, 1.2, 241.13], [1, 1.21, 338.41]]}, {"timestamp": 1631538923481, "ltp": 1.17, "tv": 8982.06, "trd": [[1.17, 302.94]], "batb": [[0, 1.14, 187.8], [1, 1.13, 420.11]], "batl": [[0, 1.16, 393.07], [1, 1.17, 198.48], [2, 1.2, 108]]}, {"timestamp": 1631538926698, "ltp": 1.17, "tv": 8982.06, "trd": NaN, "batb": [[0, 1.09, 243.61], [1, 1.08, 415.7], [2, 1.01, 115.38]], "batl": [[0, 1.2, 108], [1, 1.21, 338.41], [2, 1.23, 193.1]]}, {"timestamp": 1631538929519, "ltp": 1.17, "tv": 8982.06, "trd": NaN, "batb": [[0, 1.11, 94.86], [1, 1.1, 530.48], [2, 1.09, 243.61]], "batl": [[2, 1.23, 96.6]]}, {"timestamp": 1631538930725, "ltp": 1.17, "tv": 8982.06, "trd": NaN, "batb": [[1, 1.1, 803.92]], "batl": NaN}, {"timestamp": 1631538931797, "ltp": 1.17, "tv": 8982.06, "trd": NaN, "batb": [[1, 1.1, 1785.52]], "batl": [[0, 1.12, 226.1], [1, 1.13, 385.47], [2, 1.14, 1760.59]]}, {"timestamp": 1631538932693, "ltp": 1.17, "tv": 8982.06, "trd": NaN, "batb": [[1, 1.1, 1794.61]], "batl": NaN}, {"timestamp": 1631538939822, "ltp": 1.17, "tv": 8982.06, "trd": NaN, "batb": [[0, 1.11, 239.86], [1, 1.1, 1757.93]], "batl": [[0, 1.12, 190.1]]}, {"timestamp": 1631538942714, "ltp": 1.17, "tv": 8982.06, "trd": NaN, "batb": [[0, 1.11, 276.2]], "batl": [[1, 1.13, 421.15]]}, {"timestamp": 1631538946630, "ltp": 1.17, "tv": 8982.06, "trd": NaN, "batb": [[1, 1.1, 1742.36]], "batl": [[0, 1.12, 174.82]]}, {"timestamp": 1631538947046, "ltp": 1.11, "tv": 8986.06, "trd": [[1.11, 4]], "batb": [[0, 1.11, 274.2]], "batl": NaN}, {"timestamp": 1631538948626, "ltp": 1.12, "tv": 8994.0, "trd": [[1.12, 7.94]], "batb": NaN, "batl": [[0, 1.12, 170.85]]}, {"timestamp": 1631538949523, "ltp": 1.12, "tv": 8994.0, "trd": NaN, "batb": [[0, 1.11, 289.63], [1, 1.1, 1690.1]], "batl": [[1, 1.13, 436.3]]}, {"timestamp": 1631538954145, "ltp": 1.12, "tv": 9001.39, "trd": [[1.12, 15.33]], "batb": NaN, "batl": [[0, 1.12, 163.46]]}, {"timestamp": 1631538956439, "ltp": 1.11, "tv": 9001.93, "trd": [[1.11, 4.16], [1.12, 15.71]], "batb": [[0, 1.11, 289.55]], "batl": [[0, 1.12, 163.27]]}, {"timestamp": 1631538958958, "ltp": 1.11, "tv": 9001.93, "trd": NaN, "batb": [[1, 1.1, 1736.03]], "batl": [[0, 1.12, 220.88]]}, {"timestamp": 1631538966477, "ltp": 1.11, "tv": 9001.93, "trd": NaN, "batb": [[1, 1.1, 1715.51]], "batl": NaN}, {"timestamp": 1631538969712, "ltp": 1.12, "tv": 9002.67, "trd": [[1.12, 16.45]], "batb": [[0, 1.11, 145], [1, 1.1, 1257.8]], "batl": [[0, 1.12, 57.24], [1, 1.14, 1760.59], [2, 1.15, 8.7]]}, {"timestamp": 1631538970395, "ltp": 1.12, "tv": 9002.67, "trd": NaN, "batb": [[0, 1.07, 906.17], [1, 1.06, 378.58], [2, 1.04, 1266.91]], "batl": [[0, 1.17, 127], [1, 1.18, 137.25], [2, 1.19, 147.5]]}, {"timestamp": 1631538971819, "ltp": 1.12, "tv": 9002.67, "trd": NaN, "batb": [[1, 1.06, 1028.41]], "batl": [[0, 1.17, 527.91], [1, 1.18, 323.48]]}, {"timestamp": 1631538971972, "ltp": 1.12, "tv": 9002.67, "trd": NaN, "batb": [[1, 1.06, 378.58]], "batl": [[0, 1.17, 127], [1, 1.18, 137.25]]}, {"timestamp": 1631538973804, "ltp": 1.12, "tv": 9002.67, "trd": NaN, "batb": [[0, 1.04, 1266.91], [1, 1.01, 115.38], [2, 1.04, 0]], "batl": NaN}, {"timestamp": 1631538974779, "ltp": 1.12, "tv": 9002.67, "trd": NaN, "batb": [[0, 1.1, 227.8], [1, 1.09, 402.05], [2, 1.04, 1266.91]], "batl": [[0, 1.11, 150.68], [1, 1.12, 484.39], [2, 1.17, 127]]}, {"timestamp": 1631538975300, "ltp": 1.12, "tv": 9002.67, "trd": NaN, "batb": NaN, "batl": [[1, 1.12, 465.68]]}, {"timestamp": 1631538977725, "ltp": 1.12, "tv": 9002.67, "trd": NaN, "batb": [[2, 1.06, 1394.21]], "batl": [[2, 1.17, 273.5]]}, {"timestamp": 1631538980528, "ltp": 1.12, "tv": 9002.67, "trd": NaN, "batb": [[0, 1.06, 1394.21], [1, 1.04, 1266.91], [2, 1.02, 1066.3]], "batl": [[0, 1.17, 127], [1, 1.18, 137.25], [2, 1.19, 147.5]]}, {"timestamp": 1631538983722, "ltp": 1.12, "tv": 9002.67, "trd": NaN, "batb": [[0, 1.06, 2044.04]], "batl": [[0, 1.17, 679.41], [1, 1.18, 323.48]]}, {"timestamp": 1631538990756, "ltp": 1.12, "tv": 9002.67, "trd": NaN, "batb": NaN, "batl": [[0, 1.17, 127], [1, 1.2, 108], [2, 1.21, 212.91]]}, {"timestamp": 1631538991859, "ltp": 1.12, "tv": 9002.67, "trd": NaN, "batb": [[0, 1.06, 1075.41]], "batl": NaN}, {"timestamp": 1631538993444, "ltp": 1.12, "tv": 9002.67, "trd": NaN, "batb": [[1, 1.05, 54.75], [2, 1.04, 1266.91]], "batl": [[0, 1.08, 637.8], [1, 1.09, 2049.75], [2, 1.1, 9.09]]}, {"timestamp": 1631538994441, "ltp": 1.12, "tv": 9002.67, "trd": NaN, "batb": [[0, 1.06, 1076.71], [1, 1.05, 64.27]], "batl": NaN}, {"timestamp": 1631538999636, "ltp": 1.12, "tv": 9002.67, "trd": NaN, "batb": [[0, 1.06, 1149.71]], "batl": NaN}, {"timestamp": 1631539000532, "ltp": 1.12, "tv": 9002.67, "trd": NaN, "batb": [[1, 1.05, 627.36]], "batl": NaN}, {"timestamp": 1631539001419, "ltp": 1.12, "tv": 9002.67, "trd": NaN, "batb": [[0, 1.06, 1076.71]], "batl": NaN}, {"timestamp": 1631539002626, "ltp": 1.08, "tv": 9288.57, "trd": [[1.08, 285.9]], "batb": NaN, "batl": [[0, 1.08, 351.9]]}, {"timestamp": 1631539004451, "ltp": 1.08, "tv": 9289.49, "trd": [[1.08, 286.82]], "batb": [[0, 1.07, 253], [1, 1.06, 1076.71], [2, 1.05, 627.36]], "batl": [[0, 1.08, 351.44]]}, {"timestamp": 1631539005655, "ltp": 1.08, "tv": 9289.49, "trd": NaN, "batb": NaN, "batl": [[0, 1.08, 637.34]]}, {"timestamp": 1631539006654, "ltp": 1.08, "tv": 9289.49, "trd": NaN, "batb": [[1, 1.06, 1075.41]], "batl": NaN}, {"timestamp": 1631539008755, "ltp": 1.08, "tv": 9329.49, "trd": [[1.08, 326.82]], "batb": NaN, "batl": [[0, 1.08, 617.34]]}, {"timestamp": 1631539009847, "ltp": 1.08, "tv": 9332.09, "trd": [[1.08, 329.42]], "batb": NaN, "batl": [[0, 1.08, 616.04]]}, {"timestamp": 1631539011851, "ltp": 1.08, "tv": 9595.23, "trd": [[1.08, 592.56]], "batb": NaN, "batl": [[0, 1.08, 504.93]]}, {"timestamp": 1631539012065, "ltp": 1.08, "tv": 9599.09, "trd": [[1.08, 596.42]], "batb": NaN, "batl": [[0, 1.08, 503]]}, {"timestamp": 1631539014782, "ltp": 1.08, "tv": 9599.09, "trd": NaN, "batb": NaN, "batl": [[0, 1.08, 602.01]]}, {"timestamp": 1631539014940, "ltp": 1.08, "tv": 9599.47, "trd": [[1.08, 596.8]], "batb": NaN, "batl": [[0, 1.08, 601.82]]}, {"timestamp": 1631539016367, "ltp": 1.08, "tv": 9699.47, "trd": [[1.08, 696.8]], "batb": NaN, "batl": [[0, 1.08, 551.82]]}, {"timestamp": 1631539019382, "ltp": 1.08, "tv": 9699.47, "trd": NaN, "batb": NaN, "batl": [[0, 1.08, 575.14]]}, {"timestamp": 1631539023758, "ltp": 1.08, "tv": 9699.47, "trd": NaN, "batb": [[2, 1.05, 617.84]], "batl": [[2, 1.11, 232.5]]}, {"timestamp": 1631539024694, "ltp": 1.08, "tv": 9699.47, "trd": NaN, "batb": [[1, 1.06, 425.58], [2, 1.05, 563.09]], "batl": [[0, 1.13, 171.5], [1, 1.21, 14.82], [2, 1.23, 29.65]]}, {"timestamp": 1631539025486, "ltp": 1.08, "tv": 9699.47, "trd": NaN, "batb": [[0, 1.05, 563.09], [1, 1.03, 2474.74], [2, 1.02, 1066.3]], "batl": NaN}, {"timestamp": 1631539027685, "ltp": 1.08, "tv": 9699.47, "trd": NaN, "batb": [[0, 1.05, 1219.11]], "batl": [[0, 1.1, 271.21], [1, 1.11, 604.29], [2, 1.13, 171.5]]}, {"timestamp": 1631539028799, "ltp": 1.08, "tv": 9699.47, "trd": NaN, "batb": [[0, 1.06, 368.58], [1, 1.05, 1219.11], [2, 1.04, 703.87]], "batl": [[0, 1.21, 14.82], [1, 1.23, 29.65], [2, 1.25, 14.82]]}, {"timestamp": 1631539030717, "ltp": 1.06, "tv": 9809.53, "trd": [[1.06, 110.06]], "batb": [[0, 1.06, 313.55], [1, 1.05, 2260.75]], "batl": [[0, 1.07, 5694.55], [1, 1.09, 9.17], [2, 1.11, 51.79]]}, {"timestamp": 1631539031778, "ltp": 1.06, "tv": 9809.53, "trd": NaN, "batb": [[1, 1.05, 2346.47], [2, 1.04, 756.35]], "batl": [[0, 1.07, 2724.91]]}, {"timestamp": 1631539031919, "ltp": 1.06, "tv": 9809.53, "trd": NaN, "batb": [[1, 1.05, 2289.33], [2, 1.04, 727.77]], "batl": NaN}, {"timestamp": 1631539035683, "ltp": 1.07, "tv": 11561.95, "trd": [[1.07, 1752.42]], "batb": NaN, "batl": [[0, 1.07, 1848.7]]}, {"timestamp": 1631539037103, "ltp": 1.07, "tv": 11561.95, "trd": NaN, "batb": NaN, "batl": [[1, 1.09, 280.67], [2, 1.1, 215.55]]}, {"timestamp": 1631539039308, "ltp": 1.07, "tv": 11561.95, "trd": NaN, "batb": [[0, 1.06, 423.55]], "batl": NaN}, {"timestamp": 1631539040732, "ltp": 1.06, "tv": 11591.95, "trd": [[1.06, 140.06]], "batb": [[0, 1.06, 408.55]], "batl": NaN}, {"timestamp": 1631539043719, "ltp": 1.06, "tv": 11591.95, "trd": NaN, "batb": [[1, 1.05, 2369.29]], "batl": [[0, 1.07, 1962.93]]}, {"timestamp": 1631539044820, "ltp": 1.07, "tv": 11644.57, "trd": [[1.07, 1805.04]], "batb": [[0, 1.06, 110], [1, 1.04, 703.87], [2, 1.03, 914.83]], "batl": [[0, 1.09, 271.5], [1, 1.1, 215.55], [2, 1.11, 232.5]]}, {"timestamp": 1631539045713, "ltp": 1.07, "tv": 11644.57, "trd": NaN, "batb": [[0, 1.04, 703.87], [1, 1.02, 4382.27], [2, 1.01, 115.38]], "batl": [[0, 1.1, 215.55], [1, 1.19, 14.82], [2, 1.21, 14.82]]}, {"timestamp": 1631539047527, "ltp": 1.07, "tv": 11644.57, "trd": NaN, "batb": [[0, 1.04, 1366.2]], "batl": [[0, 1.08, 199.33], [1, 1.09, 434.44], [2, 1.1, 215.55]]}, {"timestamp": 1631539048319, "ltp": 1.07, "tv": 11644.57, "trd": NaN, "batb": NaN, "batl": [[1, 1.09, 699.94]]}, {"timestamp": 1631539048893, "ltp": 1.07, "tv": 11644.57, "trd": NaN, "batb": [[1, 1.03, 791.83], [2, 1.02, 4382.27]], "batl": NaN}, {"timestamp": 1631539061833, "ltp": 1.07, "tv": 11644.57, "trd": NaN, "batb": NaN, "batl": [[0, 1.09, 265.5], [1, 1.1, 215.55], [2, 1.19, 14.82]]}, {"timestamp": 1631539062048, "ltp": 1.07, "tv": 11644.57, "trd": NaN, "batb": [[0, 1.05, 499.09], [1, 1.04, 1366.2], [2, 1.03, 791.83]], "batl": NaN}, {"timestamp": 1631539064654, "ltp": 1.07, "tv": 11644.57, "trd": NaN, "batb": [[1, 1.04, 3001.48]], "batl": [[0, 1.06, 4809.73], [1, 1.07, 3481.37], [2, 1.08, 9.26]]}, {"timestamp": 1631539065761, "ltp": 1.07, "tv": 11644.57, "trd": NaN, "batb": [[2, 1.03, 801.54]], "batl": [[0, 1.06, 1133.86]]}, {"timestamp": 1631539070953, "ltp": 1.07, "tv": 11644.57, "trd": NaN, "batb": NaN, "batl": [[1, 1.07, 3887.87], [2, 1.08, 316.95]]}, {"timestamp": 1631539072675, "ltp": 1.07, "tv": 11644.57, "trd": NaN, "batb": [[0, 1.05, 658.09]], "batl": NaN}, {"timestamp": 1631539076484, "ltp": 1.07, "tv": 11644.57, "trd": NaN, "batb": NaN, "batl": [[0, 1.06, 812.46]]}, {"timestamp": 1631539076965, "ltp": 1.06, "tv": 11644.87, "trd": [[1.06, 140.36]], "batb": NaN, "batl": [[0, 1.06, 812.31]]}, {"timestamp": 1631539087212, "ltp": 1.06, "tv": 11644.87, "trd": NaN, "batb": [[1, 1.04, 2909.57]], "batl": [[0, 1.06, 665.58]]}, {"timestamp": 1631539090071, "ltp": 1.06, "tv": 11644.87, "trd": NaN, "batb": [[1, 1.04, 3001.55]], "batl": [[0, 1.06, 812.31]]}, {"timestamp": 1631539093803, "ltp": 1.06, "tv": 11644.87, "trd": NaN, "batb": [[0, 1.05, 159], [1, 1.04, 1003.97], [2, 1.03, 791.83]], "batl": [[0, 1.08, 307.69], [1, 1.17, 29.65], [2, 1.19, 14.82]]}, {"timestamp": 1631539094395, "ltp": 1.06, "tv": 11644.87, "trd": NaN, "batb": [[0, 1.04, 1003.97], [1, 1.03, 791.83], [2, 1.02, 3280.14]], "batl": NaN}, {"timestamp": 1631539099599, "ltp": 1.06, "tv": 11644.87, "trd": NaN, "batb": NaN, "batl": [[0, 1.06, 21.75], [1, 1.08, 307.69], [2, 1.17, 29.65]]}, {"timestamp": 1631539100285, "ltp": 1.06, "tv": 11644.87, "trd": NaN, "batb": [[0, 1.04, 1366.2]], "batl": [[0, 1.06, 649.83], [1, 1.07, 372.5], [2, 1.08, 307.69]]}, {"timestamp": 1631539102603, "ltp": 1.06, "tv": 11644.87, "trd": NaN, "batb": [[0, 1.04, 1417.2]], "batl": NaN}, {"timestamp": 1631539106615, "ltp": 1.06, "tv": 11644.87, "trd": NaN, "batb": [[0, 1.04, 1003.97]], "batl": [[0, 1.07, 372.5], [1, 1.08, 307.69], [2, 1.09, 268.5]]}, {"timestamp": 1631539106931, "ltp": 1.06, "tv": 11644.87, "trd": NaN, "batb": NaN, "batl": [[0, 1.08, 307.69], [1, 1.17, 29.65], [2, 1.19, 14.82]]}, {"timestamp": 1631539109619, "ltp": 1.06, "tv": 11644.87, "trd": NaN, "batb": [[0, 1.05, 258], [1, 1.04, 1003.97], [2, 1.03, 1157.57]], "batl": [[0, 1.07, 643.76], [1, 1.08, 307.69], [2, 1.17, 29.65]]}, {"timestamp": 1631539110145, "ltp": 1.06, "tv": 11644.87, "trd": NaN, "batb": NaN, "batl": [[0, 1.07, 961.26], [2, 1.09, 294.5]]}, {"timestamp": 1631539116414, "ltp": 1.06, "tv": 11644.87, "trd": NaN, "batb": [[0, 1.04, 1003.97], [1, 1.03, 1157.57], [2, 1.02, 3280.14]], "batl": NaN}, {"timestamp": 1631539117261, "ltp": 1.04, "tv": 11647.41, "trd": [[1.04, 2.54]], "batb": [[0, 1.04, 1002.7]], "batl": NaN}, {"timestamp": 1631539123131, "ltp": 1.04, "tv": 11647.41, "trd": NaN, "batb": NaN, "batl": [[0, 1.06, 6.57], [1, 1.07, 961.26], [2, 1.08, 307.69]]}, {"timestamp": 1631539124663, "ltp": 1.04, "tv": 11647.41, "trd": NaN, "batb": NaN, "batl": [[1, 1.07, 317.5], [2, 1.17, 29.65]]}, {"timestamp": 1631539126060, "ltp": 1.04, "tv": 11647.41, "trd": NaN, "batb": [[2, 1.02, 1066.3]], "batl": NaN}, {"timestamp": 1631539127684, "ltp": 1.04, "tv": 11647.41, "trd": NaN, "batb": [[2, 1.02, 1122.66]], "batl": [[0, 1.05, 1047.72], [1, 1.06, 3500.19], [2, 1.07, 326.85]]}, {"timestamp": 1631539128475, "ltp": 1.04, "tv": 11647.41, "trd": NaN, "batb": [[1, 1.03, 1167.28]], "batl": NaN}, {"timestamp": 1631539131253, "ltp": 1.04, "tv": 11647.41, "trd": NaN, "batb": [[0, 1.04, 1125.7]], "batl": NaN}, {"timestamp": 1631539138592, "ltp": 1.05, "tv": 11647.79, "trd": [[1.05, 0.38]], "batb": NaN, "batl": [[0, 1.05, 1047.53]]}, {"timestamp": 1631539139493, "ltp": 1.05, "tv": 11649.33, "trd": [[1.05, 1.92]], "batb": NaN, "batl": [[0, 1.05, 720.49]]}, {"timestamp": 1631539144711, "ltp": 1.04, "tv": 11658.01, "trd": [[1.04, 11.21]], "batb": [[0, 1.04, 1121.36], [2, 1.02, 1066.3]], "batl": NaN}, {"timestamp": 1631539145611, "ltp": 1.05, "tv": 11711.24, "trd": [[1.05, 55.15]], "batb": NaN, "batl": [[0, 1.05, 693.87]]}, {"timestamp": 1631539148607, "ltp": 1.05, "tv": 11711.24, "trd": NaN, "batb": [[0, 1.04, 123], [1, 1.03, 365.74], [2, 1.01, 4237.26]], "batl": [[0, 1.06, 6.57], [1, 1.07, 317.5], [2, 1.08, 268.94]]}, {"timestamp": 1631539149287, "ltp": 1.05, "tv": 11711.24, "trd": NaN, "batb": [[0, 1.03, 365.74], [1, 1.01, 4237.26], [2, 1.01, 0]], "batl": NaN}, {"timestamp": 1631539150800, "ltp": 1.05, "tv": 11711.24, "trd": NaN, "batb": [[0, 1.03, 177.32]], "batl": NaN}, {"timestamp": 1631539153793, "ltp": 1.07, "tv": 11728.28, "trd": [[1.06, 153.5], [1.07, 1808.94]], "batb": [[0, 1.04, 486.71], [1, 1.03, 177.32], [2, 1.01, 4237.26]], "batl": [[0, 1.05, 656.02], [1, 1.06, 19.25], [2, 1.07, 315.55]]}, {"timestamp": 1631539154002, "ltp": 1.07, "tv": 11728.28, "trd": NaN, "batb": NaN, "batl": [[1, 1.07, 315.55], [2, 1.08, 268.94]]}, {"timestamp": 1631539155728, "ltp": 1.07, "tv": 11728.28, "trd": NaN, "batb": NaN, "batl": [[1, 1.06, 440.25], [2, 1.07, 315.55]]}, {"timestamp": 1631539158898, "ltp": 1.07, "tv": 11728.28, "trd": NaN, "batb": [[0, 1.04, 580.71]], "batl": NaN}, {"timestamp": 1631539160835, "ltp": 1.07, "tv": 11728.28, "trd": NaN, "batb": [[0, 1.04, 94]], "batl": [[0, 1.06, 440.25], [1, 1.07, 315.55], [2, 1.08, 268.94]]}, {"timestamp": 1631539161415, "ltp": 1.07, "tv": 11728.28, "trd": NaN, "batb": [[0, 1.03, 177.32], [1, 1.01, 4237.26], [2, 1.01, 0]], "batl": [[0, 1.07, 315.55], [1, 1.08, 268.94], [2, 1.15, 14.82]]}, {"timestamp": 1631539163827, "ltp": 1.07, "tv": 11728.28, "trd": NaN, "batb": [[0, 1.03, 668.76]], "batl": [[0, 1.06, 649.83], [1, 1.07, 315.55], [2, 1.08, 268.94]]}, {"timestamp": 1631539164315, "ltp": 1.07, "tv": 11728.28, "trd": NaN, "batb": NaN, "batl": [[0, 1.06, 1063.58]]}, {"timestamp": 1631539167608, "ltp": 1.07, "tv": 11728.28, "trd": NaN, "batb": NaN, "batl": [[0, 1.06, 413.75], [1, 1.15, 14.82], [2, 1.17, 29.65]]}, {"timestamp": 1631539168545, "ltp": 1.07, "tv": 11728.28, "trd": NaN, "batb": [[1, 1.01, 115.38]], "batl": NaN}, {"timestamp": 1631539170743, "ltp": 1.07, "tv": 11728.28, "trd": NaN, "batb": [[1, 1.01, 200.77]], "batl": [[0, 1.04, 160.67], [1, 1.05, 2281.44], [2, 1.06, 413.75]]}, {"timestamp": 1631539171529, "ltp": 1.07, "tv": 11728.28, "trd": NaN, "batb": [[1, 1.02, 9.8], [2, 1.01, 200.77]], "batl": NaN}, {"timestamp": 1631539172635, "ltp": 1.07, "tv": 11728.28, "trd": NaN, "batb": [[2, 1.01, 4131.03]], "batl": NaN}, {"timestamp": 1631539175631, "ltp": 1.04, "tv": 11826.78, "trd": [[1.04, 109.71]], "batb": NaN, "batl": [[0, 1.04, 62.17]]}, {"timestamp": 1631539178845, "ltp": 1.03, "tv": 11831.46, "trd": [[1.03, 4.68]], "batb": [[0, 1.03, 666.42]], "batl": [[0, 1.04, 104.97], [1, 1.05, 2336.6]]}, {"timestamp": 1631539180845, "ltp": 1.03, "tv": 12786.64, "trd": [[1.03, 659.86], [1.04, 409.71]], "batb": [[0, 1.03, 338.83]], "batl": [[0, 1.05, 2336.6], [1, 1.06, 413.75], [2, 1.07, 9.35]]}, {"timestamp": 1631539181464, "ltp": 1.03, "tv": 12786.64, "trd": NaN, "batb": NaN, "batl": [[0, 1.05, 2215.08]]}, {"timestamp": 1631539182462, "ltp": 1.03, "tv": 12786.64, "trd": NaN, "batb": NaN, "batl": [[0, 1.05, 1885.79]]}, {"timestamp": 1631539183766, "ltp": 1.05, "tv": 14785.3, "trd": [[1.05, 2053.81]], "batb": NaN, "batl": [[0, 1.05, 990.44]]}, {"timestamp": 1631539184351, "ltp": 1.04, "tv": 14807.8, "trd": [[1.04, 432.21]], "batb": [[0, 1.03, 669.93]], "batl": [[0, 1.04, 205.17], [1, 1.05, 886.46], [2, 1.06, 413.75]]}, {"timestamp": 1631539185761, "ltp": 1.04, "tv": 15218.14, "trd": [[1.04, 842.55]], "batb": [[0, 1.04, 303.83], [1, 1.03, 669.93], [2, 1.02, 9.8]], "batl": [[0, 1.05, 886.46], [1, 1.06, 413.75], [2, 1.07, 9.35]]}, {"timestamp": 1631539187556, "ltp": 1.04, "tv": 15218.14, "trd": NaN, "batb": NaN, "batl": [[0, 1.05, 898.77]]}, {"timestamp": 1631539188652, "ltp": 1.04, "tv": 15421.86, "trd": [[1.04, 1046.27]], "batb": [[0, 1.04, 201.97]], "batl": [[0, 1.05, 1011.07]]}, {"timestamp": 1631539191873, "ltp": 1.04, "tv": 15421.86, "trd": NaN, "batb": NaN, "batl": [[0, 1.05, 1111.96]]}, {"timestamp": 1631539194291, "ltp": 1.04, "tv": 15825.8, "trd": [[1.04, 1450.21]], "batb": [[0, 1.03, 669.93], [1, 1.02, 9.8], [2, 1.01, 4131.03]], "batl": [[0, 1.04, 298.03], [1, 1.05, 1111.96], [2, 1.06, 413.75]]}, {"timestamp": 1631539194979, "ltp": 1.04, "tv": 15827.66, "trd": [[1.04, 1452.07]], "batb": NaN, "batl": [[0, 1.04, 297.1]]}, {"timestamp": 1631539196670, "ltp": 1.04, "tv": 15827.66, "trd": NaN, "batb": NaN, "batl": [[0, 1.04, 2304.29]]}, {"timestamp": 1631539197403, "ltp": 1.04, "tv": 16441.72, "trd": [[1.04, 2066.13]], "batb": NaN, "batl": [[0, 1.04, 1997.26], [1, 1.05, 1137.44]]}, {"timestamp": 1631539201313, "ltp": 1.04, "tv": 17614.26, "trd": [[1.04, 3238.67]], "batb": NaN, "batl": [[0, 1.04, 1410.99]]}, {"timestamp": 1631539230035, "ltp": 1.04, "tv": 17623.92, "trd": [[1.04, 3248.33]], "batb": NaN, "batl": [[0, 1.04, 1401.33]]}, {"timestamp": 1631539233241, "ltp": 1.04, "tv": 18567.74, "trd": [[1.04, 4192.15]], "batb": NaN, "batl": [[0, 1.04, 929.42]]}, {"timestamp": 1631539249558, "ltp": 1.04, "tv": 18567.74, "trd": NaN, "batb": NaN, "batl": [[0, 1.04, 930.41]]}, {"timestamp": 1631539257462, "ltp": 1.04, "tv": 18567.74, "trd": NaN, "batb": [[2, 1.01, 4045.65]], "batl": NaN}, {"timestamp": 1631539266581, "ltp": 1.04, "tv": 18567.74, "trd": NaN, "batb": [[0, 1.01, 4045.65], [1, 1.02, 0], [2, 1.01, 0]], "batl": [[1, 1.05, 278.82]]}, {"timestamp": 1631539268193, "ltp": 1.04, "tv": 18569.13, "trd": [[1.04, 4193.55]], "batb": NaN, "batl": [[0, 1.04, 929.71]]}, {"timestamp": 1631539272797, "ltp": 1.04, "tv": 18569.13, "trd": NaN, "batb": [[0, 1.03, 669.93], [1, 1.01, 4045.65]], "batl": [[0, 1.04, 1256], [1, 1.05, 333.97]]}, {"timestamp": 1631539279432, "ltp": 1.04, "tv": 18569.13, "trd": NaN, "batb": [[0, 1.01, 4045.65], [1, 1.01, 0]], "batl": [[0, 1.04, 929.71], [1, 1.05, 278.82]]}, {"timestamp": 1631539282341, "ltp": 1.04, "tv": 18569.13, "trd": NaN, "batb": [[0, 1.02, 676.49], [1, 1.01, 4045.65]], "batl": [[2, 1.06, 788.51]]}, {"timestamp": 1631539286723, "ltp": 1.04, "tv": 18569.13, "trd": NaN, "batb": NaN, "batl": [[1, 1.05, 244.01]]}, {"timestamp": 1631539289747, "ltp": 1.04, "tv": 18569.13, "trd": NaN, "batb": NaN, "batl": [[2, 1.06, 823]]}, {"timestamp": 1631539293733, "ltp": 1.04, "tv": 18569.13, "trd": NaN, "batb": [[0, 1.01, 4045.65], [1, 1.01, 0]], "batl": [[2, 1.06, 409.25]]}, {"timestamp": 1631539295521, "ltp": 1.04, "tv": 18569.13, "trd": NaN, "batb": [[0, 1.01, 115.38]], "batl": NaN}, {"timestamp": 1631539296615, "ltp": 1.04, "tv": 19498.84, "trd": [[1.04, 5123.26]], "batb": [[0, 1.04, 2256.64], [1, 1.03, 9.71], [2, 1.02, 56.36]], "batl": [[0, 1.05, 244.01], [1, 1.06, 2047.33], [2, 1.1, 52.26]]}, {"timestamp": 1631539297763, "ltp": 1.04, "tv": 19498.84, "trd": NaN, "batb": NaN, "batl": [[2, 1.08, 9.26]]}, {"timestamp": 1631539302555, "ltp": 1.04, "tv": 19498.84, "trd": NaN, "batb": [[0, 1.04, 2495.64]], "batl": NaN}, {"timestamp": 1631539302971, "ltp": 1.04, "tv": 19498.84, "trd": NaN, "batb": NaN, "batl": [[1, 1.06, 2465.58], [2, 1.07, 334.5]]}, {"timestamp": 1631539305578, "ltp": 1.04, "tv": 19498.84, "trd": NaN, "batb": NaN, "batl": [[0, 1.05, 213.12]]}, {"timestamp": 1631539308484, "ltp": 1.04, "tv": 19498.84, "trd": NaN, "batb": NaN, "batl": [[1, 1.06, 2496.17]]}, {"timestamp": 1631539316699, "ltp": 1.04, "tv": 19498.84, "trd": NaN, "batb": [[0, 1.04, 239], [1, 1.01, 4237.26], [2, 1.02, 0]], "batl": [[0, 1.06, 827.5], [1, 1.07, 334.5], [2, 1.08, 326.19]]}, {"timestamp": 1631539317384, "ltp": 1.04, "tv": 19498.84, "trd": NaN, "batb": [[0, 1.01, 4237.26], [1, 1.01, 0]], "batl": NaN}, {"timestamp": 1631539319833, "ltp": 1.04, "tv": 19498.84, "trd": NaN, "batb": NaN, "batl": [[1, 1.07, 582.23]]}, {"timestamp": 1631539319940, "ltp": 1.04, "tv": 19498.84, "trd": NaN, "batb": NaN, "batl": [[0, 1.06, 409.25], [1, 1.07, 247.73], [2, 1.11, 3.53]]}, {"timestamp": 1631539321016, "ltp": 1.04, "tv": 19498.84, "trd": NaN, "batb": [[0, 1.01, 115.38]], "batl": NaN}, {"timestamp": 1631539322630, "ltp": 1.04, "tv": 19498.84, "trd": NaN, "batb": [[0, 1.05, 1080.23], [1, 1.04, 294.35], [2, 1.03, 55.81]], "batl": [[1, 1.07, 2796.67], [2, 1.11, 55.32]]}, {"timestamp": 1631539323831, "ltp": 1.04, "tv": 19498.84, "trd": NaN, "batb": NaN, "batl": [[2, 1.08, 9.26]]}, {"timestamp": 1631539327714, "ltp": 1.05, "tv": 19521.56, "trd": [[1.05, 2076.54]], "batb": [[0, 1.05, 1068.87]], "batl": NaN}, {"timestamp": 1631539328296, "ltp": 1.05, "tv": 19521.56, "trd": NaN, "batb": [[0, 1.05, 1226.87]], "batl": NaN}, {"timestamp": 1631539329504, "ltp": 1.05, "tv": 19521.56, "trd": NaN, "batb": NaN, "batl": [[1, 1.07, 3117.17], [2, 1.08, 346.45]]}, {"timestamp": 1631539340425, "ltp": 1.05, "tv": 19524.97, "trd": [[1.05, 2079.94]], "batb": [[0, 1.05, 1225.17]], "batl": NaN}, {"timestamp": 1631539343718, "ltp": 1.05, "tv": 19524.97, "trd": NaN, "batb": [[0, 1.05, 158], [1, 1.04, 169.35], [2, 1.02, 2213.84]], "batl": [[0, 1.07, 568.23], [1, 1.08, 337.19], [2, 1.09, 269.5]]}, {"timestamp": 1631539344439, "ltp": 1.05, "tv": 19524.97, "trd": NaN, "batb": [[0, 1.04, 169.35], [1, 1.02, 2213.84], [2, 1.01, 21.7]], "batl": NaN}, {"timestamp": 1631539345743, "ltp": 1.05, "tv": 19524.97, "trd": NaN, "batb": NaN, "batl": [[0, 1.07, 97.18], [2, 1.11, 3.53]]}, {"timestamp": 1631539346421, "ltp": 1.05, "tv": 19524.97, "trd": NaN, "batb": [[0, 1.04, 352.1]], "batl": NaN}, {"timestamp": 1631539348551, "ltp": 1.05, "tv": 19524.97, "trd": NaN, "batb": [[0, 1.05, 308.41], [1, 1.04, 352.1], [2, 1.02, 2213.84]], "batl": [[0, 1.06, 552.86], [1, 1.07, 116.11], [2, 1.08, 337.19]]}, {"timestamp": 1631539349334, "ltp": 1.05, "tv": 19524.97, "trd": NaN, "batb": [[0, 1.05, 484.41]], "batl": [[1, 1.07, 407.68]]}, {"timestamp": 1631539352366, "ltp": 1.05, "tv": 19524.97, "trd": NaN, "batb": [[0, 1.04, 352.1], [1, 1.02, 2213.84], [2, 1.01, 21.7]], "batl": [[0, 1.07, 97.18], [1, 1.08, 337.19], [2, 1.11, 3.53]]}, {"timestamp": 1631539355439, "ltp": 1.05, "tv": 19524.97, "trd": NaN, "batb": [[0, 1.04, 663.48]], "batl": [[0, 1.07, 990.38], [2, 1.09, 282.5]]}, {"timestamp": 1631539357571, "ltp": 1.04, "tv": 20130.6, "trd": [[1.04, 5728.7], [1.06, 153.69]], "batb": [[0, 1.04, 360.76]], "batl": NaN}, {"timestamp": 1631539359666, "ltp": 1.04, "tv": 20130.6, "trd": NaN, "batb": [[0, 1.02, 2213.84], [1, 1.01, 21.7], [2, 1.01, 0]], "batl": NaN}, {"timestamp": 1631539361751, "ltp": 1.04, "tv": 20130.6, "trd": NaN, "batb": [[0, 1.01, 21.7], [1, 1.01, 0]], "batl": NaN}, {"timestamp": 1631539362846, "ltp": 1.04, "tv": 20130.6, "trd": NaN, "batb": [[0, 1.05, 2506.93], [1, 1.04, 52.48], [2, 1.03, 98.67]], "batl": [[0, 1.07, 1948.47], [1, 1.08, 390.5]]}, {"timestamp": 1631539363778, "ltp": 1.04, "tv": 20130.6, "trd": NaN, "batb": [[0, 1.05, 2449.79], [1, 1.04, 23.9], [2, 1.03, 70.09]], "batl": [[2, 1.09, 291.67]]}, {"timestamp": 1631539364561, "ltp": 1.06, "tv": 20247.98, "trd": [[1.06, 271.07]], "batb": NaN, "batl": [[0, 1.06, 828.79], [1, 1.07, 1948.47], [2, 1.08, 390.5]]}, {"timestamp": 1631539365287, "ltp": 1.06, "tv": 20247.98, "trd": NaN, "batb": [[2, 1.03, 1663.39]], "batl": NaN}, {"timestamp": 1631539366281, "ltp": 1.06, "tv": 21414.27, "trd": [[1.06, 1437.36]], "batb": NaN, "batl": [[0, 1.06, 245.65]]}, {"timestamp": 1631539371302, "ltp": 1.06, "tv": 21414.27, "trd": NaN, "batb": [[0, 1.05, 2746.79]], "batl": NaN}, {"timestamp": 1631539374762, "ltp": 1.06, "tv": 21414.27, "trd": NaN, "batb": NaN, "batl": [[2, 1.08, 350.3]]}, {"timestamp": 1631539377683, "ltp": 1.06, "tv": 21414.27, "trd": NaN, "batb": [[0, 1.05, 2832.51]], "batl": [[1, 1.07, 2056.98]]}, {"timestamp": 1631539381804, "ltp": 1.06, "tv": 21414.27, "trd": NaN, "batb": [[0, 1.05, 954.16], [1, 1.03, 1649.11], [2, 1.02, 1010.78]], "batl": [[1, 1.07, 990.38]]}, {"timestamp": 1631539382277, "ltp": 1.06, "tv": 21414.27, "trd": NaN, "batb": [[0, 1.05, 750.78], [1, 1.03, 1593.3]], "batl": [[1, 1.07, 762.75]]}, {"timestamp": 1631539383518, "ltp": 1.06, "tv": 21414.27, "trd": NaN, "batb": [[0, 1.05, 453.78]], "batl": NaN}, {"timestamp": 1631539386697, "ltp": 1.06, "tv": 21414.27, "trd": NaN, "batb": [[0, 1.05, 657.16]], "batl": [[1, 1.07, 990.38]]}, {"timestamp": 1631539387895, "ltp": 1.06, "tv": 21414.27, "trd": NaN, "batb": NaN, "batl": [[0, 1.06, 247.39]]}, {"timestamp": 1631539389608, "ltp": 1.06, "tv": 21496.82, "trd": [[1.06, 1519.91]], "batb": NaN, "batl": [[0, 1.06, 164.84]]}, {"timestamp": 1631539390498, "ltp": 1.06, "tv": 21496.82, "trd": NaN, "batb": [[0, 1.05, 453.78]], "batl": [[1, 1.07, 762.75]]}, {"timestamp": 1631539392325, "ltp": 1.06, "tv": 21496.82, "trd": NaN, "batb": NaN, "batl": [[1, 1.07, 538.89]]}, {"timestamp": 1631539393107, "ltp": 1.06, "tv": 21496.82, "trd": NaN, "batb": [[1, 1.04, 205.33], [2, 1.03, 1593.3]], "batl": NaN}, {"timestamp": 1631539394204, "ltp": 1.06, "tv": 21496.82, "trd": NaN, "batb": [[2, 1.02, 1010.78]], "batl": NaN}, {"timestamp": 1631539395301, "ltp": 1.06, "tv": 21496.82, "trd": NaN, "batb": [[0, 1.05, 1262.55], [2, 1.03, 55.81]], "batl": [[0, 1.06, 698.49], [1, 1.07, 2814.34], [2, 1.08, 359.56]]}, {"timestamp": 1631539396529, "ltp": 1.06, "tv": 21496.82, "trd": NaN, "batb": [[1, 1.04, 243.79], [2, 1.03, 70.23]], "batl": NaN}, {"timestamp": 1631539397502, "ltp": 1.05, "tv": 21502.6, "trd": [[1.05, 2085.72]], "batb": [[0, 1.05, 1259.66]], "batl": NaN}, {"timestamp": 1631539401715, "ltp": 1.05, "tv": 21538.68, "trd": [[1.05, 2121.8]], "batb": [[0, 1.05, 1583.62]], "batl": NaN}, {"timestamp": 1631539410558, "ltp": 1.05, "tv": 21538.68, "trd": NaN, "batb": [[0, 1.05, 1597.25]], "batl": NaN}, {"timestamp": 1631539412745, "ltp": 1.05, "tv": 21538.68, "trd": NaN, "batb": [[0, 1.05, 355.63], [1, 1.04, 205.33], [2, 1.03, 55.81]], "batl": [[0, 1.06, 164.84], [1, 1.07, 538.89], [2, 1.08, 350.3]]}, {"timestamp": 1631539413370, "ltp": 1.05, "tv": 21538.68, "trd": NaN, "batb": [[0, 1.05, 13.63], [2, 1.02, 3224.61]], "batl": NaN}, {"timestamp": 1631539415446, "ltp": 1.05, "tv": 21538.68, "trd": NaN, "batb": [[1, 1.04, 663.48]], "batl": [[1, 1.07, 990.38]]}, {"timestamp": 1631539417065, "ltp": 1.05, "tv": 21538.68, "trd": NaN, "batb": NaN, "batl": [[1, 1.07, 345.5]]}, {"timestamp": 1631539418465, "ltp": 1.05, "tv": 21538.68, "trd": NaN, "batb": [[2, 1.02, 1010.78]], "batl": NaN}, {"timestamp": 1631539420753, "ltp": 1.05, "tv": 21565.94, "trd": [[1.05, 2149.06]], "batb": [[0, 1.04, 2147.62], [1, 1.02, 56.36], [2, 1.01, 50.17]], "batl": [[0, 1.05, 203.22], [1, 1.06, 2673.14], [2, 1.07, 345.5]]}, {"timestamp": 1631539421271, "ltp": 1.05, "tv": 21565.94, "trd": NaN, "batb": [[1, 1.03, 9.71], [2, 1.02, 56.36]], "batl": NaN}, {"timestamp": 1631539423299, "ltp": 1.05, "tv": 21565.94, "trd": NaN, "batb": NaN, "batl": [[1, 1.06, 2686.19]]}, {"timestamp": 1631539427267, "ltp": 1.05, "tv": 21565.94, "trd": NaN, "batb": [[0, 1.04, 2339.62]], "batl": NaN}, {"timestamp": 1631539430091, "ltp": 1.05, "tv": 21565.94, "trd": NaN, "batb": NaN, "batl": [[0, 1.05, 199.49]]}, {"timestamp": 1631539433590, "ltp": 1.05, "tv": 21565.94, "trd": NaN, "batb": [[0, 1.04, 192], [1, 1.01, 4143.58], [2, 1.02, 0]], "batl": [[0, 1.06, 290.08], [1, 1.07, 345.5], [2, 1.08, 350.3]]}, {"timestamp": 1631539434427, "ltp": 1.05, "tv": 21565.94, "trd": NaN, "batb": [[0, 1.01, 4143.58], [1, 1.01, 0]], "batl": NaN}, {"timestamp": 1631539436820, "ltp": 1.05, "tv": 21565.94, "trd": NaN, "batb": [[0, 1.03, 383], [1, 1.02, 550], [2, 1.01, 5193.58]], "batl": [[0, 1.06, 383.08], [1, 1.07, 444.5], [2, 1.08, 448.3]]}, {"timestamp": 1631539438236, "ltp": 1.05, "tv": 21565.94, "trd": NaN, "batb": [[0, 1.04, 663.48], [1, 1.03, 383], [2, 1.02, 550]], "batl": [[0, 1.05, 487.63], [1, 1.06, 425.77], [2, 1.07, 444.5]]}, {"timestamp": 1631539439534, "ltp": 1.05, "tv": 21565.94, "trd": NaN, "batb": [[0, 1.04, 874.48]], "batl": NaN}, {"timestamp": 1631539442528, "ltp": 1.05, "tv": 21565.94, "trd": NaN, "batb": [[0, 1.04, 211]], "batl": [[0, 1.06, 383.08], [1, 1.07, 444.5], [2, 1.08, 448.3]]}, {"timestamp": 1631539444736, "ltp": 1.05, "tv": 21565.94, "trd": NaN, "batb": [[0, 1.03, 383], [1, 1.02, 550], [2, 1.01, 5193.58]], "batl": [[0, 1.06, 257.84], [2, 1.08, 111.11]]}, {"timestamp": 1631539445728, "ltp": 1.05, "tv": 21565.94, "trd": NaN, "batb": [[0, 1.03, 1052.93]], "batl": NaN}, {"timestamp": 1631539446043, "ltp": 1.05, "tv": 21565.94, "trd": NaN, "batb": [[2, 1.01, 1071.7]], "batl": [[2, 1.08, 13.11]]}, {"timestamp": 1631539447734, "ltp": 1.05, "tv": 21565.94, "trd": NaN, "batb": [[2, 1.01, 1157.09]], "batl": [[0, 1.04, 539.76], [1, 1.05, 437.36], [2, 1.06, 3771.28]]}, {"timestamp": 1631539448456, "ltp": 1.05, "tv": 21565.94, "trd": NaN, "batb": [[1, 1.02, 559.8]], "batl": NaN}, {"timestamp": 1631539449035, "ltp": 1.05, "tv": 21565.94, "trd": NaN, "batb": NaN, "batl": [[1, 1.05, 536.36]]}, {"timestamp": 1631