{"info": {"id": "1.187594320", "eventId": "30897898", "eventName": "Match Odds", "marketType": "MATCH_ODDS", "openDate": 1631542906269, "name": "R Serban v S Milatova", "numberOfActiveRunner": 2, "countryCode": "", "sport": "TENNIS", "venue": "", "volume": {"total": 247.03, "preMatch": 6.17, "inPlay": 240.86}, "winner": {"id": 9637111, "name": "R Serban", "status": "WINNER", "position": 1}, "delay": 5}, "runners": [{"id": 9637111, "name": "R Serban", "status": "WINNER", "position": 1, "inPlayOdds": 1.08, "inPlayTime": 1631551543149, "avgPrematch": 0, "closedOdds": 1.05, "maxPrematch": -100, "minPrematch": 1001, "maxInPlay": 1.08, "minInPlay": 1.01, "inPlayIndex": 0, "lengthOdds": 74, "lengthOddsPrematch": 0, "lengthOddsInPlay": 74, "tradedVolume": 232.3, "preMatchVolume": 3.41, "inPlayVolume": 228.89}, {"id": 20586366, "name": "S Milatova", "status": "LOSER", "position": 2, "inPlayOdds": 5.0, "inPlayTime": 1631542906269, "avgPrematch": 5.0, "closedOdds": 8.6, "maxPrematch": 5.0, "minPrematch": 5.0, "maxInPlay": 8.6, "minInPlay": 4.3, "inPlayIndex": 2, "lengthOdds": 249, "lengthOddsPrematch": 2, "lengthOddsInPlay": 247, "tradedVolume": 14.73, "preMatchVolume": 2.76, "inPlayVolume": 11.97}], "marketUpdates": [{"timestamp": 1631518387108000000, "openDate": "2021-09-13T12:00:00.000Z", "status": "OPEN", "betDelay": 0, "inPlay": false, "complete": true}, {"timestamp": 1631522764139000000, "openDate": "2021-09-13T14:00:00.000Z", "status": "OPEN", "betDelay": 0, "inPlay": false, "complete": true}, {"timestamp": 1631526208626000000, "openDate": "2021-09-13T14:15:00.000Z", "status": "OPEN", "betDelay": 0, "inPlay": false, "complete": true}, {"timestamp": 1631527853934000000, "openDate": "2021-09-13T14:35:00.000Z", "status": "OPEN", "betDelay": 0, "inPlay": false, "complete": true}, {"timestamp": 1631530575170000000, "openDate": "2021-09-13T14:00:00.000Z", "status": "OPEN", "betDelay": 0, "inPlay": false, "complete": true}, {"timestamp": 1631531633841000000, "openDate": "2021-09-13T14:10:00.000Z", "status": "OPEN", "betDelay": 0, "inPlay": false, "complete": true}, {"timestamp": 1631536574244000000, "openDate": "2021-09-13T14:20:00.000Z", "status": "OPEN", "betDelay": 0, "inPlay": false, "complete": true}, {"timestamp": 1631537247903000000, "openDate": "2021-09-13T14:30:00.000Z", "status": "OPEN", "betDelay": 0, "inPlay": false, "complete": true}, {"timestamp": 1631537889204000000, "openDate": "2021-09-13T14:40:00.000Z", "status": "OPEN", "betDelay": 0, "inPlay": false, "complete": true}, {"timestamp": 1631537976689000000, "openDate": "2021-09-13T14:35:00.000Z", "status": "OPEN", "betDelay": 0, "inPlay": false, "complete": true}, {"timestamp": 1631538341817000000, "openDate": "2021-09-13T14:30:00.000Z", "status": "OPEN", "betDelay": 0, "inPlay": false, "complete": true}, {"timestamp": 1631542560034000000, "openDate": "2021-09-13T14:25:00.000Z", "status": "OPEN", "betDelay": 0, "inPlay": false, "complete": true}, {"timestamp": 1631542866793000000, "openDate": "2021-09-13T14:20:00.000Z", "status": "OPEN", "betDelay": 0, "inPlay": false, "complete": true}, {"timestamp": 1631542906269000000, "openDate": "2021-09-13T14:20:00.000Z", "status": "OPEN", "betDelay": 5, "inPlay": true, "complete": true}, {"timestamp": 1631549997128000000, "openDate": "2021-09-13T16:19:53.000Z", "status": "OPEN", "betDelay": 5, "inPlay": true, "complete": true}, {"timestamp": 1631555692614000000, "openDate": "2021-09-13T16:19:53.000Z", "status": "SUSPENDED", "betDelay": 5, "inPlay": true, "complete": true}, {"timestamp": 1631555697653000000, "openDate": "2021-09-13T16:19:53.000Z", "status": "CLOSED", "betDelay": 5, "inPlay": true, "complete": true}], "odds": [{"runnerId": 9637111, "odds": [{"timestamp": 1631551543149, "ltp": 1.08, "tv": 3.41, "trd": [[1.08, 3.42]], "batb": [[0, 1.01, 12], [1, 1.01, 0]], "batl": NaN}, {"timestamp": 1631551548051, "ltp": 1.08, "tv": 3.41, "trd": NaN, "batb": [[0, 1.08, 374.99], [1, 1.01, 12]], "batl": NaN}, {"timestamp": 1631551562694, "ltp": 1.08, "tv": 3.41, "trd": NaN, "batb": [[0, 1.01, 12], [1, 1.01, 0]], "batl": NaN}, {"timestamp": 1631551567581, "ltp": 1.08, "tv": 3.41, "trd": NaN, "batb": [[0, 1.05, 599.99], [1, 1.01, 12]], "batl": NaN}, {"timestamp": 1631551618167, "ltp": 1.08, "tv": 3.41, "trd": NaN, "batb": [[0, 1.01, 12], [1, 1.01, 0]], "batl": NaN}, {"timestamp": 1631551623190, "ltp": 1.08, "tv": 3.41, "trd": NaN, "batb": [[0, 1.04, 749.99], [1, 1.01, 12]], "batl": NaN}, {"timestamp": 1631551653242, "ltp": 1.08, "tv": 3.41, "trd": NaN, "batb": [[0, 1.01, 12], [1, 1.01, 0]], "batl": NaN}, {"timestamp": 1631551658351, "ltp": 1.08, "tv": 3.41, "trd": NaN, "batb": [[0, 1.05, 599.99], [1, 1.01, 12]], "batl": NaN}, {"timestamp": 1631551683176, "ltp": 1.08, "tv": 3.41, "trd": NaN, "batb": [[0, 1.01, 12], [1, 1.01, 0]], "batl": NaN}, {"timestamp": 1631551688221, "ltp": 1.08, "tv": 3.41, "trd": NaN, "batb": [[0, 1.06, 499.99], [1, 1.01, 12]], "batl": NaN}, {"timestamp": 1631551721041, "ltp": 1.08, "tv": 3.41, "trd": NaN, "batb": [[0, 1.01, 12], [1, 1.01, 0]], "batl": NaN}, {"timestamp": 1631551725952, "ltp": 1.08, "tv": 3.41, "trd": NaN, "batb": [[0, 1.05, 599.99], [1, 1.01, 12]], "batl": NaN}, {"timestamp": 1631551763924, "ltp": 1.08, "tv": 3.41, "trd": NaN, "batb": [[0, 1.01, 12], [1, 1.01, 0]], "batl": NaN}, {"timestamp": 1631551768955, "ltp": 1.08, "tv": 3.41, "trd": NaN, "batb": [[0, 1.08, 374.99], [1, 1.01, 12]], "batl": NaN}, {"timestamp": 1631551970005, "ltp": 1.08, "tv": 3.41, "trd": NaN, "batb": [[0, 1.01, 12], [1, 1.01, 0]], "batl": NaN}, {"timestamp": 1631551974948, "ltp": 1.08, "tv": 3.41, "trd": NaN, "batb": [[0, 1.05, 599.99], [1, 1.01, 12]], "batl": NaN}, {"timestamp": 1631552008477, "ltp": 1.08, "tv": 3.41, "trd": NaN, "batb": [[0, 1.01, 12], [1, 1.01, 0]], "batl": NaN}, {"timestamp": 1631552013382, "ltp": 1.08, "tv": 3.41, "trd": NaN, "batb": [[0, 1.08, 374.99], [1, 1.01, 12]], "batl": NaN}, {"timestamp": 1631552039931, "ltp": 1.08, "tv": 3.41, "trd": NaN, "batb": [[0, 1.01, 12], [1, 1.01, 0]], "batl": NaN}, {"timestamp": 1631552044890, "ltp": 1.08, "tv": 3.41, "trd": NaN, "batb": [[0, 1.05, 599.99], [1, 1.01, 12]], "batl": NaN}, {"timestamp": 1631552119409, "ltp": 1.08, "tv": 3.41, "trd": NaN, "batb": [[0, 1.01, 12], [1, 1.01, 0]], "batl": NaN}, {"timestamp": 1631552124308, "ltp": 1.08, "tv": 3.41, "trd": NaN, "batb": [[0, 1.04, 749.99], [1, 1.01, 12]], "batl": NaN}, {"timestamp": 1631552208147, "ltp": 1.08, "tv": 3.41, "trd": NaN, "batb": [[0, 1.01, 12], [1, 1.01, 0]], "batl": NaN}, {"timestamp": 1631552213024, "ltp": 1.08, "tv": 3.41, "trd": NaN, "batb": [[0, 1.03, 999.99], [1, 1.01, 12]], "batl": NaN}, {"timestamp": 1631552257002, "ltp": 1.08, "tv": 3.41, "trd": NaN, "batb": [[0, 1.01, 12], [1, 1.01, 0]], "batl": NaN}, {"timestamp": 1631552261995, "ltp": 1.08, "tv": 3.41, "trd": NaN, "batb": [[0, 1.02, 1499.99], [1, 1.01, 12]], "batl": NaN}, {"timestamp": 1631552670835, "ltp": 1.08, "tv": 3.41, "trd": [[1.08, 3.42]], "batb": [[0, 1.01, 12], [1, 1.01, 0]], "batl": NaN}, {"timestamp": 1631552896200, "ltp": 1.08, "tv": 3.41, "trd": NaN, "batb": [[0, 1.02, 1499.99], [1, 1.01, 12]], "batl": NaN}, {"timestamp": 1631552916946, "ltp": 1.08, "tv": 3.41, "trd": NaN, "batb": [[0, 1.01, 12], [1, 1.01, 0]], "batl": NaN}, {"timestamp": 1631552955786, "ltp": 1.08, "tv": 3.41, "trd": NaN, "batb": [[0, 1.02, 1499.99], [1, 1.01, 12]], "batl": NaN}, {"timestamp": 1631552984734, "ltp": 1.08, "tv": 3.41, "trd": NaN, "batb": [[0, 1.01, 12], [1, 1.01, 0]], "batl": NaN}, {"timestamp": 1631552989616, "ltp": 1.08, "tv": 3.41, "trd": NaN, "batb": [[0, 1.03, 999.99], [1, 1.01, 12]], "batl": NaN}, {"timestamp": 1631553037478, "ltp": 1.08, "tv": 3.41, "trd": NaN, "batb": [[0, 1.01, 12], [1, 1.01, 0]], "batl": NaN}, {"timestamp": 1631553042501, "ltp": 1.08, "tv": 3.41, "trd": NaN, "batb": [[0, 1.02, 1499.99], [1, 1.01, 12]], "batl": NaN}, {"timestamp": 1631553077332, "ltp": 1.08, "tv": 3.41, "trd": NaN, "batb": [[0, 1.01, 12], [1, 1.01, 0]], "batl": NaN}, {"timestamp": 1631553299405, "ltp": 1.01, "tv": 27.41, "trd": [[1.01, 24]], "batb": NaN, "batl": [[0, 1.01, 88], [1, 1.47, 100]]}, {"timestamp": 1631553825679, "ltp": 1.01, "tv": 106.91, "trd": [[1.01, 103.5]], "batb": NaN, "batl": [[0, 1.01, 48.25]]}, {"timestamp": 1631553860892, "ltp": 1.01, "tv": 202.31, "trd": [[1.01, 198.9]], "batb": NaN, "batl": [[0, 1.47, 100.55], [1, 1.47, 0]]}, {"timestamp": 1631553870410, "ltp": 1.01, "tv": 203.41, "trd": [[1.01, 200]], "batb": [[0, 1.01, 722.15]], "batl": [[0, 1.47, 100]]}, {"timestamp": 1631553875623, "ltp": 1.01, "tv": 203.41, "trd": NaN, "batb": [[0, 1.04, 749.99], [1, 1.01, 722.15]], "batl": NaN}, {"timestamp": 1631553879119, "ltp": 1.01, "tv": 203.41, "trd": NaN, "batb": [[0, 1.01, 722.15], [1, 1.01, 0]], "batl": NaN}, {"timestamp": 1631553884125, "ltp": 1.01, "tv": 203.41, "trd": NaN, "batb": [[0, 1.02, 1499.99], [1, 1.01, 722.15]], "batl": NaN}, {"timestamp": 1631553890219, "ltp": 1.01, "tv": 203.41, "trd": NaN, "batb": [[1, 1.01, 0]], "batl": NaN}, {"timestamp": 1631553943914, "ltp": 1.01, "tv": 203.41, "trd": NaN, "batb": [[0, 1.03, 999.99]], "batl": NaN}, {"timestamp": 1631553962745, "ltp": 1.01, "tv": 203.41, "trd": NaN, "batb": [[0, 1.02, 1499.99]], "batl": NaN}, {"timestamp": 1631553965741, "ltp": 1.01, "tv": 203.41, "trd": NaN, "batb": NaN, "batl": [[0, 1.05, 14.45], [1, 1.47, 100]]}, {"timestamp": 1631554007294, "ltp": 1.01, "tv": 203.41, "trd": NaN, "batb": [[0, 1.02, 722.7]], "batl": NaN}, {"timestamp": 1631554048622, "ltp": 1.05, "tv": 232.3, "trd": [[1.05, 28.89]], "batb": NaN, "batl": [[0, 1.47, 100.01], [1, 1.47, 0]]}, {"timestamp": 1631554059236, "ltp": 1.05, "tv": 232.3, "trd": NaN, "batb": NaN, "batl": [[0, 1.47, 100]]}, {"timestamp": 1631554064563, "ltp": 1.05, "tv": 232.3, "trd": NaN, "batb": [[0, 1.08, 374.99], [1, 1.02, 722.7]], "batl": NaN}, {"timestamp": 1631554073364, "ltp": 1.05, "tv": 232.3, "trd": NaN, "batb": [[0, 1.02, 722.7], [1, 1.02, 0]], "batl": NaN}, {"timestamp": 1631554078371, "ltp": 1.05, "tv": 232.3, "trd": NaN, "batb": [[0, 1.05, 599.99], [1, 1.02, 722.7]], "batl": NaN}, {"timestamp": 1631554082169, "ltp": 1.05, "tv": 232.3, "trd": NaN, "batb": [[1, 1.02, 0]], "batl": NaN}, {"timestamp": 1631554124732, "ltp": 1.05, "tv": 232.3, "trd": NaN, "batb": [[0, 1.03, 999.99]], "batl": NaN}, {"timestamp": 1631554166058, "ltp": 1.05, "tv": 232.3, "trd": NaN, "batb": [[0, 1.02, 1499.99]], "batl": NaN}, {"timestamp": 1631554363818, "ltp": 1.05, "tv": 232.3, "trd": NaN, "batb": [[0, 1.02, 1499.99]], "batl": NaN}, {"timestamp": 1631554400379, "ltp": 1.05, "tv": 232.3, "trd": NaN, "batb": [[0, 1.04, 749.99]], "batl": NaN}, {"timestamp": 1631554454033, "ltp": 1.05, "tv": 232.3, "trd": NaN, "batb": [[0, 1.03, 999.99]], "batl": NaN}, {"timestamp": 1631554535434, "ltp": 1.05, "tv": 232.3, "trd": NaN, "batb": [[0, 1.03, 999.99]], "batl": NaN}, {"timestamp": 1631554590185, "ltp": 1.05, "tv": 232.3, "trd": NaN, "batb": [[0, 1.05, 599.99]], "batl": NaN}, {"timestamp": 1631554641636, "ltp": 1.05, "tv": 232.3, "trd": NaN, "batb": [[0, 1.08, 374.99]], "batl": NaN}, {"timestamp": 1631554672185, "ltp": 1.05, "tv": 232.3, "trd": NaN, "batb": [[0, 1.05, 599.99]], "batl": NaN}, {"timestamp": 1631554719309, "ltp": 1.05, "tv": 232.3, "trd": NaN, "batb": [[0, 1.03, 999.99]], "batl": NaN}, {"timestamp": 1631554747749, "ltp": 1.05, "tv": 232.3, "trd": NaN, "batb": [[0, 1.02, 1499.99]], "batl": NaN}, {"timestamp": 1631554977798, "ltp": 1.05, "tv": 232.3, "trd": NaN, "batb": [[0, 1.03, 999.99]], "batl": NaN}, {"timestamp": 1631555042863, "ltp": 1.05, "tv": 232.3, "trd": NaN, "batb": [[0, 1.04, 749.99]], "batl": NaN}, {"timestamp": 1631555075543, "ltp": 1.05, "tv": 232.3, "trd": NaN, "batb": [[0, 1.03, 999.99]], "batl": NaN}, {"timestamp": 1631555136995, "ltp": 1.05, "tv": 232.3, "trd": NaN, "batb": [[0, 1.04, 749.99]], "batl": NaN}, {"timestamp": 1631555172346, "ltp": 1.05, "tv": 232.3, "trd": NaN, "batb": [[0, 1.05, 599.99]], "batl": NaN}, {"timestamp": 1631555218685, "ltp": 1.05, "tv": 232.3, "trd": NaN, "batb": [[0, 1.04, 749.99]], "batl": NaN}, {"timestamp": 1631555255342, "ltp": 1.05, "tv": 232.3, "trd": NaN, "batb": [[0, 1.03, 999.99]], "batl": NaN}, {"timestamp": 1631555293995, "ltp": 1.05, "tv": 232.3, "trd": NaN, "batb": [[0, 1.04, 749.99]], "batl": NaN}, {"timestamp": 1631555328338, "ltp": 1.05, "tv": 232.3, "trd": NaN, "batb": [[0, 1.02, 1499.99]], "batl": NaN}, {"timestamp": 1631555537907, "ltp": 1.05, "tv": 232.3, "trd": NaN, "batb": [[0, 1.02, 1499.99]], "batl": NaN}]}, {"runnerId": 20586366, "odds": [{"timestamp": 1631542351357, "ltp": 5.0, "tv": 2.76, "trd": [[5, 2.76]], "batb": [[0, 5, 9.06]], "batl": NaN}, {"timestamp": 1631542352344, "ltp": 5.0, "tv": 2.76, "trd": NaN, "batb": [[0, 5, 10.44]], "batl": NaN}, {"timestamp": 1631542906269, "ltp": 5.0, "tv": 2.76, "trd": NaN, "batb": [[0, 1.3, 5], [1, 1.01, 7], [2, 1.01, 0]], "batl": NaN}, {"timestamp": 1631542911454, "ltp": 5.0, "tv": 2.76, "trd": NaN, "batb": [[0, 4.8, 10], [1, 1.3, 5], [2, 1.01, 7]], "batl": NaN}, {"timestamp": 1631543108241, "ltp": 5.0, "tv": 2.76, "trd": NaN, "batb": [[0, 1.3, 5], [1, 1.01, 7], [2, 1.01, 0]], "batl": NaN}, {"timestamp": 1631543867204, "ltp": 5.0, "tv": 2.76, "trd": NaN, "batb": [[0, 3.5, 86.16], [1, 1.3, 5], [2, 1.01, 7]], "batl": NaN}, {"timestamp": 1631543934932, "ltp": 5.0, "tv": 2.76, "trd": NaN, "batb": [[0, 1.3, 5], [1, 1.01, 7], [2, 1.01, 0]], "batl": NaN}, {"timestamp": 1631546265834, "ltp": 5.0, "tv": 2.76, "trd": [[5, 2.77]], "batb": NaN, "batl": NaN}, {"timestamp": 1631548422545, "ltp": 5.0, "tv": 2.76, "trd": NaN, "batb": NaN, "batl": [[0, 100, 0.37]]}, {"timestamp": 1631549092280, "ltp": 5.0, "tv": 2.76, "trd": NaN, "batb": [[1, 1.01, 12]], "batl": NaN}, {"timestamp": 1631549611133, "ltp": 5.0, "tv": 2.76, "trd": NaN, "batb": [[0, 4.8, 10], [1, 1.3, 5], [2, 1.01, 12]], "batl": NaN}, {"timestamp": 1631550030867, "ltp": 5.0, "tv": 2.76, "trd": NaN, "batb": [[0, 1.3, 5], [1, 1.01, 12], [2, 1.01, 0]], "batl": NaN}, {"timestamp": 1631550061648, "ltp": 5.0, "tv": 2.76, "trd": NaN, "batb": [[0, 4.8, 10], [1, 1.3, 5], [2, 1.01, 12]], "batl": NaN}, {"timestamp": 1631550072263, "ltp": 5.0, "tv": 2.76, "trd": NaN, "batb": [[0, 1.3, 5], [1, 1.01, 12], [2, 1.01, 0]], "batl": NaN}, {"timestamp": 1631550098409, "ltp": 5.0, "tv": 2.76, "trd": NaN, "batb": [[0, 5.3, 10], [1, 1.3, 5], [2, 1.01, 12]], "batl": NaN}, {"timestamp": 1631550133652, "ltp": 5.0, "tv": 2.76, "trd": NaN, "batb": [[0, 1.3, 5], [1, 1.01, 12], [2, 1.01, 0]], "batl": NaN}, {"timestamp": 1631550138603, "ltp": 5.0, "tv": 2.76, "trd": NaN, "batb": [[0, 5.8, 10], [1, 1.3, 5], [2, 1.01, 12]], "batl": NaN}, {"timestamp": 1631550167341, "ltp": 5.0, "tv": 2.76, "trd": NaN, "batb": [[0, 1.3, 5], [1, 1.01, 12], [2, 1.01, 0]], "batl": NaN}, {"timestamp": 1631550172209, "ltp": 5.0, "tv": 2.76, "trd": NaN, "batb": [[0, 6, 10], [1, 1.3, 5], [2, 1.01, 12]], "batl": NaN}, {"timestamp": 1631550200804, "ltp": 5.0, "tv": 2.76, "trd": NaN, "batb": [[0, 1.3, 5], [1, 1.01, 12], [2, 1.01, 0]], "batl": NaN}, {"timestamp": 1631550248860, "ltp": 5.0, "tv": 2.76, "trd": NaN, "batb": [[0, 7, 10], [1, 1.3, 5], [2, 1.01, 12]], "batl": NaN}, {"timestamp": 1631550265385, "ltp": 5.0, "tv": 2.76, "trd": NaN, "batb": [[0, 1.3, 5], [1, 1.01, 12], [2, 1.01, 0]], "batl": NaN}, {"timestamp": 1631550270309, "ltp": 5.0, "tv": 2.76, "trd": NaN, "batb": [[0, 7.6, 10], [1, 1.3, 5], [2, 1.01, 12]], "batl": NaN}, {"timestamp": 1631550299514, "ltp": 5.0, "tv": 2.76, "trd": NaN, "batb": [[0, 1.3, 5], [1, 1.01, 12], [2, 1.01, 0]], "batl": NaN}, {"timestamp": 1631550304438, "ltp": 5.0, "tv": 2.76, "trd": NaN, "batb": [[0, 6, 10], [1, 1.3, 5], [2, 1.01, 12]], "batl": NaN}, {"timestamp": 1631550382157, "ltp": 5.0, "tv": 2.76, "trd": NaN, "batb": [[0, 1.3, 5], [1, 1.01, 12], [2, 1.01, 0]], "batl": NaN}, {"timestamp": 1631550395968, "ltp": 5.0, "tv": 2.76, "trd": NaN, "batb": [[0, 5.3, 10], [1, 1.3, 5], [2, 1.01, 12]], "batl": NaN}, {"timestamp": 1631550403470, "ltp": 5.0, "tv": 2.76, "trd": NaN, "batb": [[0, 1.3, 5], [1, 1.01, 12], [2, 1.01, 0]], "batl": NaN}, {"timestamp": 1631550408397, "ltp": 5.0, "tv": 2.76, "trd": NaN, "batb": [[0, 4.3, 10], [1, 1.3, 5], [2, 1.01, 12]], "batl": NaN}, {"timestamp": 1631550454455, "ltp": 4.3, "tv": 9.7, "trd": [[4.3, 6.94]], "batb": [[0, 4.3, 6.53]], "batl": NaN}, {"timestamp": 1631550454663, "ltp": 4.3, "tv": 9.7, "trd": NaN, "batb": [[0, 1.3, 5], [1, 1.01, 12], [2, 1.01, 0]], "batl": NaN}, {"timestamp": 1631550459572, "ltp": 4.3, "tv": 9.7, "trd": NaN, "batb": [[0, 4.3, 10], [1, 1.3, 5], [2, 1.01, 12]], "batl": NaN}, {"timestamp": 1631550462967, "ltp": 4.3, "tv": 9.7, "trd": NaN, "batb": [[0, 1.3, 5], [1, 1.01, 12], [2, 1.01, 0]], "batl": NaN}, {"timestamp": 1631550467877, "ltp": 4.3, "tv": 9.7, "trd": NaN, "batb": [[0, 4.1, 10], [1, 1.3, 5], [2, 1.01, 12]], "batl": NaN}, {"timestamp": 1631550491755, "ltp": 4.3, "tv": 9.7, "trd": NaN, "batb": [[0, 1.3, 5], [1, 1.01, 12], [2, 1.01, 0]], "batl": NaN}, {"timestamp": 1631550496649, "ltp": 4.3, "tv": 9.7, "trd": NaN, "batb": [[0, 3.7, 11.11], [1, 1.3, 5], [2, 1.01, 12]], "batl": NaN}, {"timestamp": 1631550533589, "ltp": 4.3, "tv": 9.7, "trd": NaN, "batb": [[0, 1.3, 5], [1, 1.01, 12], [2, 1.01, 0]], "batl": NaN}, {"timestamp": 1631550566881, "ltp": 4.3, "tv": 9.7, "trd": NaN, "batb": [[0, 3.7, 11.11], [1, 1.3, 5], [2, 1.01, 12]], "batl": NaN}, {"timestamp": 1631550590414, "ltp": 4.3, "tv": 9.7, "trd": NaN, "batb": [[0, 1.3, 5], [1, 1.01, 12], [2, 1.01, 0]], "batl": NaN}, {"timestamp": 1631550663597, "ltp": 4.3, "tv": 9.7, "trd": NaN, "batb": [[0, 3.3, 13.04], [1, 1.3, 5], [2, 1.01, 12]], "batl": NaN}, {"timestamp": 1631550722419, "ltp": 4.3, "tv": 9.7, "trd": NaN, "batb": [[0, 1.3, 5], [1, 1.01, 12], [2, 1.01, 0]], "batl": NaN}, {"timestamp": 1631550727422, "ltp": 4.3, "tv": 9.7, "trd": NaN, "batb": [[0, 3.7, 11.11], [1, 1.3, 5], [2, 1.01, 12]], "batl": NaN}, {"timestamp": 1631550769577, "ltp": 4.3, "tv": 9.7, "trd": NaN, "batb": [[0, 1.3, 5], [1, 1.01, 12], [2, 1.01, 0]], "batl": NaN}, {"timestamp": 1631550774562, "ltp": 4.3, "tv": 9.7, "trd": NaN, "batb": [[0, 3.95, 10.16], [1, 1.3, 5], [2, 1.01, 12]], "batl": NaN}, {"timestamp": 1631550813252, "ltp": 4.3, "tv": 9.7, "trd": NaN, "batb": [[0, 1.3, 5], [1, 1.01, 12], [2, 1.01, 0]], "batl": NaN}, {"timestamp": 1631550818255, "ltp": 4.3, "tv": 9.7, "trd": NaN, "batb": [[0, 4.1, 10], [1, 1.3, 5], [2, 1.01, 12]], "batl": NaN}, {"timestamp": 1631550904625, "ltp": 4.3, "tv": 9.7, "trd": NaN, "batb": [[0, 1.3, 5], [1, 1.01, 12], [2, 1.01, 0]], "batl": NaN}, {"timestamp": 1631550909501, "ltp": 4.3, "tv": 9.7, "trd": NaN, "batb": [[0, 5.3, 10], [1, 1.3, 5], [2, 1.01, 12]], "batl": NaN}, {"timestamp": 1631550937388, "ltp": 4.3, "tv": 9.7, "trd": NaN, "batb": [[0, 1.3, 5], [1, 1.01, 12], [2, 1.01, 0]], "batl": NaN}, {"timestamp": 1631550942273, "ltp": 4.3, "tv": 9.7, "trd": NaN, "batb": [[0, 4.3, 10], [1, 1.3, 5], [2, 1.01, 12]], "batl": NaN}, {"timestamp": 1631550982437, "ltp": 4.3, "tv": 9.7, "trd": NaN, "batb": [[0, 1.3, 5], [1, 1.01, 12], [2, 1.01, 0]], "batl": NaN}, {"timestamp": 1631550987343, "ltp": 4.3, "tv": 9.7, "trd": NaN, "batb": [[0, 5.3, 10], [1, 1.3, 5], [2, 1.01, 12]], "batl": NaN}, {"timestamp": 1631551029370, "ltp": 4.3, "tv": 9.7, "trd": NaN, "batb": [[0, 1.3, 5], [1, 1.01, 12], [2, 1.01, 0]], "batl": NaN}, {"timestamp": 1631551034274, "ltp": 4.3, "tv": 9.7, "trd": NaN, "batb": [[0, 5.8, 10], [1, 1.3, 5], [2, 1.01, 12]], "batl": NaN}, {"timestamp": 1631551062920, "ltp": 4.3, "tv": 9.7, "trd": NaN, "batb": [[0, 1.3, 5], [1, 1.01, 12], [2, 1.01, 0]], "batl": NaN}, {"timestamp": 1631551067817, "ltp": 4.3, "tv": 9.7, "trd": NaN, "batb": [[0, 6, 10], [1, 1.3, 5], [2, 1.01, 12]], "batl": NaN}, {"timestamp": 1631551182123, "ltp": 4.3, "tv": 9.7, "trd": NaN, "batb": [[0, 1.3, 5], [1, 1.01, 12], [2, 1.01, 0]], "batl": NaN}, {"timestamp": 1631551187038, "ltp": 4.3, "tv": 9.7, "trd": NaN, "batb": [[0, 7, 10], [1, 1.3, 5], [2, 1.01, 12]], "batl": NaN}, {"timestamp": 1631551228132, "ltp": 4.3, "tv": 9.7, "trd": NaN, "batb": [[0, 1.3, 5], [1, 1.01, 12], [2, 1.01, 0]], "batl": NaN}, {"timestamp": 1631551233095, "ltp": 4.3, "tv": 9.7, "trd": NaN, "batb": [[0, 7.6, 10], [1, 1.3, 5], [2, 1.01, 12]], "batl": NaN}, {"timestamp": 1631551284382, "ltp": 4.3, "tv": 9.7, "trd": NaN, "batb": [[0, 1.3, 5], [1, 1.01, 12], [2, 1.01, 0]], "batl": NaN}, {"timestamp": 1631551289392, "ltp": 4.3, "tv": 9.7, "trd": NaN, "batb": [[0, 7, 10], [1, 1.3, 5], [2, 1.01, 12]], "batl": NaN}, {"timestamp": 1631551328057, "ltp": 4.3, "tv": 9.7, "trd": NaN, "batb": [[0, 1.3, 5], [1, 1.01, 12], [2, 1.01, 0]], "batl": NaN}, {"timestamp": 1631551332962, "ltp": 4.3, "tv": 9.7, "trd": NaN, "batb": [[0, 6, 10], [1, 1.3, 5], [2, 1.01, 12]], "batl": NaN}, {"timestamp": 1631551372031, "ltp": 4.3, "tv": 9.7, "trd": NaN, "batb": [[0, 1.3, 5], [1, 1.01, 12], [2, 1.01, 0]], "batl": NaN}, {"timestamp": 1631551377054, "ltp": 4.3, "tv": 9.7, "trd": NaN, "batb": [[0, 5.3, 10], [1, 1.3, 5], [2, 1.01, 12]], "batl": NaN}, {"timestamp": 1631551403497, "ltp": 4.3, "tv": 9.7, "trd": NaN, "batb": [[0, 1.3, 5], [1, 1.01, 12], [2, 1.01, 0]], "batl": NaN}, {"timestamp": 1631551408402, "ltp": 4.3, "tv": 9.7, "trd": NaN, "batb": [[0, 6, 10], [1, 1.3, 5], [2, 1.01, 12]], "batl": NaN}, {"timestamp": 1631551473507, "ltp": 4.3, "tv": 9.7, "trd": NaN, "batb": [[0, 1.3, 5], [1, 1.01, 12], [2, 1.01, 0]], "batl": NaN}, {"timestamp": 1631551478413, "ltp": 4.3, "tv": 9.7, "trd": NaN, "batb": [[0, 5.8, 10], [1, 1.3, 5], [2, 1.01, 12]], "batl": NaN}, {"timestamp": 1631551523722, "ltp": 4.3, "tv": 9.7, "trd": NaN, "batb": [[0, 1.3, 5], [1, 1.01, 12], [2, 1.01, 0]], "batl": NaN}, {"timestamp": 1631551528723, "ltp": 4.3, "tv": 9.7, "trd": NaN, "batb": [[0, 6, 10], [1, 1.3, 5], [2, 1.01, 12]], "batl": NaN}, {"timestamp": 1631551562694, "ltp": 4.3, "tv": 9.7, "trd": NaN, "batb": [[0, 1.3, 5], [1, 1.01, 12], [2, 1.01, 0]], "batl": NaN}, {"timestamp": 1631551567581, "ltp": 4.3, "tv": 9.7, "trd": NaN, "batb": [[0, 7.6, 10], [1, 1.3, 5], [2, 1.01, 12]], "batl": NaN}, {"timestamp": 1631551618167, "ltp": 4.3, "tv": 9.7, "trd": NaN, "batb": [[0, 1.3, 5], [1, 1.01, 12], [2, 1.01, 0]], "batl": NaN}, {"timestamp": 1631551623190, "ltp": 4.3, "tv": 9.7, "trd": NaN, "batb": [[0, 8, 10], [1, 1.3, 5], [2, 1.01, 12]], "batl": NaN}, {"timestamp": 1631551653242, "ltp": 4.3, "tv": 9.7, "trd": NaN, "batb": [[0, 1.3, 5], [1, 1.01, 12], [2, 1.01, 0]], "batl": NaN}, {"timestamp": 1631551658351, "ltp": 4.3, "tv": 9.7, "trd": NaN, "batb": [[0, 7.6, 10], [1, 1.3, 5], [2, 1.01, 12]], "batl": NaN}, {"timestamp": 1631551683176, "ltp": 4.3, "tv": 9.7, "trd": NaN, "batb": [[0, 1.3, 5], [1, 1.01, 12], [2, 1.01, 0]], "batl": NaN}, {"timestamp": 1631551688221, "ltp": 4.3, "tv": 9.7, "trd": NaN, "batb": [[0, 7, 10], [1, 1.3, 5], [2, 1.01, 12]], "batl": NaN}, {"timestamp": 1631551721041, "ltp": 4.3, "tv": 9.7, "trd": NaN, "batb": [[0, 1.3, 5], [1, 1.01, 12], [2, 1.01, 0]], "batl": NaN}, {"timestamp": 1631551725952, "ltp": 4.3, "tv": 9.7, "trd": NaN, "batb": [[0, 7.6, 10], [1, 1.3, 5], [2, 1.01, 12]], "batl": NaN}, {"timestamp": 1631551763924, "ltp": 4.3, "tv": 9.7, "trd": NaN, "batb": [[0, 1.3, 5], [1, 1.01, 12], [2, 1.01, 0]], "batl": NaN}, {"timestamp": 1631551768955, "ltp": 4.3, "tv": 9.7, "trd": NaN, "batb": [[0, 6, 10], [1, 1.3, 5], [2, 1.01, 12]], "batl": NaN}, {"timestamp": 1631551970005, "ltp": 4.3, "tv": 9.7, "trd": NaN, "batb": [[0, 1.3, 5], [1, 1.01, 12], [2, 1.01, 0]], "batl": NaN}, {"timestamp": 1631551974948, "ltp": 4.3, "tv": 9.7, "trd": NaN, "batb": [[0, 7.6, 10], [1, 1.3, 5], [2, 1.01, 12]], "batl": NaN}, {"timestamp": 1631552008477, "ltp": 4.3, "tv": 9.7, "trd": NaN, "batb": [[0, 1.3, 5], [1, 1.01, 12], [2, 1.01, 0]], "batl": NaN}, {"timestamp": 1631552013382, "ltp": 4.3, "tv": 9.7, "trd": NaN, "batb": [[0, 6, 10], [1, 1.3, 5], [2, 1.01, 12]], "batl": NaN}, {"timestamp": 1631552039931, "ltp": 4.3, "tv": 9.7, "trd": NaN, "batb": [[0, 1.3, 5], [1, 1.01, 12], [2, 1.01, 0]], "batl": NaN}, {"timestamp": 1631552044890, "ltp": 4.3, "tv": 9.7, "trd": NaN, "batb": [[0, 7.6, 10], [1, 1.3, 5], [2, 1.01, 12]], "batl": NaN}, {"timestamp": 1631552119409, "ltp": 4.3, "tv": 9.7, "trd": NaN, "batb": [[0, 1.3, 5], [1, 1.01, 12], [2, 1.01, 0]], "batl": NaN}, {"timestamp": 1631552124308, "ltp": 4.3, "tv": 9.7, "trd": NaN, "batb": [[0, 8.6, 10], [1, 1.3, 5], [2, 1.01, 12]], "batl": NaN}, {"timestamp": 1631552141877, "ltp": 4.3, "tv": 9.7, "trd": NaN, "batb": [[0, 1.3, 5], [1, 1.01, 12], [2, 1.01, 0]], "batl": NaN}, {"timestamp": 1631552146672, "ltp": 4.3, "tv": 9.7, "trd": NaN, "batb": [[0, 7.6, 10], [1, 1.3, 5], [2, 1.01, 12]], "batl": NaN}, {"timestamp": 1631552169796, "ltp": 4.3, "tv": 9.7, "trd": NaN, "batb": [[0, 1.3, 5], [1, 1.01, 12], [2, 1.01, 0]], "batl": NaN}, {"timestamp": 1631552174690, "ltp": 4.3, "tv": 9.7, "trd": NaN, "batb": [[0, 8.6, 10], [1, 1.3, 5], [2, 1.01, 12]], "batl": NaN}, {"timestamp": 1631552208147, "ltp": 4.3, "tv": 9.7, "trd": NaN, "batb": [[0, 1.3, 5], [1, 1.01, 12], [2, 1.01, 0]], "batl": NaN}, {"timestamp": 1631552213024, "ltp": 4.3, "tv": 9.7, "trd": NaN, "batb": [[0, 9.6, 10], [1, 1.3, 5], [2, 1.01, 12]], "batl": NaN}, {"timestamp": 1631552670835, "ltp": 4.3, "tv": 9.69, "trd": [[4.3, 6.93], [5, 2.77]], "batb": [[0, 1.3, 5], [1, 1.01, 12], [2, 1.01, 0]], "batl": NaN}, {"timestamp": 1631552675725, "ltp": 4.3, "tv": 9.69, "trd": NaN, "batb": [[0, 11, 10], [1, 1.3, 5], [2, 1.01, 12]], "batl": NaN}, {"timestamp": 1631552700469, "ltp": 4.3, "tv": 9.69, "trd": NaN, "batb": [[0, 1.3, 5], [1, 1.01, 12], [2, 1.01, 0]], "batl": NaN}, {"timestamp": 1631552705448, "ltp": 4.3, "tv": 9.69, "trd": NaN, "batb": [[0, 14, 10], [1, 1.3, 5], [2, 1.01, 12]], "batl": NaN}, {"timestamp": 1631552726292, "ltp": 4.3, "tv": 9.69, "trd": NaN, "batb": [[0, 1.3, 5], [1, 1.01, 12], [2, 1.01, 0]], "batl": NaN}, {"timestamp": 1631552731188, "ltp": 4.3, "tv": 9.69, "trd": NaN, "batb": [[0, 11, 10], [1, 1.3, 5], [2, 1.01, 12]], "batl": NaN}, {"timestamp": 1631552751838, "ltp": 4.3, "tv": 9.69, "trd": NaN, "batb": [[0, 1.3, 5], [1, 1.01, 12], [2, 1.01, 0]], "batl": NaN}, {"timestamp": 1631552756844, "ltp": 4.3, "tv": 9.69, "trd": NaN, "batb": [[0, 12, 10], [1, 1.3, 5], [2, 1.01, 12]], "batl": NaN}, {"timestamp": 1631552781047, "ltp": 4.3, "tv": 9.69, "trd": NaN, "batb": [[0, 1.3, 5], [1, 1.01, 12], [2, 1.01, 0]], "batl": NaN}, {"timestamp": 1631552786057, "ltp": 4.3, "tv": 9.69, "trd": NaN, "batb": [[0, 14, 10], [1, 1.3, 5], [2, 1.01, 12]], "batl": NaN}, {"timestamp": 1631552857562, "ltp": 4.3, "tv": 9.69, "trd": NaN, "batb": [[0, 1.3, 5], [1, 1.01, 12], [2, 1.01, 0]], "batl": NaN}, {"timestamp": 1631552862460, "ltp": 4.3, "tv": 9.69, "trd": NaN, "batb": [[0, 12, 10], [1, 1.3, 5], [2, 1.01, 12]], "batl": NaN}, {"timestamp": 1631552891292, "ltp": 4.3, "tv": 9.69, "trd": NaN, "batb": [[0, 1.3, 5], [1, 1.01, 12], [2, 1.01, 0]], "batl": NaN}, {"timestamp": 1631552896200, "ltp": 4.3, "tv": 9.69, "trd": NaN, "batb": [[0, 10, 10], [1, 1.3, 5], [2, 1.01, 12]], "batl": NaN}, {"timestamp": 1631552916946, "ltp": 4.3, "tv": 9.69, "trd": NaN, "batb": [[0, 1.3, 5], [1, 1.01, 12], [2, 1.01, 0]], "batl": NaN}, {"timestamp": 1631552921849, "ltp": 4.3, "tv": 9.69, "trd": NaN, "batb": [[0, 11, 10], [1, 1.3, 5], [2, 1.01, 12]], "batl": NaN}, {"timestamp": 1631552940040, "ltp": 4.3, "tv": 9.69, "trd": NaN, "batb": [[0, 1.3, 5], [1, 1.01, 12], [2, 1.01, 0]], "batl": NaN}, {"timestamp": 1631552945048, "ltp": 4.3, "tv": 9.69, "trd": NaN, "batb": [[0, 12, 10], [1, 1.3, 5], [2, 1.01, 12]], "batl": NaN}, {"timestamp": 1631552950836, "ltp": 4.3, "tv": 9.69, "trd": NaN, "batb": [[0, 1.3, 5], [1, 1.01, 12], [2, 1.01, 0]], "batl": NaN}, {"timestamp": 1631552955786, "ltp": 4.3, "tv": 9.69, "trd": NaN, "batb": [[0, 10, 10], [1, 1.3, 5], [2, 1.01, 12]], "batl": NaN}, {"timestamp": 1631552984734, "ltp": 4.3, "tv": 9.69, "trd": NaN, "batb": [[0, 1.3, 5], [1, 1.01, 12], [2, 1.01, 0]], "batl": NaN}, {"timestamp": 1631552989616, "ltp": 4.3, "tv": 9.69, "trd": NaN, "batb": [[0, 8.6, 10], [1, 1.3, 5], [2, 1.01, 12]], "batl": NaN}, {"timestamp": 1631553037478, "ltp": 4.3, "tv": 9.69, "trd": NaN, "batb": [[0, 1.3, 5], [1, 1.01, 12], [2, 1.01, 0]], "batl": NaN}, {"timestamp": 1631553042501, "ltp": 4.3, "tv": 9.69, "trd": NaN, "batb": [[0, 10, 10], [1, 1.3, 5], [2, 1.01, 12]], "batl": NaN}, {"timestamp": 1631553077332, "ltp": 4.3, "tv": 9.69, "trd": NaN, "batb": [[0, 1.3, 5], [1, 1.01, 12], [2, 1.01, 0]], "batl": NaN}, {"timestamp": 1631553082333, "ltp": 4.3, "tv": 9.69, "trd": NaN, "batb": [[0, 11, 10], [1, 1.3, 5], [2, 1.01, 12]], "batl": NaN}, {"timestamp": 1631553121475, "ltp": 4.3, "tv": 9.69, "trd": NaN, "batb": [[0, 1.3, 5], [1, 1.01, 12], [2, 1.01, 0]], "batl": NaN}, {"timestamp": 1631553126385, "ltp": 4.3, "tv": 9.69, "trd": NaN, "batb": [[0, 12, 10], [1, 1.3, 5], [2, 1.01, 12]], "batl": NaN}, {"timestamp": 1631553157830, "ltp": 4.3, "tv": 9.69, "trd": NaN, "batb": [[0, 1.3, 5], [1, 1.01, 12], [2, 1.01, 0]], "batl": NaN}, {"timestamp": 1631553162731, "ltp": 4.3, "tv": 9.69, "trd": NaN, "batb": [[0, 14, 10], [1, 1.3, 5], [2, 1.01, 12]], "batl": NaN}, {"timestamp": 1631553270090, "ltp": 4.3, "tv": 9.69, "trd": NaN, "batb": [[0, 1.3, 5], [1, 1.01, 12], [2, 1.01, 0]], "batl": NaN}, {"timestamp": 1631553274998, "ltp": 4.3, "tv": 9.69, "trd": NaN, "batb": [[0, 16, 10], [1, 1.3, 5], [2, 1.01, 12]], "batl": NaN}, {"timestamp": 1631553307127, "ltp": 4.3, "tv": 9.69, "trd": NaN, "batb": [[0, 1.3, 5], [1, 1.01, 12], [2, 1.01, 0]], "batl": NaN}, {"timestamp": 1631553312107, "ltp": 4.3, "tv": 9.69, "trd": NaN, "batb": [[0, 14, 10], [1, 1.3, 5], [2, 1.01, 12]], "batl": NaN}, {"timestamp": 1631553331569, "ltp": 4.3, "tv": 9.69, "trd": NaN, "batb": [[0, 1.3, 5], [1, 1.01, 12], [2, 1.01, 0]], "batl": NaN}, {"timestamp": 1631553336468, "ltp": 4.3, "tv": 9.69, "trd": NaN, "batb": [[0, 16, 10], [1, 1.3, 5], [2, 1.01, 12]], "batl": NaN}, {"timestamp": 1631553375954, "ltp": 4.3, "tv": 9.69, "trd": NaN, "batb": [[0, 1.3, 5], [1, 1.01, 12], [2, 1.01, 0]], "batl": NaN}, {"timestamp": 1631553380796, "ltp": 4.3, "tv": 9.69, "trd": NaN, "batb": [[0, 19.5, 10], [1, 1.3, 5], [2, 1.01, 12]], "batl": NaN}, {"timestamp": 1631553408838, "ltp": 4.3, "tv": 9.69, "trd": NaN, "batb": [[0, 1.3, 5], [1, 1.01, 12], [2, 1.01, 0]], "batl": NaN}, {"timestamp": 1631553413841, "ltp": 4.3, "tv": 9.69, "trd": NaN, "batb": [[0, 24, 10], [1, 1.3, 5], [2, 1.01, 12]], "batl": NaN}, {"timestamp": 1631553459836, "ltp": 4.3, "tv": 9.69, "trd": NaN, "batb": [[0, 1.3, 5], [1, 1.01, 12], [2, 1.01, 0]], "batl": NaN}, {"timestamp": 1631553464784, "ltp": 4.3, "tv": 9.69, "trd": NaN, "batb": [[0, 19.5, 10], [1, 1.3, 5], [2, 1.01, 12]], "batl": NaN}, {"timestamp": 1631553504239, "ltp": 4.3, "tv": 9.69, "trd": NaN, "batb": [[0, 1.3, 5], [1, 1.01, 12], [2, 1.01, 0]], "batl": NaN}, {"timestamp": 1631553509242, "ltp": 4.3, "tv": 9.69, "trd": NaN, "batb": [[0, 24, 10], [1, 1.3, 5], [2, 1.01, 12]], "batl": NaN}, {"timestamp": 1631553527290, "ltp": 4.3, "tv": 9.69, "trd": NaN, "batb": [[0, 1.3, 5], [1, 1.01, 12], [2, 1.01, 0]], "batl": NaN}, {"timestamp": 1631553532288, "ltp": 4.3, "tv": 9.69, "trd": NaN, "batb": [[0, 19.5, 10], [1, 1.3, 5], [2, 1.01, 12]], "batl": NaN}, {"timestamp": 1631553568357, "ltp": 4.3, "tv": 9.69, "trd": NaN, "batb": [[0, 1.3, 5], [1, 1.01, 12], [2, 1.01, 0]], "batl": NaN}, {"timestamp": 1631553573353, "ltp": 4.3, "tv": 9.69, "trd": NaN, "batb": [[0, 16, 10], [1, 1.3, 5], [2, 1.01, 12]], "batl": NaN}, {"timestamp": 1631553624786, "ltp": 4.3, "tv": 9.69, "trd": NaN, "batb": [[0, 1.3, 5], [1, 1.01, 12], [2, 1.01, 0]], "batl": NaN}, {"timestamp": 1631553629798, "ltp": 4.3, "tv": 9.69, "trd": NaN, "batb": [[0, 24, 10], [1, 1.3, 5], [2, 1.01, 12]], "batl": NaN}, {"timestamp": 1631553653686, "ltp": 4.3, "tv": 9.69, "trd": NaN, "batb": [[0, 1.3, 5], [1, 1.01, 12], [2, 1.01, 0]], "batl": NaN}, {"timestamp": 1631553658423, "ltp": 4.3, "tv": 9.69, "trd": NaN, "batb": [[0, 19.5, 10], [1, 1.3, 5], [2, 1.01, 12]], "batl": NaN}, {"timestamp": 1631553671558, "ltp": 4.3, "tv": 9.69, "trd": NaN, "batb": [[0, 1.3, 5], [1, 1.01, 12], [2, 1.01, 0]], "batl": NaN}, {"timestamp": 1631553676481, "ltp": 4.3, "tv": 9.69, "trd": NaN, "batb": [[0, 16, 10], [1, 1.3, 5], [2, 1.01, 12]], "batl": NaN}, {"timestamp": 1631553726067, "ltp": 4.3, "tv": 9.69, "trd": NaN, "batb": [[0, 1.3, 5], [1, 1.01, 12], [2, 1.01, 0]], "batl": NaN}, {"timestamp": 1631553731057, "ltp": 4.3, "tv": 9.69, "trd": NaN, "batb": [[0, 12, 10], [1, 1.3, 5], [2, 1.01, 12]], "batl": NaN}, {"timestamp": 1631553825260, "ltp": 4.3, "tv": 9.69, "trd": NaN, "batb": [[0, 1.3, 5], [1, 1.01, 12], [2, 1.01, 0]], "batl": NaN}, {"timestamp": 1631553830257, "ltp": 4.3, "tv": 9.69, "trd": NaN, "batb": [[0, 10, 10], [1, 1.3, 5], [2, 1.01, 12]], "batl": NaN}, {"timestamp": 1631553844692, "ltp": 4.3, "tv": 9.69, "trd": NaN, "batb": [[0, 1.3, 5], [1, 1.01, 12], [2, 1.01, 0]], "batl": NaN}, {"timestamp": 1631553849694, "ltp": 4.3, "tv": 9.69, "trd": NaN, "batb": [[0, 8.6, 10], [1, 1.3, 5], [2, 1.01, 12]], "batl": NaN}, {"timestamp": 1631553879119, "ltp": 4.3, "tv": 9.69, "trd": NaN, "batb": [[0, 1.3, 5], [1, 1.01, 12], [2, 1.01, 0]], "batl": NaN}, {"timestamp": 1631553884125, "ltp": 4.3, "tv": 9.69, "trd": NaN, "batb": [[0, 10, 10], [1, 1.3, 5], [2, 1.01, 12]], "batl": NaN}, {"timestamp": 1631553914156, "ltp": 4.3, "tv": 9.69, "trd": NaN, "batb": [[0, 1.3, 5], [1, 1.01, 12], [2, 1.01, 0]], "batl": NaN}, {"timestamp": 1631553919066, "ltp": 4.3, "tv": 9.69, "trd": NaN, "batb": [[0, 12, 10], [1, 1.3, 5], [2, 1.01, 12]], "batl": NaN}, {"timestamp": 1631553939008, "ltp": 4.3, "tv": 9.69, "trd": NaN, "batb": [[0, 1.3, 5], [1, 1.01, 12], [2, 1.01, 0]], "batl": NaN}, {"timestamp": 1631553943914, "ltp": 4.3, "tv": 9.69, "trd": NaN, "batb": [[0, 9.6, 10], [1, 1.3, 5], [2, 1.01, 12]], "batl": NaN}, {"timestamp": 1631553957730, "ltp": 4.3, "tv": 9.69, "trd": NaN, "batb": [[0, 1.3, 5], [1, 1.01, 12], [2, 1.01, 0]], "batl": NaN}, {"timestamp": 1631553962745, "ltp": 4.3, "tv": 9.69, "trd": NaN, "batb": [[0, 10, 10], [1, 1.3, 5], [2, 1.01, 12]], "batl": NaN}, {"timestamp": 1631553970738, "ltp": 4.3, "tv": 9.69, "trd": NaN, "batb": [[0, 1.3, 5], [1, 1.01, 12], [2, 1.01, 0]], "batl": NaN}, {"timestamp": 1631553975663, "ltp": 4.3, "tv": 9.69, "trd": NaN, "batb": [[0, 7.6, 10], [1, 1.3, 5], [2, 1.01, 12]], "batl": NaN}, {"timestamp": 1631554043634, "ltp": 4.3, "tv": 9.69, "trd": NaN, "batb": [[0, 1.3, 5], [1, 1.01, 12], [2, 1.01, 0]], "batl": NaN}, {"timestamp": 1631554048622, "ltp": 4.3, "tv": 9.69, "trd": NaN, "batb": [[0, 6, 10], [1, 1.3, 5], [2, 1.01, 12]], "batl": NaN}, {"timestamp": 1631554073364, "ltp": 4.3, "tv": 9.69, "trd": NaN, "batb": [[0, 1.3, 5], [1, 1.01, 12], [2, 1.01, 0]], "batl": NaN}, {"timestamp": 1631554078371, "ltp": 4.3, "tv": 9.69, "trd": NaN, "batb": [[0, 7.6, 10], [1, 1.3, 5], [2, 1.01, 12]], "batl": NaN}, {"timestamp": 1631554119796, "ltp": 4.3, "tv": 9.69, "trd": NaN, "batb": [[0, 1.3, 5], [1, 1.01, 12], [2, 1.01, 0]], "batl": NaN}, {"timestamp": 1631554124732, "ltp": 4.3, "tv": 9.69, "trd": NaN, "batb": [[0, 8.6, 10], [1, 1.3, 5], [2, 1.01, 12]], "batl": NaN}, {"timestamp": 1631554161094, "ltp": 4.3, "tv": 9.69, "trd": NaN, "batb": [[0, 1.3, 5], [1, 1.01, 12], [2, 1.01, 0]], "batl": NaN}, {"timestamp": 1631554166058, "ltp": 4.3, "tv": 9.69, "trd": NaN, "batb": [[0, 10, 10], [1, 1.3, 5], [2, 1.01, 12]], "batl": NaN}, {"timestamp": 1631554194906, "ltp": 4.3, "tv": 9.69, "trd": NaN, "batb": [[0, 1.3, 5], [1, 1.01, 12], [2, 1.01, 0]], "batl": NaN}, {"timestamp": 1631554199816, "ltp": 4.3, "tv": 9.69, "trd": NaN, "batb": [[0, 12, 10], [1, 1.3, 5], [2, 1.01, 12]], "batl": NaN}, {"timestamp": 1631554300633, "ltp": 4.3, "tv": 9.69, "trd": NaN, "batb": [[0, 1.3, 5], [1, 1.01, 12], [2, 1.01, 0]], "batl": NaN}, {"timestamp": 1631554305640, "ltp": 4.3, "tv": 9.69, "trd": NaN, "batb": [[0, 16, 10], [1, 1.3, 5], [2, 1.01, 12]], "batl": NaN}, {"timestamp": 1631554318663, "ltp": 4.3, "tv": 9.69, "trd": NaN, "batb": [[0, 1.3, 5], [1, 1.01, 12], [2, 1.01, 0]], "batl": NaN}, {"timestamp": 1631554323663, "ltp": 4.3, "tv": 9.69, "trd": NaN, "batb": [[0, 12, 10], [1, 1.3, 5], [2, 1.01, 12]], "batl": NaN}, {"timestamp": 1631554358799, "ltp": 4.3, "tv": 9.69, "trd": NaN, "batb": [[0, 1.3, 5], [1, 1.01, 12], [2, 1.01, 0]], "batl": NaN}, {"timestamp": 1631554363818, "ltp": 4.3, "tv": 9.69, "trd": NaN, "batb": [[0, 10, 10], [1, 1.3, 5], [2, 1.01, 12]], "batl": NaN}, {"timestamp": 1631554395480, "ltp": 4.3, "tv": 9.69, "trd": NaN, "batb": [[0, 1.3, 5], [1, 1.01, 12], [2, 1.01, 0]], "batl": NaN}, {"timestamp": 1631554400379, "ltp": 4.3, "tv": 9.69, "trd": NaN, "batb": [[0, 8, 10], [1, 1.3, 5], [2, 1.01, 12]], "batl": NaN}, {"timestamp": 1631554449248, "ltp": 4.3, "tv": 9.69, "trd": NaN, "batb": [[0, 1.3, 5], [1, 1.01, 12], [2, 1.01, 0]], "batl": NaN}, {"timestamp": 1631554454033, "ltp": 4.3, "tv": 9.69, "trd": NaN, "batb": [[0, 8.6, 10], [1, 1.3, 5], [2, 1.01, 12]], "batl": NaN}, {"timestamp": 1631554501843, "ltp": 4.3, "tv": 9.69, "trd": NaN, "batb": [[0, 1.3, 5], [1, 1.01, 12], [2, 1.01, 0]], "batl": NaN}, {"timestamp": 1631554506703, "ltp": 4.3, "tv": 9.69, "trd": NaN, "batb": [[0, 12, 10], [1, 1.3, 5], [2, 1.01, 12]], "batl": NaN}, {"timestamp": 1631554530548, "ltp": 4.3, "tv": 9.69, "trd": NaN, "batb": [[0, 1.3, 5], [1, 1.01, 12], [2, 1.01, 0]], "batl": NaN}, {"timestamp": 1631554535434, "ltp": 4.3, "tv": 9.69, "trd": NaN, "batb": [[0, 8.6, 10], [1, 1.3, 5], [2, 1.01, 12]], "batl": NaN}, {"timestamp": 1631554560900, "ltp": 8.6, "tv": 14.73, "trd": [[8.6, 5.04]], "batb": [[0, 1.3, 5], [1, 1.01, 12], [2, 1.01, 0]], "batl": NaN}, {"timestamp": 1631554565773, "ltp": 8.6, "tv": 14.73, "trd": NaN, "batb": [[0, 9.6, 10], [1, 1.3, 5], [2, 1.01, 12]], "batl": NaN}, {"timestamp": 1631554585197, "ltp": 8.6, "tv": 14.73, "trd": NaN, "batb": [[0, 1.3, 5], [1, 1.01, 12], [2, 1.01, 0]], "batl": NaN}, {"timestamp": 1631554590185, "ltp": 8.6, "tv": 14.73, "trd": NaN, "batb": [[0, 7.6, 10], [1, 1.3, 5], [2, 1.01, 12]], "batl": NaN}, {"timestamp": 1631554636737, "ltp": 8.6, "tv": 14.73, "trd": NaN, "batb": [[0, 1.3, 5], [1, 1.01, 12], [2, 1.01, 0]], "batl": NaN}, {"timestamp": 1631554641636, "ltp": 8.6, "tv": 14.73, "trd": NaN, "batb": [[0, 6, 10], [1, 1.3, 5], [2, 1.01, 12]], "batl": NaN}, {"timestamp": 1631554667299, "ltp": 8.6, "tv": 14.73, "trd": NaN, "batb": [[0, 1.3, 5], [1, 1.01, 12], [2, 1.01, 0]], "batl": NaN}, {"timestamp": 1631554672185, "ltp": 8.6, "tv": 14.73, "trd": NaN, "batb": [[0, 7.6, 10], [1, 1.3, 5], [2, 1.01, 12]], "batl": NaN}, {"timestamp": 1631554714314, "ltp": 8.6, "tv": 14.73, "trd": NaN, "batb": [[0, 1.3, 5], [1, 1.01, 12], [2, 1.01, 0]], "batl": NaN}, {"timestamp": 1631554719309, "ltp": 8.6, "tv": 14.73, "trd": NaN, "batb": [[0, 8.6, 10], [1, 1.3, 5], [2, 1.01, 12]], "batl": NaN}, {"timestamp": 1631554742858, "ltp": 8.6, "tv": 14.73, "trd": NaN, "batb": [[0, 1.3, 5], [1, 1.01, 12], [2, 1.01, 0]], "batl": NaN}, {"timestamp": 1631554747749, "ltp": 8.6, "tv": 14.73, "trd": NaN, "batb": [[0, 10, 10], [1, 1.3, 5], [2, 1.01, 12]], "batl": NaN}, {"timestamp": 1631554773290, "ltp": 8.6, "tv": 14.73, "trd": NaN, "batb": [[0, 1.3, 5], [1, 1.01, 12], [2, 1.01, 0]], "batl": NaN}, {"timestamp": 1631554778211, "ltp": 8.6, "tv": 14.73, "trd": NaN, "batb": [[0, 12, 10], [1, 1.3, 5], [2, 1.01, 12]], "batl": NaN}, {"timestamp": 1631554889447, "ltp": 8.6, "tv": 14.73, "trd": NaN, "batb": [[0, 1.3, 5], [1, 1.01, 12], [2, 1.01, 0]], "batl": NaN}, {"timestamp": 1631554894381, "ltp": 8.6, "tv": 14.73, "trd": NaN, "batb": [[0, 16, 10], [1, 1.3, 5], [2, 1.01, 12]], "batl": NaN}, {"timestamp": 1631554917023, "ltp": 8.6, "tv": 14.73, "trd": NaN, "batb": [[0, 1.3, 5], [1, 1.01, 12], [2, 1.01, 0]], "batl": NaN}, {"timestamp": 1631554921932, "ltp": 8.6, "tv": 14.73, "trd": NaN, "batb": [[0, 12, 10], [1, 1.3, 5], [2, 1.01, 12]], "batl": NaN}, {"timestamp": 1631554942322, "ltp": 8.6, "tv": 14.73, "trd": NaN, "batb": [[0, 1.3, 5], [1, 1.01, 12], [2, 1.01, 0]], "batl": NaN}, {"timestamp": 1631554947138, "ltp": 8.6, "tv": 14.73, "trd": NaN, "batb": [[0, 14, 10], [1, 1.3, 5], [2, 1.01, 12]], "batl": NaN}, {"timestamp": 1631554972791, "ltp": 8.6, "tv": 14.73, "trd": NaN, "batb": [[0, 1.3, 5], [1, 1.01, 12], [2, 1.01, 0]], "batl": NaN}, {"timestamp": 1631554977798, "ltp": 8.6, "tv": 14.73, "trd": NaN, "batb": [[0, 9.6, 10], [1, 1.3, 5], [2, 1.01, 12]], "batl": NaN}, {"timestamp": 1631555008625, "ltp": 8.6, "tv": 14.73, "trd": NaN, "batb": [[0, 1.3, 5], [1, 1.01, 12], [2, 1.01, 0]], "batl": NaN}, {"timestamp": 1631555013558, "ltp": 8.6, "tv": 14.73, "trd": NaN, "batb": [[0, 12, 10], [1, 1.3, 5], [2, 1.01, 12]], "batl": NaN}, {"timestamp": 1631555037991, "ltp": 8.6, "tv": 14.73, "trd": NaN, "batb": [[0, 1.3, 5], [1, 1.01, 12], [2, 1.01, 0]], "batl": NaN}, {"timestamp": 1631555042863, "ltp": 8.6, "tv": 14.73, "trd": NaN, "batb": [[0, 8.6, 10], [1, 1.3, 5], [2, 1.01, 12]], "batl": NaN}, {"timestamp": 1631555070516, "ltp": 8.6, "tv": 14.73, "trd": NaN, "batb": [[0, 1.3, 5], [1, 1.01, 12], [2, 1.01, 0]], "batl": NaN}, {"timestamp": 1631555075543, "ltp": 8.6, "tv": 14.73, "trd": NaN, "batb": [[0, 9.6, 10], [1, 1.3, 5], [2, 1.01, 12]], "batl": NaN}, {"timestamp": 1631555083550, "ltp": 8.6, "tv": 14.73, "trd": NaN, "batb": [[0, 1.3, 5], [1, 1.01, 12], [2, 1.01, 0]], "batl": NaN}, {"timestamp": 1631555088567, "ltp": 8.6, "tv": 14.73, "trd": NaN, "batb": [[0, 12, 10], [1, 1.3, 5], [2, 1.01, 12]], "batl": NaN}, {"timestamp": 1631555109545, "ltp": 8.6, "tv": 14.73, "trd": NaN, "batb": [[0, 1.3, 5], [1, 1.01, 12], [2, 1.01, 0]], "batl": NaN}, {"timestamp": 1631555114459, "ltp": 8.6, "tv": 14.73, "trd": NaN, "batb": [[0, 14, 10], [1, 1.3, 5], [2, 1.01, 12]], "batl": NaN}, {"timestamp": 1631555132020, "ltp": 8.6, "tv": 14.73, "trd": NaN, "batb": [[0, 1.3, 5], [1, 1.01, 12], [2, 1.01, 0]], "batl": NaN}, {"timestamp": 1631555136995, "ltp": 8.6, "tv": 14.73, "trd": NaN, "batb": [[0, 8.6, 10], [1, 1.3, 5], [2, 1.01, 12]], "batl": NaN}, {"timestamp": 1631555167479, "ltp": 8.6, "tv": 14.73, "trd": NaN, "batb": [[0, 1.3, 5], [1, 1.01, 12], [2, 1.01, 0]], "batl": NaN}, {"timestamp": 1631555172346, "ltp": 8.6, "tv": 14.73, "trd": NaN, "batb": [[0, 7.6, 10], [1, 1.3, 5], [2, 1.01, 12]], "batl": NaN}, {"timestamp": 1631555213718, "ltp": 8.6, "tv": 14.73, "trd": NaN, "batb": [[0, 1.3, 5], [1, 1.01, 12], [2, 1.01, 0]], "batl": NaN}, {"timestamp": 1631555218685, "ltp": 8.6, "tv": 14.73, "trd": NaN, "batb": [[0, 8, 10], [1, 1.3, 5], [2, 1.01, 12]], "batl": NaN}, {"timestamp": 1631555250357, "ltp": 8.6, "tv": 14.73, "trd": NaN, "batb": [[0, 1.3, 5], [1, 1.01, 12], [2, 1.01, 0]], "batl": NaN}, {"timestamp": 1631555255342, "ltp": 8.6, "tv": 14.73, "trd": NaN, "batb": [[0, 9.6, 10], [1, 1.3, 5], [2, 1.01, 12]], "batl": NaN}, {"timestamp": 1631555289074, "ltp": 8.6, "tv": 14.73, "trd": NaN, "batb": [[0, 1.3, 5], [1, 1.01, 12], [2, 1.01, 0]], "batl": NaN}, {"timestamp": 1631555293995, "ltp": 8.6, "tv": 14.73, "trd": NaN, "batb": [[0, 8, 10], [1, 1.3, 5], [2, 1.01, 12]], "batl": NaN}, {"timestamp": 1631555323431, "ltp": 8.6, "tv": 14.73, "trd": NaN, "batb": [[0, 1.3, 5], [1, 1.01, 12], [2, 1.01, 0]], "batl": NaN}, {"timestamp": 1631555328338, "ltp": 8.6, "tv": 14.73, "trd": NaN, "batb": [[0, 10, 10], [1, 1.3, 5], [2, 1.01, 12]], "batl": NaN}, {"timestamp": 1631555484611, "ltp": 8.6, "tv": 14.73, "trd": NaN, "batb": [[0, 1.3, 5], [1, 1.01, 12], [2, 1.01, 0]], "batl": NaN}, {"timestamp": 1631555489537, "ltp": 8.6, "tv": 14.73, "trd": NaN, "batb": [[0, 11, 10], [1, 1.3, 5], [2, 1.01, 12]], "batl": NaN}, {"timestamp": 1631555502662, "ltp": 8.6, "tv": 14.73, "trd": NaN, "batb": [[0, 1.3, 5], [1, 1.01, 12], [2, 1.01, 0]], "batl": NaN}, {"timestamp": 1631555507632, "ltp": 8.6, "tv": 14.73, "trd": NaN, "batb": [[0, 14, 10], [1, 1.3, 5], [2, 1.01, 12]], "batl": NaN}, {"timestamp": 1631555532986, "ltp": 8.6, "tv": 14.73, "trd": NaN, "batb": [[0, 1.3, 5], [1, 1.01, 12], [2, 1.01, 0]], "batl": NaN}, {"timestamp": 1631555537907, "ltp": 8.6, "tv": 14.73, "trd": NaN, "batb": [[0, 10, 10], [1, 1.3, 5], [2, 1.01, 12]], "batl": NaN}, {"timestamp": 1631555567142, "ltp": 8.6, "tv": 14.73, "trd": NaN, "batb": [[0, 1.3, 5], [1, 1.01, 12], [2, 1.01, 0]], "batl": NaN}, {"timestamp": 1631555572142, "ltp": 8.6, "tv": 14.73, "trd": NaN, "batb": [[0, 16, 10], [1, 1.3, 5], [2, 1.01, 12]], "batl": NaN}, {"timestamp": 1631555603491, "ltp": 8.6, "tv": 14.73, "trd": NaN, "batb": [[0, 1.3, 5], [1, 1.01, 12], [2, 1.01, 0]], "batl": NaN}, {"timestamp": 1631555608476, "ltp": 8.6, "tv": 14.73, "trd": NaN, "batb": [[0, 24, 10], [1, 1.3, 5], [2, 1.01, 12]], "batl": NaN}, {"timestamp": 1631555632829, "ltp": 8.6, "tv": 14.73, "trd": NaN, "batb": [[0, 1.3, 5], [1, 1.01, 12], [2, 1.01, 0]], "batl": NaN}, {"timestamp": 1631555637798, "ltp": 8.6, "tv": 14.73, "trd": NaN, "batb": [[0, 19.5, 10], [1, 1.3, 5], [2, 1.01, 12]], "batl": NaN}, {"timestamp": 1631555656242, "ltp": 8.6, "tv": 14.73, "trd": NaN, "batb": [[0, 1.3, 5], [1, 1.01, 12], [2, 1.01, 0]], "batl": NaN}]}]}