{"info": {"id": "1.187557146", "eventId": "30895970", "eventName": "Match Odds", "marketType": "MATCH_ODDS", "openDate": 1631527537376, "name": "Bega v Ti Droguet", "numberOfActiveRunner": 2, "countryCode": "", "sport": "TENNIS", "venue": "", "volume": {"total": 37353.7, "preMatch": 30.47, "inPlay": 37323.23}, "winner": {"id": 8257797, "name": "Alessandro Bega", "status": "WINNER", "position": 1}, "delay": 3}, "runners": [{"id": 8257797, "name": "Alessandro Bega", "status": "WINNER", "position": 1, "inPlayOdds": 2.1, "inPlayTime": 1631527537376, "avgPrematch": 2.1, "closedOdds": 1.03, "maxPrematch": 2.1, "minPrematch": 2.1, "maxInPlay": 3.3, "minInPlay": 1.01, "inPlayIndex": 13, "lengthOdds": 2148, "lengthOddsPrematch": 13, "lengthOddsInPlay": 2135, "tradedVolume": 30256.41, "preMatchVolume": 8.8, "inPlayVolume": 30247.61}, {"id": 19931652, "name": "Titouan Droguet", "status": "LOSER", "position": 2, "inPlayOdds": 1.72, "inPlayTime": 1631527537376, "avgPrematch": 1.67, "closedOdds": 20.0, "maxPrematch": 1.72, "minPrematch": 1.66, "maxInPlay": 100.0, "minInPlay": 1.31, "inPlayIndex": 12, "lengthOdds": 1591, "lengthOddsPrematch": 12, "lengthOddsInPlay": 1579, "tradedVolume": 7097.29, "preMatchVolume": 21.67, "inPlayVolume": 7075.62}], "marketUpdates": [{"timestamp": 1631458340232000000, "openDate": "2021-09-13T10:00:00.000Z", "status": "OPEN", "betDelay": 0, "inPlay": false, "complete": true}, {"timestamp": 1631527319243000000, "openDate": "2021-09-13T09:57:00.000Z", "status": "OPEN", "betDelay": 0, "inPlay": false, "complete": true}, {"timestamp": 1631527537376000000, "openDate": "2021-09-13T09:57:00.000Z", "status": "OPEN", "betDelay": 3, "inPlay": true, "complete": true}, {"timestamp": 1631534874348000000, "openDate": "2021-09-13T09:57:00.000Z", "status": "SUSPENDED", "betDelay": 3, "inPlay": true, "complete": true}, {"timestamp": 1631534920596000000, "openDate": "2021-09-13T09:57:00.000Z", "status": "CLOSED", "betDelay": 3, "inPlay": true, "complete": true}], "odds": [{"runnerId": 8257797, "odds": [{"timestamp": 1631514657627, "ltp": 2.1, "tv": 8.79, "trd": [[2.1, 8.8]], "batb": [[0, 2.1, 26.34]], "batl": NaN}, {"timestamp": 1631514662833, "ltp": 2.1, "tv": 8.79, "trd": NaN, "batb": [[0, 2.1, 30.74]], "batl": NaN}, {"timestamp": 1631519787781, "ltp": 2.1, "tv": 8.8, "trd": [[2.1, 8.8]], "batb": [[1, 1.55, 35.48], [2, 1.44, 40.32]], "batl": [[1, 46, 29.07]]}, {"timestamp": 1631520002724, "ltp": 2.1, "tv": 8.8, "trd": NaN, "batb": [[0, 2.1, 40.99]], "batl": NaN}, {"timestamp": 1631520388015, "ltp": 2.1, "tv": 8.8, "trd": NaN, "batb": [[0, 2.1, 37.97]], "batl": NaN}, {"timestamp": 1631521640704, "ltp": 2.1, "tv": 8.8, "trd": NaN, "batb": [[0, 2.2, 34.8]], "batl": NaN}, {"timestamp": 1631523601250, "ltp": 2.1, "tv": 8.8, "trd": NaN, "batb": [[0, 2.22, 10.5], [1, 2.2, 34.8], [2, 1.55, 35.48]], "batl": NaN}, {"timestamp": 1631523718165, "ltp": 2.1, "tv": 8.8, "trd": [[2.1, 8.8]], "batb": [[0, 2.22, 10.5], [2, 1.55, 35.45]], "batl": [[1, 46, 29.05]]}, {"timestamp": 1631524389067, "ltp": 2.1, "tv": 8.8, "trd": NaN, "batb": [[2, 1.41, 23.9]], "batl": NaN}, {"timestamp": 1631524861556, "ltp": 2.1, "tv": 8.8, "trd": NaN, "batb": [[2, 2.14, 2.66]], "batl": NaN}, {"timestamp": 1631527001231, "ltp": 2.1, "tv": 8.8, "trd": NaN, "batb": [[0, 2.26, 10.16], [1, 2.22, 10.5], [2, 2.2, 34.8]], "batl": NaN}, {"timestamp": 1631527167064, "ltp": 2.1, "tv": 8.8, "trd": NaN, "batb": [[1, 2.22, 43.16]], "batl": NaN}, {"timestamp": 1631527536437, "ltp": 2.1, "tv": 8.8, "trd": NaN, "batb": [[1, 2.22, 10.5]], "batl": NaN}, {"timestamp": 1631527537376, "ltp": 2.1, "tv": 8.8, "trd": NaN, "batb": [[0, 1.01, 105.88], [1, 2.22, 0], [2, 2.2, 0]], "batl": NaN}, {"timestamp": 1631527542774, "ltp": 2.4, "tv": 9.41, "trd": [[2.4, 0.61]], "batb": [[0, 2.42, 5.46], [1, 2.36, 94.03], [2, 1.01, 105.88]], "batl": NaN}, {"timestamp": 1631527543856, "ltp": 2.4, "tv": 9.41, "trd": NaN, "batb": [[2, 2.32, 28.47]], "batl": NaN}, {"timestamp": 1631527552269, "ltp": 2.4, "tv": 9.41, "trd": NaN, "batb": [[0, 2.32, 28.47], [1, 2.18, 34.42], [2, 1.03, 494.14]], "batl": NaN}, {"timestamp": 1631527552787, "ltp": 2.4, "tv": 9.41, "trd": NaN, "batb": [[0, 2.18, 34.42], [1, 1.03, 494.14], [2, 1.01, 579.24]], "batl": NaN}, {"timestamp": 1631527556264, "ltp": 2.4, "tv": 9.41, "trd": NaN, "batb": [[1, 1.05, 474.38], [2, 1.03, 494.14]], "batl": NaN}, {"timestamp": 1631527559078, "ltp": 2.4, "tv": 9.41, "trd": NaN, "batb": [[1, 1.11, 269.53], [2, 1.1, 296.48]], "batl": NaN}, {"timestamp": 1631527562302, "ltp": 2.4, "tv": 9.41, "trd": NaN, "batb": [[1, 1.2, 385.43], [2, 1.11, 269.53]], "batl": NaN}, {"timestamp": 1631527565970, "ltp": 2.4, "tv": 9.41, "trd": NaN, "batb": [[1, 1.4, 148.24], [2, 1.3, 197.65]], "batl": NaN}, {"timestamp": 1631527569282, "ltp": 2.4, "tv": 9.41, "trd": NaN, "batb": [[1, 1.6, 98.83], [2, 1.5, 106.73]], "batl": NaN}, {"timestamp": 1631527577340, "ltp": 2.4, "tv": 9.41, "trd": NaN, "batb": NaN, "batl": [[0, 2.5, 279.27]]}, {"timestamp": 1631527578634, "ltp": 2.4, "tv": 9.41, "trd": NaN, "batb": [[1, 2, 43.63], [2, 1.6, 98.83]], "batl": NaN}, {"timestamp": 1631527582321, "ltp": 2.4, "tv": 9.41, "trd": NaN, "batb": NaN, "batl": [[0, 2.32, 41.43], [1, 2.5, 279.27]]}, {"timestamp": 1631527582424, "ltp": 2.4, "tv": 9.41, "trd": NaN, "batb": NaN, "batl": [[0, 2.5, 279.27], [1, 2.5, 0]]}, {"timestamp": 1631527593643, "ltp": 2.4, "tv": 9.41, "trd": NaN, "batb": NaN, "batl": [[0, 2.32, 5.93], [1, 2.5, 279.27]]}, {"timestamp": 1631527595350, "ltp": 2.4, "tv": 9.41, "trd": NaN, "batb": [[0, 2, 43.63], [1, 1.6, 98.83], [2, 1.5, 106.73]], "batl": NaN}, {"timestamp": 1631527621959, "ltp": 2.24, "tv": 16.02, "trd": [[2.24, 6.61]], "batb": [[0, 2.08, 7.86], [1, 2, 103], [2, 1.6, 98.83]], "batl": NaN}, {"timestamp": 1631527623145, "ltp": 2.24, "tv": 16.02, "trd": NaN, "batb": [[2, 1.85, 28.64]], "batl": NaN}, {"timestamp": 1631527627078, "ltp": 2.24, "tv": 31.1, "trd": [[2.24, 21.69]], "batb": NaN, "batl": NaN}, {"timestamp": 1631527630183, "ltp": 2.24, "tv": 31.1, "trd": NaN, "batb": [[0, 2.1, 38.37], [1, 2.08, 7.86], [2, 2, 103]], "batl": NaN}, {"timestamp": 1631527630496, "ltp": 2.24, "tv": 31.1, "trd": NaN, "batb": [[0, 2.08, 7.86], [1, 2, 103], [2, 1.85, 28.64]], "batl": NaN}, {"timestamp": 1631527632099, "ltp": 2.24, "tv": 31.1, "trd": NaN, "batb": [[0, 2, 103], [1, 1.85, 28.64], [2, 1.5, 106.73]], "batl": NaN}, {"timestamp": 1631527634063, "ltp": 2.24, "tv": 31.1, "trd": NaN, "batb": [[0, 2, 43.63]], "batl": NaN}, {"timestamp": 1631527635303, "ltp": 2.24, "tv": 31.1, "trd": NaN, "batb": [[0, 1.85, 28.64], [1, 1.5, 106.73], [2, 1.4, 148.24]], "batl": NaN}, {"timestamp": 1631527641298, "ltp": 2.24, "tv": 31.1, "trd": NaN, "batb": NaN, "batl": [[0, 2.24, 4], [1, 2.26, 223.51]]}, {"timestamp": 1631527652014, "ltp": 2.24, "tv": 31.1, "trd": NaN, "batb": [[1, 1.4, 148.24], [2, 1.3, 197.65]], "batl": [[0, 1.94, 12.5], [1, 2.16, 568.37]]}, {"timestamp": 1631527652991, "ltp": 2.24, "tv": 31.1, "trd": NaN, "batb": [[1, 1.7, 37.52], [2, 1.4, 148.24]], "batl": NaN}, {"timestamp": 1631527670108, "ltp": 2.24, "tv": 31.1, "trd": NaN, "batb": [[0, 1.7, 37.52], [1, 1.4, 148.24], [2, 1.3, 197.65]], "batl": NaN}, {"timestamp": 1631527677228, "ltp": 2.24, "tv": 31.1, "trd": NaN, "batb": NaN, "batl": [[0, 1.99, 256.44]]}, {"timestamp": 1631527691157, "ltp": 2.24, "tv": 31.1, "trd": NaN, "batb": [[0, 2, 7.26], [1, 1.7, 37.52], [2, 1.4, 148.24]], "batl": [[0, 2.06, 94.66]]}, {"timestamp": 1631527692142, "ltp": 2.24, "tv": 31.1, "trd": NaN, "batb": [[1, 1.95, 48.07], [2, 1.73, 35.42]], "batl": NaN}, {"timestamp": 1631527694271, "ltp": 2.06, "tv": 220.26, "trd": [[2.06, 189.16]], "batb": NaN, "batl": [[0, 2.06, 0.08]]}, {"timestamp": 1631527700262, "ltp": 2.06, "tv": 220.34, "trd": [[2.06, 189.24]], "batb": NaN, "batl": NaN}, {"timestamp": 1631527703472, "ltp": 2.06, "tv": 220.34, "trd": NaN, "batb": NaN, "batl": [[0, 2.86, 5.31]]}, {"timestamp": 1631527704361, "ltp": 2.06, "tv": 220.34, "trd": NaN, "batb": [[0, 1.95, 48.07], [1, 1.73, 35.42], [2, 1.5, 106.73]], "batl": NaN}, {"timestamp": 1631527706176, "ltp": 2.06, "tv": 220.34, "trd": NaN, "batb": [[0, 1.73, 35.42], [1, 1.5, 106.73], [2, 1.4, 148.24]], "batl": NaN}, {"timestamp": 1631527707267, "ltp": 2.06, "tv": 220.34, "trd": NaN, "batb": NaN, "batl": [[0, 2.08, 7.51]]}, {"timestamp": 1631527741131, "ltp": 2.06, "tv": 220.34, "trd": NaN, "batb": [[0, 1.76, 18.46], [1, 1.73, 35.42], [2, 1.5, 106.73]], "batl": [[0, 1.86, 189.75]]}, {"timestamp": 1631527742121, "ltp": 2.06, "tv": 220.34, "trd": NaN, "batb": [[2, 1.66, 40.62]], "batl": NaN}, {"timestamp": 1631527746012, "ltp": 1.76, "tv": 257.26, "trd": [[1.76, 36.92]], "batb": [[0, 1.73, 35.42], [1, 1.66, 40.62], [2, 1.3, 197.65]], "batl": NaN}, {"timestamp": 1631527759224, "ltp": 1.76, "tv": 257.26, "trd": NaN, "batb": [[0, 1.74, 12.84], [1, 1.73, 35.42], [2, 1.66, 40.62]], "batl": [[0, 1.78, 12.19], [1, 1.86, 189.75]]}, {"timestamp": 1631527768462, "ltp": 1.78, "tv": 277.26, "trd": [[1.78, 20]], "batb": NaN, "batl": [[0, 1.78, 2.19]]}, {"timestamp": 1631527771154, "ltp": 1.78, "tv": 281.26, "trd": [[1.78, 24]], "batb": NaN, "batl": [[0, 1.86, 189.94], [1, 1.86, 0]]}, {"timestamp": 1631527778675, "ltp": 1.78, "tv": 281.26, "trd": NaN, "batb": [[0, 1.73, 35.42], [1, 1.66, 40.62], [2, 1.3, 197.65]], "batl": [[0, 1.86, 189.75]]}, {"timestamp": 1631527784843, "ltp": 1.78, "tv": 281.26, "trd": NaN, "batb": [[0, 1.76, 12.13], [1, 1.73, 35.42], [2, 1.66, 40.62]], "batl": [[0, 1.8, 11.89], [1, 1.86, 189.75]]}, {"timestamp": 1631527799467, "ltp": 1.78, "tv": 281.26, "trd": NaN, "batb": [[0, 1.76, 120.13]], "batl": NaN}, {"timestamp": 1631527805291, "ltp": 1.78, "tv": 281.26, "trd": NaN, "batb": [[0, 1.76, 108], [1, 1.66, 40.62], [2, 1.3, 197.65]], "batl": NaN}, {"timestamp": 1631527806116, "ltp": 1.78, "tv": 281.26, "trd": NaN, "batb": [[0, 1.66, 40.62], [1, 1.3, 197.65], [2, 1.25, 237.19]], "batl": NaN}, {"timestamp": 1631527825911, "ltp": 1.78, "tv": 281.26, "trd": NaN, "batb": [[1, 1.31, 768.11], [2, 1.3, 197.65]], "batl": NaN}, {"timestamp": 1631527833317, "ltp": 1.78, "tv": 281.26, "trd": NaN, "batb": NaN, "batl": [[0, 1.72, 9.17], [1, 1.74, 99.6]]}, {"timestamp": 1631527834150, "ltp": 1.78, "tv": 281.26, "trd": NaN, "batb": [[1, 1.61, 45.47], [2, 1.31, 768.11]], "batl": NaN}, {"timestamp": 1631527844476, "ltp": 1.78, "tv": 281.26, "trd": NaN, "batb": [[0, 1.61, 45.47], [1, 1.31, 768.11], [2, 1.3, 197.65]], "batl": NaN}, {"timestamp": 1631527851245, "ltp": 1.78, "tv": 281.26, "trd": NaN, "batb": NaN, "batl": [[0, 810, 0.07]]}, {"timestamp": 1631527858070, "ltp": 1.78, "tv": 281.26, "trd": NaN, "batb": NaN, "batl": [[0, 820, 0.14]]}, {"timestamp": 1631527868291, "ltp": 1.78, "tv": 281.26, "trd": NaN, "batb": NaN, "batl": [[0, 1.7, 1804.62], [1, 1.74, 114.94], [2, 1.77, 8.24]]}, {"timestamp": 1631527869168, "ltp": 1.78, "tv": 281.26, "trd": NaN, "batb": [[1, 1.57, 50.08], [2, 1.31, 768.11]], "batl": [[0, 1.66, 9], [1, 1.68, 109.88], [2, 1.74, 22.98]]}, {"timestamp": 1631527870611, "ltp": 1.78, "tv": 281.26, "trd": NaN, "batb": [[2, 1.44, 443.07]], "batl": NaN}, {"timestamp": 1631527876196, "ltp": 1.78, "tv": 281.26, "trd": NaN, "batb": [[0, 1.57, 50.08], [1, 1.44, 443.07], [2, 1.31, 768.11]], "batl": [[0, 2.16, 348.23], [1, 810, 0.07], [2, 1.74, 0]]}, {"timestamp": 1631527886132, "ltp": 1.78, "tv": 281.26, "trd": NaN, "batb": NaN, "batl": [[0, 1.62, 12.34], [1, 1.64, 140.31], [2, 2.16, 348.23]]}, {"timestamp": 1631527887008, "ltp": 1.78, "tv": 281.26, "trd": NaN, "batb": [[1, 1.54, 53.35], [2, 1.44, 443.07]], "batl": NaN}, {"timestamp": 1631527896931, "ltp": 1.78, "tv": 281.26, "trd": NaN, "batb": NaN, "batl": [[0, 2.16, 348.23], [1, 810, 0.07], [2, 2.16, 0]]}, {"timestamp": 1631527897448, "ltp": 1.78, "tv": 281.26, "trd": NaN, "batb": [[0, 1.54, 53.35], [1, 1.44, 443.07], [2, 1.31, 768.11]], "batl": NaN}, {"timestamp": 1631527921346, "ltp": 1.78, "tv": 281.26, "trd": NaN, "batb": [[1, 1.31, 768.11], [2, 1.3, 197.65]], "batl": [[0, 810, 0.07], [1, 810, 0]]}, {"timestamp": 1631527922237, "ltp": 1.78, "tv": 281.26, "trd": NaN, "batb": [[0, 1.54, 161.47]], "batl": [[0, 1.6, 116.16], [1, 1.63, 122.7], [2, 810, 0.07]]}, {"timestamp": 1631527923245, "ltp": 1.78, "tv": 281.26, "trd": NaN, "batb": [[1, 1.49, 61.55], [2, 1.31, 768.11]], "batl": [[1, 1.63, 24.54]]}, {"timestamp": 1631527923975, "ltp": 1.78, "tv": 281.26, "trd": NaN, "batb": NaN, "batl": [[2, 1.74, 6.38]]}, {"timestamp": 1631527925272, "ltp": 1.78, "tv": 281.26, "trd": NaN, "batb": [[2, 1.38, 455.53]], "batl": NaN}, {"timestamp": 1631527927245, "ltp": 1.78, "tv": 281.26, "trd": NaN, "batb": NaN, "batl": [[0, 1.6, 177.38]]}, {"timestamp": 1631527927657, "ltp": 1.78, "tv": 281.26, "trd": NaN, "batb": NaN, "batl": [[0, 1.6, 116.16], [2, 2.04, 389.06]]}, {"timestamp": 1631527933703, "ltp": 1.78, "tv": 281.26, "trd": NaN, "batb": [[2, 1.31, 768.11]], "batl": [[2, 810, 0.07]]}, {"timestamp": 1631527954307, "ltp": 1.78, "tv": 281.26, "trd": NaN, "batb": [[0, 1.54, 53.35]], "batl": [[0, 810, 0.07], [1, 1.63, 0], [2, 810, 0]]}, {"timestamp": 1631527954722, "ltp": 1.78, "tv": 281.26, "trd": NaN, "batb": [[0, 1.49, 61.55], [1, 1.31, 768.11], [2, 1.3, 197.65]], "batl": NaN}, {"timestamp": 1631527970245, "ltp": 1.78, "tv": 281.26, "trd": NaN, "batb": [[0, 1.5, 7], [1, 1.49, 61.55], [2, 1.47, 162.87]], "batl": [[0, 1.54, 121.73], [1, 810, 0.07]]}, {"timestamp": 1631527975280, "ltp": 1.78, "tv": 281.26, "trd": NaN, "batb": NaN, "batl": [[1, 1.55, 77.4], [2, 810, 0.07]]}, {"timestamp": 1631527975439, "ltp": 1.78, "tv": 281.26, "trd": NaN, "batb": NaN, "batl": [[1, 810, 0.07], [2, 810, 0]]}, {"timestamp": 1631527984358, "ltp": 1.78, "tv": 281.26, "trd": NaN, "batb": [[0, 1.49, 61.55], [1, 1.42, 73.53], [2, 1.31, 768.11]], "batl": [[0, 810, 0.07], [1, 810, 0]]}, {"timestamp": 1631527984779, "ltp": 1.78, "tv": 281.26, "trd": NaN, "batb": [[0, 1.42, 73.53], [1, 1.31, 768.11], [2, 1.25, 237.19]], "batl": NaN}, {"timestamp": 1631527995253, "ltp": 1.78, "tv": 281.26, "trd": NaN, "batb": [[1, 1.41, 151.51], [2, 1.31, 768.11]], "batl": [[0, 1.6, 25], [1, 810, 0.07]]}, {"timestamp": 1631527996155, "ltp": 1.78, "tv": 281.26, "trd": NaN, "batb": [[2, 1.37, 87.35]], "batl": NaN}, {"timestamp": 1631528003290, "ltp": 1.78, "tv": 281.26, "trd": NaN, "batb": [[0, 1.44, 127], [1, 1.42, 73.53], [2, 1.41, 151.51]], "batl": [[0, 1.56, 13.76], [1, 1.6, 25], [2, 810, 0.07]]}, {"timestamp": 1631528004908, "ltp": 1.78, "tv": 281.26, "trd": NaN, "batb": [[0, 1.37, 87.35], [1, 1.31, 768.11], [2, 1.2, 385.43]], "batl": [[0, 810, 0.07], [1, 1.6, 0], [2, 810, 0]]}, {"timestamp": 1631528013173, "ltp": 1.78, "tv": 281.26, "trd": NaN, "batb": [[0, 1.48, 12.62], [1, 1.37, 87.35], [2, 1.31, 768.11]], "batl": [[0, 1.5, 5.07], [1, 1.52, 147.98], [2, 810, 0.07]]}, {"timestamp": 1631528014100, "ltp": 1.78, "tv": 281.26, "trd": NaN, "batb": [[1, 1.47, 64.73], [2, 1.4, 79.56]], "batl": NaN}, {"timestamp": 1631528018187, "ltp": 1.78, "tv": 281.26, "trd": NaN, "batb": NaN, "batl": [[2, 1.53, 88.24]]}, {"timestamp": 1631528018390, "ltp": 1.78, "tv": 281.26, "trd": NaN, "batb": NaN, "batl": [[2, 810, 0.07]]}, {"timestamp": 1631528021391, "ltp": 1.78, "tv": 281.26, "trd": NaN, "batb": [[0, 1.48, 122.62]], "batl": NaN}, {"timestamp": 1631528023321, "ltp": 1.78, "tv": 281.26, "trd": NaN, "batb": [[0, 1.48, 110]], "batl": [[0, 810, 0.07], [1, 1.52, 0], [2, 810, 0]]}, {"timestamp": 1631528023798, "ltp": 1.78, "tv": 281.26, "trd": NaN, "batb": [[0, 1.4, 79.56], [1, 1.31, 768.11], [2, 1.2, 385.43]], "batl": NaN}, {"timestamp": 1631528026991, "ltp": 1.78, "tv": 281.26, "trd": NaN, "batb": [[2, 1.25, 237.19]], "batl": NaN}, {"timestamp": 1631528035817, "ltp": 1.78, "tv": 281.26, "trd": NaN, "batb": [[0, 1.65, 2.17], [1, 1.4, 79.56], [2, 1.31, 768.11]], "batl": NaN}, {"timestamp": 1631528039324, "ltp": 1.65, "tv": 285.6, "trd": [[1.65, 4.34]], "batb": [[0, 1.4, 92], [1, 1.38, 178.95]], "batl": [[0, 1.44, 2300.88], [1, 1.49, 8.43], [2, 1.58, 126.58]]}, {"timestamp": 1631528040158, "ltp": 1.65, "tv": 285.6, "trd": NaN, "batb": [[2, 1.34, 97.06]], "batl": [[0, 1.58, 25.32], [1, 810, 0.07], [2, 1.58, 0]]}, {"timestamp": 1631528042620, "ltp": 1.43, "tv": 297.24, "trd": [[1.43, 11.64]], "batb": NaN, "batl": NaN}, {"timestamp": 1631528044343, "ltp": 1.43, "tv": 297.24, "trd": NaN, "batb": NaN, "batl": [[0, 1.45, 76.92], [1, 1.58, 25.32], [2, 810, 0.07]]}, {"timestamp": 1631528044550, "ltp": 1.43, "tv": 297.24, "trd": NaN, "batb": NaN, "batl": [[0, 1.58, 25.32], [1, 810, 0.07], [2, 810, 0]]}, {"timestamp": 1631528046128, "ltp": 1.4, "tv": 302.35, "trd": [[1.4, 5.11]], "batb": [[0, 1.4, 89.45]], "batl": NaN}, {"timestamp": 1631528050352, "ltp": 1.4, "tv": 302.35, "trd": NaN, "batb": NaN, "batl": [[0, 1.56, 14.16], [1, 1.58, 25.32], [2, 810, 0.07]]}, {"timestamp": 1631528052857, "ltp": 1.4, "tv": 302.35, "trd": NaN, "batb": [[0, 1.4, 77.01]], "batl": NaN}, {"timestamp": 1631528066166, "ltp": 1.4, "tv": 302.35, "trd": NaN, "batb": [[0, 1.34, 97.06], [1, 1.2, 385.43], [2, 1.17, 313.93]], "batl": [[0, 810, 0.07], [1, 1.58, 0], [2, 810, 0]]}, {"timestamp": 1631528076254, "ltp": 1.4, "tv": 302.35, "trd": NaN, "batb": NaN, "batl": [[0, 1.37, 12.57], [1, 1.44, 647.94], [2, 810, 0.07]]}, {"timestamp": 1631528077254, "ltp": 1.37, "tv": 306.69, "trd": [[1.37, 4.34]], "batb": [[1, 1.31, 107.03]], "batl": [[0, 1.37, 10.4]]}, {"timestamp": 1631528078344, "ltp": 1.37, "tv": 306.69, "trd": NaN, "batb": [[2, 1.23, 524.63]], "batl": [[2, 1.73, 535.9]]}, {"timestamp": 1631528081261, "ltp": 1.37, "tv": 306.69, "trd": NaN, "batb": NaN, "batl": [[1, 1.39, 2.59], [2, 1.44, 647.94]]}, {"timestamp": 1631528082469, "ltp": 1.37, "tv": 306.69, "trd": NaN, "batb": NaN, "batl": [[1, 1.44, 647.94], [2, 1.73, 535.9]]}, {"timestamp": 1631528084396, "ltp": 1.37, "tv": 306.69, "trd": NaN, "batb": [[0, 1.35, 409], [1, 1.34, 97.06], [2, 1.31, 107.03]], "batl": NaN}, {"timestamp": 1631528085805, "ltp": 1.35, "tv": 311.1, "trd": [[1.35, 4.42]], "batb": [[0, 1.35, 406.79]], "batl": NaN}, {"timestamp": 1631528087173, "ltp": 1.35, "tv": 311.1, "trd": NaN, "batb": NaN, "batl": [[0, 1.44, 647.94], [1, 1.73, 535.9], [2, 810, 0.07]]}, {"timestamp": 1631528093478, "ltp": 1.35, "tv": 311.1, "trd": NaN, "batb": NaN, "batl": [[2, 44, 7.24]]}, {"timestamp": 1631528094608, "ltp": 1.35, "tv": 550.28, "trd": [[1.35, 243.6]], "batb": [[0, 1.35, 287.2]], "batl": NaN}, {"timestamp": 1631528105602, "ltp": 1.35, "tv": 556.24, "trd": [[1.35, 249.56]], "batb": [[0, 1.35, 284.22]], "batl": NaN}, {"timestamp": 1631528152646, "ltp": 1.35, "tv": 556.24, "trd": NaN, "batb": NaN, "batl": [[0, 1.38, 14.99], [1, 1.44, 647.94], [2, 1.73, 535.9]]}, {"timestamp": 1631528154154, "ltp": 1.35, "tv": 556.24, "trd": NaN, "batb": [[0, 1.31, 107.03], [1, 1.23, 524.63], [2, 1.17, 313.93]], "batl": [[0, 1.73, 535.9], [1, 44, 7.24], [2, 1.73, 0]]}, {"timestamp": 1631528163488, "ltp": 1.35, "tv": 556.24, "trd": NaN, "batb": [[0, 1.5, 2.17], [1, 1.31, 107.03], [2, 1.23, 524.63]], "batl": NaN}, {"timestamp": 1631528171875, "ltp": 1.5, "tv": 560.59, "trd": [[1.5, 4.34]], "batb": [[0, 1.31, 107.03], [1, 1.23, 524.63], [2, 1.17, 313.93]], "batl": [[0, 1.35, 171.64], [1, 1.73, 535.9], [2, 44, 7.24]]}, {"timestamp": 1631528172968, "ltp": 1.5, "tv": 560.59, "trd": NaN, "batb": [[1, 1.29, 115.99], [2, 1.25, 237.19]], "batl": NaN}, {"timestamp": 1631528173485, "ltp": 1.5, "tv": 560.59, "trd": NaN, "batb": [[2, 1.23, 524.63]], "batl": NaN}, {"timestamp": 1631528175091, "ltp": 1.35, "tv": 650.27, "trd": [[1.35, 339.24]], "batb": NaN, "batl": [[0, 1.35, 126.8]]}, {"timestamp": 1631528178094, "ltp": 1.35, "tv": 650.27, "trd": NaN, "batb": [[0, 1.33, 112], [1, 1.31, 107.03], [2, 1.29, 115.99]], "batl": NaN}, {"timestamp": 1631528179185, "ltp": 1.33, "tv": 655.16, "trd": [[1.33, 4.9]], "batb": [[0, 1.33, 109.55]], "batl": NaN}, {"timestamp": 1631528184103, "ltp": 1.33, "tv": 655.16, "trd": NaN, "batb": [[0, 1.29, 115.99], [1, 1.23, 524.63], [2, 1.17, 313.93]], "batl": [[0, 1.73, 535.9], [1, 44, 7.24], [2, 44, 0]]}, {"timestamp": 1631528189429, "ltp": 1.29, "tv": 688.28, "trd": [[1.29, 33.11]], "batb": [[0, 1.29, 99.43]], "batl": NaN}, {"timestamp": 1631528197134, "ltp": 1.29, "tv": 688.28, "trd": NaN, "batb": [[0, 1.45, 2.17], [1, 1.29, 99.43], [2, 1.23, 524.63]], "batl": NaN}, {"timestamp": 1631528202349, "ltp": 1.29, "tv": 688.28, "trd": NaN, "batb": [[2, 1.17, 313.93]], "batl": [[0, 44, 7.24], [1, 44, 0]]}, {"timestamp": 1631528204057, "ltp": 1.45, "tv": 692.62, "trd": [[1.45, 4.34]], "batb": [[0, 1.29, 249.58], [1, 1.17, 313.93], [2, 1.11, 269.53]], "batl": [[0, 1.33, 166.5], [1, 44, 7.24]]}, {"timestamp": 1631528205145, "ltp": 1.45, "tv": 692.62, "trd": NaN, "batb": [[1, 1.28, 123.86], [2, 1.17, 313.93]], "batl": NaN}, {"timestamp": 1631528206032, "ltp": 1.45, "tv": 692.62, "trd": NaN, "batb": [[2, 1.2, 539.24]], "batl": [[1, 1.66, 588.96], [2, 44, 7.24]]}, {"timestamp": 1631528210963, "ltp": 1.31, "tv": 695.02, "trd": [[1.31, 2.4]], "batb": NaN, "batl": NaN}, {"timestamp": 1631528211945, "ltp": 1.31, "tv": 695.02, "trd": NaN, "batb": [[0, 1.31, 70], [1, 1.29, 249.58], [2, 1.28, 123.86]], "batl": NaN}, {"timestamp": 1631528213149, "ltp": 1.31, "tv": 695.02, "trd": NaN, "batb": [[0, 1.28, 123.86], [1, 1.2, 539.24], [2, 1.17, 313.93]], "batl": [[0, 1.66, 588.96], [1, 44, 7.24], [2, 44, 0]]}, {"timestamp": 1631528226260, "ltp": 1.31, "tv": 695.02, "trd": NaN, "batb": [[0, 1.29, 16.59], [1, 1.28, 123.86], [2, 1.2, 539.24]], "batl": [[0, 1.31, 149.49], [1, 1.32, 90.91], [2, 1.66, 588.96]]}, {"timestamp": 1631528227184, "ltp": 1.31, "tv": 695.02, "trd": NaN, "batb": [[2, 1.26, 132.32]], "batl": [[1, 1.32, 30.3]]}, {"timestamp": 1631528235081, "ltp": 1.31, "tv": 695.02, "trd": NaN, "batb": [[0, 1.29, 122.59]], "batl": NaN}, {"timestamp": 1631528240308, "ltp": 1.29, "tv": 695.18, "trd": [[1.29, 33.27]], "batb": [[0, 1.26, 132.32], [1, 1.2, 539.24], [2, 1.17, 313.93]], "batl": [[0, 1.66, 588.96], [1, 44, 7.24], [2, 1.66, 0]]}, {"timestamp": 1631528244092, "ltp": 1.29, "tv": 695.18, "trd": NaN, "batb": [[1, 1.17, 313.93], [2, 1.11, 269.53]], "batl": [[0, 44, 7.24], [1, 44, 0]]}, {"timestamp": 1631528246309, "ltp": 1.29, "tv": 695.18, "trd": NaN, "batb": [[0, 1.28, 13.01], [1, 1.26, 132.32], [2, 1.17, 313.93]], "batl": [[0, 1.3, 157.85], [1, 1.32, 30.3], [2, 1.66, 705.62]]}, {"timestamp": 1631528247291, "ltp": 1.29, "tv": 695.18, "trd": NaN, "batb": [[2, 1.24, 146.05]], "batl": [[2, 44, 7.24]]}, {"timestamp": 1631528247703, "ltp": 1.29, "tv": 695.18, "trd": NaN, "batb": NaN, "batl": [[2, 1.58, 660.85]]}, {"timestamp": 1631528254230, "ltp": 1.29, "tv": 695.18, "trd": NaN, "batb": [[0, 1.29, 121], [1, 1.28, 13.01], [2, 1.26, 132.32]], "batl": NaN}, {"timestamp": 1631528261034, "ltp": 1.29, "tv": 695.18, "trd": NaN, "batb": [[1, 1.26, 132.32], [2, 1.24, 146.05]], "batl": NaN}, {"timestamp": 1631528263925, "ltp": 1.29, "tv": 695.18, "trd": NaN, "batb": NaN, "batl": [[0, 1.3, 170.05]]}, {"timestamp": 1631528269246, "ltp": 1.29, "tv": 695.18, "trd": NaN, "batb": NaN, "batl": [[0, 1.58, 660.85], [1, 8.8, 7.24], [2, 44, 7.24]]}, {"timestamp": 1631528269557, "ltp": 1.29, "tv": 695.18, "trd": NaN, "batb": [[0, 1.24, 146.05], [1, 1.17, 313.93], [2, 1.16, 585.23]], "batl": NaN}, {"timestamp": 1631528281230, "ltp": 1.29, "tv": 695.18, "trd": NaN, "batb": NaN, "batl": [[0, 1.28, 16.11], [1, 1.3, 2807.94], [2, 1.58, 660.85]]}, {"timestamp": 1631528282261, "ltp": 1.29, "tv": 695.18, "trd": NaN, "batb": [[1, 1.22, 162.88], [2, 1.17, 313.93]], "batl": [[1, 1.58, 660.85], [2, 8.8, 7.24]]}, {"timestamp": 1631528286251, "ltp": 1.28, "tv": 711.29, "trd": [[1.28, 16.11]], "batb": NaN, "batl": [[0, 1.32, 151.43]]}, {"timestamp": 1631528286456, "ltp": 1.28, "tv": 711.29, "trd": NaN, "batb": NaN, "batl": [[0, 1.58, 660.85], [1, 8.8, 7.24], [2, 44, 7.24]]}, {"timestamp": 1631528289661, "ltp": 1.28, "tv": 711.29, "trd": NaN, "batb": NaN, "batl": [[0, 1.44, 16.48], [1, 1.58, 660.85], [2, 8.8, 7.24]]}, {"timestamp": 1631528291158, "ltp": 1.28, "tv": 711.29, "trd": NaN, "batb": NaN, "batl": [[0, 1.58, 660.85], [1, 8.8, 7.24], [2, 44, 7.24]]}, {"timestamp": 1631528291572, "ltp": 1.28, "tv": 711.29, "trd": NaN, "batb": [[0, 1.22, 162.88], [1, 1.17, 313.93], [2, 1.16, 585.23]], "batl": NaN}, {"timestamp": 1631528297192, "ltp": 1.28, "tv": 711.29, "trd": NaN, "batb": [[0, 1.29, 13.05], [1, 1.26, 138.15], [2, 1.22, 162.88]], "batl": NaN}, {"timestamp": 1631528298276, "ltp": 1.28, "tv": 711.29, "trd": NaN, "batb": [[0, 1.26, 271.81], [1, 1.23, 149.74], [2, 1.17, 313.93]], "batl": NaN}, {"timestamp": 1631528300292, "ltp": 1.28, "tv": 711.29, "trd": NaN, "batb": [[0, 1.29, 13.05], [1, 1.26, 271.81], [2, 1.23, 149.74]], "batl": NaN}, {"timestamp": 1631528305418, "ltp": 1.28, "tv": 711.29, "trd": NaN, "batb": [[0, 1.29, 146.05]], "batl": NaN}, {"timestamp": 1631528307170, "ltp": 1.28, "tv": 711.29, "trd": NaN, "batb": [[0, 1.23, 149.74], [1, 1.17, 313.93], [2, 1.16, 585.23]], "batl": NaN}, {"timestamp": 1631528311457, "ltp": 1.28, "tv": 711.29, "trd": NaN, "batb": [[2, 1.11, 269.53]], "batl": NaN}, {"timestamp": 1631528312852, "ltp": 1.28, "tv": 711.29, "trd": NaN, "batb": [[0, 1.3, 30.76], [1, 1.28, 132.12], [2, 1.23, 149.74]], "batl": [[0, 1.32, 201.1], [1, 1.58, 660.85], [2, 8.8, 7.24]]}, {"timestamp": 1631528313884, "ltp": 1.28, "tv": 711.29, "trd": NaN, "batb": [[2, 1.27, 124.53]], "batl": NaN}, {"timestamp": 1631528317098, "ltp": 1.28, "tv": 711.29, "trd": NaN, "batb": [[0, 1.3, 113.76]], "batl": NaN}, {"timestamp": 1631528319276, "ltp": 1.28, "tv": 711.29, "trd": NaN, "batb": [[0, 1.3, 83], [1, 1.27, 124.53], [2, 1.25, 136.09]], "batl": [[0, 1.58, 660.85], [1, 8.8, 7.24], [2, 44, 7.24]]}, {"timestamp": 1631528320199, "ltp": 1.28, "tv": 711.29, "trd": NaN, "batb": [[0, 1.25, 136.09], [1, 1.18, 558.4], [2, 1.17, 313.93]], "batl": NaN}, {"timestamp": 1631528328794, "ltp": 1.28, "tv": 711.29, "trd": NaN, "batb": NaN, "batl": [[0, 1.33, 117.12], [1, 1.34, 18.71], [2, 1.58, 660.85]]}, {"timestamp": 1631528329823, "ltp": 1.28, "tv": 711.29, "trd": NaN, "batb": [[0, 1.29, 116.99], [1, 1.27, 124.95], [2, 1.18, 558.4]], "batl": NaN}, {"timestamp": 1631528332305, "ltp": 1.33, "tv": 715.63, "trd": [[1.33, 9.24]], "batb": NaN, "batl": [[0, 1.33, 114.95]]}, {"timestamp": 1631528337308, "ltp": 1.33, "tv": 715.63, "trd": NaN, "batb": [[0, 1.32, 95], [1, 1.29, 116.99], [2, 1.27, 124.95]], "batl": NaN}, {"timestamp": 1631528338234, "ltp": 1.33, "tv": 715.63, "trd": NaN, "batb": NaN, "batl": [[0, 1.58, 660.85], [1, 8.8, 7.24], [2, 44, 7.24]]}, {"timestamp": 1631528338494, "ltp": 1.33, "tv": 715.63, "trd": NaN, "batb": [[0, 1.27, 124.95], [1, 1.18, 558.4], [2, 1.17, 313.93]], "batl": NaN}, {"timestamp": 1631528340809, "ltp": 1.33, "tv": 715.63, "trd": NaN, "batb": NaN, "batl": [[0, 1.58, 660.93]]}, {"timestamp": 1631528346318, "ltp": 1.27, "tv": 720.18, "trd": [[1.27, 4.54]], "batb": [[0, 1.27, 122.68]], "batl": NaN}, {"timestamp": 1631528358225, "ltp": 1.32, "tv": 720.34, "trd": [[1.32, 0.16]], "batb": [[0, 1.34, 29.86], [1, 1.27, 122.68], [2, 1.18, 558.4]], "batl": [[0, 1.58, 660.85]]}, {"timestamp": 1631528359051, "ltp": 1.32, "tv": 720.34, "trd": NaN, "batb": [[1, 1.3, 110.79], [2, 1.28, 119.5]], "batl": NaN}, {"timestamp": 1631528359928, "ltp": 1.35, "tv": 722.51, "trd": [[1.35, 341.41]], "batb": NaN, "batl": NaN}, {"timestamp": 1631528366480, "ltp": 1.34, "tv": 726.87, "trd": [[1.34, 4.37]], "batb": [[0, 1.34, 27.68]], "batl": NaN}, {"timestamp": 1631528369677, "ltp": 1.34, "tv": 726.87, "trd": NaN, "batb": NaN, "batl": [[0, 1.52, 16.22], [1, 1.58, 660.85], [2, 8.8, 7.24]]}, {"timestamp": 1631528439161, "ltp": 1.34, "tv": 726.87, "trd": NaN, "batb": [[0, 1.3, 110.79], [1, 1.28, 119.5], [2, 1.18, 558.4]], "batl": [[0, 1.58, 660.85], [1, 8.8, 7.24], [2, 44, 7.24]]}, {"timestamp": 1631528439575, "ltp": 1.34, "tv": 726.87, "trd": NaN, "batb": [[0, 1.28, 119.5], [1, 1.18, 558.4], [2, 1.17, 313.93]], "batl": NaN}, {"timestamp": 1631528446350, "ltp": 1.34, "tv": 726.87, "trd": NaN, "batb": NaN, "batl": [[0, 1.33, 204.12], [1, 1.58, 660.85], [2, 8.8, 7.24]]}, {"timestamp": 1631528447644, "ltp": 1.34, "tv": 726.87, "trd": NaN, "batb": [[1, 1.27, 128.8], [2, 1.18, 558.4]], "batl": NaN}, {"timestamp": 1631528449554, "ltp": 1.33, "tv": 731.21, "trd": [[1.33, 13.58]], "batb": NaN, "batl": [[0, 1.33, 201.95]]}, {"timestamp": 1631528453994, "ltp": 1.33, "tv": 731.21, "trd": NaN, "batb": [[0, 1.27, 128.8], [1, 1.18, 558.4], [2, 1.17, 313.93]], "batl": [[0, 1.58, 660.85], [1, 8.8, 7.24], [2, 44, 7.24]]}, {"timestamp": 1631528465177, "ltp": 1.33, "tv": 731.21, "trd": NaN, "batb": [[0, 1.4, 2.17], [1, 1.27, 128.8], [2, 1.18, 558.4]], "batl": NaN}, {"timestamp": 1631528472412, "ltp": 1.33, "tv": 731.21, "trd": NaN, "batb": [[0, 1.27, 128.8], [1, 1.18, 558.4], [2, 1.17, 313.93]], "batl": NaN}, {"timestamp": 1631528481318, "ltp": 1.33, "tv": 731.21, "trd": NaN, "batb": [[1, 1.17, 313.93], [2, 1.11, 269.53]], "batl": [[0, 1.31, 188.61], [1, 1.58, 660.85], [2, 8.8, 7.24]]}, {"timestamp": 1631528482307, "ltp": 1.31, "tv": 735.56, "trd": [[1.31, 6.74]], "batb": [[1, 1.25, 138.26], [2, 1.17, 313.93]], "batl": [[0, 1.31, 186.44]]}, {"timestamp": 1631528488131, "ltp": 1.29, "tv": 740.0, "trd": [[1.29, 37.72]], "batb": NaN, "batl": NaN}, {"timestamp": 1631528489316, "ltp": 1.29, "tv": 740.0, "trd": NaN, "batb": [[0, 1.29, 84], [1, 1.27, 128.8], [2, 1.25, 138.26]], "batl": NaN}, {"timestamp": 1631528494327, "ltp": 1.29, "tv": 740.0, "trd": NaN, "batb": [[0, 1.25, 138.26], [1, 1.17, 313.93], [2, 1.14, 637.83]], "batl": [[0, 1.58, 660.85], [1, 8.8, 7.24], [2, 44, 7.24]]}, {"timestamp": 1631528501457, "ltp": 1.29, "tv": 740.0, "trd": NaN, "batb": [[2, 1.11, 269.53]], "batl": NaN}, {"timestamp": 1631528503173, "ltp": 1.29, "tv": 740.0, "trd": NaN, "batb": [[0, 1.28, 16.2], [1, 1.25, 280.39], [2, 1.17, 313.93]], "batl": [[0, 1.31, 378.48], [1, 1.58, 660.85], [2, 8.8, 7.24]]}, {"timestamp": 1631528504266, "ltp": 1.29, "tv": 740.0, "trd": NaN, "batb": [[2, 1.24, 145.55]], "batl": NaN}, {"timestamp": 1631528505351, "ltp": 1.3, "tv": 742.17, "trd": [[1.3, 2.17]], "batb": NaN, "batl": NaN}, {"timestamp": 1631528510171, "ltp": 1.3, "tv": 742.17, "trd": NaN, "batb": [[0, 1.24, 145.55], [1, 1.17, 313.93], [2, 1.13, 639.92]], "batl": [[0, 1.58, 660.85], [1, 8.8, 7.24], [2, 44, 7.24]]}, {"timestamp": 1631528512239, "ltp": 1.3, "tv": 742.17, "trd": NaN, "batb": NaN, "batl": [[0, 1.28, 37.47], [1, 1.58, 660.85], [2, 8.8, 7.24]]}, {"timestamp": 1631528513263, "ltp": 1.3, "tv": 742.17, "trd": NaN, "batb": NaN, "batl": [[0, 1.28, 53.68]]}, {"timestamp": 1631528514354, "ltp": 1.3, "tv": 742.17, "trd": NaN, "batb": NaN, "batl": [[0, 1.28, 16.21]]}, {"timestamp": 1631528514968, "ltp": 1.3, "tv": 742.17, "trd": NaN, "batb": NaN, "batl": [[0, 1.58, 660.93], [1, 8.8, 7.24], [2, 44, 7.24]]}, {"timestamp": 1631528519356, "ltp": 1.25, "tv": 744.43, "trd": [[1.25, 2.26]], "batb": NaN, "batl": NaN}, {"timestamp": 1631528524894, "ltp": 1.25, "tv": 744.43, "trd": NaN, "batb": [[0, 1.25, 67.71], [1, 1.24, 145.55], [2, 1.17, 313.93]], "batl": [[0, 1.3, 369.93]]}, {"timestamp": 1631528526353, "ltp": 1.25, "tv": 744.43, "trd": NaN, "batb": [[2, 1.22, 160.96]], "batl": NaN}, {"timestamp": 1631528529259, "ltp": 1.29, "tv": 746.68, "trd": [[1.28, 16.27], [1.29, 39.81]], "batb": NaN, "batl": [[0, 1.3, 369.85], [1, 1.49, 773.7], [2, 8.8, 7.24]]}, {"timestamp": 1631528530280, "ltp": 1.27, "tv": 763.66, "trd": [[1.27, 21.53]], "batb": NaN, "batl": [[0, 1.27, 84.95], [1, 1.3, 369.85], [2, 1.49, 773.7]]}, {"timestamp": 1631528531276, "ltp": 1.27, "tv": 763.66, "trd": NaN, "batb": NaN, "batl": [[0, 1.27, 322.74]]}, {"timestamp": 1631528532304, "ltp": 1.27, "tv": 763.66, "trd": NaN, "batb": NaN, "batl": [[0, 1.27, 101.94]]}, {"timestamp": 1631528532670, "ltp": 1.27, "tv": 763.66, "trd": NaN, "batb": NaN, "batl": [[0, 1.27, 17]]}, {"timestamp": 1631528533385, "ltp": 1.27, "tv": 763.66, "trd": NaN, "batb": NaN, "batl": [[0, 1.3, 369.85], [1, 1.49, 773.7], [2, 8.8, 7.24]]}, {"timestamp": 1631528534681, "ltp": 1.25, "tv": 768.15, "trd": [[1.25, 6.74]], "batb": [[0, 1.25, 65.47]], "batl": NaN}, {"timestamp": 1631528537069, "ltp": 1.25, "tv": 948.84, "trd": [[1.25, 187.43]], "batb": [[0, 1.24, 145.55], [1, 1.22, 160.96], [2, 1.11, 964.65]], "batl": NaN}, {"timestamp": 1631528541198, "ltp": 1.25, "tv": 948.84, "trd": NaN, "batb": NaN, "batl": [[0, 1.28, 20], [1, 1.3, 369.85], [2, 1.49, 773.7]]}, {"timestamp": 1631528541409, "ltp": 1.25, "tv": 948.84, "trd": NaN, "batb": NaN, "batl": [[0, 1.3, 369.85], [1, 1.49, 773.7], [2, 8.8, 7.24]]}, {"timestamp": 1631528544303, "ltp": 1.25, "tv": 948.84, "trd": NaN, "batb": NaN, "batl": [[0, 1.28, 20], [1, 1.3, 369.85], [2, 1.49, 773.7]]}, {"timestamp": 1631528546211, "ltp": 1.25, "tv": 948.84, "trd": NaN, "batb": NaN, "batl": [[0, 1.49, 773.7], [1, 8.8, 7.24], [2, 44, 7.24]]}, {"timestamp": 1631528546578, "ltp": 1.25, "tv": 948.84, "trd": NaN, "batb": [[0, 1.22, 160.96], [1, 1.11, 964.65], [2, 1.1, 296.48]], "batl": NaN}, {"timestamp": 1631528550516, "ltp": 1.25, "tv": 948.84, "trd": NaN, "batb": [[1, 1.11, 269.53]], "batl": NaN}, {"timestamp": 1631528552294, "ltp": 1.25, "tv": 948.84, "trd": NaN, "batb": [[0, 1.26, 158.74], [1, 1.25, 88.86], [2, 1.22, 160.96]], "batl": [[0, 1.29, 14.36], [1, 1.49, 773.7], [2, 8.8, 7.24]]}, {"timestamp": 1631528553300, "ltp": 1.25, "tv": 948.84, "trd": NaN, "batb": [[0, 1.26, 31.74], [1, 1.25, 226.2], [2, 1.23, 150.57]], "batl": NaN}, {"timestamp": 1631528557324, "ltp": 1.25, "tv": 948.84, "trd": NaN, "batb": [[0, 1.23, 150.57], [1, 1.13, 639.92], [2, 1.11, 269.53]], "batl": [[0, 1.32, 192.49]]}, {"timestamp": 1631528557488, "ltp": 1.25, "tv": 948.84, "trd": NaN, "batb": NaN, "batl": [[0, 1.49, 773.7], [1, 8.8, 7.24], [2, 44, 7.24]]}, {"timestamp": 1631528566038, "ltp": 1.25, "tv": 948.84, "trd": NaN, "batb": [[0, 1.34, 2.17], [1, 1.23, 150.57], [2, 1.13, 639.92]], "batl": NaN}, {"timestamp": 1631528570238, "ltp": 1.25, "tv": 948.84, "trd": NaN, "batb": [[2, 1.15, 355.78]], "batl": NaN}, {"timestamp": 1631528572422, "ltp": 1.25, "tv": 948.84, "trd": NaN, "batb": [[0, 1.23, 150.57], [1, 1.15, 355.78], [2, 1.13, 639.92]], "batl": NaN}, {"timestamp": 1631528581346, "ltp": 1.25, "tv": 948.84, "trd": NaN, "batb": [[0, 1.26, 131.4], [1, 1.25, 140.52], [2, 1.23, 150.57]], "batl": [[0, 1.3, 188.83], [1, 1.49, 773.7], [2, 8.8, 7.24]]}, {"timestamp": 1631528582030, "ltp": 1.25, "tv": 948.84, "trd": NaN, "batb": [[2, 1.15, 355.78]], "batl": NaN}, {"timestamp": 1631528583533, "ltp": 1.28, "tv": 951.01, "trd": [[1.28, 18.44]], "batb": NaN, "batl": NaN}, {"timestamp": 1631528589350, "ltp": 1.28, "tv": 951.01, "trd": NaN, "batb": NaN, "batl": [[0, 1.49, 773.7], [1, 8.8, 7.24], [2, 44, 7.24]]}, {"timestamp": 1631528589457, "ltp": 1.28, "tv": 951.01, "trd": NaN, "batb": [[0, 1.25, 140.52], [1, 1.15, 355.78], [2, 1.13, 639.92]], "batl": NaN}, {"timestamp": 1631528595563, "ltp": 1.28, "tv": 951.01, "trd": NaN, "batb": [[2, 1.11, 269.53]], "batl": NaN}, {"timestamp": 1631528597173, "ltp": 1.28, "tv": 951.01, "trd": NaN, "batb": NaN, "batl": [[0, 1.31, 30.54], [1, 1.49, 773.7], [2, 8.8, 7.24]]}, {"timestamp": 1631528598161, "ltp": 1.28, "tv": 951.01, "trd": NaN, "batb": [[1, 1.23, 155.01], [2, 1.15, 355.78]], "batl": NaN}, {"timestamp": 1631528599359, "ltp": 1.27, "tv": 953.18, "trd": [[1.27, 23.7]], "batb": NaN, "batl": NaN}, {"timestamp": 1631528603867, "ltp": 1.27, "tv": 967.7, "trd": [[1.27, 38.22]], "batb": NaN, "batl": [[0, 1.27, 33.04], [1, 1.31, 30.54], [2, 1.49, 773.7]]}, {"timestamp": 1631528604592, "ltp": 1.27, "tv": 967.7, "trd": NaN, "batb": [[2, 1.11, 964.65]], "batl": [[0, 1.31, 30.54], [1, 1.49, 773.7], [2, 8.8, 7.24]]}, {"timestamp": 1631528606157, "ltp": 1.27, "tv": 1001.82, "trd": [[1.27, 72.35]], "batb": [[0, 1.27, 105.94], [1, 1.25, 140.52], [2, 1.23, 155.01]], "batl": NaN}, {"timestamp": 1631528607356, "ltp": 1.27, "tv": 1030.83, "trd": [[1.27, 101.35]], "batb": [[0, 1.27, 91.44], [1, 1.23, 155.01], [2, 1.11, 964.65]], "batl": [[0, 1.49, 773.7], [1, 8.8, 7.24], [2, 44, 7.24]]}, {"timestamp": 1631528608176, "ltp": 1.27, "tv": 1030.83, "trd": NaN, "batb": [[0, 1.23, 155.01], [1, 1.11, 964.65], [2, 1.1, 296.48]], "batl": NaN}, {"timestamp": 1631528609782, "ltp": 1.27, "tv": 1030.83, "trd": NaN, "batb": [[1, 1.11, 695.13], [2, 1.06, 494.14]], "batl": NaN}, {"timestamp": 1631528613267, "ltp": 1.27, "tv": 1030.83, "trd": NaN, "batb": NaN, "batl": [[0, 1.25, 29.95], [1, 1.49, 773.7], [2, 8.8, 7.24]]}, {"timestamp": 1631528614771, "ltp": 1.27, "tv": 1030.83, "trd": NaN, "batb": NaN, "batl": [[1, 1.49, 774.6]]}, {"timestamp": 1631528617071, "ltp": 1.27, "tv": 1030.83, "trd": NaN, "batb": [[0, 1.24, 261], [1, 1.23, 155.01], [2, 1.11, 695.13]], "batl": NaN}, {"timestamp": 1631528627089, "ltp": 1.27, "tv": 1030.83, "trd": NaN, "batb": [[0, 1.23, 155.01], [1, 1.11, 695.13], [2, 1.06, 494.14]], "batl": NaN}, {"timestamp": 1631528627973, "ltp": 1.25, "tv": 1037.15, "trd": [[1.25, 193.75]], "batb": NaN, "batl": [[0, 1.25, 26.79]]}, {"timestamp": 1631528631393, "ltp": 1.25, "tv": 1037.15, "trd": NaN, "batb": [[1, 1.06, 494.14], [2, 1.05, 474.38]], "batl": NaN}, {"timestamp": 1631528634814, "ltp": 1.25, "tv": 1037.15, "trd": NaN, "batb": [[1, 1.13, 639.92], [2, 1.06, 494.14]], "batl": NaN}, {"timestamp": 1631528635704, "ltp": 1.25, "tv": 1051.07, "trd": [[1.25, 207.67]], "batb": [[0, 1.23, 335.05], [1, 1.06, 494.14], [2, 1.05, 474.38]], "batl": [[0, 1.25, 12.87]]}, {"timestamp": 1631528636692, "ltp": 1.25, "tv": 1051.07, "trd": NaN, "batb": [[1, 1.2, 173.69], [2, 1.06, 494.14]], "batl": NaN}, {"timestamp": 1631528639017, "ltp": 1.25, "tv": 1051.07, "trd": NaN, "batb": [[2, 1.11, 695.13]], "batl": NaN}, {"timestamp": 1631528640728, "ltp": 1.25, "tv": 1063.94, "trd": [[1.25, 220.54]], "batb": NaN, "batl": [[0, 1.49, 774.6], [1, 8.8, 7.24], [2, 44, 7.24]]}, {"timestamp": 1631528645352, "ltp": 1.25, "tv": 1063.94, "trd": NaN, "batb": NaN, "batl": [[0, 1.42, 21.48], [1, 1.49, 773.7], [2, 8.8, 7.24]]}, {"timestamp": 1631528647737, "ltp": 1.25, "tv": 1063.94, "trd": NaN, "batb": [[0, 1.2, 173.69], [1, 1.11, 695.13], [2, 1.06, 494.14]], "batl": [[0, 1.49, 774.6], [1, 8.8, 7.24], [2, 44, 7.24]]}, {"timestamp": 1631528666140, "ltp": 1.25, "tv": 1063.94, "trd": NaN, "batb": [[1, 1.06, 494.14], [2, 1.05, 474.38]], "batl": NaN}, {"timestamp": 1631528667281, "ltp": 1.25, "tv": 1063.94, "trd": NaN, "batb": [[0, 1.26, 18.61], [1, 1.2, 173.69], [2, 1.06, 494.14]], "batl": [[0, 1.28, 242.13], [1, 1.49, 773.7], [2, 8.8, 7.24]]}, {"timestamp": 1631528668678, "ltp": 1.25, "tv": 1063.94, "trd": NaN, "batb": [[1, 1.24, 143.96], [2, 1.22, 156.18]], "batl": NaN}, {"timestamp": 1631528672352, "ltp": 1.27, "tv": 1083.45, "trd": [[1.26, 18.61], [1.27, 102.25]], "batb": [[0, 1.24, 143.96], [1, 1.22, 156.18], [2, 1.13, 639.92]], "batl": [[0, 1.28, 241.23]]}, {"timestamp": 1631528675294, "ltp": 1.27, "tv": 1083.45, "trd": NaN, "batb": [[0, 1.24, 216.96]], "batl": NaN}, {"timestamp": 1631528680260, "ltp": 1.27, "tv": 1083.45, "trd": NaN, "batb": [[0, 1.24, 143.96]], "batl": [[0, 1.49, 773.7], [1, 8.8, 7.24], [2, 44, 7.24]]}, {"timestamp": 1631528681292, "ltp": 1.27, "tv": 1083.45, "trd": NaN, "batb": [[0, 1.22, 156.18], [1, 1.13, 639.92], [2, 1.06, 494.14]], "batl": NaN}, {"timestamp": 1631528697314, "ltp": 1.27, "tv": 1083.45, "trd": NaN, "batb": [[0, 1.26, 31.74], [1, 1.25, 108.9], [2, 1.22, 156.18]], "batl": [[0, 1.28, 19.88], [1, 1.49, 773.7], [2, 8.8, 7.24]]}, {"timestamp": 1631528697625, "ltp": 1.27, "tv": 1083.45, "trd": NaN, "batb": [[1, 1.25, 244.32], [2, 1.24, 145.63]], "batl": NaN}, {"timestamp": 1631528704731, "ltp": 1.27, "tv": 1083.45, "trd": NaN, "batb": [[0, 1.27, 180], [1, 1.26, 31.74], [2, 1.25, 244.32]], "batl": NaN}, {"timestamp": 1631528706030, "ltp": 1.27, "tv": 1239.09, "trd": [[1.27, 257.89]], "batb": [[0, 1.27, 24.36]], "batl": NaN}, {"timestamp": 1631528710117, "ltp": 1.27, "tv": 1239.09, "trd": NaN, "batb": [[0, 1.27, 180]], "batl": NaN}, {"timestamp": 1631528712506, "ltp": 1.27, "tv": 1239.09, "trd": NaN, "batb": NaN, "batl": [[0, 1.49, 773.7], [1, 8.8, 7.24], [2, 44, 7.24]]}, {"timestamp": 1631528715608, "ltp": 1.27, "tv": 1273.13, "trd": [[1.27, 291.93]], "batb": [[0, 1.27, 162.98], [2, 1.25, 261.96]], "batl": [[0, 1.44, 22.55], [1, 1.49, 773.7], [2, 8.8, 7.24]]}, {"timestamp": 1631528722345, "ltp": 1.27, "tv": 1436.11, "trd": [[1.27, 454.91]], "batb": [[0, 1.26, 31.74], [1, 1.25, 261.96], [2, 1.24, 145.63]], "batl": NaN}, {"timestamp": 1631528726151, "ltp": 1.27, "tv": 1436.11, "trd": NaN, "batb": [[0, 1.26, 148.74], [1, 1.25, 244.32]], "batl": NaN}, {"timestamp": 1631528727031, "ltp": 1.26, "tv": 1543.64, "trd": [[1.26, 126.14]], "batb": [[0, 1.26, 41.21]], "batl": NaN}, {"timestamp": 1631528729060, "ltp": 1.26, "tv": 1543.64, "trd": NaN, "batb": NaN, "batl": [[0, 1.28, 23.47]]}, {"timestamp": 1631528731142, "ltp": 1.26, "tv": 1543.64, "trd": NaN, "batb": [[0, 1.26, 117]], "batl": NaN}, {"timestamp": 1631528793239, "ltp": 1.26, "tv": 1543.64, "trd": NaN, "batb": [[0, 1.24, 145.63], [1, 1.13, 639.92], [2, 1.06, 494.14]], "batl": [[0, 1.49, 773.7], [1, 8.8, 7.24], [2, 44, 7.24]]}, {"timestamp": 1631528799054, "ltp": 1.26, "tv": 1543.64, "trd": NaN, "batb": [[1, 1.06, 494.14], [2, 1.05, 474.38]], "batl": NaN}, {"timestamp": 1631528800247, "ltp": 1.26, "tv": 1543.64, "trd": NaN, "batb": [[0, 1.24, 306.89]], "batl": [[0, 1.28, 249.48], [1, 1.29, 31], [2, 1.49, 773.7]]}, {"timestamp": 1631528800978, "ltp": 1.26, "tv": 1543.64, "trd": NaN, "batb": [[1, 1.22, 157.61], [2, 1.06, 494.14]], "batl": NaN}, {"timestamp": 1631528803564, "ltp": 1.26, "tv": 1543.64, "trd": NaN, "batb": [[2, 1.11, 695.13]], "batl": NaN}, {"timestamp": 1631528806767, "ltp": 1.26, "tv": 1543.64, "trd": NaN, "batb": [[0, 1.24, 145.63]], "batl": [[0, 1.49, 773.7], [1, 8.8, 7.24], [2, 44, 7.24]]}, {"timestamp": 1631528808159, "ltp": 1.26, "tv": 1543.64, "trd": NaN, "batb": [[0, 1.27, 197]], "batl": NaN}, {"timestamp": 1631528808373, "ltp": 1.26, "tv": 1543.64, "trd": NaN, "batb": [[0, 1.22, 157.61], [1, 1.11, 695.13], [2, 1.06, 494.14]], "batl": NaN}, {"timestamp": 1631528813567, "ltp": 1.26, "tv": 1543.64, "trd": NaN, "batb": [[1, 1.06, 494.14], [2, 1.05, 474.38]], "batl": NaN}, {"timestamp": 1631528815862, "ltp": 1.26, "tv": 1543.64, "trd": NaN, "batb": [[0, 1.23, 143.9], [1, 1.22, 157.61], [2, 1.06, 494.14]], "batl": [[0, 1.27, 293.16], [1, 1.49, 773.7], [2, 8.8, 7.24]]}, {"timestamp": 1631528816800, "ltp": 1.26, "tv": 1543.64, "trd": NaN, "batb": [[2, 1.21, 167.49]], "batl": NaN}, {"timestamp": 1631528818300, "ltp": 1.23, "tv": 1753.46, "trd": [[1.23, 209.81]], "batb": [[0, 1.23, 39.02]], "batl": NaN}, {"timestamp": 1631528818664, "ltp": 1.23, "tv": 1753.46, "trd": NaN, "batb": NaN, "batl": [[0, 1.26, 22.72], [1, 1.27, 293.16], [2, 1.49, 773.7]]}, {"timestamp": 1631528820808, "ltp": 1.26, "tv": 1776.18, "trd": [[1.26, 148.86]], "batb": NaN, "batl": [[0, 1.27, 293.16], [1, 1.49, 773.7], [2, 8.8, 7.24]]}, {"timestamp": 1631528822211, "ltp": 1.26, "tv": 1776.18, "trd": NaN, "batb": [[0, 1.24, 110], [1, 1.23, 39.02], [2, 1.22, 157.61]], "batl": NaN}, {"timestamp": 1631528824297, "ltp": 1.26, "tv": 1776.18, "trd": NaN, "batb": [[0, 1.21, 167.49], [1, 1.09, 791.35], [2, 1.06, 494.14]], "batl": [[0, 1.49, 773.7], [1, 8.8, 7.24], [2, 44, 7.24]]}, {"timestamp": 1631528825804, "ltp": 1.26, "tv": 1776.18, "trd": NaN, "batb": NaN, "batl": [[0, 1.24, 34.14], [1, 1.49, 773.7], [2, 8.8, 7.24]]}, {"timestamp": 1631528826994, "ltp": 1.26, "tv": 1776.18, "trd": NaN, "batb": [[1, 1.06, 494.14], [2, 1.05, 474.38]], "batl": [[0, 1.49, 773.7], [1, 8.8, 7.24], [2, 44, 7.24]]}, {"timestamp": 1631528830893, "ltp": 1.26, "tv": 1776.18, "trd": NaN, "batb": [[1, 1.11, 695.13], [2, 1.06, 494.14]], "batl": NaN}, {"timestamp": 1631528838021, "ltp": 1.26, "tv": 1776.18, "trd": NaN, "batb": [[1, 1.06, 494.14], [2, 1.05, 474.38]], "batl": NaN}, {"timestamp": 1631528840318, "ltp": 1.26, "tv": 1776.18, "trd": NaN, "batb": [[1, 1.2, 175.86], [2, 1.06, 494.14]], "batl": [[0, 1.26, 26.02], [1, 1.27, 548.33], [2, 1.49, 773.7]]}, {"timestamp": 1631528842246, "ltp": 1.26, "tv": 1776.18, "trd": NaN, "batb": [[2, 1.09, 791.35]], "batl": NaN}, {"timestamp": 1631528846317, "ltp": 1.24, "tv": 1790.92, "trd": [[1.24, 14.74]], "batb": NaN, "batl": [[0, 1.24, 117.39], [1, 1.26, 26.02], [2, 1.27, 548.33]]}, {"timestamp": 1631528847243, "ltp": 1.24, "tv": 1790.92, "trd": NaN, "batb": NaN, "batl": [[0, 1.24, 146.84]]}, {"timestamp": 1631528848224, "ltp": 1.24, "tv": 1790.92, "trd": NaN, "batb": NaN, "batl": [[0, 1.24, 44.08]]}, {"timestamp": 1631528849217, "ltp": 1.24, "tv": 1790.92, "trd": NaN, "batb": NaN, "batl": [[0, 1.24, 29.4]]}, {"timestamp": 1631528850315, "ltp": 1.24, "tv": 1790.92, "trd": NaN, "batb": NaN, "batl": [[0, 1.24, 14.7]]}, {"timestamp": 1631528850419, "ltp": 1.24, "tv": 1790.92, "trd": NaN, "batb": NaN, "batl": [[0, 1.26, 26.02], [1, 1.27, 548.33], [2, 1.49, 773.7]]}, {"timestamp": 1631528852248, "ltp": 1.24, "tv": 1790.92, "trd": NaN, "batb": NaN, "batl": [[0, 1.49, 773.7], [1, 8.8, 7.24], [2, 44, 7.24]]}, {"timestamp": 1631528852620, "ltp": 1.24, "tv": 1790.92, "trd": NaN, "batb": [[0, 1.2, 175.86], [1, 1.09, 791.35], [2, 1.06, 494.14]], "batl": NaN}, {"timestamp": 1631528856429, "ltp": 1.24, "tv": 1790.92, "trd": NaN, "batb": [[1, 1.06, 494.14], [2, 1.05, 474.38]], "batl": NaN}, {"timestamp": 1631528858348, "ltp": 1.24, "tv": 1790.92, "trd": NaN, "batb": [[0, 1.2, 338.23]], "batl": [[0, 1.24, 239.16], [1, 1.49, 773.7], [2, 8.8, 7.24]]}, {"timestamp": 1631528859239, "ltp": 1.24, "tv": 1790.92, "trd": NaN, "batb": [[0, 1.22, 45.86], [1, 1.2, 338.23], [2, 1.16, 218.41]], "batl": [[1, 1.33, 42.06], [2, 1.49, 773.7]]}, {"timestamp": 1631528863254, "ltp": 1.24, "tv": 1818.19, "trd": [[1.24, 42.01]], "batb": NaN, "batl": [[0, 1.24, 211.89], [1, 1.28, 196.18], [2, 1.33, 42.06]]}, {"timestamp": 1631528863463, "ltp": 1.24, "tv": 1818.19, "trd": NaN, "batb": NaN, "batl": [[1, 1.33, 42.06], [2, 1.49, 773.7]]}, {"timestamp": 1631528865136, "ltp": 1.24, "tv": 1818.19, "trd": NaN, "batb": [[0, 1.23, 17.01], [1, 1.22, 135.86], [2, 1.2, 338.23]], "batl": NaN}, {"timestamp": 1631528866350, "ltp": 1.22, "tv": 1971.05, "trd": [[1.22, 135.86], [1.23, 226.82]], "batb": [[0, 1.2, 338.23], [1, 1.16, 218.41], [2, 1.08, 837.7]], "batl": NaN}, {"timestamp": 1631528867350, "ltp": 1.22, "tv": 1971.05, "trd": NaN, "batb": NaN, "batl": [[0, 1.22, 29.87], [1, 1.24, 211.89], [2, 1.33, 42.06]]}, {"timestamp": 1631528868348, "ltp": 1.22, "tv": 1971.05, "trd": NaN, "batb": NaN, "batl": [[0, 1.24, 211.89], [1, 1.33, 42.06], [2, 1.49, 773.7]]}, {"timestamp": 1631528870339, "ltp": 1.22, "tv": 1971.05, "trd": NaN, "batb": [[0, 1.21, 235], [1, 1.2, 338.23], [2, 1.16, 218.41]], "batl": NaN}, {"timestamp": 1631528870864, "ltp": 1.21, "tv": 2015.77, "trd": [[1.21, 44.72]], "batb": [[0, 1.21, 212.64]], "batl": NaN}, {"timestamp": 1631528878547, "ltp": 1.21, "tv": 2015.77, "trd": NaN, "batb": NaN, "batl": [[0, 1.24, 239.91]]}, {"timestamp": 1631528884202, "ltp": 1.22, "tv": 2039.35, "trd": [[1.22, 159.43]], "batb": NaN, "batl": NaN}, {"timestamp": 1631528888311, "ltp": 1.24, "tv": 2047.24, "trd": [[1.24, 49.91]], "batb": NaN, "batl": [[0, 1.24, 234.66]]}, {"timestamp": 1631528894202, "ltp": 1.21, "tv": 2064.29, "trd": [[1.21, 61.77]], "batb": [[0, 1.21, 195.59]], "batl": [[0, 1.24, 206.64]]}, {"timestamp": 1631528896767, "ltp": 1.21, "tv": 2064.29, "trd": NaN, "batb": NaN, "batl": [[0, 1.23, 23.41], [1, 1.24, 206.64], [2, 1.33, 42.06]]}, {"timestamp": 1631528903085, "ltp": 1.21, "tv": 2106.96, "trd": [[1.21, 104.44]], "batb": [[0, 1.21, 174.26]], "batl": NaN}, {"timestamp": 1631528907571, "ltp": 1.21, "tv": 2215.83, "trd": [[1.21, 213.31]], "batb": [[0, 1.21, 119.84]], "batl": NaN}, {"timestamp": 1631528910203, "ltp": 1.21, "tv": 2249.89, "trd": [[1.21, 247.37]], "batb": [[0, 1.21, 85.78]], "batl": NaN}, {"timestamp": 1631528912277, "ltp": 1.21, "tv": 2275.45, "trd": [[1.21, 272.93]], "batb": [[0, 1.21, 60.22]], "batl": NaN}, {"timestamp": 1631528915376, "ltp": 1.21, "tv": 2275.45, "trd": NaN, "batb": NaN, "batl": [[0, 1.24, 206.64], [1, 1.33, 42.06], [2, 1.49, 773.7]]}, {"timestamp": 1631528918585, "ltp": 1.21, "tv": 2275.45, "trd": NaN, "batb": [[0, 1.21, 235]], "batl": NaN}, {"timestamp": 1631528921534, "ltp": 1.21, "tv": 2275.45, "trd": NaN, "batb": [[1, 1.2, 361.09]], "batl": [[0, 1.22, 23.6], [1, 1.24, 206.64], [2, 1.33, 42.06]]}, {"timestamp": 1631528941351, "ltp": 1.21, "tv": 2275.45, "trd": NaN, "batb": [[0, 1.2, 175.86], [1, 1.16, 218.41], [2, 1.08, 837.7]], "batl": [[0, 1.33, 42.06], [1, 1.49, 773.7], [2, 8.8, 7.24]]}, {"timestamp": 1631528941556, "ltp": 1.21, "tv": 2275.45, "trd": NaN, "batb": [[0, 1.16, 218.41], [1, 1.08, 837.7], [2, 1.01, 105.88]], "batl": [[0, 1.49, 773.7], [1, 8.8, 7.24], [2, 44, 7.24]]}, {"timestamp": 1631528959563, "ltp": 1.21, "tv": 2275.45, "trd": NaN, "batb": [[1, 1.01, 105.88], [2, 1.01, 0]], "batl": NaN}, {"timestamp": 1631528961180, "ltp": 1.21, "tv": 2275.45, "trd": NaN, "batb": [[0, 1.24, 45.11], [1, 1.23, 248.02], [2, 1.22, 22.92]], "batl": [[0, 1.27, 218.3], [1, 1.35, 41.44], [2, 1.37, 20.42]]}, {"timestamp": 1631528962068, "ltp": 1.21, "tv": 2275.45, "trd": NaN, "batb": [[1, 1.23, 402.03]], "batl": NaN}, {"timestamp": 1631528965174, "ltp": 1.25, "tv": 2278.31, "trd": [[1.25, 223.4]], "batb": NaN, "batl": NaN}, {"timestamp": 1631528966062, "ltp": 1.27, "tv": 2306.95, "trd": [[1.27, 483.55]], "batb": NaN, "batl": [[0, 1.27, 189.66]]}, {"timestamp": 1631528968349, "ltp": 1.27, "tv": 2306.95, "trd": NaN, "batb": [[0, 1.24, 187.11]], "batl": NaN}, {"timestamp": 1631528969173, "ltp": 1.24, "tv": 2310.36, "trd": [[1.24, 53.32]], "batb": [[0, 1.24, 185.41]], "batl": NaN}, {"timestamp": 1631528970260, "ltp": 1.24, "tv": 2310.36, "trd": NaN, "batb": [[0, 1.24, 142], [1, 1.23, 154.01], [2, 1.19, 183.9]], "batl": [[0, 1.49, 773.7], [1, 8.8, 7.24], [2, 44, 7.24]]}, {"timestamp": 1631528971293, "ltp": 1.24, "tv": 2310.36, "trd": NaN, "batb": [[0, 1.19, 183.9], [1, 1.11, 695.13], [2, 1.01, 105.88]], "batl": NaN}, {"timestamp": 1631528973274, "ltp": 1.24, "tv": 2310.36, "trd": NaN, "batb": NaN, "batl": [[0, 1.34, 27.24], [1, 1.49, 773.7], [2, 8.8, 7.24]]}, {"timestamp": 1631528973483, "ltp": 1.24, "tv": 2310.36, "trd": NaN, "batb": NaN, "batl": [[0, 1.49, 773.7], [1, 8.8, 7.24], [2, 44, 7.24]]}, {"timestamp": 1631528976910, "ltp": 1.24, "tv": 2310.36, "trd": NaN, "batb": [[1, 1.01, 105.88], [2, 1.01, 0]], "batl": NaN}, {"timestamp": 1631528978999, "ltp": 1.24, "tv": 2310.36, "trd": NaN, "batb": [[0, 1.21, 46.23], [1, 1.19, 207.41], [2, 1.01, 105.88]], "batl": [[0, 1.24, 289.37], [1, 1.32, 42.38], [2, 1.34, 20.87]]}, {"timestamp": 1631528979889, "ltp": 1.24, "tv": 2310.36, "trd": NaN, "batb": [[2, 1.15, 240.77]], "batl": NaN}, {"timestamp": 1631528981813, "ltp": 1.24, "tv": 2310.36, "trd": NaN, "batb": [[1, 1.2, 18.7], [2, 1.19, 207.41]], "batl": [[0, 1.22, 30.12], [1, 1.24, 289.37], [2, 1.32, 42.38]]}, {"timestamp": 1631528983180, "ltp": 1.22, "tv": 2318.42, "trd": [[1.22, 167.48]], "batb": NaN, "batl": [[0, 1.22, 24.77]]}, {"timestamp": 1631528985095, "ltp": 1.22, "tv": 2318.42, "trd": NaN, "batb": [[0, 1.21, 216.23]], "batl": NaN}, {"timestamp": 1631528993398, "ltp": 1.22, "tv": 2318.42, "trd": NaN, "batb": [[1, 1.19, 207.41], [2, 1.15, 240.77]], "batl": [[0, 1.24, 289.37], [1, 1.32, 42.38], [2, 1.34, 20.87]]}, {"timestamp": 1631528995219, "ltp": 1.22, "tv": 2318.42, "trd": NaN, "batb": [[0, 1.21, 46.23], [1, 1.19, 23.51]], "batl": [[0, 1.32, 42.38], [1, 1.34, 20.87], [2, 1.49, 773.7]]}, {"timestamp": 1631528996316, "ltp": 1.22, "tv": 2318.42, "trd": NaN, "batb": [[0, 1.2, 21.42], [1, 1.15, 240.77], [2, 1.08, 837.7]], "batl": [[0, 1.22, 24.77], [1, 1.49, 773.7], [2, 8.8, 7.24]]}, {"timestamp": 1631528996525, "ltp": 1.22, "tv": 2318.42, "trd": NaN, "batb": [[0, 1.15, 240.77], [1, 1.08, 837.7], [2, 1.01, 105.88]], "batl": [[0, 1.49, 773.7], [1, 8.8, 7.24], [2, 44, 7.24]]}, {"timestamp": 1631528998344, "ltp": 1.22, "tv": 2318.42, "trd": NaN, "batb": [[1, 1.01, 105.88], [2, 1.01, 0]], "batl": NaN}, {"timestamp": 1631529001345, "ltp": 1.22, "tv": 2318.42, "trd": NaN, "batb": NaN, "batl": [[0, 1.24, 4], [1, 1.49, 773.7], [2, 8.8, 7.24]]}, {"timestamp": 1631529001613, "ltp": 1.22, "tv": 2318.42, "trd": NaN, "batb": [[1, 1.11, 695.13], [2, 1.01, 105.88]], "batl": [[0, 1.49, 773.7], [1, 8.8, 7.24], [2, 44, 7.24]]}, {"timestamp": 1631529009732, "ltp": 1.22, "tv": 2318.42, "trd": NaN, "batb": [[1, 1.01, 105.88], [2, 1.01, 0]], "batl": NaN}, {"timestamp": 1631529011259, "ltp": 1.22, "tv": 2318.42, "trd": NaN, "batb": [[0, 1.24, 45.11], [1, 1.22, 22.92], [2, 1.2, 382.92]], "batl": [[0, 1.25, 11.9], [1, 1.35, 41.44], [2, 1.37, 20.42]]}, {"timestamp": 1631529012142, "ltp": 1.22, "tv": 2318.42, "trd": NaN, "batb": [[1, 1.22, 180.28]], "batl": NaN}, {"timestamp": 1631529014963, "ltp": 1.24, "tv": 2326.81, "trd": [[1.24, 61.71]], "batb": [[0, 1.24, 36.72]], "batl": NaN}, {"timestamp": 1631529016133, "ltp": 1.25, "tv": 2335.38, "trd": [[1.25, 231.98]], "batb": NaN, "batl": [[0, 1.25, 6.19]]}, {"timestamp": 1631529018168, "ltp": 1.25, "tv": 2335.38, "trd": NaN, "batb": [[0, 1.24, 145.72]], "batl": NaN}, {"timestamp": 1631529020949, "ltp": 1.25, "tv": 2335.38, "trd": NaN, "batb": [[0, 1.18, 193.28], [1, 1.13, 639.92], [2, 1.01, 105.88]], "batl": [[0, 1.49, 773.7], [1, 8.8, 7.24], [2, 44, 7.24]]}, {"timestamp": 1631529042303, "ltp": 1.25, "tv": 2335.38, "trd": NaN, "batb": [[1, 1.01, 105.88], [2, 1.01, 0]], "batl": NaN}, {"timestamp": 1631529043877, "ltp": 1.19, "tv": 2337.55, "trd": [[1.19, 2.17]], "batb": [[0, 1.2, 46.62], [1, 1.19, 223.21], [2, 1.18, 216.99]], "batl": [[0, 1.26, 714.58], [1, 1.31, 42.7], [2, 1.33, 21.03]]}, {"timestamp": 1631529048202, "ltp": 1.19, "tv": 2337.55, "trd": NaN, "batb": [[0, 1.2, 149.62]], "batl": NaN}, {"timestamp": 1631529054016, "ltp": 1.19, "tv": 2337.55, "trd": NaN, "batb": [[0, 1.2, 46.62]], "batl": NaN}, {"timestamp": 1631529057192, "ltp": 1.22, "tv": 2339.83, "trd": [[1.22, 169.76]], "batb": NaN, "batl": [[0, 1.22, 30.27], [1, 1.26, 714.58], [2, 1.31, 42.7]]}, {"timestamp": 1631529058333, "ltp": 1.22, "tv": 2339.83, "trd": NaN, "batb": NaN, "batl": [[0, 1.26, 714.58], [1, 1.31, 42.7], [2, 1.33, 21.03]]}, {"timestamp": 1631529061310, "ltp": 1.22, "tv": 2339.83, "trd": NaN, "batb": [[0, 1.2, 64.39]], "batl": [[0, 1.22, 30.27], [1, 1.26, 714.58], [2, 1.31, 42.7]]}, {"timestamp": 1631529061520, "ltp": 1.22, "tv": 2339.83, "trd": NaN, "batb": [[0, 1.2, 46.62]], "batl": [[0, 1.26, 714.58], [1, 1.31, 42.7], [2, 1.33, 21.03]]}, {"timestamp": 1631529064514, "ltp": 1.22, "tv": 2339.83, "trd": NaN, "batb": [[0, 1.2, 64.39]], "batl": [[0, 1.22, 30.27], [1, 1.26, 714.58], [2, 1.31, 42.7]]}, {"timestamp": 1631529067125, "ltp": 1.22, "tv": 2339.83, "trd": NaN, "batb": [[0, 1.26, 3.53], [1, 1.13, 273.51], [2, 1.11, 695.13]], "batl": [[0, 1.49, 773.7], [1, 8.8, 7.24], [2, 44, 7.24]]}, {"timestamp": 1631529073935, "ltp": 1.22, "tv": 2339.83, "trd": NaN, "batb": [[2, 1.01, 105.88]], "batl": NaN}, {"timestamp": 1631529075338, "ltp": 1.26, "tv": 2346.89, "trd": [[1.26, 155.92]], "batb": [[0, 1.24, 23.78]], "batl": [[0, 1.26, 25.89], [1, 1.27, 245.8], [2, 1.49, 773.7]]}, {"timestamp": 1631529076228, "ltp": 1.26, "tv": 2346.89, "trd": NaN, "batb": [[0, 1.24, 68.89], [1, 1.22, 179.95], [2, 1.18, 197.22]], "batl": [[2, 1.35, 41.44]]}, {"timestamp": 1631529080352, "ltp": 1.26, "tv": 2355.4, "trd": [[1.26, 164.42]], "batb": NaN, "batl": [[0, 1.26, 20.26]]}, {"timestamp": 1631529081143, "ltp": 1.26, "tv": 2355.4, "trd": NaN, "batb": [[0, 1.24, 170.89]], "batl": NaN}, {"timestamp": 1631529083120, "ltp": 1.24, "tv": 2355.56, "trd": [[1.24, 61.87]], "batb": [[0, 1.24, 102], [1, 1.18, 197.22], [2, 1.13, 639.92]], "batl": [[0, 1.49, 773.7], [1, 8.8, 7.24], [2, 44, 7.24]]}, {"timestamp": 1631529084152, "ltp": 1.24, "tv": 2355.56, "trd": NaN, "batb": [[0, 1.18, 197.22], [1, 1.13, 639.92], [2, 1.01, 105.88]], "batl": NaN}, {"timestamp": 1631529090235, "ltp": 1.24, "tv": 2355.56, "trd": NaN, "batb": NaN, "batl": [[0, 1.27, 502.93], [1, 1.49, 773.7], [2, 8.8, 7.24]]}, {"timestamp": 1631529090442, "ltp": 1.24, "tv": 2355.56, "trd": NaN, "batb": NaN, "batl": [[0, 1.49, 773.7], [1, 8.8, 7.24], [2, 44, 7.24]]}, {"timestamp": 1631529094343, "ltp": 1.24, "tv": 2355.56, "trd": NaN, "batb": [[1, 1.01, 105.88], [2, 1.01, 0]], "batl": NaN}, {"timestamp": 1631529097988, "ltp": 1.24, "tv": 2355.56, "trd": NaN, "batb": [[1, 1.16, 585.23], [2, 1.01, 105.88]], "batl": NaN}, {"timestamp": 1631529104597, "ltp": 1.24, "tv": 2355.56, "trd": NaN, "batb": [[1, 1.01, 105.88], [2, 1.01, 0]], "batl": NaN}, {"timestamp": 1631529106260, "ltp": 1.24, "tv": 2355.56, "trd": NaN, "batb": [[0, 1.2, 46.62], [1, 1.18, 220.92], [2, 1.01, 105.88]], "batl": [[0, 1.21, 165.28], [1, 1.22, 33.78], [2, 1.31, 42.7]]}, {"timestamp": 1631529107254, "ltp": 1.24, "tv": 2355.56, "trd": NaN, "batb": [[2, 1.13, 277.95]], "batl": [[0, 1.21, 33.06]]}, {"timestamp": 1631529108078, "ltp": 1.24, "tv": 2355.56, "trd": NaN, "batb": [[2, 1.13, 917.87]], "batl": NaN}, {"timestamp": 1631529111265, "ltp": 1.21, "tv": 2364.23, "trd": [[1.21, 281.61]], "batb": NaN, "batl": [[0, 1.21, 27.28]]}, {"timestamp": 1631529114290, "ltp": 1.21, "tv": 2364.23, "trd": NaN, "batb": [[0, 1.2, 164.62]], "batl": NaN}, {"timestamp": 1631529125201, "ltp": 1.21, "tv": 2364.23, "trd": NaN, "batb": [[0, 1.13, 917.87], [1, 1.01, 105.88], [2, 1.13, 0]], "batl": [[0, 1.49, 773.7], [1, 8.8, 7.24], [2, 44, 7.24]]}, {"timestamp": 1631529140347, "ltp": 1.21, "tv": 2364.23, "trd": NaN, "batb": [[0, 1.13, 277.95]], "batl": NaN}, {"timestamp": 1631529141338, "ltp": 1.21, "tv": 2364.23, "trd": NaN, "batb": [[0, 1.24, 64.61], [1, 1.22, 22.92], [2, 1.13, 277.95]], "batl": [[0, 1.26, 211.32], [1, 1.35, 41.44], [2, 1.37, 20.42]]}, {"timestamp": 1631529142327, "ltp": 1.21, "tv": 2364.23, "trd": NaN, "batb": [[1, 1.22, 183.55], [2, 1.18, 200.65]], "batl": NaN}, {"timestamp": 1631529146264, "ltp": 1.26, "tv": 2372.85, "trd": [[1.26, 173.04]], "batb": NaN, "batl": [[0, 1.26, 205.6]]}, {"timestamp": 1631529147931, "ltp": 1.26, "tv": 2372.85, "trd": NaN, "batb": [[0, 1.24, 163.61]], "batl": NaN}, {"timestamp": 1631529153233, "ltp": 1.26, "tv": 2372.85, "trd": NaN, "batb": [[0, 1.24, 144.11]], "batl": [[0, 1.35, 41.44], [1, 1.37, 20.42], [2, 1.49, 773.7]]}, {"timestamp": 1631529153753, "ltp": 1.26, "tv": 2372.85, "trd": NaN, "batb": [[0, 1.18, 200.65], [1, 1.16, 585.23], [2, 1.01, 105.88]], "batl": [[0, 1.49, 773.7], [1, 8.8, 7.24], [2, 44, 7.24]]}, {"timestamp": 1631529162781, "ltp": 1.26, "tv": 2372.85, "trd": NaN, "batb": [[1, 1.01, 105.88], [2, 1.01, 0]], "batl": NaN}, {"timestamp": 1631529164331, "ltp": 1.26, "tv": 2372.85, "trd": NaN, "batb": [[0, 1.27, 44.05], [1, 1.25, 111.1], [2, 1.18, 200.65]], "batl": [[0, 1.29, 182.28], [1, 1.39, 40.25], [2, 1.41, 19.83]]}, {"timestamp": 1631529165261, "ltp": 1.26, "tv": 2372.85, "trd": NaN, "batb": [[1, 1.25, 249.69], [2, 1.23, 155.26]], "batl": NaN}, {"timestamp": 1631529169162, "ltp": 1.26, "tv": 2372.85, "trd": NaN, "batb": NaN, "batl": [[1, 1.33, 229.21], [2, 1.39, 40.25]]}, {"timestamp": 1631529169370, "ltp": 1.26, "tv": 2372.85, "trd": NaN, "batb": NaN, "batl": [[1, 1.39, 40.25], [2, 1.41, 19.83]]}, {"timestamp": 1631529172390, "ltp": 1.26, "tv": 2372.85, "trd": NaN, "batb": [[0, 1.27, 147.05]], "batl": NaN}, {"timestamp": 1631529186193, "ltp": 1.29, "tv": 2378.87, "trd": [[1.29, 45.83]], "batb": NaN, "batl": [[0, 1.29, 179.27]]}, {"timestamp": 1631529201312, "ltp": 1.29, "tv": 2378.87, "trd": NaN, "batb": [[0, 1.27, 103], [1, 1.25, 227.32]], "batl": [[1, 1.49, 773.7], [2, 8.8, 7.24]]}, {"timestamp": 1631529228135, "ltp": 1.28, "tv": 2383.41, "trd": [[1.28, 22.98]], "batb": NaN, "batl": [[0, 1.28, 9.1], [1, 1.29, 179.27], [2, 1.49, 773.7]]}, {"timestamp": 1631529233770, "ltp": 1.28, "tv": 2383.41, "trd": NaN, "batb": [[0, 1.23, 155.26], [1, 1.18, 558.4], [2, 1.01, 105.88]], "batl": [[0, 1.49, 773.7], [1, 8.8, 7.24], [2, 44, 7.24]]}, {"timestamp": 1631529246060, "ltp": 1.28, "tv": 2383.41, "trd": NaN, "batb": [[0, 1.24, 45.11], [1, 1.23, 155.26], [2, 1.22, 22.92]], "batl": [[0, 1.26, 25.61], [1, 1.35, 41.44], [2, 1.37, 20.42]]}, {"timestamp": 1631529251184, "ltp": 1.26, "tv": 2389.27, "trd": [[1.26, 178.9]], "batb": NaN, "batl": [[0, 1.26, 22.68]]}, {"timestamp": 1631529253263, "ltp": 1.26, "tv": 2389.27, "trd": NaN, "batb": NaN, "batl": [[0, 1.35, 41.44], [1, 1.37, 20.42], [2, 1.49, 773.7]]}, {"timestamp": 1631529254194, "ltp": 1.26, "tv": 2389.27, "trd": NaN, "batb": [[0, 1.21, 170.09], [1, 1.18, 558.4], [2, 1.01, 105.88]], "batl": [[0, 1.49, 773.7], [1, 8.8, 7.24], [2, 44, 7.24]]}, {"timestamp": 1631529260904, "ltp": 1.26, "tv": 2389.27, "trd": NaN, "batb": [[1, 1.01, 105.88], [2, 1.01, 0]], "batl": NaN}, {"timestamp": 1631529262203, "ltp": 1.26, "tv": 2389.27, "trd": NaN, "batb": [[0, 1.22, 45.86], [1, 1.21, 170.09], [2, 1.2, 208.35]], "batl": [[0, 1.26, 460.06], [1, 1.27, 31.5], [2, 1.33, 42.06]]}, {"timestamp": 1631529265116, "ltp": 1.26, "tv": 2389.27, "trd": NaN, "batb": NaN, "batl": [[0, 1.24, 25.11], [1, 1.26, 460.06], [2, 1.27, 31.5]]}, {"timestamp": 1631529267194, "ltp": 1.24, "tv": 2412.1, "trd": [[1.24, 84.7]], "batb": NaN, "batl": [[0, 1.24, 4.97]]}, {"timestamp": 1631529270316, "ltp": 1.24, "tv": 2412.1, "trd": NaN, "batb": [[0, 1.19, 182.48], [1, 1.14, 637.83], [2, 1.01, 105.88]], "batl": [[0, 1.49, 773.7], [1, 8.8, 7.24], [2, 44, 7.24]]}, {"timestamp": 1631529286105, "ltp": 1.24, "tv": 2412.1, "trd": NaN, "batb": [[0, 1.26, 15.32], [1, 1.25, 44.75], [2, 1.24, 32.26]], "batl": [[0, 1.27, 176.86], [1, 1.28, 31.44], [2, 1.36, 41.13]]}, {"timestamp": 1631529287347, "ltp": 1.24, "tv": 2412.1, "trd": NaN, "batb": [[2, 1.24, 178.65]], "batl": NaN}, {"timestamp": 1631529289118, "ltp": 1.26, "tv": 2426.45, "trd": [[1.26, 193.25]], "batb": [[0, 1.25, 45.72], [1, 1.24, 178.65], [2, 1.23, 22.74]], "batl": NaN}, {"timestamp": 1631529291252, "ltp": 1.27, "tv": 2457.24, "trd": [[1.27, 514.34]], "batb": [[0, 1.26, 135.97], [1, 1.25, 44.75], [2, 1.24, 178.65]], "batl": [[0, 1.27, 149.03]]}, {"timestamp": 1631529299243, "ltp": 1.27, "tv": 2457.24, "trd": NaN, "batb": [[0, 1.27, 141.18], [1, 1.24, 146.39], [2, 1.22, 161.96]], "batl": [[0, 1.49, 773.7], [1, 8.8, 7.24], [2, 44, 7.24]]}, {"timestamp": 1631529299452, "ltp": 1.27, "tv": 2457.24, "trd": NaN, "batb": [[1, 1.22, 161.96], [2, 1.18, 558.4]], "batl": NaN}, {"timestamp": 1631529303358, "ltp": 1.27, "tv": 2457.24, "trd": NaN, "batb": [[0, 1.22, 161.96], [1, 1.18, 558.4], [2, 1.01, 105.88]], "batl": NaN}, {"timestamp": 1631529307864, "ltp": 1.27, "tv": 2457.24, "trd": NaN, "batb": [[1, 1.01, 105.88], [2, 1.01, 0]], "batl": [[0, 8.8, 7.24], [1, 44, 7.24], [2, 50, 7.24]]}, {"timestamp": 1631529309851, "ltp": 1.27, "tv": 2457.24, "trd": NaN, "batb": [[0, 1.3, 14.71], [1, 1.29, 43.37], [2, 1.27, 22.02]], "batl": [[0, 1.32, 176.54], [1, 1.41, 39.68], [2, 1.43, 19.56]]}, {"timestamp": 1631529310568, "ltp": 1.27, "tv": 2457.24, "trd": NaN, "batb": [[1, 1.29, 160.78]], "batl": NaN}, {"timestamp": 1631529314261, "ltp": 1.32, "tv": 2466.0, "trd": [[1.32, 8.91]], "batb": NaN, "batl": [[0, 1.32, 170.71]]}, {"timestamp": 1631529316177, "ltp": 1.32, "tv": 2466.0, "trd": NaN, "batb": [[0, 1.3, 109.71]], "batl": NaN}, {"timestamp": 1631529323463, "ltp": 1.3, "tv": 2492.04, "trd": [[1.3, 28.22]], "batb": [[0, 1.3, 96.69]], "batl": NaN}, {"timestamp": 1631529324460, "ltp": 1.3, "tv": 2492.04, "trd": NaN, "batb": [[0, 1.3, 95]], "batl": [[0, 1.32, 151.04]]}, {"timestamp": 1631529326796, "ltp": 1.3, "tv": 2492.04, "trd": NaN, "batb": [[1, 1.29, 117.41], [2, 1.25, 435.58]], "batl": [[1, 1.66, 588.96], [2, 8.8, 7.24]]}, {"timestamp": 1631529327375, "ltp": 1.3, "tv": 2492.04, "trd": NaN, "batb": NaN, "batl": [[0, 1.31, 13.1], [1, 1.32, 151.04], [2, 1.66, 588.96]]}, {"timestamp": 1631529329190, "ltp": 1.3, "tv": 2492.04, "trd": NaN, "batb": [[0, 1.25, 140.94], [1, 1.2, 539.24], [2, 1.01, 105.88]], "batl": [[0, 1.66, 588.96], [1, 8.8, 7.24], [2, 44, 7.24]]}, {"timestamp": 1631529335009, "ltp": 1.3, "tv": 2492.04, "trd": NaN, "batb": [[1, 1.01, 105.88], [2, 1.01, 0]], "batl": NaN}, {"timestamp": 1631529338786, "ltp": 1.3, "tv": 2492.04, "trd": NaN, "batb": [[1, 1.22, 531.25], [2, 1.01, 105.88]], "batl": NaN}, {"timestamp": 1631529358025, "ltp": 1.3, "tv": 2492.04, "trd": NaN, "batb": [[1, 1.01, 105.88], [2, 1.01, 0]], "batl": NaN}, {"timestamp": 1631529358915, "ltp": 1.3, "tv": 2492.04, "trd": NaN, "batb": [[1, 1.24, 45.11], [2, 1.22, 22.92]], "batl": [[0, 1.27, 24.3], [1, 1.28, 234.1], [2, 1.32, 30.3]]}, {"timestamp": 1631529359907, "ltp": 1.3, "tv": 2492.04, "trd": NaN, "batb": [[2, 1.22, 182.54]], "batl": NaN}, {"timestamp": 1631529364239, "ltp": 1.27, "tv": 2517.83, "trd": [[1.27, 540.12]], "batb": NaN, "batl": [[0, 1.27, 1.41]]}, {"timestamp": 1631529365330, "ltp": 1.27, "tv": 2517.83, "trd": NaN, "batb": [[0, 1.25, 211.94]], "batl": NaN}, {"timestamp": 1631529372150, "ltp": 1.27, "tv": 2517.83, "trd": NaN, "batb": [[0, 1.22, 159.62], [1, 1.18, 558.4], [2, 1.01, 105.88]], "batl": [[0, 1.66, 588.96], [1, 8.8, 7.24], [2, 44, 7.24]]}, {"timestamp": 1631529394764, "ltp": 1.27, "tv": 2517.83, "trd": NaN, "batb": NaN, "batl": [[0, 8.8, 7.24], [1, 44, 7.24], [2, 50, 7.24]]}, {"timestamp": 1631529396274, "ltp": 1.27, "tv": 2517.83, "trd": NaN, "batb": [[1, 1.21, 46.23], [2, 1.19, 23.51]], "batl": [[0, 1.25, 121.96], [1, 1.28, 156.24], [2, 1.32, 42.38]]}, {"timestamp": 1631529397097, "ltp": 1.27, "tv": 2517.83, "trd": NaN, "batb": NaN, "batl": [[1, 1.28, 31.24]]}, {"timestamp": 1631529404261, "ltp": 1.27, "tv": 2517.83, "trd": NaN, "batb": [[0, 1.23, 107], [1, 1.22, 159.62], [2, 1.21, 46.23]], "batl": NaN}, {"timestamp": 1631529406185, "ltp": 1.25, "tv": 2523.12, "trd": [[1.25, 237.27]], "batb": NaN, "batl": [[0, 1.25, 119.31]]}, {"timestamp": 1631529425314, "ltp": 1.25, "tv": 2523.12, "trd": NaN, "batb": NaN, "batl": [[1, 1.32, 42.38], [2, 1.34, 20.87]]}, {"timestamp": 1631529426208, "ltp": 1.25, "tv": 2523.12, "trd": NaN, "batb": [[0, 1.18, 760.65], [1, 1.01, 105.88], [2, 1.21, 0]], "batl": [[0, 1.58, 660.85], [1, 8.8, 7.24], [2, 44, 7.24]]}, {"timestamp": 1631529433120, "ltp": 1.25, "tv": 2523.12, "trd": NaN, "batb": [[0, 1.24, 211.68], [1, 1.22, 22.92], [2, 1.18, 760.65]], "batl": [[0, 1.28, 228.31], [1, 1.36, 41.13], [2, 1.38, 20.27]]}, {"timestamp": 1631529434103, "ltp": 1.25, "tv": 2523.12, "trd": NaN, "batb": [[0, 1.25, 138.51], [1, 1.24, 211.68], [2, 1.22, 22.92]], "batl": NaN}, {"timestamp": 1631529437224, "ltp": 1.28, "tv": 2531.27, "trd": [[1.28, 31.12]], "batb": NaN, "batl": [[0, 1.28, 222.89]]}, {"timestamp": 1631529441326, "ltp": 1.28, "tv": 2531.27, "trd": NaN, "batb": [[0, 1.26, 95], [1, 1.25, 138.51], [2, 1.24, 211.68]], "batl": NaN}, {"timestamp": 1631529442108, "ltp": 1.28, "tv": 2531.27, "trd": NaN, "batb": [[0, 1.21, 167.83], [1, 1.18, 558.4], [2, 1.01, 105.88]], "batl": [[0, 1.58, 660.85], [1, 8.8, 7.24], [2, 44, 7.24]]}, {"timestamp": 1631529453914, "ltp": 1.28, "tv": 2531.27, "trd": NaN, "batb": [[1, 1.01, 105.88], [2, 1.01, 0]], "batl": NaN}, {"timestamp": 1631529455149, "ltp": 1.28, "tv": 2531.27, "trd": NaN, "batb": [[0, 1.23, 14.77], [1, 1.21, 214.06], [2, 1.2, 138.85]], "batl": [[0, 1.31, 42.7], [1, 1.33, 21.03], [2, 1.58, 660.85]]}, {"timestamp": 1631529463135, "ltp": 1.28, "tv": 2531.27, "trd": NaN, "batb": [[0, 1.23, 129.77]], "batl": NaN}, {"timestamp": 1631529466348, "ltp": 1.28, "tv": 2531.27, "trd": NaN, "batb": [[0, 1.23, 14.77]], "batl": NaN}, {"timestamp": 1631529468646, "ltp": 1.28, "tv": 2531.27, "trd": NaN, "batb": [[0, 1.16, 222.26], [1, 1.14, 637.83], [2, 1.01, 105.88]], "batl": [[0, 1.58, 660.85], [1, 8.8, 7.24], [2, 44, 7.24]]}, {"timestamp": 1631529501201, "ltp": 1.28, "tv": 2531.27, "trd": NaN, "batb": [[1, 1.01, 105.88], [2, 1.01, 0]], "batl": [[0, 8.8, 7.24], [1, 44, 7.24], [2, 50, 7.24]]}, {"timestamp": 1631529502296, "ltp": 1.28, "tv": 2531.27, "trd": NaN, "batb": [[0, 1.18, 26.52], [1, 1.16, 222.26], [2, 1.01, 105.88]], "batl": [[0, 1.2, 176.38], [1, 1.21, 3409.92], [2, 8.8, 7.24]]}, {"timestamp": 1631529503183, "ltp": 1.28, "tv": 2531.27, "trd": NaN, "batb": [[1, 1.16, 270.49], [2, 1.14, 24.53]], "batl": [[1, 1.26, 44.4], [2, 1.28, 21.85]]}, {"timestamp": 1631529507293, "ltp": 1.28, "tv": 2531.27, "trd": NaN, "batb": NaN, "batl": [[1, 1.22, 260.75], [2, 1.26, 44.4]]}, {"timestamp": 1631529507497, "ltp": 1.28, "tv": 2531.27, "trd": NaN, "batb": NaN, "batl": [[1, 1.26, 44.4], [2, 1.28, 21.85]]}, {"timestamp": 1631529510505, "ltp": 1.28, "tv": 2531.27, "trd": NaN, "batb": [[0, 1.18, 119.52]], "batl": NaN}, {"timestamp": 1631529517405, "ltp": 1.28, "tv": 2531.27, "trd": NaN, "batb": [[0, 1.18, 93]], "batl": NaN}, {"timestamp": 1631529519529, "ltp": 1.28, "tv": 2531.27, "trd": NaN, "batb": [[1, 1.16, 222.26], [2, 1.11, 1026.59]], "batl": [[1, 1.49, 773.7], [2, 8.8, 7.24]]}, {"timestamp": 1631529520415, "ltp": 1.28, "tv": 2531.27, "trd": NaN, "batb": NaN, "batl": [[0, 1.2, 190.55]]}, {"timestamp": 1631529521944, "ltp": 1.28, "tv": 2531.27, "trd": NaN, "batb": NaN, "batl": [[2, 3.8, 27.5]]}, {"timestamp": 1631529529326, "ltp": 1.28, "tv": 2531.27, "trd": NaN, "batb": NaN, "batl": [[0, 1.49, 773.7], [1, 3.8, 27.5], [2, 8.8, 7.24]]}, {"timestamp": 1631529529844, "ltp": 1.28, "tv": 2531.27, "trd": NaN, "batb": [[0, 1.11, 1026.59], [1, 1.01, 105.88], [2, 1.11, 0]], "batl": NaN}, {"timestamp": 1631529544240, "ltp": 1.28, "tv": 2531.27, "trd": NaN, "batb": [[0, 1.28, 2.17], [1, 1.11, 331.46], [2, 1.01, 105.88]], "batl": NaN}, {"timestamp": 1631529545331, "ltp": 1.28, "tv": 2535.61, "trd": [[1.28, 35.46]], "batb": [[0, 1.18, 572.76]], "batl": [[0, 1.24, 20.12], [1, 1.49, 773.7], [2, 3.8, 27.5]]}, {"timestamp": 1631529546164, "ltp": 1.28, "tv": 2535.61, "trd": NaN, "batb": [[0, 1.2, 223.15], [1, 1.18, 596.46], [2, 1.14, 255.34]], "batl": [[1, 1.31, 42.7], [2, 1.33, 21.03]]}, {"timestamp": 1631529548155, "ltp": 1.28, "tv": 2535.61, "trd": NaN, "batb": [[2, 1.14, 893.17]], "batl": NaN}, {"timestamp": 1631529553353, "ltp": 1.22, "tv": 2537.88, "trd": [[1.22, 172.04]], "batb": [[0, 1.22, 82], [1, 1.2, 223.15], [2, 1.18, 596.46]], "batl": NaN}, {"timestamp": 1631529555582, "ltp": 1.22, "tv": 2537.88, "trd": NaN, "batb": NaN, "batl": [[0, 1.31, 42.7], [1, 1.33, 21.03], [2, 1.49, 773.7]]}, {"timestamp": 1631529558469, "ltp": 1.22, "tv": 2537.88, "trd": NaN, "batb": NaN, "batl": [[0, 1.24, 22.28], [1, 1.31, 42.7], [2, 1.33, 21.03]]}, {"timestamp": 1631529561160, "ltp": 1.22, "tv": 2537.88, "trd": NaN, "batb": [[2, 1.18, 23.7]], "batl": [[0, 1.31, 42.7], [1, 1.33, 21.03], [2, 1.49, 773.7]]}, {"timestamp": 1631529561574, "ltp": 1.22, "tv": 2537.88, "trd": NaN, "batb": [[0, 1.14, 893.17], [1, 1.01, 105.88], [2, 1.18, 0]], "batl": [[0, 1.49, 773.7], [1, 3.8, 27.5], [2, 8.8, 7.24]]}, {"timestamp": 1631529569580, "ltp": 1.22, "tv": 2537.88, "trd": NaN, "batb": NaN, "batl": [[0, 1.15, 2.17], [1, 1.49, 773.7], [2, 3.8, 27.5]]}, {"timestamp": 1631529576008, "ltp": 1.22, "tv": 2537.88, "trd": NaN, "batb": NaN, "batl": [[0, 1.49, 773.7], [1, 3.8, 27.5], [2, 8.8, 7.24]]}, {"timestamp": 1631529592030, "ltp": 1.22, "tv": 2537.88, "trd": NaN, "batb": [[0, 1.33, 2.17], [1, 1.14, 893.17], [2, 1.01, 105.88]], "batl": NaN}, {"timestamp": 1631529596235, "ltp": 1.22, "tv": 2537.88, "trd": NaN, "batb": [[0, 1.14, 893.17], [1, 1.01, 105.88], [2, 1.01, 0]], "batl": NaN}, {"timestamp": 1631529605655, "ltp": 1.22, "tv": 2537.88, "trd": NaN, "batb": NaN, "batl": [[0, 1.15, 2.17], [1, 1.49, 773.7], [2, 3.8, 27.5]]}, {"timestamp": 1631529608826, "ltp": 1.22, "tv": 2537.88, "trd": NaN, "batb": [[0, 1.14, 989.17]], "batl": NaN}, {"timestamp": 1631529610227, "ltp": 1.22, "tv": 2537.88, "trd": NaN, "batb": NaN, "batl": [[0, 1.49, 773.7], [1, 3.8, 27.5], [2, 8.8, 7.24]]}, {"timestamp": 1631529610436, "ltp": 1.22, "tv": 2537.88, "trd": NaN, "batb": [[0, 1.14, 893.17]], "batl": NaN}, {"timestamp": 1631529645011, "ltp": 1.22, "tv": 2537.88, "trd": NaN, "batb": NaN, "batl": [[0, 1.15, 2.17], [1, 1.49, 773.7], [2, 3.8, 27.5]]}, {"timestamp": 1631529646309, "ltp": 1.15, "tv": 2540.05, "trd": [[1.15, 2.17]], "batb": [[0, 1.14, 255.34]], "batl": [[0, 1.18, 1634.1], [1, 1.2, 166.66], [2, 1.49, 773.7]]}, {"timestamp": 1631529647197, "ltp": 1.15, "tv": 2540.05, "trd": NaN, "batb": [[0, 1.15, 48.64], [1, 1.14, 255.34], [2, 1.13, 24.75]], "batl": [[0, 1.18, 418.92], [1, 1.2, 33.34], [2, 1.24, 45.11]]}, {"timestamp": 1631529651184, "ltp": 1.15, "tv": 2540.05, "trd": NaN, "batb": NaN, "batl": [[1, 1.2, 366.11]]}, {"timestamp": 1631529651390, "ltp": 1.15, "tv": 2540.05, "trd": NaN, "batb": NaN, "batl": [[1, 1.2, 33.34]]}, {"timestamp": 1631529654405, "ltp": 1.15, "tv": 2540.05, "trd": NaN, "batb": [[0, 1.16, 201], [1, 1.15, 48.64], [2, 1.14, 255.34]], "batl": NaN}, {"timestamp": 1631529655499, "ltp": 1.18, "tv": 2544.19, "trd": [[1.18, 4.14]], "batb": NaN, "batl": [[0, 1.18, 416.85]]}, {"timestamp": 1631529656487, "ltp": 1.18, "tv": 2544.19, "trd": NaN, "batb": NaN, "batl": [[0, 1.18, 380.82]]}, {"timestamp": 1631529659414, "ltp": 1.18, "tv": 2544.19, "trd": NaN, "batb": NaN, "batl": [[0, 1.18, 418.99]]}, {"timestamp": 1631529663303, "ltp": 1.18, "tv": 2544.19, "trd": NaN, "batb": [[1, 1.14, 255.34], [2, 1.09, 791.35]], "batl": [[2, 1.49, 773.7]]}, {"timestamp": 1631529664131, "ltp": 1.18, "tv": 2544.19, "trd": NaN, "batb": [[0, 1.09, 791.35], [1, 1.06, 503.48], [2, 1.01, 105.88]], "batl": [[0, 1.49, 773.7], [1, 3.8, 27.5], [2, 8.8, 7.24]]}, {"timestamp": 1631529664395, "ltp": 1.29, "tv": 2544.23, "trd": [[1.29, 45.87]], "batb": NaN, "batl": NaN}, {"timestamp": 1631529666317, "ltp": 1.29, "tv": 2544.23, "trd": NaN, "batb": NaN, "batl": [[0, 1.16, 21.71], [1, 1.49, 773.7], [2, 3.8, 27.5]]}, {"timestamp": 1631529669045, "ltp": 1.29, "tv": 2544.23, "trd": NaN, "batb": [[0, 1.06, 503.48], [1, 1.01, 105.88], [2, 1.01, 0]], "batl": [[1, 3.8, 27.5], [2, 8.8, 7.24]]}, {"timestamp": 1631529670341, "ltp": 1.29, "tv": 2544.23, "trd": NaN, "batb": NaN, "batl": [[0, 3.8, 27.5], [1, 8.8, 7.24], [2, 44, 7.24]]}, {"timestamp": 1631529677153, "ltp": 1.29, "tv": 2544.23, "trd": NaN, "batb": [[0, 1.08, 837.7], [1, 1.06, 503.48], [2, 1.01, 105.88]], "batl": [[0, 1.45, 853.1], [1, 3.8, 27.5], [2, 8.8, 7.24]]}, {"timestamp": 1631529687174, "ltp": 1.29, "tv": 2544.23, "trd": NaN, "batb": NaN, "batl": [[0, 1.39, 17.79], [1, 1.45, 853.1], [2, 3.8, 27.5]]}, {"timestamp": 1631529689161, "ltp": 1.29, "tv": 2544.23, "trd": NaN, "batb": [[0, 1.06, 503.48], [1, 1.01, 105.88], [2, 1.01, 0]], "batl": [[1, 3.8, 27.5], [2, 8.8, 7.24]]}, {"timestamp": 1631529691770, "ltp": 1.29, "tv": 2544.23, "trd": NaN, "batb": [[0, 1.28, 2.17], [1, 1.06, 503.48], [2, 1.01, 105.88]], "batl": NaN}, {"timestamp": 1631529694058, "ltp": 1.28, "tv": 2546.4, "trd": [[1.28, 37.64]], "batb": [[0, 1.2, 226.33], [1, 1.18, 23.7], [2, 1.14, 261.79]], "batl": [[0, 1.3, 43.03], [1, 1.32, 21.19], [2, 1.39, 17.79]]}, {"timestamp": 1631529700562, "ltp": 1.22, "tv": 2548.67, "trd": [[1.22, 174.31]], "batb": NaN, "batl": NaN}, {"timestamp": 1631529701448, "ltp": 1.22, "tv": 2548.67, "trd": NaN, "batb": [[0, 1.22, 99], [1, 1.2, 226.33], [2, 1.18, 23.7]], "batl": NaN}, {"timestamp": 1631529702553, "ltp": 1.22, "tv": 2548.67, "trd": NaN, "batb": NaN, "batl": [[0, 1.28, 18.09], [1, 1.3, 43.03], [2, 1.32, 21.19]]}, {"timestamp": 1631529705247, "ltp": 1.22, "tv": 2548.67, "trd": NaN, "batb": NaN, "batl": [[0, 1.3, 43.03], [1, 1.32, 21.19], [2, 1.39, 17.79]]}, {"timestamp": 1631529710985, "ltp": 1.22, "tv": 2548.67, "trd": NaN, "batb": [[0, 1.14, 261.79], [1, 1.01, 105.88], [2, 1.18, 0]], "batl": [[0, 1.39, 17.79], [1, 3.8, 27.5], [2, 8.8, 7.24]]}, {"timestamp": 1631529722379, "ltp": 1.22, "tv": 2548.67, "trd": NaN, "batb": NaN, "batl": [[0, 1.15, 2.17], [1, 1.39, 17.79], [2, 3.8, 27.5]]}, {"timestamp": 1631529727789, "ltp": 1.22, "tv": 2548.67, "trd": NaN, "batb": NaN, "batl": [[0, 1.39, 17.79], [1, 3.8, 27.5], [2, 8.8, 7.24]]}, {"timestamp": 1631529732123, "ltp": 1.22, "tv": 2548.67, "trd": NaN, "batb": NaN, "batl": [[0, 3.8, 27.5], [1, 8.8, 7.24], [2, 44, 7.24]]}, {"timestamp": 1631529745808, "ltp": 1.22, "tv": 2548.67, "trd": NaN, "batb": [[0, 1.14, 310.86], [1, 1.12, 24.98], [2, 1.01, 105.88]], "batl": [[0, 1.18, 33.9], [1, 1.24, 965.35], [2, 1.26, 22.19]]}, {"timestamp": 1631529746853, "ltp": 1.22, "tv": 2548.67, "trd": NaN, "batb": [[2, 1.06, 510.18]], "batl": NaN}, {"timestamp": 1631529753833, "ltp": 1.22, "tv": 2548.67, "trd": NaN, "batb": [[0, 1.16, 86], [1, 1.14, 310.86], [2, 1.12, 24.98]], "batl": NaN}, {"timestamp": 1631529757224, "ltp": 1.16, "tv": 2613.79, "trd": [[1.16, 65.12]], "batb": [[0, 1.16, 53.45]], "batl": NaN}, {"timestamp": 1631529758268, "ltp": 1.16, "tv": 2613.79, "trd": NaN, "batb": [[0, 1.14, 310.86], [1, 1.12, 24.98], [2, 1.06, 510.18]], "batl": NaN}, {"timestamp": 1631529761348, "ltp": 1.16, "tv": 2613.79, "trd": NaN, "batb": [[0, 1.17, 330], [1, 1.14, 310.86], [2, 1.12, 24.98]], "batl": NaN}, {"timestamp": 1631529762867, "ltp": 1.16, "tv": 2613.79, "trd": NaN, "batb": [[1, 1.14, 261.79], [2, 1.06, 510.18]], "batl": [[1, 1.24, 920.24], [2, 3.8, 27.5]]}, {"timestamp": 1631529768969, "ltp": 1.16, "tv": 2613.79, "trd": NaN, "batb": [[0, 1.06, 510.18], [1, 1.01, 105.88], [2, 1.06, 0]], "batl": [[0, 3.8, 27.5], [1, 8.8, 7.24], [2, 44, 7.24]]}, {"timestamp": 1631529775345, "ltp": 1.16, "tv": 2613.79, "trd": NaN, "batb": [[0, 1.2, 46.62], [1, 1.18, 23.7], [2, 1.06, 510.18]], "batl": [[0, 1.23, 286.06], [1, 1.3, 43.03], [2, 1.32, 21.19]]}, {"timestamp": 1631529776270, "ltp": 1.16, "tv": 2613.79, "trd": NaN, "batb": [[1, 1.19, 182.73], [2, 1.18, 23.7]], "batl": NaN}, {"timestamp": 1631529783288, "ltp": 1.16, "tv": 2613.79, "trd": NaN, "batb": [[0, 1.22, 157], [1, 1.2, 46.62], [2, 1.19, 182.73]], "batl": NaN}, {"timestamp": 1631529789189, "ltp": 1.16, "tv": 2613.79, "trd": NaN, "batb": [[0, 1.13, 265.3], [1, 1.01, 105.88], [2, 1.19, 0]], "batl": [[0, 3.8, 27.5], [1, 8.8, 7.24], [2, 44, 7.24]]}, {"timestamp": 1631529794277, "ltp": 1.16, "tv": 2613.79, "trd": NaN, "batb": NaN, "batl": [[0, 1.24, 534.41], [1, 3.8, 27.5], [2, 8.8, 7.24]]}, {"timestamp": 1631529794482, "ltp": 1.16, "tv": 2613.79, "trd": NaN, "batb": NaN, "batl": [[0, 3.8, 27.5], [1, 8.8, 7.24], [2, 44, 7.24]]}, {"timestamp": 1631529802004, "ltp": 1.16, "tv": 2613.79, "trd": NaN, "batb": NaN, "batl": [[0, 1.14, 2.17], [1, 3.8, 27.5], [2, 8.8, 7.24]]}, {"timestamp": 1631529804289, "ltp": 1.16, "tv": 2613.79, "trd": NaN, "batb": NaN, "batl": [[1, 1.39, 17.79], [2, 3.8, 27.5]]}, {"timestamp": 1631529806209, "ltp": 1.16, "tv": 2613.79, "trd": NaN, "batb": NaN, "batl": [[0, 1.39, 17.79], [1, 3.8, 27.5], [2, 8.8, 7.24]]}, {"timestamp": 1631529806890, "ltp": 1.16, "tv": 2613.79, "trd": NaN, "batb": [[0, 1.14, 49.07], [1, 1.13, 265.3], [2, 1.12, 24.98]], "batl": [[0, 1.17, 312.59], [1, 1.18, 33.9], [2, 1.24, 45.11]]}, {"timestamp": 1631529811212, "ltp": 1.16, "tv": 2613.79, "trd": NaN, "batb": [[0, 1.15, 73], [1, 1.14, 49.07], [2, 1.13, 265.3]], "batl": NaN}, {"timestamp": 1631529818329, "ltp": 1.16, "tv": 2613.79, "trd": NaN, "batb": [[0, 1.14, 49.07], [1, 1.13, 265.3], [2, 1.12, 24.98]], "batl": NaN}, {"timestamp": 1631529821380, "ltp": 1.16, "tv": 2613.79, "trd": NaN, "batb": [[0, 1.16, 254], [1, 1.14, 49.07], [2, 1.13, 265.3]], "batl": NaN}, {"timestamp": 1631529823724, "ltp": 1.16, "tv": 2613.79, "trd": NaN, "batb": [[1, 1.13, 265.3], [2, 1.06, 516.46]], "batl": [[2, 1.39, 17.79]]}, {"timestamp": 1631529829144, "ltp": 1.16, "tv": 2613.79, "trd": NaN, "batb": NaN, "batl": [[0, 1.39, 17.79], [1, 3.8, 27.5], [2, 8.8, 7.24]]}, {"timestamp": 1631529830242, "ltp": 1.16, "tv": 2613.79, "trd": NaN, "batb": [[0, 1.06, 516.46], [1, 1.01, 105.88], [2, 1.06, 0]], "batl": NaN}, {"timestamp": 1631529837318, "ltp": 1.16, "tv": 2613.79, "trd": NaN, "batb": NaN, "batl": [[0, 1.17, 638.81], [1, 1.39, 17.79], [2, 3.8, 27.5]]}, {"timestamp": 1631529837422, "ltp": 1.16, "tv": 2613.79, "trd": NaN, "batb": NaN, "batl": [[0, 1.39, 17.79], [1, 3.8, 27.5], [2, 8.8, 7.24]]}, {"timestamp": 1631529839312, "ltp": 1.16, "tv": 2613.79, "trd": NaN, "batb": [[0, 1.07, 908.1], [1, 1.06, 516.46], [2, 1.01, 105.88]], "batl": [[1, 1.43, 886.16], [2, 3.8, 27.5]]}, {"timestamp": 1631529841859, "ltp": 1.16, "tv": 2613.79, "trd": NaN, "batb": NaN, "batl": [[0, 1.43, 886.16], [1, 3.8, 27.5], [2, 8.8, 7.24]]}, {"timestamp": 1631529851567, "ltp": 1.16, "tv": 2613.79, "trd": NaN, "batb": [[0, 1.06, 516.46], [1, 1.01, 105.88], [2, 1.01, 0]], "batl": [[0, 3.8, 27.5], [1, 8.8, 7.24], [2, 44, 7.24]]}, {"timestamp": 1631529852867, "ltp": 1.16, "tv": 2613.79, "trd": NaN, "batb": [[0, 1.08, 96.2], [1, 1.06, 542.84], [2, 1.01, 105.88]], "batl": [[0, 1.1, 258.95], [1, 1.11, 36.04], [2, 1.16, 48.23]]}, {"timestamp": 1631529853644, "ltp": 1.16, "tv": 2613.79, "trd": NaN, "batb": [[2, 1.05, 630.01]], "batl": NaN}, {"timestamp": 1631529856148, "ltp": 1.16, "tv": 2613.79, "trd": NaN, "batb": [[0, 1.08, 336.2]], "batl": NaN}, {"timestamp": 1631529939751, "ltp": 1.16, "tv": 2613.79, "trd": NaN, "batb": [[0, 1.08, 284.4], [1, 1.06, 516.46]], "batl": [[2, 1.25, 14.82]]}, {"timestamp": 1631529943757, "ltp": 1.16, "tv": 2613.79, "trd": NaN, "batb": [[0, 1.05, 630.01], [1, 1.03, 1596.7], [2, 1.01, 105.88]], "batl": [[0, 1.25, 14.82], [1, 1.35, 1073.88], [2, 1.39, 17.79]]}, {"timestamp": 1631529959200, "ltp": 1.16, "tv": 2613.79, "trd": NaN, "batb": [[1, 1.01, 105.88], [2, 1.01, 0]], "batl": NaN}, {"timestamp": 1631529960288, "ltp": 1.16, "tv": 2613.79, "trd": NaN, "batb": [[0, 1.11, 50.39], [1, 1.09, 25.66], [2, 1.05, 630.01]], "batl": [[0, 1.13, 551.21], [1, 1.2, 46.62], [2, 1.22, 22.92]]}, {"timestamp": 1631529961216, "ltp": 1.16, "tv": 2613.79, "trd": NaN, "batb": [[1, 1.09, 394.3], [2, 1.07, 464.03]], "batl": NaN}, {"timestamp": 1631529966594, "ltp": 1.16, "tv": 2613.79, "trd": NaN, "batb": [[0, 1.11, 366.39]], "batl": NaN}, {"timestamp": 1631529971340, "ltp": 1.16, "tv": 2613.79, "trd": NaN, "batb": [[0, 1.07, 464.03], [1, 1.06, 970.7], [2, 1.01, 105.88]], "batl": [[0, 1.25, 14.82], [1, 1.35, 1073.88], [2, 1.39, 17.79]]}, {"timestamp": 1631529979520, "ltp": 1.16, "tv": 2613.79, "trd": NaN, "batb": [[1, 1.01, 105.88], [2, 1.01, 0]], "batl": NaN}, {"timestamp": 1631529980817, "ltp": 1.16, "tv": 2613.79, "trd": NaN, "batb": [[0, 1.15, 48.64], [1, 1.13, 24.75], [2, 1.07, 464.03]], "batl": [[0, 1.17, 348.04], [1, 1.24, 45.11], [2, 1.25, 14.82]]}, {"timestamp": 1631529981806, "ltp": 1.16, "tv": 2613.79, "trd": NaN, "batb": [[1, 1.14, 256.18], [2, 1.13, 24.75]], "batl": NaN}, {"timestamp": 1631529985240, "ltp": 1.17, "tv": 2622.54, "trd": [[1.17, 8.75]], "batb": NaN, "batl": [[0, 1.17, 342.21]]}, {"timestamp": 1631529987225, "ltp": 1.17, "tv": 2622.54, "trd": NaN, "batb": [[0, 1.16, 225], [1, 1.15, 48.64], [2, 1.14, 256.18]], "batl": NaN}, {"timestamp": 1631529989337, "ltp": 1.17, "tv": 2622.54, "trd": NaN, "batb": [[0, 1.11, 317.48], [1, 1.08, 837.7], [2, 1.01, 105.88]], "batl": [[0, 1.25, 14.82], [1, 1.35, 1073.88], [2, 1.39, 17.79]]}, {"timestamp": 1631530002867, "ltp": 1.17, "tv": 2622.54, "trd": NaN, "batb": [[1, 1.01, 105.88], [2, 1.01, 0]], "batl": [[1, 1.39, 17.79], [2, 3.8, 27.5]]}, {"timestamp": 1631530004278, "ltp": 1.17, "tv": 2622.54, "trd": NaN, "batb": [[0, 1.19, 47.01], [1, 1.18, 289.51], [2, 1.17, 23.91]], "batl": [[0, 1.23, 34.48], [1, 1.25, 14.82], [2, 1.29, 43.37]]}, {"timestamp": 1631530005263, "ltp": 1.17, "tv": 2622.54, "trd": NaN, "batb": [[0, 1.2, 180.14], [1, 1.19, 47.01], [2, 1.18, 289.51]], "batl": NaN}, {"timestamp": 1631530009269, "ltp": 1.23, "tv": 2628.38, "trd": [[1.23, 232.66]], "batb": NaN, "batl": [[0, 1.23, 31.56]]}, {"timestamp": 1631530012294, "ltp": 1.23, "tv": 2628.38, "trd": NaN, "batb": [[0, 1.21, 85], [1, 1.2, 180.14], [2, 1.19, 47.01]], "batl": NaN}, {"timestamp": 1631530018286, "ltp": 1.23, "tv": 2628.38, "trd": NaN, "batb": [[0, 1.17, 211.04], [1, 1.13, 639.92], [2, 1.01, 105.88]], "batl": [[0, 1.25, 14.82], [1, 1.39, 17.79], [2, 1.53, 725.37]]}, {"timestamp": 1631530032495, "ltp": 1.23, "tv": 2628.38, "trd": NaN, "batb": NaN, "batl": [[0, 1.39, 17.79], [1, 1.53, 725.37], [2, 3.8, 27.5]]}, {"timestamp": 1631530043324, "ltp": 1.23, "tv": 2628.38, "trd": NaN, "batb": [[0, 1.17, 258.85], [1, 1.15, 24.32]], "batl": [[0, 1.2, 13.97], [1, 1.23, 865.8], [2, 1.27, 44.05]]}, {"timestamp": 1631530044203, "ltp": 1.2, "tv": 2632.72, "trd": [[1.2, 4.34]], "batb": [[2, 1.13, 268.49]], "batl": [[0, 1.2, 11.8]]}, {"timestamp": 1631530046219, "ltp": 1.2, "tv": 2656.32, "trd": [[1.2, 27.94]], "batb": NaN, "batl": [[0, 1.23, 865.8], [1, 1.27, 44.05], [2, 1.29, 21.68]]}, {"timestamp": 1631530051302, "ltp": 1.18, "tv": 2658.53, "trd": [[1.18, 6.35]], "batb": [[0, 1.19, 151], [1, 1.17, 258.85], [2, 1.15, 24.32]], "batl": NaN}, {"timestamp": 1631530051509, "ltp": 1.18, "tv": 2658.53, "trd": NaN, "batb": [[0, 1.17, 258.85], [1, 1.15, 24.32], [2, 1.13, 268.49]], "batl": NaN}, {"timestamp": 1631530054217, "ltp": 1.18, "tv": 2658.53, "trd": NaN, "batb": NaN, "batl": [[0, 1.27, 44.05], [1, 1.29, 21.68], [2, 1.39, 17.79]]}, {"timestamp": 1631530054841, "ltp": 1.18, "tv": 2658.53, "trd": NaN, "batb": [[0, 1.13, 268.49], [1, 1.11, 695.13], [2, 1.01, 105.88]], "batl": [[0, 1.39, 17.79], [1, 1.53, 725.37], [2, 3.8, 27.5]]}, {"timestamp": 1631530057121, "ltp": 1.18, "tv": 2658.53, "trd": NaN, "batb": NaN, "batl": [[0, 1.53, 725.37], [1, 3.8, 27.5], [2, 8.8, 7.24]]}, {"timestamp": 1631530065038, "ltp": 1.18, "tv": 2658.53, "trd": NaN, "batb": [[0, 1.32, 2.17], [1, 1.13, 268.49]], "batl": [[0, 3.8, 27.5], [1, 8.8, 7.24], [2, 44, 7.24]]}, {"timestamp": 1631530066330, "ltp": 1.32, "tv": 2662.87, "trd": [[1.32, 13.26]], "batb": [[0, 1.13, 268.49], [1, 1.01, 105.88], [2, 1.01, 0]], "batl": [[0, 1.16, 292.23], [1, 1.17, 46.48], [2, 3.8, 27.5]]}, {"timestamp": 1631530067158, "ltp": 1.32, "tv": 2662.87, "trd": NaN, "batb": [[0, 1.13, 317.99], [1, 1.11, 25.2], [2, 1.09, 394.69]], "batl": [[2, 1.23, 45.48]]}, {"timestamp": 1631530071249, "ltp": 1.16, "tv": 2671.6, "trd": [[1.16, 73.85]], "batb": NaN, "batl": [[0, 1.16, 286.41], [1, 1.17, 366.15]]}, {"timestamp": 1631530071455, "ltp": 1.16, "tv": 2671.6, "trd": NaN, "batb": NaN, "batl": [[1, 1.17, 46.48]]}, {"timestamp": 1631530073169, "ltp": 1.15, "tv": 2674.1, "trd": [[1.15, 4.67]], "batb": NaN, "batl": NaN}, {"timestamp": 1631530074361, "ltp": 1.15, "tv": 2674.1, "trd": NaN, "batb": [[0, 1.15, 117], [1, 1.13, 317.99], [2, 1.11, 25.2]], "batl": NaN}, {"timestamp": 1631530079072, "ltp": 1.15, "tv": 2674.1, "trd": NaN, "batb": NaN, "batl": [[0, 1.23, 45.48], [1, 1.25, 22.38], [2, 1.45, 853.1]]}, {"timestamp": 1631530079642, "ltp": 1.15, "tv": 2674.1, "trd": NaN, "batb": [[0, 1.09, 394.69], [1, 1.08, 837.7], [2, 1.01, 105.88]], "batl": [[0, 1.45, 853.1], [1, 3.8, 27.5], [2, 8.8, 7.24]]}, {"timestamp": 1631530085291, "ltp": 1.15, "tv": 2674.1, "trd": NaN, "batb": NaN, "batl": [[0, 3.8, 27.5], [1, 8.8, 7.24], [2, 44, 7.24]]}, {"timestamp": 1631530085447, "ltp": 1.15, "tv": 2674.1, "trd": NaN, "batb": [[1, 1.01, 105.88], [2, 1.01, 0]], "batl": NaN}, {"timestamp": 1631530087050, "ltp": 1.15, "tv": 2674.1, "trd": NaN, "batb": [[0, 1.09, 446.01], [1, 1.08, 342.48], [2, 1.07, 26.14]], "batl": [[0, 1.17, 905.53], [1, 1.18, 47.41], [2, 1.2, 23.31]]}, {"timestamp": 1631530091299, "ltp": 1.1, "tv": 2676.1, "trd": [[1.1, 2]], "batb": NaN, "batl": NaN}, {"timestamp": 1631530097182, "ltp": 1.1, "tv": 2676.1, "trd": NaN, "batb": [[1, 1.07, 26.14], [2, 1.06, 548.7]], "batl": [[0, 1.18, 47.41], [1, 1.2, 23.31], [2, 1.38, 988.33]]}, {"timestamp": 1631530097705, "ltp": 1.1, "tv": 2676.1, "trd": NaN, "batb": [[0, 1.06, 548.7], [1, 1.05, 1086.45], [2, 1.01, 105.88]], "batl": [[0, 1.38, 988.33], [1, 3.8, 27.5], [2, 8.8, 7.24]]}, {"timestamp": 1631530105786, "ltp": 1.1, "tv": 2676.1, "trd": NaN, "batb": [[1, 1.01, 105.88], [2, 1.01, 0]], "batl": NaN}, {"timestamp": 1631530107800, "ltp": 1.1, "tv": 2676.1, "trd": NaN, "batb": [[0, 1.06, 601.47], [1, 1.04, 26.89], [2, 1.01, 105.88]], "batl": [[0, 1.09, 85.53], [1, 1.12, 905.53], [2, 1.14, 49.07]]}, {"timestamp": 1631530108580, "ltp": 1.1, "tv": 2676.1, "trd": NaN, "batb": [[1, 1.04, 727.92]], "batl": NaN}, {"timestamp": 1631530109529, "ltp": 1.1, "tv": 2676.1, "trd": NaN, "batb": [[2, 1.03, 1596.7]], "batl": NaN}, {"timestamp": 1631530116093, "ltp": 1.1, "tv": 2676.1, "trd": NaN, "batb": [[0, 1.04, 701.03], [1, 1.03, 1596.7], [2, 1.01, 105.88]], "batl": [[0, 1.38, 988.33], [1, 3.8, 27.5], [2, 8.8, 7.24]]}, {"timestamp": 1631530126445, "ltp": 1.1, "tv": 2676.1, "trd": NaN, "batb": NaN, "batl": [[1, 1.39, 17.79], [2, 3.8, 27.5]]}, {"timestamp": 1631530128212, "ltp": 1.1, "tv": 2676.1, "trd": NaN, "batb": [[1, 1.01, 105.88], [2, 1.01, 0]], "batl": NaN}, {"timestamp": 1631530129248, "ltp": 1.1, "tv": 2676.1, "trd": NaN, "batb": [[0, 1.06, 31.85], [1, 1.05, 183.91], [2, 1.04, 754.82]], "batl": [[0, 1.07, 717.45], [1, 1.12, 49.95], [2, 1.14, 24.53]]}, {"timestamp": 1631530135914, "ltp": 1.1, "tv": 2676.1, "trd": NaN, "batb": [[0, 1.06, 148.85]], "batl": NaN}, {"timestamp": 1631530149869, "ltp": 1.06, "tv": 2679.52, "trd": [[1.06, 3.42]], "batb": [[0, 1.06, 147.14]], "batl": NaN}, {"timestamp": 1631530159237, "ltp": 1.06, "tv": 2679.52, "trd": NaN, "batb": [[0, 1.03, 927.81], [1, 1.02, 2218.56], [2, 1.01, 105.88]], "batl": [[0, 1.38, 988.33], [1, 1.39, 17.79], [2, 3.8, 27.5]]}, {"timestamp": 1631530164285, "ltp": 1.06, "tv": 2679.52, "trd": NaN, "batb": NaN, "batl": [[0, 1.08, 983.19], [1, 1.38, 988.33], [2, 1.39, 17.79]]}, {"timestamp": 1631530164492, "ltp": 1.06, "tv": 2679.52, "trd": NaN, "batb": NaN, "batl": [[0, 1.38, 988.33], [1, 1.39, 17.79], [2, 3.8, 27.5]]}, {"timestamp": 1631530168759, "ltp": 1.06, "tv": 2679.52, "trd": NaN, "batb": NaN, "batl": [[0, 1.06, 2.17], [1, 1.38, 988.33], [2, 1.39, 17.79]]}, {"timestamp": 1631530180182, "ltp": 1.06, "tv": 2679.52, "trd": NaN, "batb": [[1, 1.01, 105.88], [2, 1.01, 0]], "batl": [[1, 1.19, 14.82], [2, 1.25, 14.82]]}, {"timestamp": 1631530181183, "ltp": 1.06, "tv": 2681.69, "trd": [[1.06, 5.59]], "batb": [[0, 1.07, 30.4], [1, 1.05, 683.95], [2, 1.03, 954.97]], "batl": [[0, 1.08, 327.12], [1, 1.14, 49.07], [2, 1.16, 24.11]]}, {"timestamp": 1631530182110, "ltp": 1.06, "tv": 2681.69, "trd": NaN, "batb": [[1, 1.05, 1277.78], [2, 1.04, 737.46]], "batl": NaN}, {"timestamp": 1631530185190, "ltp": 1.06, "tv": 2681.69, "trd": NaN, "batb": [[0, 1.07, 167.4]], "batl": NaN}, {"timestamp": 1631530192234, "ltp": 1.06, "tv": 2681.69, "trd": NaN, "batb": [[0, 1.04, 737.46], [1, 1.03, 1596.7], [2, 1.01, 105.88]], "batl": [[0, 1.19, 14.82], [1, 1.21, 14.82], [2, 1.23, 29.65]]}, {"timestamp": 1631530201947, "ltp": 1.06, "tv": 2681.69, "trd": NaN, "batb": [[0, 1.07, 37.38], [1, 1.06, 52.78], [2, 1.04, 764.35]], "batl": [[0, 1.09, 652.11], [1, 1.15, 48.64], [2, 1.17, 23.91]]}, {"timestamp": 1631530202836, "ltp": 1.06, "tv": 2681.69, "trd": NaN, "batb": [[1, 1.06, 578.11], [2, 1.05, 611.17]], "batl": NaN}, {"timestamp": 1631530210261, "ltp": 1.06, "tv": 2681.69, "trd": NaN, "batb": [[0, 1.08, 233], [1, 1.07, 37.38], [2, 1.06, 578.11]], "batl": NaN}, {"timestamp": 1631530213448, "ltp": 1.09, "tv": 2682.71, "trd": [[1.09, 1.02]], "batb": NaN, "batl": [[0, 1.09, 651.09]]}, {"timestamp": 1631530215340, "ltp": 1.09, "tv": 2682.71, "trd": NaN, "batb": [[0, 1.06, 525.33], [1, 1.05, 611.17], [2, 1.03, 1596.7]], "batl": [[0, 1.19, 14.82], [1, 1.21, 14.82], [2, 1.23, 29.65]]}, {"timestamp": 1631530215441, "ltp": 1.09, "tv": 2682.71, "trd": NaN, "batb": [[0, 1.05, 611.17], [1, 1.03, 1596.7], [2, 1.01, 105.88]], "batl": NaN}, {"timestamp": 1631530227647, "ltp": 1.09, "tv": 2682.71, "trd": NaN, "batb": NaN, "batl": [[0, 1.17, 29.65], [1, 1.19, 14.82], [2, 1.21, 14.82]]}, {"timestamp": 1631530233060, "ltp": 1.09, "tv": 2682.71, "trd": NaN, "batb": [[1, 1.01, 105.88], [2, 1.01, 0]], "batl": NaN}, {"timestamp": 1631530235094, "ltp": 1.09, "tv": 2682.71, "trd": NaN, "batb": [[0, 1.07, 52.28], [1, 1.05, 637.81], [2, 1.01, 105.88]], "batl": [[0, 1.09, 266.49], [1, 1.1, 37.91], [2, 1.16, 48.23]]}, {"timestamp": 1631530235994, "ltp": 1.09, "tv": 2682.71, "trd": NaN, "batb": [[1, 1.06, 528.43], [2, 1.05, 26.64]], "batl": NaN}, {"timestamp": 1631530243070, "ltp": 1.09, "tv": 2682.71, "trd": NaN, "batb": [[0, 1.08, 86], [1, 1.07, 52.28], [2, 1.06, 528.43]], "batl": NaN}, {"timestamp": 1631530244201, "ltp": 1.09, "tv": 2682.71, "trd": NaN, "batb": NaN, "batl": [[0, 1.16, 48.23], [1, 1.17, 29.65], [2, 1.18, 23.7]]}, {"timestamp": 1631530244779, "ltp": 1.09, "tv": 2682.71, "trd": NaN, "batb": [[0, 1.06, 528.43], [1, 1.04, 1282.94], [2, 1.01, 105.88]], "batl": [[0, 1.17, 29.65], [1, 1.19, 14.82], [2, 1.21, 14.82]]}, {"timestamp": 1631530246015, "ltp": 1.09, "tv": 2682.71, "trd": NaN, "batb": [[0, 1.09, 90.16], [1, 1.06, 528.43], [2, 1.04, 1282.94]], "batl": NaN}, {"timestamp": 1631530249286, "ltp": 1.09, "tv": 2682.71, "trd": NaN, "batb": [[0, 1.06, 528.43], [1, 1.04, 1282.94], [2, 1.01, 105.88]], "batl": NaN}, {"timestamp": 1631530260620, "ltp": 1.09, "tv": 2682.71, "trd": NaN, "batb": [[1, 1.01, 105.88], [2, 1.01, 0]], "batl": NaN}, {"timestamp": 1631530261817, "ltp": 1.09, "tv": 2682.71, "trd": NaN, "batb": [[0, 1.06, 581.21], [1, 1.04, 26.89], [2, 1.01, 105.88]], "batl": [[0, 1.09, 630.69], [1, 1.11, 36.04], [2, 1.15, 48.64]]}, {"timestamp": 1631530262701, "ltp": 1.09, "tv": 2682.71, "trd": NaN, "batb": [[1, 1.05, 604.64], [2, 1.04, 26.89]], "batl": NaN}, {"timestamp": 1631530270240, "ltp": 1.09, "tv": 2682.71, "trd": NaN, "batb": [[0, 1.07, 133], [1, 1.06, 581.21], [2, 1.05, 604.64]], "batl": NaN}, {"timestamp": 1631530272208, "ltp": 1.07, "tv": 2693.11, "trd": [[1.07, 10.4]], "batb": [[0, 1.06, 581.21], [1, 1.05, 604.64], [2, 1.04, 26.89]], "batl": NaN}, {"timestamp": 1631530275310, "ltp": 1.07, "tv": 2693.11, "trd": NaN, "batb": [[0, 1.08, 327], [2, 1.03, 1596.7]], "batl": [[0, 1.17, 29.65], [1, 1.19, 14.82], [2, 1.21, 14.82]]}, {"timestamp": 1631530275510, "ltp": 1.07, "tv": 2693.11, "trd": NaN, "batb": [[0, 1.05, 604.64], [1, 1.03, 1596.7], [2, 1.01, 105.88]], "batl": NaN}, {"timestamp": 1631530276651, "ltp": 1.07, "tv": 2693.11, "trd": NaN, "batb": [[0, 1.09, 90.16], [1, 1.05, 604.64], [2, 1.03, 1596.7]], "batl": NaN}, {"timestamp": 1631530280163, "ltp": 1.07, "tv": 2693.11, "trd": NaN, "batb": [[0, 1.05, 604.64], [1, 1.03, 1596.7], [2, 1.01, 105.88]], "batl": NaN}, {"timestamp": 1631530282749, "ltp": 1.07, "tv": 2693.11, "trd": NaN, "batb": [[0, 1.08, 42.51], [1, 1.07, 52.28], [2, 1.05, 631.28]], "batl": [[0, 1.09, 257.83], [1, 1.1, 37.13], [2, 1.16, 48.23]]}, {"timestamp": 1631530283840, "ltp": 1.07, "tv": 2693.11, "trd": NaN, "batb": [[1, 1.07, 531.55]], "batl": NaN}, {"timestamp": 1631530292163, "ltp": 1.09, "tv": 2727.35, "trd": [[1.09, 35.26]], "batb": NaN, "batl": [[0, 1.09, 223.59]]}, {"timestamp": 1631530292475, "ltp": 1.09, "tv": 2907.67, "trd": [[1.09, 215.58]], "batb": NaN, "batl": [[0, 1.09, 133.43]]}, {"timestamp": 1631530298478, "ltp": 1.08, "tv": 2911.67, "trd": [[1.08, 4]], "batb": [[0, 1.08, 40.51]], "batl": NaN}, {"timestamp": 1631530308649, "ltp": 1.08, "tv": 2911.67, "trd": NaN, "batb": [[0, 1.07, 531.55], [1, 1.05, 631.28], [2, 1.03, 1596.7]], "batl": [[1, 1.16, 48.23], [2, 1.18, 23.7]]}, {"timestamp": 1631530311971, "ltp": 1.08, "tv": 2911.67, "trd": NaN, "batb": NaN, "batl": [[1, 1.1, 38.12], [2, 1.16, 48.23]]}, {"timestamp": 1631530369745, "ltp": 1.08, "tv": 2911.67, "trd": NaN, "batb": [[0, 1.07, 479.27], [1, 1.05, 604.64]], "batl": [[2, 1.18, 90.16]]}, {"timestamp": 1631530380134, "ltp": 1.08, "tv": 2911.67, "trd": NaN, "batb": NaN, "batl": [[0, 1.18, 90.16], [1, 1.19, 14.82], [2, 1.21, 14.82]]}, {"timestamp": 1631530380547, "ltp": 1.08, "tv": 2911.67, "trd": NaN, "batb": [[0, 1.05, 604.64], [1, 1.03, 1596.7], [2, 1.01, 105.88]], "batl": NaN}, {"timestamp": 1631530385270, "ltp": 1.08, "tv": 2911.67, "trd": NaN, "batb": [[1, 1.01, 105.88], [2, 1.01, 0]], "batl": NaN}, {"timestamp": 1631530388742, "ltp": 1.08, "tv": 2911.67, "trd": NaN, "batb": [[1, 1.04, 1282.94], [2, 1.01, 105.88]], "batl": NaN}, {"timestamp": 1631530416276, "ltp": 1.08, "tv": 2911.67, "trd": NaN, "batb": [[1, 1.01, 105.88], [2, 1.01, 0]], "batl": NaN}, {"timestamp": 1631530417306, "ltp": 1.08, "tv": 2911.67, "trd": NaN, "batb": [[0, 1.05, 1265.13], [1, 1.03, 27.16], [2, 1.01, 105.88]], "batl": [[0, 1.08, 40.4], [1, 1.1, 390.06], [2, 1.13, 49.5]]}, {"timestamp": 1631530418188, "ltp": 1.08, "tv": 2911.67, "trd": NaN, "batb": [[1, 1.03, 806.99]], "batl": NaN}, {"timestamp": 1631530420095, "ltp": 1.08, "tv": 2911.67, "trd": NaN, "batb": [[2, 1.02, 2218.56]], "batl": NaN}, {"timestamp": 1631530434290, "ltp": 1.08, "tv": 2911.67, "trd": NaN, "batb": [[0, 1.03, 779.83], [1, 1.02, 2218.56], [2, 1.01, 105.88]], "batl": [[0, 1.18, 90.16], [1, 1.19, 14.82], [2, 1.21, 14.82]]}, {"timestamp": 1631530439727, "ltp": 1.08, "tv": 2911.67, "trd": NaN, "batb": [[1, 1.01, 105.88], [2, 1.01, 0]], "batl": NaN}, {"timestamp": 1631530441230, "ltp": 1.08, "tv": 2911.67, "trd": NaN, "batb": [[0, 1.04, 655.97], [1, 1.03, 779.83], [2, 1.01, 105.88]], "batl": [[0, 1.06, 27.15], [1, 1.07, 780.11], [2, 1.18, 90.16]]}, {"timestamp": 1631530442325, "ltp": 1.08, "tv": 2911.67, "trd": NaN, "batb": [[0, 1.04, 709.76], [2, 1.02, 27.42]], "batl": [[2, 1.12, 49.95]]}, {"timestamp": 1631530446316, "ltp": 1.08, "tv": 2911.67, "trd": NaN, "batb": NaN, "batl": [[2, 1.08, 15.08]]}, {"timestamp": 1631530446416, "ltp": 1.08, "tv": 2911.67, "trd": NaN, "batb": NaN, "batl": [[2, 1.12, 49.95]]}, {"timestamp": 1631530450354, "ltp": 1.08, "tv": 2911.67, "trd": NaN, "batb": [[0, 1.04, 53.79]], "batl": [[0, 1.12, 49.95], [1, 1.14, 24.53], [2, 1.18, 90.16]]}, {"timestamp": 1631530450824, "ltp": 1.08, "tv": 2911.67, "trd": NaN, "batb": [[0, 1.03, 779.83], [1, 1.01, 4236.55], [2, 1.02, 0]], "batl": [[0, 1.18, 90.16], [1, 1.19, 14.82], [2, 1.21, 14.82]]}, {"timestamp": 1631530457354, "ltp": 1.08, "tv": 2911.67, "trd": NaN, "batb": [[0, 1.04, 348.66], [1, 1.03, 779.83], [2, 1.01, 4236.55]], "batl": [[0, 1.06, 905.46], [1, 1.18, 90.16], [2, 1.19, 14.82]]}, {"timestamp": 1631530458344, "ltp": 1.08, "tv": 2911.67, "trd": NaN, "batb": [[1, 1.03, 834.14], [2, 1.02, 1057.78]], "batl": [[1, 1.11, 50.39], [2, 1.13, 24.75]]}, {"timestamp": 1631530465359, "ltp": 1.08, "tv": 2911.67, "trd": NaN, "batb": [[0, 1.03, 54.31], [1, 1.02, 1057.78], [2, 1.01, 4264.25]], "batl": [[0, 1.11, 50.39], [1, 1.13, 24.75], [2, 1.18, 90.16]]}, {"timestamp": 1631530465557, "ltp": 1.08, "tv": 2911.67, "trd": NaN, "batb": [[0, 1.02, 1057.78], [1, 1.01, 4236.55], [2, 1.01, 0]], "batl": [[0, 1.18, 90.16], [1, 1.19, 14.82], [2, 1.21, 14.82]]}, {"timestamp": 1631530483164, "ltp": 1.08, "tv": 2911.67, "trd": NaN, "batb": [[0, 1.04, 646], [1, 1.03, 54.31], [2, 1.02, 1057.78]], "batl": [[0, 1.06, 34.2], [1, 1.11, 50.39], [2, 1.13, 24.75]]}, {"timestamp": 1631530484187, "ltp": 1.08, "tv": 2911.67, "trd": NaN, "batb": [[0, 1.04, 1404.9], [1, 1.03, 963.36]], "batl": NaN}, {"timestamp": 1631530484966, "ltp": 1.08, "tv": 2911.67, "trd": NaN, "batb": [[2, 1.01, 4264.25]], "batl": NaN}, {"timestamp": 1631530486465, "ltp": 1.05, "tv": 2914.56, "trd": [[1.05, 2.9]], "batb": NaN, "batl": NaN}, {"timestamp": 1631530493977, "ltp": 1.05, "tv": 2914.56, "trd": NaN, "batb": NaN, "batl": [[1, 1.07, 214.83], [2, 1.11, 50.39]]}, {"timestamp": 1631530496703, "ltp": 1.06, "tv": 2919.86, "trd": [[1.06, 10.89]], "batb": NaN, "batl": [[0, 1.07, 214.83], [1, 1.11, 50.39], [2, 1.13, 24.75]]}, {"timestamp": 1631530498199, "ltp": 1.06, "tv": 2919.86, "trd": NaN, "batb": [[0, 1.04, 758.9]], "batl": NaN}, {"timestamp": 1631530498715, "ltp": 1.06, "tv": 2919.86, "trd": NaN, "batb": [[0, 1.03, 909.05], [1, 1.01, 4236.55], [2, 1.01, 0]], "batl": [[1, 1.19, 14.82], [2, 1.21, 14.82]]}, {"timestamp": 1631530515323, "ltp": 1.06, "tv": 2919.86, "trd": NaN, "batb": [[0, 1.04, 434.43], [1, 1.03, 909.05], [2, 1.02, 54.84]], "batl": [[0, 1.06, 719.53], [1, 1.07, 214.83], [2, 1.1, 50.85]]}, {"timestamp": 1631530540352, "ltp": 1.06, "tv": 2919.86, "trd": NaN, "batb": [[0, 1.03, 909.05], [1, 1.01, 4236.55], [2, 1.02, 0]], "batl": [[0, 1.07, 214.83], [1, 1.19, 14.82], [2, 1.21, 14.82]]}, {"timestamp": 1631530540560, "ltp": 1.06, "tv": 2919.86, "trd": NaN, "batb": [[0, 1.01, 4236.55], [1, 1.01, 0]], "batl": NaN}, {"timestamp": 1631530541859, "ltp": 1.06, "tv": 2919.86, "trd": NaN, "batb": NaN, "batl": [[1, 1.17, 29.65], [2, 1.19, 14.82]]}, {"timestamp": 1631530546578, "ltp": 1.07, "tv": 2919.91, "trd": [[1.07, 10.45]], "batb": NaN, "batl": [[0, 1.07, 214.81]]}, {"timestamp": 1631530550672, "ltp": 1.07, "tv": 2919.91, "trd": NaN, "batb": NaN, "batl": [[0, 1.05, 90.16], [1, 1.07, 214.81], [2, 1.17, 29.65]]}, {"timestamp": 1631530557270, "ltp": 1.02, "tv": 2922.8, "trd": [[1.02, 2.9]], "batb": [[0, 1.01, 188.96]], "batl": [[0, 1.04, 19.98], [1, 1.05, 386], [2, 1.07, 214.81]]}, {"timestamp": 1631530566302, "ltp": 1.02, "tv": 2922.8, "trd": NaN, "batb": [[0, 1.01, 105.88]], "batl": [[0, 1.05, 90.16], [1, 1.07, 214.81], [2, 1.17, 29.65]]}, {"timestamp": 1631530568586, "ltp": 1.02, "tv": 2922.8, "trd": NaN, "batb": [[0, 1.01, 12]], "batl": NaN}, {"timestamp": 1631530584009, "ltp": 1.02, "tv": 2922.8, "trd": NaN, "batb": [[0, 1.04, 232], [1, 1.02, 54.84], [2, 1.01, 39.69]], "batl": [[0, 1.05, 107.02], [1, 1.06, 594.62], [2, 1.07, 214.81]]}, {"timestamp": 1631530584532, "ltp": 1.02, "tv": 2922.8, "trd": NaN, "batb": [[1, 1.02, 998.48]], "batl": NaN}, {"timestamp": 1631530586148, "ltp": 1.05, "tv": 2928.33, "trd": [[1.05, 8.42]], "batb": [[2, 1.01, 3978.35]], "batl": [[0, 1.05, 104.26]]}, {"timestamp": 1631530592051, "ltp": 1.05, "tv": 2928.33, "trd": NaN, "batb": [[0, 1.04, 356]], "batl": NaN}, {"timestamp": 1631530593354, "ltp": 1.04, "tv": 2951.11, "trd": [[1.04, 22.78]], "batb": [[0, 1.04, 344.61]], "batl": NaN}, {"timestamp": 1631530595123, "ltp": 1.04, "tv": 2951.11, "trd": NaN, "batb": [[0, 1.04, 124]], "batl": [[0, 1.05, 87.4], [1, 1.07, 214.81], [2, 1.1, 50.85]]}, {"timestamp": 1631530596225, "ltp": 1.04, "tv": 2951.11, "trd": NaN, "batb": [[0, 1.01, 3950.65], [1, 1.02, 0], [2, 1.01, 0]], "batl": [[2, 1.17, 29.65]]}, {"timestamp": 1631530599726, "ltp": 1.05, "tv": 2951.21, "trd": [[1.05, 8.52]], "batb": NaN, "batl": [[0, 1.05, 87.35]]}, {"timestamp": 1631530604542, "ltp": 1.05, "tv": 2951.21, "trd": NaN, "batb": [[0, 1.01, 12]], "batl": NaN}, {"timestamp": 1631530606157, "ltp": 1.05, "tv": 2951.21, "trd": NaN, "batb": [[0, 1.01, 95.08]], "batl": [[0, 1.04, 285.82], [1, 1.05, 87.35], [2, 1.07, 214.81]]}, {"timestamp": 1631530615094, "ltp": 1.05, "tv": 2951.21, "trd": NaN, "batb": [[0, 1.01, 12]], "batl": [[0, 1.05, 87.35], [1, 1.07, 214.81], [2, 1.17, 29.65]]}, {"timestamp": 1631530622099, "ltp": 1.05, "tv": 2951.21, "trd": NaN, "batb": NaN, "batl": [[0, 1.02, 2.9], [1, 1.05, 87.35], [2, 1.07, 214.81]]}, {"timestamp": 1631530632199, "ltp": 1.05, "tv": 2951.21, "trd": NaN, "batb": NaN, "batl": [[0, 1.05, 87.35], [1, 1.07, 214.81], [2, 1.17, 29.65]]}, {"timestamp": 1631530639111, "ltp": 1.05, "tv": 2951.21, "trd": NaN, "batb": NaN, "batl": [[0, 1.02, 68.11], [1, 1.03, 606.01], [2, 1.05, 87.35]]}, {"timestamp": 1631530648002, "ltp": 1.05, "tv": 2951.21, "trd": NaN, "batb": NaN, "batl": [[0, 1.05, 87.35], [1, 1.06, 52.78], [2, 1.07, 214.81]]}, {"timestamp": 1631530649199, "ltp": 1.05, "tv": 2951.21, "trd": NaN, "batb": NaN, "batl": [[1, 1.07, 214.81], [2, 1.17, 29.65]]}, {"timestamp": 1631530667031, "ltp": 1.05, "tv": 2951.21, "trd": NaN, "batb": [[0, 1.04, 3.62], [1, 1.01, 12]], "batl": NaN}, {"timestamp": 1631530670671, "ltp": 1.01, "tv": 2982.46, "trd": [[1.01, 24.01], [1.04, 30.02]], "batb": NaN, "batl": [[0, 1.01, 159.45], [1, 1.05, 87.35], [2, 1.07, 214.81]]}, {"timestamp": 1631530676353, "ltp": 1.01, "tv": 3141.91, "trd": [[1.01, 183.46]], "batb": NaN, "batl": [[0, 1.03, 49.6], [1, 1.04, 303], [2, 1.05, 87.35]]}, {"timestamp": 1631530684754, "ltp": 1.01, "tv": 3141.91, "trd": NaN, "batb": NaN, "batl": [[2, 1.07, 214.81]]}, {"timestamp": 1631530703273, "ltp": 1.01, "tv": 3141.91, "trd": NaN, "batb": NaN, "batl": [[0, 1.07, 214.81], [1, 1.13, 14.82], [2, 1.15, 14.82]]}, {"timestamp": 1631530725000, "ltp": 1.01, "tv": 3141.91, "trd": NaN, "batb": [[0, 1.02, 54.84], [1, 1.01, 27.69]], "batl": [[0, 1.05, 34.84], [1, 1.06, 606.01], [2, 1.07, 214.81]]}, {"timestamp": 1631530725621, "ltp": 1.01, "tv": 3141.91, "trd": NaN, "batb": [[0, 1.02, 1067.15]], "batl": NaN}, {"timestamp": 1631530726723, "ltp": 1.01, "tv": 3141.91, "trd": NaN, "batb": [[1, 1.01, 3966.35]], "batl": NaN}, {"timestamp": 1631530732895, "ltp": 1.01, "tv": 3141.91, "trd": NaN, "batb": [[0, 1.04, 164], [1, 1.02, 1067.15], [2, 1.01, 3966.35]], "batl": NaN}, {"timestamp": 1631530734132, "ltp": 1.01, "tv": 3141.91, "trd": NaN, "batb": [[1, 1.01, 3938.65], [2, 1.01, 0]], "batl": [[0, 1.07, 214.81], [1, 1.13, 14.82], [2, 1.15, 14.82]]}, {"timestamp": 1631530735333, "ltp": 1.01, "tv": 3141.91, "trd": NaN, "batb": [[0, 1.01, 3938.65], [1, 1.01, 0]], "batl": NaN}, {"timestamp": 1631530758142, "ltp": 1.01, "tv": 3141.91, "trd": NaN, "batb": [[0, 1.05, 185.45], [1, 1.03, 54.31], [2, 1.01, 27.69]], "batl": [[0, 1.07, 914.1], [1, 1.11, 50.39], [2, 1.13, 39.58]]}, {"timestamp": 1631530758863, "ltp": 1.01, "tv": 3141.91, "trd": NaN, "batb": [[1, 1.04, 764.51], [2, 1.03, 54.31]], "batl": NaN}, {"timestamp": 1631530766143, "ltp": 1.01, "tv": 3141.91, "trd": NaN, "batb": [[0, 1.06, 142], [1, 1.05, 185.45], [2, 1.04, 764.51]], "batl": NaN}, {"timestamp": 1631530773153, "ltp": 1.01, "tv": 3141.91, "trd": NaN, "batb": [[1, 1.02, 1021.61], [2, 1.01, 4130.67]], "batl": [[0, 1.07, 214.81], [1, 1.13, 14.82], [2, 1.15, 14.82]]}, {"timestamp": 1631530774182, "ltp": 1.01, "tv": 3141.91, "trd": NaN, "batb": [[0, 1.02, 1021.61], [1, 1.01, 4130.67], [2, 1.01, 0]], "batl": NaN}, {"timestamp": 1631530785506, "ltp": 1.01, "tv": 3141.91, "trd": NaN, "batb": NaN, "batl": [[0, 1.03, 2.17], [1, 1.07, 214.81], [2, 1.13, 14.82]]}, {"timestamp": 1631530790296, "ltp": 1.01, "tv": 3141.91, "trd": NaN, "batb": NaN, "batl": [[0, 1.07, 214.81], [1, 1.13, 14.82], [2, 1.15, 14.82]]}, {"timestamp": 1631530792214, "ltp": 1.01, "tv": 3141.91, "trd": NaN, "batb": [[0, 1.02, 1076.45], [1, 1.01, 27.69]], "batl": [[0, 1.05, 229.5], [1, 1.06, 606.01], [2, 1.07, 214.81]]}, {"timestamp": 1631530793100, "ltp": 1.01, "tv": 3141.91, "trd": NaN, "batb": NaN, "batl": [[0, 1.05, 77.12]]}, {"timestamp": 1631530795484, "ltp": 1.01, "tv": 3141.91, "trd": NaN, "batb": [[1, 1.01, 3966.35]], "batl": NaN}, {"timestamp": 1631530798710, "ltp": 1.01, "tv": 3141.91, "trd": NaN, "batb": [[0, 1.04, 124], [1, 1.02, 1076.45], [2, 1.01, 3966.35]], "batl": NaN}, {"timestamp": 1631530803221, "ltp": 1.01, "tv": 3141.91, "trd": NaN, "batb": NaN, "batl": [[0, 1.07, 214.81], [1, 1.1, 50.85], [2, 1.12, 24.98]]}, {"timestamp": 1631530804118, "ltp": 1.01, "tv": 3140.59, "trd": [[1.01, 183.29], [1.02, 2.89], [1.04, 29.99], [1.05, 8.52], [1.06, 10.88], [1.15, 4.66], [1.16, 73.82], [1.17, 8.74], [1.18, 6.34], [1.19, 2.17], [1.2, 27.94], [1.21, 281.45], [1.22, 174.15], [1.23, 232.45], [1.24, 84.66], [1.25, 237.03], [1.26, 193.23], [1.27, 539.98], [1.28, 37.62], [1.29, 45.84], [1.3, 28.21], [1.31, 6.74], [1.32, 13.25], [1.33, 13.57], [1.34, 4.36], [1.35, 341.41], [1.37, 4.34], [1.4, 5.1], [1.45, 4.34], [1.5, 4.34], [1.65, 4.34], [2.1, 8.8]], "batb": [[0, 1.01, 3930.94], [1, 1.02, 0], [2, 1.01, 0]], "batl": [[0, 1.07, 214.39], [1, 1.13, 14.81], [2, 1.15, 14.81]]}, {"timestamp": 1631530815641, "ltp": 1.01, "tv": 3140.59, "trd": NaN, "batb": [[0, 1.06, 2.17], [1, 1.01, 3930.94]], "batl": NaN}, {"timestamp": 1631530829635, "ltp": 1.01, "tv": 3140.59, "trd": NaN, "batb": NaN, "batl": [[1, 1.11, 11.85], [2, 1.13, 14.81]]}, {"timestamp": 1631530834256, "ltp": 1.01, "tv": 3140.59, "trd": NaN, "batb": NaN, "batl": [[1, 1.09, 11.85], [2, 1.11, 11.85]]}, {"timestamp": 1631530839346, "ltp": 1.01, "tv": 3140.59, "trd": NaN, "batb": NaN, "batl": [[0, 1.03, 67.63], [1, 1.04, 303], [2, 1.07, 266.55]]}, {"timestamp": 1631530856281, "ltp": 1.01, "tv": 3140.59, "trd": NaN, "batb": NaN, "batl": [[2, 1.07, 214.39]]}, {"timestamp": 1631530857780, "ltp": 1.01, "tv": 3140.59, "trd": NaN, "batb": NaN, "batl": [[0, 1.07, 214.39], [1, 1.09, 11.85], [2, 1.11, 11.85]]}, {"timestamp": 1631530858674, "ltp": 1.01, "tv": 3140.59, "trd": NaN, "batb": NaN, "batl": [[0, 1.02, 48.54], [1, 1.07, 214.39], [2, 1.09, 11.85]]}, {"timestamp": 1631530872716, "ltp": 1.01, "tv": 3140.59, "trd": NaN, "batb": NaN, "batl": [[0, 1.07, 214.39], [1, 1.09, 11.85], [2, 1.11, 11.85]]}, {"timestamp": 1631530874279, "ltp": 1.01, "tv": 3140.59, "trd": NaN, "batb": [[0, 1.02, 1109.85], [1, 1.01, 27.63]], "batl": [[0, 1.05, 42.99], [1, 1.06, 606.01], [2, 1.07, 214.39]]}, {"timestamp": 1631530875313, "ltp": 1.01, "tv": 3140.59, "trd": NaN, "batb": [[1, 1.01, 3958.57]], "batl": NaN}, {"timestamp": 1631530881705, "ltp": 1.01, "tv": 3140.59, "trd": NaN, "batb": [[0, 1.04, 320], [1, 1.02, 1109.85], [2, 1.01, 3958.57]], "batl": NaN}, {"timestamp": 1631530890809, "ltp": 1.01, "tv": 3140.59, "trd": NaN, "batb": [[1, 1.02, 1055.13], [2, 1.01, 3930.94]], "batl": NaN}, {"timestamp": 1631530896212, "ltp": 1.01, "tv": 3140.59, "trd": NaN, "batb": [[1, 1.01, 3930.94], [2, 1.01, 0]], "batl": [[0, 1.07, 214.39], [1, 1.11, 11.85], [2, 1.13, 14.81]]}, {"timestamp": 1631530896416, "ltp": 1.01, "tv": 3140.59, "trd": NaN, "batb": [[0, 1.01, 3930.94], [1, 1.01, 0]], "batl": NaN}, {"timestamp": 1631530905053, "ltp": 1.01, "tv": 3140.59, "trd": NaN, "batb": [[0, 1.02, 405.73]], "batl": NaN}, {"timestamp": 1631530906259, "ltp": 1.01, "tv": 3140.59, "trd": NaN, "batb": NaN, "batl": [[0, 1.03, 76.19], [1, 1.04, 303], [2, 1.07, 266.55]]}, {"timestamp": 1631530906842, "ltp": 1.02, "tv": 3144.93, "trd": [[1.02, 7.23]], "batb": [[0, 1.02, 403.56]], "batl": NaN}, {"timestamp": 1631530908755, "ltp": 1.02, "tv": 3242.01, "trd": [[1.02, 104.31]], "batb": [[0, 1.02, 355.02]], "batl": NaN}, {"timestamp": 1631530910359, "ltp": 1.02, "tv": 3242.01, "trd": NaN, "batb": NaN, "batl": [[2, 1.05, 1236.34]]}, {"timestamp": 1631530910568, "ltp": 1.02, "tv": 3242.01, "trd": NaN, "batb": NaN, "batl": [[2, 1.07, 266.55]]}, {"timestamp": 1631530915169, "ltp": 1.02, "tv": 3242.01, "trd": NaN, "batb": NaN, "batl": [[0, 1.07, 214.39], [1, 1.11, 11.85], [2, 1.13, 14.81]]}, {"timestamp": 1631530935261, "ltp": 1.02, "tv": 3242.01, "trd": NaN, "batb": NaN, "batl": [[0, 1.05, 46.86], [1, 1.06, 606.01], [2, 1.07, 214.39]]}, {"timestamp": 1631530936288, "ltp": 1.02, "tv": 3242.01, "trd": NaN, "batb": [[0, 1.02, 1090.27], [1, 1.01, 27.63]], "batl": NaN}, {"timestamp": 1631530937068, "ltp": 1.02, "tv": 3242.01, "trd": NaN, "batb": [[1, 1.01, 3958.57]], "batl": NaN}, {"timestamp": 1631530940289, "ltp": 1.02, "tv": 3242.01, "trd": NaN, "batb": NaN, "batl": [[1, 1.06, 1439.61]]}, {"timestamp": 1631530940495, "ltp": 1.02, "tv": 3242.01, "trd": NaN, "batb": NaN, "batl": [[1, 1.06, 606.01]]}, {"timestamp": 1631530952216, "ltp": 1.02, "tv": 3242.01, "trd": NaN, "batb": NaN, "batl": [[0, 1.07, 214.39], [1, 1.1, 50.74], [2, 1.12, 24.92]]}, {"timestamp": 1631530952490, "ltp": 1.02, "tv": 3242.01, "trd": NaN, "batb": [[0, 1.01, 3930.94], [1, 1.01, 0]], "batl": [[1, 1.13, 14.81], [2, 1.15, 14.81]]}, {"timestamp": 1631530955311, "ltp": 1.02, "tv": 3242.01, "trd": NaN, "batb": [[0, 1.04, 312], [1, 1.01, 3930.94]], "batl": NaN}, {"timestamp": 1631530955516, "ltp": 1.02, "tv": 3242.01, "trd": NaN, "batb": [[0, 1.01, 3930.94], [1, 1.01, 0]], "batl": NaN}, {"timestamp": 1631530960417, "ltp": 1.02, "tv": 3242.01, "trd": NaN, "batb": NaN, "batl": [[1, 1.11, 11.85], [2, 1.13, 14.81]]}, {"timestamp": 1631530964038, "ltp": 1.02, "tv": 3242.01, "trd": NaN, "batb": NaN, "batl": [[0, 1.02, 2.17], [1, 1.07, 214.39], [2, 1.11, 11.85]]}, {"timestamp": 1631530969314, "ltp": 1.02, "tv": 3242.01, "trd": NaN, "batb": NaN, "batl": [[0, 1.07, 214.39], [1, 1.11, 11.85], [2, 1.13, 14.81]]}, {"timestamp": 1631530979231, "ltp": 1.02, "tv": 3242.01, "trd": NaN, "batb": NaN, "batl": [[0, 1.03, 123.36], [1, 1.04, 303], [2, 1.07, 266.55]]}, {"timestamp": 1631530980266, "ltp": 1.03, "tv": 3246.35, "trd": [[1.03, 4.34]], "batb": NaN, "batl": [[0, 1.03, 121.19]]}, {"timestamp": 1631530981636, "ltp": 1.02, "tv": 3294.88, "trd": [[1.02, 152.84]], "batb": NaN, "batl": NaN}, {"timestamp": 1631530996379, "ltp": 1.02, "tv": 3294.88, "trd": NaN, "batb": NaN, "batl": [[2, 1.07, 214.39]]}, {"timestamp": 1631531004260, "ltp": 1.02, "tv": 3294.88, "trd": NaN, "batb": NaN, "batl": [[0, 1.03, 36.67], [1, 1.07, 214.39], [2, 1.09, 11.85]]}, {"timestamp": 1631531004880, "ltp": 1.02, "tv": 3294.88, "trd": NaN, "batb": NaN, "batl": [[2, 1.11, 11.85]]}, {"timestamp": 1631531007074, "ltp": 1.02, "tv": 3294.88, "trd": NaN, "batb": NaN, "batl": [[0, 1.02, 4.26], [1, 1.03, 36.67], [2, 1.07, 214.39]]}, {"timestamp": 1631531018196, "ltp": 1.03, "tv": 3335.81, "trd": [[1.02, 157.1], [1.03, 41.01]], "batb": [[0, 1.02, 1123.15], [1, 1.01, 27.63]], "batl": [[0, 1.05, 267.14], [1, 1.07, 214.39], [2, 1.09, 51.21]]}, {"timestamp": 1631531026224, "ltp": 1.03, "tv": 3335.81, "trd": NaN, "batb": [[0, 1.04, 305], [1, 1.02, 1123.15], [2, 1.01, 27.63]], "batl": NaN}, {"timestamp": 1631531031278, "ltp": 1.03, "tv": 3335.81, "trd": NaN, "batb": [[1, 1.02, 0], [2, 1.01, 0]], "batl": [[0, 1.07, 214.39], [1, 1.11, 11.85], [2, 1.13, 14.81]]}, {"timestamp": 1631531044732, "ltp": 1.03, "tv": 3335.81, "trd": NaN, "batb": [[0, 1.06, 2.17]], "batl": NaN}, {"timestamp": 1631531048221, "ltp": 1.03, "tv": 3335.81, "trd": NaN, "batb": NaN, "batl": [[1, 1.13, 14.81], [2, 1.15, 14.81]]}, {"timestamp": 1631531051134, "ltp": 1.03, "tv": 3335.81, "trd": NaN, "batb": NaN, "batl": [[0, 1.06, 21.29], [1, 1.07, 214.39], [2, 1.13, 14.81]]}, {"timestamp": 1631531052336, "ltp": 1.03, "tv": 3335.81, "trd": NaN, "batb": NaN, "batl": [[0, 1.07, 214.39], [1, 1.13, 14.81], [2, 1.15, 14.81]]}, {"timestamp": 1631531053014, "ltp": 1.06, "tv": 3384.43, "trd": [[1.06, 59.5]], "batb": [[0, 1.04, 605.22], [1, 1.03, 54.19], [2, 1.01, 27.63]], "batl": [[0, 1.07, 909.95], [1, 1.11, 50.28], [2, 1.13, 39.51]]}, {"timestamp": 1631531053842, "ltp": 1.06, "tv": 3384.43, "trd": NaN, "batb": [[1, 1.03, 858.36], [2, 1.02, 1076.8]], "batl": NaN}, {"timestamp": 1631531056034, "ltp": 1.06, "tv": 3384.43, "trd": NaN, "batb": [[1, 1.03, 900.95]], "batl": NaN}, {"timestamp": 1631531057236, "ltp": 1.06, "tv": 3384.43, "trd": NaN, "batb": [[0, 1.06, 158], [1, 1.04, 605.22], [2, 1.03, 900.95]], "batl": NaN}, {"timestamp": 1631531061359, "ltp": 1.06, "tv": 3384.43, "trd": NaN, "batb": [[1, 1.05, 405.73], [2, 1.04, 605.22]], "batl": [[1, 1.08, 21.29], [2, 1.09, 63.88]]}, {"timestamp": 1631531065961, "ltp": 1.06, "tv": 3384.43, "trd": NaN, "batb": [[1, 1.05, 474.43]], "batl": [[0, 1.07, 1008.1]]}, {"timestamp": 1631531067222, "ltp": 1.06, "tv": 3564.75, "trd": [[1.06, 239.82]], "batb": [[0, 1.06, 67.84]], "batl": NaN}, {"timestamp": 1631531070262, "ltp": 1.06, "tv": 3564.75, "trd": NaN, "batb": [[0, 1.05, 405.73], [1, 1.03, 42.59], [2, 1.02, 1076.8]], "batl": [[0, 1.07, 214.39]]}, {"timestamp": 1631531072658, "ltp": 1.06, "tv": 3564.75, "trd": NaN, "batb": [[0, 1.03, 42.59], [1, 1.02, 1076.8], [2, 1.01, 4122.58]], "batl": NaN}, {"timestamp": 1631531075068, "ltp": 1.06, "tv": 3564.75, "trd": NaN, "batb": [[0, 1.03, 448.32]], "batl": NaN}, {"timestamp": 1631531090776, "ltp": 1.06, "tv": 3564.75, "trd": NaN, "batb": NaN, "batl": [[1, 1.09, 63.88], [2, 1.13, 14.81]]}, {"timestamp": 1631531095285, "ltp": 1.06, "tv": 3564.75, "trd": NaN, "batb": [[2, 1.01, 0]], "batl": NaN}, {"timestamp": 1631531096258, "ltp": 1.06, "tv": 3564.75, "trd": NaN, "batb": [[1, 1.02, 1131.52], [2, 1.01, 27.63]], "batl": [[0, 1.05, 68.03], [1, 1.07, 909.95], [2, 1.09, 115.09]]}, {"timestamp": 1631531098066, "ltp": 1.06, "tv": 3564.75, "trd": NaN, "batb": NaN, "batl": [[1, 1.06, 42.59], [2, 1.07, 909.95]]}, {"timestamp": 1631531099100, "ltp": 1.06, "tv": 3564.75, "trd": NaN, "batb": NaN, "batl": [[1, 1.06, 127.77]]}, {"timestamp": 1631531104207, "ltp": 1.06, "tv": 3564.75, "trd": NaN, "batb": [[0, 1.04, 148], [1, 1.03, 448.32], [2, 1.02, 1131.52]], "batl": NaN}, {"timestamp": 1631531113286, "ltp": 1.06, "tv": 3564.75, "trd": NaN, "batb": [[2, 1.02, 1076.8]], "batl": NaN}, {"timestamp": 1631531122106, "ltp": 1.06, "tv": 3564.75, "trd": NaN, "batb": NaN, "batl": [[0, 1.06, 127.77], [1, 1.07, 214.39], [2, 1.09, 63.88]]}, {"timestamp": 1631531123202, "ltp": 1.06, "tv": 3564.75, "trd": NaN, "batb": [[0, 1.03, 448.32], [1, 1.03, 0], [2, 1.02, 0]], "batl": NaN}, {"timestamp": 1631531132055, "ltp": 1.06, "tv": 3564.75, "trd": NaN, "batb": [[0, 1.03, 42.59]], "batl": NaN}, {"timestamp": 1631531135112, "ltp": 1.06, "tv": 3564.75, "trd": NaN, "batb": [[1, 1.02, 405.73]], "batl": NaN}, {"timestamp": 1631531149762, "ltp": 1.06, "tv": 3564.75, "trd": NaN, "batb": NaN, "batl": [[0, 1.07, 214.39], [1, 1.09, 63.88], [2, 1.13, 14.81]]}, {"timestamp": 1631531151340, "ltp": 1.06, "tv": 3564.75, "trd": NaN, "batb": [[0, 1.04, 573.66], [1, 1.03, 920.36], [2, 1.02, 1509.73]], "batl": [[0, 1.07, 319.03], [2, 1.11, 50.28]]}, {"timestamp": 1631531156667, "ltp": 1.06, "tv": 3564.75, "trd": NaN, "batb": [[0, 1.05, 62], [1, 1.04, 573.66], [2, 1.03, 920.36]], "batl": NaN}, {"timestamp": 1631531158693, "ltp": 1.07, "tv": 4242.24, "trd": [[1.07, 687.93]], "batb": NaN, "batl": [[0, 1.09, 63.88], [1, 1.11, 50.28], [2, 1.13, 39.51]]}, {"timestamp": 1631531159893, "ltp": 1.07, "tv": 4242.24, "trd": NaN, "batb": [[0, 1.05, 467.73]], "batl": NaN}, {"timestamp": 1631531167718, "ltp": 1.07, "tv": 4242.24, "trd": NaN, "batb": [[2, 1.03, 866.17]], "batl": [[1, 1.13, 14.81], [2, 1.15, 14.81]]}, {"timestamp": 1631531171905, "ltp": 1.07, "tv": 4242.24, "trd": NaN, "batb": NaN, "batl": [[0, 1.08, 36.72], [1, 1.09, 63.88], [2, 1.13, 14.81]]}, {"timestamp": 1631531178276, "ltp": 1.07, "tv": 4242.24, "trd": NaN, "batb": [[0, 1.05, 405.73], [1, 1.03, 42.59], [2, 1.02, 1509.73]], "batl": [[0, 1.09, 63.88], [1, 1.13, 14.81], [2, 1.15, 14.81]]}, {"timestamp": 1631531190249, "ltp": 1.07, "tv": 4242.24, "trd": NaN, "batb": NaN, "batl": [[0, 1.13, 14.81], [1, 1.15, 14.81], [2, 1.17, 29.62]]}, {"timestamp": 1631531192034, "ltp": 1.07, "tv": 4242.24, "trd": NaN, "batb": [[0, 1.06, 290.18], [1, 1.05, 405.73], [2, 1.04, 53.67]], "batl": [[0, 1.08, 224.76], [1, 1.12, 49.84], [2, 1.13, 14.81]]}, {"timestamp": 1631531192805, "ltp": 1.07, "tv": 4242.24, "trd": NaN, "batb": [[2, 1.04, 742.44]], "batl": NaN}, {"timestamp": 1631531195044, "ltp": 1.07, "tv": 4242.24, "trd": NaN, "batb": [[0, 1.07, 405.73], [1, 1.06, 290.18], [2, 1.05, 405.73]], "batl": NaN}, {"timestamp": 1631531197851, "ltp": 1.07, "tv": 4242.24, "trd": NaN, "batb": [[0, 1.07, 522.73]], "batl": NaN}, {"timestamp": 1631531200031, "ltp": 1.08, "tv": 4795.68, "trd": [[1.08, 557.44]], "batb": NaN, "batl": [[0, 1.12, 49.84], [1, 1.13, 14.81], [2, 1.14, 24.48]]}, {"timestamp": 1631531213140, "ltp": 1.08, "tv": 4795.68, "trd": NaN, "batb": NaN, "batl": [[0, 1.08, 16.35], [1, 1.12, 49.84], [2, 1.13, 14.81]]}, {"timestamp": 1631531219931, "ltp": 1.08, "tv": 4797.66, "trd": [[1.08, 559.42]], "batb": NaN, "batl": [[0, 1.08, 15.36]]}, {"timestamp": 1631531221350, "ltp": 1.08, "tv": 4916.38, "trd": [[1.08, 678.14]], "batb": NaN, "batl": [[0, 1.12, 49.84], [1, 1.13, 14.81], [2, 1.14, 24.48]]}, {"timestamp": 1631531236180, "ltp": 1.08, "tv": 4916.38, "trd": NaN, "batb": NaN, "batl": [[0, 1.09, 82.94], [1, 1.12, 49.84], [2, 1.13, 14.81]]}, {"timestamp": 1631531279032, "ltp": 1.08, "tv": 4916.38, "trd": NaN, "batb": NaN, "batl": [[1, 1.13, 14.81], [2, 1.15, 14.81]]}, {"timestamp": 1631531304275, "ltp": 1.08, "tv": 4916.38, "trd": NaN, "batb": [[0, 1.07, 405.73], [1, 1.05, 405.73], [2, 1.02, 1391.32]], "batl": [[0, 1.13, 14.81], [1, 1.15, 14.81], [2, 1.17, 29.62]]}, {"timestamp": 1631531315310, "ltp": 1.08, "tv": 4916.38, "trd": NaN, "batb": [[0, 1.1, 36.36], [1, 1.07, 457.89], [2, 1.05, 432.31]], "batl": [[0, 1.16, 48.12], [1, 1.18, 23.65], [2, 1.23, 29.62]]}, {"timestamp": 1631531316299, "ltp": 1.08, "tv": 4916.38, "trd": NaN, "batb": [[1, 1.08, 419.32], [2, 1.07, 457.89]], "batl": NaN}, {"timestamp": 1631531319311, "ltp": 1.08, "tv": 4916.38, "trd": NaN, "batb": [[0, 1.11, 405.73], [1, 1.1, 36.36], [2, 1.08, 419.32]], "batl": NaN}, {"timestamp": 1631531320092, "ltp": 1.11, "tv": 5762.42, "trd": [[1.11, 846.04]], "batb": [[0, 1.1, 36.36], [1, 1.08, 419.32], [2, 1.07, 457.89]], "batl": NaN}, {"timestamp": 1631531322223, "ltp": 1.11, "tv": 5762.42, "trd": NaN, "batb": [[0, 1.08, 419.32], [1, 1.07, 405.73], [2, 1.05, 1007.89]], "batl": [[0, 1.23, 29.62], [1, 1.25, 14.81], [2, 1.3, 1241.76]]}, {"timestamp": 1631531322536, "ltp": 1.11, "tv": 5762.42, "trd": NaN, "batb": [[0, 1.07, 405.73], [1, 1.05, 1007.89], [2, 1.03, 1593.57]], "batl": NaN}, {"timestamp": 1631531325196, "ltp": 1.11, "tv": 5762.42, "trd": NaN, "batb": [[0, 1.07, 775.8]], "batl": [[0, 1.17, 138.5], [1, 1.18, 131.25], [2, 1.19, 131.5]]}, {"timestamp": 1631531325515, "ltp": 1.11, "tv": 5762.42, "trd": NaN, "batb": NaN, "batl": [[0, 1.19, 131.5], [1, 1.23, 29.62], [2, 1.25, 14.81]]}, {"timestamp": 1631531340026, "ltp": 1.11, "tv": 5762.42, "trd": NaN, "batb": [[2, 1.02, 405.73]], "batl": NaN}, {"timestamp": 1631531341845, "ltp": 1.11, "tv": 5762.42, "trd": NaN, "batb": [[0, 1.12, 49.84], [1, 1.1, 1107.06], [2, 1.07, 775.8]], "batl": [[0, 1.18, 38.26], [1, 1.19, 131.5], [2, 1.21, 46.13]]}, {"timestamp": 1631531342846, "ltp": 1.11, "tv": 5762.42, "trd": NaN, "batb": [[0, 1.14, 253.13], [1, 1.12, 49.84], [2, 1.1, 1454]], "batl": NaN}, {"timestamp": 1631531346246, "ltp": 1.11, "tv": 5762.42, "trd": NaN, "batb": [[1, 1.13, 405.73], [2, 1.12, 49.84]], "batl": NaN}, {"timestamp": 1631531346761, "ltp": 1.16, "tv": 5790.05, "trd": [[1.16, 101.45]], "batb": NaN, "batl": NaN}, {"timestamp": 1631531349052, "ltp": 1.16, "tv": 5790.05, "trd": NaN, "batb": [[2, 1.12, 246.63]], "batl": NaN}, {"timestamp": 1631531354349, "ltp": 1.16, "tv": 5790.05, "trd": NaN, "batb": [[0, 1.13, 405.73], [1, 1.12, 196.79], [2, 1.11, 228.59]], "batl": [[0, 1.27, 82.5], [1, 1.29, 81.5], [2, 1.3, 1241.76]]}, {"timestamp": 1631531354658, "ltp": 1.16, "tv": 5790.05, "trd": NaN, "batb": NaN, "batl": [[0, 1.3, 1241.76], [1, 1.31, 82.5], [2, 1.39, 17.78]]}, {"timestamp": 1631531357952, "ltp": 1.16, "tv": 5790.05, "trd": NaN, "batb": NaN, "batl": [[0, 1.27, 82.5], [1, 1.3, 1241.76], [2, 1.31, 82.5]]}, {"timestamp": 1631531358371, "ltp": 1.16, "tv": 5790.05, "trd": NaN, "batb": NaN, "batl": [[0, 1.3, 1241.76], [1, 1.31, 82.5], [2, 1.39, 17.78]]}, {"timestamp": 1631531361179, "ltp": 1.16, "tv": 5790.05, "trd": NaN, "batb": NaN, "batl": [[0, 1.29, 89.5], [1, 1.3, 1241.76], [2, 1.31, 82.5]]}, {"timestamp": 1631531361766, "ltp": 1.16, "tv": 5790.05, "trd": NaN, "batb": NaN, "batl": [[0, 1.3, 1241.76], [1, 1.31, 82.5], [2, 1.39, 17.78]]}, {"timestamp": 1631531364265, "ltp": 1.16, "tv": 5790.05, "trd": NaN, "batb": [[0, 1.16, 21.29], [1, 1.15, 405.73], [2, 1.12, 196.79]], "batl": NaN}, {"timestamp": 1631531365260, "ltp": 1.16, "tv": 5790.05, "trd": NaN, "batb": [[0, 1.16, 106.47]], "batl": NaN}, {"timestamp": 1631531369175, "ltp": 1.16, "tv": 5790.05, "trd": NaN, "batb": NaN, "batl": [[0, 1.28, 21.29], [1, 1.3, 1241.76], [2, 1.31, 82.5]]}, {"timestamp": 1631531370271, "ltp": 1.16, "tv": 5790.05, "trd": NaN, "batb": NaN, "batl": [[0, 1.28, 127.77]]}, {"timestamp": 1631531375263, "ltp": 1.16, "tv": 5790.05, "trd": NaN, "batb": NaN, "batl": [[0, 1.27, 87.5], [1, 1.28, 127.77], [2, 1.3, 1241.76]]}, {"timestamp": 1631531375573, "ltp": 1.16, "tv": 5790.05, "trd": NaN, "batb": NaN, "batl": [[0, 1.28, 127.77], [1, 1.3, 1241.76], [2, 1.31, 82.5]]}, {"timestamp": 1631531382182, "ltp": 1.16, "tv": 5790.05, "trd": NaN, "batb": NaN, "batl": [[0, 1.27, 106.5], [1, 1.28, 127.77], [2, 1.3, 1241.76]]}, {"timestamp": 1631531382390, "ltp": 1.16, "tv": 5790.05, "trd": NaN, "batb": NaN, "batl": [[0, 1.28, 127.77], [1, 1.3, 1241.76], [2, 1.31, 82.5]]}, {"timestamp": 1631531389305, "ltp": 1.16, "tv": 5790.05, "trd": NaN, "batb": [[0, 1.15, 405.73], [1, 1.12, 196.79], [2, 1.11, 228.59]], "batl": NaN}, {"timestamp": 1631531391185, "ltp": 1.16, "tv": 5790.05, "trd": NaN, "batb": [[0, 1.12, 19.18], [1, 1.1, 568.28], [2, 1.09, 51.21]], "batl": [[0, 1.13, 32.14], [1, 1.18, 47.3], [2, 1.2, 23.26]]}, {"timestamp": 1631531393103, "ltp": 1.16, "tv": 5790.05, "trd": NaN, "batb": NaN, "batl": [[2, 1.19, 63.88]]}, {"timestamp": 1631531393625, "ltp": 1.16, "tv": 5790.05, "trd": NaN, "batb": [[1, 1.11, 405.73], [2, 1.1, 568.28]], "batl": [[2, 1.19, 85.18]]}, {"timestamp": 1631531396121, "ltp": 1.12, "tv": 5828.41, "trd": [[1.12, 38.36]], "batb": [[0, 1.11, 405.73], [1, 1.1, 568.28], [2, 1.09, 51.21]], "batl": NaN}, {"timestamp": 1631531397991, "ltp": 1.12, "tv": 5828.41, "trd": NaN, "batb": [[2, 1.09, 323.82]], "batl": NaN}, {"timestamp": 1631531399133, "ltp": 1.12, "tv": 5828.41, "trd": NaN, "batb": [[0, 1.11, 554.73]], "batl": NaN}, {"timestamp": 1631531406232, "ltp": 1.12, "tv": 5828.41, "trd": NaN, "batb": [[0, 1.11, 405.73]], "batl": [[0, 1.18, 47.3], [1, 1.19, 85.18], [2, 1.2, 23.26]]}, {"timestamp": 1631531409042, "ltp": 1.12, "tv": 5828.41, "trd": NaN, "batb": NaN, "batl": [[0, 1.13, 51.18], [1, 1.18, 47.3], [2, 1.19, 85.18]]}, {"timestamp": 1631531411231, "ltp": 1.12, "tv": 5828.41, "trd": NaN, "batb": [[1, 1.09, 272.61], [2, 1.08, 324.81]], "batl": [[0, 1.19, 85.18], [1, 1.28, 127.77], [2, 1.29, 88.5]]}, {"timestamp": 1631531420649, "ltp": 1.12, "tv": 5828.41, "trd": NaN, "batb": [[1, 1.08, 324.81], [2, 1.07, 370.07]], "batl": NaN}, {"timestamp": 1631531422060, "ltp": 1.12, "tv": 5828.41, "trd": NaN, "batb": [[0, 1.08, 324.81], [1, 1.07, 370.07], [2, 1.06, 938.79]], "batl": NaN}, {"timestamp": 1631531423150, "ltp": 1.12, "tv": 5828.41, "trd": NaN, "batb": NaN, "batl": [[0, 1.09, 58.94], [1, 1.19, 85.18], [2, 1.28, 127.77]]}, {"timestamp": 1631531424343, "ltp": 1.12, "tv": 5828.41, "trd": NaN, "batb": NaN, "batl": [[1, 1.14, 48.96], [2, 1.16, 24.06]]}, {"timestamp": 1631531426346, "ltp": 1.12, "tv": 5828.41, "trd": NaN, "batb": [[0, 1.08, 730.54]], "batl": [[1, 1.14, 134.14]]}, {"timestamp": 1631531428268, "ltp": 1.12, "tv": 5828.41, "trd": NaN, "batb": [[0, 1.08, 847.54]], "batl": [[0, 1.09, 583.62]]}, {"timestamp": 1631531429159, "ltp": 1.12, "tv": 5828.41, "trd": NaN, "batb": NaN, "batl": [[0, 1.09, 58.94]]}, {"timestamp": 1631531437282, "ltp": 1.12, "tv": 5828.41, "trd": NaN, "batb": [[0, 1.08, 405.73], [1, 1.06, 533.21], [2, 1.05, 527.65]], "batl": [[0, 1.14, 134.14], [1, 1.16, 24.06], [2, 1.2, 122.03]]}, {"timestamp": 1631531438269, "ltp": 1.12, "tv": 5828.41, "trd": NaN, "batb": [[1, 1.05, 474.49], [2, 1.04, 539.12]], "batl": [[0, 1.14, 85.18], [1, 1.22, 112.75], [2, 1.23, 29.64]]}, {"timestamp": 1631531443297, "ltp": 1.12, "tv": 5828.41, "trd": NaN, "batb": [[0, 1.09, 106.47], [1, 1.08, 405.73], [2, 1.05, 474.49]], "batl": NaN}, {"timestamp": 1631531443559, "ltp": 1.12, "tv": 5828.41, "trd": NaN, "batb": [[0, 1.09, 127.77]], "batl": NaN}, {"timestamp": 1631531444699, "ltp": 1.12, "tv": 5828.41, "trd": NaN, "batb": [[1, 1.05, 474.49], [2, 1.04, 539.12]], "batl": NaN}, {"timestamp": 1631531446105, "ltp": 1.09, "tv": 5956.18, "trd": [[1.09, 343.35]], "batb": [[0, 1.05, 474.49], [1, 1.04, 942.25], [2, 1.03, 1673.86]], "batl": [[0, 1.06, 132.03], [1, 1.14, 85.18], [2, 1.22, 112.75]]}, {"timestamp": 1631531447261, "ltp": 1.09, "tv": 5956.18, "trd": NaN, "batb": NaN, "batl": [[1, 1.1, 50.74], [2, 1.12, 24.92]]}, {"timestamp": 1631531449274, "ltp": 1.06, "tv": 5977.66, "trd": [[1.06, 261.3]], "batb": [[0, 1.05, 880.22]], "batl": [[0, 1.06, 121.29]]}, {"timestamp": 1631531451671, "ltp": 1.06, "tv": 5977.66, "trd": NaN, "batb": NaN, "batl": [[1, 1.07, 130.15], [2, 1.1, 50.74]]}, {"timestamp": 1631531452593, "ltp": 1.06, "tv": 5977.66, "trd": NaN, "batb": NaN, "batl": [[2, 1.09, 307.5]]}, {"timestamp": 1631531455182, "ltp": 1.06, "tv": 5977.66, "trd": NaN, "batb": [[0, 1.05, 1053.22]], "batl": NaN}, {"timestamp": 1631531459776, "ltp": 1.06, "tv": 5977.66, "trd": NaN, "batb": [[0, 1.05, 880.22]], "batl": [[0, 1.07, 130.15], [1, 1.09, 307.5], [2, 1.1, 295.99]]}, {"timestamp": 1631531461122, "ltp": 1.06, "tv": 5977.66, "trd": NaN, "batb": [[0, 1.05, 405.73], [1, 1.03, 742.83], [2, 1.02, 1228.01]], "batl": [[2, 1.1, 245.25]]}, {"timestamp": 1631531464291, "ltp": 1.06, "tv": 5977.66, "trd": NaN, "batb": [[0, 1.06, 187.39], [1, 1.05, 405.73], [2, 1.03, 742.83]], "batl": NaN}, {"timestamp": 1631531464496, "ltp": 1.06, "tv": 5977.66, "trd": NaN, "batb": [[0, 1.06, 234.24]], "batl": NaN}, {"timestamp": 1631531468228, "ltp": 1.06, "tv": 5977.66, "trd": NaN, "batb": [[0, 1.06, 358.24]], "batl": NaN}, {"timestamp": 1631531470614, "ltp": 1.07, "tv": 6237.96, "trd": [[1.07, 948.24]], "batb": [[0, 1.07, 275.58], [1, 1.06, 234.24], [2, 1.05, 405.73]], "batl": [[0, 1.11, 205.5], [1, 1.17, 29.64], [2, 1.19, 14.83]]}, {"timestamp": 1631531472018, "ltp": 1.07, "tv": 6237.96, "trd": NaN, "batb": [[2, 1.03, 742.83]], "batl": NaN}, {"timestamp": 1631531472743, "ltp": 1.07, "tv": 6237.96, "trd": NaN, "batb": [[0, 1.06, 234.24], [1, 1.03, 742.83], [2, 1.02, 1228.01]], "batl": NaN}, {"timestamp": 1631531475238, "ltp": 1.07, "tv": 6237.96, "trd": NaN, "batb": NaN, "batl": [[0, 1.1, 46.85], [1, 1.11, 205.5], [2, 1.17, 29.64]]}, {"timestamp": 1631531475823, "ltp": 1.07, "tv": 6237.96, "trd": NaN, "batb": NaN, "batl": [[0, 1.1, 140.55]]}, {"timestamp": 1631531477214, "ltp": 1.07, "tv": 6237.96, "trd": NaN, "batb": NaN, "batl": [[0, 1.09, 278.5], [1, 1.1, 391.7]]}, {"timestamp": 1631531477836, "ltp": 1.07, "tv": 6237.96, "trd": NaN, "batb": [[0, 1.03, 742.83], [1, 1.02, 1228.01], [2, 1.01, 2265.59]], "batl": NaN}, {"timestamp": 1631531479934, "ltp": 1.07, "tv": 6237.96, "trd": NaN, "batb": NaN, "batl": [[0, 1.04, 83.22], [1, 1.07, 52.16], [2, 1.09, 304.1]]}, {"timestamp": 1631531481340, "ltp": 1.07, "tv": 6237.96, "trd": NaN, "batb": NaN, "batl": [[1, 1.05, 46.85], [2, 1.07, 52.16]]}, {"timestamp": 1631531482029, "ltp": 1.07, "tv": 6237.96, "trd": NaN, "batb": NaN, "batl": [[1, 1.05, 234.24]]}, {"timestamp": 1631531482962, "ltp": 1.07, "tv": 6237.96, "trd": NaN, "batb": [[0, 1.03, 1148.56]], "batl": NaN}, {"timestamp": 1631531486236, "ltp": 1.07, "tv": 6237.96, "trd": NaN, "batb": NaN, "batl": [[1, 1.05, 812.94], [2, 1.06, 390.75]]}, {"timestamp": 1631531487232, "ltp": 1.07, "tv": 6237.96, "trd": NaN, "batb": [[0, 1.03, 1242.25]], "batl": NaN}, {"timestamp": 1631531501046, "ltp": 1.03, "tv": 8381.36, "trd": [[1.03, 2184.41]], "batb": [[0, 1.03, 170.55]], "batl": NaN}, {"timestamp": 1631531505949, "ltp": 1.04, "tv": 8417.44, "trd": [[1.04, 66.07]], "batb": NaN, "batl": [[0, 1.04, 65.18]]}, {"timestamp": 1631531516190, "ltp": 1.04, "tv": 8417.44, "trd": NaN, "batb": NaN, "batl": [[0, 1.05, 812.94], [1, 1.06, 390.75], [2, 1.07, 351.66]]}, {"timestamp": 1631531516770, "ltp": 1.04, "tv": 8417.44, "trd": NaN, "batb": NaN, "batl": [[2, 1.07, 299.5]]}, {"timestamp": 1631531519053, "ltp": 1.04, "tv": 8417.44, "trd": NaN, "batb": NaN, "batl": [[0, 1.04, 74.2], [1, 1.05, 812.94], [2, 1.06, 390.75]]}, {"timestamp": 1631531522879, "ltp": 1.03, "tv": 8451.15, "trd": [[1.03, 2218.11]], "batb": [[0, 1.03, 153.7]], "batl": NaN}, {"timestamp": 1631531528880, "ltp": 1.04, "tv": 8451.49, "trd": [[1.04, 66.42]], "batb": NaN, "batl": [[0, 1.04, 74.03]]}, {"timestamp": 1631531531209, "ltp": 1.04, "tv": 8451.49, "trd": NaN, "batb": NaN, "batl": [[0, 1.05, 812.94], [1, 1.06, 390.75], [2, 1.07, 299.5]]}, {"timestamp": 1631531536008, "ltp": 1.04, "tv": 8451.49, "trd": NaN, "batb": [[0, 1.04, 90.16], [1, 1.03, 153.7], [2, 1.02, 1228.01]], "batl": NaN}, {"timestamp": 1631531540277, "ltp": 1.04, "tv": 8451.49, "trd": NaN, "batb": NaN, "batl": [[0, 1.05, 816.94]]}, {"timestamp": 1631531540385, "ltp": 1.04, "tv": 8451.49, "trd": NaN, "batb": NaN, "batl": [[0, 1.05, 812.94]]}, {"timestamp": 1631531542210, "ltp": 1.04, "tv": 8536.25, "trd": [[1.04, 151.18]], "batb": [[0, 1.03, 153.7], [1, 1.02, 1228.01], [2, 1.01, 2265.59]], "batl": [[0, 1.05, 859.79]]}, {"timestamp": 1631531542680, "ltp": 1.04, "tv": 8536.25, "trd": NaN, "batb": NaN, "batl": [[0, 1.04, 93.7], [1, 1.05, 859.79], [2, 1.06, 390.75]]}, {"timestamp": 1631531546484, "ltp": 1.04, "tv": 8536.25, "trd": NaN, "batb": NaN, "batl": [[0, 1.04, 93.74]]}, {"timestamp": 1631531550315, "ltp": 1.04, "tv": 8536.25, "trd": NaN, "batb": [[0, 1.03, 60.01]], "batl": [[1, 1.05, 281.09], [2, 1.13, 14.83]]}, {"timestamp": 1631531551987, "ltp": 1.03, "tv": 8656.27, "trd": [[1.03, 2338.13]], "batb": [[0, 1.02, 1682.07], [1, 1.01, 2265.59], [2, 1.01, 0]], "batl": [[0, 1.03, 542.36], [1, 1.04, 93.74], [2, 1.05, 281.09]]}, {"timestamp": 1631531554227, "ltp": 1.03, "tv": 8656.27, "trd": NaN, "batb": NaN, "batl": [[0, 1.03, 776.6], [1, 1.04, 93.7], [2, 1.06, 52.66]]}, {"timestamp": 1631531559294, "ltp": 1.03, "tv": 8656.27, "trd": NaN, "batb": NaN, "batl": [[1, 1.04, 747.83], [2, 1.05, 449.9]]}, {"timestamp": 1631531561894, "ltp": 1.03, "tv": 8656.27, "trd": NaN, "batb": NaN, "batl": [[0, 1.03, 683.74]]}, {"timestamp": 1631531564909, "ltp": 1.03, "tv": 8656.27, "trd": NaN, "batb": NaN, "batl": [[0, 1.03, 776.6]]}, {"timestamp": 1631531566318, "ltp": 1.02, "tv": 8656.35, "trd": [[1.02, 157.19]], "batb": [[0, 1.02, 1682.03]], "batl": NaN}, {"timestamp": 1631531569035, "ltp": 1.02, "tv": 8970.93, "trd": [[1.02, 471.77]], "batb": [[0, 1.02, 1524.74]], "batl": NaN}, {"timestamp": 1631531571954, "ltp": 1.02, "tv": 8970.93, "trd": NaN, "batb": NaN, "batl": [[0, 1.03, 234.24]]}, {"timestamp": 1631531577110, "ltp": 1.02, "tv": 8970.93, "trd": NaN, "batb": NaN, "batl": [[0, 1.02, 18.04], [1, 1.03, 234.24], [2, 1.04, 747.83]]}, {"timestamp": 1631531585146, "ltp": 1.02, "tv": 8970.93, "trd": NaN, "batb": NaN, "batl": [[2, 1.04, 654.13]]}, {"timestamp": 1631531588222, "ltp": 1.02, "tv": 8970.93, "trd": NaN, "batb": NaN, "batl": [[0, 1.02, 111.74]]}, {"timestamp": 1631531597166, "ltp": 1.02, "tv": 8970.93, "trd": NaN, "batb": NaN, "batl": [[0, 1.02, 4005.22], [1, 1.04, 654.13], [2, 1.09, 11.86]]}, {"timestamp": 1631531598055, "ltp": 1.02, "tv": 8970.93, "trd": NaN, "batb": NaN, "batl": [[0, 1.02, 910.47], [2, 1.05, 53.16]]}, {"timestamp": 1631531600090, "ltp": 1.01, "tv": 9205.17, "trd": [[1.01, 417.54]], "batb": NaN, "batl": NaN}, {"timestamp": 1631531604544, "ltp": 1.01, "tv": 9205.17, "trd": NaN, "batb": NaN, "batl": [[1, 1.03, 826.5], [2, 1.04, 654.13]]}, {"timestamp": 1631531608236, "ltp": 1.01, "tv": 9208.79, "trd": [[1.01, 421.15]], "batb": NaN, "batl": NaN}, {"timestamp": 1631531608858, "ltp": 1.01, "tv": 9208.79, "trd": NaN, "batb": [[0, 1.01, 405.73]], "batl": NaN}, {"timestamp": 1631531610149, "ltp": 1.01, "tv": 9225.82, "trd": [[1.01, 438.19]], "batb": [[0, 1.01, 397.21]], "batl": NaN}, {"timestamp": 1631531617270, "ltp": 1.01, "tv": 9225.82, "trd": NaN, "batb": NaN, "batl": [[0, 1.02, 111.74]]}, {"timestamp": 1631531618184, "ltp": 1.01, "tv": 9242.86, "trd": [[1.01, 455.23]], "batb": [[0, 1.01, 388.69]], "batl": NaN}, {"timestamp": 1631531631296, "ltp": 1.01, "tv": 9242.86, "trd": NaN, "batb": NaN, "batl": [[0, 1.02, 196.92]]}, {"timestamp": 1631531631496, "ltp": 1.01, "tv": 9242.86, "trd": NaN, "batb": NaN, "batl": [[0, 1.02, 282.09]]}, {"timestamp": 1631531632802, "ltp": 1.01, "tv": 9242.86, "trd": NaN, "batb": NaN, "batl": [[1, 1.03, 1219.91]]}, {"timestamp": 1631531637277, "ltp": 1.01, "tv": 9242.86, "trd": NaN, "batb": [[0, 1.01, 644.23]], "batl": NaN}, {"timestamp": 1631531644118, "ltp": 1.01, "tv": 9242.86, "trd": NaN, "batb": NaN, "batl": [[1, 1.04, 654.13], [2, 1.05, 480.5]]}, {"timestamp": 1631531650903, "ltp": 1.02, "tv": 9807.06, "trd": [[1.02, 1035.96]], "batb": NaN, "batl": [[0, 1.05, 480.5], [1, 1.06, 392.25], [2, 1.09, 11.86]]}, {"timestamp": 1631531653126, "ltp": 1.02, "tv": 9807.06, "trd": NaN, "batb": NaN, "batl": [[0, 1.02, 18.75], [1, 1.05, 480.5], [2, 1.06, 392.25]]}, {"timestamp": 1631531654213, "ltp": 1.02, "tv": 9807.06, "trd": NaN, "batb": NaN, "batl": [[0, 1.05, 480.5], [1, 1.06, 392.25], [2, 1.09, 11.86]]}, {"timestamp": 1631531656291, "ltp": 1.02, "tv": 9807.06, "trd": NaN, "batb": [[0, 1.01, 473.87]], "batl": NaN}, {"timestamp": 1631531656502, "ltp": 1.02, "tv": 9807.06, "trd": NaN, "batb": [[0, 1.01, 644.23]], "batl": NaN}, {"timestamp": 1631531661323, "ltp": 1.02, "tv": 9807.06, "trd": NaN, "batb": [[0, 1.01, 814.58]], "batl": NaN}, {"timestamp": 1631531661737, "ltp": 1.02, "tv": 9807.06, "trd": NaN, "batb": [[0, 1.01, 984.94]], "batl": NaN}, {"timestamp": 1631531663004, "ltp": 1.02, "tv": 9807.06, "trd": NaN, "batb": NaN, "batl": [[0, 1.03, 340.72], [1, 1.05, 480.5], [2, 1.06, 392.25]]}, {"timestamp": 1631531665037, "ltp": 1.02, "tv": 9807.06, "trd": NaN, "batb": [[0, 1.01, 899.76]], "batl": [[1, 1.04, 597.13], [2, 1.05, 480.5]]}, {"timestamp": 1631531666333, "ltp": 1.02, "tv": 9807.06, "trd": NaN, "batb": [[0, 1.01, 729.4]], "batl": NaN}, {"timestamp": 1631531671233, "ltp": 1.02, "tv": 9807.06, "trd": NaN, "batb": [[0, 1.03, 33.44], [1, 1.01, 729.4]], "batl": [[0, 1.04, 781.52], [1, 1.05, 480.5], [2, 1.06, 392.25]]}, {"timestamp": 1631531673312, "ltp": 1.02, "tv": 9807.06, "trd": NaN, "batb": [[1, 1.02, 255.54], [2, 1.01, 729.4]], "batl": NaN}, {"timestamp": 1631531675240, "ltp": 1.02, "tv": 9807.06, "trd": NaN, "batb": [[0, 1.02, 340.72], [1, 1.01, 729.4], [2, 1.01, 0]], "batl": [[0, 1.04, 597.13]]}, {"timestamp": 1631531676023, "ltp": 1.02, "tv": 9807.06, "trd": NaN, "batb": [[0, 1.02, 425.89]], "batl": [[0, 1.06, 392.25], [1, 1.11, 11.86], [2, 1.13, 14.83]]}, {"timestamp": 1631531680922, "ltp": 1.02, "tv": 9807.06, "trd": NaN, "batb": [[0, 1.04, 1.93], [1, 1.02, 425.89], [2, 1.01, 729.4]], "batl": NaN}, {"timestamp": 1631531682216, "ltp": 1.02, "tv": 9807.06, "trd": NaN, "batb": NaN, "batl": [[0, 1.05, 475.5], [1, 1.06, 392.25], [2, 1.07, 386.5]]}, {"timestamp": 1631531682424, "ltp": 1.02, "tv": 9807.06, "trd": NaN, "batb": NaN, "batl": [[0, 1.06, 392.25], [1, 1.11, 11.86], [2, 1.13, 14.83]]}, {"timestamp": 1631531684238, "ltp": 1.02, "tv": 9807.06, "trd": NaN, "batb": [[0, 1.02, 425.89], [1, 1.01, 729.4], [2, 1.01, 0]], "batl": NaN}, {"timestamp": 1631531687243, "ltp": 1.02, "tv": 9807.06, "trd": NaN, "batb": NaN, "batl": [[0, 1.04, 85.18], [1, 1.06, 392.25], [2, 1.09, 11.88]]}, {"timestamp": 1631531688334, "ltp": 1.02, "tv": 9807.06, "trd": NaN, "batb": NaN, "batl": [[0, 1.03, 136], [1, 1.04, 340.72], [2, 1.06, 392.25]]}, {"timestamp": 1631531689264, "ltp": 1.02, "tv": 9807.06, "trd": NaN, "batb": NaN, "batl": [[2, 1.05, 453.1]]}, {"timestamp": 1631531695962, "ltp": 1.02, "tv": 9807.06, "trd": NaN, "batb": NaN, "batl": [[1, 1.05, 453.1], [2, 1.06, 392.25]]}, {"timestamp": 1631531697158, "ltp": 1.03, "tv": 9943.06, "trd": [[1.03, 2474.13]], "batb": [[0, 1.03, 1.93], [1, 1.02, 425.89], [2, 1.01, 812.3]], "batl": [[0, 1.05, 623.9], [1, 1.06, 392.25], [2, 1.07, 385.5]]}, {"timestamp": 1631531699283, "ltp": 1.03, "tv": 9943.06, "trd": NaN, "batb": [[0, 1.03, 87.11]], "batl": NaN}, {"timestamp": 1631531700265, "ltp": 1.03, "tv": 9943.06, "trd": NaN, "batb": [[0, 1.03, 513.01]], "batl": NaN}, {"timestamp": 1631531702352, "ltp": 1.03, "tv": 9943.06, "trd": NaN, "batb": NaN, "batl": [[0, 1.04, 340.72], [1, 1.05, 623.9], [2, 1.06, 392.25]]}, {"timestamp": 1631531707258, "ltp": 1.04, "tv": 9979.22, "trd": [[1.04, 187.34]], "batb": NaN, "batl": [[0, 1.04, 304.56], [1, 1.05, 571.43]]}, {"timestamp": 1631531709185, "ltp": 1.04, "tv": 9979.22, "trd": NaN, "batb": [[2, 1.01, 729.4]], "batl": [[1, 1.11, 11.86], [2, 1.13, 14.83]]}, {"timestamp": 1631531717695, "ltp": 1.04, "tv": 9979.47, "trd": [[1.04, 187.59]], "batb": NaN, "batl": [[0, 1.04, 304.43]]}, {"timestamp": 1631531721278, "ltp": 1.04, "tv": 9979.47, "trd": NaN, "batb": NaN, "batl": [[1, 1.05, 1254], [2, 1.11, 11.86]]}, {"timestamp": 1631531721485, "ltp": 1.04, "tv": 9979.47, "trd": NaN, "batb": NaN, "batl": [[1, 1.11, 11.86], [2, 1.13, 14.83]]}, {"timestamp": 1631531722579, "ltp": 1.04, "tv": 9979.47, "trd": NaN, "batb": [[0, 1.03, 511.07]], "batl": NaN}, {"timestamp": 1631531723466, "ltp": 1.04, "tv": 9983.34, "trd": [[1.04, 191.46]], "batb": NaN, "batl": [[0, 1.04, 302.5]]}, {"timestamp": 1631531727108, "ltp": 1.04, "tv": 9983.34, "trd": NaN, "batb": NaN, "batl": [[0, 1.11, 11.86], [1, 1.13, 14.83], [2, 1.15, 14.83]]}, {"timestamp": 1631531728102, "ltp": 1.04, "tv": 9983.34, "trd": NaN, "batb": [[2, 1.01, 812.3]], "batl": [[0, 1.05, 192.1], [1, 1.09, 51.21], [2, 1.11, 37]]}, {"timestamp": 1631531728884, "ltp": 1.04, "tv": 9983.34, "trd": NaN, "batb": [[1, 1.02, 1525.12]], "batl": NaN}, {"timestamp": 1631531731182, "ltp": 1.04, "tv": 9983.34, "trd": NaN, "batb": [[0, 1.04, 425.89], [1, 1.03, 511.07], [2, 1.02, 1525.12]], "batl": NaN}, {"timestamp": 1631531731387, "ltp": 1.04, "tv": 9983.34, "trd": NaN, "batb": [[0, 1.04, 511.07]], "batl": NaN}, {"timestamp": 1631531733213, "ltp": 1.04, "tv": 9983.34, "trd": NaN, "batb": [[0, 1.04, 681.43]], "batl": NaN}, {"timestamp": 1631531737188, "ltp": 1.04, "tv": 9983.34, "trd": NaN, "batb": [[0, 1.04, 839.43]], "batl": NaN}, {"timestamp": 1631531745515, "ltp": 1.05, "tv": 9997.8, "trd": [[1.05, 22.98]], "batb": NaN, "batl": [[0, 1.05, 184.87]]}, {"timestamp": 1631531755721, "ltp": 1.05, "tv": 9997.8, "trd": NaN, "batb": NaN, "batl": [[0, 1.05, 118.33]]}, {"timestamp": 1631531758627, "ltp": 1.05, "tv": 9997.8, "trd": NaN, "batb": NaN, "batl": [[0, 1.05, 188.49]]}, {"timestamp": 1631531762427, "ltp": 1.04, "tv": 10014.84, "trd": [[1.04, 208.5]], "batb": [[0, 1.04, 830.91]], "batl": NaN}, {"timestamp": 1631531765809, "ltp": 1.04, "tv": 10014.84, "trd": NaN, "batb": [[1, 1.02, 1525.12], [2, 1.01, 812.3]], "batl": NaN}, {"timestamp": 1631531768240, "ltp": 1.04, "tv": 10058.76, "trd": [[1.04, 252.42]], "batb": [[0, 1.04, 808.95]], "batl": NaN}, {"timestamp": 1631531768705, "ltp": 1.04, "tv": 10622.93, "trd": [[1.04, 256.42], [1.05, 583.15]], "batb": [[0, 1.04, 806.95]], "batl": [[0, 1.09, 51.21], [1, 1.11, 37], [2, 1.13, 14.83]]}, {"timestamp": 1631531775155, "ltp": 1.04, "tv": 10622.93, "trd": NaN, "batb": NaN, "batl": [[0, 1.06, 340.72], [1, 1.09, 51.21], [2, 1.11, 37]]}, {"timestamp": 1631531778841, "ltp": 1.05, "tv": 10623.03, "trd": [[1.05, 583.24]], "batb": NaN, "batl": NaN}, {"timestamp": 1631531781847, "ltp": 1.05, "tv": 10623.03, "trd": NaN, "batb": NaN, "batl": [[0, 1.06, 447.7]]}, {"timestamp": 1631531783853, "ltp": 1.04, "tv": 10891.03, "trd": [[1.04, 524.42]], "batb": [[0, 1.04, 672.95]], "batl": NaN}, {"timestamp": 1631531800845, "ltp": 1.06, "tv": 11634.4, "trd": [[1.06, 1004.67]], "batb": NaN, "batl": [[0, 1.06, 76.01]]}, {"timestamp": 1631531808966, "ltp": 1.06, "tv": 11634.4, "trd": NaN, "batb": [[0, 1.04, 843.31]], "batl": NaN}, {"timestamp": 1631531811091, "ltp": 1.06, "tv": 11634.4, "trd": NaN, "batb": NaN, "batl": [[0, 1.09, 51.21], [1, 1.11, 37], [2, 1.13, 14.83]]}, {"timestamp": 1631531814259, "ltp": 1.06, "tv": 11634.4, "trd": NaN, "batb": [[0, 1.05, 340.72], [1, 1.04, 843.31], [2, 1.02, 425.89]], "batl": [[0, 1.11, 11.86], [1, 1.13, 14.83], [2, 1.15, 14.83]]}, {"timestamp": 1631531814467, "ltp": 1.06, "tv": 11634.4, "trd": NaN, "batb": [[0, 1.05, 425.89], [1, 1.04, 685.31]], "batl": NaN}, {"timestamp": 1631531816082, "ltp": 1.06, "tv": 11634.4, "trd": NaN, "batb": [[0, 1.05, 511.07]], "batl": NaN}, {"timestamp": 1631531816900, "ltp": 1.06, "tv": 11634.4, "trd": NaN, "batb": NaN, "batl": [[1, 1.13, 203.33]]}, {"timestamp": 1631531818089, "ltp": 1.06, "tv": 11634.4, "trd": NaN, "batb": [[0, 1.06, 9.02], [1, 1.05, 511.07], [2, 1.04, 685.31]], "batl": [[0, 1.13, 203.33], [1, 1.15, 14.83], [2, 1.17, 29.64]]}, {"timestamp": 1631531821512, "ltp": 1.06, "tv": 11634.4, "trd": NaN, "batb": [[2, 1.02, 425.89]], "batl": NaN}, {"timestamp": 1631531823311, "ltp": 1.06, "tv": 11708.9, "trd": [[1.06, 1079.17]], "batb": [[0, 1.06, 56.95]], "batl": NaN}, {"timestamp": 1631531825287, "ltp": 1.06, "tv": 11708.9, "trd": NaN, "batb": [[0, 1.06, 312.49]], "batl": NaN}, {"timestamp": 1631531826279, "ltp": 1.06, "tv": 11708.9, "trd": NaN, "batb": [[0, 1.06, 653.2]], "batl": NaN}, {"timestamp": 1631531827000, "ltp": 1.06, "tv": 11708.9, "trd": NaN, "batb": NaN, "batl": [[0, 1.11, 236.5], [1, 1.13, 203.33], [2, 1.15, 14.83]]}, {"timestamp": 1631531827982, "ltp": 1.06, "tv": 11709.08, "trd": [[1.06, 1079.35]], "batb": [[0, 1.06, 653.11], [1, 1.02, 425.89], [2, 1.01, 340.72]], "batl": [[0, 1.13, 203.33], [1, 1.15, 14.83], [2, 1.17, 29.64]]}, {"timestamp": 1631531834104, "ltp": 1.06, "tv": 11709.08, "trd": NaN, "batb": NaN, "batl": [[0, 1.11, 231.5], [1, 1.13, 203.33], [2, 1.15, 14.83]]}, {"timestamp": 1631531834413, "ltp": 1.06, "tv": 11709.08, "trd": NaN, "batb": NaN, "batl": [[0, 1.13, 203.33], [1, 1.15, 14.83], [2, 1.17, 29.64]]}, {"timestamp": 1631531836807, "ltp": 1.06, "tv": 11709.08, "trd": NaN, "batb": [[1, 1.05, 53.16], [2, 1.03, 27.09]], "batl": [[0, 1.11, 61.18], [1, 1.13, 237.89], [2, 1.15, 24.27]]}, {"timestamp": 1631531838105, "ltp": 1.06, "tv": 11709.08, "trd": NaN, "batb": [[0, 1.06, 528.53], [2, 1.03, 951.93]], "batl": NaN}, {"timestamp": 1631531841312, "ltp": 1.06, "tv": 11709.08, "trd": NaN, "batb": [[0, 1.08, 659.51], [1, 1.06, 528.53], [2, 1.05, 53.16]], "batl": NaN}, {"timestamp": 1631531841729, "ltp": 1.09, "tv": 11754.33, "trd": [[1.09, 388.6]], "batb": NaN, "batl": NaN}, {"timestamp": 1631531844108, "ltp": 1.09, "tv": 11754.33, "trd": NaN, "batb": [[0, 1.09, 143], [1, 1.08, 659.51], [2, 1.06, 528.53]], "batl": NaN}, {"timestamp": 1631531844522, "ltp": 1.09, "tv": 11754.35, "trd": [[1.09, 388.62]], "batb": [[0, 1.09, 142.99]], "batl": NaN}, {"timestamp": 1631531848302, "ltp": 1.09, "tv": 11754.35, "trd": NaN, "batb": [[0, 1.08, 659.51], [1, 1.03, 913.88], [2, 1.02, 2214.22]], "batl": [[0, 1.19, 14.83], [1, 1.21, 14.83], [2, 1.23, 237.14]]}, {"timestamp": 1631531849137, "ltp": 1.09, "tv": 11754.35, "trd": NaN, "batb": NaN, "batl": [[0, 1.19, 15.6], [2, 1.23, 29.64]]}, {"timestamp": 1631531851333, "ltp": 1.09, "tv": 11754.35, "trd": NaN, "batb": NaN, "batl": [[1, 1.21, 211.33]]}, {"timestamp": 1631531851644, "ltp": 1.09, "tv": 11754.35, "trd": NaN, "batb": NaN, "batl": [[1, 1.21, 14.83], [2, 1.23, 227.14]]}, {"timestamp": 1631531854134, "ltp": 1.09, "tv": 11754.35, "trd": NaN, "batb": NaN, "batl": [[0, 1.19, 14.83]]}, {"timestamp": 1631531858229, "ltp": 1.09, "tv": 11754.35, "trd": NaN, "batb": NaN, "batl": [[1, 1.21, 231.33]]}, {"timestamp": 1631531858744, "ltp": 1.09, "tv": 11754.35, "trd": NaN, "batb": NaN, "batl": [[1, 1.21, 14.83], [2, 1.23, 29.64]]}, {"timestamp": 1631531860245, "ltp": 1.09, "tv": 11754.35, "trd": NaN, "batb": [[2, 1.02, 0]], "batl": NaN}, {"timestamp": 1631531861229, "ltp": 1.09, "tv": 11754.35, "trd": NaN, "batb": [[0, 1.1, 50.74], [1, 1.08, 2102.21], [2, 1.03, 913.88]], "batl": [[0, 1.17, 39.12], [1, 1.19, 46.91], [2, 1.21, 23.07]]}, {"timestamp": 1631531861915, "ltp": 1.09, "tv": 11754.35, "trd": NaN, "batb": [[0, 1.13, 267.61], [1, 1.1, 50.74], [2, 1.08, 2508.39]], "batl": NaN}, {"timestamp": 1631531863313, "ltp": 1.09, "tv": 11754.35, "trd": NaN, "batb": [[1, 1.12, 340.72], [2, 1.1, 50.74]], "batl": NaN}, {"timestamp": 1631531864240, "ltp": 1.09, "tv": 11754.35, "trd": NaN, "batb": [[1, 1.12, 766.61]], "batl": NaN}, {"timestamp": 1631531865234, "ltp": 1.09, "tv": 11754.35, "trd": NaN, "batb": [[1, 1.1, 50.74], [2, 1.08, 1848.89]], "batl": NaN}, {"timestamp": 1631531866323, "ltp": 1.15, "tv": 11816.35, "trd": [[1.15, 66.66]], "batb": [[0, 1.14, 624.8], [1, 1.13, 267.61], [2, 1.12, 85.18]], "batl": NaN}, {"timestamp": 1631531867257, "ltp": 1.15, "tv": 11816.35, "trd": NaN, "batb": [[0, 1.15, 99], [1, 1.14, 624.8], [2, 1.13, 267.61]], "batl": NaN}, {"timestamp": 1631531869638, "ltp": 1.17, "tv": 11836.37, "trd": [[1.17, 28.76]], "batb": NaN, "batl": [[0, 1.17, 19.1]]}, {"timestamp": 1631531872952, "ltp": 1.15, "tv": 11837.27, "trd": [[1.15, 67.56]], "batb": [[0, 1.15, 98.55]], "batl": NaN}, {"timestamp": 1631531874755, "ltp": 1.15, "tv": 11837.27, "trd": NaN, "batb": NaN, "batl": [[0, 1.16, 405.73], [1, 1.17, 19.1], [2, 1.19, 46.91]]}, {"timestamp": 1631531876049, "ltp": 1.15, "tv": 11837.27, "trd": NaN, "batb": NaN, "batl": [[1, 1.19, 46.91], [2, 1.21, 23.07]]}, {"timestamp": 1631531877240, "ltp": 1.16, "tv": 11866.2, "trd": [[1.16, 130.38]], "batb": [[2, 1.08, 406.19]], "batl": [[0, 1.16, 391.26], [1, 1.29, 238.5], [2, 1.31, 208.5]]}, {"timestamp": 1631531878328, "ltp": 1.16, "tv": 11866.2, "trd": NaN, "batb": [[0, 1.14, 624.8], [1, 1.08, 406.19], [2, 1.06, 968.8]], "batl": NaN}, {"timestamp": 1631531879356, "ltp": 1.16, "tv": 12206.92, "trd": [[1.16, 471.1]], "batb": NaN, "batl": [[0, 1.16, 220.9], [2, 1.3, 216.75]]}, {"timestamp": 1631531880242, "ltp": 1.16, "tv": 12648.72, "trd": [[1.16, 912.89]], "batb": [[0, 1.16, 34.64], [1, 1.14, 624.8], [2, 1.08, 406.19]], "batl": [[0, 1.29, 238.5], [1, 1.3, 216.75], [2, 1.31, 208.5]]}, {"timestamp": 1631531880963, "ltp": 1.16, "tv": 12648.72, "trd": NaN, "batb": [[0, 1.14, 624.8], [1, 1.08, 406.19], [2, 1.06, 968.8]], "batl": [[0, 1.32, 190.61], [1, 1.33, 206.5], [2, 1.34, 1125.11]]}, {"timestamp": 1631531882162, "ltp": 1.16, "tv": 12648.72, "trd": NaN, "batb": [[0, 1.08, 406.19], [1, 1.06, 968.8], [2, 1.06, 0]], "batl": NaN}, {"timestamp": 1631531883350, "ltp": 1.16, "tv": 12648.72, "trd": NaN, "batb": NaN, "batl": [[0, 1.32, 191.11]]}, {"timestamp": 1631531884235, "ltp": 1.15, "tv": 12649.67, "trd": [[1.15, 68.52]], "batb": NaN, "batl": [[0, 1.32, 190.61]]}, {"timestamp": 1631531885532, "ltp": 1.15, "tv": 12649.67, "trd": NaN, "batb": [[0, 1.14, 226.68], [1, 1.08, 406.19], [2, 1.06, 968.8]], "batl": NaN}, {"timestamp": 1631531889264, "ltp": 1.15, "tv": 12649.67, "trd": NaN, "batb": NaN, "batl": [[0, 1.29, 85.18], [1, 1.32, 190.61], [2, 1.33, 206.5]]}, {"timestamp": 1631531890247, "ltp": 1.15, "tv": 12649.67, "trd": NaN, "batb": NaN, "batl": [[0, 1.29, 511.07]]}, {"timestamp": 1631531890660, "ltp": 1.15, "tv": 12649.67, "trd": NaN, "batb": NaN, "batl": [[0, 1.29, 745.57]]}, {"timestamp": 1631531891952, "ltp": 1.15, "tv": 12649.67, "trd": NaN, "batb": [[0, 1.08, 406.19], [1, 1.06, 968.8], [2, 1.06, 0]], "batl": NaN}, {"timestamp": 1631531892780, "ltp": 1.15, "tv": 12649.67, "trd": NaN, "batb": [[1, 1.06, 0]], "batl": NaN}, {"timestamp": 1631531893972, "ltp": 1.15, "tv": 12649.67, "trd": NaN, "batb": [[1, 1.07, 52.16], [2, 1.05, 26.58]], "batl": [[0, 1.12, 612.46], [1, 1.15, 48.53], [2, 1.17, 23.85]]}, {"timestamp": 1631531898287, "ltp": 1.15, "tv": 12649.67, "trd": NaN, "batb": [[0, 1.1, 141], [1, 1.08, 406.19], [2, 1.07, 52.16]], "batl": NaN}, {"timestamp": 1631531899270, "ltp": 1.1, "tv": 12995.97, "trd": [[1.1, 348.3]], "batb": [[0, 1.11, 170.36]], "batl": NaN}, {"timestamp": 1631531900051, "ltp": 1.1, "tv": 12995.97, "trd": NaN, "batb": [[0, 1.11, 255.54]], "batl": NaN}, {"timestamp": 1631531903280, "ltp": 1.1, "tv": 12995.97, "trd": NaN, "batb": [[0, 1.11, 430.54]], "batl": NaN}, {"timestamp": 1631531905159, "ltp": 1.12, "tv": 12997.21, "trd": [[1.12, 39.6]], "batb": NaN, "batl": [[0, 1.12, 611.84]]}, {"timestamp": 1631531905367, "ltp": 1.11, "tv": 13097.21, "trd": [[1.11, 946.04]], "batb": [[0, 1.11, 380.54]], "batl": NaN}, {"timestamp": 1631531906496, "ltp": 1.12, "tv": 13098.21, "trd": [[1.12, 40.6]], "batb": NaN, "batl": [[0, 1.12, 611.34]]}, {"timestamp": 1631531908262, "ltp": 1.12, "tv": 13098.21, "trd": NaN, "batb": NaN, "batl": [[0, 1.15, 48.53], [1, 1.17, 23.85], [2, 1.25, 14.85]]}, {"timestamp": 1631531908991, "ltp": 1.12, "tv": 13098.21, "trd": NaN, "batb": [[1, 1.04, 767.6], [2, 1.07, 0]], "batl": [[0, 1.25, 14.85], [1, 1.31, 165.5], [2, 1.39, 17.78]]}, {"timestamp": 1631531909404, "ltp": 1.12, "tv": 13098.21, "trd": NaN, "batb": [[0, 1.11, 205.54]], "batl": NaN}, {"timestamp": 1631531911279, "ltp": 1.11, "tv": 13104.98, "trd": [[1.11, 952.8]], "batb": [[0, 1.11, 202.16]], "batl": [[0, 1.12, 255.54], [1, 1.25, 14.85], [2, 1.31, 165.5]]}, {"timestamp": 1631531912001, "ltp": 1.11, "tv": 13104.98, "trd": NaN, "batb": NaN, "batl": [[0, 1.12, 511.07], [2, 1.26, 166.75]]}, {"timestamp": 1631531913573, "ltp": 1.11, "tv": 13123.02, "trd": [[1.11, 970.84]], "batb": [[0, 1.11, 193.13]], "batl": NaN}, {"timestamp": 1631531916896, "ltp": 1.12, "tv": 13125.34, "trd": [[1.12, 42.92]], "batb": [[0, 1.04, 767.6], [1, 1.04, 0]], "batl": [[0, 1.12, 509.91]]}, {"timestamp": 1631531918190, "ltp": 1.12, "tv": 13125.34, "trd": NaN, "batb": [[0, 1.05, 248.04], [1, 1.04, 767.6]], "batl": [[0, 1.06, 29.19], [1, 1.12, 509.91], [2, 1.25, 14.85]]}, {"timestamp": 1631531919284, "ltp": 1.12, "tv": 13125.34, "trd": NaN, "batb": [[2, 1.02, 54.72]], "batl": [[0, 1.07, 595.5], [1, 1.1, 50.74], [2, 1.12, 534.84]]}, {"timestamp": 1631531921308, "ltp": 1.12, "tv": 13125.34, "trd": NaN, "batb": NaN, "batl": [[0, 1.06, 114.37], [1, 1.07, 680.68], [2, 1.1, 50.74]]}, {"timestamp": 1631531921685, "ltp": 1.12, "tv": 13125.34, "trd": NaN, "batb": NaN, "batl": [[0, 1.07, 680.68], [1, 1.1, 50.74], [2, 1.12, 534.84]]}, {"timestamp": 1631531923288, "ltp": 1.07, "tv": 13127.32, "trd": [[1.07, 950.22]], "batb": [[0, 1.05, 588.76]], "batl": [[0, 1.07, 679.69], [2, 1.12, 24.92]]}, {"timestamp": 1631531925316, "ltp": 1.07, "tv": 13127.32, "trd": NaN, "batb": [[0, 1.05, 687.76]], "batl": [[0, 1.06, 29.19], [1, 1.07, 679.69], [2, 1.1, 50.74]]}, {"timestamp": 1631531927121, "ltp": 1.07, "tv": 13127.32, "trd": NaN, "batb": NaN, "batl": [[1, 1.07, 1020.4]]}, {"timestamp": 1631531930912, "ltp": 1.05, "tv": 13232.76, "trd": [[1.05, 688.69]], "batb": [[0, 1.05, 635.04]], "batl": NaN}, {"timestamp": 1631531932995, "ltp": 1.05, "tv": 13232.76, "trd": NaN, "batb": [[0, 1.06, 9.02], [1, 1.05, 340.72], [2, 1.01, 4122.58]], "batl": [[0, 1.07, 425.89], [1, 1.19, 14.85], [2, 1.23, 142.21]]}, {"timestamp": 1631531935330, "ltp": 1.07, "tv": 13233.53, "trd": [[1.07, 950.99]], "batb": [[0, 1.06, 9.14], [2, 1.01, 0]], "batl": [[0, 1.07, 425.51]]}, {"timestamp": 1631531936229, "ltp": 1.07, "tv": 13233.53, "trd": NaN, "batb": NaN, "batl": [[2, 1.21, 14.85]]}, {"timestamp": 1631531941420, "ltp": 1.07, "tv": 13233.53, "trd": NaN, "batb": [[0, 1.05, 340.83], [1, 1.05, 0]], "batl": NaN}, {"timestamp": 1631531942510, "ltp": 1.07, "tv": 13233.53, "trd": NaN, "batb": [[0, 1.06, 218.12], [1, 1.05, 340.72]], "batl": NaN}, {"timestamp": 1631531946107, "ltp": 1.07, "tv": 13254.79, "trd": [[1.07, 972.25]], "batb": NaN, "batl": [[0, 1.07, 414.88]]}, {"timestamp": 1631531951314, "ltp": 1.07, "tv": 13271.95, "trd": [[1.07, 989.41]], "batb": [[0, 1.05, 340.83], [1, 1.05, 0]], "batl": [[0, 1.07, 406.3]]}, {"timestamp": 1631531952821, "ltp": 1.07, "tv": 13272.72, "trd": [[1.07, 990.18]], "batb": NaN, "batl": [[0, 1.07, 405.92]]}, {"timestamp": 1631531955324, "ltp": 1.06, "tv": 13272.96, "trd": [[1.06, 1079.59]], "batb": [[0, 1.05, 340.72]], "batl": [[0, 1.06, 1.28], [1, 1.07, 405.92], [2, 1.19, 14.85]]}, {"timestamp": 1631531957468, "ltp": 1.07, "tv": 13277.83, "trd": [[1.07, 995.06]], "batb": NaN, "batl": [[0, 1.07, 403.48], [1, 1.19, 14.85], [2, 1.21, 14.85]]}, {"timestamp": 1631531959132, "ltp": 1.07, "tv": 13277.83, "trd": NaN, "batb": NaN, "batl": [[1, 1.17, 29.71], [2, 1.19, 14.85]]}, {"timestamp": 1631531965334, "ltp": 1.07, "tv": 13277.83, "trd": NaN, "batb": NaN, "batl": [[0, 1.14, 41.45], [1, 1.17, 82.36]]}, {"timestamp": 1631531966272, "ltp": 1.07, "tv": 13277.83, "trd": NaN, "batb": [[0, 1.12, 290.54], [1, 1.09, 51.21], [2, 1.07, 26.08]], "batl": [[1, 1.17, 52.65], [2, 1.18, 47.3]]}, {"timestamp": 1631531970579, "ltp": 1.13, "tv": 13657.34, "trd": [[1.13, 379.5]], "batb": NaN, "batl": NaN}, {"timestamp": 1631531973546, "ltp": 1.13, "tv": 13657.34, "trd": NaN, "batb": [[0, 1.12, 435.54]], "batl": NaN}, {"timestamp": 1631531978292, "ltp": 1.13, "tv": 13657.34, "trd": NaN, "batb": [[0, 1.06, 968.8], [1, 1.04, 708.52], [2, 1.07, 0]], "batl": [[0, 1.39, 18.32], [1, 1.4, 940.5], [2, 1.44, 114.08]]}, {"timestamp": 1631531979280, "ltp": 1.13, "tv": 13657.34, "trd": NaN, "batb": [[0, 1.04, 708.52], [1, 1.04, 0]], "batl": [[0, 1.16, 170.36], [1, 1.39, 18.32]]}, {"timestamp": 1631531979952, "ltp": 1.13, "tv": 13657.34, "trd": NaN, "batb": NaN, "batl": [[0, 1.16, 425.89]]}, {"timestamp": 1631531980368, "ltp": 1.13, "tv": 13657.34, "trd": NaN, "batb": NaN, "batl": [[0, 1.12, 36.06], [1, 1.16, 425.89], [2, 1.39, 18.32]]}, {"timestamp": 1631531986667, "ltp": 1.13, "tv": 13657.34, "trd": NaN, "batb": NaN, "batl": [[0, 1.16, 425.89], [1, 1.39, 18.32], [2, 3.8, 27.48]]}, {"timestamp": 1631531988171, "ltp": 1.13, "tv": 13657.34, "trd": NaN, "batb": NaN, "batl": [[0, 1.39, 18.32], [1, 3.8, 27.48], [2, 8.8, 7.23]]}, {"timestamp": 1631531989260, "ltp": 1.21, "tv": 13657.88, "trd": [[1.21, 281.99]], "batb": NaN, "batl": [[0, 1.39, 17.78]]}, {"timestamp": 1631531990300, "ltp": 1.3, "tv": 13697.91, "trd": [[1.3, 68.24]], "batb": [[0, 1.3, 138.45], [1, 1.25, 187.04], [2, 1.22, 158.24]], "batl": [[0, 1.32, 42.29], [1, 1.34, 20.83], [2, 1.35, 52.65]]}, {"timestamp": 1631531992893, "ltp": 1.3, "tv": 13718.45, "trd": [[1.3, 88.78]], "batb": [[0, 1.3, 128.18]], "batl": NaN}, {"timestamp": 1631531994509, "ltp": 1.3, "tv": 13807.25, "trd": [[1.3, 177.58]], "batb": [[0, 1.3, 83.78]], "batl": NaN}, {"timestamp": 1631531999916, "ltp": 1.3, "tv": 13882.92, "trd": [[1.3, 249.7], [1.32, 16.8]], "batb": [[0, 1.3, 47.72]], "batl": [[0, 1.32, 38.74]]}, {"timestamp": 1631532000800, "ltp": 1.3, "tv": 13883.7, "trd": [[1.3, 250.48]], "batb": [[0, 1.3, 47.33]], "batl": NaN}, {"timestamp": 1631532003309, "ltp": 1.3, "tv": 13921.66, "trd": [[1.3, 288.44]], "batb": [[0, 1.3, 28.35], [1, 1.28, 20.54], [2, 1.25, 187.04]], "batl": NaN}, {"timestamp": 1631532003992, "ltp": 1.3, "tv": 13928.89, "trd": [[1.3, 295.67]], "batb": [[0, 1.3, 24.74]], "batl": NaN}, {"timestamp": 1631532006189, "ltp": 1.3, "tv": 13939.71, "trd": [[1.3, 306.49]], "batb": [[0, 1.3, 19.33]], "batl": NaN}, {"timestamp": 1631532007285, "ltp": 1.3, "tv": 13941.23, "trd": [[1.3, 308.01]], "batb": [[0, 1.3, 17.8]], "batl": [[1, 1.33, 405.73], [2, 1.34, 20.83]]}, {"timestamp": 1631532009989, "ltp": 1.33, "tv": 14830.16, "trd": [[1.32, 94.27], [1.33, 825.03]], "batb": [[0, 1.33, 298.9], [1, 1.3, 17.8], [2, 1.28, 20.54]], "batl": [[0, 1.34, 20.83], [1, 1.35, 52.65], [2, 1.37, 315.5]]}, {"timestamp": 1631532010404, "ltp": 1.33, "tv": 14830.16, "trd": NaN, "batb": NaN, "batl": [[2, 1.66, 587.81]]}, {"timestamp": 1631532012901, "ltp": 1.33, "tv": 14931.73, "trd": [[1.33, 926.6]], "batb": [[0, 1.33, 248.12], [2, 1.25, 187.04]], "batl": NaN}, {"timestamp": 1631532015613, "ltp": 1.33, "tv": 14967.67, "trd": [[1.33, 962.54]], "batb": [[0, 1.33, 230.15]], "batl": NaN}, {"timestamp": 1631532018229, "ltp": 1.33, "tv": 14969.83, "trd": [[1.33, 964.7]], "batb": [[0, 1.33, 229.07], [2, 1.23, 523.6]], "batl": [[1, 1.38, 337.36]]}, {"timestamp": 1631532018807, "ltp": 1.33, "tv": 14969.83, "trd": NaN, "batb": [[1, 1.23, 523.6], [2, 1.22, 158.24]], "batl": [[0, 1.38, 337.36], [1, 1.66, 587.81], [2, 3.8, 27.48]]}, {"timestamp": 1631532020322, "ltp": 1.33, "tv": 14969.83, "trd": NaN, "batb": [[0, 1.23, 523.6], [1, 1.22, 158.24], [2, 1.06, 2973.46]], "batl": [[1, 1.4, 294.89], [2, 1.66, 587.81]]}, {"timestamp": 1631532024805, "ltp": 1.33, "tv": 14969.83, "trd": NaN, "batb": [[0, 1.22, 158.24], [1, 1.06, 2973.46], [2, 1.06, 0]], "batl": [[2, 3.8, 27.48]]}, {"timestamp": 1631532025428, "ltp": 1.33, "tv": 14969.83, "trd": NaN, "batb": NaN, "batl": [[0, 1.4, 294.89], [1, 3.8, 27.48], [2, 8.8, 7.23]]}, {"timestamp": 1631532027348, "ltp": 1.33, "tv": 14969.83, "trd": NaN, "batb": [[0, 1.25, 44.65], [1, 1.23, 22.69], [2, 1.22, 158.24]], "batl": [[0, 1.37, 40.74], [1, 1.38, 52.65], [2, 1.39, 20.08]]}, {"timestamp": 1631532028338, "ltp": 1.33, "tv": 14969.83, "trd": NaN, "batb": [[0, 1.34, 95.23], [1, 1.28, 492.6], [2, 1.27, 124.43]], "batl": NaN}, {"timestamp": 1631532030007, "ltp": 1.33, "tv": 14969.83, "trd": NaN, "batb": NaN, "batl": [[0, 1.37, 51.66]]}, {"timestamp": 1631532032151, "ltp": 1.37, "tv": 14972.98, "trd": [[1.37, 7.49]], "batb": NaN, "batl": [[0, 1.37, 48.51]]}, {"timestamp": 1631532033241, "ltp": 1.37, "tv": 14972.98, "trd": NaN, "batb": NaN, "batl": [[0, 1.37, 377.42], [1, 1.39, 20.08], [2, 1.4, 294.89]]}, {"timestamp": 1631532033918, "ltp": 1.37, "tv": 14972.98, "trd": NaN, "batb": [[0, 1.28, 492.6], [1, 1.27, 124.43], [2, 1.06, 2973.46]], "batl": [[0, 1.37, 339.83], [1, 1.4, 294.89], [2, 1.42, 287.75]]}, {"timestamp": 1631532036631, "ltp": 1.37, "tv": 14972.98, "trd": NaN, "batb": NaN, "batl": [[0, 1.37, 340.02]]}, {"timestamp": 1631532037622, "ltp": 1.37, "tv": 15189.04, "trd": [[1.36, 0.19], [1.37, 223.36]], "batb": NaN, "batl": [[0, 1.37, 123.96]]}, {"timestamp": 1631532039336, "ltp": 1.37, "tv": 15189.08, "trd": [[1.37, 223.39]], "batb": NaN, "batl": [[0, 1.37, 123.95]]}, {"timestamp": 1631532044248, "ltp": 1.37, "tv": 15228.14, "trd": [[1.37, 262.45]], "batb": NaN, "batl": [[0, 1.37, 84.88]]}, {"timestamp": 1631532044457, "ltp": 1.37, "tv": 15228.14, "trd": NaN, "batb": NaN, "batl": [[1, 1.42, 287.75], [2, 1.82, 475.58]]}, {"timestamp": 1631532046333, "ltp": 1.37, "tv": 15228.14, "trd": NaN, "batb": NaN, "batl": [[0, 1.42, 287.75], [1, 1.82, 475.58], [2, 3.8, 27.48]]}, {"timestamp": 1631532047268, "ltp": 1.37, "tv": 15228.14, "trd": NaN, "batb": [[0, 1.27, 124.43], [1, 1.06, 2973.46], [2, 1.06, 0]], "batl": NaN}, {"timestamp": 1631532048148, "ltp": 1.37, "tv": 15228.14, "trd": NaN, "batb": [[0, 1.29, 43.27], [1, 1.27, 146.41], [2, 1.06, 2973.46]], "batl": [[0, 1.41, 39.59], [1, 1.42, 287.75], [2, 1.43, 19.52]]}, {"timestamp": 1631532049036, "ltp": 1.39, "tv": 15232.48, "trd": [[1.39, 4.34]], "batb": [[0, 1.39, 78.33], [1, 1.34, 97.49], [2, 1.29, 43.27]], "batl": NaN}, {"timestamp": 1631532052169, "ltp": 1.39, "tv": 15282.95, "trd": [[1.39, 54.82]], "batb": [[0, 1.39, 27.85], [2, 1.31, 484.1]], "batl": NaN}, {"timestamp": 1631532053268, "ltp": 1.39, "tv": 15282.95, "trd": NaN, "batb": [[0, 1.39, 139.85], [1, 1.37, 9.02], [2, 1.34, 97.49]], "batl": NaN}, {"timestamp": 1631532055154, "ltp": 1.39, "tv": 15282.95, "trd": NaN, "batb": NaN, "batl": [[2, 1.43, 301.02]]}, {"timestamp": 1631532055362, "ltp": 1.41, "tv": 15299.99, "trd": [[1.41, 17.03]], "batb": NaN, "batl": [[0, 1.41, 31.07]]}, {"timestamp": 1631532058382, "ltp": 1.41, "tv": 15304.19, "trd": [[1.41, 21.23]], "batb": NaN, "batl": [[0, 1.41, 28.97]]}, {"timestamp": 1631532061004, "ltp": 1.41, "tv": 15304.19, "trd": NaN, "batb": NaN, "batl": [[0, 1.41, 41.64]]}, {"timestamp": 1631532065280, "ltp": 1.41, "tv": 15304.19, "trd": NaN, "batb": [[0, 1.37, 9.02], [1, 1.34, 97.49], [2, 1.31, 484.1]], "batl": [[0, 1.44, 80.76], [1, 1.82, 475.58], [2, 3.8, 27.48]]}, {"timestamp": 1631532068159, "ltp": 1.41, "tv": 15304.19, "trd": NaN, "batb": [[2, 1.33, 99.33]], "batl": [[0, 1.42, 311.75], [1, 1.43, 313.5], [2, 1.44, 80.76]]}, {"timestamp": 1631532068789, "ltp": 1.41, "tv": 15304.19, "trd": NaN, "batb": [[1, 1.33, 99.33], [2, 1.31, 484.1]], "batl": [[0, 1.43, 313.5], [1, 1.44, 80.76], [2, 1.82, 475.58]]}, {"timestamp": 1631532073098, "ltp": 1.41, "tv": 15304.19, "trd": NaN, "batb": NaN, "batl": [[1, 1.82, 475.58], [2, 3.8, 27.48]]}, {"timestamp": 1631532075182, "ltp": 1.41, "tv": 15304.19, "trd": NaN, "batb": NaN, "batl": [[0, 1.42, 393.64], [1, 1.43, 313.5], [2, 1.82, 475.58]]}, {"timestamp": 1631532075391, "ltp": 1.41, "tv": 15304.19, "trd": NaN, "batb": NaN, "batl": [[0, 1.42, 81.89]]}, {"timestamp": 1631532082311, "ltp": 1.41, "tv": 15304.19, "trd": NaN, "batb": NaN, "batl": [[0, 1.42, 356.64]]}, {"timestamp": 1631532082574, "ltp": 1.41, "tv": 15304.19, "trd": NaN, "batb": NaN, "batl": [[0, 1.42, 81.89]]}, {"timestamp": 1631532086319, "ltp": 1.37, "tv": 15322.23, "trd": [[1.37, 280.49]], "batb": [[0, 1.33, 99.33], [1, 1.06, 2973.46], [2, 1.31, 0]], "batl": [[0, 1.36, 11.21], [1, 1.37, 346.5], [2, 1.4, 85.72]]}, {"timestamp": 1631532087124, "ltp": 1.37, "tv": 15322.23, "trd": NaN, "batb": [[1, 1.25, 180.72], [2, 1.23, 22.69]], "batl": [[1, 1.37, 387.24], [2, 1.39, 20.08]]}, {"timestamp": 1631532090128, "ltp": 1.37, "tv": 15322.23, "trd": NaN, "batb": [[1, 1.25, 692.78]], "batl": NaN}, {"timestamp": 1631532094334, "ltp": 1.36, "tv": 15333.43, "trd": [[1.36, 11.39]], "batb": [[0, 1.34, 163], [1, 1.33, 99.33], [2, 1.25, 692.78]], "batl": [[0, 1.37, 387.25], [1, 1.39, 20.08], [2, 1.4, 333.27]]}, {"timestamp": 1631532098308, "ltp": 1.36, "tv": 15333.43, "trd": NaN, "batb": NaN, "batl": [[2, 1.4, 304.69]]}, {"timestamp": 1631532099245, "ltp": 1.36, "tv": 15333.43, "trd": NaN, "batb": [[0, 1.25, 648.13], [1, 1.06, 2973.46], [2, 1.25, 0]], "batl": [[0, 1.42, 379.14], [1, 1.82, 475.58], [2, 3.8, 27.48]]}, {"timestamp": 1631532105167, "ltp": 1.36, "tv": 15333.43, "trd": NaN, "batb": [[0, 1.26, 2.89], [1, 1.25, 136.06], [2, 1.06, 2973.46]], "batl": [[0, 1.42, 297.25]]}, {"timestamp": 1631532106256, "ltp": 1.4, "tv": 15351.17, "trd": [[1.4, 22.84]], "batb": NaN, "batl": [[0, 1.4, 260.67], [1, 1.42, 297.25], [2, 1.43, 52.65]]}, {"timestamp": 1631532107245, "ltp": 1.4, "tv": 15351.17, "trd": NaN, "batb": [[0, 1.39, 82.68], [1, 1.33, 98.58], [2, 1.3, 42.94]], "batl": [[0, 1.42, 336.55], [1, 1.43, 52.65], [2, 1.44, 19.38]]}, {"timestamp": 1631532109330, "ltp": 1.4, "tv": 15351.17, "trd": NaN, "batb": [[0, 1.4, 8.87], [1, 1.39, 82.68], [2, 1.33, 98.58]], "batl": NaN}, {"timestamp": 1631532111259, "ltp": 1.4, "tv": 15371.6, "trd": [[1.4, 43.27]], "batb": [[0, 1.39, 82.68], [1, 1.33, 98.58], [2, 1.31, 484.1]], "batl": NaN}, {"timestamp": 1631532113337, "ltp": 1.4, "tv": 15371.6, "trd": NaN, "batb": [[0, 1.4, 155], [1, 1.39, 82.68], [2, 1.33, 98.58]], "batl": [[1, 1.43, 365.15], [2, 1.44, 312.21]]}, {"timestamp": 1631532116642, "ltp": 1.4, "tv": 15371.76, "trd": [[1.4, 43.43]], "batb": [[0, 1.4, 154.92]], "batl": NaN}, {"timestamp": 1631532118260, "ltp": 1.4, "tv": 15371.76, "trd": NaN, "batb": [[0, 1.33, 98.58], [1, 1.31, 484.1], [2, 1.06, 2973.46]], "batl": [[0, 1.46, 79.65], [1, 1.82, 475.58], [2, 3.8, 27.48]]}, {"timestamp": 1631532119354, "ltp": 1.4, "tv": 15371.76, "trd": NaN, "batb": NaN, "batl": [[0, 1.41, 13.44], [1, 1.46, 79.65], [2, 1.82, 475.58]]}, {"timestamp": 1631532119560, "ltp": 1.4, "tv": 15371.76, "trd": NaN, "batb": NaN, "batl": [[0, 1.46, 79.65], [1, 1.82, 475.58], [2, 3.8, 27.48]]}, {"timestamp": 1631532121169, "ltp": 1.4, "tv": 15371.76, "trd": NaN, "batb": NaN, "batl": [[0, 1.44, 279.92], [1, 1.46, 79.65], [2, 1.82, 475.58]]}, {"timestamp": 1631532123948, "ltp": 1.4, "tv": 15371.85, "trd": [[1.4, 43.53]], "batb": NaN, "batl": [[0, 1.44, 279.83]]}, {"timestamp": 1631532134273, "ltp": 1.4, "tv": 15371.85, "trd": NaN, "batb": NaN, "batl": [[0, 1.38, 52.65], [1, 1.39, 309.5], [2, 1.4, 28.58]]}, {"timestamp": 1631532135310, "ltp": 1.4, "tv": 15371.85, "trd": NaN, "batb": [[2, 1.26, 44.3]], "batl": [[0, 1.38, 93.1], [2, 1.4, 48.51]]}, {"timestamp": 1631532139315, "ltp": 1.33, "tv": 15393.08, "trd": [[1.33, 969.54], [1.34, 20.75]], "batb": [[0, 1.33, 96.16]], "batl": NaN}, {"timestamp": 1631532144422, "ltp": 1.37, "tv": 15397.32, "trd": [[1.37, 284.73]], "batb": NaN, "batl": NaN}, {"timestamp": 1631532147709, "ltp": 1.37, "tv": 15397.32, "trd": NaN, "batb": [[0, 1.33, 149.16]], "batl": NaN}, {"timestamp": 1631532149622, "ltp": 1.37, "tv": 15397.32, "trd": NaN, "batb": [[0, 1.33, 96.16]], "batl": NaN}, {"timestamp": 1631532151338, "ltp": 1.37, "tv": 15397.32, "trd": NaN, "batb": [[2, 1.25, 141.09]], "batl": [[0, 1.38, 52.65], [2, 1.4, 28.58]]}, {"timestamp": 1631532152227, "ltp": 1.37, "tv": 15397.32, "trd": NaN, "batb": [[0, 1.34, 12.14], [1, 1.33, 96.16], [2, 1.31, 484.1]], "batl": [[0, 1.36, 18.95], [1, 1.38, 52.65], [2, 1.39, 309.5]]}, {"timestamp": 1631532154622, "ltp": 1.37, "tv": 15397.32, "trd": NaN, "batb": [[0, 1.33, 96.16], [1, 1.31, 484.1], [2, 1.25, 141.09]], "batl": [[0, 1.38, 52.65], [1, 1.39, 309.5], [2, 1.4, 28.58]]}, {"timestamp": 1631532157544, "ltp": 1.37, "tv": 15397.32, "trd": NaN, "batb": [[0, 1.34, 12.14], [1, 1.33, 96.16], [2, 1.31, 484.1]], "batl": [[0, 1.36, 18.95], [1, 1.38, 52.65], [2, 1.39, 309.5]]}, {"timestamp": 1631532159326, "ltp": 1.37, "tv": 15397.32, "trd": NaN, "batb": [[0, 1.33, 96.16], [1, 1.31, 484.1], [2, 1.25, 141.09]], "batl": [[0, 1.39, 309.5], [1, 1.43, 250.5], [2, 1.44, 279.83]]}, {"timestamp": 1631532159740, "ltp": 1.37, "tv": 15397.32, "trd": NaN, "batb": [[0, 1.31, 484.1], [1, 1.25, 141.09], [2, 1.06, 2973.46]], "batl": [[0, 1.46, 329.4], [1, 1.82, 475.58], [2, 3.8, 27.48]]}, {"timestamp": 1631532163337, "ltp": 1.37, "tv": 15397.32, "trd": NaN, "batb": [[0, 1.25, 141.09], [1, 1.06, 2973.46], [2, 1.06, 0]], "batl": NaN}, {"timestamp": 1631532166920, "ltp": 1.37, "tv": 15397.32, "trd": NaN, "batb": [[0, 1.25, 653.15]], "batl": NaN}, {"timestamp": 1631532170242, "ltp": 1.37, "tv": 15397.32, "trd": NaN, "batb": NaN, "batl": [[0, 1.43, 265.5], [1, 1.46, 329.4], [2, 1.82, 475.58]]}, {"timestamp": 1631532170446, "ltp": 1.37, "tv": 15397.32, "trd": NaN, "batb": NaN, "batl": [[0, 1.46, 329.4], [1, 1.82, 475.58], [2, 3.8, 27.48]]}, {"timestamp": 1631532177136, "ltp": 1.37, "tv": 15397.32, "trd": NaN, "batb": NaN, "batl": [[0, 1.43, 253.5], [1, 1.46, 329.4], [2, 1.82, 475.58]]}, {"timestamp": 1631532177447, "ltp": 1.37, "tv": 15397.32, "trd": NaN, "batb": NaN, "batl": [[0, 1.46, 329.4], [1, 1.82, 475.58], [2, 3.8, 27.48]]}, {"timestamp": 1631532183270, "ltp": 1.37, "tv": 15397.32, "trd": NaN, "batb": NaN, "batl": [[0, 1.46, 330.14]]}, {"timestamp": 1631532183639, "ltp": 1.37, "tv": 15397.32, "trd": NaN, "batb": [[0, 1.25, 141.09]], "batl": [[1, 3.8, 27.48], [2, 8.8, 7.23]]}, {"timestamp": 1631532185354, "ltp": 1.37, "tv": 15397.32, "trd": NaN, "batb": [[0, 1.26, 14.98], [1, 1.25, 141.09], [2, 1.19, 46.91]], "batl": [[0, 1.28, 27.28], [1, 1.3, 95.59], [2, 1.31, 347.5]]}, {"timestamp": 1631532187266, "ltp": 1.37, "tv": 15397.32, "trd": NaN, "batb": [[2, 1.2, 538.19]], "batl": NaN}, {"timestamp": 1631532189341, "ltp": 1.26, "tv": 15526.66, "trd": [[1.26, 322.57]], "batb": [[0, 1.26, 95.31]], "batl": [[0, 1.28, 118.13]]}, {"timestamp": 1631532195346, "ltp": 1.26, "tv": 15528.52, "trd": [[1.26, 324.43]], "batb": [[0, 1.26, 94.38]], "batl": NaN}, {"timestamp": 1631532199872, "ltp": 1.28, "tv": 15528.75, "trd": [[1.28, 37.86]], "batb": NaN, "batl": [[0, 1.28, 90.74]]}, {"timestamp": 1631532201580, "ltp": 1.28, "tv": 15528.75, "trd": NaN, "batb": NaN, "batl": [[1, 1.3, 52.65]]}, {"timestamp": 1631532202467, "ltp": 1.28, "tv": 15528.75, "trd": NaN, "batb": NaN, "batl": [[0, 1.27, 21.81], [1, 1.28, 90.74], [2, 1.3, 52.65]]}, {"timestamp": 1631532205066, "ltp": 1.28, "tv": 15710.07, "trd": [[1.27, 583.6], [1.28, 175.56]], "batb": NaN, "batl": [[0, 1.28, 21.88], [1, 1.3, 52.65], [2, 1.31, 347.5]]}, {"timestamp": 1631532208288, "ltp": 1.26, "tv": 15727.11, "trd": [[1.26, 341.47]], "batb": [[0, 1.2, 538.19], [1, 1.14, 248.7], [2, 1.06, 2973.46]], "batl": [[1, 1.37, 219.5], [2, 1.4, 227.49]]}, {"timestamp": 1631532211199, "ltp": 1.26, "tv": 15727.11, "trd": NaN, "batb": [[1, 1.17, 109], [2, 1.16, 113]], "batl": NaN}, {"timestamp": 1631532214127, "ltp": 1.26, "tv": 15727.11, "trd": NaN, "batb": [[0, 1.17, 109], [1, 1.16, 113], [2, 1.15, 117]], "batl": NaN}, {"timestamp": 1631532215319, "ltp": 1.26, "tv": 15727.11, "trd": NaN, "batb": [[0, 1.34, 12.73], [1, 1.17, 109], [2, 1.16, 113]], "batl": [[0, 1.36, 18.17], [1, 1.4, 227.49], [2, 1.41, 203.5]]}, {"timestamp": 1631532216207, "ltp": 1.26, "tv": 15727.11, "trd": NaN, "batb": [[0, 1.33, 101.34], [1, 1.26, 44.3], [2, 1.24, 167.44]], "batl": [[0, 1.37, 40.74], [1, 1.39, 20.08], [2, 1.4, 227.49]]}, {"timestamp": 1631532218294, "ltp": 1.26, "tv": 15727.11, "trd": NaN, "batb": [[0, 1.34, 12.73], [1, 1.33, 101.34], [2, 1.26, 44.3]], "batl": [[0, 1.36, 18.17], [1, 1.37, 40.74], [2, 1.39, 20.08]]}, {"timestamp": 1631532220210, "ltp": 1.33, "tv": 15756.51, "trd": [[1.33, 973.48], [1.34, 46.21]], "batb": [[0, 1.33, 99.37], [1, 1.26, 44.3], [2, 1.25, 512.06]], "batl": [[0, 1.36, 38.77]]}, {"timestamp": 1631532224010, "ltp": 1.33, "tv": 15756.51, "trd": NaN, "batb": NaN, "batl": [[0, 1.34, 8.52], [1, 1.36, 38.77], [2, 1.37, 40.74]]}, {"timestamp": 1631532228957, "ltp": 1.33, "tv": 15756.51, "trd": NaN, "batb": [[0, 1.25, 512.06], [1, 1.24, 144.93], [2, 1.2, 100]], "batl": [[1, 1.36, 20.6], [2, 1.44, 221.58]]}, {"timestamp": 1631532237357, "ltp": 1.33, "tv": 15756.51, "trd": NaN, "batb": NaN, "batl": [[0, 1.36, 20.6], [1, 1.37, 4]]}, {"timestamp": 1631532237934, "ltp": 1.33, "tv": 15756.51, "trd": NaN, "batb": NaN, "batl": [[1, 1.44, 221.58], [2, 1.66, 587.81]]}, {"timestamp": 1631532246240, "ltp": 1.33, "tv": 15756.51, "trd": NaN, "batb": NaN, "batl": [[1, 1.41, 273.5], [2, 1.44, 221.58]]}, {"timestamp": 1631532246449, "ltp": 1.33, "tv": 15756.51, "trd": NaN, "batb": NaN, "batl": [[1, 1.44, 221.58], [2, 1.66, 587.81]]}, {"timestamp": 1631532253160, "ltp": 1.33, "tv": 15756.51, "trd": NaN, "batb": NaN, "batl": [[1, 1.41, 232.5], [2, 1.44, 221.58]]}, {"timestamp": 1631532253469, "ltp": 1.33, "tv": 15756.51, "trd": NaN, "batb": NaN, "batl": [[1, 1.44, 221.58], [2, 1.66, 587.81]]}, {"timestamp": 1631532254665, "ltp": 1.33, "tv": 15756.51, "trd": NaN, "batb": NaN, "batl": [[0, 1.44, 221.58], [1, 1.66, 587.81], [2, 3.8, 27.48]]}, {"timestamp": 1631532260159, "ltp": 1.33, "tv": 15756.51, "trd": NaN, "batb": NaN, "batl": [[0, 1.41, 240.5], [1, 1.44, 221.58], [2, 1.66, 587.81]]}, {"timestamp": 1631532260465, "ltp": 1.33, "tv": 15756.51, "trd": NaN, "batb": NaN, "batl": [[0, 1.44, 221.58], [1, 1.66, 587.81], [2, 3.8, 27.48]]}, {"timestamp": 1631532263987, "ltp": 1.33, "tv": 15756.51, "trd": NaN, "batb": [[0, 1.24, 144.93], [1, 1.2, 100], [2, 1.19, 103]], "batl": [[1, 3.8, 27.48], [2, 8.8, 7.23]]}, {"timestamp": 1631532264870, "ltp": 1.33, "tv": 15756.51, "trd": NaN, "batb": [[0, 1.39, 11.83], [1, 1.38, 28.98], [2, 1.31, 42.61]], "batl": [[0, 1.41, 14.77], [1, 1.44, 260.34], [2, 1.46, 19.12]]}, {"timestamp": 1631532266011, "ltp": 1.33, "tv": 15756.51, "trd": NaN, "batb": [[0, 1.39, 94.26], [2, 1.33, 99.91]], "batl": NaN}, {"timestamp": 1631532267104, "ltp": 1.33, "tv": 15756.51, "trd": NaN, "batb": NaN, "batl": [[1, 1.42, 19.72], [2, 1.44, 260.34]]}, {"timestamp": 1631532269284, "ltp": 1.33, "tv": 15756.51, "trd": NaN, "batb": [[0, 1.39, 201.26]], "batl": NaN}, {"timestamp": 1631532275690, "ltp": 1.41, "tv": 15786.05, "trd": [[1.41, 50.77]], "batb": [[0, 1.41, 6.01], [1, 1.39, 201.26], [2, 1.38, 28.98]], "batl": [[0, 1.42, 19.72], [1, 1.44, 260.34], [2, 1.46, 19.12]]}, {"timestamp": 1631532281087, "ltp": 1.41, "tv": 15786.82, "trd": [[1.41, 51.54]], "batb": [[0, 1.41, 5.62]], "batl": NaN}, {"timestamp": 1631532282324, "ltp": 1.41, "tv": 15790.42, "trd": [[1.41, 55.14]], "batb": [[0, 1.41, 3.82]], "batl": NaN}, {"timestamp": 1631532286218, "ltp": 1.42, "tv": 15804.36, "trd": [[1.42, 13.94]], "batb": [[1, 1.39, 189.43]], "batl": [[0, 1.42, 10.4]]}, {"timestamp": 1631532288797, "ltp": 1.42, "tv": 15804.36, "trd": NaN, "batb": NaN, "batl": [[0, 1.42, 22.84]]}, {"timestamp": 1631532290136, "ltp": 1.41, "tv": 15812.01, "trd": [[1.41, 62.79]], "batb": [[0, 1.39, 189.43], [1, 1.38, 28.98], [2, 1.33, 99.91]], "batl": [[0, 1.41, 4.71], [1, 1.42, 22.84], [2, 1.44, 260.34]]}, {"timestamp": 1631532300231, "ltp": 1.41, "tv": 15812.01, "trd": NaN, "batb": NaN, "batl": [[0, 1.42, 23.04], [1, 1.44, 260.34], [2, 1.46, 19.12]]}, {"timestamp": 1631532301538, "ltp": 1.4, "tv": 15862.01, "trd": [[1.4, 93.53]], "batb": NaN, "batl": NaN}, {"timestamp": 1631532305165, "ltp": 1.4, "tv": 15862.56, "trd": [[1.4, 94.08]], "batb": NaN, "batl": [[0, 1.42, 23.42]]}, {"timestamp": 1631532305842, "ltp": 1.42, "tv": 15880.76, "trd": [[1.4, 94.46], [1.41, 62.99], [1.42, 31.56]], "batb": NaN, "batl": [[0, 1.42, 5.22]]}, {"timestamp": 1631532312357, "ltp": 1.42, "tv": 15880.76, "trd": NaN, "batb": [[0, 1.39, 82.43]], "batl": [[0, 1.44, 260.34], [1, 1.46, 19.12], [2, 1.89, 441.29]]}, {"timestamp": 1631532323209, "ltp": 1.39, "tv": 15882.62, "trd": [[1.39, 56.68]], "batb": [[0, 1.39, 81.5]], "batl": NaN}, {"timestamp": 1631532327299, "ltp": 1.44, "tv": 15882.85, "trd": [[1.44, 0.23]], "batb": NaN, "batl": [[0, 1.44, 260.11]]}, {"timestamp": 1631532334814, "ltp": 1.39, "tv": 15902.85, "trd": [[1.39, 76.68]], "batb": [[0, 1.39, 71.5]], "batl": NaN}, {"timestamp": 1631532336115, "ltp": 1.39, "tv": 15903.03, "trd": [[1.39, 76.86]], "batb": [[0, 1.39, 71.4]], "batl": NaN}, {"timestamp": 1631532339835, "ltp": 1.39, "tv": 15903.03, "trd": NaN, "batb": [[0, 1.4, 10.75], [1, 1.39, 71.4], [2, 1.38, 28.98]], "batl": NaN}, {"timestamp": 1631532342625, "ltp": 1.39, "tv": 15948.98, "trd": [[1.39, 90.56], [1.4, 126.71]], "batb": [[0, 1.39, 64.55], [1, 1.38, 28.98], [2, 1.33, 99.91]], "batl": NaN}, {"timestamp": 1631532345837, "ltp": 1.39, "tv": 15948.98, "trd": NaN, "batb": [[0, 1.39, 175.55]], "batl": NaN}, {"timestamp": 1631532347862, "ltp": 1.39, "tv": 15949.08, "trd": [[1.39, 90.66]], "batb": [[0, 1.39, 175.51]], "batl": NaN}, {"timestamp": 1631532351847, "ltp": 1.39, "tv": 15949.08, "trd": NaN, "batb": NaN, "batl": [[0, 1.44, 221.35], [1, 1.89, 441.29], [2, 3.8, 27.48]]}, {"timestamp": 1631532353063, "ltp": 1.39, "tv": 15949.08, "trd": NaN, "batb": [[0, 1.39, 64.51]], "batl": NaN}, {"timestamp": 1631532354256, "ltp": 1.39, "tv": 15969.08, "trd": [[1.39, 110.66]], "batb": [[0, 1.39, 54.51]], "batl": NaN}, {"timestamp": 1631532355960, "ltp": 1.39, "tv": 15969.08, "trd": NaN, "batb": NaN, "batl": [[0, 1.41, 12.99], [1, 1.44, 221.35], [2, 1.52, 204.01]]}, {"timestamp": 1631532360575, "ltp": 1.39, "tv": 15969.08, "trd": NaN, "batb": NaN, "batl": [[2, 1.51, 219.5]]}, {"timestamp": 1631532361462, "ltp": 1.39, "tv": 15969.08, "trd": NaN, "batb": [[0, 1.39, 220.51]], "batl": NaN}, {"timestamp": 1631532367174, "ltp": 1.39, "tv": 15978.1, "trd": [[1.39, 119.68]], "batb": [[0, 1.39, 216]], "batl": NaN}, {"timestamp": 1631532370287, "ltp": 1.39, "tv": 15978.1, "trd": NaN, "batb": [[0, 1.39, 50], [1, 1.33, 99.91], [2, 1.31, 484.1]], "batl": [[0, 1.89, 441.29], [1, 3.8, 27.48], [2, 8.8, 7.23]]}, {"timestamp": 1631532370392, "ltp": 1.39, "tv": 15978.1, "trd": NaN, "batb": [[0, 1.33, 99.91], [1, 1.31, 484.1], [2, 1.2, 100]], "batl": NaN}, {"timestamp": 1631532373659, "ltp": 1.39, "tv": 15978.1, "trd": NaN, "batb": NaN, "batl": [[0, 1.55, 193.9], [1, 1.89, 441.29], [2, 3.8, 27.48]]}, {"timestamp": 1631532386113, "ltp": 1.39, "tv": 15978.1, "trd": NaN, "batb": NaN, "batl": [[0, 1.51, 224.5], [1, 1.55, 193.9], [2, 1.89, 441.29]]}, {"timestamp": 1631532387307, "ltp": 1.39, "tv": 15978.1, "trd": NaN, "batb": NaN, "batl": [[0, 1.55, 193.9], [1, 1.89, 441.29], [2, 3.8, 27.48]]}, {"timestamp": 1631532397646, "ltp": 1.39, "tv": 15978.1, "trd": NaN, "batb": [[1, 1.2, 100], [2, 1.19, 103]], "batl": NaN}, {"timestamp": 1631532399111, "ltp": 1.39, "tv": 15978.1, "trd": NaN, "batb": [[0, 1.48, 186.98], [1, 1.39, 40.16], [2, 1.37, 20.37]], "batl": [[0, 1.53, 36.48], [1, 1.55, 211.9], [2, 1.89, 441.29]]}, {"timestamp": 1631532400248, "ltp": 1.39, "tv": 15978.1, "trd": NaN, "batb": [[0, 1.49, 60.5], [1, 1.48, 186.98], [2, 1.4, 77.91]], "batl": NaN}, {"timestamp": 1631532403351, "ltp": 1.49, "tv": 15982.1, "trd": [[1.49, 4]], "batb": [[0, 1.49, 58.5]], "batl": NaN}, {"timestamp": 1631532404238, "ltp": 1.52, "tv": 15988.77, "trd": [[1.49, 8.26], [1.52, 2.41]], "batb": [[0, 1.49, 56.37], [2, 1.44, 1.7]], "batl": NaN}, {"timestamp": 1631532406954, "ltp": 1.52, "tv": 15988.77, "trd": NaN, "batb": NaN, "batl": [[2, 1.68, 201.89]]}, {"timestamp": 1631532410339, "ltp": 1.52, "tv": 15988.77, "trd": NaN, "batb": [[0, 1.44, 1.7], [1, 1.4, 77.91], [2, 1.38, 454.63]], "batl": [[0, 1.89, 441.29], [1, 3.8, 27.48], [2, 8.8, 7.23]]}, {"timestamp": 1631532410962, "ltp": 1.52, "tv": 15988.77, "trd": NaN, "batb": NaN, "batl": [[0, 1.49, 9.02], [1, 1.89, 441.29], [2, 3.8, 27.48]]}, {"timestamp": 1631532413355, "ltp": 1.52, "tv": 15988.77, "trd": NaN, "batb": [[1, 1.41, 76.74], [2, 1.4, 77.91]], "batl": [[0, 1.49, 10.82], [1, 1.68, 188.64], [2, 1.74, 190.25]]}, {"timestamp": 1631532413771, "ltp": 1.49, "tv": 15999.59, "trd": [[1.49, 19.08]], "batb": [[2, 1.38, 454.63]], "batl": [[0, 1.74, 190.25], [1, 1.89, 441.29], [2, 3.8, 27.48]]}, {"timestamp": 1631532417068, "ltp": 1.49, "tv": 15999.59, "trd": NaN, "batb": [[2, 1.2, 100]], "batl": [[1, 3.8, 27.48], [2, 8.8, 7.23]]}, {"timestamp": 1631532419069, "ltp": 1.49, "tv": 15999.59, "trd": NaN, "batb": [[0, 1.51, 36.97], [1, 1.49, 18.73], [2, 1.48, 1012.45]], "batl": [[0, 1.67, 33.42], [1, 1.68, 11.49], [2, 1.69, 16.52]]}, {"timestamp": 1631532419960, "ltp": 1.49, "tv": 15999.59, "trd": NaN, "batb": [[0, 1.66, 41.09], [1, 1.54, 53.56], [2, 1.51, 36.97]], "batl": NaN}, {"timestamp": 1631532423158, "ltp": 1.66, "tv": 16010.6, "trd": [[1.66, 4], [1.67, 7.01]], "batb": [[0, 1.66, 39.09]], "batl": [[0, 1.67, 28.77]]}, {"timestamp": 1631532423891, "ltp": 1.66, "tv": 16010.79, "trd": [[1.66, 4.19]], "batb": [[0, 1.66, 38.99]], "batl": NaN}, {"timestamp": 1631532424469, "ltp": 1.66, "tv": 16017.24, "trd": [[1.66, 10.64]], "batb": [[0, 1.66, 35.77]], "batl": NaN}, {"timestamp": 1631532428283, "ltp": 1.67, "tv": 16033.88, "trd": [[1.67, 23.64]], "batb": NaN, "batl": [[0, 1.67, 12.14]]}, {"timestamp": 1631532434264, "ltp": 1.67, "tv": 16033.88, "trd": NaN, "batb": [[0, 1.54, 53.56], [1, 1.5, 432.79], [2, 1.44, 1.7]], "batl": [[0, 2.3, 314.02], [1, 3.8, 27.48], [2, 8.8, 7.23]]}, {"timestamp": 1631532437291, "ltp": 1.67, "tv": 16033.88, "trd": NaN, "batb": NaN, "batl": [[0, 1.99, 143.5], [1, 2.3, 314.02], [2, 3.8, 27.48]]}, {"timestamp": 1631532438170, "ltp": 1.66, "tv": 16035.51, "trd": [[1.66, 12.28]], "batb": NaN, "batl": NaN}, {"timestamp": 1631532439171, "ltp": 1.67, "tv": 16035.61, "trd": [[1.67, 23.74]], "batb": NaN, "batl": NaN}, {"timestamp": 1631532441265, "ltp": 1.54, "tv": 16039.63, "trd": [[1.54, 4], [1.91, 0.02]], "batb": [[0, 1.54, 51.56]], "batl": NaN}, {"timestamp": 1631532456213, "ltp": 1.54, "tv": 16039.63, "trd": NaN, "batb": [[1, 1.44, 1.7], [2, 1.2, 100]], "batl": [[0, 1.57, 2002.74], [1, 1.58, 22.11], [2, 1.99, 143.5]]}, {"timestamp": 1631532457316, "ltp": 1.54, "tv": 16039.63, "trd": NaN, "batb": [[2, 1.43, 72.55]], "batl": [[0, 1.57, 312.05], [2, 1.59, 17.55]]}, {"timestamp": 1631532460318, "ltp": 1.54, "tv": 16039.63, "trd": NaN, "batb": [[0, 1.55, 187], [1, 1.54, 51.56], [2, 1.44, 1.7]], "batl": NaN}, {"timestamp": 1631532461312, "ltp": 1.57, "tv": 16044.29, "trd": [[1.57, 4.66]], "batb": NaN, "batl": [[0, 1.57, 309.72]]}, {"timestamp": 1631532466107, "ltp": 1.57, "tv": 16663.74, "trd": [[1.57, 624.11]], "batb": [[0, 1.57, 30.99], [1, 1.55, 187], [2, 1.54, 51.56]], "batl": [[0, 1.58, 22.11], [1, 1.59, 17.55], [2, 1.8, 176.57]]}, {"timestamp": 1631532467309, "ltp": 1.58, "tv": 16670.95, "trd": [[1.57, 624.3], [1.58, 7.02]], "batb": [[0, 1.57, 30.89]], "batl": [[0, 1.58, 18.6]]}, {"timestamp": 1631532469702, "ltp": 1.58, "tv": 16744.6, "trd": [[1.58, 80.67]], "batb": [[0, 1.58, 125.27], [1, 1.57, 30.89], [2, 1.55, 187]], "batl": [[0, 1.59, 17.55], [1, 1.8, 176.57], [2, 1.81, 177.5]]}, {"timestamp": 1631532471110, "ltp": 1.58, "tv": 16744.6, "trd": NaN, "batb": NaN, "batl": [[1, 2.1, 368.32], [2, 3.8, 27.48]]}, {"timestamp": 1631532472351, "ltp": 1.58, "tv": 16744.6, "trd": NaN, "batb": [[2, 1.44, 1.7]], "batl": [[0, 2.1, 368.32], [1, 3.8, 27.48], [2, 8.8, 7.23]]}, {"timestamp": 1631532473343, "ltp": 1.58, "tv": 16744.6, "trd": NaN, "batb": NaN, "batl": [[0, 1.93, 39.5], [1, 2.1, 368.32], [2, 3.8, 27.48]]}, {"timestamp": 1631532474343, "ltp": 1.58, "tv": 16744.6, "trd": NaN, "batb": NaN, "batl": [[0, 1.91, 41.5], [1, 1.93, 39.5], [2, 2.1, 368.32]]}, {"timestamp": 1631532476634, "ltp": 1.58, "tv": 16744.76, "trd": [[1.58, 80.83]], "batb": [[0, 1.58, 125.19]], "batl": NaN}, {"timestamp": 1631532478238, "ltp": 1.58, "tv": 16744.76, "trd": NaN, "batb": NaN, "batl": [[0, 1.83, 42.5], [1, 1.91, 41.5], [2, 1.93, 39.5]]}, {"timestamp": 1631532478546, "ltp": 1.58, "tv": 16744.76, "trd": NaN, "batb": NaN, "batl": [[0, 1.91, 41.5], [1, 1.93, 39.5], [2, 2.1, 368.32]]}, {"timestamp": 1631532491336, "ltp": 1.58, "tv": 16744.76, "trd": NaN, "batb": [[0, 1.57, 30.89], [1, 1.44, 1.7], [2, 1.43, 72.55]], "batl": NaN}, {"timestamp": 1631532492325, "ltp": 1.58, "tv": 16744.76, "trd": NaN, "batb": NaN, "batl": [[0, 1.83, 44.5], [1, 1.91, 41.5], [2, 1.93, 39.5]]}, {"timestamp": 1631532493046, "ltp": 1.58, "tv": 16744.76, "trd": NaN, "batb": NaN, "batl": [[0, 1.91, 41.5], [1, 1.93, 39.5], [2, 3.8, 27.48]]}, {"timestamp": 1631532494342, "ltp": 1.58, "tv": 16744.76, "trd": NaN, "batb": [[0, 1.72, 292.73], [1, 1.57, 30.89], [2, 1.44, 1.7]], "batl": [[0, 1.83, 9.92], [1, 1.91, 41.5], [2, 1.93, 39.5]]}, {"timestamp": 1631532495338, "ltp": 1.76, "tv": 16792.59, "trd": [[1.76, 69.17], [1.78, 39.59]], "batb": [[0, 1.76, 17.01], [1, 1.72, 199.71], [2, 1.62, 44.85]], "batl": [[0, 1.78, 15.68], [1, 1.83, 9.92], [2, 1.91, 41.5]]}, {"timestamp": 1631532499279, "ltp": 1.78, "tv": 16799.24, "trd": [[1.78, 46.24]], "batb": NaN, "batl": [[0, 1.78, 11.22]]}, {"timestamp": 1631532504761, "ltp": 1.78, "tv": 16799.24, "trd": NaN, "batb": NaN, "batl": [[1, 1.91, 41.5], [2, 1.93, 39.5]]}, {"timestamp": 1631532507680, "ltp": 1.78, "tv": 16799.24, "trd": NaN, "batb": [[0, 1.76, 28.98]], "batl": [[1, 1.8, 10.03], [2, 1.91, 41.5]]}, {"timestamp": 1631532510660, "ltp": 1.78, "tv": 16821.67, "trd": [[1.78, 68.67]], "batb": [[0, 1.79, 78.94], [1, 1.76, 28.98], [2, 1.72, 199.71]], "batl": [[0, 1.8, 10.03], [1, 1.91, 41.5], [2, 1.93, 39.5]]}, {"timestamp": 1631532523155, "ltp": 1.8, "tv": 16841.73, "trd": [[1.8, 20.06]], "batb": [[0, 1.8, 17.08], [1, 1.79, 78.94], [2, 1.76, 17.01]], "batl": [[0, 2.42, 290.48], [1, 990, 0.01], [2, 1.93, 0]]}, {"timestamp": 1631532523570, "ltp": 1.8, "tv": 16841.73, "trd": NaN, "batb": [[2, 1.62, 44.85]], "batl": NaN}, {"timestamp": 1631532526272, "ltp": 1.8, "tv": 16841.73, "trd": NaN, "batb": [[1, 1.62, 44.85], [2, 1.57, 30.89]], "batl": NaN}, {"timestamp": 1631532526710, "ltp": 1.8, "tv": 16841.73, "trd": NaN, "batb": [[1, 1.61, 45.19]], "batl": [[0, 2.26, 6.75], [1, 2.42, 290.48], [2, 990, 0.01]]}, {"timestamp": 1631532537070, "ltp": 1.8, "tv": 16841.73, "trd": NaN, "batb": NaN, "batl": [[0, 2.14, 7.75], [1, 2.26, 6.75], [2, 2.42, 290.48]]}, {"timestamp": 1631532538310, "ltp": 1.8, "tv": 16841.73, "trd": NaN, "batb": NaN, "batl": [[0, 2.26, 6.75], [1, 2.42, 290.48], [2, 990, 0.01]]}, {"timestamp": 1631532538681, "ltp": 1.8, "tv": 16841.73, "trd": NaN, "batb": NaN, "batl": [[1, 990, 0.01], [2, 990, 0]]}, {"timestamp": 1631532540223, "ltp": 2.08, "tv": 16849.1, "trd": [[2.08, 7.37]], "batb": [[0, 2, 68.73], [1, 1.9, 21.06], [2, 1.8, 17.08]], "batl": [[0, 2.12, 6.07], [1, 2.26, 6.75], [2, 990, 0.01]]}, {"timestamp": 1631532541320, "ltp": 2.04, "tv": 16868.76, "trd": [[2.04, 19.65]], "batb": [[0, 2.04, 22.19], [1, 2, 68.73], [2, 1.9, 21.06]], "batl": NaN}, {"timestamp": 1631532542420, "ltp": 2.04, "tv": 16868.76, "trd": NaN, "batb": NaN, "batl": [[2, 2.82, 234.47]]}, {"timestamp": 1631532545010, "ltp": 2.06, "tv": 16871.82, "trd": [[2.06, 192.3]], "batb": NaN, "batl": NaN}, {"timestamp": 1631532548319, "ltp": 2.04, "tv": 16894.0, "trd": [[2.04, 41.84]], "batb": [[0, 2, 68.73], [1, 1.9, 21.06], [2, 1.84, 28.87]], "batl": NaN}, {"timestamp": 1631532549300, "ltp": 2.04, "tv": 16894.0, "trd": NaN, "batb": [[0, 2.02, 42.34], [1, 2, 68.73], [2, 1.9, 21.06]], "batl": NaN}, {"timestamp": 1631532550394, "ltp": 2.04, "tv": 16894.0, "trd": NaN, "batb": NaN, "batl": [[0, 2.26, 6.75], [1, 2.82, 234.47], [2, 990, 0.01]]}, {"timestamp": 1631532553327, "ltp": 2.06, "tv": 16901.04, "trd": [[2.04, 41.92], [2.06, 199.26]], "batb": NaN, "batl": [[0, 2.12, 13.32], [1, 2.26, 6.75], [2, 2.82, 234.47]]}, {"timestamp": 1631532558619, "ltp": 2.06, "tv": 16901.04, "trd": NaN, "batb": NaN, "batl": [[0, 2.06, 8.76], [1, 2.12, 13.32], [2, 2.26, 6.75]]}, {"timestamp": 1631532560327, "ltp": 2.06, "tv": 16901.04, "trd": NaN, "batb": NaN, "batl": [[0, 2.12, 13.32], [1, 2.26, 6.75], [2, 2.82, 234.47]]}, {"timestamp": 1631532562145, "ltp": 2.02, "tv": 16958.19, "trd": [[2.02, 57.15]], "batb": [[0, 2.02, 13.77]], "batl": NaN}, {"timestamp": 1631532564108, "ltp": 2.02, "tv": 16976.06, "trd": [[2.02, 75.02]], "batb": [[0, 2.02, 4.83]], "batl": [[0, 2.26, 6.75], [1, 2.82, 234.47], [2, 990, 0.01]]}, {"timestamp": 1631532565451, "ltp": 2.02, "tv": 16976.06, "trd": NaN, "batb": [[0, 2.02, 34.04]], "batl": NaN}, {"timestamp": 1631532566543, "ltp": 2.02, "tv": 16976.06, "trd": NaN, "batb": NaN, "batl": [[0, 2.08, 6.98], [1, 2.26, 6.75], [2, 2.82, 234.47]]}, {"timestamp": 1631532568311, "ltp": 2.02, "tv": 16979.51, "trd": [[2.02, 78.47]], "batb": [[0, 2.02, 32.31]], "batl": NaN}, {"timestamp": 1631532569651, "ltp": 2.02, "tv": 16982.75, "trd": [[2.02, 81.71]], "batb": [[0, 2.02, 30.69]], "batl": NaN}, {"timestamp": 1631532574230, "ltp": 2.02, "tv": 16982.75, "trd": NaN, "batb": [[0, 2, 112.75], [1, 1.9, 21.06], [2, 1.81, 30.29]], "batl": NaN}, {"timestamp": 1631532576629, "ltp": 2.02, "tv": 16982.75, "trd": NaN, "batb": NaN, "batl": [[0, 2.26, 6.75], [1, 2.82, 234.47], [2, 990, 0.01]]}, {"timestamp": 1631532579631, "ltp": 2.16, "tv": 16989.33, "trd": [[2.16, 6.58]], "batb": NaN, "batl": NaN}, {"timestamp": 1631532582270, "ltp": 2.16, "tv": 16989.33, "trd": NaN, "batb": [[0, 2.02, 8.75], [1, 2, 112.75], [2, 1.9, 21.06]], "batl": NaN}, {"timestamp": 1631532586763, "ltp": 2.16, "tv": 16989.33, "trd": NaN, "batb": [[0, 2, 112.75], [1, 1.9, 21.06], [2, 1.81, 30.29]], "batl": NaN}, {"timestamp": 1631532592743, "ltp": 2.16, "tv": 16995.78, "trd": [[2.16, 13.03]], "batb": NaN, "batl": [[0, 2.08, 6.69], [1, 2.1, 107.55], [2, 2.26, 6.75]]}, {"timestamp": 1631532594251, "ltp": 2.16, "tv": 16995.78, "trd": NaN, "batb": NaN, "batl": [[1, 2.26, 6.75], [2, 2.82, 234.47]]}, {"timestamp": 1631532599658, "ltp": 2.08, "tv": 17009.16, "trd": [[2.08, 20.75]], "batb": [[0, 2.08, 2.06], [1, 2, 112.75], [2, 1.9, 21.06]], "batl": [[0, 2.26, 6.75], [1, 2.82, 234.47], [2, 990, 0.01]]}, {"timestamp": 1631532607105, "ltp": 2.08, "tv": 17009.16, "trd": NaN, "batb": NaN, "batl": [[0, 2.12, 110], [1, 2.26, 6.75], [2, 2.82, 234.47]]}, {"timestamp": 1631532612922, "ltp": 2.08, "tv": 17013.27, "trd": [[2.08, 24.86]], "batb": [[0, 2.06, 7.04]], "batl": [[0, 2.08, 19.24], [1, 2.12, 123.32], [2, 2.26, 6.75]]}, {"timestamp": 1631532614723, "ltp": 2.06, "tv": 17013.45, "trd": [[2.06, 199.44]], "batb": [[0, 2.06, 6.95]], "batl": NaN}, {"timestamp": 1631532619785, "ltp": 2.08, "tv": 17048.43, "trd": [[2.08, 59.84]], "batb": NaN, "batl": [[0, 2.08, 1.75]]}, {"timestamp": 1631532625315, "ltp": 2.08, "tv": 17048.43, "trd": NaN, "batb": [[0, 2, 112.75], [1, 1.9, 21.06], [2, 1.81, 30.29]], "batl": [[1, 2.12, 110]]}, {"timestamp": 1631532627832, "ltp": 2.08, "tv": 17048.43, "trd": NaN, "batb": [[0, 2.06, 6.95], [1, 2, 112.75], [2, 1.9, 21.06]], "batl": [[1, 2.12, 123.41]]}, {"timestamp": 1631532630719, "ltp": 2.06, "tv": 17062.33, "trd": [[2.06, 213.34]], "batb": [[0, 2, 112.75], [1, 1.9, 21.06], [2, 1.81, 30.29]], "batl": [[0, 2.06, 815.13], [1, 2.08, 1.75], [2, 2.12, 123.41]]}, {"timestamp": 1631532634227, "ltp": 2.06, "tv": 17304.32, "trd": [[2.06, 455.34]], "batb": NaN, "batl": [[0, 2.06, 573.13]]}, {"timestamp": 1631532638137, "ltp": 2.06, "tv": 17312.99, "trd": [[2.06, 464.01]], "batb": NaN, "batl": [[0, 2.06, 564.46]]}, {"timestamp": 1631532639646, "ltp": 2.06, "tv": 17321.49, "trd": [[2.06, 472.5]], "batb": NaN, "batl": [[0, 2.06, 555.97]]}, {"timestamp": 1631532640944, "ltp": 2.06, "tv": 17321.49, "trd": NaN, "batb": NaN, "batl": [[2, 2.12, 110]]}, {"timestamp": 1631532642243, "ltp": 2.04, "tv": 17414.32, "trd": [[2.04, 134.75]], "batb": NaN, "batl": [[0, 2.04, 7.17], [1, 2.06, 555.97], [2, 2.08, 1.75]]}, {"timestamp": 1631532643853, "ltp": 2.04, "tv": 17420.96, "trd": [[2.04, 141.39]], "batb": NaN, "batl": [[0, 2.06, 556.5], [1, 2.08, 8.73], [2, 2.12, 110]]}, {"timestamp": 1631532646248, "ltp": 2.04, "tv": 17420.96, "trd": NaN, "batb": [[0, 2, 299.75]], "batl": NaN}, {"timestamp": 1631532646452, "ltp": 2.04, "tv": 17420.96, "trd": NaN, "batb": [[0, 2, 112.75]], "batl": NaN}, {"timestamp": 1631532649524, "ltp": 2.04, "tv": 17420.96, "trd": NaN, "batb": NaN, "batl": [[2, 2.26, 6.75]]}, {"timestamp": 1631532653936, "ltp": 2.04, "tv": 17420.96, "trd": NaN, "batb": NaN, "batl": [[1, 2.08, 1.75]]}, {"timestamp": 1631532656950, "ltp": 2.04, "tv": 17420.96, "trd": NaN, "batb": NaN, "batl": [[0, 2.06, 563.08]]}, {"timestamp": 1631532665083, "ltp": 2.02, "tv": 17428.88, "trd": [[2.02, 89.63]], "batb": NaN, "batl": [[0, 2.02, 24.08], [1, 2.06, 563.08], [2, 2.08, 1.75]]}, {"timestamp": 1631532666175, "ltp": 2.02, "tv": 17452.96, "trd": [[2.02, 113.71]], "batb": NaN, "batl": [[0, 2.06, 563.08], [1, 2.08, 1.75], [2, 2.26, 6.75]]}, {"timestamp": 1631532667980, "ltp": 2.02, "tv": 17452.96, "trd": NaN, "batb": NaN, "batl": [[0, 2.06, 7.11]]}, {"timestamp": 1631532671192, "ltp": 2.02, "tv": 17608.25, "trd": [[2.02, 269]], "batb": NaN, "batl": [[0, 2.02, 400.68], [1, 2.06, 7.11], [2, 2.08, 1.75]]}, {"timestamp": 1631532675200, "ltp": 2.02, "tv": 17608.25, "trd": NaN, "batb": NaN, "batl": [[0, 2.08, 2.28], [1, 2.26, 6.75], [2, 2.82, 234.47]]}, {"timestamp": 1631532678215, "ltp": 2.0, "tv": 17914.26, "trd": [[2, 306.01]], "batb": [[0, 1.9, 21.06], [1, 1.81, 30.29], [2, 1.78, 31.36]], "batl": [[0, 2, 211.35], [1, 2.04, 7.77], [2, 2.08, 1.75]]}, {"timestamp": 1631532680707, "ltp": 2.0, "tv": 17914.26, "trd": NaN, "batb": NaN, "batl": [[0, 2.04, 7.77], [1, 2.08, 1.75], [2, 2.26, 6.75]]}, {"timestamp": 1631532684184, "ltp": 1.9, "tv": 18127.46, "trd": [[1.9, 106.21], [2, 314.98], [2.02, 367.02]], "batb": [[0, 1.81, 30.29], [1, 1.78, 31.36], [2, 1.77, 407.82]], "batl": [[0, 1.9, 51.24], [1, 2.04, 7.77], [2, 2.08, 1.75]]}, {"timestamp": 1631532687287, "ltp": 2.04, "tv": 18245.35, "trd": [[1.9, 208.69], [2.04, 156.79]], "batb": [[1, 1.77, 407.82], [2, 1.57, 30.89]], "batl": [[0, 2.08, 1.82], [1, 2.26, 6.75], [2, 2.82, 234.47]]}, {"timestamp": 1631532689302, "ltp": 2.04, "tv": 18245.35, "trd": NaN, "batb": [[0, 1.9, 298.8], [1, 1.81, 30.29], [2, 1.77, 407.82]], "batl": [[0, 2.08, 1.75]]}, {"timestamp": 1631532690285, "ltp": 2.04, "tv": 18245.35, "trd": NaN, "batb": [[0, 1.9, 352.58]], "batl": NaN}, {"timestamp": 1631532691318, "ltp": 2.04, "tv": 18245.35, "trd": NaN, "batb": [[0, 1.9, 114.5]], "batl": NaN}, {"timestamp": 1631532692303, "ltp": 2.04, "tv": 18245.35, "trd": NaN, "batb": [[0, 2, 3.65]], "batl": [[0, 2.04, 7.79], [1, 2.08, 1.75], [2, 2.26, 6.75]]}, {"timestamp": 1631532694118, "ltp": 2.04, "tv": 18245.35, "trd": NaN, "batb": [[1, 1.9, 33.11], [2, 1.81, 30.29]], "batl": NaN}, {"timestamp": 1631532695510, "ltp": 2.04, "tv": 18245.35, "trd": NaN, "batb": [[1, 1.81, 30.29], [2, 1.77, 407.82]], "batl": NaN}, {"timestamp": 1631532696543, "ltp": 2.04, "tv": 18260.91, "trd": [[2.04, 172.35]], "batb": NaN, "batl": [[0, 2.08, 1.76], [1, 2.26, 6.75], [2, 2.82, 234.47]]}, {"timestamp": 1631532698301, "ltp": 2.04, "tv": 18260.91, "trd": NaN, "batb": [[0, 1.81, 30.29], [1, 1.77, 407.82], [2, 1.57, 30.89]], "batl": [[0, 2, 90], [1, 2.08, 1.75], [2, 2.26, 6.75]]}, {"timestamp": 1631532700430, "ltp": 2.0, "tv": 18268.36, "trd": [[2, 322.43]], "batb": NaN, "batl": [[0, 2, 82.55], [1, 2.06, 7.2], [2, 2.08, 1.75]]}, {"timestamp": 1631532703336, "ltp": 2.0, "tv": 18270.53, "trd": [[2, 324.6]], "batb": NaN, "batl": [[0, 2, 80.38]]}, {"timestamp": 1631532706342, "ltp": 2.0, "tv": 18350.91, "trd": [[2, 404.98]], "batb": NaN, "batl": [[0, 2.06, 7.2], [1, 2.08, 1.75], [2, 2.26, 6.75]]}, {"timestamp": 1631532707223, "ltp": 2.0, "tv": 18350.91, "trd": NaN, "batb": [[0, 2, 17.04], [1, 1.81, 30.29], [2, 1.77, 407.82]], "batl": [[0, 2.08, 1.75], [1, 2.26, 6.75], [2, 2.82, 234.47]]}, {"timestamp": 1631532708930, "ltp": 2.0, "tv": 18350.91, "trd": NaN, "batb": [[0, 1.81, 30.29], [1, 1.77, 407.82], [2, 1.57, 30.89]], "batl": NaN}, {"timestamp": 1631532709653, "ltp": 2.0, "tv": 18350.91, "trd": NaN, "batb": [[0, 2, 3.89], [1, 1.81, 30.29], [2, 1.77, 407.82]], "batl": [[0, 2.04, 7.33], [1, 2.08, 1.75], [2, 2.26, 6.75]]}, {"timestamp": 1631532710535, "ltp": 2.0, "tv": 18350.91, "trd": NaN, "batb": [[0, 1.81, 30.29], [1, 1.77, 407.82], [2, 1.57, 30.89]], "batl": [[0, 2.08, 1.75], [1, 2.26, 6.75], [2, 2.82, 234.47]]}, {"timestamp": 1631532712340, "ltp": 2.0, "tv": 18350.91, "trd": NaN, "batb": NaN, "batl": [[1, 2.82, 234.47], [2, 990, 0.01]]}, {"timestamp": 1631532715651, "ltp": 2.0, "tv": 18350.91, "trd": NaN, "batb": [[0, 1.8, 31.05]], "batl": NaN}, {"timestamp": 1631532717324, "ltp": 2.0, "tv": 18350.91, "trd": NaN, "batb": NaN, "batl": [[0, 2.06, 248.18], [1, 2.08, 1.75], [2, 2.82, 234.47]]}, {"timestamp": 1631532717533, "ltp": 2.0, "tv": 18350.91, "trd": NaN, "batb": NaN, "batl": [[0, 2.08, 1.75], [1, 2.82, 234.47], [2, 990, 0.01]]}, {"timestamp": 1631532727981, "ltp": 2.0, "tv": 18350.91, "trd": NaN, "batb": [[2, 1.67, 33.42]], "batl": [[0, 1.86, 74.27], [1, 1.88, 29.69], [2, 1.9, 14.69]]}, {"timestamp": 1631532734897, "ltp": 1.8, "tv": 18352.3, "trd": [[1.8, 21.45]], "batb": [[0, 1.8, 30.35]], "batl": NaN}, {"timestamp": 1631532736973, "ltp": 1.8, "tv": 18352.3, "trd": NaN, "batb": [[0, 1.77, 407.82], [1, 1.61, 45.52], [2, 1.57, 30.89]], "batl": [[0, 2, 6.91], [1, 2.08, 1.75], [2, 2.82, 234.47]]}, {"timestamp": 1631532740187, "ltp": 1.8, "tv": 18352.3, "trd": NaN, "batb": [[0, 1.86, 8.12], [1, 1.77, 407.82], [2, 1.61, 45.35]], "batl": [[1, 2.08, 8.69]]}, {"timestamp": 1631532744174, "ltp": 1.86, "tv": 18356.98, "trd": [[1.86, 4.68]], "batb": [[0, 1.86, 5.78]], "batl": NaN}, {"timestamp": 1631532747101, "ltp": 2.0, "tv": 18357.16, "trd": [[2, 405.17]], "batb": NaN, "batl": [[0, 2, 6.81]]}, {"timestamp": 1631532750303, "ltp": 2.0, "tv": 18357.16, "trd": NaN, "batb": NaN, "batl": [[1, 2.02, 8.25], [2, 2.08, 8.69]]}, {"timestamp": 1631532750512, "ltp": 2.0, "tv": 18357.16, "trd": NaN, "batb": NaN, "batl": [[1, 2.08, 8.69], [2, 2.82, 234.47]]}, {"timestamp": 1631532759137, "ltp": 2.0, "tv": 18357.16, "trd": NaN, "batb": [[0, 1.77, 407.82], [1, 1.61, 45.35], [2, 1.57, 30.89]], "batl": NaN}, {"timestamp": 1631532759809, "ltp": 2.0, "tv": 18357.16, "trd": NaN, "batb": [[0, 1.61, 45.35], [1, 1.57, 30.89], [2, 1.21, 766.61]], "batl": [[2, 990, 0.01]]}, {"timestamp": 1631532761036, "ltp": 1.8, "tv": 18360.89, "trd": [[1.8, 25.18]], "batb": [[1, 1.6, 125.36], [2, 1.57, 30.89]], "batl": [[0, 1.66, 15.32], [1, 1.68, 101.86], [2, 1.7, 16.42]]}, {"timestamp": 1631532771149, "ltp": 1.66, "tv": 18391.44, "trd": [[1.66, 42.83]], "batb": NaN, "batl": [[0, 1.68, 101.86], [1, 1.7, 16.42], [2, 1.81, 51.5]]}, {"timestamp": 1631532772036, "ltp": 1.66, "tv": 18391.44, "trd": NaN, "batb": [[0, 1.66, 15.23], [1, 1.61, 45.35], [2, 1.6, 125.36]], "batl": NaN}, {"timestamp": 1631532773337, "ltp": 1.66, "tv": 18391.44, "trd": NaN, "batb": [[0, 1.61, 45.35], [1, 1.6, 125.36], [2, 1.57, 30.89]], "batl": NaN}, {"timestamp": 1631532776249, "ltp": 1.66, "tv": 18391.44, "trd": NaN, "batb": [[1, 1.57, 30.89], [2, 1.55, 426.3]], "batl": [[0, 1.68, 33.22]]}, {"timestamp": 1631532776760, "ltp": 1.66, "tv": 18391.44, "trd": NaN, "batb": [[0, 1.57, 30.89], [1, 1.55, 426.3], [2, 1.45, 67.36]], "batl": [[0, 1.86, 43.75], [1, 2, 11.42], [2, 2.08, 1.75]]}, {"timestamp": 1631532778326, "ltp": 1.66, "tv": 18391.44, "trd": NaN, "batb": [[0, 1.68, 22.42], [1, 1.57, 30.89], [2, 1.55, 426.3]], "batl": NaN}, {"timestamp": 1631532779157, "ltp": 1.66, "tv": 18391.44, "trd": NaN, "batb": [[0, 1.57, 30.89], [1, 1.55, 426.3], [2, 1.45, 67.36]], "batl": NaN}, {"timestamp": 1631532788061, "ltp": 1.66, "tv": 18391.44, "trd": NaN, "batb": [[0, 1.72, 146.33], [1, 1.69, 23.66], [2, 1.6, 34.88]], "batl": [[0, 1.8, 31.01], [1, 1.82, 15.33], [2, 1.83, 17.94]]}, {"timestamp": 1631532788838, "ltp": 1.66, "tv": 18391.44, "trd": NaN, "batb": [[0, 1.74, 34.81], [1, 1.72, 146.33], [2, 1.69, 23.66]], "batl": NaN}, {"timestamp": 1631532794340, "ltp": 1.74, "tv": 18399.35, "trd": [[1.74, 0.47], [1.78, 76.11]], "batb": [[0, 1.74, 34.58]], "batl": NaN}, {"timestamp": 1631532794544, "ltp": 1.8, "tv": 18435.23, "trd": [[1.8, 61.06]], "batb": NaN, "batl": [[0, 1.8, 13.07]]}, {"timestamp": 1631532799073, "ltp": 1.8, "tv": 18435.23, "trd": NaN, "batb": [[0, 1.62, 421.