{"info": {"id": "1.187605875", "eventId": "30896916", "eventName": "Match Odds", "marketType": "MATCH_ODDS", "openDate": 1631543757612, "name": "Al Pisareva v Motlagh", "numberOfActiveRunner": 2, "countryCode": "", "sport": "TENNIS", "venue": "", "volume": {"total": 2191.43, "preMatch": 115.85, "inPlay": 2075.58}, "winner": {"id": 11214864, "name": "A Pisareva", "status": "WINNER", "position": 1}, "delay": 3}, "runners": [{"id": 11214864, "name": "A Pisareva", "status": "WINNER", "position": 1, "inPlayOdds": 1.23, "inPlayTime": 1631543948031, "avgPrematch": 0, "closedOdds": 1.01, "maxPrematch": -100, "minPrematch": 1001, "maxInPlay": 1.45, "minInPlay": 1.01, "inPlayIndex": 0, "lengthOdds": 710, "lengthOddsPrematch": 0, "lengthOddsInPlay": 710, "tradedVolume": 2145.34, "preMatchVolume": 72.06, "inPlayVolume": 2073.28}, {"id": 40752182, "name": "S Motlagh", "status": "LOSER", "position": 2, "inPlayOdds": 3.6, "inPlayTime": 1631544853595, "avgPrematch": 0, "closedOdds": 13.5, "maxPrematch": -100, "minPrematch": 1001, "maxInPlay": 13.5, "minInPlay": 3.6, "inPlayIndex": 0, "lengthOdds": 167, "lengthOddsPrematch": 0, "lengthOddsInPlay": 167, "tradedVolume": 46.09, "preMatchVolume": 43.79, "inPlayVolume": 2.3}], "marketUpdates": [{"timestamp": 1631522345145000000, "openDate": "2021-09-13T16:30:00.000Z", "status": "OPEN", "betDelay": 0, "inPlay": false, "complete": true}, {"timestamp": 1631543531373000000, "openDate": "2021-09-13T14:30:00.000Z", "status": "OPEN", "betDelay": 0, "inPlay": false, "complete": true}, {"timestamp": 1631543757612000000, "openDate": "2021-09-13T14:30:00.000Z", "status": "OPEN", "betDelay": 3, "inPlay": true, "complete": true}, {"timestamp": 1631548558470000000, "openDate": "2021-09-13T14:30:00.000Z", "status": "SUSPENDED", "betDelay": 3, "inPlay": true, "complete": true}, {"timestamp": 1631548596427000000, "openDate": "2021-09-13T14:30:00.000Z", "status": "CLOSED", "betDelay": 3, "inPlay": true, "complete": true}], "odds": [{"runnerId": 11214864, "odds": [{"timestamp": 1631543948031, "ltp": 1.23, "tv": 72.06, "trd": [[1.23, 72.06]], "batb": [[0, 1.23, 144.59], [1, 1.22, 192.32], [2, 1.2, 108.4]], "batl": [[0, 1.24, 247.23], [1, 1.26, 176.19], [2, 1.27, 142.01]]}, {"timestamp": 1631543951280, "ltp": 1.23, "tv": 72.06, "trd": NaN, "batb": [[0, 1.23, 156.53]], "batl": [[1, 1.26, 199.73]]}, {"timestamp": 1631543952947, "ltp": 1.23, "tv": 72.06, "trd": NaN, "batb": [[0, 1.01, 25], [1, 1.22, 0], [2, 1.2, 0]], "batl": [[0, 1.68, 5.96], [1, 1.7, 236.76], [2, 1.8, 264.01]]}, {"timestamp": 1631543958626, "ltp": 1.23, "tv": 72.06, "trd": NaN, "batb": [[0, 1.22, 239.02], [1, 1.21, 173.34], [2, 1.01, 25]], "batl": [[0, 1.25, 148.24], [1, 1.26, 149.81], [2, 1.68, 5.96]]}, {"timestamp": 1631543965745, "ltp": 1.23, "tv": 72.06, "trd": NaN, "batb": [[0, 1.01, 25], [1, 1.21, 0], [2, 1.01, 0]], "batl": [[0, 1.68, 5.96], [1, 1.7, 236.76], [2, 1.8, 264.01]]}, {"timestamp": 1631543968735, "ltp": 1.23, "tv": 72.06, "trd": NaN, "batb": [[0, 1.2, 188.25], [1, 1.19, 229.75], [2, 1.01, 25]], "batl": [[0, 1.29, 133.92], [1, 1.3, 126.31], [2, 1.68, 5.96]]}, {"timestamp": 1631543981375, "ltp": 1.23, "tv": 72.06, "trd": NaN, "batb": NaN, "batl": [[0, 1.68, 5.96], [1, 1.7, 236.76], [2, 1.8, 264.01]]}, {"timestamp": 1631543984094, "ltp": 1.23, "tv": 72.06, "trd": NaN, "batb": NaN, "batl": [[0, 1.21, 29.54], [1, 1.24, 757.25], [2, 1.68, 5.96]]}, {"timestamp": 1631543984358, "ltp": 1.23, "tv": 72.06, "trd": NaN, "batb": NaN, "batl": [[1, 1.22, 71.73], [2, 1.23, 175.41]]}, {"timestamp": 1631543988185, "ltp": 1.2, "tv": 116.78, "trd": [[1.2, 44.72]], "batb": [[0, 1.2, 165.89]], "batl": NaN}, {"timestamp": 1631543991486, "ltp": 1.2, "tv": 116.78, "trd": NaN, "batb": [[0, 1.2, 173.3]], "batl": [[1, 1.22, 86.44]]}, {"timestamp": 1631544021638, "ltp": 1.2, "tv": 116.78, "trd": NaN, "batb": [[0, 1.01, 25], [1, 1.19, 0], [2, 1.01, 0]], "batl": [[1, 1.24, 757.25], [2, 1.68, 5.96]]}, {"timestamp": 1631544024551, "ltp": 1.2, "tv": 116.78, "trd": NaN, "batb": [[0, 1.18, 139.31], [1, 1.17, 260.11], [2, 1.01, 25]], "batl": [[2, 1.26, 154.03]]}, {"timestamp": 1631544051873, "ltp": 1.2, "tv": 116.78, "trd": NaN, "batb": NaN, "batl": [[0, 1.26, 154.03], [1, 1.27, 143.39], [2, 1.68, 5.96]]}, {"timestamp": 1631544066595, "ltp": 1.2, "tv": 116.78, "trd": NaN, "batb": [[0, 1.01, 25], [1, 1.17, 0], [2, 1.01, 0]], "batl": NaN}, {"timestamp": 1631544069580, "ltp": 1.2, "tv": 116.78, "trd": NaN, "batb": [[0, 1.23, 208.13], [1, 1.22, 194.17], [2, 1.2, 150.52]], "batl": [[0, 1.24, 199.63], [1, 1.26, 154.03], [2, 1.27, 143.39]]}, {"timestamp": 1631544085818, "ltp": 1.2, "tv": 116.78, "trd": NaN, "batb": [[0, 1.16, 583.98], [1, 1.01, 25], [2, 1.2, 0]], "batl": [[0, 1.58, 659.44], [1, 1.68, 5.96], [2, 1.7, 236.76]]}, {"timestamp": 1631544092130, "ltp": 1.2, "tv": 116.78, "trd": NaN, "batb": [[0, 1.24, 163.23], [1, 1.23, 182.94], [2, 1.16, 583.98]], "batl": [[0, 1.27, 173.56], [1, 1.28, 136.83], [2, 1.58, 659.44]]}, {"timestamp": 1631544096637, "ltp": 1.2, "tv": 116.78, "trd": NaN, "batb": [[0, 1.16, 583.98], [1, 1.01, 25], [2, 1.16, 0]], "batl": [[0, 1.58, 659.44], [1, 1.68, 5.96], [2, 1.7, 236.76]]}, {"timestamp": 1631544099519, "ltp": 1.2, "tv": 116.78, "trd": NaN, "batb": [[0, 1.21, 73.9], [1, 1.2, 213.14], [2, 1.16, 583.98]], "batl": [[0, 1.3, 99.68], [1, 1.31, 122.22], [2, 1.58, 659.44]]}, {"timestamp": 1631544102751, "ltp": 1.2, "tv": 116.78, "trd": NaN, "batb": [[0, 1.16, 583.98], [1, 1.01, 25], [2, 1.16, 0]], "batl": NaN}, {"timestamp": 1631544104833, "ltp": 1.2, "tv": 116.78, "trd": NaN, "batb": [[0, 1.01, 25], [1, 1.01, 0]], "batl": NaN}, {"timestamp": 1631544105753, "ltp": 1.2, "tv": 116.78, "trd": NaN, "batb": [[0, 1.27, 184.44], [1, 1.26, 158.18], [2, 1.24, 189.88]], "batl": [[0, 1.28, 181.47], [1, 1.3, 99.68], [2, 1.31, 122.22]]}, {"timestamp": 1631544130379, "ltp": 1.2, "tv": 116.78, "trd": NaN, "batb": [[2, 1.18, 557.21]], "batl": [[0, 1.3, 99.68], [1, 1.31, 122.22], [2, 1.58, 659.44]]}, {"timestamp": 1631544131581, "ltp": 1.2, "tv": 116.78, "trd": NaN, "batb": [[0, 1.18, 557.21], [1, 1.01, 25], [2, 1.18, 0]], "batl": [[0, 1.58, 659.44], [1, 1.68, 5.96], [2, 1.7, 236.76]]}, {"timestamp": 1631544134598, "ltp": 1.2, "tv": 116.78, "trd": NaN, "batb": [[0, 1.24, 202.02], [1, 1.23, 183.94], [2, 1.18, 557.21]], "batl": [[0, 1.35, 139.82], [1, 1.36, 100.97], [2, 1.58, 659.44]]}, {"timestamp": 1631544136679, "ltp": 1.2, "tv": 116.78, "trd": NaN, "batb": [[0, 1.18, 557.21], [1, 1.01, 25], [2, 1.18, 0]], "batl": NaN}, {"timestamp": 1631544138394, "ltp": 1.2, "tv": 116.78, "trd": NaN, "batb": [[0, 1.01, 25], [1, 1.01, 0]], "batl": NaN}, {"timestamp": 1631544139700, "ltp": 1.2, "tv": 116.78, "trd": NaN, "batb": [[0, 1.32, 68.41], [1, 1.31, 138], [2, 1.01, 25]], "batl": NaN}, {"timestamp": 1631544142192, "ltp": 1.2, "tv": 116.78, "trd": NaN, "batb": [[2, 1.2, 538.09]], "batl": NaN}, {"timestamp": 1631544154591, "ltp": 1.2, "tv": 116.78, "trd": NaN, "batb": [[0, 1.2, 538.09], [1, 1.01, 25], [2, 1.2, 0]], "batl": [[0, 1.58, 659.44], [1, 1.68, 5.96], [2, 1.7, 236.76]]}, {"timestamp": 1631544160297, "ltp": 1.2, "tv": 116.78, "trd": NaN, "batb": [[0, 1.32, 149.81], [1, 1.31, 126.69], [2, 1.2, 538.09]], "batl": [[0, 1.35, 63.69], [1, 1.36, 102.01], [2, 1.58, 659.44]]}, {"timestamp": 1631544163113, "ltp": 1.2, "tv": 116.78, "trd": NaN, "batb": [[0, 1.2, 538.09], [1, 1.01, 25], [2, 1.2, 0]], "batl": [[0, 1.58, 659.44], [1, 1.36, 0], [2, 1.58, 0]]}, {"timestamp": 1631544166022, "ltp": 1.2, "tv": 116.78, "trd": NaN, "batb": [[0, 1.29, 131.78], [1, 1.28, 143.43], [2, 1.2, 538.09]], "batl": [[0, 1.38, 70.37], [1, 1.39, 92.11], [2, 1.58, 659.44]]}, {"timestamp": 1631544168947, "ltp": 1.2, "tv": 116.78, "trd": NaN, "batb": NaN, "batl": [[0, 1.58, 659.44], [1, 1.39, 0], [2, 1.58, 0]]}, {"timestamp": 1631544171928, "ltp": 1.2, "tv": 116.78, "trd": NaN, "batb": [[1, 1.28, 164.13], [2, 1.25, 132.41]], "batl": [[0, 1.3, 22.4], [1, 1.32, 118.32], [2, 1.33, 112.86]]}, {"timestamp": 1631544194996, "ltp": 1.2, "tv": 116.78, "trd": NaN, "batb": [[1, 1.28, 143.43], [2, 1.2, 538.09]], "batl": [[0, 1.32, 118.32], [1, 1.33, 112.86], [2, 1.58, 659.44]]}, {"timestamp": 1631544195309, "ltp": 1.2, "tv": 116.78, "trd": NaN, "batb": [[0, 1.2, 538.09], [1, 1.01, 25], [2, 1.2, 0]], "batl": [[0, 1.58, 659.44], [1, 1.33, 0], [2, 1.58, 0]]}, {"timestamp": 1631544201914, "ltp": 1.2, "tv": 116.78, "trd": NaN, "batb": [[0, 1.3, 114.34], [1, 1.29, 137.03], [2, 1.2, 538.09]], "batl": [[0, 1.33, 121.1], [1, 1.34, 108.72], [2, 1.58, 659.44]]}, {"timestamp": 1631544208818, "ltp": 1.2, "tv": 116.78, "trd": NaN, "batb": [[0, 1.2, 538.09], [1, 1.01, 25], [2, 1.2, 0]], "batl": [[0, 1.58, 659.44], [1, 1.34, 0], [2, 1.58, 0]]}, {"timestamp": 1631544211734, "ltp": 1.2, "tv": 116.78, "trd": NaN, "batb": [[0, 1.26, 101.24], [1, 1.25, 164.01], [2, 1.2, 538.09]], "batl": [[0, 1.37, 121.31], [1, 1.38, 94.56], [2, 1.58, 659.44]]}, {"timestamp": 1631544219137, "ltp": 1.2, "tv": 116.78, "trd": NaN, "batb": NaN, "batl": [[0, 1.58, 659.44], [1, 1.38, 0], [2, 1.58, 0]]}, {"timestamp": 1631544220454, "ltp": 1.2, "tv": 116.78, "trd": NaN, "batb": [[2, 1.01, 25]], "batl": NaN}, {"timestamp": 1631544222034, "ltp": 1.2, "tv": 116.78, "trd": NaN, "batb": NaN, "batl": [[0, 1.28, 59.94], [1, 1.29, 133.38], [2, 1.58, 659.44]]}, {"timestamp": 1631544223958, "ltp": 1.2, "tv": 116.78, "trd": NaN, "batb": [[2, 1.16, 583.98]], "batl": NaN}, {"timestamp": 1631544246899, "ltp": 1.2, "tv": 116.78, "trd": NaN, "batb": [[0, 1.16, 583.98], [1, 1.01, 25], [2, 1.16, 0]], "batl": [[0, 1.58, 659.44], [1, 1.29, 0], [2, 1.58, 0]]}, {"timestamp": 1631544249772, "ltp": 1.2, "tv": 116.78, "trd": NaN, "batb": [[0, 1.21, 235.85], [1, 1.2, 179.97], [2, 1.16, 583.98]], "batl": [[0, 1.35, 66.45], [1, 1.36, 101.98], [2, 1.58, 659.44]]}, {"timestamp": 1631544260292, "ltp": 1.2, "tv": 116.78, "trd": NaN, "batb": [[0, 1.16, 583.98], [1, 1.01, 25], [2, 1.16, 0]], "batl": NaN}, {"timestamp": 1631544262003, "ltp": 1.2, "tv": 116.78, "trd": NaN, "batb": [[0, 1.01, 25], [1, 1.01, 0]], "batl": NaN}, {"timestamp": 1631544262999, "ltp": 1.2, "tv": 116.78, "trd": NaN, "batb": [[0, 1.31, 14.36], [1, 1.01, 25]], "batl": [[0, 1.33, 238.78], [1, 1.35, 66.45], [2, 1.36, 101.98]]}, {"timestamp": 1631544263207, "ltp": 1.2, "tv": 116.78, "trd": NaN, "batb": [[0, 1.32, 146.85], [1, 1.31, 141], [2, 1.01, 25]], "batl": NaN}, {"timestamp": 1631544266293, "ltp": 1.2, "tv": 116.78, "trd": NaN, "batb": [[2, 1.18, 557.21]], "batl": NaN}, {"timestamp": 1631544293830, "ltp": 1.2, "tv": 116.78, "trd": NaN, "batb": [[0, 1.18, 557.21], [1, 1.01, 25], [2, 1.18, 0]], "batl": [[0, 1.58, 659.44], [1, 1.35, 0], [2, 1.36, 0]]}, {"timestamp": 1631544296741, "ltp": 1.2, "tv": 116.78, "trd": NaN, "batb": [[0, 1.28, 117.83], [1, 1.27, 149.69], [2, 1.18, 557.21]], "batl": [[0, 1.4, 57.84], [1, 1.41, 86.55], [2, 1.58, 659.44]]}, {"timestamp": 1631544297836, "ltp": 1.2, "tv": 116.78, "trd": NaN, "batb": [[0, 1.18, 557.21], [1, 1.01, 25], [2, 1.18, 0]], "batl": NaN}, {"timestamp": 1631544298453, "ltp": 1.2, "tv": 116.78, "trd": NaN, "batb": [[0, 1.01, 25], [1, 1.01, 0]], "batl": NaN}, {"timestamp": 1631544301064, "ltp": 1.37, "tv": 324.82, "trd": [[1.37, 208.04]], "batb": [[0, 1.36, 104.27], [1, 1.32, 171.24], [2, 1.01, 25]], "batl": [[0, 1.37, 49.06], [1, 1.4, 57.84], [2, 1.41, 86.55]]}, {"timestamp": 1631544302652, "ltp": 1.37, "tv": 324.82, "trd": NaN, "batb": [[2, 1.2, 538.09]], "batl": NaN}, {"timestamp": 1631544304163, "ltp": 1.37, "tv": 324.82, "trd": NaN, "batb": [[0, 1.36, 139.03], [1, 1.35, 109.42], [2, 1.32, 171.24]], "batl": [[1, 1.4, 125.91]]}, {"timestamp": 1631544311675, "ltp": 1.37, "tv": 324.82, "trd": NaN, "batb": [[0, 1.2, 538.09], [1, 1.01, 7], [2, 1.32, 0]], "batl": [[0, 1.58, 659.44], [1, 1.4, 0], [2, 1.41, 0]]}, {"timestamp": 1631544314553, "ltp": 1.37, "tv": 324.82, "trd": NaN, "batb": [[0, 1.32, 69.08], [1, 1.31, 126.48], [2, 1.2, 538.09]], "batl": [[0, 1.45, 87.04], [1, 1.46, 74.92], [2, 1.58, 659.44]]}, {"timestamp": 1631544318170, "ltp": 1.37, "tv": 324.82, "trd": NaN, "batb": [[0, 1.2, 538.09], [1, 1.01, 7], [2, 1.2, 0]], "batl": NaN}, {"timestamp": 1631544319667, "ltp": 1.37, "tv": 324.82, "trd": NaN, "batb": [[0, 1.01, 7], [1, 1.01, 0]], "batl": NaN}, {"timestamp": 1631544321071, "ltp": 1.37, "tv": 324.82, "trd": NaN, "batb": [[0, 1.41, 125.58], [1, 1.4, 102.2], [2, 1.01, 7]], "batl": NaN}, {"timestamp": 1631544323974, "ltp": 1.37, "tv": 324.82, "trd": NaN, "batb": [[2, 1.23, 523.51]], "batl": NaN}, {"timestamp": 1631544338886, "ltp": 1.37, "tv": 324.82, "trd": NaN, "batb": [[0, 1.23, 523.51], [1, 1.01, 7], [2, 1.23, 0]], "batl": [[0, 1.58, 659.44], [1, 1.46, 0], [2, 1.58, 0]]}, {"timestamp": 1631544341791, "ltp": 1.37, "tv": 324.82, "trd": NaN, "batb": [[0, 1.37, 85.16], [1, 1.36, 104.89], [2, 1.23, 523.51]], "batl": [[0, 1.5, 83.39], [1, 1.51, 65.41], [2, 1.58, 659.44]]}, {"timestamp": 1631544342310, "ltp": 1.37, "tv": 324.82, "trd": NaN, "batb": [[0, 1.23, 523.51], [1, 1.01, 7], [2, 1.23, 0]], "batl": [[0, 1.58, 659.44], [1, 1.51, 0], [2, 1.58, 0]]}, {"timestamp": 1631544345185, "ltp": 1.37, "tv": 324.82, "trd": NaN, "batb": [[0, 1.4, 134.82], [1, 1.39, 95.11], [2, 1.23, 523.51]], "batl": [[0, 1.44, 87.61], [1, 1.45, 77.1], [2, 1.58, 659.44]]}, {"timestamp": 1631544349111, "ltp": 1.37, "tv": 324.82, "trd": NaN, "batb": [[0, 1.23, 523.51], [1, 1.01, 7], [2, 1.23, 0]], "batl": [[0, 1.58, 659.44], [1, 1.45, 0], [2, 1.58, 0]]}, {"timestamp": 1631544351981, "ltp": 1.37, "tv": 324.82, "trd": NaN, "batb": [[0, 1.37, 85.16], [1, 1.36, 104.89], [2, 1.23, 523.51]], "batl": [[0, 1.5, 83.39], [1, 1.51, 65.41], [2, 1.58, 659.44]]}, {"timestamp": 1631544364505, "ltp": 1.37, "tv": 324.82, "trd": NaN, "batb": NaN, "batl": [[0, 1.58, 659.44], [1, 1.51, 0], [2, 1.58, 0]]}, {"timestamp": 1631544366283, "ltp": 1.37, "tv": 324.82, "trd": NaN, "batb": [[2, 1.01, 7]], "batl": NaN}, {"timestamp": 1631544367485, "ltp": 1.37, "tv": 324.82, "trd": NaN, "batb": [[1, 1.36, 118.97]], "batl": [[0, 1.38, 17.77], [1, 1.4, 77.99], [2, 1.41, 87.07]]}, {"timestamp": 1631544370505, "ltp": 1.37, "tv": 324.82, "trd": NaN, "batb": [[2, 1.2, 538.09]], "batl": NaN}, {"timestamp": 1631544391738, "ltp": 1.37, "tv": 324.82, "trd": NaN, "batb": [[0, 1.2, 538.09], [1, 1.01, 7], [2, 1.2, 0]], "batl": [[0, 1.58, 659.44], [1, 1.4, 0], [2, 1.41, 0]]}, {"timestamp": 1631544394605, "ltp": 1.37, "tv": 324.82, "trd": NaN, "batb": [[0, 1.31, 183.18], [1, 1.3, 133.68], [2, 1.2, 538.09]], "batl": [[0, 1.46, 64.58], [1, 1.47, 73.02], [2, 1.58, 659.44]]}, {"timestamp": 1631544399515, "ltp": 1.37, "tv": 324.82, "trd": NaN, "batb": NaN, "batl": [[0, 1.58, 659.44], [1, 1.47, 0], [2, 1.58, 0]]}, {"timestamp": 1631544402441, "ltp": 1.37, "tv": 324.82, "trd": NaN, "batb": [[0, 1.31, 196.73]], "batl": [[0, 1.33, 24.43], [1, 1.35, 153.97], [2, 1.36, 101.72]]}, {"timestamp": 1631544423247, "ltp": 1.37, "tv": 324.82, "trd": NaN, "batb": [[0, 1.2, 538.09], [1, 1.01, 7], [2, 1.2, 0]], "batl": [[0, 1.58, 659.44], [1, 1.35, 0], [2, 1.36, 0]]}, {"timestamp": 1631544426265, "ltp": 1.37, "tv": 324.82, "trd": NaN, "batb": [[0, 1.26, 94.48], [1, 1.25, 165.4], [2, 1.2, 538.09]], "batl": [[0, 1.42, 136.75], [1, 1.43, 81.32], [2, 1.58, 659.44]]}, {"timestamp": 1631544432590, "ltp": 1.37, "tv": 324.82, "trd": NaN, "batb": [[0, 1.2, 538.09], [1, 1.01, 7], [2, 1.2, 0]], "batl": NaN}, {"timestamp": 1631544434157, "ltp": 1.37, "tv": 324.82, "trd": NaN, "batb": [[0, 1.01, 7], [1, 1.01, 0]], "batl": NaN}, {"timestamp": 1631544435550, "ltp": 1.37, "tv": 324.82, "trd": NaN, "batb": [[0, 1.38, 103.49], [1, 1.37, 101.48], [2, 1.34, 195.69]], "batl": [[0, 1.39, 15.57], [1, 1.4, 79.33], [2, 1.42, 136.75]]}, {"timestamp": 1631544447912, "ltp": 1.37, "tv": 324.82, "trd": NaN, "batb": [[2, 1.22, 530.12]], "batl": [[0, 1.42, 136.75], [1, 1.43, 81.32], [2, 1.58, 659.44]]}, {"timestamp": 1631544448181, "ltp": 1.37, "tv": 324.82, "trd": NaN, "batb": [[0, 1.22, 530.12], [1, 1.01, 7], [2, 1.22, 0]], "batl": [[0, 1.58, 659.44], [1, 1.43, 0], [2, 1.58, 0]]}, {"timestamp": 1631544451096, "ltp": 1.37, "tv": 324.82, "trd": NaN, "batb": [[0, 1.31, 181.16], [1, 1.3, 133.64], [2, 1.22, 530.12]], "batl": [[0, 1.49, 70.55], [1, 1.5, 67.26], [2, 1.58, 659.44]]}, {"timestamp": 1631544452825, "ltp": 1.37, "tv": 324.82, "trd": NaN, "batb": [[0, 1.22, 530.12], [1, 1.01, 7], [2, 1.22, 0]], "batl": [[0, 1.58, 659.44], [1, 1.5, 0], [2, 1.58, 0]]}, {"timestamp": 1631544455690, "ltp": 1.37, "tv": 324.82, "trd": NaN, "batb": [[0, 1.37, 69.35], [1, 1.36, 104.7], [2, 1.22, 530.12]], "batl": [[0, 1.4, 92.93], [1, 1.41, 86.92], [2, 1.58, 659.44]]}, {"timestamp": 1631544458820, "ltp": 1.37, "tv": 324.82, "trd": NaN, "batb": [[0, 1.22, 530.12], [1, 1.01, 7], [2, 1.22, 0]], "batl": [[0, 1.58, 659.44], [1, 1.41, 0], [2, 1.58, 0]]}, {"timestamp": 1631544461725, "ltp": 1.37, "tv": 324.82, "trd": NaN, "batb": [[0, 1.31, 181.16], [1, 1.3, 133.64], [2, 1.22, 530.12]], "batl": [[0, 1.49, 70.55], [1, 1.5, 67.26], [2, 1.58, 659.44]]}, {"timestamp": 1631544485553, "ltp": 1.37, "tv": 324.82, "trd": NaN, "batb": NaN, "batl": [[0, 1.58, 659.44], [1, 1.5, 0], [2, 1.58, 0]]}, {"timestamp": 1631544486862, "ltp": 1.37, "tv": 324.82, "trd": NaN, "batb": [[2, 1.01, 7]], "batl": NaN}, {"timestamp": 1631544488545, "ltp": 1.37, "tv": 324.82, "trd": NaN, "batb": [[0, 1.31, 195.1]], "batl": [[0, 1.33, 24.06], [1, 1.34, 223.53], [2, 1.35, 155.81]]}, {"timestamp": 1631544490778, "ltp": 1.37, "tv": 324.82, "trd": NaN, "batb": [[2, 1.18, 557.21]], "batl": NaN}, {"timestamp": 1631544513594, "ltp": 1.37, "tv": 324.82, "trd": NaN, "batb": [[0, 1.18, 557.21], [1, 1.03, 497.67], [2, 1.01, 479.65]], "batl": [[0, 1.58, 659.44], [1, 44, 7.23], [2, 1.35, 0]]}, {"timestamp": 1631544517098, "ltp": 1.37, "tv": 324.82, "trd": NaN, "batb": [[0, 1.26, 92.24], [1, 1.25, 165.35], [2, 1.18, 557.21]], "batl": [[0, 1.41, 54.26], [1, 1.42, 84.65], [2, 1.58, 659.44]]}, {"timestamp": 1631544521723, "ltp": 1.37, "tv": 324.82, "trd": NaN, "batb": [[0, 1.18, 557.21], [1, 1.05, 477.76], [2, 1.03, 497.67]], "batl": NaN}, {"timestamp": 1631544522873, "ltp": 1.37, "tv": 324.82, "trd": NaN, "batb": [[0, 1.05, 477.76], [1, 1.03, 497.67], [2, 1.01, 479.65]], "batl": NaN}, {"timestamp": 1631544523398, "ltp": 1.37, "tv": 324.82, "trd": NaN, "batb": [[0, 1.34, 195.68], [1, 1.05, 477.76], [2, 1.03, 497.67]], "batl": [[0, 1.39, 15.6], [1, 1.4, 79.52], [2, 1.41, 54.26]]}, {"timestamp": 1631544525112, "ltp": 1.37, "tv": 324.82, "trd": NaN, "batb": [[0, 1.38, 101.56], [1, 1.37, 101.46], [2, 1.34, 195.68]], "batl": NaN}, {"timestamp": 1631544542129, "ltp": 1.37, "tv": 324.82, "trd": NaN, "batb": [[0, 1.22, 530.12], [1, 1.05, 477.76], [2, 1.03, 497.67]], "batl": [[0, 1.58, 659.44], [1, 44, 7.23], [2, 820, 0.14]]}, {"timestamp": 1631544542542, "ltp": 1.37, "tv": 324.82, "trd": NaN, "batb": NaN, "batl": [[2, 810, 0.07]]}, {"timestamp": 1631544545045, "ltp": 1.37, "tv": 324.82, "trd": NaN, "batb": [[0, 1.31, 179.08], [1, 1.3, 133.6], [2, 1.22, 530.12]], "batl": [[0, 1.49, 72.38], [1, 1.5, 67.24], [2, 1.58, 659.44]]}, {"timestamp": 1631544549427, "ltp": 1.37, "tv": 324.82, "trd": NaN, "batb": NaN, "batl": [[0, 1.58, 659.44], [1, 44, 7.23], [2, 810, 0.07]]}, {"timestamp": 1631544550720, "ltp": 1.37, "tv": 324.82, "trd": NaN, "batb": [[2, 1.05, 477.76]], "batl": NaN}, {"timestamp": 1631544552121, "ltp": 1.37, "tv": 324.82, "trd": NaN, "batb": [[0, 1.31, 193.3]], "batl": [[0, 1.33, 23.8], [1, 1.34, 222.1], [2, 1.58, 659.44]]}, {"timestamp": 1631544552432, "ltp": 1.37, "tv": 324.82, "trd": NaN, "batb": NaN, "batl": [[2, 1.35, 157.71]]}, {"timestamp": 1631544554420, "ltp": 1.37, "tv": 324.82, "trd": NaN, "batb": [[2, 1.18, 557.21]], "batl": NaN}, {"timestamp": 1631544564974, "ltp": 1.37, "tv": 324.82, "trd": NaN, "batb": [[0, 1.31, 179.08]], "batl": [[0, 1.35, 157.71], [1, 1.36, 101.68], [2, 1.58, 659.44]]}, {"timestamp": 1631544565240, "ltp": 1.37, "tv": 324.82, "trd": NaN, "batb": [[0, 1.18, 557.21], [1, 1.05, 477.76], [2, 1.03, 497.67]], "batl": [[0, 1.58, 659.44], [1, 44, 7.23], [2, 810, 0.07]]}, {"timestamp": 1631544568248, "ltp": 1.37, "tv": 324.82, "trd": NaN, "batb": [[0, 1.26, 89.95], [1, 1.25, 165.3], [2, 1.18, 557.21]], "batl": [[0, 1.41, 56.13], [1, 1.42, 84.63], [2, 1.58, 659.44]]}, {"timestamp": 1631544582476, "ltp": 1.37, "tv": 324.82, "trd": NaN, "batb": [[0, 1.18, 557.21], [1, 1.05, 477.76], [2, 1.03, 497.67]], "batl": NaN}, {"timestamp": 1631544584199, "ltp": 1.37, "tv": 324.82, "trd": NaN, "batb": [[0, 1.05, 477.76], [1, 1.03, 497.67], [2, 1.01, 479.65]], "batl": NaN}, {"timestamp": 1631544585511, "ltp": 1.37, "tv": 324.82, "trd": NaN, "batb": [[0, 1.38, 99.59], [1, 1.37, 101.42], [2, 1.34, 195.61]], "batl": [[0, 1.39, 15.63], [1, 1.4, 79.68], [2, 1.41, 56.13]]}, {"timestamp": 1631544608817, "ltp": 1.37, "tv": 324.82, "trd": NaN, "batb": [[0, 1.22, 530.12], [1, 1.05, 477.76], [2, 1.03, 497.67]], "batl": [[0, 1.58, 659.44], [1, 44, 7.23], [2, 810, 0.07]]}, {"timestamp": 1631544611829, "ltp": 1.37, "tv": 324.82, "trd": NaN, "batb": [[0, 1.31, 176.94], [1, 1.3, 133.58], [2, 1.22, 530.12]], "batl": [[0, 1.49, 74.26], [1, 1.5, 67.22], [2, 1.58, 659.44]]}, {"timestamp": 1631544612622, "ltp": 1.37, "tv": 324.82, "trd": NaN, "batb": [[0, 1.22, 530.12], [1, 1.05, 477.76], [2, 1.03, 497.67]], "batl": [[0, 1.58, 659.44], [1, 44, 7.23], [2, 810, 0.07]]}, {"timestamp": 1631544615538, "ltp": 1.37, "tv": 324.82, "trd": NaN, "batb": [[0, 1.37, 65.43], [1, 1.36, 104.64], [2, 1.22, 530.12]], "batl": [[0, 1.4, 96.64], [1, 1.41, 86.88], [2, 1.58, 659.44]]}, {"timestamp": 1631544619029, "ltp": 1.37, "tv": 324.82, "trd": NaN, "batb": [[0, 1.22, 530.12], [1, 1.05, 477.76], [2, 1.03, 497.67]], "batl": [[0, 1.58, 659.44], [1, 44, 7.23], [2, 810, 0.07]]}, {"timestamp": 1631544621939, "ltp": 1.37, "tv": 324.82, "trd": NaN, "batb": [[0, 1.31, 176.94], [1, 1.3, 133.58], [2, 1.22, 530.12]], "batl": [[0, 1.49, 74.26], [1, 1.5, 67.22], [2, 1.58, 659.44]]}, {"timestamp": 1631544629936, "ltp": 1.37, "tv": 324.82, "trd": NaN, "batb": [[0, 1.22, 530.12], [1, 1.05, 477.76], [2, 1.03, 497.67]], "batl": NaN}, {"timestamp": 1631544632935, "ltp": 1.37, "tv": 324.82, "trd": NaN, "batb": [[0, 1.45, 104.68], [1, 1.44, 92.32], [2, 1.4, 105.88]], "batl": [[0, 1.46, 13.43], [1, 1.47, 135.5], [2, 1.49, 74.26]]}, {"timestamp": 1631544650070, "ltp": 1.45, "tv": 367.43, "trd": [[1.45, 42.61]], "batb": [[0, 1.45, 83.36]], "batl": NaN}, {"timestamp": 1631544651955, "ltp": 1.45, "tv": 423.67, "trd": [[1.45, 98.86]], "batb": [[0, 1.45, 55.22]], "batl": NaN}, {"timestamp": 1631544653088, "ltp": 1.45, "tv": 423.67, "trd": NaN, "batb": [[0, 1.45, 62.29]], "batl": [[2, 1.49, 88.13]]}, {"timestamp": 1631544655585, "ltp": 1.45, "tv": 457.75, "trd": [[1.45, 132.94]], "batb": [[0, 1.45, 54.57]], "batl": [[2, 1.49, 106.44]]}, {"timestamp": 1631544657090, "ltp": 1.45, "tv": 525.93, "trd": [[1.45, 201.11]], "batb": [[0, 1.45, 20.46]], "batl": NaN}, {"timestamp": 1631544657875, "ltp": 1.45, "tv": 566.82, "trd": [[1.45, 242]], "batb": [[0, 1.44, 92.32], [1, 1.4, 105.88], [2, 1.22, 530.12]], "batl": [[0, 1.45, 22.15], [1, 1.46, 13.43], [2, 1.47, 135.5]]}, {"timestamp": 1631544659068, "ltp": 1.45, "tv": 578.12, "trd": [[1.45, 253.3]], "batb": NaN, "batl": [[0, 1.45, 15.64]]}, {"timestamp": 1631544659279, "ltp": 1.45, "tv": 578.12, "trd": NaN, "batb": NaN, "batl": [[0, 1.46, 13.43], [1, 1.47, 135.5], [2, 1.49, 74.26]]}, {"timestamp": 1631544660589, "ltp": 1.45, "tv": 578.12, "trd": NaN, "batb": [[0, 1.44, 116.24], [1, 1.43, 84.09], [2, 1.4, 105.88]], "batl": [[2, 1.48, 84.04]]}, {"timestamp": 1631544743967, "ltp": 1.45, "tv": 578.12, "trd": NaN, "batb": [[0, 1.44, 104.85], [2, 1.22, 530.12]], "batl": [[0, 1.48, 84.04], [1, 1.49, 74.26], [2, 1.58, 659.44]]}, {"timestamp": 1631544744175, "ltp": 1.45, "tv": 578.12, "trd": NaN, "batb": [[0, 1.22, 530.12], [1, 1.05, 477.76], [2, 1.03, 497.67]], "batl": [[0, 1.58, 659.44], [1, 44, 7.23], [2, 810, 0.07]]}, {"timestamp": 1631544747188, "ltp": 1.45, "tv": 578.12, "trd": NaN, "batb": [[0, 1.39, 87.26], [1, 1.38, 98.75], [2, 1.22, 530.12]], "batl": [[0, 1.56, 81.84], [1, 1.57, 56.8], [2, 1.58, 659.44]]}, {"timestamp": 1631544754904, "ltp": 1.45, "tv": 578.12, "trd": NaN, "batb": NaN, "batl": [[0, 1.58, 659.44], [1, 44, 7.23], [2, 810, 0.07]]}, {"timestamp": 1631544757902, "ltp": 1.45, "tv": 578.12, "trd": NaN, "batb": [[2, 1.36, 156.48]], "batl": [[0, 1.41, 19.26], [1, 1.42, 62.5], [2, 1.43, 82.81]]}, {"timestamp": 1631544776013, "ltp": 1.45, "tv": 578.12, "trd": NaN, "batb": [[2, 1.22, 530.12]], "batl": [[0, 1.42, 62.5], [1, 1.43, 82.81], [2, 1.58, 659.44]]}, {"timestamp": 1631544776225, "ltp": 1.45, "tv": 578.12, "trd": NaN, "batb": [[0, 1.22, 530.12], [1, 1.05, 477.76], [2, 1.03, 497.67]], "batl": [[0, 1.58, 659.44], [1, 44, 7.23], [2, 810, 0.07]]}, {"timestamp": 1631544779227, "ltp": 1.45, "tv": 578.12, "trd": NaN, "batb": [[0, 1.35, 59.9], [1, 1.34, 113.56], [2, 1.22, 530.12]], "batl": [[0, 1.49, 84.59], [1, 1.5, 67.74], [2, 1.58, 659.44]]}, {"timestamp": 1631544783848, "ltp": 1.45, "tv": 578.12, "trd": NaN, "batb": [[0, 1.22, 530.12], [1, 1.05, 477.76], [2, 1.03, 497.67]], "batl": NaN}, {"timestamp": 1631544785551, "ltp": 1.45, "tv": 578.12, "trd": NaN, "batb": [[0, 1.05, 477.76], [1, 1.03, 497.67], [2, 1.01, 479.65]], "batl": [[2, 44, 7.23]]}, {"timestamp": 1631544786859, "ltp": 1.45, "tv": 578.12, "trd": NaN, "batb": [[0, 1.45, 106.28], [1, 1.44, 81.52], [2, 1.05, 477.76]], "batl": [[0, 1.47, 14.13], [1, 1.48, 143.96], [2, 1.49, 84.59]]}, {"timestamp": 1631544789938, "ltp": 1.45, "tv": 578.12, "trd": NaN, "batb": [[2, 1.25, 511.97]], "batl": NaN}, {"timestamp": 1631544815852, "ltp": 1.45, "tv": 578.12, "trd": NaN, "batb": [[0, 1.45, 96.33]], "batl": [[0, 1.49, 84.59], [1, 1.5, 67.74], [2, 1.77, 507.43]]}, {"timestamp": 1631544816163, "ltp": 1.45, "tv": 578.12, "trd": NaN, "batb": [[0, 1.25, 511.97], [1, 1.05, 477.76], [2, 1.03, 497.67]], "batl": [[0, 1.77, 507.43], [1, 44, 7.23], [2, 810, 0.07]]}, {"timestamp": 1631544819078, "ltp": 1.45, "tv": 578.12, "trd": NaN, "batb": [[0, 1.39, 101.29], [1, 1.38, 98.9], [2, 1.25, 511.97]], "batl": [[0, 1.58, 61.73], [1, 1.59, 54.28], [2, 1.77, 507.43]]}, {"timestamp": 1631544819761, "ltp": 1.45, "tv": 578.12, "trd": NaN, "batb": [[0, 1.25, 511.97], [1, 1.05, 477.76], [2, 1.03, 497.67]], "batl": [[0, 1.77, 507.43], [1, 44, 7.23], [2, 810, 0.07]]}, {"timestamp": 1631544821279, "ltp": 1.45, "tv": 578.12, "trd": NaN, "batb": NaN, "batl": [[2, 810, 0]]}, {"timestamp": 1631544822747, "ltp": 1.45, "tv": 578.12, "trd": NaN, "batb": [[0, 1.47, 67.04], [1, 1.46, 76.62], [2, 1.25, 511.97]], "batl": [[0, 1.51, 98.19], [1, 1.52, 64.2], [2, 1.77, 507.43]]}, {"timestamp": 1631544828495, "ltp": 1.45, "tv": 578.12, "trd": NaN, "batb": [[0, 1.25, 511.97], [1, 1.05, 477.76], [2, 1.03, 497.67]], "batl": [[0, 1.77, 507.43], [1, 44, 7.23], [2, 1.77, 0]]}, {"timestamp": 1631544831352, "ltp": 1.45, "tv": 578.12, "trd": NaN, "batb": [[0, 1.39, 101.29], [1, 1.38, 98.9], [2, 1.25, 511.97]], "batl": [[0, 1.58, 61.73], [1, 1.59, 54.28], [2, 1.77, 507.43]]}, {"timestamp": 1631544843396, "ltp": 1.45, "tv": 578.12, "trd": NaN, "batb": NaN, "batl": [[0, 1.77, 507.43], [1, 44, 7.23], [2, 1.77, 0]]}, {"timestamp": 1631544846092, "ltp": 1.45, "tv": 578.12, "trd": NaN, "batb": [[0, 1.39, 113.57], [2, 1.36, 169.55]], "batl": [[0, 1.41, 16.56]]}, {"timestamp": 1631544846301, "ltp": 1.45, "tv": 578.12, "trd": NaN, "batb": NaN, "batl": [[1, 1.43, 131.77], [2, 1.44, 79.75]]}, {"timestamp": 1631544853595, "ltp": 1.39, "tv": 691.67, "trd": [[1.39, 113.55]], "batb": [[0, 1.38, 98.92], [1, 1.36, 169.55], [2, 1.2, 538.09]], "batl": NaN}, {"timestamp": 1631544854446, "ltp": 1.39, "tv": 691.67, "trd": NaN, "batb": NaN, "batl": [[1, 1.43, 82.96], [2, 1.66, 587.71]]}, {"timestamp": 1631544857122, "ltp": 1.39, "tv": 691.67, "trd": NaN, "batb": [[0, 1.38, 132.77], [1, 1.37, 103.46], [2, 1.36, 169.55]], "batl": [[1, 1.42, 115.43], [2, 1.43, 82.96]]}, {"timestamp": 1631544863834, "ltp": 1.39, "tv": 691.67, "trd": NaN, "batb": [[0, 1.38, 132.75]], "batl": [[0, 1.42, 115.43], [1, 1.43, 82.96], [2, 1.66, 587.71]]}, {"timestamp": 1631544866736, "ltp": 1.39, "tv": 691.67, "trd": NaN, "batb": [[0, 1.38, 148.24]], "batl": [[0, 1.4, 7.34], [1, 1.42, 115.43], [2, 1.43, 82.96]]}, {"timestamp": 1631544868912, "ltp": 1.39, "tv": 691.67, "trd": NaN, "batb": [[0, 1.2, 538.09], [1, 1.05, 477.76], [2, 1.03, 497.67]], "batl": [[0, 1.66, 587.71], [1, 44, 7.23], [2, 1.43, 0]]}, {"timestamp": 1631544872604, "ltp": 1.39, "tv": 691.67, "trd": NaN, "batb": [[0, 1.05, 477.76], [1, 1.03, 497.67], [2, 1.01, 479.65]], "batl": NaN}, {"timestamp": 1631544874318, "ltp": 1.39, "tv": 691.67, "trd": NaN, "batb": [[0, 1.4, 63.91], [1, 1.39, 95.91], [2, 1.05, 477.76]], "batl": [[0, 1.43, 79.14], [1, 1.44, 80.83], [2, 1.66, 587.71]]}, {"timestamp": 1631544876648, "ltp": 1.39, "tv": 691.67, "trd": NaN, "batb": [[2, 1.22, 530.12]], "batl": NaN}, {"timestamp": 1631544881726, "ltp": 1.39, "tv": 691.67, "trd": NaN, "batb": [[0, 1.22, 530.12], [1, 1.05, 477.76], [2, 1.03, 497.67]], "batl": [[0, 1.66, 587.71], [1, 44, 7.23], [2, 1.66, 0]]}, {"timestamp": 1631544885258, "ltp": 1.39, "tv": 691.67, "trd": NaN, "batb": [[0, 1.34, 57.82], [1, 1.33, 118.84], [2, 1.22, 530.12]], "batl": [[0, 1.49, 77.03], [1, 1.5, 68.27], [2, 1.66, 587.71]]}, {"timestamp": 1631544903779, "ltp": 1.39, "tv": 691.67, "trd": NaN, "batb": NaN, "batl": [[0, 1.66, 587.71], [1, 44, 7.23], [2, 1.66, 0]]}, {"timestamp": 1631544904978, "ltp": 1.39, "tv": 691.67, "trd": NaN, "batb": [[2, 1.05, 477.76]], "batl": NaN}, {"timestamp": 1631544906800, "ltp": 1.39, "tv": 691.67, "trd": NaN, "batb": NaN, "batl": [[0, 1.35, 13.69], [1, 1.37, 136.89], [2, 1.38, 97.03]]}, {"timestamp": 1631544909106, "ltp": 1.39, "tv": 691.67, "trd": NaN, "batb": [[2, 1.18, 557.21]], "batl": NaN}, {"timestamp": 1631544935428, "ltp": 1.39, "tv": 691.67, "trd": NaN, "batb": [[0, 1.18, 557.21], [1, 1.11, 271.45], [2, 1.1, 298.6]], "batl": [[0, 1.66, 587.71], [1, 44, 7.23], [2, 1.38, 0]]}, {"timestamp": 1631544938511, "ltp": 1.39, "tv": 691.67, "trd": NaN, "batb": [[0, 1.3, 190.18], [1, 1.29, 142.07], [2, 1.18, 557.21]], "batl": [[0, 1.41, 74.92], [1, 1.42, 85.92], [2, 1.66, 587.71]]}, {"timestamp": 1631544942520, "ltp": 1.39, "tv": 691.67, "trd": NaN, "batb": NaN, "batl": [[0, 1.66, 587.71], [1, 44, 7.23], [2, 1.66, 0]]}, {"timestamp": 1631544945110, "ltp": 1.39, "tv": 691.67, "trd": NaN, "batb": [[1, 1.29, 296.92]], "batl": [[0, 1.32, 16.71], [1, 1.33, 132.02], [2, 44, 7.23]]}, {"timestamp": 1631544945317, "ltp": 1.39, "tv": 691.67, "trd": NaN, "batb": NaN, "batl": [[1, 1.33, 192.49], [2, 1.34, 112.78]]}, {"timestamp": 1631544963960, "ltp": 1.39, "tv": 691.67, "trd": NaN, "batb": [[1, 1.29, 142.07]], "batl": [[0, 1.33, 60.47], [1, 1.34, 112.78], [2, 1.58, 659.44]]}, {"timestamp": 1631544964280, "ltp": 1.39, "tv": 691.67, "trd": NaN, "batb": [[0, 1.18, 557.21], [1, 1.15, 358.31], [2, 1.11, 271.45]], "batl": [[0, 1.58, 659.44], [1, 44, 7.23], [2, 1.58, 0]]}, {"timestamp": 1631544967201, "ltp": 1.39, "tv": 691.67, "trd": NaN, "batb": [[0, 1.26, 135.23], [1, 1.25, 169.52], [2, 1.18, 557.21]], "batl": [[0, 1.39, 143.84], [1, 1.4, 90.79], [2, 1.58, 659.44]]}, {"timestamp": 1631544971690, "ltp": 1.39, "tv": 691.67, "trd": NaN, "batb": NaN, "batl": [[0, 1.58, 659.44], [1, 44, 7.23], [2, 1.58, 0]]}, {"timestamp": 1631544972687, "ltp": 1.39, "tv": 691.67, "trd": NaN, "batb": [[2, 1.15, 358.31]], "batl": NaN}, {"timestamp": 1631544973991, "ltp": 1.39, "tv": 691.67, "trd": NaN, "batb": [[0, 1.26, 153.77]], "batl": [[0, 1.28, 28.72], [1, 1.29, 906.42], [2, 1.33, 13.1]]}, {"timestamp": 1631544974563, "ltp": 1.39, "tv": 691.67, "trd": NaN, "batb": NaN, "batl": [[1, 1.29, 374.04], [2, 1.3, 129.8]]}, {"timestamp": 1631544988888, "ltp": 1.39, "tv": 691.67, "trd": NaN, "batb": [[0, 1.15, 358.31], [1, 1.14, 618.77], [2, 1.11, 271.45]], "batl": [[0, 1.58, 659.44], [1, 44, 7.23], [2, 1.3, 0]]}, {"timestamp": 1631544994985, "ltp": 1.39, "tv": 691.67, "trd": NaN, "batb": [[0, 1.25, 166.45], [1, 1.24, 178.9], [2, 1.15, 358.31]], "batl": [[0, 1.28, 164.17], [1, 1.29, 135.5], [2, 1.58, 659.44]]}, {"timestamp": 1631544998326, "ltp": 1.39, "tv": 691.67, "trd": NaN, "batb": [[0, 1.15, 358.31], [1, 1.14, 618.77], [2, 1.11, 271.45]], "batl": [[0, 1.58, 659.44], [1, 44, 7.23], [2, 1.58, 0]]}, {"timestamp": 1631545001298, "ltp": 1.39, "tv": 691.67, "trd": NaN, "batb": [[0, 1.22, 139.16], [1, 1.21, 209.35], [2, 1.15, 358.31]], "batl": [[0, 1.33, 72.29], [1, 1.34, 112.61], [2, 1.58, 659.44]]}, {"timestamp": 1631545016316, "ltp": 1.39, "tv": 691.67, "trd": NaN, "batb": NaN, "batl": [[0, 1.58, 659.44], [1, 44, 7.23], [2, 1.58, 0]]}, {"timestamp": 1631545018136, "ltp": 1.39, "tv": 691.67, "trd": NaN, "batb": NaN, "batl": [[0, 44, 7.23], [1, 44, 0]]}, {"timestamp": 1631545019020, "ltp": 1.39, "tv": 691.67, "trd": NaN, "batb": [[2, 1.2, 195.1]], "batl": [[0, 1.24, 33.28], [1, 1.25, 892.68], [2, 1.28, 14.33]]}, {"timestamp": 1631545019329, "ltp": 1.39, "tv": 691.67, "trd": NaN, "batb": NaN, "batl": [[0, 1.24, 125.19], [1, 1.25, 285.67], [2, 44, 7.23]]}, {"timestamp": 1631545022543, "ltp": 1.39, "tv": 691.67, "trd": NaN, "batb": NaN, "batl": [[2, 1.51, 751.18]]}, {"timestamp": 1631545034482, "ltp": 1.39, "tv": 691.67, "trd": NaN, "batb": NaN, "batl": [[2, 44, 7.23]]}, {"timestamp": 1631545037968, "ltp": 1.39, "tv": 691.67, "trd": NaN, "batb": NaN, "batl": [[2, 8.8, 7.23]]}, {"timestamp": 1631545040839, "ltp": 1.39, "tv": 691.67, "trd": NaN, "batb": [[0, 1.05, 477.76], [1, 1.03, 497.67], [2, 1.01, 479.65]], "batl": [[0, 8.8, 7.23], [1, 44, 7.23], [2, 50, 7.23]]}, {"timestamp": 1631545044065, "ltp": 1.39, "tv": 691.67, "trd": NaN, "batb": [[0, 1.19, 120.82], [1, 1.18, 250.49], [2, 1.05, 477.76]], "batl": [[0, 1.28, 128.7], [1, 1.29, 136.18], [2, 8.8, 7.23]]}, {"timestamp": 1631545044481, "ltp": 1.39, "tv": 691.67, "trd": NaN, "batb": [[0, 1.05, 477.76], [1, 1.03, 497.67], [2, 1.01, 479.65]], "batl": [[0, 8.8, 7.23], [1, 44, 7.23], [2, 50, 7.23]]}, {"timestamp": 1631545047760, "ltp": 1.39, "tv": 691.67, "trd": NaN, "batb": [[0, 1.21, 217.67], [1, 1.2, 198.3], [2, 1.05, 477.76]], "batl": [[0, 1.24, 210.58], [1, 1.25, 161.06], [2, 8.8, 7.23]]}, {"timestamp": 1631545051095, "ltp": 1.39, "tv": 691.67, "trd": NaN, "batb": [[0, 1.05, 477.76], [1, 1.03, 497.67], [2, 1.01, 479.65]], "batl": [[0, 8.8, 7.23], [1, 44, 7.23], [2, 50, 7.23]]}, {"timestamp": 1631545053962, "ltp": 1.39, "tv": 691.67, "trd": NaN, "batb": [[0, 1.19, 120.82], [1, 1.18, 250.49], [2, 1.05, 477.76]], "batl": [[0, 1.28, 128.7], [1, 1.29, 136.18], [2, 8.8, 7.23]]}, {"timestamp": 1631545055372, "ltp": 1.39, "tv": 691.67, "trd": NaN, "batb": NaN, "batl": [[0, 8.8, 7.23], [1, 44, 7.23], [2, 50, 7.23]]}, {"timestamp": 1631545058071, "ltp": 1.39, "tv": 691.67, "trd": NaN, "batb": [[1, 1.18, 466.69]], "batl": [[0, 1.21, 1713.97], [1, 8.8, 7.23], [2, 44, 7.23]]}, {"timestamp": 1631545058687, "ltp": 1.39, "tv": 691.67, "trd": NaN, "batb": NaN, "batl": [[0, 1.21, 347.27], [1, 1.22, 188.69], [2, 8.8, 7.23]]}, {"timestamp": 1631545070100, "ltp": 1.39, "tv": 691.67, "trd": NaN, "batb": NaN, "batl": [[0, 1.21, 212.18]]}, {"timestamp": 1631545075822, "ltp": 1.39, "tv": 691.67, "trd": NaN, "batb": [[0, 1.05, 477.76], [1, 1.03, 497.67], [2, 1.01, 479.65]], "batl": [[0, 8.8, 7.23], [1, 44, 7.23], [2, 50, 7.23]]}, {"timestamp": 1631545078899, "ltp": 1.39, "tv": 691.67, "trd": NaN, "batb": [[0, 1.17, 147.62], [1, 1.05, 477.76], [2, 1.03, 497.67]], "batl": NaN}, {"timestamp": 1631545081731, "ltp": 1.39, "tv": 691.67, "trd": NaN, "batb": [[0, 1.18, 278.5], [1, 1.17, 147.62], [2, 1.05, 477.76]], "batl": [[0, 1.21, 252.32], [1, 1.22, 160.68], [2, 8.8, 7.23]]}, {"timestamp": 1631545086723, "ltp": 1.39, "tv": 691.67, "trd": NaN, "batb": [[0, 1.17, 147.62], [1, 1.05, 477.76], [2, 1.03, 497.67]], "batl": [[0, 8.8, 7.23], [1, 44, 7.23], [2, 50, 7.23]]}, {"timestamp": 1631545089723, "ltp": 1.39, "tv": 691.67, "trd": NaN, "batb": [[0, 1.17, 154.68], [1, 1.16, 276.18], [2, 1.05, 477.76]], "batl": [[0, 1.23, 116.36], [1, 1.24, 171.54], [2, 8.8, 7.23]]}, {"timestamp": 1631545094633, "ltp": 1.39, "tv": 691.67, "trd": NaN, "batb": NaN, "batl": [[0, 8.8, 7.23], [1, 44, 7.23], [2, 50, 7.23]]}, {"timestamp": 1631545097648, "ltp": 1.39, "tv": 691.67, "trd": NaN, "batb": [[2, 1.03, 497.67]], "batl": [[0, 1.19, 193.52], [1, 1.2, 210.29], [2, 8.8, 7.23]]}, {"timestamp": 1631545100744, "ltp": 1.39, "tv": 691.67, "trd": NaN, "batb": NaN, "batl": [[2, 3.8, 27.46]]}, {"timestamp": 1631545109355, "ltp": 1.39, "tv": 691.67, "trd": NaN, "batb": NaN, "batl": [[0, 1.19, 190.64]]}, {"timestamp": 1631545204084, "ltp": 1.39, "tv": 691.82, "trd": [[1.45, 253.45]], "batb": [[2, 1.03, 497.16]], "batl": [[2, 3.8, 27.43]]}, {"timestamp": 1631545204299, "ltp": 1.39, "tv": 691.82, "trd": NaN, "batb": [[0, 1.03, 497.16], [1, 1.01, 479.17], [2, 1.03, 0]], "batl": [[0, 3.8, 27.43], [1, 8.8, 7.22], [2, 44, 7.22]]}, {"timestamp": 1631545208103, "ltp": 1.39, "tv": 691.82, "trd": NaN, "batb": [[0, 1.15, 89.51], [1, 1.14, 333.15], [2, 1.03, 497.16]], "batl": [[0, 1.16, 31.6], [1, 1.17, 306.33], [2, 3.8, 27.43]]}, {"timestamp": 1631545208211, "ltp": 1.39, "tv": 691.82, "trd": NaN, "batb": NaN, "batl": [[1, 1.17, 621.15], [2, 1.18, 112.71]]}, {"timestamp": 1631545210006, "ltp": 1.39, "tv": 691.82, "trd": NaN, "batb": [[2, 1.06, 950.7]], "batl": NaN}, {"timestamp": 1631545229922, "ltp": 1.39, "tv": 691.82, "trd": NaN, "batb": [[0, 1.06, 950.7], [1, 1.03, 497.16], [2, 1.01, 479.17]], "batl": [[0, 1.39, 17.9], [1, 1.4, 954.47], [2, 3.8, 27.43]]}, {"timestamp": 1631545232839, "ltp": 1.39, "tv": 691.82, "trd": NaN, "batb": [[0, 1.13, 153.51], [1, 1.12, 292.75], [2, 1.06, 950.7]], "batl": [[0, 1.2, 272.6], [1, 1.21, 143.98], [2, 1.39, 17.9]]}, {"timestamp": 1631545239025, "ltp": 1.39, "tv": 691.82, "trd": NaN, "batb": NaN, "batl": [[0, 1.39, 17.9], [1, 1.4, 954.47], [2, 3.8, 27.43]]}, {"timestamp": 1631545240523, "ltp": 1.39, "tv": 691.82, "trd": NaN, "batb": [[2, 1.03, 497.16]], "batl": NaN}, {"timestamp": 1631545242122, "ltp": 1.39, "tv": 691.82, "trd": NaN, "batb": [[1, 1.12, 538.88], [2, 1.01, 479.17]], "batl": [[0, 1.14, 40], [1, 1.15, 728.51], [2, 1.16, 93.97]]}, {"timestamp": 1631545244417, "ltp": 1.39, "tv": 691.82, "trd": NaN, "batb": [[2, 1.05, 1085.45]], "batl": NaN}, {"timestamp": 1631545254006, "ltp": 1.39, "tv": 691.82, "trd": NaN, "batb": [[0, 1.05, 1085.45], [1, 1.01, 479.17], [2, 1.05, 0]], "batl": [[0, 1.39, 17.9], [1, 1.4, 954.47], [2, 3.8, 27.43]]}, {"timestamp": 1631545256864, "ltp": 1.39, "tv": 691.82, "trd": NaN, "batb": [[0, 1.11, 451.66], [1, 1.05, 1085.45], [2, 1.01, 479.17]], "batl": [[0, 1.17, 258.98], [1, 1.18, 168.08], [2, 1.39, 17.9]]}, {"timestamp": 1631545264702, "ltp": 1.39, "tv": 691.82, "trd": NaN, "batb": [[0, 1.05, 1085.45], [1, 1.01, 479.17], [2, 1.01, 0]], "batl": NaN}, {"timestamp": 1631545266785, "ltp": 1.39, "tv": 691.82, "trd": NaN, "batb": [[0, 1.01, 479.17], [1, 1.01, 0]], "batl": NaN}, {"timestamp": 1631545267720, "ltp": 1.39, "tv": 691.82, "trd": NaN, "batb": [[0, 1.15, 151.65], [1, 1.14, 513.43], [2, 1.01, 479.17]], "batl": [[0, 1.16, 28.89], [1, 1.17, 552.58], [2, 1.18, 168.08]]}, {"timestamp": 1631545270786, "ltp": 1.39, "tv": 691.82, "trd": NaN, "batb": [[2, 1.06, 1008.65]], "batl": NaN}, {"timestamp": 1631545280903, "ltp": 1.39, "tv": 691.82, "trd": NaN, "batb": [[0, 1.06, 1008.65], [1, 1.01, 479.17], [2, 1.06, 0]], "batl": [[0, 1.39, 17.9], [1, 1.4, 954.47], [2, 3.8, 27.43]]}, {"timestamp": 1631545287634, "ltp": 1.39, "tv": 691.82, "trd": NaN, "batb": [[0, 1.15, 343.1], [1, 1.14, 93.66], [2, 1.06, 1008.65]], "batl": [[0, 1.17, 86.92], [1, 1.18, 241.76], [2, 1.39, 17.9]]}, {"timestamp": 1631545294039, "ltp": 1.39, "tv": 691.82, "trd": NaN, "batb": [[0, 1.06, 1008.65], [1, 1.01, 479.17], [2, 1.06, 0]], "batl": [[0, 1.39, 17.9], [1, 1.4, 954.47], [2, 3.8, 27.43]]}, {"timestamp": 1631545297050, "ltp": 1.39, "tv": 691.82, "trd": NaN, "batb": [[0, 1.13, 124.59], [1, 1.12, 321.93], [2, 1.06, 1008.65]], "batl": [[0, 1.2, 134.81], [1, 1.21, 200.47], [2, 1.39, 17.9]]}, {"timestamp": 1631545306740, "ltp": 1.39, "tv": 691.82, "trd": NaN, "batb": [[0, 1.06, 1008.65], [1, 1.01, 479.17], [2, 1.06, 0]], "batl": NaN}, {"timestamp": 1631545308243, "ltp": 1.39, "tv": 691.82, "trd": NaN, "batb": [[0, 1.01, 479.17], [1, 1.01, 0]], "batl": NaN}, {"timestamp": 1631545309646, "ltp": 1.39, "tv": 691.82, "trd": NaN, "batb": [[0, 1.18, 208.72], [1, 1.17, 241.13], [2, 1.01, 479.17]], "batl": [[1, 1.21, 551.05]]}, {"timestamp": 1631545311935, "ltp": 1.39, "tv": 691.82, "trd": NaN, "batb": [[2, 1.08, 812.84]], "batl": NaN}, {"timestamp": 1631545334103, "ltp": 1.39, "tv": 691.82, "trd": NaN, "batb": [[0, 1.08, 812.84], [1, 1.03, 497.12], [2, 1.01, 479.17]], "batl": [[0, 1.39, 17.9], [1, 1.4, 954.47], [2, 3.8, 27.43]]}, {"timestamp": 1631545336875, "ltp": 1.39, "tv": 691.82, "trd": NaN, "batb": [[0, 1.15, 103.21], [1, 1.14, 333.85], [2, 1.08, 812.84]], "batl": [[0, 1.26, 213.97], [1, 1.27, 146.81], [2, 1.39, 17.9]]}, {"timestamp": 1631545351923, "ltp": 1.39, "tv": 691.82, "trd": NaN, "batb": NaN, "batl": [[0, 1.39, 17.9], [1, 1.4, 954.47], [2, 3.8, 27.43]]}, {"timestamp": 1631545353707, "ltp": 1.39, "tv": 691.82, "trd": NaN, "batb": [[2, 1.03, 497.12]], "batl": NaN}, {"timestamp": 1631545354912, "ltp": 1.39, "tv": 691.82, "trd": NaN, "batb": NaN, "batl": [[0, 1.16, 41.57], [1, 1.17, 646.65], [2, 1.18, 124.92]]}, {"timestamp": 1631545357208, "ltp": 1.39, "tv": 691.82, "trd": NaN, "batb": [[2, 1.06, 950.7]], "batl": NaN}, {"timestamp": 1631545375446, "ltp": 1.39, "tv": 691.82, "trd": NaN, "batb": [[0, 1.06, 950.7], [1, 1.03, 497.12], [2, 1.01, 479.17]], "batl": [[0, 1.39, 17.9], [1, 1.4, 954.47], [2, 3.8, 27.43]]}, {"timestamp": 1631545379936, "ltp": 1.39, "tv": 691.82, "trd": NaN, "batb": [[0, 1.03, 497.12], [1, 1.01, 479.17], [2, 1.01, 0]], "batl": NaN}, {"timestamp": 1631545381560, "ltp": 1.39, "tv": 691.82, "trd": NaN, "batb": [[0, 1.15, 328.22], [1, 1.14, 108.68], [2, 1.03, 497.12]], "batl": [[0, 1.17, 100.3], [1, 1.18, 241.23], [2, 1.39, 17.9]]}, {"timestamp": 1631545383462, "ltp": 1.39, "tv": 691.82, "trd": NaN, "batb": [[2, 1.06, 1008.65]], "batl": NaN}, {"timestamp": 1631545388602, "ltp": 1.39, "tv": 691.82, "trd": NaN, "batb": [[0, 1.06, 1008.65], [1, 1.03, 497.12], [2, 1.01, 479.17]], "batl": [[0, 1.39, 17.9], [1, 1.4, 954.47], [2, 3.8, 27.43]]}, {"timestamp": 1631545391621, "ltp": 1.39, "tv": 691.82, "trd": NaN, "batb": [[0, 1.12, 289.86], [1, 1.11, 159.19], [2, 1.06, 1008.65]], "batl": [[0, 1.21, 244.5], [1, 1.22, 168.44], [2, 1.39, 17.9]]}, {"timestamp": 1631545403711, "ltp": 1.39, "tv": 691.82, "trd": NaN, "batb": NaN, "batl": [[0, 1.39, 17.9], [1, 1.4, 954.47], [2, 3.8, 27.43]]}, {"timestamp": 1631545407008, "ltp": 1.39, "tv": 691.82, "trd": NaN, "batb": [[0, 1.12, 311.79], [2, 1.01, 479.17]], "batl": [[0, 1.13, 35.37], [1, 1.14, 845.79], [2, 1.15, 164.92]]}, {"timestamp": 1631545409609, "ltp": 1.39, "tv": 691.82, "trd": NaN, "batb": [[2, 1.04, 1300.13]], "batl": NaN}, {"timestamp": 1631545418536, "ltp": 1.39, "tv": 691.82, "trd": NaN, "batb": NaN, "batl": [[1, 1.14, 635.19]]}, {"timestamp": 1631545443789, "ltp": 1.39, "tv": 691.82, "trd": NaN, "batb": [[0, 1.12, 21.93], [1, 1.04, 1300.13], [2, 1.01, 479.17]], "batl": [[1, 1.14, 361.78], [2, 1.39, 17.9]]}, {"timestamp": 1631545446794, "ltp": 1.39, "tv": 691.82, "trd": NaN, "batb": [[1, 1.1, 455.77], [2, 1.04, 1300.13]], "batl": [[2, 1.16, 278.98]]}, {"timestamp": 1631545477232, "ltp": 1.39, "tv": 691.82, "trd": NaN, "batb": [[0, 1.1, 455.77], [1, 1.04, 1300.13], [2, 1.01, 479.17]], "batl": [[0, 1.16, 278.98], [1, 1.17, 151.9], [2, 1.39, 17.9]]}, {"timestamp": 1631545483947, "ltp": 1.39, "tv": 691.82, "trd": NaN, "batb": NaN, "batl": [[0, 1.39, 17.9], [1, 1.4, 954.47], [2, 3.8, 27.43]]}, {"timestamp": 1631545486966, "ltp": 1.39, "tv": 691.82, "trd": NaN, "batb": NaN, "batl": [[0, 1.12, 508.6], [1, 1.13, 256.72], [2, 1.39, 17.9]]}, {"timestamp": 1631545497045, "ltp": 1.39, "tv": 691.82, "trd": NaN, "batb": [[0, 1.04, 1300.13], [1, 1.01, 479.17], [2, 1.01, 0]], "batl": [[0, 1.39, 17.9], [1, 1.4, 954.47], [2, 3.8, 27.43]]}, {"timestamp": 1631545499948, "ltp": 1.39, "tv": 691.82, "trd": NaN, "batb": [[0, 1.09, 371.69], [1, 1.08, 89.07], [2, 1.04, 1300.13]], "batl": [[0, 1.14, 249.57], [1, 1.15, 188.55], [2, 1.39, 17.9]]}, {"timestamp": 1631545502738, "ltp": 1.39, "tv": 691.82, "trd": NaN, "batb": [[0, 1.04, 1300.13], [1, 1.01, 479.17], [2, 1.04, 0]], "batl": NaN}, {"timestamp": 1631545505977, "ltp": 1.39, "tv": 691.82, "trd": NaN, "batb": [[0, 1.12, 532.78], [1, 1.11, 131.64], [2, 1.04, 1300.13]], "batl": [[0, 1.13, 31.54], [1, 1.14, 609.66], [2, 1.15, 188.55]]}, {"timestamp": 1631545517085, "ltp": 1.39, "tv": 691.82, "trd": NaN, "batb": [[0, 1.04, 1300.13], [1, 1.01, 479.17], [2, 1.04, 0]], "batl": [[0, 1.39, 17.9], [1, 1.4, 954.47], [2, 3.8, 27.43]]}, {"timestamp": 1631545520002, "ltp": 1.39, "tv": 691.82, "trd": NaN, "batb": [[0, 1.1, 455.77], [1, 1.04, 1300.13], [2, 1.01, 479.17]], "batl": [[0, 1.16, 195], [1, 1.17, 235.16], [2, 1.39, 17.9]]}, {"timestamp": 1631545523597, "ltp": 1.39, "tv": 691.82, "trd": NaN, "batb": [[0, 1.04, 1300.13], [1, 1.01, 479.17], [2, 1.01, 0]], "batl": NaN}, {"timestamp": 1631545525626, "ltp": 1.39, "tv": 691.82, "trd": NaN, "batb": [[0, 1.01, 479.17], [1, 1.01, 0]], "batl": NaN}, {"timestamp": 1631545526404, "ltp": 1.39, "tv": 691.82, "trd": NaN, "batb": [[0, 1.14, 293.11], [1, 1.13, 173.93], [2, 1.01, 479.17]], "batl": [[0, 1.15, 23.3], [1, 1.16, 469.02], [2, 1.17, 235.16]]}, {"timestamp": 1631545529732, "ltp": 1.39, "tv": 691.82, "trd": NaN, "batb": [[2, 1.06, 950.7]], "batl": NaN}, {"timestamp": 1631545548750, "ltp": 1.39, "tv": 691.82, "trd": NaN, "batb": [[0, 1.06, 950.7], [1, 1.01, 479.17], [2, 1.06, 0]], "batl": [[0, 1.39, 17.9], [1, 1.4, 954.47], [2, 3.8, 27.43]]}, {"timestamp": 1631545552815, "ltp": 1.39, "tv": 691.82, "trd": NaN, "batb": [[0, 1.01, 479.17], [1, 1.01, 0]], "batl": NaN}, {"timestamp": 1631545554533, "ltp": 1.39, "tv": 691.82, "trd": NaN, "batb": [[0, 1.14, 136.79], [1, 1.13, 305.66], [2, 1.01, 479.17]], "batl": [[0, 1.16, 311.38], [1, 1.17, 119.77], [2, 1.39, 17.9]]}, {"timestamp": 1631545556835, "ltp": 1.39, "tv": 691.82, "trd": NaN, "batb": [[2, 1.05, 1085.45]], "batl": NaN}, {"timestamp": 1631545561534, "ltp": 1.39, "tv": 691.82, "trd": NaN, "batb": [[0, 1.05, 1085.45], [1, 1.01, 479.17], [2, 1.05, 0]], "batl": [[0, 1.39, 17.9], [1, 1.4, 954.47], [2, 3.8, 27.43]]}, {"timestamp": 1631545564470, "ltp": 1.39, "tv": 691.82, "trd": NaN, "batb": [[0, 1.12, 334.75], [1, 1.11, 113.9], [2, 1.05, 1085.45]], "batl": [[0, 1.18, 121.66], [1, 1.19, 225.81], [2, 1.39, 17.9]]}, {"timestamp": 1631545572692, "ltp": 1.39, "tv": 691.82, "trd": NaN, "batb": [[0, 1.05, 1085.45], [1, 1.01, 479.17], [2, 1.05, 0]], "batl": NaN}, {"timestamp": 1631545573879, "ltp": 1.39, "tv": 691.82, "trd": NaN, "batb": [[0, 1.01, 479.17], [1, 1.01, 0]], "batl": NaN}, {"timestamp": 1631545575287, "ltp": 1.39, "tv": 691.82, "trd": NaN, "batb": [[0, 1.16, 265.12], [1, 1.15, 168.52], [2, 1.01, 479.17]], "batl": NaN}, {"timestamp": 1631545577969, "ltp": 1.39, "tv": 691.82, "trd": NaN, "batb": [[2, 1.06, 1008.65]], "batl": NaN}, {"timestamp": 1631545589309, "ltp": 1.39, "tv": 691.82, "trd": NaN, "batb": [[0, 1.15, 81.5], [1, 1.06, 1008.65], [2, 1.01, 479.17]], "batl": [[0, 1.39, 17.9], [1, 1.4, 954.47], [2, 3.8, 27.43]]}, {"timestamp": 1631545594985, "ltp": 1.39, "tv": 691.82, "trd": NaN, "batb": [[0, 1.16, 169.7], [1, 1.15, 264.77], [2, 1.06, 1008.65]], "batl": [[0, 1.18, 208.02], [1, 1.19, 215.02], [2, 1.39, 17.9]]}, {"timestamp": 1631545600026, "ltp": 1.39, "tv": 691.82, "trd": NaN, "batb": [[0, 1.15, 81.5], [1, 1.06, 1008.65], [2, 1.01, 479.17]], "batl": [[0, 1.39, 17.9], [1, 1.4, 954.47], [2, 3.8, 27.43]]}, {"timestamp": 1631545602886, "ltp": 1.39, "tv": 691.82, "trd": NaN, "batb": [[1, 1.14, 332.75], [2, 1.06, 1008.65]], "batl": [[0, 1.2, 147.85], [1, 1.21, 200.06], [2, 1.39, 17.9]]}, {"timestamp": 1631545619807, "ltp": 1.39, "tv": 691.82, "trd": NaN, "batb": [[0, 1.06, 1008.65], [1, 1.01, 479.17], [2, 1.06, 0]], "batl": NaN}, {"timestamp": 1631545622761, "ltp": 1.39, "tv": 691.82, "trd": NaN, "batb": [[0, 1.18, 200.34], [1, 1.17, 255.48], [2, 1.06, 1008.65]], "batl": [[1, 1.21, 542.63]]}, {"timestamp": 1631545727020, "ltp": 1.18, "tv": 1072.08, "trd": [[1.18, 380.26]], "batb": [[0, 1.17, 255.48], [1, 1.06, 1008.65], [2, 1.03, 497.12]], "batl": [[1, 1.21, 505.12]]}, {"timestamp": 1631545729967, "ltp": 1.18, "tv": 1072.08, "trd": NaN, "batb": [[0, 1.17, 334.17], [1, 1.16, 95.14], [2, 1.06, 1008.65]], "batl": [[0, 1.2, 253.88]]}, {"timestamp": 1631545737071, "ltp": 1.18, "tv": 1072.08, "trd": NaN, "batb": [[0, 1.06, 1008.65], [1, 1.03, 497.12], [2, 1.01, 479.17]], "batl": [[0, 1.39, 17.9], [1, 1.4, 954.47], [2, 3.8, 27.43]]}, {"timestamp": 1631545740066, "ltp": 1.18, "tv": 1072.08, "trd": NaN, "batb": [[0, 1.15, 171.19], [1, 1.14, 267.08], [2, 1.06, 1008.65]], "batl": [[0, 1.24, 156.78], [1, 1.25, 165.08], [2, 1.39, 17.9]]}, {"timestamp": 1631545742672, "ltp": 1.18, "tv": 1072.08, "trd": NaN, "batb": NaN, "batl": [[0, 1.39, 17.9], [1, 1.4, 954.47], [2, 3.8, 27.43]]}, {"timestamp": 1631545744600, "ltp": 1.18, "tv": 1072.08, "trd": NaN, "batb": [[2, 1.03, 497.12]], "batl": NaN}, {"timestamp": 1631545745680, "ltp": 1.18, "tv": 1072.08, "trd": NaN, "batb": NaN, "batl": [[0, 1.16, 32.38], [1, 1.17, 250.41], [2, 1.18, 176.58]]}, {"timestamp": 1631545748175, "ltp": 1.18, "tv": 1072.08, "trd": NaN, "batb": [[2, 1.06, 950.7]], "batl": NaN}, {"timestamp": 1631545760875, "ltp": 1.18, "tv": 1072.08, "trd": NaN, "batb": [[0, 1.06, 950.7], [1, 1.03, 497.12], [2, 1.01, 479.17]], "batl": [[0, 1.39, 17.9], [1, 1.4, 954.47], [2, 3.8, 27.43]]}, {"timestamp": 1631545766726, "ltp": 1.18, "tv": 1072.08, "trd": NaN, "batb": [[0, 1.15, 371.4], [1, 1.06, 950.7], [2, 1.03, 497.12]], "batl": [[0, 1.17, 70.42], [1, 1.18, 246.55], [2, 1.39, 17.9]]}, {"timestamp": 1631545773841, "ltp": 1.18, "tv": 1072.08, "trd": NaN, "batb": [[0, 1.06, 950.7], [1, 1.03, 497.12], [2, 1.01, 479.17]], "batl": [[0, 1.39, 17.9], [1, 1.4, 954.47], [2, 3.8, 27.43]]}, {"timestamp": 1631545776700, "ltp": 1.18, "tv": 1072.08, "trd": NaN, "batb": [[0, 1.13, 143.74], [1, 1.12, 302.61], [2, 1.06, 950.7]], "batl": [[0, 1.2, 102.69], [1, 1.21, 204.85], [2, 1.39, 17.9]]}, {"timestamp": 1631545782730, "ltp": 1.18, "tv": 1072.08, "trd": NaN, "batb": NaN, "batl": [[0, 1.39, 17.9], [1, 1.4, 954.47], [2, 3.8, 27.43]]}, {"timestamp": 1631545784069, "ltp": 1.18, "tv": 1072.08, "trd": NaN, "batb": [[2, 1.03, 497.12]], "batl": NaN}, {"timestamp": 1631545785751, "ltp": 1.18, "tv": 1072.08, "trd": NaN, "batb": [[2, 1.01, 479.17]], "batl": [[0, 1.14, 50.35], [1, 1.15, 631.22], [2, 1.16, 74.86]]}, {"timestamp": 1631545788450, "ltp": 1.18, "tv": 1072.08, "trd": NaN, "batb": [[2, 1.04, 1300.13]], "batl": NaN}, {"timestamp": 1631545804049, "ltp": 1.18, "tv": 1072.08, "trd": NaN, "batb": NaN, "batl": [[0, 1.15, 360.44], [1, 1.16, 74.86], [2, 1.39, 17.9]]}, {"timestamp": 1631545804456, "ltp": 1.18, "tv": 1072.08, "trd": NaN, "batb": [[0, 1.04, 1300.13], [1, 1.01, 479.17], [2, 1.04, 0]], "batl": [[0, 1.39, 17.9], [1, 1.4, 954.47], [2, 3.8, 27.43]]}, {"timestamp": 1631545810854, "ltp": 1.18, "tv": 1072.08, "trd": NaN, "batb": [[0, 1.13, 310.68], [1, 1.12, 134.18], [2, 1.04, 1300.13]], "batl": [[0, 1.15, 212.98], [1, 1.16, 221.05], [2, 1.39, 17.9]]}, {"timestamp": 1631545814960, "ltp": 1.18, "tv": 1072.08, "trd": NaN, "batb": [[0, 1.04, 1300.13], [1, 1.01, 479.17], [2, 1.04, 0]], "batl": [[0, 1.39, 17.9], [1, 1.4, 954.47], [2, 3.8, 27.43]]}, {"timestamp": 1631545817865, "ltp": 1.18, "tv": 1072.08, "trd": NaN, "batb": [[0, 1.11, 392.67], [1, 1.04, 1300.13], [2, 1.01, 479.17]], "batl": [[0, 1.17, 196.56], [1, 1.18, 229.97], [2, 1.39, 17.9]]}, {"timestamp": 1631545820147, "ltp": 1.18, "tv": 1072.08, "trd": NaN, "batb": [[0, 1.04, 1300.13], [1, 1.01, 479.17], [2, 1.01, 0]], "batl": NaN}, {"timestamp": 1631545822946, "ltp": 1.18, "tv": 1072.08, "trd": NaN, "batb": [[0, 1.15, 17.48]], "batl": [[0, 1.16, 28.99], [1, 1.17, 196.56], [2, 1.18, 577.3]]}, {"timestamp": 1631545823154, "ltp": 1.18, "tv": 1072.08, "trd": NaN, "batb": [[0, 1.15, 248.56], [1, 1.14, 206.67], [2, 1.01, 479.17]], "batl": NaN}, {"timestamp": 1631545826774, "ltp": 1.18, "tv": 1072.08, "trd": NaN, "batb": [[2, 1.06, 950.7]], "batl": NaN}, {"timestamp": 1631545843067, "ltp": 1.18, "tv": 1072.08, "trd": NaN, "batb": [[0, 1.15, 231.08]], "batl": [[0, 1.17, 196.56], [1, 1.18, 229.97], [2, 1.39, 17.9]]}, {"timestamp": 1631545843275, "ltp": 1.18, "tv": 1072.08, "trd": NaN, "batb": [[0, 1.06, 950.7], [1, 1.01, 479.17], [2, 1.06, 0]], "batl": [[0, 1.39, 17.9], [1, 1.4, 954.47], [2, 3.8, 27.43]]}, {"timestamp": 1631545846296, "ltp": 1.18, "tv": 1072.08, "trd": NaN, "batb": [[0, 1.13, 88.7], [1, 1.12, 358.14], [2, 1.06, 950.7]], "batl": [[0, 1.21, 153.28], [1, 1.22, 192.4], [2, 1.39, 17.9]]}, {"timestamp": 1631545856098, "ltp": 1.18, "tv": 1072.08, "trd": NaN, "batb": NaN, "batl": [[0, 1.39, 17.9], [1, 1.4, 954.47], [2, 3.8, 27.43]]}, {"timestamp": 1631545857973, "ltp": 1.18, "tv": 1072.08, "trd": NaN, "batb": [[2, 1.01, 479.17]], "batl": NaN}, {"timestamp": 1631545859021, "ltp": 1.18, "tv": 1072.08, "trd": NaN, "batb": [[1, 1.12, 637.09]], "batl": [[0, 1.14, 107.88], [1, 1.15, 637.1], [2, 1.39, 17.9]]}, {"timestamp": 1631545862103, "ltp": 1.18, "tv": 1072.08, "trd": NaN, "batb": [[2, 1.04, 1300.13]], "batl": NaN}, {"timestamp": 1631545872036, "ltp": 1.18, "tv": 1072.08, "trd": NaN, "batb": [[1, 1.12, 358.14]], "batl": [[1, 1.15, 302.12]]}, {"timestamp": 1631545872409, "ltp": 1.18, "tv": 1072.08, "trd": NaN, "batb": [[0, 1.04, 1300.13], [1, 1.01, 479.17], [2, 1.04, 0]], "batl": [[0, 1.39, 17.9], [1, 1.4, 954.47], [2, 3.8, 27.43]]}, {"timestamp": 1631545875312, "ltp": 1.18, "tv": 1072.08, "trd": NaN, "batb": [[0, 1.11, 318], [1, 1.1, 134.87], [2, 1.04, 1300.13]], "batl": [[0, 1.17, 259.36], [1, 1.18, 167.71], [2, 1.39, 17.9]]}, {"timestamp": 1631545896041, "ltp": 1.18, "tv": 1072.08, "trd": NaN, "batb": NaN, "batl": [[0, 1.39, 17.9], [1, 1.4, 954.47], [2, 3.8, 27.43]]}, {"timestamp": 1631545898941, "ltp": 1.18, "tv": 1072.08, "trd": NaN, "batb": [[0, 1.11, 339.76], [1, 1.1, 425.24]], "batl": [[0, 1.12, 42.76], [1, 1.13, 600.63], [2, 1.14, 119.61]]}, {"timestamp": 1631545921679, "ltp": 1.18, "tv": 1072.08, "trd": NaN, "batb": [[0, 1.1, 120.26], [1, 1.04, 1300.13], [2, 1.01, 479.17]], "batl": [[0, 1.14, 103.37], [1, 1.39, 17.9], [2, 1.4, 954.47]]}, {"timestamp": 1631545924477, "ltp": 1.18, "tv": 1072.08, "trd": NaN, "batb": [[1, 1.09, 338.58], [2, 1.04, 1300.13]], "batl": [[1, 1.15, 302.35], [2, 1.39, 17.9]]}, {"timestamp": 1631545931094, "ltp": 1.18, "tv": 1072.08, "trd": NaN, "batb": NaN, "batl": [[0, 1.39, 17.9], [1, 1.4, 954.47], [2, 3.8, 27.43]]}, {"timestamp": 1631545932083, "ltp": 1.18, "tv": 1072.08, "trd": NaN, "batb": [[2, 1.01, 479.17]], "batl": NaN}, {"timestamp": 1631545933996, "ltp": 1.18, "tv": 1072.08, "trd": NaN, "batb": NaN, "batl": [[0, 1.11, 257.7], [1, 1.12, 750.49], [2, 1.39, 17.9]]}, {"timestamp": 1631545935685, "ltp": 1.18, "tv": 1072.08, "trd": NaN, "batb": [[2, 1.03, 1558.63]], "batl": NaN}, {"timestamp": 1631545944524, "ltp": 1.18, "tv": 1072.08, "trd": NaN, "batb": [[0, 1.03, 1558.63], [1, 1.01, 479.17], [2, 1.03, 0]], "batl": [[0, 1.39, 17.9], [1, 1.4, 954.47], [2, 3.8, 27.43]]}, {"timestamp": 1631545950945, "ltp": 1.18, "tv": 1072.08, "trd": NaN, "batb": [[0, 1.09, 459.95], [1, 1.03, 1558.63], [2, 1.01, 479.17]], "batl": [[0, 1.11, 308.78], [1, 1.12, 141.6], [2, 1.39, 17.9]]}, {"timestamp": 1631545954650, "ltp": 1.18, "tv": 1072.08, "trd": NaN, "batb": [[0, 1.03, 1558.63], [1, 1.01, 479.17], [2, 1.01, 0]], "batl": [[0, 1.39, 17.9], [1, 1.4, 954.47], [2, 3.8, 27.43]]}, {"timestamp": 1631545957619, "ltp": 1.18, "tv": 1072.08, "trd": NaN, "batb": [[0, 1.08, 464.21], [1, 1.03, 1558.63], [2, 1.01, 479.17]], "batl": [[0, 1.13, 324.99], [1, 1.14, 117.63], [2, 1.39, 17.9]]}, {"timestamp": 1631545968673, "ltp": 1.18, "tv": 1072.08, "trd": NaN, "batb": [[0, 1.03, 1558.63], [1, 1.01, 479.17], [2, 1.01, 0]], "batl": NaN}, {"timestamp": 1631545970591, "ltp": 1.18, "tv": 1072.08, "trd": NaN, "batb": [[0, 1.01, 479.17], [1, 1.01, 0]], "batl": NaN}, {"timestamp": 1631545971580, "ltp": 1.18, "tv": 1072.08, "trd": NaN, "batb": [[0, 1.11, 338.96], [1, 1.1, 431.83], [2, 1.01, 479.17]], "batl": [[0, 1.12, 41.36], [1, 1.13, 593.61], [2, 1.14, 117.63]]}, {"timestamp": 1631545974181, "ltp": 1.18, "tv": 1072.08, "trd": NaN, "batb": [[2, 1.04, 1252.86]], "batl": NaN}, {"timestamp": 1631545989537, "ltp": 1.18, "tv": 1072.08, "trd": NaN, "batb": [[0, 1.04, 1252.86], [1, 1.01, 479.17], [2, 1.04, 0]], "batl": [[0, 1.39, 17.9], [1, 1.4, 954.47], [2, 3.8, 27.43]]}, {"timestamp": 1631545992542, "ltp": 1.18, "tv": 1072.08, "trd": NaN, "batb": [[0, 1.09, 459.95], [1, 1.04, 1252.86], [2, 1.01, 479.17]], "batl": [[0, 1.15, 348.98], [1, 1.16, 86.22], [2, 1.39, 17.9]]}, {"timestamp": 1631545994523, "ltp": 1.18, "tv": 1072.08, "trd": NaN, "batb": [[0, 1.04, 1252.86], [1, 1.01, 479.17], [2, 1.01, 0]], "batl": NaN}, {"timestamp": 1631545996046, "ltp": 1.18, "tv": 1072.08, "trd": NaN, "batb": [[0, 1.01, 479.17], [1, 1.01, 0]], "batl": NaN}, {"timestamp": 1631545997432, "ltp": 1.18, "tv": 1072.08, "trd": NaN, "batb": [[0, 1.13, 156.72], [1, 1.12, 289.51], [2, 1.01, 479.17]], "batl": [[0, 1.14, 49.22], [1, 1.15, 621.24], [2, 1.16, 86.22]]}, {"timestamp": 1631545999435, "ltp": 1.18, "tv": 1072.08, "trd": NaN, "batb": [[2, 1.04, 1300.13]], "batl": NaN}, {"timestamp": 1631546016585, "ltp": 1.18, "tv": 1072.08, "trd": NaN, "batb": [[0, 1.04, 1300.13], [1, 1.01, 479.17], [2, 1.04, 0]], "batl": [[0, 1.16, 86.22], [1, 1.39, 17.9], [2, 1.4, 954.47]]}, {"timestamp": 1631546019581, "ltp": 1.18, "tv": 1072.08, "trd": NaN, "batb": [[0, 1.11, 304.93], [1, 1.1, 148.07], [2, 1.04, 1300.13]], "batl": [[1, 1.17, 262.47], [2, 1.39, 17.9]]}, {"timestamp": 1631546023499, "ltp": 1.18, "tv": 1072.08, "trd": NaN, "batb": NaN, "batl": [[0, 1.39, 17.9], [1, 1.4, 954.47], [2, 3.8, 27.43]]}, {"timestamp": 1631546026365, "ltp": 1.18, "tv": 1072.08, "trd": NaN, "batb": [[0, 1.11, 329.85], [1, 1.1, 445.35]], "batl": [[0, 1.12, 39.84], [1, 1.13, 589.88], [2, 1.14, 108.43]]}, {"timestamp": 1631546037827, "ltp": 1.18, "tv": 1072.08, "trd": NaN, "batb": [[0, 1.04, 1300.13], [1, 1.01, 479.17], [2, 1.04, 0]], "batl": [[0, 1.39, 17.9], [1, 1.4, 954.47], [2, 3.8, 27.43]]}, {"timestamp": 1631546040824, "ltp": 1.18, "tv": 1072.08, "trd": NaN, "batb": [[0, 1.09, 387.72], [1, 1.08, 72.89], [2, 1.04, 1300.13]], "batl": [[0, 1.15, 241.35], [1, 1.16, 192.92], [2, 1.39, 17.9]]}, {"timestamp": 1631546041663, "ltp": 1.18, "tv": 1072.08, "trd": NaN, "batb": [[0, 1.04, 1300.13], [1, 1.01, 479.17], [2, 1.04, 0]], "batl": [[0, 1.39, 17.9], [1, 1.4, 954.47], [2, 3.8, 27.43]]}, {"timestamp": 1631546042832, "ltp": 1.18, "tv": 1072.08, "trd": NaN, "batb": [[0, 1.01, 479.17], [1, 1.01, 0]], "batl": NaN}, {"timestamp": 1631546044668, "ltp": 1.18, "tv": 1072.08, "trd": NaN, "batb": [[0, 1.11, 128.12], [1, 1.1, 326.48], [2, 1.01, 479.17]], "batl": [[0, 1.12, 134.53], [1, 1.13, 310.33], [2, 1.39, 17.9]]}, {"timestamp": 1631546047151, "ltp": 1.18, "tv": 1072.08, "trd": NaN, "batb": [[2, 1.03, 1558.63]], "batl": NaN}, {"timestamp": 1631546049486, "ltp": 1.18, "tv": 1072.08, "trd": NaN, "batb": [[0, 1.03, 1558.63], [1, 1.01, 479.17], [2, 1.03, 0]], "batl": [[0, 1.39, 17.9], [1, 1.4, 954.47], [2, 3.8, 27.43]]}, {"timestamp": 1631546052347, "ltp": 1.18, "tv": 1072.08, "trd": NaN, "batb": [[0, 1.09, 387.72], [1, 1.08, 72.89], [2, 1.03, 1558.63]], "batl": [[0, 1.15, 241.35], [1, 1.16, 192.92], [2, 1.39, 17.9]]}, {"timestamp": 1631546057083, "ltp": 1.18, "tv": 1072.08, "trd": NaN, "batb": NaN, "batl": [[0, 1.39, 17.9], [1, 1.4, 954.47], [2, 3.8, 27.43]]}, {"timestamp": 1631546060089, "ltp": 1.18, "tv": 1072.08, "trd": NaN, "batb": [[1, 1.08, 473.27], [2, 1.01, 7]], "batl": [[0, 1.1, 19.36], [1, 1.11, 716.43], [2, 1.39, 17.9]]}, {"timestamp": 1631546062979, "ltp": 1.18, "tv": 1072.08, "trd": NaN, "batb": NaN, "batl": [[2, 1.25, 14.92]]}, {"timestamp": 1631546063499, "ltp": 1.18, "tv": 1072.08, "trd": NaN, "batb": [[2, 1.02, 2179.83]], "batl": NaN}, {"timestamp": 1631546078807, "ltp": 1.18, "tv": 1072.08, "trd": NaN, "batb": [[0, 1.02, 2179.83], [1, 1.01, 7], [2, 1.02, 0]], "batl": [[0, 1.25, 14.92], [1, 1.33, 1138.02], [2, 1.39, 17.9]]}, {"timestamp": 1631546081807, "ltp": 1.18, "tv": 1072.08, "trd": NaN, "batb": [[0, 1.07, 468.55], [1, 1.02, 2179.83], [2, 1.01, 7]], "batl": [[0, 1.13, 316.85], [1, 1.14, 125.7], [2, 1.25, 14.92]]}, {"timestamp": 1631546082214, "ltp": 1.18, "tv": 1072.08, "trd": NaN, "batb": [[0, 1.02, 2179.83], [1, 1.01, 7], [2, 1.01, 0]], "batl": [[0, 1.25, 14.92], [1, 1.33, 1138.02], [2, 1.39, 17.9]]}, {"timestamp": 1631546085095, "ltp": 1.18, "tv": 1072.08, "trd": NaN, "batb": [[0, 1.09, 177.37], [1, 1.08, 285.19], [2, 1.02, 2179.83]], "batl": [[0, 1.1, 180.18], [1, 1.11, 273.1], [2, 1.25, 14.92]]}, {"timestamp": 1631546087219, "ltp": 1.18, "tv": 1072.08, "trd": NaN, "batb": [[0, 1.02, 2179.83], [1, 1.01, 7], [2, 1.02, 0]], "batl": [[0, 1.25, 14.92], [1, 1.33, 1138.02], [2, 1.39, 17.9]]}, {"timestamp": 1631546090105, "ltp": 1.18, "tv": 1072.08, "trd": NaN, "batb": [[0, 1.07, 468.55], [1, 1.02, 2179.83], [2, 1.01, 7]], "batl": [[0, 1.13, 316.85], [1, 1.14, 125.7], [2, 1.25, 14.92]]}, {"timestamp": 1631546093219, "ltp": 1.18, "tv": 1072.08, "trd": NaN, "batb": [[0, 1.02, 2179.83], [1, 1.01, 7], [2, 1.01, 0]], "batl": NaN}, {"timestamp": 1631546094714, "ltp": 1.18, "tv": 1072.08, "trd": NaN, "batb": [[0, 1.01, 7], [1, 1.01, 0]], "batl": NaN}, {"timestamp": 1631546096127, "ltp": 1.18, "tv": 1072.08, "trd": NaN, "batb": [[0, 1.11, 351.49], [1, 1.1, 423.35], [2, 1.01, 7]], "batl": [[0, 1.12, 38.49], [1, 1.13, 554.4], [2, 1.14, 125.7]]}, {"timestamp": 1631546098904, "ltp": 1.18, "tv": 1072.08, "trd": NaN, "batb": [[2, 1.04, 1252.86]], "batl": NaN}, {"timestamp": 1631546111743, "ltp": 1.18, "tv": 1072.08, "trd": NaN, "batb": [[0, 1.11, 325.11], [1, 1.1, 127.69]], "batl": [[0, 1.13, 316.85], [1, 1.14, 125.7], [2, 1.25, 14.92]]}, {"timestamp": 1631546112327, "ltp": 1.18, "tv": 1072.08, "trd": NaN, "batb": [[0, 1.04, 1252.86], [1, 1.01, 7], [2, 1.04, 0]], "batl": [[0, 1.25, 14.92], [1, 1.33, 1138.02], [2, 1.39, 17.9]]}, {"timestamp": 1631546115259, "ltp": 1.18, "tv": 1072.08, "trd": NaN, "batb": [[0, 1.09, 408.57], [1, 1.04, 1252.86], [2, 1.01, 7]], "batl": [[0, 1.15, 225.14], [1, 1.16, 208.99], [2, 1.25, 14.92]]}, {"timestamp": 1631546131703, "ltp": 1.18, "tv": 1072.08, "trd": NaN, "batb": NaN, "batl": [[2, 1.2, 8.47]]}, {"timestamp": 1631546139627, "ltp": 1.18, "tv": 1072.08, "trd": NaN, "batb": NaN, "batl": [[0, 1.2, 8.47], [1, 1.25, 14.92], [2, 1.33, 1138.02]]}, {"timestamp": 1631546140835, "ltp": 1.18, "tv": 1072.08, "trd": NaN, "batb": [[1, 1.01, 7], [2, 1.01, 0]], "batl": NaN}, {"timestamp": 1631546142815, "ltp": 1.18, "tv": 1072.08, "trd": NaN, "batb": [[1, 1.08, 406.85], [2, 1.01, 7]], "batl": [[0, 1.1, 18.48], [1, 1.11, 910.66], [2, 1.2, 8.47]]}, {"timestamp": 1631546144542, "ltp": 1.18, "tv": 1072.08, "trd": NaN, "batb": [[2, 1.02, 2179.83]], "batl": NaN}, {"timestamp": 1631546150743, "ltp": 1.18, "tv": 1072.08, "trd": NaN, "batb": NaN, "batl": [[2, 1.25, 14.92]]}, {"timestamp": 1631546154351, "ltp": 1.18, "tv": 1072.08, "trd": NaN, "batb": NaN, "batl": [[1, 1.11, 689.25]]}, {"timestamp": 1631546163878, "ltp": 1.09, "tv": 1089.02, "trd": [[1.09, 16.94]], "batb": [[0, 1.09, 400.1]], "batl": NaN}, {"timestamp": 1631546178602, "ltp": 1.09, "tv": 1089.02, "trd": NaN, "batb": [[0, 1.02, 2179.83], [1, 1.01, 7], [2, 1.02, 0]], "batl": [[0, 1.25, 14.92], [1, 1.33, 1138.02], [2, 1.39, 17.9]]}, {"timestamp": 1631546181610, "ltp": 1.09, "tv": 1089.02, "trd": NaN, "batb": [[0, 1.07, 468.55], [1, 1.02, 2179.83], [2, 1.01, 7]], "batl": [[0, 1.13, 305.38], [1, 1.14, 137.07], [2, 1.25, 14.92]]}, {"timestamp": 1631546191701, "ltp": 1.09, "tv": 1089.02, "trd": NaN, "batb": [[0, 1.03, 8.47]], "batl": NaN}, {"timestamp": 1631546192800, "ltp": 1.09, "tv": 1089.02, "trd": NaN, "batb": [[1, 1.01, 7], [2, 1.01, 0]], "batl": NaN}, {"timestamp": 1631546194682, "ltp": 1.09, "tv": 1089.02, "trd": NaN, "batb": [[0, 1.11, 605.91], [1, 1.1, 413.65], [2, 1.03, 8.47]], "batl": [[0, 1.12, 37.23], [1, 1.13, 535.89], [2, 1.14, 137.07]]}, {"timestamp": 1631546196442, "ltp": 1.09, "tv": 1089.02, "trd": NaN, "batb": [[2, 1.04, 1252.86]], "batl": NaN}, {"timestamp": 1631546206218, "ltp": 1.09, "tv": 1089.02, "trd": NaN, "batb": [[0, 1.11, 366.94]], "batl": NaN}, {"timestamp": 1631546210424, "ltp": 1.09, "tv": 1089.02, "trd": NaN, "batb": [[0, 1.04, 1252.86], [1, 1.03, 8.47], [2, 1.01, 7]], "batl": [[0, 1.25, 14.92], [1, 1.33, 1138.02], [2, 1.39, 17.9]]}, {"timestamp": 1631546213380, "ltp": 1.09, "tv": 1089.02, "trd": NaN, "batb": [[0, 1.09, 423.17], [1, 1.04, 1252.86], [2, 1.03, 8.47]], "batl": [[0, 1.15, 214.71], [1, 1.16, 219.34], [2, 1.25, 14.92]]}, {"timestamp": 1631546218448, "ltp": 1.09, "tv": 1089.02, "trd": NaN, "batb": NaN, "batl": [[0, 1.25, 14.92], [1, 1.33, 1138.02], [2, 1.39, 17.9]]}, {"timestamp": 1631546220445, "ltp": 1.09, "tv": 1089.02, "trd": NaN, "batb": [[1, 1.03, 8.47], [2, 1.01, 7]], "batl": NaN}, {"timestamp": 1631546221813, "ltp": 1.09, "tv": 1089.02, "trd": NaN, "batb": [[1, 1.08, 413.67], [2, 1.03, 8.47]], "batl": [[0, 1.1, 17.56], [1, 1.11, 889.11], [2, 1.25, 14.92]]}, {"timestamp": 1631546233230, "ltp": 1.09, "tv": 1089.02, "trd": NaN, "batb": NaN, "batl": [[1, 1.11, 667.75]]}, {"timestamp": 1631546236975, "ltp": 1.09, "tv": 1089.02, "trd": NaN, "batb": [[1, 1.03, 8.47], [2, 1.02, 2179.83]], "batl": [[0, 1.11, 396.52], [1, 1.25, 14.92], [2, 1.33, 1138.02]]}, {"timestamp": 1631546237184, "ltp": 1.09, "tv": 1089.02, "trd": NaN, "batb": [[0, 1.03, 8.47], [1, 1.02, 2179.83], [2, 1.01, 7]], "batl": [[0, 1.25, 14.92], [1, 1.33, 1138.02], [2, 1.39, 17.9]]}, {"timestamp": 1631546240154, "ltp": 1.09, "tv": 1089.02, "trd": NaN, "batb": [[0, 1.07, 468.55], [1, 1.03, 8.47], [2, 1.02, 2179.83]], "batl": [[0, 1.13, 288.93], [1, 1.14, 153.38], [2, 1.25, 14.92]]}, {"timestamp": 1631546247758, "ltp": 1.09, "tv": 1089.02, "trd": NaN, "batb": NaN, "batl": [[0, 1.25, 14.92], [1, 1.33, 1138.02], [2, 1.39, 17.9]]}, {"timestamp": 1631546249191, "ltp": 1.09, "tv": 1089.02, "trd": NaN, "batb": [[2, 1.01, 7]], "batl": NaN}, {"timestamp": 1631546250666, "ltp": 1.09, "tv": 1089.02, "trd": NaN, "batb": NaN, "batl": [[0, 1.09, 784.67], [1, 1.25, 14.92], [2, 1.33, 1138.02]]}, {"timestamp": 1631546253396, "ltp": 1.09, "tv": 1089.02, "trd": NaN, "batb": [[2, 1.01, 4165.03]], "batl": [[1, 1.23, 29.82], [2, 1.25, 14.92]]}, {"timestamp": 1631546254695, "ltp": 1.09, "tv": 1129.02, "trd": [[1.09, 56.94]], "batb": NaN, "batl": [[0, 1.09, 764.67]]}, {"timestamp": 1631546262200, "ltp": 1.09, "tv": 1129.02, "trd": NaN, "batb": NaN, "batl": [[0, 1.09, 559.09]]}, {"timestamp": 1631546272614, "ltp": 1.09, "tv": 1129.02, "trd": NaN, "batb": [[2, 1.01, 4167.03]], "batl": NaN}, {"timestamp": 1631546283540, "ltp": 1.09, "tv": 1133.02, "trd": [[1.09, 60.94]], "batb": NaN, "batl": [[0, 1.09, 557.09]]}, {"timestamp": 1631546293741, "ltp": 1.09, "tv": 1133.02, "trd": NaN, "batb": NaN, "batl": [[0, 1.09, 459.95]]}, {"timestamp": 1631546296624, "ltp": 1.09, "tv": 1133.02, "trd": NaN, "batb": NaN, "batl": [[0, 1.09, 557.09]]}, {"timestamp": 1631546303648, "ltp": 1.09, "tv": 1149.96, "trd": [[1.09, 77.88]], "batb": NaN, "batl": [[0, 1.09, 548.62]]}, {"timestamp": 1631546307148, "ltp": 1.09, "tv": 1149.96, "trd": NaN, "batb": NaN, "batl": [[0, 1.09, 557.09]]}, {"timestamp": 1631546331283, "ltp": 1.09, "tv": 1149.96, "trd": NaN, "batb": NaN, "batl": [[0, 1.08, 28.14], [1, 1.09, 557.09], [2, 1.23, 29.82]]}, {"timestamp": 1631546334607, "ltp": 1.09, "tv": 1149.96, "trd": NaN, "batb": NaN, "batl": [[2, 1.21, 14.92]]}, {"timestamp": 1631546391078, "ltp": 1.09, "tv": 1149.96, "trd": NaN, "batb": [[0, 1.03, 8.47], [1, 1.01, 4167.03], [2, 1.01, 0]], "batl": [[1, 1.21, 14.92], [2, 1.23, 29.82]]}, {"timestamp": 1631546393984, "ltp": 1.09, "tv": 1149.96, "trd": NaN, "batb": [[0, 1.06, 472.97], [1, 1.03, 8.47], [2, 1.01, 4167.03]], "batl": [[1, 1.1, 129.55], [2, 1.11, 323.28]]}, {"timestamp": 1631546394610, "ltp": 1.09, "tv": 1149.96, "trd": NaN, "batb": [[0, 1.03, 8.47], [1, 1.01, 4167.03], [2, 1.01, 0]], "batl": [[1, 1.21, 14.92], [2, 1.23, 29.82]]}, {"timestamp": 1631546396890, "ltp": 1.09, "tv": 1149.96, "trd": NaN, "batb": [[0, 1.07, 468.55], [1, 1.03, 8.47], [2, 1.01, 4167.03]], "batl": [[1, 1.09, 373.68], [2, 1.21, 14.92]]}, {"timestamp": 1631546397203, "ltp": 1.09, "tv": 1149.96, "trd": NaN, "batb": NaN, "batl": [[2, 1.1, 85.49]]}, {"timestamp": 1631546402628, "ltp": 1.09, "tv": 1149.96, "trd": NaN, "batb": [[0, 1.03, 8.47], [1, 1.01, 4167.03], [2, 1.01, 0]], "batl": [[1, 1.1, 85.49], [2, 1.21, 14.92]]}, {"timestamp": 1631546405607, "ltp": 1.09, "tv": 1149.96, "trd": NaN, "batb": [[0, 1.06, 472.97], [1, 1.03, 8.47], [2, 1.01, 4167.03]], "batl": [[1, 1.1, 129.55], [2, 1.11, 323.28]]}, {"timestamp": 1631546406609, "ltp": 1.09, "tv": 1149.96, "trd": NaN, "batb": [[0, 1.03, 8.47], [1, 1.01, 4167.03], [2, 1.01, 0]], "batl": NaN}, {"timestamp": 1631546408030, "ltp": 1.09, "tv": 1149.96, "trd": NaN, "batb": [[1, 1.01, 9]], "batl": NaN}, {"timestamp": 1631546409951, "ltp": 1.08, "tv": 1178.09, "trd": [[1.08, 28.14]], "batb": [[0, 1.09, 233.07], [1, 1.08, 228.97], [2, 1.03, 8.47]], "batl": [[0, 1.1, 147.02], [1, 1.11, 604.83], [2, 1.21, 14.92]]}, {"timestamp": 1631546419532, "ltp": 1.08, "tv": 1178.09, "trd": NaN, "batb": NaN, "batl": [[0, 1.1, 129.55]]}, {"timestamp": 1631546422534, "ltp": 1.08, "tv": 1178.09, "trd": NaN, "batb": [[1, 1.08, 288.46]], "batl": [[0, 1.1, 160.84]]}, {"timestamp": 1631546429455, "ltp": 1.08, "tv": 1178.09, "trd": NaN, "batb": [[0, 1.03, 8.47], [1, 1.02, 2179.83], [2, 1.01, 9]], "batl": [[0, 1.21, 14.92], [1, 1.23, 29.82], [2, 1.25, 14.92]]}, {"timestamp": 1631546432448, "ltp": 1.08, "tv": 1178.09, "trd": NaN, "batb": [[0, 1.07, 468.55], [1, 1.03, 8.47], [2, 1.02, 2179.83]], "batl": [[0, 1.13, 372.81], [1, 1.14, 70.23], [2, 1.21, 14.92]]}, {"timestamp": 1631546436653, "ltp": 1.08, "tv": 1178.09, "trd": NaN, "batb": NaN, "batl": [[0, 1.21, 14.92], [1, 1.23, 29.82], [2, 1.25, 14.92]]}, {"timestamp": 1631546438670, "ltp": 1.08, "tv": 1178.09, "trd": NaN, "batb": [[2, 1.01, 9]], "batl": NaN}, {"timestamp": 1631546439558, "ltp": 1.08, "tv": 1178.09, "trd": NaN, "batb": NaN, "batl": [[0, 1.09, 494.33], [1, 1.1, 350.61], [2, 1.21, 14.92]]}, {"timestamp": 1631546442739, "ltp": 1.08, "tv": 1178.09, "trd": NaN, "batb": [[2, 1.01, 4167.03]], "batl": NaN}, {"timestamp": 1631546447352, "ltp": 1.08, "tv": 1178.09, "trd": NaN, "batb": [[0, 1.03, 8.47], [1, 1.01, 4167.03], [2, 1.01, 0]], "batl": [[0, 1.21, 14.92], [1, 1.23, 29.82], [2, 1.25, 14.92]]}, {"timestamp": 1631546450412, "ltp": 1.08, "tv": 1178.09, "trd": NaN, "batb": [[0, 1.06, 472.97], [1, 1.03, 8.47], [2, 1.01, 4167.03]], "batl": [[0, 1.11, 273.37], [1, 1.12, 176.7], [2, 1.21, 14.92]]}, {"timestamp": 1631546457006, "ltp": 1.08, "tv": 1178.09, "trd": NaN, "batb": NaN, "batl": [[0, 1.21, 14.92], [1, 1.23, 29.82], [2, 1.25, 14.92]]}, {"timestamp": 1631546458104, "ltp": 1.08, "tv": 1178.09, "trd": NaN, "batb": [[2, 1.01, 9]], "batl": NaN}, {"timestamp": 1631546459891, "ltp": 1.08, "tv": 1178.09, "trd": NaN, "batb": NaN, "batl": [[0, 1.07, 56.93], [1, 1.08, 658.79], [2, 1.21, 14.92]]}, {"timestamp": 1631546462209, "ltp": 1.08, "tv": 1178.09, "trd": NaN, "batb": [[2, 1.01, 3979.74]], "batl": NaN}, {"timestamp": 1631546473396, "ltp": 1.08, "tv": 1178.09, "trd": NaN, "batb": [[0, 1.03, 8.47], [1, 1.01, 3979.74], [2, 1.01, 0]], "batl": [[0, 1.21, 14.92], [1, 1.23, 29.82], [2, 1.25, 14.92]]}, {"timestamp": 1631546476428, "ltp": 1.08, "tv": 1178.09, "trd": NaN, "batb": [[0, 1.05, 477.47], [1, 1.03, 8.47], [2, 1.01, 3979.74]], "batl": [[0, 1.09, 202.91], [1, 1.1, 254.7], [2, 1.21, 14.92]]}, {"timestamp": 1631546484223, "ltp": 1.08, "tv": 1178.09, "trd": NaN, "batb": [[0, 1.03, 8.47], [1, 1.01, 3979.74], [2, 1.01, 0]], "batl": NaN}, {"timestamp": 1631546487036, "ltp": 1.08, "tv": 1178.09, "trd": NaN, "batb": [[1, 1.01, 9]], "batl": [[0, 1.09, 287.36], [1, 1.1, 472.22]]}, {"timestamp": 1631546487244, "ltp": 1.08, "tv": 1178.09, "trd": NaN, "batb": [[0, 1.08, 220.48], [1, 1.07, 246.01], [2, 1.03, 8.47]], "batl": NaN}, {"timestamp": 1631546505943, "ltp": 1.08, "tv": 1178.09, "trd": NaN, "batb": NaN, "batl": [[0, 1.09, 202.91], [1, 1.1, 254.7]]}, {"timestamp": 1631546506150, "ltp": 1.08, "tv": 1178.09, "trd": NaN, "batb": [[0, 1.03, 8.47], [1, 1.01, 4167.03], [2, 1.03, 0]], "batl": [[0, 1.21, 14.92], [1, 1.23, 29.82], [2, 1.25, 14.92]]}, {"timestamp": 1631546509159, "ltp": 1.08, "tv": 1178.09, "trd": NaN, "batb": [[0, 1.06, 472.97], [1, 1.03, 8.47], [2, 1.01, 4167.03]], "batl": [[0, 1.12, 265.49], [1, 1.13, 180.53], [2, 1.21, 14.92]]}, {"timestamp": 1631546512884, "ltp": 1.08, "tv": 1178.09, "trd": NaN, "batb": NaN, "batl": [[0, 1.21, 14.92], [1, 1.23, 29.82], [2, 1.25, 14.92]]}, {"timestamp": 1631546513970, "ltp": 1.08, "tv": 1178.09, "trd": NaN, "batb": [[2, 1.01, 9]], "batl": NaN}, {"timestamp": 1631546515860, "ltp": 1.08, "tv": 1178.09, "trd": NaN, "batb": [[0, 1.06, 846]], "batl": [[0, 1.07, 142.79], [1, 1.08, 621], [2, 1.21, 14.92]]}, {"timestamp": 1631546517891, "ltp": 1.08, "tv": 1178.09, "trd": NaN, "batb": [[2, 1.01, 3979.74]], "batl": NaN}, {"timestamp": 1631546523664, "ltp": 1.08, "tv": 1178.09, "trd": NaN, "batb": [[0, 1.03, 8.47], [1, 1.01, 3979.74], [2, 1.01, 0]], "batl": [[0, 1.21, 14.92], [1, 1.23, 29.82], [2, 1.25, 14.92]]}, {"timestamp": 1631546526704, "ltp": 1.08, "tv": 1178.09, "trd": NaN, "batb": [[0, 1.05, 425.78], [1, 1.03, 8.47], [2, 1.01, 3979.74]], "batl": [[0, 1.09, 74.02], [1, 1.1, 382.42], [2, 1.21, 14.92]]}, {"timestamp": 1631546535507, "ltp": 1.08, "tv": 1178.09, "trd": NaN, "batb": NaN, "batl": [[0, 1.21, 14.92], [1, 1.23, 29.82], [2, 1.25, 14.92]]}, {"timestamp": 1631546537290, "ltp": 1.08, "tv": 1178.09, "trd": NaN, "batb": [[2, 1.01, 9]], "batl": NaN}, {"timestamp": 1631546538493, "ltp": 1.08, "tv": 1178.09, "trd": NaN, "batb": [[1, 1.04, 829.19], [2, 1.03, 8.47]], "batl": [[0, 1.06, 460.31], [1, 1.07, 907.61], [2, 1.21, 14.92]]}, {"timestamp": 1631546575566, "ltp": 1.08, "tv": 1178.09, "trd": NaN, "batb": [[0, 1.04, 829.19], [1, 1.03, 8.47], [2, 1.01, 9]], "batl": [[0, 1.06, 116.87]]}, {"timestamp": 1631546578875, "ltp": 1.08, "tv": 1178.09, "trd": NaN, "batb": [[0, 1.04, 1311.26]], "batl": [[1, 1.07, 939.13], [2, 1.08, 305.84]]}, {"timestamp": 1631546585758, "ltp": 1.08, "tv": 1178.09, "trd": NaN, "batb": [[1, 1.01, 9], [2, 1.01, 0]], "batl": NaN}, {"timestamp": 1631546633724, "ltp": 1.08, "tv": 1178.09, "trd": NaN, "batb": [[0, 1.04, 482.07]], "batl": [[0, 1.07, 159.84], [1, 1.08, 305.84], [2, 1.21, 14.92]]}, {"timestamp": 1631546637141, "ltp": 1.08, "tv": 1178.09, "trd": NaN, "batb": [[0, 1.04, 267.58]], "batl": [[0, 1.21, 14.92], [1, 1.23, 29.82], [2, 1.25, 14.92]]}, {"timestamp": 1631546640058, "ltp": 1.08, "tv": 1178.09, "trd": NaN, "batb": [[0, 1.05, 212.44], [1, 1.04, 267.58], [2, 1.01, 9]], "batl": [[0, 1.06, 472.97], [1, 1.21, 14.92], [2, 1.23, 29.82]]}, {"timestamp": 1631546647067, "ltp": 1.08, "tv": 1178.09, "trd": NaN, "batb": [[0, 1.04, 267.58], [1, 1.01, 9], [2, 1.01, 0]], "batl": [[0, 1.21, 14.92], [1, 1.23, 29.82], [2, 1.25, 14.92]]}, {"timestamp": 1631546650077, "ltp": 1.08, "tv": 1178.09, "trd": NaN, "batb": [[0, 1.04, 482.07]], "batl": [[0, 1.07, 159.84], [1, 1.08, 305.84], [2, 1.21, 14.92]]}, {"timestamp": 1631546655248, "ltp": 1.08, "tv": 1178.09, "trd": NaN, "batb": [[0, 1.01, 9], [1, 1.01, 0]], "batl": NaN}, {"timestamp": 1631546658075, "ltp": 1.08, "tv": 1178.09, "trd": NaN, "batb": [[0, 1.06, 31.74], [1, 1.05, 630.9], [2, 1.01, 9]], "batl": [[0, 1.07, 248.6], [1, 1.08, 588.82]]}, {"timestamp": 1631546658286, "ltp": 1.08, "tv": 1178.09, "trd": NaN, "batb": [[0, 1.06, 504.71]], "batl": NaN}, {"timestamp": 1631546660648, "ltp": 1.08, "tv": 1178.09, "trd": NaN, "batb": [[2, 1.01, 3979.74]], "batl": NaN}, {"timestamp": 1631546679798, "ltp": 1.08, "tv": 1178.09, "trd": NaN, "batb": [[0, 1.01, 3979.74], [1, 1.05, 0], [2, 1.01, 0]], "batl": [[0, 1.21, 14.92], [1, 1.23, 29.82], [2, 1.25, 14.92]]}, {"timestamp": 1631546682716, "ltp": 1.08, "tv": 1178.09, "trd": NaN, "batb": [[0, 1.05, 441.59], [1, 1.01, 3979.74]], "batl": [[0, 1.09, 459.95], [1, 1.21, 14.92], [2, 1.23, 29.82]]}, {"timestamp": 1631546689012, "ltp": 1.08, "tv": 1178.09, "trd": NaN, "batb": NaN, "batl": [[0, 1.21, 14.92], [1, 1.23, 29.82], [2, 1.25, 14.92]]}, {"timestamp": 1631546691103, "ltp": 1.08, "tv": 1178.09, "trd": NaN, "batb": [[1, 1.01, 9]], "batl": NaN}, {"timestamp": 1631546691932, "ltp": 1.08, "tv": 1178.09, "trd": NaN, "batb": [[1, 1.04, 835.2], [2, 1.01, 9]], "batl": [[0, 1.06, 447.03], [1, 1.07, 3830.86], [2, 1.21, 14.92]]}, {"timestamp": 1631546692305, "ltp": 1.08, "tv": 1178.09, "trd": NaN, "batb": NaN, "batl": [[1, 1.07, 1163.14]]}, {"timestamp": 1631546701929, "ltp": 1.08, "tv": 1178.09, "trd": NaN, "batb": [[0, 1.01, 9], [1, 1.04, 0], [2, 1.01, 0]], "batl": [[0, 1.21, 14.92], [1, 1.23, 29.82], [2, 1.25, 14.92]]}, {"timestamp": 1631546704927, "ltp": 1.08, "tv": 1178.09, "trd": NaN, "batb": [[0, 1.04, 337.29], [1, 1.03, 146.18], [2, 1.01, 9]], "batl": [[0, 1.08, 464.21], [1, 1.21, 14.92], [2, 1.23, 29.82]]}, {"timestamp": 1631546714954, "ltp": 1.08, "tv": 1178.09, "trd": NaN, "batb": [[0, 1.01, 9], [1, 1.03, 0], [2, 1.01, 0]], "batl": NaN}, {"timestamp": 1631546717837, "ltp": 1.08, "tv": 1178.09, "trd": NaN, "batb": [[0, 1.06, 3523.64], [1, 1.01, 9]], "batl": [[0, 1.07, 71.18], [1, 1.08, 695.43], [2, 1.21, 14.92]]}, {"timestamp": 1631546718146, "ltp": 1.08, "tv": 1178.09, "trd": NaN, "batb": [[0, 1.06, 719.53]], "batl": NaN}, {"timestamp": 1631546720355, "ltp": 1.08, "tv": 1178.09, "trd": NaN, "batb": [[1, 1.01, 3979.74]], "batl": NaN}, {"timestamp": 1631546729666, "ltp": 1.08, "tv": 1178.09, "trd": NaN, "batb": [[0, 1.06, 472.97]], "batl": NaN}, {"timestamp": 1631546739069, "ltp": 1.08, "tv": 1178.09, "trd": NaN, "batb": [[0, 1.01, 3979.74], [1, 1.01, 0]], "batl": [[0, 1.21, 14.92], [1, 1.23, 29.82], [2, 1.25, 14.92]]}, {"timestamp": 1631546741997, "ltp": 1.08, "tv": 1178.09, "trd": NaN, "batb": [[0, 1.05, 457.26], [1, 1.01, 3979.74]], "batl": [[0, 1.09, 323.34], [1, 1.1, 135.36], [2, 1.21, 14.92]]}, {"timestamp": 1631546746987, "ltp": 1.08, "tv": 1178.09, "trd": NaN, "batb": [[0, 1.01, 3979.74], [1, 1.01, 0]], "batl": NaN}, {"timestamp": 1631546748867, "ltp": 1.08, "tv": 1178.09, "trd": NaN, "batb": [[0, 1.01, 9]], "batl": NaN}, {"timestamp": 1631546750058, "ltp": 1.08, "tv": 1205.51, "trd": [[1.08, 55.56]], "batb": [[0, 1.08, 72.64], [1, 1.07, 381.39], [2, 1.01, 9]], "batl": [[1, 1.1, 428.1]]}, {"timestamp": 1631546753068, "ltp": 1.08, "tv": 1205.51, "trd": NaN, "batb": [[1, 1.07, 390.63], [2, 1.01, 4167.03]], "batl": [[0, 1.09, 332.43]]}, {"timestamp": 1631546762964, "ltp": 1.08, "tv": 1205.51, "trd": NaN, "batb": NaN, "batl": [[0, 1.09, 432.1]]}, {"timestamp": 1631546776090, "ltp": 1.08, "tv": 1205.51, "trd": NaN, "batb": NaN, "batl": [[0, 1.09, 332.43], [1, 1.1, 126.36]]}, {"timestamp": 1631546776191, "ltp": 1.08, "tv": 1205.51, "trd": NaN, "batb": [[0, 1.01, 4167.03], [1, 1.07, 0], [2, 1.01, 0]], "batl": [[0, 1.1, 126.36], [1, 1.21, 14.92], [2, 1.23, 29.82]]}, {"timestamp": 1631546779732, "ltp": 1.08, "tv": 1205.51, "trd": NaN, "batb": NaN, "batl": [[0, 1.21, 14.92], [1, 1.23, 29.82], [2, 1.25, 14.92]]}, {"timestamp": 1631546782689, "ltp": 1.08, "tv": 1205.51, "trd": NaN, "batb": [[0, 1.07, 468.55], [1, 1.01, 4167.03]], "batl": [[0, 1.09, 455.33], [1, 1.21, 14.92], [2, 1.23, 29.82]]}, {"timestamp": 1631546785028, "ltp": 1.08, "tv": 1205.51, "trd": NaN, "batb": [[0, 1.01, 4167.03], [1, 1.01, 0]], "batl": [[0, 1.21, 14.92], [1, 1.23, 29.82], [2, 1.25, 14.92]]}, {"timestamp": 1631546787940, "ltp": 1.08, "tv": 1205.51, "trd": NaN, "batb": [[0, 1.06, 472.97], [1, 1.01, 4167.03]], "batl": [[0, 1.1, 208.25], [1, 1.11, 245.29], [2, 1.21, 14.92]]}, {"timestamp": 1631546788720, "ltp": 1.08, "tv": 1205.51, "trd": NaN, "batb": [[1, 1.01, 9]], "batl": NaN}, {"timestamp": 1631546793834, "ltp": 1.08, "tv": 1205.51, "trd": NaN, "batb": NaN, "batl": [[0, 1.21, 14.92], [1, 1.23, 29.82], [2, 1.25, 14.92]]}, {"timestamp": 1631546797123, "ltp": 1.08, "tv": 1205.51, "trd": NaN, "batb": NaN, "batl": [[0, 1.08, 573.99], [1, 1.09, 762.37], [2, 1.21, 14.92]]}, {"timestamp": 1631546808567, "ltp": 1.08, "tv": 1205.51, "trd": NaN, "batb": NaN, "batl": [[0, 1.08, 448.9]]}, {"timestamp": 1631546818697, "ltp": 1.08, "tv": 1205.51, "trd": NaN, "batb": [[0, 1.01, 9], [1, 1.01, 0]], "batl": [[0, 1.21, 14.92], [1, 1.23, 29.82], [2, 1.25, 14.92]]}, {"timestamp": 1631546824602, "ltp": 1.08, "tv": 1205.51, "trd": NaN, "batb": [[0, 1.06, 472.97], [1, 1.01, 9]], "batl": [[0, 1.08, 464.21], [1, 1.21, 14.92], [2, 1.23, 29.82]]}, {"timestamp": 1631546832100, "ltp": 1.08, "tv": 1205.51, "trd": NaN, "batb": [[0, 1.01, 9], [1, 1.01, 0]], "batl": [[0, 1.21, 14.92], [1, 1.23, 29.82], [2, 1.25, 14.92]]}, {"timestamp": 1631546834990, "ltp": 1.08, "tv": 1205.51, "trd": NaN, "batb": [[0, 1.05, 473.44], [1, 1.01, 9]], "batl": [[0, 1.1, 450.03], [1, 1.21, 14.92], [2, 1.23, 29.82]]}, {"timestamp": 1631546849218, "ltp": 1.08, "tv": 1205.51, "trd": NaN, "batb": NaN, "batl": [[0, 1.21, 14.92], [1, 1.23, 29.82], [2, 1.25, 14.92]]}, {"timestamp": 1631546852126, "ltp": 1.08, "tv": 1205.51, "trd": NaN, "batb": [[1, 1.04, 701.09], [2, 1.01, 9]], "batl": [[0, 1.06, 407.08], [1, 1.07, 3766.99], [2, 1.21, 14.92]]}, {"timestamp": 1631546852494, "ltp": 1.08, "tv": 1205.51, "trd": NaN, "batb": NaN, "batl": [[1, 1.07, 1156.82]]}, {"timestamp": 1631546864016, "ltp": 1.08, "tv": 1205.51, "trd": NaN, "batb": [[1, 1.01, 9], [2, 1.01, 0]], "batl": [[0, 1.06, 304.67], [1, 1.07, 166.73]]}, {"timestamp": 1631546864218, "ltp": 1.08, "tv": 1205.51, "trd": NaN, "batb": [[0, 1.01, 9], [1, 1.01, 0]], "batl": [[0, 1.21, 14.92], [1, 1.23, 29.82], [2, 1.25, 14.92]]}, {"timestamp": 1631546867136, "ltp": 1.08, "tv": 1205.51, "trd": NaN, "batb": [[0, 1.03, 486.75], [1, 1.01, 9]], "batl": [[0, 1.08, 420.02], [1, 1.21, 14.92], [2, 1.23, 29.82]]}, {"timestamp": 1631546867348, "ltp": 1.08, "tv": 1205.51, "trd": NaN, "batb": [[0, 1.01, 9], [1, 1.01, 0]], "batl": [[0, 1.21, 14.92], [1, 1.23, 29.82], [2, 1.25, 14.92]]}, {"timestamp": 1631546870162, "ltp": 1.08, "tv": 1205.51, "trd": NaN, "batb": [[0, 1.05, 169.76], [1, 1.04, 310.67], [2, 1.01, 9]], "batl": [[0, 1.06, 472.97], [1, 1.21, 14.92], [2, 1.23, 29.82]]}, {"timestamp": 1631546877367, "ltp": 1.08, "tv": 1205.51, "trd": NaN, "batb": [[0, 1.01, 9], [1, 1.04, 0], [2, 1.01, 0]], "batl": [[0, 1.21, 14.92], [1, 1.23, 29.82], [2, 1.25, 14.92]]}, {"timestamp": 1631546880231, "ltp": 1.08, "tv": 1205.51, "trd": NaN, "batb": [[0, 1.03, 486.75], [1, 1.01, 9]], "batl": [[0, 1.08, 420.02], [1, 1.21, 14.92], [2, 1.23, 29.82]]}, {"timestamp": 1631546910550, "ltp": 1.08, "tv": 1205.51, "trd": NaN, "batb": [[0, 1.01, 9], [1, 1.01, 0]], "batl": NaN}, {"timestamp": 1631546913449, "ltp": 1.08, "tv": 1205.51, "trd": NaN, "batb": [[0, 1.06, 472.97], [1, 1.01, 9]], "batl": [[1, 1.09, 728.29], [2, 1.21, 14.92]]}, {"timestamp": 1631546946407, "ltp": 1.08, "tv": 1205.51, "trd": NaN, "batb": [[0, 1.01, 9], [1, 1.01, 0]], "batl": [[0, 1.21, 14.92], [1, 1.23, 29.82], [2, 1.25, 14.92]]}, {"timestamp": 1631546949409, "ltp": 1.08, "tv": 1205.51, "trd": NaN, "batb": [[0, 1.05, 477.47], [1, 1.01, 9]], "batl": [[0, 1.1, 425.31], [1, 1.21, 14.92], [2, 1.23, 29.82]]}, {"timestamp": 1631546953035, "ltp": 1.08, "tv": 1205.51, "trd": NaN, "batb": NaN, "batl": [[0, 1.21, 14.92], [1, 1.23, 29.82], [2, 1.25, 14.92]]}, {"timestamp": 1631546955944, "ltp": 1.08, "tv": 1205.51, "trd": NaN, "batb": [[1, 1.04, 699.19], [2, 1.01, 9]], "batl": [[0, 1.06, 375.42], [1, 1.07, 960.37], [2, 1.21, 14.92]]}, {"timestamp": 1631546974070, "ltp": 1.08, "tv": 1205.51, "trd": NaN, "batb": [[1, 1.01, 9], [2, 1.01, 0]], "batl": [[0, 1.06, 272.67], [1, 1.07, 198.42]]}, {"timestamp": 1631546974230, "ltp": 1.08, "tv": 1205.51, "trd": NaN, "batb": [[0, 1.01, 9], [1, 1.01, 0]], "batl": [[0, 1.21, 14.92], [1, 1.23, 29.82], [2, 1.25, 14.92]]}, {"timestamp": 1631546977139, "ltp": 1.08, "tv": 1205.51, "trd": NaN, "batb": [[0, 1.03, 486.75], [1, 1.01, 9]], "batl": [[0, 1.08, 391.95], [1, 1.09, 71.6], [2, 1.21, 14.92]]}, {"timestamp": 1631546980062, "ltp": 1.08, "tv": 1205.51, "trd": NaN, "batb": [[0, 1.01, 9], [1, 1.01, 0]], "batl": NaN}, {"timestamp": 1631546983074, "ltp": 1.08, "tv": 1205.51, "trd": NaN, "batb": [[0, 1.07, 95.81], [1, 1.06, 376.25], [2, 1.01, 9]], "batl": [[1, 1.09, 804.09]]}, {"timestamp": 1631547000990, "ltp": 1.08, "tv": 1205.51, "trd": NaN, "batb": [[0, 1.01, 9], [1, 1.06, 0], [2, 1.01, 0]], "batl": [[0, 1.21, 14.92], [1, 1.23, 29.82], [2, 1.25, 14.92]]}, {"timestamp": 1631547003872, "ltp": 1.08, "tv": 1205.51, "trd": NaN, "batb": [[0, 1.05, 477.47], [1, 1.01, 9]], "batl": [[0, 1.1, 401.25], [1, 1.21, 14.92], [2, 1.23, 29.82]]}, {"timestamp": 1631547004511, "ltp": 1.08, "tv": 1205.51, "trd": NaN, "batb": [[0, 1.01, 9], [1, 1.01, 0]], "batl": [[0, 1.21, 14.92], [1, 1.23, 29.82], [2, 1.25, 14.92]]}, {"timestamp": 1631547007387, "ltp": 1.08, "tv": 1205.51, "trd": NaN, "batb": [[0, 1.06, 472.97], [1, 1.01, 9]], "batl": [[0, 1.08, 464.21], [1, 1.21, 14.92], [2, 1.23, 29.82]]}, {"timestamp": 1631547011718, "ltp": 1.08, "tv": 1205.51, "trd": NaN, "batb": [[0, 1.01, 9], [1, 1.01, 0]], "batl": [[0, 1.21, 14.92], [1, 1.23, 29.82], [2, 1.25, 14.92]]}, {"timestamp": 1631547014685, "ltp": 1.08, "tv": 1205.51, "trd": NaN, "batb": [[0, 1.05, 477.47], [1, 1.01, 9]], "batl": [[0, 1.1, 401.25], [1, 1.21, 14.92], [2, 1.23, 29.82]]}, {"timestamp": 1631547019920, "ltp": 1.08, "tv": 1205.51, "trd": NaN, "batb": NaN, "batl": [[0, 1.21, 14.92], [1, 1.23, 29.82], [2, 1.25, 14.92]]}, {"timestamp": 1631547022891, "ltp": 1.08, "tv": 1205.51, "trd": NaN, "batb": [[1, 1.04, 704.46], [2, 1.01, 9]], "batl": [[0, 1.06, 343.26], [1, 1.07, 986.3], [2, 1.21, 14.92]]}, {"timestamp": 1631547040385, "ltp": 1.08, "tv": 1205.51, "trd": NaN, "batb": [[0, 1.01, 9], [1, 1.04, 0], [2, 1.01, 0]], "batl": [[0, 1.21, 14.92], [1, 1.23, 29.82], [2, 1.25, 14.92]]}, {"timestamp": 1631547043350, "ltp": 1.08, "tv": 1205.51, "trd": NaN, "batb": [[0, 1.04, 74.72], [1, 1.03, 411.29], [2, 1.01, 9]], "batl": [[0, 1.08, 364.66], [1, 1.09, 98.64], [2, 1.21, 14.92]]}, {"timestamp": 1631547056373, "ltp": 1.08, "tv": 1205.51, "trd": NaN, "batb": [[0, 1.01, 9], [1, 1.03, 0], [2, 1.01, 0]], "batl": NaN}, {"timestamp": 1631547059377, "ltp": 1.08, "tv": 1205.51, "trd": NaN, "batb": [[0, 1.07, 126.68], [1, 1.06, 345.08], [2, 1.01, 9]], "batl": [[1, 1.09, 827.22]]}, {"timestamp": 1631547075066, "ltp": 1.08, "tv": 1205.51, "trd": NaN, "batb": [[0, 1.01, 9], [1, 1.06, 0], [2, 1.01, 0]], "batl": [[0, 1.21, 14.92], [1, 1.23, 29.82], [2, 1.25, 14.92]]}, {"timestamp": 1631547077936, "ltp": 1.08, "tv": 1205.51, "trd": NaN, "batb": [[0, 1.05, 477.47], [1, 1.01, 9]], "batl": [[0, 1.1, 377.85], [1, 1.11, 77.21], [2, 1.21, 14.92]]}, {"timestamp": 1631547078198, "ltp": 1.08, "tv": 1205.51, "trd": NaN, "batb": [[0, 1.01, 9], [1, 1.01, 0]], "batl": [[0, 1.21, 14.92], [1, 1.23, 29.82], [2, 1.25, 14.92]]}, {"timestamp": 1631547081215, "ltp": 1.08, "tv": 1205.51, "trd": NaN, "batb": [[0, 1.06, 472.97], [1, 1.01, 9]], "batl": [[0, 1.08, 464.21], [1, 1.21, 14.92], [2, 1.23, 29.82]]}, {"timestamp": 1631547087561, "ltp": 1.08, "tv": 1205.51, "trd": NaN, "batb": [[0, 1.01, 9], [1, 1.01, 0]], "batl": [[0, 1.21, 14.92], [1, 1.23, 29.82], [2, 1.25, 14.92]]}, {"timestamp": 1631547090528, "ltp": 1.08, "tv": 1205.51, "trd": NaN, "batb": [[0, 1.05, 477.47], [1, 1.01, 9]], "batl": [[0, 1.1, 377.85], [1, 1.11, 77.21], [2, 1.21, 14.92]]}, {"timestamp": 1631547109942, "ltp": 1.08, "tv": 1205.51, "trd": NaN, "batb": [[0, 1.01, 9], [1, 1.01, 0]], "batl": NaN}, {"timestamp": 1631547112954, "ltp": 1.08, "tv": 1205.51, "trd": NaN, "batb": [[0, 1.08, 621.92], [1, 1.01, 9]], "batl": [[0, 1.09, 42.64], [1, 1.1, 514.47], [2, 1.11, 77.21]]}, {"timestamp": 1631547114457, "ltp": 1.08, "tv": 1205.51, "trd": NaN, "batb": [[1, 1.02, 2179.83], [2, 1.01, 9]], "batl": NaN}, {"timestamp": 1631547150096, "ltp": 1.08, "tv": 1205.51, "trd": NaN, "batb": [[0, 1.08, 157.71]], "batl": [[1, 1.1, 136.62], [2, 1.21, 14.92]]}, {"timestamp": 1631547151555, "ltp": 1.08, "tv": 1205.51, "trd": NaN, "batb": [[0, 1.02, 2179.83], [1, 1.01, 9], [2, 1.01, 0]], "batl": [[0, 1.21, 14.92], [1, 1.23, 29.82], [2, 1.25, 14.92]]}, {"timestamp": 1631547152953, "ltp": 1.08, "tv": 1205.51, "trd": NaN, "batb": [[0, 1.07, 453.52], [1, 1.02, 2179.83], [2, 1.01, 9]], "batl": [[0, 1.12, 250.69], [1, 1.13, 195.2], [2, 1.21, 14.92]]}, {"timestamp": 1631547154464, "ltp": 1.08, "tv": 1205.51, "trd": NaN, "batb": [[0, 1.02, 2179.83], [1, 1.01, 9], [2, 1.01, 0]], "batl": [[0, 1.21, 14.92], [1, 1.23, 29.82], [2, 1.25, 14.92]]}, {"timestamp": 1631547157476, "ltp": 1.08, "tv": 1205.51, "trd": NaN, "batb": [[0, 1.09, 185.87], [1, 1.08, 276.61], [2, 1.02, 2179.83]], "batl": [[0, 1.1, 173.2], [1, 1.11, 280.02], [2, 1.21, 14.92]]}, {"timestamp": 1631547164598, "ltp": 1.08, "tv": 1205.51, "trd": NaN, "batb": [[0, 1.02, 2179.83], [1, 1.01, 9], [2, 1.02, 0]], "batl": [[0, 1.21, 14.92], [1, 1.23, 29.82], [2, 1.25, 14.92]]}, {"timestamp": 1631547167611, "ltp": 1.08, "tv": 1205.51, "trd": NaN, "batb": [[0, 1.07, 453.52], [1, 1.02, 2179.83], [2, 1.01, 9]], "batl": [[0, 1.12, 250.69], [1, 1.13, 195.2], [2, 1.21, 14.92]]}, {"timestamp": 1631547175525, "ltp": 1.08, "tv": 1205.51, "trd": NaN, "batb": NaN, "batl": [[0, 1.21, 14.92], [1, 1.23, 29.82], [2, 1.25, 14.92]]}, {"timestamp": 1631547177728, "ltp": 1.08, "tv": 1205.51, "trd": NaN, "batb": [[1, 1.01, 9], [2, 1.01, 0]], "batl": NaN}, {"timestamp": 1631547178512, "ltp": 1.08, "tv": 1205.51, "trd": NaN, "batb": NaN, "batl": [[0, 1.08, 114.48], [1, 1.09, 912.05], [2, 1.21, 14.92]]}, {"timestamp": 1631547181243, "ltp": 1.08, "tv": 1205.51, "trd": NaN, "batb": [[1, 1.01, 4167.03]], "batl": NaN}, {"timestamp": 1631547190722, "ltp": 1.08, "tv": 1205.51, "trd": NaN, "batb": [[0, 1.01, 4167.03], [1, 1.01, 0]], "batl": [[0, 1.21, 14.92], [1, 1.23, 29.82], [2, 1.25, 14.92]]}, {"timestamp": 1631547193721, "ltp": 1.08, "tv": 1205.51, "trd": NaN, "batb": [[0, 1.06, 472.97], [1, 1.01, 4167.03]], "batl": [[0, 1.1, 182.46], [1, 1.11, 270.85], [2, 1.21, 14.92]]}, {"timestamp": 1631547199725, "ltp": 1.08, "tv": 1205.51, "trd": NaN, "batb": NaN, "batl": [[0, 1.21, 14.92], [1, 1.23, 29.82], [2, 1.25, 14.92]]}, {"timestamp": 1631547202764, "ltp": 1.08, "tv": 1205.51, "trd": NaN, "batb": [[1, 1.05, 643.5], [2, 1.01, 9]], "batl": [[0, 1.07, 230.26], [1, 1.08, 674.92], [2, 1.21, 14.92]]}, {"timestamp": 1631547206649, "ltp": 1.08, "tv": 1205.51, "trd": NaN, "batb": [[2, 1.01, 3979.74]], "batl": NaN}, {"timestamp": 1631547220780, "ltp": 1.08, "tv": 1205.51, "trd": NaN, "batb": [[0, 1.01, 3979.74], [1, 1.05, 0], [2, 1.01, 0]], "batl": [[0, 1.21, 14.92], [1, 1.23, 29.82], [2, 1.25, 14.92]]}, {"timestamp": 1631547223767, "ltp": 1.08, "tv": 1205.51, "trd": NaN, "batb": [[0, 1.05, 477.47], [1, 1.01, 3979.74]], "batl": [[0, 1.09, 459.95], [1, 1.21, 14.92], [2, 1.23, 29.82]]}, {"timestamp": 1631547231498, "ltp": 1.08, "tv": 1205.51, "trd": NaN, "batb": NaN, "batl": [[0, 1.21, 14.92], [1, 1.23, 29.82], [2, 1.25, 14.92]]}, {"timestamp": 1631547233700, "ltp": 1.08, "tv": 1205.51, "trd": NaN, "batb": [[1, 1.01, 9]], "batl": NaN}, {"timestamp": 1631547234495, "ltp": 1.08, "tv": 1205.51, "trd": NaN, "batb": [[0, 1.05, 693.17]], "batl": [[0, 1.06, 76.34], [1, 1.07, 1134.4], [2, 1.21, 14.92]]}, {"timestamp": 1631547244096, "ltp": 1.05, "tv": 1869.07, "trd": [[1.05, 663.56]], "batb": [[0, 1.05, 361.39]], "batl": NaN}, {"timestamp": 1631547244511, "ltp": 1.05, "tv": 1869.07, "trd": NaN, "batb": NaN, "batl": [[1, 1.07, 979.49]]}, {"timestamp": 1631547247683, "ltp": 1.05, "tv": 1869.07, "trd": NaN, "batb": [[0, 1.05, 693.17]], "batl": [[0, 1.06, 232.7]]}, {"timestamp": 1631547252996, "ltp": 1.05, "tv": 1869.07, "trd": NaN, "batb": [[0, 1.05, 205.51]], "batl": [[0, 1.07, 313.64], [1, 1.21, 14.92], [2, 1.23, 29.82]]}, {"timestamp": 1631547256042, "ltp": 1.05, "tv": 1869.07, "trd": NaN, "batb": [[1, 1.04, 274.57], [2, 1.01, 9]], "batl": [[0, 1.07, 364.12], [1, 1.08, 103.46], [2, 1.21, 14.92]]}, {"timestamp": 1631547256191, "ltp": 1.05, "tv": 1869.07, "trd": NaN, "batb": [[1, 1.01, 9], [2, 1.01, 0]], "batl": [[1, 1.21, 14.92], [2, 1.23, 29.82]]}, {"timestamp": 1631547258999, "ltp": 1.05, "tv": 1869.07, "trd": NaN, "batb": [[0, 1.05, 477.47]], "batl": [[0, 1.07, 468.55]]}, {"timestamp": 1631547265433, "ltp": 1.05, "tv": 1869.07, "trd": NaN, "batb": [[0, 1.05, 205.51]], "batl": [[0, 1.07, 364.12]]}, {"timestamp": 1631547268420, "ltp": 1.05, "tv": 1869.07, "trd": NaN, "batb": [[1, 1.04, 274.57], [2, 1.01, 9]], "batl": [[1, 1.08, 103.46], [2, 1.21, 14.92]]}, {"timestamp": 1631547276943, "ltp": 1.05, "tv": 1869.07, "trd": NaN, "batb": NaN, "batl": [[0, 1.21, 14.92], [1, 1.23, 29.82], [2, 1.25, 14.92]]}, {"timestamp": 1631547279785, "ltp": 1.05, "tv": 1869.07, "trd": NaN, "batb": [[1, 1.04, 1008]], "batl": [[0, 1.06, 961.65], [1, 1.21, 14.92], [2, 1.23, 29.82]]}, {"timestamp": 1631547386909, "ltp": 1.05, "tv": 1869.07, "trd": NaN, "batb": [[1, 1.04, 274.57]], "batl": [[0, 1.06, 472.97]]}, {"timestamp": 1631547387488, "ltp": 1.05, "tv": 1869.07, "trd": NaN, "batb": [[0, 1.04, 157.61], [1, 1.01, 9], [2, 1.01, 0]], "batl": [[0, 1.21, 14.92], [1, 1.23, 29.82], [2, 1.25, 14.92]]}, {"timestamp": 1631547390508, "ltp": 1.05, "tv": 1869.07, "trd": NaN, "batb": [[1, 1.03, 327.6], [2, 1.01, 9]], "batl": [[0, 1.07, 343.65], [1, 1.08, 123.74], [2, 1.21, 14.92]]}, {"timestamp": 1631547393997, "ltp": 1.05, "tv": 1869.07, "trd": NaN, "batb": NaN, "batl": [[0, 1.21, 14.92], [1, 1.23, 29.82], [2, 1.25, 14.92]]}, {"timestamp": 1631547397018, "ltp": 1.05, "tv": 1869.07, "trd": NaN, "batb": NaN, "batl": [[0, 1.05, 812.02], [1, 1.21, 14.92], [2, 1.23, 29.82]]}, {"timestamp": 1631547411538, "ltp": 1.05, "tv": 1869.07, "trd": NaN, "batb": [[0, 1.03, 248.88], [1, 1.01, 9], [2, 1.01, 0]], "batl": [[0, 1.21, 14.92], [1, 1.23, 29.82], [2, 1.25, 14.92]]}, {"timestamp": 1631547414541, "ltp": 1.05, "tv": 1869.07, "trd": NaN, "batb": [[1, 1.02, 240.19], [2, 1.01, 9]], "batl": [[0, 1.06, 472.97], [1, 1.21, 14.92], [2, 1.23, 29.82]]}, {"timestamp": 1631547415544, "ltp": 1.05, "tv": 1869.07, "trd": NaN, "batb": [[1, 1.01, 9], [2, 1.01, 0]], "batl": [[0, 1.21, 14.92], [1, 1.23, 29.82], [2, 1.25, 14.92]]}, {"timestamp": 1631547418512, "ltp": 1.05, "tv": 1869.07, "trd": NaN, "batb": [[0, 1.03, 486.75]], "batl": [[0, 1.05, 477.47], [1, 1.21, 14.92], [2, 1.23, 29.82]]}, {"timestamp": 1631547421064, "ltp": 1.05, "tv": 1869.07, "trd": NaN, "batb": [[0, 1.03, 248.88]], "batl": [[0, 1.21, 14.92], [1, 1.23, 29.82], [2, 1.25, 14.92]]}, {"timestamp": 1631547424039, "ltp": 1.05, "tv": 1869.07, "trd": NaN, "batb": [[1, 1.02, 240.19], [2, 1.01, 9]], "batl": [[0, 1.06, 472.97], [1, 1.21, 14.92], [2, 1.23, 29.82]]}, {"timestamp": 1631547429272, "ltp": 1.05, "tv": 1869.07, "trd": NaN, "batb": NaN, "batl": [[0, 1.21, 14.92], [1, 1.23, 29.82], [2, 1.25, 14.92]]}, {"timestamp": 1631547431935, "ltp": 1.05, "tv": 1869.07, "trd": NaN, "batb": NaN, "batl": [[0, 1.04, 431.65], [1, 1.21, 14.92], [2, 1.23, 29.82]]}, {"timestamp": 1631547432246, "ltp": 1.05, "tv": 1869.07, "trd": NaN, "batb": NaN, "batl": [[0, 1.04, 913.72]]}, {"timestamp": 1631547448594, "ltp": 1.05, "tv": 1869.07, "trd": NaN, "batb": [[0, 1.02, 240.19], [1, 1.01, 9], [2, 1.01, 0]], "batl": [[0, 1.21, 14.92], [1, 1.23, 29.82], [2, 1.25, 14.92]]}, {"timestamp": 1631547451640, "ltp": 1.05, "tv": 1869.07, "trd": NaN, "batb": [[0, 1.02, 491.52]], "batl": [[0, 1.05, 477.47], [1, 1.21, 14.92], [2, 1.23, 29.82]]}, {"timestamp": 1631547453002, "ltp": 1.05, "tv": 1869.07, "trd": NaN, "batb": [[0, 1.01, 9], [1, 1.01, 0]], "batl": NaN}, {"timestamp": 1631547455901, "ltp": 1.05, "tv": 1869.07, "trd": NaN, "batb": [[0, 1.03, 486.75], [1, 1.01, 9]], "batl": [[0, 1.04, 17.27], [1, 1.05, 815.08], [2, 1.21, 14.92]]}, {"timestamp": 1631547465580, "ltp": 1.05, "tv": 1869.07, "trd": NaN, "batb": [[0, 1.01, 9], [1, 1.01, 0]], "batl": [[0, 1.21, 14.92], [1, 1.23, 29.82], [2, 1.25, 14.92]]}, {"timestamp": 1631547471398, "ltp": 1.05, "tv": 1869.07, "trd": NaN, "batb": [[0, 1.03, 486.75], [1, 1.01, 9]], "batl": [[0, 1.04, 183.04], [1, 1.05, 296.17], [2, 1.21, 14.92]]}, {"timestamp": 1631547475522, "ltp": 1.05, "tv": 1869.07, "trd": NaN, "batb": [[0, 1.01, 9], [1, 1.01, 0]], "batl": [[0, 1.21, 14.92], [1, 1.23, 29.82], [2, 1.25, 14.92]]}, {"timestamp": 1631547478500, "ltp": 1.05, "tv": 1869.07, "trd": NaN, "batb": [[0, 1.02, 491.52], [1, 1.01, 9]], "batl": [[0, 1.06, 472.97], [1, 1.21, 14.92], [2, 1.23, 29.82]]}, {"timestamp": 1631547482440, "ltp": 1.05, "tv": 1869.07, "trd": NaN, "batb": [[0, 1.01, 9], [1, 1.01, 0]], "batl": NaN}, {"timestamp": 1631547485318, "ltp": 1.05, "tv": 1869.07, "trd": NaN, "batb": [[0, 1.05, 213.45], [1, 1.04, 949.7], [2, 1.01, 9]], "batl": [[0, 1.06, 604.92]]}, {"timestamp": 1631547499435, "ltp": 1.05, "tv": 1869.07, "trd": NaN, "batb": [[0, 1.01, 9], [1, 1.04, 0], [2, 1.01, 0]], "batl": [[0, 1.21, 14.92], [1, 1.23, 29.82], [2, 1.25, 14.92]]}, {"timestamp": 1631547502445, "ltp": 1.05, "tv": 1869.07, "trd": NaN, "batb": [[0, 1.03, 486.75], [1, 1.01, 9]], "batl": [[0, 1.08, 464.21], [1, 1.21, 14.92], [2, 1.23, 29.82]]}, {"timestamp": 1631547511555, "ltp": 1.05, "tv": 1869.07, "trd": NaN, "batb": [[0, 1.01, 9], [1, 1.01, 0]], "batl": NaN}, {"timestamp": 1631547514477, "ltp": 1.05, "tv": 1869.07, "trd": NaN, "batb": [[0, 1.06, 472.97], [1, 1.01, 9]], "batl": [[0, 1.07, 41.06], [1, 1.08, 641.32], [2, 1.21, 14.92]]}, {"timestamp": 1631547517054, "ltp": 1.05, "tv": 1869.07, "trd": NaN, "batb": [[1, 1.01, 3979.74]], "batl": NaN}, {"timestamp": 1631547532403, "ltp": 1.05, "tv": 1869.07, "trd": NaN, "batb": [[0, 1.01, 3979.74], [1, 1.01, 0]], "batl": [[0, 1.21, 14.92], [1, 1.23, 29.82], [2, 1.25, 14.92]]}, {"timestamp": 1631547535398, "ltp": 1.05, "tv": 1869.07, "trd": NaN, "batb": [[0, 1.05, 240.85], [1, 1.04, 238.89], [2, 1.01, 3979.74]], "batl": [[0, 1.09, 126.5], [1, 1.1, 330.41], [2, 1.21, 14.92]]}, {"timestamp": 1631547540792, "ltp": 1.05, "tv": 1869.07, "trd": NaN, "batb": NaN, "batl": [[0, 1.21, 14.92], [1, 1.23, 29.82], [2, 1.25, 14.92]]}, {"timestamp": 1631547543815, "ltp": 1.05, "tv": 1869.07, "trd": NaN, "batb": [[1, 1.04, 913.83], [2, 1.01, 9]], "batl": [[0, 1.06, 604.56], [1, 1.21, 14.92], [2, 1.23, 29.82]]}, {"timestamp": 1631547556028, "ltp": 1.05, "tv": 1869.07, "trd": NaN, "batb": [[0, 1.01, 9], [1, 1.04, 0], [2, 1.01, 0]], "batl": [[0, 1.21, 14.92], [1, 1.23, 29.82], [2, 1.25, 14.92]]}, {"timestamp": 1631547562115, "ltp": 1.05, "tv": 1869.07, "trd": NaN, "batb": [[0, 1.04, 482.07], [1, 1.01, 9]], "batl": [[0, 1.06, 472.97], [1, 1.21, 14.92], [2, 1.23, 29.82]]}, {"timestamp": 1631547565002, "ltp": 1.05, "tv": 1869.07, "trd": NaN, "batb": [[0, 1.01, 9], [1, 1.01, 0]], "batl": [[0, 1.21, 14.92], [1, 1.23, 29.82], [2, 1.25, 14.92]]}, {"timestamp": 1631547567970, "ltp": 1.05, "tv": 1869.07, "trd": NaN, "batb": [[0, 1.03, 486.75], [1, 1.01, 9]], "batl": [[0, 1.08, 464.21], [1, 1.21, 14.92], [2, 1.23, 29.82]]}, {"timestamp": 1631547587422, "ltp": 1.05, "tv": 1869.07, "trd": NaN, "batb": NaN, "batl": [[0, 1.21, 14.92], [1, 1.23, 29.82], [2, 1.25, 14.92]]}, {"timestamp": 1631547590393, "ltp": 1.05, "tv": 1869.07, "trd": NaN, "batb": NaN, "batl": [[0, 1.04, 311.24], [1, 1.05, 669.99], [2, 1.21, 14.92]]}, {"timestamp": 1631547602303, "ltp": 1.05, "tv": 1869.07, "trd": NaN, "batb": NaN, "batl": [[1, 1.05, 665.35]]}, {"timestamp": 1631547609013, "ltp": 1.05, "tv": 1869.07, "trd": NaN, "batb": NaN, "batl": [[0, 1.04, 262.61], [1, 1.05, 217.36]]}, {"timestamp": 1631547609228, "ltp": 1.05, "tv": 1869.07, "trd": NaN, "batb": [[0, 1.01, 9], [1, 1.01, 0]], "batl": [[0, 1.21, 14.92], [1, 1.23, 29.82], [2, 1.25, 14.92]]}, {"timestamp": 1631547612219, "ltp": 1.05, "tv": 1869.07, "trd": NaN, "batb": [[0, 1.02, 425.03], [1, 1.01, 9]], "batl": [[0, 1.06, 472.97], [1, 1.21, 14.92], [2, 1.23, 29.82]]}, {"timestamp": 1631547619330, "ltp": 1.05, "tv": 1869.07, "trd": NaN, "batb": [[0, 1.01, 9], [1, 1.01, 0]], "batl": NaN}, {"timestamp": 1631547622350, "ltp": 1.05, "tv": 1869.07, "trd": NaN, "batb": [[0, 1.05, 281.28], [1, 1.04, 868.24], [2, 1.01, 9]], "batl": [[0, 1.06, 604.06], [1, 1.07, 895.98], [2, 1.21, 14.92]]}, {"timestamp": 1631547643645, "ltp": 1.05, "tv": 1869.07, "trd": NaN, "batb": [[0, 1.01, 9], [1, 1.04, 0], [2, 1.01, 0]], "batl": [[0, 1.21, 14.92], [1, 1.23, 29.82], [2, 1.25, 14.92]]}, {"timestamp": 1631547649879, "ltp": 1.05, "tv": 1869.07, "trd": NaN, "batb": [[0, 1.04, 482.07], [1, 1.01, 9]], "batl": [[0, 1.06, 472.97], [1, 1.21, 14.92], [2, 1.23, 29.82]]}, {"timestamp": 1631547654436, "ltp": 1.05, "tv": 1869.07, "trd": NaN, "batb": [[0, 1.01, 9], [1, 1.01, 0]], "batl": [[0, 1.21, 14.92], [1, 1.23, 29.82], [2, 1.25, 14.92]]}, {"timestamp": 1631547657312, "ltp": 1.05, "tv": 1869.07, "trd": NaN, "batb": [[0, 1.03, 486.75], [1, 1.01, 9]], "batl": [[0, 1.08, 464.21], [1, 1.21, 14.92], [2, 1.23, 29.82]]}, {"timestamp": 1631547663012, "ltp": 1.05, "tv": 1869.07, "trd": NaN, "batb": [[0, 1.01, 9], [1, 1.01, 0]], "batl": NaN}, {"timestamp": 1631547666015, "ltp": 1.05, "tv": 1869.07, "trd": NaN, "batb": [[0, 1.06, 472.97], [1, 1.01, 9]], "batl": [[0, 1.07, 40.58], [1, 1.08, 640.07], [2, 1.21, 14.92]]}, {"timestamp": 1631547668747, "ltp": 1.05, "tv": 1869.07, "trd": NaN, "batb": [[1, 1.01, 3979.74]], "batl": NaN}, {"timestamp": 1631547686466, "ltp": 1.05, "tv": 1869.07, "trd": NaN, "batb": [[0, 1.01, 3979.74], [1, 1.01, 0]], "batl": [[0, 1.21, 14.92], [1, 1.23, 29.82], [2, 1.25, 14.92]]}, {"timestamp": 1631547689378, "ltp": 1.05, "tv": 1869.07, "trd": NaN, "batb": [[0, 1.05, 307.13], [1, 1.04, 171.98], [2, 1.01, 3979.74]], "batl": [[0, 1.09, 76.09], [1, 1.1, 380.37], [2, 1.21, 14.92]]}, {"timestamp": 1631547692338, "ltp": 1.05, "tv": 1869.07, "trd": NaN, "batb": [[0, 1.01, 3979.74], [1, 1.04, 0], [2, 1.01, 0]], "batl": NaN}, {"timestamp": 1631547693950, "ltp": 1.05, "tv": 1869.07, "trd": NaN, "batb": [[0, 1.01, 9]], "batl": NaN}, {"timestamp": 1631547695048, "ltp": 1.05, "tv": 1869.07, "trd": NaN, "batb": NaN, "batl": [[0, 1.09, 132.45], [1, 1.1, 554.59]]}, {"timestamp": 1631547695248, "ltp": 1.05, "tv": 1869.07, "trd": NaN, "batb": [[0, 1.08, 385.46], [1, 1.07, 79.48], [2, 1.01, 9]], "batl": NaN}, {"timestamp": 1631547697950, "ltp": 1.05, "tv": 1869.07, "trd": NaN, "batb": [[2, 1.02, 2179.83]], "batl": NaN}, {"timestamp": 1631547729024, "ltp": 1.05, "tv": 1869.07, "trd": NaN, "batb": [[0, 1.07, 79.48], [1, 1.02, 2179.83], [2, 1.01, 9]], "batl": [[0, 1.21, 14.92], [1, 1.23, 29.82], [2, 1.25, 14.92]]}, {"timestamp": 1631547732031, "ltp": 1.05, "tv": 1869.07, "trd": NaN, "batb": [[0, 1.07, 218.47], [1, 1.06, 252.44], [2, 1.02, 2179.83]], "batl": [[0, 1.12, 355.6], [1, 1.13, 91.21], [2, 1.21, 14.92]]}, {"timestamp": 1631547737330, "ltp": 1.05, "tv": 1869.07, "trd": NaN, "batb": NaN, "batl": [[0, 1.21, 14.92], [1, 1.23, 29.82], [2, 1.25, 14.92]]}, {"timestamp": 1631547738892, "ltp": 1.05, "tv": 1869.07, "trd": NaN, "batb": [[2, 1.01, 9]], "batl": NaN}, {"timestamp": 1631547740127, "ltp": 1.05, "tv": 1869.07, "trd": NaN, "batb": NaN, "batl": [[0, 1.08, 48.72], [1, 1.09, 634.98], [2, 1.21, 14.92]]}, {"timestamp": 1631547740335, "ltp": 1.05, "tv": 1869.07, "trd": NaN, "batb": NaN, "batl": [[0, 1.08, 355.86], [1, 1.09, 790.6]]}, {"timestamp": 1631547742619, "ltp": 1.05, "tv": 1869.07, "trd": NaN, "batb": [[2, 1.01, 4167.03]], "batl": NaN}, {"timestamp": 1631547752422, "ltp": 1.05, "tv": 1869.07, "trd": NaN, "batb": [[0, 1.06, 245.14], [1, 1.01, 4167.03], [2, 1.01, 0]], "batl": [[0, 1.21, 14.92], [1, 1.23, 29.82], [2, 1.25, 14.92]]}, {"timestamp": 1631547755428, "ltp": 1.05, "tv": 1869.07, "trd": NaN, "batb": [[1, 1.05, 230], [2, 1.01, 4167.03]], "batl": [[0, 1.1, 340.6], [1, 1.11, 114.12], [2, 1.21, 14.92]]}, {"timestamp": 1631547767754, "ltp": 1.05, "tv": 1869.07, "trd": NaN, "batb": [[0, 1.01, 4167.03], [1, 1.05, 0], [2, 1.01, 0]], "batl": NaN}, {"timestamp": 1631547770764, "ltp": 1.05, "tv": 1869.07, "trd": NaN, "batb": [[0, 1.08, 667.91], [1, 1.01, 9]], "batl": [[0, 1.09, 29.25], [1, 1.1, 340.6], [2, 1.11, 704.51]]}, {"timestamp": 1631547773878, "ltp": 1.05, "tv": 1869.07, "trd": NaN, "batb": [[1, 1.02, 2179.83], [2, 1.01, 9]], "batl": NaN}, {"timestamp": 1631547791377, "ltp": 1.05, "tv": 1869.07, "trd": NaN, "batb": [[0, 1.02, 2179.83], [1, 1.01, 9], [2, 1.01, 0]], "batl": [[0, 1.21, 14.92], [1, 1.23, 29.82], [2, 1.25, 14.92]]}, {"timestamp": 1631547794306, "ltp": 1.05, "tv": 1869.07, "trd": NaN, "batb": [[0, 1.07, 336.99], [1, 1.06, 132.8], [2, 1.02, 2179.83]], "batl": [[0, 1.13, 353.74], [1, 1.14, 89.14], [2, 1.21, 14.92]]}, {"timestamp": 1631547823812, "ltp": 1.05, "tv": 1869.07, "trd": NaN, "batb": NaN, "batl": [[0, 1.21, 14.92], [1, 1.23, 29.82], [2, 1.25, 14.92]]}, {"timestamp": 1631547826839, "ltp": 1.05, "tv": 1869.07, "trd": NaN, "batb": [[2, 1.01, 9]], "batl": [[0, 1.08, 2480.97], [1, 1.09, 859.78], [2, 1.21, 14.92]]}, {"timestamp": 1631547827214, "ltp": 1.05, "tv": 1869.07, "trd": NaN, "batb": NaN, "batl": [[0, 1.08, 429.26]]}, {"timestamp": 1631547838723, "ltp": 1.05, "tv": 1869.07, "trd": NaN, "batb": NaN, "batl": [[0, 1.08, 248.85]]}, {"timestamp": 1631547863995, "ltp": 1.05, "tv": 1869.07, "trd": NaN, "batb": [[0, 1.06, 132.8], [1, 1.01, 9], [2, 1.01, 0]], "batl": [[0, 1.08, 46.52], [1, 1.09, 600.3]]}, {"timestamp": 1631547866866, "ltp": 1.05, "tv": 1869.07, "trd": NaN, "batb": [[0, 1.06, 220.88], [1, 1.05, 254.48], [2, 1.01, 9]], "batl": [[2, 1.1, 106.88]]}, {"timestamp": 1631547867699, "ltp": 1.05, "tv": 1869.07, "trd": NaN, "batb": NaN, "batl": [[0, 1.1, 106.88], [1, 1.11, 345.74], [2, 1.21, 14.92]]}, {"timestamp": 1631547874312, "ltp": 1.05, "tv": 1869.07, "trd": NaN, "batb": NaN, "batl": [[0, 1.21, 14.92], [1, 1.23, 29.82], [2, 1.25, 14.92]]}, {"timestamp": 1631547877078, "ltp": 1.05, "tv": 1869.07, "trd": NaN, "batb": NaN, "batl": [[0, 1.09, 9.64], [1, 1.21, 14.92], [2, 1.23, 29.82]]}, {"timestamp": 1631547877397, "ltp": 1.05, "tv": 1869.07, "trd": NaN, "batb": [[1, 1.05, 635.9]], "batl": [[0, 1.07, 773.41]]}, {"timestamp": 1631547878981, "ltp": 1.05, "tv": 1869.07, "trd": NaN, "batb": [[2, 1.01, 3979.74]], "batl": NaN}, {"timestamp": 1631547887148, "ltp": 1.05, "tv": 1869.07, "trd": NaN, "batb": [[0, 1.05, 254.48], [1, 1.01, 3979.74], [2, 1.01, 0]], "batl": [[0, 1.21, 14.92], [1, 1.23, 29.82], [2, 1.25, 14.92]]}, {"timestamp": 1631547890042, "ltp": 1.05, "tv": 1869.07, "trd": NaN, "batb": [[0, 1.05, 477.47]], "batl": [[0, 1.08, 235.33], [1, 1.09, 226.78], [2, 1.21, 14.92]]}, {"timestamp": 1631547890426, "ltp": 1.05, "tv": 1869.07, "trd": NaN, "batb": [[0, 1.01, 3979.74], [1, 1.01, 0]], "batl": [[1, 1.21, 14.92], [2, 1.23, 29.82]]}, {"timestamp": 1631547893413, "ltp": 1.05, "tv": 1869.07, "trd": NaN, "batb": [[0, 1.06, 420.63], [1, 1.01, 3979.74]], "batl": [[0, 1.07, 236.76], [1, 1.08, 235.33], [2, 1.21, 14.92]]}, {"timestamp": 1631547897021, "ltp": 1.05, "tv": 1869.07, "trd": NaN, "batb": [[0, 1.01, 3979.74], [1, 1.01, 0]], "batl": [[0, 1.08, 235.33], [1, 1.21, 14.92], [2, 1.23, 29.82]]}, {"timestamp": 1631547899959, "ltp": 1.05, "tv": 1869.07, "trd": NaN, "batb": [[0, 1.05, 477.47], [1, 1.01, 3979.74]], "batl": [[1, 1.09, 226.78], [2, 1.21, 14.92]]}, {"timestamp": 1631547907746, "ltp": 1.05, "tv": 1869.07, "trd": NaN, "batb": NaN, "batl": [[0, 1.21, 14.92], [1, 1.23, 29.82], [2, 1.25, 14.92]]}, {"timestamp": 1631547911044, "ltp": 1.05, "tv": 1869.07, "trd": NaN, "batb": [[1, 1.04, 782.16], [2, 1.01, 9]], "batl": [[0, 1.06, 386.26], [1, 1.07, 438.7], [2, 1.21, 14.92]]}, {"timestamp": 1631547922581, "ltp": 1.05, "tv": 1869.07, "trd": NaN, "batb": NaN, "batl": [[1, 1.07, 203.02]]}, {"timestamp": 1631548023136, "ltp": 1.05, "tv": 1869.07, "trd": NaN, "batb": [[0, 1.01, 9], [1, 1.04, 0], [2, 1.01, 0]], "batl": [[0, 1.21, 14.92], [1, 1.23, 29.82], [2, 1.25, 14.92]]}, {"timestamp": 1631548026124, "ltp": 1.05, "tv": 1869.07, "trd": NaN, "batb": [[0, 1.04, 349.19], [1, 1.03, 134.16], [2, 1.01, 9]], "batl": [[0, 1.08, 464.21], [1, 1.21, 14.92], [2, 1.23, 29.82]]}, {"timestamp": 1631548035130, "ltp": 1.05, "tv": 1869.07, "trd": NaN, "batb": NaN, "batl": [[0, 1.21, 14.92], [1, 1.23, 29.82], [2, 1.25, 14.92]]}, {"timestamp": 1631548038060, "ltp": 1.05, "tv": 1869.07, "trd": NaN, "batb": NaN, "batl": [[0, 1.05, 342.71], [1, 1.21, 14.92], [2, 1.23, 29.82]]}, {"timestamp": 1631548038165, "ltp": 1.05, "tv": 1869.07, "trd": NaN, "batb": NaN, "batl": [[0, 1.05, 820.18]]}, {"timestamp": 1631548046937, "ltp": 1.05, "tv": 1869.07, "trd": NaN, "batb": [[0, 1.03, 134.16], [1, 1.01, 9], [2, 1.01, 0]], "batl": [[0, 1.21, 14.92], [1, 1.23, 29.82], [2, 1.25, 14.92]]}, {"timestamp": 1631548049828, "ltp": 1.05, "tv": 1869.07, "trd": NaN, "batb": [[0, 1.03, 169.11], [1, 1.02, 320.75], [2, 1.01, 9]], "batl": [[0, 1.06, 299.79], [1, 1.07, 171.55], [2, 1.21, 14.92]]}, {"timestamp": 1631548059650, "ltp": 1.05, "tv": 1869.07, "trd": NaN, "batb": NaN, "batl": [[0, 1.21, 14.92], [1, 1.23, 29.82], [2, 1.25, 14.92]]}, {"timestamp": 1631548062578, "ltp": 1.05, "tv": 1869.07, "trd": NaN, "batb": NaN, "batl": [[0, 1.04, 1017.06], [1, 1.21, 14.92], [2, 1.23, 29.82]]}, {"timestamp": 1631548076000, "ltp": 1.05, "tv": 1869.07, "trd": NaN, "batb": [[0, 1.02, 320.75], [1, 1.01, 9], [2, 1.01, 0]], "batl": [[0, 1.21, 14.92], [1, 1.23, 29.82], [2, 1.25, 14.92]]}, {"timestamp": 1631548079015, "ltp": 1.05, "tv": 1869.07, "trd": NaN, "batb": [[0, 1.02, 491.52]], "batl": [[0, 1.05, 477.47], [1, 1.21, 14.92], [2, 1.23, 29.82]]}, {"timestamp": 1631548079287, "ltp": 1.05, "tv": 1869.07, "trd": NaN, "batb": NaN, "batl": [[0, 1.21, 14.92], [1, 1.23, 29.82], [2, 1.25, 14.92]]}, {"timestamp": 1631548082268, "ltp": 1.05, "tv": 1869.07, "trd": NaN, "batb": NaN, "batl": [[0, 1.04, 482.07], [1, 1.21, 14.92], [2, 1.23, 29.82]]}, {"timestamp": 1631548086310, "ltp": 1.05, "tv": 1869.07, "trd": NaN, "batb": NaN, "batl": [[0, 1.21, 14.92], [1, 1.23, 29.82], [2, 1.25, 14.92]]}, {"timestamp": 1631548089301, "ltp": 1.05, "tv": 1869.07, "trd": NaN, "batb": NaN, "batl": [[0, 1.05, 477.47], [1, 1.21, 14.92], [2, 1.23, 29.82]]}, {"timestamp": 1631548094001, "ltp": 1.05, "tv": 1869.07, "trd": NaN, "batb": NaN, "batl": [[0, 1.21, 14.92], [1, 1.23, 29.82], [2, 1.25, 14.92]]}, {"timestamp": 1631548097009, "ltp": 1.05, "tv": 1869.07, "trd": NaN, "batb": NaN, "batl": [[0, 1.03, 1635.01], [1, 1.21, 14.92], [2, 1.23, 29.82]]}, {"timestamp": 1631548109824, "ltp": 1.05, "tv": 1869.07, "trd": NaN, "batb": [[0, 1.01, 9], [1, 1.01, 0]], "batl": [[0, 1.03, 341.31]]}, {"timestamp": 1631548112730, "ltp": 1.05, "tv": 1869.07, "trd": NaN, "batb": [[0, 1.01, 505.39]], "batl": [[1, 1.04, 144.03], [2, 1.21, 14.92]]}, {"timestamp": 1631548118398, "ltp": 1.05, "tv": 1869.07, "trd": NaN, "batb": NaN, "batl": [[2, 1.2, 767.39]]}, {"timestamp": 1631548121015, "ltp": 1.05, "tv": 1869.07, "trd": NaN, "batb": NaN, "batl": [[2, 1.18, 10.23]]}, {"timestamp": 1631548125114, "ltp": 1.01, "tv": 2141.92, "trd": [[1.01, 272.85]], "batb": [[0, 1.01, 368.97]], "batl": [[1, 1.18, 10.23], [2, 1.2, 767.39]]}, {"timestamp": 1631548128153, "ltp": 1.01, "tv": 2141.92, "trd": NaN, "batb": [[0, 1.01, 496.39]], "batl": [[0, 1.03, 424.73]]}, {"timestamp": 1631548130069, "ltp": 1.01, "tv": 2141.92, "trd": NaN, "batb": NaN, "batl": [[0, 1.18, 10.23], [1, 1.2, 767.39], [2, 1.21, 14.92]]}, {"timestamp": 1631548132964, "ltp": 1.01, "tv": 2141.92, "trd": NaN, "batb": NaN, "batl": [[0, 1.02, 630.84], [1, 1.03, 895.98], [2, 1.18, 10.23]]}, {"timestamp": 1631548160665, "ltp": 1.01, "tv": 2141.92, "trd": NaN, "batb": NaN, "batl": [[0, 1.18, 10.23], [1, 1.2, 767.39], [2, 1.21, 14.92]]}, {"timestamp": 1631548163672, "ltp": 1.01, "tv": 2141.92, "trd": NaN, "batb": NaN, "batl": [[0, 1.03, 486.75], [1, 1.18, 10.23], [2, 1.2, 767.39]]}, {"timestamp": 1631548166813, "ltp": 1.01, "tv": 2141.92, "trd": NaN, "batb": NaN, "batl": [[0, 1.18, 10.23], [1, 1.2, 767.39], [2, 1.21, 14.92]]}, {"timestamp": 1631548169708, "ltp": 1.01, "tv": 2141.92, "trd": NaN, "batb": [[0, 1.01, 1070.91]], "batl": [[0, 1.02, 1731.95], [1, 1.18, 10.23], [2, 1.2, 767.39]]}, {"timestamp": 1631548178126, "ltp": 1.01, "tv": 2145.34, "trd": [[1.01, 276.26]], "batb": [[0, 1.01, 1069.2]], "batl": NaN}, {"timestamp": 1631548186345, "ltp": 1.01, "tv": 2145.34, "trd": NaN, "batb": NaN, "batl": [[0, 1.02, 491.52]]}, {"timestamp": 1631548193872, "ltp": 1.01, "tv": 2145.34, "trd": NaN, "batb": NaN, "batl": [[0, 1.18, 10.23], [1, 1.2, 767.39], [2, 1.21, 14.92]]}, {"timestamp": 1631548196884, "ltp": 1.01, "tv": 2145.34, "trd": NaN, "batb": NaN, "batl": [[0, 1.01, 669.06], [1, 1.02, 895.98], [2, 1.18, 10.23]]}, {"timestamp": 1631548221990, "ltp": 1.01, "tv": 2145.34, "trd": NaN, "batb": NaN, "batl": [[0, 1.01, 496.39], [1, 1.18, 10.23], [2, 1.2, 767.39]]}, {"timestamp": 1631548222198, "ltp": 1.01, "tv": 2145.34, "trd": NaN, "batb": NaN, "batl": [[0, 1.18, 10.23], [1, 1.2, 767.39], [2, 1.21, 14.92]]}, {"timestamp": 1631548225085, "ltp": 1.01, "tv": 2145.34, "trd": NaN, "batb": NaN, "batl": [[0, 1.02, 491.52], [1, 1.18, 10.23], [2, 1.2, 767.39]]}, {"timestamp": 1631548225291, "ltp": 1.01, "tv": 2145.34, "trd": NaN, "batb": NaN, "batl": [[0, 1.02, 271.69]]}, {"timestamp": 1631548227813, "ltp": 1.01, "tv": 2145.34, "trd": NaN, "batb": NaN, "batl": [[0, 1.01, 222], [1, 1.02, 271.69], [2, 1.18, 10.23]]}, {"timestamp": 1631548234798, "ltp": 1.01, "tv": 2145.34, "trd": NaN, "batb": NaN, "batl": [[0, 1.02, 271.69], [1, 1.18, 10.23], [2, 1.2, 767.39]]}, {"timestamp": 1631548237792, "ltp": 1.01, "tv": 2145.34, "trd": NaN, "batb": NaN, "batl": [[0, 1.02, 491.52]]}, {"timestamp": 1631548243188, "ltp": 1.01, "tv": 2145.34, "trd": NaN, "batb": NaN, "batl": [[0, 1.18, 10.23], [1, 1.2, 767.39], [2, 1.21, 14.92]]}, {"timestamp": 1631548245291, "ltp": 1.01, "tv": 2145.34, "trd": NaN, "batb": NaN, "batl": [[0, 1.01, 895.98], [1, 1.18, 10.23], [2, 1.2, 767.39]]}, {"timestamp": 1631548246179, "ltp": 1.01, "tv": 2145.34, "trd": NaN, "batb": NaN, "batl": [[0, 1.01, 1392.37]]}, {"timestamp": 1631548260110, "ltp": 1.01, "tv": 2145.34, "trd": NaN, "batb": NaN, "batl": [[0, 1.01, 496.39]]}, {"timestamp": 1631548384465, "ltp": 1.01, "tv": 2145.34, "trd": NaN, "batb": NaN, "batl": [[0, 1.01, 1392.37]]}, {"timestamp": 1631548393651, "ltp": 1.01, "tv": 2145.34, "trd": NaN, "batb": NaN, "batl": [[0, 1.01, 496.39]]}, {"timestamp": 1631548414917, "ltp": 1.01, "tv": 2145.34, "trd": NaN, "batb": NaN, "batl": [[0, 1.01, 513.44]]}, {"timestamp": 1631548556907, "ltp": 1.01, "tv": 2145.34, "trd": NaN, "batb": NaN, "batl": [[0, 1.01, 17.05]]}]}, {"runnerId": 40752182, "odds": [{"timestamp": 1631544853595, "ltp": 3.6, "tv": 43.79, "trd": [[3.6, 43.79]], "batb": NaN, "batl": NaN}, {"timestamp": 1631544868912, "ltp": 3.6, "tv": 43.79, "trd": NaN, "batb": [[0, 2, 11.95], [1, 1.8, 11.95], [2, 1.7, 17.06]], "batl": NaN}, {"timestamp": 1631544906800, "ltp": 3.6, "tv": 43.79, "trd": NaN, "batb": NaN, "batl": [[0, 4, 5.35], [1, 4.2, 67.74]]}, {"timestamp": 1631544909765, "ltp": 3.6, "tv": 43.79, "trd": NaN, "batb": [[0, 2.2, 42.64], [1, 2, 11.95], [2, 1.8, 11.95]], "batl": NaN}, {"timestamp": 1631544945110, "ltp": 3.6, "tv": 43.79, "trd": NaN, "batb": NaN, "batl": [[0, 4.3, 5.21]]}, {"timestamp": 1631544973991, "ltp": 3.6, "tv": 43.79, "trd": NaN, "batb": NaN, "batl": [[0, 5.1, 54.51]]}, {"timestamp": 1631545019020, "ltp": 3.6, "tv": 43.79, "trd": NaN, "batb": [[0, 5, 30.44], [1, 2.2, 42.64], [2, 2, 11.95]], "batl": [[0, 5.5, 3.8], [1, 6, 39.02]]}, {"timestamp": 1631545022543, "ltp": 3.6, "tv": 43.79, "trd": NaN, "batb": [[1, 3, 5.97], [2, 2.2, 42.64]], "batl": NaN}, {"timestamp": 1631545037968, "ltp": 3.6, "tv": 43.79, "trd": NaN, "batb": [[2, 2.6, 3.73]], "batl": NaN}, {"timestamp": 1631545040839, "ltp": 3.6, "tv": 43.79, "trd": NaN, "batb": [[0, 3, 5.97], [1, 2.6, 3.73], [2, 2.2, 42.64]], "batl": NaN}, {"timestamp": 1631545058071, "ltp": 3.6, "tv": 43.79, "trd": NaN, "batb": [[0, 5.7, 41.25], [1, 3, 5.97], [2, 2.6, 3.73]], "batl": NaN}, {"timestamp": 1631545075822, "ltp": 3.6, "tv": 43.79, "trd": NaN, "batb": [[0, 3, 5.97], [1, 2.6, 3.73], [2, 2.2, 42.64]], "batl": NaN}, {"timestamp": 1631545097648, "ltp": 3.6, "tv": 43.79, "trd": NaN, "batb": [[0, 6.4, 5.2], [1, 6.2, 41.19], [2, 3, 5.97]], "batl": [[0, 6.8, 3.62], [1, 7.2, 42.63]]}, {"timestamp": 1631545204084, "ltp": 3.6, "tv": 43.84, "trd": [[3.6, 43.84]], "batb": [[0, 3, 5.96], [1, 2.6, 3.73], [2, 2.2, 42.6]], "batl": NaN}, {"timestamp": 1631545208103, "ltp": 3.6, "tv": 43.84, "trd": NaN, "batb": NaN, "batl": [[0, 8, 7.03], [1, 8.6, 64.79]]}, {"timestamp": 1631545242122, "ltp": 3.6, "tv": 43.84, "trd": NaN, "batb": NaN, "batl": [[0, 9.2, 7.35]]}, {"timestamp": 1631545267720, "ltp": 3.6, "tv": 43.84, "trd": NaN, "batb": NaN, "batl": [[0, 8, 7.46]]}, {"timestamp": 1631545309646, "ltp": 3.6, "tv": 43.84, "trd": NaN, "batb": [[0, 6.2, 4.31], [1, 3, 5.96], [2, 2.6, 3.73]], "batl": [[0, 7.2, 71.39]]}, {"timestamp": 1631545334103, "ltp": 3.6, "tv": 43.84, "trd": NaN, "batb": [[0, 3, 5.96], [1, 2.6, 3.73], [2, 2.2, 42.6]], "batl": NaN}, {"timestamp": 1631545354912, "ltp": 3.6, "tv": 43.84, "trd": NaN, "batb": NaN, "batl": [[0, 8, 5.46], [1, 8.6, 52.36]]}, {"timestamp": 1631545407008, "ltp": 3.6, "tv": 43.84, "trd": NaN, "batb": NaN, "batl": [[0, 10, 30.05]]}, {"timestamp": 1631545486966, "ltp": 3.6, "tv": 43.84, "trd": NaN, "batb": NaN, "batl": [[0, 11, 5.56], [1, 12, 53.77]]}, {"timestamp": 1631545505977, "ltp": 3.6, "tv": 43.84, "trd": NaN, "batb": NaN, "batl": [[0, 10, 35.65]]}, {"timestamp": 1631545526404, "ltp": 3.6, "tv": 43.84, "trd": NaN, "batb": NaN, "batl": [[0, 8.6, 33.05]]}, {"timestamp": 1631545574763, "ltp": 3.6, "tv": 43.84, "trd": NaN, "batb": [[0, 6.4, 51.33], [1, 3, 5.96], [2, 2.6, 3.73]], "batl": [[0, 7.2, 4.58], [1, 7.6, 41.95]]}, {"timestamp": 1631545588996, "ltp": 3.6, "tv": 43.84, "trd": NaN, "batb": [[0, 3, 5.96], [1, 2.6, 3.73], [2, 2.2, 42.6]], "batl": NaN}, {"timestamp": 1631545622761, "ltp": 3.6, "tv": 43.84, "trd": NaN, "batb": NaN, "batl": [[0, 6.8, 35.83]]}, {"timestamp": 1631545745680, "ltp": 3.6, "tv": 43.84, "trd": NaN, "batb": NaN, "batl": [[0, 8, 49.6]]}, {"timestamp": 1631545785751, "ltp": 3.6, "tv": 43.84, "trd": NaN, "batb": NaN, "batl": [[0, 9.2, 42.51]]}, {"timestamp": 1631545822946, "ltp": 3.6, "tv": 43.84, "trd": NaN, "batb": NaN, "batl": [[0, 8, 46.02]]}, {"timestamp": 1631545859021, "ltp": 3.6, "tv": 43.84, "trd": NaN, "batb": NaN, "batl": [[0, 9.2, 4.61]]}, {"timestamp": 1631545898941, "ltp": 3.6, "tv": 43.84, "trd": NaN, "batb": NaN, "batl": [[0, 11, 29.04]]}, {"timestamp": 1631545933996, "ltp": 3.6, "tv": 43.84, "trd": NaN, "batb": NaN, "batl": [[0, 12, 42.2]]}, {"timestamp": 1631545971580, "ltp": 3.6, "tv": 43.84, "trd": NaN, "batb": NaN, "batl": [[0, 11, 29.46]]}, {"timestamp": 1631545997432, "ltp": 3.6, "tv": 43.84, "trd": NaN, "batb": NaN, "batl": [[0, 9.2, 44.74]]}, {"timestamp": 1631546026365, "ltp": 3.6, "tv": 43.84, "trd": NaN, "batb": NaN, "batl": [[0, 11, 29.73]]}, {"timestamp": 1631546060089, "ltp": 3.6, "tv": 43.84, "trd": NaN, "batb": NaN, "batl": [[0, 13.5, 32.03]]}, {"timestamp": 1631546096127, "ltp": 3.6, "tv": 43.84, "trd": NaN, "batb": NaN, "batl": [[0, 11, 29.57]]}, {"timestamp": 1631546142815, "ltp": 3.6, "tv": 43.84, "trd": NaN, "batb": NaN, "batl": [[0, 13.5, 32.55]]}, {"timestamp": 1631546194682, "ltp": 3.6, "tv": 43.84, "trd": NaN, "batb": NaN, "batl": [[0, 11, 30.02]]}, {"timestamp": 1631546221813, "ltp": 3.6, "tv": 43.84, "trd": NaN, "batb": NaN, "batl": [[0, 12, 3.44], [1, 13.5, 33.09]]}, {"timestamp": 1631546250666, "ltp": 3.6, "tv": 43.84, "trd": NaN, "batb": [[0, 12, 25.25], [1, 3, 5.96], [2, 2.6, 3.73]], "batl": [[0, 15, 33.95]]}, {"timestamp": 1631546260382, "ltp": 3.6, "tv": 43.84, "trd": NaN, "batb": [[1, 1.41, 16.2], [2, 1.4, 767.39]], "batl": [[1, 990, 0.01]]}, {"timestamp": 1631546293741, "ltp": 3.6, "tv": 43.84, "trd": NaN, "batb": NaN, "batl": [[0, 15, 28.45]]}, {"timestamp": 1631546296624, "ltp": 3.6, "tv": 43.84, "trd": NaN, "batb": NaN, "batl": [[0, 15, 34.1]]}, {"timestamp": 1631546391078, "ltp": 3.6, "tv": 43.84, "trd": NaN, "batb": [[0, 1.41, 16.2], [1, 1.4, 767.39], [2, 1.01, 7]], "batl": [[0, 990, 0.01], [1, 990, 0]]}, {"timestamp": 1631546409951, "ltp": 13.5, "tv": 46.09, "trd": [[13.5, 2.25]], "batb": NaN, "batl": [[0, 12, 1.19], [1, 15, 103.59], [2, 990, 0.01]]}, {"timestamp": 1631546419532, "ltp": 13.5, "tv": 46.09, "trd": NaN, "batb": NaN, "batl": [[0, 15, 103.59], [1, 990, 0.01], [2, 990, 0]]}, {"timestamp": 1631546422534, "ltp": 13.5, "tv": 46.09, "trd": NaN, "batb": NaN, "batl": [[0, 13.5, 4.76], [1, 15, 103.59], [2, 990, 0.01]]}, {"timestamp": 1631546429455, "ltp": 13.5, "tv": 46.09, "trd": NaN, "batb": NaN, "batl": [[0, 990, 0.01], [1, 15, 0], [2, 990, 0]]}, {"timestamp": 1631546439558, "ltp": 13.5, "tv": 46.09, "trd": NaN, "batb": [[0, 11, 28.06], [1, 1.41, 16.2], [2, 1.4, 767.39]], "batl": [[0, 15, 45.27], [1, 990, 0.01]]}, {"timestamp": 1631546447352, "ltp": 13.5, "tv": 46.09, "trd": NaN, "batb": [[0, 1.41, 16.2], [1, 1.4, 767.39], [2, 1.01, 7]], "batl": [[0, 990, 0.01], [1, 990, 0]]}, {"timestamp": 1631546459891, "ltp": 13.5, "tv": 46.09, "trd": NaN, "batb": [[0, 13.5, 15.57], [1, 1.41, 16.2], [2, 1.4, 767.39]], "batl": [[0, 17.5, 30.63], [1, 990, 0.01]]}, {"timestamp": 1631546473396, "ltp": 13.5, "tv": 46.09, "trd": NaN, "batb": [[0, 1.41, 16.2], [1, 1.4, 767.39], [2, 1.01, 7]], "batl": [[0, 990, 0.01], [1, 990, 0]]}, {"timestamp": 1631546487036, "ltp": 13.5, "tv": 46.09, "trd": NaN, "batb": [[0, 11, 21.75], [1, 1.41, 16.2], [2, 1.4, 767.39]], "batl": [[0, 15, 56.78], [1, 990, 0.01]]}, {"timestamp": 1631546505943, "ltp": 13.5, "tv": 46.09, "trd": NaN, "batb": [[0, 1.41, 16.2], [1, 1.4, 767.39], [2, 1.01, 7]], "batl": [[0, 990, 0.01], [1, 990, 0]]}, {"timestamp": 1631546515860, "ltp": 13.5, "tv": 46.09, "trd": NaN, "batb": [[0, 13.5, 18.16], [1, 1.41, 16.2], [2, 1.4, 767.39]], "batl": NaN}, {"timestamp": 1631546523664, "ltp": 13.5, "tv": 46.09, "trd": NaN, "batb": [[0, 1.41, 16.2], [1, 1.4, 767.39], [2, 1.01, 7]], "batl": NaN}, {"timestamp": 1631546538493, "ltp": 13.5, "tv": 46.09, "trd": NaN, "batb": NaN, "batl": [[0, 26, 33.17], [1, 990, 0.01]]}, {"timestamp": 1631546541213, "ltp": 13.5, "tv": 46.09, "trd": NaN, "batb": NaN, "batl": [[1, 170, 37.53], [2, 990, 0.01]]}, {"timestamp": 1631546633724, "ltp": 13.5, "tv": 46.09, "trd": NaN, "batb": NaN, "batl": [[0, 170, 37.53], [1, 990, 0.01], [2, 990, 0]]}, {"timestamp": 1631546656283, "ltp": 13.5, "tv": 46.09, "trd": NaN, "batb": NaN, "batl": [[0, 990, 0.01], [1, 990, 0]]}, {"timestamp": 1631546658075, "ltp": 13.5, "tv": 46.09, "trd": NaN, "batb": [[0, 13.5, 22.64], [1, 1.41, 16.2], [2, 1.4, 767.39]], "batl": [[0, 17.5, 89.76], [1, 21, 31.54], [2, 990, 0.01]]}, {"timestamp": 1631546658286, "ltp": 13.5, "tv": 46.09, "trd": NaN, "batb": NaN, "batl": [[0, 21, 31.54], [1, 990, 0.01], [2, 990, 0]]}, {"timestamp": 1631546679798, "ltp": 13.5, "tv": 46.09, "trd": NaN, "batb": [[0, 1.41, 16.2], [1, 1.4, 767.39], [2, 1.01, 7]], "batl": [[0, 990, 0.01], [1, 990, 0]]}, {"timestamp": 1631546691932, "ltp": 13.5, "tv": 46.09, "trd": NaN, "batb": NaN, "batl": [[0, 26, 33.41], [1, 990, 0.01]]}, {"timestamp": 1631546695024, "ltp": 13.5, "tv": 46.09, "trd": NaN, "batb": NaN, "batl": [[1, 170, 37.53], [2, 990, 0.01]]}, {"timestamp": 1631546701929, "ltp": 13.5, "tv": 46.09, "trd": NaN, "batb": NaN, "batl": [[0, 170, 37.53], [1, 990, 0.01], [2, 990, 0]]}, {"timestamp": 1631546716427, "ltp": 13.5, "tv": 46.09, "trd": NaN, "batb": NaN, "batl": [[0, 990, 0.01], [1, 990, 0]]}, {"timestamp": 1631546717837, "ltp": 13.5, "tv": 46.09, "trd": NaN, "batb": [[0, 13.5, 18.5], [1, 1.41, 16.2], [2, 1.4, 767.39]], "batl": [[0, 17.5, 20.83], [1, 990, 0.01]]}, {"timestamp": 1631546739069, "ltp": 13.5, "tv": 46.09, "trd": NaN, "batb": [[0, 1.41, 16.2], [1, 1.4, 767.39], [2, 1.01, 7]], "batl": [[0, 990, 0.01], [1, 990, 0]]}, {"timestamp": 1631546750058, "ltp": 13.5, "tv": 46.09, "trd": NaN, "batb": [[0, 11, 30.17], [1, 1.41, 16.2], [2, 1.4, 767.39]], "batl": [[0, 15, 39.82], [1, 990, 0.01]]}, {"timestamp": 1631546759993, "ltp": 13.5, "tv": 46.09, "trd": NaN, "batb": NaN, "batl": [[0, 15, 35.16]]}, {"timestamp": 1631546762964, "ltp": 13.5, "tv": 46.09, "trd": NaN, "batb": NaN, "batl": [[0, 15, 40.81]]}, {"timestamp": 1631546776090, "ltp": 13.5, "tv": 46.09, "trd": NaN, "batb": [[0, 1.41, 16.2], [1, 1.4, 767.39], [2, 1.01, 7]], "batl": [[0, 990, 0.01], [1, 990, 0]]}, {"timestamp": 1631546797123, "ltp": 13.5, "tv": 46.09, "trd": NaN, "batb": NaN, "batl": [[0, 17.5, 42.68], [1, 990, 0.01]]}, {"timestamp": 1631546818697, "ltp": 13.5, "tv": 46.09, "trd": NaN, "batb": NaN, "batl": [[0, 990, 0.01], [1, 990, 0]]}, {"timestamp": 1631546852126, "ltp": 13.5, "tv": 46.09, "trd": NaN, "batb": NaN, "batl": [[0, 26, 28.04], [1, 990, 0.01]]}, {"timestamp": 1631546864016, "ltp": 13.5, "tv": 46.09, "trd": NaN, "batb": NaN, "batl": [[0, 990, 0.01], [1, 990, 0]]}, {"timestamp": 1631546913449, "ltp": 13.5, "tv": 46.09, "trd": NaN, "batb": NaN, "batl": [[0, 17.5, 40.51], [1, 990, 0.01]]}, {"timestamp": 1631546946407, "ltp": 13.5, "tv": 46.09, "trd": NaN, "batb": NaN, "batl": [[0, 990, 0.01], [1, 990, 0]]}, {"timestamp": 1631546955944, "ltp": 13.5, "tv": 46.09, "trd": NaN, "batb": NaN, "batl": [[0, 26, 27.97], [1, 990, 0.01]]}, {"timestamp": 1631546958436, "ltp": 13.5, "tv": 46.09, "trd": NaN, "batb": NaN, "batl": [[1, 170, 37.53], [2, 990, 0.01]]}, {"timestamp": 1631546960053, "ltp": 13.5, "tv": 46.09, "trd": NaN, "batb": NaN, "batl": [[1, 990, 0.01], [2, 990, 0]]}, {"timestamp": 1631546974070, "ltp": 13.5, "tv": 46.09, "trd": NaN, "batb": NaN, "batl": [[0, 990, 0.01], [1, 990, 0]]}, {"timestamp": 1631546983074, "ltp": 13.5, "tv": 46.09, "trd": NaN, "batb": NaN, "batl": [[0, 17.5, 40.13], [1, 990, 0.01]]}, {"timestamp": 1631547000990, "ltp": 13.5, "tv": 46.09, "trd": NaN, "batb": NaN, "batl": [[0, 990, 0.01], [1, 990, 0]]}, {"timestamp": 1631547022891, "ltp": 13.5, "tv": 46.09, "trd": NaN, "batb": NaN, "batl": [[0, 26, 28.18], [1, 990, 0.01]]}, {"timestamp": 1631547040385, "ltp": 13.5, "tv": 46.09, "trd": NaN, "batb": NaN, "batl": [[0, 990, 0.01], [1, 990, 0]]}, {"timestamp": 1631547059377, "ltp": 13.5, "tv": 46.09, "trd": NaN, "batb": NaN, "batl": [[0, 17.5, 40.53], [1, 990, 0.01]]}, {"timestamp": 1631547075066, "ltp": 13.5, "tv": 46.09, "trd": NaN, "batb": NaN, "batl": [[0, 990, 0.01], [1, 990, 0]]}, {"timestamp": 1631547112954, "ltp": 13.5, "tv": 46.09, "trd": NaN, "batb": [[0, 11, 13.66], [1, 1.41, 16.2], [2, 1.4, 767.39]], "batl": [[0, 13.5, 16.61], [1, 990, 0.01]]}, {"timestamp": 1631547151555, "ltp": 13.5, "tv": 46.09, "trd": NaN, "batb": [[0, 1.41, 16.2], [1, 1.4, 767.39], [2, 1.01, 7]], "batl": [[0, 990, 0.01], [1, 990, 0]]}, {"timestamp": 1631547178512, "ltp": 13.5, "tv": 46.09, "trd": NaN, "batb": NaN, "batl": [[0, 17.5, 64.37], [1, 990, 0.01]]}, {"timestamp": 1631547190722, "ltp": 13.5, "tv": 46.09, "trd": NaN, "batb": NaN, "batl": [[0, 990, 0.01], [1, 990, 0]]}, {"timestamp": 1631547202764, "ltp": 13.5, "tv": 46.09, "trd": NaN, "batb": [[0, 13.5, 27.5], [1, 1.41, 16.2], [2, 1.4, 767.39]], "batl": [[0, 21, 32.17], [1, 990, 0.01]]}, {"timestamp": 1631547220780, "ltp": 13.5, "tv": 46.09, "trd": NaN, "batb": [[0, 1.41, 16.2], [1, 1.4, 767.39], [2, 1.01, 7]], "batl": [[0, 990, 0.01], [1, 990, 0]]}, {"timestamp": 1631547234495, "ltp": 13.5, "tv": 46.09, "trd": NaN, "batb": NaN, "batl": [[0, 21, 14.27], [1, 990, 0.01]]}, {"timestamp": 1631547237907, "ltp": 13.5, "tv": 46.09, "trd": NaN, "batb": NaN, "batl": [[1, 170, 37.53], [2, 990, 0.01]]}, {"timestamp": 1631547252996, "ltp": 13.5, "tv": 46.09, "trd": NaN, "batb": NaN, "batl": [[0, 170, 37.53], [1, 990, 0.01], [2, 990, 0]]}, {"timestamp": 1631547279785, "ltp": 13.5, "tv": 46.09, "trd": NaN, "batb": NaN, "batl": [[0, 26, 29.34], [1, 170, 37.53], [2, 990, 0.01]]}, {"timestamp": 1631547284087, "ltp": 13.5, "tv": 46.09, "trd": NaN, "batb": NaN, "batl": [[1, 990, 0.01], [2, 990, 0]]}, {"timestamp": 1631547386909, "ltp": 13.5, "tv": 46.09, "trd": NaN, "batb": NaN, "batl": [[0, 990, 0.01], [1, 990, 0]]}, {"timestamp": 1631547397018, "ltp": 13.5, "tv": 46.09, "trd": NaN, "batb": [[0, 21, 16.73], [1, 1.41, 16.2], [2, 1.4, 767.39]], "batl": [[0, 34, 51.28], [1, 990, 0.01]]}, {"timestamp": 1631547411538, "ltp": 13.5, "tv": 46.09, "trd": NaN, "batb": [[0, 1.41, 16.2], [1, 1.4, 767.39], [2, 1.01, 7]], "batl": [[0, 990, 0.01], [1, 990, 0]]}, {"timestamp": 1631547431935, "ltp": 13.5, "tv": 46.09, "trd": NaN, "batb": [[0, 26, 17.27], [1, 1.41, 16.2], [2, 1.4, 767.39]], "batl": [[0, 50, 53.45], [1, 990, 0.01]]}, {"timestamp": 1631547448594, "ltp": 13.5, "tv": 46.09, "trd": NaN, "batb": [[0, 1.41, 16.2], [1, 1.4, 767.39], [2, 1.01, 7]], "batl": [[0, 990, 0.01], [1, 990, 0]]}, {"timestamp": 1631547455901, "ltp": 13.5, "tv": 46.09, "trd": NaN, "batb": [[0, 21, 16.88], [1, 1.41, 16.2], [2, 1.4, 767.39]], "batl": [[0, 34, 43], [1, 990, 0.01]]}, {"timestamp": 1631547465580, "ltp": 13.5, "tv": 46.09, "trd": NaN, "batb": [[0, 1.41, 16.2], [1, 1.4, 767.39], [2, 1.01, 7]], "batl": [[0, 990, 0.01], [1, 990, 0]]}, {"timestamp": 1631547485318, "ltp": 13.5, "tv": 46.09, "trd": NaN, "batb": [[0, 17.5, 21.31], [1, 1.41, 16.2], [2, 1.4, 767.39]], "batl": [[0, 26, 27.32], [1, 990, 0.01]]}, {"timestamp": 1631547486726, "ltp": 13.5, "tv": 46.09, "trd": NaN, "batb": NaN, "batl": [[1, 170, 37.53], [2, 990, 0.01]]}, {"timestamp": 1631547499435, "ltp": 13.5, "tv": 46.09, "trd": NaN, "batb": [[0, 1.41, 16.2], [1, 1.4, 767.39], [2, 1.01, 7]], "batl": [[0, 170, 37.53], [1, 990, 0.01], [2, 990, 0]]}, {"timestamp": 1631547513070, "ltp": 13.5, "tv": 46.09, "trd": NaN, "batb": NaN, "batl": [[0, 990, 0.01], [1, 990, 0]]}, {"timestamp": 1631547514477, "ltp": 13.5, "tv": 46.09, "trd": NaN, "batb": [[0, 13.5, 14.17], [1, 1.41, 16.2], [2, 1.4, 767.39]], "batl": [[0, 17.5, 30.66], [1, 990, 0.01]]}, {"timestamp": 1631547532403, "ltp": 13.5, "tv": 46.09, "trd": NaN, "batb": [[0, 1.41, 16.2], [1, 1.4, 767.39], [2, 1.01, 7]], "batl": [[0, 990, 0.01], [1, 990, 0]]}, {"timestamp": 1631547543815, "ltp": 13.5, "tv": 46.09, "trd": NaN, "batb": [[0, 17.5, 20.32], [1, 1.41, 16.2], [2, 1.4, 767.39]], "batl": [[0, 26, 26.99], [1, 990, 0.01]]}, {"timestamp": 1631547547320, "ltp": 13.5, "tv": 46.09, "trd": NaN, "batb": NaN, "batl": [[1, 170, 37.53], [2, 990, 0.01]]}, {"timestamp": 1631547556028, "ltp": 13.5, "tv": 46.09, "trd": NaN, "batb": [[0, 1.41, 16.2], [1, 1.4, 767.39], [2, 1.01, 7]], "batl": [[0, 170, 37.53], [1, 990, 0.01], [2, 990, 0]]}, {"timestamp": 1631547560676, "ltp": 13.5, "tv": 46.09, "trd": NaN, "batb": NaN, "batl": [[0, 990, 0.01], [1, 990, 0]]}, {"timestamp": 1631547590393, "ltp": 13.5, "tv": 46.09, "trd": NaN, "batb": [[0, 21, 22.4], [1, 1.41, 16.2], [2, 1.4, 767.39]], "batl": [[0, 34, 23.75], [1, 990, 0.01]]}, {"timestamp": 1631547609013, "ltp": 13.5, "tv": 46.09, "trd": NaN, "batb": [[0, 1.41, 16.2], [1, 1.4, 767.39], [2, 1.01, 7]], "batl": [[0, 990, 0.01], [1, 990, 0]]}, {"timestamp": 1631547622350, "ltp": 13.5, "tv": 46.09, "trd": NaN, "batb": NaN, "batl": [[0, 26, 26.81], [1, 990, 0.01]]}, {"timestamp": 1631547624238, "ltp": 13.5, "tv": 46.09, "trd": NaN, "batb": NaN, "batl": [[1, 170, 37.53], [2, 990, 0.01]]}, {"timestamp": 1631547643645, "ltp": 13.5, "tv": 46.09, "trd": NaN, "batb": NaN, "batl": [[0, 170, 37.53], [1, 990, 0.01], [2, 990, 0]]}, {"timestamp": 1631547664546, "ltp": 13.5, "tv": 46.09, "trd": NaN, "batb": NaN, "batl": [[0, 990, 0.01], [1, 990, 0]]}, {"timestamp": 1631547666015, "ltp": 13.5, "tv": 46.09, "trd": NaN, "batb": [[0, 13.5, 14.07], [1, 1.41, 16.2], [2, 1.4, 767.39]], "batl": [[0, 17.5, 30.9], [1, 990, 0.01]]}, {"timestamp": 1631547686466, "ltp": 13.5, "tv": 46.09, "trd": NaN, "batb": [[0, 1.41, 16.2], [1, 1.4, 767.39], [2, 1.01, 7]], "batl": [[0, 990, 0.01], [1, 990, 0]]}, {"timestamp": 1631547695048, "ltp": 13.5, "tv": 46.09, "trd": NaN, "batb": [[0, 11, 17.42], [1, 1.41, 16.2], [2, 1.4, 767.39]], "batl": [[0, 15, 56.66], [1, 990, 0.01]]}, {"timestamp": 1631547729024, "ltp": 13.5, "tv": 46.09, "trd": NaN, "batb": [[0, 1.41, 16.2], [1, 1.4, 767.39], [2, 1.01, 7]], "batl": [[0, 990, 0.01], [1, 990, 0]]}, {"timestamp": 1631547740127, "ltp": 13.5, "tv": 46.09, "trd": NaN, "batb": [[0, 13.5, 3.9], [1, 1.41, 16.2], [2, 1.4, 767.39]], "batl": [[0, 17.5, 53.29], [1, 990, 0.01]]}, {"timestamp": 1631547752422, "ltp": 13.5, "tv": 46.09, "trd": NaN, "batb": [[0, 1.41, 16.2], [1, 1.4, 767.39], [2, 1.01, 7]], "batl": [[0, 990, 0.01], [1, 990, 0]]}, {"timestamp": 1631547770764, "ltp": 13.5, "tv": 46.09, "trd": NaN, "batb": NaN, "batl": [[0, 13.5, 21.48], [1, 990, 0.01]]}, {"timestamp": 1631547791377, "ltp": 13.5, "tv": 46.09, "trd": NaN, "batb": NaN, "batl": [[0, 990, 0.01], [1, 990, 0]]}, {"timestamp": 1631547826839, "ltp": 13.5, "tv": 46.09, "trd": NaN, "batb": [[0, 13.5, 3.72], [1, 1.41, 16.2], [2, 1.4, 767.39]], "batl": [[0, 17.5, 54.8], [1, 990, 0.01]]}, {"timestamp": 1631547867699, "ltp": 13.5, "tv": 46.09, "trd": NaN, "batb": [[0, 1.41, 16.2], [1, 1.4, 767.39], [2, 1.01, 7]], "batl": [[0, 990, 0.01], [1, 990, 0]]}, {"timestamp": 1631547877397, "ltp": 13.5, "tv": 46.09, "trd": NaN, "batb": NaN, "batl": [[0, 21, 25.63], [1, 990, 0.01]]}, {"timestamp": 1631547887030, "ltp": 13.5, "tv": 46.09, "trd": NaN, "batb": NaN, "batl": [[0, 21, 19.07]]}, {"timestamp": 1631547887148, "ltp": 13.5, "tv": 46.09, "trd": NaN, "batb": NaN, "batl": [[0, 990, 0.01], [1, 990, 0]]}, {"timestamp": 1631547911044, "ltp": 13.5, "tv": 46.09, "trd": NaN, "batb": [[0, 17.5, 18.72], [1, 1.41, 16.2], [2, 1.4, 767.39]], "batl": [[0, 26, 31.29], [1, 990, 0.01]]}, {"timestamp": 1631547914562, "ltp": 13.5, "tv": 46.09, "trd": NaN, "batb": NaN, "batl": [[1, 170, 37.53], [2, 990, 0.01]]}, {"timestamp": 1631547995972, "ltp": 13.5, "tv": 46.09, "trd": NaN, "batb": NaN, "batl": [[1, 990, 0.01], [2, 990, 0]]}, {"timestamp": 1631548023136, "ltp": 13.5, "tv": 46.09, "trd": NaN, "batb": [[0, 1.41, 16.2], [1, 1.4, 767.39], [2, 1.01, 7]], "batl": [[0, 990, 0.01], [1, 990, 0]]}, {"timestamp": 1631548038060, "ltp": 13.5, "tv": 46.09, "trd": NaN, "batb": [[0, 21, 17.14], [1, 1.41, 16.2], [2, 1.4, 767.39]], "batl": [[0, 34, 49.75], [1, 990, 0.01]]}, {"timestamp": 1631548042355, "ltp": 13.5, "tv": 46.09, "trd": NaN, "batb": NaN, "batl": [[1, 340, 36.42], [2, 990, 0.01]]}, {"timestamp": 1631548046937, "ltp": 13.5, "tv": 46.09, "trd": NaN, "batb": [[0, 1.41, 16.2], [1, 1.4, 767.39], [2, 1.01, 7]], "batl": [[0, 340, 36.42], [1, 990, 0.01], [2, 990, 0]]}, {"timestamp": 1631548061790, "ltp": 13.5, "tv": 46.09, "trd": NaN, "batb": NaN, "batl": [[0, 990, 0.01], [1, 990, 0]]}, {"timestamp": 1631548062578, "ltp": 13.5, "tv": 46.09, "trd": NaN, "batb": [[0, 26, 21.4], [1, 1.41, 16.2], [2, 1.4, 767.39]], "batl": [[0, 50, 44.81], [1, 990, 0.01]]}, {"timestamp": 1631548076000, "ltp": 13.5, "tv": 46.09, "trd": NaN, "batb": [[0, 1.41, 16.2], [1, 1.4, 767.39], [2, 1.01, 7]], "batl": [[0, 990, 0.01], [1, 990, 0]]}, {"timestamp": 1631548097009, "ltp": 13.5, "tv": 46.09, "trd": NaN, "batb": NaN, "batl": [[0, 100, 57.64], [1, 990, 0.01]]}, {"timestamp": 1631548109824, "ltp": 13.5, "tv": 46.09, "trd": NaN, "batb": NaN, "batl": [[0, 990, 0.01], [1, 990, 0]]}, {"timestamp": 1631548132964, "ltp": 13.5, "tv": 46.09, "trd": NaN, "batb": NaN, "batl": [[0, 100, 34.73], [1, 990, 0.01]]}, {"timestamp": 1631548160665, "ltp": 13.5, "tv": 46.09, "trd": NaN, "batb": NaN, "batl": [[0, 990, 0.01], [1, 990, 0]]}, {"timestamp": 1631548196884, "ltp": 13.5, "tv": 46.09, "trd": NaN, "batb": NaN, "batl": [[0, 190, 10.13], [1, 990, 0.01]]}, {"timestamp": 1631548221990, "ltp": 13.5, "tv": 46.09, "trd": NaN, "batb": NaN, "batl": [[0, 990, 0.01], [1, 990, 0]]}, {"timestamp": 1631548245291, "ltp": 13.5, "tv": 46.09, "trd": NaN, "batb": NaN, "batl": [[0, 290, 7.95], [1, 990, 0.01]]}, {"timestamp": 1631548260110, "ltp": 13.5, "tv": 46.09, "trd": NaN, "batb": NaN, "batl": [[0, 990, 0.01], [1, 990, 0]]}, {"timestamp": 1631548276414, "ltp": 13.5, "tv": 46.09, "trd": NaN, "batb": [[0, 140, 6.45], [1, 1.41, 16.2], [2, 1.4, 767.39]], "batl": NaN}, {"timestamp": 1631548375547, "ltp": 13.5, "tv": 46.09, "trd": NaN, "batb": [[0, 1.41, 16.2], [1, 1.4, 767.39], [2, 1.01, 7]], "batl": NaN}, {"timestamp": 1631548384465, "ltp": 13.5, "tv": 46.09, "trd": NaN, "batb": NaN, "batl": [[0, 290, 11.92], [1, 990, 0.01]]}, {"timestamp": 1631548393651, "ltp": 13.5, "tv": 46.09, "trd": NaN, "batb": NaN, "batl": [[0, 990, 0.01], [1, 990, 0]]}, {"timestamp": 1631548417782, "ltp": 13.5, "tv": 46.09, "trd": NaN, "batb": [[0, 140, 6.45], [1, 1.41, 16.2], [2, 1.4, 767.39]], "batl": [[0, 490, 10.33], [1, 990, 0.01]]}, {"timestamp": 1631548426602, "ltp": 13.5, "tv": 46.09, "trd": NaN, "batb": [[0, 1.41, 16.2], [1, 1.4, 767.39], [2, 1.01, 7]], "batl": [[0, 990, 0.01], [1, 990, 0]]}, {"timestamp": 1631548445461, "ltp": 13.5, "tv": 46.09, "trd": NaN, "batb": [[0, 190, 4.74], [1, 1.41, 16.2], [2, 1.4, 767.39]], "batl": [[0, 990, 6.36]]}, {"timestamp": 1631548465044, "ltp": 13.5, "tv": 46.09, "trd": NaN, "batb": [[0, 1.41, 16.2], [1, 1.4, 767.39], [2, 1.01, 7]], "batl": [[0, 990, 0.01]]}, {"timestamp": 1631548522817, "ltp": 13.5, "tv": 46.09, "trd": NaN, "batb": [[0, 190, 4.74], [1, 1.41, 16.2], [2, 1.4, 767.39]], "batl": [[0, 990, 3.94]]}, {"timestamp": 1631548535673, "ltp": 13.5, "tv": 46.09, "trd": NaN, "batb": [[0, 1.41, 16.2], [1, 1.4, 767.39], [2, 1.01, 7]], "batl": [[0, 990, 0.01]]}, {"timestamp": 1631548563707, "ltp": 13.5, "tv": 46.09, "trd": NaN, "batb": [[0, 1.01, 7], [1, 1.4, 0], [2, 1.01, 0]], "batl": NaN}]}]}