{"info": {"id": "1.188136695", "eventId": "30941535", "eventName": "Match Odds", "marketType": "MATCH_ODDS", "openDate": 1632579485640, "name": "Kontaveit v Kvitova", "numberOfActiveRunner": 2, "countryCode": "", "sport": "TENNIS", "venue": "", "volume": {"total": 669724.58, "preMatch": 32745.17, "inPlay": 636979.41}, "winner": {"id": 5300737, "name": "Anett Kontaveit", "status": "WINNER", "position": 1}, "delay": 3}, "runners": [{"id": 5300737, "name": "Anett Kontaveit", "status": "WINNER", "position": 1, "inPlayOdds": 1.99, "inPlayTime": 1632579485640, "avgPrematch": 2.03, "closedOdds": 1.01, "maxPrematch": 2.2, "minPrematch": 1.94, "maxInPlay": 2.0, "minInPlay": 1.01, "inPlayIndex": 632, "lengthOdds": 4216, "lengthOddsPrematch": 632, "lengthOddsInPlay": 3584, "tradedVolume": 630272.91, "preMatchVolume": 12389.43, "inPlayVolume": 617883.48}, {"id": 2497008, "name": "Petra Kvitova", "status": "LOSER", "position": 2, "inPlayOdds": 2.0, "inPlayTime": 1632579485640, "avgPrematch": 1.96, "closedOdds": 34.0, "maxPrematch": 2.06, "minPrematch": 1.83, "maxInPlay": 50.0, "minInPlay": 2.0, "inPlayIndex": 611, "lengthOdds": 2738, "lengthOddsPrematch": 611, "lengthOddsInPlay": 2127, "tradedVolume": 39451.67, "preMatchVolume": 20355.74, "inPlayVolume": 19095.93}], "marketUpdates": [{"timestamp": 1632511078541000000, "openDate": "2021-09-25T13:30:00.000Z", "status": "OPEN", "betDelay": 0, "inPlay": false, "complete": true}, {"timestamp": 1632577063238000000, "openDate": "2021-09-25T13:45:00.000Z", "status": "OPEN", "betDelay": 0, "inPlay": false, "complete": true}, {"timestamp": 1632577661781000000, "openDate": "2021-09-25T14:00:00.000Z", "status": "OPEN", "betDelay": 0, "inPlay": false, "complete": true}, {"timestamp": 1632579485640000000, "openDate": "2021-09-25T14:00:00.000Z", "status": "OPEN", "betDelay": 3, "inPlay": true, "complete": true}, {"timestamp": 1632583766634000000, "openDate": "2021-09-25T14:00:00.000Z", "status": "SUSPENDED", "betDelay": 3, "inPlay": true, "complete": true}, {"timestamp": 1632583846068000000, "openDate": "2021-09-25T14:00:00.000Z", "status": "CLOSED", "betDelay": 3, "inPlay": true, "complete": true}], "odds": [{"runnerId": 5300737, "odds": [{"timestamp": 1632523562858, "ltp": 2.2, "tv": 2.8, "trd": [[2.2, 2.8]], "batb": NaN, "batl": [[0, 2.2, 85.91]]}, {"timestamp": 1632524113471, "ltp": 2.2, "tv": 2.8, "trd": NaN, "batb": [[0, 2.02, 4]], "batl": NaN}, {"timestamp": 1632524117472, "ltp": 2.2, "tv": 2.8, "trd": NaN, "batb": [[0, 2.02, 182.92]], "batl": NaN}, {"timestamp": 1632524480586, "ltp": 2.2, "tv": 2.8, "trd": NaN, "batb": [[0, 2.04, 3], [1, 2.02, 182.04], [2, 1.25, 914.87]], "batl": [[0, 2.18, 3], [1, 2.2, 85.91], [2, 2.24, 25]]}, {"timestamp": 1632524486268, "ltp": 2.2, "tv": 2.8, "trd": NaN, "batb": [[1, 2.02, 4]], "batl": NaN}, {"timestamp": 1632524685654, "ltp": 2.2, "tv": 2.8, "trd": NaN, "batb": [[1, 1.25, 914.87], [2, 1.12, 1237.68]], "batl": [[0, 2.16, 85.71], [1, 2.18, 3]]}, {"timestamp": 1632525215785, "ltp": 2.2, "tv": 2.8, "trd": NaN, "batb": [[0, 2, 4], [1, 1.99, 4], [2, 1.25, 914.87]], "batl": [[0, 2.14, 3], [1, 2.16, 85.71], [2, 2.18, 3]]}, {"timestamp": 1632525999576, "ltp": 2.2, "tv": 2.8, "trd": NaN, "batb": [[1, 1.25, 914.87], [2, 1.12, 1237.68]], "batl": [[2, 2.24, 25]]}, {"timestamp": 1632526160398, "ltp": 2.2, "tv": 2.8, "trd": NaN, "batb": [[0, 2.02, 35.57], [1, 2, 4], [2, 1.25, 914.87]], "batl": NaN}, {"timestamp": 1632526648467, "ltp": 2.2, "tv": 2.8, "trd": NaN, "batb": NaN, "batl": [[0, 2.16, 85.71], [1, 2.24, 25], [2, 11, 5]]}, {"timestamp": 1632526894612, "ltp": 2.2, "tv": 2.8, "trd": NaN, "batb": [[0, 2.04, 42.86], [1, 2.02, 35.57], [2, 2, 4]], "batl": [[0, 2.14, 32.57], [1, 2.16, 85.71], [2, 2.24, 25]]}, {"timestamp": 1632526932747, "ltp": 2.2, "tv": 2.8, "trd": NaN, "batb": [[0, 2.04, 63.03], [1, 2, 4], [2, 1.25, 914.87]], "batl": NaN}, {"timestamp": 1632527080270, "ltp": 2.2, "tv": 2.8, "trd": NaN, "batb": [[0, 2.04, 244.21]], "batl": NaN}, {"timestamp": 1632527284182, "ltp": 2.2, "tv": 2.8, "trd": NaN, "batb": [[0, 2.04, 42.86]], "batl": NaN}, {"timestamp": 1632527327731, "ltp": 2.2, "tv": 2.8, "trd": NaN, "batb": [[0, 2.04, 244.21]], "batl": NaN}, {"timestamp": 1632527960625, "ltp": 2.04, "tv": 9.71, "trd": [[2.04, 6.91]], "batb": [[0, 2.04, 240.75]], "batl": NaN}, {"timestamp": 1632528180033, "ltp": 2.04, "tv": 9.71, "trd": NaN, "batb": [[0, 2.04, 101.06]], "batl": NaN}, {"timestamp": 1632528265095, "ltp": 2.04, "tv": 9.71, "trd": NaN, "batb": [[0, 2.04, 106.2]], "batl": NaN}, {"timestamp": 1632528626485, "ltp": 2.04, "tv": 13.7, "trd": [[2.04, 10.91]], "batb": [[0, 2.04, 104.21], [1, 1.25, 914.87], [2, 1.12, 1237.68]], "batl": NaN}, {"timestamp": 1632528679439, "ltp": 2.04, "tv": 13.7, "trd": NaN, "batb": [[0, 2.04, 42.55]], "batl": NaN}, {"timestamp": 1632530400770, "ltp": 2.04, "tv": 156.25, "trd": [[2.04, 153.46]], "batb": [[0, 1.73, 974.85]], "batl": NaN}, {"timestamp": 1632530402780, "ltp": 2.04, "tv": 156.25, "trd": NaN, "batb": [[0, 2, 32.57], [1, 1.73, 974.85], [2, 1.25, 914.87]], "batl": [[0, 2.14, 84]]}, {"timestamp": 1632530479464, "ltp": 2.04, "tv": 156.25, "trd": NaN, "batb": [[0, 2, 722.6], [1, 1.25, 914.87], [2, 1.12, 1237.68]], "batl": NaN}, {"timestamp": 1632530522761, "ltp": 2.04, "tv": 156.25, "trd": NaN, "batb": [[0, 2, 32.57]], "batl": NaN}, {"timestamp": 1632530523070, "ltp": 2.04, "tv": 156.25, "trd": NaN, "batb": [[0, 2, 216.35]], "batl": NaN}, {"timestamp": 1632530528484, "ltp": 2.04, "tv": 156.25, "trd": NaN, "batb": [[0, 2, 664.7]], "batl": NaN}, {"timestamp": 1632530879761, "ltp": 2.04, "tv": 156.25, "trd": NaN, "batb": [[0, 2, 568.43]], "batl": NaN}, {"timestamp": 1632530886630, "ltp": 2.04, "tv": 156.25, "trd": NaN, "batb": [[0, 2, 160.2]], "batl": NaN}, {"timestamp": 1632530892049, "ltp": 2.04, "tv": 156.25, "trd": NaN, "batb": [[0, 2, 650.4]], "batl": NaN}, {"timestamp": 1632530922804, "ltp": 2.04, "tv": 156.25, "trd": NaN, "batb": NaN, "batl": [[0, 2.16, 85.71], [1, 2.24, 25], [2, 11, 5]]}, {"timestamp": 1632530923317, "ltp": 2.04, "tv": 156.25, "trd": NaN, "batb": NaN, "batl": [[0, 2.1, 49.71], [1, 2.16, 85.71], [2, 2.24, 25]]}, {"timestamp": 1632530978972, "ltp": 2.1, "tv": 171.03, "trd": [[2.1, 14.78]], "batb": NaN, "batl": [[0, 2.1, 42.32]]}, {"timestamp": 1632530993099, "ltp": 2.1, "tv": 171.03, "trd": NaN, "batb": [[0, 2, 660.69]], "batl": NaN}, {"timestamp": 1632531178159, "ltp": 2.1, "tv": 171.03, "trd": NaN, "batb": [[0, 2, 118.97]], "batl": NaN}, {"timestamp": 1632531183353, "ltp": 2.1, "tv": 171.03, "trd": NaN, "batb": [[0, 2, 647.61]], "batl": NaN}, {"timestamp": 1632531500602, "ltp": 2.1, "tv": 171.03, "trd": NaN, "batb": [[0, 2, 118.97]], "batl": NaN}, {"timestamp": 1632531505735, "ltp": 2.1, "tv": 171.03, "trd": NaN, "batb": [[0, 2, 647.61]], "batl": NaN}, {"timestamp": 1632531681449, "ltp": 2.1, "tv": 171.03, "trd": NaN, "batb": [[0, 2, 118.97]], "batl": NaN}, {"timestamp": 1632531686752, "ltp": 2.1, "tv": 171.03, "trd": NaN, "batb": [[0, 2, 647.61]], "batl": NaN}, {"timestamp": 1632531783315, "ltp": 2.1, "tv": 171.03, "trd": NaN, "batb": [[0, 2, 118.97]], "batl": NaN}, {"timestamp": 1632531788696, "ltp": 2.1, "tv": 171.03, "trd": NaN, "batb": [[0, 2, 647.61]], "batl": NaN}, {"timestamp": 1632531908601, "ltp": 2.1, "tv": 171.03, "trd": NaN, "batb": [[0, 2, 118.96]], "batl": NaN}, {"timestamp": 1632531913683, "ltp": 2.1, "tv": 171.03, "trd": NaN, "batb": [[0, 2, 42.86]], "batl": NaN}, {"timestamp": 1632531913888, "ltp": 2.1, "tv": 171.03, "trd": NaN, "batb": [[0, 2, 647.61]], "batl": NaN}, {"timestamp": 1632532002821, "ltp": 2.1, "tv": 171.03, "trd": NaN, "batb": [[0, 2, 118.96]], "batl": NaN}, {"timestamp": 1632532007942, "ltp": 2.1, "tv": 171.03, "trd": NaN, "batb": [[0, 2, 647.61]], "batl": NaN}, {"timestamp": 1632532125671, "ltp": 2.1, "tv": 171.03, "trd": NaN, "batb": [[0, 2, 983.52]], "batl": NaN}, {"timestamp": 1632532271295, "ltp": 2.1, "tv": 171.03, "trd": NaN, "batb": [[0, 2, 118.96]], "batl": NaN}, {"timestamp": 1632532276470, "ltp": 2.1, "tv": 171.03, "trd": NaN, "batb": [[0, 2, 954.06]], "batl": NaN}, {"timestamp": 1632532700333, "ltp": 2.1, "tv": 171.03, "trd": NaN, "batb": [[0, 2, 118.96]], "batl": NaN}, {"timestamp": 1632532705532, "ltp": 2.1, "tv": 171.03, "trd": NaN, "batb": [[0, 2, 985.62]], "batl": NaN}, {"timestamp": 1632532995824, "ltp": 2.1, "tv": 171.03, "trd": NaN, "batb": [[0, 2, 118.96]], "batl": NaN}, {"timestamp": 1632533001152, "ltp": 2.1, "tv": 171.03, "trd": NaN, "batb": [[0, 2, 981.41]], "batl": NaN}, {"timestamp": 1632533163536, "ltp": 2.1, "tv": 171.03, "trd": NaN, "batb": [[0, 2, 42.86]], "batl": NaN}, {"timestamp": 1632533163900, "ltp": 2.1, "tv": 171.03, "trd": NaN, "batb": [[0, 2, 118.96]], "batl": NaN}, {"timestamp": 1632533168826, "ltp": 2.1, "tv": 171.03, "trd": NaN, "batb": [[0, 2, 981.41]], "batl": NaN}, {"timestamp": 1632533446306, "ltp": 2.1, "tv": 171.03, "trd": NaN, "batb": [[0, 2, 118.96]], "batl": NaN}, {"timestamp": 1632533451822, "ltp": 2.1, "tv": 171.03, "trd": NaN, "batb": [[0, 2, 986.32]], "batl": NaN}, {"timestamp": 1632533635450, "ltp": 2.1, "tv": 171.03, "trd": NaN, "batb": [[0, 2, 118.96]], "batl": NaN}, {"timestamp": 1632533640674, "ltp": 2.1, "tv": 171.03, "trd": NaN, "batb": [[0, 2, 986.32]], "batl": NaN}, {"timestamp": 1632533829473, "ltp": 2.1, "tv": 171.03, "trd": NaN, "batb": [[0, 2, 42.86]], "batl": NaN}, {"timestamp": 1632533829886, "ltp": 2.1, "tv": 171.03, "trd": NaN, "batb": [[0, 2, 118.96]], "batl": NaN}, {"timestamp": 1632533835095, "ltp": 2.1, "tv": 171.03, "trd": NaN, "batb": [[0, 2, 986.32]], "batl": NaN}, {"timestamp": 1632533937754, "ltp": 2.1, "tv": 171.03, "trd": NaN, "batb": [[0, 2, 42.86]], "batl": NaN}, {"timestamp": 1632533938160, "ltp": 2.1, "tv": 171.03, "trd": NaN, "batb": [[0, 2, 1321.87]], "batl": NaN}, {"timestamp": 1632534145100, "ltp": 2.1, "tv": 171.03, "trd": NaN, "batb": [[0, 2, 1269.73]], "batl": NaN}, {"timestamp": 1632534207550, "ltp": 2.1, "tv": 171.03, "trd": NaN, "batb": [[0, 2, 103.92]], "batl": NaN}, {"timestamp": 1632534212710, "ltp": 2.1, "tv": 171.03, "trd": NaN, "batb": [[0, 2, 42.86]], "batl": NaN}, {"timestamp": 1632534212916, "ltp": 2.1, "tv": 171.03, "trd": NaN, "batb": [[0, 2, 1320.69]], "batl": NaN}, {"timestamp": 1632534310490, "ltp": 2.1, "tv": 171.03, "trd": NaN, "batb": [[0, 2, 103.92]], "batl": NaN}, {"timestamp": 1632534315509, "ltp": 2.1, "tv": 171.03, "trd": NaN, "batb": [[0, 2, 1320.69]], "batl": NaN}, {"timestamp": 1632534538257, "ltp": 2.1, "tv": 171.03, "trd": NaN, "batb": [[0, 2, 103.92]], "batl": NaN}, {"timestamp": 1632534543284, "ltp": 2.1, "tv": 171.03, "trd": NaN, "batb": [[0, 2, 1320.69]], "batl": NaN}, {"timestamp": 1632534816720, "ltp": 2.1, "tv": 171.03, "trd": NaN, "batb": [[0, 2, 42.86]], "batl": NaN}, {"timestamp": 1632534817238, "ltp": 2.1, "tv": 171.03, "trd": NaN, "batb": [[0, 2, 103.92]], "batl": NaN}, {"timestamp": 1632534822335, "ltp": 2.1, "tv": 171.03, "trd": NaN, "batb": [[0, 2, 1320.69]], "batl": NaN}, {"timestamp": 1632535134331, "ltp": 2.1, "tv": 171.03, "trd": NaN, "batb": [[0, 2, 103.92]], "batl": NaN}, {"timestamp": 1632535139727, "ltp": 2.1, "tv": 171.03, "trd": NaN, "batb": [[0, 2, 1320.69]], "batl": NaN}, {"timestamp": 1632535294360, "ltp": 2.1, "tv": 171.03, "trd": NaN, "batb": [[0, 2, 103.92]], "batl": NaN}, {"timestamp": 1632535299758, "ltp": 2.1, "tv": 171.03, "trd": NaN, "batb": [[0, 2, 42.86]], "batl": NaN}, {"timestamp": 1632535299863, "ltp": 2.1, "tv": 171.03, "trd": NaN, "batb": [[0, 2, 1320.69]], "batl": NaN}, {"timestamp": 1632535939677, "ltp": 2.1, "tv": 171.03, "trd": NaN, "batb": [[0, 2, 103.92]], "batl": NaN}, {"timestamp": 1632535945175, "ltp": 2.1, "tv": 171.03, "trd": NaN, "batb": [[0, 2, 1320.69]], "batl": NaN}, {"timestamp": 1632536053819, "ltp": 2.1, "tv": 171.03, "trd": NaN, "batb": [[0, 2, 42.86]], "batl": NaN}, {"timestamp": 1632536053919, "ltp": 2.1, "tv": 171.03, "trd": NaN, "batb": [[0, 2, 103.92]], "batl": NaN}, {"timestamp": 1632536059609, "ltp": 2.1, "tv": 171.03, "trd": NaN, "batb": [[0, 2, 1321.39]], "batl": NaN}, {"timestamp": 1632536088729, "ltp": 2.1, "tv": 171.03, "trd": NaN, "batb": [[0, 2, 42.86]], "batl": NaN}, {"timestamp": 1632536088832, "ltp": 2.1, "tv": 171.03, "trd": NaN, "batb": [[0, 2, 103.92]], "batl": NaN}, {"timestamp": 1632536090739, "ltp": 2.1, "tv": 171.03, "trd": NaN, "batb": [[0, 2, 61.06]], "batl": NaN}, {"timestamp": 1632536090943, "ltp": 2.1, "tv": 171.03, "trd": NaN, "batb": [[1, 1.99, 4], [2, 1.98, 4]], "batl": NaN}, {"timestamp": 1632536106778, "ltp": 2.1, "tv": 171.03, "trd": NaN, "batb": [[0, 2, 104.77], [2, 1.25, 914.87]], "batl": NaN}, {"timestamp": 1632536117701, "ltp": 2.1, "tv": 171.03, "trd": NaN, "batb": [[0, 2, 61.06]], "batl": [[0, 2.16, 85.71], [1, 2.24, 25], [2, 990, 2.2]]}, {"timestamp": 1632536164625, "ltp": 2.1, "tv": 171.03, "trd": NaN, "batb": [[0, 2, 103.92]], "batl": [[0, 2.1, 42], [1, 2.16, 85.71], [2, 2.24, 25]]}, {"timestamp": 1632536280904, "ltp": 2.1, "tv": 171.03, "trd": NaN, "batb": [[0, 2, 42.86]], "batl": NaN}, {"timestamp": 1632538881243, "ltp": 2.1, "tv": 171.03, "trd": NaN, "batb": [[1, 1.25, 914.87], [2, 1.12, 1237.68]], "batl": NaN}, {"timestamp": 1632538981094, "ltp": 2.1, "tv": 171.03, "trd": NaN, "batb": [[0, 2.04, 16.48], [1, 2, 42.86], [2, 1.25, 914.87]], "batl": NaN}, {"timestamp": 1632541250073, "ltp": 2.1, "tv": 171.03, "trd": NaN, "batb": [[1, 1.25, 914.87], [2, 1.12, 1237.68]], "batl": NaN}, {"timestamp": 1632541330768, "ltp": 2.1, "tv": 171.03, "trd": NaN, "batb": [[1, 2, 44.57], [2, 1.25, 914.87]], "batl": NaN}, {"timestamp": 1632546014055, "ltp": 2.1, "tv": 171.03, "trd": NaN, "batb": NaN, "batl": [[0, 2.08, 6.12], [1, 2.1, 42], [2, 2.16, 85.71]]}, {"timestamp": 1632547134764, "ltp": 2.1, "tv": 171.03, "trd": NaN, "batb": [[1, 1.25, 914.87], [2, 1.12, 1237.68]], "batl": NaN}, {"timestamp": 1632547135174, "ltp": 2.1, "tv": 171.03, "trd": NaN, "batb": [[1, 2.02, 36], [2, 1.25, 914.87]], "batl": [[1, 2.1, 33.43]]}, {"timestamp": 1632548429638, "ltp": 2.04, "tv": 173.84, "trd": [[2.04, 156.27]], "batb": [[0, 2.04, 15.08]], "batl": NaN}, {"timestamp": 1632549314427, "ltp": 2.04, "tv": 173.84, "trd": NaN, "batb": [[2, 1.31, 35.39]], "batl": NaN}, {"timestamp": 1632549717341, "ltp": 2.04, "tv": 179.31, "trd": [[2.04, 161.74]], "batb": [[0, 2.04, 12.34]], "batl": NaN}, {"timestamp": 1632550176729, "ltp": 2.04, "tv": 199.31, "trd": [[2.04, 181.74]], "batb": [[0, 2.04, 2.34]], "batl": NaN}, {"timestamp": 1632550176935, "ltp": 2.04, "tv": 199.31, "trd": NaN, "batb": [[0, 2.02, 36], [1, 1.31, 35.39], [2, 1.25, 914.87]], "batl": NaN}, {"timestamp": 1632550954424, "ltp": 2.04, "tv": 199.31, "trd": NaN, "batb": NaN, "batl": [[0, 2.04, 292.53], [1, 2.08, 6.12], [2, 2.1, 33.43]]}, {"timestamp": 1632550977444, "ltp": 2.04, "tv": 207.28, "trd": [[2.04, 189.71]], "batb": NaN, "batl": [[0, 2.04, 288.54]]}, {"timestamp": 1632553551807, "ltp": 2.04, "tv": 207.28, "trd": NaN, "batb": [[0, 1.31, 35.39], [1, 1.25, 914.87], [2, 1.12, 1237.68]], "batl": NaN}, {"timestamp": 1632553552126, "ltp": 2.04, "tv": 207.28, "trd": NaN, "batb": [[0, 1.63, 2261.37], [1, 1.31, 35.39], [2, 1.25, 914.87]], "batl": NaN}, {"timestamp": 1632553598771, "ltp": 2.04, "tv": 207.28, "trd": NaN, "batb": [[0, 2.02, 32.57], [1, 1.63, 2261.37], [2, 1.31, 35.39]], "batl": NaN}, {"timestamp": 1632553598975, "ltp": 2.04, "tv": 207.28, "trd": NaN, "batb": [[1, 1.31, 35.39], [2, 1.25, 914.87]], "batl": NaN}, {"timestamp": 1632553820099, "ltp": 2.04, "tv": 207.28, "trd": NaN, "batb": NaN, "batl": [[2, 2.16, 85.71]]}, {"timestamp": 1632553928840, "ltp": 2.04, "tv": 207.28, "trd": NaN, "batb": NaN, "batl": [[2, 2.1, 35.14]]}, {"timestamp": 1632554358357, "ltp": 2.04, "tv": 495.83, "trd": [[2.04, 478.25]], "batb": NaN, "batl": [[0, 2.08, 6.12], [1, 2.1, 35.14], [2, 2.16, 85.71]]}, {"timestamp": 1632554376789, "ltp": 2.08, "tv": 501.94, "trd": [[2.08, 6.12]], "batb": NaN, "batl": [[0, 2.1, 35.14], [1, 2.16, 85.71], [2, 2.24, 25]]}, {"timestamp": 1632554382708, "ltp": 2.08, "tv": 501.94, "trd": NaN, "batb": [[1, 1.99, 4], [2, 1.98, 4]], "batl": NaN}, {"timestamp": 1632554384478, "ltp": 2.08, "tv": 501.94, "trd": NaN, "batb": NaN, "batl": [[0, 2.16, 401.56], [1, 2.24, 25], [2, 5.7, 219.68]]}, {"timestamp": 1632554385201, "ltp": 2.08, "tv": 501.94, "trd": NaN, "batb": NaN, "batl": [[0, 2.16, 85.71]]}, {"timestamp": 1632554400819, "ltp": 2.08, "tv": 501.94, "trd": NaN, "batb": [[0, 2.02, 148.21], [2, 1.31, 35.39]], "batl": NaN}, {"timestamp": 1632554409825, "ltp": 2.08, "tv": 501.94, "trd": NaN, "batb": [[0, 2.02, 32.57]], "batl": NaN}, {"timestamp": 1632554411951, "ltp": 2.1, "tv": 504.94, "trd": [[2.1, 17.78]], "batb": NaN, "batl": NaN}, {"timestamp": 1632554435178, "ltp": 2.16, "tv": 585.52, "trd": [[2.16, 80.58]], "batb": NaN, "batl": [[0, 2.16, 5.13]]}, {"timestamp": 1632554480736, "ltp": 2.16, "tv": 585.52, "trd": NaN, "batb": NaN, "batl": [[0, 2.14, 70.28], [1, 2.16, 5.13], [2, 2.24, 25]]}, {"timestamp": 1632554701139, "ltp": 2.16, "tv": 585.52, "trd": NaN, "batb": NaN, "batl": [[0, 2.14, 171.37]]}, {"timestamp": 1632554842723, "ltp": 2.16, "tv": 585.52, "trd": NaN, "batb": [[0, 2.04, 292.53], [1, 2.02, 32.57], [2, 1.99, 4]], "batl": NaN}, {"timestamp": 1632555136136, "ltp": 2.16, "tv": 585.52, "trd": NaN, "batb": NaN, "batl": [[1, 2.24, 25], [2, 5.7, 219.68]]}, {"timestamp": 1632555140714, "ltp": 2.16, "tv": 585.52, "trd": NaN, "batb": NaN, "batl": [[0, 2.14, 101.09]]}, {"timestamp": 1632555141135, "ltp": 2.16, "tv": 585.52, "trd": NaN, "batb": NaN, "batl": [[0, 2.1, 35.14]]}, {"timestamp": 1632555190009, "ltp": 2.16, "tv": 585.52, "trd": NaN, "batb": [[0, 2.06, 81.43], [1, 2.04, 292.53], [2, 2.02, 32.57]], "batl": NaN}, {"timestamp": 1632555210730, "ltp": 2.16, "tv": 585.52, "trd": NaN, "batb": [[0, 2.04, 292.53], [1, 2.02, 32.57], [2, 1.99, 4]], "batl": NaN}, {"timestamp": 1632555213759, "ltp": 2.12, "tv": 703.42, "trd": [[2.1, 123.74], [2.12, 11.94]], "batb": NaN, "batl": [[0, 2.24, 25], [1, 5.7, 219.68], [2, 990, 2.2]]}, {"timestamp": 1632555213915, "ltp": 2.12, "tv": 703.42, "trd": NaN, "batb": NaN, "batl": [[0, 2.22, 487.43], [1, 2.24, 25], [2, 5.7, 219.68]]}, {"timestamp": 1632555215636, "ltp": 2.12, "tv": 703.42, "trd": NaN, "batb": [[1, 1.99, 4], [2, 1.7, 21.24]], "batl": NaN}, {"timestamp": 1632555216633, "ltp": 2.12, "tv": 703.42, "trd": NaN, "batb": [[0, 2.06, 34.28], [1, 2.04, 292.53], [2, 1.99, 4]], "batl": [[0, 2.14, 35.14], [1, 2.22, 487.43], [2, 2.24, 25]]}, {"timestamp": 1632555284238, "ltp": 2.12, "tv": 703.42, "trd": NaN, "batb": NaN, "batl": [[1, 2.24, 25], [2, 5.7, 219.68]]}, {"timestamp": 1632555737568, "ltp": 2.12, "tv": 703.42, "trd": NaN, "batb": [[0, 2.06, 58.28]], "batl": [[0, 2.22, 664.23]]}, {"timestamp": 1632555767448, "ltp": 2.12, "tv": 703.42, "trd": NaN, "batb": [[0, 2.08, 36], [1, 2.06, 28.52], [2, 2.04, 292.53]], "batl": [[0, 2.16, 32.57], [1, 2.22, 587.95], [2, 2.24, 25]]}, {"timestamp": 1632555806684, "ltp": 2.12, "tv": 703.42, "trd": NaN, "batb": NaN, "batl": [[0, 2.22, 587.95], [1, 2.24, 25], [2, 5.7, 219.68]]}, {"timestamp": 1632555806892, "ltp": 2.12, "tv": 703.42, "trd": NaN, "batb": [[1, 2.04, 292.53], [2, 1.99, 4]], "batl": [[0, 2.2, 61.71], [1, 2.22, 587.95], [2, 2.24, 25]]}, {"timestamp": 1632555830670, "ltp": 2.12, "tv": 703.42, "trd": NaN, "batb": NaN, "batl": [[0, 2.18, 564.06], [1, 2.2, 61.71]]}, {"timestamp": 1632555859119, "ltp": 2.12, "tv": 703.42, "trd": NaN, "batb": NaN, "batl": [[0, 2.16, 33.43], [1, 2.18, 564.06]]}, {"timestamp": 1632556159298, "ltp": 2.12, "tv": 703.42, "trd": NaN, "batb": NaN, "batl": [[0, 2.16, 165.59], [1, 2.24, 25], [2, 5.7, 219.68]]}, {"timestamp": 1632556381359, "ltp": 2.12, "tv": 703.42, "trd": NaN, "batb": NaN, "batl": [[0, 2.14, 8.57], [1, 2.16, 165.59], [2, 2.24, 25]]}, {"timestamp": 1632556459093, "ltp": 2.12, "tv": 703.42, "trd": NaN, "batb": NaN, "batl": [[1, 2.16, 33.43]]}, {"timestamp": 1632556460397, "ltp": 2.12, "tv": 703.42, "trd": NaN, "batb": NaN, "batl": [[0, 2.16, 165.59], [1, 2.24, 25], [2, 5.7, 219.68]]}, {"timestamp": 1632556740807, "ltp": 2.12, "tv": 703.42, "trd": NaN, "batb": NaN, "batl": [[0, 2.14, 8.57], [1, 2.16, 165.59], [2, 2.24, 25]]}, {"timestamp": 1632556760453, "ltp": 2.12, "tv": 703.42, "trd": NaN, "batb": NaN, "batl": [[1, 2.16, 33.43]]}, {"timestamp": 1632556761751, "ltp": 2.12, "tv": 703.42, "trd": NaN, "batb": NaN, "batl": [[0, 2.16, 33.43], [1, 2.24, 25], [2, 5.7, 219.68]]}, {"timestamp": 1632556761955, "ltp": 2.12, "tv": 703.42, "trd": NaN, "batb": NaN, "batl": [[0, 2.16, 165.59]]}, {"timestamp": 1632556801223, "ltp": 2.12, "tv": 703.42, "trd": NaN, "batb": NaN, "batl": [[0, 2.14, 8.57], [1, 2.16, 165.59], [2, 2.24, 25]]}, {"timestamp": 1632556836591, "ltp": 2.12, "tv": 703.42, "trd": NaN, "batb": NaN, "batl": [[1, 2.16, 33.43]]}, {"timestamp": 1632556837785, "ltp": 2.12, "tv": 703.42, "trd": NaN, "batb": NaN, "batl": [[0, 2.16, 165.59], [1, 2.24, 25], [2, 5.7, 219.68]]}, {"timestamp": 1632556972039, "ltp": 2.08, "tv": 743.42, "trd": [[2.08, 46.11]], "batb": [[0, 2.08, 16]], "batl": NaN}, {"timestamp": 1632556990365, "ltp": 2.08, "tv": 743.42, "trd": NaN, "batb": [[0, 2.06, 43.71], [1, 2.04, 533.74]], "batl": [[0, 2.16, 175.02]]}, {"timestamp": 1632557208394, "ltp": 2.08, "tv": 743.42, "trd": NaN, "batb": [[1, 2.04, 292.53]], "batl": NaN}, {"timestamp": 1632557640529, "ltp": 2.08, "tv": 743.42, "trd": NaN, "batb": NaN, "batl": [[0, 2.14, 8.57], [1, 2.16, 175.02], [2, 2.24, 25]]}, {"timestamp": 1632557889859, "ltp": 2.08, "tv": 743.42, "trd": NaN, "batb": NaN, "batl": [[1, 2.16, 42.86]]}, {"timestamp": 1632557891263, "ltp": 2.08, "tv": 743.42, "trd": NaN, "batb": NaN, "batl": [[0, 2.16, 175.02], [1, 2.24, 25], [2, 5.7, 219.68]]}, {"timestamp": 1632558300566, "ltp": 2.08, "tv": 743.42, "trd": NaN, "batb": NaN, "batl": [[0, 2.14, 8.57], [1, 2.16, 175.02], [2, 2.24, 25]]}, {"timestamp": 1632558396167, "ltp": 2.08, "tv": 743.42, "trd": NaN, "batb": NaN, "batl": [[1, 2.16, 42.86]]}, {"timestamp": 1632558397646, "ltp": 2.08, "tv": 743.42, "trd": NaN, "batb": NaN, "batl": [[0, 2.16, 42.86], [1, 2.24, 25], [2, 5.7, 219.68]]}, {"timestamp": 1632558397932, "ltp": 2.08, "tv": 743.42, "trd": NaN, "batb": NaN, "batl": [[0, 2.16, 175.02]]}, {"timestamp": 1632558480896, "ltp": 2.08, "tv": 743.42, "trd": NaN, "batb": NaN, "batl": [[0, 2.14, 8.57], [1, 2.16, 175.02], [2, 2.24, 25]]}, {"timestamp": 1632558697848, "ltp": 2.08, "tv": 743.42, "trd": NaN, "batb": NaN, "batl": [[1, 2.16, 42.86]]}, {"timestamp": 1632558699723, "ltp": 2.08, "tv": 743.42, "trd": NaN, "batb": NaN, "batl": [[0, 2.16, 42.86], [1, 2.24, 25], [2, 5.7, 219.68]]}, {"timestamp": 1632558699932, "ltp": 2.08, "tv": 743.42, "trd": NaN, "batb": NaN, "batl": [[0, 2.16, 175.02]]}, {"timestamp": 1632558701807, "ltp": 2.06, "tv": 783.42, "trd": [[2.06, 40]], "batb": [[0, 2.06, 23.72]], "batl": NaN}, {"timestamp": 1632558721435, "ltp": 2.06, "tv": 783.42, "trd": NaN, "batb": [[0, 2.06, 34.86]], "batl": [[0, 2.14, 42], [1, 2.16, 132.16], [2, 2.24, 25]]}, {"timestamp": 1632558751479, "ltp": 2.06, "tv": 783.42, "trd": NaN, "batb": NaN, "batl": [[1, 2.24, 25], [2, 5.7, 219.68]]}, {"timestamp": 1632558934635, "ltp": 2.06, "tv": 787.41, "trd": [[2.06, 43.99]], "batb": [[0, 2.06, 32.86]], "batl": NaN}, {"timestamp": 1632559098671, "ltp": 2.14, "tv": 813.97, "trd": [[2.14, 26.55]], "batb": NaN, "batl": [[0, 2.14, 28.72]]}, {"timestamp": 1632559151522, "ltp": 2.14, "tv": 813.97, "trd": NaN, "batb": [[0, 2.06, 43.15]], "batl": [[0, 2.14, 34.72]]}, {"timestamp": 1632559181178, "ltp": 2.14, "tv": 813.97, "trd": NaN, "batb": [[2, 1.91, 35.14]], "batl": NaN}, {"timestamp": 1632559425144, "ltp": 2.06, "tv": 826.27, "trd": [[2.06, 56.3]], "batb": [[0, 2.06, 36.99]], "batl": NaN}, {"timestamp": 1632559481816, "ltp": 2.06, "tv": 826.27, "trd": NaN, "batb": [[0, 2.04, 574.69], [1, 1.91, 35.14], [2, 1.7, 21.24]], "batl": [[0, 2.22, 597.34]]}, {"timestamp": 1632559489246, "ltp": 2.06, "tv": 826.27, "trd": NaN, "batb": NaN, "batl": [[0, 2.12, 51.29]]}, {"timestamp": 1632559511749, "ltp": 2.06, "tv": 826.27, "trd": NaN, "batb": [[0, 2.06, 35.14], [1, 2.04, 574.69], [2, 1.91, 35.14]], "batl": [[1, 2.14, 32.57], [2, 2.24, 25]]}, {"timestamp": 1632559583660, "ltp": 2.06, "tv": 826.27, "trd": NaN, "batb": [[1, 2.04, 292.53]], "batl": NaN}, {"timestamp": 1632560950985, "ltp": 2.06, "tv": 826.27, "trd": NaN, "batb": [[0, 2.06, 58.11]], "batl": NaN}, {"timestamp": 1632561240633, "ltp": 2.06, "tv": 826.27, "trd": NaN, "batb": [[0, 2.1, 5.46], [1, 2.06, 58.11], [2, 2.04, 292.53]], "batl": [[1, 2.14, 36.57]]}, {"timestamp": 1632561251063, "ltp": 2.06, "tv": 826.27, "trd": NaN, "batb": [[1, 2.06, 35.14]], "batl": NaN}, {"timestamp": 1632561543352, "ltp": 2.06, "tv": 826.27, "trd": NaN, "batb": NaN, "batl": [[1, 2.14, 46.86]]}, {"timestamp": 1632561696705, "ltp": 2.1, "tv": 849.95, "trd": [[2.1, 147.42]], "batb": [[0, 2.06, 74.45], [1, 2.04, 292.53], [2, 1.91, 35.14]], "batl": [[0, 2.1, 103.16], [1, 2.12, 58.29], [2, 2.14, 48.86]]}, {"timestamp": 1632561696870, "ltp": 2.1, "tv": 849.95, "trd": NaN, "batb": [[0, 2.08, 6], [1, 2.06, 74.45], [2, 2.04, 292.53]], "batl": NaN}, {"timestamp": 1632561720805, "ltp": 2.1, "tv": 849.95, "trd": NaN, "batb": [[0, 2.06, 74.45], [1, 2.04, 292.53], [2, 1.91, 35.14]], "batl": [[1, 2.12, 51.29], [2, 2.14, 42.86]]}, {"timestamp": 1632562717794, "ltp": 2.1, "tv": 849.95, "trd": NaN, "batb": [[0, 2.08, 7], [1, 2.06, 81.45], [2, 2.04, 299.53]], "batl": [[1, 2.12, 61.29]]}, {"timestamp": 1632562718311, "ltp": 2.1, "tv": 849.95, "trd": NaN, "batb": NaN, "batl": [[0, 2.1, 113.16]]}, {"timestamp": 1632562783518, "ltp": 2.1, "tv": 849.95, "trd": NaN, "batb": [[1, 2.06, 42.14]], "batl": NaN}, {"timestamp": 1632562799163, "ltp": 2.1, "tv": 849.95, "trd": NaN, "batb": [[0, 2.08, 28], [1, 2.06, 63.14], [2, 2.04, 320.53]], "batl": [[0, 2.1, 130.16], [1, 2.12, 76.29], [2, 2.14, 65.86]]}, {"timestamp": 1632562938509, "ltp": 2.08, "tv": 855.25, "trd": [[2.08, 51.42]], "batb": [[0, 2.08, 25.35]], "batl": NaN}, {"timestamp": 1632563117267, "ltp": 2.08, "tv": 855.45, "trd": [[2.08, 51.62]], "batb": [[0, 2.08, 25.25]], "batl": NaN}, {"timestamp": 1632563561820, "ltp": 2.08, "tv": 855.45, "trd": NaN, "batb": [[0, 2.08, 44.49]], "batl": NaN}, {"timestamp": 1632564663053, "ltp": 2.08, "tv": 855.45, "trd": NaN, "batb": [[0, 2.08, 19.24]], "batl": NaN}, {"timestamp": 1632565042241, "ltp": 2.08, "tv": 855.45, "trd": NaN, "batb": NaN, "batl": [[0, 2.1, 27]]}, {"timestamp": 1632565050688, "ltp": 2.08, "tv": 855.45, "trd": NaN, "batb": [[0, 2.06, 63.14], [1, 2.04, 320.53], [2, 2.02, 28.65]], "batl": NaN}, {"timestamp": 1632565050959, "ltp": 2.08, "tv": 855.45, "trd": NaN, "batb": [[0, 2.06, 85.14], [1, 2.04, 342.53], [2, 2.02, 50]], "batl": [[0, 2.1, 45], [1, 2.12, 94.29], [2, 2.14, 82.86]]}, {"timestamp": 1632565058058, "ltp": 2.08, "tv": 855.45, "trd": NaN, "batb": [[0, 2.06, 104.56]], "batl": NaN}, {"timestamp": 1632565062992, "ltp": 2.08, "tv": 855.45, "trd": NaN, "batb": NaN, "batl": [[0, 2.08, 53.16], [1, 2.1, 45], [2, 2.12, 94.29]]}, {"timestamp": 1632565072981, "ltp": 2.08, "tv": 855.45, "trd": NaN, "batb": [[0, 2.06, 54.56], [1, 2.04, 292.53], [2, 1.7, 21.24]], "batl": [[1, 2.12, 51.29], [2, 2.14, 42.86]]}, {"timestamp": 1632565083704, "ltp": 2.08, "tv": 874.36, "trd": [[2.08, 70.52]], "batb": NaN, "batl": [[0, 2.08, 43.71]]}, {"timestamp": 1632565104434, "ltp": 2.08, "tv": 874.36, "trd": NaN, "batb": [[0, 2.06, 104.56]], "batl": [[1, 2.1, 45], [2, 2.12, 51.29]]}, {"timestamp": 1632565162337, "ltp": 2.08, "tv": 874.36, "trd": NaN, "batb": [[1, 2.04, 340.53], [2, 2.02, 48.61]], "batl": NaN}, {"timestamp": 1632565187671, "ltp": 2.08, "tv": 874.36, "trd": NaN, "batb": [[0, 2.06, 54.56], [1, 2.04, 292.53], [2, 1.7, 21.24]], "batl": [[1, 2.12, 51.29], [2, 2.14, 42.86]]}, {"timestamp": 1632565227337, "ltp": 2.08, "tv": 874.36, "trd": NaN, "batb": [[0, 2.06, 100.56]], "batl": [[1, 2.1, 42], [2, 2.12, 51.29]]}, {"timestamp": 1632565279551, "ltp": 2.08, "tv": 874.36, "trd": NaN, "batb": NaN, "batl": [[0, 2.1, 42], [1, 2.12, 51.29], [2, 2.24, 25]]}, {"timestamp": 1632565286248, "ltp": 2.08, "tv": 874.36, "trd": NaN, "batb": [[1, 2.04, 339.53], [2, 2.02, 47.37]], "batl": [[1, 2.12, 91.29], [2, 2.14, 37]]}, {"timestamp": 1632565311584, "ltp": 2.08, "tv": 874.36, "trd": NaN, "batb": [[0, 2.06, 54.56], [1, 2.04, 292.53], [2, 1.7, 21.24]], "batl": [[0, 2.12, 51.29], [1, 2.24, 25], [2, 5.7, 219.68]]}, {"timestamp": 1632565370148, "ltp": 2.08, "tv": 874.36, "trd": NaN, "batb": [[0, 2.06, 100.56], [2, 2.02, 4]], "batl": [[0, 2.1, 42], [1, 2.12, 51.29], [2, 2.14, 41.14]]}, {"timestamp": 1632565373770, "ltp": 2.06, "tv": 961.78, "trd": [[2.06, 143.72]], "batb": [[0, 2.06, 56.85], [1, 2.04, 339.53], [2, 2.02, 51.42]], "batl": [[1, 2.12, 91.29], [2, 2.14, 78.14]]}, {"timestamp": 1632565479812, "ltp": 2.06, "tv": 961.78, "trd": NaN, "batb": NaN, "batl": [[2, 2.14, 37]]}, {"timestamp": 1632565480603, "ltp": 2.06, "tv": 961.78, "trd": NaN, "batb": [[1, 2.04, 372.1]], "batl": [[1, 2.12, 135]]}, {"timestamp": 1632565557951, "ltp": 2.06, "tv": 961.78, "trd": NaN, "batb": [[0, 2.06, 10.85]], "batl": [[0, 2.08, 46], [1, 2.1, 42], [2, 2.12, 135]]}, {"timestamp": 1632565563220, "ltp": 2.06, "tv": 961.78, "trd": NaN, "batb": [[0, 2.04, 386.31], [1, 2.02, 51.42], [2, 2, 47.42]], "batl": [[0, 2.06, 46.52], [1, 2.08, 46], [2, 2.1, 42]]}, {"timestamp": 1632565568744, "ltp": 2.06, "tv": 961.78, "trd": NaN, "batb": [[0, 2.04, 397.27]], "batl": NaN}, {"timestamp": 1632565584436, "ltp": 2.06, "tv": 987.64, "trd": [[2.06, 169.58]], "batb": [[0, 2.04, 350.27], [1, 2.02, 4], [2, 1.7, 21.24]], "batl": [[0, 2.06, 33.59]]}, {"timestamp": 1632565612090, "ltp": 2.06, "tv": 987.64, "trd": NaN, "batb": [[1, 2.02, 55.55]], "batl": NaN}, {"timestamp": 1632565812611, "ltp": 2.06, "tv": 987.64, "trd": NaN, "batb": [[0, 2.04, 336.06]], "batl": NaN}, {"timestamp": 1632565972724, "ltp": 2.06, "tv": 987.64, "trd": NaN, "batb": [[0, 2.04, 303.49]], "batl": NaN}, {"timestamp": 1632566000794, "ltp": 2.06, "tv": 987.64, "trd": NaN, "batb": [[0, 2.04, 337.77]], "batl": NaN}, {"timestamp": 1632567342336, "ltp": 2.04, "tv": 1137.65, "trd": [[2.04, 628.26]], "batb": [[0, 2.04, 262.77], [1, 2.02, 51.55]], "batl": NaN}, {"timestamp": 1632567920187, "ltp": 2.06, "tv": 1141.65, "trd": [[2.06, 173.58]], "batb": NaN, "batl": [[0, 2.06, 31.59]]}, {"timestamp": 1632568571287, "ltp": 2.06, "tv": 1141.65, "trd": NaN, "batb": [[1, 2.02, 27]], "batl": [[1, 2.08, 21], [2, 2.1, 21]]}, {"timestamp": 1632568578676, "ltp": 2.06, "tv": 1141.65, "trd": NaN, "batb": NaN, "batl": [[0, 2.06, 47.06]]}, {"timestamp": 1632568642744, "ltp": 2.06, "tv": 1141.65, "trd": NaN, "batb": [[0, 2.04, 228.48], [1, 2.02, 69.86]], "batl": [[2, 2.1, 63]]}, {"timestamp": 1632568967697, "ltp": 2.06, "tv": 1161.15, "trd": [[2.06, 193.09]], "batb": NaN, "batl": [[0, 2.06, 37.31]]}, {"timestamp": 1632569694873, "ltp": 2.06, "tv": 1161.15, "trd": NaN, "batb": [[0, 2.04, 10.96]], "batl": NaN}, {"timestamp": 1632569698790, "ltp": 2.06, "tv": 1161.15, "trd": NaN, "batb": [[0, 2.02, 2890.15], [1, 2, 29], [2, 1.99, 25.49]], "batl": NaN}, {"timestamp": 1632569703981, "ltp": 2.06, "tv": 1161.15, "trd": NaN, "batb": [[0, 2.02, 2901.21]], "batl": NaN}, {"timestamp": 1632569711403, "ltp": 2.06, "tv": 1161.15, "trd": NaN, "batb": [[0, 2.04, 217.52], [1, 2.02, 82.92], [2, 2, 29]], "batl": NaN}, {"timestamp": 1632569715303, "ltp": 2.06, "tv": 1161.15, "trd": NaN, "batb": [[1, 2.02, 71.86]], "batl": NaN}, {"timestamp": 1632569721101, "ltp": 2.06, "tv": 1161.15, "trd": NaN, "batb": [[0, 2.04, 228.48]], "batl": NaN}, {"timestamp": 1632570119914, "ltp": 2.04, "tv": 1178.29, "trd": [[2.04, 645.4]], "batb": [[0, 2.04, 219.91]], "batl": NaN}, {"timestamp": 1632570126732, "ltp": 2.04, "tv": 1398.21, "trd": [[2.04, 865.31]], "batb": [[0, 2.02, 3007.66], [1, 2, 29], [2, 1.99, 25.49]], "batl": NaN}, {"timestamp": 1632570127533, "ltp": 2.04, "tv": 1398.21, "trd": NaN, "batb": [[0, 2.02, 71.86]], "batl": NaN}, {"timestamp": 1632570132744, "ltp": 2.04, "tv": 1398.21, "trd": NaN, "batb": [[0, 2, 3291.62], [1, 1.99, 25.49], [2, 1.98, 30.39]], "batl": NaN}, {"timestamp": 1632570144247, "ltp": 2.04, "tv": 1398.21, "trd": NaN, "batb": NaN, "batl": [[0, 2.06, 21.84]]}, {"timestamp": 1632570158740, "ltp": 2.04, "tv": 1398.21, "trd": NaN, "batb": [[0, 2.02, 42.86], [1, 2, 3291.62], [2, 1.99, 25.49]], "batl": NaN}, {"timestamp": 1632570159051, "ltp": 2.04, "tv": 1398.21, "trd": NaN, "batb": [[0, 2.02, 86.86], [2, 1.99, 44]], "batl": [[0, 2.06, 36], [1, 2.08, 36], [2, 2.1, 77]]}, {"timestamp": 1632570179572, "ltp": 2.04, "tv": 1398.21, "trd": NaN, "batb": [[1, 2, 56]], "batl": NaN}, {"timestamp": 1632570210935, "ltp": 2.04, "tv": 1398.21, "trd": NaN, "batb": NaN, "batl": [[0, 2.04, 48.44], [1, 2.06, 36], [2, 2.08, 36]]}, {"timestamp": 1632570231305, "ltp": 2.04, "tv": 1398.21, "trd": NaN, "batb": [[0, 2.02, 42.86]], "batl": NaN}, {"timestamp": 1632570262682, "ltp": 2.04, "tv": 1398.21, "trd": NaN, "batb": [[1, 2, 30]], "batl": [[0, 2.04, 25]]}, {"timestamp": 1632570415741, "ltp": 2.04, "tv": 1398.21, "trd": NaN, "batb": [[0, 2.02, 13.55], [1, 2, 55.64], [2, 1.99, 14]], "batl": [[0, 2.06, 12], [1, 2.08, 11], [2, 2.1, 53]]}, {"timestamp": 1632570416526, "ltp": 2.04, "tv": 1398.21, "trd": NaN, "batb": [[1, 2, 2752.01]], "batl": NaN}, {"timestamp": 1632570420287, "ltp": 2.04, "tv": 1398.21, "trd": NaN, "batb": [[1, 2, 2709.37]], "batl": NaN}, {"timestamp": 1632570442818, "ltp": 2.04, "tv": 1398.21, "trd": NaN, "batb": [[1, 2, 13]], "batl": NaN}, {"timestamp": 1632570443131, "ltp": 2.04, "tv": 1398.21, "trd": NaN, "batb": [[0, 2, 13], [1, 1.99, 14], [2, 1.98, 14]], "batl": [[0, 2.04, 16.57], [1, 2.06, 12], [2, 2.08, 11]]}, {"timestamp": 1632570446608, "ltp": 2.04, "tv": 1398.21, "trd": NaN, "batb": [[0, 2, 2715.87]], "batl": NaN}, {"timestamp": 1632570446870, "ltp": 2.04, "tv": 1398.21, "trd": NaN, "batb": [[0, 2.02, 39.57], [1, 2, 2742.87], [2, 1.99, 40]], "batl": [[0, 2.06, 33], [1, 2.08, 32], [2, 2.1, 73]]}, {"timestamp": 1632570489949, "ltp": 2.04, "tv": 1398.21, "trd": NaN, "batb": [[1, 2, 40]], "batl": NaN}, {"timestamp": 1632570491164, "ltp": 2.04, "tv": 1398.21, "trd": NaN, "batb": [[0, 2.02, 84.14]], "batl": NaN}, {"timestamp": 1632570492063, "ltp": 2.04, "tv": 1398.21, "trd": NaN, "batb": NaN, "batl": [[0, 2.04, 37.6], [1, 2.06, 33], [2, 2.08, 32]]}, {"timestamp": 1632570512451, "ltp": 2.04, "tv": 1398.21, "trd": NaN, "batb": [[0, 2.02, 44.57]], "batl": NaN}, {"timestamp": 1632570578527, "ltp": 2.04, "tv": 1418.01, "trd": [[2.04, 885.11]], "batb": NaN, "batl": [[0, 2.04, 27.7]]}, {"timestamp": 1632571424518, "ltp": 2.02, "tv": 1428.0, "trd": [[2.02, 10]], "batb": [[0, 2.02, 39.57]], "batl": NaN}, {"timestamp": 1632571511806, "ltp": 2.02, "tv": 1428.0, "trd": NaN, "batb": [[0, 2.02, 33.57]], "batl": NaN}, {"timestamp": 1632571690282, "ltp": 2.02, "tv": 1428.0, "trd": NaN, "batb": [[1, 2, 50.53]], "batl": NaN}, {"timestamp": 1632571725719, "ltp": 2.02, "tv": 1527.08, "trd": [[2.02, 109.07]], "batb": [[0, 2, 2850.06], [1, 1.99, 40], [2, 1.98, 40]], "batl": [[0, 2.02, 332.5], [1, 2.04, 27.7], [2, 2.06, 33]]}, {"timestamp": 1632571726822, "ltp": 2.02, "tv": 1527.08, "trd": NaN, "batb": [[0, 2, 2824.06], [1, 1.99, 14], [2, 1.98, 63.57]], "batl": [[1, 2.04, 9], [2, 2.06, 50.14]]}, {"timestamp": 1632571727626, "ltp": 2.02, "tv": 1602.23, "trd": [[2.02, 184.23]], "batb": NaN, "batl": [[0, 2.02, 294.92]]}, {"timestamp": 1632571737200, "ltp": 2.02, "tv": 1602.23, "trd": NaN, "batb": [[0, 2, 2855.92]], "batl": NaN}, {"timestamp": 1632571755755, "ltp": 2.02, "tv": 2201.9, "trd": [[2, 589.84], [2.02, 194.05]], "batb": [[0, 2.02, 18.72], [1, 2, 55.86], [2, 1.99, 14]], "batl": [[0, 2.04, 16.63], [1, 2.06, 57.14], [2, 2.08, 16]]}, {"timestamp": 1632571756463, "ltp": 2.02, "tv": 2201.9, "trd": NaN, "batb": [[0, 2, 55.86], [1, 1.99, 14], [2, 1.98, 13]], "batl": [[1, 2.06, 16]]}, {"timestamp": 1632571757638, "ltp": 2.02, "tv": 2201.9, "trd": NaN, "batb": NaN, "batl": [[0, 2.04, 57.77]]}, {"timestamp": 1632571764579, "ltp": 2.02, "tv": 2201.9, "trd": NaN, "batb": NaN, "batl": [[0, 2.04, 58.63]]}, {"timestamp": 1632571772074, "ltp": 2.02, "tv": 2201.9, "trd": NaN, "batb": [[0, 2, 24]], "batl": NaN}, {"timestamp": 1632571885310, "ltp": 2.0, "tv": 2205.9, "trd": [[2, 593.84]], "batb": [[0, 2, 22]], "batl": NaN}, {"timestamp": 1632572290287, "ltp": 2.0, "tv": 2205.9, "trd": NaN, "batb": [[1, 1.99, 23.72]], "batl": NaN}, {"timestamp": 1632572964892, "ltp": 2.04, "tv": 2232.44, "trd": [[2.04, 911.65]], "batb": NaN, "batl": [[0, 2.04, 45.36]]}, {"timestamp": 1632573007756, "ltp": 2.04, "tv": 2232.44, "trd": NaN, "batb": NaN, "batl": [[0, 2.04, 49], [1, 2.06, 8], [2, 2.08, 9]]}, {"timestamp": 1632573008056, "ltp": 2.04, "tv": 2232.44, "trd": NaN, "batb": [[0, 2, 23.33], [1, 1.99, 25.04]], "batl": [[0, 2.04, 50.3], [1, 2.06, 9.3]]}, {"timestamp": 1632573011753, "ltp": 2.04, "tv": 2232.44, "trd": NaN, "batb": [[0, 2, 65.97], [2, 1.98, 14.34]], "batl": [[2, 2.08, 10.31]]}, {"timestamp": 1632573197104, "ltp": 2.04, "tv": 2232.44, "trd": NaN, "batb": NaN, "batl": [[0, 2.04, 43.3], [1, 2.06, 1.3], [2, 2.08, 1.31]]}, {"timestamp": 1632573573684, "ltp": 2.0, "tv": 2252.83, "trd": [[2, 614.23]], "batb": [[0, 2, 53.97]], "batl": [[0, 2.04, 58.3]]}, {"timestamp": 1632573574756, "ltp": 2.0, "tv": 2252.83, "trd": NaN, "batb": [[0, 2, 11.33]], "batl": [[0, 2.02, 15.64], [1, 2.04, 58.3], [2, 2.06, 1.3]]}, {"timestamp": 1632573584274, "ltp": 2.0, "tv": 2252.83, "trd": NaN, "batb": [[1, 1.99, 41.05]], "batl": NaN}, {"timestamp": 1632573617711, "ltp": 2.0, "tv": 2252.83, "trd": NaN, "batb": [[0, 1.99, 34.05], [1, 1.98, 14.34], [2, 1.97, 1.48]], "batl": NaN}, {"timestamp": 1632573618332, "ltp": 2.0, "tv": 2252.83, "trd": NaN, "batb": [[0, 1.99, 33.75]], "batl": [[0, 2.02, 16.65]]}, {"timestamp": 1632573619504, "ltp": 2.0, "tv": 2252.83, "trd": NaN, "batb": [[0, 1.99, 17.74]], "batl": NaN}, {"timestamp": 1632573652660, "ltp": 2.0, "tv": 2252.83, "trd": NaN, "batb": [[0, 1.99, 10.74], [1, 1.98, 6.34]], "batl": NaN}, {"timestamp": 1632573690696, "ltp": 2.0, "tv": 2252.83, "trd": NaN, "batb": [[0, 1.98, 5], [1, 1.97, 1.48], [2, 1.93, 27.65]], "batl": [[1, 2.04, 51.3]]}, {"timestamp": 1632573691400, "ltp": 2.0, "tv": 2252.83, "trd": NaN, "batb": [[1, 1.79, 32.54], [2, 1.78, 16.01]], "batl": NaN}, {"timestamp": 1632573695690, "ltp": 2.0, "tv": 2252.83, "trd": NaN, "batb": [[0, 1.95, 4.38], [2, 1.7, 21.24]], "batl": NaN}, {"timestamp": 1632573696392, "ltp": 2.0, "tv": 2252.83, "trd": NaN, "batb": [[1, 1.77, 33.39]], "batl": NaN}, {"timestamp": 1632573708745, "ltp": 2.0, "tv": 2252.83, "trd": NaN, "batb": [[0, 1.97, 41.14], [1, 1.95, 4.38], [2, 1.77, 33.39]], "batl": NaN}, {"timestamp": 1632573709446, "ltp": 2.0, "tv": 2252.83, "trd": NaN, "batb": [[0, 1.97, 45.14], [2, 1.93, 27.65]], "batl": NaN}, {"timestamp": 1632573774402, "ltp": 2.0, "tv": 2252.83, "trd": NaN, "batb": [[0, 1.97, 61.31]], "batl": NaN}, {"timestamp": 1632573835696, "ltp": 2.0, "tv": 2252.83, "trd": NaN, "batb": [[0, 1.97, 45.14]], "batl": NaN}, {"timestamp": 1632573943828, "ltp": 2.0, "tv": 2252.83, "trd": NaN, "batb": [[0, 1.98, 6.23], [1, 1.97, 45.14], [2, 1.95, 4.38]], "batl": [[0, 2, 4], [1, 2.02, 16.65], [2, 2.04, 51.3]]}, {"timestamp": 1632573944535, "ltp": 2.0, "tv": 2252.83, "trd": NaN, "batb": NaN, "batl": [[0, 2, 16.51], [1, 2.02, 10.01]]}, {"timestamp": 1632573990986, "ltp": 2.0, "tv": 2252.83, "trd": NaN, "batb": NaN, "batl": [[0, 2, 12.51]]}, {"timestamp": 1632573994857, "ltp": 2.0, "tv": 2252.83, "trd": NaN, "batb": [[1, 1.97, 61.31]], "batl": NaN}, {"timestamp": 1632574295759, "ltp": 2.0, "tv": 2252.83, "trd": NaN, "batb": [[0, 1.97, 20.89], [1, 1.95, 4.38], [2, 1.94, 53.14]], "batl": [[1, 2.02, 61.44], [2, 2.04, 9.3]]}, {"timestamp": 1632574296366, "ltp": 2.0, "tv": 2252.83, "trd": NaN, "batb": [[0, 1.97, 20.17]], "batl": NaN}, {"timestamp": 1632574301763, "ltp": 2.0, "tv": 2252.83, "trd": NaN, "batb": [[0, 1.96, 6.17]], "batl": NaN}, {"timestamp": 1632574302150, "ltp": 2.0, "tv": 2252.83, "trd": NaN, "batb": [[0, 1.96, 5.38], [1, 1.95, 5.18], [2, 1.94, 53.94]], "batl": NaN}, {"timestamp": 1632574645041, "ltp": 1.96, "tv": 2262.83, "trd": [[1.96, 10]], "batb": [[0, 1.95, 5.56], [1, 1.94, 53.94], [2, 1.91, 28.26]], "batl": NaN}, {"timestamp": 1632574817771, "ltp": 1.96, "tv": 2262.83, "trd": NaN, "batb": [[0, 1.96, 41.52], [1, 1.95, 5.18], [2, 1.91, 29.06]], "batl": [[1, 2.02, 43.44]]}, {"timestamp": 1632574818072, "ltp": 1.96, "tv": 2262.83, "trd": NaN, "batb": [[0, 1.96, 42.33]], "batl": NaN}, {"timestamp": 1632574837685, "ltp": 1.96, "tv": 2262.83, "trd": NaN, "batb": [[0, 1.96, 1.19]], "batl": NaN}, {"timestamp": 1632574838375, "ltp": 1.96, "tv": 2262.83, "trd": NaN, "batb": [[0, 1.95, 4.38], [1, 1.77, 34.19], [2, 1.7, 21.24]], "batl": NaN}, {"timestamp": 1632574858789, "ltp": 1.96, "tv": 2262.83, "trd": NaN, "batb": [[0, 1.94, 79.55], [1, 1.77, 33.39]], "batl": [[0, 2, 13.07]]}, {"timestamp": 1632574859314, "ltp": 1.96, "tv": 2262.83, "trd": NaN, "batb": [[0, 1.95, 5.93], [1, 1.94, 79.55], [2, 1.91, 28.26]], "batl": NaN}, {"timestamp": 1632574873637, "ltp": 1.96, "tv": 2262.83, "trd": NaN, "batb": [[0, 1.97, 6.13], [1, 1.96, 41.9], [2, 1.95, 5.93]], "batl": [[0, 2, 12.51]]}, {"timestamp": 1632574991538, "ltp": 1.96, "tv": 2262.83, "trd": NaN, "batb": [[2, 1.95, 22.58]], "batl": NaN}, {"timestamp": 1632575033462, "ltp": 1.96, "tv": 2262.83, "trd": NaN, "batb": [[1, 1.96, 58.15]], "batl": NaN}, {"timestamp": 1632575039186, "ltp": 1.96, "tv": 2262.83, "trd": NaN, "batb": [[1, 1.96, 41.9], [2, 1.95, 38.83]], "batl": NaN}, {"timestamp": 1632575069233, "ltp": 2.0, "tv": 2281.69, "trd": [[2, 633.09]], "batb": NaN, "batl": [[0, 2, 3.08], [1, 2.02, 42.43]]}, {"timestamp": 1632575071744, "ltp": 2.0, "tv": 2284.77, "trd": [[2, 636.17]], "batb": [[2, 1.95, 22.58]], "batl": [[0, 2.02, 42.43], [1, 2.04, 9.3], [2, 2.06, 1.3]]}, {"timestamp": 1632575072236, "ltp": 2.0, "tv": 2289.77, "trd": [[2, 641.17]], "batb": [[0, 2, 7], [1, 1.97, 6.13], [2, 1.96, 58.15]], "batl": [[0, 2.02, 38.1]]}, {"timestamp": 1632575091664, "ltp": 2.0, "tv": 2299.45, "trd": [[2, 650.86]], "batb": [[0, 2, 2.16]], "batl": NaN}, {"timestamp": 1632575112958, "ltp": 2.0, "tv": 2299.45, "trd": NaN, "batb": [[2, 1.96, 41.9]], "batl": NaN}, {"timestamp": 1632575134166, "ltp": 2.0, "tv": 2299.45, "trd": NaN, "batb": [[1, 1.97, 50.13]], "batl": NaN}, {"timestamp": 1632575173615, "ltp": 2.0, "tv": 2299.45, "trd": NaN, "batb": NaN, "batl": [[0, 2.02, 45.81]]}, {"timestamp": 1632575283360, "ltp": 2.0, "tv": 2299.45, "trd": NaN, "batb": [[0, 2, 32], [1, 1.99, 33.89], [2, 1.97, 73.76]], "batl": [[0, 2.02, 41.14], [1, 2.04, 24.3]]}, {"timestamp": 1632575297774, "ltp": 2.02, "tv": 2363.59, "trd": [[2.02, 258.19]], "batb": [[0, 2, 33.34]], "batl": [[0, 2.04, 59.78], [1, 2.06, 1.3], [2, 2.08, 1.31]]}, {"timestamp": 1632575298758, "ltp": 2.02, "tv": 2363.59, "trd": NaN, "batb": [[0, 2, 61.34]], "batl": [[0, 2.04, 36.78]]}, {"timestamp": 1632575299749, "ltp": 2.02, "tv": 2363.59, "trd": NaN, "batb": [[2, 1.98, 59.14]], "batl": [[1, 2.06, 44.16]]}, {"timestamp": 1632575300357, "ltp": 2.02, "tv": 2363.59, "trd": NaN, "batb": [[2, 1.98, 60.51]], "batl": [[0, 2.04, 1.3]]}, {"timestamp": 1632575313052, "ltp": 2.02, "tv": 2363.59, "trd": NaN, "batb": [[0, 2.02, 60.21], [1, 2, 61.34], [2, 1.99, 33.89]], "batl": [[0, 2.06, 44.16], [1, 2.08, 1.31], [2, 2.1, 11.49]]}, {"timestamp": 1632575345732, "ltp": 2.02, "tv": 2363.59, "trd": NaN, "batb": [[0, 2.02, 75.98]], "batl": NaN}, {"timestamp": 1632575346358, "ltp": 2.02, "tv": 2363.59, "trd": NaN, "batb": [[1, 2, 34.34], [2, 1.99, 18.3]], "batl": NaN}, {"timestamp": 1632575364582, "ltp": 2.02, "tv": 2363.59, "trd": NaN, "batb": [[0, 2.02, 60.21]], "batl": NaN}, {"timestamp": 1632575480786, "ltp": 2.02, "tv": 2363.59, "trd": NaN, "batb": [[2, 1.99, 69.73]], "batl": NaN}, {"timestamp": 1632575494779, "ltp": 2.02, "tv": 2363.59, "trd": NaN, "batb": [[0, 2.02, 1.6], [2, 1.99, 18.3]], "batl": [[0, 2.06, 113.42]]}, {"timestamp": 1632575600792, "ltp": 2.02, "tv": 2365.19, "trd": [[2.02, 259.79]], "batb": [[0, 2, 34.34], [1, 1.99, 18.3], [2, 1.98, 1.37]], "batl": NaN}, {"timestamp": 1632575724694, "ltp": 2.0, "tv": 2405.19, "trd": [[2, 690.86]], "batb": [[0, 2, 14.34]], "batl": NaN}, {"timestamp": 1632575771644, "ltp": 2.0, "tv": 2405.19, "trd": NaN, "batb": [[0, 2.02, 34.51], [1, 2, 23.34], [2, 1.99, 18.3]], "batl": NaN}, {"timestamp": 1632575820810, "ltp": 2.02, "tv": 2505.2, "trd": [[2.02, 359.79]], "batb": [[0, 2, 23.34], [1, 1.99, 18.3], [2, 1.98, 1.37]], "batl": NaN}, {"timestamp": 1632575826400, "ltp": 2.02, "tv": 2505.2, "trd": NaN, "batb": NaN, "batl": [[1, 2.08, 1.41]]}, {"timestamp": 1632575893714, "ltp": 2.02, "tv": 2505.2, "trd": NaN, "batb": NaN, "batl": [[0, 2.04, 4], [1, 2.06, 113.42], [2, 2.08, 1.41]]}, {"timestamp": 1632575894749, "ltp": 2.02, "tv": 2505.2, "trd": NaN, "batb": [[0, 2, 1.34], [1, 1.99, 32.3]], "batl": [[0, 2.04, 15.64]]}, {"timestamp": 1632575901739, "ltp": 2.0, "tv": 2506.54, "trd": [[2, 692.2]], "batb": [[0, 1.98, 36.6], [1, 1.97, 76.76], [2, 1.95, 28.4]], "batl": [[0, 2.02, 21.6], [1, 2.04, 26.04], [2, 2.06, 113.42]]}, {"timestamp": 1632575902118, "ltp": 2.0, "tv": 2506.54, "trd": NaN, "batb": [[1, 1.97, 76]], "batl": [[0, 2.02, 22.7], [2, 2.06, 79.3]]}, {"timestamp": 1632575902842, "ltp": 2.0, "tv": 2506.54, "trd": NaN, "batb": [[2, 1.95, 1.33]], "batl": NaN}, {"timestamp": 1632575915445, "ltp": 2.0, "tv": 2506.54, "trd": NaN, "batb": [[1, 1.97, 129.14]], "batl": NaN}, {"timestamp": 1632575927760, "ltp": 2.0, "tv": 2506.54, "trd": NaN, "batb": [[2, 1.95, 28.4]], "batl": [[0, 2.02, 1.1], [1, 2.04, 28.66], [2, 2.06, 101.3]]}, {"timestamp": 1632575928765, "ltp": 1.98, "tv": 2518.84, "trd": [[1.98, 12.3]], "batb": [[0, 1.98, 30.45], [2, 1.95, 1.33]], "batl": NaN}, {"timestamp": 1632575949804, "ltp": 2.02, "tv": 2519.94, "trd": [[2.02, 360.89]], "batb": NaN, "batl": [[0, 2.04, 28.66], [1, 2.06, 101.3], [2, 2.08, 1.41]]}, {"timestamp": 1632575950793, "ltp": 2.02, "tv": 2519.94, "trd": NaN, "batb": [[0, 2.02, 50], [1, 1.99, 13.54], [2, 1.98, 31.86]], "batl": [[0, 2.04, 17.34]]}, {"timestamp": 1632575951502, "ltp": 2.02, "tv": 2519.94, "trd": NaN, "batb": [[0, 2, 51.63]], "batl": [[0, 2.04, 36.34]]}, {"timestamp": 1632575952007, "ltp": 2.02, "tv": 2519.94, "trd": NaN, "batb": [[0, 2, 65.23], [1, 1.99, 14.99]], "batl": [[0, 2.04, 37.76]]}, {"timestamp": 1632575969819, "ltp": 2.02, "tv": 2519.94, "trd": NaN, "batb": [[0, 1.99, 14.99], [1, 1.98, 1.41], [2, 1.97, 98.55]], "batl": NaN}, {"timestamp": 1632575978726, "ltp": 2.02, "tv": 2519.94, "trd": NaN, "batb": [[0, 1.99, 71.63]], "batl": NaN}, {"timestamp": 1632576002644, "ltp": 2.02, "tv": 2519.94, "trd": NaN, "batb": NaN, "batl": [[0, 2.04, 24.42]]}, {"timestamp": 1632576024762, "ltp": 1.99, "tv": 2559.94, "trd": [[1.99, 40]], "batb": [[0, 1.99, 63.34], [1, 1.98, 64.75]], "batl": [[0, 2.02, 31.34], [1, 2.04, 36.42], [2, 2.06, 101.3]]}, {"timestamp": 1632576025180, "ltp": 1.99, "tv": 2559.94, "trd": NaN, "batb": [[0, 1.98, 64.75], [1, 1.97, 98.55], [2, 1.95, 1.33]], "batl": [[2, 2.06, 116.3]]}, {"timestamp": 1632576050728, "ltp": 1.98, "tv": 2604.98, "trd": [[1.98, 57.34]], "batb": [[0, 1.98, 42.23]], "batl": NaN}, {"timestamp": 1632576050935, "ltp": 1.98, "tv": 2604.98, "trd": NaN, "batb": [[1, 1.97, 97.14]], "batl": [[0, 2.02, 32.95]]}, {"timestamp": 1632576072116, "ltp": 1.98, "tv": 2604.98, "trd": NaN, "batb": NaN, "batl": [[0, 2.02, 1.61], [1, 2.04, 18.42], [2, 2.06, 94.3]]}, {"timestamp": 1632576116676, "ltp": 1.98, "tv": 2604.98, "trd": NaN, "batb": NaN, "batl": [[1, 2.04, 5.42], [2, 2.06, 79.3]]}, {"timestamp": 1632576117884, "ltp": 1.98, "tv": 2604.98, "trd": NaN, "batb": [[2, 1.95, 28.4]], "batl": NaN}, {"timestamp": 1632576126574, "ltp": 1.98, "tv": 2604.98, "trd": NaN, "batb": NaN, "batl": [[1, 2.04, 57.7], [2, 2.06, 1.3]]}, {"timestamp": 1632576170845, "ltp": 1.98, "tv": 2639.26, "trd": [[1.98, 91.62]], "batb": [[0, 1.98, 25.09]], "batl": NaN}, {"timestamp": 1632576174936, "ltp": 1.98, "tv": 2639.26, "trd": NaN, "batb": [[2, 1.95, 1.33]], "batl": NaN}, {"timestamp": 1632576194251, "ltp": 2.02, "tv": 2640.87, "trd": [[2.02, 362.5]], "batb": NaN, "batl": [[0, 2.04, 57.7], [1, 2.06, 1.3], [2, 2.08, 1.41]]}, {"timestamp": 1632576194961, "ltp": 2.02, "tv": 2640.87, "trd": NaN, "batb": [[2, 1.95, 28.4]], "batl": NaN}, {"timestamp": 1632576248461, "ltp": 2.02, "tv": 2640.87, "trd": NaN, "batb": [[2, 1.95, 1.33]], "batl": [[0, 2.02, 4.82], [1, 2.04, 57.7], [2, 2.06, 1.3]]}, {"timestamp": 1632576251558, "ltp": 2.02, "tv": 2640.87, "trd": NaN, "batb": [[1, 1.97, 44]], "batl": [[1, 2.04, 90.27]]}, {"timestamp": 1632576257643, "ltp": 2.02, "tv": 2640.87, "trd": NaN, "batb": NaN, "batl": [[0, 2.02, 15.51]]}, {"timestamp": 1632576258754, "ltp": 2.02, "tv": 2640.87, "trd": NaN, "batb": [[0, 1.99, 7.85], [1, 1.98, 25.09], [2, 1.97, 44]], "batl": NaN}, {"timestamp": 1632576259677, "ltp": 2.02, "tv": 2640.87, "trd": NaN, "batb": [[0, 1.99, 52.32]], "batl": [[1, 2.04, 108.27]]}, {"timestamp": 1632576283802, "ltp": 2.02, "tv": 2651.74, "trd": [[2.02, 373.37]], "batb": NaN, "batl": [[0, 2.02, 4.63], [1, 2.04, 104.27]]}, {"timestamp": 1632576284071, "ltp": 2.02, "tv": 2651.74, "trd": NaN, "batb": [[1, 1.98, 44]], "batl": [[1, 2.04, 86.27]]}, {"timestamp": 1632576322564, "ltp": 1.99, "tv": 2756.38, "trd": [[1.99, 144.64]], "batb": [[0, 1.98, 44], [1, 1.97, 44], [2, 1.95, 28.4]], "batl": NaN}, {"timestamp": 1632576323727, "ltp": 1.99, "tv": 2756.38, "trd": NaN, "batb": [[0, 1.97, 92.5], [1, 1.95, 1.33], [2, 1.94, 42.67]], "batl": [[0, 2, 29.5], [1, 2.02, 29.11], [2, 2.04, 86.27]]}, {"timestamp": 1632576324778, "ltp": 1.99, "tv": 2756.38, "trd": NaN, "batb": [[2, 1.93, 4.26]], "batl": NaN}, {"timestamp": 1632576361704, "ltp": 1.99, "tv": 2756.38, "trd": NaN, "batb": [[2, 1.94, 43.53]], "batl": NaN}, {"timestamp": 1632576459649, "ltp": 2.0, "tv": 2757.99, "trd": [[2, 693.8]], "batb": NaN, "batl": [[0, 2, 28.7], [1, 2.02, 30.34]]}, {"timestamp": 1632576462642, "ltp": 2.0, "tv": 2757.99, "trd": NaN, "batb": [[0, 1.97, 69]], "batl": [[0, 2, 4.2], [1, 2.02, 5.86]]}, {"timestamp": 1632576463452, "ltp": 2.0, "tv": 2757.99, "trd": NaN, "batb": [[0, 1.98, 24.58], [1, 1.97, 70.18], [2, 1.95, 1.33]], "batl": [[1, 2.02, 4.63]]}, {"timestamp": 1632576471350, "ltp": 2.0, "tv": 2757.99, "trd": NaN, "batb": NaN, "batl": [[1, 2.02, 74.06], [2, 2.04, 1.42]]}, {"timestamp": 1632576474584, "ltp": 2.0, "tv": 2762.05, "trd": [[2, 697.86]], "batb": NaN, "batl": [[0, 2.02, 74.2], [1, 2.04, 1.42], [2, 2.06, 1.3]]}, {"timestamp": 1632576474923, "ltp": 2.0, "tv": 2762.05, "trd": NaN, "batb": [[1, 1.97, 69]], "batl": NaN}, {"timestamp": 1632576500498, "ltp": 2.0, "tv": 2762.05, "trd": NaN, "batb": [[0, 1.97, 112], [1, 1.94, 44.1], [2, 1.93, 31.24]], "batl": [[0, 1.99, 40.6], [1, 2, 59.14], [2, 2.02, 75.15]]}, {"timestamp": 1632576501813, "ltp": 2.0, "tv": 2762.05, "trd": NaN, "batb": [[2, 1.93, 3.59]], "batl": NaN}, {"timestamp": 1632576507912, "ltp": 2.0, "tv": 2762.05, "trd": NaN, "batb": [[0, 1.97, 44], [1, 1.96, 72.6], [2, 1.94, 44.1]], "batl": NaN}, {"timestamp": 1632576523624, "ltp": 2.0, "tv": 2889.84, "trd": [[1.99, 225.84], [2, 744.45]], "batb": NaN, "batl": [[0, 2, 35.84], [1, 2.02, 75.15], [2, 2.04, 1.42]]}, {"timestamp": 1632576523839, "ltp": 2.0, "tv": 2889.84, "trd": NaN, "batb": [[1, 1.96, 73.84]], "batl": NaN}, {"timestamp": 1632576540553, "ltp": 2.0, "tv": 2889.84, "trd": NaN, "batb": [[0, 1.97, 104.62], [1, 1.96, 44], [2, 1.94, 42.86]], "batl": [[0, 2, 18], [1, 2.02, 74.06], [2, 2.1, 10.72]]}, {"timestamp": 1632576540869, "ltp": 2.0, "tv": 2889.84, "trd": NaN, "batb": NaN, "batl": [[0, 2, 20.23]]}, {"timestamp": 1632576548478, "ltp": 2.0, "tv": 2889.84, "trd": NaN, "batb": NaN, "batl": [[0, 1.99, 5.24], [1, 2, 18], [2, 2.02, 74.06]]}, {"timestamp": 1632576561990, "ltp": 2.0, "tv": 2889.84, "trd": NaN, "batb": NaN, "batl": [[1, 2.02, 74.06], [2, 2.1, 10.72]]}, {"timestamp": 1632576562993, "ltp": 2.0, "tv": 2889.84, "trd": NaN, "batb": NaN, "batl": [[0, 1.99, 2.24]]}, {"timestamp": 1632576575321, "ltp": 2.0, "tv": 2889.84, "trd": NaN, "batb": NaN, "batl": [[1, 2, 3], [2, 2.02, 74.06]]}, {"timestamp": 1632576595151, "ltp": 2.0, "tv": 2889.84, "trd": NaN, "batb": NaN, "batl": [[0, 1.99, 4.24]]}, {"timestamp": 1632576659501, "ltp": 1.98, "tv": 2895.42, "trd": [[1.98, 97.2]], "batb": NaN, "batl": [[0, 1.99, 4.5]]}, {"timestamp": 1632576660194, "ltp": 1.98, "tv": 2900.44, "trd": [[1.98, 102.22]], "batb": [[0, 1.97, 44]], "batl": [[0, 1.99, 2]]}, {"timestamp": 1632576692505, "ltp": 1.98, "tv": 2900.44, "trd": NaN, "batb": NaN, "batl": [[2, 2.02, 69.43]]}, {"timestamp": 1632576700813, "ltp": 1.98, "tv": 2900.44, "trd": NaN, "batb": NaN, "batl": [[0, 1.99, 6.63]]}, {"timestamp": 1632576733051, "ltp": 1.99, "tv": 2908.44, "trd": [[1.99, 233.84]], "batb": NaN, "batl": [[0, 1.99, 2.63]]}, {"timestamp": 1632576760770, "ltp": 1.99, "tv": 2908.44, "trd": NaN, "batb": NaN, "batl": [[0, 1.99, 3.44]]}, {"timestamp": 1632576772326, "ltp": 1.99, "tv": 2908.44, "trd": NaN, "batb": [[1, 1.96, 87]], "batl": [[0, 1.99, 42.86]]}, {"timestamp": 1632576792550, "ltp": 1.99, "tv": 2908.44, "trd": NaN, "batb": [[1, 1.94, 42.86], [2, 1.93, 2.91]], "batl": [[0, 1.99, 3.44]]}, {"timestamp": 1632576829111, "ltp": 1.99, "tv": 2910.57, "trd": [[1.99, 235.97]], "batb": NaN, "batl": [[0, 1.99, 2.37]]}, {"timestamp": 1632576925652, "ltp": 1.99, "tv": 2910.57, "trd": NaN, "batb": [[1, 1.96, 100.5], [2, 1.94, 42.86]], "batl": [[0, 1.99, 52.87]]}, {"timestamp": 1632576926358, "ltp": 1.99, "tv": 2910.57, "trd": NaN, "batb": [[0, 1.97, 144.5]], "batl": NaN}, {"timestamp": 1632576929646, "ltp": 1.99, "tv": 2910.57, "trd": NaN, "batb": [[0, 1.97, 44], [1, 1.94, 42.86], [2, 1.93, 2.91]], "batl": [[0, 1.99, 2.37], [1, 2, 7]]}, {"timestamp": 1632576975491, "ltp": 1.99, "tv": 2910.57, "trd": NaN, "batb": [[0, 1.97, 86.52]], "batl": NaN}, {"timestamp": 1632576996029, "ltp": 1.97, "tv": 2911.79, "trd": [[1.97, 1.22]], "batb": [[0, 1.97, 85.91]], "batl": NaN}, {"timestamp": 1632577158686, "ltp": 1.97, "tv": 2911.79, "trd": NaN, "batb": [[1, 1.96, 35.08], [2, 1.94, 42.86]], "batl": NaN}, {"timestamp": 1632577177826, "ltp": 1.99, "tv": 2916.54, "trd": [[1.99, 240.72]], "batb": [[0, 1.99, 27.35], [1, 1.97, 85.91], [2, 1.96, 35.08]], "batl": [[0, 2, 3], [1, 2.02, 69.43], [2, 2.1, 10.62]]}, {"timestamp": 1632577178710, "ltp": 1.99, "tv": 2916.54, "trd": NaN, "batb": [[1, 1.98, 33.64], [2, 1.97, 64.39]], "batl": NaN}, {"timestamp": 1632577210804, "ltp": 2.0, "tv": 2917.32, "trd": [[2, 745.23]], "batb": NaN, "batl": [[0, 2, 2.61]]}, {"timestamp": 1632577211232, "ltp": 2.0, "tv": 2917.32, "trd": NaN, "batb": [[0, 1.99, 29.13], [1, 1.98, 35.42]], "batl": NaN}, {"timestamp": 1632577218757, "ltp": 2.0, "tv": 2920.24, "trd": [[2, 748.16]], "batb": [[2, 1.97, 66.18]], "batl": [[0, 2.02, 69.43], [1, 2.1, 10.62], [2, 2.12, 51.29]]}, {"timestamp": 1632577219744, "ltp": 2.0, "tv": 2920.24, "trd": NaN, "batb": [[0, 2, 33.76], [1, 1.99, 29.13], [2, 1.98, 9.78]], "batl": [[0, 2.1, 10.62], [1, 2.12, 51.29], [2, 2.24, 25]]}, {"timestamp": 1632577220629, "ltp": 2.0, "tv": 2920.24, "trd": NaN, "batb": NaN, "batl": [[0, 2.04, 69.43], [1, 2.08, 1.72], [2, 2.1, 10.62]]}, {"timestamp": 1632577221654, "ltp": 2.0, "tv": 2920.24, "trd": NaN, "batb": NaN, "batl": [[0, 2.04, 137.76]]}, {"timestamp": 1632577252509, "ltp": 2.0, "tv": 2920.24, "trd": NaN, "batb": NaN, "batl": [[0, 2.04, 68.33]]}, {"timestamp": 1632577290755, "ltp": 2.0, "tv": 2920.24, "trd": NaN, "batb": NaN, "batl": [[0, 2.04, 137.76]]}, {"timestamp": 1632577291693, "ltp": 2.0, "tv": 2920.24, "trd": NaN, "batb": [[0, 2, 102.01]], "batl": NaN}, {"timestamp": 1632577294275, "ltp": 2.0, "tv": 2920.24, "trd": NaN, "batb": NaN, "batl": [[0, 2.04, 69.43]]}, {"timestamp": 1632577300358, "ltp": 2.0, "tv": 2924.01, "trd": [[2, 751.92]], "batb": [[0, 2, 100.13]], "batl": NaN}, {"timestamp": 1632577310379, "ltp": 2.0, "tv": 2924.01, "trd": NaN, "batb": [[0, 2, 102.01], [1, 1.99, 49.13]], "batl": NaN}, {"timestamp": 1632577312581, "ltp": 2.0, "tv": 2924.01, "trd": NaN, "batb": [[0, 2, 33.76]], "batl": NaN}, {"timestamp": 1632577314702, "ltp": 2.0, "tv": 2924.01, "trd": NaN, "batb": [[0, 2.02, 32], [1, 2, 21.76], [2, 1.99, 37.13]], "batl": NaN}, {"timestamp": 1632577315777, "ltp": 2.0, "tv": 2924.01, "trd": NaN, "batb": NaN, "batl": [[0, 2.06, 69.43], [1, 2.08, 323.52]]}, {"timestamp": 1632577331738, "ltp": 2.0, "tv": 2924.01, "trd": NaN, "batb": [[0, 2.02, 33.92]], "batl": [[0, 2.06, 202.53], [1, 2.1, 10.62], [2, 2.12, 51.29]]}, {"timestamp": 1632577359140, "ltp": 2.0, "tv": 2924.01, "trd": NaN, "batb": NaN, "batl": [[0, 2.06, 204.47]]}, {"timestamp": 1632577361761, "ltp": 2.0, "tv": 2924.01, "trd": NaN, "batb": [[0, 2.02, 91.72]], "batl": NaN}, {"timestamp": 1632577390508, "ltp": 2.0, "tv": 2924.01, "trd": NaN, "batb": NaN, "batl": [[0, 2.06, 204.37]]}, {"timestamp": 1632577390918, "ltp": 2.0, "tv": 2924.01, "trd": NaN, "batb": NaN, "batl": [[0, 2.06, 202.53]]}, {"timestamp": 1632577394419, "ltp": 2.0, "tv": 2924.01, "trd": NaN, "batb": NaN, "batl": [[0, 2.06, 69.43]]}, {"timestamp": 1632577417881, "ltp": 2.02, "tv": 2934.25, "trd": [[2.02, 383.61]], "batb": [[0, 2.02, 86.6]], "batl": NaN}, {"timestamp": 1632577435707, "ltp": 2.02, "tv": 2934.72, "trd": [[2.02, 384.09]], "batb": [[0, 2.02, 86.36]], "batl": NaN}, {"timestamp": 1632577440249, "ltp": 2.02, "tv": 2934.72, "trd": NaN, "batb": [[0, 2.02, 84.44], [1, 2, 20], [2, 1.99, 35.35]], "batl": NaN}, {"timestamp": 1632577454828, "ltp": 2.02, "tv": 2934.72, "trd": NaN, "batb": [[0, 2.04, 32.47], [1, 2.02, 84.44], [2, 2, 8]], "batl": NaN}, {"timestamp": 1632577455659, "ltp": 2.02, "tv": 2934.72, "trd": NaN, "batb": [[2, 2, 57.71]], "batl": [[0, 2.08, 58.28], [1, 2.1, 797.91]]}, {"timestamp": 1632577456253, "ltp": 2.02, "tv": 2934.72, "trd": NaN, "batb": [[0, 2.02, 84.44], [1, 2, 69.71], [2, 1.99, 35.35]], "batl": NaN}, {"timestamp": 1632577471367, "ltp": 2.02, "tv": 2934.72, "trd": NaN, "batb": NaN, "batl": [[0, 2.08, 98.31], [1, 2.1, 10.62]]}, {"timestamp": 1632577475441, "ltp": 2.02, "tv": 2934.72, "trd": NaN, "batb": [[2, 1.99, 8]], "batl": NaN}, {"timestamp": 1632577485790, "ltp": 2.02, "tv": 2934.72, "trd": NaN, "batb": [[1, 2, 20]], "batl": [[0, 2.08, 40.03]]}, {"timestamp": 1632577486559, "ltp": 2.02, "tv": 2934.72, "trd": NaN, "batb": [[1, 2, 69.71]], "batl": [[0, 2.08, 100.89]]}, {"timestamp": 1632577486982, "ltp": 2.02, "tv": 2934.72, "trd": NaN, "batb": [[0, 2.02, 26.64]], "batl": NaN}, {"timestamp": 1632577500788, "ltp": 2.02, "tv": 2934.72, "trd": NaN, "batb": [[1, 2, 20]], "batl": [[0, 2.08, 40.03]]}, {"timestamp": 1632577599111, "ltp": 2.02, "tv": 2934.72, "trd": NaN, "batb": NaN, "batl": [[0, 2.08, 40.13]]}, {"timestamp": 1632577677661, "ltp": 2.02, "tv": 2934.72, "trd": NaN, "batb": NaN, "batl": [[0, 2.1, 973.25], [1, 2.12, 51.29], [2, 2.24, 25]]}, {"timestamp": 1632577685376, "ltp": 2.02, "tv": 2989.88, "trd": [[2.02, 439.25]], "batb": [[0, 2, 20], [1, 1.99, 17], [2, 1.98, 8]], "batl": NaN}, {"timestamp": 1632577692815, "ltp": 2.02, "tv": 2989.88, "trd": NaN, "batb": [[0, 2.04, 25.6], [1, 2, 8], [2, 1.99, 8]], "batl": NaN}, {"timestamp": 1632577695513, "ltp": 2.02, "tv": 2989.88, "trd": NaN, "batb": NaN, "batl": [[0, 2.1, 36.33]]}, {"timestamp": 1632577696729, "ltp": 2.02, "tv": 2989.88, "trd": NaN, "batb": [[0, 2.02, 22.6], [1, 2, 15]], "batl": [[0, 2.1, 45.07]]}, {"timestamp": 1632577698508, "ltp": 2.02, "tv": 2989.88, "trd": NaN, "batb": [[0, 1.97, 268.51], [1, 1.96, 26.78], [2, 1.95, 27.07]], "batl": NaN}, {"timestamp": 1632577699401, "ltp": 2.02, "tv": 2989.88, "trd": NaN, "batb": [[0, 1.97, 242], [1, 1.96, 28.1]], "batl": NaN}, {"timestamp": 1632577741770, "ltp": 2.02, "tv": 2989.88, "trd": NaN, "batb": [[0, 2, 23], [1, 1.97, 44.72], [2, 1.96, 28.1]], "batl": NaN}, {"timestamp": 1632577742048, "ltp": 2.02, "tv": 2989.88, "trd": NaN, "batb": [[2, 1.96, 1.32]], "batl": NaN}, {"timestamp": 1632577752764, "ltp": 2.02, "tv": 2989.88, "trd": NaN, "batb": [[0, 2, 43]], "batl": [[0, 2.04, 20.63], [1, 2.1, 45.07], [2, 2.12, 51.29]]}, {"timestamp": 1632577753095, "ltp": 2.02, "tv": 2989.88, "trd": NaN, "batb": NaN, "batl": [[1, 2.1, 10.72]]}, {"timestamp": 1632577766399, "ltp": 2.02, "tv": 2989.88, "trd": NaN, "batb": NaN, "batl": [[1, 2.1, 10.62]]}, {"timestamp": 1632577920816, "ltp": 2.02, "tv": 2989.88, "trd": NaN, "batb": [[0, 1.99, 37.62]], "batl": [[0, 2.02, 27], [1, 2.04, 20.63], [2, 2.1, 10.62]]}, {"timestamp": 1632577945558, "ltp": 2.0, "tv": 3007.92, "trd": [[2, 769.96]], "batb": NaN, "batl": NaN}, {"timestamp": 1632577982243, "ltp": 2.0, "tv": 3136.15, "trd": [[2, 898.18]], "batb": NaN, "batl": NaN}, {"timestamp": 1632577989760, "ltp": 2.0, "tv": 3264.37, "trd": [[2, 1026.4]], "batb": NaN, "batl": NaN}, {"timestamp": 1632577990436, "ltp": 2.0, "tv": 3264.37, "trd": NaN, "batb": [[0, 1.99, 82.23]], "batl": [[0, 2.02, 74], [1, 2.04, 70], [2, 2.06, 65.43]]}, {"timestamp": 1632578000581, "ltp": 2.0, "tv": 3392.59, "trd": [[2, 1154.62]], "batb": NaN, "batl": NaN}, {"timestamp": 1632578029594, "ltp": 2.0, "tv": 3392.59, "trd": NaN, "batb": [[0, 2, 13.68], [1, 1.99, 82.23], [2, 1.97, 44.72]], "batl": [[1, 2.04, 72.32]]}, {"timestamp": 1632578038682, "ltp": 2.0, "tv": 3448.27, "trd": [[2, 1210.31]], "batb": [[0, 1.98, 81.46], [1, 1.97, 44.72], [2, 1.96, 1.32]], "batl": [[0, 2, 289.44], [1, 2.02, 74], [2, 2.04, 72.32]]}, {"timestamp": 1632578047797, "ltp": 2.0, "tv": 3448.27, "trd": NaN, "batb": [[0, 1.97, 127.18], [1, 1.96, 1.32], [2, 1.93, 30.56]], "batl": NaN}, {"timestamp": 1632578048231, "ltp": 2.0, "tv": 3448.27, "trd": NaN, "batb": [[0, 1.97, 136.21], [1, 1.96, 83.46], [2, 1.93, 2.91]], "batl": [[0, 1.99, 75.46], [1, 2, 289.44], [2, 2.02, 74]]}, {"timestamp": 1632578095021, "ltp": 1.99, "tv": 3472.21, "trd": [[1.99, 264.66]], "batb": [[0, 1.97, 53.75], [1, 1.93, 2.91], [2, 1.92, 27.95]], "batl": [[0, 2, 214.44], [1, 2.04, 2.32], [2, 2.1, 10.62]]}, {"timestamp": 1632578097399, "ltp": 1.99, "tv": 3472.21, "trd": NaN, "batb": [[0, 1.97, 43.39]], "batl": NaN}, {"timestamp": 1632578178306, "ltp": 1.97, "tv": 3472.41, "trd": [[1.97, 1.42]], "batb": [[0, 1.97, 43.29]], "batl": NaN}, {"timestamp": 1632578198048, "ltp": 1.97, "tv": 3480.75, "trd": [[1.97, 9.76]], "batb": [[0, 1.97, 39.12]], "batl": NaN}, {"timestamp": 1632578207436, "ltp": 1.97, "tv": 3480.75, "trd": NaN, "batb": [[0, 1.97, 77.69]], "batl": NaN}, {"timestamp": 1632578214866, "ltp": 2.0, "tv": 3485.04, "trd": [[2, 1214.59]], "batb": NaN, "batl": [[0, 2, 210.15]]}, {"timestamp": 1632578221174, "ltp": 1.97, "tv": 3493.06, "trd": [[1.97, 17.79]], "batb": [[0, 1.97, 73.68]], "batl": NaN}, {"timestamp": 1632578246828, "ltp": 2.0, "tv": 3913.37, "trd": [[2, 1634.91]], "batb": [[0, 2, 279.25], [1, 1.97, 73.68], [2, 1.93, 2.91]], "batl": [[0, 2.04, 7.13], [1, 2.1, 10.62], [2, 2.12, 51.29]]}, {"timestamp": 1632578247715, "ltp": 2.0, "tv": 3913.37, "trd": NaN, "batb": [[2, 1.95, 27.07]], "batl": NaN}, {"timestamp": 1632578327741, "ltp": 2.0, "tv": 3913.37, "trd": NaN, "batb": [[0, 2.02, 14], [1, 2, 279.25], [2, 1.97, 73.68]], "batl": NaN}, {"timestamp": 1632578340586, "ltp": 2.0, "tv": 3913.37, "trd": NaN, "batb": [[1, 2, 277.99]], "batl": NaN}, {"timestamp": 1632578386697, "ltp": 2.02, "tv": 3941.37, "trd": [[2.02, 467.24]], "batb": [[0, 2, 277.99], [1, 1.97, 73.68], [2, 1.95, 27.07]], "batl": [[0, 2.02, 174.46], [1, 2.04, 7.13], [2, 2.1, 10.62]]}, {"timestamp": 1632578387743, "ltp": 2.02, "tv": 4024.89, "trd": [[2.02, 550.76]], "batb": NaN, "batl": [[0, 2.02, 132.7]]}, {"timestamp": 1632578424551, "ltp": 2.0, "tv": 4144.88, "trd": [[2, 1754.9]], "batb": [[0, 2, 217.99]], "batl": [[1, 2.1, 10.62], [2, 2.12, 51.29]]}, {"timestamp": 1632578437488, "ltp": 2.0, "tv": 4164.89, "trd": [[2, 1774.91]], "batb": [[0, 2, 207.99]], "batl": NaN}, {"timestamp": 1632578456567, "ltp": 2.02, "tv": 4297.59, "trd": [[2.02, 683.46]], "batb": NaN, "batl": [[0, 2.1, 10.62], [1, 2.12, 51.29], [2, 2.24, 25]]}, {"timestamp": 1632578457610, "ltp": 2.02, "tv": 4297.59, "trd": NaN, "batb": NaN, "batl": [[0, 2.08, 1301.4], [1, 2.1, 10.62], [2, 2.12, 51.29]]}, {"timestamp": 1632578458614, "ltp": 2.02, "tv": 4297.59, "trd": NaN, "batb": [[0, 2.02, 43.78], [1, 2, 207.99], [2, 1.97, 73.68]], "batl": [[0, 2.08, 1806.76]]}, {"timestamp": 1632578474597, "ltp": 2.02, "tv": 4297.59, "trd": NaN, "batb": NaN, "batl": [[0, 2.04, 293.25]]}, {"timestamp": 1632578480791, "ltp": 2.02, "tv": 4317.58, "trd": [[2.02, 703.46]], "batb": [[0, 2.02, 33.78]], "batl": NaN}, {"timestamp": 1632578492128, "ltp": 2.02, "tv": 4337.58, "trd": [[2.02, 723.46]], "batb": [[0, 2.02, 23.78]], "batl": NaN}, {"timestamp": 1632578494674, "ltp": 2.02, "tv": 4337.58, "trd": NaN, "batb": [[2, 1.98, 16.17]], "batl": NaN}, {"timestamp": 1632578497607, "ltp": 2.02, "tv": 4337.58, "trd": NaN, "batb": [[0, 2, 207.99], [1, 1.98, 16.17], [2, 1.97, 73.68]], "batl": NaN}, {"timestamp": 1632578504251, "ltp": 2.02, "tv": 4337.58, "trd": NaN, "batb": NaN, "batl": [[0, 2.04, 286.12]]}, {"timestamp": 1632578532422, "ltp": 2.02, "tv": 4337.58, "trd": NaN, "batb": [[0, 2, 465.12]], "batl": NaN}, {"timestamp": 1632578532976, "ltp": 2.02, "tv": 4337.58, "trd": NaN, "batb": [[0, 2, 545.44], [1, 1.99, 43.87], [2, 1.98, 16.17]], "batl": NaN}, {"timestamp": 1632578550622, "ltp": 2.02, "tv": 4337.58, "trd": NaN, "batb": [[0, 2.02, 96.84], [1, 2, 545.44], [2, 1.99, 43.87]], "batl": NaN}, {"timestamp": 1632578552737, "ltp": 2.04, "tv": 4529.38, "trd": [[2.04, 1103.45]], "batb": [[0, 2, 465.12], [1, 1.98, 16.17], [2, 1.97, 73.68]], "batl": [[0, 2.04, 190.22]]}, {"timestamp": 1632578560929, "ltp": 2.04, "tv": 4529.38, "trd": NaN, "batb": [[0, 2.02, 35.11], [1, 2, 465.12], [2, 1.98, 16.17]], "batl": NaN}, {"timestamp": 1632578579548, "ltp": 2.04, "tv": 4529.38, "trd": NaN, "batb": NaN, "batl": [[0, 2.04, 371.14]]}, {"timestamp": 1632578594367, "ltp": 2.04, "tv": 4529.38, "trd": NaN, "batb": [[2, 1.98, 22.25]], "batl": NaN}, {"timestamp": 1632578606694, "ltp": 2.02, "tv": 4619.59, "trd": [[2.02, 813.67]], "batb": [[0, 2, 465.12], [1, 1.98, 22.25], [2, 1.97, 38.57]], "batl": [[0, 2.02, 2514.8], [1, 2.04, 371.14], [2, 2.1, 10.62]]}, {"timestamp": 1632578617815, "ltp": 2.02, "tv": 4698.06, "trd": [[2.02, 892.14]], "batb": [[0, 2, 556.34]], "batl": [[0, 2.02, 2436.33]]}, {"timestamp": 1632578631248, "ltp": 2.02, "tv": 6378.35, "trd": [[2.02, 2572.43]], "batb": NaN, "batl": [[0, 2.02, 756.04]]}, {"timestamp": 1632578632912, "ltp": 2.02, "tv": 6378.35, "trd": NaN, "batb": NaN, "batl": [[0, 2.02, 756.67]]}, {"timestamp": 1632578686937, "ltp": 2.0, "tv": 6466.34, "trd": [[2, 1862.9]], "batb": [[0, 2, 512.34]], "batl": NaN}, {"timestamp": 1632578693830, "ltp": 2.0, "tv": 6466.34, "trd": NaN, "batb": [[1, 1.98, 16.17]], "batl": NaN}, {"timestamp": 1632578699745, "ltp": 2.02, "tv": 7223.01, "trd": [[2.02, 3329.1]], "batb": NaN, "batl": [[0, 2.04, 371.14], [1, 2.1, 10.62], [2, 2.12, 51.29]]}, {"timestamp": 1632578701754, "ltp": 2.02, "tv": 7223.01, "trd": NaN, "batb": [[0, 2.02, 90.31], [1, 2, 512.34], [2, 1.98, 16.17]], "batl": NaN}, {"timestamp": 1632578702738, "ltp": 2.02, "tv": 7413.32, "trd": [[2.02, 3519.41]], "batb": [[0, 2, 497.02], [1, 1.98, 16.17], [2, 1.97, 38.57]], "batl": NaN}, {"timestamp": 1632578705444, "ltp": 2.02, "tv": 7413.32, "trd": NaN, "batb": [[0, 2, 421.13]], "batl": NaN}, {"timestamp": 1632578707749, "ltp": 2.0, "tv": 7466.02, "trd": [[2, 1915.6]], "batb": [[0, 2, 394.78]], "batl": NaN}, {"timestamp": 1632578714648, "ltp": 2.0, "tv": 7466.02, "trd": NaN, "batb": NaN, "batl": [[0, 2.02, 38.57], [1, 2.04, 371.14], [2, 2.1, 10.62]]}, {"timestamp": 1632578717674, "ltp": 2.0, "tv": 7466.02, "trd": NaN, "batb": NaN, "batl": [[0, 2.04, 371.14], [1, 2.1, 10.62], [2, 2.12, 51.29]]}, {"timestamp": 1632578725168, "ltp": 2.0, "tv": 7543.16, "trd": [[2, 1992.74]], "batb": [[0, 2, 356.21]], "batl": NaN}, {"timestamp": 1632578751427, "ltp": 2.0, "tv": 7543.16, "trd": NaN, "batb": NaN, "batl": [[0, 2.02, 135.42], [1, 2.04, 371.14], [2, 2.1, 10.62]]}, {"timestamp": 1632578758106, "ltp": 2.0, "tv": 7631.03, "trd": [[2, 2080.61]], "batb": [[0, 2, 312.27]], "batl": NaN}, {"timestamp": 1632578762236, "ltp": 2.0, "tv": 7631.03, "trd": NaN, "batb": NaN, "batl": [[0, 2.02, 139.71]]}, {"timestamp": 1632578772649, "ltp": 2.0, "tv": 7631.03, "trd": NaN, "batb": NaN, "batl": [[0, 2.04, 510.85], [1, 2.1, 10.62], [2, 2.12, 51.29]]}, {"timestamp": 1632578773723, "ltp": 2.0, "tv": 7631.24, "trd": [[2, 2080.82]], "batb": [[0, 2, 312.17]], "batl": NaN}, {"timestamp": 1632578776750, "ltp": 2.0, "tv": 7631.24, "trd": NaN, "batb": NaN, "batl": [[0, 2.02, 139.71], [1, 2.04, 371.14], [2, 2.1, 10.62]]}, {"timestamp": 1632578788767, "ltp": 2.0, "tv": 8255.58, "trd": [[2, 2705.16]], "batb": [[0, 1.98, 16.17], [1, 1.97, 38.57], [2, 1.96, 182.8]], "batl": [[0, 2, 8.97], [1, 2.02, 139.71], [2, 2.04, 371.14]]}, {"timestamp": 1632578794670, "ltp": 2.0, "tv": 8270.82, "trd": [[2, 2720.4]], "batb": [[0, 1.97, 56.44], [1, 1.96, 182.8], [2, 1.94, 10.62]], "batl": [[0, 2.02, 139.71], [1, 2.04, 371.14], [2, 2.1, 10.62]]}, {"timestamp": 1632578795073, "ltp": 2.0, "tv": 8270.82, "trd": NaN, "batb": [[0, 1.97, 52.01]], "batl": NaN}, {"timestamp": 1632578800778, "ltp": 2.0, "tv": 8270.82, "trd": NaN, "batb": NaN, "batl": [[0, 2, 139.71]]}, {"timestamp": 1632578802828, "ltp": 2.0, "tv": 8355.93, "trd": [[2, 2805.51]], "batb": NaN, "batl": [[0, 2, 97.15]]}, {"timestamp": 1632578813786, "ltp": 2.0, "tv": 8621.44, "trd": [[2, 3071.02]], "batb": [[0, 2, 90.72], [1, 1.97, 52.01], [2, 1.96, 182.8]], "batl": [[0, 2.04, 371.14], [1, 2.1, 10.62], [2, 2.12, 51.29]]}, {"timestamp": 1632578823020, "ltp": 2.0, "tv": 8641.62, "trd": [[2, 3091.2]], "batb": [[0, 2, 80.63]], "batl": NaN}, {"timestamp": 1632578824935, "ltp": 2.0, "tv": 8645.62, "trd": [[2, 3095.2]], "batb": [[0, 2, 78.63]], "batl": NaN}, {"timestamp": 1632578829808, "ltp": 2.0, "tv": 8645.62, "trd": NaN, "batb": [[0, 2, 548.3]], "batl": NaN}, {"timestamp": 1632578830540, "ltp": 2.0, "tv": 8645.62, "trd": NaN, "batb": NaN, "batl": [[1, 2.1, 13.26]]}, {"timestamp": 1632578832432, "ltp": 2.0, "tv": 9448.48, "trd": [[2, 3898.06]], "batb": [[0, 2, 146.87]], "batl": NaN}, {"timestamp": 1632578834013, "ltp": 2.0, "tv": 9448.48, "trd": NaN, "batb": NaN, "batl": [[0, 2.04, 593.73]]}, {"timestamp": 1632578837814, "ltp": 2.0, "tv": 9448.48, "trd": NaN, "batb": NaN, "batl": [[0, 2.02, 19.7], [1, 2.04, 593.73], [2, 2.1, 13.26]]}, {"timestamp": 1632578840733, "ltp": 2.0, "tv": 9448.48, "trd": NaN, "batb": [[2, 1.95, 211.81]], "batl": NaN}, {"timestamp": 1632578848651, "ltp": 2.02, "tv": 9455.79, "trd": [[2.02, 3526.72]], "batb": NaN, "batl": [[0, 2.02, 12.39]]}, {"timestamp": 1632578849384, "ltp": 2.02, "tv": 9455.79, "trd": NaN, "batb": NaN, "batl": [[1, 2.04, 371.14]]}, {"timestamp": 1632578858465, "ltp": 2.0, "tv": 9477.73, "trd": [[2, 3920]], "batb": [[0, 2, 135.9]], "batl": NaN}, {"timestamp": 1632578872596, "ltp": 2.0, "tv": 9749.53, "trd": [[2, 4191.8]], "batb": [[0, 1.97, 52.01], [1, 1.95, 211.81], [2, 1.94, 10.62]], "batl": [[0, 2, 114.1], [1, 2.02, 12.39], [2, 2.04, 371.14]]}, {"timestamp": 1632578873318, "ltp": 2.0, "tv": 9749.53, "trd": NaN, "batb": [[0, 1.97, 62.92], [1, 1.95, 184.74]], "batl": [[0, 2, 412.4]]}, {"timestamp": 1632578881097, "ltp": 2.0, "tv": 9749.53, "trd": NaN, "batb": NaN, "batl": [[0, 2, 285.6]]}, {"timestamp": 1632578894324, "ltp": 2.0, "tv": 9756.85, "trd": [[2, 4199.12]], "batb": [[0, 1.98, 10.96], [1, 1.97, 49.48], [2, 1.95, 184.74]], "batl": [[0, 2, 278.28]]}, {"timestamp": 1632578895595, "ltp": 2.0, "tv": 9756.85, "trd": NaN, "batb": [[1, 1.97, 38.57]], "batl": NaN}, {"timestamp": 1632578897829, "ltp": 1.97, "tv": 10057.92, "trd": [[1.97, 296.93], [1.98, 124.15]], "batb": [[0, 1.96, 11.99], [1, 1.95, 349.28], [2, 1.94, 10.62]], "batl": NaN}, {"timestamp": 1632578898818, "ltp": 1.97, "tv": 10057.92, "trd": NaN, "batb": NaN, "batl": [[0, 1.97, 4], [1, 2, 278.28], [2, 2.02, 12.39]]}, {"timestamp": 1632578899822, "ltp": 1.97, "tv": 10057.92, "trd": NaN, "batb": [[1, 1.95, 184.74]], "batl": NaN}, {"timestamp": 1632578910633, "ltp": 1.97, "tv": 10057.92, "trd": NaN, "batb": NaN, "batl": [[0, 1.98, 4]]}, {"timestamp": 1632578919948, "ltp": 1.98, "tv": 10060.16, "trd": [[1.98, 126.39]], "batb": NaN, "batl": [[0, 1.98, 1.76]]}, {"timestamp": 1632578925283, "ltp": 1.96, "tv": 10064.16, "trd": [[1.96, 14]], "batb": [[0, 1.96, 9.99]], "batl": NaN}, {"timestamp": 1632578929500, "ltp": 1.96, "tv": 10064.16, "trd": NaN, "batb": [[0, 1.97, 38.57], [1, 1.96, 9.99], [2, 1.95, 184.74]], "batl": NaN}, {"timestamp": 1632578932098, "ltp": 1.97, "tv": 10097.98, "trd": [[1.97, 330.76]], "batb": [[0, 1.97, 21.66]], "batl": NaN}, {"timestamp": 1632578938710, "ltp": 1.96, "tv": 10161.29, "trd": [[1.96, 33.98], [1.97, 374.07]], "batb": [[0, 1.95, 184.74], [1, 1.94, 10.62], [2, 1.93, 2.91]], "batl": [[0, 1.96, 95.15], [1, 1.98, 1.76], [2, 2, 278.28]]}, {"timestamp": 1632578939600, "ltp": 1.96, "tv": 10239.75, "trd": [[1.96, 112.44]], "batb": [[2, 1.93, 20.63]], "batl": [[0, 1.96, 55.92]]}, {"timestamp": 1632578958725, "ltp": 1.96, "tv": 10239.75, "trd": NaN, "batb": NaN, "batl": [[0, 1.98, 1.76], [1, 2, 278.28], [2, 2.02, 12.39]]}, {"timestamp": 1632578960125, "ltp": 1.95, "tv": 10467.74, "trd": [[1.95, 227.99]], "batb": [[0, 1.95, 70.75]], "batl": NaN}, {"timestamp": 1632578961655, "ltp": 1.95, "tv": 10467.74, "trd": NaN, "batb": [[0, 1.94, 3206.42], [1, 1.93, 20.63], [2, 1.91, 28.26]], "batl": NaN}, {"timestamp": 1632578962620, "ltp": 1.95, "tv": 10467.74, "trd": NaN, "batb": [[2, 1.9, 33.57]], "batl": NaN}, {"timestamp": 1632578963794, "ltp": 1.95, "tv": 10467.74, "trd": NaN, "batb": [[0, 1.94, 3195.8]], "batl": NaN}, {"timestamp": 1632578964550, "ltp": 1.95, "tv": 10467.74, "trd": NaN, "batb": [[0, 1.94, 2517.78]], "batl": NaN}, {"timestamp": 1632578971449, "ltp": 1.95, "tv": 10467.74, "trd": NaN, "batb": [[0, 1.94, 2517.62]], "batl": NaN}, {"timestamp": 1632578979668, "ltp": 1.94, "tv": 10579.58, "trd": [[1.94, 111.84]], "batb": [[0, 1.94, 2461.7]], "batl": NaN}, {"timestamp": 1632578983773, "ltp": 1.94, "tv": 10579.58, "trd": NaN, "batb": [[0, 1.95, 5.31], [1, 1.94, 2461.7], [2, 1.93, 20.63]], "batl": NaN}, {"timestamp": 1632578994162, "ltp": 1.94, "tv": 10579.58, "trd": NaN, "batb": [[0, 1.95, 12.71], [1, 1.94, 130.35], [2, 1.93, 2.91]], "batl": NaN}, {"timestamp": 1632579001601, "ltp": 2.0, "tv": 10592.99, "trd": [[1.98, 128.15], [2, 4210.77]], "batb": NaN, "batl": [[0, 2, 266.63], [1, 2.02, 12.39], [2, 2.04, 371.14]]}, {"timestamp": 1632579030643, "ltp": 1.96, "tv": 10593.29, "trd": [[1.96, 112.74]], "batb": NaN, "batl": NaN}, {"timestamp": 1632579045973, "ltp": 1.96, "tv": 10593.29, "trd": NaN, "batb": NaN, "batl": [[0, 2, 406.63]]}, {"timestamp": 1632579048668, "ltp": 1.95, "tv": 10620.62, "trd": [[1.95, 253.41], [1.96, 114.67]], "batb": [[0, 1.94, 130.35], [1, 1.93, 2.91], [2, 1.9, 33.57]], "batl": [[0, 1.95, 7.08], [1, 2, 406.63], [2, 2.02, 12.39]]}, {"timestamp": 1632579049331, "ltp": 1.95, "tv": 10634.78, "trd": [[1.95, 267.56]], "batb": [[0, 1.95, 15.12], [1, 1.94, 3055.66], [2, 1.93, 2.91]], "batl": [[0, 2, 406.63], [1, 2.02, 12.39], [2, 2.04, 371.14]]}, {"timestamp": 1632579064342, "ltp": 1.95, "tv": 10634.78, "trd": NaN, "batb": [[1, 1.94, 130.35]], "batl": NaN}, {"timestamp": 1632579085726, "ltp": 2.0, "tv": 10639.78, "trd": [[2, 4215.77]], "batb": NaN, "batl": [[0, 2, 401.63]]}, {"timestamp": 1632579095666, "ltp": 1.95, "tv": 10683.02, "trd": [[1.95, 310.8]], "batb": [[0, 1.94, 3014.7], [1, 1.93, 2.91], [2, 1.9, 33.57]], "batl": [[0, 1.95, 14.95], [1, 2, 401.63], [2, 2.02, 12.39]]}, {"timestamp": 1632579096383, "ltp": 1.95, "tv": 10701.64, "trd": [[1.95, 329.42]], "batb": [[2, 1.91, 24.01]], "batl": [[0, 1.95, 5.64]]}, {"timestamp": 1632579109494, "ltp": 1.95, "tv": 10701.64, "trd": NaN, "batb": [[0, 1.94, 3014.96]], "batl": NaN}, {"timestamp": 1632579121626, "ltp": 1.95, "tv": 10706.16, "trd": [[1.95, 333.94]], "batb": NaN, "batl": [[0, 1.95, 1.12]]}, {"timestamp": 1632579131236, "ltp": 1.95, "tv": 10706.16, "trd": NaN, "batb": [[0, 1.94, 3014.7]], "batl": NaN}, {"timestamp": 1632579156734, "ltp": 2.0, "tv": 11108.91, "trd": [[1.95, 335.06], [2, 4617.4]], "batb": NaN, "batl": [[0, 2.02, 12.39], [1, 2.04, 371.14], [2, 2.1, 13.26]]}, {"timestamp": 1632579157361, "ltp": 2.0, "tv": 11120.43, "trd": [[2, 4628.92]], "batb": NaN, "batl": [[0, 2.02, 25.8]]}, {"timestamp": 1632579158070, "ltp": 2.0, "tv": 11120.43, "trd": NaN, "batb": [[0, 1.95, 22.07], [1, 1.94, 3042.05], [2, 1.93, 2.91]], "batl": [[0, 2.02, 12.39]]}, {"timestamp": 1632579163046, "ltp": 1.95, "tv": 11121.72, "trd": [[1.95, 336.34]], "batb": [[0, 1.95, 20.79]], "batl": NaN}, {"timestamp": 1632579164057, "ltp": 1.95, "tv": 11121.72, "trd": NaN, "batb": [[1, 1.94, 3014.7]], "batl": NaN}, {"timestamp": 1632579173173, "ltp": 1.94, "tv": 11241.72, "trd": [[1.94, 190.26], [1.95, 377.91]], "batb": [[0, 1.94, 2975.48], [1, 1.93, 2.91], [2, 1.92, 27.95]], "batl": NaN}, {"timestamp": 1632579174685, "ltp": 1.94, "tv": 11241.72, "trd": NaN, "batb": [[0, 1.94, 3072.12], [2, 1.91, 28.26]], "batl": NaN}, {"timestamp": 1632579175686, "ltp": 1.94, "tv": 11241.72, "trd": NaN, "batb": [[2, 1.92, 20.01]], "batl": [[0, 2.02, 24.79]]}, {"timestamp": 1632579188815, "ltp": 1.94, "tv": 11241.72, "trd": NaN, "batb": [[0, 1.97, 20.07], [1, 1.94, 187.77], [2, 1.93, 2.91]], "batl": NaN}, {"timestamp": 1632579189523, "ltp": 1.94, "tv": 11241.72, "trd": NaN, "batb": NaN, "batl": [[0, 2.02, 12.39]]}, {"timestamp": 1632579203115, "ltp": 1.94, "tv": 11241.72, "trd": NaN, "batb": [[2, 1.93, 30.56]], "batl": NaN}, {"timestamp": 1632579224952, "ltp": 1.94, "tv": 11241.72, "trd": NaN, "batb": [[1, 1.94, 187.53]], "batl": NaN}, {"timestamp": 1632579226144, "ltp": 1.94, "tv": 11241.72, "trd": NaN, "batb": [[2, 1.93, 2.91]], "batl": NaN}, {"timestamp": 1632579237267, "ltp": 1.94, "tv": 11241.72, "trd": NaN, "batb": [[0, 1.97, 18.1]], "batl": NaN}, {"timestamp": 1632579246586, "ltp": 1.94, "tv": 11241.72, "trd": NaN, "batb": [[2, 1.93, 799.34]], "batl": NaN}, {"timestamp": 1632579292630, "ltp": 1.94, "tv": 11241.72, "trd": NaN, "batb": NaN, "batl": [[1, 2.04, 374.29]]}, {"timestamp": 1632579306201, "ltp": 1.94, "tv": 11241.72, "trd": NaN, "batb": [[2, 1.93, 826.99]], "batl": NaN}, {"timestamp": 1632579312660, "ltp": 1.97, "tv": 11285.38, "trd": [[1.97, 417.74]], "batb": [[0, 1.94, 3236.82], [1, 1.93, 826.99], [2, 1.92, 27.95]], "batl": [[0, 1.97, 80.75], [1, 2.02, 12.39], [2, 2.04, 374.29]]}, {"timestamp": 1632579313138, "ltp": 1.97, "tv": 11285.38, "trd": NaN, "batb": [[1, 1.93, 799.34], [2, 1.9, 5]], "batl": NaN}, {"timestamp": 1632579314785, "ltp": 1.97, "tv": 11285.38, "trd": NaN, "batb": [[0, 1.95, 183.98], [1, 1.94, 3236.82], [2, 1.93, 799.34]], "batl": NaN}, {"timestamp": 1632579315347, "ltp": 2.0, "tv": 11446.88, "trd": [[1.97, 579.23], [2, 4628.93]], "batb": [[1, 1.94, 187.53]], "batl": [[0, 2.02, 12.39], [1, 2.04, 374.29], [2, 2.1, 13.26]]}, {"timestamp": 1632579325575, "ltp": 2.0, "tv": 11446.88, "trd": NaN, "batb": [[0, 1.96, 181.7], [1, 1.95, 183.98], [2, 1.94, 187.53]], "batl": NaN}, {"timestamp": 1632579327263, "ltp": 2.0, "tv": 11446.88, "trd": NaN, "batb": NaN, "batl": [[1, 2.04, 1374.29]]}, {"timestamp": 1632579330491, "ltp": 2.0, "tv": 11446.88, "trd": NaN, "batb": NaN, "batl": [[0, 2.02, 69.58]]}, {"timestamp": 1632579333202, "ltp": 2.0, "tv": 11446.88, "trd": NaN, "batb": NaN, "batl": [[0, 2.02, 12.39]]}, {"timestamp": 1632579339279, "ltp": 1.96, "tv": 11536.4, "trd": [[1.96, 204.19]], "batb": [[0, 1.96, 136.94]], "batl": NaN}, {"timestamp": 1632579340199, "ltp": 1.96, "tv": 11536.4, "trd": NaN, "batb": [[1, 1.93, 799.34], [2, 1.92, 27.95]], "batl": NaN}, {"timestamp": 1632579353123, "ltp": 1.96, "tv": 11536.4, "trd": NaN, "batb": NaN, "batl": [[0, 1.98, 20], [1, 2.02, 12.39], [2, 2.04, 1374.29]]}, {"timestamp": 1632579354197, "ltp": 1.96, "tv": 11536.4, "trd": NaN, "batb": [[2, 1.9, 33.57]], "batl": NaN}, {"timestamp": 1632579369157, "ltp": 1.96, "tv": 11537.93, "trd": [[1.96, 205.72]], "batb": [[0, 1.96, 136.18]], "batl": NaN}, {"timestamp": 1632579370125, "ltp": 2.0, "tv": 11577.93, "trd": [[1.98, 168.14], [2, 4628.94]], "batb": NaN, "batl": [[0, 2.02, 12.39], [1, 2.04, 1374.29], [2, 2.1, 13.26]]}, {"timestamp": 1632579371227, "ltp": 2.0, "tv": 11577.93, "trd": NaN, "batb": NaN, "batl": [[0, 2, 70.45], [1, 2.02, 12.39], [2, 2.04, 1374.29]]}, {"timestamp": 1632579372245, "ltp": 2.0, "tv": 11577.93, "trd": NaN, "batb": [[2, 1.91, 28.26]], "batl": NaN}, {"timestamp": 1632579400805, "ltp": 1.96, "tv": 11854.29, "trd": [[1.96, 482.07]], "batb": [[0, 1.93, 939.74], [1, 1.91, 28.26], [2, 1.9, 33.57]], "batl": [[0, 1.96, 137.02], [1, 2, 70.45], [2, 2.02, 12.39]]}, {"timestamp": 1632579401786, "ltp": 1.96, "tv": 11854.29, "trd": NaN, "batb": [[0, 1.95, 183.56], [1, 1.93, 939.74], [2, 1.9, 5]], "batl": NaN}, {"timestamp": 1632579408140, "ltp": 1.96, "tv": 11854.29, "trd": NaN, "batb": [[1, 1.93, 799.34]], "batl": NaN}, {"timestamp": 1632579417234, "ltp": 1.95, "tv": 11857.7, "trd": [[1.95, 381.33]], "batb": [[0, 1.95, 180.15]], "batl": NaN}, {"timestamp": 1632579418700, "ltp": 1.95, "tv": 11857.7, "trd": NaN, "batb": NaN, "batl": [[2, 2.04, 1374.29]]}, {"timestamp": 1632579421827, "ltp": 2.0, "tv": 12065.18, "trd": [[1.96, 619.09], [2, 4699.39]], "batb": NaN, "batl": [[0, 2.04, 1573.86], [1, 2.1, 13.26], [2, 2.12, 51.29]]}, {"timestamp": 1632579422531, "ltp": 2.0, "tv": 12065.18, "trd": NaN, "batb": [[0, 1.95, 207.21]], "batl": NaN}, {"timestamp": 1632579424536, "ltp": 2.0, "tv": 12065.18, "trd": NaN, "batb": NaN, "batl": [[0, 2.04, 1383.64]]}, {"timestamp": 1632579428452, "ltp": 2.0, "tv": 12065.18, "trd": NaN, "batb": [[0, 1.96, 182.12], [1, 1.95, 207.21], [2, 1.93, 799.34]], "batl": NaN}, {"timestamp": 1632579429361, "ltp": 1.96, "tv": 12200.49, "trd": [[1.96, 718.29], [2, 4735.5]], "batb": [[0, 1.96, 132.52], [1, 1.95, 180.15], [2, 1.94, 27.35]], "batl": NaN}, {"timestamp": 1632579430367, "ltp": 1.96, "tv": 12200.49, "trd": NaN, "batb": [[2, 1.93, 799.34]], "batl": NaN}, {"timestamp": 1632579433799, "ltp": 1.96, "tv": 12200.49, "trd": NaN, "batb": [[0, 1.96, 205.65]], "batl": [[0, 2.04, 1184.07]]}, {"timestamp": 1632579434421, "ltp": 1.96, "tv": 12200.49, "trd": NaN, "batb": [[0, 1.96, 132.52]], "batl": [[0, 2.04, 1337.6]]}, {"timestamp": 1632579438813, "ltp": 1.96, "tv": 12200.49, "trd": NaN, "batb": [[1, 1.93, 799.34], [2, 1.92, 27.95]], "batl": NaN}, {"timestamp": 1632579445896, "ltp": 1.96, "tv": 12251.22, "trd": [[1.96, 769.03]], "batb": [[0, 1.96, 107.16]], "batl": NaN}, {"timestamp": 1632579449798, "ltp": 1.96, "tv": 12251.22, "trd": NaN, "batb": NaN, "batl": [[0, 2.04, 1184.07]]}, {"timestamp": 1632579457049, "ltp": 1.96, "tv": 12251.22, "trd": NaN, "batb": [[0, 1.96, 189.28]], "batl": NaN}, {"timestamp": 1632579458442, "ltp": 1.96, "tv": 12254.59, "trd": [[1.96, 772.39]], "batb": [[0, 1.96, 187.59]], "batl": NaN}, {"timestamp": 1632579459470, "ltp": 1.96, "tv": 12337.33, "trd": [[1.96, 855.13]], "batb": [[0, 1.96, 183.32]], "batl": NaN}, {"timestamp": 1632579463763, "ltp": 2.0, "tv": 12339.09, "trd": [[2, 4737.26]], "batb": NaN, "batl": NaN}, {"timestamp": 1632579464754, "ltp": 2.0, "tv": 12344.09, "trd": [[2, 4742.26]], "batb": NaN, "batl": NaN}, {"timestamp": 1632579465394, "ltp": 2.0, "tv": 12344.09, "trd": NaN, "batb": [[0, 2, 7.51], [1, 1.96, 183.32], [2, 1.93, 799.34]], "batl": NaN}, {"timestamp": 1632579466383, "ltp": 2.0, "tv": 12344.09, "trd": NaN, "batb": [[2, 1.95, 27.07]], "batl": NaN}, {"timestamp": 1632579469684, "ltp": 2.0, "tv": 12344.09, "trd": NaN, "batb": [[1, 1.96, 181.11], [2, 1.93, 826.99]], "batl": NaN}, {"timestamp": 1632579470193, "ltp": 2.0, "tv": 12344.09, "trd": NaN, "batb": [[0, 2, 8.21]], "batl": NaN}, {"timestamp": 1632579474698, "ltp": 1.99, "tv": 12365.11, "trd": [[1.99, 268.65], [2, 4759.29]], "batb": [[0, 1.96, 181.11], [1, 1.93, 826.99], [2, 1.92, 27.95]], "batl": [[0, 1.99, 28.77], [1, 2.04, 1184.07], [2, 2.1, 13.26]]}, {"timestamp": 1632579475302, "ltp": 1.99, "tv": 12365.11, "trd": NaN, "batb": [[1, 1.93, 799.34]], "batl": NaN}, {"timestamp": 1632579476501, "ltp": 1.99, "tv": 12365.11, "trd": NaN, "batb": NaN, "batl": [[1, 2, 433.37], [2, 2.04, 1184.07]]}, {"timestamp": 1632579478472, "ltp": 1.99, "tv": 12365.11, "trd": NaN, "batb": NaN, "batl": [[1, 2, 447.01]]}, {"timestamp": 1632579480591, "ltp": 1.99, "tv": 12368.41, "trd": [[1.99, 271.95]], "batb": NaN, "batl": [[0, 1.99, 25.47]]}, {"timestamp": 1632579481330, "ltp": 1.99, "tv": 12369.25, "trd": [[1.99, 272.79]], "batb": NaN, "batl": [[0, 1.99, 25.05]]}, {"timestamp": 1632579482116, "ltp": 1.96, "tv": 12376.27, "trd": [[1.96, 862.15]], "batb": [[0, 1.96, 177.6]], "batl": NaN}, {"timestamp": 1632579483396, "ltp": 1.99, "tv": 12389.07, "trd": [[1.99, 285.6]], "batb": NaN, "batl": [[0, 1.99, 18.65]]}, {"timestamp": 1632579484686, "ltp": 1.99, "tv": 12389.43, "trd": [[1.99, 285.95]], "batb": [[0, 1.93, 799.34], [1, 1.92, 27.95], [2, 1.9, 5]], "batl": [[0, 1.99, 18.3], [1, 2, 553.2]]}, {"timestamp": 1632579485640, "ltp": 1.99, "tv": 12389.43, "trd": NaN, "batb": [[0, 1.93, 796.43], [1, 1.88, 16.91], [2, 1.7, 21.93]], "batl": [[0, 2.04, 3.15], [1, 2.1, 13.26], [2, 2.32, 9.2]]}, {"timestamp": 1632579490211, "ltp": 2.0, "tv": 12393.04, "trd": [[2, 4762.91]], "batb": NaN, "batl": [[0, 1.96, 165.47], [1, 2.04, 3.15], [2, 2.1, 13.26]]}, {"timestamp": 1632579491676, "ltp": 1.93, "tv": 13287.06, "trd": [[1.93, 894.02]], "batb": [[0, 1.93, 349.42]], "batl": NaN}, {"timestamp": 1632579492321, "ltp": 1.93, "tv": 13985.9, "trd": [[1.93, 1592.86]], "batb": [[0, 1.88, 16.91], [1, 1.7, 21.93], [2, 1.65, 110]], "batl": [[0, 1.93, 169.14], [1, 1.96, 165.47], [2, 2.04, 3.15]]}, {"timestamp": 1632579493810, "ltp": 1.93, "tv": 13985.9, "trd": NaN, "batb": NaN, "batl": [[0, 1.91, 6327.42], [1, 1.93, 169.14], [2, 1.96, 165.47]]}, {"timestamp": 1632579494814, "ltp": 1.93, "tv": 13985.9, "trd": NaN, "batb": NaN, "batl": [[0, 1.96, 165.47], [1, 2.04, 3.15], [2, 2.1, 13.26]]}, {"timestamp": 1632579495527, "ltp": 1.93, "tv": 13985.9, "trd": NaN, "batb": [[1, 1.85, 217.38], [2, 1.72, 274.55]], "batl": NaN}, {"timestamp": 1632579497715, "ltp": 1.88, "tv": 14019.54, "trd": [[1.88, 33.64]], "batb": [[0, 1.85, 217.47], [1, 1.72, 274.55], [2, 1.7, 21.24]], "batl": NaN}, {"timestamp": 1632579498721, "ltp": 1.88, "tv": 14053.84, "trd": [[1.88, 67.93]], "batb": [[0, 1.89, 146.87], [1, 1.85, 217.38], [2, 1.72, 274.55]], "batl": [[0, 1.95, 158.88], [1, 1.96, 165.47], [2, 2.04, 3.15]]}, {"timestamp": 1632579499534, "ltp": 1.89, "tv": 14141.92, "trd": [[1.89, 88.08]], "batb": [[0, 1.89, 102.83]], "batl": [[1, 1.96, 200.47]]}, {"timestamp": 1632579501710, "ltp": 1.89, "tv": 14141.92, "trd": NaN, "batb": [[0, 1.86, 157.93]], "batl": NaN}, {"timestamp": 1632579502781, "ltp": 1.9, "tv": 14169.2, "trd": [[1.9, 27.28]], "batb": [[0, 1.9, 137.24], [1, 1.86, 157.93], [2, 1.85, 217.38]], "batl": NaN}, {"timestamp": 1632579503740, "ltp": 1.9, "tv": 14169.2, "trd": NaN, "batb": [[0, 1.9, 342.85]], "batl": NaN}, {"timestamp": 1632579507554, "ltp": 1.9, "tv": 14169.2, "trd": NaN, "batb": [[0, 1.9, 463.52]], "batl": NaN}, {"timestamp": 1632579508717, "ltp": 1.9, "tv": 14239.94, "trd": [[1.9, 98.03]], "batb": [[0, 1.9, 307.47], [1, 1.72, 274.55], [2, 1.7, 21.24]], "batl": [[0, 1.96, 200.47], [1, 2.04, 3.15], [2, 2.1, 13.26]]}, {"timestamp": 1632579509640, "ltp": 1.9, "tv": 14239.94, "trd": NaN, "batb": [[0, 1.93, 5.26], [1, 1.9, 307.47], [2, 1.72, 274.55]], "batl": NaN}, {"timestamp": 1632579510727, "ltp": 1.9, "tv": 14865.4, "trd": [[1.9, 712.97], [1.93, 1603.38]], "batb": [[0, 1.72, 274.55], [1, 1.7, 21.24], [2, 1.65, 110]], "batl": [[0, 1.87, 146.91], [1, 1.96, 200.47], [2, 2.04, 3.15]]}, {"timestamp": 1632579511608, "ltp": 1.9, "tv": 14865.4, "trd": NaN, "batb": [[0, 1.73, 271.17], [1, 1.72, 273.86], [2, 1.7, 21.24]], "batl": NaN}, {"timestamp": 1632579512647, "ltp": 1.9, "tv": 14865.4, "trd": NaN, "batb": [[1, 1.7, 21.24], [2, 1.65, 110]], "batl": [[1, 1.9, 46.48], [2, 1.96, 200.47]]}, {"timestamp": 1632579513532, "ltp": 1.9, "tv": 14865.4, "trd": NaN, "batb": NaN, "batl": [[1, 1.9, 593.66]]}, {"timestamp": 1632579514783, "ltp": 1.9, "tv": 14865.4, "trd": NaN, "batb": [[0, 1.78, 5.69], [1, 1.77, 4], [2, 1.76, 5]], "batl": NaN}, {"timestamp": 1632579515447, "ltp": 1.87, "tv": 14867.16, "trd": [[1.87, 1.76]], "batb": NaN, "batl": [[0, 1.87, 146.03]]}, {"timestamp": 1632579517246, "ltp": 1.87, "tv": 14867.16, "trd": NaN, "batb": [[0, 1.83, 570.19], [1, 1.81, 569.8], [2, 1.78, 5]], "batl": [[1, 1.9, 1017.34], [2, 1.92, 480.34]]}, {"timestamp": 1632579518350, "ltp": 1.87, "tv": 14867.16, "trd": NaN, "batb": NaN, "batl": [[1, 1.9, 1017.69]]}, {"timestamp": 1632579519496, "ltp": 1.87, "tv": 14867.16, "trd": NaN, "batb": [[0, 1.78, 5.69], [1, 1.77, 4], [2, 1.76, 5]], "batl": [[1, 1.9, 525.48], [2, 1.96, 200.47]]}, {"timestamp": 1632579520869, "ltp": 1.87, "tv": 14898.06, "trd": [[1.87, 32.66]], "batb": NaN, "batl": [[0, 1.87, 115.13]]}, {"timestamp": 1632579522488, "ltp": 1.87, "tv": 14898.7, "trd": [[1.87, 33.3]], "batb": NaN, "batl": [[0, 1.87, 114.49]]}, {"timestamp": 1632579523777, "ltp": 1.87, "tv": 14898.7, "trd": NaN, "batb": NaN, "batl": [[1, 1.9, 525.13]]}, {"timestamp": 1632579524077, "ltp": 1.87, "tv": 14962.53, "trd": [[1.87, 97.13]], "batb": NaN, "batl": [[0, 1.87, 50.66]]}, {"timestamp": 1632579526578, "ltp": 1.83, "tv": 14967.67, "trd": [[1.83, 3.76], [1.84, 1.38]], "batb": [[0, 1.78, 5]], "batl": [[0, 1.83, 475.96], [1, 1.87, 50.66], [2, 1.9, 525.13]]}, {"timestamp": 1632579527260, "ltp": 1.83, "tv": 14967.67, "trd": NaN, "batb": [[1, 1.74, 450.99], [2, 1.73, 270.48]], "batl": NaN}, {"timestamp": 1632579528570, "ltp": 1.78, "tv": 14972.79, "trd": [[1.78, 5.13]], "batb": [[0, 1.74, 450.99], [1, 1.73, 270.48], [2, 1.72, 675.22]], "batl": [[0, 1.78, 513.43], [1, 1.8, 2222], [2, 1.83, 475.96]]}, {"timestamp": 1632579529763, "ltp": 1.78, "tv": 14972.79, "trd": NaN, "batb": NaN, "batl": [[2, 1.81, 6694.26]]}, {"timestamp": 1632579530777, "ltp": 1.78, "tv": 14973.49, "trd": [[1.78, 5.83]], "batb": NaN, "batl": [[0, 1.78, 513.08], [1, 1.8, 2813.26], [2, 1.82, 567.34]]}, {"timestamp": 1632579531770, "ltp": 1.78, "tv": 15007.56, "trd": [[1.78, 39.89]], "batb": NaN, "batl": [[0, 1.78, 496.05]]}, {"timestamp": 1632579533684, "ltp": 1.78, "tv": 15007.56, "trd": NaN, "batb": NaN, "batl": [[0, 1.78, 496.4], [1, 1.8, 591.26]]}, {"timestamp": 1632579534599, "ltp": 1.78, "tv": 15207.56, "trd": [[1.78, 239.89]], "batb": [[0, 1.76, 4], [1, 1.75, 5], [2, 1.74, 450.99]], "batl": [[0, 1.78, 401.4]]}, {"timestamp": 1632579535790, "ltp": 1.75, "tv": 15311.74, "trd": [[1.75, 48.26], [1.76, 20.87], [1.78, 274.95]], "batb": [[0, 1.75, 109.68], [1, 1.74, 450.99], [2, 1.73, 270.48]], "batl": [[0, 1.78, 532.18]]}, {"timestamp": 1632579535915, "ltp": 1.75, "tv": 15311.74, "trd": NaN, "batb": NaN, "batl": [[0, 1.78, 153.66]]}, {"timestamp": 1632579537825, "ltp": 1.75, "tv": 15311.74, "trd": NaN, "batb": NaN, "batl": [[0, 1.78, 153.31]]}, {"timestamp": 1632579538681, "ltp": 1.75, "tv": 15311.74, "trd": NaN, "batb": NaN, "batl": [[0, 1.76, 2.35], [1, 1.78, 362.31], [2, 1.8, 591.26]]}, {"timestamp": 1632579539118, "ltp": 1.75, "tv": 15311.74, "trd": NaN, "batb": [[1, 1.74, 455.99]], "batl": NaN}, {"timestamp": 1632579541596, "ltp": 1.76, "tv": 15463.26, "trd": [[1.75, 185.32], [1.76, 30.21], [1.78, 280.07]], "batb": [[0, 1.75, 41.15], [1, 1.74, 566.11]], "batl": [[0, 1.77, 149.01], [1, 1.78, 359.75]]}, {"timestamp": 1632579542093, "ltp": 1.74, "tv": 15596.35, "trd": [[1.74, 46.8], [1.75, 271.6]], "batb": [[0, 1.74, 542.71], [1, 1.73, 270.48], [2, 1.72, 675.22]], "batl": NaN}, {"timestamp": 1632579543700, "ltp": 1.74, "tv": 15596.35, "trd": NaN, "batb": [[0, 1.76, 151.71], [1, 1.74, 542.71], [2, 1.73, 270.48]], "batl": NaN}, {"timestamp": 1632579544520, "ltp": 1.77, "tv": 15598.62, "trd": [[1.77, 2.27]], "batb": NaN, "batl": [[0, 1.77, 151.74]]}, {"timestamp": 1632579545589, "ltp": 1.77, "tv": 15616.58, "trd": [[1.77, 20.23]], "batb": [[2, 1.73, 275.48]], "batl": [[0, 1.77, 142.76]]}, {"timestamp": 1632579547808, "ltp": 1.77, "tv": 15616.58, "trd": NaN, "batb": [[1, 1.7, 21.24], [2, 1.65, 125]], "batl": [[0, 1.87, 50.66], [1, 1.9, 46.48], [2, 1.96, 200.47]]}, {"timestamp": 1632579548783, "ltp": 1.76, "tv": 15617.28, "trd": [[1.76, 30.91]], "batb": [[0, 1.76, 156.36], [1, 1.75, 5], [2, 1.7, 21.24]], "batl": NaN}, {"timestamp": 1632579549213, "ltp": 1.76, "tv": 15617.28, "trd": NaN, "batb": [[0, 1.76, 151.36], [1, 1.7, 21.24], [2, 1.65, 125]], "batl": NaN}, {"timestamp": 1632579550782, "ltp": 1.78, "tv": 15619.63, "trd": [[1.78, 282.41]], "batb": NaN, "batl": [[1, 1.89, 545.05], [2, 1.9, 46.48]]}, {"timestamp": 1632579552809, "ltp": 1.76, "tv": 15799.8, "trd": [[1.76, 190.19], [1.78, 303.3]], "batb": [[0, 1.76, 71.72]], "batl": NaN}, {"timestamp": 1632579556626, "ltp": 1.76, "tv": 15819.5, "trd": [[1.76, 209.89]], "batb": [[0, 1.76, 61.87]], "batl": NaN}, {"timestamp": 1632579558817, "ltp": 1.76, "tv": 15819.5, "trd": NaN, "batb": NaN, "batl": [[1, 1.9, 46.48], [2, 1.96, 200.47]]}, {"timestamp": 1632579559002, "ltp": 1.76, "tv": 15819.5, "trd": NaN, "batb": [[0, 1.7, 21.24], [1, 1.65, 125], [2, 1.64, 15]], "batl": NaN}, {"timestamp": 1632579560633, "ltp": 1.7, "tv": 15861.98, "trd": [[1.7, 42.48]], "batb": [[0, 1.65, 125], [1, 1.64, 15], [2, 1.63, 697.43]], "batl": [[0, 1.68, 2200.76], [1, 1.69, 518.56], [2, 1.87, 50.66]]}, {"timestamp": 1632579561719, "ltp": 1.7, "tv": 15861.98, "trd": NaN, "batb": NaN, "batl": [[0, 1.68, 2588.12], [1, 1.69, 1537.05], [2, 1.7, 1699.71]]}, {"timestamp": 1632579562809, "ltp": 1.7, "tv": 15861.98, "trd": NaN, "batb": [[0, 1.65, 115]], "batl": NaN}, {"timestamp": 1632579563727, "ltp": 1.7, "tv": 15861.98, "trd": NaN, "batb": [[0, 1.65, 119], [1, 1.64, 20]], "batl": [[0, 1.68, 387.36]]}, {"timestamp": 1632579564539, "ltp": 1.7, "tv": 15861.98, "trd": NaN, "batb": NaN, "batl": [[1, 1.69, 1367.3], [2, 1.7, 1534.95]]}, {"timestamp": 1632579566709, "ltp": 1.7, "tv": 15861.98, "trd": NaN, "batb": NaN, "batl": [[0, 1.68, 533.15]]}, {"timestamp": 1632579567666, "ltp": 1.7, "tv": 15861.98, "trd": NaN, "batb": [[2, 1.63, 1050.16]], "batl": [[0, 1.66, 1904.52], [1, 1.68, 533.15], [2, 1.69, 1367.3]]}, {"timestamp": 1632579568792, "ltp": 1.7, "tv": 15861.98, "trd": NaN, "batb": NaN, "batl": [[1, 1.67, 247], [2, 1.68, 533.15]]}, {"timestamp": 1632579569419, "ltp": 1.66, "tv": 15947.01, "trd": [[1.66, 85.03]], "batb": NaN, "batl": [[0, 1.66, 1862], [1, 1.67, 605.28]]}, {"timestamp": 1632579570821, "ltp": 1.65, "tv": 16052.99, "trd": [[1.65, 105.98]], "batb": [[0, 1.65, 66.01]], "batl": [[0, 1.66, 2020.32]]}, {"timestamp": 1632579571370, "ltp": 1.66, "tv": 16252.99, "trd": [[1.66, 285.03]], "batb": NaN, "batl": [[0, 1.66, 1920.32]]}, {"timestamp": 1632579572753, "ltp": 1.66, "tv": 16935.53, "trd": [[1.66, 967.58]], "batb": [[0, 1.65, 108.78]], "batl": [[0, 1.66, 1579.05]]}, {"timestamp": 1632579573487, "ltp": 1.66, "tv": 17354.63, "trd": [[1.65, 125.08], [1.66, 1367.58]], "batb": [[0, 1.65, 99.23]], "batl": [[0, 1.66, 1379.05]]}, {"timestamp": 1632579574819, "ltp": 1.66, "tv": 17764.24, "trd": [[1.65, 334.06], [1.66, 1568.2]], "batb": [[0, 1.64, 62.82], [1, 1.63, 1050.16], [2, 1.62, 425.42]], "batl": [[0, 1.66, 158.01], [1, 1.67, 908.09]]}, {"timestamp": 1632579575612, "ltp": 1.66, "tv": 17764.24, "trd": NaN, "batb": [[0, 1.65, 442.68], [1, 1.64, 62.82], [2, 1.63, 1050.16]], "batl": NaN}, {"timestamp": 1632579576693, "ltp": 1.63, "tv": 21554.37, "trd": [[1.63, 2654.27], [1.64, 156.22], [1.65, 1219.43], [1.66, 1662.48]], "batb": [[0, 1.62, 425.42], [1, 1.61, 344.71], [2, 1.6, 34.28]], "batl": [[0, 1.63, 1269.8], [1, 1.66, 110.87], [2, 1.67, 908.09]]}, {"timestamp": 1632579577413, "ltp": 1.63, "tv": 21763.59, "trd": [[1.63, 2863.49]], "batb": NaN, "batl": [[0, 1.63, 1165.18], [2, 1.67, 1102.17]]}, {"timestamp": 1632579578591, "ltp": 1.63, "tv": 22111.03, "trd": [[1.63, 3210.93]], "batb": NaN, "batl": [[0, 1.63, 991.46], [1, 1.65, 5.21], [2, 1.66, 110.87]]}, {"timestamp": 1632579579797, "ltp": 1.63, "tv": 22390.36, "trd": [[1.63, 3490.26]], "batb": [[0, 1.62, 618.46], [1, 1.61, 350.71], [2, 1.6, 349.2]], "batl": [[0, 1.63, 848.63]]}, {"timestamp": 1632579580751, "ltp": 1.63, "tv": 23199.58, "trd": [[1.63, 4299.48]], "batb": [[0, 1.62, 430.42]], "batl": [[0, 1.63, 444.02], [1, 1.66, 110.87], [2, 1.67, 1102.17]]}, {"timestamp": 1632579581541, "ltp": 1.63, "tv": 23202.74, "trd": [[1.63, 4302.63]], "batb": NaN, "batl": [[0, 1.63, 442.44]]}, {"timestamp": 1632579582636, "ltp": 1.63, "tv": 23422.47, "trd": [[1.63, 4522.36]], "batb": NaN, "batl": [[0, 1.63, 589.71], [1, 1.64, 215.3], [2, 1.66, 110.87]]}, {"timestamp": 1632579583831, "ltp": 1.63, "tv": 23511.3, "trd": [[1.63, 4611.2]], "batb": [[0, 1.62, 666.31], [1, 1.61, 437.54], [2, 1.6, 34.28]], "batl": [[0, 1.63, 545.3], [1, 1.65, 100], [2, 1.67, 717.29]]}, {"timestamp": 1632579584822, "ltp": 1.63, "tv": 23566.36, "trd": [[1.63, 4666.26]], "batb": [[0, 1.62, 5], [1, 1.6, 34.28], [2, 1.57, 180.88]], "batl": [[0, 1.63, 517.77], [1, 1.65, 102.36], [2, 1.69, 19.5]]}, {"timestamp": 1632579585824, "ltp": 1.62, "tv": 23576.36, "trd": [[1.62, 10]], "batb": [[0, 1.6, 34.28], [1, 1.57, 180.88], [2, 1.56, 204.38]], "batl": [[0, 1.62, 3584.86], [1, 1.63, 517.77], [2, 1.65, 102.36]]}, {"timestamp": 1632579586811, "ltp": 1.62, "tv": 24385.74, "trd": [[1.62, 819.38]], "batb": NaN, "batl": [[0, 1.62, 3180.17]]}, {"timestamp": 1632579587203, "ltp": 1.62, "tv": 24438.84, "trd": [[1.62, 872.48]], "batb": NaN, "batl": [[0, 1.62, 3153.62], [2, 1.65, 2.36]]}, {"timestamp": 1632579589336, "ltp": 1.62, "tv": 24438.84, "trd": NaN, "batb": NaN, "batl": [[2, 1.69, 19.5]]}, {"timestamp": 1632579590608, "ltp": 1.62, "tv": 24440.46, "trd": [[1.62, 874.1]], "batb": NaN, "batl": [[0, 1.62, 3252.81]]}, {"timestamp": 1632579591656, "ltp": 1.62, "tv": 24440.46, "trd": NaN, "batb": [[1, 1.55, 21.39], [2, 1.54, 414.38]], "batl": [[0, 1.62, 3252.71], [2, 1.7, 17.25]]}, {"timestamp": 1632579592717, "ltp": 1.63, "tv": 31981.42, "trd": [[1.62, 7379.52], [1.63, 5701.8]], "batb": [[0, 1.68, 1451.43], [1, 1.67, 518.56], [2, 1.6, 34.28]], "batl": [[0, 1.72, 16.91], [1, 1.73, 564.27], [2, 1.74, 128.17]]}, {"timestamp": 1632579593737, "ltp": 1.63, "tv": 31981.42, "trd": NaN, "batb": [[2, 1.65, 1988.64]], "batl": NaN}, {"timestamp": 1632579594740, "ltp": 1.63, "tv": 31981.42, "trd": NaN, "batb": [[1, 1.67, 1247.69], [2, 1.66, 386.42]], "batl": [[1, 1.73, 2370.63], [2, 1.74, 1031.35]]}, {"timestamp": 1632579595686, "ltp": 1.68, "tv": 31998.67, "trd": [[1.68, 17.24]], "batb": [[0, 1.68, 1442.81], [1, 1.67, 1550.97]], "batl": [[1, 1.73, 1015.86], [2, 1.74, 353.97]]}, {"timestamp": 1632579596815, "ltp": 1.68, "tv": 32008.26, "trd": [[1.68, 26.84]], "batb": [[0, 1.67, 1550.97], [1, 1.66, 386.42], [2, 1.65, 473.49]], "batl": NaN}, {"timestamp": 1632579597774, "ltp": 1.66, "tv": 35154.97, "trd": [[1.66, 1693.02], [1.67, 3101.94], [1.68, 41.06]], "batb": [[0, 1.66, 371.15], [1, 1.65, 473.49], [2, 1.64, 236.74]], "batl": NaN}, {"timestamp": 1632579598766, "ltp": 1.66, "tv": 35154.97, "trd": NaN, "batb": NaN, "batl": [[0, 1.71, 208.55], [1, 1.72, 16.91], [2, 1.73, 506.4]]}, {"timestamp": 1632579599821, "ltp": 1.66, "tv": 35154.97, "trd": NaN, "batb": [[0, 1.67, 293.87], [1, 1.66, 377.15], [2, 1.65, 473.49]], "batl": [[2, 1.73, 802.15]]}, {"timestamp": 1632579600731, "ltp": 1.66, "tv": 35154.97, "trd": NaN, "batb": [[0, 1.66, 377.15], [1, 1.65, 473.49], [2, 1.64, 236.74]], "batl": NaN}, {"timestamp": 1632579601629, "ltp": 1.67, "tv": 36004.72, "trd": [[1.67, 3951.7]], "batb": [[1, 1.65, 479.49]], "batl": [[0, 1.67, 2482.25], [1, 1.71, 208.55], [2, 1.72, 846.83]]}, {"timestamp": 1632579602557, "ltp": 1.65, "tv": 37497.9, "trd": [[1.65, 1958.31], [1.66, 2447.32]], "batb": [[0, 1.65, 110.05], [1, 1.64, 236.74], [2, 1.63, 236.74]], "batl": NaN}, {"timestamp": 1632579603672, "ltp": 1.65, "tv": 37497.9, "trd": NaN, "batb": NaN, "batl": [[1, 1.7, 201], [2, 1.71, 225.05]]}, {"timestamp": 1632579604539, "ltp": 1.65, "tv": 37497.9, "trd": NaN, "batb": NaN, "batl": [[0, 1.68, 211.05]]}, {"timestamp": 1632579605764, "ltp": 1.65, "tv": 37497.9, "trd": NaN, "batb": [[0, 1.66, 261.21], [1, 1.65, 505.95], [2, 1.64, 241.74]], "batl": [[0, 1.7, 201], [1, 1.71, 225.05], [2, 1.72, 488.78]]}, {"timestamp": 1632579606269, "ltp": 1.65, "tv": 37497.9, "trd": NaN, "batb": [[0, 1.66, 476.2]], "batl": [[0, 1.68, 169.08], [1, 1.7, 201], [2, 1.71, 737.81]]}, {"timestamp": 1632579607703, "ltp": 1.65, "tv": 37497.9, "trd": NaN, "batb": NaN, "batl": [[0, 1.67, 99], [1, 1.68, 169.08], [2, 1.7, 201]]}, {"timestamp": 1632579608660, "ltp": 1.65, "tv": 37497.9, "trd": NaN, "batb": NaN, "batl": [[0, 1.67, 10.15], [1, 1.68, 513.23], [2, 1.69, 397.99]]}, {"timestamp": 1632579609469, "ltp": 1.65, "tv": 37497.9, "trd": NaN, "batb": NaN, "batl": [[1, 1.68, 742.39]]}, {"timestamp": 1632579610769, "ltp": 1.67, "tv": 37497.92, "trd": [[1.67, 3951.72]], "batb": NaN, "batl": [[0, 1.67, 10.14], [1, 1.68, 732.31]]}, {"timestamp": 1632579611475, "ltp": 1.66, "tv": 37502.62, "trd": [[1.66, 2452.02]], "batb": [[0, 1.66, 473.85]], "batl": NaN}, {"timestamp": 1632579612797, "ltp": 1.67, "tv": 37573.44, "trd": [[1.66, 2522.14], [1.67, 3952.42]], "batb": [[0, 1.66, 438.79], [1, 1.65, 401.9], [2, 1.64, 5]], "batl": [[0, 1.67, 9.79], [1, 1.68, 514.27], [2, 1.71, 512.76]]}, {"timestamp": 1632579613379, "ltp": 1.66, "tv": 37591.46, "trd": [[1.66, 2540.16]], "batb": [[0, 1.6, 34.28], [1, 1.58, 137.34], [2, 1.57, 228.6]], "batl": [[0, 1.66, 27.98], [1, 1.67, 9.79], [2, 1.68, 514.27]]}, {"timestamp": 1632579615666, "ltp": 1.66, "tv": 37592.82, "trd": [[1.66, 2541.52]], "batb": NaN, "batl": [[0, 1.66, 26.62]]}, {"timestamp": 1632579618221, "ltp": 1.66, "tv": 37592.82, "trd": NaN, "batb": NaN, "batl": [[1, 1.68, 514.27], [2, 1.73, 15.87]]}, {"timestamp": 1632579619728, "ltp": 1.66, "tv": 37596.82, "trd": [[1.66, 2545.52]], "batb": NaN, "batl": [[0, 1.66, 24.62], [1, 1.68, 534.41]]}, {"timestamp": 1632579620204, "ltp": 1.66, "tv": 37596.82, "trd": NaN, "batb": [[0, 1.64, 415.8], [1, 1.63, 413.64], [2, 1.6, 34.28]], "batl": [[1, 1.68, 514.27], [2, 1.69, 637.74]]}, {"timestamp": 1632579621377, "ltp": 1.64, "tv": 37616.4, "trd": [[1.64, 175.8]], "batb": [[0, 1.64, 406.01]], "batl": NaN}, {"timestamp": 1632579623607, "ltp": 1.66, "tv": 37624.98, "trd": [[1.66, 2554.09]], "batb": NaN, "batl": [[0, 1.66, 20.33]]}, {"timestamp": 1632579624670, "ltp": 1.66, "tv": 37624.98, "trd": NaN, "batb": [[0, 1.6, 34.28], [1, 1.56, 22.83], [2, 1.55, 423.94]], "batl": [[2, 1.73, 15.87]]}, {"timestamp": 1632579625574, "ltp": 1.66, "tv": 37628.98, "trd": [[1.66, 2558.09]], "batb": NaN, "batl": [[0, 1.66, 18.33]]}, {"timestamp": 1632579627817, "ltp": 1.66, "tv": 37628.98, "trd": NaN, "batb": [[1, 1.56, 461.77], [2, 1.55, 923.8]], "batl": NaN}, {"timestamp": 1632579627865, "ltp": 1.66, "tv": 37628.98, "trd": NaN, "batb": [[2, 1.55, 902.41]], "batl": NaN}, {"timestamp": 1632579629192, "ltp": 1.6, "tv": 37697.54, "trd": [[1.6, 68.56]], "batb": [[0, 1.56, 461.77], [1, 1.55, 902.41], [2, 1.51, 24.99]], "batl": [[0, 1.59, 518.56], [1, 1.6, 2187.72], [2, 1.66, 18.33]]}, {"timestamp": 1632579631790, "ltp": 1.59, "tv": 37722.9, "trd": [[1.59, 25.35]], "batb": [[2, 1.54, 507.3]], "batl": [[0, 1.59, 493.2], [1, 1.6, 2697.93], [2, 1.61, 431.59]]}, {"timestamp": 1632579632493, "ltp": 1.59, "tv": 37722.9, "trd": NaN, "batb": [[0, 1.56, 467.77], [1, 1.55, 907.41]], "batl": NaN}, {"timestamp": 1632579634757, "ltp": 1.59, "tv": 37722.9, "trd": NaN, "batb": NaN, "batl": [[0, 1.58, 212.5], [1, 1.59, 493.2], [2, 1.6, 2697.93]]}, {"timestamp": 1632579635571, "ltp": 1.59, "tv": 37722.9, "trd": NaN, "batb": NaN, "batl": [[2, 1.6, 510.21]]}, {"timestamp": 1632579636673, "ltp": 1.58, "tv": 37742.9, "trd": [[1.58, 20]], "batb": NaN, "batl": [[0, 1.58, 202.5]]}, {"timestamp": 1632579637676, "ltp": 1.58, "tv": 37742.9, "trd": NaN, "batb": [[0, 1.57, 82], [1, 1.56, 467.77], [2, 1.55, 907.41]], "batl": NaN}, {"timestamp": 1632579638770, "ltp": 1.58, "tv": 37842.9, "trd": [[1.58, 120]], "batb": [[2, 1.55, 1311.52]], "batl": [[0, 1.58, 152.5]]}, {"timestamp": 1632579639803, "ltp": 1.58, "tv": 37844.46, "trd": [[1.58, 121.56]], "batb": [[2, 1.55, 1309.75]], "batl": [[0, 1.58, 151.72]]}, {"timestamp": 1632579640799, "ltp": 1.57, "tv": 38223.15, "trd": [[1.57, 174], [1.58, 326.26]], "batb": [[0, 1.56, 467.77], [1, 1.55, 1309.75], [2, 1.54, 949.9]], "batl": [[0, 1.57, 2553.36], [1, 1.59, 219.3]]}, {"timestamp": 1632579641683, "ltp": 1.57, "tv": 38423.15, "trd": [[1.57, 374]], "batb": NaN, "batl": [[0, 1.57, 2453.36], [1, 1.58, 256], [2, 1.59, 219.3]]}, {"timestamp": 1632579642697, "ltp": 1.57, "tv": 38448.63, "trd": [[1.57, 399.48]], "batb": NaN, "batl": [[0, 1.57, 2437.88]]}, {"timestamp": 1632579643693, "ltp": 1.57, "tv": 38457.41, "trd": [[1.57, 408.26]], "batb": NaN, "batl": [[0, 1.57, 2433.49]]}, {"timestamp": 1632579644297, "ltp": 1.57, "tv": 38466.03, "trd": [[1.57, 416.88]], "batb": NaN, "batl": [[0, 1.57, 2631.3], [1, 1.58, 456.84]]}, {"timestamp": 1632579645787, "ltp": 1.57, "tv": 39364.96, "trd": [[1.57, 1315.81]], "batb": [[0, 1.56, 512.56], [1, 1.55, 1371.58]], "batl": [[0, 1.57, 2181.83]]}, {"timestamp": 1632579646266, "ltp": 1.57, "tv": 39447.68, "trd": [[1.57, 1398.53]], "batb": NaN, "batl": [[0, 1.57, 2099.11]]}, {"timestamp": 1632579647217, "ltp": 1.57, "tv": 39451.57, "trd": [[1.57, 1402.42]], "batb": [[0, 1.56, 517.02]], "batl": [[0, 1.57, 2095.22], [1, 1.58, 846.27], [2, 1.59, 679.7]]}, {"timestamp": 1632579648499, "ltp": 1.57, "tv": 39456.27, "trd": [[1.57, 1407.12]], "batb": [[1, 1.55, 1378.58]], "batl": [[0, 1.57, 2092.87]]}, {"timestamp": 1632579649782, "ltp": 1.57, "tv": 39457.45, "trd": [[1.57, 1408.3]], "batb": NaN, "batl": [[0, 1.57, 2117.28]]}, {"timestamp": 1632579650695, "ltp": 1.57, "tv": 39457.45, "trd": NaN, "batb": [[0, 1.56, 547.02], [1, 1.55, 3283.09]], "batl": NaN}, {"timestamp": 1632579651481, "ltp": 1.57, "tv": 39535.47, "trd": [[1.57, 1486.32]], "batb": NaN, "batl": [[0, 1.57, 2078.27]]}, {"timestamp": 1632579652494, "ltp": 1.57, "tv": 39648.35, "trd": [[1.56, 21.72], [1.57, 1577.48]], "batb": [[0, 1.56, 536.16]], "batl": [[0, 1.57, 2032.69]]}, {"timestamp": 1632579654288, "ltp": 1.57, "tv": 39668.36, "trd": [[1.57, 1597.48]], "batb": NaN, "batl": [[0, 1.57, 2022.69]]}, {"timestamp": 1632579654907, "ltp": 1.57, "tv": 39669.76, "trd": [[1.57, 1598.89]], "batb": NaN, "batl": [[0, 1.57, 2021.99]]}, {"timestamp": 1632579656780, "ltp": 1.57, "tv": 39901.97, "trd": [[1.57, 1831.09]], "batb": NaN, "batl": [[0, 1.57, 1905.88]]}, {"timestamp": 1632579657272, "ltp": 1.56, "tv": 39907.69, "trd": [[1.56, 27.44]], "batb": [[0, 1.56, 533.3]], "batl": NaN}, {"timestamp": 1632579662809, "ltp": 1.57, "tv": 40266.08, "trd": [[1.57, 2189.48]], "batb": [[1, 1.55, 3276.09]], "batl": [[0, 1.57, 1726.68]]}, {"timestamp": 1632579663735, "ltp": 1.56, "tv": 40267.76, "trd": [[1.56, 29.12]], "batb": [[0, 1.56, 532.46]], "batl": NaN}, {"timestamp": 1632579664395, "ltp": 1.56, "tv": 40267.76, "trd": NaN, "batb": [[0, 1.56, 502.46]], "batl": NaN}, {"timestamp": 1632579665557, "ltp": 1.56, "tv": 40305.04, "trd": [[1.56, 56.4], [1.57, 2199.48]], "batb": [[0, 1.56, 488.82]], "batl": [[0, 1.57, 1721.69]]}, {"timestamp": 1632579666132, "ltp": 1.57, "tv": 41291.58, "trd": [[1.57, 3186.02]], "batb": NaN, "batl": [[0, 1.57, 1228.41]]}, {"timestamp": 1632579667739, "ltp": 1.57, "tv": 41397.9, "trd": [[1.56, 160.4], [1.57, 3188.34]], "batb": [[0, 1.56, 55.25], [1, 1.55, 871.72]], "batl": [[0, 1.57, 1227.26]]}, {"timestamp": 1632579670562, "ltp": 1.57, "tv": 41411.92, "trd": [[1.57, 3202.36]], "batb": NaN, "batl": [[0, 1.57, 1220.25]]}, {"timestamp": 1632579671454, "ltp": 1.56, "tv": 41412.3, "trd": [[1.56, 160.78]], "batb": [[0, 1.56, 55.06]], "batl": NaN}, {"timestamp": 1632579673819, "ltp": 1.57, "tv": 41422.07, "trd": [[1.56, 161.88], [1.57, 3211.03]], "batb": [[0, 1.56, 9.72]], "batl": [[0, 1.57, 1215.91]]}, {"timestamp": 1632579674242, "ltp": 1.55, "tv": 43503.51, "trd": [[1.55, 2047.04], [1.56, 196.28]], "batb": [[0, 1.54, 949.9], [1, 1.53, 11088.92], [2, 1.52, 253.65]], "batl": NaN}, {"timestamp": 1632579676806, "ltp": 1.57, "tv": 43515.9, "trd": [[1.57, 3223.43]], "batb": [[0, 1.51, 513.76], [1, 1.5, 1230.93], [2, 1.49, 232.6]], "batl": [[0, 1.57, 1007.59], [1, 1.58, 256], [2, 1.6, 46.48]]}, {"timestamp": 1632579677764, "ltp": 1.56, "tv": 43527.9, "trd": [[1.56, 208.28]], "batb": NaN, "batl": [[1, 1.6, 46.48], [2, 1.67, 168.44]]}, {"timestamp": 1632579678658, "ltp": 1.57, "tv": 43531.53, "trd": [[1.57, 3227.05]], "batb": NaN, "batl": [[0, 1.57, 1004.28]]}, {"timestamp": 1632579679823, "ltp": 1.57, "tv": 43537.53, "trd": [[1.57, 3233.05]], "batb": [[0, 1.52, 23.24], [1, 1.51, 513.76], [2, 1.5, 1256.67]], "batl": [[0, 1.57, 1001.28], [2, 1.67, 186.94]]}, {"timestamp": 1632579680827, "ltp": 1.57, "tv": 43589.05, "trd": [[1.57, 3284.58]], "batb": [[0, 1.57, 209.13], [1, 1.51, 6], [2, 1.5, 237.23]], "batl": [[0, 1.6, 46.48], [1, 1.67, 186.94], [2, 1.68, 177.73]]}, {"timestamp": 1632579681719, "ltp": 1.57, "tv": 43590.97, "trd": [[1.57, 3286.5]], "batb": [[0, 1.57, 208.17]], "batl": NaN}, {"timestamp": 1632579681936, "ltp": 1.57, "tv": 43597.99, "trd": [[1.57, 3293.52]], "batb": [[0, 1.57, 204.66]], "batl": NaN}, {"timestamp": 1632579683761, "ltp": 1.57, "tv": 43597.99, "trd": NaN, "batb": [[1, 1.52, 25.74], [2, 1.51, 6]], "batl": NaN}, {"timestamp": 1632579684574, "ltp": 1.57, "tv": 43853.97, "trd": [[1.57, 3549.5]], "batb": [[0, 1.57, 742.23], [1, 1.56, 1440.94], [2, 1.52, 25.74]], "batl": [[1, 1.62, 678.01], [2, 1.63, 412.29]]}, {"timestamp": 1632579685759, "ltp": 1.57, "tv": 43853.97, "trd": NaN, "batb": NaN, "batl": [[0, 1.6, 115.48]]}, {"timestamp": 1632579686739, "ltp": 1.57, "tv": 43853.97, "trd": NaN, "batb": [[0, 1.57, 76.67], [1, 1.52, 25.74], [2, 1.51, 6]], "batl": [[0, 1.6, 46.48], [1, 1.67, 186.94], [2, 1.68, 177.73]]}, {"timestamp": 1632579687773, "ltp": 1.57, "tv": 43853.97, "trd": NaN, "batb": [[0, 1.58, 275.41], [1, 1.57, 76.67], [2, 1.52, 25.74]], "batl": [[0, 1.6, 466.52]]}, {"timestamp": 1632579687939, "ltp": 1.57, "tv": 43853.97, "trd": NaN, "batb": [[0, 1.57, 76.67], [1, 1.52, 25.74], [2, 1.51, 6]], "batl": [[0, 1.6, 46.48]]}, {"timestamp": 1632579689649, "ltp": 1.57, "tv": 43859.97, "trd": [[1.57, 3555.5]], "batb": [[0, 1.57, 73.67], [1, 1.52, 59.74], [2, 1.51, 494.77]], "batl": NaN}, {"timestamp": 1632579690303, "ltp": 1.57, "tv": 43859.97, "trd": NaN, "batb": [[2, 1.51, 528.77]], "batl": NaN}, {"timestamp": 1632579692667, "ltp": 1.6, "tv": 43952.93, "trd": [[1.6, 161.52]], "batb": NaN, "batl": [[0, 1.67, 186.94], [1, 1.68, 177.73], [2, 1.69, 882.57]]}, {"timestamp": 1632579693783, "ltp": 1.6, "tv": 43952.93, "trd": NaN, "batb": [[0, 1.6, 2.55], [1, 1.57, 73.67], [2, 1.52, 69.74]], "batl": NaN}, {"timestamp": 1632579694569, "ltp": 1.57, "tv": 44105.37, "trd": [[1.57, 3702.84], [1.6, 166.62]], "batb": [[0, 1.52, 54], [1, 1.51, 528.77], [2, 1.5, 801.96]], "batl": [[0, 1.53, 4084.97], [1, 1.67, 186.94], [2, 1.68, 177.73]]}, {"timestamp": 1632579696573, "ltp": 1.57, "tv": 44105.37, "trd": NaN, "batb": [[1, 1.51, 40], [2, 1.5, 232.23]], "batl": [[1, 1.67, 168.44]]}, {"timestamp": 1632579697781, "ltp": 1.53, "tv": 44530.15, "trd": [[1.53, 424.79]], "batb": NaN, "batl": [[0, 1.53, 3680.85]]}, {"timestamp": 1632579698375, "ltp": 1.53, "tv": 44548.49, "trd": [[1.53, 443.13]], "batb": NaN, "batl": [[0, 1.53, 3662.51]]}, {"timestamp": 1632579699762, "ltp": 1.53, "tv": 44588.49, "trd": [[1.53, 483.13]], "batb": NaN, "batl": [[0, 1.53, 3642.51]]}, {"timestamp": 1632579702682, "ltp": 1.53, "tv": 44588.49, "trd": NaN, "batb": [[0, 1.52, 34]], "batl": NaN}, {"timestamp": 1632579702976, "ltp": 1.53, "tv": 44628.49, "trd": [[1.53, 523.13]], "batb": NaN, "batl": [[0, 1.53, 3622.51]]}, {"timestamp": 1632579704985, "ltp": 1.53, "tv": 44635.51, "trd": [[1.53, 530.15]], "batb": NaN, "batl": [[0, 1.53, 3619]]}, {"timestamp": 1632579706097, "ltp": 1.52, "tv": 44703.51, "trd": [[1.52, 68]], "batb": [[0, 1.51, 60], [1, 1.5, 232.23], [2, 1.49, 719.51]], "batl": [[0, 1.52, 187.83], [1, 1.53, 3619], [2, 1.67, 168.44]]}, {"timestamp": 1632579708603, "ltp": 1.52, "tv": 44705.12, "trd": [[1.52, 69.6]], "batb": NaN, "batl": [[0, 1.52, 184.68]]}, {"timestamp": 1632579709577, "ltp": 1.52, "tv": 44717.12, "trd": [[1.52, 81.6]], "batb": [[0, 1.51, 40], [1, 1.5, 239.23]], "batl": [[0, 1.52, 178.68], [2, 1.64, 20]]}, {"timestamp": 1632579713291, "ltp": 1.52, "tv": 44717.9, "trd": [[1.52, 82.39]], "batb": NaN, "batl": [[0, 1.52, 178.29]]}, {"timestamp": 1632579714392, "ltp": 1.52, "tv": 44726.92, "trd": [[1.52, 91.4]], "batb": NaN, "batl": [[0, 1.52, 173.78]]}, {"timestamp": 1632579715812, "ltp": 1.52, "tv": 44730.84, "trd": [[1.52, 95.33]], "batb": NaN, "batl": [[0, 1.52, 171.82]]}, {"timestamp": 1632579716107, "ltp": 1.52, "tv": 44787.57, "trd": [[1.52, 152.06]], "batb": NaN, "batl": [[0, 1.52, 143.45]]}, {"timestamp": 1632579719694, "ltp": 1.52, "tv": 44788.59, "trd": [[1.52, 153.08]], "batb": [[0, 1.51, 6]], "batl": [[0, 1.52, 142.43]]}, {"timestamp": 1632579721216, "ltp": 1.52, "tv": 44795.61, "trd": [[1.52, 160.1]], "batb": NaN, "batl": [[0, 1.52, 138.92]]}, {"timestamp": 1632579722172, "ltp": 1.5, "tv": 45667.73, "trd": [[1.5, 860.12], [1.51, 12]], "batb": [[0, 1.49, 719.51], [1, 1.48, 228.48], [2, 1.42, 1.76]], "batl": NaN}, {"timestamp": 1632579725578, "ltp": 1.5, "tv": 45667.73, "trd": NaN, "batb": [[0, 1.51, 7], [1, 1.5, 6], [2, 1.49, 725.51]], "batl": [[0, 1.52, 136.57]]}, {"timestamp": 1632579725968, "ltp": 1.5, "tv": 45667.73, "trd": NaN, "batb": [[0, 1.49, 725.51], [1, 1.48, 234.48], [2, 1.42, 1.76]], "batl": NaN}, {"timestamp": 1632579727801, "ltp": 1.5, "tv": 45667.73, "trd": NaN, "batb": NaN, "batl": [[1, 1.53, 7703.97], [2, 1.56, 6]]}, {"timestamp": 1632579728443, "ltp": 1.52, "tv": 45703.75, "trd": [[1.52, 196.12]], "batb": [[2, 1.47, 531.46]], "batl": [[0, 1.52, 104.84], [1, 1.53, 4435.99]]}, {"timestamp": 1632579729628, "ltp": 1.52, "tv": 45703.75, "trd": NaN, "batb": [[0, 1.49, 31.01], [1, 1.48, 6], [2, 1.46, 513.98]], "batl": [[0, 1.51, 89.71], [1, 1.52, 104.84]]}, {"timestamp": 1632579730131, "ltp": 1.52, "tv": 45703.75, "trd": NaN, "batb": [[0, 1.49, 6], [2, 1.46, 512.12]], "batl": [[2, 1.64, 20]]}, {"timestamp": 1632579731153, "ltp": 1.51, "tv": 45705.75, "trd": [[1.51, 14]], "batb": NaN, "batl": [[0, 1.51, 88.71]]}, {"timestamp": 1632579732609, "ltp": 1.49, "tv": 45717.75, "trd": [[1.49, 12]], "batb": [[0, 1.48, 6], [1, 1.47, 564.85], [2, 1.46, 1149.99]], "batl": [[0, 1.49, 45.76], [1, 1.51, 88.71], [2, 1.52, 104.84]]}, {"timestamp": 1632579733707, "ltp": 1.49, "tv": 45724.77, "trd": [[1.49, 19.02]], "batb": NaN, "batl": [[0, 1.49, 42.25], [1, 1.5, 20]]}, {"timestamp": 1632579735809, "ltp": 1.48, "tv": 45745.02, "trd": [[1.48, 20.25]], "batb": [[0, 1.47, 572.85], [1, 1.46, 1149.99], [2, 1.42, 1.76]], "batl": NaN}, {"timestamp": 1632579736810, "ltp": 1.47, "tv": 46662.13, "trd": [[1.47, 917.12]], "batb": [[0, 1.47, 114.29]], "batl": [[0, 1.49, 2264.25]]}, {"timestamp": 1632579737797, "ltp": 1.49, "tv": 46666.13, "trd": [[1.49, 23.02]], "batb": [[0, 1.47, 8]], "batl": [[0, 1.49, 2262.25], [1, 1.52, 293.57], [2, 1.53, 183.18]]}, {"timestamp": 1632579738665, "ltp": 1.49, "tv": 46673.05, "trd": [[1.49, 29.94]], "batb": NaN, "batl": [[0, 1.49, 2257.03], [1, 1.51, 566.04], [2, 1.52, 4068.24]]}, {"timestamp": 1632579739813, "ltp": 1.47, "tv": 48721.51, "trd": [[1.47, 933.12], [1.49, 2062.4]], "batb": [[0, 1.46, 1155.99], [1, 1.43, 556.26]], "batl": [[0, 1.47, 944.26], [1, 1.49, 1227.01], [2, 1.51, 559.04]]}, {"timestamp": 1632579740830, "ltp": 1.47, "tv": 48721.51, "trd": NaN, "batb": [[0, 1.46, 1530.64], [1, 1.45, 661.58], [2, 1.43, 556.26]], "batl": [[1, 1.48, 40], [2, 1.49, 1227.01]]}, {"timestamp": 1632579741821, "ltp": 1.47, "tv": 48721.51, "trd": NaN, "batb": NaN, "batl": [[0, 1.48, 40], [1, 1.49, 1227.01], [2, 1.5, 441.92]]}, {"timestamp": 1632579742346, "ltp": 1.48, "tv": 48722.31, "trd": [[1.48, 21.05]], "batb": [[0, 1.47, 282.89], [1, 1.46, 1530.64], [2, 1.45, 661.58]], "batl": [[0, 1.48, 39.6], [1, 1.49, 441.73]]}, {"timestamp": 1632579743691, "ltp": 1.48, "tv": 48722.31, "trd": NaN, "batb": [[1, 1.46, 1823.83], [2, 1.45, 667.58]], "batl": [[0, 1.48, 484.54], [1, 1.49, 450.52], [2, 1.5, 851.62]]}, {"timestamp": 1632579744751, "ltp": 1.48, "tv": 48736.33, "trd": [[1.48, 35.07]], "batb": NaN, "batl": [[0, 1.48, 477.53]]}, {"timestamp": 1632579745653, "ltp": 1.48, "tv": 48736.33, "trd": NaN, "batb": [[0, 1.47, 332.89]], "batl": NaN}, {"timestamp": 1632579746651, "ltp": 1.48, "tv": 48736.33, "trd": NaN, "batb": NaN, "batl": [[1, 1.49, 806.22], [2, 1.5, 1250.18]]}, {"timestamp": 1632579747249, "ltp": 1.48, "tv": 48750.33, "trd": [[1.48, 49.07]], "batb": [[0, 1.47, 282.89]], "batl": [[0, 1.48, 470.53]]}, {"timestamp": 1632579748820, "ltp": 1.48, "tv": 48750.33, "trd": NaN, "batb": [[0, 1.47, 568.31]], "batl": [[0, 1.48, 233.59]]}, {"timestamp": 1632579749579, "ltp": 1.48, "tv": 49041.75, "trd": [[1.47, 1124.54], [1.48, 149.07]], "batb": [[0, 1.47, 479.3], [1, 1.46, 2183.82], [2, 1.45, 1095.28]], "batl": [[0, 1.48, 183.59]]}, {"timestamp": 1632579750661, "ltp": 1.48, "tv": 49062.79, "trd": [[1.48, 170.11]], "batb": NaN, "batl": [[0, 1.48, 173.07]]}, {"timestamp": 1632579751787, "ltp": 1.48, "tv": 49071.37, "trd": [[1.48, 178.68]], "batb": [[0, 1.47, 292.47], [1, 1.46, 1538.69], [2, 1.45, 667.58]], "batl": [[0, 1.48, 168.78], [1, 1.49, 377.23], [2, 1.5, 911.62]]}, {"timestamp": 1632579752788, "ltp": 1.49, "tv": 50544.87, "trd": [[1.47, 1505.1], [1.48, 1256.06], [1.49, 2077.96]], "batb": [[0, 1.49, 10.76], [1, 1.48, 239.34], [2, 1.47, 96.19]], "batl": [[0, 1.54, 184.86], [1, 1.55, 220.12], [2, 1.56, 228.33]]}, {"timestamp": 1632579753770, "ltp": 1.49, "tv": 50544.87, "trd": NaN, "batb": [[1, 1.48, 243.35]], "batl": NaN}, {"timestamp": 1632579755754, "ltp": 1.49, "tv": 50544.87, "trd": NaN, "batb": [[2, 1.47, 95.84]], "batl": [[1, 1.55, 713.18], [2, 1.56, 714.66]]}, {"timestamp": 1632579756688, "ltp": 1.49, "tv": 50568.4, "trd": [[1.49, 2101.49]], "batb": [[0, 1.48, 243.35], [1, 1.47, 95.84], [2, 1.46, 8.05]], "batl": [[0, 1.49, 183.46], [1, 1.54, 184.86], [2, 1.55, 220.12]]}, {"timestamp": 1632579757787, "ltp": 1.49, "tv": 50568.4, "trd": NaN, "batb": [[0, 1.48, 245.11]], "batl": [[0, 1.49, 546.51]]}, {"timestamp": 1632579758584, "ltp": 1.48, "tv": 50621.54, "trd": [[1.48, 1309.2]], "batb": [[0, 1.48, 218.54]], "batl": NaN}, {"timestamp": 1632579759792, "ltp": 1.49, "tv": 50711.54, "trd": [[1.49, 2191.49]], "batb": [[0, 1.48, 236.07]], "batl": [[0, 1.49, 614.51]]}, {"timestamp": 1632579760758, "ltp": 1.49, "tv": 50715.57, "trd": [[1.49, 2195.52]], "batb": [[1, 1.47, 1021.46], [2, 1.46, 649.81]], "batl": [[0, 1.49, 579.53], [1, 1.51, 466.33], [2, 1.52, 537.69]]}, {"timestamp": 1632579761558, "ltp": 1.48, "tv": 50925.24, "trd": [[1.48, 1518.88]], "batb": [[0, 1.48, 131.23]], "batl": [[0, 1.49, 113]]}, {"timestamp": 1632579762786, "ltp": 1.49, "tv": 50960.89, "trd": [[1.48, 1552.52], [1.49, 2197.53]], "batb": [[0, 1.48, 114.41], [1, 1.47, 95.84], [2, 1.46, 8.05]], "batl": [[0, 1.54, 184.86], [1, 1.55, 220.12], [2, 1.56, 228.33]]}, {"timestamp": 1632579763757, "ltp": 1.49, "tv": 50960.89, "trd": NaN, "batb": [[0, 1.48, 110.4]], "batl": NaN}, {"timestamp": 1632579764752, "ltp": 1.48, "tv": 51142.19, "trd": [[1.48, 1733.81]], "batb": [[0, 1.48, 19.75]], "batl": NaN}, {"timestamp": 1632579765782, "ltp": 1.48, "tv": 51142.19, "trd": NaN, "batb": NaN, "batl": [[1, 1.55, 713.18], [2, 1.56, 714.66]]}, {"timestamp": 1632579767673, "ltp": 1.54, "tv": 51160.25, "trd": [[1.48, 1749.87], [1.54, 2]], "batb": [[0, 1.48, 11.72]], "batl": [[0, 1.54, 183.86]]}, {"timestamp": 1632579768753, "ltp": 1.54, "tv": 51162.25, "trd": [[1.54, 4.01]], "batb": NaN, "batl": [[0, 1.54, 182.86]]}, {"timestamp": 1632579769808, "ltp": 1.54, "tv": 51162.25, "trd": NaN, "batb": [[0, 1.49, 1.15], [1, 1.48, 11.72], [2, 1.47, 95.84]], "batl": NaN}, {"timestamp": 1632579770801, "ltp": 1.54, "tv": 51165.86, "trd": [[1.49, 2199.13], [1.54, 6.01]], "batb": [[0, 1.48, 5.86], [1, 1.46, 8.75], [2, 1.45, 6]], "batl": [[0, 1.54, 181.85]]}, {"timestamp": 1632579771822, "ltp": 1.54, "tv": 51165.86, "trd": NaN, "batb": NaN, "batl": [[0, 1.64, 20], [1, 1.84, 2], [2, 2.04, 3.15]]}, {"timestamp": 1632579772810, "ltp": 1.45, "tv": 51296.89, "trd": [[1.45, 14.2], [1.46, 16.1], [1.47, 1506.5], [1.48, 1848.8], [1.54, 6.41]], "batb": [[0, 1.44, 532.96], [1, 1.43, 1472.58], [2, 1.42, 215.62]], "batl": [[0, 1.45, 450.36], [1, 1.46, 2213.25], [2, 1.48, 412.15]]}, {"timestamp": 1632579773812, "ltp": 1.45, "tv": 51296.89, "trd": NaN, "batb": NaN, "batl": [[2, 1.47, 6189.74]]}, {"timestamp": 1632579774805, "ltp": 1.45, "tv": 51641.74, "trd": [[1.45, 359.05]], "batb": NaN, "batl": [[0, 1.45, 277.93], [2, 1.47, 952.26]]}, {"timestamp": 1632579775797, "ltp": 1.45, "tv": 51803.57, "trd": [[1.44, 34.88], [1.45, 486.01]], "batb": [[0, 1.44, 518.08], [1, 1.43, 1479.24]], "batl": [[0, 1.45, 196.67], [1, 1.48, 1430.59], [2, 1.49, 578.26]]}, {"timestamp": 1632579776605, "ltp": 1.45, "tv": 51805.58, "trd": [[1.45, 488.01]], "batb": NaN, "batl": [[0, 1.45, 195.67], [1, 1.48, 1065.09]]}, {"timestamp": 1632579777702, "ltp": 1.45, "tv": 51805.58, "trd": NaN, "batb": NaN, "batl": [[0, 1.48, 1065.09], [1, 1.49, 578.26], [2, 1.52, 40]]}, {"timestamp": 1632579778829, "ltp": 1.46, "tv": 51807.58, "trd": [[1.46, 18.1]], "batb": [[0, 1.44, 867.74]], "batl": [[0, 1.46, 343.87], [1, 1.48, 1065.09], [2, 1.49, 578.26]]}, {"timestamp": 1632579779582, "ltp": 1.44, "tv": 51835.6, "trd": [[1.44, 62.9]], "batb": [[0, 1.44, 853.73]], "batl": NaN}, {"timestamp": 1632579780655, "ltp": 1.44, "tv": 51835.6, "trd": NaN, "batb": [[0, 1.45, 342.08], [1, 1.44, 853.73], [2, 1.43, 1479.24]], "batl": [[0, 1.47, 337.43]]}, {"timestamp": 1632579781795, "ltp": 1.44, "tv": 51835.6, "trd": NaN, "batb": [[0, 1.45, 346.09], [2, 1.43, 1509.67]], "batl": NaN}, {"timestamp": 1632579782686, "ltp": 1.44, "tv": 51835.6, "trd": NaN, "batb": [[0, 1.45, 353.85], [1, 1.44, 880.65]], "batl": NaN}, {"timestamp": 1632579783741, "ltp": 1.47, "tv": 51837.6, "trd": [[1.47, 1508.5]], "batb": NaN, "batl": [[0, 1.47, 336.43]]}, {"timestamp": 1632579784802, "ltp": 1.47, "tv": 51837.6, "trd": NaN, "batb": [[0, 1.45, 354.37], [1, 1.44, 900.65]], "batl": [[0, 1.47, 890.13], [1, 1.48, 1556.22]]}, {"timestamp": 1632579786821, "ltp": 1.47, "tv": 51837.6, "trd": NaN, "batb": [[0, 1.45, 29.54], [1, 1.44, 52.92], [2, 1.43, 37.43]], "batl": [[0, 1.48, 46.65], [1, 1.5, 194.8], [2, 1.51, 239.12]]}, {"timestamp": 1632579787794, "ltp": 1.45, "tv": 51844.62, "trd": [[1.45, 495.03]], "batb": [[0, 1.45, 1.02], [2, 1.43, 7]], "batl": NaN}, {"timestamp": 1632579788809, "ltp": 1.45, "tv": 51844.62, "trd": NaN, "batb": [[2, 1.42, 230.75]], "batl": NaN}, {"timestamp": 1632579789794, "ltp": 1.45, "tv": 51844.62, "trd": NaN, "batb": [[0, 1.45, 285.92], [2, 1.42, 903.25]], "batl": [[2, 1.51, 1159.05]]}, {"timestamp": 1632579790715, "ltp": 1.45, "tv": 51844.62, "trd": NaN, "batb": [[0, 1.44, 53.42], [1, 1.42, 903.25], [2, 1.41, 1586.53]], "batl": [[1, 1.51, 948.43], [2, 1.52, 574.97]]}, {"timestamp": 1632579791624, "ltp": 1.43, "tv": 51972.82, "trd": [[1.43, 21.35], [1.44, 168.74], [1.45, 496.04]], "batb": [[0, 1.42, 699.7], [1, 1.41, 1586.53], [2, 1.4, 278.53]], "batl": [[0, 1.43, 2206.65], [1, 1.44, 458.56], [2, 1.45, 12.86]]}, {"timestamp": 1632579792831, "ltp": 1.43, "tv": 51972.82, "trd": NaN, "batb": [[1, 1.41, 1636.53]], "batl": [[0, 1.43, 2216.79], [2, 1.45, 121.49]]}, {"timestamp": 1632579793827, "ltp": 1.43, "tv": 51972.82, "trd": NaN, "batb": [[2, 1.4, 1507.99]], "batl": [[0, 1.43, 10.14]]}, {"timestamp": 1632579794726, "ltp": 1.42, "tv": 52031.74, "trd": [[1.42, 28], [1.43, 34.71], [1.45, 513.6]], "batb": [[0, 1.42, 685.7]], "batl": [[0, 1.45, 112.71], [1, 1.46, 1149.68], [2, 1.47, 1640.59]]}, {"timestamp": 1632579795744, "ltp": 1.45, "tv": 52035.26, "trd": [[1.45, 517.11]], "batb": [[0, 1.42, 692.7]], "batl": [[0, 1.45, 108.63]]}, {"timestamp": 1632579797637, "ltp": 1.45, "tv": 52047.26, "trd": [[1.45, 529.11]], "batb": [[0, 1.44, 5], [1, 1.42, 692.7], [2, 1.41, 1586.53]], "batl": [[0, 1.45, 102.63]]}, {"timestamp": 1632579798636, "ltp": 1.45, "tv": 52047.26, "trd": NaN, "batb": [[0, 1.44, 39], [1, 1.43, 378.85], [2, 1.42, 1018.12]], "batl": [[0, 1.45, 421.31]]}, {"timestamp": 1632579799647, "ltp": 1.45, "tv": 52047.26, "trd": NaN, "batb": [[0, 1.44, 107]], "batl": NaN}, {"timestamp": 1632579800830, "ltp": 1.45, "tv": 52047.26, "trd": NaN, "batb": [[0, 1.44, 211.67], [1, 1.43, 689.34], [2, 1.42, 1068.12]], "batl": NaN}, {"timestamp": 1632579801726, "ltp": 1.45, "tv": 52055.83, "trd": [[1.45, 537.69]], "batb": NaN, "batl": [[0, 1.45, 821.58], [1, 1.46, 1617.67]]}, {"timestamp": 1632579802743, "ltp": 1.44, "tv": 52081.55, "trd": [[1.44, 194.46]], "batb": [[0, 1.44, 266.81], [1, 1.43, 312.84], [2, 1.42, 1073.89]], "batl": NaN}, {"timestamp": 1632579803557, "ltp": 1.44, "tv": 52081.55, "trd": NaN, "batb": [[1, 1.43, 541.7]], "batl": [[1, 1.46, 1893.51]]}, {"timestamp": 1632579804766, "ltp": 1.44, "tv": 52081.55, "trd": NaN, "batb": [[0, 1.44, 733.12], [1, 1.43, 542.05]], "batl": [[0, 1.45, 1062.58]]}, {"timestamp": 1632579805781, "ltp": 1.45, "tv": 52839.24, "trd": [[1.45, 1295.38]], "batb": [[1, 1.43, 744.14], [2, 1.42, 1260.47]], "batl": [[0, 1.45, 683.74], [1, 1.46, 1820.76]]}, {"timestamp": 1632579806653, "ltp": 1.45, "tv": 52845.24, "trd": [[1.45, 1301.38]], "batb": [[0, 1.44, 738.12]], "batl": [[0, 1.45, 680.74]]}, {"timestamp": 1632579807714, "ltp": 1.45, "tv": 52882.81, "trd": [[1.45, 1338.96]], "batb": [[1, 1.43, 737.23]], "batl": [[0, 1.45, 661.95]]}, {"timestamp": 1632579808779, "ltp": 1.45, "tv": 52883.85, "trd": [[1.45, 1340]], "batb": [[0, 1.44, 788.12]], "batl": [[0, 1.45, 661.43]]}, {"timestamp": 1632579809758, "ltp": 1.45, "tv": 52885.65, "trd": [[1.45, 1341.8]], "batb": [[1, 1.43, 736.88]], "batl": [[0, 1.45, 660.53]]}, {"timestamp": 1632579811762, "ltp": 1.45, "tv": 52926.32, "trd": [[1.45, 1382.46]], "batb": [[0, 1.44, 795.12], [1, 1.43, 735.93]], "batl": [[0, 1.45, 640.2]]}, {"timestamp": 1632579812752, "ltp": 1.45, "tv": 52926.32, "trd": NaN, "batb": [[0, 1.44, 745.12]], "batl": NaN}, {"timestamp": 1632579814750, "ltp": 1.45, "tv": 52935.44, "trd": [[1.44, 196.56], [1.45, 1389.48]], "batb": [[0, 1.44, 744.07]], "batl": [[0, 1.45, 636.69]]}, {"timestamp": 1632579815757, "ltp": 1.45, "tv": 53046.14, "trd": [[1.45, 1500.19]], "batb": NaN, "batl": [[0, 1.45, 708.15]]}, {"timestamp": 1632579816750, "ltp": 1.45, "tv": 53048.94, "trd": [[1.45, 1502.98]], "batb": NaN, "batl": [[0, 1.45, 706.75]]}, {"timestamp": 1632579818794, "ltp": 1.45, "tv": 53084.94, "trd": [[1.45, 1538.98]], "batb": [[0, 1.44, 745.83]], "batl": [[0, 1.45, 688.75]]}, {"timestamp": 1632579819759, "ltp": 1.44, "tv": 53615.89, "trd": [[1.44, 727.51]], "batb": [[0, 1.44, 204.33], [1, 1.43, 230.6], [2, 1.42, 12.77]], "batl": [[0, 1.48, 46.65], [1, 1.5, 191.93], [2, 1.51, 220.25]]}, {"timestamp": 1632579820659, "ltp": 1.44, "tv": 53615.89, "trd": NaN, "batb": [[0, 1.44, 197.33], [2, 1.42, 5.77]], "batl": NaN}, {"timestamp": 1632579821367, "ltp": 1.44, "tv": 53615.89, "trd": NaN, "batb": [[0, 1.44, 197.68]], "batl": NaN}, {"timestamp": 1632579822475, "ltp": 1.44, "tv": 53629.1, "trd": [[1.44, 740.02], [1.45, 1539.68]], "batb": [[0, 1.44, 191.07], [1, 1.43, 230.25]], "batl": [[1, 1.49, 628.29], [2, 1.5, 757.86]]}, {"timestamp": 1632579823753, "ltp": 1.44, "tv": 53629.1, "trd": NaN, "batb": NaN, "batl": [[0, 1.47, 20], [1, 1.48, 46.65], [2, 1.49, 46.5]]}, {"timestamp": 1632579824772, "ltp": 1.44, "tv": 53629.1, "trd": NaN, "batb": [[1, 1.43, 228.85]], "batl": NaN}, {"timestamp": 1632579825650, "ltp": 1.44, "tv": 53629.1, "trd": NaN, "batb": NaN, "batl": [[0, 1.46, 40.25], [1, 1.47, 20], [2, 1.48, 60.29]]}, {"timestamp": 1632579826755, "ltp": 1.44, "tv": 53629.1, "trd": NaN, "batb": [[0, 1.45, 2.88], [1, 1.44, 191.07], [2, 1.43, 228.85]], "batl": [[0, 1.47, 20], [1, 1.48, 60.29], [2, 1.49, 46.5]]}, {"timestamp": 1632579827642, "ltp": 1.44, "tv": 53727.75, "trd": [[1.44, 832.91], [1.45, 1545.44]], "batb": [[0, 1.44, 144.63], [1, 1.43, 228.85], [2, 1.42, 5.77]], "batl": [[0, 1.47, 40]]}, {"timestamp": 1632579828077, "ltp": 1.44, "tv": 53727.75, "trd": NaN, "batb": NaN, "batl": [[0, 1.45, 1009.46], [1, 1.46, 628.54], [2, 1.47, 40]]}, {"timestamp": 1632579829740, "ltp": 1.44, "tv": 53727.75, "trd": NaN, "batb": NaN, "batl": [[2, 1.47, 225]]}, {"timestamp": 1632579830776, "ltp": 1.44, "tv": 54307.29, "trd": [[1.44, 853.38], [1.45, 2104.52]], "batb": [[0, 1.44, 134.39]], "batl": [[0, 1.45, 729.92]]}, {"timestamp": 1632579831780, "ltp": 1.44, "tv": 54307.29, "trd": NaN, "batb": NaN, "batl": [[2, 1.47, 40]]}, {"timestamp": 1632579832737, "ltp": 1.44, "tv": 54307.29, "trd": NaN, "batb": NaN, "batl": [[0, 1.47, 40], [1, 1.48, 60.29], [2, 1.49, 46.5]]}, {"timestamp": 1632579833351, "ltp": 1.45, "tv": 54322.38, "trd": [[1.45, 2119.6]], "batb": NaN, "batl": NaN}, {"timestamp": 1632579834554, "ltp": 1.47, "tv": 54324.48, "trd": [[1.47, 1510.6]], "batb": NaN, "batl": [[0, 1.47, 38.95]]}, {"timestamp": 1632579835092, "ltp": 1.47, "tv": 54324.48, "trd": NaN, "batb": NaN, "batl": [[2, 1.49, 513.86]]}, {"timestamp": 1632579836752, "ltp": 1.47, "tv": 54351.76, "trd": [[1.47, 1537.88]], "batb": [[0, 1.45, 26.55], [1, 1.44, 134.39], [2, 1.43, 228.85]], "batl": [[0, 1.47, 25.31]]}, {"timestamp": 1632579837758, "ltp": 1.47, "tv": 54351.76, "trd": NaN, "batb": [[0, 1.45, 142.28]], "batl": NaN}, {"timestamp": 1632579839683, "ltp": 1.45, "tv": 54370.62, "trd": [[1.45, 2138.46]], "batb": [[0, 1.45, 132.85]], "batl": NaN}, {"timestamp": 1632579840462, "ltp": 1.45, "tv": 54371.32, "trd": [[1.45, 2139.16]], "batb": [[0, 1.45, 136.01]], "batl": NaN}, {"timestamp": 1632579841695, "ltp": 1.47, "tv": 54421.94, "trd": [[1.47, 1588.5]], "batb": [[0, 1.46, 458.56], [1, 1.45, 135.66], [2, 1.44, 2356.39]], "batl": [[0, 1.48, 60.29], [1, 1.49, 513.86], [2, 1.5, 757.82]]}, {"timestamp": 1632579844796, "ltp": 1.47, "tv": 54421.94, "trd": NaN, "batb": [[1, 1.45, 1069.02], [2, 1.44, 3032.48]], "batl": NaN}, {"timestamp": 1632579845810, "ltp": 1.47, "tv": 54421.94, "trd": NaN, "batb": [[0, 1.47, 8.03], [1, 1.46, 458.56], [2, 1.45, 1069.02]], "batl": NaN}, {"timestamp": 1632579848707, "ltp": 1.48, "tv": 54595.26, "trd": [[1.48, 2022.13]], "batb": [[2, 1.45, 1068.16]], "batl": [[0, 1.48, 7]]}, {"timestamp": 1632579849509, "ltp": 1.48, "tv": 54595.26, "trd": NaN, "batb": [[0, 1.47, 14.03], [1, 1.46, 465.56]], "batl": NaN}, {"timestamp": 1632579850201, "ltp": 1.46, "tv": 54906.2, "trd": [[1.46, 300.98], [1.47, 1616.55]], "batb": [[0, 1.46, 585.33], [1, 1.45, 1068.16], [2, 1.44, 1349.51]], "batl": [[0, 1.48, 264.68]]}, {"timestamp": 1632579851806, "ltp": 1.46, "tv": 54906.2, "trd": NaN, "batb": [[0, 1.47, 253.59], [1, 1.46, 268.21], [2, 1.45, 1068.16]], "batl": [[0, 1.48, 257.68], [1, 1.49, 770.04]]}, {"timestamp": 1632579851869, "ltp": 1.46, "tv": 54906.2, "trd": NaN, "batb": NaN, "batl": [[1, 1.49, 764.04]]}, {"timestamp": 1632579853726, "ltp": 1.46, "tv": 54906.2, "trd": NaN, "batb": [[0, 1.46, 268.21], [1, 1.45, 1068.16], [2, 1.44, 1379.93]], "batl": [[0, 1.48, 807.95], [1, 1.49, 1275.74]]}, {"timestamp": 1632579854407, "ltp": 1.48, "tv": 54918.9, "trd": [[1.48, 2034.83]], "batb": [[0, 1.46, 694.2], [1, 1.45, 1628.71]], "batl": [[0, 1.48, 801.6]]}, {"timestamp": 1632579858806, "ltp": 1.48, "tv": 54918.9, "trd": NaN, "batb": [[0, 1.45, 1063.16], [1, 1.44, 1373.93], [2, 1.43, 215.57]], "batl": [[0, 1.48, 168], [1, 1.49, 467.36], [2, 1.5, 565.89]]}, {"timestamp": 1632579859797, "ltp": 1.48, "tv": 54918.9, "trd": NaN, "batb": [[0, 1.45, 16.77], [1, 1.44, 158.05]], "batl": [[0, 1.51, 28.5], [1, 1.53, 43.5], [2, 1.54, 161.82]]}, {"timestamp": 1632579860794, "ltp": 1.48, "tv": 54918.9, "trd": NaN, "batb": [[0, 1.48, 11.27], [1, 1.45, 16.77], [2, 1.44, 158.05]], "batl": NaN}, {"timestamp": 1632579861713, "ltp": 1.48, "tv": 54918.9, "trd": NaN, "batb": [[0, 1.48, 12.22]], "batl": [[0, 1.51, 33.5]]}, {"timestamp": 1632579862754, "ltp": 1.48, "tv": 54918.9, "trd": NaN, "batb": NaN, "batl": [[0, 1.51, 5]]}, {"timestamp": 1632579864807, "ltp": 1.48, "tv": 54918.9, "trd": NaN, "batb": [[0, 1.48, 16.08]], "batl": NaN}, {"timestamp": 1632579865531, "ltp": 1.48, "tv": 54951.06, "trd": [[1.48, 2066.99]], "batb": [[0, 1.45, 16.77], [1, 1.44, 158.05], [2, 1.43, 215.57]], "batl": [[0, 1.51, 52.5]]}, {"timestamp": 1632579866510, "ltp": 1.47, "tv": 54986.47, "trd": [[1.47, 1651.96]], "batb": NaN, "batl": NaN}, {"timestamp": 1632579867824, "ltp": 1.47, "tv": 54986.47, "trd": NaN, "batb": [[0, 1.48, 2.55], [1, 1.45, 503.22], [2, 1.44, 834.78]], "batl": [[0, 1.49, 996.28], [1, 1.5, 562.34], [2, 1.51, 52.5]]}, {"timestamp": 1632579870331, "ltp": 1.49, "tv": 55015.73, "trd": [[1.49, 2228.39]], "batb": [[1, 1.45, 16.77], [2, 1.44, 158.05]], "batl": [[0, 1.51, 52.5], [1, 1.53, 43.5], [2, 1.54, 161.82]]}, {"timestamp": 1632579871710, "ltp": 1.51, "tv": 55090.95, "trd": [[1.48, 2072.08], [1.51, 84.12]], "batb": [[0, 1.45, 16.77], [1, 1.44, 158.05], [2, 1.43, 215.57]], "batl": [[0, 1.49, 239]]}, {"timestamp": 1632579872630, "ltp": 1.51, "tv": 55090.95, "trd": NaN, "batb": [[0, 1.48, 88.06], [1, 1.45, 16.77], [2, 1.44, 158.05]], "batl": [[0, 1.53, 43.5], [1, 1.54, 161.82], [2, 1.55, 165.24]]}, {"timestamp": 1632579873772, "ltp": 1.48, "tv": 55099.56, "trd": [[1.48, 2078.94], [1.51, 85.88]], "batb": [[0, 1.48, 84.63]], "batl": [[0, 1.53, 803.12], [1, 1.54, 670.56]]}, {"timestamp": 1632579874821, "ltp": 1.48, "tv": 55209.68, "trd": [[1.48, 2189.05]], "batb": [[0, 1.48, 29.58]], "batl": [[0, 1.52, 6], [1, 1.53, 803.12], [2, 1.54, 670.56]]}, {"timestamp": 1632579876642, "ltp": 1.48, "tv": 55209.68, "trd": NaN, "batb": [[0, 1.49, 69.85], [1, 1.48, 29.58], [2, 1.45, 16.77]], "batl": [[0, 1.51, 5], [1, 1.52, 6], [2, 1.53, 803.12]]}, {"timestamp": 1632579877647, "ltp": 1.5, "tv": 55211.28, "trd": [[1.5, 861.72]], "batb": NaN, "batl": NaN}, {"timestamp": 1632579878820, "ltp": 1.44, "tv": 55835.04, "trd": [[1.44, 1180.79], [1.45, 2172.7], [1.47, 1715.91], [1.48, 2248.21], [1.49, 2368.09]], "batb": [[0, 1.43, 215.57], [1, 1.42, 227.69], [2, 1.41, 1313.46]], "batl": [[2, 1.54, 20]]}, {"timestamp": 1632579879424, "ltp": 1.44, "tv": 55835.04, "trd": NaN, "batb": [[0, 1.42, 227.69], [1, 1.41, 1313.46], [2, 1.4, 1408.97]], "batl": [[0, 1.45, 432.84], [1, 1.46, 2222], [2, 1.51, 5]]}, {"timestamp": 1632579880754, "ltp": 1.44, "tv": 55835.04, "trd": NaN, "batb": [[0, 1.42, 30.71]], "batl": [[0, 1.45, 470.54], [1, 1.46, 3.51], [2, 1.47, 1170.91]]}, {"timestamp": 1632579881722, "ltp": 1.45, "tv": 55937.16, "trd": [[1.45, 2274.81]], "batb": [[2, 1.4, 1408.8]], "batl": [[0, 1.45, 1138.31], [1, 1.46, 633.05]]}, {"timestamp": 1632579882736, "ltp": 1.45, "tv": 55937.16, "trd": NaN, "batb": [[0, 1.43, 5], [1, 1.42, 36.71], [2, 1.41, 1319.46]], "batl": NaN}, {"timestamp": 1632579883648, "ltp": 1.45, "tv": 55937.16, "trd": NaN, "batb": NaN, "batl": [[0, 1.45, 2090.57]]}, {"timestamp": 1632579884736, "ltp": 1.45, "tv": 55937.16, "trd": NaN, "batb": NaN, "batl": [[0, 1.44, 6], [1, 1.45, 807.58], [2, 1.46, 1053.04]]}, {"timestamp": 1632579885659, "ltp": 1.45, "tv": 55937.16, "trd": NaN, "batb": [[0, 1.43, 245.6], [1, 1.42, 1231.23]], "batl": [[0, 1.44, 244.89], [1, 1.45, 1044.86]]}, {"timestamp": 1632579886032, "ltp": 1.44, "tv": 55939.26, "trd": [[1.44, 1182.89]], "batb": NaN, "batl": [[0, 1.44, 243.84], [1, 1.45, 1503.42], [2, 1.46, 1556.17]]}, {"timestamp": 1632579887645, "ltp": 1.44, "tv": 56196.38, "trd": [[1.44, 1440.02]], "batb": NaN, "batl": [[0, 1.44, 115.28]]}, {"timestamp": 1632579888664, "ltp": 1.44, "tv": 56199.9, "trd": [[1.44, 1443.54]], "batb": NaN, "batl": [[0, 1.44, 113.52]]}, {"timestamp": 1632579890641, "ltp": 1.44, "tv": 56199.9, "trd": NaN, "batb": [[1, 1.42, 278.97]], "batl": [[0, 1.44, 488.94], [1, 1.45, 1957.69]]}, {"timestamp": 1632579891432, "ltp": 1.44, "tv": 56206.92, "trd": [[1.44, 1450.56]], "batb": NaN, "batl": [[0, 1.44, 485.43]]}, {"timestamp": 1632579892736, "ltp": 1.44, "tv": 56222.86, "trd": [[1.44, 1466.49]], "batb": [[0, 1.43, 396.45]], "batl": [[0, 1.44, 783.46]]}, {"timestamp": 1632579894252, "ltp": 1.44, "tv": 56234.4, "trd": [[1.44, 1478.03]], "batb": NaN, "batl": [[0, 1.44, 777.69]]}, {"timestamp": 1632579895296, "ltp": 1.44, "tv": 56334.4, "trd": [[1.44, 1578.03]], "batb": [[1, 1.42, 272.97], [2, 1.41, 1313.46]], "batl": [[0, 1.44, 727.69]]}, {"timestamp": 1632579896650, "ltp": 1.44, "tv": 56389.78, "trd": [[1.44, 1633.41]], "batb": NaN, "batl": [[0, 1.44, 700]]}, {"timestamp": 1632579897768, "ltp": 1.44, "tv": 56403.66, "trd": [[1.44, 1647.29]], "batb": NaN, "batl": [[0, 1.44, 693.06]]}, {"timestamp": 1632579898754, "ltp": 1.44, "tv": 56403.66, "trd": NaN, "batb": [[0, 1.43, 155.85], [1, 1.42, 38.71]], "batl": [[0, 1.44, 681.42], [1, 1.45, 1720.41]]}, {"timestamp": 1632579899744, "ltp": 1.44, "tv": 56403.66, "trd": NaN, "batb": [[0, 1.43, 150.85], [1, 1.42, 5.77], [2, 1.41, 1]], "batl": [[0, 1.44, 313], [1, 1.46, 3.51], [2, 1.47, 45.5]]}, {"timestamp": 1632579900162, "ltp": 1.43, "tv": 56426.69, "trd": [[1.43, 57.74]], "batb": [[0, 1.44, 4.01], [1, 1.43, 127.82], [2, 1.42, 5.77]], "batl": [[0, 1.46, 3.51], [1, 1.48, 36.62], [2, 1.49, 40.5]]}, {"timestamp": 1632579901714, "ltp": 1.43, "tv": 56426.69, "trd": NaN, "batb": [[0, 1.44, 17.65]], "batl": NaN}, {"timestamp": 1632579902474, "ltp": 1.46, "tv": 56430.2, "trd": [[1.46, 304.49]], "batb": [[0, 1.44, 38.69]], "batl": [[0, 1.48, 36.62], [1, 1.49, 643.91], [2, 1.5, 763.29]]}, {"timestamp": 1632579903768, "ltp": 1.46, "tv": 56430.2, "trd": NaN, "batb": NaN, "batl": [[0, 1.47, 43.5], [1, 1.48, 36.62], [2, 1.49, 643.91]]}, {"timestamp": 1632579904250, "ltp": 1.46, "tv": 56430.2, "trd": NaN, "batb": NaN, "batl": [[0, 1.48, 36.62], [1, 1.49, 643.91], [2, 1.5, 763.29]]}, {"timestamp": 1632579905577, "ltp": 1.46, "tv": 56430.2, "trd": NaN, "batb": NaN, "batl": [[1, 1.49, 40.5], [2, 1.5, 198.41]]}, {"timestamp": 1632579906723, "ltp": 1.46, "tv": 56430.2, "trd": NaN, "batb": [[0, 1.46, 13.04], [1, 1.44, 38.69], [2, 1.43, 127.82]], "batl": NaN}, {"timestamp": 1632579907770, "ltp": 1.46, "tv": 56430.2, "trd": NaN, "batb": NaN, "batl": [[0, 1.47, 45.5], [1, 1.48, 36.62], [2, 1.49, 40.5]]}, {"timestamp": 1632579908483, "ltp": 1.45, "tv": 56945.84, "trd": [[1.45, 2764.37], [1.46, 330.57]], "batb": [[0, 1.44, 38.69], [1, 1.43, 127.82], [2, 1.42, 5.77]], "batl": [[0, 1.45, 496.88], [1, 1.46, 629.54], [2, 1.47, 116.72]]}, {"timestamp": 1632579909755, "ltp": 1.45, "tv": 56945.84, "trd": NaN, "batb": [[0, 1.44, 17.65]], "batl": NaN}, {"timestamp": 1632579910647, "ltp": 1.45, "tv": 57399.86, "trd": [[1.45, 3218.39]], "batb": [[0, 1.44, 13.64]], "batl": [[0, 1.45, 269.87]]}, {"timestamp": 1632579911553, "ltp": 1.45, "tv": 57399.86, "trd": NaN, "batb": [[1, 1.43, 344.78]], "batl": [[0, 1.45, 483.84]]}, {"timestamp": 1632579912649, "ltp": 1.45, "tv": 57399.86, "trd": NaN, "batb": [[0, 1.44, 13.99]], "batl": [[0, 1.45, 633.14]]}, {"timestamp": 1632579913766, "ltp": 1.45, "tv": 57833.86, "trd": [[1.45, 3652.39]], "batb": [[1, 1.43, 127.82], [2, 1.42, 502.12]], "batl": [[0, 1.45, 132.64], [1, 1.48, 36.62], [2, 1.49, 40.5]]}, {"timestamp": 1632579914262, "ltp": 1.45, "tv": 57833.86, "trd": NaN, "batb": [[2, 1.42, 5.77]], "batl": [[0, 1.48, 36.62], [1, 1.49, 40.5], [2, 1.5, 198.41]]}, {"timestamp": 1632579915065, "ltp": 1.45, "tv": 57833.86, "trd": NaN, "batb": [[1, 1.42, 5.77], [2, 1.41, 1]], "batl": NaN}, {"timestamp": 1632579918680, "ltp": 1.45, "tv": 57833.86, "trd": NaN, "batb": [[0, 1.45, 2.65], [1, 1.44, 13.99], [2, 1.42, 5.77]], "batl": [[2, 1.5, 1078.35]]}, {"timestamp": 1632579919389, "ltp": 1.45, "tv": 57833.86, "trd": NaN, "batb": NaN, "batl": [[2, 1.5, 198.41]]}, {"timestamp": 1632579923552, "ltp": 1.45, "tv": 57833.86, "trd": NaN, "batb": [[0, 1.46, 17.26], [1, 1.45, 5.11], [2, 1.44, 13.99]], "batl": NaN}, {"timestamp": 1632579924368, "ltp": 1.44, "tv": 57966.06, "trd": [[1.44, 1726.56], [1.45, 3670.81], [1.46, 365.09]], "batb": [[0, 1.42, 5.77], [1, 1.41, 583.75], [2, 1.4, 767.14]], "batl": [[0, 1.44, 451.89], [1, 1.45, 647.43], [2, 1.48, 36.62]]}, {"timestamp": 1632579925201, "ltp": 1.44, "tv": 57976.06, "trd": [[1.44, 1736.56]], "batb": NaN, "batl": [[0, 1.44, 446.89]]}, {"timestamp": 1632579926777, "ltp": 1.44, "tv": 57976.76, "trd": [[1.44, 1737.26]], "batb": [[1, 1.41, 1], [2, 1.4, 2]], "batl": [[0, 1.48, 229.29], [1, 1.49, 40.5], [2, 1.5, 198.41]]}, {"timestamp": 1632579927825, "ltp": 1.44, "tv": 57976.76, "trd": NaN, "batb": NaN, "batl": [[0, 1.44, 108], [1, 1.48, 36.62], [2, 1.49, 40.5]]}, {"timestamp": 1632579927998, "ltp": 1.44, "tv": 57976.76, "trd": NaN, "batb": NaN, "batl": [[0, 1.48, 36.62], [1, 1.49, 40.5], [2, 1.5, 198.41]]}, {"timestamp": 1632579929738, "ltp": 1.44, "tv": 57976.76, "trd": NaN, "batb": NaN, "batl": [[0, 1.48, 34.86]]}, {"timestamp": 1632579930793, "ltp": 1.48, "tv": 58010.58, "trd": [[1.48, 2282.03]], "batb": NaN, "batl": [[0, 1.48, 17.95]]}, {"timestamp": 1632579931804, "ltp": 1.48, "tv": 58010.58, "trd": NaN, "batb": [[0, 1.46, 432.84], [1, 1.44, 2222.3], [2, 1.42, 5.77]], "batl": [[2, 1.5, 1047.69]]}, {"timestamp": 1632579932822, "ltp": 1.48, "tv": 58010.58, "trd": NaN, "batb": [[0, 1.47, 531.46], [1, 1.46, 1267.26], [2, 1.45, 920.88]], "batl": NaN}, {"timestamp": 1632579933712, "ltp": 1.48, "tv": 58010.58, "trd": NaN, "batb": [[0, 1.47, 1483.72]], "batl": NaN}, {"timestamp": 1632579936732, "ltp": 1.48, "tv": 58010.58, "trd": NaN, "batb": NaN, "batl": [[0, 1.48, 22.95]]}, {"timestamp": 1632579937748, "ltp": 1.48, "tv": 58035.58, "trd": [[1.48, 2307.03]], "batb": [[1, 1.46, 834.42], [2, 1.45, 920.58]], "batl": [[0, 1.48, 5.45], [1, 1.49, 230.09]]}, {"timestamp": 1632579939725, "ltp": 1.48, "tv": 58035.58, "trd": NaN, "batb": [[1, 1.46, 1215.37], [2, 1.45, 1399.14]], "batl": NaN}, {"timestamp": 1632579940622, "ltp": 1.48, "tv": 58035.58, "trd": NaN, "batb": [[0, 1.47, 576.19]], "batl": NaN}, {"timestamp": 1632579941521, "ltp": 1.47, "tv": 58240.28, "trd": [[1.47, 1920.61]], "batb": [[0, 1.47, 473.84]], "batl": [[1, 1.49, 588.01], [2, 1.5, 1457.39]]}, {"timestamp": 1632579941902, "ltp": 1.47, "tv": 58243.5, "trd": [[1.47, 1923.83]], "batb": [[0, 1.47, 472.23]], "batl": NaN}, {"timestamp": 1632579943829, "ltp": 1.47, "tv": 58243.5, "trd": NaN, "batb": NaN, "batl": [[0, 1.48, 374.45]]}, {"timestamp": 1632579946639, "ltp": 1.47, "tv": 58243.5, "trd": NaN, "batb": [[2, 1.45, 1412.78]], "batl": NaN}, {"timestamp": 1632579947731, "ltp": 1.47, "tv": 58246.94, "trd": [[1.47, 1927.27]], "batb": [[0, 1.47, 470.51]], "batl": [[0, 1.48, 590]]}, {"timestamp": 1632579948721, "ltp": 1.48, "tv": 58280.04, "trd": [[1.48, 2340.13]], "batb": NaN, "batl": [[0, 1.48, 573.45]]}, {"timestamp": 1632579949766, "ltp": 1.48, "tv": 58287.06, "trd": [[1.48, 2347.15]], "batb": [[0, 1.46, 568.69], [1, 1.45, 668.49], [2, 1.44, 536.71]], "batl": [[0, 1.48, 354.39], [1, 1.49, 40.5], [2, 1.5, 849.28]]}, {"timestamp": 1632579950721, "ltp": 1.46, "tv": 58356.1, "trd": [[1.46, 434.13]], "batb": [[0, 1.45, 13.64], [1, 1.44, 1.76], [2, 1.43, 204.05]], "batl": [[0, 1.54, 20], [1, 1.56, 190.8], [2, 1.57, 220.86]]}, {"timestamp": 1632579951721, "ltp": 1.47, "tv": 58356.41, "trd": [[1.47, 1927.58]], "batb": NaN, "batl": NaN}, {"timestamp": 1632579953341, "ltp": 1.47, "tv": 58356.41, "trd": NaN, "batb": NaN, "batl": [[0, 1.47, 18.86], [1, 1.54, 884.02], [2, 1.55, 493.78]]}, {"timestamp": 1632579955523, "ltp": 1.47, "tv": 58371.63, "trd": [[1.47, 1942.8]], "batb": NaN, "batl": [[0, 1.47, 11.25]]}, {"timestamp": 1632579963368, "ltp": 1.47, "tv": 58371.63, "trd": NaN, "batb": NaN, "batl": [[0, 1.54, 20], [1, 1.64, 20], [2, 1.69, 1]]}, {"timestamp": 1632579964378, "ltp": 1.45, "tv": 58398.91, "trd": [[1.45, 3698.09]], "batb": [[0, 1.44, 1.76], [1, 1.43, 204.05], [2, 1.42, 232.92]], "batl": [[0, 1.46, 2654.84], [1, 1.54, 20], [2, 1.64, 20]]}, {"timestamp": 1632579966555, "ltp": 1.45, "tv": 58398.91, "trd": NaN, "batb": [[1, 1.42, 232.92], [2, 1.41, 1165.72]], "batl": [[0, 1.45, 992.14], [1, 1.46, 3287.45], [2, 1.47, 1170.91]]}, {"timestamp": 1632579967552, "ltp": 1.44, "tv": 58422.08, "trd": [[1.44, 1739.02], [1.45, 3719.5]], "batb": [[0, 1.42, 232.92], [1, 1.41, 1165.72], [2, 1.4, 1381.38]], "batl": [[0, 1.45, 970.73]]}, {"timestamp": 1632579968756, "ltp": 1.44, "tv": 58449.23, "trd": [[1.44, 1766.17]], "batb": NaN, "batl": [[1, 1.46, 1065.45]]}, {"timestamp": 1632579970763, "ltp": 1.44, "tv": 58449.23, "trd": NaN, "batb": [[0, 1.43, 58.58], [1, 1.42, 232.92], [2, 1.41, 1165.72]], "batl": [[0, 1.44, 223.24], [1, 1.45, 970.73], [2, 1.46, 632.61]]}, {"timestamp": 1632579972755, "ltp": 1.44, "tv": 58449.23, "trd": NaN, "batb": NaN, "batl": [[0, 1.44, 338.24], [1, 1.45, 1364.15], [2, 1.46, 1068.88]]}, {"timestamp": 1632579973350, "ltp": 1.44, "tv": 58449.81, "trd": [[1.44, 1766.75]], "batb": NaN, "batl": [[0, 1.44, 337.95]]}, {"timestamp": 1632579974575, "ltp": 1.44, "tv": 58535.52, "trd": [[1.44, 1852.46]], "batb": NaN, "batl": [[0, 1.44, 295.09]]}, {"timestamp": 1632579975675, "ltp": 1.44, "tv": 58543.55, "trd": [[1.44, 1860.49]], "batb": NaN, "batl": [[0, 1.44, 291.08]]}, {"timestamp": 1632579976064, "ltp": 1.44, "tv": 58553.91, "trd": [[1.44, 1870.85]], "batb": [[1, 1.42, 333.57]], "batl": [[0, 1.44, 285.9]]}, {"timestamp": 1632579977564, "ltp": 1.43, "tv": 58649.99, "trd": [[1.43, 77.74], [1.44, 1946.93]], "batb": [[0, 1.43, 48.58]], "batl": [[0, 1.44, 209.82]]}, {"timestamp": 1632579978485, "ltp": 1.43, "tv": 58649.99, "trd": NaN, "batb": [[0, 1.43, 128.58]], "batl": [[1, 1.45, 1317.67]]}, {"timestamp": 1632579979604, "ltp": 1.44, "tv": 58650.59, "trd": [[1.44, 1947.53]], "batb": NaN, "batl": [[0, 1.44, 674.08]]}, {"timestamp": 1632579980686, "ltp": 1.43, "tv": 58650.71, "trd": [[1.43, 77.86]], "batb": [[0, 1.43, 128.46]], "batl": NaN}, {"timestamp": 1632579981315, "ltp": 1.44, "tv": 58660.43, "trd": [[1.44, 1957.25]], "batb": NaN, "batl": [[0, 1.44, 669.22]]}, {"timestamp": 1632579982381, "ltp": 1.43, "tv": 58682.39, "trd": [[1.43, 99.82]], "batb": [[0, 1.43, 37.48]], "batl": NaN}, {"timestamp": 1632579983796, "ltp": 1.44, "tv": 58733.32, "trd": [[1.44, 2008.17]], "batb": NaN, "batl": [[0, 1.44, 643.76]]}, {"timestamp": 1632579985770, "ltp": 1.43, "tv": 58741.26, "trd": [[1.43, 99.99], [1.44, 2015.95]], "batb": [[0, 1.43, 37.4]], "batl": [[0, 1.44, 635.98]]}, {"timestamp": 1632579986608, "ltp": 1.43, "tv": 58741.26, "trd": NaN, "batb": [[0, 1.42, 5.77], [1, 1.41, 1], [2, 1.4, 2]], "batl": [[0, 1.44, 579.56], [1, 1.48, 42.74], [2, 1.51, 241.01]]}, {"timestamp": 1632579987695, "ltp": 1.44, "tv": 58747.26, "trd": [[1.44, 2021.95]], "batb": NaN, "batl": [[0, 1.44, 461.56]]}, {"timestamp": 1632579988585, "ltp": 1.43, "tv": 58763.5, "trd": [[1.43, 111.53], [1.44, 2026.65]], "batb": NaN, "batl": [[0, 1.43, 23.52], [1, 1.44, 459.21], [2, 1.48, 42.74]]}, {"timestamp": 1632579990172, "ltp": 1.44, "tv": 58888.67, "trd": [[1.43, 135.05], [1.44, 2128.31]], "batb": NaN, "batl": [[0, 1.44, 357.56], [1, 1.48, 42.74], [2, 1.5, 698.17]]}, {"timestamp": 1632579991689, "ltp": 1.44, "tv": 58892.19, "trd": [[1.44, 2131.82]], "batb": NaN, "batl": [[0, 1.44, 355.8]]}, {"timestamp": 1632579994498, "ltp": 1.44, "tv": 59247.71, "trd": [[1.44, 2487.34]], "batb": NaN, "batl": [[0, 1.44, 178.04]]}, {"timestamp": 1632579995789, "ltp": 1.44, "tv": 59267.61, "trd": [[1.44, 2507.25]], "batb": NaN, "batl": [[0, 1.44, 168.09]]}, {"timestamp": 1632579997799, "ltp": 1.44, "tv": 59271.83, "trd": [[1.44, 2511.46]], "batb": [[1, 1.41, 181.85]], "batl": [[0, 1.44, 165.98]]}, {"timestamp": 1632579998188, "ltp": 1.44, "tv": 59271.83, "trd": NaN, "batb": [[1, 1.41, 1]], "batl": NaN}, {"timestamp": 1632579999806, "ltp": 1.44, "tv": 59599.82, "trd": [[1.44, 2839.46]], "batb": [[0, 1.46, 11775.84], [1, 1.45, 271.18], [2, 1.43, 2222]], "batl": [[0, 1.5, 698.17], [1, 1.51, 788.47], [2, 1.52, 217.2]]}, {"timestamp": 1632580000514, "ltp": 1.44, "tv": 59599.82, "trd": NaN, "batb": [[0, 1.46, 11738.58], [2, 1.43, 2222.7]], "batl": NaN}, {"timestamp": 1632580001827, "ltp": 1.46, "tv": 59634.88, "trd": [[1.46, 469.19]], "batb": [[0, 1.46, 11721.05], [1, 1.42, 6.47], [2, 1.41, 1]], "batl": NaN}, {"timestamp": 1632580002715, "ltp": 1.46, "tv": 59634.88, "trd": NaN, "batb": [[1, 1.44, 11.22], [2, 1.42, 5.77]], "batl": [[0, 1.48, 37.99], [1, 1.49, 7], [2, 1.5, 698.17]]}, {"timestamp": 1632580003098, "ltp": 1.46, "tv": 59634.88, "trd": NaN, "batb": [[0, 1.48, 13.64], [1, 1.46, 11721.05], [2, 1.44, 11.22]], "batl": [[0, 1.49, 7], [1, 1.5, 698.17], [2, 1.51, 788.47]]}, {"timestamp": 1632580004789, "ltp": 1.5, "tv": 59653.12, "trd": [[1.49, 2375.09], [1.5, 872.96]], "batb": [[0, 1.48, 20.64], [1, 1.46, 821.97], [2, 1.45, 656.16]], "batl": [[0, 1.5, 686.93], [1, 1.51, 788.47], [2, 1.52, 1349.6]]}, {"timestamp": 1632580005790, "ltp": 1.5, "tv": 59653.12, "trd": NaN, "batb": [[1, 1.46, 1340.61]], "batl": [[0, 1.5, 709.43]]}, {"timestamp": 1632580006804, "ltp": 1.5, "tv": 59653.12, "trd": NaN, "batb": [[1, 1.47, 10], [2, 1.46, 1380.47]], "batl": [[0, 1.49, 1085.11], [1, 1.5, 709.43], [2, 1.51, 788.47]]}, {"timestamp": 1632580008814, "ltp": 1.49, "tv": 59653.93, "trd": [[1.49, 2375.89]], "batb": [[1, 1.47, 914.26]], "batl": [[0, 1.49, 1084.71], [1, 1.5, 935.08]]}, {"timestamp": 1632580009319, "ltp": 1.49, "tv": 59653.93, "trd": NaN, "batb": [[1, 1.47, 1490.44]], "batl": [[0, 1.49, 1310.88], [1, 1.5, 1337.93], [2, 1.51, 1326.74]]}, {"timestamp": 1632580010390, "ltp": 1.48, "tv": 59758.58, "trd": [[1.48, 2431.79], [1.49, 2395.91]], "batb": [[0, 1.47, 1490.44], [1, 1.46, 1380.47], [2, 1.45, 656.16]], "batl": [[0, 1.48, 429.42], [1, 1.49, 1300.87], [2, 1.5, 1337.93]]}, {"timestamp": 1632580011700, "ltp": 1.48, "tv": 59758.58, "trd": NaN, "batb": [[0, 1.47, 2442.7], [1, 1.46, 1815.04], [2, 1.45, 1233.09]], "batl": [[1, 1.49, 1557.87]]}, {"timestamp": 1632580012807, "ltp": 1.48, "tv": 59758.58, "trd": NaN, "batb": NaN, "batl": [[0, 1.48, 431.02]]}, {"timestamp": 1632580013529, "ltp": 1.48, "tv": 59758.83, "trd": [[1.48, 2432.05]], "batb": NaN, "batl": [[0, 1.48, 430.9]]}, {"timestamp": 1632580014613, "ltp": 1.48, "tv": 59795.76, "trd": [[1.47, 1963.93], [1.48, 2447.85]], "batb": [[0, 1.47, 2432.14]], "batl": [[0, 1.48, 498.11]]}, {"timestamp": 1632580016817, "ltp": 1.47, "tv": 62496.77, "trd": [[1.47, 4664.93]], "batb": [[0, 1.47, 129.37], [1, 1.46, 1721.88]], "batl": [[0, 1.48, 498.46], [1, 1.49, 1912.27], [2, 1.5, 1716.77]]}, {"timestamp": 1632580017749, "ltp": 1.47, "tv": 62496.77, "trd": NaN, "batb": NaN, "batl": [[0, 1.48, 533.52]]}, {"timestamp": 1632580018448, "ltp": 1.47, "tv": 62496.77, "trd": NaN, "batb": NaN, "batl": [[0, 1.48, 460.39], [2, 1.5, 1723.08]]}, {"timestamp": 1632580018938, "ltp": 1.48, "tv": 62499.57, "trd": [[1.48, 2450.65]], "batb": NaN, "batl": [[0, 1.48, 458.99]]}, {"timestamp": 1632580020827, "ltp": 1.48, "tv": 62500.34, "trd": [[1.48, 2451.42]], "batb": [[1, 1.46, 2040.79]], "batl": [[0, 1.48, 458.61]]}, {"timestamp": 1632580021616, "ltp": 1.47, "tv": 62646.6, "trd": [[1.47, 4811.2]], "batb": [[0, 1.47, 56.24], [1, 1.46, 1566.36], [2, 1.45, 656.16]], "batl": [[0, 1.48, 459.31], [1, 1.49, 1557.87], [2, 1.5, 941.39]]}, {"timestamp": 1632580022829, "ltp": 1.47, "tv": 62646.6, "trd": NaN, "batb": [[0, 1.44, 15.03], [1, 1.42, 257.89], [2, 1.41, 883.69]], "batl": [[0, 1.48, 210.39], [1, 1.49, 1074.7], [2, 1.5, 6.31]]}, {"timestamp": 1632580023753, "ltp": 1.48, "tv": 62667.64, "trd": [[1.48, 2472.46]], "batb": NaN, "batl": [[0, 1.48, 200.39], [1, 1.5, 6.31], [2, 1.51, 40.5]]}, {"timestamp": 1632580024830, "ltp": 1.48, "tv": 62667.64, "trd": NaN, "batb": [[2, 1.41, 1516.39]], "batl": [[0, 1.48, 199.69]]}, {"timestamp": 1632580025723, "ltp": 1.48, "tv": 62675.67, "trd": [[1.47, 4812.12], [1.48, 2479.57]], "batb": [[2, 1.41, 879.97]], "batl": [[0, 1.48, 192.06]]}, {"timestamp": 1632580026739, "ltp": 1.48, "tv": 62867.73, "trd": [[1.48, 2671.63]], "batb": NaN, "batl": [[0, 1.5, 6.31], [1, 1.53, 42.5], [2, 1.55, 155.78]]}, {"timestamp": 1632580027720, "ltp": 1.48, "tv": 62999.21, "trd": [[1.48, 2803.11]], "batb": NaN, "batl": [[0, 1.47, 49.37], [1, 1.5, 6.31], [2, 1.53, 42.5]]}, {"timestamp": 1632580028529, "ltp": 1.47, "tv": 63003.01, "trd": [[1.47, 4815.91]], "batb": NaN, "batl": [[0, 1.47, 292.42]]}, {"timestamp": 1632580029733, "ltp": 1.47, "tv": 63021.27, "trd": [[1.47, 4834.17]], "batb": [[0, 1.45, 695.49], [1, 1.44, 690.78], [2, 1.42, 257.89]], "batl": [[0, 1.46, 361.7], [1, 1.47, 274.17], [2, 1.49, 789.26]]}, {"timestamp": 1632580030736, "ltp": 1.46, "tv": 63161.46, "trd": [[1.46, 609.39]], "batb": [[0, 1.45, 734.02]], "batl": [[0, 1.46, 61.7]]}, {"timestamp": 1632580031754, "ltp": 1.46, "tv": 63164.98, "trd": [[1.46, 612.9]], "batb": NaN, "batl": [[0, 1.47, 386.17], [1, 1.48, 1.76]]}, {"timestamp": 1632580032246, "ltp": 1.46, "tv": 63164.98, "trd": NaN, "batb": [[0, 1.45, 962.11]], "batl": [[0, 1.47, 736.92]]}, {"timestamp": 1632580033266, "ltp": 1.46, "tv": 63164.98, "trd": NaN, "batb": NaN, "batl": [[0, 1.46, 347.56], [1, 1.47, 736.92], [2, 1.48, 1.76]]}, {"timestamp": 1632580034753, "ltp": 1.46, "tv": 63164.98, "trd": NaN, "batb": NaN, "batl": [[0, 1.47, 528.75], [1, 1.48, 1.76], [2, 1.49, 789.26]]}, {"timestamp": 1632580035265, "ltp": 1.47, "tv": 63167.51, "trd": [[1.47, 4836.71]], "batb": [[0, 1.45, 266.62], [1, 1.44, 15.03]], "batl": [[0, 1.47, 527.48], [2, 1.5, 37.86]]}, {"timestamp": 1632580037596, "ltp": 1.47, "tv": 63167.51, "trd": NaN, "batb": [[0, 1.46, 27.43]], "batl": [[0, 1.47, 176.73], [2, 1.5, 6.31]]}, {"timestamp": 1632580038247, "ltp": 1.47, "tv": 63167.51, "trd": NaN, "batb": NaN, "batl": [[0, 1.47, 64.73]]}, {"timestamp": 1632580039298, "ltp": 1.47, "tv": 63168.25, "trd": [[1.47, 4837.44]], "batb": NaN, "batl": [[0, 1.47, 63.99]]}, {"timestamp": 1632580040890, "ltp": 1.46, "tv": 63184.19, "trd": [[1.46, 628.84]], "batb": [[0, 1.46, 19.46]], "batl": NaN}, {"timestamp": 1632580043771, "ltp": 1.47, "tv": 63187.71, "trd": [[1.47, 4840.96]], "batb": [[0, 1.44, 15.03], [1, 1.42, 257.89], [2, 1.41, 1512.67]], "batl": [[0, 1.47, 62.24]]}, {"timestamp": 1632580044792, "ltp": 1.47, "tv": 63187.71, "trd": NaN, "batb": NaN, "batl": [[0, 1.45, 2222], [1, 1.47, 62.24], [2, 1.48, 1.76]]}, {"timestamp": 1632580045649, "ltp": 1.44, "tv": 63217.86, "trd": [[1.44, 2869.52], [1.45, 3719.59]], "batb": [[0, 1.42, 257.89], [1, 1.41, 1512.67], [2, 1.4, 994.23]], "batl": [[0, 1.44, 5992.05], [1, 1.45, 2221.91], [2, 1.46, 432.84]]}, {"timestamp": 1632580046651, "ltp": 1.44, "tv": 63223.75, "trd": [[1.44, 2875.41]], "batb": [[0, 1.42, 5.77]], "batl": [[0, 1.44, 564.03], [1, 1.45, 828.49], [2, 1.46, 439.84]]}, {"timestamp": 1632580047731, "ltp": 1.44, "tv": 63223.75, "trd": NaN, "batb": NaN, "batl": [[1, 1.45, 647.64]]}, {"timestamp": 1632580048766, "ltp": 1.44, "tv": 63348.4, "trd": [[1.44, 3000.06]], "batb": NaN, "batl": [[0, 1.44, 439.38]]}, {"timestamp": 1632580049673, "ltp": 1.44, "tv": 63348.4, "trd": NaN, "batb": [[0, 1.42, 374.47], [1, 1.41, 1518.67]], "batl": NaN}, {"timestamp": 1632580050780, "ltp": 1.44, "tv": 63349.98, "trd": [[1.44, 3001.64]], "batb": [[0, 1.42, 1241.63]], "batl": [[0, 1.44, 737.56], [1, 1.45, 1026.1], [2, 1.46, 643.68]]}, {"timestamp": 1632580051798, "ltp": 1.44, "tv": 63349.98, "trd": NaN, "batb": [[0, 1.42, 1306.99]], "batl": [[2, 1.46, 523.61]]}, {"timestamp": 1632580052780, "ltp": 1.43, "tv": 63350.25, "trd": [[1.43, 135.32]], "batb": [[0, 1.42, 1234.63], [1, 1.41, 1512.67]], "batl": [[0, 1.43, 903.99], [1, 1.44, 732.56], [2, 1.45, 1026.1]]}, {"timestamp": 1632580053188, "ltp": 1.43, "tv": 64828.1, "trd": [[1.43, 1613.16]], "batb": NaN, "batl": [[0, 1.43, 526.77]]}, {"timestamp": 1632580054264, "ltp": 1.43, "tv": 65001.88, "trd": [[1.43, 1786.95]], "batb": NaN, "batl": [[0, 1.43, 439.87], [1, 1.44, 755.06]]}, {"timestamp": 1632580055519, "ltp": 1.43, "tv": 65002.93, "trd": [[1.43, 1787.99]], "batb": NaN, "batl": [[0, 1.43, 439.35]]}, {"timestamp": 1632580056783, "ltp": 1.43, "tv": 65002.93, "trd": NaN, "batb": NaN, "batl": [[0, 1.43, 737.97]]}, {"timestamp": 1632580057793, "ltp": 1.43, "tv": 65002.93, "trd": NaN, "batb": NaN, "batl": [[0, 1.43, 1075.97]]}, {"timestamp": 1632580058489, "ltp": 1.43, "tv": 65182.64, "trd": [[1.43, 1967.71]], "batb": NaN, "batl": [[0, 1.43, 986.11]]}, {"timestamp": 1632580060094, "ltp": 1.42, "tv": 65242.64, "trd": [[1.42, 88]], "batb": [[0, 1.42, 1204.63]], "batl": NaN}, {"timestamp": 1632580060997, "ltp": 1.43, "tv": 65277.7, "trd": [[1.43, 2002.77]], "batb": NaN, "batl": [[0, 1.43, 968.58]]}, {"timestamp": 1632580062400, "ltp": 1.43, "tv": 65312.76, "trd": [[1.43, 2037.83]], "batb": NaN, "batl": [[0, 1.43, 951.05]]}, {"timestamp": 1632580064503, "ltp": 1.43, "tv": 65377.23, "trd": [[1.43, 2102.3]], "batb": NaN, "batl": [[0, 1.43, 886.75]]}, {"timestamp": 1632580065419, "ltp": 1.43, "tv": 65398.18, "trd": [[1.43, 2123.24]], "batb": NaN, "batl": [[0, 1.43, 865.8]]}, {"timestamp": 1632580066830, "ltp": 1.43, "tv": 66693.3, "trd": [[1.43, 3418.37]], "batb": NaN, "batl": [[0, 1.43, 206.48]]}, {"timestamp": 1632580067818, "ltp": 1.43, "tv": 66697.52, "trd": [[1.43, 3422.59]], "batb": [[0, 1.42, 1060.88], [1, 1.41, 1], [2, 1.4, 2]], "batl": [[0, 1.44, 22.5], [1, 1.47, 26.5], [2, 1.48, 28.5]]}, {"timestamp": 1632580068762, "ltp": 1.43, "tv": 66697.52, "trd": NaN, "batb": [[0, 1.43, 4.29]], "batl": [[0, 1.47, 26.5], [1, 1.48, 28.5], [2, 1.5, 33.18]]}, {"timestamp": 1632580069422, "ltp": 1.43, "tv": 66697.52, "trd": NaN, "batb": NaN, "batl": [[0, 1.48, 1.76], [1, 1.5, 33.18], [2, 1.51, 252.76]]}, {"timestamp": 1632580070824, "ltp": 1.43, "tv": 66697.52, "trd": NaN, "batb": NaN, "batl": [[1, 1.5, 894.5], [2, 1.51, 799.02]]}, {"timestamp": 1632580071801, "ltp": 1.43, "tv": 66705.62, "trd": [[1.43, 3430.69]], "batb": [[0, 1.41, 1.23], [1, 1.4, 2], [2, 1.36, 256.97]], "batl": NaN}, {"timestamp": 1632580072687, "ltp": 1.43, "tv": 66705.62, "trd": NaN, "batb": [[0, 1.43, 17.76], [1, 1.41, 1], [2, 1.4, 2]], "batl": [[0, 1.47, 28.5], [1, 1.48, 1.76], [2, 1.49, 4]]}, {"timestamp": 1632580073755, "ltp": 1.43, "tv": 66705.62, "trd": NaN, "batb": [[0, 1.44, 432.84], [1, 1.43, 2240.11], [2, 1.41, 1]], "batl": [[0, 1.48, 1.76], [1, 1.5, 894.5], [2, 1.51, 799.02]]}, {"timestamp": 1632580075698, "ltp": 1.48, "tv": 66707.38, "trd": [[1.48, 2804.87]], "batb": [[0, 1.46, 14], [1, 1.44, 432.84], [2, 1.43, 2240.11]], "batl": [[0, 1.5, 894.5], [1, 1.51, 799.02], [2, 1.52, 7753.62]]}, {"timestamp": 1632580076809, "ltp": 1.48, "tv": 66707.38, "trd": NaN, "batb": [[0, 1.46, 1093.83], [1, 1.45, 654.69], [2, 1.44, 432.84]], "batl": [[0, 1.49, 90], [1, 1.5, 899.5], [2, 1.51, 799.02]]}, {"timestamp": 1632580077816, "ltp": 1.48, "tv": 67792.49, "trd": [[1.46, 1352.25], [1.48, 3166.58]], "batb": [[0, 1.48, 771.41], [1, 1.46, 725.13], [2, 1.45, 654.69]], "batl": NaN}, {"timestamp": 1632580078730, "ltp": 1.48, "tv": 68164.19, "trd": [[1.48, 3538.28]], "batb": [[0, 1.48, 585.56], [1, 1.46, 524.13], [2, 1.45, 704.8]], "batl": [[1, 1.5, 602.85], [2, 1.51, 252.76]]}, {"timestamp": 1632580079507, "ltp": 1.48, "tv": 68164.19, "trd": NaN, "batb": [[0, 1.46, 524.13], [1, 1.45, 654.69], [2, 1.44, 432.84]], "batl": NaN}, {"timestamp": 1632580080717, "ltp": 1.47, "tv": 68172.31, "trd": [[1.47, 4849.08]], "batb": [[0, 1.47, 331.95], [1, 1.46, 531.13], [2, 1.45, 659.69]], "batl": [[0, 1.48, 331.56], [1, 1.49, 421.5], [2, 1.5, 602.85]]}, {"timestamp": 1632580081826, "ltp": 1.47, "tv": 68172.31, "trd": NaN, "batb": [[0, 1.47, 1597.91], [1, 1.46, 524.13], [2, 1.45, 1069.15]], "batl": [[1, 1.49, 1225.66], [2, 1.5, 597.85]]}, {"timestamp": 1632580082820, "ltp": 1.48, "tv": 68179.31, "trd": [[1.48, 3545.28]], "batb": [[0, 1.47, 2550.17], [1, 1.46, 574.24]], "batl": [[0, 1.48, 413.77], [1, 1.49, 1954.03]]}, {"timestamp": 1632580083634, "ltp": 1.48, "tv": 68203.79, "trd": [[1.48, 3569.76]], "batb": NaN, "batl": [[0, 1.48, 406.53], [1, 1.49, 2496.58]]}, {"timestamp": 1632580085731, "ltp": 1.48, "tv": 68203.79, "trd": NaN, "batb": NaN, "batl": [[0, 1.48, 758.53]]}, {"timestamp": 1632580086739, "ltp": 1.48, "tv": 69706.79, "trd": [[1.47, 6345.08], [1.48, 3576.75]], "batb": [[0, 1.47, 849.91]], "batl": [[0, 1.48, 755.83], [1, 1.49, 1230.62]]}, {"timestamp": 1632580087640, "ltp": 1.48, "tv": 69724.61, "trd": [[1.48, 3594.57]], "batb": NaN, "batl": [[0, 1.48, 746.92]]}, {"timestamp": 1632580088731, "ltp": 1.48, "tv": 69738.6, "trd": [[1.48, 3608.56]], "batb": NaN, "batl": [[0, 1.48, 920.78], [1, 1.49, 866.38]]}, {"timestamp": 1632580089722, "ltp": 1.48, "tv": 69739.18, "trd": [[1.48, 3609.14]], "batb": [[0, 1.47, 1044.47]], "batl": [[0, 1.48, 1282.19]]}, {"timestamp": 1632580090458, "ltp": 1.48, "tv": 69739.18, "trd": NaN, "batb": NaN, "batl": [[0, 1.48, 2005.6]]}, {"timestamp": 1632580091830, "ltp": 1.48, "tv": 69739.18, "trd": NaN, "batb": [[0, 1.47, 849.91], [1, 1.42, 269.12], [2, 1.41, 813.63]], "batl": [[0, 1.48, 1709.48], [1, 1.49, 90], [2, 1.5, 6.31]]}, {"timestamp": 1632580092743, "ltp": 1.48, "tv": 69739.18, "trd": NaN, "batb": [[0, 1.42, 269.12], [1, 1.41, 813.63], [2, 1.4, 324.56]], "batl": [[0, 1.48, 5.92], [1, 1.5, 6.31], [2, 1.51, 400.9]]}, {"timestamp": 1632580093636, "ltp": 1.48, "tv": 69739.76, "trd": [[1.48, 3609.72]], "batb": NaN, "batl": [[0, 1.48, 5.51]]}, {"timestamp": 1632580093940, "ltp": 1.48, "tv": 69739.76, "trd": NaN, "batb": NaN, "batl": [[0, 1.48, 5.86]]}, {"timestamp": 1632580095256, "ltp": 1.48, "tv": 69739.76, "trd": NaN, "batb": [[2, 1.4, 1377.9]], "batl": NaN}, {"timestamp": 1632580096544, "ltp": 1.48, "tv": 69739.76, "trd": NaN, "batb": [[2, 1.4, 324.56]], "batl": NaN}, {"timestamp": 1632580097643, "ltp": 1.48, "tv": 69739.76, "trd": NaN, "batb": NaN, "batl": [[0, 1.47, 1.15], [1, 1.48, 5.51], [2, 1.5, 6.31]]}, {"timestamp": 1632580098736, "ltp": 1.48, "tv": 69739.76, "trd": NaN, "batb": NaN, "batl": [[1, 1.48, 713.22]]}, {"timestamp": 1632580099522, "ltp": 1.47, "tv": 69740.46, "trd": [[1.47, 6345.78]], "batb": NaN, "batl": [[0, 1.47, 136.77]]}, {"timestamp": 1632580100341, "ltp": 1.47, "tv": 69740.46, "trd": NaN, "batb": [[0, 1.44, 1041.68], [1, 1.43, 700.8], [2, 1.42, 268.88]], "batl": [[1, 1.48, 880.96], [2, 1.49, 579.45]]}, {"timestamp": 1632580102341, "ltp": 1.46, "tv": 69773.64, "trd": [[1.46, 1385.43]], "batb": [[1, 1.43, 929.44]], "batl": [[0, 1.46, 325.24], [1, 1.47, 136.77], [2, 1.48, 880.96]]}, {"timestamp": 1632580103752, "ltp": 1.46, "tv": 69773.64, "trd": NaN, "batb": [[1, 1.43, 700.8]], "batl": [[0, 1.47, 136.77], [1, 1.48, 880.96], [2, 1.49, 579.45]]}, {"timestamp": 1632580104747, "ltp": 1.46, "tv": 69773.64, "trd": NaN, "batb": [[0, 1.42, 269.12], [1, 1.41, 813.63], [2, 1.4, 324.56]], "batl": [[0, 1.46, 1.76], [1, 1.47, 136.77], [2, 1.5, 7.11]]}, {"timestamp": 1632580105735, "ltp": 1.46, "tv": 69773.64, "trd": NaN, "batb": NaN, "batl": [[0, 1.46, 1.41]]}, {"timestamp": 1632580106754, "ltp": 1.47, "tv": 69784.84, "trd": [[1.47, 6356.98]], "batb": [[2, 1.4, 1377.9]], "batl": [[0, 1.47, 131.17], [1, 1.5, 7.11], [2, 1.51, 400.9]]}, {"timestamp": 1632580109580, "ltp": 1.47, "tv": 69785.94, "trd": [[1.47, 6358.08]], "batb": [[0, 1.42, 275.12], [1, 1.41, 819.63]], "batl": [[0, 1.47, 130.62]]}, {"timestamp": 1632580110247, "ltp": 1.47, "tv": 69785.94, "trd": NaN, "batb": [[0, 1.43, 1.03], [1, 1.42, 274.88], [2, 1.41, 819.63]], "batl": NaN}, {"timestamp": 1632580111145, "ltp": 1.46, "tv": 69787.54, "trd": [[1.46, 1387.03]], "batb": [[0, 1.42, 275.12], [1, 1.41, 819.63], [2, 1.4, 1377.9]], "batl": [[0, 1.46, 2654.04], [1, 1.47, 130.62], [2, 1.5, 7.11]]}, {"timestamp": 1632580112760, "ltp": 1.46, "tv": 69787.54, "trd": NaN, "batb": NaN, "batl": [[0, 1.44, 7870.74], [1, 1.45, 3956.9], [2, 1.46, 6494.56]]}, {"timestamp": 1632580113825, "ltp": 1.46, "tv": 69787.54, "trd": NaN, "batb": [[0, 1.41, 813.87], [1, 1.4, 1377.9], [2, 1.39, 829.56]], "batl": [[0, 1.45, 197.85], [1, 1.46, 2846.07], [2, 1.47, 322.65]]}, {"timestamp": 1632580114786, "ltp": 1.45, "tv": 69788.22, "trd": [[1.45, 3720.26]], "batb": NaN, "batl": [[0, 1.44, 14.08], [1, 1.45, 1186.73], [2, 1.46, 1585]]}, {"timestamp": 1632580115805, "ltp": 1.44, "tv": 69874.94, "trd": [[1.41, 1.66], [1.43, 3431.15], [1.44, 3086.23]], "batb": [[0, 1.41, 812.8]], "batl": [[0, 1.44, 772.54], [1, 1.45, 1832.66]]}, {"timestamp": 1632580116698, "ltp": 1.44, "tv": 69874.94, "trd": NaN, "batb": NaN, "batl": [[1, 1.45, 1922.66]]}, {"timestamp": 1632580117774, "ltp": 1.44, "tv": 69875.28, "trd": [[1.44, 3086.57]], "batb": [[0, 1.42, 723.41], [1, 1.41, 812.8], [2, 1.4, 1377.9]], "batl": [[0, 1.44, 772.37]]}, {"timestamp": 1632580118813, "ltp": 1.42, "tv": 69877.22, "trd": [[1.42, 89.94]], "batb": [[0, 1.42, 903.29]], "batl": [[1, 1.45, 1832.66]]}, {"timestamp": 1632580119787, "ltp": 1.44, "tv": 69881.44, "trd": [[1.44, 3090.8]], "batb": [[0, 1.42, 1217.32], [1, 1.41, 882.59]], "batl": [[0, 1.43, 779.3], [1, 1.44, 848.25], [2, 1.45, 1832.66]]}, {"timestamp": 1632580120771, "ltp": 1.42, "tv": 69899.82, "trd": [[1.42, 107.65], [1.43, 3431.83]], "batb": [[0, 1.42, 1393.92]], "batl": [[0, 1.43, 1864.08], [1, 1.44, 1191.96]]}, {"timestamp": 1632580121479, "ltp": 1.43, "tv": 69900.52, "trd": [[1.43, 3432.53]], "batb": [[0, 1.42, 1208.46]], "batl": [[0, 1.43, 1863.73]]}, {"timestamp": 1632580122778, "ltp": 1.43, "tv": 69901.19, "trd": [[1.43, 3433.2]], "batb": [[0, 1.42, 1671.31], [1, 1.41, 1435.43]], "batl": [[0, 1.43, 2155.39], [1, 1.44, 1652.23], [2, 1.45, 2254.36]]}, {"timestamp": 1632580123777, "ltp": 1.43, "tv": 69901.19, "trd": NaN, "batb": [[0, 1.42, 1676.31]], "batl": NaN}, {"timestamp": 1632580124692, "ltp": 1.43, "tv": 69901.19, "trd": NaN, "batb": [[1, 1.41, 1365.65]], "batl": [[1, 1.44, 1967.09], [2, 1.45, 2759.62]]}, {"timestamp": 1632580125636, "ltp": 1.43, "tv": 70364.74, "trd": [[1.43, 3896.75]], "batb": NaN, "batl": [[0, 1.43, 1923.62]]}, {"timestamp": 1632580127603, "ltp": 1.43, "tv": 70536.17, "trd": [[1.43, 4068.18]], "batb": [[0, 1.42, 1671.31]], "batl": [[0, 1.43, 1837.9]]}, {"timestamp": 1632580128732, "ltp": 1.43, "tv": 70844.36, "trd": [[1.43, 4376.37]], "batb": NaN, "batl": [[0, 1.43, 1683.8], [1, 1.44, 1574.25]]}, {"timestamp": 1632580129216, "ltp": 1.42, "tv": 70856.4, "trd": [[1.42, 119.68]], "batb": [[0, 1.42, 1665.29]], "batl": [[2, 1.45, 2254.36]]}, {"timestamp": 1632580130590, "ltp": 1.43, "tv": 70866.4, "trd": [[1.43, 4386.37]], "batb": [[0, 1.42, 776.87]], "batl": [[0, 1.43, 412.84]]}, {"timestamp": 1632580131276, "ltp": 1.43, "tv": 70869.92, "trd": [[1.43, 4389.89]], "batb": NaN, "batl": [[0, 1.43, 411.08]]}, {"timestamp": 1632580133806, "ltp": 1.43, "tv": 71632.5, "trd": [[1.43, 5152.47]], "batb": NaN, "batl": [[0, 1.43, 29.79]]}, {"timestamp": 1632580134805, "ltp": 1.43, "tv": 71632.5, "trd": NaN, "batb": [[1, 1.41, 1158.48], [2, 1.4, 1055.34]], "batl": [[2, 1.45, 1067.63]]}, {"timestamp": 1632580135799, "ltp": 1.43, "tv": 71633.9, "trd": [[1.43, 5153.87]], "batb": [[0, 1.4, 2.17], [1, 1.39, 12.1], [2, 1.36, 176.19]], "batl": [[0, 1.44, 90], [1, 1.47, 154.12], [2, 1.48, 114.2]]}, {"timestamp": 1632580136736, "ltp": 1.44, "tv": 71661.18, "trd": [[1.44, 3118.08]], "batb": NaN, "batl": [[0, 1.43, 262.21]]}, {"timestamp": 1632580136996, "ltp": 1.43, "tv": 71664.72, "trd": [[1.43, 5157.41]], "batb": NaN, "batl": [[0, 1.47, 154.12], [1, 1.48, 114.2], [2, 1.49, 13.1]]}, {"timestamp": 1632580138602, "ltp": 1.43, "tv": 71664.72, "trd": NaN, "batb": [[0, 1.43, 8], [1, 1.4, 2.17], [2, 1.39, 12.1]], "batl": [[2, 1.49, 622.01]]}, {"timestamp": 1632580139387, "ltp": 1.44, "tv": 71664.74, "trd": [[1.44, 3118.1]], "batb": [[0, 1.43, 11.51]], "batl": NaN}, {"timestamp": 1632580140104, "ltp": 1.44, "tv": 71664.74, "trd": NaN, "batb": [[2, 1.36, 176.19]], "batl": NaN}, {"timestamp": 1632580141725, "ltp": 1.44, "tv": 71664.74, "trd": NaN, "batb": NaN, "batl": [[0, 1.46, 5], [1, 1.47, 154.12], [2, 1.48, 114.2]]}, {"timestamp": 1632580142828, "ltp": 1.42, "tv": 71702.11, "trd": [[1.4, 9.17], [1.41, 2], [1.42, 124.51], [1.43, 5180.43]], "batb": [[0, 1.36, 176.19], [1, 1.35, 1028.91], [2, 1.34, 335.27]], "batl": [[0, 1.42, 7.93], [1, 1.44, 20.58], [2, 1.46, 1515.68]]}, {"timestamp": 1632580143627, "ltp": 1.42, "tv": 71702.11, "trd": NaN, "batb": NaN, "batl": [[1, 1.46, 10], [2, 1.47, 154.12]]}, {"timestamp": 1632580144613, "ltp": 1.42, "tv": 71717.97, "trd": [[1.42, 140.37]], "batb": [[0, 1.43, 13.59], [1, 1.41, 12.56], [2, 1.36, 176.19]], "batl": [[0, 1.46, 10], [1, 1.47, 154.12], [2, 1.48, 114.2]]}, {"timestamp": 1632580145809, "ltp": 1.43, "tv": 71746.68, "trd": [[1.43, 5209.15]], "batb": [[0, 1.41, 12.56], [1, 1.39, 913.73], [2, 1.38, 822.38]], "batl": [[0, 1.43, 1001.97], [1, 1.44, 663.08], [2, 1.46, 10]]}, {"timestamp": 1632580146813, "ltp": 1.41, "tv": 71774.63, "trd": [[1.41, 27.12], [1.42, 143.2]], "batb": [[0, 1.37, 444.42], [1, 1.36, 176.19], [2, 1.35, 1028.91]], "batl": [[0, 1.41, 416.42], [1, 1.46, 10], [2, 1.47, 154.12]]}, {"timestamp": 1632580147727, "ltp": 1.41, "tv": 71774.63, "trd": NaN, "batb": [[0, 1.36, 176.19], [1, 1.35, 1028.91], [2, 1.34, 335.27]], "batl": [[0, 1.46, 10], [1, 1.47, 154.12], [2, 1.48, 114.2]]}, {"timestamp": 1632580149063, "ltp": 1.46, "tv": 71774.88, "trd": [[1.46, 1387.29]], "batb": NaN, "batl": [[0, 1.46, 9.87]]}, {"timestamp": 1632580151529, "ltp": 1.46, "tv": 71776.4, "trd": [[1.46, 1388.81]], "batb": [[2, 1.34, 1646.86]], "batl": [[0, 1.46, 9.11]]}, {"timestamp": 1632580154053, "ltp": 1.43, "tv": 71778.41, "trd": [[1.43, 5211.15]], "batb": NaN, "batl": [[0, 1.4, 432.84], [1, 1.42, 2222], [2, 1.46, 9.11]]}, {"timestamp": 1632580155818, "ltp": 1.37, "tv": 71781.11, "trd": [[1.37, 2.7]], "batb": [[0, 1.36, 1]], "batl": [[0, 1.37, 47.3], [1, 1.38, 1193.04], [2, 1.39, 773.08]]}, {"timestamp": 1632580156638, "ltp": 1.37, "tv": 71811.98, "trd": [[1.37, 33.57]], "batb": NaN, "batl": [[0, 1.37, 16.43], [2, 1.39, 863.08]]}, {"timestamp": 1632580158815, "ltp": 1.37, "tv": 71815.52, "trd": [[1.37, 37.11]], "batb": NaN, "batl": [[0, 1.38, 1193.04], [1, 1.39, 863.08], [2, 1.4, 432.84]]}, {"timestamp": 1632580159544, "ltp": 1.37, "tv": 71815.52, "trd": NaN, "batb": [[0, 1.36, 63.39], [1, 1.35, 1090.01]], "batl": [[0, 1.37, 68.18], [1, 1.38, 1193.04], [2, 1.39, 773.08]]}, {"timestamp": 1632580160727, "ltp": 1.37, "tv": 71815.52, "trd": NaN, "batb": [[1, 1.35, 1517.04], [2, 1.34, 1712.78]], "batl": [[0, 1.37, 488.98], [1, 1.38, 1260.68]]}, {"timestamp": 1632580161824, "ltp": 1.37, "tv": 71847.1, "trd": [[1.37, 68.69]], "batb": [[0, 1.36, 143.39]], "batl": [[0, 1.37, 473.19]]}, {"timestamp": 1632580162634, "ltp": 1.37, "tv": 71847.1, "trd": NaN, "batb": [[0, 1.36, 544.04]], "batl": [[1, 1.38, 1745.53]]}, {"timestamp": 1632580163819, "ltp": 1.37, "tv": 71854.22, "trd": [[1.37, 75.81]], "batb": NaN, "batl": [[0, 1.37, 466.06]]}, {"timestamp": 1632580164765, "ltp": 1.35, "tv": 72953.04, "trd": [[1.35, 10.74], [1.36, 1088.09]], "batb": [[0, 1.35, 1511.67], [1, 1.34, 1646.86], [2, 1.33, 990.92]], "batl": [[0, 1.37, 525.98], [1, 1.38, 2071.31], [2, 1.39, 1229.92]]}, {"timestamp": 1632580165565, "ltp": 1.37, "tv": 72960.07, "trd": [[1.37, 82.83]], "batb": NaN, "batl": [[0, 1.37, 931.31], [1, 1.38, 2585.58]]}, {"timestamp": 1632580166348, "ltp": 1.37, "tv": 72978.8, "trd": [[1.37, 101.57]], "batb": NaN, "batl": [[0, 1.37, 921.94]]}, {"timestamp": 1632580167831, "ltp": 1.37, "tv": 73078.7, "trd": [[1.37, 201.46]], "batb": [[0, 1.36, 443.13], [1, 1.35, 2061.08], [2, 1.34, 1646.86]], "batl": [[0, 1.37, 872], [1, 1.38, 2526.96]]}, {"timestamp": 1632580168763, "ltp": 1.36, "tv": 73880.28, "trd": [[1.36, 1886.15], [1.37, 204.98]], "batb": [[0, 1.35, 2061.08], [1, 1.34, 1646.86], [2, 1.33, 990.92]], "batl": [[0, 1.36, 635], [1, 1.37, 870.24], [2, 1.38, 2526.96]]}, {"timestamp": 1632580169655, "ltp": 1.36, "tv": 73897.16, "trd": [[1.36, 1903.03]], "batb": NaN, "batl": [[0, 1.36, 626.56]]}, {"timestamp": 1632580170549, "ltp": 1.36, "tv": 74331.6, "trd": [[1.36, 2337.47]], "batb": NaN, "batl": [[0, 1.36, 409.34]]}, {"timestamp": 1632580171647, "ltp": 1.36, "tv": 74332.3, "trd": [[1.36, 2338.17]], "batb": NaN, "batl": [[0, 1.36, 408.99]]}, {"timestamp": 1632580172043, "ltp": 1.36, "tv": 74340.72, "trd": [[1.36, 2346.59]], "batb": NaN, "batl": [[0, 1.36, 404.78]]}, {"timestamp": 1632580175029, "ltp": 1.36, "tv": 74360.72, "trd": [[1.36, 2366.59]], "batb": NaN, "batl": [[0, 1.36, 406.78]]}, {"timestamp": 1632580176725, "ltp": 1.35, "tv": 74579.44, "trd": [[1.35, 214.74], [1.36, 2381.31]], "batb": [[0, 1.35, 1959.08]], "batl": [[0, 1.36, 629.64], [1, 1.37, 810.33]]}, {"timestamp": 1632580177770, "ltp": 1.36, "tv": 74589.44, "trd": [[1.36, 2391.31]], "batb": [[0, 1.35, 1154.59], [1, 1.34, 1311.59]], "batl": [[0, 1.36, 624.64], [1, 1.37, 401.48], [2, 1.38, 1614.94]]}, {"timestamp": 1632580178751, "ltp": 1.36, "tv": 74609.75, "trd": [[1.36, 2411.62]], "batb": [[0, 1.35, 61.1], [1, 1.31, 1], [2, 1.3, 17.53]], "batl": [[0, 1.36, 12], [1, 1.38, 90], [2, 1.41, 43.43]]}, {"timestamp": 1632580179722, "ltp": 1.36, "tv": 74609.75, "trd": NaN, "batb": [[0, 1.31, 1], [1, 1.3, 17.53], [2, 1.28, 279.95]], "batl": [[1, 1.41, 43.43], [2, 1.42, 30.25]]}, {"timestamp": 1632580180739, "ltp": 1.36, "tv": 74609.75, "trd": NaN, "batb": [[0, 1.36, 8.63], [1, 1.31, 1], [2, 1.3, 17.53]], "batl": [[0, 1.41, 10.93], [1, 1.44, 27.58], [2, 1.45, 238.31]]}, {"timestamp": 1632580181763, "ltp": 1.36, "tv": 74609.75, "trd": NaN, "batb": [[0, 1.36, 27.49]], "batl": [[1, 1.44, 950.93], [2, 1.45, 882.87]]}, {"timestamp": 1632580182469, "ltp": 1.36, "tv": 74609.75, "trd": NaN, "batb": [[0, 1.36, 32.41]], "batl": NaN}, {"timestamp": 1632580183646, "ltp": 1.36, "tv": 74657.76, "trd": [[1.36, 2459.63]], "batb": [[0, 1.36, 8.69]], "batl": NaN}, {"timestamp": 1632580185453, "ltp": 1.36, "tv": 74657.76, "trd": NaN, "batb": [[0, 1.36, 5.21]], "batl": [[0, 1.4, 10], [1, 1.41, 10.93], [2, 1.44, 950.93]]}, {"timestamp": 1632580186762, "ltp": 1.36, "tv": 74657.76, "trd": NaN, "batb": NaN, "batl": [[1, 1.41, 42.43], [2, 1.47, 130.62]]}, {"timestamp": 1632580187739, "ltp": 1.36, "tv": 74657.76, "trd": NaN, "batb": [[0, 1.36, 5.04]], "batl": [[0, 1.39, 20], [1, 1.4, 10], [2, 1.41, 10.93]]}, {"timestamp": 1632580188790, "ltp": 1.31, "tv": 74676.63, "trd": [[1.31, 2], [1.33, 5.55], [1.36, 2470.94]], "batb": [[0, 1.3, 17.53], [1, 1.28, 1002.8], [2, 1.27, 2512.68]], "batl": [[0, 1.35, 2222], [1, 1.39, 20], [2, 1.4, 10]]}, {"timestamp": 1632580189787, "ltp": 1.31, "tv": 74676.63, "trd": NaN, "batb": NaN, "batl": [[0, 1.31, 1488.28], [1, 1.32, 2289.11], [2, 1.33, 1282.18]]}, {"timestamp": 1632580190658, "ltp": 1.31, "tv": 74676.63, "trd": NaN, "batb": NaN, "batl": [[0, 1.31, 2440.54]]}, {"timestamp": 1632580193762, "ltp": 1.31, "tv": 74876.63, "trd": [[1.31, 202]], "batb": [[0, 1.3, 26.53], [1, 1.29, 8], [2, 1.28, 1002.8]], "batl": [[0, 1.31, 2349.54]]}, {"timestamp": 1632580194686, "ltp": 1.31, "tv": 75276.63, "trd": [[1.31, 602]], "batb": [[1, 1.29, 812.11]], "batl": [[0, 1.31, 2610.81]]}, {"timestamp": 1632580195797, "ltp": 1.31, "tv": 75281.63, "trd": [[1.31, 607]], "batb": [[1, 1.29, 853.89]], "batl": [[0, 1.31, 2608.31]]}, {"timestamp": 1632580196686, "ltp": 1.31, "tv": 75320.33, "trd": [[1.31, 645.7]], "batb": NaN, "batl": [[0, 1.31, 2588.96], [2, 1.33, 1288.18]]}, {"timestamp": 1632580197827, "ltp": 1.31, "tv": 75320.33, "trd": NaN, "batb": [[1, 1.29, 952.98], [2, 1.28, 1089.78]], "batl": [[0, 1.31, 2951.1], [2, 1.33, 1282.18]]}, {"timestamp": 1632580198778, "ltp": 1.31, "tv": 75330.03, "trd": [[1.31, 655.41]], "batb": NaN, "batl": [[0, 1.31, 2946.25], [2, 1.33, 1265.63]]}, {"timestamp": 1632580199396, "ltp": 1.31, "tv": 75334.03, "trd": [[1.3, 3.42], [1.31, 655.99]], "batb": [[0, 1.3, 24.82]], "batl": [[0, 1.31, 2945.96]]}, {"timestamp": 1632580200497, "ltp": 1.31, "tv": 75362.29, "trd": [[1.31, 684.24]], "batb": NaN, "batl": [[0, 1.31, 2931.83]]}, {"timestamp": 1632580201598, "ltp": 1.31, "tv": 75362.99, "trd": [[1.31, 684.94]], "batb": NaN, "batl": [[0, 1.31, 2931.48]]}, {"timestamp": 1632580202711, "ltp": 1.31, "tv": 75391.56, "trd": [[1.31, 713.52]], "batb": [[0, 1.3, 250.24]], "batl": [[0, 1.31, 2917.19]]}, {"timestamp": 1632580203680, "ltp": 1.31, "tv": 75422.49, "trd": [[1.31, 744.44]], "batb": [[1, 1.29, 148.87]], "batl": [[0, 1.31, 2983.47]]}, {"timestamp": 1632580204289, "ltp": 1.3, "tv": 75436.49, "trd": [[1.3, 17.42]], "batb": [[0, 1.3, 243.24]], "batl": NaN}, {"timestamp": 1632580205723, "ltp": 1.31, "tv": 75604.77, "trd": [[1.3, 180.79], [1.31, 749.36]], "batb": [[0, 1.3, 161.56]], "batl": [[0, 1.31, 2981.01]]}, {"timestamp": 1632580206810, "ltp": 1.31, "tv": 75616.31, "trd": [[1.31, 760.9]], "batb": [[0, 1.3, 959.48]], "batl": [[0, 1.31, 2987.22]]}, {"timestamp": 1632580207306, "ltp": 1.31, "tv": 75621.03, "trd": [[1.3, 184.8], [1.31, 761.6]], "batb": [[0, 1.3, 957.48]], "batl": [[0, 1.31, 2986.87]]}, {"timestamp": 1632580208695, "ltp": 1.3, "tv": 76100.59, "trd": [[1.3, 655.17], [1.31, 770.8]], "batb": [[0, 1.3, 781.39]], "batl": [[0, 1.31, 2982.27]]}, {"timestamp": 1632580209622, "ltp": 1.31, "tv": 76107.61, "trd": [[1.31, 777.82]], "batb": NaN, "batl": [[0, 1.31, 2978.76]]}, {"timestamp": 1632580210729, "ltp": 1.3, "tv": 76145.34, "trd": [[1.3, 662.19], [1.31, 808.52]], "batb": [[0, 1.3, 777.88], [2, 1.28, 1192.6]], "batl": [[0, 1.31, 2963.41]]}, {"timestamp": 1632580211770, "ltp": 1.31, "tv": 76171.06, "trd": [[1.31, 834.24]], "batb": NaN, "batl": [[0, 1.31, 2938.57]]}, {"timestamp": 1632580212734, "ltp": 1.3, "tv": 78719.71, "trd": [[1.3, 3210.79], [1.31, 834.3]], "batb": [[0, 1.29, 800.28], [1, 1.28, 1192.6], [2, 1.27, 2761.46]], "batl": [[0, 1.3, 973.5], [1, 1.31, 2938.54], [2, 1.32, 2289.11]]}, {"timestamp": 1632580213656, "ltp": 1.3, "tv": 78769.71, "trd": [[1.3, 3260.79]], "batb": NaN, "batl": [[0, 1.3, 948.5], [2, 1.32, 2726.24]]}, {"timestamp": 1632580214601, "ltp": 1.3, "tv": 78769.71, "trd": NaN, "batb": NaN, "batl": [[0, 1.3, 960.48]]}, {"timestamp": 1632580215549, "ltp": 1.3, "tv": 79315.77, "trd": [[1.3, 3806.85]], "batb": NaN, "batl": [[0, 1.3, 687.45]]}, {"timestamp": 1632580216658, "ltp": 1.3, "tv": 79319.2, "trd": [[1.3, 3810.28]], "batb": [[1, 1.28, 1200.6]], "batl": [[0, 1.3, 685.74]]}, {"timestamp": 1632580217384, "ltp": 1.3, "tv": 79323.27, "trd": [[1.3, 3814.35]], "batb": NaN, "batl": [[0, 1.3, 781.67]]}, {"timestamp": 1632580218680, "ltp": 1.3, "tv": 79333.27, "trd": [[1.3, 3824.35]], "batb": NaN, "batl": [[0, 1.3, 1338.68], [1, 1.31, 3373.1], [2, 1.32, 3257.65]]}, {"timestamp": 1632580219668, "ltp": 1.3, "tv": 79333.27, "trd": NaN, "batb": NaN, "batl": [[0, 1.3, 1335.17]]}, {"timestamp": 1632580221655, "ltp": 1.29, "tv": 81781.39, "trd": [[1.29, 866.6], [1.3, 5405.87]], "batb": [[0, 1.29, 366.98]], "batl": [[0, 1.3, 544.41]]}, {"timestamp": 1632580222548, "ltp": 1.3, "tv": 81981.67, "trd": [[1.3, 5606.15]], "batb": NaN, "batl": [[0, 1.3, 444.27], [1, 1.31, 3364.1]]}, {"timestamp": 1632580223663, "ltp": 1.3, "tv": 81985.1, "trd": [[1.3, 5609.58]], "batb": [[1, 1.28, 2178.35], [2, 1.27, 1779.82]], "batl": [[0, 1.3, 442.56]]}, {"timestamp": 1632580224656, "ltp": 1.3, "tv": 81985.1, "trd": NaN, "batb": [[0, 1.29, 375.98], [2, 1.27, 1953.02]], "batl": NaN}, {"timestamp": 1632580225568, "ltp": 1.3, "tv": 82010.12, "trd": [[1.3, 5634.6]], "batb": NaN, "batl": [[0, 1.3, 941.01]]}, {"timestamp": 1632580226393, "ltp": 1.3, "tv": 82014.12, "trd": [[1.3, 5638.6]], "batb": NaN, "batl": [[0, 1.3, 939.01]]}, {"timestamp": 1632580227693, "ltp": 1.3, "tv": 82029.9, "trd": [[1.3, 5654.38]], "batb": NaN, "batl": [[0, 1.3, 923.23]]}, {"timestamp": 1632580228687, "ltp": 1.3, "tv": 82042.9, "trd": [[1.3, 5667.38]], "batb": NaN, "batl": [[0, 1.3, 916.73]]}, {"timestamp": 1632580229558, "ltp": 1.29, "tv": 82811.89, "trd": [[1.29, 1632.2], [1.3, 5670.76]], "batb": [[0, 1.28, 2178.35], [1, 1.27, 1953.02], [2, 1.26, 2631.66]], "batl": [[0, 1.29, 110.38], [1, 1.3, 935.04], [2, 1.31, 3364.1]]}, {"timestamp": 1632580230649, "ltp": 1.29, "tv": 82817.89, "trd": [[1.29, 1638.2]], "batb": NaN, "batl": [[0, 1.29, 107.38]]}, {"timestamp": 1632580231585, "ltp": 1.3, "tv": 83304.95, "trd": [[1.29, 1852.96], [1.3, 5943.06]], "batb": NaN, "batl": [[0, 1.3, 798.89], [1, 1.31, 3364.1], [2, 1.32, 3257.65]]}, {"timestamp": 1632580232676, "ltp": 1.3, "tv": 83318.99, "trd": [[1.3, 5957.1]], "batb": NaN, "batl": [[0, 1.3, 791.87]]}, {"timestamp": 1632580233385, "ltp": 1.3, "tv": 83318.99, "trd": NaN, "batb": NaN, "batl": [[0, 1.3, 891.87]]}, {"timestamp": 1632580234676, "ltp": 1.29, "tv": 83330.4, "trd": [[1.29, 1863.2], [1.3, 5958.28]], "batb": [[0, 1.28, 2347.21]], "batl": [[0, 1.29, 374.43], [1, 1.3, 891.28], [2, 1.31, 3364.1]]}, {"timestamp": 1632580235688, "ltp": 1.29, "tv": 83330.75, "trd": [[1.29, 1863.54]], "batb": NaN, "batl": [[0, 1.29, 374.09], [1, 1.3, 1438.12], [2, 1.31, 4032.65]]}, {"timestamp": 1632580236794, "ltp": 1.29, "tv": 83475.91, "trd": [[1.29, 2008.7]], "batb": NaN, "batl": [[0, 1.29, 301.33]]}, {"timestamp": 1632580237678, "ltp": 1.28, "tv": 83505.47, "trd": [[1.28, 29.56]], "batb": [[0, 1.28, 2332.43], [1, 1.27, 1779.82]], "batl": NaN}, {"timestamp": 1632580238771, "ltp": 1.29, "tv": 83621.42, "trd": [[1.29, 2124.65]], "batb": [[0, 1.28, 2328.54], [2, 1.26, 2628.2]], "batl": [[0, 1.29, 243.35], [1, 1.3, 1444.62]]}, {"timestamp": 1632580239581, "ltp": 1.29, "tv": 83637.67, "trd": [[1.29, 2140.91]], "batb": NaN, "batl": [[0, 1.29, 235.22]]}, {"timestamp": 1632580240769, "ltp": 1.29, "tv": 83637.67, "trd": NaN, "batb": [[2, 1.26, 2804.7]], "batl": NaN}, {"timestamp": 1632580242790, "ltp": 1.29, "tv": 83638.6, "trd": [[1.29, 2141.83]], "batb": [[2, 1.26, 13510.11]], "batl": [[0, 1.29, 234.76], [1, 1.3, 1630.28], [2, 1.31, 4243.66]]}, {"timestamp": 1632580243296, "ltp": 1.29, "tv": 83638.6, "trd": NaN, "batb": NaN, "batl": [[1, 1.3, 1116.01]]}, {"timestamp": 1632580246103, "ltp": 1.29, "tv": 84108.12, "trd": [[1.29, 2611.35]], "batb": [[0, 1.29, 633.19], [1, 1.28, 2324.57], [2, 1.27, 1779.82]], "batl": [[0, 1.3, 1116.01], [1, 1.31, 4243.66], [2, 1.32, 3257.65]]}, {"timestamp": 1632580247691, "ltp": 1.29, "tv": 84709.3, "trd": [[1.29, 3212.54]], "batb": [[0, 1.29, 332.6]], "batl": [[2, 1.32, 3347.65]]}, {"timestamp": 1632580248613, "ltp": 1.29, "tv": 84755.3, "trd": [[1.29, 3258.54]], "batb": [[0, 1.29, 309.6]], "batl": [[1, 1.31, 4032.65]]}, {"timestamp": 1632580249408, "ltp": 1.3, "tv": 84779.82, "trd": [[1.29, 3269.06], [1.3, 5972.28]], "batb": [[0, 1.29, 517.04]], "batl": [[0, 1.3, 1109.01]]}, {"timestamp": 1632580250806, "ltp": 1.3, "tv": 84779.82, "trd": NaN, "batb": [[0, 1.29, 519.05]], "batl": NaN}, {"timestamp": 1632580251371, "ltp": 1.29, "tv": 84934.84, "trd": [[1.29, 3424.08]], "batb": [[0, 1.29, 441.54]], "batl": NaN}, {"timestamp": 1632580252593, "ltp": 1.29, "tv": 84934.84, "trd": NaN, "batb": [[0, 1.29, 458.8]], "batl": NaN}, {"timestamp": 1632580253804, "ltp": 1.3, "tv": 84969.04, "trd": [[1.3, 6006.48]], "batb": [[0, 1.29, 466.8]], "batl": [[0, 1.3, 1091.91]]}, {"timestamp": 1632580255797, "ltp": 1.3, "tv": 84969.74, "trd": [[1.3, 6007.18]], "batb": NaN, "batl": [[0, 1.3, 1091.56]]}, {"timestamp": 1632580256791, "ltp": 1.3, "tv": 84969.74, "trd": NaN, "batb": [[0, 1.29, 456.79], [1, 1.28, 2316.57]], "batl": NaN}, {"timestamp": 1632580263198, "ltp": 1.3, "tv": 84973.26, "trd": [[1.3, 6010.7]], "batb": NaN, "batl": [[0, 1.3, 1089.8]]}, {"timestamp": 1632580268291, "ltp": 1.3, "tv": 84973.26, "trd": NaN, "batb": [[1, 1.28, 2404.73]], "batl": NaN}, {"timestamp": 1632580270727, "ltp": 1.3, "tv": 84974.24, "trd": [[1.3, 6011.68]], "batb": NaN, "batl": [[0, 1.3, 1089.31]]}, {"timestamp": 1632580271118, "ltp": 1.29, "tv": 85074.24, "trd": [[1.29, 3524.08]], "batb": [[0, 1.29, 406.79]], "batl": NaN}, {"timestamp": 1632580272215, "ltp": 1.29, "tv": 85074.24, "trd": NaN, "batb": [[0, 1.29, 481.82]], "batl": [[0, 1.3, 1161.11]]}, {"timestamp": 1632580273808, "ltp": 1.29, "tv": 85074.24, "trd": NaN, "batb": [[0, 1.29, 493.35]], "batl": NaN}, {"timestamp": 1632580275707, "ltp": 1.29, "tv": 85078.17, "trd": [[1.29, 3528.01]], "batb": [[0, 1.29, 491.38]], "batl": NaN}, {"timestamp": 1632580277741, "ltp": 1.29, "tv": 85586.48, "trd": [[1.29, 4033.71], [1.3, 6014.28]], "batb": [[0, 1.29, 238.53]], "batl": [[0, 1.3, 1159.81]]}, {"timestamp": 1632580277934, "ltp": 1.29, "tv": 85586.88, "trd": [[1.29, 4034.12]], "batb": [[0, 1.29, 238.33]], "batl": NaN}, {"timestamp": 1632580279612, "ltp": 1.29, "tv": 85929.73, "trd": [[1.29, 4376.96]], "batb": [[0, 1.29, 66.9]], "batl": NaN}, {"timestamp": 1632580279844, "ltp": 1.29, "tv": 85929.73, "trd": NaN, "batb": [[2, 1.27, 1825.69]], "batl": NaN}, {"timestamp": 1632580283431, "ltp": 1.3, "tv": 85937.94, "trd": [[1.3, 6022.5]], "batb": NaN, "batl": [[0, 1.3, 1155.7]]}, {"timestamp": 1632580284627, "ltp": 1.3, "tv": 85938.11, "trd": [[1.3, 6022.66]], "batb": NaN, "batl": [[0, 1.3, 1155.62]]}, {"timestamp": 1632580284922, "ltp": 1.3, "tv": 85945.13, "trd": [[1.3, 6029.68]], "batb": NaN, "batl": [[0, 1.3, 1152.11]]}, {"timestamp": 1632580286367, "ltp": 1.3, "tv": 85945.21, "trd": [[1.3, 6029.76]], "batb": [[1, 1.28, 2425.15]], "batl": [[0, 1.3, 1152.07]]}, {"timestamp": 1632580287731, "ltp": 1.3, "tv": 85945.55, "trd": [[1.3, 6030.1]], "batb": NaN, "batl": [[0, 1.3, 1151.9], [1, 1.31, 3982.65]]}, {"timestamp": 1632580288341, "ltp": 1.3, "tv": 85945.55, "trd": NaN, "batb": NaN, "batl": [[1, 1.31, 3030.39]]}, {"timestamp": 1632580288842, "ltp": 1.3, "tv": 85952.57, "trd": [[1.3, 6037.12]], "batb": NaN, "batl": [[0, 1.3, 1148.39]]}, {"timestamp": 1632580290730, "ltp": 1.3, "tv": 85952.57, "trd": NaN, "batb": NaN, "batl": [[0, 1.3, 1128.39]]}, {"timestamp": 1632580294715, "ltp": 1.29, "tv": 85992.57, "trd": [[1.29, 4416.96]], "batb": [[0, 1.29, 46.91]], "batl": NaN}, {"timestamp": 1632580295520, "ltp": 1.3, "tv": 85999.62, "trd": [[1.3, 6044.18]], "batb": NaN, "batl": [[0, 1.3, 1124.86]]}, {"timestamp": 1632580296745, "ltp": 1.29, "tv": 85999.81, "trd": [[1.29, 4417.15]], "batb": [[0, 1.29, 46.81]], "batl": NaN}, {"timestamp": 1632580298391, "ltp": 1.3, "tv": 86000.21, "trd": [[1.3, 6044.58]], "batb": NaN, "batl": [[0, 1.3, 1124.66]]}, {"timestamp": 1632580299458, "ltp": 1.3, "tv": 86000.91, "trd": [[1.3, 6045.28]], "batb": NaN, "batl": [[0, 1.3, 1124.31]]}, {"timestamp": 1632580300653, "ltp": 1.29, "tv": 86084.98, "trd": [[1.29, 4501.22]], "batb": [[0, 1.29, 4.77]], "batl": NaN}, {"timestamp": 1632580302563, "ltp": 1.29, "tv": 86084.98, "trd": NaN, "batb": NaN, "batl": [[1, 1.31, 2948.65]]}, {"timestamp": 1632580304729, "ltp": 1.3, "tv": 86085.49, "trd": [[1.3, 6045.78]], "batb": NaN, "batl": [[0, 1.3, 1124.06]]}, {"timestamp": 1632580305756, "ltp": 1.3, "tv": 86085.49, "trd": NaN, "batb": [[1, 1.28, 2198.04], [2, 1.27, 1561.46]], "batl": [[0, 1.3, 391.56], [1, 1.31, 1845.54], [2, 1.32, 1075.13]]}, {"timestamp": 1632580306547, "ltp": 1.3, "tv": 86085.49, "trd": NaN, "batb": [[1, 1.28, 20.42], [2, 1.27, 299.13]], "batl": [[0, 1.3, 178.3], [1, 1.31, 247], [2, 1.32, 90]]}, {"timestamp": 1632580307678, "ltp": 1.3, "tv": 86085.49, "trd": NaN, "batb": NaN, "batl": [[1, 1.33, 36.5], [2, 1.35, 39.9]]}, {"timestamp": 1632580309738, "ltp": 1.3, "tv": 86085.49, "trd": NaN, "batb": NaN, "batl": [[2, 1.34, 663.77]]}, {"timestamp": 1632580310047, "ltp": 1.3, "tv": 86085.49, "trd": NaN, "batb": [[1, 1.28, 62.58]], "batl": NaN}, {"timestamp": 1632580312535, "ltp": 1.3, "tv": 86085.49, "trd": NaN, "batb": [[0, 1.29, 11.78]], "batl": NaN}, {"timestamp": 1632580313605, "ltp": 1.3, "tv": 86090.0, "trd": [[1.3, 6050.3]], "batb": NaN, "batl": [[0, 1.3, 176.04]]}, {"timestamp": 1632580314772, "ltp": 1.3, "tv": 86091.4, "trd": [[1.3, 6051.7]], "batb": NaN, "batl": [[0, 1.3, 103.54]]}, {"timestamp": 1632580315065, "ltp": 1.3, "tv": 86096.48, "trd": [[1.3, 6056.78]], "batb": NaN, "batl": [[0, 1.3, 101], [2, 1.35, 39.9]]}, {"timestamp": 1632580317673, "ltp": 1.29, "tv": 86193.98, "trd": [[1.29, 4598.72]], "batb": [[0, 1.28, 20.42], [1, 1.27, 299.13], [2, 1.26, 2259.04]], "batl": [[0, 1.3, 138.35]]}, {"timestamp": 1632580318173, "ltp": 1.3, "tv": 86221.39, "trd": [[1.3, 6084.19]], "batb": [[0, 1.29, 602.02], [1, 1.28, 1219.09], [2, 1.27, 299.13]], "batl": [[0, 1.3, 87.29], [1, 1.32, 1472.91], [2, 1.33, 980.07]]}, {"timestamp": 1632580319375, "ltp": 1.3, "tv": 86221.39, "trd": NaN, "batb": NaN, "batl": [[1, 1.32, 1482.18]]}, {"timestamp": 1632580320586, "ltp": 1.3, "tv": 86308.68, "trd": [[1.3, 6171.48]], "batb": [[1, 1.28, 1275.19]], "batl": [[0, 1.32, 1482.18], [1, 1.33, 980.07], [2, 1.35, 39.9]]}, {"timestamp": 1632580321046, "ltp": 1.29, "tv": 86562.48, "trd": [[1.29, 4609.04], [1.3, 6414.96]], "batb": [[0, 1.29, 596.86], [1, 1.28, 1317.85]], "batl": NaN}, {"timestamp": 1632580322666, "ltp": 1.29, "tv": 86562.48, "trd": NaN, "batb": [[0, 1.3, 641.1], [1, 1.29, 596.86], [2, 1.28, 1261.75]], "batl": NaN}, {"timestamp": 1632580323452, "ltp": 1.3, "tv": 86565.24, "trd": [[1.3, 6417.72]], "batb": [[0, 1.3, 639.92], [1, 1.28, 63.08], [2, 1.27, 299.13]], "batl": [[0, 1.32, 9.27], [1, 1.35, 39.9], [2, 1.36, 231.16]]}, {"timestamp": 1632580324776, "ltp": 1.3, "tv": 86565.24, "trd": NaN, "batb": NaN, "batl": [[0, 1.31, 249], [1, 1.32, 9.27], [2, 1.35, 39.9]]}, {"timestamp": 1632580325364, "ltp": 1.3, "tv": 86565.24, "trd": NaN, "batb": [[0, 1.3, 641.65]], "batl": [[0, 1.32, 9.27], [1, 1.35, 39.9], [2, 1.36, 231.16]]}, {"timestamp": 1632580326474, "ltp": 1.3, "tv": 86565.24, "trd": NaN, "batb": NaN, "batl": [[1, 1.33, 39.5], [2, 1.35, 39.9]]}, {"timestamp": 1632580327460, "ltp": 1.3, "tv": 86565.24, "trd": NaN, "batb": NaN, "batl": [[1, 1.34, 665.86], [2, 1.35, 927.95]]}, {"timestamp": 1632580328783, "ltp": 1.3, "tv": 86565.24, "trd": NaN, "batb": [[0, 1.3, 5055.11], [1, 1.29, 4283.65], [2, 1.28, 4346.73]], "batl": [[0, 1.34, 665.86], [1, 1.35, 927.95], [2, 1.36, 231.16]]}, {"timestamp": 1632580328898, "ltp": 1.3, "tv": 86565.24, "trd": NaN, "batb": [[0, 1.3, 862.32], [1, 1.29, 214.18], [2, 1.28, 277.26]], "batl": NaN}, {"timestamp": 1632580331784, "ltp": 1.3, "tv": 86565.24, "trd": NaN, "batb": [[0, 1.3, 1965.68], [1, 1.29, 1285.09], [2, 1.28, 1348.17]], "batl": NaN}, {"timestamp": 1632580332799, "ltp": 1.3, "tv": 86592.66, "trd": [[1.3, 6445.13]], "batb": [[0, 1.32, 828.6], [1, 1.31, 1277.77], [2, 1.3, 3062.52]], "batl": [[1, 1.35, 1017.95]]}, {"timestamp": 1632580333626, "ltp": 1.3, "tv": 86592.66, "trd": NaN, "batb": [[1, 1.31, 2230.03]], "batl": NaN}, {"timestamp": 1632580334781, "ltp": 1.32, "tv": 86638.72, "trd": [[1.32, 46.06]], "batb": [[0, 1.32, 806]], "batl": NaN}, {"timestamp": 1632580335776, "ltp": 1.32, "tv": 86638.72, "trd": NaN, "batb": [[0, 1.32, 862.66], [1, 1.31, 2349.84]], "batl": [[0, 1.33, 72.78], [1, 1.34, 1178.84], [2, 1.35, 1088.91]]}, {"timestamp": 1632580337400, "ltp": 1.32, "tv": 86638.72, "trd": NaN, "batb": NaN, "batl": [[1, 1.34, 1826.21]]}, {"timestamp": 1632580338794, "ltp": 1.32, "tv": 87926.0, "trd": [[1.32, 1333.35]], "batb": [[0, 1.32, 219.02], [1, 1.31, 2309.84], [2, 1.3, 3072.52]], "batl": [[0, 1.33, 290.28], [1, 1.34, 1178.84]]}, {"timestamp": 1632580339787, "ltp": 1.32, "tv": 87926.0, "trd": NaN, "batb": [[1, 1.31, 1357.58]], "batl": NaN}, {"timestamp": 1632580340717, "ltp": 1.32, "tv": 87926.0, "trd": NaN, "batb": NaN, "batl": [[2, 1.35, 1017.95]]}, {"timestamp": 1632580341769, "ltp": 1.33, "tv": 88088.0, "trd": [[1.33, 167.55]], "batb": [[0, 1.32, 218.59]], "batl": [[0, 1.33, 619.54]]}, {"timestamp": 1632580342814, "ltp": 1.32, "tv": 88091.21, "trd": [[1.32, 1336.56]], "batb": [[0, 1.32, 216.98], [1, 1.31, 1287.77]], "batl": [[0, 1.33, 694.95], [1, 1.34, 1123.02]]}, {"timestamp": 1632580343579, "ltp": 1.33, "tv": 88099.28, "trd": [[1.32, 1343.58], [1.33, 168.6]], "batb": [[0, 1.32, 213.47]], "batl": [[0, 1.33, 693.9]]}, {"timestamp": 1632580345125, "ltp": 1.32, "tv": 88169.4, "trd": [[1.32, 1413.7]], "batb": [[0, 1.32, 178.41]], "batl": NaN}, {"timestamp": 1632580347541, "ltp": 1.32, "tv": 88315.62, "trd": [[1.32, 1519.92], [1.33, 208.6]], "batb": [[0, 1.32, 125.3]], "batl": [[0, 1.33, 673.9]]}, {"timestamp": 1632580348734, "ltp": 1.32, "tv": 88315.62, "trd": NaN, "batb": [[1, 1.31, 1232.64], [2, 1.3, 1738.49]], "batl": [[2, 1.35, 978.05]]}, {"timestamp": 1632580349829, "ltp": 1.33, "tv": 88316.48, "trd": [[1.33, 209.46]], "batb": [[0, 1.32, 56.66], [1, 1.3, 627.94], [2, 1.29, 1341.78]], "batl": [[0, 1.33, 75.41], [1, 1.36, 153.99], [2, 1.37, 123.5]]}, {"timestamp": 1632580350803, "ltp": 1.33, "tv": 88316.48, "trd": NaN, "batb": NaN, "batl": [[1, 1.36, 13.42], [2, 1.38, 142.25]]}, {"timestamp": 1632580351299, "ltp": 1.33, "tv": 88316.48, "trd": NaN, "batb": [[0, 1.3, 627.94], [1, 1.29, 1341.78], [2, 1.28, 387.88]], "batl": [[0, 1.36, 13.42], [1, 1.38, 142.25], [2, 1.4, 242.47]]}, {"timestamp": 1632580352596, "ltp": 1.3, "tv": 89023.52, "trd": [[1.3, 6894.26], [1.32, 1520.05], [1.33, 467.24]], "batb": [[0, 1.3, 403.38], [1, 1.29, 421.61], [2, 1.28, 1341.02]], "batl": [[0, 1.32, 192.9]]}, {"timestamp": 1632580353817, "ltp": 1.3, "tv": 89023.52, "trd": NaN, "batb": NaN, "batl": [[0, 1.32, 227.96], [1, 1.36, 144.07], [2, 1.38, 142.25]]}, {"timestamp": 1632580354794, "ltp": 1.32, "tv": 89032.61, "trd": [[1.32, 1529.14]], "batb": NaN, "batl": [[0, 1.32, 218.87]]}, {"timestamp": 1632580355829, "ltp": 1.32, "tv": 89418.32, "trd": [[1.32, 1914.84]], "batb": NaN, "batl": [[0, 1.32, 185.55], [1, 1.38, 142.25], [2, 1.4, 242.47]]}, {"timestamp": 1632580356825, "ltp": 1.32, "tv": 89789.42, "trd": [[1.32, 2285.94]], "batb": [[0, 1.33, 766.71], [1, 1.3, 403.38], [2, 1.29, 421.61]], "batl": [[0, 1.35, 10.93]]}, {"timestamp": 1632580357741, "ltp": 1.32, "tv": 89789.42, "trd": NaN, "batb": [[1, 1.32, 1006.25], [2, 1.31, 1062.13]], "batl": [[0, 1.35, 788.42], [1, 1.36, 855.49], [2, 1.38, 142.25]]}, {"timestamp": 1632580358731, "ltp": 1.32, "tv": 89789.42, "trd": NaN, "batb": [[0, 1.3, 403.38], [1, 1.29, 421.61], [2, 1.28, 1341.02]], "batl": [[0, 1.35, 10.93], [1, 1.38, 142.25], [2, 1.4, 242.47]]}, {"timestamp": 1632580359811, "ltp": 1.32, "tv": 89789.42, "trd": NaN, "batb": NaN, "batl": [[0, 1.34, 184.16], [1, 1.35, 227.93], [2, 1.38, 142.25]]}, {"timestamp": 1632580360319, "ltp": 1.32, "tv": 89789.42, "trd": NaN, "batb": NaN, "batl": [[1, 1.35, 10.93]]}, {"timestamp": 1632580361739, "ltp": 1.32, "tv": 89789.42, "trd": NaN, "batb": [[0, 1.3, 404.14], [1, 1.29, 1205.69], [2, 1.28, 2543.19]], "batl": [[0, 1.35, 10.93], [1, 1.38, 142.25], [2, 1.39, 1053.04]]}, {"timestamp": 1632580362629, "ltp": 1.32, "tv": 89789.42, "trd": NaN, "batb": [[0, 1.33, 10], [1, 1.32, 10.04], [2, 1.3, 403.38]], "batl": [[1, 1.36, 151.82], [2, 1.38, 142.25]]}, {"timestamp": 1632580363736, "ltp": 1.32, "tv": 89829.5, "trd": [[1.32, 2306.02], [1.33, 487.24]], "batb": [[0, 1.3, 403.38], [1, 1.29, 1196.47], [2, 1.28, 2543.19]], "batl": [[0, 1.31, 2201.96], [1, 1.32, 432.84], [2, 1.35, 10.93]]}, {"timestamp": 1632580364672, "ltp": 1.32, "tv": 89829.5, "trd": NaN, "batb": NaN, "batl": [[1, 1.32, 11796.71], [2, 1.33, 4313.91]]}, {"timestamp": 1632580365614, "ltp": 1.32, "tv": 89829.5, "trd": NaN, "batb": NaN, "batl": [[0, 1.31, 30.5], [1, 1.32, 433.65], [2, 1.33, 1294.18]]}, {"timestamp": 1632580366829, "ltp": 1.32, "tv": 90251.81, "trd": [[1.31, 872.99], [1.32, 2689.64]], "batb": NaN, "batl": [[0, 1.32, 1545.98], [1, 1.33, 2240.48], [2, 1.34, 1263.11]]}, {"timestamp": 1632580369830, "ltp": 1.31, "tv": 90271.81, "trd": [[1.31, 892.99]], "batb": [[0, 1.3, 484.77], [1, 1.29, 1275.7]], "batl": [[0, 1.31, 128.18], [1, 1.32, 1992.6], [2, 1.33, 2479.72]]}, {"timestamp": 1632580370764, "ltp": 1.31, "tv": 90271.81, "trd": NaN, "batb": [[0, 1.3, 486.65]], "batl": [[1, 1.32, 2230.6], [2, 1.33, 2314.72]]}, {"timestamp": 1632580371760, "ltp": 1.31, "tv": 90271.81, "trd": NaN, "batb": NaN, "batl": [[1, 1.32, 1989.56]]}, {"timestamp": 1632580373570, "ltp": 1.31, "tv": 90271.81, "trd": NaN, "batb": NaN, "batl": [[2, 1.33, 2404.72]]}, {"timestamp": 1632580374879, "ltp": 1.31, "tv": 90271.81, "trd": NaN, "batb": NaN, "batl": [[2, 1.33, 2330.48]]}, {"timestamp": 1632580376754, "ltp": 1.3, "tv": 90271.96, "trd": [[1.3, 6894.42]], "batb": [[0, 1.3, 486.58], [1, 1.29, 1196.47]], "batl": [[1, 1.32, 2429.32], [2, 1.33, 2858.46]]}, {"timestamp": 1632580377730, "ltp": 1.31, "tv": 90273.96, "trd": [[1.31, 895]], "batb": NaN, "batl": [[0, 1.31, 133.33]]}, {"timestamp": 1632580378346, "ltp": 1.31, "tv": 90540.62, "trd": [[1.31, 1161.65]], "batb": [[0, 1.31, 95.76], [1, 1.3, 486.58], [2, 1.29, 1196.47]], "batl": [[0, 1.32, 2429.32], [1, 1.33, 2858.46], [2, 1.34, 1406.86]]}, {"timestamp": 1632580380268, "ltp": 1.31, "tv": 90540.62, "trd": NaN, "batb": [[1, 1.3, 993.14], [2, 1.29, 1893.3]], "batl": NaN}, {"timestamp": 1632580381681, "ltp": 1.31, "tv": 90540.62, "trd": NaN, "batb": [[1, 1.3, 486.58], [2, 1.29, 784.08]], "batl": [[0, 1.32, 1947.81], [1, 1.33, 1036.3], [2, 1.34, 7]]}, {"timestamp": 1632580382768, "ltp": 1.31, "tv": 90540.62, "trd": NaN, "batb": [[2, 1.28, 20.42]], "batl": [[0, 1.32, 60.96], [1, 1.35, 149.3], [2, 1.36, 152.24]]}, {"timestamp": 1632580384462, "ltp": 1.31, "tv": 90543.41, "trd": [[1.31, 1164.45]], "batb": [[0, 1.31, 94.36]], "batl": NaN}, {"timestamp": 1632580385776, "ltp": 1.31, "tv": 90543.41, "trd": NaN, "batb": NaN, "batl": [[1, 1.34, 144.25], [2, 1.35, 149.3]]}, {"timestamp": 1632580386061, "ltp": 1.31, "tv": 90598.24, "trd": [[1.31, 1219.27]], "batb": [[0, 1.31, 66.95]], "batl": NaN}, {"timestamp": 1632580387656, "ltp": 1.28, "tv": 91746.14, "trd": [[1.28, 70.4], [1.3, 7867.58], [1.31, 1353.17]], "batb": [[0, 1.31, 1.76], [1, 1.27, 815.68], [2, 1.26, 3837.08]], "batl": NaN}, {"timestamp": 1632580388381, "ltp": 1.28, "tv": 91746.14, "trd": NaN, "batb": [[0, 1.31, 2.11]], "batl": NaN}, {"timestamp": 1632580392790, "ltp": 1.28, "tv": 91746.14, "trd": NaN, "batb": [[1, 1.27, 295.47], [2, 1.26, 2324.9]], "batl": [[0, 1.36, 152.24], [1, 1.37, 367.15], [2, 1.38, 398.29]]}, {"timestamp": 1632580393581, "ltp": 1.28, "tv": 91746.14, "trd": NaN, "batb": [[0, 1.31, 2.14]], "batl": NaN}, {"timestamp": 1632580395791, "ltp": 1.28, "tv": 91746.14, "trd": NaN, "batb": [[0, 1.32, 7.34], [1, 1.31, 1.79], [2, 1.27, 295.47]], "batl": NaN}, {"timestamp": 1632580396698, "ltp": 1.31, "tv": 91764.4, "trd": [[1.31, 1356.75], [1.32, 2704.32]], "batb": [[0, 1.27, 295.47], [1, 1.26, 2324.9], [2, 1.25, 1245.08]], "batl": [[0, 1.31, 90.87], [1, 1.36, 154.24], [2, 1.37, 367.15]]}, {"timestamp": 1632580400398, "ltp": 1.31, "tv": 91764.4, "trd": NaN, "batb": [[0, 1.28, 20], [1, 1.27, 360.52], [2, 1.26, 2324.9]], "batl": [[1, 1.35, 2.5], [2, 1.36, 152.24]]}, {"timestamp": 1632580401772, "ltp": 1.31, "tv": 91789.1, "trd": [[1.31, 1381.45]], "batb": NaN, "batl": [[0, 1.31, 79.57]]}, {"timestamp": 1632580402618, "ltp": 1.31, "tv": 91809.1, "trd": [[1.31, 1401.45]], "batb": [[1, 1.27, 295.47]], "batl": [[0, 1.31, 69.57]]}, {"timestamp": 1632580406386, "ltp": 1.31, "tv": 91809.1, "trd": NaN, "batb": NaN, "batl": [[0, 1.29, 2222], [1, 1.3, 432.84], [2, 1.31, 69.57]]}, {"timestamp": 1632580407496, "ltp": 1.31, "tv": 91809.1, "trd": NaN, "batb": [[0, 1.27, 295.47], [1, 1.26, 2324.9], [2, 1.25, 1245.08]], "batl": NaN}, {"timestamp": 1632580408793, "ltp": 1.29, "tv": 91810.37, "trd": [[1.29, 4610.31]], "batb": NaN, "batl": [[0, 1.29, 2221.08]]}, {"timestamp": 1632580409390, "ltp": 1.29, "tv": 91812.13, "trd": [[1.29, 4612.07]], "batb": NaN, "batl": [[0, 1.3, 432.84], [1, 1.31, 69.57], [2, 1.35, 2.5]]}, {"timestamp": 1632580411788, "ltp": 1.29, "tv": 91812.13, "trd": NaN, "batb": [[0, 1.29, 5.91], [1, 1.27, 295.47], [2, 1.26, 2324.9]], "batl": [[0, 1.31, 69.57], [1, 1.33, 952.26]]}, {"timestamp": 1632580412801, "ltp": 1.29, "tv": 91812.13, "trd": NaN, "batb": [[1, 1.27, 284.37]], "batl": [[1, 1.35, 2.5], [2, 1.36, 152.24]]}, {"timestamp": 1632580413694, "ltp": 1.29, "tv": 91825.35, "trd": [[1.29, 4623.89], [1.31, 1402.85]], "batb": [[0, 1.28, 6.12]], "batl": [[0, 1.31, 287.86], [1, 1.32, 212.55], [2, 1.33, 212.55]]}, {"timestamp": 1632580414716, "ltp": 1.28, "tv": 91837.59, "trd": [[1.28, 82.64]], "batb": [[0, 1.26, 2324.9], [1, 1.25, 1245.08], [2,