{"info": {"id": "1.188075669", "eventId": "30936519", "eventName": "Match Odds", "marketType": "MATCH_ODDS", "openDate": 1632492303465, "name": "Escoffier v Huesler", "numberOfActiveRunner": 2, "countryCode": "", "sport": "TENNIS", "venue": "", "volume": {"total": 43829.69, "preMatch": 925.02, "inPlay": 42904.67}, "winner": {"id": 9631939, "name": "Marc-Andrea Huesler", "status": "WINNER", "position": 2}, "delay": 3}, "runners": [{"id": 9454286, "name": "Antoine Escoffier", "status": "LOSER", "position": 1, "inPlayOdds": 3.1, "inPlayTime": 1632492303465, "avgPrematch": 2.92, "closedOdds": 100.0, "maxPrematch": 3.2, "minPrematch": 2.74, "maxInPlay": 190.0, "minInPlay": 1.44, "inPlayIndex": 109, "lengthOdds": 2454, "lengthOddsPrematch": 109, "lengthOddsInPlay": 2345, "tradedVolume": 6951.46, "preMatchVolume": 248.7, "inPlayVolume": 6702.76}, {"id": 9631939, "name": "Marc-Andrea Huesler", "status": "WINNER", "position": 2, "inPlayOdds": 1.44, "inPlayTime": 1632492303465, "avgPrematch": 1.5, "closedOdds": 1.01, "maxPrematch": 1.55, "minPrematch": 1.44, "maxInPlay": 3.15, "minInPlay": 1.01, "inPlayIndex": 173, "lengthOdds": 3005, "lengthOddsPrematch": 173, "lengthOddsInPlay": 2832, "tradedVolume": 36878.23, "preMatchVolume": 676.32, "inPlayVolume": 36201.91}], "marketUpdates": [{"timestamp": 1632401904616000000, "openDate": "2021-09-24T09:00:00.000Z", "status": "OPEN", "betDelay": 0, "inPlay": false, "complete": true}, {"timestamp": 1632418326592000000, "openDate": "2021-09-24T15:00:00.000Z", "status": "OPEN", "betDelay": 0, "inPlay": false, "complete": true}, {"timestamp": 1632473845570000000, "openDate": "2021-09-24T14:54:00.000Z", "status": "OPEN", "betDelay": 0, "inPlay": false, "complete": true}, {"timestamp": 1632479532043000000, "openDate": "2021-09-24T14:34:00.000Z", "status": "OPEN", "betDelay": 0, "inPlay": false, "complete": true}, {"timestamp": 1632485827468000000, "openDate": "2021-09-24T14:32:00.000Z", "status": "OPEN", "betDelay": 0, "inPlay": false, "complete": true}, {"timestamp": 1632486129401000000, "openDate": "2021-09-24T14:17:00.000Z", "status": "OPEN", "betDelay": 0, "inPlay": false, "complete": true}, {"timestamp": 1632491527355000000, "openDate": "2021-09-24T13:54:00.000Z", "status": "OPEN", "betDelay": 0, "inPlay": false, "complete": true}, {"timestamp": 1632491856325000000, "openDate": "2021-09-24T13:53:00.000Z", "status": "OPEN", "betDelay": 0, "inPlay": false, "complete": true}, {"timestamp": 1632492303223000000, "openDate": "2021-09-24T13:53:00.000Z", "status": "SUSPENDED", "betDelay": 0, "inPlay": false, "complete": true}, {"timestamp": 1632492303465000000, "openDate": "2021-09-24T13:53:00.000Z", "status": "OPEN", "betDelay": 3, "inPlay": true, "complete": true}, {"timestamp": 1632498558045000000, "openDate": "2021-09-24T13:53:00.000Z", "status": "SUSPENDED", "betDelay": 3, "inPlay": true, "complete": true}, {"timestamp": 1632498623937000000, "openDate": "2021-09-24T13:53:00.000Z", "status": "CLOSED", "betDelay": 3, "inPlay": true, "complete": true}], "odds": [{"runnerId": 9454286, "odds": [{"timestamp": 1632462653145, "ltp": 2.74, "tv": 23.42, "trd": [[2.74, 23.42]], "batb": [[0, 1.34, 10.72], [1, 1.01, 616.31], [2, 1.01, 0]], "batl": [[0, 2.74, 1.12], [1, 3.25, 42.66], [2, 46, 28.9]]}, {"timestamp": 1632462654127, "ltp": 2.74, "tv": 25.66, "trd": [[2.74, 25.66]], "batb": [[0, 2.68, 360.1], [1, 1.5, 14.57], [2, 1.34, 10.72]], "batl": [[0, 3.25, 202.88], [1, 46, 28.9], [2, 990, 2.2]]}, {"timestamp": 1632462655211, "ltp": 2.74, "tv": 25.66, "trd": NaN, "batb": NaN, "batl": [[0, 3.25, 25]]}, {"timestamp": 1632462655307, "ltp": 2.74, "tv": 25.66, "trd": NaN, "batb": NaN, "batl": [[0, 3.2, 184.52], [1, 3.25, 25], [2, 46, 28.9]]}, {"timestamp": 1632463258969, "ltp": 2.74, "tv": 25.66, "trd": [[2.74, 25.67]], "batb": [[0, 2.7, 465.75], [1, 2.68, 10.38], [2, 1.5, 14.58]], "batl": [[2, 46, 28.91]]}, {"timestamp": 1632463263182, "ltp": 2.74, "tv": 25.66, "trd": NaN, "batb": [[1, 2.68, 4]], "batl": NaN}, {"timestamp": 1632463263286, "ltp": 2.74, "tv": 25.66, "trd": NaN, "batb": [[0, 2.72, 3.65], [1, 2.7, 465.75], [2, 2.68, 4]], "batl": NaN}, {"timestamp": 1632463364082, "ltp": 2.74, "tv": 25.66, "trd": NaN, "batb": [[1, 2.7, 3], [2, 1.5, 14.58]], "batl": NaN}, {"timestamp": 1632463465150, "ltp": 2.74, "tv": 25.66, "trd": NaN, "batb": [[0, 2.7, 3], [1, 1.5, 14.58], [2, 1.34, 10.72]], "batl": NaN}, {"timestamp": 1632463465355, "ltp": 2.74, "tv": 25.66, "trd": NaN, "batb": [[0, 2.7, 473.33]], "batl": NaN}, {"timestamp": 1632463748798, "ltp": 2.74, "tv": 25.66, "trd": NaN, "batb": [[0, 2.74, 3], [1, 2.72, 28.81], [2, 2.7, 473.33]], "batl": NaN}, {"timestamp": 1632463749413, "ltp": 2.74, "tv": 25.66, "trd": NaN, "batb": [[1, 2.72, 4]], "batl": NaN}, {"timestamp": 1632463765534, "ltp": 2.74, "tv": 25.66, "trd": NaN, "batb": [[0, 2.76, 481.56], [1, 2.74, 3], [2, 2.7, 5]], "batl": NaN}, {"timestamp": 1632463864780, "ltp": 2.74, "tv": 25.66, "trd": NaN, "batb": [[2, 2.64, 9.26]], "batl": NaN}, {"timestamp": 1632464400258, "ltp": 2.74, "tv": 25.66, "trd": NaN, "batb": NaN, "batl": [[0, 3.25, 25], [1, 46, 28.91], [2, 990, 2.2]]}, {"timestamp": 1632464401587, "ltp": 2.74, "tv": 25.66, "trd": NaN, "batb": NaN, "batl": [[0, 3.2, 148.33], [1, 3.25, 25], [2, 46, 28.91]]}, {"timestamp": 1632465203827, "ltp": 2.74, "tv": 25.66, "trd": NaN, "batb": [[0, 2.78, 481.36]], "batl": NaN}, {"timestamp": 1632466964417, "ltp": 2.74, "tv": 25.66, "trd": NaN, "batb": [[0, 2.8, 3], [1, 2.78, 484.36], [2, 2.74, 3]], "batl": NaN}, {"timestamp": 1632467004072, "ltp": 2.74, "tv": 25.66, "trd": NaN, "batb": [[0, 2.82, 474.51], [1, 2.8, 3], [2, 2.64, 9.26]], "batl": NaN}, {"timestamp": 1632467029032, "ltp": 2.82, "tv": 30.59, "trd": [[2.82, 4.92]], "batb": [[0, 2.82, 472.05]], "batl": NaN}, {"timestamp": 1632467029911, "ltp": 2.82, "tv": 30.59, "trd": NaN, "batb": [[0, 2.8, 3], [1, 2.64, 9.26], [2, 1.5, 14.58]], "batl": [[0, 3.2, 148.14]]}, {"timestamp": 1632467496995, "ltp": 2.82, "tv": 30.59, "trd": NaN, "batb": [[0, 2.82, 472.89], [1, 2.8, 3], [2, 2.64, 9.26]], "batl": NaN}, {"timestamp": 1632467639934, "ltp": 2.82, "tv": 30.59, "trd": NaN, "batb": [[0, 2.82, 3], [1, 2.8, 469.53]], "batl": NaN}, {"timestamp": 1632467726471, "ltp": 2.82, "tv": 30.59, "trd": NaN, "batb": [[0, 2.84, 3], [1, 2.82, 3]], "batl": NaN}, {"timestamp": 1632467765619, "ltp": 2.82, "tv": 30.59, "trd": NaN, "batb": [[1, 2.66, 12.05], [2, 1.5, 14.58]], "batl": NaN}, {"timestamp": 1632467868034, "ltp": 2.82, "tv": 30.59, "trd": NaN, "batb": [[1, 2.7, 11.46]], "batl": NaN}, {"timestamp": 1632469109283, "ltp": 2.84, "tv": 30.81, "trd": [[2.84, 0.22]], "batb": [[0, 2.84, 2.89]], "batl": NaN}, {"timestamp": 1632469140024, "ltp": 2.84, "tv": 30.81, "trd": NaN, "batb": NaN, "batl": [[0, 3.25, 25], [1, 46, 28.91], [2, 990, 2.2]]}, {"timestamp": 1632469140232, "ltp": 2.84, "tv": 30.81, "trd": NaN, "batb": NaN, "batl": [[0, 3.2, 171.68], [1, 3.25, 25], [2, 46, 28.91]]}, {"timestamp": 1632469266845, "ltp": 2.84, "tv": 30.81, "trd": NaN, "batb": [[1, 2.8, 12.87], [2, 2.7, 11.46]], "batl": NaN}, {"timestamp": 1632469532643, "ltp": 2.84, "tv": 30.81, "trd": NaN, "batb": NaN, "batl": [[0, 3.2, 18.52]]}, {"timestamp": 1632469568414, "ltp": 2.84, "tv": 30.81, "trd": NaN, "batb": NaN, "batl": [[0, 3.2, 171.68]]}, {"timestamp": 1632470487029, "ltp": 2.84, "tv": 30.82, "trd": [[2.74, 25.68], [2.82, 4.93]], "batb": [[2, 2.7, 11.46]], "batl": [[2, 46, 28.92]]}, {"timestamp": 1632473907580, "ltp": 2.84, "tv": 30.82, "trd": NaN, "batb": [[1, 2.8, 19.3]], "batl": NaN}, {"timestamp": 1632474059134, "ltp": 2.84, "tv": 30.82, "trd": NaN, "batb": [[2, 1.5, 14.59]], "batl": NaN}, {"timestamp": 1632474059267, "ltp": 2.84, "tv": 30.82, "trd": NaN, "batb": [[1, 2.82, 3.6], [2, 2.8, 19.3]], "batl": NaN}, {"timestamp": 1632474287007, "ltp": 2.84, "tv": 30.82, "trd": NaN, "batb": NaN, "batl": [[0, 3.25, 199.1], [1, 46, 28.92], [2, 990, 2.2]]}, {"timestamp": 1632475018293, "ltp": 2.84, "tv": 30.82, "trd": NaN, "batb": [[0, 2.88, 18.48], [1, 2.84, 2.89], [2, 2.82, 3.6]], "batl": NaN}, {"timestamp": 1632475337980, "ltp": 2.84, "tv": 30.82, "trd": NaN, "batb": NaN, "batl": [[0, 3.25, 43.09]]}, {"timestamp": 1632475361785, "ltp": 2.84, "tv": 30.82, "trd": NaN, "batb": NaN, "batl": [[0, 3.25, 199.7]]}, {"timestamp": 1632476059462, "ltp": 2.84, "tv": 30.82, "trd": NaN, "batb": [[2, 2.74, 10.65]], "batl": NaN}, {"timestamp": 1632476445339, "ltp": 2.84, "tv": 30.82, "trd": NaN, "batb": NaN, "batl": [[0, 3.2, 13.37], [1, 3.25, 25], [2, 46, 28.92]]}, {"timestamp": 1632477042424, "ltp": 2.84, "tv": 30.82, "trd": NaN, "batb": [[1, 2.74, 10.65], [2, 1.5, 14.59]], "batl": NaN}, {"timestamp": 1632477059145, "ltp": 2.84, "tv": 30.82, "trd": NaN, "batb": NaN, "batl": [[0, 3.25, 25], [1, 46, 28.92], [2, 990, 2.2]]}, {"timestamp": 1632477059719, "ltp": 2.84, "tv": 30.82, "trd": NaN, "batb": [[0, 2.94, 4.98], [1, 2.88, 18.48]], "batl": NaN}, {"timestamp": 1632477090953, "ltp": 2.84, "tv": 30.82, "trd": NaN, "batb": NaN, "batl": [[0, 3.25, 25.86]]}, {"timestamp": 1632477716169, "ltp": 2.84, "tv": 30.82, "trd": NaN, "batb": [[2, 1.5, 14.59]], "batl": [[1, 46, 28.93]]}, {"timestamp": 1632479582130, "ltp": 2.84, "tv": 30.82, "trd": NaN, "batb": [[0, 2.94, 473.03]], "batl": NaN}, {"timestamp": 1632479585532, "ltp": 2.84, "tv": 30.82, "trd": NaN, "batb": [[0, 3, 3], [1, 2.98, 3], [2, 2.94, 473.03]], "batl": NaN}, {"timestamp": 1632479660033, "ltp": 2.84, "tv": 30.82, "trd": NaN, "batb": [[2, 2.94, 4.98]], "batl": NaN}, {"timestamp": 1632479660920, "ltp": 2.84, "tv": 30.82, "trd": NaN, "batb": [[1, 2.94, 4.98], [2, 2.88, 18.48]], "batl": NaN}, {"timestamp": 1632482488319, "ltp": 2.84, "tv": 30.82, "trd": NaN, "batb": [[0, 2.98, 3], [1, 2.96, 3], [2, 2.94, 4.98]], "batl": NaN}, {"timestamp": 1632482636695, "ltp": 2.84, "tv": 30.82, "trd": NaN, "batb": [[1, 2.94, 4.98], [2, 2.88, 18.48]], "batl": NaN}, {"timestamp": 1632483097647, "ltp": 2.84, "tv": 30.82, "trd": NaN, "batb": [[2, 1.8, 11.94]], "batl": NaN}, {"timestamp": 1632483248947, "ltp": 2.84, "tv": 30.82, "trd": NaN, "batb": NaN, "batl": [[1, 46, 29.9]]}, {"timestamp": 1632484211082, "ltp": 2.84, "tv": 30.82, "trd": NaN, "batb": [[0, 2.94, 4.98], [1, 1.8, 11.94], [2, 1.5, 14.59]], "batl": NaN}, {"timestamp": 1632484211243, "ltp": 2.84, "tv": 30.82, "trd": NaN, "batb": [[0, 2.96, 462.76], [1, 2.94, 4.98], [2, 1.8, 11.94]], "batl": NaN}, {"timestamp": 1632484581567, "ltp": 2.84, "tv": 30.82, "trd": NaN, "batb": [[2, 1.8, 23.82]], "batl": NaN}, {"timestamp": 1632485059387, "ltp": 2.84, "tv": 30.84, "trd": [[2.74, 25.7], [2.82, 4.93]], "batb": [[0, 2.98, 2.84], [1, 2.96, 462.76], [2, 1.8, 23.88]], "batl": [[1, 46, 29.97]]}, {"timestamp": 1632485106030, "ltp": 2.84, "tv": 30.84, "trd": NaN, "batb": [[1, 1.8, 23.88], [2, 1.5, 14.63]], "batl": NaN}, {"timestamp": 1632485959018, "ltp": 2.84, "tv": 30.84, "trd": NaN, "batb": [[0, 1.8, 23.88], [1, 1.5, 14.63], [2, 1.34, 10.76]], "batl": NaN}, {"timestamp": 1632485959536, "ltp": 2.84, "tv": 30.84, "trd": NaN, "batb": [[0, 2.96, 462.76], [1, 2.94, 4.99], [2, 1.8, 23.88]], "batl": NaN}, {"timestamp": 1632486544634, "ltp": 2.84, "tv": 30.84, "trd": NaN, "batb": [[0, 2.94, 4.99], [1, 1.8, 23.88], [2, 1.5, 14.63]], "batl": NaN}, {"timestamp": 1632486545525, "ltp": 2.84, "tv": 30.84, "trd": NaN, "batb": [[0, 2.94, 489.21]], "batl": NaN}, {"timestamp": 1632486849006, "ltp": 2.84, "tv": 30.84, "trd": NaN, "batb": [[0, 3, 3], [1, 2.98, 3], [2, 2.94, 489.21]], "batl": NaN}, {"timestamp": 1632486850221, "ltp": 2.84, "tv": 30.84, "trd": NaN, "batb": NaN, "batl": [[1, 46, 29]]}, {"timestamp": 1632486850540, "ltp": 2.84, "tv": 30.84, "trd": NaN, "batb": NaN, "batl": [[1, 46, 29.97]]}, {"timestamp": 1632486902676, "ltp": 2.84, "tv": 30.84, "trd": NaN, "batb": [[1, 2.94, 4.99], [2, 1.8, 23.88]], "batl": NaN}, {"timestamp": 1632488306508, "ltp": 3.05, "tv": 32.55, "trd": [[3.05, 1.71]], "batb": NaN, "batl": NaN}, {"timestamp": 1632488359701, "ltp": 3.05, "tv": 32.55, "trd": NaN, "batb": [[1, 2.94, 7.98]], "batl": NaN}, {"timestamp": 1632489167610, "ltp": 3.05, "tv": 32.55, "trd": NaN, "batb": [[0, 3, 29.36]], "batl": NaN}, {"timestamp": 1632489420869, "ltp": 3.05, "tv": 32.55, "trd": NaN, "batb": [[0, 3, 26.36], [1, 2.98, 6.49], [2, 2.94, 7.98]], "batl": NaN}, {"timestamp": 1632489659708, "ltp": 3.05, "tv": 32.55, "trd": NaN, "batb": [[0, 3, 31.79], [2, 1.8, 23.88]], "batl": NaN}, {"timestamp": 1632489763943, "ltp": 3.05, "tv": 32.55, "trd": NaN, "batb": [[0, 3.1, 2.65], [1, 3, 31.79], [2, 2.98, 6.49]], "batl": NaN}, {"timestamp": 1632490451074, "ltp": 3.05, "tv": 32.55, "trd": NaN, "batb": NaN, "batl": [[1, 46, 29]]}, {"timestamp": 1632490453557, "ltp": 3.05, "tv": 32.55, "trd": NaN, "batb": NaN, "batl": [[1, 46, 29.91]]}, {"timestamp": 1632490454876, "ltp": 3.05, "tv": 32.55, "trd": NaN, "batb": [[0, 3.15, 10.36], [1, 3.1, 2.65], [2, 3.05, 6.27]], "batl": NaN}, {"timestamp": 1632490459984, "ltp": 3.05, "tv": 32.55, "trd": NaN, "batb": [[0, 3.1, 2.65], [1, 3.05, 6.27], [2, 3, 31.79]], "batl": NaN}, {"timestamp": 1632490460786, "ltp": 3.05, "tv": 32.55, "trd": NaN, "batb": [[1, 3, 31.79], [2, 2.98, 6.49]], "batl": NaN}, {"timestamp": 1632490627002, "ltp": 3.1, "tv": 92.55, "trd": [[3.1, 60]], "batb": [[0, 3, 31.79], [1, 2.98, 6.49], [2, 1.8, 23.88]], "batl": NaN}, {"timestamp": 1632491256271, "ltp": 3.1, "tv": 92.55, "trd": NaN, "batb": [[2, 2.88, 2.65]], "batl": NaN}, {"timestamp": 1632491278735, "ltp": 3.0, "tv": 188.23, "trd": [[3, 20.02], [3.05, 77.37]], "batb": [[0, 3, 21.78]], "batl": NaN}, {"timestamp": 1632491279414, "ltp": 3.0, "tv": 188.23, "trd": NaN, "batb": [[1, 2.96, 6.55]], "batl": NaN}, {"timestamp": 1632491497968, "ltp": 3.0, "tv": 188.23, "trd": NaN, "batb": [[0, 3.05, 4.66], [1, 3, 21.78], [2, 2.96, 6.55]], "batl": NaN}, {"timestamp": 1632491498285, "ltp": 3.0, "tv": 188.23, "trd": NaN, "batb": [[0, 3, 21.78], [1, 2.96, 6.55], [2, 2.88, 2.65]], "batl": NaN}, {"timestamp": 1632491636401, "ltp": 3.0, "tv": 188.23, "trd": NaN, "batb": NaN, "batl": [[0, 3.25, 27.86]]}, {"timestamp": 1632491678197, "ltp": 3.0, "tv": 188.23, "trd": NaN, "batb": [[0, 3, 178.71]], "batl": NaN}, {"timestamp": 1632491742898, "ltp": 3.0, "tv": 188.23, "trd": NaN, "batb": [[0, 3.05, 4.11], [1, 3, 178.71], [2, 2.96, 6.55]], "batl": NaN}, {"timestamp": 1632491762204, "ltp": 3.2, "tv": 188.48, "trd": [[3.2, 0.25]], "batb": NaN, "batl": [[0, 3.25, 27.61]]}, {"timestamp": 1632491782633, "ltp": 3.2, "tv": 188.48, "trd": NaN, "batb": [[2, 2.98, 6.49]], "batl": NaN}, {"timestamp": 1632491798274, "ltp": 3.2, "tv": 188.53, "trd": [[3.2, 0.3]], "batb": NaN, "batl": [[0, 3.25, 27.56]]}, {"timestamp": 1632491840675, "ltp": 3.2, "tv": 188.53, "trd": NaN, "batb": NaN, "batl": [[0, 3.15, 30.31], [1, 3.25, 27.56], [2, 46, 29.91]]}, {"timestamp": 1632491841766, "ltp": 3.2, "tv": 188.53, "trd": NaN, "batb": [[2, 2.96, 6.55]], "batl": NaN}, {"timestamp": 1632491857807, "ltp": 3.15, "tv": 195.01, "trd": [[3.15, 6.48]], "batb": [[0, 3, 173.28], [1, 2.96, 6.55], [2, 2.88, 2.65]], "batl": [[0, 3.15, 27.08]]}, {"timestamp": 1632491858602, "ltp": 3.15, "tv": 195.01, "trd": NaN, "batb": [[0, 3.05, 6.86], [1, 3, 173.28], [2, 2.96, 6.55]], "batl": NaN}, {"timestamp": 1632491970006, "ltp": 3.15, "tv": 195.01, "trd": NaN, "batb": [[0, 3.1, 1.17], [1, 3.05, 6.86], [2, 3, 173.28]], "batl": NaN}, {"timestamp": 1632491983926, "ltp": 3.15, "tv": 195.01, "trd": NaN, "batb": [[1, 3, 176.28], [2, 2.98, 3]], "batl": [[2, 3.5, 3]]}, {"timestamp": 1632492025899, "ltp": 3.15, "tv": 195.58, "trd": [[2.74, 25.66], [2.82, 4.92], [3, 20], [3.05, 77.25], [3.15, 7.22]], "batb": [[0, 3.1, 1.17], [1, 3, 175.98], [2, 2.92, 6.68]], "batl": [[0, 3.15, 26.28], [2, 46, 29.87]]}, {"timestamp": 1632492053345, "ltp": 3.15, "tv": 195.58, "trd": NaN, "batb": NaN, "batl": [[2, 4.2, 8.22]]}, {"timestamp": 1632492067164, "ltp": 3.15, "tv": 195.58, "trd": NaN, "batb": NaN, "batl": [[0, 3.25, 27.56], [1, 4.2, 8.22], [2, 46, 28.96]]}, {"timestamp": 1632492067747, "ltp": 3.1, "tv": 248.14, "trd": [[3.1, 112.56]], "batb": [[0, 3, 175.98], [1, 2.92, 6.68], [2, 2.88, 2.65]], "batl": NaN}, {"timestamp": 1632492070750, "ltp": 3.1, "tv": 248.14, "trd": NaN, "batb": [[1, 2.96, 6.54], [2, 2.92, 6.68]], "batl": NaN}, {"timestamp": 1632492082187, "ltp": 3.1, "tv": 248.14, "trd": NaN, "batb": [[2, 2.94, 30.27]], "batl": NaN}, {"timestamp": 1632492087183, "ltp": 3.1, "tv": 248.14, "trd": NaN, "batb": [[2, 2.92, 6.68]], "batl": NaN}, {"timestamp": 1632492088100, "ltp": 3.1, "tv": 248.14, "trd": NaN, "batb": [[2, 2.94, 30.27]], "batl": NaN}, {"timestamp": 1632492088797, "ltp": 3.1, "tv": 248.14, "trd": NaN, "batb": [[0, 3, 175.81]], "batl": NaN}, {"timestamp": 1632492100039, "ltp": 3.1, "tv": 248.14, "trd": NaN, "batb": [[2, 2.92, 36.95]], "batl": NaN}, {"timestamp": 1632492122859, "ltp": 3.1, "tv": 248.7, "trd": [[3.1, 113.12]], "batb": NaN, "batl": [[0, 3.25, 27]]}, {"timestamp": 1632492181076, "ltp": 3.1, "tv": 248.7, "trd": NaN, "batb": [[0, 3, 174.96]], "batl": NaN}, {"timestamp": 1632492303465, "ltp": 3.1, "tv": 248.7, "trd": NaN, "batb": [[0, 3, 16.33], [1, 2.92, 30.27], [2, 1.53, 3.42]], "batl": NaN}, {"timestamp": 1632492306935, "ltp": 3.1, "tv": 248.7, "trd": NaN, "batb": [[2, 1.8, 10.52]], "batl": NaN}, {"timestamp": 1632492321183, "ltp": 7.6, "tv": 249.03, "trd": [[7.6, 0.33]], "batb": NaN, "batl": [[0, 3.7, 4], [1, 3.8, 293.99]]}, {"timestamp": 1632492324183, "ltp": 7.6, "tv": 249.03, "trd": NaN, "batb": NaN, "batl": [[0, 8.2, 2], [1, 3.8, 0]]}, {"timestamp": 1632492324554, "ltp": 7.6, "tv": 251.03, "trd": [[7.6, 2.33]], "batb": NaN, "batl": NaN}, {"timestamp": 1632492327469, "ltp": 7.6, "tv": 251.03, "trd": NaN, "batb": [[2, 2.2, 43.09]], "batl": NaN}, {"timestamp": 1632492332217, "ltp": 7.6, "tv": 251.03, "trd": NaN, "batb": [[0, 3.05, 8.88], [1, 3, 108.05], [2, 2.92, 30.27]], "batl": NaN}, {"timestamp": 1632492333009, "ltp": 7.6, "tv": 251.03, "trd": NaN, "batb": [[1, 3, 672.26]], "batl": NaN}, {"timestamp": 1632492333802, "ltp": 3.2, "tv": 257.83, "trd": [[3.2, 7.11]], "batb": [[0, 3.2, 128.33], [1, 3.05, 8.88], [2, 3, 108.05]], "batl": NaN}, {"timestamp": 1632492335207, "ltp": 3.2, "tv": 257.83, "trd": NaN, "batb": [[1, 3.05, 10.88], [2, 3, 110.05]], "batl": [[0, 8, 2], [1, 8.2, 2]]}, {"timestamp": 1632492338214, "ltp": 3.2, "tv": 257.83, "trd": NaN, "batb": NaN, "batl": [[0, 5.8, 177.94], [1, 8, 2], [2, 8.2, 2]]}, {"timestamp": 1632492338688, "ltp": 3.2, "tv": 257.83, "trd": NaN, "batb": NaN, "batl": [[0, 8, 2], [1, 8.2, 2], [2, 8.2, 0]]}, {"timestamp": 1632492341525, "ltp": 3.2, "tv": 257.83, "trd": NaN, "batb": NaN, "batl": [[0, 6, 175.67], [1, 8, 2], [2, 8.2, 2]]}, {"timestamp": 1632492343210, "ltp": 3.2, "tv": 257.83, "trd": NaN, "batb": [[0, 3.05, 2], [1, 3, 18.33], [2, 2.94, 166.43]], "batl": [[0, 8, 2], [1, 8.2, 2], [2, 8.2, 0]]}, {"timestamp": 1632492343526, "ltp": 3.2, "tv": 257.83, "trd": NaN, "batb": [[0, 3, 16.33], [1, 2.94, 166.43], [2, 2.92, 30.27]], "batl": NaN}, {"timestamp": 1632492346732, "ltp": 3.2, "tv": 257.83, "trd": NaN, "batb": NaN, "batl": [[0, 3.5, 3], [1, 3.65, 2]]}, {"timestamp": 1632492350046, "ltp": 3.4, "tv": 264.16, "trd": [[3.4, 6.33]], "batb": [[0, 3.25, 4.76], [1, 3.1, 175.9], [2, 3, 16.33]], "batl": [[0, 3.65, 2], [1, 3.65, 0]]}, {"timestamp": 1632492351149, "ltp": 3.4, "tv": 264.16, "trd": NaN, "batb": [[0, 3.3, 121.81], [1, 3.25, 4.76], [2, 3.1, 320.23]], "batl": [[1, 4, 7.5]]}, {"timestamp": 1632492360145, "ltp": 3.4, "tv": 264.16, "trd": NaN, "batb": [[0, 3.1, 144.33], [1, 3.05, 3], [2, 3, 19.33]], "batl": [[1, 4, 0]]}, {"timestamp": 1632492362842, "ltp": 3.4, "tv": 264.16, "trd": NaN, "batb": NaN, "batl": [[0, 3.6, 3], [1, 3.65, 2]]}, {"timestamp": 1632492363437, "ltp": 3.4, "tv": 264.16, "trd": NaN, "batb": [[0, 3.1, 147.33]], "batl": NaN}, {"timestamp": 1632492366166, "ltp": 3.1, "tv": 265.78, "trd": [[3.1, 114.74]], "batb": [[0, 3.1, 146.52]], "batl": NaN}, {"timestamp": 1632492366332, "ltp": 3.1, "tv": 265.78, "trd": NaN, "batb": [[1, 3, 16.33], [2, 2.92, 30.27]], "batl": NaN}, {"timestamp": 1632492369542, "ltp": 3.1, "tv": 265.78, "trd": NaN, "batb": [[1, 3.05, 3], [2, 3, 16.33]], "batl": NaN}, {"timestamp": 1632492372059, "ltp": 3.1, "tv": 265.78, "trd": NaN, "batb": [[0, 3.1, 148.79], [1, 3, 16.33], [2, 2.92, 188.3]], "batl": [[0, 3.2, 7.26], [1, 3.6, 3], [2, 3.65, 2]]}, {"timestamp": 1632492373165, "ltp": 3.2, "tv": 273.04, "trd": [[3.2, 14.37]], "batb": [[2, 2.94, 159.86]], "batl": [[0, 3.55, 157.29]]}, {"timestamp": 1632492374063, "ltp": 3.2, "tv": 273.04, "trd": NaN, "batb": NaN, "batl": [[0, 3.6, 3], [1, 3.65, 2], [2, 3.8, 131.57]]}, {"timestamp": 1632492375172, "ltp": 3.2, "tv": 273.04, "trd": NaN, "batb": NaN, "batl": [[1, 3.8, 131.57], [2, 3.85, 61.84]]}, {"timestamp": 1632492382961, "ltp": 3.2, "tv": 273.04, "trd": NaN, "batb": [[0, 3.1, 143.52]], "batl": [[0, 3.6, 262.96]]}, {"timestamp": 1632492386094, "ltp": 3.25, "tv": 275.17, "trd": [[3.25, 2.13]], "batb": [[0, 3.15, 6.23], [1, 3.1, 143.52], [2, 3, 16.33]], "batl": [[0, 3.25, 3.83], [1, 3.6, 3], [2, 3.8, 131.57]]}, {"timestamp": 1632492388106, "ltp": 3.25, "tv": 275.17, "trd": NaN, "batb": [[0, 3.1, 143.52], [1, 3, 16.33], [2, 2.92, 30.27]], "batl": [[0, 3.6, 3], [1, 3.6, 0], [2, 3.8, 0]]}, {"timestamp": 1632492388998, "ltp": 3.25, "tv": 275.17, "trd": NaN, "batb": [[0, 3, 16.33], [1, 2.92, 30.27], [2, 2.86, 71.79]], "batl": NaN}, {"timestamp": 1632492394192, "ltp": 3.25, "tv": 275.17, "trd": NaN, "batb": NaN, "batl": [[0, 3.5, 2], [1, 3.6, 3]]}, {"timestamp": 1632492395199, "ltp": 3.3, "tv": 296.51, "trd": [[3.3, 12.52], [3.4, 15.15]], "batb": [[0, 3.05, 139.44], [1, 3, 16.33], [2, 2.92, 30.27]], "batl": [[0, 3.3, 152.6], [1, 3.4, 4.69], [2, 3.6, 3]]}, {"timestamp": 1632492396092, "ltp": 3.3, "tv": 296.51, "trd": NaN, "batb": [[0, 3.25, 129.06], [1, 3.05, 289.68], [2, 3, 16.33]], "batl": [[1, 3.6, 3], [2, 4, 7.5]]}, {"timestamp": 1632492397998, "ltp": 3.3, "tv": 296.51, "trd": NaN, "batb": [[1, 3.05, 291.68], [2, 3, 18.33]], "batl": [[1, 3.55, 3], [2, 3.6, 3]]}, {"timestamp": 1632492398988, "ltp": 3.3, "tv": 296.51, "trd": NaN, "batb": [[0, 3.25, 134.81]], "batl": [[1, 3.35, 5.5], [2, 3.55, 3]]}, {"timestamp": 1632492405140, "ltp": 3.3, "tv": 296.51, "trd": NaN, "batb": [[0, 3.25, 129.06]], "batl": [[1, 3.55, 3], [2, 3.6, 3]]}, {"timestamp": 1632492407033, "ltp": 3.3, "tv": 296.51, "trd": NaN, "batb": [[0, 3.05, 152.24], [1, 3, 18.33], [2, 2.92, 30.27]], "batl": [[0, 3.55, 3], [1, 3.6, 3], [2, 3.6, 0]]}, {"timestamp": 1632492410131, "ltp": 3.3, "tv": 296.51, "trd": NaN, "batb": [[1, 3, 16.33]], "batl": [[1, 3.6, 0]]}, {"timestamp": 1632492413027, "ltp": 3.3, "tv": 296.51, "trd": NaN, "batb": [[0, 3.1, 3], [1, 3.05, 152.24], [2, 3, 16.33]], "batl": NaN}, {"timestamp": 1632492414139, "ltp": 3.3, "tv": 296.51, "trd": NaN, "batb": [[0, 3.35, 285.44], [1, 3.3, 277.04], [2, 3.25, 277.04]], "batl": NaN}, {"timestamp": 1632492414731, "ltp": 3.3, "tv": 296.51, "trd": NaN, "batb": [[0, 3.35, 403.88]], "batl": [[0, 4.1, 7.32]]}, {"timestamp": 1632492416936, "ltp": 3.3, "tv": 296.51, "trd": NaN, "batb": [[2, 3.25, 280.04]], "batl": NaN}, {"timestamp": 1632492425153, "ltp": 3.3, "tv": 296.51, "trd": NaN, "batb": [[2, 3.25, 277.04]], "batl": [[0, 4, 607.31], [1, 4.1, 7.32]]}, {"timestamp": 1632492457219, "ltp": 3.3, "tv": 296.51, "trd": NaN, "batb": NaN, "batl": [[1, 4.1, 0]]}, {"timestamp": 1632492457904, "ltp": 3.3, "tv": 296.51, "trd": NaN, "batb": [[0, 3.15, 135.9], [1, 3, 16.33], [2, 2.92, 30.27]], "batl": NaN}, {"timestamp": 1632492461124, "ltp": 3.3, "tv": 296.51, "trd": NaN, "batb": [[0, 3.15, 138.9], [1, 3.1, 3], [2, 3, 16.33]], "batl": [[0, 3.95, 3]]}, {"timestamp": 1632492470027, "ltp": 3.3, "tv": 296.51, "trd": NaN, "batb": [[0, 3.15, 135.9], [1, 3, 16.33], [2, 2.92, 30.27]], "batl": NaN}, {"timestamp": 1632492471132, "ltp": 3.3, "tv": 296.51, "trd": NaN, "batb": [[0, 3.15, 142.74], [1, 3, 141.09]], "batl": [[0, 3.25, 5.27], [1, 3.3, 310.06], [2, 3.35, 71.22]]}, {"timestamp": 1632492471858, "ltp": 3.25, "tv": 301.78, "trd": [[3.25, 7.4]], "batb": [[1, 3, 294.87]], "batl": [[0, 3.3, 310.06], [1, 3.35, 71.22], [2, 3.4, 71.22]]}, {"timestamp": 1632492481777, "ltp": 3.25, "tv": 301.78, "trd": NaN, "batb": [[0, 3.15, 135.9]], "batl": NaN}, {"timestamp": 1632492484089, "ltp": 3.15, "tv": 301.91, "trd": [[3.15, 7.29], [3.2, 14.43]], "batb": [[0, 3.15, 135.86]], "batl": NaN}, {"timestamp": 1632492484682, "ltp": 3.15, "tv": 301.91, "trd": NaN, "batb": [[0, 3.2, 5.99], [1, 3.15, 135.86], [2, 3, 294.87]], "batl": [[0, 3.3, 315.8]]}, {"timestamp": 1632492485958, "ltp": 3.15, "tv": 301.91, "trd": NaN, "batb": [[0, 3, 170.11], [1, 2.92, 30.27], [2, 2, 10.52]], "batl": [[0, 3.9, 2], [1, 3.35, 0], [2, 3.4, 0]]}, {"timestamp": 1632492489179, "ltp": 3.15, "tv": 301.91, "trd": NaN, "batb": [[0, 3, 173.11], [1, 2.98, 4], [2, 2.92, 30.27]], "batl": [[0, 3.55, 3], [1, 3.8, 3], [2, 3.9, 2]]}, {"timestamp": 1632492492076, "ltp": 3.15, "tv": 301.91, "trd": NaN, "batb": [[0, 3, 170.11], [1, 2.92, 30.27], [2, 2, 10.52]], "batl": NaN}, {"timestamp": 1632492492872, "ltp": 3.15, "tv": 301.91, "trd": NaN, "batb": [[0, 3.05, 8.66], [1, 3, 170.11], [2, 2.92, 30.27]], "batl": [[0, 3.25, 294.22], [1, 3.3, 285.58], [2, 3.35, 285.58]]}, {"timestamp": 1632492493879, "ltp": 3.15, "tv": 301.91, "trd": NaN, "batb": [[2, 2.92, 98.18]], "batl": NaN}, {"timestamp": 1632492503797, "ltp": 3.15, "tv": 301.91, "trd": NaN, "batb": [[0, 3, 170.11], [1, 2.92, 98.18], [2, 2, 10.52]], "batl": NaN}, {"timestamp": 1632492509708, "ltp": 3.15, "tv": 301.91, "trd": NaN, "batb": [[2, 2.84, 8.15]], "batl": [[0, 3.25, 304.22]]}, {"timestamp": 1632492514129, "ltp": 3.15, "tv": 301.91, "trd": NaN, "batb": NaN, "batl": [[0, 3.25, 157.11], [1, 3.3, 142.79], [2, 3.35, 142.79]]}, {"timestamp": 1632492515017, "ltp": 3.15, "tv": 301.91, "trd": NaN, "batb": [[0, 3, 16.33]], "batl": [[0, 3.25, 10], [1, 3.5, 3], [2, 3.35, 0]]}, {"timestamp": 1632492515330, "ltp": 3.15, "tv": 301.91, "trd": NaN, "batb": [[2, 2, 10.52]], "batl": [[0, 3.5, 3], [1, 3.5, 0]]}, {"timestamp": 1632492516227, "ltp": 3.15, "tv": 301.91, "trd": NaN, "batb": [[1, 2.94, 4], [2, 2.92, 101.18]], "batl": NaN}, {"timestamp": 1632492517757, "ltp": 3.15, "tv": 301.91, "trd": NaN, "batb": [[0, 3, 19.33], [1, 2.98, 4], [2, 2.94, 4]], "batl": NaN}, {"timestamp": 1632492520553, "ltp": 3.15, "tv": 301.91, "trd": NaN, "batb": NaN, "batl": [[0, 3.4, 3], [1, 3.5, 3]]}, {"timestamp": 1632492522154, "ltp": 3.15, "tv": 301.91, "trd": NaN, "batb": [[0, 3, 16.33], [1, 2.92, 98.18], [2, 2, 10.52]], "batl": NaN}, {"timestamp": 1632492523154, "ltp": 3.15, "tv": 301.91, "trd": NaN, "batb": [[0, 3, 21.36], [2, 2.86, 334.36]], "batl": [[0, 3.2, 298.82], [1, 3.25, 725.1], [2, 3.3, 290.04]]}, {"timestamp": 1632492523631, "ltp": 3.15, "tv": 301.91, "trd": NaN, "batb": [[2, 2.86, 405.81]], "batl": [[1, 3.25, 290.04]]}, {"timestamp": 1632492525062, "ltp": 3.15, "tv": 301.91, "trd": NaN, "batb": NaN, "batl": [[0, 3.15, 10.22], [1, 3.2, 298.82], [2, 3.25, 290.04]]}, {"timestamp": 1632492536985, "ltp": 3.15, "tv": 301.91, "trd": NaN, "batb": [[0, 3, 16.33], [1, 2.92, 30.27], [2, 2.86, 71.45]], "batl": [[1, 3.35, 3], [2, 3.25, 0]]}, {"timestamp": 1632492538366, "ltp": 3.15, "tv": 301.91, "trd": NaN, "batb": NaN, "batl": [[0, 3.35, 3], [1, 3.35, 0]]}, {"timestamp": 1632492540086, "ltp": 3.15, "tv": 301.91, "trd": NaN, "batb": [[0, 3, 19.33], [1, 2.98, 3], [2, 2.92, 30.27]], "batl": NaN}, {"timestamp": 1632492542794, "ltp": 3.15, "tv": 301.91, "trd": NaN, "batb": NaN, "batl": [[0, 3.25, 3], [1, 3.35, 3]]}, {"timestamp": 1632492545207, "ltp": 3.15, "tv": 301.91, "trd": NaN, "batb": [[0, 3.1, 20], [1, 3, 19.33], [2, 2.98, 3]], "batl": NaN}, {"timestamp": 1632492546209, "ltp": 2.96, "tv": 359.0, "trd": [[2.96, 11.76], [2.98, 6], [3, 39.33], [3.1, 134.74]], "batb": [[0, 2.92, 30.27], [1, 2.86, 71.45], [2, 2.78, 144.1]], "batl": [[0, 2.96, 126.02], [1, 3.05, 1261.12], [2, 3.1, 1217.22]]}, {"timestamp": 1632492547211, "ltp": 2.96, "tv": 369.27, "trd": [[2.96, 22.03]], "batb": NaN, "batl": [[0, 2.96, 115.75], [1, 3.05, 320.54], [2, 3.1, 304.3]]}, {"timestamp": 1632492548210, "ltp": 2.96, "tv": 369.27, "trd": NaN, "batb": NaN, "batl": [[1, 3.05, 331.01]]}, {"timestamp": 1632492548689, "ltp": 2.96, "tv": 370.39, "trd": [[2.96, 23.15]], "batb": NaN, "batl": [[0, 2.96, 114.63], [1, 3.05, 320.54]]}, {"timestamp": 1632492552125, "ltp": 2.96, "tv": 370.39, "trd": NaN, "batb": NaN, "batl": [[1, 3, 10.6], [2, 3.05, 320.54]]}, {"timestamp": 1632492552505, "ltp": 2.96, "tv": 370.39, "trd": NaN, "batb": NaN, "batl": [[1, 3.05, 320.54], [2, 3.1, 304.3]]}, {"timestamp": 1632492556020, "ltp": 2.92, "tv": 372.67, "trd": [[2.92, 2.28]], "batb": [[0, 2.92, 29.13]], "batl": [[0, 2.96, 125.34]]}, {"timestamp": 1632492556504, "ltp": 2.92, "tv": 372.67, "trd": NaN, "batb": NaN, "batl": [[1, 3.05, 313.52]]}, {"timestamp": 1632492559326, "ltp": 2.92, "tv": 372.67, "trd": NaN, "batb": NaN, "batl": [[1, 3, 5.8], [2, 3.05, 313.52]]}, {"timestamp": 1632492569123, "ltp": 2.92, "tv": 372.67, "trd": NaN, "batb": [[2, 2.6, 91.69]], "batl": [[0, 2.96, 10.71], [1, 3.25, 3], [2, 3.65, 173.5]]}, {"timestamp": 1632492569906, "ltp": 2.92, "tv": 372.67, "trd": NaN, "batb": [[1, 2.6, 91.69], [2, 2, 10.52]], "batl": [[1, 3.65, 173.5], [2, 3.65, 0]]}, {"timestamp": 1632492570327, "ltp": 2.92, "tv": 372.67, "trd": NaN, "batb": NaN, "batl": [[0, 3.65, 173.5], [1, 3.65, 0]]}, {"timestamp": 1632492578143, "ltp": 2.92, "tv": 401.8, "trd": [[2.92, 31.41]], "batb": [[0, 2.66, 6.05]], "batl": [[0, 2.72, 5.25], [1, 2.8, 1366.08], [2, 2.82, 1325.9]]}, {"timestamp": 1632492579145, "ltp": 2.92, "tv": 401.8, "trd": NaN, "batb": [[2, 1.97, 402.02]], "batl": [[1, 2.8, 341.52], [2, 2.82, 331.48]]}, {"timestamp": 1632492579936, "ltp": 2.92, "tv": 401.8, "trd": NaN, "batb": [[2, 2.3, 125.86]], "batl": NaN}, {"timestamp": 1632492581960, "ltp": 2.92, "tv": 401.8, "trd": NaN, "batb": NaN, "batl": [[0, 2.72, 16.68]]}, {"timestamp": 1632492583167, "ltp": 2.92, "tv": 401.8, "trd": NaN, "batb": NaN, "batl": [[1, 2.8, 366.91]]}, {"timestamp": 1632492583471, "ltp": 2.92, "tv": 401.8, "trd": NaN, "batb": NaN, "batl": [[1, 2.8, 341.52]]}, {"timestamp": 1632492594178, "ltp": 2.66, "tv": 413.64, "trd": [[2.66, 11.84]], "batb": [[0, 2.6, 91.82], [1, 2.3, 125.86], [2, 1.97, 402.02]], "batl": NaN}, {"timestamp": 1632492596177, "ltp": 2.66, "tv": 413.64, "trd": NaN, "batb": [[0, 2.3, 125.86], [1, 1.97, 402.02], [2, 1.8, 10.52]], "batl": [[0, 2.72, 11.43], [1, 3.45, 183.67], [2, 2.82, 0]]}, {"timestamp": 1632492597760, "ltp": 2.66, "tv": 413.64, "trd": NaN, "batb": NaN, "batl": [[0, 3.45, 183.67], [1, 3.45, 0]]}, {"timestamp": 1632492599675, "ltp": 2.66, "tv": 413.64, "trd": NaN, "batb": [[0, 2.3, 129.86], [1, 2.28, 3], [2, 1.97, 402.02]], "batl": NaN}, {"timestamp": 1632492602868, "ltp": 2.66, "tv": 413.64, "trd": NaN, "batb": [[0, 2.42, 4], [1, 2.4, 3], [2, 2.38, 3]], "batl": NaN}, {"timestamp": 1632492608373, "ltp": 2.66, "tv": 413.64, "trd": NaN, "batb": [[0, 2.3, 125.86], [1, 2.28, 3], [2, 1.8, 10.52]], "batl": NaN}, {"timestamp": 1632492610198, "ltp": 2.66, "tv": 413.64, "trd": NaN, "batb": [[0, 2.32, 9.67], [1, 2.3, 125.86], [2, 2.28, 3]], "batl": [[0, 2.48, 385.58], [1, 2.5, 374.24], [2, 2.52, 374.24]]}, {"timestamp": 1632492610994, "ltp": 2.66, "tv": 413.64, "trd": NaN, "batb": [[2, 2.04, 180.69]], "batl": NaN}, {"timestamp": 1632492612097, "ltp": 2.66, "tv": 413.64, "trd": NaN, "batb": [[2, 2.26, 3]], "batl": [[0, 2.44, 50], [1, 2.48, 385.58], [2, 2.5, 374.24]]}, {"timestamp": 1632492620911, "ltp": 2.66, "tv": 413.64, "trd": NaN, "batb": [[0, 2.3, 125.86], [1, 2.26, 3], [2, 2.04, 180.69]], "batl": NaN}, {"timestamp": 1632492623830, "ltp": 2.66, "tv": 413.64, "trd": NaN, "batb": [[0, 2.36, 7.58], [1, 2.3, 125.86], [2, 2.26, 3]], "batl": [[0, 2.42, 7.81], [1, 2.44, 50], [2, 2.48, 385.58]]}, {"timestamp": 1632492629134, "ltp": 2.66, "tv": 413.64, "trd": NaN, "batb": NaN, "batl": [[1, 2.48, 385.58], [2, 2.5, 374.24]]}, {"timestamp": 1632492632360, "ltp": 2.66, "tv": 413.64, "trd": NaN, "batb": NaN, "batl": [[0, 2.42, 58.16]]}, {"timestamp": 1632492633944, "ltp": 2.66, "tv": 413.64, "trd": NaN, "batb": [[0, 2.04, 180.52], [1, 1.77, 409.56], [2, 1.7, 15.02]], "batl": [[0, 2.42, 50.35], [1, 2.96, 3], [2, 3, 217.32]]}, {"timestamp": 1632492635356, "ltp": 2.66, "tv": 413.64, "trd": NaN, "batb": NaN, "batl": [[0, 2.96, 3], [1, 3, 217.32], [2, 3, 0]]}, {"timestamp": 1632492637117, "ltp": 2.66, "tv": 413.64, "trd": NaN, "batb": [[0, 2.18, 12.71], [1, 2.04, 180.52], [2, 1.77, 409.56]], "batl": NaN}, {"timestamp": 1632492637438, "ltp": 2.66, "tv": 413.64, "trd": NaN, "batb": [[0, 2.04, 180.52], [1, 1.77, 409.56], [2, 1.7, 15.02]], "batl": NaN}, {"timestamp": 1632492649071, "ltp": 2.66, "tv": 413.64, "trd": NaN, "batb": [[0, 2.06, 2830.18], [1, 2.04, 180.52], [2, 1.8, 10.52]], "batl": [[0, 2.6, 262.37], [1, 2.96, 3], [2, 3, 217.32]]}, {"timestamp": 1632492650070, "ltp": 2.66, "tv": 413.64, "trd": NaN, "batb": [[0, 2.48, 103.25], [1, 2.16, 152.94]], "batl": [[1, 2.92, 1.71], [2, 2.96, 3]]}, {"timestamp": 1632492651172, "ltp": 2.66, "tv": 413.64, "trd": NaN, "batb": NaN, "batl": [[0, 2.58, 47.73], [1, 2.6, 262.37], [2, 2.92, 1.71]]}, {"timestamp": 1632492651751, "ltp": 2.66, "tv": 413.64, "trd": NaN, "batb": [[1, 2.42, 4], [2, 2.16, 152.94]], "batl": NaN}, {"timestamp": 1632492659752, "ltp": 2.66, "tv": 413.64, "trd": NaN, "batb": NaN, "batl": [[2, 2.96, 3]]}, {"timestamp": 1632492663067, "ltp": 2.66, "tv": 413.64, "trd": NaN, "batb": NaN, "batl": [[0, 2.6, 262.37], [1, 2.96, 3], [2, 3, 217.32]]}, {"timestamp": 1632492665990, "ltp": 2.66, "tv": 413.64, "trd": NaN, "batb": NaN, "batl": [[1, 2.62, 47.14], [2, 2.96, 3]]}, {"timestamp": 1632492673197, "ltp": 2.66, "tv": 413.64, "trd": NaN, "batb": [[0, 2.16, 152.68], [1, 1.77, 409.56], [2, 1.7, 15.02]], "batl": [[0, 2.62, 47.14], [1, 2.96, 3], [2, 3, 217.32]]}, {"timestamp": 1632492674319, "ltp": 2.66, "tv": 413.64, "trd": NaN, "batb": NaN, "batl": [[0, 2.96, 3], [1, 3, 217.32], [2, 3, 0]]}, {"timestamp": 1632492676709, "ltp": 2.66, "tv": 413.64, "trd": NaN, "batb": [[0, 2.24, 3], [1, 2.22, 4], [2, 2.16, 152.68]], "batl": NaN}, {"timestamp": 1632492677974, "ltp": 2.66, "tv": 413.64, "trd": NaN, "batb": NaN, "batl": [[2, 1000, 0.07]]}, {"timestamp": 1632492679178, "ltp": 2.66, "tv": 413.64, "trd": NaN, "batb": NaN, "batl": [[2, 1000, 0]]}, {"timestamp": 1632492681903, "ltp": 2.66, "tv": 413.64, "trd": NaN, "batb": NaN, "batl": [[2, 810, 0.07]]}, {"timestamp": 1632492690200, "ltp": 2.66, "tv": 413.64, "trd": NaN, "batb": [[1, 2.16, 152.68], [2, 1.77, 409.56]], "batl": NaN}, {"timestamp": 1632492691718, "ltp": 2.66, "tv": 413.64, "trd": NaN, "batb": [[0, 2.16, 152.68], [1, 1.77, 409.56], [2, 1.6, 87.64]], "batl": [[1, 810, 0.07], [2, 810, 0]]}, {"timestamp": 1632492693199, "ltp": 2.24, "tv": 421.27, "trd": [[2.24, 7.63]], "batb": [[1, 2.12, 451.06], [2, 2.1, 437.8]], "batl": [[0, 2.24, 6.15], [1, 2.6, 1.71], [2, 2.66, 1830.6]]}, {"timestamp": 1632492694205, "ltp": 2.24, "tv": 427.42, "trd": [[2.24, 13.78]], "batb": NaN, "batl": [[0, 2.32, 52.22]]}, {"timestamp": 1632492695729, "ltp": 2.24, "tv": 427.42, "trd": NaN, "batb": NaN, "batl": [[0, 2.6, 1.71], [1, 2.66, 1830.6], [2, 2.82, 235.47]]}, {"timestamp": 1632492697038, "ltp": 2.24, "tv": 427.42, "trd": NaN, "batb": NaN, "batl": [[0, 2.56, 979.96], [1, 2.6, 1.71], [2, 2.66, 1830.6]]}, {"timestamp": 1632492697937, "ltp": 2.24, "tv": 427.42, "trd": NaN, "batb": NaN, "batl": [[0, 2.6, 1.71], [1, 2.66, 1830.6], [2, 2.82, 235.47]]}, {"timestamp": 1632492699166, "ltp": 2.24, "tv": 427.42, "trd": NaN, "batb": NaN, "batl": [[0, 2.32, 52.22], [1, 2.6, 1.71], [2, 2.66, 1830.6]]}, {"timestamp": 1632492703528, "ltp": 2.24, "tv": 427.42, "trd": NaN, "batb": NaN, "batl": [[1, 2.66, 1830.6], [2, 2.82, 235.47]]}, {"timestamp": 1632492709172, "ltp": 2.24, "tv": 427.42, "trd": NaN, "batb": NaN, "batl": [[0, 2.28, 11.88], [1, 2.32, 52.22], [2, 2.66, 1830.6]]}, {"timestamp": 1632492709852, "ltp": 2.24, "tv": 427.42, "trd": NaN, "batb": [[0, 2.08, 13.88], [1, 1.89, 114.13], [2, 1.77, 409.56]], "batl": [[0, 2.32, 52.22], [1, 2.82, 235.47], [2, 2.96, 3]]}, {"timestamp": 1632492712057, "ltp": 2.24, "tv": 427.42, "trd": NaN, "batb": [[0, 1.89, 114.13], [1, 1.77, 409.56], [2, 1.6, 87.64]], "batl": [[0, 2.82, 235.47], [1, 2.96, 3], [2, 810, 0.07]]}, {"timestamp": 1632492715157, "ltp": 2.24, "tv": 427.42, "trd": NaN, "batb": [[0, 1.89, 119.13], [1, 1.88, 4], [2, 1.77, 409.56]], "batl": [[2, 1000, 0.15]]}, {"timestamp": 1632492716051, "ltp": 2.24, "tv": 427.42, "trd": NaN, "batb": [[0, 1.9, 4], [1, 1.89, 119.13], [2, 1.88, 4]], "batl": [[2, 810, 0.07]]}, {"timestamp": 1632492718669, "ltp": 2.24, "tv": 427.42, "trd": NaN, "batb": NaN, "batl": [[2, 820, 0.15]]}, {"timestamp": 1632492719656, "ltp": 2.24, "tv": 427.42, "trd": NaN, "batb": NaN, "batl": [[2, 810, 0.07]]}, {"timestamp": 1632492726405, "ltp": 2.24, "tv": 427.42, "trd": NaN, "batb": [[1, 1.89, 114.13], [2, 1.77, 409.56]], "batl": NaN}, {"timestamp": 1632492729103, "ltp": 2.42, "tv": 440.27, "trd": [[2.42, 12.85]], "batb": [[0, 2.4, 9.14], [1, 2.24, 229.24], [2, 1.9, 4]], "batl": [[0, 2.42, 233.77], [1, 2.82, 235.47], [2, 2.96, 3]]}, {"timestamp": 1632492730182, "ltp": 2.42, "tv": 440.27, "trd": NaN, "batb": [[1, 2.34, 122.48], [2, 2.24, 229.24]], "batl": [[1, 2.5, 48.98], [2, 2.66, 1.71]]}, {"timestamp": 1632492732128, "ltp": 2.42, "tv": 450.35, "trd": [[2.42, 22.93]], "batb": [[2, 2.3, 4]], "batl": [[0, 2.42, 228.73]]}, {"timestamp": 1632492734223, "ltp": 2.42, "tv": 450.35, "trd": NaN, "batb": NaN, "batl": [[1, 2.66, 1.71], [2, 2.82, 235.47]]}, {"timestamp": 1632492737521, "ltp": 2.42, "tv": 450.35, "trd": NaN, "batb": NaN, "batl": [[1, 2.46, 49.65], [2, 2.66, 1.71]]}, {"timestamp": 1632492740897, "ltp": 2.42, "tv": 450.35, "trd": NaN, "batb": NaN, "batl": [[2, 2.82, 235.47]]}, {"timestamp": 1632492749129, "ltp": 2.4, "tv": 451.48, "trd": [[2.4, 1.13]], "batb": [[0, 2.4, 8.01]], "batl": NaN}, {"timestamp": 1632492755957, "ltp": 2.4, "tv": 451.48, "trd": NaN, "batb": [[0, 1.92, 109.41], [1, 1.77, 409.56], [2, 1.7, 15.02]], "batl": [[0, 2.46, 49.65], [1, 2.82, 235.47], [2, 2.96, 3]]}, {"timestamp": 1632492757183, "ltp": 2.4, "tv": 451.48, "trd": NaN, "batb": NaN, "batl": [[0, 2.82, 235.47], [1, 2.96, 3], [2, 810, 0.07]]}, {"timestamp": 1632492759223, "ltp": 2.4, "tv": 451.48, "trd": NaN, "batb": [[0, 1.92, 113.41], [1, 1.91, 3], [2, 1.77, 409.56]], "batl": NaN}, {"timestamp": 1632492760166, "ltp": 2.4, "tv": 451.48, "trd": NaN, "batb": NaN, "batl": [[0, 2.82, 239.47]]}, {"timestamp": 1632492762061, "ltp": 2.42, "tv": 463.4, "trd": [[2.42, 26.01], [2.62, 2.69], [2.78, 6.15]], "batb": NaN, "batl": NaN}, {"timestamp": 1632492770351, "ltp": 2.42, "tv": 463.4, "trd": NaN, "batb": [[1, 1.77, 409.56], [2, 1.7, 15.02]], "batl": NaN}, {"timestamp": 1632492772051, "ltp": 2.42, "tv": 463.4, "trd": NaN, "batb": NaN, "batl": [[1, 810, 0.07], [2, 810, 0]]}, {"timestamp": 1632492777973, "ltp": 2.42, "tv": 463.4, "trd": NaN, "batb": [[1, 1.91, 2], [2, 1.77, 409.56]], "batl": NaN}, {"timestamp": 1632492778979, "ltp": 2.42, "tv": 463.4, "trd": NaN, "batb": [[2, 1.7, 15.02]], "batl": [[0, 2.82, 4]]}, {"timestamp": 1632492780188, "ltp": 2.42, "tv": 463.4, "trd": NaN, "batb": [[0, 2.64, 362.22], [1, 2.62, 351.56], [2, 2.6, 351.56]], "batl": [[0, 2.78, 275.83], [1, 2.84, 13.67], [2, 2.9, 329.74]]}, {"timestamp": 1632492781216, "ltp": 2.42, "tv": 463.4, "trd": NaN, "batb": [[0, 2.66, 86.72], [1, 2.64, 362.22], [2, 2.62, 351.56]], "batl": [[0, 2.78, 320.8]]}, {"timestamp": 1632492798200, "ltp": 2.42, "tv": 463.4, "trd": NaN, "batb": NaN, "batl": [[1, 2.9, 329.74], [2, 2.92, 320.04]]}, {"timestamp": 1632492800043, "ltp": 2.42, "tv": 463.4, "trd": NaN, "batb": [[1, 2.6, 4], [2, 2.58, 3]], "batl": [[0, 2.78, 44.97], [1, 3.45, 183.67], [2, 810, 0.07]]}, {"timestamp": 1632492801002, "ltp": 2.42, "tv": 463.4, "trd": NaN, "batb": [[0, 2.3, 127.21], [1, 1.92, 402.07], [2, 1.8, 10.52]], "batl": NaN}, {"timestamp": 1632492801327, "ltp": 2.42, "tv": 463.4, "trd": NaN, "batb": NaN, "batl": [[0, 3.45, 183.67], [1, 810, 0.07], [2, 810, 0]]}, {"timestamp": 1632492805142, "ltp": 2.42, "tv": 463.4, "trd": NaN, "batb": [[0, 2.3, 131.21], [1, 2.28, 4], [2, 1.92, 402.07]], "batl": NaN}, {"timestamp": 1632492806210, "ltp": 2.42, "tv": 463.4, "trd": NaN, "batb": NaN, "batl": [[0, 3.1, 3]]}, {"timestamp": 1632492807028, "ltp": 2.32, "tv": 463.83, "trd": [[2.32, 0.43]], "batb": NaN, "batl": NaN}, {"timestamp": 1632492809856, "ltp": 2.32, "tv": 463.83, "trd": NaN, "batb": NaN, "batl": [[1, 3.3, 195.4], [2, 810, 0.07]]}, {"timestamp": 1632492816933, "ltp": 2.32, "tv": 463.83, "trd": NaN, "batb": [[1, 1.92, 402.07], [2, 1.7, 15.02]], "batl": NaN}, {"timestamp": 1632492819157, "ltp": 2.32, "tv": 463.83, "trd": NaN, "batb": NaN, "batl": [[1, 810, 0.07], [2, 810, 0]]}, {"timestamp": 1632492820161, "ltp": 2.32, "tv": 463.83, "trd": NaN, "batb": [[2, 1.6, 87.64]], "batl": [[0, 810, 0.07], [1, 810, 0]]}, {"timestamp": 1632492821169, "ltp": 2.96, "tv": 474.24, "trd": [[2.96, 33.56]], "batb": [[0, 2.9, 329.74], [1, 2.88, 328.62], [2, 2.86, 320.04]], "batl": [[0, 2.96, 212.45], [1, 3, 4.74], [2, 3.2, 298.82]]}, {"timestamp": 1632492822162, "ltp": 2.96, "tv": 474.24, "trd": NaN, "batb": [[1, 2.88, 399.31]], "batl": [[1, 2.98, 42.64], [2, 3, 4.74]]}, {"timestamp": 1632492823164, "ltp": 2.96, "tv": 474.24, "trd": NaN, "batb": NaN, "batl": [[1, 3, 4.74], [2, 3.2, 298.82]]}, {"timestamp": 1632492823961, "ltp": 2.96, "tv": 478.7, "trd": [[2.96, 38.02]], "batb": NaN, "batl": [[0, 2.96, 210.22]]}, {"timestamp": 1632492825686, "ltp": 2.96, "tv": 518.07, "trd": [[2.96, 77.39]], "batb": NaN, "batl": [[0, 2.96, 170.85], [1, 2.98, 42.64], [2, 3, 4.74]]}, {"timestamp": 1632492830997, "ltp": 2.9, "tv": 546.33, "trd": [[2.9, 28.26]], "batb": [[0, 2.9, 301.48]], "batl": NaN}, {"timestamp": 1632492834168, "ltp": 2.9, "tv": 546.66, "trd": [[2.9, 28.59]], "batb": [[0, 2.9, 301.15]], "batl": NaN}, {"timestamp": 1632492834906, "ltp": 2.9, "tv": 548.26, "trd": [[2.9, 30.19]], "batb": [[0, 2.9, 299.55]], "batl": NaN}, {"timestamp": 1632492839207, "ltp": 2.9, "tv": 548.26, "trd": NaN, "batb": [[0, 2.6, 91.27], [1, 2.36, 3], [2, 1.92, 402.07]], "batl": [[0, 2.98, 42.64], [1, 3.65, 173.5], [2, 810, 0.07]]}, {"timestamp": 1632492840313, "ltp": 2.9, "tv": 548.26, "trd": NaN, "batb": NaN, "batl": [[0, 3.65, 173.5], [1, 810, 0.07], [2, 810, 0]]}, {"timestamp": 1632492842217, "ltp": 2.9, "tv": 548.26, "trd": NaN, "batb": [[0, 2.8, 3], [1, 2.78, 3], [2, 2.6, 91.27]], "batl": NaN}, {"timestamp": 1632492842692, "ltp": 2.9, "tv": 548.26, "trd": NaN, "batb": [[0, 2.6, 94.27], [1, 2.58, 3], [2, 2.36, 3]], "batl": NaN}, {"timestamp": 1632492843619, "ltp": 2.9, "tv": 548.26, "trd": NaN, "batb": NaN, "batl": [[0, 3.3, 3], [1, 3.65, 173.5], [2, 810, 0.07]]}, {"timestamp": 1632492844312, "ltp": 2.9, "tv": 548.26, "trd": NaN, "batb": NaN, "batl": [[1, 810, 0.07], [2, 810, 0]]}, {"timestamp": 1632492846217, "ltp": 2.9, "tv": 548.26, "trd": NaN, "batb": [[0, 2.6, 91.27], [1, 2.36, 3], [2, 1.92, 402.07]], "batl": [[0, 3.25, 3], [1, 3.3, 3], [2, 810, 0.07]]}, {"timestamp": 1632492847223, "ltp": 2.72, "tv": 555.58, "trd": [[2.72, 5.08], [3.2, 16.67]], "batb": NaN, "batl": [[0, 2.72, 251.1], [1, 2.8, 341.52], [2, 2.82, 331.48]]}, {"timestamp": 1632492848015, "ltp": 2.72, "tv": 566.9, "trd": [[2.72, 16.4]], "batb": [[2, 2.26, 132.44]], "batl": [[0, 2.72, 239.78]]}, {"timestamp": 1632492849126, "ltp": 2.72, "tv": 566.9, "trd": NaN, "batb": [[1, 2.56, 3], [2, 2.54, 3]], "batl": NaN}, {"timestamp": 1632492851904, "ltp": 2.72, "tv": 566.9, "trd": NaN, "batb": NaN, "batl": [[0, 2.72, 285.52]]}, {"timestamp": 1632492860833, "ltp": 2.72, "tv": 566.9, "trd": NaN, "batb": [[2, 2.26, 132.44]], "batl": NaN}, {"timestamp": 1632492864051, "ltp": 2.72, "tv": 566.9, "trd": NaN, "batb": [[2, 2.54, 3]], "batl": NaN}, {"timestamp": 1632492865157, "ltp": 2.72, "tv": 566.9, "trd": NaN, "batb": [[0, 2.34, 3.72], [1, 2.26, 135.92], [2, 1.92, 402.07]], "batl": [[0, 2.72, 45.74], [1, 3.2, 3], [2, 3.3, 195.4]]}, {"timestamp": 1632492866162, "ltp": 2.72, "tv": 566.9, "trd": NaN, "batb": [[0, 2.26, 135.75], [1, 1.92, 402.07], [2, 1.8, 10.52]], "batl": NaN}, {"timestamp": 1632492866265, "ltp": 2.72, "tv": 566.9, "trd": NaN, "batb": NaN, "batl": [[0, 3.2, 3], [1, 3.3, 195.4], [2, 810, 0.07]]}, {"timestamp": 1632492868164, "ltp": 2.72, "tv": 566.9, "trd": NaN, "batb": NaN, "batl": [[0, 3.05, 2.1], [1, 3.2, 3], [2, 3.3, 195.4]]}, {"timestamp": 1632492868953, "ltp": 2.72, "tv": 566.9, "trd": NaN, "batb": [[0, 2.34, 6.22], [1, 2.32, 3], [2, 2.3, 4]], "batl": NaN}, {"timestamp": 1632492869952, "ltp": 2.72, "tv": 566.9, "trd": NaN, "batb": [[0, 2.34, 3]], "batl": NaN}, {"timestamp": 1632492871162, "ltp": 2.72, "tv": 566.9, "trd": NaN, "batb": [[0, 2.36, 3], [1, 2.34, 3], [2, 2.32, 3]], "batl": NaN}, {"timestamp": 1632492872169, "ltp": 2.76, "tv": 576.01, "trd": [[2.76, 1.24], [2.88, 1.16], [2.92, 33.69], [2.96, 79.63], [3, 41.52]], "batb": NaN, "batl": NaN}, {"timestamp": 1632492876074, "ltp": 2.76, "tv": 576.01, "trd": NaN, "batb": [[1, 2.34, 6.72]], "batl": NaN}, {"timestamp": 1632492876975, "ltp": 2.76, "tv": 576.01, "trd": NaN, "batb": [[1, 2.34, 3]], "batl": NaN}, {"timestamp": 1632492880859, "ltp": 2.76, "tv": 576.01, "trd": NaN, "batb": [[1, 2.26, 135.75], [2, 1.92, 402.07]], "batl": [[2, 810, 0.07]]}, {"timestamp": 1632492882179, "ltp": 2.92, "tv": 577.15, "trd": [[2.92, 34.83]], "batb": [[0, 2.88, 6.77], [1, 2.8, 341.52], [2, 2.78, 331.48]], "batl": [[0, 2.92, 226.23], [1, 2.96, 5.57], [2, 3.05, 2.1]]}, {"timestamp": 1632492883176, "ltp": 2.92, "tv": 581.71, "trd": [[2.92, 39.39]], "batb": [[1, 2.82, 74.15], [2, 2.8, 341.52]], "batl": [[0, 2.92, 264.97]]}, {"timestamp": 1632492884959, "ltp": 2.92, "tv": 581.71, "trd": NaN, "batb": NaN, "batl": [[0, 2.92, 221.67]]}, {"timestamp": 1632492888201, "ltp": 2.92, "tv": 581.71, "trd": NaN, "batb": NaN, "batl": [[2, 2.98, 42.64]]}, {"timestamp": 1632492898117, "ltp": 2.88, "tv": 581.76, "trd": [[2.88, 1.21]], "batb": [[0, 2.88, 6.72]], "batl": NaN}, {"timestamp": 1632492901204, "ltp": 2.88, "tv": 581.76, "trd": NaN, "batb": [[0, 2.82, 74.15], [1, 2.76, 3], [2, 2.66, 2.28]], "batl": [[0, 2.98, 42.64], [1, 3.05, 2.1], [2, 3.15, 2.1]]}, {"timestamp": 1632492902013, "ltp": 2.88, "tv": 581.76, "trd": NaN, "batb": [[0, 2.58, 2.37], [1, 2.54, 96.17], [2, 2.26, 3.48]], "batl": NaN}, {"timestamp": 1632492902605, "ltp": 2.88, "tv": 581.76, "trd": NaN, "batb": NaN, "batl": [[0, 3.15, 2.1], [1, 3.2, 3], [2, 3.65, 173.5]]}, {"timestamp": 1632492905208, "ltp": 2.88, "tv": 581.76, "trd": NaN, "batb": [[0, 2.66, 13.03], [1, 2.64, 4], [2, 2.58, 5.37]], "batl": NaN}, {"timestamp": 1632492906219, "ltp": 2.88, "tv": 581.76, "trd": NaN, "batb": [[0, 2.66, 4]], "batl": [[0, 3.15, 5.1], [2, 810, 0.07]]}, {"timestamp": 1632492909224, "ltp": 2.88, "tv": 581.76, "trd": NaN, "batb": [[0, 2.66, 6.28]], "batl": [[2, 3.45, 183.67]]}, {"timestamp": 1632492909535, "ltp": 2.88, "tv": 581.76, "trd": NaN, "batb": NaN, "batl": [[0, 3.05, 2.3], [1, 3.15, 5.1], [2, 3.2, 3]]}, {"timestamp": 1632492913536, "ltp": 2.88, "tv": 581.76, "trd": NaN, "batb": [[0, 2.66, 4]], "batl": [[0, 3.15, 5.1], [1, 3.2, 3], [2, 3.45, 183.67]]}, {"timestamp": 1632492917013, "ltp": 2.88, "tv": 581.76, "trd": NaN, "batb": [[1, 2.58, 5.37], [2, 2.56, 99]], "batl": NaN}, {"timestamp": 1632492917227, "ltp": 2.88, "tv": 581.76, "trd": NaN, "batb": [[1, 2.58, 2.37], [2, 2.56, 96]], "batl": [[1, 3.45, 183.67], [2, 810, 0.07]]}, {"timestamp": 1632492919120, "ltp": 2.88, "tv": 581.76, "trd": NaN, "batb": [[0, 3, 3.81], [1, 2.68, 1011.48], [2, 2.66, 4]], "batl": [[0, 3.05, 227.1], [1, 3.1, 6.24], [2, 3.15, 2.1]]}, {"timestamp": 1632492920022, "ltp": 2.88, "tv": 581.76, "trd": NaN, "batb": [[1, 2.94, 164.49], [2, 2.82, 74.4]], "batl": NaN}, {"timestamp": 1632492920756, "ltp": 2.88, "tv": 581.76, "trd": NaN, "batb": [[2, 2.82, 82.64]], "batl": [[2, 3.15, 43.01]]}, {"timestamp": 1632492922929, "ltp": 2.88, "tv": 581.76, "trd": NaN, "batb": [[2, 2.9, 3]], "batl": NaN}, {"timestamp": 1632492925148, "ltp": 2.88, "tv": 581.76, "trd": NaN, "batb": [[1, 2.94, 164.24]], "batl": NaN}, {"timestamp": 1632492932156, "ltp": 3.0, "tv": 585.57, "trd": [[3, 45.33]], "batb": [[0, 2.94, 164.24], [1, 2.9, 3], [2, 2.88, 3]], "batl": NaN}, {"timestamp": 1632492934570, "ltp": 3.0, "tv": 585.57, "trd": NaN, "batb": [[2, 2.82, 82.47]], "batl": NaN}, {"timestamp": 1632492937647, "ltp": 3.0, "tv": 585.57, "trd": NaN, "batb": [[2, 2.88, 3]], "batl": NaN}, {"timestamp": 1632492941362, "ltp": 3.0, "tv": 585.57, "trd": NaN, "batb": NaN, "batl": [[1, 3.15, 43.01], [2, 3.3, 289.78]]}, {"timestamp": 1632492944176, "ltp": 3.0, "tv": 585.57, "trd": NaN, "batb": [[0, 2.96, 5.84], [1, 2.94, 164.24], [2, 2.9, 3]], "batl": [[0, 3.05, 234.08]]}, {"timestamp": 1632492944384, "ltp": 3.0, "tv": 585.57, "trd": NaN, "batb": [[0, 2.94, 164.24], [1, 2.9, 3], [2, 2.88, 3]], "batl": [[0, 3.05, 227.1]]}, {"timestamp": 1632492945461, "ltp": 3.0, "tv": 585.57, "trd": NaN, "batb": NaN, "batl": [[1, 3.1, 61.7], [2, 3.15, 43.01]]}, {"timestamp": 1632492947876, "ltp": 3.0, "tv": 585.57, "trd": NaN, "batb": [[0, 2.96, 5.84], [1, 2.94, 164.24], [2, 2.9, 3]], "batl": [[0, 3.05, 234.08]]}, {"timestamp": 1632492951291, "ltp": 3.0, "tv": 585.57, "trd": NaN, "batb": [[2, 2.88, 3]], "batl": NaN}, {"timestamp": 1632492968709, "ltp": 2.94, "tv": 602.45, "trd": [[2.94, 11.04], [2.96, 85.47]], "batb": [[0, 2.94, 153.2], [1, 2.88, 3], [2, 2.82, 82.47]], "batl": NaN}, {"timestamp": 1632492971923, "ltp": 2.94, "tv": 602.45, "trd": NaN, "batb": [[1, 2.82, 82.47], [2, 2.58, 2.37]], "batl": NaN}, {"timestamp": 1632492979218, "ltp": 2.94, "tv": 602.45, "trd": NaN, "batb": NaN, "batl": [[0, 3.05, 227.1]]}, {"timestamp": 1632492981864, "ltp": 2.94, "tv": 602.45, "trd": NaN, "batb": NaN, "batl": [[0, 3, 5.76], [1, 3.05, 227.1], [2, 3.1, 61.7]]}, {"timestamp": 1632492992553, "ltp": 2.94, "tv": 755.65, "trd": [[2.94, 164.24]], "batb": [[0, 2.82, 82.47], [1, 2.58, 2.37], [2, 1.92, 402.07]], "batl": NaN}, {"timestamp": 1632492997050, "ltp": 2.94, "tv": 755.65, "trd": NaN, "batb": [[0, 2.82, 812.95]], "batl": NaN}, {"timestamp": 1632493002769, "ltp": 2.94, "tv": 755.65, "trd": NaN, "batb": NaN, "batl": [[0, 3.05, 227.1], [1, 3.1, 61.7], [2, 3.15, 43.01]]}, {"timestamp": 1632493005994, "ltp": 2.96, "tv": 757.8, "trd": [[2.96, 87.62]], "batb": [[0, 2.88, 6.65], [1, 2.86, 3], [2, 2.84, 3]], "batl": [[0, 2.96, 3.32], [1, 3.05, 227.1], [2, 3.1, 61.7]]}, {"timestamp": 1632493008074, "ltp": 2.96, "tv": 757.8, "trd": NaN, "batb": [[0, 2.82, 82.47], [1, 1.92, 402.07], [2, 1.8, 10.52]], "batl": [[0, 3.15, 40.91], [1, 3.45, 183.67], [2, 3.1, 0]]}, {"timestamp": 1632493009185, "ltp": 2.96, "tv": 757.8, "trd": NaN, "batb": [[1, 2.78, 2.16], [2, 1.92, 402.07]], "batl": [[1, 3.35, 2], [2, 3.45, 183.67]]}, {"timestamp": 1632493010090, "ltp": 2.96, "tv": 757.8, "trd": NaN, "batb": [[0, 2.82, 74.23], [1, 2.8, 2.13], [2, 2.78, 2.16]], "batl": [[0, 3.3, 2.05], [1, 3.45, 185.77], [2, 3.45, 0]]}, {"timestamp": 1632493011196, "ltp": 2.96, "tv": 757.8, "trd": NaN, "batb": [[0, 2.8, 2.13], [1, 2.78, 2.16], [2, 2.76, 77.27]], "batl": [[0, 3.45, 185.77], [1, 3.45, 0]]}, {"timestamp": 1632493012786, "ltp": 2.96, "tv": 757.8, "trd": NaN, "batb": NaN, "batl": [[0, 3.35, 3], [1, 3.45, 188.77]]}, {"timestamp": 1632493013971, "ltp": 2.96, "tv": 757.8, "trd": NaN, "batb": NaN, "batl": [[1, 3.4, 3], [2, 3.45, 188.77]]}, {"timestamp": 1632493015105, "ltp": 2.96, "tv": 757.8, "trd": NaN, "batb": [[0, 2.8, 6.13], [1, 2.78, 5.16]], "batl": [[0, 2.84, 7.43], [1, 2.88, 186.88], [2, 2.98, 320.9]]}, {"timestamp": 1632493016180, "ltp": 2.84, "tv": 765.23, "trd": [[2.84, 7.65]], "batb": [[0, 2.8, 2.13], [1, 2.78, 2.16]], "batl": [[0, 2.88, 186.88], [1, 2.98, 363.54], [2, 3, 311.46]]}, {"timestamp": 1632493017184, "ltp": 2.84, "tv": 765.23, "trd": NaN, "batb": NaN, "batl": [[1, 2.98, 320.9]]}, {"timestamp": 1632493018780, "ltp": 2.84, "tv": 765.23, "trd": NaN, "batb": NaN, "batl": [[0, 2.88, 193.28]]}, {"timestamp": 1632493019683, "ltp": 2.84, "tv": 765.23, "trd": NaN, "batb": NaN, "batl": [[1, 2.98, 363.54]]}, {"timestamp": 1632493023222, "ltp": 2.84, "tv": 765.23, "trd": NaN, "batb": NaN, "batl": [[0, 2.98, 42.64], [1, 3.05, 2.1], [2, 3.15, 2.1]]}, {"timestamp": 1632493024020, "ltp": 2.84, "tv": 765.23, "trd": NaN, "batb": [[0, 2.72, 2.34], [1, 2.66, 9.03], [2, 2.64, 86.04]], "batl": NaN}, {"timestamp": 1632493025190, "ltp": 2.84, "tv": 765.23, "trd": NaN, "batb": [[1, 2.64, 86.04], [2, 1.92, 402.07]], "batl": [[0, 3.15, 2.1], [1, 3.25, 3], [2, 3.3, 3]]}, {"timestamp": 1632493027137, "ltp": 2.84, "tv": 765.23, "trd": NaN, "batb": [[0, 2.74, 5.52], [1, 2.72, 5.34], [2, 2.7, 3]], "batl": NaN}, {"timestamp": 1632493028210, "ltp": 2.84, "tv": 765.23, "trd": NaN, "batb": [[0, 2.74, 3]], "batl": [[0, 3.15, 5.1]]}, {"timestamp": 1632493028805, "ltp": 2.84, "tv": 765.23, "trd": NaN, "batb": NaN, "batl": [[1, 3.3, 3], [2, 3.45, 2.1]]}, {"timestamp": 1632493031132, "ltp": 2.84, "tv": 765.23, "trd": NaN, "batb": [[0, 2.72, 2.34], [1, 2.66, 85.62], [2, 1.92, 402.07]], "batl": [[0, 2.78, 9.16], [1, 2.84, 336.7], [2, 2.86, 326.8]]}, {"timestamp": 1632493032205, "ltp": 2.84, "tv": 765.23, "trd": NaN, "batb": [[2, 2.56, 93.72]], "batl": [[1, 2.84, 380.93]]}, {"timestamp": 1632493033517, "ltp": 2.84, "tv": 765.23, "trd": NaN, "batb": [[2, 2.62, 3]], "batl": NaN}, {"timestamp": 1632493035634, "ltp": 2.84, "tv": 765.23, "trd": NaN, "batb": NaN, "batl": [[1, 2.84, 336.7]]}, {"timestamp": 1632493038846, "ltp": 2.84, "tv": 765.23, "trd": NaN, "batb": [[1, 2.68, 2.36], [2, 2.66, 88.4]], "batl": [[1, 2.8, 44.72], [2, 2.84, 336.7]]}, {"timestamp": 1632493044124, "ltp": 2.84, "tv": 765.23, "trd": NaN, "batb": NaN, "batl": [[0, 2.8, 44.72], [1, 2.84, 168.35], [2, 2.86, 163.4]]}, {"timestamp": 1632493044434, "ltp": 2.84, "tv": 765.23, "trd": NaN, "batb": [[0, 2.62, 3], [1, 2.6, 3], [2, 2.56, 93.72]], "batl": [[1, 2.9, 2.05], [2, 2.98, 2.25]]}, {"timestamp": 1632493045529, "ltp": 2.84, "tv": 765.23, "trd": NaN, "batb": [[1, 2.56, 93.72], [2, 1.92, 402.07]], "batl": [[0, 2.98, 2.25], [1, 3.15, 5.1], [2, 3.3, 195.4]]}, {"timestamp": 1632493047745, "ltp": 2.84, "tv": 765.23, "trd": NaN, "batb": [[0, 2.66, 6.78], [1, 2.64, 3], [2, 2.62, 3]], "batl": NaN}, {"timestamp": 1632493049052, "ltp": 2.84, "tv": 765.23, "trd": NaN, "batb": NaN, "batl": [[0, 2.98, 5.25]]}, {"timestamp": 1632493050947, "ltp": 2.84, "tv": 765.23, "trd": NaN, "batb": [[0, 2.68, 5.36], [1, 2.66, 6.78], [2, 2.64, 3]], "batl": NaN}, {"timestamp": 1632493051536, "ltp": 2.84, "tv": 765.23, "trd": NaN, "batb": [[0, 2.68, 3]], "batl": NaN}, {"timestamp": 1632493052366, "ltp": 2.84, "tv": 765.23, "trd": NaN, "batb": NaN, "batl": [[0, 2.9, 2.15], [1, 2.98, 5.25], [2, 3.15, 5.1]]}, {"timestamp": 1632493053538, "ltp": 2.84, "tv": 765.23, "trd": NaN, "batb": NaN, "batl": [[0, 2.98, 5.25], [1, 3.15, 5.1], [2, 3.3, 195.4]]}, {"timestamp": 1632493058154, "ltp": 2.84, "tv": 765.23, "trd": NaN, "batb": [[0, 2.68, 5.61]], "batl": NaN}, {"timestamp": 1632493058464, "ltp": 2.84, "tv": 765.23, "trd": NaN, "batb": [[0, 2.68, 3]], "batl": NaN}, {"timestamp": 1632493061064, "ltp": 2.84, "tv": 765.23, "trd": NaN, "batb": [[0, 2.8, 2], [1, 2.68, 3], [2, 2.66, 2.78]], "batl": [[0, 2.96, 215.57], [1, 2.98, 2.25], [2, 3.15, 2.1]]}, {"timestamp": 1632493062164, "ltp": 2.84, "tv": 765.23, "trd": NaN, "batb": [[0, 2.82, 72.97], [1, 2.8, 2], [2, 2.7, 8.82]], "batl": [[2, 3.05, 41.9]]}, {"timestamp": 1632493064154, "ltp": 2.84, "tv": 765.23, "trd": NaN, "batb": [[2, 2.7, 10.82]], "batl": NaN}, {"timestamp": 1632493068188, "ltp": 2.84, "tv": 765.23, "trd": NaN, "batb": [[2, 2.74, 2.29]], "batl": NaN}, {"timestamp": 1632493077178, "ltp": 2.84, "tv": 765.23, "trd": NaN, "batb": NaN, "batl": [[0, 2.98, 2.25], [1, 3.05, 41.9], [2, 3.1, 2.05]]}, {"timestamp": 1632493078180, "ltp": 2.84, "tv": 765.23, "trd": NaN, "batb": [[0, 2.7, 2], [1, 2.68, 86.21], [2, 2.66, 2.78]], "batl": [[0, 3.1, 2.05], [1, 3.15, 2.1], [2, 3.2, 2.03]]}, {"timestamp": 1632493078494, "ltp": 2.84, "tv": 765.23, "trd": NaN, "batb": NaN, "batl": [[0, 3.2, 2.03], [1, 3.45, 2.1], [2, 3.65, 173.5]]}, {"timestamp": 1632493081207, "ltp": 2.84, "tv": 765.23, "trd": NaN, "batb": [[0, 2.74, 3], [1, 2.72, 3], [2, 2.7, 2]], "batl": NaN}, {"timestamp": 1632493083176, "ltp": 2.84, "tv": 765.23, "trd": NaN, "batb": NaN, "batl": [[0, 2.96, 17.87], [1, 3.2, 2.03], [2, 3.45, 2.1]]}, {"timestamp": 1632493084086, "ltp": 2.84, "tv": 765.23, "trd": NaN, "batb": NaN, "batl": [[0, 3.2, 2.03], [1, 3.45, 2.1], [2, 3.65, 173.5]]}, {"timestamp": 1632493085188, "ltp": 2.84, "tv": 765.23, "trd": NaN, "batb": [[0, 2.74, 5.29]], "batl": NaN}, {"timestamp": 1632493085613, "ltp": 2.84, "tv": 765.23, "trd": NaN, "batb": NaN, "batl": [[0, 3.1, 2.05], [1, 3.2, 2.03], [2, 3.45, 2.1]]}, {"timestamp": 1632493087526, "ltp": 2.84, "tv": 765.23, "trd": NaN, "batb": [[0, 2.74, 3]], "batl": [[0, 3.2, 2.03], [1, 3.45, 2.1], [2, 3.65, 173.5]]}, {"timestamp": 1632493093132, "ltp": 2.84, "tv": 765.23, "trd": NaN, "batb": [[1, 2.68, 88.87], [2, 2.66, 2.78]], "batl": NaN}, {"timestamp": 1632493094029, "ltp": 2.84, "tv": 765.23, "trd": NaN, "batb": [[0, 2.74, 5.52], [1, 2.68, 85.87]], "batl": NaN}, {"timestamp": 1632493095194, "ltp": 2.84, "tv": 765.23, "trd": NaN, "batb": [[0, 2.74, 3]], "batl": NaN}, {"timestamp": 1632493096205, "ltp": 2.84, "tv": 765.23, "trd": NaN, "batb": [[0, 3.15, 5.67], [1, 3, 1275], [2, 2.98, 1237.5]], "batl": [[1, 3.25, 6.53], [2, 3.35, 1141.78]]}, {"timestamp": 1632493097209, "ltp": 2.84, "tv": 765.23, "trd": NaN, "batb": [[1, 3, 320.76], [2, 2.98, 309.38]], "batl": [[0, 3.2, 5.03], [2, 3.35, 285.44]]}, {"timestamp": 1632493097707, "ltp": 2.84, "tv": 765.23, "trd": NaN, "batb": [[1, 3.1, 143.4], [2, 3, 320.76]], "batl": [[0, 3.2, 2.03]]}, {"timestamp": 1632493099123, "ltp": 2.84, "tv": 765.23, "trd": NaN, "batb": NaN, "batl": [[2, 3.35, 324.57]]}, {"timestamp": 1632493099914, "ltp": 3.15, "tv": 766.25, "trd": [[3.15, 8.31]], "batb": [[0, 3.15, 4.65]], "batl": NaN}, {"timestamp": 1632493103216, "ltp": 3.15, "tv": 775.55, "trd": [[3.15, 17.61]], "batb": [[0, 3.1, 143.4], [1, 3, 320.76], [2, 2.98, 309.38]], "batl": [[0, 3.15, 10], [1, 3.2, 2.03], [2, 3.25, 6.53]]}, {"timestamp": 1632493106113, "ltp": 3.15, "tv": 775.55, "trd": NaN, "batb": NaN, "batl": [[0, 3.15, 14.64]]}, {"timestamp": 1632493107220, "ltp": 3.15, "tv": 775.55, "trd": NaN, "batb": NaN, "batl": [[0, 3.15, 10]]}, {"timestamp": 1632493109436, "ltp": 3.15, "tv": 775.55, "trd": NaN, "batb": NaN, "batl": [[2, 3.35, 324.57]]}, {"timestamp": 1632493112040, "ltp": 3.15, "tv": 775.55, "trd": NaN, "batb": [[0, 2.96, 7.65], [1, 2.86, 70.86], [2, 2.8, 2.08]], "batl": [[1, 3.35, 39.13], [2, 3.8, 2]]}, {"timestamp": 1632493114048, "ltp": 3.15, "tv": 775.55, "trd": NaN, "batb": [[0, 2.86, 70.86], [1, 2.8, 2.08], [2, 2.76, 3]], "batl": [[1, 4.2, 152.71], [2, 4.3, 2]]}, {"timestamp": 1632493115159, "ltp": 3.15, "tv": 775.55, "trd": NaN, "batb": NaN, "batl": [[1, 3.55, 2], [2, 4.2, 152.71]]}, {"timestamp": 1632493120968, "ltp": 3.15, "tv": 775.55, "trd": NaN, "batb": NaN, "batl": [[2, 3.8, 2]]}, {"timestamp": 1632493122078, "ltp": 3.15, "tv": 775.55, "trd": NaN, "batb": NaN, "batl": [[2, 4.2, 152.71]]}, {"timestamp": 1632493128359, "ltp": 3.15, "tv": 775.55, "trd": NaN, "batb": NaN, "batl": [[2, 3.8, 2]]}, {"timestamp": 1632493129565, "ltp": 3.15, "tv": 775.55, "trd": NaN, "batb": NaN, "batl": [[2, 4.2, 152.71]]}, {"timestamp": 1632493132160, "ltp": 3.15, "tv": 775.55, "trd": NaN, "batb": NaN, "batl": [[0, 2.96, 7.9], [1, 3, 93.7], [2, 3.15, 10]]}, {"timestamp": 1632493133171, "ltp": 3.15, "tv": 775.55, "trd": NaN, "batb": NaN, "batl": [[2, 3.1, 41.4]]}, {"timestamp": 1632493137208, "ltp": 3.15, "tv": 775.55, "trd": NaN, "batb": NaN, "batl": [[2, 3.15, 10]]}, {"timestamp": 1632493140160, "ltp": 3.15, "tv": 775.55, "trd": NaN, "batb": NaN, "batl": [[2, 3.15, 12.1]]}, {"timestamp": 1632493140583, "ltp": 3.15, "tv": 775.55, "trd": NaN, "batb": NaN, "batl": [[2, 3.05, 41.9]]}, {"timestamp": 1632493154983, "ltp": 3.15, "tv": 775.55, "trd": NaN, "batb": [[0, 2.72, 11.31], [1, 2.7, 81.82], [2, 2.68, 2.36]], "batl": [[0, 3.05, 41.9], [1, 3.15, 12.1], [2, 3.25, 2.02]]}, {"timestamp": 1632493155506, "ltp": 3.15, "tv": 775.55, "trd": NaN, "batb": [[0, 2.72, 8.72]], "batl": NaN}, {"timestamp": 1632493156613, "ltp": 3.15, "tv": 775.55, "trd": NaN, "batb": [[0, 2.7, 81.82], [1, 2.68, 2.36], [2, 2.66, 2.78]], "batl": [[0, 3.15, 10], [1, 3.25, 2.02], [2, 3.55, 2]]}, {"timestamp": 1632493158996, "ltp": 3.15, "tv": 775.55, "trd": NaN, "batb": [[0, 2.72, 3], [1, 2.7, 85.82], [2, 2.68, 2.36]], "batl": NaN}, {"timestamp": 1632493160102, "ltp": 3.15, "tv": 775.55, "trd": NaN, "batb": [[2, 2.68, 5.36]], "batl": NaN}, {"timestamp": 1632493162214, "ltp": 3.15, "tv": 777.59, "trd": [[3.15, 19.65]], "batb": [[0, 2.72, 5.59]], "batl": [[0, 3.15, 7.96]]}, {"timestamp": 1632493162797, "ltp": 3.1, "tv": 777.98, "trd": [[3.1, 135.13]], "batb": [[0, 2.72, 3]], "batl": NaN}, {"timestamp": 1632493166815, "ltp": 3.1, "tv": 777.98, "trd": NaN, "batb": NaN, "batl": [[0, 3.15, 10.06]]}, {"timestamp": 1632493167818, "ltp": 3.1, "tv": 777.98, "trd": NaN, "batb": NaN, "batl": [[0, 3.15, 7.96]]}, {"timestamp": 1632493171206, "ltp": 3.1, "tv": 777.98, "trd": NaN, "batb": [[1, 2.7, 81.82]], "batl": NaN}, {"timestamp": 1632493171410, "ltp": 3.1, "tv": 777.98, "trd": NaN, "batb": [[2, 2.68, 2.36]], "batl": NaN}, {"timestamp": 1632493172943, "ltp": 3.1, "tv": 777.98, "trd": NaN, "batb": [[0, 2.72, 5.09]], "batl": NaN}, {"timestamp": 1632493174211, "ltp": 3.15, "tv": 789.46, "trd": [[3.1, 138.65], [3.15, 27.61]], "batb": [[0, 3.05, 313.52], [1, 3, 437.29], [2, 2.98, 304.3]], "batl": [[0, 3.25, 2.02], [1, 3.35, 199.54], [2, 3.4, 281.24]]}, {"timestamp": 1632493175218, "ltp": 3.15, "tv": 789.46, "trd": NaN, "batb": [[0, 3.15, 136.57], [1, 3.05, 313.52], [2, 3, 437.29]], "batl": NaN}, {"timestamp": 1632493183137, "ltp": 3.15, "tv": 789.46, "trd": NaN, "batb": [[2, 3, 444.79]], "batl": NaN}, {"timestamp": 1632493192565, "ltp": 3.15, "tv": 789.46, "trd": NaN, "batb": [[0, 3.15, 142.66]], "batl": [[0, 3.25, 8.02]]}, {"timestamp": 1632493197153, "ltp": 3.15, "tv": 789.46, "trd": NaN, "batb": [[0, 3.15, 136.57], [1, 3, 7.5], [2, 2.9, 169.13]], "batl": [[0, 3.45, 38.33], [1, 3.9, 2], [2, 3.95, 2]]}, {"timestamp": 1632493197951, "ltp": 3.15, "tv": 789.46, "trd": NaN, "batb": [[0, 3, 7.5], [1, 2.9, 169.13], [2, 2.84, 2.22]], "batl": NaN}, {"timestamp": 1632493198575, "ltp": 3.15, "tv": 789.46, "trd": NaN, "batb": [[0, 2.9, 169.13], [1, 2.84, 2.22], [2, 2.74, 2.52]], "batl": [[0, 4.2, 152.71], [1, 4.3, 2], [2, 4.4, 2]]}, {"timestamp": 1632493200964, "ltp": 3.15, "tv": 789.46, "trd": NaN, "batb": NaN, "batl": [[0, 4.2, 2]]}, {"timestamp": 1632493202169, "ltp": 3.15, "tv": 789.46, "trd": NaN, "batb": NaN, "batl": [[0, 4.2, 4]]}, {"timestamp": 1632493205077, "ltp": 3.15, "tv": 789.46, "trd": NaN, "batb": [[0, 2.92, 71.91], [1, 2.9, 169.13], [2, 2.84, 2.22]], "batl": [[0, 3.95, 3], [1, 4.1, 3], [2, 4.2, 4]]}, {"timestamp": 1632493206185, "ltp": 3.15, "tv": 789.46, "trd": NaN, "batb": [[0, 2.9, 169.13], [1, 2.84, 2.22], [2, 2.74, 2.52]], "batl": [[0, 3.9, 2], [1, 3.95, 3], [2, 4.1, 3]]}, {"timestamp": 1632493207186, "ltp": 3.15, "tv": 789.46, "trd": NaN, "batb": NaN, "batl": [[0, 3.95, 3], [1, 4.1, 3], [2, 4.2, 4]]}, {"timestamp": 1632493208183, "ltp": 3.15, "tv": 789.46, "trd": NaN, "batb": NaN, "batl": [[0, 3.8, 44.41], [1, 3.95, 3], [2, 4.1, 3]]}, {"timestamp": 1632493209084, "ltp": 3.15, "tv": 789.46, "trd": NaN, "batb": [[1, 2.74, 2.52], [2, 2.72, 3]], "batl": [[0, 3.95, 3], [1, 4.1, 3], [2, 4.2, 4]]}, {"timestamp": 1632493210200, "ltp": 3.15, "tv": 789.46, "trd": NaN, "batb": NaN, "batl": [[0, 3.9, 2], [1, 3.95, 3], [2, 4.1, 3]]}, {"timestamp": 1632493211201, "ltp": 3.15, "tv": 789.46, "trd": NaN, "batb": [[0, 3.6, 5.44], [1, 3.5, 129.8], [2, 2.9, 169.13]], "batl": [[1, 4.1, 3], [2, 4.2, 4]]}, {"timestamp": 1632493212202, "ltp": 3.15, "tv": 789.46, "trd": NaN, "batb": [[0, 3.75, 89.67], [1, 3.6, 5.44], [2, 3.5, 129.8]], "batl": [[1, 4, 34.64], [2, 4.1, 3]]}, {"timestamp": 1632493214083, "ltp": 3.75, "tv": 790.35, "trd": [[3.75, 0.89]], "batb": [[0, 3.75, 88.78], [2, 3.55, 3]], "batl": NaN}, {"timestamp": 1632493221209, "ltp": 3.75, "tv": 791.64, "trd": [[3.75, 2.18]], "batb": [[0, 3.75, 87.49]], "batl": NaN}, {"timestamp": 1632493226000, "ltp": 3.75, "tv": 791.87, "trd": [[3.75, 2.41]], "batb": [[0, 3.75, 87.26]], "batl": NaN}, {"timestamp": 1632493229205, "ltp": 3.75, "tv": 791.87, "trd": NaN, "batb": [[0, 3.5, 6], [1, 3.2, 130.84], [2, 3.05, 2.29]], "batl": [[0, 4, 34.64], [1, 5.5, 117.14], [2, 5.6, 2]]}, {"timestamp": 1632493230205, "ltp": 3.75, "tv": 791.87, "trd": NaN, "batb": [[0, 3.2, 130.84], [1, 3.05, 2.29], [2, 2.92, 2.44]], "batl": [[0, 5.5, 117.14], [1, 5.6, 2], [2, 5.8, 2]]}, {"timestamp": 1632493234212, "ltp": 3.75, "tv": 791.87, "trd": NaN, "batb": NaN, "batl": [[0, 5.5, 119.14]]}, {"timestamp": 1632493235112, "ltp": 3.75, "tv": 791.87, "trd": NaN, "batb": NaN, "batl": [[0, 5.2, 3], [1, 5.5, 119.14], [2, 5.6, 2]]}, {"timestamp": 1632493236207, "ltp": 3.75, "tv": 791.87, "trd": NaN, "batb": [[1, 3.15, 4.7], [2, 3.05, 574.5]], "batl": [[0, 3.25, 7.2], [1, 3.4, 703.12], [2, 3.45, 272.98]]}, {"timestamp": 1632493237205, "ltp": 3.25, "tv": 795.41, "trd": [[3.25, 10.94]], "batb": [[2, 3.1, 7.14]], "batl": [[0, 3.25, 3.66], [1, 3.4, 281.24]]}, {"timestamp": 1632493240124, "ltp": 3.25, "tv": 802.13, "trd": [[3.25, 17.66]], "batb": NaN, "batl": [[0, 3.4, 281.54], [1, 3.45, 272.98], [2, 3.5, 272.98]]}, {"timestamp": 1632493245113, "ltp": 3.25, "tv": 802.13, "trd": NaN, "batb": NaN, "batl": [[2, 3.5, 310.92]]}, {"timestamp": 1632493247111, "ltp": 3.25, "tv": 802.13, "trd": NaN, "batb": [[1, 3.1, 7.14], [2, 3.05, 574.5]], "batl": [[0, 3.4, 281.24]]}, {"timestamp": 1632493250041, "ltp": 3.25, "tv": 802.13, "trd": NaN, "batb": [[0, 3.2, 136.46]], "batl": [[0, 3.3, 5.96], [1, 3.4, 281.24], [2, 3.45, 272.98]]}, {"timestamp": 1632493250311, "ltp": 3.25, "tv": 802.13, "trd": NaN, "batb": [[0, 3.2, 130.84]], "batl": [[0, 3.4, 281.24], [1, 3.45, 272.98], [2, 3.5, 310.92]]}, {"timestamp": 1632493253241, "ltp": 3.25, "tv": 802.13, "trd": NaN, "batb": [[0, 3.2, 136.46]], "batl": [[0, 3.3, 5.96], [1, 3.4, 281.24], [2, 3.45, 272.98]]}, {"timestamp": 1632493256034, "ltp": 3.25, "tv": 802.13, "trd": NaN, "batb": [[0, 3.1, 7.14], [1, 2.96, 2.13], [2, 2.94, 165.08]], "batl": [[0, 3.5, 37.94], [1, 3.95, 2], [2, 4.4, 2]]}, {"timestamp": 1632493257439, "ltp": 3.25, "tv": 802.13, "trd": NaN, "batb": [[0, 2.94, 165.08], [1, 2.92, 2.44], [2, 2.88, 2.46]], "batl": [[0, 4.4, 2], [1, 4.9, 128.56], [2, 5.2, 3]]}, {"timestamp": 1632493261129, "ltp": 3.25, "tv": 802.13, "trd": NaN, "batb": NaN, "batl": [[0, 3.95, 2], [1, 4.2, 2], [2, 4.4, 2]]}, {"timestamp": 1632493261967, "ltp": 3.55, "tv": 806.13, "trd": [[3.55, 1.72], [3.6, 0.84], [3.7, 0.81], [3.85, 0.63]], "batb": NaN, "batl": NaN}, {"timestamp": 1632493263966, "ltp": 3.55, "tv": 806.13, "trd": NaN, "batb": [[0, 2.96, 69.1], [1, 2.94, 165.08], [2, 2.92, 2.44]], "batl": [[1, 4, 10], [2, 4.2, 2]]}, {"timestamp": 1632493265126, "ltp": 3.55, "tv": 806.13, "trd": NaN, "batb": [[0, 2.94, 165.08], [1, 2.92, 2.44], [2, 2.88, 2.46]], "batl": [[1, 4.2, 2], [2, 4.4, 2]]}, {"timestamp": 1632493268172, "ltp": 3.55, "tv": 806.13, "trd": NaN, "batb": [[0, 2.96, 2.13], [1, 2.94, 165.08], [2, 2.92, 2.44]], "batl": [[0, 3.95, 4]]}, {"timestamp": 1632493269070, "ltp": 3.55, "tv": 806.13, "trd": NaN, "batb": [[0, 2.94, 165.08], [1, 2.92, 2.44], [2, 2.88, 2.46]], "batl": [[0, 3.95, 2]]}, {"timestamp": 1632493269967, "ltp": 3.55, "tv": 806.13, "trd": NaN, "batb": NaN, "batl": [[0, 4.2, 2], [1, 4.4, 2], [2, 5.2, 3]]}, {"timestamp": 1632493271135, "ltp": 3.55, "tv": 806.13, "trd": NaN, "batb": [[0, 3.65, 1047.94], [1, 3.6, 1238.17], [2, 3.55, 1017.12]], "batl": NaN}, {"timestamp": 1632493272135, "ltp": 3.55, "tv": 806.13, "trd": NaN, "batb": [[0, 3.8, 87.73], [1, 3.65, 261.98], [2, 3.6, 475.33]], "batl": [[0, 4.2, 35.54], [2, 4.7, 8.09]]}, {"timestamp": 1632493273035, "ltp": 3.55, "tv": 806.13, "trd": NaN, "batb": NaN, "batl": [[0, 4.1, 10], [1, 4.2, 35.54], [2, 4.4, 2]]}, {"timestamp": 1632493274776, "ltp": 3.55, "tv": 806.13, "trd": NaN, "batb": NaN, "batl": [[0, 3.85, 3.05], [1, 4.1, 10], [2, 4.2, 35.54]]}, {"timestamp": 1632493276144, "ltp": 3.55, "tv": 806.13, "trd": NaN, "batb": NaN, "batl": [[0, 4.1, 10], [1, 4.2, 35.54], [2, 4.4, 2]]}, {"timestamp": 1632493279979, "ltp": 3.55, "tv": 806.13, "trd": NaN, "batb": [[2, 3.6, 481.09]], "batl": NaN}, {"timestamp": 1632493287062, "ltp": 3.55, "tv": 806.13, "trd": NaN, "batb": [[1, 3.6, 11.15], [2, 3.25, 126.28]], "batl": [[0, 4.2, 35.54], [1, 4.4, 2], [2, 5.8, 2]]}, {"timestamp": 1632493288064, "ltp": 3.55, "tv": 806.13, "trd": NaN, "batb": [[0, 3.6, 5.76], [1, 3.25, 126.28], [2, 3.15, 11.06]], "batl": [[0, 4.2, 33.54], [1, 5.8, 2], [2, 6, 108.1]]}, {"timestamp": 1632493288964, "ltp": 3.55, "tv": 806.13, "trd": NaN, "batb": [[0, 3.25, 126.28], [1, 3.15, 11.06], [2, 3, 12.5]], "batl": [[0, 5.8, 2], [1, 6, 108.1], [2, 7, 2]]}, {"timestamp": 1632493291486, "ltp": 3.55, "tv": 806.13, "trd": NaN, "batb": NaN, "batl": [[0, 5.8, 4]]}, {"timestamp": 1632493294210, "ltp": 3.55, "tv": 806.13, "trd": NaN, "batb": NaN, "batl": [[0, 5.4, 3], [1, 5.8, 4], [2, 6, 108.1]]}, {"timestamp": 1632493295211, "ltp": 3.55, "tv": 806.13, "trd": NaN, "batb": [[0, 3.3, 70.84], [1, 3.25, 126.28], [2, 3.15, 11.06]], "batl": NaN}, {"timestamp": 1632493296104, "ltp": 3.55, "tv": 806.13, "trd": NaN, "batb": [[0, 3.25, 126.28], [1, 3.15, 11.06], [2, 3, 12.5]], "batl": NaN}, {"timestamp": 1632493297203, "ltp": 3.55, "tv": 806.13, "trd": NaN, "batb": [[1, 3.15, 8.83]], "batl": NaN}, {"timestamp": 1632493298091, "ltp": 3.55, "tv": 806.13, "trd": NaN, "batb": NaN, "batl": [[0, 4.9, 20], [1, 5.4, 3], [2, 5.8, 4]]}, {"timestamp": 1632493299201, "ltp": 3.55, "tv": 806.13, "trd": NaN, "batb": NaN, "batl": [[0, 5.4, 3], [1, 5.8, 4], [2, 7, 2]]}, {"timestamp": 1632493300202, "ltp": 3.55, "tv": 806.13, "trd": NaN, "batb": [[0, 4.8, 199.22], [1, 4.7, 193.36], [2, 4.6, 193.36]], "batl": [[0, 5.7, 174.65], [1, 5.8, 166.82], [2, 5.9, 162.82]]}, {"timestamp": 1632493301203, "ltp": 3.55, "tv": 806.13, "trd": NaN, "batb": [[0, 5.1, 87.31], [1, 4.8, 199.22], [2, 4.7, 193.36]], "batl": [[0, 5.5, 28.28], [1, 5.7, 174.65], [2, 5.8, 166.82]]}, {"timestamp": 1632493303197, "ltp": 3.55, "tv": 806.13, "trd": NaN, "batb": NaN, "batl": [[0, 5.7, 174.65], [1, 5.8, 166.82], [2, 5.9, 162.82]]}, {"timestamp": 1632493306096, "ltp": 3.55, "tv": 806.13, "trd": NaN, "batb": NaN, "batl": [[0, 5.6, 27.97], [1, 5.7, 174.65], [2, 5.8, 166.82]]}, {"timestamp": 1632493307199, "ltp": 3.55, "tv": 806.13, "trd": NaN, "batb": NaN, "batl": [[0, 5.6, 29.97]]}, {"timestamp": 1632493309217, "ltp": 3.55, "tv": 806.13, "trd": NaN, "batb": NaN, "batl": [[0, 5.6, 46.13]]}, {"timestamp": 1632493310012, "ltp": 3.55, "tv": 806.13, "trd": NaN, "batb": NaN, "batl": [[0, 5.6, 29.97], [1, 5.7, 167.76]]}, {"timestamp": 1632493313119, "ltp": 3.55, "tv": 806.13, "trd": NaN, "batb": NaN, "batl": [[0, 5.5, 21.45], [1, 5.6, 29.97], [2, 5.7, 167.76]]}, {"timestamp": 1632493317807, "ltp": 3.55, "tv": 806.13, "trd": NaN, "batb": NaN, "batl": [[1, 5.6, 2]]}, {"timestamp": 1632493321026, "ltp": 3.55, "tv": 806.13, "trd": NaN, "batb": NaN, "batl": [[0, 5.5, 49.73]]}, {"timestamp": 1632493323239, "ltp": 3.55, "tv": 806.13, "trd": NaN, "batb": NaN, "batl": [[0, 5.5, 44.44]]}, {"timestamp": 1632493329142, "ltp": 3.55, "tv": 806.13, "trd": NaN, "batb": [[0, 4.6, 4.16], [1, 4.4, 119.95], [2, 4.3, 7.68]], "batl": [[0, 5.5, 28.28], [2, 5.8, 4]]}, {"timestamp": 1632493330454, "ltp": 3.55, "tv": 806.13, "trd": NaN, "batb": [[0, 4.4, 119.95], [1, 4.3, 7.68], [2, 4.1, 7.64]], "batl": [[0, 5.8, 4], [1, 7, 2], [2, 7.4, 2]]}, {"timestamp": 1632493333939, "ltp": 3.55, "tv": 806.13, "trd": NaN, "batb": [[0, 4.4, 122.95], [1, 4.3, 9.68]], "batl": [[0, 5.6, 3], [1, 5.8, 4], [2, 7, 2]]}, {"timestamp": 1632493337151, "ltp": 3.55, "tv": 806.13, "trd": NaN, "batb": [[0, 4.5, 38.24], [1, 4.4, 122.95], [2, 4.3, 9.68]], "batl": [[0, 5.6, 5]]}, {"timestamp": 1632493338939, "ltp": 3.55, "tv": 806.13, "trd": NaN, "batb": [[0, 4.4, 122.95], [1, 4.3, 9.68], [2, 4.1, 7.64]], "batl": [[0, 5.6, 3]]}, {"timestamp": 1632493342181, "ltp": 3.55, "tv": 806.13, "trd": NaN, "batb": NaN, "batl": [[0, 5.6, 5]]}, {"timestamp": 1632493343076, "ltp": 3.55, "tv": 806.13, "trd": NaN, "batb": NaN, "batl": [[0, 5.5, 2], [1, 5.6, 3], [2, 5.8, 4]]}, {"timestamp": 1632493345175, "ltp": 3.55, "tv": 806.13, "trd": NaN, "batb": [[0, 4.5, 158.77], [1, 4.4, 119.95], [2, 4.3, 9.68]], "batl": [[0, 4.8, 5.58], [1, 5.5, 2], [2, 5.6, 8.36]]}, {"timestamp": 1632493346174, "ltp": 3.55, "tv": 806.13, "trd": NaN, "batb": NaN, "batl": [[0, 4.8, 36.35]]}, {"timestamp": 1632493346962, "ltp": 3.55, "tv": 806.13, "trd": NaN, "batb": [[1, 4.4, 136.77]], "batl": [[1, 5.4, 10], [2, 5.5, 2]]}, {"timestamp": 1632493347860, "ltp": 3.55, "tv": 806.13, "trd": NaN, "batb": NaN, "batl": [[0, 4.8, 5.58], [1, 5.4, 13]]}, {"timestamp": 1632493349073, "ltp": 3.55, "tv": 806.13, "trd": NaN, "batb": [[2, 4.3, 4]], "batl": NaN}, {"timestamp": 1632493351073, "ltp": 3.55, "tv": 806.13, "trd": NaN, "batb": NaN, "batl": [[0, 4.8, 36.35]]}, {"timestamp": 1632493352708, "ltp": 3.55, "tv": 806.13, "trd": NaN, "batb": NaN, "batl": [[1, 5, 2], [2, 5.2, 2]]}, {"timestamp": 1632493360115, "ltp": 3.55, "tv": 806.13, "trd": NaN, "batb": [[0, 4.1, 4.83], [1, 3.85, 6.97], [2, 3.8, 87.9]], "batl": [[0, 4.8, 30.77]]}, {"timestamp": 1632493361006, "ltp": 3.55, "tv": 806.13, "trd": NaN, "batb": [[1, 3.8, 87.9], [2, 3.6, 9.49]], "batl": NaN}, {"timestamp": 1632493362217, "ltp": 3.55, "tv": 806.13, "trd": NaN, "batb": [[0, 3.8, 87.9], [1, 3.6, 9.49], [2, 2.9, 382.66]], "batl": [[0, 5.2, 2], [1, 5.4, 3], [2, 5.8, 2]]}, {"timestamp": 1632493365002, "ltp": 3.55, "tv": 806.13, "trd": NaN, "batb": [[0, 4, 3], [1, 3.95, 3], [2, 3.8, 90.9]], "batl": [[0, 5.2, 5]]}, {"timestamp": 1632493367214, "ltp": 3.55, "tv": 806.13, "trd": NaN, "batb": [[0, 4.8, 8.36], [1, 4.5, 488.47], [2, 4, 3]], "batl": [[0, 5.2, 2], [2, 5.5, 173.86]]}, {"timestamp": 1632493368217, "ltp": 3.55, "tv": 806.13, "trd": NaN, "batb": [[0, 4.8, 107.06], [2, 4.4, 4.41]], "batl": [[0, 5.2, 31.27]]}, {"timestamp": 1632493370026, "ltp": 3.55, "tv": 806.13, "trd": NaN, "batb": [[1, 4.6, 3], [2, 4.5, 490.47]], "batl": NaN}, {"timestamp": 1632493373020, "ltp": 3.55, "tv": 806.13, "trd": NaN, "batb": [[0, 4.8, 122.06]], "batl": NaN}, {"timestamp": 1632493380215, "ltp": 3.55, "tv": 806.13, "trd": NaN, "batb": [[0, 4.8, 107.06], [2, 4.5, 2]], "batl": [[2, 5.5, 86.93]]}, {"timestamp": 1632493381027, "ltp": 3.55, "tv": 806.13, "trd": NaN, "batb": [[0, 4.8, 4.48], [1, 4.4, 4.41], [2, 4.1, 145.56]], "batl": [[0, 5.2, 29.27], [1, 5.4, 2], [2, 5.6, 2]]}, {"timestamp": 1632493382030, "ltp": 3.55, "tv": 806.13, "trd": NaN, "batb": [[1, 4.1, 145.56], [2, 4, 8.33]], "batl": [[0, 5.6, 2], [1, 7, 2], [2, 7.2, 93.85]]}, {"timestamp": 1632493384131, "ltp": 3.55, "tv": 806.13, "trd": NaN, "batb": [[1, 4.2, 5.47], [2, 4.1, 145.56]], "batl": NaN}, {"timestamp": 1632493385031, "ltp": 3.55, "tv": 806.13, "trd": NaN, "batb": [[1, 4.1, 145.56], [2, 4, 8.33]], "batl": [[0, 5.6, 4]]}, {"timestamp": 1632493390130, "ltp": 3.55, "tv": 806.13, "trd": NaN, "batb": NaN, "batl": [[2, 7.4, 2]]}, {"timestamp": 1632493391144, "ltp": 3.55, "tv": 806.13, "trd": NaN, "batb": [[0, 5.1, 750], [1, 5, 727.94], [2, 4.9, 727.94]], "batl": [[0, 5.6, 2], [1, 5.7, 6.68], [2, 5.9, 648.3]]}, {"timestamp": 1632493392146, "ltp": 3.55, "tv": 806.13, "trd": NaN, "batb": [[0, 5.1, 197.58], [1, 5, 181.98], [2, 4.9, 181.98]], "batl": [[2, 5.9, 162.08]]}, {"timestamp": 1632493393049, "ltp": 3.55, "tv": 806.13, "trd": NaN, "batb": [[0, 5.2, 81.4], [1, 5.1, 197.58], [2, 5, 181.98]], "batl": NaN}, {"timestamp": 1632493394025, "ltp": 3.55, "tv": 806.13, "trd": NaN, "batb": NaN, "batl": [[1, 5.7, 34.35]]}, {"timestamp": 1632493396138, "ltp": 3.55, "tv": 806.13, "trd": NaN, "batb": [[0, 5.2, 103.8]], "batl": [[2, 5.8, 36.32]]}, {"timestamp": 1632493396344, "ltp": 3.55, "tv": 806.13, "trd": NaN, "batb": NaN, "batl": [[2, 5.9, 162.08]]}, {"timestamp": 1632493398539, "ltp": 5.6, "tv": 808.87, "trd": [[5.6, 2.74]], "batb": NaN, "batl": [[0, 5.7, 34.98], [1, 5.8, 2]]}, {"timestamp": 1632493408092, "ltp": 5.6, "tv": 808.87, "trd": NaN, "batb": [[0, 5.1, 4.14], [1, 4.9, 3.84], [2, 4.8, 7.01]], "batl": [[0, 5.7, 27.67], [2, 6, 2]]}, {"timestamp": 1632493409574, "ltp": 5.6, "tv": 808.87, "trd": NaN, "batb": [[1, 4.8, 7.01], [2, 4.6, 110.17]], "batl": [[0, 6, 2], [1, 7, 2], [2, 7.4, 2]]}, {"timestamp": 1632493412765, "ltp": 5.6, "tv": 808.87, "trd": NaN, "batb": NaN, "batl": [[0, 5.8, 2], [1, 6, 2], [2, 7, 2]]}, {"timestamp": 1632493413688, "ltp": 5.6, "tv": 808.87, "trd": NaN, "batb": NaN, "batl": [[0, 6, 2], [1, 7, 2], [2, 7.4, 2]]}, {"timestamp": 1632493416064, "ltp": 5.6, "tv": 808.87, "trd": NaN, "batb": [[0, 5.7, 107.67], [1, 5.4, 708.34], [2, 5.3, 687.5]], "batl": [[0, 6, 6.5], [1, 6.4, 693.02], [2, 6.6, 580.08]]}, {"timestamp": 1632493417170, "ltp": 5.6, "tv": 808.87, "trd": NaN, "batb": [[1, 5.6, 68.75], [2, 5.5, 12.14]], "batl": [[1, 6.4, 270.59], [2, 6.6, 145.02]]}, {"timestamp": 1632493421090, "ltp": 5.6, "tv": 808.87, "trd": NaN, "batb": NaN, "batl": [[1, 6.2, 34.79], [2, 6.4, 270.59]]}, {"timestamp": 1632493421389, "ltp": 5.6, "tv": 808.87, "trd": NaN, "batb": NaN, "batl": [[1, 6.4, 270.59], [2, 6.6, 145.02]]}, {"timestamp": 1632493424305, "ltp": 5.6, "tv": 808.87, "trd": NaN, "batb": NaN, "batl": [[1, 6.4, 272.59]]}, {"timestamp": 1632493433998, "ltp": 5.6, "tv": 808.87, "trd": NaN, "batb": [[0, 5.5, 4.24], [1, 5.3, 7.76], [2, 5.2, 83.51]], "batl": [[0, 6, 2], [1, 6.4, 27.81], [2, 7, 2]]}, {"timestamp": 1632493434995, "ltp": 5.6, "tv": 808.87, "trd": NaN, "batb": [[1, 5.3, 3.48]], "batl": NaN}, {"timestamp": 1632493435312, "ltp": 5.6, "tv": 808.87, "trd": NaN, "batb": [[1, 5.2, 83.51], [2, 5.1, 6.58]], "batl": [[0, 6.4, 2], [1, 7, 2], [2, 7.4, 2]]}, {"timestamp": 1632493437201, "ltp": 5.6, "tv": 808.87, "trd": NaN, "batb": [[1, 5.3, 2.28], [2, 5.2, 83.51]], "batl": [[0, 6, 2], [1, 6.4, 2], [2, 7, 2]]}, {"timestamp": 1632493438022, "ltp": 5.6, "tv": 808.87, "trd": NaN, "batb": [[1, 5.2, 83.51], [2, 5.1, 6.58]], "batl": NaN}, {"timestamp": 1632493439121, "ltp": 5.6, "tv": 808.87, "trd": NaN, "batb": NaN, "batl": [[1, 6.4, 218.45]]}, {"timestamp": 1632493440195, "ltp": 5.6, "tv": 808.87, "trd": NaN, "batb": NaN, "batl": [[1, 6.4, 4]]}, {"timestamp": 1632493441206, "ltp": 5.6, "tv": 808.87, "trd": NaN, "batb": [[0, 5.5, 13.39], [1, 5.3, 2.28], [2, 5.2, 83.51]], "batl": [[0, 6, 11.21]]}, {"timestamp": 1632493442204, "ltp": 5.6, "tv": 808.87, "trd": NaN, "batb": [[1, 5.3, 6.86]], "batl": [[0, 6, 13.21]]}, {"timestamp": 1632493443926, "ltp": 5.6, "tv": 808.87, "trd": NaN, "batb": [[0, 5.3, 6.86], [1, 5.2, 83.51], [2, 5.1, 6.58]], "batl": NaN}, {"timestamp": 1632493446052, "ltp": 5.6, "tv": 808.87, "trd": NaN, "batb": NaN, "batl": [[0, 6, 4]]}, {"timestamp": 1632493447144, "ltp": 5.6, "tv": 808.87, "trd": NaN, "batb": [[0, 5.4, 13.82]], "batl": NaN}, {"timestamp": 1632493447400, "ltp": 5.6, "tv": 808.87, "trd": NaN, "batb": [[0, 5.2, 83.51], [1, 5.1, 6.58], [2, 4.8, 2.38]], "batl": [[0, 6, 2]]}, {"timestamp": 1632493449927, "ltp": 5.6, "tv": 808.87, "trd": NaN, "batb": [[0, 5.2, 86.51], [1, 5.1, 9.58]], "batl": NaN}, {"timestamp": 1632493452022, "ltp": 5.6, "tv": 808.87, "trd": NaN, "batb": NaN, "batl": [[0, 6, 4], [1, 6.4, 2]]}, {"timestamp": 1632493453116, "ltp": 5.6, "tv": 808.87, "trd": NaN, "batb": [[0, 5.3, 6.66], [1, 5.2, 86.51], [2, 5.1, 9.58]], "batl": [[0, 6, 2]]}, {"timestamp": 1632493453452, "ltp": 5.6, "tv": 808.87, "trd": NaN, "batb": [[0, 5.2, 86.51], [1, 5.1, 9.58], [2, 4.1, 3]], "batl": [[2, 9.8, 76.64]]}, {"timestamp": 1632493456137, "ltp": 5.6, "tv": 808.87, "trd": NaN, "batb": [[0, 5.8, 405.16], [1, 5.7, 202.58], [2, 5.6, 202.58]], "batl": [[0, 6.2, 3.53], [2, 6.8, 151.36]]}, {"timestamp": 1632493457135, "ltp": 5.6, "tv": 808.87, "trd": NaN, "batb": [[0, 5.9, 124.26], [1, 5.8, 81.04], [2, 5.7, 40.52]], "batl": [[2, 6.8, 358.72]]}, {"timestamp": 1632493458031, "ltp": 5.6, "tv": 808.87, "trd": NaN, "batb": NaN, "batl": [[2, 6.8, 245.39]]}, {"timestamp": 1632493543971, "ltp": 5.6, "tv": 808.87, "trd": NaN, "batb": [[0, 5.6, 72.6], [1, 5.3, 2], [2, 3, 5.26]], "batl": [[0, 6.8, 24.91], [1, 6.4, 0], [2, 6.8, 0]]}, {"timestamp": 1632493545260, "ltp": 5.6, "tv": 808.87, "trd": NaN, "batb": [[0, 5.6, 69.34]], "batl": NaN}, {"timestamp": 1632493547163, "ltp": 5.6, "tv": 808.87, "trd": NaN, "batb": [[1, 5.5, 4.24], [2, 5.3, 8.76]], "batl": [[0, 6.4, 2], [1, 6.6, 2], [2, 6.8, 2]]}, {"timestamp": 1632493549968, "ltp": 5.6, "tv": 808.87, "trd": NaN, "batb": NaN, "batl": [[1, 6.6, 4]]}, {"timestamp": 1632493550667, "ltp": 5.6, "tv": 808.87, "trd": NaN, "batb": [[0, 5.7, 14.65], [1, 5.6, 69.34], [2, 5.5, 6.48]], "batl": [[0, 6.4, 10.92]]}, {"timestamp": 1632493552067, "ltp": 5.6, "tv": 808.87, "trd": NaN, "batb": [[0, 5.6, 69.34], [1, 5.5, 6.48], [2, 5.3, 8.76]], "batl": [[0, 6.4, 2]]}, {"timestamp": 1632493553177, "ltp": 5.6, "tv": 808.87, "trd": NaN, "batb": [[1, 5.3, 8.76], [2, 3, 5.26]], "batl": [[0, 6.2, 3], [1, 6.4, 2], [2, 6.6, 4]]}, {"timestamp": 1632493554181, "ltp": 5.6, "tv": 816.29, "trd": [[5.6, 10.16]], "batb": [[0, 5.6, 65.63]], "batl": [[2, 6.6, 2]]}, {"timestamp": 1632493555512, "ltp": 5.6, "tv": 816.29, "trd": NaN, "batb": [[1, 5.5, 6.56], [2, 5.3, 8.76]], "batl": NaN}, {"timestamp": 1632493556876, "ltp": 5.6, "tv": 816.29, "trd": NaN, "batb": [[1, 5.5, 4.24]], "batl": NaN}, {"timestamp": 1632493559193, "ltp": 6.4, "tv": 824.03, "trd": [[6.2, 6], [6.4, 1.74]], "batb": [[0, 6, 644.61], [1, 5.9, 618.76], [2, 5.8, 618.76]], "batl": [[0, 6.4, 1.13], [1, 6.6, 2], [2, 6.8, 7.23]]}, {"timestamp": 1632493560175, "ltp": 6.4, "tv": 824.03, "trd": NaN, "batb": [[0, 6.4, 101.73], [1, 6, 286.36], [2, 5.9, 154.7]], "batl": [[0, 6.8, 7.23], [1, 7, 4], [2, 7.2, 88.8]]}, {"timestamp": 1632493562206, "ltp": 6.4, "tv": 824.03, "trd": NaN, "batb": NaN, "batl": [[1, 7, 2]]}, {"timestamp": 1632493562582, "ltp": 6.4, "tv": 824.03, "trd": NaN, "batb": NaN, "batl": [[0, 6.8, 16.03]]}, {"timestamp": 1632493564193, "ltp": 6.4, "tv": 824.03, "trd": NaN, "batb": [[1, 6, 289.36]], "batl": NaN}, {"timestamp": 1632493570002, "ltp": 6.4, "tv": 824.03, "trd": NaN, "batb": NaN, "batl": [[0, 6.8, 10.8]]}, {"timestamp": 1632493571207, "ltp": 6.4, "tv": 824.03, "trd": NaN, "batb": [[0, 6, 122.87], [1, 5.7, 2.02], [2, 5.5, 6.36]], "batl": [[0, 7.4, 2], [1, 7.8, 2], [2, 7.2, 0]]}, {"timestamp": 1632493573215, "ltp": 6.4, "tv": 824.03, "trd": NaN, "batb": [[0, 6, 119.87]], "batl": NaN}, {"timestamp": 1632493574394, "ltp": 6.4, "tv": 824.03, "trd": NaN, "batb": [[1, 5.5, 6.36], [2, 5.3, 6.58]], "batl": NaN}, {"timestamp": 1632493577193, "ltp": 6.4, "tv": 824.03, "trd": NaN, "batb": [[0, 6, 179.49]], "batl": [[0, 6.8, 92.59], [1, 7.4, 2], [2, 7.6, 3.95]]}, {"timestamp": 1632493578207, "ltp": 6.4, "tv": 824.03, "trd": NaN, "batb": [[1, 5.8, 3.12], [2, 5.7, 68.33]], "batl": [[1, 7, 24.49], [2, 7.4, 2]]}, {"timestamp": 1632493580012, "ltp": 6.4, "tv": 824.03, "trd": NaN, "batb": NaN, "batl": [[0, 6.6, 3], [1, 6.8, 92.59], [2, 7, 24.49]]}, {"timestamp": 1632493584439, "ltp": 6.4, "tv": 824.03, "trd": NaN, "batb": [[2, 5.7, 70.45]], "batl": [[0, 6.6, 5], [2, 7, 26.49]]}, {"timestamp": 1632493587135, "ltp": 6.4, "tv": 824.03, "trd": NaN, "batb": [[0, 6, 119.87]], "batl": [[1, 7, 26.49], [2, 7.4, 2]]}, {"timestamp": 1632493587719, "ltp": 6.4, "tv": 824.03, "trd": NaN, "batb": [[0, 5.8, 3.12], [1, 5.7, 68.33], [2, 5.5, 6.36]], "batl": [[0, 7, 26.49], [1, 7.4, 2], [2, 7.8, 2]]}, {"timestamp": 1632493588254, "ltp": 6.4, "tv": 824.03, "trd": NaN, "batb": [[0, 5.7, 68.33], [1, 5.5, 6.36], [2, 5.3, 6.58]], "batl": [[0, 7, 2]]}, {"timestamp": 1632493591038, "ltp": 6.4, "tv": 824.03, "trd": NaN, "batb": [[0, 5.7, 70.45]], "batl": [[0, 7, 4]]}, {"timestamp": 1632493591422, "ltp": 6.4, "tv": 824.03, "trd": NaN, "batb": [[0, 5.7, 68.33]], "batl": NaN}, {"timestamp": 1632493594220, "ltp": 6.4, "tv": 824.03, "trd": NaN, "batb": NaN, "batl": [[0, 6.6, 2], [1, 7, 4], [2, 7.4, 2]]}, {"timestamp": 1632493595128, "ltp": 6.4, "tv": 824.03, "trd": NaN, "batb": NaN, "batl": [[0, 7, 4], [1, 7.4, 2], [2, 7.8, 2]]}, {"timestamp": 1632493597140, "ltp": 6.2, "tv": 825.71, "trd": [[6.2, 7.68]], "batb": NaN, "batl": [[0, 6, 5.89], [1, 6.2, 214.48], [2, 6.4, 37.9]]}, {"timestamp": 1632493598125, "ltp": 6.2, "tv": 825.71, "trd": NaN, "batb": [[2, 5.4, 510.53]], "batl": NaN}, {"timestamp": 1632493598932, "ltp": 6.2, "tv": 825.71, "trd": NaN, "batb": [[2, 5.4, 165.77]], "batl": NaN}, {"timestamp": 1632493604943, "ltp": 6.2, "tv": 825.71, "trd": NaN, "batb": [[0, 5.7, 70.55]], "batl": [[2, 6.4, 39.9]]}, {"timestamp": 1632493613060, "ltp": 6.2, "tv": 825.71, "trd": NaN, "batb": [[0, 5.5, 6.36], [1, 5.4, 78.73], [2, 5.3, 6.58]], "batl": [[0, 6.4, 2], [1, 6.6, 27.35], [2, 6.8, 2]]}, {"timestamp": 1632493613268, "ltp": 6.2, "tv": 825.71, "trd": NaN, "batb": [[0, 5.5, 2.12]], "batl": [[0, 6.6, 27.35], [1, 6.8, 2], [2, 7, 2]]}, {"timestamp": 1632493615053, "ltp": 6.2, "tv": 825.71, "trd": NaN, "batb": [[1, 5.4, 75.33]], "batl": [[0, 6.6, 2], [2, 7.8, 2]]}, {"timestamp": 1632493616170, "ltp": 6.2, "tv": 825.71, "trd": NaN, "batb": [[0, 5.7, 2.42], [1, 5.5, 2.12], [2, 5.4, 75.33]], "batl": NaN}, {"timestamp": 1632493616965, "ltp": 6.2, "tv": 825.71, "trd": NaN, "batb": [[0, 5.5, 4.12], [1, 5.4, 78.33], [2, 5.3, 6.58]], "batl": NaN}, {"timestamp": 1632493619066, "ltp": 6.2, "tv": 825.71, "trd": NaN, "batb": NaN, "batl": [[0, 6, 20.9], [1, 6.6, 2], [2, 6.8, 2]]}, {"timestamp": 1632493620162, "ltp": 6.2, "tv": 825.71, "trd": NaN, "batb": NaN, "batl": [[0, 6.6, 2], [1, 6.8, 2], [2, 7.8, 2]]}, {"timestamp": 1632493621169, "ltp": 6.2, "tv": 825.71, "trd": NaN, "batb": [[0, 5.6, 10.91], [1, 5.5, 4.12], [2, 5.4, 78.33]], "batl": [[0, 6.4, 2], [1, 6.6, 2], [2, 6.8, 2]]}, {"timestamp": 1632493622181, "ltp": 6.2, "tv": 825.71, "trd": NaN, "batb": [[0, 5.5, 4.12], [1, 5.4, 78.33], [2, 5.3, 6.58]], "batl": NaN}, {"timestamp": 1632493622469, "ltp": 6.2, "tv": 825.71, "trd": NaN, "batb": NaN, "batl": [[0, 6.6, 2], [1, 6.8, 2], [2, 7.8, 2]]}, {"timestamp": 1632493626995, "ltp": 6.2, "tv": 825.71, "trd": NaN, "batb": [[0, 5.7, 2.52], [1, 5.5, 4.12], [2, 5.4, 78.33]], "batl": NaN}, {"timestamp": 1632493627278, "ltp": 6.2, "tv": 825.71, "trd": NaN, "batb": [[0, 5.5, 4.12], [1, 5.4, 78.33], [2, 5.3, 6.58]], "batl": NaN}, {"timestamp": 1632493630102, "ltp": 6.2, "tv": 825.71, "trd": NaN, "batb": [[1, 5.4, 75.33], [2, 5.3, 4.58]], "batl": NaN}, {"timestamp": 1632493632202, "ltp": 6.2, "tv": 825.71, "trd": NaN, "batb": [[0, 6.2, 92.99], [1, 6, 401.39], [2, 5.9, 195.84]], "batl": [[0, 6.4, 3.89], [1, 6.6, 2], [2, 6.8, 2]]}, {"timestamp": 1632493633184, "ltp": 6.2, "tv": 825.71, "trd": NaN, "batb": [[1, 6, 201.17], [2, 5.9, 39.16]], "batl": [[1, 6.6, 4]]}, {"timestamp": 1632493634095, "ltp": 6.2, "tv": 825.71, "trd": NaN, "batb": NaN, "batl": [[1, 6.6, 14]]}, {"timestamp": 1632493647196, "ltp": 6.2, "tv": 825.71, "trd": NaN, "batb": [[0, 6, 113.12], [1, 5.8, 3.12], [2, 5.7, 134.93]], "batl": [[0, 6.6, 2], [1, 7, 2], [2, 7.2, 24.09]]}, {"timestamp": 1632493648027, "ltp": 6.2, "tv": 825.71, "trd": NaN, "batb": [[0, 5.8, 3.12], [1, 5.7, 134.93], [2, 5.6, 3]], "batl": [[0, 7, 2], [1, 7.2, 24.09], [2, 7.4, 2]]}, {"timestamp": 1632493648618, "ltp": 6.2, "tv": 825.71, "trd": NaN, "batb": [[0, 5.7, 134.93], [1, 5.6, 3], [2, 5.5, 2.12]], "batl": [[0, 7.4, 2], [1, 7.2, 0], [2, 7.4, 0]]}, {"timestamp": 1632493650705, "ltp": 6.2, "tv": 825.71, "trd": NaN, "batb": [[0, 5.8, 2], [1, 5.7, 136.93], [2, 5.6, 3]], "batl": NaN}, {"timestamp": 1632493651815, "ltp": 6.2, "tv": 825.71, "trd": NaN, "batb": NaN, "batl": [[0, 7.4, 4]]}, {"timestamp": 1632493654019, "ltp": 6.2, "tv": 825.71, "trd": NaN, "batb": [[0, 6, 2.99], [1, 5.8, 2], [2, 5.7, 136.93]], "batl": NaN}, {"timestamp": 1632493655026, "ltp": 6.2, "tv": 825.71, "trd": NaN, "batb": [[0, 5.8, 2], [1, 5.7, 136.93], [2, 5.6, 3]], "batl": [[0, 7, 2], [1, 7.4, 4]]}, {"timestamp": 1632493655303, "ltp": 6.2, "tv": 825.71, "trd": NaN, "batb": NaN, "batl": [[0, 7.4, 4], [1, 7.4, 0]]}, {"timestamp": 1632493658029, "ltp": 6.2, "tv": 825.71, "trd": NaN, "batb": [[0, 5.7, 134.93], [1, 5.5, 2.12], [2, 5.3, 4.58]], "batl": [[0, 6.2, 83.93], [1, 6.4, 37.9], [2, 6.6, 37.9]]}, {"timestamp": 1632493659136, "ltp": 6.2, "tv": 825.71, "trd": NaN, "batb": [[1, 5.5, 76.02], [2, 5.4, 87.04]], "batl": NaN}, {"timestamp": 1632493659824, "ltp": 6.2, "tv": 825.71, "trd": NaN, "batb": [[1, 5.5, 79.35]], "batl": [[2, 6.6, 63.25]]}, {"timestamp": 1632493662839, "ltp": 6.2, "tv": 825.71, "trd": NaN, "batb": NaN, "batl": [[0, 6.2, 103.93]]}, {"timestamp": 1632493665130, "ltp": 6.2, "tv": 825.71, "trd": NaN, "batb": NaN, "batl": [[2, 6.6, 65.25]]}, {"timestamp": 1632493674129, "ltp": 6.2, "tv": 825.71, "trd": NaN, "batb": [[2, 5.3, 7.36]], "batl": [[0, 6.6, 27.35], [1, 7, 2], [2, 7.4, 4]]}, {"timestamp": 1632493674750, "ltp": 6.2, "tv": 825.71, "trd": NaN, "batb": [[0, 5.5, 77.23], [1, 5.3, 7.36], [2, 3, 5.26]], "batl": [[0, 6.6, 25.35]]}, {"timestamp": 1632493675338, "ltp": 6.2, "tv": 825.71, "trd": NaN, "batb": [[0, 5.5, 73.9]], "batl": [[0, 7, 2], [1, 7.4, 4], [2, 7.4, 0]]}, {"timestamp": 1632493678043, "ltp": 6.2, "tv": 825.71, "trd": NaN, "batb": NaN, "batl": [[0, 6.6, 5], [1, 7, 2], [2, 7.4, 4]]}, {"timestamp": 1632493678657, "ltp": 6.2, "tv": 825.71, "trd": NaN, "batb": NaN, "batl": [[1, 7, 5]]}, {"timestamp": 1632493690748, "ltp": 6.2, "tv": 825.71, "trd": NaN, "batb": NaN, "batl": [[0, 6.6, 2], [2, 7.4, 2]]}, {"timestamp": 1632493692057, "ltp": 6.2, "tv": 825.71, "trd": NaN, "batb": [[0, 5.5, 76.41]], "batl": NaN}, {"timestamp": 1632493692371, "ltp": 6.2, "tv": 825.71, "trd": NaN, "batb": [[0, 5.5, 73.9]], "batl": NaN}, {"timestamp": 1632493693981, "ltp": 6.2, "tv": 825.71, "trd": NaN, "batb": NaN, "batl": [[0, 6.6, 5]]}, {"timestamp": 1632493699165, "ltp": 6.2, "tv": 825.71, "trd": NaN, "batb": [[0, 5.5, 76.34]], "batl": NaN}, {"timestamp": 1632493699988, "ltp": 6.2, "tv": 825.71, "trd": NaN, "batb": [[0, 5.5, 73.9]], "batl": [[0, 6.6, 3]]}, {"timestamp": 1632493703162, "ltp": 6.2, "tv": 825.71, "trd": NaN, "batb": NaN, "batl": [[0, 5.9, 79.66], [1, 6, 172.81], [2, 6.2, 39.84]]}, {"timestamp": 1632493704171, "ltp": 6.2, "tv": 825.71, "trd": NaN, "batb": [[2, 5.2, 93.95]], "batl": NaN}, {"timestamp": 1632493707977, "ltp": 6.2, "tv": 825.71, "trd": NaN, "batb": NaN, "batl": [[0, 5.9, 94.66]]}, {"timestamp": 1632493710901, "ltp": 6.2, "tv": 825.71, "trd": NaN, "batb": NaN, "batl": [[2, 6.2, 66.15]]}, {"timestamp": 1632493737219, "ltp": 6.2, "tv": 825.71, "trd": NaN, "batb": [[2, 5.2, 3.57]], "batl": [[0, 6.2, 26.31], [1, 6.4, 2], [2, 6.6, 5]]}, {"timestamp": 1632493738214, "ltp": 6.2, "tv": 825.71, "trd": NaN, "batb": [[0, 4.8, 2.53], [1, 4.7, 104.09], [2, 4.5, 2.68]], "batl": [[0, 6.4, 2], [1, 6.6, 5], [2, 7, 2]]}, {"timestamp": 1632493738834, "ltp": 6.2, "tv": 825.71, "trd": NaN, "batb": [[0, 4.7, 104.09], [1, 4.5, 2.68], [2, 3, 5.26]], "batl": [[0, 6.6, 5], [1, 7, 2], [2, 7.4, 2]]}, {"timestamp": 1632493742121, "ltp": 6.2, "tv": 825.71, "trd": NaN, "batb": [[0, 4.8, 4.93], [1, 4.7, 106.09], [2, 4.6, 2]], "batl": [[0, 6.4, 4], [1, 6.6, 5], [2, 7, 2]]}, {"timestamp": 1632493743019, "ltp": 6.2, "tv": 825.71, "trd": NaN, "batb": [[0, 4.8, 2]], "batl": [[0, 6.4, 2]]}, {"timestamp": 1632493744044, "ltp": 6.2, "tv": 825.71, "trd": NaN, "batb": NaN, "batl": [[0, 6.2, 218.27], [1, 6.4, 2], [2, 6.6, 5]]}, {"timestamp": 1632493744513, "ltp": 6.2, "tv": 825.71, "trd": NaN, "batb": NaN, "batl": [[0, 6.4, 2], [1, 6.6, 5], [2, 7, 2]]}, {"timestamp": 1632493745923, "ltp": 6.2, "tv": 825.71, "trd": NaN, "batb": [[0, 4.9, 24.65], [1, 4.8, 4.73], [2, 4.7, 106.09]], "batl": [[0, 6.2, 10], [1, 6.4, 4], [2, 6.6, 5]]}, {"timestamp": 1632493749222, "ltp": 6.2, "tv": 825.71, "trd": NaN, "batb": [[0, 4.8, 2], [1, 4.7, 106.09], [2, 4.6, 2]], "batl": [[0, 6.4, 2], [1, 6.6, 5], [2, 7, 2]]}, {"timestamp": 1632493752517, "ltp": 6.2, "tv": 825.71, "trd": NaN, "batb": NaN, "batl": [[0, 6.4, 4]]}, {"timestamp": 1632493756139, "ltp": 6.2, "tv": 825.71, "trd": NaN, "batb": [[1, 4.7, 104.09], [2, 4.5, 2.68]], "batl": [[1, 6.6, 2]]}, {"timestamp": 1632493758551, "ltp": 6.2, "tv": 825.71, "trd": NaN, "batb": NaN, "batl": [[0, 6.4, 2]]}, {"timestamp": 1632493759972, "ltp": 6.2, "tv": 825.71, "trd": NaN, "batb": [[0, 4.7, 104.09], [1, 4.5, 2.68], [2, 3, 5.26]], "batl": NaN}, {"timestamp": 1632493761176, "ltp": 6.2, "tv": 825.71, "trd": NaN, "batb": [[0, 4.8, 162.36], [1, 4.7, 104.09], [2, 4.5, 2.68]], "batl": [[0, 5, 4.28], [1, 5.5, 122.83], [2, 6, 5]]}, {"timestamp": 1632493762864, "ltp": 6.2, "tv": 825.71, "trd": NaN, "batb": [[2, 4.5, 6.96]], "batl": [[1, 5.4, 28.6], [2, 5.5, 122.83]]}, {"timestamp": 1632493766168, "ltp": 6.2, "tv": 825.71, "trd": NaN, "batb": NaN, "batl": [[1, 5.5, 122.83], [2, 5.9, 10]]}, {"timestamp": 1632493769141, "ltp": 6.2, "tv": 825.71, "trd": NaN, "batb": NaN, "batl": [[2, 5.8, 2]]}, {"timestamp": 1632493769663, "ltp": 6.2, "tv": 825.71, "trd": NaN, "batb": NaN, "batl": [[1, 5.3, 28.93], [2, 5.5, 122.83]]}, {"timestamp": 1632493782073, "ltp": 6.2, "tv": 825.71, "trd": NaN, "batb": [[0, 4.7, 104.09], [1, 4.5, 4.28], [2, 4.1, 2.94]], "batl": [[0, 5.3, 28.93], [1, 5.8, 2], [2, 6.2, 2]]}, {"timestamp": 1632493782385, "ltp": 6.2, "tv": 825.71, "trd": NaN, "batb": [[0, 4.5, 4.28], [1, 4.1, 2.94], [2, 3.9, 165.68]], "batl": NaN}, {"timestamp": 1632493783755, "ltp": 6.2, "tv": 825.71, "trd": NaN, "batb": [[0, 3.9, 165.68], [1, 3, 5.26], [2, 2.8, 382.14]], "batl": [[0, 6.2, 2], [1, 6.4, 2], [2, 6.6, 2]]}, {"timestamp": 1632493787009, "ltp": 6.2, "tv": 825.71, "trd": NaN, "batb": [[0, 4.1, 6.04], [1, 4, 3], [2, 3.9, 168.68]], "batl": [[0, 5.8, 2], [1, 6, 2], [2, 6.2, 2]]}, {"timestamp": 1632493788106, "ltp": 6.2, "tv": 825.71, "trd": NaN, "batb": [[0, 4.1, 3]], "batl": [[0, 6, 2], [1, 6.2, 2], [2, 6.4, 2]]}, {"timestamp": 1632493789685, "ltp": 6.2, "tv": 825.71, "trd": NaN, "batb": [[0, 4.2, 3], [1, 4.1, 3], [2, 4, 3]], "batl": NaN}, {"timestamp": 1632493790592, "ltp": 6.2, "tv": 825.71, "trd": NaN, "batb": [[1, 4.1, 6.14]], "batl": [[0, 5.7, 10], [1, 5.8, 2], [2, 6, 2]]}, {"timestamp": 1632493793212, "ltp": 6.2, "tv": 825.71, "trd": NaN, "batb": NaN, "batl": [[0, 5.8, 2], [1, 6, 2], [2, 6.2, 2]]}, {"timestamp": 1632493794005, "ltp": 6.2, "tv": 825.71, "trd": NaN, "batb": [[1, 4.1, 3]], "batl": [[0, 6, 2], [1, 6.2, 2], [2, 6.4, 2]]}, {"timestamp": 1632493797108, "ltp": 6.2, "tv": 825.71, "trd": NaN, "batb": NaN, "batl": [[0, 5.8, 2], [1, 6, 2], [2, 6.2, 2]]}, {"timestamp": 1632493800600, "ltp": 6.2, "tv": 825.71, "trd": NaN, "batb": [[1, 3.9, 165.68], [2, 2.8, 382.14]], "batl": [[2, 6.4, 2]]}, {"timestamp": 1632493804211, "ltp": 6.2, "tv": 825.71, "trd": NaN, "batb": [[1, 4.1, 3], [2, 3.9, 165.68]], "batl": NaN}, {"timestamp": 1632493815147, "ltp": 6.2, "tv": 825.71, "trd": NaN, "batb": [[1, 4.1, 6.04]], "batl": NaN}, {"timestamp": 1632493815565, "ltp": 6.2, "tv": 825.71, "trd": NaN, "batb": [[1, 4.1, 3]], "batl": NaN}, {"timestamp": 1632493819044, "ltp": 6.2, "tv": 825.71, "trd": NaN, "batb": [[1, 3.9, 165.68], [2, 2.8, 382.14]], "batl": NaN}, {"timestamp": 1632493822078, "ltp": 6.2, "tv": 825.71, "trd": NaN, "batb": [[1, 4.1, 3], [2, 3.9, 165.68]], "batl": [[0, 6, 2], [1, 6.4, 2], [2, 6.6, 2]]}, {"timestamp": 1632493824171, "ltp": 4.2, "tv": 831.71, "trd": [[4.2, 6]], "batb": [[0, 4.1, 3], [1, 4, 193.09]], "batl": [[0, 4.2, 3.91], [1, 4.7, 247.48], [2, 5.1, 5.88]]}, {"timestamp": 1632493825168, "ltp": 4.2, "tv": 831.71, "trd": NaN, "batb": [[0, 4, 193.09], [1, 3.9, 165.68], [2, 3.8, 251.64]], "batl": NaN}, {"timestamp": 1632493826163, "ltp": 4.2, "tv": 831.71, "trd": NaN, "batb": NaN, "batl": [[2, 4.9, 10]]}, {"timestamp": 1632493827158, "ltp": 4.2, "tv": 831.71, "trd": NaN, "batb": [[2, 3.85, 5.26]], "batl": [[1, 4.6, 31.62], [2, 4.7, 247.48]]}, {"timestamp": 1632493828058, "ltp": 4.2, "tv": 831.71, "trd": NaN, "batb": NaN, "batl": [[1, 4.7, 247.48], [2, 4.9, 10]]}, {"timestamp": 1632493829207, "ltp": 4.2, "tv": 831.71, "trd": NaN, "batb": NaN, "batl": [[1, 4.5, 56.49], [2, 4.7, 247.48]]}, {"timestamp": 1632493829679, "ltp": 4.2, "tv": 831.71, "trd": NaN, "batb": NaN, "batl": [[1, 4.7, 247.48], [2, 4.9, 10]]}, {"timestamp": 1632493831069, "ltp": 4.2, "tv": 831.71, "trd": NaN, "batb": NaN, "batl": [[1, 4.6, 31.62], [2, 4.7, 247.48]]}, {"timestamp": 1632493832083, "ltp": 4.2, "tv": 831.71, "trd": NaN, "batb": NaN, "batl": [[1, 4.7, 247.48], [2, 4.9, 10]]}, {"timestamp": 1632493834673, "ltp": 4.2, "tv": 831.71, "trd": NaN, "batb": NaN, "batl": [[0, 4.7, 247.48], [1, 5.1, 5.88], [2, 5.2, 1.71]]}, {"timestamp": 1632493836203, "ltp": 4.2, "tv": 831.71, "trd": NaN, "batb": NaN, "batl": [[0, 4.5, 32.07], [1, 4.7, 247.48], [2, 5.1, 5.88]]}, {"timestamp": 1632493837910, "ltp": 4.2, "tv": 831.71, "trd": NaN, "batb": NaN, "batl": [[0, 4.2, 3.91], [1, 4.5, 32.07], [2, 4.6, 30.81]]}, {"timestamp": 1632493856198, "ltp": 4.2, "tv": 831.71, "trd": NaN, "batb": [[0, 3.9, 162.22], [1, 3.85, 5.26], [2, 3.35, 4.27]], "batl": [[0, 4.5, 32.07], [1, 6, 2], [2, 6.6, 100.74]]}, {"timestamp": 1632493857133, "ltp": 4.2, "tv": 831.71, "trd": NaN, "batb": [[0, 3.85, 5.26], [1, 3.35, 4.27], [2, 3.25, 128.56]], "batl": NaN}, {"timestamp": 1632493857604, "ltp": 4.2, "tv": 831.71, "trd": NaN, "batb": [[0, 3.25, 124.59], [1, 3.2, 3.47], [2, 2.8, 382.14]], "batl": [[0, 6, 2], [1, 6.6, 100.74], [2, 6.6, 0]]}, {"timestamp": 1632493860810, "ltp": 4.2, "tv": 831.71, "trd": NaN, "batb": [[0, 3.35, 6.87], [1, 3.3, 3], [2, 3.25, 127.59]], "batl": NaN}, {"timestamp": 1632493861226, "ltp": 4.2, "tv": 831.71, "trd": NaN, "batb": [[0, 3.35, 3]], "batl": NaN}, {"timestamp": 1632493863118, "ltp": 4.2, "tv": 831.71, "trd": NaN, "batb": NaN, "batl": [[0, 4.2, 18.68], [1, 6, 2], [2, 6.6, 100.74]]}, {"timestamp": 1632493863535, "ltp": 4.2, "tv": 831.71, "trd": NaN, "batb": NaN, "batl": [[0, 6, 2], [1, 6.6, 100.74], [2, 6.6, 0]]}, {"timestamp": 1632493865019, "ltp": 4.2, "tv": 831.71, "trd": NaN, "batb": [[0, 3.4, 15], [1, 3.35, 6.67], [2, 3.3, 3]], "batl": [[0, 4.7, 10], [1, 6, 2], [2, 6.6, 100.74]]}, {"timestamp": 1632493868842, "ltp": 4.2, "tv": 831.71, "trd": NaN, "batb": [[0, 3.35, 3], [1, 3.3, 3], [2, 3.25, 127.59]], "batl": [[0, 6, 2], [1, 6.6, 100.74], [2, 6.6, 0]]}, {"timestamp": 1632493872037, "ltp": 4.2, "tv": 831.71, "trd": NaN, "batb": [[0, 3.35, 7.07]], "batl": NaN}, {"timestamp": 1632493872357, "ltp": 4.2, "tv": 831.71, "trd": NaN, "batb": [[0, 3.35, 3]], "batl": NaN}, {"timestamp": 1632493875956, "ltp": 4.2, "tv": 831.71, "trd": NaN, "batb": [[1, 3.25, 124.59], [2, 3.2, 3.47]], "batl": [[1, 6.6, 0]]}, {"timestamp": 1632493878171, "ltp": 4.2, "tv": 831.71, "trd": NaN, "batb": [[0, 3.35, 5.24], [1, 3.3, 219.75], [2, 3.25, 124.59]], "batl": [[0, 3.5, 4.8], [1, 4.3, 811.74], [2, 5.8, 440.98]]}, {"timestamp": 1632493879134, "ltp": 4.2, "tv": 831.71, "trd": NaN, "batb": NaN, "batl": [[1, 4.3, 813.45], [2, 6, 2]]}, {"timestamp": 1632493880132, "ltp": 4.2, "tv": 831.71, "trd": NaN, "batb": [[1, 3.3, 226.27], [2, 3.25, 127.59]], "batl": [[1, 3.8, 35.85], [2, 4.1, 10]]}, {"timestamp": 1632493881174, "ltp": 4.2, "tv": 831.71, "trd": NaN, "batb": [[1, 3.3, 245.68]], "batl": NaN}, {"timestamp": 1632493882857, "ltp": 4.2, "tv": 831.71, "trd": NaN, "batb": NaN, "batl": [[1, 4.1, 10], [2, 4.3, 813.45]]}, {"timestamp": 1632493886068, "ltp": 4.2, "tv": 831.71, "trd": NaN, "batb": NaN, "batl": [[1, 3.75, 36.18], [2, 4.1, 12]]}, {"timestamp": 1632493889064, "ltp": 4.2, "tv": 831.71, "trd": NaN, "batb": [[0, 3.3, 245.68], [1, 3.25, 127.59], [2, 3.2, 6.47]], "batl": [[0, 3.75, 36.18], [1, 4.1, 2], [2, 4.3, 813.45]]}, {"timestamp": 1632493890056, "ltp": 4.2, "tv": 831.71, "trd": NaN, "batb": NaN, "batl": [[2, 4.3, 811.74]]}, {"timestamp": 1632493891792, "ltp": 4.2, "tv": 831.71, "trd": NaN, "batb": [[0, 3.4, 5.03], [1, 3.3, 245.68], [2, 3.25, 127.59]], "batl": [[0, 3.5, 4.8], [1, 3.75, 36.18], [2, 4.1, 2]]}, {"timestamp": 1632493893063, "ltp": 4.2, "tv": 831.71, "trd": NaN, "batb": NaN, "batl": [[1, 3.7, 25.82], [2, 3.75, 36.18]]}, {"timestamp": 1632493894161, "ltp": 4.2, "tv": 831.71, "trd": NaN, "batb": [[0, 3.3, 25.93], [1, 3.25, 127.59], [2, 3.2, 3.47]], "batl": [[0, 3.7, 25.82], [1, 3.75, 36.18], [2, 4.1, 2]]}, {"timestamp": 1632493895157, "ltp": 4.2, "tv": 831.71, "trd": NaN, "batb": [[0, 2.96, 4.63], [1, 2.88, 4.21], [2, 2.86, 70.1]], "batl": [[0, 4.1, 2], [1, 4.4, 2], [2, 4.8, 2]]}, {"timestamp": 1632493895997, "ltp": 4.2, "tv": 831.71, "trd": NaN, "batb": [[0, 2.88, 4.21], [1, 2.86, 70.1], [2, 2.84, 4.97]], "batl": NaN}, {"timestamp": 1632493899001, "ltp": 4.2, "tv": 831.71, "trd": NaN, "batb": [[0, 2.88, 7.21], [1, 2.86, 73.1]], "batl": NaN}, {"timestamp": 1632493900574, "ltp": 4.2, "tv": 831.71, "trd": NaN, "batb": [[0, 2.92, 3], [1, 2.9, 3], [2, 2.88, 7.21]], "batl": NaN}, {"timestamp": 1632493902204, "ltp": 4.2, "tv": 831.71, "trd": NaN, "batb": [[0, 2.96, 4.38], [1, 2.92, 3], [2, 2.9, 3]], "batl": NaN}, {"timestamp": 1632493902464, "ltp": 4.2, "tv": 831.71, "trd": NaN, "batb": [[0, 2.92, 3], [1, 2.9, 3], [2, 2.88, 7.21]], "batl": NaN}, {"timestamp": 1632493909183, "ltp": 4.2, "tv": 831.71, "trd": NaN, "batb": [[0, 2.96, 4.63], [1, 2.92, 3], [2, 2.9, 3]], "batl": NaN}, {"timestamp": 1632493909500, "ltp": 4.2, "tv": 831.71, "trd": NaN, "batb": [[0, 2.92, 3], [1, 2.9, 3], [2, 2.88, 7.21]], "batl": NaN}, {"timestamp": 1632493912184, "ltp": 4.2, "tv": 831.71, "trd": NaN, "batb": [[2, 2.88, 4.21]], "batl": NaN}, {"timestamp": 1632493913280, "ltp": 4.2, "tv": 831.71, "trd": NaN, "batb": [[1, 2.88, 4.21], [2, 2.86, 70.1]], "batl": NaN}, {"timestamp": 1632493915216, "ltp": 4.2, "tv": 831.71, "trd": NaN, "batb": [[0, 2.92, 5.15], [2, 2.86, 404.46]], "batl": [[0, 3, 6.28], [1, 3.2, 747.07], [2, 3.25, 290.04]]}, {"timestamp": 1632493916220, "ltp": 3.0, "tv": 837.99, "trd": [[3, 51.61]], "batb": NaN, "batl": [[0, 3.2, 298.82], [1, 3.25, 290.04], [2, 3.3, 290.04]]}, {"timestamp": 1632493917119, "ltp": 3.0, "tv": 837.99, "trd": NaN, "batb": [[0, 2.92, 20.15]], "batl": NaN}, {"timestamp": 1632493917903, "ltp": 3.0, "tv": 837.99, "trd": NaN, "batb": [[0, 2.92, 5.15]], "batl": NaN}, {"timestamp": 1632493920001, "ltp": 3.0, "tv": 837.99, "trd": NaN, "batb": [[0, 2.92, 12.96]], "batl": NaN}, {"timestamp": 1632493921110, "ltp": 3.0, "tv": 837.99, "trd": NaN, "batb": NaN, "batl": [[0, 3.15, 17.13], [1, 3.2, 298.82], [2, 3.25, 290.04]]}, {"timestamp": 1632493924122, "ltp": 3.0, "tv": 837.99, "trd": NaN, "batb": [[0, 2.92, 33.34], [1, 2.88, 73.97]], "batl": NaN}, {"timestamp": 1632493925015, "ltp": 3.0, "tv": 837.99, "trd": NaN, "batb": [[2, 2.86, 334.36]], "batl": NaN}, {"timestamp": 1632493926117, "ltp": 3.0, "tv": 837.99, "trd": NaN, "batb": [[0, 2.92, 28.19]], "batl": NaN}, {"timestamp": 1632493926746, "ltp": 3.0, "tv": 837.99, "trd": NaN, "batb": NaN, "batl": [[2, 3.25, 330.04]]}, {"timestamp": 1632493928853, "ltp": 3.0, "tv": 837.99, "trd": NaN, "batb": [[0, 2.96, 5.68], [1, 2.92, 28.19], [2, 2.88, 73.97]], "batl": [[0, 3.05, 6.79], [1, 3.15, 17.13], [2, 3.2, 298.82]]}, {"timestamp": 1632493932119, "ltp": 3.0, "tv": 837.99, "trd": NaN, "batb": [[2, 2.9, 68.5]], "batl": NaN}, {"timestamp": 1632493935956, "ltp": 3.0, "tv": 837.99, "trd": NaN, "batb": [[1, 2.92, 20.38]], "batl": NaN}, {"timestamp": 1632494008159, "ltp": 3.0, "tv": 837.99, "trd": NaN, "batb": [[0, 2.86, 8.06], [1, 2.8, 5.63], [2, 2.74, 5.02]], "batl": [[0, 3.25, 40], [1, 3.75, 2], [2, 4.2, 152.71]]}, {"timestamp": 1632494008576, "ltp": 3.0, "tv": 837.99, "trd": NaN, "batb": [[0, 2.74, 5.02], [1, 2.7, 81.74], [2, 2.38, 389.23]], "batl": [[0, 3.75, 2], [1, 4.2, 152.71], [2, 4.8, 2]]}, {"timestamp": 1632494011956, "ltp": 3.0, "tv": 837.99, "trd": NaN, "batb": [[0, 2.74, 8.02], [1, 2.72, 3], [2, 2.7, 81.74]], "batl": NaN}, {"timestamp": 1632494013654, "ltp": 3.0, "tv": 837.99, "trd": NaN, "batb": [[0, 2.74, 5.02], [1, 2.7, 81.74], [2, 2, 10.52]], "batl": [[1, 4.2, 2]]}, {"timestamp": 1632494015175, "ltp": 3.0, "tv": 837.99, "trd": NaN, "batb": NaN, "batl": [[0, 2.88, 7.24], [1, 2.94, 325.26], [2, 2.96, 315.7]]}, {"timestamp": 1632494016180, "ltp": 3.0, "tv": 837.99, "trd": NaN, "batb": [[2, 2.66, 9.03]], "batl": NaN}, {"timestamp": 1632494017064, "ltp": 3.0, "tv": 837.99, "trd": NaN, "batb": [[2, 2.68, 3]], "batl": NaN}, {"timestamp": 1632494021687, "ltp": 3.0, "tv": 837.99, "trd": NaN, "batb": [[2, 2.68, 8.36]], "batl": NaN}, {"timestamp": 1632494030079, "ltp": 3.0, "tv": 837.99, "trd": NaN, "batb": [[0, 2.66, 9.03], [1, 2.62, 6.04], [2, 2.56, 93.55]], "batl": [[0, 3, 42.42], [1, 3.2, 2.03], [2, 3.35, 2]]}, {"timestamp": 1632494031309, "ltp": 3.0, "tv": 837.99, "trd": NaN, "batb": [[0, 2.62, 6.04], [1, 2.56, 93.55], [2, 2.04, 401.24]], "batl": [[0, 3.2, 2.03], [1, 3.35, 2], [2, 3.45, 3]]}, {"timestamp": 1632494034699, "ltp": 3.0, "tv": 837.99, "trd": NaN, "batb": [[0, 2.62, 9.04], [1, 2.6, 3], [2, 2.56, 93.55]], "batl": NaN}, {"timestamp": 1632494036106, "ltp": 3.0, "tv": 837.99, "trd": NaN, "batb": [[0, 2.62, 6.04], [1, 2.56, 93.55], [2, 2.04, 401.24]], "batl": [[0, 2.72, 481.56], [1, 2.74, 86.4], [2, 2.76, 86.4]]}, {"timestamp": 1632494037199, "ltp": 3.0, "tv": 837.99, "trd": NaN, "batb": [[2, 2.54, 185.04]], "batl": NaN}, {"timestamp": 1632494037626, "ltp": 2.62, "tv": 855.06, "trd": [[2.62, 11.45], [2.66, 20.15]], "batb": [[0, 2.62, 1.66]], "batl": NaN}, {"timestamp": 1632494039207, "ltp": 2.62, "tv": 855.06, "trd": NaN, "batb": [[2, 2.54, 189.04]], "batl": NaN}, {"timestamp": 1632494043111, "ltp": 2.62, "tv": 855.06, "trd": NaN, "batb": [[1, 2.58, 5.56], [2, 2.56, 98.88]], "batl": NaN}, {"timestamp": 1632494045215, "ltp": 2.62, "tv": 855.06, "trd": NaN, "batb": NaN, "batl": [[0, 2.72, 239.16], [1, 2.74, 43.2], [2, 2.76, 43.2]]}, {"timestamp": 1632494046015, "ltp": 2.62, "tv": 855.06, "trd": NaN, "batb": [[0, 2.56, 5.33], [1, 2.54, 4], [2, 2.52, 4]], "batl": [[0, 2.8, 44.72], [1, 2.9, 2.45], [2, 3, 2.14]]}, {"timestamp": 1632494046329, "ltp": 2.62, "tv": 855.06, "trd": NaN, "batb": NaN, "batl": [[0, 2.9, 2.45], [1, 3, 2.14], [2, 3.2, 2.03]]}, {"timestamp": 1632494049117, "ltp": 2.62, "tv": 855.06, "trd": NaN, "batb": [[0, 2.58, 5.56], [1, 2.56, 8.33], [2, 2.54, 4]], "batl": NaN}, {"timestamp": 1632494049331, "ltp": 2.62, "tv": 855.06, "trd": NaN, "batb": [[0, 2.56, 8.33], [1, 2.54, 4], [2, 2.52, 4]], "batl": NaN}, {"timestamp": 1632494050961, "ltp": 2.62, "tv": 855.06, "trd": NaN, "batb": [[1, 2.44, 106.37], [2, 2.04, 401.24]], "batl": NaN}, {"timestamp": 1632494052748, "ltp": 2.62, "tv": 855.06, "trd": NaN, "batb": [[0, 2.58, 5.56], [1, 2.56, 8.33], [2, 2.44, 106.37]], "batl": NaN}, {"timestamp": 1632494053954, "ltp": 2.62, "tv": 855.06, "trd": NaN, "batb": [[2, 2.54, 4]], "batl": NaN}, {"timestamp": 1632494054228, "ltp": 2.62, "tv": 855.06, "trd": NaN, "batb": [[0, 2.56, 8.33], [1, 2.54, 4], [2, 2.44, 106.37]], "batl": NaN}, {"timestamp": 1632494060972, "ltp": 2.62, "tv": 855.06, "trd": NaN, "batb": [[0, 2.58, 6.06], [1, 2.56, 8.33], [2, 2.54, 4]], "batl": NaN}, {"timestamp": 1632494061344, "ltp": 2.62, "tv": 855.06, "trd": NaN, "batb": [[0, 2.56, 8.33], [1, 2.54, 4], [2, 2.44, 106.37]], "batl": NaN}, {"timestamp": 1632494065251, "ltp": 2.62, "tv": 855.06, "trd": NaN, "batb": [[1, 2.44, 106.37], [2, 2.04, 401.24]], "batl": NaN}, {"timestamp": 1632494068139, "ltp": 2.62, "tv": 855.06, "trd": NaN, "batb": [[0, 2.56, 5.33], [1, 2.44, 498.27], [2, 2.42, 380.38]], "batl": [[0, 2.66, 898.72], [1, 2.68, 348.92], [2, 2.7, 348.92]]}, {"timestamp": 1632494069183, "ltp": 2.62, "tv": 855.06, "trd": NaN, "batb": NaN, "batl": [[0, 2.66, 359.48], [2, 2.7, 394.93]]}, {"timestamp": 1632494071990, "ltp": 2.56, "tv": 865.72, "trd": [[2.56, 10.66]], "batb": [[0, 2.44, 498.27], [1, 2.42, 380.38], [2, 2.4, 391.09]], "batl": NaN}, {"timestamp": 1632494073961, "ltp": 2.56, "tv": 865.72, "trd": NaN, "batb": NaN, "batl": [[0, 2.66, 379.79]]}, {"timestamp": 1632494075166, "ltp": 2.56, "tv": 865.72, "trd": NaN, "batb": [[0, 2.52, 3.24], [1, 2.5, 2.81], [2, 2.46, 30.4]], "batl": NaN}, {"timestamp": 1632494076174, "ltp": 2.56, "tv": 865.72, "trd": NaN, "batb": [[2, 2.48, 2.51]], "batl": NaN}, {"timestamp": 1632494083200, "ltp": 2.52, "tv": 871.72, "trd": [[2.52, 6]], "batb": [[0, 2.5, 3.05], [1, 2.48, 2.51], [2, 2.46, 33.28]], "batl": NaN}, {"timestamp": 1632494090200, "ltp": 2.52, "tv": 871.72, "trd": NaN, "batb": NaN, "batl": [[0, 2.66, 200.05], [1, 2.68, 174.46], [2, 2.7, 220.47]]}, {"timestamp": 1632494091179, "ltp": 2.52, "tv": 871.72, "trd": NaN, "batb": [[0, 2.46, 2.88], [1, 2.4, 10.71], [2, 2.38, 114.55]], "batl": [[0, 2.7, 46.01], [1, 2.76, 2.52], [2, 2.9, 2.45]]}, {"timestamp": 1632494092405, "ltp": 2.52, "tv": 871.72, "trd": NaN, "batb": [[1, 2.38, 114.55], [2, 2.04, 401.24]], "batl": [[0, 2.76, 2.52], [1, 2.9, 2.45], [2, 3, 2.14]]}, {"timestamp": 1632494094219, "ltp": 2.52, "tv": 871.72, "trd": NaN, "batb": [[0, 2.48, 6.76], [1, 2.46, 5.88], [2, 2.44, 3]], "batl": NaN}, {"timestamp": 1632494094494, "ltp": 2.52, "tv": 871.72, "trd": NaN, "batb": [[0, 2.48, 4]], "batl": NaN}, {"timestamp": 1632494099707, "ltp": 2.52, "tv": 871.72, "trd": NaN, "batb": [[0, 2.46, 2.88], [1, 2.4, 112.78], [2, 2.04, 401.24]], "batl": NaN}, {"timestamp": 1632494101199, "ltp": 2.52, "tv": 871.72, "trd": NaN, "batb": [[0, 2.5, 203.1], [1, 2.46, 2.88], [2, 2.4, 112.78]], "batl": [[0, 2.58, 370.64], [1, 2.6, 359.74], [2, 2.62, 359.74]]}, {"timestamp": 1632494102221, "ltp": 2.52, "tv": 871.72, "trd": NaN, "batb": NaN, "batl": [[2, 2.62, 406.88]]}, {"timestamp": 1632494103201, "ltp": 2.52, "tv": 871.72, "trd": NaN, "batb": [[2, 2.4, 115.78]], "batl": [[2, 2.62, 359.74]]}, {"timestamp": 1632494115932, "ltp": 2.5, "tv": 918.72, "trd": [[2.5, 47]], "batb": [[0, 2.5, 156.1]], "batl": NaN}, {"timestamp": 1632494128948, "ltp": 2.5, "tv": 918.72, "trd": NaN, "batb": [[0, 2.22, 2.93], [1, 2.16, 3.53], [2, 2.14, 155.13]], "batl": [[0, 2.66, 46.56], [1, 2.74, 2.75], [2, 2.82, 2.47]]}, {"timestamp": 1632494130258, "ltp": 2.5, "tv": 918.72, "trd": NaN, "batb": NaN, "batl": [[0, 2.74, 2.75], [1, 2.82, 2.47], [2, 3.45, 186.67]]}, {"timestamp": 1632494132149, "ltp": 2.5, "tv": 918.72, "trd": NaN, "batb": [[0, 2.16, 3.53], [1, 2.14, 155.13], [2, 2.04, 401.24]], "batl": NaN}, {"timestamp": 1632494136179, "ltp": 2.5, "tv": 918.72, "trd": NaN, "batb": [[0, 2.62, 3.33], [1, 2.6, 7.25], [2, 2.46, 771.61]], "batl": [[2, 2.84, 565.67]]}, {"timestamp": 1632494137177, "ltp": 2.5, "tv": 918.72, "trd": NaN, "batb": [[2, 2.56, 93.38]], "batl": NaN}, {"timestamp": 1632494138589, "ltp": 2.5, "tv": 918.72, "trd": NaN, "batb": [[2, 2.56, 97.38]], "batl": NaN}, {"timestamp": 1632494143796, "ltp": 2.5, "tv": 918.72, "trd": NaN, "batb": [[2, 2.56, 106.99]], "batl": NaN}, {"timestamp": 1632494145577, "ltp": 2.5, "tv": 918.72, "trd": NaN, "batb": [[1, 2.56, 106.99], [2, 2.54, 3]], "batl": NaN}, {"timestamp": 1632494147178, "ltp": 2.5, "tv": 918.72, "trd": NaN, "batb": [[0, 2.56, 102.99], [1, 2.48, 2.51], [2, 2.42, 2.94]], "batl": [[0, 2.82, 2.47], [1, 2.88, 43.75], [2, 2.9, 2.05]]}, {"timestamp": 1632494148173, "ltp": 2.5, "tv": 918.72, "trd": NaN, "batb": [[0, 2.48, 2.51], [1, 2.42, 2.94], [2, 2.32, 121.64]], "batl": [[1, 2.9, 2.05], [2, 3.45, 186.67]]}, {"timestamp": 1632494148687, "ltp": 2.5, "tv": 918.72, "trd": NaN, "batb": [[0, 2.42, 2.94], [1, 2.32, 121.64], [2, 2.16, 3.53]], "batl": [[0, 2.9, 2.05], [1, 3.45, 186.67], [2, 3.45, 0]]}, {"timestamp": 1632494152203, "ltp": 2.5, "tv": 918.72, "trd": NaN, "batb": [[0, 2.48, 2.51], [1, 2.42, 6.94], [2, 2.4, 3]], "batl": NaN}, {"timestamp": 1632494153195, "ltp": 2.5, "tv": 918.72, "trd": NaN, "batb": [[0, 2.74, 857.66], [1, 2.72, 428.82], [2, 2.7, 428.82]], "batl": [[0, 2.84, 9.21], [1, 2.9, 2.05], [2, 2.96, 206.42]]}, {"timestamp": 1632494154198, "ltp": 2.5, "tv": 918.72, "trd": NaN, "batb": [[0, 2.74, 252.76], [1, 2.72, 85.76], [2, 2.7, 85.76]], "batl": [[2, 2.96, 1000.34]]}, {"timestamp": 1632494155191, "ltp": 2.5, "tv": 918.72, "trd": NaN, "batb": NaN, "batl": [[2, 2.96, 365.2]]}, {"timestamp": 1632494155743, "ltp": 2.5, "tv": 918.72, "trd": NaN, "batb": [[2, 2.7, 94.58]], "batl": NaN}, {"timestamp": 1632494159008, "ltp": 2.84, "tv": 925.71, "trd": [[2.84, 14.64]], "batb": [[0, 2.76, 18.67], [1, 2.74, 252.76], [2, 2.72, 85.76]], "batl": [[0, 2.84, 2.22]]}, {"timestamp": 1632494160695, "ltp": 2.84, "tv": 925.71, "trd": NaN, "batb": NaN, "batl": [[2, 2.94, 2.25]]}, {"timestamp": 1632494161707, "ltp": 2.84, "tv": 925.71, "trd": NaN, "batb": [[1, 2.74, 261.38]], "batl": NaN}, {"timestamp": 1632494167112, "ltp": 2.84, "tv": 925.71, "trd": NaN, "batb": [[0, 2.74, 8.62], [1, 2.62, 2.62], [2, 2.58, 2.37]], "batl": [[0, 2.94, 2.25], [1, 3.1, 41.4], [2, 3.45, 3]]}, {"timestamp": 1632494168203, "ltp": 2.84, "tv": 925.71, "trd": NaN, "batb": [[0, 2.62, 2.62], [1, 2.58, 2.37], [2, 2.54, 95.41]], "batl": [[1, 3.45, 3], [2, 3.9, 161.11]]}, {"timestamp": 1632494168938, "ltp": 2.84, "tv": 925.71, "trd": NaN, "batb": [[0, 2.58, 2.37], [1, 2.54, 95.41], [2, 2.48, 2.51]], "batl": NaN}, {"timestamp": 1632494172118, "ltp": 2.84, "tv": 925.71, "trd": NaN, "batb": [[0, 2.62, 2.83], [1, 2.58, 5.37], [2, 2.56, 3]], "batl": NaN}, {"timestamp": 1632494173213, "ltp": 2.84, "tv": 925.71, "trd": NaN, "batb": [[0, 2.88, 4.95], [1, 2.84, 496.48], [2, 2.82, 349.1]], "batl": [[1, 2.96, 6.94], [2, 3.05, 201.83]]}, {"timestamp": 1632494174205, "ltp": 2.84, "tv": 925.71, "trd": NaN, "batb": [[1, 2.86, 70.02], [2, 2.84, 165.5]], "batl": [[2, 3.05, 355.93]]}, {"timestamp": 1632494180449, "ltp": 2.84, "tv": 925.71, "trd": NaN, "batb": NaN, "batl": [[2, 2.98, 2.25]]}, {"timestamp": 1632494182066, "ltp": 2.84, "tv": 925.71, "trd": NaN, "batb": [[1, 2.86, 78.08]], "batl": NaN}, {"timestamp": 1632494184964, "ltp": 2.84, "tv": 925.71, "trd": NaN, "batb": [[0, 2.86, 8.06], [1, 2.78, 142.39], [2, 2.76, 187.9]], "batl": [[0, 2.98, 2.25], [1, 3, 2.16], [2, 3.1, 146.31]]}, {"timestamp": 1632494186436, "ltp": 2.84, "tv": 925.71, "trd": NaN, "batb": [[0, 2.78, 142.39], [1, 2.76, 187.9], [2, 2.74, 2.02]], "batl": [[0, 3, 2.16], [1, 3.1, 146.31], [2, 3.15, 133.99]]}, {"timestamp": 1632494197971, "ltp": 2.84, "tv": 925.71, "trd": NaN, "batb": NaN, "batl": [[0, 2.98, 2.25], [1, 3, 2.16], [2, 3.1, 146.31]]}, {"timestamp": 1632494198495, "ltp": 2.84, "tv": 925.71, "trd": NaN, "batb": NaN, "batl": [[0, 3, 2.16], [1, 3.1, 146.31], [2, 3.15, 133.99]]}, {"timestamp": 1632494205757, "ltp": 2.84, "tv": 925.71, "trd": NaN, "batb": NaN, "batl": [[1, 3.45, 3], [2, 3.9, 161.11]]}, {"timestamp": 1632494209169, "ltp": 2.84, "tv": 925.71, "trd": NaN, "batb": NaN, "batl": [[0, 2.84, 8.64], [1, 2.92, 214.88], [2, 2.98, 320.9]]}, {"timestamp": 1632494210165, "ltp": 2.84, "tv": 934.35, "trd": [[2.84, 23.28]], "batb": NaN, "batl": [[0, 2.92, 214.88], [1, 2.98, 320.9], [2, 3, 313.62]]}, {"timestamp": 1632494210585, "ltp": 2.84, "tv": 934.35, "trd": NaN, "batb": NaN, "batl": [[1, 2.98, 331.7]]}, {"timestamp": 1632494216584, "ltp": 2.84, "tv": 934.35, "trd": NaN, "batb": NaN, "batl": [[1, 2.94, 2.08], [2, 2.98, 333.95]]}, {"timestamp": 1632494219782, "ltp": 2.84, "tv": 934.35, "trd": NaN, "batb": NaN, "batl": [[0, 2.9, 2.15], [1, 2.92, 214.88], [2, 2.94, 2.08]]}, {"timestamp": 1632494222503, "ltp": 2.84, "tv": 934.35, "trd": NaN, "batb": NaN, "batl": [[0, 2.88, 6.29], [1, 2.9, 2.15], [2, 2.92, 214.88]]}, {"timestamp": 1632494227216, "ltp": 2.84, "tv": 934.35, "trd": NaN, "batb": NaN, "batl": [[0, 2.9, 2.15], [1, 2.94, 2.08], [2, 2.98, 13.05]]}, {"timestamp": 1632494228125, "ltp": 2.84, "tv": 934.35, "trd": NaN, "batb": [[0, 2.7, 8.82], [1, 2.62, 2.83], [2, 2.6, 4]], "batl": [[2, 3, 2.16]]}, {"timestamp": 1632494228449, "ltp": 2.84, "tv": 934.35, "trd": NaN, "batb": [[0, 2.62, 2.83], [1, 2.6, 4], [2, 2.54, 96.59]], "batl": [[0, 2.94, 2.08], [1, 3.45, 3], [2, 3.9, 161.11]]}, {"timestamp": 1632494232049, "ltp": 2.84, "tv": 934.35, "trd": NaN, "batb": [[0, 2.68, 4], [1, 2.66, 3], [2, 2.62, 5.83]], "batl": NaN}, {"timestamp": 1632494234762, "ltp": 2.84, "tv": 934.35, "trd": NaN, "batb": [[0, 2.68, 6.61]], "batl": NaN}, {"timestamp": 1632494235356, "ltp": 2.84, "tv": 934.35, "trd": NaN, "batb": NaN, "batl": [[0, 2.9, 2.15], [1, 2.94, 2.08], [2, 3.45, 3]]}, {"timestamp": 1632494236632, "ltp": 2.84, "tv": 934.35, "trd": NaN, "batb": [[0, 2.7, 20], [1, 2.68, 6.61], [2, 2.66, 3]], "batl": NaN}, {"timestamp": 1632494241067, "ltp": 2.84, "tv": 934.35, "trd": NaN, "batb": [[0, 2.68, 4], [1, 2.66, 3], [2, 2.62, 5.83]], "batl": [[0, 2.94, 2.08], [1, 3.45, 3], [2, 3.9, 161.11]]}, {"timestamp": 1632494243971, "ltp": 2.84, "tv": 934.35, "trd": NaN, "batb": [[1, 2.62, 2.83], [2, 2.54, 96.59]], "batl": NaN}, {"timestamp": 1632494247165, "ltp": 2.84, "tv": 934.35, "trd": NaN, "batb": [[0, 2.88, 6.54], [1, 2.84, 8.47], [2, 2.8, 341.52]], "batl": [[1, 2.96, 5.47], [2, 3, 101.48]]}, {"timestamp": 1632494248161, "ltp": 2.84, "tv": 934.35, "trd": NaN, "batb": [[1, 2.84, 80.17]], "batl": NaN}, {"timestamp": 1632494252884, "ltp": 2.84, "tv": 934.35, "trd": NaN, "batb": [[1, 2.84, 80]], "batl": NaN}, {"timestamp": 1632494340184, "ltp": 2.84, "tv": 934.35, "trd": NaN, "batb": [[0, 2.84, 71.53], [1, 2.76, 8.52], [2, 2.72, 3.34]], "batl": [[0, 3.15, 40.91], [1, 3.35, 121.54], [2, 3.4, 148.26]]}, {"timestamp": 1632494341086, "ltp": 2.84, "tv": 934.35, "trd": NaN, "batb": [[0, 2.76, 8.52], [1, 2.72, 3.34], [2, 2.68, 4]], "batl": NaN}, {"timestamp": 1632494341293, "ltp": 2.84, "tv": 934.35, "trd": NaN, "batb": [[0, 2.72, 3.34], [1, 2.68, 4], [2, 2.66, 148.8]], "batl": [[0, 3.35, 121.54], [1, 3.4, 148.26], [2, 3.45, 3]]}, {"timestamp": 1632494344705, "ltp": 2.84, "tv": 934.35, "trd": NaN, "batb": [[0, 2.68, 4], [1, 2.66, 148.8], [2, 2.64, 254.84]], "batl": [[0, 3.35, 3], [1, 3.45, 3], [2, 3.5, 2]]}, {"timestamp": 1632494347123, "ltp": 2.88, "tv": 939.22, "trd": [[2.88, 6.08]], "batb": NaN, "batl": [[0, 2.84, 673.41], [1, 2.86, 648.74], [2, 2.88, 653.61]]}, {"timestamp": 1632494348121, "ltp": 2.88, "tv": 939.22, "trd": NaN, "batb": [[0, 2.66, 148.8], [1, 2.64, 254.84], [2, 2.04, 401.24]], "batl": [[0, 2.78, 5.37], [1, 2.84, 588.92], [2, 2.86, 326.8]]}, {"timestamp": 1632494348824, "ltp": 2.88, "tv": 939.22, "trd": NaN, "batb": [[2, 2.5, 100.72]], "batl": NaN}, {"timestamp": 1632494350508, "ltp": 2.88, "tv": 939.22, "trd": NaN, "batb": [[2, 2.6, 4]], "batl": NaN}, {"timestamp": 1632494356032, "ltp": 2.88, "tv": 939.22, "trd": NaN, "batb": [[2, 2.6, 7.99]], "batl": NaN}, {"timestamp": 1632494357131, "ltp": 2.88, "tv": 939.22, "trd": NaN, "batb": NaN, "batl": [[1, 2.84, 633.15]]}, {"timestamp": 1632494361219, "ltp": 2.88, "tv": 939.22, "trd": NaN, "batb": NaN, "batl": [[0, 2.84, 212.58], [1, 2.86, 163.4], [2, 2.88, 163.4]]}, {"timestamp": 1632494362161, "ltp": 2.88, "tv": 939.22, "trd": NaN, "batb": [[0, 2.6, 4], [1, 2.58, 3], [2, 2.52, 3.74]], "batl": [[0, 2.84, 44.23], [1, 2.98, 2.25], [2, 3.1, 2.05]]}, {"timestamp": 1632494362842, "ltp": 2.88, "tv": 939.22, "trd": NaN, "batb": [[1, 2.52, 3.74], [2, 2.5, 100.72]], "batl": NaN}, {"timestamp": 1632494363525, "ltp": 2.88, "tv": 939.22, "trd": NaN, "batb": NaN, "batl": [[0, 3.1, 2.05], [1, 3.35, 3], [2, 3.5, 2]]}, {"timestamp": 1632494365039, "ltp": 2.88, "tv": 939.22, "trd": NaN, "batb": [[0, 2.64, 3], [1, 2.62, 4], [2, 2.6, 4]], "batl": NaN}, {"timestamp": 1632494367032, "ltp": 2.88, "tv": 939.22, "trd": NaN, "batb": NaN, "batl": [[0, 3.1, 5.05]]}, {"timestamp": 1632494371081, "ltp": 2.64, "tv": 942.41, "trd": [[2.64, 3], [2.66, 20.34]], "batb": [[0, 2.52, 3.74], [1, 2.5, 283.83], [2, 2.46, 388.72]], "batl": [[0, 2.66, 6.79], [1, 2.68, 356.8], [2, 2.7, 346.32]]}, {"timestamp": 1632494374145, "ltp": 2.64, "tv": 942.41, "trd": NaN, "batb": [[2, 2.46, 391.72]], "batl": NaN}, {"timestamp": 1632494376099, "ltp": 2.64, "tv": 942.41, "trd": NaN, "batb": NaN, "batl": [[0, 2.64, 46.85], [1, 2.66, 6.79], [2, 2.68, 356.8]]}, {"timestamp": 1632494377161, "ltp": 2.64, "tv": 942.41, "trd": NaN, "batb": NaN, "batl": [[1, 2.66, 32.04]]}, {"timestamp": 1632494378190, "ltp": 2.64, "tv": 942.41, "trd": NaN, "batb": [[1, 2.5, 287.51]], "batl": NaN}, {"timestamp": 1632494380767, "ltp": 2.64, "tv": 942.41, "trd": NaN, "batb": NaN, "batl": [[1, 2.66, 25.25]]}, {"timestamp": 1632494383694, "ltp": 2.64, "tv": 942.41, "trd": NaN, "batb": [[2, 2.48, 4.26]], "batl": [[1, 2.66, 32.04]]}, {"timestamp": 1632494387178, "ltp": 2.64, "tv": 942.41, "trd": NaN, "batb": [[0, 2.48, 4.26], [1, 2.46, 3], [2, 2.44, 175.06]], "batl": [[1, 2.76, 2.52], [2, 2.8, 146.02]]}, {"timestamp": 1632494388178, "ltp": 2.64, "tv": 942.41, "trd": NaN, "batb": NaN, "batl": [[0, 2.76, 2.52], [1, 2.8, 146.02], [2, 2.82, 146.65]]}, {"timestamp": 1632494388916, "ltp": 2.64, "tv": 942.41, "trd": NaN, "batb": NaN, "batl": [[0, 2.8, 146.02], [1, 2.82, 146.65], [2, 3.1, 5.05]]}, {"timestamp": 1632494390114, "ltp": 2.64, "tv": 942.41, "trd": NaN, "batb": [[0, 2.52, 4], [1, 2.5, 3], [2, 2.48, 7.26]], "batl": NaN}, {"timestamp": 1632494390804, "ltp": 2.64, "tv": 942.41, "trd": NaN, "batb": [[0, 2.48, 4.26], [1, 2.46, 3], [2, 2.44, 175.06]], "batl": NaN}, {"timestamp": 1632494393191, "ltp": 2.64, "tv": 942.41, "trd": NaN, "batb": [[2, 2.44, 178.06]], "batl": [[0, 2.78, 3], [1, 2.8, 146.02], [2, 2.82, 146.65]]}, {"timestamp": 1632494393978, "ltp": 2.64, "tv": 942.41, "trd": NaN, "batb": [[0, 2.5, 4.01], [1, 2.48, 4.26], [2, 2.46, 3]], "batl": NaN}, {"timestamp": 1632494394921, "ltp": 2.64, "tv": 942.41, "trd": NaN, "batb": [[0, 2.48, 4.26], [1, 2.46, 3], [2, 2.44, 178.06]], "batl": [[0, 2.74, 3], [1, 2.78, 3], [2, 2.8, 146.02]]}, {"timestamp": 1632494397090, "ltp": 2.64, "tv": 942.41, "trd": NaN, "batb": NaN, "batl": [[1, 2.76, 4], [2, 2.78, 3]]}, {"timestamp": 1632494398094, "ltp": 2.64, "tv": 942.41, "trd": NaN, "batb": [[0, 2.5, 4.22], [1, 2.48, 4.26], [2, 2.46, 3]], "batl": [[0, 2.72, 3], [1, 2.74, 3], [2, 2.76, 4]]}, {"timestamp": 1632494399097, "ltp": 2.64, "tv": 942.41, "trd": NaN, "batb": [[0, 2.48, 4.26], [1, 2.46, 3], [2, 2.44, 178.06]], "batl": NaN}, {"timestamp": 1632494402009, "ltp": 2.64, "tv": 942.41, "trd": NaN, "batb": NaN, "batl": [[0, 2.8, 146.02], [1, 2.82, 146.65], [2, 3.1, 5.05]]}, {"timestamp": 1632494405140, "ltp": 2.64, "tv": 942.41, "trd": NaN, "batb": [[2, 2.44, 175.06]], "batl": NaN}, {"timestamp": 1632494408108, "ltp": 2.64, "tv": 942.41, "trd": NaN, "batb": NaN, "batl": [[0, 2.78, 3], [1, 2.8, 146.02], [2, 2.82, 146.65]]}, {"timestamp": 1632494409217, "ltp": 2.64, "tv": 942.41, "trd": NaN, "batb": [[2, 2.44, 178.06]], "batl": NaN}, {"timestamp": 1632494410007, "ltp": 2.64, "tv": 942.41, "trd": NaN, "batb": NaN, "batl": [[0, 2.74, 4], [1, 2.76, 2.77], [2, 2.78, 3]]}, {"timestamp": 1632494410320, "ltp": 2.64, "tv": 942.41, "trd": NaN, "batb": NaN, "batl": [[1, 2.78, 3], [2, 2.8, 146.02]]}, {"timestamp": 1632494411322, "ltp": 2.64, "tv": 942.41, "trd": NaN, "batb": NaN, "batl": [[1, 2.76, 3], [2, 2.78, 3]]}, {"timestamp": 1632494413010, "ltp": 2.64, "tv": 942.41, "trd": NaN, "batb": NaN, "batl": [[0, 2.8, 146.02], [1, 2.82, 146.65], [2, 3.1, 5.05]]}, {"timestamp": 1632494416218, "ltp": 2.64, "tv": 942.41, "trd": NaN, "batb": [[0, 2.5, 4.04], [1, 2.48, 4.26], [2, 2.46, 3]], "batl": [[0, 2.82, 2.25], [1, 3.1, 5.05], [2, 3.45, 183.67]]}, {"timestamp": 1632494417009, "ltp": 2.64, "tv": 942.41, "trd": NaN, "batb": [[0, 2.48, 4.26], [1, 2.46, 3], [2, 2.44, 178.06]], "batl": [[0, 2.76, 2.02], [1, 2.82, 2.25], [2, 3.1, 5.05]]}, {"timestamp": 1632494418036, "ltp": 2.64, "tv": 942.41, "trd": NaN, "batb": [[1, 2.44, 175.06], [2, 2.42, 169.44]], "batl": [[0, 2.82, 2.25], [1, 3.1, 5.05], [2, 3.45, 183.67]]}, {"timestamp": 1632494419144, "ltp": 2.6, "tv": 942.6, "trd": [[2.6, 0.19]], "batb": NaN, "batl": [[0, 2.58, 926.6], [1, 2.6, 371.69], [2, 2.62, 359.74]]}, {"timestamp": 1632494420038, "ltp": 2.6, "tv": 942.6, "trd": NaN, "batb": NaN, "batl": [[0, 2.58, 370.64]]}, {"timestamp": 1632494420715, "ltp": 2.6, "tv": 942.6, "trd": NaN, "batb": NaN, "batl": [[0, 2.54, 48.34], [1, 2.58, 370.64], [2, 2.6, 371.69]]}, {"timestamp": 1632494422023, "ltp": 2.6, "tv": 942.6, "trd": NaN, "batb": NaN, "batl": [[2, 2.6, 374.69]]}, {"timestamp": 1632494426062, "ltp": 2.6, "tv": 942.6, "trd": NaN, "batb": NaN, "batl": [[2, 2.6, 540.17]]}, {"timestamp": 1632494427059, "ltp": 2.6, "tv": 942.6, "trd": NaN, "batb": [[1, 2.46, 3.88], [2, 2.44, 178.73]], "batl": [[2, 2.6, 542.73]]}, {"timestamp": 1632494430173, "ltp": 2.6, "tv": 942.6, "trd": NaN, "batb": [[0, 2.4, 112.36], [1, 2.38, 155.39], [2, 2.36, 170.03]], "batl": [[1, 2.6, 171.04], [2, 2.62, 200.47]]}, {"timestamp": 1632494431066, "ltp": 2.6, "tv": 942.6, "trd": NaN, "batb": [[0, 2.38, 155.39], [1, 2.36, 170.03], [2, 2.34, 121.05]], "batl": [[1, 2.6, 168.04]]}, {"timestamp": 1632494431547, "ltp": 2.6, "tv": 942.6, "trd": NaN, "batb": NaN, "batl": [[0, 2.6, 165.48], [1, 2.62, 200.47], [2, 2.64, 2.43]]}, {"timestamp": 1632494434138, "ltp": 2.6, "tv": 942.6, "trd": NaN, "batb": [[0, 2.44, 7.92], [1, 2.42, 4], [2, 2.38, 155.39]], "batl": NaN}, {"timestamp": 1632494436988, "ltp": 2.6, "tv": 942.6, "trd": NaN, "batb": [[0, 2.46, 4.38], [1, 2.44, 7.92], [2, 2.42, 4]], "batl": NaN}, {"timestamp": 1632494437847, "ltp": 2.6, "tv": 942.6, "trd": NaN, "batb": [[0, 2.44, 7.92], [1, 2.42, 4], [2, 2.38, 155.39]], "batl": NaN}, {"timestamp": 1632494440962, "ltp": 2.6, "tv": 942.6, "trd": NaN, "batb": [[2, 2.34, 121.05]], "batl": NaN}, {"timestamp": 1632494443686, "ltp": 2.6, "tv": 953.64, "trd": [[2.6, 11.23]], "batb": [[0, 2.5, 14.72], [1, 2.44, 7.92], [2, 2.42, 4]], "batl": [[0, 2.6, 159.97]]}, {"timestamp": 1632494445160, "ltp": 2.6, "tv": 953.64, "trd": NaN, "batb": [[0, 2.52, 97.51], [1, 2.5, 14.72], [2, 2.46, 35.78]], "batl": NaN}, {"timestamp": 1632494451119, "ltp": 2.6, "tv": 953.64, "trd": NaN, "batb": [[2, 2.48, 3.76]], "batl": NaN}, {"timestamp": 1632494457096, "ltp": 2.6, "tv": 953.64, "trd": NaN, "batb": [[1, 2.48, 3.76], [2, 2.46, 4.38]], "batl": [[0, 2.68, 2.17], [1, 2.72, 45.74], [2, 2.74, 2.25]]}, {"timestamp": 1632494457996, "ltp": 2.6, "tv": 953.64, "trd": NaN, "batb": [[0, 2.46, 4.38], [1, 2.44, 14.41], [2, 2.42, 108.57]], "batl": NaN}, {"timestamp": 1632494458319, "ltp": 2.6, "tv": 953.64, "trd": NaN, "batb": [[1, 2.44, 4]], "batl": [[0, 2.74, 2.25], [1, 2.8, 3], [2, 2.82, 2.25]]}, {"timestamp": 1632494461207, "ltp": 2.6, "tv": 953.64, "trd": NaN, "batb": [[0, 2.48, 4], [1, 2.46, 7.38], [2, 2.44, 4]], "batl": NaN}, {"timestamp": 1632494472218, "ltp": 2.6, "tv": 953.64, "trd": NaN, "batb": NaN, "batl": [[0, 2.68, 2.39], [1, 2.74, 2.25]]}, {"timestamp": 1632494473112, "ltp": 2.74, "tv": 954.39, "trd": [[2.74, 26.41]], "batb": [[0, 2.6, 11.84], [1, 2.56, 585.05], [2, 2.5, 297.11]], "batl": [[0, 2.74, 1.5], [1, 2.82, 2.25], [2, 2.84, 12.42]]}, {"timestamp": 1632494474209, "ltp": 2.74, "tv": 957.39, "trd": [[2.74, 29.41]], "batb": [[0, 2.74, 77.79], [1, 2.62, 9.25], [2, 2.6, 11.84]], "batl": [[0, 2.82, 2.25], [1, 2.84, 12.42], [2, 2.92, 241.46]]}, {"timestamp": 1632494474625, "ltp": 2.74, "tv": 957.39, "trd": NaN, "batb": NaN, "batl": [[0, 2.84, 12.42], [1, 2.92, 241.46], [2, 2.94, 325.26]]}, {"timestamp": 1632494475829, "ltp": 2.74, "tv": 957.39, "trd": NaN, "batb": [[1, 2.64, 3], [2, 2.62, 12.25]], "batl": NaN}, {"timestamp": 1632494478036, "ltp": 2.74, "tv": 957.39, "trd": NaN, "batb": [[2, 2.62, 3]], "batl": NaN}, {"timestamp": 1632494481252, "ltp": 2.74, "tv": 957.39, "trd": NaN, "batb": [[1, 2.66, 9.03], [2, 2.64, 3]], "batl": NaN}, {"timestamp": 1632494489955, "ltp": 2.74, "tv": 961.77, "trd": [[2.74, 33.79]], "batb": [[0, 2.74, 75.6]], "batl": NaN}, {"timestamp": 1632494493177, "ltp": 2.74, "tv": 961.77, "trd": NaN, "batb": [[0, 2.66, 9.03], [1, 2.62, 3], [2, 2.52, 97.51]], "batl": [[0, 2.98, 42.64], [1, 3.1, 2.05], [2, 3.15, 2.1]]}, {"timestamp": 1632494493457, "ltp": 2.74, "tv": 961.77, "trd": NaN, "batb": [[1, 2.52, 97.51], [2, 2.48, 4.51]], "batl": NaN}, {"timestamp": 1632494494661, "ltp": 2.74, "tv": 961.77, "trd": NaN, "batb": [[0, 2.52, 97.51], [1, 2.48, 4.51], [2, 2.46, 4.38]], "batl": [[0, 3.25, 2], [1, 3.5, 2], [2, 3.9, 161.11]]}, {"timestamp": 1632494498091, "ltp": 2.74, "tv": 961.77, "trd": NaN, "batb": [[0, 2.52, 100.51], [1, 2.5, 3], [2, 2.48, 4.51]], "batl": [[0, 3.25, 5]]}, {"timestamp": 1632494501977, "ltp": 2.74, "tv": 961.77, "trd": NaN, "batb": [[0, 2.54, 73.58], [1, 2.52, 100.51], [2, 2.5, 3]], "batl": [[0, 3.15, 3], [1, 3.2, 27], [2, 3.25, 5]]}, {"timestamp": 1632494502278, "ltp": 2.74, "tv": 961.77, "trd": NaN, "batb": NaN, "batl": [[1, 3.2, 2]]}, {"timestamp": 1632494503864, "ltp": 2.74, "tv": 961.77, "trd": NaN, "batb": [[0, 2.52, 100.51], [1, 2.5, 3], [2, 2.48, 4.51]], "batl": NaN}, {"timestamp": 1632494507076, "ltp": 2.74, "tv": 961.77, "trd": NaN, "batb": NaN, "batl": [[0, 3.1, 2.05], [1, 3.15, 3], [2, 3.2, 2]]}, {"timestamp": 1632494507592, "ltp": 2.74, "tv": 961.77, "trd": NaN, "batb": [[0, 2.52, 97.51], [1, 2.48, 4.51], [2, 2.46, 4.38]], "batl": [[0, 3.15, 3], [1, 3.2, 2], [2, 3.25, 5]]}, {"timestamp": 1632494509190, "ltp": 2.74, "tv": 961.77, "trd": NaN, "batb": NaN, "batl": [[0, 2.66, 369.92], [1, 2.68, 348.92], [2, 2.7, 348.92]]}, {"timestamp": 1632494514092, "ltp": 2.74, "tv": 961.77, "trd": NaN, "batb": [[0, 2.52, 107.37]], "batl": NaN}, {"timestamp": 1632494514670, "ltp": 2.74, "tv": 961.77, "trd": NaN, "batb": NaN, "batl": [[0, 2.66, 391.28]]}, {"timestamp": 1632494537141, "ltp": 2.74, "tv": 961.77, "trd": NaN, "batb": NaN, "batl": [[0, 2.66, 21.36], [1, 2.74, 2.48], [2, 2.76, 169.86]]}, {"timestamp": 1632494538042, "ltp": 2.74, "tv": 961.77, "trd": NaN, "batb": [[0, 2.52, 9.86], [1, 2.26, 165.25], [2, 2.24, 357.47]], "batl": [[0, 2.74, 2.48], [1, 2.76, 169.86], [2, 2.78, 138.43]]}, {"timestamp": 1632494538661, "ltp": 2.74, "tv": 961.77, "trd": NaN, "batb": [[0, 2.26, 165.25], [1, 2.24, 357.47], [2, 2.16, 4.28]], "batl": [[0, 2.76, 169.86], [1, 2.78, 138.43], [2, 2.8, 2.32]]}, {"timestamp": 1632494541033, "ltp": 2.74, "tv": 961.77, "trd": NaN, "batb": [[0, 2.28, 129.57], [1, 2.26, 165.25], [2, 2.24, 357.47]], "batl": NaN}, {"timestamp": 1632494541956, "ltp": 2.3, "tv": 963.87, "trd": [[2.3, 2.1]], "batb": [[0, 2.28, 132.47], [2, 2.24, 223.35]], "batl": [[0, 2.74, 2.48], [1, 2.8, 2.32], [2, 3.15, 3]]}, {"timestamp": 1632494542258, "ltp": 2.3, "tv": 963.87, "trd": NaN, "batb": [[0, 2.28, 131.57]], "batl": [[0, 2.8, 2.32], [1, 3.15, 3], [2, 3.25, 2]]}, {"timestamp": 1632494544058, "ltp": 2.3, "tv": 963.87, "trd": NaN, "batb": [[0, 2.28, 129.57]], "batl": NaN}, {"timestamp": 1632494545148, "ltp": 2.3, "tv": 963.87, "trd": NaN, "batb": [[0, 2.32, 6.94], [1, 2.28, 129.57], [2, 2.26, 169.25]], "batl": [[0, 2.46, 233.93], [1, 2.62, 1.71], [2, 2.8, 13.03]]}, {"timestamp": 1632494545980, "ltp": 2.3, "tv": 963.87, "trd": NaN, "batb": [[2, 2.26, 165.25]], "batl": NaN}, {"timestamp": 1632494547041, "ltp": 2.3, "tv": 963.87, "trd": NaN, "batb": NaN, "batl": [[1, 2.52, 48.66], [2, 2.62, 1.71]]}, {"timestamp": 1632494547768, "ltp": 2.3, "tv": 963.87, "trd": NaN, "batb": NaN, "batl": [[0, 2.44, 3], [1, 2.46, 233.93]]}, {"timestamp": 1632494550170, "ltp": 2.3, "tv": 963.87, "trd": NaN, "batb": NaN, "batl": [[0, 2.44, 46.65]]}, {"timestamp": 1632494551071, "ltp": 2.3, "tv": 963.87, "trd": NaN, "batb": NaN, "batl": [[0, 2.44, 3], [2, 2.52, 48.66]]}, {"timestamp": 1632494551962, "ltp": 2.3, "tv": 963.87, "trd": NaN, "batb": NaN, "batl": [[2, 2.54, 145.01]]}, {"timestamp": 1632494554182, "ltp": 2.3, "tv": 963.87, "trd": NaN, "batb": NaN, "batl": [[0, 2.42, 15], [1, 2.44, 3], [2, 2.46, 233.93]]}, {"timestamp": 1632494559167, "ltp": 2.28, "tv": 1109.94, "trd": [[2.28, 132.19], [2.32, 14.31]], "batb": [[0, 2.28, 63.47], [1, 2.26, 165.25], [2, 2.24, 235.44]], "batl": NaN}, {"timestamp": 1632494562070, "ltp": 2.28, "tv": 1109.94, "trd": NaN, "batb": [[0, 2.24, 12.09], [1, 1.99, 445.14], [2, 1.98, 249.97]], "batl": [[0, 2.48, 49.31], [1, 2.54, 145.01], [2, 2.56, 157.35]]}, {"timestamp": 1632494563278, "ltp": 2.28, "tv": 1109.94, "trd": NaN, "batb": [[0, 1.99, 445.14], [1, 1.98, 249.97], [2, 1.91, 48.39]], "batl": [[0, 2.54, 145.01], [1, 2.56, 157.35], [2, 3.15, 204.05]]}, {"timestamp": 1632494565194, "ltp": 2.28, "tv": 1109.94, "trd": NaN, "batb": [[0, 2, 4], [1, 1.99, 255.63], [2, 1.98, 249.97]], "batl": NaN}, {"timestamp": 1632494566603, "ltp": 2.28, "tv": 1109.94, "trd": NaN, "batb": [[2, 1.98, 254.97]], "batl": NaN}, {"timestamp": 1632494569903, "ltp": 2.28, "tv": 1109.94, "trd": NaN, "batb": [[0, 2.02, 20], [1, 2, 4], [2, 1.99, 255.63]], "batl": [[0, 2.52, 83.38], [1, 2.54, 145.01], [2, 2.56, 157.35]]}, {"timestamp": 1632494572902, "ltp": 2.28, "tv": 1109.94, "trd": NaN, "batb": [[0, 2, 4], [1, 1.99, 255.63], [2, 1.98, 254.97]], "batl": [[0, 2.54, 145.01], [1, 2.56, 157.35], [2, 3.15, 204.05]]}, {"timestamp": 1632494577014, "ltp": 2.28, "tv": 1109.94, "trd": NaN, "batb": [[1, 1.99, 251.63]], "batl": NaN}, {"timestamp": 1632494577229, "ltp": 2.28, "tv": 1109.94, "trd": NaN, "batb": NaN, "batl": [[0, 3.15, 204.05], [1, 810, 0.07], [2, 3.15, 0]]}, {"timestamp": 1632494579015, "ltp": 2.28, "tv": 1109.94, "trd": NaN, "batb": NaN, "batl": [[0, 810, 0.07], [1, 810, 0]]}, {"timestamp": 1632494580190, "ltp": 2.28, "tv": 1109.94, "trd": NaN, "batb": [[0, 2, 5.56], [1, 1.99, 48.51], [2, 1.97, 198.91]], "batl": [[0, 2.04, 200.28], [1, 2.06, 141.02], [2, 2.42, 12.4]]}, {"timestamp": 1632494581192, "ltp": 2.28, "tv": 1109.94, "trd": NaN, "batb": [[1, 1.97, 214.14], [2, 1.96, 117.45]], "batl": [[2, 2.18, 55.23]]}, {"timestamp": 1632494582945, "ltp": 2.28, "tv": 1109.94, "trd": NaN, "batb": [[1, 1.97, 198.91]], "batl": [[2, 2.26, 102.56]]}, {"timestamp": 1632494586108, "ltp": 2.28, "tv": 1109.94, "trd": NaN, "batb": [[1, 1.97, 214.14]], "batl": NaN}, {"timestamp": 1632494587203, "ltp": 2.28, "tv": 1109.94, "trd": NaN, "batb": NaN, "batl": [[2, 2.24, 183.4]]}, {"timestamp": 1632494600759, "ltp": 2.28, "tv": 1109.94, "trd": NaN, "batb": [[0, 1.97, 15.23], [1, 1.73, 236.93], [2, 1.72, 389.4]], "batl": [[0, 2.24, 183.4], [1, 2.26, 194.15], [2, 2.56, 3]]}, {"timestamp": 1632494602346, "ltp": 2.28, "tv": 1109.94, "trd": NaN, "batb": [[0, 1.73, 236.93], [1, 1.72, 389.4], [2, 1.67, 471.66]], "batl": NaN}, {"timestamp": 1632494604146, "ltp": 2.28, "tv": 1109.94, "trd": NaN, "batb": [[2, 1.71, 168.76]], "batl": [[0, 2.22, 116.92], [1, 2.24, 284.14], [2, 2.26, 194.15]]}, {"timestamp": 1632494604671, "ltp": 2.28, "tv": 1109.94, "trd": NaN, "batb": [[0, 1.72, 152.85], [1, 1.67, 471.66], [2, 1.53, 3.42]], "batl": [[0, 2.24, 183.4], [1, 2.26, 194.15], [2, 2.56, 3]]}, {"timestamp": 1632494605570, "ltp": 2.28, "tv": 1109.94, "trd": NaN, "batb": [[0, 1.73, 4], [1, 1.72, 156.85], [2, 1.67, 471.66]], "batl": NaN}, {"timestamp": 1632494607150, "ltp": 2.28, "tv": 1109.94, "trd": NaN, "batb": [[0, 2.16, 18.03], [1, 2.12, 2562.84], [2, 2.1, 1821.42]], "batl": [[0, 2.24, 195.79], [2, 2.28, 1677.64]]}, {"timestamp": 1632494608162, "ltp": 2.28, "tv": 1109.94, "trd": NaN, "batb": [[1, 2.12, 216.79], [2, 2.1, 455.36]], "batl": [[2, 2.28, 419.4]]}, {"timestamp": 1632494609041, "ltp": 2.28, "tv": 1109.94, "trd": NaN, "batb": [[1, 2.14, 153.7], [2, 2.12, 216.79]], "batl": NaN}, {"timestamp": 1632494612343, "ltp": 2.28, "tv": 1109.94, "trd": NaN, "batb": [[2, 2.12, 203.4]], "batl": NaN}, {"timestamp": 1632494615572, "ltp": 2.28, "tv": 1109.94, "trd": NaN, "batb": [[1, 2.14, 166.85]], "batl": NaN}, {"timestamp": 1632494619197, "ltp": 2.28, "tv": 1109.94, "trd": NaN, "batb": [[2, 2.1, 459.36]], "batl": NaN}, {"timestamp": 1632494623193, "ltp": 2.28, "tv": 1109.94, "trd": NaN, "batb": [[0, 2.14, 13.15], [1, 1.84, 211.17], [2, 1.83, 411.34]], "batl": [[0, 2.48, 152.45], [1, 2.5, 196.08], [2, 2.56, 3]]}, {"timestamp": 1632494624200, "ltp": 2.28, "tv": 1109.94, "trd": NaN, "batb": [[0, 1.84, 211.17], [1, 1.83, 411.01], [2, 1.82, 46.14]], "batl": NaN}, {"timestamp": 1632494627375, "ltp": 2.28, "tv": 1109.94, "trd": NaN, "batb": [[0, 1.84, 215.17], [1, 1.83, 416.01]], "batl": NaN}, {"timestamp": 1632494635794, "ltp": 1.84, "tv": 1166.23, "trd": [[1.84, 56.28]], "batb": [[0, 1.84, 187.03]], "batl": NaN}, {"timestamp": 1632494637525, "ltp": 1.84, "tv": 1166.23, "trd": NaN, "batb": [[0, 1.84, 4], [1, 1.83, 129.85]], "batl": NaN}, {"timestamp": 1632494640120, "ltp": 1.84, "tv": 1166.23, "trd": NaN, "batb": [[0, 2.36, 3213.3], [1, 2.34, 497.88], [2, 2.32, 497.88]], "batl": [[0, 2.46, 11.02], [1, 2.48, 152.45], [2, 2.5, 196.08]]}, {"timestamp": 1632494641128, "ltp": 1.84, "tv": 1166.23, "trd": NaN, "batb": [[0, 2.38, 130.42], [1, 2.36, 823.48], [2, 2.34, 99.58]], "batl": NaN}, {"timestamp": 1632494642029, "ltp": 2.38, "tv": 1222.51, "trd": [[2.38, 56.28]], "batb": [[0, 2.38, 102.28]], "batl": NaN}, {"timestamp": 1632494647924, "ltp": 2.38, "tv": 1278.79, "trd": [[2.38, 112.56]], "batb": [[0, 2.38, 74.14]], "batl": NaN}, {"timestamp": 1632494649551, "ltp": 2.38, "tv": 1278.79, "trd": NaN, "batb": [[0, 2.38, 85]], "batl": NaN}, {"timestamp": 1632494665180, "ltp": 2.38, "tv": 1278.79, "trd": NaN, "batb": [[1, 2.04, 214.83], [2, 2.02, 235.68]], "batl": [[0, 2.78, 120.16], [1, 2.8, 178.74], [2, 3.3, 195.4]]}, {"timestamp": 1632494666075, "ltp": 2.38, "tv": 1278.79, "trd": NaN, "batb": [[0, 2.38, 10.86]], "batl": NaN}, {"timestamp": 1632494666285, "ltp": 2.38, "tv": 1278.79, "trd": NaN, "batb": [[0, 2.04, 214.83], [1, 2.02, 235.68], [2, 2, 186.26]], "batl": NaN}, {"timestamp": 1632494668182, "ltp": 2.38, "tv": 1278.79, "trd": NaN, "batb": NaN, "batl": [[0, 2.64, 46.85], [1, 2.78, 120.16], [2, 2.8, 178.74]]}, {"timestamp": 1632494668454, "ltp": 2.38, "tv": 1278.79, "trd": NaN, "batb": NaN, "batl": [[0, 2.78, 120.16], [1, 2.8, 178.74], [2, 3.3, 195.4]]}, {"timestamp": 1632494692221, "ltp": 2.38, "tv": 1278.79, "trd": NaN, "batb": [[0, 2.06, 115.13], [1, 2.04, 214.83], [2, 2.02, 235.68]], "batl": [[0, 2.68, 82.89], [1, 2.78, 120.16], [2, 2.8, 178.74]]}, {"timestamp": 1632494694896, "ltp": 2.38, "tv": 1278.79, "trd": NaN, "batb": [[0, 2.04, 214.83], [1, 2.02, 235.68], [2, 2, 186.26]], "batl": [[0, 2.78, 120.16], [1, 2.8, 178.74], [2, 3.3, 195.4]]}, {"timestamp": 1632494702715, "ltp": 2.38, "tv": 1278.79, "trd": NaN, "batb": NaN, "batl": [[0, 3.3, 195.4], [1, 810, 0.07], [2, 3.3, 0]]}, {"timestamp": 1632494703728, "ltp": 2.38, "tv": 1278.79, "trd": NaN, "batb": NaN, "batl": [[0, 810, 0.07], [1, 810, 0]]}, {"timestamp": 1632494706113, "ltp": 2.38, "tv": 1278.79, "trd": NaN, "batb": [[0, 2.04, 4], [1, 2.02, 238.68]], "batl": [[0, 2.06, 6.52], [1, 2.46, 12.2], [2, 2.5, 1668.1]]}, {"timestamp": 1632494707017, "ltp": 2.06, "tv": 1285.31, "trd": [[2.06, 6.52]], "batb": [[0, 2.02, 235.68], [1, 2, 186.26], [2, 1.97, 524.57]], "batl": [[0, 2.4, 1.71]]}, {"timestamp": 1632494707805, "ltp": 2.06, "tv": 1285.31, "trd": NaN, "batb": [[0, 2.02, 250.38]], "batl": [[0, 2.24, 53.88], [1, 2.4, 1.71], [2, 2.46, 12.2]]}, {"timestamp": 1632494709026, "ltp": 2.06, "tv": 1285.31, "trd": NaN, "batb": [[2, 1.97, 489.4]], "batl": NaN}, {"timestamp": 1632494710750, "ltp": 2.06, "tv": 1285.31, "trd": NaN, "batb": NaN, "batl": [[0, 2.4, 1.71], [1, 2.46, 12.2], [2, 2.5, 1668.1]]}, {"timestamp": 1632494713138, "ltp": 2.06, "tv": 1285.31, "trd": NaN, "batb": NaN, "batl": [[0, 2.22, 1186.37], [1, 2.4, 1.71], [2, 2.46, 12.2]]}, {"timestamp": 1632494713923, "ltp": 2.06, "tv": 1285.31, "trd": NaN, "batb": NaN, "batl": [[0, 2.22, 1167.58]]}, {"timestamp": 1632494716545, "ltp": 2.06, "tv": 1285.31, "trd": NaN, "batb": NaN, "batl": [[0, 2.2, 73.11], [1, 2.22, 1167.58], [2, 2.4, 1.71]]}, {"timestamp": 1632494717278, "ltp": 2.06, "tv": 1285.31, "trd": NaN, "batb": NaN, "batl": [[2, 2.46, 12.2]]}, {"timestamp": 1632494719866, "ltp": 2.06, "tv": 1285.31, "trd": NaN, "batb": NaN, "batl": [[0, 2.08, 7.45], [1, 2.2, 73.11], [2, 2.22, 54.32]]}, {"timestamp": 1632494727762, "ltp": 2.06, "tv": 1285.31, "trd": NaN, "batb": [[0, 2.02, 14.7], [1, 1.7, 416.74], [2, 1.59, 200.18]], "batl": [[0, 2.22, 54.32], [1, 2.82, 235.47], [2, 880, 0.01]]}, {"timestamp": 1632494729693, "ltp": 2.06, "tv": 1285.31, "trd": NaN, "batb": [[0, 1.7, 416.74], [1, 1.59, 200.18], [2, 1.53, 3.42]], "batl": [[0, 2.82, 235.47], [1, 880, 0.01], [2, 880, 0]]}, {"timestamp": 1632494731155, "ltp": 2.06, "tv": 1285.74, "trd": [[2.06, 6.95]], "batb": NaN, "batl": NaN}, {"timestamp": 1632494733194, "ltp": 2.06, "tv": 1285.74, "trd": NaN, "batb": [[0, 1.59, 200.18], [1, 1.53, 3.42], [2, 1.43, 40.43]], "batl": [[0, 880, 0.01], [1, 880, 0]]}, {"timestamp": 1632494735190, "ltp": 2.06, "tv": 1285.74, "trd": NaN, "batb": [[0, 2.38, 14.46], [1, 2.36, 10.04], [2, 2.32, 202.58]], "batl": [[0, 2.46, 3], [1, 2.56, 309.59], [2, 880, 0.01]]}, {"timestamp": 1632494736190, "ltp": 2.06, "tv": 1285.74, "trd": NaN, "batb": [[2, 2.34, 119.03]], "batl": [[0, 2.56, 309.59], [1, 2.64, 46.85], [2, 2.86, 1.71]]}, {"timestamp": 1632494737760, "ltp": 2.06, "tv": 1285.74, "trd": NaN, "batb": NaN, "batl": [[0, 2.54, 37.28], [1, 2.56, 309.59], [2, 2.64, 46.85]]}, {"timestamp": 1632494740181, "ltp": 2.06, "tv": 1285.74, "trd": NaN, "batb": NaN, "batl": [[2, 2.86, 1.71]]}, {"timestamp": 1632494741905, "ltp": 2.06, "tv": 1285.74, "trd": NaN, "batb": NaN, "batl": [[2, 2.76, 129.13]]}, {"timestamp": 1632494743109, "ltp": 2.06, "tv": 1285.74, "trd": NaN, "batb": [[2, 2.34, 130.22]], "batl": [[2, 2.6, 47.43]]}, {"timestamp": 1632494751007, "ltp": 2.06, "tv": 1285.74, "trd": NaN, "batb": [[0, 2.34, 11.19], [1, 2.02, 193.06], [2, 2, 183.64]], "batl": [[0, 2.6, 47.43], [1, 2.76, 129.13], [2, 2.78, 187.94]]}, {"timestamp": 1632494752315, "ltp": 2.06, "tv": 1285.74, "trd": NaN, "batb": [[0, 2.02, 193.06], [1, 2, 183.64], [2, 1.98, 194.61]], "batl": [[0, 2.76, 129.13], [1, 2.78, 187.94], [2, 3.3, 195.4]]}, {"timestamp": 1632494754209, "ltp": 2.06, "tv": 1285.74, "trd": NaN, "batb": [[2, 1.99, 193.93]], "batl": NaN}, {"timestamp": 1632494755522, "ltp": 2.06, "tv": 1285.74, "trd": NaN, "batb": NaN, "batl": [[0, 2.7, 3], [1, 2.76, 129.13], [2, 2.78, 187.94]]}, {"timestamp": 1632494757799, "ltp": 2.06, "tv": 1285.74, "trd": NaN, "batb": NaN, "batl": [[1, 3.3, 195.4], [2, 880, 0.01]]}, {"timestamp": 1632494759790, "ltp": 2.06, "tv": 1285.74, "trd": NaN, "batb": NaN, "batl": [[1, 880, 0.01], [2, 880, 0]]}, {"timestamp": 1632494761207, "ltp": 2.06, "tv": 1285.74, "trd": NaN, "batb": [[0, 2, 183.64], [1, 1.99, 193.93], [2, 1.95, 33.31]], "batl": [[0, 2.3, 1.71], [1, 2.44, 12.3], [2, 2.5, 1813.21]]}, {"timestamp": 1632494762202, "ltp": 2.06, "tv": 1285.74, "trd": NaN, "batb": [[0, 2, 198.64]], "batl": [[0, 2.24, 53.88], [1, 2.3, 1.71], [2, 2.44, 12.3]]}, {"timestamp": 1632494762939, "ltp": 2.06, "tv": 1285.74, "trd": NaN, "batb": NaN, "batl": [[0, 2.28, 15]]}, {"timestamp": 1632494763727, "ltp": 2.06, "tv": 1285.74, "trd": NaN, "batb": NaN, "batl": [[2, 2.42, 3]]}, {"timestamp": 1632494766135, "ltp": 2.06, "tv": 1285.74, "trd": NaN, "batb": NaN, "batl": [[0, 2.22, 54.32]]}, {"timestamp": 1632494771209, "ltp": 2.06, "tv": 1285.74, "trd": NaN, "batb": NaN, "batl": [[1, 2.42, 3], [2, 2.44, 12.3]]}, {"timestamp": 1632494775023, "ltp": 2.06, "tv": 1285.74, "trd": NaN, "batb": NaN, "batl": [[0, 2.18, 1326.85], [1, 2.22, 54.32], [2, 2.42, 3]]}, {"timestamp": 1632494775971, "ltp": 2.06, "tv": 1285.74, "trd": NaN, "batb": NaN, "batl": [[0, 2.22, 54.32], [1, 2.42, 3], [2, 2.44, 12.3]]}, {"timestamp": 1632494782173, "ltp": 2.06, "tv": 1285.74, "trd": NaN, "batb": NaN, "batl": [[0, 2.2, 74.99], [1, 2.22, 54.32], [2, 2.42, 3]]}, {"timestamp": 1632494783174, "ltp": 2.06, "tv": 1285.74, "trd": NaN, "batb": [[0, 2, 15], [1, 1.58, 204.9], [2, 1.53, 3.42]], "batl": [[0, 2.22, 54.32], [1, 880, 0.01], [2, 2.42, 0]]}, {"timestamp": 1632494783279, "ltp": 2.06, "tv": 1285.74, "trd": NaN, "batb": [[0, 1.58, 204.9], [1, 1.53, 3.42], [2, 1.49, 41.01]], "batl": [[0, 880, 0.01], [1, 880, 0]]}, {"timestamp": 1632494788902, "ltp": 2.06, "tv": 1285.74, "trd": NaN, "batb": [[2, 1.42, 43.44]], "batl": NaN}, {"timestamp": 1632494792097, "ltp": 2.06, "tv": 1285.74, "trd": NaN, "batb": [[0, 2.3, 415.76], [1, 2.28, 403.54], [2, 2.26, 403.54]], "batl": [[0, 2.42, 10.27], [1, 880, 0.01]]}, {"timestamp": 1632494793198, "ltp": 2.06, "tv": 1285.74, "trd": NaN, "batb": [[0, 2.32, 123.07], [1, 2.3, 415.76], [2, 2.28, 415.25]], "batl": [[1, 2.6, 47.43], [2, 2.66, 1.71]]}, {"timestamp": 1632494793777, "ltp": 2.06, "tv": 1285.74, "trd": NaN, "batb": NaN, "batl": [[1, 2.66, 1.71], [2, 2.9, 10.34]]}, {"timestamp": 1632494796658, "ltp": 2.06, "tv": 1285.74, "trd": NaN, "batb": [[2, 2.28, 403.54]], "batl": [[1, 2.56, 48.03], [2, 2.66, 1.71]]}, {"timestamp": 1632494799895, "ltp": 2.06, "tv": 1285.74, "trd": NaN, "batb": [[1, 2.3, 427.29]], "batl": NaN}, {"timestamp": 1632494802887, "ltp": 2.06, "tv": 1285.74, "trd": NaN, "batb": NaN, "batl": [[2, 2.68, 137.92]]}, {"timestamp": 1632494807198, "ltp": 2.06, "tv": 1285.74, "trd": NaN, "batb": [[1, 2.3, 11.53], [2, 1.98, 215.83]], "batl": [[0, 2.56, 48.03], [1, 2.68, 137.92], [2, 2.7, 194.17]]}, {"timestamp": 1632494807987, "ltp": 2.06, "tv": 1285.74, "trd": NaN, "batb": [[0, 2.3, 11.53], [1, 1.98, 215.83], [2, 1.97, 397.3]], "batl": NaN}, {"timestamp": 1632494808570, "ltp": 2.06, "tv": 1285.74, "trd": NaN, "batb": [[0, 1.98, 215.83], [1, 1.97, 397.3], [2, 1.95, 38.51]], "batl": [[0, 2.68, 137.92], [1, 2.7, 194.17], [2, 3.15, 204.05]]}, {"timestamp": 1632494810197, "ltp": 2.06, "tv": 1285.74, "trd": NaN, "batb": NaN, "batl": [[0, 2.56, 521.83], [1, 2.68, 137.92], [2, 2.7, 194.17]]}, {"timestamp": 1632494811186, "ltp": 2.06, "tv": 1285.74, "trd": NaN, "batb": NaN, "batl": [[0, 2.54, 3]]}, {"timestamp": 1632494812019, "ltp": 2.06, "tv": 1285.74, "trd": NaN, "batb": NaN, "batl": [[0, 2.68, 137.92], [1, 2.7, 194.17], [2, 3.15, 204.05]]}, {"timestamp": 1632494815912, "ltp": 2.06, "tv": 1285.74, "trd": NaN, "batb": [[0, 2.02, 115], [1, 1.98, 215.83], [2, 1.97, 397.3]], "batl": [[0, 2.62, 87.27], [1, 2.68, 137.92], [2, 2.7, 194.17]]}, {"timestamp": 1632494818195, "ltp": 2.06, "tv": 1285.74, "trd": NaN, "batb": [[0, 1.98, 215.83], [1, 1.97, 397.3], [2, 1.95, 38.51]], "batl": [[0, 2.68, 137.92], [1, 2.7, 194.17], [2, 3.15, 204.05]]}, {"timestamp": 1632494824826, "ltp": 2.06, "tv": 1285.74, "trd": NaN, "batb": NaN, "batl": [[0, 3.15, 204.05], [1, 880, 0.01], [2, 3.15, 0]]}, {"timestamp": 1632494826234, "ltp": 2.06, "tv": 1285.74, "trd": NaN, "batb": NaN, "batl": [[0, 880, 0.01], [1, 880, 0]]}, {"timestamp": 1632494828024, "ltp": 2.06, "tv": 1285.74, "trd": NaN, "batb": [[0, 2.02, 4], [1, 2, 7.56], [2, 1.98, 215.83]], "batl": [[0, 2.04, 177.75], [1, 2.06, 128.33], [2, 2.42, 12.4]]}, {"timestamp": 1632494829122, "ltp": 2.04, "tv": 1301.4, "trd": [[2.04, 15.66]], "batb": [[0, 2, 3.56], [1, 1.98, 215.83], [2, 1.97, 397.3]], "batl": [[0, 2.04, 162.09], [2, 2.34, 1.71]]}, {"timestamp": 1632494830121, "ltp": 2.04, "tv": 1301.4, "trd": NaN, "batb": [[2, 1.97, 412.53]], "batl": [[2, 2.18, 55.23]]}, {"timestamp": 1632494831634, "ltp": 2.04, "tv": 1301.4, "trd": NaN, "batb": NaN, "batl": [[0, 2.18, 55.23], [1, 2.34, 1.71], [2, 2.42, 12.4]]}, {"timestamp": 1632494832935, "ltp": 2.04, "tv": 1301.4, "trd": NaN, "batb": NaN, "batl": [[0, 2.34, 1.71], [1, 2.42, 12.4], [2, 2.46, 1825.38]]}, {"timestamp": 1632494835025, "ltp": 2.04, "tv": 1301.4, "trd": NaN, "batb": NaN, "batl": [[0, 2.16, 69.37], [1, 2.18, 1682.92], [2, 2.34, 1.71]]}, {"timestamp": 1632494836168, "ltp": 2.04, "tv": 1301.4, "trd": NaN, "batb": NaN, "batl": [[0, 2.16, 125.07]]}, {"timestamp": 1632494837165, "ltp": 2.04, "tv": 1301.4, "trd": NaN, "batb": NaN, "batl": [[0, 2.16, 55.7]]}, {"timestamp": 1632494839146, "ltp": 2.04, "tv": 1301.4, "trd": NaN, "batb": [[0, 1.98, 215.83], [1, 1.97, 412.53], [2, 1.95, 38.51]], "batl": [[2, 2.42, 12.4]]}, {"timestamp": 1632494840141, "ltp": 2.04, "tv": 1301.4, "trd": NaN, "batb": NaN, "batl": [[0, 2.14, 69.37], [1, 2.16, 55.7]]}, {"timestamp": 1632494841866, "ltp": 2.04, "tv": 1301.4, "trd": NaN, "batb": NaN, "batl": [[0, 2.06, 7.67]]}, {"timestamp": 1632494844945, "ltp": 2.04, "tv": 1301.4, "trd": NaN, "batb": NaN, "batl": [[0, 2.06, 77.04], [1, 2.42, 12.4], [2, 2.46, 1825.38]]}, {"timestamp": 1632494846150, "ltp": 2.04, "tv": 1301.4, "trd": NaN, "batb": NaN, "batl": [[0, 2.06, 36.77]]}, {"timestamp": 1632494847861, "ltp": 2.04, "tv": 1301.4, "trd": NaN, "batb": NaN, "batl": [[1, 2.14, 56.19], [2, 2.42, 12.4]]}, {"timestamp": 1632494851152, "ltp": 2.04, "tv": 1301.4, "trd": NaN, "batb": [[0, 1.97, 213.97], [1, 1.67, 417.19], [2, 1.57, 210.05]], "batl": [[0, 2.14, 56.19], [1, 2.72, 245.93], [2, 880, 0.01]]}, {"timestamp": 1632494851364, "ltp": 2.04, "tv": 1301.4, "trd": NaN, "batb": [[0, 1.97, 15.23]], "batl": NaN}, {"timestamp": 1632494852771, "ltp": 2.04, "tv": 1301.4, "trd": NaN, "batb": [[0, 1.67, 417.19], [1, 1.57, 210.05], [2, 1.53, 3.42]], "batl": [[0, 2.72, 245.93], [1, 880, 0.01], [2, 880, 0]]}, {"timestamp": 1632494855074, "ltp": 2.04, "tv": 1301.4, "trd": NaN, "batb": NaN, "batl": [[0, 880, 0.01], [1, 880, 0]]}, {"timestamp": 1632494856066, "ltp": 2.02, "tv": 1303.78, "trd": [[2.02, 2.38]], "batb": [[0, 1.87, 148.26], [1, 1.85, 175.24], [2, 1.67, 417.19]], "batl": [[0, 1.94, 168.51], [1, 1.96, 149.06], [2, 2.08, 18.44]]}, {"timestamp": 1632494856493, "ltp": 2.02, "tv": 1303.78, "trd": NaN, "batb": NaN, "batl": [[2, 880, 0.01]]}, {"timestamp": 1632494857663, "ltp": 2.02, "tv": 1303.78, "trd": NaN, "batb": [[2, 1.72, 133.72]], "batl": [[2, 2.14, 106.23]]}, {"timestamp": 1632494858970, "ltp": 1.94, "tv": 1308.2, "trd": [[1.94, 4.42]], "batb": NaN, "batl": [[0, 1.94, 166.3]]}, {"timestamp": 1632494860586, "ltp": 1.94, "tv": 1310.53, "trd": [[1.94, 6.75]], "batb": NaN, "batl": [[0, 1.94, 163.97]]}, {"timestamp": 1632494861683, "ltp": 1.94, "tv": 1310.53, "trd": NaN, "batb": [[0, 1.67, 417.19], [1, 1.57, 210.05], [2, 1.53, 3.42]], "batl": [[0, 2.6, 262.24], [1, 880, 0.01], [2, 2.14, 0]]}, {"timestamp": 1632494864578, "ltp": 1.94, "tv": 1310.53, "trd": NaN, "batb": [[1, 1.57, 390.31], [2, 1.56, 159.91]], "batl": [[0, 2.4, 107.1], [1, 2.44, 160.33], [2, 2.6, 262.24]]}, {"timestamp": 1632494868711, "ltp": 1.94, "tv": 1310.53, "trd": NaN, "batb": NaN, "batl": [[0, 2.6, 262.24], [1, 880, 0.01], [2, 2.6, 0]]}, {"timestamp": 1632494870211, "ltp": 1.67, "tv": 1315.94, "trd": [[1.67, 5.41]], "batb": [[0, 1.67, 414.49]], "batl": NaN}, {"timestamp": 1632494870921, "ltp": 1.67, "tv": 1315.94, "trd": NaN, "batb": [[0, 1.57, 390.31], [1, 1.56, 159.91], [2, 1.53, 3.42]], "batl": [[0, 880, 0.01], [1, 880, 0]]}, {"timestamp": 1632494871918, "ltp": 1.67, "tv": 1315.94, "trd": NaN, "batb": NaN, "batl": [[0, 1.6, 10.92], [1, 1.62, 258.47], [2, 1.63, 136.1]]}, {"timestamp": 1632494873189, "ltp": 1.6, "tv": 1326.86, "trd": [[1.6, 10.92]], "batb": NaN, "batl": [[0, 1.62, 258.47], [1, 1.63, 136.1], [2, 1.74, 60]]}, {"timestamp": 1632494874024, "ltp": 1.6, "tv": 1326.86, "trd": NaN, "batb": NaN, "batl": [[0, 1.62, 242.68], [2, 1.75, 137.49]]}, {"timestamp": 1632494875697, "ltp": 1.6, "tv": 1326.86, "trd": NaN, "batb": NaN, "batl": [[2, 1.67, 4]]}, {"timestamp": 1632494876899, "ltp": 1.6, "tv": 1326.86, "trd": NaN, "batb": [[0, 1.57, 408.23]], "batl": NaN}, {"timestamp": 1632494877633, "ltp": 1.57, "tv": 1354.58, "trd": [[1.57, 27.72]], "batb": [[0, 1.57, 394.2]], "batl": NaN}, {"timestamp": 1632494884142, "ltp": 1.57, "tv": 1354.77, "trd": [[1.57, 27.92]], "batb": [[0, 1.57, 394.1]], "batl": NaN}, {"timestamp": 1632494886049, "ltp": 1.57, "tv": 1378.42, "trd": [[1.57, 35.22], [1.58, 16.35]], "batb": [[0, 1.57, 390.45]], "batl": [[0, 1.62, 259.15]]}, {"timestamp": 1632494886627, "ltp": 1.62, "tv": 1379.68, "trd": [[1.62, 1.26]], "batb": NaN, "batl": [[0, 1.62, 258.52]]}, {"timestamp": 1632494896120, "ltp": 1.62, "tv": 1379.68, "trd": NaN, "batb": NaN, "batl": [[0, 1.62, 242.05]]}, {"timestamp": 1632494897320, "ltp": 1.62, "tv": 1384.38, "trd": [[1.62, 5.96]], "batb": NaN, "batl": [[0, 1.62, 239.7]]}, {"timestamp": 1632494899047, "ltp": 1.62, "tv": 1392.18, "trd": [[1.62, 13.76]], "batb": NaN, "batl": [[0, 1.6, 16.16], [1, 1.62, 235.8], [2, 1.63, 136.1]]}, {"timestamp": 1632494900147, "ltp": 1.6, "tv": 1393.36, "trd": [[1.6, 12.1]], "batb": NaN, "batl": [[0, 1.6, 15.57]]}, {"timestamp": 1632494903029, "ltp": 1.6, "tv": 1393.36, "trd": NaN, "batb": NaN, "batl": [[0, 1.6, 478.57]]}, {"timestamp": 1632494908174, "ltp": 1.6, "tv": 1393.52, "trd": [[1.6, 12.26]], "batb": NaN, "batl": [[0, 1.6, 478.41]]}, {"timestamp": 1632494909055, "ltp": 1.6, "tv": 1393.85, "trd": [[1.6, 12.59]], "batb": NaN, "batl": [[0, 1.6, 478.24]]}, {"timestamp": 1632494910046, "ltp": 1.6, "tv": 1393.85, "trd": NaN, "batb": NaN, "batl": [[0, 1.6, 463]]}, {"timestamp": 1632494912988, "ltp": 1.57, "tv": 1718.43, "trd": [[1.57, 359.79]], "batb": [[0, 1.57, 228.16]], "batl": [[0, 1.6, 478.24]]}, {"timestamp": 1632494917201, "ltp": 1.6, "tv": 1718.51, "trd": [[1.6, 12.67]], "batb": [[0, 1.57, 411.38]], "batl": [[0, 1.6, 478.2]]}, {"timestamp": 1632494918505, "ltp": 1.6, "tv": 1719.29, "trd": [[1.6, 13.45]], "batb": NaN, "batl": [[0, 1.6, 462.57]]}, {"timestamp": 1632494923221, "ltp": 1.6, "tv": 1719.91, "trd": [[1.6, 14.07]], "batb": NaN, "batl": [[0, 1.6, 462.26]]}, {"timestamp": 1632494924218, "ltp": 1.6, "tv": 1853.02, "trd": [[1.57, 492.87], [1.6, 14.1]], "batb": [[0, 1.57, 344.84]], "batl": [[0, 1.6, 462.23]]}, {"timestamp": 1632494924792, "ltp": 1.6, "tv": 1853.02, "trd": NaN, "batb": NaN, "batl": [[0, 1.6, 477.47]]}, {"timestamp": 1632494927183, "ltp": 1.6, "tv": 1853.02, "trd": NaN, "batb": [[0, 1.57, 365.13]], "batl": [[1, 1.62, 258.46]]}, {"timestamp": 1632494933112, "ltp": 1.6, "tv": 1855.76, "trd": [[1.6, 16.84]], "batb": NaN, "batl": [[0, 1.6, 476.1]]}, {"timestamp": 1632494944136, "ltp": 1.6, "tv": 1889.98, "trd": [[1.6, 51.06]], "batb": NaN, "batl": [[0, 1.6, 458.99]]}, {"timestamp": 1632494944918, "ltp": 1.6, "tv": 1892.32, "trd": [[1.6, 53.4]], "batb": NaN, "batl": [[0, 1.6, 457.82]]}, {"timestamp": 1632494960179, "ltp": 1.6, "tv": 1892.32, "trd": NaN, "batb": NaN, "batl": [[0, 1.6, 442.58]]}, {"timestamp": 1632494961171, "ltp": 1.6, "tv": 1892.32, "trd": NaN, "batb": [[0, 1.53, 3.42], [1, 1.5, 252.73], [2, 1.49, 43.01]], "batl": [[0, 1.98, 30.45], [1, 2.22, 334.98], [2, 990, 0.01]]}, {"timestamp": 1632494963945, "ltp": 1.6, "tv": 1892.32, "trd": NaN, "batb": [[1, 1.5, 485.75], [2, 1.49, 193.81]], "batl": [[0, 1.76, 141.97], [1, 1.77, 14.5], [2, 1.78, 202.87]]}, {"timestamp": 1632494964769, "ltp": 1.6, "tv": 1892.32, "trd": NaN, "batb": NaN, "batl": [[0, 1.76, 3], [2, 1.83, 14.5]]}, {"timestamp": 1632494968190, "ltp": 1.6, "tv": 1892.32, "trd": NaN, "batb": NaN, "batl": [[0, 1.54, 222.7], [1, 1.55, 164.22], [2, 1.56, 511.66]]}, {"timestamp": 1632494969875, "ltp": 1.6, "tv": 1892.32, "trd": NaN, "batb": [[1, 1.51, 21], [2, 1.5, 485.75]], "batl": NaN}, {"timestamp": 1632494970986, "ltp": 1.53, "tv": 1899.16, "trd": [[1.53, 6.84]], "batb": [[0, 1.51, 21], [1, 1.5, 485.75], [2, 1.49, 200.81]], "batl": NaN}, {"timestamp": 1632494973970, "ltp": 1.53, "tv": 1899.16, "trd": NaN, "batb": NaN, "batl": [[0, 1.54, 360.7]]}, {"timestamp": 1632494975081, "ltp": 1.53, "tv": 1899.16, "trd": NaN, "batb": [[2, 1.49, 252.82]], "batl": [[0, 1.54, 222.7]]}, {"timestamp": 1632494977191, "ltp": 1.53, "tv": 1899.16, "trd": NaN, "batb": NaN, "batl": [[0, 1.53, 378], [1, 1.54, 222.7], [2, 1.55, 164.22]]}, {"timestamp": 1632494978915, "ltp": 1.53, "tv": 1899.34, "trd": [[1.53, 7.03]], "batb": NaN, "batl": [[0, 1.53, 377.91]]}, {"timestamp": 1632494982102, "ltp": 1.53, "tv": 1899.34, "trd": NaN, "batb": [[1, 1.48, 5], [2, 1.47, 52.67]], "batl": [[0, 1.62, 60], [1, 1.63, 20.77], [2, 1.64, 267.03]]}, {"timestamp": 1632494982696, "ltp": 1.53, "tv": 1899.34, "trd": NaN, "batb": [[0, 1.48, 5], [1, 1.46, 800.64], [2, 1.45, 435.52]], "batl": [[0, 1.64, 267.03], [1, 1.65, 218.42], [2, 1.66, 19.25]]}, {"timestamp": 1632494984180, "ltp": 1.53, "tv": 1899.34, "trd": NaN, "batb": [[2, 1.45, 729.41]], "batl": [[1, 1.65, 453.65], [2, 1.66, 146.9]]}, {"timestamp": 1632494984803, "ltp": 1.53, "tv": 1899.34, "trd": NaN, "batb": NaN, "batl": [[1, 1.65, 218.42], [2, 1.66, 19.25]]}, {"timestamp": 1632494986110, "ltp": 1.53, "tv": 1899.34, "trd": NaN, "batb": [[0, 1.52, 153.36], [1, 1.51, 183.39], [2, 1.48, 5]], "batl": [[0, 1.55, 18.5], [1, 1.56, 213.64], [2, 1.57, 156.45]]}, {"timestamp": 1632494987213, "ltp": 1.53, "tv": 1899.34, "trd": NaN, "batb": [[2, 1.49, 25]], "batl": [[0, 1.56, 213.64], [1, 1.57, 156.45], [2, 1.63, 98.01]]}, {"timestamp": 1632494989733, "ltp": 1.53, "tv": 1899.34, "trd": NaN, "batb": [[0, 1.48, 5], [1, 1.47, 7], [2, 1.46, 800.64]], "batl": [[0, 1.64, 267.03], [1, 1.65, 218.42], [2, 1.66, 19.25]]}, {"timestamp": 1632494993007, "ltp": 1.53, "tv": 1899.34, "trd": NaN, "batb": [[1, 1.47, 63.67]], "batl": [[0, 1.63, 19.5], [1, 1.64, 267.03], [2, 1.65, 451.83]]}, {"timestamp": 1632494994005, "ltp": 1.53, "tv": 1899.34, "trd": NaN, "batb": [[1, 1.47, 7]], "batl": [[0, 1.52, 48.26], [1, 1.66, 19.25], [2, 1.67, 16.5]]}, {"timestamp": 1632494994618, "ltp": 1.53, "tv": 1899.34, "trd": NaN, "batb": NaN, "batl": [[0, 1.49, 2.19], [1, 1.52, 48.26]]}, {"timestamp": 1632494995417, "ltp": 1.53, "tv": 1899.34, "trd": NaN, "batb": [[2, 1.46, 357.04]], "batl": NaN}, {"timestamp": 1632494997124, "ltp": 1.48, "tv": 1909.34, "trd": [[1.48, 10]], "batb": [[0, 1.47, 7], [1, 1.46, 357.04], [2, 1.45, 729.41]], "batl": [[0, 1.48, 151.44], [1, 1.49, 194.55], [2, 1.5, 8.16]]}, {"timestamp": 1632494998219, "ltp": 1.48, "tv": 1932.07, "trd": [[1.48, 32.73]], "batb": [[1, 1.46, 379.15]], "batl": [[0, 1.49, 192.36], [1, 1.5, 8.16], [2, 1.52, 48.26]]}, {"timestamp": 1632494999038, "ltp": 1.48, "tv": 1932.07, "trd": NaN, "batb": [[0, 1.46, 379.15], [1, 1.45, 729.41], [2, 1.44, 605.12]], "batl": [[2, 1.56, 1370.77]]}, {"timestamp": 1632495000214, "ltp": 1.48, "tv": 1932.07, "trd": NaN, "batb": [[0, 1.46, 386.15]], "batl": [[2, 1.56, 1310.77]]}, {"timestamp": 1632495001216, "ltp": 1.48, "tv": 1932.07, "trd": NaN, "batb": [[0, 1.46, 379.15], [1, 1.45, 885.46]], "batl": [[0, 1.48, 139], [1, 1.49, 366.28], [2, 1.5, 194.13]]}, {"timestamp": 1632495002037, "ltp": 1.48, "tv": 1932.07, "trd": NaN, "batb": [[2, 1.44, 611.12]], "batl": NaN}, {"timestamp": 1632495004044, "ltp": 1.48, "tv": 1938.97, "trd": [[1.48, 39.63]], "batb": NaN, "batl": [[0, 1.48, 443.55]]}, {"timestamp": 1632495005125, "ltp": 1.48, "tv": 1938.97, "trd": NaN, "batb": [[2, 1.44, 668.54]], "batl": NaN}, {"timestamp": 1632495007124, "ltp": 1.48, "tv": 1946.61, "trd": [[1.48, 47.27]], "batb": NaN, "batl": [[0, 1.48, 439.73]]}, {"timestamp": 1632495011943, "ltp": 1.48, "tv": 1946.61, "trd": NaN, "batb": [[0, 1.46, 357.04]], "batl": NaN}, {"timestamp": 1632495015169, "ltp": 1.48, "tv": 1946.61, "trd": NaN, "batb": [[0, 1.45, 53.01], [1, 1.44, 86.03], [2, 1.43, 282.57]], "batl": [[0, 1.54, 24.75], [1, 1.56, 277.46], [2, 1.57, 314.56]]}, {"timestamp": 1632495015378, "ltp": 1.48, "tv": 1946.61, "trd": NaN, "batb": [[0, 1.44, 86.03], [1, 1.43, 282.57], [2, 1.42, 346.42]], "batl": [[0, 1.56, 277.46], [1, 1.57, 314.56], [2, 1.63, 17.5]]}, {"timestamp": 1632495016744, "ltp": 1.48, "tv": 1946.61, "trd": NaN, "batb": [[0, 1.44, 63.42]], "batl": [[0, 1.47, 57.91], [1, 1.56, 277.46], [2, 1.57, 314.56]]}, {"timestamp": 1632495018044, "ltp": 1.48, "tv": 1946.61, "trd": NaN, "batb": NaN, "batl": [[1, 1.55, 172.87], [2, 1.56, 437.89]]}, {"timestamp": 1632495018969, "ltp": 1.47, "tv": 1951.3, "trd": [[1.47, 4.69]], "batb": [[1, 1.43, 289.57]], "batl": [[0, 1.47, 55.57], [1, 1.54, 22.25], [2, 1.55, 172.87]]}, {"timestamp": 1632495019956, "ltp": 1.47, "tv": 1951.3, "trd": NaN, "batb": NaN, "batl": [[2, 1.56, 283.46]]}, {"timestamp": 1632495021948, "ltp": 1.54, "tv": 1955.68, "trd": [[1.54, 4.38]], "batb": [[0, 1.45, 54.81], [1, 1.44, 63.42], [2, 1.43, 289.57]], "batl": [[0, 1.56, 283.46], [1, 1.57, 314.56], [2, 1.63, 17.5]]}, {"timestamp": 1632495023185, "ltp": 1.54, "tv": 1955.68, "trd": NaN, "batb": [[0, 1.46, 202.23], [1, 1.45, 217.51], [2, 1.44, 63.42]], "batl": [[0, 1.49, 18.99], [1, 1.5, 268.9], [2, 1.51, 181.51]]}, {"timestamp": 1632495023969, "ltp": 1.54, "tv": 1955.68, "trd": NaN, "batb": [[1, 1.45, 261.33]], "batl": [[0, 1.5, 268.9], [1, 1.51, 181.51], [2, 1.56, 283.46]]}, {"timestamp": 1632495024964, "ltp": 1.54, "tv": 1955.68, "trd": NaN, "batb": NaN, "batl": [[2, 1.53, 65.78]]}, {"timestamp": 1632495025857, "ltp": 1.54, "tv": 1955.68, "trd": NaN, "batb": [[1, 1.45, 322.74]], "batl": NaN}, {"timestamp": 1632495028084, "ltp": 1.54, "tv": 1955.68, "trd": NaN, "batb": [[0, 1.44, 63.42], [1, 1.43, 289.57], [2, 1.42, 346.42]], "batl": [[0, 1.56, 283.46], [1, 1.57, 314.56], [2, 1.63, 17.5]]}, {"timestamp": 1632495029179, "ltp": 1.54, "tv": 1955.68, "trd": NaN, "batb": [[0, 1.47, 2.35], [1, 1.44, 63.42], [2, 1.43, 289.57]], "batl": [[0, 1.49, 119], [1, 1.56, 283.46], [2, 1.57, 314.56]]}, {"timestamp": 1632495029861, "ltp": 1.54, "tv": 1955.68, "trd": NaN, "batb": [[2, 1.43, 7]], "batl": [[0, 1.56, 283.46], [1, 1.57, 314.56], [2, 1.63, 17.5]]}, {"timestamp": 1632495030992, "ltp": 1.54, "tv": 1955.68, "trd": NaN, "batb": [[2, 1.41, 328.73]], "batl": [[0, 1.55, 172.87], [1, 1.56, 437.89], [2, 1.57, 314.56]]}, {"timestamp": 1632495032164, "ltp": 1.54, "tv": 1955.68, "trd": NaN, "batb": [[1, 1.45, 3], [2, 1.44, 63.42]], "batl": NaN}, {"timestamp": 1632495033199, "ltp": 1.54, "tv": 1955.68, "trd": NaN, "batb": [[0, 1.51, 272.74], [1, 1.5, 188.69], [2, 1.49, 641.78]], "batl": [[1, 1.56, 450.95], [2, 1.57, 923.64]]}, {"timestamp": 1632495034196, "ltp": 1.54, "tv": 1955.68, "trd": NaN, "batb": [[0, 1.51, 515.77], [1, 1.5, 209.9]], "batl": NaN}, {"timestamp": 1632495035969, "ltp": 1.54, "tv": 1955.68, "trd": NaN, "batb": [[1, 1.5, 215.9], [2, 1.49, 648.78]], "batl": NaN}, {"timestamp": 1632495037881, "ltp": 1.54, "tv": 1955.68, "trd": NaN, "batb": [[1, 1.5, 194.69]], "batl": NaN}, {"timestamp": 1632495038976, "ltp": 1.54, "tv": 1955.68, "trd": NaN, "batb": NaN, "batl": [[0, 1.54, 280], [1, 1.55, 172.87], [2, 1.56, 450.95]]}, {"timestamp": 1632495041133, "ltp": 1.54, "tv": 1955.68, "trd": NaN, "batb": [[0, 1.51, 536.77]], "batl": NaN}, {"timestamp": 1632495045222, "ltp": 1.53, "tv": 1969.84, "trd": [[1.53, 21.18]], "batb": NaN, "batl": [[0, 1.53, 14.8], [1, 1.54, 280], [2, 1.55, 172.87]]}, {"timestamp": 1632495046014, "ltp": 1.53, "tv": 1969.84, "trd": NaN, "batb": NaN, "batl": [[1, 1.55, 172.87], [2, 1.56, 450.95]]}, {"timestamp": 1632495046796, "ltp": 1.53, "tv": 1999.44, "trd": [[1.53, 50.79]], "batb": [[0, 1.54, 120.45], [1, 1.51, 536.77], [2, 1.5, 194.69]], "batl": [[0, 1.55, 172.87], [1, 1.56, 450.95], [2, 1.57, 923.64]]}, {"timestamp": 1632495048032, "ltp": 1.51, "tv": 2462.22, "trd": [[1.51, 221.88], [1.54, 245.28]], "batb": [[0, 1.51, 425.83], [1, 1.5, 194.69], [2, 1.49, 648.78]], "batl": NaN}, {"timestamp": 1632495048310, "ltp": 1.51, "tv": 2462.22, "trd": NaN, "batb": [[2, 1.49, 641.78]], "batl": NaN}, {"timestamp": 1632495051525, "ltp": 1.51, "tv": 2462.22, "trd": NaN, "batb": [[2, 1.49, 648.78]], "batl": [[0, 1.55, 206.36]]}, {"timestamp": 1632495055022, "ltp": 1.51, "tv": 2462.22, "trd": NaN, "batb": [[0, 1.51, 21], [1, 1.47, 60.02], [2, 1.46, 56.88]], "batl": [[0, 1.63, 17.5], [1, 1.66, 259.14], [2, 1.67, 268.35]]}, {"timestamp": 1632495056163, "ltp": 1.51, "tv": 2462.22, "trd": NaN, "batb": NaN, "batl": [[0, 1.66, 259.14], [1, 1.67, 268.35], [2, 1.98, 16.27]]}, {"timestamp": 1632495056931, "ltp": 1.51, "tv": 2462.22, "trd": NaN, "batb": [[0, 1.54, 2.19], [1, 1.47, 2.35], [2, 1.45, 585.47]], "batl": NaN}, {"timestamp": 1632495057955, "ltp": 1.51, "tv": 2462.22, "trd": NaN, "batb": NaN, "batl": [[2, 1.68, 194.48]]}, {"timestamp": 1632495059023, "ltp": 1.51, "tv": 2462.22, "trd": NaN, "batb": NaN, "batl": [[0, 1.66, 263.14]]}, {"timestamp": 1632495060154, "ltp": 1.51, "tv": 2462.22, "trd": NaN, "batb": [[0, 1.47, 2.35], [1, 1.45, 585.47], [2, 1.44, 696.78]], "batl": [[0, 1.66, 4], [1, 1.67, 16.5], [2, 1.98, 16.27]]}, {"timestamp": 1632495063159, "ltp": 1.51, "tv": 2462.22, "trd": NaN, "batb": NaN, "batl": [[0, 1.48, 165.74], [1, 1.49, 192.41], [2, 1.56, 1213.55]]}, {"timestamp": 1632495064073, "ltp": 1.51, "tv": 2462.22, "trd": NaN, "batb": NaN, "batl": [[2, 1.51, 27.37]]}, {"timestamp": 1632495065049, "ltp": 1.51, "tv": 2462.22, "trd": NaN, "batb": [[0, 1.45, 585.47], [1, 1.44, 719.39], [2, 1.43, 232.61]], "batl": NaN}, {"timestamp": 1632495065469, "ltp": 1.51, "tv": 2462.22, "trd": NaN, "batb": [[1, 1.44, 726.39], [2, 1.43, 238.61]], "batl": NaN}, {"timestamp": 1632495069551, "ltp": 1.51, "tv": 2462.22, "trd": NaN, "batb": [[2, 1.43, 549.65]], "batl": NaN}, {"timestamp": 1632495070756, "ltp": 1.46, "tv": 2464.53, "trd": [[1.46, 2.31]], "batb": [[2, 1.43, 580.08]], "batl": [[2, 1.51, 51.87]]}, {"timestamp": 1632495073052, "ltp": 1.48, "tv": 2476.81, "trd": [[1.48, 59.55]], "batb": NaN, "batl": [[0, 1.48, 159.6]]}, {"timestamp": 1632495073260, "ltp": 1.48, "tv": 2484.65, "trd": [[1.48, 67.39]], "batb": NaN, "batl": [[0, 1.48, 155.68]]}, {"timestamp": 1632495076210, "ltp": 1.48, "tv": 2484.65, "trd": NaN, "batb": NaN, "batl": [[2, 1.51, 24.5]]}, {"timestamp": 1632495076264, "ltp": 1.48, "tv": 2489.35, "trd": [[1.48, 72.09]], "batb": NaN, "batl": [[0, 1.48, 153.33]]}, {"timestamp": 1632495078159, "ltp": 1.48, "tv": 2489.35, "trd": NaN, "batb": [[0, 1.44, 87.03], [1, 1.43, 341.47], [2, 1.42, 652.96]], "batl": [[0, 1.51, 24.5], [1, 1.53, 23.5], [2, 1.54, 331.76]]}, {"timestamp": 1632495079194, "ltp": 1.48, "tv": 2489.35, "trd": NaN, "batb": [[0, 1.44, 64.42]], "batl": [[0, 1.53, 23.5], [1, 1.54, 271.76], [2, 1.55, 331.54]]}, {"timestamp": 1632495079664, "ltp": 1.48, "tv": 2489.35, "trd": NaN, "batb": [[0, 1.44, 7]], "batl": [[0, 1.46, 2.35], [1, 1.47, 27.37], [2, 1.53, 23.5]]}, {"timestamp": 1632495081877, "ltp": 1.48, "tv": 2489.35, "trd": NaN, "batb": [[1, 1.43, 348.47]], "batl": NaN}, {"timestamp": 1632495084077, "ltp": 1.47, "tv": 2496.08, "trd": [[1.46, 4.65], [1.47, 9.07]], "batb": [[0, 1.46, 173.61], [1, 1.45, 217.5], [2, 1.44, 7]], "batl": [[0, 1.47, 25.18], [1, 1.5, 296.74], [2, 1.51, 181.51]]}, {"timestamp": 1632495085075, "ltp": 1.47, "tv": 2546.44, "trd": [[1.47, 59.44]], "batb": [[0, 1.48, 26.03], [1, 1.46, 173.61], [2, 1.45, 217.5]], "batl": [[0, 1.5, 296.74], [1, 1.51, 181.51], [2, 1.53, 23.5]]}, {"timestamp": 1632495086183, "ltp": 1.47, "tv": 2546.44, "trd": NaN, "batb": [[1, 1.44, 39.67], [2, 1.43, 348.47]], "batl": [[0, 1.51, 22.01], [1, 1.53, 23.5], [2, 1.54, 271.76]]}, {"timestamp": 1632495086482, "ltp": 1.47, "tv": 2546.44, "trd": NaN, "batb": [[1, 1.44, 7]], "batl": [[0, 1.53, 23.5], [1, 1.54, 271.76], [2, 1.55, 331.54]]}, {"timestamp": 1632495088997, "ltp": 1.47, "tv": 2546.44, "trd": NaN, "batb": NaN, "batl": [[2, 1.55, 567.58]]}, {"timestamp": 1632495090096, "ltp": 1.47, "tv": 2546.44, "trd": NaN, "batb": [[1, 1.44, 21.92]], "batl": NaN}, {"timestamp": 1632495090409, "ltp": 1.47, "tv": 2546.44, "trd": NaN, "batb": [[1, 1.44, 22.01]], "batl": NaN}, {"timestamp": 1632495093687, "ltp": 1.47, "tv": 2546.44, "trd": NaN, "batb": [[2, 1.43, 341.47]], "batl": NaN}, {"timestamp": 1632495094819, "ltp": 1.47, "tv": 2546.44, "trd": NaN, "batb": [[0, 1.52, 2.19], [1, 1.48, 26.03], [2, 1.44, 22.01]], "batl": NaN}, {"timestamp": 1632495097125, "ltp": 1.47, "tv": 2546.44, "trd": NaN, "batb": [[0, 1.48, 26.03], [1, 1.44, 51.18], [2, 1.43, 341.47]], "batl": [[0, 1.51, 23.5], [1, 1.53, 23.5], [2, 1.54, 271.76]]}, {"timestamp": 1632495097231, "ltp": 1.47, "tv": 2546.44, "trd": NaN, "batb": [[1, 1.44, 22.01], [2, 1.43, 30.43]], "batl": [[0, 1.53, 23.5], [1, 1.54, 271.76], [2, 1.55, 567.58]]}, {"timestamp": 1632495100009, "ltp": 1.53, "tv": 2564.17, "trd": [[1.53, 68.52]], "batb": [[0, 1.51, 146.26], [1, 1.5, 219.98], [2, 1.48, 1630.48]], "batl": [[0, 1.53, 5.77], [2, 1.55, 565.58]]}, {"timestamp": 1632495101208, "ltp": 1.53, "tv": 2564.17, "trd": NaN, "batb": [[0, 1.52, 238.98], [1, 1.51, 146.26], [2, 1.5, 219.98]], "batl": NaN}, {"timestamp": 1632495104037, "ltp": 1.53, "tv": 2575.71, "trd": [[1.53, 80.06]], "batb": NaN, "batl": [[0, 1.54, 271.76], [1, 1.55, 565.58], [2, 1.56, 160.3]]}, {"timestamp": 1632495107720, "ltp": 1.52, "tv": 2579.95, "trd": [[1.52, 4.24]], "batb": [[0, 1.52, 236.86]], "batl": NaN}, {"timestamp": 1632495108516, "ltp": 1.52, "tv": 2579.95, "trd": NaN, "batb": [[1, 1.51, 167.26]], "batl": NaN}, {"timestamp": 1632495119846, "ltp": 1.52, "tv": 2579.95, "trd": NaN, "batb": [[0, 1.53, 2.35], [1, 1.52, 236.86], [2, 1.51, 167.26]], "batl": NaN}, {"timestamp": 1632495121569, "ltp": 1.54, "tv": 2586.28, "trd": [[1.54, 251.61]], "batb": NaN, "batl": [[0, 1.54, 268.6]]}, {"timestamp": 1632495124148, "ltp": 1.54, "tv": 2586.28, "trd": NaN, "batb": NaN, "batl": [[0, 1.55, 236.04], [1, 1.56, 160.3], [2, 1.64, 17.68]]}, {"timestamp": 1632495125139, "ltp": 1.54, "tv": 2586.28, "trd": NaN, "batb": [[1, 1.51, 21], [2, 1.48, 26.03]], "batl": [[0, 1.68, 224.38], [1, 1.69, 331.86], [2, 2.1, 372.06]]}, {"timestamp": 1632495126133, "ltp": 1.54, "tv": 2586.28, "trd": NaN, "batb": [[1, 1.48, 26.03], [2, 1.45, 288.72]], "batl": NaN}, {"timestamp": 1632495127963, "ltp": 1.54, "tv": 2586.28, "trd": NaN, "batb": [[0, 1.54, 2.35], [1, 1.53, 2.35], [2, 1.48, 26.03]], "batl": [[0, 1.69, 19.5], [1, 2.1, 372.06], [2, 990, 0.01]]}, {"timestamp": 1632495128783, "ltp": 1.54, "tv": 2586.28, "trd": NaN, "batb": NaN, "batl": [[0, 1.68, 2], [1, 1.69, 19.5], [2, 2.1, 372.06]]}, {"timestamp": 1632495130190, "ltp": 1.48, "tv": 2647.73, "trd": [[1.48, 124.15], [1.53, 84.75], [1.54, 256.31]], "batb": [[0, 1.46, 13.6], [1, 1.45, 288.72], [2, 1.44, 1036.42]], "batl": [[0, 1.48, 4378.1], [1, 1.5, 159.75], [2, 1.66, 18.07]]}, {"timestamp": 1632495131182, "ltp": 1.47, "tv": 2675.02, "trd": [[1.47, 82.03], [1.48, 128.85]], "batb": [[1, 1.44, 1079.58], [2, 1.43, 1945.99]], "batl": [[0, 1.47, 229.09], [1, 1.48, 207.46], [2, 1.5, 159.75]]}, {"timestamp": 1632495132179, "ltp": 1.47, "tv": 2675.02, "trd": NaN, "batb": [[2, 1.43, 631.31]], "batl": NaN}, {"timestamp": 1632495133799, "ltp": 1.47, "tv": 2675.02, "trd": NaN, "batb": [[2, 1.43, 635.75]], "batl": NaN}, {"timestamp": 1632495136874, "ltp": 1.47, "tv": 2675.02, "trd": NaN, "batb": [[2, 1.43, 645.4]], "batl": NaN}, {"timestamp": 1632495138079, "ltp": 1.46, "tv": 2785.56, "trd": [[1.46, 115.19]], "batb": [[0, 1.44, 1079.58], [1, 1.43, 645.4], [2, 1.42, 402.2]], "batl": [[0, 1.46, 87.3], [1, 1.47, 229.09], [2, 1.48, 207.46]]}, {"timestamp": 1632495140180, "ltp": 1.46, "tv": 2828.51, "trd": [[1.46, 158.15]], "batb": NaN, "batl": [[0, 1.46, 65.82]]}, {"timestamp": 1632495142113, "ltp": 1.46, "tv": 2834.52, "trd": [[1.46, 164.15]], "batb": NaN, "batl": [[0, 1.46, 62.82]]}, {"timestamp": 1632495142320, "ltp": 1.46, "tv": 2862.66, "trd": [[1.46, 192.3]], "batb": NaN, "batl": [[0, 1.46, 48.74]]}, {"timestamp": 1632495144913, "ltp": 1.46, "tv": 2862.86, "trd": [[1.46, 192.49]], "batb": NaN, "batl": [[0, 1.46, 48.55]]}, {"timestamp": 1632495145904, "ltp": 1.47, "tv": 3048.08, "trd": [[1.44, 3.82], [1.45, 0.18], [1.46, 289.59], [1.47, 166.15]], "batb": [[0, 1.44, 1077.57]], "batl": [[0, 1.47, 187.03], [1, 1.48, 207.46], [2, 1.5, 159.75]]}, {"timestamp": 1632495146268, "ltp": 1.47, "tv": 3048.08, "trd": NaN, "batb": [[0, 1.46, 25], [1, 1.44, 1077.57], [2, 1.43, 645.4]], "batl": NaN}, {"timestamp": 1632495148214, "ltp": 1.47, "tv": 3052.78, "trd": [[1.47, 170.84]], "batb": NaN, "batl": [[0, 1.47, 184.68]]}, {"timestamp": 1632495149107, "ltp": 1.47, "tv": 3052.78, "trd": NaN, "batb": [[0, 1.46, 26.57], [2, 1.43, 684.08]], "batl": [[0, 1.47, 213.6], [1, 1.48, 197.17]]}, {"timestamp": 1632495151824, "ltp": 1.47, "tv": 3052.78, "trd": NaN, "batb": [[1, 1.45, 12.65], [2, 1.44, 1077.57]], "batl": [[0, 1.47, 225.71]]}, {"timestamp": 1632495155124, "ltp": 1.47, "tv": 3092.78, "trd": [[1.47, 210.84]], "batb": NaN, "batl": [[0, 1.47, 205.71]]}, {"timestamp": 1632495159049, "ltp": 1.47, "tv": 3093.09, "trd": [[1.47, 211.16]], "batb": NaN, "batl": [[0, 1.47, 205.55]]}, {"timestamp": 1632495162131, "ltp": 1.47, "tv": 3246.07, "trd": [[1.47, 364.14]], "batb": NaN, "batl": [[0, 1.47, 12.11]]}, {"timestamp": 1632495163221, "ltp": 1.46, "tv": 3305.98, "trd": [[1.46, 349.5]], "batb": [[0, 1.45, 12.65], [1, 1.44, 1077.57], [2, 1.43, 591.45]], "batl": [[0, 1.46, 9.73], [1, 1.47, 12.11], [2, 1.48, 197.17]]}, {"timestamp": 1632495165067, "ltp": 1.46, "tv": 3305.98, "trd": NaN, "batb": [[1, 1.44, 1268.65]], "batl": [[2, 1.48, 315.36]]}, {"timestamp": 1632495165319, "ltp": 1.46, "tv": 3305.98, "trd": NaN, "batb": NaN, "batl": [[0, 1.46, 4.57]]}, {"timestamp": 1632495177669, "ltp": 1.46, "tv": 3305.98, "trd": NaN, "batb": [[0, 1.46, 13.76], [1, 1.45, 12.65], [2, 1.44, 1268.65]], "batl": [[0, 1.47, 12.11], [1, 1.48, 315.36], [2, 1.49, 190.45]]}, {"timestamp": 1632495178933, "ltp": 1.46, "tv": 3305.98, "trd": NaN, "batb": [[0, 1.46, 14.93]], "batl": NaN}, {"timestamp": 1632495180137, "ltp": 1.46, "tv": 3394.9, "trd": [[1.46, 438.42]], "batb": [[0, 1.45, 12.65], [1, 1.44, 1268.65], [2, 1.43, 591.45]], "batl": [[0, 1.46, 435.01], [1, 1.47, 12.11], [2, 1.48, 315.36]]}, {"timestamp": 1632495184072, "ltp": 1.46, "tv": 3394.9, "trd": NaN, "batb": NaN, "batl": [[0, 1.46, 686]]}, {"timestamp": 1632495186070, "ltp": 1.46, "tv": 3394.9, "trd": NaN, "batb": [[0, 1.45, 13]], "batl": NaN}, {"timestamp": 1632495188267, "ltp": 1.46, "tv": 3395.41, "trd": [[1.46, 438.93]], "batb": NaN, "batl": [[0, 1.46, 685.49]]}, {"timestamp": 1632495189988, "ltp": 1.46, "tv": 3410.33, "trd": [[1.46, 453.85]], "batb": NaN, "batl": [[0, 1.46, 678.03]]}, {"timestamp": 1632495190983, "ltp": 1.45, "tv": 3436.32, "trd": [[1.45, 26.18]], "batb": [[0, 1.44, 1268.65], [1, 1.43, 591.45], [2, 1.42, 164.34]], "batl": [[0, 1.45, 10.74], [1, 1.46, 678.03], [2, 1.47, 12.11]]}, {"timestamp": 1632495191498, "ltp": 1.46, "tv": 3461.44, "trd": [[1.45, 39.26], [1.46, 465.88]], "batb": NaN, "batl": [[0, 1.46, 666], [1, 1.47, 12.11], [2, 1.48, 315.36]]}, {"timestamp": 1632495193172, "ltp": 1.46, "tv": 3466.13, "trd": [[1.46, 470.57]], "batb": NaN, "batl": [[0, 1.46, 663.65]]}, {"timestamp": 1632495193280, "ltp": 1.46, "tv": 3473.03, "trd": [[1.46, 477.47]], "batb": NaN, "batl": [[0, 1.46, 660.2]]}, {"timestamp": 1632495195707, "ltp": 1.46, "tv": 3473.22, "trd": [[1.46, 477.66]], "batb": NaN, "batl": [[0, 1.46, 660.11]]}, {"timestamp": 1632495198321, "ltp": 1.44, "tv": 3478.26, "trd": [[1.44, 8.87]], "batb": [[0, 1.44, 1266.13]], "batl": NaN}, {"timestamp": 1632495201103, "ltp": 1.44, "tv": 3478.26, "trd": NaN, "batb": NaN, "batl": [[1, 1.48, 315.36], [2, 1.49, 190.45]]}, {"timestamp": 1632495204092, "ltp": 1.44, "tv": 3478.26, "trd": NaN, "batb": [[0, 1.44, 1279.26]], "batl": [[0, 1.46, 672.67]]}, {"timestamp": 1632495204823, "ltp": 1.46, "tv": 3508.26, "trd": [[1.46, 507.66]], "batb": [[0, 1.44, 1266.13]], "batl": [[0, 1.46, 645.11]]}, {"timestamp": 1632495207277, "ltp": 1.46, "tv": 3508.26, "trd": NaN, "batb": [[0, 1.44, 1279.26]], "batl": [[0, 1.46, 657.67]]}, {"timestamp": 1632495210594, "ltp": 1.46, "tv": 3510.11, "trd": [[1.46, 509.51]], "batb": NaN, "batl": [[0, 1.46, 655.82]]}, {"timestamp": 1632495214812, "ltp": 1.46, "tv": 3511.8, "trd": [[1.46, 511.19]], "batb": NaN, "batl": [[0, 1.46, 654.98]]}, {"timestamp": 1632495215806, "ltp": 1.46, "tv": 3513.48, "trd": [[1.46, 512.87]], "batb": NaN, "batl": [[0, 1.46, 653.3]]}, {"timestamp": 1632495227133, "ltp": 1.46, "tv": 3513.48, "trd": NaN, "batb": [[1, 1.43, 581.8]], "batl": NaN}, {"timestamp": 1632495230120, "ltp": 1.46, "tv": 3515.28, "trd": [[1.46, 514.67]], "batb": NaN, "batl": [[0, 1.46, 652.4]]}, {"timestamp": 1632495234312, "ltp": 1.46, "tv": 3522.31, "trd": [[1.46, 521.71]], "batb": NaN, "batl": [[0, 1.46, 648.88]]}, {"timestamp": 1632495238056, "ltp": 1.46, "tv": 3636.55, "trd": [[1.46, 635.95]], "batb": NaN, "batl": [[0, 1.46, 534.64]]}, {"timestamp": 1632495241154, "ltp": 1.46, "tv": 3636.55, "trd": NaN, "batb": [[0, 1.44, 1322.1]], "batl": NaN}, {"timestamp": 1632495241468, "ltp": 1.46, "tv": 3669.31, "trd": [[1.46, 668.71]], "batb": NaN, "batl": [[0, 1.46, 518.26]]}, {"timestamp": 1632495244870, "ltp": 1.46, "tv": 3702.59, "trd": [[1.46, 701.99]], "batb": NaN, "batl": [[0, 1.46, 501.62]]}, {"timestamp": 1632495247963, "ltp": 1.46, "tv": 3702.59, "trd": NaN, "batb": NaN, "batl": [[0, 1.46, 12.56]]}, {"timestamp": 1632495248969, "ltp": 1.46, "tv": 3707.29, "trd": [[1.46, 706.68]], "batb": NaN, "batl": [[0, 1.46, 10.21]]}, {"timestamp": 1632495251939, "ltp": 1.46, "tv": 3711.98, "trd": [[1.46, 711.38]], "batb": NaN, "batl": [[0, 1.46, 7.86]]}, {"timestamp": 1632495254176, "ltp": 1.46, "tv": 3716.68, "trd": [[1.46, 716.07]], "batb": NaN, "batl": [[0, 1.46, 5.51]]}, {"timestamp": 1632495255172, "ltp": 1.46, "tv": 3722.19, "trd": [[1.46, 721.58]], "batb": NaN, "batl": [[0, 1.48, 315.36], [1, 1.49, 190.45], [2, 1.5, 159.75]]}, {"timestamp": 1632495257168, "ltp": 1.46, "tv": 3722.19, "trd": NaN, "batb": [[0, 1.44, 938.37], [1, 1.43, 253.12], [2, 1.41, 51.54]], "batl": [[2, 1.52, 280.34]]}, {"timestamp": 1632495257694, "ltp": 1.46, "tv": 3722.19, "trd": NaN, "batb": [[0, 1.44, 10.48], [1, 1.43, 22.87], [2, 1.41, 9.65]], "batl": [[0, 1.52, 280.34], [1, 1.53, 270.54], [2, 1.68, 2]]}, {"timestamp": 1632495258310, "ltp": 1.46, "tv": 3722.19, "trd": NaN, "batb": [[1, 1.41, 9.65], [2, 1.39, 307.86]], "batl": [[0, 1.52, 220.34]]}, {"timestamp": 1632495260983, "ltp": 1.46, "tv": 3722.19, "trd": NaN, "batb": NaN, "batl": [[0, 1.51, 7], [1, 1.52, 374.1], [2, 1.53, 443.09]]}, {"timestamp": 1632495262653, "ltp": 1.46, "tv": 3722.19, "trd": NaN, "batb": [[2, 1.37, 366.04]], "batl": NaN}, {"timestamp": 1632495266075, "ltp": 1.46, "tv": 3722.19, "trd": NaN, "batb": [[0, 1.48, 989.24], [1, 1.47, 205.18], [2, 1.44, 10.48]], "batl": [[0, 1.52, 367.1], [1, 1.53, 443.09], [2, 1.54, 301.58]]}, {"timestamp": 1632495267179, "ltp": 1.46, "tv": 3722.19, "trd": NaN, "batb": [[0, 1.49, 260.57], [1, 1.48, 989.24], [2, 1.47, 227.05]], "batl": NaN}, {"timestamp": 1632495268181, "ltp": 1.46, "tv": 3722.19, "trd": NaN, "batb": [[2, 1.47, 234.05]], "batl": NaN}, {"timestamp": 1632495270081, "ltp": 1.46, "tv": 3722.19, "trd": NaN, "batb": NaN, "batl": [[0, 1.51, 233], [1, 1.52, 367.1], [2, 1.53, 443.09]]}, {"timestamp": 1632495270759, "ltp": 1.46, "tv": 3722.19, "trd": NaN, "batb": [[2, 1.47, 212.18]], "batl": NaN}, {"timestamp": 1632495273983, "ltp": 1.51, "tv": 3755.85, "trd": [[1.51, 255.54]], "batb": [[1, 1.48, 1010.89]], "batl": [[0, 1.51, 341.17], [2, 1.53, 468.59]]}, {"timestamp": 1632495276913, "ltp": 1.51, "tv": 3788.81, "trd": [[1.51, 288.5]], "batb": NaN, "batl": [[0, 1.51, 324.69]]}, {"timestamp": 1632495277975, "ltp": 1.49, "tv": 3789.43, "trd": [[1.49, 0.62]], "batb": [[0, 1.49, 260.26], [1, 1.48, 742.39]], "batl": NaN}, {"timestamp": 1632495279169, "ltp": 1.49, "tv": 3789.43, "trd": NaN, "batb": [[1, 1.48, 68.41], [2, 1.44, 57.9]], "batl": [[1, 1.53, 25.5], [2, 1.54, 23.25]]}, {"timestamp": 1632495280106, "ltp": 1.51, "tv": 3795.83, "trd": [[1.51, 294.9]], "batb": [[0, 1.48, 21.65], [1, 1.44, 57.9], [2, 1.43, 310.85]], "batl": [[0, 1.53, 25.5], [1, 1.54, 23.25], [2, 1.68, 2]]}, {"timestamp": 1632495280369, "ltp": 1.51, "tv": 3795.83, "trd": NaN, "batb": [[0, 1.44, 57.9], [1, 1.43, 310.85], [2, 1.42, 43.94]], "batl": [[0, 1.54, 23.25], [1, 1.68, 2], [2, 1.89, 445.56]]}, {"timestamp": 1632495282218, "ltp": 1.51, "tv": 3795.83, "trd": NaN, "batb": [[0, 1.44, 10.48], [2, 1.42, 330.99]], "batl": [[1, 1.57, 273.98], [2, 1.58, 152.12]]}, {"timestamp": 1632495283201, "ltp": 1.51, "tv": 3795.83, "trd": NaN, "batb": [[2, 1.42, 43.94]], "batl": [[1, 1.68, 2], [2, 1.89, 445.56]]}, {"timestamp": 1632495284016, "ltp": 1.51, "tv": 3795.83, "trd": NaN, "batb": NaN, "batl": [[0, 1.53, 22.5], [1, 1.54, 23.25], [2, 1.68, 2]]}, {"timestamp": 1632495285019, "ltp": 1.51, "tv": 3795.83, "trd": NaN, "batb": NaN, "batl": [[0, 1.54, 23.25], [1, 1.68, 2], [2, 990, 0.01]]}, {"timestamp": 1632495286220, "ltp": 1.51, "tv": 3849.64, "trd": [[1.51, 348.71]], "batb": [[0, 1.47, 237.31], [1, 1.46, 210.83], [2, 1.44, 54.9]], "batl": [[0, 1.5, 19.59], [1, 1.51, 158.52], [2, 1.52, 176.62]]}, {"timestamp": 1632495287206, "ltp": 1.51, "tv": 3849.64, "trd": NaN, "batb": [[2, 1.44, 61.9]], "batl": [[0, 1.51, 158.52], [1, 1.52, 176.62], [2, 1.54, 23.25]]}, {"timestamp": 1632495288101, "ltp": 1.51, "tv": 3849.64, "trd": NaN, "batb": NaN, "batl": [[2, 1.53, 57.01]]}, {"timestamp": 1632495290099, "ltp": 1.51, "tv": 3849.64, "trd": NaN, "batb": [[0, 1.47, 267.89], [1, 1.46, 369.82]], "batl": [[0, 1.51, 182.6]]}, {"timestamp": 1632495291221, "ltp": 1.51, "tv": 3867.68, "trd": [[1.51, 366.75]], "batb": [[0, 1.47, 320.29]], "batl": [[0, 1.51, 173.58]]}, {"timestamp": 1632495291994, "ltp": 1.51, "tv": 3867.68, "trd": NaN, "batb": NaN, "batl": [[0, 1.5, 149], [1, 1.51, 173.58], [2, 1.52, 176.62]]}, {"timestamp": 1632495293111, "ltp": 1.51, "tv": 3867.68, "trd": NaN, "batb": [[0, 1.46, 158.99], [1, 1.44, 61.9], [2, 1.43, 316.85]], "batl": [[0, 1.53, 21.5], [1, 1.54, 23.25], [2, 1.68, 2]]}, {"timestamp": 1632495293426, "ltp": 1.51, "tv": 3867.68, "trd": NaN, "batb": NaN, "batl": [[0, 1.54, 23.25], [1, 1.68, 2], [2, 990, 0.01]]}, {"timestamp": 1632495295199, "ltp": 1.51, "tv": 3867.68, "trd": NaN, "batb": NaN, "batl": [[0, 1.54, 23.56]]}, {"timestamp": 1632495295619, "ltp": 1.51, "tv": 3867.68, "trd": NaN, "batb": NaN, "batl": [[1, 1.57, 240.58], [2, 1.58, 152.1]]}, {"timestamp": 1632495299112, "ltp": 1.54, "tv": 3885.03, "trd": [[1.52, 4.86], [1.54, 273.04]], "batb": [[0, 1.53, 233.83], [1, 1.52, 550.59], [2, 1.51, 224.55]], "batl": [[0, 1.54, 6.52], [2, 1.58, 533.64]]}, {"timestamp": 1632495301132, "ltp": 1.54, "tv": 3893.65, "trd": [[1.54, 281.66]], "batb": [[2, 1.51, 226.9]], "batl": [[0, 1.57, 240.58], [1, 1.58, 533.64], [2, 1.59, 601.42]]}, {"timestamp": 1632495304118, "ltp": 1.54, "tv": 3893.65, "trd": NaN, "batb": [[0, 1.53, 234.07]], "batl": NaN}, {"timestamp": 1632495305009, "ltp": 1.54, "tv": 3893.65, "trd": NaN, "batb": NaN, "batl": [[0, 1.56, 154], [1, 1.57, 240.58], [2, 1.58, 533.64]]}, {"timestamp": 1632495306119, "ltp": 1.54, "tv": 3893.65, "trd": NaN, "batb": NaN, "batl": [[0, 1.56, 175.67], [1, 1.57, 262.08], [2, 1.58, 551.89]]}, {"timestamp": 1632495306913, "ltp": 1.54, "tv": 3893.65, "trd": NaN, "batb": [[1, 1.52, 633.79]], "batl": NaN}, {"timestamp": 1632495308011, "ltp": 1.54, "tv": 3893.65, "trd": NaN, "batb": NaN, "batl": [[0, 1.56, 325.67]]}, {"timestamp": 1632495309164, "ltp": 1.54, "tv": 3893.65, "trd": NaN, "batb": [[0, 1.55, 2.35], [1, 1.53, 234.07], [2, 1.52, 633.79]], "batl": NaN}, {"timestamp": 1632495311159, "ltp": 1.55, "tv": 3894.27, "trd": [[1.55, 0.62]], "batb": [[0, 1.55, 2.04], [1, 1.52, 83.43], [2, 1.51, 2.35]], "batl": [[0, 1.56, 304], [1, 1.57, 21.5], [2, 1.58, 18.25]]}, {"timestamp": 1632495312150, "ltp": 1.55, "tv": 3894.27, "trd": NaN, "batb": [[0, 1.56, 17.25], [1, 1.55, 2.04], [2, 1.52, 83.43]], "batl": [[0, 1.57, 21.5], [1, 1.58, 18.25], [2, 1.68, 2]]}, {"timestamp": 1632495312569, "ltp": 1.55, "tv": 3894.27, "trd": NaN, "batb": [[2, 1.51, 2.58]], "batl": NaN}, {"timestamp": 1632495314136, "ltp": 1.56, "tv": 3941.19, "trd": [[1.56, 46.92]], "batb": [[0, 1.56, 23.79]], "batl": NaN}, {"timestamp": 1632495316069, "ltp": 1.56, "tv": 3941.19, "trd": NaN, "batb": [[0, 1.56, 27.32]], "batl": [[1, 1.58, 692.21]]}, {"timestamp": 1632495316749, "ltp": 1.54, "tv": 4000.37, "trd": [[1.54, 282.12], [1.55, 4.7], [1.56, 101.56]], "batb": [[0, 1.51, 297.16], [1, 1.5, 190.91], [2, 1.48, 268.5]], "batl": [[0, 1.56, 221.81], [1, 1.57, 177.19], [2, 1.58, 18.25]]}, {"timestamp": 1632495318033, "ltp": 1.54, "tv": 4000.37, "trd": NaN, "batb": NaN, "batl": [[0, 1.56, 221.9]]}, {"timestamp": 1632495319078, "ltp": 1.56, "tv": 4018.42, "trd": [[1.54, 282.31], [1.56, 119.42]], "batb": NaN, "batl": [[0, 1.56, 212.88]]}, {"timestamp": 1632495320174, "ltp": 1.56, "tv": 4018.42, "trd": NaN, "batb": [[0, 1.51, 2.35], [1, 1.5, 2.35]], "batl": [[0, 1.57, 21.5], [1, 1.58, 18.25], [2, 1.68, 2]]}, {"timestamp": 1632495321158, "ltp": 1.57, "tv": 4018.88, "trd": [[1.57, 493.34]], "batb": NaN, "batl": [[0, 1.57, 21.27]]}, {"timestamp": 1632495322783, "ltp": 1.57, "tv": 4018.88, "trd": NaN, "batb": [[2, 1.48, 444.04]], "batl": [[0, 1.57, 21.58], [2, 1.6, 193.47]]}, {"timestamp": 1632495323673, "ltp": 1.57, "tv": 4018.88, "trd": NaN, "batb": NaN, "batl": [[0, 1.54, 3.27], [1, 1.57, 21.58], [2, 1.58, 18.25]]}, {"timestamp": 1632495325094, "ltp": 1.57, "tv": 4018.88, "trd": NaN, "batb": [[2, 1.48, 268.5]], "batl": NaN}, {"timestamp": 1632495328181, "ltp": 1.57, "tv": 4042.04, "trd": [[1.54, 288.85], [1.57, 509.95]], "batb": [[0, 1.55, 2533.35], [1, 1.54, 213.04], [2, 1.52, 67.99]], "batl": [[0, 1.57, 4.97], [1, 1.58, 29.63], [2, 1.6, 505.17]]}, {"timestamp": 1632495329178, "ltp": 1.57, "tv": 4042.04, "trd": NaN, "batb": [[0, 1.56, 216.88], [1, 1.55, 457.9], [2, 1.54, 209.81]], "batl": NaN}, {"timestamp": 1632495330066, "ltp": 1.57, "tv": 4042.04, "trd": NaN, "batb": [[2, 1.54, 213.81]], "batl": NaN}, {"timestamp": 1632495331981, "ltp": 1.56, "tv": 4357.32, "trd": [[1.56, 434.7]], "batb": [[0, 1.56, 59.24]], "batl": NaN}, {"timestamp": 1632495333176, "ltp": 1.57, "tv": 4360.74, "trd": [[1.57, 513.37]], "batb": NaN, "batl": [[0, 1.57, 3.26]]}, {"timestamp": 1632495334073, "ltp": 1.57, "tv": 4360.74, "trd": NaN, "batb": NaN, "batl": [[0, 1.57, 233.26]]}, {"timestamp": 1632495334966, "ltp": 1.57, "tv": 4360.74, "trd": NaN, "batb": [[2, 1.54, 493.18]], "batl": NaN}, {"timestamp": 1632495337111, "ltp": 1.57, "tv": 4364.74, "trd": [[1.57, 517.37]], "batb": [[1, 1.55, 538.8]], "batl": [[0, 1.57, 449.26]]}, {"timestamp": 1632495339877, "ltp": 1.57, "tv": 4364.74, "trd": NaN, "batb": [[1, 1.55, 359.6]], "batl": NaN}, {"timestamp": 1632495342182, "ltp": 1.57, "tv": 4364.74, "trd": NaN, "batb": [[1, 1.54, 279.37], [2, 1.53, 299.45]], "batl": [[1, 1.58, 18.25], [2, 1.62, 286.65]]}, {"timestamp": 1632495343175, "ltp": 1.57, "tv": 4364.74, "trd": NaN, "batb": [[0, 1.54, 279.37], [1, 1.53, 299.45], [2, 1.52, 244.98]], "batl": [[0, 1.57, 1.26]]}, {"timestamp": 1632495344220, "ltp": 1.57, "tv": 4364.84, "trd": [[1.57, 517.47]], "batb": NaN, "batl": [[0, 1.58, 18.46], [1, 1.62, 286.65], [2, 1.63, 280.8]]}, {"timestamp": 1632495345217, "ltp": 1.57, "tv": 4364.84, "trd": NaN, "batb": [[2, 1.52, 497.74]], "batl": [[1, 1.62, 467.82], [2, 1.63, 416.8]]}, {"timestamp": 1632495346009, "ltp": 1.57, "tv": 4364.84, "trd": NaN, "batb": [[2, 1.52, 6]], "batl": [[1, 1.62, 286.65], [2, 1.63, 280.8]]}, {"timestamp": 1632495348210, "ltp": 1.57, "tv": 4364.84, "trd": NaN, "batb": NaN, "batl": [[1, 1.61, 656.59], [2, 1.62, 286.65]]}, {"timestamp": 1632495348996, "ltp": 1.57, "tv": 4364.84, "trd": NaN, "batb": [[0, 1.55, 172.17], [1, 1.54, 448.4], [2, 1.53, 299.45]], "batl": [[1, 1.59, 149.72], [2, 1.6, 145.51]]}, {"timestamp": 1632495350193, "ltp": 1.57, "tv": 4364.84, "trd": NaN, "batb": [[0, 1.55, 206.87]], "batl": [[0, 1.57, 24.71], [1, 1.58, 18.25], [2, 1.59, 149.72]]}, {"timestamp": 1632495350298, "ltp": 1.57, "tv": 4364.84, "trd": NaN, "batb": NaN, "batl": [[0, 1.58, 18.46], [1, 1.59, 149.72], [2, 1.6, 145.51]]}, {"timestamp": 1632495351912, "ltp": 1.57, "tv": 4364.84, "trd": NaN, "batb": NaN, "batl": [[0, 1.57, 166.21], [1, 1.58, 18.25], [2, 1.59, 149.72]]}, {"timestamp": 1632495353539, "ltp": 1.57, "tv": 4364.84, "trd": NaN, "batb": NaN, "batl": [[0, 1.57, 186.71]]}, {"timestamp": 1632495355139, "ltp": 1.57, "tv": 4364.84, "trd": NaN, "batb": [[0, 1.55, 2.35], [1, 1.54, 279.37]], "batl": [[0, 1.57, 109.71], [2, 1.62, 286.65]]}, {"timestamp": 1632495355348, "ltp": 1.57, "tv": 4364.84, "trd": NaN, "batb": NaN, "batl": [[0, 1.58, 18.46], [1, 1.62, 286.65], [2, 1.63, 280.8]]}, {"timestamp": 1632495358028, "ltp": 1.57, "tv": 4365.05, "trd": [[1.57, 517.68]], "batb": [[1, 1.52, 6], [2, 1.51, 314.02]], "batl": [[0, 1.58, 18.25], [1, 1.62, 467.82], [2, 1.63, 416.8]]}, {"timestamp": 1632495360137, "ltp": 1.6, "tv": 4385.03, "trd": [[1.58, 34.6], [1.6, 55.13]], "batb": [[0, 1.57, 2746.44], [1, 1.55, 2.35], [2, 1.52, 6]], "batl": [[0, 1.6, 13.24], [1, 1.62, 839.4]]}, {"timestamp": 1632495361133, "ltp": 1.6, "tv": 4385.03, "trd": NaN, "batb": [[0, 1.57, 477.01], [1, 1.56, 200.92], [2, 1.55, 2.35]], "batl": NaN}, {"timestamp": 1632495362039, "ltp": 1.6, "tv": 4385.03, "trd": NaN, "batb": [[0, 1.58, 208.27], [1, 1.57, 482.01], [2, 1.56, 217.67]], "batl": NaN}, {"timestamp": 1632495362622, "ltp": 1.58, "tv": 4404.33, "trd": [[1.58, 53.91]], "batb": [[0, 1.58, 198.62]], "batl": NaN}, {"timestamp": 1632495367061, "ltp": 1.58, "tv": 4404.33, "trd": NaN, "batb": NaN, "batl": [[0, 1.6, 176.24]]}, {"timestamp": 1632495368942, "ltp": 1.6, "tv": 4420.96, "trd": [[1.6, 71.76]], "batb": NaN, "batl": [[0, 1.6, 159.61]]}, {"timestamp": 1632495371076, "ltp": 1.6, "tv": 4420.96, "trd": NaN, "batb": NaN, "batl": [[0, 1.6, 254.61]]}, {"timestamp": 1632495372170, "ltp": 1.6, "tv": 4468.8, "trd": [[1.6, 119.6]], "batb": [[1, 1.57, 264.04]], "batl": [[0, 1.6, 230.69]]}, {"timestamp": 1632495372480, "ltp": 1.6, "tv": 4468.8, "trd": NaN, "batb": NaN, "batl": [[0, 1.6, 231]]}, {"timestamp": 1632495373684, "ltp": 1.6, "tv": 4468.8, "trd": NaN, "batb": [[2, 1.56, 212.67]], "batl": [[1, 1.62, 855.94]]}, {"timestamp": 1632495375145, "ltp": 1.58, "tv": 4486.17, "trd": [[1.58, 71.27]], "batb": [[0, 1.58, 189.94]], "batl": [[0, 1.6, 350.31]]}, {"timestamp": 1632495376870, "ltp": 1.6, "tv": 4502.3, "trd": [[1.59, 0.62], [1.6, 135.11]], "batb": NaN, "batl": [[0, 1.6, 338.69]]}, {"timestamp": 1632495378967, "ltp": 1.58, "tv": 4502.77, "trd": [[1.58, 71.74]], "batb": [[0, 1.58, 189.7]], "batl": [[1, 1.62, 839.4]]}, {"timestamp": 1632495382092, "ltp": 1.58, "tv": 4502.77, "trd": NaN, "batb": NaN, "batl": [[0, 1.59, 13.16], [1, 1.6, 338.69], [2, 1.62, 855.94]]}, {"timestamp": 1632495385583, "ltp": 1.6, "tv": 4563.66, "trd": [[1.59, 13.78], [1.6, 182.84]], "batb": NaN, "batl": [[0, 1.6, 290.96], [1, 1.62, 855.94], [2, 1.63, 416.8]]}, {"timestamp": 1632495392496, "ltp": 1.6, "tv": 4563.66, "trd": NaN, "batb": [[0, 1.59, 2.35], [1, 1.58, 189.7], [2, 1.57, 264.04]], "batl": NaN}, {"timestamp": 1632495396598, "ltp": 1.6, "tv": 4563.66, "trd": NaN, "batb": [[0, 1.58, 189.7], [1, 1.57, 264.04], [2, 1.56, 212.67]], "batl": NaN}, {"timestamp": 1632495397520, "ltp": 1.6, "tv": 4563.66, "trd": NaN, "batb": [[1, 1.57, 5], [2, 1.56, 11.75]], "batl": [[1, 1.62, 674.77], [2, 1.63, 280.8]]}, {"timestamp": 1632495405536, "ltp": 1.6, "tv": 4565.06, "trd": [[1.6, 184.24]], "batb": NaN, "batl": [[0, 1.6, 290.26]]}, {"timestamp": 1632495406628, "ltp": 1.6, "tv": 4569.76, "trd": [[1.6, 188.94]], "batb": NaN, "batl": [[0, 1.6, 287.91]]}, {"timestamp": 1632495408939, "ltp": 1.6, "tv": 4569.76, "trd": NaN, "batb": [[0, 1.55, 2.35], [1, 1.54, 298.78], [2, 1.53, 528.25]], "batl": [[1, 1.65, 60], [2, 1.68, 2]]}, {"timestamp": 1632495410139, "ltp": 1.6, "tv": 4569.76, "trd": NaN, "batb": NaN, "batl": [[0, 1.65, 60], [1, 1.68, 2], [2, 1.71, 226.36]]}, {"timestamp": 1632495411131, "ltp": 1.6, "tv": 4569.76, "trd": NaN, "batb": [[1, 1.54, 217.14]], "batl": [[0, 1.68, 2], [1, 1.71, 226.36], [2, 1.72, 217.72]]}, {"timestamp": 1632495411926, "ltp": 1.6, "tv": 4569.76, "trd": NaN, "batb": NaN, "batl": [[1, 1.71, 243.86]]}, {"timestamp": 1632495414029, "ltp": 1.6, "tv": 4569.76, "trd": NaN, "batb": [[0, 1.59, 222.66], [1, 1.58, 153.37], [2, 1.55, 2.35]], "batl": [[0, 1.64, 186.98], [1, 1.65, 130.17], [2, 1.68, 2]]}, {"timestamp": 1632495415124, "ltp": 1.6, "tv": 4569.76, "trd": NaN, "batb": NaN, "batl": [[2, 1.68, 20.14]]}, {"timestamp": 1632495415751, "ltp": 1.6, "tv": 4569.76, "trd": NaN, "batb": NaN, "batl": [[2, 1.67, 10]]}, {"timestamp": 1632495419148, "ltp": 1.6, "tv": 4569.76, "trd": NaN, "batb": [[0, 1.59, 40.33], [1, 1.54, 217.14], [2, 1.53, 528.25]], "batl": [[0, 1.68, 2], [1, 1.71, 243.86], [2, 1.72, 217.72]]}, {"timestamp": 1632495419248, "ltp": 1.6, "tv": 4569.76, "trd": NaN, "batb": [[0, 1.54, 217.14], [1, 1.53, 528.25], [2, 1.52, 85.49]], "batl": NaN}, {"timestamp": 1632495422155, "ltp": 1.6, "tv": 4569.76, "trd": NaN, "batb": [[2, 1.52, 369.8]], "batl": [[1, 1.71, 17.5], [2, 990, 0.01]]}, {"timestamp": 1632495425158, "ltp": 1.6, "tv": 4569.76, "trd": NaN, "batb": [[0, 1.54, 12.1], [1, 1.53, 234.42]], "batl": [[0, 1.57, 239.78], [1, 1.58, 629.37], [2, 1.67, 37.13]]}, {"timestamp": 1632495426173, "ltp": 1.6, "tv": 4569.76, "trd": NaN, "batb": NaN, "batl": [[2, 1.59, 60]]}, {"timestamp": 1632495429059, "ltp": 1.6, "tv": 4569.76, "trd": NaN, "batb": NaN, "batl": [[0, 1.56, 226], [1, 1.57, 239.78], [2, 1.58, 629.37]]}, {"timestamp": 1632495436080, "ltp": 1.6, "tv": 4569.76, "trd": NaN, "batb": [[0, 1.53, 234.42], [1, 1.52, 369.8], [2, 1.51, 224.4]], "batl": NaN}, {"timestamp": 1632495438174, "ltp": 1.6, "tv": 4569.76, "trd": NaN, "batb": NaN, "batl": [[0, 1.55, 1.71], [1, 1.56, 226], [2, 1.57, 239.78]]}, {"timestamp": 1632495439167, "ltp": 1.6, "tv": 4569.76, "trd": NaN, "batb": [[0, 1.49, 432.23], [1, 1.48, 87.26], [2, 1.46, 158.99]], "batl": [[1, 1.59, 60], [2, 1.6, 18.11]]}, {"timestamp": 1632495440269, "ltp": 1.6, "tv": 4569.76, "trd": NaN, "batb": [[0, 1.49, 346.52]], "batl": [[1, 1.6, 18.11], [2, 1.61, 20.5]]}, {"timestamp": 1632495442106, "ltp": 1.6, "tv": 4569.76, "trd": NaN, "batb": [[0, 1.5, 84.88], [1, 1.49, 495.44], [2, 1.48, 291.34]], "batl": NaN}, {"timestamp": 1632495442281, "ltp": 1.6, "tv": 4569.76, "trd": NaN, "batb": [[0, 1.49, 495.44], [1, 1.48, 291.34], [2, 1.46, 158.99]], "batl": NaN}, {"timestamp": 1632495444305, "ltp": 1.6, "tv": 4569.76, "trd": NaN, "batb": [[0, 1.49, 351.52], [1, 1.48, 93.26]], "batl": NaN}, {"timestamp": 1632495447209, "ltp": 1.61, "tv": 4629.9, "trd": [[1.55, 8.12], [1.6, 225.16], [1.61, 20.5]], "batb": [[0, 1.6, 2284.28], [1, 1.59, 149.46], [2, 1.57, 92.57]], "batl": [[0, 1.62, 19.25], [1, 1.63, 18.5], [2, 1.65, 244.87]]}, {"timestamp": 1632495448212, "ltp": 1.61, "tv": 4629.9, "trd": NaN, "batb": [[0, 1.6, 516.04], [2, 1.57, 132.06]], "batl": [[1, 1.65, 244.87], [2, 1.66, 613.56]]}, {"timestamp": 1632495452193, "ltp": 1.6, "tv": 5030.74, "trd": [[1.6, 626]], "batb": [[0, 1.6, 315.62]], "batl": [[2, 1.66, 779.19]]}, {"timestamp": 1632495452986, "ltp": 1.6, "tv": 5030.74, "trd": NaN, "batb": [[0, 1.6, 349.63]], "batl": [[2, 1.66, 613.56]]}, {"timestamp": 1632495454185, "ltp": 1.6, "tv": 5030.74, "trd": NaN, "batb": NaN, "batl": [[0, 1.62, 149.25]]}, {"timestamp": 1632495457207, "ltp": 1.6, "tv": 5030.74, "trd": NaN, "batb": NaN, "batl": [[0, 1.62, 239.25], [2, 1.66, 595.73]]}, {"timestamp": 1632495460214, "ltp": 1.6, "tv": 5030.74, "trd": NaN, "batb": NaN, "batl": [[1, 1.64, 11.91], [2, 1.65, 244.87]]}, {"timestamp": 1632495461004, "ltp": 1.6, "tv": 5030.82, "trd": [[1.6, 626.08]], "batb": [[0, 1.6, 195.54], [1, 1.57, 39.49], [2, 1.56, 80.17]], "batl": [[0, 1.62, 220], [1, 1.75, 35.43], [2, 1.76, 200.9]]}, {"timestamp": 1632495462005, "ltp": 1.6, "tv": 5030.82, "trd": NaN, "batb": [[0, 1.56, 80.17], [1, 1.55, 211.97], [2, 1.54, 676.51]], "batl": [[0, 1.76, 200.9], [1, 1.77, 260.04], [2, 1.95, 419.78]]}, {"timestamp": 1632495463116, "ltp": 1.6, "tv": 5030.82, "trd": NaN, "batb": [[0, 1.55, 211.97], [1, 1.54, 676.51], [2, 1.51, 111.99]], "batl": [[0, 1.62, 126], [1, 1.76, 200.9], [2, 1.77, 260.04]]}, {"timestamp": 1632495464216, "ltp": 1.6, "tv": 5030.82, "trd": NaN, "batb": [[2, 1.53, 287.35]], "batl": [[0, 1.76, 200.9], [1, 1.77, 432.52], [2, 1.79, 198.93]]}, {"timestamp": 1632495465210, "ltp": 1.6, "tv": 5030.82, "trd": NaN, "batb": NaN, "batl": [[0, 1.68, 60.2], [1, 1.76, 200.9], [2, 1.77, 432.52]]}, {"timestamp": 1632495465521, "ltp": 1.6, "tv": 5030.82, "trd": NaN, "batb": NaN, "batl": [[0, 1.76, 205.09], [1, 1.77, 432.52], [2, 1.79, 198.93]]}, {"timestamp": 1632495466723, "ltp": 1.6, "tv": 5030.82, "trd": NaN, "batb": NaN, "batl": [[0, 1.71, 4], [1, 1.76, 204.9], [2, 1.77, 432.52]]}, {"timestamp": 1632495470640, "ltp": 1.6, "tv": 5030.82, "trd": NaN, "batb": [[2, 1.51, 111.99]], "batl": [[2, 1.77, 260.04]]}, {"timestamp": 1632495473937, "ltp": 1.6, "tv": 5030.82, "trd": NaN, "batb": [[0, 1.62, 161.76], [1, 1.61, 142.77], [2, 1.55, 211.97]], "batl": [[0, 1.64, 20.68], [1, 1.67, 206.19], [2, 1.69, 240.9]]}, {"timestamp": 1632495474922, "ltp": 1.6, "tv": 5030.82, "trd": NaN, "batb": NaN, "batl": [[0, 1.67, 206.19], [1, 1.69, 240.9], [2, 1.76, 204.9]]}, {"timestamp": 1632495475914, "ltp": 1.6, "tv": 5030.82, "trd": NaN, "batb": [[0, 1.55, 211.97], [1, 1.54, 676.51], [2, 1.51, 111.99]], "batl": [[0, 1.76, 204.9], [1, 1.77, 260.04], [2, 1.95, 419.78]]}, {"timestamp": 1632495476949, "ltp": 1.6, "tv": 5030.82, "trd": NaN, "batb": NaN, "batl": [[0, 1.72, 5], [1, 1.76, 204.9], [2, 1.77, 260.04]]}, {"timestamp": 1632495478619, "ltp": 1.6, "tv": 5030.82, "trd": NaN, "batb": [[2, 1.53, 287.32]], "batl": [[1, 1.73, 5], [2, 1.76, 204.9]]}, {"timestamp": 1632495489150, "ltp": 1.6, "tv": 5030.82, "trd": NaN, "batb": [[0, 1.54, 346.1], [1, 1.51, 111.99], [2, 1.5, 104.82]], "batl": NaN}, {"timestamp": 1632495489359, "ltp": 1.6, "tv": 5030.82, "trd": NaN, "batb": NaN, "batl": [[0, 1.73, 5], [1, 1.76, 200.9], [2, 1.77, 432.54]]}, {"timestamp": 1632495492146, "ltp": 1.6, "tv": 5030.82, "trd": NaN, "batb": [[0, 1.71, 3140.67], [1, 1.69, 348.76], [2, 1.67, 37.13]], "batl": [[0, 1.76, 200.9], [1, 1.77, 432.54], [2, 1.78, 327.57]]}, {"timestamp": 1632495493184, "ltp": 1.73, "tv": 5035.64, "trd": [[1.73, 4.82]], "batb": [[0, 1.72, 154.29], [1, 1.71, 438.09], [2, 1.69, 348.76]], "batl": NaN}, {"timestamp": 1632495497153, "ltp": 1.73, "tv": 5035.64, "trd": NaN, "batb": [[0, 1.72, 183.32]], "batl": NaN}, {"timestamp": 1632495500059, "ltp": 1.73, "tv": 5035.64, "trd": NaN, "batb": NaN, "batl": [[0, 1.75, 806], [1, 1.76, 200.9], [2, 1.77, 432.54]]}, {"timestamp": 1632495501158, "ltp": 1.72, "tv": 5036.1, "trd": [[1.72, 0.47]], "batb": [[0, 1.72, 183.08]], "batl": NaN}, {"timestamp": 1632495503084, "ltp": 1.72, "tv": 5036.16, "trd": [[1.72, 0.52]], "batb": [[0, 1.72, 183.05]], "batl": NaN}, {"timestamp": 1632495504080, "ltp": 1.72, "tv": 5036.16, "trd": NaN, "batb": [[1, 1.71, 205.11]], "batl": NaN}, {"timestamp": 1632495505075, "ltp": 1.72, "tv": 5037.1, "trd": [[1.72, 1.46]], "batb": [[0, 1.72, 192.65]], "batl": NaN}, {"timestamp": 1632495505391, "ltp": 1.72, "tv": 5037.1, "trd": NaN, "batb": [[0, 1.72, 182.59]], "batl": NaN}, {"timestamp": 1632495508205, "ltp": 1.72, "tv": 5037.1, "trd": NaN, "batb": [[0, 1.72, 192.65]], "batl": NaN}, {"timestamp": 1632495513922, "ltp": 1.72, "tv": 5037.1, "trd": NaN, "batb": [[0, 1.72, 153.56], [1, 1.63, 184.74], [2, 1.61, 110.09]], "batl": [[1, 1.8, 60.17], [2, 2.22, 337.02]]}, {"timestamp": 1632495514239, "ltp": 1.72, "tv": 5037.1, "trd": NaN, "batb": [[0, 1.63, 184.74], [1, 1.61, 110.09], [2, 1.57, 100.57]], "batl": [[0, 1.8, 60.17], [1, 2.22, 337.02], [2, 990, 0.01]]}, {"timestamp": 1632495516009, "ltp": 1.72, "tv": 5037.1, "trd": NaN, "batb": NaN, "batl": [[0, 2.22, 337.41], [1, 990, 0.01], [2, 990, 0]]}, {"timestamp": 1632495517210, "ltp": 1.72, "tv": 5037.1, "trd": NaN, "batb": [[1, 1.62, 176.27], [2, 1.61, 252.9]], "batl": [[0, 1.72, 18.26], [1, 1.96, 118.16], [2, 1.98, 145.18]]}, {"timestamp": 1632495518895, "ltp": 1.72, "tv": 5037.1, "trd": NaN, "batb": NaN, "batl": [[0, 1.72, 18.13], [2, 1.97, 4]]}, {"timestamp": 1632495519727, "ltp": 1.72, "tv": 5055.23, "trd": [[1.72, 19.6]], "batb": [[1, 1.61, 110.09], [2, 1.57, 100.57]], "batl": [[0, 1.96, 118.16], [1, 1.97, 4], [2, 1.98, 145.18]]}, {"timestamp": 1632495522224, "ltp": 1.8, "tv": 5055.57, "trd": [[1.8, 0.34]], "batb": [[0, 1.92, 8.74], [1, 1.87, 2045.46], [2, 1.86, 1985.13]], "batl": [[0, 1.96, 127.43]]}, {"timestamp": 1632495523216, "ltp": 1.8, "tv": 5055.57, "trd": NaN, "batb": [[1, 1.9, 111.52], [2, 1.89, 183.6]], "batl": [[1, 1.98, 145.18], [2, 2, 478.12]]}, {"timestamp": 1632495524554, "ltp": 1.8, "tv": 5055.57, "trd": NaN, "batb": NaN, "batl": [[1, 1.98, 205.18]]}, {"timestamp": 1632495527104, "ltp": 1.94, "tv": 5056.35, "trd": [[1.94, 7.53]]