{"info": {"id": "1.167206550", "eventId": "29646660", "eventName": "2m4f Hcap Chs", "marketType": "WIN", "openDate": 1578749437968, "name": "Kemp  11th Jan", "numberOfActiveRunner": 9, "countryCode": "", "sport": "HORSE RACING", "venue": "", "volume": {"total": 752005.21, "preMatch": 506541.78, "inPlay": 245463.43}, "winner": {"id": 16016341, "name": "Erick Le Rouge", "status": "WINNER", "position": 3}, "delay": 1}, "runners": [{"id": 11042216, "name": "First Drift", "status": "REMOVED", "position": 1, "inPlayOdds": 0, "openOdds": 0, "closedOdds": 0, "maxPrematch": 0, "minPrematch": 0, "maxInPlay": 0, "minInPlay": 0, "tradedVolume": 0, "preMatchVolume": 0, "inPlayVolume": 0}, {"id": 22492304, "name": "Sammy Bill", "status": "LOSER", "position": 2, "inPlayOdds": 3.5, "inPlayTime": 1578749437968, "avgPrematch": 3.38, "closedOdds": 1000.0, "maxPrematch": 4.3, "minPrematch": 2.4, "maxInPlay": 1000.0, "minInPlay": 3.05, "inPlayIndex": 4908, "lengthOdds": 5221, "lengthOddsPrematch": 4908, "lengthOddsInPlay": 313, "tradedVolume": 281076.89, "preMatchVolume": 236897.18, "inPlayVolume": 44179.71}, {"id": 16016341, "name": "Erick Le Rouge", "status": "WINNER", "position": 3, "inPlayOdds": 5.0, "inPlayTime": 1578749437968, "avgPrematch": 6.84, "closedOdds": 1.01, "maxPrematch": 13.5, "minPrematch": 4.8, "maxInPlay": 10.5, "minInPlay": 1.01, "inPlayIndex": 3488, "lengthOdds": 3800, "lengthOddsPrematch": 3488, "lengthOddsInPlay": 312, "tradedVolume": 171753.46, "preMatchVolume": 66775.87, "inPlayVolume": 104977.59}, {"id": 12978716, "name": "Sao", "status": "LOSER", "position": 4, "inPlayOdds": 6.8, "inPlayTime": 1578749437968, "avgPrematch": 5.5, "closedOdds": 1000.0, "maxPrematch": 6.8, "minPrematch": 4.4, "maxInPlay": 1000.0, "minInPlay": 4.0, "inPlayIndex": 3236, "lengthOdds": 3548, "lengthOddsPrematch": 3236, "lengthOddsInPlay": 312, "tradedVolume": 85865.16, "preMatchVolume": 69106.8, "inPlayVolume": 16758.36}, {"id": 12129149, "name": "Mercian Prince", "status": "LOSER", "position": 5, "inPlayOdds": 7.4, "inPlayTime": 1578749437968, "avgPrematch": 8.35, "closedOdds": 1000.0, "maxPrematch": 10.5, "minPrematch": 6.4, "maxInPlay": 1000.0, "minInPlay": 2.4, "inPlayIndex": 3499, "lengthOdds": 3810, "lengthOddsPrematch": 3499, "lengthOddsInPlay": 311, "tradedVolume": 102574.14, "preMatchVolume": 52251.9, "inPlayVolume": 50322.24}, {"id": 15914188, "name": "Gowiththeflow", "status": "LOSER", "position": 6, "inPlayOdds": 12.5, "inPlayTime": 1578749437968, "avgPrematch": 11.22, "closedOdds": 1000.0, "maxPrematch": 28.0, "minPrematch": 8.0, "maxInPlay": 1000.0, "minInPlay": 2.24, "inPlayIndex": 3659, "lengthOdds": 3968, "lengthOddsPrematch": 3659, "lengthOddsInPlay": 309, "tradedVolume": 57546.47, "preMatchVolume": 39467.59, "inPlayVolume": 18078.88}, {"id": 10547981, "name": "Mr Medic", "status": "LOSER", "position": 7, "inPlayOdds": 13.0, "inPlayTime": 1578749437968, "avgPrematch": 12.57, "closedOdds": 1000.0, "maxPrematch": 22.0, "minPrematch": 9.2, "maxInPlay": 1000.0, "minInPlay": 7.0, "inPlayIndex": 2855, "lengthOdds": 3158, "lengthOddsPrematch": 2855, "lengthOddsInPlay": 303, "tradedVolume": 26206.27, "preMatchVolume": 20464.72, "inPlayVolume": 5741.55}, {"id": 12905688, "name": "Cap St Vincent", "status": "LOSER", "position": 8, "inPlayOdds": 15.0, "inPlayTime": 1578749437968, "avgPrematch": 20.88, "closedOdds": 1000.0, "maxPrematch": 30.0, "minPrematch": 11.0, "maxInPlay": 1000.0, "minInPlay": 10.0, "inPlayIndex": 2719, "lengthOdds": 3020, "lengthOddsPrematch": 2719, "lengthOddsInPlay": 301, "tradedVolume": 21466.19, "preMatchVolume": 17462.99, "inPlayVolume": 4003.2}, {"id": 12059871, "name": "One For Billy", "status": "LOSER", "position": 9, "inPlayOdds": 140.0, "inPlayTime": 1578749437968, "avgPrematch": 45.48, "closedOdds": 1000.0, "maxPrematch": 150.0, "minPrematch": 21.0, "maxInPlay": 1000.0, "minInPlay": 40.0, "inPlayIndex": 2704, "lengthOdds": 3000, "lengthOddsPrematch": 2704, "lengthOddsInPlay": 296, "tradedVolume": 5516.63, "preMatchVolume": 4114.73, "inPlayVolume": 1401.9}], "marketUpdates": [{"timestamp": 1578655072846000000, "openDate": "2020-01-11T12:20:00.000Z", "status": "OPEN", "betDelay": 0, "inPlay": false, "complete": true}, {"timestamp": 1578731658956000000, "openDate": "2020-01-11T12:20:00.000Z", "status": "SUSPENDED", "betDelay": 0, "inPlay": false, "complete": true}, {"timestamp": 1578731660965000000, "openDate": "2020-01-11T12:20:00.000Z", "status": "OPEN", "betDelay": 0, "inPlay": false, "complete": true}, {"timestamp": 1578740722963000000, "openDate": "2020-01-11T12:20:00.000Z", "status": "SUSPENDED", "betDelay": 0, "inPlay": false, "complete": true}, {"timestamp": 1578740723934000000, "openDate": "2020-01-11T12:20:00.000Z", "status": "OPEN", "betDelay": 0, "inPlay": false, "complete": true}, {"timestamp": 1578747785933000000, "openDate": "2020-01-11T12:20:00.000Z", "status": "SUSPENDED", "betDelay": 0, "inPlay": false, "complete": true}, {"timestamp": 1578747786804000000, "openDate": "2020-01-11T12:20:00.000Z", "status": "OPEN", "betDelay": 0, "inPlay": false, "complete": true}, {"timestamp": 1578749436981000000, "openDate": "2020-01-11T12:20:00.000Z", "status": "SUSPENDED", "betDelay": 0, "inPlay": false, "complete": true}, {"timestamp": 1578749437968000000, "openDate": "2020-01-11T12:20:00.000Z", "status": "OPEN", "betDelay": 1, "inPlay": true, "complete": true}, {"timestamp": 1578749748502000000, "openDate": "2020-01-11T12:20:00.000Z", "status": "SUSPENDED", "betDelay": 1, "inPlay": true, "complete": true}, {"timestamp": 1578749891004000000, "openDate": "2020-01-11T12:20:00.000Z", "status": "CLOSED", "betDelay": 1, "inPlay": true, "complete": true}], "odds": [{"runnerId": 11042216, "odds": [{"timestamp": 1578672947744, "ltp": 25.0, "tv": 19.99, "trd": [[25, 12.28], [26, 5.1], [27, 2.62]], "batb": [[0, 1.14, 77.66], [1, 1.04, 2], [2, 1.03, 1833.07]], "batl": NaN}, {"timestamp": 1578672999471, "ltp": 25.0, "tv": 19.99, "trd": NaN, "batb": [[0, 1.14, 80.66]], "batl": NaN}, {"timestamp": 1578673023293, "ltp": 25.0, "tv": 19.99, "trd": NaN, "batb": [[0, 1.15, 3.21], [1, 1.14, 80], [2, 1.04, 2]], "batl": NaN}, {"timestamp": 1578673026971, "ltp": 25.0, "tv": 19.99, "trd": NaN, "batb": [[0, 1.16, 32.99], [1, 1.15, 2.55], [2, 1.14, 80]], "batl": NaN}, {"timestamp": 1578673045916, "ltp": 25.0, "tv": 19.99, "trd": NaN, "batb": [[0, 1.16, 35.99], [2, 1.14, 77]], "batl": NaN}, {"timestamp": 1578673052824, "ltp": 25.0, "tv": 19.99, "trd": NaN, "batb": [[0, 11, 21.66], [1, 1.16, 35.33], [2, 1.15, 2.55]], "batl": NaN}, {"timestamp": 1578673067927, "ltp": 25.0, "tv": 19.99, "trd": NaN, "batb": [[0, 11.5, 2.4], [1, 11, 21], [2, 1.16, 32.33]], "batl": NaN}, {"timestamp": 1578673072949, "ltp": 25.0, "tv": 19.99, "trd": NaN, "batb": [[2, 1.15, 2.55]], "batl": NaN}, {"timestamp": 1578673073261, "ltp": 25.0, "tv": 19.99, "trd": NaN, "batb": [[0, 12, 3.79], [1, 11.5, 1.74], [2, 11, 21]], "batl": NaN}, {"timestamp": 1578673083867, "ltp": 25.0, "tv": 19.99, "trd": NaN, "batb": [[1, 11.5, 4.29]], "batl": NaN}, {"timestamp": 1578673090494, "ltp": 25.0, "tv": 19.99, "trd": NaN, "batb": [[1, 11.5, 2.55]], "batl": NaN}, {"timestamp": 1578673125443, "ltp": 25.0, "tv": 19.99, "trd": NaN, "batb": [[0, 12, 24.79], [2, 1.15, 2.55]], "batl": NaN}, {"timestamp": 1578673383474, "ltp": 25.0, "tv": 19.99, "trd": NaN, "batb": [[0, 12.5, 3.21], [1, 12, 24.12], [2, 11.5, 2.55]], "batl": NaN}, {"timestamp": 1578673404712, "ltp": 25.0, "tv": 19.99, "trd": NaN, "batb": [[0, 13, 3.55], [1, 12.5, 2.55], [2, 12, 21]], "batl": NaN}, {"timestamp": 1578673552996, "ltp": 25.0, "tv": 19.99, "trd": NaN, "batb": [[0, 13.5, 2.64], [1, 13, 2.89], [2, 12.5, 2.55]], "batl": NaN}, {"timestamp": 1578673560269, "ltp": 25.0, "tv": 19.99, "trd": NaN, "batb": [[1, 12.5, 2.55], [2, 12, 21]], "batl": NaN}, {"timestamp": 1578674169976, "ltp": 25.0, "tv": 19.99, "trd": NaN, "batb": [[0, 13, 2.64]], "batl": NaN}, {"timestamp": 1578674182893, "ltp": 25.0, "tv": 19.99, "trd": NaN, "batb": [[0, 13.5, 3.44], [1, 13, 1.98], [2, 12.5, 2.55]], "batl": NaN}, {"timestamp": 1578674644004, "ltp": 25.0, "tv": 19.99, "trd": NaN, "batb": [[2, 12, 21]], "batl": NaN}, {"timestamp": 1578674644636, "ltp": 25.0, "tv": 19.99, "trd": NaN, "batb": [[2, 12, 21.4]], "batl": NaN}, {"timestamp": 1578674703497, "ltp": 25.0, "tv": 19.99, "trd": NaN, "batb": [[2, 12.5, 2.95]], "batl": NaN}, {"timestamp": 1578674788653, "ltp": 25.0, "tv": 19.99, "trd": NaN, "batb": [[0, 14, 2.64], [1, 13.5, 2.78]], "batl": NaN}, {"timestamp": 1578674790745, "ltp": 25.0, "tv": 19.99, "trd": NaN, "batb": [[1, 12.5, 2.95], [2, 12, 21]], "batl": NaN}, {"timestamp": 1578674832405, "ltp": 25.0, "tv": 19.99, "trd": NaN, "batb": [[1, 12.5, 3.07]], "batl": NaN}, {"timestamp": 1578674899371, "ltp": 25.0, "tv": 19.99, "trd": NaN, "batb": NaN, "batl": [[0, 36, 4], [1, 85, 5.26]]}, {"timestamp": 1578675402263, "ltp": 25.0, "tv": 19.99, "trd": NaN, "batb": [[0, 13, 2.77], [1, 12.5, 2.95]], "batl": NaN}, {"timestamp": 1578675404538, "ltp": 25.0, "tv": 19.99, "trd": NaN, "batb": [[0, 13.5, 3.56], [1, 13, 1.98], [2, 12.5, 2.95]], "batl": NaN}, {"timestamp": 1578675604485, "ltp": 25.0, "tv": 20.01, "trd": [[25, 12.29], [26, 5.1], [27, 2.62]], "batb": [[0, 13.5, 3.57], [1, 13, 1.98], [2, 12.5, 2.95]], "batl": NaN}, {"timestamp": 1578675645143, "ltp": 25.0, "tv": 20.01, "trd": NaN, "batb": [[0, 14, 2.65], [1, 13.5, 2.9]], "batl": NaN}, {"timestamp": 1578675650848, "ltp": 25.0, "tv": 20.01, "trd": NaN, "batb": [[1, 12.5, 3.08], [2, 12, 21]], "batl": NaN}, {"timestamp": 1578675664463, "ltp": 25.0, "tv": 20.01, "trd": NaN, "batb": [[0, 13, 2.77], [1, 12.5, 2.95]], "batl": NaN}, {"timestamp": 1578675672383, "ltp": 25.0, "tv": 20.01, "trd": NaN, "batb": [[0, 13.5, 3.57], [1, 13, 1.98], [2, 12.5, 2.95]], "batl": NaN}, {"timestamp": 1578675683472, "ltp": 25.0, "tv": 20.01, "trd": NaN, "batb": [[0, 14, 2.65], [1, 13.5, 2.9]], "batl": NaN}, {"timestamp": 1578675694587, "ltp": 25.0, "tv": 20.01, "trd": NaN, "batb": [[1, 12.5, 3.08], [2, 12, 21]], "batl": NaN}, {"timestamp": 1578675701715, "ltp": 25.0, "tv": 20.01, "trd": NaN, "batb": [[0, 13, 2.77], [1, 12.5, 2.95]], "batl": NaN}, {"timestamp": 1578675716723, "ltp": 25.0, "tv": 20.01, "trd": NaN, "batb": [[0, 13.5, 3.57], [1, 13, 1.98], [2, 12.5, 2.95]], "batl": NaN}, {"timestamp": 1578675719740, "ltp": 25.0, "tv": 20.01, "trd": NaN, "batb": [[0, 14, 2.65], [1, 13.5, 2.9]], "batl": NaN}, {"timestamp": 1578675739336, "ltp": 25.0, "tv": 20.01, "trd": NaN, "batb": [[0, 14.5, 3.25], [1, 14, 1.98], [2, 12.5, 3.08]], "batl": NaN}, {"timestamp": 1578675741935, "ltp": 25.0, "tv": 20.01, "trd": NaN, "batb": [[2, 12.5, 2.95]], "batl": NaN}, {"timestamp": 1578675742038, "ltp": 25.0, "tv": 20.01, "trd": NaN, "batb": [[1, 14, 2.1]], "batl": NaN}, {"timestamp": 1578675757856, "ltp": 25.0, "tv": 20.01, "trd": NaN, "batb": [[0, 15, 2.65], [1, 14.5, 2.59], [2, 12.5, 3.07]], "batl": NaN}, {"timestamp": 1578675761761, "ltp": 25.0, "tv": 20.01, "trd": NaN, "batb": [[1, 12.5, 3.07], [2, 12, 21]], "batl": NaN}, {"timestamp": 1578675777412, "ltp": 25.0, "tv": 20.01, "trd": NaN, "batb": [[0, 13, 2.76], [1, 12.5, 2.95]], "batl": NaN}, {"timestamp": 1578675784888, "ltp": 25.0, "tv": 20.01, "trd": NaN, "batb": [[0, 13.5, 3.56], [1, 13, 1.98], [2, 12.5, 2.95]], "batl": NaN}, {"timestamp": 1578675795543, "ltp": 25.0, "tv": 20.01, "trd": NaN, "batb": [[0, 14, 2.76], [1, 13.5, 2.78]], "batl": NaN}, {"timestamp": 1578675807906, "ltp": 25.0, "tv": 20.01, "trd": NaN, "batb": [[1, 12.5, 2.95], [2, 12, 21]], "batl": NaN}, {"timestamp": 1578675814929, "ltp": 25.0, "tv": 20.01, "trd": NaN, "batb": [[0, 13, 2.76]], "batl": NaN}, {"timestamp": 1578675829265, "ltp": 25.0, "tv": 20.01, "trd": NaN, "batb": [[0, 13.5, 3.56], [1, 13, 1.98], [2, 12.5, 2.95]], "batl": NaN}, {"timestamp": 1578675832963, "ltp": 25.0, "tv": 20.01, "trd": NaN, "batb": [[1, 12.5, 2.95], [2, 12, 21]], "batl": NaN}, {"timestamp": 1578675833070, "ltp": 25.0, "tv": 20.01, "trd": NaN, "batb": [[0, 14, 2.76], [1, 13.5, 2.78], [2, 12.5, 2.95]], "batl": NaN}, {"timestamp": 1578675851792, "ltp": 25.0, "tv": 20.01, "trd": NaN, "batb": [[0, 14.5, 3.37], [1, 14, 1.98]], "batl": NaN}, {"timestamp": 1578675870723, "ltp": 25.0, "tv": 20.01, "trd": NaN, "batb": [[0, 15, 2.65], [1, 14.5, 2.7]], "batl": NaN}, {"timestamp": 1578675874099, "ltp": 25.0, "tv": 20.01, "trd": NaN, "batb": [[1, 12.5, 3.07], [2, 12, 21]], "batl": NaN}, {"timestamp": 1578675889720, "ltp": 25.0, "tv": 20.01, "trd": NaN, "batb": [[0, 13, 2.76], [1, 12.5, 2.95]], "batl": NaN}, {"timestamp": 1578675896461, "ltp": 25.0, "tv": 20.01, "trd": NaN, "batb": [[0, 13.5, 3.56], [1, 13, 1.98], [2, 12.5, 2.95]], "batl": NaN}, {"timestamp": 1578675940313, "ltp": 25.0, "tv": 20.01, "trd": NaN, "batb": [[0, 14, 2.76], [1, 13.5, 2.78]], "batl": NaN}, {"timestamp": 1578675962838, "ltp": 25.0, "tv": 20.01, "trd": NaN, "batb": [[0, 14.5, 3.37], [1, 14, 1.98]], "batl": NaN}, {"timestamp": 1578675973961, "ltp": 25.0, "tv": 20.01, "trd": NaN, "batb": [[0, 15, 2.65], [1, 14.5, 2.7]], "batl": NaN}, {"timestamp": 1578675984713, "ltp": 25.0, "tv": 20.01, "trd": NaN, "batb": [[1, 12.5, 3.07], [2, 12, 21]], "batl": NaN}, {"timestamp": 1578676006440, "ltp": 25.0, "tv": 20.01, "trd": NaN, "batb": [[0, 13, 2.76], [1, 12.5, 2.95]], "batl": NaN}, {"timestamp": 1578676008628, "ltp": 25.0, "tv": 20.01, "trd": NaN, "batb": [[0, 13.5, 3.56], [1, 13, 1.98], [2, 12.5, 2.95]], "batl": NaN}, {"timestamp": 1578676038954, "ltp": 25.0, "tv": 20.01, "trd": NaN, "batb": [[0, 14, 2.76], [1, 13.5, 2.78]], "batl": NaN}, {"timestamp": 1578676053684, "ltp": 25.0, "tv": 20.01, "trd": NaN, "batb": [[0, 14.5, 3.37], [1, 14, 1.98]], "batl": NaN}, {"timestamp": 1578676072597, "ltp": 25.0, "tv": 20.01, "trd": NaN, "batb": [[0, 15, 2.65], [1, 14.5, 2.7]], "batl": NaN}, {"timestamp": 1578676077427, "ltp": 25.0, "tv": 20.01, "trd": NaN, "batb": [[0, 15.5, 3.08], [1, 15, 1.98], [2, 12.5, 3.07]], "batl": NaN}, {"timestamp": 1578676083642, "ltp": 25.0, "tv": 20.01, "trd": NaN, "batb": [[1, 15, 2.09], [2, 12.5, 2.95]], "batl": NaN}, {"timestamp": 1578676100634, "ltp": 25.0, "tv": 20.01, "trd": NaN, "batb": [[0, 15, 2.75], [1, 12.5, 2.95], [2, 12, 21]], "batl": NaN}, {"timestamp": 1578676105869, "ltp": 25.0, "tv": 20.01, "trd": NaN, "batb": [[0, 13, 2.75]], "batl": NaN}, {"timestamp": 1578676122572, "ltp": 25.0, "tv": 20.01, "trd": NaN, "batb": [[0, 13.5, 3.55], [1, 13, 1.98], [2, 12.5, 2.95]], "batl": NaN}, {"timestamp": 1578676138778, "ltp": 25.0, "tv": 20.01, "trd": NaN, "batb": [[0, 14, 2.75], [1, 13.5, 2.78]], "batl": NaN}, {"timestamp": 1578676145677, "ltp": 25.0, "tv": 20.01, "trd": NaN, "batb": [[1, 12.5, 2.95], [2, 12, 21]], "batl": NaN}, {"timestamp": 1578676172998, "ltp": 25.0, "tv": 20.01, "trd": NaN, "batb": [[0, 12.5, 3.73], [1, 12, 21], [2, 2, 10]], "batl": NaN}, {"timestamp": 1578676173101, "ltp": 25.0, "tv": 20.01, "trd": NaN, "batb": [[0, 13, 2.75], [1, 12.5, 2.95], [2, 12, 21]], "batl": NaN}, {"timestamp": 1578676190348, "ltp": 25.0, "tv": 20.01, "trd": NaN, "batb": [[0, 13.5, 3.55], [1, 13, 1.98], [2, 12.5, 2.95]], "batl": NaN}, {"timestamp": 1578676253713, "ltp": 25.0, "tv": 20.01, "trd": NaN, "batb": [[0, 14, 2.75], [1, 13.5, 2.78]], "batl": NaN}, {"timestamp": 1578676256823, "ltp": 25.0, "tv": 20.01, "trd": NaN, "batb": [[0, 14.5, 3.36], [1, 14, 1.98]], "batl": NaN}, {"timestamp": 1578676279572, "ltp": 25.0, "tv": 20.01, "trd": NaN, "batb": [[0, 14, 2.75], [1, 12.5, 2.95], [2, 12, 21]], "batl": NaN}, {"timestamp": 1578676344805, "ltp": 25.0, "tv": 20.01, "trd": NaN, "batb": [[0, 13, 2.75]], "batl": NaN}, {"timestamp": 1578676346904, "ltp": 25.0, "tv": 20.01, "trd": NaN, "batb": [[0, 13.5, 3.55], [1, 13, 1.98], [2, 12.5, 2.95]], "batl": NaN}, {"timestamp": 1578676437903, "ltp": 25.0, "tv": 20.01, "trd": NaN, "batb": [[1, 12.5, 2.95], [2, 12, 21]], "batl": NaN}, {"timestamp": 1578676438008, "ltp": 25.0, "tv": 20.01, "trd": NaN, "batb": [[0, 14, 2.75], [1, 13.5, 2.78], [2, 12.5, 2.95]], "batl": NaN}, {"timestamp": 1578676457745, "ltp": 25.0, "tv": 20.01, "trd": NaN, "batb": [[1, 12.5, 2.95], [2, 12, 21]], "batl": NaN}, {"timestamp": 1578676528714, "ltp": 25.0, "tv": 20.01, "trd": NaN, "batb": [[0, 13, 2.75]], "batl": NaN}, {"timestamp": 1578676534644, "ltp": 25.0, "tv": 20.01, "trd": NaN, "batb": [[0, 14.5, 21.77], [1, 13, 1.98], [2, 12.5, 2.95]], "batl": NaN}, {"timestamp": 1578676543833, "ltp": 25.0, "tv": 20.01, "trd": NaN, "batb": [[0, 13.5, 21.77]], "batl": NaN}, {"timestamp": 1578676563457, "ltp": 25.0, "tv": 20.01, "trd": NaN, "batb": [[0, 14, 3.33], [1, 13.5, 21], [2, 13, 1.98]], "batl": NaN}, {"timestamp": 1578676564870, "ltp": 25.0, "tv": 20.01, "trd": NaN, "batb": [[0, 14.5, 2.75], [1, 14, 2.55], [2, 13.5, 21]], "batl": NaN}, {"timestamp": 1578676567901, "ltp": 25.0, "tv": 20.01, "trd": NaN, "batb": [[0, 15, 3.28], [1, 14.5, 1.98], [2, 14, 2.55]], "batl": NaN}, {"timestamp": 1578676600318, "ltp": 25.0, "tv": 20.01, "trd": NaN, "batb": [[0, 15.5, 2.65], [1, 15, 2.61]], "batl": NaN}, {"timestamp": 1578676613633, "ltp": 25.0, "tv": 20.01, "trd": NaN, "batb": [[1, 14, 2.66], [2, 13.5, 21]], "batl": NaN}, {"timestamp": 1578676635552, "ltp": 25.0, "tv": 20.01, "trd": NaN, "batb": [[0, 14.5, 2.75], [1, 14, 2.55]], "batl": NaN}, {"timestamp": 1578676658667, "ltp": 25.0, "tv": 20.01, "trd": NaN, "batb": [[0, 15, 3.28], [1, 14.5, 1.98], [2, 14, 2.55]], "batl": NaN}, {"timestamp": 1578676672482, "ltp": 25.0, "tv": 20.01, "trd": NaN, "batb": [[0, 15.5, 2.65], [1, 15, 2.61]], "batl": NaN}, {"timestamp": 1578676681782, "ltp": 25.0, "tv": 20.01, "trd": NaN, "batb": [[1, 14, 2.66], [2, 13.5, 21]], "batl": NaN}, {"timestamp": 1578676682093, "ltp": 25.0, "tv": 20.01, "trd": NaN, "batb": [[0, 16, 3.01], [1, 15.5, 1.98], [2, 14, 2.66]], "batl": NaN}, {"timestamp": 1578676683720, "ltp": 25.0, "tv": 20.01, "trd": NaN, "batb": [[2, 14, 2.55]], "batl": NaN}, {"timestamp": 1578676684608, "ltp": 25.0, "tv": 20.01, "trd": NaN, "batb": [[1, 15.5, 2.09]], "batl": NaN}, {"timestamp": 1578676704427, "ltp": 25.0, "tv": 20.01, "trd": NaN, "batb": [[0, 15.5, 2.75], [1, 14, 2.55], [2, 13.5, 21]], "batl": NaN}, {"timestamp": 1578676707640, "ltp": 25.0, "tv": 20.01, "trd": NaN, "batb": [[0, 14.5, 2.75]], "batl": NaN}, {"timestamp": 1578676712722, "ltp": 25.0, "tv": 20.01, "trd": NaN, "batb": [[1, 14, 12.55]], "batl": NaN}, {"timestamp": 1578676726651, "ltp": 25.0, "tv": 20.01, "trd": NaN, "batb": [[0, 15, 3.28], [1, 14.5, 1.98], [2, 14, 12.55]], "batl": NaN}, {"timestamp": 1578676728469, "ltp": 25.0, "tv": 20.01, "trd": NaN, "batb": [[2, 14, 12.67]], "batl": NaN}, {"timestamp": 1578676737654, "ltp": 25.0, "tv": 20.01, "trd": NaN, "batb": [[2, 14, 12.55]], "batl": NaN}, {"timestamp": 1578676738541, "ltp": 25.0, "tv": 20.01, "trd": NaN, "batb": [[1, 14.5, 2.1]], "batl": NaN}, {"timestamp": 1578676744686, "ltp": 25.0, "tv": 20.01, "trd": NaN, "batb": [[0, 15.5, 2.75], [1, 15, 2.5], [2, 14, 12.67]], "batl": NaN}, {"timestamp": 1578676748759, "ltp": 25.0, "tv": 20.01, "trd": NaN, "batb": [[1, 14, 12.67], [2, 13.5, 21]], "batl": NaN}, {"timestamp": 1578676749698, "ltp": 25.0, "tv": 20.01, "trd": NaN, "batb": [[1, 14, 12.55]], "batl": NaN}, {"timestamp": 1578676751004, "ltp": 25.0, "tv": 20.01, "trd": NaN, "batb": [[1, 14, 12.66]], "batl": NaN}, {"timestamp": 1578676781949, "ltp": 25.0, "tv": 20.01, "trd": NaN, "batb": [[0, 14.5, 2.86], [1, 14, 12.55]], "batl": NaN}, {"timestamp": 1578676793362, "ltp": 25.0, "tv": 20.01, "trd": NaN, "batb": [[0, 15, 3.38], [1, 14.5, 1.98], [2, 14, 12.55]], "batl": NaN}, {"timestamp": 1578676865898, "ltp": 25.0, "tv": 20.01, "trd": NaN, "batb": [[0, 15.5, 2.75], [1, 15, 2.61]], "batl": NaN}, {"timestamp": 1578676880760, "ltp": 25.0, "tv": 20.01, "trd": NaN, "batb": [[1, 14, 12.66], [2, 13.5, 21]], "batl": NaN}, {"timestamp": 1578676881543, "ltp": 25.0, "tv": 20.01, "trd": NaN, "batb": [[0, 16, 3.01], [1, 15.5, 2.09], [2, 14, 12.66]], "batl": NaN}, {"timestamp": 1578676884958, "ltp": 25.0, "tv": 20.01, "trd": NaN, "batb": [[2, 14, 12.55]], "batl": NaN}, {"timestamp": 1578676887475, "ltp": 25.0, "tv": 20.01, "trd": NaN, "batb": [[1, 15.5, 2.2]], "batl": NaN}, {"timestamp": 1578676902974, "ltp": 25.0, "tv": 20.01, "trd": NaN, "batb": [[0, 15.5, 2.86], [1, 14, 12.55], [2, 13.5, 21]], "batl": NaN}, {"timestamp": 1578676960957, "ltp": 25.0, "tv": 20.01, "trd": NaN, "batb": [[0, 14.5, 2.86]], "batl": NaN}, {"timestamp": 1578676968782, "ltp": 25.0, "tv": 20.01, "trd": NaN, "batb": [[0, 15, 3.38], [1, 14.5, 1.98], [2, 14, 12.55]], "batl": NaN}, {"timestamp": 1578677058846, "ltp": 25.0, "tv": 20.01, "trd": NaN, "batb": [[0, 15.5, 2.86], [1, 14, 12.55], [2, 13.5, 21]], "batl": NaN}, {"timestamp": 1578677059161, "ltp": 25.0, "tv": 20.01, "trd": NaN, "batb": [[0, 16, 3.01], [1, 15.5, 2.2], [2, 14, 12.55]], "batl": NaN}, {"timestamp": 1578677081470, "ltp": 25.0, "tv": 20.01, "trd": NaN, "batb": [[0, 15.5, 2.86], [1, 14, 12.55], [2, 13.5, 21]], "batl": NaN}, {"timestamp": 1578677107722, "ltp": 25.0, "tv": 20.01, "trd": NaN, "batb": [[0, 14.5, 2.86]], "batl": NaN}, {"timestamp": 1578677125933, "ltp": 25.0, "tv": 20.01, "trd": NaN, "batb": [[0, 15, 3.38], [1, 14.5, 1.98], [2, 14, 12.55]], "batl": NaN}, {"timestamp": 1578677135725, "ltp": 25.0, "tv": 20.01, "trd": NaN, "batb": [[0, 15.5, 2.86], [1, 15, 2.5]], "batl": NaN}, {"timestamp": 1578677147957, "ltp": 25.0, "tv": 20.01, "trd": NaN, "batb": [[1, 14, 12.55], [2, 13.5, 21]], "batl": NaN}, {"timestamp": 1578677159773, "ltp": 25.0, "tv": 20.01, "trd": NaN, "batb": [[0, 14.5, 2.86]], "batl": NaN}, {"timestamp": 1578677170206, "ltp": 25.0, "tv": 20.01, "trd": NaN, "batb": [[0, 15, 3.38], [1, 14.5, 1.98], [2, 14, 12.55]], "batl": NaN}, {"timestamp": 1578677186243, "ltp": 25.0, "tv": 20.01, "trd": NaN, "batb": [[0, 15.5, 2.86], [1, 15, 2.5]], "batl": NaN}, {"timestamp": 1578677192455, "ltp": 25.0, "tv": 20.01, "trd": NaN, "batb": [[1, 14, 12.55], [2, 13.5, 21]], "batl": NaN}, {"timestamp": 1578677211903, "ltp": 25.0, "tv": 20.01, "trd": NaN, "batb": [[0, 14, 13.43], [1, 13.5, 21], [2, 12.5, 2.95]], "batl": NaN}, {"timestamp": 1578677212009, "ltp": 25.0, "tv": 20.01, "trd": NaN, "batb": [[0, 14.5, 2.86], [1, 14, 12.55], [2, 13.5, 21]], "batl": NaN}, {"timestamp": 1578677216603, "ltp": 25.0, "tv": 20.01, "trd": NaN, "batb": [[0, 15, 3.38], [1, 14.5, 1.98], [2, 14, 12.55]], "batl": NaN}, {"timestamp": 1578677237491, "ltp": 25.0, "tv": 20.01, "trd": NaN, "batb": [[0, 15.5, 2.86], [1, 15, 2.5]], "batl": NaN}, {"timestamp": 1578677238900, "ltp": 25.0, "tv": 20.01, "trd": NaN, "batb": [[1, 14, 12.55], [2, 13.5, 21]], "batl": NaN}, {"timestamp": 1578677239320, "ltp": 25.0, "tv": 20.01, "trd": NaN, "batb": [[0, 16, 3.01], [1, 15.5, 2.2], [2, 14, 12.55]], "batl": NaN}, {"timestamp": 1578677247686, "ltp": 25.0, "tv": 20.01, "trd": NaN, "batb": [[0, 20, 2.66], [1, 16, 2.34], [2, 15.5, 2.2]], "batl": NaN}, {"timestamp": 1578677250716, "ltp": 25.0, "tv": 20.01, "trd": NaN, "batb": [[2, 15.5, 2.09]], "batl": NaN}, {"timestamp": 1578677251394, "ltp": 25.0, "tv": 20.01, "trd": NaN, "batb": [[1, 16, 2.43]], "batl": NaN}, {"timestamp": 1578677253902, "ltp": 25.0, "tv": 20.01, "trd": NaN, "batb": [[2, 15.5, 1.98]], "batl": NaN}, {"timestamp": 1578677255622, "ltp": 25.0, "tv": 20.01, "trd": NaN, "batb": [[1, 16, 2.51]], "batl": NaN}, {"timestamp": 1578677262242, "ltp": 25.0, "tv": 20.01, "trd": NaN, "batb": [[1, 15.5, 2.15], [2, 14, 12.55]], "batl": NaN}, {"timestamp": 1578677263734, "ltp": 25.0, "tv": 20.01, "trd": NaN, "batb": [[0, 21, 2.65], [1, 20, 2], [2, 14, 12.72]], "batl": NaN}, {"timestamp": 1578677265934, "ltp": 25.0, "tv": 20.01, "trd": NaN, "batb": [[2, 14, 12.64]], "batl": NaN}, {"timestamp": 1578677266931, "ltp": 25.0, "tv": 20.01, "trd": NaN, "batb": [[1, 20, 2.08], [2, 14, 12.55]], "batl": NaN}, {"timestamp": 1578677267723, "ltp": 25.0, "tv": 20.01, "trd": NaN, "batb": [[1, 20, 2.17]], "batl": NaN}, {"timestamp": 1578678809858, "ltp": 21.0, "tv": 24.01, "trd": [[21, 2.68], [25, 13.61]], "batb": [[0, 20, 2.82], [1, 14, 12.55], [2, 13.5, 21]], "batl": NaN}, {"timestamp": 1578678811268, "ltp": 21.0, "tv": 24.01, "trd": NaN, "batb": NaN, "batl": [[0, 36, 4.2], [1, 85, 5.06]]}, {"timestamp": 1578678818464, "ltp": 21.0, "tv": 24.01, "trd": NaN, "batb": NaN, "batl": [[1, 85, 2.06]]}, {"timestamp": 1578678981621, "ltp": 21.0, "tv": 24.01, "trd": NaN, "batb": [[1, 14, 12.89]], "batl": NaN}, {"timestamp": 1578680170647, "ltp": 34.0, "tv": 24.41, "trd": [[34, 0.4]], "batb": [[0, 21, 1.03], [1, 20, 2.17], [2, 14, 12.89]], "batl": [[0, 36, 4]]}, {"timestamp": 1578680869965, "ltp": 34.0, "tv": 24.41, "trd": NaN, "batb": NaN, "batl": [[2, 150, 9]]}, {"timestamp": 1578680892592, "ltp": 34.0, "tv": 25.17, "trd": [[34, 1.16]], "batb": [[0, 20, 2.82], [1, 14, 12.89], [2, 13.5, 21]], "batl": [[0, 32, 1.62], [1, 36, 4], [2, 85, 2.06]]}, {"timestamp": 1578680900990, "ltp": 34.0, "tv": 25.17, "trd": NaN, "batb": NaN, "batl": [[0, 34, 1.62]]}, {"timestamp": 1578680905509, "ltp": 34.0, "tv": 25.17, "trd": NaN, "batb": NaN, "batl": [[0, 34, 1.8]]}, {"timestamp": 1578680953862, "ltp": 34.0, "tv": 25.17, "trd": NaN, "batb": [[0, 20, 12.82]], "batl": NaN}, {"timestamp": 1578680994907, "ltp": 34.0, "tv": 25.17, "trd": NaN, "batb": [[0, 21, 1.96], [1, 20, 12.17], [2, 14, 12.89]], "batl": NaN}, {"timestamp": 1578681063864, "ltp": 34.0, "tv": 25.17, "trd": NaN, "batb": [[0, 21, 4.51]], "batl": NaN}, {"timestamp": 1578681076677, "ltp": 34.0, "tv": 25.17, "trd": NaN, "batb": [[0, 22, 1.71], [1, 21, 4.51], [2, 20, 12.17]], "batl": NaN}, {"timestamp": 1578681078364, "ltp": 34.0, "tv": 25.17, "trd": NaN, "batb": [[0, 22, 2.35], [1, 21, 3.87]], "batl": NaN}, {"timestamp": 1578681080983, "ltp": 34.0, "tv": 25.17, "trd": NaN, "batb": [[2, 20, 12.08]], "batl": NaN}, {"timestamp": 1578681081567, "ltp": 34.0, "tv": 25.17, "trd": NaN, "batb": [[1, 21, 3.94]], "batl": NaN}, {"timestamp": 1578681082982, "ltp": 34.0, "tv": 25.17, "trd": NaN, "batb": [[1, 21, 4.02], [2, 20, 12]], "batl": NaN}, {"timestamp": 1578681213861, "ltp": 34.0, "tv": 25.17, "trd": NaN, "batb": [[2, 20, 2]], "batl": NaN}, {"timestamp": 1578681218890, "ltp": 34.0, "tv": 25.17, "trd": NaN, "batb": [[0, 23, 9.35], [1, 22, 1.71], [2, 21, 4.02]], "batl": NaN}, {"timestamp": 1578681220983, "ltp": 34.0, "tv": 25.17, "trd": NaN, "batb": [[2, 21, 3.94]], "batl": NaN}, {"timestamp": 1578681222795, "ltp": 34.0, "tv": 25.17, "trd": NaN, "batb": [[1, 22, 1.78], [2, 21, 3.87]], "batl": NaN}, {"timestamp": 1578681223589, "ltp": 34.0, "tv": 25.17, "trd": NaN, "batb": [[1, 22, 1.86]], "batl": NaN}, {"timestamp": 1578681227801, "ltp": 34.0, "tv": 25.17, "trd": NaN, "batb": [[1, 21, 4.02], [2, 20, 2]], "batl": NaN}, {"timestamp": 1578681303672, "ltp": 34.0, "tv": 25.17, "trd": NaN, "batb": [[0, 24, 2.55], [1, 23, 9.35], [2, 21, 1.47]], "batl": [[0, 34, 1.62]]}, {"timestamp": 1578681305885, "ltp": 34.0, "tv": 25.17, "trd": NaN, "batb": [[1, 23, 9.42], [2, 21, 1.39]], "batl": NaN}, {"timestamp": 1578681307864, "ltp": 34.0, "tv": 25.17, "trd": NaN, "batb": [[2, 21, 1.31]], "batl": NaN}, {"timestamp": 1578681309997, "ltp": 34.0, "tv": 25.17, "trd": NaN, "batb": [[1, 23, 9.48]], "batl": NaN}, {"timestamp": 1578681363921, "ltp": 34.0, "tv": 25.17, "trd": NaN, "batb": [[0, 24, 3.2], [1, 23, 8.84]], "batl": NaN}, {"timestamp": 1578681454453, "ltp": 34.0, "tv": 25.17, "trd": NaN, "batb": [[0, 25, 5.49], [1, 24, 2.55], [2, 23, 8.84]], "batl": NaN}, {"timestamp": 1578681463464, "ltp": 34.0, "tv": 25.17, "trd": NaN, "batb": [[1, 24, 2.62], [2, 23, 8.77]], "batl": NaN}, {"timestamp": 1578681467971, "ltp": 34.0, "tv": 25.17, "trd": NaN, "batb": [[2, 23, 8.7]], "batl": NaN}, {"timestamp": 1578681468232, "ltp": 34.0, "tv": 25.17, "trd": NaN, "batb": [[1, 24, 2.69]], "batl": NaN}, {"timestamp": 1578681484874, "ltp": 34.0, "tv": 25.17, "trd": NaN, "batb": [[1, 23, 8.84], [2, 21, 1.31]], "batl": NaN}, {"timestamp": 1578681543751, "ltp": 34.0, "tv": 25.17, "trd": NaN, "batb": [[1, 24, 2.3], [2, 23, 8.7]], "batl": NaN}, {"timestamp": 1578681786910, "ltp": 34.0, "tv": 25.17, "trd": NaN, "batb": [[2, 21, 1.31]], "batl": NaN}, {"timestamp": 1578681792725, "ltp": 34.0, "tv": 25.17, "trd": NaN, "batb": [[0, 26, 7.69], [1, 25, 5.49], [2, 24, 2.3]], "batl": NaN}, {"timestamp": 1578681798702, "ltp": 34.0, "tv": 25.17, "trd": NaN, "batb": [[2, 24, 2.23]], "batl": NaN}, {"timestamp": 1578681800875, "ltp": 34.0, "tv": 25.17, "trd": NaN, "batb": [[1, 25, 5.55]], "batl": NaN}, {"timestamp": 1578681830213, "ltp": 34.0, "tv": 25.17, "trd": NaN, "batb": [[0, 27, 1.02], [1, 26, 7.69], [2, 25, 5.55]], "batl": NaN}, {"timestamp": 1578681842825, "ltp": 34.0, "tv": 25.17, "trd": NaN, "batb": [[0, 27, 2.94]], "batl": NaN}, {"timestamp": 1578681849926, "ltp": 34.0, "tv": 25.17, "trd": NaN, "batb": [[2, 25, 5.49]], "batl": NaN}, {"timestamp": 1578681850347, "ltp": 34.0, "tv": 25.17, "trd": NaN, "batb": [[1, 26, 7.75]], "batl": NaN}, {"timestamp": 1578682725953, "ltp": 34.0, "tv": 25.17, "trd": NaN, "batb": [[0, 27, 6.34]], "batl": NaN}, {"timestamp": 1578682832949, "ltp": 34.0, "tv": 25.17, "trd": [[25, 13.61]], "batb": [[0, 27, 6.34]], "batl": NaN}, {"timestamp": 1578683000629, "ltp": 27.0, "tv": 35.17, "trd": [[27, 12.62]], "batb": [[0, 27, 1.35]], "batl": NaN}, {"timestamp": 1578683258183, "ltp": 27.0, "tv": 35.17, "trd": NaN, "batb": [[0, 27, 1.99], [2, 25, 4.84]], "batl": NaN}, {"timestamp": 1578683688743, "ltp": 27.0, "tv": 35.17, "trd": NaN, "batb": [[1, 26, 7.79]], "batl": NaN}, {"timestamp": 1578683737685, "ltp": 27.0, "tv": 35.17, "trd": NaN, "batb": [[0, 26, 8.43], [1, 25, 4.84], [2, 20, 2.07]], "batl": NaN}, {"timestamp": 1578685720630, "ltp": 27.0, "tv": 35.17, "trd": NaN, "batb": [[0, 26, 8.75]], "batl": NaN}, {"timestamp": 1578686273738, "ltp": 27.0, "tv": 35.17, "trd": NaN, "batb": [[0, 27, 2.96], [1, 26, 7.79], [2, 25, 4.84]], "batl": NaN}, {"timestamp": 1578686410879, "ltp": 27.0, "tv": 35.17, "trd": NaN, "batb": [[0, 28, 4], [1, 27, 2.96], [2, 26, 7.79]], "batl": [[2, 44, 3]]}, {"timestamp": 1578686412958, "ltp": 27.0, "tv": 35.17, "trd": NaN, "batb": [[2, 26, 7.75]], "batl": NaN}, {"timestamp": 1578686413750, "ltp": 27.0, "tv": 35.17, "trd": NaN, "batb": [[1, 27, 3]], "batl": NaN}, {"timestamp": 1578686432989, "ltp": 27.0, "tv": 35.17, "trd": NaN, "batb": [[0, 29, 1.5], [1, 28, 4], [2, 27, 3]], "batl": NaN}, {"timestamp": 1578686447025, "ltp": 34.0, "tv": 35.57, "trd": [[34, 1.56]], "batb": NaN, "batl": [[0, 34, 1.42]]}, {"timestamp": 1578686454744, "ltp": 34.0, "tv": 35.57, "trd": NaN, "batb": [[0, 29, 2.14], [2, 27, 2.35]], "batl": NaN}, {"timestamp": 1578686460959, "ltp": 34.0, "tv": 35.57, "trd": NaN, "batb": [[2, 27, 2.32]], "batl": NaN}, {"timestamp": 1578686461812, "ltp": 34.0, "tv": 35.57, "trd": NaN, "batb": [[1, 28, 4.03]], "batl": NaN}, {"timestamp": 1578686536355, "ltp": 34.0, "tv": 35.57, "trd": NaN, "batb": [[1, 27, 2.35], [2, 26, 7.75]], "batl": [[2, 85, 2.06]]}, {"timestamp": 1578686569672, "ltp": 34.0, "tv": 35.57, "trd": NaN, "batb": [[0, 29, 1.5], [1, 27, 3]], "batl": NaN}, {"timestamp": 1578686657735, "ltp": 34.0, "tv": 35.57, "trd": NaN, "batb": NaN, "batl": [[2, 48, 2]]}, {"timestamp": 1578686809934, "ltp": 34.0, "tv": 36.49, "trd": [[34, 2.48]], "batb": NaN, "batl": [[0, 36, 4.96], [1, 48, 2], [2, 85, 2.06]]}, {"timestamp": 1578688002647, "ltp": 36.0, "tv": 46.41, "trd": [[34, 4.4], [36, 8]], "batb": [[0, 29, 2.23]], "batl": [[0, 48, 2], [1, 85, 2.06], [2, 150, 9]]}, {"timestamp": 1578688013685, "ltp": 36.0, "tv": 46.41, "trd": NaN, "batb": [[0, 30, 1.38], [1, 29, 1.5], [2, 27, 2.35]], "batl": NaN}, {"timestamp": 1578688014971, "ltp": 36.0, "tv": 46.41, "trd": NaN, "batb": [[2, 28, 10.74]], "batl": NaN}, {"timestamp": 1578688016791, "ltp": 36.0, "tv": 46.41, "trd": NaN, "batb": [[1, 29, 4.9]], "batl": NaN}, {"timestamp": 1578688020795, "ltp": 36.0, "tv": 46.41, "trd": NaN, "batb": [[0, 29, 5.55], [1, 28, 10.8], [2, 27, 2.32]], "batl": NaN}, {"timestamp": 1578688021985, "ltp": 36.0, "tv": 46.41, "trd": NaN, "batb": [[0, 30, 1.38], [1, 29, 4.9], [2, 28, 10.8]], "batl": NaN}, {"timestamp": 1578688025994, "ltp": 36.0, "tv": 46.41, "trd": NaN, "batb": [[0, 30, 2.06]], "batl": NaN}, {"timestamp": 1578688026891, "ltp": 36.0, "tv": 46.41, "trd": NaN, "batb": [[1, 29, 4.96], [2, 28, 10.76]], "batl": NaN}, {"timestamp": 1578688028391, "ltp": 36.0, "tv": 46.41, "trd": NaN, "batb": [[1, 29, 4.99]], "batl": NaN}, {"timestamp": 1578688029908, "ltp": 36.0, "tv": 46.41, "trd": NaN, "batb": [[2, 28, 10.71]], "batl": NaN}, {"timestamp": 1578688031611, "ltp": 36.0, "tv": 46.41, "trd": NaN, "batb": [[1, 29, 5.04]], "batl": NaN}, {"timestamp": 1578688069804, "ltp": 36.0, "tv": 46.41, "trd": NaN, "batb": [[1, 29, 8.04]], "batl": [[0, 85, 2.06], [1, 120, 2.4]]}, {"timestamp": 1578688119277, "ltp": 36.0, "tv": 46.41, "trd": NaN, "batb": NaN, "batl": [[2, 350, 9]]}, {"timestamp": 1578688135655, "ltp": 36.0, "tv": 46.41, "trd": NaN, "batb": NaN, "batl": [[0, 85, 2.26]]}, {"timestamp": 1578688806279, "ltp": 36.0, "tv": 46.41, "trd": NaN, "batb": [[0, 32, 3], [1, 30, 2.06], [2, 29, 5.04]], "batl": NaN}, {"timestamp": 1578688807967, "ltp": 36.0, "tv": 46.41, "trd": NaN, "batb": [[2, 29, 4.96]], "batl": NaN}, {"timestamp": 1578688808868, "ltp": 36.0, "tv": 46.41, "trd": NaN, "batb": [[1, 30, 2.14]], "batl": NaN}, {"timestamp": 1578688810001, "ltp": 36.0, "tv": 46.41, "trd": NaN, "batb": [[2, 29, 4.9]], "batl": NaN}, {"timestamp": 1578688810879, "ltp": 36.0, "tv": 46.41, "trd": NaN, "batb": [[1, 30, 2.19]], "batl": NaN}, {"timestamp": 1578688816771, "ltp": 29.0, "tv": 64.41, "trd": [[29, 7.62], [30, 4.38], [32, 6]], "batb": [[0, 29, 1.1], [1, 28, 10.71], [2, 27, 2.32]], "batl": NaN}, {"timestamp": 1578688822004, "ltp": 29.0, "tv": 64.41, "trd": NaN, "batb": NaN, "batl": [[0, 85, 2.31]]}, {"timestamp": 1578688822888, "ltp": 29.0, "tv": 64.41, "trd": NaN, "batb": [[2, 27, 2.4]], "batl": [[0, 85, 2.32]]}, {"timestamp": 1578688823005, "ltp": 29.0, "tv": 64.41, "trd": NaN, "batb": NaN, "batl": [[0, 85, 2.37]]}, {"timestamp": 1578688840522, "ltp": 29.0, "tv": 64.41, "trd": NaN, "batb": [[0, 29, 4.63]], "batl": NaN}, {"timestamp": 1578688844961, "ltp": 29.0, "tv": 64.41, "trd": NaN, "batb": NaN, "batl": [[0, 85, 2.32]]}, {"timestamp": 1578688845038, "ltp": 29.0, "tv": 64.41, "trd": NaN, "batb": NaN, "batl": [[0, 85, 2.37]]}, {"timestamp": 1578688866885, "ltp": 29.0, "tv": 64.41, "trd": NaN, "batb": NaN, "batl": [[0, 85, 2.17]]}, {"timestamp": 1578688869965, "ltp": 29.0, "tv": 64.41, "trd": NaN, "batb": NaN, "batl": [[0, 85, 2.15]]}, {"timestamp": 1578688870973, "ltp": 29.0, "tv": 64.41, "trd": NaN, "batb": NaN, "batl": [[0, 85, 2.12]]}, {"timestamp": 1578688871672, "ltp": 29.0, "tv": 64.41, "trd": NaN, "batb": NaN, "batl": [[0, 85, 2.17]]}, {"timestamp": 1578689025979, "ltp": 29.0, "tv": 64.41, "trd": NaN, "batb": [[0, 30, 1.75], [1, 29, 4.63], [2, 28, 10.71]], "batl": NaN}, {"timestamp": 1578689087297, "ltp": 29.0, "tv": 64.41, "trd": NaN, "batb": [[1, 29, 3.53]], "batl": NaN}, {"timestamp": 1578689307989, "ltp": 29.0, "tv": 64.41, "trd": NaN, "batb": [[0, 30, 2.62]], "batl": NaN}, {"timestamp": 1578689372963, "ltp": 29.0, "tv": 64.41, "trd": NaN, "batb": [[0, 30, 5.95]], "batl": NaN}, {"timestamp": 1578689786254, "ltp": 29.0, "tv": 64.41, "trd": NaN, "batb": [[0, 32, 5.01], [1, 30, 5.08], [2, 29, 3.53]], "batl": NaN}, {"timestamp": 1578689943451, "ltp": 29.0, "tv": 64.41, "trd": NaN, "batb": [[2, 28, 10.71]], "batl": NaN}, {"timestamp": 1578690005208, "ltp": 29.0, "tv": 64.42, "trd": [[25, 13.61], [26, 5.11], [27, 12.62], [29, 7.62]], "batb": [[0, 32, 5.01]], "batl": NaN}, {"timestamp": 1578690066713, "ltp": 29.0, "tv": 64.42, "trd": NaN, "batb": [[0, 34, 3], [1, 32, 5.01], [2, 30, 5.08]], "batl": NaN}, {"timestamp": 1578690077923, "ltp": 29.0, "tv": 64.42, "trd": NaN, "batb": [[0, 34, 6.89], [1, 30, 5.95], [2, 28, 10.71]], "batl": NaN}, {"timestamp": 1578690247773, "ltp": 34.0, "tv": 68.42, "trd": [[34, 8.4]], "batb": [[0, 34, 4.89]], "batl": NaN}, {"timestamp": 1578690252775, "ltp": 34.0, "tv": 68.42, "trd": NaN, "batb": [[0, 34, 1], [1, 32, 5.01], [2, 30, 5.08]], "batl": NaN}, {"timestamp": 1578690549907, "ltp": 34.0, "tv": 68.42, "trd": NaN, "batb": [[0, 34, 1.51]], "batl": NaN}, {"timestamp": 1578691496868, "ltp": 34.0, "tv": 68.42, "trd": NaN, "batb": [[0, 34, 3.41]], "batl": NaN}, {"timestamp": 1578691497555, "ltp": 34.0, "tv": 68.42, "trd": NaN, "batb": [[0, 34, 7.3], [1, 30, 5.95], [2, 28, 10.71]], "batl": NaN}, {"timestamp": 1578692023809, "ltp": 34.0, "tv": 68.42, "trd": NaN, "batb": [[0, 34, 3.41]], "batl": NaN}, {"timestamp": 1578692771535, "ltp": 34.0, "tv": 68.42, "trd": NaN, "batb": [[0, 34, 7.3]], "batl": NaN}, {"timestamp": 1578692803604, "ltp": 34.0, "tv": 68.42, "trd": NaN, "batb": [[0, 34, 3.41]], "batl": NaN}, {"timestamp": 1578692819399, "ltp": 34.0, "tv": 68.42, "trd": NaN, "batb": [[0, 34, 7.3]], "batl": NaN}, {"timestamp": 1578692908754, "ltp": 34.0, "tv": 68.42, "trd": NaN, "batb": [[1, 30, 5.08]], "batl": NaN}, {"timestamp": 1578692951989, "ltp": 34.0, "tv": 72.42, "trd": [[34, 12.4]], "batb": [[0, 34, 5.29]], "batl": NaN}, {"timestamp": 1578693003940, "ltp": 36.0, "tv": 72.51, "trd": [[36, 8.1]], "batb": [[0, 36, 3.55], [1, 34, 5.29], [2, 30, 5.08]], "batl": [[0, 85, 2.12]]}, {"timestamp": 1578693008942, "ltp": 36.0, "tv": 72.51, "trd": NaN, "batb": [[0, 36, 7.22], [1, 34, 1.41]], "batl": NaN}, {"timestamp": 1578693072648, "ltp": 36.0, "tv": 72.51, "trd": NaN, "batb": [[2, 30, 3.33]], "batl": NaN}, {"timestamp": 1578693110135, "ltp": 36.0, "tv": 86.51, "trd": [[36, 22.1]], "batb": [[0, 34, 1.63], [1, 30, 3.33], [2, 28, 10.71]], "batl": NaN}, {"timestamp": 1578693113226, "ltp": 36.0, "tv": 86.51, "trd": NaN, "batb": [[1, 32, 1.98], [2, 30, 3.33]], "batl": NaN}, {"timestamp": 1578693124341, "ltp": 36.0, "tv": 86.51, "trd": NaN, "batb": [[0, 34, 1.41]], "batl": NaN}, {"timestamp": 1578693159944, "ltp": 36.0, "tv": 86.51, "trd": NaN, "batb": [[0, 34, 4.42]], "batl": NaN}, {"timestamp": 1578693267515, "ltp": 36.0, "tv": 86.51, "trd": NaN, "batb": [[0, 34, 4.9]], "batl": NaN}, {"timestamp": 1578693319979, "ltp": 36.0, "tv": 86.51, "trd": NaN, "batb": [[1, 30, 3.33], [2, 28, 10.71]], "batl": NaN}, {"timestamp": 1578693352837, "ltp": 36.0, "tv": 86.51, "trd": NaN, "batb": [[0, 36, 2.19], [1, 34, 4.42], [2, 30, 3.33]], "batl": NaN}, {"timestamp": 1578693406412, "ltp": 36.0, "tv": 86.51, "trd": NaN, "batb": [[1, 34, 1.41]], "batl": NaN}, {"timestamp": 1578693528232, "ltp": 38.0, "tv": 86.55, "trd": [[38, 0.04]], "batb": [[0, 38, 3.48], [1, 36, 2.19], [2, 34, 1.41]], "batl": [[0, 85, 2.11]]}, {"timestamp": 1578693803582, "ltp": 40.0, "tv": 86.64, "trd": [[40, 0.09]], "batb": [[0, 38, 3.87], [1, 36, 1.7]], "batl": [[0, 85, 2.06]]}, {"timestamp": 1578693806577, "ltp": 40.0, "tv": 86.64, "trd": NaN, "batb": NaN, "batl": [[0, 85, 2.26]]}, {"timestamp": 1578693809565, "ltp": 40.0, "tv": 86.64, "trd": NaN, "batb": [[1, 36, 1.75]], "batl": NaN}, {"timestamp": 1578693980553, "ltp": 40.0, "tv": 86.64, "trd": NaN, "batb": NaN, "batl": [[1, 120, 4.4]]}, {"timestamp": 1578693986360, "ltp": 40.0, "tv": 86.64, "trd": NaN, "batb": NaN, "batl": [[1, 120, 4.9]]}, {"timestamp": 1578693991972, "ltp": 40.0, "tv": 86.64, "trd": NaN, "batb": NaN, "batl": [[1, 120, 2.9]]}, {"timestamp": 1578693998978, "ltp": 40.0, "tv": 86.64, "trd": NaN, "batb": NaN, "batl": [[1, 120, 2.4]]}, {"timestamp": 1578693999074, "ltp": 40.0, "tv": 86.64, "trd": NaN, "batb": NaN, "batl": [[1, 120, 2.9]]}, {"timestamp": 1578694159410, "ltp": 40.0, "tv": 86.64, "trd": NaN, "batb": [[0, 38, 7.56]], "batl": NaN}, {"timestamp": 1578694199778, "ltp": 40.0, "tv": 86.64, "trd": NaN, "batb": [[1, 36, 1.78]], "batl": NaN}, {"timestamp": 1578694203885, "ltp": 40.0, "tv": 86.64, "trd": NaN, "batb": [[1, 36, 1.82]], "batl": NaN}, {"timestamp": 1578694218917, "ltp": 40.0, "tv": 86.64, "trd": NaN, "batb": [[0, 46, 13.04], [1, 38, 7.56], [2, 36, 1.82]], "batl": NaN}, {"timestamp": 1578694221594, "ltp": 40.0, "tv": 86.64, "trd": NaN, "batb": [[2, 36, 1.78]], "batl": NaN}, {"timestamp": 1578694222989, "ltp": 40.0, "tv": 86.64, "trd": NaN, "batb": [[1, 38, 7.6], [2, 36, 1.75]], "batl": NaN}, {"timestamp": 1578694223610, "ltp": 40.0, "tv": 86.64, "trd": NaN, "batb": [[1, 38, 3.93]], "batl": NaN}, {"timestamp": 1578694224689, "ltp": 40.0, "tv": 86.64, "trd": NaN, "batb": [[1, 38, 3.97], [2, 36, 1.7]], "batl": NaN}, {"timestamp": 1578694238439, "ltp": 46.0, "tv": 97.64, "trd": [[46, 11]], "batb": [[0, 46, 7.54]], "batl": NaN}, {"timestamp": 1578694261968, "ltp": 46.0, "tv": 97.64, "trd": NaN, "batb": [[1, 36, 2.19], [2, 34, 1.41]], "batl": NaN}, {"timestamp": 1578694349789, "ltp": 46.0, "tv": 97.64, "trd": NaN, "batb": [[0, 46, 7.91], [1, 36, 1.8]], "batl": NaN}, {"timestamp": 1578694354694, "ltp": 46.0, "tv": 97.64, "trd": NaN, "batb": NaN, "batl": [[0, 85, 2.06]]}, {"timestamp": 1578694382458, "ltp": 46.0, "tv": 97.64, "trd": NaN, "batb": [[0, 48, 3.37], [1, 46, 7.54], [2, 36, 1.8]], "batl": NaN}, {"timestamp": 1578694383960, "ltp": 46.0, "tv": 97.64, "trd": NaN, "batb": [[1, 46, 7.57], [2, 36, 1.76]], "batl": NaN}, {"timestamp": 1578694384736, "ltp": 46.0, "tv": 97.64, "trd": NaN, "batb": [[2, 36, 1.72]], "batl": NaN}, {"timestamp": 1578694385461, "ltp": 46.0, "tv": 97.64, "trd": NaN, "batb": [[1, 46, 7.6], [2, 36, 1.7]], "batl": NaN}, {"timestamp": 1578694509984, "ltp": 46.0, "tv": 97.64, "trd": NaN, "batb": [[0, 50, 2.81], [1, 48, 3.37], [2, 46, 7.6]], "batl": NaN}, {"timestamp": 1578694511985, "ltp": 46.0, "tv": 97.64, "trd": NaN, "batb": [[2, 46, 7.57]], "batl": NaN}, {"timestamp": 1578694512494, "ltp": 46.0, "tv": 97.64, "trd": NaN, "batb": [[1, 48, 3.4]], "batl": NaN}, {"timestamp": 1578694521622, "ltp": 46.0, "tv": 97.64, "trd": NaN, "batb": NaN, "batl": [[0, 80, 3.06], [1, 85, 2], [2, 120, 2.9]]}, {"timestamp": 1578694594318, "ltp": 46.0, "tv": 121.64, "trd": [[46, 22.6], [48, 6.8], [50, 5.61]], "batb": [[0, 46, 1.77], [1, 36, 1.7], [2, 34, 1.41]], "batl": NaN}, {"timestamp": 1578694600132, "ltp": 46.0, "tv": 121.64, "trd": NaN, "batb": [[1, 36, 1.75]], "batl": [[0, 80, 3.08]]}, {"timestamp": 1578694800921, "ltp": 46.0, "tv": 121.64, "trd": NaN, "batb": [[1, 36, 1.77]], "batl": NaN}, {"timestamp": 1578695121770, "ltp": 46.0, "tv": 121.64, "trd": NaN, "batb": [[1, 38, 2.83], [2, 36, 1.7]], "batl": NaN}, {"timestamp": 1578695625913, "ltp": 46.0, "tv": 121.64, "trd": NaN, "batb": NaN, "batl": [[0, 60, 3], [1, 80, 3.08], [2, 85, 2]]}, {"timestamp": 1578695652740, "ltp": 46.0, "tv": 121.64, "trd": NaN, "batb": NaN, "batl": [[0, 50, 3], [1, 60, 3], [2, 80, 3.08]]}, {"timestamp": 1578695655978, "ltp": 46.0, "tv": 121.64, "trd": NaN, "batb": [[0, 46, 3.3]], "batl": NaN}, {"timestamp": 1578695991996, "ltp": 46.0, "tv": 128.25, "trd": [[46, 29.21]], "batb": [[0, 38, 2.83], [1, 36, 1.7], [2, 34, 1.41]], "batl": NaN}, {"timestamp": 1578695996780, "ltp": 46.0, "tv": 128.25, "trd": NaN, "batb": NaN, "batl": [[1, 60, 3.02]]}, {"timestamp": 1578696025727, "ltp": 46.0, "tv": 128.25, "trd": NaN, "batb": [[0, 36, 1.77], [1, 34, 1.41], [2, 30, 3.33]], "batl": [[0, 50, 3.1], [2, 80, 3.02]]}, {"timestamp": 1578696045873, "ltp": 46.0, "tv": 128.25, "trd": NaN, "batb": [[0, 34, 1.47], [1, 32, 1.7]], "batl": NaN}, {"timestamp": 1578696062683, "ltp": 46.0, "tv": 128.25, "trd": NaN, "batb": [[0, 34, 2.57]], "batl": NaN}, {"timestamp": 1578696108488, "ltp": 46.0, "tv": 128.25, "trd": NaN, "batb": [[2, 30, 6.33]], "batl": NaN}, {"timestamp": 1578696902896, "ltp": 46.0, "tv": 128.25, "trd": NaN, "batb": NaN, "batl": [[0, 48, 2.1], [1, 50, 3], [2, 60, 3.02]]}, {"timestamp": 1578697203924, "ltp": 46.0, "tv": 128.22, "trd": [[21, 2.68], [25, 13.61], [26, 5.1], [27, 12.62], [29, 7.61], [30, 4.38], [36, 22.09], [46, 29.21], [50, 5.6]], "batb": [[1, 32, 1.7]], "batl": NaN}, {"timestamp": 1578698668357, "ltp": 44.0, "tv": 128.25, "trd": [[44, 0.04]], "batb": [[0, 34, 2.55]], "batl": [[0, 48, 3.08], [2, 55, 2.02]]}, {"timestamp": 1578698673972, "ltp": 44.0, "tv": 128.25, "trd": NaN, "batb": NaN, "batl": [[1, 50, 3.02]]}, {"timestamp": 1578698678691, "ltp": 40.0, "tv": 128.35, "trd": [[40, 0.18]], "batb": [[0, 34, 2.51]], "batl": [[0, 48, 3.03]]}, {"timestamp": 1578698681161, "ltp": 40.0, "tv": 128.35, "trd": NaN, "batb": NaN, "batl": [[0, 48, 3.07]]}, {"timestamp": 1578698817660, "ltp": 40.0, "tv": 128.35, "trd": NaN, "batb": [[1, 32, 2.25]], "batl": NaN}, {"timestamp": 1578698870917, "ltp": 40.0, "tv": 128.35, "trd": NaN, "batb": [[2, 30, 3.33]], "batl": NaN}, {"timestamp": 1578699741946, "ltp": 40.0, "tv": 128.35, "trd": NaN, "batb": NaN, "batl": [[0, 46, 6.7], [1, 48, 2.1], [2, 50, 3.02]]}, {"timestamp": 1578699756970, "ltp": 40.0, "tv": 128.35, "trd": NaN, "batb": NaN, "batl": [[0, 48, 8.57], [1, 50, 3.02], [2, 55, 2.02]]}, {"timestamp": 1578699772912, "ltp": 40.0, "tv": 128.35, "trd": NaN, "batb": NaN, "batl": [[0, 46, 6.7], [1, 48, 2.1], [2, 50, 3.02]]}, {"timestamp": 1578699788929, "ltp": 40.0, "tv": 128.35, "trd": NaN, "batb": NaN, "batl": [[0, 48, 3.07], [1, 50, 3.02], [2, 55, 2.02]]}, {"timestamp": 1578700269948, "ltp": 40.0, "tv": 128.35, "trd": NaN, "batb": NaN, "batl": [[0, 46, 6.7], [1, 48, 2.1], [2, 50, 3.02]]}, {"timestamp": 1578700285485, "ltp": 40.0, "tv": 128.35, "trd": NaN, "batb": NaN, "batl": [[0, 48, 8.57], [1, 50, 3.02], [2, 55, 2.02]]}, {"timestamp": 1578700301811, "ltp": 40.0, "tv": 128.35, "trd": NaN, "batb": NaN, "batl": [[0, 46, 6.7], [1, 48, 2.1], [2, 50, 3.02]]}, {"timestamp": 1578700317465, "ltp": 40.0, "tv": 128.35, "trd": NaN, "batb": NaN, "batl": [[0, 48, 8.57], [1, 50, 3.02], [2, 55, 2.02]]}, {"timestamp": 1578700333507, "ltp": 40.0, "tv": 128.35, "trd": NaN, "batb": NaN, "batl": [[0, 48, 3.07]]}, {"timestamp": 1578700428639, "ltp": 40.0, "tv": 128.35, "trd": NaN, "batb": NaN, "batl": [[0, 46, 6.7], [1, 48, 2.1], [2, 50, 3.02]]}, {"timestamp": 1578700444651, "ltp": 40.0, "tv": 128.35, "trd": NaN, "batb": NaN, "batl": [[0, 48, 8.57], [1, 50, 3.02], [2, 55, 2.02]]}, {"timestamp": 1578700460757, "ltp": 40.0, "tv": 128.35, "trd": NaN, "batb": NaN, "batl": [[0, 46, 6.7], [1, 48, 2.1], [2, 50, 3.02]]}, {"timestamp": 1578700476455, "ltp": 40.0, "tv": 128.35, "trd": NaN, "batb": NaN, "batl": [[0, 48, 8.57], [1, 50, 3.02], [2, 55, 2.02]]}, {"timestamp": 1578700492599, "ltp": 40.0, "tv": 128.35, "trd": NaN, "batb": NaN, "batl": [[0, 46, 6.7], [1, 48, 2.1], [2, 50, 3.02]]}, {"timestamp": 1578700508505, "ltp": 40.0, "tv": 128.35, "trd": NaN, "batb": NaN, "batl": [[0, 48, 8.57], [1, 50, 3.02], [2, 55, 2.02]]}, {"timestamp": 1578700524557, "ltp": 40.0, "tv": 128.35, "trd": NaN, "batb": NaN, "batl": [[0, 46, 6.7], [1, 48, 2.1], [2, 50, 3.02]]}, {"timestamp": 1578700540777, "ltp": 40.0, "tv": 128.35, "trd": NaN, "batb": NaN, "batl": [[0, 48, 8.57], [1, 50, 3.02], [2, 55, 2.02]]}, {"timestamp": 1578700556537, "ltp": 40.0, "tv": 128.35, "trd": NaN, "batb": NaN, "batl": [[0, 46, 6.7], [1, 48, 2.1], [2, 50, 3.02]]}, {"timestamp": 1578700572534, "ltp": 40.0, "tv": 128.35, "trd": NaN, "batb": NaN, "batl": [[0, 48, 8.57], [1, 50, 3.02], [2, 55, 2.02]]}, {"timestamp": 1578700587579, "ltp": 40.0, "tv": 128.35, "trd": NaN, "batb": NaN, "batl": [[0, 46, 6.7], [1, 48, 2.1], [2, 50, 3.02]]}, {"timestamp": 1578700603651, "ltp": 40.0, "tv": 128.35, "trd": NaN, "batb": NaN, "batl": [[0, 48, 8.57], [1, 50, 3.02], [2, 55, 2.02]]}, {"timestamp": 1578700619971, "ltp": 40.0, "tv": 128.35, "trd": NaN, "batb": NaN, "batl": [[0, 46, 6.7], [1, 48, 2.1], [2, 50, 3.02]]}, {"timestamp": 1578700635982, "ltp": 40.0, "tv": 128.35, "trd": NaN, "batb": NaN, "batl": [[0, 48, 8.57], [1, 50, 3.02], [2, 55, 2.02]]}, {"timestamp": 1578700651410, "ltp": 40.0, "tv": 128.35, "trd": NaN, "batb": NaN, "batl": [[0, 48, 3.07]]}, {"timestamp": 1578700763476, "ltp": 40.0, "tv": 128.35, "trd": NaN, "batb": NaN, "batl": [[0, 46, 6.7], [1, 48, 2.1], [2, 50, 3.02]]}, {"timestamp": 1578700778468, "ltp": 40.0, "tv": 128.35, "trd": NaN, "batb": NaN, "batl": [[0, 48, 3.07], [1, 50, 3.02], [2, 55, 2.02]]}, {"timestamp": 1578701577972, "ltp": 42.0, "tv": 129.65, "trd": [[42, 1.3]], "batb": NaN, "batl": [[0, 48, 2.42]]}, {"timestamp": 1578701580954, "ltp": 42.0, "tv": 129.65, "trd": NaN, "batb": [[0, 34, 5.46], [1, 32, 1.7]], "batl": NaN}, {"timestamp": 1578701582549, "ltp": 42.0, "tv": 130.21, "trd": [[42, 1.86]], "batb": NaN, "batl": [[0, 48, 2.14]]}, {"timestamp": 1578702003689, "ltp": 42.0, "tv": 130.21, "trd": NaN, "batb": [[1, 32, 1.77]], "batl": NaN}, {"timestamp": 1578702035825, "ltp": 34.0, "tv": 134.2, "trd": [[34, 15.42], [36, 23.06]], "batb": [[0, 34, 3.47]], "batl": NaN}, {"timestamp": 1578702050387, "ltp": 34.0, "tv": 134.2, "trd": NaN, "batb": NaN, "batl": [[0, 48, 2.21]]}, {"timestamp": 1578702923889, "ltp": 34.0, "tv": 134.2, "trd": NaN, "batb": NaN, "batl": [[0, 38, 1.7], [1, 48, 2.21], [2, 50, 3.02]]}, {"timestamp": 1578702956425, "ltp": 34.0, "tv": 141.13, "trd": [[34, 22.35]], "batb": [[0, 32, 1.77], [1, 30, 3.33], [2, 28, 10.71]], "batl": NaN}, {"timestamp": 1578702975500, "ltp": 34.0, "tv": 141.13, "trd": NaN, "batb": NaN, "batl": [[1, 46, 5.77], [2, 48, 2.17]]}, {"timestamp": 1578702993621, "ltp": 34.0, "tv": 141.13, "trd": NaN, "batb": NaN, "batl": [[1, 44, 6], [2, 48, 2.21]]}, {"timestamp": 1578702995788, "ltp": 34.0, "tv": 141.13, "trd": NaN, "batb": NaN, "batl": [[2, 48, 2.14]]}, {"timestamp": 1578702996097, "ltp": 34.0, "tv": 141.13, "trd": NaN, "batb": NaN, "batl": [[1, 44, 6.89]]}, {"timestamp": 1578703010538, "ltp": 34.0, "tv": 141.13, "trd": NaN, "batb": NaN, "batl": [[1, 48, 3.03], [2, 50, 3.02]]}, {"timestamp": 1578703021441, "ltp": 34.0, "tv": 141.13, "trd": NaN, "batb": NaN, "batl": [[0, 36, 1.7]]}, {"timestamp": 1578703045528, "ltp": 34.0, "tv": 141.13, "trd": NaN, "batb": NaN, "batl": [[1, 46, 6.67], [2, 48, 2.1]]}, {"timestamp": 1578703064953, "ltp": 34.0, "tv": 141.13, "trd": NaN, "batb": NaN, "batl": [[1, 48, 3.03], [2, 50, 3.02]]}, {"timestamp": 1578703116429, "ltp": 34.0, "tv": 141.13, "trd": NaN, "batb": NaN, "batl": [[1, 46, 6.67], [2, 48, 2.1]]}, {"timestamp": 1578703135584, "ltp": 34.0, "tv": 141.13, "trd": NaN, "batb": NaN, "batl": [[1, 44, 6.89], [2, 48, 2.14]]}, {"timestamp": 1578703154387, "ltp": 34.0, "tv": 141.13, "trd": NaN, "batb": NaN, "batl": [[1, 48, 3.03], [2, 50, 3.02]]}, {"timestamp": 1578703192874, "ltp": 34.0, "tv": 141.13, "trd": NaN, "batb": NaN, "batl": [[1, 46, 6.67], [2, 48, 2.1]]}, {"timestamp": 1578703211401, "ltp": 34.0, "tv": 141.13, "trd": NaN, "batb": NaN, "batl": [[1, 48, 3.03], [2, 50, 3.02]]}, {"timestamp": 1578703287519, "ltp": 34.0, "tv": 141.13, "trd": NaN, "batb": NaN, "batl": [[1, 46, 6.67], [2, 48, 2.1]]}, {"timestamp": 1578703307483, "ltp": 34.0, "tv": 141.13, "trd": NaN, "batb": NaN, "batl": [[1, 48, 3.03], [2, 50, 3.02]]}, {"timestamp": 1578703326921, "ltp": 34.0, "tv": 141.13, "trd": NaN, "batb": NaN, "batl": [[1, 46, 6.67], [2, 48, 2.1]]}, {"timestamp": 1578703345550, "ltp": 34.0, "tv": 141.13, "trd": NaN, "batb": NaN, "batl": [[1, 48, 3.03], [2, 50, 3.02]]}, {"timestamp": 1578703364488, "ltp": 34.0, "tv": 141.13, "trd": NaN, "batb": NaN, "batl": [[1, 46, 6.67], [2, 48, 2.1]]}, {"timestamp": 1578703383598, "ltp": 34.0, "tv": 141.13, "trd": NaN, "batb": NaN, "batl": [[1, 48, 3.03], [2, 50, 3.02]]}, {"timestamp": 1578703402529, "ltp": 34.0, "tv": 141.13, "trd": NaN, "batb": NaN, "batl": [[1, 46, 6.67], [2, 48, 2.1]]}, {"timestamp": 1578703421572, "ltp": 34.0, "tv": 141.13, "trd": NaN, "batb": NaN, "batl": [[1, 48, 3.03], [2, 50, 3.02]]}, {"timestamp": 1578703440484, "ltp": 34.0, "tv": 141.13, "trd": NaN, "batb": NaN, "batl": [[1, 46, 6.67], [2, 48, 2.1]]}, {"timestamp": 1578703459394, "ltp": 34.0, "tv": 141.13, "trd": NaN, "batb": NaN, "batl": [[1, 48, 3.03], [2, 50, 3.02]]}, {"timestamp": 1578703478429, "ltp": 34.0, "tv": 141.13, "trd": NaN, "batb": NaN, "batl": [[1, 46, 6.67], [2, 48, 2.1]]}, {"timestamp": 1578703498450, "ltp": 34.0, "tv": 141.13, "trd": NaN, "batb": NaN, "batl": [[1, 48, 3.03], [2, 50, 3.02]]}, {"timestamp": 1578703916960, "ltp": 32.0, "tv": 144.67, "trd": [[32, 9.54]], "batb": [[0, 30, 3.33], [1, 28, 10.71], [2, 27, 2]], "batl": [[0, 36, 2.49]]}, {"timestamp": 1578703922981, "ltp": 32.0, "tv": 144.67, "trd": NaN, "batb": NaN, "batl": [[1, 48, 2.2]]}, {"timestamp": 1578704637477, "ltp": 32.0, "tv": 144.67, "trd": NaN, "batb": NaN, "batl": [[0, 36, 1.7]]}, {"timestamp": 1578704650473, "ltp": 32.0, "tv": 144.67, "trd": NaN, "batb": NaN, "batl": [[1, 48, 3.02]]}, {"timestamp": 1578704877943, "ltp": 30.0, "tv": 151.33, "trd": [[30, 11.04]], "batb": [[0, 28, 10.71], [1, 27, 2], [2, 26, 7.69]], "batl": NaN}, {"timestamp": 1578705001987, "ltp": 30.0, "tv": 151.33, "trd": NaN, "batb": [[1, 27, 2.1]], "batl": NaN}, {"timestamp": 1578705838486, "ltp": 28.0, "tv": 163.51, "trd": [[28, 12.18]], "batb": [[0, 28, 4.62]], "batl": NaN}, {"timestamp": 1578706409807, "ltp": 28.0, "tv": 163.51, "trd": NaN, "batb": [[1, 27, 3.96]], "batl": NaN}, {"timestamp": 1578706677550, "ltp": 28.0, "tv": 163.51, "trd": NaN, "batb": [[0, 29, 1.77], [1, 28, 4.62], [2, 27, 3.96]], "batl": NaN}, {"timestamp": 1578706798664, "ltp": 29.0, "tv": 167.05, "trd": [[29, 11.16]], "batb": [[0, 28, 4.62], [1, 27, 3.96], [2, 26, 7.69]], "batl": [[0, 36, 2.49]]}, {"timestamp": 1578706817750, "ltp": 29.0, "tv": 167.05, "trd": NaN, "batb": NaN, "batl": [[1, 48, 2.2]]}, {"timestamp": 1578707519878, "ltp": 29.0, "tv": 167.05, "trd": NaN, "batb": NaN, "batl": [[0, 36, 1.7]]}, {"timestamp": 1578707532302, "ltp": 29.0, "tv": 167.05, "trd": NaN, "batb": NaN, "batl": [[1, 48, 3.02]]}, {"timestamp": 1578707625315, "ltp": 29.0, "tv": 167.05, "trd": NaN, "batb": [[1, 27, 3.89]], "batl": NaN}, {"timestamp": 1578707626240, "ltp": 29.0, "tv": 167.05, "trd": NaN, "batb": [[0, 28, 6.41], [1, 27, 2.1]], "batl": NaN}, {"timestamp": 1578721118940, "ltp": 29.0, "tv": 167.05, "trd": NaN, "batb": [[0, 29, 3.45], [1, 28, 6.41], [2, 27, 2.1]], "batl": NaN}, {"timestamp": 1578721140694, "ltp": 29.0, "tv": 167.05, "trd": NaN, "batb": [[0, 29, 5.18], [1, 28, 4.62]], "batl": NaN}, {"timestamp": 1578721198963, "ltp": 29.0, "tv": 167.05, "trd": NaN, "batb": [[0, 29, 5.21]], "batl": NaN}, {"timestamp": 1578721884000, "ltp": 36.0, "tv": 167.95, "trd": [[36, 23.96]], "batb": NaN, "batl": [[0, 36, 1.25]]}, {"timestamp": 1578722565647, "ltp": 36.0, "tv": 167.95, "trd": NaN, "batb": [[0, 29, 48.21]], "batl": NaN}, {"timestamp": 1578722986935, "ltp": 36.0, "tv": 167.95, "trd": NaN, "batb": [[0, 29, 48.88]], "batl": NaN}, {"timestamp": 1578723074837, "ltp": 36.0, "tv": 169.63, "trd": [[36, 25.64]], "batb": NaN, "batl": [[0, 46, 1.33], [1, 48, 2.1]]}, {"timestamp": 1578723075931, "ltp": 36.0, "tv": 169.63, "trd": NaN, "batb": [[0, 29, 49.07]], "batl": NaN}, {"timestamp": 1578723076550, "ltp": 38.0, "tv": 170.57, "trd": [[36, 26.46], [38, 0.16]], "batb": NaN, "batl": [[0, 48, 2.96], [1, 50, 3.02], [2, 55, 2.02]]}, {"timestamp": 1578723080879, "ltp": 38.0, "tv": 170.57, "trd": NaN, "batb": [[0, 29, 49.13]], "batl": NaN}, {"timestamp": 1578723082580, "ltp": 38.0, "tv": 170.57, "trd": NaN, "batb": [[0, 30, 1.02], [1, 29, 48.18], [2, 28, 4.62]], "batl": NaN}, {"timestamp": 1578723096954, "ltp": 38.0, "tv": 170.57, "trd": NaN, "batb": [[0, 30, 1.56]], "batl": [[0, 46, 1.21], [1, 48, 2.1], [2, 50, 3.02]]}, {"timestamp": 1578723298807, "ltp": 38.0, "tv": 170.57, "trd": NaN, "batb": [[0, 30, 3.93]], "batl": NaN}, {"timestamp": 1578723326464, "ltp": 38.0, "tv": 170.57, "trd": NaN, "batb": [[0, 30, 3.39]], "batl": [[0, 48, 2.96], [1, 50, 3.02], [2, 55, 2.02]]}, {"timestamp": 1578723880719, "ltp": 38.0, "tv": 170.57, "trd": NaN, "batb": [[1, 29, 48.12]], "batl": NaN}, {"timestamp": 1578723881496, "ltp": 38.0, "tv": 170.57, "trd": NaN, "batb": [[0, 30, 5.06], [1, 29, 46.45]], "batl": NaN}, {"timestamp": 1578724050969, "ltp": 38.0, "tv": 170.57, "trd": NaN, "batb": [[0, 30, 5.61]], "batl": NaN}, {"timestamp": 1578725227777, "ltp": 38.0, "tv": 170.57, "trd": NaN, "batb": [[0, 30, 10.72]], "batl": NaN}, {"timestamp": 1578725871969, "ltp": 38.0, "tv": 170.57, "trd": NaN, "batb": [[0, 32, 8.92], [1, 30, 10.04], [2, 29, 46.45]], "batl": NaN}, {"timestamp": 1578725882985, "ltp": 38.0, "tv": 170.57, "trd": NaN, "batb": [[0, 32, 9.51], [1, 30, 9.37]], "batl": NaN}, {"timestamp": 1578725983983, "ltp": 38.0, "tv": 170.57, "trd": NaN, "batb": [[0, 32, 52.51], [2, 29, 3.45]], "batl": NaN}, {"timestamp": 1578725987790, "ltp": 38.0, "tv": 170.57, "trd": NaN, "batb": [[0, 34, 13.45], [1, 32, 43.67], [2, 30, 4.26]], "batl": NaN}, {"timestamp": 1578726002801, "ltp": 38.0, "tv": 170.57, "trd": NaN, "batb": [[0, 36, 7.32], [1, 34, 5.7], [2, 32, 43.67]], "batl": NaN}, {"timestamp": 1578726014920, "ltp": 38.0, "tv": 170.57, "trd": NaN, "batb": [[0, 36, 7.85], [1, 34, 5.11]], "batl": NaN}, {"timestamp": 1578726019823, "ltp": 38.0, "tv": 170.57, "trd": NaN, "batb": [[1, 34, 7.11]], "batl": NaN}, {"timestamp": 1578726182003, "ltp": 38.0, "tv": 170.57, "trd": NaN, "batb": [[0, 36, 8.31], [2, 32, 43.13]], "batl": NaN}, {"timestamp": 1578726193771, "ltp": 38.0, "tv": 170.57, "trd": NaN, "batb": [[0, 38, 2.99], [1, 36, 7.32], [2, 34, 5.11]], "batl": NaN}, {"timestamp": 1578726194750, "ltp": 38.0, "tv": 170.57, "trd": NaN, "batb": [[0, 38, 2.46]], "batl": NaN}, {"timestamp": 1578726203821, "ltp": 38.0, "tv": 170.57, "trd": NaN, "batb": [[0, 38, 45.46]], "batl": NaN}, {"timestamp": 1578726212847, "ltp": 38.0, "tv": 170.57, "trd": NaN, "batb": [[0, 40, 4.26], [1, 38, 45.46], [2, 36, 7.32]], "batl": NaN}, {"timestamp": 1578726217866, "ltp": 38.0, "tv": 170.57, "trd": NaN, "batb": [[0, 42, 6.28], [1, 40, 4.26], [2, 38, 45.46]], "batl": NaN}, {"timestamp": 1578726249992, "ltp": 42.0, "tv": 183.13, "trd": [[42, 14.42]], "batb": [[0, 40, 4.26], [1, 38, 45.46], [2, 30, 2.02]], "batl": NaN}, {"timestamp": 1578726270783, "ltp": 42.0, "tv": 183.13, "trd": NaN, "batb": NaN, "batl": [[0, 46, 1.21], [1, 48, 2.1], [2, 50, 3.02]]}, {"timestamp": 1578726309943, "ltp": 42.0, "tv": 183.13, "trd": NaN, "batb": [[0, 42, 1.54], [1, 40, 4.26], [2, 38, 45.46]], "batl": NaN}, {"timestamp": 1578726449865, "ltp": 42.0, "tv": 183.13, "trd": NaN, "batb": [[0, 42, 1.96], [2, 38, 45]], "batl": NaN}, {"timestamp": 1578726505937, "ltp": 42.0, "tv": 183.13, "trd": NaN, "batb": NaN, "batl": [[0, 48, 2.96], [1, 50, 3.02], [2, 55, 2.02]]}, {"timestamp": 1578726905960, "ltp": 42.0, "tv": 183.13, "trd": NaN, "batb": [[1, 40, 5.52]], "batl": NaN}, {"timestamp": 1578727009895, "ltp": 40.0, "tv": 187.13, "trd": [[40, 0.27], [42, 18.34]], "batb": [[0, 40, 5.47], [1, 38, 45], [2, 29, 3.8]], "batl": NaN}, {"timestamp": 1578727015998, "ltp": 40.0, "tv": 187.13, "trd": NaN, "batb": [[1, 38, 47.78]], "batl": NaN}, {"timestamp": 1578727018835, "ltp": 40.0, "tv": 187.13, "trd": NaN, "batb": NaN, "batl": [[0, 46, 1.21], [1, 48, 2.1], [2, 50, 3.02]]}, {"timestamp": 1578727050762, "ltp": 40.0, "tv": 187.13, "trd": NaN, "batb": [[0, 42, 7.83], [1, 40, 5.47], [2, 38, 47.78]], "batl": NaN}, {"timestamp": 1578727061982, "ltp": 40.0, "tv": 187.13, "trd": NaN, "batb": [[1, 40, 8.62]], "batl": NaN}, {"timestamp": 1578727112766, "ltp": 40.0, "tv": 187.13, "trd": NaN, "batb": [[0, 42, 50.83], [2, 38, 4.78]], "batl": NaN}, {"timestamp": 1578727121953, "ltp": 40.0, "tv": 187.13, "trd": NaN, "batb": [[0, 44, 4.26], [1, 42, 50.83], [2, 40, 8.62]], "batl": NaN}, {"timestamp": 1578727122981, "ltp": 40.0, "tv": 187.13, "trd": NaN, "batb": [[2, 40, 4.41]], "batl": NaN}, {"timestamp": 1578727210869, "ltp": 44.0, "tv": 195.64, "trd": [[44, 8.55]], "batb": [[0, 42, 50.83], [1, 40, 1.26], [2, 30, 6.66]], "batl": NaN}, {"timestamp": 1578727211951, "ltp": 44.0, "tv": 195.64, "trd": NaN, "batb": NaN, "batl": [[0, 48, 2.96], [1, 50, 3.02], [2, 55, 2.02]]}, {"timestamp": 1578727232937, "ltp": 44.0, "tv": 195.64, "trd": NaN, "batb": [[2, 36, 2]], "batl": NaN}, {"timestamp": 1578727289932, "ltp": 44.0, "tv": 195.64, "trd": NaN, "batb": [[0, 44, 2.58], [1, 42, 50.83], [2, 40, 1.26]], "batl": NaN}, {"timestamp": 1578727640756, "ltp": 44.0, "tv": 195.64, "trd": NaN, "batb": [[0, 42, 50.83], [1, 40, 1.26], [2, 30, 9.17]], "batl": NaN}, {"timestamp": 1578727697001, "ltp": 44.0, "tv": 195.64, "trd": NaN, "batb": [[2, 36, 2]], "batl": NaN}, {"timestamp": 1578727868966, "ltp": 44.0, "tv": 195.64, "trd": NaN, "batb": [[0, 42, 7.83], [2, 38, 43]], "batl": NaN}, {"timestamp": 1578727884905, "ltp": 44.0, "tv": 195.64, "trd": NaN, "batb": [[1, 40, 4.41]], "batl": NaN}, {"timestamp": 1578727907948, "ltp": 44.0, "tv": 195.64, "trd": NaN, "batb": [[1, 40, 6.41]], "batl": NaN}, {"timestamp": 1578727931975, "ltp": 44.0, "tv": 195.64, "trd": NaN, "batb": [[1, 40, 3.26]], "batl": NaN}, {"timestamp": 1578727932954, "ltp": 44.0, "tv": 195.64, "trd": NaN, "batb": [[0, 42, 50.83], [2, 30, 3.5]], "batl": NaN}, {"timestamp": 1578727941991, "ltp": 44.0, "tv": 195.64, "trd": NaN, "batb": [[1, 40, 6.41]], "batl": NaN}, {"timestamp": 1578728163964, "ltp": 44.0, "tv": 195.64, "trd": NaN, "batb": [[0, 44, 2], [1, 42, 50.83], [2, 40, 4.41]], "batl": NaN}, {"timestamp": 1578728168972, "ltp": 44.0, "tv": 195.64, "trd": NaN, "batb": [[2, 40, 1.26]], "batl": NaN}, {"timestamp": 1578728171838, "ltp": 44.0, "tv": 199.64, "trd": [[44, 12.55]], "batb": [[0, 42, 50.83], [1, 40, 1.26], [2, 30, 6.57]], "batl": [[0, 46, 1.41], [1, 48, 2.1], [2, 50, 3.02]]}, {"timestamp": 1578728178558, "ltp": 44.0, "tv": 199.64, "trd": NaN, "batb": [[2, 30, 9.72]], "batl": NaN}, {"timestamp": 1578728263845, "ltp": 44.0, "tv": 199.64, "trd": NaN, "batb": [[1, 40, 1.2]], "batl": NaN}, {"timestamp": 1578728264563, "ltp": 44.0, "tv": 199.64, "trd": NaN, "batb": [[0, 42, 52.03], [1, 30, 9.72], [2, 29, 3.45]], "batl": NaN}, {"timestamp": 1578728508712, "ltp": 44.0, "tv": 199.64, "trd": NaN, "batb": NaN, "batl": [[0, 46, 4.41]]}, {"timestamp": 1578728596879, "ltp": 44.0, "tv": 199.64, "trd": NaN, "batb": [[0, 42, 9.03], [1, 32, 43.13], [2, 30, 9.59]], "batl": NaN}, {"timestamp": 1578728626925, "ltp": 44.0, "tv": 199.64, "trd": NaN, "batb": [[1, 34, 6.31], [2, 32, 43.13]], "batl": NaN}, {"timestamp": 1578728656476, "ltp": 44.0, "tv": 199.64, "trd": NaN, "batb": [[1, 34, 9.46]], "batl": NaN}, {"timestamp": 1578728742969, "ltp": 44.0, "tv": 200.75, "trd": [[44, 13.66]], "batb": [[0, 44, 1.07], [1, 42, 9.03], [2, 34, 9.46]], "batl": [[0, 46, 3.86]]}, {"timestamp": 1578728765921, "ltp": 42.0, "tv": 206.75, "trd": [[42, 22.2], [44, 15.8]], "batb": [[0, 42, 7.1], [1, 34, 9.46], [2, 32, 43.13]], "batl": NaN}, {"timestamp": 1578728826706, "ltp": 42.0, "tv": 214.75, "trd": [[42, 30.2]], "batb": [[0, 42, 3.1]], "batl": NaN}, {"timestamp": 1578728833996, "ltp": 42.0, "tv": 214.75, "trd": NaN, "batb": [[1, 34, 6.31]], "batl": NaN}, {"timestamp": 1578728845943, "ltp": 42.0, "tv": 214.75, "trd": NaN, "batb": [[1, 34, 9.46]], "batl": NaN}, {"timestamp": 1578728927921, "ltp": 42.0, "tv": 218.55, "trd": [[42, 34]], "batb": [[0, 34, 6.31], [1, 32, 46.68], [2, 29, 3.67]], "batl": NaN}, {"timestamp": 1578728930918, "ltp": 42.0, "tv": 218.55, "trd": NaN, "batb": [[0, 32, 46.68], [1, 29, 3.67], [2, 27, 4.79]], "batl": NaN}, {"timestamp": 1578728932928, "ltp": 42.0, "tv": 218.55, "trd": NaN, "batb": [[0, 32, 43.13], [1, 30, 3.89], [2, 29, 6.44]], "batl": NaN}, {"timestamp": 1578728940924, "ltp": 42.0, "tv": 218.55, "trd": NaN, "batb": [[0, 32, 43.6]], "batl": NaN}, {"timestamp": 1578729007957, "ltp": 32.0, "tv": 226.56, "trd": [[32, 16.6], [34, 23.29]], "batb": [[0, 32, 39.6]], "batl": NaN}, {"timestamp": 1578729008943, "ltp": 32.0, "tv": 226.56, "trd": NaN, "batb": NaN, "batl": [[0, 46, 3.92]]}, {"timestamp": 1578729013822, "ltp": 32.0, "tv": 226.56, "trd": NaN, "batb": NaN, "batl": [[0, 46, 3.97]]}, {"timestamp": 1578729029952, "ltp": 32.0, "tv": 226.56, "trd": NaN, "batb": [[0, 32, 40.07]], "batl": NaN}, {"timestamp": 1578729079945, "ltp": 32.0, "tv": 226.56, "trd": NaN, "batb": [[0, 32, 39.6]], "batl": [[0, 46, 4.34]]}, {"timestamp": 1578729188558, "ltp": 32.0, "tv": 234.56, "trd": [[32, 24.6]], "batb": [[0, 32, 35.6]], "batl": NaN}, {"timestamp": 1578729200862, "ltp": 32.0, "tv": 234.56, "trd": NaN, "batb": [[1, 29, 6.67], [2, 27, 2.1]], "batl": NaN}, {"timestamp": 1578729201788, "ltp": 32.0, "tv": 234.56, "trd": NaN, "batb": [[1, 30, 3.89], [2, 29, 6.44]], "batl": NaN}, {"timestamp": 1578729219827, "ltp": 32.0, "tv": 234.56, "trd": NaN, "batb": [[1, 29, 6.67], [2, 27, 2.1]], "batl": NaN}, {"timestamp": 1578729221991, "ltp": 32.0, "tv": 234.56, "trd": NaN, "batb": [[1, 29, 9.28]], "batl": NaN}, {"timestamp": 1578729241678, "ltp": 32.0, "tv": 234.56, "trd": NaN, "batb": [[1, 30, 3.89], [2, 29, 9.06]], "batl": NaN}, {"timestamp": 1578729339779, "ltp": 32.0, "tv": 234.56, "trd": NaN, "batb": [[0, 32, 36.11]], "batl": NaN}, {"timestamp": 1578729340968, "ltp": 32.0, "tv": 234.56, "trd": NaN, "batb": [[1, 29, 9.28], [2, 27, 2.1]], "batl": NaN}, {"timestamp": 1578729341993, "ltp": 32.0, "tv": 240.56, "trd": [[32, 29.58], [34, 24.31]], "batb": [[0, 32, 33.11]], "batl": NaN}, {"timestamp": 1578729374730, "ltp": 32.0, "tv": 248.56, "trd": [[32, 37.58]], "batb": [[0, 32, 29.11]], "batl": NaN}, {"timestamp": 1578729382913, "ltp": 32.0, "tv": 248.56, "trd": NaN, "batb": [[1, 30, 3.89], [2, 29, 9.06]], "batl": NaN}, {"timestamp": 1578729505958, "ltp": 32.0, "tv": 248.56, "trd": NaN, "batb": NaN, "batl": [[2, 50, 5.02]]}, {"timestamp": 1578729551919, "ltp": 32.0, "tv": 256.56, "trd": [[32, 45.58]], "batb": [[0, 32, 25.11]], "batl": NaN}, {"timestamp": 1578729606891, "ltp": 32.0, "tv": 256.56, "trd": NaN, "batb": [[1, 30, 5.55]], "batl": NaN}, {"timestamp": 1578729731985, "ltp": 32.0, "tv": 260.56, "trd": [[32, 49.58]], "batb": [[0, 32, 23.11]], "batl": NaN}, {"timestamp": 1578729938979, "ltp": 32.0, "tv": 260.56, "trd": NaN, "batb": NaN, "batl": [[0, 42, 2.11], [1, 46, 4.22], [2, 50, 5.12]]}, {"timestamp": 1578729955403, "ltp": 32.0, "tv": 260.56, "trd": NaN, "batb": [[1, 30, 5.46]], "batl": NaN}, {"timestamp": 1578729957943, "ltp": 32.0, "tv": 260.56, "trd": NaN, "batb": [[0, 32, 24.68], [1, 30, 3.89]], "batl": [[1, 46, 3.41]]}, {"timestamp": 1578729958830, "ltp": 32.0, "tv": 260.56, "trd": NaN, "batb": NaN, "batl": [[0, 42, 3.01]]}, {"timestamp": 1578729979931, "ltp": 32.0, "tv": 260.56, "trd": NaN, "batb": [[0, 34, 3.14], [1, 32, 24.68], [2, 30, 3.89]], "batl": NaN}, {"timestamp": 1578729980856, "ltp": 32.0, "tv": 260.56, "trd": NaN, "batb": NaN, "batl": [[2, 48, 1.03]]}, {"timestamp": 1578729983858, "ltp": 32.0, "tv": 260.56, "trd": NaN, "batb": NaN, "batl": [[1, 46, 3.04]]}, {"timestamp": 1578729998889, "ltp": 32.0, "tv": 260.56, "trd": NaN, "batb": NaN, "batl": [[1, 46, 4.06]]}, {"timestamp": 1578730117943, "ltp": 34.0, "tv": 264.56, "trd": [[34, 28.31]], "batb": [[0, 34, 1.14]], "batl": [[1, 46, 3.04], [2, 50, 5.12]]}, {"timestamp": 1578730118823, "ltp": 34.0, "tv": 264.56, "trd": NaN, "batb": NaN, "batl": [[1, 46, 4.06]]}, {"timestamp": 1578730119862, "ltp": 34.0, "tv": 264.56, "trd": NaN, "batb": [[2, 30, 6.72]], "batl": NaN}, {"timestamp": 1578730133966, "ltp": 34.0, "tv": 264.56, "trd": NaN, "batb": NaN, "batl": [[0, 42, 3.42]]}, {"timestamp": 1578730157994, "ltp": 34.0, "tv": 264.56, "trd": NaN, "batb": [[0, 34, 1.65]], "batl": NaN}, {"timestamp": 1578730204928, "ltp": 34.0, "tv": 264.56, "trd": NaN, "batb": NaN, "batl": [[1, 46, 3.04], [2, 48, 1.03]]}, {"timestamp": 1578730231994, "ltp": 34.0, "tv": 264.56, "trd": NaN, "batb": NaN, "batl": [[1, 46, 4.06]]}, {"timestamp": 1578730232982, "ltp": 42.0, "tv": 266.08, "trd": [[38, 0.27], [40, 1.2], [42, 34.48]], "batb": NaN, "batl": [[0, 42, 2.66]]}, {"timestamp": 1578730234978, "ltp": 42.0, "tv": 266.08, "trd": NaN, "batb": [[1, 32, 24.81]], "batl": NaN}, {"timestamp": 1578730238984, "ltp": 40.0, "tv": 266.9, "trd": [[40, 2.02]], "batb": [[0, 34, 1.67]], "batl": NaN}, {"timestamp": 1578730239661, "ltp": 42.0, "tv": 267.76, "trd": [[42, 35.34]], "batb": NaN, "batl": [[0, 42, 2.23]]}, {"timestamp": 1578730245963, "ltp": 42.0, "tv": 268.3, "trd": [[42, 35.88]], "batb": NaN, "batl": [[0, 42, 1.96]]}, {"timestamp": 1578730246956, "ltp": 32.0, "tv": 272.3, "trd": [[32, 50.24], [34, 31.62], [40, 2.06]], "batb": [[0, 32, 24.48], [1, 30, 6.72], [2, 29, 3.45]], "batl": NaN}, {"timestamp": 1578730247997, "ltp": 32.0, "tv": 272.3, "trd": NaN, "batb": NaN, "batl": [[1, 46, 3.04], [2, 50, 5.12]]}, {"timestamp": 1578730255975, "ltp": 42.0, "tv": 272.92, "trd": [[42, 36.5]], "batb": NaN, "batl": [[0, 42, 1.65]]}, {"timestamp": 1578730264696, "ltp": 42.0, "tv": 272.92, "trd": NaN, "batb": NaN, "batl": [[1, 46, 3.41]]}, {"timestamp": 1578730368804, "ltp": 42.0, "tv": 272.92, "trd": NaN, "batb": NaN, "batl": [[1, 46, 3.04]]}, {"timestamp": 1578730388954, "ltp": 42.0, "tv": 274.08, "trd": [[42, 37.66]], "batb": NaN, "batl": [[0, 42, 1.07]]}, {"timestamp": 1578730402938, "ltp": 42.0, "tv": 276.21, "trd": [[42, 39.79]], "batb": NaN, "batl": [[0, 46, 3.04], [1, 50, 5.12], [2, 55, 2.02]]}, {"timestamp": 1578730478824, "ltp": 46.0, "tv": 276.33, "trd": [[46, 29.32]], "batb": NaN, "batl": [[0, 46, 2.98]]}, {"timestamp": 1578730480002, "ltp": 46.0, "tv": 276.33, "trd": NaN, "batb": [[0, 32, 24.53]], "batl": NaN}, {"timestamp": 1578730496935, "ltp": 46.0, "tv": 276.33, "trd": NaN, "batb": [[0, 32, 24.7]], "batl": NaN}, {"timestamp": 1578730606942, "ltp": 46.0, "tv": 276.59, "trd": [[46, 29.58]], "batb": NaN, "batl": [[0, 46, 2.85]]}, {"timestamp": 1578730609840, "ltp": 46.0, "tv": 277.63, "trd": [[46, 30.62]], "batb": NaN, "batl": [[0, 46, 2.33]]}, {"timestamp": 1578730653807, "ltp": 46.0, "tv": 277.63, "trd": NaN, "batb": [[1, 29, 3.67], [2, 27, 2.1]], "batl": NaN}, {"timestamp": 1578730654733, "ltp": 46.0, "tv": 277.63, "trd": NaN, "batb": [[1, 30, 3.89], [2, 29, 7.12]], "batl": NaN}, {"timestamp": 1578730691866, "ltp": 32.0, "tv": 281.63, "trd": [[32, 53.8], [34, 32.05]], "batb": [[0, 32, 22.7]], "batl": NaN}, {"timestamp": 1578730692844, "ltp": 32.0, "tv": 281.63, "trd": NaN, "batb": NaN, "batl": [[0, 46, 2.37]]}, {"timestamp": 1578730704969, "ltp": 32.0, "tv": 281.63, "trd": NaN, "batb": NaN, "batl": [[1, 50, 7.12]]}, {"timestamp": 1578730717001, "ltp": 32.0, "tv": 281.63, "trd": NaN, "batb": NaN, "batl": [[0, 46, 2.74]]}, {"timestamp": 1578730770943, "ltp": 32.0, "tv": 285.63, "trd": [[32, 57.8]], "batb": [[0, 32, 20.7]], "batl": NaN}, {"timestamp": 1578730787575, "ltp": 44.0, "tv": 286.12, "trd": [[44, 16.29]], "batb": NaN, "batl": [[0, 46, 2.49]]}, {"timestamp": 1578730792986, "ltp": 44.0, "tv": 286.12, "trd": NaN, "batb": [[0, 32, 20.75]], "batl": NaN}, {"timestamp": 1578730802904, "ltp": 44.0, "tv": 286.12, "trd": NaN, "batb": [[0, 32, 22.39]], "batl": NaN}, {"timestamp": 1578730838967, "ltp": 44.0, "tv": 286.12, "trd": NaN, "batb": [[0, 34, 7.81], [1, 32, 22.35], [2, 30, 3.89]], "batl": [[1, 50, 7.98]]}, {"timestamp": 1578730843939, "ltp": 44.0, "tv": 286.12, "trd": NaN, "batb": [[1, 32, 25.07]], "batl": NaN}, {"timestamp": 1578730860973, "ltp": 44.0, "tv": 286.12, "trd": NaN, "batb": NaN, "batl": [[1, 48, 1.03], [2, 50, 7.88]]}, {"timestamp": 1578730895716, "ltp": 44.0, "tv": 286.12, "trd": NaN, "batb": NaN, "batl": [[0, 46, 3.51]]}, {"timestamp": 1578730896995, "ltp": 44.0, "tv": 286.12, "trd": NaN, "batb": [[0, 32, 25.12], [1, 30, 3.89], [2, 29, 3.45]], "batl": [[0, 46, 2.49], [1, 50, 7.12], [2, 55, 2.02]]}, {"timestamp": 1578730898996, "ltp": 44.0, "tv": 286.12, "trd": NaN, "batb": [[0, 32, 22.39], [1, 30, 6.72]], "batl": NaN}, {"timestamp": 1578730910918, "ltp": 44.0, "tv": 286.12, "trd": NaN, "batb": [[0, 34, 7.81], [1, 32, 22.35], [2, 30, 6.72]], "batl": [[1, 48, 1.03], [2, 50, 7.02]]}, {"timestamp": 1578730912868, "ltp": 44.0, "tv": 286.12, "trd": NaN, "batb": [[1, 32, 24.98]], "batl": NaN}, {"timestamp": 1578730917846, "ltp": 44.0, "tv": 286.12, "trd": NaN, "batb": NaN, "batl": [[0, 46, 4.49]]}, {"timestamp": 1578730924996, "ltp": 44.0, "tv": 286.12, "trd": NaN, "batb": [[0, 32, 25.02], [1, 30, 6.72], [2, 29, 3.45]], "batl": [[1, 50, 7.12], [2, 55, 2.02]]}, {"timestamp": 1578730926855, "ltp": 44.0, "tv": 286.12, "trd": NaN, "batb": [[0, 32, 22.39]], "batl": NaN}, {"timestamp": 1578730932876, "ltp": 44.0, "tv": 286.12, "trd": NaN, "batb": NaN, "batl": [[0, 46, 5.79]]}, {"timestamp": 1578730941001, "ltp": 44.0, "tv": 286.12, "trd": NaN, "batb": NaN, "batl": [[0, 46, 3.79]]}, {"timestamp": 1578730953512, "ltp": 44.0, "tv": 286.12, "trd": NaN, "batb": [[0, 34, 7.81], [1, 32, 22.35], [2, 30, 6.72]], "batl": NaN}, {"timestamp": 1578730959944, "ltp": 44.0, "tv": 286.12, "trd": NaN, "batb": NaN, "batl": [[0, 46, 4.81]]}, {"timestamp": 1578730960923, "ltp": 44.0, "tv": 286.12, "trd": NaN, "batb": [[1, 32, 25.07]], "batl": NaN}, {"timestamp": 1578730973731, "ltp": 44.0, "tv": 286.12, "trd": NaN, "batb": NaN, "batl": [[0, 46, 3.79], [1, 48, 1.03], [2, 50, 7.88]]}, {"timestamp": 1578730993997, "ltp": 44.0, "tv": 286.12, "trd": NaN, "batb": [[0, 34, 9.36]], "batl": NaN}, {"timestamp": 1578731014928, "ltp": 44.0, "tv": 286.12, "trd": NaN, "batb": NaN, "batl": [[0, 46, 3.63], [1, 48, 3.66]]}, {"timestamp": 1578731035968, "ltp": 34.0, "tv": 290.12, "trd": [[34, 36.05]], "batb": [[0, 34, 7.36]], "batl": NaN}, {"timestamp": 1578731038949, "ltp": 34.0, "tv": 290.12, "trd": NaN, "batb": NaN, "batl": [[0, 46, 4]]}, {"timestamp": 1578731040443, "ltp": 34.0, "tv": 290.12, "trd": NaN, "batb": NaN, "batl": [[0, 46, 4.04]]}, {"timestamp": 1578731052769, "ltp": 34.0, "tv": 290.12, "trd": NaN, "batb": NaN, "batl": [[0, 46, 4.54]]}, {"timestamp": 1578731057490, "ltp": 34.0, "tv": 290.12, "trd": NaN, "batb": NaN, "batl": [[0, 46, 3.24]]}, {"timestamp": 1578731098967, "ltp": 34.0, "tv": 290.12, "trd": NaN, "batb": NaN, "batl": [[1, 48, 2.73]]}, {"timestamp": 1578731099952, "ltp": 44.0, "tv": 290.94, "trd": [[44, 17.11]], "batb": NaN, "batl": [[0, 46, 2.83]]}, {"timestamp": 1578731104946, "ltp": 44.0, "tv": 290.94, "trd": NaN, "batb": [[0, 34, 7.41]], "batl": NaN}, {"timestamp": 1578731112967, "ltp": 44.0, "tv": 290.94, "trd": NaN, "batb": NaN, "batl": [[1, 48, 3.66]]}, {"timestamp": 1578731117979, "ltp": 44.0, "tv": 290.94, "trd": NaN, "batb": [[0, 34, 1.6]], "batl": NaN}, {"timestamp": 1578731123778, "ltp": 44.0, "tv": 290.94, "trd": NaN, "batb": [[1, 32, 22.35]], "batl": NaN}, {"timestamp": 1578731135995, "ltp": 44.0, "tv": 290.94, "trd": NaN, "batb": NaN, "batl": [[1, 48, 2.73]]}, {"timestamp": 1578731203988, "ltp": 44.0, "tv": 290.94, "trd": NaN, "batb": NaN, "batl": [[1, 48, 3.66]]}, {"timestamp": 1578731228960, "ltp": 44.0, "tv": 290.94, "trd": NaN, "batb": [[0, 34, 7.41]], "batl": NaN}, {"timestamp": 1578731237940, "ltp": 44.0, "tv": 290.94, "trd": NaN, "batb": [[2, 29, 3.67]], "batl": NaN}, {"timestamp": 1578731238664, "ltp": 44.0, "tv": 290.94, "trd": NaN, "batb": [[1, 32, 25.9]], "batl": NaN}, {"timestamp": 1578731244965, "ltp": 44.0, "tv": 290.94, "trd": NaN, "batb": [[0, 34, 1.6], [2, 30, 4.34]], "batl": NaN}, {"timestamp": 1578731246969, "ltp": 44.0, "tv": 290.94, "trd": NaN, "batb": [[1, 32, 22.35], [2, 30, 7.21]], "batl": NaN}, {"timestamp": 1578731274984, "ltp": 44.0, "tv": 290.94, "trd": NaN, "batb": NaN, "batl": [[0, 46, 3.85]]}, {"timestamp": 1578731278905, "ltp": 44.0, "tv": 290.94, "trd": NaN, "batb": [[0, 34, 7.41]], "batl": NaN}, {"timestamp": 1578731280916, "ltp": 44.0, "tv": 290.94, "trd": NaN, "batb": [[1, 32, 24.52]], "batl": NaN}, {"timestamp": 1578731292817, "ltp": 44.0, "tv": 290.94, "trd": NaN, "batb": NaN, "batl": [[0, 46, 3.97], [1, 48, 3.56]]}, {"timestamp": 1578731294932, "ltp": 44.0, "tv": 290.94, "trd": NaN, "batb": [[0, 34, 1.6]], "batl": NaN}, {"timestamp": 1578731297938, "ltp": 44.0, "tv": 290.94, "trd": NaN, "batb": [[1, 32, 22.35]], "batl": NaN}, {"timestamp": 1578731329886, "ltp": 44.0, "tv": 290.94, "trd": NaN, "batb": NaN, "batl": [[1, 50, 8.81], [2, 55, 2.02]]}, {"timestamp": 1578731335918, "ltp": 44.0, "tv": 290.94, "trd": NaN, "batb": NaN, "batl": [[0, 46, 2.95]]}, {"timestamp": 1578731343920, "ltp": 44.0, "tv": 290.94, "trd": NaN, "batb": [[0, 34, 7.41]], "batl": NaN}, {"timestamp": 1578731346919, "ltp": 44.0, "tv": 290.94, "trd": NaN, "batb": [[1, 32, 24.59]], "batl": NaN}, {"timestamp": 1578731353901, "ltp": 34.0, "tv": 294.94, "trd": [[34, 40.05]], "batb": [[0, 34, 5.41]], "batl": NaN}, {"timestamp": 1578731356953, "ltp": 34.0, "tv": 294.94, "trd": NaN, "batb": NaN, "batl": [[0, 46, 2.99]]}, {"timestamp": 1578731357936, "ltp": 34.0, "tv": 294.94, "trd": NaN, "batb": NaN, "batl": [[1, 50, 7.88]]}, {"timestamp": 1578731359945, "ltp": 34.0, "tv": 294.94, "trd": NaN, "batb": [[0, 32, 24.59], [1, 30, 7.21], [2, 29, 3.45]], "batl": [[1, 50, 7.02]]}, {"timestamp": 1578731362957, "ltp": 34.0, "tv": 294.94, "trd": NaN, "batb": [[0, 32, 22.35]], "batl": NaN}, {"timestamp": 1578731363945, "ltp": 32.0, "tv": 304.94, "trd": [[32, 67.8]], "batb": [[0, 32, 17.35]], "batl": NaN}, {"timestamp": 1578731389665, "ltp": 32.0, "tv": 304.94, "trd": NaN, "batb": [[0, 32, 17.28]], "batl": [[0, 46, 2.95]]}, {"timestamp": 1578731419961, "ltp": 32.0, "tv": 304.94, "trd": NaN, "batb": NaN, "batl": [[0, 46, 3.01]]}, {"timestamp": 1578731438987, "ltp": 32.0, "tv": 304.94, "trd": NaN, "batb": [[0, 34, 5.41], [1, 32, 17.28], [2, 30, 7.21]], "batl": [[0, 46, 4.03]]}, {"timestamp": 1578731442972, "ltp": 32.0, "tv": 304.94, "trd": NaN, "batb": NaN, "batl": [[0, 46, 3.01], [1, 50, 7.95]]}, {"timestamp": 1578731451811, "ltp": 32.0, "tv": 304.94, "trd": NaN, "batb": NaN, "batl": [[0, 46, 4.03]]}, {"timestamp": 1578731454911, "ltp": 32.0, "tv": 304.94, "trd": NaN, "batb": [[0, 32, 17.28], [1, 30, 7.21], [2, 29, 3.45]], "batl": [[0, 46, 3.01], [1, 50, 7.02]]}, {"timestamp": 1578731566896, "ltp": 32.0, "tv": 304.94, "trd": NaN, "batb": [[0, 34, 5.41], [1, 32, 17.28], [2, 30, 7.21]], "batl": [[1, 50, 7.88]]}, {"timestamp": 1578731581931, "ltp": 32.0, "tv": 304.94, "trd": NaN, "batb": [[0, 36, 3.45], [1, 34, 5.41], [2, 32, 17.28]], "batl": NaN}, {"timestamp": 1578731582602, "ltp": 32.0, "tv": 304.94, "trd": NaN, "batb": [[1, 32, 17.28], [2, 30, 4.34]], "batl": [[0, 44, 1.29], [1, 46, 2.83], [2, 50, 8.81]]}, {"timestamp": 1578731594916, "ltp": 32.0, "tv": 304.94, "trd": NaN, "batb": [[1, 32, 19.99]], "batl": NaN}, {"timestamp": 1578731603970, "ltp": 32.0, "tv": 304.94, "trd": NaN, "batb": [[0, 36, 4.91]], "batl": NaN}, {"timestamp": 1578731605935, "ltp": 32.0, "tv": 304.94, "trd": NaN, "batb": [[1, 34, 2.65], [2, 32, 19.99]], "batl": NaN}, {"timestamp": 1578731606972, "ltp": 32.0, "tv": 304.94, "trd": NaN, "batb": NaN, "batl": [[2, 48, 3.78]]}, {"timestamp": 1578731607951, "ltp": 32.0, "tv": 304.94, "trd": NaN, "batb": [[1, 34, 5.29]], "batl": NaN}, {"timestamp": 1578731641917, "ltp": 32.0, "tv": 304.94, "trd": NaN, "batb": NaN, "batl": [[0, 46, 3.01], [1, 48, 2.85], [2, 50, 7.02]]}, {"timestamp": 1578731642907, "ltp": 32.0, "tv": 304.94, "trd": NaN, "batb": NaN, "batl": [[0, 44, 1.29], [1, 46, 2.83], [2, 48, 2.85]]}, {"timestamp": 1578731651955, "ltp": 32.0, "tv": 304.94, "trd": NaN, "batb": NaN, "batl": [[2, 50, 7.02]]}, {"timestamp": 1578731654941, "ltp": 32.0, "tv": 304.94, "trd": NaN, "batb": NaN, "batl": [[0, 46, 3.01], [1, 50, 7.02], [2, 55, 2.02]]}]}, {"runnerId": 22492304, "odds": [{"timestamp": 1578670018546, "ltp": 2.4, "tv": 4.0, "trd": [[2.4, 4]], "batb": [[0, 2.4, 18], [1, 2.32, 1.99], [2, 2.3, 23.7]], "batl": [[0, 2.58, 70], [1, 2.68, 2], [2, 2.78, 2]]}, {"timestamp": 1578670031506, "ltp": 2.4, "tv": 4.0, "trd": NaN, "batb": [[0, 2.42, 8.26], [1, 2.4, 18], [2, 2.32, 1.99]], "batl": NaN}, {"timestamp": 1578670043909, "ltp": 2.4, "tv": 4.0, "trd": NaN, "batb": NaN, "batl": [[0, 2.5, 2], [1, 2.58, 70], [2, 2.68, 2]]}, {"timestamp": 1578670152359, "ltp": 2.4, "tv": 4.0, "trd": NaN, "batb": [[0, 2.44, 1.99], [1, 2.42, 8.26], [2, 2.4, 18]], "batl": NaN}, {"timestamp": 1578670398751, "ltp": 2.4, "tv": 4.0, "trd": NaN, "batb": NaN, "batl": [[1, 2.58, 7]]}, {"timestamp": 1578670411064, "ltp": 2.42, "tv": 10.0, "trd": [[2.42, 2.02], [2.44, 3.98]], "batb": [[0, 2.42, 7.25], [1, 2.4, 18], [2, 2.3, 12]], "batl": NaN}, {"timestamp": 1578670980973, "ltp": 2.42, "tv": 10.0, "trd": NaN, "batb": NaN, "batl": [[1, 2.56, 5.57], [2, 2.58, 7]]}, {"timestamp": 1578671366631, "ltp": 2.42, "tv": 10.0, "trd": NaN, "batb": [[0, 2.42, 107.25]], "batl": NaN}, {"timestamp": 1578671481864, "ltp": 2.42, "tv": 10.0, "trd": NaN, "batb": [[0, 2.44, 3], [1, 2.42, 107.25], [2, 2.4, 18]], "batl": NaN}, {"timestamp": 1578671946922, "ltp": 2.42, "tv": 10.0, "trd": NaN, "batb": [[2, 2.3, 12]], "batl": NaN}, {"timestamp": 1578672062581, "ltp": 2.44, "tv": 16.0, "trd": [[2.44, 9.98]], "batb": [[0, 2.42, 107.25], [1, 2.3, 12], [2, 2.26, 6.31]], "batl": [[0, 2.56, 5.57], [1, 2.58, 7], [2, 2.68, 2]]}, {"timestamp": 1578672069261, "ltp": 2.44, "tv": 16.0, "trd": NaN, "batb": [[1, 2.36, 3], [2, 2.3, 12]], "batl": NaN}, {"timestamp": 1578672083704, "ltp": 2.44, "tv": 16.0, "trd": NaN, "batb": NaN, "batl": [[0, 2.54, 2.88], [1, 2.56, 5.57], [2, 2.58, 7]]}, {"timestamp": 1578672222944, "ltp": 2.44, "tv": 16.0, "trd": NaN, "batb": NaN, "batl": [[0, 2.46, 2], [1, 2.54, 2.88], [2, 2.56, 5.57]]}, {"timestamp": 1578672231561, "ltp": 2.44, "tv": 16.0, "trd": NaN, "batb": NaN, "batl": [[0, 2.48, 2]]}, {"timestamp": 1578672240502, "ltp": 2.42, "tv": 56.0, "trd": [[2.42, 42.02]], "batb": [[0, 2.42, 87.25]], "batl": NaN}, {"timestamp": 1578672251992, "ltp": 2.42, "tv": 56.0, "trd": NaN, "batb": [[1, 2.3, 12], [2, 2.26, 6.31]], "batl": NaN}, {"timestamp": 1578672253596, "ltp": 2.42, "tv": 56.0, "trd": NaN, "batb": NaN, "batl": [[2, 2.58, 7]]}, {"timestamp": 1578672254216, "ltp": 2.42, "tv": 56.0, "trd": NaN, "batb": NaN, "batl": [[1, 2.52, 3.06], [2, 2.54, 2.88]]}, {"timestamp": 1578672261108, "ltp": 2.42, "tv": 56.0, "trd": NaN, "batb": NaN, "batl": [[2, 2.58, 7]]}, {"timestamp": 1578672292854, "ltp": 2.42, "tv": 56.0, "trd": NaN, "batb": NaN, "batl": [[1, 2.58, 7], [2, 2.68, 2]]}, {"timestamp": 1578672293018, "ltp": 2.42, "tv": 56.0, "trd": NaN, "batb": NaN, "batl": [[1, 2.56, 3.06], [2, 2.58, 7]]}, {"timestamp": 1578672424483, "ltp": 2.42, "tv": 56.0, "trd": NaN, "batb": [[1, 2.32, 90], [2, 2.3, 12]], "batl": NaN}, {"timestamp": 1578672427389, "ltp": 2.42, "tv": 56.0, "trd": NaN, "batb": [[1, 2.34, 6], [2, 2.32, 90]], "batl": NaN}, {"timestamp": 1578672454539, "ltp": 2.42, "tv": 56.0, "trd": NaN, "batb": [[0, 2.36, 87.25]], "batl": NaN}, {"timestamp": 1578672463024, "ltp": 2.42, "tv": 56.0, "trd": NaN, "batb": NaN, "batl": [[1, 2.54, 2.88], [2, 2.56, 3.06]]}, {"timestamp": 1578672467964, "ltp": 2.42, "tv": 56.0, "trd": NaN, "batb": NaN, "batl": [[2, 2.58, 7]]}, {"timestamp": 1578672468658, "ltp": 2.42, "tv": 56.0, "trd": NaN, "batb": NaN, "batl": [[1, 2.52, 3.06], [2, 2.54, 2.88]]}, {"timestamp": 1578672491976, "ltp": 2.42, "tv": 56.0, "trd": NaN, "batb": NaN, "batl": [[2, 2.58, 7]]}, {"timestamp": 1578672492229, "ltp": 2.42, "tv": 56.0, "trd": NaN, "batb": NaN, "batl": [[2, 2.56, 2.86]]}, {"timestamp": 1578672505602, "ltp": 2.42, "tv": 56.0, "trd": NaN, "batb": NaN, "batl": [[1, 2.56, 6.6], [2, 2.58, 7]]}, {"timestamp": 1578672604847, "ltp": 2.42, "tv": 56.0, "trd": NaN, "batb": [[0, 2.38, 2.55], [1, 2.36, 87.25], [2, 2.34, 6]], "batl": NaN}, {"timestamp": 1578672608236, "ltp": 2.42, "tv": 56.0, "trd": NaN, "batb": [[0, 2.38, 3.27]], "batl": NaN}, {"timestamp": 1578672644838, "ltp": 2.42, "tv": 56.0, "trd": NaN, "batb": [[0, 2.4, 5.73], [1, 2.38, 3.27], [2, 2.36, 87.25]], "batl": NaN}, {"timestamp": 1578672816361, "ltp": 2.42, "tv": 56.0, "trd": NaN, "batb": [[0, 2.4, 92.98], [2, 2.34, 6]], "batl": NaN}, {"timestamp": 1578672935442, "ltp": 2.42, "tv": 56.0, "trd": NaN, "batb": [[0, 2.4, 99.01]], "batl": NaN}, {"timestamp": 1578672963189, "ltp": 2.42, "tv": 56.0, "trd": NaN, "batb": [[0, 2.42, 2.55], [1, 2.4, 99.01], [2, 2.38, 3.27]], "batl": NaN}, {"timestamp": 1578673062346, "ltp": 2.42, "tv": 56.0, "trd": NaN, "batb": [[1, 2.4, 11.76], [2, 2.38, 90.52]], "batl": NaN}, {"timestamp": 1578673074355, "ltp": 2.42, "tv": 56.0, "trd": NaN, "batb": [[0, 2.42, 89.8], [2, 2.38, 3.27]], "batl": NaN}, {"timestamp": 1578673552996, "ltp": 2.42, "tv": 56.0, "trd": NaN, "batb": [[0, 2.42, 95.82], [1, 2.4, 5.73]], "batl": NaN}, {"timestamp": 1578673781197, "ltp": 2.42, "tv": 73.99, "trd": [[2.42, 60.02]], "batb": [[0, 2.42, 86.82]], "batl": NaN}, {"timestamp": 1578674012378, "ltp": 2.42, "tv": 73.99, "trd": NaN, "batb": NaN, "batl": [[0, 2.46, 2], [1, 2.48, 2], [2, 2.56, 6.6]]}, {"timestamp": 1578674013110, "ltp": 2.42, "tv": 73.99, "trd": NaN, "batb": NaN, "batl": [[0, 2.48, 2], [1, 2.56, 6.6], [2, 2.58, 7]]}, {"timestamp": 1578674503936, "ltp": 2.48, "tv": 77.99, "trd": [[2.48, 4]], "batb": [[0, 2.48, 2], [1, 2.42, 86.82], [2, 2.4, 5.73]], "batl": [[0, 2.56, 6.6], [1, 2.58, 7], [2, 2.68, 2]]}, {"timestamp": 1578674507374, "ltp": 2.48, "tv": 77.99, "trd": NaN, "batb": [[1, 2.44, 6], [2, 2.42, 86.82]], "batl": NaN}, {"timestamp": 1578674644004, "ltp": 2.48, "tv": 77.99, "trd": NaN, "batb": [[1, 2.46, 2.55], [2, 2.44, 6]], "batl": NaN}, {"timestamp": 1578674788653, "ltp": 2.48, "tv": 77.99, "trd": NaN, "batb": [[0, 2.48, 8.02]], "batl": NaN}, {"timestamp": 1578674823599, "ltp": 2.48, "tv": 77.99, "trd": NaN, "batb": [[0, 2.5, 2.55], [1, 2.48, 8.02], [2, 2.46, 2.55]], "batl": NaN}, {"timestamp": 1578674826775, "ltp": 2.48, "tv": 77.99, "trd": NaN, "batb": [[0, 2.5, 8.74]], "batl": NaN}, {"timestamp": 1578674847992, "ltp": 2.48, "tv": 77.99, "trd": NaN, "batb": NaN, "batl": [[0, 2.56, 2.86]]}, {"timestamp": 1578674903488, "ltp": 2.5, "tv": 95.49, "trd": [[2.5, 17.49]], "batb": [[0, 2.48, 8.02], [1, 2.46, 2.55], [2, 2.44, 6]], "batl": [[0, 2.5, 16.25], [1, 2.56, 2.86], [2, 2.58, 7]]}, {"timestamp": 1578675002767, "ltp": 2.48, "tv": 111.54, "trd": [[2.48, 20.05]], "batb": [[0, 2.46, 2.55], [1, 2.44, 6], [2, 2.42, 80.8]], "batl": [[0, 2.48, 16.58], [1, 2.5, 16.25], [2, 2.56, 2.86]]}, {"timestamp": 1578675006944, "ltp": 2.48, "tv": 111.54, "trd": NaN, "batb": NaN, "batl": [[0, 2.5, 16.25], [1, 2.56, 2.86], [2, 2.58, 7]]}, {"timestamp": 1578675013946, "ltp": 2.46, "tv": 115.54, "trd": [[2.46, 4]], "batb": [[0, 2.44, 6.55], [1, 2.42, 80.8], [2, 2.38, 2.55]], "batl": NaN}, {"timestamp": 1578675014568, "ltp": 2.46, "tv": 116.64, "trd": [[2.46, 5.1]], "batb": [[0, 2.44, 6]], "batl": NaN}, {"timestamp": 1578675018986, "ltp": 2.44, "tv": 128.64, "trd": [[2.44, 21.98]], "batb": [[0, 2.42, 80.8], [1, 2.38, 2.55], [2, 2.36, 3]], "batl": NaN}, {"timestamp": 1578675020846, "ltp": 2.44, "tv": 128.64, "trd": NaN, "batb": NaN, "batl": [[0, 2.48, 6], [1, 2.5, 16.25], [2, 2.56, 2.86]]}, {"timestamp": 1578675026651, "ltp": 2.42, "tv": 145.8, "trd": [[2.42, 77.18]], "batb": [[0, 2.42, 72.22]], "batl": NaN}, {"timestamp": 1578675030167, "ltp": 2.42, "tv": 145.8, "trd": NaN, "batb": [[2, 2.34, 6]], "batl": NaN}, {"timestamp": 1578675050694, "ltp": 2.42, "tv": 149.8, "trd": [[2.42, 81.18]], "batb": [[0, 2.42, 70.22]], "batl": NaN}, {"timestamp": 1578675063498, "ltp": 2.42, "tv": 149.8, "trd": NaN, "batb": [[0, 2.44, 2.55], [1, 2.42, 70.22], [2, 2.38, 2.55]], "batl": NaN}, {"timestamp": 1578675091650, "ltp": 2.42, "tv": 149.8, "trd": NaN, "batb": NaN, "batl": [[1, 2.5, 116.25]]}, {"timestamp": 1578675116354, "ltp": 2.44, "tv": 154.9, "trd": [[2.44, 27.08]], "batb": [[0, 2.42, 70.22], [1, 2.38, 2.55], [2, 2.34, 6]], "batl": [[0, 2.48, 6.45]]}, {"timestamp": 1578675117384, "ltp": 2.44, "tv": 154.9, "trd": NaN, "batb": NaN, "batl": [[0, 2.44, 6.45]]}, {"timestamp": 1578675124986, "ltp": 2.44, "tv": 154.9, "trd": NaN, "batb": [[1, 2.36, 5.55]], "batl": NaN}, {"timestamp": 1578675259729, "ltp": 2.44, "tv": 154.9, "trd": NaN, "batb": NaN, "batl": [[1, 2.5, 126.25]]}, {"timestamp": 1578675368607, "ltp": 2.42, "tv": 160.9, "trd": [[2.42, 87.18]], "batb": [[0, 2.42, 67.22]], "batl": NaN}, {"timestamp": 1578675378983, "ltp": 2.42, "tv": 160.9, "trd": NaN, "batb": [[1, 2.36, 2.55]], "batl": NaN}, {"timestamp": 1578675401927, "ltp": 2.42, "tv": 160.9, "trd": NaN, "batb": [[0, 2.42, 73.86]], "batl": NaN}, {"timestamp": 1578675482750, "ltp": 2.42, "tv": 160.9, "trd": NaN, "batb": NaN, "batl": [[2, 2.52, 2]]}, {"timestamp": 1578675591586, "ltp": 2.42, "tv": 160.9, "trd": NaN, "batb": [[0, 2.42, 6.64], [1, 2.36, 69.77]], "batl": NaN}, {"timestamp": 1578675594871, "ltp": 2.42, "tv": 160.9, "trd": NaN, "batb": [[1, 2.38, 6], [2, 2.36, 69.77]], "batl": NaN}, {"timestamp": 1578675604485, "ltp": 2.42, "tv": 160.94, "trd": [[2.42, 87.18], [2.44, 27.08], [2.46, 5.1], [2.48, 20.07], [2.5, 17.51]], "batb": [[0, 2.42, 6.65], [1, 2.4, 2.55], [2, 2.38, 6]], "batl": NaN}, {"timestamp": 1578675861716, "ltp": 2.42, "tv": 174.24, "trd": [[2.42, 100.48]], "batb": [[0, 2.4, 2.55], [1, 2.38, 6], [2, 2.36, 69.77]], "batl": [[0, 2.42, 10.96], [1, 2.44, 6.45], [2, 2.5, 126.25]]}, {"timestamp": 1578675868437, "ltp": 2.4, "tv": 179.34, "trd": [[2.4, 9.1]], "batb": [[0, 2.38, 6], [1, 2.36, 69.77], [2, 2.34, 6]], "batl": [[0, 2.4, 3.45], [1, 2.42, 10.96], [2, 2.5, 126.7]]}, {"timestamp": 1578675903955, "ltp": 2.4, "tv": 184.45, "trd": [[2.4, 14.21]], "batb": NaN, "batl": [[0, 2.42, 11.86], [1, 2.5, 126.7], [2, 2.52, 2]]}, {"timestamp": 1578675904682, "ltp": 2.4, "tv": 186.25, "trd": [[2.4, 16.01]], "batb": NaN, "batl": [[0, 2.42, 10.96]]}, {"timestamp": 1578675962838, "ltp": 2.4, "tv": 186.25, "trd": NaN, "batb": [[0, 2.4, 2.55], [1, 2.38, 6], [2, 2.36, 69.77]], "batl": NaN}, {"timestamp": 1578676018861, "ltp": 2.42, "tv": 208.17, "trd": [[2.42, 122.4]], "batb": [[0, 2.4, 2.59]], "batl": [[0, 2.5, 126.7], [1, 2.52, 2], [2, 2.56, 2.86]]}, {"timestamp": 1578676021523, "ltp": 2.42, "tv": 208.17, "trd": NaN, "batb": NaN, "batl": [[2, 2.58, 7]]}, {"timestamp": 1578676038954, "ltp": 2.42, "tv": 208.17, "trd": NaN, "batb": [[0, 2.42, 1.74], [1, 2.4, 2.55], [2, 2.38, 6]], "batl": NaN}, {"timestamp": 1578676054786, "ltp": 2.5, "tv": 460.17, "trd": [[2.44, 27.98], [2.5, 268.61]], "batb": NaN, "batl": [[0, 2.52, 2.7], [1, 2.58, 7], [2, 2.68, 2]]}, {"timestamp": 1578676058986, "ltp": 2.5, "tv": 460.17, "trd": NaN, "batb": NaN, "batl": [[1, 2.56, 3.06], [2, 2.58, 7]]}, {"timestamp": 1578676060413, "ltp": 2.5, "tv": 460.17, "trd": NaN, "batb": NaN, "batl": [[0, 2.5, 3.63], [1, 2.52, 2], [2, 2.56, 3.06]]}, {"timestamp": 1578676274433, "ltp": 2.5, "tv": 460.17, "trd": NaN, "batb": NaN, "batl": [[0, 2.48, 2], [1, 2.5, 3.63], [2, 2.52, 2]]}, {"timestamp": 1578676278836, "ltp": 2.5, "tv": 460.17, "trd": NaN, "batb": NaN, "batl": [[0, 2.46, 2], [1, 2.48, 2], [2, 2.5, 3.63]]}, {"timestamp": 1578676285726, "ltp": 2.5, "tv": 460.17, "trd": NaN, "batb": NaN, "batl": [[0, 2.44, 2], [1, 2.46, 2], [2, 2.48, 2]]}, {"timestamp": 1578676289008, "ltp": 2.42, "tv": 463.65, "trd": [[2.42, 125.89]], "batb": [[0, 2.4, 2.55], [1, 2.38, 6], [2, 2.36, 72.77]], "batl": [[0, 2.44, 2.26]]}, {"timestamp": 1578676296357, "ltp": 2.42, "tv": 463.65, "trd": NaN, "batb": [[2, 2.36, 69.77]], "batl": NaN}, {"timestamp": 1578676559495, "ltp": 2.4, "tv": 468.76, "trd": [[2.4, 21.11]], "batb": [[0, 2.38, 6], [1, 2.36, 69.77], [2, 2.34, 6]], "batl": NaN}, {"timestamp": 1578676563457, "ltp": 2.4, "tv": 468.76, "trd": NaN, "batb": [[0, 2.4, 2.55], [1, 2.38, 6], [2, 2.36, 69.77]], "batl": NaN}, {"timestamp": 1578676639482, "ltp": 2.4, "tv": 468.76, "trd": NaN, "batb": [[2, 2.36, 2.55]], "batl": NaN}, {"timestamp": 1578676640481, "ltp": 2.4, "tv": 468.76, "trd": NaN, "batb": [[1, 2.36, 2.55], [2, 2.34, 73.22]], "batl": NaN}, {"timestamp": 1578676645856, "ltp": 2.44, "tv": 473.28, "trd": [[2.42, 126.41], [2.44, 31.98]], "batb": [[0, 2.44, 297.74], [1, 2.4, 2.55], [2, 2.36, 69.77]], "batl": [[0, 2.46, 2], [1, 2.48, 2], [2, 2.5, 3.63]]}, {"timestamp": 1578676647577, "ltp": 2.44, "tv": 473.28, "trd": NaN, "batb": [[2, 2.36, 72.77]], "batl": NaN}, {"timestamp": 1578676649979, "ltp": 2.5, "tv": 488.54, "trd": [[2.46, 9.1], [2.48, 24.07], [2.5, 275.87]], "batb": [[0, 2.5, 290.11]], "batl": [[0, 2.52, 2], [1, 2.56, 3.06], [2, 2.58, 7]]}, {"timestamp": 1578676651657, "ltp": 2.5, "tv": 488.54, "trd": NaN, "batb": [[2, 2.38, 6]], "batl": NaN}, {"timestamp": 1578676657204, "ltp": 2.52, "tv": 492.54, "trd": [[2.52, 4]], "batb": NaN, "batl": [[0, 2.56, 3.06], [1, 2.58, 7], [2, 2.68, 2]]}, {"timestamp": 1578676661071, "ltp": 2.52, "tv": 492.54, "trd": NaN, "batb": [[2, 2.38, 9]], "batl": NaN}, {"timestamp": 1578676684608, "ltp": 2.52, "tv": 492.54, "trd": NaN, "batb": NaN, "batl": [[0, 2.58, 7], [1, 2.68, 2], [2, 2.78, 2]]}, {"timestamp": 1578676923497, "ltp": 2.5, "tv": 592.54, "trd": [[2.5, 375.87]], "batb": [[0, 2.5, 240.11]], "batl": NaN}, {"timestamp": 1578676935004, "ltp": 2.5, "tv": 592.54, "trd": NaN, "batb": [[2, 2.38, 6]], "batl": NaN}, {"timestamp": 1578676997210, "ltp": 2.5, "tv": 592.54, "trd": NaN, "batb": [[0, 2.52, 3], [1, 2.5, 240.11], [2, 2.4, 2.55]], "batl": NaN}, {"timestamp": 1578677002980, "ltp": 2.5, "tv": 592.54, "trd": NaN, "batb": [[2, 2.46, 2]], "batl": NaN}, {"timestamp": 1578677134845, "ltp": 2.5, "tv": 592.54, "trd": NaN, "batb": [[0, 2.52, 4.7]], "batl": NaN}, {"timestamp": 1578677162803, "ltp": 2.5, "tv": 592.54, "trd": NaN, "batb": [[2, 2.46, 4]], "batl": NaN}, {"timestamp": 1578677308382, "ltp": 2.5, "tv": 592.54, "trd": NaN, "batb": [[0, 2.52, 11.7]], "batl": NaN}, {"timestamp": 1578677328802, "ltp": 2.58, "tv": 606.54, "trd": [[2.58, 14]], "batb": [[0, 2.58, 8], [1, 2.52, 11.7], [2, 2.5, 240.11]], "batl": [[0, 2.68, 2], [1, 2.78, 2], [2, 2.88, 2]]}, {"timestamp": 1578677337992, "ltp": 2.58, "tv": 606.54, "trd": NaN, "batb": [[2, 2.5, 243.11]], "batl": NaN}, {"timestamp": 1578677339610, "ltp": 2.58, "tv": 606.54, "trd": NaN, "batb": [[0, 2.6, 3], [1, 2.58, 8], [2, 2.52, 11.7]], "batl": NaN}, {"timestamp": 1578677342642, "ltp": 2.58, "tv": 606.54, "trd": NaN, "batb": [[0, 2.6, 4.7], [2, 2.52, 10]], "batl": NaN}, {"timestamp": 1578677362907, "ltp": 2.58, "tv": 606.54, "trd": NaN, "batb": [[0, 2.6, 1.7]], "batl": NaN}, {"timestamp": 1578677381032, "ltp": 2.58, "tv": 606.54, "trd": NaN, "batb": NaN, "batl": [[1, 2.76, 4.04], [2, 2.78, 2]]}, {"timestamp": 1578677395941, "ltp": 2.58, "tv": 606.54, "trd": NaN, "batb": [[2, 2.54, 4]], "batl": NaN}, {"timestamp": 1578677408868, "ltp": 2.68, "tv": 610.54, "trd": [[2.68, 4]], "batb": [[0, 2.68, 13], [1, 2.6, 1.7], [2, 2.58, 8]], "batl": [[0, 2.76, 4.04], [1, 2.78, 2], [2, 2.88, 2]]}, {"timestamp": 1578677416803, "ltp": 2.68, "tv": 610.54, "trd": NaN, "batb": NaN, "batl": [[0, 2.74, 33], [1, 2.76, 4.04], [2, 2.78, 2]]}, {"timestamp": 1578677456755, "ltp": 2.68, "tv": 610.54, "trd": NaN, "batb": NaN, "batl": [[0, 2.76, 4.04], [1, 2.78, 35], [2, 2.88, 2]]}, {"timestamp": 1578677471856, "ltp": 2.68, "tv": 610.54, "trd": NaN, "batb": [[0, 2.68, 14.7], [1, 2.58, 8], [2, 2.54, 4]], "batl": NaN}, {"timestamp": 1578677479768, "ltp": 2.68, "tv": 610.54, "trd": NaN, "batb": NaN, "batl": [[1, 2.78, 2], [2, 2.86, 33]]}, {"timestamp": 1578677491593, "ltp": 2.68, "tv": 610.54, "trd": NaN, "batb": [[0, 2.68, 1.7], [1, 2.54, 4], [2, 2.52, 10]], "batl": NaN}, {"timestamp": 1578677494662, "ltp": 2.68, "tv": 610.54, "trd": NaN, "batb": NaN, "batl": [[2, 2.84, 19.14]]}, {"timestamp": 1578677495963, "ltp": 2.68, "tv": 610.54, "trd": NaN, "batb": NaN, "batl": [[0, 2.78, 2], [1, 2.84, 19.14], [2, 2.86, 33]]}, {"timestamp": 1578677496791, "ltp": 2.68, "tv": 610.54, "trd": NaN, "batb": NaN, "batl": [[1, 2.82, 3.94], [2, 2.84, 19.14]]}, {"timestamp": 1578677502895, "ltp": 2.68, "tv": 610.54, "trd": NaN, "batb": [[1, 2.54, 7]], "batl": NaN}, {"timestamp": 1578677507507, "ltp": 2.68, "tv": 610.54, "trd": NaN, "batb": NaN, "batl": [[1, 2.8, 33], [2, 2.82, 3.94]]}, {"timestamp": 1578677527952, "ltp": 2.78, "tv": 614.54, "trd": [[2.78, 4]], "batb": [[0, 2.78, 8], [1, 2.68, 1.7], [2, 2.54, 7]], "batl": [[0, 2.8, 33], [1, 2.82, 3.94], [2, 2.84, 19.14]]}, {"timestamp": 1578677535042, "ltp": 2.78, "tv": 614.54, "trd": NaN, "batb": [[2, 2.62, 3]], "batl": NaN}, {"timestamp": 1578677551548, "ltp": 2.78, "tv": 614.54, "trd": NaN, "batb": [[0, 2.68, 1.7], [1, 2.62, 3], [2, 2.54, 4]], "batl": NaN}, {"timestamp": 1578677554966, "ltp": 2.78, "tv": 614.54, "trd": NaN, "batb": NaN, "batl": [[0, 2.78, 4], [1, 2.8, 33]]}, {"timestamp": 1578677565787, "ltp": 2.78, "tv": 614.54, "trd": NaN, "batb": [[0, 2.64, 1.7]], "batl": NaN}, {"timestamp": 1578677570467, "ltp": 2.78, "tv": 614.54, "trd": NaN, "batb": NaN, "batl": [[0, 2.76, 4], [1, 2.78, 4], [2, 2.8, 33]]}, {"timestamp": 1578677584877, "ltp": 2.76, "tv": 622.54, "trd": [[2.76, 8]], "batb": [[0, 2.76, 6], [1, 2.64, 1.7], [2, 2.62, 3]], "batl": [[0, 2.78, 4], [1, 2.8, 33], [2, 2.84, 19.14]]}, {"timestamp": 1578677589698, "ltp": 2.76, "tv": 622.54, "trd": NaN, "batb": NaN, "batl": [[0, 2.8, 33], [1, 2.84, 19.14], [2, 2.88, 2]]}, {"timestamp": 1578677609819, "ltp": 2.76, "tv": 644.54, "trd": [[2.76, 20], [2.8, 10]], "batb": [[0, 2.64, 1.7], [1, 2.62, 3], [2, 2.54, 4]], "batl": [[0, 2.8, 28]]}, {"timestamp": 1578677615914, "ltp": 2.76, "tv": 644.54, "trd": NaN, "batb": [[0, 2.64, 5.88]], "batl": [[0, 2.82, 28]]}, {"timestamp": 1578677630540, "ltp": 2.76, "tv": 644.54, "trd": NaN, "batb": NaN, "batl": [[0, 2.8, 3.06], [1, 2.82, 28], [2, 2.84, 19.14]]}, {"timestamp": 1578677644851, "ltp": 2.76, "tv": 644.54, "trd": NaN, "batb": NaN, "batl": [[0, 2.78, 2], [1, 2.8, 3.06], [2, 2.82, 28]]}, {"timestamp": 1578677749970, "ltp": 2.76, "tv": 644.54, "trd": NaN, "batb": [[2, 2.54, 7]], "batl": NaN}, {"timestamp": 1578677794692, "ltp": 2.76, "tv": 644.54, "trd": NaN, "batb": NaN, "batl": [[0, 2.68, 3.86], [1, 2.78, 2], [2, 2.8, 3.06]]}, {"timestamp": 1578677801093, "ltp": 2.76, "tv": 644.54, "trd": NaN, "batb": NaN, "batl": [[2, 2.82, 28]]}, {"timestamp": 1578677805798, "ltp": 2.76, "tv": 644.54, "trd": NaN, "batb": NaN, "batl": [[1, 2.8, 2]]}, {"timestamp": 1578677824235, "ltp": 2.64, "tv": 656.3, "trd": [[2.64, 11.76]], "batb": [[0, 2.62, 3], [1, 2.54, 3], [2, 2.52, 3]], "batl": [[0, 2.64, 4.12], [1, 2.68, 3.86], [2, 2.8, 2]]}, {"timestamp": 1578677827751, "ltp": 2.64, "tv": 656.3, "trd": NaN, "batb": [[1, 2.52, 6], [2, 2.5, 240.11]], "batl": NaN}, {"timestamp": 1578677832831, "ltp": 2.64, "tv": 656.3, "trd": NaN, "batb": [[0, 2.52, 6], [1, 2.5, 243.11], [2, 2.46, 4]], "batl": NaN}, {"timestamp": 1578677852278, "ltp": 2.64, "tv": 656.3, "trd": NaN, "batb": NaN, "batl": [[0, 2.62, 19.1], [1, 2.64, 4.12], [2, 2.68, 3.86]]}, {"timestamp": 1578677883907, "ltp": 2.64, "tv": 656.3, "trd": NaN, "batb": [[0, 2.54, 2.55], [1, 2.52, 6], [2, 2.5, 243.11]], "batl": NaN}, {"timestamp": 1578677920446, "ltp": 2.64, "tv": 656.3, "trd": NaN, "batb": NaN, "batl": [[0, 2.64, 4.12], [1, 2.68, 3.86], [2, 2.82, 28]]}, {"timestamp": 1578677921334, "ltp": 2.64, "tv": 656.3, "trd": NaN, "batb": NaN, "batl": [[1, 2.66, 5.8], [2, 2.68, 3.86]]}, {"timestamp": 1578677929673, "ltp": 2.64, "tv": 656.3, "trd": NaN, "batb": [[0, 2.54, 5.55]], "batl": NaN}, {"timestamp": 1578677932542, "ltp": 2.64, "tv": 656.3, "trd": NaN, "batb": [[0, 2.58, 3], [1, 2.54, 2.55], [2, 2.52, 6]], "batl": NaN}, {"timestamp": 1578677933427, "ltp": 2.64, "tv": 656.3, "trd": NaN, "batb": [[0, 2.54, 2.55], [1, 2.52, 6], [2, 2.5, 243.11]], "batl": NaN}, {"timestamp": 1578677961781, "ltp": 2.64, "tv": 656.3, "trd": NaN, "batb": [[0, 2.54, 14.55]], "batl": NaN}, {"timestamp": 1578677968681, "ltp": 2.64, "tv": 656.3, "trd": NaN, "batb": [[0, 2.56, 3], [1, 2.54, 14.55], [2, 2.52, 3]], "batl": NaN}, {"timestamp": 1578677980477, "ltp": 2.64, "tv": 656.3, "trd": NaN, "batb": NaN, "batl": [[0, 2.62, 3.06], [1, 2.64, 4.12]]}, {"timestamp": 1578678070004, "ltp": 2.62, "tv": 662.42, "trd": [[2.62, 6.12]], "batb": [[0, 2.62, 1.94], [1, 2.56, 3], [2, 2.54, 14.55]], "batl": [[0, 2.64, 4.12], [1, 2.68, 3.86], [2, 2.8, 19.14]]}, {"timestamp": 1578678094285, "ltp": 2.64, "tv": 670.66, "trd": [[2.64, 20]], "batb": NaN, "batl": [[0, 2.68, 3.86], [1, 2.8, 19.14], [2, 2.82, 28]]}, {"timestamp": 1578678158707, "ltp": 2.68, "tv": 678.38, "trd": [[2.68, 11.72]], "batb": [[0, 2.68, 6.14], [1, 2.62, 1.94], [2, 2.56, 3]], "batl": [[0, 2.8, 19.14], [1, 2.82, 28], [2, 2.88, 2]]}, {"timestamp": 1578678168894, "ltp": 2.68, "tv": 678.38, "trd": NaN, "batb": [[0, 2.62, 1.94], [1, 2.56, 3], [2, 2.54, 14.55]], "batl": NaN}, {"timestamp": 1578678169209, "ltp": 2.8, "tv": 690.66, "trd": [[2.8, 22.28]], "batb": NaN, "batl": [[0, 2.8, 13]]}, {"timestamp": 1578678172225, "ltp": 2.8, "tv": 690.66, "trd": NaN, "batb": [[1, 2.58, 3], [2, 2.56, 3]], "batl": NaN}, {"timestamp": 1578678181884, "ltp": 2.8, "tv": 690.66, "trd": NaN, "batb": [[1, 2.6, 3]], "batl": NaN}, {"timestamp": 1578678187415, "ltp": 2.8, "tv": 690.66, "trd": NaN, "batb": NaN, "batl": [[0, 2.78, 2], [1, 2.8, 13], [2, 2.82, 28]]}, {"timestamp": 1578678192210, "ltp": 2.8, "tv": 690.66, "trd": NaN, "batb": [[0, 2.62, 4.94], [1, 2.56, 3], [2, 2.54, 14.55]], "batl": NaN}, {"timestamp": 1578678254565, "ltp": 2.8, "tv": 690.66, "trd": NaN, "batb": [[2, 2.54, 2.55]], "batl": NaN}, {"timestamp": 1578678261592, "ltp": 2.8, "tv": 690.66, "trd": NaN, "batb": [[1, 2.54, 2.55], [2, 2.52, 9.82]], "batl": NaN}, {"timestamp": 1578678300418, "ltp": 2.8, "tv": 690.66, "trd": NaN, "batb": [[1, 2.54, 5.55]], "batl": NaN}, {"timestamp": 1578678622940, "ltp": 2.8, "tv": 690.66, "trd": NaN, "batb": NaN, "batl": [[0, 2.78, 30], [2, 2.88, 2]]}, {"timestamp": 1578678867990, "ltp": 2.8, "tv": 690.66, "trd": NaN, "batb": NaN, "batl": [[1, 2.88, 2], [2, 2.98, 2]]}, {"timestamp": 1578678868091, "ltp": 2.8, "tv": 690.66, "trd": NaN, "batb": NaN, "batl": [[0, 2.76, 13], [1, 2.78, 30], [2, 2.88, 2]]}, {"timestamp": 1578678887639, "ltp": 2.8, "tv": 690.66, "trd": NaN, "batb": NaN, "batl": [[0, 2.74, 2], [1, 2.76, 13], [2, 2.78, 28]]}, {"timestamp": 1578679061691, "ltp": 2.8, "tv": 690.66, "trd": NaN, "batb": NaN, "batl": [[0, 2.74, 22]]}, {"timestamp": 1578679090928, "ltp": 2.8, "tv": 690.66, "trd": NaN, "batb": NaN, "batl": [[0, 2.74, 20]]}, {"timestamp": 1578679219862, "ltp": 2.8, "tv": 690.66, "trd": NaN, "batb": NaN, "batl": [[0, 2.72, 7.26], [1, 2.74, 20], [2, 2.76, 13]]}, {"timestamp": 1578679505198, "ltp": 2.62, "tv": 700.54, "trd": [[2.62, 16]], "batb": [[0, 2.54, 5.55], [1, 2.52, 9.82], [2, 2.5, 240.11]], "batl": [[0, 2.62, 95.06], [1, 2.72, 7.26], [2, 2.74, 20]]}, {"timestamp": 1578679516738, "ltp": 2.54, "tv": 711.65, "trd": [[2.54, 11.1]], "batb": [[0, 2.52, 9.82], [1, 2.5, 240.11], [2, 2.46, 4]], "batl": [[0, 2.54, 89.51]]}, {"timestamp": 1578679530138, "ltp": 2.52, "tv": 731.29, "trd": [[2.52, 23.64]], "batb": [[0, 2.5, 240.11], [1, 2.46, 4], [2, 2.4, 4.55]], "batl": [[0, 2.52, 79.69]]}, {"timestamp": 1578679541850, "ltp": 2.5, "tv": 890.67, "trd": [[2.5, 535.25]], "batb": [[0, 2.5, 160.42]], "batl": [[0, 2.72, 7.26], [1, 2.74, 20], [2, 2.76, 13]]}, {"timestamp": 1578679563978, "ltp": 2.5, "tv": 890.67, "trd": NaN, "batb": [[0, 2.52, 2.55], [1, 2.5, 160.42], [2, 2.46, 4]], "batl": NaN}, {"timestamp": 1578679585763, "ltp": 2.5, "tv": 890.67, "trd": NaN, "batb": NaN, "batl": [[0, 2.7, 2], [1, 2.72, 7.26], [2, 2.74, 20]]}, {"timestamp": 1578679641927, "ltp": 2.5, "tv": 890.67, "trd": NaN, "batb": NaN, "batl": [[1, 2.72, 20.26]]}, {"timestamp": 1578679669496, "ltp": 2.5, "tv": 890.67, "trd": NaN, "batb": NaN, "batl": [[0, 2.7, 4.82]]}, {"timestamp": 1578679699922, "ltp": 2.5, "tv": 890.67, "trd": NaN, "batb": [[0, 2.52, 4.52]], "batl": NaN}, {"timestamp": 1578680134802, "ltp": 2.54, "tv": 898.67, "trd": [[2.54, 19.1]], "batb": [[0, 2.54, 3.85], [1, 2.52, 4.52], [2, 2.5, 160.42]], "batl": NaN}, {"timestamp": 1578680135726, "ltp": 2.54, "tv": 898.67, "trd": NaN, "batb": [[0, 2.52, 4.52], [1, 2.5, 160.42], [2, 2.46, 4]], "batl": NaN}, {"timestamp": 1578680146918, "ltp": 2.7, "tv": 908.31, "trd": [[2.7, 9.64]], "batb": NaN, "batl": [[0, 2.72, 20.26], [1, 2.74, 20], [2, 2.78, 28]]}, {"timestamp": 1578680170647, "ltp": 2.72, "tv": 922.91, "trd": [[2.72, 14.6]], "batb": [[0, 2.52, 7.52]], "batl": [[0, 2.72, 12.96]]}, {"timestamp": 1578680172950, "ltp": 2.72, "tv": 922.91, "trd": NaN, "batb": [[0, 2.54, 2.13], [1, 2.52, 7.52], [2, 2.5, 160.42]], "batl": NaN}, {"timestamp": 1578680173843, "ltp": 2.72, "tv": 922.91, "trd": NaN, "batb": [[0, 2.54, 4.1], [1, 2.52, 5.55]], "batl": NaN}, {"timestamp": 1578680174671, "ltp": 2.72, "tv": 922.91, "trd": NaN, "batb": [[1, 2.52, 5.6]], "batl": NaN}, {"timestamp": 1578680836930, "ltp": 2.72, "tv": 922.91, "trd": NaN, "batb": NaN, "batl": [[2, 2.8, 28]]}, {"timestamp": 1578680843515, "ltp": 2.72, "tv": 922.91, "trd": NaN, "batb": NaN, "batl": [[2, 2.86, 28]]}, {"timestamp": 1578680953862, "ltp": 2.72, "tv": 922.91, "trd": NaN, "batb": [[0, 2.54, 82.84]], "batl": NaN}, {"timestamp": 1578680957979, "ltp": 2.72, "tv": 922.91, "trd": NaN, "batb": [[1, 2.52, 2.6]], "batl": NaN}, {"timestamp": 1578680994907, "ltp": 2.72, "tv": 922.91, "trd": NaN, "batb": [[0, 2.56, 10.77], [1, 2.54, 82.84], [2, 2.52, 2.6]], "batl": NaN}, {"timestamp": 1578681028877, "ltp": 2.72, "tv": 922.91, "trd": NaN, "batb": [[0, 2.58, 2.09], [1, 2.56, 10.77], [2, 2.54, 80.71]], "batl": NaN}, {"timestamp": 1578681029972, "ltp": 2.72, "tv": 922.91, "trd": NaN, "batb": [[0, 2.58, 5.09]], "batl": NaN}, {"timestamp": 1578681032970, "ltp": 2.72, "tv": 922.91, "trd": NaN, "batb": [[0, 2.58, 7.06], [2, 2.54, 78.74]], "batl": NaN}, {"timestamp": 1578681033959, "ltp": 2.72, "tv": 922.91, "trd": NaN, "batb": NaN, "batl": [[0, 2.7, 28], [1, 2.72, 12.96], [2, 2.74, 20]]}, {"timestamp": 1578681063864, "ltp": 2.72, "tv": 922.91, "trd": NaN, "batb": [[0, 2.6, 2.55], [1, 2.58, 7.06], [2, 2.56, 10.77]], "batl": [[0, 2.68, 5.53], [1, 2.7, 28], [2, 2.72, 12.96]]}, {"timestamp": 1578681078364, "ltp": 2.72, "tv": 922.91, "trd": NaN, "batb": [[0, 2.6, 4.52], [1, 2.58, 5.09]], "batl": NaN}, {"timestamp": 1578681079574, "ltp": 2.72, "tv": 922.91, "trd": NaN, "batb": [[0, 2.62, 2.06], [1, 2.6, 4.52], [2, 2.58, 3]], "batl": NaN}, {"timestamp": 1578681126930, "ltp": 2.72, "tv": 922.91, "trd": NaN, "batb": [[0, 2.62, 4.03], [1, 2.6, 2.55]], "batl": NaN}, {"timestamp": 1578681337911, "ltp": 2.62, "tv": 926.91, "trd": [[2.62, 20]], "batb": [[0, 2.62, 2.03]], "batl": NaN}, {"timestamp": 1578681454453, "ltp": 2.62, "tv": 926.91, "trd": NaN, "batb": [[1, 2.6, 49.09]], "batl": NaN}, {"timestamp": 1578681462846, "ltp": 2.62, "tv": 926.91, "trd": NaN, "batb": [[0, 2.62, 5.03], [2, 2.56, 10.81]], "batl": NaN}, {"timestamp": 1578681615324, "ltp": 2.62, "tv": 926.91, "trd": NaN, "batb": [[0, 2.62, 22.05]], "batl": NaN}, {"timestamp": 1578681631127, "ltp": 2.62, "tv": 926.91, "trd": NaN, "batb": [[0, 2.62, 19.05]], "batl": NaN}, {"timestamp": 1578681663634, "ltp": 2.62, "tv": 926.91, "trd": NaN, "batb": [[0, 2.64, 2.55], [1, 2.62, 19.05], [2, 2.6, 49.09]], "batl": NaN}, {"timestamp": 1578681697201, "ltp": 2.62, "tv": 926.91, "trd": NaN, "batb": [[0, 2.64, 4.52], [1, 2.62, 17.09]], "batl": NaN}, {"timestamp": 1578681708911, "ltp": 2.62, "tv": 936.9, "trd": [[2.62, 20.96], [2.64, 29.04]], "batb": [[0, 2.62, 16.61], [1, 2.6, 49.09], [2, 2.56, 10.81]], "batl": NaN}, {"timestamp": 1578681723626, "ltp": 2.62, "tv": 936.9, "trd": NaN, "batb": [[0, 2.64, 2.55], [1, 2.62, 16.61], [2, 2.6, 49.09]], "batl": NaN}, {"timestamp": 1578681823738, "ltp": 2.62, "tv": 936.9, "trd": NaN, "batb": [[0, 2.66, 5.56], [1, 2.64, 78.31], [2, 2.62, 16.61]], "batl": [[0, 2.7, 28], [1, 2.72, 12.96], [2, 2.74, 20]]}, {"timestamp": 1578681878577, "ltp": 2.62, "tv": 936.9, "trd": NaN, "batb": [[0, 2.66, 15.93]], "batl": NaN}, {"timestamp": 1578681903338, "ltp": 2.62, "tv": 936.9, "trd": NaN, "batb": [[0, 2.68, 2.55], [1, 2.66, 15.93], [2, 2.64, 78.31]], "batl": NaN}, {"timestamp": 1578682075015, "ltp": 2.62, "tv": 936.9, "trd": NaN, "batb": NaN, "batl": [[1, 2.74, 20], [2, 2.88, 2]]}, {"timestamp": 1578682080431, "ltp": 2.7, "tv": 936.98, "trd": [[2.7, 9.72]], "batb": NaN, "batl": [[0, 2.7, 27.96]]}, {"timestamp": 1578682143411, "ltp": 2.7, "tv": 992.9, "trd": [[2.7, 65.64]], "batb": [[0, 2.7, 16.85], [1, 2.68, 2.55], [2, 2.66, 15.93]], "batl": [[0, 2.74, 20], [1, 2.88, 2], [2, 2.98, 2]]}, {"timestamp": 1578682203624, "ltp": 2.7, "tv": 992.9, "trd": NaN, "batb": [[0, 2.72, 2.55], [1, 2.7, 16.85], [2, 2.68, 2.55]], "batl": NaN}, {"timestamp": 1578682358398, "ltp": 2.74, "tv": 997.3, "trd": [[2.74, 4.4]], "batb": NaN, "batl": [[0, 2.74, 17.8]]}, {"timestamp": 1578682452000, "ltp": 2.72, "tv": 1001.3, "trd": [[2.72, 18.6]], "batb": [[0, 2.7, 17.4], [1, 2.68, 2.55], [2, 2.66, 15.93]], "batl": NaN}, {"timestamp": 1578682468716, "ltp": 2.7, "tv": 1033.31, "trd": [[2.7, 96.54], [2.72, 19.7]], "batb": [[0, 2.7, 1.4]], "batl": NaN}, {"timestamp": 1578682521513, "ltp": 2.7, "tv": 1036.11, "trd": [[2.7, 99.34]], "batb": [[0, 2.68, 2.55], [1, 2.66, 10.37], [2, 2.64, 78.31]], "batl": [[0, 2.7, 4.11], [1, 2.72, 12], [2, 2.74, 17.8]]}, {"timestamp": 1578682525642, "ltp": 2.68, "tv": 1041.21, "trd": [[2.68, 16.82]], "batb": [[0, 2.66, 10.37], [1, 2.64, 78.31], [2, 2.6, 2.55]], "batl": [[0, 2.68, 17.45], [1, 2.7, 4.11], [2, 2.72, 12]]}, {"timestamp": 1578682725953, "ltp": 2.68, "tv": 1041.21, "trd": NaN, "batb": [[0, 2.66, 39.31]], "batl": NaN}, {"timestamp": 1578682832949, "ltp": 2.68, "tv": 1041.22, "trd": [[2.4, 21.11], [2.42, 126.41], [2.48, 24.07], [2.5, 535.25], [2.52, 23.64], [2.62, 20.96], [2.64, 29.04], [2.8, 22.28]], "batb": [[0, 2.66, 39.32]], "batl": NaN}, {"timestamp": 1578682913813, "ltp": 2.68, "tv": 1041.22, "trd": NaN, "batb": [[1, 2.64, 2.55]], "batl": NaN}, {"timestamp": 1578682918804, "ltp": 2.68, "tv": 1076.12, "trd": [[2.68, 51.72]], "batb": [[0, 2.68, 57.18], [1, 2.66, 39.32], [2, 2.64, 2.55]], "batl": [[0, 2.7, 4.11], [1, 2.72, 12], [2, 2.74, 17.8]]}, {"timestamp": 1578682923721, "ltp": 2.7, "tv": 1084.35, "trd": [[2.7, 107.56]], "batb": NaN, "batl": [[0, 2.72, 12], [1, 2.74, 17.8], [2, 2.88, 2]]}, {"timestamp": 1578682931932, "ltp": 2.7, "tv": 1084.35, "trd": NaN, "batb": [[0, 2.7, 18.73], [1, 2.68, 57.18], [2, 2.66, 39.32]], "batl": NaN}, {"timestamp": 1578682932242, "ltp": 2.7, "tv": 1084.35, "trd": NaN, "batb": [[2, 2.66, 10.37]], "batl": NaN}, {"timestamp": 1578682982551, "ltp": 2.7, "tv": 1084.35, "trd": NaN, "batb": [[0, 2.7, 21.29]], "batl": NaN}, {"timestamp": 1578683149860, "ltp": 2.7, "tv": 1084.35, "trd": NaN, "batb": NaN, "batl": [[2, 2.8, 2.5]]}, {"timestamp": 1578683153145, "ltp": 2.7, "tv": 1084.35, "trd": NaN, "batb": NaN, "batl": [[2, 2.8, 5]]}, {"timestamp": 1578683157749, "ltp": 2.7, "tv": 1084.35, "trd": NaN, "batb": NaN, "batl": [[1, 2.74, 20.3], [2, 2.8, 2.5]]}, {"timestamp": 1578683163864, "ltp": 2.7, "tv": 1084.35, "trd": NaN, "batb": NaN, "batl": [[2, 2.84, 2.5]]}, {"timestamp": 1578683166661, "ltp": 2.7, "tv": 1084.35, "trd": NaN, "batb": NaN, "batl": [[2, 2.84, 5]]}, {"timestamp": 1578683170169, "ltp": 2.7, "tv": 1084.35, "trd": NaN, "batb": NaN, "batl": [[2, 2.84, 2.5]]}, {"timestamp": 1578683175461, "ltp": 2.7, "tv": 1089.27, "trd": [[2.7, 112.48]], "batb": [[0, 2.7, 18.83]], "batl": NaN}, {"timestamp": 1578683229649, "ltp": 2.7, "tv": 1095.27, "trd": [[2.7, 118.48]], "batb": [[0, 2.7, 15.83]], "batl": NaN}, {"timestamp": 1578683257764, "ltp": 2.7, "tv": 1095.27, "trd": NaN, "batb": [[0, 2.7, 20.74]], "batl": NaN}, {"timestamp": 1578683281921, "ltp": 2.7, "tv": 1099.27, "trd": [[2.7, 122.48]], "batb": [[0, 2.7, 18.74]], "batl": NaN}, {"timestamp": 1578683349790, "ltp": 2.72, "tv": 1123.27, "trd": [[2.72, 43.7]], "batb": NaN, "batl": [[0, 2.74, 20.3], [1, 2.84, 2.5], [2, 2.88, 2]]}, {"timestamp": 1578683562715, "ltp": 2.7, "tv": 1133.27, "trd": [[2.7, 132.48]], "batb": [[0, 2.7, 13.74]], "batl": NaN}, {"timestamp": 1578683731682, "ltp": 2.7, "tv": 1133.27, "trd": NaN, "batb": NaN, "batl": [[1, 2.8, 3], [2, 2.84, 2.5]]}, {"timestamp": 1578683737685, "ltp": 2.7, "tv": 1133.27, "trd": NaN, "batb": [[0, 2.7, 7.47]], "batl": NaN}, {"timestamp": 1578683980948, "ltp": 2.68, "tv": 1153.27, "trd": [[2.68, 56.8], [2.7, 147.41]], "batb": [[0, 2.68, 54.64], [1, 2.66, 10.37], [2, 2.64, 2.55]], "batl": NaN}, {"timestamp": 1578684002341, "ltp": 2.68, "tv": 1153.27, "trd": NaN, "batb": [[0, 2.7, 2.55], [1, 2.68, 54.64], [2, 2.66, 10.37]], "batl": NaN}, {"timestamp": 1578684117409, "ltp": 2.74, "tv": 1193.87, "trd": [[2.74, 45]], "batb": [[0, 2.74, 4.7], [1, 2.7, 2.55], [2, 2.68, 54.64]], "batl": [[0, 2.8, 3], [1, 2.84, 2.5], [2, 2.88, 2]]}, {"timestamp": 1578684120329, "ltp": 2.74, "tv": 1193.87, "trd": NaN, "batb": [[1, 2.7, 5.55]], "batl": NaN}, {"timestamp": 1578684149168, "ltp": 2.74, "tv": 1197.87, "trd": [[2.74, 49]], "batb": [[0, 2.74, 2.7]], "batl": NaN}, {"timestamp": 1578684231142, "ltp": 2.8, "tv": 1203.87, "trd": [[2.8, 28.28]], "batb": [[0, 2.8, 6], [1, 2.74, 2.7], [2, 2.7, 5.55]], "batl": [[0, 2.84, 2.5], [1, 2.88, 2], [2, 2.94, 2.5]]}, {"timestamp": 1578684235859, "ltp": 2.8, "tv": 1203.87, "trd": NaN, "batb": NaN, "batl": [[2, 2.94, 12.5]]}, {"timestamp": 1578684242442, "ltp": 2.8, "tv": 1203.87, "trd": NaN, "batb": [[0, 2.82, 2.55], [1, 2.8, 6], [2, 2.74, 2.7]], "batl": NaN}, {"timestamp": 1578684249783, "ltp": 2.82, "tv": 1208.98, "trd": [[2.82, 5.1]], "batb": [[0, 2.8, 6], [1, 2.74, 2.7], [2, 2.7, 2.55]], "batl": NaN}, {"timestamp": 1578684250981, "ltp": 2.82, "tv": 1208.98, "trd": NaN, "batb": NaN, "batl": [[0, 2.84, 3.05]]}, {"timestamp": 1578684264999, "ltp": 2.82, "tv": 1210.08, "trd": [[2.82, 6.2]], "batb": [[0, 2.82, 9.23], [1, 2.8, 6], [2, 2.74, 2.7]], "batl": [[0, 2.84, 2.5]]}, {"timestamp": 1578684265592, "ltp": 2.82, "tv": 1216.08, "trd": [[2.82, 12.2]], "batb": [[0, 2.82, 6.23]], "batl": NaN}, {"timestamp": 1578684285194, "ltp": 2.82, "tv": 1220.08, "trd": [[2.82, 16.2]], "batb": [[0, 2.82, 4.23]], "batl": NaN}, {"timestamp": 1578684302295, "ltp": 2.82, "tv": 1220.08, "trd": NaN, "batb": [[0, 2.82, 6.78]], "batl": NaN}, {"timestamp": 1578684775926, "ltp": 2.8, "tv": 1242.08, "trd": [[2.8, 36.72], [2.82, 29.77]], "batb": [[0, 2.8, 1.78], [1, 2.74, 2.7], [2, 2.7, 2.55]], "batl": NaN}, {"timestamp": 1578684782834, "ltp": 2.8, "tv": 1242.08, "trd": NaN, "batb": [[2, 2.7, 5.55]], "batl": NaN}, {"timestamp": 1578684963717, "ltp": 2.8, "tv": 1245.64, "trd": [[2.8, 40.28]], "batb": [[0, 2.74, 2.7], [1, 2.7, 5.55], [2, 2.68, 54.64]], "batl": [[0, 2.84, 2.72]]}, {"timestamp": 1578685106268, "ltp": 2.8, "tv": 1245.64, "trd": NaN, "batb": NaN, "batl": [[0, 2.8, 23.22], [1, 2.84, 2.5], [2, 2.88, 2]]}, {"timestamp": 1578685284586, "ltp": 2.8, "tv": 1245.64, "trd": NaN, "batb": [[0, 2.74, 4.4]], "batl": NaN}, {"timestamp": 1578685580878, "ltp": 2.74, "tv": 1254.44, "trd": [[2.74, 57.8]], "batb": [[0, 2.7, 5.55], [1, 2.68, 54.64], [2, 2.64, 2.55]], "batl": [[0, 2.74, 5.6], [1, 2.8, 23.22], [2, 2.84, 2.5]]}, {"timestamp": 1578685581198, "ltp": 2.74, "tv": 1254.44, "trd": NaN, "batb": [[0, 2.7, 16.57]], "batl": NaN}, {"timestamp": 1578685584483, "ltp": 2.74, "tv": 1254.44, "trd": NaN, "batb": NaN, "batl": [[1, 2.78, 7.03], [2, 2.8, 23.22]]}, {"timestamp": 1578685594608, "ltp": 2.74, "tv": 1254.44, "trd": NaN, "batb": NaN, "batl": [[0, 2.74, 15.6]]}, {"timestamp": 1578685599747, "ltp": 2.74, "tv": 1254.44, "trd": NaN, "batb": [[0, 2.7, 13.57]], "batl": NaN}, {"timestamp": 1578685601648, "ltp": 2.74, "tv": 1254.44, "trd": NaN, "batb": [[0, 2.72, 4.26], [1, 2.7, 13.57], [2, 2.68, 54.64]], "batl": NaN}, {"timestamp": 1578685719848, "ltp": 2.74, "tv": 1254.44, "trd": NaN, "batb": [[0, 2.72, 7.39]], "batl": NaN}, {"timestamp": 1578686002845, "ltp": 2.74, "tv": 1285.64, "trd": [[2.74, 89]], "batb": [[0, 2.74, 16.15], [1, 2.72, 7.39], [2, 2.7, 13.57]], "batl": [[0, 2.78, 7.03], [1, 2.8, 23.22], [2, 2.84, 2.5]]}, {"timestamp": 1578686022958, "ltp": 2.74, "tv": 1285.64, "trd": NaN, "batb": [[0, 2.76, 5.11], [1, 2.74, 16.15], [2, 2.72, 7.39]], "batl": NaN}, {"timestamp": 1578686023576, "ltp": 2.74, "tv": 1285.64, "trd": NaN, "batb": [[2, 2.72, 3.13]], "batl": NaN}, {"timestamp": 1578686042168, "ltp": 2.74, "tv": 1285.64, "trd": NaN, "batb": [[0, 2.76, 7.66]], "batl": NaN}, {"timestamp": 1578686172989, "ltp": 2.74, "tv": 1285.64, "trd": NaN, "batb": NaN, "batl": [[0, 2.78, 29.03]]}, {"timestamp": 1578686431988, "ltp": 2.74, "tv": 1285.64, "trd": NaN, "batb": [[1, 2.74, 32]], "batl": NaN}, {"timestamp": 1578686496888, "ltp": 2.76, "tv": 1293.65, "trd": [[2.76, 28]], "batb": [[0, 2.76, 3.66]], "batl": NaN}, {"timestamp": 1578686809934, "ltp": 2.78, "tv": 1304.95, "trd": [[2.78, 15.3]], "batb": NaN, "batl": [[0, 2.78, 23.38]]}, {"timestamp": 1578687151756, "ltp": 2.76, "tv": 1312.27, "trd": [[2.76, 35.32]], "batb": [[0, 2.74, 32], [1, 2.72, 3.13], [2, 2.7, 2.55]], "batl": [[0, 2.76, 2.34], [1, 2.78, 23.38], [2, 2.8, 23.22]]}, {"timestamp": 1578687183725, "ltp": 2.76, "tv": 1316.95, "trd": [[2.76, 40.01]], "batb": [[0, 2.74, 32.21], [2, 2.68, 54.64]], "batl": [[0, 2.78, 23.38], [1, 2.8, 23.22], [2, 2.84, 2.5]]}, {"timestamp": 1578687193935, "ltp": 2.76, "tv": 1316.95, "trd": NaN, "batb": [[2, 2.7, 6]], "batl": NaN}, {"timestamp": 1578687248952, "ltp": 2.76, "tv": 1316.95, "trd": NaN, "batb": NaN, "batl": [[1, 2.8, 63.22]]}, {"timestamp": 1578687295614, "ltp": 2.76, "tv": 1316.95, "trd": NaN, "batb": [[0, 2.76, 10.43], [1, 2.74, 32], [2, 2.72, 3.13]], "batl": NaN}, {"timestamp": 1578687390146, "ltp": 2.76, "tv": 1316.95, "trd": NaN, "batb": [[0, 2.76, 12.13]], "batl": NaN}, {"timestamp": 1578688014971, "ltp": 2.8, "tv": 1385.17, "trd": [[2.78, 62.06], [2.8, 61.74]], "batb": [[0, 2.78, 84.53], [1, 2.76, 12.13], [2, 2.74, 32]], "batl": [[0, 2.8, 52.49], [1, 2.84, 2.5], [2, 2.88, 2]]}, {"timestamp": 1578688023965, "ltp": 2.8, "tv": 1399.77, "trd": [[2.8, 76.34]], "batb": NaN, "batl": [[0, 2.8, 45.19]]}, {"timestamp": 1578688044810, "ltp": 2.8, "tv": 1431.19, "trd": [[2.8, 107.76]], "batb": NaN, "batl": [[0, 2.8, 29.48]]}, {"timestamp": 1578688059933, "ltp": 2.8, "tv": 1431.19, "trd": NaN, "batb": [[2, 2.74, 15.85]], "batl": NaN}, {"timestamp": 1578688128942, "ltp": 2.78, "tv": 1435.19, "trd": [[2.78, 66.06]], "batb": [[0, 2.78, 82.53]], "batl": NaN}, {"timestamp": 1578688488030, "ltp": 2.78, "tv": 1485.19, "trd": [[2.78, 116.06]], "batb": [[0, 2.78, 57.53]], "batl": NaN}, {"timestamp": 1578688693360, "ltp": 2.78, "tv": 1485.19, "trd": NaN, "batb": NaN, "batl": [[2, 2.86, 33]]}, {"timestamp": 1578688707586, "ltp": 2.78, "tv": 1493.19, "trd": [[2.78, 124.06]], "batb": [[0, 2.78, 53.53]], "batl": NaN}, {"timestamp": 1578688866885, "ltp": 2.78, "tv": 1493.19, "trd": NaN, "batb": NaN, "batl": [[2, 2.86, 35]]}, {"timestamp": 1578688873571, "ltp": 2.78, "tv": 1493.19, "trd": NaN, "batb": NaN, "batl": [[2, 2.86, 36]]}, {"timestamp": 1578688886874, "ltp": 2.78, "tv": 1495.19, "trd": [[2.78, 126.06]], "batb": [[0, 2.78, 52.53]], "batl": [[2, 2.86, 33]]}, {"timestamp": 1578689021770, "ltp": 2.78, "tv": 1600.25, "trd": [[2.78, 231.12]], "batb": [[0, 2.76, 12.13], [1, 2.74, 15.85], [2, 2.72, 3.13]], "batl": [[0, 2.78, 97.47], [1, 2.8, 29.48], [2, 2.84, 2.5]]}, {"timestamp": 1578689022568, "ltp": 2.76, "tv": 1624.51, "trd": [[2.76, 64.27]], "batb": [[0, 2.74, 15.85], [1, 2.72, 3.13], [2, 2.7, 6]], "batl": NaN}, {"timestamp": 1578689025979, "ltp": 2.76, "tv": 1624.51, "trd": NaN, "batb": [[0, 2.74, 19.44]], "batl": NaN}, {"timestamp": 1578689030477, "ltp": 2.76, "tv": 1624.51, "trd": NaN, "batb": NaN, "batl": [[0, 2.76, 97.47]]}, {"timestamp": 1578689032961, "ltp": 2.76, "tv": 1624.51, "trd": NaN, "batb": NaN, "batl": [[0, 2.8, 29.48], [1, 2.84, 2.5], [2, 2.86, 33]]}, {"timestamp": 1578689033070, "ltp": 2.74, "tv": 1663.38, "trd": [[2.74, 127.87]], "batb": [[0, 2.72, 3.13], [1, 2.7, 6], [2, 2.68, 54.64]], "batl": [[0, 2.74, 78.04], [1, 2.8, 29.48], [2, 2.84, 2.5]]}, {"timestamp": 1578689037488, "ltp": 2.72, "tv": 1691.7, "trd": [[2.72, 72.03]], "batb": [[0, 2.7, 6], [1, 2.68, 54.64], [2, 2.52, 6]], "batl": [[0, 2.72, 63.88]]}, {"timestamp": 1578689042685, "ltp": 2.7, "tv": 1703.7, "trd": [[2.7, 159.41]], "batb": [[0, 2.68, 54.64], [1, 2.52, 6], [2, 2.5, 160.42]], "batl": [[0, 2.7, 57.88]]}, {"timestamp": 1578689043819, "ltp": 2.7, "tv": 1703.7, "trd": NaN, "batb": [[1, 2.54, 2.15], [2, 2.52, 6]], "batl": NaN}, {"timestamp": 1578689049801, "ltp": 2.68, "tv": 1715.7, "trd": [[2.68, 68.8]], "batb": [[0, 2.68, 48.64]], "batl": NaN}, {"timestamp": 1578689052891, "ltp": 2.68, "tv": 1812.98, "trd": [[2.68, 166.08]], "batb": [[0, 2.54, 2.15], [1, 2.52, 6], [2, 2.5, 160.42]], "batl": [[0, 2.68, 9.24]]}, {"timestamp": 1578689054325, "ltp": 2.68, "tv": 1812.98, "trd": NaN, "batb": [[1, 2.52, 17.01]], "batl": NaN}, {"timestamp": 1578689056227, "ltp": 2.68, "tv": 1812.98, "trd": NaN, "batb": [[0, 2.54, 5.15]], "batl": NaN}, {"timestamp": 1578689065006, "ltp": 2.68, "tv": 1812.98, "trd": NaN, "batb": NaN, "batl": [[0, 2.66, 2], [1, 2.68, 9.24], [2, 2.8, 29.48]]}, {"timestamp": 1578689086992, "ltp": 2.68, "tv": 1812.98, "trd": NaN, "batb": [[1, 2.52, 42.1]], "batl": NaN}, {"timestamp": 1578689214937, "ltp": 2.68, "tv": 1812.98, "trd": NaN, "batb": [[0, 2.56, 4], [1, 2.54, 5.15], [2, 2.52, 42.1]], "batl": NaN}, {"timestamp": 1578689252422, "ltp": 2.68, "tv": 1812.98, "trd": NaN, "batb": NaN, "batl": [[0, 2.68, 9.24], [1, 2.8, 29.48], [2, 2.84, 2.5]]}, {"timestamp": 1578689307989, "ltp": 2.68, "tv": 1812.98, "trd": NaN, "batb": [[0, 2.58, 10.89], [1, 2.56, 4], [2, 2.54, 5.15]], "batl": NaN}, {"timestamp": 1578689316962, "ltp": 2.68, "tv": 1831.46, "trd": [[2.68, 184.56]], "batb": [[0, 2.68, 28.07], [1, 2.58, 10.89], [2, 2.56, 4]], "batl": [[0, 2.78, 5.37]]}, {"timestamp": 1578689331023, "ltp": 2.68, "tv": 1831.46, "trd": NaN, "batb": [[1, 2.6, 21.5], [2, 2.58, 10.89]], "batl": NaN}, {"timestamp": 1578689342953, "ltp": 2.68, "tv": 1831.46, "trd": NaN, "batb": [[0, 2.7, 2.03], [1, 2.68, 28.07], [2, 2.6, 21.5]], "batl": NaN}, {"timestamp": 1578689356978, "ltp": 2.68, "tv": 1871.46, "trd": [[2.68, 220.5], [2.7, 163.46]], "batb": [[0, 2.68, 10.1], [1, 2.6, 21.5], [2, 2.58, 10.89]], "batl": NaN}, {"timestamp": 1578689453928, "ltp": 2.68, "tv": 1871.46, "trd": NaN, "batb": NaN, "batl": [[2, 2.84, 15.95]]}, {"timestamp": 1578689464607, "ltp": 2.68, "tv": 1871.46, "trd": NaN, "batb": NaN, "batl": [[0, 2.76, 4], [1, 2.78, 5.37], [2, 2.8, 29.48]]}, {"timestamp": 1578689498951, "ltp": 2.68, "tv": 1871.46, "trd": NaN, "batb": NaN, "batl": [[0, 2.74, 50], [1, 2.76, 4], [2, 2.78, 5.37]]}, {"timestamp": 1578689513896, "ltp": 2.68, "tv": 1871.46, "trd": NaN, "batb": NaN, "batl": [[1, 2.78, 5.37], [2, 2.8, 29.48]]}, {"timestamp": 1578689734473, "ltp": 2.74, "tv": 1872.06, "trd": [[2.74, 128.47]], "batb": NaN, "batl": [[0, 2.74, 49.7]]}, {"timestamp": 1578689899686, "ltp": 2.74, "tv": 1872.06, "trd": NaN, "batb": [[2, 2.58, 21.65]], "batl": NaN}, {"timestamp": 1578690005208, "ltp": 2.74, "tv": 1872.11, "trd": [[2.4, 21.12], [2.42, 126.41], [2.44, 31.99], [2.46, 9.11], [2.48, 24.07], [2.5, 535.25], [2.54, 19.11], [2.64, 29.05], [2.68, 220.51], [2.7, 163.47], [2.72, 72.03], [2.74, 128.47], [2.76, 64.28], [2.8, 107.76], [2.82, 29.77]], "batb": [[2, 2.58, 21.66]], "batl": NaN}, {"timestamp": 1578690115876, "ltp": 2.74, "tv": 1872.11, "trd": NaN, "batb": NaN, "batl": [[1, 2.78, 38.37]]}, {"timestamp": 1578690122894, "ltp": 2.74, "tv": 1872.11, "trd": NaN, "batb": NaN, "batl": [[0, 2.72, 4], [1, 2.74, 49.7], [2, 2.78, 38.37]]}, {"timestamp": 1578690209325, "ltp": 2.68, "tv": 1878.49, "trd": [[2.68, 226.89]], "batb": [[0, 2.68, 6.91]], "batl": NaN}, {"timestamp": 1578690446941, "ltp": 2.68, "tv": 1878.49, "trd": NaN, "batb": NaN, "batl": [[0, 2.7, 2.3], [1, 2.72, 4], [2, 2.74, 49.7]]}, {"timestamp": 1578690449564, "ltp": 2.68, "tv": 1878.49, "trd": NaN, "batb": NaN, "batl": [[0, 2.72, 4], [1, 2.74, 49.7], [2, 2.78, 38.37]]}, {"timestamp": 1578690458447, "ltp": 2.68, "tv": 1878.49, "trd": NaN, "batb": [[0, 2.7, 6.47], [1, 2.68, 6.91], [2, 2.6, 21.5]], "batl": NaN}, {"timestamp": 1578690527579, "ltp": 2.7, "tv": 1891.43, "trd": [[2.7, 176.41]], "batb": [[0, 2.68, 6.91], [1, 2.6, 21.5], [2, 2.58, 21.66]], "batl": [[0, 2.7, 1.53], [1, 2.72, 4], [2, 2.74, 49.7]]}, {"timestamp": 1578690534480, "ltp": 2.68, "tv": 1905.25, "trd": [[2.68, 240.71]], "batb": [[0, 2.6, 21.5], [1, 2.58, 21.66], [2, 2.52, 6]], "batl": [[0, 2.68, 1.09], [1, 2.7, 1.53], [2, 2.72, 4]]}, {"timestamp": 1578690541969, "ltp": 2.68, "tv": 1905.25, "trd": NaN, "batb": NaN, "batl": [[1, 2.7, 5.53]]}, {"timestamp": 1578690747489, "ltp": 2.68, "tv": 1905.25, "trd": NaN, "batb": NaN, "batl": [[0, 2.68, 4.09]]}, {"timestamp": 1578690753900, "ltp": 2.68, "tv": 1905.25, "trd": NaN, "batb": NaN, "batl": [[1, 2.7, 1.53]]}, {"timestamp": 1578690801967, "ltp": 2.68, "tv": 1905.25, "trd": NaN, "batb": [[0, 2.58, 36.66], [1, 2.52, 6], [2, 2.5, 472.42]], "batl": NaN}, {"timestamp": 1578690802649, "ltp": 2.68, "tv": 1905.25, "trd": NaN, "batb": [[0, 2.6, 3], [1, 2.58, 36.66], [2, 2.52, 6]], "batl": NaN}, {"timestamp": 1578690819885, "ltp": 2.58, "tv": 1934.12, "trd": [[2.58, 36.88], [2.6, 6]], "batb": [[0, 2.58, 25.22], [1, 2.52, 6], [2, 2.5, 472.42]], "batl": [[0, 2.6, 97], [1, 2.68, 4.09], [2, 2.7, 1.53]]}, {"timestamp": 1578690825705, "ltp": 2.58, "tv": 1984.56, "trd": [[2.58, 87.32]], "batb": [[0, 2.52, 6], [1, 2.5, 472.42], [2, 2.46, 4]], "batl": [[0, 2.58, 71.78]]}, {"timestamp": 1578690826187, "ltp": 2.58, "tv": 1984.56, "trd": NaN, "batb": [[0, 2.52, 17.49]], "batl": NaN}, {"timestamp": 1578690827985, "ltp": 2.58, "tv": 1984.56, "trd": NaN, "batb": [[0, 2.52, 27.14]], "batl": NaN}, {"timestamp": 1578690841690, "ltp": 2.58, "tv": 1984.56, "trd": NaN, "batb": [[0, 2.54, 52.07], [1, 2.52, 27.14], [2, 2.5, 472.42]], "batl": NaN}, {"timestamp": 1578690916998, "ltp": 2.58, "tv": 1984.56, "trd": NaN, "batb": [[1, 2.52, 50.14]], "batl": [[2, 2.7, 15.53]]}, {"timestamp": 1578691154774, "ltp": 2.58, "tv": 2128.12, "trd": [[2.58, 230.88]], "batb": [[0, 2.58, 28.22], [1, 2.54, 52.07], [2, 2.52, 50.14]], "batl": [[0, 2.68, 4.09], [1, 2.7, 15.53], [2, 2.72, 33.48]]}, {"timestamp": 1578691156771, "ltp": 2.58, "tv": 2128.12, "trd": NaN, "batb": NaN, "batl": [[1, 2.7, 45.01], [2, 2.72, 4]]}, {"timestamp": 1578691160002, "ltp": 2.58, "tv": 2128.12, "trd": NaN, "batb": [[1, 2.56, 6], [2, 2.54, 52.07]], "batl": [[0, 2.66, 2.93], [1, 2.68, 4.09], [2, 2.7, 45.01]]}, {"timestamp": 1578691163983, "ltp": 2.58, "tv": 2128.12, "trd": NaN, "batb": [[1, 2.56, 36.77], [2, 2.52, 17.49]], "batl": [[2, 2.7, 31.01]]}, {"timestamp": 1578691167801, "ltp": 2.58, "tv": 2128.12, "trd": NaN, "batb": [[1, 2.56, 30.77]], "batl": NaN}, {"timestamp": 1578691193736, "ltp": 2.58, "tv": 2128.12, "trd": NaN, "batb": NaN, "batl": [[2, 2.7, 1.53]]}, {"timestamp": 1578691195830, "ltp": 2.58, "tv": 2128.12, "trd": NaN, "batb": [[0, 2.6, 50.86], [1, 2.58, 28.22], [2, 2.56, 30.77]], "batl": NaN}, {"timestamp": 1578691263963, "ltp": 2.58, "tv": 2128.12, "trd": NaN, "batb": [[0, 2.62, 16.19], [1, 2.6, 50.86], [2, 2.58, 28.22]], "batl": NaN}, {"timestamp": 1578691274465, "ltp": 2.58, "tv": 2128.12, "trd": NaN, "batb": [[1, 2.58, 28.22], [2, 2.56, 30.77]], "batl": NaN}, {"timestamp": 1578691283611, "ltp": 2.58, "tv": 2128.12, "trd": NaN, "batb": [[0, 2.58, 28.22], [1, 2.56, 30.77], [2, 2.52, 17.49]], "batl": NaN}, {"timestamp": 1578691290618, "ltp": 2.58, "tv": 2128.12, "trd": NaN, "batb": [[0, 2.6, 50.86], [1, 2.58, 28.22], [2, 2.56, 30.77]], "batl": NaN}, {"timestamp": 1578691328162, "ltp": 2.6, "tv": 2176.12, "trd": [[2.6, 54]], "batb": [[0, 2.6, 26.86]], "batl": NaN}, {"timestamp": 1578691408506, "ltp": 2.6, "tv": 2176.12, "trd": NaN, "batb": [[2, 2.52, 17.49]], "batl": NaN}, {"timestamp": 1578691460497, "ltp": 2.6, "tv": 2176.12, "trd": NaN, "batb": [[0, 2.62, 8.52], [1, 2.6, 26.86], [2, 2.58, 28.22]], "batl": NaN}, {"timestamp": 1578691465399, "ltp": 2.6, "tv": 2176.12, "trd": NaN, "batb": [[1, 2.58, 28.22], [2, 2.52, 17.49]], "batl": NaN}, {"timestamp": 1578691480873, "ltp": 2.6, "tv": 2176.12, "trd": NaN, "batb": [[0, 2.58, 28.22], [1, 2.52, 17.49], [2, 2.5, 485.42]], "batl": NaN}, {"timestamp": 1578691481456, "ltp": 2.6, "tv": 2176.12, "trd": NaN, "batb": [[0, 2.6, 26.86], [1, 2.58, 28.22], [2, 2.52, 17.49]], "batl": NaN}, {"timestamp": 1578691496868, "ltp": 2.6, "tv": 2176.12, "trd": NaN, "batb": [[0, 2.62, 24.61], [1, 2.6, 26.86], [2, 2.58, 28.22]], "batl": NaN}, {"timestamp": 1578691497555, "ltp": 2.6, "tv": 2176.12, "trd": NaN, "batb": [[1, 2.58, 28.22], [2, 2.52, 17.49]], "batl": NaN}, {"timestamp": 1578691641853, "ltp": 2.6, "tv": 2176.12, "trd": NaN, "batb": [[0, 2.64, 7.67], [1, 2.62, 24.61], [2, 2.58, 28.22]], "batl": NaN}, {"timestamp": 1578691645762, "ltp": 2.66, "tv": 2180.12, "trd": [[2.66, 4]], "batb": NaN, "batl": [[0, 2.68, 5.02], [1, 2.7, 1.53], [2, 2.72, 37]]}, {"timestamp": 1578691741718, "ltp": 2.64, "tv": 2184.13, "trd": [[2.64, 33.05]], "batb": [[0, 2.64, 5.66]], "batl": NaN}, {"timestamp": 1578691752905, "ltp": 2.62, "tv": 2244.67, "trd": [[2.62, 70.18], [2.64, 44.37]], "batb": [[0, 2.58, 28.22], [1, 2.52, 6], [2, 2.5, 485.42]], "batl": [[0, 2.62, 69.73], [1, 2.68, 5.02], [2, 2.7, 1.53]]}, {"timestamp": 1578691774989, "ltp": 2.62, "tv": 2244.67, "trd": NaN, "batb": [[1, 2.52, 28.21]], "batl": NaN}, {"timestamp": 1578691784726, "ltp": 2.58, "tv": 2254.67, "trd": [[2.58, 240.88]], "batb": [[0, 2.58, 23.22]], "batl": NaN}, {"timestamp": 1578691801931, "ltp": 2.58, "tv": 2270.67, "trd": [[2.58, 256.88]], "batb": [[0, 2.58, 15.22]], "batl": NaN}, {"timestamp": 1578691931897, "ltp": 2.58, "tv": 2270.67, "trd": NaN, "batb": [[0, 2.6, 4.26], [1, 2.58, 15.22], [2, 2.52, 28.21]], "batl": NaN}, {"timestamp": 1578692020919, "ltp": 2.58, "tv": 2270.67, "trd": NaN, "batb": [[2, 2.52, 6]], "batl": NaN}, {"timestamp": 1578692142022, "ltp": 2.58, "tv": 2270.67, "trd": NaN, "batb": NaN, "batl": [[1, 2.68, 17.31]]}, {"timestamp": 1578692574441, "ltp": 2.62, "tv": 2320.67, "trd": [[2.62, 120.18]], "batb": NaN, "batl": [[0, 2.62, 44.73]]}, {"timestamp": 1578692634903, "ltp": 2.62, "tv": 2320.67, "trd": NaN, "batb": NaN, "batl": [[1, 2.68, 5.02], [2, 2.7, 18.13]]}, {"timestamp": 1578692871964, "ltp": 2.6, "tv": 2329.19, "trd": [[2.6, 62.52]], "batb": [[0, 2.58, 15.22], [1, 2.52, 6], [2, 2.5, 485.42]], "batl": [[0, 2.6, 15.74], [1, 2.62, 44.73], [2, 2.68, 5.02]]}, {"timestamp": 1578692877888, "ltp": 2.58, "tv": 2359.63, "trd": [[2.58, 287.32]], "batb": [[0, 2.52, 17.49], [1, 2.5, 485.42], [2, 2.46, 4]], "batl": [[0, 2.62, 45.25], [1, 2.68, 5.02], [2, 2.7, 18.13]]}, {"timestamp": 1578692878812, "ltp": 2.58, "tv": 2359.63, "trd": NaN, "batb": [[0, 2.52, 28.47]], "batl": NaN}, {"timestamp": 1578692881697, "ltp": 2.58, "tv": 2359.63, "trd": NaN, "batb": [[0, 2.52, 57.97]], "batl": NaN}, {"timestamp": 1578692884598, "ltp": 2.52, "tv": 2360.67, "trd": [[2.52, 24.68]], "batb": [[0, 2.52, 57.45]], "batl": [[0, 2.62, 44.73]]}, {"timestamp": 1578692890130, "ltp": 2.52, "tv": 2360.67, "trd": NaN, "batb": NaN, "batl": [[0, 2.62, 45.25]]}, {"timestamp": 1578693003940, "ltp": 2.52, "tv": 2360.67, "trd": NaN, "batb": NaN, "batl": [[2, 2.7, 1.53]]}, {"timestamp": 1578693069142, "ltp": 2.52, "tv": 2360.67, "trd": NaN, "batb": [[0, 2.54, 18.74], [1, 2.52, 57.45], [2, 2.5, 485.42]], "batl": NaN}, {"timestamp": 1578693071971, "ltp": 2.52, "tv": 2360.67, "trd": NaN, "batb": [[0, 2.54, 20.44]], "batl": NaN}, {"timestamp": 1578693167069, "ltp": 2.52, "tv": 2360.67, "trd": NaN, "batb": NaN, "batl": [[0, 2.6, 3.12], [1, 2.62, 45.25], [2, 2.68, 5.02]]}, {"timestamp": 1578693172484, "ltp": 2.52, "tv": 2360.67, "trd": NaN, "batb": NaN, "batl": [[0, 2.6, 3.64], [1, 2.62, 44.73]]}, {"timestamp": 1578693207628, "ltp": 2.52, "tv": 2360.67, "trd": NaN, "batb": [[0, 2.56, 6.82], [1, 2.54, 20.44], [2, 2.52, 57.45]], "batl": NaN}, {"timestamp": 1578693319979, "ltp": 2.52, "tv": 2360.67, "trd": NaN, "batb": [[0, 2.56, 8.53], [1, 2.54, 18.74]], "batl": NaN}, {"timestamp": 1578693429625, "ltp": 2.56, "tv": 2365.03, "trd": [[2.56, 4.36]], "batb": [[0, 2.56, 6.35]], "batl": NaN}, {"timestamp": 1578693528232, "ltp": 2.56, "tv": 2365.03, "trd": NaN, "batb": [[2, 2.52, 27.95]], "batl": NaN}, {"timestamp": 1578693529915, "ltp": 2.56, "tv": 2365.03, "trd": NaN, "batb": [[1, 2.52, 16.46], [2, 2.5, 485.42]], "batl": NaN}, {"timestamp": 1578693531650, "ltp": 2.56, "tv": 2370.39, "trd": [[2.56, 9.72]], "batb": [[0, 2.56, 3.66]], "batl": NaN}, {"timestamp": 1578693674995, "ltp": 2.58, "tv": 2371.43, "trd": [[2.58, 288.36]], "batb": [[0, 2.58, 14.78], [1, 2.56, 3.66], [2, 2.52, 16.46]], "batl": [[0, 2.6, 3.12]]}, {"timestamp": 1578693715358, "ltp": 2.58, "tv": 2371.43, "trd": NaN, "batb": [[0, 2.58, 20.74]], "batl": NaN}, {"timestamp": 1578694002990, "ltp": 2.58, "tv": 2391.43, "trd": [[2.58, 308.36]], "batb": [[0, 2.58, 10.74]], "batl": NaN}, {"timestamp": 1578694004807, "ltp": 2.58, "tv": 2391.43, "trd": NaN, "batb": [[0, 2.58, 17.74]], "batl": NaN}, {"timestamp": 1578694218917, "ltp": 2.58, "tv": 2391.43, "trd": NaN, "batb": [[2, 2.54, 236.22]], "batl": NaN}, {"timestamp": 1578694220978, "ltp": 2.58, "tv": 2391.43, "trd": NaN, "batb": [[1, 2.56, 13.8]], "batl": NaN}, {"timestamp": 1578694283903, "ltp": 2.6, "tv": 2397.67, "trd": [[2.6, 68.76]], "batb": NaN, "batl": [[0, 2.62, 44.73], [1, 2.68, 5.02], [2, 2.7, 1.53]]}, {"timestamp": 1578694366830, "ltp": 2.6, "tv": 2397.67, "trd": NaN, "batb": [[0, 2.6, 6.71], [1, 2.58, 17.74], [2, 2.56, 11.84]], "batl": NaN}, {"timestamp": 1578694382458, "ltp": 2.6, "tv": 2397.67, "trd": NaN, "batb": NaN, "batl": [[2, 2.7, 12.93]]}, {"timestamp": 1578694502990, "ltp": 2.6, "tv": 2397.67, "trd": NaN, "batb": [[0, 2.6, 36.71]], "batl": NaN}, {"timestamp": 1578694605341, "ltp": 2.6, "tv": 2397.67, "trd": NaN, "batb": NaN, "batl": [[0, 2.62, 46.86]]}, {"timestamp": 1578694626545, "ltp": 2.6, "tv": 2397.67, "trd": NaN, "batb": NaN, "batl": [[2, 2.7, 1.53]]}, {"timestamp": 1578694812728, "ltp": 2.6, "tv": 2417.67, "trd": [[2.6, 88.76]], "batb": [[0, 2.6, 26.71]], "batl": NaN}, {"timestamp": 1578695286675, "ltp": 2.62, "tv": 2421.67, "trd": [[2.62, 124.18]], "batb": [[0, 2.6, 28.71]], "batl": [[0, 2.62, 44.86]]}, {"timestamp": 1578695287658, "ltp": 2.62, "tv": 2421.67, "trd": NaN, "batb": [[1, 2.58, 19.74]], "batl": NaN}, {"timestamp": 1578695294771, "ltp": 2.62, "tv": 2421.67, "trd": NaN, "batb": [[0, 2.6, 26.71], [2, 2.56, 13.84]], "batl": NaN}, {"timestamp": 1578695351890, "ltp": 2.62, "tv": 2421.67, "trd": NaN, "batb": [[1, 2.58, 17.74], [2, 2.56, 11.84]], "batl": NaN}, {"timestamp": 1578695515880, "ltp": 2.6, "tv": 2461.67, "trd": [[2.6, 128.76]], "batb": [[0, 2.6, 6.71]], "batl": NaN}, {"timestamp": 1578695655978, "ltp": 2.6, "tv": 2461.67, "trd": NaN, "batb": [[0, 2.6, 19.81]], "batl": NaN}, {"timestamp": 1578695877982, "ltp": 2.6, "tv": 2461.67, "trd": NaN, "batb": NaN, "batl": [[0, 2.62, 46.39]]}, {"timestamp": 1578695991996, "ltp": 2.62, "tv": 2554.48, "trd": [[2.62, 216.98]], "batb": NaN, "batl": [[0, 2.68, 5.02], [1, 2.7, 1.53], [2, 2.72, 37]]}, {"timestamp": 1578696009298, "ltp": 2.62, "tv": 2554.48, "trd": NaN, "batb": [[0, 2.62, 77.14], [1, 2.6, 19.81], [2, 2.58, 17.74]], "batl": NaN}, {"timestamp": 1578696012903, "ltp": 2.62, "tv": 2554.48, "trd": NaN, "batb": [[0, 2.64, 25.56], [1, 2.62, 77.14], [2, 2.6, 19.81]], "batl": NaN}, {"timestamp": 1578696025727, "ltp": 2.62, "tv": 2554.48, "trd": NaN, "batb": [[1, 2.6, 19.81], [2, 2.58, 11.78]], "batl": NaN}, {"timestamp": 1578696036971, "ltp": 2.62, "tv": 2554.48, "trd": NaN, "batb": [[0, 2.6, 19.81], [1, 2.58, 11.78], [2, 2.56, 1.7]], "batl": NaN}, {"timestamp": 1578696037746, "ltp": 2.62, "tv": 2554.48, "trd": NaN, "batb": [[2, 2.56, 11.53]], "batl": NaN}, {"timestamp": 1578696041351, "ltp": 2.62, "tv": 2554.48, "trd": NaN, "batb": [[0, 2.62, 77.14], [1, 2.6, 19.81], [2, 2.58, 11.78]], "batl": NaN}, {"timestamp": 1578696132797, "ltp": 2.62, "tv": 2554.48, "trd": NaN, "batb": [[0, 2.64, 16.85], [1, 2.62, 77.14], [2, 2.6, 19.81]], "batl": NaN}, {"timestamp": 1578696136804, "ltp": 2.62, "tv": 2554.48, "trd": NaN, "batb": [[1, 2.6, 19.81], [2, 2.58, 11.78]], "batl": NaN}, {"timestamp": 1578696137930, "ltp": 2.72, "tv": 2588.17, "trd": [[2.66, 5.86], [2.68, 248.89], [2.7, 179.47], [2.72, 92.62]], "batb": NaN, "batl": [[0, 2.72, 26.71], [1, 2.74, 79.18], [2, 2.84, 2.5]]}, {"timestamp": 1578696187609, "ltp": 2.72, "tv": 2588.17, "trd": NaN, "batb": [[0, 2.66, 5.11], [1, 2.64, 16.85], [2, 2.6, 19.81]], "batl": NaN}, {"timestamp": 1578696320062, "ltp": 2.72, "tv": 2588.17, "trd": NaN, "batb": NaN, "batl": [[0, 2.7, 30], [1, 2.72, 26.71], [2, 2.74, 79.18]]}, {"timestamp": 1578696360995, "ltp": 2.72, "tv": 2588.17, "trd": NaN, "batb": NaN, "batl": [[0, 2.68, 1.96], [1, 2.7, 30], [2, 2.72, 26.71]]}, {"timestamp": 1578696361923, "ltp": 2.72, "tv": 2588.17, "trd": NaN, "batb": NaN, "batl": [[0, 2.7, 30], [1, 2.72, 26.71], [2, 2.74, 79.18]]}, {"timestamp": 1578696364912, "ltp": 2.66, "tv": 2592.1, "trd": [[2.66, 9.79]], "batb": [[0, 2.66, 3.14]], "batl": NaN}, {"timestamp": 1578696416949, "ltp": 2.66, "tv": 2598.1, "trd": [[2.66, 15.79]], "batb": [[0, 2.64, 17], [1, 2.6, 19.81], [2, 2.58, 11.78]], "batl": NaN}, {"timestamp": 1578696426974, "ltp": 2.66, "tv": 2598.1, "trd": NaN, "batb": [[1, 2.62, 2], [2, 2.6, 19.81]], "batl": NaN}, {"timestamp": 1578696779636, "ltp": 2.66, "tv": 2598.1, "trd": NaN, "batb": NaN, "batl": [[1, 2.72, 30.54]]}, {"timestamp": 1578696937437, "ltp": 2.66, "tv": 2598.1, "trd": NaN, "batb": NaN, "batl": [[0, 2.68, 3.83], [1, 2.7, 30], [2, 2.72, 26.71]]}, {"timestamp": 1578696939844, "ltp": 2.66, "tv": 2598.1, "trd": NaN, "batb": NaN, "batl": [[0, 2.68, 5.83]]}, {"timestamp": 1578696952967, "ltp": 2.68, "tv": 2609.75, "trd": [[2.68, 260.53]], "batb": NaN, "batl": [[0, 2.7, 30.01], [1, 2.72, 26.71], [2, 2.74, 79.18]]}, {"timestamp": 1578696985710, "ltp": 2.72, "tv": 2686.33, "trd": [[2.68, 260.55], [2.7, 239.49], [2.72, 109.16]], "batb": NaN, "batl": [[0, 2.72, 18.44], [1, 2.74, 79.18], [2, 2.84, 2.5]]}, {"timestamp": 1578696999914, "ltp": 2.72, "tv": 2686.33, "trd": NaN, "batb": [[0, 2.66, 76.12], [1, 2.64, 16.85], [2, 2.62, 2]], "batl": NaN}, {"timestamp": 1578697019263, "ltp": 2.66, "tv": 2692.33, "trd": [[2.66, 21.8]], "batb": [[0, 2.66, 73.12]], "batl": NaN}, {"timestamp": 1578697031749, "ltp": 2.66, "tv": 2692.33, "trd": NaN, "batb": [[0, 2.64, 16.85], [1, 2.62, 2], [2, 2.6, 19.81]], "batl": NaN}, {"timestamp": 1578697068004, "ltp": 2.72, "tv": 2710.7, "trd": [[2.72, 127.53]], "batb": NaN, "batl": [[0, 2.72, 9.26]]}, {"timestamp": 1578697068977, "ltp": 2.72, "tv": 2722.95, "trd": [[2.72, 139.78]], "batb": NaN, "batl": [[0, 2.72, 3.14]]}, {"timestamp": 1578697070671, "ltp": 2.72, "tv": 2722.95, "trd": NaN, "batb": NaN, "batl": [[0, 2.72, 6.2]]}, {"timestamp": 1578697073698, "ltp": 2.72, "tv": 2722.95, "trd": NaN, "batb": NaN, "batl": [[0, 2.72, 3.14]]}, {"timestamp": 1578697074981, "ltp": 2.72, "tv": 2729.24, "trd": [[2.72, 146.06]], "batb": NaN, "batl": [[0, 2.72, 3.06]]}, {"timestamp": 1578697157635, "ltp": 2.72, "tv": 2729.24, "trd": NaN, "batb": [[0, 2.66, 5.11], [1, 2.64, 16.85], [2, 2.62, 2]], "batl": NaN}, {"timestamp": 1578697203924, "ltp": 2.72, "tv": 2728.94, "trd": [[2.4, 21.11], [2.42, 126.4], [2.44, 31.98], [2.46, 9.1], [2.48, 24.07], [2.5, 535.25], [2.52, 24.68], [2.54, 19.1], [2.56, 9.72], [2.58, 308.35], [2.6, 128.69], [2.62, 216.94], [2.64, 44.36], [2.66, 21.79], [2.68, 260.54], [2.7, 239.45], [2.72, 146.04], [2.74, 128.47], [2.76, 64.26], [2.8, 107.75], [2.82, 29.77]], "batb": [[0, 2.66, 5.11], [1, 2.64, 16.84]], "batl": [[0, 2.72, 3.06]]}, {"timestamp": 1578697306081, "ltp": 2.72, "tv": 2728.94, "trd": NaN, "batb": NaN, "batl": [[1, 2.74, 59.18]]}, {"timestamp": 1578697338189, "ltp": 2.66, "tv": 2738.93, "trd": [[2.66, 31.78]], "batb": [[0, 2.64, 16.95], [1, 2.62, 2], [2, 2.6, 19.8]], "batl": NaN}, {"timestamp": 1578697340507, "ltp": 2.66, "tv": 2757.89, "trd": [[2.66, 50.74]], "batb": [[0, 2.66, 1.66], [1, 2.64, 16.84], [2, 2.62, 2]], "batl": [[1, 2.74, 49.7]]}, {"timestamp": 1578697349711, "ltp": 2.66, "tv": 2757.89, "trd": NaN, "batb": [[0, 2.66, 74.57]], "batl": NaN}, {"timestamp": 1578697355986, "ltp": 2.66, "tv": 2757.89, "trd": NaN, "batb": [[1, 2.62, 2], [2, 2.6, 19.8]], "batl": NaN}, {"timestamp": 1578697356398, "ltp": 2.66, "tv": 2757.89, "trd": NaN, "batb": [[0, 2.68, 16.84], [1, 2.66, 74.57], [2, 2.62, 2]], "batl": NaN}, {"timestamp": 1578697362303, "ltp": 2.68, "tv": 2789.9, "trd": [[2.68, 292.54]], "batb": [[0, 2.66, 75.41], [1, 2.62, 2], [2, 2.6, 19.8]], "batl": NaN}, {"timestamp": 1578697365935, "ltp": 2.68, "tv": 2789.9, "trd": NaN, "batb": [[0, 2.62, 76.87], [1, 2.6, 19.8], [2, 2.58, 11.78]], "batl": [[0, 2.72, 12.36]]}, {"timestamp": 1578697371522, "ltp": 2.68, "tv": 2789.9, "trd": NaN, "batb": [[0, 2.64, 17.68], [1, 2.62, 76.02], [2, 2.6, 19.8]], "batl": NaN}, {"timestamp": 1578697372343, "ltp": 2.68, "tv": 2789.9, "trd": NaN, "batb": [[0, 2.64, 16.84]], "batl": [[0, 2.72, 3.06]]}, {"timestamp": 1578697381608, "ltp": 2.68, "tv": 2789.9, "trd": NaN, "batb": [[0, 2.66, 72.91], [1, 2.64, 16.84], [2, 2.62, 2]], "batl": NaN}, {"timestamp": 1578697495574, "ltp": 2.68, "tv": 2789.9, "trd": NaN, "batb": [[0, 2.68, 23.83], [1, 2.66, 72.91], [2, 2.64, 16.84]], "batl": NaN}, {"timestamp": 1578697509405, "ltp": 2.68, "tv": 2789.9, "trd": NaN, "batb": [[1, 2.64, 16.84], [2, 2.62, 2]], "batl": NaN}, {"timestamp": 1578697512995, "ltp": 2.68, "tv": 2789.9, "trd": NaN, "batb": [[0, 2.64, 16.84], [1, 2.62, 2], [2, 2.6, 19.8]], "batl": NaN}, {"timestamp": 1578697524426, "ltp": 2.68, "tv": 2789.9, "trd": NaN, "batb": [[0, 2.66, 72.91], [1, 2.64, 16.84], [2, 2.62, 2]], "batl": NaN}, {"timestamp": 1578697655457, "ltp": 2.68, "tv": 2789.9, "trd": NaN, "batb": NaN, "batl": [[0, 2.72, 6.12]]}, {"timestamp": 1578697677906, "ltp": 2.68, "tv": 2789.9, "trd": NaN, "batb": [[0, 2.68, 23.83], [1, 2.66, 72.91], [2, 2.64, 16.84]], "batl": NaN}, {"timestamp": 1578697684507, "ltp": 2.68, "tv": 2789.9, "trd": NaN, "batb": [[1, 2.64, 16.84], [2, 2.62, 2]], "batl": NaN}, {"timestamp": 1578697697611, "ltp": 2.68, "tv": 2789.9, "trd": NaN, "batb": [[0, 2.64, 16.84], [1, 2.62, 2], [2, 2.6, 19.8]], "batl": NaN}, {"timestamp": 1578697700426, "ltp": 2.68, "tv": 2789.9, "trd": NaN, "batb": [[0, 2.66, 72.91], [1, 2.64, 16.84], [2, 2.62, 2]], "batl": NaN}, {"timestamp": 1578697881959, "ltp": 2.68, "tv": 2789.9, "trd": NaN, "batb": [[0, 2.68, 23.83], [1, 2.66, 72.91], [2, 2.64, 16.84]], "batl": NaN}, {"timestamp": 1578697891458, "ltp": 2.68, "tv": 2789.9, "trd": NaN, "batb": [[1, 2.64, 16.84], [2, 2.62, 2]], "batl": NaN}, {"timestamp": 1578697903683, "ltp": 2.68, "tv": 2789.9, "trd": NaN, "batb": [[0, 2.64, 16.84], [1, 2.62, 2], [2, 2.6, 19.8]], "batl": NaN}, {"timestamp": 1578697907405, "ltp": 2.68, "tv": 2789.9, "trd": NaN, "batb": [[0, 2.66, 72.91], [1, 2.64, 16.84], [2, 2.62, 2]], "batl": NaN}, {"timestamp": 1578697912998, "ltp": 2.72, "tv": 2802.15, "trd": [[2.72, 158.3]], "batb": NaN, "batl": [[0, 2.74, 49.7], [1, 2.84, 2.5], [2, 2.88, 5.32]]}, {"timestamp": 1578697914997, "ltp": 2.74, "tv": 2886.37, "trd": [[2.74, 212.68]], "batb": NaN, "batl": [[0, 2.74, 7.59]]}, {"timestamp": 1578697915615, "ltp": 2.74, "tv": 2901.54, "trd": [[2.74, 227.86]], "batb": [[0, 2.74, 11.55], [1, 2.66, 72.91], [2, 2.64, 16.84]], "batl": [[0, 2.84, 2.5], [1, 2.88, 5.32], [2, 2.92, 1.79]]}, {"timestamp": 1578697917509, "ltp": 2.74, "tv": 2901.54, "trd": NaN, "batb": [[1, 2.68, 6], [2, 2.66, 72.91]], "batl": NaN}, {"timestamp": 1578697922933, "ltp": 2.74, "tv": 2901.54, "trd": NaN, "batb": [[2, 2.64, 16.84]], "batl": NaN}, {"timestamp": 1578697927698, "ltp": 2.74, "tv": 2901.54, "trd": NaN, "batb": [[1, 2.64, 16.84], [2, 2.62, 2]], "batl": NaN}, {"timestamp": 1578697968541, "ltp": 2.74, "tv": 2901.54, "trd": NaN, "batb": [[1, 2.66, 8.36], [2, 2.64, 16.84]], "batl": NaN}, {"timestamp": 1578698037919, "ltp": 2.74, "tv": 2901.54, "trd": NaN, "batb": [[0, 2.68, 11.55]], "batl": NaN}, {"timestamp": 1578698042929, "ltp": 2.74, "tv": 2901.54, "trd": NaN, "batb": [[0, 2.66, 19.91], [1, 2.64, 16.84], [2, 2.62, 2]], "batl": NaN}, {"timestamp": 1578698050915, "ltp": 2.74, "tv": 2901.54, "trd": NaN, "batb": [[0, 2.68, 72.37], [1, 2.66, 19.91], [2, 2.64, 16.84]], "batl": NaN}, {"timestamp": 1578698052855, "ltp": 2.74, "tv": 2901.54, "trd": NaN, "batb": [[0, 2.7, 9], [1, 2.68, 72.37], [2, 2.66, 11.55]], "batl": NaN}, {"timestamp": 1578698056951, "ltp": 2.74, "tv": 2901.54, "trd": NaN, "batb": [[0, 2.72, 3], [1, 2.7, 9], [2, 2.68, 72.37]], "batl": NaN}, {"timestamp": 1578698066748, "ltp": 2.74, "tv": 2901.54, "trd": NaN, "batb": [[0, 2.72, 74.31], [2, 2.66, 11.55]], "batl": NaN}, {"timestamp": 1578698071451, "ltp": 2.74, "tv": 2901.54, "trd": NaN, "batb": [[0, 2.74, 24.69], [1, 2.72, 74.31], [2, 2.7, 9]], "batl": NaN}, {"timestamp": 1578698073445, "ltp": 2.74, "tv": 2901.54, "trd": NaN, "batb": [[0, 2.76, 3], [1, 2.74, 24.69], [2, 2.72, 71.31]], "batl": NaN}, {"timestamp": 1578698082361, "ltp": 2.74, "tv": 2901.54, "trd": NaN, "batb": [[2, 2.7, 9]], "batl": NaN}, {"timestamp": 1578698088959, "ltp": 2.74, "tv": 2901.54, "trd": NaN, "batb": [[1, 2.7, 9], [2, 2.66, 11.55]], "batl": NaN}, {"timestamp": 1578698089776, "ltp": 2.74, "tv": 2901.54, "trd": NaN, "batb": [[0, 2.7, 9], [1, 2.66, 11.55], [2, 2.64, 16.84]], "batl": [[0, 2.82, 9.07], [1, 2.84, 2.5], [2, 2.88, 5.32]]}, {"timestamp": 1578698133836, "ltp": 2.74, "tv": 2901.54, "trd": NaN, "batb": [[0, 2.68, 11.4]], "batl": NaN}, {"timestamp": 1578698145440, "ltp": 2.74, "tv": 2901.54, "trd": NaN, "batb": [[0, 2.7, 71.83], [1, 2.68, 11.4], [2, 2.66, 11.55]], "batl": NaN}, {"timestamp": 1578698150768, "ltp": 2.74, "tv": 2901.54, "trd": NaN, "batb": [[0, 2.72, 3], [1, 2.7, 71.83], [2, 2.68, 11.4]], "batl": NaN}, {"timestamp": 1578698175566, "ltp": 2.74, "tv": 2901.54, "trd": NaN, "batb": [[0, 2.72, 14.55]], "batl": [[0, 2.84, 2.5], [1, 2.88, 5.32], [2, 2.92, 1.79]]}, {"timestamp": 1578698177671, "ltp": 2.74, "tv": 2901.54, "trd": NaN, "batb": [[0, 2.74, 70.78], [1, 2.72, 14.55]], "batl": NaN}, {"timestamp": 1578698194375, "ltp": 2.74, "tv": 2901.54, "trd": NaN, "batb": [[0, 2.76, 3], [1, 2.74, 70.78], [2, 2.72, 11.55]], "batl": NaN}, {"timestamp": 1578698209511, "ltp": 2.74, "tv": 2901.54, "trd": NaN, "batb": [[1, 2.72, 11.55], [2, 2.68, 11.4]], "batl": NaN}, {"timestamp": 1578698216791, "ltp": 2.74, "tv": 2901.54, "trd": NaN, "batb": [[0, 2.72, 11.55], [1, 2.68, 11.4], [2, 2.64, 16.84]], "batl": NaN}, {"timestamp": 1578698225533, "ltp": 2.74, "tv": 2901.54, "trd": NaN, "batb": [[0, 2.74, 70.78], [1, 2.72, 11.55], [2, 2.68, 11.4]], "batl": NaN}, {"timestamp": 1578698246878, "ltp": 2.88, "tv": 2907.66, "trd": [[2.84, 5], [2.88, 1.12]], "batb": NaN, "batl": [[0, 2.88, 4.76], [1, 2.92, 1.79], [2, 2.94, 12.5]]}, {"timestamp": 1578698247753, "ltp": 2.88, "tv": 2907.66, "trd": NaN, "batb": NaN, "batl": [[0, 2.86, 2], [1, 2.88, 4.76], [2, 2.92, 1.79]]}, {"timestamp": 1578698258354, "ltp": 2.88, "tv": 2907.66, "trd": NaN, "batb": [[0, 2.76, 22.98], [1, 2.74, 70.78], [2, 2.72, 11.55]], "batl": NaN}, {"timestamp": 1578698266591, "ltp": 2.88, "tv": 2907.66, "trd": NaN, "batb": [[0, 2.78, 3], [1, 2.76, 22.98], [2, 2.74, 70.78]], "batl": NaN}, {"timestamp": 1578698272797, "ltp": 2.78, "tv": 2913.66, "trd": [[2.78, 237.12]], "batb": [[0, 2.76, 22.98], [1, 2.74, 70.78], [2, 2.72, 11.55]], "batl": [[0, 2.78, 2], [1, 2.86, 2], [2, 2.88, 4.76]]}, {"timestamp": 1578698273571, "ltp": 2.78, "tv": 2913.66, "trd": NaN, "batb": [[1, 2.72, 11.55], [2, 2.68, 11.4]], "batl": NaN}, {"timestamp": 1578698278595, "ltp": 2.78, "tv": 2913.66, "trd": NaN, "batb": [[0, 2.72, 11.55], [1, 2.68, 11.4], [2, 2.64, 16.84]], "batl": NaN}, {"timestamp": 1578698283778, "ltp": 2.78, "tv": 2913.66, "trd": NaN, "batb": [[0, 2.7, 11.55]], "batl": NaN}, {"timestamp": 1578698288281, "ltp": 2.78, "tv": 2913.66, "trd": NaN, "batb": NaN, "batl": [[1, 2.84, 2.94], [2, 2.86, 2]]}, {"timestamp": 1578698299001, "ltp": 2.78, "tv": 2913.66, "trd": NaN, "batb": [[0, 2.72, 10.01], [1, 2.7, 11.55]], "batl": NaN}, {"timestamp": 1578698430455, "ltp": 2.78, "tv": 2913.66, "trd": NaN, "batb": [[0, 2.74, 6.37], [1, 2.72, 10.01], [2, 2.7, 11.55]], "batl": NaN}, {"timestamp": 1578698444886, "ltp": 2.78, "tv": 2913.66, "trd": NaN, "batb": [[0, 2.74, 11.47]], "batl": NaN}, {"timestamp": 1578698501548, "ltp": 2.78, "tv": 2913.66, "trd": NaN, "batb": [[0, 2.74, 6.37]], "batl": NaN}, {"timestamp": 1578698580839, "ltp": 2.78, "tv": 2913.66, "trd": NaN, "batb": NaN, "batl": [[1, 2.86, 4.92], [2, 2.88, 4.76]]}, {"timestamp": 1578698584481, "ltp": 2.78, "tv": 2913.66, "trd": NaN, "batb": NaN, "batl": [[1, 2.86, 2.92]]}, {"timestamp": 1578698737727, "ltp": 2.78, "tv": 2917.66, "trd": [[2.78, 241.12]], "batb": [[0, 2.78, 1.06], [1, 2.74, 6.37], [2, 2.72, 10.01]], "batl": [[0, 2.84, 9.02]]}, {"timestamp": 1578698739735, "ltp": 2.84, "tv": 2929.91, "trd": [[2.84, 17.25]], "batb": NaN, "batl": [[0, 2.84, 2.9]]}, {"timestamp": 1578698740602, "ltp": 2.86, "tv": 2936.03, "trd": [[2.84, 23.05], [2.86, 0.32]], "batb": NaN, "batl": [[0, 2.86, 2.76], [1, 2.88, 4.76], [2, 2.92, 1.79]]}, {"timestamp": 1578698742508, "ltp": 2.88, "tv": 2948.27, "trd": [[2.86, 5.84], [2.88, 7.84]], "batb": [[0, 2.8, 10.87], [1, 2.78, 1.06], [2, 2.74, 6.37]], "batl": [[0, 2.88, 1.4], [1, 2.92, 1.79], [2, 2.94, 12.5]]}, {"timestamp": 1578698744816, "ltp": 2.92, "tv": 2954.4, "trd": [[2.88, 10.64], [2.92, 3.32]], "batb": NaN, "batl": [[0, 2.94, 12.63], [1, 2.98, 5.05], [2, 3.05, 2.5]]}, {"timestamp": 1578698746618, "ltp": 2.92, "tv": 2954.4, "trd": NaN, "batb": NaN, "batl": [[0, 2.92, 3.19], [1, 2.94, 12.5], [2, 2.98, 5.05]]}, {"timestamp": 1578698873906, "ltp": 2.92, "tv": 2960.78, "trd": [[2.92, 9.71]], "batb": NaN, "batl": [[0, 2.94, 12.5], [1, 2.98, 5.05], [2, 3.05, 2.5]]}, {"timestamp": 1578698877968, "ltp": 2.92, "tv": 2960.78, "trd": NaN, "batb": [[2, 2.7, 11.55]], "batl": NaN}, {"timestamp": 1578698878430, "ltp": 2.92, "tv": 2960.78, "trd": NaN, "batb": [[0, 2.82, 6.19], [1, 2.8, 10.87], [2, 2.78, 1.06]], "batl": NaN}, {"timestamp": 1578698888945, "ltp": 2.94, "tv": 2985.78, "trd": [[2.94, 25]], "batb": NaN, "batl": [[0, 2.98, 5.05], [1, 3.05, 2.5], [2, 3.15, 2.5]]}, {"timestamp": 1578698907953, "ltp": 2.94, "tv": 2985.78, "trd": NaN, "batb": NaN, "batl": [[0, 2.96, 2], [1, 2.98, 5.05], [2, 3.05, 2.5]]}, {"timestamp": 1578699216361, "ltp": 2.94, "tv": 2985.78, "trd": NaN, "batb": [[0, 2.84, 1.84], [1, 2.82, 6.19], [2, 2.8, 10.87]], "batl": NaN}, {"timestamp": 1578699295834, "ltp": 2.94, "tv": 2985.78, "trd": NaN, "batb": NaN, "batl": [[0, 2.9, 3.74], [1, 2.96, 2], [2, 2.98, 5.05]]}, {"timestamp": 1578699296962, "ltp": 2.94, "tv": 2985.78, "trd": NaN, "batb": NaN, "batl": [[0, 2.96, 2], [1, 2.98, 5.05], [2, 3.05, 2.5]]}, {"timestamp": 1578699323953, "ltp": 2.94, "tv": 2985.78, "trd": NaN, "batb": [[0, 2.84, 6.74]], "batl": NaN}, {"timestamp": 1578699358693, "ltp": 2.94, "tv": 2985.78, "trd": NaN, "batb": [[0, 2.86, 6.1], [1, 2.84, 6.74]], "batl": NaN}, {"timestamp": 1578699384633, "ltp": 2.94, "tv": 2985.78, "trd": NaN, "batb": NaN, "batl": [[0, 2.98, 5.05], [1, 3.05, 2.5], [2, 3.15, 2.5]]}, {"timestamp": 1578699507482, "ltp": 2.86, "tv": 2989.78, "trd": [[2.86, 9.84]], "batb": [[0, 2.86, 4.1]], "batl": NaN}, {"timestamp": 1578699543971, "ltp": 3.05, "tv": 3004.89, "trd": [[2.98, 10.1], [3.05, 5]], "batb": [[0, 2.86, 4.2]], "batl": [[0, 3.15, 2.5], [1, 3.25, 2.5], [2, 4, 32.04]]}, {"timestamp": 1578699544789, "ltp": 3.05, "tv": 3004.89, "trd": NaN, "batb": [[0, 3.1, 4.92], [1, 2.86, 4.2], [2, 2.84, 6.74]], "batl": NaN}, {"timestamp": 1578699545866, "ltp": 3.1, "tv": 3008.89, "trd": [[3.1, 4]], "batb": [[0, 3.1, 2.92], [1, 2.86, 4.1]], "batl": NaN}, {"timestamp": 1578699546581, "ltp": 3.1, "tv": 3012.89, "trd": [[3.1, 8]], "batb": [[0, 2.86, 5.02], [1, 2.84, 6.74], [2, 2.66, 11.55]], "batl": NaN}, {"timestamp": 1578699548286, "ltp": 3.1, "tv": 3014.73, "trd": [[3.1, 9.84]], "batb": [[0, 2.86, 4.1]], "batl": NaN}, {"timestamp": 1578699549978, "ltp": 3.25, "tv": 3022.37, "trd": [[3.15, 5], [3.25, 2.64]], "batb": NaN, "batl": [[0, 3.25, 1.18], [1, 4, 32.04], [2, 6.6, 2]]}, {"timestamp": 1578699550482, "ltp": 3.25, "tv": 3022.37, "trd": NaN, "batb": NaN, "batl": [[0, 3.25, 1.37]]}, {"timestamp": 1578699574895, "ltp": 3.25, "tv": 3022.37, "trd": NaN, "batb": NaN, "batl": [[1, 3.95, 2], [2, 4, 32.04]]}, {"timestamp": 1578699584943, "ltp": 3.25, "tv": 3022.37, "trd": NaN, "batb": NaN, "batl": [[1, 3.9, 9.62], [2, 3.95, 2]]}, {"timestamp": 1578699623378, "ltp": 3.25, "tv": 3022.37, "trd": NaN, "batb": NaN, "batl": [[1, 3.85, 2], [2, 3.9, 9.62]]}, {"timestamp": 1578699626749, "ltp": 3.25, "tv": 3022.37, "trd": NaN, "batb": NaN, "batl": [[2, 4, 32.04]]}, {"timestamp": 1578699705945, "ltp": 3.25, "tv": 3025.12, "trd": [[3.2, 0.38], [3.25, 5]], "batb": [[0, 2.86, 4.26]], "batl": [[0, 3.85, 2], [1, 4, 32.04], [2, 6.6, 2]]}, {"timestamp": 1578699706259, "ltp": 3.25, "tv": 3025.12, "trd": NaN, "batb": NaN, "batl": [[0, 3.8, 4.7], [1, 3.85, 2], [2, 4, 32.04]]}, {"timestamp": 1578699707947, "ltp": 3.25, "tv": 3025.12, "trd": NaN, "batb": NaN, "batl": [[0, 3.8, 4.9]]}, {"timestamp": 1578699715678, "ltp": 3.0, "tv": 3041.7, "trd": [[3, 16.26], [3.25, 5.33]], "batb": [[0, 2.88, 5.34], [1, 2.86, 4.1], [2, 2.84, 6.74]], "batl": [[0, 3.85, 2.22], [1, 4, 32.04], [2, 6.6, 2]]}, {"timestamp": 1578699717977, "ltp": 3.0, "tv": 3041.7, "trd": NaN, "batb": NaN, "batl": [[0, 3.85, 2.02]]}, {"timestamp": 1578699719968, "ltp": 3.0, "tv": 3041.7, "trd": NaN, "batb": NaN, "batl": [[0, 3.1, 8.15], [1, 3.95, 2], [2, 4, 32.04]]}, {"timestamp": 1578699725546, "ltp": 3.0, "tv": 3041.7, "trd": NaN, "batb": [[0, 2.88, 72.69]], "batl": NaN}, {"timestamp": 1578699726926, "ltp": 2.88, "tv": 3049.7, "trd": [[2.88, 18.64]], "batb": [[0, 2.88, 68.69]], "batl": NaN}, {"timestamp": 1578699727950, "ltp": 2.88, "tv": 3053.7, "trd": [[2.88, 22.64]], "batb": [[0, 2.88, 66.69]], "batl": NaN}, {"timestamp": 1578699729976, "ltp": 2.88, "tv": 3053.7, "trd": NaN, "batb": NaN, "batl": [[1, 3.45, 45.93], [2, 3.95, 2]]}, {"timestamp": 1578699731537, "ltp": 2.88, "tv": 3053.7, "trd": NaN, "batb": NaN, "batl": [[1, 3.4, 45.93]]}, {"timestamp": 1578699732964, "ltp": 3.1, "tv": 3069.01, "trd": [[3, 16.29], [3.1, 25.12]], "batb": NaN, "batl": [[0, 3.4, 46.42], [1, 3.95, 2], [2, 4, 32.04]]}, {"timestamp": 1578699741946, "ltp": 3.1, "tv": 3069.01, "trd": NaN, "batb": [[0, 2.86, 4.1], [1, 2.84, 6.74], [2, 2.66, 11.55]], "batl": NaN}, {"timestamp": 1578699742763, "ltp": 3.1, "tv": 3069.01, "trd": NaN, "batb": NaN, "batl": [[0, 3.35, 4.49], [1, 3.4, 45.93], [2, 3.95, 2]]}, {"timestamp": 1578699748348, "ltp": 3.1, "tv": 3069.01, "trd": NaN, "batb": NaN, "batl": [[0, 3.35, 35.11]]}, {"timestamp": 1578699757889, "ltp": 3.1, "tv": 3069.01, "trd": NaN, "batb": NaN, "batl": [[0, 3.35, 81.05], [1, 3.95, 2], [2, 4, 32.04]]}, {"timestamp": 1578699764604, "ltp": 3.1, "tv": 3069.01, "trd": NaN, "batb": NaN, "batl": [[0, 3.35, 96.36]]}, {"timestamp": 1578699767981, "ltp": 3.1, "tv": 3069.01, "trd": NaN, "batb": NaN, "batl": [[0, 3.3, 2.49], [1, 3.35, 95.87]]}, {"timestamp": 1578699772912, "ltp": 3.3, "tv": 3072.07, "trd": [[3.1, 26.1], [3.3, 2.08]], "batb": NaN, "batl": [[0, 3.3, 10.63]]}, {"timestamp": 1578699775369, "ltp": 3.3, "tv": 3072.07, "trd": NaN, "batb": NaN, "batl": [[1, 3.35, 49.93]]}, {"timestamp": 1578699777003, "ltp": 3.3, "tv": 3072.07, "trd": NaN, "batb": NaN, "batl": [[0, 3.3, 10.83]]}, {"timestamp": 1578699786885, "ltp": 3.3, "tv": 3072.07, "trd": NaN, "batb": NaN, "batl": [[0, 3.25, 4.2], [1, 3.3, 10.63], [2, 3.35, 45.93]]}, {"timestamp": 1578699787396, "ltp": 3.3, "tv": 3072.07, "trd": NaN, "batb": NaN, "batl": [[0, 3.25, 7.26]]}, {"timestamp": 1578699801922, "ltp": 3.3, "tv": 3072.07, "trd": NaN, "batb": NaN, "batl": [[1, 3.3, 56.56], [2, 4, 32.04]]}, {"timestamp": 1578699815922, "ltp": 3.3, "tv": 3072.07, "trd": NaN, "batb": NaN, "batl": [[0, 3.2, 2.2], [1, 3.25, 7.06], [2, 3.3, 55.6]]}, {"timestamp": 1578699822964, "ltp": 3.3, "tv": 3072.07, "trd": NaN, "batb": NaN, "batl": [[0, 3.2, 48.13], [2, 3.3, 9.67]]}, {"timestamp": 1578699834662, "ltp": 3.2, "tv": 3168.33, "trd": [[3.15, 5.4], [3.2, 96.25]], "batb": [[0, 2.86, 4.11]], "batl": [[0, 3.25, 7.06], [1, 3.3, 9.67], [2, 4, 32.04]]}, {"timestamp": 1578699835943, "ltp": 3.2, "tv": 3168.35, "trd": [[3.2, 96.27]], "batb": [[0, 2.86, 4.1]], "batl": [[0, 3.25, 7.23]]}, {"timestamp": 1578699836967, "ltp": 3.2, "tv": 3168.35, "trd": NaN, "batb": NaN, "batl": [[0, 3.25, 3.23]]}, {"timestamp": 1578699864510, "ltp": 3.2, "tv": 3168.35, "trd": NaN, "batb": [[0, 2.88, 3.41], [1, 2.86, 4.1], [2, 2.84, 6.74]], "batl": [[1, 4, 32.04], [2, 6.6, 2]]}, {"timestamp": 1578699868810, "ltp": 3.2, "tv": 3168.35, "trd": NaN, "batb": NaN, "batl": [[1, 3.5, 4], [2, 4, 32.04]]}, {"timestamp": 1578699877999, "ltp": 3.2, "tv": 3168.35, "trd": NaN, "batb": NaN, "batl": [[0, 3.5, 4.17], [1, 4, 32.04], [2, 6.6, 2]]}, {"timestamp": 1578699884001, "ltp": 3.2, "tv": 3168.35, "trd": NaN, "batb": NaN, "batl": [[0, 3.15, 10], [1, 3.2, 72.55], [2, 3.5, 4.17]]}, {"timestamp": 1578699885705, "ltp": 3.2, "tv": 3168.35, "trd": NaN, "batb": NaN, "batl": [[0, 3.1, 4], [1, 3.15, 10], [2, 3.2, 72.55]]}, {"timestamp": 1578699887703, "ltp": 3.2, "tv": 3168.35, "trd": NaN, "batb": NaN, "batl": [[2, 3.5, 4.17]]}, {"timestamp": 1578699907947, "ltp": 3.2, "tv": 3168.35, "trd": NaN, "batb": NaN, "batl": [[0, 3.15, 10], [1, 3.5, 4.17], [2, 4, 32.04]]}, {"timestamp": 1578699938671, "ltp": 3.2, "tv": 3168.35, "trd": NaN, "batb": [[2, 2.84, 1.84]], "batl": NaN}, {"timestamp": 1578700025266, "ltp": 3.2, "tv": 3168.35, "trd": NaN, "batb": NaN, "batl": [[2, 4.1, 9.02]]}, {"timestamp": 1578700248603, "ltp": 3.2, "tv": 3168.35, "trd": NaN, "batb": [[0, 2.88, 70.1]], "batl": [[0, 3.5, 4.17], [1, 4.1, 9.02], [2, 4.5, 32.04]]}, {"timestamp": 1578700259919, "ltp": 3.2, "tv": 3168.35, "trd": NaN, "batb": [[0, 2.9, 2.42], [1, 2.88, 70.1], [2, 2.86, 4.1]], "batl": NaN}, {"timestamp": 1578700269948, "ltp": 3.2, "tv": 3168.35, "trd": NaN, "batb": [[0, 2.9, 5.42], [1, 2.88, 3.41]], "batl": NaN}, {"timestamp": 1578700284871, "ltp": 3.2, "tv": 3168.35, "trd": NaN, "batb": NaN, "batl": [[1, 4.5, 32.04], [2, 6.6, 2]]}, {"timestamp": 1578700286770, "ltp": 3.2, "tv": 3168.35, "trd": NaN, "batb": [[0, 2.92, 3.36], [1, 2.9, 5.42]], "batl": NaN}, {"timestamp": 1578700296988, "ltp": 3.2, "tv": 3168.35, "trd": NaN, "batb": [[1, 2.9, 2.42], [2, 2.86, 7.1]], "batl": NaN}, {"timestamp": 1578700326585, "ltp": 2.92, "tv": 3175.07, "trd": [[2.92, 16.43]], "batb": [[0, 2.9, 2.42], [1, 2.86, 7.1], [2, 2.84, 1.84]], "batl": [[0, 2.92, 7.21], [1, 2.94, 8.51], [2, 3.5, 4.17]]}, {"timestamp": 1578700327710, "ltp": 2.92, "tv": 3175.07, "trd": NaN, "batb": NaN, "batl": [[2, 3.5, 4]]}, {"timestamp": 1578700331609, "ltp": 2.92, "tv": 3175.07, "trd": NaN, "batb": NaN, "batl": [[0, 2.92, 15.72]]}, {"timestamp": 1578700340810, "ltp": 2.92, "tv": 3175.07, "trd": NaN, "batb": [[1, 2.86, 4.1]], "batl": NaN}, {"timestamp": 1578700350602, "ltp": 2.92, "tv": 3175.07, "trd": NaN, "batb": [[0, 2.9, 14.16]], "batl": NaN}, {"timestamp": 1578700414903, "ltp": 2.94, "tv": 3213.31, "trd": [[2.92, 47.87], [2.94, 31.8]], "batb": [[0, 2.92, 85.28], [1, 2.9, 14.16], [2, 2.86, 4.1]], "batl": [[0, 2.94, 5.12], [1, 3.5, 4], [2, 4.5, 32.04]]}, {"timestamp": 1578700415006, "ltp": 2.94, "tv": 3223.55, "trd": [[2.94, 42.03]], "batb": [[0, 2.94, 2.04], [1, 2.92, 85.28], [2, 2.9, 14.16]], "batl": [[0, 3.5, 4], [1, 4.5, 32.04], [2, 6.6, 2]]}, {"timestamp": 1578700417989, "ltp": 2.94, "tv": 3223.55, "trd": NaN, "batb": NaN, "batl": [[0, 3.5, 4.2]]}, {"timestamp": 1578700420188, "ltp": 2.94, "tv": 3223.55, "trd": NaN, "batb": NaN, "batl": [[1, 4.5, 41.06], [2, 5.4, 26.02]]}, {"timestamp": 1578700421986, "ltp": 2.94, "tv": 3223.55, "trd": NaN, "batb": [[0, 2.94, 5.04]], "batl": NaN}, {"timestamp": 1578700430798, "ltp": 2.94, "tv": 3223.55, "trd": NaN, "batb": NaN, "batl": [[0, 3.45, 2.2], [1, 3.5, 4], [2, 4.5, 41.06]]}, {"timestamp": 1578700634406, "ltp": 2.94, "tv": 3223.55, "trd": NaN, "batb": NaN, "batl": [[0, 3.4, 5.2], [1, 3.45, 2], [2, 3.5, 4]]}, {"timestamp": 1578700635982, "ltp": 2.94, "tv": 3223.55, "trd": NaN, "batb": NaN, "batl": [[1, 3.5, 4], [2, 4.5, 41.06]]}, {"timestamp": 1578700636906, "ltp": 2.94, "tv": 3223.55, "trd": NaN, "batb": NaN, "batl": [[0, 3.35, 2], [1, 3.4, 5.2], [2, 3.5, 4]]}, {"timestamp": 1578700639207, "ltp": 2.94, "tv": 3223.55, "trd": NaN, "batb": NaN, "batl": [[0, 3.35, 2.2], [1, 3.4, 5]]}, {"timestamp": 1578700644035, "ltp": 2.94, "tv": 3223.55, "trd": NaN, "batb": NaN, "batl": [[0, 3.35, 7.2]]}, {"timestamp": 1578700650542, "ltp": 2.94, "tv": 3223.55, "trd": NaN, "batb": NaN, "batl": [[0, 3.3, 5.2], [1, 3.35, 7], [2, 3.4, 5]]}, {"timestamp": 1578700656735, "ltp": 2.94, "tv": 3223.55, "trd": NaN, "batb": NaN, "batl": [[0, 3.25, 5], [1, 3.3, 5.2], [2, 3.35, 7]]}, {"timestamp": 1578700664618, "ltp": 2.94, "tv": 3223.55, "trd": NaN, "batb": NaN, "batl": [[0, 3.2, 4], [1, 3.25, 5], [2, 3.3, 5.2]]}, {"timestamp": 1578700669335, "ltp": 2.94, "tv": 3223.55, "trd": NaN, "batb": NaN, "batl": [[0, 3.15, 4], [1, 3.2, 4], [2, 3.25, 5]]}, {"timestamp": 1578700673945, "ltp": 2.94, "tv": 3223.55, "trd": NaN, "batb": NaN, "batl": [[0, 3.1, 3], [1, 3.15, 4], [2, 3.2, 4]]}, {"timestamp": 1578700677835, "ltp": 2.94, "tv": 3223.55, "trd": NaN, "batb": NaN, "batl": [[0, 3, 3], [1, 3.1, 3], [2, 3.15, 4]]}, {"timestamp": 1578700697358, "ltp": 2.94, "tv": 3223.55, "trd": NaN, "batb": NaN, "batl": [[0, 2.98, 5.05], [1, 3, 3], [2, 3.1, 3]]}, {"timestamp": 1578700758968, "ltp": 3.1, "tv": 3239.79, "trd": [[2.98, 20.21], [3, 22.29], [3.1, 26.24]], "batb": NaN, "batl": [[0, 3.1, 2.93], [1, 3.15, 4], [2, 3.2, 4]]}, {"timestamp": 1578700759374, "ltp": 3.15, "tv": 3245.91, "trd": [[3.1, 32.1], [3.15, 5.66]], "batb": NaN, "batl": [[0, 3.15, 3.87], [1, 3.2, 4], [2, 3.25, 5]]}, {"timestamp": 1578700760761, "ltp": 3.2, "tv": 3259.78, "trd": [[3.15, 13.4], [3.2, 102.39]], "batb": NaN, "batl": [[0, 3.25, 5.94], [1, 3.3, 5], [2, 3.35, 5]]}, {"timestamp": 1578700762558, "ltp": 3.3, "tv": 3281.66, "trd": [[3.2, 104.27], [3.25, 15.33], [3.3, 12.09]], "batb": NaN, "batl": [[0, 3.35, 5], [1, 3.4, 5], [2, 3.5, 4]]}, {"timestamp": 1578700763476, "ltp": 3.3, "tv": 3281.66, "trd": NaN, "batb": NaN, "batl": [[0, 3.3, 21.73], [1, 3.35, 5], [2, 3.4, 5]]}, {"timestamp": 1578700767842, "ltp": 2.98, "tv": 3285.66, "trd": [[2.98, 24.21]], "batb": NaN, "batl": NaN}, {"timestamp": 1578700768660, "ltp": 2.98, "tv": 3285.66, "trd": NaN, "batb": NaN, "batl": [[0, 3.3, 90.64]]}, {"timestamp": 1578700778468, "ltp": 2.98, "tv": 3285.66, "trd": NaN, "batb": NaN, "batl": [[0, 3.3, 68.9]]}, {"timestamp": 1578700781595, "ltp": 2.98, "tv": 3285.66, "trd": NaN, "batb": [[0, 2.94, 3]], "batl": [[0, 3.25, 16.74], [1, 3.3, 114.84], [2, 3.35, 5]]}, {"timestamp": 1578700782991, "ltp": 2.98, "tv": 3285.66, "trd": NaN, "batb": NaN, "batl": [[1, 3.3, 68.9]]}, {"timestamp": 1578700783402, "ltp": 2.98, "tv": 3285.66, "trd": NaN, "batb": NaN, "batl": [[0, 3.25, 131.58], [1, 3.35, 5], [2, 3.4, 5]]}, {"timestamp": 1578700793933, "ltp": 2.98, "tv": 3285.66, "trd": NaN, "batb": [[0, 2.92, 85.28], [1, 2.9, 14.16], [2, 2.86, 4.1]], "batl": [[0, 3.2, 4], [1, 3.25, 131.58], [2, 3.35, 5]]}, {"timestamp": 1578700794918, "ltp": 3.2, "tv": 3293.66, "trd": [[3.2, 112.27]], "batb": NaN, "batl": [[0, 3.25, 131.58], [1, 3.35, 5], [2, 3.4, 5]]}, {"timestamp": 1578700795938, "ltp": 3.2, "tv": 3293.66, "trd": NaN, "batb": NaN, "batl": [[0, 3.2, 45.93], [1, 3.25, 85.64], [2, 3.35, 5]]}, {"timestamp": 1578700796917, "ltp": 3.2, "tv": 3293.66, "trd": NaN, "batb": NaN, "batl": [[1, 3.25, 76.88]]}, {"timestamp": 1578700797947, "ltp": 3.2, "tv": 3293.66, "trd": NaN, "batb": NaN, "batl": [[0, 3.2, 114.84], [1, 3.25, 7.98]]}, {"timestamp": 1578700798923, "ltp": 3.2, "tv": 3293.66, "trd": NaN, "batb": NaN, "batl": [[0, 3.2, 68.9], [2, 3.3, 45.93]]}, {"timestamp": 1578700804712, "ltp": 3.2, "tv": 3293.66, "trd": NaN, "batb": NaN, "batl": [[0, 3.25, 7.98], [1, 3.3, 45.93], [2, 3.35, 5]]}, {"timestamp": 1578700805743, "ltp": 3.2, "tv": 3293.66, "trd": NaN, "batb": NaN, "batl": [[0, 3.25, 76.88]]}, {"timestamp": 1578700808940, "ltp": 3.2, "tv": 3293.66, "trd": NaN, "batb": NaN, "batl": [[0, 3.25, 7.98]]}, {"timestamp": 1578700809451, "ltp": 3.2, "tv": 3293.66, "trd": NaN, "batb": [[0, 2.94, 2.04], [1, 2.92, 85.28], [2, 2.9, 14.16]], "batl": [[0, 3.35, 5], [1, 3.4, 50.93], [2, 3.5, 4]]}, {"timestamp": 1578700810532, "ltp": 3.2, "tv": 3293.66, "trd": NaN, "batb": [[0, 2.94, 67.36]], "batl": NaN}, {"timestamp": 1578700811611, "ltp": 3.2, "tv": 3293.66, "trd": NaN, "batb": NaN, "batl": [[0, 3.35, 5.18]]}, {"timestamp": 1578700815831, "ltp": 3.2, "tv": 3293.66, "trd": NaN, "batb": [[0, 2.96, 4.32], [1, 2.94, 67.36], [2, 2.92, 85.28]], "batl": NaN}, {"timestamp": 1578700818963, "ltp": 3.2, "tv": 3293.66, "trd": NaN, "batb": NaN, "batl": [[1, 3.4, 5], [2, 3.5, 49.93]]}, {"timestamp": 1578700824876, "ltp": 3.2, "tv": 3293.66, "trd": NaN, "batb": NaN, "batl": [[0, 3.3, 3.18], [1, 3.35, 5], [2, 3.4, 5]]}, {"timestamp": 1578700834285, "ltp": 3.2, "tv": 3293.66, "trd": NaN, "batb": NaN, "batl": [[0, 3.25, 3], [1, 3.3, 3.18], [2, 3.35, 5]]}, {"timestamp": 1578700838959, "ltp": 3.2, "tv": 3293.66, "trd": NaN, "batb": [[0, 2.96, 7.32]], "batl": NaN}, {"timestamp": 1578700842460, "ltp": 3.2, "tv": 3293.66, "trd": NaN, "batb": [[0, 2.96, 72.2], [1, 2.94, 2.04]], "batl": NaN}, {"timestamp": 1578700853678, "ltp": 3.2, "tv": 3293.66, "trd": NaN, "batb": [[1, 2.94, 8.73]], "batl": NaN}, {"timestamp": 1578700898734, "ltp": 3.25, "tv": 3299.66, "trd": [[3.25, 21.33]], "batb": NaN, "batl": [[0, 3.3, 3.18], [1, 3.35, 5], [2, 3.4, 5]]}, {"timestamp": 1578700921702, "ltp": 3.25, "tv": 3299.66, "trd": NaN, "batb": NaN, "batl": [[0, 3.25, 2], [1, 3.3, 3.18], [2, 3.35, 5]]}, {"timestamp": 1578701005937, "ltp": 3.25, "tv": 3299.66, "trd": NaN, "batb": NaN, "batl": [[0, 3.2, 68.9], [1, 3.25, 2], [2, 3.3, 3]]}, {"timestamp": 1578701012938, "ltp": 3.25, "tv": 3299.66, "trd": NaN, "batb": NaN, "batl": [[0, 3.15, 8.55], [1, 3.2, 114.84], [2, 3.25, 2]]}, {"timestamp": 1578701019756, "ltp": 3.15, "tv": 3316.78, "trd": [[3.15, 30.52]], "batb": NaN, "batl": [[0, 3.2, 114.84], [1, 3.25, 2], [2, 3.3, 3]]}, {"timestamp": 1578701020324, "ltp": 3.15, "tv": 3316.78, "trd": NaN, "batb": [[1, 2.94, 17.9]], "batl": NaN}, {"timestamp": 1578701045725, "ltp": 3.15, "tv": 3316.78, "trd": NaN, "batb": NaN, "batl": [[0, 3.2, 45.93]]}, {"timestamp": 1578701066708, "ltp": 3.15, "tv": 3316.78, "trd": NaN, "batb": NaN, "batl": [[0, 3.25, 2], [1, 3.3, 3], [2, 3.35, 50.93]]}, {"timestamp": 1578701086487, "ltp": 3.15, "tv": 3316.78, "trd": NaN, "batb": NaN, "batl": [[0, 3.2, 2], [1, 3.25, 2], [2, 3.3, 3]]}, {"timestamp": 1578701159919, "ltp": 3.15, "tv": 3316.78, "trd": NaN, "batb": [[0, 2.98, 9], [1, 2.96, 72.2], [2, 2.94, 11.21]], "batl": NaN}, {"timestamp": 1578701161817, "ltp": 3.15, "tv": 3316.78, "trd": NaN, "batb": [[0, 3, 64.02], [1, 2.98, 9], [2, 2.96, 7.32]], "batl": NaN}, {"timestamp": 1578701163001, "ltp": 3.15, "tv": 3316.78, "trd": NaN, "batb": [[0, 3.05, 4.2], [1, 3, 64.02], [2, 2.98, 9]], "batl": NaN}, {"timestamp": 1578701176742, "ltp": 3.15, "tv": 3316.78, "trd": NaN, "batb": [[1, 2.98, 9], [2, 2.94, 11.21]], "batl": NaN}, {"timestamp": 1578701181863, "ltp": 3.15, "tv": 3316.78, "trd": NaN, "batb": NaN, "batl": [[0, 3.25, 2], [1, 3.3, 3], [2, 3.35, 50.93]]}, {"timestamp": 1578701182326, "ltp": 3.15, "tv": 3316.78, "trd": NaN, "batb": [[2, 2.94, 9.17]], "batl": [[1, 3.3, 10.9]]}, {"timestamp": 1578701185350, "ltp": 3.15, "tv": 3316.78, "trd": NaN, "batb": [[0, 3, 4.27]], "batl": NaN}, {"timestamp": 1578701192439, "ltp": 3.15, "tv": 3316.78, "trd": NaN, "batb": [[0, 3, 68.29]], "batl": NaN}, {"timestamp": 1578701336735, "ltp": 3.15, "tv": 3316.78, "trd": NaN, "batb": [[0, 3.05, 3], [1, 3, 68.29], [2, 2.98, 9]], "batl": NaN}, {"timestamp": 1578701427928, "ltp": 3.15, "tv": 3316.78, "trd": NaN, "batb": [[2, 2.94, 9.17]], "batl": NaN}, {"timestamp": 1578701513454, "ltp": 3.15, "tv": 3316.78, "trd": NaN, "batb": NaN, "batl": [[0, 3.15, 2], [1, 3.25, 2], [2, 3.3, 10.9]]}, {"timestamp": 1578701527881, "ltp": 3.15, "tv": 3316.78, "trd": NaN, "batb": [[1, 3, 4.27]], "batl": NaN}, {"timestamp": 1578701532963, "ltp": 3.15, "tv": 3316.78, "trd": NaN, "batb": [[0, 2.96, 7.32], [1, 2.94, 9.17], [2, 2.92, 85.28]], "batl": NaN}, {"timestamp": 1578701533371, "ltp": 3.15, "tv": 3316.78, "trd": NaN, "batb": [[0, 2.96, 9.36]], "batl": [[2, 3.3, 3]]}, {"timestamp": 1578701543416, "ltp": 3.15, "tv": 3316.78, "trd": NaN, "batb": [[0, 2.98, 64.44], [1, 2.96, 9.36], [2, 2.94, 9.17]], "batl": NaN}, {"timestamp": 1578701549722, "ltp": 3.15, "tv": 3316.78, "trd": NaN, "batb": [[0, 3, 7.27], [1, 2.98, 64.44], [2, 2.96, 2.04]], "batl": NaN}, {"timestamp": 1578701577972, "ltp": 3.0, "tv": 3349.36, "trd": [[3, 54.87]], "batb": [[0, 2.98, 64.44], [1, 2.96, 2.04], [2, 2.94, 9.17]], "batl": [[0, 3, 33.71], [1, 3.15, 2], [2, 3.25, 2]]}, {"timestamp": 1578701579980, "ltp": 3.0, "tv": 3405.2, "trd": [[3, 110.71]], "batb": NaN, "batl": [[0, 3, 5.79]]}, {"timestamp": 1578701582549, "ltp": 3.0, "tv": 3416.78, "trd": [[3, 122.29]], "batb": NaN, "batl": [[0, 3.15, 2], [1, 3.25, 2], [2, 3.3, 3]]}, {"timestamp": 1578701590652, "ltp": 3.0, "tv": 3416.78, "trd": NaN, "batb": [[0, 2.96, 66.92], [1, 2.94, 9.17], [2, 2.92, 85.28]], "batl": NaN}, {"timestamp": 1578701598597, "ltp": 3.0, "tv": 3416.78, "trd": NaN, "batb": NaN, "batl": [[1, 3.2, 2.81], [2, 3.25, 2]]}, {"timestamp": 1578701663961, "ltp": 3.0, "tv": 3416.78, "trd": NaN, "batb": NaN, "batl": [[1, 3.25, 4.77], [2, 3.3, 3]]}, {"timestamp": 1578701712949, "ltp": 3.15, "tv": 3420.78, "trd": [[3.15, 34.52]], "batb": NaN, "batl": [[0, 3.25, 4.77], [1, 3.3, 3], [2, 3.35, 50.93]]}, {"timestamp": 1578701718486, "ltp": 3.25, "tv": 3430.31, "trd": [[3.25, 30.86]], "batb": NaN, "batl": [[0, 3.3, 3], [1, 3.35, 50.93], [2, 3.4, 5]]}, {"timestamp": 1578701723677, "ltp": 3.25, "tv": 3430.31, "trd": NaN, "batb": NaN, "batl": [[0, 3.3, 71.9]]}, {"timestamp": 1578701726397, "ltp": 3.25, "tv": 3430.31, "trd": NaN, "batb": NaN, "batl": [[0, 3.3, 117.84], [1, 3.35, 5]]}, {"timestamp": 1578701733974, "ltp": 3.25, "tv": 3430.31, "trd": NaN, "batb": [[0, 2.98, 10.16], [1, 2.96, 66.92], [2, 2.94, 9.17]], "batl": NaN}, {"timestamp": 1578701734893, "ltp": 3.25, "tv": 3430.31, "trd": NaN, "batb": [[0, 3, 64.02], [1, 2.98, 10.16]], "batl": [[0, 3.25, 7.98], [1, 3.3, 117.84], [2, 3.35, 5]]}, {"timestamp": 1578701736691, "ltp": 3.25, "tv": 3430.31, "trd": NaN, "batb": NaN, "batl": [[0, 3.25, 76.88], [1, 3.3, 48.93]]}, {"timestamp": 1578701737665, "ltp": 3.25, "tv": 3430.31, "trd": NaN, "batb": NaN, "batl": [[0, 3.25, 122.82], [1, 3.3, 3]]}, {"timestamp": 1578701740484, "ltp": 3.25, "tv": 3430.31, "trd": NaN, "batb": NaN, "batl": [[0, 3.2, 4], [1, 3.25, 122.82], [2, 3.3, 3]]}, {"timestamp": 1578701742691, "ltp": 3.25, "tv": 3430.31, "trd": NaN, "batb": NaN, "batl": [[0, 3.2, 72.9], [1, 3.25, 53.91]]}, {"timestamp": 1578701743410, "ltp": 3.25, "tv": 3430.31, "trd": NaN, "batb": NaN, "batl": [[0, 3.2, 118.84], [1, 3.25, 7.98]]}, {"timestamp": 1578701750789, "ltp": 3.25, "tv": 3430.31, "trd": NaN, "batb": [[0, 2.98, 10.16], [1, 2.94, 9.17], [2, 2.92, 85.28]], "batl": NaN}, {"timestamp": 1578701755602, "ltp": 3.2, "tv": 3667.99, "trd": [[3.2, 349.95]], "batb": NaN, "batl": [[0, 3.25, 7.98], [1, 3.3, 3], [2, 3.35, 5]]}, {"timestamp": 1578701762527, "ltp": 3.2, "tv": 3667.99, "trd": NaN, "batb": [[0, 3, 7.27], [1, 2.98, 10.16], [2, 2.94, 9.17]], "batl": NaN}, {"timestamp": 1578702479933, "ltp": 3.2, "tv": 3667.99, "trd": NaN, "batb": [[0, 3, 12.38]], "batl": NaN}, {"timestamp": 1578702496747, "ltp": 3.2, "tv": 3667.99, "trd": NaN, "batb": [[0, 3, 9.38]], "batl": NaN}, {"timestamp": 1578702631441, "ltp": 3.2, "tv": 3667.99, "trd": NaN, "batb": [[0, 3.15, 1.66], [1, 3, 9.38], [2, 2.98, 10.16]], "batl": NaN}, {"timestamp": 1578702633756, "ltp": 3.2, "tv": 3667.99, "trd": NaN, "batb": [[0, 3, 9.38], [1, 2.98, 10.16], [2, 2.94, 9.17]], "batl": NaN}, {"timestamp": 1578702634626, "ltp": 3.2, "tv": 3667.99, "trd": NaN, "batb": [[0, 3.05, 1.71], [1, 3, 9.38], [2, 2.98, 10.16]], "batl": NaN}, {"timestamp": 1578702637966, "ltp": 3.25, "tv": 3683.3, "trd": [[3.25, 46.17]], "batb": NaN, "batl": [[0, 3.3, 3.32], [1, 3.35, 5], [2, 3.4, 5]]}, {"timestamp": 1578702638429, "ltp": 3.25, "tv": 3683.94, "trd": [[3.25, 46.81]], "batb": [[0, 3.05, 11.94]], "batl": [[0, 3.3, 3]]}, {"timestamp": 1578702643846, "ltp": 3.35, "tv": 3699.25, "trd": [[3.3, 18.09], [3.35, 9.3]], "batb": NaN, "batl": [[0, 3.4, 5.35], [1, 3.5, 4], [2, 3.85, 38.28]]}, {"timestamp": 1578702646780, "ltp": 3.35, "tv": 3699.25, "trd": NaN, "batb": [[0, 3.25, 1.71], [1, 3.05, 10.23], [2, 3, 9.38]], "batl": NaN}, {"timestamp": 1578702651977, "ltp": 3.35, "tv": 3699.25, "trd": NaN, "batb": [[2, 3, 17.52]], "batl": NaN}, {"timestamp": 1578702652959, "ltp": 3.5, "tv": 3716.09, "trd": [[3.35, 10.01], [3.4, 10], [3.5, 6.14]], "batb": NaN, "batl": [[0, 3.85, 39.21], [1, 4.7, 32.04], [2, 5, 17.05]]}, {"timestamp": 1578702657874, "ltp": 3.5, "tv": 3717.63, "trd": [[3.5, 7.68]], "batb": NaN, "batl": [[0, 3.8, 2.16], [1, 3.85, 38.28], [2, 4.7, 32.04]]}, {"timestamp": 1578702658185, "ltp": 3.5, "tv": 3717.63, "trd": NaN, "batb": NaN, "batl": [[1, 3.85, 76.56]]}, {"timestamp": 1578702659470, "ltp": 3.5, "tv": 3717.63, "trd": NaN, "batb": [[1, 3.1, 4.13], [2, 3.05, 10.23]], "batl": NaN}, {"timestamp": 1578702663505, "ltp": 3.5, "tv": 3717.63, "trd": NaN, "batb": [[0, 3.15, 1.71]], "batl": NaN}, {"timestamp": 1578702666896, "ltp": 3.5, "tv": 3717.63, "trd": NaN, "batb": NaN, "batl": [[0, 3.8, 40.44]]}, {"timestamp": 1578702667204, "ltp": 3.5, "tv": 3717.63, "trd": NaN, "batb": NaN, "batl": [[1, 3.85, 38.28]]}, {"timestamp": 1578702672988, "ltp": 3.5, "tv": 3717.63, "trd": NaN, "batb": NaN, "batl": [[0, 3.75, 2.16], [1, 3.8, 40.28], [2, 3.85, 38.28]]}, {"timestamp": 1578702673808, "ltp": 3.5, "tv": 3717.63, "trd": NaN, "batb": NaN, "batl": [[0, 3.7, 2.16], [1, 3.75, 2], [2, 3.8, 78.56]]}, {"timestamp": 1578702677715, "ltp": 3.5, "tv": 3717.63, "trd": NaN, "batb": NaN, "batl": [[0, 3.7, 40.44]]}, {"timestamp": 1578702680593, "ltp": 3.5, "tv": 3717.63, "trd": NaN, "batb": NaN, "batl": [[0, 3.65, 4.16], [1, 3.7, 40.28], [2, 3.75, 2]]}, {"timestamp": 1578702683424, "ltp": 3.5, "tv": 3717.63, "trd": NaN, "batb": NaN, "batl": [[1, 3.7, 78.56]]}, {"timestamp": 1578702686230, "ltp": 3.5, "tv": 3717.63, "trd": NaN, "batb": NaN, "batl": [[0, 3.65, 42.44]]}, {"timestamp": 1578702689940, "ltp": 3.5, "tv": 3717.63, "trd": NaN, "batb": NaN, "batl": [[0, 3.65, 80.72], [1, 3.7, 40.28]]}, {"timestamp": 1578702767900, "ltp": 3.5, "tv": 3717.63, "trd": NaN, "batb": NaN, "batl": [[0, 3.6, 2.16], [1, 3.65, 80.56], [2, 3.7, 40.28]]}, {"timestamp": 1578702772675, "ltp": 3.5, "tv": 3717.63, "trd": NaN, "batb": NaN, "batl": [[0, 3.55, 2.16], [1, 3.6, 2], [2, 3.65, 78.56]]}, {"timestamp": 1578702782820, "ltp": 3.5, "tv": 3717.63, "trd": NaN, "batb": NaN, "batl": [[0, 3.5, 2.16], [1, 3.55, 2], [2, 3.6, 2]]}, {"timestamp": 1578702783592, "ltp": 3.5, "tv": 3717.63, "trd": NaN, "batb": [[2, 3, 13.25]], "batl": [[0, 3.5, 22.65]]}, {"timestamp": 1578702800515, "ltp": 3.5, "tv": 3717.63, "trd": NaN, "batb": NaN, "batl": [[0, 3.5, 2.16], [1, 3.55, 22.2]]}, {"timestamp": 1578702803351, "ltp": 3.5, "tv": 3717.63, "trd": NaN, "batb": [[0, 3.1, 4.13], [1, 3, 13.25], [2, 2.96, 1.71]], "batl": NaN}, {"timestamp": 1578702805932, "ltp": 3.5, "tv": 3717.63, "trd": NaN, "batb": [[2, 2.94, 9.17]], "batl": NaN}, {"timestamp": 1578702806552, "ltp": 3.5, "tv": 3717.63, "trd": NaN, "batb": [[0, 3.05, 7.2], [2, 2.96, 1.77]], "batl": NaN}, {"timestamp": 1578702810531, "ltp": 3.5, "tv": 3717.63, "trd": NaN, "batb": [[2, 2.94, 9.17]], "batl": NaN}, {"timestamp": 1578702813975, "ltp": 3.5, "tv": 3717.63, "trd": NaN, "batb": [[0, 3.1, 1.69], [1, 3.05, 7.2], [2, 3, 13.25]], "batl": NaN}, {"timestamp": 1578702815879, "ltp": 3.5, "tv": 3717.63, "trd": NaN, "batb": NaN, "batl": [[0, 3.45, 2], [1, 3.5, 2.16], [2, 3.55, 20.2]]}, {"timestamp": 1578702818453, "ltp": 3.5, "tv": 3717.63, "trd": NaN, "batb": NaN, "batl": [[2, 3.6, 2]]}, {"timestamp": 1578702833760, "ltp": 3.5, "tv": 3717.63, "trd": NaN, "batb": [[1, 3.05, 4.2]], "batl": NaN}, {"timestamp": 1578702841974, "ltp": 3.5, "tv": 3717.63, "trd": NaN, "batb": NaN, "batl": [[1, 3.55, 2.16]]}, {"timestamp": 1578702864427, "ltp": 3.5, "tv": 3717.63, "trd": NaN, "batb": NaN, "batl": [[0, 3.5, 2.16], [1, 3.55, 2]]}, {"timestamp": 1578702876112, "ltp": 3.5, "tv": 3717.63, "trd": NaN, "batb": NaN, "batl": [[1, 3.6, 2], [2, 3.65, 78.56]]}, {"timestamp": 1578702889948, "ltp": 3.5, "tv": 3717.63, "trd": NaN, "batb": NaN, "batl": [[2, 3.65, 40.28]]}, {"timestamp": 1578702893551, "ltp": 3.5, "tv": 3717.63, "trd": NaN, "batb": [[1, 3.05, 7.2]], "batl": NaN}, {"timestamp": 1578702912946, "ltp": 3.5, "tv": 3717.63, "trd": NaN, "batb": NaN, "batl": [[0, 3.6, 2.16], [1, 3.65, 40.28], [2, 3.7, 2]]}, {"timestamp": 1578702913047, "ltp": 3.5, "tv": 3717.95, "trd": [[3.5, 8]], "batb": NaN, "batl": [[0, 3.6, 2]]}, {"timestamp": 1578702914642, "ltp": 3.5, "tv": 3717.95, "trd": NaN, "batb": NaN, "batl": [[0, 3.45, 5.62], [1, 3.6, 2.18], [2, 3.65, 40.28]]}, {"timestamp": 1578702928792, "ltp": 3.5, "tv": 3717.95, "trd": NaN, "batb": NaN, "batl": [[1, 3.6, 40.46], [2, 3.65, 2]]}, {"timestamp": 1578702939820, "ltp": 3.5, "tv": 3717.95, "trd": NaN, "batb": NaN, "batl": [[0, 3.45, 43.9]]}, {"timestamp": 1578702942904, "ltp": 3.5, "tv": 3717.95, "trd": NaN, "batb": NaN, "batl": [[1, 3.6, 2.18]]}, {"timestamp": 1578702943518, "ltp": 3.5, "tv": 3717.95, "trd": NaN, "batb": NaN, "batl": [[0, 3.45, 82.18]]}, {"timestamp": 1578702956425, "ltp": 3.45, "tv": 3802.86, "trd": [[3.45, 84.92]], "batb": NaN, "batl": [[0, 3.45, 39.72]]}, {"timestamp": 1578702960955, "ltp": 3.45, "tv": 3805.74, "trd": [[3.45, 87.8]], "batb": [[0, 3.1, 12.13]], "batl": [[0, 3.6, 2.18], [1, 3.65, 2], [2, 3.7, 2]]}, {"timestamp": 1578702971999, "ltp": 3.45, "tv": 3805.74, "trd": NaN, "batb": NaN, "batl": [[0, 3.55, 19.32], [1, 3.6, 2], [2, 3.65, 2]]}, {"timestamp": 1578702985989, "ltp": 3.45, "tv": 3805.74, "trd": NaN, "batb": [[1, 3.05, 3]], "batl": NaN}, {"timestamp": 1578702986300, "ltp": 3.45, "tv": 3805.74, "trd": NaN, "batb": [[0, 3.15, 4.06], [1, 3.1, 12.13]], "batl": NaN}, {"timestamp": 1578702992800, "ltp": 3.45, "tv": 3805.74, "trd": NaN, "batb": NaN, "batl": [[1, 3.7, 2], [2, 3.75, 2]]}, {"timestamp": 1578702993621, "ltp": 3.45, "tv": 3805.74, "trd": NaN, "batb": NaN, "batl": [[1, 3.75, 2], [2, 3.8, 2]]}, {"timestamp": 1578702998718, "ltp": 3.45, "tv": 3805.74, "trd": NaN, "batb": [[0, 3.2, 1.69], [1, 3.15, 4.06], [2, 3.1, 10.44]], "batl": NaN}, {"timestamp": 1578703004835, "ltp": 3.45, "tv": 3805.74, "trd": NaN, "batb": NaN, "batl": [[0, 3.5, 2], [1, 3.55, 19.32], [2, 3.75, 2]]}, {"timestamp": 1578703007711, "ltp": 3.45, "tv": 3805.74, "trd": NaN, "batb": NaN, "batl": [[1, 3.55, 19.14]]}, {"timestamp": 1578703079922, "ltp": 3.45, "tv": 3805.74, "trd": NaN, "batb": [[0, 3.15, 4.06], [1, 3.1, 10.44], [2, 3, 13.25]], "batl": NaN}, {"timestamp": 1578703151923, "ltp": 3.45, "tv": 3805.74, "trd": NaN, "batb": NaN, "batl": [[2, 4.5, 9.02]]}, {"timestamp": 1578703355941, "ltp": 3.45, "tv": 3805.74, "trd": NaN, "batb": NaN, "batl": [[2, 5, 17.05]]}, {"timestamp": 1578703448921, "ltp": 3.45, "tv": 3805.74, "trd": NaN, "batb": NaN, "batl": [[2, 4.5, 9.02]]}, {"timestamp": 1578703605748, "ltp": 3.45, "tv": 3805.74, "trd": NaN, "batb": [[2, 3, 8.14]], "batl": NaN}, {"timestamp": 1578703708452, "ltp": 3.45, "tv": 3805.74, "trd": NaN, "batb": [[0, 3.15, 65.03]], "batl": NaN}, {"timestamp": 1578703731613, "ltp": 3.45, "tv": 3805.74, "trd": NaN, "batb": [[0, 3.2, 3], [1, 3.15, 65.03], [2, 3.1, 10.44]], "batl": NaN}, {"timestamp": 1578703749198, "ltp": 3.45, "tv": 3805.74, "trd": NaN, "batb": NaN, "batl": [[0, 3.4, 8.79], [1, 3.5, 2], [2, 3.55, 19.14]]}, {"timestamp": 1578703755475, "ltp": 3.45, "tv": 3805.74, "trd": NaN, "batb": [[1, 3.15, 4.06]], "batl": NaN}, {"timestamp": 1578703758912, "ltp": 3.45, "tv": 3805.74, "trd": NaN, "batb": [[0, 3.15, 4.06], [1, 3.1, 10.44], [2, 3, 8.14]], "batl": NaN}, {"timestamp": 1578703887716, "ltp": 3.45, "tv": 3805.74, "trd": NaN, "batb": [[1, 3, 8.14], [2, 2.94, 9.17]], "batl": [[0, 3.4, 27.93], [2, 5.2, 32.04]]}, {"timestamp": 1578703895789, "ltp": 3.45, "tv": 3805.74, "trd": NaN, "batb": [[0, 3.05, 7.2]], "batl": NaN}, {"timestamp": 1578703911440, "ltp": 3.45, "tv": 3805.74, "trd": NaN, "batb": [[0, 3.05, 70.17]], "batl": NaN}, {"timestamp": 1578703916960, "ltp": 3.4, "tv": 3835.91, "trd": [[3.4, 40.16]], "batb": NaN, "batl": [[0, 3.35, 2], [1, 3.4, 12.85]]}, {"timestamp": 1578703917941, "ltp": 3.4, "tv": 3835.91, "trd": NaN, "batb": NaN, "batl": [[2, 4.3, 9.02]]}, {"timestamp": 1578703935749, "ltp": 3.4, "tv": 3835.91, "trd": NaN, "batb": [[0, 3.1, 10.44], [1, 3.05, 70.17], [2, 3, 8.14]], "batl": [[1, 4.3, 9.02], [2, 5.1, 26.02]]}, {"timestamp": 1578703936572, "ltp": 3.4, "tv": 3835.91, "trd": NaN, "batb": NaN, "batl": [[1, 3.4, 15.31], [2, 4.3, 9.02]]}, {"timestamp": 1578703939866, "ltp": 3.4, "tv": 3835.91, "trd": NaN, "batb": [[0, 3.15, 7.06], [1, 3.1, 10.44], [2, 3.05, 62.97]], "batl": NaN}, {"timestamp": 1578703950787, "ltp": 3.4, "tv": 3835.91, "trd": NaN, "batb": [[0, 3.15, 68.03], [2, 3, 8.14]], "batl": NaN}, {"timestamp": 1578703964809, "ltp": 3.4, "tv": 3835.91, "trd": NaN, "batb": NaN, "batl": [[0, 3.4, 15.31], [1, 4.3, 9.02], [2, 5.1, 26.02]]}, {"timestamp": 1578704251779, "ltp": 3.4, "tv": 3835.91, "trd": NaN, "batb": NaN, "batl": [[1, 5.2, 32.04], [2, 6.6, 2]]}, {"timestamp": 1578704344644, "ltp": 3.4, "tv": 3835.91, "trd": NaN, "batb": NaN, "batl": [[1, 4.4, 9.02], [2, 5.2, 58.06]]}, {"timestamp": 1578704354052, "ltp": 3.4, "tv": 3835.91, "trd": NaN, "batb": [[0, 3.15, 65.03]], "batl": NaN}, {"timestamp": 1578704464954, "ltp": 3.4, "tv": 3835.91, "trd": NaN, "batb": NaN, "batl": [[2, 5.2, 26.02]]}, {"timestamp": 1578704486055, "ltp": 3.4, "tv": 3835.91, "trd": NaN, "batb": [[0, 3.2, 3], [1, 3.15, 65.03], [2, 3.1, 10.44]], "batl": NaN}, {"timestamp": 1578704504501, "ltp": 3.4, "tv": 3835.91, "trd": NaN, "batb": [[1, 3.15, 4.06]], "batl": NaN}, {"timestamp": 1578704508584, "ltp": 3.4, "tv": 3835.91, "trd": NaN, "batb": [[0, 3.15, 4.06], [1, 3.1, 10.44], [2, 3, 8.14]], "batl": NaN}, {"timestamp": 1578704518415, "ltp": 3.4, "tv": 3835.91, "trd": NaN, "batb": NaN, "batl": [[2, 5.1, 17.05]]}, {"timestamp": 1578704526423, "ltp": 3.4, "tv": 3835.91, "trd": NaN, "batb": NaN, "batl": [[2, 5, 32.04]]}, {"timestamp": 1578704568448, "ltp": 3.4, "tv": 3835.91, "trd": NaN, "batb": NaN, "batl": [[1, 3.85, 20], [2, 4.4, 9.02]]}, {"timestamp": 1578704658809, "ltp": 3.35, "tv": 3865.43, "trd": [[3.35, 39.53]], "batb": NaN, "batl": [[0, 3.85, 20.55], [1, 4.4, 9.02], [2, 5, 32.04]]}, {"timestamp": 1578704659275, "ltp": 3.35, "tv": 3866.53, "trd": [[3.35, 40.63]], "batb": [[1, 3, 8.14], [2, 2.94, 9.17]], "batl": [[0, 3.85, 20.19]]}, {"timestamp": 1578704660505, "ltp": 3.35, "tv": 3866.53, "trd": NaN, "batb": [[0, 3.05, 4.2]], "batl": NaN}, {"timestamp": 1578704664881, "ltp": 3.35, "tv": 3866.53, "trd": NaN, "batb": NaN, "batl": [[0, 3.35, 15.31], [1, 3.85, 20.19], [2, 4.4, 9.02]]}, {"timestamp": 1578704668585, "ltp": 3.35, "tv": 3866.53, "trd": NaN, "batb": NaN, "batl": [[1, 3.85, 20]]}, {"timestamp": 1578704671514, "ltp": 3.35, "tv": 3866.53, "trd": NaN, "batb": [[2, 2.96, 11.48]], "batl": NaN}, {"timestamp": 1578704678610, "ltp": 3.35, "tv": 3866.53, "trd": NaN, "batb": NaN, "batl": [[2, 5, 32.04]]}, {"timestamp": 1578704680614, "ltp": 3.35, "tv": 3866.53, "trd": NaN, "batb": [[0, 3.1, 10.44], [1, 3.05, 67.17], [2, 3, 8.14]], "batl": NaN}, {"timestamp": 1578704682002, "ltp": 3.35, "tv": 3866.53, "trd": NaN, "batb": [[0, 3.15, 4.06], [1, 3.1, 10.44], [2, 3.05, 62.97]], "batl": NaN}, {"timestamp": 1578704700952, "ltp": 3.35, "tv": 3866.53, "trd": NaN, "batb": [[2, 3, 8.14]], "batl": NaN}, {"timestamp": 1578704771319, "ltp": 3.35, "tv": 3866.53, "trd": NaN, "batb": NaN, "batl": [[2, 4.3, 9.02]]}, {"timestamp": 1578704773324, "ltp": 3.15, "tv": 3874.53, "trd": [[3.15, 42.52]], "batb": [[0, 3, 8.2], [1, 2.96, 11.48], [2, 2.94, 6]], "batl": NaN}, {"timestamp": 1578704774820, "ltp": 3.15, "tv": 3874.53, "trd": NaN, "batb": [[2, 2.94, 15.17]], "batl": NaN}, {"timestamp": 1578704776517, "ltp": 3.15, "tv": 3874.53, "trd": NaN, "batb": [[0, 3, 72.22]], "batl": NaN}, {"timestamp": 1578704780589, "ltp": 3.15, "tv": 3874.53, "trd": NaN, "batb": [[0, 3.05, 6.06], [1, 3, 72.16], [2, 2.96, 11.48]], "batl": NaN}, {"timestamp": 1578704786908, "ltp": 3.15, "tv": 3874.53, "trd": NaN, "batb": [[2, 2.98, 9.04]], "batl": NaN}, {"timestamp": 1578704792301, "ltp": 3.15, "tv": 3874.53, "trd": NaN, "batb": NaN, "batl": [[0, 3.25, 8], [1, 3.35, 15.31], [2, 3.85, 20]]}, {"timestamp": 1578704794936, "ltp": 3.15, "tv": 3874.53, "trd": NaN, "batb": [[0, 3.1, 11.04], [1, 3.05, 6], [2, 3, 72.16]], "batl": NaN}, {"timestamp": 1578704795502, "ltp": 3.15, "tv": 3874.53, "trd": NaN, "batb": [[2, 3, 8.14]], "batl": NaN}, {"timestamp": 1578704796941, "ltp": 3.15, "tv": 3874.53, "trd": NaN, "batb": NaN, "batl": [[0, 3.3, 8]]}, {"timestamp": 1578704800751, "ltp": 3.15, "tv": 3874.53, "trd": NaN, "batb": [[1, 3, 8.14], [2, 2.96, 11.48]], "batl": NaN}, {"timestamp": 1578704819534, "ltp": 3.1, "tv": 3886.53, "trd": [[3.1, 43.98], [3.15, 42.64]], "batb": [[0, 3.1, 5.04]], "batl": NaN}, {"timestamp": 1578704839417, "ltp": 3.1, "tv": 3886.53, "trd": NaN, "batb": NaN, "batl": [[0, 3.3, 15.66]]}, {"timestamp": 1578704856535, "ltp": 3.1, "tv": 3894.53, "trd": [[3.1, 51.98]], "batb": [[0, 3.1, 1.04]], "batl": NaN}, {"timestamp": 1578704870915, "ltp": 3.1, "tv": 3894.53, "trd": NaN, "batb": NaN, "batl": [[0, 3.2, 8], [1, 3.3, 7.66], [2, 3.35, 15.31]]}, {"timestamp": 1578704871835, "ltp": 3.1, "tv": 3894.53, "trd": NaN, "batb": [[1, 3.05, 62.97], [2, 3, 8.14]], "batl": NaN}, {"timestamp": 1578704877943, "ltp": 3.2, "tv": 3910.53, "trd": [[3.2, 365.95]], "batb": NaN, "batl": [[0, 3.3, 7.66], [1, 3.35, 15.31], [2, 3.85, 20]]}, {"timestamp": 1578704896239, "ltp": 3.2, "tv": 3910.53, "trd": NaN, "batb": [[0, 3.1, 11.48]], "batl": [[0, 3.35, 15.31], [1, 3.85, 20], [2, 4.3, 9.02]]}, {"timestamp": 1578704910469, "ltp": 3.2, "tv": 3910.53, "trd": NaN, "batb": [[1, 3, 8.14], [2, 2.96, 11.48]], "batl": NaN}, {"timestamp": 1578704929529, "ltp": 3.2, "tv": 3910.53, "trd": NaN, "batb": NaN, "batl": [[0, 3.3, 4], [1, 3.35, 15.31], [2, 3.85, 20]]}, {"timestamp": 1578705215440, "ltp": 3.2, "tv": 3910.53, "trd": NaN, "batb": [[1, 3.05, 10.1], [2, 3, 8.14]], "batl": NaN}, {"timestamp": 1578705290732, "ltp": 3.2, "tv": 3910.53, "trd": NaN, "batb": NaN, "batl": [[0, 3.25, 1.7], [1, 3.3, 4], [2, 3.35, 15.31]]}, {"timestamp": 1578705291399, "ltp": 3.2, "tv": 3910.53, "trd": NaN, "batb": NaN, "batl": [[0, 3.3, 4], [1, 3.35, 15.31], [2, 3.85, 20]]}, {"timestamp": 1578705300640, "ltp": 3.1, "tv": 3914.53, "trd": [[3.1, 55.98]], "batb": [[0, 3.1, 9.48]], "batl": NaN}, {"timestamp": 1578705488707, "ltp": 3.1, "tv": 3914.53, "trd": NaN, "batb": NaN, "batl": [[1, 3.65, 15.31]]}, {"timestamp": 1578705492558, "ltp": 3.1, "tv": 3914.53, "trd": NaN, "batb": NaN, "batl": [[2, 3.8, 7.66]]}, {"timestamp": 1578705493327, "ltp": 3.1, "tv": 3914.53, "trd": NaN, "batb": NaN, "batl": [[2, 3.8, 15.31]]}, {"timestamp": 1578705633743, "ltp": 3.1, "tv": 3914.53, "trd": NaN, "batb": [[0, 3.15, 5.8], [1, 3.1, 9.48]], "batl": NaN}, {"timestamp": 1578705838486, "ltp": 3.3, "tv": 3922.53, "trd": [[3.3, 26.09]], "batb": NaN, "batl": [[0, 3.65, 15.31], [1, 3.8, 15.31], [2, 3.85, 20]]}, {"timestamp": 1578705840753, "ltp": 3.3, "tv": 3922.53, "trd": NaN, "batb": [[1, 3, 8.14], [2, 2.96, 11.48]], "batl": [[0, 3.65, 15.49]]}, {"timestamp": 1578705841882, "ltp": 3.3, "tv": 3922.53, "trd": NaN, "batb": NaN, "batl": [[0, 3.6, 2.18], [1, 3.65, 15.31], [2, 3.8, 15.31]]}, {"timestamp": 1578706131466, "ltp": 3.3, "tv": 3922.53, "trd": NaN, "batb": [[2, 2.94, 6]], "batl": NaN}, {"timestamp": 1578706132291, "ltp": 3.3, "tv": 3922.53, "trd": NaN, "batb": [[1, 3, 19.47]], "batl": NaN}, {"timestamp": 1578706136802, "ltp": 3.3, "tv": 3922.53, "trd": NaN, "batb": NaN, "batl": [[1, 3.75, 15.31]]}, {"timestamp": 1578706137773, "ltp": 3.3, "tv": 3922.53, "trd": NaN, "batb": NaN, "batl": [[1, 3.7, 4], [2, 3.75, 15.31]]}, {"timestamp": 1578706172735, "ltp": 3.3, "tv": 3922.53, "trd": NaN, "batb": NaN, "batl": [[0, 3.65, 2.18]]}, {"timestamp": 1578706202670, "ltp": 3.3, "tv": 3922.53, "trd": NaN, "batb": NaN, "batl": [[1, 3.75, 15.31], [2, 3.8, 15.31]]}, {"timestamp": 1578706220910, "ltp": 3.3, "tv": 3922.53, "trd": NaN, "batb": NaN, "batl": [[0, 3.75, 15.49], [1, 3.8, 15.31], [2, 3.85, 20]]}, {"timestamp": 1578706221372, "ltp": 3.3, "tv": 3922.53, "trd": NaN, "batb": NaN, "batl": [[0, 3.7, 2.18], [1, 3.75, 15.31], [2, 3.8, 15.31]]}, {"timestamp": 1578706390584, "ltp": 3.0, "tv": 3936.53, "trd": [[3, 124.69], [3.15, 54.24]], "batb": [[0, 3.05, 9.59], [1, 3, 18.27]], "batl": NaN}, {"timestamp": 1578706394806, "ltp": 3.0, "tv": 3936.53, "trd": NaN, "batb": NaN, "batl": [[0, 3.1, 1.2], [1, 3.7, 2.18], [2, 3.75, 15.31]]}, {"timestamp": 1578706398887, "ltp": 3.0, "tv": 3936.53, "trd": NaN, "batb": NaN, "batl": [[1, 3.7, 2]]}, {"timestamp": 1578706408414, "ltp": 3.0, "tv": 3936.53, "trd": NaN, "batb": [[1, 3, 30.77]], "batl": NaN}, {"timestamp": 1578706409807, "ltp": 3.0, "tv": 3936.53, "trd": NaN, "batb": NaN, "batl": [[1, 3.65, 10.27], [2, 3.7, 2]]}, {"timestamp": 1578706426824, "ltp": 3.1, "tv": 3938.93, "trd": [[3.1, 58.38]], "batb": [[0, 3.1, 9.77], [1, 3.05, 9.59], [2, 3, 30.77]], "batl": [[0, 3.65, 10.27], [1, 3.7, 2], [2, 3.75, 15.31]]}, {"timestamp": 1578706427811, "ltp": 3.1, "tv": 3938.93, "trd": NaN, "batb": [[0, 3.05, 9.59], [1, 3, 30.77], [2, 2.94, 6]], "batl": NaN}, {"timestamp": 1578706428944, "ltp": 3.1, "tv": 3938.93, "trd": NaN, "batb": NaN, "batl": [[0, 3.65, 10.46]]}, {"timestamp": 1578706429458, "ltp": 3.1, "tv": 3938.93, "trd": NaN, "batb": [[1, 3, 19.44]], "batl": NaN}, {"timestamp": 1578706431053, "ltp": 3.1, "tv": 3938.93, "trd": NaN, "batb": [[0, 3.05, 19.51]], "batl": NaN}, {"timestamp": 1578706459769, "ltp": 3.1, "tv": 3938.93, "trd": NaN, "batb": NaN, "batl": [[0, 3.6, 2.19], [1, 3.65, 10.27]]}, {"timestamp": 1578706462906, "ltp": 3.1, "tv": 3938.93, "trd": NaN, "batb": NaN, "batl": [[0, 3.6, 2]]}, {"timestamp": 1578706463008, "ltp": 3.1, "tv": 3938.93, "trd": NaN, "batb": NaN, "batl": [[0, 3.6, 2.19]]}, {"timestamp": 1578706476593, "ltp": 3.1, "tv": 3938.93, "trd": NaN, "batb": [[0, 3.1, 7.9], [1, 3.05, 19.51], [2, 3, 19.44]], "batl": NaN}, {"timestamp": 1578706501547, "ltp": 3.1, "tv": 3938.93, "trd": NaN, "batb": [[0, 3.3, 1.7], [1, 3.1, 7.9], [2, 3.05, 9.92]], "batl": NaN}, {"timestamp": 1578706502938, "ltp": 3.1, "tv": 3938.93, "trd": NaN, "batb": [[0, 3.1, 7.9], [1, 3.05, 9.92], [2, 3, 19.44]], "batl": NaN}, {"timestamp": 1578706516764, "ltp": 3.1, "tv": 3948.93, "trd": [[3.1, 68.38]], "batb": [[0, 3.1, 2.9]], "batl": NaN}, {"timestamp": 1578706650080, "ltp": 3.1, "tv": 3948.93, "trd": NaN, "batb": NaN, "batl": [[0, 3.4, 11.48], [1, 3.6, 2.19], [2, 3.65, 10.27]]}, {"timestamp": 1578706653983, "ltp": 3.1, "tv": 3948.93, "trd": NaN, "batb": NaN, "batl": [[0, 3.35, 11.48], [1, 3.4, 11.48], [2, 3.6, 2.19]]}, {"timestamp": 1578706654815, "ltp": 3.1, "tv": 3948.93, "trd": NaN, "batb": NaN, "batl": [[2, 3.6, 2]]}, {"timestamp": 1578706655423, "ltp": 3.1, "tv": 3948.93, "trd": NaN, "batb": NaN, "batl": [[1, 3.6, 2], [2, 3.75, 15.31]]}, {"timestamp": 1578706670611, "ltp": 3.1, "tv": 3954.73, "trd": [[3.1, 74.18]], "batb": [[0, 3.05, 9.92], [1, 3, 19.44], [2, 2.94, 6]], "batl": [[0, 3.1, 7.1], [1, 3.35, 11.48], [2, 3.6, 2]]}, {"timestamp": 1578706675905, "ltp": 3.1, "tv": 3968.93, "trd": [[3.1, 88.38]], "batb": [[0, 3.15, 9.37], [1, 3.1, 9.38], [2, 3.05, 9.92]], "batl": [[0, 3.35, 11.48], [1, 3.6, 2], [2, 3.75, 15.31]]}, {"timestamp": 1578706691437, "ltp": 3.1, "tv": 3968.93, "trd": NaN, "batb": NaN, "batl": [[1, 3.75, 15.31], [2, 3.8, 15.31]]}, {"timestamp": 1578706719741, "ltp": 3.1, "tv": 3968.93, "trd": NaN, "batb": [[1, 3.1, 21.48]], "batl": NaN}, {"timestamp": 1578707320779, "ltp": 3.1, "tv": 3968.93, "trd": NaN, "batb": [[0, 3.15, 18.12]], "batl": NaN}, {"timestamp": 1578707344799, "ltp": 3.15, "tv": 3978.93, "trd": [[3.15, 64.24]], "batb": [[0, 3.15, 13.12]], "batl": NaN}, {"timestamp": 1578707526577, "ltp": 3.35, "tv": 3988.93, "trd": [[3.35, 50.63]], "batb": NaN, "batl": [[0, 3.35, 6.48]]}, {"timestamp": 1578707625315, "ltp": 3.35, "tv": 3988.93, "trd": NaN, "batb": [[1, 3.1, 21.29]], "batl": NaN}, {"timestamp": 1578707626240, "ltp": 3.35, "tv": 3988.93, "trd": NaN, "batb": [[0, 3.15, 25.03], [1, 3.1, 9.38]], "batl": NaN}, {"timestamp": 1578707851246, "ltp": 3.35, "tv": 3988.93, "trd": NaN, "batb": NaN, "batl": [[0, 3.3, 5.36], [1, 3.35, 6.48], [2, 3.75, 15.31]]}, {"timestamp": 1578707852392, "ltp": 3.35, "tv": 3988.93, "trd": NaN, "batb": NaN, "batl": [[1, 3.75, 15.31], [2, 3.8, 15.31]]}, {"timestamp": 1578707918416, "ltp": 3.35, "tv": 3988.93, "trd": NaN, "batb": NaN, "batl": [[0, 3.25, 2.5], [1, 3.3, 5.36], [2, 3.75, 15.31]]}, {"timestamp": 1578707919132, "ltp": 3.35, "tv": 3988.93, "trd": NaN, "batb": NaN, "batl": [[0, 3.3, 5.36], [1, 3.75, 15.31], [2, 3.8, 15.31]]}, {"timestamp": 1578708756597, "ltp": 3.35, "tv": 3988.93, "trd": NaN, "batb": [[0, 3.2, 7.66], [1, 3.15, 25.03], [2, 3.1, 9.38]], "batl": NaN}, {"timestamp": 1578708976872, "ltp": 3.3, "tv": 3999.65, "trd": [[3.3, 36.81]], "batb": [[0, 3.3, 3.81], [1, 3.2, 7.66], [2, 3.15, 20.66]], "batl": [[0, 3.7, 5.39]]}, {"timestamp": 1578708977854, "ltp": 3.3, "tv": 3999.65, "trd": NaN, "batb": [[0, 3.25, 4.32]], "batl": [[0, 3.65, 2]]}, {"timestamp": 1578708982473, "ltp": 3.3, "tv": 3999.65, "trd": NaN, "batb": NaN, "batl": [[1, 3.8, 15.31], [2, 3.85, 20]]}, {"timestamp": 1578709025789, "ltp": 3.3, "tv": 3999.65, "trd": NaN, "batb": NaN, "batl": [[0, 3.75, 2]]}, {"timestamp": 1578709360522, "ltp": 3.3, "tv": 3999.65, "trd": NaN, "batb": [[2, 3.15, 20.29]], "batl": NaN}, {"timestamp": 1578709361245, "ltp": 3.3, "tv": 3999.65, "trd": NaN, "batb": [[0, 3.25, 15.86], [2, 3.15, 8.75]], "batl": NaN}, {"timestamp": 1578709525908, "ltp": 3.3, "tv": 3999.65, "trd": NaN, "batb": [[1, 3.15, 8.75], [2, 3.1, 9.38]], "batl": NaN}, {"timestamp": 1578710277878, "ltp": 3.3, "tv": 3999.65, "trd": NaN, "batb": [[2, 3.05, 4.13]], "batl": NaN}, {"timestamp": 1578710289886, "ltp": 3.25, "tv": 4023.65, "trd": [[3.25, 70.81]], "batb": [[0, 3.25, 3.86]], "batl": [[0, 3.75, 11.1]]}, {"timestamp": 1578710294116, "ltp": 3.25, "tv": 4023.65, "trd": NaN, "batb": NaN, "batl": [[0, 3.7, 10.14], [1, 3.75, 11.1], [2, 3.8, 15.31]]}, {"timestamp": 1578710299379, "ltp": 3.25, "tv": 4023.65, "trd": NaN, "batb": NaN, "batl": [[0, 3.65, 19.65], [1, 3.7, 10.14], [2, 3.75, 11.1]]}, {"timestamp": 1578710303405, "ltp": 3.25, "tv": 4023.65, "trd": NaN, "batb": NaN, "batl": [[0, 3.6, 2], [1, 3.65, 19.65], [2, 3.7, 10.14]]}, {"timestamp": 1578710314325, "ltp": 3.25, "tv": 4023.65, "trd": NaN, "batb": NaN, "batl": [[2, 3.75, 9.1]]}, {"timestamp": 1578710318814, "ltp": 3.25, "tv": 4023.65, "trd": NaN, "batb": NaN, "batl": [[1, 3.7, 19.38]]}, {"timestamp": 1578710350935, "ltp": 3.25, "tv": 4023.65, "trd": NaN, "batb": NaN, "batl": [[0, 3.65, 2]]}, {"timestamp": 1578710591494, "ltp": 3.25, "tv": 4023.65, "trd": NaN, "batb": NaN, "batl": [[1, 3.75, 9.1], [2, 3.8, 15.31]]}, {"timestamp": 1578710594177, "ltp": 3.25, "tv": 4023.65, "trd": NaN, "batb": NaN, "batl": [[1, 3.7, 10.14], [2, 3.75, 9.1]]}, {"timestamp": 1578710887370, "ltp": 3.25, "tv": 4023.65, "trd": NaN, "batb": [[1, 3.2, 2.2], [2, 3.15, 8.75]], "batl": NaN}, {"timestamp": 1578711033354, "ltp": 3.25, "tv": 4023.65, "trd": NaN, "batb": [[0, 3.3, 1.96], [1, 3.25, 3.86], [2, 3.2, 2.2]], "batl": NaN}, {"timestamp": 1578711034232, "ltp": 3.25, "tv": 4023.65, "trd": NaN, "batb": [[0, 3.25, 3.86], [1, 3.2, 2.2], [2, 3.15, 8.75]], "batl": NaN}, {"timestamp": 1578711381783, "ltp": 3.25, "tv": 4031.37, "trd": [[3.25, 78.53]], "batb": [[0, 3.2, 2.2], [1, 3.15, 8.75], [2, 3.05, 4.13]], "batl": [[0, 3.25, 4.14], [1, 3.65, 2], [2, 3.7, 10.14]]}, {"timestamp": 1578711382974, "ltp": 3.25, "tv": 4031.37, "trd": NaN, "batb": [[0, 3.2, 11.28]], "batl": NaN}, {"timestamp": 1578711388675, "ltp": 3.25, "tv": 4031.37, "trd": NaN, "batb": NaN, "batl": [[2, 3.8, 15.31]]}, {"timestamp": 1578711404709, "ltp": 3.25, "tv": 4031.37, "trd": NaN, "batb": NaN, "batl": [[1, 3.75, 2]]}, {"timestamp": 1578711477634, "ltp": 3.25, "tv": 4039.65, "trd": [[3.25, 86.82]], "batb": NaN, "batl": [[0, 3.75, 11.1], [1, 3.8, 15.31], [2, 3.85, 20]]}, {"timestamp": 1578711479235, "ltp": 3.25, "tv": 4039.65, "trd": NaN, "batb": [[2, 3, 6.94]], "batl": NaN}, {"timestamp": 1578711493357, "ltp": 3.25, "tv": 4039.65, "trd": NaN, "batb": NaN, "batl": [[0, 3.7, 10.14], [1, 3.75, 11.1], [2, 3.8, 15.31]]}, {"timestamp": 1578711501483, "ltp": 3.25, "tv": 4039.65, "trd": NaN, "batb": NaN, "batl": [[0, 3.65, 2], [1, 3.7, 10.14], [2, 3.75, 9.1]]}, {"timestamp": 1578711524802, "ltp": 3.25, "tv": 4039.65, "trd": NaN, "batb": NaN, "batl": [[0, 3.65, 21.65]]}, {"timestamp": 1578711534824, "ltp": 3.25, "tv": 4039.65, "trd": NaN, "batb": NaN, "batl": [[1, 3.75, 9.1], [2, 3.8, 15.31]]}, {"timestamp": 1578711543527, "ltp": 3.25, "tv": 4039.65, "trd": NaN, "batb": NaN, "batl": [[0, 3.65, 2], [1, 3.8, 15.31], [2, 3.85, 20]]}, {"timestamp": 1578711549927, "ltp": 3.25, "tv": 4039.65, "trd": NaN, "batb": NaN, "batl": [[0, 3.75, 2]]}, {"timestamp": 1578711555652, "ltp": 3.25, "tv": 4039.65, "trd": NaN, "batb": NaN, "batl": [[0, 3.7, 9.19], [1, 3.75, 12.01], [2, 3.8, 15.31]]}, {"timestamp": 1578711563692, "ltp": 3.25, "tv": 4039.65, "trd": NaN, "batb": NaN, "batl": [[0, 3.65, 19.65], [1, 3.7, 9.19], [2, 3.75, 12.01]]}, {"timestamp": 1578711576907, "ltp": 3.25, "tv": 4039.65, "trd": NaN, "batb": NaN, "batl": [[2, 3.75, 2]]}, {"timestamp": 1578711593827, "ltp": 3.25, "tv": 4039.65, "trd": NaN, "batb": NaN, "batl": [[0, 3.6, 2], [1, 3.65, 19.65], [2, 3.7, 9.19]]}, {"timestamp": 1578711987669, "ltp": 3.25, "tv": 4039.65, "trd": NaN, "batb": NaN, "batl": [[0, 3.6, 2.85]]}, {"timestamp": 1578712002683, "ltp": 3.25, "tv": 4039.65, "trd": NaN, "batb": NaN, "batl": [[0, 3.6, 22.77], [1, 3.7, 9.19], [2, 3.8, 15.31]]}, {"timestamp": 1578712021990, "ltp": 3.25, "tv": 4039.65, "trd": NaN, "batb": NaN, "batl": [[0, 3.6, 2.85], [1, 3.65, 19.65], [2, 3.7, 9.19]]}, {"timestamp": 1578712040511, "ltp": 3.25, "tv": 4039.65, "trd": NaN, "batb": NaN, "batl": [[1, 3.7, 9.19], [2, 3.8, 15.31]]}, {"timestamp": 1578712065982, "ltp": 3.25, "tv": 4039.65, "trd": NaN, "batb": NaN, "batl": [[0, 3.65, 2.85], [1, 3.8, 15.31], [2, 3.85, 20]]}, {"timestamp": 1578712109659, "ltp": 3.25, "tv": 4039.65, "trd": NaN, "batb": NaN, "batl": [[0, 3.75, 2.85]]}, {"timestamp": 1578712114661, "ltp": 3.25, "tv": 4039.65, "trd": NaN, "batb": NaN, "batl": [[0, 3.7, 10.99], [1, 3.75, 2], [2, 3.8, 15.31]]}, {"timestamp": 1578712117557, "ltp": 3.25, "tv": 4039.65, "trd": NaN, "batb": NaN, "batl": [[0, 3.65, 20.5], [1, 3.7, 10.14], [2, 3.75, 2]]}, {"timestamp": 1578712135403, "ltp": 3.25, "tv": 4039.65, "trd": NaN, "batb": NaN, "batl": [[1, 3.75, 2], [2, 3.8, 15.31]]}, {"timestamp": 1578712136392, "ltp": 3.25, "tv": 4039.65, "trd": NaN, "batb": NaN, "batl": [[0, 3.75, 2.85], [1, 3.8, 15.31], [2, 3.85, 20]]}, {"timestamp": 1578712155649, "ltp": 3.25, "tv": 4039.65, "trd": NaN, "batb": NaN, "batl": [[0, 3.7, 10.99], [1, 3.75, 2], [2, 3.8, 15.31]]}, {"timestamp": 1578712174482, "ltp": 3.25, "tv": 4039.65, "trd": NaN, "batb": NaN, "batl": [[0, 3.65, 20.5], [1, 3.7, 10.14], [2, 3.75, 2]]}, {"timestamp": 1578712176243, "ltp": 3.25, "tv": 4039.65, "trd": NaN, "batb": NaN, "batl": [[1, 3.75, 2], [2, 3.8, 15.31]]}, {"timestamp": 1578712193378, "ltp": 3.25, "tv": 4039.65, "trd": NaN, "batb": NaN, "batl": [[0, 3.75, 2.85], [1, 3.8, 15.31], [2, 3.85, 20]]}, {"timestamp": 1578712196337, "ltp": 3.25, "tv": 4039.65, "trd": NaN, "batb": NaN, "batl": [[0, 3.7, 10.99], [1, 3.75, 2], [2, 3.8, 15.31]]}, {"timestamp": 1578712201613, "ltp": 3.25, "tv": 4039.65, "trd": NaN, "batb": NaN, "batl": [[0, 3.65, 2.85], [1, 3.7, 10.14]]}, {"timestamp": 1578712212541, "ltp": 3.25, "tv": 4039.65, "trd": NaN, "batb": NaN, "batl": [[0, 3.6, 20.77], [1, 3.65, 2], [2, 3.7, 10.14]]}, {"timestamp": 1578712216221, "ltp": 3.25, "tv": 4039.65, "trd": NaN, "batb": NaN, "batl": [[2, 3.8, 15.31]]}, {"timestamp": 1578712231657, "ltp": 3.25, "tv": 4039.65, "trd": NaN, "batb": NaN, "batl": [[0, 3.65, 2.85], [1, 3.8, 15.31], [2, 3.85, 20]]}, {"timestamp": 1578712245725, "ltp":