{"info": {"id": "1.167206578", "eventId": "29646660", "eventName": "2m Hcap Hrd", "marketType": "WIN", "openDate": 1578757520949, "name": "Kemp  11th Jan", "numberOfActiveRunner": 9, "countryCode": "", "sport": "HORSE RACING", "venue": "", "volume": {"total": 693799.88, "preMatch": 461655.95, "inPlay": 232143.93}, "winner": {"id": 17647241, "name": "Never Adapt", "status": "WINNER", "position": 1}, "delay": 1}, "runners": [{"id": 17647241, "name": "Never Adapt", "status": "WINNER", "position": 1, "inPlayOdds": 2.36, "inPlayTime": 1578757520949, "avgPrematch": 2.69, "closedOdds": 1.01, "maxPrematch": 3.0, "minPrematch": 2.14, "maxInPlay": 2.98, "minInPlay": 1.01, "inPlayIndex": 3982, "lengthOdds": 4223, "lengthOddsPrematch": 3982, "lengthOddsInPlay": 241, "tradedVolume": 477389.71, "preMatchVolume": 293225.61, "inPlayVolume": 184164.1}, {"id": 13417002, "name": "Ecu De La Noverie", "status": "LOSER", "position": 2, "inPlayOdds": 5.6, "inPlayTime": 1578757520949, "avgPrematch": 4.98, "closedOdds": 1000.0, "maxPrematch": 7.4, "minPrematch": 3.75, "maxInPlay": 1000.0, "minInPlay": 2.94, "inPlayIndex": 3159, "lengthOdds": 3400, "lengthOddsPrematch": 3159, "lengthOddsInPlay": 241, "tradedVolume": 86419.49, "preMatchVolume": 69672.61, "inPlayVolume": 16746.88}, {"id": 12314311, "name": "Fin And Game", "status": "LOSER", "position": 3, "inPlayOdds": 9.6, "inPlayTime": 1578757520949, "avgPrematch": 8.66, "closedOdds": 1000.0, "maxPrematch": 12.0, "minPrematch": 6.2, "maxInPlay": 1000.0, "minInPlay": 7.0, "inPlayIndex": 2825, "lengthOdds": 3054, "lengthOddsPrematch": 2825, "lengthOddsInPlay": 229, "tradedVolume": 25682.49, "preMatchVolume": 20601.83, "inPlayVolume": 5080.66}, {"id": 21580749, "name": "Golden Taipan", "status": "LOSER", "position": 4, "inPlayOdds": 8.0, "inPlayTime": 1578757520949, "avgPrematch": 9.3, "closedOdds": 1000.0, "maxPrematch": 12.0, "minPrematch": 5.2, "maxInPlay": 1000.0, "minInPlay": 2.4, "inPlayIndex": 3139, "lengthOdds": 3377, "lengthOddsPrematch": 3139, "lengthOddsInPlay": 238, "tradedVolume": 44329.29, "preMatchVolume": 30237.92, "inPlayVolume": 14091.37}, {"id": 7320024, "name": "Beltor", "status": "LOSER", "position": 5, "inPlayOdds": 9.0, "inPlayTime": 1578757520949, "avgPrematch": 10.68, "closedOdds": 1000.0, "maxPrematch": 13.0, "minPrematch": 9.0, "maxInPlay": 1000.0, "minInPlay": 8.8, "inPlayIndex": 2212, "lengthOdds": 2445, "lengthOddsPrematch": 2212, "lengthOddsInPlay": 233, "tradedVolume": 30764.21, "preMatchVolume": 26500.68, "inPlayVolume": 4263.53}, {"id": 18766106, "name": "Fransham", "status": "LOSER", "position": 6, "inPlayOdds": 20.0, "inPlayTime": 1578757520949, "avgPrematch": 16.69, "closedOdds": 1000.0, "maxPrematch": 26.0, "minPrematch": 9.4, "maxInPlay": 1000.0, "minInPlay": 11.0, "inPlayIndex": 3410, "lengthOdds": 3638, "lengthOddsPrematch": 3410, "lengthOddsInPlay": 228, "tradedVolume": 14467.14, "preMatchVolume": 11768.04, "inPlayVolume": 2699.1}, {"id": 24111116, "name": "Darkest Day", "status": "LOSER", "position": 7, "inPlayOdds": 28.0, "inPlayTime": 1578757520949, "avgPrematch": 30.91, "closedOdds": 1000.0, "maxPrematch": 55.0, "minPrematch": 15.0, "maxInPlay": 1000.0, "minInPlay": 21.0, "inPlayIndex": 2423, "lengthOdds": 2653, "lengthOddsPrematch": 2423, "lengthOddsInPlay": 230, "tradedVolume": 7676.01, "preMatchVolume": 5510.36, "inPlayVolume": 2165.65}, {"id": 9536858, "name": "New Agenda", "status": "LOSER", "position": 8, "inPlayOdds": 120.0, "inPlayTime": 1578757520949, "avgPrematch": 69.46, "closedOdds": 1000.0, "maxPrematch": 190.0, "minPrematch": 24.0, "maxInPlay": 1000.0, "minInPlay": 29.0, "inPlayIndex": 2296, "lengthOdds": 2527, "lengthOddsPrematch": 2296, "lengthOddsInPlay": 231, "tradedVolume": 5487.05, "preMatchVolume": 2748.35, "inPlayVolume": 2738.7}, {"id": 11118089, "name": "Peruvien Bleu", "status": "LOSER", "position": 9, "inPlayOdds": 140.0, "inPlayTime": 1578757520949, "avgPrematch": 143.92, "closedOdds": 1000.0, "maxPrematch": 300.0, "minPrematch": 55.0, "maxInPlay": 1000.0, "minInPlay": 100.0, "inPlayIndex": 1922, "lengthOdds": 2088, "lengthOddsPrematch": 1922, "lengthOddsInPlay": 166, "tradedVolume": 1584.49, "preMatchVolume": 1390.55, "inPlayVolume": 193.94}], "marketUpdates": [{"timestamp": 1578655280704000000, "openDate": "2020-01-11T12:20:00.000Z", "status": "OPEN", "betDelay": 0, "inPlay": false, "complete": true}, {"timestamp": 1578740947963000000, "openDate": "2020-01-11T12:20:00.000Z", "status": "SUSPENDED", "betDelay": 0, "inPlay": false, "complete": true}, {"timestamp": 1578740948921000000, "openDate": "2020-01-11T12:20:00.000Z", "status": "OPEN", "betDelay": 0, "inPlay": false, "complete": true}, {"timestamp": 1578741008928000000, "openDate": "2020-01-11T12:20:00.000Z", "status": "SUSPENDED", "betDelay": 0, "inPlay": false, "complete": true}, {"timestamp": 1578741009945000000, "openDate": "2020-01-11T12:20:00.000Z", "status": "OPEN", "betDelay": 0, "inPlay": false, "complete": true}, {"timestamp": 1578744228004000000, "openDate": "2020-01-11T12:20:00.000Z", "status": "SUSPENDED", "betDelay": 0, "inPlay": false, "complete": true}, {"timestamp": 1578744228911000000, "openDate": "2020-01-11T12:20:00.000Z", "status": "OPEN", "betDelay": 0, "inPlay": false, "complete": true}, {"timestamp": 1578757518707000000, "openDate": "2020-01-11T12:20:00.000Z", "status": "SUSPENDED", "betDelay": 0, "inPlay": false, "complete": true}, {"timestamp": 1578757520949000000, "openDate": "2020-01-11T12:20:00.000Z", "status": "OPEN", "betDelay": 1, "inPlay": true, "complete": true}, {"timestamp": 1578757760685000000, "openDate": "2020-01-11T12:20:00.000Z", "status": "SUSPENDED", "betDelay": 1, "inPlay": true, "complete": true}, {"timestamp": 1578757916372000000, "openDate": "2020-01-11T12:20:00.000Z", "status": "CLOSED", "betDelay": 1, "inPlay": true, "complete": true}], "odds": [{"runnerId": 17647241, "odds": [{"timestamp": 1578674163653, "ltp": 2.64, "tv": 10.0, "trd": [[2.64, 6.04], [2.66, 3.96]], "batb": [[0, 2.62, 3.43], [1, 2.6, 64.58], [2, 1.61, 1.7]], "batl": NaN}, {"timestamp": 1578674166345, "ltp": 2.64, "tv": 10.0, "trd": NaN, "batb": [[2, 2.5, 3]], "batl": NaN}, {"timestamp": 1578674169976, "ltp": 2.64, "tv": 10.0, "trd": NaN, "batb": NaN, "batl": [[0, 2.94, 65], [1, 2.98, 1.7], [2, 3, 100]]}, {"timestamp": 1578674181480, "ltp": 2.64, "tv": 10.0, "trd": NaN, "batb": [[0, 2.6, 65.01], [1, 2.5, 3], [2, 1.61, 1.7]], "batl": NaN}, {"timestamp": 1578674206834, "ltp": 2.64, "tv": 10.0, "trd": NaN, "batb": [[0, 2.62, 2.13], [1, 2.6, 64.58], [2, 2.5, 3]], "batl": NaN}, {"timestamp": 1578674773600, "ltp": 2.64, "tv": 10.0, "trd": NaN, "batb": [[0, 2.62, 5.3]], "batl": NaN}, {"timestamp": 1578674920901, "ltp": 2.64, "tv": 10.0, "trd": NaN, "batb": [[1, 2.6, 68.58]], "batl": NaN}, {"timestamp": 1578674926377, "ltp": 2.64, "tv": 10.0, "trd": NaN, "batb": NaN, "batl": [[2, 3, 104]]}, {"timestamp": 1578675535336, "ltp": 2.62, "tv": 15.99, "trd": [[2.62, 5.14], [2.64, 6.9]], "batb": [[0, 2.62, 2.3]], "batl": NaN}, {"timestamp": 1578675541051, "ltp": 2.62, "tv": 15.99, "trd": NaN, "batb": NaN, "batl": [[1, 2.98, 1.5]]}, {"timestamp": 1578675562521, "ltp": 2.62, "tv": 15.99, "trd": NaN, "batb": [[0, 2.64, 1.99], [1, 2.62, 2.3], [2, 2.6, 68.58]], "batl": NaN}, {"timestamp": 1578675623004, "ltp": 2.62, "tv": 16.01, "trd": [[2.62, 5.14], [2.64, 6.91], [2.66, 3.96]], "batb": [[0, 2.64, 4.3], [1, 2.6, 68.7], [2, 2.5, 3]], "batl": [[1, 2.98, 1.5]]}, {"timestamp": 1578675939790, "ltp": 2.62, "tv": 16.01, "trd": NaN, "batb": NaN, "batl": [[0, 2.8, 10], [1, 2.94, 65], [2, 2.98, 1.5]]}, {"timestamp": 1578675982003, "ltp": 2.62, "tv": 16.01, "trd": NaN, "batb": NaN, "batl": [[0, 2.76, 100], [1, 2.8, 10], [2, 2.94, 65]]}, {"timestamp": 1578676335205, "ltp": 2.62, "tv": 16.01, "trd": NaN, "batb": NaN, "batl": [[0, 2.74, 65], [1, 2.76, 100], [2, 2.8, 10]]}, {"timestamp": 1578676397858, "ltp": 2.62, "tv": 16.01, "trd": NaN, "batb": NaN, "batl": [[2, 2.98, 1.5]]}, {"timestamp": 1578676411598, "ltp": 2.62, "tv": 16.01, "trd": NaN, "batb": NaN, "batl": [[0, 2.72, 10], [1, 2.74, 65], [2, 2.76, 100]]}, {"timestamp": 1578676558562, "ltp": 2.64, "tv": 24.0, "trd": [[2.64, 14.9]], "batb": [[0, 2.6, 69], [1, 2.5, 3], [2, 2.38, 4.99]], "batl": NaN}, {"timestamp": 1578676559495, "ltp": 2.64, "tv": 24.6, "trd": [[2.64, 15.5]], "batb": [[0, 2.6, 68.7]], "batl": NaN}, {"timestamp": 1578676566963, "ltp": 2.64, "tv": 24.6, "trd": NaN, "batb": [[0, 2.6, 70.41]], "batl": NaN}, {"timestamp": 1578677217701, "ltp": 2.64, "tv": 24.6, "trd": NaN, "batb": NaN, "batl": [[0, 2.7, 4], [1, 2.72, 10], [2, 2.74, 65]]}, {"timestamp": 1578677401678, "ltp": 2.64, "tv": 24.6, "trd": NaN, "batb": [[0, 2.62, 2], [1, 2.6, 70.41], [2, 2.5, 3]], "batl": NaN}, {"timestamp": 1578677450114, "ltp": 2.64, "tv": 24.6, "trd": NaN, "batb": [[0, 2.62, 3.7], [1, 2.6, 68.7]], "batl": NaN}, {"timestamp": 1578677864198, "ltp": 2.64, "tv": 24.6, "trd": NaN, "batb": NaN, "batl": [[0, 2.7, 7]]}, {"timestamp": 1578677865967, "ltp": 2.64, "tv": 24.6, "trd": NaN, "batb": NaN, "batl": [[0, 2.68, 3], [1, 2.7, 4], [2, 2.72, 10]]}, {"timestamp": 1578677866903, "ltp": 2.64, "tv": 24.6, "trd": NaN, "batb": NaN, "batl": [[0, 2.7, 4], [1, 2.72, 10], [2, 2.74, 65]]}, {"timestamp": 1578677991991, "ltp": 2.62, "tv": 30.6, "trd": [[2.62, 11.14]], "batb": [[0, 2.6, 69.41], [1, 2.5, 3], [2, 2.38, 4.99]], "batl": NaN}, {"timestamp": 1578678459263, "ltp": 2.62, "tv": 30.6, "trd": NaN, "batb": NaN, "batl": [[2, 2.74, 67]]}, {"timestamp": 1578679368932, "ltp": 2.62, "tv": 30.6, "trd": NaN, "batb": NaN, "batl": [[0, 2.7, 14], [1, 2.74, 67], [2, 2.76, 100]]}, {"timestamp": 1578679404436, "ltp": 2.62, "tv": 30.6, "trd": NaN, "batb": NaN, "batl": [[1, 2.72, 14.55], [2, 2.74, 67]]}, {"timestamp": 1578679981926, "ltp": 2.62, "tv": 30.6, "trd": NaN, "batb": NaN, "batl": [[0, 2.68, 4], [1, 2.7, 10], [2, 2.72, 14.55]]}, {"timestamp": 1578681102902, "ltp": 2.62, "tv": 30.6, "trd": NaN, "batb": [[0, 2.62, 2.68], [1, 2.6, 68.7], [2, 2.5, 3]], "batl": NaN}, {"timestamp": 1578681464367, "ltp": 2.62, "tv": 35.96, "trd": [[2.62, 16.5]], "batb": [[0, 2.6, 68.7], [1, 2.5, 3], [2, 2.38, 4.99]], "batl": [[0, 2.62, 67.32], [1, 2.68, 4], [2, 2.7, 10]]}, {"timestamp": 1578681467971, "ltp": 2.62, "tv": 35.96, "trd": NaN, "batb": NaN, "batl": [[0, 2.68, 4], [1, 2.7, 10], [2, 2.72, 14.55]]}, {"timestamp": 1578681477847, "ltp": 2.6, "tv": 155.94, "trd": [[2.6, 119.99]], "batb": [[0, 2.6, 8.72]], "batl": NaN}, {"timestamp": 1578681489984, "ltp": 2.6, "tv": 155.94, "trd": NaN, "batb": [[0, 2.6, 10.51]], "batl": NaN}, {"timestamp": 1578681601927, "ltp": 2.6, "tv": 155.94, "trd": NaN, "batb": NaN, "batl": [[0, 2.66, 1.68], [1, 2.68, 4], [2, 2.7, 10]]}, {"timestamp": 1578682231275, "ltp": 2.6, "tv": 165.94, "trd": [[2.6, 129.98]], "batb": [[0, 2.6, 5.52]], "batl": NaN}, {"timestamp": 1578682264542, "ltp": 2.6, "tv": 165.94, "trd": NaN, "batb": [[1, 2.52, 7.94], [2, 2.5, 3]], "batl": NaN}, {"timestamp": 1578682779302, "ltp": 2.6, "tv": 176.98, "trd": [[2.6, 141.02]], "batb": [[0, 2.52, 7.94], [1, 2.5, 3], [2, 2.38, 4.99]], "batl": NaN}, {"timestamp": 1578682789543, "ltp": 2.6, "tv": 176.98, "trd": NaN, "batb": NaN, "batl": [[1, 2.68, 34]]}, {"timestamp": 1578682802880, "ltp": 2.6, "tv": 176.98, "trd": NaN, "batb": [[0, 2.52, 10.55]], "batl": NaN}, {"timestamp": 1578682818725, "ltp": 2.6, "tv": 176.99, "trd": [[2.6, 141.03], [2.64, 15.5]], "batb": [[2, 2.38, 4.99]], "batl": NaN}, {"timestamp": 1578683017996, "ltp": 2.6, "tv": 176.99, "trd": NaN, "batb": NaN, "batl": [[0, 2.64, 2], [1, 2.66, 1.68], [2, 2.68, 34]]}, {"timestamp": 1578683489509, "ltp": 2.52, "tv": 198.1, "trd": [[2.52, 21.1]], "batb": [[0, 2.5, 3], [1, 2.38, 4.99], [2, 2.22, 19.15]], "batl": [[0, 2.52, 89.45], [1, 2.64, 2], [2, 2.66, 1.68]]}, {"timestamp": 1578683493518, "ltp": 2.52, "tv": 198.1, "trd": NaN, "batb": [[0, 2.38, 7.99], [1, 2.22, 19.15], [2, 2.12, 19.15]], "batl": NaN}, {"timestamp": 1578683503667, "ltp": 2.52, "tv": 198.1, "trd": NaN, "batb": NaN, "batl": [[1, 2.66, 1.68], [2, 2.68, 34]]}, {"timestamp": 1578683645948, "ltp": 2.52, "tv": 198.1, "trd": NaN, "batb": [[1, 2.32, 100], [2, 2.22, 19.15]], "batl": NaN}, {"timestamp": 1578683649353, "ltp": 2.52, "tv": 198.1, "trd": NaN, "batb": [[0, 2.4, 3], [1, 2.38, 7.99], [2, 2.32, 100]], "batl": NaN}, {"timestamp": 1578683655073, "ltp": 2.52, "tv": 211.0, "trd": [[2.52, 34]], "batb": NaN, "batl": [[0, 2.52, 83]]}, {"timestamp": 1578683661716, "ltp": 2.52, "tv": 211.0, "trd": NaN, "batb": [[2, 2.34, 6]], "batl": NaN}, {"timestamp": 1578683666779, "ltp": 2.52, "tv": 267.0, "trd": [[2.52, 90]], "batb": NaN, "batl": [[0, 2.52, 55]]}, {"timestamp": 1578683682418, "ltp": 2.52, "tv": 275.62, "trd": [[2.52, 98.62]], "batb": NaN, "batl": [[0, 2.52, 50.69]]}, {"timestamp": 1578683696656, "ltp": 2.52, "tv": 288.18, "trd": [[2.52, 111.18]], "batb": NaN, "batl": [[0, 2.52, 44.41]]}, {"timestamp": 1578683699149, "ltp": 2.52, "tv": 377.0, "trd": [[2.52, 200]], "batb": [[0, 2.52, 55.59], [1, 2.4, 3], [2, 2.38, 7.99]], "batl": [[0, 2.66, 1.68], [1, 2.68, 34], [2, 2.7, 10]]}, {"timestamp": 1578683701930, "ltp": 2.52, "tv": 377.0, "trd": NaN, "batb": NaN, "batl": [[0, 2.64, 2], [1, 2.66, 1.68], [2, 2.68, 34]]}, {"timestamp": 1578683710987, "ltp": 2.52, "tv": 377.0, "trd": NaN, "batb": [[0, 2.54, 3], [1, 2.52, 55.59]], "batl": NaN}, {"timestamp": 1578683750797, "ltp": 2.52, "tv": 377.0, "trd": NaN, "batb": NaN, "batl": [[0, 2.66, 1.68], [1, 2.68, 34], [2, 2.7, 10]]}, {"timestamp": 1578683757488, "ltp": 2.52, "tv": 377.0, "trd": NaN, "batb": [[0, 2.54, 4.7]], "batl": NaN}, {"timestamp": 1578684479762, "ltp": 2.52, "tv": 377.0, "trd": NaN, "batb": NaN, "batl": [[0, 2.66, 5.68], [1, 2.68, 30]]}, {"timestamp": 1578684605316, "ltp": 2.54, "tv": 386.4, "trd": [[2.54, 9.4]], "batb": [[0, 2.52, 55.59], [1, 2.38, 7.99], [2, 2.34, 6]], "batl": [[0, 2.54, 24.3], [1, 2.66, 5.68], [2, 2.68, 30]]}, {"timestamp": 1578684611568, "ltp": 2.54, "tv": 386.4, "trd": NaN, "batb": [[0, 2.52, 57.29]], "batl": NaN}, {"timestamp": 1578684643940, "ltp": 2.54, "tv": 386.4, "trd": NaN, "batb": NaN, "batl": [[1, 2.66, 4]]}, {"timestamp": 1578684681806, "ltp": 2.52, "tv": 396.4, "trd": [[2.52, 210]], "batb": [[0, 2.52, 52.29]], "batl": NaN}, {"timestamp": 1578684728393, "ltp": 2.52, "tv": 500.98, "trd": [[2.52, 314.59]], "batb": [[0, 2.38, 7.99], [1, 2.34, 6], [2, 2.32, 100]], "batl": NaN}, {"timestamp": 1578684733730, "ltp": 2.52, "tv": 500.98, "trd": NaN, "batb": NaN, "batl": [[0, 2.52, 2], [1, 2.54, 24.3], [2, 2.66, 4]]}, {"timestamp": 1578684745468, "ltp": 2.52, "tv": 500.98, "trd": NaN, "batb": NaN, "batl": [[0, 2.5, 1.79], [1, 2.52, 2], [2, 2.54, 24.3]]}, {"timestamp": 1578684749468, "ltp": 2.52, "tv": 500.98, "trd": NaN, "batb": [[0, 2.38, 18.99]], "batl": NaN}, {"timestamp": 1578684788846, "ltp": 2.52, "tv": 500.98, "trd": NaN, "batb": NaN, "batl": [[0, 2.52, 2], [1, 2.54, 24.3], [2, 2.66, 4]]}, {"timestamp": 1578684789443, "ltp": 2.52, "tv": 500.98, "trd": NaN, "batb": NaN, "batl": [[2, 2.66, 4.95]]}, {"timestamp": 1578684793883, "ltp": 2.54, "tv": 521.78, "trd": [[2.52, 318.59], [2.54, 26.2]], "batb": NaN, "batl": [[0, 2.54, 15.9], [1, 2.66, 4.95], [2, 2.68, 30]]}, {"timestamp": 1578684830624, "ltp": 2.54, "tv": 521.78, "trd": NaN, "batb": [[0, 2.4, 2.1], [1, 2.38, 18.99], [2, 2.34, 6]], "batl": NaN}, {"timestamp": 1578684969535, "ltp": 2.54, "tv": 553.58, "trd": [[2.54, 58]], "batb": [[0, 2.54, 4.44], [1, 2.4, 2.1], [2, 2.38, 18.99]], "batl": [[0, 2.66, 4.95], [1, 2.68, 30], [2, 2.7, 10]]}, {"timestamp": 1578684982036, "ltp": 2.54, "tv": 553.58, "trd": NaN, "batb": NaN, "batl": [[0, 2.64, 3.84], [1, 2.66, 4], [2, 2.68, 30]]}, {"timestamp": 1578685059688, "ltp": 2.54, "tv": 553.58, "trd": NaN, "batb": [[0, 2.54, 5.1]], "batl": NaN}, {"timestamp": 1578685453963, "ltp": 2.54, "tv": 553.58, "trd": NaN, "batb": NaN, "batl": [[0, 2.62, 10.95], [1, 2.64, 2.89], [2, 2.66, 4]]}, {"timestamp": 1578685465534, "ltp": 2.54, "tv": 553.58, "trd": NaN, "batb": NaN, "batl": [[0, 2.6, 2.93], [1, 2.62, 10.95]]}, {"timestamp": 1578685499993, "ltp": 2.54, "tv": 553.58, "trd": NaN, "batb": NaN, "batl": [[0, 2.58, 1.73], [1, 2.6, 2.93], [2, 2.62, 10]]}, {"timestamp": 1578685545950, "ltp": 2.54, "tv": 553.58, "trd": NaN, "batb": NaN, "batl": [[0, 2.6, 2.93], [1, 2.62, 10], [2, 2.66, 4]]}, {"timestamp": 1578685546961, "ltp": 2.54, "tv": 553.58, "trd": NaN, "batb": NaN, "batl": [[1, 2.62, 11.17]]}, {"timestamp": 1578685583791, "ltp": 2.54, "tv": 553.58, "trd": NaN, "batb": NaN, "batl": [[0, 2.58, 1.73], [1, 2.6, 2.93], [2, 2.62, 10]]}, {"timestamp": 1578685618925, "ltp": 2.54, "tv": 553.58, "trd": NaN, "batb": NaN, "batl": [[0, 2.6, 2.93], [1, 2.62, 11.17], [2, 2.66, 4]]}, {"timestamp": 1578685665560, "ltp": 2.54, "tv": 553.58, "trd": NaN, "batb": NaN, "batl": [[0, 2.58, 1.73], [1, 2.6, 2.93], [2, 2.62, 10]]}, {"timestamp": 1578685707906, "ltp": 2.54, "tv": 553.58, "trd": NaN, "batb": NaN, "batl": [[0, 2.6, 2.93], [1, 2.62, 10], [2, 2.66, 4]]}, {"timestamp": 1578685708285, "ltp": 2.54, "tv": 553.58, "trd": NaN, "batb": NaN, "batl": [[1, 2.62, 11.17]]}, {"timestamp": 1578685742950, "ltp": 2.54, "tv": 553.58, "trd": NaN, "batb": NaN, "batl": [[0, 2.58, 1.73], [1, 2.6, 2.93], [2, 2.62, 10]]}, {"timestamp": 1578685744785, "ltp": 2.54, "tv": 553.58, "trd": NaN, "batb": [[0, 2.54, 6.98]], "batl": NaN}, {"timestamp": 1578685790979, "ltp": 2.54, "tv": 553.58, "trd": NaN, "batb": NaN, "batl": [[0, 2.6, 2.93], [1, 2.62, 10], [2, 2.66, 4]]}, {"timestamp": 1578685791813, "ltp": 2.54, "tv": 553.58, "trd": NaN, "batb": NaN, "batl": [[1, 2.62, 11.17]]}, {"timestamp": 1578685834928, "ltp": 2.54, "tv": 553.58, "trd": NaN, "batb": NaN, "batl": [[0, 2.58, 1.73], [1, 2.6, 2.93], [2, 2.62, 10]]}, {"timestamp": 1578685869899, "ltp": 2.54, "tv": 553.58, "trd": NaN, "batb": NaN, "batl": [[0, 2.6, 2.93], [1, 2.62, 11.17], [2, 2.66, 4]]}, {"timestamp": 1578685903952, "ltp": 2.54, "tv": 553.58, "trd": NaN, "batb": NaN, "batl": [[0, 2.58, 1.73], [1, 2.6, 2.93], [2, 2.62, 10]]}, {"timestamp": 1578685942874, "ltp": 2.54, "tv": 553.58, "trd": NaN, "batb": NaN, "batl": [[0, 2.6, 2.93], [1, 2.62, 10], [2, 2.66, 4]]}, {"timestamp": 1578685943973, "ltp": 2.54, "tv": 553.58, "trd": NaN, "batb": NaN, "batl": [[1, 2.62, 11.17]]}, {"timestamp": 1578685948976, "ltp": 2.54, "tv": 553.58, "trd": NaN, "batb": [[0, 2.56, 5.85], [1, 2.54, 6.31], [2, 2.4, 2.1]], "batl": NaN}, {"timestamp": 1578686026881, "ltp": 2.54, "tv": 553.58, "trd": NaN, "batb": [[0, 2.56, 7.72], [1, 2.54, 4.44]], "batl": NaN}, {"timestamp": 1578686050515, "ltp": 2.56, "tv": 569.02, "trd": [[2.56, 15.44]], "batb": [[0, 2.54, 4.44], [1, 2.4, 2.1], [2, 2.38, 18.99]], "batl": NaN}, {"timestamp": 1578686063905, "ltp": 2.56, "tv": 569.02, "trd": NaN, "batb": [[0, 2.56, 2.67], [1, 2.54, 4.44], [2, 2.4, 2.1]], "batl": NaN}, {"timestamp": 1578686423989, "ltp": 2.56, "tv": 569.02, "trd": NaN, "batb": NaN, "batl": [[1, 2.62, 22.37]]}, {"timestamp": 1578686593755, "ltp": 2.56, "tv": 569.02, "trd": NaN, "batb": NaN, "batl": [[0, 2.58, 10], [1, 2.6, 2.93], [2, 2.62, 22.37]]}, {"timestamp": 1578686596428, "ltp": 2.56, "tv": 569.02, "trd": NaN, "batb": NaN, "batl": [[1, 2.62, 22.37], [2, 2.66, 4]]}, {"timestamp": 1578686606936, "ltp": 2.56, "tv": 574.35, "trd": [[2.56, 20.77]], "batb": [[0, 2.54, 4.44], [1, 2.4, 2.1], [2, 2.38, 18.99]], "batl": [[0, 2.56, 4.79], [1, 2.58, 10], [2, 2.62, 11.17]]}, {"timestamp": 1578686611859, "ltp": 2.56, "tv": 574.35, "trd": NaN, "batb": [[0, 2.54, 7.12]], "batl": NaN}, {"timestamp": 1578686646906, "ltp": 2.56, "tv": 574.35, "trd": NaN, "batb": [[0, 2.54, 4.44]], "batl": NaN}, {"timestamp": 1578686917444, "ltp": 2.56, "tv": 578.35, "trd": [[2.56, 24.77]], "batb": NaN, "batl": [[0, 2.56, 2.79]]}, {"timestamp": 1578686918920, "ltp": 2.56, "tv": 579.71, "trd": [[2.56, 26.13]], "batb": NaN, "batl": [[0, 2.56, 2.11]]}, {"timestamp": 1578686921936, "ltp": 2.56, "tv": 583.65, "trd": [[2.56, 30.07]], "batb": NaN, "batl": [[0, 2.58, 10.14], [1, 2.62, 11.17], [2, 2.66, 4]]}, {"timestamp": 1578686924541, "ltp": 2.58, "tv": 587.59, "trd": [[2.56, 30.35], [2.58, 3.66]], "batb": NaN, "batl": [[0, 2.58, 8.17]]}, {"timestamp": 1578686930975, "ltp": 2.58, "tv": 587.59, "trd": NaN, "batb": [[2, 2.38, 15.99]], "batl": NaN}, {"timestamp": 1578686931407, "ltp": 2.58, "tv": 587.59, "trd": NaN, "batb": [[1, 2.5, 3], [2, 2.4, 2.1]], "batl": NaN}, {"timestamp": 1578686938803, "ltp": 2.58, "tv": 587.59, "trd": NaN, "batb": NaN, "batl": [[1, 2.62, 1.17]]}, {"timestamp": 1578686943417, "ltp": 2.58, "tv": 587.59, "trd": NaN, "batb": NaN, "batl": [[0, 2.56, 2.98], [1, 2.58, 8.17], [2, 2.62, 1.17]]}, {"timestamp": 1578687073724, "ltp": 2.56, "tv": 593.55, "trd": [[2.56, 36.31]], "batb": [[0, 2.56, 7.02], [1, 2.54, 4.44], [2, 2.5, 3]], "batl": [[0, 2.58, 8.17], [1, 2.62, 1.17], [2, 2.66, 4]]}, {"timestamp": 1578687074715, "ltp": 2.56, "tv": 593.55, "trd": NaN, "batb": [[2, 2.4, 2.1]], "batl": NaN}, {"timestamp": 1578687082843, "ltp": 2.58, "tv": 607.59, "trd": [[2.58, 17.7]], "batb": [[0, 2.54, 4.44], [1, 2.4, 2.1], [2, 2.38, 18.99]], "batl": [[0, 2.58, 1.15]]}, {"timestamp": 1578687084934, "ltp": 2.58, "tv": 607.59, "trd": NaN, "batb": [[1, 2.5, 3], [2, 2.4, 2.1]], "batl": NaN}, {"timestamp": 1578687100953, "ltp": 2.58, "tv": 607.59, "trd": NaN, "batb": NaN, "batl": [[1, 2.6, 5], [2, 2.62, 1.17]]}, {"timestamp": 1578687180925, "ltp": 2.6, "tv": 619.89, "trd": [[2.58, 20], [2.6, 151.03]], "batb": NaN, "batl": [[0, 2.62, 1.17], [1, 2.66, 4], [2, 2.68, 30]]}, {"timestamp": 1578687191947, "ltp": 2.6, "tv": 619.89, "trd": NaN, "batb": [[0, 2.56, 4.66], [1, 2.54, 4.44], [2, 2.5, 3]], "batl": NaN}, {"timestamp": 1578687230997, "ltp": 2.6, "tv": 619.89, "trd": NaN, "batb": [[0, 2.56, 7.83]], "batl": NaN}, {"timestamp": 1578687284609, "ltp": 2.6, "tv": 619.89, "trd": NaN, "batb": NaN, "batl": [[1, 2.64, 13.5], [2, 2.66, 4]]}, {"timestamp": 1578687470003, "ltp": 2.6, "tv": 619.89, "trd": NaN, "batb": NaN, "batl": [[1, 2.66, 4], [2, 2.68, 44]]}, {"timestamp": 1578687522872, "ltp": 2.6, "tv": 619.89, "trd": NaN, "batb": NaN, "batl": [[0, 2.66, 4], [1, 2.68, 44], [2, 2.72, 16.55]]}, {"timestamp": 1578687523192, "ltp": 2.6, "tv": 619.89, "trd": NaN, "batb": NaN, "batl": [[0, 2.64, 1.69], [1, 2.66, 4], [2, 2.68, 44]]}, {"timestamp": 1578687561428, "ltp": 2.6, "tv": 619.89, "trd": NaN, "batb": NaN, "batl": [[0, 2.6, 1.7], [1, 2.64, 1.69], [2, 2.66, 4]]}, {"timestamp": 1578687562706, "ltp": 2.6, "tv": 619.89, "trd": NaN, "batb": NaN, "batl": [[0, 2.64, 1.69], [1, 2.66, 4], [2, 2.68, 44]]}, {"timestamp": 1578687652243, "ltp": 2.6, "tv": 619.89, "trd": NaN, "batb": NaN, "batl": [[2, 2.68, 30]]}, {"timestamp": 1578688056951, "ltp": 2.6, "tv": 619.89, "trd": NaN, "batb": [[0, 2.56, 46.89]], "batl": NaN}, {"timestamp": 1578688234900, "ltp": 2.6, "tv": 619.89, "trd": NaN, "batb": NaN, "batl": [[0, 2.62, 3], [1, 2.64, 1.69], [2, 2.66, 4]]}, {"timestamp": 1578688240692, "ltp": 2.6, "tv": 619.89, "trd": NaN, "batb": [[0, 2.58, 11.29], [1, 2.56, 46.89], [2, 2.54, 4.44]], "batl": NaN}, {"timestamp": 1578688250830, "ltp": 2.6, "tv": 619.89, "trd": NaN, "batb": [[0, 2.6, 3], [1, 2.58, 11.29], [2, 2.56, 46.89]], "batl": NaN}, {"timestamp": 1578688274910, "ltp": 2.6, "tv": 619.89, "trd": NaN, "batb": NaN, "batl": [[1, 2.66, 4], [2, 2.68, 30]]}, {"timestamp": 1578688275922, "ltp": 2.6, "tv": 619.89, "trd": NaN, "batb": [[0, 2.6, 6.17], [2, 2.56, 43.72]], "batl": NaN}, {"timestamp": 1578688283873, "ltp": 2.6, "tv": 619.89, "trd": NaN, "batb": [[0, 2.6, 3.17]], "batl": NaN}, {"timestamp": 1578688343618, "ltp": 2.6, "tv": 626.23, "trd": [[2.6, 157.37]], "batb": [[0, 2.58, 11.29], [1, 2.56, 43.72], [2, 2.54, 4.44]], "batl": [[0, 2.6, 6.83], [1, 2.62, 3], [2, 2.66, 4]]}, {"timestamp": 1578688345333, "ltp": 2.6, "tv": 626.23, "trd": NaN, "batb": [[0, 2.58, 14.63]], "batl": NaN}, {"timestamp": 1578688412750, "ltp": 2.6, "tv": 639.89, "trd": [[2.6, 171.03]], "batb": [[0, 2.6, 3.33], [1, 2.58, 14.63], [2, 2.56, 43.72]], "batl": [[0, 2.62, 3], [1, 2.66, 4], [2, 2.68, 30]]}, {"timestamp": 1578688413850, "ltp": 2.6, "tv": 639.89, "trd": NaN, "batb": [[0, 2.6, 6.33]], "batl": NaN}, {"timestamp": 1578688417732, "ltp": 2.6, "tv": 639.89, "trd": NaN, "batb": [[0, 2.6, 9.67], [1, 2.58, 11.29]], "batl": NaN}, {"timestamp": 1578688426086, "ltp": 2.6, "tv": 639.89, "trd": NaN, "batb": [[0, 2.6, 16.48]], "batl": NaN}, {"timestamp": 1578688435830, "ltp": 2.6, "tv": 639.89, "trd": NaN, "batb": [[0, 2.6, 13.48]], "batl": NaN}, {"timestamp": 1578688555535, "ltp": 2.62, "tv": 645.89, "trd": [[2.62, 22.5]], "batb": [[0, 2.62, 97], [1, 2.6, 13.48], [2, 2.58, 11.29]], "batl": [[0, 2.66, 4], [1, 2.68, 30], [2, 2.7, 12.33]]}, {"timestamp": 1578688557823, "ltp": 2.62, "tv": 645.89, "trd": NaN, "batb": [[0, 2.64, 31.51], [1, 2.62, 97], [2, 2.6, 6.67]], "batl": NaN}, {"timestamp": 1578688570539, "ltp": 2.62, "tv": 645.89, "trd": NaN, "batb": [[0, 2.64, 34.84], [2, 2.6, 3.33]], "batl": NaN}, {"timestamp": 1578688576856, "ltp": 2.64, "tv": 685.89, "trd": [[2.64, 55.51]], "batb": [[0, 2.64, 14.84]], "batl": NaN}, {"timestamp": 1578689252422, "ltp": 2.64, "tv": 715.56, "trd": [[2.64, 85.18]], "batb": [[0, 2.62, 97], [1, 2.6, 3.33], [2, 2.58, 11.29]], "batl": NaN}, {"timestamp": 1578689256810, "ltp": 2.62, "tv": 737.86, "trd": [[2.62, 44.8]], "batb": [[0, 2.62, 85.85]], "batl": NaN}, {"timestamp": 1578689319406, "ltp": 2.62, "tv": 870.17, "trd": [[2.62, 177.11]], "batb": [[0, 2.62, 19.7]], "batl": [[0, 2.66, 9.56]]}, {"timestamp": 1578689468197, "ltp": 2.62, "tv": 870.17, "trd": NaN, "batb": [[0, 2.62, 21.4]], "batl": NaN}, {"timestamp": 1578689513896, "ltp": 2.66, "tv": 871.87, "trd": [[2.66, 5.66]], "batb": NaN, "batl": [[0, 2.66, 8.71]]}, {"timestamp": 1578689836774, "ltp": 2.66, "tv": 889.29, "trd": [[2.66, 23.08]], "batb": [[0, 2.66, 16.1], [1, 2.62, 21.4], [2, 2.6, 3.33]], "batl": [[0, 2.68, 30], [1, 2.7, 12.33], [2, 2.72, 16.55]]}, {"timestamp": 1578689843790, "ltp": 2.66, "tv": 911.93, "trd": [[2.66, 45.73]], "batb": [[0, 2.66, 4.78]], "batl": NaN}, {"timestamp": 1578689867236, "ltp": 2.66, "tv": 911.93, "trd": NaN, "batb": [[0, 2.66, 6.48], [1, 2.62, 19.7]], "batl": NaN}, {"timestamp": 1578689911696, "ltp": 2.68, "tv": 931.93, "trd": [[2.68, 20]], "batb": NaN, "batl": [[0, 2.68, 20]]}, {"timestamp": 1578690014907, "ltp": 2.68, "tv": 932.0, "trd": [[2.52, 318.59], [2.56, 36.31], [2.6, 171.06], [2.62, 177.12], [2.64, 85.19], [2.66, 45.73]], "batb": NaN, "batl": NaN}, {"timestamp": 1578690065481, "ltp": 2.66, "tv": 944.97, "trd": [[2.66, 58.7]], "batb": [[0, 2.62, 19.7], [1, 2.6, 3.33], [2, 2.58, 11.29]], "batl": [[0, 2.66, 8.58], [1, 2.68, 20], [2, 2.7, 12.33]]}, {"timestamp": 1578690081834, "ltp": 2.66, "tv": 944.97, "trd": NaN, "batb": NaN, "batl": [[2, 2.7, 182.7]]}, {"timestamp": 1578690082718, "ltp": 2.62, "tv": 967.28, "trd": [[2.62, 199.44]], "batb": [[0, 2.62, 8.54]], "batl": [[1, 2.68, 29.45]]}, {"timestamp": 1578690083441, "ltp": 2.62, "tv": 984.37, "trd": [[2.62, 216.52]], "batb": [[0, 2.6, 3.33], [1, 2.58, 11.29], [2, 2.56, 43.72]], "batl": [[0, 2.62, 2.62], [1, 2.66, 8.58], [2, 2.68, 29.45]]}, {"timestamp": 1578690115876, "ltp": 2.6, "tv": 989.37, "trd": [[2.6, 176.06]], "batb": [[0, 2.58, 12.12], [1, 2.56, 43.72], [2, 2.54, 4.44]], "batl": NaN}, {"timestamp": 1578690116293, "ltp": 2.6, "tv": 991.03, "trd": [[2.6, 177.72]], "batb": [[0, 2.6, 11.31], [1, 2.58, 11.29], [2, 2.56, 43.72]], "batl": NaN}, {"timestamp": 1578690137798, "ltp": 2.6, "tv": 991.03, "trd": NaN, "batb": [[0, 2.6, 13.01]], "batl": NaN}, {"timestamp": 1578690792702, "ltp": 2.6, "tv": 991.03, "trd": NaN, "batb": [[2, 2.56, 39.06]], "batl": NaN}, {"timestamp": 1578690852970, "ltp": 2.6, "tv": 997.03, "trd": [[2.6, 183.72]], "batb": [[0, 2.6, 10.01]], "batl": NaN}, {"timestamp": 1578690894936, "ltp": 2.62, "tv": 1002.26, "trd": [[2.62, 221.75]], "batb": [[0, 2.62, 1.64], [1, 2.6, 10.01], [2, 2.58, 11.29]], "batl": [[0, 2.66, 11.51], [1, 2.68, 29.45], [2, 2.7, 182.7]]}, {"timestamp": 1578690895135, "ltp": 2.62, "tv": 1002.26, "trd": NaN, "batb": [[1, 2.6, 1.7]], "batl": NaN}, {"timestamp": 1578690908852, "ltp": 2.62, "tv": 1002.26, "trd": NaN, "batb": NaN, "batl": [[0, 2.64, 1.69], [1, 2.66, 11.51], [2, 2.68, 29.45]]}, {"timestamp": 1578690922896, "ltp": 2.62, "tv": 1002.26, "trd": NaN, "batb": NaN, "batl": [[0, 2.64, 4.24]]}, {"timestamp": 1578690962429, "ltp": 2.62, "tv": 1002.26, "trd": NaN, "batb": NaN, "batl": [[0, 2.64, 1.69]]}, {"timestamp": 1578691531797, "ltp": 2.62, "tv": 1002.26, "trd": NaN, "batb": [[0, 2.62, 13.64]], "batl": NaN}, {"timestamp": 1578691540916, "ltp": 2.62, "tv": 1002.26, "trd": NaN, "batb": [[0, 2.62, 15.35], [1, 2.58, 11.29], [2, 2.56, 39.06]], "batl": NaN}, {"timestamp": 1578691799854, "ltp": 2.66, "tv": 1022.18, "trd": [[2.64, 88.57], [2.66, 75.24]], "batb": [[0, 2.64, 6.62], [1, 2.62, 15.35], [2, 2.58, 11.29]], "batl": [[0, 2.66, 3.24], [1, 2.68, 29.45], [2, 2.7, 182.7]]}, {"timestamp": 1578691840846, "ltp": 2.66, "tv": 1028.66, "trd": [[2.66, 81.72]], "batb": [[0, 2.66, 6.84], [1, 2.64, 6.62], [2, 2.62, 15.35]], "batl": [[0, 2.68, 29.45], [1, 2.7, 182.7], [2, 2.72, 16.55]]}, {"timestamp": 1578691895121, "ltp": 2.7, "tv": 1228.65, "trd": [[2.68, 78.9], [2.7, 141.1]], "batb": NaN, "batl": [[0, 2.7, 112.16], [1, 2.72, 16.55], [2, 2.74, 6]]}, {"timestamp": 1578691896929, "ltp": 2.7, "tv": 1228.65, "trd": NaN, "batb": [[2, 2.62, 18.35]], "batl": NaN}, {"timestamp": 1578691964440, "ltp": 2.7, "tv": 1228.65, "trd": NaN, "batb": [[0, 2.68, 6.52], [1, 2.66, 6.84]], "batl": NaN}, {"timestamp": 1578691989887, "ltp": 2.68, "tv": 1233.88, "trd": [[2.68, 84.13]], "batb": [[0, 2.68, 3.9]], "batl": NaN}, {"timestamp": 1578691991770, "ltp": 2.68, "tv": 1233.88, "trd": NaN, "batb": [[2, 2.62, 15.35]], "batl": NaN}, {"timestamp": 1578691996388, "ltp": 2.68, "tv": 1233.88, "trd": NaN, "batb": [[0, 2.68, 14.77]], "batl": NaN}, {"timestamp": 1578692015126, "ltp": 2.68, "tv": 1233.88, "trd": NaN, "batb": [[2, 2.62, 13.7]], "batl": NaN}, {"timestamp": 1578692035849, "ltp": 2.7, "tv": 1458.2, "trd": [[2.7, 365.41]], "batb": [[0, 2.7, 87.84], [1, 2.68, 14.77], [2, 2.66, 6.84]], "batl": [[0, 2.72, 16.55], [1, 2.74, 6], [2, 2.76, 100]]}, {"timestamp": 1578692036057, "ltp": 2.7, "tv": 1458.2, "trd": NaN, "batb": [[0, 2.7, 97.22]], "batl": NaN}, {"timestamp": 1578692081130, "ltp": 2.7, "tv": 1458.2, "trd": NaN, "batb": NaN, "batl": [[1, 2.74, 10.26]]}, {"timestamp": 1578692144928, "ltp": 2.7, "tv": 1470.2, "trd": [[2.7, 377.41]], "batb": [[0, 2.7, 91.22]], "batl": NaN}, {"timestamp": 1578692858979, "ltp": 2.7, "tv": 1470.2, "trd": NaN, "batb": [[0, 2.7, 92.92]], "batl": NaN}, {"timestamp": 1578692965718, "ltp": 2.72, "tv": 1503.29, "trd": [[2.72, 33.1]], "batb": [[0, 2.72, 18.7], [1, 2.7, 92.92], [2, 2.68, 14.77]], "batl": [[0, 2.74, 10.26], [1, 2.76, 100], [2, 3, 4]]}, {"timestamp": 1578692983504, "ltp": 2.72, "tv": 1503.29, "trd": NaN, "batb": [[0, 2.72, 10.93]], "batl": NaN}, {"timestamp": 1578692994976, "ltp": 2.72, "tv": 1503.29, "trd": NaN, "batb": [[0, 2.72, 12.63], [1, 2.7, 91.22]], "batl": NaN}, {"timestamp": 1578693026105, "ltp": 2.74, "tv": 1515.29, "trd": [[2.74, 12]], "batb": NaN, "batl": [[0, 2.74, 4.26]]}, {"timestamp": 1578693029607, "ltp": 2.74, "tv": 1523.81, "trd": [[2.74, 20.52]], "batb": [[0, 2.74, 1.74], [1, 2.72, 12.63], [2, 2.7, 91.22]], "batl": [[0, 2.76, 100], [1, 3, 4], [2, 3.35, 4.99]]}, {"timestamp": 1578693045920, "ltp": 2.74, "tv": 1527.29, "trd": [[2.74, 24]], "batb": [[0, 2.72, 12.63], [1, 2.7, 91.22], [2, 2.68, 14.77]], "batl": [[0, 2.74, 3.99], [1, 2.76, 100], [2, 3, 4]]}, {"timestamp": 1578693191915, "ltp": 2.72, "tv": 1547.29, "trd": [[2.72, 53.1]], "batb": [[0, 2.72, 2.63]], "batl": NaN}, {"timestamp": 1578693650853, "ltp": 2.72, "tv": 1547.29, "trd": NaN, "batb": [[0, 2.72, 23.93]], "batl": NaN}, {"timestamp": 1578693736651, "ltp": 2.74, "tv": 1555.28, "trd": [[2.74, 31.98]], "batb": [[0, 2.74, 3.71], [1, 2.72, 23.93], [2, 2.7, 91.22]], "batl": [[0, 2.76, 100], [1, 3, 4], [2, 3.35, 4.99]]}, {"timestamp": 1578693751777, "ltp": 2.74, "tv": 1555.28, "trd": NaN, "batb": [[0, 2.72, 23.93], [1, 2.7, 91.22], [2, 2.68, 14.77]], "batl": NaN}, {"timestamp": 1578693758125, "ltp": 2.74, "tv": 1555.28, "trd": NaN, "batb": NaN, "batl": [[1, 2.88, 14.1], [2, 3, 4]]}, {"timestamp": 1578693852167, "ltp": 2.74, "tv": 1555.28, "trd": NaN, "batb": NaN, "batl": [[0, 2.76, 102]]}, {"timestamp": 1578693898985, "ltp": 2.74, "tv": 1555.28, "trd": NaN, "batb": [[0, 2.74, 6.37], [1, 2.72, 23.93], [2, 2.7, 91.22]], "batl": NaN}, {"timestamp": 1578693939271, "ltp": 2.74, "tv": 1555.28, "trd": NaN, "batb": [[0, 2.74, 8.08], [1, 2.72, 22.23]], "batl": NaN}, {"timestamp": 1578693956231, "ltp": 2.74, "tv": 1563.28, "trd": [[2.74, 39.99]], "batb": [[0, 2.74, 4.07]], "batl": NaN}, {"timestamp": 1578693965801, "ltp": 2.74, "tv": 1563.28, "trd": NaN, "batb": [[1, 2.72, 26.61]], "batl": NaN}, {"timestamp": 1578693974822, "ltp": 2.74, "tv": 1563.28, "trd": NaN, "batb": [[0, 2.74, 7.79]], "batl": NaN}, {"timestamp": 1578693990369, "ltp": 2.74, "tv": 1563.28, "trd": NaN, "batb": [[0, 2.74, 4.07]], "batl": NaN}, {"timestamp": 1578694006972, "ltp": 2.72, "tv": 1582.92, "trd": [[2.72, 64.6], [2.74, 48.13]], "batb": [[0, 2.72, 20.85], [1, 2.7, 91.22], [2, 2.68, 10.87]], "batl": NaN}, {"timestamp": 1578694019607, "ltp": 2.72, "tv": 1582.92, "trd": NaN, "batb": [[0, 2.72, 28.7]], "batl": NaN}, {"timestamp": 1578694298730, "ltp": 2.72, "tv": 1582.92, "trd": NaN, "batb": NaN, "batl": [[0, 2.74, 8.63], [1, 2.76, 102], [2, 2.88, 14.1]]}, {"timestamp": 1578694309844, "ltp": 2.74, "tv": 1590.35, "trd": [[2.74, 55.55]], "batb": NaN, "batl": [[0, 2.74, 4.92]]}, {"timestamp": 1578694341603, "ltp": 2.74, "tv": 1590.35, "trd": NaN, "batb": NaN, "batl": [[0, 2.74, 6.92]]}, {"timestamp": 1578694369726, "ltp": 2.74, "tv": 1590.35, "trd": NaN, "batb": NaN, "batl": [[2, 3, 4]]}, {"timestamp": 1578694495798, "ltp": 2.74, "tv": 1604.19, "trd": [[2.74, 69.39]], "batb": [[0, 2.74, 66.07], [1, 2.72, 28.7], [2, 2.7, 91.22]], "batl": [[0, 2.76, 102], [1, 3, 4], [2, 3.35, 4.99]]}, {"timestamp": 1578694496574, "ltp": 2.74, "tv": 1604.19, "trd": NaN, "batb": [[0, 2.74, 75.31], [2, 2.7, 81.84]], "batl": NaN}, {"timestamp": 1578694554685, "ltp": 2.74, "tv": 1610.19, "trd": [[2.74, 75.39]], "batb": [[0, 2.74, 72.31]], "batl": NaN}, {"timestamp": 1578694612910, "ltp": 2.74, "tv": 1610.19, "trd": NaN, "batb": NaN, "batl": [[1, 2.88, 14.49], [2, 3, 4]]}, {"timestamp": 1578695037741, "ltp": 2.74, "tv": 1610.19, "trd": NaN, "batb": NaN, "batl": [[2, 3, 8]]}, {"timestamp": 1578695045247, "ltp": 2.74, "tv": 1632.05, "trd": [[2.74, 97.25]], "batb": [[0, 2.74, 61.38]], "batl": [[0, 2.76, 202]]}, {"timestamp": 1578695046548, "ltp": 2.74, "tv": 1632.05, "trd": NaN, "batb": [[0, 2.74, 52.14], [1, 2.72, 38.01]], "batl": NaN}, {"timestamp": 1578695058049, "ltp": 2.74, "tv": 1632.05, "trd": NaN, "batb": NaN, "batl": [[0, 2.76, 102]]}, {"timestamp": 1578695066990, "ltp": 2.76, "tv": 1836.05, "trd": [[2.76, 204]], "batb": [[0, 2.76, 8.89], [1, 2.74, 52.14], [2, 2.72, 38.01]], "batl": [[0, 2.88, 14.49], [1, 3, 8], [2, 3.35, 4.99]]}, {"timestamp": 1578695070506, "ltp": 2.76, "tv": 1836.05, "trd": NaN, "batb": [[0, 2.78, 3], [1, 2.76, 8.89], [2, 2.74, 52.14]], "batl": NaN}, {"timestamp": 1578695099245, "ltp": 2.76, "tv": 1836.05, "trd": NaN, "batb": [[0, 2.8, 10.4], [1, 2.78, 3], [2, 2.76, 8.89]], "batl": NaN}, {"timestamp": 1578695104935, "ltp": 2.76, "tv": 1836.05, "trd": NaN, "batb": NaN, "batl": [[0, 3, 8], [1, 3.35, 4.99], [2, 6, 9]]}, {"timestamp": 1578695107316, "ltp": 2.76, "tv": 1836.05, "trd": NaN, "batb": NaN, "batl": [[0, 3, 8.2]]}, {"timestamp": 1578695131940, "ltp": 2.76, "tv": 1836.05, "trd": NaN, "batb": [[0, 2.82, 3], [1, 2.8, 10.4]], "batl": NaN}, {"timestamp": 1578695136781, "ltp": 2.76, "tv": 1836.05, "trd": NaN, "batb": [[2, 2.78, 12.9]], "batl": [[1, 3.2, 6.61], [2, 3.35, 4.99]]}, {"timestamp": 1578695191978, "ltp": 2.76, "tv": 1836.05, "trd": NaN, "batb": [[0, 2.8, 10.4], [1, 2.78, 12.9], [2, 2.76, 18.06]], "batl": NaN}, {"timestamp": 1578695192753, "ltp": 2.76, "tv": 1836.05, "trd": NaN, "batb": [[2, 2.76, 8.89]], "batl": NaN}, {"timestamp": 1578695337986, "ltp": 2.76, "tv": 1836.05, "trd": NaN, "batb": [[0, 2.82, 6.19], [1, 2.8, 10.4], [2, 2.78, 12.9]], "batl": NaN}, {"timestamp": 1578695382840, "ltp": 2.76, "tv": 1836.05, "trd": NaN, "batb": [[2, 2.76, 18.06]], "batl": NaN}, {"timestamp": 1578695383305, "ltp": 2.76, "tv": 1836.05, "trd": NaN, "batb": [[2, 2.76, 8.89]], "batl": NaN}, {"timestamp": 1578695505875, "ltp": 2.76, "tv": 1836.05, "trd": NaN, "batb": [[0, 2.82, 17.19]], "batl": NaN}, {"timestamp": 1578695785935, "ltp": 2.76, "tv": 1836.05, "trd": NaN, "batb": NaN, "batl": [[1, 3.15, 1.53], [2, 3.2, 6.61]]}, {"timestamp": 1578695920207, "ltp": 2.76, "tv": 1836.05, "trd": NaN, "batb": NaN, "batl": [[0, 3, 9.73], [1, 3.2, 6.61], [2, 3.35, 4.99]]}, {"timestamp": 1578695977966, "ltp": 2.76, "tv": 1836.05, "trd": NaN, "batb": [[0, 2.84, 5], [1, 2.82, 17.19], [2, 2.8, 10.4]], "batl": NaN}, {"timestamp": 1578695997704, "ltp": 2.76, "tv": 1836.05, "trd": NaN, "batb": [[1, 2.82, 6.19], [2, 2.8, 22.87]], "batl": NaN}, {"timestamp": 1578696016917, "ltp": 2.84, "tv": 1846.05, "trd": [[2.84, 10]], "batb": [[0, 2.82, 6.19], [1, 2.8, 22.87], [2, 2.76, 18.06]], "batl": NaN}, {"timestamp": 1578696028352, "ltp": 2.82, "tv": 1858.05, "trd": [[2.82, 12.01]], "batb": [[0, 2.8, 23.06], [1, 2.76, 18.06], [2, 2.74, 55.14]], "batl": NaN}, {"timestamp": 1578696031341, "ltp": 2.82, "tv": 1858.05, "trd": NaN, "batb": [[2, 2.74, 52.14]], "batl": NaN}, {"timestamp": 1578696032037, "ltp": 2.82, "tv": 1858.05, "trd": NaN, "batb": [[1, 2.76, 8.89]], "batl": NaN}, {"timestamp": 1578696039847, "ltp": 2.8, "tv": 1904.06, "trd": [[2.8, 45.62], [2.82, 12.38]], "batb": [[0, 2.74, 52.2], [1, 2.72, 12.22], [2, 2.7, 81.84]], "batl": [[0, 2.98, 2.27], [1, 3, 9.53], [2, 3.2, 6.61]]}, {"timestamp": 1578696040879, "ltp": 2.8, "tv": 1904.06, "trd": NaN, "batb": [[1, 2.72, 21.54]], "batl": NaN}, {"timestamp": 1578696043657, "ltp": 2.8, "tv": 1904.06, "trd": NaN, "batb": [[0, 2.76, 3.06], [1, 2.74, 52.14], [2, 2.72, 21.54]], "batl": NaN}, {"timestamp": 1578696061971, "ltp": 2.76, "tv": 1927.96, "trd": [[2.76, 227.78], [2.8, 45.74]], "batb": [[0, 2.74, 52.14], [1, 2.72, 21.54], [2, 2.7, 81.84]], "batl": [[0, 2.76, 88.05], [1, 3, 9.73]]}, {"timestamp": 1578696064173, "ltp": 2.76, "tv": 1927.96, "trd": NaN, "batb": NaN, "batl": [[1, 3, 9.53]]}, {"timestamp": 1578696083955, "ltp": 2.74, "tv": 2032.24, "trd": [[2.74, 201.53]], "batb": [[0, 2.72, 21.54], [1, 2.7, 81.84], [2, 2.62, 15]], "batl": [[0, 2.74, 35.91]]}, {"timestamp": 1578696479450, "ltp": 2.72, "tv": 2072.25, "trd": [[2.72, 104.61]], "batb": [[0, 2.72, 1.52]], "batl": NaN}, {"timestamp": 1578696480642, "ltp": 2.72, "tv": 2072.25, "trd": NaN, "batb": [[0, 2.7, 81.84], [1, 2.62, 15], [2, 2.56, 39.06]], "batl": NaN}, {"timestamp": 1578696486920, "ltp": 2.72, "tv": 2072.25, "trd": NaN, "batb": [[1, 2.62, 42.05]], "batl": NaN}, {"timestamp": 1578696538819, "ltp": 2.7, "tv": 2232.25, "trd": [[2.7, 537.41]], "batb": [[0, 2.7, 1.84]], "batl": NaN}, {"timestamp": 1578696539901, "ltp": 2.7, "tv": 2232.25, "trd": NaN, "batb": NaN, "batl": [[0, 2.72, 5.53], [1, 2.74, 35.91], [2, 3, 9.53]]}, {"timestamp": 1578696552666, "ltp": 2.7, "tv": 2232.25, "trd": NaN, "batb": NaN, "batl": [[2, 2.88, 6.65]]}, {"timestamp": 1578696612831, "ltp": 2.7, "tv": 2232.25, "trd": NaN, "batb": [[1, 2.62, 15], [2, 2.58, 29.01]], "batl": NaN}, {"timestamp": 1578697125358, "ltp": 2.72, "tv": 2243.31, "trd": [[2.72, 115.67]], "batb": [[0, 2.72, 44.47], [1, 2.7, 1.84], [2, 2.62, 15]], "batl": [[0, 2.74, 35.91], [1, 2.88, 6.65], [2, 2.98, 6.32]]}, {"timestamp": 1578697160617, "ltp": 2.74, "tv": 2289.24, "trd": [[2.74, 247.47]], "batb": NaN, "batl": [[0, 2.74, 12.95]]}, {"timestamp": 1578697162825, "ltp": 2.74, "tv": 2315.15, "trd": [[2.74, 273.38]], "batb": NaN, "batl": [[0, 2.88, 6.65], [1, 2.98, 6.32], [2, 3, 9.53]]}, {"timestamp": 1578697167809, "ltp": 2.74, "tv": 2315.15, "trd": NaN, "batb": NaN, "batl": [[0, 2.86, 3.06], [1, 2.88, 6.65], [2, 2.98, 6.32]]}, {"timestamp": 1578697172439, "ltp": 2.74, "tv": 2315.15, "trd": NaN, "batb": NaN, "batl": [[0, 2.84, 2.92], [1, 2.86, 3.06], [2, 2.88, 6.65]]}, {"timestamp": 1578697174951, "ltp": 2.74, "tv": 2315.15, "trd": NaN, "batb": NaN, "batl": [[0, 2.84, 5.98], [1, 2.88, 6.65], [2, 2.98, 6.32]]}, {"timestamp": 1578697185539, "ltp": 2.74, "tv": 2315.15, "trd": NaN, "batb": [[2, 2.62, 26.58]], "batl": [[1, 2.86, 10.61], [2, 2.88, 6.65]]}, {"timestamp": 1578697203924, "ltp": 2.74, "tv": 2314.75, "trd": [[2.52, 318.59], [2.54, 58], [2.56, 36.3], [2.6, 183.66], [2.62, 221.71], [2.64, 88.54], [2.66, 81.71], [2.68, 84.12], [2.7, 537.28], [2.72, 115.6], [2.74, 273.33], [2.8, 45.74], [2.82, 12.38]], "batb": [[2, 2.62, 26.57]], "batl": [[0, 2.84, 5.98], [1, 2.86, 10.6]]}, {"timestamp": 1578697220268, "ltp": 2.74, "tv": 2314.75, "trd": NaN, "batb": NaN, "batl": [[0, 2.82, 4.15], [1, 2.84, 5.98]]}, {"timestamp": 1578697222743, "ltp": 2.74, "tv": 2314.75, "trd": NaN, "batb": NaN, "batl": [[0, 2.8, 2.96], [1, 2.82, 4.15], [2, 2.84, 3.06]]}, {"timestamp": 1578697251001, "ltp": 2.74, "tv": 2314.75, "trd": NaN, "batb": NaN, "batl": [[0, 2.76, 2], [1, 2.8, 2.96], [2, 2.82, 4.15]]}, {"timestamp": 1578697251361, "ltp": 2.74, "tv": 2314.75, "trd": NaN, "batb": [[0, 2.74, 5.47], [1, 2.72, 44.47], [2, 2.7, 1.84]], "batl": NaN}, {"timestamp": 1578697258475, "ltp": 2.72, "tv": 2361.21, "trd": [[2.72, 151.12], [2.74, 284.27]], "batb": [[0, 2.72, 26.71], [1, 2.7, 1.84], [2, 2.64, 9.1]], "batl": NaN}, {"timestamp": 1578697332794, "ltp": 2.72, "tv": 2361.21, "trd": NaN, "batb": NaN, "batl": [[2, 2.84, 3.06]]}, {"timestamp": 1578697455857, "ltp": 2.72, "tv": 2361.21, "trd": NaN, "batb": NaN, "batl": [[1, 2.84, 3.06], [2, 2.88, 6.65]]}, {"timestamp": 1578697720557, "ltp": 2.72, "tv": 2361.21, "trd": NaN, "batb": NaN, "batl": [[1, 2.82, 2.94], [2, 2.84, 3.06]]}, {"timestamp": 1578697782321, "ltp": 2.72, "tv": 2361.21, "trd": NaN, "batb": [[0, 2.74, 5], [1, 2.72, 26.71], [2, 2.7, 1.84]], "batl": NaN}, {"timestamp": 1578697797929, "ltp": 2.76, "tv": 2365.2, "trd": [[2.76, 231.78]], "batb": [[0, 2.76, 1.06], [1, 2.74, 5], [2, 2.72, 26.71]], "batl": [[0, 2.82, 2.94], [1, 2.84, 3.06], [2, 2.88, 6.65]]}, {"timestamp": 1578697799870, "ltp": 2.76, "tv": 2365.2, "trd": NaN, "batb": NaN, "batl": [[1, 2.88, 6.65], [2, 2.98, 9.32]]}, {"timestamp": 1578697800280, "ltp": 2.76, "tv": 2365.2, "trd": NaN, "batb": NaN, "batl": [[0, 2.82, 6]]}, {"timestamp": 1578697928811, "ltp": 2.76, "tv": 2365.2, "trd": NaN, "batb": [[1, 2.74, 8.92]], "batl": NaN}, {"timestamp": 1578697983480, "ltp": 2.76, "tv": 2365.2, "trd": NaN, "batb": [[1, 2.74, 16.68]], "batl": NaN}, {"timestamp": 1578698226719, "ltp": 2.76, "tv": 2365.2, "trd": NaN, "batb": [[0, 2.74, 16.68], [1, 2.72, 26.71], [2, 2.7, 1.84]], "batl": NaN}, {"timestamp": 1578698228713, "ltp": 2.74, "tv": 2371.33, "trd": [[2.74, 290.4]], "batb": [[0, 2.74, 13.62]], "batl": NaN}, {"timestamp": 1578698229945, "ltp": 2.74, "tv": 2377.45, "trd": [[2.74, 296.52]], "batb": [[0, 2.74, 10.55]], "batl": NaN}, {"timestamp": 1578698230714, "ltp": 2.74, "tv": 2383.58, "trd": [[2.74, 302.65]], "batb": [[0, 2.74, 7.49]], "batl": NaN}, {"timestamp": 1578698233433, "ltp": 2.74, "tv": 2389.7, "trd": [[2.74, 308.77]], "batb": [[0, 2.74, 4.43]], "batl": NaN}, {"timestamp": 1578698234974, "ltp": 2.74, "tv": 2389.7, "trd": NaN, "batb": [[0, 2.72, 26.71], [1, 2.7, 1.84], [2, 2.62, 15]], "batl": NaN}, {"timestamp": 1578698260966, "ltp": 2.74, "tv": 2389.7, "trd": NaN, "batb": [[2, 2.62, 22.13]], "batl": [[1, 2.86, 6.54], [2, 2.88, 6.65]]}, {"timestamp": 1578698478554, "ltp": 2.74, "tv": 2389.7, "trd": NaN, "batb": [[2, 2.64, 11.37]], "batl": NaN}, {"timestamp": 1578698903851, "ltp": 2.74, "tv": 2389.7, "trd": NaN, "batb": NaN, "batl": [[2, 2.88, 16.65]]}, {"timestamp": 1578698922922, "ltp": 2.74, "tv": 2389.7, "trd": NaN, "batb": [[0, 2.72, 29.02]], "batl": NaN}, {"timestamp": 1578699307878, "ltp": 2.72, "tv": 2395.82, "trd": [[2.72, 157.25]], "batb": [[0, 2.72, 25.96]], "batl": NaN}, {"timestamp": 1578699308086, "ltp": 2.72, "tv": 2401.94, "trd": [[2.72, 163.37]], "batb": [[0, 2.72, 22.9]], "batl": NaN}, {"timestamp": 1578699309157, "ltp": 2.72, "tv": 2408.06, "trd": [[2.72, 169.49]], "batb": [[0, 2.72, 19.84]], "batl": NaN}, {"timestamp": 1578699311774, "ltp": 2.72, "tv": 2414.19, "trd": [[2.72, 175.61]], "batb": [[0, 2.72, 16.78]], "batl": NaN}, {"timestamp": 1578699313970, "ltp": 2.72, "tv": 2414.19, "trd": NaN, "batb": NaN, "batl": [[0, 2.82, 2.94]]}, {"timestamp": 1578699314740, "ltp": 2.72, "tv": 2420.31, "trd": [[2.72, 181.74]], "batb": [[0, 2.72, 13.72]], "batl": NaN}, {"timestamp": 1578699316989, "ltp": 2.72, "tv": 2426.43, "trd": [[2.72, 187.86]], "batb": [[0, 2.72, 10.66]], "batl": NaN}, {"timestamp": 1578699319239, "ltp": 2.72, "tv": 2426.43, "trd": NaN, "batb": NaN, "batl": [[0, 2.8, 5.85], [1, 2.82, 2.94], [2, 2.86, 6.54]]}, {"timestamp": 1578699576898, "ltp": 2.72, "tv": 2436.43, "trd": [[2.72, 197.86]], "batb": [[0, 2.72, 5.66]], "batl": [[0, 2.78, 5.39], [1, 2.8, 5.85], [2, 2.82, 2.94]]}, {"timestamp": 1578699610478, "ltp": 2.72, "tv": 2436.43, "trd": NaN, "batb": NaN, "batl": [[2, 2.86, 2.9]]}, {"timestamp": 1578699717977, "ltp": 2.78, "tv": 2440.43, "trd": [[2.78, 4]], "batb": NaN, "batl": [[0, 2.78, 3.39]]}, {"timestamp": 1578700162698, "ltp": 2.78, "tv": 2440.43, "trd": NaN, "batb": NaN, "batl": [[2, 2.86, 7.9]]}, {"timestamp": 1578700436951, "ltp": 2.78, "tv": 2447.21, "trd": [[2.78, 10.78]], "batb": [[0, 2.78, 97.61], [1, 2.72, 5.66], [2, 2.7, 1.84]], "batl": [[0, 2.8, 5.85], [1, 2.86, 7.9], [2, 2.88, 16.65]]}, {"timestamp": 1578700437155, "ltp": 2.8, "tv": 2458.91, "trd": [[2.8, 57.44]], "batb": NaN, "batl": [[0, 2.86, 7.9], [1, 2.88, 16.65], [2, 2.92, 20]]}, {"timestamp": 1578700441831, "ltp": 2.8, "tv": 2458.91, "trd": NaN, "batb": [[0, 2.8, 31.49], [1, 2.78, 97.61], [2, 2.72, 5.66]], "batl": NaN}, {"timestamp": 1578700648239, "ltp": 2.8, "tv": 2458.91, "trd": NaN, "batb": NaN, "batl": [[2, 2.9, 20]]}, {"timestamp": 1578700917991, "ltp": 2.86, "tv": 2462.91, "trd": [[2.86, 4]], "batb": NaN, "batl": [[0, 2.86, 5.9]]}, {"timestamp": 1578700920301, "ltp": 2.86, "tv": 2462.91, "trd": NaN, "batb": [[2, 2.74, 3]], "batl": NaN}, {"timestamp": 1578701150792, "ltp": 2.86, "tv": 2462.91, "trd": NaN, "batb": [[0, 2.78, 97.61], [1, 2.74, 3], [2, 2.72, 5.66]], "batl": NaN}, {"timestamp": 1578701759443, "ltp": 2.86, "tv": 2462.91, "trd": NaN, "batb": [[0, 2.8, 6.23], [1, 2.78, 97.61], [2, 2.74, 3]], "batl": NaN}, {"timestamp": 1578701876180, "ltp": 2.86, "tv": 2462.91, "trd": NaN, "batb": NaN, "batl": [[2, 2.9, 20.43]]}, {"timestamp": 1578701923712, "ltp": 2.86, "tv": 2462.91, "trd": NaN, "batb": NaN, "batl": [[2, 2.9, 20]]}, {"timestamp": 1578702047601, "ltp": 2.86, "tv": 2462.91, "trd": NaN, "batb": [[0, 2.8, 8.54]], "batl": NaN}, {"timestamp": 1578702174964, "ltp": 2.86, "tv": 2462.91, "trd": NaN, "batb": [[0, 2.82, 8.98], [1, 2.8, 8.54], [2, 2.78, 97.61]], "batl": NaN}, {"timestamp": 1578702176964, "ltp": 2.86, "tv": 2462.91, "trd": NaN, "batb": [[0, 2.82, 23.17]], "batl": NaN}, {"timestamp": 1578702300295, "ltp": 2.86, "tv": 2462.91, "trd": NaN, "batb": [[0, 2.84, 6.15], [1, 2.82, 23.17], [2, 2.8, 2.31]], "batl": NaN}, {"timestamp": 1578702594709, "ltp": 2.82, "tv": 2502.9, "trd": [[2.82, 40.08], [2.84, 22.3]], "batb": [[0, 2.82, 9.32], [1, 2.8, 2.31], [2, 2.78, 97.61]], "batl": NaN}, {"timestamp": 1578703288901, "ltp": 2.82, "tv": 2502.9, "trd": NaN, "batb": NaN, "batl": [[0, 2.84, 2], [1, 2.86, 5.9], [2, 2.88, 16.65]]}, {"timestamp": 1578704050002, "ltp": 2.82, "tv": 2521.55, "trd": [[2.82, 58.72]], "batb": [[0, 2.8, 2.31], [1, 2.78, 97.61], [2, 2.72, 3.35]], "batl": [[0, 2.82, 11.96], [1, 2.84, 2], [2, 2.86, 5.9]]}, {"timestamp": 1578704060904, "ltp": 2.82, "tv": 2521.55, "trd": NaN, "batb": NaN, "batl": [[0, 2.84, 2], [1, 2.86, 5.9], [2, 2.88, 16.65]]}, {"timestamp": 1578704061523, "ltp": 2.82, "tv": 2521.55, "trd": NaN, "batb": NaN, "batl": [[0, 2.84, 13.96]]}, {"timestamp": 1578704190876, "ltp": 2.82, "tv": 2521.55, "trd": NaN, "batb": [[0, 2.8, 8.54]], "batl": NaN}, {"timestamp": 1578704492953, "ltp": 2.8, "tv": 2537.54, "trd": [[2.8, 73.43]], "batb": [[0, 2.78, 98.15], [1, 2.72, 3.35], [2, 2.7, 46.1]], "batl": NaN}, {"timestamp": 1578704493675, "ltp": 2.8, "tv": 2538.62, "trd": [[2.8, 74.52]], "batb": [[0, 2.78, 97.61]], "batl": NaN}, {"timestamp": 1578704511174, "ltp": 2.78, "tv": 2557.62, "trd": [[2.78, 29.78]], "batb": [[0, 2.78, 88.11]], "batl": NaN}, {"timestamp": 1578704790813, "ltp": 2.78, "tv": 2557.62, "trd": NaN, "batb": NaN, "batl": [[0, 2.8, 13.67], [1, 2.84, 13.96], [2, 2.86, 5.9]]}, {"timestamp": 1578704796941, "ltp": 2.78, "tv": 2557.62, "trd": NaN, "batb": NaN, "batl": [[0, 2.84, 13.96], [1, 2.86, 5.9], [2, 2.88, 16.65]]}, {"timestamp": 1578705239574, "ltp": 2.78, "tv": 2557.62, "trd": NaN, "batb": [[1, 2.72, 14.35]], "batl": NaN}, {"timestamp": 1578705412617, "ltp": 2.78, "tv": 2557.62, "trd": NaN, "batb": NaN, "batl": [[0, 2.82, 1.7], [1, 2.84, 13.96], [2, 2.86, 5.9]]}, {"timestamp": 1578705413132, "ltp": 2.78, "tv": 2557.62, "trd": NaN, "batb": NaN, "batl": [[0, 2.84, 13.96], [1, 2.86, 5.9], [2, 2.88, 16.65]]}, {"timestamp": 1578705997534, "ltp": 2.78, "tv": 2557.62, "trd": NaN, "batb": [[0, 2.82, 5.39], [1, 2.8, 28.94], [2, 2.78, 88.11]], "batl": NaN}, {"timestamp": 1578707032724, "ltp": 2.82, "tv": 2568.4, "trd": [[2.82, 69.5]], "batb": [[0, 2.8, 28.94], [1, 2.78, 88.11], [2, 2.72, 3.35]], "batl": [[0, 2.82, 4.61], [1, 2.84, 13.96], [2, 2.86, 5.9]]}, {"timestamp": 1578707466840, "ltp": 2.82, "tv": 2568.4, "trd": NaN, "batb": [[0, 2.78, 88.11], [1, 2.72, 3.35], [2, 2.7, 46.1]], "batl": NaN}, {"timestamp": 1578707571991, "ltp": 2.82, "tv": 2568.4, "trd": NaN, "batb": [[0, 2.78, 95.48]], "batl": NaN}, {"timestamp": 1578707757839, "ltp": 2.82, "tv": 2568.4, "trd": NaN, "batb": [[1, 2.72, 13.45]], "batl": NaN}, {"timestamp": 1578707929647, "ltp": 2.82, "tv": 2568.4, "trd": NaN, "batb": NaN, "batl": [[0, 2.8, 5.62], [1, 2.82, 4.61], [2, 2.84, 13.96]]}, {"timestamp": 1578708478597, "ltp": 2.78, "tv": 2588.4, "trd": [[2.78, 49.78]], "batb": [[0, 2.78, 85.48]], "batl": NaN}, {"timestamp": 1578708919178, "ltp": 2.78, "tv": 2588.4, "trd": NaN, "batb": NaN, "batl": [[0, 2.8, 7.62], [2, 2.84, 11.96]]}, {"timestamp": 1578711062993, "ltp": 2.78, "tv": 2588.4, "trd": NaN, "batb": [[1, 2.76, 2.2], [2, 2.72, 13.45]], "batl": NaN}, {"timestamp": 1578713381935, "ltp": 2.78, "tv": 2688.4, "trd": [[2.78, 149.78]], "batb": [[0, 2.78, 35.48]], "batl": NaN}, {"timestamp": 1578714788612, "ltp": 2.78, "tv": 2688.4, "trd": NaN, "batb": [[0, 2.78, 47.4]], "batl": NaN}, {"timestamp": 1578715336329, "ltp": 2.78, "tv": 2708.4, "trd": [[2.78, 169.78]], "batb": [[0, 2.78, 37.4]], "batl": NaN}, {"timestamp": 1578716041910, "ltp": 2.78, "tv": 2708.4, "trd": NaN, "batb": [[0, 2.78, 25.48]], "batl": NaN}, {"timestamp": 1578721059753, "ltp": 2.8, "tv": 2711.81, "trd": [[2.8, 77.92]], "batb": NaN, "batl": [[0, 2.8, 5.92]]}, {"timestamp": 1578721215926, "ltp": 2.78, "tv": 2735.47, "trd": [[2.78, 193.44]], "batb": [[0, 2.78, 13.65]], "batl": NaN}, {"timestamp": 1578721216492, "ltp": 2.78, "tv": 2757.29, "trd": [[2.78, 215.26]], "batb": [[0, 2.78, 2.74]], "batl": NaN}, {"timestamp": 1578722263575, "ltp": 2.78, "tv": 2757.29, "trd": NaN, "batb": [[0, 2.78, 3.27]], "batl": NaN}, {"timestamp": 1578722319824, "ltp": 2.78, "tv": 2761.43, "trd": [[2.78, 219.4]], "batb": [[0, 2.78, 1.2]], "batl": NaN}, {"timestamp": 1578722476954, "ltp": 2.78, "tv": 2761.43, "trd": NaN, "batb": [[1, 2.76, 21.43]], "batl": NaN}, {"timestamp": 1578722513117, "ltp": 2.78, "tv": 2761.43, "trd": NaN, "batb": [[1, 2.76, 2.2]], "batl": NaN}, {"timestamp": 1578722525963, "ltp": 2.78, "tv": 2761.43, "trd": NaN, "batb": [[1, 2.76, 11.82]], "batl": NaN}, {"timestamp": 1578722556954, "ltp": 2.78, "tv": 2761.43, "trd": NaN, "batb": [[0, 2.78, 5.46]], "batl": NaN}, {"timestamp": 1578722658886, "ltp": 2.76, "tv": 2781.43, "trd": [[2.76, 240.86], [2.78, 230.32]], "batb": [[0, 2.76, 7.28], [1, 2.72, 13.45], [2, 2.7, 46.1]], "batl": NaN}, {"timestamp": 1578722675936, "ltp": 2.7, "tv": 2861.43, "trd": [[2.7, 575.82], [2.72, 224.76], [2.76, 255.41]], "batb": [[0, 2.72, 11.05], [1, 2.7, 26.83], [2, 2.68, 8.55]], "batl": NaN}, {"timestamp": 1578722677841, "ltp": 2.7, "tv": 2861.43, "trd": NaN, "batb": [[1, 2.7, 27.38]], "batl": NaN}, {"timestamp": 1578722696661, "ltp": 2.7, "tv": 2861.43, "trd": NaN, "batb": [[2, 2.68, 6]], "batl": NaN}, {"timestamp": 1578722863638, "ltp": 2.7, "tv": 2861.43, "trd": NaN, "batb": [[0, 2.74, 3.4], [1, 2.72, 11.05], [2, 2.7, 27.38]], "batl": NaN}, {"timestamp": 1578723038918, "ltp": 2.7, "tv": 2861.43, "trd": NaN, "batb": [[0, 2.74, 7.33]], "batl": NaN}, {"timestamp": 1578723193876, "ltp": 2.7, "tv": 2861.43, "trd": NaN, "batb": [[0, 2.74, 9.33]], "batl": NaN}, {"timestamp": 1578724650917, "ltp": 2.8, "tv": 2863.87, "trd": [[2.8, 80.36]], "batb": NaN, "batl": [[0, 2.8, 4.7]]}, {"timestamp": 1578724870733, "ltp": 2.8, "tv": 2863.87, "trd": NaN, "batb": [[0, 2.74, 14.33]], "batl": NaN}, {"timestamp": 1578725078913, "ltp": 2.8, "tv": 2863.87, "trd": NaN, "batb": [[0, 2.76, 6.32], [1, 2.74, 14.33], [2, 2.72, 11.05]], "batl": NaN}, {"timestamp": 1578725213983, "ltp": 2.76, "tv": 2876.51, "trd": [[2.76, 268.06]], "batb": [[0, 2.74, 14.33], [1, 2.7, 27.38], [2, 2.68, 6]], "batl": [[0, 2.76, 93.68], [1, 2.8, 4.7], [2, 2.82, 4.61]]}, {"timestamp": 1578725215995, "ltp": 2.76, "tv": 2876.51, "trd": NaN, "batb": [[2, 2.68, 14.62]], "batl": NaN}, {"timestamp": 1578725224989, "ltp": 2.76, "tv": 2876.51, "trd": NaN, "batb": [[0, 2.74, 12.33], [1, 2.72, 2], [2, 2.7, 27.38]], "batl": NaN}, {"timestamp": 1578725237002, "ltp": 2.74, "tv": 2901.16, "trd": [[2.74, 333.42]], "batb": [[0, 2.72, 2], [1, 2.7, 27.38], [2, 2.68, 14.62]], "batl": [[0, 2.74, 81.36]]}, {"timestamp": 1578725244983, "ltp": 2.74, "tv": 2901.16, "trd": NaN, "batb": NaN, "batl": [[2, 2.82, 11.91]]}, {"timestamp": 1578725277975, "ltp": 2.7, "tv": 3063.87, "trd": [[2.7, 734.54], [2.72, 228.76]], "batb": [[0, 2.68, 14.62], [1, 2.66, 122.57], [2, 2.62, 15]], "batl": [[0, 2.8, 4.7], [1, 2.82, 11.91], [2, 2.84, 11.96]]}, {"timestamp": 1578725282951, "ltp": 2.7, "tv": 3063.87, "trd": NaN, "batb": [[2, 2.62, 49.3]], "batl": [[0, 2.78, 32.33], [1, 2.8, 4.7], [2, 2.82, 11.91]]}, {"timestamp": 1578725287970, "ltp": 2.7, "tv": 3063.87, "trd": NaN, "batb": [[0, 2.68, 24.26]], "batl": NaN}, {"timestamp": 1578725294963, "ltp": 2.7, "tv": 3063.87, "trd": NaN, "batb": [[0, 2.68, 26.26]], "batl": NaN}, {"timestamp": 1578725304963, "ltp": 2.7, "tv": 3063.87, "trd": NaN, "batb": [[2, 2.62, 49.87]], "batl": NaN}, {"timestamp": 1578725391945, "ltp": 2.76, "tv": 3067.87, "trd": [[2.76, 272.06]], "batb": NaN, "batl": NaN}, {"timestamp": 1578725466701, "ltp": 2.76, "tv": 3067.87, "trd": NaN, "batb": [[0, 2.68, 38.28]], "batl": NaN}, {"timestamp": 1578725824943, "ltp": 2.76, "tv": 3067.87, "trd": NaN, "batb": [[0, 2.7, 1], [1, 2.68, 38.28], [2, 2.66, 122.57]], "batl": NaN}, {"timestamp": 1578725825913, "ltp": 2.76, "tv": 3067.87, "trd": NaN, "batb": [[0, 2.68, 38.28], [1, 2.66, 122.57], [2, 2.62, 49.87]], "batl": NaN}, {"timestamp": 1578725988986, "ltp": 2.68, "tv": 3071.87, "trd": [[2.68, 88.12]], "batb": [[0, 2.68, 36.28]], "batl": NaN}, {"timestamp": 1578725997903, "ltp": 2.68, "tv": 3071.87, "trd": NaN, "batb": [[2, 2.62, 46.87]], "batl": [[0, 2.78, 34.33]]}, {"timestamp": 1578726609961, "ltp": 2.68, "tv": 3077.87, "trd": [[2.68, 94.12]], "batb": [[0, 2.68, 33.28]], "batl": NaN}, {"timestamp": 1578726664949, "ltp": 2.78, "tv": 3088.67, "trd": [[2.76, 277.46], [2.78, 235.72]], "batb": NaN, "batl": [[0, 2.78, 31.63], [1, 2.8, 2]]}, {"timestamp": 1578726665733, "ltp": 2.78, "tv": 3088.67, "trd": NaN, "batb": [[2, 2.62, 49.87]], "batl": NaN}, {"timestamp": 1578726730896, "ltp": 2.68, "tv": 3098.67, "trd": [[2.68, 104.12]], "batb": [[0, 2.68, 28.28]], "batl": NaN}, {"timestamp": 1578726731933, "ltp": 2.68, "tv": 3098.67, "trd": NaN, "batb": [[0, 2.68, 23.66]], "batl": NaN}, {"timestamp": 1578726737937, "ltp": 2.68, "tv": 3098.67, "trd": NaN, "batb": [[2, 2.62, 46.87]], "batl": NaN}, {"timestamp": 1578726746938, "ltp": 2.68, "tv": 3098.67, "trd": NaN, "batb": [[0, 2.68, 11.64], [2, 2.64, 15.6]], "batl": NaN}, {"timestamp": 1578726806926, "ltp": 2.68, "tv": 3098.67, "trd": NaN, "batb": [[1, 2.66, 126.17]], "batl": NaN}, {"timestamp": 1578726817962, "ltp": 2.68, "tv": 3098.67, "trd": NaN, "batb": [[2, 2.62, 46.87]], "batl": NaN}, {"timestamp": 1578726868897, "ltp": 2.68, "tv": 3098.67, "trd": NaN, "batb": [[2, 2.62, 34.87]], "batl": NaN}, {"timestamp": 1578726879903, "ltp": 2.68, "tv": 3098.67, "trd": NaN, "batb": [[0, 2.76, 11], [1, 2.68, 11.64], [2, 2.66, 126.17]], "batl": NaN}, {"timestamp": 1578726884983, "ltp": 2.68, "tv": 3098.67, "trd": NaN, "batb": [[1, 2.7, 10.92], [2, 2.68, 11.64]], "batl": NaN}, {"timestamp": 1578726906734, "ltp": 2.68, "tv": 3098.67, "trd": NaN, "batb": [[1, 2.7, 21.84]], "batl": [[0, 2.78, 2]]}, {"timestamp": 1578726914950, "ltp": 2.68, "tv": 3098.67, "trd": NaN, "batb": [[1, 2.72, 2], [2, 2.7, 21.84]], "batl": NaN}, {"timestamp": 1578726964932, "ltp": 2.68, "tv": 3098.67, "trd": NaN, "batb": [[1, 2.7, 21.84], [2, 2.68, 6]], "batl": NaN}, {"timestamp": 1578726965033, "ltp": 2.68, "tv": 3098.67, "trd": NaN, "batb": [[1, 2.74, 2], [2, 2.7, 21.84]], "batl": NaN}, {"timestamp": 1578726968966, "ltp": 2.68, "tv": 3098.67, "trd": NaN, "batb": NaN, "batl": [[2, 2.82, 4.61]]}, {"timestamp": 1578727080933, "ltp": 2.76, "tv": 3128.67, "trd": [[2.76, 307.46]], "batb": [[0, 2.74, 2], [1, 2.7, 21.84], [2, 2.68, 6]], "batl": [[0, 2.76, 35], [1, 2.78, 2], [2, 2.8, 2]]}, {"timestamp": 1578727081915, "ltp": 2.76, "tv": 3132.67, "trd": [[2.76, 311.46]], "batb": NaN, "batl": [[0, 2.76, 33]]}, {"timestamp": 1578727083003, "ltp": 2.74, "tv": 3136.67, "trd": [[2.74, 337.42]], "batb": [[0, 2.68, 6], [1, 2.66, 122.57], [2, 2.62, 3.42]], "batl": [[0, 2.74, 8.91], [1, 2.76, 33], [2, 2.78, 2]]}, {"timestamp": 1578727083828, "ltp": 2.74, "tv": 3136.67, "trd": NaN, "batb": NaN, "batl": [[0, 2.72, 6], [1, 2.74, 8.91], [2, 2.76, 33]]}, {"timestamp": 1578727085937, "ltp": 2.74, "tv": 3136.67, "trd": NaN, "batb": [[2, 2.62, 6.42]], "batl": NaN}, {"timestamp": 1578727106840, "ltp": 2.74, "tv": 3136.67, "trd": NaN, "batb": [[0, 2.7, 2.77], [1, 2.68, 6], [2, 2.66, 122.57]], "batl": NaN}, {"timestamp": 1578727142979, "ltp": 2.74, "tv": 3136.67, "trd": NaN, "batb": [[0, 2.7, 4.77], [1, 2.68, 8.03]], "batl": [[1, 2.76, 33], [2, 2.8, 2]]}, {"timestamp": 1578727143968, "ltp": 2.74, "tv": 3136.67, "trd": NaN, "batb": NaN, "batl": [[0, 2.74, 6], [2, 2.8, 4.86]]}, {"timestamp": 1578727173993, "ltp": 2.74, "tv": 3136.67, "trd": NaN, "batb": NaN, "batl": [[2, 2.8, 2]]}, {"timestamp": 1578727300003, "ltp": 2.74, "tv": 3136.67, "trd": NaN, "batb": [[1, 2.68, 45.34]], "batl": NaN}, {"timestamp": 1578727687979, "ltp": 2.74, "tv": 3140.67, "trd": [[2.74, 341.42]], "batb": NaN, "batl": [[0, 2.74, 4]]}, {"timestamp": 1578727843965, "ltp": 2.7, "tv": 3144.07, "trd": [[2.7, 737.94]], "batb": [[0, 2.7, 3.07]], "batl": NaN}, {"timestamp": 1578727926962, "ltp": 2.74, "tv": 3148.07, "trd": [[2.74, 345.42]], "batb": NaN, "batl": [[0, 2.74, 2]]}, {"timestamp": 1578728243910, "ltp": 2.76, "tv": 3168.37, "trd": [[2.74, 349.42], [2.76, 327.76]], "batb": NaN, "batl": [[0, 2.76, 24.85], [1, 2.8, 2], [2, 2.82, 4.61]]}, {"timestamp": 1578728273883, "ltp": 2.76, "tv": 3168.37, "trd": NaN, "batb": NaN, "batl": [[2, 2.82, 14.95]]}, {"timestamp": 1578728306946, "ltp": 2.76, "tv": 3168.37, "trd": NaN, "batb": NaN, "batl": [[1, 2.8, 9.3]]}, {"timestamp": 1578728404941, "ltp": 2.76, "tv": 3168.37, "trd": NaN, "batb": NaN, "batl": [[1, 2.8, 11.3]]}, {"timestamp": 1578728758916, "ltp": 2.76, "tv": 3192.37, "trd": [[2.76, 351.76]], "batb": NaN, "batl": [[0, 2.76, 12.85]]}, {"timestamp": 1578728798660, "ltp": 2.76, "tv": 3211.57, "trd": [[2.76, 370.96]], "batb": NaN, "batl": [[0, 2.76, 3.25]]}, {"timestamp": 1578728828930, "ltp": 2.76, "tv": 3211.57, "trd": NaN, "batb": NaN, "batl": [[2, 2.82, 4.61]]}, {"timestamp": 1578728842999, "ltp": 2.7, "tv": 3217.58, "trd": [[2.7, 743.94]], "batb": [[0, 2.7, 10.57]], "batl": [[1, 2.8, 4]]}, {"timestamp": 1578728872939, "ltp": 2.7, "tv": 3217.58, "trd": NaN, "batb": [[1, 2.68, 48.61]], "batl": NaN}, {"timestamp": 1578728886850, "ltp": 2.7, "tv": 3217.58, "trd": NaN, "batb": NaN, "batl": [[0, 2.74, 5], [1, 2.76, 3.25], [2, 2.8, 4]]}, {"timestamp": 1578728930918, "ltp": 2.74, "tv": 3227.58, "trd": [[2.74, 359.42]], "batb": NaN, "batl": [[0, 2.76, 3.25], [1, 2.8, 4], [2, 2.82, 4.61]]}, {"timestamp": 1578729572760, "ltp": 2.7, "tv": 3247.58, "trd": [[2.7, 763.94]], "batb": [[0, 2.68, 49.18], [1, 2.66, 122.57], [2, 2.62, 3.56]], "batl": NaN}, {"timestamp": 1578729573950, "ltp": 2.7, "tv": 3247.58, "trd": NaN, "batb": [[0, 2.68, 45.91], [1, 2.66, 135.73]], "batl": NaN}, {"timestamp": 1578729581961, "ltp": 2.7, "tv": 3247.58, "trd": NaN, "batb": [[0, 2.68, 47.91]], "batl": NaN}, {"timestamp": 1578729706928, "ltp": 2.7, "tv": 3247.58, "trd": NaN, "batb": [[0, 2.68, 49.61]], "batl": NaN}, {"timestamp": 1578729806848, "ltp": 2.7, "tv": 3247.58, "trd": NaN, "batb": [[1, 2.66, 149.82]], "batl": NaN}, {"timestamp": 1578729809981, "ltp": 2.76, "tv": 3254.08, "trd": [[2.76, 377.46]], "batb": NaN, "batl": [[0, 2.8, 4], [1, 2.82, 4.61], [2, 2.84, 11.96]]}, {"timestamp": 1578729814971, "ltp": 2.76, "tv": 3254.08, "trd": NaN, "batb": [[0, 2.68, 52.61]], "batl": NaN}, {"timestamp": 1578730018390, "ltp": 2.76, "tv": 3254.08, "trd": NaN, "batb": NaN, "batl": [[0, 2.76, 10], [1, 2.8, 4], [2, 2.82, 4.61]]}, {"timestamp": 1578730037966, "ltp": 2.8, "tv": 3274.1, "trd": [[2.76, 397.46], [2.8, 80.38]], "batb": NaN, "batl": [[0, 2.8, 3.99], [1, 2.82, 8.76], [2, 2.84, 11.96]]}, {"timestamp": 1578730039834, "ltp": 2.8, "tv": 3274.1, "trd": NaN, "batb": NaN, "batl": [[1, 2.82, 4.61]]}, {"timestamp": 1578730122943, "ltp": 2.8, "tv": 3274.1, "trd": NaN, "batb": [[0, 2.68, 66.7], [1, 2.66, 135.73]], "batl": NaN}, {"timestamp": 1578730176997, "ltp": 2.8, "tv": 3278.1, "trd": [[2.8, 84.38]], "batb": NaN, "batl": [[0, 2.8, 1.99]]}, {"timestamp": 1578730177203, "ltp": 2.82, "tv": 3282.1, "trd": [[2.8, 88.36], [2.82, 69.52]], "batb": NaN, "batl": [[0, 2.82, 4.6], [1, 2.84, 11.96], [2, 2.88, 17.55]]}, {"timestamp": 1578730217849, "ltp": 2.82, "tv": 3282.1, "trd": NaN, "batb": [[2, 2.62, 38.16]], "batl": [[0, 2.8, 32.38], [1, 2.82, 4.6], [2, 2.84, 11.96]]}, {"timestamp": 1578730244976, "ltp": 2.8, "tv": 3288.09, "trd": [[2.8, 94.35]], "batb": NaN, "batl": [[0, 2.8, 29.38]]}, {"timestamp": 1578730249865, "ltp": 2.68, "tv": 3296.09, "trd": [[2.68, 110.98], [2.7, 765.08]], "batb": [[0, 2.68, 62.7], [2, 2.62, 35.16]], "batl": NaN}, {"timestamp": 1578730254885, "ltp": 2.68, "tv": 3296.09, "trd": NaN, "batb": NaN, "batl": [[0, 2.8, 32.81]]}, {"timestamp": 1578730262987, "ltp": 2.68, "tv": 3336.09, "trd": [[2.68, 150.98]], "batb": [[0, 2.68, 42.7]], "batl": NaN}, {"timestamp": 1578730272992, "ltp": 2.68, "tv": 3336.09, "trd": NaN, "batb": [[0, 2.7, 16.78], [1, 2.68, 42.7], [2, 2.66, 135.73]], "batl": [[2, 2.84, 15.96]]}, {"timestamp": 1578730277829, "ltp": 2.68, "tv": 3336.09, "trd": NaN, "batb": [[1, 2.68, 48.41], [2, 2.66, 122.57]], "batl": NaN}, {"timestamp": 1578730290955, "ltp": 2.68, "tv": 3336.09, "trd": NaN, "batb": [[1, 2.68, 45.41]], "batl": NaN}, {"timestamp": 1578730292934, "ltp": 2.7, "tv": 3368.09, "trd": [[2.7, 797.08]], "batb": [[0, 2.68, 46.19], [1, 2.66, 122.57], [2, 2.62, 35.16]], "batl": NaN}, {"timestamp": 1578730295936, "ltp": 2.7, "tv": 3368.09, "trd": NaN, "batb": [[2, 2.62, 38.16]], "batl": NaN}, {"timestamp": 1578730318959, "ltp": 2.7, "tv": 3368.09, "trd": NaN, "batb": [[0, 2.68, 49.19]], "batl": NaN}, {"timestamp": 1578730322965, "ltp": 2.7, "tv": 3368.09, "trd": NaN, "batb": [[0, 2.68, 43.48], [1, 2.66, 136.64]], "batl": NaN}, {"timestamp": 1578730371945, "ltp": 2.68, "tv": 3376.09, "trd": [[2.68, 157.42], [2.7, 798.64]], "batb": [[0, 2.68, 39.48]], "batl": NaN}, {"timestamp": 1578730376821, "ltp": 2.68, "tv": 3376.09, "trd": NaN, "batb": [[2, 2.62, 35.16]], "batl": NaN}, {"timestamp": 1578730397820, "ltp": 2.68, "tv": 3376.09, "trd": NaN, "batb": [[0, 2.7, 11], [1, 2.68, 39.48], [2, 2.66, 136.64]], "batl": NaN}, {"timestamp": 1578730410835, "ltp": 2.68, "tv": 3376.09, "trd": NaN, "batb": [[1, 2.68, 43.31], [2, 2.66, 122.57]], "batl": NaN}, {"timestamp": 1578730437885, "ltp": 2.68, "tv": 3376.09, "trd": NaN, "batb": [[1, 2.68, 40.31]], "batl": NaN}, {"timestamp": 1578730442000, "ltp": 2.68, "tv": 3376.09, "trd": NaN, "batb": [[0, 2.7, 13], [1, 2.68, 38.31]], "batl": NaN}, {"timestamp": 1578730460793, "ltp": 2.68, "tv": 3376.09, "trd": NaN, "batb": [[0, 2.7, 2], [1, 2.68, 51.01]], "batl": NaN}, {"timestamp": 1578730463889, "ltp": 2.68, "tv": 3376.09, "trd": NaN, "batb": [[1, 2.68, 47.18]], "batl": NaN}, {"timestamp": 1578730492817, "ltp": 2.68, "tv": 3376.09, "trd": NaN, "batb": [[2, 2.66, 124.57]], "batl": NaN}, {"timestamp": 1578730498843, "ltp": 2.68, "tv": 3376.09, "trd": NaN, "batb": [[2, 2.66, 124.67]], "batl": NaN}, {"timestamp": 1578730525662, "ltp": 2.68, "tv": 3376.09, "trd": NaN, "batb": [[2, 2.66, 124.83]], "batl": NaN}, {"timestamp": 1578730536981, "ltp": 2.68, "tv": 3376.09, "trd": NaN, "batb": [[2, 2.66, 124.67]], "batl": NaN}, {"timestamp": 1578730537961, "ltp": 2.7, "tv": 3380.09, "trd": [[2.7, 802.64]], "batb": [[0, 2.68, 47.18], [1, 2.66, 124.67], [2, 2.62, 35.16]], "batl": [[0, 2.7, 2], [1, 2.8, 32.81], [2, 2.82, 4.6]]}, {"timestamp": 1578730538992, "ltp": 2.7, "tv": 3384.1, "trd": [[2.7, 806.65]], "batb": NaN, "batl": [[0, 2.8, 32.81], [1, 2.82, 4.6], [2, 2.84, 15.96]]}, {"timestamp": 1578730539877, "ltp": 2.7, "tv": 3384.1, "trd": NaN, "batb": [[1, 2.66, 138.74]], "batl": NaN}, {"timestamp": 1578730543962, "ltp": 2.7, "tv": 3384.1, "trd": NaN, "batb": [[2, 2.62, 38.16]], "batl": NaN}, {"timestamp": 1578730550783, "ltp": 2.7, "tv": 3384.1, "trd": NaN, "batb": [[1, 2.66, 136.74]], "batl": NaN}, {"timestamp": 1578730559001, "ltp": 2.7, "tv": 3384.1, "trd": NaN, "batb": [[0, 2.68, 49.18]], "batl": NaN}, {"timestamp": 1578730560914, "ltp": 2.8, "tv": 3390.36, "trd": [[2.8, 100.62]], "batb": NaN, "batl": [[0, 2.8, 29.68]]}, {"timestamp": 1578730587820, "ltp": 2.8, "tv": 3390.36, "trd": NaN, "batb": [[0, 2.68, 52.18]], "batl": NaN}, {"timestamp": 1578730826849, "ltp": 2.7, "tv": 3426.36, "trd": [[2.7, 842.65]], "batb": NaN, "batl": NaN}, {"timestamp": 1578730942906, "ltp": 2.8, "tv": 3436.36, "trd": [[2.8, 110.61]], "batb": NaN, "batl": [[0, 2.8, 24.68]]}, {"timestamp": 1578731116947, "ltp": 2.8, "tv": 3462.35, "trd": [[2.8, 136.61]], "batb": NaN, "batl": [[0, 2.8, 11.69]]}, {"timestamp": 1578731155910, "ltp": 2.8, "tv": 3462.35, "trd": NaN, "batb": NaN, "batl": [[2, 2.84, 11.96]]}, {"timestamp": 1578731317972, "ltp": 2.8, "tv": 3462.35, "trd": NaN, "batb": NaN, "batl": [[0, 2.8, 18.69]]}, {"timestamp": 1578731346919, "ltp": 2.8, "tv": 3488.35, "trd": [[2.8, 162.61]], "batb": NaN, "batl": [[0, 2.8, 5.69]]}, {"timestamp": 1578731352918, "ltp": 2.8, "tv": 3488.35, "trd": NaN, "batb": NaN, "batl": [[0, 2.78, 2.57], [1, 2.8, 5.69], [2, 2.82, 4.6]]}, {"timestamp": 1578731353901, "ltp": 2.8, "tv": 3488.35, "trd": NaN, "batb": [[0, 2.7, 33.58], [1, 2.68, 52.18], [2, 2.66, 136.74]], "batl": NaN}, {"timestamp": 1578731360936, "ltp": 2.8, "tv": 3488.35, "trd": NaN, "batb": [[0, 2.72, 13.1], [1, 2.7, 33.58], [2, 2.68, 39.48]], "batl": NaN}, {"timestamp": 1578731362957, "ltp": 2.8, "tv": 3488.35, "trd": NaN, "batb": [[1, 2.7, 38.09]], "batl": NaN}, {"timestamp": 1578731384979, "ltp": 2.8, "tv": 3488.35, "trd": NaN, "batb": [[1, 2.7, 4.51]], "batl": NaN}, {"timestamp": 1578731385602, "ltp": 2.8, "tv": 3488.35, "trd": NaN, "batb": [[0, 2.74, 12.8], [1, 2.72, 13.1], [2, 2.7, 4.51]], "batl": NaN}, {"timestamp": 1578731398785, "ltp": 2.8, "tv": 3488.35, "trd": NaN, "batb": [[0, 2.74, 14.8]], "batl": NaN}, {"timestamp": 1578731417345, "ltp": 2.8, "tv": 3488.35, "trd": NaN, "batb": [[0, 2.74, 35.09]], "batl": NaN}, {"timestamp": 1578731421921, "ltp": 2.8, "tv": 3488.35, "trd": NaN, "batb": [[1, 2.72, 21.3]], "batl": NaN}, {"timestamp": 1578731453989, "ltp": 2.78, "tv": 3493.49, "trd": [[2.78, 240.86]], "batb": [[0, 2.78, 7.43], [1, 2.74, 35.09], [2, 2.72, 21.3]], "batl": [[0, 2.8, 5.69], [1, 2.82, 4.6], [2, 2.84, 11.96]]}, {"timestamp": 1578731455902, "ltp": 2.78, "tv": 3493.49, "trd": NaN, "batb": [[1, 2.74, 38.01], [2, 2.72, 13.1]], "batl": NaN}, {"timestamp": 1578731513893, "ltp": 2.8, "tv": 3513.49, "trd": [[2.8, 182.61]], "batb": [[2, 2.7, 4.51]], "batl": [[0, 2.8, 6.41]]}, {"timestamp": 1578731581931, "ltp": 2.78, "tv": 3522.01, "trd": [[2.78, 249.37]], "batb": [[0, 2.78, 3.17]], "batl": NaN}, {"timestamp": 1578731583998, "ltp": 2.78, "tv": 3522.01, "trd": NaN, "batb": [[1, 2.74, 35.09], [2, 2.68, 37.48]], "batl": NaN}, {"timestamp": 1578731705804, "ltp": 2.8, "tv": 3525.87, "trd": [[2.8, 186.47]], "batb": NaN, "batl": [[0, 2.8, 4.48]]}, {"timestamp": 1578731708911, "ltp": 2.8, "tv": 3525.87, "trd": NaN, "batb": [[1, 2.76, 15.1], [2, 2.74, 35.09]], "batl": NaN}, {"timestamp": 1578731717919, "ltp": 2.8, "tv": 3534.82, "trd": [[2.8, 195.42]], "batb": [[0, 2.78, 16.66]], "batl": [[0, 2.82, 4.6], [1, 2.84, 11.96], [2, 2.88, 17.55]]}, {"timestamp": 1578731719928, "ltp": 2.8, "tv": 3534.82, "trd": NaN, "batb": [[0, 2.8, 10.83], [1, 2.78, 16.66], [2, 2.76, 20.74]], "batl": NaN}, {"timestamp": 1578731720953, "ltp": 2.8, "tv": 3534.82, "trd": NaN, "batb": [[1, 2.78, 18.66]], "batl": NaN}, {"timestamp": 1578731721365, "ltp": 2.8, "tv": 3534.82, "trd": NaN, "batb": [[1, 2.78, 22.42], [2, 2.76, 15.1]], "batl": NaN}, {"timestamp": 1578731733948, "ltp": 2.8, "tv": 3534.82, "trd": NaN, "batb": [[0, 2.8, 12.83], [1, 2.78, 20.42]], "batl": NaN}, {"timestamp": 1578731757896, "ltp": 2.8, "tv": 3560.48, "trd": [[2.8, 221.08]], "batb": [[0, 2.78, 20.42], [1, 2.76, 15.1], [2, 2.74, 33.09]], "batl": [[0, 2.8, 27.17], [1, 2.82, 4.6], [2, 2.84, 11.96]]}, {"timestamp": 1578731758986, "ltp": 2.8, "tv": 3561.7, "trd": [[2.8, 222.3]], "batb": NaN, "batl": [[0, 2.8, 26.56]]}, {"timestamp": 1578731759914, "ltp": 2.8, "tv": 3561.7, "trd": NaN, "batb": [[0, 2.78, 16.66], [1, 2.76, 21.96]], "batl": NaN}, {"timestamp": 1578731771934, "ltp": 2.8, "tv": 3561.7, "trd": NaN, "batb": [[0, 2.78, 18.66]], "batl": NaN}, {"timestamp": 1578731776936, "ltp": 2.8, "tv": 3561.7, "trd": NaN, "batb": [[1, 2.76, 6.86]], "batl": NaN}, {"timestamp": 1578731860896, "ltp": 2.8, "tv": 3614.82, "trd": [[2.8, 275.42]], "batb": [[0, 2.8, 26.22], [1, 2.78, 18.66], [2, 2.76, 6.86]], "batl": [[0, 2.82, 4.6], [1, 2.84, 11.96], [2, 2.88, 17.55]]}, {"timestamp": 1578731864625, "ltp": 2.8, "tv": 3614.82, "trd": NaN, "batb": [[1, 2.78, 21.32]], "batl": NaN}, {"timestamp": 1578731874922, "ltp": 2.8, "tv": 3614.82, "trd": NaN, "batb": [[1, 2.78, 19.32]], "batl": NaN}, {"timestamp": 1578731875844, "ltp": 2.8, "tv": 3614.82, "trd": NaN, "batb": [[0, 2.8, 28.22]], "batl": NaN}, {"timestamp": 1578731921488, "ltp": 2.8, "tv": 3614.82, "trd": NaN, "batb": [[0, 2.8, 2]], "batl": NaN}, {"timestamp": 1578731922988, "ltp": 2.8, "tv": 3618.82, "trd": [[2.8, 279.42]], "batb": [[0, 2.78, 16.66], [1, 2.74, 33.09], [2, 2.68, 23.39]], "batl": [[0, 2.8, 1], [1, 2.82, 4.6], [2, 2.84, 11.96]]}, {"timestamp": 1578731924997, "ltp": 2.8, "tv": 3618.82, "trd": NaN, "batb": [[1, 2.76, 5.64], [2, 2.74, 36.67]], "batl": NaN}, {"timestamp": 1578731941002, "ltp": 2.8, "tv": 3618.82, "trd": NaN, "batb": [[0, 2.78, 18.66]], "batl": NaN}, {"timestamp": 1578731954543, "ltp": 2.78, "tv": 3624.82, "trd": [[2.78, 255.37]], "batb": [[0, 2.78, 15.66], [1, 2.76, 11.93]], "batl": NaN}, {"timestamp": 1578731961539, "ltp": 2.78, "tv": 3624.82, "trd": NaN, "batb": [[1, 2.76, 9.24]], "batl": NaN}, {"timestamp": 1578731967958, "ltp": 2.78, "tv": 3632.82, "trd": [[2.78, 263.37]], "batb": [[0, 2.78, 11.66]], "batl": NaN}, {"timestamp": 1578731991581, "ltp": 2.78, "tv": 3632.82, "trd": NaN, "batb": [[1, 2.76, 7.83]], "batl": NaN}, {"timestamp": 1578732007820, "ltp": 2.8, "tv": 3634.82, "trd": [[2.8, 281.42]], "batb": NaN, "batl": [[0, 2.82, 4.6], [1, 2.84, 11.96], [2, 2.88, 17.55]]}, {"timestamp": 1578732133832, "ltp": 2.78, "tv": 3654.82, "trd": [[2.78, 283.37]], "batb": [[0, 2.78, 1.66]], "batl": NaN}, {"timestamp": 1578732142928, "ltp": 2.78, "tv": 3654.82, "trd": NaN, "batb": [[2, 2.74, 3.58]], "batl": NaN}, {"timestamp": 1578732143936, "ltp": 2.78, "tv": 3654.82, "trd": NaN, "batb": [[0, 2.78, 13.2], [1, 2.68, 23.39], [2, 2.66, 122.67]], "batl": [[0, 2.8, 10.83], [1, 2.82, 4.6], [2, 2.84, 11.96]]}, {"timestamp": 1578732145936, "ltp": 2.78, "tv": 3654.82, "trd": NaN, "batb": [[1, 2.7, 14.67], [2, 2.68, 50.86]], "batl": NaN}, {"timestamp": 1578732170948, "ltp": 2.78, "tv": 3654.82, "trd": NaN, "batb": [[1, 2.7, 29.35]], "batl": NaN}, {"timestamp": 1578732176983, "ltp": 2.78, "tv": 3654.82, "trd": NaN, "batb": [[0, 2.78, 34.27]], "batl": NaN}, {"timestamp": 1578732177980, "ltp": 2.78, "tv": 3654.82, "trd": NaN, "batb": [[1, 2.72, 14], [2, 2.7, 29.35]], "batl": NaN}, {"timestamp": 1578732207813, "ltp": 2.78, "tv": 3654.82, "trd": NaN, "batb": [[1, 2.74, 12.37], [2, 2.72, 36.12]], "batl": NaN}, {"timestamp": 1578732234887, "ltp": 2.78, "tv": 3654.82, "trd": NaN, "batb": [[0, 2.78, 32.61], [1, 2.76, 1.66], [2, 2.74, 12.37]], "batl": NaN}, {"timestamp": 1578732240911, "ltp": 2.78, "tv": 3654.82, "trd": NaN, "batb": [[0, 2.76, 34.27], [1, 2.74, 12.37], [2, 2.72, 36.12]], "batl": [[0, 2.82, 4.6], [1, 2.84, 11.96], [2, 2.86, 4.9]]}, {"timestamp": 1578732241997, "ltp": 2.78, "tv": 3654.82, "trd": NaN, "batb": [[0, 2.76, 34.51]], "batl": NaN}, {"timestamp": 1578732243937, "ltp": 2.78, "tv": 3654.82, "trd": NaN, "batb": [[2, 2.72, 21.45]], "batl": NaN}, {"timestamp": 1578732255956, "ltp": 2.78, "tv": 3654.82, "trd": NaN, "batb": NaN, "batl": [[2, 2.88, 17.55]]}, {"timestamp": 1578732265951, "ltp": 2.78, "tv": 3654.82, "trd": NaN, "batb": [[0, 2.76, 44.51]], "batl": NaN}, {"timestamp": 1578732266935, "ltp": 2.78, "tv": 3654.82, "trd": NaN, "batb": [[0, 2.76, 54.51]], "batl": NaN}, {"timestamp": 1578732268952, "ltp": 2.78, "tv": 3654.82, "trd": NaN, "batb": [[1, 2.74, 26.24]], "batl": NaN}, {"timestamp": 1578732301884, "ltp": 2.82, "tv": 3664.02, "trd": [[2.82, 78.72]], "batb": NaN, "batl": [[0, 2.84, 11.96], [1, 2.88, 17.55], [2, 2.9, 21.02]]}, {"timestamp": 1578732476964, "ltp": 2.82, "tv": 3664.02, "trd": NaN, "batb": [[2, 2.72, 7.45]], "batl": NaN}, {"timestamp": 1578732575902, "ltp": 2.82, "tv": 3664.02, "trd": NaN, "batb": [[0, 2.76, 56.21]], "batl": NaN}, {"timestamp": 1578732624956, "ltp": 2.82, "tv": 3664.02, "trd": NaN, "batb": NaN, "batl": [[1, 2.86, 20.9], [2, 2.88, 16.65]]}, {"timestamp": 1578732655969, "ltp": 2.82, "tv": 3664.02, "trd": NaN, "batb": [[1, 2.74, 30.8]], "batl": NaN}, {"timestamp": 1578732684938, "ltp": 2.84, "tv": 3677.78, "trd": [[2.84, 36.05]], "batb": [[0, 2.76, 75.32]], "batl": [[0, 2.84, 5.08]]}, {"timestamp": 1578732688924, "ltp": 2.84, "tv": 3677.78, "trd": NaN, "batb": [[0, 2.78, 71.16], [1, 2.76, 75.32], [2, 2.74, 30.8]], "batl": NaN}, {"timestamp": 1578732693949, "ltp": 2.84, "tv": 3677.78, "trd": NaN, "batb": [[2, 2.74, 33.8]], "batl": NaN}, {"timestamp": 1578732697937, "ltp": 2.84, "tv": 3677.78, "trd": NaN, "batb": [[0, 2.8, 32.38], [1, 2.78, 71.16], [2, 2.76, 42.48]], "batl": NaN}, {"timestamp": 1578732699956, "ltp": 2.84, "tv": 3677.78, "trd": NaN, "batb": [[1, 2.78, 81.86]], "batl": NaN}, {"timestamp": 1578732702960, "ltp": 2.84, "tv": 3677.78, "trd": NaN, "batb": [[0, 2.82, 10.21], [1, 2.8, 32.38], [2, 2.78, 81.86]], "batl": NaN}, {"timestamp": 1578732704974, "ltp": 2.84, "tv": 3677.78, "trd": NaN, "batb": [[1, 2.8, 35.94], [2, 2.76, 42.48]], "batl": NaN}, {"timestamp": 1578732713977, "ltp": 2.84, "tv": 3677.78, "trd": NaN, "batb": [[0, 2.82, 11.87], [2, 2.76, 40.82]], "batl": NaN}, {"timestamp": 1578732833997, "ltp": 2.84, "tv": 3681.78, "trd": [[2.84, 40.05]], "batb": NaN, "batl": [[0, 2.84, 3.08]]}, {"timestamp": 1578732866942, "ltp": 2.84, "tv": 3687.94, "trd": [[2.84, 46.22]], "batb": NaN, "batl": [[0, 2.86, 20.9], [1, 2.88, 16.65], [2, 2.9, 21.02]]}, {"timestamp": 1578732984000, "ltp": 2.86, "tv": 3729.74, "trd": [[2.86, 45.8]], "batb": NaN, "batl": [[0, 2.88, 16.65], [1, 2.9, 21.02], [2, 2.92, 20]]}, {"timestamp": 1578732993980, "ltp": 2.86, "tv": 3729.74, "trd": NaN, "batb": [[0, 2.82, 16.31]], "batl": NaN}, {"timestamp": 1578733005910, "ltp": 2.82, "tv": 3731.27, "trd": [[2.82, 80.25]], "batb": [[0, 2.82, 15.55]], "batl": NaN}, {"timestamp": 1578733035959, "ltp": 2.82, "tv": 3731.27, "trd": NaN, "batb": NaN, "batl": [[0, 2.86, 80], [1, 2.88, 16.65], [2, 2.9, 21.02]]}, {"timestamp": 1578733036951, "ltp": 2.82, "tv": 3731.27, "trd": NaN, "batb": NaN, "batl": [[0, 2.84, 13.03], [1, 2.86, 80], [2, 2.88, 16.65]]}, {"timestamp": 1578733041779, "ltp": 2.82, "tv": 3731.27, "trd": NaN, "batb": NaN, "batl": [[1, 2.88, 16.65], [2, 2.9, 21.02]]}, {"timestamp": 1578733042972, "ltp": 2.82, "tv": 3731.27, "trd": NaN, "batb": NaN, "batl": [[0, 2.84, 10.71]]}, {"timestamp": 1578733052878, "ltp": 2.82, "tv": 3731.27, "trd": NaN, "batb": NaN, "batl": [[1, 2.86, 20], [2, 2.88, 16.65]]}, {"timestamp": 1578733104857, "ltp": 2.84, "tv": 3741.1, "trd": [[2.84, 56.04]], "batb": NaN, "batl": [[0, 2.84, 5.8]]}, {"timestamp": 1578733186810, "ltp": 2.84, "tv": 3752.69, "trd": [[2.84, 67.64]], "batb": [[0, 2.84, 63.86], [1, 2.82, 15.55], [2, 2.8, 35.94]], "batl": [[0, 2.86, 20], [1, 2.88, 16.65], [2, 2.9, 21.02]]}, {"timestamp": 1578733188892, "ltp": 2.84, "tv": 3752.69, "trd": NaN, "batb": [[1, 2.82, 29.5]], "batl": NaN}, {"timestamp": 1578733202935, "ltp": 2.84, "tv": 3752.69, "trd": NaN, "batb": [[0, 2.82, 29.5], [1, 2.8, 35.94], [2, 2.76, 40.82]], "batl": NaN}, {"timestamp": 1578733205942, "ltp": 2.84, "tv": 3752.69, "trd": NaN, "batb": [[0, 2.82, 15.55], [1, 2.8, 42.14]], "batl": NaN}, {"timestamp": 1578733220876, "ltp": 2.84, "tv": 3752.69, "trd": NaN, "batb": NaN, "batl": [[0, 2.84, 1.7], [1, 2.86, 20], [2, 2.88, 16.65]]}, {"timestamp": 1578733292905, "ltp": 2.84, "tv": 3752.69, "trd": NaN, "batb": [[0, 2.82, 6.1]], "batl": NaN}, {"timestamp": 1578733304822, "ltp": 2.84, "tv": 3752.69, "trd": NaN, "batb": [[1, 2.8, 32.38]], "batl": NaN}, {"timestamp": 1578733313965, "ltp": 2.82, "tv": 3756.01, "trd": [[2.82, 83.57]], "batb": [[0, 2.8, 32.38], [1, 2.76, 40.82], [2, 2.74, 15.37]], "batl": NaN}, {"timestamp": 1578733314943, "ltp": 2.82, "tv": 3756.01, "trd": NaN, "batb": [[1, 2.78, 2.43], [2, 2.76, 40.82]], "batl": NaN}, {"timestamp": 1578733315937, "ltp": 2.82, "tv": 3756.01, "trd": NaN, "batb": [[0, 2.8, 36.84], [1, 2.78, 13.13]], "batl": NaN}, {"timestamp": 1578733319964, "ltp": 2.86, "tv": 3776.02, "trd": [[2.84, 71.04], [2.86, 62.4]], "batb": NaN, "batl": [[0, 2.86, 11.7], [1, 2.88, 16.65], [2, 2.9, 21.02]]}, {"timestamp": 1578733335905, "ltp": 2.86, "tv": 3776.02, "trd": NaN, "batb": [[0, 2.8, 38.84]], "batl": NaN}, {"timestamp": 1578733440979, "ltp": 2.86, "tv": 3776.02, "trd": NaN, "batb": [[0, 2.82, 6.19], [1, 2.8, 38.84], [2, 2.78, 13.13]], "batl": NaN}, {"timestamp": 1578733443975, "ltp": 2.86, "tv": 3776.02, "trd": NaN, "batb": [[2, 2.78, 2.43]], "batl": NaN}, {"timestamp": 1578733478975, "ltp": 2.86, "tv": 3776.02, "trd": NaN, "batb": [[0, 2.82, 8.19], [1, 2.8, 36.84]], "batl": NaN}, {"timestamp": 1578733538857, "ltp": 2.86, "tv": 3793.86, "trd": [[2.86, 80.24]], "batb": [[0, 2.84, 1.7], [1, 2.82, 8.19], [2, 2.8, 36.84]], "batl": [[0, 2.86, 2.78]]}, {"timestamp": 1578733545973, "ltp": 2.86, "tv": 3799.42, "trd": [[2.86, 85.8]], "batb": [[0, 2.86, 5.73], [1, 2.84, 1.7], [2, 2.82, 8.19]], "batl": [[0, 2.88, 16.65], [1, 2.9, 21.02], [2, 2.92, 20]]}, {"timestamp": 1578733547999, "ltp": 2.86, "tv": 3799.42, "trd": NaN, "batb": [[2, 2.82, 10.49]], "batl": NaN}, {"timestamp": 1578733568993, "ltp": 2.86, "tv": 3799.42, "trd": NaN, "batb": [[1, 2.84, 3.7], [2, 2.82, 8.49]], "batl": NaN}, {"timestamp": 1578733591824, "ltp": 2.86, "tv": 3810.88, "trd": [[2.86, 97.26]], "batb": [[0, 2.84, 3.7], [1, 2.82, 8.49], [2, 2.8, 36.84]], "batl": [[0, 2.86, 54.27], [1, 2.88, 16.65], [2, 2.9, 21.02]]}, {"timestamp": 1578733593929, "ltp": 2.86, "tv": 3814.88, "trd": [[2.86, 101.26]], "batb": [[0, 2.84, 1.7], [1, 2.82, 6.19]], "batl": [[0, 2.86, 52.27], [1, 2.88, 18.94]]}, {"timestamp": 1578733594914, "ltp": 2.84, "tv": 3818.28, "trd": [[2.84, 74.44]], "batb": [[0, 2.82, 6.19], [1, 2.8, 36.84], [2, 2.76, 40.82]], "batl": NaN}, {"timestamp": 1578733633278, "ltp": 2.84, "tv": 3818.28, "trd": NaN, "batb": [[0, 2.82, 8.19]], "batl": NaN}, {"timestamp": 1578733751948, "ltp": 2.82, "tv": 3834.66, "trd": [[2.82, 99.95]], "batb": [[0, 2.8, 36.84], [1, 2.76, 40.82], [2, 2.74, 3]], "batl": [[0, 2.82, 1.81], [1, 2.86, 52.27], [2, 2.88, 18.94]]}, {"timestamp": 1578733752850, "ltp": 2.82, "tv": 3838.28, "trd": [[2.82, 103.57]], "batb": [[0, 2.82, 9], [1, 2.8, 36.84], [2, 2.78, 3.17]], "batl": [[0, 2.86, 52.27], [1, 2.88, 18.94], [2, 2.9, 21.02]]}, {"timestamp": 1578733775998, "ltp": 2.82, "tv": 3838.28, "trd": NaN, "batb": [[0, 2.82, 11]], "batl": NaN}, {"timestamp": 1578733794925, "ltp": 2.82, "tv": 3838.28, "trd": NaN, "batb": [[1, 2.8, 40.65]], "batl": [[0, 2.84, 13.59], [1, 2.86, 52.27], [2, 2.88, 18.94]]}, {"timestamp": 1578733819918, "ltp": 2.82, "tv": 3842.28, "trd": [[2.82, 107.57]], "batb": [[0, 2.82, 9]], "batl": NaN}, {"timestamp": 1578733826865, "ltp": 2.82, "tv": 3842.28, "trd": NaN, "batb": [[1, 2.8, 36.84]], "batl": NaN}, {"timestamp": 1578733885932, "ltp": 2.82, "tv": 4042.6, "trd": [[2.76, 478.19], [2.78, 289.71], [2.8, 355.1], [2.82, 147.15]], "batb": [[0, 2.82, 7.92], [1, 2.7, 52.04], [2, 2.68, 48.52]], "batl": NaN}, {"timestamp": 1578733886916, "ltp": 2.82, "tv": 4058.44, "trd": [[2.82, 162.99]], "batb": [[0, 2.7, 52.04], [1, 2.68, 48.52], [2, 2.66, 122.67]], "batl": NaN}, {"timestamp": 1578733887909, "ltp": 2.82, "tv": 4058.44, "trd": NaN, "batb": [[0, 2.7, 22.45]], "batl": NaN}, {"timestamp": 1578733889914, "ltp": 2.82, "tv": 4058.44, "trd": NaN, "batb": [[0, 2.72, 70.26], [1, 2.7, 22], [2, 2.68, 48.52]], "batl": NaN}, {"timestamp": 1578733890916, "ltp": 2.82, "tv": 4058.44, "trd": NaN, "batb": [[0, 2.74, 4.85], [1, 2.72, 69.81], [2, 2.7, 22]], "batl": NaN}, {"timestamp": 1578733904931, "ltp": 2.82, "tv": 4058.44, "trd": NaN, "batb": [[1, 2.72, 3.13]], "batl": NaN}, {"timestamp": 1578733931992, "ltp": 2.82, "tv": 4058.44, "trd": NaN, "batb": [[0, 2.74, 6.85]], "batl": NaN}, {"timestamp": 1578733963933, "ltp": 2.82, "tv": 4058.44, "trd": NaN, "batb": NaN, "batl": [[0, 2.82, 2.32], [1, 2.84, 13.59], [2, 2.86, 52.27]]}, {"timestamp": 1578733965825, "ltp": 2.82, "tv": 4058.44, "trd": NaN, "batb": [[1, 2.72, 17.23]], "batl": NaN}, {"timestamp": 1578733984822, "ltp": 2.74, "tv": 4066.02, "trd": [[2.74, 366.09], [2.76, 479.1]], "batb": [[0, 2.74, 3.06]], "batl": NaN}, {"timestamp": 1578733995955, "ltp": 2.74, "tv": 4066.02, "trd": NaN, "batb": [[0, 2.74, 5.8]], "batl": NaN}, {"timestamp": 1578734056843, "ltp": 2.74, "tv": 4077.64, "trd": [[2.74, 377.71]], "batb": [[0, 2.74, 3]], "batl": NaN}, {"timestamp": 1578734061934, "ltp": 2.66, "tv": 4247.88, "trd": [[2.66, 130.11], [2.68, 194.8], [2.7, 886.65], [2.72, 263.22], [2.74, 383.7]], "batb": [[0, 2.68, 17.3], [1, 2.66, 98.47], [2, 2.64, 8.54]], "batl": NaN}, {"timestamp": 1578734064952, "ltp": 2.66, "tv": 4247.88, "trd": NaN, "batb": [[0, 2.7, 67.17], [1, 2.68, 17.3], [2, 2.66, 98.47]], "batl": [[2, 2.88, 16.65]]}, {"timestamp": 1578734079757, "ltp": 2.7, "tv": 4381.85, "trd": [[2.7, 1020.63]], "batb": [[0, 2.68, 17.5], [1, 2.66, 98.47], [2, 2.64, 8.54]], "batl": NaN}, {"timestamp": 1578734080950, "ltp": 2.7, "tv": 4381.85, "trd": NaN, "batb": [[0, 2.7, 97.88], [1, 2.68, 17.3], [2, 2.66, 98.47]], "batl": NaN}, {"timestamp": 1578734084971, "ltp": 2.7, "tv": 4381.85, "trd": NaN, "batb": [[0, 2.72, 2.84], [1, 2.7, 97.88], [2, 2.68, 30.02]], "batl": NaN}, {"timestamp": 1578734089945, "ltp": 2.7, "tv": 4518.16, "trd": [[2.7, 1151.25], [2.72, 268.91]], "batb": [[0, 2.7, 32.59], [1, 2.68, 30.02], [2, 2.66, 98.47]], "batl": NaN}, {"timestamp": 1578734105978, "ltp": 2.7, "tv": 4582.15, "trd": [[2.7, 1215.24]], "batb": [[0, 2.68, 30.62], [1, 2.66, 98.47], [2, 2.64, 8.54]], "batl": NaN}, {"timestamp": 1578734108904, "ltp": 2.7, "tv": 4582.15, "trd": NaN, "batb": [[0, 2.68, 17.9], [1, 2.66, 110.51]], "batl": NaN}, {"timestamp": 1578734112911, "ltp": 2.7, "tv": 4582.15, "trd": NaN, "batb": [[0, 2.68, 19.9]], "batl": NaN}, {"timestamp": 1578734116808, "ltp": 2.7, "tv": 4582.15, "trd": NaN, "batb": [[0, 2.7, 13.76], [1, 2.68, 19.3], [2, 2.66, 110.51]], "batl": NaN}, {"timestamp": 1578734118903, "ltp": 2.68, "tv": 4616.14, "trd": [[2.68, 201.28], [2.7, 1242.75]], "batb": [[0, 2.72, 3], [1, 2.68, 16.06]], "batl": NaN}, {"timestamp": 1578734125893, "ltp": 2.68, "tv": 4616.14, "trd": NaN, "batb": [[1, 2.7, 2], [2, 2.68, 14.06]], "batl": NaN}, {"timestamp": 1578734135951, "ltp": 2.68, "tv": 4616.14, "trd": NaN, "batb": [[0, 2.7, 5], [1, 2.68, 14.06], [2, 2.66, 110.51]], "batl": NaN}, {"timestamp": 1578734138938, "ltp": 2.68, "tv": 4616.14, "trd": NaN, "batb": [[0, 2.72, 2], [1, 2.7, 3], [2, 2.68, 14.06]], "batl": NaN}, {"timestamp": 1578734139932, "ltp": 2.68, "tv": 4616.14, "trd": NaN, "batb": [[2, 2.68, 7.97]], "batl": NaN}, {"timestamp": 1578734140878, "ltp": 2.68, "tv": 4616.14, "trd": NaN, "batb": [[2, 2.66, 98.47]], "batl": [[0, 2.8, 3.08], [1, 2.82, 2.32], [2, 2.84, 13.59]]}, {"timestamp": 1578734144947, "ltp": 2.68, "tv": 4616.14, "trd": NaN, "batb": [[2, 2.68, 6]], "batl": NaN}, {"timestamp": 1578734191991, "ltp": 2.72, "tv": 4620.14, "trd": [[2.72, 272.91]], "batb": [[0, 2.7, 3], [1, 2.68, 6], [2, 2.66, 98.47]], "batl": NaN}, {"timestamp": 1578734193930, "ltp": 2.72, "tv": 4620.14, "trd": NaN, "batb": [[0, 2.7, 6.11], [1, 2.68, 22]], "batl": NaN}, {"timestamp": 1578734203943, "ltp": 2.72, "tv": 4620.14, "trd": NaN, "batb": [[0, 2.7, 8.11]], "batl": NaN}, {"timestamp": 1578734225939, "ltp": 2.72, "tv": 4620.14, "trd": NaN, "batb": NaN, "batl": [[0, 2.78, 1.7], [1, 2.8, 3.08]]}, {"timestamp": 1578734290976, "ltp": 2.72, "tv": 4620.14, "trd": NaN, "batb": NaN, "batl": [[0, 2.8, 3.08], [1, 2.84, 13.59], [2, 2.86, 8.8]]}, {"timestamp": 1578734291609, "ltp": 2.72, "tv": 4620.14, "trd": NaN, "batb": NaN, "batl": [[1, 2.82, 1.7], [2, 2.84, 13.59]]}, {"timestamp": 1578734339833, "ltp": 2.72, "tv": 4620.14, "trd": NaN, "batb": NaN, "batl": [[0, 2.78, 1.7], [1, 2.8, 3.08]]}, {"timestamp": 1578734356968, "ltp": 2.7, "tv": 4636.14, "trd": [[2.7, 1258.75]], "batb": [[0, 2.7, 3.22], [2, 2.66, 103.17]], "batl": NaN}, {"timestamp": 1578734365917, "ltp": 2.7, "tv": 4636.14, "trd": NaN, "batb": NaN, "batl": [[0, 2.76, 3.4], [1, 2.78, 1.7], [2, 2.8, 3.08]]}, {"timestamp": 1578734366918, "ltp": 2.7, "tv": 4636.14, "trd": NaN, "batb": NaN, "batl": [[0, 2.78, 1.7], [1, 2.8, 3.08], [2, 2.84, 13.59]]}, {"timestamp": 1578734374995, "ltp": 2.7, "tv": 4636.14, "trd": NaN, "batb": [[0, 2.7, 21.15]], "batl": [[0, 2.78, 4.61], [1, 2.84, 13.59], [2, 2.86, 8.8]]}, {"timestamp": 1578734375825, "ltp": 2.7, "tv": 4636.14, "trd": NaN, "batb": [[0, 2.7, 31.15]], "batl": NaN}, {"timestamp": 1578734379809, "ltp": 2.7, "tv": 4636.14, "trd": NaN, "batb": [[0, 2.72, 10.32], [1, 2.7, 31.15], [2, 2.68, 6]], "batl": [[2, 2.88, 16.65]]}, {"timestamp": 1578734384935, "ltp": 2.7, "tv": 4636.14, "trd": NaN, "batb": [[0, 2.72, 10.43], [1, 2.7, 31.04]], "batl": NaN}, {"timestamp": 1578734399835, "ltp": 2.72, "tv": 4657.0, "trd": [[2.72, 293.77]], "batb": [[0, 2.7, 31.04], [1, 2.68, 12.92], [2, 2.66, 98.47]], "batl": NaN}, {"timestamp": 1578734401947, "ltp": 2.72, "tv": 4657.0, "trd": NaN, "batb": [[0, 2.7, 27.93], [1, 2.68, 21.83]], "batl": NaN}, {"timestamp": 1578734402971, "ltp": 2.78, "tv": 4660.4, "trd": [[2.78, 293.11]], "batb": NaN, "batl": [[0, 2.82, 2.87]]}, {"timestamp": 1578734406954, "ltp": 2.7, "tv": 4716.26, "trd": [[2.7, 1314.61]], "batb": [[0, 2.68, 41.51], [1, 2.66, 109.56], [2, 2.64, 8.54]], "batl": [[0, 2.7, 3.07], [1, 2.82, 2.87], [2, 2.84, 13.59]]}, {"timestamp": 1578734411935, "ltp": 2.7, "tv": 4716.26, "trd": NaN, "batb": [[0, 2.68, 43.51]], "batl": NaN}, {"timestamp": 1578734416738, "ltp": 2.7, "tv": 4716.26, "trd": NaN, "batb": [[0, 2.68, 27.68], [1, 2.66, 117.11]], "batl": NaN}, {"timestamp": 1578734445966, "ltp": 2.68, "tv": 4777.76, "trd": [[2.68, 262.77]], "batb": [[0, 2.66, 117.11], [1, 2.64, 18.28], [2, 2.62, 6.06]], "batl": [[0, 2.68, 12.25], [1, 2.7, 3.07], [2, 2.82, 2.87]]}, {"timestamp": 1578734446967, "ltp": 2.68, "tv": 4800.74, "trd": [[2.68, 285.75]], "batb": NaN, "batl": [[0, 2.68, 6.76]]}, {"timestamp": 1578734448000, "ltp": 2.68, "tv": 4806.26, "trd": [[2.68, 291.27]], "batb": [[0, 2.66, 103.04]], "batl": [[0, 2.68, 4]]}, {"timestamp": 1578734449981, "ltp": 2.68, "tv": 4806.26, "trd": NaN, "batb": [[2, 2.62, 3.06]], "batl": NaN}, {"timestamp": 1578734456988, "ltp": 2.68, "tv": 4814.26, "trd": [[2.68, 299.27]], "batb": [[0, 2.68, 8.36], [1, 2.66, 103.04], [2, 2.64, 18.28]], "batl": [[0, 2.7, 3.07], [1, 2.82, 2.87], [2, 2.84, 13.59]]}, {"timestamp": 1578734457982, "ltp": 2.68, "tv": 4814.26, "trd": NaN, "batb": [[0, 2.68, 12.84]], "batl": [[1, 2.82, 8.54]]}, {"timestamp": 1578734458915, "ltp": 2.68, "tv": 4814.26, "trd": NaN, "batb": [[2, 2.64, 8.54]], "batl": NaN}, {"timestamp": 1578734460890, "ltp": 2.68, "tv": 4814.26, "trd": NaN, "batb": NaN, "batl": [[1, 2.82, 2.87]]}, {"timestamp": 1578734475917, "ltp": 2.68, "tv": 4814.26, "trd": NaN, "batb": [[0, 2.68, 14.84]], "batl": NaN}, {"timestamp": 1578734486976, "ltp": 2.68, "tv": 4814.26, "trd": NaN, "batb": [[0, 2.68, 10.36]], "batl": NaN}, {"timestamp": 1578734506996, "ltp": 2.7, "tv": 4820.4, "trd": [[2.7, 1320.75]], "batb": [[1, 2.66, 98.47]], "batl": [[0, 2.82, 2.87], [1, 2.84, 13.59], [2, 2.88, 16.65]]}, {"timestamp": 1578734517914, "ltp": 2.7, "tv": 4820.4, "trd": NaN, "batb": NaN, "batl": [[2, 2.86, 10.04]]}, {"timestamp": 1578734543930, "ltp": 2.7, "tv": 4820.4, "trd": NaN, "batb": [[0, 2.7, 1.75], [1, 2.68, 10.36], [2, 2.66, 98.47]], "batl": NaN}, {"timestamp": 1578734639976, "ltp": 2.7, "tv": 4820.4, "trd": NaN, "batb": [[1, 2.68, 13.36]], "batl": NaN}, {"timestamp": 1578734976987, "ltp": 2.7, "tv": 4820.4, "trd": NaN, "batb": [[0, 2.7, 11.75], [1, 2.68, 23.36]], "batl": NaN}, {"timestamp": 1578734977979, "ltp": 2.7, "tv": 4820.4, "trd": NaN, "batb": [[1, 2.68, 26.39]], "batl": NaN}, {"timestamp": 1578734984920, "ltp": 2.7, "tv": 4820.4, "trd": NaN, "batb": [[1, 2.68, 23.39]], "batl": NaN}, {"timestamp": 1578734985911, "ltp": 2.7, "tv": 4820.4, "trd": NaN, "batb": [[0, 2.7, 13.75], [1, 2.68, 25.2]], "batl": NaN}, {"timestamp": 1578735011927, "ltp": 2.7, "tv": 4820.4, "trd": NaN, "batb": NaN, "batl": [[0, 2.76, 2], [1, 2.82, 2.87], [2, 2.84, 13.59]]}, {"timestamp": 1578735097944, "ltp": 2.7, "tv": 4847.9, "trd": [[2.7, 1348.25]], "batb": [[0, 2.68, 29.68], [1, 2.66, 98.47], [2, 2.62, 3.56]], "batl": [[0, 2.7, 46.25], [1, 2.76, 2], [2, 2.82, 2.87]]}, {"timestamp": 1578735098988, "ltp": 2.7, "tv": 4847.9, "trd": NaN, "batb": [[1, 2.66, 102.87]], "batl": [[0, 2.7, 63.27]]}, {"timestamp": 1578735099982, "ltp": 2.7, "tv": 4847.9, "trd": NaN, "batb": [[0, 2.68, 22.84], [1, 2.66, 111.12]], "batl": [[2, 2.82, 32.7]]}, {"timestamp": 1578735101984, "ltp": 2.7, "tv": 4847.9, "trd": NaN, "batb": NaN, "batl": [[2, 2.82, 47.62]]}, {"timestamp": 1578735151802, "ltp": 2.7, "tv": 4974.44, "trd": [[2.7, 1474.8]], "batb": [[0, 2.7, 136.73], [1, 2.68, 18.36], [2, 2.66, 111.12]], "batl": [[0, 2.76, 2], [1, 2.82, 47.62], [2, 2.84, 28.32]]}, {"timestamp": 1578735156901, "ltp": 2.7, "tv": 4974.44, "trd": NaN, "batb": [[0, 2.72, 14.58], [1, 2.7, 136.73], [2, 2.68, 10]], "batl": NaN}, {"timestamp": 1578735181775, "ltp": 2.7, "tv": 4974.44, "trd": NaN, "batb": [[1, 2.7, 141.72]], "batl": [[1, 2.82, 2.87], [2, 2.84, 13.59]]}, {"timestamp": 1578735197974, "ltp": 2.7, "tv": 4974.44, "trd": NaN, "batb": [[0, 2.72, 44.58]], "batl": NaN}, {"timestamp": 1578735221973, "ltp": 2.7, "tv": 4974.44, "trd": NaN, "batb": [[1, 2.7, 150.77]], "batl": NaN}, {"timestamp": 1578735229998, "ltp": 2.76, "tv": 4977.85, "trd": [[2.76, 482.5]], "batb": NaN, "batl": [[0, 2.82, 3.17], [1, 2.84, 13.59], [2, 2.88, 16.65]]}, {"timestamp": 1578735230889, "ltp": 2.76, "tv": 4978.45, "trd": [[2.76, 483.1]], "batb": NaN, "batl": [[0, 2.82, 2.87]]}, {"timestamp": 1578735251987, "ltp": 2.76, "tv": 4978.45, "trd": NaN, "batb": NaN, "batl": [[0, 2.8, 32.38], [1, 2.82, 2.87], [2, 2.84, 13.59]]}, {"timestamp": 1578735348718, "ltp": 2.76, "tv": 4978.45, "trd": NaN, "batb": NaN, "batl": [[1, 2.84, 13.59], [2, 2.88, 16.65]]}, {"timestamp": 1578735349911, "ltp": 2.76, "tv": 4978.45, "trd": NaN, "batb": NaN, "batl": [[1, 2.84, 19.85]]}, {"timestamp": 1578735377992, "ltp": 2.76, "tv": 4978.45, "trd": NaN, "batb": NaN, "batl": [[0, 2.82, 13.06], [2, 2.86, 14.5]]}, {"timestamp": 1578735399914, "ltp": 2.76, "tv": 4978.45, "trd": NaN, "batb": NaN, "batl": [[1, 2.84, 13.59], [2, 2.88, 16.65]]}, {"timestamp": 1578735418950, "ltp": 2.84, "tv": 5031.74, "trd": [[2.82, 189.1], [2.84, 101.62]], "batb": [[0, 2.84, 32.35], [1, 2.72, 44.58], [2, 2.7, 150.77]], "batl": [[0, 2.86, 10.56], [1, 2.88, 21.6], [2, 2.9, 30.92]]}, {"timestamp": 1578735420929, "ltp": 2.84, "tv": 5031.74, "trd": NaN, "batb": [[1, 2.74, 32], [2, 2.72, 59.08]], "batl": NaN}, {"timestamp": 1578735421971, "ltp": 2.84, "tv": 5031.74, "trd": NaN, "batb": NaN, "batl": [[1, 2.88, 16.65], [2, 2.9, 21.02]]}, {"timestamp": 1578735428855, "ltp": 2.86, "tv": 5052.86, "trd": [[2.86, 122.38]], "batb": [[0, 2.86, 21.79], [1, 2.76, 11], [2, 2.74, 32]], "batl": [[0, 2.88, 16.65], [1, 2.9, 21.02], [2, 2.92, 20]]}, {"timestamp": 1578735429948, "ltp": 2.86, "tv": 5052.86, "trd": NaN, "batb": [[1, 2.78, 14.44], [2, 2.76, 25.44]], "batl": NaN}, {"timestamp": 1578735431990, "ltp": 2.86, "tv": 5052.86, "trd": NaN, "batb": [[1, 2.78, 28.87]], "batl": NaN}, {"timestamp": 1578735434966, "ltp": 2.88, "tv": 5086.16, "trd": [[2.88, 33.3]], "batb": [[0, 2.88, 5.14], [2, 2.76, 40.11]], "batl": [[0, 2.9, 21.02], [1, 2.92, 20], [2, 2.98, 9.81]]}, {"timestamp": 1578735436954, "ltp": 2.88, "tv": 5086.16, "trd": NaN, "batb": [[1, 2.78, 2.67], [2, 2.76, 11]], "batl": NaN}, {"timestamp": 1578735437896, "ltp": 2.88, "tv": 5086.16, "trd": NaN, "batb": [[1, 2.78, 5.9]], "batl": NaN}, {"timestamp": 1578735438987, "ltp": 2.88, "tv": 5086.16, "trd": NaN, "batb": [[0, 2.78, 5.9], [1, 2.76, 11], [2, 2.74, 3]], "batl": NaN}, {"timestamp": 1578735439977, "ltp": 2.88, "tv": 5086.16, "trd": NaN, "batb": [[0, 2.78, 2.67], [1, 2.76, 17.62]], "batl": NaN}, {"timestamp": 1578735442002, "ltp": 2.88, "tv": 5086.16, "trd": NaN, "batb": [[0, 2.74, 14.06], [1, 2.72, 44.58], [2, 2.7, 136.73]], "batl": [[1, 2.92, 26.44]]}, {"timestamp": 1578735468951, "ltp": 2.88, "tv": 5086.16, "trd": NaN, "batb": [[1, 2.72, 49.4]], "batl": NaN}, {"timestamp": 1578735475959, "ltp": 2.9, "tv": 5090.16, "trd": [[2.9, 4]], "batb": NaN, "batl": [[0, 2.9, 19.02]]}, {"timestamp": 1578735487972, "ltp": 2.9, "tv": 5112.16, "trd": [[2.9, 26]], "batb": [[0, 2.76, 13.34], [1, 2.74, 14.06], [2, 2.72, 49.4]], "batl": [[0, 2.9, 8.02]]}, {"timestamp": 1578735489001, "ltp": 2.9, "tv": 5134.16, "trd": [[2.9, 48]], "batb": [[0, 2.76, 16.34], [1, 2.74, 18.18]], "batl": [[0, 2.92, 26.46], [1, 2.98, 9.81], [2, 3, 22.3]]}, {"timestamp": 1578735489982, "ltp": 2.9, "tv": 5134.2, "trd": [[2.9, 48.04]], "batb": NaN, "batl": [[0, 2.92, 26.44]]}, {"timestamp": 1578735499915, "ltp": 2.92, "tv": 5138.2, "trd": [[2.92, 4]], "batb": NaN, "batl": [[0, 2.92, 24.44]]}, {"timestamp": 1578735506000, "ltp": 2.92, "tv": 5138.2, "trd": NaN, "batb": [[0, 2.78, 10.32], [1, 2.76, 16.34], [2, 2.74, 18.18]], "batl": NaN}, {"timestamp": 1578735506826, "ltp": 2.92, "tv": 5138.2, "trd": NaN, "batb": NaN, "batl": [[1, 2.96, 6.2], [2, 2.98, 19.46]]}, {"timestamp": 1578735524941, "ltp": 2.92, "tv": 5138.2, "trd": NaN, "batb": NaN, "batl": [[0, 2.9, 4], [1, 2.92, 24.44], [2, 2.96, 6.2]]}, {"timestamp": 1578735529933, "ltp": 2.92, "tv": 5138.2, "trd": NaN, "batb": [[1, 2.76, 19.94]], "batl": [[2, 2.98, 9.81]]}, {"timestamp": 1578735532800, "ltp": 2.9, "tv": 5146.2, "trd": [[2.9, 56.04]], "batb": NaN, "batl": [[0, 2.92, 24.44], [1, 2.98, 9.81], [2, 3, 22.3]]}, {"timestamp": 1578735546966, "ltp": 2.9, "tv": 5146.2, "trd": NaN, "batb": NaN, "batl": [[1, 2.96, 6.2], [2, 2.98, 19.46]]}, {"timestamp": 1578735552975, "ltp": 2.9, "tv": 5146.2, "trd": NaN, "batb": [[0, 2.8, 4.14], [1, 2.78, 10.32], [2, 2.76, 19.94]], "batl": NaN}, {"timestamp": 1578735564927, "ltp": 2.9, "tv": 5146.2, "trd": NaN, "batb": NaN, "batl": [[0, 2.92, 18], [1, 2.96, 13.47]]}, {"timestamp": 1578735577914, "ltp": 2.9, "tv": 5146.2, "trd": NaN, "batb": [[2, 2.76, 16.34]], "batl": [[1, 2.96, 7.27]]}, {"timestamp": 1578735587953, "ltp": 2.92, "tv": 5166.2, "trd": [[2.92, 24]], "batb": NaN, "batl": [[0, 2.92, 8]]}, {"timestamp": 1578735592950, "ltp": 2.8, "tv": 5174.48, "trd": [[2.8, 363.38]], "batb": [[0, 2.78, 10.32], [1, 2.76, 16.34], [2, 2.74, 14.06]], "batl": [[0, 2.8, 11.86], [1, 2.92, 8], [2, 2.96, 7.27]]}, {"timestamp": 1578735594867, "ltp": 2.8, "tv": 5174.48, "trd": NaN, "batb": [[1, 2.76, 19.94]], "batl": [[1, 2.9, 14.62], [2, 2.92, 10.83]]}, {"timestamp": 1578735597938, "ltp": 2.8, "tv": 5174.48, "trd": NaN, "batb": [[2, 2.74, 11.06]], "batl": NaN}, {"timestamp": 1578735608957, "ltp": 2.8, "tv": 5174.48, "trd": NaN, "batb": [[1, 2.76, 16.94]], "batl": NaN}, {"timestamp": 1578735621968, "ltp": 2.8, "tv": 5174.48, "trd": NaN, "batb": [[0, 2.76, 16.94], [1, 2.74, 11.06], [2, 2.72, 30]], "batl": NaN}, {"timestamp": 1578735623000, "ltp": 2.8, "tv": 5174.48, "trd": NaN, "batb": [[2, 2.72, 34.3]], "batl": [[0, 2.78, 2.5], [1, 2.8, 11.86], [2, 2.9, 29.22]]}, {"timestamp": 1578735623980, "ltp": 2.8, "tv": 5174.48, "trd": NaN, "batb": [[0, 2.76, 13.34], [1, 2.74, 16.81]], "batl": [[2, 2.92, 8]]}, {"timestamp": 1578735641937, "ltp": 2.8, "tv": 5174.48, "trd": NaN, "batb": [[0, 2.76, 17.49]], "batl": NaN}, {"timestamp": 1578735642917, "ltp": 2.8, "tv": 5174.48, "trd": NaN, "batb": [[0, 2.76, 13.34]], "batl": NaN}, {"timestamp": 1578735644828, "ltp": 2.8, "tv": 5174.48, "trd": NaN, "batb": [[0, 2.76, 16.49]], "batl": NaN}, {"timestamp": 1578735657611, "ltp": 2.8, "tv": 5174.48, "trd": NaN, "batb": [[2, 2.72, 45.85]], "batl": NaN}, {"timestamp": 1578735661932, "ltp": 2.76, "tv": 5180.48, "trd": [[2.76, 489.1]], "batb": [[0, 2.76, 13.49]], "batl": NaN}, {"timestamp": 1578735665940, "ltp": 2.76, "tv": 5180.48, "trd": NaN, "batb": [[0, 2.76, 17.64]], "batl": NaN}, {"timestamp": 1578735707911, "ltp": 2.78, "tv": 5185.48, "trd": [[2.78, 298.11]], "batb": [[0, 2.78, 12.93], [1, 2.76, 17.64], [2, 2.74, 21.04]], "batl": [[0, 2.8, 11.86], [1, 2.92, 8], [2, 2.98, 9.81]]}, {"timestamp": 1578735708734, "ltp": 2.78, "tv": 5185.48, "trd": NaN, "batb": [[1, 2.76, 13.49]], "batl": [[1, 2.9, 3.87], [2, 2.92, 8]]}, {"timestamp": 1578735709627, "ltp": 2.78, "tv": 5185.48, "trd": NaN, "batb": [[1, 2.76, 17.94]], "batl": NaN}, {"timestamp": 1578735720834, "ltp": 2.78, "tv": 5185.48, "trd": NaN, "batb": NaN, "batl": [[1, 2.9, 18.49]]}, {"timestamp": 1578735723954, "ltp": 2.8, "tv": 5200.9, "trd": [[2.8, 378.8]], "batb": [[1, 2.76, 7.59]], "batl": [[0, 2.8, 4.15]]}, {"timestamp": 1578735737984, "ltp": 2.8, "tv": 5200.9, "trd": NaN, "batb": [[1, 2.76, 4.44]], "batl": NaN}, {"timestamp": 1578735744961, "ltp": 2.8, "tv": 5209.2, "trd": [[2.8, 387.1]], "batb": [[2, 2.74, 16.81]], "batl": [[0, 2.92, 10.21], [1, 2.98, 9.81], [2, 3, 22.3]]}, {"timestamp": 1578735759886, "ltp": 2.8, "tv": 5209.2, "trd": NaN, "batb": NaN, "batl": [[0, 2.92, 8], [1, 2.98, 13.96]]}, {"timestamp": 1578735760674, "ltp": 2.8, "tv": 5209.2, "trd": NaN, "batb": NaN, "batl": [[2, 3, 24.5]]}, {"timestamp": 1578735767987, "ltp": 2.8, "tv": 5209.2, "trd": NaN, "batb": [[0, 2.78, 16.06]], "batl": NaN}, {"timestamp": 1578735780893, "ltp": 2.8, "tv": 5209.2, "trd": NaN, "batb": NaN, "batl": [[1, 2.96, 6.2], [2, 2.98, 13.96]]}, {"timestamp": 1578735789927, "ltp": 2.8, "tv": 5209.2, "trd": NaN, "batb": NaN, "batl": [[2, 2.98, 9.81]]}, {"timestamp": 1578735792958, "ltp": 2.78, "tv": 5241.32, "trd": [[2.78, 330.23]], "batb": [[0, 2.76, 8.59], [1, 2.74, 16.81], [2, 2.72, 41.55]], "batl": [[0, 2.78, 1.94], [1, 2.92, 8], [2, 2.96, 6.2]]}, {"timestamp": 1578735794839, "ltp": 2.78, "tv": 5245.2, "trd": [[2.78, 334.11]], "batb": [[0, 2.78, 6.57], [1, 2.74, 11.06]], "batl": [[0, 2.92, 8], [1, 2.96, 6.2], [2, 2.98, 9.81]]}, {"timestamp": 1578735800954, "ltp": 2.78, "tv": 5245.2, "trd": NaN, "batb": [[1, 2.72, 41.55], [2, 2.7, 136.73]], "batl": [[0, 2.88, 22], [1, 2.92, 8], [2, 2.96, 6.2]]}, {"timestamp": 1578735825003, "ltp": 2.78, "tv": 5245.2, "trd": NaN, "batb": [[1, 2.74, 2.61], [2, 2.72, 41.55]], "batl": [[1, 2.92, 14.21]]}, {"timestamp": 1578735826002, "ltp": 2.88, "tv": 5271.2, "trd": [[2.88, 59.3]], "batb": NaN, "batl": [[0, 2.88, 9]]}, {"timestamp": 1578735828979, "ltp": 2.88, "tv": 5271.2, "trd": NaN, "batb": [[1, 2.74, 5.61]], "batl": NaN}, {"timestamp": 1578735851859, "ltp": 2.88, "tv": 5271.2, "trd": NaN, "batb": [[1, 2.76, 10.06], [2, 2.74, 5.61]], "batl": NaN}, {"timestamp": 1578735854946, "ltp": 2.88, "tv": 5271.2, "trd": NaN, "batb": [[0, 2.78, 10.94]], "batl": [[1, 2.92, 8]]}, {"timestamp": 1578735873001, "ltp": 2.88, "tv": 5289.2, "trd": [[2.88, 77.3]], "batb": NaN, "batl": [[0, 2.92, 8], [1, 2.96, 6.2], [2, 2.98, 9.81]]}, {"timestamp": 1578735873912, "ltp": 2.88, "tv": 5289.2, "trd": NaN, "batb": NaN, "batl": [[1, 2.96, 10.2]]}, {"timestamp": 1578735886813, "ltp": 2.88, "tv": 5289.2, "trd": NaN, "batb": [[0, 2.8, 3], [1, 2.78, 10.94], [2, 2.76, 10.06]], "batl": [[0, 2.9, 3], [1, 2.92, 8], [2, 2.96, 10.2]]}, {"timestamp": 1578735902945, "ltp": 2.8, "tv": 5309.2, "trd": [[2.8, 407.1]], "batb": [[0, 2.78, 11.35], [1, 2.74, 5.61], [2, 2.72, 41.55]], "batl": [[2, 2.96, 6.2]]}, {"timestamp": 1578735905936, "ltp": 2.8, "tv": 5309.2, "trd": NaN, "batb": [[0, 2.78, 21.35]], "batl": NaN}, {"timestamp": 1578735909948, "ltp": 2.8, "tv": 5309.2, "trd": NaN, "batb": [[1, 2.74, 19.85]], "batl": NaN}, {"timestamp": 1578735911927, "ltp": 2.8, "tv": 5309.2, "trd": NaN, "batb": [[1, 2.74, 16.85]], "batl": [[0, 2.9, 43]]}, {"timestamp": 1578735912914, "ltp": 2.8, "tv": 5309.2, "trd": NaN, "batb": [[0, 2.78, 10.41]], "batl": NaN}, {"timestamp": 1578735914640, "ltp": 2.8, "tv": 5309.2, "trd": NaN, "batb": [[1, 2.74, 6.96]], "batl": NaN}, {"timestamp": 1578735915948, "ltp": 2.8, "tv": 5309.2, "trd": NaN, "batb": [[1, 2.74, 11.31]], "batl": NaN}, {"timestamp": 1578735917930, "ltp": 2.8, "tv": 5309.2, "trd": NaN, "batb": [[0, 2.8, 3.81], [1, 2.78, 10], [2, 2.74, 11.31]], "batl": NaN}, {"timestamp": 1578735919929, "ltp": 2.8, "tv": 5309.2, "trd": NaN, "batb": [[2, 2.74, 8.7]], "batl": NaN}, {"timestamp": 1578735925965, "ltp": 2.8, "tv": 5316.82, "trd": [[2.8, 414.73]], "batb": [[0, 2.78, 10], [1, 2.74, 8.7], [2, 2.72, 41.55]], "batl": [[0, 2.9, 43.19]]}, {"timestamp": 1578735956776, "ltp": 2.8, "tv": 5317.2, "trd": [[2.8, 415.11]], "batb": [[0, 2.8, 10.69], [1, 2.78, 10], [2, 2.76, 14.1]], "batl": [[0, 2.9, 43]]}, {"timestamp": 1578735973911, "ltp": 2.8, "tv": 5317.2, "trd": NaN, "batb": [[0, 2.78, 10], [1, 2.76, 14.1], [2, 2.74, 8.7]], "batl": [[0, 2.88, 40], [1, 2.9, 43], [2, 2.92, 8]]}, {"timestamp": 1578735985922, "ltp": 2.8, "tv": 5317.2, "trd": NaN, "batb": NaN, "batl": [[1, 2.9, 40]]}, {"timestamp": 1578735987911, "ltp": 2.88, "tv": 5339.2, "trd": [[2.88, 99.3]], "batb": NaN, "batl": [[0, 2.88, 29]]}, {"timestamp": 1578735988801, "ltp": 2.88, "tv": 5339.2, "trd": NaN, "batb": [[0, 2.78, 17.66]], "batl": NaN}, {"timestamp": 1578735993919, "ltp": 2.88, "tv": 5339.2, "trd": NaN, "batb": [[1, 2.76, 22.82]], "batl": NaN}, {"timestamp": 1578735994913, "ltp": 2.88, "tv": 5339.2, "trd": NaN, "batb": [[2, 2.74, 11.7]], "batl": NaN}, {"timestamp": 1578735999921, "ltp": 2.88, "tv": 5339.2, "trd": NaN, "batb": [[0, 2.8, 25], [1, 2.78, 17.66], [2, 2.76, 22.82]], "batl": NaN}, {"timestamp": 1578736004943, "ltp": 2.88, "tv": 5339.2, "trd": NaN, "batb": [[1, 2.78, 25.99]], "batl": NaN}, {"timestamp": 1578736015949, "ltp": 2.88, "tv": 5339.2, "trd": NaN, "batb": [[0, 2.82, 10.64], [1, 2.8, 25], [2, 2.78, 25.99]], "batl": [[0, 2.86, 2.94], [1, 2.88, 29], [2, 2.9, 40]]}, {"timestamp": 1578736036889, "ltp": 2.88, "tv": 5339.2, "trd": NaN, "batb": [[1, 2.8, 28.69], [2, 2.78, 17.66]], "batl": NaN}, {"timestamp": 1578736050944, "ltp": 2.88, "tv": 5339.2, "trd": NaN, "batb": [[0, 2.82, 24.82]], "batl": NaN}, {"timestamp": 1578736052874, "ltp": 2.88, "tv": 5339.2, "trd": NaN, "batb": [[1, 2.8, 33.26]], "batl": NaN}, {"timestamp": 1578736072974, "ltp": 2.88, "tv": 5339.2, "trd": NaN, "batb": [[0, 2.84, 7.66], [1, 2.82, 24.82], [2, 2.8, 33.26]], "batl": NaN}, {"timestamp": 1578736075002, "ltp": 2.88, "tv": 5339.2, "trd": NaN, "batb": [[2, 2.8, 28.69]], "batl": NaN}, {"timestamp": 1578736197923, "ltp": 2.86, "tv": 5345.08, "trd": [[2.86, 128.26]], "batb": [[0, 2.86, 47.06], [1, 2.84, 7.66], [2, 2.82, 24.82]], "batl": [[0, 2.88, 29], [1, 2.9, 40], [2, 2.92, 8]]}, {"timestamp": 1578736199963, "ltp": 2.88, "tv": 5403.08, "trd": [[2.88, 157.3]], "batb": NaN, "batl": [[0, 2.9, 40], [1, 2.92, 8], [2, 2.98, 9.81]]}, {"timestamp": 1578736200964, "ltp": 2.88, "tv": 5403.08, "trd": NaN, "batb": [[1, 2.84, 21.6]], "batl": NaN}, {"timestamp": 1578736203928, "ltp": 2.9, "tv": 5483.08, "trd": [[2.9, 136.04]], "batb": [[0, 2.9, 10], [1, 2.88, 15.32], [2, 2.86, 47.06]], "batl": [[0, 2.92, 8], [1, 2.98, 9.81], [2, 3, 22.3]]}, {"timestamp": 1578736205967, "ltp": 2.9, "tv": 5483.08, "trd": NaN, "batb": [[1, 2.88, 18.8]], "batl": NaN}, {"timestamp": 1578736254951, "ltp": 2.92, "tv": 5496.62, "trd": [[2.92, 37.54]], "batb": NaN, "batl": [[0, 2.92, 1.23]]}, {"timestamp": 1578736255845, "ltp": 2.92, "tv": 5499.08, "trd": [[2.92, 40]], "batb": NaN, "batl": [[0, 2.98, 9.81], [1, 3, 22.3], [2, 3.05, 44.72]]}, {"timestamp": 1578736256849, "ltp": 2.92, "tv": 5499.08, "trd": NaN, "batb": NaN, "batl": [[1, 3, 25.13]]}, {"timestamp": 1578736258841, "ltp": 2.92, "tv": 5499.08, "trd": NaN, "batb": NaN, "batl": [[1, 3, 22.3]]}, {"timestamp": 1578736267986, "ltp": 2.92, "tv": 5499.08, "trd": NaN, "batb": [[0, 2.92, 2], [1, 2.9, 10], [2, 2.88, 18.8]], "batl": NaN}, {"timestamp": 1578736269980, "ltp": 2.92, "tv": 5499.08, "trd": NaN, "batb": [[2, 2.88, 15.32]], "batl": NaN}, {"timestamp": 1578736272470, "ltp": 2.92, "tv": 5499.08, "trd": NaN, "batb": [[2, 2.86, 47.06]], "batl": NaN}, {"timestamp": 1578736312925, "ltp": 2.92, "tv": 5499.08, "trd": NaN, "batb": NaN, "batl": [[1, 3, 32.3]]}, {"timestamp": 1578736321950, "ltp": 2.92, "tv": 5499.08, "trd": NaN, "batb": [[0, 2.92, 5.4]], "batl": NaN}, {"timestamp": 1578736336996, "ltp": 2.92, "tv": 5500.08, "trd": [[2.92, 41]], "batb": [[0, 2.92, 4.9]], "batl": NaN}, {"timestamp": 1578736376943, "ltp": 2.92, "tv": 5500.08, "trd": NaN, "batb": NaN, "batl": [[1, 3, 22.3]]}, {"timestamp": 1578736377935, "ltp": 2.92, "tv": 5500.08, "trd": NaN, "batb": NaN, "batl": [[2, 3.05, 51.99]]}, {"timestamp": 1578736406810, "ltp": 2.92, "tv": 5500.08, "trd": NaN, "batb": NaN, "batl": [[2, 3.05, 54.99]]}, {"timestamp": 1578736436800, "ltp": 2.98, "tv": 5519.71, "trd": [[2.98, 19.62]], "batb": NaN, "batl": [[0, 3, 22.3], [1, 3.05, 54.99], [2, 3.1, 21.28]]}, {"timestamp": 1578736443801, "ltp": 2.98, "tv": 5519.71, "trd": NaN, "batb": [[2, 2.86, 50.06]], "batl": NaN}, {"timestamp": 1578736466920, "ltp": 2.92, "tv": 5539.71, "trd": [[2.92, 61]], "batb": [[0, 2.92, 5.27], [2, 2.86, 52.23]], "batl": NaN}, {"timestamp": 1578736470870, "ltp": 2.92, "tv": 5539.71, "trd": NaN, "batb": NaN, "batl": [[0, 2.98, 12], [1, 3, 22.3], [2, 3.05, 54.99]]}, {"timestamp": 1578736472848, "ltp": 2.92, "tv": 5539.71, "trd": NaN, "batb": [[2, 2.86, 49.23]], "batl": NaN}, {"timestamp": 1578736476937, "ltp": 2.92, "tv": 5550.25, "trd": [[2.92, 71.54]], "batb": [[0, 2.9, 10], [1, 2.88, 2.13]], "batl": [[0, 2.98, 12.73]]}, {"timestamp": 1578736479864, "ltp": 2.92, "tv": 5550.25, "trd": NaN, "batb": [[1, 2.88, 5.61], [2, 2.86, 47.06]], "batl": NaN}, {"timestamp": 1578736518516, "ltp": 2.92, "tv": 5550.25, "trd": NaN, "batb": [[0, 2.9, 14.26]], "batl": NaN}, {"timestamp": 1578736568989, "ltp": 2.92, "tv": 5550.25, "trd": NaN, "batb": [[1, 2.88, 21.02]], "batl": NaN}, {"timestamp": 1578736654641, "ltp": 2.92, "tv": 5550.25, "trd": NaN, "batb": [[0, 2.9, 10]], "batl": NaN}, {"timestamp": 1578736677880, "ltp": 2.9, "tv": 5570.25, "trd": [[2.9, 156.04]], "batb": [[0, 2.88, 21.02], [1, 2.86, 47.06], [2, 2.82, 14.18]], "batl": NaN}, {"timestamp": 1578736679995, "ltp": 2.9, "tv": 5570.25, "trd": NaN, "batb": [[0, 2.88, 15.41], [1, 2.86, 54.07]], "batl": NaN}, {"timestamp": 1578736699907, "ltp": 2.9, "tv": 5570.25, "trd": NaN, "batb": NaN, "batl": [[0, 2.96, 4.73], [1, 2.98, 12], [2, 3, 22.3]]}, {"timestamp": 1578736714816, "ltp": 2.9, "tv": 5570.25, "trd": NaN, "batb": [[0, 2.9, 2.4], [1, 2.88, 15.41], [2, 2.86, 54.07]], "batl": NaN}, {"timestamp": 1578736716911, "ltp": 2.9, "tv": 5570.25, "trd": NaN, "batb": [[2, 2.86, 47.06]], "batl": NaN}, {"timestamp": 1578736737936, "ltp": 2.9, "tv": 5570.25, "trd": NaN, "batb": NaN, "batl": [[0, 2.94, 3.49], [1, 2.96, 4], [2, 2.98, 12]]}, {"timestamp": 1578736749965, "ltp": 2.9, "tv": 5575.05, "trd": [[2.9, 160.84]], "batb": [[0, 2.88, 15.41], [1, 2.86, 47.06], [2, 2.82, 18.11]], "batl": [[0, 2.9, 3.6], [1, 2.94, 3.49], [2, 2.96, 4]]}, {"timestamp": 1578736751890, "ltp": 2.9, "tv": 5575.05, "trd": NaN, "batb": [[1, 2.86, 52.28]], "batl": NaN}, {"timestamp": 1578736781813, "ltp": 2.9, "tv": 5575.05, "trd": NaN, "batb": NaN, "batl": [[1, 2.96, 7.47], [2, 2.98, 12]]}, {"timestamp": 1578736819958, "ltp": 2.9, "tv": 5575.05, "trd": NaN, "batb": NaN, "batl": [[1, 2.98, 12.73], [2, 3, 26.3]]}, {"timestamp": 1578736843912, "ltp": 2.9, "tv": 5575.05, "trd": NaN, "batb": NaN, "batl": [[0, 2.9, 6.39]]}, {"timestamp": 1578736852727, "ltp": 2.88, "tv": 5579.05, "trd": [[2.88, 161.3]], "batb": [[0, 2.88, 13.41]], "batl": NaN}, {"timestamp": 1578736881777, "ltp": 2.88, "tv": 5579.05, "trd": NaN, "batb": [[0, 2.86, 52.28], [1, 2.82, 14.18], [2, 2.8, 4]], "batl": NaN}, {"timestamp": 1578736882982, "ltp": 2.88, "tv": 5579.05, "trd": NaN, "batb": [[0, 2.86, 47.06]], "batl": NaN}, {"timestamp": 1578736883464, "ltp": 2.88, "tv": 5579.05, "trd": NaN, "batb": [[1, 2.84, 13.94], [2, 2.82, 27.37]], "batl": NaN}, {"timestamp": 1578736903977, "ltp": 2.9, "tv": 5583.05, "trd": [[2.9, 164.84]], "batb": NaN, "batl": [[0, 2.9, 4.39]]}, {"timestamp": 1578736910910, "ltp": 2.9, "tv": 5591.83, "trd": [[2.9, 173.61]], "batb": NaN, "batl": [[0, 2.98, 12.73], [1, 3, 28.94], [2, 3.05, 47.72]]}, {"timestamp": 1578736922917, "ltp": 2.9, "tv": 5591.83, "trd": NaN, "batb": NaN, "batl": [[1, 3, 26.3]]}, {"timestamp": 1578736946965, "ltp": 2.9, "tv": 5591.83, "trd": NaN, "batb": NaN, "batl": [[0, 2.98, 15.73]]}, {"timestamp": 1578736947925, "ltp": 2.9, "tv": 5591.83, "trd": NaN, "batb": NaN, "batl": [[2, 3.05, 55.72]]}, {"timestamp": 1578737027969, "ltp": 2.9, "tv": 5591.83, "trd": NaN, "batb": NaN, "batl": [[0, 2.96, 33.73], [1, 2.98, 15], [2, 3, 26.3]]}, {"timestamp": 1578737036906, "ltp": 2.86, "tv": 5606.83, "trd": [[2.86, 143.26]], "batb": [[0, 2.86, 39.56]], "batl": NaN}, {"timestamp": 1578737040988, "ltp": 2.86, "tv": 5606.83, "trd": NaN, "batb": NaN, "batl": [[1, 2.98, 12]]}, {"timestamp": 1578737041991, "ltp": 2.86, "tv": 5606.83, "trd": NaN, "batb": [[1, 2.84, 20.85]], "batl": NaN}, {"timestamp": 1578737069801, "ltp": 2.86, "tv": 5606.83, "trd": NaN, "batb": NaN, "batl": [[2, 3, 24.77]]}, {"timestamp": 1578737135921, "ltp": 2.86, "tv": 5606.83, "trd": NaN, "batb": NaN, "batl": [[0, 2.94, 14.9], [1, 2.96, 33], [2, 2.98, 12]]}, {"timestamp": 1578737180932, "ltp": 2.86, "tv": 5606.83, "trd": NaN, "batb": NaN, "batl": [[0, 2.9, 10], [1, 2.94, 14.9], [2, 2.96, 33]]}, {"timestamp": 1578737181731, "ltp": 2.86, "tv": 5606.83, "trd": NaN, "batb": [[0, 2.86, 58.01]], "batl": NaN}, {"timestamp": 1578737184918, "ltp": 2.84, "tv": 5744.51, "trd": [[2.84, 123.28], [2.86, 259.28]], "batb": [[0, 2.84, 10.03], [1, 2.82, 27.37], [2, 2.78, 10]], "batl": [[0, 2.86, 144.29], [1, 2.9, 10], [2, 2.94, 14.9]]}, {"timestamp": 1578737185948, "ltp": 2.84, "tv": 5744.51, "trd": NaN, "batb": [[0, 2.82, 20.6], [1, 2.78, 10], [2, 2.76, 15.1]], "batl": [[1, 2.9, 37.27]]}, {"timestamp": 1578737187711, "ltp": 2.84, "tv": 5744.51, "trd": NaN, "batb": [[0, 2.82, 14.18], [1, 2.8, 3.65], [2, 2.78, 16.72]], "batl": [[1, 2.9, 39.93]]}, {"timestamp": 1578737198955, "ltp": 2.84, "tv": 5744.51, "trd": NaN, "batb": NaN, "batl": [[2, 2.94, 26.7]]}, {"timestamp": 1578737208959, "ltp": 2.82, "tv": 5772.87, "trd": [[2.82, 217.46]], "batb": [[0, 2.8, 3.65], [1, 2.78, 16.72], [2, 2.76, 15.1]], "batl": NaN}, {"timestamp": 1578737210966, "ltp": 2.82, "tv": 5772.87, "trd": NaN, "batb": [[0, 2.78, 10], [1, 2.76, 15.1], [2, 2.72, 30]], "batl": NaN}, {"timestamp": 1578737211970, "ltp": 2.82, "tv": 5772.87, "trd": NaN, "batb": [[1, 2.76, 21.91]], "batl": NaN}, {"timestamp": 1578737214950, "ltp": 2.82, "tv": 5772.87, "trd": NaN, "batb": NaN, "batl": [[0, 2.84, 18.27], [1, 2.86, 144.29], [2, 2.9, 39.93]]}, {"timestamp": 1578737216979, "ltp": 2.82, "tv": 5772.87, "trd": NaN, "batb": NaN, "batl": [[0, 2.84, 29.33], [2, 2.9, 22.84]]}, {"timestamp": 1578737221914, "ltp": 2.82, "tv": 5772.87, "trd": NaN, "batb": NaN, "batl": [[0, 2.84, 39.39]]}, {"timestamp": 1578737232898, "ltp": 2.78, "tv": 5782.87, "trd": [[2.78, 344.11]], "batb": [[0, 2.78, 5]], "batl": NaN}, {"timestamp": 1578737247982, "ltp": 2.78, "tv": 5782.87, "trd": NaN, "batb": [[1, 2.76, 18.12]], "batl": NaN}, {"timestamp": 1578737300950, "ltp": 2.78, "tv": 5787.97, "trd": [[2.78, 349.21]], "batb": [[0, 2.78, 2.45]], "batl": NaN}, {"timestamp": 1578737433581, "ltp": 2.78, "tv": 5791.97, "trd": [[2.78, 353.21]], "batb": [[0, 2.76, 18.57], [1, 2.72, 30], [2, 2.68, 10]], "batl": NaN}, {"timestamp": 1578737434995, "ltp": 2.84, "tv": 5795.87, "trd": [[2.84, 127.18]], "batb": [[1, 2.74, 9.84], [2, 2.72, 30]], "batl": [[0, 2.84, 37.44]]}, {"timestamp": 1578737436963, "ltp": 2.78, "tv": 5796.77, "trd": [[2.78, 354.11]], "batb": [[0, 2.76, 15.1]], "batl": [[0, 2.78, 19.55], [1, 2.84, 37.44], [2, 2.86, 144.29]]}, {"timestamp": 1578737437963, "ltp": 2.78, "tv": 5835.87, "trd": [[2.78, 393.21]], "batb": NaN, "batl": [[0, 2.84, 37.44], [1, 2.86, 144.29], [2, 2.9, 10]]}, {"timestamp": 1578737463914, "ltp": 2.78, "tv": 5835.87, "trd": NaN, "batb": NaN, "batl": [[0, 2.8, 6.95], [1, 2.84, 37.44], [2, 2.86, 144.29]]}, {"timestamp": 1578737470986, "ltp": 2.8, "tv": 5849.49, "trd": [[2.8, 428.73]], "batb": NaN, "batl": [[0, 2.84, 37.58], [1, 2.86, 144.29], [2, 2.9, 10]]}, {"timestamp": 1578737483838, "ltp": 2.8, "tv": 5849.49, "trd": NaN, "batb": NaN, "batl": [[0, 2.82, 7.01], [1, 2.84, 37.44], [2, 2.86, 144.29]]}, {"timestamp": 1578737502947, "ltp": 2.8, "tv": 5849.49, "trd": NaN, "batb": [[0, 2.74, 9.84], [1, 2.72, 30], [2, 2.68, 10]], "batl": NaN}, {"timestamp": 1578737505874, "ltp": 2.8, "tv": 5849.49, "trd": NaN, "batb": [[0, 2.72, 33.35], [1, 2.68, 10], [2, 2.66, 113.51]], "batl": NaN}, {"timestamp": 1578737506983, "ltp": 2.8, "tv": 5849.49, "trd": NaN, "batb": [[0, 2.72, 30], [1, 2.7, 11.06], [2, 2.68, 17.12]], "batl": NaN}, {"timestamp": 1578737518897, "ltp": 2.8, "tv": 5849.49, "trd": NaN, "batb": [[0, 2.74, 96.27], [1, 2.72, 30], [2, 2.7, 11.06]], "batl": NaN}, {"timestamp": 1578737519962, "ltp": 2.8, "tv": 5849.49, "trd": NaN, "batb": [[0, 2.76, 10.98], [1, 2.74, 96.27], [2, 2.72, 30]], "batl": NaN}, {"timestamp": 1578737531980, "ltp": 2.8, "tv": 5849.49, "trd": NaN, "batb": [[1, 2.74, 100.09]], "batl": NaN}, {"timestamp": 1578737536992, "ltp": 2.8, "tv": 5849.49, "trd": NaN, "batb": [[1, 2.74, 3.82]], "batl": NaN}, {"timestamp": 1578737551809, "ltp": 2.8, "tv": 5849.49, "trd": NaN, "batb": [[0, 2.76, 25.47]], "batl": NaN}, {"timestamp": 1578737554920, "ltp": 2.8, "tv": 5849.49, "trd": NaN, "batb": [[1, 2.74, 8.5]], "batl": NaN}, {"timestamp": 1578737557911, "ltp": 2.82, "tv": 5861.87, "trd": [[2.8, 429.01], [2.82, 229.56]], "batb": NaN, "batl": [[0, 2.84, 38.26], [1, 2.86, 144.29], [2, 2.9, 10.11]]}, {"timestamp": 1578737558906, "ltp": 2.82, "tv": 5861.87, "trd": NaN, "batb": [[1, 2.74, 13.17]], "batl": NaN}, {"timestamp": 1578737571918, "ltp": 2.82, "tv": 5861.87, "trd": NaN, "batb": [[0, 2.78, 94.88], [1, 2.76, 25.47], [2, 2.74, 13.17]], "batl": NaN}, {"timestamp": 1578737573952, "ltp": 2.82, "tv": 5861.87, "trd": NaN, "batb": [[1, 2.76, 39.46]], "batl": NaN}, {"timestamp": 1578737634921, "ltp": 2.82, "tv": 5861.87, "trd": NaN, "batb": NaN, "batl": [[0, 2.84, 37.44]]}, {"timestamp": 1578737640898, "ltp": 2.82, "tv": 5861.87, "trd": NaN, "batb": NaN, "batl": [[0, 2.82, 2], [1, 2.84, 37.44], [2, 2.86, 144.29]]}, {"timestamp": 1578737660977, "ltp": 2.82, "tv": 5861.87, "trd": NaN, "batb": [[0, 2.76, 39.46], [1, 2.74, 27.9], [2, 2.72, 30]], "batl": NaN}, {"timestamp": 1578737662962, "ltp": 2.82, "tv": 5861.87, "trd": NaN, "batb": [[0, 2.76, 25.47], [1, 2.74, 24.08]], "batl": NaN}, {"timestamp": 1578737663969, "ltp": 2.82, "tv": 5861.87, "trd": NaN, "batb": [[1, 2.74, 14.73]], "batl": NaN}, {"timestamp": 1578737710558, "ltp": 2.76, "tv": 5901.87, "trd": [[2.76, 529.1]], "batb": [[0, 2.76, 5.47]], "batl": [[0, 2.82, 12.73]]}, {"timestamp": 1578737712461, "ltp": 2.76, "tv": 5901.87, "trd": NaN, "batb": [[1, 2.72, 30], [2, 2.68, 10]], "batl": NaN}, {"timestamp": 1578737741729, "ltp": 2.76, "tv": 5901.87, "trd": NaN, "batb": [[1, 2.72, 32.23]], "batl": [[1, 2.84, 44.25]]}, {"timestamp": 1578737783273, "ltp": 2.76, "tv": 5901.87, "trd": NaN, "batb": [[1, 2.74, 10.73], [2, 2.72, 32.23]], "batl": NaN}, {"timestamp": 1578737843989, "ltp": 2.76, "tv": 5901.87, "trd": NaN, "batb": [[0, 2.76, 15.15]], "batl": NaN}, {"timestamp": 1578737844993, "ltp": 2.76, "tv": 5901.87, "trd": NaN, "batb": [[1, 2.74, 15.9]], "batl": NaN}, {"timestamp": 1578737881838, "ltp": 2.76, "tv": 5921.87, "trd": [[2.76, 549.1]], "batb": [[0, 2.76, 5.15]], "batl": NaN}, {"timestamp": 1578737893766, "ltp": 2.76, "tv": 5921.87, "trd": NaN, "batb": [[1, 2.74, 10.73]], "batl": NaN}, {"timestamp": 1578737921000, "ltp": 2.76, "tv": 5921.87, "trd": NaN, "batb": [[0, 2.78, 6.27], [1, 2.76, 5.15], [2, 2.74, 10.73]], "batl": NaN}, {"timestamp": 1578737944936, "ltp": 2.78, "tv": 5925.87, "trd": [[2.78, 397.21]], "batb": [[0, 2.78, 4.27]], "batl": NaN}, {"timestamp": 1578737983001, "ltp": 2.78, "tv": 5925.87, "trd": NaN, "batb": [[2, 2.72, 30]], "batl": NaN}, {"timestamp": 1578738033949, "ltp": 2.82, "tv": 5949.71, "trd": [[2.82, 253.4]], "batb": NaN, "batl": [[0, 2.84, 45.06], [1, 2.86, 144.29], [2, 2.9, 10.11]]}, {"timestamp": 1578738035944, "ltp": 2.82, "tv": 5949.71, "trd": NaN, "batb": NaN, "batl": [[2, 2.88, 10.3]]}, {"timestamp": 1578738076988, "ltp": 2.82, "tv": 5951.33, "trd": [[2.82, 255.02]], "batb": NaN, "batl": [[0, 2.84, 44.25]]}, {"timestamp": 1578738093970, "ltp": 2.82, "tv": 5951.33, "trd": NaN, "batb": NaN, "batl": [[0, 2.82, 2], [1, 2.84, 44.25], [2, 2.86, 144.29]]}, {"timestamp": 1578738101956, "ltp": 2.82, "tv": 5951.33, "trd": NaN, "batb": NaN, "batl": [[0, 2.82, 16]]}, {"timestamp": 1578738130991, "ltp": 2.82, "tv": 5963.33, "trd": [[2.82, 267.02]], "batb": NaN, "batl": [[0, 2.82, 10]]}, {"timestamp": 1578738131995, "ltp": 2.82, "tv": 5963.33, "trd": NaN, "batb": [[0, 2.8, 4.03], [1, 2.78, 4.27], [2, 2.76, 5.15]], "batl": NaN}, {"timestamp": 1578738134843, "ltp": 2.82, "tv": 5963.33, "trd": NaN, "batb": [[0, 2.8, 98.24]], "batl": NaN}, {"timestamp": 1578738136966, "ltp": 2.82, "tv": 5963.33, "trd": NaN, "batb": [[1, 2.78, 18.25]], "batl": NaN}, {"timestamp": 1578738152979, "ltp": 2.82, "tv": 5963.33, "trd": NaN, "batb": [[0, 2.8, 4.03]], "batl": NaN}, {"timestamp": 1578738166982, "ltp": 2.82, "tv": 5963.33, "trd": NaN, "batb": [[1, 2.78, 4.27]], "batl": NaN}, {"timestamp": 1578738169994, "ltp": 2.82, "tv": 5963.33, "trd": NaN, "batb": [[0, 2.8, 98.24]], "batl": NaN}, {"timestamp": 1578738171884, "ltp": 2.82, "tv": 5963.33, "trd": NaN, "batb": [[1, 2.78, 18.25]], "batl": NaN}, {"timestamp": 1578738187698, "ltp": 2.82, "tv": 5963.33, "trd": NaN, "batb": [[0, 2.8, 4.03]], "batl": NaN}, {"timestamp": 1578738204819, "ltp": 2.82, "tv": 5963.33, "trd": NaN, "batb": [[0, 2.8, 98.24]], "batl": NaN}, {"timestamp": 1578738205606, "ltp": 2.82, "tv": 5963.33, "trd": NaN, "batb": [[1, 2.78, 4.27]], "batl": NaN}, {"timestamp": 1578738206816, "ltp": 2.82, "tv": 5963.33, "trd": NaN, "batb": [[1, 2.78, 18.25]], "batl": NaN}, {"timestamp": 1578738222983, "ltp": 2.82, "tv": 5963.33, "trd": NaN, "batb": [[0, 2.8, 4.03]], "batl": NaN}, {"timestamp": 1578738224854, "ltp": 2.82, "tv": 5963.33, "trd": NaN, "batb": [[1, 2.78, 4.27]], "batl": NaN}, {"timestamp": 1578738232993, "ltp": 2.8, "tv": 5971.39, "trd": [[2.8, 437.07]], "batb": [[0, 2.78, 4.27], [1, 2.76, 5.15], [2, 2.72, 30]], "batl": [[0, 2.82, 10.97]]}, {"timestamp": 1578738271930, "ltp": 2.8, "tv": 5971.39, "trd": NaN, "batb": [[0, 2.78, 18.66]], "batl": NaN}, {"timestamp": 1578738274942, "ltp": 2.8, "tv": 5971.39, "trd": NaN, "batb": [[1, 2.76, 11.44]], "batl": NaN}, {"timestamp": 1578738282959, "ltp": 2.78, "tv": 6007.39, "trd": [[2.78, 433.22]], "batb": [[0, 2.76, 12.1], [1, 2.72, 44.14], [2, 2.68, 10]], "batl": NaN}, {"timestamp": 1578738296955, "ltp": 2.78, "tv": 6007.39, "trd": NaN, "batb": [[0, 2.76, 5.81], [1, 2.74, 21.14], [2, 2.72, 30]], "batl": NaN}, {"timestamp": 1578738310995, "ltp": 2.78, "tv": 6007.39, "trd": NaN, "batb": [[1, 2.74, 16.96]], "batl": NaN}, {"timestamp": 1578738382966, "ltp": 2.82, "tv": 6011.39, "trd": [[2.8, 439.01], [2.82, 269.08]], "batb": NaN, "batl": [[0, 2.82, 8.97]]}, {"timestamp": 1578738411735, "ltp": 2.74, "tv": 6051.39, "trd": [[2.74, 412.08], [2.76, 559.39], [2.78, 434.54]], "batb": [[0, 2.74, 2.77], [1, 2.72, 30], [2, 2.68, 10]], "batl": NaN}, {"timestamp": 1578738412529, "ltp": 2.74, "tv": 6051.39, "trd": NaN, "batb": [[1, 2.72, 32.8]], "batl": NaN}, {"timestamp": 1578738422935, "ltp": 2.74, "tv": 6051.39, "trd": NaN, "batb": [[1, 2.72, 30]], "batl": NaN}, {"timestamp": 1578738429942, "ltp": 2.74, "tv": 6051.39, "trd": NaN, "batb": [[2, 2.68, 24.93]], "batl": NaN}, {"timestamp": 1578738432862, "ltp": 2.74, "tv": 6051.39, "trd": NaN, "batb": [[0, 2.74, 99.04]], "batl": NaN}, {"timestamp": 1578738433970, "ltp": 2.74, "tv": 6051.39, "trd": NaN, "batb": [[1, 2.72, 43.4]], "batl": NaN}, {"timestamp": 1578738481768, "ltp": 2.82, "tv": 6069.33, "trd": [[2.82, 287.02]], "batb": [[0, 2.8, 10.07], [1, 2.74, 99.04], [2, 2.72, 43.4]], "batl": [[0, 2.84, 44.25], [1, 2.86, 144.29], [2, 2.9, 10.11]]}, {"timestamp": 1578738484843, "ltp": 2.82, "tv": 6069.33, "trd": NaN, "batb": [[1, 2.76, 3.84], [2, 2.74, 99.04]], "batl": NaN}, {"timestamp": 1578738486967, "ltp": 2.82, "tv": 6069.33, "trd": NaN, "batb": [[2, 2.74, 2.77]], "batl": NaN}, {"timestamp": 1578738505798, "ltp": 2.82, "tv": 6075.61, "trd": [[2.82, 293.3]], "batb": NaN, "batl": [[0, 2.82, 21.13], [1, 2.84, 44.25], [2, 2.86, 144.29]]}, {"timestamp": 1578738507716, "ltp": 2.82, "tv": 6075.61, "trd": NaN, "batb": [[2, 2.72, 30]], "batl": NaN}, {"timestamp": 1578738516903, "ltp": 2.82, "tv": 6075.61, "trd": NaN, "batb": [[2, 2.74, 4.23]], "batl": NaN}, {"timestamp": 1578738517911, "ltp": 2.82, "tv": 6101.89, "trd": [[2.82, 319.58]], "batb": NaN, "batl": [[0, 2.82, 7.99]]}, {"timestamp": 1578738518924, "ltp": 2.82, "tv": 6101.89, "trd": NaN, "batb": [[2, 2.72, 30]], "batl": NaN}, {"timestamp": 1578738593974, "ltp": 2.82, "tv": 6117.87, "trd": [[2.82, 335.56]], "batb": [[0, 2.82, 7.33], [1, 2.8, 10.07], [2, 2.76, 3.84]], "batl": [[0, 2.84, 44.25], [1, 2.86, 144.29], [2, 2.9, 10.11]]}, {"timestamp": 1578738604984, "ltp": 2.82, "tv": 6121.87, "trd": [[2.82, 339.56]], "batb": [[0, 2.82, 5.33]], "batl": NaN}, {"timestamp": 1578738611000, "ltp": 2.82, "tv": 6121.87, "trd": NaN, "batb": [[0, 2.82, 98.87]], "batl": NaN}, {"timestamp": 1578738612910, "ltp": 2.82, "tv": 6121.87, "trd": NaN, "batb": NaN, "batl": [[0, 2.84, 33.19]]}, {"timestamp": 1578738616915, "ltp": 2.82, "tv": 6121.87, "trd": NaN, "batb": [[1, 2.8, 24.04]], "batl": NaN}, {"timestamp": 1578738628931, "ltp": 2.82, "tv": 6121.87, "trd": NaN, "batb": [[0, 2.82, 5.33]], "batl": NaN}, {"timestamp": 1578738630724, "ltp": 2.82, "tv": 6121.87, "trd": NaN, "batb": [[1, 2.8, 10.07]], "batl": NaN}, {"timestamp": 1578738631947, "ltp": 2.82, "tv": 6121.87, "trd": NaN, "batb": NaN, "batl": [[2, 2.9, 12.11]]}, {"timestamp": 1578738635943, "ltp": 2.82, "tv": 6121.87, "trd": NaN, "batb": NaN, "batl": [[2, 2.88, 2]]}, {"timestamp": 1578738639953, "ltp": 2.82, "tv": 6121.87, "trd": NaN, "batb": NaN, "batl": [[1, 2.86, 146.29]]}, {"timestamp": 1578738643003, "ltp": 2.82, "tv": 6121.87, "trd": NaN, "batb": NaN, "batl": [[0, 2.84, 35.19]]}, {"timestamp": 1578738645991, "ltp": 2.82, "tv": 6121.87, "trd": NaN, "batb": [[0, 2.82, 98.87]], "batl": NaN}, {"timestamp": 1578738647969, "ltp": 2.82, "tv": 6121.87, "trd": NaN, "batb": [[1, 2.8, 24.04]], "batl": NaN}, {"timestamp": 1578738653774, "ltp": 2.82, "tv": 6121.87, "trd": NaN, "batb": [[0, 2.82, 93.54]], "batl": NaN}, {"timestamp": 1578738663990, "ltp": 2.82, "tv": 6121.87, "trd": NaN, "batb": [[0, 2.8, 24.04], [1, 2.76, 3.84], [2, 2.72, 30]], "batl": NaN}, {"timestamp": 1578738665003, "ltp": 2.82, "tv": 6121.87, "trd": NaN, "batb": [[1, 2.76, 33.08]], "batl": NaN}, {"timestamp": 1578738666930, "ltp": 2.82, "tv": 6121.87, "trd": NaN, "batb": [[0, 2.8, 10.07], [1, 2.76, 14.62]], "batl": NaN}, {"timestamp": 1578738667896, "ltp": 2.82, "tv": 6121.87, "trd": NaN, "batb": [[1, 2.76, 3.84]], "batl": NaN}, {"timestamp": 1578738686968, "ltp": 2.84, "tv": 6140.63, "trd": [[2.84, 145.94]], "batb": NaN, "batl": [[0, 2.84, 25.81]]}, {"timestamp": 1578738688865, "ltp": 2.84, "tv": 6140.63, "trd": NaN, "batb": [[2, 2.74, 3]], "batl": NaN}, {"timestamp": 1578738739902, "ltp": 2.8, "tv": 6151.73, "trd": [[2.8, 450.11]], "batb": [[0, 2.8, 4.52]], "batl": NaN}, {"timestamp": 1578738741929, "ltp": 2.8, "tv": 6151.73, "trd": NaN, "batb": [[2, 2.72, 30]], "batl": NaN}, {"timestamp": 1578738746943, "ltp": 2.8, "tv": 6151.73, "trd": NaN, "batb": [[1, 2.72, 30], [2, 2.68, 24.93]], "batl": NaN}, {"timestamp": 1578738751747, "ltp": 2.8, "tv": 6151.73, "trd": NaN, "batb": [[1, 2.72, 33.71]], "batl": NaN}, {"timestamp": 1578738752962, "ltp": 2.8, "tv": 6151.73, "trd": NaN, "batb": NaN, "batl": [[2, 2.88, 11.6]]}, {"timestamp": 1578738771865, "ltp": 2.8, "tv": 6160.77, "trd": [[2.8, 459.15]], "batb": [[0, 2.74, 11.03]], "batl": [[0, 2.84, 26.29]]}, {"timestamp": 1578738776954, "ltp": 2.8, "tv": 6160.77, "trd": NaN, "batb": [[0, 2.76, 20.61], [1, 2.74, 12.89], [2, 2.72, 33.71]], "batl": NaN}, {"timestamp": 1578738777963, "ltp": 2.8, "tv": 6160.77, "trd": NaN, "batb": NaN, "batl": [[0, 2.84, 46.29]]}, {"timestamp": 1578738785961, "ltp": 2.8, "tv": 6160.77, "trd": NaN, "batb": [[0, 2.78, 94.88], [1, 2.76, 20.61], [2, 2.74, 19.82]], "batl": NaN}, {"timestamp": 1578738797988, "ltp": 2.8, "tv": 6160.77, "trd": NaN, "batb": [[1, 2.76, 34.6]], "batl": NaN}, {"timestamp": 1578738808969, "ltp": 2.78, "tv": 6175.77, "trd": [[2.78, 449.53]], "batb": [[0, 2.78, 87.39]], "batl": NaN}, {"timestamp": 1578738817797, "ltp": 2.78, "tv": 6175.77, "trd": NaN, "batb": NaN, "batl": [[0, 2.84, 49.29]]}, {"timestamp": 1578738818909, "ltp": 2.8, "tv": 6176.73, "trd": [[2.8, 460.11]], "batb": [[0, 2.8, 1.52], [1, 2.78, 87.39], [2, 2.76, 34.6]], "batl": [[0, 2.84, 48.81]]}, {"timestamp": 1578738822918, "ltp": 2.8, "tv": 6176.73, "trd": NaN, "batb": NaN, "batl": [[2, 2.88, 2]]}, {"timestamp": 1578738922962, "ltp": 2.8, "tv": 6176.73, "trd": NaN, "batb": [[0, 2.8, 7.01]], "batl": NaN}, {"timestamp": 1578738924970, "ltp": 2.8, "tv": 6176.73, "trd": NaN, "batb": [[0, 2.82, 5.49], [1, 2.8, 7.01], [2, 2.78, 87.39]], "batl": NaN}, {"timestamp": 1578738925972, "ltp": 2.8, "tv": 6176.73, "trd": NaN, "batb": [[0, 2.8, 7.01], [1, 2.78, 87.39], [2, 2.76, 20.61]], "batl": NaN}, {"timestamp": 1578738926976, "ltp": 2.8, "tv": 6176.73, "trd": NaN, "batb": [[0, 2.8, 1.61]], "batl": NaN}, {"timestamp": 1578738927868, "ltp": 2.8, "tv": 6176.73, "trd": NaN, "batb": [[1, 2.76, 23.37], [2, 2.74, 1.86]], "batl": NaN}, {"timestamp": 1578738929502, "ltp": 2.8, "tv": 6176.73, "trd": NaN, "batb": [[1, 2.76, 20.61], [2, 2.74, 10.2]], "batl": NaN}, {"timestamp": 1578738945906, "ltp": 2.8, "tv": 6176.73, "trd": NaN, "batb": [[1, 2.78, 87.39], [2, 2.76, 20.61]], "batl": NaN}, {"timestamp": 1578738958738, "ltp": 2.84, "tv": 6216.72, "trd": [[2.84, 185.94]], "batb": NaN, "batl": [[0, 2.84, 28.81]]}, {"timestamp": 1578738959947, "ltp": 2.84, "tv": 6216.72, "trd": NaN, "batb": [[2, 2.76, 30.62]], "batl": NaN}, {"timestamp": 1578738962987, "ltp": 2.84, "tv": 6236.73, "trd": [[2.84, 205.94]], "batb": NaN, "batl": [[0, 2.84, 18.81]]}, {"timestamp": 1578738963973, "ltp": 2.8, "tv": 6248.38, "trd": [[2.8, 463.15], [2.82, 348.18]], "batb": [[0, 2.78, 87.39], [1, 2.76, 30.62], [2, 2.74, 13.2]], "batl": [[0, 2.84, 19.29]]}, {"timestamp": 1578738964883, "ltp": 2.8, "tv": 6249.34, "trd": [[2.8, 464.11]], "batb": [[0, 2.8, 10.37], [1, 2.78, 87.39], [2, 2.76, 20.61]], "batl": [[0, 2.84, 18.81]]}, {"timestamp": 1578738965964, "ltp": 2.8, "tv": 6249.34, "trd": NaN, "batb": [[1, 2.78, 91]], "batl": NaN}, {"timestamp": 1578738981981, "ltp": 2.8, "tv": 6249.34, "trd": NaN, "batb": [[1, 2.78, 3.61]], "batl": NaN}, {"timestamp": 1578739000699, "ltp": 2.86, "tv": 6349.34, "trd": [[2.84, 243.56], [2.86, 321.66]], "batb": NaN, "batl": [[0, 2.86, 115.1], [1, 2.88, 2], [2, 2.9, 2.11]]}, {"timestamp": 1578739001905, "ltp": 2.8, "tv": 6397.1, "trd": [[2.8, 480.03], [2.82, 380.02]], "batb": [[0, 2.8, 2.41]], "batl": [[2, 2.9, 9.54]]}, {"timestamp": 1578739005920, "ltp": 2.8, "tv": 6397.1, "trd": NaN, "batb": [[1, 2.76, 20.61], [2, 2.74, 1.86]], "batl": [[2, 2.9, 32.04]]}, {"timestamp": 1578739015950, "ltp": 2.8, "tv": 6397.1, "trd": NaN, "batb": NaN, "batl": [[0, 2.84, 9.24], [1, 2.86, 115.1], [2, 2.88, 2]]}, {"timestamp": 1578739018843, "ltp": 2.88, "tv": 6788.79, "trd": [[2.84, 262.05], [2.86, 551.86], [2.88, 304.3]], "batb": [[0, 2.88, 4.16], [1, 2.8, 2.41], [2, 2.78, 87.39]], "batl": [[0, 2.9, 2.11], [1, 2.92, 2.73], [2, 2.94, 2]]}, {"timestamp": 1578739019922, "ltp": 2.88, "tv": 6788.79, "trd": NaN, "batb": [[0, 2.88, 204.16], [1, 2.8, 21.99]], "batl": NaN}, {"timestamp": 1578739020947, "ltp": 2.88, "tv": 6788.79, "trd": NaN, "batb": [[1, 2.82, 43.73], [2, 2.8, 33.65]], "batl": NaN}, {"timestamp": 1578739021950, "ltp": 2.88, "tv": 6788.79, "trd": NaN, "batb": [[2, 2.8, 24.27]], "batl": NaN}, {"timestamp": 1578739026953, "ltp": 2.9, "tv": 6793.01, "trd": [[2.9, 177.83]], "batb": [[0, 2.9, 219.89], [1, 2.88, 204.16], [2, 2.82, 43.73]], "batl": [[0, 2.92, 2.73], [1, 2.94, 2], [2, 2.96, 35]]}, {"timestamp": 1578739028971, "ltp": 2.9, "tv": 6793.01, "trd": NaN, "batb": [[1, 2.88, 218.08]], "batl": NaN}, {"timestamp": 1578739033856, "ltp": 2.9, "tv": 6809.68, "trd": [[2.9, 194.51]], "batb": [[0, 2.9, 211.55]], "batl": NaN}, {"timestamp": 1578739049790, "ltp": 2.92, "tv": 6815.14, "trd": [[2.92, 77.01]], "batb": [[0, 2.92, 16.04], [1, 2.9, 211.55], [2, 2.88, 218.08]], "batl": [[0, 2.94, 2], [1, 2.96, 35], [2, 2.98, 2]]}, {"timestamp": 1578739051798, "ltp": 2.92, "tv": 6815.14, "trd": NaN, "batb": [[2, 2.88, 204.16]], "batl": NaN}, {"timestamp": 1578739052907, "ltp": 2.9, "tv": 6915.14, "trd": [[2.9, 262.43], [2.92, 109.08]], "batb": [[0, 2.9, 177.59], [1, 2.88, 204.16], [2, 2.82, 21.87]], "batl": NaN}, {"timestamp": 1578739059915, "ltp": 2.9, "tv": 6954.58, "trd": [[2.9, 301.87]], "batb": [[0, 2.9, 163.28]], "batl": NaN}, {"timestamp": 1578739070991, "ltp": 2.9, "tv": 6954.58, "trd": NaN, "batb": NaN, "batl": [[2, 2.98, 4]]}, {"timestamp": 1578739075914, "ltp": 2.9, "tv": 6954.58, "trd": NaN, "batb": NaN, "batl": [[1, 2.96, 37]]}, {"timestamp": 1578739081912, "ltp": 2.9, "tv": 6954.58, "trd": NaN, "batb": [[0, 2.9, 157.87], [1, 2.88, 218.08]], "batl": [[0, 2.94, 4]]}, {"timestamp": 1578739086815, "ltp": 2.94, "tv": 6962.58, "trd": [[2.94, 8]], "batb": [[0, 2.94, 96], [1, 2.9, 157.87], [2, 2.88, 218.08]], "batl": [[0, 2.96, 37], [1, 2.98, 4], [2, 3, 17]]}, {"timestamp": 1578739087827, "ltp": 2.94, "tv": 6962.58, "trd": NaN, "batb": [[0, 2.94, 198], [1, 2.92, 6], [2, 2.9, 157.87]], "batl": NaN}, {"timestamp": 1578739088907, "ltp": 2.94, "tv": 6962.58, "trd": NaN, "batb": [[1, 2.92, 19.89]], "batl": NaN}, {"timestamp": 1578739089634, "ltp": 2.96, "tv": 7036.58, "trd": [[2.96, 74]], "batb": [[0, 2.96, 13], [1, 2.94, 102], [2, 2.92, 19.89]], "batl": [[0, 2.98, 4], [1, 3, 17], [2, 3.05, 42.56]]}, {"timestamp": 1578739090626, "ltp": 2.96, "tv": 7048.58, "trd": [[2.96, 86]], "batb": [[0, 2.96, 7]], "batl": NaN}, {"timestamp": 1578739091909, "ltp": 2.96, "tv": 7048.58, "trd": NaN, "batb": [[2, 2.92, 6]], "batl": NaN}, {"timestamp": 1578739092950, "ltp": 2.96, "tv": 7048.58, "trd": NaN, "batb": [[0, 2.96, 109], [1, 2.92, 6], [2, 2.9, 207.87]], "batl": [[0, 2.98, 12.08]]}, {"timestamp": 1578739094642, "ltp": 2.96, "tv": 7048.58, "trd": NaN, "batb": [[1, 2.92, 34.32]], "batl": NaN}, {"timestamp": 1578739095945, "ltp": 2.96, "tv": 7048.58, "trd": NaN, "batb": [[2, 2.9, 307.87]], "batl": NaN}, {"timestamp": 1578739096908, "ltp": 2.96, "tv": 7048.58, "trd": NaN, "batb": [[0, 2.96, 211]], "batl": NaN}, {"timestamp": 1578739097920, "ltp": 2.96, "tv": 7048.58, "trd": NaN, "batb": [[1, 2.94, 13.88], [2, 2.92, 34.32]], "batl": NaN}, {"timestamp": 1578739099937, "ltp": 2.96, "tv": 7056.58, "trd": [[2.96, 94]], "batb": [[0, 2.96, 207]], "batl": NaN}, {"timestamp": 1578739100936, "ltp": 2.96, "tv": 7435.86, "trd": [[2.96, 473.28]], "batb": [[0, 2.96, 17.36]], "batl": NaN}, {"timestamp": 1578739101653, "ltp": 2.96, "tv": 7441.86, "trd": [[2.96, 479.28]], "batb": [[0, 2.96, 14.36]], "batl": NaN}, {"timestamp": 1578739108964, "ltp": 2.96, "tv": 7470.58, "trd": [[2.96, 508]], "batb": [[0, 2.94, 13.88], [1, 2.92, 34.32], [2, 2.9, 307.87]], "batl": [[0, 2.96, 385.64], [1, 2.98, 12.08], [2, 3, 17]]}, {"timestamp": 1578739109962, "ltp": 2.96, "tv": 7470.58, "trd": NaN, "batb": [[0, 2.94, 4.59], [1, 2.92, 6]], "batl": NaN}, {"timestamp": 1578739110960, "ltp": 2.96, "tv": 7470.58, "trd": NaN, "batb": [[0, 2.92, 6], [1, 2.9, 307.87], [2, 2.88, 204]], "batl": [[0, 2.96, 405.64]]}, {"timestamp": 1578739113965, "ltp": 2.96, "tv": 7470.58, "trd": NaN, "batb": NaN, "batl": [[0, 2.94, 13.88], [1, 2.96, 405.64], [2, 2.98, 12.08]]}, {"timestamp": 1578739114972, "ltp": 2.96, "tv": 7470.58, "trd": NaN, "batb": NaN, "batl": [[0, 2.96, 405.64], [1, 2.98, 12.08], [2, 3, 17]]}, {"timestamp": 1578739116869, "ltp": 2.96, "tv": 7470.58, "trd": NaN, "batb": [[0, 2.92, 163.87], [1, 2.9, 150]], "batl": NaN}, {"timestamp": 1578739120848, "ltp": 2.96, "tv": 7470.58, "trd": NaN, "batb": [[1, 2.9, 163.9]], "batl": NaN}, {"timestamp": 1578739123985, "ltp": 2.96, "tv": 7470.58, "trd": NaN, "batb": NaN, "batl": [[0, 2.94, 3.06], [1, 2.96, 405.64], [2, 2.98, 12.08]]}, {"timestamp": 1578739124971, "ltp": 2.96, "tv": 7470.58, "trd": NaN, "batb": NaN, "batl": [[0, 2.96, 405.64], [1, 2.98, 12.08], [2, 3, 17]]}, {"timestamp": 1578739141901, "ltp": 2.92, "tv": 7475.58, "trd": [[2.92, 114.08]], "batb": [[0, 2.92, 161.37]], "batl": NaN}, {"timestamp": 1578739148003, "ltp": 2.92, "tv": 7475.58, "trd": NaN, "batb": [[0, 2.92, 187.52]], "batl": NaN}, {"timestamp": 1578739153916, "ltp": 2.92, "tv": 7475.58, "trd": NaN, "batb": NaN, "batl": [[0, 2.94, 2.5], [1, 2.96, 405.64], [2, 2.98, 12.08]]}, {"timestamp": 1578739155845, "ltp": 2.94, "tv": 7480.59, "trd": [[2.94, 13]], "batb": [[0, 2.94, 6.01], [1, 2.92, 187.52], [2, 2.9, 163.9]], "batl": [[0, 2.96, 405.64], [1, 2.98, 12.08], [2, 3, 17]]}, {"timestamp": 1578739172975, "ltp": 2.94, "tv": 7480.59, "trd": NaN, "batb": [[1, 2.92, 87.52]], "batl": NaN}, {"timestamp": 1578739183002, "ltp": 2.94, "tv": 7480.59, "trd": NaN, "batb": NaN, "batl": [[2, 3, 117]]}, {"timestamp": 1578739194922, "ltp": 2.94, "tv": 7480.59, "trd": NaN, "batb": [[1, 2.92, 29.65]], "batl": [[1, 2.98, 112.08], [2, 3, 17]]}, {"timestamp": 1578739196930, "ltp": 2.94, "tv": 7492.61, "trd": [[2.94, 25.02]], "batb": [[0, 2.92, 43.87], [1, 2.9, 163.9], [2, 2.88, 204]], "batl": [[0, 2.94, 13.6], [1, 2.96, 405.64], [2, 2.98, 112.08]]}, {"timestamp": 1578739199927, "ltp": 2.94, "tv": 7519.81, "trd": [[2.94, 52.22]], "batb": [[0, 2.94, 25.18], [1, 2.92, 43.87], [2, 2.9, 163.9]], "batl": [[0, 2.96, 405.64], [1, 2.98, 112.08], [2, 3, 17]]}, {"timestamp": 1578739200830, "ltp": 2.94, "tv": 7559.95, "trd": [[2.94, 92.37]], "batb": [[0, 2.94, 5.11], [1, 2.92, 58.12]], "batl": NaN}, {"timestamp": 1578739201938, "ltp": 2.94, "tv": 7559.95, "trd": NaN, "batb": [[1, 2.92, 67.54]], "batl": NaN}, {"timestamp": 1578739203751, "ltp": 2.94, "tv": 7559.95, "trd": NaN, "batb": [[0, 2.94, 107.61]], "batl": NaN}, {"timestamp": 1578739206843, "ltp": 2.94, "tv": 7610.31, "trd": [[2.94, 142.73]], "batb": [[0, 2.94, 82.43], [1, 2.92, 92.89]], "batl": NaN}, {"timestamp": 1578739212852, "ltp": 2.94, "tv": 7614.31, "trd": [[2.94, 146.73]], "batb": [[0, 2.94, 80.43]], "batl": NaN}, {"timestamp": 1578739216855, "ltp": 2.94, "tv": 7614.31, "trd": NaN, "batb": NaN, "batl": [[0, 2.96, 505.64], [1, 2.98, 12.08]]}, {"timestamp": 1578739223984, "ltp": 2.94, "tv": 7614.31, "trd": NaN, "batb": [[0, 2.94, 182.43]], "batl": NaN}, {"timestamp": 1578739228902, "ltp": 2.94, "tv": 7614.31, "trd": NaN, "batb": [[0, 2.94, 80.43]], "batl": NaN}, {"timestamp": 1578739229907, "ltp": 2.96, "tv": 7814.31, "trd": [[2.96, 708]], "batb": NaN, "batl": [[0, 2.96, 405.64]]}, {"timestamp": 1578739238919, "ltp": 2.96, "tv": 7814.31, "trd": NaN, "batb": [[0, 2.94, 182.43]], "batl": NaN}, {"timestamp": 1578739246004, "ltp": 2.96, "tv": 7814.31, "trd": NaN, "batb": [[0, 2.94, 80.43], [1, 2.92, 194.89]], "batl": NaN}, {"timestamp": 1578739258934, "ltp": 2.94, "tv": 7980.01, "trd": [[2.94, 312.43]], "batb": [[0, 2.92, 194.89], [1, 2.9, 163.9], [2, 2.88, 204]], "batl": [[0, 2.94, 17.15], [1, 2.96, 305.64], [2, 2.98, 12.08]]}, {"timestamp": 1578739259772, "ltp": 2.94, "tv": 7980.01, "trd": NaN, "batb": NaN, "batl": [[2, 2.98, 4]]}, {"timestamp": 1578739260945, "ltp": 2.94, "tv": 8014.31, "trd": [[2.94, 346.73]], "batb": [[0, 2.94, 16.5], [1, 2.92, 194.89], [2, 2.9, 163.9]], "batl": [[0, 2.96, 305.64], [1, 2.98, 4], [2, 3, 17]]}, {"timestamp": 1578739261944, "ltp": 2.94, "tv": 8014.31, "trd": NaN, "batb": [[0, 2.92, 194.89], [1, 2.9, 163.9], [2, 2.88, 204]], "batl": NaN}, {"timestamp": 1578739262944, "ltp": 2.94, "tv": 8014.31, "trd": NaN, "batb": [[0, 2.94, 18.08], [1, 2.92, 185.47], [2, 2.9, 163.9]], "batl": NaN}, {"timestamp": 1578739274891, "ltp": 2.94, "tv": 8014.31, "trd": NaN, "batb": [[0, 2.94, 21.92]], "batl": NaN}, {"timestamp": 1578739281875, "ltp": 2.94, "tv": 8014.31, "trd": NaN, "batb": [[0, 2.94, 62.78]], "batl": NaN}, {"timestamp": 1578739291927, "ltp": 2.94, "tv": 8052.31, "trd": [[2.94, 384.72]], "batb": [[0, 2.94, 43.78]], "batl": NaN}, {"timestamp": 1578739293919, "ltp": 2.94, "tv": 8052.31, "trd": NaN, "batb": [[2, 2.9, 267.9]], "batl": NaN}, {"timestamp": 1578739295923, "ltp": 2.94, "tv": 8052.31, "trd": NaN, "batb": [[0, 2.94, 40.86], [1, 2.92, 159.32], [2, 2.9, 254]], "batl": NaN}, {"timestamp": 1578739313966, "ltp": 2.94, "tv": 8052.31, "trd": NaN, "batb": [[0, 2.94, 58.8]], "batl": NaN}, {"timestamp": 1578739328959, "ltp": 2.94, "tv": 8173.92, "trd": [[2.94, 506.33]], "batb": [[0, 2.92, 159.32], [1, 2.9, 254], [2, 2.88, 204]], "batl": [[0, 2.94, 439.19], [1, 2.96, 305.64], [2, 2.98, 4]]}, {"timestamp": 1578739330001, "ltp": 2.94, "tv": 8708.72, "trd": [[2.94, 1041.13]], "batb": NaN, "batl": [[0, 2.94, 171.79]]}, {"timestamp": 1578739342004, "ltp": 2.94, "tv": 8808.72, "trd": [[2.94, 1141.13]], "batb": NaN, "batl": [[0, 2.94, 121.79]]}, {"timestamp": 1578739348969, "ltp": 2.92, "tv": 8814.72, "trd": [[2.92, 120.08]], "batb": [[0, 2.92, 156.32]], "batl": NaN}, {"timestamp": 1578739362885, "ltp": 2.92, "tv": 8814.72, "trd": NaN, "batb": NaN, "batl": [[0, 2.94, 124.79]]}, {"timestamp": 1578739375902, "ltp": 2.94, "tv": 9018.8, "trd": [[2.94, 1345.21]], "batb": NaN, "batl": [[0, 2.94, 22.75]]}, {"timestamp": 1578739390921, "ltp": 2.94, "tv": 9029.14, "trd": [[2.94, 1355.55]], "batb": NaN, "batl": [[0, 2.94, 17.58]]}, {"timestamp": 1578739391929, "ltp": 2.94, "tv": 9029.14, "trd": NaN, "batb": [[0, 2.92, 166.54]], "batl": NaN}, {"timestamp": 1578739422765, "ltp": 2.94, "tv": 9055.6, "trd": [[2.94, 1382.01]], "batb": NaN, "batl": [[0, 2.94, 4.35]]}, {"timestamp": 1578739512937, "ltp": 2.92, "tv": 9075.6, "trd": [[2.92, 140.08]], "batb": [[0, 2.92, 156.54]], "batl": NaN}, {"timestamp": 1578739514957, "ltp": 2.92, "tv": 9075.6, "trd": NaN, "batb": [[0, 2.92, 258.54]], "batl": NaN}, {"timestamp": 1578739521877, "ltp": 2.94, "tv": 9084.29, "trd": [[2.94, 1390.71]], "batb": [[0, 2.94, 78.29], [1, 2.92, 258.54], [2, 2.9, 254]], "batl": [[0, 2.96, 305.64], [1, 2.98, 4], [2, 3, 17]]}, {"timestamp": 1578739530940, "ltp": 2.94, "tv": 9085.29, "trd": [[2.94, 1391.71]], "batb": [[0, 2.94, 77.79]], "batl": NaN}, {"timestamp": 1578739540967, "ltp": 2.94, "tv": 9085.29, "trd": NaN, "batb": [[0, 2.92, 258.54], [1, 2.9, 254], [2, 2.88, 204]], "batl": NaN}, {"timestamp": 1578739551999, "ltp": 2.94, "tv": 9085.29, "trd": NaN, "batb": NaN, "batl": [[0, 2.94, 3], [1, 2.96, 305.64], [2, 2.98, 4]]}, {"timestamp": 1578739559801, "ltp": 2.94, "tv": 9091.29, "trd": [[2.94, 1397.71]], "batb": [[0, 2.94, 74.79], [1, 2.92, 258.54], [2, 2.9, 254]], "batl": [[0, 2.96, 305.64], [1, 2.98, 4], [2, 3, 17]]}, {"timestamp": 1578739578860, "ltp": 2.94, "tv": 9091.29, "trd": NaN, "batb": [[0, 2.92, 258.54], [1, 2.9, 254], [2, 2.88, 204]], "batl": NaN}, {"timestamp": 1578739652971, "ltp": 2.94, "tv": 9091.29, "trd": NaN, "batb": NaN, "batl": [[0, 2.94, 24.27], [1, 2.96, 305.64], [2, 2.98, 4]]}, {"timestamp": 1578739715971, "ltp": 2.94, "tv": 9139.83, "trd": [[2.94, 1446.24]], "batb": [[0, 2.94, 23.4], [1, 2.92, 258.54], [2, 2.9, 254]], "batl": [[0, 2.96, 305.64], [1, 2.98, 10.18], [2, 3, 17]]}, {"timestamp": 1578739717970, "ltp": 2.94, "tv": 9139.83, "trd": NaN, "batb": NaN, "batl": [[1, 2.98, 4]]}, {"timestamp": 1578739775977, "ltp": 2.94, "tv": 9139.83, "trd": NaN, "batb": [[0, 2.92, 258.54], [1, 2.9, 150], [2, 2.88, 204]], "batl": NaN}, {"timestamp": 1578739776966, "ltp": 2.94, "tv": 9139.83, "trd": NaN, "batb": [[0, 2.92, 266.3]], "batl": NaN}, {"timestamp": 1578739778956, "ltp": 2.94, "tv": 9139.83, "trd": NaN, "batb": [[0, 2.92, 258.54], [1, 2.9, 163.9]], "batl": NaN}, {"timestamp": 1578739827927, "ltp": 2.92, "tv": 9171.83, "trd": [[2.92, 172.09]], "batb": [[0, 2.92, 242.54]], "batl": NaN}, {"timestamp": 1578739829924, "ltp": 2.92, "tv": 9171.83, "trd": NaN, "batb": [[0, 2.94, 5.49], [1, 2.92, 242.54], [2, 2.9, 163.9]], "batl": NaN}, {"timestamp": 1578739831925, "ltp": 2.92, "tv": 9171.83, "trd": NaN, "batb": [[2, 2.9, 150]], "batl": NaN}, {"timestamp": 1578739837934, "ltp": 2.94, "tv": 9182.81, "trd": [[2.94, 1457.23]], "batb": [[0, 2.92, 242.54], [1, 2.9, 150], [2, 2.88, 204]], "batl": [[0, 2.94, 94.51], [1, 2.96, 305.64], [2, 2.98, 4]]}, {"timestamp": 1578739840939, "ltp": 2.94, "tv": 9182.81, "trd": NaN, "batb": [[1, 2.9, 152.31]], "batl": NaN}, {"timestamp": 1578739841941, "ltp": 2.94, "tv": 9182.81, "trd": NaN, "batb": [[1, 2.9, 164.18]], "batl": NaN}, {"timestamp": 1578739845840, "ltp": 2.94, "tv": 9342.81, "trd": [[2.94, 1617.23]], "batb": NaN, "batl": [[0, 2.94, 14.51]]}, {"timestamp": 1578739858775, "ltp": 2.94, "tv": 9342.81, "trd": NaN, "batb": NaN, "batl": [[0, 2.94, 114.51]]}, {"timestamp": 1578739876004, "ltp": 2.92, "tv": 9346.81, "trd": [[2.92, 176.09]], "batb": [[0, 2.92, 240.53]], "batl": NaN}, {"timestamp": 1578739885982, "ltp": 2.94, "tv": 9367.21, "trd": [[2.94, 1637.63]], "batb": NaN, "batl": [[0, 2.94, 104.31]]}, {"timestamp": 1578739933979, "ltp": 2.92, "tv": 9377.21, "trd": [[2.92, 186.09]], "batb": [[0, 2.92, 235.53]], "batl": NaN}, {"timestamp": 1578739935593, "ltp": 2.92, "tv": 9377.21, "trd": NaN, "batb": [[0, 2.92, 241.49]], "batl": NaN}, {"timestamp": 1578739951002, "ltp": 2.92, "tv": 9411.26, "trd": [[2.92, 220.13]], "batb": [[0, 2.92, 224.47]], "batl": NaN}, {"timestamp": 1578739970932, "ltp": 2.92, "tv": 9611.26, "trd": [[2.92, 420.13]], "batb": [[0, 2.92, 124.47]], "batl": NaN}, {"timestamp": 1578739978924, "ltp": 2.94, "tv": 9615.46, "trd": [[2.94, 1641.83]], "batb": NaN, "batl": [[0, 2.94, 102.21]]}, {"timestamp": 1578739992973, "ltp": 2.92, "tv": 9619.46, "trd": [[2.92, 424.13]], "batb": [[0, 2.92, 122.47]], "batl": NaN}, {"timestamp": 1578739995955, "ltp": 2.92, "tv": 9679.46, "trd": [[2.92, 484.14]], "batb": [[0, 2.92, 92.47]], "batl": NaN}, {"timestamp": 1578740030956, "ltp": 2.92, "tv": 9679.46, "trd": NaN, "batb": [[2, 2.88, 304]], "batl": NaN}, {"timestamp": 1578740035958, "ltp": 2.92, "tv": 9679.46, "trd": NaN, "batb": [[0, 2.92, 99.28]], "batl": NaN}, {"timestamp": 1578740060990, "ltp": 2.92, "tv": 9679.46, "trd": NaN, "batb": [[0, 2.92, 126.9]], "batl": NaN}, {"timestamp": 1578740062986, "ltp": 2.94, "tv": 9895.74, "trd": [[2.94, 1858.11]], "batb": NaN, "batl": [[0, 2.94, 4.64], [2, 2.98, 32.32]]}, {"timestamp": 1578740064660, "ltp": 2.94, "tv": 9895.74, "trd": NaN, "batb": NaN, "batl": [[2, 2.98, 4]]}, {"timestamp": 1578740078996, "ltp": 2.94, "tv": 9905.02, "trd": [[2.94, 1867.39]], "batb": [[0, 2.94, 70.15], [1, 2.92, 126.9], [2, 2.9, 164.18]], "batl": [[0, 2.96, 305.64], [1, 2.98, 4], [2, 3, 17]]}, {"timestamp": 1578740080619, "ltp": 2.94, "tv": 9905.02, "trd": NaN, "batb": [[1, 2.92, 139.97]], "batl": NaN}, {"timestamp": 1578740097851, "ltp": 2.94, "tv": 9905.02, "trd": NaN, "batb": [[0, 2.92, 139.97], [1, 2.9, 164.18], [2, 2.88, 304]], "batl": NaN}, {"timestamp": 1578740099838, "ltp": 2.94, "tv": 9905.02, "trd": NaN, "batb": [[0, 2.92, 126.9]], "batl": NaN}, {"timestamp": 1578740100976, "ltp": 2.94, "tv": 9905.02, "trd": NaN, "batb": NaN, "batl": [[0, 2.96, 315.64]]}, {"timestamp": 1578740109972, "ltp": 2.92, "tv": 9939.56, "trd": [[2.92, 518.68]], "batb": [[0, 2.92, 109.63]], "batl": NaN}, {"timestamp": 1578740123984, "ltp": 2.92, "tv": 9989.56, "trd": [[2.92, 568.68]], "batb": [[0, 2.92, 84.63]], "batl": NaN}, {"timestamp": 1578740126970, "ltp": 2.92, "tv": 9989.56, "trd": NaN, "batb": [[2, 2.88, 202]], "batl": NaN}, {"timestamp": 1578740150937, "ltp": 2.92, "tv": 9989.56, "trd": NaN, "batb": [[0, 2.94, 100], [1, 2.92, 84.63], [2, 2.9, 164.18]], "batl": NaN}, {"timestamp": 1578740152421, "ltp": 2.92, "tv": 9989.56, "trd": NaN, "batb": [[1, 2.92, 98.52]], "batl": NaN}, {"timestamp": 1578740164938, "ltp": 2.96, "tv": 10189.56, "trd": [[2.96, 908]], "batb": [[0, 2.92, 98.52], [1, 2.9, 164.18], [2, 2.88, 202]], "batl": [[0, 2.96, 215.64]]}, {"timestamp": 1578740166419, "ltp": 2.96, "tv": 10189.56, "trd": NaN, "batb": [[0, 2.92, 84.63]], "batl": NaN}, {"timestamp": 1578740194894, "ltp": 2.96, "tv": 10189.56, "trd": NaN, "batb": [[0, 2.92, 77.82]], "batl": NaN}, {"timestamp": 1578740215912, "ltp": 2.96, "tv": 10189.56, "trd": NaN, "batb": [[0, 2.92, 92.94]], "batl": [[0, 2.94, 10.83], [1, 2.96, 215.64], [2, 2.98, 4]]}, {"timestamp": 1578740228928, "ltp": 2.94, "tv": 10211.21, "trd": [[2.94, 1889.04]], "batb": [[0, 2.94, 59.32], [1, 2.92, 92.94], [2, 2.9, 164.18]], "batl": [[0, 2.96, 215.64], [1, 2.98, 4], [2, 3, 17]]}, {"timestamp": 1578740230908, "ltp": 2.94, "tv": 10211.21, "trd": NaN, "batb": [[1, 2.92, 106.83]], "batl": NaN}, {"timestamp": 1578740247881, "ltp": 2.94, "tv": 10211.21, "trd": NaN, "batb": [[0, 2.92, 106.83], [1, 2.9, 164.18], [2, 2.88, 100]], "batl": NaN}, {"timestamp": 1578740259001, "ltp": 2.94, "tv": 10211.21, "trd": NaN, "batb": [[0, 2.92, 92.94]], "batl": NaN}, {"timestamp": 1578740276996, "ltp": 2.96, "tv": 10641.92, "trd": [[2.96, 1338.71]], "batb": NaN, "batl": [[0, 2.98, 4.29], [1, 3, 17], [2, 3.05, 45.56]]}, {"timestamp": 1578740277929, "ltp": 2.96, "tv": 10642.5, "trd": [[2.96, 1339.29]], "batb": [[0, 2.94, 10.57], [1, 2.92, 92.94], [2, 2.9, 164.18]], "batl": [[0, 2.98, 4]]}, {"timestamp": 1578740278911, "ltp": 2.96, "tv": 10642.5, "trd": NaN, "batb": [[1, 2.92, 96.6], [2, 2.9, 152.31]], "batl": NaN}, {"timestamp": 1578740323956, "ltp": 2.96, "tv": 10642.5, "trd": NaN, "batb": [[0, 2.94, 110.57], [2, 2.9, 52.31]], "batl": NaN}, {"timestamp": 1578740324937, "ltp": 2.96, "tv": 10642.5, "trd": NaN, "batb": [[0, 2.96, 5.88], [1, 2.94, 110.57], [2, 2.92, 90.64]], "batl": NaN}, {"timestamp": 1578740325880, "ltp": 2.96, "tv": 10642.5, "trd": NaN, "batb": [[0, 2.96, 75.56], [2, 2.92, 75.52]], "batl": NaN}, {"timestamp": 1578740327966, "ltp": 2.96, "tv": 10642.5, "trd": NaN, "batb": [[1, 2.94, 124.45]], "batl": NaN}, {"timestamp": 1578740340986, "ltp": 2.96, "tv": 10642.5, "trd": NaN, "batb": [[0, 2.96, 87.25]], "batl": NaN}, {"timestamp": 1578740344879, "ltp": 2.98, "tv": 10650.5, "trd": [[2.98, 27.62]], "batb": [[0, 2.98, 54.53], [1, 2.96, 28.32], [2, 2.94, 124.45]], "batl": [[0, 3, 17], [1, 3.05, 45.56], [2, 3.1, 21.28]]}, {"timestamp": 1578740345970, "ltp": 3.0, "tv": 10654.5, "trd": [[3, 4]], "batb": NaN, "batl": [[0, 3, 15]]}, {"timestamp": 1578740347752, "ltp": 3.0, "tv": 10654.5, "trd": NaN, "batb": [[1, 2.96, 42.19]], "batl": NaN}, {"timestamp": 1578740364004, "ltp": 3.0, "tv": 10654.5, "trd": NaN, "batb": [[0, 2.96, 42.19], [1, 2.94, 124.45], [2, 2.92, 71.86]], "batl": NaN}, {"timestamp": 1578740385918, "ltp": 3.0, "tv": 10654.5, "trd": NaN, "batb": [[0, 2.96, 28.32], [1, 2.94, 110.57]], "batl": NaN}, {"timestamp": 1578740398842, "ltp": 3.0, "tv": 10654.5, "trd": NaN, "batb": [[1, 2.94, 119.9]], "batl": NaN}, {"timestamp": 1578740401937, "ltp": 3.0, "tv": 10654.5, "trd": NaN, "batb": NaN, "batl": [[0, 2.98, 33], [1, 3, 15], [2, 3.05, 45.56]]}, {"timestamp": 1578740420983, "ltp": 2.98, "tv": 10720.48, "trd": [[2.98, 93.61]], "batb": [[0, 2.98, 21.54], [1, 2.96, 28.32], [2, 2.94, 119.9]], "batl": [[0, 3, 15], [1, 3.05, 45.56], [2, 3.1, 21.28]]}, {"timestamp": 1578740422668, "ltp": 2.98, "tv": 10720.48, "trd": NaN, "batb": [[1, 2.96, 35.48]], "batl": NaN}, {"timestamp": 1578740440961, "ltp": 2.98, "tv": 10720.48, "trd": NaN, "batb": [[0, 2.96, 35.48], [1, 2.94, 119.9], [2, 2.92, 71.86]], "batl": NaN}, {"timestamp": 1578740442903, "ltp": 2.98, "tv": 10720.48, "trd": NaN, "batb": [[0, 2.96, 28.32], [1, 2.94, 122.19]], "batl": NaN}, {"timestamp": 1578740521706, "ltp": 3.0, "tv": 10724.14, "trd": [[3, 7.66]], "batb": NaN, "batl": [[0, 3, 13.17]]}, {"timestamp": 1578740569887, "ltp": 3.0, "tv": 10750.48, "trd": [[3, 34]], "batb": [[0, 3, 1.83], [1, 2.96, 28.32], [2, 2.94, 122.19]], "batl": [[0, 3.05, 45.56], [1, 3.1, 21.28], [2, 3.2, 2]]}, {"timestamp": 1578740570964, "ltp": 3.0, "tv": 10785.76, "trd": [[3, 69.28]], "batb": [[0, 3, 2.4], [2, 2.94, 111.62]], "batl": [[0, 3.05, 54.8], [1, 3.1, 24.74]]}, {"timestamp": 1578740571975, "ltp": 3.0, "tv": 10785.76, "trd": NaN, "batb": [[2, 2.94, 100]], "batl": [[0, 3.05, 61.11], [1, 3.1, 21.28]]}, {"timestamp": 1578740629000, "ltp": 3.0, "tv": 10785.76, "trd": NaN, "batb": NaN, "batl": [[2, 3.2, 12]]}, {"timestamp": 1578740633696, "ltp": 3.0, "tv": 10790.57, "trd": [[3, 74.08]], "batb": [[0, 2.96, 28.32], [1, 2.94, 100], [2, 2.92, 71.86]], "batl": [[0, 3.05, 63.47]]}, {"timestamp": 1578740641712, "ltp": 3.0, "tv": 10790.57, "trd": NaN, "batb": [[1, 2.94, 109.33]], "batl": NaN}, {"timestamp": 1578740661969, "ltp": 3.0, "tv": 10790.57, "trd": NaN, "batb": NaN, "batl": [[0, 3, 2.2], [1, 3.05, 63.47], [2, 3.1, 21.28]]}, {"timestamp": 1578740666861, "ltp": 2.96, "tv": 10810.57, "trd": [[2.96, 1359.29]], "batb": [[0, 2.96, 18.32]], "batl": NaN}, {"timestamp": 1578740675974, "ltp": 3.0, "tv": 10814.97, "trd": [[3, 78.48]], "batb": NaN, "batl": [[0, 3.05, 63.47], [1, 3.1, 21.28], [2, 3.2, 12]]}, {"timestamp": 1578740702907, "ltp": 3.0, "tv": 10814.97, "trd": NaN, "batb": NaN, "batl": [[0, 3, 12.5], [1, 3.05, 63.47], [2, 3.1, 21.28]]}, {"timestamp": 1578740723934, "ltp": 3.0, "tv": 10814.97, "trd": NaN, "batb": NaN, "batl": [[0, 3, 87.5]]}, {"timestamp": 1578740728922, "ltp": 3.0, "tv": 10859.63, "trd": [[3, 123.14]], "batb": NaN, "batl": [[0, 3, 65.17]]}, {"timestamp": 1578740788939, "ltp": 2.96, "tv": 10869.62, "trd": [[2.96, 1369.28]], "batb": [[0, 2.96, 13.32]], "batl": NaN}, {"timestamp": 1578740792967, "ltp": 2.96, "tv": 10869.62, "trd": NaN, "batb": [[1, 2.94, 104.53]], "batl": NaN}, {"timestamp": 1578740814985, "ltp": 2.96, "tv": 10869.62, "trd": NaN, "batb": NaN, "batl": [[0, 2.98, 34], [1, 3, 65.17], [2, 3.05, 63.47]]}, {"timestamp": 1578740817984, "ltp": 2.96, "tv": 10938.72, "trd": [[2.96, 1395.29], [2.98, 136.71]], "batb": [[0, 2.94, 104.53], [1, 2.92, 71.86], [2, 2.9, 50]], "batl": [[0, 2.98, 12.45]]}, {"timestamp": 1578740819984, "ltp": 2.96, "tv": 10938.72, "trd": NaN, "batb": [[0, 2.94, 100], [1, 2.92, 86.08]], "batl": [[1, 3, 76.39]]}, {"timestamp": 1578740838987, "ltp": 2.98, "tv": 10962.56, "trd": [[2.98, 160.54]], "batb": NaN, "batl": [[0, 3, 76.92], [1, 3.05, 63.47], [2, 3.1, 21.28]]}, {"timestamp": 1578740839987, "ltp": 2.98, "tv": 10963.62, "trd": [[2.98, 161.6]], "batb": NaN, "batl": [[0, 3, 76.39]]}, {"timestamp": 1578740875936, "ltp": 2.98, "tv": 10963.62, "trd": NaN, "batb": [[0, 2.96, 9.22], [1, 2.94, 100], [2, 2.92, 86.08]], "batl": NaN}, {"timestamp": 1578740877967, "ltp": 2.98, "tv": 10963.62, "trd": NaN, "batb": [[1, 2.94, 103.22], [2, 2.92, 71.86]], "batl": NaN}, {"timestamp": 1578740878861, "ltp": 2.98, "tv": 10963.62, "trd": NaN, "batb": NaN, "batl": [[2, 3.1, 28.88]]}, {"timestamp": 1578740893957, "ltp": 2.98, "tv": 10963.62, "trd": NaN, "batb": [[0, 2.96, 10.39]], "batl": NaN}, {"timestamp": 1578740949856, "ltp": 2.98, "tv": 10963.62, "trd": NaN, "batb": [[1, 2.94, 100]], "batl": NaN}, {"timestamp": 1578740964996, "ltp": 2.98, "tv": 10963.62, "trd": NaN, "batb": [[1, 2.94, 103.87]], "batl": NaN}, {"timestamp": 1578741035900, "ltp": 2.98, "tv": 10963.62, "trd": NaN, "batb": NaN, "batl": [[0, 3, 80.39]]}, {"timestamp": 1578741069953, "ltp": 2.96, "tv": 10983.62, "trd": [[2.96, 1415.29]], "batb": [[0, 2.94, 104.26], [1, 2.92, 71.86], [2, 2.9, 50]], "batl": NaN}, {"timestamp": 1578741071871, "ltp": 2.96, "tv": 10983.62, "trd": NaN, "batb": NaN, "batl": [[0, 3, 89.49]]}, {"timestamp": 1578741090895, "ltp": 2.96, "tv": 10983.62, "trd": NaN, "batb": [[0, 2.94, 100.39], [1, 2.92, 86.08]], "batl": NaN}, {"timestamp": 1578741108832, "ltp": 2.94, "tv": 11023.62, "trd": [[2.94, 1928.26], [2.96, 1416.07]], "batb": [[0, 2.94, 80.39]], "batl": NaN}, {"timestamp": 1578741146894, "ltp": 2.94, "tv": 11023.62, "trd": NaN, "batb": NaN, "batl": [[0, 2.98, 40], [1, 3, 89.49], [2, 3.05, 63.47]]}, {"timestamp": 1578741236885, "ltp": 2.94, "tv": 11023.62, "trd": NaN, "batb": NaN, "batl": [[0, 2.96, 61.37], [1, 2.98, 40], [2, 3, 78.27]]}, {"timestamp": 1578741237995, "ltp": 2.94, "tv": 11023.62, "trd": NaN, "batb": NaN, "batl": [[0, 2.96, 70.59], [2, 3, 69.17]]}, {"timestamp": 1578741257922, "ltp": 2.94, "tv": 11050.96, "trd": [[2.94, 1955.6]], "batb": [[0, 2.94, 66.72]], "batl": NaN}, {"timestamp": 1578741288876, "ltp": 2.94, "tv": 11184.4, "trd": [[2.94, 2089.04]], "batb": [[0, 2.92, 86.08], [1, 2.9, 50], [2, 2.88, 100]], "batl": [[0, 2.94, 33.28], [1, 2.96, 70.59], [2, 2.98, 40]]}, {"timestamp": 1578741289978, "ltp": 2.94, "tv": 11209.54, "trd": [[2.94, 2114.18]], "batb": [[1, 2.9, 78.54]], "batl": [[0, 2.94, 20.71]]}, {"timestamp": 1578741290932, "ltp": 2.94, "tv": 11209.54, "trd": NaN, "batb": [[0, 2.92, 71.86], [1, 2.9, 64.27]], "batl": NaN}, {"timestamp": 1578741298859, "ltp": 2.94, "tv": 11250.95, "trd": [[2.94, 2155.59]], "batb": [[0, 2.94, 69.01], [1, 2.92, 71.86], [2, 2.9, 64.27]], "batl": [[0, 2.96, 70.59], [1, 2.98, 40], [2, 3, 69.17]]}, {"timestamp": 1578741300928, "ltp": 2.94, "tv": 11250.95, "trd": NaN, "batb": [[1, 2.92, 85.75]], "batl": NaN}, {"timestamp": 1578741307998, "ltp": 2.94, "tv": 11250.95, "trd": NaN, "batb": NaN, "batl": [[1, 3, 69.17], [2, 3.05, 63.47]]}, {"timestamp": 1578741308921, "ltp": 2.94, "tv": 11330.94, "trd": [[2.94, 2235.58]], "batb": [[0, 2.92, 85.75], [1, 2.9, 64.27], [2, 2.88, 100]], "batl": [[1, 2.98, 20.45], [2, 3, 69.17]]}, {"timestamp": 1578741309929, "ltp": 2.94, "tv": 11330.94, "trd": NaN, "batb": [[0, 2.92, 71.86]], "batl": NaN}, {"timestamp": 1578741328845, "ltp": 2.94, "tv": 11330.94, "trd": NaN, "batb": NaN, "batl": [[0, 2.94, 50], [1, 2.96, 70.59], [2, 2.98, 20.45]]}, {"timestamp": 1578741329963, "ltp": 2.94, "tv": 11330.94, "trd": NaN, "batb": NaN, "batl": [[2, 2.98, 9.16]]}, {"timestamp": 1578741330986, "ltp": 2.94, "tv": 11330.94, "trd": NaN, "batb": NaN, "batl": [[2, 3, 69.17]]}, {"timestamp": 1578741337906, "ltp": 2.94, "tv": 11389.0, "trd": [[2.94, 2293.64]], "batb": NaN, "batl": [[0, 2.94, 20.96]]}, {"timestamp": 1578741366911, "ltp": 2.94, "tv": 11389.0, "trd": NaN, "batb": [[2, 2.88, 103.72]], "batl": NaN}, {"timestamp": 1578741395961, "ltp": 2.94, "tv": 11389.0, "trd": NaN, "batb": NaN, "batl": [[1, 2.96, 20.59]]}, {"timestamp": 1578741397983, "ltp": 2.94, "tv": 11389.0, "trd": NaN, "batb": NaN, "batl": [[1, 2.96, 11.37]]}, {"timestamp": 1578741398963, "ltp": 2.94, "tv": 11389.0, "trd": NaN, "batb": NaN, "batl": [[1, 3, 69.17], [2, 3.05, 63.47]]}, {"timestamp": 1578741402948, "ltp": 2.94, "tv": 11428.22, "trd": [[2.94, 2332.86]], "batb": NaN, "batl": [[0, 2.94, 1.35]]}, {"timestamp": 1578741403972, "ltp": 2.94, "tv": 11430.92, "trd": [[2.94, 2335.56]], "batb": [[2, 2.88, 100]], "batl": [[0, 2.98, 6.18], [1, 3, 77.49], [2, 3.05, 66.36]]}, {"timestamp": 1578741404656, "ltp": 2.94, "tv": 11430.92, "trd": NaN, "batb": NaN, "batl": [[1, 3, 88.71]]}, {"timestamp": 1578741405979, "ltp": 2.94, "tv": 11430.92, "trd": NaN, "batb": NaN, "batl": [[0, 3, 89.49], [1, 3.05, 63.47], [2, 3.1, 21.28]]}, {"timestamp": 1578741434899, "ltp": 2.94, "tv": 11430.92, "trd": NaN, "batb": NaN, "batl": [[2, 3.1, 29.28]]}, {"timestamp": 1578741444913, "ltp": 2.94, "tv": 11430.92, "trd": NaN, "batb": NaN, "batl": [[0, 2.98, 8.51], [1, 3, 89.49], [2, 3.05, 63.47]]}, {"timestamp": 1578741447308, "ltp": 2.94, "tv": 11430.92, "trd": NaN, "batb": NaN, "batl": [[0, 2.98, 28.51]]}, {"timestamp": 1578741473979, "ltp": 2.94, "tv": 11430.92, "trd": NaN, "batb": [[1, 2.9, 67.93]], "batl": NaN}, {"timestamp": 1578741511921, "ltp": 2.94, "tv": 11430.92, "trd": NaN, "batb": [[2, 2.88, 103.72]], "batl": NaN}, {"timestamp": 1578741512886, "ltp": 2.94, "tv": 11430.92, "trd": NaN, "batb": [[1, 2.9, 64.27]], "batl": NaN}, {"timestamp": 1578741514812, "ltp": 2.94, "tv": 11430.92, "trd": NaN, "batb": NaN, "batl": [[0, 2.98, 93.68], [1, 3, 24.32]]}, {"timestamp": 1578741515827, "ltp": 2.94, "tv": 11430.92, "trd": NaN, "batb": [[0, 2.92, 75.46]], "batl": [[0, 2.96, 11.37], [1, 2.98, 93.68], [2, 3, 13.1]]}, {"timestamp": 1578741516934, "ltp": 2.94, "tv": 11430.92, "trd": NaN, "batb": NaN, "batl": [[0, 2.96, 20.59], [2, 3, 4]]}, {"timestamp": 1578741545900, "ltp": 2.94, "tv": 11430.92, "trd": NaN, "batb": NaN, "batl": [[1, 2.98, 28.51]]}, {"timestamp": 1578741546976, "ltp": 2.92, "tv": 11561.26, "trd": [[2.92, 699.02]], "batb": [[0, 2.92, 10.29]], "batl": NaN}, {"timestamp": 1578741547998, "ltp": 2.92, "tv": 11561.26, "trd": NaN, "batb": NaN, "batl": [[0, 2.98, 28.51], [1, 3, 13.1], [2, 3.05, 63.47]]}, {"timestamp": 1578741548969, "ltp": 2.92, "tv": 11561.26, "trd": NaN, "batb": [[0, 2.92, 6.69], [1, 2.9, 53.57]], "batl": [[1, 3, 24.32]]}, {"timestamp": 1578741549904, "ltp": 2.92, "tv": 11561.26, "trd": NaN, "batb": [[1, 2.9, 50]], "batl": NaN}, {"timestamp": 1578741557914, "ltp": 2.92, "tv": 11579.53, "trd": [[2.92, 712.4], [2.94, 2340.45]], "batb": [[0, 2.9, 50], [1, 2.88, 103.72], [2, 2.86, 143.83]], "batl": [[0, 2.92, 30.87], [1, 2.98, 28.51], [2, 3, 24.32]]}, {"timestamp": 1578741558984, "ltp": 2.92, "tv": 11641.27, "trd": [[2.92, 774.14]], "batb": [[0, 2.9, 50.7], [1, 2.88, 102.62], [2, 2.86, 140.04]], "batl": [[0, 2.96, 10.52]]}, {"timestamp": 1578741559997, "ltp": 2.92, "tv": 11641.27, "trd": NaN, "batb": [[1, 2.88, 113.92]], "batl": NaN}, {"timestamp": 1578741568900, "ltp": 2.92, "tv": 11641.27, "trd": NaN, "batb": [[0, 2.9, 69.9]], "batl": NaN}, {"timestamp": 1578741575885, "ltp": 2.92, "tv": 11641.27, "trd": NaN, "batb": [[0, 2.92, 6.7], [1, 2.9, 69.2], [2, 2.88, 113.92]], "batl": NaN}, {"timestamp": 1578741576969, "ltp": 2.92, "tv": 11641.27, "trd": NaN, "batb": [[2, 2.88, 102.62]], "batl": NaN}, {"timestamp": 1578741628999, "ltp": 2.92, "tv": 11641.27, "trd": NaN, "batb": [[1, 2.9, 50]], "batl": NaN}, {"timestamp": 1578741634788, "ltp": 2.92, "tv": 11641.27, "trd": NaN, "batb": [[0, 2.9, 50.7], [1, 2.88, 102.62], [2, 2.86, 140.04]], "batl": NaN}, {"timestamp": 1578741664868, "ltp": 2.92, "tv": 11641.27, "trd": NaN, "batb": [[1, 2.88, 113.92]], "batl": NaN}, {"timestamp": 1578741697915, "ltp": 2.92, "tv": 11641.27, "trd": NaN, "batb": [[0, 2.9, 63.3]], "batl": NaN}, {"timestamp": 1578741704941, "ltp": 2.92, "tv": 11641.27, "trd": NaN, "batb": [[0, 2.92, 6.7], [1, 2.9, 62.6], [2, 2.88, 113.92]], "batl": NaN}, {"timestamp": 1578741706931, "ltp": 2.92, "tv": 11641.27, "trd": NaN, "batb": [[2, 2.88, 102.62]], "batl": NaN}, {"timestamp": 1578741755806, "ltp": 2.92, "tv": 11641.27, "trd": NaN, "batb": [[1, 2.9, 50]], "batl": NaN}, {"timestamp": 1578741768931, "ltp": 2.92, "tv": 11641.27, "trd": NaN, "batb": [[0, 2.9, 50.7], [1, 2.88, 102.62], [2, 2.86, 140.04]], "batl": NaN}, {"timestamp": 1578741770930, "ltp": 2.92, "tv": 11641.27, "trd": NaN, "batb": [[1, 2.88, 113.92]], "batl": NaN}, {"timestamp": 1578741773960, "ltp": 2.9, "tv": 11821.55, "trd": [[2.9, 480.75], [2.94, 2341.85]], "batb": [[0, 2.88, 117.64], [1, 2.86, 154.42], [2, 2.8, 14.29]], "batl": [[0, 2.9, 9.86]]}, {"timestamp": 1578741774931, "ltp": 2.9, "tv": 11841.27, "trd": [[2.9, 500.47]], "batb": [[0, 2.94, 5.91], [1, 2.88, 113.92], [2, 2.86, 154.42]], "batl": [[0, 2.96, 10.52], [2, 3, 13.1]]}, {"timestamp": 1578741775836, "ltp": 2.9, "tv": 11841.27, "trd": NaN, "batb": [[1, 2.88, 100], [2, 2.86, 140.04]], "batl": [[2, 3, 24.32]]}, {"timestamp": 1578741776919, "ltp": 2.9, "tv": 11841.27, "trd": NaN, "batb": [[1, 2.88, 102.55]], "batl": NaN}, {"timestamp": 1578741781930, "ltp": 2.94, "tv": 11853.09, "trd": [[2.94, 2353.67]], "batb": [[0, 2.88, 102.55], [1, 2.86, 140.04], [2, 2.82, 3.93]], "batl": [[0, 2.94, 44.09], [1, 2.96, 10.52], [2, 2.98, 28.51]]}, {"timestamp": 1578741783949, "ltp": 2.94, "tv": 11853.09, "trd": NaN, "batb": [[0, 2.88, 100], [1, 2.86, 153.97]], "batl": NaN}, {"timestamp": 1578741784948, "ltp": 2.94, "tv": 11853.09, "trd": NaN, "batb": NaN, "batl": [[1, 2.98, 28.51], [2, 3, 24.32]]}, {"timestamp": 1578741785918, "ltp": 2.94, "tv": 11853.09, "trd": NaN, "batb": NaN, "batl": [[1, 2.98, 40.58]]}, {"timestamp": 1578741786855, "ltp": 2.94, "tv": 11853.09, "trd": NaN, "batb": [[2, 2.8, 14.29]], "batl": [[0, 2.96, 44.09]]}, {"timestamp": 1578741788948, "ltp": 2.94, "tv": 11853.09, "trd": NaN, "batb": NaN, "batl": [[1, 2.98, 28.51]]}, {"timestamp": 1578741793939, "ltp": 2.88, "tv": 12053.09, "trd": [[2.88, 504.3]], "batb": [[0, 2.86, 153.97], [1, 2.82, 3.93]], "batl": [[0, 2.94, 44.09]]}, {"timestamp": 1578741794954, "ltp": 2.88, "tv": 12053.09, "trd": NaN, "batb": [[1, 2.8, 18.29], [2, 2.78, 14.4]], "batl": NaN}, {"timestamp": 1578741795979, "ltp": 2.88, "tv": 12053.09, "trd": NaN, "batb": [[1, 2.82, 16.79], [2, 2.8, 35.08]], "batl": [[1, 2.98, 40.58]]}, {"timestamp": 1578741797908, "ltp": 2.88, "tv": 12053.09, "trd": NaN, "batb": [[0, 2.86, 140.04], [1, 2.82, 33.57]], "batl": NaN}, {"timestamp": 1578741798903, "ltp": 2.88, "tv": 12053.09, "trd": NaN, "batb": [[1, 2.82, 50.36]], "batl": NaN}, {"timestamp": 1578741799980, "ltp": 2.88, "tv": 12072.41, "trd": [[2.88, 523.62]], "batb": [[0, 2.86, 143.83], [1, 2.84, 6], [2, 2.82, 50.36]], "batl": [[0, 2.88, 34.43]]}, {"timestamp": 1578741800990, "ltp": 2.88, "tv": 12072.41, "trd": NaN, "batb": [[1, 2.84, 19.94]], "batl": [[1, 2.96, 6.71], [2, 2.98, 28.51]]}, {"timestamp": 1578741801904, "ltp": 2.88, "tv": 12072.41, "trd": NaN, "batb": NaN, "batl": [[1, 2.96, 40.17]]}, {"timestamp": 1578741802916, "ltp": 2.88, "tv": 12072.41, "trd": NaN, "batb": [[0, 2.86, 140.04], [1, 2.84, 23.8]], "batl": [[0, 2.92, 34.43]]}, {"timestamp": 1578741803983, "ltp": 2.88, "tv": 12072.41, "trd": NaN, "batb": NaN, "batl": [[1, 2.96, 60.76]]}, {"timestamp": 1578741808916, "ltp": 2.86, "tv": 12172.41, "trd": [[2.86, 651.86]], "batb": [[0, 2.86, 90.04]], "batl": NaN}, {"timestamp": 1578741810997, "ltp": 2.86, "tv": 12172.41, "trd": NaN, "batb": [[0, 2.86, 93.83], [1, 2.84, 19.94]], "batl": [[0, 2.9, 34.43]]}, {"timestamp": 1578741811907, "ltp": 2.86, "tv": 12172.41, "trd": NaN, "batb": NaN, "batl": [[1, 2.96, 27.3], [2, 2.98, 47.81]]}, {"timestamp": 1578741812915, "ltp": 2.86, "tv": 12172.41, "trd": NaN, "batb": NaN, "batl": [[1, 2.96, 43.11]]}, {"timestamp": 1578741815997, "ltp": 2.86, "tv": 12172.41, "trd": NaN, "batb": NaN, "batl": [[0, 2.94, 34.43]]}, {"timestamp": 1578741816918, "ltp": 2.86, "tv": 12172.41, "trd": NaN, "batb": [[0, 2.86, 90.04]], "batl": [[1, 2.96, 58.91]]}, {"timestamp": 1578741820901, "ltp": 2.86, "tv": 12172.41, "trd": NaN, "batb": NaN, "batl": [[1, 2.96, 20.59], [2, 2.98, 28.51]]}, {"timestamp": 1578741822959, "ltp": 2.86, "tv": 12172.41, "trd": NaN, "batb": NaN, "batl": [[1, 2.98, 28.51], [2, 3, 4]]}, {"timestamp": 1578741823902, "ltp": 2.86, "tv": 12172.41, "trd": NaN, "batb": NaN, "batl": [[2, 3, 10]]}, {"timestamp": 1578741824915, "ltp": 2.86, "tv": 12172.41, "trd": NaN, "batb": NaN, "batl": [[1, 2.98, 34.69]]}, {"timestamp": 1578741836937, "ltp": 2.86, "tv": 12172.41, "trd": NaN, "batb": [[0, 2.88, 10], [1, 2.86, 90.04], [2, 2.84, 19.94]], "batl": NaN}, {"timestamp": 1578741840955, "ltp": 2.86, "tv": 12172.41, "trd": NaN, "batb": [[2, 2.84, 6]], "batl": NaN}, {"timestamp": 1578741844877, "ltp": 2.86, "tv": 12172.41, "trd": NaN, "batb": [[2, 2.82, 20.72]], "batl": NaN}, {"timestamp": 1578741852881, "ltp": 2.86, "tv": 12172.41, "trd": NaN, "batb": [[0, 2.88, 62.04], [1, 2.86, 38]], "batl": NaN}, {"timestamp": 1578741853985, "ltp": 2.86, "tv": 12172.41, "trd": NaN, "batb": [[1, 2.86, 41.79]], "batl": [[0, 2.92, 10.62], [1, 2.94, 34.43], [2, 2.98, 34.69]]}, {"timestamp": 1578741855862, "ltp": 2.86, "tv": 12172.41, "trd": NaN, "batb": [[1, 2.86, 55.72]], "batl": [[2, 2.98, 28.51]]}, {"timestamp": 1578741856999, "ltp": 2.86, "tv": 12172.41, "trd": NaN, "batb": NaN, "batl": [[1, 2.96, 34.43]]}, {"timestamp": 1578741883936, "ltp": 2.86, "tv": 12172.41, "trd": NaN, "batb": [[1, 2.86, 51.93]], "batl": NaN}, {"timestamp": 1578741895983, "ltp": 2.86, "tv": 12172.41, "trd": NaN, "batb": [[1, 2.86, 55.72]], "batl": [[0, 2.9, 34.43], [1, 2.92, 10.62]]}, {"timestamp": 1578741944862, "ltp": 2.9, "tv": 12232.41, "trd": [[2.9, 560.47]], "batb": NaN, "batl": [[0, 2.9, 4.43]]}, {"timestamp": 1578741946849, "ltp": 2.9, "tv": 12232.41, "trd": NaN, "batb": [[1, 2.86, 51.93]], "batl": NaN}, {"timestamp": 1578741947834, "ltp": 2.9, "tv": 12232.41, "trd": NaN, "batb": [[2, 2.84, 3.86]], "batl": NaN}, {"timestamp": 1578742057994, "ltp": 2.86, "tv": 12432.41, "trd": [[2.86, 727.78], [2.88, 647.7]], "batb": [[0, 2.86, 13.97], [1, 2.82, 20.72], [2, 2.8, 18.29]], "batl": NaN}, {"timestamp": 1578742058982, "ltp": 2.86, "tv": 12432.41, "trd": NaN, "batb": [[0, 2.82, 31.26], [1, 2.8, 43.17], [2, 2.78, 18.48]], "batl": NaN}, {"timestamp": 1578742059992, "ltp": 2.86, "tv": 12432.41, "trd": NaN, "batb": [[1, 2.8, 57.47], [2, 2.78, 4.08]], "batl": NaN}, {"timestamp": 1578742061000, "ltp": 2.86, "tv": 12432.41, "trd": NaN, "batb": [[0, 2.8, 43.07], [1, 2.76, 24.76], [2, 2.74, 194]], "batl": NaN}, {"timestamp": 1578742061955, "ltp": 2.86, "tv": 12432.41, "trd": NaN, "batb": [[1, 2.78, 14.62], [2, 2.76, 39.37]], "batl": NaN}, {"timestamp": 1578742063971, "ltp": 2.86, "tv": 12432.41, "trd": NaN, "batb": [[0, 2.8, 28.63], [1, 2.78, 29.23]], "batl": NaN}, {"timestamp": 1578742066977, "ltp": 2.86, "tv": 12432.41, "trd": NaN, "batb": [[1, 2.78, 43.85]], "batl": NaN}, {"timestamp": 1578742073004, "ltp": 2.86, "tv": 12432.41, "trd": NaN, "batb": [[0, 2.82, 3.04], [1, 2.8, 28.59], [2, 2.78, 47.93]], "batl": NaN}, {"timestamp": 1578742096833, "ltp": 2.86, "tv": 12432.41, "trd": NaN, "batb": [[0, 2.82, 4.84]], "batl": NaN}, {"timestamp": 1578742098861, "ltp": 2.86, "tv": 12432.41, "trd": NaN, "batb": [[0, 2.82, 17.54]], "batl": NaN}, {"timestamp": 1578742101948, "ltp": 2.86, "tv": 12432.41, "trd": NaN, "batb": [[1, 2.8, 34.51]], "batl": NaN}, {"timestamp": 1578742121975, "ltp": 2.86, "tv": 12432.41, "trd": NaN, "batb": [[1, 2.8, 38.51]], "batl": NaN}, {"timestamp": 1578742125907, "ltp": 2.86, "tv": 12432.41, "trd": NaN, "batb": [[1, 2.8, 34.51]], "batl": NaN}, {"timestamp": 1578742127999, "ltp": 2.86, "tv": 12432.41, "trd": NaN, "batb": [[0, 2.82, 22.38]], "batl": NaN}, {"timestamp": 1578742129915, "ltp": 2.86, "tv": 12432.41, "trd": NaN, "batb": [[0, 2.82, 41.09]], "batl": NaN}, {"timestamp": 1578742132000, "ltp": 2.9, "tv": 12441.27, "trd": [[2.9, 569.33]], "batb": [[1, 2.8, 42.08]], "batl": [[0, 2.92, 10.62], [1, 2.98, 28.51], [2, 3, 4]]}, {"timestamp": 1578742132902, "ltp": 2.9, "tv": 12441.27, "trd": NaN, "batb": [[2, 2.78, 43.85]], "batl": [[1, 2.98, 30.68]]}, {"timestamp": 1578742134913, "ltp": 2.9, "tv": 12441.27, "trd": NaN, "batb": NaN, "batl": [[1, 2.98, 32.92]]}, {"timestamp": 1578742145921, "ltp": 2.92, "tv": 12462.51, "trd": [[2.92, 795.38]], "batb": NaN, "batl": [[0, 2.98, 32.92], [1, 3, 4], [2, 3.05, 63.47]]}, {"timestamp": 1578742146927, "ltp": 2.92, "tv": 12462.51, "trd": NaN, "batb": [[0, 2.92, 10.62], [1, 2.82, 41.09], [2, 2.8, 42.08]], "batl": NaN}, {"timestamp": 1578742147938, "ltp": 2.92, "tv": 12462.51, "trd": NaN, "batb": NaN, "batl": [[1, 3, 31.76]]}, {"timestamp": 1578742149980, "ltp": 2.92, "tv": 12462.51, "trd": NaN, "batb": [[1, 2.84, 10.7], [2, 2.82, 52.12]], "batl": [[0, 2.98, 28.51], [1, 3, 24.32]]}, {"timestamp": 1578742154927, "ltp": 2.92, "tv": 12462.51, "trd": NaN, "batb": [[1, 2.84, 22.99]], "batl": NaN}, {"timestamp": 1578742156971, "ltp": 2.92, "tv": 12462.51, "trd": NaN, "batb": [[2, 2.82, 49.12]], "batl": NaN}, {"timestamp": 1578742160906, "ltp": 2.92, "tv": 12462.51, "trd": NaN, "batb": [[1, 2.86, 15.84], [2, 2.84, 22.95]], "batl": [[2, 3.05, 69.47]]}, {"timestamp": 1578742177842, "ltp": 2.92, "tv": 12462.51, "trd": NaN, "batb": [[0, 2.92, 20.62]], "batl": NaN}, {"timestamp": 1578742180970, "ltp": 2.92, "tv": 12462.51, "trd": NaN, "batb": [[1, 2.88, 13.42], [2, 2.86, 29.64]], "batl": NaN}, {"timestamp": 1578742183976, "ltp": 2.92, "tv": 12462.51, "trd": NaN, "batb": NaN, "batl": [[1, 3, 74.32]]}, {"timestamp": 1578742188948, "ltp": 2.92, "tv": 12462.51, "trd": NaN, "batb": [[2, 2.86, 49.64]], "batl": NaN}, {"timestamp": 1578742195989, "ltp": 2.92, "tv": 12462.51, "trd": NaN, "batb": NaN, "batl": [[1, 3, 24.32]]}, {"timestamp": 1578742203983, "ltp": 2.98, "tv": 12464.39, "trd": [[2.98, 163.48]], "batb": NaN, "batl": [[0, 2.98, 27.58]]}, {"timestamp": 1578742205999, "ltp": 2.98, "tv": 12473.27, "trd": [[2.98, 172.36]], "batb": NaN, "batl": [[0, 2.98, 23.13]]}, {"timestamp": 1578742212000, "ltp": 2.98, "tv": 12473.27, "trd": NaN, "batb": [[2, 2.86, 52.64]], "batl": NaN}, {"timestamp": 1578742223991, "ltp": 2.98, "tv": 12473.27, "trd": NaN, "batb": NaN, "batl": [[0, 2.94, 2], [1, 2.98, 23.13], [2, 3, 24.32]]}, {"timestamp": 1578742226896, "ltp": 2.98, "tv": 12473.27, "trd": NaN, "batb": NaN, "batl": [[0, 2.98, 23.13], [1, 3, 24.32], [2, 3.05, 69.47]]}, {"timestamp": 1578742293928, "ltp": 2.98, "tv": 12473.27, "trd": NaN, "batb": [[0, 2.94, 5.93], [1, 2.92, 20.62], [2, 2.88, 13.42]], "batl": NaN}, {"timestamp": 1578742295904, "ltp": 2.98, "tv": 12473.27, "trd": NaN, "batb": [[2, 2.86, 38.84]], "batl": NaN}, {"timestamp": 1578742308981, "ltp": 2.94, "tv": 12483.26, "trd": [[2.94, 2363.66]], "batb": [[0, 2.92, 21.56], [1, 2.86, 38.84], [2, 2.82, 25.35]], "batl": NaN}, {"timestamp": 1578742309942, "ltp": 2.94, "tv": 12483.26, "trd": NaN, "batb": [[1, 2.88, 3.09], [2, 2.86, 38.84]], "batl": NaN}, {"timestamp": 1578742310985, "ltp": 2.94, "tv": 12483.26, "trd": NaN, "batb": [[1, 2.88, 16.83]], "batl": NaN}, {"timestamp": 1578742318963, "ltp": 2.94, "tv": 12483.26, "trd": NaN, "batb": [[2, 2.86, 35.84]], "batl": NaN}, {"timestamp": 1578742324879, "ltp": 2.98, "tv": 12528.49, "trd": [[2.98, 217.58]], "batb": NaN, "batl": [[0, 3, 24.84], [1, 3.05, 69.47], [2, 3.1, 21.28]]}, {"timestamp": 1578742325913, "ltp": 2.98, "tv": 12545.43, "trd": [[2.98, 234.52]], "batb": [[0, 2.98, 14.7], [1, 2.92, 21.56], [2, 2.88, 16.83]], "batl": [[0, 3, 24.32]]}, {"timestamp": 1578742326988, "ltp": 2.98, "tv": 12545.43, "trd": NaN, "batb": [[1, 2.94, 5.82], [2, 2.92, 28.97]], "batl": [[0, 3, 4], [1, 3.05, 89.46]]}, {"timestamp": 1578742333999, "ltp": 2.98, "tv": 12545.43, "trd": NaN, "batb": NaN, "batl": [[1, 3.05, 83.46]]}, {"timestamp": 1578742361634, "ltp": 2.98, "tv": 12545.43, "trd": NaN, "batb": [[0, 2.98, 103.22]], "batl": NaN}, {"timestamp": 1578742362961, "ltp": 3.0, "tv": 12553.43, "trd": [[3, 131.14]], "batb": [[0, 3, 6.4], [1, 2.98, 103.22], [2, 2.94, 22.79]], "batl": [[0, 3.05, 83.46], [1, 3.1, 21.28], [2, 3.2, 2]]}, {"timestamp": 1578742364923, "ltp": 3.0, "tv": 12553.43, "trd": NaN, "batb": [[2, 2.94, 5.82]], "batl": NaN}, {"timestamp": 1578742370958, "ltp": 3.0, "tv": 12565.43, "trd": [[3, 143.14]], "batb": [[0, 2.98, 103.62], [1, 2.94, 5.82], [2, 2.92, 20.62]], "batl": NaN}, {"timestamp": 1578742371960, "ltp": 3.0, "tv": 12565.43, "trd": NaN, "batb": [[0, 2.98, 15.1]], "batl": NaN}, {"timestamp": 1578742375956, "ltp": 2.98, "tv": 12571.43, "trd": [[2.98, 239.72], [3, 143.94]], "batb": [[0, 2.98, 12.1]], "batl": NaN}, {"timestamp": 1578742377932, "ltp": 2.98, "tv": 12571.43, "trd": NaN, "batb": NaN, "batl": [[2, 3.2, 7]]}, {"timestamp": 1578742380918, "ltp": 2.96, "tv": 12616.79, "trd": [[2.96, 1437.23], [2.98, 263.93]], "batb": [[0, 2.96, 1.6], [1, 2.92, 31.75], [2, 2.88, 16.83]], "batl": [[0, 2.98, 87.9], [1, 3.05, 83.46], [2, 3.1, 21.28]]}, {"timestamp": 1578742381830, "ltp": 2.96, "tv": 12616.79, "trd": NaN, "batb": [[0, 2.92, 31.75], [1, 2.88, 16.83], [2, 2.86, 23.04]], "batl": [[0, 2.96, 20.59], [1, 2.98, 87.9], [2, 3.05, 63.47]]}, {"timestamp": 1578742382944, "ltp": 2.96, "tv": 12616.79, "trd": NaN, "batb": [[0, 2.92, 21.56], [1, 2.88, 33.99]], "batl": NaN}, {"timestamp": 1578742383950, "ltp": 2.96, "tv": 12616.79, "trd": NaN, "batb": [[1, 2.88, 20.25]], "batl": NaN}, {"timestamp": 1578742390931, "ltp": 2.96, "tv": 12616.79, "trd": NaN, "batb": [[0, 2.94, 11.53], [1, 2.92, 110.96], [2, 2.88, 20.25]], "batl": NaN}, {"timestamp": 1578742401982, "ltp": 2.96, "tv": 12616.79, "trd": NaN, "batb": [[0, 2.94, 101.24], [1, 2.92, 20.62]], "batl": NaN}, {"timestamp": 1578742402958, "ltp": 2.94, "tv": 12638.79, "trd": [[2.94, 2385.66]], "batb": [[0, 2.94, 90.25]], "batl": NaN}, {"timestamp": 1578742403975, "ltp": 2.94, "tv": 12638.79, "trd": NaN, "batb": [[1, 2.92, 34.51]], "batl": NaN}, {"timestamp": 1578742412973, "ltp": 2.94, "tv": 12638.79, "trd": NaN, "batb": [[0, 2.92, 125.38], [1, 2.88, 34.52], [2, 2.86, 20.04]], "batl": NaN}, {"timestamp": 1578742414968, "ltp": 2.94, "tv": 12638.79, "trd": NaN, "batb": [[0, 2.92, 111.49], [1, 2.88, 48.78]], "batl": NaN}, {"timestamp": 1578742431995, "ltp": 2.94, "tv": 12638.79, "trd": NaN, "batb": NaN, "batl": [[2, 3, 33.5]]}, {"timestamp": 1578742435929, "ltp": 2.94, "tv": 12638.79, "trd": NaN, "batb": NaN, "batl": [[0, 2.96, 34.59]]}, {"timestamp": 1578742519967, "ltp": 2.96, "tv": 12651.62, "trd": [[2.96, 1450.07]], "batb": NaN, "batl": [[0, 2.96, 28.17]]}, {"timestamp": 1578742526993, "ltp": 2.96, "tv": 12651.62, "trd": NaN, "batb": [[2, 2.86, 23.04]], "batl": NaN}, {"timestamp": 1578742554916, "ltp": 2.96, "tv": 12651.62, "trd": NaN, "batb": [[2, 2.86, 73.04]], "batl": NaN}, {"timestamp": 1578742610949, "ltp": 2.92, "tv": 12852.6, "trd": [[2.92, 995.29], [2.94, 2386.72]], "batb": [[0, 2.92, 11.01]], "batl": NaN}, {"timestamp": 1578742612969, "ltp": 2.92, "tv": 12852.6, "trd": NaN, "batb": [[0, 2.88, 48.78], [1, 2.86, 70.04], [2, 2.84, 14.09]], "batl": NaN}, {"timestamp": 1578742613946, "ltp": 2.92, "tv": 12852.6, "trd": NaN, "batb": [[0, 2.9, 14.89], [1, 2.88, 3.09], [2, 2.86, 70.04]], "batl": NaN}, {"timestamp": 1578742614967, "ltp": 2.92, "tv": 12852.6, "trd": NaN, "batb": [[0, 2.9, 11.09], [1, 2.88, 6.92]], "batl": NaN}, {"timestamp": 1578742621977, "ltp": 2.92, "tv": 12852.6, "trd": NaN, "batb": [[0, 2.9, 21]], "batl": NaN}, {"timestamp": 1578742623980, "ltp": 2.92, "tv": 12852.6, "trd": NaN, "batb": [[1, 2.88, 13.93]], "batl": NaN}, {"timestamp": 1578742643966, "ltp": 2.96, "tv": 12868.97, "trd": [[2.96, 1466.45]], "batb": NaN, "batl": [[0, 2.96, 19.98]]}, {"timestamp": 1578742647905, "ltp": 2.96, "tv": 12868.97, "trd": NaN, "batb": [[2, 2.86, 73.04]], "batl": NaN}, {"timestamp": 1578742649707, "ltp": 2.96, "tv": 12868.97, "trd": NaN, "batb": [[1, 2.88, 31.93]], "batl": NaN}, {"timestamp": 1578742694909, "ltp": 2.96, "tv": 12868.97, "trd": NaN, "batb": NaN, "batl": [[0, 2.94, 20], [1, 2.96, 19.98], [2, 2.98, 87.9]]}, {"timestamp": 1578742702917, "ltp": 2.96, "tv": 12868.97, "trd": NaN, "batb": [[0, 2.9, 32.09]], "batl": NaN}, {"timestamp": 1578742704998, "ltp": 2.96, "tv": 12868.97, "trd": NaN, "batb": [[1, 2.88, 13.93]], "batl": NaN}, {"timestamp": 1578742713911, "ltp": 2.88, "tv": 13068.97, "trd": [[2.88, 783.52], [2.9, 633.51]], "batb": [[0, 2.86, 73.04], [1, 2.84, 14.09], [2, 2.82, 25.35]], "batl": NaN}, {"timestamp": 1578742714910, "ltp": 2.88, "tv": 13068.97, "trd": NaN, "batb": [[0, 2.88, 9.4], [1, 2.86, 70.04], [2, 2.84, 33.59]], "batl": NaN}, {"timestamp": 1578742715920, "ltp": 2.88, "tv": 13068.97, "trd": NaN, "batb": [[0, 2.86, 70.04], [1, 2.84, 33.59], [2, 2.82, 25.35]], "batl": NaN}, {"timestamp": 1578742740989, "ltp": 2.88, "tv": 13068.97, "trd": NaN, "batb": NaN, "batl": [[1, 2.96, 28.62]]}, {"timestamp": 1578742754985, "ltp": 2.94, "tv": 13108.97, "trd": [[2.94, 2426.72]], "batb": NaN, "batl": [[0, 2.94, 10.57]]}, {"timestamp": 1578742755993, "ltp": 2.94, "tv": 13108.97, "trd": NaN, "batb": [[0, 2.86, 75.18]], "batl": [[0, 2.96, 28.62], [1, 2.98, 87.9], [2, 3, 33.5]]}, {"timestamp": 1578742761991, "ltp": 2.94, "tv": 13108.97, "trd": NaN, "batb": [[1, 2.84, 46.59]], "batl": NaN}, {"timestamp": 1578742771994, "ltp": 2.86, "tv": 13128.97, "trd": [[2.86, 747.78]], "batb": [[0, 2.86, 65.18]], "batl": [[0, 2.94, 4], [1, 2.96, 28.62], [2, 2.98, 87.9]]}, {"timestamp": 1578742795722, "ltp": 2.86, "tv": 13128.97, "trd": NaN, "batb": NaN, "batl": [[0, 2.9, 39], [1, 2.94, 4], [2, 2.96, 28.62]]}, {"timestamp": 1578742796942, "ltp": 2.86, "tv": 13128.97, "trd": NaN, "batb": [[0, 2.88, 5.42], [1, 2.86, 65.18], [2, 2.84, 46.59]], "batl": NaN}, {"timestamp": 1578742797941, "ltp": 2.86, "tv": 13128.97, "trd": NaN, "batb": NaN, "batl": [[1, 2.94, 10.21]]}, {"timestamp": 1578742798942, "ltp": 2.86, "tv": 13128.97, "trd": NaN, "batb": [[2, 2.84, 27.09]], "batl": NaN}, {"timestamp": 1578742805941, "ltp": 2.86, "tv": 13128.97, "trd": NaN, "batb": NaN, "batl": [[1, 2.94, 6.21]]}, {"timestamp": 1578742810972, "ltp": 2.86, "tv": 13128.97, "trd": NaN, "batb": NaN, "batl": [[2, 2.96, 14.62]]}, {"timestamp": 1578742815961, "ltp": 2.86, "tv": 13128.97, "trd": NaN, "batb": [[2, 2.84, 77.09]], "batl": NaN}, {"timestamp": 1578742846910, "ltp": 2.86, "tv": 13128.97, "trd": NaN, "batb": NaN, "batl": [[1, 2.94, 34.87]]}, {"timestamp": 1578742848913, "ltp": 2.86, "tv": 13128.97, "trd": NaN, "batb": NaN, "batl": [[1, 2.94, 49.19]]}, {"timestamp": 1578742849928, "ltp": 2.86, "tv": 13128.97, "trd": NaN, "batb": NaN, "batl": [[1, 2.92, 6.07], [2, 2.94, 49.19]]}, {"timestamp": 1578742852001, "ltp": 2.86, "tv": 13128.97, "trd": NaN, "batb": NaN, "batl": [[1, 2.92, 20.39]]}, {"timestamp": 1578742873946, "ltp": 2.86, "tv": 13128.97, "trd": NaN, "batb": [[1, 2.86, 15.18]], "batl": NaN}, {"timestamp": 1578742877950, "ltp": 2.88, "tv": 13139.81, "trd": [[2.88, 794.36]], "batb": [[0, 2.86, 15.18], [1, 2.84, 64.09], [2, 2.82, 25.35]], "batl": [[0, 2.88, 5.32], [1, 2.9, 39], [2, 2.92, 20.39]]}, {"timestamp": 1578742878951, "ltp": 2.88, "tv": 13139.81, "trd": NaN, "batb": [[0, 2.86, 23.94]], "batl": NaN}, {"timestamp": 1578742880968, "ltp": 2.88, "tv": 13139.81, "trd": NaN, "batb": [[1, 2.84, 72.05]], "batl": NaN}, {"timestamp": 1578742884948, "ltp": 2.88, "tv": 13139.81, "trd": NaN, "batb": NaN, "batl": [[1, 2.9, 50]]}, {"timestamp": 1578742885957, "ltp": 2.88, "tv": 13139.81, "trd": NaN, "batb": [[1, 2.84, 64.09]], "batl": NaN}, {"timestamp": 1578742906994, "ltp": 2.88, "tv": 13139.81, "trd": NaN, "batb": NaN, "batl": [[0, 2.88, 18.41]]}, {"timestamp": 1578742938930, "ltp": 2.86, "tv": 13187.69, "trd": [[2.86, 795.66]], "batb": [[0, 2.84, 64.09], [1, 2.82, 25.35], [2, 2.8, 14.3]], "batl": [[0, 2.86, 6.06], [1, 2.88, 18.41], [2, 2.9, 50]]}, {"timestamp": 1578742939932, "ltp": 2.86, "tv": 13187.69, "trd": NaN, "batb": [[1, 2.82, 34.01]], "batl": NaN}, {"timestamp": 1578742940854, "ltp": 2.86, "tv": 13187.69, "trd": NaN, "batb": [[1, 2.82, 25.35]], "batl": NaN}, {"timestamp": 1578742957963, "ltp": 2.84, "tv": 13199.81, "trd": [[2.84, 274.17]], "batb": [[0, 2.84, 58.03]], "batl": [[0, 2.88, 18.41], [1, 2.9, 50], [2, 2.92, 6.07]]}, {"timestamp": 1578742967948, "ltp": 2.84, "tv": 13203.81, "trd": [[2.84, 278.17]], "batb": [[0, 2.84, 56.03]], "batl": NaN}, {"timestamp": 1578742978979, "ltp": 2.84, "tv": 13203.81, "trd": NaN, "batb": [[0, 2.84, 6.03]], "batl": NaN}, {"timestamp": 1578742995849, "ltp": 2.84, "tv": 13215.87, "trd": [[2.84, 290.23]], "batb": [[0, 2.82, 25.35], [1, 2.8, 14.3], [2, 2.78, 29.23]], "batl": [[0, 2.88, 19.38]]}, {"timestamp": 1578743001863, "ltp": 2.82, "tv": 13217.81, "trd": [[2.82, 381.96]], "batb": [[0, 2.82, 24.38]], "batl": [[0, 2.88, 18.41]]}, {"timestamp": 1578743014871, "ltp": 2.82, "tv": 13217.81, "trd": NaN, "batb": [[0, 2.82, 29.8], [1, 2.8, 214.3]], "batl": [[0, 2.88, 13.09]]}, {"timestamp": 1578743024872, "ltp": 2.82, "tv": 13237.82, "trd": [[2.82, 401.96]], "batb": [[0, 2.82, 19.79]], "batl": NaN}, {"timestamp": 1578743031002, "ltp": 2.82, "tv": 13237.82, "trd": NaN, "batb": [[0, 2.84, 30], [1, 2.82, 19.79], [2, 2.8, 214.3]], "batl": NaN}, {"timestamp": 1578743040995, "ltp": 2.82, "tv": 13237.82, "trd": NaN, "batb": NaN, "batl": [[0, 2.9, 50], [1, 2.92, 6.07], [2, 2.96, 6]]}, {"timestamp": 1578743041778, "ltp": 2.82, "tv": 13237.82, "trd": NaN, "batb": NaN, "batl": [[0, 2.88, 13.09], [1, 2.9, 50], [2, 2.92, 28.66]]}, {"timestamp": 1578743043985, "ltp": 2.82, "tv": 13237.82, "trd": NaN, "batb": NaN, "batl": [[1, 2.9, 56.11]]}, {"timestamp": 1578743045982, "ltp": 2.82, "tv": 13237.82, "trd": NaN, "batb": NaN, "batl": [[1, 2.9, 70.48]]}, {"timestamp": 1578743049987, "ltp": 2.82, "tv": 13237.82, "trd": NaN, "batb": NaN, "batl": [[0, 2.88, 27.09]]}, {"timestamp": 1578743066936, "ltp": 2.82, "tv": 13237.82, "trd": NaN, "batb": [[1, 2.82, 32.79]], "batl": NaN}, {"timestamp": 1578743068935, "ltp": 2.82, "tv": 13237.82, "trd": NaN, "batb": [[1, 2.82, 82.79]], "batl": NaN}, {"timestamp": 1578743110998, "ltp": 2.82, "tv": 13237.82, "trd": NaN, "batb": [[1, 2.82, 69.79]], "batl": NaN}, {"timestamp": 1578743167982, "ltp": 2.88, "tv": 13238.14, "trd": [[2.88, 794.68]], "batb": NaN, "batl": [[0, 2.88, 26.77]]}, {"timestamp": 1578743168986, "ltp": 2.88, "tv": 13238.14, "trd": NaN, "batb": [[0, 2.86, 8.83], [1, 2.84, 30], [2, 2.82, 69.79]], "batl": NaN}, {"timestamp": 1578743202910, "ltp": 2.88, "tv": 13238.32, "trd": [[2.88, 794.86]], "batb": NaN, "batl": [[0, 2.88, 26.59]]}, {"timestamp": 1578743221985, "ltp": 2.88, "tv": 13246.2, "trd": [[2.88, 802.74]], "batb": [[0, 2.86, 101.06]], "batl": [[0, 2.88, 18.71]]}, {"timestamp": 1578743223951, "ltp": 2.88, "tv": 13246.2, "trd": NaN, "batb": NaN, "batl": [[0, 2.88, 25.63], [1, 2.9, 56.11]]}, {"timestamp": 1578743227932, "ltp": 2.88, "tv": 13246.2, "trd": NaN, "batb": [[0, 2.86, 101.45]], "batl": NaN}, {"timestamp": 1578743235979, "ltp": 2.88, "tv": 13266.2, "trd": [[2.88, 822.74]], "batb": [[0, 2.86, 106.78]], "batl": [[0, 2.88, 15.63]]}, {"timestamp": 1578743236986, "ltp": 2.88, "tv": 13297.46, "trd": [[2.88, 854]], "batb": [[0, 2.88, 34.37], [1, 2.86, 115.55], [2, 2.84, 30]], "batl": [[0, 2.9, 56.11], [1, 2.92, 28.66], [2, 2.94, 3]]}, {"timestamp": 1578743237996, "ltp": 2.88, "tv": 13297.46, "trd": NaN, "batb": NaN, "batl": [[0, 2.9, 50]]}, {"timestamp": 1578743238962, "ltp": 2.88, "tv": 13297.46, "trd": NaN, "batb": NaN, "batl": [[2, 2.94, 9.03]]}, {"timestamp": 1578743239993, "ltp": 2.88, "tv": 13297.46, "trd": NaN, "batb": NaN, "batl": [[2, 2.94, 3]]}, {"timestamp": 1578743243968, "ltp": 2.88, "tv": 13297.46, "trd": NaN, "batb": [[0, 2.88, 125.96], [1, 2.86, 23.32]], "batl": NaN}, {"timestamp": 1578743262945, "ltp": 2.88, "tv": 13497.44, "trd": [[2.88, 1053.98]], "batb": [[0, 2.88, 25.98]], "batl": NaN}, {"timestamp": 1578743272933, "ltp": 2.88, "tv": 13497.44, "trd": NaN, "batb": [[0, 2.86, 49.49], [1, 2.84, 30], [2, 2.82, 83.99]], "batl": NaN}, {"timestamp": 1578743273929, "ltp": 2.88, "tv": 13497.44, "trd": NaN, "batb": [[1, 2.84, 39.36]], "batl": NaN}, {"timestamp": 1578743275959, "ltp": 2.88, "tv": 13497.44, "trd": NaN, "batb": [[0, 2.88, 30], [1, 2.86, 49.49], [2, 2.84, 30]], "batl": NaN}, {"timestamp": 1578743282971, "ltp": 2.88, "tv": 13497.44, "trd": NaN, "batb": [[1, 2.86, 23.32]], "batl": NaN}, {"timestamp": 1578743283977, "ltp": 2.88, "tv": 13497.44, "trd": NaN, "batb": [[0, 2.88, 55.98]], "batl": NaN}, {"timestamp": 1578743300976, "ltp": 2.9, "tv": 13597.44, "trd": [[2.9, 733.51]], "batb": NaN, "batl": [[0, 2.92, 28.66], [1, 2.94, 3], [2, 2.96, 6]]}, {"timestamp": 1578743301905, "ltp": 2.9, "tv": 13597.44, "trd": NaN, "batb": NaN, "batl": [[1, 2.94, 12.98], [2, 2.96, 11.98]]}, {"timestamp": 1578743305983, "ltp": 2.9, "tv": 13597.44, "trd": NaN, "batb": [[1, 2.86, 37.25]], "batl": NaN}, {"timestamp": 1578743317995, "ltp": 2.9, "tv": 13597.44, "trd": NaN, "batb": [[0, 2.88, 80.98]], "batl": NaN}, {"timestamp": 1578743329965, "ltp": 2.9, "tv": 13597.44, "trd": NaN, "batb": [[2, 2.82, 33.99]], "batl": NaN}, {"timestamp": 1578743340978, "ltp": 2.9, "tv": 13597.44, "trd": NaN, "batb": NaN, "batl": [[2, 2.96, 20.69]]}, {"timestamp": 1578743351923, "ltp": 2.9, "tv": 13597.44, "trd": NaN, "batb": [[0, 2.9, 70], [1, 2.88, 80.98], [2, 2.86, 37.25]], "batl": [[0, 2.94, 7.68], [1, 2.96, 20.69], [2, 2.98, 87.9]]}, {"timestamp": 1578743353918, "ltp": 2.9, "tv": 13597.44, "trd": NaN, "batb": [[1, 2.88, 94.07]], "batl": [[0, 2.94, 3], [1, 2.96, 23.04]]}, {"timestamp": 1578743361841, "ltp": 2.9, "tv": 13597.44, "trd": NaN, "batb": [[0, 2.9, 95.8], [1, 2.88, 68.09]], "batl": NaN}, {"timestamp": 1578743366949, "ltp": 2.9, "tv": 13597.44, "trd": NaN, "batb": NaN, "batl": [[1, 2.96, 20.69]]}, {"timestamp": 1578743368947, "ltp": 2.94, "tv": 13603.44, "trd": [[2.94, 2432.72]], "batb": [[0, 2.94, 2], [1, 2.9, 95.8], [2, 2.88, 68.09]], "batl": [[0, 2.96, 20.69], [1, 2.98, 87.9], [2, 3, 33.5]]}, {"timestamp": 1578743369953, "ltp": 2.9, "tv": 13615.44, "trd": [[2.9, 741.51], [2.94, 2436.72]], "batb": [[0, 2.9, 91.8], [1, 2.88, 55], [2, 2.86, 23.32]], "batl": [[0, 2.94, 3.26], [1, 2.96, 20.69], [2, 2.98, 87.9]]}, {"timestamp": 1578743379973, "ltp": 2.9, "tv": 13615.44, "trd": NaN, "batb": [[1, 2.88, 68.92]], "batl": NaN}, {"timestamp": 1578743407902, "ltp": 2.94, "tv": 13621.96, "trd": [[2.94, 2443.24]], "batb": [[0, 2.94, 46.74], [1, 2.9, 91.8], [2, 2.88, 68.92]], "batl": [[0, 2.96, 20.69], [1, 2.98, 87.9], [2, 3, 33.5]]}, {"timestamp": 1578743408818, "ltp": 2.92, "tv": 13778.98, "trd": [[2.9, 797.55], [2.92, 1002.79], [2.94, 2536.72]], "batb": [[0, 2.92, 9.32], [1, 2.9, 63.78]], "batl": NaN}, {"timestamp": 1578743410719, "ltp": 2.92, "tv": 13778.98, "trd": NaN, "batb": [[0, 2.9, 66.94], [1, 2.88, 55], [2, 2.86, 23.32]], "batl": NaN}, {"timestamp": 1578743411916, "ltp": 2.92, "tv": 13778.98, "trd": NaN, "batb": [[0, 2.9, 63.78], [1, 2.88, 69.33]], "batl": NaN}, {"timestamp": 1578743415931, "ltp": 2.92, "tv": 13778.98, "trd": NaN, "batb": [[0, 2.9, 37.98]], "batl": NaN}, {"timestamp": 1578743442794, "ltp": 2.9, "tv": 13788.98, "trd": [[2.9, 807.55]], "batb": [[0, 2.9, 32.98]], "batl": [[0, 2.94, 2], [1, 2.96, 20.69], [2, 2.98, 87.9]]}, {"timestamp": 1578743456900, "ltp": 2.9, "tv": 13788.98, "trd": NaN, "batb": [[2, 2.86, 74.32]], "batl": NaN}, {"timestamp": 1578743461970, "ltp": 2.9, "tv": 13788.98, "trd": NaN, "batb": [[0, 2.88, 69.33], [1, 2.86, 74.32], [2, 2.82, 28.57]], "batl": NaN}, {"timestamp": 1578743464970, "ltp": 2.9, "tv": 13788.98, "trd": NaN, "batb": [[0, 2.9, 25.8], [1, 2.88, 55], [2, 2.86, 88.25]], "batl": NaN}, {"timestamp": 1578743467903, "ltp": 2.9, "tv": 13788.98, "trd": NaN, "batb": [[0, 2.92, 10.62], [1, 2.9, 25.8], [2, 2.88, 63.55]], "batl": NaN}, {"timestamp": 1578743468694, "ltp": 2.9, "tv": 13788.98, "trd": NaN, "batb": [[1, 2.9, 29.48], [2, 2.88, 55]], "batl": NaN}, {"timestamp": 1578743472802, "ltp": 2.94, "tv": 13792.98, "trd": [[2.94, 2540.72]], "batb": [[0, 2.94, 11.72]], "batl": [[0, 2.96, 20.69], [1, 2.98, 87.9], [2, 3, 33.5]]}, {"timestamp": 1578743473914, "ltp": 2.94, "tv": 13792.98, "trd": NaN, "batb": [[1, 2.92, 4.03], [2, 2.9, 29.48]], "batl": NaN}, {"timestamp": 1578743474922, "ltp": 2.94, "tv": 13792.98, "trd": NaN, "batb": [[2, 2.9, 3.68]], "batl": NaN}, {"timestamp": 1578743482917, "ltp": 2.94, "tv": 13816.42, "trd": [[2.94, 2564.16]], "batb": [[0, 2.92, 4.03], [1, 2.9, 3.68], [2, 2.88, 55]], "batl": [[0, 2.94, 18.28], [1, 2.96, 20.69], [2, 2.98, 87.9]]}, {"timestamp": 1578743484931, "ltp": 2.94, "tv": 13816.42, "trd": NaN, "batb": [[0, 2.92, 29.65]], "batl": NaN}, {"timestamp": 1578743485926, "ltp": 2.94, "tv": 13816.42, "trd": NaN, "batb": [[0, 2.92, 25.63], [1, 2.88, 55], [2, 2.86, 60.22]], "batl": NaN}, {"timestamp": 1578743489938, "ltp": 2.94, "tv": 13816.42, "trd": NaN, "batb": [[1, 2.9, 8.49], [2, 2.88, 61.67]], "batl": NaN}, {"timestamp": 1578743495941, "ltp": 2.94, "tv": 13816.42, "trd": NaN, "batb": [[0, 2.9, 8.49], [1, 2.88, 61.67], [2, 2.86, 60.22]], "batl": NaN}, {"timestamp": 1578743497740, "ltp": 2.94, "tv": 13816.42, "trd": NaN, "batb": [[0, 2.88, 55], [1, 2.86, 60.22], [2, 2.82, 28.57]], "batl": NaN}, {"timestamp": 1578743498957, "ltp": 2.94, "tv": 13816.42, "trd": NaN, "batb": [[1, 2.86, 74.15]], "batl": NaN}, {"timestamp": 1578743517835, "ltp": 2.86, "tv": 14016.43, "trd": [[2.86, 885.66], [2.88, 1163.98]], "batb": [[0, 2.86, 29.15], [1, 2.82, 28.57], [2, 2.8, 200]], "batl": NaN}, {"timestamp": 1578743518934, "ltp": 2.86, "tv": 14016.43, "trd": NaN, "batb": [[1, 2.84, 14.44], [2, 2.82, 54.79]], "batl": NaN}, {"timestamp": 1578743521736, "ltp": 2.86, "tv": 14016.43, "trd": NaN, "batb": [[0, 2.86, 15.22], [2, 2.82, 43.01]], "batl": NaN}, {"timestamp": 1578743522928, "ltp": 2.86, "tv": 14016.43, "trd": NaN, "batb": [[0, 2.88, 25.98], [1, 2.86, 15.22], [2, 2.84, 14.44]], "batl": NaN}, {"timestamp": 1578743527946, "ltp": 2.86, "tv": 14016.43, "trd": NaN, "batb": [[1, 2.86, 23.83]], "batl": NaN}, {"timestamp": 1578743534968, "ltp": 2.86, "tv": 14016.43, "trd": NaN, "batb": NaN, "batl": [[0, 2.92, 25], [1, 2.94, 18.28], [2, 2.96, 20.69]]}, {"timestamp": 1578743544962, "ltp": 2.86, "tv": 14016.43, "trd": NaN, "batb": [[0, 2.86, 23.83], [1, 2.84, 14.44], [2, 2.82, 28.57]], "batl": NaN}, {"timestamp": 1578743546982, "ltp": 2.86, "tv": 14016.43, "trd": NaN, "batb": [[0, 2.86, 15.22]], "batl": NaN}, {"timestamp": 1578743547972, "ltp": 2.86, "tv": 14016.43, "trd": NaN, "batb": [[1, 2.84, 5.16]], "batl": NaN}, {"timestamp": 1578743554961, "ltp": 2.86, "tv": 14016.43, "trd": NaN, "batb": NaN, "batl": [[0, 2.94, 18.28], [1, 2.96, 20.69], [2, 2.98, 87.9]]}, {"timestamp": 1578743561904, "ltp": 2.86, "tv": 14016.43, "trd": NaN, "batb": [[1, 2.84, 10.32]], "batl": [[0, 2.96, 20.69], [1, 2.98, 87.9], [2, 3, 33.5]]}, {"timestamp": 1578743564991, "ltp": 2.86, "tv": 14016.43, "trd": NaN, "batb": NaN, "batl": [[0, 2.94, 5.99], [1, 2.96, 20.69], [2, 2.98, 87.9]]}, {"timestamp": 1578743566003, "ltp": 2.86, "tv": 14016.43, "trd": NaN, "batb": [[0, 2.88, 25.98], [1, 2.86, 15.22], [2, 2.84, 10.32]], "batl": NaN}, {"timestamp": 1578743567980, "ltp": 2.86, "tv": 14016.43, "trd": NaN, "batb": [[1, 2.86, 23.21]], "batl": NaN}, {"timestamp": 1578743569717, "ltp": 2.88, "tv": 14068.4, "trd": [[2.88, 1215.95]], "batb": [[0, 2.86, 23.21], [1, 2.84, 10.32], [2, 2.82, 28.57]], "batl": NaN}, {"timestamp": 1578743570913, "ltp": 2.88, "tv": 14068.4, "trd": NaN, "batb": [[0, 2.86, 15.22]], "batl": NaN}, {"timestamp": 1578743588918, "ltp": 2.88, "tv": 14068.4, "trd": NaN, "batb": NaN, "batl": [[0, 2.94, 30.99]]}, {"timestamp": 1578743606922, "ltp": 2.88, "tv": 14068.4, "trd": NaN, "batb": [[0, 2.88, 20], [1, 2.86, 15.22], [2, 2.84, 10.32]], "batl": NaN}, {"timestamp": 1578743607916, "ltp": 2.88, "tv": 14068.4, "trd": NaN, "batb": [[0, 2.88, 40]], "batl": NaN}, {"timestamp": 1578743608963, "ltp": 2.88, "tv": 14068.4, "trd": NaN, "batb": [[0, 2.88, 60]], "batl": NaN}, {"timestamp": 1578743621981, "ltp": 2.9, "tv": 14074.4, "trd": [[2.9, 813.55]], "batb": [[0, 2.9, 7.68], [1, 2.88, 60], [2, 2.86, 29.15]], "batl": NaN}, {"timestamp": 1578743623987, "ltp": 2.9, "tv": 14074.4, "trd": NaN, "batb": [[2, 2.86, 15.22]], "batl": NaN}, {"timestamp": 1578743631885, "ltp": 2.9, "tv": 14074.4, "trd": NaN, "batb": NaN, "batl": [[0, 2.94, 25]]}, {"timestamp": 1578743671762, "ltp": 2.9, "tv": 14089.75, "trd": [[2.9, 828.91]], "batb": [[0, 2.88, 60], [1, 2.86, 15.22], [2, 2.84, 5.16]], "batl": [[0, 2.9, 1.69], [1, 2.94, 25], [2, 2.96, 20.69]]}, {"timestamp": 1578743676956, "ltp": 2.9, "tv": 14089.75, "trd": NaN, "batb": [[1, 2.86, 29.15]], "batl": NaN}, {"timestamp": 1578743678965, "ltp": 2.9, "tv": 14089.75, "trd": NaN, "batb": NaN, "batl": [[2, 2.96, 70.69]]}, {"timestamp": 1578743689902, "ltp": 2.9, "tv": 14091.44, "trd": [[2.9, 830.59]], "batb": NaN, "batl": [[0, 2.94, 25], [1, 2.96, 70.69], [2, 2.98, 87.9]]}, {"timestamp": 1578743735953, "ltp": 2.9, "tv": 14091.44, "trd": NaN, "batb": [[0, 2.9, 9.69], [1, 2.88, 60], [2, 2.86, 29.15]], "batl": NaN}, {"timestamp": 1578743736845, "ltp": 2.9, "tv": 14091.44, "trd": NaN, "batb": [[1, 2.88, 63.38], [2, 2.86, 15.22]], "batl": [[0, 2.92, 10.59], [1, 2.94, 25], [2, 2.96, 70.69]]}, {"timestamp": 1578743792961, "ltp": 2.9, "tv": 14091.44, "trd": NaN, "batb": NaN, "batl": [[2, 2.96, 20.69]]}, {"timestamp": 1578743798945, "ltp": 2.92, "tv": 14117.44, "trd": [[2.92, 1028.79]], "batb": NaN, "batl": [[0, 2.94, 25], [1, 2.96, 20.69], [2, 2.98, 87.9]]}, {"timestamp": 1578743799764, "ltp": 2.9, "tv": 14122.26, "trd": [[2.9, 835.41]], "batb": [[0, 2.9, 7.28]], "batl": NaN}, {"timestamp": 1578743800967, "ltp": 2.9, "tv": 14122.26, "trd": NaN, "batb": [[1, 2.88, 60]], "batl": NaN}, {"timestamp": 1578743839000, "ltp": 2.9, "tv": 14122.26, "trd": NaN, "batb": NaN, "batl": [[0, 2.92, 2], [1, 2.94, 25], [2, 2.96, 20.69]]}, {"timestamp": 1578743840002, "ltp": 2.9, "tv": 14122.26, "trd": NaN, "batb": NaN, "batl": [[0, 2.94, 25], [1, 2.96, 20.69], [2, 2.98, 87.9]]}, {"timestamp": 1578743863968, "ltp": 2.88, "tv": 14142.26, "trd": [[2.88, 1221.39], [2.9, 849.97]], "batb": [[0, 2.88, 57.28], [1, 2.86, 15.22], [2, 2.84, 5.16]], "batl": NaN}, {"timestamp": 1578743864964, "ltp": 2.88, "tv": 14142.26, "trd": NaN, "batb": [[1, 2.86, 17.55]], "batl": NaN}, {"timestamp": 1578743890978, "ltp": 2.88, "tv": 14142.26, "trd": NaN, "batb": [[1, 2.86, 28.31]], "batl": NaN}, {"timestamp": 1578743897003, "ltp": 2.94, "tv": 14144.44, "trd": [[2.94, 2566.34]], "batb": [[0, 2.88, 72.28]], "batl": [[0, 2.94, 22.82]]}, {"timestamp": 1578743897895, "ltp": 2.94, "tv": 14144.44, "trd": NaN, "batb": [[0, 2.88, 82.28]], "batl": NaN}, {"timestamp": 1578743900003, "ltp": 2.94, "tv": 14144.44, "trd": NaN, "batb": NaN, "batl": [[0, 2.96, 43.51], [1, 2.98, 87.9], [2, 3, 33.5]]}, {"timestamp": 1578743937881, "ltp": 2.94, "tv": 14144.44, "trd": NaN, "batb": [[0, 2.92, 10.61], [1, 2.9, 100], [2, 2.88, 82.28]], "batl": NaN}, {"timestamp": 1578743938977, "ltp": 2.9, "tv": 14176.3, "trd": [[2.9, 860.61], [2.92, 1050.01]], "batb": [[0, 2.9, 94.68], [1, 2.88, 82.28], [2, 2.86, 15.22]], "batl": NaN}, {"timestamp": 1578743939978, "ltp": 2.9, "tv": 14176.3, "trd": NaN, "batb": [[1, 2.88, 95.37]], "batl": NaN}, {"timestamp": 1578743993800, "ltp": 2.9, "tv": 14181.3, "trd": [[2.9, 865.61]], "batb": [[0, 2.9, 92.18]], "batl": NaN}, {"timestamp": 1578744011948, "ltp": 2.9, "tv": 14233.3, "trd": [[2.9, 917.61]], "batb": [[0, 2.9, 66.18]], "batl": NaN}, {"timestamp": 1578744055912, "ltp": 2.9, "tv": 14239.3, "trd": [[2.9, 923.61]], "batb": [[0, 2.9, 63.18]], "batl": NaN}, {"timestamp": 1578744062930, "ltp": 2.9, "tv": 14255.26, "trd": [[2.9, 927.63], [2.92, 1061.96]], "batb": [[0, 2.9, 61.17]], "batl": NaN}, {"timestamp": 1578744063935, "ltp": 2.9, "tv": 14259.26, "trd": [[2.9, 931.63]], "batb": [[0, 2.9, 59.17]], "batl": [[0, 2.96, 20.69]]}, {"timestamp": 1578744069916, "ltp": 2.9, "tv": 14259.26, "trd": NaN, "batb": NaN, "batl": [[0, 2.96, 34.69]]}, {"timestamp": 1578744070937, "ltp": 2.96, "tv": 14328.56, "trd": [[2.9, 992.45], [2.96, 1474.92]], "batb": [[0, 2.9, 28.76]], "batl": [[0, 2.96, 26.21]]}, {"timestamp": 1578744072935, "ltp": 2.96, "tv": 14328.56, "trd": NaN, "batb": [[2, 2.86, 18.22]], "batl": NaN}, {"timestamp": 1578744075942, "ltp": 2.92, "tv": 14340.56, "trd": [[2.92, 1073.96]], "batb": NaN, "batl": NaN}, {"timestamp": 1578744076842, "ltp": 2.9, "tv": 14346.56, "trd": [[2.9, 998.45]], "batb": [[0, 2.9, 25.76], [1, 2.88, 84.48]], "batl": NaN}, {"timestamp": 1578744077949, "ltp": 2.9, "tv": 14346.56, "trd": NaN, "batb": [[1, 2.88, 90.81]], "batl": NaN}, {"timestamp": 1578744078952, "ltp": 2.92, "tv": 14356.56, "trd": [[2.92, 1083.96]], "batb": NaN, "batl": [[0, 2.92, 4.56], [1, 2.96, 26.21], [2, 2.98, 87.9]]}, {"timestamp": 1578744084973, "ltp": 2.92, "tv": 14356.56, "trd": NaN, "batb": [[2, 2.86, 15.22]], "batl": NaN}, {"timestamp": 1578744095911, "ltp": 2.88, "tv": 14586.55, "trd": [[2.88, 1399.86], [2.9, 1049.97]], "batb": [[0, 2.88, 1.57], [1, 2.86, 15.22], [2, 2.84, 5.16]], "batl": NaN}, {"timestamp": 1578744096917, "ltp": 2.88, "tv": 14586.55, "trd": NaN, "batb": [[0, 2.88, 8.53], [2, 2.84, 21.3]], "batl": NaN}, {"timestamp": 1578744098886, "ltp": 2.88, "tv": 14586.55, "trd": NaN, "batb": [[0, 2.86, 15.22], [1, 2.84, 5.16], [2, 2.82, 28.57]], "batl": NaN}, {"timestamp": 1578744099914, "ltp": 2.88, "tv": 14586.55, "trd": NaN, "batb": [[1, 2.84, 10.32]], "batl": NaN}, {"timestamp": 1578744115927, "ltp": 2.88, "tv": 14586.55, "trd": NaN, "batb": [[2, 2.82, 38.35]], "batl": [[1, 2.96, 34.85]]}, {"timestamp": 1578744119936, "ltp": 2.88, "tv": 14586.55, "trd": NaN, "batb": NaN, "batl": [[0, 2.9, 2], [1, 2.92, 4.56], [2, 2.96, 34.85]]}, {"timestamp": 1578744122919, "ltp": 2.88, "tv": 14586.55, "trd": NaN, "batb": NaN, "batl": [[0, 2.92, 4.56], [1, 2.96, 34.85], [2, 2.98, 87.9]]}, {"timestamp": 1578744166994, "ltp": 2.86, "tv": 14590.55, "trd": [[2.86, 889.66]], "batb": [[0, 2.86, 13.22]], "batl": NaN}, {"timestamp": 1578744179986, "ltp": 2.86, "tv": 14590.55, "trd": NaN, "batb": [[1, 2.84, 5.16]], "batl": NaN}, {"timestamp": 1578744186909, "ltp": 2.86, "tv": 14590.55, "trd": NaN, "batb": [[1, 2.84, 22.36]], "batl": NaN}, {"timestamp": 1578744229873, "ltp": 2.86, "tv": 14590.55, "trd": NaN, "batb": [[1, 2.84, 17.2]], "batl": NaN}, {"timestamp": 1578744230989, "ltp": 2.82, "tv": 14784.82, "trd": [[2.82, 529.66], [2.84, 324.63], [2.86, 921.83]], "batb": [[0, 2.84, 2.87], [1, 2.8, 200], [2, 2.78, 4.08]], "batl": [[1, 2.94, 1.78], [2, 2.96, 38.05]]}, {"timestamp": 1578744231993, "ltp": 2.82, "tv": 14784.82, "trd": NaN, "batb": NaN, "batl": [[0, 2.86, 5], [1, 2.92, 4.56], [2, 2.96, 34.85]]}, {"timestamp": 1578744232990, "ltp": 2.82, "tv": 14784.82, "trd": NaN, "batb": [[0, 2.8, 200]