{"info": {"id": "1.167206571", "eventId": "29646660", "eventName": "3m Hcap Chs", "marketType": "WIN", "openDate": 1578755763974, "name": "Kemp  11th Jan", "numberOfActiveRunner": 8, "countryCode": "", "sport": "HORSE RACING", "venue": "", "volume": {"total": 1011371.77, "preMatch": 775642.59, "inPlay": 235729.18}, "winner": {"id": 9342038, "name": "Fingerontheswitch", "status": "WINNER", "position": 6}, "delay": 1}, "runners": [{"id": 15729341, "name": "On The Blind Side", "status": "LOSER", "position": 1, "inPlayOdds": 2.94, "inPlayTime": 1578755763974, "avgPrematch": 3.03, "closedOdds": 1000.0, "maxPrematch": 4.0, "minPrematch": 2.76, "maxInPlay": 1000.0, "minInPlay": 2.92, "inPlayIndex": 5025, "lengthOdds": 5392, "lengthOddsPrematch": 5025, "lengthOddsInPlay": 367, "tradedVolume": 538224.6, "preMatchVolume": 474397.17, "inPlayVolume": 63827.43}, {"id": 10997973, "name": "Touch Kick", "status": "LOSER", "position": 2, "inPlayOdds": 6.6, "inPlayTime": 1578755763974, "avgPrematch": 7.08, "closedOdds": 1000.0, "maxPrematch": 8.2, "minPrematch": 5.1, "maxInPlay": 1000.0, "minInPlay": 1.44, "inPlayIndex": 2954, "lengthOdds": 3321, "lengthOddsPrematch": 2954, "lengthOddsInPlay": 367, "tradedVolume": 106484.11, "preMatchVolume": 51426.85, "inPlayVolume": 55057.26}, {"id": 10074266, "name": "Walt", "status": "LOSER", "position": 3, "inPlayOdds": 8.4, "inPlayTime": 1578755763974, "avgPrematch": 7.71, "closedOdds": 1000.0, "maxPrematch": 11.5, "minPrematch": 5.1, "maxInPlay": 1000.0, "minInPlay": 6.0, "inPlayIndex": 3507, "lengthOdds": 3846, "lengthOddsPrematch": 3507, "lengthOddsInPlay": 339, "tradedVolume": 57116.54, "preMatchVolume": 52790.6, "inPlayVolume": 4325.94}, {"id": 12823371, "name": "King of Realms", "status": "LOSER", "position": 4, "inPlayOdds": 11.0, "inPlayTime": 1578755763974, "avgPrematch": 8.8, "closedOdds": 370.0, "maxPrematch": 10.5, "minPrematch": 7.6, "maxInPlay": 1000.0, "minInPlay": 5.0, "inPlayIndex": 3746, "lengthOdds": 4107, "lengthOddsPrematch": 3746, "lengthOddsInPlay": 361, "tradedVolume": 74464.87, "preMatchVolume": 55948.25, "inPlayVolume": 18516.62}, {"id": 8392987, "name": "War Sound", "status": "LOSER", "position": 5, "inPlayOdds": 15.0, "inPlayTime": 1578755763974, "avgPrematch": 9.43, "closedOdds": 1000.0, "maxPrematch": 14.5, "minPrematch": 8.0, "maxInPlay": 1000.0, "minInPlay": 5.4, "inPlayIndex": 3457, "lengthOdds": 3816, "lengthOddsPrematch": 3457, "lengthOddsInPlay": 359, "tradedVolume": 56813.1, "preMatchVolume": 44248.03, "inPlayVolume": 12565.07}, {"id": 9342038, "name": "Fingerontheswitch", "status": "WINNER", "position": 6, "inPlayOdds": 11.0, "inPlayTime": 1578755763974, "avgPrematch": 10.29, "closedOdds": 1.01, "maxPrematch": 15.5, "minPrematch": 7.2, "maxInPlay": 12.0, "minInPlay": 1.01, "inPlayIndex": 2721, "lengthOdds": 3087, "lengthOddsPrematch": 2721, "lengthOddsInPlay": 366, "tradedVolume": 123131.56, "preMatchVolume": 53602.84, "inPlayVolume": 69528.72}, {"id": 15431635, "name": "Mellow Ben", "status": "LOSER", "position": 7, "inPlayOdds": 8.6, "inPlayTime": 1578755763974, "avgPrematch": 24.01, "closedOdds": 1000.0, "maxPrematch": 150.0, "minPrematch": 8.2, "maxInPlay": 1000.0, "minInPlay": 7.0, "inPlayIndex": 2753, "lengthOdds": 3105, "lengthOddsPrematch": 2753, "lengthOddsInPlay": 352, "tradedVolume": 43938.0, "preMatchVolume": 36099.92, "inPlayVolume": 7838.08}, {"id": 8541449, "name": "Minellacelebration", "status": "LOSER", "position": 8, "inPlayOdds": 55.0, "inPlayTime": 1578755763974, "avgPrematch": 42.22, "closedOdds": 1000.0, "maxPrematch": 140.0, "minPrematch": 23.0, "maxInPlay": 1000.0, "minInPlay": 18.0, "inPlayIndex": 1794, "lengthOdds": 2150, "lengthOddsPrematch": 1794, "lengthOddsInPlay": 356, "tradedVolume": 11198.99, "preMatchVolume": 7128.93, "inPlayVolume": 4070.06}], "marketUpdates": [{"timestamp": 1578655257582000000, "openDate": "2020-01-11T12:20:00.000Z", "status": "OPEN", "betDelay": 0, "inPlay": false, "complete": true}, {"timestamp": 1578727933987000000, "openDate": "2020-01-11T12:20:00.000Z", "status": "SUSPENDED", "betDelay": 0, "inPlay": false, "complete": true}, {"timestamp": 1578727934967000000, "openDate": "2020-01-11T12:20:00.000Z", "status": "OPEN", "betDelay": 0, "inPlay": false, "complete": true}, {"timestamp": 1578739082916000000, "openDate": "2020-01-11T12:20:00.000Z", "status": "SUSPENDED", "betDelay": 0, "inPlay": false, "complete": true}, {"timestamp": 1578739083929000000, "openDate": "2020-01-11T12:20:00.000Z", "status": "OPEN", "betDelay": 0, "inPlay": false, "complete": true}, {"timestamp": 1578740899992000000, "openDate": "2020-01-11T12:20:00.000Z", "status": "SUSPENDED", "betDelay": 0, "inPlay": false, "complete": true}, {"timestamp": 1578740900957000000, "openDate": "2020-01-11T12:20:00.000Z", "status": "OPEN", "betDelay": 0, "inPlay": false, "complete": true}, {"timestamp": 1578750783001000000, "openDate": "2020-01-11T12:20:00.000Z", "status": "SUSPENDED", "betDelay": 0, "inPlay": false, "complete": true}, {"timestamp": 1578750783901000000, "openDate": "2020-01-11T12:20:00.000Z", "status": "OPEN", "betDelay": 0, "inPlay": false, "complete": true}, {"timestamp": 1578755762538000000, "openDate": "2020-01-11T12:20:00.000Z", "status": "SUSPENDED", "betDelay": 0, "inPlay": false, "complete": true}, {"timestamp": 1578755763974000000, "openDate": "2020-01-11T12:20:00.000Z", "status": "OPEN", "betDelay": 1, "inPlay": true, "complete": true}, {"timestamp": 1578756131953000000, "openDate": "2020-01-11T12:20:00.000Z", "status": "SUSPENDED", "betDelay": 1, "inPlay": true, "complete": true}, {"timestamp": 1578756323855000000, "openDate": "2020-01-11T12:20:00.000Z", "status": "CLOSED", "betDelay": 1, "inPlay": true, "complete": true}], "odds": [{"runnerId": 15729341, "odds": [{"timestamp": 1578663548566, "ltp": 4.0, "tv": 17.94, "trd": [[4, 13.96], [4.1, 3.98]], "batb": [[0, 3.95, 2.16], [1, 3.9, 1.58], [2, 3.65, 37.97]], "batl": [[0, 4, 16.03], [1, 4.5, 2], [2, 4.6, 1.7]]}, {"timestamp": 1578663553749, "ltp": 4.0, "tv": 17.94, "trd": NaN, "batb": [[2, 3.75, 3]], "batl": NaN}, {"timestamp": 1578663555942, "ltp": 4.0, "tv": 17.94, "trd": NaN, "batb": NaN, "batl": [[0, 4.5, 2], [1, 4.6, 1.7], [2, 4.7, 3]]}, {"timestamp": 1578663567494, "ltp": 3.95, "tv": 22.26, "trd": [[3.95, 4.32]], "batb": [[0, 3.9, 1.58], [1, 3.75, 3], [2, 3.65, 37.97]], "batl": [[0, 3.95, 13.87], [1, 4.5, 2], [2, 4.6, 1.7]]}, {"timestamp": 1578663570483, "ltp": 3.95, "tv": 22.26, "trd": NaN, "batb": NaN, "batl": [[0, 4.5, 2], [1, 4.6, 1.7], [2, 4.7, 3]]}, {"timestamp": 1578663579942, "ltp": 3.75, "tv": 31.42, "trd": [[3.75, 6], [3.9, 3.16]], "batb": [[0, 3.65, 37.97], [1, 3.3, 41.56], [2, 3.25, 15]], "batl": [[0, 3.75, 9.29], [1, 4.5, 2.92]]}, {"timestamp": 1578663581726, "ltp": 3.75, "tv": 31.42, "trd": NaN, "batb": NaN, "batl": [[0, 4.5, 2.92], [1, 4.7, 3], [2, 5, 3]]}, {"timestamp": 1578663613997, "ltp": 3.75, "tv": 31.42, "trd": NaN, "batb": NaN, "batl": [[0, 4.5, 2]]}, {"timestamp": 1578663614955, "ltp": 3.75, "tv": 31.42, "trd": NaN, "batb": [[1, 3.35, 19.18], [2, 3.3, 41.56]], "batl": [[1, 4.6, 16.39], [2, 4.7, 3]]}, {"timestamp": 1578663622981, "ltp": 3.65, "tv": 50.0, "trd": [[3.65, 18.58]], "batb": [[0, 3.65, 28.68]], "batl": NaN}, {"timestamp": 1578663629700, "ltp": 3.65, "tv": 50.0, "trd": NaN, "batb": [[0, 3.65, 36.07]], "batl": NaN}, {"timestamp": 1578663630903, "ltp": 3.65, "tv": 50.0, "trd": NaN, "batb": NaN, "batl": [[0, 4.4, 9.83], [1, 4.5, 2], [2, 4.6, 16.39]]}, {"timestamp": 1578663649903, "ltp": 3.65, "tv": 50.0, "trd": NaN, "batb": [[1, 3.3, 41.56], [2, 3.25, 15]], "batl": NaN}, {"timestamp": 1578663650802, "ltp": 3.65, "tv": 50.0, "trd": NaN, "batb": [[0, 3.7, 13.81], [1, 3.65, 36.07], [2, 3.3, 41.56]], "batl": NaN}, {"timestamp": 1578663669050, "ltp": 3.65, "tv": 50.0, "trd": NaN, "batb": NaN, "batl": [[0, 4.3, 2], [1, 4.4, 9.83], [2, 4.5, 2]]}, {"timestamp": 1578663687989, "ltp": 3.65, "tv": 50.0, "trd": NaN, "batb": NaN, "batl": [[1, 4.5, 2], [2, 4.6, 16.39]]}, {"timestamp": 1578663724854, "ltp": 3.65, "tv": 50.0, "trd": NaN, "batb": [[0, 3.75, 1.98], [1, 3.7, 13.81], [2, 3.65, 36.07]], "batl": NaN}, {"timestamp": 1578663727956, "ltp": 3.65, "tv": 50.0, "trd": NaN, "batb": [[1, 3.65, 36.07], [2, 3.3, 41.56]], "batl": NaN}, {"timestamp": 1578663728642, "ltp": 3.65, "tv": 50.0, "trd": NaN, "batb": [[0, 3.8, 3.95], [1, 3.75, 1.98], [2, 3.65, 36.07]], "batl": NaN}, {"timestamp": 1578663743978, "ltp": 3.65, "tv": 50.0, "trd": NaN, "batb": NaN, "batl": [[0, 4.4, 2]]}, {"timestamp": 1578663744871, "ltp": 3.65, "tv": 50.0, "trd": NaN, "batb": NaN, "batl": [[0, 4.3, 10.06], [1, 4.4, 2], [2, 4.5, 2]]}, {"timestamp": 1578663760903, "ltp": 3.65, "tv": 50.0, "trd": NaN, "batb": [[0, 3.8, 6.34]], "batl": NaN}, {"timestamp": 1578664142389, "ltp": 3.65, "tv": 50.0, "trd": NaN, "batb": [[2, 3.7, 15]], "batl": NaN}, {"timestamp": 1578664164752, "ltp": 3.65, "tv": 50.0, "trd": NaN, "batb": NaN, "batl": [[0, 4.2, 1.6], [1, 4.3, 10.06], [2, 4.4, 2]]}, {"timestamp": 1578664193921, "ltp": 3.65, "tv": 50.0, "trd": NaN, "batb": NaN, "batl": [[2, 4.5, 2]]}, {"timestamp": 1578664194131, "ltp": 3.65, "tv": 50.0, "trd": NaN, "batb": NaN, "batl": [[0, 4.1, 2], [1, 4.2, 1.6], [2, 4.3, 10.06]]}, {"timestamp": 1578664204188, "ltp": 3.65, "tv": 50.0, "trd": NaN, "batb": NaN, "batl": [[2, 4.5, 2]]}, {"timestamp": 1578664338269, "ltp": 3.65, "tv": 50.0, "trd": NaN, "batb": [[0, 3.8, 8.33], [1, 3.7, 15], [2, 3.65, 36.07]], "batl": NaN}, {"timestamp": 1578664361335, "ltp": 3.65, "tv": 50.0, "trd": NaN, "batb": [[0, 3.8, 1.98], [1, 3.75, 6.34], [2, 3.7, 15]], "batl": NaN}, {"timestamp": 1578664394570, "ltp": 3.65, "tv": 50.0, "trd": NaN, "batb": [[0, 3.85, 2.09], [1, 3.8, 1.98]], "batl": NaN}, {"timestamp": 1578664418814, "ltp": 3.65, "tv": 50.0, "trd": NaN, "batb": NaN, "batl": [[0, 4.2, 1.6], [1, 4.5, 2], [2, 4.6, 16.39]]}, {"timestamp": 1578664430930, "ltp": 3.65, "tv": 50.0, "trd": NaN, "batb": NaN, "batl": [[1, 4.4, 9.83], [2, 4.5, 2]]}, {"timestamp": 1578664440770, "ltp": 3.65, "tv": 50.0, "trd": NaN, "batb": NaN, "batl": [[1, 4.3, 32], [2, 4.4, 9.83]]}, {"timestamp": 1578664460575, "ltp": 3.65, "tv": 50.0, "trd": NaN, "batb": NaN, "batl": [[2, 4.5, 2]]}, {"timestamp": 1578664958409, "ltp": 3.65, "tv": 50.0, "trd": NaN, "batb": [[0, 3.85, 4.07], [1, 3.7, 15], [2, 3.65, 36.07]], "batl": NaN}, {"timestamp": 1578665071950, "ltp": 3.65, "tv": 50.0, "trd": NaN, "batb": [[0, 3.85, 8.52]], "batl": NaN}, {"timestamp": 1578665092484, "ltp": 3.65, "tv": 50.0, "trd": NaN, "batb": [[2, 3.65, 39.04]], "batl": NaN}, {"timestamp": 1578665189906, "ltp": 3.65, "tv": 50.0, "trd": NaN, "batb": [[0, 3.85, 1.98], [1, 3.75, 6.53], [2, 3.7, 15]], "batl": NaN}, {"timestamp": 1578665259567, "ltp": 3.65, "tv": 50.0, "trd": NaN, "batb": [[0, 3.9, 2.13], [1, 3.85, 1.98]], "batl": NaN}, {"timestamp": 1578665570772, "ltp": 3.65, "tv": 50.0, "trd": NaN, "batb": [[0, 3.9, 4.11], [1, 3.7, 15], [2, 3.65, 39.04]], "batl": NaN}, {"timestamp": 1578665580958, "ltp": 3.65, "tv": 50.0, "trd": NaN, "batb": [[0, 3.9, 9.01]], "batl": NaN}, {"timestamp": 1578665615675, "ltp": 3.65, "tv": 50.0, "trd": NaN, "batb": [[0, 3.9, 1.98], [1, 3.75, 7.02], [2, 3.7, 15]], "batl": NaN}, {"timestamp": 1578665648146, "ltp": 3.65, "tv": 50.0, "trd": NaN, "batb": [[0, 3.95, 2.26], [1, 3.9, 1.98]], "batl": NaN}, {"timestamp": 1578666186380, "ltp": 3.65, "tv": 50.0, "trd": NaN, "batb": [[0, 3.95, 4.24], [1, 3.7, 15], [2, 3.65, 39.04]], "batl": NaN}, {"timestamp": 1578667166090, "ltp": 3.65, "tv": 50.0, "trd": NaN, "batb": [[2, 3.35, 1.9]], "batl": NaN}, {"timestamp": 1578667196136, "ltp": 3.65, "tv": 50.0, "trd": NaN, "batb": [[2, 3.35, 45.93]], "batl": NaN}, {"timestamp": 1578667935724, "ltp": 3.65, "tv": 50.0, "trd": NaN, "batb": NaN, "batl": [[1, 4.3, 43]]}, {"timestamp": 1578668408860, "ltp": 3.65, "tv": 50.01, "trd": [[3.9, 3.16], [3.95, 4.33], [4, 13.97]], "batb": [[0, 3.95, 4.25]], "batl": NaN}, {"timestamp": 1578668425649, "ltp": 3.95, "tv": 58.51, "trd": [[3.95, 12.83]], "batb": [[0, 3.7, 15], [1, 3.35, 45.93], [2, 3, 51.74]], "batl": [[0, 4.2, 2.35]]}, {"timestamp": 1578668431762, "ltp": 3.95, "tv": 58.51, "trd": NaN, "batb": [[0, 3.75, 55], [1, 3.7, 15], [2, 3.35, 45.93]], "batl": NaN}, {"timestamp": 1578668436678, "ltp": 3.95, "tv": 58.51, "trd": NaN, "batb": [[0, 3.75, 25]], "batl": NaN}, {"timestamp": 1578668442156, "ltp": 3.95, "tv": 58.51, "trd": NaN, "batb": [[0, 3.8, 29], [1, 3.75, 25], [2, 3.7, 15]], "batl": NaN}, {"timestamp": 1578668505591, "ltp": 3.8, "tv": 116.3, "trd": [[3.8, 57.78]], "batb": [[0, 3.75, 25.11], [1, 3.7, 15], [2, 3.35, 45.93]], "batl": NaN}, {"timestamp": 1578668513047, "ltp": 3.8, "tv": 116.52, "trd": [[3.8, 58]], "batb": [[0, 3.75, 25]], "batl": [[0, 3.8, 28.78], [1, 4.2, 2.35], [2, 4.3, 43]]}, {"timestamp": 1578668517841, "ltp": 3.75, "tv": 165.8, "trd": [[3.75, 55.28]], "batb": [[0, 3.7, 15.36], [1, 3.35, 45.93], [2, 3, 51.74]], "batl": NaN}, {"timestamp": 1578668521495, "ltp": 3.75, "tv": 165.8, "trd": NaN, "batb": [[0, 3.7, 15.83]], "batl": NaN}, {"timestamp": 1578668524970, "ltp": 3.75, "tv": 166.52, "trd": [[3.75, 56]], "batb": [[0, 3.7, 15.47]], "batl": [[0, 3.75, 24.29], [1, 3.8, 28.78], [2, 4.2, 2.35]]}, {"timestamp": 1578668533896, "ltp": 3.7, "tv": 197.11, "trd": [[3.7, 30.59]], "batb": [[0, 3.35, 46.1], [1, 3, 51.74], [2, 1.04, 2]], "batl": NaN}, {"timestamp": 1578668538299, "ltp": 3.35, "tv": 288.87, "trd": [[3.35, 91.43], [3.7, 30.93]], "batb": [[0, 3, 51.74], [1, 2.86, 55.63]], "batl": NaN}, {"timestamp": 1578668540804, "ltp": 3.35, "tv": 288.87, "trd": NaN, "batb": [[0, 3.05, 3.36], [1, 3, 51.74], [2, 2.86, 55.63]], "batl": NaN}, {"timestamp": 1578668544526, "ltp": 3.35, "tv": 288.87, "trd": NaN, "batb": [[2, 2.88, 6]], "batl": NaN}, {"timestamp": 1578668547997, "ltp": 3.35, "tv": 288.87, "trd": NaN, "batb": [[0, 3.1, 3.11], [1, 3.05, 3.36], [2, 3, 51.74]], "batl": NaN}, {"timestamp": 1578668550528, "ltp": 3.35, "tv": 288.87, "trd": NaN, "batb": NaN, "batl": [[0, 4.2, 2.35], [1, 4.3, 43], [2, 4.5, 2]]}, {"timestamp": 1578668565143, "ltp": 3.35, "tv": 288.87, "trd": NaN, "batb": NaN, "batl": [[0, 4.1, 11.32], [1, 4.2, 1.6], [2, 4.3, 43]]}, {"timestamp": 1578668584398, "ltp": 3.35, "tv": 288.87, "trd": NaN, "batb": [[0, 3.15, 1.7], [1, 3.1, 3.11], [2, 3.05, 3.36]], "batl": NaN}, {"timestamp": 1578668625903, "ltp": 3.35, "tv": 288.87, "trd": NaN, "batb": [[0, 3.6, 3.81], [1, 3.55, 50], [2, 3.15, 1.7]], "batl": NaN}, {"timestamp": 1578668630929, "ltp": 3.35, "tv": 288.87, "trd": NaN, "batb": [[0, 3.7, 49], [1, 3.6, 3.81], [2, 3.55, 50]], "batl": NaN}, {"timestamp": 1578668636900, "ltp": 3.35, "tv": 288.87, "trd": NaN, "batb": [[0, 3.7, 50.7], [1, 3.6, 7.61]], "batl": NaN}, {"timestamp": 1578668637900, "ltp": 3.7, "tv": 385.75, "trd": [[3.7, 127.81]], "batb": [[0, 3.7, 2.26]], "batl": NaN}, {"timestamp": 1578668642949, "ltp": 3.7, "tv": 393.67, "trd": [[3.7, 135.73]], "batb": [[0, 3.55, 53.2], [1, 3.1, 3.11], [2, 3.05, 3.36]], "batl": [[0, 3.7, 46.18], [1, 4.1, 11.32], [2, 4.2, 1.6]]}, {"timestamp": 1578668644732, "ltp": 3.7, "tv": 393.67, "trd": NaN, "batb": [[0, 3.55, 50], [1, 3.05, 3.36], [2, 3, 51.74]], "batl": NaN}, {"timestamp": 1578668647712, "ltp": 3.7, "tv": 393.67, "trd": NaN, "batb": NaN, "batl": [[0, 3.6, 6.8], [1, 3.7, 46.18], [2, 4.2, 2.35]]}, {"timestamp": 1578668651940, "ltp": 3.7, "tv": 393.67, "trd": NaN, "batb": NaN, "batl": [[0, 3.7, 46.18], [1, 4.2, 2.35], [2, 4.3, 43]]}, {"timestamp": 1578668658335, "ltp": 3.55, "tv": 410.67, "trd": [[3.55, 17]], "batb": [[0, 3.55, 41.5]], "batl": NaN}, {"timestamp": 1578668678453, "ltp": 3.55, "tv": 410.67, "trd": NaN, "batb": [[0, 3.6, 3.81], [1, 3.55, 41.5], [2, 3.05, 3.36]], "batl": [[0, 4.2, 2.35], [1, 4.3, 43], [2, 4.5, 2]]}, {"timestamp": 1578668701544, "ltp": 3.55, "tv": 410.67, "trd": NaN, "batb": NaN, "batl": [[0, 4.1, 11.32], [1, 4.2, 1.6], [2, 4.3, 43]]}, {"timestamp": 1578668702130, "ltp": 3.55, "tv": 410.67, "trd": NaN, "batb": [[0, 3.65, 11.33], [1, 3.6, 3.81], [2, 3.55, 41.5]], "batl": NaN}, {"timestamp": 1578668703939, "ltp": 3.55, "tv": 410.67, "trd": NaN, "batb": [[0, 3.7, 3], [1, 3.65, 11.33], [2, 3.6, 3.81]], "batl": NaN}, {"timestamp": 1578668708164, "ltp": 3.55, "tv": 410.67, "trd": NaN, "batb": [[0, 3.7, 5.88]], "batl": NaN}, {"timestamp": 1578668715503, "ltp": 3.55, "tv": 410.67, "trd": NaN, "batb": NaN, "batl": [[0, 4, 2.75], [1, 4.1, 10.57], [2, 4.2, 1.6]]}, {"timestamp": 1578668728959, "ltp": 3.55, "tv": 410.67, "trd": NaN, "batb": NaN, "batl": [[1, 4.2, 1.6], [2, 4.3, 43]]}, {"timestamp": 1578668731759, "ltp": 3.55, "tv": 410.67, "trd": NaN, "batb": [[0, 3.7, 2.88]], "batl": NaN}, {"timestamp": 1578668764883, "ltp": 3.55, "tv": 410.67, "trd": NaN, "batb": [[0, 3.75, 3.55], [1, 3.7, 2.88]], "batl": NaN}, {"timestamp": 1578668767699, "ltp": 3.55, "tv": 410.67, "trd": NaN, "batb": [[1, 3.6, 7.61], [2, 3.55, 41.5]], "batl": NaN}, {"timestamp": 1578668784754, "ltp": 3.55, "tv": 410.67, "trd": NaN, "batb": NaN, "batl": [[0, 4.1, 2.75]]}, {"timestamp": 1578668793323, "ltp": 3.55, "tv": 410.67, "trd": NaN, "batb": NaN, "batl": [[0, 3.95, 100.75], [1, 4.1, 2], [2, 4.2, 1.6]]}, {"timestamp": 1578668797921, "ltp": 3.55, "tv": 410.67, "trd": NaN, "batb": [[0, 3.6, 7.61], [1, 3.55, 41.5], [2, 3.05, 3.36]], "batl": NaN}, {"timestamp": 1578668799336, "ltp": 3.55, "tv": 410.67, "trd": NaN, "batb": NaN, "batl": [[0, 3.9, 4], [1, 3.95, 100.75], [2, 4.1, 2]]}, {"timestamp": 1578668829987, "ltp": 3.55, "tv": 410.67, "trd": NaN, "batb": NaN, "batl": [[0, 3.85, 6.18], [1, 3.9, 4], [2, 3.95, 100.75]]}, {"timestamp": 1578668830680, "ltp": 3.6, "tv": 422.9, "trd": [[3.6, 12.24]], "batb": [[0, 3.6, 1.5], [2, 3.1, 3.49]], "batl": NaN}, {"timestamp": 1578668840696, "ltp": 3.6, "tv": 422.9, "trd": NaN, "batb": [[0, 3.65, 50], [1, 3.6, 1.5], [2, 3.55, 41.5]], "batl": NaN}, {"timestamp": 1578668843827, "ltp": 3.6, "tv": 422.9, "trd": NaN, "batb": NaN, "batl": [[1, 3.95, 100.75], [2, 4.1, 2]]}, {"timestamp": 1578668846520, "ltp": 3.6, "tv": 422.9, "trd": NaN, "batb": [[1, 3.6, 12.5]], "batl": NaN}, {"timestamp": 1578668852899, "ltp": 3.6, "tv": 422.9, "trd": NaN, "batb": NaN, "batl": [[2, 4.2, 1.6]]}, {"timestamp": 1578668860653, "ltp": 3.6, "tv": 422.9, "trd": NaN, "batb": [[1, 3.6, 11]], "batl": NaN}, {"timestamp": 1578668862659, "ltp": 3.6, "tv": 422.9, "trd": NaN, "batb": NaN, "batl": [[0, 3.95, 100.75], [1, 4, 5.94]]}, {"timestamp": 1578668874973, "ltp": 3.6, "tv": 422.9, "trd": NaN, "batb": NaN, "batl": [[0, 4, 6.69], [1, 4.2, 1.6], [2, 4.3, 43]]}, {"timestamp": 1578668875076, "ltp": 3.6, "tv": 422.9, "trd": NaN, "batb": NaN, "batl": [[1, 4.1, 100], [2, 4.2, 1.6]]}, {"timestamp": 1578668883979, "ltp": 3.6, "tv": 422.9, "trd": NaN, "batb": NaN, "batl": [[1, 4.2, 1.6], [2, 4.3, 43]]}, {"timestamp": 1578668884086, "ltp": 3.6, "tv": 422.9, "trd": NaN, "batb": NaN, "batl": [[0, 3.95, 100.75], [1, 4, 5.94], [2, 4.2, 1.6]]}, {"timestamp": 1578668894750, "ltp": 3.6, "tv": 422.9, "trd": NaN, "batb": NaN, "batl": [[0, 3.9, 4], [1, 3.95, 100.75], [2, 4, 5.94]]}, {"timestamp": 1578668896757, "ltp": 3.65, "tv": 435.31, "trd": [[3.65, 30.98]], "batb": [[0, 3.65, 43.8]], "batl": [[0, 3.85, 6.18], [1, 3.9, 4], [2, 3.95, 100.75]]}, {"timestamp": 1578668929678, "ltp": 3.65, "tv": 435.31, "trd": NaN, "batb": NaN, "batl": [[0, 3.9, 4], [1, 3.95, 100.75], [2, 4, 2.55]]}, {"timestamp": 1578668964947, "ltp": 3.65, "tv": 435.31, "trd": NaN, "batb": NaN, "batl": [[0, 3.85, 6.18], [1, 3.9, 4], [2, 3.95, 100.75]]}, {"timestamp": 1578668965733, "ltp": 3.65, "tv": 447.71, "trd": [[3.65, 43.39]], "batb": [[0, 3.65, 37.6]], "batl": NaN}, {"timestamp": 1578668998761, "ltp": 3.65, "tv": 447.71, "trd": NaN, "batb": NaN, "batl": [[0, 3.9, 4], [1, 3.95, 100.75], [2, 4, 2.55]]}, {"timestamp": 1578669031980, "ltp": 3.65, "tv": 447.71, "trd": NaN, "batb": NaN, "batl": [[0, 3.85, 6.18], [1, 3.9, 4], [2, 3.95, 100.75]]}, {"timestamp": 1578669032352, "ltp": 3.65, "tv": 460.11, "trd": [[3.65, 55.79]], "batb": [[0, 3.65, 31.4]], "batl": NaN}, {"timestamp": 1578669064814, "ltp": 3.65, "tv": 460.11, "trd": NaN, "batb": NaN, "batl": [[0, 3.9, 4], [1, 3.95, 100.75], [2, 4, 2.55]]}, {"timestamp": 1578669096998, "ltp": 3.65, "tv": 460.11, "trd": NaN, "batb": NaN, "batl": [[0, 3.85, 6.18], [1, 3.9, 4], [2, 3.95, 100.75]]}, {"timestamp": 1578669128911, "ltp": 3.6, "tv": 533.53, "trd": [[3.6, 22.86], [3.65, 118.59]], "batb": [[0, 3.6, 5.69], [1, 3.55, 41.5], [2, 3.3, 9]], "batl": [[0, 3.9, 4], [1, 3.95, 100.75], [2, 4, 2.55]]}, {"timestamp": 1578669129429, "ltp": 3.6, "tv": 533.53, "trd": NaN, "batb": NaN, "batl": [[0, 3.8, 2.55], [1, 3.9, 4], [2, 3.95, 100.75]]}, {"timestamp": 1578669133643, "ltp": 3.6, "tv": 543.73, "trd": [[3.6, 33.06]], "batb": [[0, 3.55, 42.09], [1, 3.3, 9], [2, 3.05, 3.36]], "batl": NaN}, {"timestamp": 1578669161915, "ltp": 3.6, "tv": 543.73, "trd": NaN, "batb": NaN, "batl": [[0, 3.9, 4], [1, 3.95, 100.75], [2, 4.2, 1.6]]}, {"timestamp": 1578669162435, "ltp": 3.6, "tv": 543.73, "trd": NaN, "batb": NaN, "batl": [[2, 4, 1.64]]}, {"timestamp": 1578669184035, "ltp": 3.6, "tv": 543.73, "trd": NaN, "batb": NaN, "batl": [[0, 3.85, 2], [1, 3.9, 4], [2, 3.95, 100.75]]}, {"timestamp": 1578669194956, "ltp": 3.6, "tv": 543.73, "trd": NaN, "batb": NaN, "batl": [[0, 3.8, 1.5], [1, 3.85, 2], [2, 3.9, 4]]}, {"timestamp": 1578669227790, "ltp": 3.6, "tv": 543.73, "trd": NaN, "batb": NaN, "batl": [[0, 3.8, 1.87]]}, {"timestamp": 1578669247909, "ltp": 3.6, "tv": 543.73, "trd": NaN, "batb": NaN, "batl": [[1, 3.9, 4], [2, 3.95, 100.75]]}, {"timestamp": 1578669260857, "ltp": 3.6, "tv": 543.73, "trd": NaN, "batb": NaN, "batl": [[0, 3.9, 4], [1, 3.95, 100.75], [2, 4, 1.47]]}, {"timestamp": 1578669294904, "ltp": 3.6, "tv": 543.73, "trd": NaN, "batb": NaN, "batl": [[2, 4.2, 1.6]]}, {"timestamp": 1578669295015, "ltp": 3.6, "tv": 543.73, "trd": NaN, "batb": NaN, "batl": [[0, 3.85, 6.18], [1, 3.9, 4], [2, 3.95, 100.75]]}, {"timestamp": 1578669309748, "ltp": 3.6, "tv": 543.73, "trd": NaN, "batb": [[1, 3.4, 56.05], [2, 3.3, 9]], "batl": NaN}, {"timestamp": 1578669327947, "ltp": 3.6, "tv": 543.73, "trd": NaN, "batb": NaN, "batl": [[0, 3.9, 4], [1, 3.95, 100.75], [2, 4, 2.55]]}, {"timestamp": 1578669328525, "ltp": 3.6, "tv": 543.73, "trd": NaN, "batb": NaN, "batl": [[0, 3.8, 2.55], [1, 3.9, 4], [2, 3.95, 100.75]]}, {"timestamp": 1578669340044, "ltp": 3.6, "tv": 543.73, "trd": NaN, "batb": NaN, "batl": [[1, 3.95, 100.75], [2, 4, 2.55]]}, {"timestamp": 1578669360883, "ltp": 3.6, "tv": 543.73, "trd": NaN, "batb": NaN, "batl": [[0, 3.95, 100.75], [1, 4, 5.94], [2, 4.2, 1.6]]}, {"timestamp": 1578669376135, "ltp": 3.6, "tv": 543.73, "trd": NaN, "batb": NaN, "batl": [[0, 3.9, 2], [1, 3.95, 100.75], [2, 4, 5.94]]}, {"timestamp": 1578669385044, "ltp": 3.6, "tv": 543.73, "trd": NaN, "batb": NaN, "batl": [[0, 3.9, 6]]}, {"timestamp": 1578669393665, "ltp": 3.6, "tv": 543.73, "trd": NaN, "batb": NaN, "batl": [[0, 3.85, 6.18], [1, 3.9, 6], [2, 3.95, 100.75]]}, {"timestamp": 1578669407870, "ltp": 3.6, "tv": 543.73, "trd": NaN, "batb": NaN, "batl": [[0, 3.8, 4], [1, 3.85, 6.18], [2, 3.9, 2]]}, {"timestamp": 1578669426089, "ltp": 3.6, "tv": 543.73, "trd": NaN, "batb": NaN, "batl": [[1, 3.9, 2], [2, 3.95, 100.75]]}, {"timestamp": 1578669430200, "ltp": 3.6, "tv": 543.73, "trd": NaN, "batb": NaN, "batl": [[0, 3.9, 2], [1, 3.95, 100.75], [2, 4, 2.55]]}, {"timestamp": 1578669432823, "ltp": 3.6, "tv": 543.73, "trd": NaN, "batb": [[1, 3.45, 6], [2, 3.4, 56.05]], "batl": NaN}, {"timestamp": 1578669458564, "ltp": 3.6, "tv": 543.73, "trd": NaN, "batb": NaN, "batl": [[0, 3.85, 6.18], [1, 3.9, 2], [2, 3.95, 100.75]]}, {"timestamp": 1578669474670, "ltp": 3.6, "tv": 543.73, "trd": NaN, "batb": NaN, "batl": [[0, 3.8, 4], [1, 3.85, 6.18], [2, 3.9, 2]]}, {"timestamp": 1578669490470, "ltp": 3.6, "tv": 543.73, "trd": NaN, "batb": NaN, "batl": [[1, 3.9, 2], [2, 3.95, 100.75]]}, {"timestamp": 1578669502594, "ltp": 3.6, "tv": 543.73, "trd": NaN, "batb": NaN, "batl": [[0, 3.9, 6], [1, 3.95, 100.75], [2, 4, 2.55]]}, {"timestamp": 1578669523623, "ltp": 3.6, "tv": 543.73, "trd": NaN, "batb": NaN, "batl": [[0, 3.85, 6.18], [1, 3.9, 6], [2, 3.95, 100.75]]}, {"timestamp": 1578669525822, "ltp": 3.6, "tv": 543.73, "trd": NaN, "batb": NaN, "batl": [[0, 3.8, 4], [1, 3.85, 6.18], [2, 3.9, 2]]}, {"timestamp": 1578669541234, "ltp": 3.6, "tv": 543.73, "trd": NaN, "batb": [[0, 3.6, 31.59], [1, 3.55, 41.5], [2, 3.45, 6]], "batl": NaN}, {"timestamp": 1578669555740, "ltp": 3.6, "tv": 543.73, "trd": NaN, "batb": NaN, "batl": [[1, 3.9, 2], [2, 3.95, 100.75]]}, {"timestamp": 1578669568277, "ltp": 3.6, "tv": 543.73, "trd": NaN, "batb": NaN, "batl": [[1, 3.95, 100.75], [2, 4, 2.55]]}, {"timestamp": 1578669569956, "ltp": 3.6, "tv": 543.73, "trd": NaN, "batb": NaN, "batl": [[0, 3.9, 4]]}, {"timestamp": 1578669587963, "ltp": 3.6, "tv": 543.73, "trd": NaN, "batb": NaN, "batl": [[0, 3.85, 6.18], [1, 3.9, 4], [2, 3.95, 100.75]]}, {"timestamp": 1578669620244, "ltp": 3.6, "tv": 543.73, "trd": NaN, "batb": NaN, "batl": [[0, 3.9, 4], [1, 3.95, 100.75], [2, 4, 2.55]]}, {"timestamp": 1578669652770, "ltp": 3.6, "tv": 543.73, "trd": NaN, "batb": NaN, "batl": [[0, 3.85, 6.18], [1, 3.9, 4], [2, 3.95, 100.75]]}, {"timestamp": 1578669685183, "ltp": 3.6, "tv": 543.73, "trd": NaN, "batb": NaN, "batl": [[0, 3.9, 4], [1, 3.95, 100.75], [2, 4, 2.55]]}, {"timestamp": 1578669697498, "ltp": 3.6, "tv": 543.73, "trd": NaN, "batb": NaN, "batl": [[0, 3.85, 2], [1, 3.9, 4], [2, 3.95, 100.75]]}, {"timestamp": 1578669738408, "ltp": 3.6, "tv": 543.73, "trd": NaN, "batb": [[0, 3.65, 13.7], [1, 3.6, 31.59], [2, 3.55, 41.5]], "batl": NaN}, {"timestamp": 1578669761525, "ltp": 3.6, "tv": 543.73, "trd": NaN, "batb": NaN, "batl": [[0, 3.9, 4], [1, 3.95, 100.75], [2, 4, 2.55]]}, {"timestamp": 1578669782637, "ltp": 3.6, "tv": 543.73, "trd": NaN, "batb": NaN, "batl": [[0, 3.85, 6.18], [1, 3.9, 4], [2, 3.95, 100.75]]}, {"timestamp": 1578669814937, "ltp": 3.6, "tv": 543.73, "trd": NaN, "batb": NaN, "batl": [[0, 3.8, 2.55]]}, {"timestamp": 1578669846892, "ltp": 3.6, "tv": 543.73, "trd": NaN, "batb": NaN, "batl": [[0, 3.9, 4], [1, 3.95, 100.75], [2, 4.2, 1.6]]}, {"timestamp": 1578669847797, "ltp": 3.6, "tv": 543.73, "trd": NaN, "batb": NaN, "batl": [[2, 4, 1.64]]}, {"timestamp": 1578669879844, "ltp": 3.6, "tv": 543.73, "trd": NaN, "batb": NaN, "batl": [[2, 4.2, 1.6]]}, {"timestamp": 1578669880269, "ltp": 3.6, "tv": 543.73, "trd": NaN, "batb": NaN, "batl": [[0, 3.85, 6.18], [1, 3.9, 4], [2, 3.95, 100.75]]}, {"timestamp": 1578669912928, "ltp": 3.6, "tv": 543.73, "trd": NaN, "batb": NaN, "batl": [[0, 3.8, 2.55]]}, {"timestamp": 1578669944944, "ltp": 3.6, "tv": 543.73, "trd": NaN, "batb": NaN, "batl": [[0, 3.9, 4], [1, 3.95, 100.75], [2, 4.2, 1.6]]}, {"timestamp": 1578669945430, "ltp": 3.6, "tv": 543.73, "trd": NaN, "batb": NaN, "batl": [[2, 4, 1.64]]}, {"timestamp": 1578669978387, "ltp": 3.6, "tv": 543.73, "trd": NaN, "batb": NaN, "batl": [[0, 3.85, 6.18], [1, 3.9, 4], [2, 3.95, 100.75]]}, {"timestamp": 1578670010900, "ltp": 3.6, "tv": 543.73, "trd": NaN, "batb": NaN, "batl": [[0, 3.9, 4], [1, 3.95, 100.75], [2, 4.2, 1.6]]}, {"timestamp": 1578670011278, "ltp": 3.6, "tv": 543.73, "trd": NaN, "batb": NaN, "batl": [[0, 3.8, 2.55], [1, 3.9, 4], [2, 3.95, 100.75]]}, {"timestamp": 1578670043909, "ltp": 3.6, "tv": 543.73, "trd": NaN, "batb": NaN, "batl": [[0, 3.9, 4], [1, 3.95, 100.75], [2, 4, 1.64]]}, {"timestamp": 1578670094003, "ltp": 3.6, "tv": 543.73, "trd": NaN, "batb": [[1, 3.55, 42.09], [2, 3.45, 6]], "batl": NaN}, {"timestamp": 1578670101827, "ltp": 3.6, "tv": 543.73, "trd": NaN, "batb": NaN, "batl": [[2, 4.2, 1.6]]}, {"timestamp": 1578670102414, "ltp": 3.6, "tv": 543.73, "trd": NaN, "batb": NaN, "batl": [[0, 3.85, 6.18], [1, 3.9, 4], [2, 3.95, 100.75]]}, {"timestamp": 1578670115681, "ltp": 3.85, "tv": 556.09, "trd": [[3.85, 12.36]], "batb": [[0, 3.85, 23.82], [1, 3.65, 13.7], [2, 3.55, 42.09]], "batl": [[0, 3.9, 4], [1, 3.95, 100.75], [2, 4.2, 1.6]]}, {"timestamp": 1578670140443, "ltp": 3.85, "tv": 556.09, "trd": NaN, "batb": NaN, "batl": [[0, 3.95, 100.75], [1, 4.2, 1.6], [2, 4.3, 43]]}, {"timestamp": 1578670412070, "ltp": 3.85, "tv": 556.09, "trd": NaN, "batb": NaN, "batl": [[1, 4, 50], [2, 4.2, 1.6]]}, {"timestamp": 1578670426974, "ltp": 3.85, "tv": 556.09, "trd": NaN, "batb": [[1, 3.55, 42.09], [2, 3.45, 6]], "batl": NaN}, {"timestamp": 1578670432376, "ltp": 3.85, "tv": 556.09, "trd": NaN, "batb": [[0, 3.9, 12.82], [1, 3.85, 23.82], [2, 3.55, 42.09]], "batl": NaN}, {"timestamp": 1578670476636, "ltp": 3.85, "tv": 556.09, "trd": NaN, "batb": NaN, "batl": [[0, 3.95, 10.75]]}, {"timestamp": 1578670482215, "ltp": 3.9, "tv": 562.09, "trd": [[3.9, 9.16]], "batb": [[0, 3.9, 9.82]], "batl": NaN}, {"timestamp": 1578670567334, "ltp": 3.9, "tv": 581.73, "trd": [[3.9, 28.8]], "batb": [[0, 3.85, 23.82], [1, 3.55, 42.09], [2, 3.45, 6]], "batl": [[0, 3.95, 10.93]]}, {"timestamp": 1578670661469, "ltp": 3.85, "tv": 582.09, "trd": [[3.85, 12.72]], "batb": [[0, 3.85, 23.64]], "batl": [[0, 3.95, 10.75]]}, {"timestamp": 1578670676580, "ltp": 3.95, "tv": 603.59, "trd": [[3.95, 34.33]], "batb": [[0, 3.95, 9.25], [1, 3.85, 23.64], [2, 3.55, 42.09]], "batl": [[0, 4, 50], [1, 4.2, 1.6], [2, 4.3, 43]]}, {"timestamp": 1578670709507, "ltp": 3.95, "tv": 603.59, "trd": NaN, "batb": NaN, "batl": [[0, 4, 70]]}, {"timestamp": 1578670740571, "ltp": 4.0, "tv": 643.59, "trd": [[4, 53.97]], "batb": NaN, "batl": [[0, 4, 50]]}, {"timestamp": 1578670863435, "ltp": 4.0, "tv": 649.59, "trd": [[4, 59.97]], "batb": NaN, "batl": [[0, 4, 47]]}, {"timestamp": 1578671051995, "ltp": 3.95, "tv": 667.59, "trd": [[3.95, 52.33]], "batb": [[0, 3.85, 23.89], [1, 3.55, 42.09], [2, 3.45, 6]], "batl": NaN}, {"timestamp": 1578671052474, "ltp": 3.95, "tv": 668.09, "trd": [[3.95, 52.83]], "batb": [[0, 3.85, 23.64]], "batl": NaN}, {"timestamp": 1578671066720, "ltp": 3.95, "tv": 668.09, "trd": NaN, "batb": NaN, "batl": [[0, 4, 27]]}, {"timestamp": 1578671403916, "ltp": 3.95, "tv": 668.09, "trd": NaN, "batb": NaN, "batl": [[0, 3.95, 1.9], [1, 4, 27], [2, 4.2, 1.6]]}, {"timestamp": 1578671421358, "ltp": 3.85, "tv": 685.69, "trd": [[3.85, 30.32]], "batb": [[0, 3.85, 14.84]], "batl": NaN}, {"timestamp": 1578671557497, "ltp": 3.85, "tv": 693.69, "trd": [[3.85, 38.32]], "batb": [[0, 3.85, 10.84]], "batl": NaN}, {"timestamp": 1578671983902, "ltp": 3.85, "tv": 715.37, "trd": [[3.85, 60]], "batb": [[0, 3.55, 42.09], [1, 3.45, 6], [2, 3.4, 56.05]], "batl": [[0, 3.85, 13.16], [1, 3.95, 1.9], [2, 4, 27]]}, {"timestamp": 1578671991940, "ltp": 3.85, "tv": 715.37, "trd": NaN, "batb": NaN, "batl": [[0, 3.8, 11], [1, 3.85, 13.16], [2, 3.95, 1.9]]}, {"timestamp": 1578671999892, "ltp": 3.85, "tv": 715.37, "trd": NaN, "batb": NaN, "batl": [[0, 3.8, 24]]}, {"timestamp": 1578672007942, "ltp": 3.85, "tv": 715.37, "trd": NaN, "batb": [[1, 3.5, 12.02], [2, 3.45, 6]], "batl": [[0, 3.75, 11.23], [1, 3.8, 24], [2, 3.85, 13.16]]}, {"timestamp": 1578672008945, "ltp": 3.55, "tv": 727.44, "trd": [[3.55, 27.89], [3.6, 34.23]], "batb": [[0, 3.55, 36.05]], "batl": NaN}, {"timestamp": 1578672042315, "ltp": 3.55, "tv": 727.44, "trd": NaN, "batb": NaN, "batl": [[0, 3.8, 24], [1, 3.85, 13.16], [2, 3.95, 1.9]]}, {"timestamp": 1578672053133, "ltp": 3.8, "tv": 734.54, "trd": [[3.8, 65.1]], "batb": NaN, "batl": [[0, 3.8, 20.45]]}, {"timestamp": 1578672100759, "ltp": 3.8, "tv": 741.54, "trd": [[3.8, 72.1]], "batb": NaN, "batl": [[0, 3.8, 16.95]]}, {"timestamp": 1578672127885, "ltp": 3.8, "tv": 748.34, "trd": [[3.8, 78.9]], "batb": NaN, "batl": [[0, 3.8, 13.55]]}, {"timestamp": 1578672128884, "ltp": 3.8, "tv": 748.34, "trd": NaN, "batb": [[0, 3.6, 11.69], [1, 3.55, 36.05]], "batl": NaN}, {"timestamp": 1578672322959, "ltp": 3.8, "tv": 748.34, "trd": NaN, "batb": [[0, 3.6, 13.39]], "batl": NaN}, {"timestamp": 1578672341796, "ltp": 3.8, "tv": 748.34, "trd": NaN, "batb": NaN, "batl": [[0, 3.75, 13], [1, 3.8, 13.55], [2, 3.85, 13.16]]}, {"timestamp": 1578672452917, "ltp": 3.8, "tv": 748.34, "trd": NaN, "batb": [[0, 3.6, 1.7]], "batl": NaN}, {"timestamp": 1578672582963, "ltp": 3.6, "tv": 751.74, "trd": [[3.6, 37.63]], "batb": [[0, 3.5, 36.05], [1, 3.45, 6], [2, 3.4, 56.05]], "batl": [[0, 3.6, 4.42], [1, 3.75, 13], [2, 3.8, 13.55]]}, {"timestamp": 1578672583958, "ltp": 3.6, "tv": 751.74, "trd": NaN, "batb": NaN, "batl": [[0, 3.6, 10.54]]}, {"timestamp": 1578672588911, "ltp": 3.6, "tv": 751.74, "trd": NaN, "batb": [[0, 3.5, 26]], "batl": NaN}, {"timestamp": 1578672592904, "ltp": 3.6, "tv": 772.82, "trd": [[3.6, 58.71]], "batb": NaN, "batl": [[0, 3.75, 13], [1, 3.8, 13.55], [2, 3.85, 13.16]]}, {"timestamp": 1578672594892, "ltp": 3.6, "tv": 772.82, "trd": NaN, "batb": [[0, 3.55, 3], [1, 3.5, 26], [2, 3.45, 6]], "batl": NaN}, {"timestamp": 1578672601626, "ltp": 3.75, "tv": 779.82, "trd": [[3.75, 63]], "batb": NaN, "batl": [[0, 3.75, 9.5]]}, {"timestamp": 1578673068137, "ltp": 3.75, "tv": 779.82, "trd": NaN, "batb": [[1, 3.5, 226]], "batl": NaN}, {"timestamp": 1578673190280, "ltp": 3.75, "tv": 786.96, "trd": [[3.75, 70.14]], "batb": NaN, "batl": [[0, 3.75, 5.93]]}, {"timestamp": 1578673212718, "ltp": 3.75, "tv": 786.96, "trd": NaN, "batb": NaN, "batl": [[0, 3.75, 12.93]]}, {"timestamp": 1578673409888, "ltp": 3.75, "tv": 786.96, "trd": NaN, "batb": [[0, 3.6, 2.67], [1, 3.55, 3], [2, 3.5, 226]], "batl": NaN}, {"timestamp": 1578673412916, "ltp": 3.75, "tv": 794.41, "trd": [[3.75, 77.59]], "batb": NaN, "batl": [[0, 3.75, 9.2]]}, {"timestamp": 1578673532649, "ltp": 3.75, "tv": 812.81, "trd": [[3.75, 95.99]], "batb": [[0, 3.75, 10.8], [1, 3.6, 2.67], [2, 3.55, 3]], "batl": [[0, 3.8, 13.55], [1, 3.85, 13.16], [2, 3.95, 1.9]]}, {"timestamp": 1578673540295, "ltp": 3.75, "tv": 812.81, "trd": NaN, "batb": [[2, 3.5, 226]], "batl": NaN}, {"timestamp": 1578673541974, "ltp": 3.75, "tv": 812.81, "trd": NaN, "batb": [[2, 3.55, 6]], "batl": NaN}, {"timestamp": 1578673550897, "ltp": 3.75, "tv": 812.81, "trd": NaN, "batb": [[0, 3.6, 2.67], [1, 3.55, 6], [2, 3.5, 226]], "batl": NaN}, {"timestamp": 1578673556704, "ltp": 3.8, "tv": 830.81, "trd": [[3.8, 96.9]], "batb": NaN, "batl": [[0, 3.8, 4.55]]}, {"timestamp": 1578673590414, "ltp": 3.8, "tv": 830.81, "trd": NaN, "batb": [[0, 3.6, 5.67]], "batl": NaN}, {"timestamp": 1578674162955, "ltp": 3.8, "tv": 830.81, "trd": NaN, "batb": [[0, 3.6, 7.37]], "batl": NaN}, {"timestamp": 1578674176094, "ltp": 3.8, "tv": 830.81, "trd": NaN, "batb": NaN, "batl": [[0, 3.8, 6.45]]}, {"timestamp": 1578674206834, "ltp": 3.8, "tv": 830.81, "trd": NaN, "batb": NaN, "batl": [[0, 3.8, 8.05]]}, {"timestamp": 1578674585890, "ltp": 3.8, "tv": 830.81, "trd": NaN, "batb": [[0, 3.7, 2], [1, 3.6, 7.37], [2, 3.55, 6]], "batl": NaN}, {"timestamp": 1578674656649, "ltp": 3.7, "tv": 834.81, "trd": [[3.7, 139.73]], "batb": [[0, 3.6, 7.37], [1, 3.55, 6], [2, 3.5, 226]], "batl": NaN}, {"timestamp": 1578674811546, "ltp": 3.6, "tv": 848.14, "trd": [[3.6, 72.04]], "batb": [[0, 3.55, 6.71], [1, 3.5, 226], [2, 3.45, 6]], "batl": NaN}, {"timestamp": 1578674889874, "ltp": 3.6, "tv": 848.14, "trd": NaN, "batb": [[1, 3.5, 230]], "batl": NaN}, {"timestamp": 1578675161540, "ltp": 3.6, "tv": 848.14, "trd": NaN, "batb": [[0, 3.7, 3.49], [1, 3.55, 6.71], [2, 3.5, 230]], "batl": NaN}, {"timestamp": 1578675368607, "ltp": 3.7, "tv": 855.12, "trd": [[3.7, 146.71]], "batb": [[0, 3.55, 6.71], [1, 3.5, 230], [2, 3.45, 6]], "batl": [[0, 3.7, 16.51], [1, 3.8, 8.05], [2, 3.85, 13.16]]}, {"timestamp": 1578675374982, "ltp": 3.7, "tv": 855.12, "trd": NaN, "batb": NaN, "batl": [[0, 3.8, 8.05], [1, 3.85, 13.16], [2, 3.95, 1.9]]}, {"timestamp": 1578675406418, "ltp": 3.55, "tv": 868.54, "trd": [[3.55, 39.89], [3.6, 73.46]], "batb": [[0, 3.5, 230], [1, 3.45, 6], [2, 3.4, 56.05]], "batl": [[0, 3.55, 6.29], [1, 3.8, 8.05], [2, 3.85, 13.16]]}, {"timestamp": 1578675415840, "ltp": 3.55, "tv": 868.54, "trd": NaN, "batb": NaN, "batl": [[0, 3.55, 12.29]]}, {"timestamp": 1578675430980, "ltp": 3.55, "tv": 868.54, "trd": NaN, "batb": NaN, "batl": [[0, 3.55, 6]]}, {"timestamp": 1578675431083, "ltp": 3.55, "tv": 869.96, "trd": [[3.55, 41.31]], "batb": NaN, "batl": [[0, 3.55, 5.29]]}, {"timestamp": 1578675432351, "ltp": 3.5, "tv": 909.96, "trd": [[3.5, 40]], "batb": [[0, 3.5, 210]], "batl": [[0, 3.75, 5.29]]}, {"timestamp": 1578675439724, "ltp": 3.5, "tv": 923.96, "trd": [[3.5, 54]], "batb": [[0, 3.5, 203]], "batl": NaN}, {"timestamp": 1578675442427, "ltp": 3.5, "tv": 935.87, "trd": [[3.5, 65.91]], "batb": [[0, 3.5, 197.04]], "batl": NaN}, {"timestamp": 1578675455635, "ltp": 3.6, "tv": 960.11, "trd": [[3.6, 97.7]], "batb": NaN, "batl": [[0, 3.6, 2.88], [1, 3.75, 5.29], [2, 3.8, 8.05]]}, {"timestamp": 1578675462421, "ltp": 3.6, "tv": 960.11, "trd": NaN, "batb": NaN, "batl": [[0, 3.55, 5.29], [1, 3.6, 2.88]]}, {"timestamp": 1578675465551, "ltp": 3.55, "tv": 970.69, "trd": [[3.55, 51.89]], "batb": NaN, "batl": [[0, 3.6, 2.88], [1, 3.8, 8.05], [2, 3.85, 13.16]]}, {"timestamp": 1578675470138, "ltp": 3.55, "tv": 970.69, "trd": NaN, "batb": NaN, "batl": [[1, 3.8, 25.05]]}, {"timestamp": 1578675502009, "ltp": 3.5, "tv": 1098.25, "trd": [[3.5, 193.46]], "batb": [[0, 3.5, 133.22]], "batl": NaN}, {"timestamp": 1578675503309, "ltp": 3.5, "tv": 1104.25, "trd": [[3.5, 199.46]], "batb": [[0, 3.5, 130.22]], "batl": NaN}, {"timestamp": 1578675538350, "ltp": 3.5, "tv": 1104.25, "trd": NaN, "batb": NaN, "batl": [[0, 3.6, 32.88]]}, {"timestamp": 1578675560845, "ltp": 3.5, "tv": 1104.25, "trd": NaN, "batb": [[2, 3.35, 49]], "batl": NaN}, {"timestamp": 1578675564726, "ltp": 3.5, "tv": 1104.25, "trd": NaN, "batb": [[1, 3.35, 49], [2, 3.3, 9]], "batl": NaN}, {"timestamp": 1578675568735, "ltp": 3.5, "tv": 1136.25, "trd": [[3.5, 231.46]], "batb": [[0, 3.5, 114.22]], "batl": NaN}, {"timestamp": 1578675610988, "ltp": 3.5, "tv": 1136.93, "trd": [[3.35, 91.51], [3.5, 231.59], [3.55, 51.92], [3.6, 97.78], [3.65, 118.68], [3.7, 146.84], [3.75, 96.05], [3.8, 96.96], [3.85, 60.01], [3.95, 52.84], [4, 59.97]], "batb": NaN, "batl": NaN}, {"timestamp": 1578675624920, "ltp": 3.5, "tv": 1136.93, "trd": NaN, "batb": NaN, "batl": [[0, 3.6, 24.88]]}, {"timestamp": 1578675647844, "ltp": 3.5, "tv": 1136.93, "trd": NaN, "batb": NaN, "batl": [[0, 3.55, 22], [1, 3.6, 2.88], [2, 3.8, 25.05]]}, {"timestamp": 1578675756770, "ltp": 3.5, "tv": 1136.93, "trd": NaN, "batb": NaN, "batl": [[0, 3.6, 24.88], [1, 3.8, 25.05], [2, 3.85, 13.16]]}, {"timestamp": 1578675760979, "ltp": 3.5, "tv": 1136.93, "trd": NaN, "batb": NaN, "batl": [[0, 3.6, 14.88]]}, {"timestamp": 1578675896461, "ltp": 3.5, "tv": 1140.93, "trd": [[3.5, 235.59]], "batb": [[0, 3.5, 112.22]], "batl": NaN}, {"timestamp": 1578675932879, "ltp": 3.5, "tv": 1140.93, "trd": NaN, "batb": NaN, "batl": [[0, 3.6, 2.88]]}, {"timestamp": 1578676042968, "ltp": 3.5, "tv": 1140.93, "trd": NaN, "batb": NaN, "batl": [[1, 3.75, 1.9], [2, 3.8, 25.05]]}, {"timestamp": 1578676108779, "ltp": 3.5, "tv": 1140.93, "trd": NaN, "batb": NaN, "batl": [[2, 3.8, 8.05]]}, {"timestamp": 1578676251520, "ltp": 3.5, "tv": 1140.93, "trd": NaN, "batb": [[0, 3.5, 312.22]], "batl": NaN}, {"timestamp": 1578676426634, "ltp": 3.5, "tv": 1140.93, "trd": NaN, "batb": [[0, 3.55, 2.12], [1, 3.5, 312.22], [2, 3.35, 49]], "batl": NaN}, {"timestamp": 1578676440737, "ltp": 3.5, "tv": 1180.93, "trd": [[3.5, 271.35], [3.55, 56.16]], "batb": [[0, 3.5, 294.34], [1, 3.35, 49], [2, 3.3, 9]], "batl": NaN}, {"timestamp": 1578676538935, "ltp": 3.5, "tv": 1180.93, "trd": NaN, "batb": [[0, 3.5, 296.04]], "batl": NaN}, {"timestamp": 1578676995594, "ltp": 3.5, "tv": 1180.93, "trd": NaN, "batb": [[0, 3.55, 5.83], [1, 3.5, 296.04], [2, 3.35, 49]], "batl": NaN}, {"timestamp": 1578677060832, "ltp": 3.5, "tv": 1180.93, "trd": NaN, "batb": [[0, 3.55, 7.53], [1, 3.5, 294.34]], "batl": NaN}, {"timestamp": 1578677442894, "ltp": 3.5, "tv": 1180.93, "trd": NaN, "batb": NaN, "batl": [[2, 3.8, 28.5]]}, {"timestamp": 1578677492586, "ltp": 3.55, "tv": 1195.98, "trd": [[3.55, 71.21]], "batb": [[0, 3.5, 294.34], [1, 3.35, 49], [2, 3.3, 9]], "batl": [[0, 3.55, 77.61], [1, 3.6, 2.88], [2, 3.75, 1.9]]}, {"timestamp": 1578677545032, "ltp": 3.55, "tv": 1195.98, "trd": NaN, "batb": NaN, "batl": [[0, 3.55, 118.61]]}, {"timestamp": 1578677555069, "ltp": 3.55, "tv": 1195.98, "trd": NaN, "batb": [[0, 3.5, 296.04]], "batl": NaN}, {"timestamp": 1578677556848, "ltp": 3.55, "tv": 1195.98, "trd": NaN, "batb": NaN, "batl": [[0, 3.55, 77.61]]}, {"timestamp": 1578677571297, "ltp": 3.5, "tv": 1279.98, "trd": [[3.5, 355.35]], "batb": [[0, 3.5, 254.04]], "batl": NaN}, {"timestamp": 1578677580865, "ltp": 3.5, "tv": 1279.98, "trd": NaN, "batb": NaN, "batl": [[1, 3.6, 14.88]]}, {"timestamp": 1578677603418, "ltp": 3.5, "tv": 1787.98, "trd": [[3.5, 863.35]], "batb": [[0, 3.35, 49.04], [1, 3.3, 9], [2, 3.05, 3.36]], "batl": NaN}, {"timestamp": 1578677644851, "ltp": 3.5, "tv": 1788.07, "trd": [[3.5, 863.43]], "batb": [[0, 3.35, 49]], "batl": [[0, 3.5, 5.67], [1, 3.55, 77.61], [2, 3.6, 14.88]]}, {"timestamp": 1578677647457, "ltp": 3.5, "tv": 1788.07, "trd": NaN, "batb": NaN, "batl": [[0, 3.5, 20.67]]}, {"timestamp": 1578677686785, "ltp": 3.35, "tv": 1838.07, "trd": [[3.35, 141.51]], "batb": [[0, 3.35, 24]], "batl": NaN}, {"timestamp": 1578677698803, "ltp": 3.35, "tv": 1849.93, "trd": [[3.35, 153.37]], "batb": [[0, 3.35, 18.07]], "batl": [[0, 3.5, 15]]}, {"timestamp": 1578677742059, "ltp": 3.35, "tv": 1886.07, "trd": [[3.35, 189.51]], "batb": [[0, 3.3, 9], [1, 3.05, 3.36], [2, 3, 67.26]], "batl": [[0, 3.35, 1.13], [1, 3.5, 15], [2, 3.55, 77.61]]}, {"timestamp": 1578677744254, "ltp": 3.35, "tv": 1888.33, "trd": [[3.35, 191.77]], "batb": [[0, 3.3, 9.87]], "batl": [[0, 3.5, 15], [1, 3.55, 77.61], [2, 3.6, 14.88]]}, {"timestamp": 1578677759957, "ltp": 3.3, "tv": 1898.33, "trd": [[3.3, 8.26], [3.35, 193.51]], "batb": [[0, 3.3, 4.87]], "batl": NaN}, {"timestamp": 1578677884326, "ltp": 3.3, "tv": 1898.33, "trd": NaN, "batb": NaN, "batl": [[0, 3.5, 18]]}, {"timestamp": 1578677886120, "ltp": 3.3, "tv": 1898.33, "trd": NaN, "batb": NaN, "batl": [[0, 3.45, 3], [1, 3.5, 15], [2, 3.55, 77.61]]}, {"timestamp": 1578677887117, "ltp": 3.3, "tv": 1898.33, "trd": NaN, "batb": NaN, "batl": [[0, 3.5, 15], [1, 3.55, 77.61], [2, 3.6, 14.88]]}, {"timestamp": 1578677919041, "ltp": 3.3, "tv": 1898.33, "trd": NaN, "batb": [[1, 3.1, 6.45], [2, 3.05, 3.36]], "batl": NaN}, {"timestamp": 1578677968681, "ltp": 3.5, "tv": 1918.45, "trd": [[3.5, 883.55]], "batb": NaN, "batl": [[0, 3.5, 4.94]]}, {"timestamp": 1578678057968, "ltp": 3.5, "tv": 1918.45, "trd": NaN, "batb": [[0, 3.4, 25.66], [1, 3.3, 4.87], [2, 3.1, 6.45]], "batl": NaN}, {"timestamp": 1578678063990, "ltp": 3.55, "tv": 1968.44, "trd": [[3.5, 893.43], [3.55, 111.33]], "batb": NaN, "batl": [[0, 3.55, 57.55], [1, 3.6, 14.88], [2, 3.75, 1.9]]}, {"timestamp": 1578678085584, "ltp": 3.55, "tv": 1968.44, "trd": NaN, "batb": [[2, 3.05, 3.36]], "batl": NaN}, {"timestamp": 1578678122960, "ltp": 3.55, "tv": 2058.59, "trd": [[3.55, 201.47]], "batb": NaN, "batl": [[0, 3.55, 12.48]]}, {"timestamp": 1578678174364, "ltp": 3.4, "tv": 2105.13, "trd": [[3.4, 46.54]], "batb": [[0, 3.4, 2.39]], "batl": NaN}, {"timestamp": 1578678177676, "ltp": 3.4, "tv": 2105.13, "trd": NaN, "batb": [[2, 3.05, 13.41]], "batl": NaN}, {"timestamp": 1578678197795, "ltp": 3.4, "tv": 2105.13, "trd": NaN, "batb": [[1, 3.35, 5.97], [2, 3.3, 4.87]], "batl": NaN}, {"timestamp": 1578678428320, "ltp": 3.4, "tv": 2105.13, "trd": NaN, "batb": NaN, "batl": [[1, 3.6, 16.88]]}, {"timestamp": 1578678473694, "ltp": 3.4, "tv": 2109.91, "trd": [[3.4, 51.32]], "batb": [[0, 3.35, 5.97], [1, 3.3, 4.87], [2, 3.05, 3.36]], "batl": [[0, 3.4, 1.61], [1, 3.55, 12.48], [2, 3.6, 16.88]]}, {"timestamp": 1578678476179, "ltp": 3.4, "tv": 2111.99, "trd": [[3.4, 53.4]], "batb": NaN, "batl": [[0, 3.55, 13.05], [1, 3.6, 16.88], [2, 3.75, 1.9]]}, {"timestamp": 1578678520624, "ltp": 3.4, "tv": 2111.99, "trd": NaN, "batb": [[0, 3.3, 4.87], [1, 3.05, 3.36], [2, 3, 140.37]], "batl": NaN}, {"timestamp": 1578678523116, "ltp": 3.4, "tv": 2111.99, "trd": NaN, "batb": [[1, 3.05, 13.79]], "batl": NaN}, {"timestamp": 1578678627228, "ltp": 3.4, "tv": 2111.99, "trd": NaN, "batb": [[1, 3.1, 6.45], [2, 3.05, 13.79]], "batl": NaN}, {"timestamp": 1578678638966, "ltp": 3.4, "tv": 2111.99, "trd": NaN, "batb": [[1, 3.15, 2.83], [2, 3.1, 6.45]], "batl": [[0, 3.5, 3.12], [1, 3.55, 12.48], [2, 3.6, 16.88]]}, {"timestamp": 1578678664049, "ltp": 3.4, "tv": 2111.99, "trd": NaN, "batb": [[0, 3.3, 16.87]], "batl": NaN}, {"timestamp": 1578678682184, "ltp": 3.4, "tv": 2111.99, "trd": NaN, "batb": [[2, 3.05, 3.36]], "batl": NaN}, {"timestamp": 1578678700002, "ltp": 3.4, "tv": 2111.99, "trd": NaN, "batb": [[0, 3.35, 5], [1, 3.3, 16.87], [2, 3.15, 2.83]], "batl": NaN}, {"timestamp": 1578678787914, "ltp": 3.4, "tv": 2111.99, "trd": NaN, "batb": [[1, 3.3, 96.87]], "batl": NaN}, {"timestamp": 1578678807924, "ltp": 3.4, "tv": 2111.99, "trd": NaN, "batb": [[2, 3.05, 3.36]], "batl": [[0, 3.55, 13.05], [1, 3.6, 16.88], [2, 3.75, 1.9]]}, {"timestamp": 1578678970522, "ltp": 3.4, "tv": 2111.99, "trd": NaN, "batb": [[0, 3.35, 10.97]], "batl": NaN}, {"timestamp": 1578679013862, "ltp": 3.4, "tv": 2111.99, "trd": NaN, "batb": [[0, 3.35, 15.97]], "batl": NaN}, {"timestamp": 1578679034188, "ltp": 3.4, "tv": 2111.99, "trd": NaN, "batb": [[0, 3.35, 10]], "batl": NaN}, {"timestamp": 1578679107626, "ltp": 3.55, "tv": 2137.98, "trd": [[3.4, 54.54], [3.55, 226.33]], "batb": NaN, "batl": [[0, 3.6, 16.93], [1, 3.75, 1.9], [2, 3.8, 28.5]]}, {"timestamp": 1578679137769, "ltp": 3.6, "tv": 2153.97, "trd": [[3.55, 226.43], [3.6, 113.66]], "batb": NaN, "batl": [[0, 3.6, 8.94]]}, {"timestamp": 1578679143753, "ltp": 3.6, "tv": 2153.97, "trd": NaN, "batb": [[0, 3.4, 5.88], [1, 3.35, 10], [2, 3.3, 96.87]], "batl": NaN}, {"timestamp": 1578679265998, "ltp": 3.6, "tv": 2153.97, "trd": NaN, "batb": [[0, 3.4, 10.88], [1, 3.35, 5]], "batl": NaN}, {"timestamp": 1578679274508, "ltp": 3.6, "tv": 2153.97, "trd": NaN, "batb": [[2, 3.3, 89.87]], "batl": NaN}, {"timestamp": 1578679288744, "ltp": 3.6, "tv": 2153.97, "trd": NaN, "batb": [[1, 3.35, 10], [2, 3.3, 84.87]], "batl": NaN}, {"timestamp": 1578679338970, "ltp": 3.6, "tv": 2153.97, "trd": NaN, "batb": NaN, "batl": [[1, 3.75, 3.9]]}, {"timestamp": 1578679344906, "ltp": 3.6, "tv": 2153.97, "trd": NaN, "batb": NaN, "batl": [[1, 3.7, 2], [2, 3.75, 3.9]]}, {"timestamp": 1578679352327, "ltp": 3.6, "tv": 2153.97, "trd": NaN, "batb": NaN, "batl": [[1, 3.65, 2], [2, 3.7, 2]]}, {"timestamp": 1578679359920, "ltp": 3.4, "tv": 2157.97, "trd": [[3.4, 58.54]], "batb": [[0, 3.4, 8.88]], "batl": NaN}, {"timestamp": 1578679387557, "ltp": 3.4, "tv": 2157.97, "trd": NaN, "batb": [[0, 3.5, 5.12], [1, 3.4, 8.88], [2, 3.35, 10]], "batl": NaN}, {"timestamp": 1578679426166, "ltp": 3.4, "tv": 2157.97, "trd": NaN, "batb": [[1, 3.4, 5]], "batl": NaN}, {"timestamp": 1578679431471, "ltp": 3.4, "tv": 2178.21, "trd": [[3.4, 68.54], [3.5, 903.67]], "batb": [[0, 3.35, 10], [1, 3.3, 84.87], [2, 3.05, 3.36]], "batl": [[0, 3.4, 29.88], [1, 3.6, 8.94], [2, 3.65, 2]]}, {"timestamp": 1578679435804, "ltp": 3.4, "tv": 2179.55, "trd": [[3.4, 69.88]], "batb": NaN, "batl": [[0, 3.4, 29.21]]}, {"timestamp": 1578679440865, "ltp": 3.4, "tv": 2180.89, "trd": [[3.4, 71.22]], "batb": NaN, "batl": [[0, 3.4, 28.54]]}, {"timestamp": 1578679442671, "ltp": 3.4, "tv": 2181.29, "trd": [[3.4, 71.62]], "batb": NaN, "batl": [[0, 3.4, 28.34]]}, {"timestamp": 1578679451501, "ltp": 3.4, "tv": 2181.29, "trd": NaN, "batb": NaN, "batl": [[0, 3.6, 8.94], [1, 3.65, 2], [2, 3.7, 2]]}, {"timestamp": 1578679468730, "ltp": 3.4, "tv": 2181.29, "trd": NaN, "batb": NaN, "batl": [[0, 3.6, 28.94]]}, {"timestamp": 1578679492670, "ltp": 3.35, "tv": 2201.29, "trd": [[3.35, 213.51]], "batb": [[0, 3.3, 84.87], [1, 3.05, 3.36], [2, 3, 140.37]], "batl": [[0, 3.35, 20], [1, 3.6, 28.94], [2, 3.65, 2]]}, {"timestamp": 1578679494901, "ltp": 3.35, "tv": 2201.53, "trd": [[3.35, 213.75]], "batb": NaN, "batl": [[0, 3.35, 19.88]]}, {"timestamp": 1578679499008, "ltp": 3.35, "tv": 2201.77, "trd": [[3.35, 213.99]], "batb": NaN, "batl": [[0, 3.35, 19.76]]}, {"timestamp": 1578679507522, "ltp": 3.35, "tv": 2231.77, "trd": [[3.35, 243.99]], "batb": NaN, "batl": [[0, 3.35, 4.76]]}, {"timestamp": 1578679556207, "ltp": 3.35, "tv": 2234.51, "trd": [[3.35, 246.73]], "batb": NaN, "batl": [[0, 3.35, 3.39]]}, {"timestamp": 1578679558604, "ltp": 3.35, "tv": 2236.31, "trd": [[3.35, 248.53]], "batb": NaN, "batl": [[0, 3.35, 2.49]]}, {"timestamp": 1578679560993, "ltp": 3.35, "tv": 2238.11, "trd": [[3.35, 250.33]], "batb": NaN, "batl": [[0, 3.35, 1.59]]}, {"timestamp": 1578679566697, "ltp": 3.35, "tv": 2241.29, "trd": [[3.35, 253.51]], "batb": [[0, 3.35, 1.41], [1, 3.3, 84.87], [2, 3.05, 3.36]], "batl": [[0, 3.6, 28.94], [1, 3.65, 2], [2, 3.7, 2]]}, {"timestamp": 1578679588936, "ltp": 3.35, "tv": 2241.29, "trd": NaN, "batb": [[0, 3.35, 3.39]], "batl": NaN}, {"timestamp": 1578679602889, "ltp": 3.35, "tv": 2241.29, "trd": NaN, "batb": NaN, "batl": [[0, 3.4, 45], [1, 3.6, 28.94], [2, 3.65, 2]]}, {"timestamp": 1578679605795, "ltp": 3.4, "tv": 2241.83, "trd": [[3.4, 72.16]], "batb": NaN, "batl": [[0, 3.4, 44.73]]}, {"timestamp": 1578679607582, "ltp": 3.4, "tv": 2242.37, "trd": [[3.4, 72.7]], "batb": NaN, "batl": [[0, 3.4, 44.46]]}, {"timestamp": 1578679609868, "ltp": 3.4, "tv": 2242.57, "trd": [[3.4, 72.9]], "batb": NaN, "batl": [[0, 3.4, 44.36]]}, {"timestamp": 1578679612178, "ltp": 3.4, "tv": 2242.77, "trd": [[3.4, 73.1]], "batb": NaN, "batl": [[0, 3.4, 44.26]]}, {"timestamp": 1578679825628, "ltp": 3.35, "tv": 2249.55, "trd": [[3.35, 260.3]], "batb": [[0, 3.3, 84.87], [1, 3.05, 3.36], [2, 3, 73.11]], "batl": [[0, 3.35, 46.61], [1, 3.4, 44.26], [2, 3.6, 28.94]]}, {"timestamp": 1578679924840, "ltp": 3.35, "tv": 2249.55, "trd": NaN, "batb": [[2, 3, 65]], "batl": NaN}, {"timestamp": 1578679946363, "ltp": 3.35, "tv": 2312.61, "trd": [[3.35, 323.36]], "batb": NaN, "batl": [[0, 3.35, 15.08]]}, {"timestamp": 1578680125798, "ltp": 3.3, "tv": 2392.61, "trd": [[3.3, 88.26]], "batb": [[0, 3.3, 44.87]], "batl": NaN}, {"timestamp": 1578680217111, "ltp": 3.3, "tv": 2392.61, "trd": NaN, "batb": [[1, 3.25, 500], [2, 3.05, 3.36]], "batl": NaN}, {"timestamp": 1578680219535, "ltp": 3.35, "tv": 2422.77, "trd": [[3.35, 353.52]], "batb": [[0, 3.35, 4.3], [1, 3.3, 54.81], [2, 3.25, 500]], "batl": [[0, 3.4, 44.26], [1, 3.6, 28.94], [2, 3.65, 2]]}, {"timestamp": 1578680307407, "ltp": 3.35, "tv": 2422.77, "trd": NaN, "batb": [[1, 3.3, 254.81]], "batl": NaN}, {"timestamp": 1578680426025, "ltp": 3.4, "tv": 2428.77, "trd": [[3.4, 79.1]], "batb": NaN, "batl": [[0, 3.4, 41.26]]}, {"timestamp": 1578680429099, "ltp": 3.4, "tv": 2434.77, "trd": [[3.4, 85.1]], "batb": NaN, "batl": [[0, 3.4, 38.26]]}, {"timestamp": 1578680614881, "ltp": 3.35, "tv": 2443.37, "trd": [[3.35, 362.12]], "batb": [[0, 3.3, 254.81], [1, 3.25, 500], [2, 3.05, 3.36]], "batl": [[0, 3.35, 5.7], [1, 3.4, 38.26], [2, 3.6, 28.94]]}, {"timestamp": 1578680618804, "ltp": 3.35, "tv": 2443.37, "trd": NaN, "batb": [[0, 3.3, 291.41]], "batl": NaN}, {"timestamp": 1578680627821, "ltp": 3.35, "tv": 2443.37, "trd": NaN, "batb": NaN, "batl": [[1, 3.4, 58.26]]}, {"timestamp": 1578680696073, "ltp": 3.4, "tv": 2463.77, "trd": [[3.35, 373.52], [3.4, 94.1]], "batb": NaN, "batl": [[0, 3.4, 53.76], [1, 3.6, 28.94], [2, 3.65, 2]]}, {"timestamp": 1578680745039, "ltp": 3.4, "tv": 2474.13, "trd": [[3.4, 104.46]], "batb": NaN, "batl": [[0, 3.4, 48.58]]}, {"timestamp": 1578680809896, "ltp": 3.4, "tv": 2474.13, "trd": NaN, "batb": NaN, "batl": [[0, 3.35, 6], [1, 3.4, 48.58], [2, 3.6, 28.94]]}, {"timestamp": 1578680898625, "ltp": 3.4, "tv": 2474.13, "trd": NaN, "batb": NaN, "batl": [[0, 3.35, 28]]}, {"timestamp": 1578680992924, "ltp": 3.35, "tv": 2530.13, "trd": [[3.35, 429.52]], "batb": [[0, 3.35, 91.4], [1, 3.3, 291.41], [2, 3.25, 500]], "batl": [[0, 3.4, 48.58], [1, 3.6, 28.94], [2, 3.65, 2]]}, {"timestamp": 1578680995833, "ltp": 3.35, "tv": 2530.13, "trd": NaN, "batb": [[1, 3.3, 281.48]], "batl": NaN}, {"timestamp": 1578681056751, "ltp": 3.35, "tv": 2536.13, "trd": [[3.35, 435.52]], "batb": [[0, 3.35, 88.4]], "batl": NaN}, {"timestamp": 1578681088780, "ltp": 3.4, "tv": 2576.95, "trd": [[3.4, 145.28]], "batb": NaN, "batl": [[0, 3.4, 28.17]]}, {"timestamp": 1578681243280, "ltp": 3.4, "tv": 2585.19, "trd": [[3.4, 153.52]], "batb": NaN, "batl": [[0, 3.4, 24.05]]}, {"timestamp": 1578681257801, "ltp": 3.4, "tv": 2595.63, "trd": [[3.4, 163.96]], "batb": NaN, "batl": [[0, 3.4, 18.83]]}, {"timestamp": 1578681311672, "ltp": 3.4, "tv": 2633.29, "trd": [[3.4, 201.62]], "batb": [[0, 3.4, 1.17], [1, 3.35, 88.4], [2, 3.3, 281.48]], "batl": [[0, 3.6, 28.94], [1, 3.65, 2], [2, 3.7, 2]]}, {"timestamp": 1578681375231, "ltp": 3.4, "tv": 2633.29, "trd": NaN, "batb": [[2, 3.3, 291.48]], "batl": NaN}, {"timestamp": 1578681433929, "ltp": 3.4, "tv": 2633.29, "trd": NaN, "batb": [[2, 3.3, 281.48]], "batl": NaN}, {"timestamp": 1578681437002, "ltp": 3.35, "tv": 2713.29, "trd": [[3.35, 513.18], [3.4, 203.96]], "batb": [[0, 3.35, 49.57], [1, 3.3, 281.48], [2, 3.25, 500]], "batl": NaN}, {"timestamp": 1578681437631, "ltp": 3.35, "tv": 2713.29, "trd": NaN, "batb": [[0, 3.35, 61.37]], "batl": NaN}, {"timestamp": 1578681480147, "ltp": 3.35, "tv": 2713.29, "trd": NaN, "batb": NaN, "batl": [[0, 3.5, 10], [1, 3.6, 28.94], [2, 3.65, 2]]}, {"timestamp": 1578681720517, "ltp": 3.35, "tv": 2713.29, "trd": NaN, "batb": [[0, 3.4, 20.43], [1, 3.35, 61.37], [2, 3.3, 244.87]], "batl": NaN}, {"timestamp": 1578681756681, "ltp": 3.4, "tv": 2753.29, "trd": [[3.4, 243.96]], "batb": [[0, 3.35, 61.8], [1, 3.3, 244.87], [2, 3.25, 500]], "batl": NaN}, {"timestamp": 1578681763126, "ltp": 3.4, "tv": 2753.29, "trd": NaN, "batb": NaN, "batl": [[1, 3.55, 15], [2, 3.6, 28.94]]}, {"timestamp": 1578681813185, "ltp": 3.4, "tv": 2753.29, "trd": NaN, "batb": [[0, 3.35, 61.37]], "batl": NaN}, {"timestamp": 1578681831628, "ltp": 3.35, "tv": 2765.29, "trd": [[3.35, 525.18]], "batb": [[0, 3.35, 55.37]], "batl": NaN}, {"timestamp": 1578681883574, "ltp": 3.35, "tv": 2785.29, "trd": [[3.35, 545.18]], "batb": [[0, 3.35, 45.37]], "batl": NaN}, {"timestamp": 1578681944577, "ltp": 3.35, "tv": 2875.28, "trd": [[3.35, 635.17]], "batb": [[0, 3.3, 245.24], [1, 3.25, 500], [2, 3.15, 10]], "batl": NaN}, {"timestamp": 1578681946766, "ltp": 3.35, "tv": 2875.28, "trd": NaN, "batb": [[0, 3.3, 244.87]], "batl": NaN}, {"timestamp": 1578682294418, "ltp": 3.35, "tv": 2875.28, "trd": NaN, "batb": [[0, 3.35, 100], [1, 3.3, 244.87], [2, 3.25, 500]], "batl": NaN}, {"timestamp": 1578682507509, "ltp": 3.35, "tv": 2891.38, "trd": [[3.35, 651.27]], "batb": [[0, 3.35, 91.95]], "batl": NaN}, {"timestamp": 1578682535764, "ltp": 3.35, "tv": 2891.38, "trd": NaN, "batb": [[0, 3.4, 6], [1, 3.35, 91.95], [2, 3.3, 244.87]], "batl": NaN}, {"timestamp": 1578682544737, "ltp": 3.35, "tv": 2891.38, "trd": NaN, "batb": [[0, 3.45, 2], [1, 3.4, 6], [2, 3.35, 91.95]], "batl": NaN}, {"timestamp": 1578682549230, "ltp": 3.4, "tv": 2901.38, "trd": [[3.4, 249.96], [3.45, 4]], "batb": [[0, 3.4, 3], [1, 3.35, 91.95], [2, 3.3, 244.87]], "batl": NaN}, {"timestamp": 1578682659878, "ltp": 3.5, "tv": 2918.62, "trd": [[3.5, 920.91]], "batb": NaN, "batl": [[0, 3.5, 1.38]]}, {"timestamp": 1578682660052, "ltp": 3.5, "tv": 2921.38, "trd": [[3.5, 923.67]], "batb": NaN, "batl": [[0, 3.55, 15], [1, 3.6, 28.94], [2, 3.65, 2]]}, {"timestamp": 1578682811812, "ltp": 3.5, "tv": 2921.47, "trd": [[3.35, 651.28], [3.4, 249.96], [3.5, 923.69], [3.55, 226.45], [3.6, 113.67], [3.65, 118.69], [3.7, 146.85], [3.75, 96.05], [3.8, 96.96], [3.85, 60.01], [3.95, 52.84]], "batb": NaN, "batl": NaN}, {"timestamp": 1578683376490, "ltp": 3.55, "tv": 2933.29, "trd": [[3.55, 238.27]], "batb": NaN, "batl": [[0, 3.55, 9.09]]}, {"timestamp": 1578683379714, "ltp": 3.4, "tv": 2937.29, "trd": [[3.4, 253.96]], "batb": [[0, 3.4, 1]], "batl": NaN}, {"timestamp": 1578683380900, "ltp": 3.4, "tv": 2939.29, "trd": [[3.4, 255.96]], "batb": [[0, 3.35, 91.95], [1, 3.3, 244.87], [2, 3.25, 500]], "batl": [[0, 3.4, 1], [1, 3.55, 9.09], [2, 3.6, 28.94]]}, {"timestamp": 1578683404229, "ltp": 3.4, "tv": 2939.29, "trd": NaN, "batb": NaN, "batl": [[0, 3.55, 9.09], [1, 3.6, 28.94], [2, 3.65, 2]]}, {"timestamp": 1578683419683, "ltp": 3.35, "tv": 2940.91, "trd": [[3.35, 652.9]], "batb": [[0, 3.35, 91.14]], "batl": NaN}, {"timestamp": 1578683431998, "ltp": 3.35, "tv": 2941.11, "trd": [[3.35, 653.1]], "batb": [[0, 3.35, 91.04]], "batl": NaN}, {"timestamp": 1578683593773, "ltp": 3.6, "tv": 2963.11, "trd": [[3.55, 256.45], [3.6, 117.49]], "batb": NaN, "batl": [[0, 3.6, 27.03], [1, 3.65, 2], [2, 3.7, 2]]}, {"timestamp": 1578683626916, "ltp": 3.6, "tv": 2963.11, "trd": NaN, "batb": NaN, "batl": [[2, 3.7, 4]]}, {"timestamp": 1578683639934, "ltp": 3.6, "tv": 2983.11, "trd": [[3.6, 137.49]], "batb": NaN, "batl": [[0, 3.6, 17.03]]}, {"timestamp": 1578683640437, "ltp": 3.6, "tv": 2983.11, "trd": NaN, "batb": NaN, "batl": [[1, 3.65, 4]]}, {"timestamp": 1578683692946, "ltp": 3.6, "tv": 2983.11, "trd": NaN, "batb": [[0, 3.4, 20.44], [1, 3.35, 91.04], [2, 3.3, 244.87]], "batl": NaN}, {"timestamp": 1578683894386, "ltp": 3.4, "tv": 2999.11, "trd": [[3.4, 271.97]], "batb": [[0, 3.4, 12.43]], "batl": NaN}, {"timestamp": 1578684039204, "ltp": 3.4, "tv": 3023.11, "trd": [[3.4, 295.96]], "batb": [[0, 3.35, 91.47], [1, 3.3, 244.87], [2, 3.25, 500]], "batl": NaN}, {"timestamp": 1578684049240, "ltp": 3.35, "tv": 3027.11, "trd": [[3.35, 656.24], [3.4, 296.83]], "batb": [[0, 3.35, 89.47]], "batl": NaN}, {"timestamp": 1578684196999, "ltp": 3.35, "tv": 3047.11, "trd": [[3.35, 676.24]], "batb": [[0, 3.35, 79.47]], "batl": NaN}, {"timestamp": 1578684527538, "ltp": 3.35, "tv": 3047.11, "trd": NaN, "batb": [[0, 3.4, 4.26], [1, 3.35, 79.47], [2, 3.3, 244.87]], "batl": NaN}, {"timestamp": 1578684804885, "ltp": 3.35, "tv": 3047.11, "trd": NaN, "batb": NaN, "batl": [[0, 3.6, 29.03]]}, {"timestamp": 1578684971315, "ltp": 3.35, "tv": 3047.11, "trd": NaN, "batb": NaN, "batl": [[0, 3.55, 1.9], [1, 3.6, 29.03], [2, 3.65, 4]]}, {"timestamp": 1578684993963, "ltp": 3.35, "tv": 3047.11, "trd": NaN, "batb": NaN, "batl": [[0, 3.6, 29.03], [1, 3.65, 4], [2, 3.7, 4]]}, {"timestamp": 1578684994074, "ltp": 3.35, "tv": 3047.11, "trd": NaN, "batb": NaN, "batl": [[0, 3.55, 1.6], [1, 3.6, 29.03], [2, 3.65, 4]]}, {"timestamp": 1578685040037, "ltp": 3.35, "tv": 3047.11, "trd": NaN, "batb": [[2, 3.3, 244.93]], "batl": NaN}, {"timestamp": 1578685067926, "ltp": 3.35, "tv": 3047.11, "trd": NaN, "batb": [[0, 3.4, 4.75]], "batl": NaN}, {"timestamp": 1578685267956, "ltp": 3.35, "tv": 3047.11, "trd": NaN, "batb": [[0, 3.4, 14.95]], "batl": NaN}, {"timestamp": 1578685434609, "ltp": 3.35, "tv": 3047.11, "trd": NaN, "batb": [[0, 3.5, 30], [1, 3.4, 14.95], [2, 3.35, 79.47]], "batl": NaN}, {"timestamp": 1578685437707, "ltp": 3.55, "tv": 3050.31, "trd": [[3.55, 259.65]], "batb": [[0, 3.55, 7.77], [1, 3.5, 30], [2, 3.4, 14.95]], "batl": [[0, 3.6, 29.03], [1, 3.65, 4], [2, 3.7, 4]]}, {"timestamp": 1578685438916, "ltp": 3.55, "tv": 3050.31, "trd": NaN, "batb": [[2, 3.4, 10.69]], "batl": NaN}, {"timestamp": 1578685439714, "ltp": 3.5, "tv": 3100.31, "trd": [[3.5, 958.15], [3.55, 275.19]], "batb": [[0, 3.5, 12.77], [1, 3.4, 10.69], [2, 3.35, 79.47]], "batl": NaN}, {"timestamp": 1578685510028, "ltp": 3.5, "tv": 3100.31, "trd": NaN, "batb": NaN, "batl": [[0, 3.55, 4.9], [1, 3.6, 29.03], [2, 3.65, 4]]}, {"timestamp": 1578685604616, "ltp": 3.55, "tv": 3110.11, "trd": [[3.55, 284.99]], "batb": [[0, 3.55, 1.89], [1, 3.5, 12.77], [2, 3.4, 10.69]], "batl": [[0, 3.6, 29.03], [1, 3.65, 4], [2, 3.7, 4]]}, {"timestamp": 1578685612753, "ltp": 3.55, "tv": 3113.89, "trd": [[3.55, 288.77]], "batb": [[0, 3.5, 12.77], [1, 3.4, 10.69], [2, 3.35, 79.47]], "batl": [[0, 3.55, 88.11], [1, 3.6, 29.03], [2, 3.65, 4]]}, {"timestamp": 1578685613656, "ltp": 3.55, "tv": 3113.89, "trd": NaN, "batb": [[0, 3.5, 17.03]], "batl": [[0, 3.55, 98.89]]}, {"timestamp": 1578685630908, "ltp": 3.55, "tv": 3113.89, "trd": NaN, "batb": NaN, "batl": [[2, 3.65, 12]]}, {"timestamp": 1578685704000, "ltp": 3.5, "tv": 3147.95, "trd": [[3.5, 992.2]], "batb": [[0, 3.4, 10.69], [1, 3.35, 79.47], [2, 3.3, 244.93]], "batl": [[0, 3.5, 71.08], [1, 3.55, 10.78], [2, 3.6, 29.03]]}, {"timestamp": 1578685705971, "ltp": 3.5, "tv": 3147.95, "trd": NaN, "batb": [[0, 3.4, 12.69]], "batl": NaN}, {"timestamp": 1578685714998, "ltp": 3.5, "tv": 3147.95, "trd": NaN, "batb": NaN, "batl": [[0, 3.55, 81.86], [1, 3.6, 29.03], [2, 3.65, 12]]}, {"timestamp": 1578685716804, "ltp": 3.5, "tv": 3147.95, "trd": NaN, "batb": NaN, "batl": [[0, 3.5, 15], [1, 3.55, 81.86], [2, 3.6, 29.03]]}, {"timestamp": 1578685718950, "ltp": 3.4, "tv": 3167.95, "trd": [[3.4, 315.85], [3.45, 4.98]], "batb": [[0, 3.4, 2.69]], "batl": NaN}, {"timestamp": 1578685719848, "ltp": 3.4, "tv": 3173.33, "trd": [[3.4, 321.23]], "batb": [[0, 3.35, 79.47], [1, 3.3, 244.93], [2, 3.25, 500]], "batl": [[0, 3.4, 2.31], [1, 3.5, 15], [2, 3.55, 81.86]]}, {"timestamp": 1578685722356, "ltp": 3.4, "tv": 3177.95, "trd": [[3.4, 325.85]], "batb": NaN, "batl": [[0, 3.5, 15], [1, 3.55, 81.86], [2, 3.6, 29.03]]}, {"timestamp": 1578685732474, "ltp": 3.35, "tv": 3320.11, "trd": [[3.35, 818.4]], "batb": [[0, 3.35, 8.39]], "batl": [[1, 3.55, 10.78]]}, {"timestamp": 1578685734162, "ltp": 3.35, "tv": 3320.11, "trd": NaN, "batb": NaN, "batl": [[1, 3.6, 29.03], [2, 3.65, 12]]}, {"timestamp": 1578685755709, "ltp": 3.35, "tv": 3320.11, "trd": NaN, "batb": [[0, 3.4, 4.51], [1, 3.35, 8.39], [2, 3.3, 244.93]], "batl": NaN}, {"timestamp": 1578685756907, "ltp": 3.35, "tv": 3320.11, "trd": NaN, "batb": NaN, "batl": [[0, 3.6, 29.03], [1, 3.65, 12], [2, 3.7, 4]]}, {"timestamp": 1578685842269, "ltp": 3.35, "tv": 3320.11, "trd": NaN, "batb": NaN, "batl": [[0, 3.5, 20], [1, 3.6, 29.03], [2, 3.65, 12]]}, {"timestamp": 1578685962098, "ltp": 3.4, "tv": 3329.13, "trd": [[3.4, 334.87]], "batb": [[0, 3.35, 8.39], [1, 3.3, 244.93], [2, 3.25, 500]], "batl": [[0, 3.5, 20.49]]}, {"timestamp": 1578686092474, "ltp": 3.3, "tv": 3354.13, "trd": [[3.3, 96.48], [3.35, 835.18]], "batb": [[0, 3.3, 240.82], [1, 3.25, 500], [2, 3.15, 10]], "batl": NaN}, {"timestamp": 1578686419845, "ltp": 3.3, "tv": 3354.13, "trd": NaN, "batb": [[0, 3.35, 30.06], [1, 3.3, 240.82], [2, 3.25, 500]], "batl": NaN}, {"timestamp": 1578686429962, "ltp": 3.4, "tv": 3355.12, "trd": [[3.4, 335.86]], "batb": [[0, 3.4, 2.91], [1, 3.35, 30.06], [2, 3.3, 240.82]], "batl": [[0, 3.5, 20]]}, {"timestamp": 1578686479678, "ltp": 3.4, "tv": 3360.94, "trd": [[3.4, 341.68]], "batb": [[0, 3.35, 30.06], [1, 3.3, 240.82], [2, 3.25, 500]], "batl": NaN}, {"timestamp": 1578686585604, "ltp": 3.4, "tv": 3360.94, "trd": NaN, "batb": NaN, "batl": [[2, 3.65, 165.27]]}, {"timestamp": 1578686587310, "ltp": 3.4, "tv": 3360.94, "trd": NaN, "batb": NaN, "batl": [[1, 3.6, 39.67]]}, {"timestamp": 1578686674649, "ltp": 3.5, "tv": 3388.96, "trd": [[3.5, 1020.22]], "batb": NaN, "batl": [[0, 3.5, 5.99]]}, {"timestamp": 1578686676632, "ltp": 3.5, "tv": 3388.96, "trd": NaN, "batb": NaN, "batl": [[1, 3.6, 48.65]]}, {"timestamp": 1578686695008, "ltp": 3.5, "tv": 3388.96, "trd": NaN, "batb": NaN, "batl": [[2, 3.65, 234.87]]}, {"timestamp": 1578687029973, "ltp": 3.35, "tv": 3395.78, "trd": [[3.35, 842]], "batb": [[0, 3.35, 26.65]], "batl": NaN}, {"timestamp": 1578687045786, "ltp": 3.35, "tv": 3435.78, "trd": [[3.35, 882]], "batb": [[0, 3.35, 6.65]], "batl": NaN}, {"timestamp": 1578687123992, "ltp": 3.35, "tv": 3445.78, "trd": [[3.35, 892]], "batb": [[0, 3.35, 1.65]], "batl": NaN}, {"timestamp": 1578687319465, "ltp": 3.35, "tv": 3445.78, "trd": NaN, "batb": [[0, 3.35, 26.05]], "batl": NaN}, {"timestamp": 1578687349346, "ltp": 3.35, "tv": 3445.78, "trd": NaN, "batb": [[0, 3.35, 1.65]], "batl": NaN}, {"timestamp": 1578687407454, "ltp": 3.3, "tv": 3449.78, "trd": [[3.3, 97.18], [3.35, 895.3]], "batb": [[0, 3.3, 240.47], [1, 3.25, 500], [2, 3.15, 10]], "batl": NaN}, {"timestamp": 1578687466086, "ltp": 3.3, "tv": 3449.78, "trd": NaN, "batb": [[0, 3.35, 20.6], [1, 3.3, 240.47], [2, 3.25, 500]], "batl": NaN}, {"timestamp": 1578687556783, "ltp": 3.3, "tv": 3449.78, "trd": NaN, "batb": NaN, "batl": [[0, 3.45, 1.7], [1, 3.5, 5.99], [2, 3.6, 48.65]]}, {"timestamp": 1578687557906, "ltp": 3.3, "tv": 3449.78, "trd": NaN, "batb": NaN, "batl": [[0, 3.5, 5.99], [1, 3.6, 48.65], [2, 3.65, 234.87]]}, {"timestamp": 1578687794396, "ltp": 3.3, "tv": 3449.78, "trd": NaN, "batb": NaN, "batl": [[0, 3.5, 25.99]]}, {"timestamp": 1578687834860, "ltp": 3.3, "tv": 3449.78, "trd": NaN, "batb": [[0, 3.3, 254.57], [1, 3.25, 500], [2, 3.15, 10]], "batl": NaN}, {"timestamp": 1578688312841, "ltp": 3.3, "tv": 3449.78, "trd": NaN, "batb": [[0, 3.35, 4], [1, 3.3, 254.57], [2, 3.25, 500]], "batl": NaN}, {"timestamp": 1578688375863, "ltp": 3.3, "tv": 3449.78, "trd": NaN, "batb": [[0, 3.35, 14.07]], "batl": NaN}, {"timestamp": 1578688378109, "ltp": 3.3, "tv": 3449.78, "trd": NaN, "batb": [[0, 3.35, 10.07]], "batl": NaN}, {"timestamp": 1578688430571, "ltp": 3.3, "tv": 3449.78, "trd": NaN, "batb": [[0, 3.35, 34.47]], "batl": NaN}, {"timestamp": 1578688525577, "ltp": 3.3, "tv": 3449.78, "trd": NaN, "batb": [[0, 3.35, 10.07]], "batl": NaN}, {"timestamp": 1578688568949, "ltp": 3.3, "tv": 3449.78, "trd": NaN, "batb": NaN, "batl": [[1, 3.55, 20.45], [2, 3.6, 48.65]]}, {"timestamp": 1578688630950, "ltp": 3.3, "tv": 3977.78, "trd": [[3.3, 605.04], [3.35, 915.44]], "batb": [[0, 3.25, 500.64], [1, 3.15, 10], [2, 3.05, 3.36]], "batl": NaN}, {"timestamp": 1578688637756, "ltp": 3.25, "tv": 3988.85, "trd": [[3.25, 9.8], [3.3, 606.32]], "batb": [[0, 3.25, 495.1], [2, 3.1, 25.07]], "batl": [[0, 3.45, 22.52], [1, 3.5, 25.99], [2, 3.55, 20.45]]}, {"timestamp": 1578688638864, "ltp": 3.25, "tv": 3999.92, "trd": [[3.25, 20.86]], "batb": [[0, 3.25, 489.57]], "batl": NaN}, {"timestamp": 1578688653565, "ltp": 3.25, "tv": 4921.08, "trd": [[3.25, 942.02]], "batb": [[0, 3.25, 28.99]], "batl": NaN}, {"timestamp": 1578688656868, "ltp": 3.25, "tv": 4921.08, "trd": NaN, "batb": [[0, 3.3, 100], [1, 3.25, 28.99], [2, 3.15, 10]], "batl": NaN}, {"timestamp": 1578688658681, "ltp": 3.3, "tv": 4932.32, "trd": [[3.3, 617.56]], "batb": [[0, 3.3, 94.38]], "batl": [[0, 3.4, 4.94], [1, 3.45, 22.52], [2, 3.5, 25.99]]}, {"timestamp": 1578688670006, "ltp": 3.3, "tv": 4932.32, "trd": NaN, "batb": NaN, "batl": [[1, 3.5, 25.99], [2, 3.55, 20.45]]}, {"timestamp": 1578689132926, "ltp": 3.4, "tv": 4942.2, "trd": [[3.4, 351.56]], "batb": [[0, 3.4, 19.1], [1, 3.3, 94.38], [2, 3.25, 28.99]], "batl": [[0, 3.5, 25.99], [1, 3.55, 20.45], [2, 3.6, 39.67]]}, {"timestamp": 1578689155661, "ltp": 3.4, "tv": 4942.2, "trd": NaN, "batb": NaN, "batl": [[0, 3.45, 9], [1, 3.5, 25.99], [2, 3.55, 20.45]]}, {"timestamp": 1578689160347, "ltp": 3.4, "tv": 4942.2, "trd": NaN, "batb": [[1, 3.35, 6], [2, 3.3, 94.38]], "batl": NaN}, {"timestamp": 1578689351741, "ltp": 3.4, "tv": 4942.2, "trd": NaN, "batb": NaN, "batl": [[0, 3.45, 16.66]]}, {"timestamp": 1578689429680, "ltp": 3.4, "tv": 4942.2, "trd": NaN, "batb": [[0, 3.4, 36.57]], "batl": NaN}, {"timestamp": 1578689892588, "ltp": 3.4, "tv": 5002.2, "trd": [[3.4, 411.56]], "batb": [[0, 3.4, 6.57]], "batl": NaN}, {"timestamp": 1578689906997, "ltp": 3.4, "tv": 5015.34, "trd": [[3.4, 424.7]], "batb": [[0, 3.35, 6], [1, 3.3, 94.38], [2, 3.25, 28.99]], "batl": NaN}, {"timestamp": 1578689923414, "ltp": 3.4, "tv": 5015.34, "trd": NaN, "batb": [[0, 3.35, 9.41]], "batl": NaN}, {"timestamp": 1578689974766, "ltp": 3.4, "tv": 5015.34, "trd": NaN, "batb": NaN, "batl": [[1, 3.5, 29.99]]}, {"timestamp": 1578690035743, "ltp": 3.4, "tv": 5015.57, "trd": [[3.25, 942.03], [3.3, 617.56], [3.35, 915.46], [3.4, 424.72], [3.5, 1020.26], [3.55, 288.82], [3.6, 137.5], [3.65, 118.71], [3.7, 146.88], [3.75, 96.06], [3.8, 96.97], [3.85, 60.01], [3.95, 52.84]], "batb": [[0, 3.35, 9.41]], "batl": NaN}, {"timestamp": 1578690151582, "ltp": 3.45, "tv": 5048.89, "trd": [[3.45, 38.3]], "batb": [[0, 3.45, 4.86], [1, 3.35, 9.41], [2, 3.3, 94.38]], "batl": [[0, 3.5, 29.99], [1, 3.55, 20.45], [2, 3.6, 39.67]]}, {"timestamp": 1578690374793, "ltp": 3.45, "tv": 5056.89, "trd": [[3.45, 46.3]], "batb": [[0, 3.35, 10.27], [1, 3.3, 94.38], [2, 3.25, 28.99]], "batl": NaN}, {"timestamp": 1578690376002, "ltp": 3.45, "tv": 5058.61, "trd": [[3.45, 48.02]], "batb": [[0, 3.35, 9.41]], "batl": NaN}, {"timestamp": 1578690379996, "ltp": 3.35, "tv": 5077.42, "trd": [[3.35, 934.28]], "batb": [[0, 3.3, 94.38], [1, 3.25, 28.99], [2, 3.2, 9.52]], "batl": [[0, 3.35, 4.86], [1, 3.5, 29.99], [2, 3.55, 20.45]]}, {"timestamp": 1578690380468, "ltp": 3.35, "tv": 5087.15, "trd": [[3.35, 944]], "batb": [[0, 3.35, 5.13], [1, 3.3, 94.38], [2, 3.25, 28.99]], "batl": [[0, 3.5, 29.99], [1, 3.55, 20.45], [2, 3.6, 39.67]]}, {"timestamp": 1578690381973, "ltp": 3.35, "tv": 5087.15, "trd": NaN, "batb": NaN, "batl": [[0, 3.45, 6], [1, 3.5, 29.99], [2, 3.55, 20.45]]}, {"timestamp": 1578690382383, "ltp": 3.35, "tv": 5087.15, "trd": NaN, "batb": [[0, 3.35, 5.26]], "batl": NaN}, {"timestamp": 1578690390515, "ltp": 3.35, "tv": 5097.67, "trd": [[3.35, 954.52]], "batb": [[0, 3.3, 94.38], [1, 3.25, 28.99], [2, 3.2, 9.52]], "batl": [[0, 3.35, 44.74], [1, 3.45, 6], [2, 3.5, 29.99]]}, {"timestamp": 1578690392904, "ltp": 3.35, "tv": 5112.41, "trd": [[3.35, 969.26]], "batb": NaN, "batl": [[0, 3.35, 37.37]]}, {"timestamp": 1578690393909, "ltp": 3.35, "tv": 5124.53, "trd": [[3.35, 981.38]], "batb": NaN, "batl": [[0, 3.35, 31.31]]}, {"timestamp": 1578690395991, "ltp": 3.35, "tv": 5124.73, "trd": [[3.35, 981.58]], "batb": NaN, "batl": [[0, 3.35, 37.21], [1, 3.5, 29.99], [2, 3.55, 20.45]]}, {"timestamp": 1578690398814, "ltp": 3.35, "tv": 5125.09, "trd": [[3.35, 981.94]], "batb": NaN, "batl": [[0, 3.35, 37.03]]}, {"timestamp": 1578690412931, "ltp": 3.3, "tv": 5197.55, "trd": [[3.3, 690.02]], "batb": [[0, 3.3, 58.15]], "batl": [[0, 3.35, 6]]}, {"timestamp": 1578690414906, "ltp": 3.3, "tv": 5197.55, "trd": NaN, "batb": NaN, "batl": [[2, 3.55, 31.23]]}, {"timestamp": 1578690416900, "ltp": 3.3, "tv": 5197.55, "trd": NaN, "batb": NaN, "batl": [[0, 3.45, 6]]}, {"timestamp": 1578690481391, "ltp": 3.3, "tv": 5217.55, "trd": [[3.3, 710.02]], "batb": [[0, 3.3, 48.15]], "batl": NaN}, {"timestamp": 1578690487995, "ltp": 3.45, "tv": 5229.55, "trd": [[3.45, 60.02]], "batb": [[0, 3.45, 3.48], [1, 3.3, 48.15], [2, 3.25, 28.99]], "batl": [[0, 3.5, 29.99], [1, 3.55, 31.23], [2, 3.6, 29.03]]}, {"timestamp": 1578690488927, "ltp": 3.45, "tv": 5236.51, "trd": [[3.45, 66.98]], "batb": [[0, 3.3, 48.15], [1, 3.25, 28.99], [2, 3.2, 9.52]], "batl": [[0, 3.45, 6.26], [1, 3.5, 29.99], [2, 3.55, 20.45]]}, {"timestamp": 1578690489135, "ltp": 3.45, "tv": 5236.51, "trd": NaN, "batb": [[0, 3.35, 3.58], [1, 3.3, 48.15], [2, 3.25, 28.99]], "batl": [[0, 3.5, 29.99], [1, 3.55, 20.45], [2, 3.6, 39.67]]}, {"timestamp": 1578690585782, "ltp": 3.5, "tv": 5278.93, "trd": [[3.5, 1062.68]], "batb": NaN, "batl": [[0, 3.5, 8.78]]}, {"timestamp": 1578690620898, "ltp": 3.35, "tv": 5286.09, "trd": [[3.35, 989.1]], "batb": [[0, 3.3, 48.15], [1, 3.25, 28.99], [2, 3.2, 9.52]], "batl": NaN}, {"timestamp": 1578690731860, "ltp": 3.35, "tv": 5286.09, "trd": NaN, "batb": NaN, "batl": [[0, 3.5, 58.78]]}, {"timestamp": 1578690749807, "ltp": 3.35, "tv": 5286.09, "trd": NaN, "batb": [[0, 3.35, 5.21], [1, 3.3, 48.15], [2, 3.25, 28.99]], "batl": NaN}, {"timestamp": 1578690860487, "ltp": 3.35, "tv": 5286.09, "trd": NaN, "batb": NaN, "batl": [[2, 3.6, 53.27]]}, {"timestamp": 1578690870916, "ltp": 3.35, "tv": 5296.09, "trd": [[3.35, 999.1]], "batb": [[0, 3.3, 48.36], [1, 3.25, 28.99], [2, 3.2, 9.52]], "batl": NaN}, {"timestamp": 1578690871385, "ltp": 3.35, "tv": 5296.51, "trd": [[3.35, 999.52]], "batb": [[0, 3.3, 48.15]], "batl": NaN}, {"timestamp": 1578690885946, "ltp": 3.3, "tv": 5386.51, "trd": [[3.3, 800.02]], "batb": [[0, 3.3, 3.15]], "batl": NaN}, {"timestamp": 1578690886128, "ltp": 3.3, "tv": 5386.51, "trd": NaN, "batb": NaN, "batl": [[0, 3.45, 9.74], [1, 3.5, 58.78], [2, 3.55, 20.45]]}, {"timestamp": 1578690888919, "ltp": 3.3, "tv": 5386.51, "trd": NaN, "batb": NaN, "batl": [[1, 3.5, 69.72]]}, {"timestamp": 1578690921899, "ltp": 3.3, "tv": 5386.51, "trd": NaN, "batb": NaN, "batl": [[0, 3.4, 2.3], [1, 3.45, 9.74], [2, 3.5, 69.72]]}, {"timestamp": 1578690922896, "ltp": 3.3, "tv": 5386.51, "trd": NaN, "batb": NaN, "batl": [[0, 3.45, 9.74], [1, 3.5, 69.72], [2, 3.55, 20.45]]}, {"timestamp": 1578691020945, "ltp": 3.3, "tv": 5386.51, "trd": NaN, "batb": [[1, 3.25, 68.99]], "batl": NaN}, {"timestamp": 1578691056967, "ltp": 3.45, "tv": 5405.99, "trd": [[3.45, 86.46]], "batb": NaN, "batl": [[0, 3.5, 69.72], [1, 3.55, 20.45], [2, 3.6, 42.63]]}, {"timestamp": 1578691059841, "ltp": 3.45, "tv": 5405.99, "trd": NaN, "batb": NaN, "batl": [[0, 3.5, 58.78], [1, 3.55, 31.23]]}, {"timestamp": 1578691167801, "ltp": 3.45, "tv": 5405.99, "trd": NaN, "batb": NaN, "batl": [[0, 3.45, 4], [1, 3.5, 58.78], [2, 3.55, 31.23]]}, {"timestamp": 1578691194937, "ltp": 3.45, "tv": 5405.99, "trd": NaN, "batb": NaN, "batl": [[0, 3.45, 8]]}, {"timestamp": 1578691211059, "ltp": 3.45, "tv": 5405.99, "trd": NaN, "batb": [[0, 3.3, 23.15]], "batl": NaN}, {"timestamp": 1578691260771, "ltp": 3.3, "tv": 5445.99, "trd": [[3.3, 840.02]], "batb": [[0, 3.3, 3.15]], "batl": NaN}, {"timestamp": 1578691324831, "ltp": 3.3, "tv": 5445.99, "trd": NaN, "batb": NaN, "batl": [[0, 3.4, 16.85], [1, 3.45, 8], [2, 3.5, 58.78]]}, {"timestamp": 1578691374816, "ltp": 3.3, "tv": 5452.29, "trd": [[3.3, 846.32]], "batb": [[0, 3.25, 68.99], [1, 3.2, 9.52], [2, 3.15, 10]], "batl": NaN}, {"timestamp": 1578691379444, "ltp": 3.25, "tv": 5456.12, "trd": [[3.25, 945.86]], "batb": [[0, 3.25, 67.07]], "batl": NaN}, {"timestamp": 1578691389346, "ltp": 3.25, "tv": 5459.53, "trd": [[3.25, 949.27]], "batb": [[0, 3.25, 65.37]], "batl": NaN}, {"timestamp": 1578691445782, "ltp": 3.45, "tv": 5502.57, "trd": [[3.4, 458.42], [3.45, 95.8]], "batb": NaN, "batl": [[0, 3.45, 3.33], [1, 3.5, 58.78], [2, 3.55, 31.23]]}, {"timestamp": 1578691457683, "ltp": 3.45, "tv": 5502.57, "trd": NaN, "batb": [[0, 3.3, 20], [1, 3.25, 65.37], [2, 3.2, 9.52]], "batl": NaN}, {"timestamp": 1578691475938, "ltp": 3.45, "tv": 5509.23, "trd": [[3.45, 102.46]], "batb": [[0, 3.45, 4.67], [1, 3.3, 20], [2, 3.25, 65.37]], "batl": [[0, 3.5, 58.78], [1, 3.55, 31.23], [2, 3.6, 29.03]]}, {"timestamp": 1578691508972, "ltp": 3.5, "tv": 5551.65, "trd": [[3.5, 1105.1]], "batb": NaN, "batl": [[0, 3.5, 37.57]]}, {"timestamp": 1578691539914, "ltp": 3.5, "tv": 5551.65, "trd": NaN, "batb": NaN, "batl": [[2, 3.6, 47.09]]}, {"timestamp": 1578691687521, "ltp": 3.45, "tv": 5560.99, "trd": [[3.45, 111.8]], "batb": [[0, 3.3, 20], [1, 3.25, 65.37], [2, 3.2, 9.52]], "batl": NaN}, {"timestamp": 1578691735979, "ltp": 3.25, "tv": 5660.99, "trd": [[3.25, 1009.27], [3.3, 886.32]], "batb": [[0, 3.25, 35.37], [1, 3.2, 9.52], [2, 3.15, 10]], "batl": NaN}, {"timestamp": 1578691741718, "ltp": 3.25, "tv": 5660.99, "trd": NaN, "batb": NaN, "batl": [[0, 3.45, 4], [1, 3.5, 37.57], [2, 3.55, 31.23]]}, {"timestamp": 1578691761806, "ltp": 3.25, "tv": 5660.99, "trd": NaN, "batb": NaN, "batl": [[0, 3.4, 20], [1, 3.45, 4], [2, 3.5, 37.57]]}, {"timestamp": 1578691809859, "ltp": 3.25, "tv": 5660.99, "trd": NaN, "batb": NaN, "batl": [[1, 3.5, 37.57], [2, 3.55, 31.23]]}, {"timestamp": 1578691909956, "ltp": 3.25, "tv": 5660.99, "trd": NaN, "batb": [[0, 3.3, 10.14], [1, 3.25, 35.37], [2, 3.2, 24.22]], "batl": NaN}, {"timestamp": 1578691974459, "ltp": 3.25, "tv": 5660.99, "trd": NaN, "batb": NaN, "batl": [[0, 3.45, 20]]}, {"timestamp": 1578692065614, "ltp": 3.25, "tv": 5660.99, "trd": NaN, "batb": [[1, 3.25, 85.37]], "batl": NaN}, {"timestamp": 1578692199732, "ltp": 3.45, "tv": 5700.99, "trd": [[3.45, 151.8]], "batb": [[0, 3.25, 85.87], [1, 3.2, 24.22], [2, 3.15, 10]], "batl": [[0, 3.5, 37.57], [1, 3.55, 31.23], [2, 3.6, 47.09]]}, {"timestamp": 1578692324882, "ltp": 3.45, "tv": 5700.99, "trd": NaN, "batb": [[0, 3.3, 20.5], [1, 3.25, 85.37], [2, 3.2, 24.22]], "batl": NaN}, {"timestamp": 1578692400945, "ltp": 3.45, "tv": 5700.99, "trd": NaN, "batb": [[2, 3.2, 9.52]], "batl": NaN}, {"timestamp": 1578692401046, "ltp": 3.45, "tv": 5700.99, "trd": NaN, "batb": [[0, 3.3, 40]], "batl": NaN}, {"timestamp": 1578692585655, "ltp": 3.3, "tv": 5750.99, "trd": [[3.3, 935.32], [3.45, 152.8]], "batb": [[0, 3.3, 15]], "batl": NaN}, {"timestamp": 1578692747612, "ltp": 3.5, "tv": 5768.23, "trd": [[3.5, 1122.34]], "batb": NaN, "batl": [[0, 3.5, 28.95]]}, {"timestamp": 1578692850569, "ltp": 3.5, "tv": 5785.47, "trd": [[3.5, 1139.58]], "batb": NaN, "batl": [[0, 3.5, 20.33]]}, {"timestamp": 1578692920896, "ltp": 3.5, "tv": 5785.47, "trd": NaN, "batb": [[0, 3.35, 10.03], [1, 3.3, 15], [2, 3.25, 85.37]], "batl": [[0, 3.45, 1.9], [1, 3.5, 20.33], [2, 3.55, 31.23]]}, {"timestamp": 1578692931184, "ltp": 3.5, "tv": 5802.71, "trd": [[3.45, 156.6], [3.5, 1153.02]], "batb": NaN, "batl": [[0, 3.5, 13.61], [1, 3.55, 31.23], [2, 3.6, 47.09]]}, {"timestamp": 1578692933295, "ltp": 3.5, "tv": 5802.71, "trd": NaN, "batb": NaN, "batl": [[1, 3.55, 20.45], [2, 3.6, 57.73]]}, {"timestamp": 1578692961482, "ltp": 3.35, "tv": 5822.71, "trd": [[3.35, 1019.52]], "batb": [[0, 3.3, 15.03], [1, 3.25, 85.37], [2, 3.2, 9.52]], "batl": NaN}, {"timestamp": 1578693008942, "ltp": 3.5, "tv": 5839.95, "trd": [[3.5, 1170.26]], "batb": NaN, "batl": [[0, 3.5, 4.99]]}, {"timestamp": 1578693009561, "ltp": 3.5, "tv": 5839.95, "trd": NaN, "batb": NaN, "batl": [[2, 3.6, 68.28]]}, {"timestamp": 1578693010389, "ltp": 3.5, "tv": 5839.95, "trd": NaN, "batb": NaN, "batl": [[2, 3.6, 77.99]]}, {"timestamp": 1578693015762, "ltp": 3.3, "tv": 5870.0, "trd": [[3.3, 965.31], [3.35, 1019.58]], "batb": [[0, 3.25, 85.37], [1, 3.2, 9.52], [2, 3.15, 10]], "batl": [[0, 3.3, 23.27], [1, 3.5, 4.99], [2, 3.55, 20.45]]}, {"timestamp": 1578693016974, "ltp": 3.3, "tv": 5870.0, "trd": NaN, "batb": NaN, "batl": [[1, 3.5, 21.41]]}, {"timestamp": 1578693017755, "ltp": 3.3, "tv": 5871.24, "trd": [[3.3, 966.56]], "batb": NaN, "batl": [[0, 3.3, 37.65]]}, {"timestamp": 1578693018991, "ltp": 3.3, "tv": 5946.54, "trd": [[3.3, 1041.85]], "batb": [[0, 3.3, 55.94], [1, 3.25, 85.37], [2, 3.2, 9.52]], "batl": [[0, 3.5, 21.41], [1, 3.55, 20.45], [2, 3.6, 38.74]]}, {"timestamp": 1578693019867, "ltp": 3.3, "tv": 5946.54, "trd": NaN, "batb": [[0, 3.3, 56.56]], "batl": NaN}, {"timestamp": 1578693033616, "ltp": 3.3, "tv": 5946.54, "trd": NaN, "batb": [[0, 3.25, 85.99], [1, 3.2, 9.52], [2, 3.15, 10]], "batl": NaN}, {"timestamp": 1578693113226, "ltp": 3.3, "tv": 5946.54, "trd": NaN, "batb": NaN, "batl": [[0, 3.45, 5.11], [1, 3.5, 21.41], [2, 3.55, 20.45]]}, {"timestamp": 1578693138965, "ltp": 3.3, "tv": 5946.54, "trd": NaN, "batb": NaN, "batl": [[1, 3.5, 4.99], [2, 3.55, 32.05]]}, {"timestamp": 1578693262000, "ltp": 3.3, "tv": 5946.54, "trd": NaN, "batb": [[1, 3.2, 26.59]], "batl": NaN}, {"timestamp": 1578693331910, "ltp": 3.3, "tv": 5946.54, "trd": NaN, "batb": [[0, 3.3, 100.62], [1, 3.25, 85.37], [2, 3.2, 26.59]], "batl": NaN}, {"timestamp": 1578693333810, "ltp": 3.3, "tv": 5946.54, "trd": NaN, "batb": [[0, 3.35, 8.61], [1, 3.3, 100.62], [2, 3.25, 85.37]], "batl": NaN}, {"timestamp": 1578693363944, "ltp": 3.45, "tv": 5956.54, "trd": [[3.45, 166.6]], "batb": NaN, "batl": [[0, 3.5, 5.1], [1, 3.55, 32.05], [2, 3.6, 38.74]]}, {"timestamp": 1578693364666, "ltp": 3.45, "tv": 5956.54, "trd": NaN, "batb": NaN, "batl": [[2, 3.6, 49.56]]}, {"timestamp": 1578693365242, "ltp": 3.45, "tv": 5956.54, "trd": NaN, "batb": NaN, "batl": [[2, 3.6, 58.32]]}, {"timestamp": 1578693368941, "ltp": 3.5, "tv": 5966.54, "trd": [[3.45, 166.82], [3.5, 1180.04]], "batb": NaN, "batl": [[0, 3.55, 32.15], [1, 3.6, 58.32], [2, 3.65, 234.97]]}, {"timestamp": 1578693384857, "ltp": 3.5, "tv": 5966.54, "trd": NaN, "batb": NaN, "batl": [[0, 3.55, 20.55], [1, 3.6, 70.17]]}, {"timestamp": 1578693404203, "ltp": 3.5, "tv": 5966.54, "trd": NaN, "batb": [[0, 3.35, 18.61]], "batl": NaN}, {"timestamp": 1578693405794, "ltp": 3.55, "tv": 5983.54, "trd": [[3.5, 1180.24], [3.55, 305.62]], "batb": NaN, "batl": [[0, 3.55, 21.59]]}, {"timestamp": 1578693494350, "ltp": 3.55, "tv": 5983.54, "trd": NaN, "batb": NaN, "batl": [[0, 3.5, 20], [1, 3.55, 21.59], [2, 3.6, 70.17]]}, {"timestamp": 1578693906436, "ltp": 3.55, "tv": 5983.54, "trd": NaN, "batb": NaN, "batl": [[0, 3.5, 120]]}, {"timestamp": 1578693908709, "ltp": 3.55, "tv": 5983.54, "trd": NaN, "batb": NaN, "batl": [[0, 3.45, 21.38], [1, 3.5, 120], [2, 3.55, 21.59]]}, {"timestamp": 1578693917923, "ltp": 3.55, "tv": 5983.54, "trd": NaN, "batb": NaN, "batl": [[0, 3.45, 31.66]]}, {"timestamp": 1578693968537, "ltp": 3.55, "tv": 5983.54, "trd": NaN, "batb": NaN, "batl": [[0, 3.45, 131.66]]}, {"timestamp": 1578693997886, "ltp": 3.55, "tv": 5983.54, "trd": NaN, "batb": [[0, 3.35, 99.61]], "batl": NaN}, {"timestamp": 1578694009802, "ltp": 3.35, "tv": 5994.95, "trd": [[3.35, 1031]], "batb": [[0, 3.35, 93.9]], "batl": [[2, 3.55, 3354.59]]}, {"timestamp": 1578694010107, "ltp": 3.35, "tv": 6006.36, "trd": [[3.35, 1042.41]], "batb": [[0, 3.35, 88.2]], "batl": NaN}, {"timestamp": 1578694026914, "ltp": 3.35, "tv": 6006.36, "trd": NaN, "batb": NaN, "batl": [[1, 3.5, 2342]]}, {"timestamp": 1578694057576, "ltp": 3.35, "tv": 6017.77, "trd": [[3.35, 1053.82]], "batb": [[0, 3.35, 82.5]], "batl": NaN}, {"timestamp": 1578694058598, "ltp": 3.35, "tv": 6017.77, "trd": NaN, "batb": NaN, "batl": [[0, 3.4, 10.4], [1, 3.45, 131.66], [2, 3.5, 2342]]}, {"timestamp": 1578694127681, "ltp": 3.4, "tv": 6038.57, "trd": [[3.4, 479.22]], "batb": [[0, 3.35, 91.13]], "batl": [[0, 3.45, 131.66], [1, 3.5, 2342], [2, 3.55, 3354.59]]}, {"timestamp": 1578694200700, "ltp": 3.35, "tv": 6078.57, "trd": [[3.35, 1093.82]], "batb": [[0, 3.35, 71.13]], "batl": NaN}, {"timestamp": 1578694236229, "ltp": 3.35, "tv": 6078.57, "trd": NaN, "batb": NaN, "batl": [[1, 3.5, 2366]]}, {"timestamp": 1578694276296, "ltp": 3.45, "tv": 6108.58, "trd": [[3.45, 196.83]], "batb": NaN, "batl": [[0, 3.45, 116.65]]}, {"timestamp": 1578694277782, "ltp": 3.45, "tv": 6108.58, "trd": NaN, "batb": [[0, 3.35, 79.77]], "batl": NaN}, {"timestamp": 1578694336707, "ltp": 3.45, "tv": 6151.64, "trd": [[3.45, 239.89]], "batb": NaN, "batl": [[0, 3.45, 95.12]]}, {"timestamp": 1578694337688, "ltp": 3.45, "tv": 6151.64, "trd": NaN, "batb": [[0, 3.35, 97.06]], "batl": NaN}, {"timestamp": 1578694359287, "ltp": 3.45, "tv": 6151.64, "trd": NaN, "batb": NaN, "batl": [[1, 3.5, 2342]]}, {"timestamp": 1578694481467, "ltp": 3.45, "tv": 6151.64, "trd": NaN, "batb": NaN, "batl": [[1, 3.5, 2371.43]]}, {"timestamp": 1578694493497, "ltp": 3.35, "tv": 6163.64, "trd": [[3.35, 1105.82]], "batb": [[0, 3.35, 91.06]], "batl": NaN}, {"timestamp": 1578694558686, "ltp": 3.35, "tv": 6229.64, "trd": [[3.35, 1171.82]], "batb": [[0, 3.35, 58.06]], "batl": NaN}, {"timestamp": 1578694583811, "ltp": 3.35, "tv": 6229.64, "trd": NaN, "batb": [[0, 3.35, 89.06]], "batl": NaN}, {"timestamp": 1578694598129, "ltp": 3.35, "tv": 6229.64, "trd": NaN, "batb": NaN, "batl": [[0, 3.45, 151.12]]}, {"timestamp": 1578694604523, "ltp": 3.45, "tv": 6277.72, "trd": [[3.45, 287.97]], "batb": NaN, "batl": [[0, 3.45, 127.08]]}, {"timestamp": 1578694857944, "ltp": 3.45, "tv": 6277.72, "trd": NaN, "batb": NaN, "batl": [[0, 3.4, 4], [1, 3.45, 127.08], [2, 3.5, 2371.43]]}, {"timestamp": 1578694866566, "ltp": 3.45, "tv": 6277.72, "trd": NaN, "batb": [[1, 3.25, 85.99], [2, 3.2, 9.52]], "batl": [[2, 3.5, 2271.43]]}, {"timestamp": 1578694868000, "ltp": 3.45, "tv": 6277.72, "trd": NaN, "batb": [[0, 3.35, 54.5], [1, 3.3, 13.35], [2, 3.25, 85.37]], "batl": NaN}, {"timestamp": 1578694868363, "ltp": 3.45, "tv": 6277.72, "trd": NaN, "batb": [[1, 3.3, 24.1]], "batl": NaN}, {"timestamp": 1578694909454, "ltp": 3.45, "tv": 6277.72, "trd": NaN, "batb": NaN, "batl": [[1, 3.45, 131.08]]}, {"timestamp": 1578694960886, "ltp": 3.45, "tv": 6277.72, "trd": NaN, "batb": [[2, 3.25, 35.37]], "batl": NaN}, {"timestamp": 1578694966822, "ltp": 3.45, "tv": 6277.72, "trd": NaN, "batb": NaN, "batl": [[2, 3.5, 2242]]}, {"timestamp": 1578695073394, "ltp": 3.45, "tv": 6277.72, "trd": NaN, "batb": NaN, "batl": [[1, 3.45, 75.08], [2, 3.5, 20]]}, {"timestamp": 1578695074017, "ltp": 3.45, "tv": 6277.72, "trd": NaN, "batb": NaN, "batl": [[1, 3.45, 125.08]]}, {"timestamp": 1578695250000, "ltp": 3.35, "tv": 6297.72, "trd": [[3.35, 1191.82]], "batb": [[0, 3.35, 44.5]], "batl": NaN}, {"timestamp": 1578695361578, "ltp": 3.35, "tv": 6297.72, "trd": NaN, "batb": [[1, 3.3, 99.1]], "batl": NaN}, {"timestamp": 1578695377991, "ltp": 3.35, "tv": 6297.72, "trd": NaN, "batb": [[0, 3.35, 79.5]], "batl": NaN}, {"timestamp": 1578695739363, "ltp": 3.4, "tv": 6305.72, "trd": [[3.4, 487.22]], "batb": [[0, 3.4, 4.98], [1, 3.35, 79.5], [2, 3.3, 99.1]], "batl": [[0, 3.45, 125.08], [1, 3.5, 20], [2, 3.55, 21.59]]}, {"timestamp": 1578695755293, "ltp": 3.4, "tv": 6305.72, "trd": NaN, "batb": [[0, 3.4, 6.98]], "batl": NaN}, {"timestamp": 1578695756520, "ltp": 3.4, "tv": 6305.72, "trd": NaN, "batb": [[0, 3.4, 29.77], [2, 3.3, 75.62]], "batl": NaN}, {"timestamp": 1578695762794, "ltp": 3.4, "tv": 6305.72, "trd": NaN, "batb": [[0, 3.4, 27.77]], "batl": NaN}, {"timestamp": 1578695764391, "ltp": 3.4, "tv": 6313.72, "trd": [[3.4, 495.23]], "batb": [[0, 3.4, 23.77]], "batl": NaN}, {"timestamp": 1578695771192, "ltp": 3.45, "tv": 6331.22, "trd": [[3.45, 305.47]], "batb": NaN, "batl": [[0, 3.45, 116.33]]}, {"timestamp": 1578695781606, "ltp": 3.45, "tv": 6543.22, "trd": [[3.45, 517.47]], "batb": NaN, "batl": [[0, 3.45, 10.33], [2, 3.55, 12.05]]}, {"timestamp": 1578695822781, "ltp": 3.45, "tv": 6543.22, "trd": NaN, "batb": [[0, 3.4, 98.77]], "batl": NaN}, {"timestamp": 1578695904814, "ltp": 3.45, "tv": 6543.22, "trd": NaN, "batb": NaN, "batl": [[1, 3.5, 40]]}, {"timestamp": 1578695974875, "ltp": 3.4, "tv": 6733.33, "trd": [[3.4, 685.33]], "batb": [[0, 3.4, 3.74]], "batl": [[0, 3.45, 36.32], [1, 3.5, 52.99]]}, {"timestamp": 1578695991996, "ltp": 3.4, "tv": 6740.81, "trd": [[3.4, 692.81]], "batb": [[0, 3.35, 79.5], [1, 3.3, 75.62], [2, 3.25, 35.37]], "batl": [[0, 3.4, 17.57], [1, 3.45, 36.32], [2, 3.5, 52.99]]}, {"timestamp": 1578696078853, "ltp": 3.4, "tv": 6775.94, "trd": [[3.4, 727.94]], "batb": [[0, 3.4, 72.44], [1, 3.35, 79.5], [2, 3.3, 75.62]], "batl": [[0, 3.45, 36.32], [1, 3.5, 52.99], [2, 3.55, 12.05]]}, {"timestamp": 1578696101785, "ltp": 3.4, "tv": 6775.94, "trd": NaN, "batb": NaN, "batl": [[0, 3.45, 10.33], [1, 3.5, 40]]}, {"timestamp": 1578696143805, "ltp": 3.4, "tv": 6875.94, "trd": [[3.4, 827.94]], "batb": [[0, 3.4, 22.44]], "batl": NaN}, {"timestamp": 1578696167135, "ltp": 3.4, "tv": 6875.94, "trd": NaN, "batb": NaN, "batl": [[1, 3.5, 60]]}, {"timestamp": 1578696189832, "ltp": 3.45, "tv": 6896.6, "trd": [[3.45, 538.13]], "batb": NaN, "batl": [[0, 3.5, 60], [1, 3.55, 38.04], [2, 3.6, 17.03]]}, {"timestamp": 1578696190907, "ltp": 3.45, "tv": 6896.6, "trd": NaN, "batb": NaN, "batl": [[1, 3.55, 50.93]]}, {"timestamp": 1578696223581, "ltp": 3.45, "tv": 6896.6, "trd": NaN, "batb": NaN, "batl": [[1, 3.55, 12.05]]}, {"timestamp": 1578696232993, "ltp": 3.45, "tv": 6896.6, "trd": NaN, "batb": NaN, "batl": [[1, 3.55, 37.84]]}, {"timestamp": 1578696245565, "ltp": 3.45, "tv": 6896.6, "trd": NaN, "batb": NaN, "batl": [[1, 3.55, 50.72]]}, {"timestamp": 1578696266624, "ltp": 3.5, "tv": 6906.6, "trd": [[3.5, 1190.24]], "batb": NaN, "batl": [[0, 3.5, 55]]}, {"timestamp": 1578696282728, "ltp": 3.5, "tv": 6906.6, "trd": NaN, "batb": NaN, "batl": [[1, 3.55, 12.05]]}, {"timestamp": 1578696360995, "ltp": 3.5, "tv": 6906.6, "trd": NaN, "batb": NaN, "batl": [[2, 3.6, 30.93]]}, {"timestamp": 1578696418180, "ltp": 3.5, "tv": 6906.6, "trd": NaN, "batb": [[0, 3.4, 97.44]], "batl": NaN}, {"timestamp": 1578696419773, "ltp": 3.5, "tv": 6906.6, "trd": NaN, "batb": NaN, "batl": [[1, 3.55, 37.84]]}, {"timestamp": 1578696425993, "ltp": 3.4, "tv": 7101.48, "trd": [[3.4, 1022.82]], "batb": [[0, 3.35, 79.5], [1, 3.3, 75.62], [2, 3.25, 35.37]], "batl": [[0, 3.5, 55.56], [1, 3.55, 12.05]]}, {"timestamp": 1578696428372, "ltp": 3.4, "tv": 7101.48, "trd": NaN, "batb": NaN, "batl": [[0, 3.5, 55]]}, {"timestamp": 1578696618530, "ltp": 3.4, "tv": 7101.48, "trd": NaN, "batb": NaN, "batl": [[1, 3.55, 37.84]]}, {"timestamp": 1578696648281, "ltp": 3.4, "tv": 7101.48, "trd": NaN, "batb": NaN, "batl": [[1, 3.55, 50.72]]}, {"timestamp": 1578696719955, "ltp": 3.4, "tv": 7101.48, "trd": NaN, "batb": [[0, 3.4, 10], [1, 3.35, 79.5], [2, 3.3, 75.62]], "batl": NaN}, {"timestamp": 1578696838601, "ltp": 3.35, "tv": 7141.38, "trd": [[3.35, 1211.72], [3.4, 1042.82]], "batb": [[0, 3.35, 69.55], [1, 3.3, 75.62], [2, 3.25, 35.37]], "batl": [[0, 3.4, 190], [1, 3.5, 55], [2, 3.55, 50.72]]}, {"timestamp": 1578696848813, "ltp": 3.35, "tv": 7280.48, "trd": [[3.35, 1350.82]], "batb": [[0, 3.3, 75.62], [1, 3.25, 35.37], [2, 3.2, 9.52]], "batl": [[0, 3.35, 120.45]]}, {"timestamp": 1578696853844, "ltp": 3.35, "tv": 7280.48, "trd": NaN, "batb": [[2, 3.2, 27.52]], "batl": NaN}, {"timestamp": 1578696919931, "ltp": 3.35, "tv": 7521.38, "trd": [[3.35, 1591.72]], "batb": [[0, 3.4, 9.85], [1, 3.35, 79.55], [2, 3.3, 75.62]], "batl": [[0, 3.5, 55], [1, 3.55, 50.72], [2, 3.6, 30.93]]}, {"timestamp": 1578696951981, "ltp": 3.4, "tv": 7541.07, "trd": [[3.4, 1062.51]], "batb": [[0, 3.35, 79.56], [1, 3.3, 75.62], [2, 3.25, 35.37]], "batl": NaN}, {"timestamp": 1578696952967, "ltp": 3.4, "tv": 7541.07, "trd": NaN, "batb": NaN, "batl": [[1, 3.55, 12.05]]}, {"timestamp": 1578696982729, "ltp": 3.4, "tv": 7541.07, "trd": NaN, "batb": NaN, "batl": [[0, 3.45, 15.63], [1, 3.5, 70.63], [2, 3.55, 27.68]]}, {"timestamp": 1578697012940, "ltp": 3.4, "tv": 7541.07, "trd": NaN, "batb": NaN, "batl": [[0, 3.45, 28.62]]}, {"timestamp": 1578697042554, "ltp": 3.4, "tv": 7541.07, "trd": NaN, "batb": NaN, "batl": [[0, 3.45, 41.61]]}, {"timestamp": 1578697044974, "ltp": 3.4, "tv": 7541.07, "trd": NaN, "batb": [[0, 3.35, 79.55]], "batl": [[0, 3.4, 9.87], [1, 3.45, 41.61], [2, 3.5, 90.63]]}, {"timestamp": 1578697045946, "ltp": 3.4, "tv": 7541.07, "trd": NaN, "batb": NaN, "batl": [[0, 3.4, 36.08]]}, {"timestamp": 1578697097919, "ltp": 3.4, "tv": 7613.21, "trd": [[3.4, 1134.65]], "batb": [[0, 3.4, 13.94], [1, 3.35, 79.55], [2, 3.3, 75.62]], "batl": [[0, 3.45, 41.61], [1, 3.5, 90.63], [2, 3.55, 12.05]]}, {"timestamp": 1578697098530, "ltp": 3.4, "tv": 7613.21, "trd": NaN, "batb": NaN, "batl": [[0, 3.5, 75], [1, 3.55, 12.05], [2, 3.6, 30.93]]}, {"timestamp": 1578697099822, "ltp": 3.4, "tv": 7613.21, "trd": NaN, "batb": NaN, "batl": [[1, 3.55, 37.84]]}, {"timestamp": 1578697123973, "ltp": 3.4, "tv": 7613.21, "trd": NaN, "batb": NaN, "batl": [[0, 3.5, 78.06]]}, {"timestamp": 1578697129367, "ltp": 3.4, "tv": 7613.21, "trd": NaN, "batb": NaN, "batl": [[1, 3.55, 50.72]]}, {"timestamp": 1578697180810, "ltp": 3.4, "tv": 7613.21, "trd": NaN, "batb": NaN, "batl": [[0, 3.5, 80.06]]}, {"timestamp": 1578697184824, "ltp": 3.4, "tv": 7613.21, "trd": NaN, "batb": NaN, "batl": [[2, 3.6, 33.93]]}, {"timestamp": 1578697203924, "ltp": 3.4, "tv": 7612.47, "trd": [[3.25, 1009.25], [3.3, 1041.75], [3.35, 1591.63], [3.4, 1134.47], [3.45, 538.1], [3.5, 1190.18], [3.55, 305.53], [3.6, 137.47], [3.65, 118.67], [3.7, 146.83], [3.75, 96.04], [3.8, 96.95], [3.85, 60.01], [3.95, 52.84], [4, 59.97]], "batb": NaN, "batl": [[0, 3.5, 80.06], [1, 3.55, 50.69]]}, {"timestamp": 1578697209759, "ltp": 3.4, "tv": 7612.47, "trd": NaN, "batb": [[0, 3.4, 23.82]], "batl": [[0, 3.45, 5.1], [1, 3.5, 80.06], [2, 3.55, 12.05]]}, {"timestamp": 1578697433814, "ltp": 3.4, "tv": 7612.47, "trd": NaN, "batb": NaN, "batl": [[0, 3.45, 7.1]]}, {"timestamp": 1578697455857, "ltp": 3.4, "tv": 7628.47, "trd": [[3.4, 1150.47]], "batb": [[0, 3.4, 15.82]], "batl": NaN}, {"timestamp": 1578697458632, "ltp": 3.4, "tv": 7628.47, "trd": NaN, "batb": NaN, "batl": [[0, 3.45, 16.1]]}, {"timestamp": 1578697554240, "ltp": 3.4, "tv": 7648.47, "trd": [[3.4, 1170.47]], "batb": [[0, 3.4, 5.82]], "batl": NaN}, {"timestamp": 1578697696944, "ltp": 3.4, "tv": 7648.47, "trd": NaN, "batb": [[2, 3.3, 125.62]], "batl": NaN}, {"timestamp": 1578697736977, "ltp": 3.45, "tv": 7654.97, "trd": [[3.45, 544.6]], "batb": NaN, "batl": [[0, 3.45, 12.85]]}, {"timestamp": 1578697912998, "ltp": 3.4, "tv": 7666.61, "trd": [[3.4, 1182.11]], "batb": [[0, 3.35, 79.55], [1, 3.3, 125.62], [2, 3.25, 35.37]], "batl": NaN}, {"timestamp": 1578697913825, "ltp": 3.4, "tv": 7666.61, "trd": NaN, "batb": [[0, 3.35, 90.68]], "batl": NaN}, {"timestamp": 1578697947327, "ltp": 3.4, "tv": 7666.61, "trd": NaN, "batb": NaN, "batl": [[0, 3.45, 3.85]]}, {"timestamp": 1578697967933, "ltp": 3.35, "tv": 7706.61, "trd": [[3.35, 1631.63]], "batb": [[0, 3.35, 70.68]], "batl": NaN}, {"timestamp": 1578697980262, "ltp": 3.35, "tv": 7706.61, "trd": NaN, "batb": [[0, 3.35, 81.83]], "batl": NaN}, {"timestamp": 1578698039504, "ltp": 3.35, "tv": 7706.61, "trd": NaN, "batb": [[0, 3.4, 5.13], [1, 3.35, 81.83], [2, 3.3, 125.62]], "batl": NaN}, {"timestamp": 1578698102594, "ltp": 3.35, "tv": 7730.61, "trd": [[3.35, 1645.37], [3.4, 1192.37]], "batb": [[0, 3.35, 74.96], [1, 3.3, 125.62], [2, 3.25, 35.37]], "batl": NaN}, {"timestamp": 1578698446479, "ltp": 3.35, "tv": 7761.33, "trd": [[3.35, 1676.09]], "batb": [[0, 3.35, 59.6]], "batl": NaN}, {"timestamp": 1578698565747, "ltp": 3.35, "tv": 7761.33, "trd": NaN, "batb": NaN, "batl": [[0, 3.4, 13.2], [1, 3.45, 16.83], [2, 3.5, 80.06]]}, {"timestamp": 1578698566927, "ltp": 3.35, "tv": 7761.33, "trd": NaN, "batb": NaN, "batl": [[0, 3.45, 3.85], [1, 3.5, 80.06], [2, 3.55, 12.05]]}, {"timestamp": 1578698790593, "ltp": 3.35, "tv": 7761.33, "trd": NaN, "batb": [[1, 3.3, 75.62]], "batl": NaN}, {"timestamp": 1578698867020, "ltp": 3.35, "tv": 7765.33, "trd": [[3.35, 1680.09]], "batb": [[0, 3.35, 57.6]], "batl": NaN}, {"timestamp": 1578698870917, "ltp": 3.35, "tv": 7769.33, "trd": [[3.35, 1684.09]], "batb": [[0, 3.35, 55.6]], "batl": NaN}, {"timestamp": 1578698872821, "ltp": 3.35, "tv": 7880.52, "trd": [[3.35, 1795.28]], "batb": [[0, 3.3, 75.62], [1, 3.25, 35.37], [2, 3.2, 18.95]], "batl": NaN}, {"timestamp": 1578698873906, "ltp": 3.35, "tv": 7880.52, "trd": NaN, "batb": NaN, "batl": [[1, 3.5, 90.73]]}, {"timestamp": 1578698874729, "ltp": 3.35, "tv": 7880.52, "trd": NaN, "batb": NaN, "batl": [[0, 3.45, 14.66]]}, {"timestamp": 1578698962758, "ltp": 3.3, "tv": 7980.52, "trd": [[3.3, 1141.75]], "batb": [[0, 3.3, 25.62]], "batl": [[0, 3.4, 9.89], [1, 3.45, 14.66], [2, 3.5, 90.73]]}, {"timestamp": 1578698987676, "ltp": 3.3, "tv": 7980.52, "trd": NaN, "batb": NaN, "batl": [[2, 3.5, 80.73]]}, {"timestamp": 1578699001792, "ltp": 3.3, "tv": 8031.76, "trd": [[3.3, 1192.99]], "batb": [[0, 3.25, 35.37], [1, 3.2, 18.95], [2, 3.15, 10]], "batl": [[0, 3.3, 12.38], [1, 3.4, 9.89], [2, 3.45, 14.66]]}, {"timestamp": 1578699012223, "ltp": 3.25, "tv": 8057.76, "trd": [[3.25, 1035.25]], "batb": [[0, 3.25, 22.37]], "batl": NaN}, {"timestamp": 1578699178628, "ltp": 3.25, "tv": 8057.76, "trd": NaN, "batb": NaN, "batl": [[1, 3.4, 29.89]]}, {"timestamp": 1578699266705, "ltp": 3.25, "tv": 8098.2, "trd": [[3.25, 1075.69]], "batb": [[0, 3.25, 2.15]], "batl": NaN}, {"timestamp": 1578699538882, "ltp": 3.25, "tv": 8098.2, "trd": NaN, "batb": [[0, 3.25, 22.06]], "batl": NaN}, {"timestamp": 1578699544789, "ltp": 3.3, "tv": 8116.5, "trd": [[3.3, 1211.29]], "batb": NaN, "batl": [[0, 3.3, 3.23]]}, {"timestamp": 1578699572896, "ltp": 3.3, "tv": 8122.96, "trd": [[3.3, 1217.75]], "batb": [[0, 3.3, 15.91], [1, 3.25, 22.06], [2, 3.2, 18.95]], "batl": [[0, 3.4, 29.89], [1, 3.45, 14.66], [2, 3.5, 77.67]]}, {"timestamp": 1578699574895, "ltp": 3.3, "tv": 8122.96, "trd": NaN, "batb": [[0, 3.25, 37.97], [1, 3.2, 18.95], [2, 3.15, 10]], "batl": NaN}, {"timestamp": 1578699576898, "ltp": 3.3, "tv": 8122.96, "trd": NaN, "batb": NaN, "batl": [[0, 3.4, 33.03]]}, {"timestamp": 1578699937849, "ltp": 3.3, "tv": 8122.96, "trd": NaN, "batb": [[0, 3.25, 22.06]], "batl": [[0, 3.4, 29.89]]}, {"timestamp": 1578699939981, "ltp": 3.3, "tv": 8122.96, "trd": NaN, "batb": NaN, "batl": [[0, 3.35, 3.18], [1, 3.4, 29.89], [2, 3.45, 14.66]]}, {"timestamp": 1578700020244, "ltp": 3.3, "tv": 8122.96, "trd": NaN, "batb": NaN, "batl": [[1, 3.4, 56.3]]}, {"timestamp": 1578700038241, "ltp": 3.3, "tv": 8122.96, "trd": NaN, "batb": NaN, "batl": [[0, 3.35, 8.18]]}, {"timestamp": 1578700049996, "ltp": 3.3, "tv": 8122.96, "trd": NaN, "batb": NaN, "batl": [[1, 3.4, 69.51]]}, {"timestamp": 1578700050867, "ltp": 3.3, "tv": 8122.96, "trd": NaN, "batb": NaN, "batl": [[1, 3.4, 80.49]]}, {"timestamp": 1578700052494, "ltp": 3.3, "tv": 8122.96, "trd": NaN, "batb": NaN, "batl": [[0, 3.35, 19.32], [2, 3.45, 3.85]]}, {"timestamp": 1578700081831, "ltp": 3.3, "tv": 8122.96, "trd": NaN, "batb": [[0, 3.3, 17.02], [1, 3.25, 22.06], [2, 3.2, 18.95]], "batl": NaN}, {"timestamp": 1578700091926, "ltp": 3.3, "tv": 8122.96, "trd": NaN, "batb": [[0, 3.25, 22.06], [1, 3.2, 18.95], [2, 3.15, 10]], "batl": NaN}, {"timestamp": 1578700432544, "ltp": 3.3, "tv": 8122.96, "trd": NaN, "batb": [[0, 3.3, 101], [1, 3.25, 22.06], [2, 3.2, 18.95]], "batl": NaN}, {"timestamp": 1578700593738, "ltp": 3.3, "tv": 8162.96, "trd": [[3.3, 1257.75]], "batb": [[0, 3.3, 81]], "batl": NaN}, {"timestamp": 1578700611377, "ltp": 3.3, "tv": 8168.16, "trd": [[3.3, 1262.94]], "batb": [[0, 3.3, 78.4]], "batl": NaN}, {"timestamp": 1578700705496, "ltp": 3.35, "tv": 8186.19, "trd": [[3.35, 1813.3]], "batb": NaN, "batl": [[0, 3.35, 10.3]]}, {"timestamp": 1578700706782, "ltp": 3.35, "tv": 8186.19, "trd": NaN, "batb": NaN, "batl": [[0, 3.4, 69.51], [1, 3.45, 37.76], [2, 3.5, 67]]}, {"timestamp": 1578700723908, "ltp": 3.45, "tv": 8334.93, "trd": [[3.4, 1331.38], [3.45, 554.34]], "batb": [[0, 3.4, 130.5], [1, 3.3, 78.4], [2, 3.25, 22.06]], "batl": [[0, 3.45, 32.89], [1, 3.5, 67], [2, 3.55, 12.05]]}, {"timestamp": 1578700724929, "ltp": 3.45, "tv": 8334.93, "trd": NaN, "batb": NaN, "batl": [[0, 3.45, 10], [1, 3.5, 76.66]]}, {"timestamp": 1578700725801, "ltp": 3.45, "tv": 8334.93, "trd": NaN, "batb": NaN, "batl": [[0, 3.5, 86.52], [1, 3.55, 12.05], [2, 3.6, 20.03]]}, {"timestamp": 1578700726922, "ltp": 3.45, "tv": 8334.93, "trd": NaN, "batb": NaN, "batl": [[1, 3.55, 37.82]]}, {"timestamp": 1578700735960, "ltp": 3.45, "tv": 8334.93, "trd": NaN, "batb": NaN, "batl": [[1, 3.55, 50.69]]}, {"timestamp": 1578700786591, "ltp": 3.4, "tv": 8404.93, "trd": [[3.4, 1401.38]], "batb": [[0, 3.4, 95.5]], "batl": NaN}, {"timestamp": 1578700794918, "ltp": 3.4, "tv": 8595.93, "trd": [[3.4, 1592.37]], "batb": [[0, 3.3, 78.4], [1, 3.25, 22.06], [2, 3.2, 18.95]], "batl": NaN}, {"timestamp": 1578700797947, "ltp": 3.4, "tv": 8595.93, "trd": NaN, "batb": NaN, "batl": [[2, 3.6, 27.03]]}, {"timestamp": 1578700809451, "ltp": 3.3, "tv": 8604.45, "trd": [[3.3, 1271.46]], "batb": [[0, 3.3, 74.14]], "batl": NaN}, {"timestamp": 1578701029560, "ltp": 3.3, "tv": 8604.45, "trd": NaN, "batb": NaN, "batl": [[0, 3.5, 84.52]]}, {"timestamp": 1578701458771, "ltp": 3.3, "tv": 8604.45, "trd": NaN, "batb": NaN, "batl": [[2, 3.6, 29.03]]}, {"timestamp": 1578701521152, "ltp": 3.3, "tv": 8624.45, "trd": [[3.3, 1291.46]], "batb": [[0, 3.3, 64.14]], "batl": [[0, 3.45, 4.91], [1, 3.5, 84.52], [2, 3.55, 50.69]]}, {"timestamp": 1578701580954, "ltp": 3.45, "tv": 8628.45, "trd": [[3.45, 558.34]], "batb": NaN, "batl": [[0, 3.45, 2.91]]}, {"timestamp": 1578701686731, "ltp": 3.3, "tv": 8639.68, "trd": [[3.3, 1302.7]], "batb": [[0, 3.3, 58.52]], "batl": NaN}, {"timestamp": 1578702105961, "ltp": 3.3, "tv": 8639.68, "trd": NaN, "batb": NaN, "batl": [[0, 3.45, 28.88]]}, {"timestamp": 1578702546917, "ltp": 3.3, "tv": 8679.68, "trd": [[3.3, 1342.7]], "batb": [[0, 3.3, 38.52]], "batl": NaN}, {"timestamp": 1578702736751, "ltp": 3.3, "tv": 8756.72, "trd": [[3.3, 1419.74]], "batb": [[0, 3.25, 22.06], [1, 3.2, 18.95], [2, 3.15, 10]], "batl": [[0, 3.3, 11.48], [1, 3.45, 28.88], [2, 3.5, 84.52]]}, {"timestamp": 1578702737062, "ltp": 3.3, "tv": 8756.72, "trd": NaN, "batb": NaN, "batl": [[1, 3.45, 42.19]]}, {"timestamp": 1578702742869, "ltp": 3.25, "tv": 8779.68, "trd": [[3.25, 1098.65]], "batb": [[0, 3.25, 10.58]], "batl": [[0, 3.45, 42.19], [1, 3.5, 84.52], [2, 3.55, 12.05]]}, {"timestamp": 1578702830988, "ltp": 3.25, "tv": 8779.68, "trd": NaN, "batb": [[0, 3.25, 13.58]], "batl": [[2, 3.55, 18.8]]}, {"timestamp": 1578702967587, "ltp": 3.25, "tv": 8799.68, "trd": [[3.25, 1118.66]], "batb": [[0, 3.25, 3.58]], "batl": NaN}, {"timestamp": 1578703085999, "ltp": 3.45, "tv": 8818.8, "trd": [[3.45, 577.46]], "batb": NaN, "batl": [[0, 3.45, 32.64]]}, {"timestamp": 1578703139695, "ltp": 3.45, "tv": 8818.8, "trd": NaN, "batb": [[0, 3.25, 3]], "batl": NaN}, {"timestamp": 1578703513670, "ltp": 3.45, "tv": 8818.8, "trd": NaN, "batb": [[0, 3.25, 8.37]], "batl": NaN}, {"timestamp": 1578703612952, "ltp": 3.25, "tv": 8838.8, "trd": [[3.25, 1138.66]], "batb": [[0, 3.25, 8.63]], "batl": NaN}, {"timestamp": 1578704269001, "ltp": 3.25, "tv": 8850.56, "trd": [[3.25, 1150.42]], "batb": [[0, 3.2, 18.95], [1, 3.15, 10], [2, 3.1, 50]], "batl": [[0, 3.4, 7.13], [1, 3.45, 32.64], [2, 3.5, 84.52]]}, {"timestamp": 1578704274533, "ltp": 3.25, "tv": 8850.56, "trd": NaN, "batb": NaN, "batl": [[0, 3.4, 20.22]]}, {"timestamp": 1578704279295, "ltp": 3.25, "tv": 8850.56, "trd": NaN, "batb": [[0, 3.25, 56.64], [1, 3.2, 18.95], [2, 3.15, 10]], "batl": NaN}, {"timestamp": 1578704362988, "ltp": 3.25, "tv": 8850.56, "trd": NaN, "batb": [[0, 3.3, 8.77], [1, 3.25, 56.64], [2, 3.2, 18.95]], "batl": NaN}, {"timestamp": 1578704375905, "ltp": 3.25, "tv": 8850.56, "trd": NaN, "batb": [[1, 3.2, 18.95], [2, 3.15, 10]], "batl": NaN}, {"timestamp": 1578704390913, "ltp": 3.25, "tv": 8850.56, "trd": NaN, "batb": [[1, 3.25, 4.57], [2, 3.2, 18.95]], "batl": NaN}, {"timestamp": 1578704445917, "ltp": 3.25, "tv": 8850.56, "trd": NaN, "batb": NaN, "batl": [[0, 3.35, 8.51], [1, 3.4, 20.22], [2, 3.45, 32.64]]}, {"timestamp": 1578704449700, "ltp": 3.3, "tv": 8868.11, "trd": [[3.3, 1437.28]], "batb": [[0, 3.25, 4.57], [1, 3.2, 18.95], [2, 3.15, 10]], "batl": [[0, 3.4, 20.22], [1, 3.45, 32.64], [2, 3.5, 84.52]]}, {"timestamp": 1578704605634, "ltp": 3.3, "tv": 8868.11, "trd": NaN, "batb": NaN, "batl": [[0, 3.4, 30.22]]}, {"timestamp": 1578705235559, "ltp": 3.3, "tv": 8868.11, "trd": NaN, "batb": [[0, 3.2, 18.95], [1, 3.15, 10], [2, 3.1, 50]], "batl": NaN}, {"timestamp": 1578705238956, "ltp": 3.3, "tv": 8868.11, "trd": NaN, "batb": [[0, 3.25, 18.03], [1, 3.2, 18.95], [2, 3.15, 10]], "batl": NaN}, {"timestamp": 1578705240967, "ltp": 3.3, "tv": 8868.11, "trd": NaN, "batb": [[0, 3.3, 24.56], [1, 3.25, 18.03], [2, 3.2, 18.95]], "batl": NaN}, {"timestamp": 1578705381707, "ltp": 3.3, "tv": 8868.11, "trd": NaN, "batb": NaN, "batl": [[0, 3.35, 3.4], [1, 3.4, 30.22], [2, 3.45, 32.64]]}, {"timestamp": 1578705382687, "ltp": 3.35, "tv": 8871.51, "trd": [[3.35, 1816.71]], "batb": NaN, "batl": [[0, 3.4, 30.22], [1, 3.45, 32.64], [2, 3.5, 84.52]]}, {"timestamp": 1578705384804, "ltp": 3.35, "tv": 8871.51, "trd": NaN, "batb": [[0, 3.35, 1.7], [1, 3.3, 24.56], [2, 3.25, 18.03]], "batl": NaN}, {"timestamp": 1578705386810, "ltp": 3.35, "tv": 8871.51, "trd": NaN, "batb": [[0, 3.3, 24.56], [1, 3.25, 18.03], [2, 3.2, 18.95]], "batl": NaN}, {"timestamp": 1578705387222, "ltp": 3.4, "tv": 8874.87, "trd": [[3.4, 1595.73]], "batb": NaN, "batl": [[0, 3.4, 28.54]]}, {"timestamp": 1578705453599, "ltp": 3.45, "tv": 8997.22, "trd": [[3.4, 1652.81], [3.45, 642.72]], "batb": [[0, 3.45, 43.79], [1, 3.3, 24.56], [2, 3.25, 18.03]], "batl": [[0, 3.5, 84.52], [1, 3.55, 37.82], [2, 3.6, 22.03]]}, {"timestamp": 1578705483242, "ltp": 3.45, "tv": 8997.22, "trd": NaN, "batb": NaN, "batl": [[1, 3.55, 50.69]]}, {"timestamp": 1578705568058, "ltp": 3.45, "tv": 8997.22, "trd": NaN, "batb": NaN, "batl": [[1, 3.55, 12.05]]}, {"timestamp": 1578705595454, "ltp": 3.45, "tv": 9033.26, "trd": [[3.45, 678.76]], "batb": [[0, 3.45, 25.77]], "batl": NaN}, {"timestamp": 1578706053172, "ltp": 3.45, "tv": 9033.26, "trd": NaN, "batb": NaN, "batl": [[1, 3.55, 37.82]]}, {"timestamp": 1578706082983, "ltp": 3.45, "tv": 9033.26, "trd": NaN, "batb": NaN, "batl": [[1, 3.55, 50.69]]}, {"timestamp": 1578706283043, "ltp": 3.45, "tv": 9044.5, "trd": [[3.45, 690]], "batb": [[0, 3.45, 20.15]], "batl": NaN}, {"timestamp": 1578706721236, "ltp": 3.45, "tv": 9044.5, "trd": NaN, "batb": NaN, "batl": [[0, 3.5, 97.4], [1, 3.55, 37.82]]}, {"timestamp": 1578706970897, "ltp": 3.45, "tv": 9064.5, "trd": [[3.45, 710]], "batb": [[0, 3.45, 10.15]], "batl": NaN}, {"timestamp": 1578707082462, "ltp": 3.45, "tv": 9084.8, "trd": [[3.45, 730.31]], "batb": [[0, 3.3, 24.56], [1, 3.25, 18.03], [2, 3.2, 18.95]], "batl": [[0, 3.4, 12.98], [1, 3.45, 29.62], [2, 3.5, 84.52]]}, {"timestamp": 1578707087378, "ltp": 3.45, "tv": 9084.8, "trd": NaN, "batb": NaN, "batl": [[0, 3.4, 28.29]]}, {"timestamp": 1578707112215, "ltp": 3.45, "tv": 9084.8, "trd": NaN, "batb": NaN, "batl": [[0, 3.4, 41.38]]}, {"timestamp": 1578707218977, "ltp": 3.45, "tv": 9084.8, "trd": NaN, "batb": [[0, 3.35, 5.21], [1, 3.3, 24.56], [2, 3.25, 18.03]], "batl": NaN}, {"timestamp": 1578707774400, "ltp": 3.35, "tv": 9095.22, "trd": [[3.35, 1827.13]], "batb": [[0, 3.3, 24.56], [1, 3.25, 18.03], [2, 3.2, 18.95]], "batl": [[0, 3.35, 206.79], [1, 3.4, 41.38], [2, 3.45, 29.62]]}, {"timestamp": 1578707775691, "ltp": 3.3, "tv": 9144.33, "trd": [[3.3, 1486.4]], "batb": [[0, 3.25, 18.03], [1, 3.2, 18.95], [2, 3.15, 10]], "batl": [[0, 3.3, 4.19], [1, 3.35, 227.18], [2, 3.4, 41.38]]}, {"timestamp": 1578707776205, "ltp": 3.35, "tv": 9157.95, "trd": [[3.3, 1494.77], [3.35, 1832.37]], "batb": NaN, "batl": [[0, 3.35, 224.56], [1, 3.4, 41.38], [2, 3.45, 16.64]]}, {"timestamp": 1578707777698, "ltp": 3.35, "tv": 9157.95, "trd": NaN, "batb": NaN, "batl": [[1, 3.4, 54.59]]}, {"timestamp": 1578707784673, "ltp": 3.0, "tv": 9446.85, "trd": [[3, 88.22], [3.05, 6.72], [3.1, 100], [3.15, 20], [3.2, 37.9], [3.25, 1186.48]], "batb": [[0, 2.9, 10], [1, 2.8, 90], [2, 2.64, 93.9]], "batl": [[0, 3, 59.72], [1, 3.35, 20.39], [2, 3.4, 54.59]]}, {"timestamp": 1578707785703, "ltp": 3.0, "tv": 9522.91, "trd": [[3, 164.28]], "batb": NaN, "batl": [[0, 3, 21.69], [1, 3.35, 10.3]]}, {"timestamp": 1578707786985, "ltp": 3.0, "tv": 9566.29, "trd": [[3, 207.66]], "batb": [[0, 3, 1.73], [1, 2.94, 11], [2, 2.92, 2.14]], "batl": [[0, 3.1, 8.11], [1, 3.4, 54.59], [2, 3.45, 16.64]]}, {"timestamp": 1578707787876, "ltp": 3.0, "tv": 9566.29, "trd": NaN, "batb": [[1, 2.96, 9.2], [2, 2.94, 11]], "batl": NaN}, {"timestamp": 1578707796978, "ltp": 3.0, "tv": 9566.29, "trd": NaN, "batb": [[1, 2.98, 61.77], [2, 2.96, 9.2]], "batl": NaN}, {"timestamp": 1578707814429, "ltp": 3.1, "tv": 9568.61, "trd": [[3.1, 102.32]], "batb": NaN, "batl": [[0, 3.1, 6.95]]}, {"timestamp": 1578707816539, "ltp": 3.1, "tv": 9570.17, "trd": [[3.1, 103.88]], "batb": NaN, "batl": [[0, 3.1, 6.17]]}, {"timestamp": 1578707818952, "ltp": 3.1, "tv": 9571.73, "trd": [[3.1, 105.44]], "batb": NaN, "batl": [[0, 3.1, 5.39]]}, {"timestamp": 1578707821839, "ltp": 3.1, "tv": 9572.25, "trd": [[3.1, 105.96]], "batb": NaN, "batl": [[0, 3.1, 5.13]]}, {"timestamp": 1578707823530, "ltp": 3.1, "tv": 9572.77, "trd": [[3.1, 106.48]], "batb": NaN, "batl": [[0, 3.1, 4.87]]}, {"timestamp": 1578707825640, "ltp": 3.1, "tv": 9572.97, "trd": [[3.1, 106.68]], "batb": NaN, "batl": [[0, 3.1, 4.77]]}, {"timestamp": 1578707827862, "ltp": 3.1, "tv": 9573.17, "trd": [[3.1, 106.88]], "batb": NaN, "batl": [[0, 3.1, 4.67]]}, {"timestamp": 1578707829930, "ltp": 3.1, "tv": 9582.51, "trd": [[3.1, 116.22]], "batb": [[0, 3.2, 2.07], [1, 3.15, 3.5], [2, 3, 1.73]], "batl": [[0, 3.4, 54.59], [1, 3.45, 16.64], [2, 3.5, 65]]}, {"timestamp": 1578707830340, "ltp": 3.1, "tv": 9582.51, "trd": NaN, "batb": [[0, 3, 1.83], [1, 2.98, 61.77], [2, 2.96, 13.3]], "batl": [[1, 3.45, 35.24]]}, {"timestamp": 1578707831831, "ltp": 3.1, "tv": 9582.51, "trd": NaN, "batb": [[2, 2.96, 9.2]], "batl": NaN}, {"timestamp": 1578707832240, "ltp": 3.1, "tv": 9582.51, "trd": NaN, "batb": [[0, 3.1, 11.4], [1, 3, 1.73], [2, 2.98, 61.77]], "batl": NaN}, {"timestamp": 1578707834825, "ltp": 3.1, "tv": 9582.51, "trd": NaN, "batb": [[2, 2.96, 9.2]], "batl": [[0, 3.35, 10.72], [1, 3.4, 54.59], [2, 3.45, 35.24]]}, {"timestamp": 1578707835766, "ltp": 3.1, "tv": 9582.51, "trd": NaN, "batb": NaN, "batl": [[0, 3.35, 16.08]]}, {"timestamp": 1578707838859, "ltp": 3.1, "tv": 9582.51, "trd": NaN, "batb": [[2, 2.98, 3.29]], "batl": [[0, 3.3, 2.97], [1, 3.35, 16.08], [2, 3.4, 54.59]]}, {"timestamp": 1578707845980, "ltp": 3.1, "tv": 9582.51, "trd": NaN, "batb": NaN, "batl": [[0, 3.3, 6.97]]}, {"timestamp": 1578707891576, "ltp": 3.1, "tv": 9582.51, "trd": NaN, "batb": [[2, 2.98, 11.92]], "batl": NaN}, {"timestamp": 1578708594468, "ltp": 3.1, "tv": 9582.51, "trd": NaN, "batb": [[0, 3.15, 3.84], [1, 3.1, 11.4], [2, 3, 1.73]], "batl": NaN}, {"timestamp": 1578708597919, "ltp": 3.1, "tv": 9582.51, "trd": NaN, "batb": [[2, 3, 9.87]], "batl": NaN}, {"timestamp": 1578708602827, "ltp": 3.1, "tv": 9582.51, "trd": NaN, "batb": NaN, "batl": [[0, 3.3, 4]]}, {"timestamp": 1578708610924, "ltp": 3.1, "tv": 9582.51, "trd": NaN, "batb": NaN, "batl": [[0, 3.35, 16.08], [1, 3.4, 54.59], [2, 3.45, 16.64]]}, {"timestamp": 1578709437761, "ltp": 3.1, "tv": 9582.51, "trd": NaN, "batb": NaN, "batl": [[2, 3.45, 22.39]]}, {"timestamp": 1578710699844, "ltp": 3.1, "tv": 9582.51, "trd": NaN, "batb": NaN, "batl": [[1, 3.4, 61.59], [2, 3.45, 16.64]]}, {"timestamp": 1578711546729, "ltp": 3.1, "tv": 9582.51, "trd": NaN, "batb": NaN, "batl": [[1, 3.4, 54.59], [2, 3.45, 21.94]]}, {"timestamp": 1578711619969, "ltp": 3.15, "tv": 9598.51, "trd": [[3.15, 36]], "batb": [[0, 3.15, 10.29]], "batl": NaN}, {"timestamp": 1578711620487, "ltp": 3.15, "tv": 9598.51, "trd": NaN, "batb": [[0, 3.15, 6.29]], "batl": NaN}, {"timestamp": 1578711646944, "ltp": 3.15, "tv": 9598.51, "trd": NaN, "batb": [[0, 3.15, 11.4]], "batl": NaN}, {"timestamp": 1578711958911, "ltp": 3.15, "tv": 9598.51, "trd": NaN, "batb": [[0, 3.15, 14.63]], "batl": NaN}, {"timestamp": 1578711999586, "ltp": 3.35, "tv": 9615.13, "trd": [[3.35, 1848.98]], "batb": NaN, "batl": [[0, 3.35, 7.77]]}, {"timestamp": 1578712003359, "ltp": 3.35, "tv": 9615.13, "trd": NaN, "batb": [[0, 3.15, 69.63]], "batl": NaN}, {"timestamp": 1578712004282, "ltp": 3.35, "tv": 9615.13, "trd": NaN, "batb": [[2, 3.05, 8.7]], "batl": NaN}, {"timestamp": 1578712810444, "ltp": 3.4, "tv": 9632.89, "trd": [[3.35, 1864.53], [3.4, 1655.03]], "batb": NaN, "batl": [[0, 3.4, 53.48], [1, 3.45, 21.94], [2, 3.5, 65]]}, {"timestamp": 1578712822975, "ltp": 3.4, "tv": 9632.89, "trd": NaN, "batb": NaN, "batl": [[0, 3.35, 4], [1, 3.4, 53.48], [2, 3.45, 21.94]]}, {"timestamp": 1578712873848, "ltp": 3.4, "tv": 9650.65, "trd": [[3.35, 1872.53], [3.4, 1664.79]], "batb": NaN, "batl": [[0, 3.4, 48.6], [1, 3.45, 21.94], [2, 3.5, 65]]}, {"timestamp": 1578712888864, "ltp": 3.4, "tv": 9650.65, "trd": NaN, "batb": [[0, 3.2, 4.19], [1, 3.15, 69.63], [2, 3.1, 11.4]], "batl": NaN}, {"timestamp": 1578712889842, "ltp": 3.4, "tv": 9650.65, "trd": NaN, "batb": [[1, 3.15, 73.47]], "batl": NaN}, {"timestamp": 1578712890825, "ltp": 3.4, "tv": 9650.65, "trd": NaN, "batb": [[1, 3.15, 78.05]], "batl": NaN}, {"timestamp": 1578712932726, "ltp": 3.4, "tv": 9668.41, "trd": [[3.4, 1682.55]], "batb": NaN, "batl": [[0, 3.4, 39.72]]}, {"timestamp": 1578713152935, "ltp": 3.4, "tv": 9668.41, "trd": NaN, "batb": NaN, "batl": [[0, 3.3, 1.53], [1, 3.4, 39.72], [2, 3.45, 21.94]]}, {"timestamp": 1578713153350, "ltp": 3.4, "tv": 9668.41, "trd": NaN, "batb": NaN, "batl": [[0, 3.4, 39.72], [1, 3.45, 21.94], [2, 3.5, 65]]}, {"timestamp": 1578713418325, "ltp": 3.4, "tv": 9668.41, "trd": NaN, "batb": NaN, "batl": [[0, 3.35, 2], [1, 3.4, 39.72], [2, 3.45, 21.94]]}, {"timestamp": 1578713426680, "ltp": 3.2, "tv": 9668.61, "trd": [[3.2, 38.1]], "batb": [[0, 3.2, 4.09]], "batl": NaN}, {"timestamp": 1578713962299, "ltp": 3.2, "tv": 9668.61, "trd": NaN, "batb": [[0, 3.2, 154.09]], "batl": NaN}, {"timestamp": 1578713963442, "ltp": 3.2, "tv": 9668.61, "trd": NaN, "batb": [[0, 3.25, 36.56], [1, 3.2, 154.09], [2, 3.15, 69.63]], "batl": NaN}, {"timestamp": 1578713967321, "ltp": 3.2, "tv": 9668.61, "trd": NaN, "batb": [[1, 3.2, 150]], "batl": NaN}, {"timestamp": 1578713999885, "ltp": 3.2, "tv": 9668.61, "trd": NaN, "batb": [[0, 3.3, 3.96], [1, 3.25, 36.56], [2, 3.2, 150]], "batl": NaN}, {"timestamp": 1578714000977, "ltp": 3.35, "tv": 9672.61, "trd": [[3.35, 1876.53]], "batb": NaN, "batl": [[0, 3.4, 39.72], [1, 3.45, 21.94], [2, 3.5, 65]]}, {"timestamp": 1578714059569, "ltp": 3.35, "tv": 9672.61, "trd": NaN, "batb": NaN, "batl": [[1, 3.45, 16.64], [2, 3.5, 71]]}, {"timestamp": 1578715216163, "ltp": 3.35, "tv": 9672.61, "trd": NaN, "batb": NaN, "batl": [[0, 3.35, 1.88], [1, 3.4, 39.72], [2, 3.45, 16.64]]}, {"timestamp": 1578715220935, "ltp": 3.3, "tv": 9676.37, "trd": [[3.3, 1498.53]], "batb": [[0, 3.3, 2.08]], "batl": NaN}, {"timestamp": 1578715221816, "ltp": 3.3, "tv": 9680.13, "trd": [[3.3, 1502.29]], "batb": [[0, 3.25, 36.76], [1, 3.2, 150], [2, 3.15, 61.29]], "batl": NaN}, {"timestamp": 1578715222126, "ltp": 3.3, "tv": 9680.53, "trd": [[3.3, 1502.69]], "batb": [[0, 3.25, 36.56]], "batl": [[0, 3.3, 1.68], [1, 3.35, 1.88], [2, 3.4, 39.72]]}, {"timestamp": 1578715239852, "ltp": 3.3, "tv": 9680.53, "trd": NaN, "batb": NaN, "batl": [[0, 3.4, 39.72], [1, 3.45, 16.64], [2, 3.5, 71]]}, {"timestamp": 1578715363887, "ltp": 3.3, "tv": 9680.53, "trd": NaN, "batb": NaN, "batl": [[0, 3.3, 1.88], [1, 3.4, 39.72], [2, 3.45, 16.64]]}, {"timestamp": 1578715365961, "ltp": 3.3, "tv": 9680.53, "trd": NaN, "batb": NaN, "batl": [[0, 3.4, 39.72], [1, 3.45, 16.64], [2, 3.5, 71]]}, {"timestamp": 1578716214638, "ltp": 3.3, "tv": 9680.53, "trd": NaN, "batb": NaN, "batl": [[0, 3.3, 1.88], [1, 3.4, 39.72], [2, 3.45, 16.64]]}, {"timestamp": 1578716216856, "ltp": 3.3, "tv": 9680.53, "trd": NaN, "batb": NaN, "batl": [[0, 3.4, 39.72], [1, 3.45, 16.64], [2, 3.5, 71]]}, {"timestamp": 1578716223972, "ltp": 3.25, "tv": 9700.19, "trd": [[3.25, 1206.14]], "batb": [[0, 3.25, 26.73]], "batl": NaN}, {"timestamp": 1578716861816, "ltp": 3.25, "tv": 9700.19, "trd": NaN, "batb": NaN, "batl": [[0, 3.35, 10], [1, 3.4, 39.72], [2, 3.45, 16.64]]}, {"timestamp": 1578716862703, "ltp": 3.25, "tv": 9700.19, "trd": NaN, "batb": NaN, "batl": [[0, 3.35, 15]]}, {"timestamp": 1578717279319, "ltp": 3.35, "tv": 9718.37, "trd": [[3.35, 1894.71]], "batb": NaN, "batl": [[0, 3.35, 5.91]]}, {"timestamp": 1578717430916, "ltp": 3.35, "tv": 9718.37, "trd": NaN, "batb": NaN, "batl": [[0, 3.35, 15.91]]}, {"timestamp": 1578719027791, "ltp": 3.25, "tv": 9758.38, "trd": [[3.25, 1246.15]], "batb": [[0, 3.25, 6.72]], "batl": NaN}, {"timestamp": 1578719028610, "ltp": 3.25, "tv": 9758.38, "trd": NaN, "batb": NaN, "batl": [[2, 3.45, 30.02]]}, {"timestamp": 1578719589979, "ltp": 3.25, "tv": 9758.38, "trd": NaN, "batb": NaN, "batl": [[0, 3.3, 6], [1, 3.35, 15.91], [2, 3.4, 39.72]]}, {"timestamp": 1578719590498, "ltp": 3.3, "tv": 9770.38, "trd": [[3.3, 1514.69]], "batb": NaN, "batl": [[0, 3.35, 15.91], [1, 3.4, 39.72], [2, 3.45, 30.02]]}, {"timestamp": 1578719612295, "ltp": 3.3, "tv": 9770.38, "trd": NaN, "batb": NaN, "batl": [[0, 3.3, 6], [1, 3.35, 15.91], [2, 3.4, 39.72]]}, {"timestamp": 1578720053620, "ltp": 3.25, "tv": 9783.82, "trd": [[3.25, 1259.59]], "batb": [[0, 3.2, 150], [1, 3.15, 61.29], [2, 3.1, 11.4]], "batl": NaN}, {"timestamp": 1578720055910, "ltp": 3.25, "tv": 9783.82, "trd": NaN, "batb": NaN, "batl": [[2, 3.4, 53.29]]}, {"timestamp": 1578720068695, "ltp": 3.25, "tv": 9783.82, "trd": NaN, "batb": NaN, "batl": [[0, 3.3, 11]]}, {"timestamp": 1578720069008, "ltp": 3.25, "tv": 9783.82, "trd": NaN, "batb": NaN, "batl": [[0, 3.3, 16]]}, {"timestamp": 1578720070190, "ltp": 3.25, "tv": 9783.82, "trd": NaN, "batb": NaN, "batl": [[1, 3.35, 29.68]]}, {"timestamp": 1578720863281, "ltp": 3.25, "tv": 9783.82, "trd": NaN, "batb": NaN, "batl": [[0, 3.3, 10]]}, {"timestamp": 1578720864569, "ltp": 3.25, "tv": 9783.82, "trd": NaN, "batb": NaN, "batl": [[1, 3.35, 15.91], [2, 3.4, 53.3]]}, {"timestamp": 1578720865598, "ltp": 3.25, "tv": 9783.82, "trd": NaN, "batb": NaN, "batl": [[2, 3.4, 39.72]]}, {"timestamp": 1578721120541, "ltp": 3.25, "tv": 9783.82, "trd": NaN, "batb": [[2, 3, 19.92]], "batl": NaN}, {"timestamp": 1578721121929, "ltp": 3.25, "tv": 9783.82, "trd": NaN, "batb": [[0, 3.25, 5.36], [1, 3.2, 150], [2, 3.15, 61.29]], "batl": NaN}, {"timestamp": 1578721122235, "ltp": 3.25, "tv": 9783.82, "trd": NaN, "batb": [[0, 3.25, 10.72]], "batl": NaN}, {"timestamp": 1578721125840, "ltp": 3.25, "tv": 9783.82, "trd": NaN, "batb": NaN, "batl": [[2, 3.4, 26.29]]}, {"timestamp": 1578721128937, "ltp": 3.25, "tv": 9783.82, "trd": NaN, "batb": [[0, 3.2, 150], [1, 3.15, 61.29], [2, 3, 19.92]], "batl": NaN}, {"timestamp": 1578721129448, "ltp": 3.25, "tv": 9783.82, "trd": NaN, "batb": [[0, 3.25, 29.32], [1, 3.2, 150], [2, 3.15, 61.29]], "batl": NaN}, {"timestamp": 1578721169657, "ltp": 3.25, "tv": 9793.82, "trd": [[3.25, 1269.58]], "batb": [[0, 3.25, 24.32]], "batl": NaN}, {"timestamp": 1578721191857, "ltp": 3.3, "tv": 9813.82, "trd": [[3.3, 1534.69]], "batb": NaN, "batl": [[0, 3.35, 15.91], [1, 3.4, 26.29], [2, 3.45, 30.02]]}, {"timestamp": 1578721192992, "ltp": 3.3, "tv": 9813.82, "trd": NaN, "batb": NaN, "batl": [[2, 3.45, 43.39]]}, {"timestamp": 1578721210726, "ltp": 3.3, "tv": 9813.82, "trd": NaN, "batb": [[0, 3.25, 31.32]], "batl": NaN}, {"timestamp": 1578721487701, "ltp": 3.3, "tv": 9813.82, "trd": NaN, "batb": NaN, "batl": [[0, 3.4, 26.29], [1, 3.45, 43.39], [2, 3.5, 65]]}, {"timestamp": 1578721488675, "ltp": 3.3, "tv": 9813.82, "trd": NaN, "batb": NaN, "batl": [[0, 3.35, 5], [1, 3.4, 26.29], [2, 3.45, 43.39]]}, {"timestamp": 1578721489803, "ltp": 3.3, "tv": 9813.82, "trd": NaN, "batb": NaN, "batl": [[0, 3.35, 10]]}, {"timestamp": 1578721582930, "ltp": 3.35, "tv": 9833.82, "trd": [[3.35, 1914.71]], "batb": NaN, "batl": [[0, 3.4, 26.29], [1, 3.45, 43.39], [2, 3.5, 65]]}, {"timestamp": 1578721707965, "ltp": 3.35, "tv": 9833.82, "trd": NaN, "batb": [[0, 3.3, 7.66], [1, 3.25, 31.32], [2, 3.2, 150]], "batl": NaN}, {"timestamp": 1578722052695, "ltp": 3.35, "tv": 9833.82, "trd": NaN, "batb": NaN, "batl": [[1, 3.45, 52.94]]}, {"timestamp": 1578722434821, "ltp": 3.35, "tv": 9833.82, "trd": NaN, "batb": NaN, "batl": [[0, 3.4, 35.29]]}, {"timestamp": 1578722440919, "ltp": 3.35, "tv": 9833.82, "trd": NaN, "batb": NaN, "batl": [[1, 3.45, 59.68]]}, {"timestamp": 1578722470944, "ltp": 3.35, "tv": 9833.82, "trd": NaN, "batb": NaN, "batl": [[1, 3.45, 50.13]]}, {"timestamp": 1578722998765, "ltp": 3.4, "tv": 9852.82, "trd": [[3.4, 1701.55]], "batb": NaN, "batl": [[0, 3.4, 25.79]]}, {"timestamp": 1578723289930, "ltp": 3.3, "tv": 9893.68, "trd": [[3.3, 1575.55]], "batb": [[0, 3.25, 31.32], [1, 3.2, 152.49], [2, 3.15, 61.29]], "batl": [[0, 3.3, 22.13], [1, 3.4, 25.79], [2, 3.45, 50.13]]}, {"timestamp": 1578723291729, "ltp": 3.3, "tv": 9893.68, "trd": NaN, "batb": [[1, 3.2, 150]], "batl": NaN}, {"timestamp": 1578723303932, "ltp": 3.3, "tv": 9894.97, "trd": [[3.3, 1576.85]], "batb": NaN, "batl": [[0, 3.3, 21.48]]}, {"timestamp": 1578723338682, "ltp": 3.25, "tv": 9937.94, "trd": [[3.25, 1312.55]], "batb": [[0, 3.25, 9.84]], "batl": [[0, 3.4, 25.79], [1, 3.45, 50.13], [2, 3.5, 65]]}, {"timestamp": 1578723348233, "ltp": 3.25, "tv": 9956.66, "trd": [[3.25, 1331.27]], "batb": [[0, 3.2, 150.48], [1, 3.15, 63.61], [2, 3, 19.92]], "batl": NaN}, {"timestamp": 1578723362840, "ltp": 3.2, "tv": 10041.78, "trd": [[3.2, 122.26], [3.25, 1332.23]], "batb": [[0, 3.2, 107.92], [1, 3.15, 61.29]], "batl": NaN}, {"timestamp": 1578723697116, "ltp": 3.2, "tv": 10041.78, "trd": NaN, "batb": [[0, 3.25, 4.26], [1, 3.2, 107.92], [2, 3.15, 61.29]], "batl": NaN}, {"timestamp": 1578724119954, "ltp": 3.4, "tv": 10061.02, "trd": [[3.4, 1720.78]], "batb": NaN, "batl": [[0, 3.4, 16.18]]}, {"timestamp": 1578724123660, "ltp": 3.4, "tv": 10061.02, "trd": NaN, "batb": NaN, "batl": [[0, 3.4, 28.94]]}, {"timestamp": 1578724156821, "ltp": 3.4, "tv": 10061.02, "trd": NaN, "batb": [[0, 3.25, 13.38]], "batl": [[1, 3.45, 59.13]]}, {"timestamp": 1578724227922, "ltp": 3.4, "tv": 10061.02, "trd": NaN, "batb": NaN, "batl": [[1, 3.45, 50.13]]}, {"timestamp": 1578724328971, "ltp": 3.4, "tv": 10061.02, "trd": NaN, "batb": [[0, 3.3, 29.66], [1, 3.25, 13.38], [2, 3.2, 107.92]], "batl": NaN}, {"timestamp": 1578724360319, "ltp": 3.35, "tv": 10068.78, "trd": [[3.35, 1922.47]], "batb": [[0, 3.35, 2.93], [1, 3.3, 29.66], [2, 3.25, 9.12]], "batl": NaN}, {"timestamp": 1578724372999, "ltp": 3.35, "tv": 10068.78, "trd": NaN, "batb": [[2, 3.2, 107.92]], "batl": NaN}, {"timestamp": 1578724376726, "ltp": 3.35, "tv": 10068.78, "trd": NaN, "batb": [[2, 3.25, 6]], "batl": NaN}, {"timestamp": 1578724388747, "ltp": 3.4, "tv": 10086.78, "trd": [[3.4, 1738.78]], "batb": NaN, "batl": [[0, 3.4, 19.95]]}, {"timestamp": 1578724473956, "ltp": 3.35, "tv": 10092.64, "trd": [[3.35, 1928.33]], "batb": [[0, 3.3, 29.66], [1, 3.25, 6], [2, 3.2, 107.92]], "batl": [[0, 3.4, 20.02]]}, {"timestamp": 1578724484373, "ltp": 3.3, "tv": 10106.64, "trd": [[3.3, 1590.85]], "batb": [[0, 3.3, 22.67]], "batl": NaN}, {"timestamp": 1578724519938, "ltp": 3.3, "tv": 10106.64, "trd": NaN, "batb": [[1, 3.25, 13.2]], "batl": [[1, 3.45, 55.7]]}, {"timestamp": 1578724647925, "ltp": 3.3, "tv": 10106.64, "trd": NaN, "batb": NaN, "batl": [[0, 3.4, 27.67]]}, {"timestamp": 1578724648950, "ltp": 3.3, "tv": 10106.64, "trd": NaN, "batb": NaN, "batl": [[0, 3.4, 31.5]]}, {"timestamp": 1578724649932, "ltp": 3.3, "tv": 10106.64, "trd": NaN, "batb": NaN, "batl": [[0, 3.4, 35.33]]}, {"timestamp": 1578724712877, "ltp": 3.3, "tv": 10106.64, "trd": NaN, "batb": [[1, 3.25, 16.03]], "batl": NaN}, {"timestamp": 1578724792918, "ltp": 3.3, "tv": 10106.64, "trd": NaN, "batb": [[1, 3.25, 13.2]], "batl": NaN}, {"timestamp": 1578724848917, "ltp": 3.4, "tv": 10127.88, "trd": [[3.35, 1928.47], [3.4, 1759.88]], "batb": NaN, "batl": [[0, 3.4, 24.71]]}, {"timestamp": 1578724871585, "ltp": 3.4, "tv": 10127.88, "trd": NaN, "batb": NaN, "batl": [[0, 3.4, 34.71]]}, {"timestamp": 1578725104847, "ltp": 3.4, "tv": 10127.88, "trd": NaN, "batb": [[0, 3.35, 10], [1, 3.3, 22.67], [2, 3.25, 13.2]], "batl": NaN}, {"timestamp": 1578725384707, "ltp": 3.4, "tv": 10127.88, "trd": NaN, "batb": [[2, 3.25, 15.2]], "batl": NaN}, {"timestamp": 1578725386930, "ltp": 3.35, "tv": 10127.98, "trd": [[3.35, 1928.57]], "batb": [[0, 3.35, 9.95]], "batl": NaN}, {"timestamp": 1578725755990, "ltp": 3.4, "tv": 10153.73, "trd": [[3.35, 1932.57], [3.4, 1781.64]], "batb": [[0, 3.35, 7.95]], "batl": [[0, 3.4, 23.83]]}, {"timestamp": 1578725764989, "ltp": 3.4, "tv": 10153.73, "trd": NaN, "batb": NaN, "batl": [[1, 3.45, 43.39]]}, {"timestamp": 1578725765971, "ltp": 3.4, "tv": 10153.73, "trd": NaN, "batb": NaN, "batl": [[0, 3.4, 36.47]]}, {"timestamp": 1578725875865, "ltp": 3.35, "tv": 10157.53, "trd": [[3.35, 1936.37]], "batb": [[0, 3.35, 6.05]], "batl": NaN}, {"timestamp": 1578725905817, "ltp": 3.35, "tv": 10157.93, "trd": [[3.35, 1936.77]], "batb": [[0, 3.35, 5.85]], "batl": NaN}, {"timestamp": 1578725930920, "ltp": 3.35, "tv": 10158.03, "trd": [[3.35, 1936.87]], "batb": [[0, 3.35, 5.8]], "batl": NaN}, {"timestamp": 1578726074895, "ltp": 3.4, "tv": 10177.27, "trd": [[3.4, 1800.87]], "batb": NaN, "batl": [[0, 3.4, 26.85]]}, {"timestamp": 1578726155695, "ltp": 3.4, "tv": 10184.17, "trd": [[3.4, 1807.77]], "batb": NaN, "batl": [[0, 3.4, 23.4]]}, {"timestamp": 1578726164916, "ltp": 3.4, "tv": 10184.17, "trd": NaN, "batb": [[0, 3.35, 60.75]], "batl": NaN}, {"timestamp": 1578726179836, "ltp": 3.4, "tv": 10184.17, "trd": NaN, "batb": [[0, 3.35, 5.8]], "batl": NaN}, {"timestamp": 1578726331906, "ltp": 3.4, "tv": 10184.17, "trd": NaN, "batb": [[2, 3.25, 35.2]], "batl": NaN}, {"timestamp": 1578726395802, "ltp": 3.35, "tv": 10188.57, "trd": [[3.35, 1941.27]], "batb": [[0, 3.35, 3.6]], "batl": NaN}, {"timestamp": 1578726471820, "ltp": 3.4, "tv": 10204.77, "trd": [[3.4, 1823.97]], "batb": NaN, "batl": [[0, 3.4, 15.3]]}, {"timestamp": 1578726700999, "ltp": 3.35, "tv": 10214.77, "trd": [[3.35, 1951.27]], "batb": [[0, 3.35, 8.55]], "batl": NaN}, {"timestamp": 1578726720982, "ltp": 3.35, "tv": 10231.87, "trd": [[3.35, 1968.37]], "batb": [[0, 3.3, 22.67], [1, 3.25, 35.2], [2, 3.2, 107.92]], "batl": [[0, 3.35, 15.45], [1, 3.4, 15.3], [2, 3.45, 43.39]]}, {"timestamp": 1578726970948, "ltp": 3.35, "tv": 10231.87, "trd": NaN, "batb": [[0, 3.3, 104.39]], "batl": NaN}, {"timestamp": 1578726981850, "ltp": 3.35, "tv": 10262.76, "trd": [[3.35, 1999.26]], "batb": [[0, 3.35, 39.5], [1, 3.3, 104.39], [2, 3.25, 35.2]], "batl": [[0, 3.4, 15.3], [1, 3.45, 43.39], [2, 3.5, 65]]}, {"timestamp": 1578726995958, "ltp": 3.35, "tv": 10262.76, "trd": NaN, "batb": [[0, 3.3, 104.39], [1, 3.25, 48.51], [2, 3.2, 107.92]], "batl": NaN}, {"timestamp": 1578727025521, "ltp": 3.35, "tv": 10262.76, "trd": NaN, "batb": [[1, 3.25, 35.2]], "batl": NaN}, {"timestamp": 1578727130925, "ltp": 3.35, "tv": 10262.76, "trd": NaN, "batb": [[1, 3.25, 135.2]], "batl": NaN}, {"timestamp": 1578727134934, "ltp": 3.35, "tv": 10262.76, "trd": NaN, "batb": NaN, "batl": [[0, 3.35, 25], [1, 3.4, 15.3], [2, 3.45, 43.39]]}, {"timestamp": 1578727139933, "ltp": 3.35, "tv": 10312.75, "trd": [[3.35, 2049.25]], "batb": [[0, 3.35, 14.51], [1, 3.3, 104.39], [2, 3.25, 135.2]], "batl": [[0, 3.4, 15.3], [1, 3.45, 43.39], [2, 3.5, 65]]}, {"timestamp": 1578727153861, "ltp": 3.35, "tv": 10312.75, "trd": NaN, "batb": [[0, 3.3, 104.39], [1, 3.25, 140.28], [2, 3.2, 107.92]], "batl": NaN}, {"timestamp": 1578727183913, "ltp": 3.35, "tv": 10312.75, "trd": NaN, "batb": [[1, 3.25, 135.2]], "batl": NaN}, {"timestamp": 1578727253956, "ltp": 3.3, "tv": 10322.75, "trd": [[3.3, 1600.84]], "batb": [[0, 3.3, 99.39]], "batl": NaN}, {"timestamp": 1578727257001, "ltp": 3.3, "tv": 10322.75, "trd": NaN, "batb": [[0, 3.35, 4.92], [1, 3.3, 99.39], [2, 3.25, 135.2]], "batl": NaN}, {"timestamp": 1578727286989, "ltp": 3.3, "tv": 10322.75, "trd": NaN, "batb": [[0, 3.3, 99.39], [1, 3.25, 135.2], [2, 3.2, 107.92]], "batl": NaN}, {"timestamp": 1578727287916, "ltp": 3.3, "tv": 10322.75, "trd": NaN, "batb": [[0, 3.3, 81.72]], "batl": NaN}, {"timestamp": 1578727292002, "ltp": 3.3, "tv": 10322.75, "trd": NaN, "batb": [[0, 3.35, 15.53], [1, 3.3, 81.72], [2, 3.25, 135.2]], "batl": NaN}, {"timestamp": 1578727304932, "ltp": 3.3, "tv": 10322.75, "trd": NaN, "batb": NaN, "batl": [[0, 3.4, 2.67], [1, 3.45, 54.6]]}, {"timestamp": 1578727305928, "ltp": 3.3, "tv": 10322.75, "trd": NaN, "batb": NaN, "batl": [[0, 3.4, 7.64], [1, 3.45, 43.39]]}, {"timestamp": 1578727333984, "ltp": 3.35, "tv": 10338.75, "trd": [[3.35, 2065.25]], "batb": [[0, 3.35, 7.53]], "batl": NaN}, {"timestamp": 1578727335976, "ltp": 3.35, "tv": 10338.75, "trd": NaN, "batb": NaN, "batl": [[1, 3.45, 46.49]]}, {"timestamp": 1578727344706, "ltp": 3.35, "tv": 10338.75, "trd": NaN, "batb": NaN, "batl": [[0, 3.4, 2.67]]}, {"timestamp": 1578727357833, "ltp": 3.35, "tv": 10338.75, "trd": NaN, "batb": NaN, "batl": [[1, 3.45, 43.39]]}, {"timestamp": 1578727449965, "ltp": 3.35, "tv": 10338.75, "trd": NaN, "batb": [[0, 3.35, 132.53]], "batl": NaN}, {"timestamp": 1578727526943, "ltp": 3.4, "tv": 10344.09, "trd": [[3.4, 1829.31]], "batb": [[0, 3.4, 4.58], [1, 3.35, 132.53], [2, 3.3, 81.72]], "batl": [[0, 3.45, 43.39], [1, 3.5, 65], [2, 3.55, 12.05]]}, {"timestamp": 1578727549909, "ltp": 3.4, "tv": 10344.09, "trd": NaN, "batb": NaN, "batl": [[0, 3.45, 57.39]]}, {"timestamp": 1578727602971, "ltp": 3.4, "tv": 10344.09, "trd": NaN, "batb": NaN, "batl": [[2, 3.55, 21.58]]}, {"timestamp": 1578727714841, "ltp": 3.45, "tv": 10458.86, "trd": [[3.45, 845.07]], "batb": [[0, 3.45, 192.62], [1, 3.4, 4.58], [2, 3.35, 132.53]], "batl": [[0, 3.5, 65], [1, 3.55, 27.94], [2, 3.6, 53.03]]}, {"timestamp": 1578727715931, "ltp": 3.45, "tv": 10486.86, "trd": [[3.45, 873.07]], "batb": [[0, 3.45, 178.62]], "batl": NaN}, {"timestamp": 1578727729963, "ltp": 3.5, "tv": 10504.66, "trd": [[3.5, 1207.98]], "batb": NaN, "batl": [[0, 3.5, 56.1], [1, 3.55, 18.41], [2, 3.6, 59.52]]}, {"timestamp": 1578727730947, "ltp": 3.5, "tv": 10522.77, "trd": [[3.5, 1226.09]], "batb": NaN, "batl": [[0, 3.5, 47.05]]}, {"timestamp": 1578727731777, "ltp": 3.5, "tv": 10522.77, "trd": NaN, "batb": NaN, "batl": [[1, 3.55, 36.11]]}, {"timestamp": 1578727741996, "ltp": 3.45, "tv": 10532.77, "trd": [[3.45, 883.07]], "batb": [[0, 3.45, 173.62]], "batl": NaN}, {"timestamp": 1578727744986, "ltp": 3.45, "tv": 10532.77, "trd": NaN, "batb": NaN, "batl": [[1, 3.55, 29.76]]}, {"timestamp": 1578727755861, "ltp": 3.5, "tv": 10597.45, "trd": [[3.5, 1290.77]], "batb": NaN, "batl": [[0, 3.5, 14.71]]}, {"timestamp": 1578727757981, "ltp": 3.45, "tv": 10792.15, "trd": [[3.45, 1077.77]], "batb": [[0, 3.45, 76.27]], "batl": NaN}, {"timestamp": 1578727758974, "ltp": 3.5, "tv": 10821.57, "trd": [[3.5, 1320.19]], "batb": [[0, 3.5, 35.29], [1, 3.45, 76.27], [2, 3.4, 4.58]], "batl": [[0, 3.55, 39.3], [1, 3.6, 59.52], [2, 3.65, 289.3]]}, {"timestamp": 1578727768899, "ltp": 3.5, "tv": 10821.57, "trd": NaN, "batb": NaN, "batl": [[0, 3.55, 55.3]]}, {"timestamp": 1578727777916, "ltp": 3.5, "tv": 10825.57, "trd": [[3.5, 1324.19]], "batb": [[0, 3.5, 33.29]], "batl": NaN}, {"timestamp": 1578727781909, "ltp": 3.5, "tv": 10892.15, "trd": [[3.5, 1390.77]], "batb": [[0, 3.45, 76.27], [1, 3.4, 19.03], [2, 3.35, 132.53]], "batl": [[0, 3.5, 1.71], [1, 3.55, 55.3], [2, 3.6, 59.52]]}, {"timestamp": 1578727788832, "ltp": 3.5, "tv": 10892.15, "trd": NaN, "batb": [[1, 3.4, 4.58]], "batl": [[0, 3.55, 55.3], [1, 3.6, 59.52], [2, 3.65, 289.3]]}, {"timestamp": 1578727792955, "ltp": 3.45, "tv": 10895.55, "trd": [[3.45, 1081.18]], "batb": [[0, 3.45, 74.57]], "batl": [[1, 3.6, 53.03]]}, {"timestamp": 1578727810770, "ltp": 3.45, "tv": 10895.55, "trd": NaN, "batb": [[0, 3.5, 50], [1, 3.45, 74.57], [2, 3.4, 4.58]], "batl": NaN}, {"timestamp": 1578727830913, "ltp": 3.5, "tv": 10935.55, "trd": [[3.5, 1430.77]], "batb": [[0, 3.5, 30]], "batl": NaN}, {"timestamp": 1578727834954, "ltp": 3.5, "tv": 10995.55, "trd": [[3.5, 1490.77]], "batb": [[0, 3.45, 74.57], [1, 3.4, 17.56], [2, 3.35, 132.53]], "batl": [[0, 3.5, 20], [1, 3.55, 55.3], [2, 3.6, 53.03]]}, {"timestamp": 1578727857889, "ltp": 3.5, "tv": 11003.87, "trd": [[3.5, 1499.09]], "batb": NaN, "batl": [[0, 3.5, 15.84]]}, {"timestamp": 1578727864359, "ltp": 3.5, "tv": 11003.87, "trd": NaN, "batb": [[1, 3.4, 4.58]], "batl": NaN}, {"timestamp": 1578727872904, "ltp": 3.45, "tv": 11035.87, "trd": [[3.45, 1113.18]], "batb": [[0, 3.45, 58.57]], "batl": [[1, 3.55, 39.3]]}, {"timestamp": 1578727888940, "ltp": 3.45, "tv": 11069.87, "trd": [[3.45, 1147.18]], "batb": [[0, 3.45, 41.57]], "batl": NaN}, {"timestamp": 1578727897947, "ltp": 3.45, "tv": 11091.87, "trd": [[3.45, 1169.18]], "batb": [[0, 3.45, 30.57]], "batl": NaN}, {"timestamp": 1578727918942, "ltp": 3.5, "tv": 11095.87, "trd": [[3.5, 1503.09]], "batb": NaN, "batl": [[0, 3.5, 13.84]]}, {"timestamp": 1578727922877, "ltp": 3.45, "tv": 11113.87, "trd": [[3.45, 1187.18]], "batb": [[0, 3.45, 21.57]], "batl": NaN}, {"timestamp": 1578727926962, "ltp": 3.45, "tv": 11113.87, "trd": NaN, "batb": [[1, 3.4, 12.85]], "batl": NaN}, {"timestamp": 1578727936003, "ltp": 3.45, "tv": 11139.87, "trd": [[3.45, 1213.18]], "batb": [[0, 3.45, 8.57]], "batl": NaN}, {"timestamp": 1578727953897, "ltp": 3.45, "tv": 11139.87, "trd": NaN, "batb": [[1, 3.4, 37.16], [2, 3.35, 125]], "batl": NaN}, {"timestamp": 1578727955920, "ltp": 3.45, "tv": 11139.87, "trd": NaN, "batb": NaN, "batl": [[2, 3.6, 68.34]]}, {"timestamp": 1578727965903, "ltp": 3.45, "tv": 11157.01, "trd": [[3.45, 1230.32]], "batb": [[0, 3.4, 37.16], [1, 3.35, 128.69], [2, 3.3, 81.72]], "batl": [[0, 3.45, 21.43], [1, 3.5, 13.84], [2, 3.55, 29.76]]}, {"timestamp": 1578727969832, "ltp": 3.4, "tv": 11199.87, "trd": [[3.4, 1872.17]], "batb": [[0, 3.4, 15.73], [1, 3.35, 125]], "batl": [[0, 3.5, 13.84], [1, 3.55, 29.76], [2, 3.6, 68.34]]}, {"timestamp": 1578727993807, "ltp": 3.4, "tv": 11256.87, "trd": [[3.4, 1929.17]], "batb": [[0, 3.35, 125], [1, 3.3, 88.53], [2, 3.25, 28]], "batl": [[0, 3.4, 11.5], [1, 3.5, 13.84], [2, 3.55, 29.76]]}, {"timestamp": 1578727994950, "ltp": 3.4, "tv": 11279.87, "trd": [[3.4, 1952.17]], "batb": [[0, 3.4, 5.65], [1, 3.35, 125], [2, 3.3, 88.53]], "batl": [[0, 3.5, 13.84], [1, 3.55, 29.76], [2, 3.6, 68.34]]}, {"timestamp": 1578727995993, "ltp": 3.4, "tv": 11279.87, "trd": NaN, "batb": [[2, 3.3, 81.72]], "batl": NaN}, {"timestamp": 1578728024940, "ltp": 3.4, "tv": 11279.87, "trd": NaN, "batb": NaN, "batl": [[0, 3.45, 15], [1, 3.5, 13.84], [2, 3.55, 29.76]]}, {"timestamp": 1578728029974, "ltp": 3.4, "tv": 11279.87, "trd": NaN, "batb": NaN, "batl": [[2, 3.55, 17.71]]}, {"timestamp": 1578728042972, "ltp": 3.4, "tv": 11279.87, "trd": NaN, "batb": [[1, 3.35, 150]], "batl": NaN}, {"timestamp": 1578728043857, "ltp": 3.4, "tv": 11291.17, "trd": [[3.4, 1963.47]], "batb": [[0, 3.35, 150], [1, 3.3, 81.72], [2, 3.25, 28]], "batl": [[0, 3.45, 15.35]]}, {"timestamp": 1578728045950, "ltp": 3.4, "tv": 11291.87, "trd": [[3.4, 1964.17]], "batb": [[0, 3.4, 29.44], [1, 3.35, 150], [2, 3.3, 81.72]], "batl": [[0, 3.45, 15]]}, {"timestamp": 1578728175548, "ltp": 3.4, "tv": 11291.87, "trd": NaN, "batb": [[0, 3.4, 29.88]], "batl": NaN}, {"timestamp": 1578728328945, "ltp": 3.45, "tv": 11291.89, "trd": [[3.45, 1230.34]], "batb": NaN, "batl": [[0, 3.45, 14.99]]}, {"timestamp": 1578728530930, "ltp": 3.4, "tv": 11301.89, "trd": [[3.4, 1974.17]], "batb": [[0, 3.4, 24.88]], "batl": NaN}, {"timestamp": 1578728575975, "ltp": 3.4, "tv": 11335.94, "trd": [[3.4, 2008.22]], "batb": [[0, 3.4, 7.86]], "batl": NaN}, {"timestamp": 1578728744984, "ltp": 3.45, "tv": 11344.14, "trd": [[3.45, 1238.54]], "batb": NaN, "batl": [[0, 3.45, 10.89]]}, {"timestamp": 1578728759904, "ltp": 3.3, "tv": 11847.63, "trd": [[3.25, 1352.57], [3.3, 1768.28], [3.35, 2365.25], [3.4, 2023.93]], "batb": [[0, 3.25, 17.83], [1, 3.2, 129.33], [2, 3.15, 55]], "batl": [[0, 3.3, 4033.53], [1, 3.45, 10.89], [2, 3.5, 13.84]]}, {"timestamp": 1578728760834, "ltp": 3.3, "tv": 11875.58, "trd": [[3.3, 1796.23]], "batb": [[1, 3.2, 107.92]], "batl": [[0, 3.3, 4019.56]]}, {"timestamp": 1578728763899, "ltp": 3.25, "tv": 11887.58, "trd": [[3.25, 1364.57]], "batb": [[0, 3.25, 11.83]], "batl": NaN}, {"timestamp": 1578728771913, "ltp": 3.25, "tv": 11887.58, "trd": NaN, "batb": NaN, "batl": [[1, 3.45, 23.79]]}, {"timestamp": 1578728792761, "ltp": 3.25, "tv": 11887.58, "trd": NaN, "batb": NaN, "batl": [[1, 3.4, 10.89], [2, 3.45, 12.9]]}, {"timestamp": 1578728804991, "ltp": 3.25, "tv": 11887.58, "trd": NaN, "batb": [[0, 3.25, 61.83]], "batl": NaN}, {"timestamp": 1578728809380, "ltp": 3.25, "tv": 11887.58, "trd": NaN, "batb": [[1, 3.2, 108.38]], "batl": NaN}, {"timestamp": 1578728826706, "ltp": 3.25, "tv": 11897.58, "trd": [[3.25, 1374.57]], "batb": [[0, 3.25, 56.83]], "batl": NaN}, {"timestamp": 1578728835907, "ltp": 3.25, "tv": 11897.58, "trd": NaN, "batb": NaN, "batl": [[1, 3.4, 23.89], [2, 3.5, 13.84]]}, {"timestamp": 1578728910917, "ltp": 3.3, "tv": 11977.57, "trd": [[3.3, 1876.23]], "batb": NaN, "batl": [[0, 3.3, 3979.56]]}, {"timestamp": 1578728934938, "ltp": 3.25, "tv": 12027.57, "trd": [[3.25, 1424.57]], "batb": [[0, 3.25, 31.83]], "batl": NaN}, {"timestamp": 1578729047907, "ltp": 3.3, "tv": 13027.57, "trd": [[3.3, 2876.23]], "batb": NaN, "batl": [[0, 3.3, 3479.56]]}, {"timestamp": 1578729112963, "ltp": 3.25, "tv": 13033.77, "trd": [[3.25, 1430.77]], "batb": [[0, 3.25, 28.73]], "batl": NaN}, {"timestamp": 1578729170938, "ltp": 3.25, "tv": 13033.77, "trd": NaN, "batb": [[2, 3.05, 73.72]], "batl": NaN}, {"timestamp": 1578729210981, "ltp": 3.3, "tv": 13099.24, "trd": [[3.25, 1490.77], [3.3, 2881.69]], "batb": [[0, 3.2, 108.38], [1, 3.05, 73.72], [2, 3, 19.82]], "batl": [[0, 3.3, 3476.83]]}, {"timestamp": 1578729211864, "ltp": 3.3, "tv": 13099.24, "trd": NaN, "batb": [[0, 3.25, 30], [1, 3.2, 108.38], [2, 3.1, 13.64]], "batl": NaN}, {"timestamp": 1578729249954, "ltp": 3.3, "tv": 13099.24, "trd": NaN, "batb": [[2, 3.1, 16.04]], "batl": NaN}, {"timestamp": 1578729571933, "ltp": 3.3, "tv": 13106.15, "trd": [[3.3, 2888.6]], "batb": NaN, "batl": [[0, 3.3, 3473.37]]}, {"timestamp": 1578729681972, "ltp": 3.3, "tv": 13106.15, "trd": NaN, "batb": [[0, 3.25, 50]], "batl": NaN}, {"timestamp": 1578729709947, "ltp": 3.25, "tv": 13163.05, "trd": [[3.25, 1547.67]], "batb": [[0, 3.25, 21.55]], "batl": NaN}, {"timestamp": 1578729716987, "ltp": 3.3, "tv": 13181.23, "trd": [[3.3, 2906.78]], "batb": NaN, "batl": [[0, 3.3, 3464.28]]}, {"timestamp": 1578729812950, "ltp": 3.3, "tv": 13195.81, "trd": [[3.3, 2921.36]], "batb": NaN, "batl": [[0, 3.3, 3457]]}, {"timestamp": 1578729826857, "ltp": 3.3, "tv": 13195.81, "trd": NaN, "batb": [[2, 3.1, 2.5]], "batl": NaN}, {"timestamp": 1578729847893, "ltp": 3.25, "tv": 13203.81, "trd": [[3.25, 1555.67]], "batb": [[0, 3.25, 17.55]], "batl": NaN}, {"timestamp": 1578729869957, "ltp": 3.25, "tv": 13203.81, "trd": NaN, "batb": [[0, 3.25, 572.55]], "batl": NaN}, {"timestamp": 1578729907967, "ltp": 3.25, "tv": 13203.81, "trd": NaN, "batb": [[2, 3.1, 15.64]], "batl": NaN}, {"timestamp": 1578729909985, "ltp": 3.25, "tv": 13223.81, "trd": [[3.25, 1575.67]], "batb": [[0, 3.25, 562.55]], "batl": NaN}, {"timestamp": 1578730104695, "ltp": 3.25, "tv": 13223.81, "trd": NaN, "batb": [[1, 3.2, 138.27]], "batl": NaN}, {"timestamp": 1578730161492, "ltp": 3.3, "tv": 13227.81, "trd": [[3.3, 2925.36]], "batb": NaN, "batl": [[0, 3.3, 3455]]}, {"timestamp": 1578730209934, "ltp": 3.3, "tv": 13236.39, "trd": [[3.3, 2933.94]], "batb": NaN, "batl": [[0, 3.3, 3450.71]]}, {"timestamp": 1578730224145, "ltp": 3.3, "tv": 13250.39, "trd": [[3.3, 2947.94]], "batb": NaN, "batl": [[0, 3.3, 3443.71]]}, {"timestamp": 1578730238984, "ltp": 3.3, "tv": 14360.38, "trd": [[3.3, 4057.93]], "batb": NaN, "batl": [[0, 3.3, 2888.71]]}, {"timestamp": 1578730293961, "ltp": 3.3, "tv": 14360.38, "trd": NaN, "batb": [[0, 3.25, 565.55]], "batl": NaN}, {"timestamp": 1578730321876, "ltp": 3.25, "tv": 15360.38, "trd": [[3.25, 2575.67]], "batb": [[0, 3.25, 65.55]], "batl": NaN}, {"timestamp": 1578730326997, "ltp": 3.25, "tv": 15522.24, "trd": [[3.25, 2737.53]], "batb": [[0, 3.2, 138.27], [1, 3.1, 15.64], [2, 3.05, 73.62]], "batl": [[0, 3.25, 119.07], [1, 3.3, 2888.71], [2, 3.4, 23.89]]}, {"timestamp": 1578730327977, "ltp": 3.25, "tv": 15560.98, "trd": [[3.25, 2776.27]], "batb": NaN, "batl": [[0, 3.25, 99.7]]}, {"timestamp": 1578730328968, "ltp": 3.25, "tv": 15568.34, "trd": [[3.25, 2783.63]], "batb": [[1, 3.1, 33.91]], "batl": [[0, 3.25, 96.02]]}, {"timestamp": 1578730329901, "ltp": 3.25, "tv": 15568.34, "trd": NaN, "batb": [[1, 3.1, 64.89]], "batl": NaN}, {"timestamp": 1578730333972, "ltp": 3.25, "tv": 15568.34, "trd": NaN, "batb": NaN, "batl": [[0, 3.25, 196.02]]}, {"timestamp": 1578730336997, "ltp": 3.25, "tv": 15568.34, "trd": NaN, "batb": NaN, "batl": [[2, 3.4, 13]]}, {"timestamp": 1578730337769, "ltp": 3.2, "tv": 15590.12, "trd": [[3.2, 144.04]], "batb": [[0, 3.2, 127.38]], "batl": NaN}, {"timestamp": 1578730351808, "ltp": 3.2, "tv": 15590.12, "trd": NaN, "batb": [[1, 3.15, 300], [2, 3.1, 64.89]], "batl": NaN}, {"timestamp": 1578730358929, "ltp": 3.25, "tv": 15982.16, "trd": [[3.25, 3175.67]], "batb": [[0, 3.25, 25.98], [1, 3.2, 127.38], [2, 3.15, 300]], "batl": [[0, 3.3, 2888.71], [1, 3.4, 13], [2, 3.5, 13.84]]}, {"timestamp": 1578730387973, "ltp": 3.25, "tv": 15982.16, "trd": NaN, "batb": NaN, "batl": [[1, 3.35, 2], [2, 3.4, 13]]}, {"timestamp": 1578730402004, "ltp": 3.25, "tv": 15982.16, "trd": NaN, "batb": NaN, "batl": [[0, 3.3, 2918.71]]}, {"timestamp": 1578730446960, "ltp": 3.25, "tv": 15982.16, "trd": NaN, "batb": NaN, "batl": [[1, 3.35, 19.53], [2, 3.5, 13.84]]}, {"timestamp": 1578730474911, "ltp": 3.25, "tv": 16034.12, "trd": [[3.25, 3227.63]], "batb": [[0, 3.2, 127.38], [1, 3.15, 300], [2, 3.1, 20.77]], "batl": NaN}, {"timestamp": 1578730506955, "ltp": 3.25, "tv": 16034.12, "trd": NaN, "batb": NaN, "batl": [[1, 3.35, 2], [2, 3.45, 19.9]]}, {"timestamp": 1578730540959, "ltp": 3.25, "tv": 16034.12, "trd": NaN, "batb": [[0, 3.25, 100], [1, 3.2, 127.38], [2, 3.15, 300]], "batl": NaN}, {"timestamp": 1578730575918, "ltp": 3.25, "tv": 16240.72, "trd": [[3.25, 3434.23]], "batb": [[0, 3.2, 127.38], [1, 3.15, 300], [2, 3.1, 20.77]], "batl": [[0, 3.25, 96.7], [1, 3.3, 2918.71], [2, 3.35, 2]]}, {"timestamp": 1578730603950, "ltp": 3.3, "tv": 17679.14, "trd": [[3.25, 3627.63], [3.3, 5302.95]], "batb": NaN, "batl": [[0, 3.3, 2296.21], [1, 3.35, 2], [2, 3.45, 19.9]]}, {"timestamp": 1578730632863, "ltp": 3.2, "tv": 17683.14, "trd": [[3.2, 148.04]], "batb": [[0, 3.2, 125.38]], "batl": NaN}, {"timestamp": 1578730671949, "ltp": 3.2, "tv": 17683.14, "trd": NaN, "batb": [[0, 3.25, 25], [1, 3.2, 125.38], [2, 3.15, 300]], "batl": NaN}, {"timestamp": 1578730702953, "ltp": 3.3, "tv": 17732.68, "trd": [[3.3, 5352.49]], "batb": NaN, "batl": [[0, 3.3, 2271.44]]}, {"timestamp": 1578730705952, "ltp": 3.25, "tv": 17736.68, "trd": [[3.25, 3631.63]], "batb": [[0, 3.25, 23]], "batl": NaN}, {"timestamp": 1578730732998, "ltp": 3.25, "tv": 17736.68, "trd": NaN, "batb": NaN, "batl": [[1, 3.45, 19.9], [2, 3.5, 13.84]]}, {"timestamp": 1578730733975, "ltp": 3.25, "tv": 17736.68, "trd": NaN, "batb": NaN, "batl": [[1, 3.4, 2], [2, 3.45, 19.9]]}, {"timestamp": 1578730746831, "ltp": 3.25, "tv": 17742.68, "trd": [[3.25, 3637.63]], "batb": [[0, 3.25, 20]], "batl": [[1, 3.4, 19.3], [2, 3.5, 13.84]]}, {"timestamp": 1578730750899, "ltp": 3.25, "tv": 17742.68, "trd": NaN, "batb": NaN, "batl": [[0, 3.3, 2241.44], [1, 3.35, 30], [2, 3.4, 19.3]]}, {"timestamp": 1578730788862, "ltp": 3.25, "tv": 17782.68, "trd": [[3.25, 3677.63]], "batb": [[0, 3.2, 125.38], [1, 3.15, 300], [2, 3.1, 20.77]], "batl": NaN}, {"timestamp": 1578730789992, "ltp": 3.25, "tv": 17782.68, "trd": NaN, "batb": NaN, "batl": [[0, 3.3, 2271.44], [1, 3.4, 19.3], [2, 3.5, 13.84]]}, {"timestamp": 1578730814818, "ltp": 3.25, "tv": 17782.68, "trd": NaN, "batb": NaN, "batl": [[0, 3.25, 200], [1, 3.3, 2271.44], [2, 3.4, 19.3]]}, {"timestamp": 1578730815797, "ltp": 3.25, "tv": 17782.68, "trd": NaN, "batb": NaN, "batl": [[1, 3.3, 2241.44], [2, 3.35, 30]]}, {"timestamp": 1578730827939, "ltp": 3.25, "tv": 17782.68, "trd": NaN, "batb": NaN, "batl": [[2, 3.4, 19.3]]}, {"timestamp": 1578730828040, "ltp": 3.2, "tv": 17842.68, "trd": [[3.2, 208.04]], "batb": [[0, 3.2, 95.38]], "batl": NaN}, {"timestamp": 1578730847954, "ltp": 3.25, "tv": 17861.14, "trd": [[3.25, 3696.09]], "batb": NaN, "batl": [[0, 3.25, 190.77]]}, {"timestamp": 1578730853934, "ltp": 3.2, "tv": 17943.14, "trd": [[3.2, 290.04]], "batb": [[0, 3.2, 54.38]], "batl": [[0, 3.25, 200.77]]}, {"timestamp": 1578730857969, "ltp": 3.2, "tv": 17943.14, "trd": NaN, "batb": NaN, "batl": [[0, 3.25, 266.97]]}, {"timestamp": 1578730872984, "ltp": 3.2, "tv": 17943.14, "trd": NaN, "batb": NaN, "batl": [[2, 3.4, 2]]}, {"timestamp": 1578730879999, "ltp": 3.2, "tv": 17997.14, "trd": [[3.2, 344.04]], "batb": [[0, 3.2, 27.38]], "batl": NaN}, {"timestamp": 1578730886878, "ltp": 3.2, "tv": 18017.14, "trd": [[3.2, 364.04]], "batb": [[0, 3.2, 17.38]], "batl": NaN}, {"timestamp": 1578730896995, "ltp": 3.25, "tv": 18037.26, "trd": [[3.25, 3716.21]], "batb": [[2, 3.1, 2.5]], "batl": [[0, 3.25, 256.91]]}, {"timestamp": 1578730905934, "ltp": 3.2, "tv": 18077.16, "trd": [[3.2, 403.94]], "batb": [[0, 3.15, 300], [1, 3.1, 2.5], [2, 3.05, 73.62]], "batl": [[0, 3.2, 26.05], [1, 3.25, 256.91], [2, 3.3, 2241.44]]}, {"timestamp": 1578730906909, "ltp": 3.2, "tv": 18077.16, "trd": NaN, "batb": NaN, "batl": [[0, 3.2, 35.96], [2, 3.3, 2222.38]]}, {"timestamp": 1578730907928, "ltp": 3.2, "tv": 18077.16, "trd": NaN, "batb": NaN, "batl": [[0, 3.2, 45.7]]}, {"timestamp": 1578730915952, "ltp": 3.2, "tv": 18077.16, "trd": NaN, "batb": NaN, "batl": [[1, 3.25, 190.71]]}, {"timestamp": 1578730916928, "ltp": 3.2, "tv": 18168.56, "trd": [[3.2, 495.34]], "batb": [[0, 3.2, 31.3], [1, 3.15, 300], [2, 3.1, 2.5]], "batl": [[0, 3.25, 190.71], [1, 3.3, 2222.38], [2, 3.4, 2]]}, {"timestamp": 1578730917846, "ltp": 3.2, "tv": 18218.56, "trd": [[3.2, 545.34]], "batb": [[0, 3.2, 6.3]], "batl": NaN}, {"timestamp": 1578730928963, "ltp": 3.2, "tv": 18228.56, "trd": [[3.2, 555.34]], "batb": [[0, 3.2, 1.3]], "batl": NaN}, {"timestamp": 1578730941001, "ltp": 3.2, "tv": 18231.16, "trd": [[3.2, 557.94]], "batb": [[0, 3.15, 300], [1, 3.1, 2.5], [2, 3.05, 73.62]], "batl": [[0, 3.2, 20.64], [1, 3.25, 190.71], [2, 3.3, 2222.38]]}, {"timestamp": 1578730960923, "ltp": 3.15, "tv": 18259.55, "trd": [[3.15, 64.4]], "batb": [[0, 3.15, 285.8]], "batl": NaN}, {"timestamp": 1578730966939, "ltp": 3.15, "tv": 18259.55, "trd": NaN, "batb": NaN, "batl": [[0, 3.2, 120.64]]}, {"timestamp": 1578730967916, "ltp": 3.15, "tv": 18259.55, "trd": NaN, "batb": NaN, "batl": [[1, 3.25, 180.71]]}, {"timestamp": 1578730969826, "ltp": 3.15, "tv": 18259.55, "trd": NaN, "batb": NaN, "batl": [[0, 3.2, 155.64]]}, {"timestamp": 1578730972958, "ltp": 3.15, "tv": 18259.55, "trd": NaN, "batb": NaN, "batl": [[0, 3.2, 222.87]]}, {"timestamp": 1578730974967, "ltp": 3.15, "tv": 18279.55, "trd": [[3.15, 84.4]], "batb": [[0, 3.15, 275.8]], "batl": NaN}, {"timestamp": 1578731018712, "ltp": 3.15, "tv": 18299.55, "trd": [[3.15, 104.4]], "batb": [[0, 3.15, 265.8]], "batl": NaN}, {"timestamp": 1578731034729, "ltp": 3.15, "tv": 18307.55, "trd": [[3.15, 112.4]], "batb": [[0, 3.15, 261.8]], "batl": NaN}, {"timestamp": 1578731064874, "ltp": 3.15, "tv": 18307.55, "trd": NaN, "batb": [[0, 3.15, 361.8]], "batl": NaN}, {"timestamp": 1578731067999, "ltp": 3.2, "tv": 18327.95, "trd": [[3.2, 578.34]], "batb": NaN, "batl": [[0, 3.2, 212.68]]}, {"timestamp": 1578731140404, "ltp": 3.2, "tv": 18327.95, "trd": NaN, "batb": [[2, 3, 19.82]], "batl": NaN}, {"timestamp": 1578731179949, "ltp": 3.2, "tv": 18327.95, "trd": NaN, "batb": NaN, "batl": [[0, 3.2, 145.44]]}, {"timestamp": 1578731191958, "ltp": 3.2, "tv": 18327.95, "trd": NaN, "batb": [[2, 3, 29.19]], "batl": NaN}, {"timestamp": 1578731195786, "ltp": 3.2, "tv": 18327.95, "trd": NaN, "batb": NaN, "batl": [[0, 3.2, 212.68]]}, {"timestamp": 1578731214925, "ltp": 3.2, "tv": 18327.95, "trd": NaN, "batb": NaN, "batl": [[0, 3.2, 145.44]]}, {"timestamp": 1578731235765, "ltp": 3.2, "tv": 18327.95, "trd": NaN, "batb": NaN, "batl": [[0, 3.2, 212.68]]}, {"timestamp": 1578731258971, "ltp": 3.15, "tv": 18331.95, "trd": [[3.15, 116.4]], "batb": [[0, 3.15, 359.8]], "batl": NaN}, {"timestamp": 1578731337777, "ltp": 3.15, "tv": 18425.95, "trd": [[3.15, 210.4]], "batb": [[0, 3.15, 312.8]], "batl": NaN}, {"timestamp": 1578731349712, "ltp": 3.15, "tv": 18425.95, "trd": NaN, "batb": NaN, "batl": [[0, 3.2, 145.44]]}, {"timestamp": 1578731355916, "ltp": 3.15, "tv": 18425.95, "trd": NaN, "batb": [[1, 3.1, 202.5]], "batl": NaN}, {"timestamp": 1578731427941, "ltp": 3.15, "tv": 18465.95, "trd": [[3.15, 250.4]], "batb": [[0, 3.15, 292.8]], "batl": NaN}, {"timestamp": 1578731536962, "ltp": 3.2, "tv": 18484.07, "trd": [[3.2, 596.46]], "batb": NaN, "batl": [[0, 3.2, 136.39]]}, {"timestamp": 1578731542966, "ltp": 3.15, "tv": 18519.07, "trd": [[3.15, 285.4]], "batb": [[0, 3.15, 275.3]], "batl": NaN}, {"timestamp": 1578731552965, "ltp": 3.15, "tv": 18519.07, "trd": NaN, "batb": [[0, 3.15, 275.78]], "batl": NaN}, {"timestamp": 1578731554981, "ltp": 3.15, "tv": 18519.07, "trd": NaN, "batb": [[2, 3, 29.69]], "batl": NaN}, {"timestamp": 1578731613976, "ltp": 3.2, "tv": 18539.06, "trd": [[3.2, 616.45]], "batb": NaN, "batl": [[0, 3.2, 126.39]]}, {"timestamp": 1578731734967, "ltp": 3.15, "tv": 18599.06, "trd": [[3.15, 345.4]], "batb": [[0, 3.15, 245.78]], "batl": NaN}, {"timestamp": 1578731754903, "ltp": 3.15, "tv": 18603.06, "trd": [[3.15, 349.4]], "batb": [[0, 3.15, 243.78]], "batl": NaN}, {"timestamp": 1578731806842, "ltp": 3.15, "tv": 18678.06, "trd": [[3.15, 424.4]], "batb": [[0, 3.15, 206.28]], "batl": NaN}, {"timestamp": 1578731813856, "ltp": 3.15, "tv": 18684.87, "trd": [[3.15, 431.2]], "batb": [[0, 3.15, 202.88]], "batl": NaN}, {"timestamp": 1578731881940, "ltp": 3.2, "tv": 18702.17, "trd": [[3.2, 633.75]], "batb": NaN, "batl": [[0, 3.2, 117.74]]}, {"timestamp": 1578732021633, "ltp": 3.15, "tv": 18722.17, "trd": [[3.15, 451.2]], "batb": [[0, 3.15, 192.88]], "batl": NaN}, {"timestamp": 1578732046788, "ltp": 3.15, "tv": 19092.17, "trd": [[3.15, 821.2]], "batb": [[0, 3.15, 7.88]], "batl": NaN}, {"timestamp": 1578732050813, "ltp": 3.15, "tv": 19092.17, "trd": NaN, "batb": NaN, "batl": [[0, 3.2, 184.97]]}, {"timestamp": 1578732066518, "ltp": 3.15, "tv": 19092.17, "trd": NaN, "batb": NaN, "batl": [[0, 3.2, 117.74]]}, {"timestamp": 1578732074949, "ltp": 3.15, "tv": 19102.17, "trd": [[3.15, 831.2]], "batb": [[0, 3.15, 2.88]], "batl": NaN}, {"timestamp": 1578732085949, "ltp": 3.15, "tv": 19107.93, "trd": [[3.15, 836.96]], "batb": [[0, 3.1, 202.5], [1, 3, 37.93], [2, 2.9, 20]], "batl": [[0, 3.15, 7.12], [1, 3.2, 117.74], [2, 3.25, 180.71]]}, {"timestamp": 1578732086943, "ltp": 3.15, "tv": 19107.93, "trd": NaN, "batb": [[1, 3, 65.52]], "batl": NaN}, {"timestamp": 1578732096878, "ltp": 3.1, "tv": 19512.93, "trd": [[3.1, 521.22]], "batb": [[0, 3, 65.52], [1, 2.9, 20], [2, 2.88, 80.28]], "batl": [[0, 3.1, 97.5], [1, 3.15, 7.12], [2, 3.2, 117.74]]}, {"timestamp": 1578732097966, "ltp": 3.1, "tv": 19512.93, "trd": NaN, "batb": [[0, 3, 83.73], [1, 2.92, 16.07], [2, 2.9, 36.07]], "batl": NaN}, {"timestamp": 1578732098691, "ltp": 3.05, "tv": 19516.93, "trd": [[3.05, 10.72]], "batb": [[0, 3, 99.94], [1, 2.96, 3.48], [2, 2.92, 16.07]], "batl": [[0, 3.05, 17.45], [1, 3.1, 97.5], [2, 3.15, 7.12]]}, {"timestamp": 1578732099990, "ltp": 3.05, "tv": 19516.93, "trd": NaN, "batb": [[0, 3, 64.11], [1, 2.96, 23.43], [2, 2.94, 3.54]], "batl": [[0, 3.05, 7.68], [1, 3.1, 112.5]]}, {"timestamp": 1578732100977, "ltp": 3.05, "tv": 19531.7, "trd": [[3.05, 25.5]], "batb": [[2, 2.92, 16.07]], "batl": [[0, 3.1, 112.79], [1, 3.15, 7.12], [2, 3.2, 117.74]]}, {"timestamp": 1578732101858, "ltp": 3.05, "tv": 19531.7, "trd": NaN, "batb": NaN, "batl": [[0, 3.1, 112.5]]}, {"timestamp": 1578732102275, "ltp": 3.05, "tv": 19531.7, "trd": NaN, "batb": [[0, 3, 68.12], [1, 2.92, 32.14], [2, 2.9, 20]], "batl": NaN}, {"timestamp": 1578732106991, "ltp": 3.0, "tv": 19541.92, "trd": [[3, 217.88]], "batb": [[0, 3, 63.01], [1, 2.94, 3.54], [2, 2.92, 32.14]], "batl": [[0, 3.05, 35], [1, 3.1, 112.5], [2, 3.15, 7.12]]}, {"timestamp": 1578732107974, "ltp": 3.0, "tv": 19541.92, "trd": NaN, "batb": [[0, 3, 59], [1, 2.94, 39.06]], "batl": NaN}, {"timestamp": 1578732108962, "ltp": 3.0, "tv": 19541.92, "trd": NaN, "batb": [[1, 2.96, 9.67], [2, 2.94, 55.84]], "batl": NaN}, {"timestamp": 1578732109898, "ltp": 3.0, "tv": 19541.92, "trd": NaN, "batb": NaN, "batl": [[1, 3.1, 115.88]]}, {"timestamp": 1578732110883, "ltp": 3.0, "tv": 19541.92, "trd": NaN, "batb": [[0, 3, 49.63], [2, 2.94, 52.3]], "batl": NaN}, {"timestamp": 1578732111611, "ltp": 3.0, "tv": 19552.14, "trd": [[3, 228.1]], "batb": [[0, 3, 44.52], [1, 2.98, 17.76], [2, 2.96, 13.21]], "batl": NaN}, {"timestamp": 1578732112813, "ltp": 3.0, "tv": 19552.14, "trd": NaN, "batb": [[1, 2.98, 35.16]], "batl": NaN}, {"timestamp": 1578732113909, "ltp": 3.0, "tv": 19659.92, "trd": [[3, 335.88]], "batb": [[0, 2.98, 35.16], [1, 2.96, 16.69], [2, 2.94, 17.76]], "batl": [[0, 3, 43.61], [1, 3.05, 52.91], [2, 3.1, 18.38]]}, {"timestamp": 1578732114694, "ltp": 3.0, "tv": 19660.1, "trd": [[3, 336.06]], "batb": [[0, 2.98, 17.41], [1, 2.96, 32.11]], "batl": [[0, 3, 43.52]]}, {"timestamp": 1578732115992, "ltp": 3.0, "tv": 19660.1, "trd": NaN, "batb": [[0, 2.96, 3.48], [1, 2.92, 32.14], [2, 2.9, 20]], "batl": NaN}, {"timestamp": 1578732116979, "ltp": 3.0, "tv": 19660.1, "trd": NaN, "batb": [[0, 2.92, 32.14], [1, 2.9, 23.66], [2, 2.88, 80.28]], "batl": [[2, 3.1, 23.14]]}, {"timestamp": 1578732117913, "ltp": 3.0, "tv": 19660.1, "trd": NaN, "batb": [[0, 2.9, 37.62], [1, 2.88, 84], [2, 2.8, 2]], "batl": NaN}, {"timestamp": 1578732118904, "ltp": 3.0, "tv": 19660.1, "trd": NaN, "batb": [[1, 2.88, 91.86]], "batl": NaN}, {"timestamp": 1578732120303, "ltp": 3.0, "tv": 19660.1, "trd": NaN, "batb": [[1, 2.88, 96.33]], "batl": NaN}, {"timestamp": 1578732122819, "ltp": 3.0, "tv": 19747.14, "trd": [[3, 423.1]], "batb": [[0, 3, 6.48], [1, 2.9, 37.62], [2, 2.88, 96.33]], "batl": [[0, 3.05, 52.91], [1, 3.1, 23.14], [2, 3.2, 82.74]]}, {"timestamp": 1578732123911, "ltp": 3.0, "tv": 19760.1, "trd": [[3, 436.06]], "batb": [[0, 2.9, 37.62], [1, 2.88, 80.28], [2, 2.8, 2]], "batl": NaN}, {"timestamp": 1578732125741, "ltp": 3.0, "tv": 19760.1, "trd": NaN, "batb": [[1, 2.88, 92.92]], "batl": NaN}, {"timestamp": 1578732142928, "ltp": 3.0, "tv": 19760.1, "trd": NaN, "batb": NaN, "batl": [[0, 3, 15], [1, 3.05, 52.91], [2, 3.1, 8.14]]}, {"timestamp": 1578732162871, "ltp": 3.0, "tv": 19760.1, "trd": NaN, "batb": [[0, 2.92, 3], [1, 2.9, 37.62], [2, 2.88, 92.92]], "batl": NaN}, {"timestamp": 1578732163963, "ltp": 3.0, "tv": 19760.1, "trd": NaN, "batb": [[2, 2.88, 80.28]], "batl": NaN}, {"timestamp": 1578732170948, "ltp": 3.0, "tv": 19760.1, "trd": NaN, "batb": [[1, 2.9, 47.32]], "batl": NaN}, {"timestamp": 1578732178970, "ltp": 3.0, "tv": 19760.1, "trd": NaN, "batb": [[0, 2.92, 21.07]], "batl": NaN}, {"timestamp": 1578732179963, "ltp": 3.0, "tv": 19760.1, "trd": NaN, "batb": [[0, 2.94, 38.5], [1, 2.92, 21.07], [2, 2.9, 47.32]], "batl": NaN}, {"timestamp": 1578732182992, "ltp": 2.98, "tv": 19764.1, "trd": [[2.98, 4]], "batb": [[1, 2.92, 33.66]], "batl": [[0, 2.98, 33], [1, 3, 15], [2, 3.05, 17.91]]}, {"timestamp": 1578732183993, "ltp": 2.98, "tv": 19776.1, "trd": [[2.98, 16]], "batb": NaN, "batl": [[0, 2.98, 27]]}, {"timestamp": 1578732188869, "ltp": 2.98, "tv": 19826.1, "trd": [[2.98, 66]], "batb": NaN, "batl": [[0, 2.98, 2]]}, {"timestamp": 1578732195595, "ltp": 2.98, "tv": 19826.1, "trd": NaN, "batb": [[1, 2.92, 30.66]], "batl": NaN}, {"timestamp": 1578732199981, "ltp": 2.98, "tv": 19826.1, "trd": NaN, "batb": [[0, 2.96, 18], [1, 2.94, 38.5], [2, 2.92, 30.66]], "batl": NaN}, {"timestamp": 1578732200912, "ltp": 2.98, "tv": 19826.1, "trd": NaN, "batb": [[1, 2.94, 48.24]], "batl": NaN}, {"timestamp": 1578732223914, "ltp": 2.98, "tv": 19830.1, "trd": [[2.98, 70]], "batb": [[0, 2.98, 98], [1, 2.96, 18], [2, 2.94, 48.24]], "batl": [[0, 3, 15], [1, 3.05, 17.91], [2, 3.1, 8.14]]}, {"timestamp": 1578732224947, "ltp": 3.0, "tv": 19860.11, "trd": [[3, 466.06]], "batb": [[0, 3, 6.56], [1, 2.98, 107.61], [2, 2.96, 18]], "batl": [[0, 3.05, 17.91], [1, 3.1, 8.14], [2, 3.15, 6]]}, {"timestamp": 1578732226919, "ltp": 3.0, "tv": 19860.11, "trd": NaN, "batb": NaN, "batl": [[2, 3.15, 16.27]]}, {"timestamp": 1578732229930, "ltp": 3.0, "tv": 19860.11, "trd": NaN, "batb": NaN, "batl": [[2, 3.15, 25.18]]}, {"timestamp": 1578732233904, "ltp": 3.0, "tv": 19860.11, "trd": NaN, "batb": [[1, 2.98, 108.12]], "batl": [[0, 3.05, 37.91]]}, {"timestamp": 1578732238855, "ltp": 3.0, "tv": 19860.11, "trd": NaN, "batb": [[0, 3, 506.56]], "batl": NaN}, {"timestamp": 1578732241997, "ltp": 3.05, "tv": 19909.57, "trd": [[3.05, 74.96]], "batb": NaN, "batl": [[0, 3.05, 13.18]]}, {"timestamp": 1578732243937, "ltp": 3.05, "tv": 19909.57, "trd": NaN, "batb": [[0, 3, 524.77]], "batl": NaN}, {"timestamp": 1578732245744, "ltp": 3.05, "tv": 19935.93, "trd": [[3.05, 101.32]], "batb": [[0, 3.05, 84.82], [1, 3, 524.77], [2, 2.98, 10.12]], "batl": [[0, 3.1, 8.14], [1, 3.15, 25.18], [2, 3.2, 82.74]]}, {"timestamp": 1578732246906, "ltp": 3.05, "tv": 19935.93, "trd": NaN, "batb": [[1, 3, 1024.77], [2, 2.96, 18.51]], "batl": [[1, 3.15, 34.31]]}, {"timestamp": 1578732249925, "ltp": 3.1, "tv": 19952.2, "trd": [[3.1, 537.5]], "batb": [[0, 3.1, 1.22], [1, 3.05, 84.82], [2, 3, 1024.77]], "batl": [[0, 3.15, 34.31], [1, 3.2, 82.74], [2, 3.3, 2229.07]]}, {"timestamp": 1578732250808, "ltp": 3.1, "tv": 19952.2, "trd": NaN, "batb": NaN, "batl": [[2, 3.3, 2222.38]]}, {"timestamp": 1578732251954, "ltp": 3.1, "tv": 19952.2, "trd": NaN, "batb": [[2, 3, 1018.21]], "batl": [[0, 3.15, 43.43]]}, {"timestamp": 1578732257831, "ltp": 3.1, "tv": 19952.2, "trd": NaN, "batb": NaN, "batl": [[0, 3.15, 127.17]]}, {"timestamp": 1578732258916, "ltp": 3.1, "tv": 19952.2, "trd": NaN, "batb": [[0, 3.05, 84.82], [1, 3, 1018.21], [2, 2.96, 18.51]], "batl": NaN}, {"timestamp": 1578732259847, "ltp": 3.1, "tv": 19952.2, "trd": NaN, "batb": [[1, 3, 18.21]], "batl": [[0, 3.1, 5.15], [1, 3.15, 127.17], [2, 3.2, 82.74]]}, {"timestamp": 1578732271956, "ltp": 3.05, "tv": 20000.2, "trd": [[3.05, 149.32]], "batb": [[0, 3.05, 60.82]], "batl": NaN}, {"timestamp": 1578732273975, "ltp": 3.05, "tv": 20000.2, "trd": NaN, "batb": NaN, "batl": [[0, 3.1, 18.75]]}, {"timestamp": 1578732279976, "ltp": 3.1, "tv": 20037.7, "trd": [[3.1, 575]], "batb": [[0, 3.1, 5.25], [1, 3.05, 60.82], [2, 3, 18.21]], "batl": [[0, 3.15, 127.17], [1, 3.2, 82.74], [2, 3.25, 8]]}, {"timestamp": 1578732284951, "ltp": 3.1, "tv": 20037.7, "trd": NaN, "batb": NaN, "batl": [[0, 3.15, 144.17]]}, {"timestamp": 1578732294953, "ltp": 3.1, "tv": 20037.7, "trd": NaN, "batb": NaN, "batl": [[0, 3.15, 135.26], [1, 3.2, 90.74]]}, {"timestamp": 1578732299969, "ltp": 3.1, "tv": 20037.7, "trd": NaN, "batb": [[1, 3, 79.03], [2, 2.96, 18.51]], "batl": NaN}, {"timestamp": 1578732301884, "ltp": 3.1, "tv": 20037.7, "trd": NaN, "batb": [[1, 3.05, 9.1], [2, 3, 79.03]], "batl": NaN}, {"timestamp": 1578732306874, "ltp": 3.1, "tv": 20037.7, "trd": NaN, "batb": NaN, "batl": [[2, 3.25, 9.3]]}, {"timestamp": 1578732315910, "ltp": 3.05, "tv": 20066.4, "trd": [[3.05, 167.52], [3.1, 585.5]], "batb": [[0, 3, 79.03], [1, 2.96, 18.51], [2, 2.94, 38.5]], "batl": [[0, 3.05, 1.51], [1, 3.1, 94.75], [2, 3.15, 115.86]]}, {"timestamp": 1578732316998, "ltp": 3.05, "tv": 20066.4, "trd": NaN, "batb": [[1, 2.98, 16.64], [2, 2.96, 23.67]], "batl": [[0, 3.05, 21.64], [2, 3.15, 106.74]]}, {"timestamp": 1578732317983, "ltp": 3.05, "tv": 20066.4, "trd": NaN, "batb": [[1, 2.98, 28.66]], "batl": NaN}, {"timestamp": 1578732318909, "ltp": 3.0, "tv": 20076.62, "trd": [[3, 476.28]], "batb": [[0, 3, 73.92]], "batl": [[0, 3.05, 26.67]]}, {"timestamp": 1578732320985, "ltp": 3.0, "tv": 20076.62, "trd": NaN, "batb": NaN, "batl": [[2, 3.15, 23]]}, {"timestamp": 1578732323922, "ltp": 3.0, "tv": 20076.62, "trd": NaN, "batb": NaN, "batl": [[0, 3.05, 43.67], [2, 3.15, 6]]}, {"timestamp": 1578732333865, "ltp": 3.05, "tv": 20094.36, "trd": [[3.05, 185.26]], "batb": NaN, "batl": [[0, 3.05, 34.8]]}, {"timestamp": 1578732340972, "ltp": 3.05, "tv": 20112.51, "trd": [[3.05, 203.41]], "batb": NaN, "batl": [[0, 3.05, 25.72]]}, {"timestamp": 1578732342951, "ltp": 3.05, "tv": 20112.51, "trd": NaN, "batb": [[0, 3, 85.28]], "batl": NaN}, {"timestamp": 1578732343988, "ltp": 3.05, "tv": 20112.51, "trd": NaN, "batb": [[0, 3, 253.7]], "batl": [[0, 3.05, 22.03]]}, {"timestamp": 1578732346000, "ltp": 3.05, "tv": 20112.51, "trd": NaN, "batb": [[0, 3, 260.76]], "batl": NaN}, {"timestamp": 1578732350963, "ltp": 3.05, "tv": 20112.51, "trd": NaN, "batb": [[2, 2.96, 5.67]], "batl": NaN}, {"timestamp": 1578732365001, "ltp": 3.0, "tv": 20152.51, "trd": [[3, 516.28]], "batb": [[0, 3, 240.76]], "batl": NaN}, {"timestamp": 1578732365987, "ltp": 3.0, "tv": 20192.51, "trd": [[3, 556.28]], "batb": [[0, 3, 220.76]], "batl": [[0, 3.05, 34.91]]}, {"timestamp": 1578732366974, "ltp": 3.0, "tv": 20266.57, "trd": [[3, 630.33]], "batb": [[0, 3, 183.73]], "batl": NaN}, {"timestamp": 1578732374710, "ltp": 3.0, "tv": 20272.56, "trd": [[3, 636.33]], "batb": [[0, 3, 180.74]], "batl": NaN}, {"timestamp": 1578732420943, "ltp": 3.05, "tv": 20342.38, "trd": [[3.05, 273.23]], "batb": [[0, 3.05, 65.09], [1, 3, 180.74], [2, 2.98, 28.66]], "batl": [[0, 3.1, 94.75], [1, 3.15, 6], [2, 3.2, 90.74]]}, {"timestamp": 1578732439614, "ltp": 3.05, "tv": 20342.38, "trd": NaN, "batb": NaN, "batl": [[0, 3.15, 100.75], [1, 3.2, 90.74], [2, 3.25, 9.3]]}, {"timestamp": 1578732440910, "ltp": 3.05, "tv": 20394.38, "trd": [[3.05, 325.23]], "batb": [[0, 3.05, 65.36]], "batl": NaN}, {"timestamp": 1578732446915, "ltp": 3.05, "tv": 20394.38, "trd": NaN, "batb": [[1, 3, 380.74]], "batl": NaN}, {"timestamp": 1578732447999, "ltp": 3.05, "tv": 20394.38, "trd": NaN, "batb": [[0, 3.1, 10.31], [1, 3.05, 65.36], [2, 3, 380.74]], "batl": NaN}, {"timestamp": 1578732448997, "ltp": 3.05, "tv": 20394.38, "trd": NaN, "batb": [[2, 3, 368.42]], "batl": [[0, 3.15, 184.49]]}, {"timestamp": 1578732457999, "ltp": 3.1, "tv": 20402.38, "trd": [[3.1, 593.5]], "batb": [[0, 3.1, 6.31]], "batl": NaN}, {"timestamp": 1578732468939, "ltp": 3.1, "tv": 20415.0, "trd": [[3.1, 606.12]], "batb": [[0, 3.05, 65.36], [1, 3, 368.42], [2, 2.96, 6.18]], "batl": [[0, 3.1, 43.69], [1, 3.15, 184.49], [2, 3.2, 90.74]]}, {"timestamp": 1578732478934, "ltp": 3.05, "tv": 20441.0, "trd": [[3.05, 351.23]], "batb": [[0, 3.05, 52.36]], "batl": NaN}, {"timestamp": 1578732480946, "ltp": 3.05, "tv": 20441.0, "trd": NaN, "batb": NaN, "batl": [[1, 3.15, 100.75]]}, {"timestamp": 1578732491946, "ltp": 3.05, "tv": 20465.0, "trd": [[3.05, 375.23]], "batb": [[0, 3.05, 40.36], [1, 3, 418.42]], "batl": NaN}, {"timestamp": 1578732511972, "ltp": 3.05, "tv": 20465.0, "trd": NaN, "batb": NaN, "batl": [[0, 3.1, 128.78]]}, {"timestamp": 1578732516877, "ltp": 3.05, "tv": 20495.0, "trd": [[3.05, 405.23]], "batb": [[0, 3.05, 25.36]], "batl": NaN}, {"timestamp": 1578732517864, "ltp": 3.05, "tv": 20533.36, "trd": [[3.05, 443.59]], "batb": [[0, 3.05, 6.18]], "batl": NaN}, {"timestamp": 1578732518999, "ltp": 3.05, "tv": 20533.36, "trd": NaN, "batb": [[0, 3, 418.42], [1, 2.96, 6.18], [2, 2.94, 38.5]], "batl": NaN}, {"timestamp": 1578732519880, "ltp": 3.05, "tv": 20533.36, "trd": NaN, "batb": [[0, 3, 436.63], [1, 2.96, 17.32]], "batl": [[0, 3.05, 8.44], [1, 3.1, 128.78], [2, 3.15, 100.75]]}, {"timestamp": 1578732520869, "ltp": 3.05, "tv": 20533.36, "trd": NaN, "batb": [[1, 2.96, 29.34]], "batl": NaN}, {"timestamp": 1578732527611, "ltp": 3.05, "tv": 20533.36, "trd": NaN, "batb": NaN, "batl": [[1, 3.1, 43.69]]}, {"timestamp": 1578732529992, "ltp": 3.05, "tv": 20533.36, "trd": NaN, "batb": NaN, "batl": [[0, 3.1, 54.81], [1, 3.15, 100.75], [2, 3.2, 90.74]]}, {"timestamp": 1578732530977, "ltp": 3.05, "tv": 20533.36, "trd": NaN, "batb": NaN, "batl": [[0, 3.1, 66.03], [2, 3.2, 82.74]]}, {"timestamp": 1578732535987, "ltp": 3.05, "tv": 20533.36, "trd": NaN, "batb": [[0, 3.05, 222], [1, 3, 436.63], [2, 2.96, 29.34]], "batl": NaN}, {"timestamp": 1578732536611, "ltp": 3.05, "tv": 20733.36, "trd": [[3.05, 643.59]], "batb": [[0, 3.05, 122]], "batl": [[0, 3.1, 54.91]]}, {"timestamp": 1578732543889, "ltp": 3.05, "tv": 20759.36, "trd": [[3.05, 669.59]], "batb": [[0, 3.05, 109]], "batl": NaN}, {"timestamp": 1578732545593, "ltp": 3.05, "tv": 20919.36, "trd": [[3.05, 829.59]], "batb": [[0, 3.05, 29]], "batl": NaN}, {"timestamp": 1578732559954, "ltp": 3.05, "tv": 20919.36, "trd": NaN, "batb": NaN, "batl": [[0, 3.1, 140]]}, {"timestamp": 1578732565977, "ltp": 3.05, "tv": 20925.36, "trd": [[3.05, 835.59]], "batb": [[0, 3.05, 26]], "batl": NaN}, {"timestamp": 1578732588829, "ltp": 3.05, "tv": 20925.36, "trd": NaN, "batb": NaN, "batl": [[2, 3.2, 91.75]]}, {"timestamp": 1578732607563, "ltp": 3.05, "tv": 20925.36, "trd": NaN, "batb": [[0, 3.05, 1026]], "batl": NaN}, {"timestamp": 1578732608915, "ltp": 3.05, "tv": 20937.36, "trd": [[3.05, 847.59]], "batb": [[0, 3.05, 1020]], "batl": NaN}, {"timestamp": 1578732623863, "ltp": 3.05, "tv": 20937.36, "trd": NaN, "batb": NaN, "batl": [[0, 3.1, 54.91]]}, {"timestamp": 1578732646868, "ltp": 3.1, "tv": 20971.36, "trd": [[3.1, 640.12]], "batb": NaN, "batl": [[0, 3.1, 37.91]]}, {"timestamp": 1578732648003, "ltp": 3.05, "tv": 20987.36, "trd": [[3.05, 863.59]], "batb": [[0, 3.05, 1012]], "batl": NaN}, {"timestamp": 1578732649971, "ltp": 3.05, "tv": 20987.36, "trd": NaN, "batb": NaN, "batl": [[2, 3.2, 82.74]]}, {"timestamp": 1578732660906, "ltp": 3.05, "tv": 20999.36, "trd": [[3.05, 875.59]], "batb": [[0, 3.05, 1006]], "batl": NaN}, {"timestamp": 1578732692952, "ltp": 3.05, "tv": 20999.36, "trd": NaN, "batb": NaN, "batl": [[0, 3.1, 132.66], [1, 3.15, 6]]}, {"timestamp": 1578732699956, "ltp": 3.05, "tv": 21013.36, "trd": [[3.05, 889.59]], "batb": [[0, 3.05, 999]], "batl": NaN}, {"timestamp": 1578732702960, "ltp": 3.1, "tv": 21331.75, "trd": [[3.1, 958.51]], "batb": [[0, 3.05, 1001.97]], "batl": [[0, 3.1, 58.56]]}, {"timestamp": 1578732703941, "ltp": 3.1, "tv": 21448.89, "trd": [[3.1, 1075.65]], "batb": [[0, 3.1, 6.23], [1, 3.05, 1001.97], [2, 3, 436.63]], "batl": [[0, 3.15, 15.9], [1, 3.2, 82.74], [2, 3.25, 9.3]]}, {"timestamp": 1578732704974, "ltp": 3.1, "tv": 21457.38, "trd": [[3.1, 1084.14]], "batb": [[0, 3.1, 1.98]], "batl": [[0, 3.15, 25.25]]}, {"timestamp": 1578732705943, "ltp": 3.05, "tv": 21461.38, "trd": [[3.05, 889.63], [3.1, 1088.1]], "batb": [[0, 3.05, 1021.95], [1, 3, 436.63], [2, 2.96, 29.34]], "batl": NaN}, {"timestamp": 1578732715873, "ltp": 3.05, "tv": 21461.38, "trd": NaN, "batb": [[0, 3.1, 222], [1, 3.05, 1021.95], [2, 3, 436.63]], "batl": NaN}, {"timestamp": 1578732716959, "ltp": 3.1, "tv": 21498.2, "trd": [[3.1, 1124.92]], "batb": [[0, 3.1, 203.59], [1, 3.05, 1018.98]], "batl": [[0, 3.15, 15.9]]}, {"timestamp": 1578732718863, "ltp": 3.1, "tv": 21498.2, "trd": NaN, "batb": NaN, "batl": [[0, 3.15, 71.29]]}, {"timestamp": 1578732719994, "ltp": 3.1, "tv": 21498.2, "trd": NaN, "batb": [[0, 3.1, 303.59]], "batl": NaN}, {"timestamp": 1578732727984, "ltp": 3.1, "tv": 22105.38, "trd": [[3.1, 1732.1]], "batb": [[0, 3.05, 1018.98], [1, 3, 469.22], [2, 2.96, 29.34]], "batl": [[0, 3.1, 896.41], [1, 3.15, 71.29], [2, 3.2, 82.74]]}, {"timestamp": 1578732728911, "ltp": 3.1, "tv": 22105.38, "trd": NaN, "batb": [[1, 3, 436.63]], "batl": NaN}, {"timestamp": 1578732737899, "ltp": 3.05, "tv": 22127.38, "trd": [[3.05, 911.63]], "batb": [[0, 3.05, 1007.98]], "batl": NaN}, {"timestamp": 1578732755702, "ltp": 3.05, "tv": 23920.2, "trd": [[3.05, 2704.45]], "batb": [[0, 3.05, 111.57]], "batl": [[0, 3.15, 71.29], [1, 3.2, 82.74], [2, 3.25, 9.3]]}, {"timestamp": 1578732770925, "ltp": 3.05, "tv": 23920.2, "trd": NaN, "batb": NaN, "batl": [[2, 3.25, 20.3]]}, {"timestamp": 1578732775737, "ltp": 3.15, "tv": 23938.19, "trd": [[3.15, 854.96]], "batb": NaN, "batl": [[0, 3.15, 62.29]]}, {"timestamp": 1578732776923, "ltp": 3.15, "tv": 23938.19, "trd": NaN, "batb": NaN, "batl": [[0, 3.15, 73.29]]}, {"timestamp": 1578732783932, "ltp": 3.15, "tv": 23938.19, "trd": NaN, "batb": NaN, "batl": [[0, 3.15, 95.29]]}, {"timestamp": 1578732785330, "ltp": 3.15, "tv": 23938.19, "trd": NaN, "batb": [[0, 3.1, 6], [1, 3.05, 111.57], [2, 3, 436.63]], "batl": NaN}, {"timestamp": 1578732798865, "ltp": 3.15, "tv": 23938.19, "trd": NaN, "batb": NaN, "batl": [[0, 3.15, 179.03]]}, {"timestamp": 1578732799849, "ltp": 3.15, "tv": 23942.19, "trd": [[3.15, 858.96]], "batb": NaN, "batl": [[0, 3.15, 177.03]]}, {"timestamp": 1578732810970, "ltp": 3.15, "tv": 24296.28, "trd": [[3.15, 1213.04]], "batb": [[0, 3.15, 22.94], [1, 3.1, 6], [2, 3.05, 111.57]], "batl": [[0, 3.2, 82.74], [1, 3.25, 30.26], [2, 3.3, 2222.38]]}, {"timestamp": 1578732811951, "ltp": 3.15, "tv": 24296.28, "trd": NaN, "batb": NaN, "batl": [[0, 3.2, 129.89]]}, {"timestamp": 1578732813968, "ltp": 3.15, "tv": 24296.28, "trd": NaN, "batb": [[1, 3.1, 206]], "batl": NaN}, {"timestamp": 1578732815883, "ltp": 3.15, "tv": 24296.28, "trd": NaN, "batb": [[0, 3.15, 28.94], [1, 3.1, 200]], "batl": NaN}, {"timestamp": 1578732816967, "ltp": 3.15, "tv": 24307.0, "trd": [[3.15, 1223.77]], "batb": [[0, 3.15, 23.58]], "batl": NaN}, {"timestamp": 1578732818886, "ltp": 3.15, "tv": 24307.0, "trd": NaN, "batb": [[1, 3.05, 111.57], [2, 3, 444.78]], "batl": NaN}, {"timestamp": 1578732820956, "ltp": 3.15, "tv": 24332.88, "trd": [[3.15, 1249.64]], "batb": [[0, 3.15, 10.64], [1, 3.1, 13.17], [2, 3.05, 111.57]], "batl": NaN}, {"timestamp": 1578732825979, "ltp": 3.15, "tv": 24332.88, "trd": NaN, "batb": NaN, "batl": [[0, 3.2, 157.89]]}, {"timestamp": 1578732828979, "ltp": 3.15, "tv": 24332.88, "trd": NaN, "batb": NaN, "batl": [[0, 3.2, 167.89]]}, {"timestamp": 1578732829965, "ltp": 3.15, "tv": 24354.16, "trd": [[3.15, 1270.92]], "batb": [[0, 3.1, 13.17], [1, 3.05, 111.57], [2, 3, 444.78]], "batl": [[0, 3.15, 3.5], [1, 3.2, 167.89], [2, 3.25, 30.26]]}, {"timestamp": 1578732832398, "ltp": 3.15, "tv": 24354.16, "trd": NaN, "batb": NaN, "batl": [[0, 3.15, 31.5]]}, {"timestamp": 1578732854824, "ltp": 3.1, "tv": 24380.5, "trd": [[3.1, 1758.43]], "batb": [[0, 3.05, 111.57], [1, 3, 444.78], [2, 2.96, 29.34]], "batl": [[0, 3.1, 2.56], [1, 3.15, 41.5], [2, 3.2, 157.89]]}, {"timestamp": 1578732855914, "ltp": 3.15, "tv": 24390.74, "trd": [[3.1, 1763.56], [3.15, 1276.05]], "batb": NaN, "batl": [[0, 3.15, 38.94], [1, 3.2, 157.89], [2, 3.25, 30.26]]}, {"timestamp": 1578732856838, "ltp": 3.05, "tv": 24416.06, "trd": [[3.05, 2729.76]], "batb": [[0, 3.05, 98.91]], "batl": NaN}, {"timestamp": 1578732887977, "ltp": 3.05, "tv": 24416.06, "trd": NaN, "batb": [[1, 3, 544.78]], "batl": [[2, 3.25, 20.3]]}, {"timestamp": 1578732897978, "ltp": 3.05, "tv": 24460.62, "trd": [[3.05, 2774.33]], "batb": [[0, 3.05, 76.63]], "batl": NaN}, {"timestamp": 1578732900987, "ltp": 3.05, "tv": 24460.62, "trd": NaN, "batb": NaN, "batl": [[0, 3.15, 238.94]]}, {"timestamp": 1578732901983, "ltp": 3.1, "tv": 24465.34, "trd": [[3.1, 1768.27]], "batb": [[0, 3.05, 87.52]], "batl": [[0, 3.1, 25.9], [1, 3.15, 238.94], [2, 3.2, 157.89]]}, {"timestamp": 1578732902874, "ltp": 3.1, "tv": 24465.34, "trd": NaN, "batb": NaN, "batl": [[0, 3.1, 49.71], [2, 3.2, 110.74]]}, {"timestamp": 1578732919966, "ltp": 3.05, "tv": 24485.34, "trd": [[3.05, 2794.33]], "batb": [[0, 3.05, 77.52]], "batl": [[1, 3.15, 228.94]]}, {"timestamp": 1578732932906, "ltp": 3.05, "tv": 24518.74, "trd": [[3.05, 2827.73]], "batb": [[0, 3.05, 60.82]], "batl": NaN}, {"timestamp": 1578732940946, "ltp": 3.05, "tv": 24518.74, "trd": NaN, "batb": [[0, 3.05, 62.52]], "batl": NaN}, {"timestamp": 1578732943943, "ltp": 3.05, "tv": 24537.62, "trd": [[3.05, 2846.61]], "batb": [[0, 3.05, 53.08]], "batl": NaN}, {"timestamp": 1578732946974, "ltp": 3.05, "tv": 24557.62, "trd": [[3.05, 2866.61]], "batb": [[0, 3.05, 43.08]], "batl": NaN}, {"timestamp": 1578732963976, "ltp": 3.05, "tv": 24613.24, "trd": [[3.05, 2922.23]], "batb": [[0, 3.05, 15.27]], "batl": NaN}, {"timestamp": 1578732964957, "ltp": 3.05, "tv": 24643.78, "trd": [[3.05, 2952.77]], "batb": [[0, 3, 544.78], [1, 2.96, 29.34], [2, 2.94, 38.5]], "batl": [[0, 3.05, 4.4], [1, 3.1, 49.71], [2, 3.15, 228.94]]}, {"timestamp": 1578732965988, "ltp": 3.05, "tv": 24643.78, "trd": NaN, "batb": [[1, 2.96, 47.67]], "batl": NaN}, {"timestamp": 1578732966764, "ltp": 3.05, "tv": 24643.78, "trd": NaN, "batb": [[1, 2.96, 35.66]], "batl": NaN}, {"timestamp": 1578732968990, "ltp": 3.05, "tv": 24643.78, "trd": NaN, "batb": [[0, 3, 632.7]], "batl": NaN}, {"timestamp": 1578732974888, "ltp": 3.05, "tv": 24652.58, "trd": [[3.05, 2961.57]], "batb": [[0, 3.05, 217.6], [1, 3, 632.7], [2, 2.96, 35.66]], "batl": [[0, 3.1, 49.71], [1, 3.15, 228.94], [2, 3.2, 110.74]]}, {"timestamp": 1578732984000, "ltp": 3.1, "tv": 24671.28, "trd": [[3.1, 1786.97]], "batb": NaN, "batl": [[0, 3.1, 40.36]]}, {"timestamp": 1578732984984, "ltp": 3.1, "tv": 24671.28, "trd": NaN, "batb": [[0, 3.05, 304.08], [1, 3, 544.78]], "batl": [[0, 3.1, 23.81]]}, {"timestamp": 1578732994916, "ltp": 3.1, "tv": 24671.28, "trd": NaN, "batb": NaN, "batl": [[1, 3.15, 128.94]]}, {"timestamp": 1578732997822, "ltp": 3.1, "tv": 24671.28, "trd": NaN, "batb": NaN, "batl": [[0, 3.1, 87.81]]}, {"timestamp": 1578733000897, "ltp": 3.1, "tv": 24671.28, "trd": NaN, "batb": [[0, 3.05, 217.6]], "batl": NaN}, {"timestamp": 1578733015906, "ltp": 3.1, "tv": 24671.28, "trd": NaN, "batb": NaN, "batl": [[1, 3.15, 158.94]]}, {"timestamp": 1578733024932, "ltp": 3.1, "tv": 24671.28, "trd": NaN, "batb": [[0, 3.05, 304.08]], "batl": NaN}, {"timestamp": 1578733052878, "ltp": 3.1, "tv": 24671.28, "trd": NaN, "batb": [[1, 3, 579.78]], "batl": NaN}, {"timestamp": 1578733062976, "ltp": 3.05, "tv": 24697.28, "trd": [[3.05, 2987.57]], "batb": [[0, 3.05, 291.08]], "batl": NaN}, {"timestamp": 1578733089835, "ltp": 3.05, "tv": 24697.28, "trd": NaN, "batb": [[0, 3.05, 204.6]], "batl": NaN}, {"timestamp": 1578733102941, "ltp": 3.05, "tv": 24847.28, "trd": [[3.05, 3137.57]], "batb": [[0, 3.05, 129.6]], "batl": NaN}, {"timestamp": 1578733124953, "ltp": 3.05, "tv": 24847.28, "trd": NaN, "batb": NaN, "batl": [[0, 3.1, 309.81]]}, {"timestamp": 1578733125781, "ltp": 3.05, "tv": 24847.28, "trd": NaN, "batb": NaN, "batl": [[1, 3.15, 158]]}, {"timestamp": 1578733127963, "ltp": 3.05, "tv": 24875.28, "trd": [[3.05, 3165.57]], "batb": [[0, 3.05, 115.6]], "batl": NaN}, {"timestamp": 1578733129780, "ltp": 3.05, "tv": 24975.28, "trd": [[3.05, 3265.57]], "batb": [[0, 3.05, 65.6]], "batl": NaN}, {"timestamp": 1578733153955, "ltp": 3.05, "tv": 24997.28, "trd": [[3.05, 3287.57]], "batb": [[0, 3.05, 54.6]], "batl": NaN}, {"timestamp": 1578733165987, "ltp": 3.05, "tv": 24997.28, "trd": NaN, "batb": NaN, "batl": [[2, 3.2, 118.74]]}, {"timestamp": 1578733182905, "ltp": 3.1, "tv": 25013.28, "trd": [[3.1, 1802.97]], "batb": NaN, "batl": [[0, 3.1, 301.81]]}, {"timestamp": 1578733189937, "ltp": 3.1, "tv": 25031.14, "trd": [[3.1, 1820.83]], "batb": NaN, "batl": [[0, 3.1, 292.88]]}, {"timestamp": 1578733201941, "ltp": 3.05, "tv": 25035.14, "trd": [[3.05, 3291.57]], "batb": [[0, 3.05, 52.6]], "batl": NaN}, {"timestamp": 1578733257896, "ltp": 3.05, "tv": 25049.14, "trd": [[3.05, 3305.57]], "batb": [[0, 3.05, 45.6]], "batl": NaN}, {"timestamp": 1578733292905, "ltp": 3.05, "tv": 25101.54, "trd": [[3.05, 3357.97]], "batb": [[0, 3.05, 19.4]], "batl": NaN}, {"timestamp": 1578733294937, "ltp": 3.05, "tv": 25101.54, "trd": NaN, "batb": [[2, 2.96, 17.32]], "batl": NaN}, {"timestamp": 1578733295932, "ltp": 3.05, "tv": 25113.54, "trd": [[3.05, 3369.97]], "batb": [[0, 3.05, 13.4]], "batl": NaN}, {"timestamp": 1578733342991, "ltp": 3.05, "tv": 25113.54, "trd": NaN, "batb": [[0, 3.05, 217.48]], "batl": NaN}, {"timestamp": 1578733386926, "ltp": 3.05, "tv": 25131.54, "trd": [[3.05, 3387.97]], "batb": [[0, 3.05, 208.48]], "batl": NaN}, {"timestamp": 1578733412974, "ltp": 3.05, "tv": 25145.54, "trd": [[3.05, 3401.97]], "batb": [[0, 3.05, 201.48]], "batl": NaN}, {"timestamp": 1578733426981, "ltp": 3.05, "tv": 25159.54, "trd": [[3.05, 3415.97]], "batb": [[0, 3.05, 194.48]], "batl": NaN}, {"timestamp": 1578733438997, "ltp": 3.05, "tv": 25177.54, "trd": [[3.05, 3433.97]], "batb": [[0, 3.05, 185.48]], "batl": NaN}, {"timestamp": 1578733451901, "ltp": 3.05, "tv": 25187.54, "trd": [[3.05, 3443.97]], "batb": [[0, 3.05, 180.48]], "batl": NaN}, {"timestamp": 1578733455964, "ltp": 3.05, "tv": 25187.54, "trd": NaN, "batb": [[0, 3.05, 230.48]], "batl": NaN}, {"timestamp": 1578733464959, "ltp": 3.05, "tv": 25199.54, "trd": [[3.05, 3455.97]], "batb": [[0, 3.05, 224.48]], "batl": NaN}, {"timestamp": 1578733465966, "ltp": 3.05, "tv": 25399.54, "trd": [[3.05, 3655.97]], "batb": [[0, 3.05, 124.48]], "batl": NaN}, {"timestamp": 1578733472966, "ltp": 3.05, "tv": 25409.54, "trd": [[3.05, 3665.97]], "batb": [[0, 3.05, 119.48]], "batl": NaN}, {"timestamp": 1578733477982, "ltp": 3.05, "tv": 25421.54, "trd": [[3.05, 3677.97]], "batb": [[0, 3.05, 113.48]], "batl": NaN}, {"timestamp": 1578733480905, "ltp": 3.05, "tv": 25549.54, "trd": [[3.05, 3805.97]], "batb": [[0, 3.05, 49.48]], "batl": [[0, 3.1, 228.88]]}, {"timestamp": 1578733489819, "ltp": 3.05, "tv": 25549.54, "trd": NaN, "batb": [[1, 3, 631.95]], "batl": NaN}, {"timestamp": 1578733490907, "ltp": 3.05, "tv": 25557.54, "trd": [[3.05, 3813.97]], "batb": [[0, 3.05, 45.48]], "batl": NaN}, {"timestamp": 1578733510950, "ltp": 3.05, "tv": 25557.54, "trd": NaN, "batb": [[1, 3, 579.78]], "batl": NaN}, {"timestamp": 1578733511941, "ltp": 3.05, "tv": 25557.54, "trd": NaN, "batb": [[0, 3.05, 97.65]], "batl": NaN}, {"timestamp": 1578733526977, "ltp": 3.05, "tv": 25561.54, "trd": [[3.05, 3817.97]], "batb": [[0, 3.05, 95.65]], "batl": NaN}, {"timestamp": 1578733541557, "ltp": 3.05, "tv": 25569.54, "trd": [[3.05, 3825.97]], "batb": [[0, 3.05, 91.65]], "batl": NaN}, {"timestamp": 1578733546967, "ltp": 3.1, "tv": 25721.91, "trd": [[3.1, 1973.21]], "batb": NaN, "batl": [[0, 3.1, 152.69]]}, {"timestamp": 1578733547999, "ltp": 3.1, "tv": 25721.91, "trd": NaN, "batb": NaN, "batl": [[0, 3.1, 164.14]]}, {"timestamp": 1578733554985, "ltp": 3.05, "tv": 25729.91, "trd": [[3.05, 3833.97]], "batb": [[0, 3.05, 87.65]], "batl": NaN}, {"timestamp": 1578733568001, "ltp": 3.05, "tv": 25735.91, "trd": [[3.05, 3839.97]], "batb": [[0, 3.05, 84.65]], "batl": NaN}, {"timestamp": 1578733570889, "ltp": 3.05, "tv": 25815.91, "trd": [[3.05, 3919.97]], "batb": [[0, 3.05, 44.65]], "batl": NaN}, {"timestamp": 1578733576986, "ltp": 3.05, "tv": 25815.91, "trd": NaN, "batb": [[2, 2.94, 39.01]], "batl": NaN}, {"timestamp": 1578733592934, "ltp": 3.05, "tv": 25821.91, "trd": [[3.05, 3925.97]], "batb": [[0, 3.05, 41.65]], "batl": NaN}, {"timestamp": 1578733605933, "ltp": 3.05, "tv": 25827.91, "trd": [[3.05, 3931.97]], "batb": [[0, 3.05, 38.65]], "batl": NaN}, {"timestamp": 1578733631871, "ltp": 3.05, "tv": 25833.91, "trd": [[3.05, 3937.97]], "batb": [[0, 3.05, 35.65]], "batl": NaN}, {"timestamp": 1578733657966, "ltp": 3.05, "tv": 25839.91, "trd": [[3.05, 3943.97]], "batb": [[0, 3.05, 32.65]], "batl": NaN}, {"timestamp": 1578733666892, "ltp": 3.1, "tv": 25869.91, "trd": [[3.1, 2003.21]], "batb": NaN, "batl": [[0, 3.1, 149.14]]}, {"timestamp": 1578733696906, "ltp": 3.05, "tv": 25875.91, "trd": [[3.05, 3949.97]], "batb": [[0, 3.05, 29.65]], "batl": NaN}, {"timestamp": 1578733707799, "ltp": 3.1, "tv": 25879.91, "trd": [[3.1, 2007.21]], "batb": NaN, "batl": [[0, 3.1, 147.14]]}, {"timestamp": 1578733709742, "ltp": 3.05, "tv": 25883.91, "trd": [[3.05, 3953.97]], "batb": [[0, 3.05, 27.65]], "batl": NaN}, {"timestamp": 1578733715859, "ltp": 3.05, "tv": 25903.91, "trd": [[3.05, 3973.97]], "batb": [[0, 3.05, 17.65]], "batl": NaN}, {"timestamp": 1578733736857, "ltp": 3.05, "tv": 25907.91, "trd": [[3.05, 3977.97]], "batb": [[0, 3.05, 15.65]], "batl": NaN}, {"timestamp": 1578733742949, "ltp": 3.05, "tv": 25939.21, "trd": [[3.05, 4009.27]], "batb": [[0, 3, 579.78], [1, 2.94, 39.01], [2, 2.92, 68.59]], "batl": [[0, 3.05, 14.35], [1, 3.1, 147.14], [2, 3.15, 158]]}, {"timestamp": 1578733743853, "ltp": 3.1, "tv": 25971.94, "trd": [[3.05, 4037.97], [3.1, 2011.23]], "batb": [[1, 2.96, 12.6], [2, 2.94, 49.95]], "batl": [[0, 3.1, 145.13], [1, 3.15, 158], [2, 3.2, 118.74]]}, {"timestamp": 1578733744988, "ltp": 3.1, "tv": 25971.94, "trd": NaN, "batb": [[1, 2.96, 26.66]], "batl": NaN}, {"timestamp": 1578733756970, "ltp": 3.1, "tv": 25971.94, "trd": NaN, "batb": NaN, "batl": [[0, 3.05, 100], [1, 3.1, 145.13], [2, 3.15, 58]]}, {"timestamp": 1578733760987, "ltp": 3.1, "tv": 25971.94, "trd": NaN, "batb": [[0, 3, 667.7]], "batl": NaN}, {"timestamp": 1578733769979, "ltp": 3.1, "tv": 25971.94, "trd": NaN, "batb": [[0, 3, 517.7]], "batl": NaN}, {"timestamp": 1578733775000, "ltp": 3.1, "tv": 25971.94, "trd": NaN, "batb": NaN, "batl": [[0, 3.05, 114.19]]}, {"timestamp": 1578733791914, "ltp": 3.1, "tv": 25971.94, "trd": NaN, "batb": [[0, 3, 429.78]], "batl": NaN}, {"timestamp": 1578733799809, "ltp": 3.0, "tv": 25975.94, "trd": [[3, 640.33]], "batb": [[0, 3, 427.78]], "batl": NaN}, {"timestamp": 1578733807944, "ltp": 3.05, "tv": 26000.64, "trd": [[3.05, 4062.67]], "batb": [[0, 3, 445.36]], "batl": [[0, 3.05, 101.84]]}, {"timestamp": 1578733815927, "ltp": 3.0, "tv": 26030.64, "trd": [[3, 670.33]], "batb": [[0, 3, 430.36]], "batl": NaN}, {"timestamp": 1578733829258, "ltp": 3.05, "tv": 26051.22, "trd": [[3.05, 4083.25]], "batb": NaN, "batl": [[0, 3.05, 91.55]]}, {"timestamp": 1578733858690, "ltp": 3.05, "tv": 26234.32, "trd": [[3.05, 4266.35]], "batb": [[0, 3.05, 8.45], [1, 3, 430.36], [2, 2.96, 26.66]], "batl": [[0, 3.1, 145.13], [1, 3.15, 87.23], [2, 3.2, 118.74]]}, {"timestamp": 1578733859994, "ltp": 3.05, "tv": 26234.32, "trd": NaN, "batb": NaN, "batl": [[1, 3.15, 58]]}, {"timestamp": 1578733865883, "ltp": 3.05, "tv": 26251.22, "trd": [[3.05, 4283.25]], "batb": [[0, 3, 430.36], [1, 2.96, 26.66], [2, 2.94, 38.5]], "batl": [[0, 3.05, 19.55], [1, 3.1, 145.13], [2, 3.15, 58]]}, {"timestamp": 1578733866505, "ltp": 3.05, "tv": 26290.32, "trd": [[3.05, 4322.35]], "batb": NaN, "batl": [[0, 3.1, 145.13], [1, 3.15, 58], [2, 3.2, 118.74]]}, {"timestamp": 1578733867763, "ltp": 3.05, "tv": 26290.32, "trd": NaN, "batb": [[1, 2.96, 46.92]], "batl": NaN}, {"timestamp": 1578733871985, "ltp": 3.05, "tv": 26290.32, "trd": NaN, "batb": [[1, 2.96, 67.18]], "batl": NaN}, {"timestamp": 1578733884892, "ltp": 3.05, "tv": 26290.32, "trd": NaN, "batb": [[0, 3.05, 100], [1, 3, 430.36], [2, 2.96, 67.18]], "batl": NaN}, {"timestamp": 1578733892911, "ltp": 3.05, "tv": 26298.32, "trd": [[3.05, 4330.35]], "batb": [[0, 3.05, 96]], "batl": NaN}, {"timestamp": 1578733908944, "ltp": 3.05, "tv": 26319.18, "trd": [[3.05, 4351.21]], "batb": [[0, 3.05, 85.57]], "batl": [[1, 3.15, 280]]}, {"timestamp": 1578733930999, "ltp": 3.05, "tv": 26323.18, "trd": [[3.05, 4355.21]], "batb": [[0, 3.05, 83.57]], "batl": NaN}, {"timestamp": 1578733943979, "ltp": 3.05, "tv": 26327.18, "trd": [[3.05, 4359.21]], "batb": [[0, 3.05, 81.57]], "batl": NaN}, {"timestamp": 1578733956999, "ltp": 3.05, "tv": 26331.18, "trd": [[3.05, 4363.21]], "batb": [[0, 3.05, 79.57]], "batl": NaN}, {"timestamp": 1578733978952, "ltp": 3.05, "tv": 26340.36, "trd": [[3.05, 4372.39]], "batb": [[0, 3.05, 74.98]], "batl": NaN}, {"timestamp": 1578733994954, "ltp": 3.05, "tv": 26344.36, "trd": [[3.05, 4376.39]], "batb": [[0, 3.05, 72.98]], "batl": NaN}, {"timestamp": 1578733995955, "ltp": 3.05, "tv": 26344.36, "trd": NaN, "batb": [[0, 3.05, 277.06]], "batl": NaN}, {"timestamp": 1578734013960, "ltp": 3.05, "tv": 26354.36, "trd": [[3.05, 4386.39]], "batb": [[0, 3.05, 272.06]], "batl": NaN}, {"timestamp": 1578734034004, "ltp": 3.05, "tv": 26358.36, "trd": [[3.05, 4390.39]], "batb": [[0, 3.05, 270.06]], "batl": NaN}, {"timestamp": 1578734059952, "ltp": 3.05, "tv": 26362.36, "trd": [[3.05, 4394.39]], "batb": [[0, 3.05, 268.06]], "batl": NaN}, {"timestamp": 1578734158975, "ltp": 3.1, "tv": 26375.46, "trd": [[3.1, 2024.33]], "batb": NaN, "batl": [[0, 3.1, 138.58]]}, {"timestamp": 1578734160975, "ltp": 3.05, "tv": 26395.46, "trd": [[3.05, 4414.39]], "batb": [[0, 3.05, 258.06]], "batl": NaN}, {"timestamp": 1578734162988, "ltp": 3.05, "tv": 26399.46, "trd": [[3.05, 4418.39]], "batb": [[0, 3.05, 256.06]], "batl": NaN}, {"timestamp": 1578734165985, "ltp": 3.05, "tv": 26479.44, "trd": [[3.05, 4498.37]], "batb": [[0, 3.05, 216.07]], "batl": NaN}, {"timestamp": 1578734175912, "ltp": 3.05, "tv": 26483.44, "trd": [[3.05, 4502.37]], "batb": [[0, 3.05, 214.07]], "batl": NaN}, {"timestamp": 1578734227844, "ltp": 3.05, "tv": 26487.44, "trd": [[3.05, 4506.37]], "batb": [[0, 3.05, 212.07]], "batl": NaN}, {"timestamp": 1578734240845, "ltp": 3.05, "tv": 26491.44, "trd": [[3.05, 4510.37]], "batb": [[0, 3.05, 210.07]], "batl": NaN}, {"timestamp": 1578734266913, "ltp": 3.05, "tv": 26495.44, "trd": [[3.05, 4514.37]], "batb": [[0, 3.05, 208.07]], "batl": NaN}, {"timestamp": 1578734272915, "ltp": 3.05, "tv": 26525.44, "trd": [[3.05, 4544.37]], "batb": [[0, 3.05, 193.07]], "batl": NaN}, {"timestamp": 1578734277984, "ltp": 3.05, "tv": 26565.44, "trd": [[3.05, 4584.37]], "batb": [[0, 3.05, 173.07]], "batl": NaN}, {"timestamp": 1578734278926, "ltp": 3.05, "tv": 26569.44, "trd": [[3.05, 4588.37]], "batb": [[0, 3.05, 171.07]], "batl": NaN}, {"timestamp": 1578734305992, "ltp": 3.05, "tv": 26573.44, "trd": [[3.05, 4592.37]], "batb": [[0, 3.05, 169.07]], "batl": NaN}, {"timestamp": 1578734313909, "ltp": 3.05, "tv": 26573.44, "trd": NaN, "batb": NaN, "batl": [[0, 3.1, 158.58]]}, {"timestamp": 1578734314935, "ltp": 3.05, "tv": 26573.44, "trd": NaN, "batb": NaN, "batl": [[0, 3.1, 168.58]]}, {"timestamp": 1578734315932, "ltp": 3.05, "tv": 26573.44, "trd": NaN, "batb": NaN, "batl": [[0, 3.1, 178.58]]}, {"timestamp": 1578734316928, "ltp": 3.05, "tv": 26873.44, "trd": [[3.05, 4892.37]], "batb": [[0, 3.05, 19.07]], "batl": NaN}, {"timestamp": 1578734319843, "ltp": 3.05, "tv": 26873.44, "trd": NaN, "batb": [[1, 3, 450.36], [2, 2.96, 41.03]], "batl": NaN}, {"timestamp": 1578734320942, "ltp": 3.05, "tv": 26873.44, "trd": NaN, "batb": [[2, 2.98, 20.51]], "batl": NaN}, {"timestamp": 1578734325944, "ltp": 3.1, "tv": 26891.44, "trd": [[3.1, 2042.33]], "batb": NaN, "batl": [[0, 3.1, 169.58]]}, {"timestamp": 1578734330953, "ltp": 3.05, "tv": 26895.44, "trd": [[3.05, 4896.37]], "batb": [[0, 3.05, 17.07]], "batl": NaN}, {"timestamp": 1578734332852, "ltp": 3.05, "tv": 26929.58, "trd": [[3.05, 4930.51]], "batb": [[0, 3, 450.36], [1, 2.98, 20.51], [2, 2.96, 60.52]], "batl": NaN}, {"timestamp": 1578734333741, "ltp": 3.05, "tv": 26929.58, "trd": NaN, "batb": [[0, 3, 430.36], [1, 2.98, 41.14]], "batl": NaN}, {"timestamp": 1578734334938, "ltp": 3.05, "tv": 26929.58, "trd": NaN, "batb": [[0, 3.05, 20], [1, 3, 430.36], [2, 2.98, 47.99]], "batl": NaN}, {"timestamp": 1578734336864, "ltp": 3.05, "tv": 26929.58, "trd": NaN, "batb": [[1, 3, 470.36]], "batl": NaN}, {"timestamp": 1578734337959, "ltp": 3.05, "tv": 26929.58, "trd": NaN, "batb": [[2, 2.98, 37.19]], "batl": NaN}, {"timestamp": 1578734338943, "ltp": 3.05, "tv": 26933.58, "trd": [[3.05, 4934.51]], "batb": [[0, 3.05, 18]], "batl": NaN}, {"timestamp": 1578734339833, "ltp": 3.05, "tv": 26933.58, "trd": NaN, "batb": [[2, 2.98, 20.51]], "batl": NaN}, {"timestamp": 1578734348962, "ltp": 3.05, "tv": 26969.58, "trd": [[3.05, 4970.51]], "batb": [[0, 3, 470.36], [1, 2.98, 20.51], [2, 2.96, 60.52]], "batl": [[0, 3.1, 169.71]]}, {"timestamp": 1578734350748, "ltp": 3.05, "tv": 26969.58, "trd": NaN, "batb": [[1, 2.98, 47.99]], "batl": NaN}, {"timestamp": 1578734356968, "ltp": 3.05, "tv": 26969.58, "trd": NaN, "batb": NaN, "batl": [[0, 3.05, 2.13], [1, 3.1, 169.58], [2, 3.15, 280]]}, {"timestamp": 1578734364973, "ltp": 3.05, "tv": 26969.58, "trd": NaN, "batb": NaN, "batl": [[0, 3.05, 27.13]]}, {"timestamp": 1578734423952, "ltp": 3.05, "tv": 27023.84, "trd": [[3.05, 5024.77]], "batb": [[0, 3.05, 5.87], [1, 3, 470.36], [2, 2.98, 47.99]], "batl": [[0, 3.1, 169.58], [1, 3.15, 280], [2, 3.2, 110.74]]}, {"timestamp": 1578734424956, "ltp": 3.05, "tv": 27023.84, "trd": NaN, "batb": [[2, 2.98, 20.51]], "batl": NaN}, {"timestamp": 1578734428967, "ltp": 3.05, "tv": 27023.84, "trd": NaN, "batb": NaN, "batl": [[0, 3.1, 202.58]]}, {"timestamp": 1578734466908, "ltp": 3.05, "tv": 27023.84, "trd": NaN, "batb": [[0, 3.05, 105.87]], "batl": NaN}, {"timestamp": 1578734474004, "ltp": 3.05, "tv": 27027.84, "trd": [[3.05, 5028.77]], "batb": [[0, 3.05, 103.87]], "batl": NaN}, {"timestamp": 1578734494955, "ltp": 3.1, "tv": 27035.84, "trd": [[3.1, 2050.33]], "batb": NaN, "batl": [[0, 3.1, 198.58]]}, {"timestamp": 1578734514001, "ltp": 3.05, "tv": 27039.84, "trd": [[3.05, 5032.77]], "batb": [[0, 3.05, 101.87]], "batl": NaN}, {"timestamp": 1578734526906, "ltp": 3.05, "tv": 27043.84, "trd": [[3.05, 5036.77]], "batb": [[0, 3.05, 99.87]], "batl": NaN}, {"timestamp": 1578734539964, "ltp": 3.05, "tv": 27047.84, "trd": [[3.05, 5040.77]], "batb": [[0, 3.05, 97.87]], "batl": NaN}, {"timestamp": 1578734556844, "ltp": 3.05, "tv": 27057.84, "trd": [[3.05, 5050.77]], "batb": [[0, 3.05, 92.87]], "batl": NaN}, {"timestamp": 1578734566982, "ltp": 3.05, "tv": 27061.84, "trd": [[3.05, 5054.77]], "batb": [[0, 3.05, 90.87]], "batl": NaN}, {"timestamp": 1578734573963, "ltp": 3.05, "tv": 27071.84, "trd": [[3.05, 5064.77]], "batb": [[0, 3.05, 85.87]], "batl": NaN}, {"timestamp": 1578734578992, "ltp": 3.05, "tv": 27071.84, "trd": NaN, "batb": [[0, 3.05, 185.87]], "batl": NaN}, {"timestamp": 1578734579978, "ltp": 3.05, "tv": 27075.84, "trd": [[3.05, 5068.77]], "batb": [[0, 3.05, 183.87]], "batl": NaN}, {"timestamp": 1578734605808, "ltp": 3.05, "tv": 27079.84, "trd": [[3.05, 5072.77]], "batb": [[0, 3.05, 181.87]], "batl": NaN}, {"timestamp": 1578734618967, "ltp": 3.05, "tv": 27083.84, "trd": [[3.05, 5076.77]], "batb": [[0, 3.05, 179.87]], "batl": NaN}, {"timestamp": 1578734635961, "ltp": 3.1, "tv": 27481.0, "trd": [[3.1, 2447.49]], "batb": [[0, 3.1, 11.68], [1, 3.05, 179.87], [2, 3, 470.36]], "batl": [[0, 3.15, 280], [1, 3.2, 110.74], [2, 3.25, 7.3]]}, {"timestamp": 1578734636953, "ltp": 3.1, "tv": 27481.0, "trd": NaN, "batb": NaN, "batl": [[1, 3.2, 141.15]]}, {"timestamp": 1578734637988, "ltp": 3.1, "tv": 27481.0, "trd": NaN, "batb": NaN, "batl": [[1, 3.2, 110.74]]}, {"timestamp": 1578734655004, "ltp": 3.15, "tv": 27498.58, "trd": [[3.15, 1293.63]], "batb": NaN, "batl": [[0, 3.15, 271.21]]}, {"timestamp": 1578734658004, "ltp": 3.15, "tv": 27498.58, "trd": NaN, "batb": NaN, "batl": [[0, 3.15, 273.21]]}, {"timestamp": 1578734659984, "ltp": 3.1, "tv": 27521.94, "trd": [[3.1, 2470.85]], "batb": [[0, 3.05, 179.87], [1, 3, 470.36], [2, 2.98, 20.51]], "batl": [[0, 3.15, 273.53]]}, {"timestamp": 1578734674736, "ltp": 3.1, "tv": 27521.94, "trd": NaN, "batb": NaN, "batl": [[2, 3.25, 15.5]]}, {"timestamp": 1578734687936, "ltp": 3.05, "tv": 27561.94, "trd": [[3.05, 5116.77]], "batb": [[0, 3.05, 159.87]], "batl": NaN}, {"timestamp": 1578734767935, "ltp": 3.05, "tv": 27561.94, "trd": NaN, "batb": [[0, 3.05, 179.87]], "batl": NaN}, {"timestamp": 1578734771924, "ltp": 3.05, "tv": 27561.94, "trd": NaN, "batb": NaN, "batl": [[0, 3.1, 25.32], [1, 3.15, 273.21], [2, 3.2, 110.74]]}, {"timestamp": 1578734772917, "ltp": 3.05, "tv": 27661.94, "trd": [[3.05, 5216.77]], "batb": [[0, 3.05, 129.87]], "batl": NaN}, {"timestamp": 1578734780960, "ltp": 3.0, "tv": 28993.93, "trd": [[3, 1742.58], [3.05, 5476.51]], "batb": [[0, 2.98, 54.84], [1, 2.96, 33.43], [2, 2.94, 48.5]], "batl": [[0, 3.05, 17.91], [1, 3.1, 25.32], [2, 3.15, 273.21]]}, {"timestamp": 1578734781965, "ltp": 3.0, "tv": 28993.93, "trd": NaN, "batb": NaN, "batl": [[0, 3.05, 28.34], [1, 3.1, 48.34]]}, {"timestamp": 1578734782948, "ltp": 3.0, "tv": 28993.93, "trd": NaN, "batb": [[0, 2.98, 20.51]], "batl": NaN}, {"timestamp": 1578734783937, "ltp": 3.0, "tv": 28993.93, "trd": NaN, "batb": NaN, "batl": [[1, 3.1, 56.49]]}, {"timestamp": 1578734786983, "ltp": 3.0, "tv": 28993.93, "trd": NaN, "batb": NaN, "batl": [[0, 3.05, 48.34]]}, {"timestamp": 1578734787967, "ltp": 3.0, "tv": 28993.93, "trd": NaN, "batb": NaN, "batl": [[0, 3.05, 270.34]]}, {"timestamp": 1578734788854, "ltp": 3.0, "tv": 28993.93, "trd": NaN, "batb": NaN, "batl": [[0, 3.05, 272.34], [1, 3.1, 33.47], [2, 3.15, 271.21]]}, {"timestamp": 1578734791872, "ltp": 3.0, "tv": 28993.93, "trd": NaN, "batb": [[0, 2.98, 109.02]], "batl": NaN}, {"timestamp": 1578734793590, "ltp": 3.0, "tv": 28993.93, "trd": NaN, "batb": [[1, 2.96, 50.58]], "batl": NaN}, {"timestamp": 1578734806962, "ltp": 3.0, "tv": 28993.93, "trd": NaN, "batb": [[2, 2.94, 52.04]], "batl": [[0, 3, 10], [1, 3.05, 272.34], [2, 3.1, 33.47]]}, {"timestamp": 1578734811003, "ltp": 3.0, "tv": 28993.93, "trd": NaN, "batb": [[0, 2.98, 112.42]], "batl": NaN}, {"timestamp": 1578734814583, "ltp": 2.98, "tv": 29023.3, "trd": [[2.98, 99.36]], "batb": [[0, 2.98, 97.75]], "batl": [[1, 3.05, 270.34]]}, {"timestamp": 1578734817911, "ltp": 3.0, "tv": 29043.3, "trd": [[3, 1762.58]], "batb": [[0, 3, 90], [1, 2.98, 97.75], [2, 2.96, 37.15]], "batl": [[0, 3.05, 270.34], [1, 3.1, 33.47], [2, 3.15, 271.21]]}, {"timestamp": 1578734820989, "ltp": 3.0, "tv": 29043.3, "trd": NaN, "batb": [[1, 2.98, 111.6]], "batl": NaN}, {"timestamp": 1578734826988, "ltp": 3.0, "tv": 29043.3, "trd": NaN, "batb": NaN, "batl": [[0, 3.05, 272.34]]}, {"timestamp": 1578734831829, "ltp": 3.0, "tv": 29043.3, "trd": NaN, "batb": [[1, 2.98, 23.09]], "batl": NaN}, {"timestamp": 1578734852951, "ltp": 3.0, "tv": 29043.3, "trd": NaN, "batb": NaN, "batl": [[2, 3.15, 281.47]]}, {"timestamp": 1578734856857, "ltp": 3.0, "tv": 29043.3, "trd": NaN, "batb": [[0, 3, 107]], "batl": NaN}, {"timestamp": 1578734925968, "ltp": 3.05, "tv": 29059.38, "trd": [[3.05, 5492.59]], "batb": NaN, "batl": [[0, 3.05, 264.3]]}, {"timestamp": 1578734943395, "ltp": 3.0, "tv": 29063.38, "trd": [[3, 1766.58]], "batb": [[0, 3, 105]], "batl": NaN}, {"timestamp": 1578734958904, "ltp": 3.0, "tv": 29063.38, "trd": NaN, "batb": [[0, 3, 207.04]], "batl": NaN}, {"timestamp": 1578734964981, "ltp": 3.0, "tv": 29103.38, "trd": [[3, 1806.58]], "batb": [[0, 3, 187.04]], "batl": NaN}, {"timestamp": 1578735091847, "ltp": 3.0, "tv": 29103.38, "trd": NaN, "batb": [[0, 3, 257.04]], "batl": NaN}, {"timestamp": 1578735187949, "ltp": 3.0, "tv": 29103.38, "trd": NaN, "batb": [[2, 2.96, 63.15]], "batl": NaN}, {"timestamp": 1578735196894, "ltp": 3.05, "tv": 29199.38, "trd": [[3.05, 5588.59]], "batb": [[0, 3, 275.25]], "batl": [[0, 3.05, 216.3]]}, {"timestamp": 1578735203971, "ltp": 3.0, "tv": 29349.38, "trd": [[3, 1956.58]], "batb": [[0, 3, 200.25]], "batl": NaN}, {"timestamp": 1578735209949, "ltp": 3.0, "tv": 29359.38, "trd": [[3, 1966.58]], "batb": [[0, 3, 195.25]], "batl": NaN}, {"timestamp": 1578735255829, "ltp": 3.0, "tv": 29379.38, "trd": [[3, 1986.58]], "batb": [[0, 3, 185.25]], "batl": NaN}, {"timestamp": 1578735257918, "ltp": 3.0, "tv": 29379.38, "trd": NaN, "batb": [[0, 3, 202.83]], "batl": NaN}, {"timestamp": 1578735260932, "ltp": 3.0, "tv": 29379.38, "trd": NaN, "batb": [[0, 3, 223.51]], "batl": NaN}, {"timestamp": 1578735278941, "ltp": 3.0, "tv": 29379.38, "trd": NaN, "batb": [[0, 3, 311.43]], "batl": NaN}, {"timestamp": 1578735302959, "ltp": 3.0, "tv": 29399.38, "trd": [[3, 2006.58]], "batb": [[0, 3, 301.43]], "batl": NaN}, {"timestamp": 1578735303997, "ltp": 3.05, "tv": 29429.58, "trd": [[3.05, 5618.79]], "batb": NaN, "batl": [[0, 3.05, 201.2]]}, {"timestamp": 1578735310984, "ltp": 3.05, "tv": 29429.58, "trd": NaN, "batb": [[0, 3, 213.51]], "batl": NaN}, {"timestamp": 1578735311977, "ltp": 3.05, "tv": 29831.98, "trd": [[3.05, 6021.19]], "batb": [[0, 3.05, 5.72], [1, 3, 213.51], [2, 2.98, 23.09]], "batl": [[0, 3.1, 33.47], [1, 3.15, 281.47], [2, 3.2, 110.74]]}, {"timestamp": 1578735312864, "ltp": 3.1, "tv": 29898.92, "trd": [[3.1, 2537.79]], "batb": [[0, 3.1, 166.53], [1, 3.05, 17.2], [2, 3, 213.51]], "batl": [[0, 3.15, 281.47], [1, 3.2, 118.26], [2, 3.25, 7.3]]}, {"timestamp": 1578735314004, "ltp": 3.15, "tv": 30441.34, "trd": [[3.15, 1836.05]], "batb": [[0, 3.15, 172.79], [1, 3.1, 166.53], [2, 3.05, 17.2]], "batl": [[0, 3.2, 110.74], [1, 3.25, 17.17], [2, 3.3, 2222.38]]}, {"timestamp": 1578735314897, "ltp": 3.15, "tv": 30441.34, "trd": NaN, "batb": [[2, 3.05, 5.72]], "batl": NaN}, {"timestamp": 1578735316911, "ltp": 3.2, "tv": 30662.82, "trd": [[3.2, 855.23]], "batb": [[0, 3.2, 89.26], [1, 3.15, 172.79], [2, 3.1, 166.53]], "batl": [[0, 3.25, 17.17], [1, 3.3, 2222.38], [2, 3.35, 1.33]]}, {"timestamp": 1578735317899, "ltp": 3.2, "tv": 30662.82, "trd": NaN, "batb": [[0, 3.15, 172.79], [1, 3.1, 166.53], [2, 3.05, 5.72]], "batl": NaN}, {"timestamp": 1578735318905, "ltp": 3.2, "tv": 30662.82, "trd": NaN, "batb": [[1, 3.1, 189.24]], "batl": NaN}, {"timestamp": 1578735319898, "ltp": 3.2, "tv": 30662.82, "trd": NaN, "batb": [[0, 3.2, 111], [1, 3.15, 172.79], [2, 3.1, 189.24]], "batl": NaN}, {"timestamp": 1578735320996, "ltp": 3.2, "tv": 30678.82, "trd": [[3.2, 871.23]], "batb": [[0, 3.15, 172.79], [1, 3.1, 166.53], [2, 3.05, 5.72]], "batl": NaN}, {"timestamp": 1578735321981, "ltp": 3.2, "tv": 30678.82, "trd": NaN, "batb": [[1, 3.1, 196.19]], "batl": [[1, 3.3, 2244.38]]}, {"timestamp": 1578735323916, "ltp": 3.2, "tv": 30678.82, "trd": NaN, "batb": [[1, 3.1, 166.53]], "batl": NaN}, {"timestamp": 1578735325909, "ltp": 3.2, "tv": 30678.82, "trd": NaN, "batb": [[2, 3.05, 14.49]], "batl": NaN}, {"timestamp": 1578735327890, "ltp": 3.2, "tv": 30678.82, "trd": NaN, "batb": NaN, "batl": [[0, 3.25, 50.17]]}, {"timestamp": 1578735328930, "ltp": 3.2, "tv": 30678.82, "trd": NaN, "batb": [[0, 3.15, 173.28]], "batl": NaN}, {"timestamp": 1578735329988, "ltp": 3.2, "tv": 30678.82, "trd": NaN, "batb": NaN, "batl": [[0, 3.2, 20], [1, 3.25, 71.1], [2, 3.3, 2244.38]]}, {"timestamp": 1578735335900, "ltp": 3.2, "tv": 30678.82, "trd": NaN, "batb": NaN, "batl": [[1, 3.25, 104.1]]}, {"timestamp": 1578735338921, "ltp": 3.15, "tv": 30718.82, "trd": [[3.15, 1876.05]], "batb": [[0, 3.15, 153.28]], "batl": [[0, 3.25, 104.1], [1, 3.3, 2244.38], [2, 3.35, 1.33]]}, {"timestamp": 1578735339913, "ltp": 3.15, "tv": 30718.82, "trd": NaN, "batb": NaN, "batl": [[0, 3.25, 304.1]]}, {"timestamp": 1578735350949, "ltp": 3.15, "tv": 30718.82, "trd": NaN, "batb": [[2, 3.05, 5.72]], "batl": NaN}, {"timestamp": 1578735355940, "ltp": 3.15, "tv": 30718.82, "trd": NaN, "batb": [[0, 3.2, 20], [1, 3.15, 153.28], [2, 3.1, 166.53]], "batl": NaN}, {"timestamp": 1578735371789, "ltp": 3.15, "tv": 30718.82, "trd": NaN, "batb": NaN, "batl": [[2, 3.35, 251.33]]}, {"timestamp": 1578735390908, "ltp": 3.15, "tv": 30718.82, "trd": NaN, "batb": NaN, "batl": [[0, 3.25, 385.26]]}, {"timestamp": 1578735392990, "ltp": 3.25, "tv": 30922.28, "trd": [[3.25, 3919.67]], "batb": NaN, "batl": [[0, 3.25, 283.53]]}, {"timestamp": 1578735393930, "ltp": 3.25, "tv": 30922.28, "trd": NaN, "batb": [[0, 3.2, 40.31]], "batl": NaN}, {"timestamp": 1578735394722, "ltp": 3.25, "tv": 31022.28, "trd": [[3.25, 4019.67]], "batb": NaN, "batl": [[0, 3.25, 233.53]]}, {"timestamp": 1578735395914, "ltp": 3.25, "tv": 31489.37, "trd": [[3.25, 4486.76]], "batb": [[0, 3.25, 266.44], [1, 3.2, 40.31], [2, 3.15, 153.28]], "batl": [[0, 3.3, 2244.38], [1, 3.35, 286.69], [2, 3.4, 33.44]]}, {"timestamp": 1578735396907, "ltp": 3.25, "tv": 31489.37, "trd": NaN, "batb": [[0, 3.25, 466.44]], "batl": NaN}, {"timestamp": 1578735397933, "ltp": 3.25, "tv": 31489.37, "trd": NaN, "batb": NaN, "batl": [[1, 3.35, 251.33]]}, {"timestamp": 1578735398923, "ltp": 3.25, "tv": 31489.37, "trd": NaN, "batb": [[0, 3.25, 472.44]], "batl": NaN}, {"timestamp": 1578735399914, "ltp": 3.25, "tv": 31489.37, "trd": NaN, "batb": [[0, 3.25, 622.44]], "batl": NaN}, {"timestamp": 1578735402916, "ltp": 3.25, "tv": 31489.37, "trd": NaN, "batb": [[0, 3.25, 826.52]], "batl": NaN}, {"timestamp": 1578735403900, "ltp": 3.25, "tv": 32377.37, "trd": [[3.25, 5374.76]], "batb": [[0, 3.25, 382.52]], "batl": NaN}, {"timestamp": 1578735405936, "ltp": 3.3, "tv": 32581.37, "trd": [[3.3, 5556.49]], "batb": [[1, 3.2, 592.31], [2, 3.15, 253.28]], "batl": [[0, 3.3, 2142.38]]}, {"timestamp": 1578735406923, "ltp": 3.3, "tv": 32785.37, "trd": [[3.3, 5760.49]], "batb": [[0, 3.25, 432.52]], "batl": [[0, 3.3, 2040.38]]}, {"timestamp": 1578735407905, "ltp": 3.3, "tv": 32785.37, "trd": NaN, "batb": [[0, 3.25, 632.52]], "batl": NaN}, {"timestamp": 1578735410916, "ltp": 3.3, "tv": 32989.37, "trd": [[3.3, 5964.49]], "batb": NaN, "batl": [[0, 3.3, 1938.38]]}, {"timestamp": 1578735412947, "ltp": 3.3, "tv": 32989.37, "trd": NaN, "batb": [[0, 3.25, 732.52]], "batl": NaN}, {"timestamp": 1578735413839, "ltp": 3.3, "tv": 32989.37, "trd": NaN, "batb": [[0, 3.25, 834.72]], "batl": NaN}, {"timestamp": 1578735415861, "ltp": 3.3, "tv": 32989.37, "trd": NaN, "batb": [[0, 3.25, 934.72]], "batl": NaN}, {"timestamp": 1578735418950, "ltp": 3.3, "tv": 32989.37, "trd": NaN, "batb": [[0, 3.25, 1034.72]], "batl": NaN}, {"timestamp": 1578735420929, "ltp": 3.3, "tv": 32989.37, "trd": NaN, "batb": [[0, 3.25, 932.68]], "batl": [[0, 3.3, 1988.38]]}, {"timestamp": 1578735423941, "ltp": 3.3, "tv": 33189.37, "trd": [[3.3, 6164.49]], "batb": NaN, "batl": [[0, 3.3, 1888.38]]}, {"timestamp": 1578735425978, "ltp": 3.3, "tv": 33189.37, "trd": NaN, "batb": [[1, 3.2, 627.31]], "batl": NaN}, {"timestamp": 1578735426867, "ltp": 3.3, "tv": 33393.37, "trd": [[3.3, 6368.49]], "batb": NaN, "batl": [[0, 3.3, 1786.38]]}, {"timestamp": 1578735427985, "ltp": 3.3, "tv": 33393.37, "trd": NaN, "batb": NaN, "batl": [[2, 3.4, 133.44]]}, {"timestamp": 1578735428855, "ltp": 3.3, "tv": 33393.37, "trd": NaN, "batb": NaN, "batl": [[1, 3.35, 351.33], [2, 3.4, 148.14]]}, {"timestamp": 1578735429948, "ltp": 3.3, "tv": 33393.37, "trd": NaN, "batb": [[0, 3.25, 1032.68]], "batl": NaN}, {"timestamp": 1578735430679, "ltp": 3.25, "tv": 33573.37, "trd": [[3.25, 5554.76]], "batb": [[0, 3.25, 1248.68]], "batl": [[0, 3.3, 1886.38]]}, {"timestamp": 1578735431990, "ltp": 3.25, "tv": 33573.37, "trd": NaN, "batb": NaN, "batl": [[1, 3.35, 551.33]]}, {"timestamp": 1578735432978, "ltp