{"info": {"id": "1.167206543", "eventId": "29646660", "eventName": "3m Nov Hrd", "marketType": "WIN", "openDate": 1578747339792, "name": "Kemp  11th Jan", "numberOfActiveRunner": 3, "countryCode": "", "sport": "", "venue": "", "volume": {"total": 727520.07, "preMatch": 472519.74, "inPlay": 255000.33}, "winner": {"id": 10790194, "name": "Saint Xavier", "status": "WINNER", "position": 1}, "delay": 1}, "runners": [{"id": 10790194, "name": "Saint Xavier", "status": "WINNER", "position": 1, "inPlayOdds": 1.59, "inPlayTime": 1578747339792, "avgPrematch": 1.6, "closedOdds": 1.01, "maxPrematch": 1.84, "minPrematch": 1.39, "maxInPlay": 1.75, "minInPlay": 1.01, "inPlayIndex": 2855, "lengthOdds": 3243, "lengthOddsPrematch": 2855, "lengthOddsInPlay": 388, "tradedVolume": 581702.45, "preMatchVolume": 367831.54, "inPlayVolume": 213870.91}, {"id": 26965596, "name": "Delight Of Dubai", "status": "LOSER", "position": 2, "inPlayOdds": 3.7, "inPlayTime": 1578747339792, "avgPrematch": 3.67, "closedOdds": 1000.0, "maxPrematch": 4.6, "minPrematch": 2.84, "maxInPlay": 1000.0, "minInPlay": 3.2, "inPlayIndex": 2512, "lengthOdds": 2895, "lengthOddsPrematch": 2512, "lengthOddsInPlay": 383, "tradedVolume": 99434.97, "preMatchVolume": 70238.35, "inPlayVolume": 29196.62}, {"id": 23320213, "name": "Bourbon Borderline", "status": "LOSER", "position": 3, "inPlayOdds": 9.2, "inPlayTime": 1578747339792, "avgPrematch": 10.56, "closedOdds": 1000.0, "maxPrematch": 14.0, "minPrematch": 8.2, "maxInPlay": 1000.0, "minInPlay": 7.0, "inPlayIndex": 2091, "lengthOdds": 2460, "lengthOddsPrematch": 2091, "lengthOddsInPlay": 369, "tradedVolume": 46382.65, "preMatchVolume": 34449.85, "inPlayVolume": 11932.8}], "marketUpdates": [{"timestamp": 1578655026947000000, "openDate": "2020-01-11T12:20:00.000Z", "status": "OPEN", "betDelay": 0, "inPlay": false, "complete": true}, {"timestamp": 1578740627990000000, "openDate": "2020-01-11T12:20:00.000Z", "status": "SUSPENDED", "betDelay": 0, "inPlay": false, "complete": true}, {"timestamp": 1578740629000000000, "openDate": "2020-01-11T12:20:00.000Z", "status": "OPEN", "betDelay": 0, "inPlay": false, "complete": true}, {"timestamp": 1578745705987000000, "openDate": "2020-01-11T12:20:00.000Z", "status": "SUSPENDED", "betDelay": 0, "inPlay": false, "complete": true}, {"timestamp": 1578745706990000000, "openDate": "2020-01-11T12:20:00.000Z", "status": "OPEN", "betDelay": 0, "inPlay": false, "complete": true}, {"timestamp": 1578747337839000000, "openDate": "2020-01-11T12:20:00.000Z", "status": "SUSPENDED", "betDelay": 0, "inPlay": false, "complete": true}, {"timestamp": 1578747339792000000, "openDate": "2020-01-11T12:20:00.000Z", "status": "OPEN", "betDelay": 1, "inPlay": true, "complete": true}, {"timestamp": 1578747726927000000, "openDate": "2020-01-11T12:20:00.000Z", "status": "SUSPENDED", "betDelay": 1, "inPlay": true, "complete": true}, {"timestamp": 1578747795900000000, "openDate": "2020-01-11T12:20:00.000Z", "status": "CLOSED", "betDelay": 1, "inPlay": true, "complete": true}], "odds": [{"runnerId": 10790194, "odds": [{"timestamp": 1578677292785, "ltp": 1.64, "tv": 20.0, "trd": [[1.64, 20]], "batb": [[0, 1.63, 29.31], [1, 1.6, 1.08], [2, 1.59, 7.79]], "batl": NaN}, {"timestamp": 1578677300878, "ltp": 1.63, "tv": 78.63, "trd": [[1.63, 58.63]], "batb": [[0, 1.6, 1.08], [1, 1.59, 7.79], [2, 1.29, 44]], "batl": NaN}, {"timestamp": 1578677302182, "ltp": 1.63, "tv": 78.63, "trd": NaN, "batb": [[2, 1.57, 3]], "batl": NaN}, {"timestamp": 1578677305683, "ltp": 1.63, "tv": 78.63, "trd": NaN, "batb": NaN, "batl": [[0, 1.75, 2.2], [1, 1.76, 13.52], [2, 1.77, 12]]}, {"timestamp": 1578677309389, "ltp": 1.63, "tv": 78.63, "trd": NaN, "batb": NaN, "batl": [[0, 1.7, 150], [1, 1.75, 2.2], [2, 1.76, 13.52]]}, {"timestamp": 1578677312898, "ltp": 1.63, "tv": 78.63, "trd": NaN, "batb": NaN, "batl": [[0, 1.7, 150.2], [1, 1.75, 2]]}, {"timestamp": 1578677318622, "ltp": 1.63, "tv": 78.63, "trd": NaN, "batb": [[0, 1.6, 3.06]], "batl": NaN}, {"timestamp": 1578677364705, "ltp": 1.63, "tv": 78.63, "trd": NaN, "batb": NaN, "batl": [[0, 1.69, 2.2], [1, 1.7, 150]]}, {"timestamp": 1578677379932, "ltp": 1.57, "tv": 105.43, "trd": [[1.57, 5.1], [1.59, 15.58], [1.6, 6.13]], "batb": [[0, 1.39, 281.22], [1, 1.29, 44], [2, 1.27, 1.7]], "batl": NaN}, {"timestamp": 1578677385430, "ltp": 1.57, "tv": 105.43, "trd": NaN, "batb": NaN, "batl": [[0, 1.53, 206.6], [1, 1.69, 2.2], [2, 1.7, 150]]}, {"timestamp": 1578677386536, "ltp": 1.57, "tv": 105.43, "trd": NaN, "batb": NaN, "batl": [[0, 1.53, 206.8], [1, 1.69, 2]]}, {"timestamp": 1578677395941, "ltp": 1.57, "tv": 105.43, "trd": NaN, "batb": [[0, 1.4, 2.43], [1, 1.39, 280.77], [2, 1.29, 44]], "batl": NaN}, {"timestamp": 1578677402265, "ltp": 1.57, "tv": 105.43, "trd": NaN, "batb": [[0, 1.41, 28.69], [1, 1.4, 1.98], [2, 1.39, 280.77]], "batl": NaN}, {"timestamp": 1578677423674, "ltp": 1.57, "tv": 105.43, "trd": NaN, "batb": NaN, "batl": [[0, 1.52, 2.2], [1, 1.53, 206.6]]}, {"timestamp": 1578677442894, "ltp": 1.57, "tv": 105.43, "trd": NaN, "batb": [[0, 1.42, 4.7], [1, 1.41, 28.24], [2, 1.4, 1.98]], "batl": NaN}, {"timestamp": 1578677448826, "ltp": 1.57, "tv": 105.43, "trd": NaN, "batb": [[1, 1.4, 1.98], [2, 1.39, 280.77]], "batl": NaN}, {"timestamp": 1578677470561, "ltp": 1.57, "tv": 105.43, "trd": NaN, "batb": [[0, 1.43, 2.43], [1, 1.42, 4.25]], "batl": NaN}, {"timestamp": 1578677471856, "ltp": 1.43, "tv": 109.42, "trd": [[1.43, 3.1], [1.44, 0.9]], "batb": [[0, 1.42, 4.68], [1, 1.39, 280.77], [2, 1.29, 44]], "batl": NaN}, {"timestamp": 1578677475160, "ltp": 1.43, "tv": 109.42, "trd": NaN, "batb": NaN, "batl": [[0, 1.52, 6.2]]}, {"timestamp": 1578677530915, "ltp": 1.43, "tv": 109.42, "trd": NaN, "batb": [[2, 1.3, 25]], "batl": NaN}, {"timestamp": 1578677951850, "ltp": 1.43, "tv": 109.42, "trd": NaN, "batb": NaN, "batl": [[0, 1.52, 9.2]]}, {"timestamp": 1578677952938, "ltp": 1.43, "tv": 109.42, "trd": NaN, "batb": NaN, "batl": [[0, 1.52, 6.2]]}, {"timestamp": 1578677953565, "ltp": 1.43, "tv": 109.42, "trd": NaN, "batb": NaN, "batl": [[0, 1.51, 3.2], [1, 1.52, 6], [2, 1.53, 206.6]]}, {"timestamp": 1578677954141, "ltp": 1.51, "tv": 109.82, "trd": [[1.51, 0.4]], "batb": NaN, "batl": [[0, 1.52, 6.2], [1, 1.53, 206.6], [2, 1.7, 150]]}, {"timestamp": 1578678636977, "ltp": 1.42, "tv": 119.19, "trd": [[1.42, 8.5], [1.43, 3.97]], "batb": [[0, 1.39, 280.77], [1, 1.3, 25], [2, 1.29, 44]], "batl": [[0, 1.51, 1.9], [1, 1.52, 6], [2, 1.53, 206.6]]}, {"timestamp": 1578678639864, "ltp": 1.42, "tv": 119.19, "trd": NaN, "batb": [[0, 1.4, 3], [1, 1.39, 280.77], [2, 1.3, 25]], "batl": [[0, 1.51, 28.47], [1, 1.52, 2]]}, {"timestamp": 1578678660672, "ltp": 1.42, "tv": 119.19, "trd": NaN, "batb": [[0, 1.41, 1.98], [1, 1.4, 3], [2, 1.39, 280.77]], "batl": NaN}, {"timestamp": 1578678665974, "ltp": 1.42, "tv": 119.19, "trd": NaN, "batb": NaN, "batl": [[1, 1.53, 206.6], [2, 1.7, 150]]}, {"timestamp": 1578678666078, "ltp": 1.42, "tv": 119.19, "trd": NaN, "batb": NaN, "batl": [[0, 1.5, 2.2], [1, 1.51, 28.27], [2, 1.53, 206.6]]}, {"timestamp": 1578678668067, "ltp": 1.42, "tv": 119.19, "trd": NaN, "batb": [[1, 1.39, 280.77], [2, 1.3, 25]], "batl": NaN}, {"timestamp": 1578678741982, "ltp": 1.42, "tv": 119.19, "trd": NaN, "batb": [[2, 1.31, 5.08]], "batl": NaN}, {"timestamp": 1578678758865, "ltp": 1.42, "tv": 119.19, "trd": NaN, "batb": [[0, 1.4, 1.98]], "batl": NaN}, {"timestamp": 1578678806198, "ltp": 1.42, "tv": 119.19, "trd": NaN, "batb": [[0, 1.41, 4.73], [1, 1.4, 1.98], [2, 1.39, 280.77]], "batl": NaN}, {"timestamp": 1578678872917, "ltp": 1.42, "tv": 119.19, "trd": NaN, "batb": [[0, 1.41, 47.12]], "batl": [[1, 1.51, 66.17]]}, {"timestamp": 1578678909840, "ltp": 1.42, "tv": 119.19, "trd": NaN, "batb": [[0, 1.4, 1.98], [1, 1.39, 280.77], [2, 1.33, 49.96]], "batl": NaN}, {"timestamp": 1578678910945, "ltp": 1.42, "tv": 119.19, "trd": NaN, "batb": NaN, "batl": [[0, 1.49, 17.3], [1, 1.5, 2], [2, 1.53, 206.8]]}, {"timestamp": 1578678928472, "ltp": 1.42, "tv": 119.19, "trd": NaN, "batb": [[0, 1.4, 4.98]], "batl": NaN}, {"timestamp": 1578678958000, "ltp": 1.42, "tv": 119.19, "trd": NaN, "batb": NaN, "batl": [[1, 1.53, 206.8], [2, 1.7, 150]]}, {"timestamp": 1578678958982, "ltp": 1.42, "tv": 119.19, "trd": NaN, "batb": NaN, "batl": [[0, 1.51, 5.27], [1, 1.52, 2], [2, 1.53, 206.6]]}, {"timestamp": 1578678980226, "ltp": 1.39, "tv": 123.19, "trd": [[1.39, 0.04], [1.4, 3.96]], "batb": [[0, 1.39, 280.75], [1, 1.33, 49.96], [2, 1.3, 25]], "batl": NaN}, {"timestamp": 1578678987803, "ltp": 1.39, "tv": 123.19, "trd": NaN, "batb": [[0, 1.39, 280.77]], "batl": NaN}, {"timestamp": 1578679033990, "ltp": 1.39, "tv": 123.19, "trd": NaN, "batb": NaN, "batl": [[1, 1.53, 206.6], [2, 1.7, 150]]}, {"timestamp": 1578679034188, "ltp": 1.39, "tv": 123.19, "trd": NaN, "batb": NaN, "batl": [[0, 1.5, 2.2], [1, 1.51, 5.07], [2, 1.53, 206.6]]}, {"timestamp": 1578679066306, "ltp": 1.39, "tv": 123.19, "trd": NaN, "batb": NaN, "batl": [[0, 1.49, 2.01], [1, 1.5, 2], [2, 1.53, 206.8]]}, {"timestamp": 1578679103226, "ltp": 1.39, "tv": 123.19, "trd": NaN, "batb": NaN, "batl": [[1, 1.52, 2.2], [2, 1.53, 206.6]]}, {"timestamp": 1578679133527, "ltp": 1.39, "tv": 123.19, "trd": NaN, "batb": NaN, "batl": [[0, 1.51, 2.1], [1, 1.52, 2]]}, {"timestamp": 1578679166686, "ltp": 1.39, "tv": 123.19, "trd": NaN, "batb": NaN, "batl": [[1, 1.53, 206.6], [2, 1.7, 150]]}, {"timestamp": 1578679170785, "ltp": 1.39, "tv": 123.19, "trd": NaN, "batb": NaN, "batl": [[0, 1.53, 207], [1, 1.7, 150], [2, 1.7, 0]]}, {"timestamp": 1578679371859, "ltp": 1.39, "tv": 123.19, "trd": NaN, "batb": [[0, 1.45, 30], [1, 1.39, 280.77], [2, 1.33, 49.96]], "batl": NaN}, {"timestamp": 1578679373259, "ltp": 1.39, "tv": 123.19, "trd": NaN, "batb": NaN, "batl": [[0, 1.53, 206.8]]}, {"timestamp": 1578679396976, "ltp": 1.39, "tv": 123.19, "trd": NaN, "batb": [[0, 1.39, 280.77], [1, 1.33, 49.96], [2, 1.3, 25]], "batl": NaN}, {"timestamp": 1578679397917, "ltp": 1.39, "tv": 123.19, "trd": NaN, "batb": NaN, "batl": [[2, 1000, 2]]}, {"timestamp": 1578679398905, "ltp": 1.39, "tv": 123.19, "trd": NaN, "batb": NaN, "batl": [[0, 1.53, 207], [2, 1000, 0]]}, {"timestamp": 1578679428870, "ltp": 1.39, "tv": 123.19, "trd": NaN, "batb": [[0, 1.43, 30], [1, 1.39, 280.77], [2, 1.33, 49.96]], "batl": NaN}, {"timestamp": 1578679432384, "ltp": 1.39, "tv": 123.19, "trd": NaN, "batb": NaN, "batl": [[0, 1.53, 206.8]]}, {"timestamp": 1578679436891, "ltp": 1.39, "tv": 123.19, "trd": NaN, "batb": NaN, "batl": [[0, 1.52, 2.2], [1, 1.53, 206.6], [2, 1.7, 150]]}, {"timestamp": 1578679675092, "ltp": 1.39, "tv": 123.19, "trd": NaN, "batb": [[0, 1.44, 3], [1, 1.43, 30], [2, 1.39, 280.77]], "batl": NaN}, {"timestamp": 1578679682987, "ltp": 1.39, "tv": 123.19, "trd": NaN, "batb": [[2, 1.4, 6]], "batl": NaN}, {"timestamp": 1578679703628, "ltp": 1.39, "tv": 123.19, "trd": NaN, "batb": [[0, 1.43, 30], [1, 1.4, 6], [2, 1.39, 280.77]], "batl": [[0, 1.52, 4.2]]}, {"timestamp": 1578680014562, "ltp": 1.39, "tv": 123.19, "trd": NaN, "batb": [[0, 1.45, 30]], "batl": NaN}, {"timestamp": 1578680035174, "ltp": 1.39, "tv": 123.19, "trd": NaN, "batb": [[0, 1.46, 30]], "batl": NaN}, {"timestamp": 1578680268807, "ltp": 1.48, "tv": 183.19, "trd": [[1.48, 60]], "batb": [[0, 1.4, 6], [1, 1.39, 280.77], [2, 1.33, 49.96]], "batl": NaN}, {"timestamp": 1578680274309, "ltp": 1.48, "tv": 183.19, "trd": NaN, "batb": NaN, "batl": [[0, 1.52, 4.38]]}, {"timestamp": 1578680291985, "ltp": 1.48, "tv": 183.19, "trd": NaN, "batb": NaN, "batl": [[0, 1.51, 2.38], [1, 1.52, 4], [2, 1.53, 206.6]]}, {"timestamp": 1578680364896, "ltp": 1.48, "tv": 183.19, "trd": NaN, "batb": [[0, 1.41, 1.98], [1, 1.4, 6], [2, 1.39, 280.77]], "batl": NaN}, {"timestamp": 1578680702749, "ltp": 1.51, "tv": 187.95, "trd": [[1.5, 0.36], [1.51, 4.8]], "batb": [[0, 1.51, 7.89], [1, 1.41, 1.98], [2, 1.4, 6]], "batl": [[0, 1.52, 4], [1, 1.53, 206.6], [2, 1.7, 150]]}, {"timestamp": 1578680712888, "ltp": 1.51, "tv": 187.95, "trd": NaN, "batb": [[2, 1.39, 280.77]], "batl": NaN}, {"timestamp": 1578680717103, "ltp": 1.51, "tv": 187.95, "trd": NaN, "batb": NaN, "batl": [[0, 1.53, 206.6], [1, 1.7, 150], [2, 1.7, 0]]}, {"timestamp": 1578680856756, "ltp": 1.53, "tv": 193.95, "trd": [[1.53, 6]], "batb": NaN, "batl": [[0, 1.53, 203.6]]}, {"timestamp": 1578680860566, "ltp": 1.53, "tv": 193.95, "trd": NaN, "batb": NaN, "batl": [[0, 1.53, 206.6]]}, {"timestamp": 1578680863380, "ltp": 1.53, "tv": 193.95, "trd": NaN, "batb": NaN, "batl": [[2, 2.22, 9]]}, {"timestamp": 1578680968583, "ltp": 1.51, "tv": 209.74, "trd": [[1.51, 20.58]], "batb": [[0, 1.41, 1.98], [1, 1.39, 280.77], [2, 1.33, 5.01]], "batl": [[0, 1.51, 11.25], [1, 1.53, 206.6], [2, 1.7, 150]]}, {"timestamp": 1578680969688, "ltp": 1.51, "tv": 209.74, "trd": NaN, "batb": NaN, "batl": [[0, 1.53, 206.79], [1, 1.7, 150], [2, 2.22, 9]]}, {"timestamp": 1578680971108, "ltp": 1.51, "tv": 209.74, "trd": NaN, "batb": [[0, 1.42, 8.39], [1, 1.41, 1.98], [2, 1.39, 280.77]], "batl": NaN}, {"timestamp": 1578680973983, "ltp": 1.51, "tv": 209.74, "trd": NaN, "batb": NaN, "batl": [[0, 1.53, 206.6]]}, {"timestamp": 1578680974089, "ltp": 1.51, "tv": 209.74, "trd": NaN, "batb": NaN, "batl": [[0, 1.53, 206.79]]}, {"timestamp": 1578680985896, "ltp": 1.51, "tv": 209.74, "trd": NaN, "batb": [[0, 1.43, 2.11], [1, 1.42, 8.39], [2, 1.41, 1.98]], "batl": NaN}, {"timestamp": 1578681018760, "ltp": 1.51, "tv": 209.74, "trd": NaN, "batb": NaN, "batl": [[0, 1.52, 4.19], [1, 1.53, 206.6], [2, 1.7, 150]]}, {"timestamp": 1578681026666, "ltp": 1.51, "tv": 209.74, "trd": NaN, "batb": [[0, 1.43, 4.09], [2, 1.39, 280.77]], "batl": NaN}, {"timestamp": 1578681307864, "ltp": 1.43, "tv": 217.74, "trd": [[1.43, 11.97]], "batb": [[0, 1.42, 8.49], [1, 1.39, 280.77], [2, 1.33, 5.01]], "batl": NaN}, {"timestamp": 1578681325773, "ltp": 1.43, "tv": 217.74, "trd": NaN, "batb": [[0, 1.44, 8.28], [1, 1.42, 8.49], [2, 1.39, 280.77]], "batl": NaN}, {"timestamp": 1578681327414, "ltp": 1.43, "tv": 217.74, "trd": NaN, "batb": [[1, 1.39, 280.86], [2, 1.33, 5.01]], "batl": NaN}, {"timestamp": 1578681332806, "ltp": 1.43, "tv": 217.74, "trd": NaN, "batb": [[1, 1.4, 19.24], [2, 1.39, 280.77]], "batl": NaN}, {"timestamp": 1578681335391, "ltp": 1.43, "tv": 217.74, "trd": NaN, "batb": [[1, 1.4, 38.38]], "batl": NaN}, {"timestamp": 1578681357634, "ltp": 1.43, "tv": 217.74, "trd": NaN, "batb": [[0, 1.44, 8.37], [1, 1.4, 38.28]], "batl": NaN}, {"timestamp": 1578681383959, "ltp": 1.43, "tv": 217.74, "trd": NaN, "batb": [[0, 1.45, 10], [1, 1.44, 8.37], [2, 1.4, 38.28]], "batl": NaN}, {"timestamp": 1578681387864, "ltp": 1.43, "tv": 217.74, "trd": NaN, "batb": NaN, "batl": [[0, 1.52, 4]]}, {"timestamp": 1578681414676, "ltp": 1.43, "tv": 217.74, "trd": NaN, "batb": [[0, 1.45, 21]], "batl": NaN}, {"timestamp": 1578681451312, "ltp": 1.43, "tv": 217.74, "trd": NaN, "batb": [[0, 1.45, 21.09], [1, 1.44, 8.28]], "batl": NaN}, {"timestamp": 1578681493983, "ltp": 1.43, "tv": 217.74, "trd": NaN, "batb": [[0, 1.44, 8.37], [1, 1.4, 38.28], [2, 1.39, 280.77]], "batl": NaN}, {"timestamp": 1578682887463, "ltp": 1.43, "tv": 217.75, "trd": [[1.42, 8.5], [1.51, 20.59], [1.59, 15.58], [1.63, 58.64]], "batb": [[0, 1.44, 8.37], [1, 1.4, 38.3]], "batl": NaN}, {"timestamp": 1578684071231, "ltp": 1.43, "tv": 217.75, "trd": NaN, "batb": [[0, 1.44, 28.37]], "batl": NaN}, {"timestamp": 1578684097482, "ltp": 1.43, "tv": 217.75, "trd": NaN, "batb": [[0, 1.44, 8.37], [1, 1.41, 20], [2, 1.4, 38.3]], "batl": NaN}, {"timestamp": 1578685032929, "ltp": 1.43, "tv": 217.75, "trd": NaN, "batb": NaN, "batl": [[0, 1.5, 20], [1, 1.52, 4], [2, 1.53, 206.6]]}, {"timestamp": 1578685048438, "ltp": 1.43, "tv": 217.75, "trd": NaN, "batb": NaN, "batl": [[1, 1.53, 206.6], [2, 1.7, 150]]}, {"timestamp": 1578685645416, "ltp": 1.5, "tv": 237.75, "trd": [[1.5, 20.36]], "batb": NaN, "batl": [[0, 1.5, 10]]}, {"timestamp": 1578686108212, "ltp": 1.5, "tv": 237.75, "trd": NaN, "batb": [[2, 1.4, 333.11]], "batl": [[1, 1.7, 150], [2, 2.22, 9]]}, {"timestamp": 1578686118129, "ltp": 1.5, "tv": 237.75, "trd": NaN, "batb": NaN, "batl": [[1, 1.52, 226.77], [2, 1.7, 150]]}, {"timestamp": 1578686407768, "ltp": 1.5, "tv": 237.75, "trd": NaN, "batb": [[1, 1.41, 76]], "batl": [[1, 1.51, 33], [2, 1.52, 226.77]]}, {"timestamp": 1578686482658, "ltp": 1.44, "tv": 253.76, "trd": [[1.44, 16.72], [1.45, 0.18]], "batb": [[0, 1.41, 76.37], [1, 1.4, 333.11], [2, 1.37, 6]], "batl": NaN}, {"timestamp": 1578686491950, "ltp": 1.44, "tv": 253.76, "trd": NaN, "batb": [[0, 1.41, 93.34]], "batl": NaN}, {"timestamp": 1578686500954, "ltp": 1.44, "tv": 253.76, "trd": NaN, "batb": [[0, 1.42, 6.37], [1, 1.41, 92.97], [2, 1.4, 333.11]], "batl": NaN}, {"timestamp": 1578686532530, "ltp": 1.44, "tv": 253.76, "trd": NaN, "batb": [[0, 1.42, 23.34], [1, 1.41, 76]], "batl": NaN}, {"timestamp": 1578686887964, "ltp": 1.44, "tv": 253.76, "trd": NaN, "batb": [[0, 1.43, 3.37], [1, 1.42, 22.97], [2, 1.41, 76]], "batl": NaN}, {"timestamp": 1578686963454, "ltp": 1.44, "tv": 253.76, "trd": NaN, "batb": [[0, 1.43, 25.37], [2, 1.41, 20]], "batl": NaN}, {"timestamp": 1578686964753, "ltp": 1.44, "tv": 253.76, "trd": NaN, "batb": [[0, 1.43, 42.34], [1, 1.42, 6]], "batl": NaN}, {"timestamp": 1578686968890, "ltp": 1.44, "tv": 253.76, "trd": NaN, "batb": [[1, 1.41, 20], [2, 1.4, 333.11]], "batl": NaN}, {"timestamp": 1578686970977, "ltp": 1.44, "tv": 253.76, "trd": NaN, "batb": [[0, 1.43, 39.34]], "batl": NaN}, {"timestamp": 1578687134981, "ltp": 1.44, "tv": 253.76, "trd": NaN, "batb": [[2, 1.4, 958.11]], "batl": NaN}, {"timestamp": 1578688713910, "ltp": 1.44, "tv": 253.76, "trd": NaN, "batb": [[0, 1.44, 8.75], [1, 1.43, 38.97], [2, 1.41, 20]], "batl": NaN}, {"timestamp": 1578688722530, "ltp": 1.44, "tv": 253.76, "trd": NaN, "batb": NaN, "batl": [[2, 1.7, 150]]}, {"timestamp": 1578688767780, "ltp": 1.44, "tv": 253.76, "trd": NaN, "batb": [[0, 1.44, 25.72], [1, 1.43, 22]], "batl": NaN}, {"timestamp": 1578688770903, "ltp": 1.5, "tv": 268.56, "trd": [[1.5, 35.16]], "batb": NaN, "batl": [[0, 1.5, 2.6]]}, {"timestamp": 1578688776790, "ltp": 1.5, "tv": 268.56, "trd": NaN, "batb": NaN, "batl": [[0, 1.5, 6.6]]}, {"timestamp": 1578688792447, "ltp": 1.5, "tv": 268.56, "trd": NaN, "batb": NaN, "batl": [[2, 1.52, 226.77]]}, {"timestamp": 1578688812892, "ltp": 1.5, "tv": 268.56, "trd": NaN, "batb": NaN, "batl": [[2, 1.7, 150]]}, {"timestamp": 1578688838930, "ltp": 1.5, "tv": 268.56, "trd": NaN, "batb": [[0, 1.45, 15.8], [1, 1.44, 25.72]], "batl": NaN}, {"timestamp": 1578688848656, "ltp": 1.5, "tv": 268.56, "trd": NaN, "batb": NaN, "batl": [[0, 1.5, 2.6]]}, {"timestamp": 1578688850847, "ltp": 1.5, "tv": 268.56, "trd": NaN, "batb": [[0, 1.45, 32.77], [1, 1.44, 8.75]], "batl": NaN}, {"timestamp": 1578688932720, "ltp": 1.5, "tv": 268.56, "trd": NaN, "batb": NaN, "batl": [[2, 1.52, 226.77]]}, {"timestamp": 1578688961772, "ltp": 1.5, "tv": 268.56, "trd": NaN, "batb": [[0, 1.45, 16.97], [2, 1.42, 21]], "batl": NaN}, {"timestamp": 1578689076616, "ltp": 1.5, "tv": 268.56, "trd": NaN, "batb": [[0, 1.45, 27.17]], "batl": NaN}, {"timestamp": 1578689206631, "ltp": 1.5, "tv": 268.56, "trd": NaN, "batb": [[2, 1.41, 20]], "batl": NaN}, {"timestamp": 1578689288950, "ltp": 1.5, "tv": 268.56, "trd": NaN, "batb": [[2, 1.41, 22]], "batl": NaN}, {"timestamp": 1578689517579, "ltp": 1.5, "tv": 273.76, "trd": [[1.5, 40.36]], "batb": [[0, 1.5, 18.21], [1, 1.45, 27.17], [2, 1.44, 8.75]], "batl": [[0, 1.51, 33], [1, 1.52, 226.77], [2, 1.7, 150]]}, {"timestamp": 1578689695517, "ltp": 1.5, "tv": 273.76, "trd": NaN, "batb": NaN, "batl": [[0, 1.52, 259.45], [1, 1.7, 150], [2, 2.22, 9]]}, {"timestamp": 1578689704442, "ltp": 1.5, "tv": 310.18, "trd": [[1.5, 76.78]], "batb": [[0, 1.46, 7.98]], "batl": [[0, 1.48, 9.79], [1, 1.52, 259.45], [2, 1.7, 150]]}, {"timestamp": 1578689713943, "ltp": 1.5, "tv": 310.18, "trd": NaN, "batb": NaN, "batl": [[1, 1.52, 32.68]]}, {"timestamp": 1578689780957, "ltp": 1.5, "tv": 310.18, "trd": NaN, "batb": [[1, 1.45, 10.2]], "batl": NaN}, {"timestamp": 1578689781016, "ltp": 1.5, "tv": 310.18, "trd": NaN, "batb": [[0, 1.46, 24.95]], "batl": NaN}, {"timestamp": 1578690146899, "ltp": 1.5, "tv": 310.2, "trd": [[1.42, 8.5], [1.43, 11.97], [1.57, 5.1], [1.59, 15.58], [1.6, 6.13], [1.63, 58.65]], "batb": [[0, 1.46, 24.96], [2, 1.44, 8.75]], "batl": NaN}, {"timestamp": 1578690295728, "ltp": 1.47, "tv": 314.8, "trd": [[1.47, 4.6]], "batb": [[0, 1.47, 10.22], [1, 1.46, 24.96], [2, 1.45, 10.2]], "batl": NaN}, {"timestamp": 1578690296935, "ltp": 1.47, "tv": 314.8, "trd": NaN, "batb": [[0, 1.47, 12.52]], "batl": NaN}, {"timestamp": 1578690297919, "ltp": 1.48, "tv": 334.39, "trd": [[1.48, 79.59]], "batb": [[0, 1.48, 2.81], [1, 1.47, 12.52], [2, 1.46, 24.96]], "batl": [[0, 1.52, 32.68], [1, 1.7, 150], [2, 2.22, 9]]}, {"timestamp": 1578690308931, "ltp": 1.48, "tv": 334.39, "trd": NaN, "batb": NaN, "batl": [[0, 1.7, 150], [1, 2.22, 9], [2, 21, 2]]}, {"timestamp": 1578690309916, "ltp": 1.48, "tv": 334.39, "trd": NaN, "batb": [[2, 1.46, 16.98]], "batl": [[0, 1.69, 7.21], [1, 1.7, 150], [2, 2.22, 9]]}, {"timestamp": 1578690310857, "ltp": 1.48, "tv": 334.39, "trd": NaN, "batb": NaN, "batl": [[0, 1.69, 7.39]]}, {"timestamp": 1578690314646, "ltp": 1.48, "tv": 334.39, "trd": NaN, "batb": NaN, "batl": [[0, 1.52, 226.77], [1, 1.69, 7.39], [2, 1.7, 150]]}, {"timestamp": 1578690315274, "ltp": 1.48, "tv": 334.39, "trd": NaN, "batb": NaN, "batl": [[1, 1.69, 7.21]]}, {"timestamp": 1578690321258, "ltp": 1.48, "tv": 334.39, "trd": NaN, "batb": [[0, 1.48, 12.81]], "batl": NaN}, {"timestamp": 1578690327985, "ltp": 1.48, "tv": 334.39, "trd": NaN, "batb": [[0, 1.49, 10], [1, 1.48, 2.81], [2, 1.47, 12.52]], "batl": NaN}, {"timestamp": 1578690458447, "ltp": 1.48, "tv": 334.39, "trd": NaN, "batb": [[0, 1.5, 11.64], [1, 1.49, 10], [2, 1.48, 2.81]], "batl": NaN}, {"timestamp": 1578690570322, "ltp": 1.5, "tv": 341.63, "trd": [[1.5, 84.02]], "batb": [[0, 1.5, 8.02]], "batl": NaN}, {"timestamp": 1578690721873, "ltp": 1.5, "tv": 353.62, "trd": [[1.5, 96.02]], "batb": [[0, 1.5, 2.03]], "batl": NaN}, {"timestamp": 1578690758925, "ltp": 1.5, "tv": 353.62, "trd": NaN, "batb": [[0, 1.5, 14.67]], "batl": NaN}, {"timestamp": 1578690821967, "ltp": 1.5, "tv": 353.62, "trd": NaN, "batb": [[0, 1.51, 10], [1, 1.5, 14.67]], "batl": NaN}, {"timestamp": 1578690828710, "ltp": 1.52, "tv": 373.62, "trd": [[1.52, 20]], "batb": [[0, 1.5, 14.67], [1, 1.48, 2.81], [2, 1.47, 12.52]], "batl": [[0, 1.52, 216.77]]}, {"timestamp": 1578690835906, "ltp": 1.52, "tv": 373.62, "trd": NaN, "batb": NaN, "batl": [[0, 1.52, 226.77]]}, {"timestamp": 1578690989004, "ltp": 1.5, "tv": 402.96, "trd": [[1.5, 125.36]], "batb": [[0, 1.48, 2.81], [1, 1.47, 12.52], [2, 1.46, 16.98]], "batl": [[0, 1.5, 35.33], [1, 1.52, 226.77], [2, 1.69, 7.21]]}, {"timestamp": 1578690995993, "ltp": 1.5, "tv": 402.96, "trd": NaN, "batb": NaN, "batl": [[1, 1.69, 7.21], [2, 1.7, 150]]}, {"timestamp": 1578691035903, "ltp": 1.5, "tv": 402.96, "trd": NaN, "batb": NaN, "batl": [[1, 1.53, 27.8], [2, 1.69, 7.21]]}, {"timestamp": 1578691286809, "ltp": 1.5, "tv": 473.62, "trd": [[1.5, 196.02]], "batb": [[0, 1.5, 4.67], [1, 1.48, 2.81], [2, 1.47, 12.52]], "batl": [[0, 1.53, 27.8], [1, 1.69, 7.21], [2, 1.7, 150]]}, {"timestamp": 1578691478822, "ltp": 1.5, "tv": 473.62, "trd": NaN, "batb": NaN, "batl": [[0, 1.52, 10], [1, 1.53, 27.8], [2, 1.69, 7.21]]}, {"timestamp": 1578691503492, "ltp": 1.5, "tv": 473.62, "trd": NaN, "batb": NaN, "batl": [[0, 1.52, 9.6]]}, {"timestamp": 1578691612812, "ltp": 1.52, "tv": 474.42, "trd": [[1.52, 20.8]], "batb": NaN, "batl": [[0, 1.52, 9.2]]}, {"timestamp": 1578691674805, "ltp": 1.52, "tv": 492.82, "trd": [[1.52, 39.2]], "batb": NaN, "batl": [[0, 1.53, 27.8], [1, 1.69, 7.21], [2, 1.7, 150]]}, {"timestamp": 1578691772952, "ltp": 1.52, "tv": 492.82, "trd": NaN, "batb": NaN, "batl": [[0, 1.56, 5]]}, {"timestamp": 1578691773624, "ltp": 1.56, "tv": 502.82, "trd": [[1.56, 10]], "batb": NaN, "batl": [[0, 1.69, 7.21], [1, 1.7, 150], [2, 2.22, 9]]}, {"timestamp": 1578691774989, "ltp": 1.56, "tv": 502.82, "trd": NaN, "batb": NaN, "batl": [[0, 1.69, 7.39]]}, {"timestamp": 1578691775494, "ltp": 1.56, "tv": 502.82, "trd": NaN, "batb": NaN, "batl": [[0, 1.68, 4.18], [1, 1.69, 7.21], [2, 1.7, 150]]}, {"timestamp": 1578691785041, "ltp": 1.56, "tv": 502.82, "trd": NaN, "batb": NaN, "batl": [[0, 1.67, 2.18], [1, 1.68, 4], [2, 1.69, 7.21]]}, {"timestamp": 1578691789427, "ltp": 1.56, "tv": 502.82, "trd": NaN, "batb": [[0, 1.51, 7.78], [1, 1.5, 4.67], [2, 1.48, 2.81]], "batl": [[2, 1.7, 150]]}, {"timestamp": 1578691791334, "ltp": 1.56, "tv": 502.82, "trd": NaN, "batb": NaN, "batl": [[2, 1.69, 6]]}, {"timestamp": 1578692261797, "ltp": 1.56, "tv": 502.82, "trd": NaN, "batb": [[0, 1.52, 7.6], [1, 1.51, 7.78], [2, 1.5, 4.67]], "batl": NaN}, {"timestamp": 1578692786864, "ltp": 1.67, "tv": 532.82, "trd": [[1.66, 0.36], [1.67, 29.64]], "batb": NaN, "batl": [[0, 1.68, 4], [1, 1.69, 6], [2, 1.7, 150]]}, {"timestamp": 1578692791760, "ltp": 1.67, "tv": 532.82, "trd": NaN, "batb": NaN, "batl": [[0, 1.68, 4.2]]}, {"timestamp": 1578692792841, "ltp": 1.67, "tv": 532.82, "trd": NaN, "batb": [[0, 1.53, 26.03], [1, 1.52, 7.6], [2, 1.51, 7.78]], "batl": [[1, 1.69, 14.52]]}, {"timestamp": 1578692804583, "ltp": 1.67, "tv": 532.82, "trd": NaN, "batb": [[0, 1.54, 2.17], [1, 1.53, 26.03], [2, 1.52, 7.6]], "batl": NaN}, {"timestamp": 1578692879480, "ltp": 1.67, "tv": 532.82, "trd": NaN, "batb": [[0, 1.55, 19.11], [1, 1.54, 2.17], [2, 1.53, 26.03]], "batl": [[0, 1.67, 10.8], [1, 1.68, 4], [2, 1.69, 14.52]]}, {"timestamp": 1578692886095, "ltp": 1.67, "tv": 532.82, "trd": NaN, "batb": [[2, 1.51, 7.78]], "batl": NaN}, {"timestamp": 1578692887801, "ltp": 1.67, "tv": 532.82, "trd": NaN, "batb": NaN, "batl": [[2, 1.69, 6]]}, {"timestamp": 1578692897397, "ltp": 1.67, "tv": 532.82, "trd": NaN, "batb": NaN, "batl": [[1, 1.69, 6], [2, 1.7, 150]]}, {"timestamp": 1578692901649, "ltp": 1.67, "tv": 532.82, "trd": NaN, "batb": [[0, 1.56, 2.14], [1, 1.55, 19.11]], "batl": NaN}, {"timestamp": 1578693000451, "ltp": 1.67, "tv": 532.82, "trd": NaN, "batb": NaN, "batl": [[0, 1.68, 21.61]]}, {"timestamp": 1578693003940, "ltp": 1.67, "tv": 532.82, "trd": NaN, "batb": NaN, "batl": [[0, 1.67, 4.2], [1, 1.68, 21.41], [2, 1.69, 6]]}, {"timestamp": 1578693028003, "ltp": 1.67, "tv": 532.82, "trd": NaN, "batb": [[0, 1.56, 13.33]], "batl": NaN}, {"timestamp": 1578693032794, "ltp": 1.67, "tv": 532.82, "trd": NaN, "batb": NaN, "batl": [[1, 1.69, 6], [2, 1.7, 150]]}, {"timestamp": 1578693047924, "ltp": 1.67, "tv": 532.82, "trd": NaN, "batb": NaN, "batl": [[0, 1.68, 4.2]]}, {"timestamp": 1578693156632, "ltp": 1.67, "tv": 532.82, "trd": NaN, "batb": NaN, "batl": [[0, 1.67, 6.7], [1, 1.68, 4], [2, 1.69, 6]]}, {"timestamp": 1578693157876, "ltp": 1.67, "tv": 532.82, "trd": NaN, "batb": NaN, "batl": [[1, 1.69, 6], [2, 1.7, 150]]}, {"timestamp": 1578693279803, "ltp": 1.67, "tv": 532.82, "trd": NaN, "batb": NaN, "batl": [[0, 1.68, 27.2]]}, {"timestamp": 1578693288431, "ltp": 1.67, "tv": 532.82, "trd": NaN, "batb": NaN, "batl": [[0, 1.67, 4.2], [1, 1.68, 27], [2, 1.69, 6]]}, {"timestamp": 1578693362760, "ltp": 1.67, "tv": 532.82, "trd": NaN, "batb": NaN, "batl": [[1, 1.69, 6], [2, 1.7, 150]]}, {"timestamp": 1578693375960, "ltp": 1.67, "tv": 532.82, "trd": NaN, "batb": NaN, "batl": [[0, 1.68, 4.2]]}, {"timestamp": 1578693445844, "ltp": 1.67, "tv": 532.82, "trd": NaN, "batb": NaN, "batl": [[1, 1.69, 29.3]]}, {"timestamp": 1578693616445, "ltp": 1.55, "tv": 597.71, "trd": [[1.55, 38.22], [1.56, 36.66]], "batb": [[0, 1.51, 7.78], [1, 1.5, 4.67], [2, 1.48, 2.81]], "batl": [[0, 1.55, 17.56], [1, 1.68, 4.2], [2, 1.69, 29.3]]}, {"timestamp": 1578693618751, "ltp": 1.55, "tv": 597.71, "trd": NaN, "batb": NaN, "batl": [[2, 1.69, 23.3]]}, {"timestamp": 1578693619525, "ltp": 1.55, "tv": 597.71, "trd": NaN, "batb": NaN, "batl": [[1, 1.68, 4]]}, {"timestamp": 1578693622652, "ltp": 1.55, "tv": 597.71, "trd": NaN, "batb": [[0, 1.5, 4.67], [1, 1.48, 2.81], [2, 1.47, 12.52]], "batl": [[0, 1.68, 11.24], [1, 1.69, 23.3], [2, 1.7, 150]]}, {"timestamp": 1578693624958, "ltp": 1.55, "tv": 597.71, "trd": NaN, "batb": NaN, "batl": [[0, 1.68, 11.44]]}, {"timestamp": 1578693633839, "ltp": 1.55, "tv": 597.71, "trd": NaN, "batb": NaN, "batl": [[0, 1.67, 24.05], [1, 1.68, 7.24], [2, 1.69, 23.3]]}, {"timestamp": 1578693664773, "ltp": 1.55, "tv": 597.71, "trd": NaN, "batb": [[0, 1.51, 7.78], [1, 1.5, 54.67], [2, 1.48, 2.81]], "batl": [[1, 1.69, 31.82], [2, 1.7, 150]]}, {"timestamp": 1578693691946, "ltp": 1.55, "tv": 597.71, "trd": NaN, "batb": NaN, "batl": [[1, 1.69, 8.52]]}, {"timestamp": 1578693692154, "ltp": 1.55, "tv": 597.71, "trd": NaN, "batb": [[0, 1.52, 45], [1, 1.51, 7.78], [2, 1.5, 54.67]], "batl": [[0, 1.66, 19.9], [1, 1.67, 23.85], [2, 1.69, 8.52]]}, {"timestamp": 1578693693646, "ltp": 1.55, "tv": 597.71, "trd": NaN, "batb": NaN, "batl": [[2, 1.7, 150]]}, {"timestamp": 1578693697156, "ltp": 1.55, "tv": 597.71, "trd": NaN, "batb": NaN, "batl": [[2, 1.69, 6]]}, {"timestamp": 1578693703945, "ltp": 1.55, "tv": 597.71, "trd": NaN, "batb": NaN, "batl": [[1, 1.69, 6], [2, 1.7, 150]]}, {"timestamp": 1578693772930, "ltp": 1.55, "tv": 597.71, "trd": NaN, "batb": NaN, "batl": [[0, 1.69, 6.2], [1, 1.7, 150], [2, 2, 17.75]]}, {"timestamp": 1578693773807, "ltp": 1.55, "tv": 597.71, "trd": NaN, "batb": NaN, "batl": [[0, 1.68, 21.3], [1, 1.69, 14.52], [2, 1.7, 150]]}, {"timestamp": 1578693794580, "ltp": 1.55, "tv": 597.71, "trd": NaN, "batb": NaN, "batl": [[0, 1.67, 24.05], [1, 1.68, 21.1], [2, 1.69, 14.52]]}, {"timestamp": 1578693845357, "ltp": 1.55, "tv": 597.71, "trd": NaN, "batb": NaN, "batl": [[0, 1.65, 20], [1, 1.67, 24.05], [2, 1.68, 21.1]]}, {"timestamp": 1578693846756, "ltp": 1.55, "tv": 597.71, "trd": NaN, "batb": NaN, "batl": [[0, 1.65, 20.2], [1, 1.67, 23.85]]}, {"timestamp": 1578693853823, "ltp": 1.55, "tv": 597.71, "trd": NaN, "batb": NaN, "batl": [[0, 1.64, 18.2], [1, 1.65, 20], [2, 1.67, 23.85]]}, {"timestamp": 1578693864650, "ltp": 1.55, "tv": 597.71, "trd": NaN, "batb": NaN, "batl": [[2, 1.69, 6]]}, {"timestamp": 1578693877486, "ltp": 1.55, "tv": 597.71, "trd": NaN, "batb": NaN, "batl": [[0, 1.63, 2.2], [1, 1.64, 18], [2, 1.65, 20]]}, {"timestamp": 1578694122947, "ltp": 1.55, "tv": 597.71, "trd": NaN, "batb": [[0, 1.53, 3], [1, 1.52, 45], [2, 1.51, 7.78]], "batl": NaN}, {"timestamp": 1578694181583, "ltp": 1.55, "tv": 597.71, "trd": NaN, "batb": [[1, 1.51, 7.78], [2, 1.5, 54.67]], "batl": NaN}, {"timestamp": 1578694189564, "ltp": 1.55, "tv": 597.71, "trd": NaN, "batb": [[0, 1.52, 3]], "batl": NaN}, {"timestamp": 1578694262582, "ltp": 1.55, "tv": 597.71, "trd": NaN, "batb": [[1, 1.51, 33.88]], "batl": NaN}, {"timestamp": 1578694428802, "ltp": 1.55, "tv": 597.71, "trd": NaN, "batb": NaN, "batl": [[0, 1.62, 4.79], [1, 1.63, 2]]}, {"timestamp": 1578694433816, "ltp": 1.55, "tv": 597.71, "trd": NaN, "batb": [[0, 1.51, 33.88], [1, 1.5, 54.67], [2, 1.48, 2.81]], "batl": NaN}, {"timestamp": 1578694446629, "ltp": 1.55, "tv": 597.71, "trd": NaN, "batb": NaN, "batl": [[0, 1.61, 2.2], [1, 1.62, 4.59]]}, {"timestamp": 1578694509984, "ltp": 1.55, "tv": 597.71, "trd": NaN, "batb": NaN, "batl": [[1, 1.65, 20], [2, 1.69, 6]]}, {"timestamp": 1578694510495, "ltp": 1.55, "tv": 597.71, "trd": NaN, "batb": NaN, "batl": [[0, 1.6, 6.26], [1, 1.61, 2], [2, 1.65, 20]]}, {"timestamp": 1578694528432, "ltp": 1.55, "tv": 597.71, "trd": NaN, "batb": [[0, 1.52, 3], [1, 1.51, 33.88], [2, 1.5, 54.67]], "batl": NaN}, {"timestamp": 1578694542733, "ltp": 1.55, "tv": 597.71, "trd": NaN, "batb": NaN, "batl": [[1, 1.65, 20], [2, 1.69, 6]]}, {"timestamp": 1578694590809, "ltp": 1.55, "tv": 597.71, "trd": NaN, "batb": NaN, "batl": [[0, 1.63, 12.5]]}, {"timestamp": 1578694633837, "ltp": 1.55, "tv": 597.71, "trd": NaN, "batb": NaN, "batl": [[0, 1.62, 2.2], [1, 1.63, 12.3], [2, 1.65, 20]]}, {"timestamp": 1578694635943, "ltp": 1.55, "tv": 597.71, "trd": NaN, "batb": NaN, "batl": [[0, 1.62, 2]]}, {"timestamp": 1578694636057, "ltp": 1.55, "tv": 597.71, "trd": NaN, "batb": NaN, "batl": [[0, 1.62, 2.2]]}, {"timestamp": 1578694672919, "ltp": 1.55, "tv": 597.71, "trd": NaN, "batb": NaN, "batl": [[0, 1.61, 5.64], [1, 1.62, 2]]}, {"timestamp": 1578694678635, "ltp": 1.55, "tv": 597.71, "trd": NaN, "batb": NaN, "batl": [[1, 1.65, 20], [2, 1.69, 6]]}, {"timestamp": 1578694684925, "ltp": 1.55, "tv": 597.71, "trd": NaN, "batb": [[0, 1.51, 33.88], [1, 1.5, 54.67], [2, 1.48, 2.81]], "batl": NaN}, {"timestamp": 1578694754711, "ltp": 1.55, "tv": 597.71, "trd": NaN, "batb": NaN, "batl": [[0, 1.64, 19.2]]}, {"timestamp": 1578694756043, "ltp": 1.55, "tv": 597.71, "trd": NaN, "batb": [[0, 1.52, 3], [1, 1.51, 33.88], [2, 1.5, 54.67]], "batl": NaN}, {"timestamp": 1578694764727, "ltp": 1.51, "tv": 617.71, "trd": [[1.51, 34.59], [1.52, 45.2]], "batb": [[0, 1.51, 26.88], [1, 1.5, 54.67], [2, 1.48, 2.81]], "batl": NaN}, {"timestamp": 1578694765346, "ltp": 1.51, "tv": 617.71, "trd": NaN, "batb": NaN, "batl": [[0, 1.63, 2.2], [1, 1.64, 19], [2, 1.65, 20]]}, {"timestamp": 1578694777965, "ltp": 1.51, "tv": 617.71, "trd": NaN, "batb": NaN, "batl": [[0, 1.62, 3.01], [1, 1.63, 2], [2, 1.64, 19]]}, {"timestamp": 1578694794881, "ltp": 1.51, "tv": 617.71, "trd": NaN, "batb": NaN, "batl": [[0, 1.63, 5], [1, 1.64, 19], [2, 1.65, 20]]}, {"timestamp": 1578694803913, "ltp": 1.51, "tv": 617.71, "trd": NaN, "batb": NaN, "batl": [[0, 1.62, 24.79], [1, 1.63, 4.8], [2, 1.64, 19]]}, {"timestamp": 1578694811334, "ltp": 1.51, "tv": 617.71, "trd": NaN, "batb": NaN, "batl": [[0, 1.61, 3.03], [1, 1.62, 24.59], [2, 1.63, 2]]}, {"timestamp": 1578694814993, "ltp": 1.51, "tv": 617.71, "trd": NaN, "batb": NaN, "batl": [[0, 1.6, 2.2], [1, 1.61, 2.83], [2, 1.62, 24.59]]}, {"timestamp": 1578694827010, "ltp": 1.51, "tv": 617.71, "trd": NaN, "batb": NaN, "batl": [[2, 1.64, 19]]}, {"timestamp": 1578694833350, "ltp": 1.51, "tv": 617.71, "trd": NaN, "batb": NaN, "batl": [[1, 1.63, 2.8]]}, {"timestamp": 1578694837772, "ltp": 1.51, "tv": 617.71, "trd": NaN, "batb": NaN, "batl": [[2, 1.65, 20]]}, {"timestamp": 1578694855889, "ltp": 1.51, "tv": 617.71, "trd": NaN, "batb": NaN, "batl": [[0, 1.59, 2.87], [1, 1.6, 2.2], [2, 1.64, 4]]}, {"timestamp": 1578694862993, "ltp": 1.51, "tv": 617.71, "trd": NaN, "batb": NaN, "batl": [[1, 1.64, 4.2], [2, 1.65, 20]]}, {"timestamp": 1578694877486, "ltp": 1.51, "tv": 617.71, "trd": NaN, "batb": NaN, "batl": [[0, 1.63, 3], [1, 1.64, 4]]}, {"timestamp": 1578694895702, "ltp": 1.51, "tv": 617.71, "trd": NaN, "batb": NaN, "batl": [[0, 1.62, 24.79], [1, 1.63, 2.8], [2, 1.64, 4]]}, {"timestamp": 1578694899814, "ltp": 1.51, "tv": 617.71, "trd": NaN, "batb": NaN, "batl": [[0, 1.61, 3.03], [1, 1.62, 24.59], [2, 1.65, 20]]}, {"timestamp": 1578694917939, "ltp": 1.51, "tv": 617.71, "trd": NaN, "batb": NaN, "batl": [[1, 1.65, 20], [2, 1.69, 6]]}, {"timestamp": 1578694920569, "ltp": 1.51, "tv": 617.71, "trd": NaN, "batb": NaN, "batl": [[1, 1.64, 13.8], [2, 1.65, 20]]}, {"timestamp": 1578694938396, "ltp": 1.51, "tv": 617.71, "trd": NaN, "batb": NaN, "batl": [[0, 1.63, 3]]}, {"timestamp": 1578694941670, "ltp": 1.51, "tv": 617.71, "trd": NaN, "batb": NaN, "batl": [[0, 1.62, 24.79], [1, 1.63, 2.8], [2, 1.64, 13.8]]}, {"timestamp": 1578694954978, "ltp": 1.51, "tv": 617.71, "trd": NaN, "batb": NaN, "batl": [[0, 1.61, 2.2], [1, 1.62, 24.59], [2, 1.63, 2.8]]}, {"timestamp": 1578694955382, "ltp": 1.51, "tv": 617.71, "trd": NaN, "batb": NaN, "batl": [[0, 1.61, 5.03], [2, 1.64, 13.8]]}, {"timestamp": 1578694964194, "ltp": 1.51, "tv": 617.71, "trd": NaN, "batb": NaN, "batl": [[1, 1.64, 13.8], [2, 1.65, 20]]}, {"timestamp": 1578695001874, "ltp": 1.51, "tv": 617.71, "trd": NaN, "batb": NaN, "batl": [[0, 1.6, 4.9], [1, 1.61, 4.83]]}, {"timestamp": 1578695002587, "ltp": 1.51, "tv": 617.71, "trd": NaN, "batb": NaN, "batl": [[1, 1.61, 2.83]]}, {"timestamp": 1578695004745, "ltp": 1.51, "tv": 617.71, "trd": NaN, "batb": NaN, "batl": [[0, 1.59, 2.87], [1, 1.6, 4.9]]}, {"timestamp": 1578695084484, "ltp": 1.51, "tv": 617.71, "trd": NaN, "batb": NaN, "batl": [[0, 1.58, 6.62], [1, 1.59, 2.87], [2, 1.65, 20.2]]}, {"timestamp": 1578695103639, "ltp": 1.51, "tv": 617.71, "trd": NaN, "batb": NaN, "batl": [[0, 1.57, 2.9], [1, 1.58, 6.62]]}, {"timestamp": 1578695104935, "ltp": 1.51, "tv": 617.71, "trd": NaN, "batb": NaN, "batl": [[2, 1.65, 20]]}, {"timestamp": 1578695118525, "ltp": 1.51, "tv": 617.71, "trd": NaN, "batb": NaN, "batl": [[1, 1.6, 4.77]]}, {"timestamp": 1578695125945, "ltp": 1.51, "tv": 617.71, "trd": NaN, "batb": NaN, "batl": [[0, 1.59, 4]]}, {"timestamp": 1578695126048, "ltp": 1.51, "tv": 617.71, "trd": NaN, "batb": NaN, "batl": [[0, 1.59, 6.87]]}, {"timestamp": 1578695148284, "ltp": 1.51, "tv": 617.71, "trd": NaN, "batb": NaN, "batl": [[0, 1.59, 2.87]]}, {"timestamp": 1578695199381, "ltp": 1.51, "tv": 617.71, "trd": NaN, "batb": NaN, "batl": [[0, 1.58, 5.59], [1, 1.59, 2.87]]}, {"timestamp": 1578695213762, "ltp": 1.51, "tv": 617.71, "trd": NaN, "batb": NaN, "batl": [[0, 1.57, 4], [1, 1.58, 5.59], [2, 1.59, 2.87]]}, {"timestamp": 1578695235777, "ltp": 1.51, "tv": 617.71, "trd": NaN, "batb": NaN, "batl": [[0, 1.58, 5.59], [1, 1.64, 6.78], [2, 1.65, 20]]}, {"timestamp": 1578695262924, "ltp": 1.51, "tv": 617.71, "trd": NaN, "batb": NaN, "batl": [[1, 1.64, 2.78]]}, {"timestamp": 1578695263440, "ltp": 1.51, "tv": 617.71, "trd": NaN, "batb": NaN, "batl": [[0, 1.57, 6.9], [1, 1.58, 5.59]]}, {"timestamp": 1578695282650, "ltp": 1.51, "tv": 617.71, "trd": NaN, "batb": [[0, 1.5, 55.45], [1, 1.48, 2.81], [2, 1.47, 12.52]], "batl": [[1, 1.6, 5.2]]}, {"timestamp": 1578695296986, "ltp": 1.51, "tv": 617.71, "trd": NaN, "batb": NaN, "batl": [[0, 1.57, 2.9], [1, 1.59, 4], [2, 1.6, 5.2]]}, {"timestamp": 1578695297456, "ltp": 1.51, "tv": 617.71, "trd": NaN, "batb": NaN, "batl": [[0, 1.59, 6.87], [1, 1.6, 5.2], [2, 1.65, 20]]}, {"timestamp": 1578695325394, "ltp": 1.51, "tv": 617.71, "trd": NaN, "batb": NaN, "batl": [[0, 1.59, 2.87]]}, {"timestamp": 1578695365405, "ltp": 1.51, "tv": 617.71, "trd": NaN, "batb": [[0, 1.51, 42.78], [1, 1.5, 54.67], [2, 1.48, 2.81]], "batl": [[0, 1.58, 6], [1, 1.59, 2.87]]}, {"timestamp": 1578695369390, "ltp": 1.51, "tv": 617.71, "trd": NaN, "batb": NaN, "batl": [[0, 1.57, 4], [1, 1.58, 6], [2, 1.59, 2.87]]}, {"timestamp": 1578695391915, "ltp": 1.51, "tv": 617.71, "trd": NaN, "batb": NaN, "batl": [[0, 1.58, 6], [1, 1.59, 2.87], [2, 1.65, 20]]}, {"timestamp": 1578695392905, "ltp": 1.51, "tv": 617.71, "trd": NaN, "batb": NaN, "batl": [[1, 1.64, 6.78]]}, {"timestamp": 1578695415680, "ltp": 1.51, "tv": 617.71, "trd": NaN, "batb": NaN, "batl": [[0, 1.57, 6.9], [1, 1.58, 6]]}, {"timestamp": 1578695447899, "ltp": 1.51, "tv": 617.71, "trd": NaN, "batb": [[0, 1.5, 107.45], [1, 1.48, 2.81], [2, 1.47, 12.52]], "batl": [[1, 1.6, 5]]}, {"timestamp": 1578695460923, "ltp": 1.51, "tv": 617.71, "trd": NaN, "batb": NaN, "batl": [[0, 1.59, 6.87]]}, {"timestamp": 1578695482838, "ltp": 1.51, "tv": 617.71, "trd": NaN, "batb": NaN, "batl": [[0, 1.59, 2.87]]}, {"timestamp": 1578695531285, "ltp": 1.51, "tv": 617.71, "trd": NaN, "batb": NaN, "batl": [[0, 1.58, 6.7], [1, 1.59, 2.87]]}, {"timestamp": 1578695548607, "ltp": 1.51, "tv": 617.71, "trd": NaN, "batb": NaN, "batl": [[0, 1.57, 4], [1, 1.58, 6.7], [2, 1.59, 2.87]]}, {"timestamp": 1578695570461, "ltp": 1.51, "tv": 617.71, "trd": NaN, "batb": NaN, "batl": [[0, 1.58, 6.7], [1, 1.64, 6.78], [2, 1.65, 20]]}, {"timestamp": 1578695597980, "ltp": 1.51, "tv": 617.71, "trd": NaN, "batb": NaN, "batl": [[0, 1.57, 4], [1, 1.58, 6.7]]}, {"timestamp": 1578695598450, "ltp": 1.51, "tv": 617.71, "trd": NaN, "batb": NaN, "batl": [[0, 1.57, 6.9]]}, {"timestamp": 1578695612976, "ltp": 1.51, "tv": 617.71, "trd": NaN, "batb": NaN, "batl": [[1, 1.6, 4.9]]}, {"timestamp": 1578695625913, "ltp": 1.51, "tv": 617.71, "trd": NaN, "batb": NaN, "batl": [[0, 1.59, 6.87]]}, {"timestamp": 1578695653762, "ltp": 1.51, "tv": 617.71, "trd": NaN, "batb": NaN, "batl": [[0, 1.59, 2.87]]}, {"timestamp": 1578695692192, "ltp": 1.59, "tv": 618.38, "trd": [[1.59, 16.26]], "batb": NaN, "batl": [[0, 1.59, 2.53]]}, {"timestamp": 1578695694608, "ltp": 1.59, "tv": 618.38, "trd": NaN, "batb": NaN, "batl": [[0, 1.58, 4.63], [1, 1.59, 2.53]]}, {"timestamp": 1578695697435, "ltp": 1.59, "tv": 618.38, "trd": NaN, "batb": NaN, "batl": [[1, 1.64, 4]]}, {"timestamp": 1578695705632, "ltp": 1.59, "tv": 618.38, "trd": NaN, "batb": NaN, "batl": [[1, 1.59, 3.83], [2, 1.64, 4]]}, {"timestamp": 1578695719553, "ltp": 1.59, "tv": 618.38, "trd": NaN, "batb": NaN, "batl": [[0, 1.57, 2.56], [1, 1.58, 4.63], [2, 1.59, 3.83]]}, {"timestamp": 1578695887348, "ltp": 1.59, "tv": 618.38, "trd": NaN, "batb": NaN, "batl": [[0, 1.57, 6.39], [2, 1.65, 20]]}, {"timestamp": 1578695940442, "ltp": 1.59, "tv": 618.38, "trd": NaN, "batb": NaN, "batl": [[1, 1.6, 6.7]]}, {"timestamp": 1578695999805, "ltp": 1.59, "tv": 618.38, "trd": NaN, "batb": [[0, 1.51, 17.11], [1, 1.5, 106.67], [2, 1.48, 2.81]], "batl": NaN}, {"timestamp": 1578696360995, "ltp": 1.57, "tv": 631.16, "trd": [[1.57, 17.88]], "batb": [[0, 1.57, 23.61], [1, 1.51, 17.11], [2, 1.5, 106.67]], "batl": [[0, 1.6, 6.7], [1, 1.65, 20], [2, 1.7, 150]]}, {"timestamp": 1578696376906, "ltp": 1.57, "tv": 666.28, "trd": [[1.57, 53]], "batb": [[0, 1.57, 6.05], [1, 1.51, 16.33]], "batl": [[0, 1.59, 14.16], [1, 1.6, 6.7], [2, 1.65, 20]]}, {"timestamp": 1578696379941, "ltp": 1.57, "tv": 678.38, "trd": [[1.57, 65.1]], "batb": [[0, 1.51, 16.33], [1, 1.5, 106.67], [2, 1.48, 2.81]], "batl": [[0, 1.57, 18.95], [1, 1.59, 14.16], [2, 1.6, 6.7]]}, {"timestamp": 1578696380042, "ltp": 1.57, "tv": 678.38, "trd": NaN, "batb": NaN, "batl": [[1, 1.6, 6.7], [2, 1.65, 20]]}, {"timestamp": 1578696383804, "ltp": 1.57, "tv": 678.38, "trd": NaN, "batb": NaN, "batl": [[0, 1.6, 6.7], [1, 1.65, 20], [2, 1.7, 150]]}, {"timestamp": 1578696388855, "ltp": 1.57, "tv": 678.38, "trd": NaN, "batb": NaN, "batl": [[0, 1.59, 4], [1, 1.6, 6.7], [2, 1.65, 20]]}, {"timestamp": 1578696389941, "ltp": 1.57, "tv": 678.38, "trd": NaN, "batb": [[0, 1.53, 3.93], [1, 1.51, 16.33], [2, 1.5, 106.67]], "batl": NaN}, {"timestamp": 1578696404856, "ltp": 1.57, "tv": 678.38, "trd": NaN, "batb": [[1, 1.52, 3], [2, 1.51, 16.33]], "batl": [[0, 1.6, 6.7], [1, 1.65, 20], [2, 1.69, 6]]}, {"timestamp": 1578696432390, "ltp": 1.57, "tv": 678.38, "trd": NaN, "batb": [[1, 1.52, 14]], "batl": [[0, 1.62, 13.94], [1, 1.63, 15.46], [2, 1.65, 20]]}, {"timestamp": 1578696441491, "ltp": 1.57, "tv": 678.38, "trd": NaN, "batb": [[1, 1.52, 64]], "batl": [[0, 1.63, 15.46], [1, 1.65, 20], [2, 1.69, 6]]}, {"timestamp": 1578696445564, "ltp": 1.57, "tv": 678.38, "trd": NaN, "batb": NaN, "batl": [[0, 1.63, 15.64]]}, {"timestamp": 1578696469308, "ltp": 1.57, "tv": 678.38, "trd": NaN, "batb": NaN, "batl": [[0, 1.62, 2.18], [1, 1.63, 15.46], [2, 1.65, 20]]}, {"timestamp": 1578696514990, "ltp": 1.57, "tv": 678.38, "trd": NaN, "batb": NaN, "batl": [[0, 1.61, 5.88], [1, 1.62, 2.18]]}, {"timestamp": 1578696560354, "ltp": 1.57, "tv": 678.38, "trd": NaN, "batb": NaN, "batl": [[1, 1.65, 20.18], [2, 1.69, 6]]}, {"timestamp": 1578696596214, "ltp": 1.57, "tv": 678.38, "trd": NaN, "batb": NaN, "batl": [[0, 1.64, 16.98], [1, 1.65, 20]]}, {"timestamp": 1578696655293, "ltp": 1.57, "tv": 678.38, "trd": NaN, "batb": NaN, "batl": [[0, 1.63, 2.18], [1, 1.64, 16.8], [2, 1.65, 20]]}, {"timestamp": 1578696677702, "ltp": 1.57, "tv": 678.38, "trd": NaN, "batb": NaN, "batl": [[0, 1.62, 6.18], [1, 1.63, 2]]}, {"timestamp": 1578696703182, "ltp": 1.57, "tv": 678.38, "trd": NaN, "batb": NaN, "batl": [[1, 1.65, 20], [2, 1.69, 6]]}, {"timestamp": 1578696760846, "ltp": 1.57, "tv": 678.38, "trd": NaN, "batb": NaN, "batl": [[0, 1.64, 18.18]]}, {"timestamp": 1578696781845, "ltp": 1.61, "tv": 682.38, "trd": [[1.61, 4]], "batb": NaN, "batl": [[0, 1.63, 14.05], [1, 1.64, 18], [2, 1.65, 22]]}, {"timestamp": 1578696795551, "ltp": 1.61, "tv": 682.38, "trd": NaN, "batb": NaN, "batl": [[0, 1.62, 2.18], [1, 1.63, 13.87], [2, 1.64, 18]]}, {"timestamp": 1578696843731, "ltp": 1.61, "tv": 682.38, "trd": NaN, "batb": NaN, "batl": [[0, 1.61, 9.4], [1, 1.62, 2.18], [2, 1.65, 22]]}, {"timestamp": 1578696891769, "ltp": 1.61, "tv": 682.38, "trd": NaN, "batb": NaN, "batl": [[1, 1.65, 22.18], [2, 1.69, 6]]}, {"timestamp": 1578696900279, "ltp": 1.61, "tv": 682.38, "trd": NaN, "batb": [[0, 1.54, 9.37], [1, 1.53, 3.93], [2, 1.52, 64]], "batl": NaN}, {"timestamp": 1578696917721, "ltp": 1.61, "tv": 682.38, "trd": NaN, "batb": [[0, 1.55, 3], [1, 1.54, 9.37], [2, 1.53, 3.93]], "batl": [[1, 1.65, 22]]}, {"timestamp": 1578696928708, "ltp": 1.61, "tv": 682.38, "trd": NaN, "batb": NaN, "batl": [[0, 1.64, 30.4]]}, {"timestamp": 1578697033030, "ltp": 1.61, "tv": 682.38, "trd": NaN, "batb": NaN, "batl": [[0, 1.63, 3.06], [1, 1.64, 30.4], [2, 1.65, 22]]}, {"timestamp": 1578697055972, "ltp": 1.61, "tv": 682.38, "trd": NaN, "batb": [[2, 1.52, 61]], "batl": NaN}, {"timestamp": 1578697056947, "ltp": 1.61, "tv": 682.38, "trd": NaN, "batb": [[0, 1.56, 3.85], [1, 1.55, 3], [2, 1.54, 9.37]], "batl": NaN}, {"timestamp": 1578697079099, "ltp": 1.61, "tv": 682.38, "trd": NaN, "batb": NaN, "batl": [[0, 1.62, 4], [1, 1.63, 3.06], [2, 1.64, 30.4]]}, {"timestamp": 1578697093505, "ltp": 1.61, "tv": 682.38, "trd": NaN, "batb": NaN, "batl": [[0, 1.61, 4.6], [1, 1.62, 4], [2, 1.63, 3.06]]}, {"timestamp": 1578697095807, "ltp": 1.61, "tv": 682.38, "trd": NaN, "batb": NaN, "batl": [[1, 1.63, 3.06], [2, 1.65, 22]]}, {"timestamp": 1578697112522, "ltp": 1.61, "tv": 682.38, "trd": NaN, "batb": [[1, 1.54, 9.37], [2, 1.53, 6]], "batl": NaN}, {"timestamp": 1578697176441, "ltp": 1.61, "tv": 682.38, "trd": NaN, "batb": [[2, 1.52, 50]], "batl": NaN}, {"timestamp": 1578697220268, "ltp": 1.61, "tv": 682.29, "trd": [[1.4, 3.96], [1.42, 8.5], [1.43, 11.97], [1.44, 16.72], [1.47, 4.6], [1.48, 79.58], [1.5, 196], [1.51, 34.58], [1.56, 36.65], [1.57, 65.09], [1.59, 16.25], [1.6, 6.12], [1.63, 58.63]], "batb": [[0, 1.56, 3.85], [1, 1.54, 9.36]], "batl": [[0, 1.63, 3.06], [1, 1.65, 22], [2, 1.69, 6]]}, {"timestamp": 1578697300925, "ltp": 1.61, "tv": 682.29, "trd": NaN, "batb": [[2, 1.53, 16]], "batl": NaN}, {"timestamp": 1578697441814, "ltp": 1.56, "tv": 689.99, "trd": [[1.56, 44.35]], "batb": [[0, 1.54, 9.36], [1, 1.53, 16], [2, 1.52, 50]], "batl": [[0, 1.56, 13.18], [1, 1.63, 3.06], [2, 1.65, 22]]}, {"timestamp": 1578697457551, "ltp": 1.54, "tv": 708.72, "trd": [[1.54, 18.73]], "batb": [[0, 1.53, 16], [1, 1.52, 50], [2, 1.51, 16.32]], "batl": [[0, 1.54, 3.81]]}, {"timestamp": 1578697465961, "ltp": 1.54, "tv": 708.72, "trd": NaN, "batb": [[0, 1.52, 50], [1, 1.51, 32.7], [2, 1.5, 4.67]], "batl": [[1, 1.61, 5], [2, 1.63, 3.06]]}, {"timestamp": 1578697477943, "ltp": 1.52, "tv": 716.34, "trd": [[1.52, 52.82]], "batb": [[0, 1.52, 46.19]], "batl": [[0, 1.61, 5], [1, 1.63, 3.06], [2, 1.65, 22]]}, {"timestamp": 1578697547815, "ltp": 1.52, "tv": 716.34, "trd": NaN, "batb": NaN, "batl": [[0, 1.63, 3.06], [1, 1.65, 22], [2, 1.69, 6]]}, {"timestamp": 1578697549505, "ltp": 1.52, "tv": 716.34, "trd": NaN, "batb": NaN, "batl": [[0, 1.63, 3.25]]}, {"timestamp": 1578697593687, "ltp": 1.52, "tv": 716.34, "trd": NaN, "batb": NaN, "batl": [[0, 1.62, 2.19], [1, 1.63, 3.06], [2, 1.65, 22]]}, {"timestamp": 1578697916791, "ltp": 1.52, "tv": 716.34, "trd": NaN, "batb": [[0, 1.53, 11.41], [1, 1.52, 46.19], [2, 1.51, 32.7]], "batl": NaN}, {"timestamp": 1578697961228, "ltp": 1.52, "tv": 716.34, "trd": NaN, "batb": [[0, 1.53, 26.41], [2, 1.51, 16.32]], "batl": NaN}, {"timestamp": 1578698077945, "ltp": 1.52, "tv": 716.34, "trd": NaN, "batb": NaN, "batl": [[1, 1.63, 23.06], [2, 1.65, 2]]}, {"timestamp": 1578698089776, "ltp": 1.52, "tv": 716.34, "trd": NaN, "batb": [[0, 1.54, 3], [1, 1.53, 26.41], [2, 1.52, 46.19]], "batl": NaN}, {"timestamp": 1578698101566, "ltp": 1.52, "tv": 716.34, "trd": NaN, "batb": NaN, "batl": [[0, 1.63, 23.25], [1, 1.65, 2], [2, 1.69, 6]]}, {"timestamp": 1578698126395, "ltp": 1.52, "tv": 716.34, "trd": NaN, "batb": NaN, "batl": [[0, 1.62, 5.07], [1, 1.63, 23.06], [2, 1.65, 2]]}, {"timestamp": 1578698208691, "ltp": 1.52, "tv": 716.34, "trd": NaN, "batb": [[1, 1.53, 11.41]], "batl": NaN}, {"timestamp": 1578698592866, "ltp": 1.54, "tv": 720.34, "trd": [[1.54, 22.73]], "batb": [[0, 1.54, 1]], "batl": NaN}, {"timestamp": 1578698601383, "ltp": 1.62, "tv": 732.34, "trd": [[1.61, 4.38], [1.62, 11.62]], "batb": NaN, "batl": [[0, 1.63, 23.06], [1, 1.65, 2], [2, 1.69, 6]]}, {"timestamp": 1578698616913, "ltp": 1.62, "tv": 732.34, "trd": NaN, "batb": NaN, "batl": [[0, 1.62, 2], [1, 1.63, 23.06], [2, 1.65, 2]]}, {"timestamp": 1578698617783, "ltp": 1.62, "tv": 732.34, "trd": NaN, "batb": NaN, "batl": [[0, 1.61, 4.85], [1, 1.62, 2], [2, 1.63, 23.06]]}, {"timestamp": 1578698945272, "ltp": 1.62, "tv": 732.34, "trd": NaN, "batb": NaN, "batl": [[1, 1.63, 23.06], [2, 1.65, 2]]}, {"timestamp": 1578699346099, "ltp": 1.62, "tv": 732.34, "trd": NaN, "batb": NaN, "batl": [[1, 1.63, 20]]}, {"timestamp": 1578699626749, "ltp": 1.62, "tv": 732.34, "trd": NaN, "batb": [[1, 1.53, 23.91]], "batl": NaN}, {"timestamp": 1578700328686, "ltp": 1.53, "tv": 762.34, "trd": [[1.53, 34], [1.54, 24.73]], "batb": [[0, 1.53, 9.91], [1, 1.52, 46.19], [2, 1.51, 16.32]], "batl": NaN}, {"timestamp": 1578700345721, "ltp": 1.53, "tv": 762.34, "trd": NaN, "batb": NaN, "batl": [[0, 1.6, 2.89], [1, 1.61, 4.85], [2, 1.63, 20]]}, {"timestamp": 1578700388556, "ltp": 1.53, "tv": 762.34, "trd": NaN, "batb": [[0, 1.52, 46.19], [1, 1.51, 16.32], [2, 1.5, 4.67]], "batl": NaN}, {"timestamp": 1578700540777, "ltp": 1.53, "tv": 762.34, "trd": NaN, "batb": NaN, "batl": [[1, 1.63, 20], [2, 1.65, 2]]}, {"timestamp": 1578700542881, "ltp": 1.53, "tv": 762.34, "trd": NaN, "batb": NaN, "batl": [[0, 1.62, 2.85]]}, {"timestamp": 1578700545862, "ltp": 1.53, "tv": 762.34, "trd": NaN, "batb": NaN, "batl": [[0, 1.62, 3.03]]}, {"timestamp": 1578700561938, "ltp": 1.53, "tv": 762.34, "trd": NaN, "batb": NaN, "batl": [[0, 1.61, 2.18], [1, 1.62, 2.85], [2, 1.63, 20]]}, {"timestamp": 1578700564454, "ltp": 1.53, "tv": 762.34, "trd": NaN, "batb": NaN, "batl": [[0, 1.6, 2.89], [1, 1.61, 2.18]]}, {"timestamp": 1578700619971, "ltp": 1.53, "tv": 762.34, "trd": NaN, "batb": NaN, "batl": [[1, 1.63, 20.18], [2, 1.65, 2]]}, {"timestamp": 1578700640697, "ltp": 1.53, "tv": 762.34, "trd": NaN, "batb": [[0, 1.53, 11.41], [1, 1.52, 46.19], [2, 1.51, 16.32]], "batl": [[0, 1.62, 3.03], [1, 1.63, 20]]}, {"timestamp": 1578700691064, "ltp": 1.53, "tv": 762.34, "trd": NaN, "batb": [[0, 1.53, 28.61]], "batl": [[0, 1.61, 4.73], [1, 1.62, 2.85], [2, 1.63, 20]]}, {"timestamp": 1578700787611, "ltp": 1.53, "tv": 762.34, "trd": NaN, "batb": NaN, "batl": [[0, 1.58, 18.95], [1, 1.61, 4.73], [2, 1.62, 2.85]]}, {"timestamp": 1578700791617, "ltp": 1.53, "tv": 762.34, "trd": NaN, "batb": NaN, "batl": [[1, 1.61, 4.55]]}, {"timestamp": 1578700821946, "ltp": 1.53, "tv": 762.34, "trd": NaN, "batb": NaN, "batl": [[0, 1.57, 2.94], [1, 1.58, 18.95], [2, 1.61, 4.55]]}, {"timestamp": 1578700843389, "ltp": 1.53, "tv": 762.34, "trd": NaN, "batb": [[0, 1.53, 11.41]], "batl": NaN}, {"timestamp": 1578701288750, "ltp": 1.53, "tv": 770.14, "trd": [[1.53, 41.79]], "batb": [[0, 1.53, 7.51]], "batl": NaN}, {"timestamp": 1578701530288, "ltp": 1.53, "tv": 770.14, "trd": NaN, "batb": [[0, 1.53, 17.51]], "batl": NaN}, {"timestamp": 1578702021937, "ltp": 1.53, "tv": 770.14, "trd": NaN, "batb": [[0, 1.53, 34.47]], "batl": NaN}, {"timestamp": 1578702726252, "ltp": 1.53, "tv": 770.14, "trd": NaN, "batb": [[0, 1.54, 23.28], [1, 1.53, 34.47], [2, 1.52, 46.19]], "batl": NaN}, {"timestamp": 1578702868597, "ltp": 1.53, "tv": 770.14, "trd": NaN, "batb": [[0, 1.55, 11.26], [1, 1.54, 23.28], [2, 1.53, 26.96]], "batl": NaN}, {"timestamp": 1578703678715, "ltp": 1.57, "tv": 776.01, "trd": [[1.57, 70.97]], "batb": [[0, 1.57, 10.43], [1, 1.55, 411.26], [2, 1.54, 23.28]], "batl": [[0, 1.58, 18.95], [1, 1.61, 4.55], [2, 1.63, 20]]}, {"timestamp": 1578703679540, "ltp": 1.58, "tv": 801.55, "trd": [[1.58, 25.54]], "batb": [[1, 1.56, 11.59], [2, 1.55, 411.26]], "batl": [[0, 1.58, 6.18]]}, {"timestamp": 1578704128314, "ltp": 1.58, "tv": 801.55, "trd": NaN, "batb": [[0, 1.57, 17.24]], "batl": NaN}, {"timestamp": 1578704368997, "ltp": 1.58, "tv": 801.55, "trd": NaN, "batb": NaN, "batl": [[1, 1.63, 20], [2, 1.7, 150]]}, {"timestamp": 1578704599811, "ltp": 1.58, "tv": 809.55, "trd": [[1.58, 33.54]], "batb": NaN, "batl": [[0, 1.58, 2.18]]}, {"timestamp": 1578704863210, "ltp": 1.58, "tv": 809.55, "trd": NaN, "batb": [[0, 1.57, 10.43]], "batl": NaN}, {"timestamp": 1578704952839, "ltp": 1.58, "tv": 813.91, "trd": [[1.58, 37.9]], "batb": [[0, 1.58, 11.86], [1, 1.57, 10.43], [2, 1.56, 11.59]], "batl": [[0, 1.63, 20], [1, 1.7, 150], [2, 1.75, 2]]}, {"timestamp": 1578704954841, "ltp": 1.58, "tv": 813.91, "trd": NaN, "batb": [[2, 1.55, 400]], "batl": NaN}, {"timestamp": 1578704955148, "ltp": 1.58, "tv": 813.91, "trd": NaN, "batb": [[2, 1.56, 6]], "batl": NaN}, {"timestamp": 1578704969661, "ltp": 1.58, "tv": 813.91, "trd": NaN, "batb": [[0, 1.58, 11.04]], "batl": [[0, 1.62, 2.13], [1, 1.63, 20], [2, 1.7, 150]]}, {"timestamp": 1578705257994, "ltp": 1.58, "tv": 813.91, "trd": NaN, "batb": NaN, "batl": [[0, 1.61, 1.7], [1, 1.62, 2.13], [2, 1.63, 20]]}, {"timestamp": 1578705258765, "ltp": 1.58, "tv": 813.91, "trd": NaN, "batb": NaN, "batl": [[0, 1.62, 2.13], [1, 1.63, 20], [2, 1.7, 150]]}, {"timestamp": 1578706837932, "ltp": 1.62, "tv": 851.99, "trd": [[1.62, 49.7]], "batb": [[0, 1.62, 1.96], [1, 1.58, 11.04], [2, 1.57, 10.43]], "batl": [[0, 1.63, 20], [1, 1.7, 150], [2, 1.75, 2]]}, {"timestamp": 1578706913928, "ltp": 1.62, "tv": 851.99, "trd": NaN, "batb": [[0, 1.58, 11.04], [1, 1.57, 10.43], [2, 1.56, 6]], "batl": NaN}, {"timestamp": 1578706939739, "ltp": 1.63, "tv": 857.99, "trd": [[1.63, 64.63]], "batb": NaN, "batl": [[0, 1.63, 17]]}, {"timestamp": 1578706940148, "ltp": 1.63, "tv": 857.99, "trd": NaN, "batb": [[0, 1.59, 15.07], [1, 1.58, 11.04], [2, 1.57, 10.43]], "batl": NaN}, {"timestamp": 1578707069163, "ltp": 1.63, "tv": 857.99, "trd": NaN, "batb": [[0, 1.6, 10.9], [1, 1.59, 15.07]], "batl": NaN}, {"timestamp": 1578707812521, "ltp": 1.63, "tv": 857.99, "trd": NaN, "batb": NaN, "batl": [[0, 1.62, 2.5], [1, 1.63, 17], [2, 1.7, 150]]}, {"timestamp": 1578707813810, "ltp": 1.63, "tv": 857.99, "trd": NaN, "batb": NaN, "batl": [[0, 1.63, 17], [1, 1.7, 150], [2, 1.75, 2]]}, {"timestamp": 1578709463073, "ltp": 1.63, "tv": 857.99, "trd": NaN, "batb": [[0, 1.6, 21.9]], "batl": NaN}, {"timestamp": 1578710170806, "ltp": 1.63, "tv": 857.99, "trd": NaN, "batb": [[0, 1.61, 3.4], [1, 1.6, 21.9], [2, 1.59, 15.07]], "batl": NaN}, {"timestamp": 1578710171472, "ltp": 1.63, "tv": 857.99, "trd": NaN, "batb": [[0, 1.6, 21.9], [1, 1.59, 15.07], [2, 1.57, 10.43]], "batl": NaN}, {"timestamp": 1578710979801, "ltp": 1.63, "tv": 857.99, "trd": NaN, "batb": [[0, 1.61, 1.96], [1, 1.6, 21.9], [2, 1.59, 15.07]], "batl": NaN}, {"timestamp": 1578710980729, "ltp": 1.63, "tv": 857.99, "trd": NaN, "batb": [[0, 1.6, 21.9], [1, 1.59, 15.07], [2, 1.57, 10.43]], "batl": NaN}, {"timestamp": 1578711522789, "ltp": 1.63, "tv": 857.99, "trd": NaN, "batb": NaN, "batl": [[1, 1.65, 4.2], [2, 1.7, 150]]}, {"timestamp": 1578712916888, "ltp": 1.63, "tv": 857.99, "trd": NaN, "batb": NaN, "batl": [[0, 1.62, 1.53], [1, 1.63, 17], [2, 1.65, 4.2]]}, {"timestamp": 1578712917300, "ltp": 1.63, "tv": 857.99, "trd": NaN, "batb": NaN, "batl": [[0, 1.63, 17], [1, 1.65, 4.2], [2, 1.7, 150]]}, {"timestamp": 1578718429510, "ltp": 1.63, "tv": 857.99, "trd": NaN, "batb": [[1, 1.57, 10.43], [2, 1.56, 6]], "batl": [[0, 1.62, 26.38], [1, 1.63, 17], [2, 1.65, 4.2]]}, {"timestamp": 1578719087626, "ltp": 1.63, "tv": 857.99, "trd": NaN, "batb": NaN, "batl": [[2, 1.7, 150]]}, {"timestamp": 1578720068695, "ltp": 1.62, "tv": 897.99, "trd": [[1.62, 89.69]], "batb": NaN, "batl": [[0, 1.62, 6.38]]}, {"timestamp": 1578721191857, "ltp": 1.62, "tv": 897.99, "trd": NaN, "batb": NaN, "batl": [[2, 1.65, 7.05]]}, {"timestamp": 1578721910946, "ltp": 1.62, "tv": 905.98, "trd": [[1.62, 97.69]], "batb": NaN, "batl": [[0, 1.62, 2.38]]}, {"timestamp": 1578722303636, "ltp": 1.63, "tv": 944.76, "trd": [[1.62, 102.47], [1.63, 98.63]], "batb": [[0, 1.6, 22.51]], "batl": [[0, 1.65, 7.05], [1, 1.7, 150], [2, 1.75, 2]]}, {"timestamp": 1578722304718, "ltp": 1.63, "tv": 944.76, "trd": NaN, "batb": NaN, "batl": [[1, 1.69, 9.45], [2, 1.7, 150]]}, {"timestamp": 1578722315029, "ltp": 1.63, "tv": 944.76, "trd": NaN, "batb": [[0, 1.6, 21.9]], "batl": NaN}, {"timestamp": 1578722451449, "ltp": 1.63, "tv": 944.76, "trd": NaN, "batb": [[1, 1.58, 21.3], [2, 1.57, 10.43]], "batl": [[0, 1.68, 10.46]]}, {"timestamp": 1578722462926, "ltp": 1.63, "tv": 944.76, "trd": NaN, "batb": NaN, "batl": [[0, 1.68, 13.46]]}, {"timestamp": 1578722476954, "ltp": 1.63, "tv": 944.76, "trd": NaN, "batb": NaN, "batl": [[0, 1.67, 4], [1, 1.68, 13.46], [2, 1.69, 9.45]]}, {"timestamp": 1578722477778, "ltp": 1.63, "tv": 944.76, "trd": NaN, "batb": [[0, 1.61, 14.91], [1, 1.6, 21.9], [2, 1.58, 21.3]], "batl": NaN}, {"timestamp": 1578722483683, "ltp": 1.63, "tv": 944.76, "trd": NaN, "batb": NaN, "batl": [[0, 1.67, 7]]}, {"timestamp": 1578722566826, "ltp": 1.63, "tv": 944.76, "trd": NaN, "batb": [[0, 1.62, 3], [1, 1.61, 14.91], [2, 1.6, 21.9]], "batl": [[1, 1.68, 10.46]]}, {"timestamp": 1578722575003, "ltp": 1.63, "tv": 944.76, "trd": NaN, "batb": NaN, "batl": [[0, 1.67, 3]]}, {"timestamp": 1578722699045, "ltp": 1.63, "tv": 944.76, "trd": NaN, "batb": [[0, 1.62, 13.77], [2, 1.6, 11]], "batl": NaN}, {"timestamp": 1578722700381, "ltp": 1.63, "tv": 944.76, "trd": NaN, "batb": NaN, "batl": [[2, 1.7, 150]]}, {"timestamp": 1578722723884, "ltp": 1.63, "tv": 944.76, "trd": NaN, "batb": [[0, 1.62, 10.77]], "batl": NaN}, {"timestamp": 1578722938972, "ltp": 1.62, "tv": 964.6, "trd": [[1.62, 122.3]], "batb": [[0, 1.61, 15.76], [1, 1.6, 11], [2, 1.58, 21.3]], "batl": NaN}, {"timestamp": 1578722939749, "ltp": 1.62, "tv": 966.3, "trd": [[1.62, 124]], "batb": [[0, 1.61, 14.91]], "batl": [[2, 1.69, 9.66]]}, {"timestamp": 1578722956484, "ltp": 1.62, "tv": 966.3, "trd": NaN, "batb": [[0, 1.62, 3], [1, 1.61, 14.91], [2, 1.6, 11]], "batl": NaN}, {"timestamp": 1578723122891, "ltp": 1.61, "tv": 987.94, "trd": [[1.61, 20.02], [1.62, 130]], "batb": [[0, 1.61, 7.09], [1, 1.6, 11], [2, 1.58, 21.3]], "batl": NaN}, {"timestamp": 1578723140118, "ltp": 1.61, "tv": 987.94, "trd": NaN, "batb": NaN, "batl": [[0, 1.67, 5.91]]}, {"timestamp": 1578723270203, "ltp": 1.61, "tv": 987.94, "trd": NaN, "batb": [[0, 1.62, 10.77], [1, 1.61, 7.09], [2, 1.6, 11]], "batl": NaN}, {"timestamp": 1578723292915, "ltp": 1.61, "tv": 987.94, "trd": NaN, "batb": NaN, "batl": [[1, 1.69, 9.66], [2, 1.7, 150]]}, {"timestamp": 1578723293018, "ltp": 1.61, "tv": 987.94, "trd": NaN, "batb": NaN, "batl": [[0, 1.66, 3.59], [1, 1.67, 5.91], [2, 1.69, 9.66]]}, {"timestamp": 1578723296021, "ltp": 1.61, "tv": 987.94, "trd": NaN, "batb": NaN, "batl": [[1, 1.67, 3]]}, {"timestamp": 1578723313636, "ltp": 1.62, "tv": 1009.47, "trd": [[1.62, 151.54]], "batb": [[0, 1.61, 7.09], [1, 1.6, 11], [2, 1.57, 10.43]], "batl": NaN}, {"timestamp": 1578723324447, "ltp": 1.62, "tv": 1009.47, "trd": NaN, "batb": NaN, "batl": [[0, 1.66, 6.52]]}, {"timestamp": 1578723325366, "ltp": 1.62, "tv": 1009.47, "trd": NaN, "batb": NaN, "batl": [[0, 1.66, 9.52], [1, 1.69, 9.66], [2, 1.7, 150]]}, {"timestamp": 1578723327652, "ltp": 1.62, "tv": 1009.47, "trd": NaN, "batb": NaN, "batl": [[1, 1.7, 150], [2, 1.75, 2]]}, {"timestamp": 1578723395865, "ltp": 1.62, "tv": 1009.47, "trd": NaN, "batb": NaN, "batl": [[0, 1.66, 6.52], [1, 1.69, 3], [2, 1.7, 150]]}, {"timestamp": 1578723396694, "ltp": 1.62, "tv": 1009.47, "trd": NaN, "batb": NaN, "batl": [[1, 1.69, 13.1]]}, {"timestamp": 1578723547130, "ltp": 1.62, "tv": 1009.47, "trd": NaN, "batb": NaN, "batl": [[1, 1.68, 3], [2, 1.69, 10.1]]}, {"timestamp": 1578723582881, "ltp": 1.62, "tv": 1009.47, "trd": NaN, "batb": NaN, "batl": [[1, 1.67, 3]]}, {"timestamp": 1578723617413, "ltp": 1.62, "tv": 1009.47, "trd": NaN, "batb": NaN, "batl": [[0, 1.66, 9.52], [1, 1.69, 10.1], [2, 1.7, 150]]}, {"timestamp": 1578723619625, "ltp": 1.62, "tv": 1009.47, "trd": NaN, "batb": NaN, "batl": [[1, 1.7, 150], [2, 1.75, 2]]}, {"timestamp": 1578723629994, "ltp": 1.62, "tv": 1009.47, "trd": NaN, "batb": NaN, "batl": [[0, 1.66, 6.52], [1, 1.69, 3], [2, 1.7, 150]]}, {"timestamp": 1578723630824, "ltp": 1.62, "tv": 1009.47, "trd": NaN, "batb": NaN, "batl": [[1, 1.69, 13.1]]}, {"timestamp": 1578723641002, "ltp": 1.62, "tv": 1009.47, "trd": NaN, "batb": NaN, "batl": [[1, 1.68, 3], [2, 1.69, 10.1]]}, {"timestamp": 1578723663951, "ltp": 1.62, "tv": 1009.47, "trd": NaN, "batb": NaN, "batl": [[1, 1.67, 3]]}, {"timestamp": 1578723710400, "ltp": 1.62, "tv": 1009.47, "trd": NaN, "batb": NaN, "batl": [[0, 1.66, 9.52], [1, 1.69, 10.1], [2, 1.7, 150]]}, {"timestamp": 1578723711476, "ltp": 1.62, "tv": 1009.47, "trd": NaN, "batb": NaN, "batl": [[1, 1.7, 150], [2, 1.75, 2]]}, {"timestamp": 1578723745664, "ltp": 1.62, "tv": 1009.47, "trd": NaN, "batb": NaN, "batl": [[0, 1.66, 6.52], [1, 1.69, 3], [2, 1.7, 150]]}, {"timestamp": 1578723746652, "ltp": 1.62, "tv": 1009.47, "trd": NaN, "batb": NaN, "batl": [[1, 1.69, 13.1]]}, {"timestamp": 1578723804111, "ltp": 1.62, "tv": 1009.47, "trd": NaN, "batb": NaN, "batl": [[1, 1.68, 3], [2, 1.69, 10.1]]}, {"timestamp": 1578723839998, "ltp": 1.62, "tv": 1009.47, "trd": NaN, "batb": NaN, "batl": [[1, 1.67, 3]]}, {"timestamp": 1578723876183, "ltp": 1.62, "tv": 1009.47, "trd": NaN, "batb": NaN, "batl": [[0, 1.66, 9.52], [1, 1.69, 10.1], [2, 1.7, 150]]}, {"timestamp": 1578723877887, "ltp": 1.62, "tv": 1009.47, "trd": NaN, "batb": NaN, "batl": [[1, 1.7, 150], [2, 1.75, 2]]}, {"timestamp": 1578723911902, "ltp": 1.62, "tv": 1009.47, "trd": NaN, "batb": NaN, "batl": [[0, 1.66, 6.52], [1, 1.69, 3], [2, 1.7, 150]]}, {"timestamp": 1578723912477, "ltp": 1.62, "tv": 1009.47, "trd": NaN, "batb": NaN, "batl": [[1, 1.69, 13.1]]}, {"timestamp": 1578723947810, "ltp": 1.62, "tv": 1009.47, "trd": NaN, "batb": NaN, "batl": [[1, 1.68, 3], [2, 1.69, 10.1]]}, {"timestamp": 1578723956940, "ltp": 1.62, "tv": 1009.47, "trd": NaN, "batb": [[0, 1.6, 11], [1, 1.57, 10.43], [2, 1.56, 6]], "batl": [[0, 1.63, 7.74], [1, 1.64, 26.38], [2, 1.66, 6.52]]}, {"timestamp": 1578723984401, "ltp": 1.62, "tv": 1009.47, "trd": NaN, "batb": NaN, "batl": [[2, 1.66, 3.59]]}, {"timestamp": 1578723995000, "ltp": 1.62, "tv": 1009.47, "trd": NaN, "batb": NaN, "batl": [[0, 1.63, 10.74]]}, {"timestamp": 1578724010842, "ltp": 1.62, "tv": 1009.47, "trd": NaN, "batb": NaN, "batl": [[0, 1.63, 13.72]]}, {"timestamp": 1578724133903, "ltp": 1.62, "tv": 1009.47, "trd": NaN, "batb": NaN, "batl": [[2, 1.7, 150]]}, {"timestamp": 1578724134314, "ltp": 1.62, "tv": 1009.47, "trd": NaN, "batb": NaN, "batl": [[0, 1.62, 7.94], [1, 1.63, 13.72], [2, 1.64, 26.38]]}, {"timestamp": 1578724323964, "ltp": 1.62, "tv": 1009.47, "trd": NaN, "batb": NaN, "batl": [[1, 1.63, 10.74]]}, {"timestamp": 1578724348862, "ltp": 1.62, "tv": 1009.47, "trd": NaN, "batb": NaN, "batl": [[0, 1.62, 10.94]]}, {"timestamp": 1578724419875, "ltp": 1.62, "tv": 1009.47, "trd": NaN, "batb": [[0, 1.61, 10.84], [1, 1.6, 11], [2, 1.57, 10.43]], "batl": NaN}, {"timestamp": 1578724499498, "ltp": 1.62, "tv": 1009.47, "trd": NaN, "batb": NaN, "batl": [[0, 1.62, 3], [1, 1.63, 19.99]]}, {"timestamp": 1578724670837, "ltp": 1.61, "tv": 1031.15, "trd": [[1.61, 41.7]], "batb": [[0, 1.6, 11], [1, 1.57, 10.43], [2, 1.56, 6]], "batl": NaN}, {"timestamp": 1578724819865, "ltp": 1.62, "tv": 1037.15, "trd": [[1.62, 157.54]], "batb": [[0, 1.62, 2], [1, 1.6, 11], [2, 1.57, 10.43]], "batl": [[0, 1.63, 19.99], [1, 1.64, 26.38], [2, 1.69, 6]]}, {"timestamp": 1578724901978, "ltp": 1.62, "tv": 1037.15, "trd": NaN, "batb": NaN, "batl": [[0, 1.63, 10.74]]}, {"timestamp": 1578724945801, "ltp": 1.62, "tv": 1041.15, "trd": [[1.62, 161.54]], "batb": [[0, 1.6, 11], [1, 1.57, 10.43], [2, 1.56, 6]], "batl": [[0, 1.62, 98], [1, 1.63, 10.74], [2, 1.64, 26.38]]}, {"timestamp": 1578724959882, "ltp": 1.62, "tv": 1041.15, "trd": NaN, "batb": NaN, "batl": [[0, 1.61, 9.7], [1, 1.62, 98], [2, 1.63, 10.74]]}, {"timestamp": 1578724972934, "ltp": 1.62, "tv": 1041.15, "trd": NaN, "batb": NaN, "batl": [[0, 1.61, 12.7], [2, 1.63, 7.74]]}, {"timestamp": 1578724999861, "ltp": 1.6, "tv": 1063.15, "trd": [[1.6, 28.12]], "batb": [[0, 1.57, 10.43], [1, 1.56, 28.05], [2, 1.55, 400]], "batl": [[2, 1.64, 26.38]]}, {"timestamp": 1578725018829, "ltp": 1.6, "tv": 1063.15, "trd": NaN, "batb": [[1, 1.56, 25.21]], "batl": NaN}, {"timestamp": 1578725085915, "ltp": 1.6, "tv": 1063.15, "trd": NaN, "batb": NaN, "batl": [[0, 1.61, 62.7]]}, {"timestamp": 1578725130594, "ltp": 1.6, "tv": 1063.15, "trd": NaN, "batb": [[0, 1.58, 11.04], [1, 1.57, 10.43], [2, 1.56, 25.21]], "batl": NaN}, {"timestamp": 1578725505974, "ltp": 1.6, "tv": 1063.15, "trd": NaN, "batb": [[0, 1.59, 1], [1, 1.58, 11.04], [2, 1.57, 10.43]], "batl": [[0, 1.6, 7.84], [1, 1.61, 62.7], [2, 1.62, 98]]}, {"timestamp": 1578725507000, "ltp": 1.6, "tv": 1063.15, "trd": NaN, "batb": [[0, 1.58, 11.04], [1, 1.57, 10.43], [2, 1.56, 17.97]], "batl": NaN}, {"timestamp": 1578725535930, "ltp": 1.6, "tv": 1063.15, "trd": NaN, "batb": NaN, "batl": [[0, 1.6, 10.84], [1, 1.61, 59.7]]}, {"timestamp": 1578725536914, "ltp": 1.58, "tv": 1085.23, "trd": [[1.58, 59.98]], "batb": [[0, 1.57, 10.43], [1, 1.56, 25.21], [2, 1.55, 400]], "batl": [[0, 1.58, 2.41], [1, 1.6, 3], [2, 1.61, 59.7]]}, {"timestamp": 1578725544926, "ltp": 1.57, "tv": 1106.09, "trd": [[1.57, 91.82]], "batb": [[0, 1.56, 25.21], [1, 1.55, 400], [2, 1.54, 23.28]], "batl": [[0, 1.57, 74.69], [1, 1.58, 2.41], [2, 1.6, 3]]}, {"timestamp": 1578725546947, "ltp": 1.57, "tv": 1106.09, "trd": NaN, "batb": NaN, "batl": [[2, 1.61, 59.7]]}, {"timestamp": 1578725547831, "ltp": 1.57, "tv": 1106.09, "trd": NaN, "batb": NaN, "batl": [[2, 1.59, 3]]}, {"timestamp": 1578725563765, "ltp": 1.56, "tv": 1110.09, "trd": [[1.56, 48.35]], "batb": [[0, 1.56, 23.21]], "batl": NaN}, {"timestamp": 1578725572874, "ltp": 1.56, "tv": 1110.09, "trd": NaN, "batb": NaN, "batl": [[0, 1.57, 76.69]]}, {"timestamp": 1578725583972, "ltp": 1.56, "tv": 1110.09, "trd": NaN, "batb": NaN, "batl": [[0, 1.57, 79.69], [2, 1.61, 59.7]]}, {"timestamp": 1578725945953, "ltp": 1.57, "tv": 1155.1, "trd": [[1.57, 136.84]], "batb": NaN, "batl": [[0, 1.57, 57.19]]}, {"timestamp": 1578726211654, "ltp": 1.57, "tv": 1155.1, "trd": NaN, "batb": NaN, "batl": [[1, 1.58, 55.16]]}, {"timestamp": 1578726257598, "ltp": 1.57, "tv": 1200.12, "trd": [[1.57, 181.86]], "batb": NaN, "batl": [[0, 1.57, 34.68]]}, {"timestamp": 1578726537875, "ltp": 1.57, "tv": 1200.12, "trd": NaN, "batb": NaN, "batl": [[0, 1.57, 36.38]]}, {"timestamp": 1578726545911, "ltp": 1.57, "tv": 1203.52, "trd": [[1.57, 185.26]], "batb": NaN, "batl": [[0, 1.57, 34.68]]}, {"timestamp": 1578726565827, "ltp": 1.57, "tv": 1272.7, "trd": [[1.57, 254.44]], "batb": NaN, "batl": [[0, 1.58, 55.26], [1, 1.61, 59.7], [2, 1.62, 98]]}, {"timestamp": 1578726577919, "ltp": 1.57, "tv": 1272.7, "trd": NaN, "batb": NaN, "batl": [[1, 1.6, 3], [2, 1.61, 59.7]]}, {"timestamp": 1578726589925, "ltp": 1.57, "tv": 1272.7, "trd": NaN, "batb": NaN, "batl": [[1, 1.59, 3]]}, {"timestamp": 1578726650934, "ltp": 1.57, "tv": 1272.7, "trd": NaN, "batb": NaN, "batl": [[0, 1.58, 58.26], [1, 1.61, 59.7], [2, 1.62, 98]]}, {"timestamp": 1578726687970, "ltp": 1.57, "tv": 1272.7, "trd": NaN, "batb": NaN, "batl": [[0, 1.58, 55.26], [1, 1.6, 3], [2, 1.61, 59.7]]}, {"timestamp": 1578726698983, "ltp": 1.57, "tv": 1272.7, "trd": NaN, "batb": NaN, "batl": [[1, 1.61, 59.7], [2, 1.62, 98]]}, {"timestamp": 1578726699968, "ltp": 1.57, "tv": 1272.7, "trd": NaN, "batb": NaN, "batl": [[1, 1.59, 3], [2, 1.61, 59.7]]}, {"timestamp": 1578726700999, "ltp": 1.58, "tv": 1283.82, "trd": [[1.57, 254.63], [1.58, 70.91]], "batb": NaN, "batl": [[0, 1.58, 49.7]]}, {"timestamp": 1578726758970, "ltp": 1.58, "tv": 1283.82, "trd": NaN, "batb": NaN, "batl": [[0, 1.58, 52.7], [1, 1.61, 59.7], [2, 1.62, 98]]}, {"timestamp": 1578726819918, "ltp": 1.58, "tv": 1283.82, "trd": NaN, "batb": NaN, "batl": [[0, 1.58, 49.7], [1, 1.6, 3], [2, 1.61, 59.7]]}, {"timestamp": 1578726831861, "ltp": 1.58, "tv": 1283.82, "trd": NaN, "batb": NaN, "batl": [[1, 1.59, 3]]}, {"timestamp": 1578726883706, "ltp": 1.58, "tv": 1283.82, "trd": NaN, "batb": NaN, "batl": [[0, 1.58, 52.7], [1, 1.61, 59.7], [2, 1.62, 98]]}, {"timestamp": 1578726896921, "ltp": 1.58, "tv": 1283.82, "trd": NaN, "batb": NaN, "batl": [[0, 1.58, 49.7], [1, 1.6, 3], [2, 1.61, 59.7]]}, {"timestamp": 1578726910966, "ltp": 1.58, "tv": 1283.82, "trd": NaN, "batb": NaN, "batl": [[1, 1.6, 10.9], [2, 1.61, 50]]}, {"timestamp": 1578726921979, "ltp": 1.58, "tv": 1283.82, "trd": NaN, "batb": NaN, "batl": [[1, 1.59, 3], [2, 1.6, 7.9]]}, {"timestamp": 1578726958921, "ltp": 1.58, "tv": 1283.82, "trd": NaN, "batb": NaN, "batl": [[0, 1.58, 52.7], [1, 1.6, 7.9], [2, 1.61, 50]]}, {"timestamp": 1578727123765, "ltp": 1.58, "tv": 1283.82, "trd": NaN, "batb": NaN, "batl": [[0, 1.58, 49.7], [1, 1.59, 3], [2, 1.6, 7.9]]}, {"timestamp": 1578727161977, "ltp": 1.58, "tv": 1283.82, "trd": NaN, "batb": NaN, "batl": [[0, 1.58, 52.7], [1, 1.6, 7.9], [2, 1.61, 50]]}, {"timestamp": 1578727174611, "ltp": 1.58, "tv": 1283.82, "trd": NaN, "batb": NaN, "batl": [[0, 1.58, 49.7], [1, 1.59, 3], [2, 1.6, 7.9]]}, {"timestamp": 1578727186914, "ltp": 1.58, "tv": 1283.82, "trd": NaN, "batb": NaN, "batl": [[1, 1.6, 7.9], [2, 1.61, 50]]}, {"timestamp": 1578727187944, "ltp": 1.58, "tv": 1283.82, "trd": NaN, "batb": NaN, "batl": [[0, 1.58, 52.7]]}, {"timestamp": 1578727209944, "ltp": 1.58, "tv": 1283.82, "trd": NaN, "batb": [[0, 1.57, 11.12], [1, 1.56, 23.21], [2, 1.55, 400]], "batl": NaN}, {"timestamp": 1578727225946, "ltp": 1.58, "tv": 1283.82, "trd": NaN, "batb": NaN, "batl": [[0, 1.58, 49.7], [1, 1.59, 3], [2, 1.6, 7.9]]}, {"timestamp": 1578727236953, "ltp": 1.58, "tv": 1289.81, "trd": [[1.58, 76.9]], "batb": NaN, "batl": [[0, 1.58, 46.7]]}, {"timestamp": 1578727273994, "ltp": 1.58, "tv": 1289.81, "trd": NaN, "batb": NaN, "batl": [[1, 1.59, 10.1], [2, 1.61, 50]]}, {"timestamp": 1578727288996, "ltp": 1.58, "tv": 1289.81, "trd": NaN, "batb": NaN, "batl": [[1, 1.59, 7.1]]}, {"timestamp": 1578727289932, "ltp": 1.58, "tv": 1289.81, "trd": NaN, "batb": NaN, "batl": [[0, 1.58, 49.7]]}, {"timestamp": 1578727302954, "ltp": 1.58, "tv": 1298.24, "trd": [[1.58, 85.33]], "batb": NaN, "batl": [[0, 1.58, 45.49]]}, {"timestamp": 1578727386863, "ltp": 1.58, "tv": 1320.23, "trd": [[1.58, 107.32]], "batb": NaN, "batl": [[0, 1.58, 34.5]]}, {"timestamp": 1578727878978, "ltp": 1.58, "tv": 1338.22, "trd": [[1.58, 125.31]], "batb": NaN, "batl": [[0, 1.58, 25.5]]}, {"timestamp": 1578728294909, "ltp": 1.57, "tv": 1348.22, "trd": [[1.57, 264.62]], "batb": [[0, 1.57, 6.12]], "batl": NaN}, {"timestamp": 1578728617829, "ltp": 1.57, "tv": 1360.46, "trd": [[1.57, 276.86]], "batb": [[0, 1.56, 23.21], [1, 1.55, 400], [2, 1.54, 23.28]], "batl": [[0, 1.57, 38.88], [1, 1.58, 25.5], [2, 1.59, 7.1]]}, {"timestamp": 1578728622935, "ltp": 1.56, "tv": 1406.88, "trd": [[1.56, 94.77]], "batb": [[0, 1.55, 400], [1, 1.54, 30.05], [2, 1.53, 37.96]], "batl": [[0, 1.56, 8.79], [1, 1.57, 38.88], [2, 1.58, 25.5]]}, {"timestamp": 1578728626925, "ltp": 1.56, "tv": 1406.88, "trd": NaN, "batb": [[1, 1.54, 23.28]], "batl": NaN}, {"timestamp": 1578728629940, "ltp": 1.56, "tv": 1406.88, "trd": NaN, "batb": NaN, "batl": [[0, 1.56, 12.79]]}, {"timestamp": 1578728634762, "ltp": 1.56, "tv": 1406.88, "trd": NaN, "batb": NaN, "batl": [[0, 1.56, 15.79], [2, 1.58, 22.5]]}, {"timestamp": 1578728647998, "ltp": 1.55, "tv": 1430.88, "trd": [[1.55, 62.22]], "batb": [[0, 1.55, 388]], "batl": NaN}, {"timestamp": 1578728707950, "ltp": 1.56, "tv": 1457.8, "trd": [[1.56, 121.69]], "batb": NaN, "batl": [[0, 1.56, 2.33]]}, {"timestamp": 1578728744984, "ltp": 1.56, "tv": 1462.46, "trd": [[1.56, 126.35]], "batb": [[0, 1.56, 17.67], [1, 1.55, 388], [2, 1.54, 23.28]], "batl": [[0, 1.57, 38.88], [1, 1.58, 22.5], [2, 1.61, 50]]}, {"timestamp": 1578728864854, "ltp": 1.56, "tv": 1462.46, "trd": NaN, "batb": NaN, "batl": [[0, 1.57, 42.88]]}, {"timestamp": 1578729111782, "ltp": 1.56, "tv": 1472.46, "trd": [[1.56, 136.35]], "batb": [[0, 1.56, 12.67]], "batl": NaN}, {"timestamp": 1578729190885, "ltp": 1.57, "tv": 1482.46, "trd": [[1.57, 286.86]], "batb": NaN, "batl": [[0, 1.57, 37.88]]}, {"timestamp": 1578729293007, "ltp": 1.57, "tv": 1500.0, "trd": [[1.57, 304.4]], "batb": NaN, "batl": [[0, 1.57, 29.11]]}, {"timestamp": 1578729404953, "ltp": 1.57, "tv": 1558.22, "trd": [[1.57, 362.62]], "batb": [[0, 1.57, 1.4], [1, 1.56, 12.67], [2, 1.55, 388]], "batl": [[0, 1.58, 22.5], [1, 1.6, 3.67], [2, 1.61, 57.95]]}, {"timestamp": 1578729418638, "ltp": 1.57, "tv": 1558.22, "trd": NaN, "batb": NaN, "batl": [[0, 1.58, 42.5]]}, {"timestamp": 1578729420238, "ltp": 1.57, "tv": 1558.22, "trd": NaN, "batb": NaN, "batl": [[1, 1.6, 15.34]]}, {"timestamp": 1578729433965, "ltp": 1.57, "tv": 1558.22, "trd": NaN, "batb": NaN, "batl": [[1, 1.59, 4], [2, 1.6, 15.34]]}, {"timestamp": 1578729434947, "ltp": 1.57, "tv": 1558.22, "trd": NaN, "batb": NaN, "batl": [[2, 1.6, 11.67]]}, {"timestamp": 1578729446994, "ltp": 1.57, "tv": 1558.22, "trd": NaN, "batb": NaN, "batl": [[0, 1.58, 46.5], [1, 1.6, 11.67], [2, 1.61, 50]]}, {"timestamp": 1578729455892, "ltp": 1.57, "tv": 1560.22, "trd": [[1.57, 364.62]], "batb": [[0, 1.56, 13.07], [1, 1.55, 388], [2, 1.54, 23.28]], "batl": NaN}, {"timestamp": 1578729459780, "ltp": 1.57, "tv": 1560.22, "trd": NaN, "batb": NaN, "batl": [[0, 1.58, 42.5], [1, 1.59, 4], [2, 1.6, 11.67]]}, {"timestamp": 1578729562915, "ltp": 1.57, "tv": 1560.22, "trd": NaN, "batb": NaN, "batl": [[1, 1.6, 11.67], [2, 1.61, 50]]}, {"timestamp": 1578729564000, "ltp": 1.57, "tv": 1560.22, "trd": NaN, "batb": NaN, "batl": [[0, 1.58, 46.5]]}, {"timestamp": 1578729614915, "ltp": 1.57, "tv": 1560.22, "trd": NaN, "batb": NaN, "batl": [[0, 1.58, 42.5], [1, 1.59, 4], [2, 1.6, 11.67]]}, {"timestamp": 1578729618950, "ltp": 1.58, "tv": 1564.22, "trd": [[1.58, 129.31]], "batb": NaN, "batl": [[0, 1.58, 40.51]]}, {"timestamp": 1578729640947, "ltp": 1.58, "tv": 1564.22, "trd": NaN, "batb": NaN, "batl": [[0, 1.58, 44.51], [1, 1.6, 11.67], [2, 1.61, 50]]}, {"timestamp": 1578729666977, "ltp": 1.58, "tv": 1564.22, "trd": NaN, "batb": NaN, "batl": [[0, 1.58, 40.51], [1, 1.59, 4], [2, 1.6, 11.67]]}, {"timestamp": 1578729706000, "ltp": 1.58, "tv": 1564.22, "trd": NaN, "batb": NaN, "batl": [[0, 1.58, 44.51], [1, 1.6, 11.67], [2, 1.61, 50]]}, {"timestamp": 1578729738998, "ltp": 1.58, "tv": 1583.81, "trd": [[1.58, 148.91]], "batb": NaN, "batl": [[0, 1.58, 34.71]]}, {"timestamp": 1578729740978, "ltp": 1.58, "tv": 1583.81, "trd": NaN, "batb": NaN, "batl": [[1, 1.61, 50], [2, 1.62, 98]]}, {"timestamp": 1578729821938, "ltp": 1.58, "tv": 1593.81, "trd": [[1.58, 158.91]], "batb": NaN, "batl": [[0, 1.58, 29.71]]}, {"timestamp": 1578729900956, "ltp": 1.56, "tv": 1597.81, "trd": [[1.56, 139.55], [1.57, 365.42]], "batb": [[0, 1.56, 11.07]], "batl": NaN}, {"timestamp": 1578729952821, "ltp": 1.56, "tv": 1597.81, "trd": NaN, "batb": NaN, "batl": [[0, 1.58, 25.71], [1, 1.6, 4], [2, 1.61, 50]]}, {"timestamp": 1578730003977, "ltp": 1.56, "tv": 1597.81, "trd": NaN, "batb": NaN, "batl": [[1, 1.59, 4]]}, {"timestamp": 1578730023577, "ltp": 1.58, "tv": 1608.07, "trd": [[1.58, 169.16]], "batb": NaN, "batl": [[0, 1.58, 20.59]]}, {"timestamp": 1578730055684, "ltp": 1.58, "tv": 1608.07, "trd": NaN, "batb": NaN, "batl": [[0, 1.58, 24.59], [1, 1.61, 50], [2, 1.62, 98]]}, {"timestamp": 1578730094492, "ltp": 1.58, "tv": 1608.07, "trd": NaN, "batb": NaN, "batl": [[0, 1.58, 20.59], [1, 1.6, 4], [2, 1.61, 50]]}, {"timestamp": 1578730120954, "ltp": 1.58, "tv": 1608.07, "trd": NaN, "batb": NaN, "batl": [[1, 1.59, 4]]}, {"timestamp": 1578730176997, "ltp": 1.58, "tv": 1618.58, "trd": [[1.58, 179.68]], "batb": NaN, "batl": [[0, 1.58, 15.33]]}, {"timestamp": 1578730240959, "ltp": 1.58, "tv": 1618.58, "trd": NaN, "batb": NaN, "batl": [[0, 1.58, 19.33], [1, 1.61, 50], [2, 1.62, 98]]}, {"timestamp": 1578730253900, "ltp": 1.58, "tv": 1618.58, "trd": NaN, "batb": NaN, "batl": [[0, 1.58, 15.33], [1, 1.6, 4], [2, 1.61, 50]]}, {"timestamp": 1578730279921, "ltp": 1.58, "tv": 1618.58, "trd": NaN, "batb": NaN, "batl": [[1, 1.59, 4]]}, {"timestamp": 1578730329901, "ltp": 1.58, "tv": 1618.58, "trd": NaN, "batb": [[0, 1.57, 11.12], [1, 1.56, 11.07], [2, 1.55, 388]], "batl": NaN}, {"timestamp": 1578730332992, "ltp": 1.58, "tv": 1618.58, "trd": NaN, "batb": NaN, "batl": [[0, 1.58, 19.33], [1, 1.61, 50], [2, 1.62, 98]]}, {"timestamp": 1578730345997, "ltp": 1.58, "tv": 1618.58, "trd": NaN, "batb": NaN, "batl": [[0, 1.58, 15.33], [1, 1.6, 4], [2, 1.61, 50]]}, {"timestamp": 1578730365824, "ltp": 1.56, "tv": 1662.96, "trd": [[1.56, 161.69], [1.57, 387.66]], "batb": [[0, 1.55, 388], [1, 1.54, 23.28], [2, 1.53, 37.96]], "batl": [[0, 1.56, 6.6], [1, 1.58, 15.33], [2, 1.6, 4]]}, {"timestamp": 1578730366955, "ltp": 1.56, "tv": 1662.96, "trd": NaN, "batb": [[1, 1.54, 33.4]], "batl": NaN}, {"timestamp": 1578730371945, "ltp": 1.56, "tv": 1662.96, "trd": NaN, "batb": [[1, 1.54, 23.28]], "batl": [[1, 1.57, 4], [2, 1.58, 15.33]]}, {"timestamp": 1578730384931, "ltp": 1.56, "tv": 1662.96, "trd": NaN, "batb": NaN, "batl": [[0, 1.56, 10.6], [1, 1.58, 15.33], [2, 1.61, 50]]}, {"timestamp": 1578730394940, "ltp": 1.56, "tv": 1662.96, "trd": NaN, "batb": NaN, "batl": [[0, 1.56, 4], [1, 1.58, 21.93]]}, {"timestamp": 1578730397820, "ltp": 1.56, "tv": 1662.96, "trd": NaN, "batb": NaN, "batl": [[0, 1.57, 4]]}, {"timestamp": 1578730594956, "ltp": 1.57, "tv": 1666.96, "trd": [[1.57, 391.66]], "batb": NaN, "batl": [[0, 1.57, 2]]}, {"timestamp": 1578730811985, "ltp": 1.57, "tv": 1666.96, "trd": NaN, "batb": [[0, 1.56, 2], [1, 1.55, 388], [2, 1.54, 23.28]], "batl": NaN}, {"timestamp": 1578730969826, "ltp": 1.57, "tv": 1666.96, "trd": NaN, "batb": NaN, "batl": [[0, 1.57, 52]]}, {"timestamp": 1578731235765, "ltp": 1.57, "tv": 1666.96, "trd": NaN, "batb": [[1, 1.55, 388.96]], "batl": NaN}, {"timestamp": 1578731259998, "ltp": 1.57, "tv": 1677.08, "trd": [[1.57, 401.78]], "batb": NaN, "batl": [[0, 1.57, 46.94]]}, {"timestamp": 1578731263994, "ltp": 1.57, "tv": 1677.08, "trd": NaN, "batb": NaN, "batl": [[0, 1.57, 49.94]]}, {"timestamp": 1578731272777, "ltp": 1.57, "tv": 1687.2, "trd": [[1.57, 411.9]], "batb": NaN, "batl": [[0, 1.57, 44.88]]}, {"timestamp": 1578731297938, "ltp": 1.57, "tv": 1688.28, "trd": [[1.57, 412.98]], "batb": NaN, "batl": [[0, 1.57, 44.34]]}, {"timestamp": 1578731299960, "ltp": 1.57, "tv": 1689.18, "trd": [[1.57, 413.88]], "batb": NaN, "batl": [[0, 1.57, 43.89]]}, {"timestamp": 1578731301923, "ltp": 1.57, "tv": 1690.08, "trd": [[1.57, 414.78]], "batb": NaN, "batl": [[0, 1.57, 43.44]]}, {"timestamp": 1578731303750, "ltp": 1.57, "tv": 1690.7, "trd": [[1.57, 415.4]], "batb": NaN, "batl": [[0, 1.57, 43.13]]}, {"timestamp": 1578731306644, "ltp": 1.57, "tv": 1691.32, "trd": [[1.57, 416.02]], "batb": NaN, "batl": [[0, 1.57, 42.82]]}, {"timestamp": 1578731309951, "ltp": 1.57, "tv": 1691.74, "trd": [[1.57, 416.44]], "batb": NaN, "batl": [[0, 1.57, 42.61]]}, {"timestamp": 1578731311660, "ltp": 1.57, "tv": 1692.16, "trd": [[1.57, 416.86]], "batb": NaN, "batl": [[0, 1.57, 42.4]]}, {"timestamp": 1578731313569, "ltp": 1.57, "tv": 1692.44, "trd": [[1.57, 417.14]], "batb": NaN, "batl": [[0, 1.57, 42.26]]}, {"timestamp": 1578731316779, "ltp": 1.57, "tv": 1692.72, "trd": [[1.57, 417.42]], "batb": NaN, "batl": [[0, 1.57, 42.12]]}, {"timestamp": 1578731319979, "ltp": 1.57, "tv": 1692.92, "trd": [[1.57, 417.62]], "batb": NaN, "batl": [[0, 1.57, 42.02]]}, {"timestamp": 1578731321789, "ltp": 1.57, "tv": 1693.12, "trd": [[1.57, 417.82]], "batb": NaN, "batl": [[0, 1.57, 41.92]]}, {"timestamp": 1578731323908, "ltp": 1.57, "tv": 1693.32, "trd": [[1.57, 418.02]], "batb": NaN, "batl": [[0, 1.57, 41.82]]}, {"timestamp": 1578731325870, "ltp": 1.57, "tv": 1693.52, "trd": [[1.57, 418.22]], "batb": NaN, "batl": [[0, 1.57, 41.72]]}, {"timestamp": 1578731327987, "ltp": 1.57, "tv": 1693.72, "trd": [[1.57, 418.42]], "batb": NaN, "batl": [[0, 1.57, 41.62]]}, {"timestamp": 1578731329886, "ltp": 1.57, "tv": 1693.92, "trd": [[1.57, 418.62]], "batb": NaN, "batl": [[0, 1.57, 41.52]]}, {"timestamp": 1578731428980, "ltp": 1.57, "tv": 1695.66, "trd": [[1.57, 420.36]], "batb": NaN, "batl": [[0, 1.57, 40.65]]}, {"timestamp": 1578731527740, "ltp": 1.57, "tv": 1705.98, "trd": [[1.57, 430.68]], "batb": NaN, "batl": [[0, 1.57, 35.49]]}, {"timestamp": 1578731698992, "ltp": 1.58, "tv": 1817.98, "trd": [[1.57, 501.66], [1.58, 220.7]], "batb": [[0, 1.56, 13.18]], "batl": [[0, 1.58, 1.42], [1, 1.6, 4.43]]}, {"timestamp": 1578731700801, "ltp": 1.58, "tv": 1817.98, "trd": NaN, "batb": NaN, "batl": [[2, 1.61, 70.68]]}, {"timestamp": 1578731710820, "ltp": 1.58, "tv": 1817.98, "trd": NaN, "batb": NaN, "batl": [[1, 1.61, 70.68], [2, 1.62, 98]]}, {"timestamp": 1578731718840, "ltp": 1.58, "tv": 1817.98, "trd": NaN, "batb": NaN, "batl": [[1, 1.6, 58.73], [2, 1.61, 70.68]]}, {"timestamp": 1578731765817, "ltp": 1.58, "tv": 1817.98, "trd": NaN, "batb": NaN, "batl": [[1, 1.6, 62.73]]}, {"timestamp": 1578731980965, "ltp": 1.56, "tv": 1824.82, "trd": [[1.56, 168.53]], "batb": [[0, 1.56, 9.76]], "batl": NaN}, {"timestamp": 1578731998722, "ltp": 1.56, "tv": 1824.82, "trd": NaN, "batb": [[1, 1.55, 619.5]], "batl": NaN}, {"timestamp": 1578732026770, "ltp": 1.6, "tv": 1835.02, "trd": [[1.58, 223.54], [1.6, 35.48]], "batb": NaN, "batl": [[0, 1.6, 59.06], [1, 1.61, 70.68], [2, 1.62, 98]]}, {"timestamp": 1578732195595, "ltp": 1.6, "tv": 1835.02, "trd": NaN, "batb": NaN, "batl": [[0, 1.58, 2], [1, 1.6, 59.06], [2, 1.61, 70.68]]}, {"timestamp": 1578732207813, "ltp": 1.6, "tv": 1835.02, "trd": NaN, "batb": NaN, "batl": [[1, 1.6, 4]]}, {"timestamp": 1578732228937, "ltp": 1.6, "tv": 1835.02, "trd": NaN, "batb": NaN, "batl": [[1, 1.59, 4]]}, {"timestamp": 1578732240911, "ltp": 1.6, "tv": 1835.02, "trd": NaN, "batb": [[0, 1.57, 3.74], [1, 1.56, 9.76], [2, 1.55, 619.5]], "batl": NaN}, {"timestamp": 1578732248941, "ltp": 1.6, "tv": 1835.02, "trd": NaN, "batb": [[2, 1.55, 388.96]], "batl": NaN}, {"timestamp": 1578732267651, "ltp": 1.6, "tv": 1835.02, "trd": NaN, "batb": NaN, "batl": [[0, 1.58, 6], [1, 1.61, 70.68], [2, 1.62, 98]]}, {"timestamp": 1578732280852, "ltp": 1.6, "tv": 1835.02, "trd": NaN, "batb": NaN, "batl": [[0, 1.58, 2], [1, 1.6, 4], [2, 1.61, 70.68]]}, {"timestamp": 1578732293660, "ltp": 1.6, "tv": 1835.02, "trd": NaN, "batb": NaN, "batl": [[1, 1.59, 4]]}, {"timestamp": 1578732305892, "ltp": 1.6, "tv": 1835.02, "trd": NaN, "batb": NaN, "batl": [[0, 1.58, 6], [1, 1.61, 70.68], [2, 1.62, 98]]}, {"timestamp": 1578732323922, "ltp": 1.58, "tv": 1847.02, "trd": [[1.58, 235.54]], "batb": [[0, 1.58, 494], [1, 1.57, 3.74], [2, 1.56, 9.76]], "batl": [[0, 1.61, 70.68], [1, 1.62, 98], [2, 1.64, 26.38]]}, {"timestamp": 1578732344970, "ltp": 1.58, "tv": 1847.02, "trd": NaN, "batb": NaN, "batl": [[0, 1.61, 74.68]]}, {"timestamp": 1578732347964, "ltp": 1.58, "tv": 2697.02, "trd": [[1.58, 1085.54]], "batb": [[0, 1.58, 69]], "batl": [[0, 1.6, 14.9], [1, 1.61, 74.68], [2, 1.62, 98]]}, {"timestamp": 1578732356969, "ltp": 1.58, "tv": 2697.02, "trd": NaN, "batb": NaN, "batl": [[0, 1.6, 18.9]]}, {"timestamp": 1578732357593, "ltp": 1.58, "tv": 2697.02, "trd": NaN, "batb": NaN, "batl": [[0, 1.6, 22.9], [1, 1.61, 70.68]]}, {"timestamp": 1578732452885, "ltp": 1.58, "tv": 2697.02, "trd": NaN, "batb": [[0, 1.59, 10.97], [1, 1.58, 69], [2, 1.57, 3.74]], "batl": NaN}, {"timestamp": 1578732453911, "ltp": 1.59, "tv": 2718.96, "trd": [[1.59, 38.19]], "batb": [[0, 1.58, 69], [1, 1.57, 3.74], [2, 1.55, 388.96]], "batl": NaN}, {"timestamp": 1578732457999, "ltp": 1.59, "tv": 2718.96, "trd": NaN, "batb": [[2, 1.56, 6]], "batl": NaN}, {"timestamp": 1578732494953, "ltp": 1.58, "tv": 2740.96, "trd": [[1.58, 1107.54]], "batb": [[0, 1.58, 58]], "batl": NaN}, {"timestamp": 1578732506956, "ltp": 1.58, "tv": 2784.96, "trd": [[1.58, 1151.54]], "batb": [[0, 1.58, 36]], "batl": NaN}, {"timestamp": 1578732518999, "ltp": 1.6, "tv": 2804.96, "trd": [[1.6, 55.48]], "batb": NaN, "batl": [[0, 1.6, 12.9]]}, {"timestamp": 1578732534901, "ltp": 1.6, "tv": 2814.9, "trd": [[1.6, 65.42]], "batb": NaN, "batl": [[0, 1.6, 7.93]]}, {"timestamp": 1578732552911, "ltp": 1.6, "tv": 2814.94, "trd": [[1.6, 65.46]], "batb": NaN, "batl": [[0, 1.6, 7.91]]}, {"timestamp": 1578732557937, "ltp": 1.6, "tv": 2814.94, "trd": NaN, "batb": [[0, 1.58, 36.94]], "batl": NaN}, {"timestamp": 1578732575902, "ltp": 1.6, "tv": 2814.94, "trd": NaN, "batb": NaN, "batl": [[0, 1.6, 27.91], [1, 1.61, 73.54]]}, {"timestamp": 1578732579986, "ltp": 1.6, "tv": 2814.94, "trd": NaN, "batb": NaN, "batl": [[1, 1.61, 78.54]]}, {"timestamp": 1578732580912, "ltp": 1.6, "tv": 2814.94, "trd": NaN, "batb": NaN, "batl": [[0, 1.6, 37.91]]}, {"timestamp": 1578732587901, "ltp": 1.6, "tv": 2814.94, "trd": NaN, "batb": NaN, "batl": [[1, 1.61, 81.69]]}, {"timestamp": 1578732594954, "ltp": 1.58, "tv": 2888.82, "trd": [[1.58, 1225.42]], "batb": [[0, 1.57, 3.74], [1, 1.56, 6], [2, 1.55, 388.96]], "batl": NaN}, {"timestamp": 1578732598925, "ltp": 1.56, "tv": 2908.3, "trd": [[1.56, 180.53], [1.57, 509.14]], "batb": [[0, 1.55, 388.96], [1, 1.54, 23.28], [2, 1.53, 37.96]], "batl": [[0, 1.56, 7.28], [1, 1.6, 37.91], [2, 1.61, 81.69]]}, {"timestamp": 1578732599949, "ltp": 1.56, "tv": 2922.86, "trd": [[1.56, 195.09]], "batb": [[0, 1.57, 2], [1, 1.56, 8], [2, 1.55, 388.96]], "batl": [[0, 1.6, 37.91], [1, 1.61, 81.69], [2, 1.62, 98]]}, {"timestamp": 1578732600935, "ltp": 1.57, "tv": 2926.86, "trd": [[1.57, 513.14]], "batb": [[0, 1.56, 8], [1, 1.55, 388.96], [2, 1.54, 23.28]], "batl": NaN}, {"timestamp": 1578732602939, "ltp": 1.57, "tv": 2926.86, "trd": NaN, "batb": NaN, "batl": [[0, 1.58, 2], [1, 1.59, 6], [2, 1.6, 37.91]]}, {"timestamp": 1578732613956, "ltp": 1.57, "tv": 2926.86, "trd": NaN, "batb": NaN, "batl": [[0, 1.57, 6], [1, 1.6, 37.91], [2, 1.61, 81.69]]}, {"timestamp": 1578732621842, "ltp": 1.56, "tv": 2930.86, "trd": [[1.56, 199.09]], "batb": [[0, 1.56, 6]], "batl": NaN}, {"timestamp": 1578732627953, "ltp": 1.57, "tv": 2942.86, "trd": [[1.57, 525.14]], "batb": [[0, 1.57, 4], [1, 1.56, 6], [2, 1.55, 388.96]], "batl": [[0, 1.6, 37.91], [1, 1.61, 81.69], [2, 1.62, 98]]}, {"timestamp": 1578732629970, "ltp": 1.57, "tv": 2950.86, "trd": [[1.57, 533.14]], "batb": [[0, 1.57, 10], [1, 1.56, 11]], "batl": NaN}, {"timestamp": 1578732630874, "ltp": 1.57, "tv": 2950.86, "trd": NaN, "batb": NaN, "batl": [[0, 1.59, 4], [1, 1.6, 33.91], [2, 1.61, 81.69]]}, {"timestamp": 1578732631949, "ltp": 1.57, "tv": 2970.86, "trd": [[1.57, 553.14]], "batb": [[0, 1.56, 11], [1, 1.55, 388.96], [2, 1.54, 23.28]], "batl": NaN}, {"timestamp": 1578732684938, "ltp": 1.56, "tv": 2992.86, "trd": [[1.56, 221.09]], "batb": [[0, 1.55, 388.96], [1, 1.54, 23.28], [2, 1.53, 37.96]], "batl": NaN}, {"timestamp": 1578732723966, "ltp": 1.56, "tv": 2992.86, "trd": NaN, "batb": [[2, 1.53, 63.76]], "batl": NaN}, {"timestamp": 1578732810970, "ltp": 1.56, "tv": 2992.86, "trd": NaN, "batb": [[0, 1.56, 11.18], [1, 1.55, 388.96], [2, 1.54, 23.28]], "batl": NaN}, {"timestamp": 1578732917981, "ltp": 1.56, "tv": 2992.86, "trd": NaN, "batb": [[2, 1.54, 24.25]], "batl": NaN}, {"timestamp": 1578732946974, "ltp": 1.55, "tv": 3032.87, "trd": [[1.55, 79.86], [1.56, 243.46]], "batb": [[0, 1.55, 380.14], [1, 1.54, 24.25], [2, 1.53, 37.96]], "batl": NaN}, {"timestamp": 1578732959842, "ltp": 1.55, "tv": 3032.87, "trd": NaN, "batb": [[2, 1.53, 56.21]], "batl": NaN}, {"timestamp": 1578732960972, "ltp": 1.55, "tv": 3032.87, "trd": NaN, "batb": NaN, "batl": [[2, 1.61, 75.68]]}, {"timestamp": 1578732962990, "ltp": 1.55, "tv": 3032.87, "trd": NaN, "batb": NaN, "batl": [[0, 1.59, 15.74], [2, 1.61, 55]]}, {"timestamp": 1578732988991, "ltp": 1.57, "tv": 3047.09, "trd": [[1.57, 567.36]], "batb": [[0, 1.57, 15.78], [1, 1.55, 380.14], [2, 1.54, 24.25]], "batl": NaN}, {"timestamp": 1578732992989, "ltp": 1.57, "tv": 3047.09, "trd": NaN, "batb": [[1, 1.56, 6], [2, 1.55, 380.14]], "batl": NaN}, {"timestamp": 1578732995799, "ltp": 1.58, "tv": 3062.87, "trd": [[1.58, 1241.2]], "batb": [[0, 1.56, 6], [1, 1.55, 380.14], [2, 1.54, 24.25]], "batl": NaN}, {"timestamp": 1578732996991, "ltp": 1.58, "tv": 3062.87, "trd": NaN, "batb": NaN, "batl": [[0, 1.59, 4], [1, 1.6, 45.58]]}, {"timestamp": 1578733052878, "ltp": 1.58, "tv": 3062.87, "trd": NaN, "batb": [[0, 1.56, 7.5]], "batl": NaN}, {"timestamp": 1578733103824, "ltp": 1.58, "tv": 3062.87, "trd": NaN, "batb": [[0, 1.56, 6]], "batl": NaN}, {"timestamp": 1578733118874, "ltp": 1.56, "tv": 3066.87, "trd": [[1.56, 247.46]], "batb": [[0, 1.56, 4]], "batl": NaN}, {"timestamp": 1578733126976, "ltp": 1.56, "tv": 3066.87, "trd": NaN, "batb": NaN, "batl": [[0, 1.58, 2], [1, 1.59, 4], [2, 1.6, 45.58]]}, {"timestamp": 1578733133777, "ltp": 1.57, "tv": 3077.0, "trd": [[1.57, 577.49]], "batb": NaN, "batl": NaN}, {"timestamp": 1578733141971, "ltp": 1.57, "tv": 3077.0, "trd": NaN, "batb": [[0, 1.57, 2], [1, 1.56, 4], [2, 1.55, 380.14]], "batl": NaN}, {"timestamp": 1578733148986, "ltp": 1.57, "tv": 3077.0, "trd": NaN, "batb": NaN, "batl": [[0, 1.58, 6], [1, 1.6, 45.58], [2, 1.61, 55]]}, {"timestamp": 1578733203942, "ltp": 1.57, "tv": 3081.0, "trd": [[1.57, 581.49]], "batb": [[0, 1.56, 4], [1, 1.55, 380.14], [2, 1.54, 24.25]], "batl": NaN}, {"timestamp": 1578733204941, "ltp": 1.56, "tv": 3082.0, "trd": [[1.56, 248.46]], "batb": [[0, 1.56, 3.5]], "batl": NaN}, {"timestamp": 1578733291813, "ltp": 1.56, "tv": 3082.0, "trd": NaN, "batb": NaN, "batl": [[0, 1.58, 2], [1, 1.59, 4], [2, 1.6, 45.58]]}, {"timestamp": 1578733327983, "ltp": 1.56, "tv": 3082.0, "trd": NaN, "batb": NaN, "batl": [[2, 1.6, 124.71]]}, {"timestamp": 1578733348872, "ltp": 1.56, "tv": 3082.0, "trd": NaN, "batb": NaN, "batl": [[1, 1.59, 30.38]]}, {"timestamp": 1578733350909, "ltp": 1.56, "tv": 3082.0, "trd": NaN, "batb": NaN, "batl": [[0, 1.58, 13.81], [2, 1.6, 113.04]]}, {"timestamp": 1578733368890, "ltp": 1.57, "tv": 3093.11, "trd": [[1.57, 592.6]], "batb": NaN, "batl": [[0, 1.58, 17.81], [1, 1.59, 26.38]]}, {"timestamp": 1578733424960, "ltp": 1.57, "tv": 3093.11, "trd": NaN, "batb": NaN, "batl": [[0, 1.58, 6], [1, 1.59, 38.12]]}, {"timestamp": 1578733436969, "ltp": 1.57, "tv": 3093.11, "trd": NaN, "batb": NaN, "batl": [[1, 1.59, 47.22]]}, {"timestamp": 1578733488982, "ltp": 1.55, "tv": 3101.11, "trd": [[1.55, 80.86], [1.56, 255.46]], "batb": [[0, 1.55, 379.64], [1, 1.54, 24.25], [2, 1.53, 37.96]], "batl": NaN}, {"timestamp": 1578733520952, "ltp": 1.55, "tv": 3161.11, "trd": [[1.55, 140.86]], "batb": [[0, 1.55, 349.64], [2, 1.53, 60.26]], "batl": NaN}, {"timestamp": 1578733615958, "ltp": 1.55, "tv": 3161.11, "trd": NaN, "batb": NaN, "batl": [[0, 1.58, 23.02]]}, {"timestamp": 1578733692505, "ltp": 1.55, "tv": 3161.11, "trd": NaN, "batb": [[0, 1.56, 11.18], [1, 1.55, 349.64], [2, 1.54, 24.25]], "batl": NaN}, {"timestamp": 1578733773899, "ltp": 1.56, "tv": 3166.85, "trd": [[1.56, 261.19]], "batb": [[0, 1.56, 5.45]], "batl": NaN}, {"timestamp": 1578733779808, "ltp": 1.56, "tv": 3166.85, "trd": NaN, "batb": NaN, "batl": [[0, 1.57, 3.4], [1, 1.58, 23.02], [2, 1.59, 47.22]]}, {"timestamp": 1578733780914, "ltp": 1.56, "tv": 3166.85, "trd": NaN, "batb": NaN, "batl": [[0, 1.58, 23.02], [1, 1.59, 47.22], [2, 1.6, 113.04]]}, {"timestamp": 1578733825933, "ltp": 1.57, "tv": 3187.19, "trd": [[1.57, 612.94]], "batb": [[0, 1.57, 60.66], [1, 1.56, 5.45], [2, 1.55, 349.64]], "batl": NaN}, {"timestamp": 1578733863797, "ltp": 1.58, "tv": 3250.47, "trd": [[1.58, 1304.49]], "batb": NaN, "batl": [[0, 1.59, 47.22], [1, 1.6, 113.04], [2, 1.61, 55]]}, {"timestamp": 1578733864995, "ltp": 1.58, "tv": 3250.47, "trd": NaN, "batb": NaN, "batl": [[0, 1.58, 4], [1, 1.59, 47.22], [2, 1.6, 113.04]]}, {"timestamp": 1578733887909, "ltp": 1.58, "tv": 3250.47, "trd": NaN, "batb": NaN, "batl": [[0, 1.58, 11]]}, {"timestamp": 1578733913936, "ltp": 1.58, "tv": 3250.47, "trd": NaN, "batb": [[1, 1.56, 16.11]], "batl": NaN}, {"timestamp": 1578733934870, "ltp": 1.58, "tv": 3250.47, "trd": NaN, "batb": [[1, 1.56, 5.45]], "batl": NaN}, {"timestamp": 1578733936970, "ltp": 1.58, "tv": 3271.25, "trd": [[1.58, 1325.27]], "batb": NaN, "batl": [[0, 1.59, 47.83], [1, 1.6, 113.04], [2, 1.61, 55]]}, {"timestamp": 1578733952918, "ltp": 1.58, "tv": 3272.47, "trd": [[1.58, 1326.49]], "batb": [[0, 1.58, 9.91], [1, 1.57, 60.66], [2, 1.56, 5.45]], "batl": [[0, 1.59, 47.22]]}, {"timestamp": 1578733953811, "ltp": 1.58, "tv": 3292.29, "trd": [[1.58, 1346.31]], "batb": [[0, 1.57, 60.66], [1, 1.56, 5.45], [2, 1.55, 349.64]], "batl": [[0, 1.58, 5.14], [1, 1.59, 47.22], [2, 1.6, 113.04]]}, {"timestamp": 1578733964932, "ltp": 1.58, "tv": 3292.29, "trd": NaN, "batb": NaN, "batl": [[0, 1.58, 11.14]]}, {"timestamp": 1578733980846, "ltp": 1.58, "tv": 3302.81, "trd": [[1.58, 1356.83]], "batb": NaN, "batl": [[0, 1.58, 5.88]]}, {"timestamp": 1578734012861, "ltp": 1.58, "tv": 3309.62, "trd": [[1.58, 1363.63]], "batb": NaN, "batl": [[0, 1.58, 2.48]]}, {"timestamp": 1578734013960, "ltp": 1.58, "tv": 3317.2, "trd": [[1.58, 1371.21]], "batb": NaN, "batl": [[0, 1.59, 47.22], [1, 1.6, 113.04], [2, 1.61, 55]]}, {"timestamp": 1578734019971, "ltp": 1.59, "tv": 3325.2, "trd": [[1.59, 46.19]], "batb": NaN, "batl": [[0, 1.59, 43.22]]}, {"timestamp": 1578734067731, "ltp": 1.59, "tv": 3325.2, "trd": NaN, "batb": NaN, "batl": [[0, 1.59, 49.22]]}, {"timestamp": 1578734089945, "ltp": 1.59, "tv": 3325.2, "trd": NaN, "batb": [[0, 1.58, 11.04], [1, 1.57, 60.66]], "batl": NaN}, {"timestamp": 1578734093757, "ltp": 1.59, "tv": 3325.2, "trd": NaN, "batb": [[2, 1.56, 6]], "batl": NaN}, {"timestamp": 1578734281998, "ltp": 1.59, "tv": 3335.45, "trd": [[1.59, 56.45]], "batb": NaN, "batl": [[0, 1.59, 44.1]]}, {"timestamp": 1578734306923, "ltp": 1.59, "tv": 3355.95, "trd": [[1.59, 76.94]], "batb": NaN, "batl": [[0, 1.59, 33.85]]}, {"timestamp": 1578734375825, "ltp": 1.59, "tv": 3366.15, "trd": [[1.59, 87.14]], "batb": NaN, "batl": [[0, 1.59, 28.76]]}, {"timestamp": 1578734380911, "ltp": 1.59, "tv": 3366.15, "trd": NaN, "batb": NaN, "batl": [[0, 1.59, 48.76]]}, {"timestamp": 1578734467798, "ltp": 1.58, "tv": 3388.23, "trd": [[1.58, 1393.29]], "batb": [[0, 1.57, 60.66], [1, 1.56, 6], [2, 1.55, 349.64]], "batl": [[0, 1.58, 38.96], [1, 1.59, 48.76], [2, 1.6, 113.04]]}, {"timestamp": 1578734476914, "ltp": 1.58, "tv": 3388.23, "trd": NaN, "batb": NaN, "batl": [[0, 1.58, 63.96]]}, {"timestamp": 1578734482961, "ltp": 1.58, "tv": 3388.23, "trd": NaN, "batb": NaN, "batl": [[0, 1.58, 69.96], [1, 1.59, 42.76]]}, {"timestamp": 1578734545864, "ltp": 1.58, "tv": 3408.75, "trd": [[1.58, 1413.81]], "batb": NaN, "batl": [[0, 1.58, 59.7]]}, {"timestamp": 1578734635961, "ltp": 1.58, "tv": 3429.79, "trd": [[1.58, 1434.85]], "batb": NaN, "batl": [[0, 1.58, 49.18]]}, {"timestamp": 1578734747920, "ltp": 1.57, "tv": 3493.39, "trd": [[1.57, 676.54]], "batb": [[0, 1.57, 28.86]], "batl": NaN}, {"timestamp": 1578734761002, "ltp": 1.58, "tv": 3531.39, "trd": [[1.58, 1472.85]], "batb": NaN, "batl": [[0, 1.58, 30.18]]}, {"timestamp": 1578734795895, "ltp": 1.58, "tv": 3541.65, "trd": [[1.58, 1483.11]], "batb": NaN, "batl": [[0, 1.58, 25.05]]}, {"timestamp": 1578734819996, "ltp": 1.58, "tv": 3561.65, "trd": [[1.58, 1503.11]], "batb": [[0, 1.57, 29.81]], "batl": [[0, 1.58, 15.05]]}, {"timestamp": 1578734830947, "ltp": 1.58, "tv": 3572.17, "trd": [[1.58, 1513.63]], "batb": NaN, "batl": [[0, 1.58, 9.79]]}, {"timestamp": 1578734845823, "ltp": 1.59, "tv": 3593.07, "trd": [[1.58, 1533.21], [1.59, 88.46]], "batb": NaN, "batl": [[0, 1.59, 42.1], [1, 1.6, 113.04], [2, 1.61, 55]]}, {"timestamp": 1578734846915, "ltp": 1.59, "tv": 3593.07, "trd": NaN, "batb": [[0, 1.58, 11.04], [1, 1.57, 29.81], [2, 1.56, 6]], "batl": NaN}, {"timestamp": 1578734847856, "ltp": 1.59, "tv": 3593.07, "trd": NaN, "batb": NaN, "batl": [[0, 1.59, 67.76], [1, 1.6, 120.32]]}, {"timestamp": 1578734848950, "ltp": 1.58, "tv": 3605.07, "trd": [[1.58, 1545.21]], "batb": [[0, 1.58, 5.04]], "batl": NaN}, {"timestamp": 1578734857947, "ltp": 1.57, "tv": 3617.17, "trd": [[1.57, 678.56], [1.58, 1555.29]], "batb": [[0, 1.57, 28.8], [1, 1.56, 6], [2, 1.55, 349.64]], "batl": [[0, 1.58, 5.04], [1, 1.59, 67.76], [2, 1.6, 120.32]]}, {"timestamp": 1578734858939, "ltp": 1.57, "tv": 3680.76, "trd": [[1.57, 742.16]], "batb": [[0, 1.56, 6], [1, 1.55, 349.64], [2, 1.54, 24.25]], "batl": NaN}, {"timestamp": 1578734859977, "ltp": 1.57, "tv": 3685.93, "trd": [[1.57, 747.33]], "batb": NaN, "batl": [[0, 1.59, 67.76], [1, 1.6, 120.32], [2, 1.61, 55]]}, {"timestamp": 1578734861854, "ltp": 1.59, "tv": 3695.94, "trd": [[1.59, 98.46]], "batb": NaN, "batl": [[0, 1.59, 62.76]]}, {"timestamp": 1578734862953, "ltp": 1.59, "tv": 3716.26, "trd": [[1.58, 1565.61], [1.59, 108.46]], "batb": NaN, "batl": [[0, 1.59, 57.76]]}, {"timestamp": 1578734882998, "ltp": 1.57, "tv": 3777.58, "trd": [[1.57, 808.65]], "batb": NaN, "batl": NaN}, {"timestamp": 1578734884721, "ltp": 1.57, "tv": 3777.58, "trd": NaN, "batb": NaN, "batl": [[0, 1.58, 20.14], [1, 1.59, 57.76], [2, 1.6, 120.32]]}, {"timestamp": 1578734885821, "ltp": 1.57, "tv": 3777.58, "trd": NaN, "batb": NaN, "batl": [[0, 1.58, 40.36]]}, {"timestamp": 1578734887919, "ltp": 1.57, "tv": 3777.58, "trd": NaN, "batb": NaN, "batl": [[1, 1.59, 61.76]]}, {"timestamp": 1578734915262, "ltp": 1.57, "tv": 3777.58, "trd": NaN, "batb": NaN, "batl": [[0, 1.59, 36.1], [1, 1.6, 120.32], [2, 1.61, 55]]}, {"timestamp": 1578734916877, "ltp": 1.57, "tv": 3777.58, "trd": NaN, "batb": NaN, "batl": [[1, 1.6, 113.04]]}, {"timestamp": 1578734981909, "ltp": 1.57, "tv": 3777.58, "trd": NaN, "batb": [[0, 1.56, 21.24]], "batl": [[0, 1.59, 16.1]]}, {"timestamp": 1578735026454, "ltp": 1.59, "tv": 3797.96, "trd": [[1.59, 128.84]], "batb": NaN, "batl": [[0, 1.59, 5.91]]}, {"timestamp": 1578735029779, "ltp": 1.59, "tv": 3797.96, "trd": NaN, "batb": [[0, 1.57, 14.55], [1, 1.56, 21.24], [2, 1.55, 349.64]], "batl": NaN}, {"timestamp": 1578735065926, "ltp": 1.59, "tv": 3797.96, "trd": NaN, "batb": [[0, 1.56, 34.2], [1, 1.55, 349.64], [2, 1.54, 24.25]], "batl": NaN}, {"timestamp": 1578735121962, "ltp": 1.59, "tv": 3797.96, "trd": NaN, "batb": [[0, 1.56, 84.2]], "batl": NaN}, {"timestamp": 1578735136887, "ltp": 1.59, "tv": 3797.96, "trd": NaN, "batb": [[0, 1.57, 5.11], [1, 1.56, 84.2], [2, 1.55, 349.64]], "batl": NaN}, {"timestamp": 1578735329988, "ltp": 1.59, "tv": 3809.77, "trd": [[1.59, 140.66]], "batb": [[0, 1.59, 14.09], [1, 1.57, 5.11], [2, 1.56, 68.96]], "batl": [[0, 1.6, 113.04], [1, 1.61, 61], [2, 1.62, 98]]}, {"timestamp": 1578735338921, "ltp": 1.6, "tv": 3819.89, "trd": [[1.6, 75.58]], "batb": NaN, "batl": [[0, 1.6, 107.98]]}, {"timestamp": 1578735353958, "ltp": 1.6, "tv": 3839.47, "trd": [[1.59, 150.48], [1.6, 85.34]], "batb": [[0, 1.59, 9.18]], "batl": [[0, 1.6, 103.1]]}, {"timestamp": 1578735368980, "ltp": 1.59, "tv": 3844.13, "trd": [[1.59, 155.14]], "batb": [[0, 1.59, 6.85]], "batl": NaN}, {"timestamp": 1578735369865, "ltp": 1.56, "tv": 3906.3, "trd": [[1.56, 299.45], [1.57, 818.87], [1.59, 168.84]], "batb": [[0, 1.56, 49.84], [1, 1.55, 349.64], [2, 1.54, 24.25]], "batl": [[0, 1.59, 2.33], [1, 1.6, 103.1], [2, 1.61, 87.64]]}, {"timestamp": 1578735370997, "ltp": 1.56, "tv": 3911.1, "trd": [[1.56, 304.25]], "batb": [[0, 1.57, 15.16], [1, 1.56, 47.44], [2, 1.55, 349.64]], "batl": [[0, 1.58, 6], [2, 1.61, 61]]}, {"timestamp": 1578735371789, "ltp": 1.56, "tv": 3911.1, "trd": NaN, "batb": NaN, "batl": [[1, 1.59, 13.1], [2, 1.6, 103.1]]}, {"timestamp": 1578735391896, "ltp": 1.56, "tv": 3987.26, "trd": [[1.56, 350.09], [1.57, 849.19]], "batb": [[0, 1.56, 24.52], [1, 1.55, 349.64], [2, 1.54, 24.25]], "batl": [[0, 1.57, 10.74], [1, 1.58, 6], [2, 1.59, 15.87]]}, {"timestamp": 1578735392990, "ltp": 1.56, "tv": 4009.28, "trd": [[1.56, 372.11]], "batb": [[0, 1.56, 13.51]], "batl": [[0, 1.57, 6], [1, 1.59, 15.87], [2, 1.6, 103.1]]}, {"timestamp": 1578735393930, "ltp": 1.56, "tv": 4009.28, "trd": NaN, "batb": NaN, "batl": [[1, 1.59, 13.1]]}, {"timestamp": 1578735394722, "ltp": 1.57, "tv": 4011.34, "trd": [[1.57, 851.25]], "batb": NaN, "batl": [[0, 1.57, 4.97]]}, {"timestamp": 1578735395914, "ltp": 1.57, "tv": 4021.28, "trd": [[1.57, 861.19]], "batb": [[0, 1.57, 30.37], [1, 1.56, 13.51], [2, 1.55, 349.64]], "batl": [[0, 1.59, 13.1], [1, 1.6, 103.1], [2, 1.61, 55]]}, {"timestamp": 1578735399914, "ltp": 1.57, "tv": 4021.28, "trd": NaN, "batb": [[0, 1.58, 2.64], [1, 1.57, 30.37], [2, 1.56, 13.51]], "batl": [[0, 1.59, 28.09]]}, {"timestamp": 1578735413839, "ltp": 1.57, "tv": 4021.28, "trd": NaN, "batb": [[0, 1.57, 30.37], [1, 1.56, 13.51], [2, 1.55, 349.64]], "batl": NaN}, {"timestamp": 1578735442898, "ltp": 1.59, "tv": 4026.56, "trd": [[1.59, 174.11]], "batb": NaN, "batl": [[0, 1.59, 25.45]]}, {"timestamp": 1578735444933, "ltp": 1.59, "tv": 4026.56, "trd": NaN, "batb": NaN, "batl": [[0, 1.59, 15.97]]}, {"timestamp": 1578735448728, "ltp": 1.59, "tv": 4036.81, "trd": [[1.59, 184.37]], "batb": NaN, "batl": [[0, 1.59, 10.84]]}, {"timestamp": 1578735475959, "ltp": 1.59, "tv": 4036.81, "trd": NaN, "batb": [[1, 1.56, 25.85]], "batl": NaN}, {"timestamp": 1578735490973, "ltp": 1.59, "tv": 4040.81, "trd": [[1.59, 188.37]], "batb": NaN, "batl": [[0, 1.59, 8.84]]}, {"timestamp": 1578735518946, "ltp": 1.6, "tv": 4073.8, "trd": [[1.59, 207.06], [1.6, 99.64]], "batb": NaN, "batl": [[0, 1.6, 95.95], [1, 1.61, 55], [2, 1.62, 98]]}, {"timestamp": 1578735530971, "ltp": 1.6, "tv": 4073.8, "trd": NaN, "batb": NaN, "batl": [[1, 1.61, 61]]}, {"timestamp": 1578735535001, "ltp": 1.6, "tv": 4073.8, "trd": NaN, "batb": NaN, "batl": [[0, 1.6, 105.95]]}, {"timestamp": 1578735536974, "ltp": 1.6, "tv": 4073.8, "trd": NaN, "batb": NaN, "batl": [[1, 1.61, 58.86]]}, {"timestamp": 1578735537969, "ltp": 1.6, "tv": 4073.8, "trd": NaN, "batb": [[0, 1.58, 5], [1, 1.57, 30.37], [2, 1.56, 25.85]], "batl": NaN}, {"timestamp": 1578735539991, "ltp": 1.6, "tv": 4073.8, "trd": NaN, "batb": [[1, 1.57, 40.37], [2, 1.56, 35.85]], "batl": NaN}, {"timestamp": 1578735568929, "ltp": 1.6, "tv": 4073.8, "trd": NaN, "batb": NaN, "batl": [[0, 1.6, 26.82]]}, {"timestamp": 1578735621968, "ltp": 1.6, "tv": 4073.8, "trd": NaN, "batb": [[0, 1.59, 5.1], [1, 1.58, 5], [2, 1.57, 40.37]], "batl": NaN}, {"timestamp": 1578735863990, "ltp": 1.6, "tv": 4083.98, "trd": [[1.6, 109.82]], "batb": NaN, "batl": [[0, 1.6, 21.73]]}, {"timestamp": 1578735889898, "ltp": 1.6, "tv": 4094.16, "trd": [[1.6, 120]], "batb": NaN, "batl": [[0, 1.6, 16.64]]}, {"timestamp": 1578735895969, "ltp": 1.6, "tv": 4094.16, "trd": NaN, "batb": NaN, "batl": [[1, 1.61, 71.73]]}, {"timestamp": 1578735923976, "ltp": 1.57, "tv": 4171.87, "trd": [[1.57, 918.69], [1.58, 1575.61], [1.59, 217.26]], "batb": [[0, 1.57, 11.62], [1, 1.56, 35.85], [2, 1.55, 349.64]], "batl": [[0, 1.58, 26.55], [1, 1.59, 9.74], [2, 1.6, 16.64]]}, {"timestamp": 1578735924967, "ltp": 1.57, "tv": 4171.87, "trd": NaN, "batb": [[0, 1.57, 26.8]], "batl": [[0, 1.59, 5.1], [1, 1.6, 16.64], [2, 1.61, 81.84]]}, {"timestamp": 1578735925965, "ltp": 1.57, "tv": 4182.39, "trd": [[1.57, 929.21]], "batb": [[0, 1.57, 21.54]], "batl": [[0, 1.6, 16.64], [1, 1.61, 71.73], [2, 1.62, 98]]}, {"timestamp": 1578735933865, "ltp": 1.56, "tv": 4258.75, "trd": [[1.56, 405.39], [1.57, 972.29]], "batb": [[0, 1.56, 9.21], [1, 1.55, 349.64], [2, 1.54, 24.25]], "batl": [[0, 1.57, 20], [1, 1.6, 16.64], [2, 1.61, 86.43]]}, {"timestamp": 1578735934976, "ltp": 1.56, "tv": 4277.17, "trd": [[1.56, 423.81]], "batb": [[0, 1.55, 349.64], [1, 1.54, 24.25], [2, 1.53, 371.72]], "batl": [[0, 1.56, 17.25], [1, 1.59, 8.55], [2, 1.6, 16.64]]}, {"timestamp": 1578735935977, "ltp": 1.56, "tv": 4291.63, "trd": [[1.56, 438.27]], "batb": [[2, 1.53, 29.95]], "batl": [[0, 1.56, 10.02]]}, {"timestamp": 1578735945981, "ltp": 1.56, "tv": 4298.63, "trd": [[1.56, 445.27]], "batb": NaN, "batl": [[0, 1.56, 6.52], [2, 1.6, 28.67]]}, {"timestamp": 1578735946901, "ltp": 1.56, "tv": 4298.63, "trd": NaN, "batb": NaN, "batl": [[1, 1.59, 3.07]]}, {"timestamp": 1578735948001, "ltp": 1.56, "tv": 4298.63, "trd": NaN, "batb": NaN, "batl": [[2, 1.6, 16.64]]}, {"timestamp": 1578735977995, "ltp": 1.56, "tv": 4302.63, "trd": [[1.56, 449.27]], "batb": NaN, "batl": [[0, 1.56, 4.52]]}, {"timestamp": 1578735978821, "ltp": 1.56, "tv": 4302.63, "trd": NaN, "batb": NaN, "batl": [[1, 1.58, 2], [2, 1.59, 3.07]]}, {"timestamp": 1578735983994, "ltp": 1.56, "tv": 4302.63, "trd": NaN, "batb": NaN, "batl": [[1, 1.58, 52]]}, {"timestamp": 1578735988801, "ltp": 1.56, "tv": 4302.63, "trd": NaN, "batb": NaN, "batl": [[1, 1.57, 2], [2, 1.58, 50]]}, {"timestamp": 1578736069951, "ltp": 1.55, "tv": 4545.59, "trd": [[1.55, 383.82]], "batb": [[0, 1.55, 228.16]], "batl": [[0, 1.56, 11.64], [1, 1.57, 27.83], [2, 1.58, 94.55]]}, {"timestamp": 1578736070992, "ltp": 1.55, "tv": 4545.59, "trd": NaN, "batb": NaN, "batl": [[0, 1.56, 4.52], [1, 1.57, 2], [2, 1.58, 50]]}, {"timestamp": 1578736087997, "ltp": 1.55, "tv": 4575.65, "trd": [[1.55, 413.88]], "batb": [[0, 1.55, 213.13]], "batl": NaN}, {"timestamp": 1578736088520, "ltp": 1.55, "tv": 4802.04, "trd": [[1.55, 640.26]], "batb": [[0, 1.55, 99.94]], "batl": NaN}, {"timestamp": 1578736133990, "ltp": 1.56, "tv": 4806.56, "trd": [[1.56, 453.79]], "batb": NaN, "batl": [[0, 1.57, 2], [1, 1.58, 50], [2, 1.6, 16.64]]}, {"timestamp": 1578736134981, "ltp": 1.56, "tv": 4806.56, "trd": NaN, "batb": [[0, 1.56, 21.58], [1, 1.55, 99.94], [2, 1.54, 24.25]], "batl": NaN}, {"timestamp": 1578736154963, "ltp": 1.57, "tv": 4810.56, "trd": [[1.57, 976.29]], "batb": NaN, "batl": [[0, 1.58, 66.08], [1, 1.59, 20.28]]}, {"timestamp": 1578736155776, "ltp": 1.57, "tv": 4810.56, "trd": NaN, "batb": NaN, "batl": [[0, 1.58, 93.83], [1, 1.59, 25]]}, {"timestamp": 1578736164982, "ltp": 1.58, "tv": 4816.56, "trd": [[1.58, 1581.61]], "batb": NaN, "batl": [[0, 1.58, 90.83]]}, {"timestamp": 1578736173901, "ltp": 1.58, "tv": 4816.56, "trd": NaN, "batb": NaN, "batl": [[2, 1.6, 95.77]]}, {"timestamp": 1578736175001, "ltp": 1.58, "tv": 4816.56, "trd": NaN, "batb": NaN, "batl": [[0, 1.57, 15.15], [1, 1.58, 90.83], [2, 1.59, 25]]}, {"timestamp": 1578736197923, "ltp": 1.57, "tv": 4846.56, "trd": [[1.57, 1006.29]], "batb": NaN, "batl": [[0, 1.58, 90.98], [1, 1.59, 25], [2, 1.6, 95.77]]}, {"timestamp": 1578736205967, "ltp": 1.57, "tv": 4846.56, "trd": NaN, "batb": NaN, "batl": [[1, 1.59, 29.72]]}, {"timestamp": 1578736215878, "ltp": 1.56, "tv": 4854.56, "trd": [[1.56, 461.79]], "batb": [[0, 1.56, 17.58]], "batl": NaN}, {"timestamp": 1578736273686, "ltp": 1.58, "tv": 4864.82, "trd": [[1.57, 1006.59], [1.58, 1591.57]], "batb": NaN, "batl": [[0, 1.58, 85.85]]}, {"timestamp": 1578736281915, "ltp": 1.58, "tv": 4864.82, "trd": NaN, "batb": [[0, 1.56, 22.05]], "batl": NaN}, {"timestamp": 1578736301893, "ltp": 1.58, "tv": 4874.82, "trd": [[1.58, 1601.57]], "batb": NaN, "batl": [[0, 1.58, 80.85]]}, {"timestamp": 1578736309842, "ltp": 1.58, "tv": 4874.82, "trd": NaN, "batb": NaN, "batl": [[0, 1.58, 90.85]]}, {"timestamp": 1578736311938, "ltp": 1.58, "tv": 4874.82, "trd": NaN, "batb": NaN, "batl": [[2, 1.6, 79.13]]}, {"timestamp": 1578736312925, "ltp": 1.58, "tv": 4874.82, "trd": NaN, "batb": [[0, 1.56, 32.05], [1, 1.55, 109.94], [2, 1.54, 34.25]], "batl": NaN}, {"timestamp": 1578736325968, "ltp": 1.58, "tv": 4920.82, "trd": [[1.58, 1647.57]], "batb": NaN, "batl": [[0, 1.58, 67.85]]}, {"timestamp": 1578736440980, "ltp": 1.56, "tv": 4984.92, "trd": [[1.56, 525.9]], "batb": [[0, 1.55, 109.94], [1, 1.54, 34.25], [2, 1.53, 371.72]], "batl": [[0, 1.56, 9.43], [1, 1.58, 67.85], [2, 1.59, 29.72]]}, {"timestamp": 1578736441922, "ltp": 1.55, "tv": 4990.68, "trd": [[1.55, 646.02]], "batb": [[0, 1.55, 107.06]], "batl": NaN}, {"timestamp": 1578736442803, "ltp": 1.55, "tv": 5009.7, "trd": [[1.55, 665.04]], "batb": [[0, 1.55, 97.55]], "batl": [[0, 1.58, 67.85], [1, 1.59, 29.72], [2, 1.6, 79.13]]}, {"timestamp": 1578736449904, "ltp": 1.55, "tv": 5204.79, "trd": [[1.55, 860.14]], "batb": [[0, 1.54, 49.65], [1, 1.53, 371.72], [2, 1.52, 46.19]], "batl": [[0, 1.55, 2.78], [1, 1.58, 67.85], [2, 1.59, 29.72]]}, {"timestamp": 1578736450999, "ltp": 1.54, "tv": 5210.39, "trd": [[1.54, 30.33]], "batb": [[0, 1.54, 46.85]], "batl": [[0, 1.58, 67.85], [1, 1.59, 29.72], [2, 1.6, 79.13]]}, {"timestamp": 1578736476937, "ltp": 1.58, "tv": 5220.45, "trd": [[1.58, 1657.63]], "batb": NaN, "batl": [[0, 1.58, 62.82]]}, {"timestamp": 1578736497770, "ltp": 1.58, "tv": 5220.45, "trd": NaN, "batb": [[0, 1.55, 210], [1, 1.54, 46.85], [2, 1.53, 371.72]], "batl": NaN}, {"timestamp": 1578736501914, "ltp": 1.58, "tv": 5230.45, "trd": [[1.58, 1667.63]], "batb": NaN, "batl": [[0, 1.58, 57.82]]}, {"timestamp": 1578736590922, "ltp": 1.58, "tv": 5230.45, "trd": NaN, "batb": [[0, 1.56, 85.12], [1, 1.55, 210], [2, 1.54, 46.85]], "batl": [[0, 1.57, 85.12], [1, 1.58, 57.82], [2, 1.59, 29.72]]}, {"timestamp": 1578736778987, "ltp": 1.58, "tv": 5230.45, "trd": NaN, "batb": [[0, 1.56, 90.12]], "batl": NaN}, {"timestamp": 1578736795963, "ltp": 1.57, "tv": 5234.45, "trd": [[1.57, 1010.59]], "batb": NaN, "batl": [[0, 1.57, 83.12]]}, {"timestamp": 1578736811880, "ltp": 1.57, "tv": 5239.29, "trd": [[1.57, 1015.43]], "batb": NaN, "batl": [[0, 1.57, 80.7]]}, {"timestamp": 1578736835896, "ltp": 1.56, "tv": 5257.29, "trd": [[1.56, 543.89]], "batb": [[0, 1.56, 81.12]], "batl": NaN}, {"timestamp": 1578736840994, "ltp": 1.57, "tv": 5261.29, "trd": [[1.57, 1019.43]], "batb": NaN, "batl": [[0, 1.57, 78.7]]}, {"timestamp": 1578736882982, "ltp": 1.57, "tv": 5261.29, "trd": NaN, "batb": [[1, 1.55, 230]], "batl": NaN}, {"timestamp": 1578736937938, "ltp": 1.56, "tv": 5423.53, "trd": [[1.56, 706.14]], "batb": [[0, 1.55, 230], [1, 1.54, 46.85], [2, 1.53, 49.95]], "batl": [[0, 1.56, 18.88], [1, 1.57, 78.7], [2, 1.58, 57.82]]}, {"timestamp": 1578736939834, "ltp": 1.56, "tv": 5423.53, "trd": NaN, "batb": NaN, "batl": [[0, 1.56, 31.22], [2, 1.58, 45.64]]}, {"timestamp": 1578736980649, "ltp": 1.56, "tv": 5423.53, "trd": NaN, "batb": [[0, 1.55, 238], [1, 1.54, 54.85], [2, 1.53, 57.95]], "batl": [[1, 1.57, 84.7]]}, {"timestamp": 1578737001001, "ltp": 1.56, "tv": 5423.53, "trd": NaN, "batb": NaN, "batl": [[2, 1.58, 53.64]]}, {"timestamp": 1578737047909, "ltp": 1.56, "tv": 5485.97, "trd": [[1.56, 768.58]], "batb": [[0, 1.56, 67.77], [1, 1.55, 238], [2, 1.54, 54.85]], "batl": [[0, 1.57, 84.7], [1, 1.58, 53.64], [2, 1.59, 12.76]]}, {"timestamp": 1578737062921, "ltp": 1.56, "tv": 5485.97, "trd": NaN, "batb": [[0, 1.56, 9]], "batl": NaN}, {"timestamp": 1578737078929, "ltp": 1.57, "tv": 5599.97, "trd": [[1.57, 1133.43]], "batb": NaN, "batl": [[0, 1.57, 27.71]]}, {"timestamp": 1578737079932, "ltp": 1.56, "tv": 5626.53, "trd": [[1.56, 795.14]], "batb": NaN, "batl": [[0, 1.57, 21.71]]}, {"timestamp": 1578737085812, "ltp": 1.56, "tv": 5626.53, "trd": NaN, "batb": NaN, "batl": [[0, 1.57, 51.71]]}, {"timestamp": 1578737099976, "ltp": 1.56, "tv": 5626.53, "trd": NaN, "batb": NaN, "batl": [[0, 1.57, 136.83]]}, {"timestamp": 1578737119792, "ltp": 1.57, "tv": 5638.53, "trd": [[1.57, 1145.43]], "batb": NaN, "batl": [[0, 1.57, 130.83]]}, {"timestamp": 1578737155982, "ltp": 1.56, "tv": 5674.53, "trd": [[1.56, 831.14]], "batb": [[0, 1.55, 238], [1, 1.54, 54.85], [2, 1.53, 58.95]], "batl": [[0, 1.56, 2], [1, 1.57, 134.83], [2, 1.58, 57.64]]}, {"timestamp": 1578737183907, "ltp": 1.56, "tv": 5678.53, "trd": [[1.56, 835.14]], "batb": [[0, 1.56, 34.83], [1, 1.55, 238], [2, 1.54, 54.85]], "batl": [[0, 1.57, 134.83], [1, 1.58, 57.64], [2, 1.59, 16.72]]}, {"timestamp": 1578737195941, "ltp": 1.56, "tv": 5678.53, "trd": NaN, "batb": [[0, 1.56, 44.83]], "batl": NaN}, {"timestamp": 1578737196943, "ltp": 1.56, "tv": 5678.53, "trd": NaN, "batb": [[0, 1.56, 54.83]], "batl": NaN}, {"timestamp": 1578737257864, "ltp": 1.56, "tv": 5806.2, "trd": [[1.56, 962.8]], "batb": [[0, 1.55, 238], [1, 1.54, 54.85], [2, 1.53, 49.95]], "batl": [[0, 1.56, 27.83], [1, 1.57, 134.83], [2, 1.58, 57.64]]}, {"timestamp": 1578737259857, "ltp": 1.56, "tv": 5806.2, "trd": NaN, "batb": [[1, 1.54, 68.9], [2, 1.53, 58.95]], "batl": [[2, 1.58, 62.64]]}, {"timestamp": 1578737261801, "ltp": 1.56, "tv": 5806.2, "trd": NaN, "batb": [[1, 1.54, 54.85]], "batl": NaN}, {"timestamp": 1578737262904, "ltp": 1.56, "tv": 5806.2, "trd": NaN, "batb": NaN, "batl": [[0, 1.57, 162.66], [1, 1.58, 62.64], [2, 1.59, 16.72]]}, {"timestamp": 1578737265904, "ltp": 1.56, "tv": 5806.2, "trd": NaN, "batb": NaN, "batl": [[2, 1.59, 21.72]]}, {"timestamp": 1578737401899, "ltp": 1.55, "tv": 5816.2, "trd": [[1.55, 870.14]], "batb": [[0, 1.56, 11.18], [1, 1.55, 233], [2, 1.54, 54.85]], "batl": NaN}, {"timestamp": 1578737402905, "ltp": 1.56, "tv": 5820.2, "trd": [[1.56, 966.8]], "batb": [[0, 1.56, 9.18]], "batl": NaN}, {"timestamp": 1578737404800, "ltp": 1.57, "tv": 5824.16, "trd": [[1.57, 1149.39]], "batb": NaN, "batl": [[0, 1.57, 160.67]]}, {"timestamp": 1578737497941, "ltp": 1.55, "tv": 5864.15, "trd": [[1.55, 891.76], [1.56, 985.18]], "batb": [[0, 1.55, 222.19], [1, 1.54, 54.85], [2, 1.53, 58.95]], "batl": NaN}, {"timestamp": 1578737498737, "ltp": 1.55, "tv": 5864.15, "trd": NaN, "batb": [[0, 1.55, 242.19]], "batl": [[0, 1.56, 5], [1, 1.57, 160.67], [2, 1.58, 62.64]]}, {"timestamp": 1578737499946, "ltp": 1.55, "tv": 5864.15, "trd": NaN, "batb": NaN, "batl": [[0, 1.56, 22.07], [1, 1.57, 170.67]]}, {"timestamp": 1578737523969, "ltp": 1.55, "tv": 5864.15, "trd": NaN, "batb": NaN, "batl": [[0, 1.56, 5]]}, {"timestamp": 1578737529868, "ltp": 1.55, "tv": 6067.13, "trd": [[1.55, 1094.74]], "batb": [[0, 1.55, 140.7]], "batl": [[0, 1.56, 20.26]]}, {"timestamp": 1578737534981, "ltp": 1.55, "tv": 6269.87, "trd": [[1.55, 1297.48]], "batb": [[0, 1.55, 39.33], [1, 1.54, 39.45]], "batl": [[0, 1.56, 36.07]]}, {"timestamp": 1578737560950, "ltp": 1.55, "tv": 6269.87, "trd": NaN, "batb": [[0, 1.55, 31.33]], "batl": [[0, 1.56, 246.07]]}, {"timestamp": 1578737561909, "ltp": 1.55, "tv": 6296.26, "trd": [[1.55, 1323.86]], "batb": [[0, 1.55, 18.14]], "batl": NaN}, {"timestamp": 1578737583936, "ltp": 1.56, "tv": 6326.72, "trd": [[1.56, 1015.64]], "batb": [[0, 1.55, 5028.14]], "batl": [[0, 1.56, 225.81]]}, {"timestamp": 1578737590664, "ltp": 1.56, "tv": 6326.72, "trd": NaN, "batb": [[2, 1.53, 96.95]], "batl": NaN}, {"timestamp": 1578737609979, "ltp": 1.57, "tv": 6805.06, "trd": [[1.56, 1467.26], [1.57, 1176.12]], "batb": [[0, 1.56, 4791.19], [1, 1.55, 5035.14], [2, 1.54, 48.45]], "batl": [[0, 1.57, 143.31], [1, 1.58, 62.64], [2, 1.59, 22.81]]}, {"timestamp": 1578737617897, "ltp": 1.57, "tv": 6805.06, "trd": NaN, "batb": [[2, 1.54, 31.45]], "batl": [[0, 1.57, 133.31], [1, 1.58, 52.64]]}, {"timestamp": 1578737619699, "ltp": 1.57, "tv": 6905.06, "trd": [[1.57, 1276.11]], "batb": [[0, 1.56, 4811.32]], "batl": [[0, 1.57, 83.31]]}, {"timestamp": 1578737621968, "ltp": 1.57, "tv": 6905.06, "trd": NaN, "batb": [[0, 1.56, 4831.32]], "batl": NaN}, {"timestamp": 1578737623979, "ltp": 1.57, "tv": 6905.06, "trd": NaN, "batb": [[1, 1.55, 5055.95]], "batl": NaN}, {"timestamp": 1578737630929, "ltp": 1.57, "tv": 7071.68, "trd": [[1.57, 1442.74]], "batb": [[0, 1.57, 2440.69], [1, 1.56, 4838.32], [2, 1.55, 5038.95]], "batl": [[0, 1.58, 59.64], [1, 1.59, 22.81], [2, 1.6, 102.13]]}, {"timestamp": 1578737631928, "ltp": 1.57, "tv": 7071.68, "trd": NaN, "batb": NaN, "batl": [[0, 1.58, 27.99], [1, 1.59, 54.45]]}, {"timestamp": 1578737637941, "ltp": 1.57, "tv": 7371.68, "trd": [[1.57, 1742.74]], "batb": [[0, 1.57, 2290.69]], "batl": NaN}, {"timestamp": 1578737640002, "ltp": 1.58, "tv": 7463.47, "trd": [[1.58, 1759.42]], "batb": [[0, 1.58, 2436.2], [1, 1.57, 2290.69], [2, 1.56, 4838.32]], "batl": [[0, 1.59, 54.45], [1, 1.6, 102.13], [2, 1.61, 50]]}, {"timestamp": 1578737640898, "ltp": 1.58, "tv": 7507.47, "trd": [[1.58, 1803.42]], "batb": [[0, 1.58, 2444.2], [2, 1.56, 4814.32]], "batl": [[0, 1.59, 18.09], [2, 1.61, 70]]}, {"timestamp": 1578737651948, "ltp": 1.58, "tv": 7507.47, "trd": NaN, "batb": [[1, 1.57, 2300.69]], "batl": NaN}, {"timestamp": 1578737662962, "ltp": 1.58, "tv": 7507.47, "trd": NaN, "batb": NaN, "batl": [[0, 1.6, 102.13], [1, 1.61, 70], [2, 1.62, 98]]}, {"timestamp": 1578737672771, "ltp": 1.58, "tv": 7507.47, "trd": NaN, "batb": [[0, 1.59, 5031], [1, 1.58, 2444.2], [2, 1.57, 2276.69]], "batl": [[2, 1.62, 119]]}, {"timestamp": 1578737678783, "ltp": 1.6, "tv": 7546.71, "trd": [[1.6, 159.23]], "batb": NaN, "batl": [[0, 1.6, 82.52]]}, {"timestamp": 1578737682817, "ltp": 1.6, "tv": 7546.71, "trd": NaN, "batb": [[0, 1.59, 31]], "batl": NaN}, {"timestamp": 1578737684996, "ltp": 1.59, "tv": 7597.71, "trd": [[1.59, 268.26]], "batb": [[0, 1.58, 2444.2], [1, 1.57, 2304.69], [2, 1.56, 4794.19]], "batl": [[1, 1.61, 118.76]]}, {"timestamp": 1578737688001, "ltp": 1.59, "tv": 7746.57, "trd": [[1.59, 417.12]], "batb": [[0, 1.59, 3286.57], [1, 1.58, 2444.2], [2, 1.57, 2276.69]], "batl": NaN}, {"timestamp": 1578737688991, "ltp": 1.59, "tv": 7895.43, "trd": [[1.59, 565.98]], "batb": [[0, 1.59, 3212.14]], "batl": NaN}, {"timestamp": 1578737689927, "ltp": 1.59, "tv": 7895.43, "trd": NaN, "batb": NaN, "batl": [[1, 1.61, 70]]}, {"timestamp": 1578737691926, "ltp": 1.59, "tv": 8091.95, "trd": [[1.59, 762.5]], "batb": [[0, 1.59, 3113.88]], "batl": NaN}, {"timestamp": 1578737700964, "ltp": 1.59, "tv": 8281.47, "trd": [[1.59, 952.02]], "batb": [[0, 1.59, 3019.12]], "batl": NaN}, {"timestamp": 1578737701964, "ltp": 1.59, "tv": 8383.73, "trd": [[1.59, 1054.28]], "batb": [[0, 1.59, 2967.99]], "batl": [[1, 1.61, 76.88]]}, {"timestamp": 1578737702972, "ltp": 1.59, "tv": 8391.55, "trd": [[1.59, 1062.1]], "batb": [[0, 1.59, 2964.08]], "batl": NaN}, {"timestamp": 1578737703976, "ltp": 1.59, "tv": 8391.55, "trd": NaN, "batb": NaN, "batl": [[1, 1.61, 70]]}, {"timestamp": 1578737716885, "ltp": 1.6, "tv": 8401.67, "trd": [[1.6, 169.35]], "batb": NaN, "batl": [[0, 1.6, 77.46]]}, {"timestamp": 1578737752910, "ltp": 1.59, "tv": 8405.67, "trd": [[1.59, 1066.1]], "batb": [[0, 1.59, 2962.08]], "batl": NaN}, {"timestamp": 1578737769934, "ltp": 1.59, "tv": 8405.67, "trd": NaN, "batb": NaN, "batl": [[0, 1.6, 54.46]]}, {"timestamp": 1578737805822, "ltp": 1.59, "tv": 8405.67, "trd": NaN, "batb": NaN, "batl": [[0, 1.6, 56.46]]}, {"timestamp": 1578737817951, "ltp": 1.6, "tv": 8518.6, "trd": [[1.6, 282.29]], "batb": [[0, 1.6, 2974.52], [1, 1.59, 2962.08], [2, 1.58, 2414.2]], "batl": [[0, 1.61, 77], [1, 1.62, 119], [2, 1.63, 26.22]]}, {"timestamp": 1578737818965, "ltp": 1.6, "tv": 8653.62, "trd": [[1.6, 417.31]], "batb": [[0, 1.6, 2839.5]], "batl": NaN}, {"timestamp": 1578737864984, "ltp": 1.61, "tv": 8663.24, "trd": [[1.61, 51.32]], "batb": NaN, "batl": [[0, 1.61, 72.19]]}, {"timestamp": 1578737890964, "ltp": 1.6, "tv": 8683.24, "trd": [[1.6, 437.31]], "batb": [[0, 1.6, 2829.5]], "batl": NaN}, {"timestamp": 1578737925924, "ltp": 1.61, "tv": 8726.16, "trd": [[1.61, 94.24]], "batb": NaN, "batl": [[0, 1.61, 50.73]]}, {"timestamp": 1578737955962, "ltp": 1.61, "tv": 8726.16, "trd": NaN, "batb": NaN, "batl": [[0, 1.61, 51.73]]}, {"timestamp": 1578737957959, "ltp": 1.61, "tv": 8728.16, "trd": [[1.61, 96.24]], "batb": NaN, "batl": [[0, 1.61, 50.73]]}, {"timestamp": 1578737972991, "ltp": 1.61, "tv": 8906.78, "trd": [[1.61, 274.86]], "batb": [[0, 1.61, 2431.11], [1, 1.6, 2829.5], [2, 1.59, 2934.08]], "batl": [[0, 1.62, 119], [1, 1.63, 26.22], [2, 1.64, 25.16]]}, {"timestamp": 1578737973993, "ltp": 1.61, "tv": 8906.78, "trd": NaN, "batb": NaN, "batl": [[0, 1.62, 98]]}, {"timestamp": 1578737998906, "ltp": 1.62, "tv": 9102.78, "trd": [[1.62, 357.54]], "batb": [[0, 1.62, 2124], [1, 1.61, 2431.11], [2, 1.6, 2829.5]], "batl": [[0, 1.63, 26.22], [1, 1.64, 25.16], [2, 1.65, 25.19]]}, {"timestamp": 1578737999914, "ltp": 1.65, "tv": 9116.91, "trd": [[1.65, 14.13]], "batb": [[0, 1.63, 12.07], [1, 1.62, 2124], [2, 1.61, 2431.11]], "batl": [[0, 1.66, 26.18], [1, 1.69, 148.89], [2, 1.7, 203.13]]}, {"timestamp": 1578738000820, "ltp": 1.65, "tv": 9116.91, "trd": NaN, "batb": [[0, 1.63, 40]], "batl": NaN}, {"timestamp": 1578738006930, "ltp": 1.65, "tv": 9116.91, "trd": NaN, "batb": [[0, 1.63, 2040]], "batl": NaN}, {"timestamp": 1578738007934, "ltp": 1.64, "tv": 9128.91, "trd": [[1.64, 32]], "batb": [[0, 1.64, 34.31], [1, 1.63, 2040], [2, 1.62, 2124]], "batl": NaN}, {"timestamp": 1578738008940, "ltp": 1.66, "tv": 9154.11, "trd": [[1.65, 17.19], [1.66, 22.49]], "batb": NaN, "batl": [[0, 1.68, 24.89], [1, 1.69, 148]]}, {"timestamp": 1578738010948, "ltp": 1.65, "tv": 9154.19, "trd": [[1.65, 17.28]], "batb": NaN, "batl": NaN}, {"timestamp": 1578738011951, "ltp": 1.65, "tv": 9154.19, "trd": NaN, "batb": [[0, 1.64, 2034.31]], "batl": NaN}, {"timestamp": 1578738012919, "ltp": 1.65, "tv": 9154.19, "trd": NaN, "batb": NaN, "batl": [[0, 1.65, 2], [1, 1.68, 24.89], [2, 1.69, 148]]}, {"timestamp": 1578738013225, "ltp": 1.65, "tv": 9154.19, "trd": NaN, "batb": NaN, "batl": [[1, 1.66, 24], [2, 1.67, 24]]}, {"timestamp": 1578738015925, "ltp": 1.65, "tv": 9178.55, "trd": [[1.65, 41.64]], "batb": [[0, 1.65, 2017.64], [1, 1.64, 2034.31], [2, 1.63, 2040]], "batl": [[0, 1.67, 24], [1, 1.68, 24.89], [2, 1.69, 148]]}, {"timestamp": 1578738016949, "ltp": 1.65, "tv": 9178.55, "trd": NaN, "batb": [[0, 1.66, 40.02], [1, 1.65, 2017.64], [2, 1.64, 2034.31]], "batl": [[0, 1.68, 24.89], [1, 1.69, 148], [2, 1.7, 203.13]]}, {"timestamp": 1578738023957, "ltp": 1.66, "tv": 9183.6, "trd": [[1.66, 27.54]], "batb": [[0, 1.66, 34.97]], "batl": NaN}, {"timestamp": 1578738024966, "ltp": 1.66, "tv": 9183.6, "trd": NaN, "batb": NaN, "batl": [[1, 1.69, 24]]}, {"timestamp": 1578738032971, "ltp": 1.66, "tv": 9183.6, "trd": NaN, "batb": NaN, "batl": [[0, 1.67, 2], [1, 1.68, 24.89], [2, 1.69, 24]]}, {"timestamp": 1578738033949, "ltp": 1.66, "tv": 9183.6, "trd": NaN, "batb": [[0, 1.66, 1934.97], [2, 1.64, 2000]], "batl": NaN}, {"timestamp": 1578738044863, "ltp": 1.67, "tv": 9187.6, "trd": [[1.67, 33.64]], "batb": [[0, 1.67, 1536], [1, 1.66, 1934.97], [2, 1.65, 1977.64]], "batl": [[0, 1.69, 24.89], [1, 1.7, 227.13], [2, 1.71, 24.03]]}, {"timestamp": 1578738045960, "ltp": 1.67, "tv": 9187.92, "trd": [[1.67, 33.96]], "batb": [[0, 1.67, 1535.84]], "batl": NaN}, {"timestamp": 1578738046957, "ltp": 1.68, "tv": 9189.7, "trd": [[1.68, 1.78]], "batb": [[0, 1.68, 37.14], [1, 1.67, 1535.84], [2, 1.66, 1934.97]], "batl": [[0, 1.7, 227.13], [1, 1.71, 24.03], [2, 1.75, 145]]}, {"timestamp": 1578738047961, "ltp": 1.68, "tv": 9190.02, "trd": [[1.68, 2.1]], "batb": [[0, 1.68, 36.98]], "batl": NaN}, {"timestamp": 1578738049991, "ltp": 1.68, "tv": 9190.24, "trd": [[1.68, 2.32]], "batb": [[0, 1.68, 36.87]], "batl": NaN}, {"timestamp": 1578738050990, "ltp": 1.68, "tv": 9190.24, "trd": NaN, "batb": [[0, 1.68, 1536.87]], "batl": NaN}, {"timestamp": 1578738052884, "ltp": 1.68, "tv": 9190.46, "trd": [[1.68, 2.54]], "batb": [[0, 1.68, 1536.76]], "batl": NaN}, {"timestamp": 1578738054965, "ltp": 1.68, "tv": 9190.46, "trd": NaN, "batb": NaN, "batl": [[2, 1.75, 2]]}, {"timestamp": 1578738055697, "ltp": 1.68, "tv": 9190.46, "trd": NaN, "batb": [[2, 1.66, 1936.97]], "batl": NaN}, {"timestamp": 1578738059000, "ltp": 1.68, "tv": 9190.66, "trd": [[1.68, 2.74]], "batb": [[0, 1.68, 1536.66]], "batl": NaN}, {"timestamp": 1578738062974, "ltp": 1.69, "tv": 9190.86, "trd": [[1.69, 0.2]], "batb": [[0, 1.69, 2499.9], [1, 1.68, 1536.66], [2, 1.67, 1535.84]], "batl": [[0, 1.7, 203.13], [2, 1.72, 24.03]]}, {"timestamp": 1578738070998, "ltp": 1.69, "tv": 9190.86, "trd": NaN, "batb": [[0, 1.69, 2536.9], [2, 1.67, 1497.84]], "batl": [[2, 1.72, 24]]}, {"timestamp": 1578738114899, "ltp": 1.69, "tv": 9190.86, "trd": NaN, "batb": NaN, "batl": [[1, 1.71, 55.05]]}, {"timestamp": 1578738157882, "ltp": 1.69, "tv": 14190.86, "trd": [[1.69, 5000.2]], "batb": [[0, 1.69, 36.9]], "batl": NaN}, {"timestamp": 1578738162876, "ltp": 1.69, "tv": 14290.86, "trd": [[1.69, 5100.2]], "batb": [[0, 1.69, 17.9]], "batl": NaN}, {"timestamp": 1578738163999, "ltp": 1.7, "tv": 14300.46, "trd": [[1.7, 9.6]], "batb": NaN, "batl": [[0, 1.7, 198.33]]}, {"timestamp": 1578738165974, "ltp": 1.7, "tv": 14300.46, "trd": NaN, "batb": [[0, 1.69, 517.9]], "batl": NaN}, {"timestamp": 1578738166982, "ltp": 1.69, "tv": 14320.46, "trd": [[1.69, 5120.2]], "batb": [[0, 1.69, 507.9]], "batl": NaN}, {"timestamp": 1578738167986, "ltp": 1.69, "tv": 14320.46, "trd": NaN, "batb": [[0, 1.69, 508.8]], "batl": NaN}, {"timestamp": 1578738168993, "ltp": 1.69, "tv": 14320.46, "trd": NaN, "batb": [[1, 1.68, 1586.66]], "batl": NaN}, {"timestamp": 1578738181892, "ltp": 1.69, "tv": 14320.46, "trd": NaN, "batb": NaN, "batl": [[1, 1.71, 35.66]]}, {"timestamp": 1578738184780, "ltp": 1.69, "tv": 14320.46, "trd": NaN, "batb": [[0, 1.69, 1507.8]], "batl": NaN}, {"timestamp": 1578738211955, "ltp": 1.7, "tv": 14688.46, "trd": [[1.7, 377.6]], "batb": NaN, "batl": [[0, 1.7, 14.33]]}, {"timestamp": 1578738212953, "ltp": 1.7, "tv": 14688.46, "trd": NaN, "batb": NaN, "batl": [[1, 1.71, 29.36]]}, {"timestamp": 1578738216957, "ltp": 1.7, "tv": 14688.46, "trd": NaN, "batb": NaN, "batl": [[1, 1.71, 213.36]]}, {"timestamp": 1578738226947, "ltp": 1.7, "tv": 14702.79, "trd": [[1.7, 391.93]], "batb": NaN, "batl": [[0, 1.71, 213.36], [1, 1.72, 24], [2, 1.75, 2]]}, {"timestamp": 1578738227951, "ltp": 1.7, "tv": 14713.43, "trd": [[1.7, 402.57]], "batb": [[0, 1.7, 178.62], [1, 1.69, 1530.9], [2, 1.68, 1586.66]], "batl": [[0, 1.71, 184], [2, 1.73, 29.17]]}, {"timestamp": 1578738229852, "ltp": 1.71, "tv": 14717.43, "trd": [[1.71, 4]], "batb": [[0, 1.7, 151.6], [2, 1.68, 1550]], "batl": [[0, 1.71, 182]]}, {"timestamp": 1578738231967, "ltp": 1.7, "tv": 14819.58, "trd": [[1.7, 504.71]], "batb": [[0, 1.7, 130.53]], "batl": [[1, 1.72, 35]]}, {"timestamp": 1578738234990, "ltp": 1.7, "tv": 15059.57, "trd": [[1.7, 744.71]], "batb": [[0, 1.7, 10.53]], "batl": NaN}, {"timestamp": 1578738239976, "ltp": 1.7, "tv": 15073.57, "trd": [[1.7, 758.71]], "batb": [[0, 1.7, 3.53]], "batl": NaN}, {"timestamp": 1578738244003, "ltp": 1.7, "tv": 15073.57, "trd": NaN, "batb": NaN, "batl": [[1, 1.72, 65.3]]}, {"timestamp": 1578738251898, "ltp": 1.7, "tv": 15073.57, "trd": NaN, "batb": NaN, "batl": [[0, 1.71, 190]]}, {"timestamp": 1578738252992, "ltp": 1.7, "tv": 15073.57, "trd": NaN, "batb": [[0, 1.7, 669.53]], "batl": NaN}, {"timestamp": 1578738255719, "ltp": 1.7, "tv": 15073.57, "trd": NaN, "batb": [[0, 1.7, 695]], "batl": [[2, 1.73, 39]]}, {"timestamp": 1578738258908, "ltp": 1.7, "tv": 15073.57, "trd": NaN, "batb": NaN, "batl": [[0, 1.71, 182]]}, {"timestamp": 1578738269917, "ltp": 1.7, "tv": 15073.57, "trd": NaN, "batb": NaN, "batl": [[0, 1.71, 90]]}, {"timestamp": 1578738275943, "ltp": 1.7, "tv": 15073.57, "trd": NaN, "batb": NaN, "batl": [[1, 1.72, 155.3]]}, {"timestamp": 1578738288951, "ltp": 1.7, "tv": 15174.4, "trd": [[1.7, 859.54]], "batb": [[0, 1.7, 568.7], [2, 1.68, 1578]], "batl": [[0, 1.71, 141], [1, 1.72, 168.3]]}, {"timestamp": 1578738289969, "ltp": 1.7, "tv": 15174.4, "trd": NaN, "batb": [[0, 1.7, 595.7], [2, 1.68, 1550]], "batl": [[0, 1.71, 90]]}, {"timestamp": 1578738291935, "ltp": 1.7, "tv": 15174.4, "trd": NaN, "batb": [[0, 1.7, 568.7], [2, 1.68, 1577]], "batl": [[0, 1.71, 141]]}, {"timestamp": 1578738292672, "ltp": 1.7, "tv": 15174.4, "trd": NaN, "batb": [[0, 1.7, 595.7], [2, 1.68, 1550]], "batl": [[0, 1.71, 90]]}, {"timestamp": 1578738293949, "ltp": 1.7, "tv": 15174.4, "trd": NaN, "batb": NaN, "batl": [[0, 1.71, 107.02]]}, {"timestamp": 1578738298861, "ltp": 1.7, "tv": 15191.0, "trd": [[1.7, 876.14]], "batb": [[0, 1.7, 18.7]], "batl": NaN}, {"timestamp": 1578738313989, "ltp": 1.7, "tv": 15191.0, "trd": NaN, "batb": [[0, 1.7, 1017.7]], "batl": NaN}, {"timestamp": 1578738328998, "ltp": 1.7, "tv": 15191.0, "trd": NaN, "batb": NaN, "batl": [[1, 1.72, 138]]}, {"timestamp": 1578738330929, "ltp": 1.7, "tv": 15191.0, "trd": NaN, "batb": NaN, "batl": [[0, 1.71, 112.13]]}, {"timestamp": 1578738333910, "ltp": 1.7, "tv": 15391.0, "trd": [[1.7, 1076.14]], "batb": [[0, 1.7, 943.7]], "batl": NaN}, {"timestamp": 1578738337944, "ltp": 1.7, "tv": 15391.73, "trd": [[1.7, 1076.87]], "batb": [[0, 1.7, 942.97]], "batl": NaN}, {"timestamp": 1578738346934, "ltp": 1.7, "tv": 15391.73, "trd": NaN, "batb": [[0, 1.7, 1941.97]], "batl": NaN}, {"timestamp": 1578738404907, "ltp": 1.7, "tv": 15391.73, "trd": NaN, "batb": [[0, 1.7, 2940.97]], "batl": NaN}, {"timestamp": 1578738412529, "ltp": 1.71, "tv": 15615.99, "trd": [[1.71, 228.26]], "batb": [[0, 1.71, 3214.87], [1, 1.7, 2940.97], [2, 1.69, 1499.9]], "batl": [[0, 1.72, 90], [1, 1.73, 54], [2, 1.74, 54.02]]}, {"timestamp": 1578738418947, "ltp": 1.71, "tv": 15626.2, "trd": [[1.71, 238.47]], "batb": [[0, 1.71, 3204.66]], "batl": NaN}, {"timestamp": 1578738425931, "ltp": 1.71, "tv": 15626.2, "trd": NaN, "batb": NaN, "batl": [[0, 1.73, 90], [1, 1.74, 54.02], [2, 1.75, 2]]}, {"timestamp": 1578738429942, "ltp": 1.72, "tv": 15662.82, "trd": [[1.72, 36.62]], "batb": [[0, 1.72, 2185.38], [1, 1.71, 3204.66], [2, 1.7, 2940.97]], "batl": NaN}, {"timestamp": 1578738430960, "ltp": 1.72, "tv": 15662.82, "trd": NaN, "batb": [[0, 1.72, 2219.38], [2, 1.7, 2914.97]], "batl": [[2, 1.75, 65.02]]}, {"timestamp": 1578738453983, "ltp": 1.72, "tv": 15662.82, "trd": NaN, "batb": NaN, "batl": [[0, 1.73, 89.97]]}, {"timestamp": 1578738454878, "ltp": 1.72, "tv": 15662.82, "trd": NaN, "batb": [[1, 1.71, 3213.66]], "batl": [[1, 1.74, 81.11]]}, {"timestamp": 1578738511618, "ltp": 1.72, "tv": 15662.82, "trd": NaN, "batb": NaN, "batl": [[1, 1.74, 99.09]]}, {"timestamp": 1578738520855, "ltp": 1.72, "tv": 15662.82, "trd": NaN, "batb": NaN, "batl": [[1, 1.74, 79.89]]}, {"timestamp": 1578738521918, "ltp": 1.72, "tv": 15662.82, "trd": NaN, "batb": NaN, "batl": [[1, 1.74, 85.04]]}, {"timestamp": 1578738542991, "ltp": 1.72, "tv": 15662.82, "trd": NaN, "batb": [[0, 1.73, 40.02], [1, 1.72, 2219.38], [2, 1.71, 3177.66]], "batl": [[0, 1.74, 103.01], [1, 1.75, 65.02], [2, 1.76, 66.02]]}, {"timestamp": 1578738543900, "ltp": 1.73, "tv": 15713.76, "trd": [[1.73, 50.94]], "batb": [[0, 1.73, 14.55]], "batl": [[0, 1.74, 89.97], [1, 1.75, 73.26]]}, {"timestamp": 1578738544910, "ltp": 1.73, "tv": 15713.76, "trd": NaN, "batb": NaN, "batl": [[1, 1.75, 65.02]]}, {"timestamp": 1578738553613, "ltp": 1.73, "tv": 15713.76, "trd": NaN, "batb": NaN, "batl": [[0, 1.74, 89.36]]}, {"timestamp": 1578738555941, "ltp": 1.73, "tv": 15713.76, "trd": NaN, "batb": [[0, 1.73, 1013.55]], "batl": NaN}, {"timestamp": 1578738556911, "ltp": 1.73, "tv": 15713.76, "trd": NaN, "batb": [[0, 1.73, 1038]], "batl": NaN}, {"timestamp": 1578738565947, "ltp": 1.73, "tv": 15713.76, "trd": NaN, "batb": NaN, "batl": [[1, 1.75, 91.85]]}, {"timestamp": 1578738598424, "ltp": 1.74, "tv": 15723.76, "trd": [[1.74, 10]], "batb": NaN, "batl": [[0, 1.74, 84.36]]}, {"timestamp": 1578738633959, "ltp": 1.74, "tv": 15723.76, "trd": NaN, "batb": [[2, 1.71, 3187.66]], "batl": NaN}, {"timestamp": 1578738638949, "ltp": 1.74, "tv": 15723.76, "trd": NaN, "batb": NaN, "batl": [[1, 1.75, 84.16]]}, {"timestamp": 1578738694976, "ltp": 1.73, "tv": 15800.56, "trd": [[1.73, 127.74]], "batb": [[0, 1.73, 999.6]], "batl": NaN}, {"timestamp": 1578738697963, "ltp": 1.73, "tv": 15800.56, "trd": NaN, "batb": NaN, "batl": [[1, 1.75, 73.38]]}, {"timestamp": 1578738726976, "ltp": 1.73, "tv": 15800.56, "trd": NaN, "batb": NaN, "batl": [[1, 1.75, 65.02]]}, {"timestamp": 1578738736809, "ltp": 1.73, "tv": 15800.56, "trd": NaN, "batb": NaN, "batl": [[0, 1.74, 88.62]]}, {"timestamp": 1578738745938, "ltp": 1.73, "tv": 15800.56, "trd": NaN, "batb": NaN, "batl": [[1, 1.75, 91.63]]}, {"timestamp": 1578738746943, "ltp": 1.74, "tv": 15804.56, "trd": [[1.74, 14]], "batb": NaN, "batl": [[0, 1.74, 86.62]]}, {"timestamp": 1578738747934, "ltp": 1.74, "tv": 15804.56, "trd": NaN, "batb": NaN, "batl": [[0, 1.74, 88.62]]}, {"timestamp": 1578738757945, "ltp": 1.74, "tv": 15825.62, "trd": [[1.74, 35.06]], "batb": [[0, 1.73, 1000.48]], "batl": [[0, 1.74, 78.09]]}, {"timestamp": 1578738772968, "ltp": 1.74, "tv": 15825.62, "trd": NaN, "batb": NaN, "batl": [[0, 1.74, 80.09]]}, {"timestamp": 1578738809904, "ltp": 1.74, "tv": 15825.62, "trd": NaN, "batb": NaN, "batl": [[1, 1.75, 65.02]]}, {"timestamp": 1578738811906, "ltp": 1.73, "tv": 15865.62, "trd": [[1.73, 167.74]], "batb": [[0, 1.73, 980.48]], "batl": NaN}, {"timestamp": 1578738835003, "ltp": 1.74, "tv": 16025.8, "trd": [[1.74, 195.24]], "batb": [[0, 1.74, 1954.91], [1, 1.73, 991.03], [2, 1.72, 2185.38]], "batl": [[0, 1.75, 2], [1, 1.76, 66.02], [2, 1.77, 73.02]]}, {"timestamp": 1578738838921, "ltp": 1.74, "tv": 16037.19, "trd": [[1.74, 206.63]], "batb": [[0, 1.74, 1943.52]], "batl": NaN}, {"timestamp": 1578738839934, "ltp": 1.74, "tv": 16037.19, "trd": NaN, "batb": [[2, 1.72, 2195.38]], "batl": NaN}, {"timestamp": 1578738840939, "ltp": 1.74, "tv": 16037.19, "trd": NaN, "batb": NaN, "batl": [[1, 1.76, 77.84]]}, {"timestamp": 1578738857993, "ltp": 1.74, "tv": 16037.19, "trd": NaN, "batb": NaN, "batl": [[1, 1.76, 71.65]]}, {"timestamp": 1578738860993, "ltp": 1.75, "tv": 16042.19, "trd": [[1.75, 5]], "batb": NaN, "batl": [[0, 1.76, 71.65], [1, 1.77, 73.02], [2, 1.78, 67.37]]}, {"timestamp": 1578738864000, "ltp": 1.74, "tv": 16142.19, "trd": [[1.74, 306.63]], "batb": [[0, 1.74, 1893.52]], "batl": NaN}, {"timestamp": 1578738864906, "ltp": 1.74, "tv": 16142.19, "trd": NaN, "batb": [[0, 1.75, 33.18], [1, 1.74, 1893.52], [2, 1.73, 956.03]], "batl": [[0, 1.77, 73.02], [1, 1.78, 67.37], [2, 1.82, 137]]}, {"timestamp": 1578738866910, "ltp": 1.75, "tv": 16242.19, "trd": [[1.75, 105]], "batb": [[0, 1.75, 32]], "batl": [[2, 1.84, 136]]}, {"timestamp": 1578738868307, "ltp": 1.75, "tv": 16282.19, "trd": [[1.75, 145]], "batb": [[0, 1.75, 12]], "batl": NaN}, {"timestamp": 1578738870908, "ltp": 1.75, "tv": 16282.19, "trd": NaN, "batb": [[0, 1.76, 31.01], [1, 1.75, 2031], [2, 1.74, 1858.52]], "batl": [[0, 1.78, 67.37], [1, 1.79, 64.01]]}, {"timestamp": 1578738880937, "ltp": 1.78, "tv": 16290.68, "trd": [[1.77, 0.99], [1.78, 7.5]], "batb": NaN, "batl": [[0, 1.78, 63.62]]}, {"timestamp": 1578738881946, "ltp": 1.78, "tv": 16290.68, "trd": NaN, "batb": NaN, "batl": [[0, 1.83, 62.01], [1, 1.84, 136], [2, 1.9, 3]]}, {"timestamp": 1578738882955, "ltp": 1.78, "tv": 16290.68, "trd": NaN, "batb": [[0, 1.76, 2031.01]], "batl": NaN}, {"timestamp": 1578738896963, "ltp": 1.78, "tv": 16290.68, "trd": NaN, "batb": NaN, "batl": [[0, 1.85, 61.01], [1, 1.86, 134]]}, {"timestamp": 1578738898950, "ltp": 1.78, "tv": 16290.68, "trd": NaN, "batb": NaN, "batl": [[0, 1.79, 83.01]]}, {"timestamp": 1578738900978, "ltp": 1.78, "tv": 16290.68, "trd": NaN, "batb": [[0, 1.77, 1239.91], [1, 1.76, 2031.01], [2, 1.75, 2000]], "batl": [[0, 1.78, 10.33], [1, 1.79, 83.01], [2, 1.8, 63.01]]}, {"timestamp": 1578738902939, "ltp": 1.78, "tv": 16290.68, "trd": NaN, "batb": NaN, "batl": [[0, 1.79, 83.01], [1, 1.8, 63.01], [2, 1.81, 63.01]]}, {"timestamp": 1578738907004, "ltp": 1.78, "tv": 16290.68, "trd": NaN, "batb": [[0, 1.78, 1900], [1, 1.77, 1239.91], [2, 1.76, 2031.01]], "batl": [[0, 1.79, 20]]}, {"timestamp": 1578738907844, "ltp": 1.78, "tv": 16290.68, "trd": NaN, "batb": [[1, 1.77, 1029]], "batl": NaN}, {"timestamp": 1578738915875, "ltp": 1.78, "tv": 16290.68, "trd": NaN, "batb": NaN, "batl": [[1, 1.8, 69.17]]}, {"timestamp": 1578738916981, "ltp": 1.78, "tv": 16290.68, "trd": NaN, "batb": [[0, 1.78, 1930], [2, 1.76, 2000]], "batl": NaN}, {"timestamp": 1578738969981, "ltp": 1.78, "tv": 16299.05, "trd": [[1.78, 15.87]], "batb": [[0, 1.78, 1921.63]], "batl": NaN}, {"timestamp": 1578739004917, "ltp": 1.78, "tv": 16299.05, "trd": NaN, "batb": NaN, "batl": [[1, 1.8, 63.01]]}, {"timestamp": 1578739011968, "ltp": 1.79, "tv": 16339.05, "trd": [[1.79, 40]], "batb": [[0, 1.79, 1505.84], [1, 1.78, 1941.74], [2, 1.77, 1029]], "batl": [[0, 1.84, 59.01], [1, 1.86, 134], [2, 1.9, 3]]}, {"timestamp": 1578739012896, "ltp": 1.79, "tv": 16339.05, "trd": NaN, "batb": NaN, "batl": [[0, 1.82, 78.72]]}, {"timestamp": 1578739013904, "ltp": 1.79, "tv": 16339.05, "trd": NaN, "batb": [[0, 1.8, 28.01], [1, 1.79, 1505.84], [2, 1.78, 1941.74]], "batl": [[0, 1.82, 60.01], [1, 1.84, 59.01], [2, 1.86, 134]]}, {"timestamp": 1578739014903, "ltp": 1.79, "tv": 16339.05, "trd": NaN, "batb": NaN, "batl": [[0, 1.85, 59.01], [1, 1.86, 134], [2, 1.9, 3]]}, {"timestamp": 1578739015950, "ltp": 1.79, "tv": 16339.05, "trd": NaN, "batb": [[0, 1.8, 184.51]], "batl": NaN}, {"timestamp": 1578739016949, "ltp": 1.79, "tv": 16339.05, "trd": NaN, "batb": NaN, "batl": [[0, 1.89, 58.01], [1, 1.9, 3], [2, 1.91, 131]]}, {"timestamp": 1578739019922, "ltp": 1.79, "tv": 16339.05, "trd": NaN, "batb": [[0, 1.8, 2184.51]], "batl": NaN}, {"timestamp": 1578739027955, "ltp": 1.79, "tv": 16339.05, "trd": NaN, "batb": [[0, 1.8, 184.51]], "batl": NaN}, {"timestamp": 1578739034960, "ltp": 1.8, "tv": 16693.05, "trd": [[1.8, 354]], "batb": [[0, 1.8, 7.52]], "batl": NaN}, {"timestamp": 1578739035938, "ltp": 1.8, "tv": 16693.05, "trd": NaN, "batb": [[0, 1.8, 32.52]], "batl": NaN}, {"timestamp": 1578739040980, "ltp": 1.8, "tv": 16693.05, "trd": NaN, "batb": [[0, 1.8, 2032.52]], "batl": NaN}, {"timestamp": 1578739041979, "ltp": 1.8, "tv": 16693.05, "trd": NaN, "batb": [[0, 1.81, 25.01], [1, 1.8, 2032.52], [2, 1.79, 1505.84]], "batl": NaN}, {"timestamp": 1578739046864, "ltp": 1.8, "tv": 16693.05, "trd": NaN, "batb": [[0, 1.81, 1525.01]], "batl": [[1, 1.9, 135], [2, 1.96, 2.67]]}, {"timestamp": 1578739047973, "ltp": 1.8, "tv": 16693.05, "trd": NaN, "batb": [[1, 1.8, 2025]], "batl": NaN}, {"timestamp": 1578739050792, "ltp": 1.8, "tv": 16693.05, "trd": NaN, "batb": NaN, "batl": [[0, 1.83, 56.17], [1, 1.84, 145.74], [2, 1.9, 135]]}, {"timestamp": 1578739054001, "ltp": 1.81, "tv": 16713.05, "trd": [[1.81, 20]], "batb": [[0, 1.81, 1515.01]], "batl": NaN}, {"timestamp": 1578739057692, "ltp": 1.81, "tv": 16713.05, "trd": NaN, "batb": [[0, 1.81, 1524]], "batl": NaN}, {"timestamp": 1578739058684, "ltp": 1.81, "tv": 16713.05, "trd": NaN, "batb": [[0, 1.82, 999], [1, 1.81, 1524], [2, 1.8, 2025]], "batl": NaN}, {"timestamp": 1578739059915, "ltp": 1.81, "tv": 16713.05, "trd": NaN, "batb": NaN, "batl": [[0, 1.84, 200.74], [1, 1.85, 55.17]]}, {"timestamp": 1578739063914, "ltp": 1.82, "tv": 16737.23, "trd": [[1.82, 24.18]], "batb": [[0, 1.82, 974.82]], "batl": NaN}, {"timestamp": 1578739064987, "ltp": 1.82, "tv": 16747.18, "trd": [[1.82, 34.13]], "batb": [[0, 1.82, 964.87]], "batl": NaN}, {"timestamp": 1578739067992, "ltp": 1.83, "tv": 16766.75, "trd": [[1.83, 19.57]], "batb": NaN, "batl": NaN}, {"timestamp": 1578739068991, "ltp": 1.82, "tv": 16778.33, "trd": [[1.82, 45.71]], "batb": [[0, 1.82, 953.29]], "batl": NaN}, {"timestamp": 1578739094642, "ltp": 1.82, "tv": 16817.62, "trd": [[1.82, 85]], "batb": [[0, 1.82, 914]], "batl": NaN}, {"timestamp": 1578739107763, "ltp": 1.82, "tv": 16899.33, "trd": [[1.82, 166.71]], "batb": [[0, 1.82, 832.29]], "batl": NaN}, {"timestamp": 1578739108964, "ltp": 1.82, "tv": 16899.33, "trd": NaN, "batb": [[0, 1.82, 1532.29]], "batl": NaN}, {"timestamp": 1578739114972, "ltp": 1.82, "tv": 16914.38, "trd": [[1.82, 181.76]], "batb": [[0, 1.82, 1517.24]], "batl": NaN}, {"timestamp": 1578739117870, "ltp": 1.82, "tv": 16918.38, "trd": [[1.82, 185.76]], "batb": [[0, 1.82, 1515.24]], "batl": NaN}, {"timestamp": 1578739125753, "ltp": 1.83, "tv": 16930.38, "trd": [[1.83, 31.57]], "batb": NaN, "batl": NaN}, {"timestamp": 1578739133001, "ltp": 1.83, "tv": 16942.48, "trd": [[1.83, 43.67]], "batb": [[0, 1.83, 1487.9], [1, 1.82, 1539.24], [2, 1.81, 1524]], "batl": NaN}, {"timestamp": 1578739136984, "ltp": 1.83, "tv": 16942.48, "trd": NaN, "batb": NaN, "batl": [[2, 1.9, 3]]}, {"timestamp": 1578739138986, "ltp": 1.83, "tv": 16942.48, "trd": NaN, "batb": NaN, "batl": [[1, 1.85, 85.08]]}, {"timestamp": 1578739144986, "ltp": 1.83, "tv": 17141.28, "trd": [[1.83, 242.47]], "batb": [[0, 1.83, 1388.5]], "batl": NaN}, {"timestamp": 1578739149919, "ltp": 1.83, "tv": 17180.35, "trd": [[1.83, 281.54]], "batb": [[0, 1.83, 1349.43]], "batl": NaN}, {"timestamp": 1578739169953, "ltp": 1.83, "tv": 17317.64, "trd": [[1.83, 418.83]], "batb": [[0, 1.83, 1261.25]], "batl": NaN}, {"timestamp": 1578739181976, "ltp": 1.83, "tv": 17517.64, "trd": [[1.83, 618.83]], "batb": [[0, 1.83, 1161.25]], "batl": NaN}, {"timestamp": 1578739183002, "ltp": 1.83, "tv": 17517.64, "trd": NaN, "batb": NaN, "batl": [[1, 1.85, 58.18]]}, {"timestamp": 1578739183797, "ltp": 1.83, "tv": 17517.64, "trd": NaN, "batb": NaN, "batl": [[1, 1.85, 55.17]]}, {"timestamp": 1578739186800, "ltp": 1.83, "tv": 17630.86, "trd": [[1.83, 732.05]], "batb": [[0, 1.83, 1098.03]], "batl": NaN}, {"timestamp": 1578739189713, "ltp": 1.83, "tv": 17630.86, "trd": NaN, "batb": [[0, 1.82, 1539.24], [1, 1.81, 1524], [2, 1.8, 2025]], "batl": NaN}, {"timestamp": 1578739190925, "ltp": 1.82, "tv": 17635.34, "trd": [[1.82, 190.24]], "batb": [[0, 1.82, 1534.76], [2, 1.8, 2000]], "batl": NaN}, {"timestamp": 1578739196930, "ltp": 1.82, "tv": 17635.34, "trd": NaN, "batb": NaN, "batl": [[0, 1.84, 207.09], [2, 1.9, 135]]}, {"timestamp": 1578739199927, "ltp": 1.82, "tv": 17635.34, "trd": NaN, "batb": [[0, 1.82, 1510.76], [2, 1.8, 2024]], "batl": NaN}, {"timestamp": 1578739211845, "ltp": 1.82, "tv": 17674.63, "trd": [[1.82, 229.53]], "batb": [[0, 1.82, 1471.47]], "batl": NaN}, {"timestamp": 1578739221974, "ltp": 1.82, "tv": 17690.67, "trd": [[1.82, 245.57]], "batb": [[0, 1.82, 1455.43]], "batl": NaN}, {"timestamp": 1578739291927, "ltp": 1.82, "tv": 17727.54, "trd": [[1.82, 282.44]], "batb": [[0, 1.82, 1418.56]], "batl": NaN}, {"timestamp": 1578739292920, "ltp": 1.82, "tv": 17727.54, "trd": NaN, "batb": NaN, "batl": [[0, 1.84, 200.74]]}, {"timestamp": 1578739293919, "ltp": 1.82, "tv": 17927.54, "trd": [[1.82, 482.44]], "batb": [[0, 1.82, 1318.56]], "batl": NaN}, {"timestamp": 1578739298003, "ltp": 1.82, "tv": 17927.54, "trd": NaN, "batb": NaN, "batl": [[0, 1.84, 208.8]]}, {"timestamp": 1578739298911, "ltp": 1.82, "tv": 17955.43, "trd": [[1.82, 510.33]], "batb": [[0, 1.82, 1290.67]], "batl": NaN}, {"timestamp": 1578739299946, "ltp": 1.82, "tv": 17955.43, "trd": NaN, "batb": [[0, 1.82, 1314.67], [2, 1.8, 2000]], "batl": NaN}, {"timestamp": 1578739300931, "ltp": 1.82, "tv": 17955.43, "trd": NaN, "batb": NaN, "batl": [[0, 1.84, 200.74], [1, 1.85, 78.02]]}, {"timestamp": 1578739303966, "ltp": 1.82, "tv": 18092.48, "trd": [[1.82, 647.38]], "batb": [[0, 1.82, 1177.62]], "batl": [[0, 1.84, 145.74], [2, 1.86, 55.28]]}, {"timestamp": 1578739304855, "ltp": 1.82, "tv": 18092.48, "trd": NaN, "batb": [[0, 1.83, 25.28], [1, 1.82, 1177.62], [2, 1.81, 1524]], "batl": [[0, 1.85, 222.98], [1, 1.86, 55.28], [2, 1.9, 135]]}, {"timestamp": 1578739305952, "ltp": 1.82, "tv": 18092.48, "trd": NaN, "batb": NaN, "batl": [[0, 1.85, 200.13]]}, {"timestamp": 1578739314960, "ltp": 1.82, "tv": 18092.48, "trd": NaN, "batb": [[0, 1.84, 10.55], [1, 1.83, 25.28], [2, 1.82, 1177.62]], "batl": [[0, 1.85, 144.96], [2, 1.87, 54.09]]}, {"timestamp": 1578739320976, "ltp": 1.84, "tv": 18113.57, "trd": [[1.84, 21.1]], "batb": [[0, 1.83, 151.32], [1, 1.82, 1177.62], [2, 1.81, 1500]], "batl": [[0, 1.84, 5.65], [1, 1.85, 144.96], [2, 1.86, 55.28]]}, {"timestamp": 1578739321869, "ltp": 1.84, "tv": 18113.57, "trd": NaN, "batb": NaN, "batl": [[1, 1.85, 212.91]]}, {"timestamp": 1578739326491, "ltp": 1.84, "tv": 18113.57, "trd": NaN, "batb": NaN, "batl": [[1, 1.85, 199.96]]}, {"timestamp": 1578739330893, "ltp": 1.83, "tv": 18142.02, "trd": [[1.83, 760.5]], "batb": [[0, 1.83, 122.87]], "batl": NaN}, {"timestamp": 1578739331961, "ltp": 1.83, "tv": 18387.76, "trd": [[1.83, 1006.24]], "batb": [[0, 1.82, 1177.62], [1, 1.81, 1525], [2, 1.8, 2000]], "batl": NaN}, {"timestamp": 1578739342004, "ltp": 1.83, "tv": 18387.76, "trd": NaN, "batb": NaN, "batl": [[0, 1.84, 58.74]]}, {"timestamp": 1578739343000, "ltp": 1.82, "tv": 18687.76, "trd": [[1.82, 947.38]], "batb": [[0, 1.82, 1027.62]], "batl": [[0, 1.83, 146.54], [1, 1.84, 58.74], [2, 1.85, 55]]}, {"timestamp": 1578739347921, "ltp": 1.82, "tv": 18687.76, "trd": NaN, "batb": [[0, 1.82, 1003.62], [2, 1.8, 2023]], "batl": NaN}, {"timestamp": 1578739352959, "ltp": 1.82, "tv": 18687.76, "trd": NaN, "batb": [[0, 1.82, 1026.62], [2, 1.8, 2000]], "batl": [[0, 1.84, 151.4], [1, 1.85, 55], [2, 1.86, 55.28]]}, {"timestamp": 1578739353952, "ltp": 1.82, "tv": 18687.76, "trd": NaN, "batb": NaN, "batl": [[0, 1.84, 203.4]]}, {"timestamp": 1578739354948, "ltp": 1.82, "tv": 18687.76, "trd": NaN, "batb": NaN, "batl": [[0, 1.84, 151.4]]}, {"timestamp": 1578739355951, "ltp": 1.82, "tv": 18687.76, "trd": NaN, "batb": NaN, "batl": [[1, 1.85, 79.51]]}, {"timestamp": 1578739368962, "ltp": 1.82, "tv": 19387.76, "trd": [[1.82, 1647.38]], "batb": [[0, 1.82, 676.62]], "batl": NaN}, {"timestamp": 1578739371961, "ltp": 1.82, "tv": 19387.76, "trd": NaN, "batb": NaN, "batl": [[1, 1.85, 55]]}, {"timestamp": 1578739372966, "ltp": 1.82, "tv": 19387.76, "trd": NaN, "batb": NaN, "batl": [[1, 1.85, 82.15]]}, {"timestamp": 1578739376898, "ltp": 1.82, "tv": 19687.76, "trd": [[1.82, 1947.38]], "batb": [[0, 1.82, 526.62]], "batl": NaN}, {"timestamp": 1578739377997, "ltp": 1.82, "tv": 19687.76, "trd": NaN, "batb": NaN, "batl": [[0, 1.84, 161.4]]}, {"timestamp": 1578739382906, "ltp": 1.82, "tv": 19687.76, "trd": NaN, "batb": NaN, "batl": [[0, 1.84, 213.4], [1, 1.85, 55]]}, {"timestamp": 1578739383804, "ltp": 1.82, "tv": 19687.76, "trd": NaN, "batb": [[0, 1.82, 1414.62]], "batl": NaN}, {"timestamp": 1578739384980, "ltp": 1.82, "tv": 19687.76, "trd": NaN, "batb": NaN, "batl": [[0, 1.84, 161.4]]}, {"timestamp": 1578739411842, "ltp": 1.82, "tv": 19687.76, "trd": NaN, "batb": [[0, 1.82, 1415.46]], "batl": NaN}, {"timestamp": 1578739412943, "ltp": 1.82, "tv": 19687.76, "trd": NaN, "batb": [[0, 1.82, 1392.46], [2, 1.8, 2023]], "batl": [[0, 1.83, 38.28], [1, 1.84, 213.4], [2, 1.85, 55]]}, {"timestamp": 1578739418967, "ltp": 1.82, "tv": 20464.32, "trd": [[1.82, 2723.94]], "batb": [[0, 1.82, 1004.18]], "batl": NaN}, {"timestamp": 1578739440925, "ltp": 1.82, "tv": 20540.88, "trd": [[1.82, 2800.5]], "batb": [[0, 1.82, 965.9]], "batl": NaN}, {"timestamp": 1578739458957, "ltp": 1.82, "tv": 20540.88, "trd": NaN, "batb": NaN, "batl": [[1, 1.84, 221.87]]}, {"timestamp": 1578739474992, "ltp": 1.82, "tv": 20540.88, "trd": NaN, "batb": NaN, "batl": [[0, 1.83, 76.56]]}, {"timestamp": 1578739475974, "ltp": 1.82, "tv": 20540.88, "trd": NaN, "batb": NaN, "batl": [[1, 1.84, 213.4]]}, {"timestamp": 1578739478900, "ltp": 1.82, "tv": 20840.88, "trd": [[1.82, 3100.5]], "batb": [[0, 1.82, 815.9]], "batl": NaN}, {"timestamp": 1578739484992, "ltp": 1.83, "tv": 20873.68, "trd": [[1.83, 1039.04]], "batb": NaN, "batl": [[0, 1.83, 60.16]]}, {"timestamp": 1578739490999, "ltp": 1.83, "tv": 20881.68, "trd": [[1.83, 1047.03]], "batb": NaN, "batl": [[0, 1.83, 56.16]]}, {"timestamp": 1578739494933, "ltp": 1.82, "tv": 20883.36, "trd": [[1.82, 3102.18]], "batb": [[0, 1.81, 1525], [1, 1.8, 2023], [2, 1.79, 1477.84]], "batl": NaN}, {"timestamp": 1578739501942, "ltp": 1.82, "tv": 20883.36, "trd": NaN, "batb": NaN, "batl": [[0, 1.82, 220.9], [1, 1.83, 56.16], [2, 1.84, 213.4]]}, {"timestamp": 1578739502942, "ltp": 1.82, "tv": 20891.36, "trd": [[1.82, 3110.18]], "batb": [[0, 1.81, 1500], [2, 1.79, 1500.84]], "batl": [[0, 1.82, 216.9], [1, 1.83, 109.16], [2, 1.84, 67.65]]}, {"timestamp": 1578739503943, "ltp": 1.82, "tv": 20891.36, "trd": NaN, "batb": NaN, "batl": [[0, 1.82, 480.32], [2, 1.84, 62]]}, {"timestamp": 1578739510856, "ltp": 1.81, "tv": 21891.36, "trd": [[1.81, 1020]], "batb": [[0, 1.81, 1000]], "batl": NaN}, {"timestamp": 1578739511951, "ltp": 1.81, "tv": 21891.36, "trd": NaN, "batb": NaN, "batl": [[0, 1.82, 263.42]]}, {"timestamp": 1578739513957, "ltp": 1.81, "tv": 22591.36, "trd": [[1.81, 1720]], "batb": [[0, 1.81, 650]], "batl": NaN}, {"timestamp": 1578739515955, "ltp": 1.81, "tv": 22667.92, "trd": [[1.81, 1796.56]], "batb": [[0, 1.81, 611.72]], "batl": NaN}, {"timestamp": 1578739517851, "ltp": 1.81, "tv": 22744.48, "trd": [[1.81, 1873.12]], "batb": [[0, 1.81, 1572.44]], "batl": NaN}, {"timestamp": 1578739522979, "ltp": 1.81, "tv": 22754.12, "trd": [[1.81, 1882.76]], "batb": [[0, 1.81, 1562.8]], "batl": NaN}, {"timestamp": 1578739523977, "ltp": 1.81, "tv": 22770.47, "trd": [[1.81, 1899.11]], "batb": [[0, 1.81, 1546.45]], "batl": NaN}, {"timestamp": 1578739525961, "ltp": 1.81, "tv": 22776.67, "trd": [[1.81, 1905.31]], "batb": [[0, 1.81, 1540.25]], "batl": NaN}, {"timestamp": 1578739554004, "ltp": 1.82, "tv": 22786.87, "trd": [[1.82, 3120.38]], "batb": NaN, "batl": [[0, 1.82, 258.32]]}, {"timestamp": 1578739588984, "ltp": 1.82, "tv": 22786.87, "trd": NaN, "batb": [[1, 1.8, 2040.02]], "batl": NaN}, {"timestamp": 1578739591977, "ltp": 1.82, "tv": 22790.87, "trd": [[1.82, 3124.38]], "batb": NaN, "batl": [[0, 1.82, 256.32]]}, {"timestamp": 1578739601597, "ltp": 1.81, "tv": 25790.87, "trd": [[1.81, 4905.31]], "batb": [[0, 1.81, 40.25]], "batl": NaN}, {"timestamp": 1578739604002, "ltp": 1.81, "tv": 25871.37, "trd": [[1.81, 4985.81]], "batb": [[0, 1.8, 2040.02], [1, 1.79, 1500.84], [2, 1.78, 1914.63]], "batl": [[0, 1.81, 9.75], [1, 1.82, 256.32], [2, 1.83, 109.16]]}, {"timestamp": 1578739604999, "ltp": 1.81, "tv": 25871.37, "trd": NaN, "batb": [[2, 1.78, 1891.63]], "batl": [[0, 1.82, 256.32], [1, 1.83, 109.16], [2, 1.84, 62]]}, {"timestamp": 1578739605904, "ltp": 1.81, "tv": 25871.37, "trd": NaN, "batb": [[1, 1.79, 1529.11]], "batl": NaN}, {"timestamp": 1578739611993, "ltp": 1.81, "tv": 25901.99, "trd": [[1.81, 5016.43]], "batb": [[0, 1.81, 2484.69], [1, 1.8, 2040.02], [2, 1.79, 1529.11]], "batl": NaN}, {"timestamp": 1578739646972, "ltp": 1.81, "tv": 25901.99, "trd": NaN, "batb": [[0, 1.81, 2489.69]], "batl": [[2, 1.84, 67]]}, {"timestamp": 1578739671574, "ltp": 1.81, "tv": 27604.41, "trd": [[1.81, 6718.85]], "batb": [[0, 1.81, 1638.48]], "batl": NaN}, {"timestamp": 1578739678904, "ltp": 1.81, "tv": 27604.41, "trd": NaN, "batb": [[0, 1.81, 2338.48]], "batl": NaN}, {"timestamp": 1578739684802, "ltp": 1.81, "tv": 27753.1, "trd": [[1.81, 6867.54]], "batb": [[0, 1.81, 2189.79], [1, 1.8, 2048.02], [2, 1.79, 1537.11]], "batl": NaN}, {"timestamp": 1578739686804, "ltp": 1.81, "tv": 27759.32, "trd": [[1.81, 6873.76]], "batb": [[0, 1.81, 2183.57]], "batl": NaN}, {"timestamp": 1578739687907, "ltp": 1.81, "tv": 27759.32, "trd": NaN, "batb": NaN, "batl": [[1, 1.83, 91.28]]}, {"timestamp": 1578739690840, "ltp": 1.81, "tv": 27759.32, "trd": NaN, "batb": [[0, 1.81, 3182.57]], "batl": NaN}, {"timestamp": 1578739728982, "ltp": 1.81, "tv": 27759.32, "trd": NaN, "batb": [[0, 1.81, 3217.57], [2, 1.79, 1506.11]], "batl": NaN}, {"timestamp": 1578739729982, "ltp": 1.81, "tv": 27759.32, "trd": NaN, "batb": [[2, 1.79, 1477.84]], "batl": NaN}, {"timestamp": 1578739736894, "ltp": 1.82, "tv": 28029.58, "trd": [[1.82, 3394.64]], "batb": NaN, "batl": [[0, 1.82, 121.19]]}, {"timestamp": 1578739738002, "ltp": 1.82, "tv": 28029.58, "trd": NaN, "batb": NaN, "batl": [[0, 1.82, 5.12]]}, {"timestamp": 1578739738994, "ltp": 1.82, "tv": 28029.58, "trd": NaN, "batb": NaN, "batl": [[1, 1.83, 206.71]]}, {"timestamp": 1578739767934, "ltp": 1.82, "tv": 28029.58, "trd": NaN, "batb": NaN, "batl": [[2, 1.84, 83]]}, {"timestamp": 1578739776966, "ltp": 1.81, "tv": 28033.58, "trd": [[1.81, 6877.76]], "batb": [[0, 1.81, 3215.57]], "batl": NaN}, {"timestamp": 1578739787975, "ltp": 1.81, "tv": 28033.58, "trd": NaN, "batb": NaN, "batl": [[1, 1.83, 168.43]]}, {"timestamp": 1578739800669, "ltp": 1.8, "tv": 28187.58, "trd": [[1.8, 358], [1.81, 7027.76]], "batb": [[0, 1.8, 46.02], [1, 1.79, 1477.84], [2, 1.78, 1891.63]], "batl": [[0, 1.81, 25], [1, 1.82, 5.12], [2, 1.83, 168.43]]}, {"timestamp": 1578739801973, "ltp": 1.8, "tv": 28237.88, "trd": [[1.8, 408.3]], "batb": [[0, 1.8, 20.87], [1, 1.79, 1511.84]], "batl": [[0, 1.82, 73.24], [1, 1.83, 168.43], [2, 1.84, 83]]}, {"timestamp": 1578739802966, "ltp": 1.81, "tv": 28290.72, "trd": [[1.81, 7080.6]], "batb": [[0, 1.81, 7.7], [1, 1.8, 46.87], [2, 1.79, 1477.84]], "batl": [[0, 1.82, 42.54]]}, {"timestamp": 1578739803968, "ltp": 1.8, "tv": 28313.82, "trd": [[1.8, 416], [1.81, 7096]], "batb": [[0, 1.8, 43.02], [1, 1.79, 1510.84], [2, 1.78, 1924.63]], "batl": [[0, 1.82, 61.2]]}, {"timestamp": 1578739805964, "ltp": 1.8, "tv": 28313.82, "trd": NaN, "batb": [[2, 1.78, 1891.63]], "batl": [[0, 1.82, 5.12]]}, {"timestamp": 1578739818990, "ltp": 1.8, "tv": 28313.82, "trd": NaN, "batb": NaN, "batl": [[0, 1.82, 25.12]]}, {"timestamp": 1578739822912, "ltp": 1.8, "tv": 28313.82, "trd": NaN, "batb": NaN, "batl": [[0, 1.81, 150], [1, 1.82, 25.12], [2, 1.83, 168.43]]}, {"timestamp": 1578739823909, "ltp": 1.8, "tv": 28313.82, "trd": NaN, "batb": NaN, "batl": [[1, 1.82, 93.34], [2, 1.83, 53]]}, {"timestamp": 1578739825003, "ltp": 1.8, "tv": 28463.86, "trd": [[1.8, 566.04]], "batb": [[0, 1.79, 1510.84], [1, 1.78, 1923.63], [2, 1.77, 999]], "batl": [[0, 1.8, 42.34], [1, 1.81, 219], [2, 1.82, 93.34]]}, {"timestamp": 1578739825935, "ltp": 1.8, "tv": 28463.86, "trd": NaN, "batb": NaN, "batl": [[0, 1.8, 47.51], [2, 1.82, 88.22]]}, {"timestamp": 1578739828920, "ltp": 1.79, "tv": 31463.86, "trd": [[1.79, 3040]], "batb": [[0, 1.79, 31]], "batl": NaN}, {"timestamp": 1578739832918, "ltp": 1.79, "tv": 31463.86, "trd": NaN, "batb": NaN, "batl": [[2, 1.82, 68.22]]}, {"timestamp": 1578739841941, "ltp": 1.79, "tv": 31463.86, "trd": NaN, "batb": [[0, 1.79, 2531]], "batl": NaN}, {"timestamp": 1578739847844, "ltp": 1.79, "tv": 31463.86, "trd": NaN, "batb": [[0, 1.79, 3031]], "batl": NaN}, {"timestamp": 1578739849945, "ltp": 1.79, "tv": 31463.86, "trd": NaN, "batb": [[1, 1.78, 2073.63]], "batl": NaN}, {"timestamp": 1578739852943, "ltp": 1.8, "tv": 31558.89, "trd": [[1.8, 661.07]], "batb": [[0, 1.8, 3483.48], [1, 1.79, 3031], [2, 1.78, 2073.63]], "batl": [[0, 1.81, 219], [1, 1.82, 68.22], [2, 1.83, 53]]}, {"timestamp": 1578739853765, "ltp": 1.8, "tv": 31558.89, "trd": NaN, "batb": [[2, 1.78, 2041.63]], "batl": [[0, 1.81, 150]]}, {"timestamp": 1578739897002, "ltp": 1.81, "tv": 31598.89, "trd": [[1.81, 7136]], "batb": NaN, "batl": [[0, 1.81, 130]]}, {"timestamp": 1578739929962, "ltp": 1.81, "tv": 31598.89, "trd": NaN, "batb": NaN, "batl": [[1, 1.82, 85.24], [2, 1.83, 70]]}, {"timestamp": 1578739943992, "ltp": 1.81, "tv": 31609.29, "trd": [[1.81, 7146.4]], "batb": NaN, "batl": [[0, 1.81, 124.8]]}, {"timestamp": 1578739960914, "ltp": 1.81, "tv": 31609.29, "trd": NaN, "batb": [[0, 1.8, 3485.48]], "batl": NaN}, {"timestamp": 1578739987949, "ltp": 1.81, "tv": 31617.7, "trd": [[1.81, 7154.8]], "batb": NaN, "batl": [[0, 1.81, 120.6]]}, {"timestamp": 1578740001966, "ltp": 1.8, "tv": 33320.11, "trd": [[1.8, 2363.49]], "batb": [[0, 1.8, 2634.27]], "batl": NaN}, {"timestamp": 1578740006960, "ltp": 1.81, "tv": 33330.51, "trd": [[1.81, 7165.2]], "batb": NaN, "batl": [[0, 1.81, 115.4]]}, {"timestamp": 1578740017910, "ltp": 1.72, "tv": 35337.81, "trd": [[1.72, 47.08], [1.73, 459.5], [1.75, 176.89], [1.76, 23.05], [1.77, 7.41], [1.78, 315.87], [1.79, 4241.71], [1.8, 2505.49]], "batb": [[0, 1.72, 56.39], [1, 1.68, 50.9], [2, 1.66, 2]], "batl": [[0, 1.8, 111.5], [1, 1.81, 195.4], [2, 1.82, 85.24]]}, {"timestamp": 1578740019002, "ltp": 1.73, "tv": 35677.09, "trd": [[1.7, 1081.77], [1.72, 171.02], [1.73, 517.94], [1.74, 318.63], [1.78, 385.87], [1.79, 4311.7]], "batb": [[0, 1.7, 33.22]], "batl": [[0, 1.79, 143.51], [1, 1.8, 16.5], [2, 1.81, 195.4]]}, {"timestamp": 1578740019998, "ltp": 1.71, "tv": 35792.47, "trd": [[1.7, 1162.91], [1.71, 272.71]], "batb": [[0, 1.71, 16.1], [1, 1.7, 21.91], [2, 1.69, 34.12]], "batl": [[0, 1.77, 82.22], [1, 1.78, 75.52], [2, 1.79, 81.96]]}, {"timestamp": 1578740020988, "ltp": 1.71, "tv": 35887.59, "trd": [[1.7, 1168.95], [1.71, 353.43], [1.72, 179.38]], "batb": [[0, 1.71, 20], [1, 1.7, 36.06]], "batl": [[0, 1.74, 84.22], [1, 1.75, 76.05], [2, 1.77, 100.36]]}, {"timestamp": 1578740021981, "ltp": 1.7, "tv": 35994.16, "trd": [[1.7, 1194.39], [1.71, 415.43], [1.73, 532.86], [1.74, 322.85]], "batb": [[0, 1.71, 30.22], [1, 1.7, 23.34]], "batl": [[0, 1.74, 82.11]]}, {"timestamp": 1578740022914, "ltp": 1.7, "tv": 36165.37, "trd": [[1.7, 1245.16], [1.71, 535.87]], "batb": [[0, 1.68, 50.9], [1, 1.66, 2], [2, 1.63, 184.57]], "batl": [[0, 1.71, 1465.78], [1, 1.72, 26.29], [2, 1.73, 16.65]]}, {"timestamp": 1578740024905, "ltp": 1.7, "tv": 36165.37, "trd": NaN, "batb": NaN, "batl": [[0, 1.73, 16.65], [1, 1.74, 25], [2, 1.75, 76.05]]}, {"timestamp": 1578740025893, "ltp": 1.7, "tv": 36165.37, "trd": NaN, "batb": NaN, "batl": [[0, 1.78, 30.29], [1, 1.79, 62.37], [2, 1.8, 16.5]]}, {"timestamp": 1578740026995, "ltp": 1.7, "tv": 36165.37, "trd": NaN, "batb": [[0, 1.66, 2.9], [1, 1.63, 184.57], [2, 1.62, 612.24]], "batl": [[0, 1.76, 37.46], [1, 1.78, 51.02], [2, 1.79, 62.37]]}, {"timestamp": 1578740027989, "ltp": 1.7, "tv": 36165.37, "trd": NaN, "batb": NaN, "batl": [[0, 1.75, 14.02], [1, 1.76, 37.46], [2, 1.78, 51.02]]}, {"timestamp": 1578740028926, "ltp": 1.7, "tv": 36165.37, "trd": NaN, "batb": NaN, "batl": [[1, 1.76, 31.29], [2, 1.78, 30.29]]}, {"timestamp": 1578740029916, "ltp": 1.76, "tv": 36207.37, "trd": [[1.75, 204.93], [1.76, 37.01]], "batb": [[0, 1.67, 26.19], [1, 1.66, 2], [2, 1.63, 184.57]], "batl": [[0, 1.78, 77], [1, 1.79, 62.37], [2, 1.8, 16.5]]}, {"timestamp": 1578740032922, "ltp": 1.76, "tv": 36207.37, "trd": NaN, "batb": [[0, 1.73, 40.52], [1, 1.72, 251.58], [2, 1.66, 2.9]], "batl": NaN}, {"timestamp": 1578740034955, "ltp": 1.76, "tv": 36207.37, "trd": NaN, "batb": NaN, "batl": [[0, 1.77, 82.29], [1, 1.78, 77], [2, 1.79, 62.37]]}, {"timestamp": 1578740036946, "ltp": 1.76, "tv": 36207.37, "trd": NaN, "batb": [[0, 1.73, 49.38]], "batl": [[0, 1.76, 13.08], [1, 1.77, 82.29], [2, 1.78, 77]]}, {"timestamp": 1578740037635, "ltp": 1.76, "tv": 36207.37, "trd": NaN, "batb": NaN, "batl": [[0, 1.76, 90.37]]}, {"timestamp": 1578740042972, "ltp": 1.73, "tv": 36236.82, "trd": [[1.73, 562.31]], "batb": [[0, 1.73, 13.13], [1, 1.72, 19.29]], "batl": [[0, 1.75, 129.46], [1, 1.76, 100.43], [2, 1.77, 82.29]]}, {"timestamp": 1578740044970, "ltp": 1.73, "tv": 36236.82, "trd": NaN, "batb": [[0, 1.67, 19.19], [1, 1.66, 2], [2, 1.64, 158]], "batl": [[1, 1.76, 87.34]]}, {"timestamp": 1578740045959, "ltp": 1.73, "tv": 36236.82, "trd": NaN, "batb": [[0, 1.73, 14.23], [1, 1.72, 3018], [2, 1.71, 18.29]], "batl": [[0, 1.74, 12.77], [1, 1.75, 129.46], [2, 1.76, 87.34]]}, {"timestamp": 1578740046958, "ltp": 1.73, "tv": 36236.82, "trd": NaN, "batb": NaN, "batl": [[0, 1.74, 26.37]]}, {"timestamp": 1578740048983, "ltp": 1.74, "tv": 36270.82, "trd": [[1.74, 356.85]], "batb": NaN, "batl": [[0, 1.74, 23.09]]}, {"timestamp": 1578740052950, "ltp": 1.73, "tv": 36282.82, "trd": [[1.73, 574.31]], "batb": [[0, 1.73, 8.23]], "batl": NaN}, {"timestamp": 1578740055980, "ltp": 1.73, "tv": 36282.82, "trd": NaN, "batb": [[0, 1.73, 2208.23]], "batl": NaN}, {"timestamp": 1578740057973, "ltp": 1.73, "tv": 36282.82, "trd": NaN, "batb": NaN, "batl": [[0, 1.74, 43.09]]}, {"timestamp": 1578740060990, "ltp": 1.73, "tv": 36282.82, "trd": NaN, "batb": NaN, "batl": [[0, 1.74, 23.09]]}, {"timestamp": 1578740063981, "ltp": 1.74, "tv": 36291.33, "trd": [[1.74, 365.36]], "batb": NaN, "batl": [[0, 1.74, 18.84]]}, {"timestamp": 1578740067003, "ltp": 1.74, "tv": 36291.33, "trd": NaN, "batb": [[2, 1.71, 2018.29]], "batl": NaN}, {"timestamp": 1578740069000, "ltp": 1.74, "tv": 36291.33, "trd": NaN, "batb": [[0, 1.74, 18.29], [1, 1.73, 2208.23], [2, 1.72, 3018]], "batl": [[0, 1.78, 66.29], [1, 1.79, 62.37], [2, 1.8, 16.5]]}, {"timestamp": 1578740069886, "ltp": 1.73, "tv": 36591.33, "trd": [[1.73, 837.73], [1.74, 401.94]], "batb": [[0, 1.74, 17], [1, 1.73, 2076.52]], "batl": NaN}, {"timestamp": 1578740073982, "ltp": 1.73, "tv": 36591.33, "trd": NaN, "batb": [[0, 1.73, 2107.77], [1, 1.72, 3018], [2, 1.71, 2018.29]], "batl": NaN}, {"timestamp": 1578740083921, "ltp": 1.73, "tv": 36591.33, "trd": NaN, "batb": [[0, 1.74, 17.04], [1, 1.73, 2093.52], [2, 1.72, 3018]], "batl": NaN}, {"timestamp": 1578740084912, "ltp": 1.73, "tv": 37231.33, "trd": [[1.73, 1443.65], [1.74, 436.02]], "batb": [[0, 1.73, 1790.56], [1, 1.72, 3018], [2, 1.71, 2018.29]], "batl": NaN}, {"timestamp": 1578740086004, "ltp": 1.73, "tv": 37231.33, "trd": NaN, "batb": [[0, 1.74, 17.12], [1, 1.73, 1790.56], [2, 1.72, 3018]], "batl": NaN}, {"timestamp": 1578740088812, "ltp": 1.73, "tv": 37231.33, "trd": NaN, "batb": NaN, "batl": [[0, 1.78, 216.29]]}, {"timestamp": 1578740090003, "ltp": 1.73, "tv": 37231.33, "trd": NaN, "batb": NaN, "batl": [[0, 1.78, 266.29]]}, {"timestamp": 1578740092933, "ltp": 1.73, "tv": 37231.33, "trd": NaN, "batb": [[0, 1.73, 1790.56], [1, 1.72, 3018], [2, 1.71, 2000]], "batl": [[0, 1.75, 8.81], [1, 1.76, 70.27], [2, 1.77, 66.12]]}, {"timestamp": 1578740095902, "ltp": 1.76, "tv": 37286.2, "trd": [[1.75, 240.48], [1.76, 56.33]], "batb": NaN, "batl": [[0, 1.76, 60.61], [1, 1.77, 66.12], [2, 1.78, 266.29]]}, {"timestamp": 1578740096904, "ltp": 1.76, "tv": 37359.32, "trd": [[1.75, 257.56], [1.76, 112.37]], "batb": [[0, 1.74, 247.18], [1, 1.73, 1790.56], [2, 1.72, 3000]], "batl": [[0, 1.77, 66.87], [1, 1.78, 266.29], [2, 1.79, 62.37]]}, {"timestamp": 1578740097851, "ltp": 1.76, "tv": 37360.82, "trd": [[1.76, 113.87]], "batb": [[0, 1.76, 13.02], [1, 1.75, 17.12], [2, 1.74, 247.18]], "batl": [[0, 1.78, 266.29], [1, 1.79, 127.37], [2, 1.8, 16.5]]}, {"timestamp": 1578740102965, "ltp": 1.76, "tv": 37360.82, "trd": NaN, "batb": [[1, 1.75, 67.12], [2, 1.74, 297.18]], "batl": NaN}, {"timestamp": 1578740107968, "ltp": 1.76, "tv": 37360.82, "trd": NaN, "batb": NaN, "batl": [[0, 1.77, 20], [1, 1.78, 266.29], [2, 1.79, 127.37]]}, {"timestamp": 1578740108965, "ltp": 1.76, "tv": 37360.82, "trd": NaN, "batb": NaN, "batl": [[0, 1.77, 86.12], [2, 1.79, 62.37]]}, {"timestamp": 1578740110971, "ltp": 1.75, "tv": 37514.82, "trd": [[1.75, 385.52], [1.76, 139.91]], "batb": [[0, 1.75, 3.14], [1, 1.74, 280.06], [2, 1.73, 1823.56]], "batl": NaN}, {"timestamp": 1578740118879, "ltp": 1.74, "tv": 38054.81, "trd": [[1.74, 969.73], [1.75, 391.8]], "batb": [[0, 1.74, 13.2], [1, 1.73, 1823.56], [2, 1.72, 3070]], "batl": NaN}, {"timestamp": 1578740119973, "ltp": 1.76, "tv": 38163.89, "trd": [[1.76, 248.98]], "batb": NaN, "batl": [[0, 1.76, 35.39], [1, 1.77, 303.83], [2, 1.78, 266.29]]}, {"timestamp": 1578740121900, "ltp": 1.76, "tv": 38163.89, "trd": NaN, "batb": NaN, "batl": [[0, 1.76, 98.66]]}, {"timestamp": 1578740122791, "ltp": 1.76, "tv": 38163.89, "trd": NaN, "batb": [[0, 1.74, 14.09]], "batl": [[1, 1.77, 283.83]]}, {"timestamp": 1578740124976, "ltp": 1.76, "tv": 38163.89, "trd": NaN, "batb": NaN, "batl": [[0, 1.76, 96.39]]}, {"timestamp": 1578740128898, "ltp": 1.73, "tv": 38180.05, "trd": [[1.73, 1443.79], [1.74, 985.75]], "batb": [[0, 1.74, 14.17], [1, 1.73, 1823.49]], "batl": NaN}, {"timestamp": 1578740134906, "ltp": 1.73, "tv": 38180.05, "trd": NaN, "batb": [[0, 1.74, 34.17]], "batl": NaN}, {"timestamp": 1578740135802, "ltp": 1.73, "tv": 38180.05, "trd": NaN, "batb": [[0, 1.74, 2034.17]], "batl": NaN}, {"timestamp": 1578740136499, "ltp": 1.75, "tv": 38190.45, "trd": [[1.75, 402.2]], "batb": NaN, "batl": [[0, 1.75, 34.8], [1, 1.76, 106.39], [2, 1.77, 283.83]]}, {"timestamp": 1578740141886, "ltp": 1.75, "tv": 38274.95, "trd": [[1.75, 486.7]], "batb": [[0, 1.75, 562.54], [1, 1.74, 2034.17], [2, 1.73, 1823.49]], "batl": [[0, 1.76, 106.39], [1, 1.77, 283.83], [2, 1.78, 66.29]]}, {"timestamp": 1578740142991, "ltp": 1.75, "tv": 38274.95, "trd": NaN, "batb": NaN, "batl": [[0, 1.76, 45.39], [1, 1.77, 287.22]]}, {"timestamp": 1578740146923, "ltp": 1.75, "tv": 39384.95, "trd": [[1.75, 1596.7]], "batb": [[0, 1.75, 7.54]], "batl": [[0, 1.76, 35.39]]}, {"timestamp": 1578740151733, "ltp": 1.75, "tv": 39386.52, "trd": [[1.75, 1598.27]], "batb": [[0, 1.75, 7.97]], "batl": [[1, 1.77, 283.83]]}, {"timestamp": 1578740157912, "ltp": 1.75, "tv": 39386.52, "trd": NaN, "batb": [[0, 1.75, 2007.97]], "batl": NaN}, {"timestamp": 1578740158963, "ltp": 1.76, "tv": 39390.52, "trd": [[1.76, 252.98]], "batb": [[0, 1.75, 2005.97]], "batl": [[0, 1.76, 33.39]]}, {"timestamp": 1578740162921, "ltp": 1.76, "tv": 39457.32, "trd": [[1.76, 319.78]], "batb": [[0, 1.76, 2188.59], [1, 1.75, 2005.97], [2, 1.74, 2034.17]], "batl": [[0, 1.77, 283.83], [1, 1.78, 66.29], [2, 1.79, 118.37]]}, {"timestamp": 1578740163949, "ltp": 1.76, "tv": 39457.32, "trd": NaN, "batb": NaN, "batl": [[2, 1.79, 62.37]]}, {"timestamp": 1578740165942, "ltp": 1.76, "tv": 39457.32, "trd": NaN, "batb": NaN, "batl": [[0, 1.77, 66.12], [1, 1.78, 282.79]]}, {"timestamp": 1578740166419, "ltp": 1.76, "tv": 39457.32, "trd": NaN, "batb": NaN, "batl": [[0, 1.78, 282.79], [1, 1.79, 118.37], [2, 1.8, 16.5]]}, {"timestamp": 1578740169648, "ltp": 1.77, "tv": 39463.29, "trd": [[1.77, 13.38]], "batb": [[1, 1.75, 2000]], "batl": NaN}, {"timestamp": 1578740186997, "ltp": 1.77, "tv": 39463.29, "trd": NaN, "batb": [[0, 1.76, 2193.59]], "batl": NaN}, {"timestamp": 1578740188000, "ltp": 1.77, "tv": 39473.55, "trd": [[1.77, 23.64]], "batb": [[0, 1.77, 2211.74], [1, 1.76, 2193.59], [2, 1.75, 2000]], "batl": [[0, 1.78, 216.5], [1, 1.79, 123.37], [2, 1.8, 71.66]]}, {"timestamp": 1578740188996, "ltp": 1.77, "tv": 39473.55, "trd": NaN, "batb": NaN, "batl": [[1, 1.79, 178.05]]}, {"timestamp": 1578740191004, "ltp": 1.77, "tv": 39473.55, "trd": NaN, "batb": [[0, 1.77, 2222.74]], "batl": NaN}, {"timestamp": 1578740195984, "ltp": 1.77, "tv": 39573.55, "trd": [[1.77, 123.64]], "batb": [[0, 1.77, 2172.74]], "batl": NaN}, {"timestamp": 1578740196988, "ltp": 1.77, "tv": 39873.55, "trd": [[1.77, 423.64]], "batb": [[0, 1.77, 2022.74]], "batl": NaN}, {"timestamp": 1578740197611, "ltp": 1.77, "tv": 39973.55, "trd": [[1.77, 523.64]], "batb": [[0, 1.77, 1972.74]], "batl": NaN}, {"timestamp": 1578740200981, "ltp": 1.77, "tv": 39994.8, "trd": [[1.77, 544.89]], "batb": [[0, 1.77, 1951.49]], "batl": NaN}, {"timestamp": 1578740201919, "ltp": 1.77, "tv": 39994.8, "trd": NaN, "batb": NaN, "batl": [[0, 1.79, 393.34], [1, 1.8, 71.66], [2, 1.81, 55.16]]}, {"timestamp": 1578740202922, "ltp": 1.77, "tv": 39994.8, "trd": NaN, "batb": NaN, "batl": [[0, 1.79, 338.66], [1, 1.8, 87.25]]}, {"timestamp": 1578740204923, "ltp": 1.77, "tv": 40002.23, "trd": [[1.77, 552.32]], "batb": [[0, 1.77, 1944.06]], "batl": NaN}, {"timestamp": 1578740205936, "ltp": 1.77, "tv": 40024.23, "trd": [[1.77, 574.32]], "batb": [[0, 1.76, 5], [1, 1.74, 34.17], [2, 1.73, 50]], "batl": [[0, 1.77, 89], [1, 1.79, 338.66], [2, 1.8, 87.25]]}, {"timestamp": 1578740206980, "ltp": 1.77, "tv": 40756.72, "trd": [[1.69, 5176.97], [1.7, 1607.22], [1.72, 183.04], [1.76, 329.78], [1.77, 874.32]], "batb": [[0, 1.66, 2], [1, 1.6, 29.82], [2, 1.59, 86.8]], "batl": [[0, 1.75, 104.8], [1, 1.76, 125.75], [2, 1.77, 439]]}, {"timestamp": 1578740207978, "ltp": 1.77, "tv": 40756.72, "trd": NaN, "batb": NaN, "batl": [[0, 1.69, 461.24], [1, 1.74, 61.05], [2, 1.75, 104.8]]}, {"timestamp": 1578740208932, "ltp": 1.77, "tv": 40756.72, "trd": NaN, "batb": [[1, 1.61, 24.73], [2, 1.6, 29.82]], "batl": [[0, 1.69, 524.24], [1, 1.73, 65.44], [2, 1.74, 39.36]]}, {"timestamp": 1578740209977, "ltp": 1.69, "tv": 41280.38, "trd": [[1.69, 5700.63]], "batb": NaN, "batl": [[0, 1.69, 262.41], [1, 1.73, 130.88]]}, {"timestamp": 1578740212817, "ltp": 1.69, "tv": 41280.38, "trd": NaN, "batb": NaN, "batl": [[0, 1.69, 612.41], [1, 1.73, 380.88]]}, {"timestamp": 1578740215912, "ltp": 1.69, "tv": 41280.38, "trd": NaN, "batb": NaN, "batl": [[2, 1.74, 189.36]]}, {"timestamp": 1578740217821, "ltp": 1.69, "tv": 41280.38, "trd": NaN, "batb": NaN, "batl": [[1, 1.73, 315.44]]}, {"timestamp": 1578740218708, "ltp": 1.69, "tv": 41280.38, "trd": NaN, "batb": [[1, 1.61, 179.73]], "batl": [[0, 1.69, 549.41], [1, 1.7, 19.12], [2, 1.73, 315.44]]}, {"timestamp": 1578740220861, "ltp": 1.69, "tv": 41280.38, "trd": NaN, "batb": NaN, "batl": [[1, 1.7, 169.12]]}, {"timestamp": 1578740222914, "ltp": 1.69, "tv": 41284.88, "trd": [[1.69, 5705.13]], "batb": NaN, "batl": [[0, 1.69, 212.91]]}, {"timestamp": 1578740223710, "ltp": 1.69, "tv": 41284.88, "trd": NaN, "batb": NaN, "batl": [[1, 1.7, 19.12]]}, {"timestamp": 1578740230908, "ltp": 1.69, "tv": 41284.88, "trd": NaN, "batb": NaN, "batl": [[0, 1.69, 194.91], [2, 1.73, 65.44]]}, {"timestamp": 1578740237830, "ltp": 1.69, "tv": 41284.88, "trd": NaN, "batb": NaN, "batl": [[0, 1.69, 211.91]]}, {"timestamp": 1578740238819, "ltp": 1.69, "tv": 41284.88, "trd": NaN, "batb": [[1, 1.61, 186.73]], "batl": [[0, 1.69, 439.93]]}, {"timestamp": 1578740239972, "ltp": 1.69, "tv": 41284.88, "trd": NaN, "batb": NaN, "batl": [[0, 1.68, 15.12], [1, 1.69, 439.93], [2, 1.7, 19.12]]}, {"timestamp": 1578740240862, "ltp": 1.69, "tv": 41284.88, "trd": NaN, "batb": [[0, 1.66, 16.74], [1, 1.65, 3000], [2, 1.61, 186.73]], "batl": [[0, 1.69, 439.93], [1, 1.7, 19.12], [2, 1.73, 65.44]]}, {"timestamp": 1578740241953, "ltp": 1.69, "tv": 41284.88, "trd": NaN, "batb": NaN, "batl": [[0, 1.69, 422.93]]}, {"timestamp": 1578740242935, "ltp": 1.69, "tv": 41284.88, "trd": NaN, "batb": NaN, "batl": [[0, 1.69, 772.93]]}, {"timestamp": 1578740243977, "ltp": 1.69, "tv": 41284.88, "trd": NaN, "batb": NaN, "batl": [[0, 1.69, 787.93], [1, 1.7, 169.12]]}, {"timestamp": 1578740244961, "ltp": 1.69, "tv": 41284.88, "trd": NaN, "batb": NaN, "batl": [[1, 1.7, 164], [2, 1.73, 115.44]]}, {"timestamp": 1578740246945, "ltp": 1.69, "tv": 41284.88, "trd": NaN, "batb": [[0, 1.66, 2516.74]], "batl": NaN}, {"timestamp": 1578740247881, "ltp": 1.69, "tv": 41284.88, "trd": NaN, "batb": NaN, "batl": [[0, 1.69, 422.93], [1, 1.7, 14]]}, {"timestamp": 1578740248983, "ltp": 1.69, "tv": 41284.88, "trd": NaN, "batb": [[0, 1.68, 10], [1, 1.66, 2516.74], [2, 1.65, 3000]], "batl": [[0, 1.69, 436.93], [2, 1.73, 65.44]]}, {"timestamp": 1578740249953, "ltp": 1.69, "tv": 41284.88, "trd": NaN, "batb": NaN, "batl": [[0, 1.69, 422.93], [2, 1.71, 14.12]]}, {"timestamp": 1578740250954, "ltp": 1.69, "tv": 41284.88, "trd": NaN, "batb": [[1, 1.67, 6], [2, 1.66, 2516.74]], "batl": NaN}, {"timestamp": 1578740252984, "ltp": 1.69, "tv": 41284.88, "trd": NaN, "batb": [[1, 1.67, 2228]], "batl": NaN}, {"timestamp": 1578740257904, "ltp": 1.68, "tv": 41304.88, "trd": [[1.68, 22.74]], "batb": [[0, 1.67, 2228], [1, 1.66, 2516.74], [2, 1.65, 3000]], "batl": [[0, 1.68, 40], [1, 1.69, 436.93], [2, 1.7, 14]]}, {"timestamp": 1578740262988, "ltp": 1.68, "tv": 41384.88, "trd": [[1.68, 102.74]], "batb": [[0, 1.68, 2290], [1, 1.67, 2228], [2, 1.66, 2516.74]], "batl": [[0, 1.69, 436.93], [1, 1.7, 14], [2, 1.71, 14.12]]}, {"timestamp": 1578740263917, "ltp": 1.68, "tv": 41384.88, "trd": NaN, "batb": NaN, "batl": [[0, 1.69, 194.91]]}, {"timestamp": 1578740269895, "ltp": 1.68, "tv": 41384.88, "trd": NaN, "batb": NaN, "batl": [[1, 1.7, 240.69]]}, {"timestamp": 1578740273915, "ltp": 1.68, "tv": 41384.88, "trd": NaN, "batb": NaN, "batl": [[1, 1.7, 260.14]]}, {"timestamp": 1578740280938, "ltp": 1.68, "tv": 41384.88, "trd": NaN, "batb": NaN, "batl": [[1, 1.7, 240.69]]}, {"timestamp": 1578740283902, "ltp": 1.69, "tv": 41774.7, "trd": [[1.69, 6094.95]], "batb": [[0, 1.69, 111.21], [1, 1.68, 2290], [2, 1.67, 2228]], "batl": [[0, 1.7, 226.69], [1, 1.71, 14.12], [2, 1.72, 17.19]]}, {"timestamp": 1578740284836, "ltp": 1.69, "tv": 41774.7, "trd": NaN, "batb": NaN, "batl": [[0, 1.7, 251.16], [1, 1.71, 63.07]]}, {"timestamp": 1578740285820, "ltp": 1.69, "tv": 41774.7, "trd": NaN, "batb": NaN, "batl": [[0, 1.7, 24.47]]}, {"timestamp": 1578740288920, "ltp": 1.69, "tv": 41774.7, "trd": NaN, "batb": NaN, "batl": [[0, 1.71, 63.07], [1, 1.72, 17.19], [2, 1.74, 39.36]]}, {"timestamp": 1578740289912, "ltp": 1.69, "tv": 41997.12, "trd": [[1.69, 6317.37]], "batb": [[0, 1.68, 2290], [1, 1.67, 2228], [2, 1.66, 2516.74]], "batl": [[0, 1.69, 38.79], [1, 1.71, 63.07], [2, 1.72, 39.88]]}, {"timestamp": 1578740290903, "ltp": 1.69, "tv": 41997.12, "trd": NaN, "batb": NaN, "batl": [[0, 1.71, 63.07], [1, 1.72, 39.88], [2, 1.74, 39.36]]}, {"timestamp": 1578740291847, "ltp": 1.69, "tv": 41997.12, "trd": NaN, "batb": NaN, "batl": [[0, 1.71, 65.95]]}, {"timestamp": 1578740293917, "ltp": 1.69, "tv": 41997.12, "trd": NaN, "batb": [[0, 1.69, 4.26], [1, 1.68, 2290], [2, 1.67, 2228]], "batl": NaN}, {"timestamp": 1578740297919, "ltp": 1.69, "tv": 41997.12, "trd": NaN, "batb": [[0, 1.7, 4.26]], "batl": [[0, 1.72, 17.19], [1, 1.73, 17.19]]}, {"timestamp": 1578740298755, "ltp": 1.69, "tv": 41997.12, "trd": NaN, "batb": NaN, "batl": [[0, 1.73, 17.19], [1, 1.74, 39.36], [2, 1.76, 142]]}, {"timestamp": 1578740299955, "ltp": 1.69, "tv": 41997.12, "trd": NaN, "batb": NaN, "batl": [[0, 1.75, 17.19], [1, 1.76, 142], [2, 1.78, 6]]}, {"timestamp": 1578740300744, "ltp": 1.69, "tv": 41997.12, "trd": NaN, "batb": [[1, 1.69, 2500], [2, 1.68, 2290]], "batl": NaN}, {"timestamp": 1578740304753, "ltp": 1.69, "tv": 41997.12, "trd": NaN, "batb": [[0, 1.7, 2304.26]], "batl": NaN}, {"timestamp": 1578740308963, "ltp": 1.71, "tv": 42008.8, "trd": [[1.71, 547.55]], "batb": [[0, 1.71, 2288.32], [1, 1.7, 2304.26], [2, 1.69, 2500]], "batl": [[0, 1.77, 17.19], [1, 1.78, 146], [2, 1.79, 67.37]]}, {"timestamp": 1578740309948, "ltp": 1.71, "tv": 42025.47, "trd": [[1.71, 564.22]], "batb": [[0, 1.71, 2271.65]], "batl": NaN}, {"timestamp": 1578740310573, "ltp": 1.71, "tv": 42025.47, "trd": NaN, "batb": NaN, "batl": [[0, 1.76, 2.92], [1, 1.77, 17.19], [2, 1.78, 146]]}, {"timestamp": 1578740311817, "ltp": 1.71, "tv": 42025.47, "trd": NaN, "batb": [[0, 1.71, 2276.65]], "batl": [[0, 1.74, 5], [1, 1.75, 17.19], [2, 1.76, 2.92]]}, {"timestamp": 1578740313958, "ltp": 1.72, "tv": 42026.11, "trd": [[1.72, 183.68]], "batb": [[0, 1.72, 250.94], [1, 1.71, 2276.65], [2, 1.7, 2304.26]], "batl": [[2, 1.76, 20.11]]}, {"timestamp": 1578740318954, "ltp": 1.72, "tv": 42494.11, "trd": [[1.72, 651.68]], "batb": [[0, 1.72, 16.94]], "batl": NaN}, {"timestamp": 1578740319731, "ltp": 1.72, "tv": 42494.11, "trd": NaN, "batb": NaN, "batl": [[0, 1.74, 57.25], [1, 1.75, 51], [2, 1.76, 51]]}, {"timestamp": 1578740323956, "ltp": 1.72, "tv": 42494.11, "trd": NaN, "batb": [[0, 1.71, 2276.65], [1, 1.7, 2304.26], [2, 1.69, 2500]], "batl": [[0, 1.74, 5]]}, {"timestamp": 1578740327966, "ltp": 1.72, "tv": 42494.11, "trd": NaN, "batb": NaN, "batl": [[0, 1.72, 2], [1, 1.73, 57.25], [2, 1.74, 62.25]]}, {"timestamp": 1578740328956, "ltp": 1.72, "tv": 42498.11, "trd": [[1.72, 655.68]], "batb": [[0, 1.72, 2298], [1, 1.71, 2276.65], [2, 1.7, 2304.26]], "batl": [[0, 1.74, 5], [1, 1.75, 23.25], [2, 1.76, 23.25]]}, {"timestamp": 1578740329947, "ltp": 1.72, "tv": 42498.11, "trd": NaN, "batb": NaN, "batl": [[1, 1.75, 34.41]]}, {"timestamp": 1578740331976, "ltp": 1.72, "tv": 42498.11, "trd": NaN, "batb": NaN, "batl": [[1, 1.75, 23.25]]}, {"timestamp": 1578740332968, "ltp": 1.72, "tv": 42498.11, "trd": NaN, "batb": [[0, 1.72, 2303]], "batl": NaN}, {"timestamp": 1578740333860, "ltp": 1.72, "tv": 42498.11, "trd": NaN, "batb": [[0, 1.73, 2000], [1, 1.72, 2303], [2, 1.71, 2276.65]], "batl": NaN}, {"timestamp": 1578740338975, "ltp": 1.74, "tv": 42508.11, "trd": [[1.74, 995.75]], "batb": [[0, 1.74, 2295], [1, 1.73, 2000], [2, 1.72, 2303]], "batl": [[0, 1.77, 20.73], [1, 1.78, 67.25], [2, 1.79, 67.37]]}, {"timestamp": 1578740341990, "ltp": 1.74, "tv": 42508.11, "trd": NaN, "batb": [[0, 1.74, 2304.26], [2, 1.72, 2298]], "batl": NaN}, {"timestamp": 1578740343984, "ltp": 1.74, "tv": 42508.11, "trd": NaN, "batb": [[0, 1.75, 2000], [1, 1.74, 2304.26], [2, 1.73, 2000]], "batl": NaN}, {"timestamp": 1578740344879, "ltp": 1.74, "tv": 42508.11, "trd": NaN, "batb": [[0, 1.75, 2004.26], [1, 1.74, 2300]], "batl": [[2, 1.79, 128.37]]}, {"timestamp": 1578740345970, "ltp": 1.74, "tv": 42508.11, "trd": NaN, "batb": [[1, 1.74, 2300.89]], "batl": NaN}, {"timestamp": 1578740349004, "ltp": 1.74, "tv": 42508.11, "trd": NaN, "batb": [[0, 1.76, 4.26], [1, 1.75, 2000], [2, 1.74, 2295.89]], "batl": NaN}, {"timestamp": 1578740349997, "ltp": 1.77, "tv": 42518.11, "trd": [[1.77, 884.32]], "batb": NaN, "batl": [[0, 1.77, 15.73]]}, {"timestamp": 1578740351889, "ltp": 1.77, "tv": 42518.11, "trd": NaN, "batb": [[0, 1.76, 3004.26]], "batl": NaN}, {"timestamp": 1578740353990, "ltp": 1.77, "tv": 42518.11, "trd": NaN, "batb": NaN, "batl": [[0, 1.78, 67.25], [1, 1.79, 128.37], [2, 1.8, 79.46]]}, {"timestamp": 1578740360967, "ltp": 1.77, "tv": 42518.11, "trd": NaN, "batb": [[0, 1.77, 2000], [1, 1.76, 3004.26], [2, 1.75, 2000]], "batl": [[2, 1.8, 18.21]]}, {"timestamp": 1578740364004, "ltp": 1.77, "tv": 42518.11, "trd": NaN, "batb": [[0, 1.77, 2004.26], [1, 1.76, 3000]], "batl": NaN}, {"timestamp": 1578740366987, "ltp": 1.77, "tv": 46526.62, "trd": [[1.77, 4892.83]], "batb": [[0, 1.76, 3000], [1, 1.75, 2000], [2, 1.74, 2295.89]], "batl": [[0, 1.77, 27.92], [1, 1.78, 67.25], [2, 1.79, 128.37]]}, {"timestamp": 1578740367916, "ltp": 1.77, "tv": 46526.62, "trd": NaN, "batb": [[1, 1.75, 2015.71]], "batl": NaN}, {"timestamp": 1578740369911, "ltp": 1.77, "tv": 46526.62, "trd": NaN, "batb": [[1, 1.75, 2000]], "batl": NaN}, {"timestamp": 1578740371899, "ltp": 1.76, "tv": 52526.62, "trd": [[1.76, 6329.78]], "batb": [[0, 1.75, 2000], [1, 1.74, 2295.89], [2, 1.73, 2000]], "batl": [[0, 1.77, 93.09]]}, {"timestamp": 1578740372996, "ltp": 1.76, "tv": 52526.62, "trd": NaN, "batb": NaN, "batl": [[0, 1.77, 131.37], [1, 1.78, 105.53]]}, {"timestamp": 1578740373996, "ltp": 1.76, "tv": 52526.62, "trd": NaN, "batb": [[0, 1.75, 2017], [1, 1.74, 2312.89]], "batl": NaN}, {"timestamp": 1578740375924, "ltp": 1.78, "tv": 53097.27, "trd": [[1.77, 5155.57], [1.78, 693.78]], "batb": NaN, "batl": [[0, 1.79, 128.37], [1, 1.8, 18.21], [2, 1.82, 17.86]]}, {"timestamp": 1578740376930, "ltp": 1.78, "tv": 53097.27, "trd": NaN, "batb": [[0, 1.76, 22.23], [1, 1.75, 2017], [2, 1.74, 2312.89]], "batl": [[0, 1.77, 66], [1, 1.78, 66], [2, 1.79, 128.37]]}, {"timestamp": 1578740377819, "ltp": 1.78, "tv": 53097.27, "trd": NaN, "batb": [[0, 1.75, 2017], [1, 1.74, 2312.89], [2, 1.73, 2000]], "batl": [[1, 1.78, 104.28]]}, {"timestamp": 1578740378912, "ltp": 1.78, "tv": 53097.27, "trd": NaN, "batb": NaN, "batl": [[0, 1.78, 142.56], [1, 1.79, 128.37], [2, 1.8, 18.21]]}, {"timestamp": 1578740379908, "ltp": 1.78, "tv": 53097.27, "trd": NaN, "batb": NaN, "batl": [[0, 1.77, 66], [1, 1.78, 142.56], [2, 1.79, 128.37]]}, {"timestamp": 1578740380917, "ltp": 1.78, "tv": 53097.27, "trd": NaN, "batb": [[0, 1.75, 2905]], "batl": [[0, 1.78, 142.56], [1, 1.79, 128.37], [2, 1.8, 18.21]]}, {"timestamp": 1578740381807, "ltp": 1.78, "tv": 53097.27, "trd": NaN, "batb": NaN, "batl": [[0, 1.77, 38.28], [1, 1.78, 142.56], [2, 1.79, 128.37]]}, {"timestamp": 1578740387922, "ltp": 1.75, "tv": 53119.27, "trd": [[1.75, 1620.27]], "batb": [[0, 1.75, 2894]], "batl": NaN}, {"timestamp": 1578740391936, "ltp": 1.75, "tv": 53119.27, "trd": NaN, "batb": NaN, "batl": [[0, 1.77, 42.45]]}, {"timestamp": 1578740395925, "ltp": 1.75, "tv": 53119.27, "trd": NaN, "batb": [[0, 1.76, 6], [1, 1.75, 2894], [2, 1.74, 2312.89]], "batl": NaN}, {"timestamp": 1578740397945, "ltp": 1.75, "tv": 53119.27, "trd": NaN, "batb": NaN, "batl": [[0, 1.77, 63.87], [1, 1.78, 354.08]]}, {"timestamp": 1578740401937, "ltp": 1.75, "tv": 53119.27, "trd": NaN, "batb": [[0, 1.76, 2506]], "batl": NaN}, {"timestamp": 1578740402922, "ltp": 1.75, "tv": 53119.27, "trd": NaN, "batb": NaN, "batl": [[0, 1.77, 38.28]]}, {"timestamp": 1578740404949, "ltp": 1.75, "tv": 53119.27, "trd": NaN, "batb": [[1, 1.75, 2908.21]], "batl": NaN}, {"timestamp": 1578740406753, "ltp": 1.75, "tv": 53119.27, "trd": NaN, "batb": [[1, 1.75, 2914.21], [2, 1.74, 2318.89]], "batl": NaN}, {"timestamp": 1578740410929, "ltp": 1.76, "tv": 53419.27, "trd": [[1.76, 6629.78]], "batb": [[0, 1.76, 2356]], "batl": NaN}, {"timestamp": 1578740417934, "ltp": 1.76, "tv": 53599.14, "trd": [[1.76, 6809.65]], "batb": [[0, 1.76, 2266.05]], "batl": NaN}, {"timestamp": 1578740432860, "ltp": 1.76, "tv": 57599.14, "trd": [[1.76, 10809.65]], "batb": [[0, 1.76, 266.05]], "batl": NaN}, {"timestamp": 1578740439002, "ltp": 1.76, "tv": 58077.14, "trd": [[1.76, 11287.65]], "batb": [[0, 1.76, 2527.05]], "batl": NaN}, {"timestamp": 1578740439902, "ltp": 1.76, "tv": 58177.14, "trd": [[1.76, 11387.65]], "batb": [[0, 1.76, 2477.05]], "batl": NaN}, {"timestamp": 1578740443903, "ltp": 1.76, "tv": 58277.14, "trd": [[1.76, 11487.65]], "batb": [[0, 1.76, 2427.05]], "batl": NaN}, {"timestamp": 1578740444799, "ltp": 1.76, "tv": 58277.14, "trd": NaN, "batb": [[0, 1.75, 2914.21], [1, 1.74, 2373.14], [2, 1.73, 2000]], "batl": [[0, 1.77, 109.44]]}, {"timestamp": 1578740451004, "ltp": 1.76, "tv": 58277.14, "trd": NaN, "batb": [[0, 1.76, 2500], [1, 1.75, 2914.21], [2, 1.74, 2373.14]], "batl": [[0, 1.77, 38.28]]}, {"timestamp": 1578740451918, "ltp": 1.76, "tv": 58277.14, "trd": NaN, "batb": [[2, 1.74, 2318.89]], "batl": NaN}, {"timestamp": 1578740457802, "ltp": 1.76, "tv": 58277.14, "trd": NaN, "batb": NaN, "batl": [[0, 1.77, 68.9]]}, {"timestamp": 1578740464003, "ltp": 1.76, "tv": 58277.14, "trd": NaN, "batb": NaN, "batl": [[0, 1.77, 118.9]]}, {"timestamp": 1578740469993, "ltp": 1.76, "tv": 58277.14, "trd": NaN, "batb": [[1, 1.75, 3011.71]], "batl": NaN}, {"timestamp": 1578740480974, "ltp": 1.77, "tv": 58297.84, "trd": [[1.77, 5176.27]], "batb": NaN, "batl": [[0, 1.77, 108.55]]}, {"timestamp": 1578740484000, "ltp": 1.77, "tv": 58297.84, "trd": NaN, "batb": NaN, "batl": [[0, 1.77, 58.55]]}, {"timestamp": 1578740487990, "ltp": 1.76, "tv": 62297.84, "trd": [[1.76, 15487.65]], "batb": [[0, 1.76, 500]], "batl": NaN}, {"timestamp": 1578740503919, "ltp": 1.77, "tv": 62357.83, "trd": [[1.77, 5236.26]], "batb": NaN, "batl": [[0, 1.77, 28.56]]}, {"timestamp": 1578740513894, "ltp": 1.77, "tv": 62368.29, "trd": [[1.77, 5246.72]], "batb": NaN, "batl": [[0, 1.77, 23.33]]}, {"timestamp": 1578740517935, "ltp": 1.77, "tv": 62368.29, "trd": NaN, "batb": [[0, 1.76, 1388]], "batl": NaN}, {"timestamp": 1578740527925, "ltp": 1.77, "tv": 62368.29, "trd": NaN, "batb": [[0, 1.75, 134.71], [1, 1.74, 23.89], [2, 1.73, 25]], "batl": NaN}, {"timestamp": 1578740528924, "ltp": 1.72, "tv": 62515.82, "trd": [[1.72, 680.54], [1.73, 1518.68], [1.74, 1043.53]], "batb": [[0, 1.72, 15.79], [1, 1.71, 5], [2, 1.69, 148.92]], "batl": [[0, 1.76, 676.22], [1, 1.77, 251.17], [2, 1.78, 372.71]]}, {"timestamp": 1578740529935, "ltp": 1.69, "tv": 62969.56, "trd": [[1.69, 6693.53], [1.7, 1614.15], [1.71, 574.22], [1.72, 741.18]], "batb": [[0, 1.66, 2], [1, 1.65, 1.89], [2, 1.6, 29.82]], "batl": [[0, 1.69, 319.35], [1, 1.74, 77.27], [2, 1.75, 195.07]]}, {"timestamp": 1578740530830, "ltp": 1.68, "tv": 62975.42, "trd": [[1.68, 108.6]], "batb": [[0, 1.66, 28.27]], "batl": [[0, 1.68, 74.41], [1, 1.69, 319.35]]}, {"timestamp": 1578740531944, "ltp": 1.68, "tv": 63019.41, "trd": [[1.68, 152.59]], "batb": [[0, 1.67, 55.59], [1, 1.66, 2], [2, 1.65, 1.89]], "batl": [[0, 1.68, 249.11], [1, 1.69, 344.35]]}, {"timestamp": 1578740532945, "ltp": 1.67, "tv": 63069.95, "trd": [[1.67, 84.5]], "batb": [[0, 1.67, 30.32]], "batl": [[2, 1.75, 119.03]]}, {"timestamp": 1578740536851, "ltp": 1.68, "tv": 63568.17, "trd": [[1.68, 650.82]], "batb": [[0, 1.68, 539.58], [1, 1.67, 30.32], [2, 1.66, 2]], "batl": [[0, 1.69, 344.35], [1, 1.75, 119.03], [2, 1.77, 99.14]]}, {"timestamp": 1578740537918, "ltp": 1.69, "tv": 63643.21, "trd": [[1.68, 696.82], [1.69, 6722.57]], "batb": [[0, 1.68, 516.58]], "batl": [[0, 1.69, 329.83], [1, 1.7, 22.04], [2, 1.75, 119.03]]}, {"timestamp": 1578740539935, "ltp": 1.69, "tv": 64359.95, "trd": [[1.69, 7439.31]], "batb": [[0, 1.69, 126.62], [1, 1.68, 516.58], [2, 1.67, 30.32]], "batl": [[0, 1.7, 22.04], [1, 1.75, 119.03], [2, 1.76, 6]]}, {"timestamp": 1578740540942, "ltp": 1.69, "tv": 64422.64, "trd": [[1.69, 7502]], "batb": [[0, 1.69, 84.93], [1, 1.67, 30.32], [2, 1.66, 2]], "batl": [[0, 1.74, 21.08]]}, {"timestamp": 1578740541946, "ltp": 1.69, "tv": 64422.64, "trd": NaN, "batb": [[1, 1.67, 53.04]], "batl": [[1, 1.75, 100.65]]}, {"timestamp": 1578740543956, "ltp": 1.69, "tv": 64422.64, "trd": NaN, "batb": [[1, 1.67, 326.39]], "batl": NaN}, {"timestamp": 1578740544943, "ltp": 1.69, "tv": 64422.64, "trd": NaN, "batb": [[0, 1.7, 12.08], [1, 1.69, 84.93], [2, 1.67, 326.39]], "batl": [[0, 1.74, 48]]}, {"timestamp": 1578740545945, "ltp": 1.69, "tv": 64422.64, "trd": NaN, "batb": [[2, 1.67, 300.67]], "batl": NaN}, {"timestamp": 1578740550934, "ltp": 1.73, "tv": 64434.17, "trd": [[1.73, 1530.21]], "batb": [[0, 1.73, 71.43], [1, 1.7, 12.08]], "batl": NaN}, {"timestamp": 1578740551820, "ltp": 1.73, "tv": 64516.93, "trd": [[1.73, 1612.97]], "batb": [[0, 1.73, 30.05], [1, 1.72, 2.13], [2, 1.71, 2.13]], "batl": [[0, 1.74, 30], [1, 1.75, 131.65]]}, {"timestamp": 1578740552963, "ltp": 1.73, "tv": 64516.93, "trd": NaN, "batb": NaN, "batl": [[0, 1.74, 2], [2, 1.76, 37.13]]}, {"timestamp": 1578740553848, "ltp": 1.74, "tv": 64550.55, "trd": [[1.74, 1077.16]], "batb": [[0, 1.74, 13.07], [1, 1.72, 25], [2, 1.71, 23]], "batl": [[0, 1.75, 165.65], [1, 1.76, 71], [2, 1.77, 88.46]]}, {"timestamp": 1578740554957, "ltp": 1.75, "tv": 64576.53, "trd": [[1.75, 1646.25]], "batb": [[0, 1.73, 23.13], [1, 1.72, 31.56], [2, 1.68, 23.73]], "batl": [[0, 1.75, 152.66], [2, 1.77, 23.33]]}, {"timestamp": 1578740555956, "ltp": 1.75, "tv": 64576.53, "trd": NaN, "batb": [[0, 1.72, 2], [1, 1.71, 23.13]], "batl": NaN}, {"timestamp": 1578740556829, "ltp": 1.75, "tv": 64576.53, "trd": NaN, "batb": [[2, 1.68, 40.97]], "batl": [[1, 1.76, 65]]}, {"timestamp": 1578740557960, "ltp": 1.75, "tv": 64576.53, "trd": NaN, "batb": [[2, 1.67, 30.32]], "batl": NaN}, {"timestamp": 1578740558975, "ltp": 1.75, "tv": 64576.53, "trd": NaN, "batb": [[1, 1.71, 5]], "batl": [[0, 1.75, 124.66], [1, 1.76, 37]]}, {"timestamp": 1578740564964, "ltp": 1.75, "tv": 64576.53, "trd": NaN, "batb": [[2, 1.68, 2.17]], "batl": NaN}, {"timestamp": 1578740566982, "ltp": 1.72, "tv": 64580.53, "trd": [[1.72, 745.18]], "batb": [[0, 1.67, 30.32], [1, 1.66, 2], [2, 1.65, 1.89]], "batl": [[0, 1.69, 7], [1, 1.71, 28.13], [2, 1.74, 76.29]]}, {"timestamp": 1578740567778, "ltp": 1.72, "tv": 64580.53, "trd": NaN, "batb": NaN, "batl": [[0, 1.73, 27.13], [1, 1.74, 76.29], [2, 1.75, 122.64]]}, {"timestamp": 1578740568786, "ltp": 1.72, "tv": 64580.53, "trd": NaN, "batb": NaN, "batl": [[0, 1.7, 77.31], [1, 1.73, 27.13], [2, 1.74, 76.29]]}, {"timestamp": 1578740570964, "ltp": 1.72, "tv": 64580.53, "trd": NaN, "batb": NaN, "batl": [[0, 1.69, 13.13], [1, 1.7, 87.31], [2, 1.73, 20]]}, {"timestamp": 1578740573964, "ltp": 1.72, "tv": 64580.53, "trd": NaN, "batb": NaN, "batl": [[0, 1.69, 23.13], [1, 1.7, 100.31]]}, {"timestamp": 1578740574868, "ltp": 1.72, "tv": 64580.53, "trd": NaN, "batb": NaN, "batl": [[1, 1.7, 90.31]]}, {"timestamp": 1578740575876, "ltp": 1.72, "tv": 64580.53, "trd": NaN, "batb": NaN, "batl": [[1, 1.7, 100.31]]}, {"timestamp": 1578740576980, "ltp": 1.72, "tv": 64580.53, "trd": NaN, "batb": NaN, "batl": [[2, 1.73, 30]]}, {"timestamp": 1578740577983, "ltp": 1.72, "tv": 64580.53, "trd": NaN, "batb": NaN, "batl": [[0, 1.69, 13.13]]}, {"timestamp": 1578740578791, "ltp": 1.72, "tv": 64580.53, "trd": NaN, "batb": NaN, "batl": [[1, 1.7, 90.31], [2, 1.74, 76.29]]}, {"timestamp": 1578740589891, "ltp": 1.72, "tv": 64580.53, "trd": NaN, "batb": [[0, 1.67, 44.94], [1, 1.66, 3335]], "batl": [[0, 1.7, 77.31], [1, 1.71, 12.13]]}, {"timestamp": 1578740593903, "ltp": 1.72, "tv": 64580.53, "trd": NaN, "batb": [[0, 1.67, 315.29]], "batl": NaN}, {"timestamp": 1578740595889, "ltp": 1.72, "tv": 64580.53, "trd": NaN, "batb": [[0, 1.67, 3648.29]], "batl": NaN}, {"timestamp": 1578740600891, "ltp": 1.72, "tv": 64580.53, "trd": NaN, "batb": [[0, 1.68, 3000], [1, 1.67, 3648.29], [2, 1.66, 3335]], "batl": [[1, 1.71, 19], [2, 1.72, 19.13]]}, {"timestamp": 1578740604002, "ltp": 1.72, "tv": 64580.53, "trd": NaN, "batb": [[1, 1.67, 3377.94]], "batl": NaN}, {"timestamp": 1578740607002, "ltp": 1.72, "tv": 64580.53, "trd": NaN, "batb": [[0, 1.69, 2500], [1, 1.68, 3000], [2, 1.67, 3377.94]], "batl": [[0, 1.71, 42.53], [1, 1.72, 19.13], [2, 1.74, 76.29]]}, {"timestamp": 1578740607915, "ltp": 1.72, "tv": 64580.53, "trd": NaN, "batb": NaN, "batl": [[0, 1.71, 23.53], [2, 1.73, 22.13]]}, {"timestamp": 1578740608984, "ltp": 1.72, "tv": 64580.53, "trd": NaN, "batb": NaN, "batl": [[0, 1.72, 8.19], [1, 1.73, 22.13], [2, 1.75, 87.66]]}, {"timestamp": 1578740609986, "ltp": 1.72, "tv": 64580.53, "trd": NaN, "batb": NaN, "batl": [[0, 1.73, 25.15], [1, 1.75, 87.66], [2, 1.77, 23.33]]}, {"timestamp": 1578740610814, "ltp": 1.72, "tv": 64580.53, "trd": NaN, "batb": NaN, "batl": [[0, 1.73, 3.02], [1, 1.74, 27.13], [2, 1.75, 87.66]]}, {"timestamp": 1578740611982, "ltp": 1.69, "tv": 65280.53, "trd": [[1.69, 8167.74], [1.7, 1648.41]], "batb": [[0, 1.69, 2167.13]], "batl": [[0, 1.75, 143.66], [1, 1.77, 23.33], [2, 1.78, 76.56]]}, {"timestamp": 1578740613004, "ltp": 1.69, "tv": 65280.53, "trd": NaN, "batb": [[0, 1.7, 2017], [1, 1.69, 2167.13], [2, 1.68, 3000]], "batl": NaN}, {"timestamp": 1578740619994, "ltp": 1.69, "tv": 65280.53, "trd": NaN, "batb": [[0, 1.71, 2000], [1, 1.7, 2017], [2, 1.69, 2167.13]], "batl": [[1, 1.77, 54.43]]}, {"timestamp": 1578740622984, "ltp": 1.69, "tv": 65280.53, "trd": NaN, "batb": [[0, 1.71, 2000.9]], "batl": NaN}, {"timestamp": 1578740624897, "ltp": 1.75, "tv": 65310.32, "trd": [[1.75, 1676.03]], "batb": [[1, 1.7, 2024]], "batl": [[0, 1.75, 72.77], [1, 1.76, 67.18], [2, 1.77, 54.43]]}, {"timestamp": 1578740626918, "ltp": 1.75, "tv": 65310.32, "trd": NaN, "batb": [[0, 1.72, 2000], [1, 1.71, 2000.9], [2, 1.7, 2024]], "batl": NaN}, {"timestamp": 1578740627990, "ltp": 1.75, "tv": 65310.32, "trd": NaN, "batb": [[2, 1.7, 2000]], "batl": NaN}, {"timestamp": 1578740629000, "ltp": 1.75, "tv": 65340.12, "trd": [[1.75, 1705.83]], "batb": NaN, "batl": [[0, 1.75, 57.87]]}, {"timestamp": 1578740630914, "ltp": 1.75, "tv": 65340.12, "trd": NaN, "batb": [[0, 1.73, 24.18], [1, 1.72, 2000], [2, 1.71, 2000.9]], "batl": [[1, 1.76, 82.49]]}, {"timestamp": 1578740631926, "ltp": 1.75, "tv": 65340.12, "trd": NaN, "batb": NaN, "batl": [[2, 1.77, 23.33]]}, {"timestamp": 1578740644956, "ltp": 1.75, "tv": 65340.12, "trd": NaN, "batb": [[0, 1.73, 29.18], [1, 1.72, 2024]], "batl": [[1, 1.76, 87.49], [2, 1.77, 90.51]]}, {"timestamp": 1578740660982, "ltp": 1.75, "tv": 65340.12, "trd": NaN, "batb": [[1, 1.72, 24], [2, 1.67, 31.22]], "batl": [[0, 1.75, 124.87]]}, {"timestamp": 1578740663945, "ltp": 1.75, "tv": 65340.12, "trd": NaN, "batb": [[2, 1.67, 301.57]], "batl": NaN}, {"timestamp": 1578740664966, "ltp": 1.75, "tv": 65340.12, "trd": NaN, "batb": NaN, "batl": [[0, 1.75, 57.87]]}, {"timestamp": 1578740665984, "ltp": 1.75, "tv": 65340.12, "trd": NaN, "batb": [[2, 1.68, 6.9]], "batl": NaN}, {"timestamp": 1578740673980, "ltp": 1.75, "tv": 65340.12, "trd": NaN, "batb": NaN, "batl": [[0, 1.74, 13.42], [1, 1.75, 123.87], [2, 1.76, 100.4]]}, {"timestamp": 1578740675974, "ltp": 1.75, "tv": 65340.12, "trd": NaN, "batb": NaN, "batl": [[1, 1.75, 129.28]]}, {"timestamp": 1578740682003, "ltp": 1.75, "tv": 65340.12, "trd": NaN, "batb": NaN, "batl": [[0, 1.75, 123.87], [1, 1.76, 87.49], [2, 1.77, 90.51]]}, {"timestamp": 1578740682971, "ltp": 1.73, "tv": 65398.48, "trd": [[1.73, 1671.33]], "batb": [[0, 1.7, 18.08], [1, 1.68, 6], [2, 1.67, 300.67]], "batl": [[0, 1.74, 58.18], [1, 1.75, 57.87], [2, 1.76, 87.49]]}, {"timestamp": 1578740683995, "ltp": 1.73, "tv": 65398.48, "trd": NaN, "batb": [[0, 1.7, 30.29]], "batl": [[0, 1.75, 114.87], [1, 1.76, 87.49], [2, 1.77, 90.51]]}, {"timestamp": 1578740684899, "ltp": 1.73, "tv": 65398.48, "trd": NaN, "batb": [[0, 1.7, 18.08]], "batl": NaN}, {"timestamp": 1578740697904, "ltp": 1.73, "tv": 65398.48, "trd": NaN, "batb": [[0, 1.7, 7.9]], "batl": [[0, 1.74, 47.92], [1, 1.75, 99.87], [2, 1.76, 61.31]]}, {"timestamp": 1578740702907, "ltp": 1.73, "tv": 65398.48, "trd": NaN, "batb": [[1, 1.68, 13.69]], "batl": NaN}, {"timestamp": 1578740709925, "ltp": 1.73, "tv": 65398.48, "trd": NaN, "batb": NaN, "batl": [[0, 1.73, 10], [1, 1.74, 47.92], [2, 1.75, 99.87]]}, {"timestamp": 1578740710947, "ltp": 1.73, "tv": 65398.48, "trd": NaN, "batb": NaN, "batl": [[0, 1.72, 10]]}, {"timestamp": 1578740711807, "ltp": 1.73, "tv": 65398.48, "trd": NaN, "batb": [[0, 1.7, 3.9], [1, 1.69, 3.18], [2, 1.68, 13.69]], "batl": [[1, 1.73, 37.18], [2, 1.74, 47.92]]}, {"timestamp": 1578740713935, "ltp": 1.71, "tv": 65400.27, "trd": [[1.71, 576.02]], "batb": [[0, 1.69, 3.18], [1, 1.68, 28.23], [2, 1.67, 300.67]], "batl": [[0, 1.71, 9.1], [1, 1.74, 47.92], [2, 1.75, 99.87]]}, {"timestamp": 1578740714907, "ltp": 1.71, "tv": 65400.27, "trd": NaN, "batb": [[0, 1.68, 28.23], [1, 1.67, 300.67], [2, 1.66, 8.95]], "batl": [[1, 1.72, 16.18], [2, 1.74, 21.74]]}, {"timestamp": 1578740715721, "ltp": 1.71, "tv": 65400.27, "trd": NaN, "batb": NaN, "batl": [[0, 1.7, 9.1], [1, 1.71, 16.18], [2, 1.72, 16.18]]}, {"timestamp": 1578740718624, "ltp": 1.69, "tv": 65409.37, "trd": [[1.69, 8176.84]], "batb": NaN, "batl": [[0, 1.74, 15.74], [1, 1.75, 57.87], [2, 1.76, 20.31]]}, {"timestamp": 1578740720747, "ltp": 1.69, "tv": 65409.37, "trd": NaN, "batb": NaN, "batl": [[0, 1.73, 101.48], [1, 1.74, 15.74], [2, 1.75, 57.87]]}, {"timestamp": 1578740724945, "ltp": 1.69, "tv": 65424.37, "trd": [[1.69, 8191.84]], "batb": NaN, "batl": [[0, 1.73, 108.48], [1, 1.74, 22.74]]}, {"timestamp": 1578740729935, "ltp": 1.69, "tv": 65424.37, "trd": NaN, "batb": NaN, "batl": [[0, 1.73, 118.48]]}, {"timestamp": 1578740730946, "ltp": 1.69, "tv": 65424.37, "trd": NaN, "batb": NaN, "batl": [[0, 1.73, 128.48]]}, {"timestamp": 1578740735846, "ltp": 1.69, "tv": 65424.37, "trd": NaN, "batb": NaN, "batl": [[1, 1.74, 28.6]]}, {"timestamp": 1578740744770, "ltp": 1.69, "tv": 65424.37, "trd": NaN, "batb": NaN, "batl": [[0, 1.72, 17.03], [1, 1.73, 121.48], [2, 1.74, 15.86]]}, {"timestamp": 1578740761918, "ltp": 1.69, "tv": 65424.37, "trd": NaN, "batb": NaN, "batl": [[0, 1.72, 37.03], [1, 1.73, 101.48]]}, {"timestamp": 1578740762909, "ltp": 1.69, "tv": 65424.37, "trd": NaN, "batb": NaN, "batl": [[0, 1.72, 47.03]]}, {"timestamp": 1578740763715, "ltp": 1.69, "tv": 65424.37, "trd": NaN, "batb": NaN, "batl": [[1, 1.73, 110.15]]}, {"timestamp": 1578740766926, "ltp": 1.72, "tv": 65500.94, "trd": [[1.72, 821.75]], "batb": NaN, "batl": [[0, 1.71, 8.22], [1, 1.72, 18.74], [2, 1.73, 110.15]]}, {"timestamp": 1578740767730, "ltp": 1.72, "tv": 65500.94, "trd": NaN, "batb": NaN, "batl": [[0, 1.72, 26.74], [1, 1.73, 110.15], [2, 1.74, 15.86]]}, {"timestamp": 1578740769925, "ltp": 1.72, "tv": 65500.94, "trd": NaN, "batb": [[0, 1.68, 110.25]], "batl": NaN}, {"timestamp": 1578740772915, "ltp": 1.72, "tv": 65500.94, "trd": NaN, "batb": NaN, "batl": [[1, 1.73, 112.95]]}, {"timestamp": 1578740775743, "ltp": 1.72, "tv": 65500.94, "trd": NaN, "batb": NaN, "batl": [[0, 1.7, 600], [1, 1.72, 26.74], [2, 1.73, 112.95]]}, {"timestamp": 1578740776856, "ltp": 1.72, "tv": 65500.94, "trd": NaN, "batb": [[0, 1.68, 95.71]], "batl": [[0, 1.7, 608], [1, 1.71, 8.22], [2, 1.72, 76.74]]}, {"timestamp": 1578740778815, "ltp": 1.68, "tv": 65600.94, "trd": [[1.68, 796.81]], "batb": [[0, 1.68, 45.71]], "batl": NaN}, {"timestamp": 1578740779929, "ltp": 1.68, "tv": 65618.1, "trd": [[1.68, 813.98]], "batb": [[0, 1.68, 37.13]], "batl": NaN}, {"timestamp": 1578740782935, "ltp": 1.7, "tv": 65628.64, "trd": [[1.7, 1658.95]], "batb": NaN, "batl": [[0, 1.7, 602.73], [1, 1.71, 15.91]]}, {"timestamp": 1578740783784, "ltp": 1.7, "tv": 65628.64, "trd": NaN, "batb": NaN, "batl": [[0, 1.7, 622.73], [2, 1.72, 8]]}, {"timestamp": 1578740784941, "ltp": 1.7, "tv": 65628.64, "trd": NaN, "batb": [[1, 1.67, 30.32]], "batl": [[0, 1.69, 8.22], [1, 1.7, 622.73], [2, 1.71, 15.91]]}, {"timestamp": 1578740786942, "ltp": 1.7, "tv": 65628.64, "trd": NaN, "batb": [[0, 1.67, 30.32], [1, 1.66, 8.95], [2, 1.65, 1.89]], "batl": NaN}, {"timestamp": 1578740787948, "ltp": 1.68, "tv": 65670.54, "trd": [[1.68, 855.88]], "batb": [[0, 1.68, 19], [1, 1.67, 30.32], [2, 1.66, 8.95]], "batl": NaN}, {"timestamp": 1578740788939, "ltp": 1.68, "tv": 65670.54, "trd": NaN, "batb": NaN, "batl": [[0, 1.69, 28.22], [1, 1.7, 602.73]]}, {"timestamp": 1578740789955, "ltp": 1.68, "tv": 65670.54, "trd": NaN, "batb": NaN, "batl": [[0, 1.69, 38.22]]}, {"timestamp": 1578740804944, "ltp": 1.69, "tv": 65744.37, "trd": [[1.69, 8265.68]], "batb": NaN, "batl": [[0, 1.69, 9.3]]}, {"timestamp": 1578740813004, "ltp": 1.69, "tv": 65744.37, "trd": NaN, "batb": [[2, 1.66, 608.95]], "batl": NaN}, {"timestamp": 1578740813976, "ltp": 1.69, "tv": 65744.37, "trd": NaN, "batb": NaN, "batl": [[0, 1.69, 11.3]]}, {"timestamp": 1578740815984, "ltp": 1.69, "tv": 65744.37, "trd": NaN, "batb": NaN, "batl": [[0, 1.69, 20.82]]}, {"timestamp": 1578740821960, "ltp": 1.69, "tv": 65744.37, "trd": NaN, "batb": [[2, 1.66, 8.95]], "batl": [[0, 1.69, 28.82]]}, {"timestamp": 1578740822988, "ltp": 1.69, "tv": 65744.37, "trd": NaN, "batb": NaN, "batl": [[2, 1.71, 515.91]]}, {"timestamp": 1578740825860, "ltp": 1.69, "tv": 65755.03, "trd": [[1.69, 8276.34]], "batb": NaN, "batl": [[0, 1.69, 23.49]]}, {"timestamp": 1578740836894, "ltp": 1.69, "tv": 65755.03, "trd": NaN, "batb": NaN, "batl": [[0, 1.69, 25.49]]}, {"timestamp": 1578740838987, "ltp": 1.69, "tv": 65755.03, "trd": NaN, "batb": [[1, 1.67, 40.76]], "batl": NaN}, {"timestamp": 1578740839987, "ltp": 1.68, "tv": 65793.03, "trd": [[1.68, 893.88]], "batb": [[0, 1.67, 30.32], [1, 1.66, 8.95], [2, 1.65, 101.89]], "batl": NaN}, {"timestamp": 1578740841912, "ltp": 1.68, "tv": 65793.03, "trd": NaN, "batb": NaN, "batl": [[0, 1.69, 19.52]]}, {"timestamp": 1578740842926, "ltp": 1.68, "tv": 65793.03, "trd": NaN, "batb": [[0, 1.67, 39.03]], "batl": [[0, 1.68, 2], [1, 1.69, 19.52], [2, 1.7, 602.73]]}, {"timestamp": 1578740843999, "ltp": 1.68, "tv": 65793.03, "trd": NaN, "batb": [[0, 1.67, 30.32]], "batl": NaN}, {"timestamp": 1578740879978, "ltp": 1.68, "tv": 65793.03, "trd": NaN, "batb": NaN, "batl": [[0, 1.68, 21.52], [1, 1.69, 39.03]]}, {"timestamp": 1578740881860, "ltp": 1.68, "tv": 65793.03, "trd": NaN, "batb": NaN, "batl": [[0, 1.68, 41.04]]}, {"timestamp": 1578740887953, "ltp": 1.67, "tv": 65855.35, "trd": [[1.67, 146.82]], "batb": [[0, 1.66, 8.95], [1, 1.65, 101.89], [2, 1.6, 185.82]], "batl": NaN}, {"timestamp": 1578740889992, "ltp": 1.67, "tv": 65855.35, "trd": NaN, "batb": NaN, "batl": [[0, 1.68, 61.04]]}, {"timestamp": 1578740890946, "ltp": 1.67, "tv": 65855.35, "trd": NaN, "batb": NaN, "batl": [[0, 1.68, 71.04]]}, {"timestamp": 1578740891971, "ltp": 1.67, "tv": 65855.35, "trd": NaN, "batb": [[0, 1.67, 62.73], [1, 1.66, 8.95], [2, 1.65, 101.89]], "batl": NaN}, {"timestamp": 1578740892988, "ltp": 1.67, "tv": 65855.35, "trd": NaN, "batb": NaN, "batl": [[0, 1.68, 78.04]]}, {"timestamp": 1578740900957, "ltp": 1.67, "tv": 65975.35, "trd": [[1.67, 266.82]], "batb": [[0, 1.67, 2.73]], "batl": NaN}, {"timestamp": 1578740902999, "ltp": 1.67, "tv": 65980.82, "trd": [[1.67, 272.28]], "batb": [[0, 1.66, 8.95], [1, 1.65, 101.89], [2, 1.6, 185.82]], "batl": [[0, 1.67, 2.62], [1, 1.68, 78.04], [2, 1.69, 39.03]]}, {"timestamp": 1578740903962, "ltp": 1.67, "tv": 65980.82, "trd": NaN, "batb": NaN, "batl": [[0, 1.68, 78.04], [1, 1.69, 39.03], [2, 1.7, 602.73]]}, {"timestamp": 1578740904975, "ltp": 1.67, "tv": 65980.82, "trd": NaN, "batb": NaN, "batl": [[0, 1.67, 19.52], [1, 1.68, 78.04], [2, 1.69, 39.03]]}, {"timestamp": 1578740905969, "ltp": 1.67, "tv": 65980.82, "trd": NaN, "batb": NaN, "batl": [[1, 1.68, 88.04]]}, {"timestamp": 1578740907989, "ltp": 1.67, "tv": 65980.82, "trd": NaN, "batb": NaN, "batl": [[2, 1.69, 29.52]]}, {"timestamp": 1578740909992, "ltp": 1.67, "tv": 65980.82, "trd": NaN, "batb": [[2, 1.6, 29.82]], "batl": NaN}, {"timestamp": 1578740910969, "ltp": 1.67, "tv": 65980.82, "trd": NaN, "batb": NaN, "batl": [[0, 1.68, 88.04], [1, 1.69, 29.52], [2, 1.7, 602.73]]}, {"timestamp": 1578740932929, "ltp": 1.67, "tv": 65980.82, "trd": NaN, "batb": [[1, 1.65, 102.78]], "batl": NaN}, {"timestamp": 1578740934998, "ltp": 1.67, "tv": 65980.82, "trd": NaN, "batb": [[1, 1.65, 103.67]], "batl": NaN}, {"timestamp": 1578740936932, "ltp": 1.67, "tv": 65980.82, "trd": NaN, "batb": NaN, "batl": [[2, 1.7, 8]]}, {"timestamp": 1578740946946, "ltp": 1.67, "tv": 65980.82, "trd": NaN, "batb": [[0, 1.67, 5.27], [1, 1.66, 8.95], [2, 1.65, 103.67]], "batl": NaN}, {"timestamp": 1578740971873, "ltp": 1.67, "tv": 65980.82, "trd": NaN, "batb": [[0, 1.67, 19.89]], "batl": 