{"info": {"id": "1.166703736", "eventId": "29632571", "eventName": "Half Time", "marketType": "HALF_TIME", "openDate": 1578772099563, "name": "Inter v Atalanta", "numberOfActiveRunner": 3, "countryCode": "", "sport": "FOOTBALL", "venue": "", "volume": {"total": 40226.6, "preMatch": 4832.6, "inPlay": 35394.0}, "winner": {"id": 63347, "name": "Inter", "status": "WINNER", "position": 1}, "delay": 7}, "runners": [{"id": 63347, "name": "Inter", "status": "WINNER", "position": 1, "inPlayOdds": 2.8, "inPlayTime": 1578772099563, "avgPrematch": 2.83, "closedOdds": 1.02, "maxPrematch": 2.94, "minPrematch": 2.78, "maxInPlay": 2.84, "minInPlay": 1.02, "inPlayIndex": 886, "lengthOdds": 2161, "lengthOddsPrematch": 886, "lengthOddsInPlay": 1275, "tradedVolume": 37015.67, "preMatchVolume": 3222.15, "inPlayVolume": 33793.52}, {"id": 215817, "name": "Atalanta", "status": "LOSER", "position": 2, "inPlayOdds": 4.1, "inPlayTime": 1578772099563, "avgPrematch": 4.07, "closedOdds": 1000.0, "maxPrematch": 4.1, "minPrematch": 3.9, "maxInPlay": 1000.0, "minInPlay": 4.1, "inPlayIndex": 383, "lengthOdds": 1181, "lengthOddsPrematch": 383, "lengthOddsInPlay": 798, "tradedVolume": 734.23, "preMatchVolume": 413.95, "inPlayVolume": 320.28}, {"id": 58805, "name": "The Draw", "status": "LOSER", "position": 3, "inPlayOdds": 2.38, "inPlayTime": 1578772099563, "avgPrematch": 2.52, "closedOdds": 21.0, "maxPrematch": 2.56, "minPrematch": 2.38, "maxInPlay": 21.0, "minInPlay": 2.38, "inPlayIndex": 567, "lengthOdds": 1548, "lengthOddsPrematch": 567, "lengthOddsInPlay": 981, "tradedVolume": 2476.7, "preMatchVolume": 1196.5, "inPlayVolume": 1280.2}], "marketUpdates": [{"timestamp": 1578513294362000000, "openDate": "2020-01-11T19:45:00.000Z", "status": "OPEN", "betDelay": 0, "inPlay": false, "complete": true}, {"timestamp": 1578772099563000000, "openDate": "2020-01-11T19:45:00.000Z", "status": "OPEN", "betDelay": 7, "inPlay": true, "complete": true}, {"timestamp": 1578772294860000000, "openDate": "2020-01-11T19:45:00.000Z", "status": "SUSPENDED", "betDelay": 7, "inPlay": true, "complete": true}, {"timestamp": 1578772347979000000, "openDate": "2020-01-11T19:45:00.000Z", "status": "OPEN", "betDelay": 7, "inPlay": true, "complete": true}, {"timestamp": 1578774525024000000, "openDate": "2020-01-11T19:45:00.000Z", "status": "SUSPENDED", "betDelay": 7, "inPlay": true, "complete": true}, {"timestamp": 1578774556973000000, "openDate": "2020-01-11T19:45:00.000Z", "status": "OPEN", "betDelay": 7, "inPlay": true, "complete": true}, {"timestamp": 1578774580039000000, "openDate": "2020-01-11T19:45:00.000Z", "status": "SUSPENDED", "betDelay": 7, "inPlay": true, "complete": true}, {"timestamp": 1578774582036000000, "openDate": "2020-01-11T19:45:00.000Z", "status": "OPEN", "betDelay": 7, "inPlay": true, "complete": true}, {"timestamp": 1578774859971000000, "openDate": "2020-01-11T19:45:00.000Z", "status": "SUSPENDED", "betDelay": 7, "inPlay": true, "complete": true}, {"timestamp": 1578774933003000000, "openDate": "2020-01-11T19:45:00.000Z", "status": "CLOSED", "betDelay": 7, "inPlay": true, "complete": true}], "odds": [{"runnerId": 63347, "odds": [{"timestamp": 1578647120250, "ltp": 2.78, "tv": 9.54, "trd": [[2.78, 9.54]], "batb": [[0, 2.76, 39.71], [1, 2.74, 198.6], [2, 2.74, 0]], "batl": NaN}, {"timestamp": 1578647149999, "ltp": 2.78, "tv": 9.54, "trd": NaN, "batb": NaN, "batl": [[1, 2.94, 339.06], [2, 2.96, 34.87]]}, {"timestamp": 1578647260974, "ltp": 2.78, "tv": 9.54, "trd": NaN, "batb": NaN, "batl": [[0, 2.94, 339.06], [1, 2.96, 34.87], [2, 2.98, 18.45]]}, {"timestamp": 1578649303881, "ltp": 2.78, "tv": 9.54, "trd": NaN, "batb": [[0, 2.76, 158.68]], "batl": NaN}, {"timestamp": 1578649308996, "ltp": 2.78, "tv": 9.54, "trd": NaN, "batb": [[0, 2.76, 39.71]], "batl": [[0, 2.94, 372.2]]}, {"timestamp": 1578652196953, "ltp": 2.78, "tv": 9.54, "trd": NaN, "batb": [[1, 2.74, 138.27]], "batl": NaN}, {"timestamp": 1578654151919, "ltp": 2.78, "tv": 9.54, "trd": NaN, "batb": [[1, 2.74, 138.25]], "batl": [[0, 2.94, 372.13]]}, {"timestamp": 1578658540853, "ltp": 2.78, "tv": 9.54, "trd": NaN, "batb": [[1, 2.74, 117.25], [2, 2.72, 21.24]], "batl": [[2, 2.98, 0]]}, {"timestamp": 1578658545759, "ltp": 2.78, "tv": 9.54, "trd": NaN, "batb": NaN, "batl": [[1, 2.96, 53.51]]}, {"timestamp": 1578658581009, "ltp": 2.78, "tv": 9.54, "trd": NaN, "batb": [[2, 2.7, 21.49]], "batl": [[1, 2.96, 34.87]]}, {"timestamp": 1578658586027, "ltp": 2.78, "tv": 9.54, "trd": NaN, "batb": NaN, "batl": [[0, 2.94, 390.96]]}, {"timestamp": 1578660368035, "ltp": 2.78, "tv": 9.54, "trd": NaN, "batb": [[0, 2.74, 117.48], [1, 2.7, 21.49], [2, 2.7, 0]], "batl": [[1, 2.96, 0]]}, {"timestamp": 1578660439983, "ltp": 2.78, "tv": 9.54, "trd": NaN, "batb": [[1, 2.72, 216.65], [2, 2.7, 21.49]], "batl": NaN}, {"timestamp": 1578660662023, "ltp": 2.78, "tv": 9.54, "trd": NaN, "batb": [[0, 2.72, 216.88], [1, 2.7, 21.49], [2, 2.7, 0]], "batl": NaN}, {"timestamp": 1578661352024, "ltp": 2.78, "tv": 9.54, "trd": NaN, "batb": [[0, 2.72, 216.51]], "batl": [[0, 2.94, 390.33]]}, {"timestamp": 1578661490976, "ltp": 2.78, "tv": 9.54, "trd": NaN, "batb": [[0, 2.72, 264.86]], "batl": NaN}, {"timestamp": 1578661511010, "ltp": 2.78, "tv": 9.54, "trd": NaN, "batb": [[0, 2.72, 331.02]], "batl": NaN}, {"timestamp": 1578661513016, "ltp": 2.78, "tv": 9.54, "trd": NaN, "batb": [[0, 2.7, 21.72], [1, 2.7, 0]], "batl": [[0, 2.94, 18.83]]}, {"timestamp": 1578661537971, "ltp": 2.78, "tv": 9.54, "trd": NaN, "batb": [[0, 2.72, 21.47]], "batl": NaN}, {"timestamp": 1578661542251, "ltp": 2.78, "tv": 9.54, "trd": NaN, "batb": NaN, "batl": [[0, 2.96, 18.64]]}, {"timestamp": 1578661592992, "ltp": 2.78, "tv": 9.54, "trd": NaN, "batb": [[0, 2.74, 302.18], [1, 2.72, 21.24]], "batl": [[0, 2.94, 294.32], [1, 2.96, 18.64]]}, {"timestamp": 1578661699778, "ltp": 2.78, "tv": 9.54, "trd": NaN, "batb": [[0, 2.74, 260.62]], "batl": NaN}, {"timestamp": 1578661737025, "ltp": 2.78, "tv": 9.54, "trd": NaN, "batb": NaN, "batl": [[0, 2.94, 340.97]]}, {"timestamp": 1578661950022, "ltp": 2.78, "tv": 9.54, "trd": NaN, "batb": NaN, "batl": [[0, 2.94, 387.62]]}, {"timestamp": 1578661980995, "ltp": 2.78, "tv": 9.54, "trd": NaN, "batb": [[0, 2.74, 217.36]], "batl": NaN}, {"timestamp": 1578661981972, "ltp": 2.78, "tv": 9.54, "trd": NaN, "batb": [[0, 2.72, 21.47], [1, 2.72, 0]], "batl": [[0, 2.96, 18.64], [1, 2.96, 0]]}, {"timestamp": 1578662169994, "ltp": 2.78, "tv": 9.54, "trd": NaN, "batb": [[0, 2.74, 208.88], [1, 2.72, 21.24]], "batl": [[0, 2.94, 371.5], [1, 2.96, 18.64]]}, {"timestamp": 1578667986754, "ltp": 2.78, "tv": 9.54, "trd": NaN, "batb": [[1, 2.72, 20.02]], "batl": [[1, 2.96, 0]]}, {"timestamp": 1578667991870, "ltp": 2.78, "tv": 9.54, "trd": NaN, "batb": NaN, "batl": [[1, 2.96, 17.57]]}, {"timestamp": 1578668454940, "ltp": 2.78, "tv": 9.54, "trd": NaN, "batb": [[0, 2.74, 209.27]], "batl": [[0, 2.94, 372.2]]}, {"timestamp": 1578669563601, "ltp": 2.78, "tv": 9.54, "trd": NaN, "batb": [[0, 2.74, 251.76]], "batl": NaN}, {"timestamp": 1578669623010, "ltp": 2.78, "tv": 9.54, "trd": NaN, "batb": [[0, 2.74, 44.42]], "batl": [[0, 2.94, 52.69]]}, {"timestamp": 1578669698907, "ltp": 2.78, "tv": 9.54, "trd": NaN, "batb": [[0, 2.74, 307.84]], "batl": [[0, 2.94, 288.07]]}, {"timestamp": 1578672487889, "ltp": 2.78, "tv": 9.54, "trd": NaN, "batb": [[1, 2.7, 20.26]], "batl": [[1, 2.96, 0]]}, {"timestamp": 1578672492567, "ltp": 2.78, "tv": 9.54, "trd": NaN, "batb": NaN, "batl": [[0, 2.94, 305.82]]}, {"timestamp": 1578672496164, "ltp": 2.78, "tv": 9.54, "trd": NaN, "batb": [[1, 2.72, 337.36], [2, 2.7, 20.26]], "batl": [[1, 3.1, 392.59]]}, {"timestamp": 1578672831302, "ltp": 2.78, "tv": 9.54, "trd": NaN, "batb": [[0, 2.72, 337.59], [1, 2.7, 20.26], [2, 2.7, 0]], "batl": [[1, 3.1, 0]]}, {"timestamp": 1578674551053, "ltp": 2.78, "tv": 9.54, "trd": NaN, "batb": [[0, 2.72, 58.01]], "batl": [[0, 2.94, 70.44]]}, {"timestamp": 1578674662945, "ltp": 2.78, "tv": 9.54, "trd": NaN, "batb": [[0, 2.72, 378.37]], "batl": [[0, 2.94, 304.97]]}, {"timestamp": 1578674793891, "ltp": 2.78, "tv": 9.54, "trd": NaN, "batb": [[0, 2.72, 329.94]], "batl": NaN}, {"timestamp": 1578675751995, "ltp": 2.78, "tv": 9.54, "trd": NaN, "batb": [[0, 2.72, 330.56]], "batl": [[0, 2.94, 305.51]]}, {"timestamp": 1578677723511, "ltp": 2.78, "tv": 9.54, "trd": NaN, "batb": [[0, 2.74, 57.52], [1, 2.72, 330.33], [2, 2.7, 20.26]], "batl": NaN}, {"timestamp": 1578677761942, "ltp": 2.78, "tv": 9.54, "trd": NaN, "batb": NaN, "batl": [[1, 3, 43.1]]}, {"timestamp": 1578677797937, "ltp": 2.78, "tv": 9.54, "trd": NaN, "batb": [[0, 2.76, 210.51], [1, 2.74, 57.29], [2, 2.72, 330.33]], "batl": NaN}, {"timestamp": 1578677806852, "ltp": 2.78, "tv": 9.54, "trd": NaN, "batb": [[0, 2.78, 43.8], [1, 2.76, 210.28]], "batl": NaN}, {"timestamp": 1578677909051, "ltp": 2.78, "tv": 9.54, "trd": NaN, "batb": [[0, 2.78, 213.22]], "batl": NaN}, {"timestamp": 1578678019766, "ltp": 2.78, "tv": 9.54, "trd": NaN, "batb": [[1, 2.7, 20.26], [2, 2.72, 0]], "batl": NaN}, {"timestamp": 1578678429885, "ltp": 2.78, "tv": 9.54, "trd": NaN, "batb": NaN, "batl": [[1, 2.98, 36.75]]}, {"timestamp": 1578680317995, "ltp": 2.78, "tv": 9.54, "trd": NaN, "batb": NaN, "batl": [[0, 2.94, 70.53]]}, {"timestamp": 1578680318846, "ltp": 2.78, "tv": 9.54, "trd": NaN, "batb": [[0, 2.78, 70.19]], "batl": NaN}, {"timestamp": 1578680429995, "ltp": 2.78, "tv": 9.54, "trd": NaN, "batb": [[0, 2.78, 224.29]], "batl": [[0, 2.94, 319.13]]}, {"timestamp": 1578682633963, "ltp": 2.94, "tv": 9.99, "trd": [[2.94, 0.46]], "batb": [[0, 2.78, 224.06]], "batl": [[0, 2.94, 318.9]]}, {"timestamp": 1578682952056, "ltp": 2.94, "tv": 9.99, "trd": NaN, "batb": [[0, 2.78, 224.09]], "batl": [[0, 2.94, 318.95]]}, {"timestamp": 1578685534983, "ltp": 2.94, "tv": 9.99, "trd": NaN, "batb": [[0, 2.78, 263.26]], "batl": [[0, 2.94, 443.27]]}, {"timestamp": 1578685543775, "ltp": 2.94, "tv": 9.99, "trd": NaN, "batb": [[1, 2.74, 19.79]], "batl": [[0, 2.94, 425.52]]}, {"timestamp": 1578685548868, "ltp": 2.94, "tv": 9.99, "trd": NaN, "batb": NaN, "batl": [[1, 2.98, 54.14]]}, {"timestamp": 1578685646686, "ltp": 2.94, "tv": 9.99, "trd": NaN, "batb": NaN, "batl": [[1, 2.96, 510.9], [2, 2.98, 54.14]]}, {"timestamp": 1578685649937, "ltp": 2.94, "tv": 9.99, "trd": NaN, "batb": NaN, "batl": [[2, 2.98, 36.75]]}, {"timestamp": 1578685657546, "ltp": 2.94, "tv": 9.99, "trd": NaN, "batb": NaN, "batl": [[0, 2.96, 510.9], [1, 2.98, 36.75], [2, 2.98, 0]]}, {"timestamp": 1578685660196, "ltp": 2.94, "tv": 9.99, "trd": NaN, "batb": NaN, "batl": [[1, 2.98, 54.14]]}, {"timestamp": 1578685668531, "ltp": 2.94, "tv": 9.99, "trd": NaN, "batb": NaN, "batl": [[0, 2.92, 333.79], [1, 2.96, 510.9], [2, 2.98, 54.14]]}, {"timestamp": 1578685670340, "ltp": 2.94, "tv": 9.99, "trd": NaN, "batb": NaN, "batl": [[2, 2.98, 36.75]]}, {"timestamp": 1578685729894, "ltp": 2.94, "tv": 9.99, "trd": NaN, "batb": NaN, "batl": [[0, 2.96, 510.9], [1, 2.98, 36.75], [2, 2.98, 0]]}, {"timestamp": 1578685730589, "ltp": 2.94, "tv": 9.99, "trd": NaN, "batb": NaN, "batl": [[1, 2.98, 54.14]]}, {"timestamp": 1578685983991, "ltp": 2.94, "tv": 9.99, "trd": NaN, "batb": NaN, "batl": [[2, 3, 61.43]]}, {"timestamp": 1578685985032, "ltp": 2.94, "tv": 9.99, "trd": NaN, "batb": NaN, "batl": [[1, 2.98, 17.39]]}, {"timestamp": 1578686115037, "ltp": 2.94, "tv": 9.99, "trd": NaN, "batb": NaN, "batl": [[2, 3.05, 85.34]]}, {"timestamp": 1578686117674, "ltp": 2.94, "tv": 9.99, "trd": NaN, "batb": [[0, 2.78, 333.93]], "batl": NaN}, {"timestamp": 1578686134051, "ltp": 2.94, "tv": 9.99, "trd": NaN, "batb": NaN, "batl": [[2, 3, 64.2]]}, {"timestamp": 1578686329914, "ltp": 2.94, "tv": 9.99, "trd": NaN, "batb": NaN, "batl": [[0, 2.96, 421.49]]}, {"timestamp": 1578687773941, "ltp": 2.94, "tv": 9.99, "trd": NaN, "batb": [[0, 2.78, 290.5]], "batl": NaN}, {"timestamp": 1578688096999, "ltp": 2.94, "tv": 9.99, "trd": NaN, "batb": [[1, 2.76, 19.57]], "batl": [[1, 3, 64.2], [2, 3, 0]]}, {"timestamp": 1578688102014, "ltp": 2.94, "tv": 9.99, "trd": NaN, "batb": NaN, "batl": [[1, 3, 81.42]]}, {"timestamp": 1578688121839, "ltp": 2.94, "tv": 9.99, "trd": NaN, "batb": [[0, 2.78, 309.85], [1, 2.76, 0]], "batl": [[1, 3, 64.2]]}, {"timestamp": 1578688126540, "ltp": 2.94, "tv": 9.99, "trd": NaN, "batb": NaN, "batl": [[2, 3.05, 16.8]]}, {"timestamp": 1578688135452, "ltp": 2.94, "tv": 9.99, "trd": NaN, "batb": NaN, "batl": [[1, 2.98, 517.71], [2, 3, 64.2]]}, {"timestamp": 1578688215905, "ltp": 2.94, "tv": 9.99, "trd": NaN, "batb": NaN, "batl": [[0, 2.98, 517.71], [1, 3, 64.2], [2, 3, 0]]}, {"timestamp": 1578688216749, "ltp": 2.94, "tv": 9.99, "trd": NaN, "batb": NaN, "batl": [[2, 3.05, 16.8]]}, {"timestamp": 1578689558050, "ltp": 2.94, "tv": 9.99, "trd": NaN, "batb": NaN, "batl": [[0, 2.98, 590.74], [1, 3.05, 16.8], [2, 3.05, 0]]}, {"timestamp": 1578690152047, "ltp": 2.94, "tv": 10.0, "trd": NaN, "batb": [[0, 2.78, 309.96]], "batl": [[0, 2.98, 590.96]]}, {"timestamp": 1578690749035, "ltp": 2.94, "tv": 10.0, "trd": NaN, "batb": NaN, "batl": [[0, 2.98, 632.7]]}, {"timestamp": 1578697352006, "ltp": 2.94, "tv": 9.99, "trd": NaN, "batb": [[0, 2.78, 309.77]], "batl": [[0, 2.98, 632.27]]}, {"timestamp": 1578698281927, "ltp": 2.94, "tv": 9.99, "trd": NaN, "batb": [[0, 2.78, 285.09]], "batl": NaN}, {"timestamp": 1578700242996, "ltp": 2.78, "tv": 14.59, "trd": [[2.78, 14.14]], "batb": [[0, 2.78, 282.79]], "batl": NaN}, {"timestamp": 1578707102550, "ltp": 2.78, "tv": 14.59, "trd": NaN, "batb": [[0, 2.78, 284.72]], "batl": [[1, 3.05, 0]]}, {"timestamp": 1578707107370, "ltp": 2.78, "tv": 14.59, "trd": NaN, "batb": NaN, "batl": [[1, 3.05, 18.48]]}, {"timestamp": 1578709858045, "ltp": 2.78, "tv": 14.59, "trd": NaN, "batb": [[0, 2.78, 263.44], [1, 2.72, 22.03]], "batl": [[1, 3.05, 0]]}, {"timestamp": 1578709862645, "ltp": 2.78, "tv": 14.59, "trd": NaN, "batb": NaN, "batl": [[0, 2.96, 19.33], [1, 2.98, 632.27]]}, {"timestamp": 1578709949323, "ltp": 2.78, "tv": 14.59, "trd": NaN, "batb": NaN, "batl": [[0, 2.94, 419.65], [1, 2.96, 19.33], [2, 2.98, 632.27]]}, {"timestamp": 1578710060852, "ltp": 2.78, "tv": 14.59, "trd": NaN, "batb": NaN, "batl": [[2, 2.98, 73.03]]}, {"timestamp": 1578711733988, "ltp": 2.78, "tv": 14.59, "trd": NaN, "batb": [[1, 2.76, 252.81], [2, 2.72, 22.03]], "batl": [[0, 2.94, 478.38]]}, {"timestamp": 1578711741030, "ltp": 2.78, "tv": 14.59, "trd": NaN, "batb": [[0, 2.78, 41.27]], "batl": NaN}, {"timestamp": 1578716548979, "ltp": 2.78, "tv": 14.59, "trd": NaN, "batb": NaN, "batl": [[2, 3.05, 99.9]]}, {"timestamp": 1578716618956, "ltp": 2.78, "tv": 14.59, "trd": NaN, "batb": NaN, "batl": [[2, 2.98, 99.75]]}, {"timestamp": 1578717776990, "ltp": 2.78, "tv": 14.59, "trd": NaN, "batb": NaN, "batl": [[2, 3.05, 99.9]]}, {"timestamp": 1578719136876, "ltp": 2.78, "tv": 14.59, "trd": NaN, "batb": [[0, 2.78, 287.27]], "batl": NaN}, {"timestamp": 1578719168023, "ltp": 2.78, "tv": 14.59, "trd": NaN, "batb": [[1, 2.72, 22.03], [2, 2.72, 0]], "batl": [[0, 2.94, 388.15]]}, {"timestamp": 1578719911895, "ltp": 2.78, "tv": 14.59, "trd": NaN, "batb": [[0, 2.78, 66.81]], "batl": [[0, 2.94, 58.73]]}, {"timestamp": 1578720022944, "ltp": 2.78, "tv": 14.59, "trd": NaN, "batb": [[0, 2.78, 302.59]], "batl": [[0, 2.94, 376.23]]}, {"timestamp": 1578720285019, "ltp": 2.78, "tv": 14.59, "trd": NaN, "batb": NaN, "batl": [[2, 2.98, 99.75]]}, {"timestamp": 1578720445989, "ltp": 2.78, "tv": 14.59, "trd": NaN, "batb": NaN, "batl": [[2, 3.05, 99.9]]}, {"timestamp": 1578720477030, "ltp": 2.78, "tv": 14.59, "trd": NaN, "batb": NaN, "batl": [[2, 3, 100]]}, {"timestamp": 1578720482030, "ltp": 2.78, "tv": 14.59, "trd": NaN, "batb": NaN, "batl": [[2, 3.05, 99.9]]}, {"timestamp": 1578720484811, "ltp": 2.78, "tv": 14.59, "trd": NaN, "batb": NaN, "batl": [[2, 3.05, 0]]}, {"timestamp": 1578720503228, "ltp": 2.78, "tv": 14.59, "trd": NaN, "batb": NaN, "batl": [[2, 3.05, 99.9]]}, {"timestamp": 1578723936736, "ltp": 2.78, "tv": 14.59, "trd": NaN, "batb": [[0, 2.78, 372.39]], "batl": NaN}, {"timestamp": 1578723962658, "ltp": 2.78, "tv": 14.59, "trd": NaN, "batb": [[1, 2.76, 21.52]], "batl": [[1, 3.05, 99.9], [2, 3.05, 0]]}, {"timestamp": 1578723967681, "ltp": 2.78, "tv": 14.59, "trd": NaN, "batb": NaN, "batl": [[1, 3, 18.94], [2, 3.05, 99.9]]}, {"timestamp": 1578724047014, "ltp": 2.78, "tv": 14.59, "trd": NaN, "batb": NaN, "batl": [[0, 2.98, 473.27]]}, {"timestamp": 1578725020981, "ltp": 2.78, "tv": 14.59, "trd": NaN, "batb": [[0, 2.78, 396.22]], "batl": NaN}, {"timestamp": 1578726884878, "ltp": 2.78, "tv": 14.59, "trd": NaN, "batb": [[0, 2.78, 367.28]], "batl": NaN}, {"timestamp": 1578727109771, "ltp": 2.78, "tv": 14.59, "trd": NaN, "batb": [[0, 2.78, 160.44]], "batl": [[0, 2.98, 58.73]]}, {"timestamp": 1578727180956, "ltp": 2.78, "tv": 14.59, "trd": NaN, "batb": [[0, 2.78, 97.45]], "batl": NaN}, {"timestamp": 1578727262780, "ltp": 2.78, "tv": 14.59, "trd": NaN, "batb": [[0, 2.78, 358.77]], "batl": [[0, 2.98, 470.72]]}, {"timestamp": 1578728714914, "ltp": 2.78, "tv": 14.59, "trd": NaN, "batb": [[0, 2.78, 364.39]], "batl": NaN}, {"timestamp": 1578729533305, "ltp": 2.78, "tv": 14.59, "trd": NaN, "batb": NaN, "batl": [[0, 2.98, 510.73]]}, {"timestamp": 1578730274612, "ltp": 2.78, "tv": 14.59, "trd": NaN, "batb": NaN, "batl": [[1, 3, 118.94], [2, 3.15, 19.58]]}, {"timestamp": 1578732143026, "ltp": 2.78, "tv": 14.59, "trd": NaN, "batb": NaN, "batl": [[1, 3, 18.94], [2, 3.05, 99.9]]}, {"timestamp": 1578732794933, "ltp": 2.78, "tv": 14.59, "trd": NaN, "batb": NaN, "batl": [[0, 2.98, 610.48], [2, 3.15, 19.58]]}, {"timestamp": 1578733232019, "ltp": 2.78, "tv": 14.59, "trd": NaN, "batb": [[1, 2.74, 21.77]], "batl": [[1, 3.15, 19.58], [2, 3.15, 0]]}, {"timestamp": 1578733237045, "ltp": 2.78, "tv": 14.59, "trd": NaN, "batb": NaN, "batl": [[0, 2.98, 629.61]]}, {"timestamp": 1578733637974, "ltp": 2.78, "tv": 14.59, "trd": NaN, "batb": [[0, 2.78, 317.57]], "batl": NaN}, {"timestamp": 1578734950868, "ltp": 2.78, "tv": 14.59, "trd": NaN, "batb": [[0, 2.78, 373.75]], "batl": NaN}, {"timestamp": 1578735060975, "ltp": 2.78, "tv": 14.59, "trd": NaN, "batb": [[0, 2.78, 411.21]], "batl": NaN}, {"timestamp": 1578735208221, "ltp": 2.78, "tv": 14.59, "trd": NaN, "batb": [[0, 2.78, 447.81]], "batl": NaN}, {"timestamp": 1578735214938, "ltp": 2.78, "tv": 14.59, "trd": NaN, "batb": NaN, "batl": [[0, 2.98, 547.89]]}, {"timestamp": 1578735460041, "ltp": 2.78, "tv": 14.59, "trd": NaN, "batb": [[1, 2.76, 21.52]], "batl": [[0, 2.98, 528.76]]}, {"timestamp": 1578735465032, "ltp": 2.78, "tv": 14.59, "trd": NaN, "batb": NaN, "batl": [[1, 3, 18.94], [2, 3.15, 19.58]]}, {"timestamp": 1578736832849, "ltp": 2.78, "tv": 14.59, "trd": NaN, "batb": [[0, 2.8, 21.05], [1, 2.78, 447.81]], "batl": [[1, 3.15, 19.58], [2, 3.15, 0]]}, {"timestamp": 1578736837895, "ltp": 2.78, "tv": 14.59, "trd": NaN, "batb": NaN, "batl": [[1, 3.1, 18.04], [2, 3.15, 19.58]]}, {"timestamp": 1578736844014, "ltp": 2.78, "tv": 14.59, "trd": NaN, "batb": [[0, 2.8, 26.61], [1, 2.78, 442.19]], "batl": NaN}, {"timestamp": 1578736895688, "ltp": 2.78, "tv": 14.59, "trd": NaN, "batb": [[0, 2.82, 54.92], [1, 2.8, 26.61], [2, 2.78, 400.92]], "batl": NaN}, {"timestamp": 1578736918780, "ltp": 2.78, "tv": 14.59, "trd": NaN, "batb": [[0, 2.82, 276.23]], "batl": NaN}, {"timestamp": 1578736950752, "ltp": 2.78, "tv": 14.59, "trd": NaN, "batb": [[2, 2.78, 23.83]], "batl": NaN}, {"timestamp": 1578737296009, "ltp": 2.78, "tv": 14.59, "trd": NaN, "batb": [[1, 2.8, 5.56]], "batl": [[1, 3.15, 19.58], [2, 3.15, 0]]}, {"timestamp": 1578737301009, "ltp": 2.78, "tv": 14.59, "trd": NaN, "batb": NaN, "batl": [[1, 3, 18.94], [2, 3.15, 19.58]]}, {"timestamp": 1578737909038, "ltp": 2.78, "tv": 14.59, "trd": NaN, "batb": NaN, "batl": [[0, 2.98, 429.01]]}, {"timestamp": 1578737932955, "ltp": 2.78, "tv": 14.59, "trd": NaN, "batb": NaN, "batl": [[2, 3.1, 99.75]]}, {"timestamp": 1578737942040, "ltp": 2.78, "tv": 14.59, "trd": NaN, "batb": NaN, "batl": [[2, 3.05, 99.9]]}, {"timestamp": 1578737949970, "ltp": 2.78, "tv": 14.59, "trd": NaN, "batb": [[0, 2.82, 304.32]], "batl": NaN}, {"timestamp": 1578737954963, "ltp": 2.78, "tv": 14.59, "trd": NaN, "batb": NaN, "batl": [[0, 2.98, 393.26]]}, {"timestamp": 1578738026031, "ltp": 2.78, "tv": 14.59, "trd": NaN, "batb": NaN, "batl": [[2, 3.1, 99.75]]}, {"timestamp": 1578738043857, "ltp": 2.78, "tv": 14.59, "trd": NaN, "batb": NaN, "batl": [[2, 3.05, 99.9]]}, {"timestamp": 1578738179961, "ltp": 2.78, "tv": 14.59, "trd": NaN, "batb": NaN, "batl": [[2, 3.1, 99.75]]}, {"timestamp": 1578738493914, "ltp": 2.78, "tv": 14.59, "trd": NaN, "batb": NaN, "batl": [[2, 3.05, 99.9]]}, {"timestamp": 1578738497005, "ltp": 2.78, "tv": 14.59, "trd": NaN, "batb": NaN, "batl": [[2, 3.1, 99.75]]}, {"timestamp": 1578738505046, "ltp": 2.78, "tv": 14.59, "trd": NaN, "batb": NaN, "batl": [[2, 3.05, 99.9]]}, {"timestamp": 1578739024995, "ltp": 2.78, "tv": 14.59, "trd": NaN, "batb": NaN, "batl": [[2, 3.1, 99.75]]}, {"timestamp": 1578739863352, "ltp": 2.78, "tv": 14.59, "trd": NaN, "batb": [[1, 2.78, 23.83], [2, 2.76, 21.52]], "batl": NaN}, {"timestamp": 1578740117993, "ltp": 2.78, "tv": 14.59, "trd": NaN, "batb": NaN, "batl": [[2, 3.05, 99.9]]}, {"timestamp": 1578740157972, "ltp": 2.78, "tv": 14.59, "trd": NaN, "batb": NaN, "batl": [[2, 3.1, 99.75]]}, {"timestamp": 1578740163938, "ltp": 2.78, "tv": 14.59, "trd": NaN, "batb": NaN, "batl": [[0, 2.98, 330.27]]}, {"timestamp": 1578740194896, "ltp": 2.78, "tv": 14.59, "trd": NaN, "batb": [[0, 2.86, 20.37], [1, 2.82, 304.32], [2, 2.78, 23.83]], "batl": [[1, 3.1, 99.75], [2, 3.15, 19.58]]}, {"timestamp": 1578740203929, "ltp": 2.78, "tv": 14.59, "trd": NaN, "batb": [[1, 2.84, 54.22], [2, 2.82, 249.4]], "batl": NaN}, {"timestamp": 1578740216026, "ltp": 2.78, "tv": 14.59, "trd": NaN, "batb": NaN, "batl": [[0, 3.1, 99.75], [1, 3.15, 19.58], [2, 3.25, 16.84]]}, {"timestamp": 1578740216364, "ltp": 2.78, "tv": 14.59, "trd": NaN, "batb": NaN, "batl": [[0, 3.05, 519.24], [1, 3.1, 99.75], [2, 3.15, 19.58]]}, {"timestamp": 1578740280001, "ltp": 2.78, "tv": 14.59, "trd": NaN, "batb": NaN, "batl": [[0, 3.05, 619.14], [1, 3.15, 19.58], [2, 3.25, 16.84]]}, {"timestamp": 1578740357000, "ltp": 2.78, "tv": 14.59, "trd": NaN, "batb": [[1, 2.84, 214.25], [2, 2.78, 23.83]], "batl": NaN}, {"timestamp": 1578740362043, "ltp": 2.78, "tv": 14.59, "trd": NaN, "batb": [[1, 2.84, 266.17]], "batl": NaN}, {"timestamp": 1578740370541, "ltp": 2.84, "tv": 587.65, "trd": [[2.84, 532.31], [2.86, 40.74]], "batb": [[0, 2.82, 54.94], [1, 2.78, 23.83], [2, 2.76, 21.52]], "batl": NaN}, {"timestamp": 1578740376031, "ltp": 2.84, "tv": 587.65, "trd": NaN, "batb": [[1, 2.8, 262.17], [2, 2.78, 23.83]], "batl": NaN}, {"timestamp": 1578740381025, "ltp": 2.84, "tv": 587.65, "trd": NaN, "batb": [[0, 2.82, 54.92]], "batl": NaN}, {"timestamp": 1578740385329, "ltp": 2.84, "tv": 587.65, "trd": NaN, "batb": [[0, 2.82, 60.41]], "batl": NaN}, {"timestamp": 1578740391269, "ltp": 2.84, "tv": 587.65, "trd": NaN, "batb": [[0, 2.82, 54.92]], "batl": NaN}, {"timestamp": 1578741074985, "ltp": 2.84, "tv": 587.65, "trd": NaN, "batb": [[0, 2.82, 82.16], [1, 2.78, 23.83], [2, 2.76, 21.52]], "batl": [[0, 3.05, 159.48]]}, {"timestamp": 1578741080953, "ltp": 2.84, "tv": 587.65, "trd": NaN, "batb": [[0, 2.82, 54.92]], "batl": [[0, 3.05, 99.9]]}, {"timestamp": 1578741098394, "ltp": 2.84, "tv": 587.65, "trd": NaN, "batb": [[0, 2.82, 60.41]], "batl": NaN}, {"timestamp": 1578741137055, "ltp": 2.84, "tv": 587.65, "trd": NaN, "batb": [[0, 2.84, 20.59], [1, 2.82, 60.41], [2, 2.78, 23.83]], "batl": [[2, 3.25, 0]]}, {"timestamp": 1578741139869, "ltp": 2.84, "tv": 587.65, "trd": NaN, "batb": [[1, 2.82, 85.95]], "batl": [[0, 3, 60.44], [1, 3.05, 99.9], [2, 3.15, 19.58]]}, {"timestamp": 1578741140962, "ltp": 2.84, "tv": 628.71, "trd": [[2.84, 573.37]], "batb": [[0, 2.82, 86.01], [1, 2.78, 23.83], [2, 2.78, 0]], "batl": NaN}, {"timestamp": 1578741141765, "ltp": 2.84, "tv": 628.71, "trd": NaN, "batb": [[0, 2.82, 85.95], [2, 2.74, 21.77]], "batl": NaN}, {"timestamp": 1578741316993, "ltp": 2.84, "tv": 628.71, "trd": NaN, "batb": [[0, 2.82, 277.47]], "batl": [[0, 3, 517.53]]}, {"timestamp": 1578741397552, "ltp": 2.84, "tv": 628.71, "trd": NaN, "batb": NaN, "batl": [[0, 3, 475.83]]}, {"timestamp": 1578741873768, "ltp": 2.84, "tv": 628.71, "trd": NaN, "batb": [[0, 2.82, 300.45], [1, 2.74, 21.77], [2, 2.74, 0]], "batl": NaN}, {"timestamp": 1578741883780, "ltp": 2.84, "tv": 628.71, "trd": NaN, "batb": NaN, "batl": [[1, 3.1, 99.75]]}, {"timestamp": 1578741921767, "ltp": 2.84, "tv": 628.71, "trd": NaN, "batb": NaN, "batl": [[1, 3.05, 510.73], [2, 3.1, 99.75]]}, {"timestamp": 1578741983574, "ltp": 2.84, "tv": 628.71, "trd": NaN, "batb": NaN, "batl": [[0, 3.05, 510.73], [1, 3.1, 99.75], [2, 3.15, 19.58]]}, {"timestamp": 1578742300926, "ltp": 2.84, "tv": 628.71, "trd": NaN, "batb": NaN, "batl": [[2, 3.2, 35.95]]}, {"timestamp": 1578742313965, "ltp": 2.84, "tv": 628.71, "trd": NaN, "batb": [[0, 2.82, 321.26], [1, 2.74, 0]], "batl": [[2, 3.2, 18.73]]}, {"timestamp": 1578742318954, "ltp": 2.84, "tv": 628.71, "trd": NaN, "batb": NaN, "batl": [[2, 3.15, 17.62]]}, {"timestamp": 1578742374931, "ltp": 2.84, "tv": 628.71, "trd": NaN, "batb": NaN, "batl": [[0, 3.05, 610.63], [1, 3.15, 17.62], [2, 3.2, 18.73]]}, {"timestamp": 1578742620252, "ltp": 2.84, "tv": 628.71, "trd": NaN, "batb": NaN, "batl": [[0, 3, 8.51], [1, 3.05, 610.63], [2, 3.15, 17.62]]}, {"timestamp": 1578742652938, "ltp": 2.84, "tv": 628.71, "trd": NaN, "batb": NaN, "batl": [[1, 3.05, 510.73], [2, 3.1, 99.75]]}, {"timestamp": 1578743103962, "ltp": 2.84, "tv": 628.71, "trd": NaN, "batb": [[0, 2.82, 321.74]], "batl": NaN}, {"timestamp": 1578743451991, "ltp": 2.84, "tv": 628.71, "trd": NaN, "batb": [[0, 2.82, 316.25]], "batl": NaN}, {"timestamp": 1578743455003, "ltp": 2.84, "tv": 628.71, "trd": NaN, "batb": [[0, 2.82, 321.74]], "batl": NaN}, {"timestamp": 1578743648042, "ltp": 2.84, "tv": 628.71, "trd": NaN, "batb": [[0, 2.82, 435.8]], "batl": NaN}, {"timestamp": 1578743865906, "ltp": 2.84, "tv": 628.71, "trd": NaN, "batb": [[0, 2.82, 104.68]], "batl": [[1, 3.1, 99.75], [2, 3.15, 18.02]]}, {"timestamp": 1578743866907, "ltp": 2.84, "tv": 628.71, "trd": NaN, "batb": NaN, "batl": [[0, 3.1, 99.75], [1, 3.15, 18.02], [2, 3.2, 18.73]]}, {"timestamp": 1578743882954, "ltp": 2.84, "tv": 628.71, "trd": NaN, "batb": [[0, 2.84, 34.05], [1, 2.82, 104.68]], "batl": [[0, 3.05, 59.58], [1, 3.1, 99.75], [2, 3.15, 18.02]]}, {"timestamp": 1578743887917, "ltp": 2.84, "tv": 628.71, "trd": NaN, "batb": [[0, 2.86, 62.18], [1, 2.84, 34.05], [2, 2.82, 49.76]], "batl": NaN}, {"timestamp": 1578743922901, "ltp": 2.84, "tv": 628.71, "trd": NaN, "batb": [[0, 2.86, 86.01]], "batl": NaN}, {"timestamp": 1578743974019, "ltp": 2.84, "tv": 628.71, "trd": NaN, "batb": [[0, 2.86, 280.94]], "batl": [[0, 3.05, 504.77]]}, {"timestamp": 1578744034407, "ltp": 2.84, "tv": 628.71, "trd": NaN, "batb": [[1, 2.82, 49.76], [2, 2.82, 0]], "batl": NaN}, {"timestamp": 1578744180985, "ltp": 2.84, "tv": 628.71, "trd": NaN, "batb": NaN, "batl": [[0, 3, 8.51], [1, 3.05, 504.77], [2, 3.1, 99.75]]}, {"timestamp": 1578745620056, "ltp": 2.84, "tv": 628.71, "trd": NaN, "batb": [[0, 2.86, 233.27]], "batl": NaN}, {"timestamp": 1578745622860, "ltp": 2.84, "tv": 628.71, "trd": NaN, "batb": [[0, 2.86, 62.18]], "batl": NaN}, {"timestamp": 1578745624037, "ltp": 2.84, "tv": 628.71, "trd": NaN, "batb": [[1, 2.84, 264.73], [2, 2.82, 49.76]], "batl": NaN}, {"timestamp": 1578745628952, "ltp": 2.84, "tv": 628.71, "trd": NaN, "batb": [[1, 2.82, 49.76], [2, 2.82, 0]], "batl": [[1, 3.1, 99.75], [2, 3.15, 18.02]]}, {"timestamp": 1578745632559, "ltp": 2.84, "tv": 628.71, "trd": NaN, "batb": NaN, "batl": [[0, 3.1, 99.75], [1, 3.15, 18.02], [2, 3.2, 18.73]]}, {"timestamp": 1578745707792, "ltp": 2.84, "tv": 628.71, "trd": NaN, "batb": [[1, 2.84, 246.85], [2, 2.82, 49.76]], "batl": [[0, 3.05, 518.39], [1, 3.1, 99.75], [2, 3.15, 18.02]]}, {"timestamp": 1578745710041, "ltp": 2.84, "tv": 628.71, "trd": NaN, "batb": [[1, 2.84, 219.61]], "batl": NaN}, {"timestamp": 1578745740995, "ltp": 2.84, "tv": 628.71, "trd": NaN, "batb": NaN, "batl": [[0, 3, 8.51], [1, 3.05, 518.39], [2, 3.1, 99.75]]}, {"timestamp": 1578746410674, "ltp": 2.84, "tv": 628.71, "trd": NaN, "batb": NaN, "batl": [[0, 2.98, 10.55], [1, 3, 8.51], [2, 3.05, 518.39]]}, {"timestamp": 1578746435992, "ltp": 2.84, "tv": 628.71, "trd": NaN, "batb": NaN, "batl": [[0, 2.98, 314.43]]}, {"timestamp": 1578746438485, "ltp": 2.84, "tv": 628.71, "trd": NaN, "batb": NaN, "batl": [[1, 3.05, 518.39], [2, 3.1, 99.75]]}, {"timestamp": 1578746518926, "ltp": 2.84, "tv": 628.71, "trd": NaN, "batb": NaN, "batl": [[0, 2.98, 10.55]]}, {"timestamp": 1578746640230, "ltp": 2.84, "tv": 628.71, "trd": NaN, "batb": NaN, "batl": [[1, 3, 8.51], [2, 3.05, 518.39]]}, {"timestamp": 1578746692052, "ltp": 2.84, "tv": 628.71, "trd": NaN, "batb": NaN, "batl": [[0, 2.98, 305.92], [2, 3.1, 99.75]]}, {"timestamp": 1578746692691, "ltp": 2.84, "tv": 628.71, "trd": NaN, "batb": NaN, "batl": [[1, 3.1, 99.75], [2, 3.15, 18.02]]}, {"timestamp": 1578746793945, "ltp": 2.84, "tv": 628.71, "trd": NaN, "batb": NaN, "batl": [[1, 3.05, 520.09], [2, 3.1, 99.75]]}, {"timestamp": 1578746825874, "ltp": 2.84, "tv": 628.71, "trd": NaN, "batb": NaN, "batl": [[0, 2.98, 10.55]]}, {"timestamp": 1578746881654, "ltp": 2.84, "tv": 628.71, "trd": NaN, "batb": NaN, "batl": [[1, 3, 8.51], [2, 3.05, 520.09]]}, {"timestamp": 1578746918691, "ltp": 2.84, "tv": 628.71, "trd": NaN, "batb": NaN, "batl": [[0, 2.98, 316.99]]}, {"timestamp": 1578746920570, "ltp": 2.84, "tv": 628.71, "trd": NaN, "batb": NaN, "batl": [[1, 3.05, 520.09], [2, 3.1, 99.75]]}, {"timestamp": 1578746941776, "ltp": 2.84, "tv": 628.71, "trd": NaN, "batb": NaN, "batl": [[0, 2.96, 8.51], [1, 2.98, 316.99], [2, 3.05, 520.09]]}, {"timestamp": 1578746979840, "ltp": 2.84, "tv": 628.71, "trd": NaN, "batb": NaN, "batl": [[2, 3.1, 99.75]]}, {"timestamp": 1578746986667, "ltp": 2.84, "tv": 628.71, "trd": NaN, "batb": NaN, "batl": [[1, 2.98, 306.44]]}, {"timestamp": 1578747051305, "ltp": 2.84, "tv": 628.71, "trd": NaN, "batb": NaN, "batl": [[2, 3.05, 510.73]]}, {"timestamp": 1578747224738, "ltp": 2.84, "tv": 628.71, "trd": NaN, "batb": NaN, "batl": [[1, 3.1, 99.75], [2, 3.2, 481.78]]}, {"timestamp": 1578747226522, "ltp": 2.84, "tv": 628.71, "trd": NaN, "batb": NaN, "batl": [[0, 3.1, 99.75], [1, 3.2, 481.78], [2, 3.2, 0]]}, {"timestamp": 1578747229336, "ltp": 2.84, "tv": 628.71, "trd": NaN, "batb": NaN, "batl": [[1, 3.15, 18.02], [2, 3.2, 481.78]]}, {"timestamp": 1578747253946, "ltp": 2.84, "tv": 628.71, "trd": NaN, "batb": [[2, 2.82, 44.27]], "batl": NaN}, {"timestamp": 1578747328034, "ltp": 2.84, "tv": 628.71, "trd": NaN, "batb": NaN, "batl": [[0, 3.05, 511.58], [1, 3.1, 99.75], [2, 3.15, 18.02]]}, {"timestamp": 1578747543036, "ltp": 2.84, "tv": 628.71, "trd": NaN, "batb": NaN, "batl": [[0, 3, 8.51], [1, 3.05, 511.58], [2, 3.1, 99.75]]}, {"timestamp": 1578748331590, "ltp": 2.84, "tv": 628.71, "trd": NaN, "batb": [[2, 2.82, 22.98]], "batl": NaN}, {"timestamp": 1578748337004, "ltp": 2.84, "tv": 628.71, "trd": NaN, "batb": NaN, "batl": [[1, 3.05, 530.48]]}, {"timestamp": 1578748565745, "ltp": 2.84, "tv": 628.71, "trd": NaN, "batb": [[0, 2.86, 67.56]], "batl": NaN}, {"timestamp": 1578748572926, "ltp": 2.84, "tv": 628.71, "trd": NaN, "batb": [[0, 2.86, 62.18]], "batl": NaN}, {"timestamp": 1578748838704, "ltp": 2.84, "tv": 628.71, "trd": NaN, "batb": [[0, 2.86, 67.56]], "batl": NaN}, {"timestamp": 1578748868769, "ltp": 2.84, "tv": 628.71, "trd": NaN, "batb": [[0, 2.86, 62.18]], "batl": NaN}, {"timestamp": 1578750292728, "ltp": 2.84, "tv": 628.71, "trd": NaN, "batb": [[0, 2.86, 84.31]], "batl": NaN}, {"timestamp": 1578750293738, "ltp": 2.84, "tv": 628.71, "trd": NaN, "batb": [[2, 2.78, 21.77]], "batl": NaN}, {"timestamp": 1578750322568, "ltp": 2.84, "tv": 628.71, "trd": NaN, "batb": [[1, 2.84, 296.22]], "batl": [[1, 3.05, 732.21]]}, {"timestamp": 1578751602991, "ltp": 2.84, "tv": 628.71, "trd": NaN, "batb": [[1, 2.84, 252.81]], "batl": NaN}, {"timestamp": 1578751607963, "ltp": 2.84, "tv": 628.71, "trd": NaN, "batb": [[1, 2.84, 204.29]], "batl": NaN}, {"timestamp": 1578751618127, "ltp": 2.84, "tv": 628.71, "trd": NaN, "batb": [[1, 2.84, 255.36]], "batl": NaN}, {"timestamp": 1578752918863, "ltp": 2.84, "tv": 628.71, "trd": NaN, "batb": [[1, 2.84, 349.85]], "batl": NaN}, {"timestamp": 1578753062140, "ltp": 2.84, "tv": 628.71, "trd": NaN, "batb": [[1, 2.84, 287.71]], "batl": NaN}, {"timestamp": 1578753610118, "ltp": 2.84, "tv": 628.71, "trd": NaN, "batb": NaN, "batl": [[0, 2.98, 10.55], [1, 3, 8.51], [2, 3.05, 732.21]]}, {"timestamp": 1578753675078, "ltp": 2.84, "tv": 628.71, "trd": NaN, "batb": NaN, "batl": [[0, 2.98, 482.12]]}, {"timestamp": 1578753678824, "ltp": 2.84, "tv": 628.71, "trd": NaN, "batb": NaN, "batl": [[0, 2.96, 8.51], [1, 2.98, 482.12], [2, 3.05, 713.31]]}, {"timestamp": 1578753786829, "ltp": 2.84, "tv": 628.71, "trd": NaN, "batb": NaN, "batl": [[2, 3.1, 99.75]]}, {"timestamp": 1578753789034, "ltp": 2.84, "tv": 628.71, "trd": NaN, "batb": NaN, "batl": [[2, 3.05, 18.9]]}, {"timestamp": 1578754147049, "ltp": 2.84, "tv": 628.71, "trd": NaN, "batb": [[0, 2.86, 105.14]], "batl": NaN}, {"timestamp": 1578754148021, "ltp": 2.84, "tv": 628.71, "trd": NaN, "batb": [[2, 2.78, 0]], "batl": [[2, 3.1, 99.75]]}, {"timestamp": 1578754185978, "ltp": 2.84, "tv": 628.71, "trd": NaN, "batb": NaN, "batl": [[1, 2.98, 471.57]]}, {"timestamp": 1578754233651, "ltp": 2.84, "tv": 628.71, "trd": NaN, "batb": NaN, "batl": [[2, 3.05, 729.49]]}, {"timestamp": 1578754262722, "ltp": 2.84, "tv": 628.71, "trd": NaN, "batb": [[1, 2.84, 0]], "batl": [[1, 3.1, 99.75], [2, 3.2, 18.73]]}, {"timestamp": 1578754266003, "ltp": 2.84, "tv": 628.71, "trd": NaN, "batb": NaN, "batl": [[0, 3.1, 99.75], [1, 3.2, 18.73], [2, 3.25, 17.22]]}, {"timestamp": 1578754323959, "ltp": 2.84, "tv": 628.71, "trd": NaN, "batb": [[1, 2.84, 25.54]], "batl": [[0, 3.05, 60.44], [1, 3.1, 99.75], [2, 3.2, 18.73]]}, {"timestamp": 1578754382974, "ltp": 2.84, "tv": 628.71, "trd": NaN, "batb": [[1, 2.84, 0]], "batl": [[0, 3.1, 99.75], [1, 3.2, 18.73], [2, 3.25, 17.22]]}, {"timestamp": 1578754384828, "ltp": 2.84, "tv": 628.71, "trd": NaN, "batb": [[0, 2.86, 105.9]], "batl": [[2, 3.25, 0]]}, {"timestamp": 1578754389546, "ltp": 2.84, "tv": 628.71, "trd": NaN, "batb": NaN, "batl": [[2, 3.25, 17.84]]}, {"timestamp": 1578754444043, "ltp": 2.84, "tv": 628.71, "trd": NaN, "batb": [[1, 2.84, 26.39]], "batl": [[0, 3.05, 57.88], [1, 3.1, 99.75], [2, 3.2, 18.73]]}, {"timestamp": 1578754556992, "ltp": 2.84, "tv": 628.71, "trd": NaN, "batb": [[1, 2.84, 291.96]], "batl": [[0, 3.05, 723.53]]}, {"timestamp": 1578754558854, "ltp": 2.84, "tv": 628.71, "trd": NaN, "batb": NaN, "batl": [[0, 3, 8.51], [1, 3.05, 723.53], [2, 3.1, 99.75]]}, {"timestamp": 1578755765026, "ltp": 2.84, "tv": 628.71, "trd": NaN, "batb": NaN, "batl": [[2, 3.15, 136.7]]}, {"timestamp": 1578755998969, "ltp": 2.84, "tv": 628.71, "trd": NaN, "batb": NaN, "batl": [[2, 3.1, 136.75]]}, {"timestamp": 1578756185719, "ltp": 2.84, "tv": 628.71, "trd": NaN, "batb": NaN, "batl": [[0, 2.98, 10.55], [1, 3, 8.51], [2, 3.05, 723.53]]}, {"timestamp": 1578756318989, "ltp": 2.84, "tv": 628.71, "trd": NaN, "batb": NaN, "batl": [[0, 2.98, 488.93], [2, 3.1, 136.75]]}, {"timestamp": 1578756323005, "ltp": 2.84, "tv": 628.71, "trd": NaN, "batb": NaN, "batl": [[1, 3.1, 136.75], [2, 3.2, 18.73]]}, {"timestamp": 1578756323726, "ltp": 2.84, "tv": 628.71, "trd": NaN, "batb": NaN, "batl": [[0, 2.96, 8.51], [1, 2.98, 488.93], [2, 3.1, 136.75]]}, {"timestamp": 1578756760994, "ltp": 2.84, "tv": 628.71, "trd": NaN, "batb": NaN, "batl": [[1, 2.98, 478.38]]}, {"timestamp": 1578756866340, "ltp": 2.84, "tv": 628.71, "trd": NaN, "batb": NaN, "batl": [[2, 3.05, 773.75]]}, {"timestamp": 1578757040051, "ltp": 2.84, "tv": 628.71, "trd": NaN, "batb": NaN, "batl": [[1, 3.1, 136.75], [2, 3.2, 692.03]]}, {"timestamp": 1578757041937, "ltp": 2.84, "tv": 628.71, "trd": NaN, "batb": NaN, "batl": [[0, 3.05, 8.51]]}, {"timestamp": 1578757141542, "ltp": 2.84, "tv": 628.71, "trd": NaN, "batb": NaN, "batl": [[0, 3.05, 775.45]]}, {"timestamp": 1578757492017, "ltp": 2.84, "tv": 628.71, "trd": NaN, "batb": NaN, "batl": [[2, 3.2, 18.73]]}, {"timestamp": 1578757505044, "ltp": 2.84, "tv": 628.71, "trd": NaN, "batb": [[0, 2.86, 108.3]], "batl": NaN}, {"timestamp": 1578757959916, "ltp": 2.84, "tv": 628.71, "trd": NaN, "batb": [[0, 2.86, 86.17], [2, 2.82, 22.98]], "batl": NaN}, {"timestamp": 1578758359935, "ltp": 2.84, "tv": 628.71, "trd": NaN, "batb": NaN, "batl": [[0, 3, 10.55], [1, 3.05, 775.45], [2, 3.1, 136.75]]}, {"timestamp": 1578758936959, "ltp": 2.84, "tv": 628.71, "trd": NaN, "batb": NaN, "batl": [[0, 3.05, 775.45], [1, 3.1, 136.75], [2, 3.2, 18.73]]}, {"timestamp": 1578759000583, "ltp": 2.84, "tv": 628.71, "trd": NaN, "batb": NaN, "batl": [[0, 3, 10.55], [1, 3.05, 775.45], [2, 3.1, 136.75]]}, {"timestamp": 1578759491648, "ltp": 2.84, "tv": 628.71, "trd": NaN, "batb": [[0, 2.86, 91.55]], "batl": NaN}, {"timestamp": 1578759576075, "ltp": 2.84, "tv": 628.71, "trd": NaN, "batb": NaN, "batl": [[0, 3.05, 775.45], [1, 3.1, 136.75], [2, 3.2, 18.73]]}, {"timestamp": 1578759639669, "ltp": 2.84, "tv": 628.71, "trd": NaN, "batb": NaN, "batl": [[0, 3, 10.55], [1, 3.05, 775.45], [2, 3.1, 136.75]]}, {"timestamp": 1578759673044, "ltp": 2.84, "tv": 628.71, "trd": NaN, "batb": NaN, "batl": [[1, 3.05, 933.67], [2, 3.2, 18.73]]}, {"timestamp": 1578759710640, "ltp": 2.84, "tv": 628.71, "trd": NaN, "batb": [[2, 2.82, 23.67]], "batl": NaN}, {"timestamp": 1578759712865, "ltp": 2.84, "tv": 628.71, "trd": NaN, "batb": NaN, "batl": [[1, 3.05, 935.1]]}, {"timestamp": 1578759755928, "ltp": 2.84, "tv": 628.71, "trd": NaN, "batb": [[1, 2.84, 264.73]], "batl": NaN}, {"timestamp": 1578759759012, "ltp": 2.84, "tv": 628.71, "trd": NaN, "batb": NaN, "batl": [[1, 3.05, 776.88], [2, 3.1, 158.25]]}, {"timestamp": 1578759966855, "ltp": 2.84, "tv": 628.71, "trd": NaN, "batb": NaN, "batl": [[1, 3.05, 935.18], [2, 3.2, 18.73]]}, {"timestamp": 1578760025975, "ltp": 2.84, "tv": 628.71, "trd": NaN, "batb": NaN, "batl": [[1, 3.05, 776.88], [2, 3.1, 158.25]]}, {"timestamp": 1578760215342, "ltp": 2.84, "tv": 628.71, "trd": NaN, "batb": NaN, "batl": [[0, 3.05, 776.88], [1, 3.1, 158.25], [2, 3.2, 18.73]]}, {"timestamp": 1578760275314, "ltp": 2.84, "tv": 628.71, "trd": NaN, "batb": NaN, "batl": [[0, 3, 10.55], [1, 3.05, 776.88], [2, 3.1, 158.25]]}, {"timestamp": 1578760501915, "ltp": 2.84, "tv": 628.71, "trd": NaN, "batb": NaN, "batl": [[1, 3.05, 775.45]]}, {"timestamp": 1578760504924, "ltp": 2.84, "tv": 628.71, "trd": NaN, "batb": NaN, "batl": [[0, 3, 11.55]]}, {"timestamp": 1578760850907, "ltp": 2.84, "tv": 628.71, "trd": NaN, "batb": NaN, "batl": [[0, 3, 1]]}, {"timestamp": 1578760909412, "ltp": 2.84, "tv": 628.71, "trd": NaN, "batb": NaN, "batl": [[0, 3, 11.55]]}, {"timestamp": 1578761358988, "ltp": 2.84, "tv": 628.71, "trd": NaN, "batb": [[2, 2.82, 408.41]], "batl": NaN}, {"timestamp": 1578761361899, "ltp": 2.84, "tv": 628.71, "trd": NaN, "batb": NaN, "batl": [[1, 3.05, 933.75], [2, 3.2, 18.73]]}, {"timestamp": 1578761373008, "ltp": 2.84, "tv": 628.71, "trd": NaN, "batb": NaN, "batl": [[1, 3.05, 775.45], [2, 3.1, 158.25]]}, {"timestamp": 1578761391038, "ltp": 2.84, "tv": 628.71, "trd": NaN, "batb": [[1, 2.82, 408.41], [2, 2.82, 0]], "batl": NaN}, {"timestamp": 1578761484931, "ltp": 2.84, "tv": 628.71, "trd": NaN, "batb": NaN, "batl": [[0, 3, 1]]}, {"timestamp": 1578761537986, "ltp": 2.84, "tv": 628.71, "trd": NaN, "batb": NaN, "batl": [[0, 3, 11.55]]}, {"timestamp": 1578761569013, "ltp": 2.84, "tv": 628.71, "trd": NaN, "batb": NaN, "batl": [[1, 3.05, 933.75], [2, 3.2, 18.73]]}, {"timestamp": 1578761607036, "ltp": 2.84, "tv": 628.71, "trd": NaN, "batb": NaN, "batl": [[1, 3.05, 775.45], [2, 3.1, 158.25]]}, {"timestamp": 1578761803052, "ltp": 2.84, "tv": 628.71, "trd": NaN, "batb": NaN, "batl": [[1, 3.05, 933.75], [2, 3.2, 18.73]]}, {"timestamp": 1578761870040, "ltp": 2.84, "tv": 628.71, "trd": NaN, "batb": NaN, "batl": [[1, 3.05, 775.45], [2, 3.1, 158.25]]}, {"timestamp": 1578761871996, "ltp": 2.84, "tv": 628.71, "trd": NaN, "batb": NaN, "batl": [[1, 3.05, 933.75], [2, 3.2, 18.73]]}, {"timestamp": 1578761872813, "ltp": 2.84, "tv": 628.71, "trd": NaN, "batb": NaN, "batl": [[1, 3.05, 775.45], [2, 3.1, 158.25]]}, {"timestamp": 1578761920857, "ltp": 2.84, "tv": 628.71, "trd": NaN, "batb": NaN, "batl": [[1, 3.05, 933.75], [2, 3.2, 18.73]]}, {"timestamp": 1578762049028, "ltp": 2.84, "tv": 628.71, "trd": NaN, "batb": [[0, 2.86, 86.17]], "batl": NaN}, {"timestamp": 1578762085050, "ltp": 2.84, "tv": 628.71, "trd": NaN, "batb": [[1, 2.82, 23.67]], "batl": [[1, 3.05, 166.81]]}, {"timestamp": 1578762113886, "ltp": 2.84, "tv": 628.71, "trd": NaN, "batb": NaN, "batl": [[0, 3, 1]]}, {"timestamp": 1578762159978, "ltp": 2.84, "tv": 628.71, "trd": NaN, "batb": NaN, "batl": [[0, 3, 11.55]]}, {"timestamp": 1578762217859, "ltp": 2.86, "tv": 637.25, "trd": [[2.86, 49.28]], "batb": [[0, 2.86, 81.9]], "batl": NaN}, {"timestamp": 1578762371965, "ltp": 2.86, "tv": 637.25, "trd": NaN, "batb": [[0, 2.88, 23.73], [1, 2.86, 57.91], [2, 2.82, 23.67]], "batl": NaN}, {"timestamp": 1578762376783, "ltp": 2.86, "tv": 637.25, "trd": NaN, "batb": [[1, 2.82, 111.2], [2, 2.82, 0]], "batl": NaN}, {"timestamp": 1578762382691, "ltp": 2.86, "tv": 637.25, "trd": NaN, "batb": NaN, "batl": [[2, 3.15, 19.58]]}, {"timestamp": 1578762431034, "ltp": 2.88, "tv": 684.91, "trd": [[2.88, 47.66]], "batb": [[0, 2.82, 111.2], [1, 2.78, 23.83]], "batl": NaN}, {"timestamp": 1578762433015, "ltp": 2.88, "tv": 684.91, "trd": NaN, "batb": [[1, 2.78, 48.89]], "batl": NaN}, {"timestamp": 1578762441042, "ltp": 2.88, "tv": 684.91, "trd": NaN, "batb": [[0, 2.82, 116.69]], "batl": NaN}, {"timestamp": 1578762452050, "ltp": 2.88, "tv": 684.91, "trd": NaN, "batb": [[0, 2.82, 140.52]], "batl": [[0, 3, 70.29]]}, {"timestamp": 1578762456830, "ltp": 2.88, "tv": 684.91, "trd": NaN, "batb": [[1, 2.78, 25.06]], "batl": NaN}, {"timestamp": 1578762527979, "ltp": 2.88, "tv": 684.91, "trd": NaN, "batb": [[0, 2.82, 412.06]], "batl": [[0, 3, 727.42]]}, {"timestamp": 1578762529839, "ltp": 2.88, "tv": 684.91, "trd": NaN, "batb": NaN, "batl": [[0, 2.98, 8.51], [1, 3, 727.42], [2, 3.05, 158.3]]}, {"timestamp": 1578762556490, "ltp": 2.88, "tv": 684.91, "trd": NaN, "batb": NaN, "batl": [[1, 3, 769.98]]}, {"timestamp": 1578762736014, "ltp": 2.88, "tv": 684.91, "trd": NaN, "batb": NaN, "batl": [[1, 3, 759.43]]}, {"timestamp": 1578762784592, "ltp": 2.88, "tv": 684.91, "trd": NaN, "batb": NaN, "batl": [[0, 2.96, 10.55], [1, 2.98, 8.51], [2, 3, 759.43]]}, {"timestamp": 1578762793574, "ltp": 2.88, "tv": 684.91, "trd": NaN, "batb": NaN, "batl": [[0, 2.96, 571.5]]}, {"timestamp": 1578762794861, "ltp": 2.88, "tv": 684.91, "trd": NaN, "batb": NaN, "batl": [[0, 2.94, 8.51], [1, 2.96, 571.5]]}, {"timestamp": 1578762798864, "ltp": 2.88, "tv": 684.91, "trd": NaN, "batb": NaN, "batl": [[1, 2.96, 10.55]]}, {"timestamp": 1578762799976, "ltp": 2.88, "tv": 684.91, "trd": NaN, "batb": NaN, "batl": [[0, 2.96, 10.55], [1, 2.98, 8.51]]}, {"timestamp": 1578762826824, "ltp": 2.88, "tv": 684.91, "trd": NaN, "batb": NaN, "batl": [[0, 2.94, 428.16], [1, 2.96, 10.55], [2, 2.98, 8.51]]}, {"timestamp": 1578762828415, "ltp": 2.88, "tv": 684.91, "trd": NaN, "batb": NaN, "batl": [[0, 2.92, 8.51], [1, 2.94, 428.16], [2, 2.96, 10.55]]}, {"timestamp": 1578762846925, "ltp": 2.88, "tv": 684.91, "trd": NaN, "batb": NaN, "batl": [[2, 2.96, 565.54]]}, {"timestamp": 1578762871960, "ltp": 2.88, "tv": 684.91, "trd": NaN, "batb": NaN, "batl": [[1, 2.96, 10.55], [2, 3, 1]]}, {"timestamp": 1578762872967, "ltp": 2.88, "tv": 684.91, "trd": NaN, "batb": NaN, "batl": [[0, 2.96, 10.55], [1, 3, 1], [2, 3.05, 158.3]]}, {"timestamp": 1578762873764, "ltp": 2.88, "tv": 684.91, "trd": NaN, "batb": NaN, "batl": [[1, 3, 9.51]]}, {"timestamp": 1578762887825, "ltp": 2.88, "tv": 684.91, "trd": NaN, "batb": NaN, "batl": [[0, 2.92, 290.26], [1, 2.96, 10.55], [2, 3, 9.51]]}, {"timestamp": 1578762890012, "ltp": 2.88, "tv": 684.91, "trd": NaN, "batb": NaN, "batl": [[2, 3, 1]]}, {"timestamp": 1578762899027, "ltp": 2.88, "tv": 684.91, "trd": NaN, "batb": NaN, "batl": [[0, 2.9, 8.51], [1, 2.92, 290.26], [2, 2.96, 10.55]]}, {"timestamp": 1578762940838, "ltp": 2.88, "tv": 684.91, "trd": NaN, "batb": NaN, "batl": [[1, 2.94, 420.5]]}, {"timestamp": 1578762944053, "ltp": 2.88, "tv": 684.91, "trd": NaN, "batb": NaN, "batl": [[0, 2.94, 420.5], [1, 2.96, 10.55], [2, 3, 1]]}, {"timestamp": 1578762953769, "ltp": 2.88, "tv": 684.91, "trd": NaN, "batb": NaN, "batl": [[0, 2.92, 8.51], [1, 2.94, 420.5], [2, 2.96, 10.55]]}, {"timestamp": 1578762956895, "ltp": 2.88, "tv": 684.91, "trd": NaN, "batb": NaN, "batl": [[0, 2.92, 315.8]]}, {"timestamp": 1578762991850, "ltp": 2.88, "tv": 684.91, "trd": NaN, "batb": NaN, "batl": [[0, 2.92, 8.51]]}, {"timestamp": 1578763017954, "ltp": 2.88, "tv": 684.91, "trd": NaN, "batb": NaN, "batl": [[0, 2.92, 312.39]]}, {"timestamp": 1578763046996, "ltp": 2.88, "tv": 684.91, "trd": NaN, "batb": NaN, "batl": [[0, 2.92, 8.51]]}, {"timestamp": 1578763077055, "ltp": 2.88, "tv": 684.91, "trd": NaN, "batb": [[0, 2.82, 406.57]], "batl": NaN}, {"timestamp": 1578763084785, "ltp": 2.88, "tv": 684.91, "trd": NaN, "batb": [[0, 2.82, 412.06]], "batl": NaN}, {"timestamp": 1578763119915, "ltp": 2.88, "tv": 684.91, "trd": NaN, "batb": [[0, 2.82, 406.57]], "batl": NaN}, {"timestamp": 1578763122796, "ltp": 2.88, "tv": 684.91, "trd": NaN, "batb": [[0, 2.82, 412.06]], "batl": NaN}, {"timestamp": 1578763276768, "ltp": 2.88, "tv": 684.91, "trd": NaN, "batb": [[0, 2.82, 389.08], [1, 2.78, 48.89]], "batl": NaN}, {"timestamp": 1578763344919, "ltp": 2.82, "tv": 764.91, "trd": [[2.82, 80]], "batb": [[0, 2.82, 349.08]], "batl": NaN}, {"timestamp": 1578763360037, "ltp": 2.82, "tv": 764.91, "trd": NaN, "batb": NaN, "batl": [[2, 3, 1.06]]}, {"timestamp": 1578763403003, "ltp": 2.82, "tv": 764.91, "trd": NaN, "batb": NaN, "batl": [[1, 3, 1.06], [2, 3.05, 159.3]]}, {"timestamp": 1578763405007, "ltp": 2.82, "tv": 764.91, "trd": NaN, "batb": NaN, "batl": [[0, 3, 1.06], [1, 3.05, 159.3], [2, 3.15, 788.22]]}, {"timestamp": 1578763405690, "ltp": 2.82, "tv": 764.91, "trd": NaN, "batb": NaN, "batl": [[0, 3, 9.57]]}, {"timestamp": 1578763414691, "ltp": 2.82, "tv": 764.91, "trd": NaN, "batb": [[0, 2.82, 403.56]], "batl": [[0, 2.92, 303.88], [1, 3, 9.57], [2, 3.05, 159.3]]}, {"timestamp": 1578763416979, "ltp": 2.82, "tv": 764.91, "trd": NaN, "batb": NaN, "batl": [[0, 2.9, 8.51], [1, 2.92, 303.88], [2, 3, 1.06]]}, {"timestamp": 1578763419890, "ltp": 2.82, "tv": 764.91, "trd": NaN, "batb": [[0, 2.82, 53.71], [1, 2.8, 463.91], [2, 2.78, 48.89]], "batl": NaN}, {"timestamp": 1578763430003, "ltp": 2.82, "tv": 764.91, "trd": NaN, "batb": NaN, "batl": [[1, 3, 720.33], [2, 3.05, 159.3]]}, {"timestamp": 1578763432020, "ltp": 2.82, "tv": 764.91, "trd": NaN, "batb": NaN, "batl": [[0, 2.98, 8.51]]}, {"timestamp": 1578763446027, "ltp": 2.82, "tv": 764.91, "trd": NaN, "batb": [[0, 2.82, 402.71]], "batl": [[1, 3, 774.8]]}, {"timestamp": 1578763448899, "ltp": 2.82, "tv": 764.91, "trd": NaN, "batb": NaN, "batl": [[0, 2.96, 10.55], [1, 2.98, 8.51], [2, 3, 774.8]]}, {"timestamp": 1578763451946, "ltp": 2.82, "tv": 764.91, "trd": NaN, "batb": [[0, 2.82, 53.71]], "batl": NaN}, {"timestamp": 1578763462022, "ltp": 2.82, "tv": 764.91, "trd": NaN, "batb": [[0, 2.82, 403.56]], "batl": NaN}, {"timestamp": 1578763476751, "ltp": 2.82, "tv": 764.91, "trd": NaN, "batb": NaN, "batl": [[0, 2.96, 530.64]]}, {"timestamp": 1578763478034, "ltp": 2.82, "tv": 764.91, "trd": NaN, "batb": NaN, "batl": [[0, 2.94, 8.51], [1, 2.96, 530.64]]}, {"timestamp": 1578763496975, "ltp": 2.82, "tv": 764.91, "trd": NaN, "batb": [[1, 2.78, 48.89], [2, 2.78, 0]], "batl": [[2, 3, 1.06]]}, {"timestamp": 1578763504002, "ltp": 2.82, "tv": 764.91, "trd": NaN, "batb": [[0, 2.82, 442.87]], "batl": NaN}, {"timestamp": 1578763625030, "ltp": 2.82, "tv": 764.91, "trd": NaN, "batb": [[0, 2.82, 390.09]], "batl": [[1, 2.96, 567.24]]}, {"timestamp": 1578763630024, "ltp": 2.82, "tv": 764.91, "trd": NaN, "batb": [[0, 2.82, 342.42]], "batl": [[1, 2.96, 10.55]]}, {"timestamp": 1578763631537, "ltp": 2.82, "tv": 764.91, "trd": NaN, "batb": NaN, "batl": [[0, 2.96, 10.55], [1, 3, 9.57], [2, 3.05, 159.3]]}, {"timestamp": 1578763646549, "ltp": 2.82, "tv": 764.91, "trd": NaN, "batb": [[0, 2.82, 396.9]], "batl": [[0, 2.94, 419.65], [1, 2.96, 10.55], [2, 3, 9.57]]}, {"timestamp": 1578763648054, "ltp": 2.82, "tv": 764.91, "trd": NaN, "batb": NaN, "batl": [[2, 3, 1.06]]}, {"timestamp": 1578763648261, "ltp": 2.82, "tv": 764.91, "trd": NaN, "batb": NaN, "batl": [[0, 2.92, 8.51], [1, 2.94, 419.65], [2, 2.96, 10.55]]}, {"timestamp": 1578763657988, "ltp": 2.82, "tv": 764.91, "trd": NaN, "batb": [[0, 2.82, 391.41]], "batl": NaN}, {"timestamp": 1578763668986, "ltp": 2.82, "tv": 764.91, "trd": NaN, "batb": [[0, 2.82, 396.9]], "batl": NaN}, {"timestamp": 1578763673607, "ltp": 2.82, "tv": 764.91, "trd": NaN, "batb": [[0, 2.82, 391.41]], "batl": NaN}, {"timestamp": 1578763679544, "ltp": 2.82, "tv": 764.91, "trd": NaN, "batb": [[0, 2.82, 396.9]], "batl": NaN}, {"timestamp": 1578763693026, "ltp": 2.82, "tv": 764.91, "trd": NaN, "batb": [[0, 2.82, 391.41]], "batl": NaN}, {"timestamp": 1578763724553, "ltp": 2.82, "tv": 764.91, "trd": NaN, "batb": [[0, 2.82, 396.9]], "batl": NaN}, {"timestamp": 1578763751032, "ltp": 2.82, "tv": 764.91, "trd": NaN, "batb": [[0, 2.82, 391.41]], "batl": NaN}, {"timestamp": 1578764024393, "ltp": 2.82, "tv": 764.91, "trd": NaN, "batb": NaN, "batl": [[2, 3, 1.06]]}, {"timestamp": 1578764061943, "ltp": 2.82, "tv": 764.91, "trd": NaN, "batb": [[0, 2.82, 418.65]], "batl": NaN}, {"timestamp": 1578764072367, "ltp": 2.82, "tv": 764.91, "trd": NaN, "batb": NaN, "batl": [[1, 3, 1.06], [2, 3.05, 159.3]]}, {"timestamp": 1578764073974, "ltp": 2.82, "tv": 764.91, "trd": NaN, "batb": NaN, "batl": [[0, 3, 9.57], [1, 3.05, 159.3], [2, 3.15, 784.81]]}, {"timestamp": 1578764085990, "ltp": 2.82, "tv": 764.91, "trd": NaN, "batb": NaN, "batl": [[0, 2.98, 10.55], [1, 3, 9.57], [2, 3.05, 159.3]]}, {"timestamp": 1578764098890, "ltp": 2.82, "tv": 764.91, "trd": NaN, "batb": NaN, "batl": [[1, 3, 778.21]]}, {"timestamp": 1578764215044, "ltp": 2.82, "tv": 764.91, "trd": NaN, "batb": NaN, "batl": [[1, 3, 725.43]]}, {"timestamp": 1578764226021, "ltp": 2.82, "tv": 764.91, "trd": NaN, "batb": NaN, "batl": [[1, 3, 678.62]]}, {"timestamp": 1578764260990, "ltp": 2.82, "tv": 764.91, "trd": NaN, "batb": NaN, "batl": [[1, 3, 739.9]]}, {"timestamp": 1578764422986, "ltp": 2.82, "tv": 764.91, "trd": NaN, "batb": NaN, "batl": [[1, 3, 783.32]]}, {"timestamp": 1578764482853, "ltp": 2.82, "tv": 764.91, "trd": NaN, "batb": NaN, "batl": [[2, 3.1, 159.25]]}, {"timestamp": 1578764486967, "ltp": 2.82, "tv": 764.91, "trd": NaN, "batb": [[0, 2.82, 441.63]], "batl": NaN}, {"timestamp": 1578764487767, "ltp": 2.82, "tv": 764.91, "trd": NaN, "batb": [[1, 2.78, 25.06]], "batl": NaN}, {"timestamp": 1578764505989, "ltp": 2.82, "tv": 764.91, "trd": NaN, "batb": NaN, "batl": [[2, 3.05, 159.3]]}, {"timestamp": 1578764521006, "ltp": 2.82, "tv": 764.91, "trd": NaN, "batb": NaN, "batl": [[2, 3.1, 159.25]]}, {"timestamp": 1578764521976, "ltp": 2.82, "tv": 764.91, "trd": NaN, "batb": NaN, "batl": [[2, 3.05, 159.3]]}, {"timestamp": 1578764524000, "ltp": 2.82, "tv": 764.91, "trd": NaN, "batb": NaN, "batl": [[2, 3.1, 159.25]]}, {"timestamp": 1578764524903, "ltp": 2.82, "tv": 764.91, "trd": NaN, "batb": [[0, 2.82, 447.12]], "batl": NaN}, {"timestamp": 1578764531035, "ltp": 2.82, "tv": 764.91, "trd": NaN, "batb": [[0, 2.84, 16.2], [1, 2.82, 447.12], [2, 2.78, 25.06]], "batl": NaN}, {"timestamp": 1578764532014, "ltp": 2.82, "tv": 764.91, "trd": NaN, "batb": [[0, 2.84, 102.67], [1, 2.82, 359.59]], "batl": NaN}, {"timestamp": 1578764534006, "ltp": 2.82, "tv": 764.91, "trd": NaN, "batb": [[1, 2.82, 354.1]], "batl": NaN}, {"timestamp": 1578764537985, "ltp": 2.82, "tv": 764.91, "trd": NaN, "batb": [[1, 2.82, 406.88]], "batl": NaN}, {"timestamp": 1578764541010, "ltp": 2.82, "tv": 764.91, "trd": NaN, "batb": [[1, 2.82, 446.03]], "batl": NaN}, {"timestamp": 1578764552809, "ltp": 2.82, "tv": 764.91, "trd": NaN, "batb": [[0, 2.86, 23.99], [1, 2.84, 102.67], [2, 2.82, 446.03]], "batl": NaN}, {"timestamp": 1578764557898, "ltp": 2.82, "tv": 764.91, "trd": NaN, "batb": NaN, "batl": [[1, 3, 739.05]]}, {"timestamp": 1578764602055, "ltp": 2.82, "tv": 764.91, "trd": NaN, "batb": [[1, 2.84, 16.2], [2, 2.82, 533.56]], "batl": [[2, 3.05, 159.3]]}, {"timestamp": 1578764616886, "ltp": 2.82, "tv": 764.91, "trd": NaN, "batb": [[1, 2.84, 315.83]], "batl": NaN}, {"timestamp": 1578764618054, "ltp": 2.82, "tv": 764.91, "trd": NaN, "batb": [[1, 2.84, 402.3], [2, 2.82, 446.03]], "batl": NaN}, {"timestamp": 1578764619872, "ltp": 2.82, "tv": 764.91, "trd": NaN, "batb": [[1, 2.84, 315.83], [2, 2.82, 533.56]], "batl": NaN}, {"timestamp": 1578764624005, "ltp": 2.82, "tv": 764.91, "trd": NaN, "batb": [[1, 2.84, 356.68]], "batl": NaN}, {"timestamp": 1578764658833, "ltp": 2.82, "tv": 764.91, "trd": NaN, "batb": [[2, 2.82, 110.51]], "batl": [[1, 3, 640.31]]}, {"timestamp": 1578764660908, "ltp": 2.82, "tv": 764.91, "trd": NaN, "batb": NaN, "batl": [[0, 3, 640.31], [1, 3.05, 159.3], [2, 3.15, 19.58]]}, {"timestamp": 1578764668945, "ltp": 2.82, "tv": 764.91, "trd": NaN, "batb": [[1, 2.84, 443.15], [2, 2.82, 22.98]], "batl": NaN}, {"timestamp": 1578764694041, "ltp": 2.82, "tv": 764.91, "trd": NaN, "batb": NaN, "batl": [[0, 2.98, 10.55], [1, 3, 640.31], [2, 3.05, 159.3]]}, {"timestamp": 1578764754027, "ltp": 2.82, "tv": 764.91, "trd": NaN, "batb": [[1, 2.84, 356.68], [2, 2.82, 110.51]], "batl": NaN}, {"timestamp": 1578764779034, "ltp": 2.82, "tv": 764.91, "trd": NaN, "batb": [[1, 2.84, 443.15], [2, 2.82, 22.98]], "batl": NaN}, {"timestamp": 1578764808997, "ltp": 2.82, "tv": 764.91, "trd": NaN, "batb": [[1, 2.84, 356.68], [2, 2.82, 110.51]], "batl": NaN}, {"timestamp": 1578764857016, "ltp": 2.82, "tv": 764.91, "trd": NaN, "batb": [[1, 2.84, 443.15]], "batl": NaN}, {"timestamp": 1578764858018, "ltp": 2.82, "tv": 764.91, "trd": NaN, "batb": [[2, 2.82, 22.98]], "batl": [[2, 3.1, 159.25]]}, {"timestamp": 1578764860036, "ltp": 2.82, "tv": 764.91, "trd": NaN, "batb": NaN, "batl": [[2, 3.05, 159.3]]}, {"timestamp": 1578765137570, "ltp": 2.82, "tv": 764.91, "trd": NaN, "batb": NaN, "batl": [[2, 3.1, 159.25]]}, {"timestamp": 1578765193991, "ltp": 2.82, "tv": 764.91, "trd": NaN, "batb": NaN, "batl": [[1, 3, 685.43]]}, {"timestamp": 1578765199002, "ltp": 2.82, "tv": 764.91, "trd": NaN, "batb": NaN, "batl": [[2, 3.05, 851.21]]}, {"timestamp": 1578765224956, "ltp": 2.82, "tv": 764.91, "trd": NaN, "batb": NaN, "batl": [[2, 3.1, 159.25]]}, {"timestamp": 1578765269781, "ltp": 2.82, "tv": 764.91, "trd": NaN, "batb": NaN, "batl": [[0, 3, 685.43], [1, 3.1, 159.25], [2, 3.15, 19.58]]}, {"timestamp": 1578765295027, "ltp": 2.82, "tv": 764.91, "trd": NaN, "batb": NaN, "batl": [[1, 3.05, 857.17], [2, 3.1, 159.25]]}, {"timestamp": 1578765320873, "ltp": 2.82, "tv": 764.91, "trd": NaN, "batb": NaN, "batl": [[0, 2.98, 10.55], [1, 3, 685.43], [2, 3.05, 857.17]]}, {"timestamp": 1578765321775, "ltp": 2.82, "tv": 764.91, "trd": NaN, "batb": NaN, "batl": [[1, 3, 9.57]]}, {"timestamp": 1578765352123, "ltp": 2.82, "tv": 764.91, "trd": NaN, "batb": NaN, "batl": [[0, 2.98, 557.03]]}, {"timestamp": 1578765353928, "ltp": 2.82, "tv": 764.91, "trd": NaN, "batb": NaN, "batl": [[0, 2.96, 8.51], [1, 2.98, 557.03], [2, 3, 1.06]]}, {"timestamp": 1578765378054, "ltp": 2.82, "tv": 764.91, "trd": NaN, "batb": [[1, 2.84, 356.68]], "batl": NaN}, {"timestamp": 1578765450985, "ltp": 2.82, "tv": 764.91, "trd": NaN, "batb": [[1, 2.84, 340.48]], "batl": NaN}, {"timestamp": 1578765484034, "ltp": 2.82, "tv": 764.91, "trd": NaN, "batb": [[1, 2.84, 426.95]], "batl": NaN}, {"timestamp": 1578765514028, "ltp": 2.82, "tv": 764.91, "trd": NaN, "batb": [[1, 2.84, 340.48], [2, 2.82, 110.51]], "batl": NaN}, {"timestamp": 1578765576996, "ltp": 2.82, "tv": 764.91, "trd": NaN, "batb": [[1, 2.84, 300.48]], "batl": [[1, 2.98, 608.95]]}, {"timestamp": 1578765651008, "ltp": 2.82, "tv": 764.91, "trd": NaN, "batb": [[2, 2.82, 533.56]], "batl": NaN}, {"timestamp": 1578765682053, "ltp": 2.82, "tv": 764.91, "trd": NaN, "batb": [[1, 2.82, 533.56], [2, 2.82, 0]], "batl": NaN}, {"timestamp": 1578765700031, "ltp": 2.82, "tv": 764.91, "trd": NaN, "batb": [[1, 2.84, 16.42], [2, 2.82, 533.56]], "batl": NaN}, {"timestamp": 1578765896447, "ltp": 2.82, "tv": 764.91, "trd": NaN, "batb": NaN, "batl": [[1, 2.98, 598.4]]}, {"timestamp": 1578765961026, "ltp": 2.82, "tv": 764.91, "trd": NaN, "batb": NaN, "batl": [[1, 3, 1.06], [2, 3.05, 159.3]]}, {"timestamp": 1578765961995, "ltp": 2.82, "tv": 764.91, "trd": NaN, "batb": NaN, "batl": [[0, 3, 9.57], [1, 3.05, 159.3], [2, 3.15, 19.58]]}, {"timestamp": 1578765967028, "ltp": 2.82, "tv": 764.91, "trd": NaN, "batb": NaN, "batl": [[0, 2.96, 501.36], [1, 3, 9.57], [2, 3.05, 159.3]]}, {"timestamp": 1578765970033, "ltp": 2.82, "tv": 764.91, "trd": NaN, "batb": NaN, "batl": [[2, 3.05, 173.86]]}, {"timestamp": 1578765972005, "ltp": 2.82, "tv": 764.91, "trd": NaN, "batb": [[1, 2.84, 32.02]], "batl": NaN}, {"timestamp": 1578765977929, "ltp": 2.82, "tv": 764.91, "trd": NaN, "batb": NaN, "batl": [[1, 3, 743.31]]}, {"timestamp": 1578765979053, "ltp": 2.82, "tv": 764.91, "trd": NaN, "batb": [[2, 2.82, 446.03]], "batl": NaN}, {"timestamp": 1578765986009, "ltp": 2.82, "tv": 764.91, "trd": NaN, "batb": NaN, "batl": [[0, 2.94, 8.51], [1, 2.96, 501.36], [2, 3, 743.31]]}, {"timestamp": 1578765987040, "ltp": 2.82, "tv": 764.91, "trd": NaN, "batb": NaN, "batl": [[2, 3, 734.8]]}, {"timestamp": 1578765992868, "ltp": 2.82, "tv": 764.91, "trd": NaN, "batb": NaN, "batl": [[1, 3, 734.8], [2, 3.05, 173.86]]}, {"timestamp": 1578765995536, "ltp": 2.82, "tv": 764.91, "trd": NaN, "batb": NaN, "batl": [[0, 2.98, 8.51]]}, {"timestamp": 1578766014496, "ltp": 2.82, "tv": 764.91, "trd": NaN, "batb": NaN, "batl": [[0, 2.94, 379.64], [1, 2.98, 8.51], [2, 3, 734.8]]}, {"timestamp": 1578766015708, "ltp": 2.82, "tv": 764.91, "trd": NaN, "batb": NaN, "batl": [[0, 2.92, 8.51], [1, 2.94, 379.64]]}, {"timestamp": 1578766040922, "ltp": 2.82, "tv": 764.91, "trd": NaN, "batb": NaN, "batl": [[1, 3, 1.06], [2, 3.05, 173.86]]}, {"timestamp": 1578766042963, "ltp": 2.82, "tv": 764.91, "trd": NaN, "batb": NaN, "batl": [[0, 3, 9.57], [1, 3.05, 173.86], [2, 3.15, 19.58]]}, {"timestamp": 1578766054838, "ltp": 2.82, "tv": 764.91, "trd": NaN, "batb": NaN, "batl": [[0, 2.98, 10.55], [1, 3, 9.57], [2, 3.05, 173.86]]}, {"timestamp": 1578766071951, "ltp": 2.82, "tv": 764.91, "trd": NaN, "batb": NaN, "batl": [[0, 2.98, 646.4]]}, {"timestamp": 1578766073740, "ltp": 2.82, "tv": 764.91, "trd": NaN, "batb": NaN, "batl": [[0, 2.96, 8.51], [1, 2.98, 646.4], [2, 3, 1.06]]}, {"timestamp": 1578766110845, "ltp": 2.82, "tv": 764.91, "trd": NaN, "batb": [[0, 2.88, 8.35], [1, 2.86, 32.4], [2, 2.84, 32.02]], "batl": [[0, 2.94, 8.18], [1, 2.96, 16.64], [2, 2.98, 646.4]]}, {"timestamp": 1578766162877, "ltp": 2.82, "tv": 764.91, "trd": NaN, "batb": NaN, "batl": [[0, 2.94, 381.01]]}, {"timestamp": 1578766164049, "ltp": 2.82, "tv": 764.91, "trd": NaN, "batb": NaN, "batl": [[0, 2.92, 16.38], [1, 2.94, 381.01], [2, 2.96, 8.13]]}, {"timestamp": 1578766164900, "ltp": 2.82, "tv": 764.91, "trd": NaN, "batb": NaN, "batl": [[0, 2.92, 24.89]]}, {"timestamp": 1578766216759, "ltp": 2.82, "tv": 764.91, "trd": NaN, "batb": [[0, 2.86, 32.4], [1, 2.84, 19.06], [2, 2.82, 533.56]], "batl": NaN}, {"timestamp": 1578766230696, "ltp": 2.82, "tv": 764.91, "trd": NaN, "batb": [[2, 2.82, 496.11]], "batl": NaN}, {"timestamp": 1578766256031, "ltp": 2.82, "tv": 764.91, "trd": NaN, "batb": [[2, 2.82, 408.58]], "batl": NaN}, {"timestamp": 1578766274852, "ltp": 2.92, "tv": 773.26, "trd": [[2.92, 8.36]], "batb": NaN, "batl": [[0, 2.92, 20.71]]}, {"timestamp": 1578766275766, "ltp": 2.92, "tv": 773.26, "trd": NaN, "batb": [[0, 2.88, 2.6], [1, 2.86, 32.4], [2, 2.84, 19.06]], "batl": [[0, 2.92, 8.51]]}, {"timestamp": 1578766277365, "ltp": 2.92, "tv": 773.26, "trd": NaN, "batb": NaN, "batl": [[0, 2.92, 11.08]]}, {"timestamp": 1578766324055, "ltp": 2.84, "tv": 881.33, "trd": [[2.84, 611.44], [2.86, 114.08], [2.88, 52.87]], "batb": [[0, 2.82, 408.61], [1, 2.8, 88.38], [2, 2.78, 15.62]], "batl": NaN}, {"timestamp": 1578766324914, "ltp": 2.84, "tv": 881.33, "trd": NaN, "batb": [[0, 2.82, 412.61], [1, 2.8, 92.44]], "batl": [[0, 2.9, 3.92], [1, 2.92, 11.08], [2, 2.94, 381.01]]}, {"timestamp": 1578766336020, "ltp": 2.84, "tv": 881.33, "trd": NaN, "batb": [[0, 2.84, 16.49], [1, 2.82, 412.61], [2, 2.8, 92.44]], "batl": NaN}, {"timestamp": 1578766414828, "ltp": 2.84, "tv": 881.33, "trd": NaN, "batb": [[0, 2.84, 20.66]], "batl": NaN}, {"timestamp": 1578766423018, "ltp": 2.84, "tv": 881.33, "trd": NaN, "batb": [[1, 2.82, 500.14], [2, 2.8, 4.06]], "batl": NaN}, {"timestamp": 1578766429569, "ltp": 2.84, "tv": 881.33, "trd": NaN, "batb": NaN, "batl": [[0, 2.9, 7.92]]}, {"timestamp": 1578766438964, "ltp": 2.84, "tv": 881.33, "trd": NaN, "batb": NaN, "batl": [[1, 2.92, 298.79]]}, {"timestamp": 1578766440868, "ltp": 2.84, "tv": 881.33, "trd": NaN, "batb": NaN, "batl": [[0, 2.9, 3.92]]}, {"timestamp": 1578766444041, "ltp": 2.84, "tv": 881.33, "trd": NaN, "batb": NaN, "batl": [[1, 2.92, 11.08], [2, 2.94, 8.18]]}, {"timestamp": 1578766445860, "ltp": 2.84, "tv": 889.33, "trd": [[2.84, 619.44]], "batb": [[0, 2.84, 16.66]], "batl": [[1, 2.92, 2.57]]}, {"timestamp": 1578766455053, "ltp": 2.84, "tv": 889.33, "trd": NaN, "batb": NaN, "batl": [[1, 2.92, 292.83]]}, {"timestamp": 1578766457668, "ltp": 2.84, "tv": 889.33, "trd": NaN, "batb": NaN, "batl": [[0, 2.9, 12.82]]}, {"timestamp": 1578766458887, "ltp": 2.84, "tv": 889.33, "trd": NaN, "batb": NaN, "batl": [[0, 2.88, 2.61], [1, 2.9, 12.82], [2, 2.92, 292.83]]}, {"timestamp": 1578766488797, "ltp": 2.84, "tv": 917.33, "trd": [[2.84, 647.43]], "batb": [[0, 2.84, 2.66]], "batl": NaN}, {"timestamp": 1578766489923, "ltp": 2.84, "tv": 917.33, "trd": NaN, "batb": [[0, 2.82, 500.14], [1, 2.8, 4.06], [2, 2.78, 15.62]], "batl": NaN}, {"timestamp": 1578766501015, "ltp": 2.84, "tv": 917.33, "trd": NaN, "batb": [[0, 2.84, 16.49], [1, 2.82, 500.14], [2, 2.8, 4.06]], "batl": NaN}, {"timestamp": 1578766506837, "ltp": 2.84, "tv": 927.33, "trd": [[2.84, 657.43]], "batb": [[0, 2.84, 11.49]], "batl": NaN}, {"timestamp": 1578766566717, "ltp": 2.84, "tv": 949.83, "trd": [[2.84, 679.93]], "batb": [[0, 2.82, 500.38], [1, 2.8, 4.06], [2, 2.78, 15.62]], "batl": NaN}, {"timestamp": 1578766588963, "ltp": 2.84, "tv": 949.83, "trd": NaN, "batb": [[0, 2.82, 500.14]], "batl": NaN}, {"timestamp": 1578766630905, "ltp": 2.84, "tv": 949.83, "trd": NaN, "batb": [[0, 2.84, 2.66], [1, 2.82, 500.14], [2, 2.8, 4.06]], "batl": NaN}, {"timestamp": 1578766786922, "ltp": 2.84, "tv": 949.83, "trd": NaN, "batb": [[1, 2.82, 412.61], [2, 2.8, 92.44]], "batl": NaN}, {"timestamp": 1578766804047, "ltp": 2.84, "tv": 949.83, "trd": NaN, "batb": [[1, 2.82, 500.14], [2, 2.8, 4.06]], "batl": NaN}, {"timestamp": 1578767037747, "ltp": 2.84, "tv": 949.83, "trd": NaN, "batb": [[0, 2.84, 19.19]], "batl": NaN}, {"timestamp": 1578767101032, "ltp": 2.84, "tv": 949.83, "trd": NaN, "batb": NaN, "batl": [[2, 2.92, 2.57]]}, {"timestamp": 1578767121545, "ltp": 2.84, "tv": 953.57, "trd": [[2.84, 683.68]], "batb": [[0, 2.84, 17.32]], "batl": NaN}, {"timestamp": 1578767122763, "ltp": 2.84, "tv": 953.57, "trd": NaN, "batb": [[0, 2.84, 16.53]], "batl": NaN}, {"timestamp": 1578767254611, "ltp": 2.84, "tv": 953.57, "trd": NaN, "batb": [[2, 2.8, 4.27]], "batl": NaN}, {"timestamp": 1578767256785, "ltp": 2.84, "tv": 953.57, "trd": NaN, "batb": [[0, 2.84, 19.22]], "batl": NaN}, {"timestamp": 1578767608012, "ltp": 2.84, "tv": 953.57, "trd": NaN, "batb": NaN, "batl": [[2, 2.92, 300.49]]}, {"timestamp": 1578767608905, "ltp": 2.84, "tv": 953.57, "trd": NaN, "batb": NaN, "batl": [[0, 2.9, 12.82], [1, 2.92, 300.49], [2, 2.94, 8.18]]}, {"timestamp": 1578767619016, "ltp": 2.84, "tv": 953.57, "trd": NaN, "batb": NaN, "batl": [[1, 2.92, 2.57]]}, {"timestamp": 1578767621025, "ltp": 2.84, "tv": 953.57, "trd": NaN, "batb": NaN, "batl": [[0, 2.9, 3.92]]}, {"timestamp": 1578767627521, "ltp": 2.84, "tv": 953.57, "trd": NaN, "batb": NaN, "batl": [[1, 2.92, 298.79]]}, {"timestamp": 1578767628942, "ltp": 2.84, "tv": 953.57, "trd": NaN, "batb": NaN, "batl": [[0, 2.9, 13.46]]}, {"timestamp": 1578767630016, "ltp": 2.84, "tv": 953.57, "trd": NaN, "batb": NaN, "batl": [[0, 2.88, 2.66], [1, 2.9, 13.46], [2, 2.92, 298.79]]}, {"timestamp": 1578767632017, "ltp": 2.84, "tv": 953.57, "trd": NaN, "batb": NaN, "batl": [[2, 2.92, 333.69]]}, {"timestamp": 1578767635043, "ltp": 2.84, "tv": 953.57, "trd": NaN, "batb": [[0, 2.84, 2.69]], "batl": NaN}, {"timestamp": 1578767637056, "ltp": 2.84, "tv": 953.57, "trd": NaN, "batb": NaN, "batl": [[2, 2.92, 2.57]]}, {"timestamp": 1578767637953, "ltp": 2.84, "tv": 953.57, "trd": NaN, "batb": [[1, 2.82, 455.88]], "batl": NaN}, {"timestamp": 1578767639010, "ltp": 2.84, "tv": 953.57, "trd": NaN, "batb": NaN, "batl": [[1, 2.9, 3.92]]}, {"timestamp": 1578767712650, "ltp": 2.84, "tv": 953.57, "trd": NaN, "batb": [[1, 2.82, 199.67]], "batl": NaN}, {"timestamp": 1578767749497, "ltp": 2.84, "tv": 953.57, "trd": NaN, "batb": [[1, 2.82, 191.16]], "batl": NaN}, {"timestamp": 1578767811963, "ltp": 2.84, "tv": 953.57, "trd": NaN, "batb": [[1, 2.82, 201.37]], "batl": NaN}, {"timestamp": 1578768049554, "ltp": 2.84, "tv": 953.57, "trd": NaN, "batb": [[1, 2.82, 192.86]], "batl": NaN}, {"timestamp": 1578768077021, "ltp": 2.84, "tv": 953.57, "trd": NaN, "batb": [[0, 2.84, 19.41]], "batl": NaN}, {"timestamp": 1578768111872, "ltp": 2.84, "tv": 953.57, "trd": NaN, "batb": [[1, 2.82, 200.52]], "batl": NaN}, {"timestamp": 1578768133647, "ltp": 2.84, "tv": 953.57, "trd": NaN, "batb": [[1, 2.82, 112.99], [2, 2.8, 92.65]], "batl": NaN}, {"timestamp": 1578768202927, "ltp": 2.84, "tv": 953.57, "trd": NaN, "batb": [[0, 2.84, 2.69]], "batl": NaN}, {"timestamp": 1578768302899, "ltp": 2.84, "tv": 953.57, "trd": NaN, "batb": [[0, 2.84, 3.85]], "batl": NaN}, {"timestamp": 1578768306001, "ltp": 2.84, "tv": 953.57, "trd": NaN, "batb": [[1, 2.82, 200.52]], "batl": NaN}, {"timestamp": 1578768306970, "ltp": 2.84, "tv": 953.57, "trd": NaN, "batb": [[2, 2.8, 4.06]], "batl": NaN}, {"timestamp": 1578768406694, "ltp": 2.84, "tv": 953.57, "trd": NaN, "batb": NaN, "batl": [[2, 2.92, 69.82]]}, {"timestamp": 1578768536985, "ltp": 2.84, "tv": 953.57, "trd": NaN, "batb": NaN, "batl": [[2, 2.92, 2.57]]}, {"timestamp": 1578768537672, "ltp": 2.84, "tv": 953.57, "trd": NaN, "batb": [[1, 2.82, 192.86]], "batl": NaN}, {"timestamp": 1578768541965, "ltp": 2.84, "tv": 953.57, "trd": NaN, "batb": [[0, 2.84, 20.78]], "batl": NaN}, {"timestamp": 1578768644712, "ltp": 2.84, "tv": 953.57, "trd": NaN, "batb": [[1, 2.82, 105.33], [2, 2.8, 92.44]], "batl": NaN}, {"timestamp": 1578768647010, "ltp": 2.84, "tv": 953.57, "trd": NaN, "batb": [[0, 2.84, 16.93]], "batl": NaN}, {"timestamp": 1578768647794, "ltp": 2.84, "tv": 953.57, "trd": NaN, "batb": [[0, 2.84, 20.77]], "batl": NaN}, {"timestamp": 1578768678894, "ltp": 2.84, "tv": 953.57, "trd": NaN, "batb": [[0, 2.84, 16.93], [1, 2.82, 82.35]], "batl": NaN}, {"timestamp": 1578768683915, "ltp": 2.84, "tv": 953.57, "trd": NaN, "batb": [[1, 2.82, 105.33]], "batl": NaN}, {"timestamp": 1578768684810, "ltp": 2.84, "tv": 953.57, "trd": NaN, "batb": [[0, 2.84, 20.77]], "batl": NaN}, {"timestamp": 1578768748002, "ltp": 2.84, "tv": 953.57, "trd": NaN, "batb": [[0, 2.84, 3.84]], "batl": NaN}, {"timestamp": 1578768776957, "ltp": 2.84, "tv": 953.57, "trd": NaN, "batb": [[2, 2.8, 4.06]], "batl": NaN}, {"timestamp": 1578768793970, "ltp": 2.84, "tv": 953.57, "trd": NaN, "batb": [[0, 2.82, 105.33], [1, 2.8, 4.06], [2, 2.78, 105.6]], "batl": NaN}, {"timestamp": 1578768801682, "ltp": 2.84, "tv": 953.57, "trd": NaN, "batb": [[0, 2.82, 110.82]], "batl": NaN}, {"timestamp": 1578768803055, "ltp": 2.84, "tv": 953.57, "trd": NaN, "batb": [[0, 2.84, 4.37], [1, 2.82, 110.82], [2, 2.8, 4.06]], "batl": NaN}, {"timestamp": 1578768803986, "ltp": 2.84, "tv": 953.57, "trd": NaN, "batb": [[2, 2.8, 92.84]], "batl": NaN}, {"timestamp": 1578768804876, "ltp": 2.84, "tv": 953.57, "trd": NaN, "batb": [[0, 2.84, 3.85]], "batl": NaN}, {"timestamp": 1578768816004, "ltp": 2.84, "tv": 953.57, "trd": NaN, "batb": [[2, 2.8, 4.06]], "batl": NaN}, {"timestamp": 1578768818609, "ltp": 2.84, "tv": 953.57, "trd": NaN, "batb": [[0, 2.82, 110.82], [1, 2.8, 4.06], [2, 2.78, 105.6]], "batl": NaN}, {"timestamp": 1578768883697, "ltp": 2.84, "tv": 953.57, "trd": NaN, "batb": [[0, 2.84, 4.37], [1, 2.82, 110.82], [2, 2.8, 4.06]], "batl": NaN}, {"timestamp": 1578768888021, "ltp": 2.84, "tv": 953.57, "trd": NaN, "batb": [[0, 2.82, 110.82], [1, 2.8, 4.06], [2, 2.78, 105.6]], "batl": NaN}, {"timestamp": 1578768944983, "ltp": 2.84, "tv": 953.57, "trd": NaN, "batb": [[0, 2.82, 105.33]], "batl": NaN}, {"timestamp": 1578769006952, "ltp": 2.84, "tv": 953.57, "trd": NaN, "batb": [[0, 2.82, 27.02], [1, 2.8, 88.33]], "batl": NaN}, {"timestamp": 1578769012962, "ltp": 2.84, "tv": 953.57, "trd": NaN, "batb": [[2, 2.78, 15.62]], "batl": NaN}, {"timestamp": 1578769034992, "ltp": 2.84, "tv": 953.57, "trd": NaN, "batb": [[2, 2.78, 105.6]], "batl": NaN}, {"timestamp": 1578769047029, "ltp": 2.84, "tv": 953.57, "trd": NaN, "batb": [[1, 2.8, 177.11], [2, 2.78, 15.62]], "batl": NaN}, {"timestamp": 1578769048917, "ltp": 2.84, "tv": 953.57, "trd": NaN, "batb": [[0, 2.84, 86.82], [1, 2.82, 27.02], [2, 2.8, 177.11]], "batl": NaN}, {"timestamp": 1578769049920, "ltp": 2.84, "tv": 953.57, "trd": NaN, "batb": [[0, 2.84, 90.44]], "batl": NaN}, {"timestamp": 1578769053027, "ltp": 2.84, "tv": 953.57, "trd": NaN, "batb": [[2, 2.8, 88.33]], "batl": NaN}, {"timestamp": 1578769055036, "ltp": 2.88, "tv": 958.9, "trd": [[2.88, 58.2]], "batb": [[0, 2.88, 83.31], [1, 2.84, 90.44], [2, 2.82, 27.02]], "batl": [[0, 2.9, 3.92], [1, 2.92, 2.57], [2, 2.94, 8.18]]}, {"timestamp": 1578769056046, "ltp": 2.88, "tv": 958.9, "trd": NaN, "batb": [[1, 2.86, 3.54], [2, 2.84, 90.44]], "batl": [[0, 2.92, 2.57], [1, 2.94, 8.18], [2, 2.96, 15.42]]}, {"timestamp": 1578769057044, "ltp": 2.88, "tv": 958.9, "trd": NaN, "batb": [[2, 2.84, 140.91]], "batl": [[0, 2.94, 8.18], [1, 2.96, 3.6], [2, 2.98, 160.23]]}, {"timestamp": 1578769058039, "ltp": 2.88, "tv": 958.9, "trd": NaN, "batb": NaN, "batl": [[2, 3, 160.23]]}, {"timestamp": 1578769059046, "ltp": 2.86, "tv": 965.54, "trd": [[2.86, 120.72]], "batb": [[0, 2.84, 20.26], [1, 2.82, 27.02], [2, 2.8, 4.06]], "batl": NaN}, {"timestamp": 1578769060056, "ltp": 2.86, "tv": 965.54, "trd": NaN, "batb": [[0, 2.84, 20.04], [1, 2.82, 113.84]], "batl": [[2, 3.05, 14.56]]}, {"timestamp": 1578769061049, "ltp": 2.86, "tv": 965.54, "trd": NaN, "batb": [[0, 2.84, 16.42]], "batl": NaN}, {"timestamp": 1578769061951, "ltp": 2.86, "tv": 965.54, "trd": NaN, "batb": [[0, 2.82, 113.84], [1, 2.8, 4.06], [2, 2.78, 15.62]], "batl": NaN}, {"timestamp": 1578769063046, "ltp": 2.86, "tv": 965.54, "trd": NaN, "batb": [[0, 2.82, 200.66]], "batl": NaN}, {"timestamp": 1578769066950, "ltp": 2.86, "tv": 965.54, "trd": NaN, "batb": NaN, "batl": [[2, 2.98, 161.18]]}, {"timestamp": 1578769067694, "ltp": 2.86, "tv": 965.54, "trd": NaN, "batb": [[0, 2.84, 2.8], [1, 2.82, 200.66], [2, 2.8, 4.06]], "batl": NaN}, {"timestamp": 1578769071789, "ltp": 2.86, "tv": 965.54, "trd": NaN, "batb": [[1, 2.82, 113.84]], "batl": [[1, 2.96, 125.32]]}, {"timestamp": 1578769086908, "ltp": 2.86, "tv": 965.54, "trd": NaN, "batb": NaN, "batl": [[0, 2.94, 95]]}, {"timestamp": 1578769088017, "ltp": 2.86, "tv": 965.54, "trd": NaN, "batb": NaN, "batl": [[0, 2.92, 5.08], [1, 2.94, 95], [2, 2.96, 125.32]]}, {"timestamp": 1578769107018, "ltp": 2.86, "tv": 965.54, "trd": NaN, "batb": [[2, 2.8, 93.39]], "batl": [[2, 2.96, 3.6]]}, {"timestamp": 1578769113047, "ltp": 2.86, "tv": 965.54, "trd": NaN, "batb": [[0, 2.84, 20.06]], "batl": NaN}, {"timestamp": 1578769209872, "ltp": 2.86, "tv": 965.54, "trd": [[2.82, 80]], "batb": NaN, "batl": NaN}, {"timestamp": 1578769210755, "ltp": 2.86, "tv": 965.54, "trd": NaN, "batb": [[0, 2.84, 17.26]], "batl": NaN}, {"timestamp": 1578769214947, "ltp": 2.86, "tv": 965.54, "trd": NaN, "batb": [[0, 2.84, 21.24]], "batl": NaN}, {"timestamp": 1578769299899, "ltp": 2.86, "tv": 965.54, "trd": NaN, "batb": [[2, 2.8, 4.06]], "batl": NaN}, {"timestamp": 1578769306899, "ltp": 2.86, "tv": 965.54, "trd": NaN, "batb": [[0, 2.84, 17.26]], "batl": NaN}, {"timestamp": 1578769307996, "ltp": 2.86, "tv": 965.54, "trd": NaN, "batb": [[0, 2.84, 20.09]], "batl": NaN}, {"timestamp": 1578769310000, "ltp": 2.86, "tv": 965.54, "trd": NaN, "batb": [[0, 2.84, 17.26]], "batl": NaN}, {"timestamp": 1578769315027, "ltp": 2.86, "tv": 965.54, "trd": NaN, "batb": [[0, 2.84, 20.09]], "batl": NaN}, {"timestamp": 1578769317043, "ltp": 2.86, "tv": 965.54, "trd": NaN, "batb": [[2, 2.8, 93.39]], "batl": NaN}, {"timestamp": 1578769364013, "ltp": 2.86, "tv": 965.54, "trd": NaN, "batb": [[2, 2.8, 4.06]], "batl": NaN}, {"timestamp": 1578769436986, "ltp": 2.86, "tv": 965.54, "trd": NaN, "batb": [[2, 2.8, 93.39]], "batl": NaN}, {"timestamp": 1578769471016, "ltp": 2.82, "tv": 1109.71, "trd": [[2.82, 183.99], [2.84, 723.85]], "batb": [[0, 2.82, 84.82], [1, 2.8, 89.33], [2, 2.78, 18.53]], "batl": NaN}, {"timestamp": 1578769472011, "ltp": 2.82, "tv": 1109.71, "trd": NaN, "batb": [[1, 2.8, 92.97]], "batl": NaN}, {"timestamp": 1578769474025, "ltp": 2.82, "tv": 1109.71, "trd": NaN, "batb": [[0, 2.82, 22.98], [1, 2.8, 89.33]], "batl": [[1, 2.94, 8.18]]}, {"timestamp": 1578769474918, "ltp": 2.82, "tv": 1109.71, "trd": NaN, "batb": [[1, 2.8, 176.49]], "batl": [[1, 2.94, 49.04]]}, {"timestamp": 1578769478950, "ltp": 2.82, "tv": 1109.71, "trd": NaN, "batb": [[0, 2.82, 28.47], [1, 2.8, 92.22]], "batl": [[1, 2.94, 8.18]]}, {"timestamp": 1578769480836, "ltp": 2.82, "tv": 1109.71, "trd": NaN, "batb": [[1, 2.8, 178.19]], "batl": [[1, 2.94, 43.08]]}, {"timestamp": 1578769486053, "ltp": 2.82, "tv": 1109.71, "trd": NaN, "batb": [[0, 2.82, 45.99]], "batl": NaN}, {"timestamp": 1578769492935, "ltp": 2.82, "tv": 1109.71, "trd": NaN, "batb": [[0, 2.82, 48.86]], "batl": [[1, 2.94, 132.46]]}, {"timestamp": 1578769495867, "ltp": 2.82, "tv": 1109.71, "trd": NaN, "batb": NaN, "batl": [[2, 2.96, 18.71]]}, {"timestamp": 1578769531034, "ltp": 2.82, "tv": 1109.71, "trd": NaN, "batb": [[1, 2.8, 568.89]], "batl": [[1, 2.94, 560.61]]}, {"timestamp": 1578769542896, "ltp": 2.82, "tv": 1109.71, "trd": NaN, "batb": [[0, 2.82, 45.99]], "batl": NaN}, {"timestamp": 1578769560029, "ltp": 2.82, "tv": 1109.71, "trd": NaN, "batb": NaN, "batl": [[1, 2.94, 603.18]]}, {"timestamp": 1578769561036, "ltp": 2.82, "tv": 1109.71, "trd": NaN, "batb": [[1, 2.8, 471.85]], "batl": NaN}, {"timestamp": 1578769569972, "ltp": 2.82, "tv": 1109.71, "trd": NaN, "batb": NaN, "batl": [[1, 2.94, 8.18]]}, {"timestamp": 1578769572900, "ltp": 2.82, "tv": 1109.71, "trd": NaN, "batb": [[0, 2.82, 40.5]], "batl": NaN}, {"timestamp": 1578769579985, "ltp": 2.82, "tv": 1109.71, "trd": NaN, "batb": NaN, "batl": [[0, 2.92, 516.66]]}, {"timestamp": 1578769580888, "ltp": 2.82, "tv": 1109.71, "trd": NaN, "batb": NaN, "batl": [[0, 2.9, 2.8], [1, 2.92, 516.66], [2, 2.94, 8.18]]}, {"timestamp": 1578769587008, "ltp": 2.82, "tv": 1109.71, "trd": NaN, "batb": [[0, 2.82, 45.99]], "batl": NaN}, {"timestamp": 1578769588879, "ltp": 2.82, "tv": 1109.71, "trd": NaN, "batb": [[0, 2.82, 40.5]], "batl": NaN}, {"timestamp": 1578769602027, "ltp": 2.82, "tv": 1109.71, "trd": NaN, "batb": [[1, 2.8, 550.17]], "batl": [[1, 2.92, 437.5]]}, {"timestamp": 1578769603985, "ltp": 2.82, "tv": 1109.71, "trd": NaN, "batb": [[0, 2.82, 45.99]], "batl": NaN}, {"timestamp": 1578769604984, "ltp": 2.82, "tv": 1109.71, "trd": NaN, "batb": [[0, 2.82, 40.5]], "batl": NaN}, {"timestamp": 1578769605995, "ltp": 2.82, "tv": 1109.71, "trd": NaN, "batb": NaN, "batl": [[1, 2.92, 346.42]]}, {"timestamp": 1578769616958, "ltp": 2.82, "tv": 1109.71, "trd": NaN, "batb": [[0, 2.82, 45.99]], "batl": [[1, 2.92, 429.83]]}, {"timestamp": 1578769639378, "ltp": 2.82, "tv": 1109.71, "trd": NaN, "batb": [[0, 2.82, 40.5]], "batl": NaN}, {"timestamp": 1578769655976, "ltp": 2.82, "tv": 1109.71, "trd": NaN, "batb": [[0, 2.82, 45.99]], "batl": NaN}, {"timestamp": 1578769669015, "ltp": 2.82, "tv": 1109.71, "trd": NaN, "batb": [[0, 2.82, 48.88]], "batl": NaN}, {"timestamp": 1578769671033, "ltp": 2.82, "tv": 1109.71, "trd": NaN, "batb": [[0, 2.82, 45.99]], "batl": NaN}, {"timestamp": 1578769671720, "ltp": 2.82, "tv": 1109.71, "trd": NaN, "batb": [[0, 2.82, 48.88]], "batl": NaN}, {"timestamp": 1578769673007, "ltp": 2.82, "tv": 1109.71, "trd": NaN, "batb": [[0, 2.82, 45.99]], "batl": NaN}, {"timestamp": 1578769673741, "ltp": 2.82, "tv": 1109.71, "trd": NaN, "batb": [[0, 2.82, 48.88]], "batl": NaN}, {"timestamp": 1578769676920, "ltp": 2.82, "tv": 1109.71, "trd": NaN, "batb": [[0, 2.82, 45.99]], "batl": NaN}, {"timestamp": 1578769678053, "ltp": 2.82, "tv": 1109.71, "trd": NaN, "batb": [[0, 2.82, 48.88]], "batl": NaN}, {"timestamp": 1578769679029, "ltp": 2.82, "tv": 1109.71, "trd": NaN, "batb": [[0, 2.82, 45.99]], "batl": NaN}, {"timestamp": 1578769680040, "ltp": 2.82, "tv": 1109.71, "trd": NaN, "batb": [[0, 2.82, 48.88]], "batl": NaN}, {"timestamp": 1578769681023, "ltp": 2.82, "tv": 1109.71, "trd": NaN, "batb": [[0, 2.82, 45.99]], "batl": NaN}, {"timestamp": 1578769685035, "ltp": 2.82, "tv": 1109.71, "trd": NaN, "batb": [[0, 2.82, 48.88]], "batl": NaN}, {"timestamp": 1578769685982, "ltp": 2.82, "tv": 1109.71, "trd": NaN, "batb": [[0, 2.82, 45.99]], "batl": NaN}, {"timestamp": 1578769688049, "ltp": 2.82, "tv": 1109.71, "trd": NaN, "batb": [[0, 2.82, 48.88]], "batl": NaN}, {"timestamp": 1578769688736, "ltp": 2.82, "tv": 1109.71, "trd": NaN, "batb": [[0, 2.82, 45.99]], "batl": NaN}, {"timestamp": 1578769689858, "ltp": 2.82, "tv": 1109.71, "trd": NaN, "batb": [[0, 2.82, 48.88]], "batl": NaN}, {"timestamp": 1578769690961, "ltp": 2.82, "tv": 1109.71, "trd": NaN, "batb": [[0, 2.82, 45.99]], "batl": NaN}, {"timestamp": 1578769691966, "ltp": 2.82, "tv": 1109.71, "trd": NaN, "batb": [[0, 2.82, 48.88]], "batl": NaN}, {"timestamp": 1578769692966, "ltp": 2.82, "tv": 1109.71, "trd": NaN, "batb": [[0, 2.82, 45.99]], "batl": NaN}, {"timestamp": 1578769694963, "ltp": 2.82, "tv": 1109.71, "trd": NaN, "batb": [[0, 2.82, 48.88]], "batl": NaN}, {"timestamp": 1578769695859, "ltp": 2.82, "tv": 1109.71, "trd": NaN, "batb": [[0, 2.82, 45.99]], "batl": NaN}, {"timestamp": 1578769696976, "ltp": 2.82, "tv": 1109.71, "trd": NaN, "batb": [[0, 2.82, 48.88]], "batl": NaN}, {"timestamp": 1578769697977, "ltp": 2.82, "tv": 1109.71, "trd": NaN, "batb": [[0, 2.82, 45.99]], "batl": NaN}, {"timestamp": 1578769716897, "ltp": 2.82, "tv": 1109.71, "trd": NaN, "batb": [[0, 2.82, 48.89]], "batl": NaN}, {"timestamp": 1578769837995, "ltp": 2.82, "tv": 1109.71, "trd": NaN, "batb": [[2, 2.78, 130.69]], "batl": NaN}, {"timestamp": 1578769838967, "ltp": 2.82, "tv": 1109.71, "trd": NaN, "batb": [[1, 2.8, 460.84], [2, 2.78, 18.53]], "batl": NaN}, {"timestamp": 1578769872943, "ltp": 2.82, "tv": 1109.71, "trd": NaN, "batb": [[2, 2.78, 130.69]], "batl": NaN}, {"timestamp": 1578769903959, "ltp": 2.82, "tv": 1109.71, "trd": NaN, "batb": [[1, 2.8, 571.72], [2, 2.78, 18.53]], "batl": NaN}, {"timestamp": 1578769909052, "ltp": 2.82, "tv": 1109.71, "trd": NaN, "batb": [[1, 2.8, 530.86]], "batl": NaN}, {"timestamp": 1578769911961, "ltp": 2.82, "tv": 1109.71, "trd": NaN, "batb": [[1, 2.8, 419.98], [2, 2.78, 130.69]], "batl": NaN}, {"timestamp": 1578769914976, "ltp": 2.82, "tv": 1109.71, "trd": NaN, "batb": NaN, "batl": [[1, 2.92, 480.91]]}, {"timestamp": 1578769946025, "ltp": 2.8, "tv": 2182.63, "trd": [[2.8, 975.16], [2.82, 281.75]], "batb": [[0, 2.78, 151.61], [1, 2.76, 2.93], [2, 2.72, 15.31]], "batl": [[0, 2.8, 383.54], [1, 2.9, 2.8], [2, 2.92, 480.91]]}, {"timestamp": 1578769947034, "ltp": 2.8, "tv": 2347.77, "trd": [[2.8, 1140.3]], "batb": [[0, 2.78, 135.99], [2, 2.74, 17.19]], "batl": [[0, 2.8, 300.97], [1, 2.86, 16.47], [2, 2.88, 16.36]]}, {"timestamp": 1578769948050, "ltp": 2.8, "tv": 2347.77, "trd": NaN, "batb": [[1, 2.74, 17.19], [2, 2.72, 18.39]], "batl": NaN}, {"timestamp": 1578769948732, "ltp": 2.8, "tv": 2347.77, "trd": NaN, "batb": NaN, "batl": [[1, 2.84, 2.95], [2, 2.86, 16.47]]}, {"timestamp": 1578769949816, "ltp": 2.8, "tv": 2347.77, "trd": NaN, "batb": [[1, 2.76, 471.57], [2, 2.74, 17.19]], "batl": NaN}, {"timestamp": 1578769953917, "ltp": 2.8, "tv": 2347.77, "trd": NaN, "batb": [[0, 2.78, 141.61]], "batl": NaN}, {"timestamp": 1578769965840, "ltp": 2.8, "tv": 2347.77, "trd": NaN, "batb": NaN, "batl": [[1, 2.82, 6.26], [2, 2.84, 2.95]]}, {"timestamp": 1578769967030, "ltp": 2.8, "tv": 2347.77, "trd": NaN, "batb": [[1, 2.76, 477.95]], "batl": NaN}, {"timestamp": 1578770014672, "ltp": 2.8, "tv": 2347.77, "trd": NaN, "batb": [[1, 2.76, 471.57]], "batl": NaN}, {"timestamp": 1578770019053, "ltp": 2.8, "tv": 2413.53, "trd": [[2.8, 1206.06]], "batb": NaN, "batl": [[0, 2.8, 268.09]]}, {"timestamp": 1578770040935, "ltp": 2.8, "tv": 2724.89, "trd": [[2.8, 1517.41]], "batb": NaN, "batl": [[0, 2.8, 112.41]]}, {"timestamp": 1578770042017, "ltp": 2.8, "tv": 2724.89, "trd": NaN, "batb": NaN, "batl": [[0, 2.8, 118.31]]}, {"timestamp": 1578770052831, "ltp": 2.8, "tv": 2724.89, "trd": NaN, "batb": [[1, 2.76, 477.55]], "batl": NaN}, {"timestamp": 1578770053415, "ltp": 2.8, "tv": 2724.89, "trd": NaN, "batb": [[1, 2.76, 471.57]], "batl": NaN}, {"timestamp": 1578770089990, "ltp": 2.8, "tv": 2724.89, "trd": NaN, "batb": [[0, 2.78, 159.87]], "batl": NaN}, {"timestamp": 1578770168593, "ltp": 2.8, "tv": 2724.89, "trd": NaN, "batb": [[1, 2.76, 426.46]], "batl": NaN}, {"timestamp": 1578770187885, "ltp": 2.8, "tv": 2724.89, "trd": NaN, "batb": [[0, 2.78, 136.04], [1, 2.76, 450.29]], "batl": NaN}, {"timestamp": 1578770190984, "ltp": 2.8, "tv": 2774.31, "trd": [[2.8, 1566.83]], "batb": NaN, "batl": [[0, 2.8, 68.89]]}, {"timestamp": 1578770191687, "ltp": 2.8, "tv": 2774.31, "trd": NaN, "batb": [[1, 2.76, 456.05]], "batl": NaN}, {"timestamp": 1578770197896, "ltp": 2.8, "tv": 2836.47, "trd": [[2.8, 1628.99]], "batb": NaN, "batl": [[0, 2.8, 37.81]]}, {"timestamp": 1578770225033, "ltp": 2.8, "tv": 2836.47, "trd": NaN, "batb": [[1, 2.76, 456.4]], "batl": NaN}, {"timestamp": 1578770263979, "ltp": 2.8, "tv": 2836.47, "trd": NaN, "batb": NaN, "batl": [[0, 2.8, 31.91]]}, {"timestamp": 1578770266007, "ltp": 2.8, "tv": 2836.47, "trd": NaN, "batb": NaN, "batl": [[0, 2.8, 37.6]]}, {"timestamp": 1578770269809, "ltp": 2.8, "tv": 2843.61, "trd": [[2.8, 1636.13]], "batb": NaN, "batl": [[0, 2.8, 34.03]]}, {"timestamp": 1578770328037, "ltp": 2.8, "tv": 2843.61, "trd": NaN, "batb": [[1, 2.76, 496.41]], "batl": NaN}, {"timestamp": 1578770329951, "ltp": 2.8, "tv": 2843.61, "trd": NaN, "batb": [[0, 2.78, 473.97]], "batl": NaN}, {"timestamp": 1578770330967, "ltp": 2.8, "tv": 2843.61, "trd": NaN, "batb": [[0, 2.78, 493.33]], "batl": [[0, 2.8, 28.34]]}, {"timestamp": 1578770335999, "ltp": 2.8, "tv": 2843.61, "trd": NaN, "batb": [[1, 2.76, 533.86]], "batl": NaN}, {"timestamp": 1578770355975, "ltp": 2.8, "tv": 2900.28, "trd": [[2.8, 1692.81]], "batb": NaN, "batl": [[0, 2.82, 6.26], [1, 2.84, 2.95], [2, 2.86, 356.1]]}, {"timestamp": 1578770356714, "ltp": 2.8, "tv": 2900.28, "trd": NaN, "batb": NaN, "batl": [[0, 2.84, 2.95], [1, 2.86, 356.1], [2, 2.88, 422.2]]}, {"timestamp": 1578770357990, "ltp": 2.8, "tv": 2900.28, "trd": NaN, "batb": [[0, 2.8, 34.24], [1, 2.78, 493.33], [2, 2.76, 533.86]], "batl": NaN}, {"timestamp": 1578770359015, "ltp": 2.8, "tv": 2900.28, "trd": NaN, "batb": [[0, 2.78, 493.33], [1, 2.76, 533.86], [2, 2.74, 17.19]], "batl": NaN}, {"timestamp": 1578770361020, "ltp": 2.8, "tv": 2900.28, "trd": NaN, "batb": [[1, 2.76, 29.95]], "batl": [[1, 2.86, 16.47]]}, {"timestamp": 1578770361992, "ltp": 2.8, "tv": 2900.28, "trd": NaN, "batb": NaN, "batl": [[2, 2.88, 383.9]]}, {"timestamp": 1578770366890, "ltp": 2.8, "tv": 2900.28, "trd": NaN, "batb": NaN, "batl": [[2, 2.88, 354.1]]}, {"timestamp": 1578770391938, "ltp": 2.8, "tv": 2900.28, "trd": NaN, "batb": [[0, 2.78, 535.04]], "batl": NaN}, {"timestamp": 1578770396911, "ltp": 2.8, "tv": 2900.28, "trd": NaN, "batb": NaN, "batl": [[2, 2.88, 393.26]]}, {"timestamp": 1578770438984, "ltp": 2.8, "tv": 2900.28, "trd": NaN, "batb": [[0, 2.8, 3.08], [1, 2.78, 535.04], [2, 2.76, 29.95]], "batl": NaN}, {"timestamp": 1578770443908, "ltp": 2.8, "tv": 2900.28, "trd": NaN, "batb": NaN, "batl": [[0, 2.86, 16.47], [1, 2.88, 396.26], [2, 2.96, 15.11]]}, {"timestamp": 1578770446008, "ltp": 2.8, "tv": 2900.28, "trd": NaN, "batb": [[0, 2.8, 113.96], [1, 2.78, 422.88]], "batl": NaN}, {"timestamp": 1578770447012, "ltp": 2.8, "tv": 2900.28, "trd": NaN, "batb": [[0, 2.8, 119.52], [1, 2.78, 417.26]], "batl": NaN}, {"timestamp": 1578770480048, "ltp": 2.8, "tv": 2900.28, "trd": NaN, "batb": [[2, 2.76, 57.25]], "batl": [[2, 2.92, 24.34]]}, {"timestamp": 1578770487030, "ltp": 2.86, "tv": 2950.69, "trd": [[2.86, 171.12]], "batb": [[0, 2.82, 5.83], [1, 2.8, 119.52], [2, 2.78, 417.26]], "batl": [[0, 2.86, 8.39], [2, 2.9, 5.67]]}, {"timestamp": 1578770487554, "ltp": 2.86, "tv": 2950.69, "trd": NaN, "batb": NaN, "batl": [[0, 2.88, 396.26], [1, 2.9, 5.67], [2, 2.92, 24.34]]}, {"timestamp": 1578770491041, "ltp": 2.86, "tv": 2950.69, "trd": NaN, "batb": [[2, 2.78, 399]], "batl": NaN}, {"timestamp": 1578770492039, "ltp": 2.86, "tv": 2950.69, "trd": NaN, "batb": [[0, 2.84, 5.78], [1, 2.82, 28.46], [2, 2.8, 113.96]], "batl": NaN}, {"timestamp": 1578770494930, "ltp": 2.86, "tv": 2950.69, "trd": NaN, "batb": [[0, 2.82, 28.46], [1, 2.8, 113.96], [2, 2.78, 399]], "batl": NaN}, {"timestamp": 1578770500956, "ltp": 2.86, "tv": 2950.69, "trd": NaN, "batb": [[1, 2.8, 3.08], [2, 2.78, 511.16]], "batl": NaN}, {"timestamp": 1578770505032, "ltp": 2.86, "tv": 2950.69, "trd": NaN, "batb": [[1, 2.8, 113.96], [2, 2.78, 399]], "batl": [[1, 2.9, 514.69]]}, {"timestamp": 1578770506048, "ltp": 2.86, "tv": 2950.69, "trd": NaN, "batb": NaN, "batl": [[0, 2.86, 3.03], [1, 2.88, 396.26], [2, 2.9, 514.69]]}, {"timestamp": 1578770512557, "ltp": 2.86, "tv": 2950.69, "trd": NaN, "batb": [[0, 2.82, 10.2], [1, 2.8, 132.49]], "batl": NaN}, {"timestamp": 1578770513988, "ltp": 2.86, "tv": 2950.69, "trd": NaN, "batb": [[2, 2.78, 511.16]], "batl": NaN}, {"timestamp": 1578770515051, "ltp": 2.86, "tv": 2950.69, "trd": NaN, "batb": [[1, 2.8, 21.61]], "batl": NaN}, {"timestamp": 1578770520049, "ltp": 2.86, "tv": 2950.69, "trd": NaN, "batb": [[1, 2.8, 132.49], [2, 2.78, 399]], "batl": NaN}, {"timestamp": 1578770560039, "ltp": 2.86, "tv": 2950.69, "trd": NaN, "batb": NaN, "batl": [[1, 2.88, 3], [2, 2.9, 5.67]]}, {"timestamp": 1578770566043, "ltp": 2.86, "tv": 2950.69, "trd": NaN, "batb": NaN, "batl": [[1, 2.88, 376.69]]}, {"timestamp": 1578770573036, "ltp": 2.86, "tv": 2950.69, "trd": NaN, "batb": [[1, 2.8, 21.61], [2, 2.78, 511.16]], "batl": NaN}, {"timestamp": 1578770575856, "ltp": 2.86, "tv": 2950.69, "trd": NaN, "batb": NaN, "batl": [[1, 2.88, 3]]}, {"timestamp": 1578770585979, "ltp": 2.86, "tv": 2950.69, "trd": NaN, "batb": [[1, 2.8, 132.49], [2, 2.78, 399]], "batl": NaN}, {"timestamp": 1578770591981, "ltp": 2.86, "tv": 2950.69, "trd": NaN, "batb": [[0, 2.82, 5.83]], "batl": NaN}, {"timestamp": 1578770592978, "ltp": 2.86, "tv": 2950.69, "trd": NaN, "batb": [[0, 2.82, 9.75]], "batl": NaN}, {"timestamp": 1578770594880, "ltp": 2.86, "tv": 2950.69, "trd": NaN, "batb": [[0, 2.82, 5.83]], "batl": NaN}, {"timestamp": 1578770607992, "ltp": 2.86, "tv": 2959.67, "trd": [[2.86, 180.1]], "batb": [[0, 2.86, 1.11], [1, 2.82, 5.83], [2, 2.8, 132.49]], "batl": [[0, 2.88, 3], [1, 2.9, 5.67], [2, 2.92, 24.34]]}, {"timestamp": 1578770608684, "ltp": 2.86, "tv": 2959.67, "trd": NaN, "batb": [[1, 2.84, 3.07], [2, 2.82, 5.83]], "batl": NaN}, {"timestamp": 1578770630004, "ltp": 2.86, "tv": 2959.67, "trd": NaN, "batb": NaN, "batl": [[1, 2.9, 523.2]]}, {"timestamp": 1578770646014, "ltp": 2.86, "tv": 2959.67, "trd": NaN, "batb": [[1, 2.82, 5.83], [2, 2.8, 132.49]], "batl": NaN}, {"timestamp": 1578770652017, "ltp": 2.86, "tv": 2959.67, "trd": NaN, "batb": [[2, 2.8, 21.61]], "batl": NaN}, {"timestamp": 1578770683055, "ltp": 2.86, "tv": 2959.67, "trd": NaN, "batb": [[2, 2.8, 132.49]], "batl": NaN}, {"timestamp": 1578770706016, "ltp": 2.86, "tv": 2959.67, "trd": NaN, "batb": NaN, "batl": [[1, 2.9, 482.35]]}, {"timestamp": 1578770730004, "ltp": 2.86, "tv": 2959.67, "trd": NaN, "batb": [[2, 2.8, 21.61]], "batl": NaN}, {"timestamp": 1578770766966, "ltp": 2.86, "tv": 2959.67, "trd": NaN, "batb": NaN, "batl": [[1, 2.9, 484.64]]}, {"timestamp": 1578770787968, "ltp": 2.86, "tv": 2959.67, "trd": NaN, "batb": NaN, "batl": [[1, 2.9, 482.35]]}, {"timestamp": 1578770803010, "ltp": 2.86, "tv": 2959.67, "trd": NaN, "batb": [[2, 2.8, 132.49]], "batl": NaN}, {"timestamp": 1578770805995, "ltp": 2.86, "tv": 2959.67, "trd": NaN, "batb": [[2, 2.8, 21.61]], "batl": NaN}, {"timestamp": 1578770836915, "ltp": 2.86, "tv": 2959.67, "trd": NaN, "batb": [[2, 2.8, 132.49]], "batl": NaN}, {"timestamp": 1578770846054, "ltp": 2.86, "tv": 2959.67, "trd": NaN, "batb": [[2, 2.8, 21.61]], "batl": NaN}, {"timestamp": 1578770873993, "ltp": 2.86, "tv": 2959.67, "trd": NaN, "batb": NaN, "batl": [[1, 2.9, 422.76]]}, {"timestamp": 1578770877997, "ltp": 2.86, "tv": 2959.67, "trd": NaN, "batb": NaN, "batl": [[1, 2.9, 370.84]]}, {"timestamp": 1578770885994, "ltp": 2.86, "tv": 2960.1, "trd": [[2.86, 180.53]], "batb": [[0, 2.82, 6.51], [1, 2.8, 21.61], [2, 2.78, 600.54]], "batl": NaN}, {"timestamp": 1578770889020, "ltp": 2.86, "tv": 2960.1, "trd": NaN, "batb": [[1, 2.8, 355.29]], "batl": [[1, 2.9, 392.97]]}, {"timestamp": 1578770890014, "ltp": 2.86, "tv": 2960.1, "trd": NaN, "batb": [[0, 2.82, 5.83]], "batl": NaN}, {"timestamp": 1578770893011, "ltp": 2.86, "tv": 2960.1, "trd": NaN, "batb": [[1, 2.8, 21.61], [2, 2.78, 131.52]], "batl": NaN}, {"timestamp": 1578770895006, "ltp": 2.88, "tv": 2964.1, "trd": [[2.88, 62.2]], "batb": NaN, "batl": [[0, 2.88, 1]]}, {"timestamp": 1578770895909, "ltp": 2.88, "tv": 2964.1, "trd": NaN, "batb": NaN, "batl": [[0, 2.9, 392.97], [1, 2.92, 27.38], [2, 2.96, 15.11]]}, {"timestamp": 1578770896808, "ltp": 2.88, "tv": 2964.1, "trd": NaN, "batb": NaN, "batl": [[0, 2.88, 3.09], [1, 2.9, 392.97], [2, 2.92, 27.38]]}, {"timestamp": 1578770900041, "ltp": 2.88, "tv": 2964.1, "trd": NaN, "batb": NaN, "batl": [[0, 2.88, 8.22]]}, {"timestamp": 1578770905942, "ltp": 2.88, "tv": 2964.1, "trd": NaN, "batb": [[1, 2.8, 356.99]], "batl": NaN}, {"timestamp": 1578770917018, "ltp": 2.88, "tv": 2964.1, "trd": NaN, "batb": [[2, 2.78, 589.48]], "batl": [[1, 2.9, 427.02]]}, {"timestamp": 1578770930937, "ltp": 2.88, "tv": 2964.1, "trd": NaN, "batb": [[2, 2.78, 477.32]], "batl": NaN}, {"timestamp": 1578770934054, "ltp": 2.88, "tv": 2964.1, "trd": NaN, "batb": [[0, 2.82, 8.08]], "batl": NaN}, {"timestamp": 1578770938050, "ltp": 2.88, "tv": 2964.1, "trd": NaN, "batb": [[1, 2.8, 21.61]], "batl": NaN}, {"timestamp": 1578770941054, "ltp": 2.88, "tv": 2964.1, "trd": NaN, "batb": [[0, 2.82, 5.83]], "batl": NaN}, {"timestamp": 1578770964996, "ltp": 2.88, "tv": 2964.1, "trd": NaN, "batb": NaN, "batl": [[1, 2.9, 472.13]]}, {"timestamp": 1578770970009, "ltp": 2.88, "tv": 2964.1, "trd": NaN, "batb": [[2, 2.78, 550.32]], "batl": NaN}, {"timestamp": 1578770973023, "ltp": 2.88, "tv": 2964.1, "trd": NaN, "batb": [[2, 2.78, 514.57]], "batl": NaN}, {"timestamp": 1578770977925, "ltp": 2.88, "tv": 2964.1, "trd": NaN, "batb": [[2, 2.78, 486.48]], "batl": NaN}, {"timestamp": 1578770988935, "ltp": 2.88, "tv": 2964.1, "trd": NaN, "batb": [[2, 2.78, 539.25]], "batl": NaN}, {"timestamp": 1578770997045, "ltp": 2.88, "tv": 2964.1, "trd": NaN, "batb": [[2, 2.78, 427.09]], "batl": NaN}, {"timestamp": 1578771006029, "ltp": 2.88, "tv": 2964.1, "trd": NaN, "batb": [[2, 2.78, 539.25]], "batl": NaN}, {"timestamp": 1578771007999, "ltp": 2.88, "tv": 2964.1, "trd": NaN, "batb": [[1, 2.8, 132.49], [2, 2.78, 427.09]], "batl": NaN}, {"timestamp": 1578771009999, "ltp": 2.88, "tv": 2964.1, "trd": NaN, "batb": [[2, 2.78, 539.25]], "batl": NaN}, {"timestamp": 1578771011005, "ltp": 2.88, "tv": 2964.1, "trd": NaN, "batb": [[1, 2.8, 21.61]], "batl": NaN}, {"timestamp": 1578771013973, "ltp": 2.88, "tv": 2964.1, "trd": NaN, "batb": [[2, 2.78, 427.09]], "batl": NaN}, {"timestamp": 1578771021029, "ltp": 2.88, "tv": 2964.1, "trd": NaN, "batb": [[0, 2.82, 8.85]], "batl": NaN}, {"timestamp": 1578771029905, "ltp": 2.88, "tv": 2964.1, "trd": NaN, "batb": [[2, 2.78, 450.93]], "batl": NaN}, {"timestamp": 1578771037959, "ltp": 2.88, "tv": 2964.1, "trd": NaN, "batb": [[2, 2.78, 479.87]], "batl": NaN}, {"timestamp": 1578771046979, "ltp": 2.88, "tv": 2964.1, "trd": NaN, "batb": [[0, 2.82, 5.83]], "batl": NaN}, {"timestamp": 1578771051965, "ltp": 2.88, "tv": 2964.1, "trd": NaN, "batb": [[1, 2.8, 362.09]], "batl": NaN}, {"timestamp": 1578771059983, "ltp": 2.82, "tv": 2980.99, "trd": [[2.82, 298.65]], "batb": [[0, 2.82, 2.45]], "batl": NaN}, {"timestamp": 1578771060991, "ltp": 2.82, "tv": 2980.99, "trd": NaN, "batb": [[0, 2.82, 15.65], [1, 2.8, 21.61], [2, 2.78, 405.81]], "batl": [[1, 2.9, 523.2]]}, {"timestamp": 1578771061992, "ltp": 2.82, "tv": 2980.99, "trd": NaN, "batb": [[0, 2.8, 21.61], [1, 2.78, 405.81], [2, 2.76, 221.78]], "batl": NaN}, {"timestamp": 1578771070026, "ltp": 2.82, "tv": 2980.99, "trd": NaN, "batb": [[0, 2.82, 10.01], [1, 2.8, 21.61], [2, 2.78, 405.81]], "batl": NaN}, {"timestamp": 1578771072027, "ltp": 2.82, "tv": 2980.99, "trd": NaN, "batb": [[0, 2.82, 12.02]], "batl": NaN}, {"timestamp": 1578771073954, "ltp": 2.82, "tv": 2980.99, "trd": NaN, "batb": [[0, 2.82, 10.01]], "batl": NaN}, {"timestamp": 1578771075010, "ltp": 2.82, "tv": 2980.99, "trd": NaN, "batb": [[2, 2.78, 360.7]], "batl": NaN}, {"timestamp": 1578771084040, "ltp": 2.82, "tv": 2980.99, "trd": NaN, "batb": [[2, 2.78, 19.36]], "batl": [[1, 2.9, 5.67]]}, {"timestamp": 1578771087048, "ltp": 2.82, "tv": 2986.99, "trd": [[2.82, 304.64]], "batb": [[0, 2.82, 7.01]], "batl": NaN}, {"timestamp": 1578771087950, "ltp": 2.82, "tv": 2986.99, "trd": NaN, "batb": [[0, 2.8, 21.61], [1, 2.78, 19.36], [2, 2.76, 221.78]], "batl": NaN}, {"timestamp": 1578771092034, "ltp": 2.82, "tv": 2986.99, "trd": NaN, "batb": [[0, 2.8, 18.53], [2, 2.76, 225.06]], "batl": NaN}, {"timestamp": 1578771094965, "ltp": 2.82, "tv": 2986.99, "trd": NaN, "batb": [[0, 2.8, 21.76]], "batl": NaN}, {"timestamp": 1578771097029, "ltp": 2.82, "tv": 2986.99, "trd": NaN, "batb": [[0, 2.8, 23.82]], "batl": NaN}, {"timestamp": 1578771102966, "ltp": 2.82, "tv": 2986.99, "trd": NaN, "batb": [[1, 2.78, 356.44]], "batl": [[0, 2.88, 400.62]]}, {"timestamp": 1578771103970, "ltp": 2.82, "tv": 2986.99, "trd": NaN, "batb": NaN, "batl": [[0, 2.86, 9.98], [1, 2.88, 400.62], [2, 2.9, 5.67]]}, {"timestamp": 1578771111986, "ltp": 2.82, "tv": 2986.99, "trd": NaN, "batb": NaN, "batl": [[2, 2.9, 551.29]]}, {"timestamp": 1578771113991, "ltp": 2.82, "tv": 2986.99, "trd": NaN, "batb": [[1, 2.78, 468.6], [2, 2.76, 111.58]], "batl": NaN}, {"timestamp": 1578771116007, "ltp": 2.82, "tv": 2986.99, "trd": NaN, "batb": [[0, 2.8, 21.76]], "batl": NaN}, {"timestamp": 1578771117014, "ltp": 2.82, "tv": 2986.99, "trd": NaN, "batb": [[1, 2.78, 131.52], [2, 2.76, 500.58]], "batl": [[1, 2.88, 8.22], [2, 2.9, 641.52]]}, {"timestamp": 1578771121988, "ltp": 2.82, "tv": 2986.99, "trd": NaN, "batb": NaN, "batl": [[0, 2.86, 388.76]]}, {"timestamp": 1578771123001, "ltp": 2.82, "tv": 2986.99, "trd": NaN, "batb": NaN, "batl": [[0, 2.84, 20.66], [1, 2.86, 388.76], [2, 2.88, 8.22]]}, {"timestamp": 1578771132995, "ltp": 2.82, "tv": 2986.99, "trd": NaN, "batb": [[0, 2.8, 24.25]], "batl": NaN}, {"timestamp": 1578771144965, "ltp": 2.82, "tv": 2986.99, "trd": NaN, "batb": [[0, 2.8, 21.76]], "batl": NaN}, {"timestamp": 1578771152972, "ltp": 2.82, "tv": 2986.99, "trd": NaN, "batb": [[0, 2.8, 24.18]], "batl": NaN}, {"timestamp": 1578771157959, "ltp": 2.82, "tv": 2986.99, "trd": NaN, "batb": NaN, "batl": [[1, 2.86, 345.35]]}, {"timestamp": 1578771158864, "ltp": 2.82, "tv": 2986.99, "trd": NaN, "batb": [[0, 2.8, 21.76]], "batl": NaN}, {"timestamp": 1578771166969, "ltp": 2.82, "tv": 2986.99, "trd": NaN, "batb": [[0, 2.8, 18.53]], "batl": NaN}, {"timestamp": 1578771170995, "ltp": 2.82, "tv": 2986.99, "trd": NaN, "batb": [[0, 2.8, 24.64]], "batl": NaN}, {"timestamp": 1578771199967, "ltp": 2.82, "tv": 2986.99, "trd": NaN, "batb": [[2, 2.76, 543.99]], "batl": NaN}, {"timestamp": 1578771219051, "ltp": 2.82, "tv": 2986.99, "trd": NaN, "batb": [[2, 2.76, 657.47]], "batl": NaN}, {"timestamp": 1578771220010, "ltp": 2.82, "tv": 2986.99, "trd": NaN, "batb": [[1, 2.78, 19.36]], "batl": NaN}, {"timestamp": 1578771221872, "ltp": 2.82, "tv": 2986.99, "trd": NaN, "batb": NaN, "batl": [[1, 2.86, 426.22]]}, {"timestamp": 1578771232974, "ltp": 2.82, "tv": 2986.99, "trd": NaN, "batb": [[2, 2.76, 611.51]], "batl": [[1, 2.86, 398.13]]}, {"timestamp": 1578771249907, "ltp": 2.82, "tv": 2986.99, "trd": NaN, "batb": [[2, 2.76, 575.76]], "batl": [[1, 2.86, 440.69]]}, {"timestamp": 1578771258054, "ltp": 2.82, "tv": 2986.99, "trd": NaN, "batb": [[0, 2.8, 6.11]], "batl": NaN}, {"timestamp": 1578771259049, "ltp": 2.82, "tv": 2986.99, "trd": NaN, "batb": [[0, 2.78, 39.95], [1, 2.76, 575.76], [2, 2.72, 15.31]], "batl": NaN}, {"timestamp": 1578771264965, "ltp": 2.82, "tv": 2986.99, "trd": NaN, "batb": [[1, 2.76, 225.06], [2, 2.74, 463.91]], "batl": NaN}, {"timestamp": 1578771267043, "ltp": 2.82, "tv": 2986.99, "trd": NaN, "batb": [[0, 2.8, 9.87], [1, 2.78, 39.95], [2, 2.76, 225.06]], "batl": NaN}, {"timestamp": 1578771268055, "ltp": 2.82, "tv": 2986.99, "trd": NaN, "batb": [[1, 2.78, 152.11], [2, 2.76, 111.58]], "batl": NaN}, {"timestamp": 1578771272052, "ltp": 2.82, "tv": 2986.99, "trd": NaN, "batb": [[1, 2.78, 39.95], [2, 2.76, 225.06]], "batl": NaN}, {"timestamp": 1578771288000, "ltp": 2.82, "tv": 2986.99, "trd": NaN, "batb": [[0, 2.78, 39.95], [1, 2.76, 225.06], [2, 2.74, 463.91]], "batl": NaN}, {"timestamp": 1578771291033, "ltp": 2.82, "tv": 2986.99, "trd": NaN, "batb": [[0, 2.78, 42.25]], "batl": NaN}, {"timestamp": 1578771296032, "ltp": 2.82, "tv": 2986.99, "trd": NaN, "batb": [[0, 2.78, 39.95]], "batl": NaN}, {"timestamp": 1578771310022, "ltp": 2.82, "tv": 2986.99, "trd": NaN, "batb": [[0, 2.78, 43.58]], "batl": NaN}, {"timestamp": 1578771323960, "ltp": 2.82, "tv": 2986.99, "trd": NaN, "batb": [[0, 2.78, 39.95]], "batl": NaN}, {"timestamp": 1578771327021, "ltp": 2.82, "tv": 2986.99, "trd": NaN, "batb": [[1, 2.76, 111.58], [2, 2.74, 578.7]], "batl": NaN}, {"timestamp": 1578771334963, "ltp": 2.82, "tv": 2986.99, "trd": NaN, "batb": [[1, 2.76, 225.06]], "batl": [[0, 2.84, 398.6]]}, {"timestamp": 1578771336052, "ltp": 2.82, "tv": 2986.99, "trd": NaN, "batb": [[2, 2.74, 463.91]], "batl": [[0, 2.82, 20.29], [1, 2.84, 398.6], [2, 2.86, 440.69]]}, {"timestamp": 1578771337049, "ltp": 2.82, "tv": 2986.99, "trd": NaN, "batb": [[1, 2.76, 197.75]], "batl": NaN}, {"timestamp": 1578771338055, "ltp": 2.82, "tv": 2986.99, "trd": NaN, "batb": NaN, "batl": [[1, 2.84, 20.66]]}, {"timestamp": 1578771339054, "ltp": 2.82, "tv": 2986.99, "trd": NaN, "batb": [[2, 2.74, 435.82]], "batl": [[2, 2.86, 529.21]]}, {"timestamp": 1578771351965, "ltp": 2.82, "tv": 2986.99, "trd": NaN, "batb": [[0, 2.78, 42.23]], "batl": [[1, 2.84, 350.93]]}, {"timestamp": 1578771360012, "ltp": 2.82, "tv": 2986.99, "trd": NaN, "batb": [[1, 2.76, 84.27], [2, 2.74, 591.47]], "batl": NaN}, {"timestamp": 1578771361028, "ltp": 2.82, "tv": 2986.99, "trd": NaN, "batb": [[1, 2.76, 60.44]], "batl": NaN}, {"timestamp": 1578771363985, "ltp": 2.82, "tv": 2986.99, "trd": NaN, "batb": [[0, 2.78, 21.64], [1, 2.76, 81.54]], "batl": NaN}, {"timestamp": 1578771369019, "ltp": 2.82, "tv": 2986.99, "trd": NaN, "batb": [[1, 2.76, 195.02], [2, 2.74, 476.68]], "batl": NaN}, {"timestamp": 1578771370040, "ltp": 2.82, "tv": 2986.99, "trd": NaN, "batb": [[1, 2.76, 218.85]], "batl": NaN}, {"timestamp": 1578771375994, "ltp": 2.82, "tv": 2986.99, "trd": NaN, "batb": NaN, "batl": [[1, 2.84, 20.66]]}, {"timestamp": 1578771377007, "ltp": 2.82, "tv": 2986.99, "trd": NaN, "batb": [[0, 2.78, 19.36]], "batl": [[0, 2.84, 20.66], [1, 2.86, 484.95], [2, 2.88, 8.22]]}, {"timestamp": 1578771386042, "ltp": 2.78, "tv": 3038.35, "trd": [[2.78, 65.5]], "batb": [[0, 2.76, 218.85], [1, 2.74, 476.68], [2, 2.72, 15.31]], "batl": [[0, 2.78, 24.32], [1, 2.84, 20.66], [2, 2.86, 484.95]]}, {"timestamp": 1578771387051, "ltp": 2.78, "tv": 3086.99, "trd": [[2.78, 114.14]], "batb": [[1, 2.74, 486.41]], "batl": [[0, 2.82, 9.47], [2, 2.86, 510.86]]}, {"timestamp": 1578771388801, "ltp": 2.78, "tv": 3086.99, "trd": NaN, "batb": NaN, "batl": [[2, 2.86, 484.95]]}, {"timestamp": 1578771390018, "ltp": 2.78, "tv": 3086.99, "trd": NaN, "batb": [[0, 2.78, 9.63], [1, 2.76, 218.85], [2, 2.74, 486.41]], "batl": NaN}, {"timestamp": 1578771414053, "ltp": 2.78, "tv": 3086.99, "trd": NaN, "batb": NaN, "batl": [[1, 2.84, 368.8]]}, {"timestamp": 1578771418960, "ltp": 2.78, "tv": 3086.99, "trd": NaN, "batb": NaN, "batl": [[1, 2.84, 20.66]]}, {"timestamp": 1578771429894, "ltp": 2.78, "tv": 3086.99, "trd": NaN, "batb": NaN, "batl": [[1, 2.84, 358.59]]}, {"timestamp": 1578771444019, "ltp": 2.78, "tv": 3086.99, "trd": NaN, "batb": NaN, "batl": [[2, 2.86, 9.98]]}, {"timestamp": 1578771477963, "ltp": 2.78, "tv": 3086.99, "trd": NaN, "batb": NaN, "batl": [[2, 2.86, 440.69]]}, {"timestamp": 1578771481949, "ltp": 2.78, "tv": 3086.99, "trd": NaN, "batb": [[1, 2.76, 562.74], [2, 2.74, 9.74]], "batl": [[1, 2.84, 20.66]]}, {"timestamp": 1578771482961, "ltp": 2.78, "tv": 3086.99, "trd": NaN, "batb": NaN, "batl": [[0, 2.82, 3.36]]}, {"timestamp": 1578771491994, "ltp": 2.78, "tv": 3086.99, "trd": NaN, "batb": NaN, "batl": [[0, 2.84, 20.66], [1, 2.86, 440.69], [2, 2.88, 8.22]]}, {"timestamp": 1578771517002, "ltp": 2.78, "tv": 3086.99, "trd": NaN, "batb": NaN, "batl": [[0, 2.82, 3.38], [1, 2.84, 20.66], [2, 2.86, 440.69]]}, {"timestamp": 1578771527041, "ltp": 2.78, "tv": 3086.99, "trd": NaN, "batb": [[1, 2.76, 449.26], [2, 2.74, 124.53]], "batl": NaN}, {"timestamp": 1578771530956, "ltp": 2.78, "tv": 3086.99, "trd": NaN, "batb": [[1, 2.76, 488.41]], "batl": NaN}, {"timestamp": 1578771531963, "ltp": 2.78, "tv": 3086.99, "trd": NaN, "batb": NaN, "batl": [[0, 2.84, 20.66], [1, 2.86, 440.69], [2, 2.88, 8.22]]}, {"timestamp": 1578771537963, "ltp": 2.78, "tv": 3086.99, "trd": NaN, "batb": [[1, 2.76, 535.23]], "batl": NaN}, {"timestamp": 1578771540049, "ltp": 2.78, "tv": 3086.99, "trd": NaN, "batb": [[1, 2.76, 586.3]], "batl": [[2, 2.88, 469.57]]}, {"timestamp": 1578771541050, "ltp": 2.78, "tv": 3086.99, "trd": NaN, "batb": NaN, "batl": [[0, 2.82, 5.79], [1, 2.84, 20.66], [2, 2.86, 440.69]]}, {"timestamp": 1578771545874, "ltp": 2.78, "tv": 3086.99, "trd": NaN, "batb": [[1, 2.76, 699.78], [2, 2.74, 9.74]], "batl": [[0, 2.84, 20.66], [1, 2.86, 440.69], [2, 2.88, 494.35]]}, {"timestamp": 1578771546992, "ltp": 2.78, "tv": 3086.99, "trd": NaN, "batb": [[1, 2.76, 586.3], [2, 2.74, 124.53]], "batl": NaN}, {"timestamp": 1578771550994, "ltp": 2.78, "tv": 3086.99, "trd": NaN, "batb": [[1, 2.76, 524.17]], "batl": [[1, 2.86, 9.98]]}, {"timestamp": 1578771560050, "ltp": 2.78, "tv": 3086.99, "trd": NaN, "batb": NaN, "batl": [[2, 2.88, 33]]}, {"timestamp": 1578771561052, "ltp": 2.78, "tv": 3086.99, "trd": NaN, "batb": [[1, 2.76, 468.84]], "batl": NaN}, {"timestamp": 1578771563977, "ltp": 2.78, "tv": 3086.99, "trd": NaN, "batb": [[1, 2.76, 582.32], [2, 2.74, 9.74]], "batl": NaN}, {"timestamp": 1578771567986, "ltp": 2.78, "tv": 3086.99, "trd": NaN, "batb": NaN, "batl": [[1, 2.86, 343.65]]}, {"timestamp": 1578771569988, "ltp": 2.78, "tv": 3086.99, "trd": NaN, "batb": [[1, 2.76, 648.71]], "batl": NaN}, {"timestamp": 1578771572004, "ltp": 2.78, "tv": 3086.99, "trd": NaN, "batb": [[1, 2.76, 535.23], [2, 2.74, 124.53]], "batl": NaN}, {"timestamp": 1578771577983, "ltp": 2.78, "tv": 3086.99, "trd": NaN, "batb": [[1, 2.76, 511.4]], "batl": NaN}, {"timestamp": 1578771578991, "ltp": 2.78, "tv": 3086.99, "trd": NaN, "batb": [[2, 2.74, 148.36]], "batl": NaN}, {"timestamp": 1578771580910, "ltp": 2.78, "tv": 3086.99, "trd": NaN, "batb": NaN, "batl": [[2, 2.88, 501.16]]}, {"timestamp": 1578771586991, "ltp": 2.78, "tv": 3086.99, "trd": NaN, "batb": NaN, "batl": [[1, 2.86, 9.98]]}, {"timestamp": 1578771587990, "ltp": 2.78, "tv": 3086.99, "trd": NaN, "batb": [[1, 2.76, 547.15]], "batl": [[2, 2.88, 459.45]]}, {"timestamp": 1578771592027, "ltp": 2.78, "tv": 3086.99, "trd": NaN, "batb": NaN, "batl": [[2, 2.88, 412.64]]}, {"timestamp": 1578771602028, "ltp": 2.78, "tv": 3086.99, "trd": NaN, "batb": [[0, 2.76, 543.87], [1, 2.74, 138.62], [2, 2.72, 15.31]], "batl": [[0, 2.78, 18.04], [1, 2.88, 448.7], [2, 2.92, 24.34]]}, {"timestamp": 1578771603027, "ltp": 2.78, "tv": 3122.74, "trd": [[2.78, 149.89]], "batb": [[0, 2.76, 572.06]], "batl": [[0, 2.88, 423.92], [1, 2.92, 24.34], [2, 2.96, 214.98]]}, {"timestamp": 1578771612023, "ltp": 2.78, "tv": 3122.74, "trd": NaN, "batb": [[0, 2.76, 577.17]], "batl": NaN}, {"timestamp": 1578771614040, "ltp": 2.78, "tv": 3122.74, "trd": NaN, "batb": [[0, 2.76, 690.65], [1, 2.74, 23.83]], "batl": NaN}, {"timestamp": 1578771622034, "ltp": 2.78, "tv": 3122.74, "trd": NaN, "batb": [[0, 2.76, 685.54]], "batl": NaN}, {"timestamp": 1578771623834, "ltp": 2.78, "tv": 3122.74, "trd": NaN, "batb": [[0, 2.76, 688.23]], "batl": NaN}, {"timestamp": 1578771629981, "ltp": 2.78, "tv": 3122.74, "trd": NaN, "batb": [[0, 2.76, 685.54]], "batl": NaN}, {"timestamp": 1578771682984, "ltp": 2.78, "tv": 3122.74, "trd": NaN, "batb": NaN, "batl": [[1, 2.9, 600.1], [2, 2.92, 24.34]]}, {"timestamp": 1578771688994, "ltp": 2.78, "tv": 3122.74, "trd": NaN, "batb": NaN, "batl": [[0, 2.88, 5.13]]}, {"timestamp": 1578771699023, "ltp": 2.78, "tv": 3122.74, "trd": NaN, "batb": NaN, "batl": [[0, 2.88, 426.48], [1, 2.92, 24.34], [2, 2.96, 15.11]]}, {"timestamp": 1578771700042, "ltp": 2.78, "tv": 3122.74, "trd": NaN, "batb": NaN, "batl": [[1, 2.96, 15.11], [2, 2.98, 223.06]]}, {"timestamp": 1578771704035, "ltp": 2.78, "tv": 3122.74, "trd": NaN, "batb": NaN, "batl": [[0, 2.88, 5.13]]}, {"timestamp": 1578771706036, "ltp": 2.78, "tv": 3122.74, "trd": NaN, "batb": NaN, "batl": [[1, 2.96, 214.98], [2, 2.98, 23.31]]}, {"timestamp": 1578771710013, "ltp": 2.78, "tv": 3122.74, "trd": NaN, "batb": NaN, "batl": [[0, 2.88, 436.69]]}, {"timestamp": 1578771712017, "ltp": 2.78, "tv": 3122.74, "trd": NaN, "batb": [[0, 2.78, 342.19], [1, 2.76, 685.54], [2, 2.74, 23.83]], "batl": NaN}, {"timestamp": 1578771716038, "ltp": 2.78, "tv": 3122.74, "trd": NaN, "batb": [[0, 2.76, 685.54], [1, 2.74, 23.83], [2, 2.72, 15.31]], "batl": [[0, 2.88, 5.13]]}, {"timestamp": 1578771717037, "ltp": 2.78, "tv": 3122.74, "trd": NaN, "batb": NaN, "batl": [[1, 2.9, 552.43], [2, 2.96, 214.98]]}, {"timestamp": 1578771720963, "ltp": 2.78, "tv": 3122.74, "trd": NaN, "batb": NaN, "batl": [[1, 2.96, 15.11], [2, 2.98, 23.31]]}, {"timestamp": 1578771721962, "ltp": 2.78, "tv": 3122.74, "trd": NaN, "batb": NaN, "batl": [[0, 2.88, 423.92], [1, 2.92, 24.6], [2, 2.96, 15.11]]}, {"timestamp": 1578771728967, "ltp": 2.78, "tv": 3122.74, "trd": NaN, "batb": NaN, "batl": [[1, 2.9, 602.66], [2, 2.92, 24.6]]}, {"timestamp": 1578771762019, "ltp": 2.78, "tv": 3122.74, "trd": NaN, "batb": NaN, "batl": [[0, 2.88, 5.13]]}, {"timestamp": 1578771796055, "ltp": 2.78, "tv": 3122.74, "trd": NaN, "batb": [[0, 2.76, 730.66]], "batl": NaN}, {"timestamp": 1578771802051, "ltp": 2.78, "tv": 3122.74, "trd": NaN, "batb": NaN, "batl": [[1, 2.9, 505.62]]}, {"timestamp": 1578771807992, "ltp": 2.78, "tv": 3122.74, "trd": NaN, "batb": [[1, 2.74, 29.58]], "batl": NaN}, {"timestamp": 1578771829016, "ltp": 2.8, "tv": 3123.79, "trd": [[2.8, 1693.86]], "batb": NaN, "batl": [[0, 2.78, 14.26], [1, 2.88, 5.13], [2, 2.9, 505.62]]}, {"timestamp": 1578771830023, "ltp": 2.78, "tv": 3129.11, "trd": [[2.78, 155.21]], "batb": NaN, "batl": [[0, 2.78, 11.59]]}, {"timestamp": 1578771832008, "ltp": 2.78, "tv": 3140.26, "trd": [[2.78, 166.37]], "batb": NaN, "batl": [[0, 2.88, 5.57], [1, 2.9, 505.62], [2, 2.92, 24.6]]}, {"timestamp": 1578771833014, "ltp": 2.78, "tv": 3140.26, "trd": NaN, "batb": [[1, 2.74, 32.45]], "batl": NaN}, {"timestamp": 1578771835017, "ltp": 2.78, "tv": 3140.26, "trd": NaN, "batb": [[1, 2.74, 23.83]], "batl": NaN}, {"timestamp": 1578771836044, "ltp": 2.78, "tv": 3140.26, "trd": NaN, "batb": [[1, 2.74, 32.45]], "batl": NaN}, {"timestamp": 1578771838004, "ltp": 2.78, "tv": 3141.15, "trd": [[2.78, 167.25]], "batb": [[0, 2.78, 377.49], [1, 2.76, 219.93], [2, 2.74, 32.45]], "batl": [[0, 2.88, 5.13], [1, 2.92, 24.6], [2, 2.94, 64.75]]}, {"timestamp": 1578771841034, "ltp": 2.78, "tv": 3141.15, "trd": NaN, "batb": [[1, 2.76, 106.45], [2, 2.74, 147.24]], "batl": NaN}, {"timestamp": 1578771845025, "ltp": 2.78, "tv": 3141.15, "trd": NaN, "batb": NaN, "batl": [[0, 2.88, 396.68]]}, {"timestamp": 1578771850947, "ltp": 2.78, "tv": 3141.15, "trd": NaN, "batb": NaN, "batl": [[2, 2.96, 214.98]]}, {"timestamp": 1578771852014, "ltp": 2.78, "tv": 3141.15, "trd": NaN, "batb": NaN, "batl": [[2, 2.96, 15.11]]}, {"timestamp": 1578771853016, "ltp": 2.78, "tv": 3142.68, "trd": [[2.78, 168.78]], "batb": [[0, 2.78, 376.73]], "batl": [[1, 2.9, 517.53], [2, 2.92, 24.6]]}, {"timestamp": 1578771860041, "ltp": 2.78, "tv": 3142.68, "trd": NaN, "batb": [[2, 2.74, 145.4]], "batl": NaN}, {"timestamp": 1578771861967, "ltp": 2.78, "tv": 3142.68, "trd": NaN, "batb": [[0, 2.8, 21.32], [1, 2.78, 376.73], [2, 2.76, 85.35]], "batl": NaN}, {"timestamp": 1578771866046, "ltp": 2.8, "tv": 3151.2, "trd": [[2.8, 1702.38]], "batb": [[0, 2.8, 17.06]], "batl": NaN}, {"timestamp": 1578771867982, "ltp": 2.8, "tv": 3151.2, "trd": NaN, "batb": NaN, "batl": [[0, 2.88, 5.13]]}, {"timestamp": 1578771878981, "ltp": 2.8, "tv": 3151.2, "trd": NaN, "batb": NaN, "batl": [[0, 2.88, 386.47]]}, {"timestamp": 1578771903030, "ltp": 2.8, "tv": 3151.2, "trd": NaN, "batb": [[1, 2.76, 85.35], [2, 2.74, 138.62]], "batl": [[0, 2.88, 5.13], [1, 2.92, 24.6], [2, 2.96, 214.98]]}, {"timestamp": 1578771904978, "ltp": 2.8, "tv": 3151.2, "trd": NaN, "batb": NaN, "batl": [[1, 2.94, 62.25], [2, 2.96, 15.11]]}, {"timestamp": 1578771908039, "ltp": 2.8, "tv": 3151.2, "trd": NaN, "batb": [[2, 2.74, 23.83]], "batl": [[1, 2.96, 15.11], [2, 2.98, 23.31]]}, {"timestamp": 1578771910046, "ltp": 2.8, "tv": 3151.2, "trd": NaN, "batb": NaN, "batl": [[1, 3, 21.28], [2, 3.1, 24.12]]}, {"timestamp": 1578771912051, "ltp": 2.8, "tv": 3151.2, "trd": NaN, "batb": NaN, "batl": [[1, 3, 44.77]]}, {"timestamp": 1578771961992, "ltp": 2.8, "tv": 3151.8, "trd": [[2.8, 1702.98]], "batb": [[0, 2.8, 16.76]], "batl": NaN}, {"timestamp": 1578771969980, "ltp": 2.8, "tv": 3155.53, "trd": [[2.8, 1706.71]], "batb": [[0, 2.8, 14.89]], "batl": NaN}, {"timestamp": 1578771978023, "ltp": 2.8, "tv": 3159.27, "trd": [[2.8, 1710.45]], "batb": [[0, 2.8, 13.02]], "batl": NaN}, {"timestamp": 1578772003044, "ltp": 2.8, "tv": 3163.01, "trd": [[2.8, 1714.19]], "batb": [[0, 2.8, 11.15]], "batl": NaN}, {"timestamp": 1578772040984, "ltp": 2.8, "tv": 3173.11, "trd": [[2.8, 1724.29]], "batb": [[0, 2.8, 6.1]], "batl": NaN}, {"timestamp": 1578772069011, "ltp": 2.8, "tv": 3173.11, "trd": NaN, "batb": [[2, 2.72, 15.31]], "batl": [[1, 3, 23.49]]}, {"timestamp": 1578772071983, "ltp": 2.8, "tv": 3173.11, "trd": NaN, "batb": NaN, "batl": [[1, 2.94, 24.25], [2, 3, 23.49]]}, {"timestamp": 1578772073030, "ltp": 2.8, "tv": 3173.11, "trd": NaN, "batb": [[2, 2.74, 23.83]], "batl": [[2, 3, 44.77]]}, {"timestamp": 1578772082019, "ltp": 2.88, "tv": 3183.36, "trd": [[2.88, 72.45]], "batb": [[0, 2.88, 4.03], [1, 2.8, 6.1], [2, 2.76, 85.35]], "batl": [[0, 2.94, 24.25], [1, 3, 44.77], [2, 3.1, 24.12]]}, {"timestamp": 1578772083019, "ltp": 2.88, "tv": 3191.42, "trd": [[2.88, 80.51]], "batb": [[0, 2.8, 6.1], [1, 2.76, 85.35], [2, 2.74, 23.83]], "batl": NaN}, {"timestamp": 1578772087033, "ltp": 2.8, "tv": 3212.06, "trd": [[2.8, 1744.92]], "batb": [[0, 2.76, 85.35], [1, 2.74, 23.83], [2, 2.72, 15.31]], "batl": [[0, 2.8, 8.37], [1, 2.94, 24.25], [2, 3, 44.77]]}, {"timestamp": 1578772098026, "ltp": 2.8, "tv": 3222.15, "trd": [[2.8, 1755.02]], "batb": NaN, "batl": [[0, 2.8, 3.32]]}, {"timestamp": 1578772099563, "ltp": 2.8, "tv": 3222.15, "trd": NaN, "batb": [[0, 1.49, 0.01], [1, 2.74, 0], [2, 2.72, 0]], "batl": NaN}, {"timestamp": 1578772106990, "ltp": 2.8, "tv": 3222.15, "trd": NaN, "batb": [[0, 2.62, 63.85], [1, 1.49, 0.01]], "batl": NaN}, {"timestamp": 1578772108019, "ltp": 2.8, "tv": 3222.15, "trd": NaN, "batb": [[1, 2.58, 126.56], [2, 1.49, 0.01]], "batl": [[0, 3.25, 199.78]]}, {"timestamp": 1578772108966, "ltp": 2.8, "tv": 3222.15, "trd": NaN, "batb": [[1, 1.49, 0.01], [2, 1.49, 0]], "batl": NaN}, {"timestamp": 1578772114004, "ltp": 2.8, "tv": 3222.15, "trd": NaN, "batb": [[0, 2.7, 11.92], [1, 2.62, 63.85], [2, 1.49, 0.01]], "batl": NaN}, {"timestamp": 1578772114999, "ltp": 2.8, "tv": 3222.15, "trd": NaN, "batb": [[0, 2.76, 113.48], [1, 2.7, 11.92], [2, 2.62, 63.85]], "batl": [[0, 2.98, 49.76], [1, 3.25, 209.14]]}, {"timestamp": 1578772116004, "ltp": 2.8, "tv": 3222.15, "trd": NaN, "batb": [[0, 2.76, 137.31], [2, 2.68, 24.69]], "batl": [[1, 3.1, 19.58], [2, 3.15, 19.58]]}, {"timestamp": 1578772117012, "ltp": 2.8, "tv": 3222.15, "trd": NaN, "batb": [[0, 2.7, 11.92], [1, 2.68, 24.69], [2, 2.62, 63.85]], "batl": NaN}, {"timestamp": 1578772119004, "ltp": 2.8, "tv": 3222.15, "trd": NaN, "batb": [[1, 2.62, 63.85], [2, 1.49, 0.01]], "batl": NaN}, {"timestamp": 1578772122018, "ltp": 2.8, "tv": 3222.15, "trd": NaN, "batb": [[0, 2.72, 22], [1, 2.7, 37.92], [2, 2.68, 22]], "batl": [[1, 3.05, 34.84], [2, 3.1, 48.58]]}, {"timestamp": 1578772123020, "ltp": 2.8, "tv": 3222.15, "trd": NaN, "batb": [[0, 2.78, 42.77], [1, 2.72, 22], [2, 2.7, 57.28]], "batl": [[0, 2.94, 9.48], [1, 2.98, 67.44], [2, 3.05, 34.84]]}, {"timestamp": 1578772124032, "ltp": 2.8, "tv": 3222.15, "trd": NaN, "batb": [[0, 2.78, 539], [2, 2.7, 45.36]], "batl": NaN}, {"timestamp": 1578772125024, "ltp": 2.8, "tv": 3222.15, "trd": NaN, "batb": [[2, 2.7, 70.05]], "batl": NaN}, {"timestamp": 1578772131049, "ltp": 2.8, "tv": 3222.15, "trd": NaN, "batb": NaN, "batl": [[0, 2.94, 65.23], [2, 3.05, 44.15]]}, {"timestamp": 1578772132044, "ltp": 2.8, "tv": 3222.15, "trd": NaN, "batb": [[0, 2.78, 660.73]], "batl": NaN}, {"timestamp": 1578772132990, "ltp": 2.8, "tv": 3222.15, "trd": NaN, "batb": [[1, 2.7, 45.36], [2, 2.68, 42.05]], "batl": [[2, 3, 30]]}, {"timestamp": 1578772135024, "ltp": 2.8, "tv": 3222.15, "trd": NaN, "batb": [[1, 2.7, 57.28]], "batl": NaN}, {"timestamp": 1578772142048, "ltp": 2.8, "tv": 3222.15, "trd": NaN, "batb": NaN, "batl": [[0, 2.94, 209.48]]}, {"timestamp": 1578772146042, "ltp": 2.8, "tv": 3222.15, "trd": NaN, "batb": [[0, 2.78, 155.13]], "batl": NaN}, {"timestamp": 1578772148053, "ltp": 2.8, "tv": 3222.15, "trd": NaN, "batb": NaN, "batl": [[2, 3.05, 44.15]]}, {"timestamp": 1578772148952, "ltp": 2.8, "tv": 3222.15, "trd": NaN, "batb": NaN, "batl": [[0, 2.94, 153.73], [2, 3, 9.29]]}, {"timestamp": 1578772153956, "ltp": 2.78, "tv": 3222.46, "trd": [[2.78, 169.09]], "batb": [[0, 2.8, 250], [1, 2.78, 154.98], [2, 2.7, 57.28]], "batl": NaN}, {"timestamp": 1578772154951, "ltp": 2.78, "tv": 3222.46, "trd": NaN, "batb": [[1, 2.78, 407.78], [2, 2.72, 26]], "batl": NaN}, {"timestamp": 1578772155950, "ltp": 2.78, "tv": 3222.46, "trd": NaN, "batb": NaN, "batl": [[1, 2.98, 17.68]]}, {"timestamp": 1578772161961, "ltp": 2.78, "tv": 3222.46, "trd": NaN, "batb": [[2, 2.72, 142.09]], "batl": [[0, 2.94, 209.48]]}, {"timestamp": 1578772163053, "ltp": 2.8, "tv": 3230.29, "trd": [[2.8, 1762.85]], "batb": [[0, 2.8, 242.17]], "batl": NaN}, {"timestamp": 1578772164044, "ltp": 2.8, "tv": 3230.29, "trd": NaN, "batb": [[2, 2.72, 26]], "batl": NaN}, {"timestamp": 1578772166034, "ltp": 2.8, "tv": 3230.29, "trd": NaN, "batb": [[1, 2.78, 429.78], [2, 2.76, 25]], "batl": NaN}, {"timestamp": 1578772170053, "ltp": 2.8, "tv": 3230.29, "trd": NaN, "batb": [[0, 2.8, 250]], "batl": NaN}, {"timestamp": 1578772174045, "ltp": 2.8, "tv": 3230.29, "trd": NaN, "batb": [[1, 2.78, 317.62]], "batl": NaN}, {"timestamp": 1578772176969, "ltp": 2.8, "tv": 3230.29, "trd": NaN, "batb": [[1, 2.78, 295.62], [2, 2.74, 159.89]], "batl": NaN}, {"timestamp": 1578772179996, "ltp": 2.8, "tv": 3240.38, "trd": [[2.8, 1772.94]], "batb": [[0, 2.8, 244.95], [1, 2.78, 307.53]], "batl": NaN}, {"timestamp": 1578772180983, "ltp": 2.8, "tv": 3240.38, "trd": NaN, "batb": [[1, 2.78, 331.37]], "batl": NaN}, {"timestamp": 1578772183963, "ltp": 2.8, "tv": 3240.38, "trd": NaN, "batb": NaN, "batl": [[0, 2.94, 9.48]]}, {"timestamp": 1578772185006, "ltp": 2.8, "tv": 3240.38, "trd": NaN, "batb": NaN, "batl": [[0, 3.05, 8.84], [1, 3.1, 66.86], [2, 3.15, 33.51]]}, {"timestamp": 1578772185997, "ltp": 2.8, "tv": 3240.38, "trd": NaN, "batb": [[0, 2.82, 9.59], [1, 2.8, 244.95], [2, 2.78, 331.37]], "batl": NaN}, {"timestamp": 1578772187991, "ltp": 2.8, "tv": 3240.38, "trd": NaN, "batb": [[1, 2.8, 250]], "batl": NaN}, {"timestamp": 1578772189980, "ltp": 2.8, "tv": 3240.38, "trd": NaN, "batb": [[1, 2.8, 272.94]], "batl": [[1, 3.1, 83.57], [2, 3.15, 49.74]]}, {"timestamp": 1578772190967, "ltp": 2.8, "tv": 3240.38, "trd": NaN, "batb": [[2, 2.78, 307.53]], "batl": [[2, 3.15, 663.52]]}, {"timestamp": 1578772192015, "ltp": 2.8, "tv": 3240.38, "trd": NaN, "batb": NaN, "batl": [[0, 2.94, 199.75], [1, 3.05, 8.84], [2, 3.1, 83.57]]}, {"timestamp": 1578772192997, "ltp": 2.8, "tv": 3240.38, "trd": NaN, "batb": [[2, 2.78, 283.7]], "batl": [[0, 3.05, 8.84], [1, 3.1, 83.57], [2, 3.15, 58.54]]}, {"timestamp": 1578772193985, "ltp": 2.82, "tv": 3248.04, "trd": [[2.82, 312.3]], "batb": [[0, 2.82, 5.76]], "batl": NaN}, {"timestamp": 1578772197010, "ltp": 2.82, "tv": 3248.04, "trd": NaN, "batb": [[2, 2.78, 395.86]], "batl": NaN}, {"timestamp": 1578772197996, "ltp": 2.82, "tv": 3252.4, "trd": [[2.82, 316.66]], "batb": [[0, 2.82, 24.39], [2, 2.78, 283.7]], "batl": NaN}, {"timestamp": 1578772199036, "ltp": 2.82, "tv": 3252.4, "trd": NaN, "batb": NaN, "batl": [[1, 3.1, 394.09], [2, 3.15, 365.43]]}, {"timestamp": 1578772200033, "ltp": 2.82, "tv": 3252.4, "trd": NaN, "batb": [[0, 2.82, 47.37]], "batl": NaN}, {"timestamp": 1578772205038, "ltp": 2.82, "tv": 3252.4, "trd": NaN, "batb": NaN, "batl": [[2, 3.15, 58.54]]}, {"timestamp": 1578772206035, "ltp": 2.82, "tv": 3252.4, "trd": NaN, "batb": [[1, 2.8, 383.82]], "batl": [[0, 3.05, 18.15]]}, {"timestamp": 1578772207025, "ltp": 2.82, "tv": 3252.4, "trd": NaN, "batb": NaN, "batl": [[0, 3, 27], [1, 3.05, 57.46], [2, 3.1, 394.09]]}, {"timestamp": 1578772209009, "ltp": 2.8, "tv": 3394.9, "trd": [[2.8, 1820.7], [2.82, 411.4]], "batb": [[0, 2.8, 359.94], [1, 2.78, 283.7], [2, 2.76, 51.89]], "batl": NaN}, {"timestamp": 1578772210055, "ltp": 2.8, "tv": 3394.9, "trd": NaN, "batb": [[1, 2.78, 271.78]], "batl": NaN}, {"timestamp": 1578772212017, "ltp": 2.8, "tv": 3394.9, "trd": NaN, "batb": NaN, "batl": [[2, 3.1, 704.61]]}, {"timestamp": 1578772214029, "ltp": 2.8, "tv": 3394.9, "trd": NaN, "batb": NaN, "batl": [[0, 2.82, 1.87], [1, 3, 200], [2, 3.05, 34.46]]}, {"timestamp": 1578772215020, "ltp": 2.8, "tv": 3394.9, "trd": NaN, "batb": NaN, "batl": [[1, 2.98, 9.23], [2, 3, 226.45]]}, {"timestamp": 1578772216019, "ltp": 2.82, "tv": 3398.64, "trd": [[2.82, 415.14]], "batb": [[0, 2.84, 7.59], [1, 2.8, 383.82], [2, 2.78, 271.78]], "batl": [[0, 2.98, 9.23], [1, 3, 226.45], [2, 3.05, 34.46]]}, {"timestamp": 1578772217010, "ltp": 2.82, "tv": 3398.64, "trd": NaN, "batb": [[0, 2.8, 383.82], [1, 2.78, 271.78], [2, 2.76, 51.89]], "batl": NaN}, {"timestamp": 1578772219055, "ltp": 2.82, "tv": 3398.64, "trd": NaN, "batb": [[1, 2.78, 289.78]], "batl": NaN}, {"timestamp": 1578772221046, "ltp": 2.82, "tv": 3398.64, "trd": NaN, "batb": [[0, 2.8, 417.87], [1, 2.78, 313.62]], "batl": [[1, 3, 26.45]]}, {"timestamp": 1578772222038, "ltp": 2.82, "tv": 3398.64, "trd": NaN, "batb": NaN, "batl": [[0, 3.05, 34.46], [1, 3.1, 704.61], [2, 3.15, 42.31]]}, {"timestamp": 1578772225023, "ltp": 2.82, "tv": 3398.64, "trd": NaN, "batb": [[0, 2.82, 9], [1, 2.8, 417.87], [2, 2.78, 313.62]], "batl": NaN}, {"timestamp": 1578772229043, "ltp": 2.82, "tv": 3398.64, "trd": NaN, "batb": [[1, 2.8, 446.87]], "batl": [[0, 3.05, 57.46]]}, {"timestamp": 1578772230042, "ltp": 2.82, "tv": 3398.64, "trd": NaN, "batb": [[1, 2.8, 435.8], [2, 2.78, 289.78]], "batl": NaN}, {"timestamp": 1578772233979, "ltp": 2.82, "tv": 3398.64, "trd": NaN, "batb": NaN, "batl": [[0, 3.05, 34.46]]}, {"timestamp": 1578772236982, "ltp": 2.82, "tv": 3398.64, "trd": NaN, "batb": [[0, 2.82, 43.05]], "batl": NaN}, {"timestamp": 1578772238964, "ltp": 2.82, "tv": 3398.64, "trd": NaN, "batb": NaN, "batl": [[0, 3, 17], [1, 3.05, 34.46], [2, 3.1, 704.61]]}, {"timestamp": 1578772239957, "ltp": 2.82, "tv": 3398.64, "trd": NaN, "batb": NaN, "batl": [[0, 3.05, 34.46], [1, 3.1, 704.61], [2, 3.15, 42.31]]}, {"timestamp": 1578772245012, "ltp": 2.82, "tv": 3398.64, "trd": NaN, "batb": [[2, 2.78, 36.98]], "batl": NaN}, {"timestamp": 1578772245958, "ltp": 2.82, "tv": 3398.64, "trd": NaN, "batb": [[0, 2.82, 152.69], [1, 2.8, 74.92]], "batl": NaN}, {"timestamp": 1578772250050, "ltp": 2.82, "tv": 3398.64, "trd": NaN, "batb": [[0, 2.84, 18], [1, 2.82, 177.69], [2, 2.8, 74.92]], "batl": [[0, 3.05, 50.46]]}, {"timestamp": 1578772252005, "ltp": 2.82, "tv": 3398.64, "trd": NaN, "batb": [[2, 2.8, 324.92]], "batl": NaN}, {"timestamp": 1578772252994, "ltp": 2.82, "tv": 3398.64, "trd": NaN, "batb": [[0, 2.82, 424.94], [1, 2.8, 324.92], [2, 2.78, 36.98]], "batl": [[0, 3.05, 34.46]]}, {"timestamp": 1578772253994, "ltp": 2.82, "tv": 3398.64, "trd": NaN, "batb": [[0, 2.82, 315.3]], "batl": [[1, 3.1, 675.61]]}, {"timestamp": 1578772254993, "ltp": 2.82, "tv": 3398.64, "trd": NaN, "batb": [[0, 2.84, 9.75], [1, 2.82, 315.3], [2, 2.8, 324.92]], "batl": NaN}, {"timestamp": 1578772259971, "ltp": 2.82, "tv": 3398.64, "trd": NaN, "batb": [[0, 2.84, 118.22]], "batl": NaN}, {"timestamp": 1578772264028, "ltp": 2.82, "tv": 3398.64, "trd": NaN, "batb": [[1, 2.82, 68.05], [2, 2.8, 74.92]], "batl": [[1, 3.1, 54.57]]}, {"timestamp": 1578772264965, "ltp": 2.82, "tv": 3398.64, "trd": NaN, "batb": NaN, "batl": [[0, 3.05, 18.15]]}, {"timestamp": 1578772265855, "ltp": 2.84, "tv": 3406.11, "trd": [[2.84, 731.33]], "batb": [[0, 2.84, 114.49], [2, 2.8, 51.94]], "batl": [[0, 3.05, 8.84]]}, {"timestamp": 1578772267056, "ltp": 2.84, "tv": 3406.11, "trd": NaN, "batb": [[0, 2.86, 9.03], [1, 2.84, 114.49], [2, 2.82, 68.05]], "batl": NaN}, {"timestamp": 1578772268050, "ltp": 2.84, "tv": 3406.11, "trd": NaN, "batb": [[0, 2.86, 22.22]], "batl": [[0, 3, 200], [1, 3.05, 8.84], [2, 3.1, 54.57]]}, {"timestamp": 1578772269042, "ltp": 2.84, "tv": 3406.11, "trd": NaN, "batb": [[0, 2.84, 114.49], [1, 2.82, 68.05], [2, 2.8, 51.94]], "batl": NaN}, {"timestamp": 1578772270045, "ltp": 2.84, "tv": 3406.11, "trd": NaN, "batb": [[0, 2.84, 142.49]], "batl": [[2, 3.1, 83.57]]}, {"timestamp": 1578772272003, "ltp": 2.84, "tv": 3406.11, "trd": NaN, "batb": [[1, 2.82, 315.3], [2, 2.8, 301.94]], "batl": NaN}, {"timestamp": 1578772273001, "ltp": 2.84, "tv": 3406.11, "trd": NaN, "batb": [[0, 2.84, 57]], "batl": [[0, 3.05, 8.84], [1, 3.1, 83.57], [2, 3.15, 673.36]]}, {"timestamp": 1578772273991, "ltp": 2.84, "tv": 3406.11, "trd": NaN, "batb": NaN, "batl": [[2, 3.15, 656.09]]}, {"timestamp": 1578772275035, "ltp": 2.84, "tv": 3406.11, "trd": NaN, "batb": [[2, 2.8, 51.94]], "batl": [[0, 3, 18.48], [1, 3.05, 18.34], [2, 3.1, 83.57]]}, {"timestamp": 1578772276028, "ltp": 2.84, "tv": 3406.11, "trd": NaN, "batb": NaN, "batl": [[0, 3, 16.8], [1, 3.05, 34.47]]}, {"timestamp": 1578772277034, "ltp": 2.84, "tv": 3406.11, "trd": NaN, "batb": NaN, "batl": [[0, 3.05, 8.84], [1, 3.1, 83.57], [2, 3.15, 656.09]]}, {"timestamp": 1578772281005, "ltp": 2.84, "tv": 3406.11, "trd": NaN, "batb": [[0, 2.86, 9.81], [1, 2.84, 57], [2, 2.82, 315.3]], "batl": NaN}, {"timestamp": 1578772282055, "ltp": 2.84, "tv": 3406.11, "trd": NaN, "batb": [[2, 2.82, 562.55]], "batl": NaN}, {"timestamp": 1578772283045, "ltp": 2.84, "tv": 3406.11, "trd": NaN, "batb": [[1, 2.84, 29]], "batl": NaN}, {"timestamp": 1578772284044, "ltp": 2.84, "tv": 3406.11, "trd": NaN, "batb": [[0, 2.84, 29], [1, 2.82, 672.19], [2, 2.8, 51.94]], "batl": [[0, 3, 200], [1, 3.05, 8.84], [2, 3.1, 83.57]]}, {"timestamp": 1578772290015, "ltp": 2.84, "tv": 3406.11, "trd": NaN, "batb": [[1, 2.82, 562.55]], "batl": [[2, 3.1, 54.57]]}, {"timestamp": 1578772291956, "ltp": 2.84, "tv": 3406.11, "trd": NaN, "batb": NaN, "batl": [[0, 2.98, 9.23], [1, 3, 226.92], [2, 3.05, 35.43]]}, {"timestamp": 1578772293949, "ltp": 2.84, "tv": 3406.11, "trd": NaN, "batb": NaN, "batl": [[1, 3, 26.92]]}, {"timestamp": 1578772294860, "ltp": 2.84, "tv": 3406.11, "trd": NaN, "batb": [[0, 2.84, 6.02], [1, 2.82, 551.48]], "batl": [[0, 3.05, 18.05], [1, 3.1, 34.99], [2, 3.15, 656.09]]}, {"timestamp": 1578772296040, "ltp": 2.84, "tv": 3406.11, "trd": NaN, "batb": [[0, 1.03, 28.1], [1, 2.82, 0], [2, 2.8, 0]], "batl": [[0, 370, 1.7], [1, 890, 1.7], [2, 3.15, 0]]}, {"timestamp": 1578772347979, "ltp": 2.84, "tv": 3406.11, "trd": NaN, "batb": [[0, 1.49, 0.01]], "batl": NaN}, {"timestamp": 1578772356009, "ltp": 2.84, "tv": 3406.11, "trd": NaN, "batb": NaN, "batl": [[0, 1.65, 43.01]]}, {"timestamp": 1578772356995, "ltp": 2.84, "tv": 3406.11, "trd": NaN, "batb": NaN, "batl": [[1, 1000, 1.7]]}, {"timestamp": 1578772363012, "ltp": 1.49, "tv": 3406.13, "trd": [[1.49, 0.02]], "batb": [[0, 1.28, 47], [1, 1.27, 47], [2, 1.26, 40]], "batl": [[0, 1.4, 63.99], [1, 1.41, 43], [2, 1.42, 63]]}, {"timestamp": 1578772366041, "ltp": 1.49, "tv": 3406.13, "trd": NaN, "batb": [[0, 1.34, 21.28], [1, 1.28, 47], [2, 1.27, 47]], "batl": NaN}, {"timestamp": 1578772375041, "ltp": 1.49, "tv": 3406.13, "trd": NaN, "batb": NaN, "batl": [[0, 1.41, 43], [1, 1.42, 63], [2, 1.45, 21.28]]}, {"timestamp": 1578772375927, "ltp": 1.49, "tv": 3406.13, "trd": NaN, "batb": [[0, 1.34, 793.02]], "batl": [[0, 1.41, 380.5], [1, 1.42, 513]]}, {"timestamp": 1578772377028, "ltp": 1.49, "tv": 3406.13, "trd": NaN, "batb": [[1, 1.3, 26.83], [2, 1.29, 26.97]], "batl": [[0, 1.39, 20.93], [1, 1.4, 21.67], [2, 1.41, 64.73]]}, {"timestamp": 1578772378023, "ltp": 1.49, "tv": 3406.13, "trd": NaN, "batb": [[1, 1.3, 52.01], [2, 1.29, 52.82]], "batl": [[0, 1.4, 20.78], [1, 1.41, 84.71], [2, 1.42, 554.88]]}, {"timestamp": 1578772379046, "ltp": 1.49, "tv": 3406.13, "trd": NaN, "batb": NaN, "batl": [[0, 1.41, 84.71], [1, 1.42, 554.88], [2, 1.43, 20.8]]}, {"timestamp": 1578772380032, "ltp": 1.49, "tv": 3406.13, "trd": NaN, "batb": [[1, 1.3, 99.51], [2, 1.29, 105.29]], "batl": [[0, 1.4, 51.09], [1, 1.41, 132.86], [2, 1.42, 554.88]]}, {"timestamp": 1578772381024, "ltp": 1.49, "tv": 3406.13, "trd": NaN, "batb": [[2, 1.29, 52.82]], "batl": [[0, 1.41, 132.86], [1, 1.42, 554.88], [2, 1.43, 20.8]]}, {"timestamp": 1578772383028, "ltp": 1.49, "tv": 3406.13, "trd": NaN, "batb": [[1, 1.32, 75.49], [2, 1.31, 76.56]], "batl": NaN}, {"timestamp": 1578772384025, "ltp": 1.49, "tv": 3406.13, "trd": NaN, "batb": [[0, 1.34, 1564.76], [1, 1.32, 101.57], [2, 1.31, 103]], "batl": [[1, 1.42, 1004.88]]}, {"timestamp": 1578772384907, "ltp": 1.49, "tv": 3406.13, "trd": NaN, "batb": NaN, "batl": [[2, 1.43, 69.8]]}, {"timestamp": 1578772385966, "ltp": 1.49, "tv": 3406.13, "trd": NaN, "batb": [[0, 1.34, 21.28], [1, 1.32, 26.07], [2, 1.31, 26.44]], "batl": [[0, 1.41, 84.71], [1, 1.42, 104.88]]}, {"timestamp": 1578772386964, "ltp": 1.49, "tv": 3406.13, "trd": NaN, "batb": [[1, 1.29, 106.82], [2, 1.28, 103.33]], "batl": [[0, 1.41, 41.71]]}, {"timestamp": 1578772392023, "ltp": 1.39, "tv": 3414.52, "trd": [[1.39, 8.38]], "batb": NaN, "batl": NaN}, {"timestamp": 1578772392968, "ltp": 1.39, "tv": 3414.52, "trd": NaN, "batb": NaN, "batl": [[2, 1.43, 136.33]]}, {"timestamp": 1578772394032, "ltp": 1.4, "tv": 3416.51, "trd": [[1.4, 2]], "batb": [[0, 1.34, 1564.76], [1, 1.29, 159.29], [2, 1.28, 155.09]], "batl": [[0, 1.4, 50.05], [1, 1.41, 520.39], [2, 1.42, 554.88]]}, {"timestamp": 1578772394980, "ltp": 1.4, "tv": 3416.51, "trd": NaN, "batb": [[2, 1.28, 103.33]], "batl": [[0, 1.4, 21.45], [2, 1.42, 104.88]]}, {"timestamp": 1578772395979, "ltp": 1.4, "tv": 3416.51, "trd": NaN, "batb": [[0, 1.34, 793.02], [1, 1.32, 68], [2, 1.31, 69]], "batl": [[0, 1.41, 70.39], [1, 1.42, 104.88], [2, 1.43, 136.33]]}, {"timestamp": 1578772396977, "ltp": 1.4, "tv": 3416.51, "trd": NaN, "batb": [[1, 1.31, 69], [2, 1.3, 69]], "batl": [[0, 1.41, 21.73]]}, {"timestamp": 1578772399006, "ltp": 1.34, "tv": 3421.31, "trd": [[1.34, 4.8]], "batb": [[0, 1.34, 790.62]], "batl": NaN}, {"timestamp": 1578772400005, "ltp": 1.34, "tv": 3421.31, "trd": NaN, "batb": [[0, 1.35, 571.27], [1, 1.34, 18.88], [2, 1.31, 69]], "batl": [[0, 1.4, 199.79]]}, {"timestamp": 1578772402030, "ltp": 1.34, "tv": 3421.31, "trd": NaN, "batb": [[2, 1.32, 47.68]], "batl": NaN}, {"timestamp": 1578772403016, "ltp": 1.34, "tv": 3421.31, "trd": NaN, "batb": [[2, 1.32, 98.25]], "batl": NaN}, {"timestamp": 1578772404015, "ltp": 1.34, "tv": 3421.31, "trd": NaN, "batb": [[1, 1.34, 790.62]], "batl": [[1, 1.41, 337.5], [2, 1.42, 152.22]]}, {"timestamp": 1578772405006, "ltp": 1.34, "tv": 3421.31, "trd": NaN, "batb": NaN, "batl": [[1, 1.42, 152.22], [2, 1.43, 136.33]]}, {"timestamp": 1578772406002, "ltp": 1.34, "tv": 3421.31, "trd": NaN, "batb": NaN, "batl": [[1, 1.41, 57], [2, 1.42, 152.22]]}, {"timestamp": 1578772407006, "ltp": 1.4, "tv": 3455.11, "trd": [[1.4, 35.79]], "batb": NaN, "batl": [[0, 1.4, 182.89]]}, {"timestamp": 1578772407989, "ltp": 1.4, "tv": 3455.11, "trd": NaN, "batb": NaN, "batl": [[1, 1.41, 77.63]]}, {"timestamp": 1578772409981, "ltp": 1.4, "tv": 3455.47, "trd": [[1.4, 36.15]], "batb": NaN, "batl": [[0, 1.4, 182.71], [1, 1.41, 124.76]]}, {"timestamp": 1578772410978, "ltp": 1.4, "tv": 3455.47, "trd": NaN, "batb": NaN, "batl": [[2, 1.42, 173.5]]}, {"timestamp": 1578772411983, "ltp": 1.4, "tv": 3455.47, "trd": NaN, "batb": [[1, 1.34, 18.88]], "batl": NaN}, {"timestamp": 1578772413015, "ltp": 1.35, "tv": 3535.6, "trd": [[1.35, 4.6], [1.4, 111.69]], "batb": [[0, 1.35, 568.97], [1, 1.34, 211.81]], "batl": [[0, 1.4, 144.94], [1, 1.41, 237.26]]}, {"timestamp": 1578772413968, "ltp": 1.35, "tv": 3627.44, "trd": [[1.35, 96.44]], "batb": [[0, 1.35, 523.05]], "batl": [[1, 1.41, 124.76]]}, {"timestamp": 1578772416002, "ltp": 1.35, "tv": 3627.44, "trd": NaN, "batb": [[2, 1.33, 25.22]], "batl": [[0, 1.39, 19.13], [1, 1.4, 144.94], [2, 1.41, 124.76]]}, {"timestamp": 1578772417002, "ltp": 1.39, "tv": 3627.93, "trd": [[1.39, 8.88]], "batb": NaN, "batl": [[0, 1.39, 18.89]]}, {"timestamp": 1578772420033, "ltp": 1.39, "tv": 3627.93, "trd": NaN, "batb": NaN, "batl": [[1, 1.4, 199.78], [2, 1.41, 67.76]]}, {"timestamp": 1578772421024, "ltp": 1.39, "tv": 3635.36, "trd": [[1.39, 16.3]], "batb": [[1, 1.34, 790.62]], "batl": [[0, 1.39, 15.18], [2, 1.41, 517.76]]}, {"timestamp": 1578772422022, "ltp": 1.39, "tv": 3635.36, "trd": NaN, "batb": [[0, 1.34, 790.62], [1, 1.33, 25.22], [2, 1.32, 151.25]], "batl": NaN}, {"timestamp": 1578772423018, "ltp": 1.39, "tv": 3635.36, "trd": NaN, "batb": NaN, "batl": [[0, 1.35, 21.55], [1, 1.39, 15.18], [2, 1.4, 199.78]]}, {"timestamp": 1578772424895, "ltp": 1.36, "tv": 3715.83, "trd": [[1.35, 139.54], [1.36, 37.37]], "batb": [[0, 1.36, 3.5], [1, 1.35, 23.03], [2, 1.34, 834.3]], "batl": [[0, 1.39, 89.73], [1, 1.4, 270.69], [2, 1.41, 517.76]]}, {"timestamp": 1578772426002, "ltp": 1.39, "tv": 3716.91, "trd": [[1.39, 17.38]], "batb": [[0, 1.35, 69.33], [1, 1.34, 834.3], [2, 1.33, 25.22]], "batl": [[0, 1.39, 111.25], [1, 1.4, 291.24]]}, {"timestamp": 1578772426995, "ltp": 1.39, "tv": 3716.91, "trd": NaN, "batb": [[1, 1.34, 882.62]], "batl": [[2, 1.41, 538.84]]}, {"timestamp": 1578772428048, "ltp": 1.39, "tv": 3716.91, "trd": NaN, "batb": [[2, 1.33, 49.67]], "batl": NaN}, {"timestamp": 1578772430030, "ltp": 1.39, "tv": 3716.91, "trd": NaN, "batb": NaN, "batl": [[2, 1.41, 560.12]]}, {"timestamp": 1578772433026, "ltp": 1.39, "tv": 3717.02, "trd": [[1.39, 17.49]], "batb": [[0, 1.35, 46.3], [1, 1.34, 67.19]], "batl": [[0, 1.39, 111.2]]}, {"timestamp": 1578772434026, "ltp": 1.39, "tv": 3717.02, "trd": NaN, "batb": [[0, 1.34, 67.19], [1, 1.33, 49.67], [2, 1.32, 151.25]], "batl": [[2, 1.41, 1010.12]]}, {"timestamp": 1578772434956, "ltp": 1.39, "tv": 3717.02, "trd": NaN, "batb": [[0, 1.34, 42.03]], "batl": [[0, 1.35, 6.57], [1, 1.39, 111.2], [2, 1.4, 291.24]]}, {"timestamp": 1578772437014, "ltp": 1.39, "tv": 3717.02, "trd": NaN, "batb": [[2, 1.32, 50.56]], "batl": NaN}, {"timestamp": 1578772438051, "ltp": 1.35, "tv": 3730.17, "trd": [[1.35, 152.69]], "batb": [[0, 1.35, 564.7], [1, 1.34, 42.03], [2, 1.33, 49.67]], "batl": [[0, 1.39, 111.2], [1, 1.4, 291.24], [2, 1.41, 560.12]]}, {"timestamp": 1578772439044, "ltp": 1.35, "tv": 3730.17, "trd": NaN, "batb": NaN, "batl": [[0, 1.39, 142.97]]}, {"timestamp": 1578772440043, "ltp": 1.35, "tv": 3730.17, "trd": NaN, "batb": [[0, 1.35, 1135.18]], "batl": NaN}, {"timestamp": 1578772441035, "ltp": 1.35, "tv": 3730.17, "trd": NaN, "batb": [[1, 1.34, 86.18], [2, 1.33, 95.29]], "batl": NaN}, {"timestamp": 1578772442038, "ltp": 1.35, "tv": 3730.17, "trd": NaN, "batb": [[0, 1.35, 1159.81], [1, 1.34, 857.92]], "batl": NaN}, {"timestamp": 1578772442979, "ltp": 1.35, "tv": 3730.17, "trd": NaN, "batb": [[0, 1.35, 1166.25], [1, 1.34, 882.83]], "batl": [[0, 1.39, 328.25], [1, 1.4, 146.3]]}, {"timestamp": 1578772443967, "ltp": 1.35, "tv": 3730.17, "trd": NaN, "batb": [[0, 1.35, 1172.75]], "batl": [[2, 1.41, 512.99]]}, {"timestamp": 1578772445037, "ltp": 1.35, "tv": 3730.17, "trd": NaN, "batb": [[0, 1.35, 602.27], [1, 1.34, 111.09]], "batl": [[2, 1.41, 62.99]]}, {"timestamp": 1578772445968, "ltp": 1.35, "tv": 3745.47, "trd": [[1.35, 167.99]], "batb": [[0, 1.35, 594.62]], "batl": NaN}, {"timestamp": 1578772446968, "ltp": 1.35, "tv": 3745.47, "trd": NaN, "batb": [[1, 1.34, 282.36]], "batl": NaN}, {"timestamp": 1578772447990, "ltp": 1.35, "tv": 3745.47, "trd": NaN, "batb": [[1, 1.34, 92.21]], "batl": NaN}, {"timestamp": 1578772449055, "ltp": 1.35, "tv": 3745.47, "trd": NaN, "batb": [[1, 1.34, 134.77]], "batl": [[1, 1.4, 188.86]]}, {"timestamp": 1578772449944, "ltp": 1.35, "tv": 3745.47, "trd": NaN, "batb": NaN, "batl": [[0, 1.38, 14.58], [1, 1.39, 296.48], [2, 1.4, 188.86]]}, {"timestamp": 1578772451039, "ltp": 1.35, "tv": 3749.21, "trd": [[1.35, 171.73]], "batb": [[0, 1.35, 592.75]], "batl": [[0, 1.38, 90.32]]}, {"timestamp": 1578772451969, "ltp": 1.35, "tv": 3749.21, "trd": NaN, "batb": [[1, 1.34, 906.51]], "batl": [[0, 1.38, 14.58], [2, 1.4, 134.02]]}, {"timestamp": 1578772453944, "ltp": 1.35, "tv": 3749.21, "trd": NaN, "batb": [[2, 1.33, 116.57]], "batl": NaN}, {"timestamp": 1578772455040, "ltp": 1.35, "tv": 3749.21, "trd": NaN, "batb": [[1, 1.34, 1678.25]], "batl": [[1, 1.39, 317.76]]}, {"timestamp": 1578772456977, "ltp": 1.35, "tv": 3770.77, "trd": [[1.35, 193.29]], "batb": [[0, 1.35, 581.97]], "batl": NaN}, {"timestamp": 1578772457965, "ltp": 1.35, "tv": 3770.77, "trd": NaN, "batb": NaN, "batl": [[0, 1.38, 214.33], [1, 1.39, 117.9]]}, {"timestamp": 1578772458954, "ltp": 1.35, "tv": 3770.77, "trd": NaN, "batb": NaN, "batl": [[0, 1.38, 14.58]]}, {"timestamp": 1578772459942, "ltp": 1.35, "tv": 3770.77, "trd": NaN, "batb": NaN, "batl": [[2, 1.4, 584.02]]}, {"timestamp": 1578772460976, "ltp": 1.35, "tv": 3770.77, "trd": NaN, "batb": [[0, 1.35, 624.53]], "batl": [[0, 1.38, 90.24]]}, {"timestamp": 1578772461970, "ltp": 1.35, "tv": 3774.51, "trd": [[1.35, 197.03]], "batb": [[0, 1.35, 622.66]], "batl": [[0, 1.38, 14.58]]}, {"timestamp": 1578772468981, "ltp": 1.35, "tv": 3774.51, "trd": NaN, "batb": NaN, "batl": [[0, 1.38, 214.33]]}, {"timestamp": 1578772471002, "ltp": 1.35, "tv": 3774.51, "trd": NaN, "batb": NaN, "batl": [[0, 1.38, 199.75]]}, {"timestamp": 1578772472982, "ltp": 1.35, "tv": 3781.99, "trd": [[1.35, 204.51]], "batb": [[0, 1.35, 618.92]], "batl": NaN}, {"timestamp": 1578772476002, "ltp": 1.35, "tv": 3781.99, "trd": NaN, "batb": NaN, "batl": [[0, 1.38, 276.03]]}, {"timestamp": 1578772476996, "ltp": 1.35, "tv": 3781.99, "trd": NaN, "batb": NaN, "batl": [[0, 1.38, 297.13]]}, {"timestamp": 1578772477990, "ltp": 1.35, "tv": 3811.15, "trd": [[1.35, 233.67]], "batb": [[0, 1.35, 604.34]], "batl": NaN}, {"timestamp": 1578772478977, "ltp": 1.35, "tv": 3902.99, "trd": [[1.35, 325.51]], "batb": [[0, 1.35, 558.42]], "batl": [[2, 1.4, 641.02]]}, {"timestamp": 1578772484998, "ltp": 1.35, "tv": 3902.99, "trd": NaN, "batb": [[0, 1.35, 73.63]], "batl": NaN}, {"timestamp": 1578772487018, "ltp": 1.35, "tv": 4010.13, "trd": [[1.35, 432.65]], "batb": [[0, 1.35, 20.06], [1, 1.34, 906.51]], "batl": NaN}, {"timestamp": 1578772487975, "ltp": 1.35, "tv": 4010.13, "trd": NaN, "batb": NaN, "batl": [[2, 1.4, 598.46]]}, {"timestamp": 1578772490005, "ltp": 1.35, "tv": 4010.13, "trd": NaN, "batb": NaN, "batl": [[1, 1.39, 167.9]]}, {"timestamp": 1578772494000, "ltp": 1.35, "tv": 4010.13, "trd": NaN, "batb": NaN, "batl": [[1, 1.39, 210.46]]}, {"timestamp": 1578772496028, "ltp": 1.35, "tv": 4010.13, "trd": NaN, "batb": [[0, 1.35, 42.19]], "batl": NaN}, {"timestamp": 1578772497011, "ltp": 1.35, "tv": 4010.13, "trd": NaN, "batb": NaN, "batl": [[0, 1.37, 31.77], [1, 1.38, 297.13], [2, 1.39, 210.46]]}, {"timestamp": 1578772499031, "ltp": 1.35, "tv": 4010.13, "trd": NaN, "batb": [[2, 1.33, 722.4]], "batl": NaN}, {"timestamp": 1578772499980, "ltp": 1.35, "tv": 4010.13, "trd": NaN, "batb": [[0, 1.34, 906.51], [1, 1.33, 722.4], [2, 1.32, 50.56]], "batl": NaN}, {"timestamp": 1578772501021, "ltp": 1.35, "tv": 4010.13, "trd": NaN, "batb": NaN, "batl": [[1, 1.38, 362.13]]}, {"timestamp": 1578772503990, "ltp": 1.35, "tv": 4010.13, "trd": NaN, "batb": [[1, 1.33, 116.57]], "batl": NaN}, {"timestamp": 1578772504986, "ltp": 1.35, "tv": 4010.13, "trd": NaN, "batb": [[0, 1.34, 90.62]], "batl": [[0, 1.37, 254.66]]}, {"timestamp": 1578772506035, "ltp": 1.35, "tv": 4010.13, "trd": NaN, "batb": [[0, 1.34, 65.71]], "batl": [[1, 1.38, 162.38]]}, {"timestamp": 1578772507025, "ltp": 1.35, "tv": 4010.13, "trd": NaN, "batb": [[0, 1.34, 108.27]], "batl": NaN}, {"timestamp": 1578772508024, "ltp": 1.35, "tv": 4010.13, "trd": NaN, "batb": [[1, 1.33, 312.4]], "batl": NaN}, {"timestamp": 1578772508908, "ltp": 1.35, "tv": 4010.13, "trd": NaN, "batb": [[1, 1.33, 899.91]], "batl": NaN}, {"timestamp": 1578772509998, "ltp": 1.35, "tv": 4010.13, "trd": NaN, "batb": [[2, 1.32, 675.45]], "batl": NaN}, {"timestamp": 1578772511050, "ltp": 1.35, "tv": 4010.13, "trd": NaN, "batb": [[2, 1.32, 50.56]], "batl": NaN}, {"timestamp": 1578772512036, "ltp": 1.35, "tv": 4010.13, "trd": NaN, "batb": [[1, 1.33, 1683.25]], "batl": [[0, 1.37, 307.61], [2, 1.39, 660.46]]}, {"timestamp": 1578772513037, "ltp": 1.35, "tv": 4010.13, "trd": NaN, "batb": [[0, 1.34, 65.71], [2, 1.32, 98.25]], "batl": [[0, 1.37, 331.25]]}, {"timestamp": 1578772516044, "ltp": 1.35, "tv": 4010.13, "trd": NaN, "batb": NaN, "batl": [[2, 1.39, 1110.46]]}, {"timestamp": 1578772519021, "ltp": 1.35, "tv": 4010.13, "trd": NaN, "batb": [[0, 1.34, 42.56]], "batl": NaN}, {"timestamp": 1578772520046, "ltp": 1.35, "tv": 4010.13, "trd": NaN, "batb": [[1, 1.33, 1725.81]], "batl": NaN}, {"timestamp": 1578772524044, "ltp": 1.35, "tv": 4010.13, "trd": NaN, "batb": NaN, "batl": [[2, 1.39, 1153.02]]}, {"timestamp": 1578772525043, "ltp": 1.34, "tv": 4013.87, "trd": [[1.34, 8.54]], "batb": [[0, 1.34, 40.69]], "batl": NaN}, {"timestamp": 1578772527019, "ltp": 1.34, "tv": 4013.87, "trd": NaN, "batb": NaN, "batl": [[0, 1.36, 22.18], [1, 1.37, 331.25], [2, 1.38, 162.38]]}, {"timestamp": 1578772527957, "ltp": 1.34, "tv": 4013.87, "trd": NaN, "batb": [[1, 1.33, 1704.53]], "batl": NaN}, {"timestamp": 1578772530035, "ltp": 1.34, "tv": 4013.87, "trd": NaN, "batb": NaN, "batl": [[1, 1.37, 299.48]]}, {"timestamp": 1578772531960, "ltp": 1.34, "tv": 4013.87, "trd": NaN, "batb": NaN, "batl": [[0, 1.36, 53.95]]}, {"timestamp": 1578772534048, "ltp": 1.34, "tv": 4013.87, "trd": NaN, "batb": NaN, "batl": [[2, 1.38, 183.66]]}, {"timestamp": 1578772535036, "ltp": 1.34, "tv": 4013.87, "trd": NaN, "batb": [[2, 1.32, 119.53]], "batl": [[1, 1.37, 99.52]]}, {"timestamp": 1578772536036, "ltp": 1.34, "tv": 4013.87, "trd": NaN, "batb": NaN, "batl": [[0, 1.36, 90.95], [1, 1.37, 157.52]]}, {"timestamp": 1578772537038, "ltp": 1.34, "tv": 4013.87, "trd": NaN, "batb": [[2, 1.32, 744.42]], "batl": NaN}, {"timestamp": 1578772538971, "ltp": 1.34, "tv": 4021.34, "trd": [[1.34, 16.02]], "batb": [[0, 1.34, 36.95]], "batl": NaN}, {"timestamp": 1578772539950, "ltp": 1.34, "tv": 4021.34, "trd": NaN, "batb": NaN, "batl": [[0, 1.36, 164.34]]}, {"timestamp": 1578772542965, "ltp": 1.34, "tv": 4021.34, "trd": NaN, "batb": NaN, "batl": [[1, 1.37, 357.48]]}, {"timestamp": 1578772544979, "ltp": 1.34, "tv": 4021.34, "trd": NaN, "batb": [[0, 1.33, 1704.53], [1, 1.32, 744.42], [2, 1.31, 50.99]], "batl": NaN}, {"timestamp": 1578772545970, "ltp": 1.34, "tv": 4021.34, "trd": NaN, "batb": [[0, 1.34, 5.11], [1, 1.33, 1704.53], [2, 1.32, 744.42]], "batl": NaN}, {"timestamp": 1578772546997, "ltp": 1.34, "tv": 4021.34, "trd": NaN, "batb": [[0, 1.33, 1704.53], [1, 1.32, 744.42], [2, 1.31, 50.99]], "batl": NaN}, {"timestamp": 1578772548972, "ltp": 1.34, "tv": 4021.34, "trd": NaN, "batb": [[0, 1.33, 921.19]], "batl": NaN}, {"timestamp": 1578772551005, "ltp": 1.34, "tv": 4021.34, "trd": NaN, "batb": [[1, 1.32, 119.53]], "batl": [[0, 1.36, 132.57], [1, 1.37, 157.52], [2, 1.38, 226.22]]}, {"timestamp": 1578772551989, "ltp": 1.34, "tv": 4021.34, "trd": NaN, "batb": [[0, 1.33, 963.75]], "batl": [[0, 1.34, 15.31], [1, 1.36, 59.18], [2, 1.37, 157.52]]}, {"timestamp": 1578772554993, "ltp": 1.34, "tv": 4021.34, "trd": NaN, "batb": [[0, 1.33, 376.24]], "batl": [[0, 1.34, 17.6]]}, {"timestamp": 1578772556989, "ltp": 1.34, "tv": 4021.34, "trd": NaN, "batb": [[1, 1.32, 915.02], [2, 1.31, 96.99]], "batl": [[0, 1.34, 2.3]]}, {"timestamp": 1578772559996, "ltp": 1.34, "tv": 4021.34, "trd": NaN, "batb": NaN, "batl": [[0, 1.36, 59.18], [1, 1.37, 178.8], [2, 1.38, 1104.94]]}, {"timestamp": 1578772560977, "ltp": 1.34, "tv": 4021.34, "trd": NaN, "batb": NaN, "batl": [[0, 1.36, 138.05]]}, {"timestamp": 1578772561985, "ltp": 1.34, "tv": 4021.34, "trd": NaN, "batb": [[0, 1.33, 180.41]], "batl": [[0, 1.34, 31.77], [1, 1.36, 59.18], [2, 1.37, 178.8]]}, {"timestamp": 1578772564003, "ltp": 1.34, "tv": 4021.34, "trd": NaN, "batb": [[2, 1.31, 50.99]], "batl": NaN}, {"timestamp": 1578772566024, "ltp": 1.34, "tv": 4021.34, "trd": NaN, "batb": [[0, 1.33, 92.23]], "batl": NaN}, {"timestamp": 1578772567028, "ltp": 1.33, "tv": 4040.03, "trd": [[1.33, 18.69]], "batb": [[0, 1.33, 82.88]], "batl": NaN}, {"timestamp": 1578772570027, "ltp": 1.33, "tv": 4040.03, "trd": NaN, "batb": NaN, "batl": [[1, 1.36, 138.85]]}, {"timestamp": 1578772571010, "ltp": 1.33, "tv": 4040.03, "trd": NaN, "batb": NaN, "batl": [[0, 1.36, 138.85], [1, 1.37, 178.8], [2, 1.38, 654.94]]}, {"timestamp": 1578772571998, "ltp": 1.33, "tv": 4040.03, "trd": NaN, "batb": NaN, "batl": [[0, 1.36, 59.18]]}, {"timestamp": 1578772573030, "ltp": 1.33, "tv": 4040.03, "trd": NaN, "batb": [[1, 1.32, 957.58]], "batl": NaN}, {"timestamp": 1578772574008, "ltp": 1.33, "tv": 4044.63, "trd": [[1.33, 23.28]], "batb": [[0, 1.33, 80.58], [2, 1.31, 98.32]], "batl": NaN}, {"timestamp": 1578772582029, "ltp": 1.33, "tv": 4052.1, "trd": [[1.33, 30.76]], "batb": [[0, 1.33, 76.85], [1, 1.32, 1156.45]], "batl": [[2, 1.38, 767.44]]}, {"timestamp": 1578772583002, "ltp": 1.33, "tv": 4052.1, "trd": NaN, "batb": [[1, 1.32, 1753.07]], "batl": [[2, 1.38, 1104.94]]}, {"timestamp": 1578772589006, "ltp": 1.33, "tv": 4052.1, "trd": NaN, "batb": [[2, 1.31, 144.32]], "batl": NaN}, {"timestamp": 1578772590033, "ltp": 1.33, "tv": 4197.46, "trd": [[1.33, 176.11]], "batb": [[0, 1.33, 4.17]], "batl": NaN}, {"timestamp": 1578772598007, "ltp": 1.33, "tv": 4197.46, "trd": NaN, "batb": [[0, 1.33, 66.92], [1, 1.32, 2377.96]], "batl": [[0, 1.36, 259], [2, 1.38, 1147.5]]}, {"timestamp": 1578772599042, "ltp": 1.33, "tv": 4197.46, "trd": NaN, "batb": [[2, 1.31, 98.32]], "batl": NaN}, {"timestamp": 1578772602953, "ltp": 1.33, "tv": 4197.46, "trd": NaN, "batb": NaN, "batl": [[0, 1.35, 19.9], [1, 1.36, 259], [2, 1.37, 178.8]]}, {"timestamp": 1578772604041, "ltp": 1.33, "tv": 4197.46, "trd": NaN, "batb": NaN, "batl": [[0, 1.35, 33.35]]}, {"timestamp": 1578772605031, "ltp": 1.33, "tv": 4197.46, "trd": NaN, "batb": [[0, 1.32, 2377.96], [1, 1.31, 98.32], [2, 1.3, 192.48]], "batl": NaN}, {"timestamp": 1578772605967, "ltp": 1.33, "tv": 4197.46, "trd": NaN, "batb": NaN, "batl": [[1, 1.36, 282.63]]}, {"timestamp": 1578772606952, "ltp": 1.33, "tv": 4197.46, "trd": NaN, "batb": NaN, "batl": [[0, 1.35, 57.73], [1, 1.36, 338.34]]}, {"timestamp": 1578772609036, "ltp": 1.33, "tv": 4197.46, "trd": NaN, "batb": NaN, "batl": [[1, 1.36, 138.52]]}, {"timestamp": 1578772611053, "ltp": 1.33, "tv": 4197.46, "trd": NaN, "batb": NaN, "batl": [[0, 1.35, 82.36], [2, 1.37, 291.3]]}, {"timestamp": 1578772611983, "ltp": 1.33, "tv": 4197.46, "trd": NaN, "batb": [[0, 1.32, 2420.52]], "batl": [[0, 1.35, 57.73], [2, 1.37, 628.8]]}, {"timestamp": 1578772612975, "ltp": 1.33, "tv": 4197.46, "trd": NaN, "batb": NaN, "batl": [[0, 1.33, 40.74], [1, 1.35, 120.55], [2, 1.36, 138.52]]}, {"timestamp": 1578772618052, "ltp": 1.33, "tv": 4197.46, "trd": NaN, "batb": NaN, "batl": [[1, 1.35, 112.89]]}, {"timestamp": 1578772619962, "ltp": 1.33, "tv": 4197.46, "trd": NaN, "batb": NaN, "batl": [[0, 1.33, 59.42]]}, {"timestamp": 1578772621007, "ltp": 1.32, "tv": 4212.76, "trd": [[1.32, 15.31]], "batb": [[0, 1.32, 2412.87]], "batl": [[1, 1.35, 135.55]]}, {"timestamp": 1578772622048, "ltp": 1.32, "tv": 4212.76, "trd": NaN, "batb": [[1, 1.31, 144.32]], "batl": NaN}, {"timestamp": 1578772623990, "ltp": 1.32, "tv": 4212.76, "trd": NaN, "batb": [[0, 1.32, 1617.38]], "batl": NaN}, {"timestamp": 1578772624980, "ltp": 1.32, "tv": 4228.08, "trd": [[1.32, 30.63]], "batb": [[0, 1.32, 814.22], [1, 1.31, 98.32]], "batl": [[2, 1.36, 101.52]]}, {"timestamp": 1578772628005, "ltp": 1.32, "tv": 4228.08, "trd": NaN, "batb": NaN, "batl": [[0, 1.33, 40.74], [2, 1.36, 301.34]]}, {"timestamp": 1578772629978, "ltp": 1.32, "tv": 4228.08, "trd": NaN, "batb": NaN, "batl": [[0, 1.33, 42.6]]}, {"timestamp": 1578772630966, "ltp": 1.32, "tv": 4228.08, "trd": NaN, "batb": NaN, "batl": [[0, 1.33, 1.87], [2, 1.36, 101.52]]}, {"timestamp": 1578772632015, "ltp": 1.32, "tv": 4228.08, "trd": NaN, "batb": [[1, 1.31, 1714.76]], "batl": [[1, 1.35, 56.01], [2, 1.36, 45.81]]}, {"timestamp": 1578772633004, "ltp": 1.32, "tv": 4228.08, "trd": NaN, "batb": NaN, "batl": [[1, 1.35, 33.35]]}, {"timestamp": 1578772634971, "ltp": 1.32, "tv": 4228.08, "trd": NaN, "batb": [[1, 1.31, 906.54]], "batl": NaN}, {"timestamp": 1578772636993, "ltp": 1.32, "tv": 4228.08, "trd": NaN, "batb": [[2, 1.3, 171.2]], "batl": [[1, 1.35, 19.9]]}, {"timestamp": 1578772639970, "ltp": 1.32, "tv": 4228.08, "trd": NaN, "batb": NaN, "batl": [[1, 1.35, 44.03], [2, 1.36, 102.09]]}, {"timestamp": 1578772641007, "ltp": 1.32, "tv": 4228.08, "trd": NaN, "batb": NaN, "batl": [[1, 1.35, 19.9]]}, {"timestamp": 1578772642000, "ltp": 1.32, "tv": 4309.56, "trd": [[1.32, 112.1]], "batb": [[0, 1.32, 1568.98]], "batl": NaN}, {"timestamp": 1578772646010, "ltp": 1.32, "tv": 4346.93, "trd": [[1.32, 149.47]], "batb": [[0, 1.32, 1550.29]], "batl": NaN}, {"timestamp": 1578772646995, "ltp": 1.32, "tv": 4346.93, "trd": NaN, "batb": [[1, 1.31, 952.54], [2, 1.3, 192.48]], "batl": [[2, 1.36, 153.09]]}, {"timestamp": 1578772650004, "ltp": 1.32, "tv": 4346.93, "trd": NaN, "batb": [[0, 1.32, 1600.85]], "batl": NaN}, {"timestamp": 1578772661029, "ltp": 1.33, "tv": 4347.35, "trd": [[1.33, 176.54]], "batb": NaN, "batl": [[0, 1.33, 1.66]]}, {"timestamp": 1578772666033, "ltp": 1.33, "tv": 4347.35, "trd": NaN, "batb": [[0, 1.32, 1579.57]], "batl": NaN}, {"timestamp": 1578772672056, "ltp": 1.33, "tv": 4349.01, "trd": [[1.33, 178.19]], "batb": NaN, "batl": [[0, 1.36, 153.09], [1, 1.37, 650.08], [2, 1.38, 676.22]]}, {"timestamp": 1578772673046, "ltp": 1.33, "tv": 4349.01, "trd": NaN, "batb": [[0, 1.32, 1600.85]], "batl": NaN}, {"timestamp": 1578772675021, "ltp": 1.33, "tv": 4349.01, "trd": NaN, "batb": [[0, 1.32, 1600.98]], "batl": [[0, 1.36, 102.09]]}, {"timestamp": 1578772675953, "ltp": 1.33, "tv": 4349.01, "trd": NaN, "batb": [[0, 1.33, 24.83], [1, 1.32, 1600.85], [2, 1.31, 952.54]], "batl": NaN}, {"timestamp": 1578772678041, "ltp": 1.33, "tv": 4349.01, "trd": NaN, "batb": NaN, "batl": [[1, 1.37, 592.08]]}, {"timestamp": 1578772679028, "ltp": 1.33, "tv": 4349.01, "trd": NaN, "batb": [[0, 1.33, 50.18]], "batl": NaN}, {"timestamp": 1578772683042, "ltp": 1.33, "tv": 4349.01, "trd": NaN, "batb": [[0, 1.33, 98.2]], "batl": NaN}, {"timestamp": 1578772686033, "ltp": 1.36, "tv": 4352.41, "trd": [[1.36, 40.77]], "batb": NaN, "batl": [[0, 1.36, 100.38]]}, {"timestamp": 1578772690031, "ltp": 1.36, "tv": 4352.41, "trd": NaN, "batb": NaN, "batl": [[1, 1.37, 636.08]]}, {"timestamp": 1578772690956, "ltp": 1.36, "tv": 4352.67, "trd": [[1.36, 41.03]], "batb": NaN, "batl": [[0, 1.36, 100.26]]}, {"timestamp": 1578772693968, "ltp": 1.36, "tv": 4352.67, "trd": NaN, "batb": NaN, "batl": [[1, 1.37, 592.08]]}, {"timestamp": 1578772694955, "ltp": 1.36, "tv": 4352.67, "trd": NaN, "batb": [[1, 1.32, 1558.29]], "batl": [[2, 1.38, 633.66]]}, {"timestamp": 1578772700968, "ltp": 1.36, "tv": 4352.67, "trd": NaN, "batb": [[2, 1.31, 906.54]], "batl": NaN}, {"timestamp": 1578772701957, "ltp": 1.36, "tv": 4352.67, "trd": NaN, "batb": [[0, 1.33, 140.76]], "batl": NaN}, {"timestamp": 1578772703974, "ltp": 1.36, "tv": 4432.67, "trd": [[1.36, 121.03]], "batb": [[0, 1.35, 40], [1, 1.33, 140.76], [2, 1.32, 1558.29]], "batl": [[0, 1.36, 60.26]]}, {"timestamp": 1578772706050, "ltp": 1.36, "tv": 4432.67, "trd": NaN, "batb": [[0, 1.33, 140.76], [1, 1.32, 1558.29], [2, 1.31, 906.54]], "batl": [[2, 1.38, 612.38]]}, {"timestamp": 1578772706981, "ltp": 1.36, "tv": 4432.67, "trd": NaN, "batb": [[0, 1.33, 746.59], [1, 1.32, 933.4]], "batl": NaN}, {"timestamp": 1578772707982, "ltp": 1.36, "tv": 4432.67, "trd": NaN, "batb": [[0, 1.33, 140.76]], "batl": [[1, 1.37, 792.04]]}, {"timestamp": 1578772710029, "ltp": 1.36, "tv": 4432.67, "trd": NaN, "batb": NaN, "batl": [[2, 1.38, 547.38]]}, {"timestamp": 1578772712014, "ltp": 1.33, "tv": 4436.41, "trd": [[1.33, 181.93]], "batb": [[0, 1.33, 138.89], [2, 1.31, 98.32]], "batl": [[0, 1.36, 82.92], [1, 1.37, 342.04]]}, {"timestamp": 1578772713005, "ltp": 1.33, "tv": 4436.41, "trd": NaN, "batb": NaN, "batl": [[1, 1.37, 363.32]]}, {"timestamp": 1578772714011, "ltp": 1.33, "tv": 4436.41, "trd": NaN, "batb": NaN, "batl": [[1, 1.37, 399.32]]}, {"timestamp": 1578772717040, "ltp": 1.36, "tv": 4440.15, "trd": [[1.36, 124.77]], "batb": NaN, "batl": [[0, 1.36, 81.05]]}, {"timestamp": 1578772718985, "ltp": 1.36, "tv": 4440.15, "trd": NaN, "batb": [[1, 1.32, 912.12]], "batl": NaN}, {"timestamp": 1578772720049, "ltp": 1.33, "tv": 4631.49, "trd": [[1.33, 373.27]], "batb": [[0, 1.33, 42.56]], "batl": NaN}, {"timestamp": 1578772724995, "ltp": 1.33, "tv": 4631.49, "trd": NaN, "batb": [[1, 1.32, 1537.01]], "batl": NaN}, {"timestamp": 1578772725994, "ltp": 1.33, "tv": 4631.49, "trd": NaN, "batb": [[0, 1.32, 1537.01], [1, 1.31, 119.6], [2, 1.3, 192.48]], "batl": NaN}, {"timestamp": 1578772728034, "ltp": 1.33, "tv": 4631.49, "trd": NaN, "batb": [[1, 1.31, 927.82], [2, 1.3, 123.48]], "batl": [[0, 1.36, 147.05], [2, 1.38, 612.38]]}, {"timestamp": 1578772732012, "ltp": 1.33, "tv": 4631.49, "trd": NaN, "batb": [[0, 1.34, 94.96], [1, 1.33, 23.93], [2, 1.32, 1579.57]], "batl": [[2, 1.38, 654.94]]}, {"timestamp": 1578772732998, "ltp": 1.33, "tv": 4631.49, "trd": NaN, "batb": [[1, 1.33, 55.14]], "batl": NaN}, {"timestamp": 1578772734043, "ltp": 1.33, "tv": 4631.49, "trd": NaN, "batb": NaN, "batl": [[0, 1.36, 346.87], [1, 1.37, 199.36]]}, {"timestamp": 1578772735037, "ltp": 1.33, "tv": 4631.49, "trd": NaN, "batb": NaN, "batl": [[0, 1.35, 24.63], [1, 1.36, 346.87], [2, 1.37, 199.36]]}, {"timestamp": 1578772736024, "ltp": 1.33, "tv": 4631.49, "trd": NaN, "batb": NaN, "batl": [[0, 1.36, 346.87], [1, 1.37, 649.36], [2, 1.38, 654.94]]}, {"timestamp": 1578772740040, "ltp": 1.33, "tv": 4631.49, "trd": NaN, "batb": [[0, 1.35, 3.68], [1, 1.34, 94.96], [2, 1.33, 55.14]], "batl": NaN}, {"timestamp": 1578772741036, "ltp": 1.33, "tv": 4631.49, "trd": NaN, "batb": [[1, 1.33, 55.14], [2, 1.32, 1579.57]], "batl": NaN}, {"timestamp": 1578772742028, "ltp": 1.33, "tv": 4631.49, "trd": NaN, "batb": [[0, 1.35, 122.85]], "batl": NaN}, {"timestamp": 1578772749029, "ltp": 1.35, "tv": 4638.62, "trd": [[1.35, 439.78]], "batb": [[0, 1.35, 119.28]], "batl": NaN}, {"timestamp": 1578772750021, "ltp": 1.35, "tv": 4638.62, "trd": NaN, "batb": [[1, 1.34, 94.96], [2, 1.33, 119.64]], "batl": [[2, 1.38, 676.22]]}, {"timestamp": 1578772751007, "ltp": 1.35, "tv": 4643.21, "trd": [[1.35, 444.37]], "batb": [[0, 1.35, 116.99]], "batl": NaN}, {"timestamp": 1578772753040, "ltp": 1.35, "tv": 4746.66, "trd": [[1.35, 547.82]], "batb": [[0, 1.35, 65.26]], "batl": NaN}, {"timestamp": 1578772754033, "ltp": 1.35, "tv": 4877.18, "trd": [[1.35, 678.35]], "batb": [[0, 1.33, 119.64], [1, 1.32, 1579.57], [2, 1.31, 927.82]], "batl": [[0, 1.35, 197.76], [1, 1.36, 346.87], [2, 1.37, 649.36]]}, {"timestamp": 1578772754919, "ltp": 1.35, "tv": 4877.18, "trd": NaN, "batb": [[0, 1.32, 1579.57], [1, 1.31, 927.82], [2, 1.3, 74.95]], "batl": NaN}, {"timestamp": 1578772763042, "ltp": 1.35, "tv": 4877.18, "trd": NaN, "batb": NaN, "batl": [[0, 1.36, 346.87], [1, 1.37, 649.36], [2, 1.38, 622.67]]}, {"timestamp": 1578772763970, "ltp": 1.35, "tv": 4877.18, "trd": NaN, "batb": NaN, "batl": [[0, 1.35, 133.87], [1, 1.36, 346.87], [2, 1.37, 649.36]]}, {"timestamp": 1578772764959, "ltp": 1.35, "tv": 4929.5, "trd": [[1.35, 730.66]], "batb": NaN, "batl": [[0, 1.35, 107.71]]}, {"timestamp": 1578772769051, "ltp": 1.35, "tv": 4966.87, "trd": [[1.35, 768.03]], "batb": NaN, "batl": [[0, 1.35, 89.03]]}, {"timestamp": 1578772769986, "ltp": 1.35, "tv": 4966.87, "trd": NaN, "batb": NaN, "batl": [[0, 1.34, 197.76], [1, 1.35, 10.23], [2, 1.36, 346.87]]}, {"timestamp": 1578772774042, "ltp": 1.33, "tv": 4971.12, "trd": [[1.33, 377.52]], "batb": [[0, 1.32, 784.08], [1, 1.31, 119.6]], "batl": NaN}, {"timestamp": 1578772777992, "ltp": 1.33, "tv": 4971.12, "trd": NaN, "batb": NaN, "batl": [[1, 1.35, 121.2]]}, {"timestamp": 1578772781050, "ltp": 1.34, "tv": 5161.3, "trd": [[1.34, 206.2]], "batb": NaN, "batl": [[0, 1.34, 102.67]]}, {"timestamp": 1578772784993, "ltp": 1.34, "tv": 5182.07, "trd": [[1.34, 226.97]], "batb": NaN, "batl": [[0, 1.34, 92.29]]}, {"timestamp": 1578772785988, "ltp": 1.34, "tv": 5182.07, "trd": NaN, "batb": [[1, 1.31, 1736.04], [2, 1.3, 143.95]], "batl": NaN}, {"timestamp": 1578772786967, "ltp": 1.34, "tv": 5182.07, "trd": NaN, "batb": [[0, 1.32, 760.57]], "batl": NaN}, {"timestamp": 1578772790987, "ltp": 1.34, "tv": 5182.07, "trd": NaN, "batb": NaN, "batl": [[0, 1.35, 121.2], [1, 1.36, 346.87], [2, 1.37, 649.36]]}, {"timestamp": 1578772792022, "ltp": 1.34, "tv": 5182.07, "trd": NaN, "batb": [[2, 1.3, 122.67]], "batl": [[2, 1.37, 691.92]]}, {"timestamp": 1578772793002, "ltp": 1.34, "tv": 5182.07, "trd": NaN, "batb": NaN, "batl": [[0, 1.34, 55.69], [1, 1.35, 121.2], [2, 1.36, 346.87]]}, {"timestamp": 1578772793985, "ltp": 1.34, "tv": 5182.07, "trd": NaN, "batb": NaN, "batl": [[0, 1.35, 121.2], [1, 1.36, 346.87], [2, 1.37, 691.92]]}, {"timestamp": 1578772795020, "ltp": 1.34, "tv": 5182.07, "trd": NaN, "batb": [[2, 1.3, 190.54]], "batl": NaN}, {"timestamp": 1578772796021, "ltp": 1.33, "tv": 5182.38, "trd": [[1.33, 377.82]], "batb": NaN, "batl": [[0, 1.33, 2.3], [1, 1.35, 121.2], [2, 1.36, 346.87]]}, {"timestamp": 1578772797990, "ltp": 1.33, "tv": 5182.38, "trd": NaN, "batb": [[0, 1.32, 718.01]], "batl": [[0, 1.33, 94.59]]}, {"timestamp": 1578772799026, "ltp": 1.33, "tv": 5182.38, "trd": NaN, "batb": [[0, 1.32, 736.27]], "batl": NaN}, {"timestamp": 1578772799906, "ltp": 1.32, "tv": 5191.03, "trd": [[1.32, 158.13]], "batb": [[0, 1.32, 663.12]], "batl": NaN}, {"timestamp": 1578772804005, "ltp": 1.32, "tv": 5191.03, "trd": NaN, "batb": NaN, "batl": [[0, 1.33, 92.29]]}, {"timestamp": 1578772804999, "ltp": 1.32, "tv": 5191.03, "trd": NaN, "batb": [[1, 1.31, 1778.6]], "batl": NaN}, {"timestamp": 1578772806013, "ltp": 1.32, "tv": 5191.03, "trd": NaN, "batb": NaN, "batl": [[1, 1.34, 131], [2, 1.35, 121.2]]}, {"timestamp": 1578772809033, "ltp": 1.33, "tv": 5203.04, "trd": [[1.33, 389.83]], "batb": NaN, "batl": [[0, 1.33, 86.29]]}, {"timestamp": 1578772811015, "ltp": 1.32, "tv": 5207.63, "trd": [[1.32, 162.73]], "batb": [[0, 1.32, 660.82]], "batl": NaN}, {"timestamp": 1578772816037, "ltp": 1.32, "tv": 5211.16, "trd": [[1.32, 166.25]], "batb": [[0, 1.32, 659.06]], "batl": NaN}, {"timestamp": 1578772821016, "ltp": 1.32, "tv": 5211.16, "trd": NaN, "batb": NaN, "batl": [[2, 1.35, 321.1]]}, {"timestamp": 1578772827020, "ltp": 1.32, "tv": 5211.16, "trd": NaN, "batb": [[0, 1.32, 616.5]], "batl": NaN}, {"timestamp": 1578772834052, "ltp": 1.32, "tv": 5211.16, "trd": NaN, "batb": [[1, 1.31, 1821.16]], "batl": NaN}, {"timestamp": 1578772838047, "ltp": 1.32, "tv": 5211.16, "trd": NaN, "batb": NaN, "batl": [[0, 1.34, 131], [1, 1.35, 321.1], [2, 1.36, 660.89]]}, {"timestamp": 1578772839029, "ltp": 1.32, "tv": 5211.16, "trd": NaN, "batb": NaN, "batl": [[0, 1.35, 321.1], [1, 1.36, 660.89], [2, 1.37, 125.13]]}, {"timestamp": 1578772842055, "ltp": 1.32, "tv": 5211.16, "trd": NaN, "batb": [[1, 1.31, 1799.88]], "batl": NaN}, {"timestamp": 1578772842952, "ltp": 1.32, "tv": 5211.16, "trd": NaN, "batb": NaN, "batl": [[0, 1.35, 365.1]]}, {"timestamp": 1578772844986, "ltp": 1.32, "tv": 5211.16, "trd": NaN, "batb": [[1, 1.31, 991.66]], "batl": NaN}, {"timestamp": 1578772845978, "ltp": 1.32, "tv": 5383.73, "trd": [[1.32, 338.83]], "batb": [[0, 1.32, 555.23]], "batl": [[2, 1.37, 575.13]]}, {"timestamp": 1578772848979, "ltp": 1.32, "tv": 5383.73, "trd": NaN, "batb": [[2, 1.3, 211.82]], "batl": NaN}, {"timestamp": 1578772851988, "ltp": 1.32, "tv": 5383.73, "trd": NaN, "batb": [[2, 1.3, 1033.4]], "batl": NaN}, {"timestamp": 1578772852978, "ltp": 1.32, "tv": 5383.73, "trd": NaN, "batb": [[0, 1.32, 590.34]], "batl": NaN}, {"timestamp": 1578772853962, "ltp": 1.32, "tv": 5383.73, "trd": NaN, "batb": [[0, 1.32, 657.76]], "batl": NaN}, {"timestamp": 1578772855006, "ltp": 1.32, "tv": 5383.73, "trd": NaN, "batb": NaN, "batl": [[2, 1.37, 532.57]]}, {"timestamp": 1578772855984, "ltp": 1.32, "tv": 5383.73, "trd": NaN, "batb": [[2, 1.3, 964.4]], "batl": [[0, 1.35, 321.1]]}, {"timestamp": 1578772862002, "ltp": 1.32, "tv": 5383.73, "trd": NaN, "batb": NaN, "batl": [[1, 1.36, 703.45]]}, {"timestamp": 1578772862982, "ltp": 1.32, "tv": 5383.73, "trd": NaN, "batb": NaN, "batl": [[2, 1.37, 553.85]]}, {"timestamp": 1578772865008, "ltp": 1.32, "tv": 5383.73, "trd": NaN, "batb": [[2, 1.3, 1018.4]], "batl": NaN}, {"timestamp": 1578772871031, "ltp": 1.32, "tv": 5391.21, "trd": [[1.32, 346.3]], "batb": [[0, 1.32, 654.02]], "batl": NaN}, {"timestamp": 1578772875025, "ltp": 1.32, "tv": 5391.21, "trd": NaN, "batb": NaN, "batl": [[1, 1.36, 253.45], [2, 1.37, 103.85]]}, {"timestamp": 1578772882045, "ltp": 1.32, "tv": 5391.21, "trd": NaN, "batb": [[2, 1.3, 964.4]], "batl": [[0, 1.34, 25.16], [1, 1.35, 771.1], [2, 1.36, 253.45]]}, {"timestamp": 1578772883027, "ltp": 1.32, "tv": 5391.21, "trd": NaN, "batb": NaN, "batl": [[2, 1.36, 703.45]]}, {"timestamp": 1578772893031, "ltp": 1.32, "tv": 5391.21, "trd": NaN, "batb": [[0, 1.32, 127.55]], "batl": NaN}, {"timestamp": 1578772894020, "ltp": 1.32, "tv": 5391.21, "trd": NaN, "batb": [[0, 1.32, 25.02]], "batl": NaN}, {"timestamp": 1578772894905, "ltp": 1.32, "tv": 5391.21, "trd": NaN, "batb": [[0, 1.31, 991.66], [1, 1.3, 964.4], [2, 1.29, 137.24]], "batl": NaN}, {"timestamp": 1578772896043, "ltp": 1.32, "tv": 5391.21, "trd": NaN, "batb": [[0, 1.31, 949.1]], "batl": NaN}, {"timestamp": 1578772896938, "ltp": 1.32, "tv": 5391.21, "trd": NaN, "batb": [[0, 1.31, 342.93]], "batl": NaN}, {"timestamp": 1578772898031, "ltp": 1.32, "tv": 5391.21, "trd": NaN, "batb": [[0, 1.31, 140.88]], "batl": [[2, 1.36, 253.45]]}, {"timestamp": 1578772900957, "ltp": 1.32, "tv": 5391.21, "trd": NaN, "batb": NaN, "batl": [[0, 1.34, 136.87], [2, 1.36, 232.17]]}, {"timestamp": 1578772903039, "ltp": 1.32, "tv": 5391.21, "trd": NaN, "batb": [[1, 1.3, 1006.96], [2, 1.29, 53.96]], "batl": NaN}, {"timestamp": 1578772904041, "ltp": 1.32, "tv": 5391.21, "trd": NaN, "batb": [[0, 1.31, 98.32]], "batl": [[0, 1.32, 17.02], [1, 1.34, 136.87], [2, 1.35, 771.1]]}, {"timestamp": 1578772904921, "ltp": 1.32, "tv": 5391.21, "trd": NaN, "batb": NaN, "batl": [[1, 1.34, 336.62], [2, 1.35, 571.2]]}, {"timestamp": 1578772907035, "ltp": 1.32, "tv": 5391.21, "trd": NaN, "batb": NaN, "batl": [[2, 1.35, 592.48]]}, {"timestamp": 1578772908955, "ltp": 1.32, "tv": 5391.21, "trd": NaN, "batb": NaN, "batl": [[0, 1.32, 18.89]]}, {"timestamp": 1578772909953, "ltp": 1.32, "tv": 5391.21, "trd": NaN, "batb": NaN, "batl": [[1, 1.34, 388.62], [2, 1.35, 679.04]]}, {"timestamp": 1578772910849, "ltp": 1.32, "tv": 5391.21, "trd": NaN, "batb": [[1, 1.3, 1049.52]], "batl": [[1, 1.34, 336.62], [2, 1.35, 635.04]]}, {"timestamp": 1578772911956, "ltp": 1.31, "tv": 5437.13, "trd": [[1.31, 45.92]], "batb": [[0, 1.31, 75.37]], "batl": NaN}, {"timestamp": 1578772913047, "ltp": 1.31, "tv": 5437.13, "trd": NaN, "batb": [[1, 1.3, 227.94]], "batl": [[2, 1.35, 185.04]]}, {"timestamp": 1578772914044, "ltp": 1.31, "tv": 5437.13, "trd": NaN, "batb": [[0, 1.31, 47.34]], "batl": [[0, 1.32, 17.02]]}, {"timestamp": 1578772914973, "ltp": 1.31, "tv": 5437.13, "trd": NaN, "batb": [[0, 1.3, 227.94], [1, 1.29, 53.96], [2, 1.28, 131.32]], "batl": NaN}, {"timestamp": 1578772915958, "ltp": 1.31, "tv": 5437.13, "trd": NaN, "batb": NaN, "batl": [[0, 1.34, 336.62], [1, 1.35, 227.6], [2, 1.36, 147.05]]}, {"timestamp": 1578772916952, "ltp": 1.31, "tv": 5437.13, "trd": NaN, "batb": NaN, "batl": [[0, 1.33, 24.45], [1, 1.34, 336.62], [2, 1.35, 227.6]]}, {"timestamp": 1578772919975, "ltp": 1.31, "tv": 5437.13, "trd": NaN, "batb": [[0, 1.31, 645.08], [1, 1.3, 227.94], [2, 1.29, 53.96]], "batl": [[1, 1.34, 136.87], [2, 1.35, 384.94]]}, {"timestamp": 1578772920969, "ltp": 1.31, "tv": 5440.87, "trd": [[1.31, 49.66]], "batb": [[0, 1.31, 643.21], [1, 1.3, 1006.96], [2, 1.29, 92.96]], "batl": [[0, 1.34, 136.87], [1, 1.35, 384.94], [2, 1.36, 597.05]]}, {"timestamp": 1578772921967, "ltp": 1.31, "tv": 5440.87, "trd": NaN, "batb": [[1, 1.3, 1212.35], [2, 1.29, 167.18]], "batl": [[2, 1.36, 709.55]]}, {"timestamp": 1578772922971, "ltp": 1.31, "tv": 5474.91, "trd": [[1.31, 83.7]], "batb": [[0, 1.31, 626.19], [1, 1.3, 1828.54]], "batl": [[2, 1.36, 1047.05]]}, {"timestamp": 1578772926968, "ltp": 1.31, "tv": 5474.91, "trd": NaN, "batb": [[0, 1.31, 668.75]], "batl": [[1, 1.35, 8897.03], [2, 1.36, 1089.61]]}, {"timestamp": 1578772927949, "ltp": 1.31, "tv": 5474.91, "trd": NaN, "batb": [[0, 1.31, 798.42]], "batl": NaN}, {"timestamp": 1578772930999, "ltp": 1.31, "tv": 5474.91, "trd": NaN, "batb": [[1, 1.3, 1006.96]], "batl": [[2, 1.36, 639.61]]}, {"timestamp": 1578772933968, "ltp": 1.31, "tv": 5474.91, "trd": NaN, "batb": [[0, 1.31, 755.86]], "batl": NaN}, {"timestamp": 1578772937979, "ltp": 1.31, "tv": 5474.91, "trd": NaN, "batb": [[1, 1.3, 1044.96], [2, 1.29, 1002.8]], "batl": [[1, 1.35, 9147.13]]}, {"timestamp": 1578772938980, "ltp": 1.31, "tv": 5474.91, "trd": NaN, "batb": [[2, 1.29, 167.18]], "batl": NaN}, {"timestamp": 1578772939966, "ltp": 1.31, "tv": 5474.91, "trd": NaN, "batb": [[1, 1.3, 1006.96], [2, 1.29, 128.18]], "batl": [[0, 1.34, 56.36]]}, {"timestamp": 1578772941009, "ltp": 1.31, "tv": 5474.91, "trd": NaN, "batb": [[1, 1.3, 1049.52]], "batl": NaN}, {"timestamp": 1578772942001, "ltp": 1.31, "tv": 5474.91, "trd": NaN, "batb": [[1, 1.3, 1028.24]], "batl": NaN}, {"timestamp": 1578772942990, "ltp": 1.31, "tv": 5600.21, "trd": [[1.31, 209]], "batb": [[0, 1.31, 693.21]], "batl": NaN}, {"timestamp": 1578772946028, "ltp": 1.31, "tv": 5600.21, "trd": NaN, "batb": [[2, 1.29, 963.8]], "batl": NaN}, {"timestamp": 1578772948002, "ltp": 1.31, "tv": 5600.21, "trd": NaN, "batb": [[2, 1.29, 1025.8]], "batl": [[0, 1.34, 93.36], [1, 1.35, 9191.13], [2, 1.36, 660.89]]}, {"timestamp": 1578772948994, "ltp": 1.31, "tv": 5600.21, "trd": NaN, "batb": [[2, 1.29, 1047.08]], "batl": NaN}, {"timestamp": 1578772950045, "ltp": 1.31, "tv": 5600.21, "trd": NaN, "batb": [[1, 1.3, 206.66], [2, 1.29, 211.46]], "batl": [[1, 1.35, 8741.13], [2, 1.36, 210.89]]}, {"timestamp": 1578772951764, "ltp": 1.31, "tv": 5600.21, "trd": NaN, "batb": [[0, 1.32, 25.02], [1, 1.31, 693.21], [2, 1.3, 206.66]], "batl": NaN}, {"timestamp": 1578772956048, "ltp": 1.31, "tv": 5600.21, "trd": NaN, "batb": NaN, "batl": [[0, 1.34, 176.39]]}, {"timestamp": 1578772971051, "ltp": 1.34, "tv": 5604.72, "trd": [[1.34, 231.48]], "batb": NaN, "batl": [[0, 1.34, 174.13]]}, {"timestamp": 1578772976972, "ltp": 1.34, "tv": 5604.72, "trd": NaN, "batb": [[0, 1.32, 26.89]], "batl": NaN}, {"timestamp": 1578772977969, "ltp": 1.34, "tv": 5604.72, "trd": NaN, "batb": [[0, 1.32, 1.87]], "batl": NaN}, {"timestamp": 1578772979993, "ltp": 1.34, "tv": 5604.72, "trd": NaN, "batb": [[1, 1.31, 129.67], [2, 1.3, 873.14]], "batl": NaN}, {"timestamp": 1578772980986, "ltp": 1.32, "tv": 5608.5, "trd": [[1.32, 350.08]], "batb": [[0, 1.31, 129.67], [1, 1.3, 873.14], [2, 1.29, 211.46]], "batl": [[0, 1.32, 26.11], [1, 1.34, 137.13], [2, 1.35, 8741.13]]}, {"timestamp": 1578772981970, "ltp": 1.32, "tv": 5608.5, "trd": NaN, "batb": [[2, 1.29, 149.46]], "batl": NaN}, {"timestamp": 1578772986041, "ltp": 1.32, "tv": 5634.61, "trd": [[1.32, 376.19]], "batb": NaN, "batl": [[0, 1.34, 137.13], [1, 1.35, 8941.03], [2, 1.36, 210.89]]}, {"timestamp": 1578772989014, "ltp": 1.32, "tv": 5634.61, "trd": NaN, "batb": [[1, 1.3, 1694.72], [2, 1.29, 985.08]], "batl": [[1, 1.35, 9369.75], [2, 1.36, 660.89]]}, {"timestamp": 1578772996002, "ltp": 1.32, "tv": 5634.61, "trd": NaN, "batb": [[0, 1.31, 774.75], [1, 1.3, 1028.24]], "batl": NaN}, {"timestamp": 1578772996888, "ltp": 1.32, "tv": 5634.61, "trd": NaN, "batb": NaN, "batl": [[2, 1.36, 682.17]]}, {"timestamp": 1578773000010, "ltp": 1.32, "tv": 5634.61, "trd": NaN, "batb": [[2, 1.29, 1032.08]], "batl": [[0, 1.34, 189.13]]}, {"timestamp": 1578773005049, "ltp": 1.32, "tv": 5634.61, "trd": NaN, "batb": [[1, 1.3, 985.68], [2, 1.29, 196.46]], "batl": [[2, 1.36, 639.61]]}, {"timestamp": 1578773007999, "ltp": 1.32, "tv": 5634.61, "trd": NaN, "batb": [[0, 1.31, 129.67]], "batl": NaN}, {"timestamp": 1578773012041, "ltp": 1.32, "tv": 5634.61, "trd": NaN, "batb": [[1, 1.3, 1807.26]], "batl": NaN}, {"timestamp": 1578773014018, "ltp": 1.32, "tv": 5634.61, "trd": NaN, "batb": NaN, "batl": [[0, 1.34, 137.13]]}, {"timestamp": 1578773014949, "ltp": 1.32, "tv": 5634.61, "trd": NaN, "batb": [[0, 1.31, 184.5]], "batl": [[2, 1.36, 618.33]]}, {"timestamp": 1578773016042, "ltp": 1.32, "tv": 5634.61, "trd": NaN, "batb": [[1, 1.3, 1849.82]], "batl": [[1, 1.35, 9412.31]]}, {"timestamp": 1578773019054, "ltp": 1.32, "tv": 5634.61, "trd": NaN, "batb": [[2, 1.29, 149.46]], "batl": NaN}, {"timestamp": 1578773021056, "ltp": 1.32, "tv": 5634.61, "trd": NaN, "batb": [[1, 1.3, 1911.82]], "batl": NaN}, {"timestamp": 1578773022047, "ltp": 1.32, "tv": 5634.61, "trd": NaN, "batb": NaN, "batl": [[1, 1.35, 9433.59]]}, {"timestamp": 1578773026965, "ltp": 1.32, "tv": 5634.61, "trd": NaN, "batb": [[1, 1.3, 2578.3]], "batl": NaN}, {"timestamp": 1578773031036, "ltp": 1.31, "tv": 5638.35, "trd": [[1.31, 212.74]], "batb": [[0, 1.31, 182.63]], "batl": NaN}, {"timestamp": 1578773033947, "ltp": 1.34, "tv": 5642.03, "trd": [[1.34, 235.16]], "batb": NaN, "batl": [[0, 1.34, 135.29]]}, {"timestamp": 1578773035049, "ltp": 1.34, "tv": 5642.03, "trd": NaN, "batb": [[2, 1.29, 219.46]], "batl": NaN}, {"timestamp": 1578773036039, "ltp": 1.34, "tv": 5642.03, "trd": NaN, "batb": NaN, "batl": [[0, 1.34, 335.04], [1, 1.35, 9233.69]]}, {"timestamp": 1578773043049, "ltp": 1.31, "tv": 5654.03, "trd": [[1.31, 224.74]], "batb": [[0, 1.31, 176.63]], "batl": NaN}, {"timestamp": 1578773046973, "ltp": 1.31, "tv": 5702.63, "trd": [[1.31, 273.35]], "batb": [[0, 1.31, 152.33]], "batl": NaN}, {"timestamp": 1578773048968, "ltp": 1.31, "tv": 5702.63, "trd": NaN, "batb": NaN, "batl": [[0, 1.34, 395.04]]}, {"timestamp": 1578773049960, "ltp": 1.31, "tv": 5702.63, "trd": NaN, "batb": NaN, "batl": [[0, 1.34, 335.04]]}, {"timestamp": 1578773057961, "ltp": 1.31, "tv": 5702.63, "trd": NaN, "batb": [[1, 1.3, 2535.74]], "batl": NaN}, {"timestamp": 1578773060991, "ltp": 1.31, "tv": 5702.63, "trd": NaN, "batb": [[1, 1.3, 2473.74]], "batl": NaN}, {"timestamp": 1578773064988, "ltp": 1.31, "tv": 5702.63, "trd": NaN, "batb": [[2, 1.29, 262.02]], "batl": [[1, 1.35, 9191.13]]}, {"timestamp": 1578773065988, "ltp": 1.31, "tv": 5702.63, "trd": NaN, "batb": [[0, 1.31, 97.5], [1, 1.3, 1652.16]], "batl": NaN}, {"timestamp": 1578773070009, "ltp": 1.31, "tv": 5702.63, "trd": NaN, "batb": NaN, "batl": [[2, 1.36, 597.05]]}, {"timestamp": 1578773071992, "ltp": 1.31, "tv": 5702.63, "trd": NaN, "batb": NaN, "batl": [[0, 1.34, 377.6]]}, {"timestamp": 1578773072984, "ltp": 1.31, "tv": 5702.63, "trd": NaN, "batb": NaN, "batl": [[0, 1.34, 414.6]]}, {"timestamp": 1578773073984, "ltp": 1.31, "tv": 5702.63, "trd": NaN, "batb": [[2, 1.29, 1097.64]], "batl": NaN}, {"timestamp": 1578773076019, "ltp": 1.31, "tv": 5702.63, "trd": NaN, "batb": NaN, "batl": [[1, 1.35, 9212.41]]}, {"timestamp": 1578773076998, "ltp": 1.31, "tv": 5702.63, "trd": NaN, "batb": NaN, "batl": [[0, 1.34, 214.85]]}, {"timestamp": 1578773077987, "ltp": 1.31, "tv": 5702.63, "trd": NaN, "batb": [[1, 1.3, 1609.6]], "batl": NaN}, {"timestamp": 1578773079992, "ltp": 1.31, "tv": 5714.96, "trd": [[1.31, 285.67]], "batb": [[0, 1.31, 91.33]], "batl": NaN}, {"timestamp": 1578773083986, "ltp": 1.31, "tv": 5714.96, "trd": NaN, "batb": [[2, 1.29, 1076.36]], "batl": NaN}, {"timestamp": 1578773085029, "ltp": 1.31, "tv": 5714.96, "trd": NaN, "batb": [[2, 1.29, 1118.92]], "batl": [[2, 1.36, 147.05]]}, {"timestamp": 1578773087026, "ltp": 1.31, "tv": 5714.96, "trd": NaN, "batb": NaN, "batl": [[1, 1.35, 9191.13]]}, {"timestamp": 1578773088045, "ltp": 1.34, "tv": 5791.49, "trd": [[1.34, 311.69]], "batb": NaN, "batl": [[0, 1.34, 176.59]]}, {"timestamp": 1578773089001, "ltp": 1.34, "tv": 5791.49, "trd": NaN, "batb": NaN, "batl": [[0, 1.34, 139.59]]}, {"timestamp": 1578773092026, "ltp": 1.34, "tv": 5791.49, "trd": NaN, "batb": NaN, "batl": [[1, 1.35, 9619.85]]}, {"timestamp": 1578773093017, "ltp": 1.34, "tv": 5791.49, "trd": NaN, "batb": [[2, 1.29, 1808.35]], "batl": [[0, 1.34, 339.34]]}, {"timestamp": 1578773094025, "ltp": 1.34, "tv": 5883.3, "trd": [[1.34, 403.51]], "batb": NaN, "batl": [[0, 1.34, 93.68], [1, 1.35, 9598.57]]}, {"timestamp": 1578773095904, "ltp": 1.34, "tv": 5883.3, "trd": NaN, "batb": NaN, "batl": [[0, 1.34, 117.34]]}, {"timestamp": 1578773099029, "ltp": 1.34, "tv": 5883.3, "trd": NaN, "batb": [[2, 1.29, 1118.92]], "batl": [[0, 1.34, 138.62]]}, {"timestamp": 1578773100030, "ltp": 1.34, "tv": 5883.3, "trd": NaN, "batb": NaN, "batl": [[0, 1.34, 181.18]]}, {"timestamp": 1578773102025, "ltp": 1.34, "tv": 5883.3, "trd": NaN, "batb": NaN, "batl": [[0, 1.34, 214.73]]}, {"timestamp": 1578773104955, "ltp": 1.34, "tv": 5883.3, "trd": NaN, "batb": [[1, 1.3, 788.02]], "batl": [[0, 1.34, 259.73], [1, 1.35, 9148.57]]}, {"timestamp": 1578773106023, "ltp": 1.34, "tv": 5883.3, "trd": NaN, "batb": [[2, 1.29, 283.3]], "batl": [[1, 1.35, 8698.57]]}, {"timestamp": 1578773107020, "ltp": 1.34, "tv": 5886.93, "trd": [[1.34, 407.14]], "batb": NaN, "batl": [[0, 1.34, 257.91]]}, {"timestamp": 1578773110035, "ltp": 1.34, "tv": 5887.62, "trd": [[1.34, 407.82]], "batb": NaN, "batl": [[0, 1.34, 457.32]]}, {"timestamp": 1578773111971, "ltp": 1.34, "tv": 5887.62, "trd": NaN, "batb": [[2, 1.29, 492.2]], "batl": [[1, 1.35, 8811.07]]}, {"timestamp": 1578773113031, "ltp": 1.34, "tv": 5887.62, "trd": NaN, "batb": [[2, 1.29, 1118.92]], "batl": [[1, 1.35, 9148.57]]}, {"timestamp": 1578773114039, "ltp": 1.34, "tv": 5887.62, "trd": NaN, "batb": [[2, 1.29, 1954.54]], "batl": [[1, 1.35, 9598.57]]}, {"timestamp": 1578773118036, "ltp": 1.34, "tv": 5904.45, "trd": [[1.34, 424.66]], "batb": [[2, 1.29, 1884.54]], "batl": [[0, 1.34, 448.9]]}, {"timestamp": 1578773130962, "ltp": 1.32, "tv": 5912.11, "trd": [[1.32, 383.84]], "batb": [[2, 1.29, 1946.54]], "batl": NaN}, {"timestamp": 1578773133007, "ltp": 1.32, "tv": 5912.11, "trd": NaN, "batb": NaN, "batl": [[0, 1.34, 249.15]]}, {"timestamp": 1578773134987, "ltp": 1.32, "tv": 5912.11, "trd": NaN, "batb": [[1, 1.3, 121.54], [2, 1.29, 2635.97]], "batl": NaN}, {"timestamp": 1578773136980, "ltp": 1.32, "tv": 5912.11, "trd": NaN, "batb": [[0, 1.31, 33.45]], "batl": NaN}, {"timestamp": 1578773137983, "ltp": 1.32, "tv": 5912.11, "trd": NaN, "batb": [[0, 1.3, 121.54], [1, 1.29, 2635.97], [2, 1.28, 131.32]], "batl": NaN}, {"timestamp": 1578773147003, "ltp": 1.32, "tv": 5912.11, "trd": NaN, "batb": NaN, "batl": [[0, 1.33, 23.67], [1, 1.34, 249.15], [2, 1.35, 9598.57]]}, {"timestamp": 1578773148016, "ltp": 1.32, "tv": 5912.11, "trd": NaN, "batb": NaN, "batl": [[2, 1.35, 9148.57]]}, {"timestamp": 1578773150008, "ltp": 1.3, "tv": 5913.64, "trd": [[1.3, 1.53]], "batb": [[0, 1.3, 120.77]], "batl": [[0, 1.33, 223.66]]}, {"timestamp": 1578773152001, "ltp": 1.3, "tv": 5913.64, "trd": NaN, "batb": [[1, 1.29, 2573.97]], "batl": NaN}, {"timestamp": 1578773155014, "ltp": 1.3, "tv": 5913.64, "trd": NaN, "batb": NaN, "batl": [[0, 1.33, 23.67]]}, {"timestamp": 1578773156017, "ltp": 1.3, "tv": 5913.64, "trd": NaN, "batb": [[0, 1.3, 787.25], [1, 1.29, 1884.54]], "batl": [[1, 1.34, 699.15]]}, {"timestamp": 1578773157012, "ltp": 1.3, "tv": 5913.64, "trd": NaN, "batb": [[0, 1.3, 120.77]], "batl": NaN}, {"timestamp": 1578773158020, "ltp": 1.3, "tv": 5913.64, "trd": NaN, "batb": NaN, "batl": [[0, 1.33, 142.37]]}, {"timestamp": 1578773167010, "ltp": 1.3, "tv": 5913.64, "trd": NaN, "batb": [[0, 1.3, 787.25]], "batl": [[1, 1.34, 677.87]]}, {"timestamp": 1578773173044, "ltp": 1.3, "tv": 5913.64, "trd": NaN, "batb": [[1, 1.29, 1841.98]], "batl": [[0, 1.33, 163.65], [1, 1.34, 635.31]]}, {"timestamp": 1578773174056, "ltp": 1.3, "tv": 5913.64, "trd": NaN, "batb": NaN, "batl": [[1, 1.34, 790.06]]}, {"timestamp": 1578773177037, "ltp": 1.3, "tv": 5913.64, "trd": NaN, "batb": [[1, 1.29, 1006.36]], "batl": [[1, 1.34, 340.06]]}, {"timestamp": 1578773180047, "ltp": 1.3, "tv": 5913.64, "trd": NaN, "batb": [[2, 1.28, 173.88]], "batl": [[0, 1.33, 206.21]]}, {"timestamp": 1578773182056, "ltp": 1.3, "tv": 5913.64, "trd": NaN, "batb": NaN, "batl": [[0, 1.33, 406.2], [1, 1.34, 140.31]]}, {"timestamp": 1578773184055, "ltp": 1.3, "tv": 5913.64, "trd": NaN, "batb": [[1, 1.29, 1060.36]], "batl": [[1, 1.34, 192.31]]}, {"timestamp": 1578773185050, "ltp": 1.3, "tv": 5913.64, "trd": NaN, "batb": [[1, 1.29, 1841.98]], "batl": [[2, 1.35, 9598.57]]}, {"timestamp": 1578773186054, "ltp": 1.3, "tv": 5913.64, "trd": NaN, "batb": NaN, "batl": [[2, 1.35, 9148.57]]}, {"timestamp": 1578773187049, "ltp": 1.33, "tv": 5927.63, "trd": [[1.33, 403.82]], "batb": NaN, "batl": [[0, 1.33, 399.21]]}, {"timestamp": 1578773189041, "ltp": 1.33, "tv": 5927.63, "trd": NaN, "batb": [[1, 1.29, 1799.42]], "batl": [[0, 1.33, 377.93]]}, {"timestamp": 1578773192971, "ltp": 1.33, "tv": 5927.63, "trd": NaN, "batb": [[0, 1.3, 120.77]], "batl": [[1, 1.34, 642.31]]}, {"timestamp": 1578773196056, "ltp": 1.33, "tv": 5927.63, "trd": NaN, "batb": NaN, "batl": [[0, 1.33, 177.94], [1, 1.34, 663.59]]}, {"timestamp": 1578773196950, "ltp": 1.33, "tv": 5927.63, "trd": NaN, "batb": [[1, 1.29, 1903.98]], "batl": NaN}, {"timestamp": 1578773200002, "ltp": 1.33, "tv": 5927.63, "trd": NaN, "batb": NaN, "batl": [[0, 1.32, 24.23], [1, 1.33, 177.94], [2, 1.34, 663.59]]}, {"timestamp": 1578773200976, "ltp": 1.33, "tv": 5927.63, "trd": NaN, "batb": NaN, "batl": [[0, 1.33, 177.94], [1, 1.34, 663.59], [2, 1.35, 9148.57]]}, {"timestamp": 1578773203971, "ltp": 1.33, "tv": 5927.63, "trd": NaN, "batb": [[1, 1.29, 1861.42]], "batl": NaN}, {"timestamp": 1578773204976, "ltp": 1.33, "tv": 5927.63, "trd": NaN, "batb": NaN, "batl": [[1, 1.34, 820.78]]}, {"timestamp": 1578773206979, "ltp": 1.33, "tv": 5927.63, "trd": NaN, "batb": [[0, 1.3, 787.25]], "batl": NaN}, {"timestamp": 1578773207972, "ltp": 1.33, "tv": 5927.63, "trd": NaN, "batb": [[1, 1.29, 1799.42]], "batl": NaN}, {"timestamp": 1578773210972, "ltp": 1.33, "tv": 5927.63, "trd": NaN, "batb": [[2, 1.28, 216.44]], "batl": NaN}, {"timestamp": 1578773211969, "ltp": 1.33, "tv": 5927.63, "trd": NaN, "batb": NaN, "batl": [[0, 1.33, 220.5]]}, {"timestamp": 1578773218989, "ltp": 1.33, "tv": 5927.63, "trd": NaN, "batb": [[1, 1.29, 1846.42]], "batl": [[0, 1.33, 265.5]]}, {"timestamp": 1578773220004, "ltp": 1.33, "tv": 5927.63, "trd": NaN, "batb": NaN, "batl": [[0, 1.33, 465.49], [1, 1.34, 621.03]]}, {"timestamp": 1578773221994, "ltp": 1.33, "tv": 5927.63, "trd": NaN, "batb": [[1, 1.29, 1799.42], [2, 1.28, 169.44]], "batl": NaN}, {"timestamp": 1578773223974, "ltp": 1.33, "tv": 5927.63, "trd": NaN, "batb": NaN, "batl": [[2, 1.35, 9127.29]]}, {"timestamp": 1578773225997, "ltp": 1.33, "tv": 5927.63, "trd": NaN, "batb": NaN, "batl": [[0, 1.33, 420.49]]}, {"timestamp": 1578773226991, "ltp": 1.33, "tv": 5927.63, "trd": NaN, "batb": NaN, "batl": [[0, 1.32, 4.67], [1, 1.33, 420.49], [2, 1.34, 621.03]]}, {"timestamp": 1578773229997, "ltp": 1.33, "tv": 5927.63, "trd": NaN, "batb": NaN, "batl": [[2, 1.34, 642.31]]}, {"timestamp": 1578773230998, "ltp": 1.33, "tv": 5927.63, "trd": NaN, "batb": [[2, 1.28, 231.44]], "batl": NaN}, {"timestamp": 1578773234017, "ltp": 1.33, "tv": 5927.63, "trd": NaN, "batb": [[2, 1.28, 210.16]], "batl": NaN}, {"timestamp": 1578773238989, "ltp": 1.33, "tv": 5927.63, "trd": NaN, "batb": [[2, 1.28, 236.12]], "batl": NaN}, {"timestamp": 1578773240994, "ltp": 1.33, "tv": 5927.63, "trd": NaN, "batb": NaN, "batl": [[1, 1.33, 220.5]]}, {"timestamp": 1578773244033, "ltp": 1.33, "tv": 5927.63, "trd": NaN, "batb": [[1, 1.29, 1838.42]], "batl": NaN}, {"timestamp": 1578773245001, "ltp": 1.33, "tv": 5927.63, "trd": NaN, "batb": [[1, 1.29, 1002.8]], "batl": NaN}, {"timestamp": 1578773252052, "ltp": 1.33, "tv": 5927.63, "trd": NaN, "batb": [[1, 1.29, 963.8]], "batl": NaN}, {"timestamp": 1578773255027, "ltp": 1.33, "tv": 5927.63, "trd": NaN, "batb": NaN, "batl": [[1, 1.33, 280.5]]}, {"timestamp": 1578773256995, "ltp": 1.33, "tv": 5927.63, "trd": NaN, "batb": NaN, "batl": [[1, 1.33, 220.5], [2, 1.34, 590.31]]}, {"timestamp": 1578773259005, "ltp": 1.33, "tv": 5927.63, "trd": NaN, "batb": [[1, 1.29, 1172.7]], "batl": NaN}, {"timestamp": 1578773260055, "ltp": 1.33, "tv": 5927.63, "trd": NaN, "batb": [[1, 1.29, 1799.42]], "batl": NaN}, {"timestamp": 1578773265010, "ltp": 1.33, "tv": 5927.63, "trd": NaN, "batb": NaN, "batl": [[1, 1.33, 465.49], [2, 1.34, 657.31]]}, {"timestamp": 1578773269036, "ltp": 1.33, "tv": 5927.63, "trd": NaN, "batb": NaN, "batl": [[2, 1.34, 636.03]]}, {"timestamp": 1578773276009, "ltp": 1.33, "tv": 5927.63, "trd": NaN, "batb": NaN, "batl": [[1, 1.33, 486.77]]}, {"timestamp": 1578773278972, "ltp": 1.33, "tv": 5927.63, "trd": NaN, "batb": NaN, "batl": [[2, 1.34, 1086.03]]}, {"timestamp": 1578773285965, "ltp": 1.33, "tv": 5927.63, "trd": NaN, "batb": [[1, 1.29, 963.8]], "batl": NaN}, {"timestamp": 1578773289989, "ltp": 1.32, "tv": 5936.98, "trd": [[1.32, 393.18]], "batb": [[0, 1.32, 328.33], [1, 1.3, 787.25], [2, 1.29, 963.8]], "batl": [[0, 1.33, 486.77], [1, 1.34, 1086.03], [2, 1.35, 8677.29]]}, {"timestamp": 1578773290957, "ltp": 1.32, "tv": 5936.98, "trd": NaN, "batb": NaN, "batl": [[0, 1.33, 401]]}, {"timestamp": 1578773292017, "ltp": 1.32, "tv": 5936.98, "trd": NaN, "batb": NaN, "batl": [[1, 1.34, 636.03]]}, {"timestamp": 1578773296991, "ltp": 1.33, "tv": 6059.46, "trd": [[1.33, 526.31]], "batb": NaN, "batl": [[0, 1.33, 339.76]]}, {"timestamp": 1578773297975, "ltp": 1.32, "tv": 6716.12, "trd": [[1.32, 1049.84]], "batb": [[0, 1.3, 787.25], [1, 1.29, 963.8], [2, 1.28, 236.12]], "batl": [[0, 1.32, 10.38], [1, 1.33, 339.76], [2, 1.34, 636.03]]}, {"timestamp": 1578773298992, "ltp": 1.32, "tv": 6716.12, "trd": NaN, "batb": [[0, 1.3, 120.77], [1, 1.29, 1653.23]], "batl": [[0, 1.33, 339.76], [1, 1.34, 614.75], [2, 1.35, 8677.29]]}, {"timestamp": 1578773300986, "ltp": 1.32, "tv": 6716.12, "trd": NaN, "batb": [[0, 1.29, 1653.23], [1, 1.28, 236.12], [2, 1.27, 135.75]], "batl": NaN}, {"timestamp": 1578773302994, "ltp": 1.33, "tv": 6723.65, "trd": [[1.33, 533.84]], "batb": NaN, "batl": [[0, 1.33, 335.99]]}, {"timestamp": 1578773303990, "ltp": 1.33, "tv": 6723.65, "trd": NaN, "batb": NaN, "batl": [[0, 1.33, 370.99]]}, {"timestamp": 1578773304981, "ltp": 1.33, "tv": 6723.65, "trd": NaN, "batb": [[1, 1.28, 1086.54]], "batl": [[1, 1.34, 1064.75]]}, {"timestamp": 1578773305974, "ltp": 1.33, "tv": 6723.65, "trd": NaN, "batb": NaN, "batl": [[0, 1.33, 506.85]]}, {"timestamp": 1578773308025, "ltp": 1.33, "tv": 6723.65, "trd": NaN, "batb": NaN, "batl": [[0, 1.32, 59.08], [1, 1.33, 506.85], [2, 1.34, 1064.75]]}, {"timestamp": 1578773309046, "ltp": 1.33, "tv": 6723.65, "trd": NaN, "batb": [[2, 1.27, 182.29]], "batl": NaN}, {"timestamp": 1578773310002, "ltp": 1.33, "tv": 6723.65, "trd": NaN, "batb": NaN, "batl": [[1, 1.33, 511.1]]}, {"timestamp": 1578773311985, "ltp": 1.33, "tv": 6723.65, "trd": NaN, "batb": [[1, 1.28, 1131.29]], "batl": NaN}, {"timestamp": 1578773314009, "ltp": 1.32, "tv": 6724.57, "trd": [[1.32, 1050.76]], "batb": NaN, "batl": [[0, 1.32, 58.62]]}, {"timestamp": 1578773315004, "ltp": 1.32, "tv": 6724.62, "trd": [[1.32, 1050.81]], "batb": NaN, "batl": [[0, 1.32, 58.6]]}, {"timestamp": 1578773325019, "ltp": 1.32, "tv": 6724.62, "trd": NaN, "batb": [[0, 1.29, 1653.56]], "batl": NaN}, {"timestamp": 1578773325985, "ltp": 1.32, "tv": 6724.62, "trd": NaN, "batb": NaN, "batl": [[2, 1.34, 614.75]]}, {"timestamp": 1578773327037, "ltp": 1.32, "tv": 6724.62, "trd": NaN, "batb": [[1, 1.28, 1131.64]], "batl": NaN}, {"timestamp": 1578773327997, "ltp": 1.32, "tv": 6724.62, "trd": NaN, "batb": [[2, 1.27, 161.01]], "batl": NaN}, {"timestamp": 1578773329004, "ltp": 1.32, "tv": 6724.62, "trd": NaN, "batb": [[0, 1.3, 8.66], [1, 1.29, 1653.23], [2, 1.28, 1131.64]], "batl": NaN}, {"timestamp": 1578773334037, "ltp": 1.32, "tv": 6724.62, "trd": NaN, "batb": NaN, "batl": [[1, 1.33, 961.1]]}, {"timestamp": 1578773335936, "ltp": 1.32, "tv": 6724.62, "trd": NaN, "batb": NaN, "batl": [[1, 1.33, 939.82]]}, {"timestamp": 1578773340012, "ltp": 1.32, "tv": 6724.62, "trd": NaN, "batb": NaN, "batl": [[1, 1.33, 897.34]]}, {"timestamp": 1578773342028, "ltp": 1.32, "tv": 6724.62, "trd": NaN, "batb": [[2, 1.28, 1089.08]], "batl": NaN}, {"timestamp": 1578773343023, "ltp": 1.32, "tv": 6724.62, "trd": NaN, "batb": NaN, "batl": [[0, 1.32, 79.88]]}, {"timestamp": 1578773344012, "ltp": 1.32, "tv": 6724.62, "trd": NaN, "batb": [[0, 1.31, 4.71], [1, 1.3, 8.66], [2, 1.29, 1653.23]], "batl": NaN}, {"timestamp": 1578773346908, "ltp": 1.32, "tv": 6724.62, "trd": NaN, "batb": NaN, "batl": [[0, 1.32, 122.44]]}, {"timestamp": 1578773358053, "ltp": 1.32, "tv": 6724.62, "trd": NaN, "batb": NaN, "batl": [[0, 1.32, 322.3], [1, 1.33, 697.35]]}, {"timestamp": 1578773361967, "ltp": 1.32, "tv": 6724.62, "trd": NaN, "batb": NaN, "batl": [[0, 1.32, 122.44]]}, {"timestamp": 1578773366043, "ltp": 1.32, "tv": 6724.62, "trd": NaN, "batb": [[2, 1.29, 1026.51]], "batl": [[0, 1.32, 205.82]]}, {"timestamp": 1578773367043, "ltp": 1.31, "tv": 6731.43, "trd": [[1.31, 292.48]], "batb": [[0, 1.31, 1.3]], "batl": NaN}, {"timestamp": 1578773370974, "ltp": 1.32, "tv": 6750.12, "trd": [[1.32, 1069.5]], "batb": [[2, 1.29, 337.08]], "batl": [[0, 1.32, 396.34]]}, {"timestamp": 1578773374963, "ltp": 1.32, "tv": 6750.12, "trd": NaN, "batb": [[1, 1.29, 263.19], [2, 1.28, 1673.24]], "batl": NaN}, {"timestamp": 1578773375950, "ltp": 1.32, "tv": 6750.12, "trd": NaN, "batb": [[1, 1.29, 262.86]], "batl": NaN}, {"timestamp": 1578773377000, "ltp": 1.32, "tv": 6750.12, "trd": NaN, "batb": [[2, 1.28, 1672.89]], "batl": NaN}, {"timestamp": 1578773385004, "ltp": 1.32, "tv": 6750.12, "trd": NaN, "batb": [[0, 1.29, 262.86], [1, 1.28, 1672.89], [2, 1.27, 246.13]], "batl": [[0, 1.31, 3.37], [1, 1.32, 396.34], [2, 1.33, 697.35]]}, {"timestamp": 1578773386993, "ltp": 1.32, "tv": 6750.12, "trd": NaN, "batb": NaN, "batl": [[2, 1.33, 676.07]]}, {"timestamp": 1578773388000, "ltp": 1.32, "tv": 6750.12, "trd": NaN, "batb": [[0, 1.29, 53.96]], "batl": NaN}, {"timestamp": 1578773389002, "ltp": 1.32, "tv": 6750.12, "trd": NaN, "batb": [[0, 1.28, 2387.05], [1, 1.27, 246.13], [2, 1.26, 162.72]], "batl": NaN}, {"timestamp": 1578773391007, "ltp": 1.32, "tv": 6750.12, "trd": NaN, "batb": [[0, 1.28, 1672.89]], "batl": NaN}, {"timestamp": 1578773394005, "ltp": 1.32, "tv": 6750.12, "trd": NaN, "batb": NaN, "batl": [[1, 1.32, 417.62]]}, {"timestamp": 1578773395022, "ltp": 1.32, "tv": 6750.12, "trd": NaN, "batb": [[0, 1.28, 1896.59]], "batl": [[2, 1.33, 1126.07]]}, {"timestamp": 1578773396011, "ltp": 1.32, "tv": 6750.12, "trd": NaN, "batb": NaN, "batl": [[0, 1.31, 28.73]]}, {"timestamp": 1578773400034, "ltp": 1.32, "tv": 6750.12, "trd": NaN, "batb": NaN, "batl": [[2, 1.33, 1083.51]]}, {"timestamp": 1578773401031, "ltp": 1.32, "tv": 6750.12, "trd": NaN, "batb": [[2, 1.26, 141.44]], "batl": [[1, 1.32, 396.34]]}, {"timestamp": 1578773402040, "ltp": 1.32, "tv": 6750.12, "trd": NaN, "batb": NaN, "batl": [[1, 1.32, 375.06]]}, {"timestamp": 1578773406034, "ltp": 1.32, "tv": 6750.12, "trd": NaN, "batb": [[0, 1.28, 984.17]], "batl": [[0, 1.3, 4.67], [1, 1.31, 28.73], [2, 1.32, 375.06]]}, {"timestamp": 1578773407039, "ltp": 1.32, "tv": 6750.12, "trd": NaN, "batb": NaN, "batl": [[2, 1.32, 417.62]]}, {"timestamp": 1578773408040, "ltp": 1.29, "tv": 6766.24, "trd": [[1.29, 16.12]], "batb": [[0, 1.28, 947.98]], "batl": [[0, 1.29, 124.02], [1, 1.3, 4.67], [2, 1.31, 50.01]]}, {"timestamp": 1578773409042, "ltp": 1.29, "tv": 6766.24, "trd": NaN, "batb": [[0, 1.28, 876.38]], "batl": NaN}, {"timestamp": 1578773413924, "ltp": 1.29, "tv": 6766.24, "trd": NaN, "batb": [[1, 1.27, 1112.15]], "batl": NaN}, {"timestamp": 1578773415032, "ltp": 1.29, "tv": 6766.24, "trd": NaN, "batb": NaN, "batl": [[2, 1.31, 85.98]]}, {"timestamp": 1578773416040, "ltp": 1.29, "tv": 6766.24, "trd": NaN, "batb": NaN, "batl": [[2, 1.31, 169.61]]}, {"timestamp": 1578773417048, "ltp": 1.29, "tv": 6766.24, "trd": NaN, "batb": [[2, 1.26, 189.39]], "batl": [[1, 1.3, 64.79]]}, {"timestamp": 1578773419040, "ltp": 1.29, "tv": 6766.24, "trd": NaN, "batb": [[0, 1.28, 1590.54]], "batl": [[2, 1.31, 369.53]]}, {"timestamp": 1578773421954, "ltp": 1.29, "tv": 6766.24, "trd": NaN, "batb": NaN, "batl": [[2, 1.31, 438.53]]}, {"timestamp": 1578773424041, "ltp": 1.29, "tv": 6766.24, "trd": NaN, "batb": NaN, "batl": [[2, 1.31, 481.09]]}, {"timestamp": 1578773425049, "ltp": 1.29, "tv": 6766.24, "trd": NaN, "batb": [[1, 1.27, 1069.59]], "batl": NaN}, {"timestamp": 1578773429044, "ltp": 1.29, "tv": 6766.24, "trd": NaN, "batb": [[1, 1.27, 1027.03]], "batl": NaN}, {"timestamp": 1578773431967, "ltp": 1.29, "tv": 6766.24, "trd": NaN, "batb": [[2, 1.26, 231.96]], "batl": NaN}, {"timestamp": 1578773432964, "ltp": 1.29, "tv": 6766.24, "trd": NaN, "batb": NaN, "batl": [[1, 1.3, 110.79]]}, {"timestamp": 1578773433967, "ltp": 1.29, "tv": 6794.4, "trd": [[1.29, 44.28]], "batb": NaN, "batl": [[0, 1.29, 109.94]]}, {"timestamp": 1578773434971, "ltp": 1.29, "tv": 6794.4, "trd": NaN, "batb": NaN, "batl": [[1, 1.3, 310.54], [2, 1.31, 302.45]]}, {"timestamp": 1578773435983, "ltp": 1.29, "tv": 6794.4, "trd": NaN, "batb": [[2, 1.26, 274.52]], "batl": [[2, 1.31, 345.01]]}, {"timestamp": 1578773436988, "ltp": 1.29, "tv": 6794.4, "trd": NaN, "batb": [[1, 1.27, 980.03]], "batl": NaN}, {"timestamp": 1578773437992, "ltp": 1.29, "tv": 6794.4, "trd": NaN, "batb": [[0, 1.28, 963.82]], "batl": NaN}, {"timestamp": 1578773440011, "ltp": 1.29, "tv": 6794.4, "trd": NaN, "batb": NaN, "batl": [[1, 1.3, 110.79]]}, {"timestamp": 1578773440987, "ltp": 1.29, "tv": 6794.4, "trd": NaN, "batb": NaN, "batl": [[1, 1.3, 195.62]]}, {"timestamp": 1578773443991, "ltp": 1.29, "tv": 6794.4, "trd": NaN, "batb": NaN, "batl": [[2, 1.31, 544.93]]}, {"timestamp": 1578773444990, "ltp": 1.29, "tv": 6794.4, "trd": NaN, "batb": [[0, 1.28, 740.12], [1, 1.27, 1606.75]], "batl": NaN}, {"timestamp": 1578773445995, "ltp": 1.29, "tv": 6794.4, "trd": NaN, "batb": [[1, 1.27, 740.73]], "batl": NaN}, {"timestamp": 1578773448009, "ltp": 1.29, "tv": 6859.79, "trd": [[1.29, 109.67]], "batb": NaN, "batl": [[0, 1.29, 77.25], [2, 1.31, 345.01]]}, {"timestamp": 1578773450994, "ltp": 1.29, "tv": 6859.79, "trd": NaN, "batb": NaN, "batl": [[1, 1.3, 190.95]]}, {"timestamp": 1578773451995, "ltp": 1.29, "tv": 6859.79, "trd": NaN, "batb": [[1, 1.27, 980.03]], "batl": [[2, 1.31, 341.64]]}, {"timestamp": 1578773452992, "ltp": 1.29, "tv": 6859.79, "trd": NaN, "batb": [[2, 1.26, 1157.04]], "batl": [[2, 1.31, 791.64]]}, {"timestamp": 1578773457043, "ltp": 1.29, "tv": 6859.79, "trd": NaN, "batb": [[1, 1.27, 1035.03]], "batl": [[1, 1.3, 390.7]]}, {"timestamp": 1578773458001, "ltp": 1.29, "tv": 6874.74, "trd": [[1.29, 124.62]], "batb": NaN, "batl": [[0, 1.29, 69.77]]}, {"timestamp": 1578773458996, "ltp": 1.28, "tv": 6907.24, "trd": [[1.28, 32.35], [1.29, 124.77]], "batb": [[0, 1.28, 723.95]], "batl": [[0, 1.29, 69.7]]}, {"timestamp": 1578773462014, "ltp": 1.28, "tv": 6907.24, "trd": NaN, "batb": [[1, 1.27, 980.03]], "batl": [[1, 1.3, 344.7], [2, 1.31, 770.36]]}, {"timestamp": 1578773464011, "ltp": 1.28, "tv": 6907.24, "trd": NaN, "batb": NaN, "batl": [[0, 1.29, 74.37]]}, {"timestamp": 1578773468026, "ltp": 1.28, "tv": 6907.24, "trd": NaN, "batb": NaN, "batl": [[1, 1.3, 144.95], [2, 1.31, 970.28]]}, {"timestamp": 1578773469028, "ltp": 1.28, "tv": 6907.24, "trd": NaN, "batb": NaN, "batl": [[1, 1.3, 166.23]]}, {"timestamp": 1578773470031, "ltp": 1.28, "tv": 6907.24, "trd": NaN, "batb": NaN, "batl": [[0, 1.29, 224.37]]}, {"timestamp": 1578773474026, "ltp": 1.29, "tv": 6918.45, "trd": [[1.29, 135.98]], "batb": NaN, "batl": [[0, 1.29, 218.76]]}, {"timestamp": 1578773480032, "ltp": 1.29, "tv": 6918.45, "trd": NaN, "batb": [[1, 1.27, 1043.03]], "batl": [[0, 1.29, 219.32], [1, 1.3, 220.23]]}, {"timestamp": 1578773485961, "ltp": 1.29, "tv": 6918.45, "trd": NaN, "batb": [[1, 1.27, 416.31]], "batl": NaN}, {"timestamp": 1578773486970, "ltp": 1.29, "tv": 6918.45, "trd": NaN, "batb": [[1, 1.27, 353.31]], "batl": [[2, 1.31, 927.72]]}, {"timestamp": 1578773488958, "ltp": 1.29, "tv": 6918.45, "trd": NaN, "batb": [[0, 1.28, 9.79]], "batl": [[2, 1.31, 727.8]]}, {"timestamp": 1578773489957, "ltp": 1.29, "tv": 6918.45, "trd": NaN, "batb": [[1, 1.27, 239.3]], "batl": NaN}, {"timestamp": 1578773492991, "ltp": 1.29, "tv": 6918.45, "trd": NaN, "batb": [[2, 1.26, 1783.76]], "batl": [[2, 1.31, 1177.8]]}, {"timestamp": 1578773493978, "ltp": 1.29, "tv": 6918.45, "trd": NaN, "batb": [[2, 1.26, 1157.04]], "batl": [[1, 1.3, 262.79], [2, 1.31, 840.3]]}, {"timestamp": 1578773496971, "ltp": 1.29, "tv": 6918.45, "trd": NaN, "batb": NaN, "batl": [[0, 1.29, 283.03]]}, {"timestamp": 1578773501004, "ltp": 1.29, "tv": 6918.45, "trd": NaN, "batb": [[2, 1.26, 1783.76]], "batl": NaN}, {"timestamp": 1578773502999, "ltp": 1.29, "tv": 6918.45, "trd": NaN, "batb": [[2, 1.26, 1741.2]], "batl": NaN}, {"timestamp": 1578773503997, "ltp": 1.28, "tv": 6938.02, "trd": [[1.28, 51.92]], "batb": [[0, 1.27, 239.3], [1, 1.26, 1741.2], [2, 1.25, 168.13]], "batl": [[0, 1.28, 83.64], [1, 1.29, 322.03], [2, 1.3, 262.79]]}, {"timestamp": 1578773505993, "ltp": 1.28, "tv": 6938.02, "trd": NaN, "batb": [[0, 1.26, 1741.2], [1, 1.25, 168.13], [2, 1.24, 187.25]], "batl": NaN}, {"timestamp": 1578773506993, "ltp": 1.28, "tv": 6938.02, "trd": NaN, "batb": [[0, 1.26, 1622.8]], "batl": NaN}, {"timestamp": 1578773507991, "ltp": 1.28, "tv": 6938.02, "trd": NaN, "batb": NaN, "batl": [[0, 1.28, 91.3]]}, {"timestamp": 1578773509879, "ltp": 1.28, "tv": 6938.02, "trd": NaN, "batb": [[1, 1.25, 210.69]], "batl": NaN}, {"timestamp": 1578773512020, "ltp": 1.28, "tv": 6938.02, "trd": NaN, "batb": NaN, "batl": [[1, 1.29, 409.11], [2, 1.3, 284.07]]}, {"timestamp": 1578773513977, "ltp": 1.28, "tv": 6938.02, "trd": NaN, "batb": [[0, 1.26, 1878.6]], "batl": [[0, 1.28, 129.04]]}, {"timestamp": 1578773515023, "ltp": 1.28, "tv": 6938.02, "trd": NaN, "batb": [[0, 1.26, 1807.6], [2, 1.24, 241.67]], "batl": [[0, 1.28, 156.19]]}, {"timestamp": 1578773516022, "ltp": 1.28, "tv": 6938.02, "trd": NaN, "batb": [[2, 1.24, 220.39]], "batl": [[0, 1.28, 72.54]]}, {"timestamp": 1578773517025, "ltp": 1.28, "tv": 6938.02, "trd": NaN, "batb": [[0, 1.26, 1765.04]], "batl": NaN}, {"timestamp": 1578773518025, "ltp": 1.28, "tv": 6938.02, "trd": NaN, "batb": [[0, 1.26, 882.52]], "batl": NaN}, {"timestamp": 1578773519987, "ltp": 1.28, "tv": 6938.02, "trd": NaN, "batb": NaN, "batl": [[1, 1.29, 408.55]]}, {"timestamp": 1578773523045, "ltp": 1.28, "tv": 6938.02, "trd": NaN, "batb": [[0, 1.25, 210.69], [1, 1.24, 220.39], [2, 1.23, 98.32]], "batl": [[0, 1.27, 83.64], [1, 1.28, 72.54], [2, 1.29, 408.55]]}, {"timestamp": 1578773524042, "ltp": 1.28, "tv": 6938.02, "trd": NaN, "batb": [[0, 1.25, 253.25]], "batl": NaN}, {"timestamp": 1578773525046, "ltp": 1.28, "tv": 6938.02, "trd": NaN, "batb": [[0, 1.25, 1153.25]], "batl": [[0, 1.26, 3.06], [1, 1.27, 83.64], [2, 1.28, 72.54]]}, {"timestamp": 1578773526022, "ltp": 1.28, "tv": 6938.02, "trd": NaN, "batb": [[2, 1.23, 163.32]], "batl": NaN}, {"timestamp": 1578773527025, "ltp": 1.26, "tv": 6944.14, "trd": [[1.26, 6.12]], "batb": [[0, 1.26, 765.92], [1, 1.25, 1153.25], [2, 1.24, 220.39]], "batl": [[0, 1.27, 84.2], [1, 1.28, 72.54], [2, 1.29, 608.43]]}, {"timestamp": 1578773529034, "ltp": 1.26, "tv": 6944.14, "trd": NaN, "batb": NaN, "batl": [[1, 1.28, 64.89], [2, 1.29, 408.55]]}, {"timestamp": 1578773530044, "ltp": 1.27, "tv": 6958.11, "trd": [[1.27, 13.97]], "batb": NaN, "batl": [[0, 1.27, 77.22]]}, {"timestamp": 1578773531053, "ltp": 1.27, "tv": 6958.11, "trd": NaN, "batb": NaN, "batl": [[1, 1.28, 157.31]]}, {"timestamp": 1578773533053, "ltp": 1.27, "tv": 6958.11, "trd": NaN, "batb": NaN, "batl": [[2, 1.29, 403.88]]}, {"timestamp": 1578773534955, "ltp": 1.27, "tv": 6958.11, "trd": NaN, "batb": NaN, "batl": [[1, 1.28, 37.74]]}, {"timestamp": 1578773535955, "ltp": 1.27, "tv": 6958.11, "trd": NaN, "batb": NaN, "batl": [[1, 1.29, 403.88], [2, 1.3, 976.38]]}, {"timestamp": 1578773537051, "ltp": 1.27, "tv": 6958.11, "trd": NaN, "batb": [[1, 1.25, 1828.25]], "batl": NaN}, {"timestamp": 1578773538027, "ltp": 1.27, "tv": 6958.11, "trd": NaN, "batb": [[1, 1.25, 1153.25]], "batl": NaN}, {"timestamp": 1578773539010, "ltp": 1.27, "tv": 6958.11, "trd": NaN, "batb": NaN, "batl": [[2, 1.3, 776.63]]}, {"timestamp": 1578773542951, "ltp": 1.27, "tv": 6958.11, "trd": NaN, "batb": NaN, "batl": [[0, 1.29, 604.32], [1, 1.3, 776.63], [2, 1.31, 130.33]]}, {"timestamp": 1578773546048, "ltp": 1.27, "tv": 6958.11, "trd": NaN, "batb": [[1, 1.25, 2053.25], [2, 1.24, 199.11]], "batl": NaN}, {"timestamp": 1578773547042, "ltp": 1.27, "tv": 6958.11, "trd": NaN, "batb": NaN, "batl": [[1, 1.3, 734.07]]}, {"timestamp": 1578773548050, "ltp": 1.27, "tv": 6958.11, "trd": NaN, "batb": [[1, 1.25, 2010.69]], "batl": [[1, 1.3, 712.79]]}, {"timestamp": 1578773549054, "ltp": 1.27, "tv": 6959.24, "trd": [[1.27, 15.1]], "batb": [[0, 1.26, 766.7]], "batl": [[0, 1.28, 62], [1, 1.29, 603.76], [2, 1.3, 712.79]]}, {"timestamp": 1578773549948, "ltp": 1.27, "tv": 6959.24, "trd": NaN, "batb": NaN, "batl": [[0, 1.28, 130.1]]}, {"timestamp": 1578773551044, "ltp": 1.26, "tv": 7112.55, "trd": [[1.26, 157.87], [1.27, 16.66]], "batb": [[0, 1.26, 690.05]], "batl": NaN}, {"timestamp": 1578773552976, "ltp": 1.26, "tv": 7112.55, "trd": NaN, "batb": [[1, 1.25, 1962.69]], "batl": [[1, 1.29, 646.32]]}, {"timestamp": 1578773553976, "ltp": 1.26, "tv": 7112.55, "trd": NaN, "batb": NaN, "batl": [[2, 1.3, 1162.79]]}, {"timestamp": 1578773554976, "ltp": 1.26, "tv": 7112.55, "trd": NaN, "batb": [[1, 1.25, 1920.13], [2, 1.24, 241.67]], "batl": [[1, 1.29, 667.6], [2, 1.3, 712.79]]}, {"timestamp": 1578773558969, "ltp": 1.26, "tv": 8040.3, "trd": [[1.26, 1085.62]], "batb": [[0, 1.26, 226.17]], "batl": NaN}, {"timestamp": 1578773560966, "ltp": 1.26, "tv": 8040.3, "trd": NaN, "batb": [[1, 1.25, 1963.15]], "batl": NaN}, {"timestamp": 1578773561966, "ltp": 1.26, "tv": 8046.42, "trd": [[1.26, 1091.74]], "batb": [[0, 1.26, 223.11], [2, 1.24, 284.23]], "batl": [[1, 1.29, 1117.6]]}, {"timestamp": 1578773564977, "ltp": 1.26, "tv": 8046.42, "trd": NaN, "batb": NaN, "batl": [[2, 1.3, 670.23]]}, {"timestamp": 1578773565983, "ltp": 1.26, "tv": 8046.42, "trd": NaN, "batb": [[1, 1.25, 1063.15]], "batl": NaN}, {"timestamp": 1578773566982, "ltp": 1.26, "tv": 8046.42, "trd": NaN, "batb": NaN, "batl": [[0, 1.28, 329.94], [1, 1.29, 917.72]]}, {"timestamp": 1578773567995, "ltp": 1.26, "tv": 8046.42, "trd": NaN, "batb": NaN, "batl": [[0, 1.28, 261.84]]}, {"timestamp": 1578773568999, "ltp": 1.26, "tv": 8046.42, "trd": NaN, "batb": NaN, "batl": [[0, 1.28, 62]]}, {"timestamp": 1578773570989, "ltp": 1.26, "tv": 8046.42, "trd": NaN, "batb": NaN, "batl": [[1, 1.29, 960.28]]}, {"timestamp": 1578773571993, "ltp": 1.26, "tv": 8046.42, "trd": NaN, "batb": NaN, "batl": [[1, 1.29, 810.28]]}, {"timestamp": 1578773573001, "ltp": 1.26, "tv": 8046.42, "trd": NaN, "batb": [[1, 1.25, 1135.15]], "batl": NaN}, {"timestamp": 1578773574006, "ltp": 1.26, "tv": 8046.42, "trd": NaN, "batb": [[1, 1.25, 1063.15], [2, 1.24, 1202.78]], "batl": NaN}, {"timestamp": 1578773577028, "ltp": 1.26, "tv": 8046.42, "trd": NaN, "batb": NaN, "batl": [[0, 1.28, 324.78]]}, {"timestamp": 1578773579002, "ltp": 1.26, "tv": 8046.42, "trd": NaN, "batb": NaN, "batl": [[0, 1.27, 150], [1, 1.28, 124.94], [2, 1.29, 810.28]]}, {"timestamp": 1578773587035, "ltp": 1.26, "tv": 8046.42, "trd": NaN, "batb": NaN, "batl": [[1, 1.28, 215.41]]}, {"timestamp": 1578773589032, "ltp": 1.26, "tv": 8046.42, "trd": NaN, "batb": NaN, "batl": [[1, 1.28, 153.41]]}, {"timestamp": 1578773595963, "ltp": 1.26, "tv": 8046.42, "trd": NaN, "batb": NaN, "batl": [[1, 1.28, 353.25]]}, {"timestamp": 1578773601042, "ltp": 1.26, "tv": 8046.42, "trd": NaN, "batb": NaN, "batl": [[1, 1.28, 423.25]]}, {"timestamp": 1578773602041, "ltp": 1.26, "tv": 8046.42, "trd": NaN, "batb": [[2, 1.24, 1129.78]], "batl": [[2, 1.29, 767.72]]}, {"timestamp": 1578773608971, "ltp": 1.26, "tv": 8046.42, "trd": NaN, "batb": NaN, "batl": [[1, 1.28, 465.81]]}, {"timestamp": 1578773610963, "ltp": 1.27, "tv": 8091.88, "trd": [[1.27, 62.12]], "batb": [[0, 1.25, 1063.15], [1, 1.24, 1129.78], [2, 1.23, 163.32]], "batl": [[0, 1.27, 127.27]]}, {"timestamp": 1578773611957, "ltp": 1.27, "tv": 8091.88, "trd": NaN, "batb": [[0, 1.25, 943.02]], "batl": [[0, 1.27, 190.27], [1, 1.28, 481.12]]}, {"timestamp": 1578773614046, "ltp": 1.27, "tv": 8091.88, "trd": NaN, "batb": NaN, "batl": [[2, 1.29, 1217.72]]}, {"timestamp": 1578773615036, "ltp": 1.27, "tv": 8095.71, "trd": [[1.27, 65.94]], "batb": NaN, "batl": [[0, 1.27, 188.36]]}, {"timestamp": 1578773617975, "ltp": 1.27, "tv": 8095.71, "trd": NaN, "batb": [[1, 1.24, 1963.05]], "batl": NaN}, {"timestamp": 1578773618968, "ltp": 1.27, "tv": 8095.71, "trd": NaN, "batb": NaN, "batl": [[0, 1.27, 255.03]]}, {"timestamp": 1578773619960, "ltp": 1.27, "tv": 8095.71, "trd": NaN, "batb": [[2, 1.23, 215.1]], "batl": [[0, 1.27, 354.12]]}, {"timestamp": 1578773622055, "ltp": 1.27, "tv": 8096.06, "trd": [[1.27, 66.3]], "batb": NaN, "batl": [[0, 1.27, 353.94]]}, {"timestamp": 1578773625972, "ltp": 1.27, "tv": 8096.06, "trd": NaN, "batb": [[0, 1.25, 268.02]], "batl": NaN}, {"timestamp": 1578773626973, "ltp": 1.27, "tv": 8096.06, "trd": NaN, "batb": NaN, "batl": [[0, 1.26, 1.87], [1, 1.27, 353.94], [2, 1.28, 481.12]]}, {"timestamp": 1578773629960, "ltp"