{"info": {"id": "1.166703740", "eventId": "29632571", "eventName": "Over/Under 4.5 Goals", "marketType": "OVER_UNDER_45", "openDate": 1578772101023, "name": "Inter v Atalanta", "numberOfActiveRunner": 2, "countryCode": "", "sport": "TENNIS", "venue": "", "volume": {"total": 291399.25, "preMatch": 18999.08, "inPlay": 272400.17}, "winner": {"id": 1222347, "name": "Under 4.5 Goals", "status": "WINNER", "position": 1}, "delay": 7}, "runners": [{"id": 1222347, "name": "Under 4.5 Goals", "status": "WINNER", "position": 1, "inPlayOdds": 1.2, "inPlayTime": 1578772101023, "avgPrematch": 1.22, "closedOdds": 1.01, "maxPrematch": 1.24, "minPrematch": 1.19, "maxInPlay": 1.45, "minInPlay": 1.01, "inPlayIndex": 616, "lengthOdds": 2950, "lengthOddsPrematch": 616, "lengthOddsInPlay": 2334, "tradedVolume": 282948.8, "preMatchVolume": 17909.39, "inPlayVolume": 265039.41}, {"id": 1222346, "name": "Over 4.5 Goals", "status": "LOSER", "position": 2, "inPlayOdds": 6.0, "inPlayTime": 1578772101023, "avgPrematch": 5.52, "closedOdds": 1000.0, "maxPrematch": 6.4, "minPrematch": 5.1, "maxInPlay": 1000.0, "minInPlay": 3.2, "inPlayIndex": 458, "lengthOdds": 2632, "lengthOddsPrematch": 458, "lengthOddsInPlay": 2174, "tradedVolume": 8450.45, "preMatchVolume": 1089.69, "inPlayVolume": 7360.76}], "marketUpdates": [{"timestamp": 1578513294362000000, "openDate": "2020-01-11T19:45:00.000Z", "status": "OPEN", "betDelay": 0, "inPlay": false, "complete": true}, {"timestamp": 1578772101023000000, "openDate": "2020-01-11T19:45:00.000Z", "status": "OPEN", "betDelay": 7, "inPlay": true, "complete": true}, {"timestamp": 1578772294860000000, "openDate": "2020-01-11T19:45:00.000Z", "status": "SUSPENDED", "betDelay": 7, "inPlay": true, "complete": true}, {"timestamp": 1578772347979000000, "openDate": "2020-01-11T19:45:00.000Z", "status": "OPEN", "betDelay": 7, "inPlay": true, "complete": true}, {"timestamp": 1578774525024000000, "openDate": "2020-01-11T19:45:00.000Z", "status": "SUSPENDED", "betDelay": 7, "inPlay": true, "complete": true}, {"timestamp": 1578774556973000000, "openDate": "2020-01-11T19:45:00.000Z", "status": "OPEN", "betDelay": 7, "inPlay": true, "complete": true}, {"timestamp": 1578774580039000000, "openDate": "2020-01-11T19:45:00.000Z", "status": "SUSPENDED", "betDelay": 7, "inPlay": true, "complete": true}, {"timestamp": 1578774582036000000, "openDate": "2020-01-11T19:45:00.000Z", "status": "OPEN", "betDelay": 7, "inPlay": true, "complete": true}, {"timestamp": 1578774866982000000, "openDate": "2020-01-11T19:45:00.000Z", "status": "OPEN", "betDelay": 1, "inPlay": true, "complete": true}, {"timestamp": 1578775780035000000, "openDate": "2020-01-11T19:45:00.000Z", "status": "OPEN", "betDelay": 7, "inPlay": true, "complete": true}, {"timestamp": 1578777631947000000, "openDate": "2020-01-11T19:45:00.000Z", "status": "SUSPENDED", "betDelay": 7, "inPlay": true, "complete": true}, {"timestamp": 1578777690042000000, "openDate": "2020-01-11T19:45:00.000Z", "status": "OPEN", "betDelay": 7, "inPlay": true, "complete": true}, {"timestamp": 1578778337987000000, "openDate": "2020-01-11T19:45:00.000Z", "status": "SUSPENDED", "betDelay": 7, "inPlay": true, "complete": true}, {"timestamp": 1578778432037000000, "openDate": "2020-01-11T19:45:00.000Z", "status": "OPEN", "betDelay": 7, "inPlay": true, "complete": true}, {"timestamp": 1578778774964000000, "openDate": "2020-01-11T19:45:00.000Z", "status": "SUSPENDED", "betDelay": 7, "inPlay": true, "complete": true}, {"timestamp": 1578778867538000000, "openDate": "2020-01-11T19:45:00.000Z", "status": "CLOSED", "betDelay": 7, "inPlay": true, "complete": true}], "odds": [{"runnerId": 1222347, "odds": [{"timestamp": 1578678544259, "ltp": 1.24, "tv": 7.73, "trd": [[1.24, 7.73]], "batb": NaN, "batl": NaN}, {"timestamp": 1578680180506, "ltp": 1.24, "tv": 7.73, "trd": NaN, "batb": NaN, "batl": [[1, 1.26, 0]]}, {"timestamp": 1578681398963, "ltp": 1.24, "tv": 7.73, "trd": NaN, "batb": NaN, "batl": [[1, 1.26, 125.25], [2, 1.27, 128.5]]}, {"timestamp": 1578682591618, "ltp": 1.24, "tv": 7.73, "trd": NaN, "batb": NaN, "batl": [[2, 1.27, 122.5]]}, {"timestamp": 1578682792655, "ltp": 1.24, "tv": 7.73, "trd": NaN, "batb": NaN, "batl": [[1, 1.26, 0], [2, 1.27, 0]]}, {"timestamp": 1578682793672, "ltp": 1.24, "tv": 7.73, "trd": NaN, "batb": NaN, "batl": [[1, 1.26, 122.25], [2, 1.27, 125.5]]}, {"timestamp": 1578682808983, "ltp": 1.24, "tv": 7.73, "trd": [[1.24, 7.74]], "batb": [[0, 1.19, 5.8], [2, 1.16, 117.95]], "batl": [[1, 1.26, 0], [2, 1.27, 0]]}, {"timestamp": 1578682809895, "ltp": 1.24, "tv": 7.73, "trd": NaN, "batb": NaN, "batl": [[1, 1.26, 135.75]]}, {"timestamp": 1578682810878, "ltp": 1.24, "tv": 7.73, "trd": NaN, "batb": NaN, "batl": [[0, 1.26, 135.75], [1, 1.26, 0]]}, {"timestamp": 1578683262839, "ltp": 1.24, "tv": 7.73, "trd": NaN, "batb": NaN, "batl": [[0, 1.25, 142.34], [1, 1.26, 138.25], [2, 1.27, 119.5]]}, {"timestamp": 1578683270951, "ltp": 1.24, "tv": 7.73, "trd": NaN, "batb": NaN, "batl": [[0, 1.25, 142.66], [1, 1.26, 121.75]]}, {"timestamp": 1578683278942, "ltp": 1.24, "tv": 7.73, "trd": NaN, "batb": NaN, "batl": [[0, 1.25, 124.3], [1, 1.26, 139.25], [2, 1.27, 0]]}, {"timestamp": 1578687298962, "ltp": 1.24, "tv": 7.73, "trd": NaN, "batb": NaN, "batl": [[0, 1.26, 142.25], [1, 1.27, 118.5]]}, {"timestamp": 1578688098022, "ltp": 1.24, "tv": 7.73, "trd": NaN, "batb": [[1, 1.17, 245.94]], "batl": NaN}, {"timestamp": 1578688544822, "ltp": 1.24, "tv": 7.73, "trd": NaN, "batb": [[1, 1.17, 379.21]], "batl": NaN}, {"timestamp": 1578690341999, "ltp": 1.24, "tv": 7.73, "trd": NaN, "batb": [[0, 1.17, 379.21], [1, 1.16, 117.95], [2, 1.15, 877.6]], "batl": NaN}, {"timestamp": 1578690342730, "ltp": 1.24, "tv": 7.73, "trd": NaN, "batb": [[0, 1.18, 5.8], [1, 1.17, 379.21], [2, 1.16, 117.95]], "batl": NaN}, {"timestamp": 1578690347009, "ltp": 1.24, "tv": 7.73, "trd": NaN, "batb": [[2, 1.16, 451.13]], "batl": NaN}, {"timestamp": 1578690370471, "ltp": 1.24, "tv": 7.73, "trd": NaN, "batb": [[1, 1.17, 245.94]], "batl": NaN}, {"timestamp": 1578697352006, "ltp": 1.24, "tv": 7.73, "trd": [[1.24, 7.73]], "batb": [[0, 1.18, 5.8], [2, 1.16, 450.93]], "batl": NaN}, {"timestamp": 1578697610030, "ltp": 1.24, "tv": 7.73, "trd": NaN, "batb": [[1, 1.17, 563.66]], "batl": NaN}, {"timestamp": 1578697634141, "ltp": 1.24, "tv": 7.73, "trd": NaN, "batb": [[1, 1.17, 696.87]], "batl": NaN}, {"timestamp": 1578698006364, "ltp": 1.24, "tv": 7.73, "trd": NaN, "batb": [[1, 1.17, 714.69]], "batl": NaN}, {"timestamp": 1578701242003, "ltp": 1.24, "tv": 7.73, "trd": NaN, "batb": [[0, 1.18, 309.73]], "batl": NaN}, {"timestamp": 1578701266094, "ltp": 1.24, "tv": 7.73, "trd": NaN, "batb": [[1, 1.17, 581.48]], "batl": NaN}, {"timestamp": 1578702139996, "ltp": 1.24, "tv": 7.73, "trd": NaN, "batb": NaN, "batl": [[2, 1.28, 135.59]]}, {"timestamp": 1578702251824, "ltp": 1.24, "tv": 7.73, "trd": NaN, "batb": [[1, 1.17, 580.34]], "batl": [[2, 1.28, 117.59]]}, {"timestamp": 1578702638996, "ltp": 1.24, "tv": 7.73, "trd": NaN, "batb": NaN, "batl": [[2, 1.28, 0]]}, {"timestamp": 1578702656008, "ltp": 1.24, "tv": 7.73, "trd": NaN, "batb": NaN, "batl": [[2, 1.28, 117.84]]}, {"timestamp": 1578703311020, "ltp": 1.24, "tv": 7.73, "trd": NaN, "batb": NaN, "batl": [[2, 1.28, 113.59]]}, {"timestamp": 1578703540896, "ltp": 1.24, "tv": 7.73, "trd": NaN, "batb": NaN, "batl": [[2, 1.28, 0]]}, {"timestamp": 1578703557018, "ltp": 1.24, "tv": 7.73, "trd": NaN, "batb": NaN, "batl": [[2, 1.28, 134.09]]}, {"timestamp": 1578703925663, "ltp": 1.24, "tv": 7.73, "trd": NaN, "batb": NaN, "batl": [[2, 1.28, 0]]}, {"timestamp": 1578703941005, "ltp": 1.24, "tv": 7.73, "trd": NaN, "batb": NaN, "batl": [[2, 1.28, 124.34]]}, {"timestamp": 1578704115713, "ltp": 1.24, "tv": 7.73, "trd": NaN, "batb": NaN, "batl": [[2, 1.28, 119.84]]}, {"timestamp": 1578704431703, "ltp": 1.24, "tv": 7.73, "trd": NaN, "batb": NaN, "batl": [[2, 1.28, 134.34]]}, {"timestamp": 1578704873989, "ltp": 1.24, "tv": 7.73, "trd": NaN, "batb": [[0, 1.18, 5.8]], "batl": NaN}, {"timestamp": 1578704874501, "ltp": 1.24, "tv": 7.73, "trd": NaN, "batb": NaN, "batl": [[2, 1.28, 120.84]]}, {"timestamp": 1578705349843, "ltp": 1.24, "tv": 7.73, "trd": NaN, "batb": NaN, "batl": [[2, 1.28, 0]]}, {"timestamp": 1578705525962, "ltp": 1.24, "tv": 7.73, "trd": NaN, "batb": NaN, "batl": [[2, 1.28, 119.59]]}, {"timestamp": 1578705565010, "ltp": 1.24, "tv": 7.73, "trd": NaN, "batb": NaN, "batl": [[2, 1.28, 111.84]]}, {"timestamp": 1578705728626, "ltp": 1.24, "tv": 7.73, "trd": NaN, "batb": NaN, "batl": [[2, 1.28, 0]]}, {"timestamp": 1578705739847, "ltp": 1.24, "tv": 7.73, "trd": NaN, "batb": NaN, "batl": [[2, 1.28, 125.59]]}, {"timestamp": 1578706243516, "ltp": 1.24, "tv": 7.73, "trd": NaN, "batb": NaN, "batl": [[2, 1.28, 0]]}, {"timestamp": 1578707104004, "ltp": 1.24, "tv": 7.73, "trd": NaN, "batb": [[1, 1.17, 604.82]], "batl": NaN}, {"timestamp": 1578707236095, "ltp": 1.24, "tv": 7.73, "trd": NaN, "batb": NaN, "batl": [[2, 1.28, 124.84]]}, {"timestamp": 1578707824879, "ltp": 1.24, "tv": 7.73, "trd": NaN, "batb": NaN, "batl": [[2, 1.28, 134.59]]}, {"timestamp": 1578708008050, "ltp": 1.24, "tv": 7.73, "trd": NaN, "batb": NaN, "batl": [[2, 1.28, 0]]}, {"timestamp": 1578708030571, "ltp": 1.24, "tv": 7.73, "trd": NaN, "batb": NaN, "batl": [[2, 1.28, 120.09]]}, {"timestamp": 1578708079941, "ltp": 1.24, "tv": 7.73, "trd": NaN, "batb": NaN, "batl": [[2, 1.28, 119.84]]}, {"timestamp": 1578708529912, "ltp": 1.24, "tv": 7.73, "trd": NaN, "batb": [[1, 1.17, 738.03]], "batl": NaN}, {"timestamp": 1578708530283, "ltp": 1.24, "tv": 7.73, "trd": NaN, "batb": NaN, "batl": [[2, 1.28, 129.59]]}, {"timestamp": 1578709279986, "ltp": 1.24, "tv": 7.73, "trd": NaN, "batb": NaN, "batl": [[2, 1.28, 117.34]]}, {"timestamp": 1578709354013, "ltp": 1.24, "tv": 7.73, "trd": NaN, "batb": NaN, "batl": [[2, 1.28, 0]]}, {"timestamp": 1578709354994, "ltp": 1.24, "tv": 7.73, "trd": NaN, "batb": NaN, "batl": [[2, 1.28, 135.09]]}, {"timestamp": 1578709859022, "ltp": 1.24, "tv": 7.73, "trd": NaN, "batb": NaN, "batl": [[2, 1.28, 122.84]]}, {"timestamp": 1578710313995, "ltp": 1.24, "tv": 7.73, "trd": NaN, "batb": [[0, 1.18, 260.12]], "batl": NaN}, {"timestamp": 1578710314976, "ltp": 1.24, "tv": 7.73, "trd": NaN, "batb": [[1, 1.17, 468.75]], "batl": [[2, 1.28, 116.34]]}, {"timestamp": 1578710323478, "ltp": 1.24, "tv": 7.73, "trd": NaN, "batb": NaN, "batl": [[2, 1.28, 119.34]]}, {"timestamp": 1578710335931, "ltp": 1.24, "tv": 7.73, "trd": NaN, "batb": [[1, 1.17, 335.54]], "batl": [[2, 1.28, 0]]}, {"timestamp": 1578710336136, "ltp": 1.24, "tv": 7.73, "trd": NaN, "batb": NaN, "batl": [[2, 1.28, 115.34]]}, {"timestamp": 1578710394503, "ltp": 1.24, "tv": 7.73, "trd": NaN, "batb": NaN, "batl": [[2, 1.28, 127.34]]}, {"timestamp": 1578710708013, "ltp": 1.24, "tv": 7.73, "trd": NaN, "batb": NaN, "batl": [[2, 1.28, 0]]}, {"timestamp": 1578712579867, "ltp": 1.24, "tv": 7.73, "trd": NaN, "batb": NaN, "batl": [[2, 1.28, 131.84]]}, {"timestamp": 1578713413675, "ltp": 1.24, "tv": 7.73, "trd": NaN, "batb": NaN, "batl": [[2, 1.28, 0]]}, {"timestamp": 1578713425931, "ltp": 1.24, "tv": 7.73, "trd": NaN, "batb": NaN, "batl": [[2, 1.28, 134.34]]}, {"timestamp": 1578713967943, "ltp": 1.24, "tv": 7.73, "trd": NaN, "batb": [[1, 1.17, 468.75]], "batl": [[2, 1.28, 122.59]]}, {"timestamp": 1578714360658, "ltp": 1.24, "tv": 7.73, "trd": NaN, "batb": NaN, "batl": [[2, 1.28, 0]]}, {"timestamp": 1578714934868, "ltp": 1.24, "tv": 7.73, "trd": NaN, "batb": NaN, "batl": [[2, 1.28, 117.09]]}, {"timestamp": 1578715206629, "ltp": 1.24, "tv": 7.73, "trd": NaN, "batb": NaN, "batl": [[2, 1.28, 0]]}, {"timestamp": 1578715233050, "ltp": 1.24, "tv": 7.73, "trd": NaN, "batb": NaN, "batl": [[2, 1.28, 135.59]]}, {"timestamp": 1578715335811, "ltp": 1.24, "tv": 7.73, "trd": NaN, "batb": NaN, "batl": [[2, 1.28, 123.34]]}, {"timestamp": 1578715350905, "ltp": 1.24, "tv": 7.73, "trd": NaN, "batb": NaN, "batl": [[2, 1.28, 114.34]]}, {"timestamp": 1578715362017, "ltp": 1.24, "tv": 7.73, "trd": NaN, "batb": NaN, "batl": [[2, 1.28, 127.34]]}, {"timestamp": 1578715375945, "ltp": 1.24, "tv": 7.73, "trd": NaN, "batb": NaN, "batl": [[2, 1.28, 118.59]]}, {"timestamp": 1578715387967, "ltp": 1.24, "tv": 7.73, "trd": NaN, "batb": NaN, "batl": [[2, 1.28, 114.09]]}, {"timestamp": 1578715844999, "ltp": 1.24, "tv": 7.73, "trd": NaN, "batb": NaN, "batl": [[2, 1.28, 120.34]]}, {"timestamp": 1578716352989, "ltp": 1.24, "tv": 7.73, "trd": NaN, "batb": NaN, "batl": [[2, 1.28, 127.09]]}, {"timestamp": 1578716361990, "ltp": 1.24, "tv": 7.73, "trd": NaN, "batb": NaN, "batl": [[2, 1.28, 113.34]]}, {"timestamp": 1578716371698, "ltp": 1.24, "tv": 7.73, "trd": NaN, "batb": NaN, "batl": [[2, 1.28, 134.34]]}, {"timestamp": 1578716379877, "ltp": 1.24, "tv": 7.73, "trd": NaN, "batb": NaN, "batl": [[2, 1.28, 0]]}, {"timestamp": 1578716380836, "ltp": 1.24, "tv": 7.73, "trd": NaN, "batb": NaN, "batl": [[2, 1.28, 133.84]]}, {"timestamp": 1578716695846, "ltp": 1.24, "tv": 7.73, "trd": NaN, "batb": NaN, "batl": [[2, 1.28, 123.09]]}, {"timestamp": 1578717010356, "ltp": 1.24, "tv": 7.73, "trd": NaN, "batb": NaN, "batl": [[1, 1.27, 0], [2, 1.28, 0]]}, {"timestamp": 1578717023876, "ltp": 1.24, "tv": 7.73, "trd": NaN, "batb": NaN, "batl": [[1, 1.27, 130.5], [2, 1.28, 127.34]]}, {"timestamp": 1578717024973, "ltp": 1.24, "tv": 7.73, "trd": NaN, "batb": NaN, "batl": [[0, 1.27, 130.5], [1, 1.28, 127.34], [2, 1.28, 0]]}, {"timestamp": 1578721267600, "ltp": 1.24, "tv": 7.73, "trd": NaN, "batb": NaN, "batl": [[0, 1.25, 5.36], [1, 1.27, 130.5], [2, 1.28, 127.34]]}, {"timestamp": 1578721274530, "ltp": 1.24, "tv": 7.73, "trd": NaN, "batb": NaN, "batl": [[0, 1.25, 7.66]]}, {"timestamp": 1578721282439, "ltp": 1.24, "tv": 7.73, "trd": NaN, "batb": NaN, "batl": [[0, 1.24, 7.66], [1, 1.25, 7.66], [2, 1.27, 130.5]]}, {"timestamp": 1578722838843, "ltp": 1.24, "tv": 7.73, "trd": NaN, "batb": NaN, "batl": [[2, 1.27, 0]]}, {"timestamp": 1578723329052, "ltp": 1.24, "tv": 7.73, "trd": NaN, "batb": NaN, "batl": [[2, 1.27, 136.5]]}, {"timestamp": 1578723961877, "ltp": 1.24, "tv": 7.73, "trd": NaN, "batb": [[0, 1.18, 5.8], [1, 1.17, 738.03]], "batl": NaN}, {"timestamp": 1578726665724, "ltp": 1.24, "tv": 7.73, "trd": NaN, "batb": [[1, 1.17, 420.31]], "batl": NaN}, {"timestamp": 1578726689790, "ltp": 1.24, "tv": 7.73, "trd": NaN, "batb": [[1, 1.17, 287.1]], "batl": NaN}, {"timestamp": 1578727315245, "ltp": 1.24, "tv": 7.73, "trd": NaN, "batb": [[0, 1.22, 52.75], [1, 1.18, 5.8], [2, 1.17, 287.1]], "batl": NaN}, {"timestamp": 1578728471910, "ltp": 1.24, "tv": 7.73, "trd": NaN, "batb": [[2, 1.17, 604.82]], "batl": NaN}, {"timestamp": 1578728495331, "ltp": 1.24, "tv": 7.73, "trd": NaN, "batb": [[2, 1.17, 738.03]], "batl": NaN}, {"timestamp": 1578728714914, "ltp": 1.24, "tv": 7.73, "trd": NaN, "batb": [[0, 1.22, 98.2]], "batl": NaN}, {"timestamp": 1578729046036, "ltp": 1.24, "tv": 7.73, "trd": NaN, "batb": NaN, "batl": [[2, 1.26, 138.75]]}, {"timestamp": 1578729645938, "ltp": 1.24, "tv": 7.73, "trd": NaN, "batb": [[1, 1.17, 738.03], [2, 1.16, 450.93]], "batl": NaN}, {"timestamp": 1578730297434, "ltp": 1.24, "tv": 7.73, "trd": NaN, "batb": [[1, 1.18, 303.94], [2, 1.17, 738.03]], "batl": NaN}, {"timestamp": 1578730321980, "ltp": 1.24, "tv": 7.73, "trd": NaN, "batb": [[1, 1.18, 431.02]], "batl": NaN}, {"timestamp": 1578732039893, "ltp": 1.24, "tv": 7.73, "trd": NaN, "batb": NaN, "batl": [[2, 1.26, 0]]}, {"timestamp": 1578732250291, "ltp": 1.24, "tv": 7.73, "trd": NaN, "batb": NaN, "batl": [[2, 1.26, 127.75]]}, {"timestamp": 1578733237045, "ltp": 1.24, "tv": 7.73, "trd": NaN, "batb": [[1, 1.19, 240.93], [2, 1.18, 431.02]], "batl": NaN}, {"timestamp": 1578736031946, "ltp": 1.24, "tv": 7.73, "trd": NaN, "batb": NaN, "batl": [[2, 1.26, 0]]}, {"timestamp": 1578736183742, "ltp": 1.24, "tv": 7.73, "trd": NaN, "batb": NaN, "batl": [[2, 1.26, 127.75]]}, {"timestamp": 1578736899949, "ltp": 1.24, "tv": 7.73, "trd": NaN, "batb": NaN, "batl": [[2, 1.26, 0]]}, {"timestamp": 1578737238724, "ltp": 1.24, "tv": 7.73, "trd": NaN, "batb": NaN, "batl": [[2, 1.26, 132.75]]}, {"timestamp": 1578737796769, "ltp": 1.24, "tv": 7.73, "trd": NaN, "batb": NaN, "batl": [[2, 1.26, 0]]}, {"timestamp": 1578738039968, "ltp": 1.24, "tv": 7.73, "trd": NaN, "batb": NaN, "batl": [[2, 1.27, 124.5]]}, {"timestamp": 1578738702991, "ltp": 1.24, "tv": 7.73, "trd": NaN, "batb": NaN, "batl": [[2, 1.27, 0]]}, {"timestamp": 1578739283729, "ltp": 1.24, "tv": 7.73, "trd": NaN, "batb": NaN, "batl": [[2, 1.27, 136.5]]}, {"timestamp": 1578739531043, "ltp": 1.24, "tv": 7.73, "trd": NaN, "batb": NaN, "batl": [[2, 1.26, 143.75]]}, {"timestamp": 1578739600045, "ltp": 1.24, "tv": 7.73, "trd": NaN, "batb": NaN, "batl": [[2, 1.26, 0]]}, {"timestamp": 1578739728560, "ltp": 1.24, "tv": 7.73, "trd": NaN, "batb": NaN, "batl": [[2, 1.26, 127.75]]}, {"timestamp": 1578740501012, "ltp": 1.24, "tv": 7.73, "trd": NaN, "batb": NaN, "batl": [[2, 1.26, 0]]}, {"timestamp": 1578740565182, "ltp": 1.24, "tv": 7.73, "trd": NaN, "batb": [[0, 1.22, 52.75]], "batl": NaN}, {"timestamp": 1578740568795, "ltp": 1.24, "tv": 7.73, "trd": NaN, "batb": [[0, 1.22, 98.2]], "batl": NaN}, {"timestamp": 1578740765139, "ltp": 1.24, "tv": 7.73, "trd": NaN, "batb": NaN, "batl": [[2, 1.26, 130.25]]}, {"timestamp": 1578741097009, "ltp": 1.24, "tv": 7.73, "trd": NaN, "batb": [[0, 1.22, 52.75]], "batl": NaN}, {"timestamp": 1578741137990, "ltp": 1.24, "tv": 7.73, "trd": NaN, "batb": [[1, 1.18, 685.34], [2, 1.17, 468.75]], "batl": NaN}, {"timestamp": 1578741325029, "ltp": 1.24, "tv": 7.73, "trd": NaN, "batb": NaN, "batl": [[2, 1.26, 0]]}, {"timestamp": 1578741525984, "ltp": 1.24, "tv": 7.73, "trd": NaN, "batb": NaN, "batl": [[1, 1.25, 129.6], [2, 1.26, 124.25]]}, {"timestamp": 1578742226909, "ltp": 1.24, "tv": 7.73, "trd": NaN, "batb": NaN, "batl": [[1, 1.25, 7.66], [2, 1.26, 0]]}, {"timestamp": 1578743101847, "ltp": 1.24, "tv": 7.73, "trd": NaN, "batb": [[1, 1.18, 604.42]], "batl": NaN}, {"timestamp": 1578743618719, "ltp": 1.22, "tv": 13.85, "trd": [[1.22, 6.12]], "batb": [[0, 1.22, 49.69]], "batl": NaN}, {"timestamp": 1578747897701, "ltp": 1.22, "tv": 17.85, "trd": [[1.22, 10.12]], "batb": [[0, 1.22, 47.69]], "batl": NaN}, {"timestamp": 1578748074378, "ltp": 1.22, "tv": 17.85, "trd": NaN, "batb": [[2, 1.17, 450.93]], "batl": NaN}, {"timestamp": 1578748331046, "ltp": 1.22, "tv": 17.85, "trd": NaN, "batb": [[1, 1.18, 431.02], [2, 1.17, 634.53]], "batl": NaN}, {"timestamp": 1578751151144, "ltp": 1.22, "tv": 22.44, "trd": [[1.22, 14.71]], "batb": [[0, 1.22, 45.4]], "batl": NaN}, {"timestamp": 1578755434888, "ltp": 1.22, "tv": 22.44, "trd": NaN, "batb": NaN, "batl": [[0, 1.24, 135.14], [1, 1.25, 138.64]]}, {"timestamp": 1578755439789, "ltp": 1.22, "tv": 22.44, "trd": NaN, "batb": [[2, 1.17, 450.93]], "batl": NaN}, {"timestamp": 1578755730897, "ltp": 1.22, "tv": 22.44, "trd": NaN, "batb": [[2, 1.17, 634.53]], "batl": NaN}, {"timestamp": 1578755811943, "ltp": 1.22, "tv": 22.44, "trd": NaN, "batb": NaN, "batl": [[0, 1.24, 7.66], [1, 1.25, 7.66]]}, {"timestamp": 1578755917987, "ltp": 1.22, "tv": 22.44, "trd": NaN, "batb": NaN, "batl": [[0, 1.23, 158.5], [1, 1.24, 136.89], [2, 1.25, 153.24]]}, {"timestamp": 1578755921791, "ltp": 1.22, "tv": 22.44, "trd": NaN, "batb": [[2, 1.17, 450.93]], "batl": NaN}, {"timestamp": 1578755923018, "ltp": 1.22, "tv": 22.44, "trd": NaN, "batb": NaN, "batl": [[2, 1.25, 140.84]]}, {"timestamp": 1578755929823, "ltp": 1.22, "tv": 22.44, "trd": NaN, "batb": NaN, "batl": [[2, 1.25, 7.66]]}, {"timestamp": 1578755930115, "ltp": 1.22, "tv": 22.44, "trd": NaN, "batb": NaN, "batl": [[2, 1.25, 133.4]]}, {"timestamp": 1578755945936, "ltp": 1.22, "tv": 22.44, "trd": NaN, "batb": NaN, "batl": [[2, 1.25, 7.66]]}, {"timestamp": 1578756736717, "ltp": 1.22, "tv": 22.44, "trd": NaN, "batb": NaN, "batl": [[2, 1.25, 131.4]]}, {"timestamp": 1578756742875, "ltp": 1.22, "tv": 22.44, "trd": NaN, "batb": NaN, "batl": [[2, 1.25, 7.66]]}, {"timestamp": 1578756743964, "ltp": 1.22, "tv": 22.44, "trd": NaN, "batb": NaN, "batl": [[2, 1.25, 144.88]]}, {"timestamp": 1578756761736, "ltp": 1.22, "tv": 22.44, "trd": NaN, "batb": NaN, "batl": [[2, 1.25, 7.66]]}, {"timestamp": 1578756915335, "ltp": 1.22, "tv": 22.44, "trd": NaN, "batb": NaN, "batl": [[2, 1.25, 135.6]]}, {"timestamp": 1578757483812, "ltp": 1.22, "tv": 22.44, "trd": NaN, "batb": NaN, "batl": [[2, 1.25, 129.52]]}, {"timestamp": 1578757790953, "ltp": 1.22, "tv": 22.44, "trd": NaN, "batb": NaN, "batl": [[2, 1.25, 7.66]]}, {"timestamp": 1578757792053, "ltp": 1.22, "tv": 22.44, "trd": NaN, "batb": NaN, "batl": [[2, 1.25, 152.12]]}, {"timestamp": 1578757820879, "ltp": 1.22, "tv": 22.44, "trd": NaN, "batb": NaN, "batl": [[2, 1.25, 7.66]]}, {"timestamp": 1578757838883, "ltp": 1.22, "tv": 22.44, "trd": NaN, "batb": NaN, "batl": [[2, 1.25, 139.04]]}, {"timestamp": 1578757961310, "ltp": 1.22, "tv": 22.44, "trd": NaN, "batb": NaN, "batl": [[2, 1.25, 133.24]]}, {"timestamp": 1578758278009, "ltp": 1.22, "tv": 22.44, "trd": NaN, "batb": NaN, "batl": [[2, 1.25, 7.66]]}, {"timestamp": 1578758278114, "ltp": 1.22, "tv": 22.44, "trd": NaN, "batb": NaN, "batl": [[2, 1.25, 136.4]]}, {"timestamp": 1578758316924, "ltp": 1.22, "tv": 22.44, "trd": NaN, "batb": NaN, "batl": [[2, 1.25, 7.66]]}, {"timestamp": 1578758423488, "ltp": 1.22, "tv": 22.44, "trd": NaN, "batb": [[2, 1.17, 756.93]], "batl": NaN}, {"timestamp": 1578758431016, "ltp": 1.22, "tv": 37.76, "trd": [[1.22, 30.03]], "batb": [[0, 1.22, 37.74]], "batl": NaN}, {"timestamp": 1578758664741, "ltp": 1.22, "tv": 37.76, "trd": NaN, "batb": NaN, "batl": [[2, 1.25, 132.36]]}, {"timestamp": 1578758669762, "ltp": 1.22, "tv": 37.76, "trd": NaN, "batb": [[2, 1.17, 450.93]], "batl": [[2, 1.25, 7.66]]}, {"timestamp": 1578759640981, "ltp": 1.22, "tv": 37.76, "trd": NaN, "batb": NaN, "batl": [[2, 1.25, 133.28]]}, {"timestamp": 1578759648813, "ltp": 1.22, "tv": 37.76, "trd": NaN, "batb": NaN, "batl": [[2, 1.25, 7.66]]}, {"timestamp": 1578759830967, "ltp": 1.22, "tv": 37.76, "trd": NaN, "batb": [[1, 1.18, 440.68]], "batl": NaN}, {"timestamp": 1578759831802, "ltp": 1.22, "tv": 37.76, "trd": NaN, "batb": NaN, "batl": [[2, 1.25, 28.76]]}, {"timestamp": 1578760515955, "ltp": 1.22, "tv": 37.76, "trd": NaN, "batb": NaN, "batl": [[2, 1.25, 152.66]]}, {"timestamp": 1578760686947, "ltp": 1.22, "tv": 37.76, "trd": NaN, "batb": NaN, "batl": [[2, 1.25, 172.74]]}, {"timestamp": 1578760767932, "ltp": 1.22, "tv": 37.76, "trd": NaN, "batb": NaN, "batl": [[2, 1.25, 157.78]]}, {"timestamp": 1578761043007, "ltp": 1.22, "tv": 37.76, "trd": NaN, "batb": NaN, "batl": [[2, 1.25, 28.76]]}, {"timestamp": 1578761044026, "ltp": 1.22, "tv": 37.76, "trd": NaN, "batb": NaN, "batl": [[2, 1.25, 152.54]]}, {"timestamp": 1578761053024, "ltp": 1.22, "tv": 37.76, "trd": NaN, "batb": NaN, "batl": [[2, 1.25, 28.76]]}, {"timestamp": 1578761363812, "ltp": 1.22, "tv": 74.25, "trd": [[1.22, 66.53]], "batb": [[0, 1.22, 19.5]], "batl": NaN}, {"timestamp": 1578761755898, "ltp": 1.22, "tv": 86.75, "trd": [[1.22, 79.02]], "batb": [[0, 1.22, 13.25]], "batl": NaN}, {"timestamp": 1578761798457, "ltp": 1.22, "tv": 86.75, "trd": NaN, "batb": [[1, 1.18, 313.59], [2, 1.17, 317.72]], "batl": NaN}, {"timestamp": 1578761834961, "ltp": 1.22, "tv": 86.75, "trd": NaN, "batb": [[1, 1.18, 9.65], [2, 1.16, 469.87]], "batl": NaN}, {"timestamp": 1578761863823, "ltp": 1.22, "tv": 100.0, "trd": [[1.22, 92.27]], "batb": [[0, 1.18, 9.65], [1, 1.16, 469.87], [2, 1.15, 973.89]], "batl": NaN}, {"timestamp": 1578761867952, "ltp": 1.22, "tv": 100.0, "trd": NaN, "batb": [[1, 1.17, 306], [2, 1.16, 469.87]], "batl": NaN}, {"timestamp": 1578761872813, "ltp": 1.22, "tv": 100.0, "trd": NaN, "batb": [[0, 1.18, 65.21]], "batl": NaN}, {"timestamp": 1578762055042, "ltp": 1.22, "tv": 100.0, "trd": NaN, "batb": [[1, 1.16, 794.99], [2, 1.15, 973.89]], "batl": NaN}, {"timestamp": 1578762267034, "ltp": 1.22, "tv": 100.0, "trd": NaN, "batb": NaN, "batl": [[0, 1.22, 7.66], [1, 1.23, 158.5], [2, 1.24, 136.89]]}, {"timestamp": 1578762371005, "ltp": 1.22, "tv": 100.0, "trd": NaN, "batb": [[0, 1.18, 354.21], [1, 1.16, 469.87]], "batl": NaN}, {"timestamp": 1578763052822, "ltp": 1.22, "tv": 122.38, "trd": [[1.22, 114.66]], "batb": [[0, 1.22, 64.25], [1, 1.18, 354.21], [2, 1.16, 469.87]], "batl": [[0, 1.23, 158.5], [1, 1.24, 136.89], [2, 1.25, 28.76]]}, {"timestamp": 1578763058927, "ltp": 1.22, "tv": 122.38, "trd": NaN, "batb": [[1, 1.18, 65.21]], "batl": NaN}, {"timestamp": 1578763063812, "ltp": 1.22, "tv": 122.38, "trd": NaN, "batb": [[1, 1.18, 65.48]], "batl": NaN}, {"timestamp": 1578763065021, "ltp": 1.22, "tv": 122.38, "trd": NaN, "batb": NaN, "batl": [[1, 1.24, 157.99], [2, 1.25, 7.66]]}, {"timestamp": 1578763077055, "ltp": 1.22, "tv": 122.38, "trd": NaN, "batb": [[0, 1.18, 65.48], [1, 1.16, 469.87], [2, 1.15, 973.89]], "batl": NaN}, {"timestamp": 1578763079039, "ltp": 1.22, "tv": 122.38, "trd": NaN, "batb": [[0, 1.18, 354.48]], "batl": NaN}, {"timestamp": 1578763126044, "ltp": 1.23, "tv": 280.34, "trd": [[1.23, 157.96]], "batb": NaN, "batl": [[0, 1.23, 79.52]]}, {"timestamp": 1578763465841, "ltp": 1.23, "tv": 280.34, "trd": NaN, "batb": NaN, "batl": [[2, 1.25, 135.16]]}, {"timestamp": 1578763504978, "ltp": 1.23, "tv": 280.34, "trd": NaN, "batb": NaN, "batl": [[2, 1.25, 131.4]]}, {"timestamp": 1578763541015, "ltp": 1.23, "tv": 280.34, "trd": NaN, "batb": NaN, "batl": [[2, 1.25, 7.66]]}, {"timestamp": 1578763630710, "ltp": 1.23, "tv": 280.34, "trd": NaN, "batb": [[0, 1.18, 356.18]], "batl": [[2, 1.25, 143.76]]}, {"timestamp": 1578763637049, "ltp": 1.23, "tv": 280.34, "trd": NaN, "batb": [[0, 1.18, 356.21]], "batl": [[2, 1.25, 7.66]]}, {"timestamp": 1578763656974, "ltp": 1.23, "tv": 280.34, "trd": NaN, "batb": [[0, 1.18, 354.51]], "batl": NaN}, {"timestamp": 1578763884028, "ltp": 1.23, "tv": 280.34, "trd": NaN, "batb": NaN, "batl": [[2, 1.25, 154.56]]}, {"timestamp": 1578763895025, "ltp": 1.23, "tv": 280.34, "trd": NaN, "batb": NaN, "batl": [[2, 1.25, 135.68]]}, {"timestamp": 1578763932971, "ltp": 1.23, "tv": 280.34, "trd": NaN, "batb": NaN, "batl": [[2, 1.25, 7.66]]}, {"timestamp": 1578763933880, "ltp": 1.23, "tv": 280.34, "trd": NaN, "batb": NaN, "batl": [[2, 1.25, 145.24]]}, {"timestamp": 1578764149990, "ltp": 1.23, "tv": 280.34, "trd": NaN, "batb": NaN, "batl": [[2, 1.25, 148.6]]}, {"timestamp": 1578764154929, "ltp": 1.23, "tv": 280.34, "trd": NaN, "batb": NaN, "batl": [[2, 1.25, 137.96]]}, {"timestamp": 1578764159904, "ltp": 1.23, "tv": 280.34, "trd": NaN, "batb": NaN, "batl": [[2, 1.25, 135.08]]}, {"timestamp": 1578764170452, "ltp": 1.23, "tv": 280.34, "trd": NaN, "batb": NaN, "batl": [[2, 1.25, 144.64]]}, {"timestamp": 1578764210794, "ltp": 1.23, "tv": 280.34, "trd": NaN, "batb": NaN, "batl": [[2, 1.25, 7.66]]}, {"timestamp": 1578764227949, "ltp": 1.23, "tv": 280.34, "trd": NaN, "batb": NaN, "batl": [[2, 1.25, 152.08]]}, {"timestamp": 1578764330444, "ltp": 1.23, "tv": 280.34, "trd": NaN, "batb": NaN, "batl": [[2, 1.25, 152.28]]}, {"timestamp": 1578764375033, "ltp": 1.23, "tv": 280.34, "trd": NaN, "batb": NaN, "batl": [[2, 1.25, 143.44]]}, {"timestamp": 1578764384045, "ltp": 1.23, "tv": 280.34, "trd": NaN, "batb": NaN, "batl": [[2, 1.25, 147.56]]}, {"timestamp": 1578764553913, "ltp": 1.23, "tv": 280.34, "trd": NaN, "batb": [[0, 1.18, 65.51], [1, 1.17, 306], [2, 1.16, 469.87]], "batl": NaN}, {"timestamp": 1578764554997, "ltp": 1.23, "tv": 280.34, "trd": NaN, "batb": NaN, "batl": [[2, 1.25, 133.2]]}, {"timestamp": 1578764564023, "ltp": 1.23, "tv": 280.34, "trd": NaN, "batb": NaN, "batl": [[2, 1.25, 133]]}, {"timestamp": 1578764605049, "ltp": 1.23, "tv": 280.34, "trd": NaN, "batb": NaN, "batl": [[2, 1.25, 7.66]]}, {"timestamp": 1578764605970, "ltp": 1.23, "tv": 280.34, "trd": NaN, "batb": NaN, "batl": [[2, 1.25, 143.04]]}, {"timestamp": 1578764618954, "ltp": 1.23, "tv": 280.34, "trd": NaN, "batb": NaN, "batl": [[2, 1.25, 156]]}, {"timestamp": 1578764624860, "ltp": 1.23, "tv": 280.34, "trd": NaN, "batb": NaN, "batl": [[2, 1.25, 150.88]]}, {"timestamp": 1578764635011, "ltp": 1.23, "tv": 280.34, "trd": NaN, "batb": NaN, "batl": [[2, 1.25, 147.68]]}, {"timestamp": 1578764640984, "ltp": 1.23, "tv": 280.34, "trd": NaN, "batb": NaN, "batl": [[2, 1.25, 136.28]]}, {"timestamp": 1578764645915, "ltp": 1.23, "tv": 280.34, "trd": NaN, "batb": NaN, "batl": [[2, 1.25, 7.66]]}, {"timestamp": 1578764646915, "ltp": 1.23, "tv": 280.34, "trd": NaN, "batb": NaN, "batl": [[2, 1.25, 129.2]]}, {"timestamp": 1578764651892, "ltp": 1.23, "tv": 280.34, "trd": NaN, "batb": NaN, "batl": [[2, 1.25, 137.56]]}, {"timestamp": 1578764656590, "ltp": 1.23, "tv": 280.34, "trd": NaN, "batb": NaN, "batl": [[2, 1.25, 146.12]]}, {"timestamp": 1578764661342, "ltp": 1.23, "tv": 280.34, "trd": NaN, "batb": NaN, "batl": [[2, 1.25, 7.66]]}, {"timestamp": 1578764662901, "ltp": 1.23, "tv": 280.34, "trd": NaN, "batb": NaN, "batl": [[2, 1.25, 144.8]]}, {"timestamp": 1578764668047, "ltp": 1.23, "tv": 280.34, "trd": NaN, "batb": NaN, "batl": [[2, 1.25, 7.66]]}, {"timestamp": 1578764670020, "ltp": 1.23, "tv": 280.34, "trd": NaN, "batb": NaN, "batl": [[2, 1.25, 136.32]]}, {"timestamp": 1578764675051, "ltp": 1.23, "tv": 280.34, "trd": NaN, "batb": NaN, "batl": [[2, 1.25, 148.76]]}, {"timestamp": 1578764679228, "ltp": 1.23, "tv": 280.34, "trd": NaN, "batb": NaN, "batl": [[2, 1.25, 7.66]]}, {"timestamp": 1578764681255, "ltp": 1.23, "tv": 280.34, "trd": NaN, "batb": NaN, "batl": [[2, 1.25, 155.76]]}, {"timestamp": 1578764687237, "ltp": 1.23, "tv": 280.34, "trd": NaN, "batb": NaN, "batl": [[2, 1.25, 153.24]]}, {"timestamp": 1578764692663, "ltp": 1.23, "tv": 280.34, "trd": NaN, "batb": NaN, "batl": [[2, 1.25, 154.36]]}, {"timestamp": 1578764697676, "ltp": 1.23, "tv": 280.34, "trd": NaN, "batb": NaN, "batl": [[2, 1.25, 140.04]]}, {"timestamp": 1578764703055, "ltp": 1.23, "tv": 280.34, "trd": NaN, "batb": NaN, "batl": [[2, 1.25, 150.6]]}, {"timestamp": 1578764704993, "ltp": 1.23, "tv": 280.34, "trd": NaN, "batb": [[1, 1.17, 290.7]], "batl": NaN}, {"timestamp": 1578764707789, "ltp": 1.23, "tv": 280.34, "trd": NaN, "batb": NaN, "batl": [[2, 1.25, 141.12]]}, {"timestamp": 1578764712774, "ltp": 1.23, "tv": 280.34, "trd": NaN, "batb": NaN, "batl": [[2, 1.25, 135.96]]}, {"timestamp": 1578764718687, "ltp": 1.23, "tv": 280.34, "trd": NaN, "batb": NaN, "batl": [[2, 1.25, 140.56]]}, {"timestamp": 1578764723906, "ltp": 1.23, "tv": 280.34, "trd": NaN, "batb": NaN, "batl": [[2, 1.25, 7.66]]}, {"timestamp": 1578764725799, "ltp": 1.23, "tv": 280.34, "trd": NaN, "batb": NaN, "batl": [[2, 1.25, 134.28]]}, {"timestamp": 1578764730803, "ltp": 1.23, "tv": 280.34, "trd": NaN, "batb": NaN, "batl": [[2, 1.25, 129.48]]}, {"timestamp": 1578764746027, "ltp": 1.23, "tv": 280.34, "trd": NaN, "batb": NaN, "batl": [[2, 1.25, 7.66]]}, {"timestamp": 1578764948031, "ltp": 1.23, "tv": 280.34, "trd": NaN, "batb": NaN, "batl": [[2, 1.25, 135.76]]}, {"timestamp": 1578764956951, "ltp": 1.23, "tv": 280.34, "trd": NaN, "batb": NaN, "batl": [[2, 1.25, 7.66]]}, {"timestamp": 1578764957958, "ltp": 1.23, "tv": 280.34, "trd": NaN, "batb": NaN, "batl": [[2, 1.25, 138.68]]}, {"timestamp": 1578764989967, "ltp": 1.23, "tv": 280.34, "trd": NaN, "batb": NaN, "batl": [[2, 1.25, 7.66]]}, {"timestamp": 1578764990965, "ltp": 1.23, "tv": 280.34, "trd": NaN, "batb": NaN, "batl": [[2, 1.25, 141.44]]}, {"timestamp": 1578765002994, "ltp": 1.23, "tv": 280.34, "trd": NaN, "batb": NaN, "batl": [[2, 1.25, 143.56]]}, {"timestamp": 1578765014910, "ltp": 1.23, "tv": 280.34, "trd": NaN, "batb": NaN, "batl": [[2, 1.25, 154.96]]}, {"timestamp": 1578765023011, "ltp": 1.23, "tv": 280.34, "trd": NaN, "batb": [[0, 1.18, 916.72]], "batl": [[2, 1.25, 144.6]]}, {"timestamp": 1578765028017, "ltp": 1.23, "tv": 280.34, "trd": NaN, "batb": [[1, 1.17, 1141.91]], "batl": [[2, 1.25, 143.68]]}, {"timestamp": 1578765035821, "ltp": 1.23, "tv": 280.34, "trd": NaN, "batb": [[2, 1.16, 1321.08]], "batl": [[2, 1.25, 135.32]]}, {"timestamp": 1578765041737, "ltp": 1.23, "tv": 280.34, "trd": NaN, "batb": NaN, "batl": [[2, 1.25, 136.8]]}, {"timestamp": 1578765045819, "ltp": 1.23, "tv": 280.34, "trd": NaN, "batb": [[0, 1.19, 425.64], [1, 1.18, 916.69], [2, 1.17, 1141.91]], "batl": NaN}, {"timestamp": 1578765047024, "ltp": 1.23, "tv": 280.34, "trd": NaN, "batb": NaN, "batl": [[2, 1.25, 136.32]]}, {"timestamp": 1578765078368, "ltp": 1.23, "tv": 280.34, "trd": NaN, "batb": NaN, "batl": [[2, 1.25, 151.48]]}, {"timestamp": 1578765084876, "ltp": 1.23, "tv": 280.34, "trd": NaN, "batb": NaN, "batl": [[2, 1.25, 147.96]]}, {"timestamp": 1578765092040, "ltp": 1.23, "tv": 280.34, "trd": NaN, "batb": NaN, "batl": [[2, 1.25, 129.52]]}, {"timestamp": 1578765098880, "ltp": 1.23, "tv": 280.34, "trd": NaN, "batb": NaN, "batl": [[2, 1.25, 135]]}, {"timestamp": 1578765111004, "ltp": 1.23, "tv": 280.34, "trd": NaN, "batb": NaN, "batl": [[2, 1.25, 7.66]]}, {"timestamp": 1578765223947, "ltp": 1.23, "tv": 280.34, "trd": NaN, "batb": NaN, "batl": [[2, 1.25, 142.36]]}, {"timestamp": 1578765232738, "ltp": 1.23, "tv": 280.34, "trd": NaN, "batb": NaN, "batl": [[2, 1.25, 140.12]]}, {"timestamp": 1578765268791, "ltp": 1.23, "tv": 280.34, "trd": NaN, "batb": NaN, "batl": [[2, 1.25, 144.6]]}, {"timestamp": 1578765379056, "ltp": 1.23, "tv": 280.34, "trd": NaN, "batb": NaN, "batl": [[2, 1.25, 153.32]]}, {"timestamp": 1578765396989, "ltp": 1.23, "tv": 280.34, "trd": NaN, "batb": NaN, "batl": [[2, 1.25, 142.64]]}, {"timestamp": 1578765401982, "ltp": 1.23, "tv": 280.34, "trd": NaN, "batb": NaN, "batl": [[2, 1.25, 144.88]]}, {"timestamp": 1578765406690, "ltp": 1.23, "tv": 280.34, "trd": NaN, "batb": NaN, "batl": [[2, 1.25, 130.76]]}, {"timestamp": 1578765412012, "ltp": 1.23, "tv": 280.34, "trd": NaN, "batb": NaN, "batl": [[2, 1.25, 136.6]]}, {"timestamp": 1578765416626, "ltp": 1.23, "tv": 280.34, "trd": NaN, "batb": NaN, "batl": [[2, 1.25, 150.48]]}, {"timestamp": 1578765421627, "ltp": 1.23, "tv": 280.34, "trd": NaN, "batb": NaN, "batl": [[2, 1.25, 152.24]]}, {"timestamp": 1578765507030, "ltp": 1.23, "tv": 280.34, "trd": NaN, "batb": NaN, "batl": [[0, 1.22, 22.97], [1, 1.23, 79.52], [2, 1.24, 157.99]]}, {"timestamp": 1578765540008, "ltp": 1.23, "tv": 280.34, "trd": NaN, "batb": [[0, 1.2, 20.03], [1, 1.19, 425.6], [2, 1.18, 916.69]], "batl": NaN}, {"timestamp": 1578765543884, "ltp": 1.23, "tv": 280.34, "trd": NaN, "batb": NaN, "batl": [[1, 1.24, 157.99], [2, 1.25, 133.88]]}, {"timestamp": 1578765549961, "ltp": 1.23, "tv": 280.34, "trd": NaN, "batb": [[0, 1.2, 70.03], [2, 1.18, 861.13]], "batl": NaN}, {"timestamp": 1578765782808, "ltp": 1.23, "tv": 280.34, "trd": NaN, "batb": [[0, 1.2, 20.03]], "batl": NaN}, {"timestamp": 1578765886008, "ltp": 1.21, "tv": 297.69, "trd": [[1.21, 17.35]], "batb": [[0, 1.2, 20]], "batl": NaN}, {"timestamp": 1578765970033, "ltp": 1.21, "tv": 297.69, "trd": NaN, "batb": NaN, "batl": [[1, 1.24, 446.3], [2, 1.25, 419.88]]}, {"timestamp": 1578765972005, "ltp": 1.21, "tv": 297.69, "trd": NaN, "batb": [[0, 1.2, 247.99], [1, 1.19, 673.83], [2, 1.18, 1126.29]], "batl": NaN}, {"timestamp": 1578766154225, "ltp": 1.21, "tv": 297.69, "trd": NaN, "batb": NaN, "batl": [[1, 1.23, 38.28], [2, 1.24, 446.3]]}, {"timestamp": 1578766924177, "ltp": 1.21, "tv": 297.69, "trd": NaN, "batb": NaN, "batl": [[1, 1.23, 48.28]]}, {"timestamp": 1578766925393, "ltp": 1.21, "tv": 297.69, "trd": NaN, "batb": NaN, "batl": [[2, 1.24, 456.3]]}, {"timestamp": 1578766942891, "ltp": 1.21, "tv": 297.69, "trd": NaN, "batb": NaN, "batl": [[1, 1.23, 196.78]]}, {"timestamp": 1578766945796, "ltp": 1.21, "tv": 297.69, "trd": NaN, "batb": NaN, "batl": [[1, 1.23, 487.43]]}, {"timestamp": 1578767184822, "ltp": 1.21, "tv": 297.69, "trd": NaN, "batb": NaN, "batl": [[0, 1.22, 322.97]]}, {"timestamp": 1578767187439, "ltp": 1.21, "tv": 297.69, "trd": NaN, "batb": NaN, "batl": [[0, 1.22, 616]]}, {"timestamp": 1578767293751, "ltp": 1.21, "tv": 297.69, "trd": NaN, "batb": NaN, "batl": [[2, 1.24, 438.52]]}, {"timestamp": 1578768101055, "ltp": 1.21, "tv": 297.69, "trd": NaN, "batb": [[0, 1.21, 25], [1, 1.2, 247.99], [2, 1.19, 673.83]], "batl": [[0, 1.22, 641]]}, {"timestamp": 1578768103946, "ltp": 1.21, "tv": 345.69, "trd": [[1.21, 65.35]], "batb": [[0, 1.21, 1]], "batl": NaN}, {"timestamp": 1578768106379, "ltp": 1.21, "tv": 345.69, "trd": NaN, "batb": NaN, "batl": [[0, 1.22, 665]]}, {"timestamp": 1578768108994, "ltp": 1.21, "tv": 642.16, "trd": [[1.21, 361.81]], "batb": [[0, 1.2, 247.99], [1, 1.19, 673.83], [2, 1.18, 1126.29]], "batl": NaN}, {"timestamp": 1578768109986, "ltp": 1.21, "tv": 642.16, "trd": NaN, "batb": NaN, "batl": [[0, 1.22, 666]]}, {"timestamp": 1578768113981, "ltp": 1.21, "tv": 937.62, "trd": [[1.21, 657.28]], "batb": NaN, "batl": NaN}, {"timestamp": 1578768119987, "ltp": 1.21, "tv": 1233.08, "trd": [[1.21, 952.74]], "batb": NaN, "batl": NaN}, {"timestamp": 1578768124522, "ltp": 1.21, "tv": 1528.55, "trd": [[1.21, 1248.2]], "batb": NaN, "batl": NaN}, {"timestamp": 1578768129837, "ltp": 1.21, "tv": 1824.01, "trd": [[1.21, 1543.67]], "batb": NaN, "batl": NaN}, {"timestamp": 1578768135029, "ltp": 1.21, "tv": 2119.47, "trd": [[1.21, 1839.13]], "batb": NaN, "batl": NaN}, {"timestamp": 1578768140944, "ltp": 1.21, "tv": 2414.93, "trd": [[1.21, 2134.59]], "batb": NaN, "batl": NaN}, {"timestamp": 1578768145627, "ltp": 1.21, "tv": 2710.4, "trd": [[1.21, 2430.05]], "batb": NaN, "batl": NaN}, {"timestamp": 1578768150766, "ltp": 1.21, "tv": 3005.86, "trd": [[1.21, 2725.52]], "batb": NaN, "batl": NaN}, {"timestamp": 1578768156964, "ltp": 1.21, "tv": 3301.32, "trd": [[1.21, 3020.98]], "batb": NaN, "batl": NaN}, {"timestamp": 1578768161781, "ltp": 1.21, "tv": 3547.41, "trd": [[1.21, 3267.06]], "batb": NaN, "batl": NaN}, {"timestamp": 1578768166881, "ltp": 1.21, "tv": 3762.33, "trd": [[1.21, 3481.99]], "batb": NaN, "batl": NaN}, {"timestamp": 1578768172013, "ltp": 1.21, "tv": 3944.1, "trd": [[1.21, 3663.75]], "batb": NaN, "batl": NaN}, {"timestamp": 1578768179689, "ltp": 1.21, "tv": 4113.96, "trd": [[1.21, 3833.62]], "batb": NaN, "batl": NaN}, {"timestamp": 1578768182997, "ltp": 1.21, "tv": 4260.62, "trd": [[1.21, 3980.28]], "batb": NaN, "batl": NaN}, {"timestamp": 1578768187817, "ltp": 1.21, "tv": 4386.77, "trd": [[1.21, 4106.42]], "batb": NaN, "batl": NaN}, {"timestamp": 1578768192911, "ltp": 1.21, "tv": 4496.77, "trd": [[1.21, 4216.43]], "batb": NaN, "batl": NaN}, {"timestamp": 1578768195010, "ltp": 1.21, "tv": 4506.77, "trd": [[1.21, 4226.43]], "batb": NaN, "batl": NaN}, {"timestamp": 1578768195534, "ltp": 1.21, "tv": 4506.77, "trd": NaN, "batb": [[0, 1.2, 20]], "batl": NaN}, {"timestamp": 1578768196724, "ltp": 1.21, "tv": 4506.77, "trd": NaN, "batb": [[0, 1.2, 51.65]], "batl": [[0, 1.21, 31.65], [1, 1.22, 666], [2, 1.23, 487.43]]}, {"timestamp": 1578768198005, "ltp": 1.21, "tv": 4538.41, "trd": [[1.21, 4258.06]], "batb": NaN, "batl": [[0, 1.22, 666.02], [1, 1.23, 487.43], [2, 1.24, 438.52]]}, {"timestamp": 1578768198905, "ltp": 1.21, "tv": 4634.34, "trd": [[1.21, 4353.99]], "batb": NaN, "batl": [[0, 1.22, 666]]}, {"timestamp": 1578768201904, "ltp": 1.21, "tv": 4634.34, "trd": NaN, "batb": [[2, 1.18, 1892.37]], "batl": NaN}, {"timestamp": 1578768202927, "ltp": 1.21, "tv": 4634.34, "trd": NaN, "batb": [[2, 1.18, 1126.29]], "batl": NaN}, {"timestamp": 1578768204004, "ltp": 1.21, "tv": 4634.34, "trd": NaN, "batb": NaN, "batl": [[0, 1.21, 84.51], [1, 1.22, 666], [2, 1.23, 487.43]]}, {"timestamp": 1578768205015, "ltp": 1.21, "tv": 4634.34, "trd": NaN, "batb": [[0, 1.2, 20], [1, 1.19, 705.48]], "batl": NaN}, {"timestamp": 1578768229665, "ltp": 1.21, "tv": 4634.34, "trd": NaN, "batb": [[1, 1.19, 706.01]], "batl": NaN}, {"timestamp": 1578768256672, "ltp": 1.21, "tv": 4668.1, "trd": [[1.21, 4387.75]], "batb": [[1, 1.19, 280.41]], "batl": [[0, 1.21, 67.63]]}, {"timestamp": 1578768312996, "ltp": 1.21, "tv": 4668.1, "trd": NaN, "batb": [[2, 1.18, 1116.37]], "batl": NaN}, {"timestamp": 1578768411811, "ltp": 1.21, "tv": 4702.62, "trd": [[1.21, 4422.27]], "batb": NaN, "batl": [[0, 1.21, 50.37]]}, {"timestamp": 1578768471701, "ltp": 1.21, "tv": 4778.05, "trd": [[1.21, 4497.71]], "batb": NaN, "batl": [[0, 1.22, 666], [1, 1.23, 487.43], [2, 1.24, 435.2]]}, {"timestamp": 1578768472387, "ltp": 1.21, "tv": 4778.05, "trd": NaN, "batb": [[1, 1.19, 248.22]], "batl": NaN}, {"timestamp": 1578768474016, "ltp": 1.21, "tv": 4820.36, "trd": [[1.21, 4540.02]], "batb": NaN, "batl": NaN}, {"timestamp": 1578768479026, "ltp": 1.21, "tv": 4820.36, "trd": NaN, "batb": NaN, "batl": [[0, 1.21, 38.82], [1, 1.22, 666], [2, 1.23, 487.43]]}, {"timestamp": 1578768479924, "ltp": 1.21, "tv": 4859.17, "trd": [[1.21, 4578.83]], "batb": NaN, "batl": [[0, 1.22, 666], [1, 1.23, 487.43], [2, 1.24, 435.2]]}, {"timestamp": 1578768484495, "ltp": 1.21, "tv": 4892.36, "trd": [[1.21, 4612.02]], "batb": NaN, "batl": NaN}, {"timestamp": 1578768489810, "ltp": 1.21, "tv": 4921.43, "trd": [[1.21, 4641.09]], "batb": NaN, "batl": NaN}, {"timestamp": 1578768494905, "ltp": 1.21, "tv": 4946.35, "trd": [[1.21, 4666.01]], "batb": NaN, "batl": NaN}, {"timestamp": 1578768498533, "ltp": 1.21, "tv": 4946.35, "trd": NaN, "batb": [[0, 1.2, 51.92]], "batl": NaN}, {"timestamp": 1578768499913, "ltp": 1.21, "tv": 4946.35, "trd": NaN, "batb": NaN, "batl": [[0, 1.21, 21.9], [1, 1.22, 666], [2, 1.23, 487.43]]}, {"timestamp": 1578768500753, "ltp": 1.21, "tv": 4968.26, "trd": [[1.21, 4687.91]], "batb": NaN, "batl": [[0, 1.22, 666], [1, 1.23, 487.43], [2, 1.24, 435.2]]}, {"timestamp": 1578768502643, "ltp": 1.2, "tv": 5034.1, "trd": [[1.2, 65.84]], "batb": [[0, 1.2, 19]], "batl": NaN}, {"timestamp": 1578768505918, "ltp": 1.21, "tv": 5055.02, "trd": [[1.21, 4708.84]], "batb": NaN, "batl": NaN}, {"timestamp": 1578768511033, "ltp": 1.21, "tv": 5071.9, "trd": [[1.21, 4725.72]], "batb": NaN, "batl": NaN}, {"timestamp": 1578768511957, "ltp": 1.21, "tv": 5071.9, "trd": NaN, "batb": [[0, 1.2, 6.08]], "batl": NaN}, {"timestamp": 1578768515965, "ltp": 1.21, "tv": 5087.51, "trd": [[1.21, 4741.33]], "batb": NaN, "batl": NaN}, {"timestamp": 1578768520972, "ltp": 1.21, "tv": 5087.51, "trd": NaN, "batb": NaN, "batl": [[0, 1.21, 13.87], [1, 1.22, 666], [2, 1.23, 487.43]]}, {"timestamp": 1578768521757, "ltp": 1.21, "tv": 5101.38, "trd": [[1.21, 4755.2]], "batb": NaN, "batl": [[0, 1.22, 666], [1, 1.23, 487.43], [2, 1.24, 435.2]]}, {"timestamp": 1578768526973, "ltp": 1.21, "tv": 5112.58, "trd": [[1.21, 4766.39]], "batb": NaN, "batl": NaN}, {"timestamp": 1578768531870, "ltp": 1.21, "tv": 5123.04, "trd": [[1.21, 4776.86]], "batb": [[0, 1.2, 19]], "batl": NaN}, {"timestamp": 1578768536985, "ltp": 1.21, "tv": 5123.04, "trd": NaN, "batb": NaN, "batl": [[0, 1.21, 8.9], [1, 1.22, 666], [2, 1.23, 487.43]]}, {"timestamp": 1578768537672, "ltp": 1.21, "tv": 5131.94, "trd": [[1.21, 4785.76]], "batb": NaN, "batl": [[0, 1.22, 666], [1, 1.23, 487.43], [2, 1.24, 435.2]]}, {"timestamp": 1578768541965, "ltp": 1.21, "tv": 5131.94, "trd": NaN, "batb": NaN, "batl": [[0, 1.21, 7.6], [1, 1.22, 666], [2, 1.23, 487.43]]}, {"timestamp": 1578768542894, "ltp": 1.21, "tv": 5139.54, "trd": [[1.21, 4793.36]], "batb": NaN, "batl": [[0, 1.22, 666], [1, 1.23, 487.43], [2, 1.24, 435.2]]}, {"timestamp": 1578768547975, "ltp": 1.21, "tv": 5146.34, "trd": [[1.21, 4800.16]], "batb": NaN, "batl": NaN}, {"timestamp": 1578768552968, "ltp": 1.21, "tv": 5152.27, "trd": [[1.21, 4806.09]], "batb": NaN, "batl": NaN}, {"timestamp": 1578768557979, "ltp": 1.21, "tv": 5157.27, "trd": [[1.21, 4811.09]], "batb": NaN, "batl": NaN}, {"timestamp": 1578768563012, "ltp": 1.21, "tv": 5157.27, "trd": NaN, "batb": NaN, "batl": [[0, 1.21, 4.48], [1, 1.22, 666], [2, 1.23, 487.43]]}, {"timestamp": 1578768563796, "ltp": 1.21, "tv": 5161.75, "trd": [[1.21, 4815.57]], "batb": NaN, "batl": [[0, 1.22, 666], [1, 1.23, 487.43], [2, 1.24, 435.2]]}, {"timestamp": 1578768568395, "ltp": 1.21, "tv": 5165.5, "trd": [[1.21, 4819.31]], "batb": NaN, "batl": NaN}, {"timestamp": 1578768573696, "ltp": 1.21, "tv": 5169.01, "trd": [[1.21, 4822.83]], "batb": NaN, "batl": NaN}, {"timestamp": 1578768578810, "ltp": 1.21, "tv": 5171.91, "trd": [[1.21, 4825.72]], "batb": NaN, "batl": NaN}, {"timestamp": 1578768583936, "ltp": 1.21, "tv": 5171.91, "trd": NaN, "batb": NaN, "batl": [[0, 1.21, 2.55], [1, 1.22, 666], [2, 1.23, 487.43]]}, {"timestamp": 1578768585044, "ltp": 1.21, "tv": 5174.45, "trd": [[1.21, 4828.27]], "batb": NaN, "batl": [[0, 1.22, 666], [1, 1.23, 487.43], [2, 1.24, 435.2]]}, {"timestamp": 1578768589851, "ltp": 1.21, "tv": 5176.88, "trd": [[1.21, 4830.69]], "batb": NaN, "batl": NaN}, {"timestamp": 1578768594939, "ltp": 1.21, "tv": 5178.91, "trd": [[1.21, 4832.73]], "batb": NaN, "batl": NaN}, {"timestamp": 1578769029912, "ltp": 1.21, "tv": 5178.91, "trd": NaN, "batb": [[0, 1.19, 267.38], [1, 1.18, 1116.37], [2, 1.17, 2395.68]], "batl": NaN}, {"timestamp": 1578769051027, "ltp": 1.21, "tv": 5178.91, "trd": NaN, "batb": [[0, 1.19, 293.25]], "batl": [[0, 1.21, 25.45], [1, 1.22, 666], [2, 1.23, 487.43]]}, {"timestamp": 1578769051814, "ltp": 1.21, "tv": 5206.36, "trd": [[1.21, 4860.18]], "batb": NaN, "batl": [[0, 1.22, 666], [1, 1.23, 487.43], [2, 1.24, 435.2]]}, {"timestamp": 1578769165811, "ltp": 1.21, "tv": 5206.36, "trd": NaN, "batb": [[2, 1.17, 1895.68]], "batl": NaN}, {"timestamp": 1578769214947, "ltp": 1.21, "tv": 5206.5, "trd": [[1.2, 65.85], [1.21, 4860.23], [1.22, 114.74], [1.24, 7.73]], "batb": [[0, 1.19, 293.28]], "batl": [[0, 1.22, 666], [1, 1.23, 487.42], [2, 1.24, 435.2]]}, {"timestamp": 1578769300908, "ltp": 1.21, "tv": 5206.5, "trd": NaN, "batb": NaN, "batl": [[0, 1.22, 674]]}, {"timestamp": 1578769306003, "ltp": 1.21, "tv": 5206.5, "trd": NaN, "batb": [[0, 1.21, 15.31], [1, 1.19, 293.28], [2, 1.18, 1116.37]], "batl": NaN}, {"timestamp": 1578769315928, "ltp": 1.21, "tv": 5206.5, "trd": NaN, "batb": [[1, 1.2, 19.19], [2, 1.19, 274.09]], "batl": NaN}, {"timestamp": 1578769329972, "ltp": 1.21, "tv": 5206.5, "trd": NaN, "batb": [[1, 1.2, 19.03]], "batl": NaN}, {"timestamp": 1578769342795, "ltp": 1.21, "tv": 5237.1, "trd": [[1.21, 4890.82]], "batb": [[0, 1.2, 19.04], [1, 1.19, 274.09], [2, 1.18, 1116.37]], "batl": NaN}, {"timestamp": 1578769343964, "ltp": 1.21, "tv": 5237.11, "trd": [[1.21, 4890.84]], "batb": [[0, 1.2, 19.03]], "batl": NaN}, {"timestamp": 1578769381053, "ltp": 1.21, "tv": 5237.11, "trd": NaN, "batb": [[1, 1.19, 312.36], [2, 1.18, 1154.64]], "batl": NaN}, {"timestamp": 1578769383798, "ltp": 1.21, "tv": 5237.11, "trd": NaN, "batb": [[0, 1.2, 57.29]], "batl": NaN}, {"timestamp": 1578769548033, "ltp": 1.21, "tv": 5237.11, "trd": NaN, "batb": NaN, "batl": [[0, 1.21, 17], [1, 1.22, 674], [2, 1.23, 487.42]]}, {"timestamp": 1578769577970, "ltp": 1.21, "tv": 5237.11, "trd": NaN, "batb": [[0, 1.2, 19.03]], "batl": NaN}, {"timestamp": 1578769823955, "ltp": 1.21, "tv": 5253.63, "trd": [[1.21, 4907.36]], "batb": NaN, "batl": [[0, 1.21, 8.74]]}, {"timestamp": 1578769835965, "ltp": 1.21, "tv": 5271.01, "trd": [[1.21, 4924.74]], "batb": NaN, "batl": [[0, 1.22, 674.05], [1, 1.23, 487.42], [2, 1.24, 435.2]]}, {"timestamp": 1578769847997, "ltp": 1.21, "tv": 5271.11, "trd": [[1.21, 4924.84]], "batb": [[0, 1.21, 446.83], [1, 1.2, 19.03], [2, 1.19, 312.36]], "batl": [[0, 1.22, 674]]}, {"timestamp": 1578769851017, "ltp": 1.21, "tv": 5271.11, "trd": NaN, "batb": [[1, 1.2, 316.95]], "batl": NaN}, {"timestamp": 1578769854010, "ltp": 1.21, "tv": 5271.11, "trd": NaN, "batb": [[0, 1.21, 465.86], [1, 1.2, 297.92]], "batl": NaN}, {"timestamp": 1578769868014, "ltp": 1.21, "tv": 5271.11, "trd": NaN, "batb": [[0, 1.21, 465.7]], "batl": NaN}, {"timestamp": 1578769871989, "ltp": 1.22, "tv": 6164.78, "trd": [[1.22, 1008.41]], "batb": [[0, 1.21, 18.87]], "batl": [[0, 1.22, 227.16]]}, {"timestamp": 1578769872943, "ltp": 1.22, "tv": 6164.78, "trd": NaN, "batb": [[0, 1.2, 367.04], [1, 1.19, 312.36], [2, 1.18, 1154.64]], "batl": NaN}, {"timestamp": 1578769874018, "ltp": 1.22, "tv": 6164.78, "trd": NaN, "batb": [[0, 1.2, 69.12]], "batl": [[0, 1.22, 58]]}, {"timestamp": 1578769894036, "ltp": 1.22, "tv": 6164.78, "trd": NaN, "batb": [[0, 1.2, 69.28]], "batl": NaN}, {"timestamp": 1578769900034, "ltp": 1.22, "tv": 6164.78, "trd": NaN, "batb": NaN, "batl": [[0, 1.22, 66]]}, {"timestamp": 1578769971901, "ltp": 1.22, "tv": 6164.78, "trd": NaN, "batb": [[0, 1.21, 300], [1, 1.2, 69.28], [2, 1.19, 312.36]], "batl": NaN}, {"timestamp": 1578769972881, "ltp": 1.22, "tv": 6164.78, "trd": NaN, "batb": [[1, 1.2, 367.2]], "batl": NaN}, {"timestamp": 1578769976797, "ltp": 1.22, "tv": 6164.78, "trd": NaN, "batb": [[0, 1.21, 318.87], [1, 1.2, 348.17]], "batl": NaN}, {"timestamp": 1578770001932, "ltp": 1.22, "tv": 6164.78, "trd": NaN, "batb": [[0, 1.21, 614.33]], "batl": NaN}, {"timestamp": 1578770004948, "ltp": 1.21, "tv": 6218.28, "trd": [[1.21, 4978.34]], "batb": [[0, 1.21, 587.58]], "batl": NaN}, {"timestamp": 1578770060051, "ltp": 1.22, "tv": 6284.28, "trd": [[1.22, 1074.41]], "batb": [[0, 1.21, 693.67]], "batl": [[0, 1.23, 487.42], [1, 1.24, 435.2], [2, 1.25, 186.99]]}, {"timestamp": 1578770060210, "ltp": 1.22, "tv": 6284.28, "trd": NaN, "batb": [[0, 1.21, 718.67]], "batl": NaN}, {"timestamp": 1578770082049, "ltp": 1.22, "tv": 6284.28, "trd": NaN, "batb": [[2, 1.19, 737.96]], "batl": NaN}, {"timestamp": 1578770087851, "ltp": 1.22, "tv": 6284.28, "trd": NaN, "batb": [[1, 1.2, 730.85]], "batl": NaN}, {"timestamp": 1578770093023, "ltp": 1.22, "tv": 6284.28, "trd": NaN, "batb": [[1, 1.2, 348.17]], "batl": NaN}, {"timestamp": 1578770157834, "ltp": 1.23, "tv": 6292.79, "trd": [[1.23, 166.47]], "batb": NaN, "batl": [[0, 1.23, 483.17]]}, {"timestamp": 1578770186019, "ltp": 1.23, "tv": 6292.79, "trd": NaN, "batb": [[0, 1.22, 382.67], [1, 1.21, 718.67], [2, 1.2, 348.17]], "batl": NaN}, {"timestamp": 1578770195926, "ltp": 1.23, "tv": 6292.79, "trd": NaN, "batb": NaN, "batl": [[2, 1.25, 318.29]]}, {"timestamp": 1578770196990, "ltp": 1.23, "tv": 6292.79, "trd": NaN, "batb": [[0, 1.22, 401.54], [1, 1.21, 699.8]], "batl": NaN}, {"timestamp": 1578770206005, "ltp": 1.23, "tv": 6292.79, "trd": NaN, "batb": [[0, 1.22, 401.39]], "batl": [[2, 1.25, 323.73]]}, {"timestamp": 1578770220056, "ltp": 1.23, "tv": 6292.79, "trd": NaN, "batb": NaN, "batl": [[2, 1.25, 186.99]]}, {"timestamp": 1578770221027, "ltp": 1.23, "tv": 6292.79, "trd": NaN, "batb": NaN, "batl": [[2, 1.25, 314.77]]}, {"timestamp": 1578770223965, "ltp": 1.23, "tv": 6292.79, "trd": NaN, "batb": [[1, 1.21, 701.66]], "batl": NaN}, {"timestamp": 1578770225033, "ltp": 1.22, "tv": 7095.57, "trd": [[1.22, 1877.19]], "batb": [[0, 1.21, 701.66], [1, 1.2, 348.17], [2, 1.19, 737.96]], "batl": [[0, 1.22, 57.41], [1, 1.23, 483.17], [2, 1.24, 435.2]]}, {"timestamp": 1578770236050, "ltp": 1.22, "tv": 7095.57, "trd": NaN, "batb": [[0, 1.21, 714.5]], "batl": NaN}, {"timestamp": 1578770251807, "ltp": 1.22, "tv": 7095.57, "trd": NaN, "batb": [[0, 1.21, 733.37]], "batl": NaN}, {"timestamp": 1578770261900, "ltp": 1.22, "tv": 7095.57, "trd": NaN, "batb": [[0, 1.21, 1135.14]], "batl": [[0, 1.22, 89.12]]}, {"timestamp": 1578770263019, "ltp": 1.22, "tv": 7095.57, "trd": NaN, "batb": [[0, 1.21, 1499.59]], "batl": NaN}, {"timestamp": 1578770266007, "ltp": 1.22, "tv": 7095.57, "trd": NaN, "batb": [[1, 1.2, 773.78]], "batl": NaN}, {"timestamp": 1578770274701, "ltp": 1.22, "tv": 7095.57, "trd": NaN, "batb": [[2, 1.19, 1029.56]], "batl": NaN}, {"timestamp": 1578770304034, "ltp": 1.21, "tv": 7623.97, "trd": [[1.21, 5506.74]], "batb": [[0, 1.21, 1235.39]], "batl": [[2, 1.24, 437.49]]}, {"timestamp": 1578770317043, "ltp": 1.21, "tv": 7729.65, "trd": [[1.21, 5612.41]], "batb": [[0, 1.21, 1182.55]], "batl": NaN}, {"timestamp": 1578770319981, "ltp": 1.21, "tv": 7729.65, "trd": NaN, "batb": NaN, "batl": [[2, 1.24, 435.2]]}, {"timestamp": 1578770357990, "ltp": 1.21, "tv": 7729.65, "trd": NaN, "batb": NaN, "batl": [[0, 1.22, 57.41]]}, {"timestamp": 1578770442016, "ltp": 1.22, "tv": 7729.68, "trd": [[1.22, 1877.22]], "batb": NaN, "batl": [[0, 1.22, 57.4]]}, {"timestamp": 1578770448580, "ltp": 1.22, "tv": 7729.68, "trd": NaN, "batb": [[1, 1.2, 1199.38]], "batl": NaN}, {"timestamp": 1578770454013, "ltp": 1.22, "tv": 7844.48, "trd": [[1.22, 1992.02]], "batb": [[0, 1.22, 54.11], [1, 1.21, 1182.55], [2, 1.2, 1199.38]], "batl": [[0, 1.23, 483.17], [1, 1.24, 435.2], [2, 1.25, 186.99]]}, {"timestamp": 1578770456502, "ltp": 1.22, "tv": 7844.48, "trd": NaN, "batb": NaN, "batl": [[0, 1.23, 816.17]]}, {"timestamp": 1578770457695, "ltp": 1.22, "tv": 7844.48, "trd": NaN, "batb": [[0, 1.22, 85.82], [1, 1.21, 1150.85]], "batl": NaN}, {"timestamp": 1578770462005, "ltp": 1.22, "tv": 7859.12, "trd": [[1.22, 2006.66]], "batb": [[0, 1.22, 78.5]], "batl": [[1, 1.24, 768.2]]}, {"timestamp": 1578770473040, "ltp": 1.22, "tv": 7859.12, "trd": NaN, "batb": NaN, "batl": [[2, 1.25, 324.13]]}, {"timestamp": 1578770500956, "ltp": 1.22, "tv": 7859.12, "trd": NaN, "batb": [[0, 1.22, 86.5]], "batl": [[2, 1.25, 309.97]]}, {"timestamp": 1578770521053, "ltp": 1.22, "tv": 7859.12, "trd": NaN, "batb": NaN, "batl": [[2, 1.25, 186.99]]}, {"timestamp": 1578770571053, "ltp": 1.22, "tv": 7859.12, "trd": NaN, "batb": [[1, 1.21, 1321.09]], "batl": NaN}, {"timestamp": 1578770573036, "ltp": 1.22, "tv": 7859.12, "trd": NaN, "batb": [[1, 1.21, 1491.33]], "batl": NaN}, {"timestamp": 1578770576612, "ltp": 1.22, "tv": 7875.07, "trd": [[1.22, 2022.61]], "batb": [[0, 1.22, 78.52]], "batl": NaN}, {"timestamp": 1578770585979, "ltp": 1.22, "tv": 7879.07, "trd": [[1.22, 2026.61]], "batb": [[0, 1.22, 76.52]], "batl": NaN}, {"timestamp": 1578770619031, "ltp": 1.22, "tv": 7879.07, "trd": NaN, "batb": NaN, "batl": [[2, 1.25, 333.09]]}, {"timestamp": 1578770630004, "ltp": 1.22, "tv": 7879.07, "trd": NaN, "batb": NaN, "batl": [[2, 1.25, 315.21]]}, {"timestamp": 1578770653032, "ltp": 1.22, "tv": 7879.07, "trd": NaN, "batb": NaN, "batl": [[2, 1.25, 325.57]]}, {"timestamp": 1578770660970, "ltp": 1.22, "tv": 7879.07, "trd": NaN, "batb": NaN, "batl": [[0, 1.23, 667.67]]}, {"timestamp": 1578770707000, "ltp": 1.22, "tv": 7888.25, "trd": [[1.22, 2035.79]], "batb": [[0, 1.22, 71.93]], "batl": NaN}, {"timestamp": 1578770725017, "ltp": 1.22, "tv": 7888.25, "trd": NaN, "batb": NaN, "batl": [[1, 1.24, 758.2], [2, 1.25, 335.57]]}, {"timestamp": 1578770756031, "ltp": 1.22, "tv": 8032.38, "trd": [[1.22, 2179.92]], "batb": [[0, 1.21, 1491.33], [1, 1.2, 1213.79], [2, 1.19, 1029.56]], "batl": [[0, 1.22, 57.59], [1, 1.23, 675.67], [2, 1.24, 758.2]]}, {"timestamp": 1578770759040, "ltp": 1.22, "tv": 8032.38, "trd": NaN, "batb": NaN, "batl": [[1, 1.23, 707.37]]}, {"timestamp": 1578770786971, "ltp": 1.22, "tv": 8032.38, "trd": NaN, "batb": [[1, 1.2, 1209.38]], "batl": NaN}, {"timestamp": 1578770788972, "ltp": 1.22, "tv": 8032.38, "trd": NaN, "batb": [[0, 1.21, 1523.03]], "batl": NaN}, {"timestamp": 1578770795968, "ltp": 1.22, "tv": 8036.38, "trd": [[1.22, 2183.92]], "batb": NaN, "batl": [[0, 1.22, 55.59]]}, {"timestamp": 1578770808013, "ltp": 1.21, "tv": 8112.92, "trd": [[1.21, 5688.95]], "batb": [[0, 1.21, 1484.76]], "batl": NaN}, {"timestamp": 1578770846054, "ltp": 1.21, "tv": 8112.92, "trd": NaN, "batb": NaN, "batl": [[1, 1.23, 844.87]]}, {"timestamp": 1578770862976, "ltp": 1.21, "tv": 8112.92, "trd": NaN, "batb": NaN, "batl": [[0, 1.22, 87.3], [1, 1.23, 813.17]]}, {"timestamp": 1578770863981, "ltp": 1.21, "tv": 8112.92, "trd": NaN, "batb": NaN, "batl": [[0, 1.22, 55.59], [1, 1.23, 844.87]]}, {"timestamp": 1578770880008, "ltp": 1.21, "tv": 8112.92, "trd": NaN, "batb": [[0, 1.21, 1314.52]], "batl": NaN}, {"timestamp": 1578770883991, "ltp": 1.21, "tv": 8112.92, "trd": NaN, "batb": NaN, "batl": [[0, 1.22, 87.3], [1, 1.23, 813.17]]}, {"timestamp": 1578770885994, "ltp": 1.21, "tv": 8419.06, "trd": [[1.21, 5995.09]], "batb": [[0, 1.21, 1161.45], [1, 1.2, 1229.99]], "batl": NaN}, {"timestamp": 1578770910032, "ltp": 1.21, "tv": 8419.06, "trd": NaN, "batb": NaN, "batl": [[0, 1.22, 420.3]]}, {"timestamp": 1578770912039, "ltp": 1.21, "tv": 8419.06, "trd": NaN, "batb": NaN, "batl": [[0, 1.22, 627.85]]}, {"timestamp": 1578770917018, "ltp": 1.21, "tv": 8419.06, "trd": NaN, "batb": [[1, 1.2, 1209.38]], "batl": NaN}, {"timestamp": 1578770925038, "ltp": 1.21, "tv": 8450.83, "trd": [[1.21, 6026.86]], "batb": [[0, 1.21, 1145.57]], "batl": NaN}, {"timestamp": 1578770946976, "ltp": 1.21, "tv": 8525.57, "trd": [[1.21, 6101.6]], "batb": [[0, 1.21, 1108.2]], "batl": NaN}, {"timestamp": 1578770953979, "ltp": 1.21, "tv": 8530.16, "trd": [[1.21, 6106.2]], "batb": [[0, 1.21, 1105.9]], "batl": [[0, 1.22, 687.44]]}, {"timestamp": 1578770960977, "ltp": 1.21, "tv": 8530.16, "trd": NaN, "batb": [[0, 1.21, 741.45]], "batl": NaN}, {"timestamp": 1578770963992, "ltp": 1.21, "tv": 8530.16, "trd": NaN, "batb": [[1, 1.2, 1592.05]], "batl": NaN}, {"timestamp": 1578770995032, "ltp": 1.22, "tv": 8550.17, "trd": [[1.22, 2203.92]], "batb": NaN, "batl": [[0, 1.22, 677.44]]}, {"timestamp": 1578770998940, "ltp": 1.22, "tv": 8577.64, "trd": [[1.22, 2231.4]], "batb": NaN, "batl": [[0, 1.22, 663.7]]}, {"timestamp": 1578771006988, "ltp": 1.22, "tv": 8577.64, "trd": NaN, "batb": [[0, 1.21, 635.05]], "batl": NaN}, {"timestamp": 1578771013973, "ltp": 1.22, "tv": 8577.64, "trd": NaN, "batb": [[2, 1.19, 1197.56]], "batl": [[2, 1.24, 919.2]]}, {"timestamp": 1578771022034, "ltp": 1.22, "tv": 8577.64, "trd": NaN, "batb": [[0, 1.21, 735.05]], "batl": NaN}, {"timestamp": 1578771044949, "ltp": 1.22, "tv": 8577.64, "trd": NaN, "batb": NaN, "batl": [[0, 1.22, 677.08]]}, {"timestamp": 1578771060991, "ltp": 1.21, "tv": 8583.21, "trd": [[1.21, 6111.76]], "batb": [[0, 1.21, 732.27]], "batl": NaN}, {"timestamp": 1578771097029, "ltp": 1.21, "tv": 9183.21, "trd": [[1.21, 6711.76]], "batb": [[0, 1.21, 432.27], [1, 1.2, 1581.8], [2, 1.19, 1171.69]], "batl": [[0, 1.22, 725.53]]}, {"timestamp": 1578771098946, "ltp": 1.21, "tv": 9183.21, "trd": NaN, "batb": NaN, "batl": [[0, 1.22, 815.53]]}, {"timestamp": 1578771108965, "ltp": 1.21, "tv": 9183.21, "trd": NaN, "batb": [[0, 1.21, 717.91]], "batl": NaN}, {"timestamp": 1578771126987, "ltp": 1.21, "tv": 9183.21, "trd": NaN, "batb": [[1, 1.2, 1541.8]], "batl": NaN}, {"timestamp": 1578771172985, "ltp": 1.21, "tv": 9183.21, "trd": NaN, "batb": NaN, "batl": [[0, 1.22, 802.15]]}, {"timestamp": 1578771180006, "ltp": 1.21, "tv": 9183.21, "trd": NaN, "batb": [[0, 1.21, 696.82]], "batl": NaN}, {"timestamp": 1578771208964, "ltp": 1.21, "tv": 9183.21, "trd": NaN, "batb": [[0, 1.21, 795.19]], "batl": NaN}, {"timestamp": 1578771215972, "ltp": 1.21, "tv": 9210.0, "trd": [[1.21, 6738.55]], "batb": [[0, 1.21, 781.8]], "batl": NaN}, {"timestamp": 1578771236999, "ltp": 1.21, "tv": 9218.51, "trd": [[1.21, 6747.06]], "batb": [[0, 1.21, 777.54]], "batl": NaN}, {"timestamp": 1578771240801, "ltp": 1.21, "tv": 9218.51, "trd": NaN, "batb": [[0, 1.21, 871.23]], "batl": NaN}, {"timestamp": 1578771261960, "ltp": 1.21, "tv": 9429.22, "trd": [[1.21, 6957.77]], "batb": [[0, 1.21, 765.87], [1, 1.2, 1553.72]], "batl": NaN}, {"timestamp": 1578771263033, "ltp": 1.21, "tv": 9429.22, "trd": NaN, "batb": [[0, 1.21, 902.25]], "batl": NaN}, {"timestamp": 1578771268055, "ltp": 1.21, "tv": 9429.22, "trd": NaN, "batb": [[1, 1.2, 1552.87]], "batl": NaN}, {"timestamp": 1578771269959, "ltp": 1.21, "tv": 9429.22, "trd": NaN, "batb": NaN, "batl": [[1, 1.23, 976.17]]}, {"timestamp": 1578771273974, "ltp": 1.21, "tv": 9697.09, "trd": [[1.21, 7225.64]], "batb": [[0, 1.21, 768.31], [1, 1.2, 1579.66]], "batl": NaN}, {"timestamp": 1578771280982, "ltp": 1.21, "tv": 9697.09, "trd": NaN, "batb": NaN, "batl": [[0, 1.22, 712.15], [1, 1.23, 968.17]]}, {"timestamp": 1578771282897, "ltp": 1.22, "tv": 9711.09, "trd": [[1.22, 2245.4]], "batb": NaN, "batl": [[0, 1.22, 705.15]]}, {"timestamp": 1578771284911, "ltp": 1.22, "tv": 9711.09, "trd": NaN, "batb": [[0, 1.21, 631.94]], "batl": NaN}, {"timestamp": 1578771286988, "ltp": 1.22, "tv": 9711.09, "trd": NaN, "batb": [[0, 1.21, 538.25]], "batl": NaN}, {"timestamp": 1578771289011, "ltp": 1.22, "tv": 9711.09, "trd": NaN, "batb": [[0, 1.21, 488.77]], "batl": NaN}, {"timestamp": 1578771290002, "ltp": 1.22, "tv": 9711.09, "trd": NaN, "batb": [[0, 1.21, 203.13]], "batl": NaN}, {"timestamp": 1578771291991, "ltp": 1.22, "tv": 9711.09, "trd": NaN, "batb": [[1, 1.2, 1552.87]], "batl": NaN}, {"timestamp": 1578771292990, "ltp": 1.22, "tv": 9711.09, "trd": NaN, "batb": [[1, 1.2, 1559.99]], "batl": NaN}, {"timestamp": 1578771297991, "ltp": 1.22, "tv": 9711.09, "trd": NaN, "batb": NaN, "batl": [[0, 1.22, 709.15]]}, {"timestamp": 1578771298577, "ltp": 1.22, "tv": 9711.09, "trd": NaN, "batb": [[0, 1.21, 192.51]], "batl": NaN}, {"timestamp": 1578771301006, "ltp": 1.21, "tv": 10096.12, "trd": [[1.21, 7610.67]], "batb": [[0, 1.2, 1885.49], [1, 1.19, 1171.69], [2, 1.18, 1898.53]], "batl": [[0, 1.21, 477.41], [1, 1.22, 709.15], [2, 1.23, 968.17]]}, {"timestamp": 1578771302014, "ltp": 1.21, "tv": 10096.12, "trd": NaN, "batb": [[0, 1.2, 2828.3]], "batl": NaN}, {"timestamp": 1578771304012, "ltp": 1.21, "tv": 10096.12, "trd": NaN, "batb": [[0, 1.2, 1611.97]], "batl": NaN}, {"timestamp": 1578771305023, "ltp": 1.21, "tv": 10096.12, "trd": NaN, "batb": [[0, 1.2, 1601.86]], "batl": [[0, 1.21, 509.11], [1, 1.22, 677.45]]}, {"timestamp": 1578771305993, "ltp": 1.21, "tv": 10096.12, "trd": NaN, "batb": NaN, "batl": [[1, 1.22, 617.86]]}, {"timestamp": 1578771306898, "ltp": 1.21, "tv": 10096.12, "trd": NaN, "batb": [[0, 1.2, 1601.84]], "batl": NaN}, {"timestamp": 1578771309020, "ltp": 1.21, "tv": 10096.12, "trd": NaN, "batb": [[0, 1.2, 1601.82]], "batl": NaN}, {"timestamp": 1578771310022, "ltp": 1.21, "tv": 10279.8, "trd": [[1.21, 7794.35]], "batb": [[0, 1.2, 1611.92]], "batl": [[0, 1.21, 417.27]]}, {"timestamp": 1578771314029, "ltp": 1.21, "tv": 10279.8, "trd": NaN, "batb": [[2, 1.18, 2664.61]], "batl": NaN}, {"timestamp": 1578771315027, "ltp": 1.21, "tv": 10279.8, "trd": NaN, "batb": [[1, 1.19, 1937.78]], "batl": NaN}, {"timestamp": 1578771316962, "ltp": 1.21, "tv": 10279.8, "trd": NaN, "batb": NaN, "batl": [[0, 1.21, 417.54]]}, {"timestamp": 1578771317856, "ltp": 1.21, "tv": 10479.8, "trd": [[1.21, 7994.35]], "batb": NaN, "batl": [[0, 1.21, 317.54]]}, {"timestamp": 1578771322042, "ltp": 1.21, "tv": 10489.56, "trd": [[1.21, 8004.11]], "batb": NaN, "batl": [[0, 1.21, 312.66]]}, {"timestamp": 1578771329933, "ltp": 1.21, "tv": 10489.56, "trd": NaN, "batb": NaN, "batl": [[0, 1.21, 510]]}, {"timestamp": 1578771331037, "ltp": 1.21, "tv": 10489.56, "trd": NaN, "batb": [[0, 1.2, 1601.26]], "batl": NaN}, {"timestamp": 1578771334963, "ltp": 1.21, "tv": 10489.56, "trd": NaN, "batb": [[0, 1.2, 1768.26]], "batl": [[2, 1.23, 805.17]]}, {"timestamp": 1578771339960, "ltp": 1.21, "tv": 10489.56, "trd": NaN, "batb": [[0, 1.2, 1749.9]], "batl": NaN}, {"timestamp": 1578771343047, "ltp": 1.21, "tv": 10569.56, "trd": [[1.21, 8084.11]], "batb": [[0, 1.2, 1757.9]], "batl": [[0, 1.21, 470]]}, {"timestamp": 1578771343985, "ltp": 1.21, "tv": 10569.56, "trd": NaN, "batb": [[0, 1.2, 1590.9]], "batl": NaN}, {"timestamp": 1578771345991, "ltp": 1.21, "tv": 10725.56, "trd": [[1.21, 8240.11]], "batb": [[0, 1.2, 1606.5]], "batl": [[0, 1.21, 392]]}, {"timestamp": 1578771346891, "ltp": 1.21, "tv": 10725.56, "trd": NaN, "batb": NaN, "batl": [[0, 1.21, 642]]}, {"timestamp": 1578771348962, "ltp": 1.21, "tv": 10725.56, "trd": NaN, "batb": [[0, 1.2, 1586.5]], "batl": NaN}, {"timestamp": 1578771352975, "ltp": 1.21, "tv": 10725.56, "trd": NaN, "batb": [[0, 1.2, 1585.52]], "batl": NaN}, {"timestamp": 1578771357994, "ltp": 1.21, "tv": 10725.56, "trd": NaN, "batb": [[0, 1.2, 1980.76]], "batl": NaN}, {"timestamp": 1578771365905, "ltp": 1.21, "tv": 10725.56, "trd": NaN, "batb": [[0, 1.2, 2193.57]], "batl": NaN}, {"timestamp": 1578771372987, "ltp": 1.21, "tv": 10725.56, "trd": NaN, "batb": [[0, 1.2, 2185.57]], "batl": NaN}, {"timestamp": 1578771375994, "ltp": 1.21, "tv": 10725.56, "trd": NaN, "batb": [[0, 1.2, 2179.97], [2, 1.18, 2681.64]], "batl": NaN}, {"timestamp": 1578771398052, "ltp": 1.21, "tv": 10725.56, "trd": NaN, "batb": [[0, 1.2, 1795.63]], "batl": NaN}, {"timestamp": 1578771434002, "ltp": 1.21, "tv": 10725.56, "trd": NaN, "batb": [[0, 1.2, 2511.12]], "batl": NaN}, {"timestamp": 1578771443026, "ltp": 1.21, "tv": 10725.56, "trd": NaN, "batb": NaN, "batl": [[2, 1.23, 968.17]]}, {"timestamp": 1578771454923, "ltp": 1.21, "tv": 10725.56, "trd": NaN, "batb": NaN, "batl": [[2, 1.23, 805.17]]}, {"timestamp": 1578771466021, "ltp": 1.2, "tv": 10752.69, "trd": [[1.2, 92.98]], "batb": [[0, 1.2, 2497.55]], "batl": NaN}, {"timestamp": 1578771467031, "ltp": 1.2, "tv": 10752.69, "trd": NaN, "batb": [[0, 1.2, 2374.91]], "batl": NaN}, {"timestamp": 1578771490987, "ltp": 1.21, "tv": 10768.0, "trd": [[1.21, 8255.41]], "batb": NaN, "batl": [[0, 1.21, 634.35]]}, {"timestamp": 1578771509881, "ltp": 1.2, "tv": 11303.73, "trd": [[1.2, 628.72]], "batb": [[0, 1.2, 2147.04]], "batl": NaN}, {"timestamp": 1578771512898, "ltp": 1.2, "tv": 11387.92, "trd": [[1.2, 712.91]], "batb": [[0, 1.2, 2104.95]], "batl": NaN}, {"timestamp": 1578771515003, "ltp": 1.2, "tv": 11387.92, "trd": NaN, "batb": [[0, 1.2, 2402.87]], "batl": NaN}, {"timestamp": 1578771523954, "ltp": 1.2, "tv": 11387.92, "trd": NaN, "batb": [[0, 1.2, 2352.87], [1, 1.19, 1987.78]], "batl": NaN}, {"timestamp": 1578771530054, "ltp": 1.2, "tv": 11387.92, "trd": NaN, "batb": NaN, "batl": [[2, 1.23, 968.17]]}, {"timestamp": 1578771530956, "ltp": 1.21, "tv": 11391.92, "trd": [[1.21, 8259.41]], "batb": NaN, "batl": [[0, 1.21, 632.35]]}, {"timestamp": 1578771537963, "ltp": 1.21, "tv": 11391.92, "trd": NaN, "batb": NaN, "batl": [[0, 1.21, 635.35]]}, {"timestamp": 1578771539039, "ltp": 1.2, "tv": 11456.61, "trd": [[1.2, 777.6]], "batb": [[0, 1.2, 2320.53]], "batl": NaN}, {"timestamp": 1578771541050, "ltp": 1.2, "tv": 11456.61, "trd": NaN, "batb": [[1, 1.19, 1952.3]], "batl": NaN}, {"timestamp": 1578771543965, "ltp": 1.2, "tv": 11456.61, "trd": NaN, "batb": [[1, 1.19, 1947.78]], "batl": NaN}, {"timestamp": 1578771547994, "ltp": 1.2, "tv": 11686.22, "trd": [[1.2, 1007.2]], "batb": [[0, 1.2, 2205.72], [1, 1.19, 1966.12]], "batl": NaN}, {"timestamp": 1578771561963, "ltp": 1.2, "tv": 11686.22, "trd": NaN, "batb": [[1, 1.19, 1965.74]], "batl": NaN}, {"timestamp": 1578771569988, "ltp": 1.2, "tv": 11686.22, "trd": NaN, "batb": [[1, 1.19, 1959.59]], "batl": NaN}, {"timestamp": 1578771578991, "ltp": 1.2, "tv": 11686.22, "trd": NaN, "batb": [[1, 1.19, 1947.78]], "batl": NaN}, {"timestamp": 1578771600017, "ltp": 1.2, "tv": 11686.22, "trd": NaN, "batb": NaN, "batl": [[2, 1.23, 805.17]]}, {"timestamp": 1578771603027, "ltp": 1.2, "tv": 11686.22, "trd": NaN, "batb": NaN, "batl": [[0, 1.21, 783.2]]}, {"timestamp": 1578771605856, "ltp": 1.2, "tv": 11686.22, "trd": NaN, "batb": NaN, "batl": [[0, 1.21, 796.02]]}, {"timestamp": 1578771607046, "ltp": 1.2, "tv": 11686.22, "trd": NaN, "batb": NaN, "batl": [[2, 1.23, 968.17]]}, {"timestamp": 1578771616050, "ltp": 1.2, "tv": 11686.22, "trd": NaN, "batb": NaN, "batl": [[0, 1.21, 796.93]]}, {"timestamp": 1578771635973, "ltp": 1.2, "tv": 11686.22, "trd": NaN, "batb": NaN, "batl": [[2, 1.23, 805.17]]}, {"timestamp": 1578771644966, "ltp": 1.2, "tv": 11686.22, "trd": NaN, "batb": NaN, "batl": [[2, 1.23, 968.17]]}, {"timestamp": 1578771672920, "ltp": 1.2, "tv": 11686.22, "trd": NaN, "batb": NaN, "batl": [[2, 1.23, 805.17]]}, {"timestamp": 1578771675046, "ltp": 1.2, "tv": 11686.22, "trd": NaN, "batb": NaN, "batl": [[2, 1.23, 968.17]]}, {"timestamp": 1578771676985, "ltp": 1.2, "tv": 11686.22, "trd": NaN, "batb": NaN, "batl": [[2, 1.23, 805.17]]}, {"timestamp": 1578771692029, "ltp": 1.21, "tv": 11762.22, "trd": [[1.21, 8335.41]], "batb": NaN, "batl": [[0, 1.21, 758.93]]}, {"timestamp": 1578771695025, "ltp": 1.21, "tv": 11862.22, "trd": [[1.21, 8435.41]], "batb": [[1, 1.19, 1954.5]], "batl": [[0, 1.21, 708.93]]}, {"timestamp": 1578771696041, "ltp": 1.21, "tv": 11862.22, "trd": NaN, "batb": [[1, 1.19, 1786.5]], "batl": [[2, 1.23, 968.17]]}, {"timestamp": 1578771704035, "ltp": 1.21, "tv": 11862.22, "trd": NaN, "batb": [[1, 1.19, 1954.5]], "batl": NaN}, {"timestamp": 1578771720963, "ltp": 1.21, "tv": 11862.22, "trd": NaN, "batb": NaN, "batl": [[0, 1.21, 561.08]]}, {"timestamp": 1578771721962, "ltp": 1.21, "tv": 11862.22, "trd": NaN, "batb": [[0, 1.2, 2189.8]], "batl": NaN}, {"timestamp": 1578771722971, "ltp": 1.21, "tv": 11862.22, "trd": NaN, "batb": [[1, 1.19, 1947.78]], "batl": NaN}, {"timestamp": 1578771725981, "ltp": 1.21, "tv": 11862.22, "trd": NaN, "batb": [[0, 1.2, 2050.85]], "batl": NaN}, {"timestamp": 1578771727049, "ltp": 1.21, "tv": 11862.22, "trd": NaN, "batb": [[1, 1.19, 1779.78]], "batl": NaN}, {"timestamp": 1578771765029, "ltp": 1.21, "tv": 11862.22, "trd": NaN, "batb": NaN, "batl": [[0, 1.21, 894.08]]}, {"timestamp": 1578771775032, "ltp": 1.2, "tv": 12972.22, "trd": [[1.2, 2117.21]], "batb": [[0, 1.2, 1495.84], [1, 1.19, 1819.78]], "batl": NaN}, {"timestamp": 1578771776038, "ltp": 1.2, "tv": 12972.22, "trd": NaN, "batb": [[0, 1.2, 1370.77]], "batl": NaN}, {"timestamp": 1578771781022, "ltp": 1.2, "tv": 12972.22, "trd": NaN, "batb": NaN, "batl": [[0, 1.21, 946.16]]}, {"timestamp": 1578771782040, "ltp": 1.2, "tv": 12972.22, "trd": NaN, "batb": [[0, 1.2, 772.2], [1, 1.19, 2041.78]], "batl": NaN}, {"timestamp": 1578771783044, "ltp": 1.2, "tv": 12972.22, "trd": NaN, "batb": [[0, 1.2, 769.71]], "batl": NaN}, {"timestamp": 1578771789047, "ltp": 1.2, "tv": 12972.22, "trd": NaN, "batb": [[2, 1.18, 2792.64]], "batl": NaN}, {"timestamp": 1578771797953, "ltp": 1.2, "tv": 12972.22, "trd": NaN, "batb": [[0, 1.2, 718.93]], "batl": NaN}, {"timestamp": 1578771801041, "ltp": 1.2, "tv": 12972.22, "trd": NaN, "batb": [[0, 1.2, 729.54]], "batl": NaN}, {"timestamp": 1578771804972, "ltp": 1.2, "tv": 12972.22, "trd": NaN, "batb": [[1, 1.19, 2001.78]], "batl": NaN}, {"timestamp": 1578771815000, "ltp": 1.2, "tv": 12972.22, "trd": NaN, "batb": NaN, "batl": [[0, 1.21, 696.16]]}, {"timestamp": 1578771829016, "ltp": 1.2, "tv": 12972.22, "trd": NaN, "batb": NaN, "batl": [[0, 1.21, 644.08], [1, 1.22, 569.41]]}, {"timestamp": 1578771836044, "ltp": 1.2, "tv": 16703.76, "trd": [[1.2, 5848.75]], "batb": [[0, 1.19, 2041.78], [1, 1.18, 2792.64], [2, 1.17, 2769.74]], "batl": NaN}, {"timestamp": 1578771837003, "ltp": 1.2, "tv": 16703.76, "trd": NaN, "batb": NaN, "batl": [[0, 1.21, 1023.6]]}, {"timestamp": 1578771838004, "ltp": 1.2, "tv": 16703.76, "trd": NaN, "batb": [[0, 1.2, 5.52], [1, 1.19, 2041.78], [2, 1.18, 2792.64]], "batl": NaN}, {"timestamp": 1578771845025, "ltp": 1.2, "tv": 16703.76, "trd": NaN, "batb": NaN, "batl": [[0, 1.21, 1034.12]]}, {"timestamp": 1578771863963, "ltp": 1.2, "tv": 16703.76, "trd": NaN, "batb": NaN, "batl": [[1, 1.22, 733.41]]}, {"timestamp": 1578771867051, "ltp": 1.2, "tv": 16703.76, "trd": NaN, "batb": [[1, 1.19, 2001.78]], "batl": NaN}, {"timestamp": 1578771875049, "ltp": 1.2, "tv": 16703.86, "trd": [[1.2, 5848.85]], "batb": [[0, 1.2, 5.42]], "batl": NaN}, {"timestamp": 1578771878055, "ltp": 1.2, "tv": 16703.86, "trd": NaN, "batb": [[1, 1.19, 1991.78]], "batl": NaN}, {"timestamp": 1578771880972, "ltp": 1.2, "tv": 16703.86, "trd": NaN, "batb": [[1, 1.19, 2001.78]], "batl": NaN}, {"timestamp": 1578771883005, "ltp": 1.2, "tv": 16703.86, "trd": NaN, "batb": [[1, 1.19, 1991.78]], "batl": NaN}, {"timestamp": 1578771883992, "ltp": 1.21, "tv": 16713.86, "trd": [[1.21, 8445.41]], "batb": [[1, 1.19, 2001.78]], "batl": [[0, 1.21, 1029.12]]}, {"timestamp": 1578771894995, "ltp": 1.2, "tv": 16724.7, "trd": [[1.2, 5859.69]], "batb": [[0, 1.19, 2001.78], [1, 1.18, 2792.64], [2, 1.17, 2769.74]], "batl": [[0, 1.2, 135.73], [1, 1.21, 1029.12], [2, 1.22, 733.41]]}, {"timestamp": 1578771897000, "ltp": 1.2, "tv": 16724.7, "trd": NaN, "batb": NaN, "batl": [[0, 1.2, 236.72]]}, {"timestamp": 1578771902023, "ltp": 1.2, "tv": 16724.7, "trd": NaN, "batb": [[0, 1.19, 1710.18]], "batl": NaN}, {"timestamp": 1578771903030, "ltp": 1.2, "tv": 16724.7, "trd": NaN, "batb": NaN, "batl": [[0, 1.2, 279.57], [1, 1.21, 986.63]]}, {"timestamp": 1578771904031, "ltp": 1.2, "tv": 16743.94, "trd": [[1.19, 6], [1.2, 5872.93]], "batb": [[0, 1.19, 1707.18]], "batl": [[0, 1.2, 272.95]]}, {"timestamp": 1578771904978, "ltp": 1.2, "tv": 16747.94, "trd": [[1.2, 5876.93]], "batb": NaN, "batl": [[0, 1.2, 270.95]]}, {"timestamp": 1578771907026, "ltp": 1.2, "tv": 16766.28, "trd": [[1.2, 5895.27]], "batb": [[0, 1.19, 941.1]], "batl": [[0, 1.2, 261.78]]}, {"timestamp": 1578771909040, "ltp": 1.2, "tv": 16787.22, "trd": [[1.2, 5916.21]], "batb": NaN, "batl": [[0, 1.2, 251.31]]}, {"timestamp": 1578771911052, "ltp": 1.2, "tv": 16787.22, "trd": NaN, "batb": [[0, 1.19, 515.49]], "batl": NaN}, {"timestamp": 1578771915056, "ltp": 1.2, "tv": 16787.22, "trd": NaN, "batb": NaN, "batl": [[2, 1.22, 767.42]]}, {"timestamp": 1578771916051, "ltp": 1.2, "tv": 16797.35, "trd": [[1.19, 12.12], [1.2, 5920.21]], "batb": [[0, 1.19, 512.43]], "batl": [[0, 1.2, 249.31]]}, {"timestamp": 1578771918947, "ltp": 1.2, "tv": 16797.35, "trd": NaN, "batb": [[0, 1.19, 680.43]], "batl": [[2, 1.22, 603.42]]}, {"timestamp": 1578771921957, "ltp": 1.2, "tv": 16797.35, "trd": NaN, "batb": [[0, 1.19, 512.43]], "batl": [[2, 1.22, 767.42]]}, {"timestamp": 1578771924053, "ltp": 1.2, "tv": 16797.35, "trd": NaN, "batb": [[0, 1.19, 680.43]], "batl": [[2, 1.22, 603.42]]}, {"timestamp": 1578771927047, "ltp": 1.2, "tv": 16797.35, "trd": NaN, "batb": [[0, 1.19, 512.43]], "batl": [[2, 1.22, 767.42]]}, {"timestamp": 1578771927986, "ltp": 1.2, "tv": 16797.35, "trd": NaN, "batb": [[0, 1.19, 502.43], [1, 1.18, 2802.64]], "batl": NaN}, {"timestamp": 1578771933043, "ltp": 1.2, "tv": 16797.35, "trd": NaN, "batb": [[0, 1.19, 512.43], [1, 1.18, 2792.64]], "batl": NaN}, {"timestamp": 1578771950972, "ltp": 1.2, "tv": 16797.35, "trd": NaN, "batb": NaN, "batl": [[1, 1.21, 607.12]]}, {"timestamp": 1578771951964, "ltp": 1.2, "tv": 16797.35, "trd": NaN, "batb": [[0, 1.19, 733.06]], "batl": [[0, 1.2, 148.31], [2, 1.22, 603.42]]}, {"timestamp": 1578771952954, "ltp": 1.2, "tv": 16797.35, "trd": NaN, "batb": NaN, "batl": [[0, 1.2, 530.99]]}, {"timestamp": 1578771953958, "ltp": 1.2, "tv": 16797.35, "trd": NaN, "batb": NaN, "batl": [[0, 1.2, 601.35]]}, {"timestamp": 1578771963003, "ltp": 1.2, "tv": 16812.38, "trd": [[1.2, 5935.25]], "batb": NaN, "batl": [[0, 1.2, 593.83]]}, {"timestamp": 1578771963789, "ltp": 1.2, "tv": 16812.38, "trd": NaN, "batb": [[0, 1.19, 680.43]], "batl": NaN}, {"timestamp": 1578771965997, "ltp": 1.2, "tv": 17088.11, "trd": [[1.19, 165.19], [1.2, 6057.91]], "batb": [[0, 1.19, 621.52]], "batl": [[0, 1.2, 532.5]]}, {"timestamp": 1578771973012, "ltp": 1.2, "tv": 17210.76, "trd": [[1.2, 6180.56]], "batb": [[0, 1.19, 633.17]], "batl": [[0, 1.2, 471.17]]}, {"timestamp": 1578771975003, "ltp": 1.2, "tv": 17210.76, "trd": NaN, "batb": NaN, "batl": [[0, 1.2, 453.03]]}, {"timestamp": 1578771986003, "ltp": 1.2, "tv": 17210.76, "trd": NaN, "batb": NaN, "batl": [[0, 1.2, 471.17]]}, {"timestamp": 1578771990011, "ltp": 1.19, "tv": 17250.57, "trd": [[1.19, 204.99]], "batb": [[0, 1.19, 617.05]], "batl": NaN}, {"timestamp": 1578771994008, "ltp": 1.19, "tv": 17250.57, "trd": NaN, "batb": [[0, 1.19, 1017.01]], "batl": NaN}, {"timestamp": 1578771997011, "ltp": 1.19, "tv": 17250.57, "trd": NaN, "batb": [[0, 1.19, 992.24]], "batl": NaN}, {"timestamp": 1578772000750, "ltp": 1.2, "tv": 17528.19, "trd": [[1.2, 6458.18]], "batb": [[0, 1.19, 1018.62]], "batl": [[0, 1.2, 193.55]]}, {"timestamp": 1578772002037, "ltp": 1.2, "tv": 17528.19, "trd": NaN, "batb": [[0, 1.19, 1021.68]], "batl": NaN}, {"timestamp": 1578772003044, "ltp": 1.2, "tv": 17528.19, "trd": NaN, "batb": [[0, 1.19, 1010.02]], "batl": [[0, 1.2, 123.19]]}, {"timestamp": 1578772017961, "ltp": 1.19, "tv": 17728.19, "trd": [[1.19, 404.99]], "batb": [[0, 1.19, 929.02]], "batl": NaN}, {"timestamp": 1578772019746, "ltp": 1.19, "tv": 17728.19, "trd": NaN, "batb": [[0, 1.19, 925.24]], "batl": NaN}, {"timestamp": 1578772020957, "ltp": 1.2, "tv": 17732.73, "trd": [[1.2, 6462.73]], "batb": NaN, "batl": [[0, 1.2, 120.92]]}, {"timestamp": 1578772031054, "ltp": 1.2, "tv": 17756.47, "trd": [[1.2, 6486.47]], "batb": [[0, 1.19, 901.56]], "batl": [[0, 1.2, 109.05]]}, {"timestamp": 1578772033875, "ltp": 1.2, "tv": 17756.47, "trd": NaN, "batb": [[0, 1.19, 733.56]], "batl": [[2, 1.22, 767.42]]}, {"timestamp": 1578772038998, "ltp": 1.19, "tv": 17776.47, "trd": [[1.19, 424.99]], "batb": [[0, 1.19, 723.56]], "batl": NaN}, {"timestamp": 1578772047971, "ltp": 1.19, "tv": 17776.47, "trd": NaN, "batb": [[0, 1.19, 711.87]], "batl": NaN}, {"timestamp": 1578772070993, "ltp": 1.19, "tv": 17776.47, "trd": NaN, "batb": NaN, "batl": [[2, 1.22, 603.42]]}, {"timestamp": 1578772074020, "ltp": 1.2, "tv": 17778.69, "trd": [[1.2, 6488.69]], "batb": NaN, "batl": [[0, 1.2, 106.83]]}, {"timestamp": 1578772080032, "ltp": 1.2, "tv": 17828.69, "trd": [[1.2, 6538.69]], "batb": NaN, "batl": [[0, 1.2, 56.83]]}, {"timestamp": 1578772087033, "ltp": 1.2, "tv": 17840.17, "trd": [[1.2, 6550.17]], "batb": NaN, "batl": [[0, 1.2, 45.35]]}, {"timestamp": 1578772090032, "ltp": 1.2, "tv": 17840.17, "trd": NaN, "batb": NaN, "batl": [[0, 1.2, 27.21]]}, {"timestamp": 1578772091030, "ltp": 1.2, "tv": 17840.17, "trd": NaN, "batb": NaN, "batl": [[1, 1.21, 625.26]]}, {"timestamp": 1578772094022, "ltp": 1.2, "tv": 17840.17, "trd": NaN, "batb": NaN, "batl": [[1, 1.21, 625.11]]}, {"timestamp": 1578772095011, "ltp": 1.2, "tv": 17840.17, "trd": NaN, "batb": NaN, "batl": [[0, 1.2, 395.56]]}, {"timestamp": 1578772098026, "ltp": 1.2, "tv": 17909.39, "trd": [[1.2, 6619.39]], "batb": [[0, 1.19, 714.5], [1, 1.18, 2623.64], [2, 1.17, 2598.74]], "batl": [[0, 1.2, 360.95]]}, {"timestamp": 1578772101023, "ltp": 1.2, "tv": 17909.39, "trd": NaN, "batb": [[0, 1.19, 663.08], [1, 1.18, 1507.27], [2, 1.17, 1469.14]], "batl": [[0, 1.21, 60.04], [1, 1.22, 34.01], [2, 1.22, 0]]}, {"timestamp": 1578772108019, "ltp": 1.2, "tv": 17909.39, "trd": NaN, "batb": [[1, 1.18, 1810.24], [2, 1.17, 1774.7]], "batl": [[0, 1.2, 171.82], [1, 1.21, 221.84], [2, 1.22, 204.73]]}, {"timestamp": 1578772108966, "ltp": 1.2, "tv": 17909.39, "trd": NaN, "batb": [[0, 1.19, 716.39], [1, 1.18, 1560.84], [2, 1.17, 1523.03]], "batl": [[0, 1.21, 107.13], [1, 1.22, 34.01], [2, 1.22, 0]]}, {"timestamp": 1578772109962, "ltp": 1.2, "tv": 17909.39, "trd": NaN, "batb": [[0, 1.19, 724.4], [1, 1.18, 1573.53], [2, 1.17, 1539.44]], "batl": [[0, 1.21, 117.67]]}, {"timestamp": 1578772113015, "ltp": 1.2, "tv": 17909.39, "trd": NaN, "batb": [[0, 1.19, 745.68]], "batl": NaN}, {"timestamp": 1578772114004, "ltp": 1.2, "tv": 17909.39, "trd": NaN, "batb": [[2, 1.17, 1710.44]], "batl": NaN}, {"timestamp": 1578772116004, "ltp": 1.2, "tv": 17909.39, "trd": NaN, "batb": [[0, 1.2, 106.4], [1, 1.19, 762.7], [2, 1.18, 1573.53]], "batl": [[0, 1.21, 135.66], [2, 1.24, 38.3]]}, {"timestamp": 1578772117012, "ltp": 1.2, "tv": 17909.39, "trd": NaN, "batb": [[0, 1.19, 762.7], [1, 1.18, 1575.53], [2, 1.17, 1712.44]], "batl": [[2, 1.23, 138.5]]}, {"timestamp": 1578772118011, "ltp": 1.2, "tv": 17909.39, "trd": NaN, "batb": NaN, "batl": [[2, 1.24, 17.02]]}, {"timestamp": 1578772120976, "ltp": 1.2, "tv": 17909.39, "trd": NaN, "batb": [[1, 1.18, 1431.53]], "batl": NaN}, {"timestamp": 1578772123020, "ltp": 1.2, "tv": 17909.39, "trd": NaN, "batb": [[0, 1.19, 764.7]], "batl": NaN}, {"timestamp": 1578772124032, "ltp": 1.2, "tv": 17909.39, "trd": NaN, "batb": [[0, 1.2, 38.3], [1, 1.19, 3004.87], [2, 1.18, 1641.9]], "batl": [[0, 1.21, 183.73], [1, 1.22, 171.37], [2, 1.23, 900]]}, {"timestamp": 1578772125024, "ltp": 1.2, "tv": 17909.39, "trd": NaN, "batb": [[0, 1.19, 3004.87], [1, 1.18, 1641.9], [2, 1.17, 1944.43]], "batl": [[1, 1.22, 34.01]]}, {"timestamp": 1578772126020, "ltp": 1.19, "tv": 17913.39, "trd": [[1.19, 428.99]], "batb": [[0, 1.19, 3002.88]], "batl": NaN}, {"timestamp": 1578772127024, "ltp": 1.19, "tv": 17913.39, "trd": NaN, "batb": NaN, "batl": [[2, 1.23, 1054.5]]}, {"timestamp": 1578772131049, "ltp": 1.19, "tv": 17913.39, "trd": NaN, "batb": [[0, 1.19, 3024.16]], "batl": NaN}, {"timestamp": 1578772132990, "ltp": 1.19, "tv": 17913.39, "trd": NaN, "batb": [[0, 1.19, 3007.13], [1, 1.18, 1854.38]], "batl": [[1, 1.22, 167.12]]}, {"timestamp": 1578772144036, "ltp": 1.19, "tv": 17913.39, "trd": NaN, "batb": NaN, "batl": [[2, 1.23, 1345.15]]}, {"timestamp": 1578772145032, "ltp": 1.19, "tv": 17913.39, "trd": NaN, "batb": [[1, 1.18, 1641.9]], "batl": NaN}, {"timestamp": 1578772146042, "ltp": 1.19, "tv": 17913.39, "trd": NaN, "batb": [[0, 1.19, 942.39]], "batl": [[2, 1.23, 445.15]]}, {"timestamp": 1578772147044, "ltp": 1.19, "tv": 17913.39, "trd": NaN, "batb": NaN, "batl": [[1, 1.22, 34.01]]}, {"timestamp": 1578772150049, "ltp": 1.2, "tv": 17916.04, "trd": [[1.2, 6622.04]], "batb": NaN, "batl": NaN}, {"timestamp": 1578772153956, "ltp": 1.2, "tv": 17916.04, "trd": NaN, "batb": [[1, 1.18, 2702.56]], "batl": [[2, 1.23, 895.15]]}, {"timestamp": 1578772154951, "ltp": 1.2, "tv": 17916.04, "trd": NaN, "batb": NaN, "batl": [[2, 1.23, 1481.71]]}, {"timestamp": 1578772155950, "ltp": 1.2, "tv": 17916.04, "trd": NaN, "batb": [[1, 1.18, 1641.9]], "batl": [[1, 1.22, 171.76]]}, {"timestamp": 1578772160968, "ltp": 1.2, "tv": 17916.04, "trd": NaN, "batb": [[0, 1.19, 943.45]], "batl": [[0, 1.2, 76.53], [1, 1.21, 183.73], [2, 1.22, 171.76]]}, {"timestamp": 1578772161961, "ltp": 1.2, "tv": 17916.04, "trd": NaN, "batb": [[0, 1.19, 1975.82]], "batl": [[2, 1.22, 311.96]]}, {"timestamp": 1578772163053, "ltp": 1.2, "tv": 17916.04, "trd": NaN, "batb": [[0, 1.19, 3008.19]], "batl": [[1, 1.21, 165.73]]}, {"timestamp": 1578772166034, "ltp": 1.2, "tv": 17916.04, "trd": NaN, "batb": [[0, 1.19, 3171.06], [1, 1.18, 1819.64], [2, 1.17, 2132.92]], "batl": [[2, 1.22, 604.99]]}, {"timestamp": 1578772170053, "ltp": 1.2, "tv": 17916.04, "trd": NaN, "batb": NaN, "batl": [[0, 1.2, 94.53]]}, {"timestamp": 1578772171041, "ltp": 1.2, "tv": 17916.04, "trd": NaN, "batb": NaN, "batl": [[0, 1.2, 76.53]]}, {"timestamp": 1578772177959, "ltp": 1.2, "tv": 17916.04, "trd": NaN, "batb": [[1, 1.18, 1836.66]], "batl": [[1, 1.21, 183.73]]}, {"timestamp": 1578772180983, "ltp": 1.19, "tv": 17916.58, "trd": [[1.19, 429.53]], "batb": [[0, 1.19, 3170.8]], "batl": NaN}, {"timestamp": 1578772183963, "ltp": 1.19, "tv": 17916.58, "trd": NaN, "batb": NaN, "batl": [[1, 1.21, 165.73]]}, {"timestamp": 1578772185997, "ltp": 1.19, "tv": 17916.58, "trd": NaN, "batb": [[2, 1.17, 2870.92]], "batl": NaN}, {"timestamp": 1578772186994, "ltp": 1.19, "tv": 17916.58, "trd": NaN, "batb": [[1, 1.18, 1840.49]], "batl": NaN}, {"timestamp": 1578772197996, "ltp": 1.19, "tv": 17916.58, "trd": NaN, "batb": NaN, "batl": [[1, 1.21, 183.73]]}, {"timestamp": 1578772199036, "ltp": 1.2, "tv": 17942.94, "trd": [[1.2, 6648.4]], "batb": NaN, "batl": [[0, 1.2, 50.18], [1, 1.21, 105.69]]}, {"timestamp": 1578772200033, "ltp": 1.2, "tv": 17942.94, "trd": NaN, "batb": [[2, 1.17, 2874.75]], "batl": NaN}, {"timestamp": 1578772206035, "ltp": 1.2, "tv": 17942.94, "trd": NaN, "batb": [[1, 1.18, 2561.49]], "batl": NaN}, {"timestamp": 1578772207025, "ltp": 1.19, "tv": 17973.69, "trd": [[1.19, 460.28]], "batb": [[0, 1.19, 3155.42]], "batl": [[0, 1.2, 110.22]]}, {"timestamp": 1578772210055, "ltp": 1.19, "tv": 17973.69, "trd": NaN, "batb": NaN, "batl": [[1, 1.21, 242.53]]}, {"timestamp": 1578772211013, "ltp": 1.19, "tv": 17973.69, "trd": NaN, "batb": NaN, "batl": [[1, 1.21, 105.69]]}, {"timestamp": 1578772212017, "ltp": 1.19, "tv": 17973.69, "trd": NaN, "batb": [[1, 1.18, 2773.97]], "batl": NaN}, {"timestamp": 1578772213029, "ltp": 1.19, "tv": 17973.69, "trd": NaN, "batb": NaN, "batl": [[1, 1.21, 123.69]]}, {"timestamp": 1578772214029, "ltp": 1.19, "tv": 17973.69, "trd": NaN, "batb": NaN, "batl": [[2, 1.22, 1352.99]]}, {"timestamp": 1578772216019, "ltp": 1.2, "tv": 18083.91, "trd": [[1.2, 6758.62]], "batb": NaN, "batl": [[0, 1.21, 123.69], [1, 1.22, 1352.99], [2, 1.23, 1786.8]]}, {"timestamp": 1578772217010, "ltp": 1.2, "tv": 18085.78, "trd": [[1.2, 6760.48]], "batb": NaN, "batl": NaN}, {"timestamp": 1578772221046, "ltp": 1.2, "tv": 18085.78, "trd": NaN, "batb": NaN, "batl": [[1, 1.22, 604.99], [2, 1.23, 1092.8]]}, {"timestamp": 1578772222038, "ltp": 1.2, "tv": 18085.78, "trd": NaN, "batb": [[0, 1.19, 3134.14]], "batl": [[0, 1.21, 566.29]]}, {"timestamp": 1578772223039, "ltp": 1.2, "tv": 18085.78, "trd": NaN, "batb": [[0, 1.2, 23.89], [1, 1.19, 2359.86], [2, 1.18, 2773.97]], "batl": [[0, 1.21, 123.69]]}, {"timestamp": 1578772225971, "ltp": 1.2, "tv": 18186.21, "trd": [[1.2, 6860.91]], "batb": [[0, 1.19, 2359.86], [1, 1.18, 2773.97], [2, 1.17, 2874.75]], "batl": NaN}, {"timestamp": 1578772226954, "ltp": 1.2, "tv": 18186.21, "trd": NaN, "batb": [[0, 1.19, 1327.49], [2, 1.17, 2771.75]], "batl": [[2, 1.23, 642.8]]}, {"timestamp": 1578772229043, "ltp": 1.2, "tv": 18186.21, "trd": NaN, "batb": [[1, 1.18, 2795.25]], "batl": NaN}, {"timestamp": 1578772230042, "ltp": 1.2, "tv": 18186.21, "trd": NaN, "batb": [[1, 1.18, 2773.97]], "batl": [[2, 1.23, 621.52]]}, {"timestamp": 1578772231048, "ltp": 1.2, "tv": 18186.21, "trd": NaN, "batb": [[1, 1.18, 3548.25]], "batl": NaN}, {"timestamp": 1578772232039, "ltp": 1.2, "tv": 18271.51, "trd": [[1.2, 6946.21]], "batb": NaN, "batl": [[0, 1.2, 514.7], [1, 1.21, 123.69], [2, 1.22, 604.99]]}, {"timestamp": 1578772233033, "ltp": 1.2, "tv": 18271.51, "trd": NaN, "batb": [[0, 1.19, 906.59]], "batl": NaN}, {"timestamp": 1578772233979, "ltp": 1.2, "tv": 18271.51, "trd": NaN, "batb": [[1, 1.18, 4763.92]], "batl": [[1, 1.21, 147.38], [2, 1.22, 1054.99]]}, {"timestamp": 1578772235048, "ltp": 1.2, "tv": 18397.79, "trd": [[1.2, 7072.49]], "batb": [[0, 1.19, 1390.5]], "batl": [[0, 1.2, 388.42], [1, 1.21, 920.38], [2, 1.22, 1834.99]]}, {"timestamp": 1578772236042, "ltp": 1.2, "tv": 18397.79, "trd": NaN, "batb": NaN, "batl": [[2, 1.22, 1541.96]]}, {"timestamp": 1578772236982, "ltp": 1.2, "tv": 18397.79, "trd": NaN, "batb": [[1, 1.18, 4785.2]], "batl": NaN}, {"timestamp": 1578772237971, "ltp": 1.2, "tv": 18397.79, "trd": NaN, "batb": NaN, "batl": [[1, 1.21, 878.69]]}, {"timestamp": 1578772239957, "ltp": 1.19, "tv": 18415.73, "trd": [[1.19, 478.22]], "batb": [[0, 1.19, 1381.53]], "batl": [[0, 1.2, 649.91], [1, 1.21, 1174.16]]}, {"timestamp": 1578772241962, "ltp": 1.19, "tv": 18415.73, "trd": NaN, "batb": [[1, 1.18, 5071.58]], "batl": NaN}, {"timestamp": 1578772242966, "ltp": 1.19, "tv": 18415.73, "trd": NaN, "batb": NaN, "batl": [[0, 1.2, 947.83]]}, {"timestamp": 1578772245012, "ltp": 1.19, "tv": 18415.73, "trd": NaN, "batb": NaN, "batl": [[0, 1.2, 989.87]]}, {"timestamp": 1578772245958, "ltp": 1.19, "tv": 18415.73, "trd": NaN, "batb": [[0, 1.19, 978.72]], "batl": NaN}, {"timestamp": 1578772250969, "ltp": 1.19, "tv": 18415.73, "trd": NaN, "batb": NaN, "batl": [[1, 1.21, 1324.66]]}, {"timestamp": 1578772253994, "ltp": 1.19, "tv": 18415.73, "trd": NaN, "batb": NaN, "batl": [[2, 1.22, 1544.25]]}, {"timestamp": 1578772262972, "ltp": 1.19, "tv": 18417.97, "trd": [[1.19, 480.47]], "batb": [[0, 1.19, 977.59]], "batl": NaN}, {"timestamp": 1578772264028, "ltp": 1.19, "tv": 19013.82, "trd": [[1.19, 1076.31]], "batb": [[0, 1.19, 679.67], [1, 1.18, 2950.26]], "batl": [[2, 1.22, 1094.25]]}, {"timestamp": 1578772264965, "ltp": 1.19, "tv": 19013.82, "trd": NaN, "batb": [[1, 1.18, 2737.78]], "batl": NaN}, {"timestamp": 1578772270045, "ltp": 1.19, "tv": 19013.82, "trd": NaN, "batb": NaN, "batl": [[1, 1.21, 551.66]]}, {"timestamp": 1578772271046, "ltp": 1.19, "tv": 19073.82, "trd": [[1.19, 1136.31]], "batb": [[0, 1.19, 649.67]], "batl": NaN}, {"timestamp": 1578772272003, "ltp": 1.19, "tv": 19073.82, "trd": NaN, "batb": [[1, 1.18, 4859.1]], "batl": NaN}, {"timestamp": 1578772273001, "ltp": 1.19, "tv": 19073.82, "trd": NaN, "batb": NaN, "batl": [[2, 1.22, 1994.25]]}, {"timestamp": 1578772273991, "ltp": 1.19, "tv": 19125.74, "trd": [[1.19, 1188.23]], "batb": [[0, 1.19, 623.71]], "batl": NaN}, {"timestamp": 1578772275035, "ltp": 1.19, "tv": 19125.74, "trd": NaN, "batb": NaN, "batl": [[2, 1.22, 2015.53]]}, {"timestamp": 1578772278020, "ltp": 1.19, "tv": 19125.74, "trd": NaN, "batb": NaN, "batl": [[0, 1.2, 1008.55]]}, {"timestamp": 1578772279014, "ltp": 1.19, "tv": 19125.74, "trd": NaN, "batb": [[2, 1.17, 2600.75]], "batl": NaN}, {"timestamp": 1578772281005, "ltp": 1.19, "tv": 19125.74, "trd": NaN, "batb": NaN, "batl": [[0, 1.2, 989.87]]}, {"timestamp": 1578772288914, "ltp": 1.19, "tv": 19125.74, "trd": NaN, "batb": NaN, "batl": [[2, 1.22, 2032.56]]}, {"timestamp": 1578772290955, "ltp": 1.19, "tv": 19163.11, "trd": [[1.19, 1225.61]], "batb": [[0, 1.19, 605.02]], "batl": NaN}, {"timestamp": 1578772293949, "ltp": 1.19, "tv": 19163.11, "trd": NaN, "batb": [[0, 1.18, 4138.1], [1, 1.17, 1862.75], [2, 1.16, 2207.63]], "batl": [[2, 1.22, 1252.56]]}, {"timestamp": 1578772294860, "ltp": 1.19, "tv": 19163.11, "trd": NaN, "batb": [[0, 1.18, 4116.82]], "batl": [[2, 1.22, 1231.28]]}, {"timestamp": 1578772296040, "ltp": 1.19, "tv": 19163.11, "trd": NaN, "batb": [[0, 1.18, 1577.12], [1, 1.17, 1428.21], [2, 1.16, 1589.9]], "batl": [[0, 1.2, 480.51], [1, 1.21, 48.07], [2, 1.22, 36.31]]}, {"timestamp": 1578772296937, "ltp": 1.19, "tv": 19163.11, "trd": NaN, "batb": [[0, 1.18, 1524.11], [1, 1.17, 1371.97], [2, 1.16, 1529.42]], "batl": [[0, 1.2, 430.45], [1, 1.22, 36.31], [2, 1.23, 12]]}, {"timestamp": 1578772347979, "ltp": 1.19, "tv": 19163.11, "trd": NaN, "batb": [[0, 1.18, 1365.27], [1, 1.17, 1368.14], [2, 1.16, 1459.6]], "batl": NaN}, {"timestamp": 1578772356009, "ltp": 1.19, "tv": 19163.11, "trd": NaN, "batb": [[0, 1.38, 61], [1, 1.36, 69.01], [2, 1.18, 1365.27]], "batl": [[0, 1.59, 381]]}, {"timestamp": 1578772356995, "ltp": 1.19, "tv": 19163.11, "trd": NaN, "batb": [[0, 1.43, 177.99], [1, 1.4, 555], [2, 1.39, 571]], "batl": [[0, 1.55, 398], [1, 1.56, 382], [2, 1.57, 391]]}, {"timestamp": 1578772357976, "ltp": 1.19, "tv": 19163.11, "trd": NaN, "batb": [[1, 1.39, 571], [2, 1.38, 581]], "batl": NaN}, {"timestamp": 1578772359020, "ltp": 1.19, "tv": 19163.11, "trd": NaN, "batb": NaN, "batl": [[0, 1.56, 382], [1, 1.57, 391], [2, 1.58, 393]]}, {"timestamp": 1578772362030, "ltp": 1.19, "tv": 19163.11, "trd": NaN, "batb": NaN, "batl": [[0, 1.53, 1999.84], [1, 1.56, 382], [2, 1.57, 391]]}, {"timestamp": 1578772364993, "ltp": 1.19, "tv": 19163.11, "trd": NaN, "batb": [[1, 1.4, 598], [2, 1.39, 571]], "batl": NaN}, {"timestamp": 1578772366041, "ltp": 1.19, "tv": 19163.11, "trd": NaN, "batb": [[0, 1.43, 199.27], [1, 1.41, 561], [2, 1.4, 598]], "batl": [[1, 1.54, 21.28], [2, 1.56, 382]]}, {"timestamp": 1578772367023, "ltp": 1.19, "tv": 19163.11, "trd": NaN, "batb": [[2, 1.4, 769.6]], "batl": [[1, 1.55, 297.92]]}, {"timestamp": 1578772368009, "ltp": 1.19, "tv": 19163.11, "trd": NaN, "batb": [[1, 1.41, 654.28]], "batl": NaN}, {"timestamp": 1578772369001, "ltp": 1.19, "tv": 19163.11, "trd": NaN, "batb": NaN, "batl": [[0, 1.49, 7.66], [1, 1.53, 1999.84], [2, 1.55, 297.92]]}, {"timestamp": 1578772369992, "ltp": 1.43, "tv": 19188.74, "trd": [[1.43, 25.62]], "batb": [[0, 1.43, 186.46], [1, 1.42, 141], [2, 1.41, 1025.88]], "batl": [[1, 1.51, 8.65], [2, 1.53, 1999.84]]}, {"timestamp": 1578772371027, "ltp": 1.43, "tv": 19188.74, "trd": NaN, "batb": NaN, "batl": [[2, 1.52, 297.92]]}, {"timestamp": 1578772372020, "ltp": 1.43, "tv": 19188.74, "trd": NaN, "batb": NaN, "batl": [[0, 1.45, 30.61], [1, 1.49, 7.66], [2, 1.51, 8.65]]}, {"timestamp": 1578772373995, "ltp": 1.43, "tv": 19188.74, "trd": NaN, "batb": [[1, 1.42, 196]], "batl": NaN}, {"timestamp": 1578772375927, "ltp": 1.43, "tv": 19188.74, "trd": NaN, "batb": [[0, 1.43, 165.18], [1, 1.42, 890.36], [2, 1.41, 1552.97]], "batl": [[2, 1.5, 337.5]]}, {"timestamp": 1578772377028, "ltp": 1.45, "tv": 19205.63, "trd": [[1.45, 16.89]], "batb": [[2, 1.41, 1025.88]], "batl": [[0, 1.45, 13.72], [1, 1.49, 1423.65], [2, 1.51, 459.65]]}, {"timestamp": 1578772378023, "ltp": 1.43, "tv": 19535.98, "trd": [[1.43, 355.98]], "batb": [[0, 1.42, 890.36], [1, 1.41, 1025.88], [2, 1.4, 1026.11]], "batl": [[0, 1.43, 223.82], [1, 1.45, 13.72], [2, 1.49, 1423.65]]}, {"timestamp": 1578772379046, "ltp": 1.43, "tv": 19535.98, "trd": NaN, "batb": [[2, 1.4, 912.6]], "batl": [[2, 1.49, 1415.99]]}, {"timestamp": 1578772380032, "ltp": 1.42, "tv": 19553.01, "trd": [[1.42, 17.02]], "batb": [[0, 1.42, 881.85]], "batl": [[0, 1.45, 13.72], [1, 1.49, 1427.5], [2, 1.51, 592.95]]}, {"timestamp": 1578772381024, "ltp": 1.42, "tv": 19590.38, "trd": [[1.42, 54.4]], "batb": [[0, 1.42, 1092.98]], "batl": [[1, 1.47, 2.3], [2, 1.49, 1427.5]]}, {"timestamp": 1578772383028, "ltp": 1.42, "tv": 19590.38, "trd": NaN, "batb": [[0, 1.42, 1114.26], [1, 1.41, 1038.69]], "batl": [[2, 1.49, 1684]]}, {"timestamp": 1578772384025, "ltp": 1.42, "tv": 19626.63, "trd": [[1.42, 90.22], [1.44, 0.42]], "batb": [[0, 1.42, 1735.49]], "batl": [[2, 1.49, 1672.49]]}, {"timestamp": 1578772384907, "ltp": 1.42, "tv": 19626.63, "trd": NaN, "batb": NaN, "batl": [[0, 1.43, 13.78], [1, 1.45, 13.72], [2, 1.47, 2.3]]}, {"timestamp": 1578772385966, "ltp": 1.43, "tv": 19654.19, "trd": [[1.43, 383.53]], "batb": [[0, 1.42, 542.3]], "batl": [[0, 1.43, 133.1]]}, {"timestamp": 1578772386964, "ltp": 1.43, "tv": 19654.19, "trd": NaN, "batb": NaN, "batl": [[0, 1.43, 135.1]]}, {"timestamp": 1578772387959, "ltp": 1.43, "tv": 19654.19, "trd": NaN, "batb": NaN, "batl": [[1, 1.47, 2.3], [2, 1.48, 330.56]]}, {"timestamp": 1578772388952, "ltp": 1.43, "tv": 19654.19, "trd": NaN, "batb": [[1, 1.41, 2734.97]], "batl": [[2, 1.48, 430.34]]}, {"timestamp": 1578772389985, "ltp": 1.43, "tv": 19924.38, "trd": [[1.43, 653.73]], "batb": NaN, "batl": [[0, 1.47, 2.3], [1, 1.48, 355.53], [2, 1.49, 8.65]]}, {"timestamp": 1578772390974, "ltp": 1.43, "tv": 19924.38, "trd": NaN, "batb": [[0, 1.42, 346.77]], "batl": [[2, 1.49, 465.65]]}, {"timestamp": 1578772392968, "ltp": 1.43, "tv": 19924.38, "trd": NaN, "batb": [[0, 1.43, 540], [1, 1.42, 894.77], [2, 1.41, 2734.97]], "batl": [[0, 1.47, 26.79]]}, {"timestamp": 1578772394032, "ltp": 1.44, "tv": 19947.3, "trd": [[1.44, 23.34]], "batb": [[0, 1.44, 81.08], [1, 1.43, 540], [2, 1.42, 1589.13]], "batl": [[0, 1.47, 57.08], [1, 1.48, 389.85]]}, {"timestamp": 1578772394980, "ltp": 1.44, "tv": 20000.77, "trd": [[1.44, 76.81]], "batb": [[0, 1.44, 54.35]], "batl": [[1, 1.48, 355.53]]}, {"timestamp": 1578772396977, "ltp": 1.44, "tv": 20000.77, "trd": NaN, "batb": NaN, "batl": [[0, 1.47, 64.74], [2, 1.49, 670.85]]}, {"timestamp": 1578772397970, "ltp": 1.44, "tv": 20004.13, "trd": [[1.44, 80.17]], "batb": [[0, 1.44, 52.67]], "batl": [[0, 1.47, 57.08]]}, {"timestamp": 1578772399006, "ltp": 1.44, "tv": 20004.13, "trd": NaN, "batb": [[0, 1.43, 540], [1, 1.42, 1589.13], [2, 1.41, 2790.69]], "batl": [[0, 1.45, 252.07], [1, 1.47, 57.08], [2, 1.48, 355.53]]}, {"timestamp": 1578772400005, "ltp": 1.44, "tv": 20004.13, "trd": NaN, "batb": [[0, 1.43, 568.31], [1, 1.42, 922.4], [2, 1.41, 2819.09]], "batl": [[2, 1.48, 323.38]]}, {"timestamp": 1578772401002, "ltp": 1.44, "tv": 20004.13, "trd": NaN, "batb": [[0, 1.43, 790.01], [1, 1.42, 1253.6], [2, 1.41, 3155.19]], "batl": [[1, 1.47, 346.25]]}, {"timestamp": 1578772402030, "ltp": 1.44, "tv": 20288.0, "trd": [[1.43, 923.93], [1.44, 93.84]], "batb": [[0, 1.44, 19.08]], "batl": [[2, 1.48, 1042.91]]}, {"timestamp": 1578772403016, "ltp": 1.44, "tv": 20288.0, "trd": NaN, "batb": [[0, 1.42, 1253.6], [1, 1.41, 1458.91], [2, 1.4, 3104.04]], "batl": [[0, 1.44, 13.67], [1, 1.45, 252.07], [2, 1.47, 346.25]]}, {"timestamp": 1578772404015, "ltp": 1.44, "tv": 20288.0, "trd": NaN, "batb": [[2, 1.4, 1280.28]], "batl": [[2, 1.46, 15.31]]}, {"timestamp": 1578772405006, "ltp": 1.44, "tv": 20288.0, "trd": NaN, "batb": NaN, "batl": [[0, 1.43, 10], [1, 1.44, 13.67], [2, 1.45, 252.07]]}, {"timestamp": 1578772406002, "ltp": 1.43, "tv": 20308.0, "trd": [[1.43, 943.93]], "batb": [[2, 1.4, 1387.28]], "batl": [[0, 1.44, 13.67], [1, 1.45, 252.07], [2, 1.46, 15.31]]}, {"timestamp": 1578772407006, "ltp": 1.43, "tv": 20308.0, "trd": NaN, "batb": [[1, 1.41, 1552.19]], "batl": [[1, 1.45, 284.29]]}, {"timestamp": 1578772407989, "ltp": 1.43, "tv": 20308.0, "trd": NaN, "batb": [[0, 1.42, 1947.96]], "batl": [[1, 1.45, 359.17]]}, {"timestamp": 1578772408980, "ltp": 1.43, "tv": 20308.0, "trd": NaN, "batb": NaN, "batl": [[0, 1.44, 47.99], [1, 1.45, 385.77]]}, {"timestamp": 1578772409981, "ltp": 1.43, "tv": 20308.0, "trd": NaN, "batb": NaN, "batl": [[0, 1.44, 48.26]]}, {"timestamp": 1578772410978, "ltp": 1.43, "tv": 20308.0, "trd": NaN, "batb": [[0, 1.42, 3534.78]], "batl": [[1, 1.45, 632.34], [2, 1.46, 489.31]]}, {"timestamp": 1578772411983, "ltp": 1.44, "tv": 20334.83, "trd": [[1.44, 120.67]], "batb": [[1, 1.41, 1458.91]], "batl": [[0, 1.44, 34.84]]}, {"timestamp": 1578772413015, "ltp": 1.44, "tv": 20334.83, "trd": NaN, "batb": [[1, 1.41, 1634.6]], "batl": [[1, 1.45, 456.8]]}, {"timestamp": 1578772413968, "ltp": 1.44, "tv": 20334.83, "trd": NaN, "batb": [[0, 1.42, 2744.53], [1, 1.41, 2161.69]], "batl": NaN}, {"timestamp": 1578772415025, "ltp": 1.44, "tv": 20334.83, "trd": NaN, "batb": [[0, 1.42, 2746.84]], "batl": NaN}, {"timestamp": 1578772416002, "ltp": 1.44, "tv": 20334.83, "trd": NaN, "batb": [[0, 1.42, 2639.78]], "batl": [[2, 1.46, 474]]}, {"timestamp": 1578772417002, "ltp": 1.44, "tv": 20334.83, "trd": NaN, "batb": [[0, 1.42, 2388.02]], "batl": [[0, 1.44, 35.55]]}, {"timestamp": 1578772418000, "ltp": 1.44, "tv": 20334.83, "trd": NaN, "batb": [[0, 1.43, 2.3], [1, 1.42, 2388.02], [2, 1.41, 2161.69]], "batl": NaN}, {"timestamp": 1578772418985, "ltp": 1.42, "tv": 20388.82, "trd": [[1.42, 135.62], [1.43, 948.53], [1.44, 124.67]], "batb": [[0, 1.42, 2365.31], [1, 1.41, 2161.69], [2, 1.4, 1387.28]], "batl": [[0, 1.44, 33.56]]}, {"timestamp": 1578772421024, "ltp": 1.42, "tv": 20388.82, "trd": NaN, "batb": NaN, "batl": [[1, 1.45, 529.83]]}, {"timestamp": 1578772422022, "ltp": 1.42, "tv": 20388.82, "trd": NaN, "batb": NaN, "batl": [[0, 1.44, 64.21]]}, {"timestamp": 1578772423018, "ltp": 1.42, "tv": 20388.82, "trd": NaN, "batb": [[0, 1.42, 2203.03]], "batl": [[0, 1.43, 15.31], [1, 1.44, 58.85], [2, 1.45, 529.83]]}, {"timestamp": 1578772424004, "ltp": 1.42, "tv": 20685.88, "trd": [[1.42, 432.68]], "batb": [[0, 1.42, 2054.5]], "batl": [[1, 1.44, 77.53], [2, 1.45, 1001.83]]}, {"timestamp": 1578772424895, "ltp": 1.42, "tv": 20685.88, "trd": NaN, "batb": NaN, "batl": [[0, 1.43, 193.3]]}, {"timestamp": 1578772426002, "ltp": 1.45, "tv": 21958.54, "trd": [[1.43, 1141.82], [1.44, 202.2], [1.45, 1018.72]], "batb": NaN, "batl": [[0, 1.46, 474], [1, 1.47, 475], [2, 1.48, 439]]}, {"timestamp": 1578772426995, "ltp": 1.45, "tv": 22018.24, "trd": [[1.45, 1078.42]], "batb": NaN, "batl": NaN}, {"timestamp": 1578772428048, "ltp": 1.45, "tv": 22035.66, "trd": [[1.45, 1095.84]], "batb": NaN, "batl": NaN}, {"timestamp": 1578772429042, "ltp": 1.42, "tv": 22108.34, "trd": [[1.42, 505.36]], "batb": [[0, 1.42, 2018.17]], "batl": NaN}, {"timestamp": 1578772430030, "ltp": 1.42, "tv": 22108.34, "trd": NaN, "batb": [[1, 1.41, 2182.97]], "batl": [[1, 1.47, 587.5], [2, 1.48, 889]]}, {"timestamp": 1578772431967, "ltp": 1.44, "tv": 22236.22, "trd": [[1.42, 542.74], [1.43, 1157.13], [1.44, 277.39]], "batb": [[0, 1.42, 1999.48]], "batl": [[0, 1.44, 206.16], [1, 1.46, 474], [2, 1.47, 587.5]]}, {"timestamp": 1578772433026, "ltp": 1.44, "tv": 22236.22, "trd": NaN, "batb": NaN, "batl": [[0, 1.44, 77.72], [2, 1.47, 712.16]]}, {"timestamp": 1578772434026, "ltp": 1.44, "tv": 22236.22, "trd": NaN, "batb": NaN, "batl": [[1, 1.45, 25.78], [2, 1.46, 474]]}, {"timestamp": 1578772434956, "ltp": 1.44, "tv": 22237.72, "trd": [[1.44, 278.89]], "batb": NaN, "batl": [[0, 1.45, 26.58], [1, 1.46, 474], [2, 1.47, 712.16]]}, {"timestamp": 1578772436023, "ltp": 1.45, "tv": 22279.17, "trd": [[1.44, 279.68], [1.45, 1136.5]], "batb": [[0, 1.43, 31.7], [1, 1.42, 1999.48], [2, 1.41, 2182.97]], "batl": [[0, 1.45, 31.04], [1, 1.46, 519.92], [2, 1.47, 1982.81]]}, {"timestamp": 1578772438051, "ltp": 1.43, "tv": 22280.12, "trd": [[1.43, 1158.07]], "batb": [[0, 1.43, 31.23], [1, 1.42, 2181.7]], "batl": [[0, 1.44, 45.92], [1, 1.45, 31.04], [2, 1.46, 519.92]]}, {"timestamp": 1578772440043, "ltp": 1.44, "tv": 22282.52, "trd": [[1.44, 282.09]], "batb": [[1, 1.42, 2267.18], [2, 1.41, 2885.75]], "batl": [[0, 1.44, 43.52]]}, {"timestamp": 1578772441035, "ltp": 1.43, "tv": 22292.52, "trd": [[1.43, 1168.07]], "batb": [[0, 1.43, 26.24], [2, 1.41, 2979.03]], "batl": [[1, 1.45, 415.56]]}, {"timestamp": 1578772442038, "ltp": 1.43, "tv": 22292.52, "trd": NaN, "batb": [[1, 1.42, 2294.81], [2, 1.41, 2885.75]], "batl": NaN}, {"timestamp": 1578772442979, "ltp": 1.43, "tv": 22292.52, "trd": NaN, "batb": [[0, 1.42, 2294.81], [1, 1.41, 2743.75], [2, 1.4, 1387.28]], "batl": [[1, 1.45, 495.38], [2, 1.46, 45.92]]}, {"timestamp": 1578772443967, "ltp": 1.44, "tv": 22369.49, "trd": [[1.42, 575.97], [1.43, 1168.29], [1.44, 325.6]], "batb": [[0, 1.42, 1179.57], [1, 1.41, 4526.42]], "batl": [[0, 1.45, 522.8], [1, 1.46, 45.92], [2, 1.47, 12]]}, {"timestamp": 1578772445037, "ltp": 1.45, "tv": 22431.11, "trd": [[1.45, 1198.12]], "batb": [[1, 1.41, 3120.86]], "batl": [[0, 1.45, 165.61]]}, {"timestamp": 1578772445968, "ltp": 1.42, "tv": 22588.72, "trd": [[1.42, 730.17], [1.45, 1201.53]], "batb": [[0, 1.42, 1102.47]], "batl": [[0, 1.44, 22.8], [1, 1.45, 163.91], [2, 1.46, 45.92]]}, {"timestamp": 1578772446968, "ltp": 1.44, "tv": 22595.53, "trd": [[1.44, 332.41]], "batb": NaN, "batl": [[0, 1.44, 19.39]]}, {"timestamp": 1578772447990, "ltp": 1.44, "tv": 22617.64, "trd": [[1.42, 745.48], [1.44, 339.22]], "batb": [[0, 1.42, 1094.82]], "batl": [[0, 1.44, 15.99]]}, {"timestamp": 1578772449055, "ltp": 1.44, "tv": 22804.83, "trd": [[1.42, 925.86], [1.44, 346.03]], "batb": [[0, 1.42, 1004.63], [1, 1.41, 1423.31]], "batl": [[0, 1.44, 12.58]]}, {"timestamp": 1578772449944, "ltp": 1.44, "tv": 22826.57, "trd": [[1.42, 933.32], [1.44, 360.32]], "batb": [[0, 1.44, 1.7], [1, 1.42, 838.9], [2, 1.41, 1274.31]], "batl": [[0, 1.45, 183.91], [1, 1.46, 45.92], [2, 1.47, 24]]}, {"timestamp": 1578772451039, "ltp": 1.45, "tv": 22829.98, "trd": [[1.45, 1204.93]], "batb": NaN, "batl": [[0, 1.45, 182.21]]}, {"timestamp": 1578772451969, "ltp": 1.45, "tv": 22829.98, "trd": NaN, "batb": NaN, "batl": [[2, 1.47, 474]]}, {"timestamp": 1578772452958, "ltp": 1.44, "tv": 22833.38, "trd": [[1.44, 363.72]], "batb": [[0, 1.43, 1.7], [1, 1.42, 653.71], [2, 1.41, 1253.03]], "batl": [[0, 1.44, 44.22], [1, 1.45, 182.21], [2, 1.46, 369.49]]}, {"timestamp": 1578772453944, "ltp": 1.42, "tv": 22864.0, "trd": [[1.42, 960.53], [1.43, 1171.7]], "batb": [[0, 1.42, 640.1], [1, 1.41, 1253.03], [2, 1.4, 2703.3]], "batl": [[1, 1.45, 428.77]]}, {"timestamp": 1578772455040, "ltp": 1.45, "tv": 23052.97, "trd": [[1.44, 452.16], [1.45, 1305.46]], "batb": [[0, 1.42, 682.66]], "batl": [[0, 1.45, 378.5], [1, 1.46, 1937.74], [2, 1.47, 475.7]]}, {"timestamp": 1578772455985, "ltp": 1.45, "tv": 23052.97, "trd": NaN, "batb": NaN, "batl": [[1, 1.46, 369.49], [2, 1.47, 925.7]]}, {"timestamp": 1578772456977, "ltp": 1.45, "tv": 23052.97, "trd": NaN, "batb": NaN, "batl": [[0, 1.45, 675.86], [1, 1.46, 856.49], [2, 1.47, 1375.7]]}, {"timestamp": 1578772457965, "ltp": 1.45, "tv": 23052.97, "trd": NaN, "batb": [[2, 1.4, 2560.3]], "batl": [[0, 1.43, 30], [1, 1.45, 675.86], [2, 1.46, 856.49]]}, {"timestamp": 1578772458954, "ltp": 1.45, "tv": 23052.97, "trd": NaN, "batb": [[0, 1.42, 569.55], [1, 1.41, 1291.3]], "batl": [[1, 1.45, 655.86]]}, {"timestamp": 1578772459942, "ltp": 1.45, "tv": 23052.97, "trd": NaN, "batb": [[2, 1.4, 2581.58]], "batl": NaN}, {"timestamp": 1578772460976, "ltp": 1.42, "tv": 23056.71, "trd": [[1.42, 964.27]], "batb": [[0, 1.42, 567.68], [2, 1.4, 2596.89]], "batl": [[1, 1.45, 735.68]]}, {"timestamp": 1578772461970, "ltp": 1.42, "tv": 23056.71, "trd": NaN, "batb": NaN, "batl": [[0, 1.45, 735.68], [1, 1.46, 856.49], [2, 1.47, 1396.98]]}, {"timestamp": 1578772462957, "ltp": 1.42, "tv": 23056.71, "trd": NaN, "batb": NaN, "batl": [[0, 1.44, 1270.58], [1, 1.45, 766.88], [2, 1.46, 779.49]]}, {"timestamp": 1578772463950, "ltp": 1.42, "tv": 23056.71, "trd": NaN, "batb": NaN, "batl": [[2, 1.46, 534.62]]}, {"timestamp": 1578772464986, "ltp": 1.42, "tv": 23056.71, "trd": NaN, "batb": [[0, 1.42, 385.45]], "batl": [[1, 1.45, 1013.44]]}, {"timestamp": 1578772465976, "ltp": 1.43, "tv": 23104.97, "trd": [[1.43, 1219.95]], "batb": [[2, 1.4, 1529.61]], "batl": [[0, 1.43, 2.94], [1, 1.44, 1296.49], [2, 1.45, 1013.44]]}, {"timestamp": 1578772467011, "ltp": 1.43, "tv": 23104.97, "trd": NaN, "batb": [[1, 1.41, 1308.32]], "batl": [[1, 1.44, 1329.57]]}, {"timestamp": 1578772468981, "ltp": 1.43, "tv": 23119.12, "trd": [[1.42, 975.49], [1.43, 1222.89]], "batb": [[0, 1.42, 379.84]], "batl": [[0, 1.44, 1813.21], [1, 1.45, 1013.44], [2, 1.46, 488.7]]}, {"timestamp": 1578772469989, "ltp": 1.42, "tv": 23179.12, "trd": [[1.42, 1035.49]], "batb": [[0, 1.42, 349.84]], "batl": [[0, 1.43, 2], [1, 1.44, 1896.78], [2, 1.45, 1013.44]]}, {"timestamp": 1578772471002, "ltp": 1.42, "tv": 23179.12, "trd": NaN, "batb": NaN, "batl": [[1, 1.44, 1661.41]]}, {"timestamp": 1578772471987, "ltp": 1.42, "tv": 23179.12, "trd": NaN, "batb": NaN, "batl": [[0, 1.43, 47.92]]}, {"timestamp": 1578772472982, "ltp": 1.42, "tv": 23252.99, "trd": [[1.42, 1061.65], [1.43, 1270.61]], "batb": [[0, 1.42, 336.76]], "batl": [[0, 1.44, 1661.62], [1, 1.45, 1013.44], [2, 1.46, 488.7]]}, {"timestamp": 1578772473967, "ltp": 1.42, "tv": 23252.99, "trd": NaN, "batb": [[0, 1.42, 44.87], [1, 1.41, 1494.99]], "batl": [[2, 1.46, 1388.7]]}, {"timestamp": 1578772476002, "ltp": 1.42, "tv": 23274.45, "trd": [[1.42, 1083.11]], "batb": [[0, 1.42, 34.14]], "batl": [[0, 1.43, 502.26], [1, 1.44, 1661.41], [2, 1.45, 1013.44]]}, {"timestamp": 1578772476996, "ltp": 1.43, "tv": 23274.75, "trd": [[1.43, 1270.9]], "batb": [[1, 1.41, 1158.89]], "batl": [[0, 1.43, 501.96]]}, {"timestamp": 1578772477990, "ltp": 1.42, "tv": 23312.12, "trd": [[1.42, 1120.48]], "batb": [[0, 1.42, 15.46]], "batl": [[0, 1.43, 504.38], [2, 1.45, 928.92]]}, {"timestamp": 1578772478977, "ltp": 1.43, "tv": 23462.99, "trd": [[1.42, 1266.74], [1.43, 1275.52]], "batb": [[0, 1.41, 1073.77], [1, 1.4, 1529.61], [2, 1.39, 1338.82]], "batl": [[0, 1.43, 499.77]]}, {"timestamp": 1578772480014, "ltp": 1.43, "tv": 23462.99, "trd": NaN, "batb": NaN, "batl": [[0, 1.43, 549.77]]}, {"timestamp": 1578772481003, "ltp": 1.43, "tv": 23462.99, "trd": NaN, "batb": [[2, 1.39, 2406.1]], "batl": NaN}, {"timestamp": 1578772481991, "ltp": 1.43, "tv": 23470.39, "trd": [[1.43, 1282.91]], "batb": NaN, "batl": [[0, 1.43, 542.37]]}, {"timestamp": 1578772482975, "ltp": 1.43, "tv": 23470.39, "trd": NaN, "batb": [[1, 1.4, 1544.66]], "batl": NaN}, {"timestamp": 1578772484013, "ltp": 1.43, "tv": 23470.39, "trd": NaN, "batb": NaN, "batl": [[1, 1.44, 390.83], [2, 1.45, 2610.02]]}, {"timestamp": 1578772484998, "ltp": 1.43, "tv": 23470.39, "trd": NaN, "batb": [[1, 1.4, 1345.51]], "batl": [[0, 1.43, 626.89]]}, {"timestamp": 1578772485999, "ltp": 1.43, "tv": 23470.39, "trd": NaN, "batb": [[1, 1.4, 1252.76]], "batl": NaN}, {"timestamp": 1578772487018, "ltp": 1.43, "tv": 23470.39, "trd": NaN, "batb": [[2, 1.39, 1872.46]], "batl": NaN}, {"timestamp": 1578772489012, "ltp": 1.43, "tv": 23470.53, "trd": [[1.43, 1283.05]], "batb": NaN, "batl": [[0, 1.43, 626.82]]}, {"timestamp": 1578772490991, "ltp": 1.43, "tv": 23470.53, "trd": NaN, "batb": [[0, 1.41, 1116.33]], "batl": NaN}, {"timestamp": 1578772491976, "ltp": 1.43, "tv": 23470.53, "trd": NaN, "batb": [[2, 1.39, 1893.74]], "batl": [[0, 1.43, 576.82], [1, 1.44, 2337.41], [2, 1.45, 928.92]]}, {"timestamp": 1578772494000, "ltp": 1.43, "tv": 23470.53, "trd": NaN, "batb": NaN, "batl": [[0, 1.43, 578.69]]}, {"timestamp": 1578772494988, "ltp": 1.42, "tv": 23473.52, "trd": [[1.42, 1269.73]], "batb": NaN, "batl": NaN}, {"timestamp": 1578772496028, "ltp": 1.42, "tv": 23473.52, "trd": NaN, "batb": NaN, "batl": [[1, 1.44, 2638.24]]}, {"timestamp": 1578772499031, "ltp": 1.42, "tv": 23511.78, "trd": [[1.42, 1308]], "batb": [[0, 1.41, 1099.31], [1, 1.4, 1297.15], [2, 1.39, 1771.74]], "batl": NaN}, {"timestamp": 1578772501021, "ltp": 1.42, "tv": 23511.78, "trd": NaN, "batb": [[0, 1.42, 31.7], [1, 1.41, 1099.31], [2, 1.4, 1297.15]], "batl": NaN}, {"timestamp": 1578772502995, "ltp": 1.42, "tv": 23513.35, "trd": [[1.42, 1309.56]], "batb": [[0, 1.42, 30.92], [1, 1.41, 1070.91]], "batl": [[2, 1.45, 543.92]]}, {"timestamp": 1578772503990, "ltp": 1.42, "tv": 23513.35, "trd": NaN, "batb": NaN, "batl": [[1, 1.44, 390.83], [2, 1.45, 45.92]]}, {"timestamp": 1578772504986, "ltp": 1.41, "tv": 23532.03, "trd": [[1.41, 18.68]], "batb": [[0, 1.41, 874.9], [1, 1.4, 1297.15], [2, 1.39, 1238.1]], "batl": NaN}, {"timestamp": 1578772506035, "ltp": 1.41, "tv": 23532.03, "trd": NaN, "batb": [[1, 1.4, 1314.17]], "batl": NaN}, {"timestamp": 1578772508024, "ltp": 1.41, "tv": 23532.03, "trd": NaN, "batb": [[0, 1.41, 832.34]], "batl": [[0, 1.42, 229.6], [1, 1.43, 578.69], [2, 1.44, 390.83]]}, {"timestamp": 1578772508908, "ltp": 1.41, "tv": 23532.03, "trd": NaN, "batb": [[0, 1.41, 280.68]], "batl": [[1, 1.43, 576.82]]}, {"timestamp": 1578772509998, "ltp": 1.41, "tv": 23532.03, "trd": NaN, "batb": NaN, "batl": [[0, 1.42, 248.29], [1, 1.43, 968.38]]}, {"timestamp": 1578772511050, "ltp": 1.42, "tv": 23532.14, "trd": [[1.42, 1309.67]], "batb": NaN, "batl": [[0, 1.42, 248.18], [1, 1.43, 1000.08]]}, {"timestamp": 1578772512036, "ltp": 1.42, "tv": 23532.14, "trd": NaN, "batb": [[0, 1.41, 51.08]], "batl": [[1, 1.43, 968.38]]}, {"timestamp": 1578772513037, "ltp": 1.42, "tv": 23532.14, "trd": NaN, "batb": [[1, 1.4, 890.57]], "batl": [[0, 1.42, 271.54]]}, {"timestamp": 1578772514014, "ltp": 1.42, "tv": 23532.14, "trd": NaN, "batb": [[1, 1.4, 1081.9]], "batl": [[2, 1.44, 248.27]]}, {"timestamp": 1578772514899, "ltp": 1.42, "tv": 23532.14, "trd": NaN, "batb": [[1, 1.4, 1124.46]], "batl": NaN}, {"timestamp": 1578772517038, "ltp": 1.42, "tv": 23535.87, "trd": [[1.42, 1313.4]], "batb": [[1, 1.4, 1107.44]], "batl": [[0, 1.42, 254.49], [1, 1.43, 965.96]]}, {"timestamp": 1578772518024, "ltp": 1.42, "tv": 23535.87, "trd": NaN, "batb": [[2, 1.39, 1216.82]], "batl": [[0, 1.42, 269.37]]}, {"timestamp": 1578772520046, "ltp": 1.42, "tv": 23535.87, "trd": NaN, "batb": [[0, 1.41, 12.81], [1, 1.4, 1078.24], [2, 1.39, 1301.94]], "batl": [[2, 1.44, 698.27]]}, {"timestamp": 1578772521033, "ltp": 1.42, "tv": 23535.87, "trd": NaN, "batb": NaN, "batl": [[0, 1.42, 413.65], [2, 1.44, 450]]}, {"timestamp": 1578772523056, "ltp": 1.41, "tv": 23539.61, "trd": [[1.41, 22.42]], "batb": [[0, 1.41, 10.94]], "batl": [[1, 1.43, 476.07]]}, {"timestamp": 1578772524044, "ltp": 1.4, "tv": 23576.98, "trd": [[1.4, 15.49], [1.41, 44.3]], "batb": [[0, 1.4, 530.5], [1, 1.39, 1301.94], [2, 1.38, 1873.13]], "batl": NaN}, {"timestamp": 1578772525043, "ltp": 1.4, "tv": 23576.98, "trd": NaN, "batb": [[2, 1.38, 1894.41]], "batl": [[0, 1.41, 15.31], [1, 1.42, 398.76], [2, 1.43, 1001.07]]}, {"timestamp": 1578772526033, "ltp": 1.4, "tv": 23576.98, "trd": NaN, "batb": [[0, 1.4, 308.64]], "batl": [[0, 1.41, 70.57]]}, {"timestamp": 1578772527019, "ltp": 1.4, "tv": 23576.98, "trd": NaN, "batb": [[0, 1.4, 117.3]], "batl": [[0, 1.41, 79.08], [1, 1.42, 1246.38]]}, {"timestamp": 1578772527957, "ltp": 1.4, "tv": 23576.98, "trd": NaN, "batb": NaN, "batl": [[0, 1.41, 82.58], [1, 1.42, 1498.15]]}, {"timestamp": 1578772529050, "ltp": 1.4, "tv": 23576.98, "trd": NaN, "batb": NaN, "batl": [[1, 1.42, 1529.85]]}, {"timestamp": 1578772530035, "ltp": 1.4, "tv": 23587.17, "trd": [[1.4, 25.68]], "batb": [[0, 1.4, 107.12]], "batl": [[0, 1.41, 572.47], [1, 1.42, 1498.15]]}, {"timestamp": 1578772531021, "ltp": 1.4, "tv": 23587.17, "trd": NaN, "batb": [[1, 1.39, 953.72]], "batl": NaN}, {"timestamp": 1578772531960, "ltp": 1.4, "tv": 23587.17, "trd": NaN, "batb": NaN, "batl": [[0, 1.41, 587.35], [1, 1.42, 1903.21]]}, {"timestamp": 1578772533055, "ltp": 1.4, "tv": 23587.17, "trd": NaN, "batb": NaN, "batl": [[0, 1.41, 93.97]]}, {"timestamp": 1578772534048, "ltp": 1.4, "tv": 23587.17, "trd": NaN, "batb": NaN, "batl": [[1, 1.42, 2231.77]]}, {"timestamp": 1578772535036, "ltp": 1.4, "tv": 23587.17, "trd": NaN, "batb": [[0, 1.4, 1522.14]], "batl": [[1, 1.42, 650.53], [2, 1.43, 1995.2]]}, {"timestamp": 1578772536036, "ltp": 1.41, "tv": 23743.79, "trd": [[1.41, 200.92]], "batb": [[0, 1.4, 678.12], [1, 1.39, 1149.97], [2, 1.38, 2010.41]], "batl": [[0, 1.41, 7.15], [1, 1.42, 422.9]]}, {"timestamp": 1578772538971, "ltp": 1.41, "tv": 23743.79, "trd": NaN, "batb": [[0, 1.4, 107.12]], "batl": [[0, 1.41, 2.3]]}, {"timestamp": 1578772539950, "ltp": 1.4, "tv": 24345.79, "trd": [[1.4, 627.68]], "batb": [[0, 1.39, 1064.85], [1, 1.38, 1894.41], [2, 1.37, 1987.96]], "batl": NaN}, {"timestamp": 1578772541044, "ltp": 1.41, "tv": 24358.63, "trd": [[1.4, 633.6], [1.41, 207.84]], "batb": NaN, "batl": [[0, 1.41, 224.98]]}, {"timestamp": 1578772541978, "ltp": 1.41, "tv": 24358.63, "trd": NaN, "batb": [[2, 1.37, 3540]], "batl": [[2, 1.43, 2460.77]]}, {"timestamp": 1578772542965, "ltp": 1.41, "tv": 24358.63, "trd": NaN, "batb": [[0, 1.39, 1119.76]], "batl": [[0, 1.4, 8.82], [1, 1.41, 224.98], [2, 1.42, 404.21]]}, {"timestamp": 1578772544050, "ltp": 1.4, "tv": 24376.28, "trd": [[1.4, 651.25]], "batb": [[0, 1.39, 1222.46]], "batl": [[0, 1.41, 224.98], [1, 1.42, 404.21], [2, 1.43, 2069.22]]}, {"timestamp": 1578772544979, "ltp": 1.4, "tv": 24376.28, "trd": NaN, "batb": [[0, 1.39, 1035.11]], "batl": NaN}, {"timestamp": 1578772545970, "ltp": 1.4, "tv": 24383.43, "trd": [[1.4, 658.39]], "batb": NaN, "batl": [[1, 1.42, 2025.96], [2, 1.43, 609.52]]}, {"timestamp": 1578772546997, "ltp": 1.41, "tv": 24608.41, "trd": [[1.41, 432.82]], "batb": [[1, 1.38, 2022.09]], "batl": [[0, 1.41, 31.7], [1, 1.42, 2027.66], [2, 1.43, 611.22]]}, {"timestamp": 1578772547985, "ltp": 1.41, "tv": 24618.01, "trd": [[1.41, 442.42]], "batb": [[1, 1.38, 2027.09], [2, 1.37, 1989.96]], "batl": [[0, 1.42, 2027.66], [1, 1.43, 611.22], [2, 1.44, 996.7]]}, {"timestamp": 1578772548972, "ltp": 1.41, "tv": 24618.01, "trd": NaN, "batb": [[1, 1.38, 2022.09]], "batl": NaN}, {"timestamp": 1578772549974, "ltp": 1.41, "tv": 24639.0, "trd": [[1.4, 677.08], [1.41, 444.73]], "batb": [[0, 1.4, 4.31], [1, 1.39, 1035.11], [2, 1.38, 1457.57]], "batl": [[0, 1.41, 149.82], [1, 1.42, 939.91], [2, 1.43, 611.22]]}, {"timestamp": 1578772551005, "ltp": 1.42, "tv": 25114.53, "trd": [[1.4, 704.27], [1.41, 820.86], [1.42, 1385.62]], "batb": [[0, 1.39, 828.39], [1, 1.38, 1253.8], [2, 1.37, 1435.11]], "batl": [[0, 1.42, 867.7], [1, 1.43, 611.22], [2, 1.44, 546.7]]}, {"timestamp": 1578772551989, "ltp": 1.4, "tv": 25171.91, "trd": [[1.4, 708.1], [1.42, 1439.17]], "batb": NaN, "batl": [[0, 1.42, 814.15]]}, {"timestamp": 1578772552975, "ltp": 1.4, "tv": 25684.59, "trd": [[1.4, 1220.78]], "batb": NaN, "batl": [[1, 1.43, 1061.22]]}, {"timestamp": 1578772553955, "ltp": 1.42, "tv": 25732.39, "trd": [[1.4, 1222.64], [1.42, 1485.09]], "batb": [[2, 1.37, 1438.61]], "batl": [[0, 1.42, 768.54]]}, {"timestamp": 1578772554993, "ltp": 1.42, "tv": 25740.59, "trd": [[1.42, 1493.3]], "batb": [[0, 1.39, 896.52]], "batl": [[0, 1.42, 760.34]]}, {"timestamp": 1578772555974, "ltp": 1.4, "tv": 25749.94, "trd": [[1.4, 1231.99]], "batb": [[0, 1.39, 1118.14]], "batl": NaN}, {"timestamp": 1578772556989, "ltp": 1.4, "tv": 25749.94, "trd": NaN, "batb": [[2, 1.37, 1455.63]], "batl": NaN}, {"timestamp": 1578772557972, "ltp": 1.4, "tv": 25751.81, "trd": [[1.4, 1233.86]], "batb": [[2, 1.37, 1476.91]], "batl": [[0, 1.42, 1210.34]]}, {"timestamp": 1578772559996, "ltp": 1.42, "tv": 25792.4, "trd": [[1.4, 1272.12], [1.42, 1495.62]], "batb": NaN, "batl": [[0, 1.42, 1320.03]]}, {"timestamp": 1578772560977, "ltp": 1.42, "tv": 25824.76, "trd": [[1.42, 1527.99]], "batb": NaN, "batl": [[0, 1.42, 1287.67]]}, {"timestamp": 1578772561985, "ltp": 1.42, "tv": 27112.43, "trd": [[1.42, 2815.66]], "batb": NaN, "batl": [[0, 1.42, 28.49]]}, {"timestamp": 1578772562968, "ltp": 1.42, "tv": 27225.36, "trd": [[1.42, 2928.59]], "batb": [[2, 1.37, 1459.89]], "batl": [[0, 1.43, 1061.22], [1, 1.44, 546.7], [2, 1.45, 539.28]]}, {"timestamp": 1578772564986, "ltp": 1.42, "tv": 27225.36, "trd": NaN, "batb": NaN, "batl": [[1, 1.44, 563.73]]}, {"timestamp": 1578772566024, "ltp": 1.41, "tv": 27289.38, "trd": [[1.4, 1330.47], [1.41, 826.53]], "batb": [[0, 1.41, 1.52], [1, 1.39, 1118.14], [2, 1.38, 1253.8]], "batl": NaN}, {"timestamp": 1578772568995, "ltp": 1.41, "tv": 27289.38, "trd": NaN, "batb": NaN, "batl": [[0, 1.42, 19.52], [1, 1.43, 861.23], [2, 1.44, 563.73]]}, {"timestamp": 1578772570027, "ltp": 1.41, "tv": 27289.38, "trd": NaN, "batb": NaN, "batl": [[0, 1.42, 54.42], [1, 1.43, 944.45]]}, {"timestamp": 1578772571010, "ltp": 1.4, "tv": 27324.57, "trd": [[1.4, 1362.63], [1.41, 829.56]], "batb": [[0, 1.39, 1118.14], [1, 1.38, 1253.8], [2, 1.37, 1274.95]], "batl": [[0, 1.42, 572.42], [1, 1.43, 971.35]]}, {"timestamp": 1578772573030, "ltp": 1.4, "tv": 27324.57, "trd": NaN, "batb": NaN, "batl": [[0, 1.42, 600.34]]}, {"timestamp": 1578772574008, "ltp": 1.4, "tv": 27324.57, "trd": NaN, "batb": NaN, "batl": [[0, 1.42, 934.98]]}, {"timestamp": 1578772576025, "ltp": 1.4, "tv": 27324.57, "trd": NaN, "batb": NaN, "batl": [[0, 1.42, 1384.98]]}, {"timestamp": 1578772577014, "ltp": 1.42, "tv": 27335.46, "trd": [[1.42, 2939.47]], "batb": NaN, "batl": [[0, 1.42, 1379.54]]}, {"timestamp": 1578772577992, "ltp": 1.4, "tv": 27508.51, "trd": [[1.4, 1535.69]], "batb": NaN, "batl": NaN}, {"timestamp": 1578772579021, "ltp": 1.4, "tv": 27661.58, "trd": [[1.4, 1688.76]], "batb": NaN, "batl": NaN}, {"timestamp": 1578772580004, "ltp": 1.4, "tv": 27661.58, "trd": NaN, "batb": [[1, 1.38, 1211.24], [2, 1.37, 1253.67]], "batl": [[1, 1.43, 992.63]]}, {"timestamp": 1578772580984, "ltp": 1.4, "tv": 27661.58, "trd": NaN, "batb": NaN, "batl": [[2, 1.44, 606.29]]}, {"timestamp": 1578772582029, "ltp": 1.4, "tv": 27663.45, "trd": [[1.4, 1690.63]], "batb": NaN, "batl": [[0, 1.42, 1829.54]]}, {"timestamp": 1578772584033, "ltp": 1.4, "tv": 27665.32, "trd": [[1.4, 1692.5]], "batb": [[1, 1.38, 1214.74]], "batl": NaN}, {"timestamp": 1578772585021, "ltp": 1.4, "tv": 27665.32, "trd": NaN, "batb": [[0, 1.41, 114.22], [1, 1.39, 1118.14], [2, 1.38, 1214.74]], "batl": NaN}, {"timestamp": 1578772588029, "ltp": 1.4, "tv": 27665.32, "trd": NaN, "batb": [[2, 1.38, 1129.62]], "batl": NaN}, {"timestamp": 1578772590033, "ltp": 1.4, "tv": 27665.32, "trd": NaN, "batb": NaN, "batl": [[0, 1.42, 1577.77]]}, {"timestamp": 1578772591011, "ltp": 1.41, "tv": 27700.94, "trd": [[1.41, 865.19]], "batb": [[0, 1.41, 96.4]], "batl": NaN}, {"timestamp": 1578772592053, "ltp": 1.41, "tv": 27797.35, "trd": [[1.41, 961.59]], "batb": [[0, 1.39, 1118.14], [1, 1.38, 1129.62], [2, 1.37, 1296.23]], "batl": [[2, 1.44, 589.26]]}, {"timestamp": 1578772595011, "ltp": 1.41, "tv": 27797.35, "trd": NaN, "batb": [[2, 1.37, 1381.35]], "batl": NaN}, {"timestamp": 1578772599042, "ltp": 1.41, "tv": 27797.35, "trd": NaN, "batb": NaN, "batl": [[1, 1.43, 1009.65]]}, {"timestamp": 1578772601025, "ltp": 1.4, "tv": 27898.62, "trd": [[1.4, 1793.77]], "batb": NaN, "batl": NaN}, {"timestamp": 1578772602953, "ltp": 1.4, "tv": 27898.62, "trd": NaN, "batb": [[0, 1.39, 921.9]], "batl": NaN}, {"timestamp": 1578772604041, "ltp": 1.4, "tv": 27898.62, "trd": NaN, "batb": [[0, 1.39, 350.9]], "batl": NaN}, {"timestamp": 1578772605031, "ltp": 1.4, "tv": 27898.62, "trd": NaN, "batb": NaN, "batl": [[0, 1.42, 3174.52]]}, {"timestamp": 1578772605967, "ltp": 1.4, "tv": 27898.85, "trd": [[1.4, 1794]], "batb": NaN, "batl": [[0, 1.41, 621.39], [1, 1.42, 2724.52], [2, 1.43, 1009.65]]}, {"timestamp": 1578772606952, "ltp": 1.4, "tv": 27898.85, "trd": NaN, "batb": NaN, "batl": [[1, 1.42, 2274.52]]}, {"timestamp": 1578772608041, "ltp": 1.4, "tv": 27898.85, "trd": NaN, "batb": [[2, 1.37, 1379.35]], "batl": NaN}, {"timestamp": 1578772609036, "ltp": 1.4, "tv": 27898.85, "trd": NaN, "batb": [[0, 1.39, 68.6]], "batl": [[0, 1.41, 44.39], [1, 1.42, 159.77], [2, 1.43, 484.65]]}, {"timestamp": 1578772609957, "ltp": 1.4, "tv": 27898.85, "trd": NaN, "batb": [[0, 1.39, 38.27]], "batl": [[2, 1.43, 457.75]]}, {"timestamp": 1578772611053, "ltp": 1.4, "tv": 27898.85, "trd": NaN, "batb": NaN, "batl": [[1, 1.42, 145.69]]}, {"timestamp": 1578772611983, "ltp": 1.4, "tv": 27898.85, "trd": NaN, "batb": [[1, 1.38, 1331.03]], "batl": NaN}, {"timestamp": 1578772613960, "ltp": 1.4, "tv": 27898.85, "trd": NaN, "batb": NaN, "batl": [[0, 1.41, 494.39], [1, 1.42, 397.45], [2, 1.43, 207.75]]}, {"timestamp": 1578772615043, "ltp": 1.4, "tv": 27898.85, "trd": NaN, "batb": [[0, 1.38, 1331.03], [1, 1.37, 1379.35], [2, 1.36, 3457.15]], "batl": [[0, 1.41, 944.39], [2, 1.43, 124.52]]}, {"timestamp": 1578772616031, "ltp": 1.4, "tv": 27898.85, "trd": NaN, "batb": [[0, 1.39, 550], [1, 1.38, 1331.03], [2, 1.37, 1379.35]], "batl": NaN}, {"timestamp": 1578772616964, "ltp": 1.4, "tv": 27898.85, "trd": NaN, "batb": [[0, 1.38, 1331.03], [1, 1.37, 1379.35], [2, 1.36, 3457.15]], "batl": [[0, 1.41, 972.49]]}, {"timestamp": 1578772618052, "ltp": 1.41, "tv": 27988.83, "trd": [[1.41, 1051.58]], "batb": [[1, 1.37, 1336.79]], "batl": [[0, 1.41, 961.53]]}, {"timestamp": 1578772618979, "ltp": 1.41, "tv": 27988.83, "trd": NaN, "batb": [[0, 1.39, 229.6], [1, 1.38, 1331.03], [2, 1.37, 1338.79]], "batl": NaN}, {"timestamp": 1578772619962, "ltp": 1.41, "tv": 27988.83, "trd": NaN, "batb": [[0, 1.38, 1331.03], [1, 1.37, 1338.79], [2, 1.36, 3457.15]], "batl": NaN}, {"timestamp": 1578772621007, "ltp": 1.41, "tv": 27988.83, "trd": NaN, "batb": NaN, "batl": [[0, 1.41, 1215.08]]}, {"timestamp": 1578772622048, "ltp": 1.41, "tv": 27988.83, "trd": NaN, "batb": NaN, "batl": [[0, 1.41, 1297.63], [2, 1.43, 107.5]]}, {"timestamp": 1578772622982, "ltp": 1.41, "tv": 27988.83, "trd": NaN, "batb": NaN, "batl": [[1, 1.42, 927.45], [2, 1.43, 629.5]]}, {"timestamp": 1578772623990, "ltp": 1.41, "tv": 27988.83, "trd": NaN, "batb": [[2, 1.36, 2707.15]], "batl": [[0, 1.41, 847.63]]}, {"timestamp": 1578772624980, "ltp": 1.41, "tv": 27988.83, "trd": NaN, "batb": [[2, 1.36, 2749.71]], "batl": [[0, 1.41, 398.23]]}, {"timestamp": 1578772625973, "ltp": 1.41, "tv": 27988.83, "trd": NaN, "batb": NaN, "batl": [[1, 1.42, 2587.51]]}, {"timestamp": 1578772628005, "ltp": 1.41, "tv": 27988.83, "trd": NaN, "batb": [[1, 1.37, 1253.67]], "batl": NaN}, {"timestamp": 1578772628997, "ltp": 1.41, "tv": 27988.83, "trd": NaN, "batb": NaN, "batl": [[1, 1.42, 2604.54]]}, {"timestamp": 1578772630966, "ltp": 1.41, "tv": 27988.83, "trd": NaN, "batb": [[0, 1.39, 550], [1, 1.38, 1331.03], [2, 1.37, 2601.48]], "batl": [[1, 1.42, 944.48]]}, {"timestamp": 1578772632015, "ltp": 1.41, "tv": 27988.83, "trd": NaN, "batb": NaN, "batl": [[0, 1.41, 1298.23], [2, 1.43, 544.98]]}, {"timestamp": 1578772633989, "ltp": 1.41, "tv": 27988.83, "trd": NaN, "batb": [[2, 1.37, 1250.17]], "batl": [[2, 1.43, 2225.97]]}, {"timestamp": 1578772634971, "ltp": 1.39, "tv": 28218.43, "trd": [[1.39, 229.6]], "batb": [[0, 1.39, 435.2]], "batl": [[1, 1.42, 927.45]]}, {"timestamp": 1578772637993, "ltp": 1.39, "tv": 28218.43, "trd": NaN, "batb": [[1, 1.38, 1333.03]], "batl": NaN}, {"timestamp": 1578772638985, "ltp": 1.39, "tv": 28218.43, "trd": NaN, "batb": [[0, 1.38, 1331.03], [1, 1.37, 1250.17], [2, 1.36, 3328.54]], "batl": NaN}, {"timestamp": 1578772639970, "ltp": 1.39, "tv": 28218.43, "trd": NaN, "batb": [[1, 1.37, 1379.68], [2, 1.36, 3285.98]], "batl": NaN}, {"timestamp": 1578772642000, "ltp": 1.39, "tv": 28218.43, "trd": NaN, "batb": [[0, 1.38, 1346.66]], "batl": [[2, 1.43, 2243]]}, {"timestamp": 1578772642998, "ltp": 1.39, "tv": 28218.43, "trd": NaN, "batb": [[2, 1.36, 3264.7]], "batl": NaN}, {"timestamp": 1578772646010, "ltp": 1.39, "tv": 28218.43, "trd": NaN, "batb": [[2, 1.36, 1903.27]], "batl": NaN}, {"timestamp": 1578772646995, "ltp": 1.4, "tv": 28246.88, "trd": [[1.4, 1822.45]], "batb": [[1, 1.37, 2720.28], [2, 1.36, 1276.98]], "batl": NaN}, {"timestamp": 1578772649011, "ltp": 1.4, "tv": 28246.88, "trd": NaN, "batb": [[0, 1.39, 546], [1, 1.38, 1145.25], [2, 1.37, 2720.28]], "batl": NaN}, {"timestamp": 1578772651814, "ltp": 1.4, "tv": 28246.88, "trd": NaN, "batb": NaN, "batl": [[0, 1.41, 1298.92]]}, {"timestamp": 1578772653017, "ltp": 1.4, "tv": 28246.88, "trd": NaN, "batb": [[1, 1.38, 1160.56], [2, 1.37, 1422.24]], "batl": NaN}, {"timestamp": 1578772655001, "ltp": 1.4, "tv": 28246.88, "trd": NaN, "batb": [[0, 1.39, 590.99]], "batl": [[0, 1.4, 2.56], [1, 1.41, 1298.23], [2, 1.42, 927.45]]}, {"timestamp": 1578772658023, "ltp": 1.4, "tv": 28246.88, "trd": NaN, "batb": [[2, 1.37, 1629.09]], "batl": NaN}, {"timestamp": 1578772659007, "ltp": 1.4, "tv": 28246.88, "trd": NaN, "batb": [[1, 1.38, 1162.56]], "batl": NaN}, {"timestamp": 1578772659991, "ltp": 1.4, "tv": 28246.88, "trd": NaN, "batb": NaN, "batl": [[0, 1.4, 24.83]]}, {"timestamp": 1578772662017, "ltp": 1.4, "tv": 28246.88, "trd": NaN, "batb": [[0, 1.39, 44.99]], "batl": NaN}, {"timestamp": 1578772665038, "ltp": 1.39, "tv": 28251.47, "trd": [[1.39, 234.19]], "batb": [[0, 1.39, 42.7]], "batl": [[0, 1.4, 1.87]]}, {"timestamp": 1578772666033, "ltp": 1.39, "tv": 28259.99, "trd": [[1.39, 242.71]], "batb": [[0, 1.39, 38.44]], "batl": [[1, 1.41, 1840.23]]}, {"timestamp": 1578772667016, "ltp": 1.39, "tv": 28261.37, "trd": [[1.39, 244.09]], "batb": [[0, 1.39, 37.75]], "batl": NaN}, {"timestamp": 1578772672056, "ltp": 1.39, "tv": 28307.29, "trd": [[1.39, 290.01]], "batb": [[0, 1.39, 14.79]], "batl": [[0, 1.41, 1840.23], [1, 1.42, 944.48], [2, 1.43, 535.7]]}, {"timestamp": 1578772673046, "ltp": 1.39, "tv": 28307.29, "trd": NaN, "batb": NaN, "batl": [[1, 1.42, 965.76]]}, {"timestamp": 1578772674034, "ltp": 1.39, "tv": 28307.29, "trd": NaN, "batb": [[0, 1.39, 21.79]], "batl": NaN}, {"timestamp": 1578772675953, "ltp": 1.39, "tv": 28308.1, "trd": [[1.39, 290.81]], "batb": [[0, 1.39, 21.39]], "batl": NaN}, {"timestamp": 1578772677048, "ltp": 1.39, "tv": 28308.1, "trd": NaN, "batb": [[1, 1.38, 1160.56]], "batl": NaN}, {"timestamp": 1578772679028, "ltp": 1.39, "tv": 28311.83, "trd": [[1.39, 294.55]], "batb": [[0, 1.39, 19.52], [2, 1.37, 1543.97]], "batl": NaN}, {"timestamp": 1578772681049, "ltp": 1.39, "tv": 28311.83, "trd": NaN, "batb": [[0, 1.39, 51.22]], "batl": NaN}, {"timestamp": 1578772682052, "ltp": 1.4, "tv": 28317.57, "trd": [[1.4, 1828.18]], "batb": NaN, "batl": [[0, 1.4, 11.29], [1, 1.41, 1840.23], [2, 1.42, 965.76]]}, {"timestamp": 1578772686033, "ltp": 1.4, "tv": 28317.57, "trd": NaN, "batb": NaN, "batl": [[1, 1.41, 1390.23]]}, {"timestamp": 1578772690956, "ltp": 1.4, "tv": 28317.57, "trd": NaN, "batb": [[0, 1.39, 46.22], [2, 1.37, 1501.41]], "batl": NaN}, {"timestamp": 1578772693968, "ltp": 1.4, "tv": 28317.57, "trd": NaN, "batb": [[1, 1.38, 1162.56]], "batl": [[0, 1.4, 461.29]]}, {"timestamp": 1578772694955, "ltp": 1.4, "tv": 28317.57, "trd": NaN, "batb": [[0, 1.39, 14.52], [1, 1.38, 890.53]], "batl": [[2, 1.42, 930.87]]}, {"timestamp": 1578772696040, "ltp": 1.4, "tv": 28317.57, "trd": NaN, "batb": NaN, "batl": [[2, 1.42, 902.95]]}, {"timestamp": 1578772701957, "ltp": 1.39, "tv": 28336.26, "trd": [[1.39, 313.24]], "batb": [[0, 1.39, 5.18]], "batl": [[0, 1.4, 512.25]]}, {"timestamp": 1578772703044, "ltp": 1.39, "tv": 28340.26, "trd": [[1.39, 317.24]], "batb": [[0, 1.39, 3.18], [1, 1.38, 888.53]], "batl": [[0, 1.4, 541.75]]}, {"timestamp": 1578772704966, "ltp": 1.39, "tv": 28340.26, "trd": NaN, "batb": [[0, 1.39, 2], [1, 1.38, 860.09]], "batl": [[2, 1.42, 568.3]]}, {"timestamp": 1578772706050, "ltp": 1.39, "tv": 28340.26, "trd": NaN, "batb": NaN, "batl": [[1, 1.41, 848.23]]}, {"timestamp": 1578772707982, "ltp": 1.39, "tv": 28340.26, "trd": NaN, "batb": NaN, "batl": [[0, 1.4, 1889.99]]}, {"timestamp": 1578772710029, "ltp": 1.39, "tv": 28344.25, "trd": [[1.39, 321.23]], "batb": [[0, 1.38, 860.09], [1, 1.37, 1501.41], [2, 1.36, 2044.67]], "batl": [[0, 1.4, 542.05], [2, 1.42, 38.3]]}, {"timestamp": 1578772710966, "ltp": 1.39, "tv": 28344.55, "trd": [[1.39, 321.53]], "batb": NaN, "batl": [[0, 1.4, 541.75]]}, {"timestamp": 1578772712014, "ltp": 1.39, "tv": 28344.55, "trd": NaN, "batb": NaN, "batl": [[0, 1.4, 431.13], [1, 1.41, 398.23]]}, {"timestamp": 1578772715998, "ltp": 1.39, "tv": 28344.55, "trd": NaN, "batb": [[0, 1.38, 630.49]], "batl": NaN}, {"timestamp": 1578772717040, "ltp": 1.39, "tv": 28344.55, "trd": NaN, "batb": [[1, 1.37, 1499.41]], "batl": NaN}, {"timestamp": 1578772717983, "ltp": 1.39, "tv": 28344.55, "trd": NaN, "batb": [[0, 1.38, 49.49]], "batl": [[2, 1.42, 80.86]]}, {"timestamp": 1578772718985, "ltp": 1.39, "tv": 28344.55, "trd": NaN, "batb": NaN, "batl": [[2, 1.42, 530.86]]}, {"timestamp": 1578772720049, "ltp": 1.39, "tv": 28344.55, "trd": NaN, "batb": NaN, "batl": [[0, 1.4, 401.63]]}, {"timestamp": 1578772720992, "ltp": 1.39, "tv": 28344.55, "trd": NaN, "batb": NaN, "batl": [[0, 1.4, 967.63], [1, 1.41, 944.23], [2, 1.42, 1068.58]]}, {"timestamp": 1578772722035, "ltp": 1.39, "tv": 28344.55, "trd": NaN, "batb": [[2, 1.36, 2002.11]], "batl": NaN}, {"timestamp": 1578772724004, "ltp": 1.39, "tv": 28344.55, "trd": NaN, "batb": [[2, 1.36, 1916.98]], "batl": NaN}, {"timestamp": 1578772724995, "ltp": 1.39, "tv": 28344.55, "trd": NaN, "batb": [[1, 1.37, 1501.41]], "batl": NaN}, {"timestamp": 1578772726992, "ltp": 1.38, "tv": 28344.75, "trd": [[1.38, 0.2]], "batb": [[0, 1.38, 49.39]], "batl": NaN}, {"timestamp": 1578772728034, "ltp": 1.38, "tv": 28344.75, "trd": NaN, "batb": NaN, "batl": [[0, 1.4, 451.81]]}, {"timestamp": 1578772731023, "ltp": 1.38, "tv": 28362.75, "trd": [[1.38, 18.2]], "batb": [[0, 1.38, 40.39]], "batl": NaN}, {"timestamp": 1578772732012, "ltp": 1.38, "tv": 28362.75, "trd": NaN, "batb": NaN, "batl": [[1, 1.41, 398.23]]}, {"timestamp": 1578772734043, "ltp": 1.38, "tv": 28443.53, "trd": [[1.38, 98.98]], "batb": [[0, 1.37, 1501.41], [1, 1.36, 1916.98], [2, 1.35, 3308.34]], "batl": [[0, 1.38, 1.15], [1, 1.4, 451.81], [2, 1.41, 1819.34]]}, {"timestamp": 1578772735037, "ltp": 1.38, "tv": 28445.82, "trd": [[1.38, 101.27]], "batb": [[0, 1.38, 618.85], [1, 1.37, 1501.41], [2, 1.36, 3731.41]], "batl": [[0, 1.4, 451.81], [1, 1.41, 398.23], [2, 1.42, 1068.58]]}, {"timestamp": 1578772736024, "ltp": 1.38, "tv": 28445.82, "trd": NaN, "batb": NaN, "batl": [[1, 1.41, 848.23]]}, {"timestamp": 1578772738011, "ltp": 1.38, "tv": 28445.82, "trd": NaN, "batb": [[1, 1.37, 1499.41]], "batl": NaN}, {"timestamp": 1578772739049, "ltp": 1.38, "tv": 28445.82, "trd": NaN, "batb": NaN, "batl": [[0, 1.4, 167.55], [2, 1.42, 1051.56]]}, {"timestamp": 1578772742028, "ltp": 1.38, "tv": 28445.82, "trd": NaN, "batb": NaN, "batl": [[0, 1.4, 153.08]]}, {"timestamp": 1578772744018, "ltp": 1.38, "tv": 28445.82, "trd": NaN, "batb": NaN, "batl": [[2, 1.42, 1136.68]]}, {"timestamp": 1578772745018, "ltp": 1.38, "tv": 28645.82, "trd": [[1.38, 301.27]], "batb": [[0, 1.38, 518.85]], "batl": [[1, 1.41, 1382.23], [2, 1.42, 1051.56]]}, {"timestamp": 1578772746006, "ltp": 1.38, "tv": 28645.82, "trd": NaN, "batb": [[0, 1.38, 547.6], [1, 1.37, 1584.53]], "batl": NaN}, {"timestamp": 1578772747044, "ltp": 1.38, "tv": 28645.82, "trd": NaN, "batb": [[2, 1.36, 3748.44]], "batl": [[0, 1.4, 181.98]]}, {"timestamp": 1578772748038, "ltp": 1.38, "tv": 28742.26, "trd": [[1.38, 397.71]], "batb": [[0, 1.38, 499.38]], "batl": NaN}, {"timestamp": 1578772749029, "ltp": 1.38, "tv": 28742.26, "trd": NaN, "batb": NaN, "batl": [[2, 1.42, 2401.31]]}, {"timestamp": 1578772750021, "ltp": 1.38, "tv": 28742.26, "trd": NaN, "batb": [[1, 1.37, 1586.53]], "batl": NaN}, {"timestamp": 1578772751007, "ltp": 1.38, "tv": 28742.26, "trd": NaN, "batb": [[0, 1.38, 736.01]], "batl": NaN}, {"timestamp": 1578772753040, "ltp": 1.38, "tv": 28742.26, "trd": NaN, "batb": [[1, 1.37, 1501.41]], "batl": NaN}, {"timestamp": 1578772754919, "ltp": 1.38, "tv": 28742.7, "trd": [[1.38, 398.15]], "batb": [[0, 1.38, 735.79]], "batl": NaN}, {"timestamp": 1578772756022, "ltp": 1.38, "tv": 28742.7, "trd": NaN, "batb": [[0, 1.38, 707.04]], "batl": NaN}, {"timestamp": 1578772756953, "ltp": 1.38, "tv": 28742.7, "trd": NaN, "batb": [[2, 1.36, 3731.41]], "batl": NaN}, {"timestamp": 1578772758052, "ltp": 1.38, "tv": 28742.7, "trd": NaN, "batb": [[1, 1.37, 1499.41]], "batl": NaN}, {"timestamp": 1578772759044, "ltp": 1.38, "tv": 28942.7, "trd": [[1.38, 598.15]], "batb": [[0, 1.38, 607.04]], "batl": NaN}, {"timestamp": 1578772759930, "ltp": 1.38, "tv": 29104.43, "trd": [[1.38, 759.88]], "batb": [[0, 1.38, 526.18], [2, 1.36, 3816.54]], "batl": NaN}, {"timestamp": 1578772761027, "ltp": 1.4, "tv": 29121.32, "trd": [[1.4, 1845.07]], "batb": NaN, "batl": [[0, 1.4, 173.54]]}, {"timestamp": 1578772761957, "ltp": 1.4, "tv": 29121.32, "trd": NaN, "batb": NaN, "batl": [[0, 1.4, 428.9]]}, {"timestamp": 1578772763042, "ltp": 1.4, "tv": 29121.32, "trd": NaN, "batb": [[2, 1.36, 4203.47]], "batl": [[2, 1.42, 1051.56]]}, {"timestamp": 1578772764959, "ltp": 1.4, "tv": 29121.32, "trd": NaN, "batb": NaN, "batl": [[1, 1.41, 1474.73], [2, 1.42, 1148.81]]}, {"timestamp": 1578772769051, "ltp": 1.4, "tv": 29121.32, "trd": NaN, "batb": [[0, 1.38, 236.63], [2, 1.36, 4034.47]], "batl": NaN}, {"timestamp": 1578772769986, "ltp": 1.4, "tv": 29121.32, "trd": NaN, "batb": NaN, "batl": [[0, 1.4, 524.94], [2, 1.42, 1051.56]]}, {"timestamp": 1578772774042, "ltp": 1.4, "tv": 29121.32, "trd": NaN, "batb": [[2, 1.36, 3284.47]], "batl": [[1, 1.41, 1024.73], [2, 1.42, 601.56]]}, {"timestamp": 1578772775033, "ltp": 1.4, "tv": 29121.32, "trd": NaN, "batb": [[2, 1.36, 2692.22]], "batl": [[2, 1.42, 2279.81]]}, {"timestamp": 1578772775969, "ltp": 1.4, "tv": 29121.32, "trd": NaN, "batb": NaN, "batl": [[0, 1.4, 1105.94]]}, {"timestamp": 1578772776956, "ltp": 1.4, "tv": 29121.32, "trd": NaN, "batb": NaN, "batl": [[2, 1.42, 2370.06]]}, {"timestamp": 1578772777992, "ltp": 1.37, "tv": 29197.85, "trd": [[1.37, 76.54]], "batb": [[0, 1.37, 1461.14], [1, 1.36, 2692.22], [2, 1.35, 1262.81]], "batl": [[1, 1.41, 990.7], [2, 1.42, 2279.81]]}, {"timestamp": 1578772781050, "ltp": 1.37, "tv": 29197.85, "trd": NaN, "batb": NaN, "batl": [[0, 1.38, 31.17], [1, 1.4, 1105.94], [2, 1.41, 990.7]]}, {"timestamp": 1578772781982, "ltp": 1.37, "tv": 29197.85, "trd": NaN, "batb": [[0, 1.37, 1111.3], [1, 1.36, 2688.72]], "batl": [[0, 1.38, 38.82], [2, 1.41, 908.15]]}, {"timestamp": 1578772782975, "ltp": 1.38, "tv": 29214.91, "trd": [[1.38, 776.94]], "batb": [[0, 1.37, 1081.67]], "batl": [[0, 1.38, 21.76], [1, 1.4, 1009.9], [2, 1.41, 787.55]]}, {"timestamp": 1578772783960, "ltp": 1.38, "tv": 29214.91, "trd": NaN, "batb": [[0, 1.37, 874.82]], "batl": NaN}, {"timestamp": 1578772784993, "ltp": 1.38, "tv": 29214.91, "trd": NaN, "batb": NaN, "batl": [[1, 1.39, 68.87], [2, 1.4, 1009.9]]}, {"timestamp": 1578772785988, "ltp": 1.38, "tv": 29214.91, "trd": NaN, "batb": [[1, 1.36, 3438.72]], "batl": NaN}, {"timestamp": 1578772788995, "ltp": 1.38, "tv": 29236.68, "trd": [[1.38, 798.7]], "batb": NaN, "batl": [[0, 1.39, 182.33], [1, 1.4, 1009.9], [2, 1.41, 534]]}, {"timestamp": 1578772790987, "ltp": 1.38, "tv": 29236.68, "trd": NaN, "batb": NaN, "batl": [[1, 1.4, 1052.46]]}, {"timestamp": 1578772792022, "ltp": 1.37, "tv": 29236.72, "trd": [[1.37, 76.58]], "batb": [[0, 1.37, 874.8]], "batl": NaN}, {"timestamp": 1578772793002, "ltp": 1.39, "tv": 29245.03, "trd": [[1.39, 329.84]], "batb": NaN, "batl": [[0, 1.39, 435.38]]}, {"timestamp": 1578772793985, "ltp": 1.39, "tv": 29245.03, "trd": NaN, "batb": [[1, 1.36, 3651.31]], "batl": [[0, 1.39, 178.18], [1, 1.4, 1502.46]]}, {"timestamp": 1578772796021, "ltp": 1.39, "tv": 29245.03, "trd": NaN, "batb": [[2, 1.35, 1265.37]], "batl": [[2, 1.41, 618.5]]}, {"timestamp": 1578772802014, "ltp": 1.39, "tv": 29245.03, "trd": NaN, "batb": [[1, 1.36, 2211.2], [2, 1.35, 3313.64]], "batl": NaN}, {"timestamp": 1578772803018, "ltp": 1.39, "tv": 29245.03, "trd": NaN, "batb": [[0, 1.37, 645.19]], "batl": NaN}, {"timestamp": 1578772804005, "ltp": 1.39, "tv": 29245.03, "trd": NaN, "batb": NaN, "batl": [[2, 1.41, 534]]}, {"timestamp": 1578772806013, "ltp": 1.37, "tv": 29258.09, "trd": [[1.37, 89.64]], "batb": [[0, 1.37, 638.66], [1, 1.36, 2126.08]], "batl": NaN}, {"timestamp": 1578772807009, "ltp": 1.37, "tv": 29258.09, "trd": NaN, "batb": [[0, 1.38, 9.79], [1, 1.37, 638.66], [2, 1.36, 2126.08]], "batl": NaN}, {"timestamp": 1578772807994, "ltp": 1.37, "tv": 29258.09, "trd": NaN, "batb": NaN, "batl": [[2, 1.41, 1921.5]]}, {"timestamp": 1578772810021, "ltp": 1.38, "tv": 29261.83, "trd": [[1.38, 802.44]], "batb": [[0, 1.38, 7.92]], "batl": NaN}, {"timestamp": 1578772811015, "ltp": 1.38, "tv": 29261.83, "trd": NaN, "batb": [[0, 1.38, 6.04]], "batl": NaN}, {"timestamp": 1578772812031, "ltp": 1.38, "tv": 29261.83, "trd": NaN, "batb": NaN, "batl": [[2, 1.41, 534]]}, {"timestamp": 1578772813024, "ltp": 1.38, "tv": 29261.83, "trd": NaN, "batb": NaN, "batl": [[2, 1.41, 984]]}, {"timestamp": 1578772813906, "ltp": 1.38, "tv": 29273.91, "trd": [[1.38, 814.52]], "batb": [[0, 1.37, 638.66], [1, 1.36, 2126.08], [2, 1.35, 1333.46]], "batl": NaN}, {"timestamp": 1578772814998, "ltp": 1.38, "tv": 29273.91, "trd": NaN, "batb": [[0, 1.37, 86.48]], "batl": NaN}, {"timestamp": 1578772816037, "ltp": 1.38, "tv": 29273.91, "trd": NaN, "batb": NaN, "batl": [[0, 1.39, 1016.38], [2, 1.41, 1069.5]]}, {"timestamp": 1578772819047, "ltp": 1.37, "tv": 29504.28, "trd": [[1.37, 320.01]], "batb": [[0, 1.36, 2126.08], [1, 1.35, 1333.46], [2, 1.34, 3401.49]], "batl": [[0, 1.37, 621.46], [1, 1.39, 1016.38], [2, 1.4, 1459.9]]}, {"timestamp": 1578772820030, "ltp": 1.37, "tv": 29504.28, "trd": NaN, "batb": [[0, 1.36, 1925.42]], "batl": [[2, 1.4, 1168.04]]}, {"timestamp": 1578772821016, "ltp": 1.37, "tv": 29504.28, "trd": NaN, "batb": [[0, 1.36, 1805.79]], "batl": [[2, 1.4, 2474.36]]}, {"timestamp": 1578772823055, "ltp": 1.37, "tv": 29504.28, "trd": NaN, "batb": [[1, 1.35, 2782.93]], "batl": NaN}, {"timestamp": 1578772824037, "ltp": 1.37, "tv": 29504.28, "trd": NaN, "batb": [[0, 1.36, 1803.79], [2, 1.34, 1380.77]], "batl": [[2, 1.4, 1055.12]]}, {"timestamp": 1578772825038, "ltp": 1.37, "tv": 29504.28, "trd": NaN, "batb": NaN, "batl": [[1, 1.39, 1031.39]]}, {"timestamp": 1578772826028, "ltp": 1.37, "tv": 29504.28, "trd": NaN, "batb": NaN, "batl": [[2, 1.4, 605.12]]}, {"timestamp": 1578772827020, "ltp": 1.37, "tv": 29504.28, "trd": NaN, "batb": NaN, "batl": [[1, 1.38, 296.15], [2, 1.39, 1031.39]]}, {"timestamp": 1578772827954, "ltp": 1.37, "tv": 29504.28, "trd": NaN, "batb": [[0, 1.36, 1829.36]], "batl": [[0, 1.37, 659.73], [1, 1.38, 417.02]]}, {"timestamp": 1578772829046, "ltp": 1.37, "tv": 29504.28, "trd": NaN, "batb": [[0, 1.36, 1079.36]], "batl": NaN}, {"timestamp": 1578772831964, "ltp": 1.37, "tv": 29504.28, "trd": NaN, "batb": NaN, "batl": [[0, 1.37, 38.27]]}, {"timestamp": 1578772834052, "ltp": 1.37, "tv": 29504.28, "trd": NaN, "batb": [[1, 1.35, 1333.46], [2, 1.34, 3284.31]], "batl": [[2, 1.39, 1481.39]]}, {"timestamp": 1578772835030, "ltp": 1.37, "tv": 29504.28, "trd": NaN, "batb": [[0, 1.36, 1085.49]], "batl": NaN}, {"timestamp": 1578772835964, "ltp": 1.37, "tv": 29504.28, "trd": NaN, "batb": [[0, 1.36, 1053.79]], "batl": NaN}, {"timestamp": 1578772836959, "ltp": 1.37, "tv": 29580.81, "trd": [[1.37, 396.54]], "batb": [[0, 1.37, 42.74], [1, 1.36, 1053.79], [2, 1.35, 1333.46]], "batl": [[0, 1.38, 417.02], [1, 1.39, 1481.39], [2, 1.4, 2142.56]]}, {"timestamp": 1578772839029, "ltp": 1.36, "tv": 30716.8, "trd": [[1.36, 1093.25], [1.37, 439.28]], "batb": [[0, 1.35, 1333.46], [1, 1.34, 4039.03], [2, 1.33, 2416.16]], "batl": [[2, 1.4, 2592.56]]}, {"timestamp": 1578772839965, "ltp": 1.36, "tv": 30716.8, "trd": NaN, "batb": NaN, "batl": [[2, 1.4, 2604.56]]}, {"timestamp": 1578772840957, "ltp": 1.36, "tv": 30716.8, "trd": NaN, "batb": NaN, "batl": [[0, 1.38, 1027.02], [2, 1.4, 2698.15]]}, {"timestamp": 1578772842055, "ltp": 1.36, "tv": 30716.8, "trd": NaN, "batb": [[0, 1.37, 27.15], [1, 1.35, 1333.46], [2, 1.34, 4039.03]], "batl": NaN}, {"timestamp": 1578772842952, "ltp": 1.36, "tv": 30716.8, "trd": NaN, "batb": [[1, 1.35, 2620.01]], "batl": [[2, 1.4, 1160.71]]}, {"timestamp": 1578772843992, "ltp": 1.36, "tv": 30716.8, "trd": NaN, "batb": NaN, "batl": [[1, 1.39, 2546.89]]}, {"timestamp": 1578772844986, "ltp": 1.36, "tv": 30716.8, "trd": NaN, "batb": [[0, 1.37, 14.17], [1, 1.35, 1248.34]], "batl": NaN}, {"timestamp": 1578772845978, "ltp": 1.36, "tv": 30716.8, "trd": NaN, "batb": NaN, "batl": [[2, 1.4, 710.71]]}, {"timestamp": 1578772848979, "ltp": 1.37, "tv": 30765.14, "trd": [[1.37, 487.62]], "batb": [[0, 1.35, 1157.73], [1, 1.34, 4039.03], [2, 1.33, 2390.62]], "batl": [[0, 1.37, 205.43], [1, 1.38, 1027.02], [2, 1.39, 2433.43]]}, {"timestamp": 1578772849970, "ltp": 1.37, "tv": 30765.14, "trd": NaN, "batb": [[0, 1.35, 946.45], [1, 1.34, 4124.15]], "batl": [[2, 1.39, 2096.5]]}, {"timestamp": 1578772851007, "ltp": 1.37, "tv": 30765.14, "trd": NaN, "batb": NaN, "batl": [[2, 1.39, 1031]]}, {"timestamp": 1578772851988, "ltp": 1.37, "tv": 30765.14, "trd": NaN, "batb": [[1, 1.34, 3545.34]], "batl": [[0, 1.38, 1027.02], [1, 1.39, 1031], [2, 1.4, 2363.02]]}, {"timestamp": 1578772852978, "ltp": 1.37, "tv": 30765.14, "trd": NaN, "batb": [[0, 1.36, 31.7], [1, 1.35, 946.45], [2, 1.34, 3545.34]], "batl": NaN}, {"timestamp": 1578772853962, "ltp": 1.36, "tv": 30828.54, "trd": [[1.36, 1156.65]], "batb": [[0, 1.35, 916.25], [1, 1.34, 3166.52], [2, 1.33, 2390.62]], "batl": [[0, 1.36, 180.9], [1, 1.38, 1027.02], [2, 1.39, 1481]]}, {"timestamp": 1578772855006, "ltp": 1.36, "tv": 30828.54, "trd": NaN, "batb": [[0, 1.35, 914.25], [1, 1.34, 1641.8], [2, 1.33, 2217.62]], "batl": [[0, 1.36, 182.77]]}, {"timestamp": 1578772855984, "ltp": 1.36, "tv": 30830.79, "trd": [[1.36, 1158.91]], "batb": NaN, "batl": [[0, 1.36, 181.64], [1, 1.37, 121.66], [2, 1.38, 1027.02]]}, {"timestamp": 1578772856972, "ltp": 1.36, "tv": 30830.79, "trd": NaN, "batb": NaN, "batl": [[0, 1.36, 190.29], [1, 1.37, 418.46], [2, 1.38, 1069.58]]}, {"timestamp": 1578772858004, "ltp": 1.36, "tv": 30830.79, "trd": NaN, "batb": [[0, 1.35, 684.65]], "batl": NaN}, {"timestamp": 1578772858992, "ltp": 1.36, "tv": 30830.79, "trd": NaN, "batb": [[2, 1.33, 2796.43]], "batl": [[0, 1.36, 472.26]]}, {"timestamp": 1578772861015, "ltp": 1.36, "tv": 30858.48, "trd": [[1.36, 1186.6]], "batb": NaN, "batl": [[0, 1.36, 458.42], [1, 1.37, 448.05]]}, {"timestamp": 1578772862002, "ltp": 1.36, "tv": 30858.48, "trd": NaN, "batb": [[2, 1.33, 4947.32]], "batl": NaN}, {"timestamp": 1578772864025, "ltp": 1.36, "tv": 30858.48, "trd": NaN, "batb": NaN, "batl": [[0, 1.36, 487.67], [1, 1.37, 449.92]]}, {"timestamp": 1578772865008, "ltp": 1.36, "tv": 30858.48, "trd": NaN, "batb": NaN, "batl": [[0, 1.36, 411.14]]}, {"timestamp": 1578772866000, "ltp": 1.36, "tv": 30858.48, "trd": NaN, "batb": [[2, 1.33, 4359.81]], "batl": NaN}, {"timestamp": 1578772868016, "ltp": 1.36, "tv": 30858.48, "trd": NaN, "batb": NaN, "batl": [[1, 1.37, 418.46]]}, {"timestamp": 1578772869001, "ltp": 1.36, "tv": 30906.64, "trd": [[1.36, 1234.75]], "batb": [[1, 1.34, 1492.8]], "batl": [[0, 1.36, 387.06]]}, {"timestamp": 1578772870005, "ltp": 1.36, "tv": 30919.02, "trd": [[1.36, 1247.13]], "batb": NaN, "batl": [[0, 1.36, 380.87]]}, {"timestamp": 1578772871031, "ltp": 1.35, "tv": 30936.32, "trd": [[1.35, 17.3]], "batb": [[0, 1.35, 676]], "batl": NaN}, {"timestamp": 1578772872019, "ltp": 1.35, "tv": 31094.79, "trd": [[1.35, 175.77]], "batb": [[0, 1.35, 596.77], [2, 1.33, 4209.81]], "batl": NaN}, {"timestamp": 1578772873012, "ltp": 1.35, "tv": 31094.79, "trd": NaN, "batb": [[0, 1.35, 44.65], [2, 1.33, 2058.92]], "batl": [[2, 1.38, 2413.25]]}, {"timestamp": 1578772873993, "ltp": 1.35, "tv": 31094.79, "trd": NaN, "batb": [[0, 1.35, 47.23]], "batl": [[2, 1.38, 2742.38]]}, {"timestamp": 1578772875025, "ltp": 1.35, "tv": 31094.79, "trd": NaN, "batb": [[1, 1.34, 1299.87], [2, 1.33, 1267.26]], "batl": [[0, 1.36, 203.15]]}, {"timestamp": 1578772876019, "ltp": 1.35, "tv": 31095.14, "trd": [[1.35, 176.12]], "batb": [[0, 1.35, 47.06]], "batl": [[1, 1.37, 1054.54], [2, 1.38, 2900.13]]}, {"timestamp": 1578772879036, "ltp": 1.35, "tv": 31095.14, "trd": NaN, "batb": [[1, 1.34, 1297.87]], "batl": [[2, 1.38, 2921.41]]}, {"timestamp": 1578772880013, "ltp": 1.35, "tv": 31099.14, "trd": [[1.35, 180.12]], "batb": [[0, 1.35, 45.06]], "batl": [[0, 1.36, 240.94]]}, {"timestamp": 1578772880995, "ltp": 1.36, "tv": 31102.91, "trd": [[1.36, 1250.9]], "batb": NaN, "batl": [[0, 1.36, 361.57]]}, {"timestamp": 1578772882045, "ltp": 1.35, "tv": 31195.55, "trd": [[1.35, 272.4], [1.36, 1251.26]], "batb": [[0, 1.34, 1297.87], [1, 1.33, 2596.39], [2, 1.32, 2244.92]], "batl": [[0, 1.35, 160.08], [1, 1.36, 361.6], [2, 1.37, 1054.54]]}, {"timestamp": 1578772883027, "ltp": 1.35, "tv": 31195.55, "trd": NaN, "batb": [[0, 1.34, 1001.47], [2, 1.32, 3040.41]], "batl": NaN}, {"timestamp": 1578772884010, "ltp": 1.35, "tv": 31195.55, "trd": NaN, "batb": [[0, 1.34, 969.27]], "batl": [[0, 1.35, 197.99]]}, {"timestamp": 1578772886032, "ltp": 1.35, "tv": 31195.55, "trd": NaN, "batb": [[0, 1.34, 884.15], [2, 1.32, 2976.57]], "batl": NaN}, {"timestamp": 1578772887025, "ltp": 1.36, "tv": 32775.55, "trd": [[1.35, 668.38], [1.36, 2435.29]], "batb": NaN, "batl": [[0, 1.37, 793.59], [1, 1.38, 2758.59], [2, 1.39, 700.52]]}, {"timestamp": 1578772888004, "ltp": 1.36, "tv": 32775.55, "trd": NaN, "batb": NaN, "batl": [[1, 1.38, 2716.03]]}, {"timestamp": 1578772889930, "ltp": 1.36, "tv": 32775.55, "trd": NaN, "batb": NaN, "batl": [[0, 1.36, 262.87], [1, 1.37, 793.59], [2, 1.38, 2716.03]]}, {"timestamp": 1578772891020, "ltp": 1.36, "tv": 32775.55, "trd": NaN, "batb": NaN, "batl": [[0, 1.37, 793.59], [1, 1.38, 2716.03], [2, 1.39, 700.52]]}, {"timestamp": 1578772893031, "ltp": 1.36, "tv": 32775.55, "trd": NaN, "batb": [[1, 1.33, 2681.51]], "batl": [[0, 1.35, 19.13], [1, 1.37, 793.59], [2, 1.38, 1177.53]]}, {"timestamp": 1578772894020, "ltp": 1.36, "tv": 32775.55, "trd": NaN, "batb": [[0, 1.34, 1091.31], [1, 1.33, 1352.38], [2, 1.32, 5152.46]], "batl": [[1, 1.36, 40.19], [2, 1.37, 1221.51]]}, {"timestamp": 1578772894905, "ltp": 1.36, "tv": 32775.55, "trd": NaN, "batb": [[0, 1.34, 1214.1]], "batl": [[2, 1.37, 1264.07]]}, {"timestamp": 1578772896938, "ltp": 1.36, "tv": 32775.55, "trd": NaN, "batb": [[0, 1.34, 1439.2], [2, 1.32, 4555.84]], "batl": NaN}, {"timestamp": 1578772898031, "ltp": 1.36, "tv": 32775.55, "trd": NaN, "batb": [[2, 1.32, 4204.97]], "batl": NaN}, {"timestamp": 1578772899022, "ltp": 1.36, "tv": 32775.55, "trd": NaN, "batb": [[1, 1.33, 1350.38], [2, 1.32, 2029.08]], "batl": [[2, 1.37, 1525.02]]}, {"timestamp": 1578772899961, "ltp": 1.35, "tv": 32809.99, "trd": [[1.35, 702.82]], "batb": NaN, "batl": [[0, 1.35, 3.83]]}, {"timestamp": 1578772900957, "ltp": 1.35, "tv": 32813.82, "trd": [[1.35, 706.65]], "batb": NaN, "batl": [[0, 1.36, 40.19], [1, 1.37, 1525.02], [2, 1.38, 727.53]]}, {"timestamp": 1578772902049, "ltp": 1.36, "tv": 32859.87, "trd": [[1.34, 32.2], [1.36, 2449.13]], "batb": [[0, 1.34, 1423.1]], "batl": [[0, 1.36, 33.27]]}, {"timestamp": 1578772904921, "ltp": 1.36, "tv": 32859.87, "trd": NaN, "batb": [[1, 1.33, 1352.79], [2, 1.32, 3522.97]], "batl": [[0, 1.36, 64.98], [1, 1.37, 3002.72]]}, {"timestamp": 1578772906044, "ltp": 1.36, "tv": 32859.87, "trd": NaN, "batb": [[0, 1.34, 1331.51]], "batl": [[0, 1.36, 97.14]]}, {"timestamp": 1578772907035, "ltp": 1.36, "tv": 32859.87, "trd": NaN, "batb": [[0, 1.34, 1124.35]], "batl": [[0, 1.35, 38.27], [1, 1.36, 97.14], [2, 1.37, 3002.72]]}, {"timestamp": 1578772907969, "ltp": 1.36, "tv": 32859.87, "trd": NaN, "batb": [[0, 1.34, 1093.15]], "batl": NaN}, {"timestamp": 1578772910849, "ltp": 1.35, "tv": 32936.4, "trd": [[1.35, 783.18]], "batb": [[0, 1.35, 8.41], [1, 1.34, 1093.15], [2, 1.33, 1352.79]], "batl": [[0, 1.36, 97.14], [1, 1.37, 3002.72], [2, 1.38, 727.53]]}, {"timestamp": 1578772913047, "ltp": 1.35, "tv": 32936.4, "trd": NaN, "batb": [[0, 1.35, 48.37]], "batl": [[0, 1.36, 187.82], [1, 1.37, 2552.72]]}, {"timestamp": 1578772914044, "ltp": 1.35, "tv": 32936.4, "trd": NaN, "batb": NaN, "batl": [[0, 1.36, 450.69], [2, 1.38, 744.55]]}, {"timestamp": 1578772914973, "ltp": 1.35, "tv": 32936.4, "trd": NaN, "batb": [[0, 1.35, 86.28]], "batl": [[0, 1.36, 418.98]]}, {"timestamp": 1578772915958, "ltp": 1.35, "tv": 32936.4, "trd": NaN, "batb": NaN, "batl": [[0, 1.36, 1066.98]]}, {"timestamp": 1578772918049, "ltp": 1.35, "tv": 32953.22, "trd": [[1.35, 800]], "batb": [[0, 1.35, 77.87]], "batl": NaN}, {"timestamp": 1578772919975, "ltp": 1.35, "tv": 32953.22, "trd": NaN, "batb": NaN, "batl": [[1, 1.37, 2888.41]]}, {"timestamp": 1578772920969, "ltp": 1.35, "tv": 32953.22, "trd": NaN, "batb": NaN, "batl": [[2, 1.38, 1194.55]]}, {"timestamp": 1578772921967, "ltp": 1.35, "tv": 32953.22, "trd": NaN, "batb": NaN, "batl": [[1, 1.37, 3338.41]]}, {"timestamp": 1578772922971, "ltp": 1.35, "tv": 32953.22, "trd": NaN, "batb": [[1, 1.34, 1124.35]], "batl": NaN}, {"timestamp": 1578772924981, "ltp": 1.35, "tv": 32953.22, "trd": NaN, "batb": [[1, 1.34, 899.25]], "batl": [[2, 1.38, 744.55]]}, {"timestamp": 1578772925973, "ltp": 1.35, "tv": 32953.22, "trd": NaN, "batb": NaN, "batl": [[1, 1.37, 3295.85]]}, {"timestamp": 1578772930999, "ltp": 1.35, "tv": 32959.35, "trd": [[1.35, 806.13]], "batb": [[0, 1.35, 74.8]], "batl": NaN}, {"timestamp": 1578772931985, "ltp": 1.35, "tv": 32963.94, "trd": [[1.35, 810.72]], "batb": [[0, 1.35, 72.51]], "batl": [[0, 1.36, 1109.54]]}, {"timestamp": 1578772933968, "ltp": 1.35, "tv": 32963.94, "trd": NaN, "batb": [[1, 1.34, 279.35], [2, 1.33, 1584.72]], "batl": NaN}, {"timestamp": 1578772935014, "ltp": 1.35, "tv": 33006.84, "trd": [[1.35, 819.57], [1.36, 2483.18]], "batb": [[0, 1.35, 63.66], [1, 1.34, 49.74]], "batl": [[0, 1.36, 1092.52]]}, {"timestamp": 1578772938980, "ltp": 1.35, "tv": 33006.84, "trd": NaN, "batb": NaN, "batl": [[0, 1.36, 444.52], [1, 1.37, 868.46], [2, 1.38, 584.55]]}, {"timestamp": 1578772945022, "ltp": 1.35, "tv": 33007.16, "trd": [[1.35, 819.89]], "batb": [[0, 1.35, 63.5], [1, 1.34, 662.74]], "batl": NaN}, {"timestamp": 1578772946028, "ltp": 1.35, "tv": 33007.16, "trd": NaN, "batb": NaN, "batl": [[1, 1.37, 418.46], [2, 1.38, 134.55]]}, {"timestamp": 1578772947005, "ltp": 1.35, "tv": 33051.32, "trd": [[1.35, 864.05]], "batb": [[0, 1.35, 41.42]], "batl": NaN}, {"timestamp": 1578772948002, "ltp": 1.35, "tv": 33051.32, "trd": NaN, "batb": [[2, 1.33, 1499.6]], "batl": [[0, 1.36, 90.97]]}, {"timestamp": 1578772950930, "ltp": 1.35, "tv": 33051.32, "trd": NaN, "batb": NaN, "batl": [[1, 1.37, 65.79]]}, {"timestamp": 1578772951764, "ltp": 1.35, "tv": 33066.63, "trd": [[1.35, 879.36]], "batb": [[0, 1.35, 33.77]], "batl": NaN}, {"timestamp": 1578772956048, "ltp": 1.35, "tv": 33073.44, "trd": [[1.35, 886.17]], "batb": [[0, 1.35, 30.36]], "batl": NaN}, {"timestamp": 1578772957937, "ltp": 1.36, "tv": 33092.66, "trd": [[1.36, 2502.4]], "batb": NaN, "batl": [[0, 1.36, 81.36], [2, 1.38, 393.62]]}, {"timestamp": 1578772959024, "ltp": 1.36, "tv": 33092.66, "trd": NaN, "batb": NaN, "batl": [[2, 1.38, 486.36]]}, {"timestamp": 1578772960956, "ltp": 1.36, "tv": 33092.66, "trd": NaN, "batb": [[1, 1.34, 49.74]], "batl": NaN}, {"timestamp": 1578772963973, "ltp": 1.35, "tv": 33143.74, "trd": [[1.35, 937.24]], "batb": [[0, 1.35, 4.82], [1, 1.34, 18.55]], "batl": NaN}, {"timestamp": 1578772968969, "ltp": 1.35, "tv": 33153.38, "trd": [[1.35, 946.89]], "batb": [[0, 1.34, 18.55], [1, 1.33, 1499.6], [2, 1.32, 1355.67]], "batl": [[0, 1.35, 95.18], [1, 1.36, 81.36], [2, 1.37, 65.79]]}, {"timestamp": 1578772969963, "ltp": 1.35, "tv": 33153.38, "trd": NaN, "batb": NaN, "batl": [[2, 1.38, 465.08]]}, {"timestamp": 1578772971051, "ltp": 1.35, "tv": 33153.38, "trd": NaN, "batb": NaN, "batl": [[0, 1.35, 99.44]]}, {"timestamp": 1578772972035, "ltp": 1.35, "tv": 33153.38, "trd": NaN, "batb": NaN, "batl": [[0, 1.35, 95.18]]}, {"timestamp": 1578772973954, "ltp": 1.35, "tv": 33153.38, "trd": NaN, "batb": NaN, "batl": [[0, 1.36, 81.36], [1, 1.38, 465.08], [2, 1.39, 199.62]]}, {"timestamp": 1578772974992, "ltp": 1.35, "tv": 33153.38, "trd": NaN, "batb": NaN, "batl": [[0, 1.36, 102.64]]}, {"timestamp": 1578772975977, "ltp": 1.35, "tv": 33153.38, "trd": NaN, "batb": NaN, "batl": [[1, 1.37, 90.77], [2, 1.38, 465.08]]}, {"timestamp": 1578772976972, "ltp": 1.34, "tv": 33171.93, "trd": [[1.34, 50.75]], "batb": [[0, 1.33, 1499.6], [1, 1.32, 1355.67], [2, 1.31, 3465.58]], "batl": [[0, 1.35, 73.13], [1, 1.36, 102.64], [2, 1.37, 260.96]]}, {"timestamp": 1578772977969, "ltp": 1.34, "tv": 33171.93, "trd": NaN, "batb": [[1, 1.32, 2765.31], [2, 1.31, 1470.79]], "batl": [[0, 1.36, 102.64], [1, 1.38, 448.05], [2, 1.39, 199.62]]}, {"timestamp": 1578772978950, "ltp": 1.34, "tv": 33171.93, "trd": NaN, "batb": NaN, "batl": [[0, 1.36, 60.08]]}, {"timestamp": 1578772979993, "ltp": 1.34, "tv": 33171.93, "trd": NaN, "batb": NaN, "batl": [[0, 1.35, 3.83], [1, 1.36, 60.08], [2, 1.38, 448.05]]}, {"timestamp": 1578772980986, "ltp": 1.33, "tv": 33362.29, "trd": [[1.33, 190.36]], "batb": [[0, 1.33, 1404.42]], "batl": [[0, 1.34, 34.05], [1, 1.35, 3.83], [2, 1.36, 60.08]]}, {"timestamp": 1578772983009, "ltp": 1.33, "tv": 33362.29, "trd": NaN, "batb": [[0, 1.33, 1174.81]], "batl": NaN}, {"timestamp": 1578772983904, "ltp": 1.33, "tv": 33362.29, "trd": NaN, "batb": [[1, 1.32, 1355.67]], "batl": NaN}, {"timestamp": 1578772984997, "ltp": 1.33, "tv": 33362.29, "trd": NaN, "batb": NaN, "batl": [[2, 1.36, 155.65]]}, {"timestamp": 1578772986041, "ltp": 1.33, "tv": 33362.29, "trd": NaN, "batb": [[0, 1.33, 829.87]], "batl": [[1, 1.35, 46.39], [2, 1.36, 753.65]]}, {"timestamp": 1578772986980, "ltp": 1.33, "tv": 33362.29, "trd": NaN, "batb": [[0, 1.33, 597.95]], "batl": NaN}, {"timestamp": 1578772989014, "ltp": 1.33, "tv": 33362.29, "trd": NaN, "batb": [[2, 1.31, 2279.01]], "batl": [[1, 1.35, 74.25], [2, 1.36, 1203.65]]}, {"timestamp": 1578772990007, "ltp": 1.33, "tv": 33362.29, "trd": NaN, "batb": [[2, 1.31, 4467.38]], "batl": NaN}, {"timestamp": 1578772993016, "ltp": 1.33, "tv": 33362.29, "trd": NaN, "batb": NaN, "batl": [[2, 1.36, 1561.05]]}, {"timestamp": 1578772994020, "ltp": 1.34, "tv": 33362.59, "trd": [[1.34, 51.05]], "batb": [[2, 1.31, 4450.36]], "batl": [[0, 1.34, 33.9], [1, 1.35, 434.61]]}, {"timestamp": 1578772996002, "ltp": 1.34, "tv": 33362.59, "trd": NaN, "batb": [[1, 1.32, 1594.84], [2, 1.31, 2261.99]], "batl": NaN}, {"timestamp": 1578772996888, "ltp": 1.34, "tv": 33362.59, "trd": NaN, "batb": [[2, 1.31, 2406.99]], "batl": [[1, 1.35, 466.31]]}, {"timestamp": 1578772997984, "ltp": 1.33, "tv": 33430.69, "trd": [[1.33, 258.46]], "batb": [[0, 1.33, 563.9]], "batl": NaN}, {"timestamp": 1578772998919, "ltp": 1.33, "tv": 33438.34, "trd": [[1.33, 266.12]], "batb": [[0, 1.33, 560.07], [2, 1.31, 4030.78]], "batl": [[2, 1.36, 3057.12]]}, {"timestamp": 1578773000994, "ltp": 1.33, "tv": 33438.34, "trd": NaN, "batb": NaN, "batl": [[1, 1.35, 434.61]]}, {"timestamp": 1578773003022, "ltp": 1.34, "tv": 33476.48, "trd": [[1.34, 89.19]], "batb": NaN, "batl": [[0, 1.34, 14.83]]}, {"timestamp": 1578773004010, "ltp": 1.33, "tv": 33490.15, "trd": [[1.33, 279.79]], "batb": [[0, 1.33, 553.23]], "batl": [[0, 1.35, 434.61], [1, 1.36, 3057.12], [2, 1.37, 1209.08]]}, {"timestamp": 1578773005049, "ltp": 1.33, "tv": 33490.15, "trd": NaN, "batb": NaN, "batl": [[2, 1.37, 1149.5]]}, {"timestamp": 1578773006042, "ltp": 1.33, "tv": 33490.15, "trd": NaN, "batb": NaN, "batl": [[0, 1.35, 535.91], [2, 1.37, 593]]}, {"timestamp": 1578773007999, "ltp": 1.33, "tv": 33490.15, "trd": NaN, "batb": NaN, "batl": [[1, 1.36, 1561.05]]}, {"timestamp": 1578773011009, "ltp": 1.33, "tv": 33490.15, "trd": NaN, "batb": NaN, "batl": [[1, 1.36, 1603.61]]}, {"timestamp": 1578773013035, "ltp": 1.33, "tv": 33552.73, "trd": [[1.33, 342.37]], "batb": [[0, 1.33, 521.94]], "batl": [[1, 1.36, 2053.61]]}, {"timestamp": 1578773016042, "ltp": 1.33, "tv": 33552.73, "trd": NaN, "batb": NaN, "batl": [[2, 1.37, 678.12]]}, {"timestamp": 1578773019054, "ltp": 1.33, "tv": 33552.73, "trd": NaN, "batb": [[2, 1.31, 4540.57]], "batl": NaN}, {"timestamp": 1578773021056, "ltp": 1.33, "tv": 33554.28, "trd": [[1.33, 343.91]], "batb": [[0, 1.33, 521.17]], "batl": NaN}, {"timestamp": 1578773022047, "ltp": 1.33, "tv": 33554.28, "trd": NaN, "batb": [[2, 1.31, 4030.78]], "batl": NaN}, {"timestamp": 1578773025922, "ltp": 1.33, "tv": 33554.28, "trd": NaN, "batb": [[2, 1.31, 1800.82]], "batl": [[1, 1.36, 3495.68]]}, {"timestamp": 1578773030047, "ltp": 1.33, "tv": 33554.28, "trd": NaN, "batb": [[2, 1.31, 1655.82]], "batl": NaN}, {"timestamp": 1578773032948, "ltp": 1.33, "tv": 33554.28, "trd": NaN, "batb": NaN, "batl": [[2, 1.37, 593]]}, {"timestamp": 1578773033947, "ltp": 1.33, "tv": 33554.28, "trd": NaN, "batb": [[2, 1.31, 3510.35]], "batl": [[0, 1.35, 1035.91], [1, 1.36, 1603.61], [2, 1.37, 2592.96]]}, {"timestamp": 1578773035049, "ltp": 1.33, "tv": 33555.81, "trd": [[1.33, 345.45]], "batb": [[0, 1.33, 520.4], [2, 1.31, 1655.82]], "batl": [[2, 1.37, 593]]}, {"timestamp": 1578773036039, "ltp": 1.33, "tv": 33555.81, "trd": NaN, "batb": NaN, "batl": [[0, 1.35, 1666.91]]}, {"timestamp": 1578773038964, "ltp": 1.33, "tv": 33555.81, "trd": NaN, "batb": [[1, 1.32, 1509.72]], "batl": [[1, 1.36, 1688.74]]}, {"timestamp": 1578773041054, "ltp": 1.33, "tv": 33593.19, "trd": [[1.33, 382.82]], "batb": [[0, 1.33, 501.71], [2, 1.31, 1653.82]], "batl": [[0, 1.35, 2116.91]]}, {"timestamp": 1578773043049, "ltp": 1.33, "tv": 33593.19, "trd": NaN, "batb": [[0, 1.33, 51.13]], "batl": NaN}, {"timestamp": 1578773045981, "ltp": 1.33, "tv": 33593.19, "trd": NaN, "batb": [[2, 1.31, 1536.89]], "batl": [[0, 1.35, 3926.01]]}, {"timestamp": 1578773048968, "ltp": 1.33, "tv": 33593.19, "trd": NaN, "batb": NaN, "batl": [[1, 1.36, 1646.17]]}, {"timestamp": 1578773049960, "ltp": 1.33, "tv": 33845.82, "trd": [[1.33, 635.46]], "batb": [[0, 1.32, 1182.48], [1, 1.31, 1536.89], [2, 1.3, 3826.87]], "batl": [[0, 1.33, 525.62], [1, 1.35, 3926.01], [2, 1.36, 1282.13]]}, {"timestamp": 1578773050951, "ltp": 1.33, "tv": 33845.82, "trd": NaN, "batb": [[0, 1.32, 1148.77]], "batl": [[2, 1.36, 1249.97]]}, {"timestamp": 1578773051988, "ltp": 1.33, "tv": 33845.82, "trd": NaN, "batb": [[2, 1.3, 2113.75]], "batl": [[0, 1.33, 562.99]]}, {"timestamp": 1578773052977, "ltp": 1.33, "tv": 34032.64, "trd": [[1.33, 822.28]], "batb": NaN, "batl": [[0, 1.33, 379.91]]}, {"timestamp": 1578773053979, "ltp": 1.33, "tv": 34032.64, "trd": NaN, "batb": [[0, 1.32, 909.6], [2, 1.3, 2329.16]], "batl": NaN}, {"timestamp": 1578773055966, "ltp": 1.33, "tv": 34032.64, "trd": NaN, "batb": NaN, "batl": [[1, 1.35, 3968.57]]}, {"timestamp": 1578773056964, "ltp": 1.33, "tv": 34032.64, "trd": NaN, "batb": NaN, "batl": [[0, 1.33, 41.11], [1, 1.34, 405.85], [2, 1.35, 3968.57]]}, {"timestamp": 1578773057961, "ltp": 1.33, "tv": 34032.64, "trd": NaN, "batb": NaN, "batl": [[1, 1.34, 439.06]]}, {"timestamp": 1578773059055, "ltp": 1.33, "tv": 34032.64, "trd": NaN, "batb": [[0, 1.32, 941.31]], "batl": [[0, 1.33, 42.98], [1, 1.34, 470.77]]}, {"timestamp": 1578773059984, "ltp": 1.33, "tv": 34036.64, "trd": [[1.33, 826.28]], "batb": [[2, 1.3, 2312.14]], "batl": [[0, 1.33, 40.98]]}, {"timestamp": 1578773060991, "ltp": 1.33, "tv": 34036.64, "trd": NaN, "batb": NaN, "batl": [[1, 1.34, 2217.88], [2, 1.35, 2159.47]]}, {"timestamp": 1578773062001, "ltp": 1.33, "tv": 34036.64, "trd": NaN, "batb": NaN, "batl": [[0, 1.33, 75.51]]}, {"timestamp": 1578773062998, "ltp": 1.33, "tv": 34036.64, "trd": NaN, "batb": [[1, 1.31, 1783.78]], "batl": [[0, 1.33, 475.51]]}, {"timestamp": 1578773063994, "ltp": 1.32, "tv": 34714.24, "trd": [[1.32, 677.6]], "batb": [[0, 1.32, 602.51]], "batl": NaN}, {"timestamp": 1578773065988, "ltp": 1.32, "tv": 34760.16, "trd": [[1.32, 723.52]], "batb": [[0, 1.32, 579.55]], "batl": [[1, 1.34, 2186.18]]}, {"timestamp": 1578773069018, "ltp": 1.32, "tv": 34767.64, "trd": [[1.32, 731]], "batb": [[0, 1.32, 575.81]], "batl": [[1, 1.34, 2686.18]]}, {"timestamp": 1578773070995, "ltp": 1.32, "tv": 35567.64, "trd": [[1.32, 1531]], "batb": [[0, 1.32, 175.81]], "batl": NaN}, {"timestamp": 1578773071992, "ltp": 1.32, "tv": 35567.64, "trd": NaN, "batb": NaN, "batl": [[1, 1.34, 2670.87]]}, {"timestamp": 1578773076998, "ltp": 1.32, "tv": 35567.64, "trd": NaN, "batb": NaN, "batl": [[1, 1.34, 1339.06]]}, {"timestamp": 1578773077987, "ltp": 1.32, "tv": 35567.64, "trd": NaN, "batb": [[0, 1.32, 834.81], [1, 1.31, 1785.78]], "batl": [[1, 1.34, 2000.06]]}, {"timestamp": 1578773079992, "ltp": 1.32, "tv": 35567.64, "trd": NaN, "batb": [[1, 1.31, 1783.78]], "batl": [[0, 1.33, 490.82], [2, 1.35, 2116.91]]}, {"timestamp": 1578773080897, "ltp": 1.32, "tv": 35567.64, "trd": NaN, "batb": [[2, 1.3, 2319.66]], "batl": [[0, 1.33, 536.74]]}, {"timestamp": 1578773081894, "ltp": 1.32, "tv": 35567.64, "trd": NaN, "batb": NaN, "batl": [[0, 1.33, 568.44]]}, {"timestamp": 1578773082990, "ltp": 1.32, "tv": 35567.64, "trd": NaN, "batb": [[1, 1.31, 1698.66], [2, 1.3, 2336.68]], "batl": NaN}, {"timestamp": 1578773085029, "ltp": 1.32, "tv": 35567.64, "trd": NaN, "batb": [[0, 1.32, 175.81]], "batl": NaN}, {"timestamp": 1578773086026, "ltp": 1.32, "tv": 35567.64, "trd": NaN, "batb": NaN, "batl": [[2, 1.35, 1666.91]]}, {"timestamp": 1578773087026, "ltp": 1.32, "tv": 35567.64, "trd": NaN, "batb": NaN, "batl": [[1, 1.34, 2042.62]]}, {"timestamp": 1578773088045, "ltp": 1.32, "tv": 35567.64, "trd": NaN, "batb": [[0, 1.32, 36.7], [2, 1.3, 1730.51]], "batl": NaN}, {"timestamp": 1578773089001, "ltp": 1.32, "tv": 35607.64, "trd": [[1.32, 1571]], "batb": [[0, 1.32, 16.7]], "batl": [[2, 1.35, 1236.13]]}, {"timestamp": 1578773090024, "ltp": 1.32, "tv": 35622.97, "trd": [[1.32, 1586.32]], "batb": [[0, 1.32, 9.04], [1, 1.31, 1474.2], [2, 1.3, 1815.64]], "batl": [[0, 1.33, 530.17]]}, {"timestamp": 1578773091027, "ltp": 1.32, "tv": 35624.5, "trd": [[1.32, 1587.86]], "batb": [[0, 1.31, 1474.2], [1, 1.3, 1815.64], [2, 1.29, 4422.36]], "batl": [[0, 1.33, 475.8]]}, {"timestamp": 1578773092026, "ltp": 1.32, "tv": 35624.5, "trd": NaN, "batb": [[2, 1.29, 4379.8]], "batl": [[2, 1.35, 1686.13]]}, {"timestamp": 1578773093017, "ltp": 1.32, "tv": 35624.5, "trd": NaN, "batb": [[0, 1.31, 1476.2]], "batl": [[1, 1.34, 3835.58], [2, 1.35, 1690.45]]}, {"timestamp": 1578773094025, "ltp": 1.32, "tv": 35624.5, "trd": NaN, "batb": NaN, "batl": [[0, 1.33, 473.93], [1, 1.34, 2492.62], [2, 1.35, 1796.85]]}, {"timestamp": 1578773095010, "ltp": 1.32, "tv": 35624.5, "trd": NaN, "batb": [[2, 1.29, 4985.97]], "batl": [[0, 1.33, 556.4]]}, {"timestamp": 1578773095904, "ltp": 1.32, "tv": 35624.5, "trd": NaN, "batb": NaN, "batl": [[0, 1.33, 897.93]]}, {"timestamp": 1578773097002, "ltp": 1.32, "tv": 35624.5, "trd": NaN, "batb": NaN, "batl": [[0, 1.32, 128.86], [1, 1.33, 897.93], [2, 1.34, 2492.62]]}, {"timestamp": 1578773098035, "ltp": 1.32, "tv": 35624.5, "trd": NaN, "batb": [[0, 1.31, 1342.76], [2, 1.29, 4625.97]], "batl": NaN}, {"timestamp": 1578773099029, "ltp": 1.32, "tv": 35624.5, "trd": NaN, "batb": [[0, 1.31, 1340.76]], "batl": NaN}, {"timestamp": 1578773100030, "ltp": 1.32, "tv": 35753.36, "trd": [[1.32, 1716.72]], "batb": NaN, "batl": [[0, 1.33, 897.93], [1, 1.34, 2492.62], [2, 1.35, 1796.85]]}, {"timestamp": 1578773101031, "ltp": 1.32, "tv": 35757.1, "trd": [[1.32, 1720.45]], "batb": [[0, 1.32, 245.52], [1, 1.31, 1340.76], [2, 1.3, 1815.64]], "batl": NaN}, {"timestamp": 1578773102025, "ltp": 1.32, "tv": 35787.71, "trd": [[1.32, 1751.07]], "batb": [[0, 1.32, 230.21]], "batl": [[0, 1.33, 629.12]]}, {"timestamp": 1578773103951, "ltp": 1.32, "tv": 35834.18, "trd": [[1.32, 1797.54]], "batb": [[0, 1.32, 206.97]], "batl": NaN}, {"timestamp": 1578773104955, "ltp": 1.32, "tv": 35834.18, "trd": NaN, "batb": NaN, "batl": [[1, 1.34, 2042.62]]}, {"timestamp": 1578773106023, "ltp": 1.32, "tv": 35882.8, "trd": [[1.32, 1846.16]], "batb": [[0, 1.32, 182.66], [2, 1.3, 1600.23]], "batl": [[2, 1.35, 1346.85]]}, {"timestamp": 1578773109031, "ltp": 1.32, "tv": 35882.8, "trd": NaN, "batb": [[1, 1.31, 1693.62]], "batl": NaN}, {"timestamp": 1578773110035, "ltp": 1.32, "tv": 35882.8, "trd": NaN, "batb": [[0, 1.32, 6.92]], "batl": [[0, 1.33, 593.75]]}, {"timestamp": 1578773111029, "ltp": 1.32, "tv": 35882.8, "trd": NaN, "batb": [[1, 1.31, 1473.84]], "batl": NaN}, {"timestamp": 1578773111971, "ltp": 1.32, "tv": 35882.8, "trd": NaN, "batb": NaN, "batl": [[2, 1.35, 1796.85]]}, {"timestamp": 1578773114039, "ltp": 1.32, "tv": 35882.8, "trd": NaN, "batb": NaN, "batl": [[1, 1.34, 2152.87]]}, {"timestamp": 1578773114932, "ltp": 1.32, "tv": 35882.8, "trd": NaN, "batb": NaN, "batl": [[0, 1.33, 1934.5]]}, {"timestamp": 1578773118036, "ltp": 1.31, "tv": 35953.55, "trd": [[1.31, 56.9], [1.32, 1860]], "batb": [[0, 1.31, 1445.39], [1, 1.3, 1600.23], [2, 1.29, 2373.18]], "batl": [[0, 1.33, 2203.31]]}, {"timestamp": 1578773122027, "ltp": 1.31, "tv": 35953.55, "trd": NaN, "batb": NaN, "batl": [[1, 1.34, 2602.87]]}, {"timestamp": 1578773122968, "ltp": 1.31, "tv": 35953.55, "trd": NaN, "batb": [[0, 1.32, 182.66], [1, 1.31, 1445.39], [2, 1.3, 1600.23]], "batl": [[1, 1.34, 2560.31]]}, {"timestamp": 1578773123971, "ltp": 1.31, "tv": 35953.55, "trd": NaN, "batb": [[1, 1.31, 1292.39]], "batl": NaN}, {"timestamp": 1578773126969, "ltp": 1.31, "tv": 35953.55, "trd": NaN, "batb": [[2, 1.3, 1598.23]], "batl": [[1, 1.34, 2450.06], [2, 1.35, 1695.55]]}, {"timestamp": 1578773129969, "ltp": 1.33, "tv": 35962.06, "trd": [[1.33, 834.8]], "batb": NaN, "batl": [[0, 1.33, 2241.61]]}, {"timestamp": 1578773130962, "ltp": 1.33, "tv": 35962.06, "trd": NaN, "batb": [[0, 1.32, 192.84]], "batl": [[0, 1.33, 2903.61]]}, {"timestamp": 1578773133007, "ltp": 1.32, "tv": 35965.89, "trd": [[1.32, 1863.83]], "batb": [[0, 1.32, 190.93]], "batl": [[0, 1.33, 1951.36]]}, {"timestamp": 1578773133989, "ltp": 1.32, "tv": 36003.91, "trd": [[1.32, 1901.86]], "batb": [[0, 1.32, 152.91]], "batl": [[0, 1.33, 1562.86]]}, {"timestamp": 1578773134987, "ltp": 1.32, "tv": 36003.91, "trd": NaN, "batb": NaN, "batl": [[2, 1.35, 1245.55]]}, {"timestamp": 1578773135950, "ltp": 1.32, "tv": 36007.74, "trd": [[1.32, 1905.68]], "batb": [[0, 1.32, 150.99]], "batl": NaN}, {"timestamp": 1578773136980, "ltp": 1.32, "tv": 36007.74, "trd": NaN, "batb": [[2, 1.3, 1513.1]], "batl": [[0, 1.33, 2062.86]]}, {"timestamp": 1578773137983, "ltp": 1.32, "tv": 36007.74, "trd": NaN, "batb": [[2, 1.3, 1528.41]], "batl": NaN}, {"timestamp": 1578773139985, "ltp": 1.32, "tv": 36011.57, "trd": [[1.32, 1909.51]], "batb": [[0, 1.32, 149.08], [1, 1.31, 1045.51]], "batl": NaN}, {"timestamp": 1578773140976, "ltp": 1.32, "tv": 36011.57, "trd": NaN, "batb": [[1, 1.31, 400.96]], "batl": NaN}, {"timestamp": 1578773141973, "ltp": 1.32, "tv": 36015.57, "trd": [[1.32, 1913.51]], "batb": [[0, 1.32, 136.9]], "batl": [[1, 1.34, 2900.06]]}, {"timestamp": 1578773142917, "ltp": 1.31, "tv": 37358.63, "trd": [[1.31, 1126.15], [1.32, 2187.32]], "batb": [[0, 1.3, 1528.41], [1, 1.29, 2354.16], [2, 1.28, 5260.43]], "batl": NaN}, {"timestamp": 1578773143859, "ltp": 1.31, "tv": 37358.63, "trd": NaN, "batb": [[1, 1.29, 2439.28]], "batl": NaN}, {"timestamp": 1578773145006, "ltp": 1.31, "tv": 37528.87, "trd": [[1.31, 1296.39]], "batb": NaN, "batl": NaN}, {"timestamp": 1578773147003, "ltp": 1.31, "tv": 37528.87, "trd": NaN, "batb": NaN, "batl": [[0, 1.32, 37.37], [1, 1.33, 2062.86], [2, 1.34, 2900.06]]}, {"timestamp": 1578773148016, "ltp": 1.31, "tv": 37528.87, "trd": NaN, "batb": NaN, "batl": [[2, 1.34, 2860.65]]}, {"timestamp": 1578773150008, "ltp": 1.31, "tv": 37528.87, "trd": NaN, "batb": NaN, "batl": [[2, 1.34, 2827.44]]}, {"timestamp": 1578773152001, "ltp": 1.31, "tv": 37528.87, "trd": NaN, "batb": [[0, 1.3, 1529.48], [2, 1.28, 5104.43]], "batl": [[0, 1.32, 83.29]]}, {"timestamp": 1578773153007, "ltp": 1.31, "tv": 37528.87, "trd": NaN, "batb": NaN, "batl": [[0, 1.32, 129.21], [2, 1.34, 2461]]}, {"timestamp": 1578773154013, "ltp": 1.31, "tv": 37528.87, "trd": NaN, "batb": NaN, "batl": [[0, 1.32, 75.64], [1, 1.33, 3619.48], [2, 1.34, 2546.12]]}, {"timestamp": 1578773155014, "ltp": 1.31, "tv": 37528.87, "trd": NaN, "batb": [[1, 1.29, 1812.56]], "batl": [[0, 1.32, 117.33], [1, 1.33, 1400.86], [2, 1.34, 1885.12]]}, {"timestamp": 1578773156017, "ltp": 1.31, "tv": 37528.87, "trd": NaN, "batb": NaN, "batl": [[0, 1.32, 79.06]]}, {"timestamp": 1578773157012, "ltp": 1.31, "tv": 37528.87, "trd": NaN, "batb": [[1, 1.29, 3176.68], [2, 1.28, 3789.18]], "batl": [[0, 1.31, 45.92], [1, 1.32, 114.18], [2, 1.33, 1400.86]]}, {"timestamp": 1578773158020, "ltp": 1.31, "tv": 37528.87, "trd": NaN, "batb": [[0, 1.3, 1272.56]], "batl": [[0, 1.31, 176.03], [1, 1.32, 76.8]]}, {"timestamp": 1578773159010, "ltp": 1.31, "tv": 37528.87, "trd": NaN, "batb": [[0, 1.3, 1007.91]], "batl": [[0, 1.31, 183.68]]}, {"timestamp": 1578773160021, "ltp": 1.31, "tv": 37528.87, "trd": NaN, "batb": NaN, "batl": [[0, 1.31, 229.6], [1, 1.32, 452.98], [2, 1.33, 1377.6]]}, {"timestamp": 1578773161020, "ltp": 1.31, "tv": 37528.87, "trd": NaN, "batb": [[2, 1.28, 3767.9]], "batl": NaN}, {"timestamp": 1578773162018, "ltp": 1.31, "tv": 37528.87, "trd": NaN, "batb": [[2, 1.28, 4394.62]], "batl": NaN}, {"timestamp": 1578773163014, "ltp": 1.31, "tv": 37528.87, "trd": NaN, "batb": [[1, 1.29, 1812.56]], "batl": [[1, 1.32, 596.41], [2, 1.33, 1335.04]]}, {"timestamp": 1578773165015, "ltp": 1.31, "tv": 37548.69, "trd": [[1.31, 1316.21]], "batb": [[1, 1.29, 1603.66]], "batl": [[0, 1.31, 219.69]]}, {"timestamp": 1578773167010, "ltp": 1.3, "tv": 37718.94, "trd": [[1.3, 170.24]], "batb": [[0, 1.3, 922.78]], "batl": NaN}, {"timestamp": 1578773168004, "ltp": 1.3, "tv": 37718.94, "trd": NaN, "batb": [[1, 1.29, 1604.51]], "batl": [[2, 1.33, 1293.88]]}, {"timestamp": 1578773170013, "ltp": 1.3, "tv": 37723.61, "trd": [[1.3, 174.91]], "batb": [[0, 1.3, 920.45]], "batl": [[1, 1.32, 638.97]]}, {"timestamp": 1578773171039, "ltp": 1.31, "tv": 37768.76, "trd": [[1.31, 1361.37]], "batb": NaN, "batl": [[0, 1.31, 197.11]]}, {"timestamp": 1578773172040, "ltp": 1.31, "tv": 37768.76, "trd": NaN, "batb": NaN, "batl": [[2, 1.33, 2193.88]]}, {"timestamp": 1578773173044, "ltp": 1.3, "tv": 37806.14, "trd": [[1.3, 212.29]], "batb": [[0, 1.3, 901.76]], "batl": NaN}, {"timestamp": 1578773174056, "ltp": 1.3, "tv": 37806.14, "trd": NaN, "batb": [[1, 1.29, 1449.51], [2, 1.28, 4377.6]], "batl": [[0, 1.31, 220.37]]}, {"timestamp": 1578773174954, "ltp": 1.3, "tv": 37806.14, "trd": NaN, "batb": [[2, 1.28, 5178.41]], "batl": [[0, 1.31, 264.43], [1, 1.32, 1273.97], [2, 1.33, 2852.88]]}, {"timestamp": 1578773176011, "ltp": 1.3, "tv": 37882.67, "trd": [[1.3, 288.82]], "batb": [[0, 1.3, 817.57]], "batl": NaN}, {"timestamp": 1578773177037, "ltp": 1.3, "tv": 38079.66, "trd": [[1.3, 485.81]], "batb": [[0, 1.3, 679.81], [1, 1.29, 1713.43], [2, 1.28, 2786.37]], "batl": [[0, 1.31, 268.35], [2, 1.33, 2402.88]]}, {"timestamp": 1578773178044, "ltp": 1.3, "tv": 38171.5, "trd": [[1.3, 577.65]], "batb": [[0, 1.3, 633.89], [2, 1.28, 2148.55]], "batl": [[0, 1.31, 71.24]]}, {"timestamp": 1578773179040, "ltp": 1.3, "tv": 38171.5, "trd": NaN, "batb": [[0, 1.3, 59.65]], "batl": [[0, 1.31, 27.18]]}, {"timestamp": 1578773180938, "ltp": 1.32, "tv": 38506.35, "trd": [[1.31, 1415.72], [1.32, 2467.83]], "batb": NaN, "batl": [[0, 1.32, 1133.72], [1, 1.33, 2488], [2, 1.34, 1548]]}, {"timestamp": 1578773182056, "ltp": 1.32, "tv": 38506.35, "trd": NaN, "batb": NaN, "batl": [[0, 1.32, 1633.72], [1, 1.33, 4114.26]]}, {"timestamp": 1578773182946, "ltp": 1.32, "tv": 38506.35, "trd": NaN, "batb": NaN, "batl": [[1, 1.33, 2488]]}, {"timestamp": 1578773184055, "ltp": 1.32, "tv": 38506.5, "trd": [[1.32, 2467.98]], "batb": [[2, 1.28, 2328.55]], "batl": [[0, 1.32, 1633.64], [2, 1.34, 1569.28]]}, {"timestamp": 1578773185050, "ltp": 1.3, "tv": 38625.79, "trd": [[1.3, 696.94]], "batb": [[0, 1.29, 1593.47], [1, 1.28, 2148.55], [2, 1.27, 2211.47]], "batl": [[0, 1.3, 137.47], [1, 1.32, 2083.64], [2, 1.33, 2456.43]]}, {"timestamp": 1578773186054, "ltp": 1.3, "tv": 38625.79, "trd": NaN, "batb": [[0, 1.29, 1359.66]], "batl": [[2, 1.33, 1639.86]]}, {"timestamp": 1578773187049, "ltp": 1.3, "tv": 38625.79, "trd": NaN, "batb": [[2, 1.27, 2806.73]], "batl": NaN}, {"timestamp": 1578773188034, "ltp": 1.3, "tv": 38625.79, "trd": NaN, "batb": NaN, "batl": [[1, 1.32, 2118.05]]}, {"timestamp": 1578773189041, "ltp": 1.3, "tv": 38625.79, "trd": NaN, "batb": NaN, "batl": [[1, 1.32, 2119.37]]}, {"timestamp": 1578773191970, "ltp": 1.3, "tv": 38625.79, "trd": NaN, "batb": [[1, 1.28, 2233.67]], "batl": [[1, 1.31, 35.25], [2, 1.32, 2119.37]]}, {"timestamp": 1578773192971, "ltp": 1.3, "tv": 38625.79, "trd": NaN, "batb": NaN, "batl": [[1, 1.31, 457.96]]}, {"timestamp": 1578773194037, "ltp": 1.3, "tv": 38625.79, "trd": NaN, "batb": [[1, 1.28, 2079.67], [2, 1.27, 2808.73]], "batl": [[2, 1.32, 2569.37]]}, {"timestamp": 1578773195055, "ltp": 1.3, "tv": 38625.79, "trd": NaN, "batb": [[0, 1.29, 1391.37], [2, 1.27, 4931.97]], "batl": NaN}, {"timestamp": 1578773196056, "ltp": 1.3, "tv": 38625.79, "trd": NaN, "batb": [[2, 1.27, 2851.29]], "batl": NaN}, {"timestamp": 1578773198047, "ltp": 1.3, "tv": 38625.79, "trd": NaN, "batb": NaN, "batl": [[0, 1.3, 137.67]]}, {"timestamp": 1578773200002, "ltp": 1.3, "tv": 38901.13, "trd": [[1.3, 972.28]], "batb": [[0, 1.29, 1161.76]], "batl": [[0, 1.31, 457.96], [1, 1.32, 2569.37], [2, 1.33, 1832.23]]}, {"timestamp": 1578773200976, "ltp": 1.31, "tv": 38901.59, "trd": [[1.31, 1416.18]], "batb": NaN, "batl": [[0, 1.31, 35.02], [2, 1.33, 1844.23]]}, {"timestamp": 1578773201975, "ltp": 1.31, "tv": 38901.59, "trd": NaN, "batb": NaN, "batl": [[0, 1.32, 2569.37], [1, 1.33, 1844.23], [2, 1.34, 1693.31]]}, {"timestamp": 1578773204976, "ltp": 1.31, "tv": 38901.59, "trd": NaN, "batb": NaN, "batl": [[2, 1.34, 1778.43]]}, {"timestamp": 1578773205971, "ltp": 1.31, "tv": 38901.59, "trd": NaN, "batb": [[1, 1.28, 1867.07]], "batl": [[0, 1.31, 1999.92], [1, 1.32, 2569.37], [2, 1.33, 1844.23]]}, {"timestamp": 1578773206979, "ltp": 1.31, "tv": 38901.59, "trd": NaN, "batb": [[0, 1.29, 1027.56]], "batl": NaN}, {"timestamp": 1578773207972, "ltp": 1.31, "tv": 38901.59, "trd": NaN, "batb": [[0, 1.29, 1263.83]], "batl": [[0, 1.31, 2621.92]]}, {"timestamp": 1578773208978, "ltp": 1.31, "tv": 38901.59, "trd": NaN, "batb": [[0, 1.3, 1.29], [1, 1.29, 1064.29], [2, 1.28, 1867.07]], "batl": NaN}, {"timestamp": 1578773209975, "ltp": 1.31, "tv": 38901.59, "trd": NaN, "batb": [[1, 1.29, 800.37]], "batl": NaN}, {"timestamp": 1578773211969, "ltp": 1.31, "tv": 38901.59, "trd": NaN, "batb": [[1, 1.29, 798.37]], "batl": [[0, 1.31, 2930.07]]}, {"timestamp": 1578773212977, "ltp": 1.31, "tv": 38932.89, "trd": [[1.31, 1447.48]], "batb": NaN, "batl": [[0, 1.31, 2914.42]]}, {"timestamp": 1578773213979, "ltp": 1.31, "tv": 38932.89, "trd": NaN, "batb": [[2, 1.28, 3200.73]], "batl": [[0, 1.31, 1082.12]]}, {"timestamp": 1578773214968, "ltp": 1.31, "tv": 38932.89, "trd": NaN, "batb": [[2, 1.28, 1867.07]], "batl": NaN}, {"timestamp": 1578773216972, "ltp": 1.29, "tv": 38952.7, "trd": [[1.29, 17.22], [1.3, 974.86]], "batb": [[0, 1.29, 789.76], [1, 1.28, 1867.07], [2, 1.27, 2834.27]], "batl": NaN}, {"timestamp": 1578773218989, "ltp": 1.29, "tv": 38952.7, "trd": NaN, "batb": [[0, 1.29, 790.09], [1, 1.28, 2140.41]], "batl": [[1, 1.32, 2682.48]]}, {"timestamp": 1578773220004, "ltp": 1.3, "tv": 38953.03, "trd": [[1.3, 975.19]], "batb": [[0, 1.29, 789.76], [2, 1.27, 2910.8]], "batl": NaN}, {"timestamp": 1578773220988, "ltp": 1.3, "tv": 38953.03, "trd": NaN, "batb": [[1, 1.28, 2675.57]], "batl": NaN}, {"timestamp": 1578773221994, "ltp": 1.3, "tv": 38953.03, "trd": NaN, "batb": [[1, 1.28, 3999.73], [2, 1.27, 2745.8]], "batl": NaN}, {"timestamp": 1578773222980, "ltp": 1.3, "tv": 38953.03, "trd": NaN, "batb": NaN, "batl": [[0, 1.31, 1092.34], [2, 1.33, 1929.35]]}, {"timestamp": 1578773223974, "ltp": 1.3, "tv": 38953.03, "trd": NaN, "batb": NaN, "batl": [[0, 1.31, 1082.12], [2, 1.33, 1886.79]]}, {"timestamp": 1578773224992, "ltp": 1.29, "tv": 39055.18, "trd": [[1.29, 119.37]], "batb": [[0, 1.29, 57.11], [1, 1.28, 2140.41]], "batl": NaN}, {"timestamp": 1578773225997, "ltp": 1.29, "tv": 39055.18, "trd": NaN, "batb": [[0, 1.29, 20.38]], "batl": [[2, 1.33, 1801.67]]}, {"timestamp": 1578773226991, "ltp": 1.31, "tv": 39088.36, "trd": [[1.31, 1480.66]], "batb": [[1, 1.28, 2138.41]], "batl": [[0, 1.31, 1065.53]]}, {"timestamp": 1578773227987, "ltp": 1.31, "tv": 39126.0, "trd": [[1.31, 1518.3]], "batb": NaN, "batl": [[0, 1.31, 1046.71]]}, {"timestamp": 1578773228990, "ltp": 1.31, "tv": 39126.0, "trd": NaN, "batb": [[2, 1.27, 2974]], "batl": NaN}, {"timestamp": 1578773229997, "ltp": 1.29, "tv": 39134.65, "trd": [[1.29, 128.02]], "batb": [[0, 1.29, 16.05]], "batl": NaN}, {"timestamp": 1578773230998, "ltp": 1.29, "tv": 39134.65, "trd": NaN, "batb": [[2, 1.27, 4698.24]], "batl": [[1, 1.32, 4724.9]]}, {"timestamp": 1578773231996, "ltp": 1.29, "tv": 39134.65, "trd": NaN, "batb": NaN, "batl": [[1, 1.32, 4611.79]]}, {"timestamp": 1578773233007, "ltp": 1.29, "tv": 39134.65, "trd": NaN, "batb": NaN, "batl": [[1, 1.32, 4696.91]]}, {"timestamp": 1578773234017, "ltp": 1.29, "tv": 39134.65, "trd": NaN, "batb": [[1, 1.28, 2053.29]], "batl": [[0, 1.3, 10.21], [1, 1.31, 1546.71], [2, 1.32, 4696.91]]}, {"timestamp": 1578773236989, "ltp": 1.29, "tv": 39134.65, "trd": NaN, "batb": NaN, "batl": [[2, 1.32, 2697.05]]}, {"timestamp": 1578773238989, "ltp": 1.29, "tv": 39134.65, "trd": NaN, "batb": NaN, "batl": [[2, 1.32, 2247.05]]}, {"timestamp": 1578773240043, "ltp": 1.29, "tv": 39134.65, "trd": NaN, "batb": [[2, 1.27, 5077.59]], "batl": [[0, 1.3, 48.48]]}, {"timestamp": 1578773240994, "ltp": 1.3, "tv": 39138.41, "trd": [[1.3, 978.96]], "batb": [[2, 1.27, 5162.71]], "batl": [[0, 1.3, 44.72], [2, 1.32, 2097.83]]}, {"timestamp": 1578773241994, "ltp": 1.3, "tv": 39209.95, "trd": [[1.29, 168.45], [1.3, 1010.06]], "batb": [[0, 1.28, 2053.29], [1, 1.27, 5162.71], [2, 1.26, 2605.5]], "batl": [[0, 1.3, 29.17], [2, 1.32, 2063.42]]}, {"timestamp": 1578773242986, "ltp": 1.3, "tv": 39209.95, "trd": NaN, "batb": [[1, 1.27, 5120.15]], "batl": [[0, 1.29, 4.26], [1, 1.3, 29.17], [2, 1.31, 1546.71]]}, {"timestamp": 1578773244033, "ltp": 1.3, "tv": 39209.95, "trd": NaN, "batb": [[1, 1.27, 4740.8]], "batl": NaN}, {"timestamp": 1578773245001, "ltp": 1.3, "tv": 39209.95, "trd": NaN, "batb": [[1, 1.27, 3874.78]], "batl": NaN}, {"timestamp": 1578773246995, "ltp": 1.3, "tv": 39209.95, "trd": NaN, "batb": [[0, 1.28, 2058.29]], "batl": [[2, 1.31, 1996.71]]}, {"timestamp": 1578773247997, "ltp": 1.3, "tv": 39209.95, "trd": NaN, "batb": NaN, "batl": [[1, 1.3, 213.51]]}, {"timestamp": 1578773249001, "ltp": 1.3, "tv": 39209.95, "trd": NaN, "batb": NaN, "batl": [[1, 1.3, 108.38]]}, {"timestamp": 1578773250004, "ltp": 1.3, "tv": 39209.95, "trd": NaN, "batb": [[2, 1.26, 2648.06]], "batl": NaN}, {"timestamp": 1578773251010, "ltp": 1.3, "tv": 39209.95, "trd": NaN, "batb": [[1, 1.27, 4091.76]], "batl": NaN}, {"timestamp": 1578773252052, "ltp": 1.29, "tv": 39210.32, "trd": [[1.29, 168.82]], "batb": NaN, "batl": [[0, 1.29, 4.07]]}, {"timestamp": 1578773253020, "ltp": 1.29, "tv": 39210.32, "trd": NaN, "batb": [[0, 1.28, 1828.68], [1, 1.27, 4395.63]], "batl": [[1, 1.3, 140.08]]}, {"timestamp": 1578773254013, "ltp": 1.29, "tv": 39210.32, "trd": NaN, "batb": [[0, 1.28, 1555.35]], "batl": NaN}, {"timestamp": 1578773255027, "ltp": 1.29, "tv": 39210.32, "trd": NaN, "batb": NaN, "batl": [[1, 1.3, 110.92]]}, {"timestamp": 1578773256045, "ltp": 1.29, "tv": 39214.15, "trd": [[1.29, 172.65]], "batb": NaN, "batl": [[0, 1.29, 2.15]]}, {"timestamp": 1578773256995, "ltp": 1.29, "tv": 39218.45, "trd": [[1.29, 176.96]], "batb": [[0, 1.29, 1.77], [1, 1.28, 1555.35], [2, 1.27, 4395.63]], "batl": [[0, 1.3, 110.92], [1, 1.31, 1996.71], [2, 1.32, 1613.42]]}, {"timestamp": 1578773259005, "ltp": 1.29, "tv": 39218.45, "trd": NaN, "batb": [[2, 1.27, 4379.35]], "batl": [[1, 1.31, 2446.71], [2, 1.32, 1363.55]]}, {"timestamp": 1578773260917, "ltp": 1.29, "tv": 39218.45, "trd": NaN, "batb": [[0, 1.29, 11.99], [2, 1.27, 3609.35]], "batl": [[1, 1.31, 3353.47], [2, 1.32, 1375.55]]}, {"timestamp": 1578773262035, "ltp": 1.29, "tv": 39242.42, "trd": [[1.29, 200.93]], "batb": [[0, 1.28, 1555.35], [1, 1.27, 3609.35], [2, 1.26, 3530.58]], "batl": [[0, 1.29, 17.18], [1, 1.3, 791.22], [2, 1.31, 3353.47]]}, {"timestamp": 1578773263030, "ltp": 1.29, "tv": 39242.42, "trd": NaN, "batb": [[1, 1.27, 3961.7]], "batl": [[2, 1.31, 2446.71]]}, {"timestamp": 1578773264034, "ltp": 1.29, "tv": 39246.66, "trd": [[1.29, 205.17]], "batb": [[1, 1.27, 4245.16]], "batl": [[0, 1.29, 15.06]]}, {"timestamp": 1578773265010, "ltp": 1.29, "tv": 39261.73, "trd": [[1.29, 220.23]], "batb": NaN, "batl": [[0, 1.3, 1066.23], [1, 1.31, 2446.71], [2, 1.32, 1928.66]]}, {"timestamp": 1578773266020, "ltp": 1.28, "tv": 39262.1, "trd": [[1.28, 0.37]], "batb": [[0, 1.28, 1555.16], [2, 1.26, 3551.86]], "batl": [[0, 1.3, 1170.25], [1, 1.31, 2489.27]]}, {"timestamp": 1578773266974, "ltp": 1.28, "tv": 39262.1, "trd": NaN, "batb": NaN, "batl": [[2, 1.32, 2445.27]]}, {"timestamp": 1578773269036, "ltp": 1.28, "tv": 39262.1, "trd": NaN, "batb": NaN, "batl": [[2, 1.32, 3323.23]]}, {"timestamp": 1578773269829, "ltp": 1.28, "tv": 39262.1, "trd": NaN, "batb": [[0, 1.28, 1555.74]], "batl": NaN}, {"timestamp": 1578773271037, "ltp": 1.28, "tv": 39268.22, "trd": [[1.28, 5.33], [1.29, 221.39]], "batb": [[0, 1.28, 1552.68]], "batl": NaN}, {"timestamp": 1578773272051, "ltp": 1.29, "tv": 39272.22, "trd": [[1.29, 225.39]], "batb": [[2, 1.26, 3556.86]], "batl": [[2, 1.32, 3344.51]]}, {"timestamp": 1578773273949, "ltp": 1.29, "tv": 39272.22, "trd": NaN, "batb": [[0, 1.28, 817.68]], "batl": NaN}, {"timestamp": 1578773276009, "ltp": 1.29, "tv": 39272.22, "trd": NaN, "batb": [[1, 1.27, 2417.72], [2, 1.26, 5648.34]], "batl": [[1, 1.31, 4396.19], [2, 1.32, 1396.83]]}, {"timestamp": 1578773276957, "ltp": 1.29, "tv": 39272.22, "trd": NaN, "batb": [[0, 1.28, 818.26]], "batl": NaN}, {"timestamp": 1578773277963, "ltp": 1.29, "tv": 39272.22, "trd": NaN, "batb": [[1, 1.27, 2415.72]], "batl": NaN}, {"timestamp": 1578773279971, "ltp": 1.3, "tv": 39276.27, "trd": [[1.3, 1014.11]], "batb": [[2, 1.26, 5631.32]], "batl": [[0, 1.3, 1168.22], [2, 1.32, 1311.71]]}, {"timestamp": 1578773280971, "ltp": 1.3, "tv": 39276.27, "trd": NaN, "batb": [[0, 1.28, 459.3]], "batl": [[0, 1.3, 1668.22]]}, {"timestamp": 1578773283055, "ltp": 1.28, "tv": 39295.08, "trd": [[1.28, 22.86], [1.29, 226.55], [1.3, 1014.23]], "batb": [[0, 1.28, 452.96]], "batl": [[0, 1.3, 1668.17]]}, {"timestamp": 1578773283966, "ltp": 1.28, "tv": 39295.08, "trd": NaN, "batb": [[1, 1.27, 3909.59], [2, 1.26, 3539.84]], "batl": [[1, 1.31, 3877.48]]}, {"timestamp": 1578773284960, "ltp": 1.28, "tv": 39325.69, "trd": [[1.28, 53.47]], "batb": [[0, 1.28, 437.66], [2, 1.26, 3938.82]], "batl": NaN}, {"timestamp": 1578773285965, "ltp": 1.28, "tv": 39325.69, "trd": NaN, "batb": [[2, 1.26, 3539.84]], "batl": NaN}, {"timestamp": 1578773286973, "ltp": 1.28, "tv": 39478.76, "trd": [[1.28, 206.54]], "batb": [[0, 1.28, 361.12], [1, 1.27, 3752.59]], "batl": [[1, 1.31, 3962.6]]}, {"timestamp": 1578773287982, "ltp": 1.28, "tv": 39478.76, "trd": NaN, "batb": [[2, 1.26, 3497.28]], "batl": NaN}, {"timestamp": 1578773289989, "ltp": 1.28, "tv": 39478.76, "trd": NaN, "batb": NaN, "batl": [[2, 1.32, 1923.32]]}, {"timestamp": 1578773290957, "ltp": 1.28, "tv": 39486.23, "trd": [[1.28, 214.02]], "batb": [[0, 1.28, 357.38]], "batl": NaN}, {"timestamp": 1578773292017, "ltp": 1.28, "tv": 39486.23, "trd": NaN, "batb": [[2, 1.26, 1777.87]], "batl": [[1, 1.31, 3062.6], [2, 1.32, 1311.71]]}, {"timestamp": 1578773292977, "ltp": 1.28, "tv": 39486.23, "trd": NaN, "batb": NaN, "batl": [[0, 1.3, 1652.86]]}, {"timestamp": 1578773293982, "ltp": 1.28, "tv": 39486.23, "trd": NaN, "batb": [[1, 1.27, 2258.72], [2, 1.26, 3913.08]], "batl": [[0, 1.29, 658], [1, 1.3, 1652.86], [2, 1.31, 3062.6]]}, {"timestamp": 1578773297975, "ltp": 1.28, "tv": 39486.23, "trd": NaN, "batb": NaN, "batl": [[2, 1.31, 3674.23]]}, {"timestamp": 1578773298992, "ltp": 1.28, "tv": 39486.23, "trd": NaN, "batb": [[2, 1.26, 1777.87]], "batl": [[1, 1.3, 2820.3], [2, 1.31, 1674.39]]}, {"timestamp": 1578773299988, "ltp": 1.28, "tv": 39486.23, "trd": NaN, "batb": [[1, 1.27, 2173.6]], "batl": [[1, 1.3, 3270.3], [2, 1.31, 1630.33]]}, {"timestamp": 1578773300986, "ltp": 1.28, "tv": 39486.23, "trd": NaN, "batb": NaN, "batl": [[2, 1.31, 1322.18]]}, {"timestamp": 1578773301987, "ltp": 1.28, "tv": 39486.23, "trd": NaN, "batb": NaN, "batl": [[2, 1.31, 1214.27]]}, {"timestamp": 1578773302994, "ltp": 1.28, "tv": 39486.23, "trd": NaN, "batb": [[2, 1.26, 3388.85]], "batl": [[2, 1.31, 1171.71]]}, {"timestamp": 1578773306978, "ltp": 1.28, "tv": 39486.23, "trd": NaN, "batb": [[2, 1.26, 3471.97]], "batl": [[0, 1.29, 702.02], [1, 1.3, 4010.35]]}, {"timestamp": 1578773308025, "ltp": 1.28, "tv": 39486.23, "trd": NaN, "batb": NaN, "batl": [[0, 1.29, 1015.5]]}, {"timestamp": 1578773309046, "ltp": 1.28, "tv": 39486.23, "trd": NaN, "batb": NaN, "batl": [[0, 1.29, 1125.69]]}, {"timestamp": 1578773310002, "ltp": 1.28, "tv": 39486.23, "trd": NaN, "batb": NaN, "batl": [[0, 1.29, 1625.69], [1, 1.3, 4052.91]]}, {"timestamp": 1578773312976, "ltp": 1.28, "tv": 39486.23, "trd": NaN, "batb": [[2, 1.26, 3312.97]], "batl": NaN}, {"timestamp": 1578773315004, "ltp": 1.28, "tv": 39486.23, "trd": NaN, "batb": [[2, 1.26, 1701.99]], "batl": [[1, 1.3, 4563.71]]}, {"timestamp": 1578773315993, "ltp": 1.28, "tv": 39536.23, "trd": [[1.28, 264.02]], "batb": [[0, 1.28, 332.38]], "batl": NaN}, {"timestamp": 1578773317988, "ltp": 1.28, "tv": 39536.23, "trd": NaN, "batb": NaN, "batl": [[0, 1.29, 1657.39]]}, {"timestamp": 1578773318985, "ltp": 1.28, "tv": 39536.23, "trd": NaN, "batb": [[1, 1.27, 1487.6]], "batl": NaN}, {"timestamp": 1578773320027, "ltp": 1.28, "tv": 39548.15, "trd": [[1.28, 275.94]], "batb": [[0, 1.28, 326.42]], "batl": NaN}, {"timestamp": 1578773323026, "ltp": 1.28, "tv": 39548.15, "trd": NaN, "batb": [[2, 1.26, 1680.71]], "batl": NaN}, {"timestamp": 1578773325019, "ltp": 1.28, "tv": 39548.15, "trd": NaN, "batb": NaN, "batl": [[2, 1.31, 1086.59]]}, {"timestamp": 1578773325985, "ltp": 1.28, "tv": 39558.85, "trd": [[1.28, 286.64]], "batb": [[0, 1.28, 321.07], [1, 1.27, 1204.14], [2, 1.26, 1460.08]], "batl": [[1, 1.3, 4113.71]]}, {"timestamp": 1578773331005, "ltp": 1.28, "tv": 39879.93, "trd": [[1.28, 607.71]], "batb": [[0, 1.27, 974.54], [1, 1.26, 1460.08], [2, 1.25, 3670.2]], "batl": [[0, 1.28, 631], [1, 1.29, 1657.39], [2, 1.3, 4198.84]]}, {"timestamp": 1578773332002, "ltp": 1.28, "tv": 39879.93, "trd": NaN, "batb": [[0, 1.27, 566.74]], "batl": [[0, 1.28, 707.53], [2, 1.3, 4157.12]]}, {"timestamp": 1578773333043, "ltp": 1.27, "tv": 39880.45, "trd": [[1.27, 0.52]], "batb": [[0, 1.27, 566.48]], "batl": [[1, 1.29, 1625.69]]}, {"timestamp": 1578773334037, "ltp": 1.27, "tv": 39880.45, "trd": NaN, "batb": NaN, "batl": [[1, 1.29, 2075.69]]}, {"timestamp": 1578773338028, "ltp": 1.27, "tv": 39880.45, "trd": NaN, "batb": [[1, 1.26, 1374.96]], "batl": NaN}, {"timestamp": 1578773339015, "ltp": 1.27, "tv": 39880.45, "trd": NaN, "batb": NaN, "batl": [[0, 1.28, 754.72], [1, 1.29, 3476.88], [2, 1.3, 2906.27]]}, {"timestamp": 1578773340012, "ltp": 1.27, "tv": 39880.45, "trd": NaN, "batb": NaN, "batl": [[0, 1.28, 786.42]]}, {"timestamp": 1578773341027, "ltp": 1.27, "tv": 39880.45, "trd": NaN, "batb": [[2, 1.25, 3627.64]], "batl": NaN}, {"timestamp": 1578773342028, "ltp": 1.27, "tv": 39880.45, "trd": NaN, "batb": NaN, "batl": [[0, 1.28, 709.89]]}, {"timestamp": 1578773343023, "ltp": 1.27, "tv": 39880.45, "trd": NaN, "batb": NaN, "batl": [[1, 1.29, 2075.69]]}, {"timestamp": 1578773345016, "ltp": 1.27, "tv": 39880.45, "trd": NaN, "batb": [[2, 1.25, 3712.76]], "batl": NaN}, {"timestamp": 1578773346017, "ltp": 1.27, "tv": 39880.45, "trd": NaN, "batb": NaN, "batl": [[2, 1.3, 2041.83]]}, {"timestamp": 1578773346908, "ltp": 1.27, "tv": 39880.45, "trd": NaN, "batb": [[2, 1.25, 3716.76]], "batl": [[2, 1.3, 3292.48]]}, {"timestamp": 1578773349955, "ltp": 1.27, "tv": 40033.52, "trd": [[1.27, 153.59]], "batb": [[0, 1.27, 489.95]], "batl": NaN}, {"timestamp": 1578773351022, "ltp": 1.27, "tv": 40035.82, "trd": [[1.27, 155.89]], "batb": [[0, 1.27, 488.8]], "batl": NaN}, {"timestamp": 1578773352025, "ltp": 1.27, "tv": 40035.82, "trd": NaN, "batb": [[1, 1.26, 647.96]], "batl": NaN}, {"timestamp": 1578773353021, "ltp": 1.27, "tv": 40035.82, "trd": NaN, "batb": NaN, "batl": [[0, 1.28, 1142.5]]}, {"timestamp": 1578773354020, "ltp": 1.27, "tv": 40054.5, "trd": [[1.27, 174.58]], "batb": [[0, 1.27, 479.45]], "batl": [[1, 1.29, 2525.69]]}, {"timestamp": 1578773356946, "ltp": 1.27, "tv": 40054.5, "trd": NaN, "batb": [[2, 1.25, 3556.76]], "batl": NaN}, {"timestamp": 1578773358053, "ltp": 1.27, "tv": 40054.5, "trd": NaN, "batb": [[2, 1.25, 1549.99]], "batl": [[1, 1.29, 4525.57], [2, 1.3, 1292.68]]}, {"timestamp": 1578773361967, "ltp": 1.27, "tv": 40054.86, "trd": [[1.27, 174.93]], "batb": [[0, 1.27, 479.27]], "batl": NaN}, {"timestamp": 1578773368979, "ltp": 1.27, "tv": 40054.86, "trd": NaN, "batb": NaN, "batl": [[0, 1.28, 1642.5]]}, {"timestamp": 1578773370974, "ltp": 1.27, "tv": 41013.4, "trd": [[1.27, 1133.48]], "batb": [[0, 1.26, 398.6], [1, 1.25, 1549.99], [2, 1.24, 3858.8]], "batl": NaN}, {"timestamp": 1578773371976, "ltp": 1.28, "tv": 41029.52, "trd": [[1.28, 623.83]], "batb": [[0, 1.27, 5], [1, 1.26, 282.27], [2, 1.25, 1549.99]], "batl": [[0, 1.28, 1602.73]]}, {"timestamp": 1578773373967, "ltp": 1.27, "tv": 41039.52, "trd": [[1.27, 1143.47]], "batb": [[0, 1.26, 282.27], [1, 1.25, 1549.99], [2, 1.24, 3858.8]], "batl": [[0, 1.27, 33.97], [1, 1.28, 1602.73], [2, 1.29, 2525.69]]}, {"timestamp": 1578773377957, "ltp": 1.27, "tv": 41039.52, "trd": NaN, "batb": [[2, 1.24, 5695.9]], "batl": NaN}, {"timestamp": 1578773379996, "ltp": 1.27, "tv": 41039.52, "trd": NaN, "batb": [[0, 1.26, 12.65]], "batl": NaN}, {"timestamp": 1578773382999, "ltp": 1.27, "tv": 41039.52, "trd": NaN, "batb": NaN, "batl": [[2, 1.29, 2610.81]]}, {"timestamp": 1578773386004, "ltp": 1.27, "tv": 41039.52, "trd": NaN, "batb": [[2, 1.24, 6045.42]], "batl": NaN}, {"timestamp": 1578773386993, "ltp": 1.27, "tv": 41039.52, "trd": NaN, "batb": NaN, "batl": [[0, 1.27, 72.24]]}, {"timestamp": 1578773388000, "ltp": 1.27, "tv": 41039.52, "trd": NaN, "batb": NaN, "batl": [[2, 1.29, 2566.79]]}, {"timestamp": 1578773389002, "ltp": 1.26, "tv": 41039.84, "trd": [[1.26, 0.32]], "batb": [[0, 1.26, 12.49]], "batl": NaN}, {"timestamp": 1578773390002, "ltp": 1.26, "tv": 41039.84, "trd": NaN, "batb": NaN, "batl": [[0, 1.27, 103.95], [2, 1.29, 2143.12]]}, {"timestamp": 1578773391007, "ltp": 1.26, "tv": 41039.84, "trd": NaN, "batb": [[1, 1.25, 1464.87], [2, 1.24, 6028.39]], "batl": [[0, 1.27, 775.95]]}, {"timestamp": 1578773392004, "ltp": 1.26, "tv": 41039.84, "trd": NaN, "batb": [[1, 1.25, 1443.59], [2, 1.24, 5678.87]], "batl": NaN}, {"timestamp": 1578773392998, "ltp": 1.26, "tv": 41044.43, "trd": [[1.26, 4.91]], "batb": [[0, 1.26, 10.2]], "batl": [[2, 1.29, 4143]]}, {"timestamp": 1578773394005, "ltp": 1.26, "tv": 41044.43, "trd": NaN, "batb": NaN, "batl": [[2, 1.29, 2143.12]]}, {"timestamp": 1578773395022, "ltp": 1.26, "tv": 41044.43, "trd": NaN, "batb": NaN, "batl": [[0, 1.27, 822]]}, {"timestamp": 1578773397009, "ltp": 1.26, "tv": 41044.43, "trd": NaN, "batb": NaN, "batl": [[0, 1.27, 1258.05]]}, {"timestamp": 1578773398010, "ltp": 1.26, "tv": 41051.9, "trd": [[1.26, 12.38]], "batb": [[0, 1.26, 6.46]], "batl": NaN}, {"timestamp": 1578773399010, "ltp": 1.26, "tv": 41051.9, "trd": NaN, "batb": [[2, 1.24, 5707.81]], "batl": NaN}, {"timestamp": 1578773401031, "ltp": 1.26, "tv": 41051.9, "trd": NaN, "batb": [[2, 1.24, 5686.53]], "batl": NaN}, {"timestamp": 1578773402040, "ltp": 1.26, "tv": 41051.9, "trd": NaN, "batb": NaN, "batl": [[0, 1.27, 1219.79]]}, {"timestamp": 1578773406034, "ltp": 1.26, "tv": 41051.9, "trd": NaN, "batb": NaN, "batl": [[2, 1.29, 1693.12]]}, {"timestamp": 1578773408040, "ltp": 1.26, "tv": 41064.82, "trd": [[1.26, 25.31]], "batb": [[0, 1.25, 1443.59], [1, 1.24, 5707.81], [2, 1.23, 2037.85]], "batl": [[0, 1.26, 31.81], [1, 1.27, 1219.79], [2, 1.28, 1602.73]]}, {"timestamp": 1578773409042, "ltp": 1.26, "tv": 41064.82, "trd": NaN, "batb": [[0, 1.25, 1186.31]], "batl": NaN}, {"timestamp": 1578773413924, "ltp": 1.26, "tv": 41064.82, "trd": NaN, "batb": NaN, "batl": [[2, 1.28, 2052.73]]}, {"timestamp": 1578773415032, "ltp": 1.26, "tv": 41064.82, "trd": NaN, "batb": [[0, 1.25, 956.7], [1, 1.24, 3420.29], [2, 1.23, 4358]], "batl": [[0, 1.26, 34.19]]}, {"timestamp": 1578773417048, "ltp": 1.26, "tv": 41065.18, "trd": [[1.26, 25.66]], "batb": NaN, "batl": [[0, 1.26, 34.02]]}, {"timestamp": 1578773418049, "ltp": 1.26, "tv": 41065.18, "trd": NaN, "batb": NaN, "batl": [[0, 1.26, 36.44]]}, {"timestamp": 1578773420052, "ltp": 1.26, "tv": 41065.18, "trd": NaN, "batb": [[0, 1.25, 273.7]], "batl": NaN}, {"timestamp": 1578773421050, "ltp": 1.26, "tv": 41065.18, "trd": NaN, "batb": [[0, 1.25, 117.51], [1, 1.24, 2731.37]], "batl": NaN}, {"timestamp": 1578773424041, "ltp": 1.26, "tv": 41065.18, "trd": NaN, "batb": NaN, "batl": [[1, 1.27, 2690.92]]}, {"timestamp": 1578773425049, "ltp": 1.26, "tv": 41065.18, "trd": NaN, "batb": [[1, 1.24, 2570.37]], "batl": NaN}, {"timestamp": 1578773426052, "ltp": 1.26, "tv": 41065.18, "trd": NaN, "batb": NaN, "batl": [[2, 1.28, 2016.16]]}, {"timestamp": 1578773427048, "ltp": 1.26, "tv": 41065.18, "trd": NaN, "batb": NaN, "batl": [[2, 1.28, 1852.24]]}, {"timestamp": 1578773428045, "ltp": 1.26, "tv": 41065.18, "trd": NaN, "batb": [[2, 1.23, 5213.21]], "batl": [[2, 1.28, 2302.24]]}, {"timestamp": 1578773431052, "ltp": 1.26, "tv": 41065.18, "trd": NaN, "batb": NaN, "batl": [[0, 1.26, 34.06]]}, {"timestamp": 1578773431967, "ltp": 1.26, "tv": 41066.77, "trd": [[1.26, 27.25]], "batb": [[0, 1.25, 827.51], [1, 1.24, 4332.89]], "batl": [[0, 1.26, 33.26]]}, {"timestamp": 1578773432964, "ltp": 1.26, "tv": 41066.77, "trd": NaN, "batb": [[2, 1.23, 2726.77]], "batl": [[0, 1.26, 73.69]]}, {"timestamp": 1578773433967, "ltp": 1.26, "tv": 41066.77, "trd": NaN, "batb": NaN, "batl": [[0, 1.26, 201.87], [1, 1.27, 2656.94]]}, {"timestamp": 1578773434971, "ltp": 1.26, "tv": 41066.77, "trd": NaN, "batb": [[1, 1.24, 4334.89], [2, 1.23, 2728.77]], "batl": [[0, 1.26, 33.26]]}, {"timestamp": 1578773435983, "ltp": 1.26, "tv": 41066.77, "trd": NaN, "batb": NaN, "batl": [[0, 1.26, 30.84]]}, {"timestamp": 1578773437992, "ltp": 1.26, "tv": 41066.77, "trd": NaN, "batb": [[1, 1.24, 3416.34]], "batl": NaN}, {"timestamp": 1578773440987, "ltp": 1.26, "tv": 41066.77, "trd": NaN, "batb": [[0, 1.25, 852.51]], "batl": NaN}, {"timestamp": 1578773441892, "ltp": 1.25, "tv": 41134.72, "trd": [[1.25, 67.95]], "batb": [[0, 1.25, 818.53]], "batl": NaN}, {"timestamp": 1578773442987, "ltp": 1.25, "tv": 41134.72, "trd": NaN, "batb": [[2, 1.23, 5126.4]], "batl": NaN}, {"timestamp": 1578773443991, "ltp": 1.25, "tv": 41180.64, "trd": [[1.25, 113.87]], "batb": [[0, 1.25, 85.57]], "batl": NaN}, {"timestamp": 1578773444990, "ltp": 1.25, "tv": 41180.64, "trd": NaN, "batb": [[1, 1.24, 1653.82], [2, 1.23, 3417.69]], "batl": NaN}, {"timestamp": 1578773445995, "ltp": 1.25, "tv": 41181.31, "trd": [[1.25, 114.54]], "batb": [[0, 1.25, 85.13]], "batl": NaN}, {"timestamp": 1578773447007, "ltp": 1.25, "tv": 41181.31, "trd": NaN, "batb": [[2, 1.23, 3583.98]], "batl": [[2, 1.28, 2022.94]]}, {"timestamp": 1578773448009, "ltp": 1.25, "tv": 41181.31, "trd": NaN, "batb": [[2, 1.23, 3417.69]], "batl": NaN}, {"timestamp": 1578773450994, "ltp": 1.25, "tv": 41181.31, "trd": NaN, "batb": [[2, 1.23, 3667.08]], "batl": [[2, 1.28, 2108.06]]}, {"timestamp": 1578773451995, "ltp": 1.25, "tv": 41181.31, "trd": NaN, "batb": [[2, 1.23, 4490.99]], "batl": NaN}, {"timestamp": 1578773452992, "ltp": 1.25, "tv": 41216.08, "trd": [[1.25, 119.31], [1.26, 57.25]], "batb": [[0, 1.25, 82.75], [2, 1.23, 6367.14]], "batl": [[0, 1.26, 64.82], [1, 1.27, 1185.81], [2, 1.28, 4104.4]]}, {"timestamp": 1578773453987, "ltp": 1.25, "tv": 41216.08, "trd": NaN, "batb": [[1, 1.24, 1663.82]], "batl": [[0, 1.26, 548.11]]}, {"timestamp": 1578773455985, "ltp": 1.25, "tv": 41216.08, "trd": NaN, "batb": [[1, 1.24, 1982.71]], "batl": NaN}, {"timestamp": 1578773458996, "ltp": 1.26, "tv": 41232.7, "trd": [[1.26, 73.87]], "batb": NaN, "batl": [[0, 1.26, 539.8]]}, {"timestamp": 1578773462014, "ltp": 1.26, "tv": 41234.5, "trd": [[1.26, 75.68]], "batb": [[1, 1.24, 3602.48], [2, 1.23, 3667.08]], "batl": [[0, 1.26, 538.89]]}, {"timestamp": 1578773464011, "ltp": 1.25, "tv": 41400.0, "trd": [[1.25, 284.81]], "batb": [[0, 1.24, 3602.48], [1, 1.23, 3667.08], [2, 1.22, 1777.94]], "batl": [[0, 1.25, 42.25], [1, 1.26, 538.89], [2, 1.27, 1185.81]]}, {"timestamp": 1578773465905, "ltp": 1.25, "tv": 41400.0, "trd": NaN, "batb": NaN, "batl": [[1, 1.26, 494.01]]}, {"timestamp": 1578773468026, "ltp": 1.25, "tv": 41400.94, "trd": [[1.25, 285.75]], "batb": NaN, "batl": [[0, 1.25, 41.78]]}, {"timestamp": 1578773469028, "ltp": 1.25, "tv": 41400.94, "trd": NaN, "batb": NaN, "batl": [[2, 1.27, 1154.11]]}, {"timestamp": 1578773470031, "ltp": 1.25, "tv": 41400.94, "trd": NaN, "batb": NaN, "batl": [[0, 1.26, 494.01], [1, 1.27, 1154.11], [2, 1.28, 3654.4]]}, {"timestamp": 1578773472032, "ltp": 1.26, "tv": 41492.79, "trd": [[1.26, 167.52]], "batb": NaN, "batl": [[0, 1.26, 448.08]]}, {"timestamp": 1578773473033, "ltp": 1.26, "tv": 41492.92, "trd": [[1.26, 167.66]], "batb": NaN, "batl": [[0, 1.26, 448.02], [1, 1.27, 1604.11]]}, {"timestamp": 1578773475026, "ltp": 1.26, "tv": 41492.92, "trd": NaN, "batb": NaN, "batl": [[0, 1.26, 1152.02]]}, {"timestamp": 1578773476034, "ltp": 1.26, "tv": 41492.92, "trd": NaN, "batb": NaN, "batl": [[0, 1.26, 1183.72]]}, {"timestamp": 1578773477041, "ltp": 1.24, "tv": 41576.48, "trd": [[1.24, 91.29]], "batb": [[0, 1.24, 3560.7]], "batl": NaN}, {"timestamp": 1578773480032, "ltp": 1.24, "tv": 41576.48, "trd": NaN, "batb": NaN, "batl": [[0, 1.26, 1152.02]]}, {"timestamp": 1578773481035, "ltp": 1.24, "tv": 41576.48, "trd": NaN, "batb": [[0, 1.24, 3563.7]], "batl": NaN}, {"timestamp": 1578773482030, "ltp": 1.24, "tv": 41576.48, "trd": NaN, "batb": [[0, 1.24, 3542.42], [1, 1.23, 3479.06]], "batl": NaN}, {"timestamp": 1578773483027, "ltp": 1.24, "tv": 41581.34, "trd": [[1.24, 96.15]], "batb": [[0, 1.24, 3540]], "batl": [[0, 1.25, 38.27], [1, 1.26, 1152.02], [2, 1.27, 1604.11]]}, {"timestamp": 1578773484029, "ltp": 1.24, "tv": 41581.34, "trd": NaN, "batb": [[0, 1.24, 3310.37], [1, 1.23, 2790.14]], "batl": [[2, 1.27, 2104.11]]}, {"timestamp": 1578773485025, "ltp": 1.24, "tv": 41581.34, "trd": NaN, "batb": [[1, 1.23, 1851.83]], "batl": [[2, 1.27, 1654.11]]}, {"timestamp": 1578773486970, "ltp": 1.24, "tv": 41622.56, "trd": [[1.24, 137.36]], "batb": [[0, 1.24, 3289.76]], "batl": NaN}, {"timestamp": 1578773487967, "ltp": 1.24, "tv": 41622.56, "trd": NaN, "batb": [[0, 1.24, 1669.99]], "batl": [[1, 1.26, 448.02], [2, 1.27, 982.11]]}, {"timestamp": 1578773488958, "ltp": 1.25, "tv": 41637.6, "trd": [[1.25, 300.79]], "batb": [[1, 1.23, 1873.11], [2, 1.22, 1802.62]], "batl": [[0, 1.25, 30.74]]}, {"timestamp": 1578773489957, "ltp": 1.25, "tv": 41637.6, "trd": NaN, "batb": [[2, 1.22, 1812.62]], "batl": NaN}, {"timestamp": 1578773492051, "ltp": 1.25, "tv": 41637.6, "trd": NaN, "batb": [[0, 1.24, 1186.3]], "batl": NaN}, {"timestamp": 1578773492991, "ltp": 1.25, "tv": 41637.6, "trd": NaN, "batb": NaN, "batl": [[1, 1.26, 898.02]]}, {"timestamp": 1578773495967, "ltp": 1.25, "tv": 41637.6, "trd": NaN, "batb": NaN, "batl": [[0, 1.25, 76.66]]}, {"timestamp": 1578773499013, "ltp": 1.25, "tv": 41637.6, "trd": NaN, "batb": [[0, 1.24, 761.68], [2, 1.22, 2058.11]], "batl": NaN}, {"timestamp": 1578773500006, "ltp": 1.25, "tv": 41637.6, "trd": NaN, "batb": [[0, 1.24, 759.68], [1, 1.23, 1851.83], [2, 1.22, 2772.02]], "batl": [[1, 1.26, 1348.02]]}, {"timestamp": 1578773501004, "ltp": 1.24, "tv": 41681.74, "trd": [[1.24, 181.5]], "batb": [[0, 1.24, 737.61], [1, 1.23, 2184.58]], "batl": NaN}, {"timestamp": 1578773502005, "ltp": 1.24, "tv": 41681.74, "trd": NaN, "batb": NaN, "batl": [[2, 1.27, 1067.23]]}, {"timestamp": 1578773502999, "ltp": 1.24, "tv": 41812.01, "trd": [[1.24, 311.14], [1.25, 301.42]], "batb": [[0, 1.24, 672.79]], "batl": [[0, 1.25, 76.35]]}, {"timestamp": 1578773503997, "ltp": 1.24, "tv": 41812.01, "trd": NaN, "batb": NaN, "batl": [[0, 1.25, 30.43]]}, {"timestamp": 1578773506993, "ltp": 1.24, "tv": 41812.01, "trd": NaN, "batb": [[2, 1.22, 2776.27]], "batl": NaN}, {"timestamp": 1578773507991, "ltp": 1.24, "tv": 41818.85, "trd": [[1.24, 317.98]], "batb": [[0, 1.2