{"info": {"id": "1.166703727", "eventId": "29632571", "eventName": "Both teams to Score?", "marketType": "BOTH_TEAMS_TO_SCORE", "openDate": 1578772099563, "name": "Inter v Atalanta", "numberOfActiveRunner": 2, "countryCode": "", "sport": "TENNIS", "venue": "", "volume": {"total": 27522.52, "preMatch": 11643.32, "inPlay": 15879.2}, "winner": {"id": 30246, "name": "Yes", "status": "WINNER", "position": 1}, "delay": 7}, "runners": [{"id": 30246, "name": "Yes", "status": "WINNER", "position": 1, "inPlayOdds": 1.58, "inPlayTime": 1578772099563, "avgPrematch": 1.61, "closedOdds": 3.4, "maxPrematch": 1.63, "minPrematch": 1.56, "maxInPlay": 3.4, "minInPlay": 1.3, "inPlayIndex": 1960, "lengthOdds": 4270, "lengthOddsPrematch": 1960, "lengthOddsInPlay": 2310, "tradedVolume": 21109.69, "preMatchVolume": 10495.77, "inPlayVolume": 10613.92}, {"id": 110503, "name": "No", "status": "LOSER", "position": 2, "inPlayOdds": 2.66, "inPlayTime": 1578772099563, "avgPrematch": 2.64, "closedOdds": 1.42, "maxPrematch": 2.78, "minPrematch": 2.6, "maxInPlay": 3.95, "minInPlay": 1.42, "inPlayIndex": 1713, "lengthOdds": 4003, "lengthOddsPrematch": 1713, "lengthOddsInPlay": 2290, "tradedVolume": 6412.83, "preMatchVolume": 1147.55, "inPlayVolume": 5265.28}], "marketUpdates": [{"timestamp": 1578513294362000000, "openDate": "2020-01-11T19:45:00.000Z", "status": "OPEN", "betDelay": 0, "inPlay": false, "complete": true}, {"timestamp": 1578772099563000000, "openDate": "2020-01-11T19:45:00.000Z", "status": "OPEN", "betDelay": 7, "inPlay": true, "complete": true}, {"timestamp": 1578772294860000000, "openDate": "2020-01-11T19:45:00.000Z", "status": "SUSPENDED", "betDelay": 7, "inPlay": true, "complete": true}, {"timestamp": 1578772347979000000, "openDate": "2020-01-11T19:45:00.000Z", "status": "OPEN", "betDelay": 7, "inPlay": true, "complete": true}, {"timestamp": 1578774525024000000, "openDate": "2020-01-11T19:45:00.000Z", "status": "SUSPENDED", "betDelay": 7, "inPlay": true, "complete": true}, {"timestamp": 1578774556973000000, "openDate": "2020-01-11T19:45:00.000Z", "status": "OPEN", "betDelay": 7, "inPlay": true, "complete": true}, {"timestamp": 1578774580039000000, "openDate": "2020-01-11T19:45:00.000Z", "status": "SUSPENDED", "betDelay": 7, "inPlay": true, "complete": true}, {"timestamp": 1578774582036000000, "openDate": "2020-01-11T19:45:00.000Z", "status": "OPEN", "betDelay": 7, "inPlay": true, "complete": true}, {"timestamp": 1578774866982000000, "openDate": "2020-01-11T19:45:00.000Z", "status": "OPEN", "betDelay": 1, "inPlay": true, "complete": true}, {"timestamp": 1578775780035000000, "openDate": "2020-01-11T19:45:00.000Z", "status": "OPEN", "betDelay": 7, "inPlay": true, "complete": true}, {"timestamp": 1578777631947000000, "openDate": "2020-01-11T19:45:00.000Z", "status": "SUSPENDED", "betDelay": 7, "inPlay": true, "complete": true}, {"timestamp": 1578777766027000000, "openDate": "2020-01-11T19:45:00.000Z", "status": "CLOSED", "betDelay": 7, "inPlay": true, "complete": true}], "odds": [{"runnerId": 30246, "odds": [{"timestamp": 1578588188461, "ltp": 1.57, "tv": 3.84, "trd": [[1.57, 3.85]], "batb": [[0, 1.56, 357.08], [1, 1.54, 111.36], [2, 1.01, 2]], "batl": [[0, 1.57, 3.28], [1, 1.65, 1.96], [2, 1.74, 199.75]]}, {"timestamp": 1578588204342, "ltp": 1.57, "tv": 3.84, "trd": NaN, "batb": NaN, "batl": [[1, 1.74, 199.75], [2, 1000, 2.2]]}, {"timestamp": 1578588220186, "ltp": 1.57, "tv": 3.84, "trd": NaN, "batb": NaN, "batl": [[1, 1.67, 199.77]]}, {"timestamp": 1578588557632, "ltp": 1.56, "tv": 10.4, "trd": [[1.56, 6.55]], "batb": [[0, 1.56, 353.8]], "batl": [[0, 1.67, 199.77], [1, 1000, 2.2], [2, 1000, 0]]}, {"timestamp": 1578589338491, "ltp": 1.56, "tv": 10.39, "trd": [[1.56, 6.55], [1.57, 3.84]], "batb": [[1, 1.55, 109.34]], "batl": NaN}, {"timestamp": 1578589490668, "ltp": 1.56, "tv": 10.39, "trd": NaN, "batb": [[0, 1.57, 1.93], [1, 1.56, 353.8], [2, 1.55, 109.34]], "batl": [[0, 1.64, 1.84], [1, 1.67, 199.77], [2, 1000, 2.2]]}, {"timestamp": 1578596551911, "ltp": 1.56, "tv": 10.39, "trd": [[1.56, 6.55], [1.57, 3.84]], "batb": [[0, 1.57, 1.93]], "batl": [[0, 1.64, 1.84]]}, {"timestamp": 1578599201032, "ltp": 1.56, "tv": 10.39, "trd": NaN, "batb": [[0, 1.57, 136.33]], "batl": [[0, 1.64, 59.68]]}, {"timestamp": 1578599201816, "ltp": 1.56, "tv": 10.39, "trd": NaN, "batb": [[0, 1.58, 344.68], [1, 1.57, 136.33]], "batl": NaN}, {"timestamp": 1578599372006, "ltp": 1.56, "tv": 10.39, "trd": NaN, "batb": [[0, 1.59, 372.58], [1, 1.58, 344.68], [2, 1.57, 136.33]], "batl": [[0, 1.64, 297.01]]}, {"timestamp": 1578599373039, "ltp": 1.56, "tv": 10.39, "trd": NaN, "batb": [[0, 1.6, 268.99], [1, 1.59, 372.58]], "batl": NaN}, {"timestamp": 1578599422999, "ltp": 1.56, "tv": 10.39, "trd": NaN, "batb": [[0, 1.6, 528.43], [1, 1.57, 1.93], [2, 1.55, 109.34]], "batl": NaN}, {"timestamp": 1578599457968, "ltp": 1.56, "tv": 10.39, "trd": NaN, "batb": [[1, 1.55, 109.34], [2, 1.01, 2]], "batl": [[0, 1.64, 295.17]]}, {"timestamp": 1578599458858, "ltp": 1.56, "tv": 10.39, "trd": NaN, "batb": [[0, 1.6, 489.3]], "batl": NaN}, {"timestamp": 1578603751928, "ltp": 1.56, "tv": 10.39, "trd": [[1.56, 6.55], [1.57, 3.84]], "batb": [[0, 1.6, 489.13]], "batl": [[0, 1.64, 294.94]]}, {"timestamp": 1578603922421, "ltp": 1.56, "tv": 10.39, "trd": NaN, "batb": NaN, "batl": [[0, 1.63, 24.19], [1, 1.64, 294.94], [2, 1.67, 199.77]]}, {"timestamp": 1578603939765, "ltp": 1.56, "tv": 10.39, "trd": NaN, "batb": NaN, "batl": [[0, 1.63, 199.29]]}, {"timestamp": 1578603947566, "ltp": 1.56, "tv": 10.39, "trd": NaN, "batb": NaN, "batl": [[0, 1.62, 1.86], [1, 1.63, 199.29], [2, 1.64, 294.94]]}, {"timestamp": 1578604012050, "ltp": 1.56, "tv": 10.39, "trd": NaN, "batb": NaN, "batl": [[2, 1.67, 199.77]]}, {"timestamp": 1578605377961, "ltp": 1.56, "tv": 10.39, "trd": NaN, "batb": [[1, 1.52, 115.65]], "batl": NaN}, {"timestamp": 1578605599007, "ltp": 1.56, "tv": 10.39, "trd": NaN, "batb": [[1, 1.53, 113.46]], "batl": NaN}, {"timestamp": 1578610951918, "ltp": 1.56, "tv": 10.38, "trd": NaN, "batb": [[0, 1.6, 489.1]], "batl": [[1, 1.63, 199.25]]}, {"timestamp": 1578612011812, "ltp": 1.56, "tv": 10.38, "trd": NaN, "batb": NaN, "batl": [[1, 1.63, 245.99]]}, {"timestamp": 1578612292697, "ltp": 1.56, "tv": 10.38, "trd": NaN, "batb": [[1, 1.53, 101.73]], "batl": NaN}, {"timestamp": 1578616228809, "ltp": 1.56, "tv": 10.38, "trd": NaN, "batb": [[0, 1.6, 268.99]], "batl": [[1, 1.63, 24.19]]}, {"timestamp": 1578616293927, "ltp": 1.56, "tv": 10.38, "trd": NaN, "batb": [[0, 1.6, 311.48]], "batl": [[1, 1.63, 57.33]]}, {"timestamp": 1578616408025, "ltp": 1.56, "tv": 10.38, "trd": NaN, "batb": [[0, 1.6, 489.95]], "batl": [[1, 1.63, 233.25]]}, {"timestamp": 1578617745964, "ltp": 1.56, "tv": 10.38, "trd": NaN, "batb": [[1, 1.58, 20.98], [2, 1.53, 101.73]], "batl": NaN}, {"timestamp": 1578618151932, "ltp": 1.56, "tv": 10.39, "trd": [[1.56, 6.55]], "batb": [[0, 1.6, 489.97], [1, 1.58, 21]], "batl": [[1, 1.63, 233.28]]}, {"timestamp": 1578625351924, "ltp": 1.56, "tv": 10.39, "trd": NaN, "batb": [[0, 1.6, 490.02], [1, 1.58, 21.01]], "batl": [[1, 1.63, 233.33]]}, {"timestamp": 1578632551910, "ltp": 1.56, "tv": 10.38, "trd": [[1.56, 6.55], [1.57, 3.84]], "batb": [[0, 1.6, 489.85], [1, 1.58, 21.02]], "batl": [[0, 1.62, 1.86], [1, 1.63, 233.16]]}, {"timestamp": 1578635996054, "ltp": 1.56, "tv": 10.38, "trd": NaN, "batb": NaN, "batl": [[2, 1.66, 199.75]]}, {"timestamp": 1578636018854, "ltp": 1.56, "tv": 10.38, "trd": [[1.56, 6.55], [1.57, 3.84]], "batb": [[0, 1.6, 489.74], [1, 1.58, 21.03]], "batl": [[1, 1.63, 233.04], [2, 1.67, 199.77]]}, {"timestamp": 1578636255587, "ltp": 1.56, "tv": 10.38, "trd": NaN, "batb": [[1, 1.53, 101.73], [2, 1.01, 2]], "batl": NaN}, {"timestamp": 1578637833686, "ltp": 1.56, "tv": 10.38, "trd": NaN, "batb": [[0, 1.6, 268.99]], "batl": [[1, 1.63, 24.18]]}, {"timestamp": 1578637898917, "ltp": 1.56, "tv": 10.38, "trd": NaN, "batb": [[0, 1.6, 311.44]], "batl": [[1, 1.63, 56.44]]}, {"timestamp": 1578638009833, "ltp": 1.56, "tv": 10.38, "trd": NaN, "batb": [[0, 1.6, 482.1]], "batl": [[1, 1.63, 238.99]]}, {"timestamp": 1578641344880, "ltp": 1.56, "tv": 10.38, "trd": NaN, "batb": NaN, "batl": [[1, 1.63, 200.78]]}, {"timestamp": 1578641697969, "ltp": 1.56, "tv": 10.38, "trd": NaN, "batb": NaN, "batl": [[0, 1.61, 24.18], [1, 1.62, 1.86], [2, 1.63, 176.6]]}, {"timestamp": 1578641822084, "ltp": 1.56, "tv": 10.38, "trd": NaN, "batb": NaN, "batl": [[1, 1.63, 176.6], [2, 1.67, 199.77]]}, {"timestamp": 1578642212526, "ltp": 1.6, "tv": 27.36, "trd": [[1.6, 16.98]], "batb": [[0, 1.6, 473.61]], "batl": NaN}, {"timestamp": 1578642630823, "ltp": 1.6, "tv": 27.36, "trd": NaN, "batb": NaN, "batl": [[2, 1000, 2.2]]}, {"timestamp": 1578642633903, "ltp": 1.6, "tv": 27.36, "trd": NaN, "batb": NaN, "batl": [[1, 1.63, 210.56]]}, {"timestamp": 1578642660904, "ltp": 1.6, "tv": 27.36, "trd": NaN, "batb": NaN, "batl": [[2, 1.66, 199.75]]}, {"timestamp": 1578642746956, "ltp": 1.6, "tv": 27.36, "trd": NaN, "batb": [[0, 1.6, 424.36]], "batl": NaN}, {"timestamp": 1578642859014, "ltp": 1.6, "tv": 27.36, "trd": NaN, "batb": [[0, 1.6, 473.61]], "batl": NaN}, {"timestamp": 1578642889861, "ltp": 1.6, "tv": 27.36, "trd": NaN, "batb": NaN, "batl": [[1, 1.63, 161.32]]}, {"timestamp": 1578643351913, "ltp": 1.6, "tv": 27.39, "trd": [[1.56, 6.55], [1.57, 3.84], [1.6, 17]], "batb": [[0, 1.6, 473.99]], "batl": [[0, 1.61, 24.2], [1, 1.63, 161.61]]}, {"timestamp": 1578644922117, "ltp": 1.6, "tv": 40.99, "trd": [[1.6, 30.6]], "batb": [[0, 1.6, 467.19]], "batl": NaN}, {"timestamp": 1578646951917, "ltp": 1.6, "tv": 40.97, "trd": [[1.57, 3.84], [1.6, 30.59]], "batb": [[0, 1.6, 466.99]], "batl": [[0, 1.61, 24.16], [1, 1.63, 161.45]]}, {"timestamp": 1578647070004, "ltp": 1.6, "tv": 40.97, "trd": NaN, "batb": [[1, 1.52, 103.68]], "batl": NaN}, {"timestamp": 1578648486883, "ltp": 1.6, "tv": 40.97, "trd": NaN, "batb": NaN, "batl": [[1, 1.63, 244.73]]}, {"timestamp": 1578648518004, "ltp": 1.6, "tv": 40.97, "trd": NaN, "batb": [[0, 1.6, 427.05]], "batl": NaN}, {"timestamp": 1578649308996, "ltp": 1.6, "tv": 40.97, "trd": NaN, "batb": [[0, 1.6, 455.94]], "batl": NaN}, {"timestamp": 1578649984017, "ltp": 1.6, "tv": 40.97, "trd": NaN, "batb": NaN, "batl": [[1, 1.63, 206.49]]}, {"timestamp": 1578652167010, "ltp": 1.6, "tv": 40.97, "trd": NaN, "batb": [[0, 1.6, 515.43]], "batl": NaN}, {"timestamp": 1578654151919, "ltp": 1.6, "tv": 40.97, "trd": [[1.56, 6.55], [1.6, 30.58]], "batb": [[0, 1.6, 515.38]], "batl": [[0, 1.61, 24.17], [1, 1.63, 206.46]]}, {"timestamp": 1578655135022, "ltp": 1.6, "tv": 40.97, "trd": NaN, "batb": NaN, "batl": [[0, 1.63, 206.46], [1, 1.66, 199.75], [2, 1000, 2.2]]}, {"timestamp": 1578655135284, "ltp": 1.6, "tv": 40.97, "trd": NaN, "batb": NaN, "batl": [[0, 1.62, 24.17], [1, 1.63, 206.46], [2, 1.66, 199.75]]}, {"timestamp": 1578660366961, "ltp": 1.6, "tv": 40.97, "trd": NaN, "batb": [[0, 1.6, 261.68]], "batl": [[2, 1000, 2.2]]}, {"timestamp": 1578660616733, "ltp": 1.6, "tv": 40.97, "trd": NaN, "batb": [[1, 1.59, 338.33], [2, 1.52, 103.68]], "batl": [[2, 1.66, 199.75]]}, {"timestamp": 1578661352024, "ltp": 1.6, "tv": 40.93, "trd": [[1.56, 6.55], [1.57, 3.83], [1.6, 30.56]], "batb": [[0, 1.6, 261.24]], "batl": [[0, 1.62, 24.12], [1, 1.63, 206.11]]}, {"timestamp": 1578661509014, "ltp": 1.6, "tv": 40.93, "trd": NaN, "batb": [[1, 1.52, 103.68], [2, 1.01, 2]], "batl": [[2, 1000, 2.2]]}, {"timestamp": 1578661511010, "ltp": 1.6, "tv": 40.93, "trd": NaN, "batb": [[1, 1.59, 290.92], [2, 1.52, 103.68]], "batl": [[0, 1.62, 196.3]]}, {"timestamp": 1578661511922, "ltp": 1.6, "tv": 40.93, "trd": NaN, "batb": [[2, 1.58, 344.68]], "batl": [[2, 1.65, 199.9]]}, {"timestamp": 1578661513016, "ltp": 1.6, "tv": 40.93, "trd": NaN, "batb": [[0, 1.58, 344.68], [1, 1.52, 103.68], [2, 1.01, 2]], "batl": [[0, 1.62, 24.12], [1, 1.65, 199.9], [2, 1000, 2.2]]}, {"timestamp": 1578661535962, "ltp": 1.6, "tv": 40.93, "trd": NaN, "batb": [[1, 1.51, 105.72]], "batl": NaN}, {"timestamp": 1578661592032, "ltp": 1.6, "tv": 40.93, "trd": NaN, "batb": [[0, 1.6, 169.64], [1, 1.58, 344.68], [2, 1.51, 105.72]], "batl": [[1, 1.63, 250.21], [2, 1.65, 199.9]]}, {"timestamp": 1578661622765, "ltp": 1.6, "tv": 40.93, "trd": NaN, "batb": NaN, "batl": [[1, 1.63, 297.71]]}, {"timestamp": 1578661697976, "ltp": 1.6, "tv": 40.93, "trd": NaN, "batb": [[1, 1.57, 350.64]], "batl": [[2, 1.64, 199.93]]}, {"timestamp": 1578661698142, "ltp": 1.6, "tv": 40.93, "trd": NaN, "batb": [[1, 1.51, 105.72], [2, 1.01, 2]], "batl": NaN}, {"timestamp": 1578661699778, "ltp": 1.6, "tv": 40.93, "trd": NaN, "batb": [[0, 1.58, 288.38]], "batl": [[0, 1.61, 166.24], [1, 1.62, 24.12]]}, {"timestamp": 1578661733624, "ltp": 1.61, "tv": 207.17, "trd": [[1.61, 166.24]], "batb": NaN, "batl": [[0, 1.62, 24.12], [1, 1.64, 199.93], [2, 1000, 2.2]]}, {"timestamp": 1578661735900, "ltp": 1.61, "tv": 207.17, "trd": NaN, "batb": [[1, 1.55, 363.39], [2, 1.51, 105.72]], "batl": [[0, 1.62, 223.87], [1, 1000, 2.2], [2, 1000, 0]]}, {"timestamp": 1578661737025, "ltp": 1.61, "tv": 207.17, "trd": NaN, "batb": [[0, 1.57, 264.63]], "batl": [[0, 1.6, 206.96], [1, 1.62, 223.87], [2, 1000, 2.2]]}, {"timestamp": 1578661737644, "ltp": 1.61, "tv": 207.17, "trd": NaN, "batb": [[1, 1.51, 105.72], [2, 1.01, 2]], "batl": [[1, 1.62, 24.12]]}, {"timestamp": 1578661739025, "ltp": 1.61, "tv": 207.17, "trd": NaN, "batb": NaN, "batl": [[0, 1.6, 247.67]]}, {"timestamp": 1578661783975, "ltp": 1.61, "tv": 207.17, "trd": NaN, "batb": [[1, 1.56, 357.08], [2, 1.51, 105.72]], "batl": [[2, 1.64, 199.93]]}, {"timestamp": 1578661791704, "ltp": 1.61, "tv": 207.17, "trd": NaN, "batb": NaN, "batl": [[0, 1.59, 1.89], [1, 1.6, 247.67], [2, 1.62, 24.12]]}, {"timestamp": 1578661950022, "ltp": 1.61, "tv": 207.17, "trd": NaN, "batb": [[0, 1.57, 299.41]], "batl": NaN}, {"timestamp": 1578661980995, "ltp": 1.61, "tv": 207.17, "trd": NaN, "batb": NaN, "batl": [[1, 1.6, 209.5]]}, {"timestamp": 1578661981972, "ltp": 1.61, "tv": 207.17, "trd": NaN, "batb": [[0, 1.56, 357.08], [1, 1.51, 105.72], [2, 1.01, 2]], "batl": [[1, 1.62, 24.12], [2, 1.64, 199.93]]}, {"timestamp": 1578662039892, "ltp": 1.61, "tv": 207.17, "trd": NaN, "batb": NaN, "batl": [[0, 1.62, 24.12], [1, 1.64, 199.93], [2, 1000, 2.2]]}, {"timestamp": 1578662040112, "ltp": 1.61, "tv": 207.17, "trd": NaN, "batb": NaN, "batl": [[0, 1.61, 1.87], [1, 1.62, 24.12], [2, 1.64, 199.93]]}, {"timestamp": 1578662169048, "ltp": 1.61, "tv": 207.17, "trd": NaN, "batb": [[0, 1.57, 294.32], [1, 1.56, 357.08], [2, 1.51, 105.72]], "batl": [[0, 1.61, 375.91]]}, {"timestamp": 1578662195592, "ltp": 1.61, "tv": 207.17, "trd": NaN, "batb": [[0, 1.57, 644.96], [1, 1.51, 105.72], [2, 1.01, 2]], "batl": NaN}, {"timestamp": 1578662287052, "ltp": 1.61, "tv": 207.17, "trd": NaN, "batb": NaN, "batl": [[0, 1.61, 374.05]]}, {"timestamp": 1578663575044, "ltp": 1.61, "tv": 207.17, "trd": NaN, "batb": NaN, "batl": [[0, 1.61, 421.91]]}, {"timestamp": 1578663909243, "ltp": 1.61, "tv": 207.17, "trd": NaN, "batb": NaN, "batl": [[0, 1.61, 374.05]]}, {"timestamp": 1578663932553, "ltp": 1.61, "tv": 207.17, "trd": NaN, "batb": NaN, "batl": [[0, 1.61, 421.91]]}, {"timestamp": 1578668515605, "ltp": 1.61, "tv": 207.53, "trd": [[1.56, 6.55], [1.57, 3.84], [1.6, 30.59], [1.61, 166.55]], "batb": [[0, 1.57, 645.51]], "batl": [[0, 1.6, 24.15], [1, 1.61, 422.61]]}, {"timestamp": 1578668567036, "ltp": 1.61, "tv": 207.53, "trd": NaN, "batb": NaN, "batl": [[0, 1.59, 1.89], [1, 1.6, 280.53], [2, 1.61, 374.75]]}, {"timestamp": 1578668677184, "ltp": 1.61, "tv": 207.53, "trd": NaN, "batb": NaN, "batl": [[2, 1.64, 199.93]]}, {"timestamp": 1578668695195, "ltp": 1.57, "tv": 255.83, "trd": [[1.57, 52.14]], "batb": [[0, 1.57, 621.36]], "batl": [[1, 1.6, 256.38]]}, {"timestamp": 1578668821289, "ltp": 1.57, "tv": 255.83, "trd": NaN, "batb": [[0, 1.57, 650.25]], "batl": NaN}, {"timestamp": 1578669553775, "ltp": 1.57, "tv": 255.83, "trd": NaN, "batb": NaN, "batl": [[1, 1.6, 208.19], [2, 1.61, 47.89]]}, {"timestamp": 1578669560874, "ltp": 1.57, "tv": 255.83, "trd": NaN, "batb": [[0, 1.57, 731.83]], "batl": [[2, 1.61, 313.02]]}, {"timestamp": 1578669563601, "ltp": 1.57, "tv": 255.83, "trd": NaN, "batb": [[0, 1.57, 906.88]], "batl": [[2, 1.61, 519.51]]}, {"timestamp": 1578669573948, "ltp": 1.57, "tv": 255.83, "trd": NaN, "batb": NaN, "batl": [[1, 1.6, 256.37], [2, 1.61, 471.62]]}, {"timestamp": 1578669585678, "ltp": 1.57, "tv": 255.83, "trd": NaN, "batb": NaN, "batl": [[1, 1.6, 208.19], [2, 1.61, 519.63]]}, {"timestamp": 1578669618039, "ltp": 1.59, "tv": 259.62, "trd": [[1.59, 3.79]], "batb": [[0, 1.59, 168.06], [1, 1.57, 906.88], [2, 1.51, 105.72]], "batl": [[0, 1.6, 208.19], [1, 1.61, 519.63], [2, 1.62, 304.21]]}, {"timestamp": 1578669623010, "ltp": 1.59, "tv": 259.62, "trd": NaN, "batb": [[0, 1.59, 25.3], [1, 1.57, 350.64], [2, 1.01, 2]], "batl": [[0, 1.62, 49.29], [1, 1.63, 46.09], [2, 1000, 2.2]]}, {"timestamp": 1578669627716, "ltp": 1.59, "tv": 259.62, "trd": NaN, "batb": [[2, 1.51, 105.72]], "batl": NaN}, {"timestamp": 1578669634837, "ltp": 1.59, "tv": 259.62, "trd": NaN, "batb": [[1, 1.51, 105.72], [2, 1.01, 2]], "batl": [[2, 1.67, 199.77]]}, {"timestamp": 1578669636040, "ltp": 1.59, "tv": 259.62, "trd": NaN, "batb": [[1, 1.58, 85.83], [2, 1.51, 105.72]], "batl": [[1, 1.63, 89.43]]}, {"timestamp": 1578669643614, "ltp": 1.59, "tv": 259.62, "trd": NaN, "batb": NaN, "batl": [[1, 1.63, 43.34], [2, 1.64, 46.27]]}, {"timestamp": 1578669645042, "ltp": 1.59, "tv": 259.62, "trd": NaN, "batb": [[0, 1.6, 333.09], [1, 1.59, 25.3], [2, 1.58, 85.83]], "batl": NaN}, {"timestamp": 1578669656965, "ltp": 1.59, "tv": 259.62, "trd": NaN, "batb": NaN, "batl": [[1, 1.63, 89.5]]}, {"timestamp": 1578669657272, "ltp": 1.59, "tv": 259.62, "trd": NaN, "batb": NaN, "batl": [[2, 1.67, 199.77]]}, {"timestamp": 1578669683919, "ltp": 1.59, "tv": 259.62, "trd": NaN, "batb": [[0, 1.59, 25.3], [1, 1.58, 85.83], [2, 1.01, 2]], "batl": [[2, 1000, 2.2]]}, {"timestamp": 1578669688188, "ltp": 1.59, "tv": 259.62, "trd": NaN, "batb": [[2, 1.51, 105.72]], "batl": NaN}, {"timestamp": 1578669697960, "ltp": 1.59, "tv": 259.62, "trd": NaN, "batb": [[2, 1.57, 723.15]], "batl": [[1, 1.63, 304.49]]}, {"timestamp": 1578669728887, "ltp": 1.59, "tv": 259.62, "trd": NaN, "batb": [[0, 1.59, 364.24]], "batl": [[2, 1.67, 199.77]]}, {"timestamp": 1578669770038, "ltp": 1.59, "tv": 259.62, "trd": NaN, "batb": [[0, 1.59, 717.74]], "batl": NaN}, {"timestamp": 1578669850865, "ltp": 1.59, "tv": 259.62, "trd": NaN, "batb": [[1, 1.51, 105.72], [2, 1.01, 2]], "batl": [[0, 1.63, 304.49], [1, 1.67, 199.77], [2, 1000, 2.2]]}, {"timestamp": 1578672212994, "ltp": 1.59, "tv": 259.62, "trd": NaN, "batb": [[1, 1.53, 101.73]], "batl": NaN}, {"timestamp": 1578672484991, "ltp": 1.59, "tv": 259.62, "trd": NaN, "batb": [[1, 1.54, 99.84]], "batl": NaN}, {"timestamp": 1578672532949, "ltp": 1.59, "tv": 259.62, "trd": NaN, "batb": NaN, "batl": [[1, 1.66, 199.75]]}, {"timestamp": 1578674543029, "ltp": 1.59, "tv": 259.62, "trd": NaN, "batb": NaN, "batl": [[1, 1.65, 199.9]]}, {"timestamp": 1578674551053, "ltp": 1.59, "tv": 259.62, "trd": NaN, "batb": [[0, 1.59, 399.08]], "batl": [[0, 1.63, 89.5]]}, {"timestamp": 1578674661936, "ltp": 1.59, "tv": 259.62, "trd": NaN, "batb": [[0, 1.59, 671]], "batl": [[0, 1.63, 335.93]]}, {"timestamp": 1578674680971, "ltp": 1.59, "tv": 259.62, "trd": NaN, "batb": [[1, 1.58, 292.32], [2, 1.54, 99.84]], "batl": [[0, 1.63, 555.17]]}, {"timestamp": 1578674681871, "ltp": 1.59, "tv": 259.62, "trd": NaN, "batb": NaN, "batl": [[0, 1.62, 47.86], [1, 1.63, 509.01], [2, 1.65, 199.9]]}, {"timestamp": 1578674792841, "ltp": 1.59, "tv": 259.62, "trd": NaN, "batb": [[0, 1.59, 338.94]], "batl": [[1, 1.65, 199.9], [2, 1000, 2.2]]}, {"timestamp": 1578674793891, "ltp": 1.59, "tv": 259.62, "trd": NaN, "batb": NaN, "batl": [[0, 1.64, 47.28]]}, {"timestamp": 1578674794267, "ltp": 1.59, "tv": 259.62, "trd": NaN, "batb": NaN, "batl": [[0, 1.61, 209.04], [1, 1.64, 47.28], [2, 1.65, 199.9]]}, {"timestamp": 1578674802761, "ltp": 1.59, "tv": 259.62, "trd": NaN, "batb": NaN, "batl": [[1, 1.62, 47.86], [2, 1.64, 47.28]]}, {"timestamp": 1578674807898, "ltp": 1.59, "tv": 259.62, "trd": NaN, "batb": NaN, "batl": [[2, 1.65, 199.9]]}, {"timestamp": 1578675100853, "ltp": 1.59, "tv": 259.62, "trd": NaN, "batb": [[1, 1.58, 310.04]], "batl": NaN}, {"timestamp": 1578675101164, "ltp": 1.59, "tv": 259.62, "trd": NaN, "batb": NaN, "batl": [[2, 1.63, 17.18]]}, {"timestamp": 1578675751995, "ltp": 1.59, "tv": 260.03, "trd": [[1.56, 6.55], [1.57, 52.21], [1.59, 3.8], [1.6, 30.61], [1.61, 166.87]], "batb": [[1, 1.58, 310.59]], "batl": [[0, 1.61, 209.43]]}, {"timestamp": 1578680317995, "ltp": 1.59, "tv": 260.03, "trd": NaN, "batb": [[1, 1.58, 67.1]], "batl": [[0, 1.61, 33.2]]}, {"timestamp": 1578680428997, "ltp": 1.59, "tv": 260.03, "trd": NaN, "batb": [[1, 1.58, 323.36]], "batl": [[0, 1.61, 217.1]]}, {"timestamp": 1578682952056, "ltp": 1.59, "tv": 260.09, "trd": [[1.56, 6.55], [1.57, 52.23], [1.6, 30.62], [1.61, 166.89]], "batb": [[1, 1.58, 323.41]], "batl": [[0, 1.61, 217.13]]}, {"timestamp": 1578685534983, "ltp": 1.59, "tv": 260.09, "trd": NaN, "batb": [[1, 1.58, 438.36]], "batl": [[0, 1.61, 258]]}, {"timestamp": 1578685540844, "ltp": 1.59, "tv": 260.09, "trd": NaN, "batb": [[2, 1.55, 98.03]], "batl": NaN}, {"timestamp": 1578685651720, "ltp": 1.59, "tv": 260.09, "trd": NaN, "batb": [[0, 1.59, 586.73]], "batl": [[1, 1.62, 482.12]]}, {"timestamp": 1578685657546, "ltp": 1.59, "tv": 260.09, "trd": NaN, "batb": [[1, 1.58, 17.72]], "batl": [[0, 1.62, 482.12], [1, 1.63, 17.18], [2, 1.65, 199.9]]}, {"timestamp": 1578685940408, "ltp": 1.59, "tv": 260.09, "trd": NaN, "batb": [[0, 1.59, 594.77]], "batl": NaN}, {"timestamp": 1578685985032, "ltp": 1.59, "tv": 260.09, "trd": NaN, "batb": [[0, 1.59, 594.32]], "batl": NaN}, {"timestamp": 1578685985970, "ltp": 1.59, "tv": 260.09, "trd": NaN, "batb": [[0, 1.59, 592.7]], "batl": NaN}, {"timestamp": 1578685987858, "ltp": 1.59, "tv": 260.09, "trd": NaN, "batb": [[0, 1.59, 592.11]], "batl": NaN}, {"timestamp": 1578686116041, "ltp": 1.59, "tv": 260.09, "trd": NaN, "batb": NaN, "batl": [[2, 1.68, 16.67]]}, {"timestamp": 1578686117674, "ltp": 1.59, "tv": 260.09, "trd": NaN, "batb": [[0, 1.59, 591.44], [1, 1.58, 444.32]], "batl": [[0, 1.62, 519.59]]}, {"timestamp": 1578686134051, "ltp": 1.59, "tv": 260.09, "trd": NaN, "batb": [[0, 1.59, 590.8]], "batl": [[2, 1.65, 199.9]]}, {"timestamp": 1578686328808, "ltp": 1.59, "tv": 260.09, "trd": NaN, "batb": [[0, 1.59, 343.01]], "batl": NaN}, {"timestamp": 1578687298962, "ltp": 1.59, "tv": 260.09, "trd": NaN, "batb": [[0, 1.59, 338.94]], "batl": NaN}, {"timestamp": 1578687402885, "ltp": 1.59, "tv": 260.09, "trd": NaN, "batb": NaN, "batl": [[2, 1.64, 199.93]]}, {"timestamp": 1578688096999, "ltp": 1.59, "tv": 260.09, "trd": NaN, "batb": [[2, 1.54, 99.84]], "batl": NaN}, {"timestamp": 1578688121839, "ltp": 1.59, "tv": 260.09, "trd": NaN, "batb": [[2, 1.55, 98.03]], "batl": NaN}, {"timestamp": 1578689229008, "ltp": 1.59, "tv": 260.09, "trd": NaN, "batb": NaN, "batl": [[0, 1.62, 534.15]]}, {"timestamp": 1578689230890, "ltp": 1.59, "tv": 260.09, "trd": NaN, "batb": NaN, "batl": [[0, 1.62, 663.58]]}, {"timestamp": 1578689242023, "ltp": 1.59, "tv": 260.09, "trd": NaN, "batb": NaN, "batl": [[0, 1.62, 711.44]]}, {"timestamp": 1578689311963, "ltp": 1.59, "tv": 260.09, "trd": NaN, "batb": [[1, 1.58, 274.02]], "batl": NaN}, {"timestamp": 1578689558050, "ltp": 1.59, "tv": 260.09, "trd": NaN, "batb": [[0, 1.58, 274.02], [1, 1.55, 98.03], [2, 1.52, 18.42]], "batl": [[0, 1.61, 110.93], [1, 1.62, 711.44], [2, 1.63, 17.18]]}, {"timestamp": 1578689558981, "ltp": 1.59, "tv": 260.09, "trd": NaN, "batb": [[1, 1.57, 350.64], [2, 1.55, 98.03]], "batl": [[1, 1.62, 601.16]]}, {"timestamp": 1578689615928, "ltp": 1.59, "tv": 260.09, "trd": NaN, "batb": NaN, "batl": [[0, 1.61, 497.51]]}, {"timestamp": 1578689838028, "ltp": 1.59, "tv": 260.09, "trd": NaN, "batb": NaN, "batl": [[1, 1.63, 17.18], [2, 1.64, 199.93]]}, {"timestamp": 1578690135046, "ltp": 1.59, "tv": 260.18, "trd": [[1.57, 52.24], [1.59, 3.8], [1.6, 30.62], [1.61, 166.96]], "batb": [[0, 1.58, 321.83]], "batl": [[0, 1.61, 497.68]]}, {"timestamp": 1578694412560, "ltp": 1.59, "tv": 260.18, "trd": NaN, "batb": NaN, "batl": [[1, 1.62, 17.29]]}, {"timestamp": 1578694447705, "ltp": 1.59, "tv": 260.18, "trd": NaN, "batb": NaN, "batl": [[0, 1.61, 386.75]]}, {"timestamp": 1578694448315, "ltp": 1.59, "tv": 260.18, "trd": NaN, "batb": NaN, "batl": [[1, 1.62, 123.64]]}, {"timestamp": 1578696416433, "ltp": 1.59, "tv": 260.18, "trd": NaN, "batb": NaN, "batl": [[0, 1.61, 497.84], [1, 1.62, 17.29]]}, {"timestamp": 1578696659761, "ltp": 1.59, "tv": 260.18, "trd": NaN, "batb": NaN, "batl": [[1, 1.64, 199.93], [2, 1.68, 16.67]]}, {"timestamp": 1578696660132, "ltp": 1.59, "tv": 260.18, "trd": NaN, "batb": NaN, "batl": [[0, 1.61, 515.24]]}, {"timestamp": 1578696690788, "ltp": 1.59, "tv": 260.18, "trd": NaN, "batb": [[1, 1.56, 357.08]], "batl": NaN}, {"timestamp": 1578697352006, "ltp": 1.59, "tv": 260.0, "trd": [[1.56, 6.55], [1.57, 52.21], [1.59, 3.8], [1.6, 30.61], [1.61, 166.84]], "batb": [[0, 1.58, 321.6]], "batl": [[0, 1.61, 514.94]]}, {"timestamp": 1578698281927, "ltp": 1.59, "tv": 260.0, "trd": NaN, "batb": [[0, 1.58, 280.74]], "batl": NaN}, {"timestamp": 1578698282853, "ltp": 1.59, "tv": 260.0, "trd": NaN, "batb": NaN, "batl": [[0, 1.61, 548.14]]}, {"timestamp": 1578698692171, "ltp": 1.59, "tv": 260.0, "trd": NaN, "batb": [[2, 1.55, 95.74]], "batl": NaN}, {"timestamp": 1578698813027, "ltp": 1.59, "tv": 260.0, "trd": NaN, "batb": NaN, "batl": [[0, 1.61, 437.05]]}, {"timestamp": 1578698847855, "ltp": 1.59, "tv": 260.0, "trd": NaN, "batb": NaN, "batl": [[0, 1.61, 548.5]]}, {"timestamp": 1578699105879, "ltp": 1.59, "tv": 260.0, "trd": NaN, "batb": NaN, "batl": [[1, 1.63, 199.77]]}, {"timestamp": 1578706379134, "ltp": 1.58, "tv": 267.48, "trd": [[1.58, 7.48]], "batb": [[0, 1.58, 277]], "batl": NaN}, {"timestamp": 1578707101986, "ltp": 1.58, "tv": 267.48, "trd": NaN, "batb": [[2, 1.55, 106.68]], "batl": NaN}, {"timestamp": 1578708828194, "ltp": 1.58, "tv": 271.22, "trd": [[1.58, 11.22]], "batb": [[0, 1.58, 275.13]], "batl": NaN}, {"timestamp": 1578709858045, "ltp": 1.58, "tv": 271.22, "trd": NaN, "batb": [[1, 1.57, 102.93], [2, 1.56, 357.08]], "batl": NaN}, {"timestamp": 1578710316789, "ltp": 1.58, "tv": 271.22, "trd": NaN, "batb": [[1, 1.56, 357.08], [2, 1.54, 108.65]], "batl": NaN}, {"timestamp": 1578711732891, "ltp": 1.58, "tv": 271.22, "trd": NaN, "batb": [[0, 1.58, 310.03]], "batl": NaN}, {"timestamp": 1578711741030, "ltp": 1.58, "tv": 271.22, "trd": NaN, "batb": NaN, "batl": [[0, 1.61, 518.7]]}, {"timestamp": 1578712082242, "ltp": 1.58, "tv": 276.82, "trd": [[1.58, 16.82]], "batb": [[0, 1.58, 307.23]], "batl": NaN}, {"timestamp": 1578714394570, "ltp": 1.58, "tv": 288.04, "trd": [[1.58, 28.04]], "batb": [[0, 1.58, 301.62]], "batl": NaN}, {"timestamp": 1578715203516, "ltp": 1.58, "tv": 289.9, "trd": [[1.58, 29.9]], "batb": [[0, 1.58, 300.69]], "batl": NaN}, {"timestamp": 1578715232000, "ltp": 1.58, "tv": 289.9, "trd": NaN, "batb": [[0, 1.58, 448.4]], "batl": [[0, 1.61, 580.75]]}, {"timestamp": 1578715233945, "ltp": 1.58, "tv": 289.9, "trd": NaN, "batb": [[0, 1.58, 300.69]], "batl": [[0, 1.61, 407.25]]}, {"timestamp": 1578715350054, "ltp": 1.58, "tv": 289.9, "trd": NaN, "batb": [[0, 1.58, 447.69]], "batl": [[0, 1.61, 580.76]]}, {"timestamp": 1578715350905, "ltp": 1.58, "tv": 289.9, "trd": NaN, "batb": [[0, 1.58, 300.69]], "batl": [[0, 1.61, 524.94]]}, {"timestamp": 1578715367041, "ltp": 1.58, "tv": 289.9, "trd": NaN, "batb": [[2, 1.52, 18.42]], "batl": NaN}, {"timestamp": 1578715845878, "ltp": 1.58, "tv": 289.9, "trd": NaN, "batb": [[2, 1.54, 108.65]], "batl": NaN}, {"timestamp": 1578716351911, "ltp": 1.58, "tv": 289.9, "trd": NaN, "batb": [[0, 1.58, 370.05]], "batl": NaN}, {"timestamp": 1578716361004, "ltp": 1.58, "tv": 289.9, "trd": NaN, "batb": [[0, 1.58, 300.69]], "batl": [[0, 1.61, 510.63]]}, {"timestamp": 1578716361990, "ltp": 1.58, "tv": 289.9, "trd": NaN, "batb": NaN, "batl": [[0, 1.61, 501.17]]}, {"timestamp": 1578716371017, "ltp": 1.58, "tv": 289.9, "trd": NaN, "batb": NaN, "batl": [[0, 1.61, 515.49]]}, {"timestamp": 1578716383022, "ltp": 1.58, "tv": 289.9, "trd": NaN, "batb": NaN, "batl": [[0, 1.61, 487.39]]}, {"timestamp": 1578716384023, "ltp": 1.58, "tv": 289.9, "trd": NaN, "batb": NaN, "batl": [[0, 1.61, 467.37]]}, {"timestamp": 1578717158402, "ltp": 1.58, "tv": 289.9, "trd": NaN, "batb": [[2, 1.52, 18.42]], "batl": NaN}, {"timestamp": 1578717856577, "ltp": 1.58, "tv": 289.9, "trd": NaN, "batb": NaN, "batl": [[0, 1.61, 407.25]]}, {"timestamp": 1578717859939, "ltp": 1.58, "tv": 289.9, "trd": NaN, "batb": NaN, "batl": [[0, 1.61, 477.64]]}, {"timestamp": 1578719136876, "ltp": 1.58, "tv": 289.9, "trd": NaN, "batb": NaN, "batl": [[0, 1.61, 515.95]]}, {"timestamp": 1578719168023, "ltp": 1.58, "tv": 289.9, "trd": NaN, "batb": [[0, 1.58, 262.39]], "batl": NaN}, {"timestamp": 1578719846805, "ltp": 1.58, "tv": 289.9, "trd": NaN, "batb": NaN, "batl": [[0, 1.61, 514.74]]}, {"timestamp": 1578719858706, "ltp": 1.58, "tv": 289.9, "trd": NaN, "batb": NaN, "batl": [[0, 1.61, 445.56]]}, {"timestamp": 1578719862040, "ltp": 1.58, "tv": 289.9, "trd": NaN, "batb": NaN, "batl": [[0, 1.61, 514.56]]}, {"timestamp": 1578719862552, "ltp": 1.58, "tv": 289.9, "trd": NaN, "batb": NaN, "batl": [[0, 1.61, 445.56]]}, {"timestamp": 1578719871453, "ltp": 1.58, "tv": 289.9, "trd": NaN, "batb": NaN, "batl": [[0, 1.61, 514.53]]}, {"timestamp": 1578719893702, "ltp": 1.58, "tv": 289.9, "trd": NaN, "batb": NaN, "batl": [[0, 1.61, 445.56]]}, {"timestamp": 1578719898796, "ltp": 1.58, "tv": 289.9, "trd": NaN, "batb": NaN, "batl": [[0, 1.61, 514.52]]}, {"timestamp": 1578719910812, "ltp": 1.58, "tv": 289.9, "trd": NaN, "batb": [[0, 1.58, 85.34]], "batl": [[0, 1.61, 157.86]]}, {"timestamp": 1578720022944, "ltp": 1.58, "tv": 289.9, "trd": NaN, "batb": [[0, 1.58, 253.03]], "batl": [[0, 1.61, 501.75]]}, {"timestamp": 1578720314942, "ltp": 1.58, "tv": 289.9, "trd": NaN, "batb": NaN, "batl": [[0, 1.6, 70.59], [1, 1.61, 432.79], [2, 1.63, 199.77]]}, {"timestamp": 1578720322741, "ltp": 1.58, "tv": 289.9, "trd": NaN, "batb": NaN, "batl": [[0, 1.6, 88.1], [1, 1.61, 415.39]]}, {"timestamp": 1578720554818, "ltp": 1.58, "tv": 289.9, "trd": NaN, "batb": [[1, 1.55, 363.39]], "batl": [[2, 1.62, 199.75]]}, {"timestamp": 1578721828984, "ltp": 1.58, "tv": 289.9, "trd": NaN, "batb": [[1, 1.56, 357.08]], "batl": [[2, 1.63, 199.77]]}, {"timestamp": 1578722648930, "ltp": 1.58, "tv": 289.9, "trd": NaN, "batb": [[1, 1.55, 363.39]], "batl": [[2, 1.62, 199.75]]}, {"timestamp": 1578722659962, "ltp": 1.58, "tv": 289.9, "trd": NaN, "batb": [[1, 1.56, 357.08]], "batl": [[2, 1.63, 199.77]]}, {"timestamp": 1578722662801, "ltp": 1.58, "tv": 289.9, "trd": NaN, "batb": [[1, 1.55, 363.39]], "batl": [[2, 1.62, 199.75]]}, {"timestamp": 1578722664462, "ltp": 1.58, "tv": 289.9, "trd": NaN, "batb": [[1, 1.56, 357.08]], "batl": [[2, 1.63, 199.77]]}, {"timestamp": 1578722665960, "ltp": 1.58, "tv": 289.9, "trd": NaN, "batb": [[1, 1.55, 363.39]], "batl": [[2, 1.62, 199.75]]}, {"timestamp": 1578722666683, "ltp": 1.58, "tv": 289.9, "trd": NaN, "batb": [[1, 1.56, 357.08]], "batl": [[2, 1.63, 199.77]]}, {"timestamp": 1578723086042, "ltp": 1.58, "tv": 289.9, "trd": NaN, "batb": [[1, 1.55, 363.39]], "batl": [[2, 1.62, 199.75]]}, {"timestamp": 1578723934036, "ltp": 1.58, "tv": 289.9, "trd": NaN, "batb": [[1, 1.56, 357.08]], "batl": [[2, 1.68, 16.67]]}, {"timestamp": 1578723936053, "ltp": 1.58, "tv": 289.9, "trd": NaN, "batb": [[1, 1.57, 467.31], [2, 1.56, 357.08]], "batl": [[0, 1.6, 301.75]]}, {"timestamp": 1578724000919, "ltp": 1.58, "tv": 289.9, "trd": NaN, "batb": NaN, "batl": [[2, 1.63, 199.77]]}, {"timestamp": 1578724047014, "ltp": 1.58, "tv": 289.9, "trd": NaN, "batb": [[0, 1.58, 2.77]], "batl": [[1, 1.63, 199.77], [2, 1.68, 16.67]]}, {"timestamp": 1578724882981, "ltp": 1.58, "tv": 323.4, "trd": [[1.58, 63.4]], "batb": [[0, 1.57, 467.31], [1, 1.56, 357.08], [2, 1.54, 108.65]], "batl": [[0, 1.6, 302.31]]}, {"timestamp": 1578724887597, "ltp": 1.58, "tv": 323.4, "trd": NaN, "batb": [[0, 1.57, 485.14]], "batl": NaN}, {"timestamp": 1578725755013, "ltp": 1.58, "tv": 323.4, "trd": NaN, "batb": NaN, "batl": [[0, 1.6, 231.72], [1, 1.61, 84.68], [2, 1.63, 199.77]]}, {"timestamp": 1578726826390, "ltp": 1.57, "tv": 331.06, "trd": [[1.57, 59.87]], "batb": [[0, 1.57, 481.31]], "batl": NaN}, {"timestamp": 1578726884878, "ltp": 1.57, "tv": 331.06, "trd": NaN, "batb": [[0, 1.57, 433.65]], "batl": NaN}, {"timestamp": 1578726885761, "ltp": 1.57, "tv": 331.06, "trd": NaN, "batb": NaN, "batl": [[0, 1.6, 269.17]]}, {"timestamp": 1578727109771, "ltp": 1.57, "tv": 331.06, "trd": NaN, "batb": [[0, 1.57, 69.33]], "batl": [[0, 1.6, 55.52]]}, {"timestamp": 1578727180956, "ltp": 1.57, "tv": 331.06, "trd": NaN, "batb": NaN, "batl": [[0, 1.6, 43.6]]}, {"timestamp": 1578727262780, "ltp": 1.57, "tv": 331.06, "trd": NaN, "batb": [[0, 1.57, 454.07]], "batl": [[0, 1.6, 265.77]]}, {"timestamp": 1578728677966, "ltp": 1.57, "tv": 331.06, "trd": NaN, "batb": [[0, 1.57, 481.31]], "batl": NaN}, {"timestamp": 1578729376020, "ltp": 1.57, "tv": 331.06, "trd": NaN, "batb": NaN, "batl": [[0, 1.6, 358.51], [1, 1.63, 199.77], [2, 1.68, 16.67]]}, {"timestamp": 1578729533305, "ltp": 1.57, "tv": 331.06, "trd": NaN, "batb": NaN, "batl": [[1, 1.61, 427.31], [2, 1.63, 199.77]]}, {"timestamp": 1578729537901, "ltp": 1.57, "tv": 331.06, "trd": NaN, "batb": NaN, "batl": [[0, 1.6, 110.81]]}, {"timestamp": 1578729553625, "ltp": 1.57, "tv": 331.06, "trd": NaN, "batb": [[0, 1.57, 534.09]], "batl": NaN}, {"timestamp": 1578729591888, "ltp": 1.57, "tv": 331.06, "trd": NaN, "batb": [[1, 1.55, 363.39]], "batl": [[2, 1.62, 199.75]]}, {"timestamp": 1578729689003, "ltp": 1.58, "tv": 331.61, "trd": [[1.58, 63.95]], "batb": [[0, 1.57, 678.53]], "batl": [[0, 1.6, 17.51], [1, 1.61, 534.1]]}, {"timestamp": 1578729691018, "ltp": 1.58, "tv": 331.61, "trd": NaN, "batb": [[1, 1.56, 357.08], [2, 1.55, 363.39]], "batl": NaN}, {"timestamp": 1578729691120, "ltp": 1.58, "tv": 331.61, "trd": NaN, "batb": [[2, 1.54, 108.65]], "batl": [[2, 1.63, 199.77]]}, {"timestamp": 1578729698001, "ltp": 1.58, "tv": 331.61, "trd": NaN, "batb": [[0, 1.58, 140.4], [1, 1.57, 678.53], [2, 1.56, 357.08]], "batl": NaN}, {"timestamp": 1578729698414, "ltp": 1.58, "tv": 331.61, "trd": NaN, "batb": [[1, 1.57, 534.09]], "batl": NaN}, {"timestamp": 1578729700701, "ltp": 1.58, "tv": 331.61, "trd": NaN, "batb": [[0, 1.58, 399.17]], "batl": NaN}, {"timestamp": 1578729703037, "ltp": 1.58, "tv": 331.61, "trd": NaN, "batb": [[1, 1.57, 516.26]], "batl": NaN}, {"timestamp": 1578729703297, "ltp": 1.58, "tv": 331.61, "trd": NaN, "batb": [[0, 1.58, 416.89]], "batl": NaN}, {"timestamp": 1578729735885, "ltp": 1.58, "tv": 331.61, "trd": NaN, "batb": NaN, "batl": [[1, 1.61, 634.89]]}, {"timestamp": 1578729737914, "ltp": 1.58, "tv": 331.61, "trd": NaN, "batb": NaN, "batl": [[1, 1.61, 543.27]]}, {"timestamp": 1578729745995, "ltp": 1.58, "tv": 331.61, "trd": NaN, "batb": NaN, "batl": [[1, 1.61, 596.08]]}, {"timestamp": 1578729750611, "ltp": 1.58, "tv": 331.61, "trd": NaN, "batb": [[1, 1.56, 357.08], [2, 1.54, 108.65]], "batl": NaN}, {"timestamp": 1578729923966, "ltp": 1.58, "tv": 348.64, "trd": [[1.58, 80.98]], "batb": [[0, 1.58, 408.38]], "batl": NaN}, {"timestamp": 1578730103970, "ltp": 1.58, "tv": 348.64, "trd": NaN, "batb": [[0, 1.58, 276.49], [1, 1.54, 108.65], [2, 1.51, 18.54]], "batl": [[0, 1.6, 187.35], [2, 1.68, 16.67]]}, {"timestamp": 1578730105055, "ltp": 1.58, "tv": 348.64, "trd": NaN, "batb": [[1, 1.57, 173.08]], "batl": [[1, 1.61, 427.31]]}, {"timestamp": 1578731024947, "ltp": 1.58, "tv": 491.15, "trd": [[1.58, 223.49]], "batb": [[0, 1.58, 205.23]], "batl": NaN}, {"timestamp": 1578731028907, "ltp": 1.58, "tv": 491.15, "trd": NaN, "batb": [[1, 1.57, 642.1]], "batl": [[0, 1.6, 434.2]]}, {"timestamp": 1578731033852, "ltp": 1.58, "tv": 491.15, "trd": NaN, "batb": [[0, 1.58, 17.72]], "batl": [[1, 1.68, 16.67], [2, 1.69, 16.57]]}, {"timestamp": 1578731400027, "ltp": 1.58, "tv": 491.15, "trd": NaN, "batb": [[1, 1.57, 469.02]], "batl": NaN}, {"timestamp": 1578731400338, "ltp": 1.58, "tv": 491.15, "trd": NaN, "batb": [[1, 1.57, 641.91]], "batl": NaN}, {"timestamp": 1578731434139, "ltp": 1.58, "tv": 491.15, "trd": NaN, "batb": [[1, 1.57, 469.02]], "batl": NaN}, {"timestamp": 1578731436969, "ltp": 1.58, "tv": 491.15, "trd": NaN, "batb": [[1, 1.57, 641.91]], "batl": NaN}, {"timestamp": 1578731481799, "ltp": 1.58, "tv": 491.15, "trd": NaN, "batb": [[2, 1.56, 357.08]], "batl": [[1, 1.63, 199.77], [2, 1.68, 16.67]]}, {"timestamp": 1578731536864, "ltp": 1.58, "tv": 495.75, "trd": [[1.58, 228.09]], "batb": [[0, 1.58, 15.42]], "batl": NaN}, {"timestamp": 1578731801028, "ltp": 1.58, "tv": 495.75, "trd": NaN, "batb": [[0, 1.58, 187.43]], "batl": NaN}, {"timestamp": 1578731801602, "ltp": 1.58, "tv": 495.75, "trd": NaN, "batb": [[1, 1.57, 469.02]], "batl": NaN}, {"timestamp": 1578732734960, "ltp": 1.58, "tv": 495.75, "trd": NaN, "batb": NaN, "batl": [[0, 1.6, 399.3]]}, {"timestamp": 1578732776511, "ltp": 1.58, "tv": 495.75, "trd": NaN, "batb": [[0, 1.58, 409.6]], "batl": [[1, 1.61, 423.05], [2, 1.63, 199.77]]}, {"timestamp": 1578732808342, "ltp": 1.58, "tv": 495.75, "trd": NaN, "batb": [[0, 1.58, 445.35]], "batl": NaN}, {"timestamp": 1578732813860, "ltp": 1.58, "tv": 495.75, "trd": NaN, "batb": [[1, 1.56, 357.08], [2, 1.51, 18.54]], "batl": [[0, 1.6, 187.35]]}, {"timestamp": 1578733622892, "ltp": 1.58, "tv": 524.25, "trd": [[1.58, 256.59]], "batb": [[0, 1.58, 431.1]], "batl": NaN}, {"timestamp": 1578733627859, "ltp": 1.58, "tv": 524.25, "trd": NaN, "batb": NaN, "batl": [[0, 1.6, 17.51], [1, 1.61, 592.19]]}, {"timestamp": 1578733971934, "ltp": 1.58, "tv": 524.25, "trd": NaN, "batb": NaN, "batl": [[0, 1.6, 187.69], [1, 1.61, 423.05]]}, {"timestamp": 1578734549757, "ltp": 1.58, "tv": 558.86, "trd": [[1.58, 291.2]], "batb": [[0, 1.58, 413.79]], "batl": NaN}, {"timestamp": 1578734599984, "ltp": 1.58, "tv": 558.86, "trd": NaN, "batb": [[0, 1.58, 431.51], [2, 1.5, 18.67]], "batl": NaN}, {"timestamp": 1578734754733, "ltp": 1.58, "tv": 558.86, "trd": NaN, "batb": [[0, 1.58, 413.79], [2, 1.01, 2]], "batl": [[0, 1.6, 170.18]]}, {"timestamp": 1578734786263, "ltp": 1.58, "tv": 558.86, "trd": NaN, "batb": NaN, "batl": [[0, 1.59, 35.22], [1, 1.6, 170.18], [2, 1.61, 423.05]]}, {"timestamp": 1578734945995, "ltp": 1.58, "tv": 558.86, "trd": NaN, "batb": [[2, 1.55, 363.39]], "batl": NaN}, {"timestamp": 1578734946989, "ltp": 1.58, "tv": 558.86, "trd": NaN, "batb": [[0, 1.58, 257.92], [1, 1.01, 2], [2, 1.55, 0]], "batl": NaN}, {"timestamp": 1578734947978, "ltp": 1.58, "tv": 558.86, "trd": NaN, "batb": [[1, 1.57, 135.06], [2, 1.01, 2]], "batl": NaN}, {"timestamp": 1578734948970, "ltp": 1.58, "tv": 558.86, "trd": NaN, "batb": [[1, 1.01, 2], [2, 1.01, 0]], "batl": NaN}, {"timestamp": 1578734951868, "ltp": 1.58, "tv": 558.86, "trd": NaN, "batb": [[1, 1.56, 357.08], [2, 1.01, 2]], "batl": NaN}, {"timestamp": 1578734955929, "ltp": 1.58, "tv": 558.86, "trd": NaN, "batb": [[1, 1.57, 166.34], [2, 1.56, 357.08]], "batl": NaN}, {"timestamp": 1578734963991, "ltp": 1.58, "tv": 558.86, "trd": NaN, "batb": [[2, 1.55, 363.39]], "batl": NaN}, {"timestamp": 1578735058051, "ltp": 1.58, "tv": 558.86, "trd": NaN, "batb": [[1, 1.57, 172.99]], "batl": NaN}, {"timestamp": 1578735060975, "ltp": 1.58, "tv": 558.86, "trd": NaN, "batb": [[1, 1.57, 647.11], [2, 1.56, 357.08]], "batl": [[1, 1.6, 431.5]]}, {"timestamp": 1578735061979, "ltp": 1.58, "tv": 558.86, "trd": NaN, "batb": [[2, 1.01, 2]], "batl": NaN}, {"timestamp": 1578735130183, "ltp": 1.58, "tv": 558.86, "trd": NaN, "batb": NaN, "batl": [[1, 1.6, 435.24]]}, {"timestamp": 1578735166042, "ltp": 1.58, "tv": 558.86, "trd": NaN, "batb": [[2, 1.55, 363.39]], "batl": NaN}, {"timestamp": 1578735208221, "ltp": 1.58, "tv": 558.86, "trd": NaN, "batb": NaN, "batl": [[1, 1.6, 475.25]]}, {"timestamp": 1578735213933, "ltp": 1.58, "tv": 558.86, "trd": NaN, "batb": [[0, 1.57, 547.52], [1, 1.55, 363.39], [2, 1.01, 2]], "batl": [[2, 1.62, 199.75]]}, {"timestamp": 1578735215668, "ltp": 1.58, "tv": 558.86, "trd": NaN, "batb": [[2, 1.52, 112.83]], "batl": NaN}, {"timestamp": 1578735457017, "ltp": 1.58, "tv": 558.86, "trd": NaN, "batb": [[2, 1.51, 115.04]], "batl": NaN}, {"timestamp": 1578735923768, "ltp": 1.57, "tv": 576.17, "trd": [[1.57, 77.17]], "batb": [[0, 1.57, 538.87]], "batl": NaN}, {"timestamp": 1578736233397, "ltp": 1.59, "tv": 592.81, "trd": [[1.59, 20.44]], "batb": NaN, "batl": [[0, 1.59, 26.9]]}, {"timestamp": 1578736646025, "ltp": 1.59, "tv": 592.81, "trd": NaN, "batb": [[1, 1.56, 357.08]], "batl": [[2, 1.63, 199.77]]}, {"timestamp": 1578736830970, "ltp": 1.59, "tv": 592.81, "trd": NaN, "batb": [[2, 1.52, 112.83]], "batl": NaN}, {"timestamp": 1578736901885, "ltp": 1.57, "tv": 615.77, "trd": [[1.57, 100.14]], "batb": [[0, 1.57, 527.39]], "batl": NaN}, {"timestamp": 1578737294008, "ltp": 1.57, "tv": 615.77, "trd": NaN, "batb": [[2, 1.51, 115.04]], "batl": NaN}, {"timestamp": 1578737492668, "ltp": 1.57, "tv": 650.38, "trd": [[1.57, 134.75]], "batb": [[0, 1.57, 510.08]], "batl": NaN}, {"timestamp": 1578737906014, "ltp": 1.57, "tv": 650.38, "trd": NaN, "batb": [[0, 1.57, 554.93]], "batl": NaN}, {"timestamp": 1578737909038, "ltp": 1.57, "tv": 650.38, "trd": NaN, "batb": [[1, 1.55, 363.39]], "batl": NaN}, {"timestamp": 1578737924334, "ltp": 1.57, "tv": 650.38, "trd": NaN, "batb": [[1, 1.56, 357.08]], "batl": NaN}, {"timestamp": 1578737942040, "ltp": 1.57, "tv": 650.38, "trd": NaN, "batb": [[1, 1.55, 363.39]], "batl": [[2, 1.62, 199.75]]}, {"timestamp": 1578737949970, "ltp": 1.57, "tv": 650.38, "trd": NaN, "batb": [[0, 1.58, 187.05], [1, 1.57, 605.15], [2, 1.55, 363.39]], "batl": NaN}, {"timestamp": 1578737950257, "ltp": 1.57, "tv": 650.38, "trd": NaN, "batb": [[1, 1.57, 424.75]], "batl": NaN}, {"timestamp": 1578738030852, "ltp": 1.57, "tv": 650.38, "trd": NaN, "batb": NaN, "batl": [[1, 1.6, 305.07], [2, 1.61, 188.48]]}, {"timestamp": 1578738031760, "ltp": 1.57, "tv": 650.38, "trd": NaN, "batb": NaN, "batl": [[2, 1.62, 199.75]]}, {"timestamp": 1578738037899, "ltp": 1.59, "tv": 669.82, "trd": [[1.59, 39.88]], "batb": NaN, "batl": [[0, 1.59, 17.18]]}, {"timestamp": 1578738039968, "ltp": 1.59, "tv": 669.82, "trd": NaN, "batb": NaN, "batl": [[2, 1.61, 198.47]]}, {"timestamp": 1578738045964, "ltp": 1.59, "tv": 669.82, "trd": NaN, "batb": [[2, 1.56, 357.08]], "batl": NaN}, {"timestamp": 1578738179961, "ltp": 1.59, "tv": 669.82, "trd": NaN, "batb": [[2, 1.55, 363.39]], "batl": NaN}, {"timestamp": 1578738480000, "ltp": 1.58, "tv": 739.05, "trd": [[1.58, 360.42]], "batb": [[0, 1.58, 227.32]], "batl": NaN}, {"timestamp": 1578738485693, "ltp": 1.59, "tv": 744.93, "trd": [[1.59, 45.76]], "batb": NaN, "batl": [[0, 1.59, 14.24]]}, {"timestamp": 1578738493914, "ltp": 1.59, "tv": 744.93, "trd": NaN, "batb": [[2, 1.56, 357.08]], "batl": NaN}, {"timestamp": 1578738497005, "ltp": 1.59, "tv": 744.93, "trd": NaN, "batb": [[2, 1.55, 363.39]], "batl": NaN}, {"timestamp": 1578738505046, "ltp": 1.59, "tv": 744.93, "trd": NaN, "batb": [[2, 1.56, 357.08]], "batl": NaN}, {"timestamp": 1578739024995, "ltp": 1.59, "tv": 744.93, "trd": NaN, "batb": [[2, 1.55, 363.39]], "batl": NaN}, {"timestamp": 1578739269939, "ltp": 1.59, "tv": 744.93, "trd": NaN, "batb": [[2, 1.56, 357.08]], "batl": NaN}, {"timestamp": 1578739365188, "ltp": 1.58, "tv": 754.93, "trd": [[1.58, 370.42]], "batb": [[0, 1.58, 222.32]], "batl": NaN}, {"timestamp": 1578739406956, "ltp": 1.58, "tv": 754.93, "trd": NaN, "batb": NaN, "batl": [[1, 1.6, 249.74]]}, {"timestamp": 1578739461754, "ltp": 1.58, "tv": 754.93, "trd": NaN, "batb": [[0, 1.58, 244.68], [1, 1.57, 447.25]], "batl": [[1, 1.6, 271.82], [2, 1.61, 220.41]]}, {"timestamp": 1578740148998, "ltp": 1.58, "tv": 754.93, "trd": NaN, "batb": [[2, 1.01, 2]], "batl": NaN}, {"timestamp": 1578740150856, "ltp": 1.58, "tv": 754.93, "trd": NaN, "batb": NaN, "batl": [[1, 1.6, 502.92], [2, 1.61, 21.94]]}, {"timestamp": 1578740154980, "ltp": 1.58, "tv": 754.93, "trd": NaN, "batb": [[0, 1.58, 22.36]], "batl": NaN}, {"timestamp": 1578740161964, "ltp": 1.58, "tv": 754.93, "trd": NaN, "batb": [[1, 1.57, 398.73]], "batl": [[1, 1.6, 560.8]]}, {"timestamp": 1578740162967, "ltp": 1.58, "tv": 754.93, "trd": NaN, "batb": [[1, 1.57, 634.21]], "batl": [[0, 1.59, 18.31]]}, {"timestamp": 1578740163938, "ltp": 1.58, "tv": 754.93, "trd": NaN, "batb": [[1, 1.57, 560.16]], "batl": NaN}, {"timestamp": 1578740164781, "ltp": 1.58, "tv": 754.93, "trd": NaN, "batb": NaN, "batl": [[0, 1.59, 14.24], [1, 1.6, 602.51]]}, {"timestamp": 1578740166988, "ltp": 1.58, "tv": 754.93, "trd": NaN, "batb": NaN, "batl": [[0, 1.59, 18.31]]}, {"timestamp": 1578740169973, "ltp": 1.58, "tv": 754.93, "trd": NaN, "batb": [[1, 1.57, 606.97]], "batl": NaN}, {"timestamp": 1578740218029, "ltp": 1.58, "tv": 754.93, "trd": NaN, "batb": [[1, 1.57, 371.49]], "batl": [[0, 1.59, 14.24]]}, {"timestamp": 1578740218931, "ltp": 1.58, "tv": 754.93, "trd": NaN, "batb": NaN, "batl": [[0, 1.59, 18.31]]}, {"timestamp": 1578740220020, "ltp": 1.58, "tv": 754.93, "trd": NaN, "batb": NaN, "batl": [[0, 1.59, 14.24]]}, {"timestamp": 1578740223240, "ltp": 1.58, "tv": 754.93, "trd": NaN, "batb": NaN, "batl": [[0, 1.59, 18.31]]}, {"timestamp": 1578740224350, "ltp": 1.58, "tv": 754.93, "trd": NaN, "batb": NaN, "batl": [[0, 1.59, 14.24]]}, {"timestamp": 1578740226621, "ltp": 1.58, "tv": 754.93, "trd": NaN, "batb": [[1, 1.57, 606.97]], "batl": NaN}, {"timestamp": 1578740227835, "ltp": 1.58, "tv": 754.93, "trd": NaN, "batb": NaN, "batl": [[0, 1.59, 18.31]]}, {"timestamp": 1578740229039, "ltp": 1.58, "tv": 754.93, "trd": NaN, "batb": NaN, "batl": [[0, 1.59, 14.24]]}, {"timestamp": 1578740230448, "ltp": 1.58, "tv": 754.93, "trd": NaN, "batb": NaN, "batl": [[0, 1.59, 18.31]]}, {"timestamp": 1578740231229, "ltp": 1.58, "tv": 754.93, "trd": NaN, "batb": NaN, "batl": [[0, 1.59, 14.24]]}, {"timestamp": 1578740232760, "ltp": 1.58, "tv": 754.93, "trd": NaN, "batb": NaN, "batl": [[0, 1.59, 18.31]]}, {"timestamp": 1578740233543, "ltp": 1.58, "tv": 754.93, "trd": NaN, "batb": NaN, "batl": [[0, 1.59, 14.24]]}, {"timestamp": 1578740234642, "ltp": 1.58, "tv": 754.93, "trd": NaN, "batb": NaN, "batl": [[0, 1.59, 18.31]]}, {"timestamp": 1578740235581, "ltp": 1.58, "tv": 754.93, "trd": NaN, "batb": NaN, "batl": [[0, 1.59, 14.24]]}, {"timestamp": 1578740236876, "ltp": 1.58, "tv": 754.93, "trd": NaN, "batb": NaN, "batl": [[0, 1.59, 18.31]]}, {"timestamp": 1578740237879, "ltp": 1.58, "tv": 754.93, "trd": NaN, "batb": NaN, "batl": [[0, 1.59, 14.24]]}, {"timestamp": 1578740239354, "ltp": 1.58, "tv": 754.93, "trd": NaN, "batb": NaN, "batl": [[0, 1.59, 18.31]]}, {"timestamp": 1578740240237, "ltp": 1.58, "tv": 754.93, "trd": NaN, "batb": NaN, "batl": [[0, 1.59, 14.24]]}, {"timestamp": 1578740241851, "ltp": 1.58, "tv": 754.93, "trd": NaN, "batb": NaN, "batl": [[0, 1.59, 18.31]]}, {"timestamp": 1578740242672, "ltp": 1.58, "tv": 754.93, "trd": NaN, "batb": NaN, "batl": [[0, 1.59, 14.24]]}, {"timestamp": 1578740246739, "ltp": 1.58, "tv": 754.93, "trd": NaN, "batb": NaN, "batl": [[0, 1.59, 18.31]]}, {"timestamp": 1578740248151, "ltp": 1.58, "tv": 754.93, "trd": NaN, "batb": NaN, "batl": [[0, 1.59, 14.24]]}, {"timestamp": 1578740249958, "ltp": 1.58, "tv": 754.93, "trd": NaN, "batb": NaN, "batl": [[0, 1.59, 18.31]]}, {"timestamp": 1578740288616, "ltp": 1.58, "tv": 754.93, "trd": NaN, "batb": NaN, "batl": [[0, 1.59, 14.24]]}, {"timestamp": 1578740289448, "ltp": 1.58, "tv": 754.93, "trd": NaN, "batb": NaN, "batl": [[0, 1.59, 18.31]]}, {"timestamp": 1578740290850, "ltp": 1.58, "tv": 754.93, "trd": NaN, "batb": NaN, "batl": [[0, 1.59, 14.24]]}, {"timestamp": 1578740291530, "ltp": 1.58, "tv": 754.93, "trd": NaN, "batb": NaN, "batl": [[0, 1.59, 18.31]]}, {"timestamp": 1578740293143, "ltp": 1.58, "tv": 754.93, "trd": NaN, "batb": NaN, "batl": [[0, 1.59, 14.24]]}, {"timestamp": 1578740295838, "ltp": 1.58, "tv": 754.93, "trd": NaN, "batb": NaN, "batl": [[0, 1.59, 18.31]]}, {"timestamp": 1578740296615, "ltp": 1.58, "tv": 754.93, "trd": NaN, "batb": NaN, "batl": [[0, 1.59, 14.24]]}, {"timestamp": 1578740297675, "ltp": 1.58, "tv": 754.93, "trd": NaN, "batb": NaN, "batl": [[0, 1.59, 18.31]]}, {"timestamp": 1578740298860, "ltp": 1.58, "tv": 754.93, "trd": NaN, "batb": NaN, "batl": [[0, 1.59, 14.24]]}, {"timestamp": 1578740301048, "ltp": 1.58, "tv": 754.93, "trd": NaN, "batb": NaN, "batl": [[0, 1.59, 18.31]]}, {"timestamp": 1578740301308, "ltp": 1.58, "tv": 754.93, "trd": NaN, "batb": NaN, "batl": [[0, 1.59, 14.24]]}, {"timestamp": 1578740302927, "ltp": 1.58, "tv": 754.93, "trd": NaN, "batb": NaN, "batl": [[0, 1.59, 18.31]]}, {"timestamp": 1578740304853, "ltp": 1.58, "tv": 754.93, "trd": NaN, "batb": NaN, "batl": [[0, 1.59, 14.24]]}, {"timestamp": 1578740305532, "ltp": 1.58, "tv": 754.93, "trd": NaN, "batb": NaN, "batl": [[0, 1.59, 18.31]]}, {"timestamp": 1578740307041, "ltp": 1.58, "tv": 754.93, "trd": NaN, "batb": NaN, "batl": [[0, 1.59, 14.24]]}, {"timestamp": 1578740307929, "ltp": 1.58, "tv": 754.93, "trd": NaN, "batb": NaN, "batl": [[0, 1.59, 18.31]]}, {"timestamp": 1578740309741, "ltp": 1.58, "tv": 754.93, "trd": NaN, "batb": NaN, "batl": [[0, 1.59, 14.24]]}, {"timestamp": 1578740311924, "ltp": 1.58, "tv": 754.93, "trd": NaN, "batb": NaN, "batl": [[0, 1.59, 18.31]]}, {"timestamp": 1578740312762, "ltp": 1.58, "tv": 754.93, "trd": NaN, "batb": NaN, "batl": [[0, 1.59, 14.24]]}, {"timestamp": 1578740313645, "ltp": 1.58, "tv": 754.93, "trd": NaN, "batb": NaN, "batl": [[0, 1.59, 18.31]]}, {"timestamp": 1578740315569, "ltp": 1.58, "tv": 754.93, "trd": NaN, "batb": NaN, "batl": [[0, 1.59, 14.24]]}, {"timestamp": 1578740317029, "ltp": 1.58, "tv": 754.93, "trd": NaN, "batb": [[0, 1.58, 256.21]], "batl": [[0, 1.59, 18.31]]}, {"timestamp": 1578740317656, "ltp": 1.58, "tv": 754.93, "trd": NaN, "batb": [[1, 1.57, 371.49]], "batl": [[0, 1.59, 14.24]]}, {"timestamp": 1578740320679, "ltp": 1.58, "tv": 754.93, "trd": NaN, "batb": NaN, "batl": [[1, 1.6, 371.41], [2, 1.61, 251.43]]}, {"timestamp": 1578740357000, "ltp": 1.58, "tv": 754.93, "trd": NaN, "batb": [[1, 1.57, 310.21]], "batl": [[1, 1.6, 406.31]]}, {"timestamp": 1578740359019, "ltp": 1.58, "tv": 754.93, "trd": NaN, "batb": NaN, "batl": [[1, 1.6, 637.23]]}, {"timestamp": 1578740359905, "ltp": 1.58, "tv": 754.93, "trd": NaN, "batb": NaN, "batl": [[2, 1.61, 21.94]]}, {"timestamp": 1578740362043, "ltp": 1.58, "tv": 754.93, "trd": NaN, "batb": NaN, "batl": [[1, 1.6, 677.24]]}, {"timestamp": 1578740366930, "ltp": 1.58, "tv": 754.93, "trd": NaN, "batb": NaN, "batl": [[1, 1.6, 724.9]]}, {"timestamp": 1578740368024, "ltp": 1.58, "tv": 754.93, "trd": NaN, "batb": [[1, 1.57, 226.79]], "batl": NaN}, {"timestamp": 1578740372842, "ltp": 1.58, "tv": 754.93, "trd": NaN, "batb": [[2, 1.56, 477.53]], "batl": NaN}, {"timestamp": 1578740381025, "ltp": 1.58, "tv": 754.93, "trd": NaN, "batb": [[0, 1.58, 22.36], [1, 1.57, 257.84], [2, 1.01, 2]], "batl": [[1, 1.6, 25.82]]}, {"timestamp": 1578740381955, "ltp": 1.58, "tv": 754.93, "trd": NaN, "batb": NaN, "batl": [[0, 1.59, 18.31]]}, {"timestamp": 1578740383761, "ltp": 1.58, "tv": 754.93, "trd": NaN, "batb": [[0, 1.57, 257.84], [1, 1.56, 4.15]], "batl": NaN}, {"timestamp": 1578740388862, "ltp": 1.58, "tv": 754.93, "trd": NaN, "batb": [[0, 1.57, 22.5], [2, 1.53, 241.49]], "batl": NaN}, {"timestamp": 1578740390959, "ltp": 1.58, "tv": 754.93, "trd": NaN, "batb": [[1, 1.56, 469.76]], "batl": [[0, 1.59, 265.16], [1, 1.6, 256.74]]}, {"timestamp": 1578740397056, "ltp": 1.58, "tv": 754.93, "trd": NaN, "batb": [[0, 1.57, 257.84], [2, 1.51, 115.04]], "batl": NaN}, {"timestamp": 1578740425930, "ltp": 1.58, "tv": 754.93, "trd": NaN, "batb": [[1, 1.56, 826.84]], "batl": NaN}, {"timestamp": 1578741068056, "ltp": 1.58, "tv": 754.93, "trd": NaN, "batb": [[1, 1.56, 361.23]], "batl": [[0, 1.59, 18.31], [1, 1.6, 25.82], [2, 1.61, 250.99]]}, {"timestamp": 1578741068808, "ltp": 1.58, "tv": 754.93, "trd": NaN, "batb": [[0, 1.57, 651.1]], "batl": [[1, 1.6, 322.04]]}, {"timestamp": 1578741069948, "ltp": 1.58, "tv": 754.93, "trd": NaN, "batb": [[0, 1.58, 24.58], [1, 1.57, 651.1], [2, 1.56, 361.23]], "batl": NaN}, {"timestamp": 1578741070954, "ltp": 1.58, "tv": 754.93, "trd": NaN, "batb": [[0, 1.58, 255.84], [2, 1.56, 657.45]], "batl": [[0, 1.59, 14.24], [2, 1.61, 628.93]]}, {"timestamp": 1578741071918, "ltp": 1.58, "tv": 754.93, "trd": NaN, "batb": [[1, 1.57, 415.76]], "batl": NaN}, {"timestamp": 1578741072935, "ltp": 1.59, "tv": 758.93, "trd": [[1.59, 49.76]], "batb": NaN, "batl": [[0, 1.59, 12.24]]}, {"timestamp": 1578741074985, "ltp": 1.59, "tv": 758.93, "trd": NaN, "batb": [[1, 1.57, 22.5], [2, 1.56, 497.42]], "batl": [[1, 1.6, 25.82], [2, 1.61, 45.78]]}, {"timestamp": 1578741075749, "ltp": 1.59, "tv": 782.47, "trd": [[1.59, 73.3]], "batb": NaN, "batl": [[0, 1.6, 26.29], [1, 1.61, 45.78], [2, 1.62, 244.25]]}, {"timestamp": 1578741079975, "ltp": 1.59, "tv": 782.47, "trd": NaN, "batb": [[1, 1.57, 255.25]], "batl": NaN}, {"timestamp": 1578741080953, "ltp": 1.59, "tv": 782.47, "trd": NaN, "batb": [[0, 1.58, 24.58], [2, 1.56, 361.23]], "batl": [[1, 1.61, 21.94]]}, {"timestamp": 1578741083882, "ltp": 1.59, "tv": 782.47, "trd": NaN, "batb": NaN, "batl": [[2, 1.62, 18.69]]}, {"timestamp": 1578741096006, "ltp": 1.59, "tv": 782.47, "trd": NaN, "batb": [[1, 1.57, 605.89], [2, 1.56, 4.15]], "batl": NaN}, {"timestamp": 1578741097009, "ltp": 1.59, "tv": 782.47, "trd": NaN, "batb": [[0, 1.58, 255.95], [1, 1.57, 373.14]], "batl": NaN}, {"timestamp": 1578741100018, "ltp": 1.59, "tv": 783.41, "trd": [[1.59, 74.24]], "batb": [[0, 1.59, 10.67], [1, 1.58, 255.95], [2, 1.57, 373.14]], "batl": [[0, 1.6, 25.82]]}, {"timestamp": 1578741138964, "ltp": 1.59, "tv": 783.41, "trd": NaN, "batb": [[0, 1.59, 60.04]], "batl": NaN}, {"timestamp": 1578741139869, "ltp": 1.59, "tv": 783.41, "trd": NaN, "batb": [[0, 1.59, 289.94], [1, 1.58, 24.58]], "batl": [[0, 1.6, 3.74], [2, 1.62, 31]]}, {"timestamp": 1578741141765, "ltp": 1.59, "tv": 783.41, "trd": NaN, "batb": [[0, 1.59, 279.27]], "batl": NaN}, {"timestamp": 1578741143676, "ltp": 1.59, "tv": 783.41, "trd": NaN, "batb": [[0, 1.59, 291.4]], "batl": NaN}, {"timestamp": 1578741163919, "ltp": 1.6, "tv": 790.88, "trd": [[1.6, 38.09]], "batb": [[0, 1.6, 32.01], [1, 1.59, 291.4], [2, 1.58, 24.58]], "batl": [[0, 1.61, 21.94], [1, 1.62, 31], [2, 1.63, 51.07]]}, {"timestamp": 1578741165027, "ltp": 1.6, "tv": 790.88, "trd": NaN, "batb": NaN, "batl": [[2, 1.63, 275.33]]}, {"timestamp": 1578741165920, "ltp": 1.6, "tv": 790.88, "trd": NaN, "batb": [[1, 1.59, 61.5]], "batl": NaN}, {"timestamp": 1578741167990, "ltp": 1.6, "tv": 790.88, "trd": NaN, "batb": [[0, 1.59, 12.13], [1, 1.58, 24.58], [2, 1.57, 373.14]], "batl": [[2, 1.63, 224.26]]}, {"timestamp": 1578741168913, "ltp": 1.6, "tv": 790.88, "trd": NaN, "batb": [[0, 1.6, 33.2], [1, 1.59, 12.13], [2, 1.58, 24.58]], "batl": NaN}, {"timestamp": 1578741172802, "ltp": 1.6, "tv": 790.88, "trd": NaN, "batb": [[0, 1.59, 12.13], [1, 1.58, 24.58], [2, 1.57, 373.14]], "batl": NaN}, {"timestamp": 1578741173801, "ltp": 1.6, "tv": 790.88, "trd": NaN, "batb": [[1, 1.58, 255.94]], "batl": [[2, 1.65, 199.9]]}, {"timestamp": 1578741174334, "ltp": 1.6, "tv": 790.88, "trd": NaN, "batb": [[0, 1.6, 34.9], [1, 1.59, 12.13], [2, 1.58, 255.94]], "batl": NaN}, {"timestamp": 1578741180822, "ltp": 1.6, "tv": 790.88, "trd": NaN, "batb": NaN, "batl": [[2, 1.64, 222.89]]}, {"timestamp": 1578741181844, "ltp": 1.6, "tv": 790.88, "trd": NaN, "batb": [[1, 1.59, 242.03], [2, 1.58, 24.58]], "batl": [[2, 1.65, 199.9]]}, {"timestamp": 1578741183113, "ltp": 1.6, "tv": 790.88, "trd": NaN, "batb": [[0, 1.6, 38.96]], "batl": NaN}, {"timestamp": 1578741185036, "ltp": 1.6, "tv": 790.88, "trd": NaN, "batb": [[1, 1.59, 300.76]], "batl": [[2, 1.63, 41.71]]}, {"timestamp": 1578741189043, "ltp": 1.6, "tv": 790.88, "trd": NaN, "batb": NaN, "batl": [[2, 1.63, 265.97]]}, {"timestamp": 1578741192822, "ltp": 1.6, "tv": 790.88, "trd": NaN, "batb": [[0, 1.6, 267.43], [1, 1.59, 70.86]], "batl": NaN}, {"timestamp": 1578741195360, "ltp": 1.6, "tv": 790.88, "trd": NaN, "batb": [[0, 1.6, 263.37]], "batl": [[0, 1.62, 31], [1, 1.63, 269.99], [2, 1.65, 199.9]]}, {"timestamp": 1578741199865, "ltp": 1.6, "tv": 790.88, "trd": NaN, "batb": [[1, 1.59, 12.13]], "batl": NaN}, {"timestamp": 1578741200654, "ltp": 1.6, "tv": 790.88, "trd": NaN, "batb": [[0, 1.6, 34.9], [1, 1.59, 242.03]], "batl": NaN}, {"timestamp": 1578741202047, "ltp": 1.6, "tv": 790.88, "trd": NaN, "batb": [[0, 1.6, 52.7]], "batl": NaN}, {"timestamp": 1578741316041, "ltp": 1.6, "tv": 790.88, "trd": NaN, "batb": [[0, 1.6, 275.72]], "batl": [[1, 1.63, 601.96]]}, {"timestamp": 1578741316993, "ltp": 1.6, "tv": 790.88, "trd": NaN, "batb": [[0, 1.6, 504.19], [1, 1.59, 12.13]], "batl": NaN}, {"timestamp": 1578741419982, "ltp": 1.6, "tv": 790.88, "trd": NaN, "batb": [[2, 1.58, 369.26]], "batl": NaN}, {"timestamp": 1578741703583, "ltp": 1.6, "tv": 795.48, "trd": [[1.6, 42.68]], "batb": [[0, 1.6, 501.89]], "batl": NaN}, {"timestamp": 1578742268783, "ltp": 1.6, "tv": 795.48, "trd": NaN, "batb": [[2, 1.58, 24.58]], "batl": NaN}, {"timestamp": 1578742287954, "ltp": 1.6, "tv": 795.48, "trd": NaN, "batb": [[2, 1.58, 369.26]], "batl": NaN}, {"timestamp": 1578742297028, "ltp": 1.6, "tv": 795.48, "trd": NaN, "batb": NaN, "batl": [[0, 1.62, 18.69], [2, 1.64, 22.45]]}, {"timestamp": 1578742297761, "ltp": 1.6, "tv": 795.48, "trd": NaN, "batb": [[1, 1.59, 351.07], [2, 1.58, 24.58]], "batl": NaN}, {"timestamp": 1578742303040, "ltp": 1.6, "tv": 795.48, "trd": NaN, "batb": [[0, 1.61, 15.01], [1, 1.6, 501.89], [2, 1.59, 351.07]], "batl": NaN}, {"timestamp": 1578742307056, "ltp": 1.6, "tv": 795.48, "trd": NaN, "batb": NaN, "batl": [[0, 1.62, 33.59]]}, {"timestamp": 1578742374931, "ltp": 1.6, "tv": 795.48, "trd": NaN, "batb": [[2, 1.59, 12.13]], "batl": NaN}, {"timestamp": 1578742652938, "ltp": 1.6, "tv": 795.48, "trd": NaN, "batb": [[2, 1.59, 351.07]], "batl": NaN}, {"timestamp": 1578742655003, "ltp": 1.6, "tv": 795.48, "trd": NaN, "batb": [[0, 1.61, 242.87], [1, 1.6, 273.42]], "batl": [[0, 1.62, 18.69]]}, {"timestamp": 1578743451991, "ltp": 1.62, "tv": 820.14, "trd": [[1.62, 24.66]], "batb": NaN, "batl": [[0, 1.62, 6.36]]}, {"timestamp": 1578743630917, "ltp": 1.62, "tv": 820.14, "trd": NaN, "batb": [[2, 1.59, 12.13]], "batl": NaN}, {"timestamp": 1578743648042, "ltp": 1.62, "tv": 820.14, "trd": NaN, "batb": [[2, 1.59, 441.99]], "batl": [[1, 1.63, 653.88]]}, {"timestamp": 1578743681965, "ltp": 1.62, "tv": 820.14, "trd": NaN, "batb": NaN, "batl": [[0, 1.62, 14.36]]}, {"timestamp": 1578743759973, "ltp": 1.62, "tv": 820.14, "trd": NaN, "batb": [[1, 1.6, 17.8]], "batl": [[1, 1.63, 691.34]]}, {"timestamp": 1578743864016, "ltp": 1.62, "tv": 820.14, "trd": NaN, "batb": [[0, 1.61, 206.73], [2, 1.59, 12.13]], "batl": [[1, 1.63, 193.39]]}, {"timestamp": 1578743865014, "ltp": 1.62, "tv": 820.14, "trd": NaN, "batb": [[0, 1.61, 15.01]], "batl": [[1, 1.63, 4.02]]}, {"timestamp": 1578743882954, "ltp": 1.62, "tv": 820.14, "trd": NaN, "batb": [[2, 1.59, 63.2]], "batl": [[0, 1.62, 46.71]]}, {"timestamp": 1578743924486, "ltp": 1.61, "tv": 830.13, "trd": [[1.61, 176.83]], "batb": [[0, 1.61, 10.01]], "batl": NaN}, {"timestamp": 1578743926363, "ltp": 1.61, "tv": 830.13, "trd": NaN, "batb": NaN, "batl": [[0, 1.62, 50.75]]}, {"timestamp": 1578743948933, "ltp": 1.61, "tv": 830.13, "trd": NaN, "batb": [[1, 1.6, 307.48]], "batl": NaN}, {"timestamp": 1578743974019, "ltp": 1.61, "tv": 830.13, "trd": NaN, "batb": [[2, 1.59, 445.39]], "batl": [[0, 1.62, 266.96], [1, 1.63, 288.37]]}, {"timestamp": 1578743974866, "ltp": 1.61, "tv": 830.13, "trd": NaN, "batb": [[0, 1.6, 307.48], [1, 1.59, 445.39], [2, 1.58, 369.26]], "batl": NaN}, {"timestamp": 1578744687683, "ltp": 1.61, "tv": 830.13, "trd": NaN, "batb": [[1, 1.59, 449.07]], "batl": NaN}, {"timestamp": 1578745622860, "ltp": 1.61, "tv": 830.13, "trd": NaN, "batb": [[0, 1.6, 556.88], [1, 1.59, 15.81]], "batl": [[0, 1.62, 18.4], [1, 1.63, 680.77]]}, {"timestamp": 1578745628952, "ltp": 1.61, "tv": 830.13, "trd": NaN, "batb": [[0, 1.6, 307.48]], "batl": [[1, 1.63, 288.37]]}, {"timestamp": 1578745631574, "ltp": 1.61, "tv": 830.13, "trd": NaN, "batb": NaN, "batl": [[1, 1.63, 4.02]]}, {"timestamp": 1578745707792, "ltp": 1.61, "tv": 830.13, "trd": NaN, "batb": [[0, 1.6, 570.5]], "batl": [[1, 1.63, 661.18]]}, {"timestamp": 1578745722160, "ltp": 1.6, "tv": 834.13, "trd": [[1.6, 46.68]], "batb": [[0, 1.6, 568.5]], "batl": NaN}, {"timestamp": 1578746122511, "ltp": 1.6, "tv": 848.64, "trd": [[1.6, 61.19]], "batb": [[0, 1.6, 561.25]], "batl": NaN}, {"timestamp": 1578746310777, "ltp": 1.6, "tv": 848.64, "trd": NaN, "batb": NaN, "batl": [[1, 1.63, 724.17]]}, {"timestamp": 1578746517027, "ltp": 1.6, "tv": 848.64, "trd": NaN, "batb": [[2, 1.58, 24.58]], "batl": NaN}, {"timestamp": 1578746517895, "ltp": 1.6, "tv": 848.64, "trd": NaN, "batb": NaN, "batl": [[1, 1.63, 439.84], [2, 1.64, 305.34]]}, {"timestamp": 1578746519839, "ltp": 1.6, "tv": 848.64, "trd": NaN, "batb": NaN, "batl": [[1, 1.63, 393.87]]}, {"timestamp": 1578746547041, "ltp": 1.6, "tv": 848.64, "trd": NaN, "batb": [[2, 1.58, 369.26]], "batl": NaN}, {"timestamp": 1578746893272, "ltp": 1.6, "tv": 848.94, "trd": [[1.6, 61.49]], "batb": [[0, 1.6, 561.1]], "batl": NaN}, {"timestamp": 1578747120989, "ltp": 1.6, "tv": 848.94, "trd": NaN, "batb": [[1, 1.59, 354.75], [2, 1.58, 24.58]], "batl": NaN}, {"timestamp": 1578747132902, "ltp": 1.6, "tv": 848.94, "trd": NaN, "batb": [[1, 1.59, 15.81], [2, 1.58, 369.26]], "batl": NaN}, {"timestamp": 1578747689044, "ltp": 1.6, "tv": 848.94, "trd": NaN, "batb": NaN, "batl": [[1, 1.63, 678.64]]}, {"timestamp": 1578747689454, "ltp": 1.6, "tv": 848.94, "trd": NaN, "batb": NaN, "batl": [[2, 1.64, 22.45]]}, {"timestamp": 1578747772877, "ltp": 1.6, "tv": 848.94, "trd": NaN, "batb": [[0, 1.6, 589.19]], "batl": NaN}, {"timestamp": 1578747790974, "ltp": 1.6, "tv": 867.63, "trd": [[1.6, 80.18]], "batb": [[0, 1.6, 579.84]], "batl": NaN}, {"timestamp": 1578747791900, "ltp": 1.6, "tv": 867.63, "trd": NaN, "batb": [[0, 1.6, 595.58]], "batl": NaN}, {"timestamp": 1578748077007, "ltp": 1.6, "tv": 867.63, "trd": NaN, "batb": NaN, "batl": [[2, 1.64, 222.38]]}, {"timestamp": 1578748077701, "ltp": 1.6, "tv": 867.63, "trd": NaN, "batb": [[2, 1.58, 24.58]], "batl": NaN}, {"timestamp": 1578748154610, "ltp": 1.6, "tv": 887.63, "trd": [[1.6, 100.18]], "batb": [[0, 1.6, 585.58]], "batl": NaN}, {"timestamp": 1578748446978, "ltp": 1.6, "tv": 887.63, "trd": NaN, "batb": [[0, 1.6, 554.94]], "batl": NaN}, {"timestamp": 1578748732865, "ltp": 1.6, "tv": 887.63, "trd": NaN, "batb": NaN, "batl": [[2, 1.64, 22.45]]}, {"timestamp": 1578748753993, "ltp": 1.6, "tv": 887.63, "trd": NaN, "batb": NaN, "batl": [[2, 1.64, 222.38]]}, {"timestamp": 1578748975829, "ltp": 1.6, "tv": 887.63, "trd": NaN, "batb": [[2, 1.58, 369.26]], "batl": [[2, 1.64, 22.45]]}, {"timestamp": 1578749290404, "ltp": 1.6, "tv": 892.83, "trd": [[1.6, 105.37]], "batb": [[0, 1.6, 552.34]], "batl": NaN}, {"timestamp": 1578749378848, "ltp": 1.6, "tv": 944.74, "trd": [[1.6, 157.29]], "batb": [[0, 1.6, 526.38]], "batl": NaN}, {"timestamp": 1578749409944, "ltp": 1.6, "tv": 944.74, "trd": NaN, "batb": [[2, 1.58, 24.58]], "batl": [[2, 1.64, 222.38]]}, {"timestamp": 1578749442768, "ltp": 1.6, "tv": 944.74, "trd": NaN, "batb": [[2, 1.58, 369.26]], "batl": [[2, 1.64, 22.45]]}, {"timestamp": 1578749845964, "ltp": 1.6, "tv": 944.74, "trd": NaN, "batb": [[2, 1.58, 24.58]], "batl": [[2, 1.64, 222.38]]}, {"timestamp": 1578749925833, "ltp": 1.6, "tv": 944.74, "trd": NaN, "batb": [[2, 1.58, 369.26]], "batl": [[2, 1.64, 22.45]]}, {"timestamp": 1578750076932, "ltp": 1.6, "tv": 944.74, "trd": NaN, "batb": NaN, "batl": [[1, 1.63, 393.87], [2, 1.64, 305.33]]}, {"timestamp": 1578750103898, "ltp": 1.6, "tv": 944.74, "trd": NaN, "batb": [[0, 1.6, 564.68]], "batl": [[1, 1.63, 353.86]]}, {"timestamp": 1578750146048, "ltp": 1.6, "tv": 944.74, "trd": NaN, "batb": [[0, 1.61, 27.07], [1, 1.6, 564.68], [2, 1.59, 15.81]], "batl": NaN}, {"timestamp": 1578750148031, "ltp": 1.6, "tv": 944.74, "trd": NaN, "batb": [[0, 1.61, 315.21], [1, 1.6, 314.51]], "batl": [[0, 1.62, 14.36]]}, {"timestamp": 1578750171023, "ltp": 1.62, "tv": 948.74, "trd": [[1.62, 28.66]], "batb": NaN, "batl": [[0, 1.62, 12.36]]}, {"timestamp": 1578750171548, "ltp": 1.61, "tv": 953.34, "trd": [[1.61, 181.43]], "batb": [[0, 1.61, 312.91]], "batl": NaN}, {"timestamp": 1578750174950, "ltp": 1.61, "tv": 953.34, "trd": NaN, "batb": [[1, 1.6, 357.92]], "batl": NaN}, {"timestamp": 1578750204035, "ltp": 1.61, "tv": 953.34, "trd": NaN, "batb": NaN, "batl": [[2, 1.64, 261.48]]}, {"timestamp": 1578750302172, "ltp": 1.61, "tv": 954.66, "trd": [[1.61, 182.75]], "batb": [[0, 1.61, 312.25]], "batl": NaN}, {"timestamp": 1578750322568, "ltp": 1.61, "tv": 954.66, "trd": NaN, "batb": [[1, 1.6, 491.56]], "batl": [[1, 1.63, 467.93]]}, {"timestamp": 1578750351946, "ltp": 1.61, "tv": 962.14, "trd": [[1.61, 190.23]], "batb": [[0, 1.61, 308.51]], "batl": NaN}, {"timestamp": 1578750637814, "ltp": 1.61, "tv": 962.14, "trd": NaN, "batb": NaN, "batl": [[0, 1.62, 35.1]]}, {"timestamp": 1578750654161, "ltp": 1.61, "tv": 962.14, "trd": NaN, "batb": NaN, "batl": [[0, 1.62, 12.36]]}, {"timestamp": 1578751297028, "ltp": 1.61, "tv": 965.88, "trd": [[1.61, 193.97]], "batb": [[0, 1.61, 306.64]], "batl": NaN}, {"timestamp": 1578751603582, "ltp": 1.61, "tv": 965.88, "trd": NaN, "batb": [[1, 1.6, 522.21]], "batl": [[1, 1.63, 381.1]]}, {"timestamp": 1578751608346, "ltp": 1.61, "tv": 965.88, "trd": NaN, "batb": NaN, "batl": [[1, 1.63, 307.05]]}, {"timestamp": 1578751618127, "ltp": 1.61, "tv": 965.88, "trd": NaN, "batb": NaN, "batl": [[1, 1.63, 388.76]]}, {"timestamp": 1578751991027, "ltp": 1.62, "tv": 990.6, "trd": [[1.62, 53.38]], "batb": [[0, 1.62, 19.89], [1, 1.61, 306.64], [2, 1.6, 522.21]], "batl": [[0, 1.63, 388.76], [1, 1.64, 261.48], [2, 1.65, 199.9]]}, {"timestamp": 1578751991902, "ltp": 1.63, "tv": 1029.14, "trd": [[1.63, 38.54]], "batb": [[0, 1.61, 306.64], [1, 1.6, 522.21], [2, 1.59, 15.81]], "batl": [[0, 1.63, 369.49]]}, {"timestamp": 1578751994206, "ltp": 1.63, "tv": 1029.14, "trd": NaN, "batb": NaN, "batl": [[0, 1.63, 392.13]]}, {"timestamp": 1578752010043, "ltp": 1.63, "tv": 1029.14, "trd": NaN, "batb": NaN, "batl": [[0, 1.63, 414.26]]}, {"timestamp": 1578752040771, "ltp": 1.63, "tv": 1029.14, "trd": NaN, "batb": [[1, 1.6, 15.74]], "batl": [[0, 1.63, 22.63]]}, {"timestamp": 1578752042852, "ltp": 1.63, "tv": 1029.14, "trd": NaN, "batb": [[0, 1.61, 18.5]], "batl": NaN}, {"timestamp": 1578752082826, "ltp": 1.63, "tv": 1029.14, "trd": NaN, "batb": [[0, 1.61, 307.08], [1, 1.6, 517.1]], "batl": [[0, 1.63, 414.19]]}, {"timestamp": 1578752097167, "ltp": 1.61, "tv": 1049.14, "trd": [[1.61, 213.97]], "batb": [[0, 1.61, 297.08]], "batl": NaN}, {"timestamp": 1578752100466, "ltp": 1.61, "tv": 1049.14, "trd": NaN, "batb": NaN, "batl": [[0, 1.62, 22.28], [1, 1.63, 414.19], [2, 1.64, 261.48]]}, {"timestamp": 1578752438967, "ltp": 1.61, "tv": 1049.14, "trd": NaN, "batb": NaN, "batl": [[2, 1.64, 239.57]]}, {"timestamp": 1578752875007, "ltp": 1.61, "tv": 1145.14, "trd": [[1.61, 309.97]], "batb": [[0, 1.61, 249.08]], "batl": NaN}, {"timestamp": 1578752877022, "ltp": 1.61, "tv": 1145.14, "trd": NaN, "batb": [[0, 1.61, 268.69]], "batl": NaN}, {"timestamp": 1578752918863, "ltp": 1.61, "tv": 1145.14, "trd": NaN, "batb": NaN, "batl": [[1, 1.63, 443.98]]}, {"timestamp": 1578753243974, "ltp": 1.61, "tv": 1145.14, "trd": NaN, "batb": NaN, "batl": [[2, 1.64, 204.39]]}, {"timestamp": 1578753364028, "ltp": 1.61, "tv": 1145.14, "trd": NaN, "batb": NaN, "batl": [[2, 1.64, 505.08]]}, {"timestamp": 1578753423894, "ltp": 1.61, "tv": 1145.14, "trd": NaN, "batb": NaN, "batl": [[2, 1.64, 305.15]]}, {"timestamp": 1578753426397, "ltp": 1.61, "tv": 1145.14, "trd": NaN, "batb": NaN, "batl": [[0, 1.63, 443.98], [1, 1.64, 305.15], [2, 1.65, 199.9]]}, {"timestamp": 1578754261037, "ltp": 1.61, "tv": 1145.14, "trd": NaN, "batb": [[1, 1.6, 15.74]], "batl": [[0, 1.63, 22.63]]}, {"timestamp": 1578754262021, "ltp": 1.61, "tv": 1145.14, "trd": NaN, "batb": [[0, 1.61, 19.61]], "batl": NaN}, {"timestamp": 1578754269900, "ltp": 1.61, "tv": 1145.14, "trd": NaN, "batb": [[0, 1.6, 15.74], [1, 1.59, 307.62], [2, 1.58, 369.26]], "batl": [[0, 1.62, 8.61], [1, 1.63, 22.63], [2, 1.64, 305.15]]}, {"timestamp": 1578754270320, "ltp": 1.61, "tv": 1145.14, "trd": NaN, "batb": NaN, "batl": [[2, 1.64, 22.45]]}, {"timestamp": 1578754323959, "ltp": 1.61, "tv": 1145.14, "trd": NaN, "batb": [[0, 1.6, 58.3]], "batl": [[1, 1.63, 58.38], [2, 1.64, 305.49]]}, {"timestamp": 1578754380961, "ltp": 1.61, "tv": 1145.14, "trd": NaN, "batb": [[0, 1.6, 15.74]], "batl": [[1, 1.63, 22.63]]}, {"timestamp": 1578754381973, "ltp": 1.61, "tv": 1145.14, "trd": NaN, "batb": NaN, "batl": [[2, 1.64, 22.45]]}, {"timestamp": 1578754444043, "ltp": 1.61, "tv": 1145.14, "trd": NaN, "batb": [[0, 1.6, 57.45]], "batl": [[1, 1.63, 57.53]]}, {"timestamp": 1578754444633, "ltp": 1.61, "tv": 1145.14, "trd": NaN, "batb": NaN, "batl": [[2, 1.64, 305.43]]}, {"timestamp": 1578754556992, "ltp": 1.61, "tv": 1145.14, "trd": NaN, "batb": [[0, 1.61, 288.25], [1, 1.6, 534.12], [2, 1.59, 15.81]], "batl": [[1, 1.63, 454.2]]}, {"timestamp": 1578754565395, "ltp": 1.61, "tv": 1145.14, "trd": NaN, "batb": [[0, 1.61, 312.12]], "batl": NaN}, {"timestamp": 1578754568297, "ltp": 1.61, "tv": 1145.14, "trd": NaN, "batb": NaN, "batl": [[0, 1.63, 454.2], [1, 1.64, 305.43], [2, 1.65, 199.9]]}, {"timestamp": 1578754765374, "ltp": 1.61, "tv": 1145.14, "trd": NaN, "batb": NaN, "batl": [[1, 1.64, 305.49]]}, {"timestamp": 1578754832768, "ltp": 1.61, "tv": 1145.14, "trd": NaN, "batb": [[1, 1.6, 579.12], [2, 1.59, 60.81]], "batl": [[1, 1.64, 350.49], [2, 1.65, 244.9]]}, {"timestamp": 1578754833999, "ltp": 1.61, "tv": 1145.14, "trd": NaN, "batb": [[0, 1.61, 357.12]], "batl": [[0, 1.63, 499.2]]}, {"timestamp": 1578754869920, "ltp": 1.61, "tv": 1145.14, "trd": NaN, "batb": NaN, "batl": [[1, 1.64, 67.45]]}, {"timestamp": 1578754874771, "ltp": 1.61, "tv": 1145.14, "trd": NaN, "batb": NaN, "batl": [[1, 1.64, 350.5]]}, {"timestamp": 1578754878754, "ltp": 1.61, "tv": 1145.14, "trd": NaN, "batb": NaN, "batl": [[1, 1.64, 67.45]]}, {"timestamp": 1578754883248, "ltp": 1.61, "tv": 1145.14, "trd": NaN, "batb": NaN, "batl": [[1, 1.64, 350.5]]}, {"timestamp": 1578755149001, "ltp": 1.61, "tv": 1145.14, "trd": NaN, "batb": NaN, "batl": [[1, 1.64, 550.43], [2, 1.65, 45]]}, {"timestamp": 1578755293506, "ltp": 1.61, "tv": 1145.14, "trd": NaN, "batb": NaN, "batl": [[0, 1.63, 783.99], [1, 1.64, 267.38]]}, {"timestamp": 1578755321868, "ltp": 1.61, "tv": 1145.14, "trd": NaN, "batb": NaN, "batl": [[0, 1.62, 4.26], [1, 1.63, 783.99], [2, 1.64, 267.38]]}, {"timestamp": 1578755375799, "ltp": 1.61, "tv": 1145.14, "trd": NaN, "batb": NaN, "batl": [[2, 1.64, 67.45]]}, {"timestamp": 1578755764022, "ltp": 1.61, "tv": 1145.14, "trd": NaN, "batb": NaN, "batl": [[1, 1.63, 499.2], [2, 1.64, 349.88]]}, {"timestamp": 1578755839601, "ltp": 1.61, "tv": 1145.14, "trd": NaN, "batb": [[2, 1.59, 399.75]], "batl": NaN}, {"timestamp": 1578755914873, "ltp": 1.62, "tv": 1149.14, "trd": [[1.62, 57.38]], "batb": NaN, "batl": [[0, 1.62, 2.26]]}, {"timestamp": 1578755989942, "ltp": 1.62, "tv": 1149.14, "trd": NaN, "batb": [[2, 1.59, 60.81]], "batl": NaN}, {"timestamp": 1578756073670, "ltp": 1.61, "tv": 1173.36, "trd": [[1.61, 334.19]], "batb": [[0, 1.61, 345.01]], "batl": NaN}, {"timestamp": 1578756429907, "ltp": 1.61, "tv": 1173.36, "trd": NaN, "batb": [[1, 1.6, 619.98]], "batl": NaN}, {"timestamp": 1578756461750, "ltp": 1.61, "tv": 1173.36, "trd": NaN, "batb": NaN, "batl": [[1, 1.63, 448.98]]}, {"timestamp": 1578756721824, "ltp": 1.62, "tv": 1177.36, "trd": [[1.62, 61.38]], "batb": NaN, "batl": [[0, 1.63, 449.23], [1, 1.64, 349.88], [2, 1.65, 244.9]]}, {"timestamp": 1578756786768, "ltp": 1.61, "tv": 1181.96, "trd": [[1.61, 338.79]], "batb": [[0, 1.61, 342.71]], "batl": NaN}, {"timestamp": 1578757470987, "ltp": 1.61, "tv": 1181.96, "trd": NaN, "batb": NaN, "batl": [[1, 1.64, 461.06], [2, 1.65, 45]]}, {"timestamp": 1578758054027, "ltp": 1.61, "tv": 1181.96, "trd": NaN, "batb": NaN, "batl": [[1, 1.64, 549.74]]}, {"timestamp": 1578758322438, "ltp": 1.62, "tv": 1185.95, "trd": [[1.62, 65.37]], "batb": NaN, "batl": [[0, 1.62, 29.86], [1, 1.63, 448.98], [2, 1.64, 549.74]]}, {"timestamp": 1578758588992, "ltp": 1.61, "tv": 1216.57, "trd": [[1.61, 369.41]], "batb": [[0, 1.61, 327.4]], "batl": NaN}, {"timestamp": 1578758590009, "ltp": 1.61, "tv": 1216.57, "trd": NaN, "batb": NaN, "batl": [[0, 1.63, 448.98], [1, 1.64, 549.74], [2, 1.65, 45]]}, {"timestamp": 1578758663934, "ltp": 1.61, "tv": 1216.57, "trd": NaN, "batb": NaN, "batl": [[2, 1.65, 244.9]]}, {"timestamp": 1578758664741, "ltp": 1.61, "tv": 1216.57, "trd": NaN, "batb": NaN, "batl": [[1, 1.64, 349.88]]}, {"timestamp": 1578758925845, "ltp": 1.61, "tv": 1216.57, "trd": NaN, "batb": NaN, "batl": [[1, 1.64, 465.81], [2, 1.65, 45]]}, {"timestamp": 1578759028937, "ltp": 1.61, "tv": 1216.57, "trd": NaN, "batb": NaN, "batl": [[0, 1.63, 414.93]]}, {"timestamp": 1578759471046, "ltp": 1.61, "tv": 1216.57, "trd": NaN, "batb": NaN, "batl": [[0, 1.63, 457.49]]}, {"timestamp": 1578759593657, "ltp": 1.61, "tv": 1216.57, "trd": NaN, "batb": [[2, 1.59, 81.91]], "batl": NaN}, {"timestamp": 1578759673044, "ltp": 1.61, "tv": 1216.57, "trd": NaN, "batb": NaN, "batl": [[1, 1.64, 349.88], [2, 1.65, 244.9]]}, {"timestamp": 1578759718862, "ltp": 1.61, "tv": 1522.81, "trd": [[1.61, 675.64]], "batb": [[0, 1.61, 283.42]], "batl": NaN}, {"timestamp": 1578759726483, "ltp": 1.61, "tv": 1522.81, "trd": NaN, "batb": [[0, 1.61, 388.83]], "batl": NaN}, {"timestamp": 1578759784926, "ltp": 1.61, "tv": 1522.81, "trd": NaN, "batb": NaN, "batl": [[1, 1.64, 549.81], [2, 1.65, 45]]}, {"timestamp": 1578759788048, "ltp": 1.61, "tv": 1522.81, "trd": NaN, "batb": NaN, "batl": [[1, 1.64, 581.23]]}, {"timestamp": 1578759818797, "ltp": 1.61, "tv": 1522.81, "trd": NaN, "batb": [[2, 1.59, 420.85]], "batl": [[1, 1.64, 381.3]]}, {"timestamp": 1578759850807, "ltp": 1.61, "tv": 1522.81, "trd": NaN, "batb": NaN, "batl": [[2, 1.65, 45.37]]}, {"timestamp": 1578759966855, "ltp": 1.61, "tv": 1522.81, "trd": NaN, "batb": [[2, 1.59, 81.91]], "batl": [[2, 1.65, 245.27]]}, {"timestamp": 1578759989046, "ltp": 1.61, "tv": 1522.81, "trd": NaN, "batb": NaN, "batl": [[1, 1.64, 498.65], [2, 1.65, 45.37]]}, {"timestamp": 1578760022967, "ltp": 1.61, "tv": 1522.81, "trd": NaN, "batb": NaN, "batl": [[1, 1.64, 381.3], [2, 1.65, 245.27]]}, {"timestamp": 1578760024922, "ltp": 1.61, "tv": 1522.81, "trd": NaN, "batb": NaN, "batl": [[1, 1.64, 381.11]]}, {"timestamp": 1578760049986, "ltp": 1.61, "tv": 1522.81, "trd": NaN, "batb": [[2, 1.59, 420.85]], "batl": [[1, 1.64, 67.45], [2, 1.65, 45.37]]}, {"timestamp": 1578760059013, "ltp": 1.61, "tv": 1522.81, "trd": NaN, "batb": NaN, "batl": [[1, 1.64, 381.15]]}, {"timestamp": 1578760069024, "ltp": 1.61, "tv": 1522.81, "trd": NaN, "batb": [[2, 1.59, 81.91]], "batl": NaN}, {"timestamp": 1578760421739, "ltp": 1.61, "tv": 1525.61, "trd": [[1.61, 678.44]], "batb": [[0, 1.61, 387.43]], "batl": NaN}, {"timestamp": 1578760720010, "ltp": 1.61, "tv": 1525.61, "trd": NaN, "batb": NaN, "batl": [[2, 1.65, 245.27]]}, {"timestamp": 1578760759939, "ltp": 1.61, "tv": 1525.61, "trd": NaN, "batb": NaN, "batl": [[2, 1.65, 45.37]]}, {"timestamp": 1578760852447, "ltp": 1.61, "tv": 1541.53, "trd": [[1.61, 694.36]], "batb": [[0, 1.61, 379.47]], "batl": NaN}, {"timestamp": 1578761286732, "ltp": 1.61, "tv": 1541.53, "trd": NaN, "batb": [[1, 1.6, 659.14]], "batl": NaN}, {"timestamp": 1578761342051, "ltp": 1.61, "tv": 1564.49, "trd": [[1.61, 717.33]], "batb": [[0, 1.61, 367.99]], "batl": NaN}, {"timestamp": 1578761361899, "ltp": 1.61, "tv": 1564.49, "trd": NaN, "batb": NaN, "batl": [[2, 1.65, 245.27]]}, {"timestamp": 1578761373008, "ltp": 1.61, "tv": 1564.49, "trd": NaN, "batb": NaN, "batl": [[2, 1.65, 45.37]]}, {"timestamp": 1578761381006, "ltp": 1.61, "tv": 1564.49, "trd": NaN, "batb": [[2, 1.59, 420.85]], "batl": NaN}, {"timestamp": 1578761384054, "ltp": 1.61, "tv": 1564.49, "trd": NaN, "batb": [[2, 1.59, 81.91]], "batl": NaN}, {"timestamp": 1578761384644, "ltp": 1.61, "tv": 1564.49, "trd": NaN, "batb": [[2, 1.59, 420.85]], "batl": NaN}, {"timestamp": 1578761413376, "ltp": 1.61, "tv": 1592.49, "trd": [[1.61, 745.33]], "batb": [[0, 1.61, 353.99]], "batl": NaN}, {"timestamp": 1578761420864, "ltp": 1.61, "tv": 1592.49, "trd": NaN, "batb": [[0, 1.61, 474.64]], "batl": NaN}, {"timestamp": 1578761569013, "ltp": 1.61, "tv": 1592.49, "trd": NaN, "batb": [[2, 1.59, 81.91]], "batl": [[1, 1.64, 495.8]]}, {"timestamp": 1578761607036, "ltp": 1.61, "tv": 1592.49, "trd": NaN, "batb": [[2, 1.59, 420.85]], "batl": [[1, 1.64, 381.15]]}, {"timestamp": 1578761777811, "ltp": 1.61, "tv": 1592.49, "trd": NaN, "batb": [[2, 1.59, 81.91]], "batl": NaN}, {"timestamp": 1578761788045, "ltp": 1.61, "tv": 1592.49, "trd": NaN, "batb": NaN, "batl": [[0, 1.63, 408.97]]}, {"timestamp": 1578761803052, "ltp": 1.61, "tv": 1592.49, "trd": NaN, "batb": NaN, "batl": [[1, 1.64, 498.83]]}, {"timestamp": 1578761804954, "ltp": 1.61, "tv": 1592.49, "trd": NaN, "batb": NaN, "batl": [[1, 1.64, 499.02]]}, {"timestamp": 1578761870040, "ltp": 1.61, "tv": 1592.49, "trd": NaN, "batb": [[2, 1.59, 420.85]], "batl": [[1, 1.64, 381.34]]}, {"timestamp": 1578761871996, "ltp": 1.61, "tv": 1592.49, "trd": NaN, "batb": [[2, 1.59, 81.91]], "batl": [[1, 1.64, 497.52]]}, {"timestamp": 1578761888039, "ltp": 1.61, "tv": 1592.49, "trd": NaN, "batb": [[2, 1.59, 420.85]], "batl": [[1, 1.64, 381.34]]}, {"timestamp": 1578761906757, "ltp": 1.61, "tv": 1596.23, "trd": [[1.61, 749.07]], "batb": [[0, 1.61, 472.77]], "batl": NaN}, {"timestamp": 1578761921681, "ltp": 1.61, "tv": 1596.23, "trd": NaN, "batb": [[2, 1.59, 81.91]], "batl": [[1, 1.64, 497.77]]}, {"timestamp": 1578761971638, "ltp": 1.61, "tv": 1600.23, "trd": [[1.61, 753.07]], "batb": [[0, 1.61, 470.77]], "batl": NaN}, {"timestamp": 1578762043027, "ltp": 1.61, "tv": 1600.23, "trd": NaN, "batb": [[0, 1.61, 249.95]], "batl": [[1, 1.64, 183.88]]}, {"timestamp": 1578762059025, "ltp": 1.61, "tv": 1600.23, "trd": NaN, "batb": NaN, "batl": [[1, 1.64, 267.31]]}, {"timestamp": 1578762077734, "ltp": 1.61, "tv": 1600.23, "trd": NaN, "batb": NaN, "batl": [[1, 1.64, 319.23]]}, {"timestamp": 1578762085050, "ltp": 1.61, "tv": 1600.23, "trd": NaN, "batb": [[1, 1.6, 60.74]], "batl": [[0, 1.63, 67.63], [1, 1.64, 267.31]]}, {"timestamp": 1578762117984, "ltp": 1.61, "tv": 1600.23, "trd": NaN, "batb": [[2, 1.59, 420.85]], "batl": [[1, 1.64, 67.45]]}, {"timestamp": 1578762124014, "ltp": 1.61, "tv": 1600.23, "trd": NaN, "batb": [[0, 1.61, 189.52]], "batl": NaN}, {"timestamp": 1578762125022, "ltp": 1.61, "tv": 1600.23, "trd": NaN, "batb": [[0, 1.61, 255.2]], "batl": NaN}, {"timestamp": 1578762142030, "ltp": 1.61, "tv": 1600.23, "trd": NaN, "batb": [[0, 1.62, 64.48], [1, 1.61, 189.52], [2, 1.6, 60.74]], "batl": NaN}, {"timestamp": 1578762142827, "ltp": 1.61, "tv": 1600.23, "trd": NaN, "batb": [[0, 1.62, 159.77]], "batl": NaN}, {"timestamp": 1578762283957, "ltp": 1.62, "tv": 1604.23, "trd": [[1.62, 69.37]], "batb": [[0, 1.62, 157.77]], "batl": NaN}, {"timestamp": 1578762431034, "ltp": 1.62, "tv": 1604.23, "trd": NaN, "batb": [[2, 1.6, 103.3]], "batl": [[0, 1.63, 103.38]]}, {"timestamp": 1578762452050, "ltp": 1.62, "tv": 1604.23, "trd": NaN, "batb": [[2, 1.6, 110.11]], "batl": NaN}, {"timestamp": 1578762455974, "ltp": 1.62, "tv": 1604.23, "trd": NaN, "batb": [[0, 1.62, 95.29], [1, 1.61, 261.53]], "batl": NaN}, {"timestamp": 1578762457901, "ltp": 1.62, "tv": 1604.23, "trd": NaN, "batb": NaN, "batl": [[0, 1.63, 93.17]]}, {"timestamp": 1578762526964, "ltp": 1.62, "tv": 1604.23, "trd": NaN, "batb": [[2, 1.6, 693.19]], "batl": [[0, 1.63, 404.71]]}, {"timestamp": 1578762527979, "ltp": 1.62, "tv": 1604.23, "trd": NaN, "batb": [[0, 1.61, 261.53], [1, 1.6, 693.19], [2, 1.59, 420.85]], "batl": NaN}, {"timestamp": 1578762555915, "ltp": 1.62, "tv": 1604.23, "trd": NaN, "batb": NaN, "batl": [[1, 1.64, 700.75]]}, {"timestamp": 1578762561890, "ltp": 1.62, "tv": 1604.23, "trd": NaN, "batb": [[1, 1.6, 745.11]], "batl": NaN}, {"timestamp": 1578762592763, "ltp": 1.62, "tv": 1604.23, "trd": NaN, "batb": NaN, "batl": [[0, 1.63, 67.63]]}, {"timestamp": 1578762642017, "ltp": 1.62, "tv": 1604.23, "trd": NaN, "batb": [[1, 1.6, 703.4]], "batl": NaN}, {"timestamp": 1578762731644, "ltp": 1.62, "tv": 1604.23, "trd": NaN, "batb": [[0, 1.61, 509.19]], "batl": [[1, 1.64, 957.36]]}, {"timestamp": 1578762771958, "ltp": 1.63, "tv": 1612.23, "trd": [[1.63, 46.54]], "batb": [[0, 1.62, 22.98], [1, 1.61, 509.19], [2, 1.6, 703.4]], "batl": [[0, 1.63, 63.63]]}, {"timestamp": 1578762773067, "ltp": 1.63, "tv": 1612.23, "trd": NaN, "batb": [[0, 1.62, 67.98]], "batl": NaN}, {"timestamp": 1578762793574, "ltp": 1.63, "tv": 1612.23, "trd": NaN, "batb": [[2, 1.6, 732.34]], "batl": NaN}, {"timestamp": 1578762891025, "ltp": 1.63, "tv": 1612.23, "trd": NaN, "batb": NaN, "batl": [[2, 1.65, 245.27]]}, {"timestamp": 1578762891934, "ltp": 1.63, "tv": 1612.23, "trd": NaN, "batb": [[2, 1.6, 753.44]], "batl": NaN}, {"timestamp": 1578762920838, "ltp": 1.63, "tv": 1612.23, "trd": NaN, "batb": NaN, "batl": [[2, 1.65, 45.37]]}, {"timestamp": 1578763023972, "ltp": 1.63, "tv": 1612.23, "trd": NaN, "batb": NaN, "batl": [[2, 1.65, 245.27]]}, {"timestamp": 1578763055048, "ltp": 1.63, "tv": 1612.23, "trd": NaN, "batb": NaN, "batl": [[1, 1.64, 1157.29], [2, 1.65, 45.37]]}, {"timestamp": 1578763057011, "ltp": 1.63, "tv": 1612.23, "trd": NaN, "batb": [[0, 1.62, 45]], "batl": NaN}, {"timestamp": 1578763092055, "ltp": 1.63, "tv": 1612.23, "trd": NaN, "batb": NaN, "batl": [[1, 1.64, 957.36], [2, 1.65, 245.27]]}, {"timestamp": 1578763349938, "ltp": 1.63, "tv": 1612.23, "trd": NaN, "batb": NaN, "batl": [[1, 1.64, 982.36]]}, {"timestamp": 1578763417877, "ltp": 1.62, "tv": 1622.61, "trd": [[1.62, 79.75]], "batb": [[0, 1.62, 39.81]], "batl": NaN}, {"timestamp": 1578763446027, "ltp": 1.62, "tv": 1622.61, "trd": NaN, "batb": NaN, "batl": [[1, 1.64, 1026.62]]}, {"timestamp": 1578763504002, "ltp": 1.62, "tv": 1622.61, "trd": NaN, "batb": NaN, "batl": [[2, 1.65, 45.37]]}, {"timestamp": 1578763504978, "ltp": 1.62, "tv": 1622.61, "trd": NaN, "batb": [[0, 1.62, 62.78]], "batl": NaN}, {"timestamp": 1578763505881, "ltp": 1.62, "tv": 1622.61, "trd": NaN, "batb": [[0, 1.62, 39.81]], "batl": NaN}, {"timestamp": 1578763507275, "ltp": 1.62, "tv": 1622.61, "trd": NaN, "batb": [[0, 1.62, 62.78]], "batl": NaN}, {"timestamp": 1578763508993, "ltp": 1.62, "tv": 1622.61, "trd": NaN, "batb": [[0, 1.62, 39.81]], "batl": NaN}, {"timestamp": 1578763509592, "ltp": 1.62, "tv": 1622.61, "trd": NaN, "batb": [[0, 1.62, 62.78]], "batl": NaN}, {"timestamp": 1578763510873, "ltp": 1.62, "tv": 1622.61, "trd": NaN, "batb": [[0, 1.62, 39.81]], "batl": NaN}, {"timestamp": 1578763511898, "ltp": 1.62, "tv": 1622.61, "trd": NaN, "batb": [[0, 1.62, 62.78]], "batl": NaN}, {"timestamp": 1578763512858, "ltp": 1.62, "tv": 1622.61, "trd": NaN, "batb": [[0, 1.62, 39.81]], "batl": NaN}, {"timestamp": 1578763513879, "ltp": 1.62, "tv": 1622.61, "trd": NaN, "batb": [[0, 1.62, 62.78]], "batl": NaN}, {"timestamp": 1578763514505, "ltp": 1.62, "tv": 1622.61, "trd": NaN, "batb": [[0, 1.62, 39.81]], "batl": NaN}, {"timestamp": 1578763516786, "ltp": 1.62, "tv": 1622.61, "trd": NaN, "batb": [[0, 1.62, 62.78]], "batl": NaN}, {"timestamp": 1578763517532, "ltp": 1.62, "tv": 1622.61, "trd": NaN, "batb": [[0, 1.62, 39.81]], "batl": NaN}, {"timestamp": 1578763520919, "ltp": 1.62, "tv": 1622.61, "trd": NaN, "batb": [[0, 1.62, 62.78]], "batl": NaN}, {"timestamp": 1578763521677, "ltp": 1.62, "tv": 1622.61, "trd": NaN, "batb": [[0, 1.62, 39.81]], "batl": NaN}, {"timestamp": 1578763523014, "ltp": 1.62, "tv": 1622.61, "trd": NaN, "batb": [[0, 1.62, 62.78]], "batl": NaN}, {"timestamp": 1578763523599, "ltp": 1.62, "tv": 1622.61, "trd": NaN, "batb": [[0, 1.62, 39.81]], "batl": NaN}, {"timestamp": 1578763524774, "ltp": 1.62, "tv": 1622.61, "trd": NaN, "batb": [[0, 1.62, 62.78]], "batl": NaN}, {"timestamp": 1578763525720, "ltp": 1.62, "tv": 1622.61, "trd": NaN, "batb": [[0, 1.62, 39.81]], "batl": NaN}, {"timestamp": 1578763526590, "ltp": 1.62, "tv": 1622.61, "trd": NaN, "batb": [[0, 1.62, 62.78]], "batl": NaN}, {"timestamp": 1578763528987, "ltp": 1.62, "tv": 1622.61, "trd": NaN, "batb": NaN, "batl": [[1, 1.64, 770.01]]}, {"timestamp": 1578763530037, "ltp": 1.62, "tv": 1622.61, "trd": NaN, "batb": [[0, 1.62, 39.81]], "batl": NaN}, {"timestamp": 1578763530999, "ltp": 1.62, "tv": 1622.61, "trd": NaN, "batb": [[0, 1.62, 62.78]], "batl": NaN}, {"timestamp": 1578763531896, "ltp": 1.62, "tv": 1622.61, "trd": NaN, "batb": [[0, 1.62, 39.81]], "batl": NaN}, {"timestamp": 1578763535019, "ltp": 1.62, "tv": 1622.61, "trd": NaN, "batb": [[0, 1.62, 62.78]], "batl": NaN}, {"timestamp": 1578763539013, "ltp": 1.62, "tv": 1622.61, "trd": NaN, "batb": NaN, "batl": [[1, 1.64, 1025.49]]}, {"timestamp": 1578763540012, "ltp": 1.62, "tv": 1622.61, "trd": NaN, "batb": [[0, 1.62, 39.81]], "batl": [[2, 1.65, 245.27]]}, {"timestamp": 1578763541015, "ltp": 1.62, "tv": 1622.61, "trd": NaN, "batb": [[0, 1.62, 70.06]], "batl": NaN}, {"timestamp": 1578763593993, "ltp": 1.62, "tv": 1622.61, "trd": NaN, "batb": NaN, "batl": [[0, 1.63, 446.68]]}, {"timestamp": 1578763594795, "ltp": 1.62, "tv": 1622.61, "trd": NaN, "batb": [[0, 1.62, 39.81]], "batl": NaN}, {"timestamp": 1578763625030, "ltp": 1.62, "tv": 1622.61, "trd": NaN, "batb": [[2, 1.6, 715.14]], "batl": [[1, 1.64, 347.93]]}, {"timestamp": 1578763630024, "ltp": 1.62, "tv": 1622.61, "trd": NaN, "batb": [[2, 1.6, 685.35]], "batl": NaN}, {"timestamp": 1578763637049, "ltp": 1.62, "tv": 1622.61, "trd": NaN, "batb": NaN, "batl": [[0, 1.63, 702.42]]}, {"timestamp": 1578763637951, "ltp": 1.62, "tv": 1622.61, "trd": NaN, "batb": NaN, "batl": [[1, 1.64, 92.45]]}, {"timestamp": 1578763646549, "ltp": 1.62, "tv": 1622.61, "trd": NaN, "batb": [[2, 1.6, 728.76]], "batl": NaN}, {"timestamp": 1578763821884, "ltp": 1.62, "tv": 1626.02, "trd": [[1.62, 83.16]], "batb": [[0, 1.62, 38.11]], "batl": NaN}, {"timestamp": 1578763884028, "ltp": 1.62, "tv": 1626.02, "trd": NaN, "batb": NaN, "batl": [[0, 1.63, 902.19], [2, 1.65, 45.37]]}, {"timestamp": 1578763932971, "ltp": 1.62, "tv": 1638.26, "trd": [[1.62, 95.4]], "batb": [[0, 1.62, 31.99]], "batl": NaN}, {"timestamp": 1578764329971, "ltp": 1.62, "tv": 1648.26, "trd": [[1.62, 105.4]], "batb": [[0, 1.62, 26.99]], "batl": NaN}, {"timestamp": 1578764541010, "ltp": 1.62, "tv": 1648.26, "trd": NaN, "batb": [[2, 1.6, 760.25]], "batl": NaN}, {"timestamp": 1578764615993, "ltp": 1.62, "tv": 1648.26, "trd": NaN, "batb": NaN, "batl": [[0, 1.63, 938.79]]}, {"timestamp": 1578764624005, "ltp": 1.62, "tv": 1648.26, "trd": NaN, "batb": NaN, "batl": [[0, 1.63, 739.02]]}, {"timestamp": 1578764658032, "ltp": 1.62, "tv": 1648.26, "trd": NaN, "batb": [[2, 1.6, 719.4]], "batl": NaN}, {"timestamp": 1578764734899, "ltp": 1.62, "tv": 1648.26, "trd": NaN, "batb": NaN, "batl": [[0, 1.63, 483.28], [1, 1.64, 405.72]]}, {"timestamp": 1578764755029, "ltp": 1.62, "tv": 1648.26, "trd": NaN, "batb": NaN, "batl": [[2, 1.65, 245.27]]}, {"timestamp": 1578765245786, "ltp": 1.62, "tv": 1648.26, "trd": NaN, "batb": NaN, "batl": [[1, 1.64, 432.12]]}, {"timestamp": 1578765256861, "ltp": 1.62, "tv": 1648.26, "trd": NaN, "batb": NaN, "batl": [[1, 1.64, 92.45]]}, {"timestamp": 1578765264997, "ltp": 1.62, "tv": 1648.26, "trd": NaN, "batb": NaN, "batl": [[1, 1.64, 432.12]]}, {"timestamp": 1578765379056, "ltp": 1.62, "tv": 1648.26, "trd": NaN, "batb": NaN, "batl": [[2, 1.65, 45.37]]}, {"timestamp": 1578765434979, "ltp": 1.62, "tv": 1702.24, "trd": [[1.62, 159.38]], "batb": [[0, 1.61, 509.19], [1, 1.6, 719.4], [2, 1.59, 60.81]], "batl": [[0, 1.62, 306.01], [1, 1.63, 483.28], [2, 1.64, 432.12]]}, {"timestamp": 1578765436781, "ltp": 1.62, "tv": 1702.24, "trd": NaN, "batb": NaN, "batl": [[0, 1.62, 343.57]]}, {"timestamp": 1578765438361, "ltp": 1.62, "tv": 1702.24, "trd": NaN, "batb": NaN, "batl": [[0, 1.62, 306.01]]}, {"timestamp": 1578765440970, "ltp": 1.62, "tv": 1702.24, "trd": NaN, "batb": NaN, "batl": [[0, 1.62, 343.57]]}, {"timestamp": 1578765441657, "ltp": 1.62, "tv": 1702.24, "trd": NaN, "batb": NaN, "batl": [[0, 1.62, 306.01]]}, {"timestamp": 1578765443768, "ltp": 1.62, "tv": 1702.24, "trd": NaN, "batb": NaN, "batl": [[0, 1.62, 343.57]]}, {"timestamp": 1578765444454, "ltp": 1.62, "tv": 1702.24, "trd": NaN, "batb": NaN, "batl": [[0, 1.62, 306.01]]}, {"timestamp": 1578765447980, "ltp": 1.62, "tv": 1702.24, "trd": NaN, "batb": NaN, "batl": [[0, 1.62, 343.57]]}, {"timestamp": 1578765451471, "ltp": 1.62, "tv": 1702.24, "trd": NaN, "batb": NaN, "batl": [[0, 1.62, 306.01]]}, {"timestamp": 1578765453182, "ltp": 1.62, "tv": 1702.24, "trd": NaN, "batb": NaN, "batl": [[0, 1.62, 343.57]]}, {"timestamp": 1578765454969, "ltp": 1.62, "tv": 1702.24, "trd": NaN, "batb": NaN, "batl": [[0, 1.62, 306.01]]}, {"timestamp": 1578765461007, "ltp": 1.62, "tv": 1726.9, "trd": [[1.62, 184.04]], "batb": NaN, "batl": [[0, 1.62, 293.68]]}, {"timestamp": 1578765463971, "ltp": 1.62, "tv": 1726.9, "trd": NaN, "batb": NaN, "batl": [[0, 1.62, 331.24]]}, {"timestamp": 1578765465879, "ltp": 1.62, "tv": 1726.9, "trd": NaN, "batb": NaN, "batl": [[0, 1.62, 293.68]]}, {"timestamp": 1578765466985, "ltp": 1.62, "tv": 1726.9, "trd": NaN, "batb": NaN, "batl": [[0, 1.62, 331.24]]}, {"timestamp": 1578765467712, "ltp": 1.62, "tv": 1726.9, "trd": NaN, "batb": NaN, "batl": [[0, 1.62, 293.68]]}, {"timestamp": 1578765472703, "ltp": 1.62, "tv": 1726.9, "trd": NaN, "batb": NaN, "batl": [[0, 1.62, 331.24]]}, {"timestamp": 1578765474596, "ltp": 1.62, "tv": 1726.9, "trd": NaN, "batb": NaN, "batl": [[0, 1.62, 293.68]]}, {"timestamp": 1578765476012, "ltp": 1.62, "tv": 1726.9, "trd": NaN, "batb": NaN, "batl": [[0, 1.62, 331.24]]}, {"timestamp": 1578765476490, "ltp": 1.62, "tv": 1726.9, "trd": NaN, "batb": NaN, "batl": [[0, 1.62, 293.68]]}, {"timestamp": 1578765481715, "ltp": 1.62, "tv": 1726.9, "trd": NaN, "batb": NaN, "batl": [[0, 1.62, 331.24]]}, {"timestamp": 1578765482717, "ltp": 1.62, "tv": 1726.9, "trd": NaN, "batb": NaN, "batl": [[0, 1.62, 293.68]]}, {"timestamp": 1578765485000, "ltp": 1.62, "tv": 1726.9, "trd": NaN, "batb": NaN, "batl": [[0, 1.62, 331.24]]}, {"timestamp": 1578765486019, "ltp": 1.62, "tv": 1726.9, "trd": NaN, "batb": NaN, "batl": [[0, 1.62, 293.68]]}, {"timestamp": 1578765486912, "ltp": 1.62, "tv": 1726.9, "trd": NaN, "batb": NaN, "batl": [[0, 1.62, 331.24]]}, {"timestamp": 1578765487697, "ltp": 1.62, "tv": 1726.9, "trd": NaN, "batb": NaN, "batl": [[0, 1.62, 293.68]]}, {"timestamp": 1578765490017, "ltp": 1.62, "tv": 1726.9, "trd": NaN, "batb": NaN, "batl": [[0, 1.62, 331.24]]}, {"timestamp": 1578765490707, "ltp": 1.62, "tv": 1726.9, "trd": NaN, "batb": NaN, "batl": [[0, 1.62, 293.68]]}, {"timestamp": 1578765499904, "ltp": 1.62, "tv": 1726.9, "trd": NaN, "batb": NaN, "batl": [[0, 1.62, 331.24]]}, {"timestamp": 1578765500545, "ltp": 1.62, "tv": 1726.9, "trd": NaN, "batb": NaN, "batl": [[0, 1.62, 293.68]]}, {"timestamp": 1578765505709, "ltp": 1.62, "tv": 1726.9, "trd": NaN, "batb": NaN, "batl": [[0, 1.62, 331.24]]}, {"timestamp": 1578765507030, "ltp": 1.62, "tv": 1726.9, "trd": NaN, "batb": NaN, "batl": [[0, 1.62, 293.68]]}, {"timestamp": 1578765510965, "ltp": 1.62, "tv": 1726.9, "trd": NaN, "batb": NaN, "batl": [[0, 1.62, 331.24]]}, {"timestamp": 1578765512919, "ltp": 1.62, "tv": 1726.9, "trd": NaN, "batb": NaN, "batl": [[0, 1.62, 293.68]]}, {"timestamp": 1578765515026, "ltp": 1.62, "tv": 1726.9, "trd": NaN, "batb": NaN, "batl": [[0, 1.62, 331.24]]}, {"timestamp": 1578765517668, "ltp": 1.62, "tv": 1726.9, "trd": NaN, "batb": NaN, "batl": [[0, 1.62, 293.68]]}, {"timestamp": 1578765520743, "ltp": 1.62, "tv": 1726.9, "trd": NaN, "batb": NaN, "batl": [[0, 1.62, 331.24]]}, {"timestamp": 1578765530751, "ltp": 1.62, "tv": 1726.9, "trd": NaN, "batb": NaN, "batl": [[0, 1.62, 293.68]]}, {"timestamp": 1578765531742, "ltp": 1.62, "tv": 1726.9, "trd": NaN, "batb": NaN, "batl": [[0, 1.62, 331.24]]}, {"timestamp": 1578765532995, "ltp": 1.61, "tv": 1731.33, "trd": [[1.61, 757.49]], "batb": [[0, 1.61, 506.98]], "batl": NaN}, {"timestamp": 1578765534052, "ltp": 1.61, "tv": 1731.33, "trd": NaN, "batb": NaN, "batl": [[0, 1.62, 293.68]]}, {"timestamp": 1578765539048, "ltp": 1.61, "tv": 1731.33, "trd": NaN, "batb": [[0, 1.61, 187.31]], "batl": [[1, 1.63, 834.68], [2, 1.64, 92.45]]}, {"timestamp": 1578765540008, "ltp": 1.61, "tv": 1731.33, "trd": NaN, "batb": NaN, "batl": [[0, 1.62, 312.87]]}, {"timestamp": 1578765546972, "ltp": 1.61, "tv": 1731.33, "trd": NaN, "batb": [[1, 1.6, 1077.38]], "batl": NaN}, {"timestamp": 1578765623022, "ltp": 1.61, "tv": 1931.33, "trd": [[1.61, 957.5]], "batb": [[0, 1.61, 87.3]], "batl": NaN}, {"timestamp": 1578765645857, "ltp": 1.61, "tv": 1931.33, "trd": NaN, "batb": [[1, 1.6, 1077.22]], "batl": NaN}, {"timestamp": 1578765651008, "ltp": 1.61, "tv": 1931.33, "trd": NaN, "batb": NaN, "batl": [[1, 1.63, 873.83]]}, {"timestamp": 1578765651960, "ltp": 1.61, "tv": 1931.33, "trd": NaN, "batb": [[1, 1.6, 719.4]], "batl": NaN}, {"timestamp": 1578765654965, "ltp": 1.61, "tv": 1931.33, "trd": NaN, "batb": [[1, 1.6, 1077.22]], "batl": NaN}, {"timestamp": 1578765765045, "ltp": 1.61, "tv": 1931.33, "trd": NaN, "batb": [[1, 1.6, 1032.1]], "batl": NaN}, {"timestamp": 1578765858635, "ltp": 1.61, "tv": 1931.33, "trd": NaN, "batb": [[1, 1.6, 1038.02]], "batl": NaN}, {"timestamp": 1578765972005, "ltp": 1.61, "tv": 1931.33, "trd": NaN, "batb": [[2, 1.59, 98.15]], "batl": NaN}, {"timestamp": 1578766096694, "ltp": 1.61, "tv": 1931.33, "trd": NaN, "batb": [[1, 1.6, 674.28]], "batl": NaN}, {"timestamp": 1578766098011, "ltp": 1.61, "tv": 1931.33, "trd": NaN, "batb": [[1, 1.6, 1038.18]], "batl": NaN}, {"timestamp": 1578766102309, "ltp": 1.61, "tv": 1931.33, "trd": NaN, "batb": [[1, 1.6, 674.28]], "batl": NaN}, {"timestamp": 1578766108988, "ltp": 1.61, "tv": 1931.33, "trd": NaN, "batb": [[1, 1.6, 1038.18]], "batl": NaN}, {"timestamp": 1578766125831, "ltp": 1.61, "tv": 1931.33, "trd": NaN, "batb": [[1, 1.6, 674.28]], "batl": NaN}, {"timestamp": 1578766126216, "ltp": 1.61, "tv": 1931.33, "trd": NaN, "batb": [[1, 1.6, 1038.18]], "batl": NaN}, {"timestamp": 1578766135871, "ltp": 1.61, "tv": 1931.33, "trd": NaN, "batb": [[1, 1.6, 1038.23]], "batl": NaN}, {"timestamp": 1578766155927, "ltp": 1.61, "tv": 1931.33, "trd": NaN, "batb": NaN, "batl": [[2, 1.64, 292.38]]}, {"timestamp": 1578766157048, "ltp": 1.61, "tv": 1931.33, "trd": NaN, "batb": [[1, 1.6, 1029.06]], "batl": [[1, 1.63, 870.68]]}, {"timestamp": 1578766423018, "ltp": 1.61, "tv": 1931.33, "trd": NaN, "batb": NaN, "batl": [[2, 1.64, 92.45]]}, {"timestamp": 1578766438964, "ltp": 1.61, "tv": 1931.33, "trd": NaN, "batb": NaN, "batl": [[1, 1.63, 962.61]]}, {"timestamp": 1578766444041, "ltp": 1.61, "tv": 1931.33, "trd": NaN, "batb": [[1, 1.6, 823.92]], "batl": [[1, 1.63, 411.88]]}, {"timestamp": 1578766444845, "ltp": 1.61, "tv": 1931.33, "trd": NaN, "batb": [[1, 1.6, 787.32]], "batl": NaN}, {"timestamp": 1578766455053, "ltp": 1.61, "tv": 1931.33, "trd": NaN, "batb": [[1, 1.6, 983.1]], "batl": [[1, 1.63, 975.38]]}, {"timestamp": 1578766457668, "ltp": 1.62, "tv": 1951.33, "trd": [[1.62, 204.04]], "batb": NaN, "batl": [[0, 1.62, 302.87]]}, {"timestamp": 1578766470010, "ltp": 1.62, "tv": 1951.33, "trd": NaN, "batb": [[1, 1.6, 946.49]], "batl": NaN}, {"timestamp": 1578766501015, "ltp": 1.62, "tv": 2035.73, "trd": [[1.62, 288.44]], "batb": NaN, "batl": [[0, 1.62, 260.67]]}, {"timestamp": 1578766503036, "ltp": 1.62, "tv": 2035.73, "trd": NaN, "batb": [[0, 1.61, 101.69]], "batl": NaN}, {"timestamp": 1578766503509, "ltp": 1.62, "tv": 2035.73, "trd": NaN, "batb": [[0, 1.61, 87.3]], "batl": NaN}, {"timestamp": 1578766507738, "ltp": 1.62, "tv": 2035.73, "trd": NaN, "batb": [[0, 1.61, 101.69]], "batl": NaN}, {"timestamp": 1578766509039, "ltp": 1.62, "tv": 2035.73, "trd": NaN, "batb": [[0, 1.61, 87.3]], "batl": NaN}, {"timestamp": 1578766509942, "ltp": 1.62, "tv": 2035.73, "trd": NaN, "batb": [[0, 1.61, 101.69]], "batl": NaN}, {"timestamp": 1578766510945, "ltp": 1.62, "tv": 2035.73, "trd": NaN, "batb": [[0, 1.61, 87.3]], "batl": NaN}, {"timestamp": 1578766512824, "ltp": 1.62, "tv": 2035.73, "trd": NaN, "batb": [[0, 1.61, 101.69]], "batl": NaN}, {"timestamp": 1578766514054, "ltp": 1.62, "tv": 2035.73, "trd": NaN, "batb": [[0, 1.61, 87.3]], "batl": NaN}, {"timestamp": 1578766515435, "ltp": 1.62, "tv": 2035.73, "trd": NaN, "batb": [[0, 1.61, 101.69]], "batl": NaN}, {"timestamp": 1578766516824, "ltp": 1.62, "tv": 2035.73, "trd": NaN, "batb": [[0, 1.61, 87.3]], "batl": NaN}, {"timestamp": 1578766518950, "ltp": 1.62, "tv": 2035.73, "trd": NaN, "batb": [[0, 1.61, 101.69]], "batl": NaN}, {"timestamp": 1578766519965, "ltp": 1.62, "tv": 2035.73, "trd": NaN, "batb": [[0, 1.61, 87.3]], "batl": NaN}, {"timestamp": 1578766521074, "ltp": 1.62, "tv": 2035.73, "trd": NaN, "batb": [[0, 1.61, 101.69]], "batl": NaN}, {"timestamp": 1578766522843, "ltp": 1.62, "tv": 2035.73, "trd": NaN, "batb": [[0, 1.61, 87.3]], "batl": NaN}, {"timestamp": 1578766523959, "ltp": 1.62, "tv": 2035.73, "trd": NaN, "batb": [[0, 1.61, 101.69]], "batl": NaN}, {"timestamp": 1578766524870, "ltp": 1.62, "tv": 2035.73, "trd": NaN, "batb": [[0, 1.61, 87.3]], "batl": NaN}, {"timestamp": 1578766526754, "ltp": 1.62, "tv": 2035.73, "trd": NaN, "batb": [[0, 1.61, 101.69]], "batl": NaN}, {"timestamp": 1578766527504, "ltp": 1.62, "tv": 2035.73, "trd": NaN, "batb": [[0, 1.61, 87.3]], "batl": NaN}, {"timestamp": 1578766529557, "ltp": 1.62, "tv": 2035.73, "trd": NaN, "batb": [[0, 1.61, 101.69]], "batl": NaN}, {"timestamp": 1578766530364, "ltp": 1.62, "tv": 2035.73, "trd": NaN, "batb": [[0, 1.61, 87.3]], "batl": NaN}, {"timestamp": 1578766532893, "ltp": 1.62, "tv": 2035.73, "trd": NaN, "batb": [[0, 1.61, 101.69]], "batl": NaN}, {"timestamp": 1578766533554, "ltp": 1.62, "tv": 2035.73, "trd": NaN, "batb": [[0, 1.61, 87.3]], "batl": NaN}, {"timestamp": 1578766534992, "ltp": 1.62, "tv": 2035.73, "trd": NaN, "batb": [[0, 1.61, 101.69]], "batl": NaN}, {"timestamp": 1578766535479, "ltp": 1.62, "tv": 2035.73, "trd": NaN, "batb": [[0, 1.61, 87.3]], "batl": NaN}, {"timestamp": 1578766536877, "ltp": 1.62, "tv": 2035.73, "trd": NaN, "batb": [[0, 1.61, 101.69]], "batl": NaN}, {"timestamp": 1578766538960, "ltp": 1.62, "tv": 2035.73, "trd": NaN, "batb": [[0, 1.61, 87.3]], "batl": NaN}, {"timestamp": 1578766540191, "ltp": 1.62, "tv": 2035.73, "trd": NaN, "batb": [[0, 1.61, 101.69]], "batl": NaN}, {"timestamp": 1578766541895, "ltp": 1.62, "tv": 2035.73, "trd": NaN, "batb": [[0, 1.61, 87.3]], "batl": NaN}, {"timestamp": 1578766542381, "ltp": 1.62, "tv": 2035.73, "trd": NaN, "batb": [[0, 1.61, 101.69]], "batl": NaN}, {"timestamp": 1578766543072, "ltp": 1.62, "tv": 2035.73, "trd": NaN, "batb": [[0, 1.61, 87.3]], "batl": NaN}, {"timestamp": 1578766546913, "ltp": 1.62, "tv": 2035.73, "trd": NaN, "batb": [[0, 1.61, 101.69]], "batl": NaN}, {"timestamp": 1578766547675, "ltp": 1.62, "tv": 2035.73, "trd": NaN, "batb": [[0, 1.61, 87.3]], "batl": NaN}, {"timestamp": 1578766549693, "ltp": 1.62, "tv": 2035.73, "trd": NaN, "batb": [[0, 1.61, 101.69]], "batl": NaN}, {"timestamp": 1578766551994, "ltp": 1.62, "tv": 2035.73, "trd": NaN, "batb": [[0, 1.61, 87.3]], "batl": NaN}, {"timestamp": 1578766552814, "ltp": 1.62, "tv": 2035.73, "trd": NaN, "batb": [[0, 1.61, 101.69]], "batl": NaN}, {"timestamp": 1578766553977, "ltp": 1.62, "tv": 2035.73, "trd": NaN, "batb": [[0, 1.61, 87.3]], "batl": NaN}, {"timestamp": 1578766561408, "ltp": 1.62, "tv": 2035.73, "trd": NaN, "batb": [[0, 1.61, 101.69]], "batl": NaN}, {"timestamp": 1578766562311, "ltp": 1.62, "tv": 2035.73, "trd": NaN, "batb": [[0, 1.61, 87.3]], "batl": NaN}, {"timestamp": 1578766565006, "ltp": 1.62, "tv": 2035.73, "trd": NaN, "batb": [[0, 1.61, 101.69]], "batl": NaN}, {"timestamp": 1578766566028, "ltp": 1.62, "tv": 2035.73, "trd": NaN, "batb": [[0, 1.61, 87.3]], "batl": NaN}, {"timestamp": 1578766566717, "ltp": 1.62, "tv": 2035.73, "trd": NaN, "batb": [[0, 1.61, 101.69]], "batl": NaN}, {"timestamp": 1578766567795, "ltp": 1.62, "tv": 2035.73, "trd": NaN, "batb": [[0, 1.61, 87.3]], "batl": NaN}, {"timestamp": 1578766568541, "ltp": 1.62, "tv": 2035.73, "trd": NaN, "batb": [[0, 1.61, 101.69]], "batl": NaN}, {"timestamp": 1578766570034, "ltp": 1.62, "tv": 2035.73, "trd": NaN, "batb": [[0, 1.61, 87.3]], "batl": NaN}, {"timestamp": 1578766571757, "ltp": 1.62, "tv": 2035.73, "trd": NaN, "batb": [[0, 1.61, 101.69]], "batl": NaN}, {"timestamp": 1578766573028, "ltp": 1.62, "tv": 2035.73, "trd": NaN, "batb": [[0, 1.61, 87.3]], "batl": NaN}, {"timestamp": 1578766575002, "ltp": 1.62, "tv": 2035.73, "trd": NaN, "batb": [[0, 1.61, 101.69]], "batl": NaN}, {"timestamp": 1578766575903, "ltp": 1.62, "tv": 2035.73, "trd": NaN, "batb": [[0, 1.61, 87.3]], "batl": NaN}, {"timestamp": 1578766578029, "ltp": 1.62, "tv": 2035.73, "trd": NaN, "batb": [[0, 1.61, 101.69]], "batl": NaN}, {"timestamp": 1578766579045, "ltp": 1.62, "tv": 2035.73, "trd": NaN, "batb": [[0, 1.61, 87.3]], "batl": NaN}, {"timestamp": 1578766583448, "ltp": 1.62, "tv": 2035.73, "trd": NaN, "batb": [[0, 1.61, 101.69]], "batl": NaN}, {"timestamp": 1578766585674, "ltp": 1.62, "tv": 2035.73, "trd": NaN, "batb": [[0, 1.61, 87.3]], "batl": NaN}, {"timestamp": 1578766587931, "ltp": 1.62, "tv": 2035.73, "trd": NaN, "batb": [[0, 1.61, 101.69]], "batl": NaN}, {"timestamp": 1578766588963, "ltp": 1.62, "tv": 2035.73, "trd": NaN, "batb": [[0, 1.61, 87.3]], "batl": NaN}, {"timestamp": 1578766589550, "ltp": 1.62, "tv": 2035.73, "trd": NaN, "batb": [[0, 1.61, 101.69]], "batl": NaN}, {"timestamp": 1578766591042, "ltp": 1.62, "tv": 2035.73, "trd": NaN, "batb": [[0, 1.61, 87.3]], "batl": NaN}, {"timestamp": 1578766591531, "ltp": 1.62, "tv": 2035.73, "trd": NaN, "batb": [[0, 1.61, 101.69]], "batl": NaN}, {"timestamp": 1578766592856, "ltp": 1.62, "tv": 2035.73, "trd": NaN, "batb": [[0, 1.61, 87.3]], "batl": NaN}, {"timestamp": 1578766593546, "ltp": 1.62, "tv": 2035.73, "trd": NaN, "batb": [[0, 1.61, 101.69]], "batl": NaN}, {"timestamp": 1578766594840, "ltp": 1.62, "tv": 2035.73, "trd": NaN, "batb": [[0, 1.61, 87.3]], "batl": NaN}, {"timestamp": 1578766595669, "ltp": 1.62, "tv": 2035.73, "trd": NaN, "batb": [[0, 1.61, 101.69]], "batl": NaN}, {"timestamp": 1578766596855, "ltp": 1.62, "tv": 2035.73, "trd": NaN, "batb": [[0, 1.61, 87.3]], "batl": NaN}, {"timestamp": 1578766597758, "ltp": 1.62, "tv": 2035.73, "trd": NaN, "batb": [[0, 1.61, 101.69]], "batl": NaN}, {"timestamp": 1578766598984, "ltp": 1.62, "tv": 2035.73, "trd": NaN, "batb": [[0, 1.61, 87.3]], "batl": NaN}, {"timestamp": 1578766600042, "ltp": 1.62, "tv": 2035.73, "trd": NaN, "batb": [[0, 1.61, 101.69]], "batl": NaN}, {"timestamp": 1578766601048, "ltp": 1.62, "tv": 2035.73, "trd": NaN, "batb": [[0, 1.61, 87.3]], "batl": NaN}, {"timestamp": 1578766602649, "ltp": 1.62, "tv": 2035.73, "trd": NaN, "batb": [[0, 1.61, 101.69]], "batl": NaN}, {"timestamp": 1578766603277, "ltp": 1.62, "tv": 2035.73, "trd": NaN, "batb": [[0, 1.61, 87.3]], "batl": NaN}, {"timestamp": 1578766604557, "ltp": 1.62, "tv": 2035.73, "trd": NaN, "batb": [[0, 1.61, 101.69]], "batl": NaN}, {"timestamp": 1578766605571, "ltp": 1.62, "tv": 2035.73, "trd": NaN, "batb": [[0, 1.61, 87.3]], "batl": NaN}, {"timestamp": 1578766610369, "ltp": 1.62, "tv": 2035.73, "trd": NaN, "batb": [[0, 1.61, 101.69]], "batl": NaN}, {"timestamp": 1578766611481, "ltp": 1.62, "tv": 2035.73, "trd": NaN, "batb": [[0, 1.61, 87.3]], "batl": NaN}, {"timestamp": 1578766613997, "ltp": 1.62, "tv": 2035.73, "trd": NaN, "batb": [[0, 1.61, 101.69]], "batl": NaN}, {"timestamp": 1578766614695, "ltp": 1.62, "tv": 2035.73, "trd": NaN, "batb": [[0, 1.61, 87.3]], "batl": NaN}, {"timestamp": 1578766615562, "ltp": 1.62, "tv": 2035.73, "trd": NaN, "batb": [[0, 1.61, 101.69]], "batl": NaN}, {"timestamp": 1578766616914, "ltp": 1.62, "tv": 2035.73, "trd": NaN, "batb": [[0, 1.61, 87.3]], "batl": NaN}, {"timestamp": 1578766617979, "ltp": 1.62, "tv": 2035.73, "trd": NaN, "batb": [[0, 1.61, 101.69]], "batl": NaN}, {"timestamp": 1578766618560, "ltp": 1.62, "tv": 2035.73, "trd": NaN, "batb": [[0, 1.61, 87.3]], "batl": NaN}, {"timestamp": 1578766620503, "ltp": 1.62, "tv": 2035.73, "trd": NaN, "batb": [[0, 1.61, 101.69]], "batl": NaN}, {"timestamp": 1578766621992, "ltp": 1.62, "tv": 2035.73, "trd": NaN, "batb": [[0, 1.61, 87.3]], "batl": NaN}, {"timestamp": 1578766623014, "ltp": 1.62, "tv": 2035.73, "trd": NaN, "batb": [[0, 1.61, 102.96]], "batl": [[2, 1.64, 292.38]]}, {"timestamp": 1578766623924, "ltp": 1.62, "tv": 2035.73, "trd": NaN, "batb": [[0, 1.61, 87.3]], "batl": NaN}, {"timestamp": 1578766625000, "ltp": 1.62, "tv": 2035.73, "trd": NaN, "batb": [[0, 1.61, 102.96]], "batl": NaN}, {"timestamp": 1578766625924, "ltp": 1.62, "tv": 2035.73, "trd": NaN, "batb": [[0, 1.61, 87.3]], "batl": NaN}, {"timestamp": 1578766628009, "ltp": 1.62, "tv": 2035.73, "trd": NaN, "batb": [[0, 1.61, 102.96]], "batl": NaN}, {"timestamp": 1578766628424, "ltp": 1.62, "tv": 2035.73, "trd": NaN, "batb": [[0, 1.61, 87.3]], "batl": NaN}, {"timestamp": 1578766632703, "ltp": 1.62, "tv": 2035.73, "trd": NaN, "batb": [[0, 1.61, 102.96]], "batl": NaN}, {"timestamp": 1578766633824, "ltp": 1.62, "tv": 2035.73, "trd": NaN, "batb": [[0, 1.61, 87.3]], "batl": NaN}, {"timestamp": 1578766635739, "ltp": 1.62, "tv": 2035.73, "trd": NaN, "batb": [[0, 1.61, 102.96]], "batl": NaN}, {"timestamp": 1578766636836, "ltp": 1.62, "tv": 2035.73, "trd": NaN, "batb": [[0, 1.61, 87.3]], "batl": NaN}, {"timestamp": 1578766638239, "ltp": 1.62, "tv": 2035.73, "trd": NaN, "batb": [[0, 1.61, 102.96]], "batl": NaN}, {"timestamp": 1578766639750, "ltp": 1.62, "tv": 2035.73, "trd": NaN, "batb": [[0, 1.61, 87.3]], "batl": NaN}, {"timestamp": 1578766642045, "ltp": 1.62, "tv": 2035.73, "trd": NaN, "batb": [[0, 1.61, 102.96]], "batl": NaN}, {"timestamp": 1578766642726, "ltp": 1.62, "tv": 2035.73, "trd": NaN, "batb": [[0, 1.61, 87.3]], "batl": NaN}, {"timestamp": 1578766644049, "ltp": 1.62, "tv": 2035.73, "trd": NaN, "batb": [[0, 1.61, 102.96]], "batl": NaN}, {"timestamp": 1578766644818, "ltp": 1.62, "tv": 2035.73, "trd": NaN, "batb": [[0, 1.61, 87.3]], "batl": NaN}, {"timestamp": 1578766645830, "ltp": 1.62, "tv": 2035.73, "trd": NaN, "batb": [[0, 1.61, 102.96]], "batl": NaN}, {"timestamp": 1578766646427, "ltp": 1.62, "tv": 2035.73, "trd": NaN, "batb": [[0, 1.61, 87.3]], "batl": NaN}, {"timestamp": 1578766647818, "ltp": 1.62, "tv": 2035.73, "trd": NaN, "batb": [[0, 1.61, 102.96]], "batl": NaN}, {"timestamp": 1578766648932, "ltp": 1.62, "tv": 2035.73, "trd": NaN, "batb": [[0, 1.61, 87.3]], "batl": NaN}, {"timestamp": 1578766650049, "ltp": 1.62, "tv": 2035.73, "trd": NaN, "batb": [[0, 1.61, 102.96]], "batl": NaN}, {"timestamp": 1578766650854, "ltp": 1.62, "tv": 2035.73, "trd": NaN, "batb": [[0, 1.61, 87.3]], "batl": NaN}, {"timestamp": 1578766651333, "ltp": 1.62, "tv": 2035.73, "trd": NaN, "batb": [[0, 1.61, 102.96]], "batl": NaN}, {"timestamp": 1578766652135, "ltp": 1.62, "tv": 2035.73, "trd": NaN, "batb": [[0, 1.61, 87.3]], "batl": NaN}, {"timestamp": 1578766658684, "ltp": 1.62, "tv": 2035.73, "trd": NaN, "batb": [[0, 1.61, 102.96]], "batl": NaN}, {"timestamp": 1578766659961, "ltp": 1.62, "tv": 2035.73, "trd": NaN, "batb": [[0, 1.61, 87.3]], "batl": NaN}, {"timestamp": 1578766661036, "ltp": 1.62, "tv": 2035.73, "trd": NaN, "batb": [[0, 1.61, 102.96]], "batl": NaN}, {"timestamp": 1578766662051, "ltp": 1.62, "tv": 2035.73, "trd": NaN, "batb": [[0, 1.61, 87.3]], "batl": NaN}, {"timestamp": 1578766665596, "ltp": 1.62, "tv": 2035.73, "trd": NaN, "batb": [[0, 1.61, 102.96]], "batl": NaN}, {"timestamp": 1578766667040, "ltp": 1.62, "tv": 2035.73, "trd": NaN, "batb": [[0, 1.61, 87.3]], "batl": NaN}, {"timestamp": 1578766669650, "ltp": 1.62, "tv": 2035.73, "trd": NaN, "batb": [[0, 1.61, 102.96]], "batl": NaN}, {"timestamp": 1578766670289, "ltp": 1.62, "tv": 2035.73, "trd": NaN, "batb": [[0, 1.61, 87.3]], "batl": NaN}, {"timestamp": 1578766671681, "ltp": 1.62, "tv": 2035.73, "trd": NaN, "batb": [[0, 1.61, 102.96]], "batl": NaN}, {"timestamp": 1578766672846, "ltp": 1.62, "tv": 2035.73, "trd": NaN, "batb": [[0, 1.61, 87.3]], "batl": NaN}, {"timestamp": 1578766673860, "ltp": 1.62, "tv": 2035.73, "trd": NaN, "batb": [[0, 1.61, 102.96]], "batl": [[2, 1.64, 92.45]]}, {"timestamp": 1578766674983, "ltp": 1.62, "tv": 2035.73, "trd": NaN, "batb": [[0, 1.61, 87.3]], "batl": NaN}, {"timestamp": 1578766676965, "ltp": 1.62, "tv": 2035.73, "trd": NaN, "batb": [[0, 1.61, 101.69]], "batl": NaN}, {"timestamp": 1578766677808, "ltp": 1.62, "tv": 2035.73, "trd": NaN, "batb": [[0, 1.61, 87.3]], "batl": NaN}, {"timestamp": 1578766678773, "ltp": 1.62, "tv": 2035.73, "trd": NaN, "batb": [[0, 1.61, 101.69]], "batl": NaN}, {"timestamp": 1578766679998, "ltp": 1.62, "tv": 2035.73, "trd": NaN, "batb": [[0, 1.61, 87.3]], "batl": NaN}, {"timestamp": 1578766680791, "ltp": 1.62, "tv": 2035.73, "trd": NaN, "batb": [[0, 1.61, 101.69]], "batl": NaN}, {"timestamp": 1578766681978, "ltp": 1.62, "tv": 2035.73, "trd": NaN, "batb": [[0, 1.61, 87.3]], "batl": NaN}, {"timestamp": 1578766684808, "ltp": 1.62, "tv": 2035.73, "trd": NaN, "batb": [[0, 1.61, 101.69]], "batl": NaN}, {"timestamp": 1578766685794, "ltp": 1.62, "tv": 2035.73, "trd": NaN, "batb": [[0, 1.61, 87.3]], "batl": NaN}, {"timestamp": 1578766686680, "ltp": 1.62, "tv": 2035.73, "trd": NaN, "batb": [[0, 1.61, 101.69]], "batl": NaN}, {"timestamp": 1578766687682, "ltp": 1.62, "tv": 2035.73, "trd": NaN, "batb": [[0, 1.61, 87.3]], "batl": NaN}, {"timestamp": 1578766688700, "ltp": 1.62, "tv": 2035.73, "trd": NaN, "batb": [[0, 1.61, 101.69]], "batl": NaN}, {"timestamp": 1578766689894, "ltp": 1.62, "tv": 2035.73, "trd": NaN, "batb": [[0, 1.61, 87.3]], "batl": NaN}, {"timestamp": 1578766690687, "ltp": 1.62, "tv": 2035.73, "trd": NaN, "batb": [[0, 1.61, 101.69]], "batl": NaN}, {"timestamp": 1578766691672, "ltp": 1.62, "tv": 2035.73, "trd": NaN, "batb": [[0, 1.61, 87.3]], "batl": NaN}, {"timestamp": 1578766693008, "ltp": 1.62, "tv": 2035.73, "trd": NaN, "batb": [[0, 1.61, 101.69]], "batl": NaN}, {"timestamp": 1578766693699, "ltp": 1.62, "tv": 2035.73, "trd": NaN, "batb": [[0, 1.61, 87.3]], "batl": NaN}, {"timestamp": 1578766696782, "ltp": 1.62, "tv": 2035.73, "trd": NaN, "batb": [[0, 1.61, 101.69]], "batl": NaN}, {"timestamp": 1578766698013, "ltp": 1.62, "tv": 2035.73, "trd": NaN, "batb": [[0, 1.61, 87.3]], "batl": NaN}, {"timestamp": 1578766700831, "ltp": 1.62, "tv": 2035.73, "trd": NaN, "batb": [[0, 1.61, 101.69]], "batl": NaN}, {"timestamp": 1578766701683, "ltp": 1.62, "tv": 2035.73, "trd": NaN, "batb": [[0, 1.61, 87.3]], "batl": NaN}, {"timestamp": 1578766702705, "ltp": 1.62, "tv": 2035.73, "trd": NaN, "batb": [[0, 1.61, 101.69]], "batl": NaN}, {"timestamp": 1578766703710, "ltp": 1.62, "tv": 2035.73, "trd": NaN, "batb": [[0, 1.61, 87.3]], "batl": NaN}, {"timestamp": 1578766708810, "ltp": 1.62, "tv": 2035.73, "trd": NaN, "batb": [[0, 1.61, 101.69]], "batl": NaN}, {"timestamp": 1578766709804, "ltp": 1.62, "tv": 2035.73, "trd": NaN, "batb": [[0, 1.61, 87.3]], "batl": NaN}, {"timestamp": 1578766710833, "ltp": 1.62, "tv": 2035.73, "trd": NaN, "batb": [[0, 1.61, 101.69]], "batl": NaN}, {"timestamp": 1578766711923, "ltp": 1.62, "tv": 2035.73, "trd": NaN, "batb": [[0, 1.61, 87.3]], "batl": NaN}, {"timestamp": 1578766712948, "ltp": 1.62, "tv": 2035.73, "trd": NaN, "batb": [[0, 1.61, 101.69]], "batl": NaN}, {"timestamp": 1578766713843, "ltp": 1.62, "tv": 2035.73, "trd": NaN, "batb": [[0, 1.61, 87.3]], "batl": NaN}, {"timestamp": 1578766714804, "ltp": 1.62, "tv": 2035.73, "trd": NaN, "batb": [[0, 1.61, 101.69]], "batl": NaN}, {"timestamp": 1578766715816, "ltp": 1.62, "tv": 2035.73, "trd": NaN, "batb": [[0, 1.61, 87.3]], "batl": NaN}, {"timestamp": 1578766718848, "ltp": 1.62, "tv": 2035.73, "trd": NaN, "batb": [[0, 1.61, 101.69]], "batl": NaN}, {"timestamp": 1578766719434, "ltp": 1.62, "tv": 2035.73, "trd": NaN, "batb": [[0, 1.61, 87.3]], "batl": NaN}, {"timestamp": 1578766720913, "ltp": 1.62, "tv": 2035.73, "trd": NaN, "batb": [[0, 1.61, 101.69]], "batl": NaN}, {"timestamp": 1578766721929, "ltp": 1.62, "tv": 2035.73, "trd": NaN, "batb": [[0, 1.61, 87.3]], "batl": NaN}, {"timestamp": 1578766723748, "ltp": 1.62, "tv": 2035.73, "trd": NaN, "batb": [[0, 1.61, 101.69]], "batl": NaN}, {"timestamp": 1578766724439, "ltp": 1.62, "tv": 2035.73, "trd": NaN, "batb": [[0, 1.61, 87.3]], "batl": NaN}, {"timestamp": 1578766725866, "ltp": 1.62, "tv": 2035.73, "trd": NaN, "batb": [[0, 1.61, 101.69]], "batl": NaN}, {"timestamp": 1578766726865, "ltp": 1.62, "tv": 2035.73, "trd": NaN, "batb": [[0, 1.61, 87.3]], "batl": NaN}, {"timestamp": 1578766727379, "ltp": 1.62, "tv": 2035.73, "trd": NaN, "batb": [[0, 1.61, 101.69]], "batl": NaN}, {"timestamp": 1578766728546, "ltp": 1.62, "tv": 2035.73, "trd": NaN, "batb": [[0, 1.61, 87.3]], "batl": NaN}, {"timestamp": 1578766732056, "ltp": 1.62, "tv": 2035.73, "trd": NaN, "batb": [[0, 1.61, 101.69]], "batl": NaN}, {"timestamp": 1578766732857, "ltp": 1.62, "tv": 2035.73, "trd": NaN, "batb": [[0, 1.61, 87.3]], "batl": NaN}, {"timestamp": 1578766734654, "ltp": 1.62, "tv": 2035.73, "trd": NaN, "batb": [[0, 1.61, 101.69]], "batl": NaN}, {"timestamp": 1578766736026, "ltp": 1.62, "tv": 2035.73, "trd": NaN, "batb": [[0, 1.61, 87.3]], "batl": NaN}, {"timestamp": 1578766740865, "ltp": 1.62, "tv": 2035.73, "trd": NaN, "batb": [[0, 1.61, 101.69]], "batl": NaN}, {"timestamp": 1578766741976, "ltp": 1.62, "tv": 2035.73, "trd": NaN, "batb": [[0, 1.61, 87.3]], "batl": NaN}, {"timestamp": 1578766742880, "ltp": 1.62, "tv": 2056.19, "trd": [[1.62, 308.9]], "batb": NaN, "batl": [[0, 1.62, 250.44]]}, {"timestamp": 1578766744985, "ltp": 1.62, "tv": 2056.19, "trd": NaN, "batb": [[0, 1.61, 101.29]], "batl": NaN}, {"timestamp": 1578766746056, "ltp": 1.62, "tv": 2056.19, "trd": NaN, "batb": [[0, 1.61, 87.3]], "batl": NaN}, {"timestamp": 1578766746963, "ltp": 1.62, "tv": 2056.19, "trd": NaN, "batb": [[0, 1.61, 101.29]], "batl": NaN}, {"timestamp": 1578766747977, "ltp": 1.62, "tv": 2056.19, "trd": NaN, "batb": [[0, 1.61, 87.3]], "batl": NaN}, {"timestamp": 1578766751151, "ltp": 1.62, "tv": 2056.19, "trd": NaN, "batb": [[0, 1.61, 101.29]], "batl": NaN}, {"timestamp": 1578766752954, "ltp": 1.62, "tv": 2056.19, "trd": NaN, "batb": [[0, 1.61, 87.3]], "batl": NaN}, {"timestamp": 1578766754002, "ltp": 1.62, "tv": 2056.19, "trd": NaN, "batb": [[0, 1.61, 101.29]], "batl": NaN}, {"timestamp": 1578766755382, "ltp": 1.62, "tv": 2056.19, "trd": NaN, "batb": [[0, 1.61, 87.3]], "batl": NaN}, {"timestamp": 1578766757987, "ltp": 1.62, "tv": 2056.19, "trd": NaN, "batb": [[0, 1.61, 101.29]], "batl": NaN}, {"timestamp": 1578766759190, "ltp": 1.62, "tv": 2056.19, "trd": NaN, "batb": [[0, 1.61, 87.3]], "batl": NaN}, {"timestamp": 1578766760786, "ltp": 1.62, "tv": 2056.19, "trd": NaN, "batb": [[0, 1.61, 101.29]], "batl": NaN}, {"timestamp": 1578766761678, "ltp": 1.62, "tv": 2056.19, "trd": NaN, "batb": [[0, 1.61, 87.3]], "batl": NaN}, {"timestamp": 1578766763903, "ltp": 1.62, "tv": 2056.19, "trd": NaN, "batb": [[0, 1.61, 101.29]], "batl": NaN}, {"timestamp": 1578766764862, "ltp": 1.62, "tv": 2056.19, "trd": NaN, "batb": [[0, 1.61, 87.3]], "batl": NaN}, {"timestamp": 1578766768989, "ltp": 1.62, "tv": 2056.19, "trd": NaN, "batb": [[0, 1.61, 101.29]], "batl": NaN}, {"timestamp": 1578766769678, "ltp": 1.62, "tv": 2056.19, "trd": NaN, "batb": [[0, 1.61, 87.3]], "batl": NaN}, {"timestamp": 1578766771695, "ltp": 1.62, "tv": 2056.19, "trd": NaN, "batb": [[0, 1.61, 101.29]], "batl": NaN}, {"timestamp": 1578766772694, "ltp": 1.62, "tv": 2056.19, "trd": NaN, "batb": [[0, 1.61, 87.3]], "batl": NaN}, {"timestamp": 1578766773381, "ltp": 1.62, "tv": 2056.19, "trd": NaN, "batb": [[0, 1.61, 101.29]], "batl": NaN}, {"timestamp": 1578766774796, "ltp": 1.62, "tv": 2056.19, "trd": NaN, "batb": [[0, 1.61, 87.3]], "batl": NaN}, {"timestamp": 1578766775807, "ltp": 1.62, "tv": 2056.19, "trd": NaN, "batb": [[0, 1.61, 101.29]], "batl": NaN}, {"timestamp": 1578766776495, "ltp": 1.62, "tv": 2056.19, "trd": NaN, "batb": [[0, 1.61, 87.3]], "batl": NaN}, {"timestamp": 1578766780817, "ltp": 1.62, "tv": 2056.19, "trd": NaN, "batb": [[0, 1.61, 101.29]], "batl": NaN}, {"timestamp": 1578766781910, "ltp": 1.62, "tv": 2056.19, "trd": NaN, "batb": [[0, 1.61, 87.3]], "batl": NaN}, {"timestamp": 1578766783810, "ltp": 1.62, "tv": 2056.19, "trd": NaN, "batb": [[0, 1.61, 101.29]], "batl": NaN}, {"timestamp": 1578766784809, "ltp": 1.62, "tv": 2056.19, "trd": NaN, "batb": [[0, 1.61, 87.3]], "batl": NaN}, {"timestamp": 1578766786922, "ltp": 1.62, "tv": 2056.19, "trd": NaN, "batb": [[0, 1.61, 101.29]], "batl": NaN}, {"timestamp": 1578766787621, "ltp": 1.62, "tv": 2056.19, "trd": NaN, "batb": [[0, 1.61, 87.3]], "batl": NaN}, {"timestamp": 1578766790929, "ltp": 1.62, "tv": 2056.19, "trd": NaN, "batb": [[0, 1.61, 101.29]], "batl": NaN}, {"timestamp": 1578766792015, "ltp": 1.62, "tv": 2056.19, "trd": NaN, "batb": [[0, 1.61, 87.3]], "batl": NaN}, {"timestamp": 1578766793020, "ltp": 1.62, "tv": 2056.19, "trd": NaN, "batb": [[0, 1.61, 101.29]], "batl": NaN}, {"timestamp": 1578766794027, "ltp": 1.62, "tv": 2056.19, "trd": NaN, "batb": [[0, 1.61, 87.3]], "batl": NaN}, {"timestamp": 1578766796521, "ltp": 1.62, "tv": 2056.19, "trd": NaN, "batb": [[0, 1.61, 101.29]], "batl": NaN}, {"timestamp": 1578766798048, "ltp": 1.62, "tv": 2056.19, "trd": NaN, "batb": [[0, 1.61, 87.3]], "batl": NaN}, {"timestamp": 1578766800024, "ltp": 1.62, "tv": 2056.19, "trd": NaN, "batb": [[0, 1.61, 101.29]], "batl": NaN}, {"timestamp": 1578766800616, "ltp": 1.62, "tv": 2056.19, "trd": NaN, "batb": [[0, 1.61, 87.3]], "batl": NaN}, {"timestamp": 1578766801624, "ltp": 1.62, "tv": 2056.19, "trd": NaN, "batb": [[0, 1.61, 101.29]], "batl": NaN}, {"timestamp": 1578766802934, "ltp": 1.62, "tv": 2056.19, "trd": NaN, "batb": [[0, 1.61, 87.3]], "batl": NaN}, {"timestamp": 1578766804047, "ltp": 1.62, "tv": 2056.19, "trd": NaN, "batb": [[0, 1.61, 101.29]], "batl": NaN}, {"timestamp": 1578766804738, "ltp": 1.62, "tv": 2056.19, "trd": NaN, "batb": [[0, 1.61, 87.3]], "batl": NaN}, {"timestamp": 1578766805744, "ltp": 1.62, "tv": 2056.19, "trd": NaN, "batb": [[0, 1.61, 101.29]], "batl": NaN}, {"timestamp": 1578766806325, "ltp": 1.62, "tv": 2056.19, "trd": NaN, "batb": [[0, 1.61, 87.3]], "batl": NaN}, {"timestamp": 1578766807836, "ltp": 1.62, "tv": 2056.19, "trd": NaN, "batb": [[0, 1.61, 101.29]], "batl": NaN}, {"timestamp": 1578766808856, "ltp": 1.62, "tv": 2056.19, "trd": NaN, "batb": [[0, 1.61, 87.3]], "batl": NaN}, {"timestamp": 1578766809800, "ltp": 1.62, "tv": 2056.19, "trd": NaN, "batb": [[0, 1.61, 101.29]], "batl": NaN}, {"timestamp": 1578766810817, "ltp": 1.62, "tv": 2056.19, "trd": NaN, "batb": [[0, 1.61, 87.3]], "batl": NaN}, {"timestamp": 1578766813765, "ltp": 1.62, "tv": 2056.19, "trd": NaN, "batb": [[0, 1.61, 101.29]], "batl": NaN}, {"timestamp": 1578766814732, "ltp": 1.62, "tv": 2056.19, "trd": NaN, "batb": [[0, 1.61, 87.3]], "batl": NaN}, {"timestamp": 1578766815850, "ltp": 1.62, "tv": 2056.19, "trd": NaN, "batb": [[0, 1.61, 101.29]], "batl": NaN}, {"timestamp": 1578766816343, "ltp": 1.62, "tv": 2056.19, "trd": NaN, "batb": [[0, 1.61, 87.3]], "batl": NaN}, {"timestamp": 1578766817865, "ltp": 1.62, "tv": 2056.19, "trd": NaN, "batb": [[0, 1.61, 101.29]], "batl": NaN}, {"timestamp": 1578766818933, "ltp": 1.62, "tv": 2056.19, "trd": NaN, "batb": [[0, 1.61, 87.3]], "batl": NaN}, {"timestamp": 1578766819668, "ltp": 1.62, "tv": 2056.19, "trd": NaN, "batb": [[0, 1.61, 101.29]], "batl": NaN}, {"timestamp": 1578766820955, "ltp": 1.62, "tv": 2056.19, "trd": NaN, "batb": [[0, 1.61, 87.3]], "batl": NaN}, {"timestamp": 1578766821759, "ltp": 1.62, "tv": 2056.19, "trd": NaN, "batb": [[0, 1.61, 101.29]], "batl": NaN}, {"timestamp": 1578766822939, "ltp": 1.62, "tv": 2056.19, "trd": NaN, "batb": [[0, 1.61, 87.3]], "batl": NaN}, {"timestamp": 1578766823949, "ltp": 1.62, "tv": 2056.19, "trd": NaN, "batb": [[0, 1.61, 101.29]], "batl": NaN}, {"timestamp": 1578766824828, "ltp": 1.62, "tv": 2056.19, "trd": NaN, "batb": [[0, 1.61, 87.3]], "batl": NaN}, {"timestamp": 1578766828972, "ltp": 1.62, "tv": 2056.19, "trd": NaN, "batb": [[2, 1.59, 437.09]], "batl": NaN}, {"timestamp": 1578766829570, "ltp": 1.62, "tv": 2056.19, "trd": NaN, "batb": [[0, 1.61, 114.88]], "batl": NaN}, {"timestamp": 1578766830361, "ltp": 1.62, "tv": 2056.19, "trd": NaN, "batb": [[0, 1.61, 87.3]], "batl": NaN}, {"timestamp": 1578766831983, "ltp": 1.62, "tv": 2056.19, "trd": NaN, "batb": [[0, 1.61, 114.88]], "batl": NaN}, {"timestamp": 1578766832990, "ltp": 1.62, "tv": 2056.19, "trd": NaN, "batb": [[0, 1.61, 87.3]], "batl": NaN}, {"timestamp": 1578766833482, "ltp": 1.62, "tv": 2056.19, "trd": NaN, "batb": [[0, 1.61, 114.88]], "batl": NaN}, {"timestamp": 1578766835970, "ltp": 1.62, "tv": 2056.19, "trd": NaN, "batb": [[0, 1.61, 87.3]], "batl": NaN}, {"timestamp": 1578766838772, "ltp": 1.62, "tv": 2056.19, "trd": NaN, "batb": [[0, 1.61, 114.88]], "batl": NaN}, {"timestamp": 1578766839892, "ltp": 1.62, "tv": 2056.19, "trd": NaN, "batb": [[0, 1.61, 87.3]], "batl": NaN}, {"timestamp": 1578766841001, "ltp": 1.62, "tv": 2056.19, "trd": NaN, "batb": [[0, 1.61, 114.88]], "batl": NaN}, {"timestamp": 1578766841875, "ltp": 1.62, "tv": 2056.19, "trd": NaN, "batb": [[0, 1.61, 87.3]], "batl": NaN}, {"timestamp": 1578766843571, "ltp": 1.62, "tv": 2056.19, "trd": NaN, "batb": [[0, 1.61, 114.88]], "batl": NaN}, {"timestamp": 1578766844573, "ltp": 1.62, "tv": 2056.19, "trd": NaN, "batb": [[0, 1.61, 87.3]], "batl": NaN}, {"timestamp": 1578766848022, "ltp": 1.62, "tv": 2056.19, "trd": NaN, "batb": [[0, 1.61, 114.88]], "batl": NaN}, {"timestamp": 1578766848721, "ltp": 1.62, "tv": 2056.19, "trd": NaN, "batb": [[0, 1.61, 87.3]], "batl": NaN}, {"timestamp": 1578766851173, "ltp": 1.62, "tv": 2056.19, "trd": NaN, "batb": [[0, 1.61, 114.88]], "batl": NaN}, {"timestamp": 1578766852187, "ltp": 1.62, "tv": 2056.19, "trd": NaN, "batb": [[0, 1.61, 87.3]], "batl": NaN}, {"timestamp": 1578766854518, "ltp": 1.62, "tv": 2056.19, "trd": NaN, "batb": [[0, 1.61, 114.88]], "batl": NaN}, {"timestamp": 1578766855438, "ltp": 1.62, "tv": 2056.19, "trd": NaN, "batb": [[0, 1.61, 87.3]], "batl": NaN}, {"timestamp": 1578766858000, "ltp": 1.62, "tv": 2056.19, "trd": NaN, "batb": [[0, 1.61, 114.88], [2, 1.59, 98.15]], "batl": NaN}, {"timestamp": 1578766859012, "ltp": 1.62, "tv": 2056.19, "trd": NaN, "batb": [[0, 1.61, 87.3]], "batl": NaN}, {"timestamp": 1578766859919, "ltp": 1.62, "tv": 2056.19, "trd": NaN, "batb": [[0, 1.61, 101.29]], "batl": NaN}, {"timestamp": 1578766860727, "ltp": 1.62, "tv": 2056.19, "trd": NaN, "batb": [[0, 1.61, 87.3]], "batl": NaN}, {"timestamp": 1578766862607, "ltp": 1.62, "tv": 2056.19, "trd": NaN, "batb": [[0, 1.61, 101.29]], "batl": NaN}, {"timestamp": 1578766863831, "ltp": 1.62, "tv": 2056.19, "trd": NaN, "batb": [[0, 1.61, 87.3]], "batl": NaN}, {"timestamp": 1578766866036, "ltp": 1.62, "tv": 2056.19, "trd": NaN, "batb": [[0, 1.61, 101.29]], "batl": NaN}, {"timestamp": 1578766868025, "ltp": 1.62, "tv": 2056.19, "trd": NaN, "batb": [[0, 1.61, 87.3]], "batl": NaN}, {"timestamp": 1578766869090, "ltp": 1.62, "tv": 2056.19, "trd": NaN, "batb": [[0, 1.61, 101.29]], "batl": NaN}, {"timestamp": 1578766870696, "ltp": 1.62, "tv": 2056.19, "trd": NaN, "batb": [[0, 1.61, 87.3]], "batl": NaN}, {"timestamp": 1578766873442, "ltp": 1.62, "tv": 2056.19, "trd": NaN, "batb": [[0, 1.61, 101.29]], "batl": NaN}, {"timestamp": 1578766875235, "ltp": 1.62, "tv": 2056.19, "trd": NaN, "batb": [[0, 1.61, 87.3]], "batl": NaN}, {"timestamp": 1578766877001, "ltp": 1.62, "tv": 2056.19, "trd": NaN, "batb": [[0, 1.61, 101.29]], "batl": NaN}, {"timestamp": 1578766878228, "ltp": 1.62, "tv": 2056.19, "trd": NaN, "batb": [[0, 1.61, 87.3]], "batl": NaN}, {"timestamp": 1578766880306, "ltp": 1.62, "tv": 2056.19, "trd": NaN, "batb": [[0, 1.61, 101.29]], "batl": NaN}, {"timestamp": 1578766881745, "ltp": 1.62, "tv": 2056.19, "trd": NaN, "batb": [[0, 1.61, 87.3]], "batl": NaN}, {"timestamp": 1578766883927, "ltp": 1.62, "tv": 2056.19, "trd": NaN, "batb": [[0, 1.61, 101.29]], "batl": NaN}, {"timestamp": 1578766884450, "ltp": 1.62, "tv": 2056.19, "trd": NaN, "batb": [[0, 1.61, 87.3]], "batl": NaN}, {"timestamp": 1578766886443, "ltp": 1.62, "tv": 2056.19, "trd": NaN, "batb": [[0, 1.61, 101.29]], "batl": NaN}, {"timestamp": 1578766887620, "ltp": 1.62, "tv": 2056.19, "trd": NaN, "batb": [[0, 1.61, 87.3]], "batl": NaN}, {"timestamp": 1578766889508, "ltp": 1.62, "tv": 2056.19, "trd": NaN, "batb": [[0, 1.61, 101.29]], "batl": NaN}, {"timestamp": 1578766891048, "ltp": 1.62, "tv": 2056.19, "trd": NaN, "batb": [[0, 1.61, 87.3]], "batl": NaN}, {"timestamp": 1578766891850, "ltp": 1.62, "tv": 2056.19, "trd": NaN, "batb": [[0, 1.61, 101.29]], "batl": NaN}, {"timestamp": 1578766892809, "ltp": 1.62, "tv": 2056.19, "trd": NaN, "batb": [[0, 1.61, 87.3]], "batl": NaN}, {"timestamp": 1578766894449, "ltp": 1.62, "tv": 2056.19, "trd": NaN, "batb": [[0, 1.61, 101.29]], "batl": NaN}, {"timestamp": 1578766895520, "ltp": 1.62, "tv": 2056.19, "trd": NaN, "batb": [[0, 1.61, 87.3]], "batl": NaN}, {"timestamp": 1578766897321, "ltp": 1.62, "tv": 2056.19, "trd": NaN, "batb": [[0, 1.61, 101.29]], "batl": NaN}, {"timestamp": 1578766898450, "ltp": 1.62, "tv": 2056.19, "trd": NaN, "batb": [[0, 1.61, 87.3]], "batl": NaN}, {"timestamp": 1578766900521, "ltp": 1.62, "tv": 2056.19, "trd": NaN, "batb": [[0, 1.61, 101.29]], "batl": NaN}, {"timestamp": 1578766901429, "ltp": 1.62, "tv": 2056.19, "trd": NaN, "batb": [[0, 1.61, 87.3]], "batl": NaN}, {"timestamp": 1578766903668, "ltp": 1.62, "tv": 2056.19, "trd": NaN, "batb": [[0, 1.61, 101.29]], "batl": NaN}, {"timestamp": 1578766906033, "ltp": 1.62, "tv": 2056.19, "trd": NaN, "batb": [[0, 1.61, 87.3]], "batl": NaN}, {"timestamp": 1578766906675, "ltp": 1.62, "tv": 2056.19, "trd": NaN, "batb": [[0, 1.61, 101.29]], "batl": NaN}, {"timestamp": 1578766907944, "ltp": 1.62, "tv": 2056.19, "trd": NaN, "batb": [[0, 1.61, 87.3]], "batl": NaN}, {"timestamp": 1578766909889, "ltp": 1.62, "tv": 2056.19, "trd": NaN, "batb": [[0, 1.61, 101.29]], "batl": NaN}, {"timestamp": 1578766910796, "ltp": 1.62, "tv": 2056.19, "trd": NaN, "batb": [[0, 1.61, 87.3]], "batl": NaN}, {"timestamp": 1578766915702, "ltp": 1.62, "tv": 2056.19, "trd": NaN, "batb": [[0, 1.61, 101.29]], "batl": NaN}, {"timestamp": 1578766916717, "ltp": 1.62, "tv": 2056.19, "trd": NaN, "batb": [[0, 1.61, 87.3]], "batl": NaN}, {"timestamp": 1578766918963, "ltp": 1.62, "tv": 2056.19, "trd": NaN, "batb": [[0, 1.61, 101.29]], "batl": NaN}, {"timestamp": 1578766919986, "ltp": 1.62, "tv": 2056.19, "trd": NaN, "batb": [[0, 1.61, 87.3]], "batl": NaN}, {"timestamp": 1578766923108, "ltp": 1.62, "tv": 2056.19, "trd": NaN, "batb": [[0, 1.61, 101.29]], "batl": NaN}, {"timestamp": 1578766924177, "ltp": 1.62, "tv": 2056.19, "trd": NaN, "batb": [[0, 1.61, 87.3]], "batl": NaN}, {"timestamp": 1578766927696, "ltp": 1.62, "tv": 2056.19, "trd": NaN, "batb": [[0, 1.61, 101.29]], "batl": NaN}, {"timestamp": 1578766928808, "ltp": 1.62, "tv": 2056.19, "trd": NaN, "batb": [[0, 1.61, 87.3]], "batl": NaN}, {"timestamp": 1578766930788, "ltp": 1.62, "tv": 2056.19, "trd": NaN, "batb": [[0, 1.61, 101.29]], "batl": NaN}, {"timestamp": 1578766931810, "ltp": 1.62, "tv": 2056.19, "trd": NaN, "batb": [[0, 1.61, 87.3]], "batl": NaN}, {"timestamp": 1578766933502, "ltp": 1.62, "tv": 2056.19, "trd": NaN, "batb": [[0, 1.61, 101.29]], "batl": NaN}, {"timestamp": 1578766934617, "ltp": 1.62, "tv": 2056.19, "trd": NaN, "batb": [[0, 1.61, 87.3]], "batl": NaN}, {"timestamp": 1578766936658, "ltp": 1.62, "tv": 2056.19, "trd": NaN, "batb": [[0, 1.61, 101.29]], "batl": NaN}, {"timestamp": 1578766937834, "ltp": 1.62, "tv": 2056.19, "trd": NaN, "batb": [[0, 1.61, 87.3]], "batl": NaN}, {"timestamp": 1578766939901, "ltp": 1.62, "tv": 2056.19, "trd": NaN, "batb": [[0, 1.61, 101.29]], "batl": NaN}, {"timestamp": 1578766940797, "ltp": 1.62, "tv": 2056.19, "trd": NaN, "batb": [[0, 1.61, 87.3]], "batl": NaN}, {"timestamp": 1578766942891, "ltp": 1.62, "tv": 2056.19, "trd": NaN, "batb": [[0, 1.61, 101.29]], "batl": NaN}, {"timestamp": 1578766943891, "ltp": 1.62, "tv": 2056.19, "trd": NaN, "batb": [[0, 1.61, 87.3]], "batl": NaN}, {"timestamp": 1578766944898, "ltp": 1.62, "tv": 2056.19, "trd": NaN, "batb": [[0, 1.61, 101.29]], "batl": NaN}, {"timestamp": 1578766946334, "ltp": 1.62, "tv": 2056.19, "trd": NaN, "batb": [[0, 1.61, 87.3]], "batl": NaN}, {"timestamp": 1578766949034, "ltp": 1.62, "tv": 2056.19, "trd": NaN, "batb": [[0, 1.61, 101.29]], "batl": NaN}, {"timestamp": 1578766949624, "ltp": 1.62, "tv": 2056.19, "trd": NaN, "batb": [[0, 1.61, 87.3]], "batl": NaN}, {"timestamp": 1578766952032, "ltp": 1.62, "tv": 2056.19, "trd": NaN, "batb": [[0, 1.61, 101.29]], "batl": NaN}, {"timestamp": 1578766952816, "ltp": 1.62, "tv": 2056.19, "trd": NaN, "batb": [[0, 1.61, 87.3]], "batl": NaN}, {"timestamp": 1578766954512, "ltp": 1.62, "tv": 2056.19, "trd": NaN, "batb": [[0, 1.61, 101.29]], "batl": NaN}, {"timestamp": 1578766955798, "ltp": 1.62, "tv": 2056.19, "trd": NaN, "batb": [[0, 1.61, 87.3]], "batl": NaN}, {"timestamp": 1578766957981, "ltp": 1.62, "tv": 2056.19, "trd": NaN, "batb": [[0, 1.61, 101.29]], "batl": NaN}, {"timestamp": 1578766958611, "ltp": 1.62, "tv": 2056.19, "trd": NaN, "batb": [[0, 1.61, 87.3]], "batl": NaN}, {"timestamp": 1578766961012, "ltp": 1.62, "tv": 2056.19, "trd": NaN, "batb": [[0, 1.61, 101.29]], "batl": NaN}, {"timestamp": 1578766961823, "ltp": 1.62, "tv": 2056.19, "trd": NaN, "batb": [[0, 1.61, 87.3]], "batl": NaN}, {"timestamp": 1578766963581, "ltp": 1.62, "tv": 2056.19, "trd": NaN, "batb": [[0, 1.61, 101.29]], "batl": NaN}, {"timestamp": 1578766964686, "ltp": 1.62, "tv": 2056.19, "trd": NaN, "batb": [[0, 1.61, 87.3]], "batl": NaN}, {"timestamp": 1578766965924, "ltp": 1.62, "tv": 2056.19, "trd": NaN, "batb": [[0, 1.61, 101.29]], "batl": NaN}, {"timestamp": 1578766966830, "ltp": 1.62, "tv": 2056.19, "trd": NaN, "batb": [[0, 1.61, 87.3]], "batl": NaN}, {"timestamp": 1578766970008, "ltp": 1.62, "tv": 2056.19, "trd": NaN, "batb": [[0, 1.61, 101.29]], "batl": NaN}, {"timestamp": 1578766970843, "ltp": 1.62, "tv": 2056.19, "trd": NaN, "batb": [[0, 1.61, 87.3]], "batl": NaN}, {"timestamp": 1578766972918, "ltp": 1.62, "tv": 2056.19, "trd": NaN, "batb": [[0, 1.61, 101.29]], "batl": NaN}, {"timestamp": 1578766975373, "ltp": 1.62, "tv": 2056.19, "trd": NaN, "batb": [[0, 1.61, 87.3]], "batl": NaN}, {"timestamp": 1578766977969, "ltp": 1.62, "tv": 2056.19, "trd": NaN, "batb": [[0, 1.61, 101.29]], "batl": NaN}, {"timestamp": 1578766978666, "ltp": 1.62, "tv": 2056.19, "trd": NaN, "batb": [[0, 1.61, 87.3]], "batl": NaN}, {"timestamp": 1578766980495, "ltp": 1.62, "tv": 2056.19, "trd": NaN, "batb": [[0, 1.61, 101.29]], "batl": NaN}, {"timestamp": 1578766981557, "ltp": 1.62, "tv": 2056.19, "trd": NaN, "batb": [[0, 1.61, 87.3]], "batl": NaN}, {"timestamp": 1578766984786, "ltp": 1.62, "tv": 2056.19, "trd": NaN, "batb": [[0, 1.61, 101.29]], "batl": NaN}, {"timestamp": 1578766985711, "ltp": 1.62, "tv": 2056.19, "trd": NaN, "batb": [[0, 1.61, 87.3]], "batl": NaN}, {"timestamp": 1578766986986, "ltp": 1.62, "tv": 2056.19, "trd": NaN, "batb": [[0, 1.61, 101.29]], "batl": NaN}, {"timestamp": 1578766987935, "ltp": 1.62, "tv": 2056.19, "trd": NaN, "batb": [[0, 1.61, 87.3]], "batl": NaN}, {"timestamp": 1578766990872, "ltp": 1.62, "tv": 2056.19, "trd": NaN, "batb": [[0, 1.61, 101.29]], "batl": NaN}, {"timestamp": 1578766991876, "ltp": 1.62, "tv": 2056.19, "trd": NaN, "batb": [[0, 1.61, 87.3]], "batl": NaN}, {"timestamp": 1578766993569, "ltp": 1.62, "tv": 2056.19, "trd": NaN, "batb": [[0, 1.61, 101.29]], "batl": NaN}, {"timestamp": 1578766994895, "ltp": 1.62, "tv": 2056.19, "trd": NaN, "batb": [[0, 1.61, 87.3]], "batl": NaN}, {"timestamp": 1578766996000, "ltp": 1.62, "tv": 2056.19, "trd": NaN, "batb": [[0, 1.61, 101.29]], "batl": NaN}, {"timestamp": 1578766997004, "ltp": 1.62, "tv": 2056.19, "trd": NaN, "batb": [[0, 1.61, 87.3]], "batl": NaN}, {"timestamp": 1578766998482, "ltp": 1.62, "tv": 2056.19, "trd": NaN, "batb": [[0, 1.61, 101.29]], "batl": NaN}, {"timestamp": 1578766999700, "ltp": 1.62, "tv": 2056.19, "trd": NaN, "batb": [[0, 1.61, 87.3]], "batl": NaN}, {"timestamp": 1578767004977, "ltp": 1.62, "tv": 2056.19, "trd": NaN, "batb": [[0, 1.61, 101.29]], "batl": NaN}, {"timestamp": 1578767005889, "ltp": 1.62, "tv": 2056.19, "trd": NaN, "batb": [[0, 1.61, 87.3]], "batl": NaN}, {"timestamp": 1578767007104, "ltp": 1.62, "tv": 2056.19, "trd": NaN, "batb": [[0, 1.61, 101.29]], "batl": NaN}, {"timestamp": 1578767009010, "ltp": 1.62, "tv": 2056.19, "trd": NaN, "batb": [[0, 1.61, 87.3]], "batl": NaN}, {"timestamp": 1578767011689, "ltp": 1.62, "tv": 2056.19, "trd": NaN, "batb": [[0, 1.61, 101.29]], "batl": NaN}, {"timestamp": 1578767012902, "ltp": 1.62, "tv": 2056.19, "trd": NaN, "batb": [[0, 1.61, 87.3]], "batl": NaN}, {"timestamp": 1578767018785, "ltp": 1.62, "tv": 2056.19, "trd": NaN, "batb": [[0, 1.61, 101.29]], "batl": NaN}, {"timestamp": 1578767020013, "ltp": 1.62, "tv": 2056.19, "trd": NaN, "batb": [[0, 1.61, 87.3]], "batl": NaN}, {"timestamp": 1578767020529, "ltp": 1.62, "tv": 2056.19, "trd": NaN, "batb": [[0, 1.61, 101.29]], "batl": NaN}, {"timestamp": 1578767021210, "ltp": 1.62, "tv": 2056.19, "trd": NaN, "batb": [[0, 1.61, 87.3]], "batl": NaN}, {"timestamp": 1578767023320, "ltp": 1.62, "tv": 2056.19, "trd": NaN, "batb": [[0, 1.61, 101.29]], "batl": NaN}, {"timestamp": 1578767024226, "ltp": 1.62, "tv": 2056.19, "trd": NaN, "batb": [[0, 1.61, 87.3]], "batl": NaN}, {"timestamp": 1578767026011, "ltp": 1.62, "tv": 2056.19, "trd": NaN, "batb": [[0, 1.61, 101.29]], "batl": NaN}, {"timestamp": 1578767026912, "ltp": 1.62, "tv": 2056.19, "trd": NaN, "batb": [[0, 1.61, 87.3]], "batl": NaN}, {"timestamp": 1578767028813, "ltp": 1.62, "tv": 2056.19, "trd": NaN, "batb": [[0, 1.61, 101.29]], "batl": NaN}, {"timestamp": 1578767029815, "ltp": 1.62, "tv": 2056.19, "trd": NaN, "batb": [[0, 1.61, 87.3]], "batl": NaN}, {"timestamp": 1578767033831, "ltp": 1.62, "tv": 2056.19, "trd": NaN, "batb": [[0, 1.61, 101.29]], "batl": NaN}, {"timestamp": 1578767034442, "ltp": 1.62, "tv": 2056.19, "trd": NaN, "batb": [[0, 1.61, 87.3]], "batl": NaN}, {"timestamp": 1578767036534, "ltp": 1.62, "tv": 2056.19, "trd": NaN, "batb": [[0, 1.61, 101.29]], "batl": NaN}, {"timestamp": 1578767037747, "ltp": 1.62, "tv": 2056.19, "trd": NaN, "batb": [[0, 1.61, 87.3]], "batl": NaN}, {"timestamp": 1578767042016, "ltp": 1.62, "tv": 2056.19, "trd": NaN, "batb": [[0, 1.61, 101.29]], "batl": NaN}, {"timestamp": 1578767042962, "ltp": 1.62, "tv": 2056.19, "trd": NaN, "batb": [[0, 1.61, 87.3]], "batl": NaN}, {"timestamp": 1578767043919, "ltp": 1.62, "tv": 2056.19, "trd": NaN, "batb": [[0, 1.61, 101.29]], "batl": NaN}, {"timestamp": 1578767045046, "ltp": 1.62, "tv": 2056.19, "trd": NaN, "batb": [[0, 1.61, 87.3]], "batl": NaN}, {"timestamp": 1578767045436, "ltp": 1.62, "tv": 2056.19, "trd": NaN, "batb": [[0, 1.61, 101.29]], "batl": NaN}, {"timestamp": 1578767046756, "ltp": 1.62, "tv": 2056.19, "trd": NaN, "batb": [[0, 1.61, 87.3]], "batl": NaN}, {"timestamp": 1578767048465, "ltp": 1.62, "tv": 2056.19, "trd": NaN, "batb": [[0, 1.61, 101.29]], "batl": NaN}, {"timestamp": 1578767050026, "ltp": 1.62, "tv": 2056.19, "trd": NaN, "batb": [[0, 1.61, 87.3]], "batl": NaN}, {"timestamp": 1578767050927, "ltp": 1.62, "tv": 2056.19, "trd": NaN, "batb": [[0, 1.61, 101.29]], "batl": NaN}, {"timestamp": 1578767051770, "ltp": 1.62, "tv": 2056.19, "trd": NaN, "batb": [[0, 1.61, 87.3]], "batl": NaN}, {"timestamp": 1578767053250, "ltp": 1.62, "tv": 2056.19, "trd": NaN, "batb": [[0, 1.61, 101.29]], "batl": NaN}, {"timestamp": 1578767054978, "ltp": 1.62, "tv": 2056.19, "trd": NaN, "batb": [[0, 1.61, 87.3]], "batl": NaN}, {"timestamp": 1578767056247, "ltp": 1.62, "tv": 2056.19, "trd": NaN, "batb": [[0, 1.61, 101.29]], "batl": NaN}, {"timestamp": 1578767057379, "ltp": 1.62, "tv": 2056.19, "trd": NaN, "batb": [[0, 1.61, 87.3]], "batl": NaN}, {"timestamp": 1578767059399, "ltp": 1.62, "tv": 2056.19, "trd": NaN, "batb": [[0, 1.61, 101.29]], "batl": NaN}, {"timestamp": 1578767060959, "ltp": 1.62, "tv": 2056.19, "trd": NaN, "batb": [[0, 1.61, 87.3]], "batl": NaN}, {"timestamp": 1578767061777, "ltp": 1.62, "tv": 2056.19, "trd": NaN, "batb": [[0, 1.61, 101.29]], "batl": NaN}, {"timestamp": 1578767062803, "ltp": 1.62, "tv": 2056.19, "trd": NaN, "batb": [[0, 1.61, 87.3]], "batl": NaN}, {"timestamp": 1578767065680, "ltp": 1.62, "tv": 2056.19, "trd": NaN, "batb": [[0, 1.61, 101.29]], "batl": NaN}, {"timestamp": 1578767066892, "ltp": 1.62, "tv": 2056.19, "trd": NaN, "batb": [[0, 1.61, 87.3]], "batl": NaN}, {"timestamp": 1578767067381, "ltp": 1.62, "tv": 2056.19, "trd": NaN, "batb": [[0, 1.61, 101.29]], "batl": NaN}, {"timestamp": 1578767068907, "ltp": 1.62, "tv": 2056.19, "trd": NaN, "batb": [[0, 1.61, 87.3]], "batl": NaN}, {"timestamp": 1578767069704, "ltp": 1.62, "tv": 2056.19, "trd": NaN, "batb": [[0, 1.61, 101.29]], "batl": [[1, 1.63, 998.37]]}, {"timestamp": 1578767070562, "ltp": 1.62, "tv": 2056.19, "trd": NaN, "batb": [[0, 1.61, 87.3]], "batl": NaN}, {"timestamp": 1578767073698, "ltp": 1.62, "tv": 2056.19, "trd": NaN, "batb": [[0, 1.61, 101.29]], "batl": NaN}, {"timestamp": 1578767074596, "ltp": 1.62, "tv": 2056.19, "trd": NaN, "batb": [[0, 1.61, 87.3]], "batl": NaN}, {"timestamp": 1578767075839, "ltp": 1.62, "tv": 2056.19, "trd": NaN, "batb": [[0, 1.61, 101.29]], "batl": NaN}, {"timestamp": 1578767076910, "ltp": 1.62, "tv": 2056.19, "trd": NaN, "batb": [[0, 1.61, 87.3]], "batl": NaN}, {"timestamp": 1578767078949, "ltp": 1.62, "tv": 2056.19, "trd": NaN, "batb": [[0, 1.61, 101.29]], "batl": NaN}, {"timestamp": 1578767079986, "ltp": 1.62, "tv": 2056.19, "trd": NaN, "batb": [[0, 1.61, 87.3]], "batl": NaN}, {"timestamp": 1578767080995, "ltp": 1.62, "tv": 2056.19, "trd": NaN, "batb": [[0, 1.61, 101.29]], "batl": NaN}, {"timestamp": 1578767081523, "ltp": 1.62, "tv": 2056.19, "trd": NaN, "batb": [[0, 1.61, 87.3]], "batl": NaN}, {"timestamp": 1578767082995, "ltp": 1.62, "tv": 2056.19, "trd": NaN, "batb": [[0, 1.61, 101.29]], "batl": NaN}, {"timestamp": 1578767083653, "ltp": 1.62, "tv": 2056.19, "trd": NaN, "batb": [[0, 1.61, 87.3]], "batl": NaN}, {"timestamp": 1578767085147, "ltp": 1.62, "tv": 2056.19, "trd": NaN, "batb": [[0, 1.61, 101.29]], "batl": NaN}, {"timestamp": 1578767086616, "ltp": 1.62, "tv": 2056.19, "trd": NaN, "batb": [[0, 1.61, 87.3]], "batl": NaN}, {"timestamp": 1578767090011, "ltp": 1.62, "tv": 2056.19, "trd": NaN, "batb": [[0, 1.61, 101.29]], "batl": NaN}, {"timestamp": 1578767090907, "ltp": 1.62, "tv": 2056.19, "trd": NaN, "batb": [[0, 1.61, 87.3]], "batl": NaN}, {"timestamp": 1578767093924, "ltp": 1.62, "tv": 2056.19, "trd": NaN, "batb": [[0, 1.61, 101.29]], "batl": NaN}, {"timestamp": 1578767094834, "ltp": 1.62, "tv": 2056.19, "trd": NaN, "batb": [[0, 1.61, 87.3]], "batl": NaN}, {"timestamp": 1578767096894, "ltp": 1.62, "tv": 2056.19, "trd": NaN, "batb": [[0, 1.61, 101.29]], "batl": NaN}, {"timestamp": 1578767098009, "ltp": 1.62, "tv": 2056.19, "trd": NaN, "batb": [[0, 1.61, 87.3]], "batl": NaN}, {"timestamp": 1578767100025, "ltp": 1.62, "tv": 2056.19, "trd": NaN, "batb": [[0, 1.61, 101.29]], "batl": NaN}, {"timestamp": 1578767101032, "ltp": 1.62, "tv": 2056.19, "trd": NaN, "batb": [[0, 1.61, 87.3]], "batl": NaN}, {"timestamp": 1578767102413, "ltp": 1.62, "tv": 2056.19, "trd": NaN, "batb": [[0, 1.61, 101.29]], "batl": NaN}, {"timestamp": 1578767103702, "ltp": 1.62, "tv": 2056.19, "trd": NaN, "batb": [[0, 1.61, 87.3]], "batl": NaN}, {"timestamp": 1578767106020, "ltp": 1.62, "tv": 2056.19, "trd": NaN, "batb": [[0, 1.61, 101.29]], "batl": NaN}, {"timestamp": 1578767106732, "ltp": 1.62, "tv": 2056.19, "trd": NaN, "batb": [[0, 1.61, 87.3]], "batl": NaN}, {"timestamp": 1578767108835, "ltp": 1.62, "tv": 2056.19, "trd": NaN, "batb": [[0, 1.61, 101.29]], "batl": NaN}, {"timestamp": 1578767109737, "ltp": 1.62, "tv": 2056.19, "trd": NaN, "batb": [[0, 1.61, 87.3]], "batl": NaN}, {"timestamp": 1578767111918, "ltp": 1.62, "tv": 2056.19, "trd": NaN, "batb": [[0, 1.61, 101.29]], "batl": NaN}, {"timestamp": 1578767112446, "ltp": 1.62, "tv": 2056.19, "trd": NaN, "batb": [[0, 1.61, 87.3]], "batl": NaN}, {"timestamp": 1578767114661, "ltp": 1.62, "tv": 2056.19, "trd": NaN, "batb": [[0, 1.61, 101.29]], "batl": NaN}, {"timestamp": 1578767116044, "ltp": 1.62, "tv": 2056.19, "trd": NaN, "batb": [[0, 1.61, 87.3]], "batl": NaN}, {"timestamp": 1578767118021, "ltp": 1.62, "tv": 2056.19, "trd": NaN, "batb": [[0, 1.61, 101.29]], "batl": NaN}, {"timestamp": 1578767119042, "ltp": 1.62, "tv": 2056.19, "trd": NaN, "batb": [[0, 1.61, 87.3]], "batl": NaN}, {"timestamp": 1578767120526, "ltp": 1.62, "tv": 2056.19, "trd": NaN, "batb": [[0, 1.61, 101.29]], "batl": NaN}, {"timestamp": 1578767121545, "ltp": 1.62, "tv": 2056.19, "trd": NaN, "batb": [[0, 1.61, 87.3]], "batl": NaN}, {"timestamp": 1578767123560, "ltp": 1.62, "tv": 2056.19, "trd": NaN, "batb": [[0, 1.61, 101.29]], "batl": NaN}, {"timestamp": 1578767124584, "ltp": 1.62, "tv": 2056.19, "trd": NaN, "batb": [[0, 1.61, 87.3]], "batl": NaN}, {"timestamp": 1578767126449, "ltp": 1.62, "tv": 2056.19, "trd": NaN, "batb": [[0, 1.61, 101.29]], "batl": NaN}, {"timestamp": 1578767128025, "ltp": 1.62, "tv": 2056.19, "trd": NaN, "batb": [[0, 1.61, 87.3]], "batl": NaN}, {"timestamp": 1578767128877, "ltp": 1.62, "tv": 2056.19, "trd": NaN, "batb": [[0, 1.61, 101.29]], "batl": NaN}, {"timestamp": 1578767129770, "ltp": 1.62, "tv": 2056.19, "trd": NaN, "batb": [[0, 1.61, 87.3]], "batl": NaN}, {"timestamp": 1578767131616, "ltp": 1.62, "tv": 2056.19, "trd": NaN, "batb": [[0, 1.61, 101.29]], "batl": NaN}, {"timestamp": 1578767132648, "ltp": 1.62, "tv": 2056.19, "trd": NaN, "batb": [[0, 1.61, 87.3]], "batl": NaN}, {"timestamp": 1578767134649, "ltp": 1.62, "tv": 2056.19, "trd": NaN, "batb": [[0, 1.61, 101.29]], "batl": NaN}, {"timestamp": 1578767135862, "ltp": 1.62, "tv": 2056.19, "trd": NaN, "batb": [[0, 1.61, 87.3]], "batl": NaN}, {"timestamp": 1578767137554, "ltp": 1.62, "tv": 2056.19, "trd": NaN, "batb": [[0, 1.61, 101.29]], "batl": NaN}, {"timestamp": 1578767138460, "ltp": 1.62, "tv": 2056.19, "trd": NaN, "batb": [[0, 1.61, 87.3]], "batl": NaN}, {"timestamp": 1578767141007, "ltp": 1.62, "tv": 2056.19, "trd": NaN, "batb": [[0, 1.61, 101.29]], "batl": NaN}, {"timestamp": 1578767142687, "ltp": 1.62, "tv": 2056.19, "trd": NaN, "batb": [[0, 1.61, 87.3]], "batl": NaN}, {"timestamp": 1578767143975, "ltp": 1.62, "tv": 2056.19, "trd": NaN, "batb": [[0, 1.61, 101.29]], "batl": NaN}, {"timestamp": 1578767144907, "ltp": 1.62, "tv": 2056.19, "trd": NaN, "batb": [[0, 1.61, 87.3]], "batl": NaN}, {"timestamp": 1578767147012, "ltp": 1.62, "tv": 2056.19, "trd": NaN, "batb": [[0, 1.61, 101.29]], "batl": NaN}, {"timestamp": 1578767147870, "ltp": 1.62, "tv": 2056.19, "trd": NaN, "batb": [[0, 1.61, 87.3]], "batl": NaN}, {"timestamp": 1578767149877, "ltp": 1.62, "tv": 2056.19, "trd": NaN, "batb": [[0, 1.61, 101.29]], "batl": NaN}, {"timestamp": 1578767150795, "ltp": 1.62, "tv": 2056.19, "trd": NaN, "batb": [[0, 1.61, 87.3]], "batl": NaN}, {"timestamp": 1578767152791, "ltp": 1.62, "tv": 2056.19, "trd": NaN, "batb": [[0, 1.61, 101.29]], "batl": NaN}, {"timestamp": 1578767154970, "ltp": 1.62, "tv": 2056.19, "trd": NaN, "batb": [[0, 1.61, 87.3]], "batl": NaN}, {"timestamp": 1578767155769, "ltp": 1.62, "tv": 2056.19, "trd": NaN, "batb": [[0, 1.61, 101.29]], "batl": NaN}, {"timestamp": 1578767156784, "ltp": 1.62, "tv": 2056.19, "trd": NaN, "batb": [[0, 1.61, 87.3]], "batl": NaN}, {"timestamp": 1578767158806, "ltp": 1.62, "tv": 2056.19, "trd": NaN, "batb": [[0, 1.61, 101.29]], "batl": NaN}, {"timestamp": 1578767159708, "ltp": 1.62, "tv": 2056.19, "trd": NaN, "batb": [[0, 1.61, 87.3]], "batl": NaN}, {"timestamp": 1578767161403, "ltp": 1.62, "tv": 2056.19, "trd": NaN, "batb": [[0, 1.61, 101.29]], "batl": NaN}, {"timestamp": 1578767162513, "ltp": 1.62, "tv": 2056.19, "trd": NaN, "batb": [[0, 1.61, 87.3]], "batl": NaN}, {"timestamp": 1578767164595, "ltp": 1.62, "tv": 2056.19, "trd": NaN, "batb": [[0, 1.61, 101.29]], "batl": NaN}, {"timestamp": 1578767165633, "ltp": 1.62, "tv": 2056.19, "trd": NaN, "batb": [[0, 1.61, 87.3]], "batl": NaN}, {"timestamp": 1578767167499, "ltp": 1.62, "tv": 2056.19, "trd": NaN, "batb": [[0, 1.61, 101.29]], "batl": NaN}, {"timestamp": 1578767168613, "ltp": 1.62, "tv": 2056.19, "trd": NaN, "batb": [[0, 1.61, 87.3]], "batl": NaN}, {"timestamp": 1578767171016, "ltp": 1.62, "tv": 2056.19, "trd": NaN, "batb": [[0, 1.61, 101.29]], "batl": NaN}, {"timestamp": 1578767171661, "ltp": 1.62, "tv": 2056.19, "trd": NaN, "batb": [[0, 1.61, 87.3]], "batl": NaN}, {"timestamp": 1578767175412, "ltp": 1.62, "tv": 2056.19, "trd": NaN, "batb": [[0, 1.61, 101.29]], "batl": NaN}, {"timestamp": 1578767176337, "ltp": 1.62, "tv": 2056.19, "trd": NaN, "batb": [[0, 1.61, 87.3]], "batl": NaN}, {"timestamp": 1578767180732, "ltp": 1.62, "tv": 2056.19, "trd": NaN, "batb": [[0, 1.61, 101.29]], "batl": NaN}, {"timestamp": 1578767181620, "ltp": 1.62, "tv": 2056.19, "trd": NaN, "batb": [[0, 1.61, 87.3]], "batl": NaN}, {"timestamp": 1578767182741, "ltp": 1.62, "tv": 2056.19, "trd": NaN, "batb": [[0, 1.61, 101.29]], "batl": NaN}, {"timestamp": 1578767183815, "ltp": 1.62, "tv": 2056.19, "trd": NaN, "batb": [[0, 1.61, 87.3]], "batl": NaN}, {"timestamp": 1578767186003, "ltp": 1.62, "tv": 2056.19, "trd": NaN, "batb": [[0, 1.61, 101.29]], "batl": NaN}, {"timestamp": 1578767186534, "ltp": 1.62, "tv": 2056.19, "trd": NaN, "batb": [[0, 1.61, 87.3]], "batl": NaN}, {"timestamp": 1578767190050, "ltp": 1.62, "tv": 2056.19, "trd": NaN, "batb": [[0, 1.61, 101.29]], "batl": NaN}, {"timestamp": 1578767190635, "ltp": 1.62, "tv": 2056.19, "trd": NaN, "batb": [[0, 1.61, 87.3]], "batl": NaN}, {"timestamp": 1578767192622, "ltp": 1.62, "tv": 2056.19, "trd": NaN, "batb": [[0, 1.61, 101.29]], "batl": NaN}, {"timestamp": 1578767194015, "ltp": 1.62, "tv": 2056.19, "trd": NaN, "batb": [[0, 1.61, 87.3]], "batl": NaN}, {"timestamp": 1578767194725, "ltp": 1.62, "tv": 2056.19, "trd": NaN, "batb": [[0, 1.61, 101.29]], "batl": NaN}, {"timestamp": 1578767195244, "ltp": 1.62, "tv": 2056.19, "trd": NaN, "batb": [[0, 1.61, 87.3]], "batl": NaN}, {"timestamp": 1578767196848, "ltp": 1.62, "tv": 2056.19, "trd": NaN, "batb": [[0, 1.61, 101.29]], "batl": NaN}, {"timestamp": 1578767197752, "ltp": 1.62, "tv": 2056.19, "trd": NaN, "batb": [[0, 1.61, 87.3]], "batl": NaN}, {"timestamp": 1578767198719, "ltp": 1.62, "tv": 2056.19, "trd": NaN, "batb": [[0, 1.61, 101.29]], "batl": NaN}, {"timestamp": 1578767199832, "ltp": 1.62, "tv": 2056.19, "trd": NaN, "batb": [[0, 1.61, 87.3]], "batl": NaN}, {"timestamp": 1578767200733, "ltp": 1.62, "tv": 2056.19, "trd": NaN, "batb": [[0, 1.61, 101.29]], "batl": NaN}, {"timestamp": 1578767201855, "ltp": 1.62, "tv": 2056.19, "trd": NaN, "batb": [[0, 1.61, 87.3]], "batl": NaN}, {"timestamp": 1578767202758, "ltp": 1.62, "tv": 2056.19, "trd": NaN, "batb": [[0, 1.61, 101.29]], "batl": NaN}, {"timestamp": 1578767203822, "ltp": 1.62, "tv": 2056.19, "trd": NaN, "batb": [[0, 1.61, 87.3]], "batl": NaN}, {"timestamp": 1578767206434, "ltp": 1.62, "tv": 2056.19, "trd": NaN, "batb": [[0, 1.61, 101.29]], "batl": NaN}, {"timestamp": 1578767207978, "ltp": 1.62, "tv": 2056.19, "trd": NaN, "batb": [[0, 1.61, 87.3]], "batl": NaN}, {"timestamp": 1578767208932, "ltp": 1.62, "tv": 2056.19, "trd": NaN, "batb": [[0, 1.61, 101.29], [1, 1.6, 925.39], [2, 1.59, 119.25]], "batl": NaN}, {"timestamp": 1578767210056, "ltp": 1.62, "tv": 2056.19, "trd": NaN, "batb": [[0, 1.61, 87.3]], "batl": NaN}, {"timestamp": 1578767211742, "ltp": 1.62, "tv": 2056.19, "trd": NaN, "batb": [[0, 1.61, 102.13]], "batl": NaN}, {"timestamp": 1578767212540, "ltp": 1.62, "tv": 2056.19, "trd": NaN, "batb": [[0, 1.61, 87.3]], "batl": NaN}, {"timestamp": 1578767215657, "ltp": 1.62, "tv": 2056.19, "trd": NaN, "batb": [[0, 1.61, 102.13]], "batl": NaN}, {"timestamp": 1578767216758, "ltp": 1.62, "tv": 2056.19, "trd": NaN, "batb": [[0, 1.61, 87.3]], "batl": NaN}, {"timestamp": 1578767217655, "ltp": 1.62, "tv": 2056.19, "trd": NaN, "batb": [[0, 1.61, 102.13]], "batl": NaN}, {"timestamp": 1578767218734, "ltp": 1.62, "tv": 2056.19, "trd": NaN, "batb": [[0, 1.61, 87.3]], "batl": NaN}, {"timestamp": 1578767219748, "ltp": 1.62, "tv": 2056.19, "trd": NaN, "batb": [[0, 1.61, 102.13]], "batl": NaN}, {"timestamp": 1578767220759, "ltp": 1.62, "tv": 2056.19, "trd": NaN, "batb": [[0, 1.61, 87.3]], "batl": NaN}, {"timestamp": 1578767223962, "ltp": 1.62, "tv": 2056.19, "trd": NaN, "batb": [[0, 1.61, 102.13]], "batl": NaN}, {"timestamp": 1578767224970, "ltp": 1.62, "tv": 2056.19, "trd": NaN, "batb": [[0, 1.61, 87.3]], "batl": NaN}, {"timestamp": 1578767225945, "ltp": 1.62, "tv": 2056.19, "trd": NaN, "batb": [[0, 1.61, 102.13]], "batl": NaN}, {"timestamp": 1578767227952, "ltp": 1.62, "tv": 2056.19, "trd": NaN, "batb": [[0, 1.61, 87.3]], "batl": NaN}, {"timestamp": 1578767228474, "ltp": 1.62, "tv": 2056.19, "trd": NaN, "batb": [[0, 1.61, 102.13]], "batl": NaN}, {"timestamp": 1578767229652, "ltp": 1.62, "tv": 2056.19, "trd": NaN, "batb": [[0, 1.61, 87.3]], "batl": NaN}, {"timestamp": 1578767231970, "ltp": 1.62, "tv": 2056.19, "trd": NaN, "batb": [[0, 1.61, 102.13]], "batl": NaN}, {"timestamp": 1578767232665, "ltp": 1.62, "tv": 2056.19, "trd": NaN, "batb": [[0, 1.61, 87.3]], "batl": NaN}, {"timestamp": 1578767235376, "ltp": 1.62, "tv": 2056.19, "trd": NaN, "batb": [[0, 1.61, 102.13]], "batl": NaN}, {"timestamp": 1578767236911, "ltp": 1.62, "tv": 2056.19, "trd": NaN, "batb": [[0, 1.61, 87.3]], "batl": NaN}, {"timestamp": 1578767240478, "ltp": 1.62, "tv": 2056.19, "trd": NaN, "batb": [[0, 1.61, 102.13]], "batl": NaN}, {"timestamp": 1578767241794, "ltp": 1.62, "tv": 2056.19, "trd": NaN, "batb": [[0, 1.61, 87.3]], "batl": NaN}, {"timestamp": 1578767242903, "ltp": 1.62, "tv": 2056.19, "trd": NaN, "batb": [[0, 1.61, 102.13]], "batl": NaN}, {"timestamp": 1578767243677, "ltp": 1.62, "tv": 2056.19, "trd": NaN, "batb": [[0, 1.61, 87.3]], "batl": NaN}, {"timestamp": 1578767244890, "ltp": 1.62, "tv": 2056.19, "trd": NaN, "batb": [[0, 1.61, 102.13]], "batl": NaN}, {"timestamp": 1578767245599, "ltp": 1.62, "tv": 2056.19, "trd": NaN, "batb": [[0, 1.61, 87.3]], "batl": NaN}, {"timestamp": 1578767248777, "ltp": 1.62, "tv": 2056.19, "trd": NaN, "batb": [[0, 1.61, 102.13]], "batl": NaN}, {"timestamp": 1578767250043, "ltp": 1.62, "tv": 2056.19, "trd": NaN, "batb": [[0, 1.61, 87.3]], "batl": NaN}, {"timestamp": 1578767251000, "ltp": 1.62, "tv": 2056.19, "trd": NaN, "batb": [[0, 1.61, 102.13]], "batl": NaN}, {"timestamp": 1578767251487, "ltp": 1.62, "tv": 2056.19, "trd": NaN, "batb": [[0, 1.61, 87.3]], "batl": NaN}, {"timestamp": 1578767253619, "ltp": 1.62, "tv": 2056.19, "trd": NaN, "batb": [[0, 1.61, 102.13]], "batl": NaN}, {"timestamp": 1578767254611, "ltp": 1.62, "tv": 2056.19, "trd": NaN, "batb": [[0, 1.61, 87.3]], "batl": NaN}, {"timestamp": 1578767256785, "ltp": 1.62, "tv": 2056.19, "trd": NaN, "batb": [[0, 1.61, 102.13]], "batl": NaN}, {"timestamp": 1578767257678, "ltp": 1.62, "tv": 2056.19, "trd": NaN, "batb": [[0, 1.61, 87.3]], "batl": NaN}, {"timestamp": 1578767260998, "ltp": 1.62, "tv": 2056.19, "trd": NaN, "batb": [[0, 1.61, 102.13]], "batl": NaN}, {"timestamp": 1578767261800, "ltp": 1.62, "tv": 2056.19, "trd": NaN, "batb": [[0, 1.61, 87.3]], "batl": NaN}, {"timestamp": 1578767264501, "ltp": 1.62, "tv": 2056.19, "trd": NaN, "batb": [[0, 1.61, 102.13]], "batl": NaN}, {"timestamp": 1578767265721, "ltp": 1.62, "tv": 2056.19, "trd": NaN, "batb": [[0, 1.61, 87.3]], "batl": NaN}, {"timestamp": 1578767268001, "ltp": 1.62, "tv": 2056.19, "trd": NaN, "batb": [[0, 1.61, 102.13]], "batl": NaN}, {"timestamp": 1578767269904, "ltp": 1.62, "tv": 2056.19, "trd": NaN, "batb": [[0, 1.61, 87.3]], "batl": NaN}, {"timestamp": 1578767271914, "ltp": 1.62, "tv": 2056.19, "trd": NaN, "batb": [[0, 1.61, 102.13]], "batl": NaN}, {"timestamp": 1578767272429, "ltp": 1.62, "tv": 2056.19, "trd": NaN, "batb": [[0, 1.61, 87.3]], "batl": NaN}, {"timestamp": 1578767275608, "ltp": 1.62, "tv": 2056.19, "trd": NaN, "batb": [[0, 1.61, 102.13]], "batl": NaN}, {"timestamp": 1578767276817, "ltp": 1.62, "tv": 2056.19, "trd": NaN, "batb": [[0, 1.61, 87.3]], "batl": NaN}, {"timestamp": 1578767277719, "ltp": 1.62, "tv": 2056.19, "trd": NaN, "batb": [[0, 1.61, 102.13]], "batl": NaN}, {"timestamp": 1578767278318, "ltp": 1.62, "tv": 2056.19, "trd": NaN, "batb": [[0, 1.61, 87.3]], "batl": NaN}, {"timestamp": 1578767280935, "ltp": 1.62, "tv": 2056.19, "trd": NaN, "batb": [[0, 1.61, 102.13]], "batl": NaN}, {"timestamp": 1578767282035, "ltp": 1.62, "tv": 2056.19, "trd": NaN, "batb": [[0, 1.61, 87.3]], "batl": NaN}, {"timestamp": 1578767283039, "ltp": 1.61, "tv": 2136.19, "trd": [[1.61, 1037.5]], "batb": [[0, 1.61, 47.3]], "batl": NaN}, {"timestamp": 1578767386712, "ltp": 1.61, "tv": 2136.19, "trd": NaN, "batb": [[0, 1.61, 62.15]], "batl": [[0, 1.62, 231.25]]}, {"timestamp": 1578767441787, "ltp": 1.61, "tv": 2136.19, "trd": NaN, "batb": NaN, "batl": [[1, 1.63, 954.95]]}, {"timestamp": 1578767448020, "ltp": 1.61, "tv": 2136.19, "trd": NaN, "batb": NaN, "batl": [[1, 1.63, 914.1]]}, {"timestamp": 1578767458007, "ltp": 1.61, "tv": 2136.19, "trd": NaN, "batb": NaN, "batl": [[1, 1.63, 967.72]]}, {"timestamp": 1578767581952, "ltp": 1.61, "tv": 2136.19, "trd": NaN, "batb": [[1, 1.6, 973.91]], "batl": NaN}, {"timestamp": 1578767587959, "ltp": 1.61, "tv": 2136.19, "trd": NaN, "batb": NaN, "batl": [[0, 1.62, 245.22]]}, {"timestamp": 1578767588951, "ltp": 1.61, "tv": 2136.19, "trd": NaN, "batb": NaN, "batl": [[0, 1.62, 231.25]]}, {"timestamp": 1578767616889, "ltp": 1.61, "tv": 2136.19, "trd": NaN, "batb": NaN, "batl": [[0, 1.62, 321.25]]}, {"timestamp": 1578767617890, "ltp": 1.61, "tv": 2136.19, "trd": NaN, "batb": NaN, "batl": [[0, 1.62, 338.81]]}, {"timestamp": 1578767700907, "ltp": 1.61, "tv": 2136.19, "trd": NaN, "batb": [[1, 1.6, 928.91], [2, 1.59, 74.25]], "batl": [[1, 1.63, 922.72], [2, 1.64, 47.45]]}, {"timestamp": 1578767712002, "ltp": 1.61, "tv": 2136.19, "trd": NaN, "batb": [[1, 1.6, 614.82]], "batl": NaN}, {"timestamp": 1578767712650, "ltp": 1.61, "tv": 2136.19, "trd": NaN, "batb": NaN, "batl": [[1, 1.63, 502.23]]}, {"timestamp": 1578767748842, "ltp": 1.61, "tv": 2136.19, "trd": NaN, "batb": [[1, 1.6, 503.31]], "batl": NaN}, {"timestamp": 1578767778896, "ltp": 1.61, "tv": 2136.19, "trd": NaN, "batb": NaN, "batl": [[1, 1.63, 534.57]]}, {"timestamp": 1578767784050, "ltp": 1.61, "tv": 2136.19, "trd": NaN, "batb": [[1, 1.6, 457.34]], "batl": NaN}, {"timestamp": 1578767903040, "ltp": 1.61, "tv": 2143.0, "trd": [[1.61, 1044.31]], "batb": [[0, 1.61, 58.75]], "batl": NaN}, {"timestamp": 1578768091030, "ltp": 1.61, "tv": 2143.0, "trd": NaN, "batb": [[1, 1.6, 486.23]], "batl": NaN}, {"timestamp": 1578768099848, "ltp": 1.61, "tv": 2143.0, "trd": NaN, "batb": [[0, 1.61, 83.75]], "batl": NaN}, {"timestamp": 1578768101055, "ltp": 1.61, "tv": 2143.0, "trd": NaN, "batb": NaN, "batl": [[0, 1.62, 363.81]]}, {"timestamp": 1578768111872, "ltp": 1.61, "tv": 2143.0, "trd": NaN, "batb": [[1, 1.6, 532.2]], "batl": NaN}, {"timestamp": 1578768117921, "ltp": 1.61, "tv": 2143.0, "trd": NaN, "batb": NaN, "batl": [[1, 1.63, 496.27]]}, {"timestamp": 1578768133647, "ltp": 1.61, "tv": 2143.0, "trd": NaN, "batb": [[2, 1.59, 413.19]], "batl": NaN}, {"timestamp": 1578768135029, "ltp": 1.61, "tv": 2143.0, "trd": NaN, "batb": [[0, 1.61, 465.3], [1, 1.6, 148.53]], "batl": NaN}, {"timestamp": 1578768135918, "ltp": 1.61, "tv": 2143.0, "trd": NaN, "batb": NaN, "batl": [[0, 1.62, 346.25]]}, {"timestamp": 1578768171003, "ltp": 1.61, "tv": 2143.0, "trd": NaN, "batb": NaN, "batl": [[2, 1.64, 422.02]]}, {"timestamp": 1578768172013, "ltp": 1.61, "tv": 2143.0, "trd": NaN, "batb": NaN, "batl": [[1, 1.63, 148.02]]}, {"timestamp": 1578768205653, "ltp": 1.61, "tv": 2163.0, "trd": [[1.61, 1064.31]], "batb": [[0, 1.61, 455.3]], "batl": NaN}, {"timestamp": 1578768256672, "ltp": 1.62, "tv": 2195.66, "trd": [[1.62, 341.56]], "batb": NaN, "batl": [[0, 1.62, 329.92]]}, {"timestamp": 1578768302899, "ltp": 1.62, "tv": 2195.66, "trd": NaN, "batb": [[2, 1.59, 392.09]], "batl": NaN}, {"timestamp": 1578768306970, "ltp": 1.62, "tv": 2195.66, "trd": NaN, "batb": [[2, 1.59, 53.15]], "batl": NaN}, {"timestamp": 1578768411811, "ltp": 1.62, "tv": 2262.32, "trd": [[1.62, 408.22]], "batb": NaN, "batl": [[0, 1.62, 296.59]]}, {"timestamp": 1578768471701, "ltp": 1.62, "tv": 2325.4, "trd": [[1.62, 471.3]], "batb": NaN, "batl": [[0, 1.62, 265.05]]}, {"timestamp": 1578768535254, "ltp": 1.62, "tv": 2362.78, "trd": [[1.62, 508.68]], "batb": NaN, "batl": [[0, 1.62, 246.36]]}, {"timestamp": 1578768579328, "ltp": 1.61, "tv": 2388.95, "trd": [[1.61, 1090.47]], "batb": [[0, 1.61, 442.22]], "batl": NaN}, {"timestamp": 1578768610951, "ltp": 1.61, "tv": 2388.95, "trd": NaN, "batb": [[1, 1.6, 181.72]], "batl": NaN}, {"timestamp": 1578768616859, "ltp": 1.61, "tv": 2388.95, "trd": NaN, "batb": NaN, "batl": [[1, 1.63, 105.46]]}, {"timestamp": 1578768624450, "ltp": 1.62, "tv": 2408.95, "trd": [[1.62, 528.68]], "batb": NaN, "batl": [[0, 1.62, 236.36]]}, {"timestamp": 1578768777837, "ltp": 1.62, "tv": 2412.95, "trd": [[1.62, 532.68]], "batb": NaN, "batl": [[0, 1.62, 234.36]]}, {"timestamp": 1578768864960, "ltp": 1.61, "tv": 2417.54, "trd": [[1.61, 1095.07]], "batb": [[0, 1.61, 439.92]], "batl": NaN}, {"timestamp": 1578768870056, "ltp": 1.61, "tv": 2587.78, "trd": [[1.61, 1265.31]], "batb": [[0, 1.61, 371.5]], "batl": [[0, 1.62, 259.36]]}, {"timestamp": 1578768905907, "ltp": 1.61, "tv": 2610.72, "trd": [[1.61, 1288.25]], "batb": [[0, 1.61, 360.03]], "batl": NaN}, {"timestamp": 1578768906912, "ltp": 1.61, "tv": 2610.72, "trd": NaN, "batb": NaN, "batl": [[0, 1.62, 276.95]]}, {"timestamp": 1578768918640, "ltp": 1.61, "tv": 2610.72, "trd": NaN, "batb": NaN, "batl": [[0, 1.62, 259.36]]}, {"timestamp": 1578768919644, "ltp": 1.61, "tv": 2610.72, "trd": NaN, "batb": NaN, "batl": [[0, 1.62, 276.95]]}, {"timestamp": 1578768920947, "ltp": 1.61, "tv": 2610.72, "trd": NaN, "batb": NaN, "batl": [[0, 1.62, 259.36]]}, {"timestamp": 1578768921837, "ltp": 1.61, "tv": 2610.72, "trd": NaN, "batb": NaN, "batl": [[0, 1.62, 276.95]]}, {"timestamp": 1578768922833, "ltp": 1.61, "tv": 2610.72, "trd": NaN, "batb": NaN, "batl": [[0, 1.62, 259.36]]}, {"timestamp": 1578768955916, "ltp": 1.61, "tv": 2610.72, "trd": NaN, "batb": NaN, "batl": [[1, 1.63, 142.91]]}, {"timestamp": 1578768981945, "ltp": 1.61, "tv": 2610.72, "trd": NaN, "batb": NaN, "batl": [[2, 1.64, 534.95]]}, {"timestamp": 1578769006952, "ltp": 1.61, "tv": 2610.72, "trd": NaN, "batb": NaN, "batl": [[1, 1.63, 105.46]]}, {"timestamp": 1578769012962, "ltp": 1.61, "tv": 2610.72, "trd": NaN, "batb": NaN, "batl": [[2, 1.64, 621.88]]}, {"timestamp": 1578769026986, "ltp": 1.61, "tv": 2610.72, "trd": NaN, "batb": NaN, "batl": [[1, 1.63, 144.61]]}, {"timestamp": 1578769029912, "ltp": 1.62, "tv": 3129.38, "trd": [[1.62, 1051.34]], "batb": [[0, 1.61, 405.03]], "batl": [[0, 1.63, 144.64], [1, 1.64, 621.88], [2, 1.65, 19.09]]}, {"timestamp": 1578769031020, "ltp": 1.62, "tv": 3155.55, "trd": [[1.62, 1077.5]], "batb": [[1, 1.6, 147.68]], "batl": [[0, 1.63, 183.66], [2, 1.65, 31.94]]}, {"timestamp": 1578769032012, "ltp": 1.62, "tv": 3155.55, "trd": NaN, "batb": [[0, 1.62, 13.27], [1, 1.61, 405.03], [2, 1.6, 147.68]], "batl": NaN}, {"timestamp": 1578769033006, "ltp": 1.62, "tv": 3155.55, "trd": NaN, "batb": [[0, 1.62, 26.32], [1, 1.61, 455.03]], "batl": NaN}, {"timestamp": 1578769043781, "ltp": 1.62, "tv": 3164.2, "trd": [[1.62, 1086.15]], "batb": [[0, 1.62, 22]], "batl": NaN}, {"timestamp": 1578769047029, "ltp": 1.62, "tv": 3164.2, "trd": NaN, "batb": [[0, 1.62, 13.05]], "batl": [[1, 1.64, 422.02]]}, {"timestamp": 1578769048026, "ltp": 1.62, "tv": 3164.2, "trd": NaN, "batb": NaN, "batl": [[1, 1.64, 421.46]]}, {"timestamp": 1578769051814, "ltp": 1.62, "tv": 3164.2, "trd": NaN, "batb": NaN, "batl": [[0, 1.63, 383.43]]}, {"timestamp": 1578769053027, "ltp": 1.62, "tv": 3164.2, "trd": NaN, "batb": [[1, 1.61, 111.7], [2, 1.6, 531.04]], "batl": [[0, 1.63, 183.66]]}, {"timestamp": 1578769056046, "ltp": 1.62, "tv": 3164.2, "trd": NaN, "batb": NaN, "batl": [[0, 1.63, 556.05], [1, 1.64, 47.45]]}, {"timestamp": 1578769057044, "ltp": 1.62, "tv": 3189.31, "trd": [[1.62, 1111.27]], "batb": [[0, 1.61, 112.19], [1, 1.6, 531.04], [2, 1.59, 53.15]], "batl": NaN}, {"timestamp": 1578769061049, "ltp": 1.62, "tv": 3189.31, "trd": NaN, "batb": [[1, 1.6, 147.68]], "batl": NaN}, {"timestamp": 1578769061951, "ltp": 1.62, "tv": 3189.31, "trd": NaN, "batb": [[1, 1.6, 516.09]], "batl": NaN}, {"timestamp": 1578769080990, "ltp": 1.62, "tv": 3189.31, "trd": NaN, "batb": [[1, 1.6, 561.09], [2, 1.59, 98.15]], "batl": [[1, 1.64, 92.45], [2, 1.65, 76.94]]}, {"timestamp": 1578769083009, "ltp": 1.62, "tv": 3189.31, "trd": NaN, "batb": [[0, 1.61, 492.15]], "batl": NaN}, {"timestamp": 1578769083990, "ltp": 1.62, "tv": 3189.31, "trd": NaN, "batb": [[0, 1.61, 112.19], [1, 1.6, 192.68]], "batl": NaN}, {"timestamp": 1578769090982, "ltp": 1.62, "tv": 3189.31, "trd": NaN, "batb": [[1, 1.6, 575.01]], "batl": NaN}, {"timestamp": 1578769112049, "ltp": 1.62, "tv": 3189.31, "trd": NaN, "batb": [[0, 1.62, 27.57], [1, 1.61, 492.31], [2, 1.6, 192.68]], "batl": [[0, 1.63, 183.66], [1, 1.64, 466.09]]}, {"timestamp": 1578769113047, "ltp": 1.62, "tv": 3189.31, "trd": NaN, "batb": [[0, 1.61, 492.8], [1, 1.6, 192.68], [2, 1.59, 98.15]], "batl": NaN}, {"timestamp": 1578769144054, "ltp": 1.62, "tv": 3189.31, "trd": NaN, "batb": NaN, "batl": [[1, 1.64, 578.52]]}, {"timestamp": 1578769144985, "ltp": 1.61, "tv": 4180.04, "trd": [[1.61, 2278], [1.62, 1112.25]], "batb": [[0, 1.6, 192.68], [1, 1.59, 98.15], [2, 1.57, 350.64]], "batl": [[0, 1.61, 2.07], [1, 1.63, 183.66], [2, 1.64, 578.52]]}, {"timestamp": 1578769145882, "ltp": 1.61, "tv": 4184.03, "trd": [[1.61, 2281.98]], "batb": [[0, 1.6, 575.05]], "batl": [[0, 1.61, 45.08], [1, 1.62, 14.97], [2, 1.63, 183.66]]}, {"timestamp": 1578769147291, "ltp": 1.61, "tv": 4184.03, "trd": NaN, "batb": NaN, "batl": [[1, 1.62, 64.97]]}, {"timestamp": 1578769173929, "ltp": 1.62, "tv": 4402.27, "trd": [[1.61, 2372.14], [1.62, 1240.33]], "batb": [[0, 1.61, 380.65], [1, 1.6, 575.05], [2, 1.59, 98.15]], "batl": [[0, 1.63, 184.59], [1, 1.64, 578.52], [2, 1.65, 76.94]]}, {"timestamp": 1578769175033, "ltp": 1.62, "tv": 4402.27, "trd": NaN, "batb": [[0, 1.61, 447.21], [1, 1.6, 192.68]], "batl": NaN}, {"timestamp": 1578769175917, "ltp": 1.62, "tv": 4402.27, "trd": NaN, "batb": [[0, 1.61, 496.28]], "batl": NaN}, {"timestamp": 1578769201027, "ltp": 1.62, "tv": 4402.27, "trd": NaN, "batb": [[0, 1.61, 501.2]], "batl": NaN}, {"timestamp": 1578769235958, "ltp": 1.62, "tv": 4402.18, "trd": [[1.57, 134.75], [1.58, 370.41], [1.6, 157.29], [1.61, 2372.08], [1.62, 1240.32]], "batb": NaN, "batl": [[0, 1.63, 575.07], [1, 1.64, 204.88]]}, {"timestamp": 1578769299899, "ltp": 1.62, "tv": 4402.18, "trd": NaN, "batb": [[0, 1.61, 509.2]], "batl": [[1, 1.64, 92.45], [2, 1.65, 276.84]]}, {"timestamp": 1578769306899, "ltp": 1.62, "tv": 4402.18, "trd": NaN, "batb": [[2, 1.59, 268.39]], "batl": [[0, 1.63, 617.63]]}, {"timestamp": 1578769311914, "ltp": 1.62, "tv": 4402.18, "trd": NaN, "batb": [[0, 1.61, 128.55]], "batl": [[1, 1.64, 202.88], [2, 1.65, 76.94]]}, {"timestamp": 1578769313025, "ltp": 1.62, "tv": 4402.18, "trd": NaN, "batb": [[1, 1.6, 590.48]], "batl": NaN}, {"timestamp": 1578769321944, "ltp": 1.62, "tv": 4402.18, "trd": NaN, "batb": [[1, 1.6, 458.54], [2, 1.59, 98.15]], "batl": [[0, 1.63, 449.09]]}, {"timestamp": 1578769332959, "ltp": 1.62, "tv": 4404.04, "trd": [[1.62, 1242.18]], "batb": NaN, "batl": [[0, 1.62, 11.86], [1, 1.63, 448.16], [2, 1.64, 202.88]]}, {"timestamp": 1578769333657, "ltp": 1.62, "tv": 4404.04, "trd": NaN, "batb": NaN, "batl": [[0, 1.63, 448.16], [1, 1.64, 202.88], [2, 1.65, 76.94]]}, {"timestamp": 1578769335952, "ltp": 1.62, "tv": 4404.04, "trd": NaN, "batb": [[0, 1.61, 129.48]], "batl": NaN}, {"timestamp": 1578769337973, "ltp": 1.62, "tv": 4404.04, "trd": NaN, "batb": [[2, 1.59, 271.8]], "batl": [[0, 1.63, 624.36]]}, {"timestamp": 1578769364013, "ltp": 1.62, "tv": 4404.04, "trd": NaN, "batb": NaN, "batl": [[1, 1.64, 92.45], [2, 1.65, 276.84]]}, {"timestamp": 1578769435985, "ltp": 1.62, "tv": 4404.04, "trd": NaN, "batb": [[1, 1.6, 593.88]], "batl": NaN}, {"timestamp": 1578769441708, "ltp": 1.62, "tv": 4404.04, "trd": NaN, "batb": [[2, 1.59, 98.15]], "batl": [[0, 1.63, 581.8]]}, {"timestamp": 1578769453973, "ltp": 1.62, "tv": 4404.04, "trd": NaN, "batb": NaN, "batl": [[1, 1.64, 203.88], [2, 1.65, 76.94]]}, {"timestamp": 1578769531034, "ltp": 1.62, "tv": 4404.04, "trd": NaN, "batb": [[1, 1.6, 969.26]], "batl": [[0, 1.63, 1094.23]]}, {"timestamp": 1578769555050, "ltp": 1.62, "tv": 4404.04, "trd": NaN, "batb": NaN, "batl": [[0, 1.63, 1129.98]]}, {"timestamp": 1578769560029, "ltp": 1.62, "tv": 4404.04, "trd": NaN, "batb": [[1, 1.6, 919.04]], "batl": NaN}, {"timestamp": 1578769564031, "ltp": 1.62, "tv": 4404.04, "trd": NaN, "batb": [[0, 1.61, 133.74]], "batl": NaN}, {"timestamp": 1578769564978, "ltp": 1.62, "tv": 4404.04, "trd": NaN, "batb": NaN, "batl": [[0, 1.63, 1176.8]]}, {"timestamp": 1578769569972, "ltp": 1.62, "tv": 4404.04, "trd": NaN, "batb": [[1, 1.6, 879.04]], "batl": NaN}, {"timestamp": 1578769601017, "ltp": 1.62, "tv": 4404.04, "trd": NaN, "batb": NaN, "batl": [[0, 1.63, 1095.08]]}, {"timestamp": 1578769602027, "ltp": 1.62, "tv": 4404.04, "trd": NaN, "batb": [[1, 1.6, 967.56]], "batl": NaN}, {"timestamp": 1578769605995, "ltp": 1.62, "tv": 4404.04, "trd": NaN, "batb": NaN, "batl": [[0, 1.63, 1004]]}, {"timestamp": 1578769616958, "ltp": 1.62, "tv": 4404.04, "trd": NaN, "batb": NaN, "batl": [[0, 1.63, 1078.06]]}, {"timestamp": 1578769666935, "ltp": 1.61, "tv": 4407.78, "trd": [[1.61, 2375.82]], "batb": [[0, 1.61, 131.86]], "batl": NaN}, {"timestamp": 1578769842705, "ltp": 1.61, "tv": 4407.78, "trd": NaN, "batb": NaN, "batl": [[1, 1.64, 342.56]]}, {"timestamp": 1578769877819, "ltp": 1.61, "tv": 4461.35, "trd": [[1.61, 2429.4]], "batb": [[0, 1.61, 105.08]], "batl": NaN}, {"timestamp": 1578769878999, "ltp": 1.61, "tv": 4461.35, "trd": NaN, "batb": [[0, 1.61, 124.09]], "batl": [[0, 1.62, 26.01], [1, 1.63, 1078.06], [2, 1.64, 342.56]]}, {"timestamp": 1578769880019, "ltp": 1.61, "tv": 4461.35, "trd": NaN, "batb": [[0, 1.61, 123.03]], "batl": NaN}, {"timestamp": 1578769880837, "ltp": 1.61, "tv": 4461.35, "trd": NaN, "batb": [[0, 1.61, 123.75]], "batl": NaN}, {"timestamp": 1578769900933, "ltp": 1.61, "tv": 4461.35, "trd": NaN, "batb": [[0, 1.61, 131.75]], "batl": NaN}, {"timestamp": 1578769903959, "ltp": 1.61, "tv": 4461.35, "trd": NaN, "batb": NaN, "batl": [[2, 1.64, 203.88]]}, {"timestamp": 1578769914976, "ltp": 1.61, "tv": 4461.35, "trd": NaN, "batb": NaN, "batl": [[1, 1.63, 1124.02]]}, {"timestamp": 1578769928969, "ltp": 1.61, "tv": 4495.4, "trd": [[1.61, 2463.44]], "batb": [[0, 1.61, 114.73]], "batl": [[0, 1.62, 43.03]]}, {"timestamp": 1578769946025, "ltp": 1.61, "tv": 4495.4, "trd": NaN, "batb": [[1, 1.6, 916.49]], "batl": NaN}, {"timestamp": 1578769949816, "ltp": 1.61, "tv": 4495.4, "trd": NaN, "batb": [[1, 1.6, 880.74]], "batl": NaN}, {"timestamp": 1578769954922, "ltp": 1.61, "tv": 4495.4, "trd": NaN, "batb": [[1, 1.6, 925.85]], "batl": NaN}, {"timestamp": 1578769955827, "ltp": 1.61, "tv": 4495.4, "trd": NaN, "batb": NaN, "batl": [[0, 1.62, 24.12]]}, {"timestamp": 1578769996039, "ltp": 1.61, "tv": 4495.4, "trd": NaN, "batb": NaN, "batl": [[2, 1.64, 92.45]]}, {"timestamp": 1578770019053, "ltp": 1.61, "tv": 4495.4, "trd": NaN, "batb": NaN, "batl": [[2, 1.64, 208.38]]}, {"timestamp": 1578770047802, "ltp": 1.61, "tv": 4495.4, "trd": NaN, "batb": NaN, "batl": [[1, 1.63, 1164.88]]}, {"timestamp": 1578770052831, "ltp": 1.61, "tv": 4495.4, "trd": NaN, "batb": [[1, 1.6, 607.5]], "batl": [[1, 1.63, 448.16]]}, {"timestamp": 1578770064940, "ltp": 1.61, "tv": 4495.4, "trd": NaN, "batb": [[1, 1.6, 877.33]], "batl": [[1, 1.63, 1181.9]]}, {"timestamp": 1578770071044, "ltp": 1.61, "tv": 4495.4, "trd": NaN, "batb": NaN, "batl": [[2, 1.64, 342.56]]}, {"timestamp": 1578770132935, "ltp": 1.61, "tv": 4495.4, "trd": NaN, "batb": NaN, "batl": [[2, 1.64, 226.63]]}, {"timestamp": 1578770146034, "ltp": 1.61, "tv": 4495.4, "trd": NaN, "batb": [[1, 1.6, 925.85]], "batl": NaN}, {"timestamp": 1578770151950, "ltp": 1.61, "tv": 4495.4, "trd": NaN, "batb": NaN, "batl": [[1, 1.63, 1137.64]]}, {"timestamp": 1578770163931, "ltp": 1.61, "tv": 4495.4, "trd": NaN, "batb": [[2, 1.59, 99.53]], "batl": NaN}, {"timestamp": 1578770164846, "ltp": 1.61, "tv": 4531.86, "trd": [[1.61, 2499.9]], "batb": [[0, 1.61, 96.5]], "batl": [[0, 1.62, 42.35]]}, {"timestamp": 1578770181978, "ltp": 1.61, "tv": 4531.86, "trd": NaN, "batb": NaN, "batl": [[2, 1.64, 92.45]]}, {"timestamp": 1578770184980, "ltp": 1.61, "tv": 4531.86, "trd": NaN, "batb": [[1, 1.6, 953.48], [2, 1.59, 771.14]], "batl": [[0, 1.62, 550.52]]}, {"timestamp": 1578770186019, "ltp": 1.61, "tv": 4531.86, "trd": NaN, "batb": [[0, 1.61, 75.18]], "batl": [[0, 1.62, 603.15]]}, {"timestamp": 1578770187885, "ltp": 1.61, "tv": 4535.42, "trd": [[1.61, 2503.46]], "batb": [[0, 1.61, 73.4]], "batl": NaN}, {"timestamp": 1578770189805, "ltp": 1.61, "tv": 4535.42, "trd": NaN, "batb": [[1, 1.6, 486.17]], "batl": [[0, 1.62, 94.98]]}, {"timestamp": 1578770190984, "ltp": 1.61, "tv": 4535.42, "trd": NaN, "batb": [[0, 1.61, 96.72], [2, 1.59, 827.32]], "batl": [[1, 1.63, 1258.51]]}, {"timestamp": 1578770192983, "ltp": 1.61, "tv": 4535.42, "trd": NaN, "batb": NaN, "batl": [[0, 1.62, 42.35]]}, {"timestamp": 1578770202014, "ltp": 1.61, "tv": 4535.42, "trd": NaN, "batb": [[1, 1.6, 500.09]], "batl": NaN}, {"timestamp": 1578770203022, "ltp": 1.61, "tv": 4535.42, "trd": NaN, "batb": NaN, "batl": [[2, 1.64, 214.13]]}, {"timestamp": 1578770206005, "ltp": 1.61, "tv": 4535.42, "trd": NaN, "batb": NaN, "batl": [[0, 1.62, 510.51]]}, {"timestamp": 1578770207018, "ltp": 1.61, "tv": 4560.96, "trd": [[1.61, 2529]], "batb": [[0, 1.61, 60.63]], "batl": [[0, 1.62, 550.74]]}, {"timestamp": 1578770211041, "ltp": 1.61, "tv": 4560.96, "trd": NaN, "batb": NaN, "batl": [[1, 1.63, 448.16]]}, {"timestamp": 1578770216949, "ltp": 1.61, "tv": 4560.96, "trd": NaN, "batb": NaN, "batl": [[1, 1.63, 451.58]]}, {"timestamp": 1578770219036, "ltp": 1.61, "tv": 4682.21, "trd": [[1.61, 2650.26]], "batb": [[0, 1.6, 500.09], [1, 1.59, 827.32], [2, 1.57, 438.71]], "batl": [[0, 1.62, 551.72]]}, {"timestamp": 1578770220056, "ltp": 1.61, "tv": 4682.21, "trd": NaN, "batb": NaN, "batl": [[0, 1.62, 633.72]]}, {"timestamp": 1578770222045, "ltp": 1.61, "tv": 4682.21, "trd": NaN, "batb": [[0, 1.6, 505.09]], "batl": NaN}, {"timestamp": 1578770222953, "ltp": 1.61, "tv": 4682.21, "trd": NaN, "batb": [[2, 1.58, 45]], "batl": NaN}, {"timestamp": 1578770238970, "ltp": 1.61, "tv": 4682.21, "trd": NaN, "batb": NaN, "batl": [[1, 1.63, 451.81]]}, {"timestamp": 1578770244024, "ltp": 1.61, "tv": 4682.21, "trd": NaN, "batb": [[0, 1.6, 222.37]], "batl": [[1, 1.63, 350.4]]}, {"timestamp": 1578770244952, "ltp": 1.61, "tv": 4682.21, "trd": NaN, "batb": NaN, "batl": [[1, 1.63, 499.35], [2, 1.64, 342.56]]}, {"timestamp": 1578770247983, "ltp": 1.61, "tv": 4682.21, "trd": NaN, "batb": NaN, "batl": [[0, 1.61, 1.21], [1, 1.62, 632.74], [2, 1.63, 499.12]]}, {"timestamp": 1578770251807, "ltp": 1.61, "tv": 4682.21, "trd": NaN, "batb": NaN, "batl": [[2, 1.63, 749.33]]}, {"timestamp": 1578770260896, "ltp": 1.61, "tv": 4682.21, "trd": NaN, "batb": NaN, "batl": [[2, 1.63, 745.91]]}, {"timestamp": 1578770263979, "ltp": 1.61, "tv": 4682.21, "trd": NaN, "batb": NaN, "batl": [[2, 1.63, 495.7]]}, {"timestamp": 1578770264996, "ltp": 1.61, "tv": 4682.21, "trd": NaN, "batb": NaN, "batl": [[2, 1.63, 614.74]]}, {"timestamp": 1578770294044, "ltp": 1.61, "tv": 4682.21, "trd": NaN, "batb": NaN, "batl": [[1, 1.62, 594.44]]}, {"timestamp": 1578770324055, "ltp": 1.61, "tv": 4682.21, "trd": NaN, "batb": NaN, "batl": [[2, 1.63, 745.78]]}, {"timestamp": 1578770328037, "ltp": 1.61, "tv": 4682.21, "trd": NaN, "batb": [[0, 1.6, 358.65]], "batl": [[1, 1.62, 641.26]]}, {"timestamp": 1578770332991, "ltp": 1.62, "tv": 4690.21, "trd": [[1.61, 2652.68], [1.62, 1247.76]], "batb": NaN, "batl": [[0, 1.62, 638.47], [1, 1.63, 745.78], [2, 1.64, 92.45]]}, {"timestamp": 1578770335999, "ltp": 1.62, "tv": 4690.21, "trd": NaN, "batb": [[0, 1.6, 515.28]], "batl": NaN}, {"timestamp": 1578770353991, "ltp": 1.62, "tv": 4690.21, "trd": NaN, "batb": NaN, "batl": [[1, 1.63, 614.74]]}, {"timestamp": 1578770415991, "ltp": 1.62, "tv": 4690.21, "trd": NaN, "batb": NaN, "batl": [[1, 1.63, 495.7], [2, 1.64, 206.88]]}, {"timestamp": 1578770422989, "ltp": 1.62, "tv": 4690.21, "trd": NaN, "batb": [[1, 1.59, 785.61]], "batl": [[0, 1.62, 673.36]]}, {"timestamp": 1578770427979, "ltp": 1.62, "tv": 4690.21, "trd": NaN, "batb": [[1, 1.59, 737.09]], "batl": NaN}, {"timestamp": 1578770438984, "ltp": 1.62, "tv": 4690.21, "trd": NaN, "batb": [[1, 1.59, 779.65]], "batl": NaN}, {"timestamp": 1578770442016, "ltp": 1.62, "tv": 4690.21, "trd": NaN, "batb": NaN, "batl": [[1, 1.63, 617.16], [2, 1.64, 92.45]]}, {"timestamp": 1578770449896, "ltp": 1.62, "tv": 4690.21, "trd": NaN, "batb": NaN, "batl": [[1, 1.63, 495.7], [2, 1.64, 342.66]]}, {"timestamp": 1578770452006, "ltp": 1.62, "tv": 4709.95, "trd": [[1.62, 1267.5]], "batb": NaN, "batl": [[0, 1.62, 663.49]]}, {"timestamp": 1578770500956, "ltp": 1.62, "tv": 4709.95, "trd": NaN, "batb": NaN, "batl": [[0, 1.62, 671.49]]}, {"timestamp": 1578770505032, "ltp": 1.62, "tv": 4709.95, "trd": NaN, "batb": NaN, "batl": [[1, 1.63, 615.56], [2, 1.64, 92.45]]}, {"timestamp": 1578770506048, "ltp": 1.62, "tv": 4719.95, "trd": [[1.62, 1277.5]], "batb": NaN, "batl": [[0, 1.62, 666.49]]}, {"timestamp": 1578770515051, "ltp": 1.62, "tv": 4719.95, "trd": NaN, "batb": NaN, "batl": [[1, 1.63, 495.7], [2, 1.64, 342.66]]}, {"timestamp": 1578770520049, "ltp": 1.62, "tv": 4719.95, "trd": NaN, "batb": NaN, "batl": [[2, 1.64, 210.13]]}, {"timestamp": 1578770543026, "ltp": 1.62, "tv": 4719.95, "trd": NaN, "batb": NaN, "batl": [[1, 1.63, 616.01], [2, 1.64, 92.45]]}, {"timestamp": 1578770573036, "ltp": 1.62, "tv": 4719.95, "trd": NaN, "batb": NaN, "batl": [[1, 1.63, 495.7], [2, 1.64, 204.06]]}, {"timestamp": 1578770588053, "ltp": 1.6, "tv": 4795.43, "trd": [[1.6, 232.77]], "batb": [[0, 1.6, 477.54]], "batl": [[0, 1.62, 688.49]]}, {"timestamp": 1578770588954, "ltp": 1.61, "tv": 4799.43, "trd": [[1.61, 2656.68]], "batb": [[0, 1.6, 516.59]], "batl": [[0, 1.61, 83.5], [1, 1.62, 688.49], [2, 1.63, 495.7]]}, {"timestamp": 1578770589959, "ltp": 1.61, "tv": 4799.43, "trd": NaN, "batb": NaN, "batl": [[0, 1.61, 46.69]]}, {"timestamp": 1578770590973, "ltp": 1.61, "tv": 4799.43, "trd": NaN, "batb": NaN, "batl": [[0, 1.61, 87.08]]}, {"timestamp": 1578770591981, "ltp": 1.61, "tv": 4799.43, "trd": NaN, "batb": NaN, "batl": [[0, 1.61, 46.69]]}, {"timestamp": 1578770605910, "ltp": 1.6, "tv": 4839.43, "trd": [[1.6, 272.77]], "batb": [[0, 1.6, 496.59]], "batl": [[0, 1.61, 66.69]]}, {"timestamp": 1578770617978, "ltp": 1.6, "tv": 4839.43, "trd": NaN, "batb": NaN, "batl": [[2, 1.63, 544.89]]}, {"timestamp": 1578770621987, "ltp": 1.6, "tv": 4839.43, "trd": NaN, "batb": NaN, "batl": [[2, 1.63, 57.68]]}, {"timestamp": 1578770626010, "ltp": 1.6, "tv": 4839.43, "trd": NaN, "batb": NaN, "batl": [[2, 1.63, 544.83]]}, {"timestamp": 1578770652017, "ltp": 1.6, "tv": 4839.43, "trd": NaN, "batb": NaN, "batl": [[2, 1.63, 655.6]]}, {"timestamp": 1578770656042, "ltp": 1.6, "tv": 4839.43, "trd": NaN, "batb": NaN, "batl": [[1, 1.62, 1197.94], [2, 1.63, 168.45]]}, {"timestamp": 1578770659969, "ltp": 1.61, "tv": 4972.81, "trd": [[1.61, 2790.06]], "batb": [[0, 1.61, 44.73], [1, 1.6, 496.59], [2, 1.59, 779.65]], "batl": [[0, 1.62, 1197.94], [1, 1.63, 168.45], [2, 1.64, 92.45]]}, {"timestamp": 1578770664046, "ltp": 1.61, "tv": 4976.22, "trd": [[1.61, 2793.46]], "batb": [[0, 1.61, 43.03]], "batl": NaN}, {"timestamp": 1578770669037, "ltp": 1.61, "tv": 4976.22, "trd": NaN, "batb": NaN, "batl": [[1, 1.63, 57.68], [2, 1.64, 511.63]]}, {"timestamp": 1578770671040, "ltp": 1.61, "tv": 4980.22, "trd": [[1.61, 2797.46]], "batb": [[0, 1.61, 41.03]], "batl": [[1, 1.63, 476.72], [2, 1.64, 92.45]]}, {"timestamp": 1578770673959, "ltp": 1.61, "tv": 4984.49, "trd": [[1.61, 2801.74]], "batb": [[0, 1.61, 38.89]], "batl": NaN}, {"timestamp": 1578770675053, "ltp": 1.61, "tv": 4988.51, "trd": [[1.61, 2805.76]], "batb": [[0, 1.61, 36.88]], "batl": NaN}, {"timestamp": 1578770677921, "ltp": 1.61, "tv": 4988.51, "trd": NaN, "batb": NaN, "batl": [[1, 1.63, 57.68], [2, 1.64, 511.63]]}, {"timestamp": 1578770678985, "ltp": 1.61, "tv": 4988.51, "trd": NaN, "batb": NaN, "batl": [[2, 1.64, 92.45]]}, {"timestamp": 1578770691051, "ltp": 1.61, "tv": 4988.51, "trd": NaN, "batb": NaN, "batl": [[2, 1.64, 209.63]]}, {"timestamp": 1578770691967, "ltp": 1.61, "tv": 4988.51, "trd": NaN, "batb": NaN, "batl": [[0, 1.62, 1210.48]]}, {"timestamp": 1578770702021, "ltp": 1.61, "tv": 4988.51, "trd": NaN, "batb": [[1, 1.6, 491.59]], "batl": NaN}, {"timestamp": 1578770702982, "ltp": 1.61, "tv": 4988.51, "trd": NaN, "batb": [[1, 1.6, 536.59]], "batl": NaN}, {"timestamp": 1578770703999, "ltp": 1.61, "tv": 4988.51, "trd": NaN, "batb": [[1, 1.6, 533.59]], "batl": NaN}, {"timestamp": 1578770706016, "ltp": 1.61, "tv": 4988.51, "trd": NaN, "batb": NaN, "batl": [[0, 1.62, 1174.73]]}, {"timestamp": 1578770711986, "ltp": 1.61, "tv": 4988.51, "trd": NaN, "batb": [[0, 1.61, 66.68]], "batl": NaN}, {"timestamp": 1578770717015, "ltp": 1.61, "tv": 4988.51, "trd": NaN, "batb": [[0, 1.61, 36.88]], "batl": NaN}, {"timestamp": 1578770720019, "ltp": 1.61, "tv": 5004.51, "trd": [[1.61, 2821.76]], "batb": [[0, 1.61, 28.88]], "batl": NaN}, {"timestamp": 1578770729034, "ltp": 1.62, "tv": 5010.51, "trd": [[1.62, 1283.5]], "batb": [[0, 1.61, 31.88]], "batl": [[0, 1.62, 1171.73]]}, {"timestamp": 1578770730004, "ltp": 1.62, "tv": 5010.51, "trd": NaN, "batb": NaN, "batl": [[2, 1.64, 92.45]]}, {"timestamp": 1578770737045, "ltp": 1.62, "tv": 5010.51, "trd": NaN, "batb": [[1, 1.6, 84.05], [2, 1.59, 1290.6]], "batl": NaN}, {"timestamp": 1578770744035, "ltp": 1.62, "tv": 5010.51, "trd": NaN, "batb": NaN, "batl": [[2, 1.64, 592.38]]}, {"timestamp": 1578770745031, "ltp": 1.61, "tv": 5040.99, "trd": [[1.61, 2852.24]], "batb": [[0, 1.61, 1.4]], "batl": NaN}, {"timestamp": 1578770754039, "ltp": 1.61, "tv": 5043.79, "trd": [[1.61, 2855.04]], "batb": [[0, 1.6, 103.89], [1, 1.59, 1290.6], [2, 1.58, 45]], "batl": [[0, 1.61, 66.56], [1, 1.62, 1171.73], [2, 1.63, 57.68]]}, {"timestamp": 1578770759040, "ltp": 1.61, "tv": 5043.79, "trd": NaN, "batb": NaN, "batl": [[0, 1.61, 45]]}, {"timestamp": 1578770761859, "ltp": 1.61, "tv": 5043.79, "trd": NaN, "batb": [[0, 1.6, 108.89]], "batl": NaN}, {"timestamp": 1578770765056, "ltp": 1.61, "tv": 5043.79, "trd": NaN, "batb": [[0, 1.6, 616.64], [1, 1.59, 779.65]], "batl": [[0, 1.62, 1171.73], [1, 1.63, 57.68], [2, 1.64, 592.38]]}, {"timestamp": 1578770766966, "ltp": 1.6, "tv": 5089.72, "trd": [[1.6, 318.69]], "batb": [[0, 1.6, 593.68]], "batl": NaN}, {"timestamp": 1578770767969, "ltp": 1.6, "tv": 5089.72, "trd": NaN, "batb": NaN, "batl": [[0, 1.61, 47.3], [1, 1.62, 1171.73], [2, 1.63, 57.68]]}, {"timestamp": 1578770768958, "ltp": 1.6, "tv": 5089.72, "trd": NaN, "batb": NaN, "batl": [[0, 1.61, 50.3]]}, {"timestamp": 1578770774972, "ltp": 1.61, "tv": 5105.7, "trd": [[1.61, 2871.03]], "batb": NaN, "batl": [[0, 1.61, 3]]}, {"timestamp": 1578770779878, "ltp": 1.61, "tv": 5105.7, "trd": NaN, "batb": NaN, "batl": [[1, 1.62, 1216]]}, {"timestamp": 1578770798973, "ltp": 1.6, "tv": 5110.31, "trd": [[1.6, 323.28], [1.61, 2871.05]], "batb": [[0, 1.6, 591.38]], "batl": [[0, 1.61, 2.99]]}, {"timestamp": 1578770802002, "ltp": 1.6, "tv": 5110.31, "trd": NaN, "batb": [[1, 1.59, 829.02]], "batl": [[1, 1.62, 1158.11]]}, {"timestamp": 1578770803010, "ltp": 1.6, "tv": 5110.31, "trd": NaN, "batb": [[2, 1.58, 500.87]], "batl": NaN}, {"timestamp": 1578770807010, "ltp": 1.6, "tv": 5110.31, "trd": NaN, "batb": NaN, "batl": [[1, 1.62, 1098.53]]}, {"timestamp": 1578770809946, "ltp": 1.6, "tv": 5132.67, "trd": [[1.6, 345.64]], "batb": [[0, 1.6, 580.21]], "batl": [[0, 1.61, 28.88]]}, {"timestamp": 1578770811026, "ltp": 1.6, "tv": 5132.67, "trd": NaN, "batb": NaN, "batl": [[0, 1.61, 28.44]]}, {"timestamp": 1578770811999, "ltp": 1.6, "tv": 5132.67, "trd": NaN, "batb": NaN, "batl": [[0, 1.61, 2.99]]}, {"timestamp": 1578770813013, "ltp": 1.6, "tv": 5132.67, "trd": NaN, "batb": [[1, 1.59, 839.02]], "batl": [[1, 1.62, 589.08], [2, 1.63, 556.12]]}, {"timestamp": 1578770819013, "ltp": 1.61, "tv": 5135.66, "trd": [[1.61, 2874.04]], "batb": NaN, "batl": [[0, 1.62, 589.08], [1, 1.63, 556.12], [2, 1.64, 92.45]]}, {"timestamp": 1578770822903, "ltp": 1.61, "tv": 5135.66, "trd": NaN, "batb": NaN, "batl": [[0, 1.62, 658.88]]}, {"timestamp": 1578770846054, "ltp": 1.61, "tv": 5135.66, "trd": NaN, "batb": NaN, "batl": [[0, 1.62, 646.34]]}, {"timestamp": 1578770846952, "ltp": 1.61, "tv": 5135.66, "trd": NaN, "batb": NaN, "batl": [[2, 1.64, 114.45]]}, {"timestamp": 1578770856957, "ltp": 1.61, "tv": 5135.66, "trd": NaN, "batb": [[1, 1.59, 829.02]], "batl": NaN}, {"timestamp": 1578770863981, "ltp": 1.6, "tv": 5139.4, "trd": [[1.6, 349.38]], "batb": [[0, 1.6, 578.34]], "batl": NaN}, {"timestamp": 1578770866054, "ltp": 1.6, "tv": 5139.4, "trd": NaN, "batb": NaN, "batl": [[0, 1.62, 653.76]]}, {"timestamp": 1578770866953, "ltp": 1.6, "tv": 5139.4, "trd": NaN, "batb": NaN, "batl": [[0, 1.61, 45.26], [1, 1.62, 646.34], [2, 1.63, 556.12]]}, {"timestamp": 1578770867973, "ltp": 1.6, "tv": 5139.4, "trd": NaN, "batb": [[1, 1.59, 856.26]], "batl": [[0, 1.62, 653.75], [1, 1.63, 556.12], [2, 1.64, 114.45]]}, {"timestamp": 1578770873000, "ltp": 1.6, "tv": 5139.4, "trd": NaN, "batb": NaN, "batl": [[0, 1.62, 614.57]]}, {"timestamp": 1578770889020, "ltp": 1.6, "tv": 5139.4, "trd": NaN, "batb": NaN, "batl": [[0, 1.62, 648.55]]}, {"timestamp": 1578770893011, "ltp": 1.6, "tv": 5139.4, "trd": NaN, "batb": [[1, 1.59, 643.45]], "batl": [[0, 1.62, 173.92]]}, {"timestamp": 1578770894005, "ltp": 1.6, "tv": 5139.4, "trd": NaN, "batb": NaN, "batl": [[0, 1.62, 181.22]]}, {"timestamp": 1578770898020, "ltp": 1.6, "tv": 5139.4, "trd": NaN, "batb": NaN, "batl": [[0, 1.62, 193.46]]}, {"timestamp": 1578770899026, "ltp": 1.6, "tv": 5139.4, "trd": NaN, "batb": NaN, "batl": [[0, 1.61, 30.01], [1, 1.62, 193.46], [2, 1.63, 556.12]]}, {"timestamp": 1578770900041, "ltp": 1.6, "tv": 5139.4, "trd": NaN, "batb": NaN, "batl": [[0, 1.62, 193.46], [1, 1.63, 556.12], [2, 1.64, 114.45]]}, {"timestamp": 1578770902005, "ltp": 1.6, "tv": 5139.4, "trd": NaN, "batb": [[2, 1.58, 45]], "batl": [[0, 1.62, 790.21], [1, 1.63, 57.68]]}, {"timestamp": 1578770905942, "ltp": 1.6, "tv": 5139.4, "trd": NaN, "batb": [[1, 1.59, 829.02]], "batl": [[0, 1.62, 1249.01]]}, {"timestamp": 1578770908029, "ltp": 1.6, "tv": 5139.4, "trd": NaN, "batb": NaN, "batl": [[2, 1.64, 226.63]]}, {"timestamp": 1578770918952, "ltp": 1.62, "tv": 5837.37, "trd": [[1.62, 1981.47]], "batb": [[0, 1.61, 159.18], [1, 1.6, 586.34], [2, 1.59, 829.02]], "batl": [[0, 1.62, 900.03]]}, {"timestamp": 1578770920056, "ltp": 1.62, "tv": 5837.37, "trd": NaN, "batb": [[0, 1.61, 167.18]], "batl": [[0, 1.62, 932.45]]}, {"timestamp": 1578770930937, "ltp": 1.62, "tv": 5837.37, "trd": NaN, "batb": [[0, 1.61, 134.87]], "batl": [[2, 1.64, 114.45]]}, {"timestamp": 1578770931944, "ltp": 1.62, "tv": 5837.37, "trd": NaN, "batb": [[0, 1.61, 162.95]], "batl": NaN}, {"timestamp": 1578770935049, "ltp": 1.62, "tv": 5837.37, "trd": NaN, "batb": [[0, 1.61, 134.87]], "batl": NaN}, {"timestamp": 1578770938050, "ltp": 1.61, "tv": 6107.12, "trd": [[1.61, 3143.78]], "batb": [[0, 1.6, 586.34], [1, 1.59, 929.02], [2, 1.58, 45]], "batl": [[0, 1.61, 94.73], [1, 1.62, 932.45], [2, 1.63, 57.68]]}, {"timestamp": 1578770939048, "ltp": 1.61, "tv": 6107.12, "trd": NaN, "batb": [[0, 1.6, 578.34]], "batl": [[0, 1.61, 135.73], [1, 1.62, 977.45]]}, {"timestamp": 1578770941054, "ltp": 1.61, "tv": 6107.12, "trd": NaN, "batb": NaN, "batl": [[0, 1.61, 137.73]]}, {"timestamp": 1578770942954, "ltp": 1.61, "tv": 6107.12, "trd": NaN, "batb": NaN, "batl": [[0, 1.61, 135.73]]}, {"timestamp": 1578770944965, "ltp": 1.61, "tv": 6107.12, "trd": NaN, "batb": NaN, "batl": [[0, 1.61, 137.6]]}, {"timestamp": 1578770947980, "ltp": 1.61, "tv": 6107.12, "trd": NaN, "batb": NaN, "batl": [[0, 1.61, 211.16]]}, {"timestamp": 1578770948985, "ltp": 1.6, "tv": 6184.24, "trd": [[1.6, 426.5]], "batb": [[0, 1.6, 539.78], [1, 1.59, 908.59]], "batl": [[0, 1.61, 141.6]]}, {"timestamp": 1578770949981, "ltp": 1.6, "tv": 6188.24, "trd": [[1.6, 430.5]], "batb": [[0, 1.6, 565.14], [1, 1.59, 929.02]], "batl": [[0, 1.61, 168.78]]}, {"timestamp": 1578770953979, "ltp": 1.6, "tv": 6188.24, "trd": NaN, "batb": [[1, 1.59, 960.51]], "batl": NaN}, {"timestamp": 1578770958988, "ltp": 1.6, "tv": 6228.16, "trd": [[1.6, 470.42]], "batb": [[0, 1.6, 540.11]], "batl": NaN}, {"timestamp": 1578770961981, "ltp": 1.61, "tv": 6253.15, "trd": [[1.61, 3168.78]], "batb": NaN, "batl": [[0, 1.61, 156.28]]}, {"timestamp": 1578770968993, "ltp": 1.61, "tv": 6253.15, "trd": NaN, "batb": [[1, 1.59, 903.59]], "batl": NaN}, {"timestamp": 1578770970009, "ltp": 1.61, "tv": 6253.15, "trd": NaN, "batb": NaN, "batl": [[0, 1.61, 129.1], [1, 1.62, 939.14]]}, {"timestamp": 1578770972017, "ltp": 1.61, "tv": 6253.15, "trd": NaN, "batb": [[1, 1.59, 858.48]], "batl": [[1, 1.62, 899.99]]}, {"timestamp": 1578770977925, "ltp": 1.61, "tv": 6253.15, "trd": NaN, "batb": [[1, 1.59, 815.92]], "batl": [[1, 1.62, 859.13]]}, {"timestamp": 1578770980029, "ltp": 1.6, "tv": 6256.89, "trd": [[1.6, 474.15]], "batb": [[0, 1.6, 538.24], [1, 1.59, 791.99]], "batl": [[0, 1.61, 127.23]]}, {"timestamp": 1578770985932, "ltp": 1.6, "tv": 6264.29, "trd": [[1.6, 481.55]], "batb": [[0, 1.6, 534.54], [1, 1.59, 795.27]], "batl": NaN}, {"timestamp": 1578770988935, "ltp": 1.6, "tv": 6264.29, "trd": NaN, "batb": [[1, 1.59, 783.5]], "batl": [[1, 1.62, 905.94]]}, {"timestamp": 1578770992953, "ltp": 1.6, "tv": 6298.34, "trd": [[1.6, 515.6]], "batb": [[0, 1.6, 517.52], [1, 1.59, 786.17]], "batl": [[0, 1.61, 152.95]]}, {"timestamp": 1578771000053, "ltp": 1.6, "tv": 6298.34, "trd": NaN, "batb": NaN, "batl": [[2, 1.63, 557.45]]}, {"timestamp": 1578771001961, "ltp": 1.6, "tv": 6298.34, "trd": NaN, "batb": [[0, 1.6, 522.52]], "batl": NaN}, {"timestamp": 1578771006029, "ltp": 1.6, "tv": 6298.34, "trd": NaN, "batb": [[1, 1.59, 833.84]], "batl": [[1, 1.62, 936.59], [2, 1.63, 57.68]]}, {"timestamp": 1578771007999, "ltp": 1.61, "tv": 6322.74, "trd": [[1.61, 3193.18]], "batb": [[1, 1.59, 841.04]], "batl": [[0, 1.61, 140.75]]}, {"timestamp": 1578771008990, "ltp": 1.61, "tv": 6322.74, "trd": NaN, "batb": [[1, 1.59, 889.55]], "batl": [[1, 1.62, 495.36], [2, 1.63, 650.58]]}, {"timestamp": 1578771009999, "ltp": 1.61, "tv": 6322.74, "trd": NaN, "batb": [[0, 1.6, 527.29]], "batl": [[0, 1.61, 115.03]]}, {"timestamp": 1578771011005, "ltp": 1.61, "tv": 6322.74, "trd": NaN, "batb": [[1, 1.59, 888.45]], "batl": NaN}, {"timestamp": 1578771012005, "ltp": 1.61, "tv": 6322.74, "trd": NaN, "batb": [[0, 1.6, 527.28]], "batl": NaN}, {"timestamp": 1578771013973, "ltp": 1.61, "tv": 6322.74, "trd": NaN, "batb": NaN, "batl": [[2, 1.63, 1150.35]]}, {"timestamp": 1578771015040, "ltp": 1.61, "tv": 6322.74, "trd": NaN, "batb": [[0, 1.6, 522.52]], "batl": NaN}, {"timestamp": 1578771015728, "ltp": 1.61, "tv": 6322.74, "trd": NaN, "batb": [[0, 1.6, 527.26]], "batl": NaN}, {"timestamp": 1578771016933, "ltp": 1.61, "tv": 6322.74, "trd": NaN, "batb": [[1, 1.59, 886.26]], "batl": [[2, 1.63, 1588.11]]}, {"timestamp": 1578771022997, "ltp": 1.61, "tv": 6322.74, "trd": NaN, "batb": [[0, 1.6, 522.52], [1, 1.59, 879.02]], "batl": NaN}, {"timestamp": 1578771024039, "ltp": 1.61, "tv": 6322.74, "trd": NaN, "batb": [[0, 1.6, 527.22]], "batl": NaN}, {"timestamp": 1578771027002, "ltp": 1.6, "tv": 6331.16, "trd": [[1.6, 524.02]], "batb": [[0, 1.6, 523.01]], "batl": NaN}, {"timestamp": 1578771031011, "ltp": 1.6, "tv": 6331.16, "trd": NaN, "batb": [[0, 1.6, 522.99]], "batl": NaN}, {"timestamp": 1578771035036, "ltp": 1.6, "tv": 6331.16, "trd": NaN, "batb": [[0, 1.6, 518.31]], "batl": [[2, 1.63, 1088.34]]}, {"timestamp": 1578771035950, "ltp": 1.6, "tv": 6331.16, "trd": NaN, "batb": [[0, 1.6, 522.97]], "batl": NaN}, {"timestamp": 1578771037959, "ltp": 1.6, "tv": 6331.16, "trd": NaN, "batb": [[0, 1.6, 522.96]], "batl": NaN}, {"timestamp": 1578771039855, "ltp": 1.6, "tv": 6334.9, "trd": [[1.6, 527.76]], "batb": [[0, 1.6, 521.09]], "batl": NaN}, {"timestamp": 1578771041031, "ltp": 1.6, "tv": 6334.9, "trd": NaN, "batb": [[0, 1.6, 521.08]], "batl": NaN}, {"timestamp": 1578771041982, "ltp": 1.6, "tv": 6342.55, "trd": [[1.6, 535.41]], "batb": [[0, 1.6, 517.25]], "batl": NaN}, {"timestamp": 1578771046979, "ltp": 1.6, "tv": 6342.55, "trd": NaN, "batb": [[0, 1.6, 517.24]], "batl": [[2, 1.63, 1200.38]]}, {"timestamp": 1578771054960, "ltp": 1.6, "tv": 6342.55, "trd": NaN, "batb": [[0, 1.6, 512.61]], "batl": [[2, 1.63, 57.68]]}, {"timestamp": 1578771055963, "ltp": 1.6, "tv": 6342.55, "trd": NaN, "batb": [[0, 1.6, 517.2]], "batl": [[2, 1.63, 1088.34]]}, {"timestamp": 1578771057025, "ltp": 1.6, "tv": 6342.55, "trd": NaN, "batb": [[1, 1.59, 920.73]], "batl": [[2, 1.63, 1819.53]]}, {"timestamp": 1578771057981, "ltp": 1.6, "tv": 6342.55, "trd": NaN, "batb": [[0, 1.6, 517.19]], "batl": [[2, 1.63, 788.87]]}, {"timestamp": 1578771060991, "ltp": 1.6, "tv": 6349.36, "trd": [[1.6, 542.22]], "batb": [[0, 1.6, 513.79]], "batl": [[1, 1.62, 77.41], [2, 1.63, 820.37]]}, {"timestamp": 1578771061992, "ltp": 1.6, "tv": 6349.36, "trd": NaN, "batb": [[0, 1.6, 509.21]], "batl": NaN}, {"timestamp": 1578771063993, "ltp": 1.6, "tv": 6349.36, "trd": NaN, "batb": NaN, "batl": [[2, 1.63, 1851.03]]}, {"timestamp": 1578771069018, "ltp": 1.6, "tv": 6349.36, "trd": NaN, "batb": NaN, "batl": [[2, 1.63, 1976.34]]}, {"timestamp": 1578771075010, "ltp": 1.61, "tv": 6537.36, "trd": [[1.61, 3381.18]], "batb": [[0, 1.6, 514.1], [1, 1.59, 968.2]], "batl": [[0, 1.61, 21.03]]}, {"timestamp": 1578771077005, "ltp": 1.6, "tv": 6585.71, "trd": [[1.6, 590.57]], "batb": [[0, 1.6, 489.92], [1, 1.59, 982.46]], "batl": NaN}, {"timestamp": 1578771084040, "ltp": 1.6, "tv": 6585.71, "trd": NaN, "batb": NaN, "batl": [[2, 1.63, 1851.03]]}, {"timestamp": 1578771085973, "ltp": 1.6, "tv": 6585.71, "trd": NaN, "batb": NaN, "batl": [[2, 1.63, 1975.53]]}, {"timestamp": 1578771087048, "ltp": 1.61, "tv": 6668.76, "trd": [[1.61, 3464.23]], "batb": [[0, 1.61, 157.98], [1, 1.6, 489.92], [2, 1.59, 1006.96]], "batl": [[0, 1.62, 102.13], [1, 1.63, 1975.53], [2, 1.64, 114.45]]}, {"timestamp": 1578771087950, "ltp": 1.61, "tv": 6668.76, "trd": NaN, "batb": [[0, 1.61, 160.98], [1, 1.6, 492.92]], "batl": NaN}, {"timestamp": 1578771088956, "ltp": 1.61, "tv": 6668.76, "trd": NaN, "batb": [[1, 1.6, 1090.24]], "batl": NaN}, {"timestamp": 1578771090996, "ltp": 1.61, "tv": 6668.76, "trd": NaN, "batb": [[2, 1.59, 1004.95]], "batl": NaN}, {"timestamp": 1578771092034, "ltp": 1.6, "tv": 7068.76, "trd": [[1.6, 668.61], [1.61, 3786.19]], "batb": [[0, 1.61, 45], [1, 1.6, 1051.22], [2, 1.59, 1010.73]], "batl": NaN}, {"timestamp": 1578771103970, "ltp": 1.6, "tv": 7068.76, "trd": NaN, "batb": [[0, 1.61, 90.12]], "batl": NaN}, {"timestamp": 1578771104878, "ltp": 1.6, "tv": 7068.76, "trd": NaN, "batb": [[0, 1.61, 45]], "batl": NaN}, {"timestamp": 1578771111986, "ltp": 1.6, "tv": 7068.76, "trd": NaN, "batb": NaN, "batl": [[0, 1.62, 536.25]]}, {"timestamp": 1578771112984, "ltp": 1.6, "tv": 7068.76, "trd": NaN, "batb": [[0, 1.6, 1051.22], [1, 1.59, 1010.73], [2, 1.58, 45]], "batl": NaN}, {"timestamp": 1578771113991, "ltp": 1.6, "tv": 7068.76, "trd": NaN, "batb": NaN, "batl": [[1, 1.63, 1851.03], [2, 1.64, 614.38]]}, {"timestamp": 1578771117014, "ltp": 1.6, "tv": 7068.76, "trd": NaN, "batb": [[1, 1.59, 884.76]], "batl": [[0, 1.62, 102.13]]}, {"timestamp": 1578771117969, "ltp": 1.6, "tv": 7068.76, "trd": NaN, "batb": NaN, "batl": [[1, 1.63, 2436.77], [2, 1.64, 114.45]]}, {"timestamp": 1578771120977, "ltp": 1.6, "tv": 7068.76, "trd": NaN, "batb": NaN, "batl": [[0, 1.62, 579.66]]}, {"timestamp": 1578771121988, "ltp": 1.6, "tv": 7068.76, "trd": NaN, "batb": [[1, 1.59, 794.76]], "batl": [[0, 1.62, 1616.69], [1, 1.63, 1406.11]]}, {"timestamp": 1578771125913, "ltp": 1.6, "tv": 7068.76, "trd": NaN, "batb": NaN, "batl": [[1, 1.63, 557.45]]}, {"timestamp": 1578771126987, "ltp": 1.6, "tv": 7068.76, "trd": NaN, "batb": NaN, "batl": [[0, 1.62, 1642.23]]}, {"timestamp": 1578771127986, "ltp": 1.6, "tv": 7068.76, "trd": NaN, "batb": NaN, "batl": [[1, 1.63, 57.68], [2, 1.64, 614.38]]}, {"timestamp": 1578771138047, "ltp": 1.6, "tv": 7068.76, "trd": NaN, "batb": NaN, "batl": [[0, 1.62, 1614.99]]}, {"timestamp": 1578771147048, "ltp": 1.6, "tv": 7068.76, "trd": NaN, "batb": NaN, "batl": [[0, 1.62, 577.96], [1, 1.63, 1088.35]]}, {"timestamp": 1578771148044, "ltp": 1.6, "tv": 7068.76, "trd": NaN, "batb": NaN, "batl": [[0, 1.62, 622.22]]}, {"timestamp": 1578771149052, "ltp": 1.6, "tv": 7068.76, "trd": NaN, "batb": NaN, "batl": [[1, 1.63, 57.68]]}, {"timestamp": 1578771154967, "ltp": 1.6, "tv": 7068.76, "trd": NaN, "batb": NaN, "batl": [[1, 1.63, 1088.34]]}, {"timestamp": 1578771157959, "ltp": 1.6, "tv": 7068.76, "trd": NaN, "batb": [[0, 1.6, 40.25], [1, 1.59, 1851.35]], "batl": NaN}, {"timestamp": 1578771158864, "ltp": 1.6, "tv": 7068.76, "trd": NaN, "batb": NaN, "batl": [[1, 1.63, 1199.31], [2, 1.64, 114.45]]}, {"timestamp": 1578771159978, "ltp": 1.6, "tv": 7068.76, "trd": NaN, "batb": [[0, 1.6, 193.32]], "batl": NaN}, {"timestamp": 1578771162964, "ltp": 1.6, "tv": 7068.76, "trd": NaN, "batb": NaN, "batl": [[1, 1.63, 1088.34]]}, {"timestamp": 1578771164010, "ltp": 1.6, "tv": 7068.76, "trd": NaN, "batb": NaN, "batl": [[1, 1.63, 1202.46]]}, {"timestamp": 1578771181020, "ltp": 1.6, "tv": 7068.76, "trd": NaN, "batb": NaN, "batl": [[1, 1.63, 1088.34]]}, {"timestamp": 1578771189022, "ltp": 1.6, "tv": 7068.76, "trd": NaN, "batb": [[0, 1.6, 203.32], [1, 1.59, 1841.35]], "batl": NaN}, {"timestamp": 1578771195053, "ltp": 1.6, "tv": 7068.76, "trd": NaN, "batb": [[0, 1.6, 1253.32]], "batl": NaN}, {"timestamp": 1578771195885, "ltp": 1.6, "tv": 7068.76, "trd": NaN, "batb": [[1, 1.59, 784.76]], "batl": NaN}, {"timestamp": 1578771198049, "ltp": 1.6, "tv": 7068.76, "trd": NaN, "batb": NaN, "batl": [[2, 1.64, 253.13]]}, {"timestamp": 1578771210976, "ltp": 1.6, "tv": 7068.76, "trd": NaN, "batb": [[0, 1.6, 1243.32]], "batl": NaN}, {"timestamp": 1578771211889, "ltp": 1.6, "tv": 7068.76, "trd": NaN, "batb": [[1, 1.59, 794.76]], "batl": NaN}, {"timestamp": 1578771212992, "ltp": 1.6, "tv": 7068.76, "trd": NaN, "batb": [[0, 1.6, 1253.32], [1, 1.59, 784.76]], "batl": NaN}, {"timestamp": 1578771219051, "ltp": 1.6, "tv": 7068.76, "trd": NaN, "batb": [[1, 1.59, 817.95]], "batl": NaN}, {"timestamp": 1578771220010, "ltp": 1.6, "tv": 7068.76, "trd": NaN, "batb": [[0, 1.6, 1243.32], [1, 1.59, 827.95]], "batl": NaN}, {"timestamp": 1578771220993, "ltp": 1.6, "tv": 7068.76, "trd": NaN, "batb": [[0, 1.6, 1253.32], [1, 1.59, 817.95]], "batl": [[1, 1.63, 57.68]]}, {"timestamp": 1578771221872, "ltp": 1.6, "tv": 7068.76, "trd": NaN, "batb": NaN, "batl": [[1, 1.63, 1088.35]]}, {"timestamp": 1578771224965, "ltp": 1.6, "tv": 7087.26, "trd": [[1.6, 687.12]], "batb": [[0, 1.6, 1244.06]], "batl": NaN}, {"timestamp": 1578771226909, "ltp": 1.6, "tv": 7087.26, "trd": NaN, "batb": NaN, "batl": [[0, 1.62, 664.78]]}, {"timestamp": 1578771232974, "ltp": 1.6, "tv": 7087.26, "trd": NaN, "batb": [[1, 1.59, 343.83]], "batl": [[0, 1.62, 102.13]]}, {"timestamp": 1578771238999, "ltp": 1.6, "tv": 7087.26, "trd": NaN, "batb": [[1, 1.59, 740.49]], "batl": [[0, 1.62, 650.31]]}, {"timestamp": 1578771284911, "ltp": 1.6, "tv": 7087.62, "trd": [[1.6, 687.48]], "batb": [[0, 1.6, 1249.01]], "batl": NaN}, {"timestamp": 1578771294004, "ltp": 1.6, "tv": 7087.62, "trd": NaN, "batb": [[0, 1.6, 1248.96]], "batl": NaN}, {"timestamp": 1578771295018, "ltp": 1.6, "tv": 7087.62, "trd": NaN, "batb": [[0, 1.6, 1238.96]], "batl": NaN}, {"timestamp": 1578771296032, "ltp": 1.6, "tv": 7087.62, "trd": NaN, "batb": [[0, 1.6, 1238.95], [1, 1.59, 750.49]], "batl": NaN}, {"timestamp": 1578771302014, "ltp": 1.6, "tv": 7087.62, "trd": NaN, "batb": [[0, 1.6, 1245.2]], "batl": NaN}, {"timestamp": 1578771302916, "ltp": 1.6, "tv": 7087.62, "trd": NaN, "batb": NaN, "batl": [[0, 1.61, 16], [1, 1.62, 650.31], [2, 1.63, 1088.35]]}, {"timestamp": 1578771308029, "ltp": 1.6, "tv": 7087.62, "trd": NaN, "batb": [[0, 1.6, 1238.95]], "batl": NaN}, {"timestamp": 1578771309020, "ltp": 1.6, "tv": 7087.62, "trd": NaN, "batb": [[0, 1.6, 1245.17]], "batl": NaN}, {"timestamp": 1578771311035, "ltp": 1.6, "tv": 7087.62, "trd": NaN, "batb": [[0, 1.6, 1245.15]], "batl": NaN}, {"timestamp": 1578771313018, "ltp": 1.6, "tv": 7095.28, "trd": [[1.6, 695.13]], "batb": [[0, 1.6, 1241.32]], "batl": NaN}, {"timestamp": 1578771315027, "ltp": 1.6, "tv": 7095.6, "trd": [[1.6, 695.46]], "batb": [[0, 1.6, 1241.15]], "batl": NaN}, {"timestamp": 1578771320978, "ltp": 1.6, "tv": 7095.6, "trd": NaN, "batb": [[0, 1.6, 191.15]], "batl": [[2, 1.63, 909.04]]}, {"timestamp": 1578771322042, "ltp": 1.6, "tv": 7095.6, "trd": NaN, "batb": [[0, 1.6, 191.11], [1, 1.59, 1807.09]], "batl": [[1, 1.62, 1687.34], [2, 1.63, 57.68]]}, {"timestamp": 1578771323960, "ltp": 1.6, "tv": 7095.6, "trd": NaN, "batb": [[0, 1.6, 201.1], [1, 1.59, 1797.09]], "batl": NaN}, {"timestamp": 1578771325972, "ltp": 1.6, "tv": 7095.6, "trd": NaN, "batb": [[0, 1.6, 194.95]], "batl": NaN}, {"timestamp": 1578771328030, "ltp": 1.6, "tv": 7095.6, "trd": NaN, "batb": [[0, 1.6, 201.08]], "batl": NaN}, {"timestamp": 1578771332037, "ltp": 1.6, "tv": 7095.6, "trd": NaN, "batb": [[0, 1.6, 1251.06], [1, 1.59, 740.49], [2, 1.58, 510.37]], "batl": NaN}, {"timestamp": 1578771333051, "ltp": 1.6, "tv": 7095.6, "trd": NaN, "batb": [[0, 1.6, 1244.95]], "batl": NaN}, {"timestamp": 1578771333951, "ltp": 1.6, "tv": 7099.34, "trd": [[1.6, 699.2]], "batb": [[0, 1.6, 1243.08]], "batl": NaN}, {"timestamp": 1578771339054, "ltp": 1.6, "tv": 7099.34, "trd": NaN, "batb": [[0, 1.6, 1233.08], [1, 1.59, 750.49]], "batl": NaN}, {"timestamp": 1578771352975, "ltp": 1.61, "tv": 7099.66, "trd": [[1.61, 3786.51]], "batb": [[0, 1.6, 1239.08], [2, 1.58, 45]], "batl": [[0, 1.61, 15.84]]}, {"timestamp": 1578771356994, "ltp": 1.61, "tv": 7099.66, "trd": NaN, "batb": [[0, 1.6, 1233.08]], "batl": NaN}, {"timestamp": 1578771357994, "ltp": 1.6, "tv": 7180.25, "trd": [[1.6, 779.78]], "batb": [[0, 1.6, 1225.24], [1, 1.59, 765.46]], "batl": [[0, 1.61, 51.08]]}, {"timestamp": 1578771359004, "ltp": 1.6, "tv": 7180.25, "trd": NaN, "batb": [[0, 1.6, 1231.36]], "batl": [[0, 1.61, 18.84]]}, {"timestamp": 1578771360012, "ltp": 1.6, "tv": 7180.25, "trd": NaN, "batb": [[0, 1.6, 1231.35], [2, 1.58, 542.06]], "batl": NaN}, {"timestamp": 1578771361028, "ltp": 1.6, "tv": 7570.25, "trd": [[1.6, 1169.78]], "batb": [[0, 1.6, 1036.35]], "batl": NaN}, {"timestamp": 1578771361986, "ltp": 1.6, "tv": 7570.25, "trd": NaN, "batb": [[1, 1.59, 840.49]], "batl": NaN}, {"timestamp": 1578771375994, "ltp": 1.6, "tv": 7570.25, "trd": NaN, "batb": NaN, "batl": [[1, 1.62, 1643.93]]}, {"timestamp": 1578771383945, "ltp": 1.6, "tv": 8677.81, "trd": [[1.6, 2277.34]], "batb": [[0, 1.6, 482.57]], "batl": NaN}, {"timestamp": 1578771388051, "ltp": 1.6, "tv": 8677.81, "trd": NaN, "batb": [[2, 1.58, 45]], "batl": NaN}, {"timestamp": 1578771388801, "ltp": 1.6, "tv": 8677.81, "trd": NaN, "batb": NaN, "batl": [[0, 1.61, 171.91]]}, {"timestamp": 1578771396041, "ltp": 1.61, "tv": 8885.16, "trd": [[1.61, 3993.87]], "batb": [[0, 1.6, 83.56], [1, 1.59, 1450.28]], "batl": [[0, 1.61, 113.23]]}, {"timestamp": 1578771397050, "ltp": 1.61, "tv": 8885.16, "trd": NaN, "batb": NaN, "batl": [[0, 1.61, 121.08]]}, {"timestamp": 15787